{"op":"mcm","clk":"11894605941","pt":1724316227447,"mc":[{"id":"1.232129550","marketDefinition":{"bspMarket":false,"turnInPlayEnabled":true,"persistenceEnabled":true,"marketBaseRate":5.0,"eventId":"33516975","eventTypeId":"4","numberOfWinners":1,"bettingType":"ODDS","marketType":"MATCH_ODDS","marketTime":"2024-08-23T16:00:00.000Z","suspendTime":"2024-08-23T16:00:00.000Z","bspReconciled":false,"complete":true,"inPlay":false,"crossMatching":true,"runnersVoidable":false,"numberOfActiveRunners":2,"betDelay":0,"status":"OPEN","runners":[{"status":"ACTIVE","sortPriority":1,"id":72922097,"name":"Caribbean Tigers"},{"status":"ACTIVE","sortPriority":2,"id":72857114,"name":"Boca Raton Trailblazers"}],"regulators":["MR_INT"],"countryCode":"GB","discountAllowed":false,"timezone":"GMT","openDate":"2024-08-23T16:00:00.000Z","version":6090675110,"name":"Match Odds","eventName":"Caribbean Tigers v Boca Raton Trailblazers"},"rc":[{"batb":[[0,1.03,200],[1,1.02,200],[2,1.01,220]],"ltp":0.0,"tv":0.0,"id":72857114},{"batb":[[0,1.03,200],[1,1.02,200],[2,1.01,220]],"ltp":0.0,"tv":0.0,"id":72922097}]}]}
{"op":"mcm","clk":"11894606018","pt":1724316228974,"mc":[{"id":"1.232129550","marketDefinition":{"bspMarket":false,"turnInPlayEnabled":true,"persistenceEnabled":true,"marketBaseRate":5.0,"eventId":"33516975","eventTypeId":"4","numberOfWinners":1,"bettingType":"ODDS","marketType":"MATCH_ODDS","marketTime":"2024-08-23T16:00:00.000Z","suspendTime":"2024-08-23T16:00:00.000Z","bspReconciled":false,"complete":true,"inPlay":false,"crossMatching":true,"runnersVoidable":false,"numberOfActiveRunners":2,"betDelay":0,"status":"OPEN","runners":[{"status":"ACTIVE","sortPriority":1,"id":72922097,"name":"Caribbean Tigers"},{"status":"ACTIVE","sortPriority":2,"id":72857114,"name":"Boca Raton Trailblazers"}],"regulators":["MR_INT"],"countryCode":"GB","discountAllowed":true,"timezone":"GMT","openDate":"2024-08-23T16:00:00.000Z","version":6090675110,"name":"Match Odds","eventName":"Caribbean Tigers v Boca Raton Trailblazers"}}]}
{"op":"mcm","clk":"11894631486","pt":1724316680008,"mc":[{"id":"1.232129550","rc":[{"batb":[[0,1.04,1.53],[1,1.03,200],[2,1.02,200]],"ltp":0.0,"tv":0.0,"id":72857114},{"batb":[[0,1.04,1.53],[1,1.03,200],[2,1.02,200]],"ltp":0.0,"tv":0.0,"id":72922097}]}]}
{"op":"mcm","clk":"11894853045","pt":1724321143889,"mc":[{"id":"1.232129550","rc":[{"batb":[[0,1.05,200],[1,1.04,251.53],[2,1.03,200]],"ltp":0.0,"tv":0.0,"id":72857114},{"batb":[[0,1.05,200],[1,1.04,251.53],[2,1.03,533.33]],"ltp":0.0,"tv":0.0,"id":72922097}]}]}
{"op":"mcm","clk":"11894853063","pt":1724321144088,"mc":[{"id":"1.232129550","rc":[{"batb":[[2,1.03,533.33]],"ltp":0.0,"tv":0.0,"id":72857114}]}]}
{"op":"mcm","clk":"11894859110","pt":1724321244107,"mc":[{"id":"1.232129550","rc":[{"batb":[[0,1.06,142.18],[1,1.05,200],[2,1.04,251.53]],"ltp":0.0,"tv":0.0,"id":72857114},{"batb":[[0,1.06,142.18],[1,1.05,200],[2,1.04,251.53]],"ltp":0.0,"tv":0.0,"id":72922097}]}]}
{"op":"mcm","clk":"11894976633","pt":1724323044575,"mc":[{"id":"1.232129550","rc":[{"batb":[[0,1.05,200],[1,1.04,251.53],[2,1.03,533.33]],"ltp":0.0,"tv":0.0,"id":72857114},{"batb":[[0,1.05,200],[1,1.04,251.53],[2,1.03,533.33]],"ltp":0.0,"tv":0.0,"id":72922097}]}]}
{"op":"mcm","clk":"11894978093","pt":1724323072719,"mc":[{"id":"1.232129550","rc":[{"batb":[[0,1.06,142.18],[1,1.05,200],[2,1.04,251.53]],"ltp":0.0,"tv":0.0,"id":72857114},{"batb":[[0,1.06,142.18],[1,1.05,200],[2,1.04,251.53]],"ltp":0.0,"tv":0.0,"id":72922097}]}]}
{"op":"mcm","clk":"11895081809","pt":1724324872916,"mc":[{"id":"1.232129550","rc":[{"batb":[[0,1.05,200],[1,1.04,251.53],[2,1.03,533.33]],"ltp":0.0,"tv":0.0,"id":72857114},{"batb":[[0,1.06,142.31]],"ltp":0.0,"tv":0.0,"id":72922097}]}]}
{"op":"mcm","clk":"11895081823","pt":1724324873121,"mc":[{"id":"1.232129550","rc":[{"batb":[[0,1.05,200],[1,1.04,251.53],[2,1.03,533.33]],"ltp":0.0,"tv":0.0,"id":72922097}]}]}
{"op":"mcm","clk":"11895083164","pt":1724324894321,"mc":[{"id":"1.232129550","rc":[{"batb":[[0,1.06,142.31],[1,1.05,200],[2,1.04,251.53]],"ltp":0.0,"tv":0.0,"id":72857114},{"batb":[[0,1.06,142.31],[1,1.05,200],[2,1.04,251.53]],"ltp":0.0,"tv":0.0,"id":72922097}]}]}
{"op":"mcm","clk":"11895196039","pt":1724326694759,"mc":[{"id":"1.232129550","rc":[{"batb":[[0,1.05,200],[1,1.04,251.53],[2,1.03,533.33]],"ltp":0.0,"tv":0.0,"id":72857114},{"batb":[[0,1.05,200],[1,1.04,251.53],[2,1.03,533.33]],"ltp":0.0,"tv":0.0,"id":72922097}]}]}
{"op":"mcm","clk":"11895196654","pt":1724326705882,"mc":[{"id":"1.232129550","rc":[{"batb":[[0,1.06,142.31],[1,1.05,200],[2,1.04,251.53]],"ltp":0.0,"tv":0.0,"id":72857114},{"batb":[[0,1.06,142.31],[1,1.05,200],[2,1.04,251.53]],"ltp":0.0,"tv":0.0,"id":72922097}]}]}
{"op":"mcm","clk":"11895206906","pt":1724326882604,"mc":[{"id":"1.232129550","rc":[{"trd":[[1.06,1.96]],"batb":[[0,1.06,141.33]],"ltp":1.06,"tv":1.95,"id":72922097}],"tv":1.95}]}
{"op":"mcm","clk":"11895262649","pt":1724327699221,"mc":[{"id":"1.232129550","rc":[{"batb":[[1,1.04,1.53],[2,1.03,200]],"ltp":0.0,"tv":0.0,"id":72857114},{"batb":[[1,1.04,1.53],[2,1.03,200]],"ltp":1.06,"tv":1.95,"id":72922097}]}]}
{"op":"mcm","clk":"11895263576","pt":1724327712259,"mc":[{"id":"1.232129550","rc":[{"batb":[[0,1.1,500],[1,1.06,141.33],[2,1.04,1.53]],"ltp":1.06,"tv":1.95,"id":72922097}]}]}
{"op":"mcm","clk":"11895263662","pt":1724327713360,"mc":[{"id":"1.232129550","rc":[{"batb":[[0,1.1,500],[1,1.06,142.31],[2,1.04,1.53]],"ltp":0.0,"tv":0.0,"id":72857114}]}]}
{"op":"mcm","clk":"11895306637","pt":1724328506356,"mc":[{"id":"1.232129550","rc":[{"batb":[[1,1.04,1.53],[2,1.03,200]],"ltp":0.0,"tv":0.0,"id":72857114},{"batb":[[1,1.04,1.53],[2,1.03,200]],"ltp":1.06,"tv":1.95,"id":72922097}]}]}
{"op":"mcm","clk":"11895307080","pt":1724328513955,"mc":[{"id":"1.232129550","rc":[{"batb":[[0,1.11,77.61],[1,1.1,500],[2,1.04,1.53]],"ltp":0.0,"tv":0.0,"id":72857114}]}]}
{"op":"mcm","clk":"11895419084","pt":1724330314174,"mc":[{"id":"1.232129550","rc":[{"batb":[[0,1.1,500],[1,1.04,1.53],[2,1.03,200]],"ltp":0.0,"tv":0.0,"id":72857114}]}]}
{"op":"mcm","clk":"11895431306","pt":1724330511307,"mc":[{"id":"1.232129550","rc":[{"batb":[[0,1.11,77.61],[1,1.1,500],[2,1.04,1.53]],"ltp":0.0,"tv":0.0,"id":72857114}]}]}
{"op":"mcm","clk":"11895469285","pt":1724331033082,"mc":[{"id":"1.232129550","rc":[{"batb":[[0,1.21,82.85],[1,1.1,500],[2,1.04,1.53]],"ltp":1.06,"tv":1.95,"id":72922097}]}]}
{"op":"mcm","clk":"11895470181","pt":1724331045755,"mc":[{"id":"1.232129550","rc":[{"batb":[[0,1.21,82.85],[1,1.11,77.61],[2,1.1,500]],"ltp":0.0,"tv":0.0,"id":72857114}]}]}
{"op":"mcm","clk":"11895472753","pt":1724331089256,"mc":[{"id":"1.232129550","rc":[{"batb":[[0,1.3,15],[1,1.21,82.85],[2,1.11,77.61]],"ltp":0.0,"tv":0.0,"id":72857114},{"batb":[[0,1.22,20],[1,1.21,82.85],[2,1.1,500]],"ltp":1.06,"tv":1.95,"id":72922097}]}]}
{"op":"mcm","clk":"11895530112","pt":1724332009152,"mc":[{"id":"1.232129550","rc":[{"batb":[[1,1.21,82.92],[2,1.11,77.59]],"ltp":0.0,"tv":0.0,"id":72857114},{"trd":[[1.22,0.1]],"batb":[[0,1.22,19.95],[1,1.21,82.92]],"ltp":1.22,"tv":2.05,"id":72922097}],"tv":2.05}]}
{"op":"mcm","clk":"11895532745","pt":1724332051732,"mc":[{"id":"1.232129550","rc":[{"trd":[[1.22,0.2]],"batb":[[0,1.22,19.9]],"ltp":1.22,"tv":2.15,"id":72922097}],"tv":2.15}]}
{"op":"mcm","clk":"11895545514","pt":1724332262325,"mc":[{"id":"1.232129550","rc":[{"trd":[[1.22,0.3]],"batb":[[0,1.22,19.85]],"ltp":1.22,"tv":2.25,"id":72922097}],"tv":2.25}]}
{"op":"mcm","clk":"11895548212","pt":1724332305563,"mc":[{"id":"1.232129550","rc":[{"batb":[[1,1.22,6.88],[2,1.21,82.92]],"ltp":0.0,"tv":0.0,"id":72857114},{"batb":[[0,1.22,26.05]],"ltp":1.22,"tv":2.25,"id":72922097}]}]}
{"op":"mcm","clk":"11895569545","pt":1724332496160,"mc":[{"id":"1.232129550","rc":[{"batb":[[0,1.31,27.53],[1,1.3,15],[2,1.22,6.88]],"ltp":0.0,"tv":0.0,"id":72857114}]}]}
{"op":"mcm","clk":"11895686259","pt":1724334296278,"mc":[{"id":"1.232129550","rc":[{"batb":[[0,1.3,15],[1,1.22,6.88],[2,1.21,82.92]],"ltp":0.0,"tv":0.0,"id":72857114}]}]}
{"op":"mcm","clk":"11895696744","pt":1724334465198,"mc":[{"id":"1.232129550","rc":[{"batb":[[0,1.31,27.53],[1,1.3,15],[2,1.22,6.88]],"ltp":0.0,"tv":0.0,"id":72857114}]}]}
{"op":"mcm","clk":"11895701991","pt":1724334548784,"mc":[{"id":"1.232129550","rc":[{"batb":[[0,1.32,6.88],[1,1.31,27.53],[2,1.3,15]],"ltp":0.0,"tv":0.0,"id":72857114}]}]}
{"op":"mcm","clk":"11895704791","pt":1724334589739,"mc":[{"id":"1.232129550","rc":[{"batb":[[0,1.25,98.46],[1,1.22,26.05],[2,1.21,82.92]],"ltp":1.22,"tv":2.25,"id":72922097}]}]}
{"op":"mcm","clk":"11895775963","pt":1724335610845,"mc":[{"id":"1.232129550","rc":[{"batb":[[0,1.4,68.64],[1,1.32,6.89],[2,1.31,27.51]],"ltp":0.0,"tv":0.0,"id":72857114},{"batb":[[1,1.22,26.06],[2,1.21,82.81]],"ltp":1.22,"tv":2.25,"id":72922097}]}]}
{"op":"mcm","clk":"11895776936","pt":1724335624944,"mc":[{"id":"1.232129550","rc":[{"batb":[[0,1.4,68.64],[1,1.25,98.46],[2,1.22,26.06]],"ltp":1.22,"tv":2.25,"id":72922097}]}]}
{"op":"mcm","clk":"11895777824","pt":1724335636683,"mc":[{"id":"1.232129550","rc":[{"trd":[[1.4,137.28]],"batb":[[0,1.32,6.89],[1,1.31,27.51],[2,1.3,15]],"batl":[[0,1.4,2.71]],"ltp":1.4,"tv":137.28,"id":72857114}],"tv":139.53}]}
{"op":"mcm","clk":"11895778638","pt":1724335647725,"mc":[{"id":"1.232129550","rc":[{"trd":[[1.4,137.28]],"batb":[[0,1.25,98.46],[1,1.22,26.06],[2,1.21,82.81]],"batl":[[0,1.4,2.71]],"ltp":1.4,"tv":139.53,"id":72922097}],"tv":276.82}]}
{"op":"mcm","clk":"11895793581","pt":1724335851735,"mc":[{"id":"1.232129550","rc":[{"batb":[[0,1.26,384.62],[1,1.25,98.46],[2,1.22,26.06]],"ltp":1.4,"tv":139.53,"id":72922097}]}]}
{"op":"mcm","clk":"11895793694","pt":1724335853949,"mc":[{"id":"1.232129550","rc":[{"batb":[[0,1.32,319.39]],"ltp":1.4,"tv":137.28,"id":72857114}]}]}
{"op":"mcm","clk":"11895799312","pt":1724335940142,"mc":[{"id":"1.232129550","rc":[{"batb":[[0,1.4,19.22],[1,1.32,319.39],[2,1.31,27.51]],"ltp":1.4,"tv":137.28,"id":72857114}]}]}
{"op":"mcm","clk":"11895799949","pt":1724335951259,"mc":[{"id":"1.232129550","rc":[{"batb":[[0,1.4,19.22],[1,1.26,384.62],[2,1.25,98.46]],"ltp":1.4,"tv":139.53,"id":72922097}]}]}
{"op":"mcm","clk":"11895800613","pt":1724335960703,"mc":[{"id":"1.232129550","rc":[{"trd":[[1.4,175.72]],"batb":[[0,1.32,319.39],[1,1.31,27.51],[2,1.3,15]],"batl":[[0,1.4,0.63]],"ltp":1.4,"tv":175.72,"id":72857114}],"tv":315.26}]}
{"op":"mcm","clk":"11895801321","pt":1724335971696,"mc":[{"id":"1.232129550","rc":[{"trd":[[1.4,175.72]],"batb":[[0,1.26,384.62],[1,1.25,98.46],[2,1.22,26.06]],"batl":[[0,1.4,0.63]],"ltp":1.4,"tv":177.97,"id":72922097}],"tv":353.7}]}
{"op":"mcm","clk":"11895820514","pt":1724336265439,"mc":[{"id":"1.232129550","rc":[{"batb":[[1,1.3,15],[2,1.21,82.81]],"ltp":1.4,"tv":175.72,"id":72857114}]}]}
{"op":"mcm","clk":"11895830652","pt":1724336414065,"mc":[{"id":"1.232129550","rc":[{"batb":[[0,1.33,25.84],[1,1.32,319.39],[2,1.3,15]],"ltp":1.4,"tv":175.72,"id":72857114}]}]}
{"op":"mcm","clk":"11895832339","pt":1724336437903,"mc":[{"id":"1.232129550","rc":[{"batb":[[0,1.27,14],[1,1.26,384.62],[2,1.25,98.46]],"batl":[[0,4,49.63]],"ltp":1.4,"tv":177.97,"id":72922097}]}]}
{"op":"mcm","clk":"11895832499","pt":1724336440478,"mc":[{"id":"1.232129550","rc":[{"batb":[[0,1.27,10]],"ltp":1.4,"tv":177.97,"id":72922097}]}]}
{"op":"mcm","clk":"11895832548","pt":1724336441198,"mc":[{"id":"1.232129550","rc":[{"batb":[[0,1.26,384.62],[1,1.25,98.46],[2,1.22,26.06]],"ltp":1.4,"tv":177.97,"id":72922097}]}]}
{"op":"mcm","clk":"11895832999","pt":1724336447283,"mc":[{"id":"1.232129550","rc":[{"batb":[[0,1.27,14],[1,1.26,384.62],[2,1.25,98.46]],"ltp":1.4,"tv":177.97,"id":72922097}]}]}
{"op":"mcm","clk":"11895833188","pt":1724336449708,"mc":[{"id":"1.232129550","rc":[{"batb":[[0,1.27,10]],"ltp":1.4,"tv":177.97,"id":72922097}]}]}
{"op":"mcm","clk":"11895833258","pt":1724336450581,"mc":[{"id":"1.232129550","rc":[{"batb":[[0,1.26,384.62],[1,1.25,98.46],[2,1.22,26.06]],"ltp":1.4,"tv":177.97,"id":72922097}]}]}
{"op":"mcm","clk":"11895833771","pt":1724336457896,"mc":[{"id":"1.232129550","rc":[{"batb":[[0,1.27,14],[1,1.26,384.62],[2,1.25,98.46]],"ltp":1.4,"tv":177.97,"id":72922097}]}]}
{"op":"mcm","clk":"11895833911","pt":1724336460113,"mc":[{"id":"1.232129550","rc":[{"batb":[[0,1.27,10]],"ltp":1.4,"tv":177.97,"id":72922097}]}]}
{"op":"mcm","clk":"11895834006","pt":1724336461301,"mc":[{"id":"1.232129550","rc":[{"batb":[[0,1.26,384.62],[1,1.25,98.46],[2,1.22,26.06]],"ltp":1.4,"tv":177.97,"id":72922097}]}]}
{"op":"mcm","clk":"11895834099","pt":1724336462791,"mc":[{"id":"1.232129550","rc":[{"batb":[[0,1.34,14],[1,1.33,25.84],[2,1.32,319.39]],"batl":[[0,4,49.63]],"ltp":1.4,"tv":175.72,"id":72857114},{"batb":[[0,1.27,4],[1,1.26,384.62],[2,1.25,98.46]],"ltp":1.4,"tv":177.97,"id":72922097}]}]}
{"op":"mcm","clk":"11895834244","pt":1724336464830,"mc":[{"id":"1.232129550","rc":[{"batb":[[0,1.28,10],[1,1.27,4],[2,1.26,384.62]],"ltp":1.4,"tv":177.97,"id":72922097}]}]}
{"op":"mcm","clk":"11895834258","pt":1724336465035,"mc":[{"id":"1.232129550","rc":[{"batb":[[0,1.34,10]],"ltp":1.4,"tv":175.72,"id":72857114},{"batb":[[1,1.26,384.62],[2,1.25,98.46]],"ltp":1.4,"tv":177.97,"id":72922097}]}]}
{"op":"mcm","clk":"11895834342","pt":1724336466237,"mc":[{"id":"1.232129550","rc":[{"batb":[[0,1.33,25.84],[1,1.32,319.39],[2,1.3,15]],"ltp":1.4,"tv":175.72,"id":72857114}]}]}
{"op":"mcm","clk":"11895834490","pt":1724336468404,"mc":[{"id":"1.232129550","rc":[{"batb":[[0,1.34,14],[1,1.33,25.84],[2,1.32,319.39]],"ltp":1.4,"tv":175.72,"id":72857114},{"batb":[[0,1.27,4]],"ltp":1.4,"tv":177.97,"id":72922097}]}]}
{"op":"mcm","clk":"11895834646","pt":1724336470724,"mc":[{"id":"1.232129550","rc":[{"batb":[[0,1.34,10]],"ltp":1.4,"tv":175.72,"id":72857114},{"batb":[[0,1.27,10]],"ltp":1.4,"tv":177.97,"id":72922097}]}]}
{"op":"mcm","clk":"11895834719","pt":1724336471905,"mc":[{"id":"1.232129550","rc":[{"batb":[[0,1.33,25.84],[1,1.32,319.39],[2,1.3,15]],"batl":[[0,3.85,49.63]],"ltp":1.4,"tv":175.72,"id":72857114}]}]}
{"op":"mcm","clk":"11895834800","pt":1724336473138,"mc":[{"id":"1.232129550","rc":[{"batb":[[0,1.34,4],[1,1.33,25.84],[2,1.32,319.39]],"ltp":1.4,"tv":175.72,"id":72857114},{"batb":[[0,1.28,4],[1,1.27,10],[2,1.26,384.62]],"ltp":1.4,"tv":177.97,"id":72922097}]}]}
{"op":"mcm","clk":"11895834878","pt":1724336474221,"mc":[{"id":"1.232129550","rc":[{"batb":[[0,1.35,10],[1,1.34,4],[2,1.33,25.84]],"ltp":1.4,"tv":175.72,"id":72857114},{"batb":[[1,1.26,384.62],[2,1.25,98.46]],"ltp":1.4,"tv":177.97,"id":72922097}]}]}
{"op":"mcm","clk":"11895834970","pt":1724336475511,"mc":[{"id":"1.232129550","rc":[{"batb":[[1,1.33,25.84],[2,1.32,319.39]],"ltp":1.4,"tv":175.72,"id":72857114},{"batb":[[0,1.26,384.62],[1,1.25,98.46],[2,1.22,26.06]],"ltp":1.4,"tv":177.97,"id":72922097}]}]}
{"op":"mcm","clk":"11895835100","pt":1724336477720,"mc":[{"id":"1.232129550","rc":[{"batb":[[0,1.34,4]],"ltp":1.4,"tv":175.72,"id":72857114},{"batb":[[0,1.28,4],[1,1.27,10],[2,1.26,384.62]],"ltp":1.4,"tv":177.97,"id":72922097}]}]}
{"op":"mcm","clk":"11895835169","pt":1724336478951,"mc":[{"id":"1.232129550","rc":[{"batl":[[0,3.9,49.63]],"ltp":1.4,"tv":177.97,"id":72922097}]}]}
{"op":"mcm","clk":"11895835287","pt":1724336480815,"mc":[{"id":"1.232129550","rc":[{"batb":[[0,1.35,10]],"ltp":1.4,"tv":175.72,"id":72857114},{"batb":[[0,1.26,384.62],[1,1.25,98.46],[2,1.22,26.06]],"ltp":1.4,"tv":177.97,"id":72922097}]}]}
{"op":"mcm","clk":"11895835490","pt":1724336483746,"mc":[{"id":"1.232129550","rc":[{"batb":[[0,1.34,4]],"ltp":1.4,"tv":175.72,"id":72857114},{"batb":[[0,1.27,14],[1,1.26,384.62],[2,1.25,98.46]],"ltp":1.4,"tv":177.97,"id":72922097}]}]}
{"op":"mcm","clk":"11895835619","pt":1724336485964,"mc":[{"id":"1.232129550","rc":[{"batb":[[0,1.27,10]],"ltp":1.4,"tv":177.97,"id":72922097}]}]}
{"op":"mcm","clk":"11895835629","pt":1724336486016,"mc":[{"id":"1.232129550","rc":[{"batb":[[0,1.35,10]],"ltp":1.4,"tv":175.72,"id":72857114}]}]}
{"op":"mcm","clk":"11895835699","pt":1724336487046,"mc":[{"id":"1.232129550","rc":[{"batb":[[0,1.26,384.62],[1,1.25,98.46],[2,1.22,26.06]],"ltp":1.4,"tv":177.97,"id":72922097}]}]}
{"op":"mcm","clk":"11895835850","pt":1724336489319,"mc":[{"id":"1.232129550","rc":[{"batb":[[0,1.36,4]],"ltp":1.4,"tv":175.72,"id":72857114},{"batb":[[0,1.27,14],[1,1.26,384.62],[2,1.25,98.46]],"ltp":1.4,"tv":177.97,"id":72922097}]}]}
{"op":"mcm","clk":"11895836017","pt":1724336491842,"mc":[{"id":"1.232129550","rc":[{"batb":[[0,1.34,10]],"ltp":1.4,"tv":175.72,"id":72857114},{"batb":[[0,1.27,10]],"ltp":1.4,"tv":177.97,"id":72922097}]}]}
{"op":"mcm","clk":"11895836081","pt":1724336492869,"mc":[{"id":"1.232129550","rc":[{"batb":[[0,1.26,384.62],[1,1.25,98.46],[2,1.22,26.06]],"ltp":1.4,"tv":177.97,"id":72922097}]}]}
{"op":"mcm","clk":"11895836204","pt":1724336494777,"mc":[{"id":"1.232129550","rc":[{"batb":[[0,1.35,4],[1,1.34,10],[2,1.33,25.84]],"ltp":1.4,"tv":175.72,"id":72857114},{"batb":[[0,1.27,4],[1,1.26,384.62],[2,1.25,98.46]],"ltp":1.4,"tv":177.97,"id":72922097}]}]}
{"op":"mcm","clk":"11895836248","pt":1724336495243,"mc":[{"id":"1.232129550","rc":[{"batb":[[1,1.33,25.84],[2,1.32,319.39]],"ltp":1.4,"tv":175.72,"id":72857114},{"batb":[[0,1.28,10],[1,1.27,4],[2,1.26,384.62]],"ltp":1.4,"tv":177.97,"id":72922097}]}]}
{"op":"mcm","clk":"11895836383","pt":1724336496937,"mc":[{"id":"1.232129550","rc":[{"batb":[[0,1.33,25.84],[1,1.32,319.39],[2,1.3,15]],"ltp":1.4,"tv":175.72,"id":72857114},{"batb":[[1,1.26,384.62],[2,1.25,98.46]],"ltp":1.4,"tv":177.97,"id":72922097}]}]}
{"op":"mcm","clk":"11895836491","pt":1724336498662,"mc":[{"id":"1.232129550","rc":[{"batb":[[0,1.34,10],[1,1.33,25.84],[2,1.32,319.39]],"ltp":1.4,"tv":175.72,"id":72857114},{"batb":[[0,1.26,384.62],[1,1.25,98.46],[2,1.22,26.06]],"ltp":1.4,"tv":177.97,"id":72922097}]}]}
{"op":"mcm","clk":"11895836758","pt":1724336501958,"mc":[{"id":"1.232129550","rc":[{"batb":[[0,1.35,4]],"ltp":1.4,"tv":175.72,"id":72857114},{"batb":[[0,1.27,14],[1,1.26,384.62],[2,1.25,98.46]],"ltp":1.4,"tv":177.97,"id":72922097}]}]}
{"op":"mcm","clk":"11895836929","pt":1724336504483,"mc":[{"id":"1.232129550","rc":[{"batb":[[0,1.34,10]],"ltp":1.4,"tv":175.72,"id":72857114},{"batb":[[0,1.27,10]],"ltp":1.4,"tv":177.97,"id":72922097}]}]}
{"op":"mcm","clk":"11895836967","pt":1724336505152,"mc":[{"id":"1.232129550","rc":[{"batb":[[0,1.26,384.62],[1,1.25,98.46],[2,1.22,26.06]],"ltp":1.4,"tv":177.97,"id":72922097}]}]}
{"op":"mcm","clk":"11895837170","pt":1724336507896,"mc":[{"id":"1.232129550","rc":[{"batb":[[0,1.34,4]],"ltp":1.4,"tv":175.72,"id":72857114},{"batb":[[0,1.27,14],[1,1.26,384.62],[2,1.25,98.46]],"ltp":1.4,"tv":177.97,"id":72922097}]}]}
{"op":"mcm","clk":"11895837331","pt":1724336510386,"mc":[{"id":"1.232129550","rc":[{"batb":[[0,1.34,10]],"ltp":1.4,"tv":175.72,"id":72857114},{"batb":[[0,1.27,10]],"ltp":1.4,"tv":177.97,"id":72922097}]}]}
{"op":"mcm","clk":"11895837387","pt":1724336511158,"mc":[{"id":"1.232129550","rc":[{"batb":[[0,1.26,384.62],[1,1.25,98.46],[2,1.22,26.06]],"ltp":1.4,"tv":177.97,"id":72922097}]}]}
{"op":"mcm","clk":"11895837535","pt":1724336513882,"mc":[{"id":"1.232129550","rc":[{"batb":[[0,1.34,4]],"ltp":1.4,"tv":175.72,"id":72857114},{"batb":[[0,1.27,14],[1,1.26,384.62],[2,1.25,98.46]],"ltp":1.4,"tv":177.97,"id":72922097}]}]}
{"op":"mcm","clk":"11895837691","pt":1724336516354,"mc":[{"id":"1.232129550","rc":[{"batb":[[0,1.34,10]],"ltp":1.4,"tv":175.72,"id":72857114},{"batb":[[0,1.27,10]],"ltp":1.4,"tv":177.97,"id":72922097}]}]}
{"op":"mcm","clk":"11895837746","pt":1724336517176,"mc":[{"id":"1.232129550","rc":[{"batb":[[0,1.26,384.62],[1,1.25,98.46],[2,1.22,26.06]],"ltp":1.4,"tv":177.97,"id":72922097}]}]}
{"op":"mcm","clk":"11895837920","pt":1724336519756,"mc":[{"id":"1.232129550","rc":[{"batb":[[0,1.34,4]],"ltp":1.4,"tv":175.72,"id":72857114},{"batb":[[0,1.27,14],[1,1.26,384.62],[2,1.25,98.46]],"ltp":1.4,"tv":177.97,"id":72922097}]}]}
{"op":"mcm","clk":"11895838091","pt":1724336522186,"mc":[{"id":"1.232129550","rc":[{"batb":[[0,1.34,10]],"ltp":1.4,"tv":175.72,"id":72857114},{"batb":[[0,1.27,10]],"ltp":1.4,"tv":177.97,"id":72922097}]}]}
{"op":"mcm","clk":"11895838160","pt":1724336523164,"mc":[{"id":"1.232129550","rc":[{"batb":[[0,1.26,384.62],[1,1.25,98.46],[2,1.22,26.06]],"ltp":1.4,"tv":177.97,"id":72922097}]}]}
{"op":"mcm","clk":"11895838308","pt":1724336525574,"mc":[{"id":"1.232129550","rc":[{"batb":[[0,1.34,4]],"ltp":1.4,"tv":175.72,"id":72857114},{"batb":[[0,1.27,14],[1,1.26,384.62],[2,1.25,98.46]],"ltp":1.4,"tv":177.97,"id":72922097}]}]}
{"op":"mcm","clk":"11895838446","pt":1724336527788,"mc":[{"id":"1.232129550","rc":[{"batb":[[0,1.33,25.84],[1,1.32,319.39],[2,1.3,15]],"ltp":1.4,"tv":175.72,"id":72857114},{"batb":[[0,1.27,10]],"ltp":1.4,"tv":177.97,"id":72922097}]}]}
{"op":"mcm","clk":"11895838461","pt":1724336527994,"mc":[{"id":"1.232129550","rc":[{"batb":[[0,1.34,10],[1,1.33,25.84],[2,1.32,319.39]],"ltp":1.4,"tv":175.72,"id":72857114}]}]}
{"op":"mcm","clk":"11895838526","pt":1724336528972,"mc":[{"id":"1.232129550","rc":[{"batb":[[0,1.26,384.62],[1,1.25,98.46],[2,1.22,26.06]],"ltp":1.4,"tv":177.97,"id":72922097}]}]}
{"op":"mcm","clk":"11895838703","pt":1724336531519,"mc":[{"id":"1.232129550","rc":[{"batb":[[0,1.34,4]],"ltp":1.4,"tv":175.72,"id":72857114},{"batb":[[0,1.27,14],[1,1.26,384.62],[2,1.25,98.46]],"ltp":1.4,"tv":177.97,"id":72922097}]}]}
{"op":"mcm","clk":"11895838853","pt":1724336533896,"mc":[{"id":"1.232129550","rc":[{"batb":[[0,1.34,10]],"ltp":1.4,"tv":175.72,"id":72857114},{"batb":[[0,1.27,10]],"ltp":1.4,"tv":177.97,"id":72922097}]}]}
{"op":"mcm","clk":"11895838922","pt":1724336534874,"mc":[{"id":"1.232129550","rc":[{"batb":[[0,1.26,384.62],[1,1.25,98.46],[2,1.22,26.06]],"ltp":1.4,"tv":177.97,"id":72922097}]}]}
{"op":"mcm","clk":"11895839087","pt":1724336537085,"mc":[{"id":"1.232129550","rc":[{"batb":[[0,1.35,4]],"ltp":1.4,"tv":175.72,"id":72857114},{"batb":[[0,1.27,14],[1,1.26,384.62],[2,1.25,98.46]],"ltp":1.4,"tv":177.97,"id":72922097}]}]}
{"op":"mcm","clk":"11895839254","pt":1724336539709,"mc":[{"id":"1.232129550","rc":[{"batb":[[0,1.36,10]],"ltp":1.4,"tv":175.72,"id":72857114},{"batb":[[0,1.27,10]],"ltp":1.4,"tv":177.97,"id":72922097}]}]}
{"op":"mcm","clk":"11895839307","pt":1724336540484,"mc":[{"id":"1.232129550","rc":[{"batb":[[0,1.26,384.62],[1,1.25,98.46],[2,1.22,26.06]],"ltp":1.4,"tv":177.97,"id":72922097}]}]}
{"op":"mcm","clk":"11895839482","pt":1724336542903,"mc":[{"id":"1.232129550","rc":[{"batb":[[0,1.37,4]],"ltp":1.4,"tv":175.72,"id":72857114},{"batb":[[0,1.27,14],[1,1.26,384.62],[2,1.25,98.46]],"ltp":1.4,"tv":177.97,"id":72922097}]}]}
{"op":"mcm","clk":"11895839627","pt":1724336545322,"mc":[{"id":"1.232129550","rc":[{"batb":[[0,1.34,10]],"ltp":1.4,"tv":175.72,"id":72857114},{"batb":[[0,1.27,10]],"ltp":1.4,"tv":177.97,"id":72922097}]}]}
{"op":"mcm","clk":"11895839679","pt":1724336546094,"mc":[{"id":"1.232129550","rc":[{"batb":[[0,1.26,384.62],[1,1.25,98.46],[2,1.22,26.06]],"ltp":1.4,"tv":177.97,"id":72922097}]}]}
{"op":"mcm","clk":"11895839895","pt":1724336548831,"mc":[{"id":"1.232129550","rc":[{"batb":[[0,1.33,25.84],[1,1.32,319.39],[2,1.3,15]],"ltp":1.4,"tv":175.72,"id":72857114}]}]}
{"op":"mcm","clk":"11895839928","pt":1724336549295,"mc":[{"id":"1.232129550","rc":[{"batb":[[0,1.34,4],[1,1.33,25.84],[2,1.32,319.39]],"ltp":1.4,"tv":175.72,"id":72857114},{"batb":[[0,1.27,14],[1,1.26,384.62],[2,1.25,98.46]],"ltp":1.4,"tv":177.97,"id":72922097}]}]}
{"op":"mcm","clk":"11895840117","pt":1724336551718,"mc":[{"id":"1.232129550","rc":[{"batb":[[0,1.35,10]],"ltp":1.4,"tv":175.72,"id":72857114},{"batb":[[0,1.27,10]],"ltp":1.4,"tv":177.97,"id":72922097}]}]}
{"op":"mcm","clk":"11895840181","pt":1724336552822,"mc":[{"id":"1.232129550","rc":[{"batb":[[0,1.26,384.62],[1,1.25,98.46],[2,1.22,26.06]],"ltp":1.4,"tv":177.97,"id":72922097}]}]}
{"op":"mcm","clk":"11895840271","pt":1724336554322,"mc":[{"id":"1.232129550","rc":[{"batb":[[0,1.36,4],[1,1.35,10],[2,1.33,25.84]],"ltp":1.4,"tv":175.72,"id":72857114},{"batb":[[0,1.27,4],[1,1.26,384.62],[2,1.25,98.46]],"ltp":1.4,"tv":177.97,"id":72922097}]}]}
{"op":"mcm","clk":"11895840333","pt":1724336555245,"mc":[{"id":"1.232129550","rc":[{"batb":[[1,1.33,25.84],[2,1.32,319.39]],"ltp":1.4,"tv":175.72,"id":72857114},{"batb":[[0,1.28,10],[1,1.27,4],[2,1.26,384.62]],"ltp":1.4,"tv":177.97,"id":72922097}]}]}
{"op":"mcm","clk":"11895840430","pt":1724336556838,"mc":[{"id":"1.232129550","rc":[{"batb":[[0,1.33,25.84],[1,1.32,319.39],[2,1.3,15]],"ltp":1.4,"tv":175.72,"id":72857114},{"batb":[[1,1.26,384.62],[2,1.25,98.46]],"ltp":1.4,"tv":177.97,"id":72922097}]}]}
{"op":"mcm","clk":"11895840549","pt":1724336558747,"mc":[{"id":"1.232129550","rc":[{"batb":[[0,1.34,10],[1,1.33,25.84],[2,1.32,319.39]],"ltp":1.4,"tv":175.72,"id":72857114},{"batb":[[0,1.26,384.62],[1,1.25,98.46],[2,1.22,26.06]],"ltp":1.4,"tv":177.97,"id":72922097}]}]}
{"op":"mcm","clk":"11895840759","pt":1724336561957,"mc":[{"id":"1.232129550","rc":[{"batb":[[0,1.35,4]],"ltp":1.4,"tv":175.72,"id":72857114},{"batb":[[0,1.27,14],[1,1.26,384.62],[2,1.25,98.46]],"ltp":1.4,"tv":177.97,"id":72922097}]}]}
{"op":"mcm","clk":"11895840949","pt":1724336564334,"mc":[{"id":"1.232129550","rc":[{"batb":[[0,1.36,10]],"ltp":1.4,"tv":175.72,"id":72857114},{"batb":[[0,1.27,10]],"ltp":1.4,"tv":177.97,"id":72922097}]}]}
{"op":"mcm","clk":"11895841033","pt":1724336565217,"mc":[{"id":"1.232129550","rc":[{"batb":[[0,1.26,384.62],[1,1.25,98.46],[2,1.22,26.06]],"ltp":1.4,"tv":177.97,"id":72922097}]}]}
{"op":"mcm","clk":"11895841132","pt":1724336566663,"mc":[{"id":"1.232129550","rc":[{"batb":[[0,1.37,4],[1,1.36,10],[2,1.33,25.84]],"ltp":1.4,"tv":175.72,"id":72857114},{"batb":[[0,1.27,4],[1,1.26,384.62],[2,1.25,98.46]],"ltp":1.4,"tv":177.97,"id":72922097}]}]}
{"op":"mcm","clk":"11895841283","pt":1724336568826,"mc":[{"id":"1.232129550","rc":[{"batb":[[1,1.33,25.84],[2,1.32,319.39]],"ltp":1.4,"tv":175.72,"id":72857114}]}]}
{"op":"mcm","clk":"11895841295","pt":1724336569033,"mc":[{"id":"1.232129550","rc":[{"batb":[[0,1.33,25.84],[1,1.32,319.39],[2,1.3,15]],"ltp":1.4,"tv":175.72,"id":72857114},{"batb":[[0,1.28,10]],"ltp":1.4,"tv":177.97,"id":72922097}]}]}
{"op":"mcm","clk":"11895841536","pt":1724336572599,"mc":[{"id":"1.232129550","rc":[{"batb":[[0,1.34,14],[1,1.33,25.84],[2,1.32,319.39]],"ltp":1.4,"tv":175.72,"id":72857114},{"batb":[[0,1.27,4]],"ltp":1.4,"tv":177.97,"id":72922097}]}]}
{"op":"mcm","clk":"11895841716","pt":1724336574814,"mc":[{"id":"1.232129550","rc":[{"batb":[[0,1.28,10],[1,1.27,4],[2,1.26,384.62]],"ltp":1.4,"tv":177.97,"id":72922097}]}]}
{"op":"mcm","clk":"11895841800","pt":1724336575896,"mc":[{"id":"1.232129550","rc":[{"batb":[[0,1.33,25.84],[1,1.32,319.39],[2,1.3,15]],"ltp":1.4,"tv":175.72,"id":72857114},{"batb":[[1,1.26,384.62],[2,1.25,98.46]],"ltp":1.4,"tv":177.97,"id":72922097}]}]}
{"op":"mcm","clk":"11895841993","pt":1724336578334,"mc":[{"id":"1.232129550","rc":[{"batb":[[0,1.34,14],[1,1.33,25.84],[2,1.32,319.39]],"ltp":1.4,"tv":175.72,"id":72857114},{"batb":[[0,1.27,4]],"ltp":1.4,"tv":177.97,"id":72922097}]}]}
{"op":"mcm","clk":"11895842137","pt":1724336580702,"mc":[{"id":"1.232129550","rc":[{"batb":[[0,1.34,10]],"ltp":1.4,"tv":175.72,"id":72857114},{"batb":[[0,1.27,10]],"ltp":1.4,"tv":177.97,"id":72922097}]}]}
{"op":"mcm","clk":"11895842209","pt":1724336581649,"mc":[{"id":"1.232129550","rc":[{"batb":[[0,1.33,25.84],[1,1.32,319.39],[2,1.3,15]],"ltp":1.4,"tv":175.72,"id":72857114}]}]}
{"op":"mcm","clk":"11895842299","pt":1724336582831,"mc":[{"id":"1.232129550","rc":[{"batb":[[0,1.34,4],[1,1.33,25.84],[2,1.32,319.39]],"ltp":1.4,"tv":175.72,"id":72857114},{"batb":[[0,1.28,4],[1,1.27,10],[2,1.26,384.62]],"ltp":1.4,"tv":177.97,"id":72922097}]}]}
{"op":"mcm","clk":"11895842400","pt":1724336584333,"mc":[{"id":"1.232129550","rc":[{"batb":[[0,1.35,10],[1,1.34,4],[2,1.33,25.84]],"ltp":1.4,"tv":175.72,"id":72857114},{"batb":[[1,1.26,384.62],[2,1.25,98.46]],"ltp":1.4,"tv":177.97,"id":72922097}]}]}
{"op":"mcm","clk":"11895842480","pt":1724336585306,"mc":[{"id":"1.232129550","rc":[{"batb":[[1,1.33,25.84],[2,1.32,319.39]],"ltp":1.4,"tv":175.72,"id":72857114},{"batb":[[0,1.26,384.62],[1,1.25,98.46],[2,1.22,26.06]],"ltp":1.4,"tv":177.97,"id":72922097}]}]}
{"op":"mcm","clk":"11895842659","pt":1724336587724,"mc":[{"id":"1.232129550","rc":[{"batb":[[0,1.33,25.84],[1,1.32,319.39],[2,1.3,15]],"ltp":1.4,"tv":175.72,"id":72857114}]}]}
{"op":"mcm","clk":"11895842685","pt":1724336588037,"mc":[{"id":"1.232129550","rc":[{"batb":[[0,1.34,4],[1,1.33,25.84],[2,1.32,319.39]],"ltp":1.4,"tv":175.72,"id":72857114},{"batb":[[0,1.27,14],[1,1.26,384.62],[2,1.25,98.46]],"ltp":1.4,"tv":177.97,"id":72922097}]}]}
{"op":"mcm","clk":"11895842859","pt":1724336590611,"mc":[{"id":"1.232129550","rc":[{"batb":[[0,1.34,10]],"ltp":1.4,"tv":175.72,"id":72857114},{"batb":[[0,1.27,10]],"ltp":1.4,"tv":177.97,"id":72922097}]}]}
{"op":"mcm","clk":"11895842923","pt":1724336591332,"mc":[{"id":"1.232129550","rc":[{"batb":[[0,1.26,384.62],[1,1.25,98.46],[2,1.22,26.06]],"ltp":1.4,"tv":177.97,"id":72922097}]}]}
{"op":"mcm","clk":"11895843109","pt":1724336593918,"mc":[{"id":"1.232129550","rc":[{"batb":[[0,1.33,25.84],[1,1.32,319.39],[2,1.3,15]],"ltp":1.4,"tv":175.72,"id":72857114}]}]}
{"op":"mcm","clk":"11895843128","pt":1724336594132,"mc":[{"id":"1.232129550","rc":[{"batb":[[0,1.34,4],[1,1.33,25.84],[2,1.32,319.39]],"ltp":1.4,"tv":175.72,"id":72857114},{"batb":[[0,1.27,14],[1,1.26,384.62],[2,1.25,98.46]],"ltp":1.4,"tv":177.97,"id":72922097}]}]}
{"op":"mcm","clk":"11895843288","pt":1724336596751,"mc":[{"id":"1.232129550","rc":[{"batb":[[0,1.34,10]],"ltp":1.4,"tv":175.72,"id":72857114},{"batb":[[0,1.27,10]],"ltp":1.4,"tv":177.97,"id":72922097}]}]}
{"op":"mcm","clk":"11895843338","pt":1724336597541,"mc":[{"id":"1.232129550","rc":[{"batb":[[0,1.26,384.62],[1,1.25,98.46],[2,1.22,26.06]],"ltp":1.4,"tv":177.97,"id":72922097}]}]}
{"op":"mcm","clk":"11895843503","pt":1724336599955,"mc":[{"id":"1.232129550","rc":[{"batb":[[0,1.33,25.84],[1,1.32,319.39],[2,1.3,15]],"ltp":1.4,"tv":175.72,"id":72857114}]}]}
{"op":"mcm","clk":"11895843510","pt":1724336600051,"mc":[{"id":"1.232129550","rc":[{"batb":[[0,1.34,4],[1,1.33,25.84],[2,1.32,319.39]],"ltp":1.4,"tv":175.72,"id":72857114},{"batb":[[0,1.27,14],[1,1.26,384.62],[2,1.25,98.46]],"ltp":1.4,"tv":177.97,"id":72922097}]}]}
{"op":"mcm","clk":"11895843679","pt":1724336602529,"mc":[{"id":"1.232129550","rc":[{"batb":[[0,1.34,10]],"ltp":1.4,"tv":175.72,"id":72857114},{"batb":[[0,1.27,10]],"ltp":1.4,"tv":177.97,"id":72922097}]}]}
{"op":"mcm","clk":"11895843744","pt":1724336603360,"mc":[{"id":"1.232129550","rc":[{"batb":[[0,1.26,384.62],[1,1.25,98.46],[2,1.22,26.06]],"ltp":1.4,"tv":177.97,"id":72922097}]}]}
{"op":"mcm","clk":"11895843820","pt":1724336604638,"mc":[{"id":"1.232129550","rc":[{"batb":[[0,1.35,4],[1,1.34,10],[2,1.33,25.84]],"ltp":1.4,"tv":175.72,"id":72857114},{"batb":[[0,1.27,4],[1,1.26,384.62],[2,1.25,98.46]],"ltp":1.4,"tv":177.97,"id":72922097}]}]}
{"op":"mcm","clk":"11895843916","pt":1724336605933,"mc":[{"id":"1.232129550","rc":[{"batb":[[1,1.33,25.84],[2,1.32,319.39]],"ltp":1.4,"tv":175.72,"id":72857114}]}]}
{"op":"mcm","clk":"11895843924","pt":1724336606034,"mc":[{"id":"1.232129550","rc":[{"batb":[[0,1.28,10],[1,1.27,4],[2,1.26,384.62]],"ltp":1.4,"tv":177.97,"id":72922097}]}]}
{"op":"mcm","clk":"11895843979","pt":1724336607062,"mc":[{"id":"1.232129550","rc":[{"batb":[[0,1.33,25.84],[1,1.32,319.39],[2,1.3,15]],"ltp":1.4,"tv":175.72,"id":72857114},{"batb":[[1,1.26,384.62],[2,1.25,98.46]],"ltp":1.4,"tv":177.97,"id":72922097}]}]}
{"op":"mcm","clk":"11895844164","pt":1724336609756,"mc":[{"id":"1.232129550","rc":[{"batb":[[0,1.34,14],[1,1.33,25.84],[2,1.32,319.39]],"ltp":1.4,"tv":175.72,"id":72857114},{"batb":[[0,1.27,4]],"ltp":1.4,"tv":177.97,"id":72922097}]}]}
{"op":"mcm","clk":"11895844335","pt":1724336611934,"mc":[{"id":"1.232129550","rc":[{"batb":[[0,1.34,10]],"ltp":1.4,"tv":175.72,"id":72857114},{"batb":[[0,1.26,384.62],[1,1.25,98.46],[2,1.22,26.06]],"ltp":1.4,"tv":177.97,"id":72922097}]}]}
{"op":"mcm","clk":"11895844342","pt":1724336612039,"mc":[{"id":"1.232129550","rc":[{"batb":[[0,1.27,10],[1,1.26,384.62],[2,1.25,98.46]],"ltp":1.4,"tv":177.97,"id":72922097}]}]}
{"op":"mcm","clk":"11895844415","pt":1724336613181,"mc":[{"id":"1.232129550","rc":[{"batb":[[0,1.33,25.84],[1,1.32,319.39],[2,1.3,15]],"ltp":1.4,"tv":175.72,"id":72857114}]}]}
{"op":"mcm","clk":"11895844561","pt":1724336615355,"mc":[{"id":"1.232129550","rc":[{"batb":[[0,1.26,384.62],[1,1.25,98.46],[2,1.22,26.06]],"ltp":1.4,"tv":177.97,"id":72922097}]}]}
{"op":"mcm","clk":"11895859717","pt":1724336838655,"mc":[{"id":"1.232129550","rc":[{"batb":[[0,1.34,6.89],[1,1.33,25.84],[2,1.32,312.5]],"ltp":1.4,"tv":175.72,"id":72857114},{"batb":[[0,1.27,6.21],[1,1.26,384.62],[2,1.25,98.46]],"ltp":1.4,"tv":177.97,"id":72922097}]}]}
{"op":"mcm","clk":"11895889093","pt":1724337266155,"mc":[{"id":"1.232129550","rc":[{"batb":[[2,1.22,19.85]],"ltp":1.4,"tv":177.97,"id":72922097}]}]}
{"op":"mcm","clk":"11895966674","pt":1724338214292,"mc":[{"id":"1.232129550","rc":[{"batb":[[1,1.32,312.5],[2,1.3,15]],"ltp":1.4,"tv":175.72,"id":72857114}]}]}
{"op":"mcm","clk":"11895976896","pt":1724338349753,"mc":[{"id":"1.232129550","rc":[{"batb":[[0,1.35,24.37],[1,1.34,6.89],[2,1.32,312.5]],"ltp":1.4,"tv":175.72,"id":72857114}]}]}
{"op":"mcm","clk":"11896078942","pt":1724339499922,"mc":[{"id":"1.232129550","rc":[{"trd":[[1.4,175.67]],"batb":[[0,1.35,24.36],[1,1.32,312.5],[2,1.3,15]],"ltp":1.4,"tv":175.67,"id":72857114},{"trd":[[1.4,175.67]],"batb":[[0,1.27,6.2]],"ltp":1.4,"tv":177.92,"id":72922097}],"tv":353.6}]}
{"op":"mcm","clk":"11896078951","pt":1724339500025,"mc":[{"id":"1.232129550","rc":[{"batb":[[1,1.33,6.89],[2,1.32,312.5]],"ltp":1.4,"tv":175.67,"id":72857114}]}]}
{"op":"mcm","clk":"11896135988","pt":1724340149927,"mc":[{"id":"1.232129550","rc":[{"batb":[[0,1.33,6.89],[1,1.32,312.5],[2,1.3,15]],"ltp":1.4,"tv":175.67,"id":72857114}]}]}
{"op":"mcm","clk":"11896146394","pt":1724340279182,"mc":[{"id":"1.232129550","rc":[{"batb":[[0,1.34,25.08],[1,1.33,6.89],[2,1.32,312.5]],"ltp":1.4,"tv":175.67,"id":72857114}]}]}
{"op":"mcm","clk":"11896201084","pt":1724340917010,"mc":[{"id":"1.232129550","rc":[{"batb":[[2,1.3,15]],"ltp":1.4,"tv":175.67,"id":72857114},{"batb":[[1,1.22,19.85],[2,1.21,82.79]],"ltp":1.4,"tv":177.92,"id":72922097}]}]}
{"op":"mcm","clk":"11896204386","pt":1724340954424,"mc":[{"id":"1.232129550","rc":[{"batb":[[0,1.27,1117.31]],"ltp":1.4,"tv":177.92,"id":72922097}]}]}
{"op":"mcm","clk":"11896204617","pt":1724340957016,"mc":[{"id":"1.232129550","rc":[{"batb":[[0,1.34,907.43]],"ltp":1.4,"tv":175.67,"id":72857114}]}]}
{"op":"mcm","clk":"11896287901","pt":1724341898312,"mc":[{"id":"1.232129550","rc":[{"batb":[[0,1.28,14],[1,1.27,1117.31],[2,1.22,19.85]],"batl":[[0,3.9,15.12]],"ltp":1.4,"tv":177.92,"id":72922097}]}]}
{"op":"mcm","clk":"11896288150","pt":1724341900611,"mc":[{"id":"1.232129550","rc":[{"batb":[[0,1.28,10]],"ltp":1.4,"tv":177.92,"id":72922097}]}]}
{"op":"mcm","clk":"11896288249","pt":1724341901598,"mc":[{"id":"1.232129550","rc":[{"batb":[[0,1.27,1117.31],[1,1.22,19.85],[2,1.21,82.79]],"ltp":1.4,"tv":177.92,"id":72922097}]}]}
{"op":"mcm","clk":"11896293496","pt":1724341960865,"mc":[{"id":"1.232129550","rc":[{"batb":[[0,1.28,14],[1,1.27,1117.31],[2,1.22,19.85]],"ltp":1.4,"tv":177.92,"id":72922097}]}]}
{"op":"mcm","clk":"11896293684","pt":1724341963337,"mc":[{"id":"1.232129550","rc":[{"batb":[[0,1.28,10]],"ltp":1.4,"tv":177.92,"id":72922097}]}]}
{"op":"mcm","clk":"11896293767","pt":1724341964426,"mc":[{"id":"1.232129550","rc":[{"batb":[[0,1.27,1117.31],[1,1.22,19.85],[2,1.21,82.79]],"ltp":1.4,"tv":177.92,"id":72922097}]}]}
{"op":"mcm","clk":"11896293910","pt":1724341966149,"mc":[{"id":"1.232129550","rc":[{"batb":[[0,1.28,4],[1,1.27,1117.31],[2,1.22,19.85]],"ltp":1.4,"tv":177.92,"id":72922097}]}]}
{"op":"mcm","clk":"11896294119","pt":1724341968849,"mc":[{"id":"1.232129550","rc":[{"batb":[[0,1.28,10]],"ltp":1.4,"tv":177.92,"id":72922097}]}]}
{"op":"mcm","clk":"11896294383","pt":1724341972363,"mc":[{"id":"1.232129550","rc":[{"batb":[[0,1.28,4]],"ltp":1.4,"tv":177.92,"id":72922097}]}]}
{"op":"mcm","clk":"11896294563","pt":1724341974967,"mc":[{"id":"1.232129550","rc":[{"batb":[[0,1.28,10]],"ltp":1.4,"tv":177.92,"id":72922097}]}]}
{"op":"mcm","clk":"11896294838","pt":1724341978475,"mc":[{"id":"1.232129550","rc":[{"batb":[[0,1.28,4]],"ltp":1.4,"tv":177.92,"id":72922097}]}]}
{"op":"mcm","clk":"11896295108","pt":1724341981383,"mc":[{"id":"1.232129550","rc":[{"batb":[[0,1.28,10]],"ltp":1.4,"tv":177.92,"id":72922097}]}]}
{"op":"mcm","clk":"11896295438","pt":1724341984770,"mc":[{"id":"1.232129550","rc":[{"batb":[[0,1.28,4]],"ltp":1.4,"tv":177.92,"id":72922097}]}]}
{"op":"mcm","clk":"11896295704","pt":1724341987450,"mc":[{"id":"1.232129550","rc":[{"batb":[[0,1.28,10]],"ltp":1.4,"tv":177.92,"id":72922097}]}]}
{"op":"mcm","clk":"11896296019","pt":1724341990950,"mc":[{"id":"1.232129550","rc":[{"batb":[[0,1.28,4]],"ltp":1.4,"tv":177.92,"id":72922097}]}]}
{"op":"mcm","clk":"11896296229","pt":1724341993491,"mc":[{"id":"1.232129550","rc":[{"batb":[[0,1.28,10]],"ltp":1.4,"tv":177.92,"id":72922097}]}]}
{"op":"mcm","clk":"11896296726","pt":1724341998756,"mc":[{"id":"1.232129550","rc":[{"batb":[[0,1.29,4]],"ltp":1.4,"tv":177.92,"id":72922097}]}]}
{"op":"mcm","clk":"11896296963","pt":1724342001559,"mc":[{"id":"1.232129550","rc":[{"batb":[[0,1.28,10]],"ltp":1.4,"tv":177.92,"id":72922097}]}]}
{"op":"mcm","clk":"11896297276","pt":1724342004962,"mc":[{"id":"1.232129550","rc":[{"batb":[[0,1.27,1117.31],[1,1.22,19.85],[2,1.21,82.79]],"ltp":1.4,"tv":177.92,"id":72922097}]}]}
{"op":"mcm","clk":"11896297297","pt":1724342005168,"mc":[{"id":"1.232129550","rc":[{"batb":[[0,1.28,4],[1,1.27,1117.31],[2,1.22,19.85]],"ltp":1.4,"tv":177.92,"id":72922097}]}]}
{"op":"mcm","clk":"11896297523","pt":1724342007608,"mc":[{"id":"1.232129550","rc":[{"batb":[[0,1.29,10]],"ltp":1.4,"tv":177.92,"id":72922097}]}]}
{"op":"mcm","clk":"11896297795","pt":1724342011200,"mc":[{"id":"1.232129550","rc":[{"batb":[[0,1.28,4]],"ltp":1.4,"tv":177.92,"id":72922097}]}]}
{"op":"mcm","clk":"11896297990","pt":1724342013694,"mc":[{"id":"1.232129550","rc":[{"batb":[[0,1.28,10]],"ltp":1.4,"tv":177.92,"id":72922097}]}]}
{"op":"mcm","clk":"11896298302","pt":1724342017113,"mc":[{"id":"1.232129550","rc":[{"batb":[[0,1.28,4]],"ltp":1.4,"tv":177.92,"id":72922097}]}]}
{"op":"mcm","clk":"11896298526","pt":1724342019608,"mc":[{"id":"1.232129550","rc":[{"batb":[[0,1.28,10]],"ltp":1.4,"tv":177.92,"id":72922097}]}]}
{"op":"mcm","clk":"11896298810","pt":1724342022829,"mc":[{"id":"1.232129550","rc":[{"batb":[[0,1.29,4]],"ltp":1.4,"tv":177.92,"id":72922097}]}]}
{"op":"mcm","clk":"11896298985","pt":1724342024802,"mc":[{"id":"1.232129550","rc":[{"batb":[[0,1.27,1117.31],[1,1.22,19.85],[2,1.21,82.79]],"ltp":1.4,"tv":177.92,"id":72922097}]}]}
{"op":"mcm","clk":"11896299003","pt":1724342025008,"mc":[{"id":"1.232129550","rc":[{"batb":[[0,1.28,10],[1,1.27,1117.31],[2,1.22,19.85]],"ltp":1.4,"tv":177.92,"id":72922097}]}]}
{"op":"mcm","clk":"11896299264","pt":1724342028434,"mc":[{"id":"1.232129550","rc":[{"batb":[[0,1.28,4]],"ltp":1.4,"tv":177.92,"id":72922097}]}]}
{"op":"mcm","clk":"11896299474","pt":1724342030899,"mc":[{"id":"1.232129550","rc":[{"batb":[[0,1.28,10]],"ltp":1.4,"tv":177.92,"id":72922097}]}]}
{"op":"mcm","clk":"11896299771","pt":1724342034320,"mc":[{"id":"1.232129550","rc":[{"batb":[[0,1.28,4]],"ltp":1.4,"tv":177.92,"id":72922097}]}]}
{"op":"mcm","clk":"11896300014","pt":1724342036809,"mc":[{"id":"1.232129550","rc":[{"batb":[[0,1.28,10]],"ltp":1.4,"tv":177.92,"id":72922097}]}]}
{"op":"mcm","clk":"11896300327","pt":1724342040338,"mc":[{"id":"1.232129550","rc":[{"batb":[[0,1.28,4]],"ltp":1.4,"tv":177.92,"id":72922097}]}]}
{"op":"mcm","clk":"11896300518","pt":1724342042757,"mc":[{"id":"1.232129550","rc":[{"batb":[[0,1.27,1117.31],[1,1.22,19.85],[2,1.21,82.79]],"ltp":1.4,"tv":177.92,"id":72922097}]}]}
{"op":"mcm","clk":"11896300549","pt":1724342043050,"mc":[{"id":"1.232129550","rc":[{"batb":[[0,1.28,10],[1,1.27,1117.31],[2,1.22,19.85]],"ltp":1.4,"tv":177.92,"id":72922097}]}]}
{"op":"mcm","clk":"11896300841","pt":1724342046544,"mc":[{"id":"1.232129550","rc":[{"batb":[[0,1.28,4]],"ltp":1.4,"tv":177.92,"id":72922097}]}]}
{"op":"mcm","clk":"11896301033","pt":1724342048785,"mc":[{"id":"1.232129550","rc":[{"batb":[[0,1.27,1117.31],[1,1.22,19.85],[2,1.21,82.79]],"ltp":1.4,"tv":177.92,"id":72922097}]}]}
{"op":"mcm","clk":"11896301064","pt":1724342049048,"mc":[{"id":"1.232129550","rc":[{"batb":[[0,1.28,10],[1,1.27,1117.31],[2,1.22,19.85]],"ltp":1.4,"tv":177.92,"id":72922097}]}]}
{"op":"mcm","clk":"11896301387","pt":1724342052611,"mc":[{"id":"1.232129550","rc":[{"batb":[[0,1.28,4]],"ltp":1.4,"tv":177.92,"id":72922097}]}]}
{"op":"mcm","clk":"11896301650","pt":1724342054960,"mc":[{"id":"1.232129550","rc":[{"batb":[[0,1.28,10]],"ltp":1.4,"tv":177.92,"id":72922097}]}]}
{"op":"mcm","clk":"11896301954","pt":1724342058543,"mc":[{"id":"1.232129550","rc":[{"batb":[[0,1.28,4]],"ltp":1.4,"tv":177.92,"id":72922097}]}]}
{"op":"mcm","clk":"11896302199","pt":1724342061182,"mc":[{"id":"1.232129550","rc":[{"batb":[[0,1.28,10]],"ltp":1.4,"tv":177.92,"id":72922097}]}]}
{"op":"mcm","clk":"11896302503","pt":1724342064566,"mc":[{"id":"1.232129550","rc":[{"batb":[[0,1.28,4]],"ltp":1.4,"tv":177.92,"id":72922097}]}]}
{"op":"mcm","clk":"11896302772","pt":1724342066898,"mc":[{"id":"1.232129550","rc":[{"batb":[[0,1.27,1117.31],[1,1.22,19.85],[2,1.21,82.79]],"ltp":1.4,"tv":177.92,"id":72922097}]}]}
{"op":"mcm","clk":"11896302802","pt":1724342067072,"mc":[{"id":"1.232129550","rc":[{"batb":[[0,1.28,10],[1,1.27,1117.31],[2,1.22,19.85]],"ltp":1.4,"tv":177.92,"id":72922097}]}]}
{"op":"mcm","clk":"11896303213","pt":1724342070796,"mc":[{"id":"1.232129550","rc":[{"batb":[[0,1.28,4]],"ltp":1.4,"tv":177.92,"id":72922097}]}]}
{"op":"mcm","clk":"11896303641","pt":1724342073507,"mc":[{"id":"1.232129550","rc":[{"batb":[[0,1.28,10]],"ltp":1.4,"tv":177.92,"id":72922097}]}]}
{"op":"mcm","clk":"11896303966","pt":1724342076881,"mc":[{"id":"1.232129550","rc":[{"batb":[[0,1.27,1117.31],[1,1.22,19.85],[2,1.21,82.79]],"ltp":1.4,"tv":177.92,"id":72922097}]}]}
{"op":"mcm","clk":"11896303985","pt":1724342077083,"mc":[{"id":"1.232129550","rc":[{"batb":[[0,1.28,4],[1,1.27,1117.31],[2,1.22,19.85]],"ltp":1.4,"tv":177.92,"id":72922097}]}]}
{"op":"mcm","clk":"11896304237","pt":1724342079504,"mc":[{"id":"1.232129550","rc":[{"batb":[[0,1.34,882.35]],"ltp":1.4,"tv":175.67,"id":72857114},{"batb":[[0,1.29,10]],"ltp":1.4,"tv":177.92,"id":72922097}]}]}
{"op":"mcm","clk":"11896304554","pt":1724342082796,"mc":[{"id":"1.232129550","rc":[{"batb":[[0,1.28,4]],"ltp":1.4,"tv":177.92,"id":72922097}]}]}
{"op":"mcm","clk":"11896304775","pt":1724342085285,"mc":[{"id":"1.232129550","rc":[{"batb":[[0,1.28,10]],"ltp":1.4,"tv":177.92,"id":72922097}]}]}
{"op":"mcm","clk":"11896305068","pt":1724342088616,"mc":[{"id":"1.232129550","rc":[{"batb":[[0,1.28,4]],"ltp":1.4,"tv":177.92,"id":72922097}]}]}
{"op":"mcm","clk":"11896305282","pt":1724342090919,"mc":[{"id":"1.232129550","rc":[{"batb":[[0,1.27,1117.31],[1,1.22,19.85],[2,1.21,82.79]],"ltp":1.4,"tv":177.92,"id":72922097}]}]}
{"op":"mcm","clk":"11896305312","pt":1724342091380,"mc":[{"id":"1.232129550","rc":[{"batb":[[0,1.28,10],[1,1.27,1117.31],[2,1.22,19.85]],"ltp":1.4,"tv":177.92,"id":72922097}]}]}
{"op":"mcm","clk":"11896305612","pt":1724342094927,"mc":[{"id":"1.232129550","rc":[{"batb":[[0,1.28,4]],"ltp":1.4,"tv":177.92,"id":72922097}]}]}
{"op":"mcm","clk":"11896305820","pt":1724342097414,"mc":[{"id":"1.232129550","rc":[{"batb":[[0,1.28,10]],"ltp":1.4,"tv":177.92,"id":72922097}]}]}
{"op":"mcm","clk":"11896306155","pt":1724342100697,"mc":[{"id":"1.232129550","rc":[{"batb":[[0,1.28,4]],"ltp":1.4,"tv":177.92,"id":72922097}]}]}
{"op":"mcm","clk":"11896306413","pt":1724342103401,"mc":[{"id":"1.232129550","rc":[{"batb":[[0,1.29,10]],"ltp":1.4,"tv":177.92,"id":72922097}]}]}
{"op":"mcm","clk":"11896306712","pt":1724342106696,"mc":[{"id":"1.232129550","rc":[{"batb":[[0,1.28,4]],"ltp":1.4,"tv":177.92,"id":72922097}]}]}
{"op":"mcm","clk":"11896306940","pt":1724342109313,"mc":[{"id":"1.232129550","rc":[{"batb":[[0,1.28,10]],"ltp":1.4,"tv":177.92,"id":72922097}]}]}
{"op":"mcm","clk":"11896307280","pt":1724342112916,"mc":[{"id":"1.232129550","rc":[{"batb":[[0,1.28,4]],"ltp":1.4,"tv":177.92,"id":72922097}]}]}
{"op":"mcm","clk":"11896307523","pt":1724342115515,"mc":[{"id":"1.232129550","rc":[{"batb":[[0,1.28,10]],"ltp":1.4,"tv":177.92,"id":72922097}]}]}
{"op":"mcm","clk":"11896307805","pt":1724342118851,"mc":[{"id":"1.232129550","rc":[{"batb":[[0,1.28,4]],"ltp":1.4,"tv":177.92,"id":72922097}]}]}
{"op":"mcm","clk":"11896308038","pt":1724342121258,"mc":[{"id":"1.232129550","rc":[{"batb":[[0,1.28,10]],"ltp":1.4,"tv":177.92,"id":72922097}]}]}
{"op":"mcm","clk":"11896308380","pt":1724342124824,"mc":[{"id":"1.232129550","rc":[{"batb":[[0,1.28,4]],"ltp":1.4,"tv":177.92,"id":72922097}]}]}
{"op":"mcm","clk":"11896308610","pt":1724342127366,"mc":[{"id":"1.232129550","rc":[{"batb":[[0,1.28,10]],"ltp":1.4,"tv":177.92,"id":72922097}]}]}
{"op":"mcm","clk":"11896308922","pt":1724342130945,"mc":[{"id":"1.232129550","rc":[{"batb":[[0,1.28,4]],"ltp":1.4,"tv":177.92,"id":72922097}]}]}
{"op":"mcm","clk":"11896309152","pt":1724342133566,"mc":[{"id":"1.232129550","rc":[{"batb":[[0,1.28,10]],"ltp":1.4,"tv":177.92,"id":72922097}]}]}
{"op":"mcm","clk":"11896309438","pt":1724342136849,"mc":[{"id":"1.232129550","rc":[{"batb":[[0,1.27,1117.31],[1,1.22,19.85],[2,1.21,82.79]],"ltp":1.4,"tv":177.92,"id":72922097}]}]}
{"op":"mcm","clk":"11896309455","pt":1724342137074,"mc":[{"id":"1.232129550","rc":[{"batb":[[0,1.28,4],[1,1.27,1117.31],[2,1.22,19.85]],"ltp":1.4,"tv":177.92,"id":72922097}]}]}
{"op":"mcm","clk":"11896309666","pt":1724342139575,"mc":[{"id":"1.232129550","rc":[{"batb":[[0,1.28,10]],"ltp":1.4,"tv":177.92,"id":72922097}]}]}
{"op":"mcm","clk":"11896309979","pt":1724342143147,"mc":[{"id":"1.232129550","rc":[{"batb":[[0,1.28,4]],"ltp":1.4,"tv":177.92,"id":72922097}]}]}
{"op":"mcm","clk":"11896310176","pt":1724342145465,"mc":[{"id":"1.232129550","rc":[{"batb":[[0,1.28,10]],"ltp":1.4,"tv":177.92,"id":72922097}]}]}
{"op":"mcm","clk":"11896310483","pt":1724342148794,"mc":[{"id":"1.232129550","rc":[{"batb":[[0,1.29,4]],"ltp":1.4,"tv":177.92,"id":72922097}]}]}
{"op":"mcm","clk":"11896310684","pt":1724342150776,"mc":[{"id":"1.232129550","rc":[{"batb":[[0,1.27,1117.31],[1,1.22,19.85],[2,1.21,82.79]],"ltp":1.4,"tv":177.92,"id":72922097}]}]}
{"op":"mcm","clk":"11896310725","pt":1724342151197,"mc":[{"id":"1.232129550","rc":[{"batb":[[0,1.28,10],[1,1.27,1117.31],[2,1.22,19.85]],"ltp":1.4,"tv":177.92,"id":72922097}]}]}
{"op":"mcm","clk":"11896310934","pt":1724342153385,"mc":[{"id":"1.232129550","rc":[{"batb":[[0,1.29,4],[1,1.28,10],[2,1.27,1117.31]],"ltp":1.4,"tv":177.92,"id":72922097}]}]}
{"op":"mcm","clk":"11896311045","pt":1724342154373,"mc":[{"id":"1.232129550","rc":[{"batb":[[1,1.27,1117.31],[2,1.22,19.85]],"ltp":1.4,"tv":177.92,"id":72922097}]}]}
{"op":"mcm","clk":"11896311158","pt":1724342155666,"mc":[{"id":"1.232129550","rc":[{"batb":[[0,1.27,1117.31],[1,1.22,19.85],[2,1.21,82.79]],"ltp":1.4,"tv":177.92,"id":72922097}]}]}
{"op":"mcm","clk":"11896311800","pt":1724342163982,"mc":[{"id":"1.232129550","rc":[{"batb":[[0,1.28,14],[1,1.27,1117.31],[2,1.22,19.85]],"ltp":1.4,"tv":177.92,"id":72922097}]}]}
{"op":"mcm","clk":"11896311986","pt":1724342166565,"mc":[{"id":"1.232129550","rc":[{"batb":[[0,1.28,10]],"ltp":1.4,"tv":177.92,"id":72922097}]}]}
{"op":"mcm","clk":"11896312087","pt":1724342167616,"mc":[{"id":"1.232129550","rc":[{"batb":[[0,1.27,1117.31],[1,1.22,19.85],[2,1.21,82.79]],"ltp":1.4,"tv":177.92,"id":72922097}]}]}
{"op":"mcm","clk":"11896312855","pt":1724342175924,"mc":[{"id":"1.232129550","rc":[{"batb":[[0,1.28,14],[1,1.27,1117.31],[2,1.22,19.85]],"ltp":1.4,"tv":177.92,"id":72922097}]}]}
{"op":"mcm","clk":"11896313030","pt":1724342178308,"mc":[{"id":"1.232129550","rc":[{"batb":[[0,1.28,10]],"ltp":1.4,"tv":177.92,"id":72922097}]}]}
{"op":"mcm","clk":"11896313118","pt":1724342179302,"mc":[{"id":"1.232129550","rc":[{"batb":[[0,1.27,1117.31],[1,1.22,19.85],[2,1.21,82.79]],"ltp":1.4,"tv":177.92,"id":72922097}]}]}
{"op":"mcm","clk":"11896314720","pt":1724342197319,"mc":[{"id":"1.232129550","rc":[{"batb":[[0,1.35,24.36],[1,1.34,882.35],[2,1.33,6.89]],"ltp":1.4,"tv":175.67,"id":72857114},{"batb":[[0,1.28,14],[1,1.27,1117.31],[2,1.22,19.85]],"ltp":1.4,"tv":177.92,"id":72922097}]}]}
{"op":"mcm","clk":"11896314985","pt":1724342199933,"mc":[{"id":"1.232129550","rc":[{"batb":[[0,1.28,10]],"ltp":1.4,"tv":177.92,"id":72922097}]}]}
{"op":"mcm","clk":"11896315068","pt":1724342200647,"mc":[{"id":"1.232129550","rc":[{"batb":[[0,1.27,1117.31],[1,1.22,19.85],[2,1.21,82.79]],"ltp":1.4,"tv":177.92,"id":72922097}]}]}
{"op":"mcm","clk":"11896315228","pt":1724342202150,"mc":[{"id":"1.232129550","rc":[{"batb":[[0,1.28,4],[1,1.27,1117.31],[2,1.22,19.85]],"ltp":1.4,"tv":177.92,"id":72922097}]}]}
{"op":"mcm","clk":"11896315465","pt":1724342204746,"mc":[{"id":"1.232129550","rc":[{"batb":[[0,1.28,10]],"ltp":1.4,"tv":177.92,"id":72922097}]}]}
{"op":"mcm","clk":"11896315650","pt":1724342207035,"mc":[{"id":"1.232129550","rc":[{"batb":[[0,1.29,4],[1,1.28,10],[2,1.27,1117.31]],"ltp":1.4,"tv":177.92,"id":72922097}]}]}
{"op":"mcm","clk":"11896315741","pt":1724342208164,"mc":[{"id":"1.232129550","rc":[{"batb":[[1,1.27,1117.31],[2,1.22,19.85]],"ltp":1.4,"tv":177.92,"id":72922097}]}]}
{"op":"mcm","clk":"11896315855","pt":1724342209772,"mc":[{"id":"1.232129550","rc":[{"batb":[[0,1.3,98.46]],"ltp":1.4,"tv":177.92,"id":72922097}]}]}
{"op":"mcm","clk":"11896316016","pt":1724342211647,"mc":[{"id":"1.232129550","rc":[{"batb":[[0,1.32,4],[1,1.31,10],[2,1.3,98.46]],"ltp":1.4,"tv":177.92,"id":72922097}]}]}
{"op":"mcm","clk":"11896316308","pt":1724342214959,"mc":[{"id":"1.232129550","rc":[{"batb":[[0,1.3,98.46],[1,1.27,1117.31],[2,1.22,19.85]],"ltp":1.4,"tv":177.92,"id":72922097}]}]}
{"op":"mcm","clk":"11896316636","pt":1724342218348,"mc":[{"id":"1.232129550","rc":[{"batb":[[0,1.31,14],[1,1.3,98.46],[2,1.27,1117.31]],"ltp":1.4,"tv":177.92,"id":72922097}]}]}
{"op":"mcm","clk":"11896316851","pt":1724342220753,"mc":[{"id":"1.232129550","rc":[{"batb":[[0,1.31,10]],"ltp":1.4,"tv":177.92,"id":72922097}]}]}
{"op":"mcm","clk":"11896316944","pt":1724342221851,"mc":[{"id":"1.232129550","rc":[{"batb":[[0,1.3,98.46],[1,1.27,1117.31],[2,1.22,19.85]],"ltp":1.4,"tv":177.92,"id":72922097}]}]}
{"op":"mcm","clk":"11896317446","pt":1724342227245,"mc":[{"id":"1.232129550","rc":[{"batb":[[0,1.31,14],[1,1.3,98.46],[2,1.27,1117.31]],"ltp":1.4,"tv":177.92,"id":72922097}]}]}
{"op":"mcm","clk":"11896317699","pt":1724342229580,"mc":[{"id":"1.232129550","rc":[{"batb":[[0,1.31,10]],"ltp":1.4,"tv":177.92,"id":72922097}]}]}
{"op":"mcm","clk":"11896317827","pt":1724342230877,"mc":[{"id":"1.232129550","rc":[{"batb":[[0,1.3,98.46],[1,1.27,1117.31],[2,1.22,19.85]],"ltp":1.4,"tv":177.92,"id":72922097}]}]}
{"op":"mcm","clk":"11896318489","pt":1724342238157,"mc":[{"id":"1.232129550","rc":[{"batb":[[0,1.31,14],[1,1.3,98.46],[2,1.27,1117.31]],"ltp":1.4,"tv":177.92,"id":72922097}]}]}
{"op":"mcm","clk":"11896318729","pt":1724342240866,"mc":[{"id":"1.232129550","rc":[{"batb":[[0,1.31,10]],"ltp":1.4,"tv":177.92,"id":72922097}]}]}
{"op":"mcm","clk":"11896318810","pt":1724342241785,"mc":[{"id":"1.232129550","rc":[{"batb":[[0,1.3,98.46],[1,1.27,1117.31],[2,1.22,19.85]],"ltp":1.4,"tv":177.92,"id":72922097}]}]}
{"op":"mcm","clk":"11896319322","pt":1724342247177,"mc":[{"id":"1.232129550","rc":[{"batb":[[0,1.31,14],[1,1.3,98.46],[2,1.27,1117.31]],"ltp":1.4,"tv":177.92,"id":72922097}]}]}
{"op":"mcm","clk":"11896319544","pt":1724342249701,"mc":[{"id":"1.232129550","rc":[{"batb":[[0,1.31,10]],"ltp":1.4,"tv":177.92,"id":72922097}]}]}
{"op":"mcm","clk":"11896319633","pt":1724342250693,"mc":[{"id":"1.232129550","rc":[{"batb":[[0,1.3,98.46],[1,1.27,1117.31],[2,1.22,19.85]],"ltp":1.4,"tv":177.92,"id":72922097}]}]}
{"op":"mcm","clk":"11896320704","pt":1724342262516,"mc":[{"id":"1.232129550","rc":[{"batb":[[0,1.31,14],[1,1.3,98.46],[2,1.27,1117.31]],"ltp":1.4,"tv":177.92,"id":72922097}]}]}
{"op":"mcm","clk":"11896320912","pt":1724342264913,"mc":[{"id":"1.232129550","rc":[{"batb":[[0,1.31,10]],"ltp":1.4,"tv":177.92,"id":72922097}]}]}
{"op":"mcm","clk":"11896321000","pt":1724342265999,"mc":[{"id":"1.232129550","rc":[{"batb":[[0,1.3,98.46],[1,1.27,1117.31],[2,1.22,19.85]],"ltp":1.4,"tv":177.92,"id":72922097}]}]}
{"op":"mcm","clk":"11896321298","pt":1724342269220,"mc":[{"id":"1.232129550","rc":[{"batb":[[0,1.31,14],[1,1.3,98.46],[2,1.27,1117.31]],"ltp":1.4,"tv":177.92,"id":72922097}]}]}
{"op":"mcm","clk":"11896321530","pt":1724342271915,"mc":[{"id":"1.232129550","rc":[{"batb":[[0,1.31,10]],"ltp":1.4,"tv":177.92,"id":72922097}]}]}
{"op":"mcm","clk":"11896321597","pt":1724342272716,"mc":[{"id":"1.232129550","rc":[{"batb":[[0,1.3,98.46],[1,1.27,1117.31],[2,1.22,19.85]],"ltp":1.4,"tv":177.92,"id":72922097}]}]}
{"op":"mcm","clk":"11896321933","pt":1724342276812,"mc":[{"id":"1.232129550","rc":[{"batb":[[0,1.31,14],[1,1.3,98.46],[2,1.27,1117.31]],"ltp":1.4,"tv":177.92,"id":72922097}]}]}
{"op":"mcm","clk":"11896322149","pt":1724342279447,"mc":[{"id":"1.232129550","rc":[{"batb":[[0,1.31,10]],"ltp":1.4,"tv":177.92,"id":72922097}]}]}
{"op":"mcm","clk":"11896322229","pt":1724342280435,"mc":[{"id":"1.232129550","rc":[{"batb":[[0,1.3,98.46],[1,1.27,1117.31],[2,1.22,19.85]],"ltp":1.4,"tv":177.92,"id":72922097}]}]}
{"op":"mcm","clk":"11896322422","pt":1724342282638,"mc":[{"id":"1.232129550","rc":[{"batb":[[0,1.31,14],[1,1.3,98.46],[2,1.27,1117.31]],"ltp":1.4,"tv":177.92,"id":72922097}]}]}
{"op":"mcm","clk":"11896322607","pt":1724342285242,"mc":[{"id":"1.232129550","rc":[{"batb":[[0,1.31,10]],"ltp":1.4,"tv":177.92,"id":72922097}]}]}
{"op":"mcm","clk":"11896322696","pt":1724342286138,"mc":[{"id":"1.232129550","rc":[{"batb":[[0,1.3,98.46],[1,1.27,1117.31],[2,1.22,19.85]],"ltp":1.4,"tv":177.92,"id":72922097}]}]}
{"op":"mcm","clk":"11896322922","pt":1724342288938,"mc":[{"id":"1.232129550","rc":[{"batb":[[0,1.31,14],[1,1.3,98.46],[2,1.27,1117.31]],"ltp":1.4,"tv":177.92,"id":72922097}]}]}
{"op":"mcm","clk":"11896323125","pt":1724342291331,"mc":[{"id":"1.232129550","rc":[{"batb":[[0,1.31,10]],"ltp":1.4,"tv":177.92,"id":72922097}]}]}
{"op":"mcm","clk":"11896323211","pt":1724342292263,"mc":[{"id":"1.232129550","rc":[{"batb":[[0,1.3,98.46],[1,1.27,1117.31],[2,1.22,19.85]],"ltp":1.4,"tv":177.92,"id":72922097}]}]}
{"op":"mcm","clk":"11896323494","pt":1724342295962,"mc":[{"id":"1.232129550","rc":[{"batb":[[0,1.31,14],[1,1.3,98.46],[2,1.27,1117.31]],"ltp":1.4,"tv":177.92,"id":72922097}]}]}
{"op":"mcm","clk":"11896323725","pt":1724342298765,"mc":[{"id":"1.232129550","rc":[{"batb":[[0,1.31,10]],"ltp":1.4,"tv":177.92,"id":72922097}]}]}
{"op":"mcm","clk":"11896323808","pt":1724342299757,"mc":[{"id":"1.232129550","rc":[{"batb":[[0,1.3,98.46],[1,1.27,1117.31],[2,1.22,19.85]],"ltp":1.4,"tv":177.92,"id":72922097}]}]}
{"op":"mcm","clk":"11896324323","pt":1724342306260,"mc":[{"id":"1.232129550","rc":[{"batb":[[0,1.31,14],[1,1.3,98.46],[2,1.27,1117.31]],"ltp":1.4,"tv":177.92,"id":72922097}]}]}
{"op":"mcm","clk":"11896324520","pt":1724342308760,"mc":[{"id":"1.232129550","rc":[{"batb":[[0,1.31,10]],"ltp":1.4,"tv":177.92,"id":72922097}]}]}
{"op":"mcm","clk":"11896324586","pt":1724342309649,"mc":[{"id":"1.232129550","rc":[{"batb":[[0,1.3,98.46],[1,1.27,1117.31],[2,1.22,19.85]],"ltp":1.4,"tv":177.92,"id":72922097}]}]}
{"op":"mcm","clk":"11896324790","pt":1724342312368,"mc":[{"id":"1.232129550","rc":[{"batb":[[0,1.31,14],[1,1.3,98.46],[2,1.27,1117.31]],"ltp":1.4,"tv":177.92,"id":72922097}]}]}
{"op":"mcm","clk":"11896324976","pt":1724342314869,"mc":[{"id":"1.232129550","rc":[{"batb":[[0,1.31,10]],"ltp":1.4,"tv":177.92,"id":72922097}]}]}
{"op":"mcm","clk":"11896325057","pt":1724342315858,"mc":[{"id":"1.232129550","rc":[{"batb":[[0,1.3,98.46],[1,1.27,1117.31],[2,1.22,19.85]],"ltp":1.4,"tv":177.92,"id":72922097}]}]}
{"op":"mcm","clk":"11896325170","pt":1724342317371,"mc":[{"id":"1.232129550","rc":[{"batb":[[0,1.31,4],[1,1.3,98.46],[2,1.27,1117.31]],"ltp":1.4,"tv":177.92,"id":72922097}]}]}
{"op":"mcm","clk":"11896325383","pt":1724342319876,"mc":[{"id":"1.232129550","rc":[{"batb":[[0,1.3,98.46],[1,1.27,1117.31],[2,1.22,19.85]],"ltp":1.4,"tv":177.92,"id":72922097}]}]}
{"op":"mcm","clk":"11896325410","pt":1724342320087,"mc":[{"id":"1.232129550","rc":[{"batb":[[0,1.31,10],[1,1.3,98.46],[2,1.27,1117.31]],"ltp":1.4,"tv":177.92,"id":72922097}]}]}
{"op":"mcm","clk":"11896325769","pt":1724342323871,"mc":[{"id":"1.232129550","rc":[{"batb":[[0,1.31,4]],"ltp":1.4,"tv":177.92,"id":72922097}]}]}
{"op":"mcm","clk":"11896325955","pt":1724342326484,"mc":[{"id":"1.232129550","rc":[{"batb":[[0,1.31,10]],"ltp":1.4,"tv":177.92,"id":72922097}]}]}
{"op":"mcm","clk":"11896326210","pt":1724342329878,"mc":[{"id":"1.232129550","rc":[{"batb":[[0,1.3,98.46],[1,1.27,1117.31],[2,1.22,19.85]],"ltp":1.4,"tv":177.92,"id":72922097}]}]}
{"op":"mcm","clk":"11896326218","pt":1724342329992,"mc":[{"id":"1.232129550","rc":[{"batb":[[0,1.31,4],[1,1.3,98.46],[2,1.27,1117.31]],"ltp":1.4,"tv":177.92,"id":72922097}]}]}
{"op":"mcm","clk":"11896326432","pt":1724342332393,"mc":[{"id":"1.232129550","rc":[{"batb":[[0,1.31,10]],"ltp":1.4,"tv":177.92,"id":72922097}]}]}
{"op":"mcm","clk":"11896326717","pt":1724342335816,"mc":[{"id":"1.232129550","rc":[{"batb":[[0,1.31,4]],"ltp":1.4,"tv":177.92,"id":72922097}]}]}
{"op":"mcm","clk":"11896326896","pt":1724342338316,"mc":[{"id":"1.232129550","rc":[{"batb":[[0,1.31,10]],"ltp":1.4,"tv":177.92,"id":72922097}]}]}
{"op":"mcm","clk":"11896327156","pt":1724342341696,"mc":[{"id":"1.232129550","rc":[{"batb":[[0,1.3,98.46],[1,1.27,1117.31],[2,1.22,19.85]],"ltp":1.4,"tv":177.92,"id":72922097}]}]}
{"op":"mcm","clk":"11896327183","pt":1724342342021,"mc":[{"id":"1.232129550","rc":[{"batb":[[0,1.31,4],[1,1.3,98.46],[2,1.27,1117.31]],"ltp":1.4,"tv":177.92,"id":72922097}]}]}
{"op":"mcm","clk":"11896327365","pt":1724342344527,"mc":[{"id":"1.232129550","rc":[{"batb":[[0,1.31,10]],"ltp":1.4,"tv":177.92,"id":72922097}]}]}
{"op":"mcm","clk":"11896327631","pt":1724342347903,"mc":[{"id":"1.232129550","rc":[{"batb":[[0,1.3,98.46],[1,1.27,1117.31],[2,1.22,19.85]],"ltp":1.4,"tv":177.92,"id":72922097}]}]}
{"op":"mcm","clk":"11896327647","pt":1724342348115,"mc":[{"id":"1.232129550","rc":[{"batb":[[0,1.31,4],[1,1.3,98.46],[2,1.27,1117.31]],"ltp":1.4,"tv":177.92,"id":72922097}]}]}
{"op":"mcm","clk":"11896327860","pt":1724342350617,"mc":[{"id":"1.232129550","rc":[{"batb":[[0,1.31,10]],"ltp":1.4,"tv":177.92,"id":72922097}]}]}
{"op":"mcm","clk":"11896328149","pt":1724342353912,"mc":[{"id":"1.232129550","rc":[{"batb":[[0,1.3,98.46],[1,1.27,1117.31],[2,1.22,19.85]],"ltp":1.4,"tv":177.92,"id":72922097}]}]}
{"op":"mcm","clk":"11896328161","pt":1724342354017,"mc":[{"id":"1.232129550","rc":[{"batb":[[0,1.31,4],[1,1.3,98.46],[2,1.27,1117.31]],"ltp":1.4,"tv":177.92,"id":72922097}]}]}
{"op":"mcm","clk":"11896328354","pt":1724342356627,"mc":[{"id":"1.232129550","rc":[{"batb":[[0,1.32,10]],"ltp":1.4,"tv":177.92,"id":72922097}]}]}
{"op":"mcm","clk":"11896328645","pt":1724342360228,"mc":[{"id":"1.232129550","rc":[{"batb":[[0,1.31,4]],"ltp":1.4,"tv":177.92,"id":72922097}]}]}
{"op":"mcm","clk":"11896328881","pt":1724342362642,"mc":[{"id":"1.232129550","rc":[{"batb":[[0,1.31,10]],"ltp":1.4,"tv":177.92,"id":72922097}]}]}
{"op":"mcm","clk":"11896329101","pt":1724342364953,"mc":[{"id":"1.232129550","rc":[{"batb":[[0,1.35,31.25],[2,1.3,15]],"ltp":1.4,"tv":175.67,"id":72857114},{"batb":[[0,1.32,4],[1,1.31,16.2],[2,1.3,98.46]],"ltp":1.4,"tv":177.92,"id":72922097}]}]}
{"op":"mcm","clk":"11896329292","pt":1724342366826,"mc":[{"id":"1.232129550","rc":[{"batb":[[0,1.31,6.2],[1,1.3,98.46],[2,1.27,1111.11]],"ltp":1.4,"tv":177.92,"id":72922097}]}]}
{"op":"mcm","clk":"11896330370","pt":1724342379869,"mc":[{"id":"1.232129550","rc":[{"batb":[[0,1.32,14],[1,1.31,6.2],[2,1.3,98.46]],"ltp":1.4,"tv":177.92,"id":72922097}]}]}
{"op":"mcm","clk":"11896330607","pt":1724342382554,"mc":[{"id":"1.232129550","rc":[{"batb":[[0,1.32,10]],"ltp":1.4,"tv":177.92,"id":72922097}]}]}
{"op":"mcm","clk":"11896330674","pt":1724342383366,"mc":[{"id":"1.232129550","rc":[{"batb":[[0,1.31,6.2],[1,1.3,98.46],[2,1.27,1111.11]],"ltp":1.4,"tv":177.92,"id":72922097}]}]}
{"op":"mcm","clk":"11896330824","pt":1724342385144,"mc":[{"id":"1.232129550","rc":[{"batb":[[0,1.32,4],[1,1.31,6.2],[2,1.3,98.46]],"ltp":1.4,"tv":177.92,"id":72922097}]}]}
{"op":"mcm","clk":"11896331043","pt":1724342387855,"mc":[{"id":"1.232129550","rc":[{"batb":[[0,1.32,10]],"ltp":1.4,"tv":177.92,"id":72922097}]}]}
{"op":"mcm","clk":"11896331309","pt":1724342391243,"mc":[{"id":"1.232129550","rc":[{"batb":[[0,1.32,4]],"ltp":1.4,"tv":177.92,"id":72922097}]}]}
{"op":"mcm","clk":"11896331527","pt":1724342393748,"mc":[{"id":"1.232129550","rc":[{"batb":[[0,1.32,10]],"ltp":1.4,"tv":177.92,"id":72922097}]}]}
{"op":"mcm","clk":"11896331849","pt":1724342397473,"mc":[{"id":"1.232129550","rc":[{"batb":[[0,1.32,4]],"ltp":1.4,"tv":177.92,"id":72922097}]}]}
{"op":"mcm","clk":"11896332057","pt":1724342399864,"mc":[{"id":"1.232129550","rc":[{"batb":[[0,1.31,6.2],[1,1.3,98.46],[2,1.27,1111.11]],"ltp":1.4,"tv":177.92,"id":72922097}]}]}
{"op":"mcm","clk":"11896332070","pt":1724342399979,"mc":[{"id":"1.232129550","rc":[{"batb":[[0,1.32,10],[1,1.31,6.2],[2,1.3,98.46]],"ltp":1.4,"tv":177.92,"id":72922097}]}]}
{"op":"mcm","clk":"11896332471","pt":1724342403387,"mc":[{"id":"1.232129550","rc":[{"trd":[[1.4,175.84]],"batb":[[0,1.35,31.27]],"ltp":1.4,"tv":175.83,"id":72857114},{"trd":[[1.06,1.96],[1.4,175.84]],"batb":[[0,1.33,4],[1,1.31,6.21]],"batl":[[0,3.9,15.12]],"ltp":1.4,"tv":178.08,"id":72922097}],"tv":353.92}]}
{"op":"mcm","clk":"11896332736","pt":1724342405871,"mc":[{"id":"1.232129550","rc":[{"batb":[[0,1.32,10]],"ltp":1.4,"tv":178.08,"id":72922097}]}]}
{"op":"mcm","clk":"11896333084","pt":1724342409703,"mc":[{"id":"1.232129550","rc":[{"batb":[[0,1.33,4],[2,1.27,1111.11]],"ltp":1.4,"tv":178.08,"id":72922097}]}]}
{"op":"mcm","clk":"11896333240","pt":1724342411494,"mc":[{"id":"1.232129550","rc":[{"batb":[[0,1.32,10]],"ltp":1.4,"tv":178.08,"id":72922097}]}]}
{"op":"mcm","clk":"11896333434","pt":1724342413586,"mc":[{"id":"1.232129550","rc":[{"batb":[[0,1.33,4],[1,1.32,10],[2,1.31,6.21]],"ltp":1.4,"tv":178.08,"id":72922097}]}]}
{"op":"mcm","clk":"11896333554","pt":1724342414783,"mc":[{"id":"1.232129550","rc":[{"batb":[[1,1.31,6.21],[2,1.27,1111.11]],"ltp":1.4,"tv":178.08,"id":72922097}]}]}
{"op":"mcm","clk":"11896333688","pt":1724342416094,"mc":[{"id":"1.232129550","rc":[{"batb":[[0,1.31,6.21],[1,1.27,1111.11],[2,1.22,19.85]],"ltp":1.4,"tv":178.08,"id":72922097}]}]}
{"op":"mcm","clk":"11896334530","pt":1724342425372,"mc":[{"id":"1.232129550","rc":[{"batb":[[0,1.32,14],[1,1.31,6.21],[2,1.27,1111.11]],"ltp":1.4,"tv":178.08,"id":72922097}]}]}
{"op":"mcm","clk":"11896334852","pt":1724342428811,"mc":[{"id":"1.232129550","rc":[{"batb":[[0,1.31,6.21],[1,1.27,1111.11],[2,1.22,19.85]],"ltp":1.4,"tv":178.08,"id":72922097}]}]}
{"op":"mcm","clk":"11896335235","pt":1724342432803,"mc":[{"id":"1.232129550","rc":[{"batb":[[0,1.32,14],[1,1.31,6.21],[2,1.27,1111.11]],"ltp":1.4,"tv":178.08,"id":72922097}]}]}
{"op":"mcm","clk":"11896335307","pt":1724342433618,"mc":[{"id":"1.232129550","rc":[{"batl":[[0,3.5,98.46],[1,3.9,15.12]],"ltp":1.4,"tv":178.08,"id":72922097}]}]}
{"op":"mcm","clk":"11896335406","pt":1724342434716,"mc":[{"id":"1.232129550","rc":[{"batl":[[1,3.9,0]],"ltp":1.4,"tv":178.08,"id":72922097}]}]}
{"op":"mcm","clk":"11896335467","pt":1724342435300,"mc":[{"id":"1.232129550","rc":[{"batb":[[0,1.32,10]],"ltp":1.4,"tv":178.08,"id":72922097}]}]}
{"op":"mcm","clk":"11896335572","pt":1724342436326,"mc":[{"id":"1.232129550","rc":[{"batb":[[0,1.31,6.21],[1,1.27,1111.11],[2,1.22,19.85]],"ltp":1.4,"tv":178.08,"id":72922097}]}]}
{"op":"mcm","clk":"11896335733","pt":1724342438024,"mc":[{"id":"1.232129550","rc":[{"batb":[[0,1.32,4],[1,1.31,6.21],[2,1.27,1111.11]],"ltp":1.4,"tv":178.08,"id":72922097}]}]}
{"op":"mcm","clk":"11896335879","pt":1724342439224,"mc":[{"id":"1.232129550","rc":[{"batb":[[0,1.33,10],[1,1.32,4],[2,1.31,6.21]],"ltp":1.4,"tv":178.08,"id":72922097}]}]}
{"op":"mcm","clk":"11896336030","pt":1724342440631,"mc":[{"id":"1.232129550","rc":[{"batb":[[1,1.31,6.21],[2,1.27,1111.11]],"ltp":1.4,"tv":178.08,"id":72922097}]}]}
{"op":"mcm","clk":"11896336237","pt":1724342442822,"mc":[{"id":"1.232129550","rc":[{"batb":[[0,1.32,4]],"ltp":1.4,"tv":178.08,"id":72922097}]}]}
{"op":"mcm","clk":"11896336482","pt":1724342445408,"mc":[{"id":"1.232129550","rc":[{"batb":[[0,1.36,14],[1,1.35,31.27],[2,1.34,882.35]],"batl":[[0,3.5,98.46]],"ltp":1.4,"tv":175.83,"id":72857114},{"batb":[[0,1.33,10]],"ltp":1.4,"tv":178.08,"id":72922097}]}]}
{"op":"mcm","clk":"11896336708","pt":1724342447719,"mc":[{"id":"1.232129550","rc":[{"batb":[[0,1.36,10]],"ltp":1.4,"tv":175.83,"id":72857114},{"batb":[[0,1.34,4],[1,1.33,10],[2,1.31,6.21]],"ltp":1.4,"tv":178.08,"id":72922097}]}]}
{"op":"mcm","clk":"11896336782","pt":1724342448542,"mc":[{"id":"1.232129550","rc":[{"batb":[[0,1.35,31.27],[1,1.34,882.35],[2,1.3,15]],"ltp":1.4,"tv":175.83,"id":72857114},{"batb":[[1,1.31,6.21],[2,1.27,1111.11]],"ltp":1.4,"tv":178.08,"id":72922097}]}]}
{"op":"mcm","clk":"11896336995","pt":1724342450228,"mc":[{"id":"1.232129550","rc":[{"batb":[[0,1.36,4],[1,1.35,31.27],[2,1.34,882.35]],"ltp":1.4,"tv":175.83,"id":72857114},{"batb":[[0,1.31,6.21],[1,1.27,1111.11],[2,1.22,19.85]],"ltp":1.4,"tv":178.08,"id":72922097}]}]}
{"op":"mcm","clk":"11896337223","pt":1724342452845,"mc":[{"id":"1.232129550","rc":[{"batb":[[0,1.36,10]],"ltp":1.4,"tv":175.83,"id":72857114},{"batb":[[0,1.32,14],[1,1.31,6.21],[2,1.27,1111.11]],"ltp":1.4,"tv":178.08,"id":72922097}]}]}
{"op":"mcm","clk":"11896337466","pt":1724342455319,"mc":[{"id":"1.232129550","rc":[{"batb":[[0,1.37,4],[1,1.36,10],[2,1.35,31.27]],"ltp":1.4,"tv":175.83,"id":72857114},{"batb":[[0,1.32,10]],"ltp":1.4,"tv":178.08,"id":72922097}]}]}
{"op":"mcm","clk":"11896337541","pt":1724342456147,"mc":[{"id":"1.232129550","rc":[{"batb":[[1,1.35,31.27],[2,1.34,882.35]],"ltp":1.4,"tv":175.83,"id":72857114},{"batb":[[0,1.31,6.21],[1,1.27,1111.11],[2,1.22,19.85]],"ltp":1.4,"tv":178.08,"id":72922097}]}]}
{"op":"mcm","clk":"11896337684","pt":1724342457709,"mc":[{"id":"1.232129550","rc":[{"batb":[[0,1.35,31.27],[1,1.34,882.35],[2,1.3,15]],"ltp":1.4,"tv":175.83,"id":72857114},{"batb":[[0,1.32,4],[1,1.31,6.21],[2,1.27,1111.11]],"ltp":1.4,"tv":178.08,"id":72922097}]}]}
{"op":"mcm","clk":"11896337942","pt":1724342460219,"mc":[{"id":"1.232129550","rc":[{"batb":[[0,1.36,14],[1,1.35,31.27],[2,1.34,882.35]],"ltp":1.4,"tv":175.83,"id":72857114},{"batb":[[0,1.32,10]],"ltp":1.4,"tv":178.08,"id":72922097}]}]}
{"op":"mcm","clk":"11896338157","pt":1724342462635,"mc":[{"id":"1.232129550","rc":[{"batb":[[0,1.36,10]],"ltp":1.4,"tv":175.83,"id":72857114},{"batb":[[0,1.33,4],[1,1.32,10],[2,1.31,6.21]],"ltp":1.4,"tv":178.08,"id":72922097}]}]}
{"op":"mcm","clk":"11896338235","pt":1724342463564,"mc":[{"id":"1.232129550","rc":[{"batb":[[0,1.35,31.27],[1,1.34,882.35],[2,1.3,15]],"ltp":1.4,"tv":175.83,"id":72857114},{"batb":[[1,1.31,6.21],[2,1.27,1111.11]],"ltp":1.4,"tv":178.08,"id":72922097}]}]}
{"op":"mcm","clk":"11896338387","pt":1724342464869,"mc":[{"id":"1.232129550","rc":[{"batb":[[0,1.31,6.21],[1,1.27,1111.11],[2,1.22,19.85]],"ltp":1.4,"tv":178.08,"id":72922097}]}]}
{"op":"mcm","clk":"11896338405","pt":1724342465019,"mc":[{"id":"1.232129550","rc":[{"batb":[[0,1.36,4],[1,1.35,31.27],[2,1.34,882.35]],"ltp":1.4,"tv":175.83,"id":72857114}]}]}
{"op":"mcm","clk":"11896338579","pt":1724342466947,"mc":[{"id":"1.232129550","rc":[{"batb":[[0,1.37,10],[1,1.36,4],[2,1.35,31.27]],"ltp":1.4,"tv":175.83,"id":72857114},{"batb":[[0,1.32,10],[1,1.31,6.21],[2,1.27,1111.11]],"ltp":1.4,"tv":178.08,"id":72922097}]}]}
{"op":"mcm","clk":"11896338621","pt":1724342467365,"mc":[{"id":"1.232129550","rc":[{"batb":[[1,1.35,31.27],[2,1.34,882.35]],"ltp":1.4,"tv":175.83,"id":72857114},{"batb":[[0,1.33,4],[1,1.32,10],[2,1.31,6.21]],"ltp":1.4,"tv":178.08,"id":72922097}]}]}
{"op":"mcm","clk":"11896338850","pt":1724342469731,"mc":[{"id":"1.232129550","rc":[{"batb":[[0,1.38,4],[1,1.37,10],[2,1.35,31.27]],"ltp":1.4,"tv":175.83,"id":72857114},{"batb":[[0,1.32,10],[1,1.31,6.21],[2,1.27,1111.11]],"ltp":1.4,"tv":178.08,"id":72922097}]}]}
{"op":"mcm","clk":"11896338911","pt":1724342470354,"mc":[{"id":"1.232129550","rc":[{"batb":[[1,1.35,31.27],[2,1.34,882.35]],"ltp":1.4,"tv":175.83,"id":72857114},{"batb":[[0,1.31,6.21],[1,1.27,1111.11],[2,1.22,19.85]],"ltp":1.4,"tv":178.08,"id":72922097}]}]}
{"op":"mcm","clk":"11896339155","pt":1724342472544,"mc":[{"id":"1.232129550","rc":[{"batb":[[0,1.36,10]],"ltp":1.4,"tv":175.83,"id":72857114},{"batb":[[0,1.33,10],[1,1.32,4],[2,1.31,6.21]],"ltp":1.4,"tv":178.08,"id":72922097}]}]}
{"op":"mcm","clk":"11896339363","pt":1724342474857,"mc":[{"id":"1.232129550","rc":[{"batb":[[1,1.31,6.21],[2,1.27,1111.11]],"ltp":1.4,"tv":178.08,"id":72922097}]}]}
{"op":"mcm","clk":"11896339382","pt":1724342475062,"mc":[{"id":"1.232129550","rc":[{"batb":[[0,1.37,4],[1,1.36,10],[2,1.35,31.27]],"ltp":1.4,"tv":175.83,"id":72857114}]}]}
{"op":"mcm","clk":"11896339482","pt":1724342476054,"mc":[{"id":"1.232129550","rc":[{"batb":[[1,1.35,31.27],[2,1.34,882.35]],"ltp":1.4,"tv":175.83,"id":72857114},{"batb":[[0,1.31,6.21],[1,1.27,1111.11],[2,1.22,19.85]],"ltp":1.4,"tv":178.08,"id":72922097}]}]}
{"op":"mcm","clk":"11896339604","pt":1724342477457,"mc":[{"id":"1.232129550","rc":[{"batb":[[0,1.35,31.27],[1,1.34,882.35],[2,1.3,15]],"ltp":1.4,"tv":175.83,"id":72857114},{"batb":[[0,1.32,4],[1,1.31,6.21],[2,1.27,1111.11]],"ltp":1.4,"tv":178.08,"id":72922097}]}]}
{"op":"mcm","clk":"11896339856","pt":1724342479857,"mc":[{"id":"1.232129550","rc":[{"batb":[[0,1.36,14],[1,1.35,31.27],[2,1.34,882.35]],"ltp":1.4,"tv":175.83,"id":72857114},{"batb":[[0,1.32,10]],"ltp":1.4,"tv":178.08,"id":72922097}]}]}
{"op":"mcm","clk":"11896340146","pt":1724342482571,"mc":[{"id":"1.232129550","rc":[{"batb":[[0,1.36,10]],"ltp":1.4,"tv":175.83,"id":72857114},{"batb":[[0,1.33,4],[1,1.32,10],[2,1.31,6.21]],"ltp":1.4,"tv":178.08,"id":72922097}]}]}
{"op":"mcm","clk":"11896340204","pt":1724342483145,"mc":[{"id":"1.232129550","rc":[{"batb":[[0,1.35,31.27],[1,1.34,882.35],[2,1.3,15]],"ltp":1.4,"tv":175.83,"id":72857114},{"batb":[[1,1.31,6.21],[2,1.27,1111.11]],"ltp":1.4,"tv":178.08,"id":72922097}]}]}
{"op":"mcm","clk":"11896340386","pt":1724342484870,"mc":[{"id":"1.232129550","rc":[{"batb":[[0,1.31,6.21],[1,1.27,1111.11],[2,1.22,19.85]],"ltp":1.4,"tv":178.08,"id":72922097}]}]}
{"op":"mcm","clk":"11896340413","pt":1724342485080,"mc":[{"id":"1.232129550","rc":[{"batb":[[0,1.36,4],[1,1.35,31.27],[2,1.34,882.35]],"ltp":1.4,"tv":175.83,"id":72857114}]}]}
{"op":"mcm","clk":"11896340646","pt":1724342487572,"mc":[{"id":"1.232129550","rc":[{"batb":[[0,1.36,10]],"ltp":1.4,"tv":175.83,"id":72857114},{"batb":[[0,1.32,14],[1,1.31,6.21],[2,1.27,1111.11]],"ltp":1.4,"tv":178.08,"id":72922097}]}]}
{"op":"mcm","clk":"11896340885","pt":1724342489770,"mc":[{"id":"1.232129550","rc":[{"batb":[[0,1.32,10]],"ltp":1.4,"tv":178.08,"id":72922097}]}]}
{"op":"mcm","clk":"11896340903","pt":1724342489976,"mc":[{"id":"1.232129550","rc":[{"batb":[[0,1.37,4],[1,1.36,10],[2,1.35,31.27]],"ltp":1.4,"tv":175.83,"id":72857114}]}]}
{"op":"mcm","clk":"11896341011","pt":1724342490974,"mc":[{"id":"1.232129550","rc":[{"batb":[[1,1.35,31.27],[2,1.34,882.35]],"ltp":1.4,"tv":175.83,"id":72857114},{"batb":[[0,1.31,6.21],[1,1.27,1111.11],[2,1.22,19.85]],"ltp":1.4,"tv":178.08,"id":72922097}]}]}
{"op":"mcm","clk":"11896341183","pt":1724342492591,"mc":[{"id":"1.232129550","rc":[{"batb":[[0,1.35,31.27],[1,1.34,882.35],[2,1.3,15]],"ltp":1.4,"tv":175.83,"id":72857114},{"batb":[[0,1.32,4],[1,1.31,6.21],[2,1.27,1111.11]],"ltp":1.4,"tv":178.08,"id":72922097}]}]}
{"op":"mcm","clk":"11896341408","pt":1724342494948,"mc":[{"id":"1.232129550","rc":[{"batb":[[0,1.31,6.21],[1,1.27,1111.11],[2,1.22,19.85]],"ltp":1.4,"tv":178.08,"id":72922097}]}]}
{"op":"mcm","clk":"11896341426","pt":1724342495153,"mc":[{"id":"1.232129550","rc":[{"batb":[[0,1.36,14],[1,1.35,31.27],[2,1.34,882.35]],"ltp":1.4,"tv":175.83,"id":72857114},{"batb":[[0,1.32,10],[1,1.31,6.21],[2,1.27,1111.11]],"ltp":1.4,"tv":178.08,"id":72922097}]}]}
{"op":"mcm","clk":"11896341687","pt":1724342497767,"mc":[{"id":"1.232129550","rc":[{"batb":[[0,1.36,10]],"ltp":1.4,"tv":175.83,"id":72857114},{"batb":[[0,1.33,4],[1,1.32,10],[2,1.31,6.21]],"ltp":1.4,"tv":178.08,"id":72922097}]}]}
{"op":"mcm","clk":"11896341737","pt":1724342498384,"mc":[{"id":"1.232129550","rc":[{"batb":[[0,1.35,31.27],[1,1.34,882.35],[2,1.3,15]],"ltp":1.4,"tv":175.83,"id":72857114},{"batb":[[1,1.31,6.21],[2,1.27,1111.11]],"ltp":1.4,"tv":178.08,"id":72922097}]}]}
{"op":"mcm","clk":"11896341914","pt":1724342500280,"mc":[{"id":"1.232129550","rc":[{"batb":[[0,1.36,4],[1,1.35,31.27],[2,1.34,882.35]],"ltp":1.4,"tv":175.83,"id":72857114},{"batb":[[0,1.31,6.21],[1,1.27,1111.11],[2,1.22,19.85]],"ltp":1.4,"tv":178.08,"id":72922097}]}]}
{"op":"mcm","clk":"11896342140","pt":1724342502689,"mc":[{"id":"1.232129550","rc":[{"batb":[[0,1.36,10]],"ltp":1.4,"tv":175.83,"id":72857114},{"batb":[[0,1.32,14],[1,1.31,6.21],[2,1.27,1111.11]],"ltp":1.4,"tv":178.08,"id":72922097}]}]}
{"op":"mcm","clk":"11896342438","pt":1724342505157,"mc":[{"id":"1.232129550","rc":[{"batb":[[0,1.37,4],[1,1.36,10],[2,1.35,31.27]],"ltp":1.4,"tv":175.83,"id":72857114},{"batb":[[0,1.32,10]],"ltp":1.4,"tv":178.08,"id":72922097}]}]}
{"op":"mcm","clk":"11896342511","pt":1724342505991,"mc":[{"id":"1.232129550","rc":[{"batb":[[1,1.35,31.27],[2,1.34,882.35]],"ltp":1.4,"tv":175.83,"id":72857114},{"batb":[[0,1.31,6.21],[1,1.27,1111.11],[2,1.22,19.85]],"ltp":1.4,"tv":178.08,"id":72922097}]}]}
{"op":"mcm","clk":"11896342644","pt":1724342507464,"mc":[{"id":"1.232129550","rc":[{"batb":[[0,1.35,31.27],[1,1.34,882.35],[2,1.3,15]],"ltp":1.4,"tv":175.83,"id":72857114},{"batb":[[0,1.32,4],[1,1.31,6.21],[2,1.27,1111.11]],"ltp":1.4,"tv":178.08,"id":72922097}]}]}
{"op":"mcm","clk":"11896342914","pt":1724342510363,"mc":[{"id":"1.232129550","rc":[{"batb":[[0,1.36,14],[1,1.35,31.27],[2,1.34,882.35]],"ltp":1.4,"tv":175.83,"id":72857114},{"batb":[[0,1.32,10]],"ltp":1.4,"tv":178.08,"id":72922097}]}]}
{"op":"mcm","clk":"11896343160","pt":1724342512887,"mc":[{"id":"1.232129550","rc":[{"batb":[[0,1.36,10]],"ltp":1.4,"tv":175.83,"id":72857114},{"batb":[[0,1.33,4],[1,1.32,10],[2,1.31,6.21]],"ltp":1.4,"tv":178.08,"id":72922097}]}]}
{"op":"mcm","clk":"11896343250","pt":1724342513677,"mc":[{"id":"1.232129550","rc":[{"batb":[[0,1.35,31.27],[1,1.34,882.35],[2,1.3,15]],"ltp":1.4,"tv":175.83,"id":72857114},{"batb":[[1,1.31,6.21],[2,1.27,1111.11]],"ltp":1.4,"tv":178.08,"id":72922097}]}]}
{"op":"mcm","clk":"11896343500","pt":1724342515462,"mc":[{"id":"1.232129550","rc":[{"batb":[[0,1.36,4],[1,1.35,31.27],[2,1.34,882.35]],"ltp":1.4,"tv":175.83,"id":72857114},{"batb":[[0,1.31,6.21],[1,1.27,1111.11],[2,1.22,19.85]],"ltp":1.4,"tv":178.08,"id":72922097}]}]}
{"op":"mcm","clk":"11896343711","pt":1724342517900,"mc":[{"id":"1.232129550","rc":[{"batb":[[0,1.36,10]],"ltp":1.4,"tv":175.83,"id":72857114},{"batb":[[0,1.32,14],[1,1.31,6.21],[2,1.27,1111.11]],"ltp":1.4,"tv":178.08,"id":72922097}]}]}
{"op":"mcm","clk":"11896343931","pt":1724342520410,"mc":[{"id":"1.232129550","rc":[{"batb":[[0,1.37,4],[1,1.36,10],[2,1.35,31.27]],"ltp":1.4,"tv":175.83,"id":72857114},{"batb":[[0,1.32,10]],"ltp":1.4,"tv":178.08,"id":72922097}]}]}
{"op":"mcm","clk":"11896344019","pt":1724342521311,"mc":[{"id":"1.232129550","rc":[{"batb":[[1,1.35,31.27],[2,1.34,882.35]],"ltp":1.4,"tv":175.83,"id":72857114},{"batb":[[0,1.31,6.21],[1,1.27,1111.11],[2,1.22,19.85]],"ltp":1.4,"tv":178.08,"id":72922097}]}]}
{"op":"mcm","clk":"11896344173","pt":1724342522916,"mc":[{"id":"1.232129550","rc":[{"batb":[[0,1.35,31.27],[1,1.34,882.35],[2,1.3,15]],"ltp":1.4,"tv":175.83,"id":72857114},{"batb":[[0,1.32,4],[1,1.31,6.21],[2,1.27,1111.11]],"ltp":1.4,"tv":178.08,"id":72922097}]}]}
{"op":"mcm","clk":"11896344436","pt":1724342525420,"mc":[{"id":"1.232129550","rc":[{"batb":[[0,1.36,14],[1,1.35,31.27],[2,1.34,882.35]],"ltp":1.4,"tv":175.83,"id":72857114},{"batb":[[0,1.32,10]],"ltp":1.4,"tv":178.08,"id":72922097}]}]}
{"op":"mcm","clk":"11896344662","pt":1724342527893,"mc":[{"id":"1.232129550","rc":[{"batb":[[0,1.36,10]],"ltp":1.4,"tv":175.83,"id":72857114}]}]}
{"op":"mcm","clk":"11896344753","pt":1724342528782,"mc":[{"id":"1.232129550","rc":[{"batb":[[0,1.35,31.27],[1,1.34,882.35],[2,1.3,15]],"ltp":1.4,"tv":175.83,"id":72857114},{"batb":[[0,1.33,4]],"ltp":1.4,"tv":178.08,"id":72922097}]}]}
{"op":"mcm","clk":"11896344910","pt":1724342530515,"mc":[{"id":"1.232129550","rc":[{"batb":[[0,1.36,4],[1,1.35,31.27],[2,1.34,882.35]],"ltp":1.4,"tv":175.83,"id":72857114},{"batb":[[0,1.31,6.21],[1,1.27,1111.11],[2,1.22,19.85]],"ltp":1.4,"tv":178.08,"id":72922097}]}]}
{"op":"mcm","clk":"11896345149","pt":1724342532895,"mc":[{"id":"1.232129550","rc":[{"batb":[[0,1.36,10]],"ltp":1.4,"tv":175.83,"id":72857114},{"batb":[[0,1.32,14],[1,1.31,6.21],[2,1.27,1111.11]],"ltp":1.4,"tv":178.08,"id":72922097}]}]}
{"op":"mcm","clk":"11896345421","pt":1724342535328,"mc":[{"id":"1.232129550","rc":[{"batb":[[0,1.37,4],[1,1.36,10],[2,1.35,31.27]],"ltp":1.4,"tv":175.83,"id":72857114},{"batb":[[0,1.32,10]],"ltp":1.4,"tv":178.08,"id":72922097}]}]}
{"op":"mcm","clk":"11896345533","pt":1724342536326,"mc":[{"id":"1.232129550","rc":[{"batb":[[1,1.35,31.27],[2,1.34,882.35]],"ltp":1.4,"tv":175.83,"id":72857114},{"batb":[[0,1.31,6.21],[1,1.27,1111.11],[2,1.22,19.85]],"ltp":1.4,"tv":178.08,"id":72922097}]}]}
{"op":"mcm","clk":"11896345674","pt":1724342537789,"mc":[{"id":"1.232129550","rc":[{"batb":[[0,1.35,31.27],[1,1.34,882.35],[2,1.3,15]],"ltp":1.4,"tv":175.83,"id":72857114},{"batb":[[0,1.32,4],[1,1.31,6.21],[2,1.27,1111.11]],"ltp":1.4,"tv":178.08,"id":72922097}]}]}
{"op":"mcm","clk":"11896345961","pt":1724342540516,"mc":[{"id":"1.232129550","rc":[{"batb":[[0,1.36,14],[1,1.35,31.27],[2,1.34,882.35]],"ltp":1.4,"tv":175.83,"id":72857114},{"batb":[[0,1.32,10]],"ltp":1.4,"tv":178.08,"id":72922097}]}]}
{"op":"mcm","clk":"11896346232","pt":1724342543212,"mc":[{"id":"1.232129550","rc":[{"batb":[[0,1.36,10]],"ltp":1.4,"tv":175.83,"id":72857114},{"batb":[[0,1.33,4],[1,1.32,10],[2,1.31,6.21]],"ltp":1.4,"tv":178.08,"id":72922097}]}]}
{"op":"mcm","clk":"11896346323","pt":1724342543999,"mc":[{"id":"1.232129550","rc":[{"batb":[[0,1.35,31.27],[1,1.34,882.35],[2,1.3,15]],"ltp":1.4,"tv":175.83,"id":72857114},{"batb":[[1,1.31,6.21],[2,1.27,1111.11]],"ltp":1.4,"tv":178.08,"id":72922097}]}]}
{"op":"mcm","clk":"11896346516","pt":1724342545844,"mc":[{"id":"1.232129550","rc":[{"batb":[[0,1.36,4],[1,1.35,31.27],[2,1.34,882.35]],"ltp":1.4,"tv":175.83,"id":72857114},{"batb":[[0,1.31,6.21],[1,1.27,1111.11],[2,1.22,19.85]],"ltp":1.4,"tv":178.08,"id":72922097}]}]}
{"op":"mcm","clk":"11896346777","pt":1724342548328,"mc":[{"id":"1.232129550","rc":[{"batb":[[0,1.36,10]],"ltp":1.4,"tv":175.83,"id":72857114},{"batb":[[0,1.32,14],[1,1.31,6.21],[2,1.27,1111.11]],"ltp":1.4,"tv":178.08,"id":72922097}]}]}
{"op":"mcm","clk":"11896346993","pt":1724342550835,"mc":[{"id":"1.232129550","rc":[{"batb":[[0,1.37,4],[1,1.36,10],[2,1.35,31.27]],"ltp":1.4,"tv":175.83,"id":72857114},{"batb":[[0,1.32,10]],"ltp":1.4,"tv":178.08,"id":72922097}]}]}
{"op":"mcm","clk":"11896347078","pt":1724342551627,"mc":[{"id":"1.232129550","rc":[{"batb":[[1,1.35,31.27],[2,1.34,882.35]],"ltp":1.4,"tv":175.83,"id":72857114},{"batb":[[0,1.31,6.21],[1,1.27,1111.11],[2,1.22,19.85]],"ltp":1.4,"tv":178.08,"id":72922097}]}]}
{"op":"mcm","clk":"11896347282","pt":1724342553332,"mc":[{"id":"1.232129550","rc":[{"batb":[[0,1.35,31.27],[1,1.34,882.35],[2,1.3,15]],"ltp":1.4,"tv":175.83,"id":72857114},{"batb":[[0,1.32,4],[1,1.31,6.21],[2,1.27,1111.11]],"ltp":1.4,"tv":178.08,"id":72922097}]}]}
{"op":"mcm","clk":"11896347552","pt":1724342555747,"mc":[{"id":"1.232129550","rc":[{"batb":[[0,1.36,14],[1,1.35,31.27],[2,1.34,882.35]],"ltp":1.4,"tv":175.83,"id":72857114},{"batb":[[0,1.32,10]],"ltp":1.4,"tv":178.08,"id":72922097}]}]}
{"op":"mcm","clk":"11896347809","pt":1724342558218,"mc":[{"id":"1.232129550","rc":[{"batb":[[0,1.36,10]],"ltp":1.4,"tv":175.83,"id":72857114},{"batb":[[0,1.33,4],[1,1.32,10],[2,1.31,6.21]],"ltp":1.4,"tv":178.08,"id":72922097}]}]}
{"op":"mcm","clk":"11896347903","pt":1724342559229,"mc":[{"id":"1.232129550","rc":[{"batb":[[0,1.35,31.27],[1,1.34,882.35],[2,1.3,15]],"ltp":1.4,"tv":175.83,"id":72857114},{"batb":[[1,1.31,6.21],[2,1.27,1111.11]],"ltp":1.4,"tv":178.08,"id":72922097}]}]}
{"op":"mcm","clk":"11896348092","pt":1724342560959,"mc":[{"id":"1.232129550","rc":[{"batb":[[0,1.36,4],[1,1.35,31.27],[2,1.34,882.35]],"ltp":1.4,"tv":175.83,"id":72857114},{"batb":[[0,1.31,6.21],[1,1.27,1111.11],[2,1.22,19.85]],"ltp":1.4,"tv":178.08,"id":72922097}]}]}
{"op":"mcm","clk":"11896348322","pt":1724342563258,"mc":[{"id":"1.232129550","rc":[{"batb":[[0,1.36,10]],"ltp":1.4,"tv":175.83,"id":72857114},{"batb":[[0,1.32,14],[1,1.31,6.21],[2,1.27,1111.11]],"ltp":1.4,"tv":178.08,"id":72922097}]}]}
{"op":"mcm","clk":"11896348538","pt":1724342565658,"mc":[{"id":"1.232129550","rc":[{"batb":[[0,1.37,4],[1,1.36,10],[2,1.35,31.27]],"ltp":1.4,"tv":175.83,"id":72857114},{"batb":[[0,1.32,10]],"ltp":1.4,"tv":178.08,"id":72922097}]}]}
{"op":"mcm","clk":"11896348638","pt":1724342566760,"mc":[{"id":"1.232129550","rc":[{"batb":[[1,1.35,31.27],[2,1.34,882.35]],"ltp":1.4,"tv":175.83,"id":72857114},{"batb":[[0,1.31,6.21],[1,1.27,1111.11],[2,1.22,19.85]],"ltp":1.4,"tv":178.08,"id":72922097}]}]}
{"op":"mcm","clk":"11896348754","pt":1724342568225,"mc":[{"id":"1.232129550","rc":[{"batb":[[0,1.35,31.27],[1,1.34,882.35],[2,1.3,15]],"ltp":1.4,"tv":175.83,"id":72857114},{"batb":[[0,1.32,4],[1,1.31,6.21],[2,1.27,1111.11]],"ltp":1.4,"tv":178.08,"id":72922097}]}]}
{"op":"mcm","clk":"11896349097","pt":1724342570629,"mc":[{"id":"1.232129550","rc":[{"batb":[[0,1.36,14],[1,1.35,31.27],[2,1.34,882.35]],"ltp":1.4,"tv":175.83,"id":72857114},{"batb":[[0,1.32,10]],"ltp":1.4,"tv":178.08,"id":72922097}]}]}
{"op":"mcm","clk":"11896349500","pt":1724342573136,"mc":[{"id":"1.232129550","rc":[{"batb":[[0,1.36,10]],"ltp":1.4,"tv":175.83,"id":72857114},{"batb":[[0,1.33,4],[1,1.32,10],[2,1.31,6.21]],"ltp":1.4,"tv":178.08,"id":72922097}]}]}
{"op":"mcm","clk":"11896349573","pt":1724342574066,"mc":[{"id":"1.232129550","rc":[{"batb":[[0,1.35,31.27],[1,1.34,882.35],[2,1.3,15]],"ltp":1.4,"tv":175.83,"id":72857114},{"batb":[[1,1.31,6.21],[2,1.27,1111.11]],"ltp":1.4,"tv":178.08,"id":72922097}]}]}
{"op":"mcm","clk":"11896349688","pt":1724342575476,"mc":[{"id":"1.232129550","rc":[{"batb":[[0,1.36,4],[1,1.35,31.27],[2,1.34,882.35]],"ltp":1.4,"tv":175.83,"id":72857114},{"batb":[[0,1.31,6.21],[1,1.27,1111.11],[2,1.22,19.85]],"ltp":1.4,"tv":178.08,"id":72922097}]}]}
{"op":"mcm","clk":"11896349899","pt":1724342577670,"mc":[{"id":"1.232129550","rc":[{"batb":[[0,1.36,10]],"ltp":1.4,"tv":175.83,"id":72857114},{"batb":[[0,1.32,14],[1,1.31,6.21],[2,1.27,1111.11]],"ltp":1.4,"tv":178.08,"id":72922097}]}]}
{"op":"mcm","clk":"11896350113","pt":1724342579966,"mc":[{"id":"1.232129550","rc":[{"batb":[[0,1.32,10]],"ltp":1.4,"tv":178.08,"id":72922097}]}]}
{"op":"mcm","clk":"11896350210","pt":1724342580966,"mc":[{"id":"1.232129550","rc":[{"batb":[[0,1.37,4]],"ltp":1.4,"tv":175.83,"id":72857114},{"batb":[[0,1.31,6.21],[1,1.27,1111.11],[2,1.22,19.85]],"ltp":1.4,"tv":178.08,"id":72922097}]}]}
{"op":"mcm","clk":"11896350360","pt":1724342582747,"mc":[{"id":"1.232129550","rc":[{"batb":[[0,1.35,31.27],[1,1.34,882.35],[2,1.3,15]],"ltp":1.4,"tv":175.83,"id":72857114},{"batb":[[0,1.32,4],[1,1.31,6.21],[2,1.27,1111.11]],"ltp":1.4,"tv":178.08,"id":72922097}]}]}
{"op":"mcm","clk":"11896350604","pt":1724342585262,"mc":[{"id":"1.232129550","rc":[{"batb":[[0,1.36,14],[1,1.35,31.27],[2,1.34,882.35]],"ltp":1.4,"tv":175.83,"id":72857114},{"batb":[[0,1.32,10]],"ltp":1.4,"tv":178.08,"id":72922097}]}]}
{"op":"mcm","clk":"11896350828","pt":1724342587773,"mc":[{"id":"1.232129550","rc":[{"batb":[[0,1.36,10]],"ltp":1.4,"tv":175.83,"id":72857114},{"batb":[[0,1.33,4],[1,1.32,10],[2,1.31,6.21]],"ltp":1.4,"tv":178.08,"id":72922097}]}]}
{"op":"mcm","clk":"11896350902","pt":1724342588564,"mc":[{"id":"1.232129550","rc":[{"batb":[[0,1.35,31.27],[1,1.34,882.35],[2,1.3,15]],"ltp":1.4,"tv":175.83,"id":72857114},{"batb":[[1,1.31,6.21],[2,1.27,1111.11]],"ltp":1.4,"tv":178.08,"id":72922097}]}]}
{"op":"mcm","clk":"11896351065","pt":1724342590287,"mc":[{"id":"1.232129550","rc":[{"batb":[[0,1.36,4],[1,1.35,31.27],[2,1.34,882.35]],"ltp":1.4,"tv":175.83,"id":72857114},{"batb":[[0,1.31,6.21],[1,1.27,1111.11],[2,1.22,19.85]],"ltp":1.4,"tv":178.08,"id":72922097}]}]}
{"op":"mcm","clk":"11896351304","pt":1724342592795,"mc":[{"id":"1.232129550","rc":[{"batb":[[0,1.36,10]],"ltp":1.4,"tv":175.83,"id":72857114},{"batb":[[0,1.32,14],[1,1.31,6.21],[2,1.27,1111.11]],"ltp":1.4,"tv":178.08,"id":72922097}]}]}
{"op":"mcm","clk":"11896351555","pt":1724342595382,"mc":[{"id":"1.232129550","rc":[{"batb":[[0,1.37,4],[1,1.36,10],[2,1.35,31.27]],"ltp":1.4,"tv":175.83,"id":72857114},{"batb":[[0,1.32,10]],"ltp":1.4,"tv":178.08,"id":72922097}]}]}
{"op":"mcm","clk":"11896351643","pt":1724342596164,"mc":[{"id":"1.232129550","rc":[{"batb":[[1,1.35,31.27],[2,1.34,882.35]],"ltp":1.4,"tv":175.83,"id":72857114},{"batb":[[0,1.31,6.21],[1,1.27,1111.11],[2,1.22,19.85]],"ltp":1.4,"tv":178.08,"id":72922097}]}]}
{"op":"mcm","clk":"11896351796","pt":1724342597790,"mc":[{"id":"1.232129550","rc":[{"batb":[[0,1.35,31.27],[1,1.34,882.35],[2,1.3,15]],"ltp":1.4,"tv":175.83,"id":72857114}]}]}
{"op":"mcm","clk":"11896351811","pt":1724342597999,"mc":[{"id":"1.232129550","rc":[{"batb":[[0,1.32,4],[1,1.31,6.21],[2,1.27,1111.11]],"ltp":1.4,"tv":178.08,"id":72922097}]}]}
{"op":"mcm","clk":"11896352065","pt":1724342600499,"mc":[{"id":"1.232129550","rc":[{"batb":[[0,1.36,14],[1,1.35,31.27],[2,1.34,882.35]],"ltp":1.4,"tv":175.83,"id":72857114},{"batb":[[0,1.33,10]],"ltp":1.4,"tv":178.08,"id":72922097}]}]}
{"op":"mcm","clk":"11896352371","pt":1724342603774,"mc":[{"id":"1.232129550","rc":[{"batb":[[0,1.35,31.27],[1,1.34,882.35],[2,1.3,15]],"ltp":1.4,"tv":175.83,"id":72857114},{"batb":[[0,1.34,4]],"ltp":1.4,"tv":178.08,"id":72922097}]}]}
{"op":"mcm","clk":"11896352563","pt":1724342605905,"mc":[{"id":"1.232129550","rc":[{"batb":[[0,1.36,14],[1,1.35,31.27],[2,1.34,882.35]],"ltp":1.4,"tv":175.83,"id":72857114},{"batb":[[0,1.35,10]],"ltp":1.4,"tv":178.08,"id":72922097}]}]}
{"op":"mcm","clk":"11896352813","pt":1724342608380,"mc":[{"id":"1.232129550","rc":[{"batb":[[0,1.36,10]],"ltp":1.4,"tv":175.83,"id":72857114},{"batb":[[0,1.36,4],[1,1.35,10],[2,1.31,6.21]],"ltp":1.4,"tv":178.08,"id":72922097}]}]}
{"op":"mcm","clk":"11896352897","pt":1724342609208,"mc":[{"id":"1.232129550","rc":[{"batb":[[0,1.35,31.27],[1,1.34,882.35],[2,1.3,15]],"ltp":1.4,"tv":175.83,"id":72857114},{"batb":[[1,1.31,6.21],[2,1.27,1111.11]],"ltp":1.4,"tv":178.08,"id":72922097}]}]}
{"op":"mcm","clk":"11896353049","pt":1724342610884,"mc":[{"id":"1.232129550","rc":[{"batb":[[0,1.36,4],[1,1.35,31.27],[2,1.34,882.35]],"ltp":1.4,"tv":175.83,"id":72857114},{"batb":[[0,1.31,6.21],[1,1.27,1111.11],[2,1.22,19.85]],"ltp":1.4,"tv":178.08,"id":72922097}]}]}
{"op":"mcm","clk":"11896353324","pt":1724342613501,"mc":[{"id":"1.232129550","rc":[{"batb":[[0,1.36,10]],"ltp":1.4,"tv":175.83,"id":72857114},{"batb":[[0,1.32,14],[1,1.31,6.21],[2,1.27,1111.11]],"ltp":1.4,"tv":178.08,"id":72922097}]}]}
{"op":"mcm","clk":"11896353600","pt":1724342616210,"mc":[{"id":"1.232129550","rc":[{"batb":[[0,1.37,4],[1,1.36,10],[2,1.35,31.27]],"ltp":1.4,"tv":175.83,"id":72857114},{"batb":[[0,1.32,10]],"ltp":1.4,"tv":178.08,"id":72922097}]}]}
{"op":"mcm","clk":"11896353674","pt":1724342616993,"mc":[{"id":"1.232129550","rc":[{"batb":[[1,1.35,31.27],[2,1.34,882.35]],"ltp":1.4,"tv":175.83,"id":72857114},{"batb":[[0,1.31,6.21],[1,1.27,1111.11],[2,1.22,19.85]],"ltp":1.4,"tv":178.08,"id":72922097}]}]}
{"op":"mcm","clk":"11896353868","pt":1724342618817,"mc":[{"id":"1.232129550","rc":[{"batb":[[0,1.35,31.27],[1,1.34,882.35],[2,1.3,15]],"ltp":1.4,"tv":175.83,"id":72857114},{"batb":[[0,1.32,4],[1,1.31,6.21],[2,1.27,1111.11]],"ltp":1.4,"tv":178.08,"id":72922097}]}]}
{"op":"mcm","clk":"11896353987","pt":1724342620017,"mc":[{"id":"1.232129550","rc":[{"batb":[[0,1.36,10],[1,1.35,31.27],[2,1.34,882.35]],"ltp":1.4,"tv":175.83,"id":72857114},{"batb":[[0,1.33,10],[1,1.32,4],[2,1.31,6.21]],"ltp":1.4,"tv":178.08,"id":72922097}]}]}
{"op":"mcm","clk":"11896354117","pt":1724342621319,"mc":[{"id":"1.232129550","rc":[{"batb":[[0,1.37,4],[1,1.36,10],[2,1.35,31.27]],"ltp":1.4,"tv":175.83,"id":72857114},{"batb":[[1,1.31,6.21],[2,1.27,1111.11]],"ltp":1.4,"tv":178.08,"id":72922097}]}]}
{"op":"mcm","clk":"11896354342","pt":1724342623714,"mc":[{"id":"1.232129550","rc":[{"batb":[[0,1.35,31.27],[1,1.34,882.35],[2,1.3,15]],"ltp":1.4,"tv":175.83,"id":72857114},{"batb":[[0,1.32,4]],"ltp":1.4,"tv":178.08,"id":72922097}]}]}
{"op":"mcm","clk":"11896354565","pt":1724342626316,"mc":[{"id":"1.232129550","rc":[{"batb":[[0,1.36,14],[1,1.35,31.27],[2,1.34,882.35]],"ltp":1.4,"tv":175.83,"id":72857114},{"batb":[[0,1.32,10]],"ltp":1.4,"tv":178.08,"id":72922097}]}]}
{"op":"mcm","clk":"11896354810","pt":1724342628931,"mc":[{"id":"1.232129550","rc":[{"batb":[[0,1.36,10]],"ltp":1.4,"tv":175.83,"id":72857114},{"batb":[[0,1.33,4],[1,1.32,10],[2,1.31,6.21]],"ltp":1.4,"tv":178.08,"id":72922097}]}]}
{"op":"mcm","clk":"11896354875","pt":1724342629715,"mc":[{"id":"1.232129550","rc":[{"batb":[[0,1.35,31.27],[1,1.34,882.35],[2,1.3,15]],"ltp":1.4,"tv":175.83,"id":72857114},{"batb":[[1,1.31,6.21],[2,1.27,1111.11]],"ltp":1.4,"tv":178.08,"id":72922097}]}]}
{"op":"mcm","clk":"11896355017","pt":1724342631442,"mc":[{"id":"1.232129550","rc":[{"batb":[[0,1.36,4],[1,1.35,31.27],[2,1.34,882.35]],"ltp":1.4,"tv":175.83,"id":72857114},{"batb":[[0,1.31,6.21],[1,1.27,1111.11],[2,1.22,19.85]],"ltp":1.4,"tv":178.08,"id":72922097}]}]}
{"op":"mcm","clk":"11896355254","pt":1724342633947,"mc":[{"id":"1.232129550","rc":[{"batb":[[0,1.36,10]],"ltp":1.4,"tv":175.83,"id":72857114},{"batb":[[0,1.32,14],[1,1.31,6.21],[2,1.27,1111.11]],"ltp":1.4,"tv":178.08,"id":72922097}]}]}
{"op":"mcm","clk":"11896355497","pt":1724342636209,"mc":[{"id":"1.232129550","rc":[{"batb":[[0,1.37,4],[1,1.36,10],[2,1.35,31.27]],"ltp":1.4,"tv":175.83,"id":72857114},{"batb":[[0,1.32,10]],"ltp":1.4,"tv":178.08,"id":72922097}]}]}
{"op":"mcm","clk":"11896355593","pt":1724342637255,"mc":[{"id":"1.232129550","rc":[{"batb":[[1,1.35,31.27],[2,1.34,882.35]],"ltp":1.4,"tv":175.83,"id":72857114},{"batb":[[0,1.31,6.21],[1,1.27,1111.11],[2,1.22,19.85]],"ltp":1.4,"tv":178.08,"id":72922097}]}]}
{"op":"mcm","clk":"11896355749","pt":1724342638736,"mc":[{"id":"1.232129550","rc":[{"batb":[[0,1.35,31.27],[1,1.34,882.35],[2,1.3,15]],"ltp":1.4,"tv":175.83,"id":72857114},{"batb":[[0,1.32,4],[1,1.31,6.21],[2,1.27,1111.11]],"ltp":1.4,"tv":178.08,"id":72922097}]}]}
{"op":"mcm","clk":"11896355999","pt":1724342641332,"mc":[{"id":"1.232129550","rc":[{"batb":[[0,1.36,14],[1,1.35,31.27],[2,1.34,882.35]],"ltp":1.4,"tv":175.83,"id":72857114},{"batb":[[0,1.32,10]],"ltp":1.4,"tv":178.08,"id":72922097}]}]}
{"op":"mcm","clk":"11896356207","pt":1724342643641,"mc":[{"id":"1.232129550","rc":[{"batb":[[0,1.36,10]],"ltp":1.4,"tv":175.83,"id":72857114}]}]}
{"op":"mcm","clk":"11896356296","pt":1724342644756,"mc":[{"id":"1.232129550","rc":[{"batb":[[0,1.35,31.27],[1,1.34,882.35],[2,1.3,15]],"ltp":1.4,"tv":175.83,"id":72857114},{"batb":[[0,1.33,4]],"ltp":1.4,"tv":178.08,"id":72922097}]}]}
{"op":"mcm","clk":"11896356498","pt":1724342646862,"mc":[{"id":"1.232129550","rc":[{"batb":[[0,1.37,10],[1,1.36,4],[2,1.35,31.27]],"ltp":1.4,"tv":175.83,"id":72857114},{"batb":[[0,1.32,10]],"ltp":1.4,"tv":178.08,"id":72922097}]}]}
{"op":"mcm","clk":"11896356746","pt":1724342649445,"mc":[{"id":"1.232129550","rc":[{"batb":[[1,1.35,31.27],[2,1.34,882.35]],"ltp":1.4,"tv":175.83,"id":72857114},{"batb":[[0,1.33,4],[1,1.32,10],[2,1.31,6.21]],"ltp":1.4,"tv":178.08,"id":72922097}]}]}
{"op":"mcm","clk":"11896356826","pt":1724342650234,"mc":[{"id":"1.232129550","rc":[{"batb":[[0,1.35,31.27],[1,1.34,882.35],[2,1.3,15]],"ltp":1.4,"tv":175.83,"id":72857114},{"batb":[[1,1.31,6.21],[2,1.27,1111.11]],"ltp":1.4,"tv":178.08,"id":72922097}]}]}
{"op":"mcm","clk":"11896356997","pt":1724342651863,"mc":[{"id":"1.232129550","rc":[{"batb":[[0,1.31,6.21],[1,1.27,1111.11],[2,1.22,19.85]],"ltp":1.4,"tv":178.08,"id":72922097}]}]}
{"op":"mcm","clk":"11896357023","pt":1724342652128,"mc":[{"id":"1.232129550","rc":[{"batb":[[0,1.36,4],[1,1.35,31.27],[2,1.34,882.35]],"ltp":1.4,"tv":175.83,"id":72857114}]}]}
{"op":"mcm","clk":"11896357138","pt":1724342653378,"mc":[{"id":"1.232129550","rc":[{"batb":[[0,1.37,10],[1,1.36,4],[2,1.35,31.27]],"ltp":1.4,"tv":175.83,"id":72857114},{"batb":[[0,1.32,10],[1,1.31,6.21],[2,1.27,1111.11]],"ltp":1.4,"tv":178.08,"id":72922097}]}]}
{"op":"mcm","clk":"11896357286","pt":1724342654751,"mc":[{"id":"1.232129550","rc":[{"batb":[[1,1.35,31.27],[2,1.34,882.35]],"ltp":1.4,"tv":175.83,"id":72857114},{"batb":[[0,1.33,4],[1,1.32,10],[2,1.31,6.21]],"ltp":1.4,"tv":178.08,"id":72922097}]}]}
{"op":"mcm","clk":"11896357456","pt":1724342656839,"mc":[{"id":"1.232129550","rc":[{"batb":[[0,1.36,4]],"ltp":1.4,"tv":175.83,"id":72857114},{"batb":[[1,1.31,6.21],[2,1.27,1111.11]],"ltp":1.4,"tv":178.08,"id":72922097}]}]}
{"op":"mcm","clk":"11896357476","pt":1724342657051,"mc":[{"id":"1.232129550","rc":[{"batb":[[0,1.31,6.21],[1,1.27,1111.11],[2,1.22,19.85]],"ltp":1.4,"tv":178.08,"id":72922097}]}]}
{"op":"mcm","clk":"11896357718","pt":1724342659456,"mc":[{"id":"1.232129550","rc":[{"batb":[[0,1.36,10]],"ltp":1.4,"tv":175.83,"id":72857114},{"batb":[[0,1.32,14],[1,1.31,6.21],[2,1.27,1111.11]],"ltp":1.4,"tv":178.08,"id":72922097}]}]}
{"op":"mcm","clk":"11896357981","pt":1724342661876,"mc":[{"id":"1.232129550","rc":[{"batb":[[0,1.37,4],[1,1.36,10],[2,1.35,31.27]],"ltp":1.4,"tv":175.83,"id":72857114},{"batb":[[0,1.32,10]],"ltp":1.4,"tv":178.08,"id":72922097}]}]}
{"op":"mcm","clk":"11896358073","pt":1724342662885,"mc":[{"id":"1.232129550","rc":[{"batb":[[1,1.35,31.27],[2,1.34,882.35]],"ltp":1.4,"tv":175.83,"id":72857114},{"batb":[[0,1.31,6.21],[1,1.27,1111.11],[2,1.22,19.85]],"ltp":1.4,"tv":178.08,"id":72922097}]}]}
{"op":"mcm","clk":"11896358191","pt":1724342664094,"mc":[{"id":"1.232129550","rc":[{"batb":[[0,1.35,31.27],[1,1.34,882.35],[2,1.3,15]],"ltp":1.4,"tv":175.83,"id":72857114},{"batb":[[0,1.32,4],[1,1.31,6.21],[2,1.27,1111.11]],"ltp":1.4,"tv":178.08,"id":72922097}]}]}
{"op":"mcm","clk":"11896358445","pt":1724342666679,"mc":[{"id":"1.232129550","rc":[{"batb":[[0,1.31,6.21],[1,1.27,1111.11],[2,1.22,19.85]],"ltp":1.4,"tv":178.08,"id":72922097}]}]}
{"op":"mcm","clk":"11896358509","pt":1724342667258,"mc":[{"id":"1.232129550","rc":[{"batb":[[0,1.36,14],[1,1.35,31.27],[2,1.34,882.35]],"ltp":1.4,"tv":175.83,"id":72857114},{"batb":[[0,1.32,10],[1,1.31,6.21],[2,1.27,1111.11]],"ltp":1.4,"tv":178.08,"id":72922097}]}]}
{"op":"mcm","clk":"11896358778","pt":1724342669881,"mc":[{"id":"1.232129550","rc":[{"batb":[[0,1.36,10]],"ltp":1.4,"tv":175.83,"id":72857114},{"batb":[[0,1.33,4],[1,1.32,10],[2,1.31,6.21]],"ltp":1.4,"tv":178.08,"id":72922097}]}]}
{"op":"mcm","clk":"11896358851","pt":1724342670566,"mc":[{"id":"1.232129550","rc":[{"batb":[[0,1.35,31.27],[1,1.34,882.35],[2,1.3,15]],"ltp":1.4,"tv":175.83,"id":72857114},{"batb":[[1,1.31,6.21],[2,1.27,1111.11]],"ltp":1.4,"tv":178.08,"id":72922097}]}]}
{"op":"mcm","clk":"11896359013","pt":1724342672456,"mc":[{"id":"1.232129550","rc":[{"batb":[[0,1.36,4],[1,1.35,31.27],[2,1.34,882.35]],"ltp":1.4,"tv":175.83,"id":72857114},{"batb":[[0,1.31,6.21],[1,1.27,1111.11],[2,1.22,19.85]],"ltp":1.4,"tv":178.08,"id":72922097}]}]}
{"op":"mcm","clk":"11896359207","pt":1724342674771,"mc":[{"id":"1.232129550","rc":[{"batb":[[0,1.36,10]],"ltp":1.4,"tv":175.83,"id":72857114},{"batb":[[0,1.32,14],[1,1.31,6.21],[2,1.27,1111.11]],"ltp":1.4,"tv":178.08,"id":72922097}]}]}
{"op":"mcm","clk":"11896359425","pt":1724342677275,"mc":[{"id":"1.232129550","rc":[{"batb":[[0,1.37,4],[1,1.36,10],[2,1.35,31.27]],"ltp":1.4,"tv":175.83,"id":72857114},{"batb":[[0,1.32,10]],"ltp":1.4,"tv":178.08,"id":72922097}]}]}
{"op":"mcm","clk":"11896359517","pt":1724342678189,"mc":[{"id":"1.232129550","rc":[{"batb":[[1,1.35,31.27],[2,1.34,882.35]],"ltp":1.4,"tv":175.83,"id":72857114},{"batb":[[0,1.31,6.21],[1,1.27,1111.11],[2,1.22,19.85]],"ltp":1.4,"tv":178.08,"id":72922097}]}]}
{"op":"mcm","clk":"11896359683","pt":1724342679908,"mc":[{"id":"1.232129550","rc":[{"batb":[[0,1.35,31.27],[1,1.34,882.35],[2,1.3,15]],"ltp":1.4,"tv":175.83,"id":72857114},{"batb":[[0,1.32,4],[1,1.31,6.21],[2,1.27,1111.11]],"ltp":1.4,"tv":178.08,"id":72922097}]}]}
{"op":"mcm","clk":"11896359906","pt":1724342682278,"mc":[{"id":"1.232129550","rc":[{"batb":[[0,1.36,14],[1,1.35,31.27],[2,1.34,882.35]],"ltp":1.4,"tv":175.83,"id":72857114},{"batb":[[0,1.32,10]],"ltp":1.4,"tv":178.08,"id":72922097}]}]}
{"op":"mcm","clk":"11896360138","pt":1724342684677,"mc":[{"id":"1.232129550","rc":[{"batb":[[0,1.36,10]],"ltp":1.4,"tv":175.83,"id":72857114},{"batb":[[0,1.33,4],[1,1.32,10],[2,1.31,6.21]],"ltp":1.4,"tv":178.08,"id":72922097}]}]}
{"op":"mcm","clk":"11896360195","pt":1724342685509,"mc":[{"id":"1.232129550","rc":[{"batb":[[0,1.35,31.27],[1,1.34,882.35],[2,1.3,15]],"ltp":1.4,"tv":175.83,"id":72857114},{"batb":[[1,1.31,6.21],[2,1.27,1111.11]],"ltp":1.4,"tv":178.08,"id":72922097}]}]}
{"op":"mcm","clk":"11896360358","pt":1724342687395,"mc":[{"id":"1.232129550","rc":[{"batb":[[0,1.36,4],[1,1.35,31.27],[2,1.34,882.35]],"ltp":1.4,"tv":175.83,"id":72857114},{"batb":[[0,1.31,6.21],[1,1.27,1111.11],[2,1.22,19.85]],"ltp":1.4,"tv":178.08,"id":72922097}]}]}
{"op":"mcm","clk":"11896360568","pt":1724342689683,"mc":[{"id":"1.232129550","rc":[{"batb":[[0,1.36,10]],"ltp":1.4,"tv":175.83,"id":72857114},{"batb":[[0,1.32,14],[1,1.31,6.21],[2,1.27,1111.11]],"ltp":1.4,"tv":178.08,"id":72922097}]}]}
{"op":"mcm","clk":"11896360830","pt":1724342692426,"mc":[{"id":"1.232129550","rc":[{"batb":[[0,1.37,4],[1,1.36,10],[2,1.35,31.27]],"ltp":1.4,"tv":175.83,"id":72857114},{"batb":[[0,1.32,10]],"ltp":1.4,"tv":178.08,"id":72922097}]}]}
{"op":"mcm","clk":"11896360918","pt":1724342693214,"mc":[{"id":"1.232129550","rc":[{"batb":[[1,1.35,31.27],[2,1.34,882.35]],"ltp":1.4,"tv":175.83,"id":72857114},{"batb":[[0,1.31,6.21],[1,1.27,1111.11],[2,1.22,19.85]],"ltp":1.4,"tv":178.08,"id":72922097}]}]}
{"op":"mcm","clk":"11896361065","pt":1724342694793,"mc":[{"id":"1.232129550","rc":[{"batb":[[0,1.35,31.27],[1,1.34,882.35],[2,1.3,15]],"ltp":1.4,"tv":175.83,"id":72857114},{"batb":[[0,1.32,4],[1,1.31,6.21],[2,1.27,1111.11]],"ltp":1.4,"tv":178.08,"id":72922097}]}]}
{"op":"mcm","clk":"11896361197","pt":1724342695992,"mc":[{"id":"1.232129550","rc":[{"batb":[[0,1.36,10],[1,1.35,31.27],[2,1.34,882.35]],"ltp":1.4,"tv":175.83,"id":72857114},{"batb":[[0,1.33,10],[1,1.32,4],[2,1.31,6.21]],"ltp":1.4,"tv":178.08,"id":72922097}]}]}
{"op":"mcm","clk":"11896361309","pt":1724342697304,"mc":[{"id":"1.232129550","rc":[{"batb":[[0,1.37,4],[1,1.36,10],[2,1.35,31.27]],"ltp":1.4,"tv":175.83,"id":72857114},{"batb":[[1,1.31,6.21],[2,1.27,1111.11]],"ltp":1.4,"tv":178.08,"id":72922097}]}]}
{"op":"mcm","clk":"11896361514","pt":1724342699623,"mc":[{"id":"1.232129550","rc":[{"batb":[[0,1.35,31.27],[1,1.34,882.35],[2,1.3,15]],"ltp":1.4,"tv":175.83,"id":72857114},{"batb":[[0,1.32,4]],"ltp":1.4,"tv":178.08,"id":72922097}]}]}
{"op":"mcm","clk":"11896361714","pt":1724342701905,"mc":[{"id":"1.232129550","rc":[{"batb":[[0,1.31,6.21],[1,1.27,1111.11],[2,1.22,19.85]],"ltp":1.4,"tv":178.08,"id":72922097}]}]}
{"op":"mcm","clk":"11896361731","pt":1724342702112,"mc":[{"id":"1.232129550","rc":[{"batb":[[0,1.36,14],[1,1.35,31.27],[2,1.34,882.35]],"ltp":1.4,"tv":175.83,"id":72857114},{"batb":[[0,1.32,10],[1,1.31,6.21],[2,1.27,1111.11]],"ltp":1.4,"tv":178.08,"id":72922097}]}]}
{"op":"mcm","clk":"11896361968","pt":1724342704622,"mc":[{"id":"1.232129550","rc":[{"batb":[[0,1.36,10]],"ltp":1.4,"tv":175.83,"id":72857114},{"batb":[[0,1.33,4],[1,1.32,10],[2,1.31,6.21]],"ltp":1.4,"tv":178.08,"id":72922097}]}]}
{"op":"mcm","clk":"11896362037","pt":1724342705420,"mc":[{"id":"1.232129550","rc":[{"batb":[[0,1.35,31.27],[1,1.34,882.35],[2,1.3,15]],"ltp":1.4,"tv":175.83,"id":72857114},{"batb":[[1,1.31,6.21],[2,1.27,1111.11]],"ltp":1.4,"tv":178.08,"id":72922097}]}]}
{"op":"mcm","clk":"11896362186","pt":1724342706800,"mc":[{"id":"1.232129550","rc":[{"batb":[[0,1.36,4],[1,1.35,31.27],[2,1.34,882.35]],"ltp":1.4,"tv":175.83,"id":72857114}]}]}
{"op":"mcm","clk":"11896362209","pt":1724342707008,"mc":[{"id":"1.232129550","rc":[{"batb":[[0,1.31,6.21],[1,1.27,1111.11],[2,1.22,19.85]],"ltp":1.4,"tv":178.08,"id":72922097}]}]}
{"op":"mcm","clk":"11896362399","pt":1724342709338,"mc":[{"id":"1.232129550","rc":[{"batb":[[0,1.36,10]],"ltp":1.4,"tv":175.83,"id":72857114},{"batb":[[0,1.32,14],[1,1.31,6.21],[2,1.27,1111.11]],"ltp":1.4,"tv":178.08,"id":72922097}]}]}
{"op":"mcm","clk":"11896362621","pt":1724342711821,"mc":[{"id":"1.232129550","rc":[{"batb":[[0,1.37,4],[1,1.36,10],[2,1.35,31.27]],"ltp":1.4,"tv":175.83,"id":72857114},{"batb":[[0,1.32,10]],"ltp":1.4,"tv":178.08,"id":72922097}]}]}
{"op":"mcm","clk":"11896362687","pt":1724342712613,"mc":[{"id":"1.232129550","rc":[{"batb":[[1,1.35,31.27],[2,1.34,882.35]],"ltp":1.4,"tv":175.83,"id":72857114},{"batb":[[0,1.31,6.21],[1,1.27,1111.11],[2,1.22,19.85]],"ltp":1.4,"tv":178.08,"id":72922097}]}]}
{"op":"mcm","clk":"11896362827","pt":1724342714342,"mc":[{"id":"1.232129550","rc":[{"batb":[[0,1.35,31.27],[1,1.34,882.35],[2,1.3,15]],"ltp":1.4,"tv":175.83,"id":72857114},{"batb":[[0,1.32,4],[1,1.31,6.21],[2,1.27,1111.11]],"ltp":1.4,"tv":178.08,"id":72922097}]}]}
{"op":"mcm","clk":"11896362927","pt":1724342715712,"mc":[{"id":"1.232129550","rc":[{"batb":[[0,1.36,10],[1,1.35,31.27],[2,1.34,882.35]],"ltp":1.4,"tv":175.83,"id":72857114},{"batb":[[0,1.33,10],[1,1.32,4],[2,1.31,6.21]],"ltp":1.4,"tv":178.08,"id":72922097}]}]}
{"op":"mcm","clk":"11896362998","pt":1724342716709,"mc":[{"id":"1.232129550","rc":[{"batb":[[0,1.37,4],[1,1.36,10],[2,1.35,31.27]],"ltp":1.4,"tv":175.83,"id":72857114},{"batb":[[1,1.31,6.21],[2,1.27,1111.11]],"ltp":1.4,"tv":178.08,"id":72922097}]}]}
{"op":"mcm","clk":"11896363192","pt":1724342719222,"mc":[{"id":"1.232129550","rc":[{"batb":[[0,1.35,31.27],[1,1.34,882.35],[2,1.3,15]],"ltp":1.4,"tv":175.83,"id":72857114},{"batb":[[0,1.32,4]],"ltp":1.4,"tv":178.08,"id":72922097}]}]}
{"op":"mcm","clk":"11896363417","pt":1724342721747,"mc":[{"id":"1.232129550","rc":[{"batb":[[0,1.36,14],[1,1.35,31.27],[2,1.34,882.35]],"ltp":1.4,"tv":175.83,"id":72857114},{"batb":[[0,1.32,10]],"ltp":1.4,"tv":178.08,"id":72922097}]}]}
{"op":"mcm","clk":"11896363603","pt":1724342723910,"mc":[{"id":"1.232129550","rc":[{"batb":[[0,1.36,10]],"ltp":1.4,"tv":175.83,"id":72857114}]}]}
{"op":"mcm","clk":"11896363703","pt":1724342724907,"mc":[{"id":"1.232129550","rc":[{"batb":[[0,1.35,31.27],[1,1.34,882.35],[2,1.3,15]],"ltp":1.4,"tv":175.83,"id":72857114},{"batb":[[0,1.33,4]],"ltp":1.4,"tv":178.08,"id":72922097}]}]}
{"op":"mcm","clk":"11896363846","pt":1724342726632,"mc":[{"id":"1.232129550","rc":[{"batb":[[0,1.36,4],[1,1.35,31.27],[2,1.34,882.35]],"ltp":1.4,"tv":175.83,"id":72857114},{"batb":[[0,1.31,6.21],[1,1.27,1111.11],[2,1.22,19.85]],"ltp":1.4,"tv":178.08,"id":72922097}]}]}
{"op":"mcm","clk":"11896363934","pt":1724342727839,"mc":[{"id":"1.232129550","rc":[{"batb":[[0,1.37,10],[1,1.36,4],[2,1.35,31.27]],"ltp":1.4,"tv":175.83,"id":72857114},{"batb":[[0,1.32,10],[1,1.31,6.21],[2,1.27,1111.11]],"ltp":1.4,"tv":178.08,"id":72922097}]}]}
{"op":"mcm","clk":"11896364050","pt":1724342729147,"mc":[{"id":"1.232129550","rc":[{"batb":[[1,1.35,31.27],[2,1.34,882.35]],"ltp":1.4,"tv":175.83,"id":72857114},{"batb":[[0,1.33,4],[1,1.32,10],[2,1.31,6.21]],"ltp":1.4,"tv":178.08,"id":72922097}]}]}
{"op":"mcm","clk":"11896364234","pt":1724342731415,"mc":[{"id":"1.232129550","rc":[{"batb":[[0,1.36,4]],"ltp":1.4,"tv":175.83,"id":72857114},{"batb":[[0,1.31,6.21],[1,1.27,1111.11],[2,1.22,19.85]],"ltp":1.4,"tv":178.08,"id":72922097}]}]}
{"op":"mcm","clk":"11896364429","pt":1724342733632,"mc":[{"id":"1.232129550","rc":[{"batb":[[0,1.36,10]],"ltp":1.4,"tv":175.83,"id":72857114},{"batb":[[0,1.32,14],[1,1.31,6.21],[2,1.27,1111.11]],"ltp":1.4,"tv":178.08,"id":72922097}]}]}
{"op":"mcm","clk":"11896364634","pt":1724342735918,"mc":[{"id":"1.232129550","rc":[{"batb":[[0,1.37,4],[1,1.36,10],[2,1.35,31.27]],"ltp":1.4,"tv":175.83,"id":72857114},{"batb":[[0,1.32,10]],"ltp":1.4,"tv":178.08,"id":72922097}]}]}
{"op":"mcm","clk":"11896364712","pt":1724342736922,"mc":[{"id":"1.232129550","rc":[{"batb":[[1,1.35,31.27],[2,1.34,882.35]],"ltp":1.4,"tv":175.83,"id":72857114},{"batb":[[0,1.31,6.21],[1,1.27,1111.11],[2,1.22,19.85]],"ltp":1.4,"tv":178.08,"id":72922097}]}]}
{"op":"mcm","clk":"11896364857","pt":1724342738442,"mc":[{"id":"1.232129550","rc":[{"batb":[[0,1.35,31.27],[1,1.34,882.35],[2,1.3,15]],"ltp":1.4,"tv":175.83,"id":72857114},{"batb":[[0,1.32,4],[1,1.31,6.21],[2,1.27,1111.11]],"ltp":1.4,"tv":178.08,"id":72922097}]}]}
{"op":"mcm","clk":"11896365092","pt":1724342740853,"mc":[{"id":"1.232129550","rc":[{"batb":[[0,1.31,6.21],[1,1.27,1111.11],[2,1.22,19.85]],"ltp":1.4,"tv":178.08,"id":72922097}]}]}
{"op":"mcm","clk":"11896365116","pt":1724342741057,"mc":[{"id":"1.232129550","rc":[{"batb":[[0,1.36,14],[1,1.35,31.27],[2,1.34,882.35]],"ltp":1.4,"tv":175.83,"id":72857114},{"batb":[[0,1.33,10],[1,1.31,6.21],[2,1.27,1111.11]],"ltp":1.4,"tv":178.08,"id":72922097}]}]}
{"op":"mcm","clk":"11896365378","pt":1724342743650,"mc":[{"id":"1.232129550","rc":[{"batb":[[0,1.36,10]],"ltp":1.4,"tv":175.83,"id":72857114},{"batb":[[0,1.34,4],[1,1.33,10],[2,1.31,6.21]],"ltp":1.4,"tv":178.08,"id":72922097}]}]}
{"op":"mcm","clk":"11896365470","pt":1724342744544,"mc":[{"id":"1.232129550","rc":[{"batb":[[0,1.35,31.27],[1,1.34,882.35],[2,1.3,15]],"ltp":1.4,"tv":175.83,"id":72857114},{"batb":[[1,1.31,6.21],[2,1.27,1111.11]],"ltp":1.4,"tv":178.08,"id":72922097}]}]}
{"op":"mcm","clk":"11896365594","pt":1724342745950,"mc":[{"id":"1.232129550","rc":[{"batb":[[0,1.36,4],[1,1.35,31.27],[2,1.34,882.35]],"ltp":1.4,"tv":175.83,"id":72857114},{"batb":[[0,1.31,6.21],[1,1.27,1111.11],[2,1.22,19.85]],"ltp":1.4,"tv":178.08,"id":72922097}]}]}
{"op":"mcm","clk":"11896365837","pt":1724342748568,"mc":[{"id":"1.232129550","rc":[{"batb":[[0,1.36,10]],"ltp":1.4,"tv":175.83,"id":72857114},{"batb":[[0,1.32,14],[1,1.31,6.21],[2,1.27,1111.11]],"ltp":1.4,"tv":178.08,"id":72922097}]}]}
{"op":"mcm","clk":"11896366071","pt":1724342751085,"mc":[{"id":"1.232129550","rc":[{"batb":[[0,1.37,4],[1,1.36,10],[2,1.35,31.27]],"ltp":1.4,"tv":175.83,"id":72857114},{"batb":[[0,1.32,10]],"ltp":1.4,"tv":178.08,"id":72922097}]}]}
{"op":"mcm","clk":"11896366177","pt":1724342752143,"mc":[{"id":"1.232129550","rc":[{"batb":[[1,1.35,31.27],[2,1.34,882.35]],"ltp":1.4,"tv":175.83,"id":72857114},{"batb":[[0,1.31,6.21],[1,1.27,1111.11],[2,1.22,19.85]],"ltp":1.4,"tv":178.08,"id":72922097}]}]}
{"op":"mcm","clk":"11896366285","pt":1724342753453,"mc":[{"id":"1.232129550","rc":[{"batb":[[0,1.35,31.27],[1,1.34,882.35],[2,1.3,15]],"ltp":1.4,"tv":175.83,"id":72857114},{"batb":[[0,1.32,4],[1,1.31,6.21],[2,1.27,1111.11]],"ltp":1.4,"tv":178.08,"id":72922097}]}]}
{"op":"mcm","clk":"11896366489","pt":1724342755962,"mc":[{"id":"1.232129550","rc":[{"batb":[[0,1.36,14],[1,1.35,31.27],[2,1.34,882.35]],"ltp":1.4,"tv":175.83,"id":72857114},{"batb":[[0,1.32,10]],"ltp":1.4,"tv":178.08,"id":72922097}]}]}
{"op":"mcm","clk":"11896366680","pt":1724342758484,"mc":[{"id":"1.232129550","rc":[{"batb":[[0,1.36,10]],"ltp":1.4,"tv":175.83,"id":72857114},{"batb":[[0,1.33,4],[1,1.32,10],[2,1.31,6.21]],"ltp":1.4,"tv":178.08,"id":72922097}]}]}
{"op":"mcm","clk":"11896366746","pt":1724342759381,"mc":[{"id":"1.232129550","rc":[{"batb":[[0,1.35,31.27],[1,1.34,882.35],[2,1.3,15]],"ltp":1.4,"tv":175.83,"id":72857114},{"batb":[[1,1.31,6.21],[2,1.27,1111.11]],"ltp":1.4,"tv":178.08,"id":72922097}]}]}
{"op":"mcm","clk":"11896366856","pt":1724342760874,"mc":[{"id":"1.232129550","rc":[{"batb":[[0,1.36,4],[1,1.35,31.27],[2,1.34,882.35]],"ltp":1.4,"tv":175.83,"id":72857114},{"batb":[[0,1.31,6.21],[1,1.27,1111.11],[2,1.22,19.85]],"ltp":1.4,"tv":178.08,"id":72922097}]}]}
{"op":"mcm","clk":"11896366967","pt":1724342762053,"mc":[{"id":"1.232129550","rc":[{"batb":[[0,1.37,10],[1,1.36,4],[2,1.35,31.27]],"ltp":1.4,"tv":175.83,"id":72857114},{"batb":[[0,1.32,10],[1,1.31,6.21],[2,1.27,1111.11]],"ltp":1.4,"tv":178.08,"id":72922097}]}]}
{"op":"mcm","clk":"11896367105","pt":1724342763477,"mc":[{"id":"1.232129550","rc":[{"batb":[[1,1.35,31.27],[2,1.34,882.35]],"ltp":1.4,"tv":175.83,"id":72857114},{"batb":[[0,1.33,4],[1,1.32,10],[2,1.31,6.21]],"ltp":1.4,"tv":178.08,"id":72922097}]}]}
{"op":"mcm","clk":"11896367339","pt":1724342765789,"mc":[{"id":"1.232129550","rc":[{"batb":[[0,1.36,4]],"ltp":1.4,"tv":175.83,"id":72857114},{"batb":[[0,1.31,6.21],[1,1.27,1111.11],[2,1.22,19.85]],"ltp":1.4,"tv":178.08,"id":72922097}]}]}
{"op":"mcm","clk":"11896367540","pt":1724342767794,"mc":[{"id":"1.232129550","rc":[{"batb":[[0,1.35,31.27],[1,1.34,882.35],[2,1.3,15]],"ltp":1.4,"tv":175.83,"id":72857114}]}]}
{"op":"mcm","clk":"11896367558","pt":1724342768008,"mc":[{"id":"1.232129550","rc":[{"batb":[[0,1.36,10],[1,1.35,31.27],[2,1.34,882.35]],"ltp":1.4,"tv":175.83,"id":72857114},{"batb":[[0,1.32,14],[1,1.31,6.21],[2,1.27,1111.11]],"ltp":1.4,"tv":178.08,"id":72922097}]}]}
{"op":"mcm","clk":"11896367808","pt":1724342770379,"mc":[{"id":"1.232129550","rc":[{"batb":[[0,1.37,4],[1,1.36,10],[2,1.35,31.27]],"ltp":1.4,"tv":175.83,"id":72857114},{"batb":[[0,1.32,10]],"ltp":1.4,"tv":178.08,"id":72922097}]}]}
{"op":"mcm","clk":"11896367905","pt":1724342771379,"mc":[{"id":"1.232129550","rc":[{"batb":[[1,1.35,31.27],[2,1.34,882.35]],"ltp":1.4,"tv":175.83,"id":72857114},{"batb":[[0,1.31,6.21],[1,1.27,1111.11],[2,1.22,19.85]],"ltp":1.4,"tv":178.08,"id":72922097}]}]}
{"op":"mcm","clk":"11896368175","pt":1724342773755,"mc":[{"id":"1.232129550","rc":[{"batb":[[0,1.36,10]],"ltp":1.4,"tv":175.83,"id":72857114},{"batb":[[0,1.33,10],[1,1.32,4],[2,1.31,6.21]],"ltp":1.4,"tv":178.08,"id":72922097}]}]}
{"op":"mcm","clk":"11896368421","pt":1724342775904,"mc":[{"id":"1.232129550","rc":[{"batb":[[0,1.37,4],[1,1.36,10],[2,1.35,31.27]],"ltp":1.4,"tv":175.83,"id":72857114},{"batb":[[1,1.31,6.21],[2,1.27,1111.11]],"ltp":1.4,"tv":178.08,"id":72922097}]}]}
{"op":"mcm","clk":"11896368541","pt":1724342777103,"mc":[{"id":"1.232129550","rc":[{"batb":[[1,1.35,31.27],[2,1.34,882.35]],"ltp":1.4,"tv":175.83,"id":72857114},{"batb":[[0,1.31,6.21],[1,1.27,1111.11],[2,1.22,19.85]],"ltp":1.4,"tv":178.08,"id":72922097}]}]}
{"op":"mcm","clk":"11896368675","pt":1724342778407,"mc":[{"id":"1.232129550","rc":[{"batb":[[0,1.35,31.27],[1,1.34,882.35],[2,1.3,15]],"ltp":1.4,"tv":175.83,"id":72857114},{"batb":[[0,1.32,4],[1,1.31,6.21],[2,1.27,1111.11]],"ltp":1.4,"tv":178.08,"id":72922097}]}]}
{"op":"mcm","clk":"11896368885","pt":1724342780610,"mc":[{"id":"1.232129550","rc":[{"batb":[[0,1.36,14],[1,1.35,31.27],[2,1.34,882.35]],"ltp":1.4,"tv":175.83,"id":72857114},{"batb":[[0,1.33,10]],"ltp":1.4,"tv":178.08,"id":72922097}]}]}
{"op":"mcm","clk":"11896369098","pt":1724342782702,"mc":[{"id":"1.232129550","rc":[{"batb":[[0,1.36,10]],"ltp":1.4,"tv":175.83,"id":72857114},{"batb":[[0,1.34,4],[1,1.33,10],[2,1.31,6.21]],"ltp":1.4,"tv":178.08,"id":72922097}]}]}
{"op":"mcm","clk":"11896369279","pt":1724342784284,"mc":[{"id":"1.232129550","rc":[{"batb":[[0,1.35,31.27],[1,1.34,882.35],[2,1.3,15]],"ltp":1.4,"tv":175.83,"id":72857114},{"batb":[[1,1.31,6.21],[2,1.27,1111.11]],"ltp":1.4,"tv":178.08,"id":72922097}]}]}
{"op":"mcm","clk":"11896369359","pt":1724342785118,"mc":[{"id":"1.232129550","rc":[{"batb":[[0,1.36,4],[1,1.35,31.27],[2,1.34,882.35]],"ltp":1.4,"tv":175.83,"id":72857114},{"batb":[[0,1.31,6.21],[1,1.27,1111.11],[2,1.22,19.85]],"ltp":1.4,"tv":178.08,"id":72922097}]}]}
{"op":"mcm","clk":"11896369625","pt":1724342787696,"mc":[{"id":"1.232129550","rc":[{"batb":[[0,1.36,10]],"ltp":1.4,"tv":175.83,"id":72857114},{"batb":[[0,1.32,14],[1,1.31,6.21],[2,1.27,1111.11]],"ltp":1.4,"tv":178.08,"id":72922097}]}]}
{"op":"mcm","clk":"11896369922","pt":1724342790892,"mc":[{"id":"1.232129550","rc":[{"batb":[[0,1.37,4]],"ltp":1.4,"tv":175.83,"id":72857114},{"batb":[[0,1.31,6.21],[1,1.27,1111.11],[2,1.22,19.85]],"ltp":1.4,"tv":178.08,"id":72922097}]}]}
{"op":"mcm","clk":"11896370079","pt":1724342792711,"mc":[{"id":"1.232129550","rc":[{"batb":[[0,1.35,31.27],[1,1.34,882.35],[2,1.3,15]],"ltp":1.4,"tv":175.83,"id":72857114},{"batb":[[0,1.32,4],[1,1.31,6.21],[2,1.27,1111.11]],"ltp":1.4,"tv":178.08,"id":72922097}]}]}
{"op":"mcm","clk":"11896370302","pt":1724342795120,"mc":[{"id":"1.232129550","rc":[{"batb":[[0,1.36,14],[1,1.35,31.27],[2,1.34,882.35]],"ltp":1.4,"tv":175.83,"id":72857114},{"batb":[[0,1.32,10]],"ltp":1.4,"tv":178.08,"id":72922097}]}]}
{"op":"mcm","clk":"11896370516","pt":1724342797718,"mc":[{"id":"1.232129550","rc":[{"batb":[[0,1.36,10]],"ltp":1.4,"tv":175.83,"id":72857114},{"batb":[[0,1.33,4],[1,1.32,10],[2,1.31,6.21]],"ltp":1.4,"tv":178.08,"id":72922097}]}]}
{"op":"mcm","clk":"11896370576","pt":1724342798541,"mc":[{"id":"1.232129550","rc":[{"batb":[[0,1.35,31.27],[1,1.34,882.35],[2,1.3,15]],"ltp":1.4,"tv":175.83,"id":72857114},{"batb":[[1,1.31,6.21],[2,1.27,1111.11]],"ltp":1.4,"tv":178.08,"id":72922097}]}]}
{"op":"mcm","clk":"11896370747","pt":1724342800319,"mc":[{"id":"1.232129550","rc":[{"batb":[[0,1.36,4],[1,1.35,31.27],[2,1.34,882.35]],"ltp":1.4,"tv":175.83,"id":72857114},{"batb":[[0,1.31,6.21],[1,1.27,1111.11],[2,1.22,19.85]],"ltp":1.4,"tv":178.08,"id":72922097}]}]}
{"op":"mcm","clk":"11896370959","pt":1724342802926,"mc":[{"id":"1.232129550","rc":[{"batb":[[0,1.36,10]],"ltp":1.4,"tv":175.83,"id":72857114},{"batb":[[0,1.32,14],[1,1.31,6.21],[2,1.27,1111.11]],"ltp":1.4,"tv":178.08,"id":72922097}]}]}
{"op":"mcm","clk":"11896371226","pt":1724342805844,"mc":[{"id":"1.232129550","rc":[{"batb":[[0,1.37,4],[1,1.36,10],[2,1.35,31.27]],"ltp":1.4,"tv":175.83,"id":72857114},{"batb":[[0,1.32,10]],"ltp":1.4,"tv":178.08,"id":72922097}]}]}
{"op":"mcm","clk":"11896371296","pt":1724342806629,"mc":[{"id":"1.232129550","rc":[{"batb":[[1,1.35,31.27],[2,1.34,882.35]],"ltp":1.4,"tv":175.83,"id":72857114},{"batb":[[0,1.31,6.21],[1,1.27,1111.11],[2,1.22,19.85]],"ltp":1.4,"tv":178.08,"id":72922097}]}]}
{"op":"mcm","clk":"11896371463","pt":1724342808346,"mc":[{"id":"1.232129550","rc":[{"batb":[[0,1.35,31.27],[1,1.34,882.35],[2,1.3,15]],"ltp":1.4,"tv":175.83,"id":72857114},{"batb":[[0,1.32,4],[1,1.31,6.21],[2,1.27,1111.11]],"ltp":1.4,"tv":178.08,"id":72922097}]}]}
{"op":"mcm","clk":"11896371689","pt":1724342810812,"mc":[{"id":"1.232129550","rc":[{"batb":[[0,1.36,14],[1,1.35,31.27],[2,1.34,882.35]],"ltp":1.4,"tv":175.83,"id":72857114},{"batb":[[0,1.32,10]],"ltp":1.4,"tv":178.08,"id":72922097}]}]}
{"op":"mcm","clk":"11896371901","pt":1724342813372,"mc":[{"id":"1.232129550","rc":[{"batb":[[0,1.36,10]],"ltp":1.4,"tv":175.83,"id":72857114},{"batb":[[0,1.33,4],[1,1.32,10],[2,1.31,6.21]],"ltp":1.4,"tv":178.08,"id":72922097}]}]}
{"op":"mcm","clk":"11896371970","pt":1724342814028,"mc":[{"id":"1.232129550","rc":[{"batb":[[0,1.35,31.27],[1,1.34,882.35],[2,1.3,15]],"ltp":1.4,"tv":175.83,"id":72857114},{"batb":[[1,1.31,6.21],[2,1.27,1111.11]],"ltp":1.4,"tv":178.08,"id":72922097}]}]}
{"op":"mcm","clk":"11896372180","pt":1724342815828,"mc":[{"id":"1.232129550","rc":[{"batb":[[0,1.36,4],[1,1.35,31.27],[2,1.34,882.35]],"ltp":1.4,"tv":175.83,"id":72857114},{"batb":[[0,1.31,6.21],[1,1.27,1111.11],[2,1.22,19.85]],"ltp":1.4,"tv":178.08,"id":72922097}]}]}
{"op":"mcm","clk":"11896372221","pt":1724342816267,"mc":[{"id":"1.232129550","rc":[{"batb":[[0,1.37,10],[1,1.36,4],[2,1.35,31.27]],"ltp":1.4,"tv":175.83,"id":72857114},{"batb":[[0,1.32,10],[1,1.31,6.21],[2,1.27,1111.11]],"ltp":1.4,"tv":178.08,"id":72922097}]}]}
{"op":"mcm","clk":"11896372414","pt":1724342818435,"mc":[{"id":"1.232129550","rc":[{"batb":[[1,1.35,31.27],[2,1.34,882.35]],"ltp":1.4,"tv":175.83,"id":72857114},{"batb":[[0,1.33,4],[1,1.32,10],[2,1.31,6.21]],"ltp":1.4,"tv":178.08,"id":72922097}]}]}
{"op":"mcm","clk":"11896372503","pt":1724342819531,"mc":[{"id":"1.232129550","rc":[{"batb":[[0,1.35,31.27],[1,1.34,882.35],[2,1.3,15]],"ltp":1.4,"tv":175.83,"id":72857114},{"batb":[[1,1.31,6.21],[2,1.27,1111.11]],"ltp":1.4,"tv":178.08,"id":72922097}]}]}
{"op":"mcm","clk":"11896372612","pt":1724342820824,"mc":[{"id":"1.232129550","rc":[{"batb":[[0,1.31,6.21],[1,1.27,1111.11],[2,1.22,19.85]],"ltp":1.4,"tv":178.08,"id":72922097}]}]}
{"op":"mcm","clk":"11896372626","pt":1724342821030,"mc":[{"id":"1.232129550","rc":[{"batb":[[0,1.36,4],[1,1.35,31.27],[2,1.34,882.35]],"ltp":1.4,"tv":175.83,"id":72857114}]}]}
{"op":"mcm","clk":"11896372831","pt":1724342823645,"mc":[{"id":"1.232129550","rc":[{"batb":[[0,1.36,10]],"ltp":1.4,"tv":175.83,"id":72857114},{"batb":[[0,1.32,14],[1,1.31,6.21],[2,1.27,1111.11]],"ltp":1.4,"tv":178.08,"id":72922097}]}]}
{"op":"mcm","clk":"11896373017","pt":1724342825827,"mc":[{"id":"1.232129550","rc":[{"batb":[[0,1.32,10]],"ltp":1.4,"tv":178.08,"id":72922097}]}]}
{"op":"mcm","clk":"11896373151","pt":1724342826889,"mc":[{"id":"1.232129550","rc":[{"batb":[[0,1.37,4]],"ltp":1.4,"tv":175.83,"id":72857114},{"batb":[[0,1.31,6.21],[1,1.27,1111.11],[2,1.22,19.85]],"ltp":1.4,"tv":178.08,"id":72922097}]}]}
{"op":"mcm","clk":"11896373278","pt":1724342828466,"mc":[{"id":"1.232129550","rc":[{"batb":[[0,1.35,31.27],[1,1.34,882.35],[2,1.3,15]],"ltp":1.4,"tv":175.83,"id":72857114},{"batb":[[0,1.32,4],[1,1.31,6.21],[2,1.27,1111.11]],"ltp":1.4,"tv":178.08,"id":72922097}]}]}
{"op":"mcm","clk":"11896373503","pt":1724342830867,"mc":[{"id":"1.232129550","rc":[{"batb":[[0,1.31,6.21],[1,1.27,1111.11],[2,1.22,19.85]],"ltp":1.4,"tv":178.08,"id":72922097}]}]}
{"op":"mcm","clk":"11896373512","pt":1724342830975,"mc":[{"id":"1.232129550","rc":[{"batb":[[0,1.36,14],[1,1.35,31.27],[2,1.34,882.35]],"ltp":1.4,"tv":175.83,"id":72857114},{"batb":[[0,1.32,10],[1,1.31,6.21],[2,1.27,1111.11]],"ltp":1.4,"tv":178.08,"id":72922097}]}]}
{"op":"mcm","clk":"11896373815","pt":1724342834262,"mc":[{"id":"1.232129550","rc":[{"batb":[[0,1.36,10]],"ltp":1.4,"tv":175.83,"id":72857114},{"batb":[[0,1.33,4],[1,1.32,10],[2,1.31,6.21]],"ltp":1.4,"tv":178.08,"id":72922097}]}]}
{"op":"mcm","clk":"11896373881","pt":1724342835043,"mc":[{"id":"1.232129550","rc":[{"batb":[[0,1.35,31.27],[1,1.34,882.35],[2,1.3,15]],"ltp":1.4,"tv":175.83,"id":72857114},{"batb":[[1,1.31,6.21],[2,1.27,1111.11]],"ltp":1.4,"tv":178.08,"id":72922097}]}]}
{"op":"mcm","clk":"11896374008","pt":1724342836656,"mc":[{"id":"1.232129550","rc":[{"batb":[[0,1.36,4],[1,1.35,31.27],[2,1.34,882.35]],"ltp":1.4,"tv":175.83,"id":72857114},{"batb":[[0,1.31,6.21],[1,1.27,1111.11],[2,1.22,19.85]],"ltp":1.4,"tv":178.08,"id":72922097}]}]}
{"op":"mcm","clk":"11896374225","pt":1724342838944,"mc":[{"id":"1.232129550","rc":[{"batb":[[0,1.35,31.27],[1,1.34,882.35],[2,1.3,15]],"ltp":1.4,"tv":175.83,"id":72857114}]}]}
{"op":"mcm","clk":"11896374243","pt":1724342839152,"mc":[{"id":"1.232129550","rc":[{"batb":[[0,1.36,10],[1,1.35,31.27],[2,1.34,882.35]],"ltp":1.4,"tv":175.83,"id":72857114},{"batb":[[0,1.32,14],[1,1.31,6.21],[2,1.27,1111.11]],"ltp":1.4,"tv":178.08,"id":72922097}]}]}
{"op":"mcm","clk":"11896374503","pt":1724342841768,"mc":[{"id":"1.232129550","rc":[{"batb":[[0,1.37,4],[1,1.36,10],[2,1.35,31.27]],"ltp":1.4,"tv":175.83,"id":72857114},{"batb":[[0,1.32,10]],"ltp":1.4,"tv":178.08,"id":72922097}]}]}
{"op":"mcm","clk":"11896374575","pt":1724342842345,"mc":[{"id":"1.232129550","rc":[{"batb":[[1,1.35,31.27],[2,1.34,882.35]],"ltp":1.4,"tv":175.83,"id":72857114},{"batb":[[0,1.31,6.21],[1,1.27,1111.11],[2,1.22,19.85]],"ltp":1.4,"tv":178.08,"id":72922097}]}]}
{"op":"mcm","clk":"11896374757","pt":1724342844185,"mc":[{"id":"1.232129550","rc":[{"batb":[[0,1.35,31.27],[1,1.34,882.35],[2,1.3,15]],"ltp":1.4,"tv":175.83,"id":72857114},{"batb":[[0,1.32,4],[1,1.31,6.21],[2,1.27,1111.11]],"ltp":1.4,"tv":178.08,"id":72922097}]}]}
{"op":"mcm","clk":"11896374989","pt":1724342846577,"mc":[{"id":"1.232129550","rc":[{"batb":[[0,1.36,14],[1,1.35,31.27],[2,1.34,882.35]],"ltp":1.4,"tv":175.83,"id":72857114},{"batb":[[0,1.32,10]],"ltp":1.4,"tv":178.08,"id":72922097}]}]}
{"op":"mcm","clk":"11896375209","pt":1724342848880,"mc":[{"id":"1.232129550","rc":[{"batb":[[0,1.36,10]],"ltp":1.4,"tv":175.83,"id":72857114}]}]}
{"op":"mcm","clk":"11896375296","pt":1724342849768,"mc":[{"id":"1.232129550","rc":[{"batb":[[0,1.33,4]],"ltp":1.4,"tv":178.08,"id":72922097}]}]}
{"op":"mcm","clk":"11896375327","pt":1724342850094,"mc":[{"id":"1.232129550","rc":[{"batb":[[0,1.35,31.27],[1,1.34,882.35],[2,1.3,15]],"ltp":1.4,"tv":175.83,"id":72857114}]}]}
{"op":"mcm","clk":"11896375444","pt":1724342851635,"mc":[{"id":"1.232129550","rc":[{"batb":[[0,1.36,4],[1,1.35,31.27],[2,1.34,882.35]],"ltp":1.4,"tv":175.83,"id":72857114},{"batb":[[0,1.31,6.21],[1,1.27,1111.11],[2,1.22,19.85]],"ltp":1.4,"tv":178.08,"id":72922097}]}]}
{"op":"mcm","clk":"11896375615","pt":1724342853571,"mc":[{"id":"1.232129550","rc":[{"batb":[[0,1.37,10],[1,1.36,4],[2,1.35,31.27]],"ltp":1.4,"tv":175.83,"id":72857114},{"batb":[[0,1.32,14],[1,1.31,6.21],[2,1.27,1111.11]],"ltp":1.4,"tv":178.08,"id":72922097}]}]}
{"op":"mcm","clk":"11896375647","pt":1724342853980,"mc":[{"id":"1.232129550","rc":[{"batb":[[1,1.35,31.27],[2,1.34,882.35]],"ltp":1.4,"tv":175.83,"id":72857114}]}]}
{"op":"mcm","clk":"11896375831","pt":1724342855903,"mc":[{"id":"1.232129550","rc":[{"batb":[[0,1.32,10]],"ltp":1.4,"tv":178.08,"id":72922097}]}]}
{"op":"mcm","clk":"11896375938","pt":1724342857202,"mc":[{"id":"1.232129550","rc":[{"batb":[[0,1.36,4]],"ltp":1.4,"tv":175.83,"id":72857114},{"batb":[[0,1.31,6.21],[1,1.27,1111.11],[2,1.22,19.85]],"ltp":1.4,"tv":178.08,"id":72922097}]}]}
{"op":"mcm","clk":"11896376158","pt":1724342859905,"mc":[{"id":"1.232129550","rc":[{"batb":[[0,1.36,10]],"ltp":1.4,"tv":175.83,"id":72857114},{"batb":[[0,1.32,14],[1,1.31,6.21],[2,1.27,1111.11]],"ltp":1.4,"tv":178.08,"id":72922097}]}]}
{"op":"mcm","clk":"11896376383","pt":1724342862614,"mc":[{"id":"1.232129550","rc":[{"batb":[[0,1.37,4],[1,1.36,10],[2,1.35,31.27]],"ltp":1.4,"tv":175.83,"id":72857114},{"batb":[[0,1.32,10]],"ltp":1.4,"tv":178.08,"id":72922097}]}]}
{"op":"mcm","clk":"11896376432","pt":1724342863298,"mc":[{"id":"1.232129550","rc":[{"batb":[[1,1.35,31.27],[2,1.34,882.35]],"ltp":1.4,"tv":175.83,"id":72857114},{"batb":[[0,1.31,6.21],[1,1.27,1111.11],[2,1.22,19.85]],"ltp":1.4,"tv":178.08,"id":72922097}]}]}
{"op":"mcm","clk":"11896376538","pt":1724342864798,"mc":[{"id":"1.232129550","rc":[{"batb":[[0,1.35,31.27],[1,1.34,882.35],[2,1.3,15]],"ltp":1.4,"tv":175.83,"id":72857114}]}]}
{"op":"mcm","clk":"11896376557","pt":1724342865008,"mc":[{"id":"1.232129550","rc":[{"batb":[[0,1.32,4],[1,1.31,6.21],[2,1.27,1111.11]],"ltp":1.4,"tv":178.08,"id":72922097}]}]}
{"op":"mcm","clk":"11896376775","pt":1724342867514,"mc":[{"id":"1.232129550","rc":[{"batb":[[0,1.36,14],[1,1.35,31.27],[2,1.34,882.35]],"ltp":1.4,"tv":175.83,"id":72857114},{"batb":[[0,1.32,10]],"ltp":1.4,"tv":178.08,"id":72922097}]}]}
{"op":"mcm","clk":"11896377023","pt":1724342869846,"mc":[{"id":"1.232129550","rc":[{"batb":[[0,1.36,10]],"ltp":1.4,"tv":175.83,"id":72857114}]}]}
{"op":"mcm","clk":"11896377141","pt":1724342870830,"mc":[{"id":"1.232129550","rc":[{"batb":[[0,1.35,31.27],[1,1.34,882.35],[2,1.3,15]],"ltp":1.4,"tv":175.83,"id":72857114},{"batb":[[0,1.33,4]],"ltp":1.4,"tv":178.08,"id":72922097}]}]}
{"op":"mcm","clk":"11896377299","pt":1724342872519,"mc":[{"id":"1.232129550","rc":[{"batb":[[0,1.36,4],[1,1.35,31.27],[2,1.34,882.35]],"ltp":1.4,"tv":175.83,"id":72857114},{"batb":[[0,1.31,6.21],[1,1.27,1111.11],[2,1.22,19.85]],"ltp":1.4,"tv":178.08,"id":72922097}]}]}
{"op":"mcm","clk":"11896377523","pt":1724342874815,"mc":[{"id":"1.232129550","rc":[{"batb":[[0,1.35,31.27],[1,1.34,882.35],[2,1.3,15]],"ltp":1.4,"tv":175.83,"id":72857114}]}]}
{"op":"mcm","clk":"11896377543","pt":1724342875009,"mc":[{"id":"1.232129550","rc":[{"batb":[[0,1.36,10],[1,1.35,31.27],[2,1.34,882.35]],"ltp":1.4,"tv":175.83,"id":72857114},{"batb":[[0,1.32,14],[1,1.31,6.21],[2,1.27,1111.11]],"ltp":1.4,"tv":178.08,"id":72922097}]}]}
{"op":"mcm","clk":"11896377773","pt":1724342877417,"mc":[{"id":"1.232129550","rc":[{"batb":[[0,1.37,4],[1,1.36,10],[2,1.35,31.27]],"ltp":1.4,"tv":175.83,"id":72857114},{"batb":[[0,1.32,10]],"ltp":1.4,"tv":178.08,"id":72922097}]}]}
{"op":"mcm","clk":"11896377847","pt":1724342878236,"mc":[{"id":"1.232129550","rc":[{"batb":[[1,1.35,31.27],[2,1.34,882.35]],"ltp":1.4,"tv":175.83,"id":72857114},{"batb":[[0,1.31,6.21],[1,1.27,1111.11],[2,1.22,19.85]],"ltp":1.4,"tv":178.08,"id":72922097}]}]}
{"op":"mcm","clk":"11896377986","pt":1724342879737,"mc":[{"id":"1.232129550","rc":[{"batb":[[0,1.35,31.27],[1,1.34,882.35],[2,1.3,15]],"ltp":1.4,"tv":175.83,"id":72857114},{"batb":[[0,1.32,4],[1,1.31,6.21],[2,1.27,1111.11]],"ltp":1.4,"tv":178.08,"id":72922097}]}]}
{"op":"mcm","clk":"11896378151","pt":1724342881623,"mc":[{"id":"1.232129550","rc":[{"batb":[[0,1.36,10],[1,1.35,31.27],[2,1.34,882.35]],"ltp":1.4,"tv":175.83,"id":72857114},{"batb":[[0,1.33,10],[1,1.32,4],[2,1.31,6.21]],"ltp":1.4,"tv":178.08,"id":72922097}]}]}
{"op":"mcm","clk":"11896378196","pt":1724342882245,"mc":[{"id":"1.232129550","rc":[{"batb":[[0,1.37,4],[1,1.36,10],[2,1.35,31.27]],"ltp":1.4,"tv":175.83,"id":72857114},{"batb":[[1,1.31,6.21],[2,1.27,1111.11]],"ltp":1.4,"tv":178.08,"id":72922097}]}]}
{"op":"mcm","clk":"11896378425","pt":1724342884720,"mc":[{"id":"1.232129550","rc":[{"batb":[[0,1.36,10],[1,1.35,31.27],[2,1.34,882.35]],"ltp":1.4,"tv":175.83,"id":72857114},{"batb":[[0,1.34,4],[1,1.33,10],[2,1.31,6.21]],"ltp":1.4,"tv":178.08,"id":72922097}]}]}
{"op":"mcm","clk":"11896378452","pt":1724342885027,"mc":[{"id":"1.232129550","rc":[{"batb":[[0,1.35,31.27],[1,1.34,882.35],[2,1.3,15]],"ltp":1.4,"tv":175.83,"id":72857114},{"batb":[[1,1.31,6.21],[2,1.27,1111.11]],"ltp":1.4,"tv":178.08,"id":72922097}]}]}
{"op":"mcm","clk":"11896378620","pt":1724342886952,"mc":[{"id":"1.232129550","rc":[{"batb":[[0,1.31,6.21],[1,1.27,1111.11],[2,1.22,19.85]],"ltp":1.4,"tv":178.08,"id":72922097}]}]}
{"op":"mcm","clk":"11896378655","pt":1724342887333,"mc":[{"id":"1.232129550","rc":[{"batb":[[0,1.37,10],[1,1.36,4],[2,1.35,31.27]],"ltp":1.4,"tv":175.83,"id":72857114},{"batb":[[0,1.32,10],[1,1.31,6.21],[2,1.27,1111.11]],"ltp":1.4,"tv":178.08,"id":72922097}]}]}
{"op":"mcm","clk":"11896378841","pt":1724342889659,"mc":[{"id":"1.232129550","rc":[{"batb":[[1,1.35,31.27],[2,1.34,882.35]],"ltp":1.4,"tv":175.83,"id":72857114},{"batb":[[0,1.33,4],[1,1.32,10],[2,1.31,6.21]],"ltp":1.4,"tv":178.08,"id":72922097}]}]}
{"op":"mcm","clk":"11896378919","pt":1724342890759,"mc":[{"id":"1.232129550","rc":[{"batb":[[0,1.35,31.27],[1,1.34,882.35],[2,1.3,15]],"ltp":1.4,"tv":175.83,"id":72857114},{"batb":[[1,1.31,6.21],[2,1.27,1111.11]],"ltp":1.4,"tv":178.08,"id":72922097}]}]}
{"op":"mcm","clk":"11896379018","pt":1724342891958,"mc":[{"id":"1.232129550","rc":[{"batb":[[0,1.31,6.21],[1,1.27,1111.11],[2,1.22,19.85]],"ltp":1.4,"tv":178.08,"id":72922097}]}]}
{"op":"mcm","clk":"11896379025","pt":1724342892059,"mc":[{"id":"1.232129550","rc":[{"batb":[[0,1.36,4],[1,1.35,31.27],[2,1.34,882.35]],"ltp":1.4,"tv":175.83,"id":72857114}]}]}
{"op":"mcm","clk":"11896379262","pt":1724342894736,"mc":[{"id":"1.232129550","rc":[{"batb":[[0,1.36,10]],"ltp":1.4,"tv":175.83,"id":72857114},{"batb":[[0,1.32,14],[1,1.31,6.21],[2,1.27,1111.11]],"ltp":1.4,"tv":178.08,"id":72922097}]}]}
{"op":"mcm","clk":"11896379500","pt":1724342897140,"mc":[{"id":"1.232129550","rc":[{"batb":[[0,1.37,4],[1,1.36,10],[2,1.35,31.27]],"ltp":1.4,"tv":175.83,"id":72857114},{"batb":[[0,1.32,10]],"ltp":1.4,"tv":178.08,"id":72922097}]}]}
{"op":"mcm","clk":"11896379594","pt":1724342898274,"mc":[{"id":"1.232129550","rc":[{"batb":[[1,1.35,31.27],[2,1.34,882.35]],"ltp":1.4,"tv":175.83,"id":72857114},{"batb":[[0,1.31,6.21],[1,1.27,1111.11],[2,1.22,19.85]],"ltp":1.4,"tv":178.08,"id":72922097}]}]}
{"op":"mcm","clk":"11896379711","pt":1724342899580,"mc":[{"id":"1.232129550","rc":[{"batb":[[0,1.35,31.27],[1,1.34,882.35],[2,1.3,15]],"ltp":1.4,"tv":175.83,"id":72857114},{"batb":[[0,1.32,4],[1,1.31,6.21],[2,1.27,1111.11]],"ltp":1.4,"tv":178.08,"id":72922097}]}]}
{"op":"mcm","clk":"11896379945","pt":1724342902266,"mc":[{"id":"1.232129550","rc":[{"batb":[[0,1.36,14],[1,1.35,31.27],[2,1.34,882.35]],"ltp":1.4,"tv":175.83,"id":72857114},{"batb":[[0,1.32,10]],"ltp":1.4,"tv":178.08,"id":72922097}]}]}
{"op":"mcm","clk":"11896380129","pt":1724342904554,"mc":[{"id":"1.232129550","rc":[{"batb":[[0,1.36,10]],"ltp":1.4,"tv":175.83,"id":72857114},{"batb":[[0,1.33,4],[1,1.32,10],[2,1.31,6.21]],"ltp":1.4,"tv":178.08,"id":72922097}]}]}
{"op":"mcm","clk":"11896380202","pt":1724342905560,"mc":[{"id":"1.232129550","rc":[{"batb":[[0,1.35,31.27],[1,1.34,882.35],[2,1.3,15]],"ltp":1.4,"tv":175.83,"id":72857114},{"batb":[[1,1.31,6.21],[2,1.27,1111.11]],"ltp":1.4,"tv":178.08,"id":72922097}]}]}
{"op":"mcm","clk":"11896380326","pt":1724342907277,"mc":[{"id":"1.232129550","rc":[{"batb":[[0,1.36,4],[1,1.35,31.27],[2,1.34,882.35]],"ltp":1.4,"tv":175.83,"id":72857114},{"batb":[[0,1.31,6.21],[1,1.27,1111.11],[2,1.22,19.85]],"ltp":1.4,"tv":178.08,"id":72922097}]}]}
{"op":"mcm","clk":"11896380588","pt":1724342909867,"mc":[{"id":"1.232129550","rc":[{"batb":[[0,1.36,10]],"ltp":1.4,"tv":175.83,"id":72857114},{"batb":[[0,1.32,14],[1,1.31,6.21],[2,1.27,1111.11]],"ltp":1.4,"tv":178.08,"id":72922097}]}]}
{"op":"mcm","clk":"11896380827","pt":1724342912278,"mc":[{"id":"1.232129550","rc":[{"batb":[[0,1.37,4],[1,1.36,10],[2,1.35,31.27]],"ltp":1.4,"tv":175.83,"id":72857114},{"batb":[[0,1.32,10]],"ltp":1.4,"tv":178.08,"id":72922097}]}]}
{"op":"mcm","clk":"11896380922","pt":1724342913282,"mc":[{"id":"1.232129550","rc":[{"batb":[[1,1.35,31.27],[2,1.34,882.35]],"ltp":1.4,"tv":175.83,"id":72857114},{"batb":[[0,1.31,6.21],[1,1.27,1111.11],[2,1.22,19.85]],"ltp":1.4,"tv":178.08,"id":72922097}]}]}
{"op":"mcm","clk":"11896381078","pt":1724342914688,"mc":[{"id":"1.232129550","rc":[{"batb":[[0,1.35,31.27],[1,1.34,882.35],[2,1.3,15]],"ltp":1.4,"tv":175.83,"id":72857114}]}]}
{"op":"mcm","clk":"11896381126","pt":1724342915078,"mc":[{"id":"1.232129550","rc":[{"batb":[[0,1.32,4],[1,1.31,6.21],[2,1.27,1111.11]],"ltp":1.4,"tv":178.08,"id":72922097}]}]}
{"op":"mcm","clk":"11896381215","pt":1724342916175,"mc":[{"id":"1.232129550","rc":[{"batb":[[0,1.36,10],[1,1.35,31.27],[2,1.34,882.35]],"ltp":1.4,"tv":175.83,"id":72857114},{"batb":[[0,1.33,10],[1,1.32,4],[2,1.31,6.21]],"ltp":1.4,"tv":178.08,"id":72922097}]}]}
{"op":"mcm","clk":"11896381317","pt":1724342917384,"mc":[{"id":"1.232129550","rc":[{"batb":[[0,1.37,4],[1,1.36,10],[2,1.35,31.27]],"ltp":1.4,"tv":175.83,"id":72857114},{"batb":[[1,1.31,6.21],[2,1.27,1111.11]],"ltp":1.4,"tv":178.08,"id":72922097}]}]}
{"op":"mcm","clk":"11896381564","pt":1724342919869,"mc":[{"id":"1.232129550","rc":[{"batb":[[0,1.35,31.27],[1,1.34,882.35],[2,1.3,15]],"ltp":1.4,"tv":175.83,"id":72857114},{"batb":[[0,1.32,4]],"ltp":1.4,"tv":178.08,"id":72922097}]}]}
{"op":"mcm","clk":"11896381745","pt":1724342922168,"mc":[{"id":"1.232129550","rc":[{"batb":[[0,1.36,14],[1,1.35,31.27],[2,1.34,882.35]],"ltp":1.4,"tv":175.83,"id":72857114},{"batb":[[0,1.32,10]],"ltp":1.4,"tv":178.08,"id":72922097}]}]}
{"op":"mcm","clk":"11896381954","pt":1724342924774,"mc":[{"id":"1.232129550","rc":[{"batb":[[0,1.36,10]],"ltp":1.4,"tv":175.83,"id":72857114},{"batb":[[0,1.33,4],[1,1.32,10],[2,1.31,6.21]],"ltp":1.4,"tv":178.08,"id":72922097}]}]}
{"op":"mcm","clk":"11896382039","pt":1724342925592,"mc":[{"id":"1.232129550","rc":[{"batb":[[0,1.35,31.27],[1,1.34,882.35],[2,1.3,15]],"ltp":1.4,"tv":175.83,"id":72857114},{"batb":[[1,1.31,6.21],[2,1.27,1111.11]],"ltp":1.4,"tv":178.08,"id":72922097}]}]}
{"op":"mcm","clk":"11896382170","pt":1724342927204,"mc":[{"id":"1.232129550","rc":[{"batb":[[0,1.36,4],[1,1.35,31.27],[2,1.34,882.35]],"ltp":1.4,"tv":175.83,"id":72857114},{"batb":[[0,1.31,6.21],[1,1.27,1111.11],[2,1.22,19.85]],"ltp":1.4,"tv":178.08,"id":72922097}]}]}
{"op":"mcm","clk":"11896382373","pt":1724342929807,"mc":[{"id":"1.232129550","rc":[{"batb":[[0,1.36,10]],"ltp":1.4,"tv":175.83,"id":72857114},{"batb":[[0,1.32,14],[1,1.31,6.21],[2,1.27,1111.11]],"ltp":1.4,"tv":178.08,"id":72922097}]}]}
{"op":"mcm","clk":"11896382543","pt":1724342932281,"mc":[{"id":"1.232129550","rc":[{"batb":[[0,1.37,4],[1,1.36,10],[2,1.35,31.27]],"ltp":1.4,"tv":175.83,"id":72857114},{"batb":[[0,1.32,10]],"ltp":1.4,"tv":178.08,"id":72922097}]}]}
{"op":"mcm","clk":"11896382607","pt":1724342933105,"mc":[{"id":"1.232129550","rc":[{"batb":[[1,1.35,31.27],[2,1.34,882.35]],"ltp":1.4,"tv":175.83,"id":72857114},{"batb":[[0,1.31,6.21],[1,1.27,1111.11],[2,1.22,19.85]],"ltp":1.4,"tv":178.08,"id":72922097}]}]}
{"op":"mcm","clk":"11896382739","pt":1724342934717,"mc":[{"id":"1.232129550","rc":[{"batb":[[0,1.35,31.27],[1,1.34,882.35],[2,1.3,15]],"ltp":1.4,"tv":175.83,"id":72857114},{"batb":[[0,1.32,4],[1,1.31,6.21],[2,1.27,1111.11]],"ltp":1.4,"tv":178.08,"id":72922097}]}]}
{"op":"mcm","clk":"11896382960","pt":1724342937396,"mc":[{"id":"1.232129550","rc":[{"batb":[[0,1.36,14],[1,1.35,31.27],[2,1.34,882.35]],"ltp":1.4,"tv":175.83,"id":72857114},{"batb":[[0,1.32,10]],"ltp":1.4,"tv":178.08,"id":72922097}]}]}
{"op":"mcm","clk":"11896383180","pt":1724342939919,"mc":[{"id":"1.232129550","rc":[{"batb":[[0,1.36,10]],"ltp":1.4,"tv":175.83,"id":72857114},{"batb":[[0,1.33,4],[1,1.32,10],[2,1.31,6.21]],"ltp":1.4,"tv":178.08,"id":72922097}]}]}
{"op":"mcm","clk":"11896383259","pt":1724342940718,"mc":[{"id":"1.232129550","rc":[{"batb":[[0,1.35,31.27],[1,1.34,882.35],[2,1.3,15]],"ltp":1.4,"tv":175.83,"id":72857114},{"batb":[[1,1.31,6.21],[2,1.27,1111.11]],"ltp":1.4,"tv":178.08,"id":72922097}]}]}
{"op":"mcm","clk":"11896383392","pt":1724342942329,"mc":[{"id":"1.232129550","rc":[{"batb":[[0,1.36,4],[1,1.35,31.27],[2,1.34,882.35]],"ltp":1.4,"tv":175.83,"id":72857114},{"batb":[[0,1.31,6.21],[1,1.27,1111.11],[2,1.22,19.85]],"ltp":1.4,"tv":178.08,"id":72922097}]}]}
{"op":"mcm","clk":"11896383474","pt":1724342943435,"mc":[{"id":"1.232129550","rc":[{"batb":[[0,1.37,10],[1,1.36,4],[2,1.35,31.27]],"ltp":1.4,"tv":175.83,"id":72857114},{"batb":[[0,1.32,10],[1,1.31,6.21],[2,1.27,1111.11]],"ltp":1.4,"tv":178.08,"id":72922097}]}]}
{"op":"mcm","clk":"11896383595","pt":1724342944820,"mc":[{"id":"1.232129550","rc":[{"batb":[[1,1.35,31.27],[2,1.34,882.35]],"ltp":1.4,"tv":175.83,"id":72857114},{"batb":[[0,1.33,4],[1,1.32,10],[2,1.31,6.21]],"ltp":1.4,"tv":178.08,"id":72922097}]}]}
{"op":"mcm","clk":"11896383764","pt":1724342946710,"mc":[{"id":"1.232129550","rc":[{"batb":[[0,1.35,31.27],[1,1.34,882.35],[2,1.3,15]],"ltp":1.4,"tv":175.83,"id":72857114},{"batb":[[1,1.31,6.21],[2,1.27,1111.11]],"ltp":1.4,"tv":178.08,"id":72922097}]}]}
{"op":"mcm","clk":"11896383792","pt":1724342947021,"mc":[{"id":"1.232129550","rc":[{"batb":[[0,1.36,4],[1,1.35,31.27],[2,1.34,882.35]],"ltp":1.4,"tv":175.83,"id":72857114},{"batb":[[0,1.31,6.21],[1,1.27,1111.11],[2,1.22,19.85]],"ltp":1.4,"tv":178.08,"id":72922097}]}]}
{"op":"mcm","clk":"11896384025","pt":1724342949642,"mc":[{"id":"1.232129550","rc":[{"batb":[[0,1.36,10]],"ltp":1.4,"tv":175.83,"id":72857114},{"batb":[[0,1.32,14],[1,1.31,6.21],[2,1.27,1111.11]],"ltp":1.4,"tv":178.08,"id":72922097}]}]}
{"op":"mcm","clk":"11896384232","pt":1724342951946,"mc":[{"id":"1.232129550","rc":[{"batb":[[0,1.32,10]],"ltp":1.4,"tv":178.08,"id":72922097}]}]}
{"op":"mcm","clk":"11896384325","pt":1724342952941,"mc":[{"id":"1.232129550","rc":[{"batb":[[0,1.37,4]],"ltp":1.4,"tv":175.83,"id":72857114},{"batb":[[0,1.31,6.21],[1,1.27,1111.11],[2,1.22,19.85]],"ltp":1.4,"tv":178.08,"id":72922097}]}]}
{"op":"mcm","clk":"11896384476","pt":1724342954818,"mc":[{"id":"1.232129550","rc":[{"batb":[[0,1.35,31.27],[1,1.34,882.35],[2,1.3,15]],"ltp":1.4,"tv":175.83,"id":72857114},{"batb":[[0,1.32,4],[1,1.31,6.21],[2,1.27,1111.11]],"ltp":1.4,"tv":178.08,"id":72922097}]}]}
{"op":"mcm","clk":"11896384720","pt":1724342957261,"mc":[{"id":"1.232129550","rc":[{"batb":[[0,1.36,14],[1,1.35,31.27],[2,1.34,882.35]],"ltp":1.4,"tv":175.83,"id":72857114},{"batb":[[0,1.32,10]],"ltp":1.4,"tv":178.08,"id":72922097}]}]}
{"op":"mcm","clk":"11896385003","pt":1724342959736,"mc":[{"id":"1.232129550","rc":[{"batb":[[0,1.36,10]],"ltp":1.4,"tv":175.83,"id":72857114},{"batb":[[0,1.33,4],[1,1.32,10],[2,1.31,6.21]],"ltp":1.4,"tv":178.08,"id":72922097}]}]}
{"op":"mcm","clk":"11896385063","pt":1724342960561,"mc":[{"id":"1.232129550","rc":[{"batb":[[0,1.35,31.27],[1,1.34,882.35],[2,1.3,15]],"ltp":1.4,"tv":175.83,"id":72857114},{"batb":[[1,1.31,6.21],[2,1.27,1111.11]],"ltp":1.4,"tv":178.08,"id":72922097}]}]}
{"op":"mcm","clk":"11896385248","pt":1724342962462,"mc":[{"id":"1.232129550","rc":[{"batb":[[0,1.36,4],[1,1.35,31.27],[2,1.34,882.35]],"ltp":1.4,"tv":175.83,"id":72857114},{"batb":[[0,1.31,6.21],[1,1.27,1111.11],[2,1.22,19.85]],"ltp":1.4,"tv":178.08,"id":72922097}]}]}
{"op":"mcm","clk":"11896385460","pt":1724342964944,"mc":[{"id":"1.232129550","rc":[{"batb":[[0,1.36,10]],"ltp":1.4,"tv":175.83,"id":72857114},{"batb":[[0,1.32,14],[1,1.31,6.21],[2,1.27,1111.11]],"ltp":1.4,"tv":178.08,"id":72922097}]}]}
{"op":"mcm","clk":"11896385682","pt":1724342967537,"mc":[{"id":"1.232129550","rc":[{"batb":[[0,1.37,4],[1,1.36,10],[2,1.35,31.27]],"ltp":1.4,"tv":175.83,"id":72857114},{"batb":[[0,1.32,10]],"ltp":1.4,"tv":178.08,"id":72922097}]}]}
{"op":"mcm","clk":"11896385733","pt":1724342968256,"mc":[{"id":"1.232129550","rc":[{"batb":[[1,1.35,31.27],[2,1.34,882.35]],"ltp":1.4,"tv":175.83,"id":72857114},{"batb":[[0,1.31,6.21],[1,1.27,1111.11],[2,1.22,19.85]],"ltp":1.4,"tv":178.08,"id":72922097}]}]}
{"op":"mcm","clk":"11896385871","pt":1724342969846,"mc":[{"id":"1.232129550","rc":[{"batb":[[0,1.32,4],[1,1.31,6.21],[2,1.27,1111.11]],"ltp":1.4,"tv":178.08,"id":72922097}]}]}
{"op":"mcm","clk":"11896385899","pt":1724342970162,"mc":[{"id":"1.232129550","rc":[{"batb":[[0,1.35,31.27],[1,1.34,882.35],[2,1.3,15]],"ltp":1.4,"tv":175.83,"id":72857114}]}]}
{"op":"mcm","clk":"11896386114","pt":1724342972346,"mc":[{"id":"1.232129550","rc":[{"batb":[[0,1.36,14],[1,1.35,31.27],[2,1.34,882.35]],"ltp":1.4,"tv":175.83,"id":72857114},{"batb":[[0,1.32,10]],"ltp":1.4,"tv":178.08,"id":72922097}]}]}
{"op":"mcm","clk":"11896386386","pt":1724342974879,"mc":[{"id":"1.232129550","rc":[{"batb":[[0,1.36,10]],"ltp":1.4,"tv":175.83,"id":72857114},{"batb":[[0,1.33,4],[1,1.32,10],[2,1.31,6.21]],"ltp":1.4,"tv":178.08,"id":72922097}]}]}
{"op":"mcm","clk":"11896386474","pt":1724342975672,"mc":[{"id":"1.232129550","rc":[{"batb":[[0,1.35,31.27],[1,1.34,882.35],[2,1.3,15]],"ltp":1.4,"tv":175.83,"id":72857114},{"batb":[[1,1.31,6.21],[2,1.27,1111.11]],"ltp":1.4,"tv":178.08,"id":72922097}]}]}
{"op":"mcm","clk":"11896386660","pt":1724342977877,"mc":[{"id":"1.232129550","rc":[{"batb":[[0,1.36,4],[1,1.35,31.27],[2,1.34,882.35]],"ltp":1.4,"tv":175.83,"id":72857114},{"batb":[[0,1.31,6.21],[1,1.27,1111.11],[2,1.22,19.85]],"ltp":1.4,"tv":178.08,"id":72922097}]}]}
{"op":"mcm","clk":"11896386808","pt":1724342979458,"mc":[{"id":"1.232129550","rc":[{"batb":[[0,1.36,10]],"ltp":1.4,"tv":175.83,"id":72857114},{"batb":[[0,1.32,14],[1,1.31,6.21],[2,1.27,1111.11]],"ltp":1.4,"tv":178.08,"id":72922097}]}]}
{"op":"mcm","clk":"11896387088","pt":1724342981891,"mc":[{"id":"1.232129550","rc":[{"batb":[[0,1.37,4],[1,1.36,10],[2,1.35,31.27]],"ltp":1.4,"tv":175.83,"id":72857114},{"batb":[[0,1.32,10]],"ltp":1.4,"tv":178.08,"id":72922097}]}]}
{"op":"mcm","clk":"11896387181","pt":1724342982784,"mc":[{"id":"1.232129550","rc":[{"batb":[[1,1.35,31.27],[2,1.34,882.35]],"ltp":1.4,"tv":175.83,"id":72857114},{"batb":[[0,1.31,6.21],[1,1.27,1111.11],[2,1.22,19.85]],"ltp":1.4,"tv":178.08,"id":72922097}]}]}
{"op":"mcm","clk":"11896387346","pt":1724342984467,"mc":[{"id":"1.232129550","rc":[{"batb":[[0,1.35,31.27],[1,1.34,882.35],[2,1.3,15]],"ltp":1.4,"tv":175.83,"id":72857114},{"batb":[[0,1.32,4],[1,1.31,6.21],[2,1.27,1111.11]],"ltp":1.4,"tv":178.08,"id":72922097}]}]}
{"op":"mcm","clk":"11896387543","pt":1724342986875,"mc":[{"id":"1.232129550","rc":[{"batb":[[0,1.36,14],[1,1.35,31.27],[2,1.34,882.35]],"ltp":1.4,"tv":175.83,"id":72857114},{"batb":[[0,1.32,10]],"ltp":1.4,"tv":178.08,"id":72922097}]}]}
{"op":"mcm","clk":"11896387765","pt":1724342989294,"mc":[{"id":"1.232129550","rc":[{"batb":[[0,1.36,10]],"ltp":1.4,"tv":175.83,"id":72857114},{"batb":[[0,1.33,4],[1,1.32,10],[2,1.31,6.21]],"ltp":1.4,"tv":178.08,"id":72922097}]}]}
{"op":"mcm","clk":"11896387834","pt":1724342990139,"mc":[{"id":"1.232129550","rc":[{"batb":[[0,1.35,31.27],[1,1.34,882.35],[2,1.3,15]],"ltp":1.4,"tv":175.83,"id":72857114},{"batb":[[1,1.31,6.21],[2,1.27,1111.11]],"ltp":1.4,"tv":178.08,"id":72922097}]}]}
{"op":"mcm","clk":"11896388024","pt":1724342991874,"mc":[{"id":"1.232129550","rc":[{"batb":[[0,1.36,4],[1,1.35,31.27],[2,1.34,882.35]],"ltp":1.4,"tv":175.83,"id":72857114},{"batb":[[0,1.31,6.21],[1,1.27,1111.11],[2,1.22,19.85]],"ltp":1.4,"tv":178.08,"id":72922097}]}]}
{"op":"mcm","clk":"11896388469","pt":1724342996183,"mc":[{"id":"1.232129550","rc":[{"batb":[[0,1.37,10]],"ltp":1.4,"tv":175.83,"id":72857114},{"batb":[[0,1.32,14],[1,1.31,6.21],[2,1.27,1111.11]],"ltp":1.4,"tv":178.08,"id":72922097}]}]}
{"op":"mcm","clk":"11896388733","pt":1724342998802,"mc":[{"id":"1.232129550","rc":[{"batb":[[0,1.32,10]],"ltp":1.4,"tv":178.08,"id":72922097}]}]}
{"op":"mcm","clk":"11896388817","pt":1724342999569,"mc":[{"id":"1.232129550","rc":[{"batb":[[0,1.38,4]],"ltp":1.4,"tv":175.83,"id":72857114},{"batb":[[0,1.31,6.21],[1,1.27,1111.11],[2,1.22,19.85]],"ltp":1.4,"tv":178.08,"id":72922097}]}]}
{"op":"mcm","clk":"11896389022","pt":1724343001903,"mc":[{"id":"1.232129550","rc":[{"batb":[[0,1.35,31.27],[1,1.34,882.35],[2,1.3,15]],"ltp":1.4,"tv":175.83,"id":72857114}]}]}
{"op":"mcm","clk":"11896389042","pt":1724343002111,"mc":[{"id":"1.232129550","rc":[{"batb":[[0,1.36,10],[1,1.35,31.27],[2,1.34,882.35]],"ltp":1.4,"tv":175.83,"id":72857114},{"batb":[[0,1.32,14],[1,1.31,6.21],[2,1.27,1111.11]],"ltp":1.4,"tv":178.08,"id":72922097}]}]}
{"op":"mcm","clk":"11896389321","pt":1724343004786,"mc":[{"id":"1.232129550","rc":[{"batb":[[0,1.32,10]],"ltp":1.4,"tv":178.08,"id":72922097}]}]}
{"op":"mcm","clk":"11896389408","pt":1724343005720,"mc":[{"id":"1.232129550","rc":[{"batb":[[0,1.37,4]],"ltp":1.4,"tv":175.83,"id":72857114},{"batb":[[0,1.31,6.21],[1,1.27,1111.11],[2,1.22,19.85]],"ltp":1.4,"tv":178.08,"id":72922097}]}]}
{"op":"mcm","clk":"11896389590","pt":1724343007608,"mc":[{"id":"1.232129550","rc":[{"batb":[[0,1.35,31.27],[1,1.34,882.35],[2,1.3,15]],"ltp":1.4,"tv":175.83,"id":72857114},{"batb":[[0,1.32,4],[1,1.31,6.21],[2,1.27,1111.11]],"ltp":1.4,"tv":178.08,"id":72922097}]}]}
{"op":"mcm","clk":"11896389831","pt":1724343010211,"mc":[{"id":"1.232129550","rc":[{"batb":[[0,1.36,14],[1,1.35,31.27],[2,1.34,882.35]],"ltp":1.4,"tv":175.83,"id":72857114},{"batb":[[0,1.32,10]],"ltp":1.4,"tv":178.08,"id":72922097}]}]}
{"op":"mcm","clk":"11896390082","pt":1724343012704,"mc":[{"id":"1.232129550","rc":[{"batb":[[0,1.36,10]],"ltp":1.4,"tv":175.83,"id":72857114},{"batb":[[0,1.33,4],[1,1.32,10],[2,1.31,6.21]],"ltp":1.4,"tv":178.08,"id":72922097}]}]}
{"op":"mcm","clk":"11896390149","pt":1724343013496,"mc":[{"id":"1.232129550","rc":[{"batb":[[0,1.35,31.27],[1,1.34,882.35],[2,1.3,15]],"ltp":1.4,"tv":175.83,"id":72857114},{"batb":[[1,1.31,6.21],[2,1.27,1111.11]],"ltp":1.4,"tv":178.08,"id":72922097}]}]}
{"op":"mcm","clk":"11896390286","pt":1724343014908,"mc":[{"id":"1.232129550","rc":[{"batb":[[0,1.31,6.21],[1,1.27,1111.11],[2,1.22,19.85]],"ltp":1.4,"tv":178.08,"id":72922097}]}]}
{"op":"mcm","clk":"11896390305","pt":1724343015108,"mc":[{"id":"1.232129550","rc":[{"batb":[[0,1.36,4],[1,1.35,31.27],[2,1.34,882.35]],"ltp":1.4,"tv":175.83,"id":72857114}]}]}
{"op":"mcm","clk":"11896390549","pt":1724343017720,"mc":[{"id":"1.232129550","rc":[{"batb":[[0,1.36,10]],"ltp":1.4,"tv":175.83,"id":72857114},{"batb":[[0,1.32,14],[1,1.31,6.21],[2,1.27,1111.11]],"ltp":1.4,"tv":178.08,"id":72922097}]}]}
{"op":"mcm","clk":"11896390782","pt":1724343020233,"mc":[{"id":"1.232129550","rc":[{"batb":[[0,1.37,4],[1,1.36,10],[2,1.35,31.27]],"ltp":1.4,"tv":175.83,"id":72857114},{"batb":[[0,1.32,10]],"ltp":1.4,"tv":178.08,"id":72922097}]}]}
{"op":"mcm","clk":"11896390852","pt":1724343021019,"mc":[{"id":"1.232129550","rc":[{"batb":[[1,1.35,31.27],[2,1.34,882.35]],"ltp":1.4,"tv":175.83,"id":72857114},{"batb":[[0,1.31,6.21],[1,1.27,1111.11],[2,1.22,19.85]],"ltp":1.4,"tv":178.08,"id":72922097}]}]}
{"op":"mcm","clk":"11896391015","pt":1724343022635,"mc":[{"id":"1.232129550","rc":[{"batb":[[0,1.35,31.27],[1,1.34,882.35],[2,1.3,15]],"ltp":1.4,"tv":175.83,"id":72857114},{"batb":[[0,1.32,4],[1,1.31,6.21],[2,1.27,1111.11]],"ltp":1.4,"tv":178.08,"id":72922097}]}]}
{"op":"mcm","clk":"11896391248","pt":1724343025202,"mc":[{"id":"1.232129550","rc":[{"batb":[[0,1.36,14],[1,1.35,31.27],[2,1.34,882.35]],"ltp":1.4,"tv":175.83,"id":72857114},{"batb":[[0,1.32,10]],"ltp":1.4,"tv":178.08,"id":72922097}]}]}
{"op":"mcm","clk":"11896391478","pt":1724343027717,"mc":[{"id":"1.232129550","rc":[{"batb":[[0,1.36,10]],"ltp":1.4,"tv":175.83,"id":72857114},{"batb":[[0,1.33,4],[1,1.32,10],[2,1.31,6.21]],"ltp":1.4,"tv":178.08,"id":72922097}]}]}
{"op":"mcm","clk":"11896391532","pt":1724343028440,"mc":[{"id":"1.232129550","rc":[{"batb":[[0,1.35,31.27],[1,1.34,882.35],[2,1.3,15]],"ltp":1.4,"tv":175.83,"id":72857114},{"batb":[[1,1.31,6.21],[2,1.27,1111.11]],"ltp":1.4,"tv":178.08,"id":72922097}]}]}
{"op":"mcm","clk":"11896391710","pt":1724343030344,"mc":[{"id":"1.232129550","rc":[{"batb":[[0,1.36,4],[1,1.35,31.27],[2,1.34,882.35]],"ltp":1.4,"tv":175.83,"id":72857114},{"batb":[[0,1.31,6.21],[1,1.27,1111.11],[2,1.22,19.85]],"ltp":1.4,"tv":178.08,"id":72922097}]}]}
{"op":"mcm","clk":"11896391885","pt":1724343032514,"mc":[{"id":"1.232129550","rc":[{"batb":[[0,1.37,10]],"ltp":1.4,"tv":175.83,"id":72857114},{"batb":[[0,1.33,4],[1,1.32,10],[2,1.31,6.21]],"ltp":1.4,"tv":178.08,"id":72922097}]}]}
{"op":"mcm","clk":"11896392158","pt":1724343035532,"mc":[{"id":"1.232129550","rc":[{"batb":[[0,1.38,4]],"ltp":1.4,"tv":175.83,"id":72857114},{"batb":[[0,1.31,6.21],[1,1.27,1111.11],[2,1.22,19.85]],"ltp":1.4,"tv":178.08,"id":72922097}]}]}
{"op":"mcm","clk":"11896392337","pt":1724343037731,"mc":[{"id":"1.232129550","rc":[{"batb":[[0,1.39,10]],"ltp":1.4,"tv":175.83,"id":72857114},{"batb":[[0,1.33,10],[1,1.32,4],[2,1.31,6.21]],"ltp":1.4,"tv":178.08,"id":72922097}]}]}
{"op":"mcm","clk":"11896392557","pt":1724343040338,"mc":[{"id":"1.232129550","rc":[{"batb":[[0,1.4,4],[1,1.39,10],[2,1.35,31.27]],"ltp":1.4,"tv":175.83,"id":72857114},{"batb":[[1,1.31,6.21],[2,1.27,1111.11]],"ltp":1.4,"tv":178.08,"id":72922097}]}]}
{"op":"mcm","clk":"11896392637","pt":1724343041135,"mc":[{"id":"1.232129550","rc":[{"batb":[[1,1.35,31.27],[2,1.34,882.35]],"ltp":1.4,"tv":175.83,"id":72857114},{"batb":[[0,1.31,6.21],[1,1.27,1111.11],[2,1.22,19.85]],"ltp":1.4,"tv":178.08,"id":72922097}]}]}
{"op":"mcm","clk":"11896392788","pt":1724343042838,"mc":[{"id":"1.232129550","rc":[{"batb":[[0,1.35,31.27],[1,1.34,882.35],[2,1.3,15]],"ltp":1.4,"tv":175.83,"id":72857114},{"batb":[[0,1.32,4],[1,1.31,6.21],[2,1.27,1111.11]],"ltp":1.4,"tv":178.08,"id":72922097}]}]}
{"op":"mcm","clk":"11896393007","pt":1724343045429,"mc":[{"id":"1.232129550","rc":[{"batb":[[0,1.36,14],[1,1.35,31.27],[2,1.34,882.35]],"ltp":1.4,"tv":175.83,"id":72857114},{"batb":[[0,1.32,10]],"ltp":1.4,"tv":178.08,"id":72922097}]}]}
{"op":"mcm","clk":"11896393274","pt":1724343048548,"mc":[{"id":"1.232129550","rc":[{"batb":[[0,1.36,10]],"ltp":1.4,"tv":175.83,"id":72857114},{"batb":[[0,1.33,4],[1,1.32,10],[2,1.31,6.21]],"ltp":1.4,"tv":178.08,"id":72922097}]}]}
{"op":"mcm","clk":"11896393344","pt":1724343049345,"mc":[{"id":"1.232129550","rc":[{"batb":[[0,1.35,31.27],[1,1.34,882.35],[2,1.3,15]],"ltp":1.4,"tv":175.83,"id":72857114},{"batb":[[1,1.31,6.21],[2,1.27,1111.11]],"ltp":1.4,"tv":178.08,"id":72922097}]}]}
{"op":"mcm","clk":"11896393477","pt":1724343050856,"mc":[{"id":"1.232129550","rc":[{"batb":[[0,1.31,6.21],[1,1.27,1111.11],[2,1.22,19.85]],"ltp":1.4,"tv":178.08,"id":72922097}]}]}
{"op":"mcm","clk":"11896393493","pt":1724343051066,"mc":[{"id":"1.232129550","rc":[{"batb":[[0,1.36,4],[1,1.35,31.27],[2,1.34,882.35]],"ltp":1.4,"tv":175.83,"id":72857114}]}]}
{"op":"mcm","clk":"11896393692","pt":1724343053345,"mc":[{"id":"1.232129550","rc":[{"batb":[[0,1.36,10]],"ltp":1.4,"tv":175.83,"id":72857114},{"batb":[[0,1.32,14],[1,1.31,6.21],[2,1.27,1111.11]],"ltp":1.4,"tv":178.08,"id":72922097}]}]}
{"op":"mcm","clk":"11896393879","pt":1724343055739,"mc":[{"id":"1.232129550","rc":[{"batb":[[0,1.37,4],[1,1.36,10],[2,1.35,31.27]],"ltp":1.4,"tv":175.83,"id":72857114},{"batb":[[0,1.32,10]],"ltp":1.4,"tv":178.08,"id":72922097}]}]}
{"op":"mcm","clk":"11896393955","pt":1724343056740,"mc":[{"id":"1.232129550","rc":[{"batb":[[1,1.35,31.27],[2,1.34,882.35]],"ltp":1.4,"tv":175.83,"id":72857114},{"batb":[[0,1.31,6.21],[1,1.27,1111.11],[2,1.22,19.85]],"ltp":1.4,"tv":178.08,"id":72922097}]}]}
{"op":"mcm","clk":"11896394100","pt":1724343058356,"mc":[{"id":"1.232129550","rc":[{"batb":[[0,1.35,31.27],[1,1.34,882.35],[2,1.3,15]],"ltp":1.4,"tv":175.83,"id":72857114},{"batb":[[0,1.32,4],[1,1.31,6.21],[2,1.27,1111.11]],"ltp":1.4,"tv":178.08,"id":72922097}]}]}
{"op":"mcm","clk":"11896394330","pt":1724343060963,"mc":[{"id":"1.232129550","rc":[{"batb":[[0,1.36,14],[1,1.35,31.27],[2,1.34,882.35]],"ltp":1.4,"tv":175.83,"id":72857114},{"batb":[[0,1.32,10]],"ltp":1.4,"tv":178.08,"id":72922097}]}]}
{"op":"mcm","clk":"11896394571","pt":1724343063566,"mc":[{"id":"1.232129550","rc":[{"batb":[[0,1.36,10]],"ltp":1.4,"tv":175.83,"id":72857114},{"batb":[[0,1.33,4],[1,1.32,10],[2,1.31,6.21]],"ltp":1.4,"tv":178.08,"id":72922097}]}]}
{"op":"mcm","clk":"11896394632","pt":1724343064157,"mc":[{"id":"1.232129550","rc":[{"batb":[[0,1.35,31.27],[1,1.34,882.35],[2,1.3,15]],"ltp":1.4,"tv":175.83,"id":72857114},{"batb":[[1,1.31,6.21],[2,1.27,1111.11]],"ltp":1.4,"tv":178.08,"id":72922097}]}]}
{"op":"mcm","clk":"11896394785","pt":1724343065938,"mc":[{"id":"1.232129550","rc":[{"batb":[[0,1.31,6.21],[1,1.27,1111.11],[2,1.22,19.85]],"ltp":1.4,"tv":178.08,"id":72922097}]}]}
{"op":"mcm","clk":"11896394802","pt":1724343066145,"mc":[{"id":"1.232129550","rc":[{"batb":[[0,1.36,4],[1,1.35,31.27],[2,1.34,882.35]],"ltp":1.4,"tv":175.83,"id":72857114}]}]}
{"op":"mcm","clk":"11896395055","pt":1724343068858,"mc":[{"id":"1.232129550","rc":[{"batb":[[0,1.36,10]],"ltp":1.4,"tv":175.83,"id":72857114},{"batb":[[0,1.32,14],[1,1.31,6.21],[2,1.27,1111.11]],"ltp":1.4,"tv":178.08,"id":72922097}]}]}
{"op":"mcm","clk":"11896395285","pt":1724343071271,"mc":[{"id":"1.232129550","rc":[{"batb":[[0,1.37,4],[1,1.36,10],[2,1.35,31.27]],"ltp":1.4,"tv":175.83,"id":72857114},{"batb":[[0,1.32,10]],"ltp":1.4,"tv":178.08,"id":72922097}]}]}
{"op":"mcm","clk":"11896395390","pt":1724343072390,"mc":[{"id":"1.232129550","rc":[{"batb":[[1,1.35,31.27],[2,1.34,882.35]],"ltp":1.4,"tv":175.83,"id":72857114},{"batb":[[0,1.31,6.21],[1,1.27,1111.11],[2,1.22,19.85]],"ltp":1.4,"tv":178.08,"id":72922097}]}]}
{"op":"mcm","clk":"11896395515","pt":1724343073770,"mc":[{"id":"1.232129550","rc":[{"batb":[[0,1.35,31.27],[1,1.34,882.35],[2,1.3,15]],"ltp":1.4,"tv":175.83,"id":72857114}]}]}
{"op":"mcm","clk":"11896395536","pt":1724343073982,"mc":[{"id":"1.232129550","rc":[{"batb":[[0,1.32,4],[1,1.31,6.21],[2,1.27,1111.11]],"ltp":1.4,"tv":178.08,"id":72922097}]}]}
{"op":"mcm","clk":"11896395757","pt":1724343076462,"mc":[{"id":"1.232129550","rc":[{"batb":[[0,1.36,14],[1,1.35,31.27],[2,1.34,882.35]],"ltp":1.4,"tv":175.83,"id":72857114},{"batb":[[0,1.32,10]],"ltp":1.4,"tv":178.08,"id":72922097}]}]}
{"op":"mcm","clk":"11896395995","pt":1724343078757,"mc":[{"id":"1.232129550","rc":[{"batb":[[0,1.36,10]],"ltp":1.4,"tv":175.83,"id":72857114},{"batb":[[0,1.33,4],[1,1.32,10],[2,1.31,6.21]],"ltp":1.4,"tv":178.08,"id":72922097}]}]}
{"op":"mcm","clk":"11896396099","pt":1724343079855,"mc":[{"id":"1.232129550","rc":[{"batb":[[0,1.35,31.27],[1,1.34,882.35],[2,1.3,15]],"ltp":1.4,"tv":175.83,"id":72857114},{"batb":[[1,1.31,6.21],[2,1.27,1111.11]],"ltp":1.4,"tv":178.08,"id":72922097}]}]}
{"op":"mcm","clk":"11896396243","pt":1724343081275,"mc":[{"id":"1.232129550","rc":[{"batb":[[0,1.36,4],[1,1.35,31.27],[2,1.34,882.35]],"ltp":1.4,"tv":175.83,"id":72857114},{"batb":[[0,1.31,6.21],[1,1.27,1111.11],[2,1.22,19.85]],"ltp":1.4,"tv":178.08,"id":72922097}]}]}
{"op":"mcm","clk":"11896396441","pt":1724343083782,"mc":[{"id":"1.232129550","rc":[{"batb":[[0,1.36,10]],"ltp":1.4,"tv":175.83,"id":72857114},{"batb":[[0,1.32,14],[1,1.31,6.21],[2,1.27,1111.11]],"ltp":1.4,"tv":178.08,"id":72922097}]}]}
{"op":"mcm","clk":"11896396682","pt":1724343086197,"mc":[{"id":"1.232129550","rc":[{"batb":[[0,1.37,4],[1,1.36,10],[2,1.35,31.27]],"ltp":1.4,"tv":175.83,"id":72857114},{"batb":[[0,1.32,10]],"ltp":1.4,"tv":178.08,"id":72922097}]}]}
{"op":"mcm","clk":"11896396780","pt":1724343087194,"mc":[{"id":"1.232129550","rc":[{"batb":[[1,1.35,31.27],[2,1.34,882.35]],"ltp":1.4,"tv":175.83,"id":72857114},{"batb":[[0,1.31,6.21],[1,1.27,1111.11],[2,1.22,19.85]],"ltp":1.4,"tv":178.08,"id":72922097}]}]}
{"op":"mcm","clk":"11896396950","pt":1724343088859,"mc":[{"id":"1.232129550","rc":[{"batb":[[0,1.35,31.27],[1,1.34,882.35],[2,1.3,15]],"ltp":1.4,"tv":175.83,"id":72857114},{"batb":[[0,1.32,4],[1,1.31,6.21],[2,1.27,1111.11]],"ltp":1.4,"tv":178.08,"id":72922097}]}]}
{"op":"mcm","clk":"11896397174","pt":1724343091487,"mc":[{"id":"1.232129550","rc":[{"batb":[[0,1.36,14],[1,1.35,31.27],[2,1.34,882.35]],"ltp":1.4,"tv":175.83,"id":72857114},{"batb":[[0,1.32,10]],"ltp":1.4,"tv":178.08,"id":72922097}]}]}
{"op":"mcm","clk":"11896397443","pt":1724343093812,"mc":[{"id":"1.232129550","rc":[{"batb":[[0,1.36,10]],"ltp":1.4,"tv":175.83,"id":72857114},{"batb":[[0,1.33,4],[1,1.32,10],[2,1.31,6.21]],"ltp":1.4,"tv":178.08,"id":72922097}]}]}
{"op":"mcm","clk":"11896397547","pt":1724343094771,"mc":[{"id":"1.232129550","rc":[{"batb":[[0,1.35,31.27],[1,1.34,882.35],[2,1.3,15]],"ltp":1.4,"tv":175.83,"id":72857114},{"batb":[[1,1.31,6.21],[2,1.27,1111.11]],"ltp":1.4,"tv":178.08,"id":72922097}]}]}
{"op":"mcm","clk":"11896397678","pt":1724343095966,"mc":[{"id":"1.232129550","rc":[{"batb":[[0,1.31,6.21],[1,1.27,1111.11],[2,1.22,19.85]],"ltp":1.4,"tv":178.08,"id":72922097}]}]}
{"op":"mcm","clk":"11896397697","pt":1724343096075,"mc":[{"id":"1.232129550","rc":[{"batb":[[0,1.36,4],[1,1.35,31.27],[2,1.34,882.35]],"ltp":1.4,"tv":175.83,"id":72857114}]}]}
{"op":"mcm","clk":"11896397928","pt":1724343098580,"mc":[{"id":"1.232129550","rc":[{"batb":[[0,1.36,10]],"ltp":1.4,"tv":175.83,"id":72857114},{"batb":[[0,1.32,14],[1,1.31,6.21],[2,1.27,1111.11]],"ltp":1.4,"tv":178.08,"id":72922097}]}]}
{"op":"mcm","clk":"11896398164","pt":1724343101185,"mc":[{"id":"1.232129550","rc":[{"batb":[[0,1.37,4],[1,1.36,10],[2,1.35,31.27]],"ltp":1.4,"tv":175.83,"id":72857114},{"batb":[[0,1.32,10]],"ltp":1.4,"tv":178.08,"id":72922097}]}]}
{"op":"mcm","clk":"11896398254","pt":1724343102187,"mc":[{"id":"1.232129550","rc":[{"batb":[[1,1.35,31.27],[2,1.34,882.35]],"ltp":1.4,"tv":175.83,"id":72857114},{"batb":[[0,1.31,6.21],[1,1.27,1111.11],[2,1.22,19.85]],"ltp":1.4,"tv":178.08,"id":72922097}]}]}
{"op":"mcm","clk":"11896398388","pt":1724343103594,"mc":[{"id":"1.232129550","rc":[{"batb":[[0,1.35,31.27],[1,1.34,882.35],[2,1.3,15]],"ltp":1.4,"tv":175.83,"id":72857114},{"batb":[[0,1.32,4],[1,1.31,6.21],[2,1.27,1111.11]],"ltp":1.4,"tv":178.08,"id":72922097}]}]}
{"op":"mcm","clk":"11896398630","pt":1724343106212,"mc":[{"id":"1.232129550","rc":[{"batb":[[0,1.36,14],[1,1.35,31.27],[2,1.34,882.35]],"ltp":1.4,"tv":175.83,"id":72857114},{"batb":[[0,1.32,10]],"ltp":1.4,"tv":178.08,"id":72922097}]}]}
{"op":"mcm","clk":"11896398838","pt":1724343108726,"mc":[{"id":"1.232129550","rc":[{"batb":[[0,1.36,10]],"ltp":1.4,"tv":175.83,"id":72857114},{"batb":[[0,1.33,4],[1,1.32,10],[2,1.31,6.21]],"ltp":1.4,"tv":178.08,"id":72922097}]}]}
{"op":"mcm","clk":"11896398911","pt":1724343109486,"mc":[{"id":"1.232129550","rc":[{"batb":[[0,1.35,31.27],[1,1.34,882.35],[2,1.3,15]],"ltp":1.4,"tv":175.83,"id":72857114},{"batb":[[1,1.31,6.21],[2,1.27,1111.11]],"ltp":1.4,"tv":178.08,"id":72922097}]}]}
{"op":"mcm","clk":"11896399080","pt":1724343111203,"mc":[{"id":"1.232129550","rc":[{"batb":[[0,1.36,4],[1,1.35,31.27],[2,1.34,882.35]],"ltp":1.4,"tv":175.83,"id":72857114},{"batb":[[0,1.31,6.21],[1,1.27,1111.11],[2,1.22,19.85]],"ltp":1.4,"tv":178.08,"id":72922097}]}]}
{"op":"mcm","clk":"11896399208","pt":1724343112615,"mc":[{"id":"1.232129550","rc":[{"batb":[[0,1.37,10],[1,1.36,4],[2,1.35,31.27]],"ltp":1.4,"tv":175.83,"id":72857114},{"batb":[[0,1.32,10],[1,1.31,6.21],[2,1.27,1111.11]],"ltp":1.4,"tv":178.08,"id":72922097}]}]}
{"op":"mcm","clk":"11896399306","pt":1724343113708,"mc":[{"id":"1.232129550","rc":[{"batb":[[1,1.35,31.27],[2,1.34,882.35]],"ltp":1.4,"tv":175.83,"id":72857114},{"batb":[[0,1.33,4],[1,1.32,10],[2,1.31,6.21]],"ltp":1.4,"tv":178.08,"id":72922097}]}]}
{"op":"mcm","clk":"11896399533","pt":1724343116301,"mc":[{"id":"1.232129550","rc":[{"batb":[[0,1.36,4]],"ltp":1.4,"tv":175.83,"id":72857114},{"batb":[[0,1.31,6.21],[1,1.27,1111.11],[2,1.22,19.85]],"ltp":1.4,"tv":178.08,"id":72922097}]}]}
{"op":"mcm","clk":"11896399741","pt":1724343118713,"mc":[{"id":"1.232129550","rc":[{"batb":[[0,1.36,10]],"ltp":1.4,"tv":175.83,"id":72857114},{"batb":[[0,1.32,14],[1,1.31,6.21],[2,1.27,1111.11]],"ltp":1.4,"tv":178.08,"id":72922097}]}]}
{"op":"mcm","clk":"11896399954","pt":1724343120834,"mc":[{"id":"1.232129550","rc":[{"batb":[[0,1.37,4],[1,1.36,10],[2,1.35,31.27]],"ltp":1.4,"tv":175.83,"id":72857114}]}]}
{"op":"mcm","clk":"11896399983","pt":1724343121109,"mc":[{"id":"1.232129550","rc":[{"batb":[[0,1.32,10]],"ltp":1.4,"tv":178.08,"id":72922097}]}]}
{"op":"mcm","clk":"11896400084","pt":1724343122247,"mc":[{"id":"1.232129550","rc":[{"batb":[[1,1.35,31.27],[2,1.34,882.35]],"ltp":1.4,"tv":175.83,"id":72857114},{"batb":[[0,1.31,6.21],[1,1.27,1111.11],[2,1.22,19.85]],"ltp":1.4,"tv":178.08,"id":72922097}]}]}
{"op":"mcm","clk":"11896400214","pt":1724343123522,"mc":[{"id":"1.232129550","rc":[{"batb":[[0,1.35,31.27],[1,1.34,882.35],[2,1.3,15]],"ltp":1.4,"tv":175.83,"id":72857114},{"batb":[[0,1.32,4],[1,1.31,6.21],[2,1.27,1111.11]],"ltp":1.4,"tv":178.08,"id":72922097}]}]}
{"op":"mcm","clk":"11896400418","pt":1724343125918,"mc":[{"id":"1.232129550","rc":[{"batb":[[0,1.31,6.21],[1,1.27,1111.11],[2,1.22,19.85]],"ltp":1.4,"tv":178.08,"id":72922097}]}]}
{"op":"mcm","clk":"11896400438","pt":1724343126125,"mc":[{"id":"1.232129550","rc":[{"batb":[[0,1.36,14],[1,1.35,31.27],[2,1.34,882.35]],"ltp":1.4,"tv":175.83,"id":72857114},{"batb":[[0,1.32,10],[1,1.31,6.21],[2,1.27,1111.11]],"ltp":1.4,"tv":178.08,"id":72922097}]}]}
{"op":"mcm","clk":"11896400689","pt":1724343128736,"mc":[{"id":"1.232129550","rc":[{"batb":[[0,1.36,10]],"ltp":1.4,"tv":175.83,"id":72857114},{"batb":[[0,1.33,4],[1,1.32,10],[2,1.31,6.21]],"ltp":1.4,"tv":178.08,"id":72922097}]}]}
{"op":"mcm","clk":"11896400775","pt":1724343129639,"mc":[{"id":"1.232129550","rc":[{"batb":[[0,1.35,31.27],[1,1.34,882.35],[2,1.3,15]],"ltp":1.4,"tv":175.83,"id":72857114},{"batb":[[1,1.31,6.21],[2,1.27,1111.11]],"ltp":1.4,"tv":178.08,"id":72922097}]}]}
{"op":"mcm","clk":"11896400933","pt":1724343131462,"mc":[{"id":"1.232129550","rc":[{"batb":[[0,1.36,4],[1,1.35,31.27],[2,1.34,882.35]],"ltp":1.4,"tv":175.83,"id":72857114},{"batb":[[0,1.31,6.21],[1,1.27,1111.11],[2,1.22,19.85]],"ltp":1.4,"tv":178.08,"id":72922097}]}]}
{"op":"mcm","clk":"11896401126","pt":1724343133851,"mc":[{"id":"1.232129550","rc":[{"batb":[[0,1.35,31.27],[1,1.34,882.35],[2,1.3,15]],"ltp":1.4,"tv":175.83,"id":72857114}]}]}
{"op":"mcm","clk":"11896401146","pt":1724343134060,"mc":[{"id":"1.232129550","rc":[{"batb":[[0,1.36,10],[1,1.35,31.27],[2,1.34,882.35]],"ltp":1.4,"tv":175.83,"id":72857114},{"batb":[[0,1.32,14],[1,1.31,6.21],[2,1.27,1111.11]],"ltp":1.4,"tv":178.08,"id":72922097}]}]}
{"op":"mcm","clk":"11896401373","pt":1724343136547,"mc":[{"id":"1.232129550","rc":[{"batb":[[0,1.37,4],[1,1.36,10],[2,1.35,31.27]],"ltp":1.4,"tv":175.83,"id":72857114},{"batb":[[0,1.32,10]],"ltp":1.4,"tv":178.08,"id":72922097}]}]}
{"op":"mcm","clk":"11896401432","pt":1724343137354,"mc":[{"id":"1.232129550","rc":[{"batb":[[1,1.35,31.27],[2,1.34,882.35]],"ltp":1.4,"tv":175.83,"id":72857114},{"batb":[[0,1.31,6.21],[1,1.27,1111.11],[2,1.22,19.85]],"ltp":1.4,"tv":178.08,"id":72922097}]}]}
{"op":"mcm","clk":"11896401557","pt":1724343138870,"mc":[{"id":"1.232129550","rc":[{"batb":[[0,1.35,31.27],[1,1.34,882.35],[2,1.3,15]],"ltp":1.4,"tv":175.83,"id":72857114}]}]}
{"op":"mcm","clk":"11896401580","pt":1724343139036,"mc":[{"id":"1.232129550","rc":[{"batb":[[0,1.32,4],[1,1.31,6.21],[2,1.27,1111.11]],"ltp":1.4,"tv":178.08,"id":72922097}]}]}
{"op":"mcm","clk":"11896401784","pt":1724343141650,"mc":[{"id":"1.232129550","rc":[{"batb":[[0,1.36,14],[1,1.35,31.27],[2,1.34,882.35]],"ltp":1.4,"tv":175.83,"id":72857114},{"batb":[[0,1.32,10]],"ltp":1.4,"tv":178.08,"id":72922097}]}]}
{"op":"mcm","clk":"11896402027","pt":1724343144264,"mc":[{"id":"1.232129550","rc":[{"batb":[[0,1.36,10]],"ltp":1.4,"tv":175.83,"id":72857114},{"batb":[[0,1.33,4],[1,1.32,10],[2,1.31,6.21]],"ltp":1.4,"tv":178.08,"id":72922097}]}]}
{"op":"mcm","clk":"11896402100","pt":1724343145068,"mc":[{"id":"1.232129550","rc":[{"batb":[[0,1.35,31.27],[1,1.34,882.35],[2,1.3,15]],"ltp":1.4,"tv":175.83,"id":72857114},{"batb":[[1,1.31,6.21],[2,1.27,1111.11]],"ltp":1.4,"tv":178.08,"id":72922097}]}]}
{"op":"mcm","clk":"11896402245","pt":1724343146779,"mc":[{"id":"1.232129550","rc":[{"batb":[[0,1.36,4],[1,1.35,31.27],[2,1.34,882.35]],"ltp":1.4,"tv":175.83,"id":72857114},{"batb":[[0,1.31,6.21],[1,1.27,1111.11],[2,1.22,19.85]],"ltp":1.4,"tv":178.08,"id":72922097}]}]}
{"op":"mcm","clk":"11896402467","pt":1724343149247,"mc":[{"id":"1.232129550","rc":[{"batb":[[0,1.36,10]],"ltp":1.4,"tv":175.83,"id":72857114},{"batb":[[0,1.32,14],[1,1.31,6.21],[2,1.27,1111.11]],"ltp":1.4,"tv":178.08,"id":72922097}]}]}
{"op":"mcm","clk":"11896402687","pt":1724343151732,"mc":[{"id":"1.232129550","rc":[{"batb":[[0,1.37,4],[1,1.36,10],[2,1.35,31.27]],"ltp":1.4,"tv":175.83,"id":72857114},{"batb":[[0,1.32,10]],"ltp":1.4,"tv":178.08,"id":72922097}]}]}
{"op":"mcm","clk":"11896402752","pt":1724343152569,"mc":[{"id":"1.232129550","rc":[{"batb":[[1,1.35,31.27],[2,1.34,882.35]],"ltp":1.4,"tv":175.83,"id":72857114},{"batb":[[0,1.31,6.21],[1,1.27,1111.11],[2,1.22,19.85]],"ltp":1.4,"tv":178.08,"id":72922097}]}]}
{"op":"mcm","clk":"11896402898","pt":1724343154262,"mc":[{"id":"1.232129550","rc":[{"batb":[[0,1.35,31.27],[1,1.34,882.35],[2,1.3,15]],"ltp":1.4,"tv":175.83,"id":72857114},{"batb":[[0,1.32,4],[1,1.31,6.21],[2,1.27,1111.11]],"ltp":1.4,"tv":178.08,"id":72922097}]}]}
{"op":"mcm","clk":"11896403105","pt":1724343156763,"mc":[{"id":"1.232129550","rc":[{"batb":[[0,1.36,14],[1,1.35,31.27],[2,1.34,882.35]],"ltp":1.4,"tv":175.83,"id":72857114},{"batb":[[0,1.32,10]],"ltp":1.4,"tv":178.08,"id":72922097}]}]}
{"op":"mcm","clk":"11896403351","pt":1724343159278,"mc":[{"id":"1.232129550","rc":[{"batb":[[0,1.36,10]],"ltp":1.4,"tv":175.83,"id":72857114},{"batb":[[0,1.33,4],[1,1.32,10],[2,1.31,6.21]],"ltp":1.4,"tv":178.08,"id":72922097}]}]}
{"op":"mcm","clk":"11896403450","pt":1724343160065,"mc":[{"id":"1.232129550","rc":[{"batb":[[0,1.35,31.27],[1,1.34,882.35],[2,1.3,15]],"ltp":1.4,"tv":175.83,"id":72857114},{"batb":[[1,1.31,6.21],[2,1.27,1111.11]],"ltp":1.4,"tv":178.08,"id":72922097}]}]}
{"op":"mcm","clk":"11896403621","pt":1724343161849,"mc":[{"id":"1.232129550","rc":[{"batb":[[0,1.36,4],[1,1.35,31.27],[2,1.34,882.35]],"ltp":1.4,"tv":175.83,"id":72857114},{"batb":[[0,1.31,6.21],[1,1.27,1111.11],[2,1.22,19.85]],"ltp":1.4,"tv":178.08,"id":72922097}]}]}
{"op":"mcm","clk":"11896403865","pt":1724343164555,"mc":[{"id":"1.232129550","rc":[{"batb":[[0,1.36,10]],"ltp":1.4,"tv":175.83,"id":72857114},{"batb":[[0,1.32,14],[1,1.31,6.21],[2,1.27,1111.11]],"ltp":1.4,"tv":178.08,"id":72922097}]}]}
{"op":"mcm","clk":"11896404055","pt":1724343166860,"mc":[{"id":"1.232129550","rc":[{"batb":[[0,1.37,4],[1,1.36,10],[2,1.35,31.27]],"ltp":1.4,"tv":175.83,"id":72857114},{"batb":[[0,1.32,10]],"ltp":1.4,"tv":178.08,"id":72922097}]}]}
{"op":"mcm","clk":"11896404152","pt":1724343167894,"mc":[{"id":"1.232129550","rc":[{"batb":[[1,1.35,31.27],[2,1.34,882.35]],"ltp":1.4,"tv":175.83,"id":72857114},{"batb":[[0,1.31,6.21],[1,1.27,1111.11],[2,1.22,19.85]],"ltp":1.4,"tv":178.08,"id":72922097}]}]}
{"op":"mcm","clk":"11896404268","pt":1724343169350,"mc":[{"id":"1.232129550","rc":[{"batb":[[0,1.35,31.27],[1,1.34,882.35],[2,1.3,15]],"ltp":1.4,"tv":175.83,"id":72857114},{"batb":[[0,1.32,4],[1,1.31,6.21],[2,1.27,1111.11]],"ltp":1.4,"tv":178.08,"id":72922097}]}]}
{"op":"mcm","clk":"11896404458","pt":1724343171865,"mc":[{"id":"1.232129550","rc":[{"batb":[[0,1.36,14],[1,1.35,31.27],[2,1.34,882.35]],"ltp":1.4,"tv":175.83,"id":72857114},{"batb":[[0,1.32,10]],"ltp":1.4,"tv":178.08,"id":72922097}]}]}
{"op":"mcm","clk":"11896404638","pt":1724343174300,"mc":[{"id":"1.232129550","rc":[{"batb":[[0,1.36,10]],"ltp":1.4,"tv":175.83,"id":72857114},{"batb":[[0,1.33,4],[1,1.32,10],[2,1.31,6.21]],"ltp":1.4,"tv":178.08,"id":72922097}]}]}
{"op":"mcm","clk":"11896416271","pt":1724343175397,"mc":[{"id":"1.232129550","rc":[{"batb":[[0,1.35,31.27],[1,1.34,882.35],[2,1.3,15]],"ltp":1.4,"tv":175.83,"id":72857114},{"batb":[[1,1.31,6.21],[2,1.27,1111.11]],"ltp":1.4,"tv":178.08,"id":72922097}]}]}
{"op":"mcm","clk":"11896416391","pt":1724343176901,"mc":[{"id":"1.232129550","rc":[{"batb":[[0,1.36,4],[1,1.35,31.27],[2,1.34,882.35]],"ltp":1.4,"tv":175.83,"id":72857114},{"batb":[[0,1.31,6.21],[1,1.27,1111.11],[2,1.22,19.85]],"ltp":1.4,"tv":178.08,"id":72922097}]}]}
{"op":"mcm","clk":"11896416571","pt":1724343179086,"mc":[{"id":"1.232129550","rc":[{"batb":[[0,1.36,10]],"ltp":1.4,"tv":175.83,"id":72857114},{"batb":[[0,1.32,14],[1,1.31,6.21],[2,1.27,1111.11]],"ltp":1.4,"tv":178.08,"id":72922097}]}]}
{"op":"mcm","clk":"11896416801","pt":1724343181597,"mc":[{"id":"1.232129550","rc":[{"batb":[[0,1.37,4],[1,1.36,10],[2,1.35,31.27]],"ltp":1.4,"tv":175.83,"id":72857114},{"batb":[[0,1.32,10]],"ltp":1.4,"tv":178.08,"id":72922097}]}]}
{"op":"mcm","clk":"11896416878","pt":1724343182378,"mc":[{"id":"1.232129550","rc":[{"batb":[[1,1.35,31.27],[2,1.34,882.35]],"ltp":1.4,"tv":175.83,"id":72857114},{"batb":[[0,1.31,6.21],[1,1.27,1111.11],[2,1.22,19.85]],"ltp":1.4,"tv":178.08,"id":72922097}]}]}
{"op":"mcm","clk":"11896417006","pt":1724343183891,"mc":[{"id":"1.232129550","rc":[{"batb":[[0,1.35,31.27],[1,1.34,882.35],[2,1.3,15]],"ltp":1.4,"tv":175.83,"id":72857114}]}]}
{"op":"mcm","clk":"11896417020","pt":1724343184098,"mc":[{"id":"1.232129550","rc":[{"batb":[[0,1.32,4],[1,1.31,6.21],[2,1.27,1111.11]],"ltp":1.4,"tv":178.08,"id":72922097}]}]}
{"op":"mcm","clk":"11896417219","pt":1724343186601,"mc":[{"id":"1.232129550","rc":[{"batb":[[0,1.36,14],[1,1.35,31.27],[2,1.34,882.35]],"ltp":1.4,"tv":175.83,"id":72857114},{"batb":[[0,1.32,10]],"ltp":1.4,"tv":178.08,"id":72922097}]}]}
{"op":"mcm","clk":"11896417534","pt":1724343189893,"mc":[{"id":"1.232129550","rc":[{"batb":[[0,1.35,31.27],[1,1.34,882.35],[2,1.3,15]],"ltp":1.4,"tv":175.83,"id":72857114},{"batb":[[0,1.33,4]],"ltp":1.4,"tv":178.08,"id":72922097}]}]}
{"op":"mcm","clk":"11896417748","pt":1724343191928,"mc":[{"id":"1.232129550","rc":[{"batb":[[0,1.36,4],[1,1.35,31.27],[2,1.34,882.35]],"ltp":1.4,"tv":175.83,"id":72857114},{"batb":[[0,1.31,6.21],[1,1.27,1111.11],[2,1.22,19.85]],"ltp":1.4,"tv":178.08,"id":72922097}]}]}
{"op":"mcm","clk":"11896418001","pt":1724343194487,"mc":[{"id":"1.232129550","rc":[{"batb":[[0,1.36,10]],"ltp":1.4,"tv":175.83,"id":72857114},{"batb":[[0,1.32,14],[1,1.31,6.21],[2,1.27,1111.11]],"ltp":1.4,"tv":178.08,"id":72922097}]}]}
{"op":"mcm","clk":"11896418203","pt":1724343196927,"mc":[{"id":"1.232129550","rc":[{"batb":[[0,1.32,10]],"ltp":1.4,"tv":178.08,"id":72922097}]}]}
{"op":"mcm","clk":"11896418283","pt":1724343197808,"mc":[{"id":"1.232129550","rc":[{"batb":[[0,1.37,4]],"ltp":1.4,"tv":175.83,"id":72857114},{"batb":[[0,1.31,6.21],[1,1.27,1111.11],[2,1.22,19.85]],"ltp":1.4,"tv":178.08,"id":72922097}]}]}
{"op":"mcm","clk":"11896418435","pt":1724343199536,"mc":[{"id":"1.232129550","rc":[{"batb":[[0,1.35,31.27],[1,1.34,882.35],[2,1.3,15]],"ltp":1.4,"tv":175.83,"id":72857114},{"batb":[[0,1.32,4],[1,1.31,6.21],[2,1.27,1111.11]],"ltp":1.4,"tv":178.08,"id":72922097}]}]}
{"op":"mcm","clk":"11896418628","pt":1724343201829,"mc":[{"id":"1.232129550","rc":[{"batb":[[0,1.31,6.21],[1,1.27,1111.11],[2,1.22,19.85]],"ltp":1.4,"tv":178.08,"id":72922097}]}]}
{"op":"mcm","clk":"11896418641","pt":1724343202012,"mc":[{"id":"1.232129550","rc":[{"batb":[[0,1.36,14],[1,1.35,31.27],[2,1.34,882.35]],"ltp":1.4,"tv":175.83,"id":72857114},{"batb":[[0,1.32,10],[1,1.31,6.21],[2,1.27,1111.11]],"ltp":1.4,"tv":178.08,"id":72922097}]}]}
{"op":"mcm","clk":"11896418893","pt":1724343204614,"mc":[{"id":"1.232129550","rc":[{"batb":[[0,1.36,10]],"ltp":1.4,"tv":175.83,"id":72857114},{"batb":[[0,1.33,4],[1,1.32,10],[2,1.31,6.21]],"ltp":1.4,"tv":178.08,"id":72922097}]}]}
{"op":"mcm","clk":"11896418956","pt":1724343205339,"mc":[{"id":"1.232129550","rc":[{"batb":[[0,1.35,31.27],[1,1.34,882.35],[2,1.3,15]],"ltp":1.4,"tv":175.83,"id":72857114},{"batb":[[1,1.31,6.21],[2,1.27,1111.11]],"ltp":1.4,"tv":178.08,"id":72922097}]}]}
{"op":"mcm","clk":"11896419098","pt":1724343206950,"mc":[{"id":"1.232129550","rc":[{"batb":[[0,1.36,4],[1,1.35,31.27],[2,1.34,882.35]],"ltp":1.4,"tv":175.83,"id":72857114},{"batb":[[0,1.31,6.21],[1,1.27,1111.11],[2,1.22,19.85]],"ltp":1.4,"tv":178.08,"id":72922097}]}]}
{"op":"mcm","clk":"11896419315","pt":1724343209238,"mc":[{"id":"1.232129550","rc":[{"batb":[[0,1.36,10]],"ltp":1.4,"tv":175.83,"id":72857114},{"batb":[[0,1.32,14],[1,1.31,6.21],[2,1.27,1111.11]],"ltp":1.4,"tv":178.08,"id":72922097}]}]}
{"op":"mcm","clk":"11896419539","pt":1724343211535,"mc":[{"id":"1.232129550","rc":[{"batb":[[0,1.37,4],[1,1.36,10],[2,1.35,31.27]],"ltp":1.4,"tv":175.83,"id":72857114},{"batb":[[0,1.32,10]],"ltp":1.4,"tv":178.08,"id":72922097}]}]}
{"op":"mcm","clk":"11896419629","pt":1724343212634,"mc":[{"id":"1.232129550","rc":[{"batb":[[1,1.35,31.27],[2,1.34,882.35]],"ltp":1.4,"tv":175.83,"id":72857114},{"batb":[[0,1.31,6.21],[1,1.27,1111.11],[2,1.22,19.85]],"ltp":1.4,"tv":178.08,"id":72922097}]}]}
{"op":"mcm","clk":"11896419735","pt":1724343213945,"mc":[{"id":"1.232129550","rc":[{"batb":[[0,1.35,31.27],[1,1.34,882.35],[2,1.3,15]],"ltp":1.4,"tv":175.83,"id":72857114}]}]}
{"op":"mcm","clk":"11896419753","pt":1724343214148,"mc":[{"id":"1.232129550","rc":[{"batb":[[0,1.32,4],[1,1.31,6.21],[2,1.27,1111.11]],"ltp":1.4,"tv":178.08,"id":72922097}]}]}
{"op":"mcm","clk":"11896419856","pt":1724343215348,"mc":[{"id":"1.232129550","rc":[{"batb":[[0,1.36,10],[1,1.35,31.27],[2,1.34,882.35]],"ltp":1.4,"tv":175.83,"id":72857114},{"batb":[[0,1.33,10],[1,1.32,4],[2,1.31,6.21]],"ltp":1.4,"tv":178.08,"id":72922097}]}]}
{"op":"mcm","clk":"11896419972","pt":1724343216760,"mc":[{"id":"1.232129550","rc":[{"batb":[[0,1.37,4],[1,1.36,10],[2,1.35,31.27]],"ltp":1.4,"tv":175.83,"id":72857114},{"batb":[[1,1.31,6.21],[2,1.27,1111.11]],"ltp":1.4,"tv":178.08,"id":72922097}]}]}
{"op":"mcm","clk":"11896420160","pt":1724343218958,"mc":[{"id":"1.232129550","rc":[{"batb":[[0,1.35,31.27],[1,1.34,882.35],[2,1.3,15]],"ltp":1.4,"tv":175.83,"id":72857114},{"batb":[[0,1.31,6.21],[1,1.27,1111.11],[2,1.22,19.85]],"ltp":1.4,"tv":178.08,"id":72922097}]}]}
{"op":"mcm","clk":"11896420175","pt":1724343219124,"mc":[{"id":"1.232129550","rc":[{"batb":[[0,1.32,4],[1,1.31,6.21],[2,1.27,1111.11]],"ltp":1.4,"tv":178.08,"id":72922097}]}]}
{"op":"mcm","clk":"11896420265","pt":1724343220333,"mc":[{"id":"1.232129550","rc":[{"batb":[[0,1.41,12.09],[1,1.35,31.27],[2,1.34,882.35]],"ltp":1.4,"tv":175.83,"id":72857114},{"batl":[[0,3.45,4.84],[1,3.5,98.46]],"ltp":1.4,"tv":178.08,"id":72922097}]}]}
{"op":"mcm","clk":"11896420374","pt":1724343221627,"mc":[{"id":"1.232129550","rc":[{"batb":[[0,1.42,14],[1,1.41,12.09],[2,1.35,31.27]],"ltp":1.4,"tv":175.83,"id":72857114},{"batb":[[0,1.32,10]],"ltp":1.4,"tv":178.08,"id":72922097}]}]}
{"op":"mcm","clk":"11896420570","pt":1724343223927,"mc":[{"id":"1.232129550","rc":[{"batb":[[0,1.42,10],[1,1.35,31.27],[2,1.34,882.35]],"ltp":1.4,"tv":175.83,"id":72857114}]}]}
{"op":"mcm","clk":"11896420578","pt":1724343224031,"mc":[{"id":"1.232129550","rc":[{"batb":[[0,1.33,4],[1,1.32,10],[2,1.31,6.21]],"ltp":1.4,"tv":178.08,"id":72922097}]}]}
{"op":"mcm","clk":"11896420676","pt":1724343225134,"mc":[{"id":"1.232129550","rc":[{"batb":[[0,1.35,31.27],[1,1.34,882.35],[2,1.3,15]],"ltp":1.4,"tv":175.83,"id":72857114},{"batb":[[1,1.31,6.21],[2,1.27,1111.11]],"ltp":1.4,"tv":178.08,"id":72922097}]}]}
{"op":"mcm","clk":"11896420794","pt":1724343226749,"mc":[{"id":"1.232129550","rc":[{"batb":[[0,1.36,4],[1,1.35,31.27],[2,1.34,882.35]],"ltp":1.4,"tv":175.83,"id":72857114},{"batb":[[0,1.31,6.21],[1,1.27,1111.11],[2,1.22,19.85]],"ltp":1.4,"tv":178.08,"id":72922097}]}]}
{"op":"mcm","clk":"11896421006","pt":1724343229256,"mc":[{"id":"1.232129550","rc":[{"batb":[[0,1.36,10]],"ltp":1.4,"tv":175.83,"id":72857114},{"batb":[[0,1.32,14],[1,1.31,6.21],[2,1.27,1111.11]],"ltp":1.4,"tv":178.08,"id":72922097}]}]}
{"op":"mcm","clk":"11896421256","pt":1724343231671,"mc":[{"id":"1.232129550","rc":[{"batb":[[0,1.37,4],[1,1.36,10],[2,1.35,31.27]],"ltp":1.4,"tv":175.83,"id":72857114},{"batb":[[0,1.32,10]],"ltp":1.4,"tv":178.08,"id":72922097}]}]}
{"op":"mcm","clk":"11896421362","pt":1724343233063,"mc":[{"id":"1.232129550","rc":[{"batb":[[1,1.35,31.27],[2,1.34,882.35]],"ltp":1.4,"tv":175.83,"id":72857114},{"batb":[[0,1.31,6.21],[1,1.27,1111.11],[2,1.22,19.85]],"ltp":1.4,"tv":178.08,"id":72922097}]}]}
{"op":"mcm","clk":"11896421473","pt":1724343234261,"mc":[{"id":"1.232129550","rc":[{"batb":[[0,1.35,31.27],[1,1.34,882.35],[2,1.3,15]],"ltp":1.4,"tv":175.83,"id":72857114},{"batb":[[0,1.32,4],[1,1.31,6.21],[2,1.27,1111.11]],"ltp":1.4,"tv":178.08,"id":72922097}]}]}
{"op":"mcm","clk":"11896421690","pt":1724343236562,"mc":[{"id":"1.232129550","rc":[{"batb":[[0,1.36,14],[1,1.35,31.27],[2,1.34,882.35]],"ltp":1.4,"tv":175.83,"id":72857114},{"batb":[[0,1.32,10]],"ltp":1.4,"tv":178.08,"id":72922097}]}]}
{"op":"mcm","clk":"11896421887","pt":1724343238868,"mc":[{"id":"1.232129550","rc":[{"batb":[[0,1.36,10]],"ltp":1.4,"tv":175.83,"id":72857114}]}]}
{"op":"mcm","clk":"11896421985","pt":1724343239858,"mc":[{"id":"1.232129550","rc":[{"batb":[[0,1.35,31.27],[1,1.34,882.35],[2,1.3,15]],"ltp":1.4,"tv":175.83,"id":72857114},{"batb":[[0,1.33,4]],"ltp":1.4,"tv":178.08,"id":72922097}]}]}
{"op":"mcm","clk":"11896422025","pt":1724343240277,"mc":[{"id":"1.232129550","rc":[{"batl":[[0,3.45,4.84],[1,3.5,98.46]],"ltp":1.4,"tv":175.83,"id":72857114},{"batb":[[0,1.41,12.09],[1,1.33,4],[2,1.31,6.21]],"ltp":1.4,"tv":178.08,"id":72922097}]}]}
{"op":"mcm","clk":"11896422120","pt":1724343241280,"mc":[{"id":"1.232129550","rc":[{"batb":[[0,1.36,4],[1,1.35,31.27],[2,1.34,882.35]],"ltp":1.4,"tv":175.83,"id":72857114},{"batb":[[1,1.31,6.21],[2,1.27,1111.11]],"ltp":1.4,"tv":178.08,"id":72922097}]}]}
{"op":"mcm","clk":"11896422374","pt":1724343243886,"mc":[{"id":"1.232129550","rc":[{"batb":[[0,1.35,31.27],[1,1.34,882.35],[2,1.3,15]],"ltp":1.4,"tv":175.83,"id":72857114}]}]}
{"op":"mcm","clk":"11896422390","pt":1724343244093,"mc":[{"id":"1.232129550","rc":[{"batb":[[0,1.36,10],[1,1.35,31.27],[2,1.34,882.35]],"ltp":1.4,"tv":175.83,"id":72857114},{"batb":[[0,1.42,14],[1,1.41,12.09],[2,1.31,6.21]],"ltp":1.4,"tv":178.08,"id":72922097}]}]}
{"op":"mcm","clk":"11896422459","pt":1724343244976,"mc":[{"id":"1.232129550","rc":[{"batb":[[1,1.31,6.21],[2,1.27,1111.11]],"ltp":1.4,"tv":178.08,"id":72922097}]}]}
{"op":"mcm","clk":"11896422621","pt":1724343246694,"mc":[{"id":"1.232129550","rc":[{"batb":[[0,1.37,4],[1,1.36,10],[2,1.35,31.27]],"ltp":1.4,"tv":175.83,"id":72857114},{"batb":[[0,1.42,10]],"ltp":1.4,"tv":178.08,"id":72922097}]}]}
{"op":"mcm","clk":"11896422700","pt":1724343247480,"mc":[{"id":"1.232129550","rc":[{"batb":[[1,1.35,31.27],[2,1.34,882.35]],"ltp":1.4,"tv":175.83,"id":72857114},{"batb":[[0,1.31,6.21],[1,1.27,1111.11],[2,1.22,19.85]],"ltp":1.4,"tv":178.08,"id":72922097}]}]}
{"op":"mcm","clk":"11896422873","pt":1724343249105,"mc":[{"id":"1.232129550","rc":[{"batb":[[0,1.35,31.27],[1,1.34,882.35],[2,1.3,15]],"ltp":1.4,"tv":175.83,"id":72857114},{"batb":[[0,1.32,4],[1,1.31,6.21],[2,1.27,1111.11]],"ltp":1.4,"tv":178.08,"id":72922097}]}]}
{"op":"mcm","clk":"11896423115","pt":1724343251602,"mc":[{"id":"1.232129550","rc":[{"batb":[[0,1.36,14],[1,1.35,31.27],[2,1.34,882.35]],"ltp":1.4,"tv":175.83,"id":72857114},{"batb":[[0,1.32,10]],"ltp":1.4,"tv":178.08,"id":72922097}]}]}
{"op":"mcm","clk":"11896423327","pt":1724343253869,"mc":[{"id":"1.232129550","rc":[{"batb":[[0,1.36,10]],"ltp":1.4,"tv":175.83,"id":72857114}]}]}
{"op":"mcm","clk":"11896423424","pt":1724343254915,"mc":[{"id":"1.232129550","rc":[{"batb":[[0,1.35,31.27],[1,1.34,882.35],[2,1.3,15]],"ltp":1.4,"tv":175.83,"id":72857114},{"batb":[[0,1.33,4]],"ltp":1.4,"tv":178.08,"id":72922097}]}]}
{"op":"mcm","clk":"11896423599","pt":1724343256585,"mc":[{"id":"1.232129550","rc":[{"batb":[[0,1.36,4],[1,1.35,31.27],[2,1.34,882.35]],"ltp":1.4,"tv":175.83,"id":72857114},{"batb":[[0,1.31,6.21],[1,1.27,1111.11],[2,1.22,19.85]],"ltp":1.4,"tv":178.08,"id":72922097}]}]}
{"op":"mcm","clk":"11896423826","pt":1724343259077,"mc":[{"id":"1.232129550","rc":[{"batb":[[0,1.36,10]],"ltp":1.4,"tv":175.83,"id":72857114},{"batb":[[0,1.32,14],[1,1.31,6.21],[2,1.27,1111.11]],"ltp":1.4,"tv":178.08,"id":72922097}]}]}
{"op":"mcm","clk":"11896424083","pt":1724343261596,"mc":[{"id":"1.232129550","rc":[{"batb":[[0,1.37,4],[1,1.36,10],[2,1.35,31.27]],"ltp":1.4,"tv":175.83,"id":72857114},{"batb":[[0,1.32,10]],"ltp":1.4,"tv":178.08,"id":72922097}]}]}
{"op":"mcm","clk":"11896424185","pt":1724343262585,"mc":[{"id":"1.232129550","rc":[{"batb":[[1,1.35,31.27],[2,1.34,882.35]],"ltp":1.4,"tv":175.83,"id":72857114},{"batb":[[0,1.31,6.21],[1,1.27,1111.11],[2,1.22,19.85]],"ltp":1.4,"tv":178.08,"id":72922097}]}]}
{"op":"mcm","clk":"11896424330","pt":1724343264095,"mc":[{"id":"1.232129550","rc":[{"batb":[[0,1.35,31.27],[1,1.34,882.35],[2,1.3,15]],"ltp":1.4,"tv":175.83,"id":72857114},{"batb":[[0,1.32,4],[1,1.31,6.21],[2,1.27,1111.11]],"ltp":1.4,"tv":178.08,"id":72922097}]}]}
{"op":"mcm","clk":"11896424558","pt":1724343266717,"mc":[{"id":"1.232129550","rc":[{"batb":[[0,1.36,14],[1,1.35,31.27],[2,1.34,882.35]],"ltp":1.4,"tv":175.83,"id":72857114},{"batb":[[0,1.32,10]],"ltp":1.4,"tv":178.08,"id":72922097}]}]}
{"op":"mcm","clk":"11896424800","pt":1724343269401,"mc":[{"id":"1.232129550","rc":[{"batb":[[0,1.36,10]],"ltp":1.4,"tv":175.83,"id":72857114},{"batb":[[0,1.33,4],[1,1.32,10],[2,1.31,6.21]],"ltp":1.4,"tv":178.08,"id":72922097}]}]}
{"op":"mcm","clk":"11896424857","pt":1724343270009,"mc":[{"id":"1.232129550","rc":[{"batb":[[0,1.35,31.27],[1,1.34,882.35],[2,1.3,15]],"ltp":1.4,"tv":175.83,"id":72857114},{"batb":[[1,1.31,6.21],[2,1.27,1111.11]],"ltp":1.4,"tv":178.08,"id":72922097}]}]}
{"op":"mcm","clk":"11896425045","pt":1724343271730,"mc":[{"id":"1.232129550","rc":[{"batb":[[0,1.31,6.21],[1,1.27,1111.11],[2,1.22,19.85]],"ltp":1.4,"tv":178.08,"id":72922097}]}]}
{"op":"mcm","clk":"11896425111","pt":1724343272313,"mc":[{"id":"1.232129550","rc":[{"batb":[[0,1.37,10],[1,1.36,4],[2,1.35,31.27]],"ltp":1.4,"tv":175.83,"id":72857114},{"batb":[[0,1.32,10],[1,1.31,6.21],[2,1.27,1111.11]],"ltp":1.4,"tv":178.08,"id":72922097}]}]}
{"op":"mcm","clk":"11896425354","pt":1724343274610,"mc":[{"id":"1.232129550","rc":[{"batb":[[1,1.35,31.27],[2,1.34,882.35]],"ltp":1.4,"tv":175.83,"id":72857114},{"batb":[[0,1.33,4],[1,1.32,10],[2,1.31,6.21]],"ltp":1.4,"tv":178.08,"id":72922097}]}]}
{"op":"mcm","clk":"11896425464","pt":1724343275821,"mc":[{"id":"1.232129550","rc":[{"batb":[[0,1.35,31.27],[1,1.34,882.35],[2,1.3,15]],"ltp":1.4,"tv":175.83,"id":72857114},{"batb":[[1,1.31,6.21],[2,1.27,1111.11]],"ltp":1.4,"tv":178.08,"id":72922097}]}]}
{"op":"mcm","clk":"11896425568","pt":1724343276913,"mc":[{"id":"1.232129550","rc":[{"batb":[[0,1.31,6.21],[1,1.27,1111.11],[2,1.22,19.85]],"ltp":1.4,"tv":178.08,"id":72922097}]}]}
{"op":"mcm","clk":"11896425582","pt":1724343277020,"mc":[{"id":"1.232129550","rc":[{"batb":[[0,1.36,4],[1,1.35,31.27],[2,1.34,882.35]],"ltp":1.4,"tv":175.83,"id":72857114}]}]}
{"op":"mcm","clk":"11896425718","pt":1724343278425,"mc":[{"id":"1.232129550","rc":[{"batb":[[0,1.37,10],[1,1.36,4],[2,1.35,31.27]],"ltp":1.4,"tv":175.83,"id":72857114},{"batb":[[0,1.32,10],[1,1.31,6.21],[2,1.27,1111.11]],"ltp":1.4,"tv":178.08,"id":72922097}]}]}
{"op":"mcm","clk":"11896425838","pt":1724343279520,"mc":[{"id":"1.232129550","rc":[{"batb":[[1,1.35,31.27],[2,1.34,882.35]],"ltp":1.4,"tv":175.83,"id":72857114},{"batb":[[0,1.33,4],[1,1.32,10],[2,1.31,6.21]],"ltp":1.4,"tv":178.08,"id":72922097}]}]}
{"op":"mcm","clk":"11896426085","pt":1724343281913,"mc":[{"id":"1.232129550","rc":[{"batb":[[0,1.35,31.27],[1,1.34,882.35],[2,1.3,15]],"ltp":1.4,"tv":175.83,"id":72857114},{"batb":[[0,1.31,6.21],[1,1.27,1111.11],[2,1.22,19.85]],"ltp":1.4,"tv":178.08,"id":72922097}]}]}
{"op":"mcm","clk":"11896426096","pt":1724343282027,"mc":[{"id":"1.232129550","rc":[{"batb":[[0,1.36,4],[1,1.35,31.27],[2,1.34,882.35]],"ltp":1.4,"tv":175.83,"id":72857114}]}]}
{"op":"mcm","clk":"11896426353","pt":1724343284619,"mc":[{"id":"1.232129550","rc":[{"batb":[[0,1.36,10]],"ltp":1.4,"tv":175.83,"id":72857114},{"batb":[[0,1.32,14],[1,1.31,6.21],[2,1.27,1111.11]],"ltp":1.4,"tv":178.08,"id":72922097}]}]}
{"op":"mcm","clk":"11896426648","pt":1724343287907,"mc":[{"id":"1.232129550","rc":[{"batb":[[0,1.37,4]],"ltp":1.4,"tv":175.83,"id":72857114},{"batb":[[0,1.31,6.21],[1,1.27,1111.11],[2,1.22,19.85]],"ltp":1.4,"tv":178.08,"id":72922097}]}]}
{"op":"mcm","clk":"11896426805","pt":1724343289729,"mc":[{"id":"1.232129550","rc":[{"batb":[[0,1.35,31.27],[1,1.34,882.35],[2,1.3,15]],"ltp":1.4,"tv":175.83,"id":72857114},{"batb":[[0,1.32,4],[1,1.31,6.21],[2,1.27,1111.11]],"ltp":1.4,"tv":178.08,"id":72922097}]}]}
{"op":"mcm","clk":"11896427037","pt":1724343292224,"mc":[{"id":"1.232129550","rc":[{"batb":[[0,1.36,14],[1,1.35,31.27],[2,1.34,882.35]],"ltp":1.4,"tv":175.83,"id":72857114},{"batb":[[0,1.32,10]],"ltp":1.4,"tv":178.08,"id":72922097}]}]}
{"op":"mcm","clk":"11896427309","pt":1724343294628,"mc":[{"id":"1.232129550","rc":[{"batb":[[0,1.36,10]],"ltp":1.4,"tv":175.83,"id":72857114},{"batb":[[0,1.33,4],[1,1.32,10],[2,1.31,6.21]],"ltp":1.4,"tv":178.08,"id":72922097}]}]}
{"op":"mcm","clk":"11896427419","pt":1724343295757,"mc":[{"id":"1.232129550","rc":[{"batb":[[0,1.35,31.27],[1,1.34,882.35],[2,1.3,15]],"ltp":1.4,"tv":175.83,"id":72857114},{"batb":[[1,1.31,6.21],[2,1.27,1111.11]],"ltp":1.4,"tv":178.08,"id":72922097}]}]}
{"op":"mcm","clk":"11896427574","pt":1724343297127,"mc":[{"id":"1.232129550","rc":[{"batb":[[0,1.36,4],[1,1.35,31.27],[2,1.34,882.35]],"ltp":1.4,"tv":175.83,"id":72857114},{"batb":[[0,1.31,6.21],[1,1.27,1111.11],[2,1.22,19.85]],"ltp":1.4,"tv":178.08,"id":72922097}]}]}
{"op":"mcm","clk":"11896427722","pt":1724343298733,"mc":[{"id":"1.232129550","rc":[{"batb":[[0,1.37,10],[1,1.36,4],[2,1.35,31.27]],"ltp":1.4,"tv":175.83,"id":72857114},{"batb":[[0,1.32,10],[1,1.31,6.21],[2,1.27,1111.11]],"ltp":1.4,"tv":178.08,"id":72922097}]}]}
{"op":"mcm","clk":"11896427804","pt":1724343299560,"mc":[{"id":"1.232129550","rc":[{"batb":[[1,1.35,31.27],[2,1.34,882.35]],"ltp":1.4,"tv":175.83,"id":72857114},{"batb":[[0,1.33,4],[1,1.32,10],[2,1.31,6.21]],"ltp":1.4,"tv":178.08,"id":72922097}]}]}
{"op":"mcm","clk":"11896428040","pt":1724343301747,"mc":[{"id":"1.232129550","rc":[{"batb":[[0,1.32,10],[1,1.31,6.21],[2,1.27,1111.11]],"ltp":1.4,"tv":178.08,"id":72922097}]}]}
{"op":"mcm","clk":"11896428077","pt":1724343302052,"mc":[{"id":"1.232129550","rc":[{"batb":[[0,1.38,4]],"ltp":1.4,"tv":175.83,"id":72857114},{"batb":[[0,1.31,6.21],[1,1.27,1111.11],[2,1.22,19.85]],"ltp":1.4,"tv":178.08,"id":72922097}]}]}
{"op":"mcm","clk":"11896428378","pt":1724343304562,"mc":[{"id":"1.232129550","rc":[{"batb":[[0,1.36,10]],"ltp":1.4,"tv":175.83,"id":72857114},{"batb":[[0,1.32,14],[1,1.31,6.21],[2,1.27,1111.11]],"ltp":1.4,"tv":178.08,"id":72922097}]}]}
{"op":"mcm","clk":"11896428688","pt":1724343307651,"mc":[{"id":"1.232129550","rc":[{"batb":[[0,1.37,4]],"ltp":1.4,"tv":175.83,"id":72857114},{"batb":[[0,1.31,6.21],[1,1.27,1111.11],[2,1.22,19.85]],"ltp":1.4,"tv":178.08,"id":72922097}]}]}
{"op":"mcm","clk":"11896428875","pt":1724343309563,"mc":[{"id":"1.232129550","rc":[{"batb":[[0,1.35,31.27],[1,1.34,882.35],[2,1.3,15]],"ltp":1.4,"tv":175.83,"id":72857114},{"batb":[[0,1.32,4],[1,1.31,6.21],[2,1.27,1111.11]],"ltp":1.4,"tv":178.08,"id":72922097}]}]}
{"op":"mcm","clk":"11896429172","pt":1724343312075,"mc":[{"id":"1.232129550","rc":[{"batb":[[0,1.36,14],[1,1.35,31.27],[2,1.34,882.35]],"ltp":1.4,"tv":175.83,"id":72857114},{"batb":[[0,1.32,10]],"ltp":1.4,"tv":178.08,"id":72922097}]}]}
{"op":"mcm","clk":"11896429479","pt":1724343314559,"mc":[{"id":"1.232129550","rc":[{"batb":[[0,1.36,10]],"ltp":1.4,"tv":175.83,"id":72857114},{"batb":[[0,1.33,4],[1,1.32,10],[2,1.31,6.21]],"ltp":1.4,"tv":178.08,"id":72922097}]}]}
{"op":"mcm","clk":"11896429572","pt":1724343315480,"mc":[{"id":"1.232129550","rc":[{"batb":[[0,1.35,31.27],[1,1.34,882.35],[2,1.3,15]],"ltp":1.4,"tv":175.83,"id":72857114},{"batb":[[1,1.31,6.21],[2,1.27,1111.11]],"ltp":1.4,"tv":178.08,"id":72922097}]}]}
{"op":"mcm","clk":"11896429753","pt":1724343317159,"mc":[{"id":"1.232129550","rc":[{"batb":[[0,1.36,4],[1,1.35,31.27],[2,1.34,882.35]],"ltp":1.4,"tv":175.83,"id":72857114},{"batb":[[0,1.31,6.21],[1,1.27,1111.11],[2,1.22,19.85]],"ltp":1.4,"tv":178.08,"id":72922097}]}]}
{"op":"mcm","clk":"11896430004","pt":1724343319471,"mc":[{"id":"1.232129550","rc":[{"batb":[[0,1.36,10]],"ltp":1.4,"tv":175.83,"id":72857114},{"batb":[[0,1.32,14],[1,1.31,6.21],[2,1.27,1111.11]],"ltp":1.4,"tv":178.08,"id":72922097}]}]}
{"op":"mcm","clk":"11896430256","pt":1724343321775,"mc":[{"id":"1.232129550","rc":[{"batb":[[0,1.37,4],[1,1.36,10],[2,1.35,31.27]],"ltp":1.4,"tv":175.83,"id":72857114},{"batb":[[0,1.32,10]],"ltp":1.4,"tv":178.08,"id":72922097}]}]}
{"op":"mcm","clk":"11896430368","pt":1724343322777,"mc":[{"id":"1.232129550","rc":[{"batb":[[1,1.35,31.27],[2,1.34,882.35]],"ltp":1.4,"tv":175.83,"id":72857114},{"batb":[[0,1.31,6.21],[1,1.27,1111.11],[2,1.22,19.85]],"ltp":1.4,"tv":178.08,"id":72922097}]}]}
{"op":"mcm","clk":"11896430505","pt":1724343324082,"mc":[{"id":"1.232129550","rc":[{"batb":[[0,1.35,31.27],[1,1.34,882.35],[2,1.3,15]],"ltp":1.4,"tv":175.83,"id":72857114},{"batb":[[0,1.32,4],[1,1.31,6.21],[2,1.27,1111.11]],"ltp":1.4,"tv":178.08,"id":72922097}]}]}
{"op":"mcm","clk":"11896430793","pt":1724343326617,"mc":[{"id":"1.232129550","rc":[{"batb":[[0,1.36,14],[1,1.35,31.27],[2,1.34,882.35]],"ltp":1.4,"tv":175.83,"id":72857114},{"batb":[[0,1.32,10]],"ltp":1.4,"tv":178.08,"id":72922097}]}]}
{"op":"mcm","clk":"11896431171","pt":1724343329878,"mc":[{"id":"1.232129550","rc":[{"batb":[[0,1.35,31.27],[1,1.34,882.35],[2,1.3,15]],"ltp":1.4,"tv":175.83,"id":72857114},{"batb":[[0,1.33,4]],"ltp":1.4,"tv":178.08,"id":72922097}]}]}
{"op":"mcm","clk":"11896431368","pt":1724343331871,"mc":[{"id":"1.232129550","rc":[{"batb":[[0,1.36,4],[1,1.35,31.27],[2,1.34,882.35]],"ltp":1.4,"tv":175.83,"id":72857114},{"batb":[[0,1.31,6.21],[1,1.27,1111.11],[2,1.22,19.85]],"ltp":1.4,"tv":178.08,"id":72922097}]}]}
{"op":"mcm","clk":"11896431685","pt":1724343334500,"mc":[{"id":"1.232129550","rc":[{"batb":[[0,1.36,10]],"ltp":1.4,"tv":175.83,"id":72857114},{"batb":[[0,1.32,14],[1,1.31,6.21],[2,1.27,1111.11]],"ltp":1.4,"tv":178.08,"id":72922097}]}]}
{"op":"mcm","clk":"11896431991","pt":1724343336912,"mc":[{"id":"1.232129550","rc":[{"batb":[[0,1.37,4],[1,1.36,10],[2,1.35,31.27]],"ltp":1.4,"tv":175.83,"id":72857114},{"batb":[[0,1.32,10]],"ltp":1.4,"tv":178.08,"id":72922097}]}]}
{"op":"mcm","clk":"11896432125","pt":1724343337904,"mc":[{"id":"1.232129550","rc":[{"batb":[[1,1.35,31.27],[2,1.34,882.35]],"ltp":1.4,"tv":175.83,"id":72857114},{"batb":[[0,1.31,6.21],[1,1.27,1111.11],[2,1.22,19.85]],"ltp":1.4,"tv":178.08,"id":72922097}]}]}
{"op":"mcm","clk":"11896432325","pt":1724343339593,"mc":[{"id":"1.232129550","rc":[{"batb":[[0,1.35,31.27],[1,1.34,882.35],[2,1.3,15]],"ltp":1.4,"tv":175.83,"id":72857114},{"batb":[[0,1.32,4],[1,1.31,6.21],[2,1.27,1111.11]],"ltp":1.4,"tv":178.08,"id":72922097}]}]}
{"op":"mcm","clk":"11896432584","pt":1724343341791,"mc":[{"id":"1.232129550","rc":[{"batb":[[0,1.31,6.21],[1,1.27,1111.11],[2,1.22,19.85]],"ltp":1.4,"tv":178.08,"id":72922097}]}]}
{"op":"mcm","clk":"11896432631","pt":1724343342104,"mc":[{"id":"1.232129550","rc":[{"batb":[[0,1.36,14],[1,1.35,31.27],[2,1.34,882.35]],"ltp":1.4,"tv":175.83,"id":72857114},{"batb":[[0,1.32,10],[1,1.31,6.21],[2,1.27,1111.11]],"ltp":1.4,"tv":178.08,"id":72922097}]}]}
{"op":"mcm","clk":"11896432901","pt":1724343344607,"mc":[{"id":"1.232129550","rc":[{"batb":[[0,1.36,10]],"ltp":1.4,"tv":175.83,"id":72857114},{"batb":[[0,1.33,4],[1,1.32,10],[2,1.31,6.21]],"ltp":1.4,"tv":178.08,"id":72922097}]}]}
{"op":"mcm","clk":"11896432973","pt":1724343345386,"mc":[{"id":"1.232129550","rc":[{"batb":[[0,1.35,31.27],[1,1.34,882.35],[2,1.3,15]],"ltp":1.4,"tv":175.83,"id":72857114},{"batb":[[1,1.31,6.21],[2,1.27,1111.11]],"ltp":1.4,"tv":178.08,"id":72922097}]}]}
{"op":"mcm","clk":"11896433144","pt":1724343347088,"mc":[{"id":"1.232129550","rc":[{"batb":[[0,1.36,4],[1,1.35,31.27],[2,1.34,882.35]],"ltp":1.4,"tv":175.83,"id":72857114},{"batb":[[0,1.31,6.21],[1,1.27,1111.11],[2,1.22,19.85]],"ltp":1.4,"tv":178.08,"id":72922097}]}]}
{"op":"mcm","clk":"11896433448","pt":1724343349611,"mc":[{"id":"1.232129550","rc":[{"batb":[[0,1.36,10]],"ltp":1.4,"tv":175.83,"id":72857114},{"batb":[[0,1.32,14],[1,1.31,6.21],[2,1.27,1111.11]],"ltp":1.4,"tv":178.08,"id":72922097}]}]}
{"op":"mcm","clk":"11896433714","pt":1724343351894,"mc":[{"id":"1.232129550","rc":[{"batb":[[0,1.32,10]],"ltp":1.4,"tv":178.08,"id":72922097}]}]}
{"op":"mcm","clk":"11896433826","pt":1724343352892,"mc":[{"id":"1.232129550","rc":[{"batb":[[0,1.37,4]],"ltp":1.4,"tv":175.83,"id":72857114},{"batb":[[0,1.31,6.21],[1,1.27,1111.11],[2,1.22,19.85]],"ltp":1.4,"tv":178.08,"id":72922097}]}]}
{"op":"mcm","clk":"11896433938","pt":1724343353888,"mc":[{"id":"1.232129550","rc":[{"batb":[[0,1.41,12.67],[1,1.37,4],[2,1.35,31.27]],"ltp":1.4,"tv":175.83,"id":72857114}]}]}
{"op":"mcm","clk":"11896434027","pt":1724343354714,"mc":[{"id":"1.232129550","rc":[{"batb":[[1,1.35,31.27],[2,1.34,882.35]],"ltp":1.4,"tv":175.83,"id":72857114},{"batb":[[0,1.32,4],[1,1.31,6.21],[2,1.27,1111.11]],"ltp":1.4,"tv":178.08,"id":72922097}]}]}
{"op":"mcm","clk":"11896434259","pt":1724343357102,"mc":[{"id":"1.232129550","rc":[{"batb":[[0,1.42,14],[1,1.41,12.67],[2,1.35,31.27]],"ltp":1.4,"tv":175.83,"id":72857114},{"batb":[[0,1.32,10]],"ltp":1.4,"tv":178.08,"id":72922097}]}]}
{"op":"mcm","clk":"11896434513","pt":1724343359510,"mc":[{"id":"1.232129550","rc":[{"batb":[[0,1.42,10]],"ltp":1.4,"tv":175.83,"id":72857114},{"batb":[[0,1.33,4],[1,1.32,10],[2,1.31,6.21]],"ltp":1.4,"tv":178.08,"id":72922097}]}]}
{"op":"mcm","clk":"11896434617","pt":1724343360506,"mc":[{"id":"1.232129550","rc":[{"batb":[[0,1.35,31.27],[1,1.34,882.35],[2,1.3,15]],"ltp":1.4,"tv":175.83,"id":72857114},{"batb":[[1,1.31,6.21],[2,1.27,1111.11]],"ltp":1.4,"tv":178.08,"id":72922097}]}]}
{"op":"mcm","clk":"11896434757","pt":1724343361794,"mc":[{"id":"1.232129550","rc":[{"batb":[[0,1.31,6.21],[1,1.27,1111.11],[2,1.22,19.85]],"ltp":1.4,"tv":178.08,"id":72922097}]}]}
{"op":"mcm","clk":"11896434778","pt":1724343362010,"mc":[{"id":"1.232129550","rc":[{"batb":[[0,1.36,4],[1,1.35,31.27],[2,1.34,882.35]],"ltp":1.4,"tv":175.83,"id":72857114}]}]}
{"op":"mcm","clk":"11896435020","pt":1724343364411,"mc":[{"id":"1.232129550","rc":[{"batb":[[0,1.36,10]],"ltp":1.4,"tv":175.83,"id":72857114},{"batb":[[0,1.32,14],[1,1.31,6.21],[2,1.27,1111.11]],"ltp":1.4,"tv":178.08,"id":72922097}]}]}
{"op":"mcm","clk":"11896435317","pt":1724343366936,"mc":[{"id":"1.232129550","rc":[{"batb":[[0,1.32,10]],"ltp":1.4,"tv":178.08,"id":72922097}]}]}
{"op":"mcm","clk":"11896435446","pt":1724343367932,"mc":[{"id":"1.232129550","rc":[{"batb":[[0,1.37,4]],"ltp":1.4,"tv":175.83,"id":72857114},{"batb":[[0,1.31,6.21],[1,1.27,1111.11],[2,1.22,19.85]],"ltp":1.4,"tv":178.08,"id":72922097}]}]}
{"op":"mcm","clk":"11896435636","pt":1724343369719,"mc":[{"id":"1.232129550","rc":[{"batb":[[0,1.35,31.27],[1,1.34,882.35],[2,1.3,15]],"ltp":1.4,"tv":175.83,"id":72857114},{"batb":[[0,1.32,4],[1,1.31,6.21],[2,1.27,1111.11]],"ltp":1.4,"tv":178.08,"id":72922097}]}]}
{"op":"mcm","clk":"11896435720","pt":1724343370353,"mc":[{"id":"1.232129550","rc":[{"batb":[[0,1.36,10],[1,1.35,31.27],[2,1.34,882.35]],"ltp":1.4,"tv":175.83,"id":72857114},{"batb":[[0,1.42,10],[1,1.41,12.67],[2,1.32,4]],"ltp":1.4,"tv":178.08,"id":72922097}]}]}
{"op":"mcm","clk":"11896435948","pt":1724343372235,"mc":[{"id":"1.232129550","rc":[{"batb":[[0,1.37,4],[1,1.36,10],[2,1.35,31.27]],"ltp":1.4,"tv":175.83,"id":72857114},{"batb":[[2,1.31,6.21]],"ltp":1.4,"tv":178.08,"id":72922097}]}]}
{"op":"mcm","clk":"11896436101","pt":1724343373730,"mc":[{"id":"1.232129550","rc":[{"batb":[[1,1.35,31.27],[2,1.34,882.35]],"ltp":1.4,"tv":175.83,"id":72857114},{"batb":[[0,1.31,6.21],[1,1.27,1111.11],[2,1.22,19.85]],"ltp":1.4,"tv":178.08,"id":72922097}]}]}
{"op":"mcm","clk":"11896436194","pt":1724343374729,"mc":[{"id":"1.232129550","rc":[{"batb":[[0,1.35,31.27],[1,1.34,882.35],[2,1.3,15]],"ltp":1.4,"tv":175.83,"id":72857114},{"batb":[[0,1.32,4],[1,1.31,6.21],[2,1.27,1111.11]],"ltp":1.4,"tv":178.08,"id":72922097}]}]}
{"op":"mcm","clk":"11896436473","pt":1724343377220,"mc":[{"id":"1.232129550","rc":[{"batb":[[0,1.36,14],[1,1.35,31.27],[2,1.34,882.35]],"ltp":1.4,"tv":175.83,"id":72857114},{"batb":[[0,1.32,10]],"ltp":1.4,"tv":178.08,"id":72922097}]}]}
{"op":"mcm","clk":"11896436759","pt":1724343379953,"mc":[{"id":"1.232129550","rc":[{"batb":[[0,1.36,10]],"ltp":1.4,"tv":175.83,"id":72857114},{"batb":[[0,1.33,4],[1,1.32,10],[2,1.31,6.21]],"ltp":1.4,"tv":178.08,"id":72922097}]}]}
{"op":"mcm","clk":"11896436842","pt":1724343380748,"mc":[{"id":"1.232129550","rc":[{"batb":[[0,1.35,31.27],[1,1.34,882.35],[2,1.3,15]],"ltp":1.4,"tv":175.83,"id":72857114},{"batb":[[1,1.31,6.21],[2,1.27,1111.11]],"ltp":1.4,"tv":178.08,"id":72922097}]}]}
{"op":"mcm","clk":"11896437039","pt":1724343382425,"mc":[{"id":"1.232129550","rc":[{"batb":[[0,1.36,4],[1,1.35,31.27],[2,1.34,882.35]],"ltp":1.4,"tv":175.83,"id":72857114},{"batb":[[0,1.31,6.21],[1,1.27,1111.11],[2,1.22,19.85]],"ltp":1.4,"tv":178.08,"id":72922097}]}]}
{"op":"mcm","clk":"11896437309","pt":1724343384937,"mc":[{"id":"1.232129550","rc":[{"batb":[[0,1.36,10]],"ltp":1.4,"tv":175.83,"id":72857114},{"batb":[[0,1.32,14],[1,1.31,6.21],[2,1.27,1111.11]],"ltp":1.4,"tv":178.08,"id":72922097}]}]}
{"op":"mcm","clk":"11896437594","pt":1724343387548,"mc":[{"id":"1.232129550","rc":[{"batb":[[0,1.37,4],[1,1.36,10],[2,1.35,31.27]],"ltp":1.4,"tv":175.83,"id":72857114},{"batb":[[0,1.32,10]],"ltp":1.4,"tv":178.08,"id":72922097}]}]}
{"op":"mcm","clk":"11896437672","pt":1724343388231,"mc":[{"id":"1.232129550","rc":[{"batb":[[1,1.35,31.27],[2,1.34,882.35]],"ltp":1.4,"tv":175.83,"id":72857114},{"batb":[[0,1.31,6.21],[1,1.27,1111.11],[2,1.22,19.85]],"ltp":1.4,"tv":178.08,"id":72922097}]}]}
{"op":"mcm","clk":"11896437830","pt":1724343389846,"mc":[{"id":"1.232129550","rc":[{"batb":[[0,1.35,31.27],[1,1.34,882.35],[2,1.3,15]],"ltp":1.4,"tv":175.83,"id":72857114},{"batb":[[0,1.32,4],[1,1.31,6.21],[2,1.27,1111.11]],"ltp":1.4,"tv":178.08,"id":72922097}]}]}
{"op":"mcm","clk":"11896437951","pt":1724343391049,"mc":[{"id":"1.232129550","rc":[{"batb":[[0,1.36,10],[1,1.35,31.27],[2,1.34,882.35]],"ltp":1.4,"tv":175.83,"id":72857114},{"batb":[[0,1.33,10],[1,1.32,4],[2,1.31,6.21]],"ltp":1.4,"tv":178.08,"id":72922097}]}]}
{"op":"mcm","clk":"11896438109","pt":1724343392566,"mc":[{"id":"1.232129550","rc":[{"batb":[[0,1.37,4],[1,1.36,10],[2,1.35,31.27]],"ltp":1.4,"tv":175.83,"id":72857114},{"batb":[[1,1.31,6.21],[2,1.27,1111.11]],"ltp":1.4,"tv":178.08,"id":72922097}]}]}
{"op":"mcm","clk":"11896438364","pt":1724343394776,"mc":[{"id":"1.232129550","rc":[{"batb":[[0,1.35,31.27],[1,1.34,882.35],[2,1.3,15]],"ltp":1.4,"tv":175.83,"id":72857114},{"batb":[[0,1.32,4]],"ltp":1.4,"tv":178.08,"id":72922097}]}]}
{"op":"mcm","clk":"11896438649","pt":1724343397242,"mc":[{"id":"1.232129550","rc":[{"batb":[[0,1.36,14],[1,1.35,31.27],[2,1.34,882.35]],"ltp":1.4,"tv":175.83,"id":72857114},{"batb":[[0,1.32,10]],"ltp":1.4,"tv":178.08,"id":72922097}]}]}
{"op":"mcm","clk":"11896438902","pt":1724343399851,"mc":[{"id":"1.232129550","rc":[{"batb":[[0,1.36,10]],"ltp":1.4,"tv":175.83,"id":72857114},{"batb":[[0,1.33,4],[1,1.32,10],[2,1.31,6.21]],"ltp":1.4,"tv":178.08,"id":72922097}]}]}
{"op":"mcm","clk":"11896438970","pt":1724343400637,"mc":[{"id":"1.232129550","rc":[{"batb":[[0,1.35,31.27],[1,1.34,882.35],[2,1.3,15]],"ltp":1.4,"tv":175.83,"id":72857114},{"batb":[[1,1.31,6.21],[2,1.27,1111.11]],"ltp":1.4,"tv":178.08,"id":72922097}]}]}
{"op":"mcm","clk":"11896439140","pt":1724343402354,"mc":[{"id":"1.232129550","rc":[{"batb":[[0,1.36,4],[1,1.35,31.27],[2,1.34,882.35]],"ltp":1.4,"tv":175.83,"id":72857114},{"batb":[[0,1.31,6.21],[1,1.27,1111.11],[2,1.22,19.85]],"ltp":1.4,"tv":178.08,"id":72922097}]}]}
{"op":"mcm","clk":"11896439375","pt":1724343404770,"mc":[{"id":"1.232129550","rc":[{"batb":[[0,1.36,10]],"ltp":1.4,"tv":175.83,"id":72857114},{"batb":[[0,1.32,14],[1,1.31,6.21],[2,1.27,1111.11]],"ltp":1.4,"tv":178.08,"id":72922097}]}]}
{"op":"mcm","clk":"11896439644","pt":1724343407266,"mc":[{"id":"1.232129550","rc":[{"batb":[[0,1.37,4],[1,1.36,10],[2,1.35,31.27]],"ltp":1.4,"tv":175.83,"id":72857114},{"batb":[[0,1.32,10]],"ltp":1.4,"tv":178.08,"id":72922097}]}]}
{"op":"mcm","clk":"11896439740","pt":1724343408158,"mc":[{"id":"1.232129550","rc":[{"batb":[[1,1.35,31.27],[2,1.34,882.35]],"ltp":1.4,"tv":175.83,"id":72857114},{"batb":[[0,1.31,6.21],[1,1.27,1111.11],[2,1.22,19.85]],"ltp":1.4,"tv":178.08,"id":72922097}]}]}
{"op":"mcm","clk":"11896439928","pt":1724343409883,"mc":[{"id":"1.232129550","rc":[{"batb":[[0,1.35,31.27],[1,1.34,882.35],[2,1.3,15]],"ltp":1.4,"tv":175.83,"id":72857114},{"batb":[[0,1.32,4],[1,1.31,6.21],[2,1.27,1111.11]],"ltp":1.4,"tv":178.08,"id":72922097}]}]}
{"op":"mcm","clk":"11896440207","pt":1724343412079,"mc":[{"id":"1.232129550","rc":[{"batb":[[0,1.36,14],[1,1.35,31.27],[2,1.34,882.35]],"ltp":1.4,"tv":175.83,"id":72857114},{"batb":[[0,1.33,10]],"ltp":1.4,"tv":178.08,"id":72922097}]}]}
{"op":"mcm","clk":"11896440452","pt":1724343414280,"mc":[{"id":"1.232129550","rc":[{"batb":[[0,1.36,10]],"ltp":1.4,"tv":175.83,"id":72857114},{"batb":[[0,1.34,4],[1,1.33,10],[2,1.31,6.21]],"ltp":1.4,"tv":178.08,"id":72922097}]}]}
{"op":"mcm","clk":"11896440561","pt":1724343415277,"mc":[{"id":"1.232129550","rc":[{"batb":[[0,1.35,31.27],[1,1.34,882.35],[2,1.3,15]],"ltp":1.4,"tv":175.83,"id":72857114},{"batb":[[1,1.31,6.21],[2,1.27,1111.11]],"ltp":1.4,"tv":178.08,"id":72922097}]}]}
{"op":"mcm","clk":"11896440692","pt":1724343416684,"mc":[{"id":"1.232129550","rc":[{"batb":[[0,1.36,4],[1,1.35,31.27],[2,1.34,882.35]],"ltp":1.4,"tv":175.83,"id":72857114},{"batb":[[0,1.31,6.21],[1,1.27,1111.11],[2,1.22,19.85]],"ltp":1.4,"tv":178.08,"id":72922097}]}]}
{"op":"mcm","clk":"11896440967","pt":1724343419093,"mc":[{"id":"1.232129550","rc":[{"batb":[[0,1.36,10]],"ltp":1.4,"tv":175.83,"id":72857114},{"batb":[[0,1.32,14],[1,1.31,6.21],[2,1.27,1111.11]],"ltp":1.4,"tv":178.08,"id":72922097}]}]}
{"op":"mcm","clk":"11896441236","pt":1724343421390,"mc":[{"id":"1.232129550","rc":[{"batb":[[0,1.37,4],[1,1.36,10],[2,1.35,31.27]],"ltp":1.4,"tv":175.83,"id":72857114},{"batb":[[0,1.32,10]],"ltp":1.4,"tv":178.08,"id":72922097}]}]}
