{"op":"mcm","clk":"11935354238","pt":1724665591597,"mc":[{"id":"1.232298775","marketDefinition":{"bspMarket":false,"turnInPlayEnabled":true,"persistenceEnabled":true,"marketBaseRate":5.0,"eventId":"33528205","eventTypeId":"4","numberOfWinners":1,"bettingType":"ODDS","marketType":"MATCH_ODDS","marketTime":"2024-08-27T02:30:00.000Z","suspendTime":"2024-08-27T02:30:00.000Z","bspReconciled":false,"complete":true,"inPlay":false,"crossMatching":false,"runnersVoidable":false,"numberOfActiveRunners":2,"betDelay":0,"status":"OPEN","runners":[{"status":"ACTIVE","sortPriority":1,"id":8858694,"name":"Kuwait"},{"status":"ACTIVE","sortPriority":2,"id":247649,"name":"Hong Kong"}],"regulators":["MR_INT"],"countryCode":"GB","discountAllowed":false,"timezone":"GMT","openDate":"2024-08-27T02:30:00.000Z","version":6101149509,"name":"Match Odds","eventName":"Kuwait v Hong Kong"},"rc":[{"batb":[[0,1.03,200],[1,1.02,200],[2,1.01,220]],"ltp":0.0,"tv":0.0,"id":247649},{"batb":[[0,1.03,200],[1,1.02,200],[2,1.01,220]],"ltp":0.0,"tv":0.0,"id":8858694}]}]}
{"op":"mcm","clk":"11935354363","pt":1724665592881,"mc":[{"id":"1.232298775","marketDefinition":{"bspMarket":false,"turnInPlayEnabled":true,"persistenceEnabled":true,"marketBaseRate":5.0,"eventId":"33528205","eventTypeId":"4","numberOfWinners":1,"bettingType":"ODDS","marketType":"MATCH_ODDS","marketTime":"2024-08-27T02:30:00.000Z","suspendTime":"2024-08-27T02:30:00.000Z","bspReconciled":false,"complete":true,"inPlay":false,"crossMatching":false,"runnersVoidable":false,"numberOfActiveRunners":2,"betDelay":0,"status":"OPEN","runners":[{"status":"ACTIVE","sortPriority":1,"id":8858694,"name":"Kuwait"},{"status":"ACTIVE","sortPriority":2,"id":247649,"name":"Hong Kong"}],"regulators":["MR_INT"],"countryCode":"GB","discountAllowed":true,"timezone":"GMT","openDate":"2024-08-27T02:30:00.000Z","version":6101149509,"name":"Match Odds","eventName":"Kuwait v Hong Kong"}}]}
{"op":"mcm","clk":"11935361657","pt":1724665671790,"mc":[{"id":"1.232298775","rc":[{"batb":[[0,1.04,1615.55],[1,1.03,2338.26],[2,1.02,3357.4]],"ltp":0.0,"tv":0.0,"id":8858694}]}]}
{"op":"mcm","clk":"11935361713","pt":1724665672407,"mc":[{"id":"1.232298775","rc":[{"batb":[[0,1.04,1615.55],[1,1.03,2338.26],[2,1.02,3357.4]],"ltp":0.0,"tv":0.0,"id":247649}]}]}
{"op":"mcm","clk":"11935649138","pt":1724668974878,"mc":[{"id":"1.232298775","rc":[{"batb":[[0,1.04,1615.83],[1,1.03,2338.62],[2,1.02,3357.94]],"ltp":0.0,"tv":0.0,"id":247649},{"batb":[[0,1.04,1615.83],[1,1.03,2338.62],[2,1.02,3357.94]],"ltp":0.0,"tv":0.0,"id":8858694}]}]}
{"op":"mcm","clk":"11935718198","pt":1724669686205,"mc":[{"id":"1.232298775","rc":[{"batb":[[0,1.2,125],[1,1.04,1615.83],[2,1.03,2338.62]],"ltp":0.0,"tv":0.0,"id":247649},{"batb":[[0,1.2,125],[1,1.04,1615.83],[2,1.03,2338.62]],"ltp":0.0,"tv":0.0,"id":8858694}]}]}
{"op":"mcm","clk":"11935720104","pt":1724669709465,"mc":[{"id":"1.232298775","marketDefinition":{"bspMarket":false,"turnInPlayEnabled":true,"persistenceEnabled":true,"marketBaseRate":5.0,"eventId":"33528205","eventTypeId":"4","numberOfWinners":1,"bettingType":"ODDS","marketType":"MATCH_ODDS","marketTime":"2024-08-27T02:30:00.000Z","suspendTime":"2024-08-27T02:30:00.000Z","bspReconciled":false,"complete":true,"inPlay":false,"crossMatching":true,"runnersVoidable":false,"numberOfActiveRunners":2,"betDelay":0,"status":"OPEN","runners":[{"status":"ACTIVE","sortPriority":1,"id":8858694,"name":"Kuwait"},{"status":"ACTIVE","sortPriority":2,"id":247649,"name":"Hong Kong"}],"regulators":["MR_INT"],"countryCode":"GB","discountAllowed":true,"timezone":"GMT","openDate":"2024-08-27T02:30:00.000Z","version":6101149509,"name":"Match Odds","eventName":"Kuwait v Hong Kong"}}]}
{"op":"mcm","clk":"11935768167","pt":1724670278729,"mc":[{"id":"1.232298775","rc":[{"batb":[[1,1.04,1614.05],[2,1.03,2336.27]],"batl":[[0,5.9,0.7]],"ltp":0.0,"tv":0.0,"id":247649},{"batb":[[1,1.04,1614.05],[2,1.03,2336.27]],"ltp":0.0,"tv":0.0,"id":8858694}]}]}
{"op":"mcm","clk":"11935768897","pt":1724670287729,"mc":[{"id":"1.232298775","rc":[{"batl":[[0,5.9,0.7]],"ltp":0.0,"tv":0.0,"id":8858694}]}]}
{"op":"mcm","clk":"11935845536","pt":1724671247509,"mc":[{"id":"1.232298775","rc":[{"batb":[[0,1.69,55.71],[1,1.2,125],[2,1.04,1614.05]],"ltp":0.0,"tv":0.0,"id":247649},{"batb":[[0,2.34,28.69],[1,1.2,125],[2,1.04,1614.05]],"ltp":0.0,"tv":0.0,"id":8858694}]}]}
{"op":"mcm","clk":"11936014294","pt":1724673302223,"mc":[{"id":"1.232298775","rc":[{"trd":[[1.75,38.36]],"batb":[[0,1.76,5],[1,1.75,23.18],[2,1.69,55.71]],"ltp":1.75,"tv":38.36,"id":247649},{"trd":[[2.34,28.69]],"batb":[[0,1.21,5]],"ltp":2.34,"tv":28.69,"id":8858694}],"tv":67.05}]}
{"op":"mcm","clk":"11936014598","pt":1724673305727,"mc":[{"id":"1.232298775","rc":[{"batb":[[0,1.75,23.18],[1,1.69,55.71],[2,1.2,125]],"ltp":1.75,"tv":38.36,"id":247649},{"batb":[[0,2.26,30.51]],"ltp":2.34,"tv":28.69,"id":8858694}]}]}
{"op":"mcm","clk":"11936014877","pt":1724673308873,"mc":[{"id":"1.232298775","rc":[{"batb":[[0,1.76,5],[1,1.75,23.18],[2,1.69,55.71]],"ltp":1.75,"tv":38.36,"id":247649},{"batb":[[0,2.28,5],[1,2.26,30.51],[2,1.2,125]],"ltp":2.34,"tv":28.69,"id":8858694}]}]}
{"op":"mcm","clk":"11936015044","pt":1724673310747,"mc":[{"id":"1.232298775","rc":[{"batb":[[2,1.2,125]],"ltp":1.75,"tv":38.36,"id":247649},{"batb":[[1,1.2,125],[2,1.04,1614.05]],"ltp":2.34,"tv":28.69,"id":8858694}]}]}
{"op":"mcm","clk":"11936015205","pt":1724673312050,"mc":[{"id":"1.232298775","rc":[{"batb":[[0,1.75,23.18],[1,1.2,125],[2,1.04,1614.05]],"ltp":1.75,"tv":38.36,"id":247649},{"batb":[[0,1.2,125],[1,1.04,1614.05],[2,1.03,2336.27]],"ltp":2.34,"tv":28.69,"id":8858694}]}]}
{"op":"mcm","clk":"11936015541","pt":1724673315853,"mc":[{"id":"1.232298775","rc":[{"batb":[[0,1.76,5],[1,1.75,23.18],[2,1.69,55.71]],"ltp":1.75,"tv":38.36,"id":247649},{"batb":[[0,2.28,5],[1,2.26,30.51],[2,1.2,125]],"ltp":2.34,"tv":28.69,"id":8858694}]}]}
{"op":"mcm","clk":"11936015842","pt":1724673319248,"mc":[{"id":"1.232298775","rc":[{"batb":[[0,1.75,23.18],[1,1.69,55.71],[2,1.2,125]],"ltp":1.75,"tv":38.36,"id":247649},{"batb":[[0,2.26,30.51],[1,1.2,125],[2,1.04,1614.05]],"ltp":2.34,"tv":28.69,"id":8858694}]}]}
{"op":"mcm","clk":"11936016873","pt":1724673330977,"mc":[{"id":"1.232298775","rc":[{"batb":[[0,1.76,5],[1,1.75,23.18],[2,1.69,55.71]],"ltp":1.75,"tv":38.36,"id":247649},{"batb":[[0,2.28,5],[1,2.26,30.51],[2,1.2,125]],"ltp":2.34,"tv":28.69,"id":8858694}]}]}
{"op":"mcm","clk":"11936017168","pt":1724673334401,"mc":[{"id":"1.232298775","rc":[{"batb":[[0,1.75,23.18],[1,1.69,55.71],[2,1.2,125]],"ltp":1.75,"tv":38.36,"id":247649},{"batb":[[0,2.26,30.51],[1,1.2,125],[2,1.04,1614.05]],"ltp":2.34,"tv":28.69,"id":8858694}]}]}
{"op":"mcm","clk":"11936017680","pt":1724673339725,"mc":[{"id":"1.232298775","rc":[{"batb":[[0,1.76,5],[1,1.75,23.18],[2,1.69,55.71]],"ltp":1.75,"tv":38.36,"id":247649},{"batb":[[0,2.28,5],[1,2.26,30.51],[2,1.2,125]],"ltp":2.34,"tv":28.69,"id":8858694}]}]}
{"op":"mcm","clk":"11936017790","pt":1724673340916,"mc":[{"id":"1.232298775","rc":[{"batb":[[2,1.2,125]],"ltp":1.75,"tv":38.36,"id":247649},{"batb":[[1,1.2,125],[2,1.04,1614.05]],"ltp":2.34,"tv":28.69,"id":8858694}]}]}
{"op":"mcm","clk":"11936017973","pt":1724673343021,"mc":[{"id":"1.232298775","rc":[{"batb":[[0,1.75,23.18],[1,1.2,125],[2,1.04,1614.05]],"ltp":1.75,"tv":38.36,"id":247649},{"batb":[[0,1.2,125],[1,1.04,1614.05],[2,1.03,2336.27]],"ltp":2.34,"tv":28.69,"id":8858694}]}]}
{"op":"mcm","clk":"11936018201","pt":1724673345802,"mc":[{"id":"1.232298775","rc":[{"batb":[[1,1.69,55.71],[2,1.2,125]],"ltp":1.75,"tv":38.36,"id":247649},{"batb":[[0,2.26,30.51],[1,1.2,125],[2,1.04,1614.05]],"ltp":2.34,"tv":28.69,"id":8858694}]}]}
{"op":"mcm","clk":"11936018210","pt":1724673345909,"mc":[{"id":"1.232298775","rc":[{"batb":[[0,1.76,5],[1,1.75,23.18],[2,1.69,55.71]],"ltp":1.75,"tv":38.36,"id":247649},{"batb":[[0,2.28,5],[1,2.26,30.51],[2,1.2,125]],"ltp":2.34,"tv":28.69,"id":8858694}]}]}
{"op":"mcm","clk":"11936018544","pt":1724673349099,"mc":[{"id":"1.232298775","rc":[{"batb":[[0,1.75,23.18],[1,1.69,55.71],[2,1.2,125]],"ltp":1.75,"tv":38.36,"id":247649},{"batb":[[0,2.26,30.51],[1,1.2,125],[2,1.04,1614.05]],"ltp":2.34,"tv":28.69,"id":8858694}]}]}
{"op":"mcm","clk":"11936018852","pt":1724673352440,"mc":[{"id":"1.232298775","rc":[{"batb":[[0,1.76,5],[1,1.75,23.18],[2,1.69,55.71]],"ltp":1.75,"tv":38.36,"id":247649},{"batb":[[0,2.28,5],[1,2.26,30.51],[2,1.2,125]],"ltp":2.34,"tv":28.69,"id":8858694}]}]}
{"op":"mcm","clk":"11936019126","pt":1724673355629,"mc":[{"id":"1.232298775","rc":[{"batb":[[0,1.75,23.18],[1,1.69,55.71],[2,1.2,125]],"ltp":1.75,"tv":38.36,"id":247649},{"batb":[[0,2.26,30.51],[1,1.2,125],[2,1.04,1614.05]],"ltp":2.34,"tv":28.69,"id":8858694}]}]}
{"op":"mcm","clk":"11936019433","pt":1724673359330,"mc":[{"id":"1.232298775","rc":[{"batb":[[0,1.76,5],[1,1.75,23.18],[2,1.69,55.71]],"ltp":1.75,"tv":38.36,"id":247649},{"batb":[[0,2.28,5],[1,2.26,30.51],[2,1.2,125]],"ltp":2.34,"tv":28.69,"id":8858694}]}]}
{"op":"mcm","clk":"11936019561","pt":1724673360926,"mc":[{"id":"1.232298775","rc":[{"batb":[[2,1.2,125]],"ltp":1.75,"tv":38.36,"id":247649},{"batb":[[1,1.2,125],[2,1.04,1614.05]],"ltp":2.34,"tv":28.69,"id":8858694}]}]}
{"op":"mcm","clk":"11936019695","pt":1724673362623,"mc":[{"id":"1.232298775","rc":[{"batb":[[0,1.75,23.18],[1,1.2,125],[2,1.04,1614.05]],"ltp":1.75,"tv":38.36,"id":247649},{"batb":[[0,1.2,125],[1,1.04,1614.05],[2,1.03,2336.27]],"ltp":2.34,"tv":28.69,"id":8858694}]}]}
{"op":"mcm","clk":"11936019968","pt":1724673366039,"mc":[{"id":"1.232298775","rc":[{"batb":[[0,1.76,5],[1,1.75,23.18],[2,1.69,55.71]],"ltp":1.75,"tv":38.36,"id":247649},{"batb":[[0,2.28,5],[1,2.26,30.51],[2,1.2,125]],"ltp":2.34,"tv":28.69,"id":8858694}]}]}
{"op":"mcm","clk":"11936020278","pt":1724673369331,"mc":[{"id":"1.232298775","rc":[{"batb":[[0,1.75,23.18],[1,1.69,55.71],[2,1.2,125]],"ltp":1.75,"tv":38.36,"id":247649},{"batb":[[0,2.26,30.51],[1,1.2,125],[2,1.04,1614.05]],"ltp":2.34,"tv":28.69,"id":8858694}]}]}
{"op":"mcm","clk":"11936020926","pt":1724673376958,"mc":[{"id":"1.232298775","rc":[{"batb":[[0,1.76,5],[1,1.75,23.18],[2,1.69,55.71]],"ltp":1.75,"tv":38.36,"id":247649},{"batb":[[0,2.28,5],[1,2.26,30.51],[2,1.2,125]],"ltp":2.34,"tv":28.69,"id":8858694}]}]}
{"op":"mcm","clk":"11936021238","pt":1724673380157,"mc":[{"id":"1.232298775","rc":[{"batb":[[0,1.75,23.18],[1,1.69,55.71],[2,1.2,125]],"ltp":1.75,"tv":38.36,"id":247649},{"batb":[[0,2.26,30.51],[1,1.2,125],[2,1.04,1614.05]],"ltp":2.34,"tv":28.69,"id":8858694}]}]}
{"op":"mcm","clk":"11936022251","pt":1724673389955,"mc":[{"id":"1.232298775","rc":[{"batb":[[0,1.76,5],[1,1.75,23.18],[2,1.69,55.71]],"ltp":1.75,"tv":38.36,"id":247649},{"batb":[[0,2.28,5],[1,2.26,30.51],[2,1.2,125]],"ltp":2.34,"tv":28.69,"id":8858694}]}]}
{"op":"mcm","clk":"11936022357","pt":1724673391243,"mc":[{"id":"1.232298775","rc":[{"trd":[[1.76,0.3]],"batb":[[0,1.76,4.85],[2,1.2,125]],"ltp":1.76,"tv":38.66,"id":247649},{"batb":[[1,1.2,125],[2,1.04,1614.05]],"ltp":2.34,"tv":28.69,"id":8858694}],"tv":67.35}]}
{"op":"mcm","clk":"11936022548","pt":1724673393153,"mc":[{"id":"1.232298775","rc":[{"batb":[[0,1.75,23.18],[1,1.2,125],[2,1.04,1614.05]],"ltp":1.76,"tv":38.66,"id":247649},{"batb":[[0,1.2,125],[1,1.04,1614.05],[2,1.03,2336.27]],"ltp":2.34,"tv":28.69,"id":8858694}]}]}
{"op":"mcm","clk":"11936022856","pt":1724673396256,"mc":[{"id":"1.232298775","rc":[{"batb":[[0,1.76,5],[1,1.75,23.18],[2,1.69,55.71]],"ltp":1.76,"tv":38.66,"id":247649},{"batb":[[0,2.28,5],[1,2.26,30.51],[2,1.2,125]],"ltp":2.34,"tv":28.69,"id":8858694}]}]}
{"op":"mcm","clk":"11936023136","pt":1724673399394,"mc":[{"id":"1.232298775","rc":[{"batb":[[0,1.75,23.18],[1,1.69,55.71],[2,1.2,125]],"ltp":1.76,"tv":38.66,"id":247649},{"batb":[[0,2.26,30.51],[1,1.2,125],[2,1.04,1614.05]],"ltp":2.34,"tv":28.69,"id":8858694}]}]}
{"op":"mcm","clk":"11936023558","pt":1724673403968,"mc":[{"id":"1.232298775","rc":[{"batb":[[0,1.76,5],[1,1.75,23.18],[2,1.69,55.71]],"ltp":1.76,"tv":38.66,"id":247649},{"batb":[[0,2.28,5],[1,2.26,30.51],[2,1.2,125]],"ltp":2.34,"tv":28.69,"id":8858694}]}]}
{"op":"mcm","clk":"11936023756","pt":1724673406491,"mc":[{"id":"1.232298775","rc":[{"trd":[[1.76,6.54]],"batb":[[0,1.76,1.88],[2,1.2,125]],"ltp":1.76,"tv":44.9,"id":247649},{"batb":[[1,1.2,125],[2,1.04,1614.05]],"ltp":2.34,"tv":28.69,"id":8858694}],"tv":73.59}]}
{"op":"mcm","clk":"11936023815","pt":1724673407206,"mc":[{"id":"1.232298775","rc":[{"batb":[[0,1.75,23.18],[1,1.2,125],[2,1.04,1614.05]],"ltp":1.76,"tv":44.9,"id":247649},{"batb":[[0,1.2,125],[1,1.04,1614.05],[2,1.03,2336.27]],"ltp":2.34,"tv":28.69,"id":8858694}]}]}
{"op":"mcm","clk":"11936024013","pt":1724673409789,"mc":[{"id":"1.232298775","rc":[{"batb":[[0,1.76,9],[1,1.75,23.18],[2,1.2,125]],"batl":[[0,3.4,35.25],[1,5.9,0.7]],"ltp":1.76,"tv":44.9,"id":247649},{"batb":[[0,1.21,5],[1,1.2,125],[2,1.04,1614.05]],"ltp":2.34,"tv":28.69,"id":8858694}]}]}
{"op":"mcm","clk":"11936024108","pt":1724673411183,"mc":[{"id":"1.232298775","rc":[{"batb":[[2,1.69,55.71]],"ltp":1.76,"tv":44.9,"id":247649},{"batb":[[0,2.26,30.51],[1,1.21,5],[2,1.2,125]],"ltp":2.34,"tv":28.69,"id":8858694}]}]}
{"op":"mcm","clk":"11936024167","pt":1724673412006,"mc":[{"id":"1.232298775","rc":[{"batb":[[0,1.76,5]],"ltp":1.76,"tv":44.9,"id":247649}]}]}
{"op":"mcm","clk":"11936024268","pt":1724673413092,"mc":[{"id":"1.232298775","rc":[{"batb":[[0,1.75,23.18],[1,1.69,55.71],[2,1.2,125]],"ltp":1.76,"tv":44.9,"id":247649},{"batb":[[1,1.2,125],[2,1.04,1614.05]],"ltp":2.34,"tv":28.69,"id":8858694}]}]}
{"op":"mcm","clk":"11936024380","pt":1724673414218,"mc":[{"id":"1.232298775","rc":[{"batb":[[0,1.76,4],[1,1.75,20.83],[2,1.69,55.71]],"ltp":1.76,"tv":44.9,"id":247649}]}]}
{"op":"mcm","clk":"11936024477","pt":1724673415414,"mc":[{"id":"1.232298775","rc":[{"batb":[[0,1.77,5],[1,1.76,4],[2,1.75,20.83]],"ltp":1.76,"tv":44.9,"id":247649},{"batb":[[0,2.28,5],[1,2.26,30.51],[2,1.2,125]],"ltp":2.34,"tv":28.69,"id":8858694}]}]}
{"op":"mcm","clk":"11936024570","pt":1724673416495,"mc":[{"id":"1.232298775","rc":[{"batb":[[1,1.75,20.83],[2,1.2,125]],"ltp":1.76,"tv":44.9,"id":247649},{"batb":[[1,1.2,125],[2,1.04,1614.05]],"ltp":2.34,"tv":28.69,"id":8858694}]}]}
{"op":"mcm","clk":"11936024779","pt":1724673418816,"mc":[{"id":"1.232298775","rc":[{"batb":[[0,1.75,20.83],[1,1.2,125],[2,1.04,1614.05]],"ltp":1.76,"tv":44.9,"id":247649},{"batb":[[0,1.2,125],[1,1.04,1614.05],[2,1.03,2336.27]],"ltp":2.34,"tv":28.69,"id":8858694}]}]}
{"op":"mcm","clk":"11936024793","pt":1724673418919,"mc":[{"id":"1.232298775","rc":[{"batb":[[0,1.76,4],[1,1.75,20.83],[2,1.2,125]],"ltp":1.76,"tv":44.9,"id":247649}]}]}
{"op":"mcm","clk":"11936025004","pt":1724673421321,"mc":[{"id":"1.232298775","rc":[{"batb":[[0,1.76,5],[2,1.69,55.71]],"ltp":1.76,"tv":44.9,"id":247649},{"batb":[[0,2.26,30.51],[1,1.21,5],[2,1.2,125]],"ltp":2.34,"tv":28.69,"id":8858694}]}]}
{"op":"mcm","clk":"11936025347","pt":1724673424616,"mc":[{"id":"1.232298775","rc":[{"batb":[[0,1.76,4]],"ltp":1.76,"tv":44.9,"id":247649},{"batb":[[1,1.2,125],[2,1.04,1614.05]],"ltp":2.34,"tv":28.69,"id":8858694}]}]}
{"op":"mcm","clk":"11936025548","pt":1724673427140,"mc":[{"id":"1.232298775","rc":[{"batb":[[0,1.76,5]],"ltp":1.76,"tv":44.9,"id":247649},{"batb":[[0,2.28,5],[1,2.26,30.51],[2,1.2,125]],"ltp":2.34,"tv":28.69,"id":8858694}]}]}
{"op":"mcm","clk":"11936025743","pt":1724673429315,"mc":[{"id":"1.232298775","rc":[{"batb":[[0,1.77,4],[1,1.76,5],[2,1.75,20.83]],"ltp":1.76,"tv":44.9,"id":247649}]}]}
{"op":"mcm","clk":"11936025857","pt":1724673430503,"mc":[{"id":"1.232298775","rc":[{"batb":[[1,1.75,20.83],[2,1.69,55.71]],"ltp":1.76,"tv":44.9,"id":247649},{"batb":[[0,2.26,30.51],[1,1.2,125],[2,1.04,1614.05]],"ltp":2.34,"tv":28.69,"id":8858694}]}]}
{"op":"mcm","clk":"11936025955","pt":1724673431528,"mc":[{"id":"1.232298775","rc":[{"batb":[[0,1.75,20.83],[1,1.69,55.71],[2,1.2,125]],"ltp":1.76,"tv":44.9,"id":247649}]}]}
{"op":"mcm","clk":"11936026396","pt":1724673436834,"mc":[{"id":"1.232298775","rc":[{"batb":[[0,1.75,23.18]],"ltp":1.76,"tv":44.9,"id":247649}]}]}
{"op":"mcm","clk":"11936026404","pt":1724673436938,"mc":[{"id":"1.232298775","rc":[{"batb":[[0,1.76,9],[1,1.75,23.18],[2,1.69,55.71]],"ltp":1.76,"tv":44.9,"id":247649},{"batb":[[0,2.28,5],[1,2.26,30.51],[2,1.2,125]],"ltp":2.34,"tv":28.69,"id":8858694}]}]}
{"op":"mcm","clk":"11936026600","pt":1724673439327,"mc":[{"id":"1.232298775","rc":[{"batb":[[0,1.76,5]],"ltp":1.76,"tv":44.9,"id":247649}]}]}
{"op":"mcm","clk":"11936026686","pt":1724673440350,"mc":[{"id":"1.232298775","rc":[{"batb":[[0,1.75,23.18],[1,1.69,55.71],[2,1.2,125]],"ltp":1.76,"tv":44.9,"id":247649},{"batb":[[0,2.26,30.51],[1,1.2,125],[2,1.04,1614.05]],"ltp":2.34,"tv":28.69,"id":8858694}]}]}
{"op":"mcm","clk":"11936027048","pt":1724673444644,"mc":[{"id":"1.232298775","rc":[{"batb":[[0,1.76,5],[1,1.75,23.18],[2,1.69,55.71]],"batl":[[0,2.34,3.12],[1,3.4,35.25],[2,5.9,0.7]],"ltp":1.76,"tv":44.9,"id":247649},{"batb":[[0,2.28,5],[1,2.26,30.51],[2,1.2,125]],"ltp":2.34,"tv":28.69,"id":8858694}]}]}
{"op":"mcm","clk":"11936027200","pt":1724673446429,"mc":[{"id":"1.232298775","rc":[{"batb":[[2,1.2,125]],"ltp":1.76,"tv":44.9,"id":247649},{"batb":[[1,1.2,125],[2,1.04,1614.05]],"ltp":2.34,"tv":28.69,"id":8858694}]}]}
{"op":"mcm","clk":"11936027347","pt":1724673448024,"mc":[{"id":"1.232298775","rc":[{"batb":[[0,1.75,23.18],[1,1.2,125],[2,1.04,1614.05]],"ltp":1.76,"tv":44.9,"id":247649},{"batb":[[0,1.2,125],[1,1.04,1614.05],[2,1.03,2336.27]],"ltp":2.34,"tv":28.69,"id":8858694}]}]}
{"op":"mcm","clk":"11936027596","pt":1724673451439,"mc":[{"id":"1.232298775","rc":[{"batb":[[0,1.76,5],[1,1.75,23.18],[2,1.69,55.71]],"ltp":1.76,"tv":44.9,"id":247649},{"batb":[[0,2.26,30.51],[1,1.21,5],[2,1.2,125]],"ltp":2.34,"tv":28.69,"id":8858694}]}]}
{"op":"mcm","clk":"11936027836","pt":1724673454367,"mc":[{"id":"1.232298775","rc":[{"batb":[[0,1.75,23.18],[1,1.69,55.71],[2,1.2,125]],"ltp":1.76,"tv":44.9,"id":247649},{"batb":[[1,1.2,125],[2,1.04,1614.05]],"ltp":2.34,"tv":28.69,"id":8858694}]}]}
{"op":"mcm","clk":"11936028343","pt":1724673459258,"mc":[{"id":"1.232298775","rc":[{"batb":[[0,1.76,5],[1,1.75,23.18],[2,1.69,55.71]],"ltp":1.76,"tv":44.9,"id":247649},{"batb":[[0,2.28,5],[1,2.26,30.51],[2,1.2,125]],"ltp":2.34,"tv":28.69,"id":8858694}]}]}
{"op":"mcm","clk":"11936028502","pt":1724673461461,"mc":[{"id":"1.232298775","rc":[{"batb":[[2,1.2,125]],"ltp":1.76,"tv":44.9,"id":247649},{"batb":[[1,1.2,125],[2,1.04,1614.05]],"ltp":2.34,"tv":28.69,"id":8858694}]}]}
{"op":"mcm","clk":"11936028635","pt":1724673462651,"mc":[{"id":"1.232298775","rc":[{"batb":[[0,1.75,23.18],[1,1.2,125],[2,1.04,1614.05]],"ltp":1.76,"tv":44.9,"id":247649},{"batb":[[0,1.2,125],[1,1.04,1614.05],[2,1.03,2336.27]],"ltp":2.34,"tv":28.69,"id":8858694}]}]}
{"op":"mcm","clk":"11936028948","pt":1724673466652,"mc":[{"id":"1.232298775","rc":[{"batb":[[0,1.76,5],[1,1.75,23.18],[2,1.69,55.71]],"ltp":1.76,"tv":44.9,"id":247649},{"batb":[[0,2.28,5],[1,2.26,30.51],[2,1.2,125]],"ltp":2.34,"tv":28.69,"id":8858694}]}]}
{"op":"mcm","clk":"11936029192","pt":1724673469894,"mc":[{"id":"1.232298775","rc":[{"batb":[[0,1.75,23.18],[1,1.69,55.71],[2,1.2,125]],"ltp":1.76,"tv":44.9,"id":247649},{"batb":[[0,2.26,30.51],[1,1.2,125],[2,1.04,1614.05]],"ltp":2.34,"tv":28.69,"id":8858694}]}]}
{"op":"mcm","clk":"11936030109","pt":1724673481581,"mc":[{"id":"1.232298775","rc":[{"batb":[[0,1.76,5],[1,1.75,23.18]],"ltp":1.76,"tv":44.9,"id":247649},{"batb":[[0,2.28,5]],"ltp":2.34,"tv":28.69,"id":8858694}]}]}
{"op":"mcm","clk":"11936030372","pt":1724673484908,"mc":[{"id":"1.232298775","rc":[{"batb":[[0,1.75,23.18],[1,1.2,125],[2,1.04,1614.05]],"ltp":1.76,"tv":44.9,"id":247649},{"batb":[[0,1.2,125],[1,1.04,1614.05],[2,1.03,2336.27]],"ltp":2.34,"tv":28.69,"id":8858694}]}]}
{"op":"mcm","clk":"11936030546","pt":1724673486604,"mc":[{"id":"1.232298775","rc":[{"batb":[[1,1.69,55.71],[2,1.2,125]],"ltp":1.76,"tv":44.9,"id":247649},{"batb":[[0,2.26,30.51],[1,1.2,125],[2,1.04,1614.05]],"ltp":2.34,"tv":28.69,"id":8858694}]}]}
{"op":"mcm","clk":"11936031311","pt":1724673495815,"mc":[{"id":"1.232298775","rc":[{"batb":[[0,1.76,5],[1,1.75,23.18],[2,1.69,55.71]],"ltp":1.76,"tv":44.9,"id":247649},{"batb":[[0,2.28,5],[1,2.26,30.51],[2,1.2,125]],"ltp":2.34,"tv":28.69,"id":8858694}]}]}
{"op":"mcm","clk":"11936031373","pt":1724673496741,"mc":[{"id":"1.232298775","rc":[{"batb":[[2,1.2,125]],"ltp":1.76,"tv":44.9,"id":247649},{"batb":[[1,1.2,125],[2,1.04,1614.05]],"ltp":2.34,"tv":28.69,"id":8858694}]}]}
{"op":"mcm","clk":"11936031552","pt":1724673499202,"mc":[{"id":"1.232298775","rc":[{"batb":[[0,1.75,23.18],[1,1.2,125],[2,1.04,1614.05]],"ltp":1.76,"tv":44.9,"id":247649},{"batb":[[0,1.2,125],[1,1.04,1614.05],[2,1.03,2336.27]],"ltp":2.34,"tv":28.69,"id":8858694}]}]}
{"op":"mcm","clk":"11936031725","pt":1724673501718,"mc":[{"id":"1.232298775","rc":[{"batb":[[0,1.76,5],[1,1.75,23.18],[2,1.69,55.71]],"ltp":1.76,"tv":44.9,"id":247649},{"batb":[[0,2.28,5],[1,2.26,30.51],[2,1.2,125]],"ltp":2.34,"tv":28.69,"id":8858694}]}]}
{"op":"mcm","clk":"11936031942","pt":1724673505018,"mc":[{"id":"1.232298775","rc":[{"batb":[[0,1.75,23.18],[1,1.69,55.71],[2,1.2,125]],"ltp":1.76,"tv":44.9,"id":247649},{"batb":[[0,2.26,30.51],[1,1.2,125],[2,1.04,1614.05]],"ltp":2.34,"tv":28.69,"id":8858694}]}]}
{"op":"mcm","clk":"11936032467","pt":1724673511725,"mc":[{"id":"1.232298775","rc":[{"batb":[[0,1.76,5],[1,1.75,23.18],[2,1.69,55.71]],"batl":[[0,2.24,17.62],[1,2.34,3.12],[2,3.4,35.25]],"ltp":1.76,"tv":44.9,"id":247649},{"batb":[[0,2.28,5],[1,2.26,30.51],[2,1.2,125]],"ltp":2.34,"tv":28.69,"id":8858694}]}]}
{"op":"mcm","clk":"11936032707","pt":1724673515038,"mc":[{"id":"1.232298775","rc":[{"batb":[[0,1.75,23.18],[1,1.69,55.71],[2,1.2,125]],"ltp":1.76,"tv":44.9,"id":247649},{"batb":[[0,2.26,30.51],[1,1.2,125],[2,1.04,1614.05]],"ltp":2.34,"tv":28.69,"id":8858694}]}]}
{"op":"mcm","clk":"11936033093","pt":1724673519954,"mc":[{"id":"1.232298775","rc":[{"batb":[[0,1.76,5],[1,1.75,23.18],[2,1.69,55.71]],"ltp":1.76,"tv":44.9,"id":247649},{"batb":[[0,2.28,5],[1,2.26,30.51],[2,1.2,125]],"ltp":2.34,"tv":28.69,"id":8858694}]}]}
{"op":"mcm","clk":"11936033249","pt":1724673521761,"mc":[{"id":"1.232298775","rc":[{"batb":[[2,1.2,125]],"ltp":1.76,"tv":44.9,"id":247649},{"batb":[[1,1.2,125],[2,1.04,1614.05]],"ltp":2.34,"tv":28.69,"id":8858694}]}]}
{"op":"mcm","clk":"11936033394","pt":1724673523354,"mc":[{"id":"1.232298775","rc":[{"batb":[[0,1.75,23.18],[1,1.2,125],[2,1.04,1614.05]],"ltp":1.76,"tv":44.9,"id":247649},{"batb":[[0,1.2,125],[1,1.04,1614.05],[2,1.03,2336.27]],"ltp":2.34,"tv":28.69,"id":8858694}]}]}
{"op":"mcm","clk":"11936033678","pt":1724673526858,"mc":[{"id":"1.232298775","rc":[{"batb":[[0,1.76,5],[1,1.75,23.18],[2,1.69,55.71]],"ltp":1.76,"tv":44.9,"id":247649},{"batb":[[0,2.28,5],[1,2.26,30.51],[2,1.2,125]],"ltp":2.34,"tv":28.69,"id":8858694}]}]}
{"op":"mcm","clk":"11936033928","pt":1724673530070,"mc":[{"id":"1.232298775","rc":[{"batb":[[0,1.75,23.18],[1,1.69,55.71],[2,1.2,125]],"ltp":1.76,"tv":44.9,"id":247649},{"batb":[[0,2.26,30.51],[1,1.2,125],[2,1.04,1614.05]],"ltp":2.34,"tv":28.69,"id":8858694}]}]}
{"op":"mcm","clk":"11936034579","pt":1724673539276,"mc":[{"id":"1.232298775","rc":[{"batb":[[0,1.76,5],[1,1.75,23.18],[2,1.69,55.71]],"ltp":1.76,"tv":44.9,"id":247649},{"batb":[[0,2.28,5],[1,2.26,30.51],[2,1.2,125]],"ltp":2.34,"tv":28.69,"id":8858694}]}]}
{"op":"mcm","clk":"11936034775","pt":1724673541871,"mc":[{"id":"1.232298775","rc":[{"batb":[[2,1.2,125]],"ltp":1.76,"tv":44.9,"id":247649},{"batb":[[1,1.2,125],[2,1.04,1614.05]],"ltp":2.34,"tv":28.69,"id":8858694}]}]}
{"op":"mcm","clk":"11936034822","pt":1724673542694,"mc":[{"id":"1.232298775","rc":[{"batb":[[0,1.75,23.18],[1,1.2,125],[2,1.04,1614.05]],"ltp":1.76,"tv":44.9,"id":247649},{"batb":[[0,1.2,125],[1,1.04,1614.05],[2,1.03,2336.27]],"ltp":2.34,"tv":28.69,"id":8858694}]}]}
{"op":"mcm","clk":"11936034991","pt":1724673544985,"mc":[{"id":"1.232298775","rc":[{"batb":[[0,1.76,5],[1,1.75,23.18],[2,1.2,125]],"ltp":1.76,"tv":44.9,"id":247649},{"batb":[[0,1.21,5],[1,1.2,125],[2,1.04,1614.05]],"ltp":2.34,"tv":28.69,"id":8858694}]}]}
{"op":"mcm","clk":"11936035131","pt":1724673546782,"mc":[{"id":"1.232298775","rc":[{"batb":[[2,1.69,55.71]],"ltp":1.76,"tv":44.9,"id":247649},{"batb":[[0,2.26,30.51],[1,1.21,5],[2,1.2,125]],"ltp":2.34,"tv":28.69,"id":8858694}]}]}
{"op":"mcm","clk":"11936035255","pt":1724673548276,"mc":[{"id":"1.232298775","rc":[{"batb":[[0,1.75,23.18],[1,1.69,55.71],[2,1.2,125]],"ltp":1.76,"tv":44.9,"id":247649},{"batb":[[1,1.2,125],[2,1.04,1614.05]],"ltp":2.34,"tv":28.69,"id":8858694}]}]}
{"op":"mcm","clk":"11936036142","pt":1724673560102,"mc":[{"id":"1.232298775","rc":[{"batb":[[0,1.76,5],[1,1.75,23.18],[2,1.69,55.71]],"ltp":1.76,"tv":44.9,"id":247649},{"batb":[[0,2.28,5],[1,2.26,30.51],[2,1.2,125]],"ltp":2.34,"tv":28.69,"id":8858694}]}]}
{"op":"mcm","clk":"11936036325","pt":1724673562002,"mc":[{"id":"1.232298775","rc":[{"batb":[[2,1.2,125]],"ltp":1.76,"tv":44.9,"id":247649},{"batb":[[1,1.2,125],[2,1.04,1614.05]],"ltp":2.34,"tv":28.69,"id":8858694}]}]}
{"op":"mcm","clk":"11936036419","pt":1724673563492,"mc":[{"id":"1.232298775","rc":[{"batb":[[0,1.75,23.18],[1,1.2,125],[2,1.04,1614.05]],"ltp":1.76,"tv":44.9,"id":247649},{"batb":[[0,1.2,125],[1,1.04,1614.05],[2,1.03,2336.27]],"ltp":2.34,"tv":28.69,"id":8858694}]}]}
{"op":"mcm","clk":"11936036658","pt":1724673567034,"mc":[{"id":"1.232298775","rc":[{"batb":[[0,1.76,5],[1,1.75,23.18],[2,1.69,55.71]],"ltp":1.76,"tv":44.9,"id":247649},{"batb":[[0,2.28,5],[1,2.26,30.51],[2,1.2,125]],"ltp":2.34,"tv":28.69,"id":8858694}]}]}
{"op":"mcm","clk":"11936036936","pt":1724673570523,"mc":[{"id":"1.232298775","rc":[{"batb":[[0,1.75,23.18],[1,1.69,55.71],[2,1.2,125]],"ltp":1.76,"tv":44.9,"id":247649},{"batb":[[0,2.26,30.51],[1,1.2,125],[2,1.04,1614.05]],"ltp":2.34,"tv":28.69,"id":8858694}]}]}
{"op":"mcm","clk":"11936037744","pt":1724673581416,"mc":[{"id":"1.232298775","rc":[{"batb":[[0,1.76,5],[1,1.75,23.18],[2,1.69,55.71]],"ltp":1.76,"tv":44.9,"id":247649},{"batb":[[0,2.28,5],[1,2.26,30.51],[2,1.2,125]],"ltp":2.34,"tv":28.69,"id":8858694}]}]}
{"op":"mcm","clk":"11936037781","pt":1724673582032,"mc":[{"id":"1.232298775","rc":[{"batb":[[2,1.2,125]],"ltp":1.76,"tv":44.9,"id":247649},{"batb":[[1,1.2,125],[2,1.04,1614.05]],"ltp":2.34,"tv":28.69,"id":8858694}]}]}
{"op":"mcm","clk":"11936037945","pt":1724673584850,"mc":[{"id":"1.232298775","rc":[{"batb":[[0,1.75,23.18],[1,1.2,125],[2,1.04,1614.05]],"ltp":1.76,"tv":44.9,"id":247649},{"batb":[[0,1.2,125],[1,1.04,1614.05],[2,1.03,2336.27]],"ltp":2.34,"tv":28.69,"id":8858694}]}]}
{"op":"mcm","clk":"11936038119","pt":1724673587025,"mc":[{"id":"1.232298775","rc":[{"batb":[[0,1.76,5],[1,1.75,23.18],[2,1.69,55.71]],"ltp":1.76,"tv":44.9,"id":247649},{"batb":[[0,2.28,5],[1,2.26,30.51],[2,1.2,125]],"ltp":2.34,"tv":28.69,"id":8858694}]}]}
{"op":"mcm","clk":"11936038382","pt":1724673590258,"mc":[{"id":"1.232298775","rc":[{"batb":[[0,1.75,23.18],[1,1.69,55.71],[2,1.2,125]],"ltp":1.76,"tv":44.9,"id":247649},{"batb":[[0,2.26,30.51],[1,1.2,125],[2,1.04,1614.05]],"ltp":2.34,"tv":28.69,"id":8858694}]}]}
{"op":"mcm","clk":"11936040346","pt":1724673611278,"mc":[{"id":"1.232298775","rc":[{"batb":[[0,1.76,5],[1,1.75,23.18],[2,1.69,55.71]],"batl":[[0,2.24,17.64],[2,3.4,35.28]],"ltp":1.76,"tv":44.9,"id":247649},{"batb":[[0,2.28,5],[1,2.26,30.51],[2,1.2,125]],"ltp":2.34,"tv":28.69,"id":8858694}]}]}
{"op":"mcm","clk":"11936040424","pt":1724673612062,"mc":[{"id":"1.232298775","rc":[{"batb":[[2,1.2,125]],"ltp":1.76,"tv":44.9,"id":247649},{"batb":[[1,1.2,125],[2,1.04,1614.32]],"ltp":2.34,"tv":28.69,"id":8858694}]}]}
{"op":"mcm","clk":"11936040668","pt":1724673614688,"mc":[{"id":"1.232298775","rc":[{"batb":[[0,1.75,23.18],[1,1.2,125],[2,1.04,1614.32]],"ltp":1.76,"tv":44.9,"id":247649},{"batb":[[0,1.2,125],[1,1.04,1614.32],[2,1.03,2336.63]],"ltp":2.34,"tv":28.69,"id":8858694}]}]}
{"op":"mcm","clk":"11936040907","pt":1724673617186,"mc":[{"id":"1.232298775","rc":[{"batb":[[0,1.76,5],[1,1.75,23.18],[2,1.69,55.71]],"ltp":1.76,"tv":44.9,"id":247649},{"batb":[[0,2.28,5],[1,2.26,30.51],[2,1.2,125]],"ltp":2.34,"tv":28.69,"id":8858694}]}]}
{"op":"mcm","clk":"11936041196","pt":1724673620481,"mc":[{"id":"1.232298775","rc":[{"batb":[[0,1.75,23.18],[1,1.69,55.71],[2,1.2,125]],"ltp":1.76,"tv":44.9,"id":247649},{"batb":[[0,2.26,30.51],[1,1.2,125],[2,1.04,1614.32]],"ltp":2.34,"tv":28.69,"id":8858694}]}]}
{"op":"mcm","clk":"11936043045","pt":1724673642818,"mc":[{"id":"1.232298775","rc":[{"batb":[[0,1.76,5],[1,1.75,23.18],[2,1.69,55.71]],"ltp":1.76,"tv":44.9,"id":247649},{"batb":[[0,2.28,5],[1,2.26,30.51],[2,1.2,125]],"ltp":2.34,"tv":28.69,"id":8858694}]}]}
{"op":"mcm","clk":"11936043297","pt":1724673646105,"mc":[{"id":"1.232298775","rc":[{"batb":[[0,1.75,23.18],[1,1.69,55.71],[2,1.2,125]],"ltp":1.76,"tv":44.9,"id":247649},{"batb":[[0,2.26,30.51],[1,1.2,125],[2,1.04,1614.32]],"ltp":2.34,"tv":28.69,"id":8858694}]}]}
{"op":"mcm","clk":"11936057176","pt":1724673833962,"mc":[{"id":"1.232298775","rc":[{"batb":[[0,1.76,5],[1,1.75,23.18],[2,1.69,55.71]],"ltp":1.76,"tv":44.9,"id":247649},{"batb":[[0,2.28,5],[1,2.26,30.51],[2,1.2,125]],"ltp":2.34,"tv":28.69,"id":8858694}]}]}
{"op":"mcm","clk":"11936057413","pt":1724673837356,"mc":[{"id":"1.232298775","rc":[{"batb":[[0,1.75,23.18],[1,1.69,55.71],[2,1.2,125]],"ltp":1.76,"tv":44.9,"id":247649},{"batb":[[0,2.26,30.51],[1,1.2,125],[2,1.04,1614.32]],"ltp":2.34,"tv":28.69,"id":8858694}]}]}
{"op":"mcm","clk":"11936070617","pt":1724673998385,"mc":[{"id":"1.232298775","rc":[{"batb":[[0,1.76,5],[1,1.75,23.18],[2,1.69,55.71]],"ltp":1.76,"tv":44.9,"id":247649},{"batb":[[0,2.28,5],[1,2.26,30.51],[2,1.2,125]],"ltp":2.34,"tv":28.69,"id":8858694}]}]}
{"op":"mcm","clk":"11936070893","pt":1724674001786,"mc":[{"id":"1.232298775","rc":[{"batb":[[0,1.75,23.18],[1,1.69,55.71],[2,1.2,125]],"ltp":1.76,"tv":44.9,"id":247649},{"batb":[[0,2.26,30.51],[1,1.2,125],[2,1.04,1614.32]],"ltp":2.34,"tv":28.69,"id":8858694}]}]}
{"op":"mcm","clk":"11936072142","pt":1724674018810,"mc":[{"id":"1.232298775","rc":[{"batb":[[0,1.76,5],[1,1.75,23.18],[2,1.69,55.71]],"ltp":1.76,"tv":44.9,"id":247649},{"batb":[[0,2.28,5],[1,2.26,30.51],[2,1.2,125]],"ltp":2.34,"tv":28.69,"id":8858694}]}]}
{"op":"mcm","clk":"11936072391","pt":1724674022219,"mc":[{"id":"1.232298775","rc":[{"batb":[[0,1.75,23.18],[1,1.69,55.71],[2,1.2,125]],"ltp":1.76,"tv":44.9,"id":247649},{"batb":[[0,2.26,30.51],[1,1.2,125],[2,1.04,1614.32]],"ltp":2.34,"tv":28.69,"id":8858694}]}]}
{"op":"mcm","clk":"11936093949","pt":1724674305801,"mc":[{"id":"1.232298775","rc":[{"batb":[[0,1.76,5],[1,1.75,23.18],[2,1.69,55.71]],"ltp":1.76,"tv":44.9,"id":247649},{"batb":[[0,2.28,5],[1,2.26,30.51],[2,1.2,125]],"ltp":2.34,"tv":28.69,"id":8858694}]}]}
{"op":"mcm","clk":"11936094197","pt":1724674309216,"mc":[{"id":"1.232298775","rc":[{"batb":[[0,1.75,23.18],[1,1.69,55.71],[2,1.2,125]],"ltp":1.76,"tv":44.9,"id":247649},{"batb":[[0,2.26,30.51],[1,1.2,125],[2,1.04,1614.32]],"ltp":2.34,"tv":28.69,"id":8858694}]}]}
{"op":"mcm","clk":"11936094642","pt":1724674314628,"mc":[{"id":"1.232298775","rc":[{"batb":[[0,1.76,5],[1,1.75,23.18]],"ltp":1.76,"tv":44.9,"id":247649},{"batb":[[0,2.28,5]],"ltp":2.34,"tv":28.69,"id":8858694}]}]}
{"op":"mcm","clk":"11936094862","pt":1724674317309,"mc":[{"id":"1.232298775","rc":[{"batb":[[0,1.75,23.18],[1,1.2,125],[2,1.04,1614.32]],"ltp":1.76,"tv":44.9,"id":247649},{"batb":[[0,1.2,125],[1,1.04,1614.32],[2,1.03,2336.63]],"ltp":2.34,"tv":28.69,"id":8858694}]}]}
{"op":"mcm","clk":"11936095029","pt":1724674319625,"mc":[{"id":"1.232298775","rc":[{"batb":[[0,1.76,5],[1,1.75,23.18],[2,1.69,55.71]],"ltp":1.76,"tv":44.9,"id":247649},{"batb":[[0,2.28,5],[1,2.26,30.51],[2,1.2,125]],"ltp":2.34,"tv":28.69,"id":8858694}]}]}
{"op":"mcm","clk":"11936095296","pt":1724674323050,"mc":[{"id":"1.232298775","rc":[{"batb":[[0,1.75,23.18],[1,1.69,55.71],[2,1.2,125]],"ltp":1.76,"tv":44.9,"id":247649},{"batb":[[0,2.26,30.51],[1,1.2,125],[2,1.04,1614.32]],"ltp":2.34,"tv":28.69,"id":8858694}]}]}
{"op":"mcm","clk":"11936111923","pt":1724674395659,"mc":[{"id":"1.232298775","rc":[{"batb":[[0,1.76,5],[1,1.75,23.18],[2,1.69,55.71]],"ltp":1.76,"tv":44.9,"id":247649},{"batb":[[0,2.28,5],[1,2.26,30.51],[2,1.2,125]],"ltp":2.34,"tv":28.69,"id":8858694}]}]}
{"op":"mcm","clk":"11936112180","pt":1724674398956,"mc":[{"id":"1.232298775","rc":[{"batb":[[0,1.75,23.18],[1,1.69,55.71],[2,1.2,125]],"ltp":1.76,"tv":44.9,"id":247649},{"batb":[[0,2.26,30.51],[1,1.2,125],[2,1.04,1614.32]],"ltp":2.34,"tv":28.69,"id":8858694}]}]}
{"op":"mcm","clk":"11936120825","pt":1724674520298,"mc":[{"id":"1.232298775","rc":[{"batb":[[0,1.76,5],[1,1.75,23.18],[2,1.69,55.71]],"ltp":1.76,"tv":44.9,"id":247649},{"batb":[[0,2.28,5],[1,2.26,30.51],[2,1.2,125]],"ltp":2.34,"tv":28.69,"id":8858694}]}]}
{"op":"mcm","clk":"11936121051","pt":1724674523703,"mc":[{"id":"1.232298775","rc":[{"batb":[[0,1.75,23.18],[1,1.69,55.71],[2,1.2,125]],"ltp":1.76,"tv":44.9,"id":247649},{"batb":[[0,2.26,30.51],[1,1.2,125],[2,1.04,1614.32]],"ltp":2.34,"tv":28.69,"id":8858694}]}]}
{"op":"mcm","clk":"11936121380","pt":1724674528302,"mc":[{"id":"1.232298775","rc":[{"batb":[[0,1.76,5],[1,1.75,23.18],[2,1.69,55.71]],"ltp":1.76,"tv":44.9,"id":247649},{"batb":[[0,2.28,5],[1,2.26,30.51],[2,1.2,125]],"ltp":2.34,"tv":28.69,"id":8858694}]}]}
{"op":"mcm","clk":"11936121515","pt":1724674530406,"mc":[{"id":"1.232298775","rc":[{"batb":[[2,1.2,125]],"ltp":1.76,"tv":44.9,"id":247649},{"batb":[[1,1.2,125],[2,1.04,1614.32]],"ltp":2.34,"tv":28.69,"id":8858694}]}]}
{"op":"mcm","clk":"11936121608","pt":1724674531691,"mc":[{"id":"1.232298775","rc":[{"batb":[[0,1.75,23.18],[1,1.2,125],[2,1.04,1614.32]],"ltp":1.76,"tv":44.9,"id":247649},{"batb":[[0,1.2,125],[1,1.04,1614.32],[2,1.03,2336.63]],"ltp":2.34,"tv":28.69,"id":8858694}]}]}
{"op":"mcm","clk":"11936121858","pt":1724674535398,"mc":[{"id":"1.232298775","rc":[{"batb":[[0,1.76,5],[1,1.75,23.18],[2,1.69,55.71]],"ltp":1.76,"tv":44.9,"id":247649},{"batb":[[0,2.28,5],[1,2.26,30.51],[2,1.2,125]],"ltp":2.34,"tv":28.69,"id":8858694}]}]}
{"op":"mcm","clk":"11936122068","pt":1724674538592,"mc":[{"id":"1.232298775","rc":[{"batb":[[0,1.75,23.18],[1,1.69,55.71],[2,1.2,125]],"ltp":1.76,"tv":44.9,"id":247649},{"batb":[[0,2.26,30.51],[1,1.2,125],[2,1.04,1614.32]],"ltp":2.34,"tv":28.69,"id":8858694}]}]}
{"op":"mcm","clk":"11936124414","pt":1724674570793,"mc":[{"id":"1.232298775","rc":[{"batb":[[0,1.76,5],[1,1.75,23.18],[2,1.69,55.71]],"ltp":1.76,"tv":44.9,"id":247649},{"batb":[[0,2.28,5],[1,2.26,30.51],[2,1.2,125]],"ltp":2.34,"tv":28.69,"id":8858694}]}]}
{"op":"mcm","clk":"11936124660","pt":1724674574153,"mc":[{"id":"1.232298775","rc":[{"batb":[[0,1.75,23.18],[1,1.69,55.71],[2,1.2,125]],"ltp":1.76,"tv":44.9,"id":247649},{"batb":[[0,2.26,30.51],[1,1.2,125],[2,1.04,1614.32]],"ltp":2.34,"tv":28.69,"id":8858694}]}]}
{"op":"mcm","clk":"11936124987","pt":1724674578680,"mc":[{"id":"1.232298775","rc":[{"batb":[[0,1.76,5],[1,1.75,23.18],[2,1.69,55.71]],"ltp":1.76,"tv":44.9,"id":247649},{"batb":[[0,2.28,5],[1,2.26,30.51],[2,1.2,125]],"ltp":2.34,"tv":28.69,"id":8858694}]}]}
{"op":"mcm","clk":"11936125111","pt":1724674580479,"mc":[{"id":"1.232298775","rc":[{"batb":[[2,1.2,125]],"ltp":1.76,"tv":44.9,"id":247649},{"batb":[[1,1.2,125],[2,1.04,1614.32]],"ltp":2.34,"tv":28.69,"id":8858694}]}]}
{"op":"mcm","clk":"11936125218","pt":1724674582069,"mc":[{"id":"1.232298775","rc":[{"batb":[[0,1.75,23.18],[1,1.2,125],[2,1.04,1614.32]],"ltp":1.76,"tv":44.9,"id":247649},{"batb":[[0,1.2,125],[1,1.04,1614.32],[2,1.03,2336.63]],"ltp":2.34,"tv":28.69,"id":8858694}]}]}
{"op":"mcm","clk":"11936125443","pt":1724674585573,"mc":[{"id":"1.232298775","rc":[{"batb":[[0,1.76,5],[1,1.75,23.18],[2,1.69,55.71]],"ltp":1.76,"tv":44.9,"id":247649},{"batb":[[0,2.28,5],[1,2.26,30.51],[2,1.2,125]],"ltp":2.34,"tv":28.69,"id":8858694}]}]}
{"op":"mcm","clk":"11936125648","pt":1724674588977,"mc":[{"id":"1.232298775","rc":[{"batb":[[0,1.75,23.18],[1,1.69,55.71],[2,1.2,125]],"ltp":1.76,"tv":44.9,"id":247649},{"batb":[[0,2.26,30.51],[1,1.2,125],[2,1.04,1614.32]],"ltp":2.34,"tv":28.69,"id":8858694}]}]}
{"op":"mcm","clk":"11936132606","pt":1724674688941,"mc":[{"id":"1.232298775","rc":[{"batb":[[0,1.76,5],[1,1.75,23.18],[2,1.69,55.71]],"ltp":1.76,"tv":44.9,"id":247649},{"batb":[[0,2.28,5],[1,2.26,30.51],[2,1.2,125]],"ltp":2.34,"tv":28.69,"id":8858694}]}]}
{"op":"mcm","clk":"11936132753","pt":1724674690845,"mc":[{"id":"1.232298775","rc":[{"batb":[[2,1.2,125]],"ltp":1.76,"tv":44.9,"id":247649},{"batb":[[1,1.2,125],[2,1.04,1614.32]],"ltp":2.34,"tv":28.69,"id":8858694}]}]}
{"op":"mcm","clk":"11936132871","pt":1724674692143,"mc":[{"id":"1.232298775","rc":[{"batb":[[0,1.75,23.18],[1,1.2,125],[2,1.04,1614.32]],"ltp":1.76,"tv":44.9,"id":247649},{"batb":[[0,1.2,125],[1,1.04,1614.32],[2,1.03,2336.63]],"ltp":2.34,"tv":28.69,"id":8858694}]}]}
{"op":"mcm","clk":"11936133141","pt":1724674695856,"mc":[{"id":"1.232298775","rc":[{"batb":[[1,1.69,55.71],[2,1.2,125]],"ltp":1.76,"tv":44.9,"id":247649},{"batb":[[0,2.26,30.51],[1,1.2,125],[2,1.04,1614.32]],"ltp":2.34,"tv":28.69,"id":8858694}]}]}
{"op":"mcm","clk":"11936133144","pt":1724674695955,"mc":[{"id":"1.232298775","rc":[{"batb":[[0,1.76,5],[1,1.75,23.18],[2,1.69,55.71]],"ltp":1.76,"tv":44.9,"id":247649},{"batb":[[0,2.28,5],[1,2.26,30.51],[2,1.2,125]],"ltp":2.34,"tv":28.69,"id":8858694}]}]}
{"op":"mcm","clk":"11936133371","pt":1724674699261,"mc":[{"id":"1.232298775","rc":[{"batb":[[0,1.75,23.18],[1,1.69,55.71],[2,1.2,125]],"ltp":1.76,"tv":44.9,"id":247649},{"batb":[[0,2.26,30.51],[1,1.2,125],[2,1.04,1614.32]],"ltp":2.34,"tv":28.69,"id":8858694}]}]}
{"op":"mcm","clk":"11936136227","pt":1724674737773,"mc":[{"id":"1.232298775","rc":[{"batb":[[0,1.76,5],[1,1.75,23.18],[2,1.69,55.71]],"ltp":1.76,"tv":44.9,"id":247649},{"batb":[[0,2.28,5],[1,2.26,30.51],[2,1.2,125]],"ltp":2.34,"tv":28.69,"id":8858694}]}]}
{"op":"mcm","clk":"11936136472","pt":1724674741034,"mc":[{"id":"1.232298775","rc":[{"batb":[[0,1.75,23.18],[1,1.2,125],[2,1.04,1614.32]],"ltp":1.76,"tv":44.9,"id":247649},{"batb":[[0,1.2,125],[1,1.04,1614.32],[2,1.03,2336.63]],"ltp":2.34,"tv":28.69,"id":8858694}]}]}
{"op":"mcm","clk":"11936136840","pt":1724674746103,"mc":[{"id":"1.232298775","rc":[{"batb":[[0,1.76,5],[1,1.75,23.18],[2,1.69,55.71]],"ltp":1.76,"tv":44.9,"id":247649},{"batb":[[0,2.28,5],[1,2.26,30.51],[2,1.2,125]],"ltp":2.34,"tv":28.69,"id":8858694}]}]}
{"op":"mcm","clk":"11936137118","pt":1724674749613,"mc":[{"id":"1.232298775","rc":[{"batb":[[0,1.75,23.18],[1,1.69,55.71],[2,1.2,125]],"ltp":1.76,"tv":44.9,"id":247649},{"batb":[[0,2.26,30.51],[1,1.2,125],[2,1.04,1614.32]],"ltp":2.34,"tv":28.69,"id":8858694}]}]}
{"op":"mcm","clk":"11936139552","pt":1724674781218,"mc":[{"id":"1.232298775","rc":[{"batb":[[0,1.76,5],[1,1.75,23.18],[2,1.69,55.71]],"ltp":1.76,"tv":44.9,"id":247649},{"batb":[[0,2.28,5],[1,2.26,30.51],[2,1.2,125]],"ltp":2.34,"tv":28.69,"id":8858694}]}]}
{"op":"mcm","clk":"11936139819","pt":1724674784642,"mc":[{"id":"1.232298775","rc":[{"batb":[[0,1.75,23.18],[1,1.69,55.71],[2,1.2,125]],"ltp":1.76,"tv":44.9,"id":247649},{"batb":[[0,2.26,30.51],[1,1.2,125],[2,1.04,1614.32]],"ltp":2.34,"tv":28.69,"id":8858694}]}]}
{"op":"mcm","clk":"11936141804","pt":1724674809991,"mc":[{"id":"1.232298775","rc":[{"batb":[[0,1.76,5],[1,1.75,23.18],[2,1.69,55.71]],"ltp":1.76,"tv":44.9,"id":247649},{"batb":[[0,2.28,5],[1,2.26,30.51],[2,1.2,125]],"ltp":2.34,"tv":28.69,"id":8858694}]}]}
{"op":"mcm","clk":"11936141932","pt":1724674811388,"mc":[{"id":"1.232298775","rc":[{"batb":[[2,1.2,125]],"ltp":1.76,"tv":44.9,"id":247649},{"batb":[[1,1.2,125],[2,1.04,1614.32]],"ltp":2.34,"tv":28.69,"id":8858694}]}]}
{"op":"mcm","clk":"11936142072","pt":1724674813400,"mc":[{"id":"1.232298775","rc":[{"batb":[[0,1.75,23.18],[1,1.2,125],[2,1.04,1614.32]],"ltp":1.76,"tv":44.9,"id":247649},{"batb":[[0,1.2,125],[1,1.04,1614.32],[2,1.03,2336.63]],"ltp":2.34,"tv":28.69,"id":8858694}]}]}
{"op":"mcm","clk":"11936142289","pt":1724674816392,"mc":[{"id":"1.232298775","rc":[{"batb":[[0,1.76,5],[1,1.75,23.18],[2,1.69,55.71]],"ltp":1.76,"tv":44.9,"id":247649},{"batb":[[0,2.28,5],[1,2.26,30.51],[2,1.2,125]],"ltp":2.34,"tv":28.69,"id":8858694}]}]}
{"op":"mcm","clk":"11936142587","pt":1724674819804,"mc":[{"id":"1.232298775","rc":[{"batb":[[0,1.75,23.18],[1,1.69,55.71],[2,1.2,125]],"ltp":1.76,"tv":44.9,"id":247649},{"batb":[[0,2.26,30.51],[1,1.2,125],[2,1.04,1614.32]],"ltp":2.34,"tv":28.69,"id":8858694}]}]}
{"op":"mcm","clk":"11936142984","pt":1724674825170,"mc":[{"id":"1.232298775","rc":[{"batb":[[0,1.76,5],[1,1.75,23.18],[2,1.69,55.71]],"ltp":1.76,"tv":44.9,"id":247649},{"batb":[[0,2.28,5],[1,2.26,30.51],[2,1.2,125]],"ltp":2.34,"tv":28.69,"id":8858694}]}]}
{"op":"mcm","clk":"11936143064","pt":1724674826408,"mc":[{"id":"1.232298775","rc":[{"batb":[[2,1.2,125]],"ltp":1.76,"tv":44.9,"id":247649},{"batb":[[1,1.2,125],[2,1.04,1614.32]],"ltp":2.34,"tv":28.69,"id":8858694}]}]}
{"op":"mcm","clk":"11936143207","pt":1724674828682,"mc":[{"id":"1.232298775","rc":[{"batb":[[0,1.75,23.18],[1,1.2,125],[2,1.04,1614.32]],"ltp":1.76,"tv":44.9,"id":247649},{"batb":[[0,1.2,125],[1,1.04,1614.32],[2,1.03,2336.63]],"ltp":2.34,"tv":28.69,"id":8858694}]}]}
{"op":"mcm","clk":"11936143362","pt":1724674831406,"mc":[{"id":"1.232298775","rc":[{"batb":[[0,1.76,5],[1,1.75,23.18],[2,1.69,55.71]],"ltp":1.76,"tv":44.9,"id":247649},{"batb":[[0,2.28,5],[1,2.26,30.51],[2,1.2,125]],"ltp":2.34,"tv":28.69,"id":8858694}]}]}
{"op":"mcm","clk":"11936143570","pt":1724674834601,"mc":[{"id":"1.232298775","rc":[{"batb":[[0,1.75,23.18],[1,1.69,55.71],[2,1.2,125]],"ltp":1.76,"tv":44.9,"id":247649},{"batb":[[0,2.26,30.51],[1,1.2,125],[2,1.04,1614.32]],"ltp":2.34,"tv":28.69,"id":8858694}]}]}
{"op":"mcm","clk":"11936144146","pt":1724674842026,"mc":[{"id":"1.232298775","rc":[{"batb":[[0,1.76,5],[1,1.75,23.18],[2,1.69,55.71]],"ltp":1.76,"tv":44.9,"id":247649},{"batb":[[0,2.28,5],[1,2.26,30.51],[2,1.2,125]],"ltp":2.34,"tv":28.69,"id":8858694}]}]}
{"op":"mcm","clk":"11936144412","pt":1724674845430,"mc":[{"id":"1.232298775","rc":[{"batb":[[0,1.75,23.18],[1,1.69,55.71],[2,1.2,125]],"ltp":1.76,"tv":44.9,"id":247649},{"batb":[[0,2.26,30.51],[1,1.2,125],[2,1.04,1614.32]],"ltp":2.34,"tv":28.69,"id":8858694}]}]}
{"op":"mcm","clk":"11936145796","pt":1724674863734,"mc":[{"id":"1.232298775","rc":[{"batb":[[0,1.76,5],[1,1.75,23.18],[2,1.69,55.71]],"ltp":1.76,"tv":44.9,"id":247649},{"batb":[[0,2.28,5],[1,2.26,30.51],[2,1.2,125]],"ltp":2.34,"tv":28.69,"id":8858694}]}]}
{"op":"mcm","clk":"11936145976","pt":1724674866558,"mc":[{"id":"1.232298775","rc":[{"batb":[[2,1.2,125]],"ltp":1.76,"tv":44.9,"id":247649},{"batb":[[1,1.2,125],[2,1.04,1614.32]],"ltp":2.34,"tv":28.69,"id":8858694}]}]}
{"op":"mcm","clk":"11936146017","pt":1724674867025,"mc":[{"id":"1.232298775","rc":[{"batb":[[0,1.75,23.18],[1,1.2,125],[2,1.04,1614.32]],"ltp":1.76,"tv":44.9,"id":247649},{"batb":[[0,1.2,125],[1,1.04,1614.32],[2,1.03,2336.63]],"ltp":2.34,"tv":28.69,"id":8858694}]}]}
{"op":"mcm","clk":"11936146376","pt":1724674871544,"mc":[{"id":"1.232298775","rc":[{"batb":[[0,1.76,5],[1,1.75,23.18],[2,1.69,55.71]],"ltp":1.76,"tv":44.9,"id":247649},{"batb":[[0,2.28,5],[1,2.26,30.51],[2,1.2,125]],"ltp":2.34,"tv":28.69,"id":8858694}]}]}
{"op":"mcm","clk":"11936146614","pt":1724674874775,"mc":[{"id":"1.232298775","rc":[{"batb":[[0,1.75,23.18],[1,1.69,55.71],[2,1.2,125]],"ltp":1.76,"tv":44.9,"id":247649},{"batb":[[0,2.26,30.51],[1,1.2,125],[2,1.04,1614.32]],"ltp":2.34,"tv":28.69,"id":8858694}]}]}
{"op":"mcm","clk":"11936156208","pt":1724674999790,"mc":[{"id":"1.232298775","rc":[{"batb":[[0,1.76,5],[1,1.75,23.18],[2,1.69,55.71]],"ltp":1.76,"tv":44.9,"id":247649},{"batb":[[0,2.28,5],[1,2.26,30.51],[2,1.2,125]],"ltp":2.34,"tv":28.69,"id":8858694}]}]}
{"op":"mcm","clk":"11936156415","pt":1724675002100,"mc":[{"id":"1.232298775","rc":[{"batb":[[2,1.2,125]],"ltp":1.76,"tv":44.9,"id":247649},{"batb":[[1,1.2,125],[2,1.04,1614.32]],"ltp":2.34,"tv":28.69,"id":8858694}]}]}
{"op":"mcm","clk":"11936156486","pt":1724675003189,"mc":[{"id":"1.232298775","rc":[{"batb":[[0,1.75,23.18],[1,1.2,125],[2,1.04,1614.32]],"ltp":1.76,"tv":44.9,"id":247649},{"batb":[[0,1.2,125],[1,1.04,1614.32],[2,1.03,2336.63]],"ltp":2.34,"tv":28.69,"id":8858694}]}]}
{"op":"mcm","clk":"11936156834","pt":1724675007099,"mc":[{"id":"1.232298775","rc":[{"batb":[[0,1.76,5],[1,1.75,23.18],[2,1.69,55.71]],"ltp":1.76,"tv":44.9,"id":247649},{"batb":[[0,2.28,5],[1,2.26,30.51],[2,1.2,125]],"ltp":2.34,"tv":28.69,"id":8858694}]}]}
{"op":"mcm","clk":"11936157159","pt":1724675010397,"mc":[{"id":"1.232298775","rc":[{"batb":[[0,1.75,23.18],[1,1.69,55.71],[2,1.2,125]],"ltp":1.76,"tv":44.9,"id":247649},{"batb":[[0,2.26,30.51],[1,1.2,125],[2,1.04,1614.32]],"ltp":2.34,"tv":28.69,"id":8858694}]}]}
{"op":"mcm","clk":"11936158307","pt":1724675024990,"mc":[{"id":"1.232298775","rc":[{"batb":[[0,1.76,5],[1,1.75,23.18],[2,1.69,55.71]],"ltp":1.76,"tv":44.9,"id":247649},{"batb":[[0,2.28,5],[1,2.26,30.51],[2,1.2,125]],"ltp":2.34,"tv":28.69,"id":8858694}]}]}
{"op":"mcm","clk":"11936158430","pt":1724675027097,"mc":[{"id":"1.232298775","rc":[{"batb":[[2,1.2,125]],"ltp":1.76,"tv":44.9,"id":247649},{"batb":[[1,1.2,125],[2,1.04,1614.32]],"ltp":2.34,"tv":28.69,"id":8858694}]}]}
{"op":"mcm","clk":"11936158522","pt":1724675028329,"mc":[{"id":"1.232298775","rc":[{"batb":[[0,1.75,23.18],[1,1.2,125],[2,1.04,1614.32]],"ltp":1.76,"tv":44.9,"id":247649},{"batb":[[0,1.2,125],[1,1.04,1614.32],[2,1.03,2336.63]],"ltp":2.34,"tv":28.69,"id":8858694}]}]}
{"op":"mcm","clk":"11936158792","pt":1724675032120,"mc":[{"id":"1.232298775","rc":[{"batb":[[0,1.76,5],[1,1.75,23.18],[2,1.69,55.71]],"ltp":1.76,"tv":44.9,"id":247649},{"batb":[[0,2.28,5],[1,2.26,30.51],[2,1.2,125]],"ltp":2.34,"tv":28.69,"id":8858694}]}]}
{"op":"mcm","clk":"11936159037","pt":1724675035415,"mc":[{"id":"1.232298775","rc":[{"batb":[[0,1.75,23.18],[1,1.69,55.71],[2,1.2,125]],"ltp":1.76,"tv":44.9,"id":247649},{"batb":[[0,2.26,30.51],[1,1.2,125],[2,1.04,1614.32]],"ltp":2.34,"tv":28.69,"id":8858694}]}]}
{"op":"mcm","clk":"11936163000","pt":1724675083992,"mc":[{"id":"1.232298775","rc":[{"batb":[[0,1.76,5],[1,1.75,23.18],[2,1.69,55.71]],"ltp":1.76,"tv":44.9,"id":247649},{"batb":[[0,2.28,5],[1,2.26,30.51],[2,1.2,125]],"ltp":2.34,"tv":28.69,"id":8858694}]}]}
{"op":"mcm","clk":"11936163263","pt":1724675087297,"mc":[{"id":"1.232298775","rc":[{"batb":[[0,1.75,23.18],[1,1.2,125],[2,1.04,1614.32]],"ltp":1.76,"tv":44.9,"id":247649},{"batb":[[0,1.2,125],[1,1.04,1614.32],[2,1.03,2336.63]],"ltp":2.34,"tv":28.69,"id":8858694}]}]}
{"op":"mcm","clk":"11936163710","pt":1724675092399,"mc":[{"id":"1.232298775","rc":[{"batb":[[0,1.76,5],[1,1.75,23.18],[2,1.69,55.71]],"ltp":1.76,"tv":44.9,"id":247649},{"batb":[[0,2.28,5],[1,2.26,30.51],[2,1.2,125]],"ltp":2.34,"tv":28.69,"id":8858694}]}]}
{"op":"mcm","clk":"11936163998","pt":1724675095906,"mc":[{"id":"1.232298775","rc":[{"batb":[[0,1.75,23.18],[1,1.69,55.71],[2,1.2,125]],"ltp":1.76,"tv":44.9,"id":247649},{"batb":[[0,2.26,30.51],[1,1.2,125],[2,1.04,1614.32]],"ltp":2.34,"tv":28.69,"id":8858694}]}]}
{"op":"mcm","clk":"11936165390","pt":1724675111715,"mc":[{"id":"1.232298775","rc":[{"batb":[[0,1.76,5],[1,1.75,23.18],[2,1.69,55.71]],"ltp":1.76,"tv":44.9,"id":247649},{"batb":[[0,2.28,5],[1,2.26,30.51],[2,1.2,125]],"ltp":2.34,"tv":28.69,"id":8858694}]}]}
{"op":"mcm","clk":"11936165442","pt":1724675112442,"mc":[{"id":"1.232298775","rc":[{"batb":[[2,1.2,125]],"ltp":1.76,"tv":44.9,"id":247649},{"batb":[[1,1.2,125],[2,1.04,1614.32]],"ltp":2.34,"tv":28.69,"id":8858694}]}]}
{"op":"mcm","clk":"11936165660","pt":1724675115019,"mc":[{"id":"1.232298775","rc":[{"batb":[[0,1.75,23.18],[1,1.2,125],[2,1.04,1614.32]],"ltp":1.76,"tv":44.9,"id":247649},{"batb":[[0,1.2,125],[1,1.04,1614.32],[2,1.03,2336.63]],"ltp":2.34,"tv":28.69,"id":8858694}]}]}
{"op":"mcm","clk":"11936165878","pt":1724675117538,"mc":[{"id":"1.232298775","rc":[{"batb":[[0,1.76,5],[1,1.75,23.18],[2,1.69,55.71]],"ltp":1.76,"tv":44.9,"id":247649},{"batb":[[0,2.28,5],[1,2.26,30.51],[2,1.2,125]],"ltp":2.34,"tv":28.69,"id":8858694}]}]}
{"op":"mcm","clk":"11936166157","pt":1724675120838,"mc":[{"id":"1.232298775","rc":[{"batb":[[0,1.75,23.18],[1,1.69,55.71],[2,1.2,125]],"ltp":1.76,"tv":44.9,"id":247649},{"batb":[[0,2.26,30.51],[1,1.2,125],[2,1.04,1614.32]],"ltp":2.34,"tv":28.69,"id":8858694}]}]}
{"op":"mcm","clk":"11936166729","pt":1724675127537,"mc":[{"id":"1.232298775","rc":[{"batb":[[0,1.76,5],[1,1.75,23.18]],"ltp":1.76,"tv":44.9,"id":247649},{"trd":[[2.26,1.02]],"batb":[[0,2.28,5]],"ltp":2.26,"tv":29.71,"id":8858694}],"tv":74.61}]}
{"op":"mcm","clk":"11936166975","pt":1724675130629,"mc":[{"id":"1.232298775","rc":[{"batb":[[0,1.75,23.18],[1,1.2,125],[2,1.04,1614.32]],"ltp":1.76,"tv":44.9,"id":247649},{"batb":[[0,1.2,125],[1,1.04,1614.32],[2,1.03,2336.63]],"ltp":2.26,"tv":29.71,"id":8858694}]}]}
{"op":"mcm","clk":"11936167132","pt":1724675132433,"mc":[{"id":"1.232298775","rc":[{"batb":[[1,1.69,55.71],[2,1.2,125]],"ltp":1.76,"tv":44.9,"id":247649},{"batb":[[0,2.26,30.51],[1,1.2,125],[2,1.04,1614.32]],"ltp":2.26,"tv":29.71,"id":8858694}]}]}
{"op":"mcm","clk":"11936171632","pt":1724675188594,"mc":[{"id":"1.232298775","rc":[{"batb":[[0,1.76,5],[1,1.75,23.18],[2,1.69,55.71]],"ltp":1.76,"tv":44.9,"id":247649},{"batb":[[0,2.28,5],[1,2.26,30.51],[2,1.2,125]],"ltp":2.26,"tv":29.71,"id":8858694}]}]}
{"op":"mcm","clk":"11936171883","pt":1724675192032,"mc":[{"id":"1.232298775","rc":[{"batb":[[0,1.75,23.18],[1,1.69,55.71],[2,1.2,125]],"ltp":1.76,"tv":44.9,"id":247649},{"batb":[[0,2.26,30.51],[1,1.2,125],[2,1.04,1614.32]],"ltp":2.26,"tv":29.71,"id":8858694}]}]}
{"op":"mcm","clk":"11936172558","pt":1724675201714,"mc":[{"id":"1.232298775","rc":[{"batb":[[0,1.76,5],[1,1.75,23.18],[2,1.69,55.71]],"ltp":1.76,"tv":44.9,"id":247649},{"batb":[[0,2.28,5],[1,2.26,30.51],[2,1.2,125]],"ltp":2.26,"tv":29.71,"id":8858694}]}]}
{"op":"mcm","clk":"11936172611","pt":1724675202743,"mc":[{"id":"1.232298775","rc":[{"batb":[[2,1.2,125]],"ltp":1.76,"tv":44.9,"id":247649},{"batb":[[1,1.2,125],[2,1.04,1614.32]],"ltp":2.26,"tv":29.71,"id":8858694}]}]}
{"op":"mcm","clk":"11936172794","pt":1724675205011,"mc":[{"id":"1.232298775","rc":[{"batb":[[0,1.75,23.18],[1,1.2,125],[2,1.04,1614.32]],"ltp":1.76,"tv":44.9,"id":247649},{"batb":[[0,1.2,125],[1,1.04,1614.32],[2,1.03,2336.63]],"ltp":2.26,"tv":29.71,"id":8858694}]}]}
{"op":"mcm","clk":"11936172985","pt":1724675207833,"mc":[{"id":"1.232298775","rc":[{"batb":[[0,1.76,5],[1,1.75,23.18],[2,1.69,55.71]],"ltp":1.76,"tv":44.9,"id":247649},{"batb":[[0,2.28,5],[1,2.26,30.51],[2,1.2,125]],"ltp":2.26,"tv":29.71,"id":8858694}]}]}
{"op":"mcm","clk":"11936173206","pt":1724675211124,"mc":[{"id":"1.232298775","rc":[{"batb":[[0,1.75,23.18],[1,1.69,55.71],[2,1.2,125]],"ltp":1.76,"tv":44.9,"id":247649},{"batb":[[0,2.26,30.51],[1,1.2,125],[2,1.04,1614.32]],"ltp":2.26,"tv":29.71,"id":8858694}]}]}
{"op":"mcm","clk":"11936176508","pt":1724675257690,"mc":[{"id":"1.232298775","rc":[{"batb":[[0,1.76,5],[1,1.75,23.18],[2,1.69,55.71]],"ltp":1.76,"tv":44.9,"id":247649},{"batb":[[0,2.28,5],[1,2.26,30.51],[2,1.2,125]],"ltp":2.26,"tv":29.71,"id":8858694}]}]}
{"op":"mcm","clk":"11936176528","pt":1724675257897,"mc":[{"id":"1.232298775","rc":[{"batb":[[2,1.2,125]],"ltp":1.76,"tv":44.9,"id":247649},{"batb":[[1,1.2,125],[2,1.04,1614.32]],"ltp":2.26,"tv":29.71,"id":8858694}]}]}
{"op":"mcm","clk":"11936176771","pt":1724675260889,"mc":[{"id":"1.232298775","rc":[{"batb":[[0,1.75,23.18],[1,1.2,125],[2,1.04,1614.32]],"ltp":1.76,"tv":44.9,"id":247649},{"batb":[[0,1.2,125],[1,1.04,1614.32],[2,1.03,2336.63]],"ltp":2.26,"tv":29.71,"id":8858694}]}]}
{"op":"mcm","clk":"11936176953","pt":1724675262907,"mc":[{"id":"1.232298775","rc":[{"batb":[[1,1.69,55.71],[2,1.2,125]],"ltp":1.76,"tv":44.9,"id":247649},{"batb":[[0,2.26,30.51],[1,1.2,125],[2,1.04,1614.32]],"ltp":2.26,"tv":29.71,"id":8858694}]}]}
{"op":"mcm","clk":"11936187157","pt":1724675392267,"mc":[{"id":"1.232298775","rc":[{"batb":[[0,1.76,5],[1,1.75,23.18],[2,1.69,55.71]],"ltp":1.76,"tv":44.9,"id":247649},{"batb":[[0,2.28,5],[1,2.26,30.51],[2,1.2,125]],"ltp":2.26,"tv":29.71,"id":8858694}]}]}
{"op":"mcm","clk":"11936187240","pt":1724675393369,"mc":[{"id":"1.232298775","rc":[{"batb":[[2,1.2,125]],"ltp":1.76,"tv":44.9,"id":247649},{"batb":[[1,1.2,125],[2,1.04,1614.32]],"ltp":2.26,"tv":29.71,"id":8858694}]}]}
{"op":"mcm","clk":"11936187421","pt":1724675395793,"mc":[{"id":"1.232298775","rc":[{"batb":[[0,1.75,23.18],[1,1.2,125],[2,1.04,1614.32]],"ltp":1.76,"tv":44.9,"id":247649},{"batb":[[0,1.2,125],[1,1.04,1614.32],[2,1.03,2336.63]],"ltp":2.26,"tv":29.71,"id":8858694}]}]}
{"op":"mcm","clk":"11936187636","pt":1724675398483,"mc":[{"id":"1.232298775","rc":[{"batb":[[0,1.76,5],[1,1.75,23.18],[2,1.69,55.71]],"ltp":1.76,"tv":44.9,"id":247649},{"batb":[[0,2.28,5],[1,2.26,30.51],[2,1.2,125]],"ltp":2.26,"tv":29.71,"id":8858694}]}]}
{"op":"mcm","clk":"11936187935","pt":1724675401780,"mc":[{"id":"1.232298775","rc":[{"batb":[[0,1.75,23.18],[1,1.69,55.71],[2,1.2,125]],"ltp":1.76,"tv":44.9,"id":247649},{"batb":[[0,2.26,30.51],[1,1.2,125],[2,1.04,1614.32]],"ltp":2.26,"tv":29.71,"id":8858694}]}]}
{"op":"mcm","clk":"11936189591","pt":1724675422603,"mc":[{"id":"1.232298775","rc":[{"batb":[[0,1.76,5],[1,1.75,23.18],[2,1.69,55.71]],"ltp":1.76,"tv":44.9,"id":247649},{"batb":[[0,2.28,5],[1,2.26,30.51],[2,1.2,125]],"ltp":2.26,"tv":29.71,"id":8858694}]}]}
{"op":"mcm","clk":"11936189652","pt":1724675423531,"mc":[{"id":"1.232298775","rc":[{"batb":[[2,1.2,125]],"ltp":1.76,"tv":44.9,"id":247649},{"batb":[[1,1.2,125],[2,1.04,1614.32]],"ltp":2.26,"tv":29.71,"id":8858694}]}]}
{"op":"mcm","clk":"11936189818","pt":1724675426052,"mc":[{"id":"1.232298775","rc":[{"batb":[[0,1.75,23.18],[1,1.2,125],[2,1.05,5.19]],"ltp":1.76,"tv":44.9,"id":247649},{"batb":[[0,1.2,125],[1,1.04,1614.32],[2,1.03,2336.63]],"ltp":2.26,"tv":29.71,"id":8858694}]}]}
{"op":"mcm","clk":"11936189980","pt":1724675428536,"mc":[{"id":"1.232298775","rc":[{"batb":[[0,1.76,5],[1,1.75,23.18],[2,1.69,55.71]],"ltp":1.76,"tv":44.9,"id":247649},{"batb":[[0,2.28,5],[1,2.26,30.51],[2,1.2,125]],"ltp":2.26,"tv":29.71,"id":8858694}]}]}
{"op":"mcm","clk":"11936190220","pt":1724675431830,"mc":[{"id":"1.232298775","rc":[{"batb":[[0,1.75,23.18],[1,1.69,55.71],[2,1.2,125]],"ltp":1.76,"tv":44.9,"id":247649},{"batb":[[0,2.26,30.51],[1,1.2,125],[2,1.04,1614.32]],"ltp":2.26,"tv":29.71,"id":8858694}]}]}
{"op":"mcm","clk":"11936192485","pt":1724675464377,"mc":[{"id":"1.232298775","rc":[{"batb":[[0,1.76,5],[1,1.75,23.18],[2,1.69,55.71]],"ltp":1.76,"tv":44.9,"id":247649},{"batb":[[0,2.28,5],[1,2.26,30.51],[2,1.2,125]],"ltp":2.26,"tv":29.71,"id":8858694}]}]}
{"op":"mcm","clk":"11936192701","pt":1724675467570,"mc":[{"id":"1.232298775","rc":[{"batb":[[0,1.75,23.18],[1,1.69,55.71],[2,1.2,125]],"ltp":1.76,"tv":44.9,"id":247649},{"batb":[[0,2.26,30.51],[1,1.2,125],[2,1.04,1614.32]],"ltp":2.26,"tv":29.71,"id":8858694}]}]}
{"op":"mcm","clk":"11936194243","pt":1724675488805,"mc":[{"id":"1.232298775","rc":[{"batb":[[0,1.76,5],[1,1.75,23.18]],"ltp":1.76,"tv":44.9,"id":247649},{"batb":[[0,2.28,5]],"ltp":2.26,"tv":29.71,"id":8858694}]}]}
{"op":"mcm","clk":"11936194427","pt":1724675491419,"mc":[{"id":"1.232298775","rc":[{"batb":[[0,1.75,23.18],[1,1.2,125],[2,1.05,5.19]],"ltp":1.76,"tv":44.9,"id":247649},{"batb":[[0,1.2,125],[1,1.04,1614.32],[2,1.03,2336.63]],"ltp":2.26,"tv":29.71,"id":8858694}]}]}
{"op":"mcm","clk":"11936194613","pt":1724675493839,"mc":[{"id":"1.232298775","rc":[{"batb":[[1,1.69,55.71],[2,1.2,125]],"ltp":1.76,"tv":44.9,"id":247649},{"batb":[[0,2.26,30.51],[1,1.2,125],[2,1.04,1614.32]],"ltp":2.26,"tv":29.71,"id":8858694}]}]}
{"op":"mcm","clk":"11936194623","pt":1724675493942,"mc":[{"id":"1.232298775","rc":[{"batb":[[0,1.76,5],[1,1.75,23.18],[2,1.69,55.71]],"ltp":1.76,"tv":44.9,"id":247649},{"batb":[[0,2.28,5],[1,2.26,30.51],[2,1.2,125]],"ltp":2.26,"tv":29.71,"id":8858694}]}]}
{"op":"mcm","clk":"11936194869","pt":1724675497236,"mc":[{"id":"1.232298775","rc":[{"batb":[[0,1.75,23.18],[1,1.69,55.71],[2,1.2,125]],"ltp":1.76,"tv":44.9,"id":247649},{"batb":[[0,2.26,30.51],[1,1.2,125],[2,1.04,1614.32]],"ltp":2.26,"tv":29.71,"id":8858694}]}]}
{"op":"mcm","clk":"11936195803","pt":1724675510827,"mc":[{"id":"1.232298775","rc":[{"batb":[[0,1.76,5],[1,1.75,23.18],[2,1.69,55.71]],"ltp":1.76,"tv":44.9,"id":247649},{"batb":[[0,2.28,5],[1,2.26,30.51],[2,1.2,125]],"ltp":2.26,"tv":29.71,"id":8858694}]}]}
{"op":"mcm","clk":"11936195987","pt":1724675514167,"mc":[{"id":"1.232298775","rc":[{"batb":[[0,1.75,23.18],[1,1.2,125],[2,1.05,5.19]],"ltp":1.76,"tv":44.9,"id":247649},{"batb":[[0,1.2,125],[1,1.04,1614.32],[2,1.03,2336.63]],"ltp":2.26,"tv":29.71,"id":8858694}]}]}
{"op":"mcm","clk":"11936196298","pt":1724675518851,"mc":[{"id":"1.232298775","rc":[{"batb":[[1,1.69,55.71],[2,1.2,125]],"ltp":1.76,"tv":44.9,"id":247649},{"batb":[[0,2.26,30.51],[1,1.2,125],[2,1.04,1614.32]],"ltp":2.26,"tv":29.71,"id":8858694}]}]}
{"op":"mcm","clk":"11936196308","pt":1724675518954,"mc":[{"id":"1.232298775","rc":[{"batb":[[0,1.76,5],[1,1.75,23.18],[2,1.69,55.71]],"ltp":1.76,"tv":44.9,"id":247649},{"batb":[[0,2.28,5],[1,2.26,30.51],[2,1.2,125]],"ltp":2.26,"tv":29.71,"id":8858694}]}]}
{"op":"mcm","clk":"11936196545","pt":1724675522261,"mc":[{"id":"1.232298775","rc":[{"batb":[[0,1.75,23.18],[1,1.69,55.71],[2,1.2,125]],"ltp":1.76,"tv":44.9,"id":247649},{"batb":[[0,2.26,30.51],[1,1.2,125],[2,1.04,1614.32]],"ltp":2.26,"tv":29.71,"id":8858694}]}]}
{"op":"mcm","clk":"11936199688","pt":1724675565900,"mc":[{"id":"1.232298775","rc":[{"batb":[[0,1.76,5],[1,1.75,23.18],[2,1.69,55.71]],"ltp":1.76,"tv":44.9,"id":247649},{"batb":[[0,2.28,5],[1,2.26,30.51],[2,1.2,125]],"ltp":2.26,"tv":29.71,"id":8858694}]}]}
{"op":"mcm","clk":"11936199930","pt":1724675569412,"mc":[{"id":"1.232298775","rc":[{"batb":[[0,1.75,23.18],[1,1.2,125],[2,1.05,5.19]],"ltp":1.76,"tv":44.9,"id":247649},{"batb":[[0,1.2,125],[1,1.04,1614.32],[2,1.03,2336.63]],"ltp":2.26,"tv":29.71,"id":8858694}]}]}
{"op":"mcm","clk":"11936200266","pt":1724675574114,"mc":[{"id":"1.232298775","rc":[{"batb":[[0,1.76,5],[1,1.75,23.18],[2,1.69,55.71]],"ltp":1.76,"tv":44.9,"id":247649},{"batb":[[0,2.28,5],[1,2.26,30.51],[2,1.2,125]],"ltp":2.26,"tv":29.71,"id":8858694}]}]}
{"op":"mcm","clk":"11936200469","pt":1724675577316,"mc":[{"id":"1.232298775","rc":[{"batb":[[0,1.75,23.18],[1,1.69,55.71],[2,1.2,125]],"ltp":1.76,"tv":44.9,"id":247649},{"batb":[[0,2.26,30.51],[1,1.2,125],[2,1.04,1614.32]],"ltp":2.26,"tv":29.71,"id":8858694}]}]}
{"op":"mcm","clk":"11936200771","pt":1724675581713,"mc":[{"id":"1.232298775","rc":[{"batb":[[0,1.76,5],[1,1.75,23.18],[2,1.69,55.71]],"ltp":1.76,"tv":44.9,"id":247649},{"batb":[[0,2.28,5],[1,2.26,30.51],[2,1.2,125]],"ltp":2.26,"tv":29.71,"id":8858694}]}]}
{"op":"mcm","clk":"11936200970","pt":1724675584249,"mc":[{"id":"1.232298775","rc":[{"batb":[[2,1.2,125]],"ltp":1.76,"tv":44.9,"id":247649},{"batb":[[1,1.2,125],[2,1.04,1614.32]],"ltp":2.26,"tv":29.71,"id":8858694}]}]}
{"op":"mcm","clk":"11936201051","pt":1724675585124,"mc":[{"id":"1.232298775","rc":[{"batb":[[0,1.75,23.18],[1,1.2,125],[2,1.05,5.19]],"ltp":1.76,"tv":44.9,"id":247649},{"batb":[[0,1.2,125],[1,1.04,1614.32],[2,1.03,2336.63]],"ltp":2.26,"tv":29.71,"id":8858694}]}]}
{"op":"mcm","clk":"11936201348","pt":1724675589238,"mc":[{"id":"1.232298775","rc":[{"batb":[[0,1.76,5],[1,1.75,23.18],[2,1.69,55.71]],"ltp":1.76,"tv":44.9,"id":247649},{"batb":[[0,2.28,5],[1,2.26,30.51],[2,1.2,125]],"ltp":2.26,"tv":29.71,"id":8858694}]}]}
{"op":"mcm","clk":"11936201579","pt":1724675592629,"mc":[{"id":"1.232298775","rc":[{"batb":[[0,1.75,23.18],[1,1.69,55.71],[2,1.2,125]],"ltp":1.76,"tv":44.9,"id":247649},{"batb":[[0,2.26,30.51],[1,1.2,125],[2,1.04,1614.32]],"ltp":2.26,"tv":29.71,"id":8858694}]}]}
{"op":"mcm","clk":"11936202129","pt":1724675600139,"mc":[{"id":"1.232298775","rc":[{"batb":[[0,1.76,5],[1,1.75,23.18],[2,1.69,55.71]],"ltp":1.76,"tv":44.9,"id":247649},{"batb":[[0,2.28,5],[1,2.26,30.51],[2,1.2,125]],"ltp":2.26,"tv":29.71,"id":8858694}]}]}
{"op":"mcm","clk":"11936202369","pt":1724675603429,"mc":[{"id":"1.232298775","rc":[{"batb":[[0,1.75,23.18],[1,1.69,55.71],[2,1.2,125]],"ltp":1.76,"tv":44.9,"id":247649},{"batb":[[0,2.26,30.51],[1,1.2,125],[2,1.04,1614.32]],"ltp":2.26,"tv":29.71,"id":8858694}]}]}
{"op":"mcm","clk":"11936202759","pt":1724675608327,"mc":[{"id":"1.232298775","rc":[{"batb":[[0,1.76,5],[1,1.75,23.18],[2,1.69,55.71]],"ltp":1.76,"tv":44.9,"id":247649},{"batb":[[0,2.28,5],[1,2.26,30.51],[2,1.2,125]],"ltp":2.26,"tv":29.71,"id":8858694}]}]}
{"op":"mcm","clk":"11936202824","pt":1724675609253,"mc":[{"id":"1.232298775","rc":[{"batb":[[2,1.2,125]],"ltp":1.76,"tv":44.9,"id":247649},{"batb":[[1,1.2,125],[2,1.04,1614.32]],"ltp":2.26,"tv":29.71,"id":8858694}]}]}
{"op":"mcm","clk":"11936203054","pt":1724675611738,"mc":[{"id":"1.232298775","rc":[{"batb":[[0,1.75,23.18],[1,1.2,125],[2,1.05,5.19]],"ltp":1.76,"tv":44.9,"id":247649},{"batb":[[0,1.2,125],[1,1.04,1614.32],[2,1.03,2336.63]],"ltp":2.26,"tv":29.71,"id":8858694}]}]}
{"op":"mcm","clk":"11936203250","pt":1724675614336,"mc":[{"id":"1.232298775","rc":[{"batb":[[0,1.76,5],[1,1.75,23.18],[2,1.69,55.71]],"ltp":1.76,"tv":44.9,"id":247649},{"batb":[[0,2.28,5],[1,2.26,30.51],[2,1.2,125]],"ltp":2.26,"tv":29.71,"id":8858694}]}]}
{"op":"mcm","clk":"11936203527","pt":1724675617581,"mc":[{"id":"1.232298775","rc":[{"batb":[[0,1.75,23.18],[1,1.69,55.71],[2,1.2,125]],"ltp":1.76,"tv":44.9,"id":247649},{"batb":[[0,2.26,30.51],[1,1.2,125],[2,1.04,1614.32]],"ltp":2.26,"tv":29.71,"id":8858694}]}]}
{"op":"mcm","clk":"11936203765","pt":1724675620360,"mc":[{"id":"1.232298775","rc":[{"batb":[[0,1.76,5],[1,1.75,23.18],[2,1.69,55.71]],"ltp":1.76,"tv":44.9,"id":247649},{"batb":[[0,2.28,5],[1,2.26,30.51],[2,1.2,125]],"ltp":2.26,"tv":29.71,"id":8858694}]}]}
{"op":"mcm","clk":"11936204037","pt":1724675623745,"mc":[{"id":"1.232298775","rc":[{"batb":[[0,1.75,23.18],[1,1.69,55.71],[2,1.2,125]],"ltp":1.76,"tv":44.9,"id":247649},{"batb":[[0,2.26,30.51],[1,1.2,125],[2,1.04,1614.32]],"ltp":2.26,"tv":29.71,"id":8858694}]}]}
{"op":"mcm","clk":"11936206456","pt":1724675654985,"mc":[{"id":"1.232298775","rc":[{"batb":[[0,1.76,5],[1,1.75,23.18],[2,1.69,55.71]],"ltp":1.76,"tv":44.9,"id":247649},{"batb":[[0,2.28,5],[1,2.26,30.51],[2,1.2,125]],"ltp":2.26,"tv":29.71,"id":8858694}]}]}
{"op":"mcm","clk":"11936206691","pt":1724675658174,"mc":[{"id":"1.232298775","rc":[{"batb":[[0,1.75,23.18],[1,1.69,55.71],[2,1.2,125]],"ltp":1.76,"tv":44.9,"id":247649},{"batb":[[0,2.26,30.51],[1,1.2,125],[2,1.04,1614.32]],"ltp":2.26,"tv":29.71,"id":8858694}]}]}
{"op":"mcm","clk":"11936207000","pt":1724675663019,"mc":[{"id":"1.232298775","rc":[{"batb":[[0,1.76,5],[1,1.75,23.18],[2,1.69,55.71]],"ltp":1.76,"tv":44.9,"id":247649},{"batb":[[0,2.28,5],[1,2.26,30.51],[2,1.2,125]],"ltp":2.26,"tv":29.71,"id":8858694}]}]}
{"op":"mcm","clk":"11936207100","pt":1724675664409,"mc":[{"id":"1.232298775","rc":[{"batb":[[2,1.2,125]],"ltp":1.76,"tv":44.9,"id":247649},{"batb":[[1,1.2,125],[2,1.04,1614.32]],"ltp":2.26,"tv":29.71,"id":8858694}]}]}
{"op":"mcm","clk":"11936207247","pt":1724675666203,"mc":[{"id":"1.232298775","rc":[{"batb":[[0,1.75,23.18],[1,1.2,125],[2,1.05,5.19]],"ltp":1.76,"tv":44.9,"id":247649},{"batb":[[0,1.2,125],[1,1.04,1614.32],[2,1.03,2336.63]],"ltp":2.26,"tv":29.71,"id":8858694}]}]}
{"op":"mcm","clk":"11936207480","pt":1724675669497,"mc":[{"id":"1.232298775","rc":[{"batb":[[0,1.76,5],[1,1.75,23.18],[2,1.69,55.71]],"ltp":1.76,"tv":44.9,"id":247649},{"batb":[[0,2.28,5],[1,2.26,30.51],[2,1.2,125]],"ltp":2.26,"tv":29.71,"id":8858694}]}]}
{"op":"mcm","clk":"11936207753","pt":1724675672888,"mc":[{"id":"1.232298775","rc":[{"batb":[[0,1.75,23.18],[1,1.69,55.71],[2,1.2,125]],"ltp":1.76,"tv":44.9,"id":247649},{"batb":[[0,2.26,30.51],[1,1.2,125],[2,1.04,1614.32]],"ltp":2.26,"tv":29.71,"id":8858694}]}]}
{"op":"mcm","clk":"11936210444","pt":1724675705543,"mc":[{"id":"1.232298775","rc":[{"batb":[[0,1.76,5],[1,1.75,23.18],[2,1.69,55.71]],"ltp":1.76,"tv":44.9,"id":247649},{"batb":[[0,2.28,5],[1,2.26,30.51],[2,1.2,125]],"ltp":2.26,"tv":29.71,"id":8858694}]}]}
{"op":"mcm","clk":"11936210726","pt":1724675708736,"mc":[{"id":"1.232298775","rc":[{"batb":[[0,1.75,23.18],[1,1.69,55.71],[2,1.2,125]],"ltp":1.76,"tv":44.9,"id":247649},{"batb":[[0,2.26,30.51],[1,1.2,125],[2,1.04,1614.32]],"ltp":2.26,"tv":29.71,"id":8858694}]}]}
{"op":"mcm","clk":"11936210947","pt":1724675711050,"mc":[{"id":"1.232298775","rc":[{"batb":[[0,1.76,5],[1,1.75,23.18],[2,1.69,55.71]],"ltp":1.76,"tv":44.9,"id":247649},{"batb":[[0,2.28,5],[1,2.26,30.51],[2,1.2,125]],"ltp":2.26,"tv":29.71,"id":8858694}]}]}
{"op":"mcm","clk":"11936211236","pt":1724675714349,"mc":[{"id":"1.232298775","rc":[{"batb":[[0,1.75,23.18],[1,1.69,55.71],[2,1.2,125]],"ltp":1.76,"tv":44.9,"id":247649},{"batb":[[0,2.26,30.51],[1,1.2,125],[2,1.04,1614.32]],"ltp":2.26,"tv":29.71,"id":8858694}]}]}
{"op":"mcm","clk":"11936213773","pt":1724675744667,"mc":[{"id":"1.232298775","rc":[{"batb":[[0,1.76,5],[1,1.75,23.18]],"ltp":1.76,"tv":44.9,"id":247649},{"batb":[[0,2.28,5]],"ltp":2.26,"tv":29.71,"id":8858694}]}]}
{"op":"mcm","clk":"11936213998","pt":1724675747542,"mc":[{"id":"1.232298775","rc":[{"batb":[[0,1.75,23.18],[1,1.2,125],[2,1.05,5.19]],"ltp":1.76,"tv":44.9,"id":247649},{"batb":[[0,1.2,125],[1,1.04,1614.32],[2,1.03,2336.63]],"ltp":2.26,"tv":29.71,"id":8858694}]}]}
{"op":"mcm","clk":"11936214155","pt":1724675749754,"mc":[{"id":"1.232298775","rc":[{"batb":[[0,1.76,5],[1,1.75,23.18],[2,1.69,55.71]],"ltp":1.76,"tv":44.9,"id":247649},{"batb":[[0,2.28,5],[1,2.26,30.51],[2,1.2,125]],"ltp":2.26,"tv":29.71,"id":8858694}]}]}
{"op":"mcm","clk":"11936214399","pt":1724675753148,"mc":[{"id":"1.232298775","rc":[{"batb":[[0,1.75,23.18],[1,1.69,55.71],[2,1.2,125]],"ltp":1.76,"tv":44.9,"id":247649},{"batb":[[0,2.26,30.51],[1,1.2,125],[2,1.04,1614.32]],"ltp":2.26,"tv":29.71,"id":8858694}]}]}
{"op":"mcm","clk":"11936215123","pt":1724675761992,"mc":[{"id":"1.232298775","rc":[{"batb":[[0,1.76,5],[1,1.75,23.18],[2,1.69,55.71]],"ltp":1.76,"tv":44.9,"id":247649},{"batb":[[0,2.28,5],[1,2.26,30.51],[2,1.2,125]],"ltp":2.26,"tv":29.71,"id":8858694}]}]}
{"op":"mcm","clk":"11936215338","pt":1724675764783,"mc":[{"id":"1.232298775","rc":[{"batb":[[2,1.2,125]],"ltp":1.76,"tv":44.9,"id":247649},{"batb":[[1,1.2,125],[2,1.04,1614.32]],"ltp":2.26,"tv":29.71,"id":8858694}]}]}
{"op":"mcm","clk":"11936215371","pt":1724675765297,"mc":[{"id":"1.232298775","rc":[{"batb":[[0,1.75,23.18],[1,1.2,125],[2,1.05,5.19]],"ltp":1.76,"tv":44.9,"id":247649},{"batb":[[0,1.2,125],[1,1.04,1614.32],[2,1.03,2336.63]],"ltp":2.26,"tv":29.71,"id":8858694}]}]}
{"op":"mcm","clk":"11936215681","pt":1724675769785,"mc":[{"id":"1.232298775","rc":[{"batb":[[1,1.69,55.71],[2,1.2,125]],"ltp":1.76,"tv":44.9,"id":247649},{"batb":[[0,2.26,30.51],[1,1.2,125],[2,1.04,1614.32]],"ltp":2.26,"tv":29.71,"id":8858694}]}]}
{"op":"mcm","clk":"11936215688","pt":1724675769884,"mc":[{"id":"1.232298775","rc":[{"batb":[[0,1.76,5],[1,1.75,23.18],[2,1.69,55.71]],"ltp":1.76,"tv":44.9,"id":247649},{"batb":[[0,2.28,5],[1,2.26,30.51],[2,1.2,125]],"ltp":2.26,"tv":29.71,"id":8858694}]}]}
{"op":"mcm","clk":"11936215978","pt":1724675773295,"mc":[{"id":"1.232298775","rc":[{"batb":[[0,1.75,23.18],[1,1.69,55.71],[2,1.2,125]],"ltp":1.76,"tv":44.9,"id":247649},{"batb":[[0,2.26,30.51],[1,1.2,125],[2,1.04,1614.32]],"ltp":2.26,"tv":29.71,"id":8858694}]}]}
{"op":"mcm","clk":"11936217392","pt":1724675788729,"mc":[{"id":"1.232298775","rc":[{"batb":[[0,1.76,5],[1,1.75,23.18],[2,1.69,55.71]],"ltp":1.76,"tv":44.9,"id":247649},{"batb":[[0,2.28,5],[1,2.26,30.51],[2,1.2,125]],"ltp":2.26,"tv":29.71,"id":8858694}]}]}
{"op":"mcm","clk":"11936217491","pt":1724675789816,"mc":[{"id":"1.232298775","rc":[{"batb":[[2,1.2,125]],"ltp":1.76,"tv":44.9,"id":247649},{"batb":[[1,1.2,125],[2,1.04,1614.32]],"ltp":2.26,"tv":29.71,"id":8858694}]}]}
{"op":"mcm","clk":"11936217706","pt":1724675792106,"mc":[{"id":"1.232298775","rc":[{"batb":[[0,1.75,23.18],[1,1.2,125],[2,1.05,5.19]],"ltp":1.76,"tv":44.9,"id":247649},{"batb":[[0,1.2,125],[1,1.04,1614.32],[2,1.03,2336.63]],"ltp":2.26,"tv":29.71,"id":8858694}]}]}
{"op":"mcm","clk":"11936217931","pt":1724675794840,"mc":[{"id":"1.232298775","rc":[{"batb":[[1,1.69,55.71],[2,1.2,125]],"ltp":1.76,"tv":44.9,"id":247649},{"batb":[[0,2.26,30.51],[1,1.2,125],[2,1.04,1614.32]],"ltp":2.26,"tv":29.71,"id":8858694}]}]}
{"op":"mcm","clk":"11936217940","pt":1724675794895,"mc":[{"id":"1.232298775","rc":[{"batb":[[0,1.76,5],[1,1.75,23.18],[2,1.69,55.71]],"ltp":1.76,"tv":44.9,"id":247649},{"batb":[[0,2.28,5],[1,2.26,30.51],[2,1.2,125]],"ltp":2.26,"tv":29.71,"id":8858694}]}]}
{"op":"mcm","clk":"11936218199","pt":1724675798307,"mc":[{"id":"1.232298775","rc":[{"batb":[[0,1.75,23.18],[1,1.69,55.71],[2,1.2,125]],"ltp":1.76,"tv":44.9,"id":247649},{"batb":[[0,2.26,30.51],[1,1.2,125],[2,1.04,1614.32]],"ltp":2.26,"tv":29.71,"id":8858694}]}]}
{"op":"mcm","clk":"11936220562","pt":1724675828533,"mc":[{"id":"1.232298775","rc":[{"batb":[[0,1.76,5],[1,1.75,23.18],[2,1.69,55.71]],"ltp":1.76,"tv":44.9,"id":247649},{"batb":[[0,2.28,5],[1,2.26,30.51],[2,1.2,125]],"ltp":2.26,"tv":29.71,"id":8858694}]}]}
{"op":"mcm","clk":"11936220672","pt":1724675829929,"mc":[{"id":"1.232298775","rc":[{"batb":[[2,1.2,125]],"ltp":1.76,"tv":44.9,"id":247649},{"batb":[[1,1.2,125],[2,1.04,1614.32]],"ltp":2.26,"tv":29.71,"id":8858694}]}]}
{"op":"mcm","clk":"11936220863","pt":1724675831916,"mc":[{"id":"1.232298775","rc":[{"batb":[[0,1.75,23.18],[1,1.2,125],[2,1.05,5.19]],"ltp":1.76,"tv":44.9,"id":247649},{"batb":[[0,1.2,125],[1,1.04,1614.32],[2,1.03,2336.63]],"ltp":2.26,"tv":29.71,"id":8858694}]}]}
{"op":"mcm","clk":"11936221092","pt":1724675835133,"mc":[{"id":"1.232298775","rc":[{"batb":[[0,1.76,5],[1,1.75,23.18],[2,1.69,55.71]],"ltp":1.76,"tv":44.9,"id":247649},{"batb":[[0,2.28,5],[1,2.26,30.51],[2,1.2,125]],"ltp":2.26,"tv":29.71,"id":8858694}]}]}
{"op":"mcm","clk":"11936221372","pt":1724675838576,"mc":[{"id":"1.232298775","rc":[{"batb":[[0,1.75,23.18],[1,1.69,55.71],[2,1.2,125]],"ltp":1.76,"tv":44.9,"id":247649},{"batb":[[0,2.26,30.51],[1,1.2,125],[2,1.04,1614.32]],"ltp":2.26,"tv":29.71,"id":8858694}]}]}
{"op":"mcm","clk":"11936224001","pt":1724675873022,"mc":[{"id":"1.232298775","rc":[{"batb":[[0,1.76,5],[1,1.75,23.18],[2,1.69,55.71]],"ltp":1.76,"tv":44.9,"id":247649},{"batb":[[0,2.28,5],[1,2.26,30.51],[2,1.2,125]],"ltp":2.26,"tv":29.71,"id":8858694}]}]}
{"op":"mcm","clk":"11936224136","pt":1724675875235,"mc":[{"id":"1.232298775","rc":[{"batb":[[2,1.2,125]],"ltp":1.76,"tv":44.9,"id":247649},{"batb":[[1,1.2,125],[2,1.04,1614.32]],"ltp":2.26,"tv":29.71,"id":8858694}]}]}
{"op":"mcm","clk":"11936224220","pt":1724675876416,"mc":[{"id":"1.232298775","rc":[{"batb":[[0,1.75,23.18],[1,1.2,125],[2,1.05,5.19]],"ltp":1.76,"tv":44.9,"id":247649},{"batb":[[0,1.2,125],[1,1.04,1614.32],[2,1.03,2336.63]],"ltp":2.26,"tv":29.71,"id":8858694}]}]}
{"op":"mcm","clk":"11936224527","pt":1724675880222,"mc":[{"id":"1.232298775","rc":[{"batb":[[0,1.76,5],[1,1.75,23.18],[2,1.69,55.71]],"ltp":1.76,"tv":44.9,"id":247649},{"batb":[[0,2.28,5],[1,2.26,30.51],[2,1.2,125]],"ltp":2.26,"tv":29.71,"id":8858694}]}]}
{"op":"mcm","clk":"11936224775","pt":1724675883518,"mc":[{"id":"1.232298775","rc":[{"batb":[[0,1.75,23.18],[1,1.69,55.71],[2,1.2,125]],"ltp":1.76,"tv":44.9,"id":247649},{"batb":[[0,2.26,30.51],[1,1.2,125],[2,1.04,1614.32]],"ltp":2.26,"tv":29.71,"id":8858694}]}]}
{"op":"mcm","clk":"11936228890","pt":1724675933291,"mc":[{"id":"1.232298775","rc":[{"batb":[[0,1.76,5],[1,1.75,23.18],[2,1.69,55.71]],"ltp":1.76,"tv":44.9,"id":247649},{"batb":[[0,2.28,5],[1,2.26,30.51],[2,1.2,125]],"ltp":2.26,"tv":29.71,"id":8858694}]}]}
{"op":"mcm","clk":"11936229046","pt":1724675935400,"mc":[{"id":"1.232298775","rc":[{"batb":[[2,1.2,125]],"ltp":1.76,"tv":44.9,"id":247649},{"batb":[[1,1.2,125],[2,1.04,1614.32]],"ltp":2.26,"tv":29.71,"id":8858694}]}]}
{"op":"mcm","clk":"11936229161","pt":1724675936586,"mc":[{"id":"1.232298775","rc":[{"batb":[[0,1.75,23.18],[1,1.2,125],[2,1.05,5.19]],"ltp":1.76,"tv":44.9,"id":247649},{"batb":[[0,1.2,125],[1,1.04,1614.32],[2,1.03,2336.63]],"ltp":2.26,"tv":29.71,"id":8858694}]}]}
{"op":"mcm","clk":"11936229490","pt":1724675940392,"mc":[{"id":"1.232298775","rc":[{"batb":[[0,1.76,5],[1,1.75,23.18],[2,1.69,55.71]],"ltp":1.76,"tv":44.9,"id":247649},{"batb":[[0,2.26,30.51],[1,1.21,5],[2,1.2,125]],"ltp":2.26,"tv":29.71,"id":8858694}]}]}
{"op":"mcm","clk":"11936229784","pt":1724675943486,"mc":[{"id":"1.232298775","rc":[{"batb":[[0,1.75,23.18],[1,1.69,55.71],[2,1.2,125]],"ltp":1.76,"tv":44.9,"id":247649},{"batb":[[1,1.2,125],[2,1.04,1614.32]],"ltp":2.26,"tv":29.71,"id":8858694}]}]}
{"op":"mcm","clk":"11936230954","pt":1724675956984,"mc":[{"id":"1.232298775","rc":[{"batb":[[0,1.76,5],[1,1.75,23.18],[2,1.69,55.71]],"ltp":1.76,"tv":44.9,"id":247649},{"batb":[[0,2.28,5],[1,2.26,30.51],[2,1.2,125]],"ltp":2.26,"tv":29.71,"id":8858694}]}]}
{"op":"mcm","clk":"11936231221","pt":1724675960484,"mc":[{"id":"1.232298775","rc":[{"batb":[[0,1.75,23.18],[1,1.2,125],[2,1.05,5.19]],"ltp":1.76,"tv":44.9,"id":247649},{"batb":[[0,1.2,125],[1,1.04,1614.32],[2,1.03,2336.63]],"ltp":2.26,"tv":29.71,"id":8858694}]}]}
{"op":"mcm","clk":"11936231619","pt":1724675965530,"mc":[{"id":"1.232298775","rc":[{"batb":[[0,1.76,5],[1,1.75,23.18],[2,1.69,55.71]],"ltp":1.76,"tv":44.9,"id":247649},{"batb":[[0,2.28,5],[1,2.26,30.51],[2,1.2,125]],"ltp":2.26,"tv":29.71,"id":8858694}]}]}
{"op":"mcm","clk":"11936231886","pt":1724675968826,"mc":[{"id":"1.232298775","rc":[{"batb":[[0,1.75,23.18],[1,1.69,55.71],[2,1.2,125]],"ltp":1.76,"tv":44.9,"id":247649},{"batb":[[0,2.26,30.51],[1,1.2,125],[2,1.04,1614.32]],"ltp":2.26,"tv":29.71,"id":8858694}]}]}
{"op":"mcm","clk":"11936232526","pt":1724675976649,"mc":[{"id":"1.232298775","rc":[{"batb":[[0,1.76,5],[1,1.75,20.83],[2,1.69,55.71]],"ltp":1.76,"tv":44.9,"id":247649},{"batb":[[0,2.28,5],[1,2.26,30.51],[2,1.2,125]],"ltp":2.26,"tv":29.71,"id":8858694}]}]}
{"op":"mcm","clk":"11936232782","pt":1724675979939,"mc":[{"id":"1.232298775","rc":[{"batb":[[0,1.75,20.83],[1,1.69,55.71],[2,1.2,125]],"ltp":1.76,"tv":44.9,"id":247649},{"batb":[[0,2.26,30.51],[1,1.2,125],[2,1.04,1614.32]],"ltp":2.26,"tv":29.71,"id":8858694}]}]}
{"op":"mcm","clk":"11936233465","pt":1724675988559,"mc":[{"id":"1.232298775","rc":[{"trd":[[1.8,2.35]],"batb":[[0,1.76,5],[1,1.75,20.83],[2,1.69,55.71]],"ltp":1.8,"tv":47.25,"id":247649},{"trd":[[2.26,2.89]],"batb":[[0,2.28,5],[1,2.26,28.64],[2,1.2,125]],"ltp":2.26,"tv":31.58,"id":8858694}],"tv":78.83}]}
{"op":"mcm","clk":"11936233599","pt":1724675990666,"mc":[{"id":"1.232298775","rc":[{"batb":[[2,1.2,125]],"ltp":1.8,"tv":47.25,"id":247649},{"batb":[[1,1.2,125],[2,1.04,1614.32]],"ltp":2.26,"tv":31.58,"id":8858694}]}]}
{"op":"mcm","clk":"11936233679","pt":1724675991854,"mc":[{"id":"1.232298775","rc":[{"batb":[[0,1.75,20.83],[1,1.2,125],[2,1.05,5.19]],"ltp":1.8,"tv":47.25,"id":247649},{"batb":[[0,1.2,125],[1,1.04,1614.32],[2,1.03,2336.63]],"ltp":2.26,"tv":31.58,"id":8858694}]}]}
{"op":"mcm","clk":"11936233980","pt":1724675995679,"mc":[{"id":"1.232298775","rc":[{"batb":[[0,1.76,5],[1,1.75,20.83],[2,1.69,55.71]],"ltp":1.8,"tv":47.25,"id":247649},{"batb":[[0,2.28,5],[1,2.26,30.51],[2,1.2,125]],"ltp":2.26,"tv":31.58,"id":8858694}]}]}
{"op":"mcm","clk":"11936234245","pt":1724675999180,"mc":[{"id":"1.232298775","rc":[{"batb":[[0,1.75,20.83],[1,1.69,55.71],[2,1.2,125]],"ltp":1.8,"tv":47.25,"id":247649},{"batb":[[0,2.26,30.51],[1,1.2,125],[2,1.04,1614.32]],"ltp":2.26,"tv":31.58,"id":8858694}]}]}
{"op":"mcm","clk":"11936237276","pt":1724676036032,"mc":[{"id":"1.232298775","rc":[{"batb":[[0,1.76,5],[1,1.75,20.83],[2,1.69,55.71]],"ltp":1.8,"tv":47.25,"id":247649},{"batb":[[0,2.28,5],[1,2.26,30.51],[2,1.2,125]],"ltp":2.26,"tv":31.58,"id":8858694}]}]}
{"op":"mcm","clk":"11936237516","pt":1724676039311,"mc":[{"id":"1.232298775","rc":[{"batb":[[0,1.75,20.83],[1,1.69,55.71],[2,1.2,125]],"ltp":1.8,"tv":47.25,"id":247649},{"batb":[[0,2.26,30.51],[1,1.2,125],[2,1.04,1614.32]],"ltp":2.26,"tv":31.58,"id":8858694}]}]}
{"op":"mcm","clk":"11936240953","pt":1724676084279,"mc":[{"id":"1.232298775","rc":[{"batb":[[0,1.76,5],[1,1.75,20.83],[2,1.69,55.71]],"ltp":1.8,"tv":47.25,"id":247649},{"batb":[[0,2.28,5],[1,2.26,30.51],[2,1.2,125]],"ltp":2.26,"tv":31.58,"id":8858694}]}]}
{"op":"mcm","clk":"11936241100","pt":1724676085985,"mc":[{"id":"1.232298775","rc":[{"batb":[[2,1.2,125]],"ltp":1.8,"tv":47.25,"id":247649},{"batb":[[1,1.2,125],[2,1.04,1614.32]],"ltp":2.26,"tv":31.58,"id":8858694}]}]}
{"op":"mcm","clk":"11936241211","pt":1724676087484,"mc":[{"id":"1.232298775","rc":[{"batb":[[0,1.75,20.83],[1,1.2,125],[2,1.05,5.19]],"ltp":1.8,"tv":47.25,"id":247649},{"batb":[[0,1.2,125],[1,1.04,1614.32],[2,1.03,2336.63]],"ltp":2.26,"tv":31.58,"id":8858694}]}]}
{"op":"mcm","clk":"11936241474","pt":1724676090993,"mc":[{"id":"1.232298775","rc":[{"batb":[[0,1.76,5],[1,1.75,20.83],[2,1.69,55.71]],"ltp":1.8,"tv":47.25,"id":247649},{"batb":[[0,2.28,5],[1,2.26,30.51],[2,1.2,125]],"ltp":2.26,"tv":31.58,"id":8858694}]}]}
{"op":"mcm","clk":"11936241718","pt":1724676094193,"mc":[{"id":"1.232298775","rc":[{"batb":[[0,1.75,20.83],[1,1.69,55.71],[2,1.2,125]],"ltp":1.8,"tv":47.25,"id":247649},{"batb":[[0,2.26,30.51],[1,1.2,125],[2,1.04,1614.32]],"ltp":2.26,"tv":31.58,"id":8858694}]}]}
{"op":"mcm","clk":"11936255367","pt":1724676278800,"mc":[{"id":"1.232298775","rc":[{"batb":[[0,1.76,5],[1,1.75,20.83],[2,1.69,55.71]],"ltp":1.8,"tv":47.25,"id":247649},{"batb":[[0,2.28,5],[1,2.26,30.51],[2,1.2,125]],"ltp":2.26,"tv":31.58,"id":8858694}]}]}
{"op":"mcm","clk":"11936255554","pt":1724676281580,"mc":[{"id":"1.232298775","rc":[{"batb":[[2,1.2,125]],"ltp":1.8,"tv":47.25,"id":247649},{"batb":[[1,1.2,125],[2,1.04,1614.32]],"ltp":2.26,"tv":31.58,"id":8858694}]}]}
{"op":"mcm","clk":"11936255591","pt":1724676282096,"mc":[{"id":"1.232298775","rc":[{"batb":[[0,1.75,20.83],[1,1.2,125],[2,1.05,5.19]],"ltp":1.8,"tv":47.25,"id":247649},{"batb":[[0,1.2,125],[1,1.04,1614.32],[2,1.03,2336.63]],"ltp":2.26,"tv":31.58,"id":8858694}]}]}
{"op":"mcm","clk":"11936255954","pt":1724676286722,"mc":[{"id":"1.232298775","rc":[{"batb":[[0,1.76,5],[1,1.75,20.83],[2,1.69,55.71]],"ltp":1.8,"tv":47.25,"id":247649},{"batb":[[0,2.28,5],[1,2.26,30.51],[2,1.2,125]],"ltp":2.26,"tv":31.58,"id":8858694}]}]}
{"op":"mcm","clk":"11936256169","pt":1724676290215,"mc":[{"id":"1.232298775","rc":[{"batb":[[0,1.75,20.83],[1,1.69,55.71],[2,1.2,125]],"ltp":1.8,"tv":47.25,"id":247649},{"batb":[[0,2.26,30.51],[1,1.2,125],[2,1.04,1614.32]],"ltp":2.26,"tv":31.58,"id":8858694}]}]}
{"op":"mcm","clk":"11936257452","pt":1724676307454,"mc":[{"id":"1.232298775","rc":[{"batb":[[0,1.76,5],[1,1.75,20.83],[2,1.69,55.71]],"ltp":1.8,"tv":47.25,"id":247649},{"batb":[[0,2.28,5],[1,2.26,30.51],[2,1.2,125]],"ltp":2.26,"tv":31.58,"id":8858694}]}]}
{"op":"mcm","clk":"11936257714","pt":1724676310750,"mc":[{"id":"1.232298775","rc":[{"batb":[[0,1.75,20.83],[1,1.69,55.71],[2,1.2,125]],"ltp":1.8,"tv":47.25,"id":247649},{"batb":[[0,2.26,30.51],[1,1.2,125],[2,1.04,1614.32]],"ltp":2.26,"tv":31.58,"id":8858694}]}]}
{"op":"mcm","clk":"11936260293","pt":1724676344073,"mc":[{"id":"1.232298775","rc":[{"batb":[[0,1.76,5],[1,1.75,20.83],[2,1.69,55.71]],"ltp":1.8,"tv":47.25,"id":247649},{"batb":[[0,2.28,5],[1,2.26,30.51],[2,1.2,125]],"ltp":2.26,"tv":31.58,"id":8858694}]}]}
{"op":"mcm","clk":"11936260536","pt":1724676346864,"mc":[{"id":"1.232298775","rc":[{"batb":[[2,1.2,125]],"ltp":1.8,"tv":47.25,"id":247649},{"batb":[[1,1.2,125],[2,1.04,1614.32]],"ltp":2.26,"tv":31.58,"id":8858694}]}]}
{"op":"mcm","clk":"11936260588","pt":1724676347486,"mc":[{"id":"1.232298775","rc":[{"batb":[[0,1.75,20.83],[1,1.2,125],[2,1.05,5.19]],"ltp":1.8,"tv":47.25,"id":247649},{"batb":[[0,1.2,125],[1,1.04,1614.32],[2,1.03,2336.63]],"ltp":2.26,"tv":31.58,"id":8858694}]}]}
{"op":"mcm","clk":"11936260922","pt":1724676351983,"mc":[{"id":"1.232298775","rc":[{"batb":[[0,1.76,5],[1,1.75,20.83],[2,1.69,55.71]],"ltp":1.8,"tv":47.25,"id":247649},{"batb":[[0,2.28,5],[1,2.26,30.51],[2,1.2,125]],"ltp":2.26,"tv":31.58,"id":8858694}]}]}
{"op":"mcm","clk":"11936261171","pt":1724676355275,"mc":[{"id":"1.232298775","rc":[{"batb":[[0,1.75,20.83],[1,1.69,55.71],[2,1.2,125]],"ltp":1.8,"tv":47.25,"id":247649},{"batb":[[0,2.26,30.51],[1,1.2,125],[2,1.04,1614.32]],"ltp":2.26,"tv":31.58,"id":8858694}]}]}
{"op":"mcm","clk":"11936262202","pt":1724676368219,"mc":[{"id":"1.232298775","rc":[{"batb":[[0,1.76,5],[1,1.75,20.83],[2,1.69,55.71]],"ltp":1.8,"tv":47.25,"id":247649},{"batb":[[0,2.28,5],[1,2.26,30.51],[2,1.2,125]],"ltp":2.26,"tv":31.58,"id":8858694}]}]}
{"op":"mcm","clk":"11936262483","pt":1724676371632,"mc":[{"id":"1.232298775","rc":[{"batb":[[0,1.75,20.83],[1,1.69,55.71],[2,1.2,125]],"ltp":1.8,"tv":47.25,"id":247649},{"batb":[[0,2.26,30.51],[1,1.2,125],[2,1.04,1614.32]],"ltp":2.26,"tv":31.58,"id":8858694}]}]}
{"op":"mcm","clk":"11936262707","pt":1724676374317,"mc":[{"id":"1.232298775","rc":[{"batb":[[0,1.76,5],[1,1.75,20.83],[2,1.69,55.71]],"ltp":1.8,"tv":47.25,"id":247649},{"batb":[[0,2.28,5],[1,2.26,30.51],[2,1.2,125]],"ltp":2.26,"tv":31.58,"id":8858694}]}]}
{"op":"mcm","clk":"11936262988","pt":1724676377619,"mc":[{"id":"1.232298775","rc":[{"batb":[[0,1.75,20.83],[1,1.2,125],[2,1.05,5.19]],"ltp":1.8,"tv":47.25,"id":247649},{"batb":[[0,1.2,125],[1,1.04,1614.32],[2,1.03,2336.63]],"ltp":2.26,"tv":31.58,"id":8858694}]}]}
{"op":"mcm","clk":"11936263325","pt":1724676382049,"mc":[{"id":"1.232298775","rc":[{"batb":[[0,1.76,5],[1,1.75,20.83],[2,1.69,55.71]],"ltp":1.8,"tv":47.25,"id":247649},{"batb":[[0,2.28,5],[1,2.26,30.51],[2,1.2,125]],"ltp":2.26,"tv":31.58,"id":8858694}]}]}
{"op":"mcm","clk":"11936263579","pt":1724676385349,"mc":[{"id":"1.232298775","rc":[{"batb":[[0,1.75,20.83],[1,1.69,55.71],[2,1.2,125]],"ltp":1.8,"tv":47.25,"id":247649},{"batb":[[0,2.26,30.51],[1,1.2,125],[2,1.04,1614.32]],"ltp":2.26,"tv":31.58,"id":8858694}]}]}
{"op":"mcm","clk":"11936263815","pt":1724676387926,"mc":[{"id":"1.232298775","rc":[{"batb":[[0,1.76,5],[1,1.75,20.83],[2,1.69,55.71]],"ltp":1.8,"tv":47.25,"id":247649},{"batb":[[0,2.28,5],[1,2.26,30.51],[2,1.2,125]],"ltp":2.26,"tv":31.58,"id":8858694}]}]}
{"op":"mcm","clk":"11936264093","pt":1724676391231,"mc":[{"id":"1.232298775","rc":[{"batb":[[0,1.75,20.83],[1,1.69,55.71],[2,1.2,125]],"ltp":1.8,"tv":47.25,"id":247649},{"batb":[[0,2.26,30.51],[1,1.2,125],[2,1.04,1614.32]],"ltp":2.26,"tv":31.58,"id":8858694}]}]}
{"op":"mcm","clk":"11936264436","pt":1724676394845,"mc":[{"id":"1.232298775","rc":[{"batb":[[0,1.76,5],[1,1.75,20.83],[2,1.69,55.71]],"ltp":1.8,"tv":47.25,"id":247649},{"batb":[[0,2.28,5],[1,2.26,30.51],[2,1.2,125]],"ltp":2.26,"tv":31.58,"id":8858694}]}]}
{"op":"mcm","clk":"11936264629","pt":1724676397058,"mc":[{"id":"1.232298775","rc":[{"batb":[[2,1.2,125]],"ltp":1.8,"tv":47.25,"id":247649},{"batb":[[1,1.2,125],[2,1.04,1614.32]],"ltp":2.26,"tv":31.58,"id":8858694}]}]}
{"op":"mcm","clk":"11936264720","pt":1724676398035,"mc":[{"id":"1.232298775","rc":[{"batb":[[0,1.75,20.83],[1,1.2,125],[2,1.05,5.19]],"ltp":1.8,"tv":47.25,"id":247649},{"batb":[[0,1.2,125],[1,1.04,1614.32],[2,1.03,2336.63]],"ltp":2.26,"tv":31.58,"id":8858694}]}]}
{"op":"mcm","clk":"11936265055","pt":1724676402159,"mc":[{"id":"1.232298775","rc":[{"batb":[[0,1.76,5],[1,1.75,20.83],[2,1.69,55.71]],"ltp":1.8,"tv":47.25,"id":247649},{"batb":[[0,2.28,5],[1,2.26,30.51],[2,1.2,125]],"ltp":2.26,"tv":31.58,"id":8858694}]}]}
{"op":"mcm","clk":"11936265296","pt":1724676405358,"mc":[{"id":"1.232298775","rc":[{"batb":[[0,1.75,20.83],[1,1.69,55.71],[2,1.2,125]],"ltp":1.8,"tv":47.25,"id":247649},{"batb":[[0,2.26,30.51],[1,1.2,125],[2,1.04,1614.32]],"ltp":2.26,"tv":31.58,"id":8858694}]}]}
{"op":"mcm","clk":"11936266105","pt":1724676415976,"mc":[{"id":"1.232298775","rc":[{"batb":[[0,1.76,5],[1,1.75,20.83],[2,1.69,55.71]],"ltp":1.8,"tv":47.25,"id":247649},{"batb":[[0,2.28,5],[1,2.26,30.51],[2,1.2,125]],"ltp":2.26,"tv":31.58,"id":8858694}]}]}
{"op":"mcm","clk":"11936266178","pt":1724676417061,"mc":[{"id":"1.232298775","rc":[{"batb":[[2,1.2,125]],"ltp":1.8,"tv":47.25,"id":247649},{"batb":[[1,1.2,125],[2,1.04,1614.32]],"ltp":2.26,"tv":31.58,"id":8858694}]}]}
{"op":"mcm","clk":"11936266323","pt":1724676419218,"mc":[{"id":"1.232298775","rc":[{"batb":[[0,1.75,20.83],[1,1.2,125],[2,1.05,5.19]],"ltp":1.8,"tv":47.25,"id":247649},{"batb":[[0,1.2,125],[1,1.04,1614.32],[2,1.03,2336.63]],"ltp":2.26,"tv":31.58,"id":8858694}]}]}
{"op":"mcm","clk":"11936266570","pt":1724676422112,"mc":[{"id":"1.232298775","rc":[{"batb":[[0,1.76,5],[1,1.75,20.83],[2,1.69,55.71]],"ltp":1.8,"tv":47.25,"id":247649},{"batb":[[0,2.26,30.51],[1,1.21,5],[2,1.2,125]],"ltp":2.26,"tv":31.58,"id":8858694}]}]}
{"op":"mcm","clk":"11936266819","pt":1724676425416,"mc":[{"id":"1.232298775","rc":[{"batb":[[0,1.75,20.83],[1,1.69,55.71],[2,1.2,125]],"ltp":1.8,"tv":47.25,"id":247649},{"batb":[[1,1.2,125],[2,1.04,1614.32]],"ltp":2.26,"tv":31.58,"id":8858694}]}]}
{"op":"mcm","clk":"11936270453","pt":1724676470523,"mc":[{"id":"1.232298775","rc":[{"batb":[[0,1.76,5],[1,1.75,20.83],[2,1.69,55.71]],"ltp":1.8,"tv":47.25,"id":247649},{"batb":[[0,2.28,5],[1,2.26,30.51],[2,1.2,125]],"ltp":2.26,"tv":31.58,"id":8858694}]}]}
{"op":"mcm","clk":"11936270604","pt":1724676472325,"mc":[{"id":"1.232298775","rc":[{"batb":[[2,1.2,125]],"ltp":1.8,"tv":47.25,"id":247649},{"batb":[[1,1.2,125],[2,1.04,1614.32]],"ltp":2.26,"tv":31.58,"id":8858694}]}]}
{"op":"mcm","clk":"11936270724","pt":1724676473971,"mc":[{"id":"1.232298775","rc":[{"batb":[[0,1.75,20.83],[1,1.2,125],[2,1.05,5.19]],"ltp":1.8,"tv":47.25,"id":247649},{"batb":[[0,1.2,125],[1,1.04,1614.32],[2,1.03,2336.63]],"ltp":2.26,"tv":31.58,"id":8858694}]}]}
{"op":"mcm","clk":"11936270985","pt":1724676477433,"mc":[{"id":"1.232298775","rc":[{"batb":[[0,1.76,5],[1,1.75,20.83],[2,1.69,55.71]],"ltp":1.8,"tv":47.25,"id":247649},{"batb":[[0,2.28,5],[1,2.26,30.51],[2,1.2,125]],"ltp":2.26,"tv":31.58,"id":8858694}]}]}
{"op":"mcm","clk":"11936271236","pt":1724676480740,"mc":[{"id":"1.232298775","rc":[{"batb":[[0,1.75,20.83],[1,1.69,55.71],[2,1.2,125]],"ltp":1.8,"tv":47.25,"id":247649},{"batb":[[0,2.26,30.51],[1,1.2,125],[2,1.04,1614.32]],"ltp":2.26,"tv":31.58,"id":8858694}]}]}
{"op":"mcm","clk":"11936272738","pt":1724676498253,"mc":[{"id":"1.232298775","rc":[{"batb":[[0,1.76,5],[1,1.75,20.83],[2,1.69,55.71]],"ltp":1.8,"tv":47.25,"id":247649},{"batb":[[0,2.28,5],[1,2.26,30.51],[2,1.2,125]],"ltp":2.26,"tv":31.58,"id":8858694}]}]}
{"op":"mcm","clk":"11936273012","pt":1724676501686,"mc":[{"id":"1.232298775","rc":[{"batb":[[0,1.75,20.83],[1,1.69,55.71],[2,1.2,125]],"ltp":1.8,"tv":47.25,"id":247649},{"batb":[[0,2.26,30.51],[1,1.2,125],[2,1.04,1614.32]],"ltp":2.26,"tv":31.58,"id":8858694}]}]}
{"op":"mcm","clk":"11936274112","pt":1724676514931,"mc":[{"id":"1.232298775","rc":[{"batb":[[0,1.76,5],[1,1.75,20.83],[2,1.69,55.71]],"ltp":1.8,"tv":47.25,"id":247649},{"batb":[[0,2.28,5],[1,2.26,30.51],[2,1.2,125]],"ltp":2.26,"tv":31.58,"id":8858694}]}]}
{"op":"mcm","clk":"11936274348","pt":1724676517530,"mc":[{"id":"1.232298775","rc":[{"batb":[[2,1.2,125]],"ltp":1.8,"tv":47.25,"id":247649},{"batb":[[1,1.2,125],[2,1.04,1614.32]],"ltp":2.26,"tv":31.58,"id":8858694}]}]}
{"op":"mcm","clk":"11936274390","pt":1724676518016,"mc":[{"id":"1.232298775","rc":[{"batb":[[0,1.75,20.83],[1,1.2,125],[2,1.05,5.19]],"ltp":1.8,"tv":47.25,"id":247649},{"batb":[[0,1.2,125],[1,1.04,1614.32],[2,1.03,2336.63]],"ltp":2.26,"tv":31.58,"id":8858694}]}]}
{"op":"mcm","clk":"11936274797","pt":1724676522626,"mc":[{"id":"1.232298775","rc":[{"batb":[[0,1.76,5],[1,1.75,20.83],[2,1.69,55.71]],"ltp":1.8,"tv":47.25,"id":247649},{"batb":[[0,2.28,5],[1,2.26,30.51],[2,1.2,125]],"ltp":2.26,"tv":31.58,"id":8858694}]}]}
{"op":"mcm","clk":"11936275099","pt":1724676526039,"mc":[{"id":"1.232298775","rc":[{"batb":[[0,1.75,20.83],[1,1.69,55.71],[2,1.2,125]],"ltp":1.8,"tv":47.25,"id":247649},{"batb":[[0,2.26,30.51],[1,1.2,125],[2,1.04,1614.32]],"ltp":2.26,"tv":31.58,"id":8858694}]}]}
{"op":"mcm","clk":"11936275428","pt":1724676529943,"mc":[{"id":"1.232298775","rc":[{"batb":[[0,1.76,5],[1,1.75,20.83],[2,1.69,55.71]],"ltp":1.8,"tv":47.25,"id":247649},{"batb":[[0,2.28,5],[1,2.26,30.51],[2,1.2,125]],"ltp":2.26,"tv":31.58,"id":8858694}]}]}
{"op":"mcm","clk":"11936275666","pt":1724676532650,"mc":[{"id":"1.232298775","rc":[{"batb":[[2,1.2,125]],"ltp":1.8,"tv":47.25,"id":247649},{"batb":[[1,1.2,125],[2,1.04,1614.32]],"ltp":2.26,"tv":31.58,"id":8858694}]}]}
{"op":"mcm","clk":"11936275730","pt":1724676533352,"mc":[{"id":"1.232298775","rc":[{"batb":[[0,1.75,20.83],[1,1.2,125],[2,1.05,5.19]],"ltp":1.8,"tv":47.25,"id":247649},{"batb":[[0,1.2,125],[1,1.04,1614.32],[2,1.03,2336.63]],"ltp":2.26,"tv":31.58,"id":8858694}]}]}
{"op":"mcm","clk":"11936276035","pt":1724676537628,"mc":[{"id":"1.232298775","rc":[{"batb":[[0,1.76,5],[1,1.75,20.83],[2,1.69,55.71]],"ltp":1.8,"tv":47.25,"id":247649},{"batb":[[0,2.28,5],[1,2.26,30.51],[2,1.2,125]],"ltp":2.26,"tv":31.58,"id":8858694}]}]}
{"op":"mcm","clk":"11936276305","pt":1724676541054,"mc":[{"id":"1.232298775","rc":[{"batb":[[0,1.75,20.83],[1,1.69,55.71],[2,1.2,125]],"ltp":1.8,"tv":47.25,"id":247649},{"batb":[[0,2.26,30.51],[1,1.2,125],[2,1.04,1614.32]],"ltp":2.26,"tv":31.58,"id":8858694}]}]}
{"op":"mcm","clk":"11936277985","pt":1724676562678,"mc":[{"id":"1.232298775","rc":[{"batb":[[0,1.76,5],[1,1.75,20.83]],"ltp":1.8,"tv":47.25,"id":247649},{"batb":[[0,2.28,5]],"ltp":2.26,"tv":31.58,"id":8858694}]}]}
{"op":"mcm","clk":"11936278215","pt":1724676565683,"mc":[{"id":"1.232298775","rc":[{"batb":[[0,1.75,20.83],[1,1.2,125],[2,1.05,5.19]],"ltp":1.8,"tv":47.25,"id":247649},{"batb":[[0,1.2,125],[1,1.04,1614.32],[2,1.03,2336.63]],"ltp":2.26,"tv":31.58,"id":8858694}]}]}
{"op":"mcm","clk":"11936278379","pt":1724676567781,"mc":[{"id":"1.232298775","rc":[{"batb":[[0,1.76,5],[1,1.75,20.83],[2,1.69,55.71]],"ltp":1.8,"tv":47.25,"id":247649},{"batb":[[0,2.28,5],[1,2.26,30.51],[2,1.2,125]],"ltp":2.26,"tv":31.58,"id":8858694}]}]}
{"op":"mcm","clk":"11936278642","pt":1724676571285,"mc":[{"id":"1.232298775","rc":[{"batb":[[0,1.75,20.83],[1,1.69,55.71],[2,1.2,125]],"ltp":1.8,"tv":47.25,"id":247649},{"batb":[[0,2.26,30.51],[1,1.2,125],[2,1.04,1614.32]],"ltp":2.26,"tv":31.58,"id":8858694}]}]}
{"op":"mcm","clk":"11936279538","pt":1724676582802,"mc":[{"id":"1.232298775","rc":[{"batb":[[0,1.76,5],[1,1.75,20.83]],"ltp":1.8,"tv":47.25,"id":247649},{"batb":[[0,2.28,5]],"ltp":2.26,"tv":31.58,"id":8858694}]}]}
{"op":"mcm","clk":"11936279795","pt":1724676585911,"mc":[{"id":"1.232298775","rc":[{"batb":[[0,1.75,20.83],[1,1.2,125],[2,1.05,5.19]],"ltp":1.8,"tv":47.25,"id":247649},{"batb":[[0,1.2,125],[1,1.04,1614.32],[2,1.03,2336.63]],"ltp":2.26,"tv":31.58,"id":8858694}]}]}
{"op":"mcm","clk":"11936279956","pt":1724676587731,"mc":[{"id":"1.232298775","rc":[{"batb":[[1,1.69,55.71],[2,1.2,125]],"ltp":1.8,"tv":47.25,"id":247649},{"batb":[[0,2.26,30.51],[1,1.2,125],[2,1.04,1614.32]],"ltp":2.26,"tv":31.58,"id":8858694}]}]}
{"op":"mcm","clk":"11936284955","pt":1724676648186,"mc":[{"id":"1.232298775","rc":[{"batb":[[0,1.76,5],[1,1.75,20.83],[2,1.69,55.71]],"ltp":1.8,"tv":47.25,"id":247649},{"batb":[[0,2.28,5],[1,2.26,30.51],[2,1.2,125]],"ltp":2.26,"tv":31.58,"id":8858694}]}]}
{"op":"mcm","clk":"11936285181","pt":1724676651398,"mc":[{"id":"1.232298775","rc":[{"batb":[[0,1.75,20.83],[1,1.69,55.71],[2,1.2,125]],"ltp":1.8,"tv":47.25,"id":247649},{"batb":[[0,2.26,30.51],[1,1.2,125],[2,1.04,1614.32]],"ltp":2.26,"tv":31.58,"id":8858694}]}]}
{"op":"mcm","clk":"11936285607","pt":1724676656892,"mc":[{"id":"1.232298775","rc":[{"batb":[[0,1.76,5],[1,1.75,20.83],[2,1.69,55.71]],"ltp":1.8,"tv":47.25,"id":247649},{"batb":[[0,2.28,5],[1,2.26,30.51],[2,1.2,125]],"ltp":2.26,"tv":31.58,"id":8858694}]}]}
{"op":"mcm","clk":"11936285692","pt":1724676658098,"mc":[{"id":"1.232298775","rc":[{"batb":[[2,1.2,125]],"ltp":1.8,"tv":47.25,"id":247649},{"batb":[[1,1.2,125],[2,1.04,1614.32]],"ltp":2.26,"tv":31.58,"id":8858694}]}]}
{"op":"mcm","clk":"11936285843","pt":1724676660111,"mc":[{"id":"1.232298775","rc":[{"batb":[[0,1.75,20.83],[1,1.2,125],[2,1.05,5.19]],"ltp":1.8,"tv":47.25,"id":247649},{"batb":[[0,1.2,125],[1,1.04,1614.32],[2,1.03,2336.63]],"ltp":2.26,"tv":31.58,"id":8858694}]}]}
{"op":"mcm","clk":"11936286078","pt":1724676663095,"mc":[{"id":"1.232298775","rc":[{"batb":[[0,1.76,5],[1,1.75,20.83],[2,1.69,55.71]],"ltp":1.8,"tv":47.25,"id":247649},{"batb":[[0,2.28,5],[1,2.26,30.51],[2,1.2,125]],"ltp":2.26,"tv":31.58,"id":8858694}]}]}
{"op":"mcm","clk":"11936286334","pt":1724676666417,"mc":[{"id":"1.232298775","rc":[{"batb":[[0,1.75,20.83],[1,1.69,55.71],[2,1.2,125]],"ltp":1.8,"tv":47.25,"id":247649},{"batb":[[0,2.26,30.51],[1,1.2,125],[2,1.04,1614.32]],"ltp":2.26,"tv":31.58,"id":8858694}]}]}
{"op":"mcm","clk":"11936286673","pt":1724676671218,"mc":[{"id":"1.232298775","rc":[{"batb":[[0,1.76,5],[1,1.75,20.83],[2,1.69,55.71]],"ltp":1.8,"tv":47.25,"id":247649},{"batb":[[0,2.28,5],[1,2.26,30.51],[2,1.2,125]],"ltp":2.26,"tv":31.58,"id":8858694}]}]}
{"op":"mcm","clk":"11936286790","pt":1724676673131,"mc":[{"id":"1.232298775","rc":[{"batb":[[2,1.2,125]],"ltp":1.8,"tv":47.25,"id":247649},{"batb":[[1,1.2,125],[2,1.04,1614.32]],"ltp":2.26,"tv":31.58,"id":8858694}]}]}
{"op":"mcm","clk":"11936286918","pt":1724676674497,"mc":[{"id":"1.232298775","rc":[{"batb":[[0,1.75,20.83],[1,1.2,125],[2,1.05,5.19]],"ltp":1.8,"tv":47.25,"id":247649},{"batb":[[0,1.2,125],[1,1.04,1614.32],[2,1.03,2336.63]],"ltp":2.26,"tv":31.58,"id":8858694}]}]}
{"op":"mcm","clk":"11936287224","pt":1724676678226,"mc":[{"id":"1.232298775","rc":[{"batb":[[0,1.76,5],[1,1.75,20.83],[2,1.69,55.71]],"ltp":1.8,"tv":47.25,"id":247649},{"batb":[[0,2.28,5],[1,2.26,30.51],[2,1.2,125]],"ltp":2.26,"tv":31.58,"id":8858694}]}]}
{"op":"mcm","clk":"11936287504","pt":1724676681715,"mc":[{"id":"1.232298775","rc":[{"batb":[[0,1.75,20.83],[1,1.69,55.71],[2,1.2,125]],"ltp":1.8,"tv":47.25,"id":247649}]}]}
{"op":"mcm","clk":"11936287518","pt":1724676681920,"mc":[{"id":"1.232298775","rc":[{"batb":[[0,2.26,30.51],[1,1.2,125],[2,1.04,1614.32]],"ltp":2.26,"tv":31.58,"id":8858694}]}]}
{"op":"mcm","clk":"11936290559","pt":1724676723171,"mc":[{"id":"1.232298775","rc":[{"batb":[[0,1.76,5],[1,1.75,20.83],[2,1.69,55.71]],"ltp":1.8,"tv":47.25,"id":247649},{"batb":[[0,2.28,5],[1,2.26,30.51],[2,1.2,125]],"ltp":2.26,"tv":31.58,"id":8858694}]}]}
{"op":"mcm","clk":"11936290835","pt":1724676726477,"mc":[{"id":"1.232298775","rc":[{"batb":[[0,1.75,20.83],[1,1.69,55.71],[2,1.2,125]],"ltp":1.8,"tv":47.25,"id":247649},{"batb":[[0,2.26,30.51],[1,1.2,125],[2,1.04,1614.32]],"ltp":2.26,"tv":31.58,"id":8858694}]}]}
{"op":"mcm","clk":"11936293101","pt":1724676755201,"mc":[{"id":"1.232298775","rc":[{"batb":[[0,1.76,5],[1,1.75,20.83],[2,1.69,55.71]],"ltp":1.8,"tv":47.25,"id":247649},{"batb":[[0,2.28,5],[1,2.26,30.51],[2,1.2,125]],"ltp":2.26,"tv":31.58,"id":8858694}]}]}
{"op":"mcm","clk":"11936293357","pt":1724676758620,"mc":[{"id":"1.232298775","rc":[{"batb":[[0,1.75,20.83],[1,1.2,125],[2,1.05,5.19]],"ltp":1.8,"tv":47.25,"id":247649},{"batb":[[0,1.2,125],[1,1.04,1614.32],[2,1.03,2336.63]],"ltp":2.26,"tv":31.58,"id":8858694}]}]}
{"op":"mcm","clk":"11936293720","pt":1724676763529,"mc":[{"id":"1.232298775","rc":[{"batb":[[0,1.76,5],[1,1.75,20.83],[2,1.69,55.71]],"ltp":1.8,"tv":47.25,"id":247649},{"batb":[[0,2.28,5],[1,2.26,30.51],[2,1.2,125]],"ltp":2.26,"tv":31.58,"id":8858694}]}]}
{"op":"mcm","clk":"11936293988","pt":1724676766910,"mc":[{"id":"1.232298775","rc":[{"batb":[[0,1.75,20.83],[1,1.69,55.71],[2,1.2,125]],"ltp":1.8,"tv":47.25,"id":247649},{"batb":[[0,2.26,30.51],[1,1.2,125],[2,1.04,1614.32]],"ltp":2.26,"tv":31.58,"id":8858694}]}]}
{"op":"mcm","clk":"11936296295","pt":1724676797856,"mc":[{"id":"1.232298775","rc":[{"batb":[[0,1.76,5],[1,1.75,20.83],[2,1.69,55.71]],"ltp":1.8,"tv":47.25,"id":247649},{"batb":[[0,2.28,5],[1,2.26,30.51],[2,1.2,125]],"ltp":2.26,"tv":31.58,"id":8858694}]}]}
{"op":"mcm","clk":"11936296351","pt":1724676798570,"mc":[{"id":"1.232298775","rc":[{"batb":[[2,1.2,125]],"ltp":1.8,"tv":47.25,"id":247649},{"batb":[[1,1.2,125],[2,1.04,1614.32]],"ltp":2.26,"tv":31.58,"id":8858694}]}]}
{"op":"mcm","clk":"11936296544","pt":1724676801175,"mc":[{"id":"1.232298775","rc":[{"batb":[[0,1.75,20.83],[1,1.2,125],[2,1.05,5.19]],"ltp":1.8,"tv":47.25,"id":247649},{"batb":[[0,1.2,125],[1,1.04,1614.32],[2,1.03,2336.63]],"ltp":2.26,"tv":31.58,"id":8858694}]}]}
{"op":"mcm","clk":"11936296715","pt":1724676803765,"mc":[{"id":"1.232298775","rc":[{"batb":[[0,1.76,5],[1,1.75,20.83],[2,1.69,55.71]],"ltp":1.8,"tv":47.25,"id":247649},{"batb":[[0,2.26,30.51],[1,1.21,5],[2,1.2,125]],"ltp":2.26,"tv":31.58,"id":8858694}]}]}
{"op":"mcm","clk":"11936296921","pt":1724676806878,"mc":[{"id":"1.232298775","rc":[{"batb":[[0,1.75,20.83],[1,1.69,55.71],[2,1.2,125]],"ltp":1.8,"tv":47.25,"id":247649},{"batb":[[1,1.2,125],[2,1.04,1614.32]],"ltp":2.26,"tv":31.58,"id":8858694}]}]}
{"op":"mcm","clk":"11936299513","pt":1724676841497,"mc":[{"id":"1.232298775","rc":[{"batb":[[0,1.76,5],[1,1.75,20.83],[2,1.69,55.71]],"ltp":1.8,"tv":47.25,"id":247649},{"batb":[[0,2.28,5],[1,2.26,30.51],[2,1.2,125]],"ltp":2.26,"tv":31.58,"id":8858694}]}]}
{"op":"mcm","clk":"11936299668","pt":1724676843715,"mc":[{"id":"1.232298775","rc":[{"batb":[[2,1.2,125]],"ltp":1.8,"tv":47.25,"id":247649},{"batb":[[1,1.2,125],[2,1.04,1614.32]],"ltp":2.26,"tv":31.58,"id":8858694}]}]}
{"op":"mcm","clk":"11936299757","pt":1724676844818,"mc":[{"id":"1.232298775","rc":[{"batb":[[0,1.75,20.83],[1,1.2,125],[2,1.05,5.19]],"ltp":1.8,"tv":47.25,"id":247649},{"batb":[[0,1.2,125],[1,1.04,1614.32],[2,1.03,2336.63]],"ltp":2.26,"tv":31.58,"id":8858694}]}]}
{"op":"mcm","clk":"11936300033","pt":1724676848795,"mc":[{"id":"1.232298775","rc":[{"batb":[[0,1.76,5],[1,1.75,20.83],[2,1.69,55.71]],"ltp":1.8,"tv":47.25,"id":247649},{"batb":[[0,2.28,5],[1,2.26,30.51],[2,1.2,125]],"ltp":2.26,"tv":31.58,"id":8858694}]}]}
{"op":"mcm","clk":"11936300278","pt":1724676852206,"mc":[{"id":"1.232298775","rc":[{"batb":[[0,1.75,20.83],[1,1.69,55.71],[2,1.2,125]],"ltp":1.8,"tv":47.25,"id":247649},{"batb":[[0,2.26,30.51],[1,1.2,125],[2,1.04,1614.32]],"ltp":2.26,"tv":31.58,"id":8858694}]}]}
{"op":"mcm","clk":"11936300628","pt":1724676856395,"mc":[{"id":"1.232298775","rc":[{"batb":[[0,1.76,5],[1,1.75,20.83],[2,1.69,55.71]],"ltp":1.8,"tv":47.25,"id":247649},{"batb":[[0,2.28,5],[1,2.26,30.51],[2,1.2,125]],"ltp":2.26,"tv":31.58,"id":8858694}]}]}
{"op":"mcm","clk":"11936300856","pt":1724676859803,"mc":[{"id":"1.232298775","rc":[{"batb":[[0,1.75,20.83],[1,1.2,125],[2,1.05,5.19]],"ltp":1.8,"tv":47.25,"id":247649},{"batb":[[0,1.2,125],[1,1.04,1614.32],[2,1.03,2336.63]],"ltp":2.26,"tv":31.58,"id":8858694}]}]}
{"op":"mcm","clk":"11936301181","pt":1724676863837,"mc":[{"id":"1.232298775","rc":[{"batb":[[1,1.69,55.71],[2,1.2,125]],"ltp":1.8,"tv":47.25,"id":247649},{"batb":[[0,2.26,30.51],[1,1.2,125],[2,1.04,1614.32]],"ltp":2.26,"tv":31.58,"id":8858694}]}]}
{"op":"mcm","clk":"11936301193","pt":1724676863954,"mc":[{"id":"1.232298775","rc":[{"batb":[[0,1.76,5],[1,1.75,20.83],[2,1.69,55.71]],"ltp":1.8,"tv":47.25,"id":247649},{"batb":[[0,2.28,5],[1,2.26,30.51],[2,1.2,125]],"ltp":2.26,"tv":31.58,"id":8858694}]}]}
{"op":"mcm","clk":"11936301439","pt":1724676867298,"mc":[{"id":"1.232298775","rc":[{"batb":[[0,1.75,20.83],[1,1.69,55.71],[2,1.2,125]],"ltp":1.8,"tv":47.25,"id":247649},{"batb":[[0,2.26,30.51],[1,1.2,125],[2,1.04,1614.32]],"ltp":2.26,"tv":31.58,"id":8858694}]}]}
{"op":"mcm","clk":"11936301999","pt":1724676875932,"mc":[{"id":"1.232298775","rc":[{"batb":[[0,1.76,5],[1,1.75,20.83],[2,1.69,55.71]],"ltp":1.8,"tv":47.25,"id":247649},{"batb":[[0,2.28,5],[1,2.26,30.51],[2,1.2,125]],"ltp":2.26,"tv":31.58,"id":8858694}]}]}
{"op":"mcm","clk":"11936302254","pt":1724676879334,"mc":[{"id":"1.232298775","rc":[{"batb":[[0,1.75,20.83],[1,1.2,125],[2,1.05,5.19]],"ltp":1.8,"tv":47.25,"id":247649},{"batb":[[0,1.2,125],[1,1.04,1614.32],[2,1.03,2336.63]],"ltp":2.26,"tv":31.58,"id":8858694}]}]}
{"op":"mcm","clk":"11936302596","pt":1724676883831,"mc":[{"id":"1.232298775","rc":[{"batb":[[1,1.69,55.71],[2,1.2,125]],"ltp":1.8,"tv":47.25,"id":247649},{"batb":[[0,2.26,30.51],[1,1.2,125],[2,1.04,1614.32]],"ltp":2.26,"tv":31.58,"id":8858694}]}]}
{"op":"mcm","clk":"11936302604","pt":1724676883934,"mc":[{"id":"1.232298775","rc":[{"batb":[[0,1.76,5],[1,1.75,20.83],[2,1.69,55.71]],"ltp":1.8,"tv":47.25,"id":247649},{"batb":[[0,2.28,5],[1,2.26,30.51],[2,1.2,125]],"ltp":2.26,"tv":31.58,"id":8858694}]}]}
{"op":"mcm","clk":"11936302880","pt":1724676887459,"mc":[{"id":"1.232298775","rc":[{"batb":[[0,1.75,20.83],[1,1.69,55.71],[2,1.2,125]],"ltp":1.8,"tv":47.25,"id":247649},{"batb":[[0,2.26,30.51],[1,1.2,125],[2,1.04,1614.32]],"ltp":2.26,"tv":31.58,"id":8858694}]}]}
{"op":"mcm","clk":"11936303431","pt":1724676894947,"mc":[{"id":"1.232298775","rc":[{"batb":[[0,1.76,5],[1,1.75,20.83],[2,1.69,55.71]],"ltp":1.8,"tv":47.25,"id":247649},{"batb":[[0,2.28,5],[1,2.26,30.51],[2,1.2,125]],"ltp":2.26,"tv":31.58,"id":8858694}]}]}
{"op":"mcm","clk":"11936303676","pt":1724676898467,"mc":[{"id":"1.232298775","rc":[{"batb":[[0,1.75,20.83],[1,1.69,55.71],[2,1.2,125]],"ltp":1.8,"tv":47.25,"id":247649},{"batb":[[0,2.26,30.51],[1,1.2,125],[2,1.04,1614.32]],"ltp":2.26,"tv":31.58,"id":8858694}]}]}
{"op":"mcm","clk":"11936304715","pt":1724676911992,"mc":[{"id":"1.232298775","rc":[{"batb":[[0,1.76,5],[1,1.75,20.83],[2,1.69,55.71]],"ltp":1.8,"tv":47.25,"id":247649},{"batb":[[0,2.28,5],[1,2.26,30.51],[2,1.2,125]],"ltp":2.26,"tv":31.58,"id":8858694}]}]}
{"op":"mcm","clk":"11936304882","pt":1724676914003,"mc":[{"id":"1.232298775","rc":[{"batb":[[2,1.2,125]],"ltp":1.8,"tv":47.25,"id":247649},{"batb":[[1,1.2,125],[2,1.04,1614.32]],"ltp":2.26,"tv":31.58,"id":8858694}]}]}
{"op":"mcm","clk":"11936304986","pt":1724676915294,"mc":[{"id":"1.232298775","rc":[{"batb":[[0,1.75,20.83],[1,1.2,125],[2,1.05,5.19]],"ltp":1.8,"tv":47.25,"id":247649},{"batb":[[0,1.2,125],[1,1.04,1614.32],[2,1.03,2336.63]],"ltp":2.26,"tv":31.58,"id":8858694}]}]}
{"op":"mcm","clk":"11936305263","pt":1724676919211,"mc":[{"id":"1.232298775","rc":[{"batb":[[0,1.76,5],[1,1.75,20.83],[2,1.69,55.71]],"ltp":1.8,"tv":47.25,"id":247649},{"batb":[[0,2.28,5],[1,2.26,30.51],[2,1.2,125]],"ltp":2.26,"tv":31.58,"id":8858694}]}]}
{"op":"mcm","clk":"11936305504","pt":1724676922507,"mc":[{"id":"1.232298775","rc":[{"batb":[[0,1.75,20.83],[1,1.69,55.71],[2,1.2,125]],"ltp":1.8,"tv":47.25,"id":247649},{"batb":[[0,2.26,30.51],[1,1.2,125],[2,1.04,1614.32]],"ltp":2.26,"tv":31.58,"id":8858694}]}]}
{"op":"mcm","clk":"11936306340","pt":1724676934139,"mc":[{"id":"1.232298775","rc":[{"batb":[[0,1.76,5],[1,1.75,20.83],[2,1.69,55.71]],"ltp":1.8,"tv":47.25,"id":247649},{"batb":[[0,2.28,5],[1,2.26,30.51],[2,1.2,125]],"ltp":2.26,"tv":31.58,"id":8858694}]}]}
{"op":"mcm","clk":"11936306607","pt":1724676937457,"mc":[{"id":"1.232298775","rc":[{"batb":[[0,1.75,20.83],[1,1.69,55.71],[2,1.2,125]],"ltp":1.8,"tv":47.25,"id":247649},{"batb":[[0,2.26,30.51],[1,1.2,125],[2,1.04,1614.32]],"ltp":2.26,"tv":31.58,"id":8858694}]}]}
{"op":"mcm","clk":"11936308947","pt":1724676966588,"mc":[{"id":"1.232298775","rc":[{"batb":[[0,1.76,5],[1,1.75,20.83],[2,1.69,55.71]],"ltp":1.8,"tv":47.25,"id":247649},{"batb":[[0,2.28,5],[1,2.26,30.51],[2,1.2,125]],"ltp":2.26,"tv":31.58,"id":8858694}]}]}
{"op":"mcm","clk":"11936309131","pt":1724676969174,"mc":[{"id":"1.232298775","rc":[{"batb":[[2,1.2,125]],"ltp":1.8,"tv":47.25,"id":247649},{"batb":[[1,1.2,125],[2,1.04,1614.32]],"ltp":2.26,"tv":31.58,"id":8858694}]}]}
{"op":"mcm","clk":"11936309175","pt":1724676969879,"mc":[{"id":"1.232298775","rc":[{"batb":[[0,1.75,20.83],[1,1.2,125],[2,1.05,5.19]],"ltp":1.8,"tv":47.25,"id":247649},{"batb":[[0,1.2,125],[1,1.04,1614.32],[2,1.03,2336.63]],"ltp":2.26,"tv":31.58,"id":8858694}]}]}
{"op":"mcm","clk":"11936309532","pt":1724676974261,"mc":[{"id":"1.232298775","rc":[{"batb":[[0,1.76,5],[1,1.75,20.83],[2,1.69,55.71]],"ltp":1.8,"tv":47.25,"id":247649},{"batb":[[0,2.28,5],[1,2.26,30.51],[2,1.2,125]],"ltp":2.26,"tv":31.58,"id":8858694}]}]}
{"op":"mcm","clk":"11936309809","pt":1724676977467,"mc":[{"id":"1.232298775","rc":[{"batb":[[0,1.75,20.83],[1,1.69,55.71],[2,1.2,125]],"ltp":1.8,"tv":47.25,"id":247649},{"batb":[[0,2.26,30.51],[1,1.2,125],[2,1.04,1614.32]],"ltp":2.26,"tv":31.58,"id":8858694}]}]}
{"op":"mcm","clk":"11936316336","pt":1724677060059,"mc":[{"id":"1.232298775","rc":[{"batb":[[0,1.76,5],[1,1.75,20.83],[2,1.69,55.71]],"ltp":1.8,"tv":47.25,"id":247649},{"batb":[[0,2.28,5],[1,2.26,30.51],[2,1.2,125]],"ltp":2.26,"tv":31.58,"id":8858694}]}]}
{"op":"mcm","clk":"11936316599","pt":1724677063475,"mc":[{"id":"1.232298775","rc":[{"batb":[[0,1.75,20.83],[1,1.69,55.71],[2,1.2,125]],"ltp":1.8,"tv":47.25,"id":247649},{"batb":[[0,2.26,30.51],[1,1.2,125],[2,1.04,1614.32]],"ltp":2.26,"tv":31.58,"id":8858694}]}]}
{"op":"mcm","clk":"11936316991","pt":1724677068075,"mc":[{"id":"1.232298775","rc":[{"batb":[[0,1.76,5],[1,1.75,20.83],[2,1.69,55.71]],"ltp":1.8,"tv":47.25,"id":247649},{"batb":[[0,2.28,5],[1,2.26,30.51],[2,1.2,125]],"ltp":2.26,"tv":31.58,"id":8858694}]}]}
{"op":"mcm","clk":"11936317098","pt":1724677069673,"mc":[{"id":"1.232298775","rc":[{"batb":[[2,1.2,125]],"ltp":1.8,"tv":47.25,"id":247649},{"batb":[[1,1.2,125],[2,1.04,1614.32]],"ltp":2.26,"tv":31.58,"id":8858694}]}]}
{"op":"mcm","clk":"11936317214","pt":1724677071284,"mc":[{"id":"1.232298775","rc":[{"batb":[[0,1.75,20.83],[1,1.2,125],[2,1.05,5.19]],"ltp":1.8,"tv":47.25,"id":247649},{"batb":[[0,1.2,125],[1,1.04,1614.32],[2,1.03,2336.63]],"ltp":2.26,"tv":31.58,"id":8858694}]}]}
{"op":"mcm","clk":"11936317471","pt":1724677074695,"mc":[{"id":"1.232298775","rc":[{"batb":[[0,1.76,5],[1,1.75,20.83],[2,1.69,55.71]],"ltp":1.8,"tv":47.25,"id":247649},{"batb":[[0,2.28,5],[1,2.26,30.51],[2,1.2,125]],"ltp":2.26,"tv":31.58,"id":8858694}]}]}
{"op":"mcm","clk":"11936317729","pt":1724677077895,"mc":[{"id":"1.232298775","rc":[{"batb":[[0,1.75,20.83],[1,1.69,55.71],[2,1.2,125]],"ltp":1.8,"tv":47.25,"id":247649},{"batb":[[0,2.26,30.51],[1,1.2,125],[2,1.04,1614.32]],"ltp":2.26,"tv":31.58,"id":8858694}]}]}
{"op":"mcm","clk":"11936318465","pt":1724677086976,"mc":[{"id":"1.232298775","rc":[{"batb":[[0,1.76,5],[1,1.75,20.83],[2,1.69,55.71]],"ltp":1.8,"tv":47.25,"id":247649},{"batb":[[0,2.28,5],[1,2.26,30.51],[2,1.2,125]],"ltp":2.26,"tv":31.58,"id":8858694}]}]}
{"op":"mcm","clk":"11936318689","pt":1724677089721,"mc":[{"id":"1.232298775","rc":[{"batb":[[2,1.2,125]],"ltp":1.8,"tv":47.25,"id":247649},{"batb":[[1,1.2,125],[2,1.04,1614.32]],"ltp":2.26,"tv":31.58,"id":8858694}]}]}
{"op":"mcm","clk":"11936318750","pt":1724677090393,"mc":[{"id":"1.232298775","rc":[{"batb":[[0,1.75,20.83],[1,1.2,125],[2,1.05,5.19]],"ltp":1.8,"tv":47.25,"id":247649},{"batb":[[0,1.2,125],[1,1.04,1614.32],[2,1.03,2336.63]],"ltp":2.26,"tv":31.58,"id":8858694}]}]}
{"op":"mcm","clk":"11936319129","pt":1724677094805,"mc":[{"id":"1.232298775","rc":[{"batb":[[0,1.76,5],[1,1.75,20.83],[2,1.69,55.71]],"ltp":1.8,"tv":47.25,"id":247649},{"batb":[[0,2.28,5],[1,2.26,30.51],[2,1.2,125]],"ltp":2.26,"tv":31.58,"id":8858694}]}]}
{"op":"mcm","clk":"11936319405","pt":1724677098012,"mc":[{"id":"1.232298775","rc":[{"batb":[[0,1.75,20.83],[1,1.69,55.71],[2,1.2,125]],"ltp":1.8,"tv":47.25,"id":247649},{"batb":[[0,2.26,30.51],[1,1.2,125],[2,1.04,1614.32]],"ltp":2.26,"tv":31.58,"id":8858694}]}]}
{"op":"mcm","clk":"11936319671","pt":1724677101224,"mc":[{"id":"1.232298775","rc":[{"batb":[[0,1.76,5],[1,1.75,20.83],[2,1.69,55.71]],"ltp":1.8,"tv":47.25,"id":247649},{"batb":[[0,2.28,5],[1,2.26,30.51],[2,1.2,125]],"ltp":2.26,"tv":31.58,"id":8858694}]}]}
{"op":"mcm","clk":"11936319964","pt":1724677104391,"mc":[{"id":"1.232298775","rc":[{"batb":[[0,1.75,20.83],[1,1.69,55.71],[2,1.2,125]],"ltp":1.8,"tv":47.25,"id":247649},{"batb":[[0,2.26,30.51],[1,1.2,125],[2,1.04,1614.32]],"ltp":2.26,"tv":31.58,"id":8858694}]}]}
{"op":"mcm","clk":"11936322333","pt":1724677133770,"mc":[{"id":"1.232298775","rc":[{"batb":[[0,1.76,5],[1,1.75,20.83],[2,1.69,55.71]],"ltp":1.8,"tv":47.25,"id":247649},{"batb":[[0,2.28,5],[1,2.26,30.51],[2,1.2,125]],"ltp":2.26,"tv":31.58,"id":8858694}]}]}
{"op":"mcm","clk":"11936322423","pt":1724677134860,"mc":[{"id":"1.232298775","rc":[{"batb":[[2,1.2,125]],"ltp":1.8,"tv":47.25,"id":247649},{"batb":[[1,1.2,125],[2,1.04,1614.32]],"ltp":2.26,"tv":31.58,"id":8858694}]}]}
{"op":"mcm","clk":"11936322608","pt":1724677137087,"mc":[{"id":"1.232298775","rc":[{"batb":[[0,1.75,20.83],[1,1.2,125],[2,1.05,5.19]],"ltp":1.8,"tv":47.25,"id":247649},{"batb":[[0,1.2,125],[1,1.04,1614.32],[2,1.03,2336.63]],"ltp":2.26,"tv":31.58,"id":8858694}]}]}
{"op":"mcm","clk":"11936322843","pt":1724677139779,"mc":[{"id":"1.232298775","rc":[{"batb":[[1,1.69,55.71],[2,1.2,125]],"ltp":1.8,"tv":47.25,"id":247649},{"batb":[[0,2.26,30.51],[1,1.2,125],[2,1.04,1614.32]],"ltp":2.26,"tv":31.58,"id":8858694}]}]}
{"op":"mcm","clk":"11936322855","pt":1724677139883,"mc":[{"id":"1.232298775","rc":[{"batb":[[0,1.76,5],[1,1.75,20.83],[2,1.69,55.71]],"ltp":1.8,"tv":47.25,"id":247649},{"batb":[[0,2.28,5],[1,2.26,30.51],[2,1.2,125]],"ltp":2.26,"tv":31.58,"id":8858694}]}]}
{"op":"mcm","clk":"11936323105","pt":1724677142991,"mc":[{"id":"1.232298775","rc":[{"batb":[[0,1.75,20.83],[1,1.69,55.71],[2,1.2,125]],"ltp":1.8,"tv":47.25,"id":247649},{"batb":[[0,2.26,30.51],[1,1.2,125],[2,1.04,1614.32]],"ltp":2.26,"tv":31.58,"id":8858694}]}]}
{"op":"mcm","clk":"11936323449","pt":1724677147283,"mc":[{"id":"1.232298775","rc":[{"batb":[[0,1.76,5],[1,1.75,20.83],[2,1.69,55.71]],"ltp":1.8,"tv":47.25,"id":247649},{"batb":[[0,2.28,5],[1,2.26,30.51],[2,1.2,125]],"ltp":2.26,"tv":31.58,"id":8858694}]}]}
{"op":"mcm","clk":"11936323710","pt":1724677150695,"mc":[{"id":"1.232298775","rc":[{"batb":[[0,1.75,20.83],[1,1.2,125],[2,1.05,5.19]],"ltp":1.8,"tv":47.25,"id":247649},{"batb":[[0,1.2,125],[1,1.04,1614.32],[2,1.03,2336.63]],"ltp":2.26,"tv":31.58,"id":8858694}]}]}
{"op":"mcm","clk":"11936324063","pt":1724677154997,"mc":[{"id":"1.232298775","rc":[{"batb":[[0,1.76,5],[1,1.75,20.83],[2,1.69,55.71]],"ltp":1.8,"tv":47.25,"id":247649},{"batb":[[0,2.28,5],[1,2.26,30.51],[2,1.2,125]],"ltp":2.26,"tv":31.58,"id":8858694}]}]}
{"op":"mcm","clk":"11936324338","pt":1724677158211,"mc":[{"id":"1.232298775","rc":[{"batb":[[0,1.75,20.83],[1,1.69,55.71],[2,1.2,125]],"ltp":1.8,"tv":47.25,"id":247649},{"batb":[[0,2.26,30.51],[1,1.2,125],[2,1.04,1614.32]],"ltp":2.26,"tv":31.58,"id":8858694}]}]}
{"op":"mcm","clk":"11936325293","pt":1724677171694,"mc":[{"id":"1.232298775","rc":[{"trd":[[1.8,40.35]],"batb":[[0,1.76,5],[1,1.75,20.83],[2,1.69,55.71]],"ltp":1.8,"tv":85.25,"id":247649},{"trd":[[2.26,33.16]],"batb":[[0,1.21,5.24]],"ltp":2.26,"tv":61.85,"id":8858694}],"tv":147.1}]}
{"op":"mcm","clk":"11936325543","pt":1724677175200,"mc":[{"id":"1.232298775","rc":[{"batb":[[0,1.75,20.83],[1,1.69,55.71],[2,1.2,125]],"ltp":1.8,"tv":85.25,"id":247649},{"batb":[[0,2.18,32.58]],"ltp":2.26,"tv":61.85,"id":8858694}]}]}
{"op":"mcm","clk":"11936326425","pt":1724677188720,"mc":[{"id":"1.232298775","rc":[{"batb":[[0,1.76,5],[1,1.75,20.83],[2,1.69,55.71]],"ltp":1.8,"tv":85.25,"id":247649},{"batb":[[0,2.2,5],[1,2.18,32.58],[2,1.2,125]],"ltp":2.26,"tv":61.85,"id":8858694}]}]}
{"op":"mcm","clk":"11936326665","pt":1724677192136,"mc":[{"id":"1.232298775","rc":[{"batb":[[0,1.75,20.83],[1,1.69,55.71],[2,1.2,125]],"ltp":1.8,"tv":85.25,"id":247649},{"batb":[[0,2.18,32.58],[1,1.2,125],[2,1.04,1614.32]],"ltp":2.26,"tv":61.85,"id":8858694}]}]}
{"op":"mcm","clk":"11936327771","pt":1724677204451,"mc":[{"id":"1.232298775","rc":[{"batb":[[0,1.76,5],[1,1.75,20.83],[2,1.69,55.71]],"batl":[[0,2.24,17.62],[2,3.4,35.24]],"ltp":1.8,"tv":85.25,"id":247649},{"batb":[[0,2.2,5],[1,2.18,32.58],[2,2,34]],"ltp":2.26,"tv":61.85,"id":8858694}]}]}
{"op":"mcm","clk":"11936328090","pt":1724677207781,"mc":[{"id":"1.232298775","rc":[{"batb":[[0,1.75,20.83],[1,1.69,55.71],[2,1.2,125]],"ltp":1.8,"tv":85.25,"id":247649},{"batb":[[0,2.18,32.58],[1,2,34],[2,1.2,125]],"ltp":2.26,"tv":61.85,"id":8858694}]}]}
{"op":"mcm","clk":"11936328340","pt":1724677210747,"mc":[{"id":"1.232298775","rc":[{"batb":[[0,1.76,5],[1,1.75,20.83],[2,1.69,55.71]],"ltp":1.8,"tv":85.25,"id":247649},{"batb":[[0,2.2,5],[1,2.18,32.58],[2,2,34]],"ltp":2.26,"tv":61.85,"id":8858694}]}]}
{"op":"mcm","clk":"11936328618","pt":1724677214173,"mc":[{"id":"1.232298775","rc":[{"batb":[[0,1.75,20.83],[1,1.69,55.71],[2,1.2,125]],"ltp":1.8,"tv":85.25,"id":247649},{"batb":[[0,2.18,32.58],[1,2,34],[2,1.2,125]],"ltp":2.26,"tv":61.85,"id":8858694}]}]}
{"op":"mcm","clk":"11936330810","pt":1724677239915,"mc":[{"id":"1.232298775","rc":[{"batb":[[0,1.76,5],[1,1.75,20.83],[2,1.69,55.71]],"ltp":1.8,"tv":85.25,"id":247649},{"batb":[[0,2.2,5],[1,2.18,32.58],[2,2,34]],"ltp":2.26,"tv":61.85,"id":8858694}]}]}
{"op":"mcm","clk":"11936331111","pt":1724677243298,"mc":[{"id":"1.232298775","rc":[{"batb":[[0,1.75,20.83],[1,1.69,55.71],[2,1.2,125]],"ltp":1.8,"tv":85.25,"id":247649},{"batb":[[0,2.18,32.58],[1,2,34],[2,1.2,125]],"ltp":2.26,"tv":61.85,"id":8858694}]}]}
{"op":"mcm","clk":"11936332510","pt":1724677260863,"mc":[{"id":"1.232298775","rc":[{"batb":[[0,1.76,5],[1,1.75,20.83],[2,1.69,55.71]],"ltp":1.8,"tv":85.25,"id":247649},{"batb":[[0,2.2,5],[1,2.18,32.58],[2,2,34]],"ltp":2.26,"tv":61.85,"id":8858694}]}]}
{"op":"mcm","clk":"11936332806","pt":1724677264230,"mc":[{"id":"1.232298775","rc":[{"batb":[[0,1.75,20.83],[1,1.69,55.71],[2,1.2,125]],"ltp":1.8,"tv":85.25,"id":247649},{"batb":[[0,2.18,32.58],[1,2,34],[2,1.2,125]],"ltp":2.26,"tv":61.85,"id":8858694}]}]}
{"op":"mcm","clk":"11936334833","pt":1724677287873,"mc":[{"id":"1.232298775","rc":[{"batb":[[0,1.76,5],[1,1.75,20.83],[2,1.69,55.71]],"ltp":1.8,"tv":85.25,"id":247649},{"batb":[[0,2.2,5],[1,2.18,32.58],[2,2,34]],"ltp":2.26,"tv":61.85,"id":8858694}]}]}
{"op":"mcm","clk":"11936335127","pt":1724677291367,"mc":[{"id":"1.232298775","rc":[{"batb":[[0,1.75,20.83],[1,1.69,55.71],[2,1.2,125]],"ltp":1.8,"tv":85.25,"id":247649},{"batb":[[0,2.18,32.58],[1,2,34],[2,1.2,125]],"ltp":2.26,"tv":61.85,"id":8858694}]}]}
{"op":"mcm","clk":"11936335361","pt":1724677293565,"mc":[{"id":"1.232298775","rc":[{"batb":[[0,1.76,5],[1,1.75,20.83],[2,1.69,55.71]],"ltp":1.8,"tv":85.25,"id":247649},{"batb":[[0,2.2,5],[1,2.18,32.58],[2,2,34]],"ltp":2.26,"tv":61.85,"id":8858694}]}]}
{"op":"mcm","clk":"11936335663","pt":1724677296961,"mc":[{"id":"1.232298775","rc":[{"batb":[[0,1.75,20.83],[1,1.69,55.71],[2,1.2,125]],"ltp":1.8,"tv":85.25,"id":247649},{"batb":[[0,2.18,32.58],[1,2,34],[2,1.2,125]],"ltp":2.26,"tv":61.85,"id":8858694}]}]}
{"op":"mcm","clk":"11936336670","pt":1724677307788,"mc":[{"id":"1.232298775","rc":[{"batb":[[0,1.76,5],[1,1.75,20.83],[2,1.69,55.71]],"ltp":1.8,"tv":85.25,"id":247649},{"batb":[[0,2.2,5],[1,2.18,32.58],[2,2,34]],"ltp":2.26,"tv":61.85,"id":8858694}]}]}
{"op":"mcm","clk":"11936336930","pt":1724677311217,"mc":[{"id":"1.232298775","rc":[{"batb":[[0,1.75,20.83],[1,1.69,55.71],[2,1.2,125]],"ltp":1.8,"tv":85.25,"id":247649},{"batb":[[0,2.18,32.58],[1,2,34],[2,1.2,125]],"ltp":2.26,"tv":61.85,"id":8858694}]}]}
{"op":"mcm","clk":"11936340854","pt":1724677358068,"mc":[{"id":"1.232298775","rc":[{"batb":[[0,1.76,5],[1,1.75,20.83],[2,1.69,55.71]],"ltp":1.8,"tv":85.25,"id":247649},{"batb":[[0,2.2,5],[1,2.18,32.58],[2,2,34]],"ltp":2.26,"tv":61.85,"id":8858694}]}]}
{"op":"mcm","clk":"11936341137","pt":1724677361444,"mc":[{"id":"1.232298775","rc":[{"batb":[[0,1.75,20.83],[1,1.69,55.71],[2,1.2,125]],"ltp":1.8,"tv":85.25,"id":247649},{"batb":[[0,2.18,32.58],[1,2,34],[2,1.2,125]],"ltp":2.26,"tv":61.85,"id":8858694}]}]}
{"op":"mcm","clk":"11936345528","pt":1724677413327,"mc":[{"id":"1.232298775","rc":[{"batb":[[0,1.76,5],[1,1.75,20.83],[2,1.69,55.71]],"ltp":1.8,"tv":85.25,"id":247649},{"batb":[[0,2.2,5],[1,2.18,32.58],[2,2,34]],"ltp":2.26,"tv":61.85,"id":8858694}]}]}
{"op":"mcm","clk":"11936345833","pt":1724677416709,"mc":[{"id":"1.232298775","rc":[{"batb":[[0,1.75,20.83],[1,1.69,55.71],[2,1.2,125]],"ltp":1.8,"tv":85.25,"id":247649},{"batb":[[0,2.18,32.58],[1,2,34],[2,1.2,125]],"ltp":2.26,"tv":61.85,"id":8858694}]}]}
{"op":"mcm","clk":"11936346058","pt":1724677419088,"mc":[{"id":"1.232298775","rc":[{"batb":[[0,1.76,5],[1,1.75,20.83],[2,1.69,55.71]],"ltp":1.8,"tv":85.25,"id":247649},{"batb":[[0,2.2,5],[1,2.18,32.58],[2,2,34]],"ltp":2.26,"tv":61.85,"id":8858694}]}]}
{"op":"mcm","clk":"11936346384","pt":1724677422393,"mc":[{"id":"1.232298775","rc":[{"batb":[[0,1.75,20.83],[1,1.69,55.71],[2,1.2,125]],"ltp":1.8,"tv":85.25,"id":247649},{"batb":[[0,2.18,32.58],[1,2,34],[2,1.2,125]],"ltp":2.26,"tv":61.85,"id":8858694}]}]}
{"op":"mcm","clk":"11936346819","pt":1724677427507,"mc":[{"id":"1.232298775","rc":[{"batb":[[0,1.76,5],[1,1.75,20.83],[2,1.69,55.71]],"ltp":1.8,"tv":85.25,"id":247649},{"batb":[[0,2.2,5],[1,2.18,32.58],[2,2,34]],"ltp":2.26,"tv":61.85,"id":8858694}]}]}
{"op":"mcm","clk":"11936347125","pt":1724677430825,"mc":[{"id":"1.232298775","rc":[{"batb":[[0,1.75,20.83],[1,1.69,55.71],[2,1.2,125]],"ltp":1.8,"tv":85.25,"id":247649},{"batb":[[0,2.18,32.58],[1,2,34],[2,1.2,125]],"ltp":2.26,"tv":61.85,"id":8858694}]}]}
{"op":"mcm","clk":"11936351947","pt":1724677486288,"mc":[{"id":"1.232298775","rc":[{"batb":[[0,1.76,5],[1,1.75,20.83],[2,1.69,55.71]],"ltp":1.8,"tv":85.25,"id":247649},{"batb":[[0,2.2,5],[1,2.18,32.58],[2,2,34]],"ltp":2.26,"tv":61.85,"id":8858694}]}]}
{"op":"mcm","clk":"11936352199","pt":1724677489660,"mc":[{"id":"1.232298775","rc":[{"batb":[[0,1.75,20.83],[1,1.69,55.71],[2,1.2,125]],"ltp":1.8,"tv":85.25,"id":247649},{"batb":[[0,2.18,32.58],[1,2,34],[2,1.2,125]],"ltp":2.26,"tv":61.85,"id":8858694}]}]}
{"op":"mcm","clk":"11936357511","pt":1724677551066,"mc":[{"id":"1.232298775","rc":[{"batb":[[0,1.76,5],[1,1.75,20.83],[2,1.69,55.71]],"ltp":1.8,"tv":85.25,"id":247649},{"batb":[[0,2.2,5],[1,2.18,32.58],[2,2,34]],"ltp":2.26,"tv":61.85,"id":8858694}]}]}
{"op":"mcm","clk":"11936357822","pt":1724677554580,"mc":[{"id":"1.232298775","rc":[{"batb":[[0,1.75,20.83],[1,1.69,55.71],[2,1.2,125]],"ltp":1.8,"tv":85.25,"id":247649},{"batb":[[0,2.18,32.58],[1,2,34],[2,1.2,125]],"ltp":2.26,"tv":61.85,"id":8858694}]}]}
{"op":"mcm","clk":"11936358346","pt":1724677560663,"mc":[{"id":"1.232298775","rc":[{"batb":[[0,1.76,5],[1,1.75,20.83],[2,1.69,55.71]],"ltp":1.8,"tv":85.25,"id":247649},{"batb":[[0,2.2,5],[1,2.18,32.58],[2,2,34]],"ltp":2.26,"tv":61.85,"id":8858694}]}]}
{"op":"mcm","clk":"11936358679","pt":1724677563900,"mc":[{"id":"1.232298775","rc":[{"batb":[[0,1.75,20.83],[1,1.69,55.71],[2,1.2,125]],"ltp":1.8,"tv":85.25,"id":247649},{"batb":[[0,2.18,32.58],[1,2,34],[2,1.2,125]],"ltp":2.26,"tv":61.85,"id":8858694}]}]}
{"op":"mcm","clk":"11936359213","pt":1724677569617,"mc":[{"id":"1.232298775","rc":[{"batb":[[0,1.76,5],[1,1.75,20.83],[2,1.69,55.71]],"ltp":1.8,"tv":85.25,"id":247649},{"batb":[[0,2.2,5],[1,2.18,32.58],[2,2,34]],"ltp":2.26,"tv":61.85,"id":8858694}]}]}
{"op":"mcm","clk":"11936359502","pt":1724677572926,"mc":[{"id":"1.232298775","rc":[{"batb":[[0,1.75,20.83],[1,1.69,55.71],[2,1.2,125]],"ltp":1.8,"tv":85.25,"id":247649},{"batb":[[0,2.18,32.58],[1,2,34],[2,1.2,125]],"ltp":2.26,"tv":61.85,"id":8858694}]}]}
{"op":"mcm","clk":"11936360166","pt":1724677579839,"mc":[{"id":"1.232298775","rc":[{"batb":[[0,1.76,5],[1,1.75,20.83],[2,1.69,55.71]],"ltp":1.8,"tv":85.25,"id":247649},{"batb":[[0,2.2,5],[1,2.18,32.58],[2,2,34]],"ltp":2.26,"tv":61.85,"id":8858694}]}]}
{"op":"mcm","clk":"11936360493","pt":1724677583306,"mc":[{"id":"1.232298775","rc":[{"batb":[[0,1.75,20.83],[1,1.69,55.71],[2,1.2,125]],"ltp":1.8,"tv":85.25,"id":247649},{"batb":[[0,2.18,32.58],[1,2,34],[2,1.2,125]],"ltp":2.26,"tv":61.85,"id":8858694}]}]}
{"op":"mcm","clk":"11936360811","pt":1724677586528,"mc":[{"id":"1.232298775","rc":[{"batb":[[0,1.76,5],[1,1.75,20.83],[2,1.69,55.71]],"ltp":1.8,"tv":85.25,"id":247649},{"batb":[[0,2.2,5],[1,2.18,32.58],[2,2,34]],"ltp":2.26,"tv":61.85,"id":8858694}]}]}
{"op":"mcm","clk":"11936361128","pt":1724677589842,"mc":[{"id":"1.232298775","rc":[{"batb":[[0,1.75,20.83],[1,1.69,55.71],[2,1.2,125]],"ltp":1.8,"tv":85.25,"id":247649},{"batb":[[0,2.18,32.58],[1,2,34],[2,1.2,125]],"ltp":2.26,"tv":61.85,"id":8858694}]}]}
{"op":"mcm","clk":"11936364184","pt":1724677623649,"mc":[{"id":"1.232298775","rc":[{"batb":[[0,1.76,5],[1,1.75,20.83],[2,1.69,55.71]],"ltp":1.8,"tv":85.25,"id":247649},{"batb":[[0,2.2,5],[1,2.18,32.58],[2,2,34]],"ltp":2.26,"tv":61.85,"id":8858694}]}]}
{"op":"mcm","clk":"11936364460","pt":1724677626871,"mc":[{"id":"1.232298775","rc":[{"batb":[[0,1.75,20.83],[1,1.69,55.71],[2,1.2,125]],"ltp":1.8,"tv":85.25,"id":247649},{"batb":[[0,2.18,32.58],[1,2,34],[2,1.2,125]],"ltp":2.26,"tv":61.85,"id":8858694}]}]}
{"op":"mcm","clk":"11936366114","pt":1724677646440,"mc":[{"id":"1.232298775","rc":[{"batb":[[0,1.76,5],[1,1.75,20.83],[2,1.69,55.71]],"ltp":1.8,"tv":85.25,"id":247649},{"batb":[[0,2.2,5],[1,2.18,32.58],[2,2,34]],"ltp":2.26,"tv":61.85,"id":8858694}]}]}
{"op":"mcm","clk":"11936366396","pt":1724677649693,"mc":[{"id":"1.232298775","rc":[{"batb":[[0,1.75,20.83],[1,1.69,55.71],[2,1.2,125]],"ltp":1.8,"tv":85.25,"id":247649},{"batb":[[0,2.18,32.58],[1,2,34],[2,1.2,125]],"ltp":2.26,"tv":61.85,"id":8858694}]}]}
{"op":"mcm","clk":"11936367798","pt":1724677664147,"mc":[{"id":"1.232298775","rc":[{"batb":[[0,1.76,5],[1,1.75,20.83],[2,1.69,55.71]],"ltp":1.8,"tv":85.25,"id":247649},{"batb":[[0,2.2,5],[1,2.18,32.58],[2,2,34]],"ltp":2.26,"tv":61.85,"id":8858694}]}]}
{"op":"mcm","clk":"11936368113","pt":1724677667566,"mc":[{"id":"1.232298775","rc":[{"batb":[[0,1.75,20.83],[1,1.69,55.71],[2,1.2,125]],"ltp":1.8,"tv":85.25,"id":247649},{"batb":[[0,2.18,32.58],[1,2,34],[2,1.2,125]],"ltp":2.26,"tv":61.85,"id":8858694}]}]}
{"op":"mcm","clk":"11936368666","pt":1724677673336,"mc":[{"id":"1.232298775","rc":[{"batb":[[0,1.76,5],[1,1.75,20.83],[2,1.69,55.71]],"ltp":1.8,"tv":85.25,"id":247649},{"batb":[[0,2.2,5],[1,2.18,32.58],[2,2,34]],"ltp":2.26,"tv":61.85,"id":8858694}]}]}
{"op":"mcm","clk":"11936368962","pt":1724677676763,"mc":[{"id":"1.232298775","rc":[{"batb":[[0,1.75,20.83],[1,1.69,55.71],[2,1.2,125]],"ltp":1.8,"tv":85.25,"id":247649},{"batb":[[0,2.18,32.58],[1,2,34],[2,1.2,125]],"ltp":2.26,"tv":61.85,"id":8858694}]}]}
{"op":"mcm","clk":"11936369798","pt":1724677686369,"mc":[{"id":"1.232298775","rc":[{"batb":[[0,1.76,5],[1,1.75,20.83],[2,1.69,55.71]],"ltp":1.8,"tv":85.25,"id":247649},{"batb":[[0,2.2,5],[1,2.18,32.58],[2,2,34]],"ltp":2.26,"tv":61.85,"id":8858694}]}]}
{"op":"mcm","clk":"11936370094","pt":1724677689757,"mc":[{"id":"1.232298775","rc":[{"batb":[[0,1.75,20.83],[1,1.69,55.71],[2,1.2,125]],"ltp":1.8,"tv":85.25,"id":247649},{"batb":[[0,2.18,32.58],[1,2,34],[2,1.2,125]],"ltp":2.26,"tv":61.85,"id":8858694}]}]}
{"op":"mcm","clk":"11936372260","pt":1724677714384,"mc":[{"id":"1.232298775","rc":[{"batb":[[0,1.76,5],[1,1.75,20.83],[2,1.69,55.71]],"ltp":1.8,"tv":85.25,"id":247649},{"batb":[[0,2.2,5],[1,2.18,32.58],[2,2,34]],"ltp":2.26,"tv":61.85,"id":8858694}]}]}
{"op":"mcm","clk":"11936372528","pt":1724677717713,"mc":[{"id":"1.232298775","rc":[{"batb":[[0,1.75,20.83],[1,1.69,55.71],[2,1.2,125]],"ltp":1.8,"tv":85.25,"id":247649},{"batb":[[0,2.18,32.58],[1,2,34],[2,1.2,125]],"ltp":2.26,"tv":61.85,"id":8858694}]}]}
{"op":"mcm","clk":"11936375015","pt":1724677747041,"mc":[{"id":"1.232298775","rc":[{"trd":[[1.76,11.54]],"batb":[[1,1.7,54.92]],"ltp":1.76,"tv":90.25,"id":247649},{"trd":[[2.32,3.79]],"batb":[[0,2.32,1.21],[1,2.3,29.57],[2,2,34]],"ltp":2.32,"tv":65.64,"id":8858694}],"tv":155.89}]}
{"op":"mcm","clk":"11936375310","pt":1724677750369,"mc":[{"id":"1.232298775","rc":[{"batb":[[0,1.76,5],[1,1.75,20.83],[2,1.7,54.92]],"ltp":1.76,"tv":90.25,"id":247649},{"batb":[[0,2.3,29.57],[1,2,34],[2,1.2,125]],"ltp":2.32,"tv":65.64,"id":8858694}]}]}
{"op":"mcm","clk":"11936375619","pt":1724677753742,"mc":[{"id":"1.232298775","rc":[{"batb":[[0,1.75,20.83],[1,1.7,54.92],[2,1.2,125]],"ltp":1.76,"tv":90.25,"id":247649},{"batb":[[0,2.32,5],[1,2.3,29.57],[2,2,34]],"ltp":2.32,"tv":65.64,"id":8858694}]}]}
{"op":"mcm","clk":"11936375886","pt":1724677757157,"mc":[{"id":"1.232298775","rc":[{"batb":[[0,1.76,5],[1,1.75,20.83]],"ltp":1.76,"tv":90.25,"id":247649},{"batb":[[0,2,34],[1,1.2,125],[2,1.04,1612.41]],"ltp":2.32,"tv":65.64,"id":8858694}]}]}
{"op":"mcm","clk":"11936376135","pt":1724677760455,"mc":[{"id":"1.232298775","rc":[{"batb":[[0,1.75,20.83],[1,1.2,125],[2,1.05,5.19]],"ltp":1.76,"tv":90.25,"id":247649},{"batb":[[0,2.02,5],[1,2,34],[2,1.2,125]],"ltp":2.32,"tv":65.64,"id":8858694}]}]}
{"op":"mcm","clk":"11936376239","pt":1724677762098,"mc":[{"id":"1.232298775","rc":[{"batb":[[1,1.7,54.92],[2,1.2,125]],"ltp":1.76,"tv":90.25,"id":247649},{"batb":[[0,2.3,29.57],[1,2.02,5],[2,2,34]],"ltp":2.32,"tv":65.64,"id":8858694}]}]}
{"op":"mcm","clk":"11936376425","pt":1724677764045,"mc":[{"id":"1.232298775","rc":[{"batb":[[0,1.76,5],[1,1.75,20.83],[2,1.7,54.92]],"ltp":1.76,"tv":90.25,"id":247649},{"batb":[[1,2,34],[2,1.2,125]],"ltp":2.32,"tv":65.64,"id":8858694}]}]}
{"op":"mcm","clk":"11936376652","pt":1724677766736,"mc":[{"id":"1.232298775","rc":[{"trd":[[1.76,16.54]],"batb":[[0,1.75,20.83],[1,1.7,54.92],[2,1.2,125]],"ltp":1.76,"tv":95.25,"id":247649},{"trd":[[2.32,7.58]],"batb":[[0,2.32,1.21],[1,2.3,29.57],[2,2,34]],"ltp":2.32,"tv":69.43,"id":8858694}],"tv":164.68}]}
{"op":"mcm","clk":"11936377026","pt":1724677770264,"mc":[{"id":"1.232298775","rc":[{"batb":[[0,1.76,5],[1,1.75,20.83],[2,1.7,54.92]],"ltp":1.76,"tv":95.25,"id":247649},{"batb":[[0,2.3,29.57],[1,2,34],[2,1.2,125]],"ltp":2.32,"tv":69.43,"id":8858694}]}]}
{"op":"mcm","clk":"11936377348","pt":1724677773793,"mc":[{"id":"1.232298775","rc":[{"batb":[[0,1.75,20.83],[1,1.7,54.92],[2,1.2,125]],"ltp":1.76,"tv":95.25,"id":247649},{"batb":[[0,2.32,5],[1,2.3,29.57],[2,2,34]],"ltp":2.32,"tv":69.43,"id":8858694}]}]}
{"op":"mcm","clk":"11936377658","pt":1724677777252,"mc":[{"id":"1.232298775","rc":[{"batb":[[0,1.76,5],[1,1.75,20.83]],"ltp":1.76,"tv":95.25,"id":247649},{"batb":[[0,2,34],[1,1.2,125],[2,1.04,1612.41]],"ltp":2.32,"tv":69.43,"id":8858694}]}]}
{"op":"mcm","clk":"11936377933","pt":1724677780561,"mc":[{"id":"1.232298775","rc":[{"batb":[[0,1.75,20.83],[1,1.2,125],[2,1.05,5.19]],"ltp":1.76,"tv":95.25,"id":247649},{"batb":[[0,2.02,5],[1,2,34],[2,1.2,125]],"ltp":2.32,"tv":69.43,"id":8858694}]}]}
{"op":"mcm","clk":"11936378074","pt":1724677782161,"mc":[{"id":"1.232298775","rc":[{"batb":[[1,1.7,54.92],[2,1.2,125]],"ltp":1.76,"tv":95.25,"id":247649},{"batb":[[0,2.3,29.57],[1,2.02,5],[2,2,34]],"ltp":2.32,"tv":69.43,"id":8858694}]}]}
{"op":"mcm","clk":"11936378224","pt":1724677783875,"mc":[{"id":"1.232298775","rc":[{"batb":[[1,2,34],[2,1.2,125]],"ltp":2.32,"tv":69.43,"id":8858694}]}]}
{"op":"mcm","clk":"11936378234","pt":1724677783981,"mc":[{"id":"1.232298775","rc":[{"batb":[[0,1.76,5],[1,1.75,20.83],[2,1.7,54.92]],"ltp":1.76,"tv":95.25,"id":247649}]}]}
{"op":"mcm","clk":"11936378547","pt":1724677787305,"mc":[{"id":"1.232298775","rc":[{"batb":[[0,1.75,20.83],[1,1.7,54.92],[2,1.2,125]],"ltp":1.76,"tv":95.25,"id":247649},{"batb":[[0,2.32,5],[1,2.3,29.57],[2,2,34]],"ltp":2.32,"tv":69.43,"id":8858694}]}]}
{"op":"mcm","clk":"11936378791","pt":1724677790460,"mc":[{"id":"1.232298775","rc":[{"batb":[[0,1.76,5],[1,1.75,20.83],[2,1.7,54.92]],"ltp":1.76,"tv":95.25,"id":247649},{"batb":[[0,2.3,29.57],[1,2,34],[2,1.2,125]],"ltp":2.32,"tv":69.43,"id":8858694}]}]}
{"op":"mcm","clk":"11936379054","pt":1724677793780,"mc":[{"id":"1.232298775","rc":[{"batb":[[0,1.75,20.83],[1,1.7,54.92],[2,1.2,125]],"ltp":1.76,"tv":95.25,"id":247649}]}]}
{"op":"mcm","clk":"11936379068","pt":1724677793882,"mc":[{"id":"1.232298775","rc":[{"batb":[[0,2.32,5],[1,2.3,29.57],[2,2,34]],"ltp":2.32,"tv":69.43,"id":8858694}]}]}
{"op":"mcm","clk":"11936379400","pt":1724677797303,"mc":[{"id":"1.232298775","rc":[{"batb":[[0,1.76,5],[1,1.75,20.83]],"ltp":1.76,"tv":95.25,"id":247649},{"batb":[[0,2,34],[1,1.2,125],[2,1.04,1612.41]],"ltp":2.32,"tv":69.43,"id":8858694}]}]}
{"op":"mcm","clk":"11936379735","pt":1724677800690,"mc":[{"id":"1.232298775","rc":[{"batb":[[0,1.75,20.83],[1,1.2,125],[2,1.05,5.19]],"ltp":1.76,"tv":95.25,"id":247649},{"batb":[[0,2.02,5],[1,2,34],[2,1.2,125]],"ltp":2.32,"tv":69.43,"id":8858694}]}]}
{"op":"mcm","clk":"11936379891","pt":1724677802203,"mc":[{"id":"1.232298775","rc":[{"batb":[[1,1.7,54.92],[2,1.2,125]],"ltp":1.76,"tv":95.25,"id":247649},{"batb":[[0,2.3,29.57],[1,2.02,5],[2,2,34]],"ltp":2.32,"tv":69.43,"id":8858694}]}]}
{"op":"mcm","clk":"11936380069","pt":1724677803983,"mc":[{"id":"1.232298775","rc":[{"batb":[[0,1.76,5],[1,1.75,20.83],[2,1.7,54.92]],"ltp":1.76,"tv":95.25,"id":247649},{"batb":[[1,2,34],[2,1.2,125]],"ltp":2.32,"tv":69.43,"id":8858694}]}]}
{"op":"mcm","clk":"11936380433","pt":1724677807424,"mc":[{"id":"1.232298775","rc":[{"batb":[[0,1.75,20.83],[1,1.7,54.92],[2,1.2,125]],"ltp":1.76,"tv":95.25,"id":247649},{"batb":[[0,2.32,5],[1,2.3,29.57],[2,2,34]],"ltp":2.32,"tv":69.43,"id":8858694}]}]}
{"op":"mcm","clk":"11936380657","pt":1724677809506,"mc":[{"id":"1.232298775","rc":[{"trd":[[1.76,21.54]],"ltp":1.76,"tv":100.25,"id":247649},{"trd":[[2.32,11.37]],"batb":[[0,2.32,1.21]],"ltp":2.32,"tv":73.22,"id":8858694}],"tv":173.47}]}
{"op":"mcm","clk":"11936380784","pt":1724677810708,"mc":[{"id":"1.232298775","rc":[{"batb":[[0,2.3,29.57],[1,2,34],[2,1.2,125]],"ltp":2.32,"tv":73.22,"id":8858694}]}]}
{"op":"mcm","clk":"11936383402","pt":1724677837490,"mc":[{"id":"1.232298775","rc":[{"trd":[[1.76,26.54]],"ltp":1.76,"tv":105.25,"id":247649},{"trd":[[2.32,15.16]],"batb":[[0,2.32,1.21],[1,2.3,29.57],[2,2,34]],"ltp":2.32,"tv":77.01,"id":8858694}],"tv":182.26}]}
{"op":"mcm","clk":"11936383674","pt":1724677840773,"mc":[{"id":"1.232298775","rc":[{"batb":[[0,1.76,5],[1,1.75,20.83],[2,1.7,54.92]],"ltp":1.76,"tv":105.25,"id":247649},{"batb":[[0,2.3,29.57],[1,2,34],[2,1.2,125]],"ltp":2.32,"tv":77.01,"id":8858694}]}]}
{"op":"mcm","clk":"11936383975","pt":1724677844063,"mc":[{"id":"1.232298775","rc":[{"batb":[[0,1.75,20.83],[1,1.7,54.92],[2,1.2,125]],"ltp":1.76,"tv":105.25,"id":247649},{"batb":[[0,2.32,5],[1,2.3,29.57],[2,2,34]],"ltp":2.32,"tv":77.01,"id":8858694}]}]}
{"op":"mcm","clk":"11936384310","pt":1724677847549,"mc":[{"id":"1.232298775","rc":[{"batb":[[0,1.76,5],[1,1.75,20.83]],"ltp":1.76,"tv":105.25,"id":247649},{"batb":[[0,2,34],[1,1.2,125],[2,1.04,1612.41]],"ltp":2.32,"tv":77.01,"id":8858694}]}]}
{"op":"mcm","clk":"11936384603","pt":1724677850777,"mc":[{"id":"1.232298775","rc":[{"batb":[[0,1.75,20.83],[1,1.2,125],[2,1.05,5.19]],"ltp":1.76,"tv":105.25,"id":247649},{"batb":[[0,2.02,5],[1,2,34],[2,1.2,125]],"ltp":2.32,"tv":77.01,"id":8858694}]}]}
{"op":"mcm","clk":"11936384742","pt":1724677852391,"mc":[{"id":"1.232298775","rc":[{"batb":[[1,1.7,54.92],[2,1.2,125]],"ltp":1.76,"tv":105.25,"id":247649},{"batb":[[0,2.3,29.57],[1,2.02,5],[2,2,34]],"ltp":2.32,"tv":77.01,"id":8858694}]}]}
{"op":"mcm","clk":"11936384900","pt":1724677854364,"mc":[{"id":"1.232298775","rc":[{"batb":[[0,1.76,5],[1,1.75,20.83],[2,1.7,54.92]],"ltp":1.76,"tv":105.25,"id":247649},{"batb":[[1,2,34],[2,1.2,125]],"ltp":2.32,"tv":77.01,"id":8858694}]}]}
{"op":"mcm","clk":"11936385251","pt":1724677857760,"mc":[{"id":"1.232298775","rc":[{"batb":[[0,1.75,20.83],[1,1.7,54.92],[2,1.2,125]],"ltp":1.76,"tv":105.25,"id":247649},{"batb":[[0,2.32,5],[1,2.3,29.57],[2,2,34]],"ltp":2.32,"tv":77.01,"id":8858694}]}]}
{"op":"mcm","clk":"11936385600","pt":1724677861265,"mc":[{"id":"1.232298775","rc":[{"batb":[[0,1.76,5],[1,1.75,20.83],[2,1.7,54.92]],"ltp":1.76,"tv":105.25,"id":247649},{"batb":[[0,2.3,29.57],[1,2,34],[2,1.2,125]],"ltp":2.32,"tv":77.01,"id":8858694}]}]}
{"op":"mcm","clk":"11936386005","pt":1724677864761,"mc":[{"id":"1.232298775","rc":[{"batb":[[0,1.75,20.83],[1,1.7,54.92],[2,1.2,125]],"ltp":1.76,"tv":105.25,"id":247649},{"batb":[[0,2.32,5],[1,2.3,29.57],[2,2,34]],"ltp":2.32,"tv":77.01,"id":8858694}]}]}
{"op":"mcm","clk":"11936386300","pt":1724677867676,"mc":[{"id":"1.232298775","rc":[{"trd":[[1.76,31.54]],"batb":[[1,1.2,125],[2,1.05,5.19]],"ltp":1.76,"tv":110.25,"id":247649},{"trd":[[2.32,18.95]],"batb":[[0,2.32,1.21],[1,2,34],[2,1.2,125]],"ltp":2.32,"tv":80.8,"id":8858694}],"tv":191.05}]}
{"op":"mcm","clk":"11936386347","pt":1724677868095,"mc":[{"id":"1.232298775","rc":[{"batb":[[0,2,34],[1,1.2,125],[2,1.04,1612.41]],"ltp":2.32,"tv":80.8,"id":8858694}]}]}
{"op":"mcm","clk":"11936386831","pt":1724677872579,"mc":[{"id":"1.232298775","rc":[{"trd":[[1.76,36.54]],"batb":[[1,1.7,54.92],[2,1.2,125]],"ltp":1.76,"tv":115.25,"id":247649},{"trd":[[2.32,22.74]],"batb":[[0,2.32,1.21],[1,2.3,29.57],[2,2,34]],"ltp":2.32,"tv":84.59,"id":8858694}],"tv":199.84}]}
{"op":"mcm","clk":"11936387178","pt":1724677876003,"mc":[{"id":"1.232298775","rc":[{"batb":[[0,1.76,5],[1,1.75,20.83],[2,1.7,54.92]],"ltp":1.76,"tv":115.25,"id":247649},{"batb":[[0,2.3,29.57],[1,2,34],[2,1.2,125]],"ltp":2.32,"tv":84.59,"id":8858694}]}]}
{"op":"mcm","clk":"11936387472","pt":1724677879373,"mc":[{"id":"1.232298775","rc":[{"batb":[[0,1.75,20.83],[1,1.7,54.92],[2,1.2,125]],"ltp":1.76,"tv":115.25,"id":247649},{"batb":[[0,2.32,5],[1,2.3,29.57],[2,2,34]],"ltp":2.32,"tv":84.59,"id":8858694}]}]}
{"op":"mcm","clk":"11936387743","pt":1724677882701,"mc":[{"id":"1.232298775","rc":[{"batb":[[0,1.76,5],[1,1.75,20.83]],"ltp":1.76,"tv":115.25,"id":247649},{"batb":[[0,2,34],[1,1.2,125],[2,1.04,1612.41]],"ltp":2.32,"tv":84.59,"id":8858694}]}]}
{"op":"mcm","clk":"11936387995","pt":1724677885976,"mc":[{"id":"1.232298775","rc":[{"batb":[[0,1.75,20.83],[1,1.2,125],[2,1.05,5.19]],"ltp":1.76,"tv":115.25,"id":247649},{"batb":[[0,2.02,5],[1,2,34],[2,1.2,125]],"ltp":2.32,"tv":84.59,"id":8858694}]}]}
{"op":"mcm","clk":"11936388093","pt":1724677887529,"mc":[{"id":"1.232298775","rc":[{"batb":[[1,1.7,54.92],[2,1.2,125]],"ltp":1.76,"tv":115.25,"id":247649},{"batb":[[0,2.3,29.57],[1,2.02,5],[2,2,34]],"ltp":2.32,"tv":84.59,"id":8858694}]}]}
{"op":"mcm","clk":"11936388257","pt":1724677889398,"mc":[{"id":"1.232298775","rc":[{"batb":[[0,1.76,5],[1,1.75,20.83],[2,1.7,54.92]],"ltp":1.76,"tv":115.25,"id":247649},{"batb":[[1,2,34],[2,1.2,125]],"ltp":2.32,"tv":84.59,"id":8858694}]}]}
{"op":"mcm","clk":"11936388502","pt":1724677892708,"mc":[{"id":"1.232298775","rc":[{"batb":[[0,1.75,20.83],[1,1.7,54.92],[2,1.2,125]],"ltp":1.76,"tv":115.25,"id":247649},{"batb":[[0,2.32,5],[1,2.3,29.57],[2,2,34]],"ltp":2.32,"tv":84.59,"id":8858694}]}]}
{"op":"mcm","clk":"11936388804","pt":1724677896027,"mc":[{"id":"1.232298775","rc":[{"batb":[[0,1.76,5],[1,1.75,20.83],[2,1.7,54.92]],"ltp":1.76,"tv":115.25,"id":247649},{"batb":[[0,2.3,29.57],[1,2,34],[2,1.2,125]],"ltp":2.32,"tv":84.59,"id":8858694}]}]}
{"op":"mcm","clk":"11936389134","pt":1724677899401,"mc":[{"id":"1.232298775","rc":[{"batb":[[0,1.75,20.83],[1,1.7,54.92],[2,1.2,125]],"ltp":1.76,"tv":115.25,"id":247649},{"batb":[[0,2.32,5],[1,2.3,29.57],[2,2,34]],"ltp":2.32,"tv":84.59,"id":8858694}]}]}
{"op":"mcm","clk":"11936389418","pt":1724677902727,"mc":[{"id":"1.232298775","rc":[{"batb":[[0,1.76,5],[1,1.75,20.83]],"ltp":1.76,"tv":115.25,"id":247649},{"batb":[[0,2,34],[1,1.2,125],[2,1.04,1612.41]],"ltp":2.32,"tv":84.59,"id":8858694}]}]}
{"op":"mcm","clk":"11936389748","pt":1724677906218,"mc":[{"id":"1.232298775","rc":[{"batb":[[0,1.75,20.83],[1,1.2,125],[2,1.05,5.19]],"ltp":1.76,"tv":115.25,"id":247649},{"batb":[[0,2.02,5],[1,2,34],[2,1.2,125]],"ltp":2.32,"tv":84.59,"id":8858694}]}]}
{"op":"mcm","clk":"11936389874","pt":1724677907624,"mc":[{"id":"1.232298775","rc":[{"batb":[[1,1.7,54.92],[2,1.2,125]],"ltp":1.76,"tv":115.25,"id":247649},{"batb":[[0,2.3,29.57],[1,2.02,5],[2,2,34]],"ltp":2.32,"tv":84.59,"id":8858694}]}]}
{"op":"mcm","clk":"11936390047","pt":1724677909547,"mc":[{"id":"1.232298775","rc":[{"batb":[[0,1.76,5],[1,1.75,20.83],[2,1.7,54.92]],"ltp":1.76,"tv":115.25,"id":247649},{"batb":[[1,2,34],[2,1.2,125]],"ltp":2.32,"tv":84.59,"id":8858694}]}]}
{"op":"mcm","clk":"11936390333","pt":1724677912849,"mc":[{"id":"1.232298775","rc":[{"batb":[[0,1.75,20.83],[1,1.7,54.92],[2,1.2,125]],"ltp":1.76,"tv":115.25,"id":247649}]}]}
{"op":"mcm","clk":"11936390346","pt":1724677912954,"mc":[{"id":"1.232298775","rc":[{"batb":[[0,2.32,5],[1,2.3,29.57],[2,2,34]],"ltp":2.32,"tv":84.59,"id":8858694}]}]}
{"op":"mcm","clk":"11936390631","pt":1724677916135,"mc":[{"id":"1.232298775","rc":[{"batb":[[0,2.3,29.57],[1,2,34],[2,1.2,125]],"ltp":2.32,"tv":84.59,"id":8858694}]}]}
{"op":"mcm","clk":"11936390732","pt":1724677917128,"mc":[{"id":"1.232298775","rc":[{"batb":[[0,1.76,5],[1,1.75,20.83],[2,1.7,54.92]],"ltp":1.76,"tv":115.25,"id":247649}]}]}
{"op":"mcm","clk":"11936391077","pt":1724677920532,"mc":[{"id":"1.232298775","rc":[{"batb":[[0,1.75,20.83],[1,1.7,54.92],[2,1.2,125]],"ltp":1.76,"tv":115.25,"id":247649},{"batb":[[0,2.32,5],[1,2.3,29.57],[2,2,34]],"ltp":2.32,"tv":84.59,"id":8858694}]}]}
{"op":"mcm","clk":"11936391290","pt":1724677922831,"mc":[{"id":"1.232298775","rc":[{"trd":[[1.76,41.54]],"batb":[[1,1.2,125],[2,1.05,5.19]],"ltp":1.76,"tv":120.25,"id":247649},{"trd":[[2.32,26.53]],"batb":[[0,2.32,1.21],[1,2,34],[2,1.2,125]],"ltp":2.32,"tv":88.38,"id":8858694}],"tv":208.63}]}
{"op":"mcm","clk":"11936391400","pt":1724677923825,"mc":[{"id":"1.232298775","rc":[{"batb":[[0,2,34],[1,1.2,125],[2,1.04,1612.41]],"ltp":2.32,"tv":88.38,"id":8858694}]}]}
{"op":"mcm","clk":"11936391738","pt":1724677927735,"mc":[{"id":"1.232298775","rc":[{"batb":[[1,1.7,54.92],[2,1.2,125]],"ltp":1.76,"tv":120.25,"id":247649},{"batb":[[0,2.3,29.57],[1,2,34],[2,1.2,125]],"ltp":2.32,"tv":88.38,"id":8858694}]}]}
{"op":"mcm","clk":"11936391750","pt":1724677927887,"mc":[{"id":"1.232298775","rc":[{"trd":[[1.76,46.54]],"ltp":1.76,"tv":125.25,"id":247649},{"trd":[[2.32,30.32]],"batb":[[0,2.32,1.21],[1,2.3,29.57],[2,2,34]],"ltp":2.32,"tv":92.17,"id":8858694}],"tv":217.42}]}
{"op":"mcm","clk":"11936392062","pt":1724677931364,"mc":[{"id":"1.232298775","rc":[{"batb":[[0,1.76,5],[1,1.75,20.83],[2,1.7,54.92]],"ltp":1.76,"tv":125.25,"id":247649},{"batb":[[0,2.3,29.57],[1,2,34],[2,1.2,125]],"ltp":2.32,"tv":92.17,"id":8858694}]}]}
{"op":"mcm","clk":"11936392329","pt":1724677934747,"mc":[{"id":"1.232298775","rc":[{"batb":[[0,1.75,20.83],[1,1.7,54.92],[2,1.2,125]],"ltp":1.76,"tv":125.25,"id":247649},{"batb":[[0,2.32,5],[1,2.3,29.57],[2,2,34]],"ltp":2.32,"tv":92.17,"id":8858694}]}]}
{"op":"mcm","clk":"11936392593","pt":1724677937855,"mc":[{"id":"1.232298775","rc":[{"batb":[[1,1.2,125],[2,1.05,5.19]],"ltp":1.76,"tv":125.25,"id":247649},{"batb":[[1,2,34],[2,1.2,125]],"ltp":2.32,"tv":92.17,"id":8858694}]}]}
{"op":"mcm","clk":"11936392604","pt":1724677937959,"mc":[{"id":"1.232298775","rc":[{"batb":[[0,1.76,5],[1,1.75,20.83],[2,1.2,125]],"ltp":1.76,"tv":125.25,"id":247649},{"batb":[[0,2,34],[1,1.2,125],[2,1.04,1612.41]],"ltp":2.32,"tv":92.17,"id":8858694}]}]}
{"op":"mcm","clk":"11936392913","pt":1724677941388,"mc":[{"id":"1.232298775","rc":[{"batb":[[0,1.75,20.83],[1,1.2,125],[2,1.05,5.19]],"ltp":1.76,"tv":125.25,"id":247649},{"batb":[[0,2.02,5],[1,2,34],[2,1.2,125]],"ltp":2.32,"tv":92.17,"id":8858694}]}]}
{"op":"mcm","clk":"11936393080","pt":1724677942855,"mc":[{"id":"1.232298775","rc":[{"batb":[[1,1.7,54.92],[2,1.2,125]],"ltp":1.76,"tv":125.25,"id":247649},{"batb":[[0,2.3,29.57],[1,2.02,5],[2,2,34]],"ltp":2.32,"tv":92.17,"id":8858694}]}]}
{"op":"mcm","clk":"11936393262","pt":1724677944783,"mc":[{"id":"1.232298775","rc":[{"batb":[[0,1.76,5],[1,1.75,20.83],[2,1.7,54.92]],"ltp":1.76,"tv":125.25,"id":247649},{"batb":[[1,2,34],[2,1.2,125]],"ltp":2.32,"tv":92.17,"id":8858694}]}]}
{"op":"mcm","clk":"11936393561","pt":1724677948170,"mc":[{"id":"1.232298775","rc":[{"batb":[[0,1.75,20.83],[1,1.7,54.92],[2,1.2,125]],"ltp":1.76,"tv":125.25,"id":247649},{"batb":[[0,2.32,5],[1,2.3,29.57],[2,2,34]],"ltp":2.32,"tv":92.17,"id":8858694}]}]}
{"op":"mcm","clk":"11936393874","pt":1724677951614,"mc":[{"id":"1.232298775","rc":[{"batb":[[0,1.76,5],[1,1.75,20.83],[2,1.7,54.92]],"ltp":1.76,"tv":125.25,"id":247649},{"batb":[[0,2.3,29.57],[1,2,34],[2,1.2,125]],"ltp":2.32,"tv":92.17,"id":8858694}]}]}
{"op":"mcm","clk":"11936394163","pt":1724677954785,"mc":[{"id":"1.232298775","rc":[{"batb":[[0,1.75,20.83],[1,1.7,54.92],[2,1.2,125]],"ltp":1.76,"tv":125.25,"id":247649}]}]}
{"op":"mcm","clk":"11936394184","pt":1724677954977,"mc":[{"id":"1.232298775","rc":[{"batb":[[0,2.32,5],[1,2.3,29.57],[2,2,34]],"ltp":2.32,"tv":92.17,"id":8858694}]}]}
{"op":"mcm","clk":"11936394520","pt":1724677958279,"mc":[{"id":"1.232298775","rc":[{"trd":[[1.76,51.54]],"batb":[[1,1.2,125],[2,1.05,5.19]],"ltp":1.76,"tv":130.25,"id":247649},{"trd":[[2.32,34.11]],"batb":[[0,2,34],[1,1.2,125],[2,1.04,1612.41]],"ltp":2.32,"tv":95.96,"id":8858694}],"tv":226.21}]}
{"op":"mcm","clk":"11936394957","pt":1724677962871,"mc":[{"id":"1.232298775","rc":[{"batb":[[1,1.7,54.92],[2,1.2,125]],"ltp":1.76,"tv":130.25,"id":247649},{"batb":[[0,2.3,29.57],[1,2,34],[2,1.2,125]],"ltp":2.32,"tv":95.96,"id":8858694}]}]}
{"op":"mcm","clk":"11936394964","pt":1724677962975,"mc":[{"id":"1.232298775","rc":[{"trd":[[1.76,56.54]],"ltp":1.76,"tv":135.25,"id":247649},{"trd":[[2.32,37.9]],"batb":[[0,2.32,1.21],[1,2.3,29.57],[2,2,34]],"ltp":2.32,"tv":99.75,"id":8858694}],"tv":235.0}]}
{"op":"mcm","clk":"11936395338","pt":1724677966633,"mc":[{"id":"1.232298775","rc":[{"batb":[[0,1.76,5],[1,1.75,20.83],[2,1.7,54.92]],"ltp":1.76,"tv":135.25,"id":247649},{"batb":[[0,2.3,29.57],[1,2,34],[2,1.2,125]],"ltp":2.32,"tv":99.75,"id":8858694}]}]}
{"op":"mcm","clk":"11936395640","pt":1724677970018,"mc":[{"id":"1.232298775","rc":[{"batb":[[0,1.75,20.83],[1,1.7,54.92],[2,1.2,125]],"ltp":1.76,"tv":135.25,"id":247649},{"batb":[[0,2.32,5],[1,2.3,29.57],[2,2,34]],"ltp":2.32,"tv":99.75,"id":8858694}]}]}
{"op":"mcm","clk":"11936395975","pt":1724677973214,"mc":[{"id":"1.232298775","rc":[{"trd":[[1.76,61.54]],"batb":[[1,1.2,125],[2,1.05,5.19]],"ltp":1.76,"tv":140.25,"id":247649},{"trd":[[2.32,41.69]],"batb":[[0,2,34],[1,1.2,125],[2,1.04,1612.41]],"ltp":2.32,"tv":103.54,"id":8858694}],"tv":243.79}]}
{"op":"mcm","clk":"11936396450","pt":1724677978100,"mc":[{"id":"1.232298775","rc":[{"trd":[[1.76,66.54]],"batb":[[1,1.7,54.92],[2,1.2,125]],"ltp":1.76,"tv":145.25,"id":247649},{"trd":[[2.32,45.48]],"batb":[[0,2.32,1.21],[1,2.3,29.57],[2,2,34]],"ltp":2.32,"tv":107.33,"id":8858694}],"tv":252.58}]}
{"op":"mcm","clk":"11936396786","pt":1724677981726,"mc":[{"id":"1.232298775","rc":[{"batb":[[0,1.76,5],[1,1.75,20.83],[2,1.7,54.92]],"ltp":1.76,"tv":145.25,"id":247649},{"batb":[[0,2.3,29.57],[1,2,34],[2,1.2,125]],"ltp":2.32,"tv":107.33,"id":8858694}]}]}
{"op":"mcm","clk":"11936397117","pt":1724677985112,"mc":[{"id":"1.232298775","rc":[{"batb":[[0,1.75,20.83],[1,1.7,54.92],[2,1.2,125]],"ltp":1.76,"tv":145.25,"id":247649},{"batb":[[0,2.32,5],[1,2.3,29.57],[2,2,34]],"ltp":2.32,"tv":107.33,"id":8858694}]}]}
{"op":"mcm","clk":"11936397413","pt":1724677988336,"mc":[{"id":"1.232298775","rc":[{"trd":[[1.76,71.54]],"batb":[[1,1.2,125],[2,1.05,5.19]],"ltp":1.76,"tv":150.25,"id":247649},{"trd":[[2.32,49.27]],"batb":[[0,2,34],[1,1.2,125],[2,1.04,1612.41]],"ltp":2.32,"tv":111.12,"id":8858694}],"tv":261.37}]}
{"op":"mcm","clk":"11936397859","pt":1724677993123,"mc":[{"id":"1.232298775","rc":[{"trd":[[1.76,76.54]],"batb":[[1,1.7,54.92],[2,1.2,125]],"ltp":1.76,"tv":155.25,"id":247649},{"trd":[[2.32,53.06]],"batb":[[0,2.32,1.21],[1,2.3,29.57],[2,2,34]],"ltp":2.32,"tv":114.91,"id":8858694}],"tv":270.16}]}
{"op":"mcm","clk":"11936398193","pt":1724677996644,"mc":[{"id":"1.232298775","rc":[{"batb":[[0,1.76,5],[1,1.75,20.83],[2,1.7,54.92]],"ltp":1.76,"tv":155.25,"id":247649},{"batb":[[0,2.3,29.57],[1,2,34],[2,1.2,125]],"ltp":2.32,"tv":114.91,"id":8858694}]}]}
{"op":"mcm","clk":"11936398517","pt":1724678000129,"mc":[{"id":"1.232298775","rc":[{"batb":[[0,1.75,20.83],[1,1.7,54.92],[2,1.2,125]],"ltp":1.76,"tv":155.25,"id":247649},{"batb":[[0,2.32,5],[1,2.3,29.57],[2,2,34]],"ltp":2.32,"tv":114.91,"id":8858694}]}]}
{"op":"mcm","clk":"11936398812","pt":1724678003340,"mc":[{"id":"1.232298775","rc":[{"trd":[[1.76,81.54]],"batb":[[1,1.2,125],[2,1.05,5.19]],"ltp":1.76,"tv":160.25,"id":247649},{"trd":[[2.32,56.85]],"batb":[[0,2,34],[1,1.2,125],[2,1.04,1612.41]],"ltp":2.32,"tv":118.7,"id":8858694}],"tv":278.95}]}
{"op":"mcm","clk":"11936399345","pt":1724678008258,"mc":[{"id":"1.232298775","rc":[{"trd":[[1.76,86.54]],"batb":[[1,1.7,54.92],[2,1.2,125]],"ltp":1.76,"tv":165.25,"id":247649},{"trd":[[2.32,60.64]],"batb":[[0,2.32,1.21],[1,2.3,29.57],[2,2,34]],"ltp":2.32,"tv":122.49,"id":8858694}],"tv":287.74}]}
{"op":"mcm","clk":"11936399687","pt":1724678011639,"mc":[{"id":"1.232298775","rc":[{"batb":[[0,1.76,5],[1,1.75,20.83],[2,1.7,54.92]],"ltp":1.76,"tv":165.25,"id":247649},{"batb":[[0,2.3,29.57],[1,2,34],[2,1.2,125]],"ltp":2.32,"tv":122.49,"id":8858694}]}]}
{"op":"mcm","clk":"11936399982","pt":1724678014843,"mc":[{"id":"1.232298775","rc":[{"batb":[[0,1.75,20.83],[1,1.7,54.92],[2,1.2,125]],"ltp":1.76,"tv":165.25,"id":247649}]}]}
{"op":"mcm","clk":"11936399997","pt":1724678014950,"mc":[{"id":"1.232298775","rc":[{"batb":[[0,2.32,5],[1,2.3,29.57],[2,2,34]],"ltp":2.32,"tv":122.49,"id":8858694}]}]}
{"op":"mcm","clk":"11936400335","pt":1724678018349,"mc":[{"id":"1.232298775","rc":[{"batb":[[0,1.76,5],[1,1.75,20.83]],"ltp":1.76,"tv":165.25,"id":247649},{"batb":[[0,2,34],[1,1.2,125],[2,1.04,1612.41]],"ltp":2.32,"tv":122.49,"id":8858694}]}]}
{"op":"mcm","clk":"11936400677","pt":1724678021771,"mc":[{"id":"1.232298775","rc":[{"batb":[[0,1.75,20.83],[1,1.2,125],[2,1.05,5.19]],"ltp":1.76,"tv":165.25,"id":247649},{"batb":[[0,2.02,5],[1,2,34],[2,1.2,125]],"ltp":2.32,"tv":122.49,"id":8858694}]}]}
{"op":"mcm","clk":"11936400818","pt":1724678023166,"mc":[{"id":"1.232298775","rc":[{"batb":[[1,1.7,54.92],[2,1.2,125]],"ltp":1.76,"tv":165.25,"id":247649},{"batb":[[0,2.3,29.57],[1,2.02,5],[2,2,34]],"ltp":2.32,"tv":122.49,"id":8858694}]}]}
{"op":"mcm","clk":"11936401268","pt":1724678025359,"mc":[{"id":"1.232298775","rc":[{"batb":[[0,1.76,5],[1,1.75,20.83],[2,1.7,54.92]],"ltp":1.76,"tv":165.25,"id":247649},{"batb":[[1,2,34],[2,1.2,125]],"ltp":2.32,"tv":122.49,"id":8858694}]}]}
{"op":"mcm","clk":"11936401836","pt":1724678028658,"mc":[{"id":"1.232298775","rc":[{"batb":[[0,1.75,20.83],[1,1.7,54.92],[2,1.2,125]],"ltp":1.76,"tv":165.25,"id":247649},{"batb":[[0,2.32,5],[1,2.3,29.57],[2,2,34]],"ltp":2.32,"tv":122.49,"id":8858694}]}]}
{"op":"mcm","clk":"11936402222","pt":1724678032670,"mc":[{"id":"1.232298775","rc":[{"batb":[[0,1.76,5],[1,1.75,20.83],[2,1.7,54.92]],"ltp":1.76,"tv":165.25,"id":247649},{"batb":[[0,2.3,29.57],[1,2.08,177.21]],"ltp":2.32,"tv":122.49,"id":8858694}]}]}
{"op":"mcm","clk":"11936402675","pt":1724678035376,"mc":[{"id":"1.232298775","rc":[{"batb":[[0,1.75,20.83],[1,1.7,54.92],[2,1.2,125]],"ltp":1.76,"tv":165.25,"id":247649},{"batb":[[0,2.32,5],[1,2.3,29.57],[2,2.08,177.21]],"ltp":2.32,"tv":122.49,"id":8858694}]}]}
{"op":"mcm","clk":"11936403082","pt":1724678038696,"mc":[{"id":"1.232298775","rc":[{"trd":[[1.76,91.54]],"batb":[[1,1.2,125],[2,1.05,5.19]],"ltp":1.76,"tv":170.25,"id":247649},{"trd":[[2.32,64.43]],"batb":[[0,2.08,177.21],[1,2,34],[2,1.2,125]],"ltp":2.32,"tv":126.28,"id":8858694}],"tv":296.53}]}
{"op":"mcm","clk":"11936403543","pt":1724678043581,"mc":[{"id":"1.232298775","rc":[{"trd":[[1.76,96.54]],"batb":[[1,1.7,54.92],[2,1.2,125]],"ltp":1.76,"tv":175.25,"id":247649},{"trd":[[2.32,68.22]],"batb":[[0,2.32,1.21],[1,2.3,29.57],[2,2.08,177.21]],"ltp":2.32,"tv":130.07,"id":8858694}],"tv":305.32}]}
{"op":"mcm","clk":"11936403855","pt":1724678047002,"mc":[{"id":"1.232298775","rc":[{"batb":[[0,1.76,5],[1,1.75,20.83],[2,1.7,54.92]],"ltp":1.76,"tv":175.25,"id":247649},{"batb":[[0,2.3,29.57],[1,2.08,177.21],[2,2,34]],"ltp":2.32,"tv":130.07,"id":8858694}]}]}
{"op":"mcm","clk":"11936404151","pt":1724678050386,"mc":[{"id":"1.232298775","rc":[{"batb":[[0,1.75,20.83],[1,1.7,54.92],[2,1.2,125]],"ltp":1.76,"tv":175.25,"id":247649},{"batb":[[0,2.32,5],[1,2.3,29.57],[2,2.08,177.21]],"ltp":2.32,"tv":130.07,"id":8858694}]}]}
{"op":"mcm","clk":"11936404462","pt":1724678053699,"mc":[{"id":"1.232298775","rc":[{"trd":[[1.76,101.54]],"batb":[[1,1.2,125],[2,1.05,5.19]],"ltp":1.76,"tv":180.25,"id":247649},{"trd":[[2.32,72.01]],"batb":[[0,2.08,177.21],[1,2,34],[2,1.2,125]],"ltp":2.32,"tv":133.86,"id":8858694}],"tv":314.11}]}
{"op":"mcm","clk":"11936404891","pt":1724678058391,"mc":[{"id":"1.232298775","rc":[{"trd":[[1.76,106.54]],"batb":[[1,1.7,54.92],[2,1.2,125]],"ltp":1.76,"tv":185.25,"id":247649},{"trd":[[2.32,75.8]],"batb":[[0,2.32,1.21],[1,2.3,29.57],[2,2.08,177.21]],"ltp":2.32,"tv":137.65,"id":8858694}],"tv":322.9}]}
{"op":"mcm","clk":"11936405185","pt":1724678061810,"mc":[{"id":"1.232298775","rc":[{"batb":[[0,2.3,29.57],[1,2.08,177.21],[2,2,34]],"ltp":2.32,"tv":137.65,"id":8858694}]}]}
{"op":"mcm","clk":"11936405192","pt":1724678061915,"mc":[{"id":"1.232298775","rc":[{"batb":[[0,1.76,5],[1,1.75,20.83],[2,1.7,54.92]],"ltp":1.76,"tv":185.25,"id":247649}]}]}
{"op":"mcm","clk":"11936405457","pt":1724678065333,"mc":[{"id":"1.232298775","rc":[{"batb":[[0,1.75,20.83],[1,1.7,54.92],[2,1.2,125]],"ltp":1.76,"tv":185.25,"id":247649},{"batb":[[0,2.32,5],[1,2.3,29.57],[2,2.08,177.21]],"ltp":2.32,"tv":137.65,"id":8858694}]}]}
{"op":"mcm","clk":"11936405723","pt":1724678068514,"mc":[{"id":"1.232298775","rc":[{"batb":[[0,1.76,5],[1,1.75,20.83]],"ltp":1.76,"tv":185.25,"id":247649},{"batb":[[0,2.08,177.21],[1,2,34],[2,1.2,125]],"ltp":2.32,"tv":137.65,"id":8858694}]}]}
{"op":"mcm","clk":"11936406007","pt":1724678071827,"mc":[{"id":"1.232298775","rc":[{"batb":[[0,1.75,20.83],[1,1.2,125],[2,1.05,5.19]],"ltp":1.76,"tv":185.25,"id":247649}]}]}
{"op":"mcm","clk":"11936406023","pt":1724678072034,"mc":[{"id":"1.232298775","rc":[{"batb":[[0,2.1,5],[1,2.08,177.21],[2,2,34]],"ltp":2.32,"tv":137.65,"id":8858694}]}]}
{"op":"mcm","clk":"11936406141","pt":1724678073438,"mc":[{"id":"1.232298775","rc":[{"batb":[[1,1.7,54.92],[2,1.2,125]],"ltp":1.76,"tv":185.25,"id":247649},{"batb":[[0,2.3,29.57],[1,2.1,5],[2,2.08,177.21]],"ltp":2.32,"tv":137.65,"id":8858694}]}]}
{"op":"mcm","clk":"11936406336","pt":1724678075425,"mc":[{"id":"1.232298775","rc":[{"batb":[[0,1.76,5],[1,1.75,20.83],[2,1.7,54.92]],"ltp":1.76,"tv":185.25,"id":247649},{"batb":[[1,2.08,177.21],[2,2,34]],"ltp":2.32,"tv":137.65,"id":8858694}]}]}
{"op":"mcm","clk":"11936406620","pt":1724678078837,"mc":[{"id":"1.232298775","rc":[{"batb":[[0,1.75,20.83],[1,1.7,54.92],[2,1.2,125]],"ltp":1.76,"tv":185.25,"id":247649}]}]}
{"op":"mcm","clk":"11936406705","pt":1724678079754,"mc":[{"id":"1.232298775","rc":[{"batb":[[0,2.32,5],[1,2.3,29.57]],"ltp":2.32,"tv":137.65,"id":8858694}]}]}
{"op":"mcm","clk":"11936406724","pt":1724678079929,"mc":[{"id":"1.232298775","rc":[{"batb":[[2,2.12,177.21]],"ltp":2.32,"tv":137.65,"id":8858694}]}]}
{"op":"mcm","clk":"11936406928","pt":1724678082350,"mc":[{"id":"1.232298775","rc":[{"batb":[[0,1.76,5],[1,1.75,20.83],[2,1.7,54.92]],"ltp":1.76,"tv":185.25,"id":247649},{"batb":[[0,2.3,29.57],[1,2.12,177.21],[2,2,34]],"ltp":2.32,"tv":137.65,"id":8858694}]}]}
{"op":"mcm","clk":"11936407236","pt":1724678085739,"mc":[{"id":"1.232298775","rc":[{"batb":[[0,1.75,20.83],[1,1.7,54.92],[2,1.2,125]],"ltp":1.76,"tv":185.25,"id":247649},{"batb":[[0,2.32,5],[1,2.3,29.57],[2,2.12,177.21]],"ltp":2.32,"tv":137.65,"id":8858694}]}]}
{"op":"mcm","clk":"11936407497","pt":1724678088654,"mc":[{"id":"1.232298775","rc":[{"trd":[[1.76,111.54]],"batb":[[1,1.2,125],[2,1.05,5.19]],"ltp":1.76,"tv":190.25,"id":247649},{"trd":[[2.32,79.59]],"batb":[[0,2.32,1.21],[1,2.12,177.21],[2,2,34]],"ltp":2.32,"tv":141.44,"id":8858694}],"tv":331.69}]}
{"op":"mcm","clk":"11936407540","pt":1724678089162,"mc":[{"id":"1.232298775","rc":[{"batb":[[0,2.12,177.21],[1,2,34],[2,1.2,125]],"ltp":2.32,"tv":141.44,"id":8858694}]}]}
{"op":"mcm","clk":"11936407906","pt":1724678093557,"mc":[{"id":"1.232298775","rc":[{"trd":[[1.76,116.54]],"batb":[[1,1.7,54.92],[2,1.2,125]],"ltp":1.76,"tv":195.25,"id":247649},{"trd":[[2.32,83.38]],"batb":[[0,2.32,1.21],[1,2.3,29.57],[2,2.12,177.21]],"ltp":2.32,"tv":145.23,"id":8858694}],"tv":340.48}]}
{"op":"mcm","clk":"11936408208","pt":1724678096873,"mc":[{"id":"1.232298775","rc":[{"batb":[[0,1.76,5],[1,1.75,20.83],[2,1.7,54.92]],"ltp":1.76,"tv":195.25,"id":247649},{"batb":[[0,2.3,29.57],[1,2.12,177.21],[2,2,34]],"ltp":2.32,"tv":145.23,"id":8858694}]}]}
{"op":"mcm","clk":"11936408536","pt":1724678100383,"mc":[{"id":"1.232298775","rc":[{"batb":[[0,1.75,20.83],[1,1.7,54.92],[2,1.2,125]],"ltp":1.76,"tv":195.25,"id":247649},{"batb":[[0,2.32,5],[1,2.3,29.57],[2,2.12,177.21]],"ltp":2.32,"tv":145.23,"id":8858694}]}]}
{"op":"mcm","clk":"11936408875","pt":1724678103681,"mc":[{"id":"1.232298775","rc":[{"batb":[[0,1.76,5],[1,1.75,20.83]],"ltp":1.76,"tv":195.25,"id":247649},{"batb":[[0,2.12,177.21],[1,2,34],[2,1.2,125]],"ltp":2.32,"tv":145.23,"id":8858694}]}]}
{"op":"mcm","clk":"11936409223","pt":1724678107160,"mc":[{"id":"1.232298775","rc":[{"batb":[[0,1.75,20.83],[1,1.2,125],[2,1.05,5.19]],"ltp":1.76,"tv":195.25,"id":247649},{"batb":[[0,2.14,5],[1,2.12,177.21],[2,2,34]],"ltp":2.32,"tv":145.23,"id":8858694}]}]}
{"op":"mcm","clk":"11936409352","pt":1724678108560,"mc":[{"id":"1.232298775","rc":[{"batb":[[1,1.7,54.92],[2,1.2,125]],"ltp":1.76,"tv":195.25,"id":247649},{"batb":[[0,2.3,29.57],[1,2.14,5],[2,2.12,177.21]],"ltp":2.32,"tv":145.23,"id":8858694}]}]}
{"op":"mcm","clk":"11936409537","pt":1724678110575,"mc":[{"id":"1.232298775","rc":[{"batb":[[1,2.12,177.21],[2,2,34]],"ltp":2.32,"tv":145.23,"id":8858694}]}]}
{"op":"mcm","clk":"11936409574","pt":1724678110991,"mc":[{"id":"1.232298775","rc":[{"batb":[[0,1.76,5],[1,1.75,20.83],[2,1.7,54.92]],"ltp":1.76,"tv":195.25,"id":247649}]}]}
{"op":"mcm","clk":"11936409903","pt":1724678114489,"mc":[{"id":"1.232298775","rc":[{"batb":[[0,1.75,20.83],[1,1.7,54.92],[2,1.2,125]],"ltp":1.76,"tv":195.25,"id":247649},{"batb":[[0,2.32,5],[1,2.3,29.57],[2,2.12,177.21]],"ltp":2.32,"tv":145.23,"id":8858694}]}]}
{"op":"mcm","clk":"11936410193","pt":1724678117796,"mc":[{"id":"1.232298775","rc":[{"batb":[[0,1.76,5],[1,1.75,20.83],[2,1.7,54.92]],"ltp":1.76,"tv":195.25,"id":247649},{"batb":[[0,2.3,29.57],[1,2.12,177.21],[2,2,34]],"ltp":2.32,"tv":145.23,"id":8858694}]}]}
{"op":"mcm","clk":"11936410476","pt":1724678121182,"mc":[{"id":"1.232298775","rc":[{"batb":[[0,1.75,20.83],[1,1.7,54.92],[2,1.2,125]],"ltp":1.76,"tv":195.25,"id":247649},{"batb":[[0,2.32,5],[1,2.3,29.57],[2,2.12,177.21]],"ltp":2.32,"tv":145.23,"id":8858694}]}]}
{"op":"mcm","clk":"11936410857","pt":1724678123775,"mc":[{"id":"1.232298775","rc":[{"trd":[[1.76,121.54]],"batb":[[1,1.2,125],[2,1.05,5.19]],"ltp":1.76,"tv":200.25,"id":247649},{"trd":[[2.32,87.17]],"batb":[[0,2.32,1.21],[1,2.12,177.21],[2,2,34]],"ltp":2.32,"tv":149.02,"id":8858694}],"tv":349.27}]}
{"op":"mcm","clk":"11936411110","pt":1724678124598,"mc":[{"id":"1.232298775","rc":[{"batb":[[0,2.12,177.21],[1,2,34],[2,1.2,125]],"ltp":2.32,"tv":149.02,"id":8858694}]}]}
{"op":"mcm","clk":"11936411478","pt":1724678128709,"mc":[{"id":"1.232298775","rc":[{"trd":[[1.76,126.54]],"batb":[[1,1.7,54.92],[2,1.2,125]],"ltp":1.76,"tv":205.25,"id":247649},{"trd":[[2.32,90.96]],"batb":[[0,2.32,1.21],[1,2.3,29.57],[2,2.12,177.21]],"ltp":2.32,"tv":152.81,"id":8858694}],"tv":358.06}]}
{"op":"mcm","clk":"11936411793","pt":1724678131986,"mc":[{"id":"1.232298775","rc":[{"batb":[[0,1.76,5],[1,1.75,20.83],[2,1.7,54.92]],"ltp":1.76,"tv":205.25,"id":247649},{"batb":[[0,2.3,29.57],[1,2.12,177.21],[2,2,34]],"ltp":2.32,"tv":152.81,"id":8858694}]}]}
{"op":"mcm","clk":"11936412101","pt":1724678135198,"mc":[{"id":"1.232298775","rc":[{"batb":[[0,1.75,20.83],[1,1.7,54.92],[2,1.2,125]],"ltp":1.76,"tv":205.25,"id":247649},{"batb":[[0,2.32,5],[1,2.3,29.57],[2,2.12,177.21]],"ltp":2.32,"tv":152.81,"id":8858694}]}]}
{"op":"mcm","clk":"11936412416","pt":1724678138624,"mc":[{"id":"1.232298775","rc":[{"batb":[[0,1.76,5],[1,1.75,20.83],[2,1.7,54.92]],"ltp":1.76,"tv":205.25,"id":247649},{"batb":[[0,2.3,29.57],[1,2.12,177.21],[2,2,34]],"ltp":2.32,"tv":152.81,"id":8858694}]}]}
{"op":"mcm","clk":"11936412744","pt":1724678142017,"mc":[{"id":"1.232298775","rc":[{"batb":[[0,1.75,20.83],[1,1.7,54.92],[2,1.2,125]],"ltp":1.76,"tv":205.25,"id":247649},{"batb":[[0,2.32,5],[1,2.3,29.57],[2,2.12,177.21]],"ltp":2.32,"tv":152.81,"id":8858694}]}]}
{"op":"mcm","clk":"11936412873","pt":1724678143733,"mc":[{"id":"1.232298775","rc":[{"batb":[[1,1.2,125],[2,1.05,5.19]],"ltp":1.76,"tv":205.25,"id":247649},{"batb":[[1,2.12,177.21],[2,2,34]],"ltp":2.32,"tv":152.81,"id":8858694}]}]}
{"op":"mcm","clk":"11936413040","pt":1724678145519,"mc":[{"id":"1.232298775","rc":[{"batb":[[0,1.76,5],[1,1.75,20.83],[2,1.2,125]],"ltp":1.76,"tv":205.25,"id":247649},{"batb":[[0,2.12,177.21],[1,2,34],[2,1.2,125]],"ltp":2.32,"tv":152.81,"id":8858694}]}]}
{"op":"mcm","clk":"11936413487","pt":1724678148838,"mc":[{"id":"1.232298775","rc":[{"batb":[[0,1.75,20.83],[1,1.7,54.92]],"ltp":1.76,"tv":205.25,"id":247649},{"batb":[[0,2.32,5],[1,2.3,29.57],[2,2.12,177.21]],"ltp":2.32,"tv":152.81,"id":8858694}]}]}
{"op":"mcm","clk":"11936413758","pt":1724678152246,"mc":[{"id":"1.232298775","rc":[{"batb":[[0,1.76,5],[1,1.75,20.83],[2,1.7,54.92]],"ltp":1.76,"tv":205.25,"id":247649},{"batb":[[0,2.3,29.57],[1,2.12,177.21],[2,2,34]],"ltp":2.32,"tv":152.81,"id":8858694}]}]}
{"op":"mcm","clk":"11936414020","pt":1724678155546,"mc":[{"id":"1.232298775","rc":[{"batb":[[0,1.75,20.83],[1,1.7,54.92],[2,1.2,125]],"ltp":1.76,"tv":205.25,"id":247649},{"batb":[[0,2.32,5],[1,2.3,29.57],[2,2.12,177.21]],"ltp":2.32,"tv":152.81,"id":8858694}]}]}
{"op":"mcm","clk":"11936414280","pt":1724678158846,"mc":[{"id":"1.232298775","rc":[{"batb":[[0,1.76,5],[1,1.75,20.83]],"ltp":1.76,"tv":205.25,"id":247649},{"batb":[[0,2.12,177.21],[1,2,34],[2,1.2,125]],"ltp":2.32,"tv":152.81,"id":8858694}]}]}
{"op":"mcm","clk":"11936414570","pt":1724678162253,"mc":[{"id":"1.232298775","rc":[{"batb":[[0,1.75,20.83],[1,1.2,125],[2,1.05,5.19]],"ltp":1.76,"tv":205.25,"id":247649},{"batb":[[0,2.14,5],[1,2.12,177.21],[2,2,34]],"ltp":2.32,"tv":152.81,"id":8858694}]}]}
{"op":"mcm","clk":"11936414723","pt":1724678163757,"mc":[{"id":"1.232298775","rc":[{"batb":[[1,1.7,54.92],[2,1.2,125]],"ltp":1.76,"tv":205.25,"id":247649},{"batb":[[0,2.3,29.57],[1,2.14,5],[2,2.12,177.21]],"ltp":2.32,"tv":152.81,"id":8858694}]}]}
{"op":"mcm","clk":"11936414906","pt":1724678165538,"mc":[{"id":"1.232298775","rc":[{"batb":[[0,1.76,5],[1,1.75,20.83],[2,1.7,54.92]],"ltp":1.76,"tv":205.25,"id":247649},{"batb":[[1,2.12,177.21],[2,2,34]],"ltp":2.32,"tv":152.81,"id":8858694}]}]}
{"op":"mcm","clk":"11936415219","pt":1724678168876,"mc":[{"id":"1.232298775","rc":[{"batb":[[0,1.75,20.83],[1,1.7,54.92],[2,1.2,125]],"ltp":1.76,"tv":205.25,"id":247649},{"batb":[[0,2.32,5],[1,2.3,29.57],[2,2.12,177.21]],"ltp":2.32,"tv":152.81,"id":8858694}]}]}
{"op":"mcm","clk":"11936415512","pt":1724678172373,"mc":[{"id":"1.232298775","rc":[{"batb":[[0,1.76,5],[1,1.75,20.83],[2,1.7,54.92]],"ltp":1.76,"tv":205.25,"id":247649},{"batb":[[0,2.3,29.57],[1,2.12,177.21],[2,2,34]],"ltp":2.32,"tv":152.81,"id":8858694}]}]}
{"op":"mcm","clk":"11936416017","pt":1724678175770,"mc":[{"id":"1.232298775","rc":[{"batb":[[0,1.75,20.83],[1,1.7,54.92],[2,1.2,125]],"ltp":1.76,"tv":205.25,"id":247649}]}]}
{"op":"mcm","clk":"11936416038","pt":1724678175976,"mc":[{"id":"1.232298775","rc":[{"batb":[[0,2.32,5],[1,2.3,29.57],[2,2.12,177.21]],"ltp":2.32,"tv":152.81,"id":8858694}]}]}
{"op":"mcm","clk":"11936416516","pt":1724678178857,"mc":[{"id":"1.232298775","rc":[{"batb":[[1,1.2,125],[2,1.05,5.19]],"ltp":1.76,"tv":205.25,"id":247649},{"batb":[[1,2.12,177.21],[2,2,34]],"ltp":2.32,"tv":152.81,"id":8858694}]}]}
{"op":"mcm","clk":"11936416541","pt":1724678179159,"mc":[{"id":"1.232298775","rc":[{"trd":[[1.76,131.54]],"ltp":1.76,"tv":210.24,"id":247649},{"trd":[[2.32,94.75]],"batb":[[0,2.12,177.21],[1,2,34],[2,1.2,125]],"ltp":2.32,"tv":156.6,"id":8858694}],"tv":366.85}]}
{"op":"mcm","clk":"11936416866","pt":1724678183867,"mc":[{"id":"1.232298775","rc":[{"batb":[[1,1.7,54.92],[2,1.2,125]],"ltp":1.76,"tv":210.24,"id":247649},{"batb":[[0,2.3,29.57],[1,2.12,177.21],[2,2,34]],"ltp":2.32,"tv":156.6,"id":8858694}]}]}
{"op":"mcm","clk":"11936416874","pt":1724678183970,"mc":[{"id":"1.232298775","rc":[{"trd":[[1.76,136.54]],"ltp":1.76,"tv":215.24,"id":247649},{"trd":[[2.32,98.54]],"batb":[[0,2.32,1.21],[1,2.3,29.57],[2,2.12,177.21]],"ltp":2.32,"tv":160.39,"id":8858694}],"tv":375.64}]}
{"op":"mcm","clk":"11936417143","pt":1724678187369,"mc":[{"id":"1.232298775","rc":[{"batb":[[0,1.76,5],[1,1.75,20.83],[2,1.7,54.92]],"ltp":1.76,"tv":215.24,"id":247649},{"batb":[[0,2.3,29.57],[1,2.12,177.21],[2,2,34]],"ltp":2.32,"tv":160.39,"id":8858694}]}]}
{"op":"mcm","clk":"11936417668","pt":1724678190877,"mc":[{"id":"1.232298775","rc":[{"batb":[[0,1.75,20.83],[1,1.7,54.92],[2,1.2,125]],"ltp":1.76,"tv":215.24,"id":247649},{"batb":[[0,2.32,5],[1,2.3,29.57],[2,2.12,177.21]],"ltp":2.32,"tv":160.39,"id":8858694}]}]}
{"op":"mcm","clk":"11936417942","pt":1724678194071,"mc":[{"id":"1.232298775","rc":[{"batb":[[0,1.76,5],[1,1.75,20.83]],"ltp":1.76,"tv":215.24,"id":247649},{"batb":[[0,2.12,177.21],[1,2,34],[2,1.2,125]],"ltp":2.32,"tv":160.39,"id":8858694}]}]}
{"op":"mcm","clk":"11936418202","pt":1724678197494,"mc":[{"id":"1.232298775","rc":[{"batb":[[0,1.75,20.83],[1,1.2,125],[2,1.05,5.19]],"ltp":1.76,"tv":215.24,"id":247649},{"batb":[[0,2.14,5],[1,2.12,177.21],[2,2,34]],"ltp":2.32,"tv":160.39,"id":8858694}]}]}
{"op":"mcm","clk":"11936418338","pt":1724678198884,"mc":[{"id":"1.232298775","rc":[{"batb":[[1,1.7,54.92],[2,1.2,125]],"ltp":1.76,"tv":215.24,"id":247649},{"batb":[[0,2.3,29.57],[1,2.14,5],[2,2.12,177.21]],"ltp":2.32,"tv":160.39,"id":8858694}]}]}
{"op":"mcm","clk":"11936418512","pt":1724678200763,"mc":[{"id":"1.232298775","rc":[{"batb":[[0,1.76,5],[1,1.75,20.83],[2,1.7,54.92]],"ltp":1.76,"tv":215.24,"id":247649},{"batb":[[1,2.12,177.21],[2,2,34]],"ltp":2.32,"tv":160.39,"id":8858694}]}]}
{"op":"mcm","clk":"11936418826","pt":1724678204294,"mc":[{"id":"1.232298775","rc":[{"batb":[[0,1.75,20.83],[1,1.7,54.92],[2,1.2,125]],"ltp":1.76,"tv":215.24,"id":247649},{"batb":[[0,2.32,5],[1,2.3,29.57],[2,2.12,177.21]],"ltp":2.32,"tv":160.39,"id":8858694}]}]}
{"op":"mcm","clk":"11936419085","pt":1724678207794,"mc":[{"id":"1.232298775","rc":[{"batb":[[0,1.76,5],[1,1.75,20.83],[2,1.7,54.92]],"ltp":1.76,"tv":215.24,"id":247649},{"batb":[[0,2.3,29.57],[1,2.12,177.21],[2,2,34]],"ltp":2.32,"tv":160.39,"id":8858694}]}]}
{"op":"mcm","clk":"11936419321","pt":1724678211182,"mc":[{"id":"1.232298775","rc":[{"batb":[[0,1.75,20.83],[1,1.7,54.92],[2,1.2,125]],"ltp":1.76,"tv":215.24,"id":247649},{"batb":[[0,2.32,5],[1,2.3,29.57],[2,2.12,177.21]],"ltp":2.32,"tv":160.39,"id":8858694}]}]}
{"op":"mcm","clk":"11936419589","pt":1724678214525,"mc":[{"id":"1.232298775","rc":[{"trd":[[1.76,141.54]],"batb":[[1,1.2,125],[2,1.05,5.19]],"ltp":1.76,"tv":220.24,"id":247649},{"trd":[[2.32,102.33]],"batb":[[0,2.12,177.21],[1,2,34],[2,1.2,125]],"ltp":2.32,"tv":164.18,"id":8858694}],"tv":384.43}]}
{"op":"mcm","clk":"11936419933","pt":1724678219205,"mc":[{"id":"1.232298775","rc":[{"trd":[[1.76,146.54]],"batb":[[1,1.7,54.92],[2,1.2,125]],"ltp":1.76,"tv":225.24,"id":247649},{"trd":[[2.32,106.12]],"batb":[[0,2.32,1.21],[1,2.3,29.57],[2,2.12,177.21]],"ltp":2.32,"tv":167.97,"id":8858694}],"tv":393.22}]}
{"op":"mcm","clk":"11936420201","pt":1724678222500,"mc":[{"id":"1.232298775","rc":[{"batb":[[0,1.76,5],[1,1.75,20.83],[2,1.7,54.92]],"ltp":1.76,"tv":225.24,"id":247649},{"batb":[[0,2.3,29.57],[1,2.12,177.21],[2,2,34]],"ltp":2.32,"tv":167.97,"id":8858694}]}]}
{"op":"mcm","clk":"11936420480","pt":1724678226012,"mc":[{"id":"1.232298775","rc":[{"batb":[[0,1.75,20.83],[1,1.7,54.92],[2,1.2,125]],"ltp":1.76,"tv":225.24,"id":247649},{"batb":[[0,2.32,5],[1,2.3,29.57],[2,2.12,177.21]],"ltp":2.32,"tv":167.97,"id":8858694}]}]}
{"op":"mcm","clk":"11936420740","pt":1724678229538,"mc":[{"id":"1.232298775","rc":[{"trd":[[1.76,151.54]],"batb":[[1,1.2,125],[2,1.05,5.19]],"ltp":1.76,"tv":230.24,"id":247649},{"trd":[[2.32,109.91]],"batb":[[0,2.12,177.21],[1,2,34],[2,1.2,125]],"ltp":2.32,"tv":171.76,"id":8858694}],"tv":402.01}]}
{"op":"mcm","clk":"11936421090","pt":1724678234136,"mc":[{"id":"1.232298775","rc":[{"trd":[[1.76,156.54]],"batb":[[1,1.7,54.92],[2,1.2,125]],"ltp":1.76,"tv":235.24,"id":247649},{"trd":[[2.32,113.7]],"batb":[[0,2.32,1.21],[1,2.3,29.57],[2,2.12,177.21]],"ltp":2.32,"tv":175.55,"id":8858694}],"tv":410.8}]}
{"op":"mcm","clk":"11936421346","pt":1724678237426,"mc":[{"id":"1.232298775","rc":[{"batb":[[0,1.76,5],[1,1.75,20.83],[2,1.7,54.92]],"ltp":1.76,"tv":235.24,"id":247649},{"batb":[[0,2.3,29.57],[1,2.12,177.21],[2,2,34]],"ltp":2.32,"tv":175.55,"id":8858694}]}]}
{"op":"mcm","clk":"11936421622","pt":1724678240837,"mc":[{"id":"1.232298775","rc":[{"batb":[[0,1.75,20.83],[1,1.7,54.92],[2,1.2,125]],"ltp":1.76,"tv":235.24,"id":247649}]}]}
{"op":"mcm","clk":"11936421657","pt":1724678241342,"mc":[{"id":"1.232298775","rc":[{"batb":[[0,2.32,5],[1,2.3,29.57],[2,2.12,177.21]],"ltp":2.32,"tv":175.55,"id":8858694}]}]}
{"op":"mcm","clk":"11936421905","pt":1724678244552,"mc":[{"id":"1.232298775","rc":[{"trd":[[1.76,161.54]],"batb":[[1,1.2,125],[2,1.05,5.19]],"ltp":1.76,"tv":240.24,"id":247649},{"trd":[[2.32,117.49]],"batb":[[0,2.12,177.21],[1,2,34],[2,1.2,125]],"ltp":2.32,"tv":179.34,"id":8858694}],"tv":419.59}]}
{"op":"mcm","clk":"11936422315","pt":1724678249354,"mc":[{"id":"1.232298775","rc":[{"trd":[[1.76,166.54]],"batb":[[1,1.7,54.92],[2,1.2,125]],"ltp":1.76,"tv":245.24,"id":247649},{"trd":[[2.32,121.28]],"batb":[[0,2.32,1.21],[1,2.3,29.57],[2,2.12,177.21]],"ltp":2.32,"tv":183.13,"id":8858694}],"tv":428.38}]}
{"op":"mcm","clk":"11936422607","pt":1724678252729,"mc":[{"id":"1.232298775","rc":[{"batb":[[0,1.76,5],[1,1.75,20.83],[2,1.7,54.92]],"ltp":1.76,"tv":245.24,"id":247649},{"batb":[[0,2.3,29.57],[1,2.12,177.21],[2,2,34]],"ltp":2.32,"tv":183.13,"id":8858694}]}]}
{"op":"mcm","clk":"11936422875","pt":1724678256061,"mc":[{"id":"1.232298775","rc":[{"batb":[[0,1.75,20.83],[1,1.7,54.92],[2,1.2,125]],"ltp":1.76,"tv":245.24,"id":247649},{"batb":[[0,2.32,5],[1,2.3,29.57],[2,2.12,177.21]],"ltp":2.32,"tv":183.13,"id":8858694}]}]}
{"op":"mcm","clk":"11936423144","pt":1724678259439,"mc":[{"id":"1.232298775","rc":[{"batb":[[0,1.76,5],[1,1.75,20.83]],"ltp":1.76,"tv":245.24,"id":247649},{"batb":[[0,2.12,177.21],[1,2,34],[2,1.2,125]],"ltp":2.32,"tv":183.13,"id":8858694}]}]}
{"op":"mcm","clk":"11936423423","pt":1724678262762,"mc":[{"id":"1.232298775","rc":[{"batb":[[0,1.75,20.83],[1,1.2,125],[2,1.05,5.19]],"ltp":1.76,"tv":245.24,"id":247649},{"batb":[[0,2.14,5],[1,2.12,177.21],[2,2,34]],"ltp":2.32,"tv":183.13,"id":8858694}]}]}
{"op":"mcm","clk":"11936423525","pt":1724678264165,"mc":[{"id":"1.232298775","rc":[{"batb":[[1,1.7,54.92],[2,1.2,125]],"ltp":1.76,"tv":245.24,"id":247649},{"batb":[[0,2.3,29.57],[1,2.14,5],[2,2.12,177.21]],"ltp":2.32,"tv":183.13,"id":8858694}]}]}
{"op":"mcm","clk":"11936423667","pt":1724678266042,"mc":[{"id":"1.232298775","rc":[{"batb":[[0,1.76,5],[1,1.75,20.83],[2,1.7,54.92]],"ltp":1.76,"tv":245.24,"id":247649},{"batb":[[1,2.12,177.21],[2,2,34]],"ltp":2.32,"tv":183.13,"id":8858694}]}]}
{"op":"mcm","clk":"11936423961","pt":1724678269456,"mc":[{"id":"1.232298775","rc":[{"batb":[[0,1.75,20.83],[1,1.7,54.92],[2,1.2,125]],"ltp":1.76,"tv":245.24,"id":247649},{"batb":[[0,2.32,5],[1,2.3,29.57],[2,2.12,177.21]],"ltp":2.32,"tv":183.13,"id":8858694}]}]}
{"op":"mcm","clk":"11936424251","pt":1724678272673,"mc":[{"id":"1.232298775","rc":[{"batb":[[0,2.3,29.57],[1,2.12,177.21],[2,2,34]],"ltp":2.32,"tv":183.13,"id":8858694}]}]}
{"op":"mcm","clk":"11936424266","pt":1724678272881,"mc":[{"id":"1.232298775","rc":[{"batb":[[0,1.76,5],[1,1.75,20.83],[2,1.7,54.92]],"ltp":1.76,"tv":245.24,"id":247649}]}]}
{"op":"mcm","clk":"11936424545","pt":1724678276369,"mc":[{"id":"1.232298775","rc":[{"batb":[[0,1.75,20.83],[1,1.7,54.92],[2,1.2,125]],"ltp":1.76,"tv":245.24,"id":247649},{"batb":[[0,2.32,5],[1,2.3,29.57],[2,2.12,177.21]],"ltp":2.32,"tv":183.13,"id":8858694}]}]}
{"op":"mcm","clk":"11936424794","pt":1724678279668,"mc":[{"id":"1.232298775","rc":[{"trd":[[1.76,171.54]],"batb":[[1,1.2,125],[2,1.05,5.19]],"ltp":1.76,"tv":250.24,"id":247649},{"trd":[[2.32,125.07]],"batb":[[0,2.12,177.21],[1,2,34],[2,1.2,125]],"ltp":2.32,"tv":186.92,"id":8858694}],"tv":437.17}]}
{"op":"mcm","clk":"11936425223","pt":1724678284400,"mc":[{"id":"1.232298775","rc":[{"trd":[[1.76,176.54]],"batb":[[1,1.7,54.92],[2,1.2,125]],"ltp":1.76,"tv":255.24,"id":247649},{"trd":[[2.32,128.86]],"batb":[[0,2.32,1.21],[1,2.3,29.57],[2,2.12,177.21]],"ltp":2.32,"tv":190.71,"id":8858694}],"tv":445.96}]}
{"op":"mcm","clk":"11936425497","pt":1724678287862,"mc":[{"id":"1.232298775","rc":[{"batb":[[0,1.76,5],[1,1.75,20.83],[2,1.7,54.92]],"ltp":1.76,"tv":255.24,"id":247649},{"batb":[[0,2.3,29.57],[1,2.12,177.21],[2,2,34]],"ltp":2.32,"tv":190.71,"id":8858694}]}]}
{"op":"mcm","clk":"11936425777","pt":1724678291485,"mc":[{"id":"1.232298775","rc":[{"batb":[[0,1.75,20.83],[1,1.7,54.92],[2,1.2,125]],"ltp":1.76,"tv":255.24,"id":247649},{"batb":[[0,2.32,5],[1,2.3,29.57],[2,2.12,177.21]],"ltp":2.32,"tv":190.71,"id":8858694}]}]}
{"op":"mcm","clk":"11936426040","pt":1724678294699,"mc":[{"id":"1.232298775","rc":[{"trd":[[1.76,181.54]],"batb":[[1,1.2,125],[2,1.05,5.19]],"ltp":1.76,"tv":260.25,"id":247649},{"trd":[[2.32,132.65]],"batb":[[0,2.12,177.21],[1,2,34],[2,1.2,125]],"ltp":2.32,"tv":194.5,"id":8858694}],"tv":454.75}]}
{"op":"mcm","clk":"11936426427","pt":1724678299366,"mc":[{"id":"1.232298775","rc":[{"trd":[[1.76,186.54]],"batb":[[1,1.7,54.92],[2,1.2,125]],"ltp":1.76,"tv":265.25,"id":247649},{"trd":[[2.32,136.44]],"batb":[[0,2.32,1.21],[1,2.3,29.57],[2,2.12,177.21]],"ltp":2.32,"tv":198.29,"id":8858694}],"tv":463.54}]}
{"op":"mcm","clk":"11936426720","pt":1724678302781,"mc":[{"id":"1.232298775","rc":[{"batb":[[0,1.76,5],[1,1.75,20.83],[2,1.7,54.92]],"ltp":1.76,"tv":265.25,"id":247649},{"batb":[[0,2.3,29.57],[1,2.12,177.21],[2,2,34]],"ltp":2.32,"tv":198.29,"id":8858694}]}]}
{"op":"mcm","clk":"11936427019","pt":1724678306195,"mc":[{"id":"1.232298775","rc":[{"batb":[[0,1.75,20.83],[1,1.7,54.92],[2,1.2,125]],"ltp":1.76,"tv":265.25,"id":247649},{"batb":[[0,2.32,5],[1,2.3,29.57],[2,2.12,177.21]],"ltp":2.32,"tv":198.29,"id":8858694}]}]}
{"op":"mcm","clk":"11936427132","pt":1724678307387,"mc":[{"id":"1.232298775","rc":[{"trd":[[1.76,187.54]],"ltp":1.76,"tv":266.25,"id":247649},{"trd":[[2.32,137.2]],"batb":[[0,2.32,4.24]],"ltp":2.32,"tv":199.05,"id":8858694}],"tv":465.3}]}
{"op":"mcm","clk":"11936427348","pt":1724678309713,"mc":[{"id":"1.232298775","rc":[{"batb":[[0,1.76,5],[1,1.75,20.83],[2,1.7,54.92]],"ltp":1.76,"tv":266.25,"id":247649},{"batb":[[0,2.3,29.57],[1,2.12,177.21],[2,2,34]],"ltp":2.32,"tv":199.05,"id":8858694}]}]}
{"op":"mcm","clk":"11936427672","pt":1724678313393,"mc":[{"id":"1.232298775","rc":[{"batb":[[0,1.75,20.83],[1,1.7,54.92],[2,1.2,125]],"ltp":1.76,"tv":266.25,"id":247649},{"batb":[[0,2.32,5],[1,2.3,29.57],[2,2.12,177.21]],"ltp":2.32,"tv":199.05,"id":8858694}]}]}
{"op":"mcm","clk":"11936427756","pt":1724678314421,"mc":[{"id":"1.232298775","rc":[{"batb":[[1,1.2,125],[2,1.05,5.19]],"ltp":1.76,"tv":266.25,"id":247649},{"batb":[[1,2.12,177.21],[2,2,34]],"ltp":2.32,"tv":199.05,"id":8858694}]}]}
{"op":"mcm","clk":"11936427870","pt":1724678315820,"mc":[{"id":"1.232298775","rc":[{"trd":[[1.76,194.13]],"batb":[[0,1.78,5],[1,1.77,31.41],[2,1.75,20.83]],"ltp":1.76,"tv":272.84,"id":247649},{"trd":[[2.32,142.2]],"batb":[[0,2.12,177.21],[1,2,34],[2,1.2,125]],"ltp":2.32,"tv":204.05,"id":8858694}],"tv":476.89}]}
{"op":"mcm","clk":"11936428148","pt":1724678319403,"mc":[{"id":"1.232298775","rc":[{"trd":[[1.77,31.41]],"batb":[[0,1.75,20.83],[1,1.7,54.92],[2,1.2,125]],"ltp":1.77,"tv":304.25,"id":247649},{"trd":[[2.3,24.17]],"batb":[[0,2.3,5.4],[1,2.14,5],[2,2.12,177.21]],"ltp":2.3,"tv":228.22,"id":8858694}],"tv":532.47}]}
{"op":"mcm","clk":"11936428404","pt":1724678322507,"mc":[{"id":"1.232298775","rc":[{"batb":[[0,1.76,5],[1,1.75,20.83],[2,1.7,54.92]],"ltp":1.77,"tv":304.25,"id":247649},{"batb":[[1,2.12,177.21],[2,2,34]],"ltp":2.3,"tv":228.22,"id":8858694}]}]}
{"op":"mcm","clk":"11936428583","pt":1724678324627,"mc":[{"id":"1.232298775","rc":[{"trd":[[1.76,199.13]],"batb":[[0,1.75,20.83],[1,1.7,54.92],[2,1.2,125]],"ltp":1.76,"tv":309.25,"id":247649},{"trd":[[2.32,145.99]],"batb":[[0,2.32,1.21],[1,2.3,29.57],[2,2.12,177.21]],"ltp":2.32,"tv":232.01,"id":8858694}],"tv":541.26}]}
{"op":"mcm","clk":"11936428826","pt":1724678327995,"mc":[{"id":"1.232298775","rc":[{"batb":[[0,1.76,5],[1,1.75,20.83],[2,1.7,54.92]],"ltp":1.76,"tv":309.25,"id":247649},{"batb":[[0,2.3,29.57],[1,2.12,177.21],[2,2,34]],"ltp":2.32,"tv":232.01,"id":8858694}]}]}
{"op":"mcm","clk":"11936428982","pt":1724678330019,"mc":[{"id":"1.232298775","rc":[{"trd":[[1.76,205.13]],"batb":[[0,1.75,20.83],[1,1.7,54.92],[2,1.2,125]],"ltp":1.76,"tv":315.25,"id":247649},{"trd":[[2.32,150.54]],"batb":[[0,2.3,30.02]],"ltp":2.32,"tv":236.56,"id":8858694}],"tv":551.81}]}
{"op":"mcm","clk":"11936429324","pt":1724678333643,"mc":[{"id":"1.232298775","rc":[{"batb":[[0,1.76,5],[1,1.75,20.83],[2,1.7,54.92]],"ltp":1.76,"tv":315.25,"id":247649},{"batb":[[0,2.3,29.57]],"ltp":2.32,"tv":236.56,"id":8858694}]}]}
{"op":"mcm","clk":"11936429577","pt":1724678336808,"mc":[{"id":"1.232298775","rc":[{"batb":[[0,1.75,20.83],[1,1.7,54.92],[2,1.2,125]],"ltp":1.76,"tv":315.25,"id":247649}]}]}
{"op":"mcm","clk":"11936429585","pt":1724678336914,"mc":[{"id":"1.232298775","rc":[{"batb":[[0,2.32,1.73],[1,2.3,29.57],[2,2.12,177.21]],"ltp":2.32,"tv":236.56,"id":8858694}]}]}
{"op":"mcm","clk":"11936429844","pt":1724678340215,"mc":[{"id":"1.232298775","rc":[{"batb":[[0,1.76,5],[1,1.75,20.83],[2,1.7,54.92]],"ltp":1.76,"tv":315.25,"id":247649},{"batb":[[0,2.3,29.57],[1,2.12,177.21],[2,2,34]],"ltp":2.32,"tv":236.56,"id":8858694}]}]}
{"op":"mcm","clk":"11936430086","pt":1724678343514,"mc":[{"id":"1.232298775","rc":[{"batb":[[0,1.75,20.83],[1,1.7,54.92],[2,1.2,125]],"ltp":1.76,"tv":315.25,"id":247649},{"batb":[[0,2.32,1.73],[1,2.3,29.57],[2,2.12,177.21]],"ltp":2.32,"tv":236.56,"id":8858694}]}]}
{"op":"mcm","clk":"11936430359","pt":1724678347038,"mc":[{"id":"1.232298775","rc":[{"batb":[[0,1.76,5],[1,1.75,20.83],[2,1.7,54.92]],"ltp":1.76,"tv":315.25,"id":247649},{"batb":[[0,2.3,29.57],[1,2.12,177.21],[2,2,34]],"ltp":2.32,"tv":236.56,"id":8858694}]}]}
{"op":"mcm","clk":"11936430649","pt":1724678350771,"mc":[{"id":"1.232298775","rc":[{"trd":[[1.76,207.13]],"batb":[[0,1.75,20.83],[1,1.7,54.92],[2,1.2,125]],"ltp":1.76,"tv":317.25,"id":247649},{"trd":[[2.32,152.06]],"batb":[[0,2.3,29.78]],"ltp":2.32,"tv":238.08,"id":8858694}],"tv":555.33}]}
{"op":"mcm","clk":"11936430931","pt":1724678354039,"mc":[{"id":"1.232298775","rc":[{"batb":[[0,1.76,5],[1,1.75,20.83],[2,1.7,54.92]],"ltp":1.76,"tv":317.25,"id":247649},{"batb":[[0,2.3,29.57]],"ltp":2.32,"tv":238.08,"id":8858694}]}]}
{"op":"mcm","clk":"11936431222","pt":1724678357255,"mc":[{"id":"1.232298775","rc":[{"batb":[[0,1.75,20.83],[1,1.7,54.92],[2,1.2,125]],"ltp":1.76,"tv":317.25,"id":247649}]}]}
{"op":"mcm","clk":"11936434028","pt":1724678390802,"mc":[{"id":"1.232298775","rc":[{"batb":[[0,1.76,19],[1,1.75,20.83],[2,1.7,54.92]],"ltp":1.76,"tv":317.25,"id":247649}]}]}
{"op":"mcm","clk":"11936437000","pt":1724678422137,"mc":[{"id":"1.232298775","rc":[{"batb":[[2,1.2,125]],"ltp":2.32,"tv":238.08,"id":8858694}]}]}
{"op":"mcm","clk":"11936468400","pt":1724678764517,"mc":[{"id":"1.232298775","rc":[{"batb":[[0,1.75,20.83],[1,1.7,54.92],[2,1.2,125]],"ltp":1.76,"tv":317.25,"id":247649}]}]}
{"op":"mcm","clk":"11936510602","pt":1724679181854,"mc":[{"id":"1.232298775","rc":[{"batb":[[0,1.76,5],[1,1.75,20.83],[2,1.7,54.92]],"ltp":1.76,"tv":317.25,"id":247649}]}]}
{"op":"mcm","clk":"11936510975","pt":1724679185153,"mc":[{"id":"1.232298775","rc":[{"batb":[[0,1.75,20.83],[1,1.7,54.92],[2,1.2,125]],"ltp":1.76,"tv":317.25,"id":247649}]}]}
{"op":"mcm","clk":"11936512046","pt":1724679194634,"mc":[{"id":"1.232298775","rc":[{"batb":[[0,1.76,5],[1,1.75,20.83],[2,1.7,54.92]],"ltp":1.76,"tv":317.25,"id":247649}]}]}
{"op":"mcm","clk":"11936512426","pt":1724679197976,"mc":[{"id":"1.232298775","rc":[{"batb":[[0,1.75,20.83],[1,1.7,54.92],[2,1.2,125]],"ltp":1.76,"tv":317.25,"id":247649}]}]}
{"op":"mcm","clk":"11936515212","pt":1724679222913,"mc":[{"id":"1.232298775","rc":[{"batb":[[0,1.76,5],[1,1.75,20.83],[2,1.7,54.92]],"ltp":1.76,"tv":317.25,"id":247649}]}]}
{"op":"mcm","clk":"11936515562","pt":1724679226205,"mc":[{"id":"1.232298775","rc":[{"batb":[[0,1.75,20.83],[1,1.7,54.92],[2,1.2,125]],"ltp":1.76,"tv":317.25,"id":247649}]}]}
{"op":"mcm","clk":"11936518846","pt":1724679256313,"mc":[{"id":"1.232298775","rc":[{"batb":[[0,1.76,5],[1,1.75,20.83],[2,1.7,54.92]],"ltp":1.76,"tv":317.25,"id":247649}]}]}
{"op":"mcm","clk":"11936519235","pt":1724679259519,"mc":[{"id":"1.232298775","rc":[{"batb":[[0,1.75,20.83],[1,1.7,54.92],[2,1.2,125]],"ltp":1.76,"tv":317.25,"id":247649}]}]}
{"op":"mcm","clk":"11936521436","pt":1724679280141,"mc":[{"id":"1.232298775","rc":[{"batb":[[0,1.76,5],[1,1.75,20.83],[2,1.7,54.92]],"ltp":1.76,"tv":317.25,"id":247649}]}]}
{"op":"mcm","clk":"11936521797","pt":1724679283545,"mc":[{"id":"1.232298775","rc":[{"batb":[[0,1.75,20.83],[1,1.7,54.92],[2,1.2,125]],"ltp":1.76,"tv":317.25,"id":247649}]}]}
{"op":"mcm","clk":"11936522984","pt":1724679294253,"mc":[{"id":"1.232298775","rc":[{"batb":[[0,1.76,5],[1,1.75,20.83],[2,1.7,54.92]],"ltp":1.76,"tv":317.25,"id":247649}]}]}
{"op":"mcm","clk":"11936523327","pt":1724679297437,"mc":[{"id":"1.232298775","rc":[{"batb":[[0,1.75,20.83],[1,1.7,54.92],[2,1.2,125]],"ltp":1.76,"tv":317.25,"id":247649}]}]}
{"op":"mcm","clk":"11936525110","pt":1724679313053,"mc":[{"id":"1.232298775","rc":[{"batb":[[0,1.76,5],[1,1.75,20.83],[2,1.7,58.3]],"ltp":1.76,"tv":317.25,"id":247649},{"batb":[[0,2.3,31.39]],"ltp":2.32,"tv":238.08,"id":8858694}]}]}
{"op":"mcm","clk":"11936525492","pt":1724679316383,"mc":[{"id":"1.232298775","rc":[{"batb":[[0,1.75,20.83],[1,1.7,58.3],[2,1.2,125]],"ltp":1.76,"tv":317.25,"id":247649}]}]}
{"op":"mcm","clk":"11936543431","pt":1724679497749,"mc":[{"id":"1.232298775","rc":[{"batb":[[0,1.76,5],[1,1.75,20.83],[2,1.7,58.3]],"ltp":1.76,"tv":317.25,"id":247649}]}]}
{"op":"mcm","clk":"11936543768","pt":1724679501247,"mc":[{"id":"1.232298775","rc":[{"batb":[[0,1.75,20.83],[1,1.7,58.3],[2,1.2,125]],"ltp":1.76,"tv":317.25,"id":247649}]}]}
{"op":"mcm","clk":"11936545763","pt":1724679521768,"mc":[{"id":"1.232298775","rc":[{"batl":[[0,1.89,80],[1,2.24,17.62],[2,2.34,3.12]],"ltp":1.76,"tv":317.25,"id":247649}]}]}
{"op":"mcm","clk":"11936564358","pt":1724679717718,"mc":[{"id":"1.232298775","rc":[{"batl":[[0,3.4,0.44]],"ltp":2.32,"tv":238.08,"id":8858694}]}]}
{"op":"mcm","clk":"11936685711","pt":1724680843821,"mc":[{"id":"1.232298775","rc":[{"trd":[[1.75,80.02]],"batb":[[0,1.7,58.3],[1,1.2,125],[2,1.05,5.19]],"batl":[[0,1.75,21.06],[1,1.89,80],[2,2.24,17.64]],"ltp":1.75,"tv":358.91,"id":247649},{"batb":[[1,2.12,177.37]],"ltp":2.32,"tv":238.08,"id":8858694}],"tv":596.99}]}
{"op":"mcm","clk":"11936690524","pt":1724680883787,"mc":[{"id":"1.232298775","rc":[{"batl":[[0,1.89,80],[1,2.24,17.64],[2,2.34,3.12]],"ltp":1.75,"tv":358.91,"id":247649}]}]}
{"op":"mcm","clk":"11936723543","pt":1724681115629,"mc":[{"id":"1.232298775","rc":[{"batb":[[0,1.71,4.38],[1,1.7,58.3],[2,1.2,125]],"ltp":1.75,"tv":358.91,"id":247649}]}]}
{"op":"mcm","clk":"11936860237","pt":1724681981812,"mc":[{"id":"1.232298775","rc":[{"batl":[[1,2.34,3.12],[2,2.34,0]],"ltp":1.75,"tv":358.91,"id":247649}]}]}
{"op":"mcm","clk":"11936923680","pt":1724682373820,"mc":[{"id":"1.232298775","rc":[{"batb":[[0,1.71,46.27]],"ltp":1.75,"tv":358.91,"id":247649}]}]}
{"op":"mcm","clk":"11936930031","pt":1724682413584,"mc":[{"id":"1.232298775","rc":[{"batb":[[0,1.71,4.38]],"ltp":1.75,"tv":358.91,"id":247649}]}]}
{"op":"mcm","clk":"11936931622","pt":1724682423505,"mc":[{"id":"1.232298775","rc":[{"trd":[[1.71,8.38]],"batb":[[0,1.7,58.49],[1,1.2,125],[2,1.05,5.19]],"ltp":1.71,"tv":367.28,"id":247649}],"tv":605.37}]}
{"op":"mcm","clk":"11936931874","pt":1724682425018,"mc":[{"id":"1.232298775","rc":[{"batb":[[0,1.7,58.3]],"ltp":1.71,"tv":367.28,"id":247649}]}]}
{"op":"mcm","clk":"11936932210","pt":1724682427002,"mc":[{"id":"1.232298775","rc":[{"batl":[[0,1.76,4.07],[1,1.89,80],[2,2.34,3.12]],"ltp":1.71,"tv":367.28,"id":247649}]}]}
{"op":"mcm","clk":"11936991233","pt":1724682780775,"mc":[{"id":"1.232298775","rc":[{"batl":[[0,1.75,14.88],[1,1.76,4.07],[2,1.89,80]],"ltp":1.71,"tv":367.28,"id":247649}]}]}
{"op":"mcm","clk":"11937233695","pt":1724684440705,"mc":[{"id":"1.232298775","rc":[{"trd":[[1.7,5.82],[1.71,8.38]],"batb":[[0,1.7,55.39]],"batl":[[1,1.76,4.07]],"ltp":1.7,"tv":373.1,"id":247649},{"batb":[[1,2.12,177.18]],"ltp":2.32,"tv":238.08,"id":8858694}],"tv":611.19}]}
{"op":"mcm","clk":"11937233798","pt":1724684441588,"mc":[{"id":"1.232298775","rc":[{"batb":[[0,1.7,58.3]],"ltp":1.7,"tv":373.1,"id":247649}]}]}
{"op":"mcm","clk":"11937507399","pt":1724686023685,"mc":[{"id":"1.232298775","rc":[{"batb":[[1,1.45,104.6],[2,1.2,125]],"ltp":1.7,"tv":373.1,"id":247649}]}]}
{"op":"mcm","clk":"11937510575","pt":1724686040562,"mc":[{"id":"1.232298775","rc":[{"batb":[[2,1.75,62.76]],"ltp":2.32,"tv":238.08,"id":8858694}]}]}
{"op":"mcm","clk":"11937540190","pt":1724686211251,"mc":[{"id":"1.232298775","rc":[{"batb":[[2,1.05,5.19]],"ltp":1.7,"tv":373.1,"id":247649}]}]}
{"op":"mcm","clk":"11937591105","pt":1724686499405,"mc":[{"id":"1.232298775","rc":[{"trd":[[1.75,82.79]],"batl":[[0,1.75,12.11]],"ltp":1.75,"tv":375.87,"id":247649},{"trd":[[2.32,154.15]],"ltp":2.32,"tv":240.17,"id":8858694}],"tv":616.05}]}
{"op":"mcm","clk":"11937594603","pt":1724686518928,"mc":[{"id":"1.232298775","rc":[{"trd":[[1.75,82.81]],"batl":[[0,1.75,12.09]],"ltp":1.75,"tv":375.89,"id":247649},{"trd":[[2.32,154.17]],"ltp":2.32,"tv":240.19,"id":8858694}],"tv":616.08}]}
{"op":"mcm","clk":"11937596221","pt":1724686527463,"mc":[{"id":"1.232298775","rc":[{"trd":[[1.75,82.83]],"batl":[[0,1.75,12.07]],"ltp":1.75,"tv":375.91,"id":247649},{"trd":[[2.32,154.18]],"ltp":2.32,"tv":240.2,"id":8858694}],"tv":616.12}]}
{"op":"mcm","clk":"11937597009","pt":1724686531582,"mc":[{"id":"1.232298775","rc":[{"trd":[[1.75,82.85]],"batl":[[0,1.75,12.05]],"ltp":1.75,"tv":375.93,"id":247649},{"trd":[[2.32,154.2]],"ltp":2.32,"tv":240.22,"id":8858694}],"tv":616.16}]}
{"op":"mcm","clk":"11937597713","pt":1724686535473,"mc":[{"id":"1.232298775","rc":[{"trd":[[1.75,82.87]],"batl":[[0,1.75,12.03]],"ltp":1.75,"tv":375.95,"id":247649},{"trd":[[2.32,154.22]],"ltp":2.32,"tv":240.24,"id":8858694}],"tv":616.2}]}
{"op":"mcm","clk":"11937600292","pt":1724686548699,"mc":[{"id":"1.232298775","rc":[{"trd":[[1.75,82.89]],"batl":[[0,1.75,12.01]],"ltp":1.75,"tv":375.97,"id":247649},{"trd":[[2.32,154.24]],"ltp":2.32,"tv":240.26,"id":8858694}],"tv":616.23}]}
{"op":"mcm","clk":"11937600956","pt":1724686551854,"mc":[{"id":"1.232298775","rc":[{"trd":[[1.75,82.91]],"batl":[[0,1.75,11.99]],"ltp":1.75,"tv":375.99,"id":247649},{"trd":[[2.32,154.25]],"ltp":2.32,"tv":240.27,"id":8858694}],"tv":616.27}]}
{"op":"mcm","clk":"11937601596","pt":1724686555271,"mc":[{"id":"1.232298775","rc":[{"trd":[[1.75,82.93]],"batl":[[0,1.75,11.97]],"ltp":1.75,"tv":376.01,"id":247649},{"trd":[[2.32,154.27]],"ltp":2.32,"tv":240.29,"id":8858694}],"tv":616.31}]}
{"op":"mcm","clk":"11937602204","pt":1724686558791,"mc":[{"id":"1.232298775","rc":[{"trd":[[1.75,82.95]],"batl":[[0,1.75,11.95]],"ltp":1.75,"tv":376.03,"id":247649},{"trd":[[2.32,154.29]],"ltp":2.32,"tv":240.31,"id":8858694}],"tv":616.35}]}
{"op":"mcm","clk":"11937602812","pt":1724686562001,"mc":[{"id":"1.232298775","rc":[{"trd":[[1.75,82.97]],"batl":[[0,1.75,11.93]],"ltp":1.75,"tv":376.05,"id":247649},{"trd":[[2.32,154.31]],"ltp":2.32,"tv":240.33,"id":8858694}],"tv":616.38}]}
{"op":"mcm","clk":"11937603555","pt":1724686565990,"mc":[{"id":"1.232298775","rc":[{"trd":[[1.75,82.99]],"batl":[[0,1.75,11.91]],"ltp":1.75,"tv":376.07,"id":247649},{"trd":[[2.32,154.32]],"ltp":2.32,"tv":240.34,"id":8858694}],"tv":616.42}]}
{"op":"mcm","clk":"11937604225","pt":1724686569672,"mc":[{"id":"1.232298775","rc":[{"trd":[[1.75,83.01]],"batl":[[0,1.75,11.89]],"ltp":1.75,"tv":376.09,"id":247649},{"trd":[[2.32,154.34]],"ltp":2.32,"tv":240.36,"id":8858694}],"tv":616.46}]}
{"op":"mcm","clk":"11937637693","pt":1724686749740,"mc":[{"id":"1.232298775","rc":[{"batb":[[1,1.75,62.76],[2,1.04,1615.24]],"ltp":2.32,"tv":240.36,"id":8858694}]}]}
{"op":"mcm","clk":"11937641106","pt":1724686767347,"mc":[{"id":"1.232298775","rc":[{"trd":[[1.7,5.93]],"batb":[[0,1.7,58.19]],"ltp":1.7,"tv":376.2,"id":247649},{"trd":[[2.44,0.08]],"ltp":2.44,"tv":240.44,"id":8858694}],"tv":616.65}]}
{"op":"mcm","clk":"11937641394","pt":1724686768842,"mc":[{"id":"1.232298775","rc":[{"batb":[[0,1.7,58.3]],"ltp":1.7,"tv":376.2,"id":247649}]}]}
{"op":"mcm","clk":"11937641929","pt":1724686771830,"mc":[{"id":"1.232298775","rc":[{"trd":[[1.7,6.04]],"batb":[[0,1.7,58.19]],"ltp":1.7,"tv":376.31,"id":247649},{"trd":[[2.44,0.16]],"ltp":2.44,"tv":240.52,"id":8858694}],"tv":616.84}]}
{"op":"mcm","clk":"11937642280","pt":1724686773727,"mc":[{"id":"1.232298775","rc":[{"batb":[[0,1.7,58.3]],"ltp":1.7,"tv":376.31,"id":247649}]}]}
{"op":"mcm","clk":"11937642608","pt":1724686775529,"mc":[{"id":"1.232298775","rc":[{"trd":[[1.7,6.07]],"batb":[[0,1.7,58.27]],"ltp":1.7,"tv":376.34,"id":247649},{"trd":[[2.44,0.18]],"ltp":2.44,"tv":240.54,"id":8858694}],"tv":616.89}]}
{"op":"mcm","clk":"11937643258","pt":1724686778859,"mc":[{"id":"1.232298775","rc":[{"batb":[[0,1.7,58.3]],"ltp":1.7,"tv":376.34,"id":247649}]}]}
{"op":"mcm","clk":"11937754300","pt":1724687363737,"mc":[{"id":"1.232298775","rc":[{"batl":[[2,1.81,1.59]],"ltp":1.7,"tv":376.34,"id":247649}]}]}
{"op":"mcm","clk":"11937824210","pt":1724687830747,"mc":[{"id":"1.232298775","rc":[{"trd":[[1.7,21.93]],"batb":[[0,1.7,50.37]],"ltp":1.7,"tv":392.2,"id":247649}],"tv":632.75}]}
{"op":"mcm","clk":"11937824415","pt":1724687832219,"mc":[{"id":"1.232298775","rc":[{"batb":[[0,1.7,58.3]],"ltp":1.7,"tv":392.2,"id":247649}]}]}
{"op":"mcm","clk":"11937841014","pt":1724687957835,"mc":[{"id":"1.232298775","rc":[{"batl":[[2,1.89,80]],"ltp":1.7,"tv":392.2,"id":247649}]}]}
{"op":"mcm","clk":"11937877859","pt":1724688188282,"mc":[{"id":"1.232298775","rc":[{"trd":[[1.7,138.54],[1.71,8.38]],"batb":[[0,1.45,104.6],[1,1.05,5.19],[2,1.04,1615.92]],"batl":[[0,1.7,141.7],[1,1.75,11.89],[2,1.76,4.07]],"ltp":1.7,"tv":508.82,"id":247649},{"batb":[[2,1.04,1615.92]],"ltp":2.44,"tv":240.54,"id":8858694}],"tv":749.36}]}
{"op":"mcm","clk":"11937878043","pt":1724688189391,"mc":[{"id":"1.232298775","rc":[{"batl":[[0,1.69,4.24],[1,1.7,141.7],[2,1.75,11.89]],"ltp":1.7,"tv":508.82,"id":247649}]}]}
{"op":"mcm","clk":"11937878725","pt":1724688193578,"mc":[{"id":"1.232298775","rc":[{"trd":[[1.66,123.68]],"batl":[[0,1.5,138.16],[1,1.69,4.24],[2,1.7,141.7]],"ltp":1.66,"tv":632.5,"id":247649}],"tv":873.04}]}
{"op":"mcm","clk":"11937878988","pt":1724688195286,"mc":[{"id":"1.232298775","rc":[{"batl":[[1,1.7,141.7],[2,1.75,11.89]],"ltp":1.66,"tv":632.5,"id":247649}]}]}
{"op":"mcm","clk":"11937879834","pt":1724688201115,"mc":[{"id":"1.232298775","rc":[{"batl":[[1,1.54,250],[2,1.7,141.7]],"ltp":1.66,"tv":632.5,"id":247649}]}]}
{"op":"mcm","clk":"11937880185","pt":1724688203502,"mc":[{"id":"1.232298775","rc":[{"batl":[[0,1.49,4.81],[1,1.5,138.16],[2,1.54,250]],"ltp":1.66,"tv":632.5,"id":247649}]}]}
{"op":"mcm","clk":"11937881837","pt":1724688214418,"mc":[{"id":"1.232298775","rc":[{"trd":[[1.49,1.19]],"batl":[[0,1.49,3.62]],"ltp":1.49,"tv":633.68,"id":247649},{"trd":[[3,0.59]],"ltp":3.0,"tv":241.13,"id":8858694}],"tv":874.82}]}
{"op":"mcm","clk":"11937884757","pt":1724688234798,"mc":[{"id":"1.232298775","rc":[{"batl":[[0,3.2,0.88]],"ltp":3.0,"tv":241.13,"id":8858694}]}]}
{"op":"mcm","clk":"11937886898","pt":1724688248708,"mc":[{"id":"1.232298775","rc":[{"trd":[[1.49,8.25]],"batl":[[0,1.5,138.25],[1,1.54,250],[2,1.58,285]],"ltp":1.49,"tv":640.74,"id":247649}],"tv":881.88}]}
{"op":"mcm","clk":"11937886982","pt":1724688249321,"mc":[{"id":"1.232298775","rc":[{"batl":[[0,1.5,138.16]],"ltp":1.49,"tv":640.74,"id":247649}]}]}
{"op":"mcm","clk":"11937887706","pt":1724688254740,"mc":[{"id":"1.232298775","rc":[{"trd":[[1.5,176.44]],"batl":[[0,1.5,49.94]],"ltp":1.5,"tv":817.18,"id":247649}],"tv":1058.32}]}
{"op":"mcm","clk":"11937889071","pt":1724688264854,"mc":[{"id":"1.232298775","rc":[{"batb":[[0,2.32,4],[1,2.3,31.39],[2,1.75,62.76]],"batl":[[0,3.2,1.76]],"ltp":3.0,"tv":241.13,"id":8858694}]}]}
{"op":"mcm","clk":"11937889427","pt":1724688266837,"mc":[{"id":"1.232298775","rc":[{"trd":[[1.5,226.38]],"batl":[[0,1.54,250],[1,1.58,285],[2,1.7,141.7]],"ltp":1.5,"tv":867.12,"id":247649},{"trd":[[3,25.56]],"batl":[[0,3,40.23],[1,3.2,1.76]],"ltp":3.0,"tv":266.1,"id":8858694}],"tv":1133.23}]}
{"op":"mcm","clk":"11937889467","pt":1724688267047,"mc":[{"id":"1.232298775","rc":[{"batb":[[0,2.3,31.39],[1,1.75,62.76],[2,1.04,1615.92]],"ltp":3.0,"tv":266.1,"id":8858694}]}]}
{"op":"mcm","clk":"11937889875","pt":1724688269560,"mc":[{"id":"1.232298775","rc":[{"batb":[[0,2.32,4],[1,2.3,31.39],[2,1.75,62.76]],"ltp":3.0,"tv":266.1,"id":8858694}]}]}
{"op":"mcm","clk":"11937890232","pt":1724688271859,"mc":[{"id":"1.232298775","rc":[{"batb":[[0,2.3,31.39],[1,1.75,62.76],[2,1.04,1615.92]],"ltp":3.0,"tv":266.1,"id":8858694}]}]}
{"op":"mcm","clk":"11937890564","pt":1724688274169,"mc":[{"id":"1.232298775","rc":[{"batb":[[0,2.32,4],[1,2.3,31.39],[2,1.75,62.76]],"ltp":3.0,"tv":266.1,"id":8858694}]}]}
{"op":"mcm","clk":"11937890977","pt":1724688276557,"mc":[{"id":"1.232298775","rc":[{"batb":[[0,2.3,31.39],[1,1.75,62.76],[2,1.04,1615.92]],"ltp":3.0,"tv":266.1,"id":8858694}]}]}
{"op":"mcm","clk":"11937891336","pt":1724688278849,"mc":[{"id":"1.232298775","rc":[{"batb":[[0,2.32,4],[1,2.3,31.39],[2,1.75,62.76]],"ltp":3.0,"tv":266.1,"id":8858694}]}]}
{"op":"mcm","clk":"11937891660","pt":1724688281280,"mc":[{"id":"1.232298775","rc":[{"batb":[[0,2.3,31.39],[1,1.75,62.76],[2,1.04,1615.92]],"ltp":3.0,"tv":266.1,"id":8858694}]}]}
{"op":"mcm","clk":"11937892066","pt":1724688283769,"mc":[{"id":"1.232298775","rc":[{"batb":[[0,2.32,4],[1,2.3,31.39],[2,1.75,62.76]],"ltp":3.0,"tv":266.1,"id":8858694}]}]}
{"op":"mcm","clk":"11937892427","pt":1724688286162,"mc":[{"id":"1.232298775","rc":[{"batb":[[0,2.3,31.39],[1,1.75,62.76],[2,1.04,1615.92]],"ltp":3.0,"tv":266.1,"id":8858694}]}]}
{"op":"mcm","clk":"11937892657","pt":1724688288080,"mc":[{"id":"1.232298775","rc":[{"trd":[[1.54,250]],"batl":[[0,1.58,285],[1,1.7,141.7],[2,1.75,11.89]],"ltp":1.54,"tv":1117.12,"id":247649},{"trd":[[2.84,135.57]],"batl":[[0,2.84,52.43],[1,3,40.23],[2,3.2,1.76]],"ltp":2.84,"tv":401.67,"id":8858694}],"tv":1518.79}]}
{"op":"mcm","clk":"11937892814","pt":1724688289172,"mc":[{"id":"1.232298775","rc":[{"batb":[[0,2.32,4],[1,2.3,31.39],[2,1.75,62.76]],"ltp":2.84,"tv":401.67,"id":8858694}]}]}
{"op":"mcm","clk":"11937893010","pt":1724688290723,"mc":[{"id":"1.232298775","rc":[{"batl":[[0,3,40.23],[1,3.2,1.76],[2,3.2,0]],"ltp":2.84,"tv":401.67,"id":8858694}]}]}
{"op":"mcm","clk":"11937893122","pt":1724688291481,"mc":[{"id":"1.232298775","rc":[{"batb":[[0,1.54,1.69],[1,1.45,104.6],[2,1.05,5.19]],"ltp":1.54,"tv":1117.12,"id":247649},{"batb":[[0,2.3,31.39],[1,1.75,62.76],[2,1.04,1615.92]],"ltp":2.84,"tv":401.67,"id":8858694}]}]}
{"op":"mcm","clk":"11937893474","pt":1724688293996,"mc":[{"id":"1.232298775","rc":[{"batb":[[0,2.32,4],[1,2.3,31.39],[2,1.75,62.76]],"ltp":2.84,"tv":401.67,"id":8858694}]}]}
{"op":"mcm","clk":"11937893817","pt":1724688296406,"mc":[{"id":"1.232298775","rc":[{"batb":[[0,2.3,31.39],[1,1.75,62.76],[2,1.04,1615.92]],"ltp":2.84,"tv":401.67,"id":8858694}]}]}
{"op":"mcm","clk":"11937894276","pt":1724688299909,"mc":[{"id":"1.232298775","rc":[{"batb":[[0,2.32,4],[1,2.3,31.39],[2,1.75,62.76]],"ltp":2.84,"tv":401.67,"id":8858694}]}]}
{"op":"mcm","clk":"11937894632","pt":1724688302220,"mc":[{"id":"1.232298775","rc":[{"batb":[[0,2.3,31.39],[1,1.75,62.76],[2,1.04,1615.92]],"ltp":2.84,"tv":401.67,"id":8858694}]}]}
{"op":"mcm","clk":"11937895508","pt":1724688308594,"mc":[{"id":"1.232298775","rc":[{"batb":[[0,2.32,4],[1,2.3,31.39],[2,1.75,62.76]],"ltp":2.84,"tv":401.67,"id":8858694}]}]}
{"op":"mcm","clk":"11937895871","pt":1724688311023,"mc":[{"id":"1.232298775","rc":[{"batb":[[0,2.3,31.39],[1,1.75,62.76],[2,1.04,1615.92]],"ltp":2.84,"tv":401.67,"id":8858694}]}]}
{"op":"mcm","clk":"11937896300","pt":1724688313749,"mc":[{"id":"1.232298775","rc":[{"batb":[[0,2.32,4],[1,2.3,31.39],[2,1.75,62.76]],"ltp":2.84,"tv":401.67,"id":8858694}]}]}
{"op":"mcm","clk":"11937896718","pt":1724688316213,"mc":[{"id":"1.232298775","rc":[{"batb":[[0,2.3,31.39],[1,1.75,62.76],[2,1.04,1615.92]],"ltp":2.84,"tv":401.67,"id":8858694}]}]}
{"op":"mcm","clk":"11937897308","pt":1724688319524,"mc":[{"id":"1.232298775","rc":[{"batl":[[0,1.57,16.41],[1,1.58,285],[2,1.7,141.7]],"ltp":1.54,"tv":1117.12,"id":247649},{"batb":[[0,2.32,4],[1,2.3,31.39],[2,1.75,62.76]],"ltp":2.84,"tv":401.67,"id":8858694}]}]}
{"op":"mcm","clk":"11937897550","pt":1724688321143,"mc":[{"id":"1.232298775","rc":[{"batb":[[0,2.3,31.39],[1,1.75,62.76],[2,1.04,1615.92]],"ltp":2.84,"tv":401.67,"id":8858694}]}]}
{"op":"mcm","clk":"11937897771","pt":1724688322433,"mc":[{"id":"1.232298775","rc":[{"trd":[[1.57,3.38]],"batb":[[0,1.45,104.6],[1,1.05,5.19],[2,1.04,1615.92]],"batl":[[0,1.57,14.72]],"ltp":1.57,"tv":1120.51,"id":247649}],"tv":1522.18}]}
{"op":"mcm","clk":"11937897997","pt":1724688323736,"mc":[{"id":"1.232298775","rc":[{"batb":[[0,1.51,6.05],[1,1.45,104.6],[2,1.05,5.19]],"ltp":1.57,"tv":1120.51,"id":247649},{"batb":[[0,2.32,4],[1,2.3,31.39],[2,1.75,62.76]],"ltp":2.84,"tv":401.67,"id":8858694}]}]}
{"op":"mcm","clk":"11937898320","pt":1724688326048,"mc":[{"id":"1.232298775","rc":[{"batb":[[0,2.3,31.39],[1,1.75,62.76],[2,1.04,1615.92]],"ltp":2.84,"tv":401.67,"id":8858694}]}]}
{"op":"mcm","clk":"11937898569","pt":1724688327760,"mc":[{"id":"1.232298775","rc":[{"batb":[[1,1.5,66],[2,1.45,104.6]],"ltp":1.57,"tv":1120.51,"id":247649}]}]}
{"op":"mcm","clk":"11937898766","pt":1724688329041,"mc":[{"id":"1.232298775","rc":[{"batb":[[0,2.32,4],[1,2.3,31.39],[2,1.75,62.76]],"ltp":2.84,"tv":401.67,"id":8858694}]}]}
{"op":"mcm","clk":"11937899118","pt":1724688331377,"mc":[{"id":"1.232298775","rc":[{"batb":[[0,2.3,31.39],[1,1.75,62.76],[2,1.04,1615.92]],"ltp":2.84,"tv":401.67,"id":8858694}]}]}
{"op":"mcm","clk":"11937899474","pt":1724688333758,"mc":[{"id":"1.232298775","rc":[{"batb":[[0,2.32,4],[1,2.3,31.39],[2,1.75,62.76]],"ltp":2.84,"tv":401.67,"id":8858694}]}]}
{"op":"mcm","clk":"11937899785","pt":1724688335961,"mc":[{"id":"1.232298775","rc":[{"batb":[[0,2.3,31.39],[1,1.75,62.76],[2,1.04,1615.92]],"ltp":2.84,"tv":401.67,"id":8858694}]}]}
{"op":"mcm","clk":"11937900307","pt":1724688339664,"mc":[{"id":"1.232298775","rc":[{"batb":[[0,2.32,4],[1,2.3,31.39],[2,1.75,62.76]],"ltp":2.84,"tv":401.67,"id":8858694}]}]}
{"op":"mcm","clk":"11937900677","pt":1724688342234,"mc":[{"id":"1.232298775","rc":[{"batb":[[0,2.3,31.39],[1,1.75,62.76],[2,1.04,1615.92]],"ltp":2.84,"tv":401.67,"id":8858694}]}]}
{"op":"mcm","clk":"11937901145","pt":1724688345382,"mc":[{"id":"1.232298775","rc":[{"batb":[[0,2.32,4],[1,2.3,31.39],[2,1.75,62.76]],"ltp":2.84,"tv":401.67,"id":8858694}]}]}
{"op":"mcm","clk":"11937901480","pt":1724688347660,"mc":[{"id":"1.232298775","rc":[{"batb":[[0,2.3,31.39],[1,1.75,62.76],[2,1.04,1615.92]],"ltp":2.84,"tv":401.67,"id":8858694}]}]}
{"op":"mcm","clk":"11937901992","pt":1724688351442,"mc":[{"id":"1.232298775","rc":[{"batb":[[0,2.32,4],[1,2.3,31.39],[2,1.75,62.76]],"ltp":2.84,"tv":401.67,"id":8858694}]}]}
{"op":"mcm","clk":"11937902313","pt":1724688353398,"mc":[{"id":"1.232298775","rc":[{"batb":[[0,2.3,31.39],[1,1.75,62.76],[2,1.04,1615.92]],"ltp":2.84,"tv":401.67,"id":8858694}]}]}
{"op":"mcm","clk":"11937902702","pt":1724688356198,"mc":[{"id":"1.232298775","rc":[{"batb":[[0,2.32,4],[1,2.3,31.39],[2,1.75,62.76]],"ltp":2.84,"tv":401.67,"id":8858694}]}]}
{"op":"mcm","clk":"11937903025","pt":1724688358577,"mc":[{"id":"1.232298775","rc":[{"batb":[[0,2.3,31.39],[1,1.75,62.76],[2,1.04,1615.92]],"ltp":2.84,"tv":401.67,"id":8858694}]}]}
{"op":"mcm","clk":"11937903386","pt":1724688361006,"mc":[{"id":"1.232298775","rc":[{"batb":[[0,2.32,4],[1,2.3,31.39],[2,1.75,62.76]],"ltp":2.84,"tv":401.67,"id":8858694}]}]}
{"op":"mcm","clk":"11937903735","pt":1724688363192,"mc":[{"id":"1.232298775","rc":[{"batb":[[0,2.3,31.39],[1,1.75,62.76],[2,1.04,1615.92]],"ltp":2.84,"tv":401.67,"id":8858694}]}]}
{"op":"mcm","clk":"11937904110","pt":1724688365694,"mc":[{"id":"1.232298775","rc":[{"batb":[[0,2.32,4],[1,2.3,31.39],[2,1.75,62.76]],"ltp":2.84,"tv":401.67,"id":8858694}]}]}
{"op":"mcm","clk":"11937904251","pt":1724688366819,"mc":[{"id":"1.232298775","rc":[{"batb":[[1,1.45,104.6],[2,1.05,5.19]],"ltp":1.57,"tv":1120.51,"id":247649}]}]}
{"op":"mcm","clk":"11937904445","pt":1724688368205,"mc":[{"id":"1.232298775","rc":[{"batb":[[0,2.3,31.39],[1,1.75,62.76],[2,1.04,1615.92]],"ltp":2.84,"tv":401.67,"id":8858694}]}]}
{"op":"mcm","clk":"11937904885","pt":1724688371325,"mc":[{"id":"1.232298775","rc":[{"batb":[[0,2.32,4],[1,2.3,31.39],[2,1.75,62.76]],"ltp":2.84,"tv":401.67,"id":8858694}]}]}
{"op":"mcm","clk":"11937905300","pt":1724688373724,"mc":[{"id":"1.232298775","rc":[{"batb":[[0,2.3,31.39],[1,1.75,62.76],[2,1.04,1615.92]],"ltp":2.84,"tv":401.67,"id":8858694}]}]}
{"op":"mcm","clk":"11937905662","pt":1724688376042,"mc":[{"id":"1.232298775","rc":[{"batb":[[0,2.32,4],[1,2.3,31.39],[2,1.75,62.76]],"ltp":2.84,"tv":401.67,"id":8858694}]}]}
{"op":"mcm","clk":"11937906074","pt":1724688378400,"mc":[{"id":"1.232298775","rc":[{"batb":[[0,2.3,31.39],[1,1.75,62.76],[2,1.04,1615.92]],"ltp":2.84,"tv":401.67,"id":8858694}]}]}
{"op":"mcm","clk":"11937906531","pt":1724688381717,"mc":[{"id":"1.232298775","rc":[{"batb":[[0,2.32,4],[1,2.3,31.39],[2,1.75,62.76]],"ltp":2.84,"tv":401.67,"id":8858694}]}]}
{"op":"mcm","clk":"11937906862","pt":1724688384129,"mc":[{"id":"1.232298775","rc":[{"batb":[[0,2.3,31.39],[1,1.75,62.76],[2,1.04,1615.92]],"ltp":2.84,"tv":401.67,"id":8858694}]}]}
{"op":"mcm","clk":"11937907180","pt":1724688386645,"mc":[{"id":"1.232298775","rc":[{"batb":[[0,2.32,4],[1,2.3,31.39],[2,1.75,62.76]],"ltp":2.84,"tv":401.67,"id":8858694}]}]}
{"op":"mcm","clk":"11937907457","pt":1724688389060,"mc":[{"id":"1.232298775","rc":[{"batb":[[0,2.3,31.39],[1,1.75,62.76],[2,1.04,1615.92]],"ltp":2.84,"tv":401.67,"id":8858694}]}]}
{"op":"mcm","clk":"11937907760","pt":1724688391535,"mc":[{"id":"1.232298775","rc":[{"batb":[[0,2.32,4],[1,2.3,31.39],[2,1.75,62.76]],"ltp":2.84,"tv":401.67,"id":8858694}]}]}
{"op":"mcm","clk":"11937908039","pt":1724688393882,"mc":[{"id":"1.232298775","rc":[{"batb":[[0,2.3,31.39],[1,1.75,62.76],[2,1.04,1615.92]],"ltp":2.84,"tv":401.67,"id":8858694}]}]}
{"op":"mcm","clk":"11937908334","pt":1724688396278,"mc":[{"id":"1.232298775","rc":[{"trd":[[1.57,19.44]],"batl":[[0,1.57,6.69]],"ltp":1.57,"tv":1136.57,"id":247649},{"batb":[[0,2.32,4],[1,2.3,31.39],[2,1.75,62.76]],"ltp":2.84,"tv":401.67,"id":8858694}],"tv":1538.24}]}
{"op":"mcm","clk":"11937908634","pt":1724688398681,"mc":[{"id":"1.232298775","rc":[{"batb":[[0,2.3,31.39],[1,1.75,62.76],[2,1.04,1615.92]],"ltp":2.84,"tv":401.67,"id":8858694}]}]}
{"op":"mcm","clk":"11937909005","pt":1724688401770,"mc":[{"id":"1.232298775","rc":[{"batb":[[0,2.32,4],[1,2.3,31.39],[2,1.75,62.76]],"ltp":2.84,"tv":401.67,"id":8858694}]}]}
{"op":"mcm","clk":"11937909281","pt":1724688404067,"mc":[{"id":"1.232298775","rc":[{"trd":[[1.57,32.82]],"batb":[[0,1.57,17.5],[1,1.51,6.05],[2,1.45,104.6]],"batl":[[0,1.58,285],[1,1.7,141.7],[2,1.75,11.89]],"ltp":1.57,"tv":1149.95,"id":247649},{"batb":[[0,2.3,31.39],[1,1.75,62.76],[2,1.04,1615.92]],"ltp":2.84,"tv":401.67,"id":8858694}],"tv":1551.62}]}
{"op":"mcm","clk":"11937909444","pt":1724688405577,"mc":[{"id":"1.232298775","rc":[{"batb":[[0,1.57,33.82],[1,1.45,104.6],[2,1.05,5.19]],"ltp":1.57,"tv":1149.95,"id":247649}]}]}
{"op":"mcm","clk":"11937909583","pt":1724688406779,"mc":[{"id":"1.232298775","rc":[{"batb":[[0,2.32,4],[1,2.3,31.39],[2,1.75,62.76]],"ltp":2.84,"tv":401.67,"id":8858694}]}]}
{"op":"mcm","clk":"11937909806","pt":1724688408676,"mc":[{"id":"1.232298775","rc":[{"trd":[[1.58,354.86]],"batl":[[0,1.58,107.57]],"ltp":1.58,"tv":1504.8,"id":247649}],"tv":1906.47}]}
{"op":"mcm","clk":"11937909855","pt":1724688409086,"mc":[{"id":"1.232298775","rc":[{"batb":[[0,2.3,31.39],[1,1.75,62.76],[2,1.04,1615.92]],"ltp":2.84,"tv":401.67,"id":8858694}]}]}
