{"op":"mcm","clk":"11993540377","pt":1725012600108,"mc":[{"id":"1.232460189","marketDefinition":{"bspMarket":false,"turnInPlayEnabled":true,"persistenceEnabled":true,"marketBaseRate":5.0,"eventId":"33540053","eventTypeId":"4","numberOfWinners":1,"bettingType":"ODDS","marketType":"MATCH_ODDS","marketTime":"2024-08-31T01:30:00.000Z","suspendTime":"2024-08-31T01:30:00.000Z","bspReconciled":false,"complete":true,"inPlay":false,"crossMatching":false,"runnersVoidable":false,"numberOfActiveRunners":2,"betDelay":0,"status":"OPEN","runners":[{"status":"ACTIVE","sortPriority":1,"id":2857968,"name":"Malaysia"},{"status":"ACTIVE","sortPriority":2,"id":73094924,"name":"Myanmar"}],"regulators":["MR_INT"],"countryCode":"GB","discountAllowed":false,"timezone":"GMT","openDate":"2024-08-31T01:30:00.000Z","version":6107623299,"name":"Match Odds","eventName":"Malaysia v Myanmar"},"rc":[{"batb":[[0,1.03,200],[1,1.02,200],[2,1.01,220]],"ltp":0.0,"tv":0.0,"id":2857968},{"batb":[[0,1.03,200],[1,1.02,200],[2,1.01,220]],"ltp":0.0,"tv":0.0,"id":73094924}]}]}
{"op":"mcm","clk":"11993540551","pt":1725012602417,"mc":[{"id":"1.232460189","marketDefinition":{"bspMarket":false,"turnInPlayEnabled":true,"persistenceEnabled":true,"marketBaseRate":5.0,"eventId":"33540053","eventTypeId":"4","numberOfWinners":1,"bettingType":"ODDS","marketType":"MATCH_ODDS","marketTime":"2024-08-31T01:30:00.000Z","suspendTime":"2024-08-31T01:30:00.000Z","bspReconciled":false,"complete":true,"inPlay":false,"crossMatching":false,"runnersVoidable":false,"numberOfActiveRunners":2,"betDelay":0,"status":"OPEN","runners":[{"status":"ACTIVE","sortPriority":1,"id":2857968,"name":"Malaysia"},{"status":"ACTIVE","sortPriority":2,"id":73094924,"name":"Myanmar"}],"regulators":["MR_INT"],"countryCode":"GB","discountAllowed":true,"timezone":"GMT","openDate":"2024-08-31T01:30:00.000Z","version":6107623299,"name":"Match Odds","eventName":"Malaysia v Myanmar"}}]}
{"op":"mcm","clk":"11993680484","pt":1725014594599,"mc":[{"id":"1.232460189","rc":[{"batb":[[0,1.04,20],[1,1.03,200],[2,1.02,200]],"ltp":0.0,"tv":0.0,"id":2857968},{"batb":[[0,1.04,20],[1,1.03,200],[2,1.02,200]],"ltp":0.0,"tv":0.0,"id":73094924}]}]}
{"op":"mcm","clk":"11993762123","pt":1725015664513,"mc":[{"id":"1.232460189","rc":[{"batb":[[0,1.2,20],[1,1.04,20],[2,1.03,200]],"ltp":0.0,"tv":0.0,"id":73094924}]}]}
{"op":"mcm","clk":"11993762725","pt":1725015671612,"mc":[{"id":"1.232460189","marketDefinition":{"bspMarket":false,"turnInPlayEnabled":true,"persistenceEnabled":true,"marketBaseRate":5.0,"eventId":"33540053","eventTypeId":"4","numberOfWinners":1,"bettingType":"ODDS","marketType":"MATCH_ODDS","marketTime":"2024-08-31T01:30:00.000Z","suspendTime":"2024-08-31T01:30:00.000Z","bspReconciled":false,"complete":true,"inPlay":false,"crossMatching":true,"runnersVoidable":false,"numberOfActiveRunners":2,"betDelay":0,"status":"OPEN","runners":[{"status":"ACTIVE","sortPriority":1,"id":2857968,"name":"Malaysia"},{"status":"ACTIVE","sortPriority":2,"id":73094924,"name":"Myanmar"}],"regulators":["MR_INT"],"countryCode":"GB","discountAllowed":true,"timezone":"GMT","openDate":"2024-08-31T01:30:00.000Z","version":6107623299,"name":"Match Odds","eventName":"Malaysia v Myanmar"}}]}
{"op":"mcm","clk":"11993778871","pt":1725015908320,"mc":[{"id":"1.232460189","rc":[{"batb":[[0,1.21,10],[1,1.2,20],[2,1.04,20]],"ltp":0.0,"tv":0.0,"id":73094924}]}]}
{"op":"mcm","clk":"11993952206","pt":1725018106395,"mc":[{"id":"1.232460189","rc":[{"batb":[[1,1.04,20],[2,1.03,200]],"ltp":0.0,"tv":0.0,"id":73094924}]}]}
{"op":"mcm","clk":"11993952217","pt":1725018106496,"mc":[{"id":"1.232460189","rc":[{"batb":[[0,1.25,20],[1,1.21,10],[2,1.04,20]],"ltp":0.0,"tv":0.0,"id":73094924}]}]}
{"op":"mcm","clk":"11993953521","pt":1725018121502,"mc":[{"id":"1.232460189","rc":[{"batb":[[0,4.9,1.52],[1,1.04,20],[2,1.03,200]],"ltp":0.0,"tv":0.0,"id":2857968}]}]}
{"op":"mcm","clk":"11993954191","pt":1725018129504,"mc":[{"id":"1.232460189","rc":[{"trd":[[4.9,3.04]],"batb":[[0,1.04,20],[1,1.03,200],[2,1.02,200]],"batl":[[0,4.9,16.98]],"ltp":4.9,"tv":3.04,"id":2857968}],"tv":3.04}]}
{"op":"mcm","clk":"11993954868","pt":1725018138414,"mc":[{"id":"1.232460189","rc":[{"batl":[[0,3,186.7],[1,4.9,16.98]],"ltp":4.9,"tv":3.04,"id":2857968}]}]}
{"op":"mcm","clk":"11993955860","pt":1725018151235,"mc":[{"id":"1.232460189","rc":[{"batl":[[0,2,186.7],[1,3,186.7],[2,4.9,16.98]],"ltp":4.9,"tv":3.04,"id":2857968}]}]}
{"op":"mcm","clk":"11993956884","pt":1725018166468,"mc":[{"id":"1.232460189","rc":[{"batl":[[0,1.3,280.04],[1,2,186.7],[2,3,186.7]],"ltp":4.9,"tv":3.04,"id":2857968}]}]}
{"op":"mcm","clk":"11993957571","pt":1725018175757,"mc":[{"id":"1.232460189","rc":[{"batb":[[0,6,14],[1,1.25,20],[2,1.21,10]],"ltp":0.0,"tv":0.0,"id":73094924}]}]}
{"op":"mcm","clk":"11994005266","pt":1725018776590,"mc":[{"id":"1.232460189","rc":[{"trd":[[1.04,20]],"batb":[[0,1.03,200],[1,1.02,200],[2,1.01,220]],"ltp":1.04,"tv":23.04,"id":2857968},{"trd":[[26,0.8]],"batb":[[0,6,14.04]],"ltp":26.0,"tv":0.8,"id":73094924}],"tv":23.84}]}
{"op":"mcm","clk":"11994072590","pt":1725019610163,"mc":[{"id":"1.232460189","rc":[{"trd":[[4.9,3.04]],"batl":[[0,1.3,279.97],[1,2,186.65],[2,3,186.65]],"ltp":1.04,"tv":23.03,"id":2857968},{"batb":[[0,7,3.04],[1,6,14],[2,1.25,20]],"ltp":26.0,"tv":0.79,"id":73094924}],"tv":23.83}]}
{"op":"mcm","clk":"11994074192","pt":1725019628004,"mc":[{"id":"1.232460189","rc":[{"trd":[[1.04,21]],"ltp":1.04,"tv":24.03,"id":2857968},{"trd":[[30,0.04]],"batb":[[0,7,3.01]],"ltp":30.0,"tv":0.83,"id":73094924}],"tv":24.87}]}
{"op":"mcm","clk":"11994080301","pt":1725019685078,"mc":[{"id":"1.232460189","rc":[{"batb":[[0,7,4.01]],"ltp":30.0,"tv":0.83,"id":73094924}]}]}
{"op":"mcm","clk":"11994118724","pt":1725020062556,"mc":[{"id":"1.232460189","rc":[{"batb":[[2,1.21,10]],"ltp":30.0,"tv":0.83,"id":73094924}]}]}
{"op":"mcm","clk":"11994132904","pt":1725020211069,"mc":[{"id":"1.232460189","rc":[{"batb":[[0,10,1.01],[1,7,3],[2,6,14]],"ltp":30.0,"tv":0.83,"id":73094924}]}]}
{"op":"mcm","clk":"11994135984","pt":1725020246028,"mc":[{"id":"1.232460189","rc":[{"batb":[[2,1.01,420]],"ltp":1.04,"tv":24.03,"id":2857968}]}]}
{"op":"mcm","clk":"11994147079","pt":1725020373566,"mc":[{"id":"1.232460189","rc":[{"batb":[[0,10,2.01]],"ltp":30.0,"tv":0.83,"id":73094924}]}]}
{"op":"mcm","clk":"11994156813","pt":1725020467622,"mc":[{"id":"1.232460189","rc":[{"trd":[[1.03,1.2]],"batb":[[0,1.02,200],[1,1.01,420],[2,1.01,0]],"ltp":1.03,"tv":25.24,"id":2857968}],"tv":26.07}]}
{"op":"mcm","clk":"11994164890","pt":1725020551751,"mc":[{"id":"1.232460189","rc":[{"batl":[[0,600,2]],"ltp":30.0,"tv":0.83,"id":73094924}]}]}
{"op":"mcm","clk":"11994172515","pt":1725020630733,"mc":[{"id":"1.232460189","rc":[{"batl":[[0,1.09,47.74],[1,1.3,279.97],[2,2,186.65]],"ltp":1.03,"tv":25.24,"id":2857968}]}]}
{"op":"mcm","clk":"11994196191","pt":1725020861333,"mc":[{"id":"1.232460189","rc":[{"batb":[[0,12.5,2.01]],"ltp":30.0,"tv":0.83,"id":73094924}]}]}
{"op":"mcm","clk":"11994215434","pt":1725021058283,"mc":[{"id":"1.232460189","rc":[{"batb":[[0,7,3.01],[1,6,14],[2,1.21,10]],"ltp":30.0,"tv":0.83,"id":73094924}]}]}
{"op":"mcm","clk":"11994216173","pt":1725021066019,"mc":[{"id":"1.232460189","rc":[{"batl":[[0,1.08,20],[1,1.09,47.74],[2,1.3,279.97]],"ltp":1.03,"tv":25.24,"id":2857968}]}]}
{"op":"mcm","clk":"11994223631","pt":1725021142754,"mc":[{"id":"1.232460189","rc":[{"batl":[[1,1.3,279.97],[2,2,186.65]],"ltp":1.03,"tv":25.24,"id":2857968}]}]}
{"op":"mcm","clk":"11994281210","pt":1725021742025,"mc":[{"id":"1.232460189","rc":[{"batl":[[0,1.07,247.58],[1,1.08,20],[2,1.3,279.97]],"ltp":1.03,"tv":25.24,"id":2857968}]}]}
{"op":"mcm","clk":"11994337801","pt":1725022146738,"mc":[{"id":"1.232460189","rc":[{"batl":[[0,1.04,773.67],[1,1.07,247.58],[2,1.08,20]],"ltp":1.03,"tv":25.24,"id":2857968}]}]}
{"op":"mcm","clk":"11994411911","pt":1725022957337,"mc":[{"id":"1.232460189","rc":[{"trd":[[1.03,1.2],[4.9,3.04]],"batl":[[0,1.04,773.47],[1,1.07,247.51]],"ltp":1.03,"tv":25.24,"id":2857968},{"trd":[[26,0.8]],"ltp":30.0,"tv":0.83,"id":73094924}],"tv":26.08}]}
{"op":"mcm","clk":"11994411920","pt":1725022957430,"mc":[{"id":"1.232460189","rc":[{"trd":[[1.04,35.33]],"batl":[[0,1.04,766.31]],"ltp":1.04,"tv":39.58,"id":2857968}],"tv":40.41}]}
{"op":"mcm","clk":"11994732681","pt":1725025633112,"mc":[{"id":"1.232460189","rc":[{"batb":[[0,27,2.01],[1,7,3],[2,6,14]],"ltp":30.0,"tv":0.83,"id":73094924}]}]}
{"op":"mcm","clk":"11994777458","pt":1725026032381,"mc":[{"id":"1.232460189","rc":[{"batl":[[2,1.2,186.74]],"ltp":1.04,"tv":39.58,"id":2857968}]}]}
{"op":"mcm","clk":"11994777469","pt":1725026032483,"mc":[{"id":"1.232460189","rc":[{"batl":[[1,1.06,20],[2,1.07,247.51]],"ltp":1.04,"tv":39.58,"id":2857968}]}]}
{"op":"mcm","clk":"11994852769","pt":1725026700727,"mc":[{"id":"1.232460189","rc":[{"trd":[[1.04,35.35],[4.9,3.05]],"batl":[[0,1.04,766.62],[2,1.07,247.61]],"ltp":1.04,"tv":39.59,"id":2857968},{"trd":[[27,1.04],[30,0.05]],"batb":[[0,27,1.48]],"ltp":27.0,"tv":1.89,"id":73094924}],"tv":41.49}]}
{"op":"mcm","clk":"11995296656","pt":1725030386663,"mc":[{"id":"1.232460189","rc":[{"trd":[[1.04,35.35]],"batl":[[0,1.04,767.3],[2,1.07,247.83]],"ltp":1.04,"tv":39.6,"id":2857968},{"batb":[[0,27,2.32]],"ltp":27.0,"tv":1.89,"id":73094924}],"tv":41.49}]}
{"op":"mcm","clk":"11995496976","pt":1725031742408,"mc":[{"id":"1.232460189","rc":[{"batb":[[0,1.01,420],[1,1.01,0]],"ltp":1.04,"tv":39.6,"id":2857968}]}]}
{"op":"mcm","clk":"11995516846","pt":1725031871697,"mc":[{"id":"1.232460189","rc":[{"trd":[[1.04,37.45]],"batl":[[0,1.04,766.25]],"ltp":1.04,"tv":41.7,"id":2857968}],"tv":43.59}]}
{"op":"mcm","clk":"11995799019","pt":1725033546573,"mc":[{"id":"1.232460189","rc":[{"batb":[[0,36,6.4],[1,27,2.32],[2,7,3]],"ltp":27.0,"tv":1.89,"id":73094924}]}]}
{"op":"mcm","clk":"11995817800","pt":1725033724705,"mc":[{"id":"1.232460189","rc":[{"trd":[[1.03,4.75],[1.04,37.43]],"batl":[[0,1.04,764.55],[2,1.07,247.28]],"ltp":1.03,"tv":45.22,"id":2857968},{"trd":[[36,0.1]],"batb":[[0,36,6.3]],"ltp":36.0,"tv":1.99,"id":73094924}],"tv":47.21}]}
{"op":"mcm","clk":"11996289360","pt":1725036526705,"mc":[{"id":"1.232460189","rc":[{"trd":[[36,0.5]],"batb":[[0,36,6.1]],"ltp":36.0,"tv":2.39,"id":73094924}],"tv":47.62}]}
{"op":"mcm","clk":"11996519818","pt":1725037975416,"mc":[{"id":"1.232460189","rc":[{"trd":[[1.03,4.75],[4.9,3.05]],"batl":[[0,1.04,764.51],[2,1.07,247.27]],"ltp":1.03,"tv":45.23,"id":2857968}],"tv":47.62}]}
{"op":"mcm","clk":"11997433410","pt":1725042333154,"mc":[{"id":"1.232460189","rc":[{"trd":[[1.03,4.75],[1.04,37.44],[4.9,3.05]],"batb":[[0,1.02,2],[1,1.01,420]],"batl":[[0,1.04,764.91],[2,1.07,247.4]],"ltp":1.03,"tv":45.24,"id":2857968}],"tv":47.64}]}
{"op":"mcm","clk":"11998403669","pt":1725046402289,"mc":[{"id":"1.232460189","rc":[{"trd":[[1.02,4],[1.03,4.75],[1.04,37.44],[4.9,3.05]],"batb":[[0,1.01,420],[1,1.01,0]],"batl":[[0,1.02,513.68],[1,1.04,765.3],[2,1.06,20]],"ltp":1.02,"tv":49.24,"id":2857968}],"tv":51.63}]}
{"op":"mcm","clk":"11998403729","pt":1725046402602,"mc":[{"id":"1.232460189","rc":[{"batb":[[0,1.01,220]],"ltp":1.02,"tv":49.24,"id":2857968}]}]}
{"op":"mcm","clk":"11998426456","pt":1725046511653,"mc":[{"id":"1.232460189","rc":[{"trd":[[1.02,517.68]],"batl":[[0,1.04,765.3],[1,1.06,20],[2,1.07,247.52]],"ltp":1.02,"tv":562.91,"id":2857968},{"trd":[[50,10.48]],"batl":[[0,50,4.52],[1,600,2]],"ltp":50.0,"tv":12.87,"id":73094924}],"tv":575.79}]}
{"op":"mcm","clk":"11998431731","pt":1725046536128,"mc":[{"id":"1.232460189","rc":[{"batl":[[0,600,2],[1,600,0]],"ltp":50.0,"tv":12.87,"id":73094924}]}]}
{"op":"mcm","clk":"11998434562","pt":1725046549125,"mc":[{"id":"1.232460189","rc":[{"trd":[[36,9.54]],"batb":[[0,36,1.58]],"ltp":36.0,"tv":21.91,"id":73094924}],"tv":584.83}]}
{"op":"mcm","clk":"11998582074","pt":1725047329580,"mc":[{"id":"1.232460189","rc":[{"batb":[[0,1.01,303.67]],"ltp":1.02,"tv":562.91,"id":2857968}]}]}
{"op":"mcm","clk":"11998590890","pt":1725047377615,"mc":[{"id":"1.232460189","rc":[{"trd":[[36,11.22]],"batb":[[0,30,1.58],[1,27,1.48]],"ltp":36.0,"tv":23.59,"id":73094924}],"tv":586.51}]}
{"op":"mcm","clk":"11998716805","pt":1725048170546,"mc":[{"id":"1.232460189","rc":[{"trd":[[1.02,517.41],[1.03,30.61],[1.04,322.37],[4.9,3.05]],"batl":[[0,1.04,622.44],[2,1.07,247.4]],"ltp":1.04,"tv":873.43,"id":2857968},{"trd":[[36,11.96]],"batb":[[0,27,2.32],[1,7,3],[2,1.51,164.76]],"ltp":36.0,"tv":24.33,"id":73094924}],"tv":897.77}]}
{"op":"mcm","clk":"11998719595","pt":1725048192766,"mc":[{"id":"1.232460189","rc":[{"batb":[[2,2.04,168.34]],"ltp":36.0,"tv":24.33,"id":73094924}]}]}
{"op":"mcm","clk":"11998737019","pt":1725048339063,"mc":[{"id":"1.232460189","rc":[{"batb":[[2,2.14,168.34]],"ltp":36.0,"tv":24.33,"id":73094924}]}]}
{"op":"mcm","clk":"11998791838","pt":1725048764981,"mc":[{"id":"1.232460189","rc":[{"trd":[[1.01,44]],"batb":[[0,1.01,281.67]],"ltp":1.01,"tv":917.43,"id":2857968}],"tv":941.77}]}
{"op":"mcm","clk":"11998964783","pt":1725050166763,"mc":[{"id":"1.232460189","rc":[{"batl":[[0,1.03,2],[1,1.04,622.44],[2,1.06,20]],"ltp":1.01,"tv":917.43,"id":2857968}]}]}
{"op":"mcm","clk":"11998988897","pt":1725050461664,"mc":[{"id":"1.232460189","rc":[{"batl":[[0,600,2.84]],"ltp":36.0,"tv":24.33,"id":73094924}]}]}
{"op":"mcm","clk":"11999010212","pt":1725050788252,"mc":[{"id":"1.232460189","rc":[{"batl":[[0,90,1.36],[1,600,2]],"ltp":36.0,"tv":24.33,"id":73094924}]}]}
{"op":"mcm","clk":"11999072920","pt":1725052030460,"mc":[{"id":"1.232460189","rc":[{"trd":[[1.02,517.33],[1.04,322.34]],"batl":[[1,1.04,1910.67]],"ltp":1.01,"tv":917.32,"id":2857968},{"batb":[[2,2.14,168.32]],"ltp":36.0,"tv":24.33,"id":73094924}],"tv":941.66}]}
{"op":"mcm","clk":"11999078120","pt":1725052161043,"mc":[{"id":"1.232460189","rc":[{"batl":[[0,1.02,1.52],[1,1.03,2],[2,1.04,1910.67]],"ltp":1.01,"tv":917.32,"id":2857968}]}]}
{"op":"mcm","clk":"11999078970","pt":1725052182875,"mc":[{"id":"1.232460189","rc":[{"batl":[[0,1.03,2],[1,1.04,1910.67],[2,1.06,20]],"ltp":1.01,"tv":917.32,"id":2857968}]}]}
{"op":"mcm","clk":"11999079190","pt":1725052189072,"mc":[{"id":"1.232460189","rc":[{"trd":[[1.03,33.65]],"batl":[[0,1.04,1911.15],[1,1.06,20],[2,1.07,247.36]],"ltp":1.03,"tv":920.36,"id":2857968}],"tv":944.7}]}
{"op":"mcm","clk":"11999079531","pt":1725052200396,"mc":[{"id":"1.232460189","rc":[{"trd":[[1.03,34.61]],"batb":[[0,1.03,1.04],[1,1.01,281.67]],"batl":[[0,1.04,1910.67]],"ltp":1.03,"tv":921.32,"id":2857968}],"tv":945.66}]}
{"op":"mcm","clk":"11999079953","pt":1725052211323,"mc":[{"id":"1.232460189","rc":[{"batb":[[0,1.01,281.67],[1,1.01,0]],"ltp":1.03,"tv":921.32,"id":2857968}]}]}
{"op":"mcm","clk":"11999082758","pt":1725052288107,"mc":[{"id":"1.232460189","rc":[{"batl":[[0,1.02,1.52],[1,1.04,1910.67],[2,1.06,20]],"ltp":1.03,"tv":921.32,"id":2857968}]}]}
{"op":"mcm","clk":"11999083174","pt":1725052298998,"mc":[{"id":"1.232460189","rc":[{"batl":[[0,1.04,1910.67],[1,1.06,20],[2,1.07,247.36]],"ltp":1.03,"tv":921.32,"id":2857968}]}]}
{"op":"mcm","clk":"11999089378","pt":1725052461625,"mc":[{"id":"1.232460189","rc":[{"batb":[[0,1.01,283.67]],"ltp":1.03,"tv":921.32,"id":2857968}]}]}
{"op":"mcm","clk":"11999090988","pt":1725052504233,"mc":[{"id":"1.232460189","rc":[{"batb":[[0,1.03,1.52],[1,1.01,283.67]],"ltp":1.03,"tv":921.32,"id":2857968}]}]}
{"op":"mcm","clk":"11999091448","pt":1725052516578,"mc":[{"id":"1.232460189","rc":[{"batb":[[0,1.01,283.67],[1,1.01,0]],"ltp":1.03,"tv":921.32,"id":2857968}]}]}
{"op":"mcm","clk":"11999093669","pt":1725052584154,"mc":[{"id":"1.232460189","rc":[{"batl":[[0,1.02,1.52],[1,1.04,1910.67],[2,1.06,20]],"ltp":1.03,"tv":921.32,"id":2857968}]}]}
{"op":"mcm","clk":"11999094117","pt":1725052597182,"mc":[{"id":"1.232460189","rc":[{"batl":[[0,1.04,1910.67],[1,1.06,20],[2,1.07,247.36]],"ltp":1.03,"tv":921.32,"id":2857968}]}]}
{"op":"mcm","clk":"11999095876","pt":1725052640762,"mc":[{"id":"1.232460189","rc":[{"batb":[[0,1.03,1.52],[1,1.01,283.67]],"ltp":1.03,"tv":921.32,"id":2857968}]}]}
{"op":"mcm","clk":"11999096297","pt":1725052651743,"mc":[{"id":"1.232460189","rc":[{"batb":[[0,1.01,283.67],[1,1.01,0]],"ltp":1.03,"tv":921.32,"id":2857968}]}]}
{"op":"mcm","clk":"11999097068","pt":1725052670304,"mc":[{"id":"1.232460189","rc":[{"batl":[[0,1.02,1.52],[1,1.04,1910.67],[2,1.06,20]],"ltp":1.03,"tv":921.32,"id":2857968}]}]}
{"op":"mcm","clk":"11999097572","pt":1725052682812,"mc":[{"id":"1.232460189","rc":[{"batl":[[0,1.04,1910.67],[1,1.06,20],[2,1.07,247.36]],"ltp":1.03,"tv":921.32,"id":2857968}]}]}
{"op":"mcm","clk":"11999098470","pt":1725052702896,"mc":[{"id":"1.232460189","rc":[{"batb":[[0,1.03,1.52],[1,1.01,283.67]],"ltp":1.03,"tv":921.32,"id":2857968}]}]}
{"op":"mcm","clk":"11999099030","pt":1725052715346,"mc":[{"id":"1.232460189","rc":[{"batb":[[0,1.01,283.67],[1,1.01,0]],"ltp":1.03,"tv":921.32,"id":2857968}]}]}
{"op":"mcm","clk":"11999099741","pt":1725052730177,"mc":[{"id":"1.232460189","rc":[{"batl":[[0,1.02,1.52],[1,1.04,1910.67],[2,1.06,20]],"ltp":1.03,"tv":921.32,"id":2857968}]}]}
{"op":"mcm","clk":"11999101761","pt":1725052774532,"mc":[{"id":"1.232460189","rc":[{"batl":[[0,1.04,1910.67],[1,1.06,20],[2,1.07,247.36]],"ltp":1.03,"tv":921.32,"id":2857968}]}]}
{"op":"mcm","clk":"11999102155","pt":1725052783546,"mc":[{"id":"1.232460189","rc":[{"batb":[[0,1.03,2.29],[1,1.01,283.67]],"ltp":1.03,"tv":921.32,"id":2857968}]}]}
{"op":"mcm","clk":"11999103259","pt":1725052806671,"mc":[{"id":"1.232460189","rc":[{"batb":[[0,1.01,283.67],[1,1.01,0]],"ltp":1.03,"tv":921.32,"id":2857968}]}]}
{"op":"mcm","clk":"11999105457","pt":1725052851415,"mc":[{"id":"1.232460189","rc":[{"batl":[[0,1.02,1.52],[1,1.04,1910.67],[2,1.06,20]],"ltp":1.03,"tv":921.32,"id":2857968}]}]}
{"op":"mcm","clk":"11999105969","pt":1725052862633,"mc":[{"id":"1.232460189","rc":[{"batl":[[0,1.04,1910.67],[1,1.06,20],[2,1.07,247.36]],"ltp":1.03,"tv":921.32,"id":2857968}]}]}
{"op":"mcm","clk":"11999107060","pt":1725052883963,"mc":[{"id":"1.232460189","rc":[{"batb":[[0,1.03,1.52],[1,1.01,283.67]],"ltp":1.03,"tv":921.32,"id":2857968}]}]}
{"op":"mcm","clk":"11999107492","pt":1725052894175,"mc":[{"id":"1.232460189","rc":[{"batb":[[0,1.01,283.67],[1,1.01,0]],"ltp":1.03,"tv":921.32,"id":2857968}]}]}
{"op":"mcm","clk":"11999109255","pt":1725052934104,"mc":[{"id":"1.232460189","rc":[{"batl":[[0,1.02,1.52],[1,1.04,1910.67],[2,1.06,20]],"ltp":1.03,"tv":921.32,"id":2857968}]}]}
{"op":"mcm","clk":"11999109744","pt":1725052945954,"mc":[{"id":"1.232460189","rc":[{"batl":[[0,1.04,1910.67],[1,1.06,20],[2,1.07,247.36]],"ltp":1.03,"tv":921.32,"id":2857968}]}]}
{"op":"mcm","clk":"11999110415","pt":1725052961166,"mc":[{"id":"1.232460189","rc":[{"batb":[[0,1.03,1.52],[1,1.01,283.67]],"ltp":1.03,"tv":921.32,"id":2857968}]}]}
{"op":"mcm","clk":"11999110757","pt":1725052970186,"mc":[{"id":"1.232460189","rc":[{"batb":[[0,1.01,283.67],[1,1.01,0]],"ltp":1.03,"tv":921.32,"id":2857968}]}]}
{"op":"mcm","clk":"11999111108","pt":1725052980109,"mc":[{"id":"1.232460189","rc":[{"batl":[[0,1.02,1.52],[1,1.04,1910.67],[2,1.06,20]],"ltp":1.03,"tv":921.32,"id":2857968}]}]}
{"op":"mcm","clk":"11999111783","pt":1725052994015,"mc":[{"id":"1.232460189","rc":[{"batl":[[0,600,2.52],[1,600,0]],"ltp":36.0,"tv":24.33,"id":73094924}]}]}
{"op":"mcm","clk":"11999112370","pt":1725053006527,"mc":[{"id":"1.232460189","rc":[{"batl":[[0,1.04,1910.67],[1,1.06,20],[2,1.07,247.36]],"ltp":1.03,"tv":921.32,"id":2857968}]}]}
{"op":"mcm","clk":"11999112615","pt":1725053012925,"mc":[{"id":"1.232460189","rc":[{"batb":[[0,1.03,2.29],[1,1.01,283.67]],"ltp":1.03,"tv":921.32,"id":2857968}]}]}
{"op":"mcm","clk":"11999113124","pt":1725053028786,"mc":[{"id":"1.232460189","rc":[{"batb":[[0,1.01,283.67],[1,1.01,0]],"ltp":1.03,"tv":921.32,"id":2857968}]}]}
{"op":"mcm","clk":"11999114265","pt":1725053069419,"mc":[{"id":"1.232460189","rc":[{"batl":[[0,1.02,1.52],[1,1.04,1910.67],[2,1.06,20]],"ltp":1.03,"tv":921.32,"id":2857968}]}]}
{"op":"mcm","clk":"11999114572","pt":1725053079921,"mc":[{"id":"1.232460189","rc":[{"batl":[[0,1.04,1910.67],[1,1.06,20],[2,1.07,247.36]],"ltp":1.03,"tv":921.32,"id":2857968}]}]}
{"op":"mcm","clk":"11999114872","pt":1725053089506,"mc":[{"id":"1.232460189","rc":[{"batb":[[0,1.03,1.52],[1,1.01,283.67]],"ltp":1.03,"tv":921.32,"id":2857968}]}]}
{"op":"mcm","clk":"11999115258","pt":1725053102460,"mc":[{"id":"1.232460189","rc":[{"batb":[[0,1.01,283.67],[1,1.01,0]],"ltp":1.03,"tv":921.32,"id":2857968}]}]}
{"op":"mcm","clk":"11999115750","pt":1725053117180,"mc":[{"id":"1.232460189","rc":[{"batl":[[0,1.02,1.52],[1,1.04,1910.67],[2,1.06,20]],"ltp":1.03,"tv":921.32,"id":2857968}]}]}
{"op":"mcm","clk":"11999116104","pt":1725053129394,"mc":[{"id":"1.232460189","rc":[{"batl":[[0,1.04,1910.67],[1,1.06,20],[2,1.07,247.36]],"ltp":1.03,"tv":921.32,"id":2857968}]}]}
{"op":"mcm","clk":"11999116520","pt":1725053141805,"mc":[{"id":"1.232460189","rc":[{"batb":[[0,1.03,1.52],[1,1.01,283.67]],"ltp":1.03,"tv":921.32,"id":2857968}]}]}
{"op":"mcm","clk":"11999116877","pt":1725053153706,"mc":[{"id":"1.232460189","rc":[{"batb":[[0,1.01,283.67],[1,1.01,0]],"ltp":1.03,"tv":921.32,"id":2857968}]}]}
{"op":"mcm","clk":"11999140620","pt":1725053840926,"mc":[{"id":"1.232460189","rc":[{"batb":[[0,1.03,2.29],[1,1.01,283.67]],"ltp":1.03,"tv":921.32,"id":2857968}]}]}
{"op":"mcm","clk":"11999140698","pt":1725053842993,"mc":[{"id":"1.232460189","rc":[{"batb":[[0,1.01,283.67],[1,1.01,0]],"ltp":1.03,"tv":921.32,"id":2857968}]}]}
{"op":"mcm","clk":"11999140987","pt":1725053850118,"mc":[{"id":"1.232460189","rc":[{"batb":[[0,1.01,285.19]],"ltp":1.03,"tv":921.32,"id":2857968}]}]}
{"op":"mcm","clk":"11999141050","pt":1725053852112,"mc":[{"id":"1.232460189","rc":[{"batb":[[0,1.01,283.67]],"ltp":1.03,"tv":921.32,"id":2857968}]}]}
{"op":"mcm","clk":"11999141260","pt":1725053859130,"mc":[{"id":"1.232460189","rc":[{"batb":[[0,1.02,1.52],[1,1.01,283.67]],"ltp":1.03,"tv":921.32,"id":2857968}]}]}
{"op":"mcm","clk":"11999141990","pt":1725053879421,"mc":[{"id":"1.232460189","rc":[{"batb":[[0,1.01,283.67],[1,1.01,0]],"ltp":1.03,"tv":921.32,"id":2857968}]}]}
{"op":"mcm","clk":"11999142906","pt":1725053902748,"mc":[{"id":"1.232460189","rc":[{"trd":[[1.04,325.39]],"batl":[[0,1.04,1909.14]],"ltp":1.04,"tv":924.37,"id":2857968}],"tv":948.71}]}
{"op":"mcm","clk":"11999249593","pt":1725056449906,"mc":[{"id":"1.232460189","rc":[{"trd":[[1.02,517.28],[1.03,34.63],[1.04,325.48]],"batl":[[0,1.04,1908.95],[2,1.2,186.98]],"ltp":1.04,"tv":924.43,"id":2857968},{"batb":[[2,2.14,168.45]],"ltp":36.0,"tv":24.33,"id":73094924}],"tv":948.77}]}
{"op":"mcm","clk":"11999252692","pt":1725056536082,"mc":[{"id":"1.232460189","rc":[{"batb":[[0,1.01,449.85]],"ltp":1.04,"tv":924.43,"id":2857968}]}]}
{"op":"mcm","clk":"11999264397","pt":1725056877646,"mc":[{"id":"1.232460189","rc":[{"trd":[[1.01,971.76]],"batl":[[0,1.01,1522.09],[1,1.04,1908.95],[2,1.06,20]],"ltp":1.01,"tv":1852.19,"id":2857968},{"trd":[[55,0.52]],"batl":[[0,600,2]],"ltp":55.0,"tv":24.85,"id":73094924}],"tv":1877.05}]}
{"op":"mcm","clk":"11999281481","pt":1725057392374,"mc":[{"id":"1.232460189","rc":[{"batl":[[1,1.02,201],[2,1.04,1908.95]],"ltp":1.01,"tv":1852.19,"id":2857968}]}]}
{"op":"mcm","clk":"11999288533","pt":1725057616930,"mc":[{"id":"1.232460189","rc":[{"batl":[[2,1.03,125.51]],"ltp":1.01,"tv":1852.19,"id":2857968}]}]}
{"op":"mcm","clk":"11999289132","pt":1725057634557,"mc":[{"id":"1.232460189","rc":[{"batl":[[0,600,2.84]],"ltp":55.0,"tv":24.85,"id":73094924}]}]}
{"op":"mcm","clk":"11999303482","pt":1725058044694,"mc":[{"id":"1.232460189","rc":[{"trd":[[1.01,1589.96]],"batl":[[0,1.01,1212.99]],"ltp":1.01,"tv":2470.4,"id":2857968}],"tv":2495.25}]}
{"op":"mcm","clk":"11999394795","pt":1725059619360,"mc":[{"id":"1.232460189","rc":[{"batl":[[1,1.02,200]],"ltp":1.01,"tv":2470.4,"id":2857968}]}]}
{"op":"mcm","clk":"11999471090","pt":1725060951121,"mc":[{"id":"1.232460189","rc":[{"batb":[[2,3.95,3.61]],"batl":[[0,550,1.55],[1,600,2.84]],"ltp":55.0,"tv":24.85,"id":73094924}]}]}
{"op":"mcm","clk":"11999512215","pt":1725061675635,"mc":[{"id":"1.232460189","rc":[{"trd":[[1.01,1787.98]],"batl":[[0,1.01,1014.97]],"ltp":1.01,"tv":2668.42,"id":2857968},{"trd":[[100,2]],"ltp":100.0,"tv":26.85,"id":73094924}],"tv":2695.27}]}
{"op":"mcm","clk":"11999515595","pt":1725061731646,"mc":[{"id":"1.232460189","rc":[{"batl":[[0,1.01,1075.34]],"ltp":1.01,"tv":2668.42,"id":2857968}]}]}
{"op":"mcm","clk":"11999523767","pt":1725061848341,"mc":[{"id":"1.232460189","rc":[{"batb":[[0,7,3.84],[1,3.95,3.61],[2,2.14,168.45]],"ltp":100.0,"tv":26.85,"id":73094924}]}]}
{"op":"mcm","clk":"11999603183","pt":1725063144672,"mc":[{"id":"1.232460189","rc":[{"trd":[[1.01,1804.74]],"batl":[[0,1.01,1066.96]],"ltp":1.01,"tv":2685.18,"id":2857968}],"tv":2712.03}]}
{"op":"mcm","clk":"11999661931","pt":1725064057766,"mc":[{"id":"1.232460189","rc":[{"batl":[[0,1.01,60.37]],"ltp":1.01,"tv":2685.18,"id":2857968}]}]}
{"op":"mcm","clk":"11999712694","pt":1725064801686,"mc":[{"id":"1.232460189","rc":[{"batl":[[0,1.01,149.74]],"ltp":1.01,"tv":2685.18,"id":2857968}]}]}
{"op":"mcm","clk":"11999723469","pt":1725064943747,"mc":[{"id":"1.232460189","rc":[{"batl":[[0,550,2.39]],"ltp":100.0,"tv":26.85,"id":73094924}]}]}
{"op":"mcm","clk":"11999723581","pt":1725064945235,"mc":[{"id":"1.232460189","rc":[{"batl":[[0,540,2.39]],"ltp":100.0,"tv":26.85,"id":73094924}]}]}
{"op":"mcm","clk":"11999725132","pt":1725064966707,"mc":[{"id":"1.232460189","rc":[{"trd":[[1.01,1972.08]],"batl":[[0,1.01,66.07]],"ltp":1.01,"tv":2852.52,"id":2857968}],"tv":2879.37}]}
{"op":"mcm","clk":"11999784847","pt":1725065534151,"mc":[{"id":"1.232460189","rc":[{"trd":[[540,1.68]],"batb":[[1,2.14,168.45],[2,2.08,168.45]],"batl":[[0,600,2.84],[1,600,0]],"ltp":540.0,"tv":28.53,"id":73094924}],"tv":2881.05}]}
{"op":"mcm","clk":"11999820417","pt":1725066053676,"mc":[{"id":"1.232460189","rc":[{"trd":[[1.01,2104.22],[1.02,517.22],[1.04,325.47]],"batb":[[0,1.01,36.93]],"batl":[[0,1.02,200],[1,1.03,125.51],[2,1.04,1908.75]],"ltp":1.01,"tv":2984.59,"id":2857968}],"tv":3013.12}]}
{"op":"mcm","clk":"11999821814","pt":1725066073526,"mc":[{"id":"1.232460189","rc":[{"batl":[[0,1.02,204]],"ltp":1.01,"tv":2984.59,"id":2857968}]}]}
{"op":"mcm","clk":"11999831961","pt":1725066217681,"mc":[{"id":"1.232460189","rc":[{"trd":[[1.01,2178.08]],"batl":[[0,1.01,381.91],[1,1.02,204],[2,1.03,125.51]],"ltp":1.01,"tv":3058.45,"id":2857968}],"tv":3086.98}]}
{"op":"mcm","clk":"11999832618","pt":1725066227962,"mc":[{"id":"1.232460189","rc":[{"batl":[[0,1.02,204],[1,1.03,125.51],[2,1.04,1908.75]],"ltp":1.01,"tv":3058.45,"id":2857968}]}]}
{"op":"mcm","clk":"11999833094","pt":1725066235993,"mc":[{"id":"1.232460189","rc":[{"batb":[[0,1.01,97.64]],"ltp":1.01,"tv":3058.45,"id":2857968}]}]}
{"op":"mcm","clk":"11999833594","pt":1725066243220,"mc":[{"id":"1.232460189","rc":[{"batl":[[1,1.03,209.18]],"ltp":1.01,"tv":3058.45,"id":2857968}]}]}
{"op":"mcm","clk":"11999834296","pt":1725066253824,"mc":[{"id":"1.232460189","rc":[{"batb":[[0,55,6.71],[1,7,3.84],[2,2.14,168.45]],"ltp":540.0,"tv":28.53,"id":73094924}]}]}
{"op":"mcm","clk":"11999834494","pt":1725066257008,"mc":[{"id":"1.232460189","rc":[{"batl":[[1,1.03,125.51]],"ltp":1.01,"tv":3058.45,"id":2857968}]}]}
{"op":"mcm","clk":"11999834913","pt":1725066263735,"mc":[{"id":"1.232460189","rc":[{"batl":[[0,1.02,287.67]],"ltp":1.01,"tv":3058.45,"id":2857968}]}]}
{"op":"mcm","clk":"11999836343","pt":1725066284755,"mc":[{"id":"1.232460189","rc":[{"batb":[[0,1.01,9.14]],"ltp":1.01,"tv":3058.45,"id":2857968}]}]}
{"op":"mcm","clk":"11999836710","pt":1725066290251,"mc":[{"id":"1.232460189","rc":[{"batb":[[0,7,3.84],[1,2.14,168.45],[2,2.08,168.45]],"ltp":540.0,"tv":28.53,"id":73094924}]}]}
{"op":"mcm","clk":"11999836956","pt":1725066294656,"mc":[{"id":"1.232460189","rc":[{"trd":[[1.01,2196.36]],"batl":[[0,1.01,367.82],[1,1.02,287.67],[2,1.03,125.51]],"ltp":1.01,"tv":3076.73,"id":2857968}],"tv":3105.26}]}
{"op":"mcm","clk":"11999837363","pt":1725066300668,"mc":[{"id":"1.232460189","rc":[{"trd":[[1.01,2283.97]],"batl":[[0,1.01,280.21]],"ltp":1.01,"tv":3164.34,"id":2857968},{"trd":[[100,2.88]],"ltp":100.0,"tv":29.41,"id":73094924}],"tv":3193.75}]}
{"op":"mcm","clk":"11999839047","pt":1725066327319,"mc":[{"id":"1.232460189","rc":[{"trd":[[1.01,2311.05]],"batl":[[0,1.01,253.13]],"ltp":1.01,"tv":3191.42,"id":2857968},{"trd":[[100,3.16]],"ltp":100.0,"tv":29.69,"id":73094924}],"tv":3221.11}]}
{"op":"mcm","clk":"11999839474","pt":1725066334115,"mc":[{"id":"1.232460189","rc":[{"batb":[[0,22,1.68],[1,7,3],[2,2.14,168.45]],"ltp":100.0,"tv":29.69,"id":73094924}]}]}
{"op":"mcm","clk":"11999840427","pt":1725066348249,"mc":[{"id":"1.232460189","rc":[{"batl":[[0,150,2],[1,600,2.84]],"ltp":100.0,"tv":29.69,"id":73094924}]}]}
{"op":"mcm","clk":"11999840506","pt":1725066349433,"mc":[{"id":"1.232460189","rc":[{"trd":[[1.01,2320.72]],"batl":[[0,1.01,243.46]],"ltp":1.01,"tv":3201.09,"id":2857968},{"trd":[[100,3.26]],"ltp":100.0,"tv":29.78,"id":73094924}],"tv":3230.87}]}
{"op":"mcm","clk":"11999842719","pt":1725066383183,"mc":[{"id":"1.232460189","rc":[{"trd":[[1.01,2807.64]],"batb":[[0,1.01,56.54]],"batl":[[0,1.02,287.67],[1,1.03,125.51],[2,1.04,1908.75]],"ltp":1.01,"tv":3688.01,"id":2857968}],"tv":3717.79}]}
{"op":"mcm","clk":"11999843682","pt":1725066396672,"mc":[{"id":"1.232460189","rc":[{"batl":[[1,590,1.68],[2,600,2]],"ltp":100.0,"tv":29.78,"id":73094924}]}]}
{"op":"mcm","clk":"11999844469","pt":1725066408227,"mc":[{"id":"1.232460189","rc":[{"batb":[[0,7,3.84],[1,2.14,168.45],[2,2.08,168.45]],"ltp":100.0,"tv":29.78,"id":73094924}]}]}
{"op":"mcm","clk":"11999844550","pt":1725066409303,"mc":[{"id":"1.232460189","rc":[{"batl":[[1,600,2.84],[2,600,0]],"ltp":100.0,"tv":29.78,"id":73094924}]}]}
{"op":"mcm","clk":"11999845402","pt":1725066422910,"mc":[{"id":"1.232460189","rc":[{"batl":[[1,580,1.68],[2,600,2]],"ltp":100.0,"tv":29.78,"id":73094924}]}]}
{"op":"mcm","clk":"11999848931","pt":1725066479407,"mc":[{"id":"1.232460189","rc":[{"trd":[[1.02,522.01]],"batl":[[0,1.02,282.88]],"ltp":1.02,"tv":3692.8,"id":2857968},{"trd":[[50,10.58]],"ltp":50.0,"tv":29.88,"id":73094924}],"tv":3722.68}]}
{"op":"mcm","clk":"11999849090","pt":1725066481572,"mc":[{"id":"1.232460189","rc":[{"trd":[[1.02,526.8]],"batl":[[0,1.02,278.09]],"ltp":1.02,"tv":3697.59,"id":2857968},{"trd":[[50,10.68]],"ltp":50.0,"tv":29.98,"id":73094924}],"tv":3727.57}]}
{"op":"mcm","clk":"11999849795","pt":1725066491680,"mc":[{"id":"1.232460189","rc":[{"batl":[[0,1.02,535.7]],"ltp":1.02,"tv":3697.59,"id":2857968}]}]}
{"op":"mcm","clk":"11999849963","pt":1725066494304,"mc":[{"id":"1.232460189","rc":[{"batl":[[0,1.02,793.31]],"ltp":1.02,"tv":3697.59,"id":2857968}]}]}
{"op":"mcm","clk":"11999850304","pt":1725066498998,"mc":[{"id":"1.232460189","rc":[{"batl":[[1,600,2.84],[2,600,0]],"ltp":50.0,"tv":29.98,"id":73094924}]}]}
{"op":"mcm","clk":"11999850618","pt":1725066503499,"mc":[{"id":"1.232460189","rc":[{"batl":[[1,1.04,1908.75],[2,1.06,20]],"ltp":1.02,"tv":3697.59,"id":2857968}]}]}
{"op":"mcm","clk":"11999854952","pt":1725066571296,"mc":[{"id":"1.232460189","rc":[{"trd":[[1.02,540.3]],"batl":[[0,1.02,779.81]],"ltp":1.02,"tv":3711.09,"id":2857968},{"trd":[[50,10.95]],"ltp":50.0,"tv":30.25,"id":73094924}],"tv":3741.35}]}
{"op":"mcm","clk":"11999858104","pt":1725066620724,"mc":[{"id":"1.232460189","rc":[{"trd":[[1.02,545.09]],"batl":[[0,1.02,775.02]],"ltp":1.02,"tv":3715.88,"id":2857968},{"trd":[[50,11.05]],"ltp":50.0,"tv":30.35,"id":73094924}],"tv":3746.23}]}
{"op":"mcm","clk":"11999867448","pt":1725066744554,"mc":[{"id":"1.232460189","rc":[{"batl":[[0,130,2]],"ltp":50.0,"tv":30.35,"id":73094924}]}]}
{"op":"mcm","clk":"11999869147","pt":1725066768903,"mc":[{"id":"1.232460189","rc":[{"batl":[[0,1.01,3864.19],[1,1.02,775.02],[2,1.04,1908.75]],"ltp":1.02,"tv":3715.88,"id":2857968}]}]}
{"op":"mcm","clk":"11999870392","pt":1725066787533,"mc":[{"id":"1.232460189","rc":[{"trd":[[1.01,2811.29]],"batl":[[0,1.01,3862.36]],"ltp":1.01,"tv":3719.53,"id":2857968}],"tv":3749.88}]}
{"op":"mcm","clk":"11999870802","pt":1725066793209,"mc":[{"id":"1.232460189","rc":[{"trd":[[1.01,2820.96]],"batl":[[0,1.01,3852.69]],"ltp":1.01,"tv":3729.2,"id":2857968},{"trd":[[100,3.35]],"ltp":100.0,"tv":30.45,"id":73094924}],"tv":3759.65}]}
{"op":"mcm","clk":"11999870869","pt":1725066794132,"mc":[{"id":"1.232460189","rc":[{"trd":[[1.01,2824.61]],"batl":[[0,1.01,3850.87]],"ltp":1.01,"tv":3732.85,"id":2857968}],"tv":3763.3}]}
{"op":"mcm","clk":"11999871364","pt":1725066801319,"mc":[{"id":"1.232460189","rc":[{"trd":[[1.01,2828.26]],"batl":[[0,1.01,3849.04]],"ltp":1.01,"tv":3736.5,"id":2857968}],"tv":3766.95}]}
{"op":"mcm","clk":"11999871784","pt":1725066807422,"mc":[{"id":"1.232460189","rc":[{"trd":[[1.01,2831.91]],"batl":[[0,1.01,3847.22]],"ltp":1.01,"tv":3740.15,"id":2857968}],"tv":3770.6}]}
{"op":"mcm","clk":"11999872234","pt":1725066813546,"mc":[{"id":"1.232460189","rc":[{"trd":[[1.01,2835.56]],"batl":[[0,1.01,3845.4]],"ltp":1.01,"tv":3743.8,"id":2857968}],"tv":3774.25}]}
{"op":"mcm","clk":"11999875699","pt":1725066863624,"mc":[{"id":"1.232460189","rc":[{"trd":[[1.01,2844.36]],"batl":[[0,1.01,3836.6]],"ltp":1.01,"tv":3752.6,"id":2857968},{"trd":[[100,3.44]],"ltp":100.0,"tv":30.54,"id":73094924}],"tv":3783.14}]}
{"op":"mcm","clk":"11999878071","pt":1725066899658,"mc":[{"id":"1.232460189","rc":[{"trd":[[110,4]],"batl":[[0,600,2.84],[1,600,0]],"ltp":110.0,"tv":34.54,"id":73094924}],"tv":3787.14}]}
{"op":"mcm","clk":"11999883287","pt":1725066970970,"mc":[{"id":"1.232460189","rc":[{"trd":[[120,4.16]],"batl":[[0,120,2.63],[1,600,2.84]],"ltp":120.0,"tv":38.7,"id":73094924}],"tv":3791.3}]}
{"op":"mcm","clk":"11999885547","pt":1725067001087,"mc":[{"id":"1.232460189","rc":[{"trd":[[1.01,2854.03]],"batl":[[0,1.01,3826.93]],"ltp":1.01,"tv":3762.27,"id":2857968},{"trd":[[100,3.54]],"ltp":100.0,"tv":38.8,"id":73094924}],"tv":3801.07}]}
{"op":"mcm","clk":"11999885601","pt":1725067001657,"mc":[{"id":"1.232460189","rc":[{"batl":[[0,110,2.63]],"ltp":100.0,"tv":38.8,"id":73094924}]}]}
{"op":"mcm","clk":"11999886522","pt":1725067012800,"mc":[{"id":"1.232460189","rc":[{"trd":[[1.01,2863.7]],"batl":[[0,1.01,3817.25]],"ltp":1.01,"tv":3771.94,"id":2857968},{"trd":[[100,3.64]],"ltp":100.0,"tv":38.89,"id":73094924}],"tv":3810.84}]}
{"op":"mcm","clk":"11999890106","pt":1725067058351,"mc":[{"id":"1.232460189","rc":[{"trd":[[1.01,2904.3]],"batl":[[0,1.01,3776.66]],"ltp":1.01,"tv":3812.53,"id":2857968},{"trd":[[100,4.05]],"ltp":100.0,"tv":39.3,"id":73094924}],"tv":3851.84}]}
{"op":"mcm","clk":"11999891727","pt":1725067077750,"mc":[{"id":"1.232460189","rc":[{"trd":[[1.01,2913.97]],"batl":[[0,1.01,3766.99]],"ltp":1.01,"tv":3822.2,"id":2857968},{"trd":[[100,4.15]],"ltp":100.0,"tv":39.4,"id":73094924}],"tv":3861.61}]}
{"op":"mcm","clk":"11999893212","pt":1725067096654,"mc":[{"id":"1.232460189","rc":[{"trd":[[1.01,2923.64]],"batl":[[0,1.01,3757.32]],"ltp":1.01,"tv":3831.88,"id":2857968},{"trd":[[100,4.24]],"ltp":100.0,"tv":39.5,"id":73094924}],"tv":3871.38}]}
{"op":"mcm","clk":"11999893461","pt":1725067099653,"mc":[{"id":"1.232460189","rc":[{"trd":[[1.01,2940.4]],"batl":[[0,1.01,3748.94]],"ltp":1.01,"tv":3848.63,"id":2857968}],"tv":3888.14}]}
{"op":"mcm","clk":"11999894163","pt":1725067108921,"mc":[{"id":"1.232460189","rc":[{"trd":[[1.01,3107.94]],"batl":[[0,1.01,3665.17]],"ltp":1.01,"tv":4016.17,"id":2857968}],"tv":4055.68}]}
{"op":"mcm","clk":"11999896535","pt":1725067138539,"mc":[{"id":"1.232460189","rc":[{"batl":[[1,1.02,816.91]],"ltp":1.01,"tv":4016.17,"id":2857968}]}]}
{"op":"mcm","clk":"11999900663","pt":1725067189075,"mc":[{"id":"1.232460189","rc":[{"trd":[[1.01,3117.61]],"batl":[[0,1.01,3655.5]],"ltp":1.01,"tv":4025.84,"id":2857968},{"trd":[[100,4.34]],"ltp":100.0,"tv":39.6,"id":73094924}],"tv":4065.45}]}
{"op":"mcm","clk":"11999903283","pt":1725067220715,"mc":[{"id":"1.232460189","rc":[{"trd":[[1.01,3200.78]],"batl":[[0,1.01,3572.33]],"ltp":1.01,"tv":4109.01,"id":2857968},{"trd":[[100,5.18]],"ltp":100.0,"tv":40.44,"id":73094924}],"tv":4149.45}]}
{"op":"mcm","clk":"11999903864","pt":1725067228843,"mc":[{"id":"1.232460189","rc":[{"trd":[[1.01,3210.45]],"batl":[[0,1.01,3562.66]],"ltp":1.01,"tv":4118.68,"id":2857968},{"trd":[[100,5.28]],"ltp":100.0,"tv":40.53,"id":73094924}],"tv":4159.22}]}
{"op":"mcm","clk":"11999906132","pt":1725067257647,"mc":[{"id":"1.232460189","rc":[{"batl":[[0,600,2.84],[1,600,0]],"ltp":100.0,"tv":40.53,"id":73094924}]}]}
{"op":"mcm","clk":"11999906728","pt":1725067265653,"mc":[{"id":"1.232460189","rc":[{"trd":[[1.01,3213.73]],"batl":[[0,1.01,3561.02]],"ltp":1.01,"tv":4121.97,"id":2857968}],"tv":4162.51}]}
{"op":"mcm","clk":"11999908749","pt":1725067292804,"mc":[{"id":"1.232460189","rc":[{"trd":[[1.01,3223.4]],"batl":[[0,1.01,3551.35]],"ltp":1.01,"tv":4131.64,"id":2857968},{"trd":[[100,5.38]],"ltp":100.0,"tv":40.63,"id":73094924}],"tv":4172.28}]}
{"op":"mcm","clk":"11999909446","pt":1725067302724,"mc":[{"id":"1.232460189","rc":[{"batl":[[0,390,16.76],[1,600,2.84]],"ltp":100.0,"tv":40.63,"id":73094924}]}]}
{"op":"mcm","clk":"11999909718","pt":1725067307101,"mc":[{"id":"1.232460189","rc":[{"trd":[[1.01,3224.32]],"batl":[[0,1.01,3550.89]],"ltp":1.01,"tv":4132.56,"id":2857968}],"tv":4173.19}]}
{"op":"mcm","clk":"11999911107","pt":1725067328322,"mc":[{"id":"1.232460189","rc":[{"trd":[[1.01,3234.72]],"batl":[[0,1.01,3540.85]],"ltp":1.01,"tv":4142.96,"id":2857968},{"trd":[[100,5.47]],"ltp":100.0,"tv":40.73,"id":73094924}],"tv":4183.69}]}
{"op":"mcm","clk":"11999911352","pt":1725067331863,"mc":[{"id":"1.232460189","rc":[{"trd":[[1.01,3244.39]],"batl":[[0,1.01,3531.18]],"ltp":1.01,"tv":4152.63,"id":2857968},{"trd":[[100,5.57]],"ltp":100.0,"tv":40.83,"id":73094924}],"tv":4193.46}]}
{"op":"mcm","clk":"11999911826","pt":1725067338543,"mc":[{"id":"1.232460189","rc":[{"trd":[[1.01,3254.06]],"batl":[[0,1.01,3521.51]],"ltp":1.01,"tv":4162.3,"id":2857968},{"trd":[[100,5.67]],"ltp":100.0,"tv":40.93,"id":73094924}],"tv":4203.23}]}
{"op":"mcm","clk":"11999913286","pt":1725067361252,"mc":[{"id":"1.232460189","rc":[{"trd":[[1.01,3294.66]],"batl":[[0,1.01,3480.92]],"ltp":1.01,"tv":4202.89,"id":2857968},{"trd":[[100,6.08]],"ltp":100.0,"tv":41.34,"id":73094924}],"tv":4244.23}]}
{"op":"mcm","clk":"11999914935","pt":1725067387188,"mc":[{"id":"1.232460189","rc":[{"trd":[[1.01,3304.33]],"batl":[[0,1.01,3471.25]],"ltp":1.01,"tv":4212.57,"id":2857968},{"trd":[[100,6.18]],"ltp":100.0,"tv":41.43,"id":73094924}],"tv":4254.0}]}
{"op":"mcm","clk":"11999916733","pt":1725067414843,"mc":[{"id":"1.232460189","rc":[{"trd":[[1.01,3314]],"batl":[[0,1.01,3461.57]],"ltp":1.01,"tv":4222.24,"id":2857968},{"trd":[[100,6.27]],"ltp":100.0,"tv":41.53,"id":73094924}],"tv":4263.77}]}
{"op":"mcm","clk":"11999917596","pt":1725067427928,"mc":[{"id":"1.232460189","rc":[{"trd":[[1.01,3354.59]],"batl":[[0,1.01,3420.98]],"ltp":1.01,"tv":4262.83,"id":2857968},{"trd":[[100,6.68]],"ltp":100.0,"tv":41.94,"id":73094924}],"tv":4304.78}]}
{"op":"mcm","clk":"11999918495","pt":1725067439941,"mc":[{"id":"1.232460189","rc":[{"trd":[[1.01,3364.27]],"batl":[[0,1.01,3411.31]],"ltp":1.01,"tv":4272.5,"id":2857968},{"trd":[[100,6.78]],"ltp":100.0,"tv":42.04,"id":73094924}],"tv":4314.54}]}
{"op":"mcm","clk":"11999918564","pt":1725067441080,"mc":[{"id":"1.232460189","rc":[{"batl":[[0,110,2.45],[1,390,16.76],[2,600,2.84]],"ltp":100.0,"tv":42.04,"id":73094924}]}]}
{"op":"mcm","clk":"11999919168","pt":1725067450052,"mc":[{"id":"1.232460189","rc":[{"trd":[[1.01,3373.94]],"batl":[[0,1.01,3401.64]],"ltp":1.01,"tv":4282.17,"id":2857968},{"trd":[[100,6.88]],"ltp":100.0,"tv":42.14,"id":73094924}],"tv":4324.31}]}
{"op":"mcm","clk":"11999922797","pt":1725067504326,"mc":[{"id":"1.232460189","rc":[{"batl":[[0,390,16.76],[1,600,2.84],[2,600,0]],"ltp":100.0,"tv":42.14,"id":73094924}]}]}
{"op":"mcm","clk":"11999925364","pt":1725067539246,"mc":[{"id":"1.232460189","rc":[{"trd":[[1.01,3383.61]],"batl":[[0,1.01,3391.97]],"ltp":1.01,"tv":4291.84,"id":2857968},{"trd":[[100,6.98]],"ltp":100.0,"tv":42.23,"id":73094924}],"tv":4334.08}]}
{"op":"mcm","clk":"11999932997","pt":1725067642870,"mc":[{"id":"1.232460189","rc":[{"trd":[[1.01,3393.28]],"batl":[[0,1.01,3382.3]],"ltp":1.01,"tv":4301.51,"id":2857968},{"trd":[[100,7.08]],"ltp":100.0,"tv":42.33,"id":73094924}],"tv":4343.85}]}
{"op":"mcm","clk":"11999933945","pt":1725067659620,"mc":[{"id":"1.232460189","rc":[{"trd":[[1.01,3402.95]],"batl":[[0,1.01,3372.63]],"ltp":1.01,"tv":4311.18,"id":2857968},{"trd":[[100,7.17]],"ltp":100.0,"tv":42.43,"id":73094924}],"tv":4353.62}]}
{"op":"mcm","clk":"11999934684","pt":1725067673110,"mc":[{"id":"1.232460189","rc":[{"trd":[[1.01,3412.62]],"batl":[[0,1.01,3362.96]],"ltp":1.01,"tv":4320.86,"id":2857968},{"trd":[[100,7.27]],"ltp":100.0,"tv":42.53,"id":73094924}],"tv":4363.39}]}
{"op":"mcm","clk":"11999936265","pt":1725067699656,"mc":[{"id":"1.232460189","rc":[{"trd":[[1.01,3422.29]],"batl":[[0,1.01,3353.28]],"ltp":1.01,"tv":4330.53,"id":2857968},{"trd":[[100,7.37]],"ltp":100.0,"tv":42.62,"id":73094924}],"tv":4373.15}]}
{"op":"mcm","clk":"11999936435","pt":1725067702728,"mc":[{"id":"1.232460189","rc":[{"trd":[[1.01,3757.37]],"batl":[[0,1.01,3185.74]],"ltp":1.01,"tv":4665.61,"id":2857968}],"tv":4708.24}]}
{"op":"mcm","clk":"11999937009","pt":1725067712346,"mc":[{"id":"1.232460189","rc":[{"batl":[[0,200,8.38],[1,390,16.76],[2,600,2.84]],"ltp":100.0,"tv":42.62,"id":73094924}]}]}
{"op":"mcm","clk":"11999937914","pt":1725067728066,"mc":[{"id":"1.232460189","rc":[{"trd":[[1.01,3767.04]],"batl":[[0,1.01,3176.07]],"ltp":1.01,"tv":4675.28,"id":2857968},{"trd":[[100,7.47]],"ltp":100.0,"tv":42.72,"id":73094924}],"tv":4718.0}]}
{"op":"mcm","clk":"11999938182","pt":1725067731978,"mc":[{"id":"1.232460189","rc":[{"trd":[[1.01,3767.24]],"batl":[[0,1.01,3175.98]],"ltp":1.01,"tv":4675.47,"id":2857968}],"tv":4718.2}]}
{"op":"mcm","clk":"11999938494","pt":1725067737107,"mc":[{"id":"1.232460189","rc":[{"batl":[[1,1.02,733.24]],"ltp":1.01,"tv":4675.47,"id":2857968}]}]}
{"op":"mcm","clk":"11999938939","pt":1725067744402,"mc":[{"id":"1.232460189","rc":[{"trd":[[1.01,3776.91]],"batl":[[0,1.01,3166.3]],"ltp":1.01,"tv":4685.14,"id":2857968},{"trd":[[100,7.56]],"ltp":100.0,"tv":42.82,"id":73094924}],"tv":4727.97}]}
{"op":"mcm","clk":"11999940165","pt":1725067764549,"mc":[{"id":"1.232460189","rc":[{"trd":[[1.01,3777.1]],"batl":[[0,1.01,3166.21]],"ltp":1.01,"tv":4685.34,"id":2857968}],"tv":4728.16}]}
{"op":"mcm","clk":"11999940526","pt":1725067770252,"mc":[{"id":"1.232460189","rc":[{"batb":[[2,2.04,168.45]],"ltp":100.0,"tv":42.82,"id":73094924}]}]}
{"op":"mcm","clk":"11999941056","pt":1725067780684,"mc":[{"id":"1.232460189","rc":[{"trd":[[1.01,3817.7]],"batl":[[0,1.01,3125.61]],"ltp":1.01,"tv":4725.93,"id":2857968},{"trd":[[100,7.97]],"ltp":100.0,"tv":43.23,"id":73094924}],"tv":4769.17}]}
{"op":"mcm","clk":"11999941128","pt":1725067782375,"mc":[{"id":"1.232460189","rc":[{"batl":[[0,200,9.22]],"ltp":100.0,"tv":43.23,"id":73094924}]}]}
{"op":"mcm","clk":"11999941835","pt":1725067795995,"mc":[{"id":"1.232460189","rc":[{"batb":[[1,2.24,42.11],[2,2.14,168.45]],"ltp":100.0,"tv":43.23,"id":73094924}]}]}
{"op":"mcm","clk":"11999941882","pt":1725067796968,"mc":[{"id":"1.232460189","rc":[{"batb":[[1,2.42,42.11],[2,2.24,42.11]],"ltp":100.0,"tv":43.23,"id":73094924}]}]}
{"op":"mcm","clk":"11999942014","pt":1725067799580,"mc":[{"id":"1.232460189","rc":[{"batb":[[1,2.6,42.11],[2,2.42,42.11]],"ltp":100.0,"tv":43.23,"id":73094924}]}]}
{"op":"mcm","clk":"11999942520","pt":1725067806172,"mc":[{"id":"1.232460189","marketDefinition":{"bspMarket":false,"turnInPlayEnabled":true,"persistenceEnabled":true,"marketBaseRate":5.0,"eventId":"33540053","eventTypeId":"4","numberOfWinners":1,"bettingType":"ODDS","marketType":"MATCH_ODDS","marketTime":"2024-08-31T01:30:00.000Z","suspendTime":"2024-08-31T01:30:00.000Z","bspReconciled":false,"complete":true,"inPlay":true,"crossMatching":true,"runnersVoidable":false,"numberOfActiveRunners":2,"betDelay":5,"status":"OPEN","runners":[{"status":"ACTIVE","sortPriority":1,"id":2857968,"name":"Malaysia"},{"status":"ACTIVE","sortPriority":2,"id":73094924,"name":"Myanmar"}],"regulators":["MR_INT"],"countryCode":"GB","discountAllowed":true,"timezone":"GMT","openDate":"2024-08-31T01:30:00.000Z","version":6109185699,"name":"Match Odds","eventName":"Malaysia v Myanmar"},"rc":[{"batl":[[0,1.02,172.13],[1,1.04,1288.06],[2,1.06,20]],"ltp":1.01,"tv":4725.93,"id":2857968},{"batb":[[0,2.6,42.96],[1,2.42,42.11],[2,2.24,42.11]],"ltp":100.0,"tv":43.23,"id":73094924}]}]}
{"op":"mcm","clk":"11999943273","pt":1725067816728,"mc":[{"id":"1.232460189","rc":[{"batl":[[2,1.06,103.67]],"ltp":1.01,"tv":4725.93,"id":2857968}]}]}
{"op":"mcm","clk":"11999943695","pt":1725067822446,"mc":[{"id":"1.232460189","rc":[{"batb":[[0,1.01,84.22]],"ltp":1.01,"tv":4725.93,"id":2857968}]}]}
{"op":"mcm","clk":"11999946486","pt":1725067864988,"mc":[{"id":"1.232460189","rc":[{"trd":[[1.02,549.88]],"batl":[[0,1.02,167.34]],"ltp":1.02,"tv":4730.72,"id":2857968},{"trd":[[50,11.15]],"ltp":50.0,"tv":43.33,"id":73094924}],"tv":4774.06}]}
{"op":"mcm","clk":"11999948478","pt":1725067896651,"mc":[{"id":"1.232460189","rc":[{"trd":[[1.02,636.63]],"batl":[[0,1.02,80.59]],"ltp":1.02,"tv":4817.47,"id":2857968},{"trd":[[50,12.92]],"ltp":50.0,"tv":45.1,"id":73094924}],"tv":4862.58}]}
{"op":"mcm","clk":"11999949497","pt":1725067914368,"mc":[{"id":"1.232460189","rc":[{"trd":[[1.02,646.67]],"batl":[[0,1.02,75.57]],"ltp":1.02,"tv":4827.51,"id":2857968}],"tv":4872.62}]}
{"op":"mcm","clk":"11999949608","pt":1725067916269,"mc":[{"id":"1.232460189","rc":[{"trd":[[1.02,651.46]],"batl":[[0,1.02,70.78]],"ltp":1.02,"tv":4832.3,"id":2857968},{"trd":[[50,13.01]],"ltp":50.0,"tv":45.19,"id":73094924}],"tv":4877.5}]}
{"op":"mcm","clk":"11999950073","pt":1725067925561,"mc":[{"id":"1.232460189","rc":[{"batl":[[2,1.06,20]],"ltp":1.02,"tv":4832.3,"id":2857968}]}]}
{"op":"mcm","clk":"11999950614","pt":1725067934744,"mc":[{"id":"1.232460189","rc":[{"batl":[[1,1.03,83.67],[2,1.04,1288.06]],"ltp":1.02,"tv":4832.3,"id":2857968}]}]}
{"op":"mcm","clk":"11999951057","pt":1725067942301,"mc":[{"id":"1.232460189","rc":[{"trd":[[1.02,656.25]],"batl":[[0,1.02,65.99]],"ltp":1.02,"tv":4837.09,"id":2857968},{"trd":[[50,13.11]],"ltp":50.0,"tv":45.29,"id":73094924}],"tv":4882.39}]}
{"op":"mcm","clk":"11999951411","pt":1725067947589,"mc":[{"id":"1.232460189","rc":[{"trd":[[1.02,659.91]],"batl":[[0,1.02,64.16]],"ltp":1.02,"tv":4840.75,"id":2857968}],"tv":4886.05}]}
{"op":"mcm","clk":"11999952546","pt":1725067965093,"mc":[{"id":"1.232460189","rc":[{"trd":[[1.02,664.7]],"batl":[[0,1.02,59.37]],"ltp":1.02,"tv":4845.54,"id":2857968},{"trd":[[50,13.21]],"ltp":50.0,"tv":45.39,"id":73094924}],"tv":4890.93}]}
{"op":"mcm","clk":"11999952773","pt":1725067969193,"mc":[{"id":"1.232460189","rc":[{"trd":[[1.02,669.49]],"batl":[[0,1.02,54.58]],"ltp":1.02,"tv":4850.33,"id":2857968},{"trd":[[50,13.31]],"ltp":50.0,"tv":45.49,"id":73094924}],"tv":4895.82}]}
{"op":"mcm","clk":"11999954950","pt":1725068006865,"mc":[{"id":"1.232460189","rc":[{"batb":[[0,55,5],[1,2.6,42.96],[2,2.42,42.11]],"ltp":50.0,"tv":45.49,"id":73094924}]}]}
{"op":"mcm","clk":"11999955062","pt":1725068008871,"mc":[{"id":"1.232460189","rc":[{"trd":[[1.02,1048.26]],"batb":[[0,1.02,10.88],[1,1.01,84.22]],"batl":[[0,1.03,83.67],[1,1.04,1288.06],[2,1.06,20]],"ltp":1.02,"tv":5229.1,"id":2857968},{"trd":[[55,5.52]],"batb":[[0,2.6,42.96],[1,2.42,42.11],[2,2.24,42.11]],"ltp":55.0,"tv":50.49,"id":73094924}],"tv":5279.59}]}
{"op":"mcm","clk":"11999956513","pt":1725068033990,"mc":[{"id":"1.232460189","rc":[{"trd":[[1.03,37.85]],"batl":[[0,1.03,80.45]],"ltp":1.03,"tv":5232.32,"id":2857968},{"trd":[[34,0.1]],"ltp":34.0,"tv":50.58,"id":73094924}],"tv":5282.91}]}
{"op":"mcm","clk":"11999956952","pt":1725068041270,"mc":[{"id":"1.232460189","rc":[{"trd":[[1.03,38.05]],"batl":[[0,1.03,80.35]],"ltp":1.03,"tv":5232.52,"id":2857968}],"tv":5283.11}]}
{"op":"mcm","clk":"11999957644","pt":1725068052398,"mc":[{"id":"1.232460189","rc":[{"batb":[[0,1.01,84.22],[1,1.01,0]],"ltp":1.03,"tv":5232.52,"id":2857968}]}]}
{"op":"mcm","clk":"11999958556","pt":1725068066731,"mc":[{"id":"1.232460189","rc":[{"trd":[[1.03,96.47]],"batl":[[0,1.03,21.93]],"ltp":1.03,"tv":5290.94,"id":2857968},{"trd":[[34,1.87]],"ltp":34.0,"tv":52.35,"id":73094924}],"tv":5343.3}]}
{"op":"mcm","clk":"11999959702","pt":1725068085121,"mc":[{"id":"1.232460189","rc":[{"batb":[[0,30,1.68],[1,2.6,42.11],[2,2.42,42.11]],"ltp":34.0,"tv":52.35,"id":73094924}]}]}
{"op":"mcm","clk":"11999960036","pt":1725068090518,"mc":[{"id":"1.232460189","rc":[{"batb":[[0,1.01,167.89]],"ltp":1.03,"tv":5290.94,"id":2857968}]}]}
{"op":"mcm","clk":"11999961441","pt":1725068109365,"mc":[{"id":"1.232460189","rc":[{"batl":[[0,1.02,125.51],[1,1.03,21.93],[2,1.04,1288.06]],"ltp":1.03,"tv":5290.94,"id":2857968}]}]}
{"op":"mcm","clk":"11999961784","pt":1725068114469,"mc":[{"id":"1.232460189","rc":[{"batl":[[0,1.03,21.93],[1,1.04,1288.06],[2,1.06,20]],"ltp":1.03,"tv":5290.94,"id":2857968}]}]}
{"op":"mcm","clk":"11999962216","pt":1725068120337,"mc":[{"id":"1.232460189","rc":[{"batl":[[0,50,0.1]],"ltp":34.0,"tv":52.35,"id":73094924}]}]}
{"op":"mcm","clk":"11999962479","pt":1725068123787,"mc":[{"id":"1.232460189","rc":[{"batb":[[0,1.03,19.91],[1,1.01,167.89]],"batl":[[0,1.04,1288.06],[1,1.27,65.68],[2,1.98,16.84]],"ltp":1.03,"tv":5290.94,"id":2857968}]}]}
{"op":"mcm","clk":"11999962836","pt":1725068128567,"mc":[{"id":"1.232460189","rc":[{"batb":[[0,1.01,167.89],[1,1.01,0]],"batl":[[0,1.03,105.6],[1,1.04,1288.06],[2,1.27,65.68]],"ltp":1.03,"tv":5290.94,"id":2857968}]}]}
{"op":"mcm","clk":"11999963214","pt":1725068133865,"mc":[{"id":"1.232460189","rc":[{"trd":[[1.03,96.67]],"batl":[[0,1.03,105.5]],"ltp":1.03,"tv":5291.14,"id":2857968}],"tv":5343.5}]}
{"op":"mcm","clk":"11999963772","pt":1725068141703,"mc":[{"id":"1.232460189","rc":[{"batl":[[0,100,16.86]],"ltp":34.0,"tv":52.35,"id":73094924}]}]}
{"op":"mcm","clk":"11999964266","pt":1725068149980,"mc":[{"id":"1.232460189","rc":[{"batl":[[0,100,16.76]],"ltp":34.0,"tv":52.35,"id":73094924}]}]}
{"op":"mcm","clk":"11999967993","pt":1725068206744,"mc":[{"id":"1.232460189","rc":[{"trd":[[1.03,96.96]],"batl":[[0,1.03,105.35]],"ltp":1.03,"tv":5291.43,"id":2857968}],"tv":5343.79}]}
{"op":"mcm","clk":"11999968153","pt":1725068208961,"mc":[{"id":"1.232460189","rc":[{"batl":[[0,100,16.86]],"ltp":34.0,"tv":52.35,"id":73094924}]}]}
{"op":"mcm","clk":"11999968326","pt":1725068211541,"mc":[{"id":"1.232460189","rc":[{"trd":[[1.03,100.18]],"batl":[[0,1.03,102.13]],"ltp":1.03,"tv":5294.65,"id":2857968},{"trd":[[34,1.96]],"ltp":34.0,"tv":52.45,"id":73094924}],"tv":5347.11}]}
{"op":"mcm","clk":"11999968477","pt":1725068214057,"mc":[{"id":"1.232460189","rc":[{"trd":[[1.03,100.92]],"batl":[[0,1.03,101.76]],"ltp":1.03,"tv":5295.39,"id":2857968}],"tv":5347.84}]}
{"op":"mcm","clk":"11999968606","pt":1725068216059,"mc":[{"id":"1.232460189","rc":[{"trd":[[1.03,101.28]],"batl":[[0,1.03,101.58]],"ltp":1.03,"tv":5295.75,"id":2857968}],"tv":5348.21}]}
{"op":"mcm","clk":"11999968677","pt":1725068217041,"mc":[{"id":"1.232460189","rc":[{"trd":[[1.03,101.98]],"batl":[[0,1.03,101.23]],"ltp":1.03,"tv":5296.45,"id":2857968}],"tv":5348.91}]}
{"op":"mcm","clk":"11999968733","pt":1725068217962,"mc":[{"id":"1.232460189","rc":[{"trd":[[1.03,105.2]],"batl":[[0,1.03,98.01]],"ltp":1.03,"tv":5299.67,"id":2857968},{"trd":[[34,2.06]],"ltp":34.0,"tv":52.55,"id":73094924}],"tv":5352.22}]}
{"op":"mcm","clk":"11999969196","pt":1725068224978,"mc":[{"id":"1.232460189","rc":[{"trd":[[1.03,105.5]],"batl":[[0,1.03,97.86]],"ltp":1.03,"tv":5299.97,"id":2857968}],"tv":5352.52}]}
{"op":"mcm","clk":"11999969826","pt":1725068234155,"mc":[{"id":"1.232460189","rc":[{"trd":[[1.03,105.79]],"batl":[[0,1.03,89.33]],"ltp":1.03,"tv":5300.26,"id":2857968}],"tv":5352.82}]}
{"op":"mcm","clk":"11999970120","pt":1725068238678,"mc":[{"id":"1.232460189","rc":[{"batl":[[0,100,16.88]],"ltp":34.0,"tv":52.55,"id":73094924}]}]}
{"op":"mcm","clk":"11999970313","pt":1725068241962,"mc":[{"id":"1.232460189","rc":[{"trd":[[1.03,106.09]],"batl":[[0,1.03,89.18]],"ltp":1.03,"tv":5300.56,"id":2857968}],"tv":5353.11}]}
{"op":"mcm","clk":"11999970369","pt":1725068242888,"mc":[{"id":"1.232460189","rc":[{"trd":[[1.03,106.39]],"batl":[[0,1.03,89.03]],"ltp":1.03,"tv":5300.86,"id":2857968}],"tv":5353.41}]}
{"op":"mcm","clk":"11999970764","pt":1725068248806,"mc":[{"id":"1.232460189","rc":[{"batb":[[0,2.6,42.96],[1,2.42,42.11],[2,2.24,42.11]],"ltp":34.0,"tv":52.55,"id":73094924}]}]}
{"op":"mcm","clk":"11999970880","pt":1725068250614,"mc":[{"id":"1.232460189","rc":[{"trd":[[1.03,106.68]],"batl":[[0,1.03,88.88]],"ltp":1.03,"tv":5301.15,"id":2857968}],"tv":5353.71}]}
{"op":"mcm","clk":"11999970974","pt":1725068251900,"mc":[{"id":"1.232460189","rc":[{"trd":[[1.03,106.98]],"batl":[[0,1.03,88.73]],"ltp":1.03,"tv":5301.45,"id":2857968}],"tv":5354.0}]}
{"op":"mcm","clk":"11999971313","pt":1725068257206,"mc":[{"id":"1.232460189","rc":[{"trd":[[1.03,107.38]],"batl":[[0,1.03,88.53]],"ltp":1.03,"tv":5301.85,"id":2857968}],"tv":5354.41}]}
{"op":"mcm","clk":"11999971430","pt":1725068259006,"mc":[{"id":"1.232460189","rc":[{"trd":[[1.03,107.68]],"batl":[[0,1.03,88.38]],"ltp":1.03,"tv":5302.15,"id":2857968}],"tv":5354.7}]}
{"op":"mcm","clk":"11999971521","pt":1725068260596,"mc":[{"id":"1.232460189","rc":[{"trd":[[1.03,107.98]],"batl":[[0,1.03,88.23]],"ltp":1.03,"tv":5302.44,"id":2857968}],"tv":5355.0}]}
{"op":"mcm","clk":"11999971653","pt":1725068262404,"mc":[{"id":"1.232460189","rc":[{"batl":[[0,100,16.98]],"ltp":34.0,"tv":52.55,"id":73094924}]}]}
{"op":"mcm","clk":"11999971974","pt":1725068267329,"mc":[{"id":"1.232460189","rc":[{"trd":[[1.03,108.27]],"batl":[[0,1.03,88.08]],"ltp":1.03,"tv":5302.74,"id":2857968}],"tv":5355.3}]}
{"op":"mcm","clk":"11999972209","pt":1725068270722,"mc":[{"id":"1.232460189","rc":[{"trd":[[1.03,108.57]],"batl":[[0,1.03,87.93]],"ltp":1.03,"tv":5303.04,"id":2857968}],"tv":5355.59}]}
{"op":"mcm","clk":"11999972592","pt":1725068276620,"mc":[{"id":"1.232460189","rc":[{"trd":[[1.03,108.87]],"batl":[[0,1.03,87.78]],"ltp":1.03,"tv":5303.33,"id":2857968},{"batb":[[1,2.52,12.56],[2,2.42,42.11]],"ltp":34.0,"tv":52.55,"id":73094924}],"tv":5355.89}]}
{"op":"mcm","clk":"11999972831","pt":1725068279654,"mc":[{"id":"1.232460189","rc":[{"trd":[[1.03,109.16]],"batl":[[0,1.03,87.63]],"ltp":1.03,"tv":5303.63,"id":2857968}],"tv":5356.19}]}
{"op":"mcm","clk":"11999973208","pt":1725068285160,"mc":[{"id":"1.232460189","rc":[{"trd":[[1.03,109.46]],"batl":[[0,1.03,87.48]],"ltp":1.03,"tv":5303.93,"id":2857968}],"tv":5356.48}]}
{"op":"mcm","clk":"11999973403","pt":1725068288148,"mc":[{"id":"1.232460189","rc":[{"trd":[[1.03,112.68]],"batl":[[0,1.03,84.26]],"ltp":1.03,"tv":5307.15,"id":2857968},{"trd":[[34,2.16]],"ltp":34.0,"tv":52.65,"id":73094924}],"tv":5359.8}]}
{"op":"mcm","clk":"11999973514","pt":1725068289842,"mc":[{"id":"1.232460189","rc":[{"trd":[[1.03,112.97]],"batl":[[0,1.03,84.11]],"ltp":1.03,"tv":5307.44,"id":2857968}],"tv":5360.1}]}
{"op":"mcm","clk":"11999973733","pt":1725068293266,"mc":[{"id":"1.232460189","rc":[{"trd":[[1.03,116.19]],"batl":[[0,1.03,80.89]],"ltp":1.03,"tv":5310.66,"id":2857968},{"trd":[[34,2.26]],"ltp":34.0,"tv":52.75,"id":73094924}],"tv":5363.41}]}
{"op":"mcm","clk":"11999974040","pt":1725068298155,"mc":[{"id":"1.232460189","rc":[{"trd":[[1.03,116.49]],"batl":[[0,1.03,80.74]],"ltp":1.03,"tv":5310.96,"id":2857968}],"tv":5363.71}]}
{"op":"mcm","clk":"11999974174","pt":1725068300268,"mc":[{"id":"1.232460189","rc":[{"trd":[[1.03,119.71]],"batl":[[0,1.03,77.52]],"ltp":1.03,"tv":5314.18,"id":2857968},{"trd":[[34,2.36]],"ltp":34.0,"tv":52.84,"id":73094924}],"tv":5367.03}]}
{"op":"mcm","clk":"11999974283","pt":1725068301145,"mc":[{"id":"1.232460189","rc":[{"trd":[[1.03,119.83]],"batl":[[0,1.03,77.46]],"ltp":1.03,"tv":5314.3,"id":2857968}],"tv":5367.15}]}
{"op":"mcm","clk":"11999974670","pt":1725068306564,"mc":[{"id":"1.232460189","rc":[{"trd":[[1.03,120.13]],"batl":[[0,1.03,77.31]],"ltp":1.03,"tv":5314.6,"id":2857968}],"tv":5367.44}]}
{"op":"mcm","clk":"11999974789","pt":1725068307952,"mc":[{"id":"1.232460189","rc":[{"batb":[[0,2.52,13.4],[1,1.51,164.75],[2,1.46,2]],"ltp":34.0,"tv":52.84,"id":73094924}]}]}
{"op":"mcm","clk":"11999975371","pt":1725068316304,"mc":[{"id":"1.232460189","rc":[{"trd":[[1.03,120.42]],"batl":[[0,1.03,77.16]],"ltp":1.03,"tv":5314.89,"id":2857968}],"tv":5367.74}]}
{"op":"mcm","clk":"11999975985","pt":1725068324406,"mc":[{"id":"1.232460189","rc":[{"trd":[[1.03,120.62]],"batl":[[0,1.03,77.06]],"ltp":1.03,"tv":5315.09,"id":2857968}],"tv":5367.94}]}
{"op":"mcm","clk":"11999976040","pt":1725068325282,"mc":[{"id":"1.232460189","rc":[{"trd":[[1.03,120.92]],"batl":[[0,1.03,76.91]],"ltp":1.03,"tv":5315.39,"id":2857968}],"tv":5368.23}]}
{"op":"mcm","clk":"11999976780","pt":1725068335920,"mc":[{"id":"1.232460189","rc":[{"trd":[[1.03,121.11]],"batl":[[0,1.03,76.81]],"ltp":1.03,"tv":5315.58,"id":2857968}],"tv":5368.43}]}
{"op":"mcm","clk":"11999977892","pt":1725068351325,"mc":[{"id":"1.232460189","rc":[{"batb":[[0,1.01,84.22]],"ltp":1.03,"tv":5315.58,"id":2857968}]}]}
{"op":"mcm","clk":"11999978175","pt":1725068355032,"mc":[{"id":"1.232460189","rc":[{"batl":[[0,1.03,68.43]],"ltp":1.03,"tv":5315.58,"id":2857968}]}]}
{"op":"mcm","clk":"11999980265","pt":1725068381846,"mc":[{"id":"1.232460189","rc":[{"batl":[[0,1.03,47.51]],"ltp":1.03,"tv":5315.58,"id":2857968}]}]}
{"op":"mcm","clk":"11999981007","pt":1725068391571,"mc":[{"id":"1.232460189","rc":[{"trd":[[1.03,121.41]],"batl":[[0,1.03,47.36]],"ltp":1.03,"tv":5315.88,"id":2857968}],"tv":5368.73}]}
{"op":"mcm","clk":"11999981330","pt":1725068396400,"mc":[{"id":"1.232460189","rc":[{"trd":[[1.03,121.61]],"batl":[[0,1.03,47.26]],"ltp":1.03,"tv":5316.08,"id":2857968}],"tv":5368.93}]}
{"op":"mcm","clk":"11999981651","pt":1725068400415,"mc":[{"id":"1.232460189","rc":[{"trd":[[1.03,121.91]],"batl":[[0,1.03,47.11]],"ltp":1.03,"tv":5316.38,"id":2857968}],"tv":5369.23}]}
{"op":"mcm","clk":"11999982659","pt":1725068413490,"mc":[{"id":"1.232460189","rc":[{"trd":[[1.03,123.01]],"batl":[[0,1.03,46.56]],"ltp":1.03,"tv":5317.48,"id":2857968}],"tv":5370.32}]}
{"op":"mcm","clk":"11999983638","pt":1725068426321,"mc":[{"id":"1.232460189","rc":[{"trd":[[1.03,126.23]],"batl":[[0,1.03,43.34]],"ltp":1.03,"tv":5320.7,"id":2857968},{"trd":[[34,2.45]],"ltp":34.0,"tv":52.94,"id":73094924}],"tv":5373.64}]}
{"op":"mcm","clk":"11999983720","pt":1725068427451,"mc":[{"id":"1.232460189","rc":[{"trd":[[1.03,129.45]],"batl":[[0,1.03,40.12]],"ltp":1.03,"tv":5323.92,"id":2857968},{"trd":[[34,2.55]],"ltp":34.0,"tv":53.04,"id":73094924}],"tv":5376.96}]}
{"op":"mcm","clk":"11999983836","pt":1725068428949,"mc":[{"id":"1.232460189","rc":[{"trd":[[1.03,132.67]],"batl":[[0,1.03,36.9]],"ltp":1.03,"tv":5327.14,"id":2857968},{"trd":[[34,2.65]],"ltp":34.0,"tv":53.14,"id":73094924}],"tv":5380.28}]}
{"op":"mcm","clk":"11999985251","pt":1725068446345,"mc":[{"id":"1.232460189","rc":[{"trd":[[1.03,138.7]],"batl":[[0,1.03,30.87]],"ltp":1.03,"tv":5333.17,"id":2857968},{"trd":[[34,2.83]],"ltp":34.0,"tv":53.32,"id":73094924}],"tv":5386.49}]}
{"op":"mcm","clk":"11999986234","pt":1725068458075,"mc":[{"id":"1.232460189","rc":[{"trd":[[1.01,3818.13],[1.03,141.92]],"batb":[[0,1.01,84.01]],"batl":[[0,1.03,27.65]],"ltp":1.03,"tv":5336.82,"id":2857968},{"trd":[[34,2.93]],"ltp":34.0,"tv":53.42,"id":73094924}],"tv":5390.24}]}
{"op":"mcm","clk":"11999986848","pt":1725068465349,"mc":[{"id":"1.232460189","rc":[{"batl":[[0,100,0.22]],"ltp":34.0,"tv":53.42,"id":73094924}]}]}
{"op":"mcm","clk":"11999987224","pt":1725068470189,"mc":[{"id":"1.232460189","rc":[{"trd":[[1.03,142.21]],"batl":[[0,1.03,27.5]],"ltp":1.03,"tv":5337.12,"id":2857968}],"tv":5390.54}]}
{"op":"mcm","clk":"11999987744","pt":1725068476001,"mc":[{"id":"1.232460189","rc":[{"batl":[[0,1.03,23.31]],"ltp":1.03,"tv":5337.12,"id":2857968}]}]}
{"op":"mcm","clk":"11999988297","pt":1725068482598,"mc":[{"id":"1.232460189","rc":[{"trd":[[1.01,3818.33]],"batb":[[0,1.01,83.9]],"ltp":1.01,"tv":5337.32,"id":2857968}],"tv":5390.74}]}
{"op":"mcm","clk":"11999990525","pt":1725068499394,"mc":[{"id":"1.232460189","rc":[{"trd":[[1.03,142.46]],"batl":[[0,1.03,23.19]],"ltp":1.03,"tv":5337.56,"id":2857968}],"tv":5390.98}]}
{"op":"mcm","clk":"11999992406","pt":1725068511366,"mc":[{"id":"1.232460189","rc":[{"trd":[[1.03,155.99]],"batl":[[0,1.03,9.66]],"ltp":1.03,"tv":5351.09,"id":2857968},{"trd":[[34,3.34]],"ltp":34.0,"tv":53.83,"id":73094924}],"tv":5404.92}]}
{"op":"mcm","clk":"11999992994","pt":1725068515098,"mc":[{"id":"1.232460189","rc":[{"batl":[[2,1.26,37.66]],"ltp":1.03,"tv":5351.09,"id":2857968}]}]}
{"op":"mcm","clk":"11999993570","pt":1725068520105,"mc":[{"id":"1.232460189","rc":[{"batl":[[0,1.02,16.76],[1,1.03,9.66],[2,1.04,1288.06]],"ltp":1.03,"tv":5351.09,"id":2857968}]}]}
{"op":"mcm","clk":"11999994932","pt":1725068535805,"mc":[{"id":"1.232460189","rc":[{"trd":[[1.02,1048.56]],"batl":[[0,1.02,16.61]],"ltp":1.02,"tv":5351.39,"id":2857968}],"tv":5405.22}]}
{"op":"mcm","clk":"11999995188","pt":1725068539144,"mc":[{"id":"1.232460189","rc":[{"trd":[[1.02,1048.85]],"batl":[[0,1.02,16.46]],"ltp":1.02,"tv":5351.68,"id":2857968}],"tv":5405.52}]}
{"op":"mcm","clk":"11999995386","pt":1725068541724,"mc":[{"id":"1.232460189","rc":[{"trd":[[1.02,1049.15]],"batl":[[0,1.02,16.31]],"ltp":1.02,"tv":5351.98,"id":2857968}],"tv":5405.81}]}
{"op":"mcm","clk":"11999995729","pt":1725068546426,"mc":[{"id":"1.232460189","rc":[{"trd":[[1.02,1053.94]],"batl":[[0,1.02,11.52]],"ltp":1.02,"tv":5356.77,"id":2857968},{"trd":[[50,13.4]],"ltp":50.0,"tv":53.92,"id":73094924}],"tv":5410.7}]}
{"op":"mcm","clk":"11999995910","pt":1725068548642,"mc":[{"id":"1.232460189","rc":[{"batb":[[0,1.51,165.6],[1,1.46,2],[2,1.05,1.04]],"ltp":50.0,"tv":53.92,"id":73094924}]}]}
{"op":"mcm","clk":"11999996089","pt":1725068550648,"mc":[{"id":"1.232460189","rc":[{"trd":[[1.02,1054.24]],"batl":[[0,1.02,11.37]],"ltp":1.02,"tv":5357.07,"id":2857968}],"tv":5411.0}]}
{"op":"mcm","clk":"11999996174","pt":1725068551520,"mc":[{"id":"1.232460189","rc":[{"trd":[[1.02,1054.47]],"batl":[[0,1.02,11.25]],"ltp":1.02,"tv":5357.3,"id":2857968}],"tv":5411.23}]}
{"op":"mcm","clk":"11999996440","pt":1725068554821,"mc":[{"id":"1.232460189","rc":[{"trd":[[1.02,1054.88]],"batl":[[0,1.02,11.05]],"ltp":1.02,"tv":5357.71,"id":2857968}],"tv":5411.64}]}
{"op":"mcm","clk":"11999996855","pt":1725068559923,"mc":[{"id":"1.232460189","rc":[{"batb":[[0,30,1.68],[1,1.51,164.75],[2,1.46,2]],"ltp":50.0,"tv":53.92,"id":73094924}]}]}
{"op":"mcm","clk":"11999998384","pt":1725068577873,"mc":[{"id":"1.232460189","rc":[{"trd":[[1.02,1059.67]],"batl":[[0,1.02,6.26]],"ltp":1.02,"tv":5362.5,"id":2857968},{"trd":[[50,13.5]],"ltp":50.0,"tv":54.02,"id":73094924}],"tv":5416.52}]}
{"op":"mcm","clk":"11999998919","pt":1725068584777,"mc":[{"id":"1.232460189","rc":[{"trd":[[1.02,1064.46]],"batl":[[0,1.02,1.47]],"ltp":1.02,"tv":5367.29,"id":2857968},{"trd":[[50,13.6]],"ltp":50.0,"tv":54.12,"id":73094924}],"tv":5421.41}]}
{"op":"mcm","clk":"11999999971","pt":1725068597679,"mc":[{"id":"1.232460189","rc":[{"trd":[[1.02,1064.86]],"batl":[[0,1.02,1.27]],"ltp":1.02,"tv":5367.69,"id":2857968}],"tv":5421.81}]}
{"op":"mcm","clk":"12000000113","pt":1725068599479,"mc":[{"id":"1.232460189","rc":[{"trd":[[1.02,1065.78]],"batl":[[0,1.03,10.47],[1,1.04,1288.06],[2,1.26,37.66]],"ltp":1.02,"tv":5368.61,"id":2857968}],"tv":5422.73}]}
{"op":"mcm","clk":"12000000372","pt":1725068602526,"mc":[{"id":"1.232460189","rc":[{"trd":[[1.02,1066.59],[1.03,158.67]],"batl":[[0,1.03,6.98]],"ltp":1.03,"tv":5372.1,"id":2857968},{"trd":[[34,3.42],[50,13.62]],"ltp":34.0,"tv":54.22,"id":73094924}],"tv":5426.32}]}
{"op":"mcm","clk":"12000000622","pt":1725068605489,"mc":[{"id":"1.232460189","rc":[{"batl":[[0,100,0.32]],"ltp":34.0,"tv":54.22,"id":73094924}]}]}
{"op":"mcm","clk":"12000000964","pt":1725068609096,"mc":[{"id":"1.232460189","rc":[{"batb":[[0,1.02,4.39],[1,1.01,83.9]],"ltp":1.03,"tv":5372.1,"id":2857968}]}]}
{"op":"mcm","clk":"12000001091","pt":1725068610539,"mc":[{"id":"1.232460189","rc":[{"trd":[[1.03,161.89]],"batl":[[0,1.03,3.76]],"ltp":1.03,"tv":5375.32,"id":2857968},{"trd":[[34,3.52]],"ltp":34.0,"tv":54.31,"id":73094924}],"tv":5429.64}]}
{"op":"mcm","clk":"12000001296","pt":1725068612908,"mc":[{"id":"1.232460189","rc":[{"batb":[[0,1.02,4.19]],"ltp":1.03,"tv":5375.32,"id":2857968}]}]}
{"op":"mcm","clk":"12000002031","pt":1725068621542,"mc":[{"id":"1.232460189","rc":[{"batb":[[0,1.01,83.9],[1,1.01,0]],"ltp":1.03,"tv":5375.32,"id":2857968}]}]}
{"op":"mcm","clk":"12000002109","pt":1725068622503,"mc":[{"id":"1.232460189","rc":[{"batl":[[0,1.03,1.67]],"ltp":1.03,"tv":5375.32,"id":2857968}]}]}
{"op":"mcm","clk":"12000002846","pt":1725068631651,"mc":[{"id":"1.232460189","rc":[{"trd":[[1.02,1068.41]],"ltp":1.02,"tv":5377.14,"id":2857968},{"trd":[[50,13.65]],"batl":[[0,100,0.28]],"ltp":50.0,"tv":54.35,"id":73094924}],"tv":5431.5}]}
{"op":"mcm","clk":"12000003053","pt":1725068634334,"mc":[{"id":"1.232460189","rc":[{"trd":[[1.02,1071.38]],"batl":[[0,1.02,332.1],[1,1.03,1.67],[2,1.04,1288.06]],"ltp":1.02,"tv":5380.11,"id":2857968},{"trd":[[50,13.71]],"batl":[[0,100,0.22]],"ltp":50.0,"tv":54.41,"id":73094924}],"tv":5434.53}]}
{"op":"mcm","clk":"12000003795","pt":1725068643373,"mc":[{"id":"1.232460189","rc":[{"batl":[[0,1.03,1.67],[1,1.04,1288.06],[2,1.26,37.66]],"ltp":1.02,"tv":5380.11,"id":2857968}]}]}
{"op":"mcm","clk":"12000004199","pt":1725068648257,"mc":[{"id":"1.232460189","rc":[{"batl":[[0,100,0.32]],"ltp":50.0,"tv":54.41,"id":73094924}]}]}
{"op":"mcm","clk":"12000004807","pt":1725068655686,"mc":[{"id":"1.232460189","rc":[{"batl":[[0,100,0.67]],"ltp":50.0,"tv":54.41,"id":73094924}]}]}
{"op":"mcm","clk":"12000005179","pt":1725068660275,"mc":[{"id":"1.232460189","rc":[{"trd":[[1.02,1073.21]],"ltp":1.02,"tv":5381.94,"id":2857968},{"trd":[[50,13.75]],"batl":[[0,100,0.63]],"ltp":50.0,"tv":54.45,"id":73094924}],"tv":5436.39}]}
{"op":"mcm","clk":"12000005234","pt":1725068660782,"mc":[{"id":"1.232460189","rc":[{"trd":[[1.03,162.18]],"batl":[[0,1.03,1.52]],"ltp":1.03,"tv":5382.24,"id":2857968},{"trd":[[50,14.53]],"batl":[[0,100,0.24]],"ltp":50.0,"tv":55.23,"id":73094924}],"tv":5437.47}]}
{"op":"mcm","clk":"12000005629","pt":1725068665787,"mc":[{"id":"1.232460189","rc":[{"batl":[[0,70,2.11],[1,100,0.22]],"ltp":50.0,"tv":55.23,"id":73094924}]}]}
{"op":"mcm","clk":"12000005928","pt":1725068669594,"mc":[{"id":"1.232460189","rc":[{"trd":[[1.02,1074.36]],"batl":[[0,1.02,333.92],[1,1.03,1.52],[2,1.04,1288.06]],"ltp":1.02,"tv":5383.39,"id":2857968},{"trd":[[50,14.55]],"batl":[[0,70,2.09]],"ltp":50.0,"tv":55.25,"id":73094924}],"tv":5438.65}]}
{"op":"mcm","clk":"12000006105","pt":1725068671701,"mc":[{"id":"1.232460189","rc":[{"trd":[[1.02,1074.42]],"batl":[[0,1.02,333.89]],"ltp":1.02,"tv":5383.45,"id":2857968}],"tv":5438.7}]}
{"op":"mcm","clk":"12000006413","pt":1725068675675,"mc":[{"id":"1.232460189","rc":[{"trd":[[1.02,1079.21]],"batl":[[0,1.02,329.1]],"ltp":1.02,"tv":5388.24,"id":2857968},{"trd":[[50,14.65]],"ltp":50.0,"tv":55.35,"id":73094924}],"tv":5443.59}]}
{"op":"mcm","clk":"12000006504","pt":1725068676886,"mc":[{"id":"1.232460189","rc":[{"batl":[[0,1.02,329.2]],"ltp":1.02,"tv":5388.24,"id":2857968}]}]}
{"op":"mcm","clk":"12000006567","pt":1725068677711,"mc":[{"id":"1.232460189","rc":[{"trd":[[1.02,1083.57]],"batl":[[0,1.02,324.84]],"ltp":1.02,"tv":5392.6,"id":2857968},{"trd":[[50,14.74]],"ltp":50.0,"tv":55.44,"id":73094924}],"tv":5448.04}]}
{"op":"mcm","clk":"12000006766","pt":1725068679984,"mc":[{"id":"1.232460189","rc":[{"batl":[[0,1.02,324.74]],"ltp":1.02,"tv":5392.6,"id":2857968}]}]}
{"op":"mcm","clk":"12000007015","pt":1725068683386,"mc":[{"id":"1.232460189","rc":[{"trd":[[1.02,1088.36]],"batl":[[0,1.02,319.95]],"ltp":1.02,"tv":5397.39,"id":2857968},{"trd":[[50,14.84]],"ltp":50.0,"tv":55.54,"id":73094924}],"tv":5452.93}]}
{"op":"mcm","clk":"12000007237","pt":1725068685874,"mc":[{"id":"1.232460189","rc":[{"batl":[[0,1.03,1.52],[1,1.04,1288.06],[2,1.26,37.66]],"ltp":1.02,"tv":5397.39,"id":2857968}]}]}
{"op":"mcm","clk":"12000007449","pt":1725068688494,"mc":[{"id":"1.232460189","rc":[{"batb":[[0,1.01,84.11]],"ltp":1.02,"tv":5397.39,"id":2857968}]}]}
{"op":"mcm","clk":"12000007913","pt":1725068694218,"mc":[{"id":"1.232460189","rc":[{"batl":[[0,70,2.19]],"ltp":50.0,"tv":55.54,"id":73094924}]}]}
{"op":"mcm","clk":"12000007955","pt":1725068694690,"mc":[{"id":"1.232460189","rc":[{"batl":[[1,100,0.31]],"ltp":50.0,"tv":55.54,"id":73094924}]}]}
{"op":"mcm","clk":"12000008596","pt":1725068702505,"mc":[{"id":"1.232460189","rc":[{"batb":[[0,32,3.35],[1,1.51,165.6]],"ltp":50.0,"tv":55.54,"id":73094924}]}]}
{"op":"mcm","clk":"12000008860","pt":1725068705909,"mc":[{"id":"1.232460189","rc":[{"trd":[[1.03,162.55]],"batl":[[0,1.03,1.34]],"ltp":1.03,"tv":5397.75,"id":2857968}],"tv":5453.29}]}
{"op":"mcm","clk":"12000008934","pt":1725068706731,"mc":[{"id":"1.232460189","rc":[{"batb":[[0,1.01,84.21]],"ltp":1.03,"tv":5397.75,"id":2857968}]}]}
{"op":"mcm","clk":"12000009070","pt":1725068708399,"mc":[{"id":"1.232460189","rc":[{"trd":[[1.03,162.74]],"batb":[[0,1.01,84]],"batl":[[0,1.03,1.24]],"ltp":1.03,"tv":5397.95,"id":2857968}],"tv":5453.49}]}
{"op":"mcm","clk":"12000009077","pt":1725068708497,"mc":[{"id":"1.232460189","rc":[{"batb":[[0,1.01,84.15]],"ltp":1.03,"tv":5397.95,"id":2857968}]}]}
{"op":"mcm","clk":"12000009552","pt":1725068714122,"mc":[{"id":"1.232460189","rc":[{"trd":[[1.02,1089.3]],"batb":[[0,1.01,83.9]],"ltp":1.02,"tv":5398.89,"id":2857968},{"trd":[[50,14.85]],"batl":[[0,70,2.17]],"ltp":50.0,"tv":55.55,"id":73094924}],"tv":5454.45}]}
{"op":"mcm","clk":"12000009722","pt":1725068716037,"mc":[{"id":"1.232460189","rc":[{"trd":[[1.02,1091.13]],"ltp":1.02,"tv":5400.72,"id":2857968},{"trd":[[50,14.89]],"batl":[[0,70,2.14]],"ltp":50.0,"tv":55.59,"id":73094924}],"tv":5456.31}]}
{"op":"mcm","clk":"12000010117","pt":1725068720636,"mc":[{"id":"1.232460189","rc":[{"trd":[[1.03,162.98]],"batl":[[0,1.03,1.12]],"ltp":1.03,"tv":5400.95,"id":2857968}],"tv":5456.55}]}
{"op":"mcm","clk":"12000014436","pt":1725068774227,"mc":[{"id":"1.232460189","rc":[{"trd":[[1.02,1093.43]],"batl":[[0,1.02,249.01],[1,1.03,1.12],[2,1.04,1288.06]],"ltp":1.02,"tv":5403.25,"id":2857968},{"trd":[[50,14.94]],"batl":[[0,70,2.09]],"ltp":50.0,"tv":55.64,"id":73094924}],"tv":5458.89}]}
{"op":"mcm","clk":"12000014535","pt":1725068775307,"mc":[{"id":"1.232460189","rc":[{"batb":[[0,30,1.68],[1,1.51,164.75]],"ltp":50.0,"tv":55.64,"id":73094924}]}]}
{"op":"mcm","clk":"12000015088","pt":1725068781540,"mc":[{"id":"1.232460189","rc":[{"batl":[[0,1.03,1.12],[1,1.04,1288.06],[2,1.26,37.72]],"ltp":1.02,"tv":5403.25,"id":2857968}]}]}
{"op":"mcm","clk":"12000015429","pt":1725068785844,"mc":[{"id":"1.232460189","rc":[{"trd":[[1.03,164.1]],"batl":[[0,1.04,1288.06],[1,1.26,37.72],[2,1.27,65.68]],"ltp":1.03,"tv":5404.37,"id":2857968},{"trd":[[34,3.55]],"batb":[[0,30,1.3]],"ltp":34.0,"tv":55.67,"id":73094924}],"tv":5460.04}]}
{"op":"mcm","clk":"12000015873","pt":1725068791128,"mc":[{"id":"1.232460189","rc":[{"batb":[[0,1.01,84.05]],"ltp":1.03,"tv":5404.37,"id":2857968}]}]}
{"op":"mcm","clk":"12000016910","pt":1725068803692,"mc":[{"id":"1.232460189","rc":[{"batb":[[0,1.02,104.75],[1,1.01,83.9]],"ltp":1.03,"tv":5404.37,"id":2857968}]}]}
{"op":"mcm","clk":"12000018084","pt":1725068816218,"mc":[{"id":"1.232460189","rc":[{"batl":[[0,1.04,3382.25]],"ltp":1.03,"tv":5404.37,"id":2857968}]}]}
{"op":"mcm","clk":"12000018311","pt":1725068819142,"mc":[{"id":"1.232460189","rc":[{"batb":[[0,1.51,165.6],[1,1.46,2],[2,1.05,1.04]],"ltp":34.0,"tv":55.67,"id":73094924}]}]}
{"op":"mcm","clk":"12000021170","pt":1725068853163,"mc":[{"id":"1.232460189","rc":[{"trd":[[1.04,333.67]],"batl":[[0,1.04,3378.15]],"ltp":1.04,"tv":5412.57,"id":2857968}],"tv":5468.24}]}
{"op":"mcm","clk":"12000021300","pt":1725068854966,"mc":[{"id":"1.232460189","rc":[{"trd":[[1.04,333.96]],"batl":[[0,1.04,3378.01]],"ltp":1.04,"tv":5412.87,"id":2857968}],"tv":5468.54}]}
{"op":"mcm","clk":"12000021362","pt":1725068855681,"mc":[{"id":"1.232460189","rc":[{"trd":[[1.02,1096.2]],"batb":[[0,1.02,103.36]],"ltp":1.02,"tv":5415.64,"id":2857968}],"tv":5471.31}]}
{"op":"mcm","clk":"12000022394","pt":1725068868015,"mc":[{"id":"1.232460189","rc":[{"trd":[[30,0.07]],"batb":[[0,1.51,165.59]],"ltp":30.0,"tv":55.68,"id":73094924}],"tv":5471.33}]}
{"op":"mcm","clk":"12000022701","pt":1725068871907,"mc":[{"id":"1.232460189","rc":[{"batb":[[0,1.01,83.9],[1,1.01,0]],"batl":[[0,1.02,147.95],[1,1.04,3378.01],[2,1.26,37.72]],"ltp":1.02,"tv":5415.64,"id":2857968}]}]}
{"op":"mcm","clk":"12000023297","pt":1725068879503,"mc":[{"id":"1.232460189","rc":[{"trd":[[1.02,1096.29]],"batl":[[0,1.02,147.91]],"ltp":1.02,"tv":5415.72,"id":2857968}],"tv":5471.41}]}
{"op":"mcm","clk":"12000023588","pt":1725068883626,"mc":[{"id":"1.232460189","rc":[{"trd":[[1.02,1101.08]],"batl":[[0,1.02,143.12]],"ltp":1.02,"tv":5420.51,"id":2857968},{"trd":[[50,15.03]],"ltp":50.0,"tv":55.78,"id":73094924}],"tv":5476.3}]}
{"op":"mcm","clk":"12000023759","pt":1725068885522,"mc":[{"id":"1.232460189","rc":[{"batl":[[0,1.02,138.93]],"ltp":1.02,"tv":5420.51,"id":2857968}]}]}
{"op":"mcm","clk":"12000025047","pt":1725068901923,"mc":[{"id":"1.232460189","rc":[{"trd":[[1.01,3819.53]],"batb":[[0,1.01,83.31]],"ltp":1.01,"tv":5421.7,"id":2857968}],"tv":5477.49}]}
{"op":"mcm","clk":"12000025102","pt":1725068902744,"mc":[{"id":"1.232460189","rc":[{"trd":[[1.02,1101.27]],"batl":[[0,1.02,138.83]],"ltp":1.02,"tv":5421.9,"id":2857968}],"tv":5477.69}]}
{"op":"mcm","clk":"12000025605","pt":1725068909431,"mc":[{"id":"1.232460189","rc":[{"batl":[[2,1.26,37.78]],"ltp":1.02,"tv":5421.9,"id":2857968}]}]}
{"op":"mcm","clk":"12000028185","pt":1725068943302,"mc":[{"id":"1.232460189","rc":[{"trd":[[1.02,1106.06]],"batl":[[0,1.02,134.04]],"ltp":1.02,"tv":5426.69,"id":2857968},{"trd":[[50,15.13]],"ltp":50.0,"tv":55.88,"id":73094924}],"tv":5482.58}]}
{"op":"mcm","clk":"12000028330","pt":1725068945102,"mc":[{"id":"1.232460189","rc":[{"trd":[[1.02,1106.36]],"batl":[[0,1.02,133.89]],"ltp":1.02,"tv":5426.99,"id":2857968},{"batl":[[1,100,0.28]],"ltp":50.0,"tv":55.88,"id":73094924}],"tv":5482.87}]}
{"op":"mcm","clk":"12000028670","pt":1725068949924,"mc":[{"id":"1.232460189","rc":[{"trd":[[1.02,1107.46]],"batl":[[0,1.02,132.79]],"ltp":1.02,"tv":5428.09,"id":2857968},{"trd":[[50,15.15]],"ltp":50.0,"tv":55.9,"id":73094924}],"tv":5484.0}]}
{"op":"mcm","clk":"12000028886","pt":1725068952601,"mc":[{"id":"1.232460189","rc":[{"batl":[[1,1.03,62.76],[2,1.04,3378.01]],"ltp":1.02,"tv":5428.09,"id":2857968}]}]}
{"op":"mcm","clk":"12000028973","pt":1725068953788,"mc":[{"id":"1.232460189","rc":[{"trd":[[1.02,1107.76]],"batl":[[0,1.02,132.64]],"ltp":1.02,"tv":5428.38,"id":2857968}],"tv":5484.29}]}
{"op":"mcm","clk":"12000029434","pt":1725068960131,"mc":[{"id":"1.232460189","rc":[{"batl":[[0,100,0.28],[1,100,0]],"ltp":50.0,"tv":55.9,"id":73094924}]}]}
{"op":"mcm","clk":"12000029659","pt":1725068963413,"mc":[{"id":"1.232460189","rc":[{"batl":[[0,1.02,128.45]],"ltp":1.02,"tv":5428.38,"id":2857968}]}]}
{"op":"mcm","clk":"12000030920","pt":1725068981126,"mc":[{"id":"1.232460189","rc":[{"batl":[[0,1.03,62.76],[1,1.04,3378.01],[2,1.26,37.78]],"ltp":1.02,"tv":5428.38,"id":2857968}]}]}
{"op":"mcm","clk":"12000031245","pt":1725068985447,"mc":[{"id":"1.232460189","rc":[{"batb":[[0,1.02,20.92],[1,1.01,83.31]],"ltp":1.02,"tv":5428.38,"id":2857968}]}]}
{"op":"mcm","clk":"12000032213","pt":1725068998563,"mc":[{"id":"1.232460189","rc":[{"batl":[[0,1.03,58.57]],"ltp":1.02,"tv":5428.38,"id":2857968}]}]}
{"op":"mcm","clk":"12000032840","pt":1725069006849,"mc":[{"id":"1.232460189","rc":[{"trd":[[1.03,167.32]],"batl":[[0,1.03,55.35]],"ltp":1.03,"tv":5431.6,"id":2857968},{"trd":[[34,3.65]],"ltp":34.0,"tv":56.0,"id":73094924}],"tv":5487.61}]}
{"op":"mcm","clk":"12000033579","pt":1725069017161,"mc":[{"id":"1.232460189","rc":[{"batl":[[0,1.03,51.17]],"ltp":1.03,"tv":5431.6,"id":2857968}]}]}
{"op":"mcm","clk":"12000033926","pt":1725069022176,"mc":[{"id":"1.232460189","rc":[{"trd":[[1.02,1111.41],[1.03,170.54]],"batb":[[0,1.02,19.09]],"batl":[[0,1.03,47.95]],"ltp":1.02,"tv":5438.48,"id":2857968},{"trd":[[34,3.74]],"ltp":34.0,"tv":56.1,"id":73094924}],"tv":5494.58}]}
{"op":"mcm","clk":"12000034739","pt":1725069032922,"mc":[{"id":"1.232460189","rc":[{"batl":[[0,100,1.12]],"ltp":34.0,"tv":56.1,"id":73094924}]}]}
{"op":"mcm","clk":"12000035387","pt":1725069041415,"mc":[{"id":"1.232460189","rc":[{"batl":[[0,100,0.28]],"ltp":34.0,"tv":56.1,"id":73094924}]}]}
{"op":"mcm","clk":"12000035703","pt":1725069045723,"mc":[{"id":"1.232460189","rc":[{"trd":[[1.03,170.84]],"batl":[[0,1.03,47.8]],"ltp":1.03,"tv":5438.78,"id":2857968}],"tv":5494.88}]}
{"op":"mcm","clk":"12000036127","pt":1725069050946,"mc":[{"id":"1.232460189","rc":[{"batb":[[1,1.01,125.15]],"ltp":1.03,"tv":5438.78,"id":2857968}]}]}
{"op":"mcm","clk":"12000036251","pt":1725069052834,"mc":[{"id":"1.232460189","rc":[{"batb":[[1,1.01,83.31]],"ltp":1.03,"tv":5438.78,"id":2857968}]}]}
{"op":"mcm","clk":"12000037064","pt":1725069065526,"mc":[{"id":"1.232460189","rc":[{"trd":[[1.03,171.13]],"batl":[[0,1.03,47.65]],"ltp":1.03,"tv":5439.07,"id":2857968}],"tv":5495.18}]}
{"op":"mcm","clk":"12000037283","pt":1725069069639,"mc":[{"id":"1.232460189","rc":[{"trd":[[1.02,1114.88]],"batb":[[0,1.02,17.36]],"ltp":1.02,"tv":5442.54,"id":2857968}],"tv":5498.64}]}
{"op":"mcm","clk":"12000037475","pt":1725069072643,"mc":[{"id":"1.232460189","rc":[{"trd":[[1.03,174.35]],"batl":[[0,1.03,44.43]],"ltp":1.03,"tv":5445.76,"id":2857968},{"trd":[[34,3.84]],"ltp":34.0,"tv":56.2,"id":73094924}],"tv":5501.96}]}
{"op":"mcm","clk":"12000037866","pt":1725069078645,"mc":[{"id":"1.232460189","rc":[{"trd":[[1.03,174.65]],"batl":[[0,1.03,44.28]],"ltp":1.03,"tv":5446.05,"id":2857968}],"tv":5502.25}]}
{"op":"mcm","clk":"12000038266","pt":1725069084263,"mc":[{"id":"1.232460189","rc":[{"trd":[[1.03,174.71]],"batl":[[0,1.03,44.25]],"ltp":1.03,"tv":5446.11,"id":2857968}],"tv":5502.31}]}
{"op":"mcm","clk":"12000039019","pt":1725069095463,"mc":[{"id":"1.232460189","rc":[{"trd":[[1.03,174.77]],"batl":[[0,1.03,44.22]],"ltp":1.03,"tv":5446.17,"id":2857968}],"tv":5502.37}]}
{"op":"mcm","clk":"12000039977","pt":1725069109769,"mc":[{"id":"1.232460189","rc":[{"trd":[[1.03,175.07]],"batl":[[0,1.03,44.07]],"ltp":1.03,"tv":5446.47,"id":2857968}],"tv":5502.67}]}
{"op":"mcm","clk":"12000040254","pt":1725069113319,"mc":[{"id":"1.232460189","rc":[{"trd":[[1.02,1118.49]],"batb":[[0,1.02,15.55]],"ltp":1.02,"tv":5450.09,"id":2857968}],"tv":5506.29}]}
{"op":"mcm","clk":"12000040585","pt":1725069117917,"mc":[{"id":"1.232460189","rc":[{"batb":[[0,1.01,83.31],[1,1.01,0]],"batl":[[0,1.02,151.99],[1,1.03,44.07],[2,1.04,3378.01]],"ltp":1.02,"tv":5450.09,"id":2857968}]}]}
{"op":"mcm","clk":"12000040790","pt":1725069120795,"mc":[{"id":"1.232460189","rc":[{"trd":[[1.02,1118.79]],"batl":[[0,1.02,151.84]],"ltp":1.02,"tv":5450.38,"id":2857968}],"tv":5506.58}]}
{"op":"mcm","clk":"12000041346","pt":1725069128317,"mc":[{"id":"1.232460189","rc":[{"batl":[[0,1.03,44.07],[1,1.04,3378.01],[2,1.26,37.78]],"ltp":1.02,"tv":5450.38,"id":2857968}]}]}
{"op":"mcm","clk":"12000041585","pt":1725069131317,"mc":[{"id":"1.232460189","rc":[{"batb":[[0,1.01,83.45]],"ltp":1.02,"tv":5450.38,"id":2857968}]}]}
{"op":"mcm","clk":"12000041975","pt":1725069136519,"mc":[{"id":"1.232460189","rc":[{"trd":[[1.02,1119.09]],"batb":[[0,1.01,83.31]],"ltp":1.02,"tv":5450.68,"id":2857968}],"tv":5506.88}]}
{"op":"mcm","clk":"12000042202","pt":1725069139458,"mc":[{"id":"1.232460189","rc":[{"batb":[[0,1.01,83.42]],"ltp":1.02,"tv":5450.68,"id":2857968}]}]}
{"op":"mcm","clk":"12000042417","pt":1725069142240,"mc":[{"id":"1.232460189","rc":[{"trd":[[1.03,175.36]],"batl":[[0,1.03,43.92]],"ltp":1.03,"tv":5450.98,"id":2857968}],"tv":5507.18}]}
{"op":"mcm","clk":"12000042434","pt":1725069142446,"mc":[{"id":"1.232460189","rc":[{"batb":[[0,1.02,104.71],[1,1.01,83.31]],"ltp":1.03,"tv":5450.98,"id":2857968}]}]}
{"op":"mcm","clk":"12000042828","pt":1725069147446,"mc":[{"id":"1.232460189","rc":[{"batb":[[0,1.02,104.6]],"ltp":1.03,"tv":5450.98,"id":2857968}]}]}
{"op":"mcm","clk":"12000043402","pt":1725069154869,"mc":[{"id":"1.232460189","rc":[{"batb":[[0,1.02,104.75]],"ltp":1.03,"tv":5450.98,"id":2857968}]}]}
{"op":"mcm","clk":"12000044253","pt":1725069166273,"mc":[{"id":"1.232460189","rc":[{"trd":[[1.03,175.66]],"batl":[[0,1.03,43.77]],"ltp":1.03,"tv":5451.27,"id":2857968}],"tv":5507.47}]}
{"op":"mcm","clk":"12000044746","pt":1725069173179,"mc":[{"id":"1.232460189","rc":[{"trd":[[1.03,178.88]],"batl":[[0,1.03,40.55]],"ltp":1.03,"tv":5454.49,"id":2857968},{"trd":[[34,3.94]],"ltp":34.0,"tv":56.29,"id":73094924}],"tv":5510.79}]}
{"op":"mcm","clk":"12000044809","pt":1725069174000,"mc":[{"id":"1.232460189","rc":[{"batb":[[0,1.02,104.89]],"ltp":1.03,"tv":5454.49,"id":2857968}]}]}
{"op":"mcm","clk":"12000045377","pt":1725069181904,"mc":[{"id":"1.232460189","rc":[{"trd":[[1.02,1119.68]],"batb":[[0,1.01,83.31],[1,1.01,0]],"batl":[[0,1.02,54.26],[1,1.03,40.55],[2,1.04,3378.01]],"ltp":1.02,"tv":5455.09,"id":2857968}],"tv":5511.38}]}
{"op":"mcm","clk":"12000045598","pt":1725069185095,"mc":[{"id":"1.232460189","rc":[{"batl":[[0,1.02,54.41]],"ltp":1.02,"tv":5455.09,"id":2857968}]}]}
{"op":"mcm","clk":"12000046728","pt":1725069200417,"mc":[{"id":"1.232460189","rc":[{"batl":[[0,1.02,12.52]],"ltp":1.02,"tv":5455.09,"id":2857968}]}]}
{"op":"mcm","clk":"12000047033","pt":1725069204391,"mc":[{"id":"1.232460189","rc":[{"trd":[[1.02,1120.16]],"batl":[[0,1.02,12.28]],"ltp":1.02,"tv":5455.56,"id":2857968}],"tv":5511.86}]}
{"op":"mcm","clk":"12000047076","pt":1725069205008,"mc":[{"id":"1.232460189","rc":[{"trd":[[1.02,1120.45]],"batl":[[0,1.02,12.13]],"ltp":1.02,"tv":5455.86,"id":2857968}],"tv":5512.16}]}
{"op":"mcm","clk":"12000048135","pt":1725069220730,"mc":[{"id":"1.232460189","rc":[{"trd":[[1.02,1120.65]],"batl":[[0,1.02,12.03]],"ltp":1.02,"tv":5456.05,"id":2857968}],"tv":5512.35}]}
{"op":"mcm","clk":"12000048495","pt":1725069225928,"mc":[{"id":"1.232460189","rc":[{"trd":[[1.02,1120.85]],"batl":[[0,1.02,11.93]],"ltp":1.02,"tv":5456.25,"id":2857968}],"tv":5512.55}]}
{"op":"mcm","clk":"12000048895","pt":1725069231239,"mc":[{"id":"1.232460189","rc":[{"trd":[[1.02,1121.14]],"batl":[[0,1.02,11.63]],"ltp":1.02,"tv":5456.55,"id":2857968}],"tv":5512.85}]}
{"op":"mcm","clk":"12000049634","pt":1725069242544,"mc":[{"id":"1.232460189","rc":[{"trd":[[1.02,1121.44]],"batl":[[0,1.02,11.48]],"ltp":1.02,"tv":5456.85,"id":2857968}],"tv":5513.14}]}
{"op":"mcm","clk":"12000050305","pt":1725069251232,"mc":[{"id":"1.232460189","rc":[{"trd":[[1.02,1121.74]],"batl":[[0,1.02,11.33]],"ltp":1.02,"tv":5457.14,"id":2857968}],"tv":5513.44}]}
{"op":"mcm","clk":"12000051052","pt":1725069260271,"mc":[{"id":"1.232460189","rc":[{"trd":[[1.02,1122.03]],"batl":[[0,1.02,11.18]],"ltp":1.02,"tv":5457.44,"id":2857968}],"tv":5513.74}]}
{"op":"mcm","clk":"12000051536","pt":1725069267071,"mc":[{"id":"1.232460189","rc":[{"batl":[[1,1.03,124.22]],"ltp":1.02,"tv":5457.44,"id":2857968}]}]}
{"op":"mcm","clk":"12000051743","pt":1725069270054,"mc":[{"id":"1.232460189","rc":[{"trd":[[1.02,1122.33]],"batl":[[0,1.02,11.03]],"ltp":1.02,"tv":5457.73,"id":2857968}],"tv":5514.03}]}
{"op":"mcm","clk":"12000052435","pt":1725069279123,"mc":[{"id":"1.232460189","rc":[{"trd":[[1.02,1122.63]],"batl":[[0,1.02,10.88]],"ltp":1.02,"tv":5458.03,"id":2857968}],"tv":5514.33}]}
{"op":"mcm","clk":"12000053086","pt":1725069288113,"mc":[{"id":"1.232460189","rc":[{"trd":[[1.02,1122.92]],"batl":[[0,1.02,10.73]],"ltp":1.02,"tv":5458.33,"id":2857968}],"tv":5514.63}]}
{"op":"mcm","clk":"12000053422","pt":1725069292592,"mc":[{"id":"1.232460189","rc":[{"trd":[[1.01,3986.6]],"ltp":1.01,"tv":5625.4,"id":2857968},{"trd":[[100,7.98]],"batl":[[0,100,0.28]],"ltp":100.0,"tv":56.3,"id":73094924}],"tv":5681.71}]}
{"op":"mcm","clk":"12000053722","pt":1725069296798,"mc":[{"id":"1.232460189","rc":[{"trd":[[1.02,1123.22]],"batl":[[0,1.02,10.58]],"ltp":1.02,"tv":5625.7,"id":2857968}],"tv":5682.0}]}
{"op":"mcm","clk":"12000054308","pt":1725069305324,"mc":[{"id":"1.232460189","rc":[{"trd":[[1.02,1123.52]],"batl":[[0,1.02,10.43]],"ltp":1.02,"tv":5626.0,"id":2857968}],"tv":5682.3}]}
{"op":"mcm","clk":"12000054809","pt":1725069311433,"mc":[{"id":"1.232460189","rc":[{"batl":[[0,1.02,52.54]],"ltp":1.02,"tv":5626.0,"id":2857968}]}]}
{"op":"mcm","clk":"12000055012","pt":1725069313750,"mc":[{"id":"1.232460189","rc":[{"trd":[[1.02,1123.81]],"batl":[[0,1.02,52.39]],"ltp":1.02,"tv":5626.29,"id":2857968}],"tv":5682.6}]}
{"op":"mcm","clk":"12000055273","pt":1725069316857,"mc":[{"id":"1.232460189","rc":[{"trd":[[1.02,1124.11]],"batl":[[0,1.02,52.24]],"ltp":1.02,"tv":5626.59,"id":2857968}],"tv":5682.89}]}
{"op":"mcm","clk":"12000055715","pt":1725069322745,"mc":[{"id":"1.232460189","rc":[{"trd":[[1.02,1124.41]],"batl":[[0,1.02,52.09]],"ltp":1.02,"tv":5626.89,"id":2857968}],"tv":5683.19}]}
{"op":"mcm","clk":"12000056745","pt":1725069336059,"mc":[{"id":"1.232460189","rc":[{"batl":[[0,1.02,42.11]],"ltp":1.02,"tv":5626.89,"id":2857968}]}]}
{"op":"mcm","clk":"12000057362","pt":1725069345475,"mc":[{"id":"1.232460189","rc":[{"trd":[[1.01,4014.26]],"batl":[[0,1.01,1260.4],[1,1.02,42.11],[2,1.03,124.22]],"ltp":1.01,"tv":5654.54,"id":2857968},{"trd":[[100,8.26]],"ltp":100.0,"tv":56.58,"id":73094924}],"tv":5711.13}]}
{"op":"mcm","clk":"12000058840","pt":1725069365792,"mc":[{"id":"1.232460189","rc":[{"trd":[[1.01,4023.93]],"batl":[[0,1.01,1250.73]],"ltp":1.01,"tv":5664.21,"id":2857968},{"trd":[[100,8.36]],"ltp":100.0,"tv":56.68,"id":73094924}],"tv":5720.9}]}
{"op":"mcm","clk":"12000058945","pt":1725069367176,"mc":[{"id":"1.232460189","rc":[{"trd":[[1.01,4026.3]],"batl":[[0,1.01,1249.55]],"ltp":1.01,"tv":5666.59,"id":2857968}],"tv":5723.27}]}
{"op":"mcm","clk":"12000059400","pt":1725069372582,"mc":[{"id":"1.232460189","rc":[{"batl":[[0,890,0.84]],"ltp":100.0,"tv":56.68,"id":73094924}]}]}
{"op":"mcm","clk":"12000059634","pt":1725069375708,"mc":[{"id":"1.232460189","rc":[{"trd":[[1.01,4027.62]],"batl":[[0,1.01,1248.89]],"ltp":1.01,"tv":5667.91,"id":2857968}],"tv":5724.59}]}
{"op":"mcm","clk":"12000061508","pt":1725069402539,"mc":[{"id":"1.232460189","rc":[{"trd":[[1.01,4037.29]],"batl":[[0,1.01,1239.22]],"ltp":1.01,"tv":5677.58,"id":2857968},{"trd":[[100,8.45]],"ltp":100.0,"tv":56.77,"id":73094924}],"tv":5734.36}]}
{"op":"mcm","clk":"12000064262","pt":1725069440809,"mc":[{"id":"1.232460189","rc":[{"batl":[[0,890,0.94]],"ltp":100.0,"tv":56.77,"id":73094924}]}]}
{"op":"mcm","clk":"12000064802","pt":1725069448294,"mc":[{"id":"1.232460189","rc":[{"trd":[[1.01,4037.7]],"batl":[[0,1.01,1239.02]],"ltp":1.01,"tv":5677.98,"id":2857968}],"tv":5734.76}]}
{"op":"mcm","clk":"12000065192","pt":1725069454094,"mc":[{"id":"1.232460189","rc":[{"batl":[[0,1000,1.04]],"ltp":100.0,"tv":56.77,"id":73094924}]}]}
{"op":"mcm","clk":"12000065607","pt":1725069460507,"mc":[{"id":"1.232460189","rc":[{"trd":[[1.01,4037.93]],"batl":[[0,1.01,1238.9]],"ltp":1.01,"tv":5678.22,"id":2857968}],"tv":5735.0}]}
{"op":"mcm","clk":"12000065913","pt":1725069465308,"mc":[{"id":"1.232460189","rc":[{"trd":[[1.01,4047.6]],"batl":[[0,1.01,1229.23]],"ltp":1.01,"tv":5687.89,"id":2857968},{"trd":[[100,8.55]],"ltp":100.0,"tv":56.87,"id":73094924}],"tv":5744.76}]}
{"op":"mcm","clk":"12000066344","pt":1725069471619,"mc":[{"id":"1.232460189","rc":[{"trd":[[1.01,4057.27]],"batl":[[0,1.01,1219.56]],"ltp":1.01,"tv":5697.56,"id":2857968},{"trd":[[100,8.65]],"ltp":100.0,"tv":56.97,"id":73094924}],"tv":5754.53}]}
{"op":"mcm","clk":"12000066581","pt":1725069475260,"mc":[{"id":"1.232460189","rc":[{"trd":[[1.01,4057.51]],"batl":[[0,1.01,1219.44]],"ltp":1.01,"tv":5697.8,"id":2857968}],"tv":5754.77}]}
{"op":"mcm","clk":"12000066704","pt":1725069477109,"mc":[{"id":"1.232460189","rc":[{"batl":[[0,600,2.19],[1,1000,0.94]],"ltp":100.0,"tv":56.97,"id":73094924}]}]}
{"op":"mcm","clk":"12000067380","pt":1725069486058,"mc":[{"id":"1.232460189","rc":[{"trd":[[1.01,4057.75]],"batl":[[0,1.01,1219.32]],"ltp":1.01,"tv":5698.03,"id":2857968}],"tv":5755.0}]}
{"op":"mcm","clk":"12000068253","pt":1725069497945,"mc":[{"id":"1.232460189","rc":[{"batl":[[0,600,3.03]],"ltp":100.0,"tv":56.97,"id":73094924}]}]}
{"op":"mcm","clk":"12000068350","pt":1725069499278,"mc":[{"id":"1.232460189","rc":[{"trd":[[1.01,4141.43]],"batl":[[0,1.01,1177.48]],"ltp":1.01,"tv":5781.71,"id":2857968}],"tv":5838.69}]}
{"op":"mcm","clk":"12000068599","pt":1725069502860,"mc":[{"id":"1.232460189","rc":[{"batl":[[1,1000,0.1]],"ltp":100.0,"tv":56.97,"id":73094924}]}]}
{"op":"mcm","clk":"12000068795","pt":1725069505691,"mc":[{"id":"1.232460189","rc":[{"trd":[[1.01,4141.66]],"batl":[[0,1.01,1177.36]],"ltp":1.01,"tv":5781.95,"id":2857968}],"tv":5838.92}]}
{"op":"mcm","clk":"12000069878","pt":1725069522300,"mc":[{"id":"1.232460189","rc":[{"trd":[[1.01,4141.9]],"batl":[[0,1.01,1177.24]],"ltp":1.01,"tv":5782.18,"id":2857968}],"tv":5839.16}]}
{"op":"mcm","clk":"12000071220","pt":1725069542237,"mc":[{"id":"1.232460189","rc":[{"trd":[[1.01,4142.13]],"batl":[[0,1.01,1177.12]],"ltp":1.01,"tv":5782.42,"id":2857968}],"tv":5839.39}]}
{"op":"mcm","clk":"12000072531","pt":1725069560359,"mc":[{"id":"1.232460189","rc":[{"trd":[[1.01,4161.48]],"batl":[[0,1.01,1157.78]],"ltp":1.01,"tv":5801.76,"id":2857968},{"trd":[[100,8.84]],"ltp":100.0,"tv":57.16,"id":73094924}],"tv":5858.93}]}
{"op":"mcm","clk":"12000072765","pt":1725069563758,"mc":[{"id":"1.232460189","rc":[{"trd":[[1.01,4161.71]],"batl":[[0,1.01,1157.66]],"ltp":1.01,"tv":5802.0,"id":2857968}],"tv":5859.16}]}
{"op":"mcm","clk":"12000073734","pt":1725069577174,"mc":[{"id":"1.232460189","rc":[{"trd":[[1.01,4161.95]],"batl":[[0,1.01,1157.55]],"ltp":1.01,"tv":5802.23,"id":2857968}],"tv":5859.4}]}
{"op":"mcm","clk":"12000074683","pt":1725069590483,"mc":[{"id":"1.232460189","rc":[{"trd":[[1.01,4162.86]],"batl":[[0,1.01,1157.09]],"ltp":1.01,"tv":5803.15,"id":2857968}],"tv":5860.32}]}
{"op":"mcm","clk":"12000076663","pt":1725069609630,"mc":[{"id":"1.232460189","rc":[{"trd":[[1.01,4172.53]],"batl":[[0,1.01,1147.42]],"ltp":1.01,"tv":5812.82,"id":2857968},{"trd":[[100,8.94]],"ltp":100.0,"tv":57.26,"id":73094924}],"tv":5870.08}]}
{"op":"mcm","clk":"12000077468","pt":1725069617612,"mc":[{"id":"1.232460189","rc":[{"trd":[[1.01,4172.71]],"batl":[[0,1.01,1147.33]],"ltp":1.01,"tv":5812.99,"id":2857968}],"tv":5870.26}]}
{"op":"mcm","clk":"12000079199","pt":1725069637766,"mc":[{"id":"1.232460189","rc":[{"trd":[[1.01,4184.71]],"batl":[[0,1.01,1141.33]],"ltp":1.01,"tv":5825.0,"id":2857968}],"tv":5882.26}]}
{"op":"mcm","clk":"12000080014","pt":1725069647746,"mc":[{"id":"1.232460189","rc":[{"batl":[[2,1.03,126.05]],"ltp":1.01,"tv":5825.0,"id":2857968}]}]}
{"op":"mcm","clk":"12000081232","pt":1725069663695,"mc":[{"id":"1.232460189","rc":[{"batl":[[2,1.03,127.87]],"ltp":1.01,"tv":5825.0,"id":2857968}]}]}
{"op":"mcm","clk":"12000086020","pt":1725069733758,"mc":[{"id":"1.232460189","rc":[{"batl":[[0,600,2.93]],"ltp":100.0,"tv":57.26,"id":73094924}]}]}
{"op":"mcm","clk":"12000086112","pt":1725069735351,"mc":[{"id":"1.232460189","rc":[{"trd":[[1.01,4184.91]],"batl":[[0,1.01,1141.23]],"ltp":1.01,"tv":5825.19,"id":2857968}],"tv":5882.46}]}
{"op":"mcm","clk":"12000087086","pt":1725069749902,"mc":[{"id":"1.232460189","rc":[{"batl":[[1,1000,0.2]],"ltp":100.0,"tv":57.26,"id":73094924}]}]}
{"op":"mcm","clk":"12000092228","pt":1725069824845,"mc":[{"id":"1.232460189","rc":[{"trd":[[1.01,4188.56]],"batl":[[0,1.01,1139.4]],"ltp":1.01,"tv":5828.84,"id":2857968}],"tv":5886.11}]}
{"op":"mcm","clk":"12000095426","pt":1725069871747,"mc":[{"id":"1.232460189","rc":[{"trd":[[1.01,4197.36]],"batl":[[0,1.01,1130.6]],"ltp":1.01,"tv":5837.64,"id":2857968},{"trd":[[100,9.03]],"ltp":100.0,"tv":57.35,"id":73094924}],"tv":5895.0}]}
{"op":"mcm","clk":"12000101144","pt":1725069952823,"mc":[{"id":"1.232460189","rc":[{"trd":[[1.01,4197.76]],"batl":[[0,1.01,1130.4]],"ltp":1.01,"tv":5838.05,"id":2857968}],"tv":5895.4}]}
{"op":"mcm","clk":"12000102257","pt":1725069966518,"mc":[{"id":"1.232460189","rc":[{"trd":[[1.01,4404.69]],"batl":[[0,1.01,923.47]],"ltp":1.01,"tv":6044.98,"id":2857968},{"trd":[[100,11.12]],"ltp":100.0,"tv":59.44,"id":73094924}],"tv":6104.42}]}
{"op":"mcm","clk":"12000103706","pt":1725069987857,"mc":[{"id":"1.232460189","rc":[{"trd":[[1.01,4404.89]],"batl":[[0,1.01,923.38]],"ltp":1.01,"tv":6045.17,"id":2857968}],"tv":6104.62}]}
{"op":"mcm","clk":"12000105561","pt":1725070019813,"mc":[{"id":"1.232460189","rc":[{"batl":[[1,1000,0.1]],"ltp":100.0,"tv":59.44,"id":73094924}]}]}
{"op":"mcm","clk":"12000105676","pt":1725070022078,"mc":[{"id":"1.232460189","rc":[{"batl":[[1,1000,0]],"ltp":100.0,"tv":59.44,"id":73094924}]}]}
{"op":"mcm","clk":"12000106325","pt":1725070034088,"mc":[{"id":"1.232460189","rc":[{"batl":[[0,600,3.03]],"ltp":100.0,"tv":59.44,"id":73094924}]}]}
{"op":"mcm","clk":"12000106927","pt":1725070044325,"mc":[{"id":"1.232460189","rc":[{"batl":[[1,1.03,127.87],[2,1.04,1284.71]],"ltp":1.01,"tv":6045.17,"id":2857968}]}]}
{"op":"mcm","clk":"12000107255","pt":1725070049421,"mc":[{"id":"1.232460189","rc":[{"batl":[[1,1.03,169.98]],"ltp":1.01,"tv":6045.17,"id":2857968}]}]}
{"op":"mcm","clk":"12000107550","pt":1725070053652,"mc":[{"id":"1.232460189","rc":[{"batl":[[1,1.03,156.51]],"ltp":1.01,"tv":6045.17,"id":2857968}]}]}
{"op":"mcm","clk":"12000109921","pt":1725070088129,"mc":[{"id":"1.232460189","rc":[{"trd":[[1.01,4446.72]],"batl":[[0,1.01,902.46]],"ltp":1.01,"tv":6087.01,"id":2857968}],"tv":6146.45}]}
{"op":"mcm","clk":"12000111259","pt":1725070109218,"mc":[{"id":"1.232460189","rc":[{"trd":[[1.01,4488.56]],"batl":[[0,1.01,881.54]],"ltp":1.01,"tv":6128.85,"id":2857968}],"tv":6188.29}]}
{"op":"mcm","clk":"12000112309","pt":1725070126373,"mc":[{"id":"1.232460189","rc":[{"trd":[[1.01,4530.4]],"batl":[[0,1.01,860.62]],"ltp":1.01,"tv":6170.69,"id":2857968}],"tv":6230.13}]}
{"op":"mcm","clk":"12000112332","pt":1725070126838,"mc":[{"id":"1.232460189","rc":[{"batl":[[0,500,8.48],[1,600,2.93]],"ltp":100.0,"tv":59.44,"id":73094924}]}]}
{"op":"mcm","clk":"12000113325","pt":1725070143607,"mc":[{"id":"1.232460189","rc":[{"trd":[[1.01,4572.24]],"batl":[[0,1.01,839.7]],"ltp":1.01,"tv":6212.52,"id":2857968}],"tv":6271.97}]}
{"op":"mcm","clk":"12000114471","pt":1725070159096,"mc":[{"id":"1.232460189","rc":[{"trd":[[1.01,4655.92]],"batl":[[0,1.01,797.86]],"ltp":1.01,"tv":6296.21,"id":2857968}],"tv":6355.65}]}
{"op":"mcm","clk":"12000115664","pt":1725070175835,"mc":[{"id":"1.232460189","rc":[{"trd":[[1.01,4681.04]],"batl":[[0,1.01,785.3]],"ltp":1.01,"tv":6321.33,"id":2857968}],"tv":6380.77}]}
{"op":"mcm","clk":"12000116044","pt":1725070181553,"mc":[{"id":"1.232460189","rc":[{"trd":[[1.01,4681.21]],"batl":[[0,1.01,785.22]],"ltp":1.01,"tv":6321.49,"id":2857968}],"tv":6380.94}]}
{"op":"mcm","clk":"12000122551","pt":1725070270155,"mc":[{"id":"1.232460189","rc":[{"trd":[[1.01,4690.88]],"batl":[[0,1.01,775.55]],"ltp":1.01,"tv":6331.16,"id":2857968},{"trd":[[100,11.22]],"ltp":100.0,"tv":59.54,"id":73094924}],"tv":6390.7}]}
{"op":"mcm","clk":"12000123112","pt":1725070278034,"mc":[{"id":"1.232460189","rc":[{"batl":[[0,500,9.32]],"ltp":100.0,"tv":59.54,"id":73094924}]}]}
{"op":"mcm","clk":"12000123488","pt":1725070283719,"mc":[{"id":"1.232460189","rc":[{"batl":[[1,600,2.09]],"ltp":100.0,"tv":59.54,"id":73094924}]}]}
{"op":"mcm","clk":"12000124800","pt":1725070303244,"mc":[{"id":"1.232460189","rc":[{"trd":[[1.01,4700.55]],"batl":[[0,1.01,765.88]],"ltp":1.01,"tv":6340.83,"id":2857968},{"trd":[[100,11.32]],"ltp":100.0,"tv":59.64,"id":73094924}],"tv":6400.47}]}
{"op":"mcm","clk":"12000128218","pt":1725070355133,"mc":[{"id":"1.232460189","rc":[{"trd":[[1.01,4717.3]],"batl":[[0,1.01,757.5]],"ltp":1.01,"tv":6357.59,"id":2857968}],"tv":6417.23}]}
{"op":"mcm","clk":"12000146307","pt":1725070379793,"mc":[{"id":"1.232460189","rc":[{"trd":[[1.01,4757.9]],"batl":[[0,1.01,716.9]],"ltp":1.01,"tv":6398.18,"id":2857968},{"trd":[[100,11.73]],"ltp":100.0,"tv":60.05,"id":73094924}],"tv":6458.23}]}
{"op":"mcm","clk":"12000147251","pt":1725070392784,"mc":[{"id":"1.232460189","rc":[{"trd":[[1.01,4758.13]],"batl":[[0,1.01,716.79]],"ltp":1.01,"tv":6398.42,"id":2857968}],"tv":6458.47}]}
{"op":"mcm","clk":"12000147904","pt":1725070400806,"mc":[{"id":"1.232460189","rc":[{"trd":[[1.01,4758.33]],"batl":[[0,1.01,716.69]],"ltp":1.01,"tv":6398.62,"id":2857968}],"tv":6458.67}]}
{"op":"mcm","clk":"12000148251","pt":1725070405217,"mc":[{"id":"1.232460189","rc":[{"batl":[[0,500,8.48]],"ltp":100.0,"tv":60.05,"id":73094924}]}]}
{"op":"mcm","clk":"12000149395","pt":1725070420514,"mc":[{"id":"1.232460189","rc":[{"trd":[[1.01,4758.8]],"batl":[[0,1.01,716.45]],"ltp":1.01,"tv":6399.09,"id":2857968}],"tv":6459.14}]}
{"op":"mcm","clk":"12000155067","pt":1725070490819,"mc":[{"id":"1.232460189","rc":[{"batl":[[1,600,0]],"ltp":100.0,"tv":60.05,"id":73094924}]}]}
{"op":"mcm","clk":"12000155363","pt":1725070495101,"mc":[{"id":"1.232460189","rc":[{"trd":[[1.01,4768.48]],"batl":[[0,1.01,706.78]],"ltp":1.01,"tv":6408.76,"id":2857968},{"trd":[[100,11.82]],"ltp":100.0,"tv":60.14,"id":73094924}],"tv":6468.91}]}
{"op":"mcm","clk":"12000156799","pt":1725070514327,"mc":[{"id":"1.232460189","rc":[{"trd":[[1.01,4768.71]],"batl":[[0,1.01,706.66]],"ltp":1.01,"tv":6409.0,"id":2857968}],"tv":6469.14}]}
{"op":"mcm","clk":"12000157156","pt":1725070518947,"mc":[{"id":"1.232460189","rc":[{"trd":[[1.01,4769.11]],"batl":[[0,1.01,706.46]],"ltp":1.01,"tv":6409.4,"id":2857968}],"tv":6469.55}]}
{"op":"mcm","clk":"12000158387","pt":1725070535278,"mc":[{"id":"1.232460189","rc":[{"trd":[[1.01,4769.52]],"batl":[[0,1.01,706.26]],"ltp":1.01,"tv":6409.8,"id":2857968}],"tv":6469.95}]}
{"op":"mcm","clk":"12000159430","pt":1725070548768,"mc":[{"id":"1.232460189","rc":[{"trd":[[1.01,4769.92]],"batl":[[0,1.01,706.06]],"ltp":1.01,"tv":6410.21,"id":2857968}],"tv":6470.36}]}
{"op":"mcm","clk":"12000160512","pt":1725070563090,"mc":[{"id":"1.232460189","rc":[{"trd":[[1.01,4770.33]],"batl":[[0,1.01,705.86]],"ltp":1.01,"tv":6410.61,"id":2857968}],"tv":6470.76}]}
{"op":"mcm","clk":"12000160562","pt":1725070563611,"mc":[{"id":"1.232460189","rc":[{"trd":[[1.01,4780]],"batl":[[0,1.01,696.19]],"ltp":1.01,"tv":6420.28,"id":2857968},{"trd":[[100,11.92]],"ltp":100.0,"tv":60.24,"id":73094924}],"tv":6480.53}]}
{"op":"mcm","clk":"12000160823","pt":1725070566613,"mc":[{"id":"1.232460189","rc":[{"batl":[[2,1.04,1286.45]],"ltp":1.01,"tv":6420.28,"id":2857968}]}]}
{"op":"mcm","clk":"12000162276","pt":1725070583649,"mc":[{"id":"1.232460189","rc":[{"trd":[[1.01,4780.4]],"batl":[[0,1.01,695.99]],"ltp":1.01,"tv":6420.69,"id":2857968}],"tv":6480.93}]}
{"op":"mcm","clk":"12000163480","pt":1725070598656,"mc":[{"id":"1.232460189","rc":[{"trd":[[1.01,4780.81]],"batl":[[0,1.01,695.79]],"ltp":1.01,"tv":6421.09,"id":2857968}],"tv":6481.34}]}
{"op":"mcm","clk":"12000164783","pt":1725070614958,"mc":[{"id":"1.232460189","rc":[{"trd":[[1.01,4781.21]],"batl":[[0,1.01,695.58]],"ltp":1.01,"tv":6421.5,"id":2857968}],"tv":6481.74}]}
{"op":"mcm","clk":"12000166973","pt":1725070642393,"mc":[{"id":"1.232460189","rc":[{"batl":[[0,400,0.1]],"ltp":100.0,"tv":60.24,"id":73094924}]}]}
{"op":"mcm","clk":"12000167754","pt":1725070653329,"mc":[{"id":"1.232460189","rc":[{"batl":[[2,1.04,1284.71]],"ltp":1.01,"tv":6421.5,"id":2857968}]}]}
{"op":"mcm","clk":"12000168592","pt":1725070664012,"mc":[{"id":"1.232460189","rc":[{"trd":[[1.01,4781.61]],"batl":[[0,1.01,695.38]],"ltp":1.01,"tv":6421.9,"id":2857968}],"tv":6482.15}]}
{"op":"mcm","clk":"12000177285","pt":1725070774153,"mc":[{"id":"1.232460189","rc":[{"trd":[[1.01,4782.4]],"batl":[[0,1.01,694.99]],"ltp":1.01,"tv":6422.68,"id":2857968}],"tv":6482.93}]}
{"op":"mcm","clk":"12000178683","pt":1725070793754,"mc":[{"id":"1.232460189","rc":[{"trd":[[1.01,4949.74]],"batl":[[0,1.01,611.32]],"ltp":1.01,"tv":6590.02,"id":2857968}],"tv":6650.27}]}
{"op":"mcm","clk":"12000189786","pt":1725070939356,"mc":[{"id":"1.232460189","rc":[{"trd":[[1.01,5117.28]],"batl":[[0,1.01,527.55]],"ltp":1.01,"tv":6757.56,"id":2857968}],"tv":6817.81}]}
{"op":"mcm","clk":"12000196961","pt":1725071046840,"mc":[{"id":"1.232460189","rc":[{"trd":[[1.01,5126.95]],"batl":[[0,1.01,517.88]],"ltp":1.01,"tv":6767.24,"id":2857968},{"trd":[[100,12.02]],"ltp":100.0,"tv":60.34,"id":73094924}],"tv":6827.58}]}
{"op":"mcm","clk":"12000197974","pt":1725071060665,"mc":[{"id":"1.232460189","rc":[{"trd":[[1.01,5127.19]],"batl":[[0,1.01,517.76]],"ltp":1.01,"tv":6767.47,"id":2857968}],"tv":6827.81}]}
{"op":"mcm","clk":"12000198130","pt":1725071063059,"mc":[{"id":"1.232460189","rc":[{"batb":[[0,110,4.19],[1,1.51,165.59],[2,1.46,2]],"ltp":100.0,"tv":60.34,"id":73094924}]}]}
{"op":"mcm","clk":"12000206135","pt":1725071180912,"mc":[{"id":"1.232460189","rc":[{"batl":[[1,1.03,154.68]],"ltp":1.01,"tv":6767.47,"id":2857968}]}]}
{"op":"mcm","clk":"12000206259","pt":1725071182708,"mc":[{"id":"1.232460189","rc":[{"batl":[[1,1.03,152.86]],"ltp":1.01,"tv":6767.47,"id":2857968}]}]}
{"op":"mcm","clk":"12000206427","pt":1725071184919,"mc":[{"id":"1.232460189","rc":[{"batb":[[0,110,3.78]],"ltp":100.0,"tv":60.34,"id":73094924}]}]}
{"op":"mcm","clk":"12000208516","pt":1725071214640,"mc":[{"id":"1.232460189","rc":[{"trd":[[110,4.2]],"batb":[[0,110,3.68]],"ltp":110.0,"tv":60.54,"id":73094924}],"tv":6828.01}]}
{"op":"mcm","clk":"12000210954","pt":1725071251019,"mc":[{"id":"1.232460189","rc":[{"trd":[[110,4.4]],"batb":[[0,110,3.58]],"ltp":110.0,"tv":60.73,"id":73094924}],"tv":6828.21}]}
{"op":"mcm","clk":"12000224640","pt":1725071472885,"mc":[{"id":"1.232460189","rc":[{"trd":[[1.01,5127.42]],"batl":[[0,1.01,517.64]],"ltp":1.01,"tv":6767.71,"id":2857968}],"tv":6828.45}]}
{"op":"mcm","clk":"12000225073","pt":1725071480852,"mc":[{"id":"1.232460189","rc":[{"trd":[[1.01,5127.66]],"batl":[[0,1.01,517.52]],"ltp":1.01,"tv":6767.94,"id":2857968}],"tv":6828.68}]}
{"op":"mcm","clk":"12000225534","pt":1725071489208,"mc":[{"id":"1.232460189","rc":[{"trd":[[1.01,5127.89]],"batl":[[0,1.01,517.4]],"ltp":1.01,"tv":6768.18,"id":2857968}],"tv":6828.92}]}
{"op":"mcm","clk":"12000229804","pt":1725071565580,"mc":[{"id":"1.232460189","rc":[{"trd":[[110,4.59]],"batb":[[0,110,3.48]],"ltp":110.0,"tv":60.93,"id":73094924}],"tv":6829.11}]}
{"op":"mcm","clk":"12000241672","pt":1725071776684,"mc":[{"id":"1.232460189","rc":[{"batb":[[0,110,3.07]],"ltp":110.0,"tv":60.93,"id":73094924}]}]}
{"op":"mcm","clk":"12000243494","pt":1725071806419,"mc":[{"id":"1.232460189","rc":[{"trd":[[110,4.79]],"batb":[[0,110,2.97]],"ltp":110.0,"tv":61.13,"id":73094924}],"tv":6829.31}]}
{"op":"mcm","clk":"12000246747","pt":1725071858719,"mc":[{"id":"1.232460189","rc":[{"trd":[[1.01,5136.27]],"batl":[[0,1.01,513.22]],"ltp":1.01,"tv":6776.56,"id":2857968}],"tv":6837.69}]}
{"op":"mcm","clk":"12000247196","pt":1725071866304,"mc":[{"id":"1.232460189","rc":[{"batb":[[0,1.51,165.59],[1,1.46,2],[2,1.05,1.04]],"batl":[[0,110,1.22]],"ltp":110.0,"tv":61.13,"id":73094924}]}]}
{"op":"mcm","clk":"12000248827","pt":1725071894229,"mc":[{"id":"1.232460189","rc":[{"trd":[[1.01,5145.94]],"batl":[[0,1.01,503.54]],"ltp":1.01,"tv":6786.23,"id":2857968},{"trd":[[100,12.12]],"ltp":100.0,"tv":61.23,"id":73094924}],"tv":6847.46}]}
{"op":"mcm","clk":"12000251477","pt":1725071936592,"mc":[{"id":"1.232460189","rc":[{"trd":[[1.01,5146.53]],"batl":[[0,1.01,503.25]],"ltp":1.01,"tv":6786.81,"id":2857968}],"tv":6848.04}]}
{"op":"mcm","clk":"12000251576","pt":1725071938590,"mc":[{"id":"1.232460189","rc":[{"trd":[[1.01,5156.2]],"batl":[[0,1.01,493.58]],"ltp":1.01,"tv":6796.48,"id":2857968},{"trd":[[100,12.21]],"ltp":100.0,"tv":61.32,"id":73094924}],"tv":6857.81}]}
{"op":"mcm","clk":"12000251970","pt":1725071943113,"mc":[{"id":"1.232460189","rc":[{"trd":[[1.01,5165.87]],"batl":[[0,1.01,483.91]],"ltp":1.01,"tv":6806.15,"id":2857968},{"trd":[[100,12.31]],"ltp":100.0,"tv":61.42,"id":73094924}],"tv":6867.58}]}
{"op":"mcm","clk":"12000253146","pt":1725071962631,"mc":[{"id":"1.232460189","rc":[{"trd":[[110,4.99]],"batl":[[0,110,1.12]],"ltp":110.0,"tv":61.62,"id":73094924}],"tv":6867.78}]}
{"op":"mcm","clk":"12000254786","pt":1725071990448,"mc":[{"id":"1.232460189","rc":[{"trd":[[1.01,5175.54]],"batl":[[0,1.01,474.24]],"ltp":1.01,"tv":6815.83,"id":2857968},{"trd":[[100,12.41]],"ltp":100.0,"tv":61.72,"id":73094924}],"tv":6877.55}]}
{"op":"mcm","clk":"12000256163","pt":1725072012586,"mc":[{"id":"1.232460189","rc":[{"batb":[[0,2.44,4.18],[1,1.51,164.75],[2,1.46,2]],"ltp":100.0,"tv":61.72,"id":73094924}]}]}
{"op":"mcm","clk":"12000256389","pt":1725072015567,"mc":[{"id":"1.232460189","rc":[{"trd":[[1.01,5216.14]],"batl":[[0,1.01,433.64]],"ltp":1.01,"tv":6856.42,"id":2857968},{"trd":[[100,12.82]],"ltp":100.0,"tv":62.13,"id":73094924}],"tv":6918.55}]}
{"op":"mcm","clk":"12000258679","pt":1725072052822,"mc":[{"id":"1.232460189","rc":[{"trd":[[1.01,5225.81]],"batl":[[0,1.01,423.97]],"ltp":1.01,"tv":6866.09,"id":2857968},{"trd":[[100,12.92]],"ltp":100.0,"tv":62.22,"id":73094924}],"tv":6928.32}]}
{"op":"mcm","clk":"12000259330","pt":1725072062225,"mc":[{"id":"1.232460189","rc":[{"trd":[[1.01,5266.4]],"batl":[[0,1.01,383.38]],"ltp":1.01,"tv":6906.69,"id":2857968},{"trd":[[100,13.33]],"ltp":100.0,"tv":62.63,"id":73094924}],"tv":6969.33}]}
{"op":"mcm","clk":"12000259928","pt":1725072069831,"mc":[{"id":"1.232460189","rc":[{"trd":[[1.01,5350.08]],"batl":[[0,1.01,341.54]],"ltp":1.01,"tv":6990.37,"id":2857968},{"batb":[[0,110,4.19],[1,2.44,4.18],[2,1.51,164.75]],"ltp":100.0,"tv":62.63,"id":73094924}],"tv":7053.01}]}
{"op":"mcm","clk":"12000261914","pt":1725072095771,"mc":[{"id":"1.232460189","rc":[{"batl":[[1,1.03,193.86]],"ltp":1.01,"tv":6990.37,"id":2857968}]}]}
{"op":"mcm","clk":"12000262638","pt":1725072105171,"mc":[{"id":"1.232460189","rc":[{"trd":[[1.01,5350.26]],"batl":[[0,1.01,341.45]],"ltp":1.01,"tv":6990.54,"id":2857968}],"tv":7053.18}]}
{"op":"mcm","clk":"12000262903","pt":1725072108685,"mc":[{"id":"1.232460189","rc":[{"trd":[[1.01,5350.49]],"batl":[[0,1.01,341.33]],"ltp":1.01,"tv":6990.78,"id":2857968}],"tv":7053.42}]}
{"op":"mcm","clk":"12000263042","pt":1725072110687,"mc":[{"id":"1.232460189","rc":[{"batl":[[0,300,0.1]],"ltp":100.0,"tv":62.63,"id":73094924}]}]}
{"op":"mcm","clk":"12000263362","pt":1725072115661,"mc":[{"id":"1.232460189","rc":[{"trd":[[1.01,5351.41]],"batl":[[0,1.01,340.87]],"ltp":1.01,"tv":6991.69,"id":2857968}],"tv":7054.33}]}
{"op":"mcm","clk":"12000263615","pt":1725072119618,"mc":[{"id":"1.232460189","rc":[{"trd":[[1.01,5351.64]],"batl":[[0,1.01,340.75]],"ltp":1.01,"tv":6991.93,"id":2857968}],"tv":7054.57}]}
{"op":"mcm","clk":"12000264311","pt":1725072129395,"mc":[{"id":"1.232460189","rc":[{"trd":[[1.01,5351.88]],"batl":[[0,1.01,340.64]],"ltp":1.01,"tv":6992.17,"id":2857968}],"tv":7054.81}]}
{"op":"mcm","clk":"12000265136","pt":1725072139821,"mc":[{"id":"1.232460189","rc":[{"trd":[[1.01,5352.12]],"batl":[[0,1.01,340.52]],"ltp":1.01,"tv":6992.4,"id":2857968},{"batb":[[0,110,3.78]],"ltp":100.0,"tv":62.63,"id":73094924}],"tv":7055.04}]}
{"op":"mcm","clk":"12000265934","pt":1725072150628,"mc":[{"id":"1.232460189","rc":[{"trd":[[110,5.17]],"batb":[[0,110,3.69]],"ltp":110.0,"tv":62.81,"id":73094924}],"tv":7055.22}]}
{"op":"mcm","clk":"12000266451","pt":1725072158064,"mc":[{"id":"1.232460189","rc":[{"trd":[[1.01,5352.35]],"batl":[[0,1.01,340.4]],"ltp":1.01,"tv":6992.64,"id":2857968},{"batl":[[0,300,0.2]],"ltp":110.0,"tv":62.81,"id":73094924}],"tv":7055.46}]}
{"op":"mcm","clk":"12000267032","pt":1725072167382,"mc":[{"id":"1.232460189","rc":[{"trd":[[1.01,5352.74]],"batl":[[0,1.01,340.2]],"ltp":1.01,"tv":6993.03,"id":2857968}],"tv":7055.85}]}
{"op":"mcm","clk":"12000267449","pt":1725072175300,"mc":[{"id":"1.232460189","rc":[{"trd":[[1.01,5362.3]],"batl":[[0,1.01,335.42]],"ltp":1.01,"tv":7002.59,"id":2857968}],"tv":7065.41}]}
{"op":"mcm","clk":"12000269175","pt":1725072201590,"mc":[{"id":"1.232460189","rc":[{"batb":[[1,1.51,165.59],[2,1.46,2]],"ltp":110.0,"tv":62.81,"id":73094924}]}]}
{"op":"mcm","clk":"12000272392","pt":1725072247449,"mc":[{"id":"1.232460189","rc":[{"trd":[[1.01,5364.13]],"batl":[[0,1.01,334.51]],"ltp":1.01,"tv":7004.41,"id":2857968}],"tv":7067.23}]}
{"op":"mcm","clk":"12000276400","pt":1725072300245,"mc":[{"id":"1.232460189","rc":[{"trd":[[1.01,5364.32]],"batl":[[0,1.01,334.41]],"ltp":1.01,"tv":7004.61,"id":2857968}],"tv":7067.43}]}
{"op":"mcm","clk":"12000276560","pt":1725072302151,"mc":[{"id":"1.232460189","rc":[{"batb":[[0,110,3.28]],"ltp":110.0,"tv":62.81,"id":73094924}]}]}
{"op":"mcm","clk":"12000278494","pt":1725072327954,"mc":[{"id":"1.232460189","rc":[{"trd":[[110,5.36]],"batb":[[0,110,3.18]],"ltp":110.0,"tv":63.01,"id":73094924}],"tv":7067.63}]}
{"op":"mcm","clk":"12000278864","pt":1725072333967,"mc":[{"id":"1.232460189","rc":[{"trd":[[1.01,5448.01]],"batl":[[0,1.01,292.57]],"ltp":1.01,"tv":7088.29,"id":2857968}],"tv":7151.31}]}
{"op":"mcm","clk":"12000279154","pt":1725072338077,"mc":[{"id":"1.232460189","rc":[{"trd":[[1.01,5448.37]],"batl":[[0,1.01,292.39]],"ltp":1.01,"tv":7088.65,"id":2857968}],"tv":7151.67}]}
{"op":"mcm","clk":"12000280596","pt":1725072361078,"mc":[{"id":"1.232460189","rc":[{"trd":[[1.01,5448.56]],"batl":[[0,1.01,292.29]],"ltp":1.01,"tv":7088.85,"id":2857968}],"tv":7151.87}]}
{"op":"mcm","clk":"12000280927","pt":1725072365715,"mc":[{"id":"1.232460189","rc":[{"trd":[[1.01,5532.25]],"batl":[[0,1.01,250.45]],"ltp":1.01,"tv":7172.53,"id":2857968}],"tv":7235.55}]}
{"op":"mcm","clk":"12000281996","pt":1725072380243,"mc":[{"id":"1.232460189","rc":[{"trd":[[110,5.56]],"batb":[[0,110,3.08]],"ltp":110.0,"tv":63.21,"id":73094924}],"tv":7235.75}]}
{"op":"mcm","clk":"12000283056","pt":1725072395867,"mc":[{"id":"1.232460189","rc":[{"trd":[[110,5.76]],"batb":[[0,110,2.98]],"ltp":110.0,"tv":63.41,"id":73094924}],"tv":7235.94}]}
{"op":"mcm","clk":"12000283337","pt":1725072400132,"mc":[{"id":"1.232460189","rc":[{"batb":[[0,110,2.57]],"ltp":110.0,"tv":63.41,"id":73094924}]}]}
{"op":"mcm","clk":"12000283357","pt":1725072400545,"mc":[{"id":"1.232460189","rc":[{"batb":[[0,1.51,165.59],[1,1.46,2],[2,1.05,1.04]],"batl":[[0,110,26.36],[1,300,0.2]],"ltp":110.0,"tv":63.41,"id":73094924}]}]}
{"op":"mcm","clk":"12000283630","pt":1725072405651,"mc":[{"id":"1.232460189","rc":[{"batl":[[0,110,27.32]],"ltp":110.0,"tv":63.41,"id":73094924}]}]}
{"op":"mcm","clk":"12000284942","pt":1725072429780,"mc":[{"id":"1.232460189","rc":[{"trd":[[1.01,5532.44]],"batl":[[0,1.01,250.35]],"ltp":1.01,"tv":7172.73,"id":2857968}],"tv":7236.14}]}
{"op":"mcm","clk":"12000285387","pt":1725072437681,"mc":[{"id":"1.232460189","rc":[{"batl":[[0,110,23.13]],"ltp":110.0,"tv":63.41,"id":73094924}]}]}
{"op":"mcm","clk":"12000286730","pt":1725072464261,"mc":[{"id":"1.232460189","rc":[{"batl":[[0,110,22.36]],"ltp":110.0,"tv":63.41,"id":73094924}]}]}
{"op":"mcm","clk":"12000286915","pt":1725072467743,"mc":[{"id":"1.232460189","rc":[{"batl":[[0,280,1.06],[1,300,0.1]],"ltp":110.0,"tv":63.41,"id":73094924}]}]}
{"op":"mcm","clk":"12000287401","pt":1725072477658,"mc":[{"id":"1.232460189","rc":[{"trd":[[1.01,5541.24]],"batl":[[0,1.01,241.55]],"ltp":1.01,"tv":7181.53,"id":2857968},{"trd":[[100,13.42]],"ltp":100.0,"tv":63.5,"id":73094924}],"tv":7245.03}]}
{"op":"mcm","clk":"12000287618","pt":1725072481876,"mc":[{"id":"1.232460189","rc":[{"trd":[[1.01,5541.97]],"batl":[[0,1.01,241.19]],"ltp":1.01,"tv":7182.26,"id":2857968}],"tv":7245.76}]}
{"op":"mcm","clk":"12000287684","pt":1725072482851,"mc":[{"id":"1.232460189","rc":[{"trd":[[1.01,5542.17]],"batl":[[0,1.01,241.09]],"ltp":1.01,"tv":7182.45,"id":2857968}],"tv":7245.95}]}
{"op":"mcm","clk":"12000288241","pt":1725072493883,"mc":[{"id":"1.232460189","rc":[{"trd":[[1.01,5551.84]],"batl":[[0,1.01,231.42]],"ltp":1.01,"tv":7192.12,"id":2857968},{"trd":[[100,13.51]],"ltp":100.0,"tv":63.59,"id":73094924}],"tv":7255.72}]}
{"op":"mcm","clk":"12000288973","pt":1725072506113,"mc":[{"id":"1.232460189","rc":[{"trd":[[1.01,5561.51]],"batl":[[0,1.01,221.75]],"ltp":1.01,"tv":7201.79,"id":2857968},{"trd":[[100,13.61]],"ltp":100.0,"tv":63.69,"id":73094924}],"tv":7265.49}]}
{"op":"mcm","clk":"12000289472","pt":1725072516313,"mc":[{"id":"1.232460189","rc":[{"trd":[[110,6.58]],"batl":[[0,300,0.75],[1,300,0]],"ltp":110.0,"tv":64.51,"id":73094924}],"tv":7266.31}]}
{"op":"mcm","clk":"12000289598","pt":1725072518612,"mc":[{"id":"1.232460189","rc":[{"batl":[[0,1.01,640.59]],"ltp":1.01,"tv":7201.79,"id":2857968}]}]}
{"op":"mcm","clk":"12000289889","pt":1725072524202,"mc":[{"id":"1.232460189","rc":[{"trd":[[1.01,5562.43]],"batl":[[0,1.01,640.13]],"ltp":1.01,"tv":7202.71,"id":2857968}],"tv":7267.23}]}
{"op":"mcm","clk":"12000290271","pt":1725072531645,"mc":[{"id":"1.232460189","rc":[{"trd":[[1.01,5572.1]],"batl":[[0,1.01,630.46]],"ltp":1.01,"tv":7212.38,"id":2857968},{"trd":[[100,13.71]],"ltp":100.0,"tv":64.61,"id":73094924}],"tv":7277.0}]}
{"op":"mcm","clk":"12000290410","pt":1725072534056,"mc":[{"id":"1.232460189","rc":[{"batl":[[0,240,1.55],[1,300,0.2]],"ltp":100.0,"tv":64.61,"id":73094924}]}]}
{"op":"mcm","clk":"12000290836","pt":1725072542740,"mc":[{"id":"1.232460189","rc":[{"trd":[[1.01,5612.69]],"batl":[[0,1.01,589.86]],"ltp":1.01,"tv":7252.98,"id":2857968},{"trd":[[100,14.12]],"ltp":100.0,"tv":65.02,"id":73094924}],"tv":7318.0}]}
{"op":"mcm","clk":"12000292518","pt":1725072574893,"mc":[{"id":"1.232460189","rc":[{"trd":[[1.01,5622.36]],"batl":[[0,1.01,580.19]],"ltp":1.01,"tv":7262.65,"id":2857968},{"trd":[[100,14.22]],"batl":[[0,240,1.65]],"ltp":100.0,"tv":65.12,"id":73094924}],"tv":7327.77}]}
{"op":"mcm","clk":"12000293663","pt":1725072597634,"mc":[{"id":"1.232460189","rc":[{"trd":[[1.01,5623.53]],"batl":[[0,1.01,579.61]],"ltp":1.01,"tv":7263.81,"id":2857968}],"tv":7328.93}]}
{"op":"mcm","clk":"12000294371","pt":1725072611940,"mc":[{"id":"1.232460189","rc":[{"trd":[[1.01,5633.2]],"batl":[[0,1.01,569.94]],"ltp":1.01,"tv":7273.48,"id":2857968},{"trd":[[100,14.31]],"ltp":100.0,"tv":65.21,"id":73094924}],"tv":7338.7}]}
{"op":"mcm","clk":"12000298748","pt":1725072692860,"mc":[{"id":"1.232460189","rc":[{"trd":[[1.01,5642.87]],"batl":[[0,1.01,560.27]],"ltp":1.01,"tv":7283.15,"id":2857968},{"trd":[[100,14.41]],"ltp":100.0,"tv":65.31,"id":73094924}],"tv":7348.47}]}
{"op":"mcm","clk":"12000298956","pt":1725072696085,"mc":[{"id":"1.232460189","rc":[{"trd":[[1.01,5652.54]],"batl":[[0,1.01,550.6]],"ltp":1.01,"tv":7292.83,"id":2857968},{"trd":[[100,14.51]],"ltp":100.0,"tv":65.41,"id":73094924}],"tv":7358.24}]}
{"op":"mcm","clk":"12000299322","pt":1725072702655,"mc":[{"id":"1.232460189","rc":[{"trd":[[1.01,5701.56]],"batl":[[0,1.01,501.57]],"ltp":1.01,"tv":7341.85,"id":2857968},{"trd":[[100,15]],"ltp":100.0,"tv":65.9,"id":73094924}],"tv":7407.76}]}
{"op":"mcm","clk":"12000299613","pt":1725072708397,"mc":[{"id":"1.232460189","rc":[{"trd":[[1.01,5702.08]],"batl":[[0,1.01,501.32]],"ltp":1.01,"tv":7342.36,"id":2857968}],"tv":7408.27}]}
{"op":"mcm","clk":"12000301516","pt":1725072743827,"mc":[{"id":"1.232460189","rc":[{"trd":[[1.01,5718.83]],"batl":[[0,1.01,492.94]],"ltp":1.01,"tv":7359.12,"id":2857968}],"tv":7425.03}]}
{"op":"mcm","clk":"12000303161","pt":1725072776771,"mc":[{"id":"1.232460189","rc":[{"trd":[[1.01,5728.51]],"batl":[[0,1.01,483.27]],"ltp":1.01,"tv":7368.79,"id":2857968},{"trd":[[100,15.1]],"ltp":100.0,"tv":66.0,"id":73094924}],"tv":7434.8}]}
{"op":"mcm","clk":"12000303929","pt":1725072791805,"mc":[{"id":"1.232460189","rc":[{"trd":[[1.01,5769.1]],"batl":[[0,1.01,442.67]],"ltp":1.01,"tv":7409.39,"id":2857968},{"trd":[[100,15.51]],"ltp":100.0,"tv":66.41,"id":73094924}],"tv":7475.8}]}
{"op":"mcm","clk":"12000304280","pt":1725072797906,"mc":[{"id":"1.232460189","rc":[{"batl":[[0,1.01,23.83]],"ltp":1.01,"tv":7409.39,"id":2857968}]}]}
{"op":"mcm","clk":"12000305196","pt":1725072816020,"mc":[{"id":"1.232460189","rc":[{"batb":[[0,40,8.38],[1,1.51,165.59],[2,1.46,2]],"ltp":100.0,"tv":66.41,"id":73094924}]}]}
{"op":"mcm","clk":"12000305713","pt":1725072825233,"mc":[{"id":"1.232460189","rc":[{"trd":[[1.01,5778.77]],"batl":[[0,1.01,14.16]],"ltp":1.01,"tv":7419.06,"id":2857968},{"trd":[[100,15.61]],"ltp":100.0,"tv":66.51,"id":73094924}],"tv":7485.57}]}
{"op":"mcm","clk":"12000306309","pt":1725072836049,"mc":[{"id":"1.232460189","rc":[{"trd":[[1.01,5807.09]],"batb":[[0,1.01,27.68]],"batl":[[0,1.03,193.86],[1,1.04,1284.71],[2,1.1,42.1]],"ltp":1.01,"tv":7447.38,"id":2857968}],"tv":7513.89}]}
{"op":"mcm","clk":"12000307276","pt":1725072854654,"mc":[{"id":"1.232460189","rc":[{"trd":[[40,0.18]],"batb":[[0,40,8.29]],"ltp":40.0,"tv":66.69,"id":73094924}],"tv":7514.07}]}
{"op":"mcm","clk":"12000307782","pt":1725072864284,"mc":[{"id":"1.232460189","rc":[{"trd":[[1.03,178.96]],"batl":[[0,1.03,193.82]],"ltp":1.03,"tv":7447.46,"id":2857968}],"tv":7514.15}]}
{"op":"mcm","clk":"12000308642","pt":1725072881091,"mc":[{"id":"1.232460189","rc":[{"batl":[[0,240,1.75]],"ltp":40.0,"tv":66.69,"id":73094924}]}]}
{"op":"mcm","clk":"12000308667","pt":1725072882222,"mc":[{"id":"1.232460189","rc":[{"trd":[[40,0.38]],"batb":[[0,40,8.19]],"ltp":40.0,"tv":66.89,"id":73094924}],"tv":7514.35}]}
{"op":"mcm","clk":"12000308932","pt":1725072888432,"mc":[{"id":"1.232460189","rc":[{"trd":[[1.01,5810.75]],"batb":[[0,1.01,25.85]],"ltp":1.01,"tv":7451.11,"id":2857968}],"tv":7518.01}]}
{"op":"mcm","clk":"12000309367","pt":1725072897956,"mc":[{"id":"1.232460189","rc":[{"batl":[[0,1.02,1.83],[1,1.03,193.82],[2,1.04,1284.71]],"ltp":1.01,"tv":7451.11,"id":2857968}]}]}
{"op":"mcm","clk":"12000309656","pt":1725072903732,"mc":[{"id":"1.232460189","rc":[{"trd":[[1.02,1126.23]],"batl":[[0,1.03,193.82],[1,1.04,1284.71],[2,1.1,42.1]],"ltp":1.02,"tv":7452.94,"id":2857968},{"trd":[[40,0.5],[50,15.19]],"batb":[[0,40,8.13]],"ltp":40.0,"tv":67.04,"id":73094924}],"tv":7519.99}]}
{"op":"mcm","clk":"12000309689","pt":1725072904445,"mc":[{"id":"1.232460189","rc":[{"batl":[[0,240,1.65]],"ltp":40.0,"tv":67.04,"id":73094924}]}]}
{"op":"mcm","clk":"12000310141","pt":1725072913445,"mc":[{"id":"1.232460189","rc":[{"trd":[[1.03,179.25]],"batl":[[0,1.03,193.67]],"ltp":1.03,"tv":7453.24,"id":2857968}],"tv":7520.29}]}
{"op":"mcm","clk":"12000310545","pt":1725072920960,"mc":[{"id":"1.232460189","rc":[{"batl":[[0,1.02,418.84],[1,1.03,193.67],[2,1.04,1284.71]],"ltp":1.03,"tv":7453.24,"id":2857968}]}]}
{"op":"mcm","clk":"12000311238","pt":1725072935111,"mc":[{"id":"1.232460189","rc":[{"batb":[[0,55,8.38],[1,40,8.13],[2,1.51,165.59]],"ltp":40.0,"tv":67.04,"id":73094924}]}]}
{"op":"mcm","clk":"12000311572","pt":1725072940237,"mc":[{"id":"1.232460189","rc":[{"trd":[[1.02,1126.53]],"batl":[[0,1.02,418.69]],"ltp":1.02,"tv":7453.53,"id":2857968},{"batb":[[1,1.51,165.59],[2,1.46,2]],"ltp":40.0,"tv":67.04,"id":73094924}],"tv":7520.58}]}
{"op":"mcm","clk":"12000311713","pt":1725072942346,"mc":[{"id":"1.232460189","rc":[{"trd":[[1.02,1127.44]],"batl":[[0,1.02,418.23]],"ltp":1.02,"tv":7454.45,"id":2857968}],"tv":7521.5}]}
{"op":"mcm","clk":"12000311867","pt":1725072945164,"mc":[{"id":"1.232460189","rc":[{"trd":[[1.02,1127.74]],"batl":[[0,1.02,418.08]],"ltp":1.02,"tv":7454.75,"id":2857968}],"tv":7521.8}]}
{"op":"mcm","clk":"12000312034","pt":1725072948549,"mc":[{"id":"1.232460189","rc":[{"trd":[[1.02,1128]],"batl":[[0,1.02,417.95]],"ltp":1.02,"tv":7455.01,"id":2857968}],"tv":7522.05}]}
{"op":"mcm","clk":"12000312202","pt":1725072951938,"mc":[{"id":"1.232460189","rc":[{"trd":[[1.02,1128.3]],"batl":[[0,1.02,417.8]],"ltp":1.02,"tv":7455.3,"id":2857968}],"tv":7522.35}]}
{"op":"mcm","clk":"12000312259","pt":1725072953371,"mc":[{"id":"1.232460189","rc":[{"trd":[[55,5.71]],"batb":[[0,55,8.28]],"ltp":55.0,"tv":67.24,"id":73094924}],"tv":7522.55}]}
{"op":"mcm","clk":"12000312322","pt":1725072954663,"mc":[{"id":"1.232460189","rc":[{"trd":[[1.02,1128.59]],"batl":[[0,1.02,417.65]],"ltp":1.02,"tv":7455.6,"id":2857968}],"tv":7522.85}]}
{"op":"mcm","clk":"12000312719","pt":1725072962763,"mc":[{"id":"1.232460189","rc":[{"trd":[[1.02,1128.89]],"batl":[[0,1.02,417.5]],"ltp":1.02,"tv":7455.9,"id":2857968}],"tv":7523.14}]}
{"op":"mcm","clk":"12000312988","pt":1725072967076,"mc":[{"id":"1.232460189","rc":[{"trd":[[1.02,1129.19]],"batl":[[0,1.02,417.35]],"ltp":1.02,"tv":7456.19,"id":2857968},{"batl":[[0,180,1.49],[1,240,1],[2,300,0.2]],"ltp":55.0,"tv":67.24,"id":73094924}],"tv":7523.44}]}
{"op":"mcm","clk":"12000313015","pt":1725072967485,"mc":[{"id":"1.232460189","rc":[{"trd":[[1.02,1129.48]],"batl":[[0,1.02,417.2]],"ltp":1.02,"tv":7456.49,"id":2857968}],"tv":7523.73}]}
{"op":"mcm","clk":"12000313262","pt":1725072971754,"mc":[{"id":"1.232460189","rc":[{"trd":[[1.02,1129.54]],"batl":[[0,1.02,417.17]],"ltp":1.02,"tv":7456.55,"id":2857968}],"tv":7523.79}]}
{"op":"mcm","clk":"12000313318","pt":1725072972884,"mc":[{"id":"1.232460189","rc":[{"trd":[[1.02,1129.84]],"batl":[[0,1.02,417.02]],"ltp":1.02,"tv":7456.84,"id":2857968}],"tv":7524.09}]}
{"op":"mcm","clk":"12000313507","pt":1725072976268,"mc":[{"id":"1.232460189","rc":[{"trd":[[1.02,1130.13]],"batl":[[0,1.02,416.87]],"ltp":1.02,"tv":7457.14,"id":2857968}],"tv":7524.39}]}
{"op":"mcm","clk":"12000313659","pt":1725072978683,"mc":[{"id":"1.232460189","rc":[{"trd":[[1.02,1130.43]],"batl":[[0,1.02,416.72],[2,1.04,1286.52]],"ltp":1.02,"tv":7457.44,"id":2857968}],"tv":7524.68}]}
{"op":"mcm","clk":"12000313910","pt":1725072983301,"mc":[{"id":"1.232460189","rc":[{"trd":[[1.02,1130.73]],"batl":[[0,1.02,416.57]],"ltp":1.02,"tv":7457.73,"id":2857968}],"tv":7524.98}]}
{"op":"mcm","clk":"12000314207","pt":1725072989291,"mc":[{"id":"1.232460189","rc":[{"trd":[[1.02,1131.02]],"batl":[[0,1.02,416.42]],"ltp":1.02,"tv":7458.03,"id":2857968}],"tv":7525.28}]}
{"op":"mcm","clk":"12000314258","pt":1725072990171,"mc":[{"id":"1.232460189","rc":[{"trd":[[1.02,1131.32]],"batl":[[0,1.02,416.27]],"ltp":1.02,"tv":7458.33,"id":2857968}],"tv":7525.57}]}
{"op":"mcm","clk":"12000314279","pt":1725072990481,"mc":[{"id":"1.232460189","rc":[{"trd":[[1.02,1131.62]],"batl":[[0,1.02,416.12]],"ltp":1.02,"tv":7458.62,"id":2857968}],"tv":7525.87}]}
{"op":"mcm","clk":"12000314457","pt":1725072993313,"mc":[{"id":"1.232460189","rc":[{"trd":[[1.02,1131.91]],"batl":[[0,1.02,415.97]],"ltp":1.02,"tv":7458.92,"id":2857968}],"tv":7526.17}]}
{"op":"mcm","clk":"12000314750","pt":1725072998087,"mc":[{"id":"1.232460189","rc":[{"trd":[[55,5.91]],"batb":[[0,55,8.18]],"ltp":55.0,"tv":67.44,"id":73094924}],"tv":7526.36}]}
{"op":"mcm","clk":"12000314807","pt":1725072999112,"mc":[{"id":"1.232460189","rc":[{"trd":[[1.02,1132.21]],"batl":[[0,1.02,415.82]],"ltp":1.02,"tv":7459.22,"id":2857968}],"tv":7526.66}]}
{"op":"mcm","clk":"12000314845","pt":1725072999778,"mc":[{"id":"1.232460189","rc":[{"trd":[[1.02,1132.51]],"batl":[[0,1.02,415.67]],"ltp":1.02,"tv":7459.51,"id":2857968}],"tv":7526.96}]}
{"op":"mcm","clk":"12000315093","pt":1725073004025,"mc":[{"id":"1.232460189","rc":[{"trd":[[1.02,1132.8]],"batl":[[0,1.02,415.52]],"ltp":1.02,"tv":7459.81,"id":2857968}],"tv":7527.25}]}
{"op":"mcm","clk":"12000315361","pt":1725073008324,"mc":[{"id":"1.232460189","rc":[{"trd":[[1.02,1136.46]],"batl":[[0,1.02,413.69]],"ltp":1.02,"tv":7463.47,"id":2857968}],"tv":7530.91}]}
{"op":"mcm","clk":"12000315402","pt":1725073008991,"mc":[{"id":"1.232460189","rc":[{"trd":[[1.02,1136.58]],"batl":[[0,1.02,413.63]],"ltp":1.02,"tv":7463.58,"id":2857968}],"tv":7531.03}]}
{"op":"mcm","clk":"12000315552","pt":1725073011396,"mc":[{"id":"1.232460189","rc":[{"trd":[[1.02,1137.17]],"batl":[[0,1.02,413.33]],"ltp":1.02,"tv":7464.18,"id":2857968}],"tv":7531.62}]}
{"op":"mcm","clk":"12000315642","pt":1725073013029,"mc":[{"id":"1.232460189","rc":[{"trd":[[1.02,1137.37]],"batl":[[0,1.02,413.23]],"ltp":1.02,"tv":7464.37,"id":2857968},{"trd":[[55,6.11]],"batb":[[0,55,8.08]],"ltp":55.0,"tv":67.64,"id":73094924}],"tv":7532.02}]}
{"op":"mcm","clk":"12000315877","pt":1725073017126,"mc":[{"id":"1.232460189","rc":[{"trd":[[1.02,1137.66]],"batl":[[0,1.02,413.08]],"ltp":1.02,"tv":7464.67,"id":2857968},{"trd":[[55,6.31]],"batb":[[0,55,7.98]],"ltp":55.0,"tv":67.83,"id":73094924}],"tv":7532.51}]}
{"op":"mcm","clk":"12000315985","pt":1725073018919,"mc":[{"id":"1.232460189","rc":[{"trd":[[1.02,1137.75]],"batl":[[0,1.02,413.04]],"ltp":1.02,"tv":7464.75,"id":2857968}],"tv":7532.59}]}
{"op":"mcm","clk":"12000316017","pt":1725073019534,"mc":[{"id":"1.232460189","rc":[{"trd":[[1.02,1138.05]],"batl":[[0,1.02,412.89]],"ltp":1.02,"tv":7465.05,"id":2857968}],"tv":7532.89}]}
{"op":"mcm","clk":"12000316241","pt":1725073023736,"mc":[{"id":"1.232460189","rc":[{"trd":[[1.02,1138.34]],"batl":[[0,1.02,412.74]],"ltp":1.02,"tv":7465.35,"id":2857968},{"trd":[[55,6.5]],"batb":[[0,55,7.88]],"ltp":55.0,"tv":68.03,"id":73094924}],"tv":7533.39}]}
{"op":"mcm","clk":"12000316418","pt":1725073026825,"mc":[{"id":"1.232460189","rc":[{"trd":[[1.02,1138.64]],"batl":[[0,1.02,412.59]],"ltp":1.02,"tv":7465.64,"id":2857968}],"tv":7533.68}]}
{"op":"mcm","clk":"12000316749","pt":1725073032366,"mc":[{"id":"1.232460189","rc":[{"trd":[[1.02,1138.93]],"batl":[[0,1.02,412.44]],"ltp":1.02,"tv":7465.94,"id":2857968},{"batl":[[2,300,0.1]],"ltp":55.0,"tv":68.03,"id":73094924}],"tv":7533.98}]}
{"op":"mcm","clk":"12000316909","pt":1725073034755,"mc":[{"id":"1.232460189","rc":[{"trd":[[1.02,1139.23]],"batl":[[0,1.02,412.29]],"ltp":1.02,"tv":7466.24,"id":2857968}],"tv":7534.27}]}
{"op":"mcm","clk":"12000316968","pt":1725073035741,"mc":[{"id":"1.232460189","rc":[{"batl":[[2,300,0]],"ltp":55.0,"tv":68.03,"id":73094924}]}]}
{"op":"mcm","clk":"12000317069","pt":1725073037167,"mc":[{"id":"1.232460189","rc":[{"trd":[[1.02,1139.53]],"batl":[[0,1.02,412.14]],"ltp":1.02,"tv":7466.53,"id":2857968}],"tv":7534.57}]}
{"op":"mcm","clk":"12000317195","pt":1725073039263,"mc":[{"id":"1.232460189","rc":[{"batb":[[0,1.01,17.47]],"ltp":1.02,"tv":7466.53,"id":2857968}]}]}
{"op":"mcm","clk":"12000317279","pt":1725073040558,"mc":[{"id":"1.232460189","rc":[{"trd":[[1.01,5816.61],[1.02,1139.82]],"batb":[[0,1.01,14.54]],"batl":[[0,1.02,411.99]],"ltp":1.01,"tv":7472.69,"id":2857968}],"tv":7540.72}]}
{"op":"mcm","clk":"12000317770","pt":1725073049679,"mc":[{"id":"1.232460189","rc":[{"trd":[[1.02,1146.97]],"batl":[[0,1.03,193.67],[1,1.04,1286.52],[2,1.26,37.92]],"ltp":1.02,"tv":7479.83,"id":2857968},{"trd":[[55,6.63]],"batb":[[0,55,7.75]],"ltp":55.0,"tv":68.16,"id":73094924}],"tv":7548.0}]}
{"op":"mcm","clk":"12000317866","pt":1725073051168,"mc":[{"id":"1.232460189","rc":[{"trd":[[1.02,1147.12]],"ltp":1.02,"tv":7479.98,"id":2857968}],"tv":7548.15}]}
{"op":"mcm","clk":"12000318099","pt":1725073055065,"mc":[{"id":"1.232460189","rc":[{"trd":[[1.02,1147.26]],"ltp":1.02,"tv":7480.13,"id":2857968}],"tv":7548.3}]}
{"op":"mcm","clk":"12000318403","pt":1725073061012,"mc":[{"id":"1.232460189","rc":[{"trd":[[1.02,1147.41]],"ltp":1.02,"tv":7480.27,"id":2857968}],"tv":7548.44}]}
{"op":"mcm","clk":"12000318529","pt":1725073063995,"mc":[{"id":"1.232460189","rc":[{"trd":[[1.02,1147.56]],"ltp":1.02,"tv":7480.42,"id":2857968}],"tv":7548.59}]}
{"op":"mcm","clk":"12000318730","pt":1725073068873,"mc":[{"id":"1.232460189","rc":[{"trd":[[1.02,1147.7]],"ltp":1.02,"tv":7480.57,"id":2857968}],"tv":7548.73}]}
{"op":"mcm","clk":"12000318929","pt":1725073072615,"mc":[{"id":"1.232460189","rc":[{"trd":[[1.02,1147.85]],"ltp":1.02,"tv":7480.71,"id":2857968}],"tv":7548.88}]}
{"op":"mcm","clk":"12000319037","pt":1725073074665,"mc":[{"id":"1.232460189","rc":[{"trd":[[1.02,1148]],"ltp":1.02,"tv":7480.86,"id":2857968}],"tv":7549.03}]}
{"op":"mcm","clk":"12000319116","pt":1725073076918,"mc":[{"id":"1.232460189","rc":[{"trd":[[1.02,1148.14]],"ltp":1.02,"tv":7481.01,"id":2857968}],"tv":7549.17}]}
{"op":"mcm","clk":"12000319297","pt":1725073080575,"mc":[{"id":"1.232460189","rc":[{"trd":[[55,6.83]],"batb":[[0,55,7.65]],"ltp":55.0,"tv":68.36,"id":73094924}],"tv":7549.37}]}
{"op":"mcm","clk":"12000319506","pt":1725073084899,"mc":[{"id":"1.232460189","rc":[{"trd":[[1.02,1148.29]],"ltp":1.02,"tv":7481.15,"id":2857968}],"tv":7549.52}]}
{"op":"mcm","clk":"12000319601","pt":1725073086998,"mc":[{"id":"1.232460189","rc":[{"trd":[[1.02,1148.44]],"ltp":1.02,"tv":7481.3,"id":2857968}],"tv":7549.67}]}
{"op":"mcm","clk":"12000319644","pt":1725073087725,"mc":[{"id":"1.232460189","rc":[{"trd":[[1.01,5820.26],[1.02,1148.58]],"batb":[[0,1.01,12.71]],"ltp":1.01,"tv":7485.1,"id":2857968}],"tv":7553.47}]}
{"op":"mcm","clk":"12000319852","pt":1725073091613,"mc":[{"id":"1.232460189","rc":[{"batl":[[2,1.08,3369.25]],"ltp":1.01,"tv":7485.1,"id":2857968}]}]}
{"op":"mcm","clk":"12000319955","pt":1725073093508,"mc":[{"id":"1.232460189","rc":[{"trd":[[1.02,1148.73]],"ltp":1.02,"tv":7485.25,"id":2857968}],"tv":7553.61}]}
{"op":"mcm","clk":"12000320212","pt":1725073098223,"mc":[{"id":"1.232460189","rc":[{"trd":[[1.02,1148.88]],"ltp":1.02,"tv":7485.4,"id":2857968}],"tv":7553.76}]}
{"op":"mcm","clk":"12000320285","pt":1725073099611,"mc":[{"id":"1.232460189","rc":[{"trd":[[1.02,1190.72]],"ltp":1.02,"tv":7527.24,"id":2857968},{"trd":[[55,7.61]],"batb":[[0,55,6.87]],"ltp":55.0,"tv":69.14,"id":73094924}],"tv":7596.38}]}
{"op":"mcm","clk":"12000320374","pt":1725073101042,"mc":[{"id":"1.232460189","rc":[{"batb":[[0,1.01,16.9]],"ltp":1.02,"tv":7527.24,"id":2857968},{"trd":[[55,7.81]],"batb":[[0,55,6.77]],"ltp":55.0,"tv":69.34,"id":73094924}],"tv":7596.58}]}
{"op":"mcm","clk":"12000320490","pt":1725073102733,"mc":[{"id":"1.232460189","rc":[{"trd":[[1.01,5822.09],[1.02,1190.86]],"batb":[[0,1.01,15.99]],"ltp":1.02,"tv":7529.21,"id":2857968}],"tv":7598.55}]}
{"op":"mcm","clk":"12000320677","pt":1725073106419,"mc":[{"id":"1.232460189","rc":[{"trd":[[1.02,1191.01]],"ltp":1.02,"tv":7529.35,"id":2857968}],"tv":7598.69}]}
{"op":"mcm","clk":"12000320888","pt":1725073110824,"mc":[{"id":"1.232460189","rc":[{"trd":[[1.01,5825.74]],"batb":[[0,1.01,14.16]],"ltp":1.01,"tv":7533.01,"id":2857968}],"tv":7602.35}]}
{"op":"mcm","clk":"12000321090","pt":1725073115341,"mc":[{"id":"1.232460189","rc":[{"trd":[[55,8.01]],"batb":[[0,55,6.67]],"batl":[[0,240,1.65],[1,240,0]],"ltp":55.0,"tv":69.54,"id":73094924}],"tv":7602.55}]}
{"op":"mcm","clk":"12000321155","pt":1725073116621,"mc":[{"id":"1.232460189","rc":[{"trd":[[1.02,1199.86]],"ltp":1.02,"tv":7541.86,"id":2857968},{"trd":[[55,8.17]],"batb":[[0,55,6.51]],"ltp":55.0,"tv":69.7,"id":73094924}],"tv":7611.56}]}
{"op":"mcm","clk":"12000321417","pt":1725073121327,"mc":[{"id":"1.232460189","rc":[{"trd":[[1.02,1200.01]],"ltp":1.02,"tv":7542.0,"id":2857968}],"tv":7611.71}]}
{"op":"mcm","clk":"12000321583","pt":1725073124263,"mc":[{"id":"1.232460189","rc":[{"trd":[[1.01,5827.48]],"batb":[[0,1.01,13.29]],"ltp":1.01,"tv":7543.74,"id":2857968}],"tv":7613.44}]}
{"op":"mcm","clk":"12000321627","pt":1725073125129,"mc":[{"id":"1.232460189","rc":[{"batl":[[0,240,1.75]],"ltp":55.0,"tv":69.7,"id":73094924}]}]}
{"op":"mcm","clk":"12000321673","pt":1725073126173,"mc":[{"id":"1.232460189","rc":[{"trd":[[1.02,1200.15]],"ltp":1.02,"tv":7543.89,"id":2857968}],"tv":7613.59}]}
{"op":"mcm","clk":"12000322440","pt":1725073141694,"mc":[{"id":"1.232460189","rc":[{"trd":[[55,8.52]],"batb":[[0,55,6.33]],"ltp":55.0,"tv":70.05,"id":73094924}],"tv":7613.95}]}
{"op":"mcm","clk":"12000322648","pt":1725073147103,"mc":[{"id":"1.232460189","rc":[{"trd":[[1.02,1200.21]],"ltp":1.02,"tv":7543.95,"id":2857968}],"tv":7614.0}]}
{"op":"mcm","clk":"12000322898","pt":1725073152316,"mc":[{"id":"1.232460189","rc":[{"trd":[[1.02,1200.36]],"ltp":1.02,"tv":7544.09,"id":2857968}],"tv":7614.15}]}
{"op":"mcm","clk":"12000323038","pt":1725073155898,"mc":[{"id":"1.232460189","rc":[{"batb":[[0,55,5.49]],"ltp":55.0,"tv":70.05,"id":73094924}]}]}
{"op":"mcm","clk":"12000323256","pt":1725073161929,"mc":[{"id":"1.232460189","rc":[{"trd":[[1.02,1200.5]],"ltp":1.02,"tv":7544.24,"id":2857968}],"tv":7614.3}]}
{"op":"mcm","clk":"12000323457","pt":1725073167698,"mc":[{"id":"1.232460189","rc":[{"batl":[[0,1.03,165.03]],"ltp":1.02,"tv":7544.24,"id":2857968}]}]}
{"op":"mcm","clk":"12000323578","pt":1725073170200,"mc":[{"id":"1.232460189","rc":[{"trd":[[1.02,1200.65]],"batl":[[0,1.02,42.11],[1,1.03,165.03],[2,1.04,1286.52]],"ltp":1.02,"tv":7544.39,"id":2857968}],"tv":7614.44}]}
{"op":"mcm","clk":"12000323585","pt":1725073170510,"mc":[{"id":"1.232460189","rc":[{"trd":[[1.02,1200.94]],"batl":[[0,1.02,41.97]],"ltp":1.02,"tv":7544.68,"id":2857968}],"tv":7614.73}]}
{"op":"mcm","clk":"12000323769","pt":1725073176038,"mc":[{"id":"1.232460189","rc":[{"trd":[[1.02,1201.14]],"batl":[[0,1.02,41.87]],"ltp":1.02,"tv":7544.88,"id":2857968}],"tv":7614.93}]}
{"op":"mcm","clk":"12000323883","pt":1725073178859,"mc":[{"id":"1.232460189","rc":[{"trd":[[1.02,1201.43]],"batl":[[0,1.02,41.72]],"ltp":1.02,"tv":7545.16,"id":2857968}],"tv":7615.22}]}
{"op":"mcm","clk":"12000324117","pt":1725073185136,"mc":[{"id":"1.232460189","rc":[{"batb":[[0,1.51,165.59],[1,1.46,2],[2,1.05,1.04]],"ltp":55.0,"tv":70.05,"id":73094924}]}]}
{"op":"mcm","clk":"12000324262","pt":1725073188720,"mc":[{"id":"1.232460189","rc":[{"batl":[[0,240,1.85]],"ltp":55.0,"tv":70.05,"id":73094924}]}]}
{"op":"mcm","clk":"12000324393","pt":1725073192862,"mc":[{"id":"1.232460189","rc":[{"batl":[[0,240,1.75]],"ltp":55.0,"tv":70.05,"id":73094924}]}]}
{"op":"mcm","clk":"12000324483","pt":1725073195364,"mc":[{"id":"1.232460189","rc":[{"trd":[[1.02,1201.72]],"batl":[[0,1.02,41.58]],"ltp":1.02,"tv":7545.45,"id":2857968}],"tv":7615.51}]}
{"op":"mcm","clk":"12000324998","pt":1725073205959,"mc":[{"id":"1.232460189","rc":[{"trd":[[1.02,1206.5]],"batl":[[0,1.02,36.8]],"ltp":1.02,"tv":7550.24,"id":2857968},{"trd":[[50,15.29]],"batb":[[0,38,8.38],[1,1.51,165.59],[2,1.46,2]],"ltp":50.0,"tv":70.15,"id":73094924}],"tv":7620.39}]}
{"op":"mcm","clk":"12000325093","pt":1725073207544,"mc":[{"id":"1.232460189","rc":[{"trd":[[1.02,1206.79]],"batl":[[0,1.02,36.65]],"ltp":1.02,"tv":7550.53,"id":2857968}],"tv":7620.68}]}
{"op":"mcm","clk":"12000325469","pt":1725073213077,"mc":[{"id":"1.232460189","rc":[{"trd":[[1.02,1207.08]],"batl":[[0,1.02,36.51]],"ltp":1.02,"tv":7550.82,"id":2857968}],"tv":7620.97}]}
{"op":"mcm","clk":"12000325697","pt":1725073217187,"mc":[{"id":"1.232460189","rc":[{"trd":[[1.02,1207.99]],"batl":[[0,1.02,36.06]],"ltp":1.02,"tv":7551.73,"id":2857968}],"tv":7621.88}]}
{"op":"mcm","clk":"12000325995","pt":1725073222681,"mc":[{"id":"1.232460189","rc":[{"batb":[[0,55,8.38],[1,38,8.38],[2,1.51,165.59]],"ltp":50.0,"tv":70.15,"id":73094924}]}]}
{"op":"mcm","clk":"12000326258","pt":1725073228106,"mc":[{"id":"1.232460189","rc":[{"trd":[[1.02,1208.28]],"batl":[[0,1.02,35.91]],"ltp":1.02,"tv":7552.02,"id":2857968}],"tv":7622.17}]}
{"op":"mcm","clk":"12000326305","pt":1725073228873,"mc":[{"id":"1.232460189","rc":[{"trd":[[55,8.72]],"batb":[[0,55,8.28]],"ltp":55.0,"tv":70.35,"id":73094924}],"tv":7622.37}]}
{"op":"mcm","clk":"12000326335","pt":1725073229589,"mc":[{"id":"1.232460189","rc":[{"batb":[[1,1.51,165.59],[2,1.46,2]],"ltp":55.0,"tv":70.35,"id":73094924}]}]}
{"op":"mcm","clk":"12000326475","pt":1725073232967,"mc":[{"id":"1.232460189","rc":[{"trd":[[1.02,1208.57]],"batl":[[0,1.02,35.77]],"ltp":1.02,"tv":7552.31,"id":2857968}],"tv":7622.66}]}
{"op":"mcm","clk":"12000326694","pt":1725073238094,"mc":[{"id":"1.232460189","rc":[{"trd":[[55,8.92]],"batb":[[0,55,8.18]],"ltp":55.0,"tv":70.55,"id":73094924}],"tv":7622.86}]}
{"op":"mcm","clk":"12000326973","pt":1725073244295,"mc":[{"id":"1.232460189","rc":[{"batl":[[1,1.03,41]],"ltp":1.02,"tv":7552.31,"id":2857968}]}]}
{"op":"mcm","clk":"12000327177","pt":1725073248302,"mc":[{"id":"1.232460189","rc":[{"trd":[[1.02,1209.77]],"batl":[[0,1.02,35.17]],"ltp":1.02,"tv":7553.51,"id":2857968}],"tv":7624.06}]}
{"op":"mcm","clk":"12000327362","pt":1725073252207,"mc":[{"id":"1.232460189","rc":[{"trd":[[1.02,1210.06]],"batl":[[0,1.02,35.03]],"ltp":1.02,"tv":7553.8,"id":2857968}],"tv":7624.35}]}
{"op":"mcm","clk":"12000327620","pt":1725073256900,"mc":[{"id":"1.232460189","rc":[{"trd":[[1.02,1210.35]],"batl":[[0,1.02,34.89]],"ltp":1.02,"tv":7554.09,"id":2857968}],"tv":7624.64}]}
{"op":"mcm","clk":"12000327972","pt":1725073263825,"mc":[{"id":"1.232460189","rc":[{"batb":[[0,55,10.28]],"ltp":55.0,"tv":70.55,"id":73094924}]}]}
{"op":"mcm","clk":"12000328035","pt":1725073265113,"mc":[{"id":"1.232460189","rc":[{"trd":[[1.01,5837.15]],"batl":[[0,1.01,10.55],[1,1.02,198.06],[2,1.03,41]],"ltp":1.01,"tv":7563.76,"id":2857968},{"trd":[[100,15.71]],"batl":[[0,240,1.65]],"ltp":100.0,"tv":70.64,"id":73094924}],"tv":7634.41}]}
{"op":"mcm","clk":"12000328055","pt":1725073265524,"mc":[{"id":"1.232460189","rc":[{"trd":[[1.01,5837.45]],"batl":[[0,1.01,10.4]],"ltp":1.01,"tv":7564.06,"id":2857968}],"tv":7634.7}]}
{"op":"mcm","clk":"12000328130","pt":1725073267117,"mc":[{"id":"1.232460189","rc":[{"trd":[[1.01,5837.74]],"batl":[[0,1.01,10.25]],"ltp":1.01,"tv":7564.35,"id":2857968},{"batb":[[0,55,2.1]],"ltp":100.0,"tv":70.64,"id":73094924}],"tv":7635.0}]}
{"op":"mcm","clk":"12000328259","pt":1725073269837,"mc":[{"id":"1.232460189","rc":[{"trd":[[1.01,5838.56]],"batl":[[0,1.01,9.84]],"ltp":1.01,"tv":7565.17,"id":2857968}],"tv":7635.82}]}
{"op":"mcm","clk":"12000329118","pt":1725073287873,"mc":[{"id":"1.232460189","rc":[{"trd":[[1.01,5848.23]],"batl":[[0,1.02,198.06],[1,1.03,41],[2,1.04,1286.52]],"ltp":1.01,"tv":7574.84,"id":2857968},{"trd":[[100,15.81]],"ltp":100.0,"tv":70.74,"id":73094924}],"tv":7645.59}]}
{"op":"mcm","clk":"12000329422","pt":1725073294558,"mc":[{"id":"1.232460189","rc":[{"batb":[[0,1.01,16.76]],"ltp":1.01,"tv":7574.84,"id":2857968}]}]}
{"op":"mcm","clk":"12000329823","pt":1725073303652,"mc":[{"id":"1.232460189","rc":[{"batl":[[0,1.01,3490.09],[1,1.02,198.06],[2,1.03,41]],"ltp":1.01,"tv":7574.84,"id":2857968}]}]}
{"op":"mcm","clk":"12000330305","pt":1725073315182,"mc":[{"id":"1.232460189","rc":[{"trd":[[1.01,5848.97]],"batl":[[0,1.01,3489.72]],"ltp":1.01,"tv":7575.58,"id":2857968}],"tv":7646.33}]}
{"op":"mcm","clk":"12000330384","pt":1725073317390,"mc":[{"id":"1.232460189","rc":[{"batb":[[0,1.51,165.59],[1,1.46,2],[2,1.05,1.04]],"ltp":100.0,"tv":70.74,"id":73094924}]}]}
{"op":"mcm","clk":"12000330871","pt":1725073328616,"mc":[{"id":"1.232460189","rc":[{"trd":[[1.01,5858.64]],"batl":[[0,1.01,3480.05]],"ltp":1.01,"tv":7585.25,"id":2857968},{"trd":[[100,15.9]],"ltp":100.0,"tv":70.84,"id":73094924}],"tv":7656.09}]}
{"op":"mcm","clk":"12000330956","pt":1725073330818,"mc":[{"id":"1.232460189","rc":[{"trd":[[110,7.88]],"batb":[[0,110,3.54],[1,1.51,165.59],[2,1.46,2]],"batl":[[0,240,1]],"ltp":110.0,"tv":72.14,"id":73094924}],"tv":7657.39}]}
{"op":"mcm","clk":"12000331568","pt":1725073344006,"mc":[{"id":"1.232460189","rc":[{"trd":[[1.01,5859.3]],"batl":[[0,1.01,3479.72]],"ltp":1.01,"tv":7585.91,"id":2857968}],"tv":7658.05}]}
{"op":"mcm","clk":"12000332738","pt":1725073370064,"mc":[{"id":"1.232460189","rc":[{"batb":[[0,110,3.13]],"ltp":110.0,"tv":72.14,"id":73094924}]}]}
{"op":"mcm","clk":"12000332832","pt":1725073371656,"mc":[{"id":"1.232460189","rc":[{"batl":[[0,240,1.22]],"ltp":110.0,"tv":72.14,"id":73094924}]}]}
{"op":"mcm","clk":"12000333501","pt":1725073385666,"mc":[{"id":"1.232460189","rc":[{"trd":[[110,8.08]],"batb":[[0,110,3.03]],"ltp":110.0,"tv":72.34,"id":73094924}],"tv":7658.25}]}
{"op":"mcm","clk":"12000333806","pt":1725073392999,"mc":[{"id":"1.232460189","rc":[{"trd":[[1.01,5859.5]],"batl":[[0,1.01,3479.62]],"ltp":1.01,"tv":7586.11,"id":2857968}],"tv":7658.45}]}
{"op":"mcm","clk":"12000334386","pt":1725073406793,"mc":[{"id":"1.232460189","rc":[{"trd":[[1.01,5859.69]],"batl":[[0,1.01,3479.52]],"ltp":1.01,"tv":7586.3,"id":2857968}],"tv":7658.65}]}
{"op":"mcm","clk":"12000334513","pt":1725073409806,"mc":[{"id":"1.232460189","rc":[{"trd":[[110,8.28]],"batb":[[0,110,2.93]],"ltp":110.0,"tv":72.53,"id":73094924}],"tv":7658.84}]}
{"op":"mcm","clk":"12000335492","pt":1725073432610,"mc":[{"id":"1.232460189","rc":[{"batl":[[0,1.01,3481.33]],"ltp":1.01,"tv":7586.3,"id":2857968}]}]}
{"op":"mcm","clk":"12000336451","pt":1725073456447,"mc":[{"id":"1.232460189","rc":[{"batl":[[0,1.01,3452.88]],"ltp":1.01,"tv":7586.3,"id":2857968}]}]}
{"op":"mcm","clk":"12000337864","pt":1725073494235,"mc":[{"id":"1.232460189","rc":[{"trd":[[1.01,5859.89]],"batl":[[0,1.01,3452.78]],"ltp":1.01,"tv":7586.5,"id":2857968}],"tv":7659.04}]}
{"op":"mcm","clk":"12000338448","pt":1725073506142,"mc":[{"id":"1.232460189","rc":[{"trd":[[1.01,5860.25]],"batl":[[0,1.01,3452.6]],"ltp":1.01,"tv":7586.86,"id":2857968}],"tv":7659.4}]}
{"op":"mcm","clk":"12000338753","pt":1725073512659,"mc":[{"id":"1.232460189","rc":[{"trd":[[1.01,5861.26]],"batl":[[0,1.01,3452.1]],"ltp":1.01,"tv":7587.87,"id":2857968}],"tv":7660.41}]}
{"op":"mcm","clk":"12000339589","pt":1725073530974,"mc":[{"id":"1.232460189","rc":[{"trd":[[110,8.47]],"batb":[[0,110,2.83]],"ltp":110.0,"tv":72.73,"id":73094924}],"tv":7660.6}]}
{"op":"mcm","clk":"12000339821","pt":1725073536277,"mc":[{"id":"1.232460189","rc":[{"batl":[[0,1.01,3443.72]],"ltp":1.01,"tv":7587.87,"id":2857968}]}]}
{"op":"mcm","clk":"12000339984","pt":1725073541244,"mc":[{"id":"1.232460189","rc":[{"trd":[[1.01,5861.62]],"batl":[[0,1.01,3443.54]],"ltp":1.01,"tv":7588.23,"id":2857968}],"tv":7660.97}]}
{"op":"mcm","clk":"12000340096","pt":1725073544469,"mc":[{"id":"1.232460189","rc":[{"batl":[[0,1.01,3434.75]],"ltp":1.01,"tv":7588.23,"id":2857968}]}]}
{"op":"mcm","clk":"12000340185","pt":1725073546977,"mc":[{"id":"1.232460189","rc":[{"batl":[[0,1.01,3436.57]],"ltp":1.01,"tv":7588.23,"id":2857968}]}]}
{"op":"mcm","clk":"12000340692","pt":1725073559878,"mc":[{"id":"1.232460189","rc":[{"batl":[[0,1.01,3415.65]],"ltp":1.01,"tv":7588.23,"id":2857968}]}]}
{"op":"mcm","clk":"12000340811","pt":1725073562693,"mc":[{"id":"1.232460189","rc":[{"trd":[[110,8.83]],"batb":[[0,110,2.65]],"ltp":110.0,"tv":73.09,"id":73094924}],"tv":7661.32}]}
{"op":"mcm","clk":"12000341477","pt":1725073577625,"mc":[{"id":"1.232460189","rc":[{"trd":[[110,9.03]],"batb":[[0,110,2.55]],"ltp":110.0,"tv":73.29,"id":73094924}],"tv":7661.52}]}
{"op":"mcm","clk":"12000342050","pt":1725073593203,"mc":[{"id":"1.232460189","rc":[{"trd":[[110,9.23]],"batb":[[0,110,2.45]],"ltp":110.0,"tv":73.48,"id":73094924}],"tv":7661.72}]}
{"op":"mcm","clk":"12000342625","pt":1725073607750,"mc":[{"id":"1.232460189","rc":[{"batl":[[0,230,1.06],[1,240,1]],"ltp":110.0,"tv":73.48,"id":73094924}]}]}
{"op":"mcm","clk":"12000343897","pt":1725073642890,"mc":[{"id":"1.232460189","rc":[{"trd":[[1.01,5861.82]],"batl":[[0,1.01,3415.55]],"ltp":1.01,"tv":7588.43,"id":2857968}],"tv":7661.92}]}
{"op":"mcm","clk":"12000344641","pt":1725073665606,"mc":[{"id":"1.232460189","rc":[{"trd":[[110,9.42]],"batb":[[0,110,2.35]],"ltp":110.0,"tv":73.68,"id":73094924}],"tv":7662.11}]}
{"op":"mcm","clk":"12000345178","pt":1725073679611,"mc":[{"id":"1.232460189","rc":[{"trd":[[1.01,5862.01]],"batl":[[0,1.01,3415.45]],"ltp":1.01,"tv":7588.62,"id":2857968}],"tv":7662.31}]}
{"op":"mcm","clk":"12000346225","pt":1725073706870,"mc":[{"id":"1.232460189","rc":[{"trd":[[1.01,5862.31]],"batl":[[0,1.01,3415.3]],"ltp":1.01,"tv":7588.92,"id":2857968}],"tv":7662.61}]}
{"op":"mcm","clk":"12000346326","pt":1725073709843,"mc":[{"id":"1.232460189","rc":[{"batl":[[1,1.02,199.88]],"ltp":1.01,"tv":7588.92,"id":2857968}]}]}
{"op":"mcm","clk":"12000347336","pt":1725073735768,"mc":[{"id":"1.232460189","rc":[{"trd":[[110,9.62]],"batb":[[0,110,2.25]],"ltp":110.0,"tv":73.88,"id":73094924}],"tv":7662.8}]}
{"op":"mcm","clk":"12000350426","pt":1725073812453,"mc":[{"id":"1.232460189","rc":[{"batb":[[0,110,1.84]],"ltp":110.0,"tv":73.88,"id":73094924}]}]}
{"op":"mcm","clk":"12000350707","pt":1725073818166,"mc":[{"id":"1.232460189","rc":[{"batb":[[0,110,2.68]],"ltp":110.0,"tv":73.88,"id":73094924}]}]}
{"op":"mcm","clk":"12000351016","pt":1725073823867,"mc":[{"id":"1.232460189","rc":[{"trd":[[110,9.82]],"batb":[[0,110,2.58]],"ltp":110.0,"tv":74.08,"id":73094924}],"tv":7663.0}]}
{"op":"mcm","clk":"12000351861","pt":1725073842100,"mc":[{"id":"1.232460189","rc":[{"batb":[[0,30,1.32],[1,1.51,164.75]],"ltp":110.0,"tv":74.08,"id":73094924}]}]}
{"op":"mcm","clk":"12000353719","pt":1725073883158,"mc":[{"id":"1.232460189","rc":[{"trd":[[1.01,5862.61]],"batl":[[0,1.01,3415.15]],"ltp":1.01,"tv":7589.22,"id":2857968}],"tv":7663.3}]}
{"op":"mcm","clk":"12000354143","pt":1725073894778,"mc":[{"id":"1.232460189","rc":[{"batl":[[0,1.01,3410.96]],"ltp":1.01,"tv":7589.22,"id":2857968}]}]}
{"op":"mcm","clk":"12000354247","pt":1725073898080,"mc":[{"id":"1.232460189","rc":[{"trd":[[1.01,5862.84]],"batl":[[0,1.01,3410.84]],"ltp":1.01,"tv":7589.45,"id":2857968}],"tv":7663.54}]}
{"op":"mcm","clk":"12000354674","pt":1725073909915,"mc":[{"id":"1.232460189","rc":[{"trd":[[1.01,5863.08]],"batl":[[0,1.01,3410.72]],"ltp":1.01,"tv":7589.69,"id":2857968},{"batb":[[0,1.51,165.67],[1,1.46,2],[2,1.05,1.04]],"ltp":110.0,"tv":74.08,"id":73094924}],"tv":7663.77}]}
{"op":"mcm","clk":"12000354869","pt":1725073914278,"mc":[{"id":"1.232460189","rc":[{"trd":[[1.01,5896.11]],"batl":[[0,1.01,3377.87]],"ltp":1.01,"tv":7622.72,"id":2857968},{"trd":[[100,16.23]],"batb":[[0,1.51,165.59]],"ltp":100.0,"tv":74.41,"id":73094924}],"tv":7697.14}]}
{"op":"mcm","clk":"12000355327","pt":1725073925135,"mc":[{"id":"1.232460189","rc":[{"trd":[[1.01,5896.35]],"batl":[[0,1.01,3377.75]],"ltp":1.01,"tv":7622.96,"id":2857968}],"tv":7697.37}]}
{"op":"mcm","clk":"12000355353","pt":1725073925706,"mc":[{"id":"1.232460189","rc":[{"trd":[[1.01,5896.59]],"batl":[[0,1.01,3377.63]],"ltp":1.01,"tv":7623.2,"id":2857968}],"tv":7697.61}]}
{"op":"mcm","clk":"12000355730","pt":1725073935021,"mc":[{"id":"1.232460189","rc":[{"trd":[[1.01,5896.83]],"batl":[[0,1.01,3377.51]],"ltp":1.01,"tv":7623.44,"id":2857968}],"tv":7697.85}]}
{"op":"mcm","clk":"12000356043","pt":1725073942315,"mc":[{"id":"1.232460189","rc":[{"batl":[[0,230,1.16]],"ltp":100.0,"tv":74.41,"id":73094924}]}]}
{"op":"mcm","clk":"12000356070","pt":1725073942928,"mc":[{"id":"1.232460189","rc":[{"trd":[[1.01,6311.68]],"batl":[[0,1.01,2962.66]],"ltp":1.01,"tv":8038.29,"id":2857968},{"trd":[[100,20.42]],"ltp":100.0,"tv":78.6,"id":73094924}],"tv":8116.89}]}
{"op":"mcm","clk":"12000356153","pt":1725073944726,"mc":[{"id":"1.232460189","rc":[{"trd":[[1.01,6311.91]],"batl":[[0,1.01,2962.54]],"ltp":1.01,"tv":8038.52,"id":2857968}],"tv":8117.12}]}
{"op":"mcm","clk":"12000356528","pt":1725073954364,"mc":[{"id":"1.232460189","rc":[{"trd":[[1.01,6312.15]],"batl":[[0,1.01,2962.42]],"ltp":1.01,"tv":8038.76,"id":2857968}],"tv":8117.36}]}
{"op":"mcm","clk":"12000356578","pt":1725073955646,"mc":[{"id":"1.232460189","rc":[{"trd":[[1.01,6321.82]],"batl":[[0,1.01,2952.75]],"ltp":1.01,"tv":8048.43,"id":2857968},{"trd":[[100,20.52]],"ltp":100.0,"tv":78.69,"id":73094924}],"tv":8127.13}]}
{"op":"mcm","clk":"12000356950","pt":1725073963954,"mc":[{"id":"1.232460189","rc":[{"trd":[[1.01,6322.06]],"batl":[[0,1.01,2952.63]],"ltp":1.01,"tv":8048.67,"id":2857968}],"tv":8127.37}]}
{"op":"mcm","clk":"12000357246","pt":1725073970566,"mc":[{"id":"1.232460189","rc":[{"batl":[[0,230,1.06]],"ltp":100.0,"tv":78.69,"id":73094924}]}]}
{"op":"mcm","clk":"12000357394","pt":1725073973488,"mc":[{"id":"1.232460189","rc":[{"trd":[[1.01,6322.29]],"batl":[[0,1.01,2952.51]],"ltp":1.01,"tv":8048.9,"id":2857968}],"tv":8127.6}]}
{"op":"mcm","clk":"12000357658","pt":1725073980366,"mc":[{"id":"1.232460189","rc":[{"trd":[[1.01,6362.88]],"batl":[[0,1.01,2870.08]],"ltp":1.01,"tv":8089.49,"id":2857968},{"trd":[[100,20.93]],"ltp":100.0,"tv":79.1,"id":73094924}],"tv":8168.6}]}
{"op":"mcm","clk":"12000357729","pt":1725073982467,"mc":[{"id":"1.232460189","rc":[{"trd":[[1.01,6363.12]],"batl":[[0,1.01,2869.96]],"ltp":1.01,"tv":8089.73,"id":2857968}],"tv":8168.84}]}
{"op":"mcm","clk":"12000357895","pt":1725073986885,"mc":[{"id":"1.232460189","rc":[{"trd":[[1.01,6363.32]],"batl":[[0,1.01,2869.86]],"ltp":1.01,"tv":8089.93,"id":2857968}],"tv":8169.04}]}
{"op":"mcm","clk":"12000358106","pt":1725073991678,"mc":[{"id":"1.232460189","rc":[{"trd":[[1.01,6363.56]],"batl":[[0,1.01,2869.74]],"ltp":1.01,"tv":8090.17,"id":2857968}],"tv":8169.28}]}
{"op":"mcm","clk":"12000358517","pt":1725074001289,"mc":[{"id":"1.232460189","rc":[{"trd":[[1.01,6363.79]],"batl":[[0,1.01,2869.62]],"ltp":1.01,"tv":8090.4,"id":2857968}],"tv":8169.51}]}
{"op":"mcm","clk":"12000358708","pt":1725074005491,"mc":[{"id":"1.232460189","rc":[{"batl":[[0,1.01,2848.68]],"ltp":1.01,"tv":8090.4,"id":2857968}]}]}
{"op":"mcm","clk":"12000358875","pt":1725074008721,"mc":[{"id":"1.232460189","rc":[{"trd":[[1.01,6363.99]],"batl":[[0,1.01,2848.58]],"ltp":1.01,"tv":8090.6,"id":2857968}],"tv":8169.71}]}
{"op":"mcm","clk":"12000359031","pt":1725074011614,"mc":[{"id":"1.232460189","rc":[{"trd":[[1.01,6373.66]],"batl":[[0,1.01,2838.91]],"ltp":1.01,"tv":8100.27,"id":2857968},{"trd":[[100,21.03]],"ltp":100.0,"tv":79.2,"id":73094924}],"tv":8179.48}]}
{"op":"mcm","clk":"12000359448","pt":1725074020833,"mc":[{"id":"1.232460189","rc":[{"trd":[[1.01,6373.86]],"batl":[[0,1.01,2838.81]],"ltp":1.01,"tv":8100.47,"id":2857968}],"tv":8179.68}]}
{"op":"mcm","clk":"12000359593","pt":1725074023555,"mc":[{"id":"1.232460189","rc":[{"batl":[[1,240,0]],"ltp":100.0,"tv":79.2,"id":73094924}]}]}
{"op":"mcm","clk":"12000359817","pt":1725074028652,"mc":[{"id":"1.232460189","rc":[{"trd":[[1.01,6601.58]],"batl":[[0,1.01,2611.09]],"ltp":1.01,"tv":8328.19,"id":2857968},{"trd":[[100,23.33]],"ltp":100.0,"tv":81.5,"id":73094924}],"tv":8409.7}]}
{"op":"mcm","clk":"12000360259","pt":1725074037656,"mc":[{"id":"1.232460189","rc":[{"trd":[[1.01,6689.19]],"batl":[[0,1.01,2523.48]],"ltp":1.01,"tv":8415.8,"id":2857968},{"trd":[[100,24.21]],"ltp":100.0,"tv":82.39,"id":73094924}],"tv":8498.19}]}
{"op":"mcm","clk":"12000360848","pt":1725074050082,"mc":[{"id":"1.232460189","rc":[{"trd":[[1.01,6698.86]],"batl":[[0,1.01,2513.81]],"ltp":1.01,"tv":8425.47,"id":2857968},{"trd":[[100,24.31]],"ltp":100.0,"tv":82.48,"id":73094924}],"tv":8507.96}]}
{"op":"mcm","clk":"12000361376","pt":1725074060297,"mc":[{"id":"1.232460189","rc":[{"trd":[[1.01,6708.53]],"batl":[[0,1.01,2504.14]],"ltp":1.01,"tv":8435.14,"id":2857968},{"trd":[[100,24.41]],"ltp":100.0,"tv":82.58,"id":73094924}],"tv":8517.73}]}
{"op":"mcm","clk":"12000361913","pt":1725074071302,"mc":[{"id":"1.232460189","rc":[{"trd":[[1.01,6876.97]],"batl":[[0,1.01,2419.92]],"ltp":1.01,"tv":8603.58,"id":2857968}],"tv":8686.17}]}
{"op":"mcm","clk":"12000362234","pt":1725074078273,"mc":[{"id":"1.232460189","rc":[{"trd":[[1.01,6877.13]],"batl":[[0,1.01,2419.84]],"ltp":1.01,"tv":8603.74,"id":2857968},{"batl":[[0,120,0.22]],"ltp":100.0,"tv":82.58,"id":73094924}],"tv":8686.33}]}
{"op":"mcm","clk":"12000362501","pt":1725074082276,"mc":[{"id":"1.232460189","rc":[{"trd":[[1.01,6896.47]],"batl":[[0,1.01,2400.5]],"ltp":1.01,"tv":8623.08,"id":2857968},{"trd":[[100,24.6]],"ltp":100.0,"tv":82.78,"id":73094924}],"tv":8705.86}]}
{"op":"mcm","clk":"12000362536","pt":1725074082786,"mc":[{"id":"1.232460189","rc":[{"batl":[[0,1000,1.06]],"ltp":100.0,"tv":82.78,"id":73094924}]}]}
{"op":"mcm","clk":"12000362941","pt":1725074091499,"mc":[{"id":"1.232460189","rc":[{"trd":[[1.01,6906.14]],"batl":[[0,1.01,2390.83]],"ltp":1.01,"tv":8632.75,"id":2857968},{"trd":[[100,24.7]],"ltp":100.0,"tv":82.88,"id":73094924}],"tv":8715.63}]}
{"op":"mcm","clk":"12000363833","pt":1725074109042,"mc":[{"id":"1.232460189","rc":[{"batl":[[1,1.02,241.99]],"ltp":1.01,"tv":8632.75,"id":2857968}]}]}
{"op":"mcm","clk":"12000363997","pt":1725074112022,"mc":[{"id":"1.232460189","rc":[{"trd":[[1.01,7104.16]],"batl":[[0,1.01,2192.81]],"ltp":1.01,"tv":8830.77,"id":2857968},{"trd":[[100,26.7]],"ltp":100.0,"tv":84.88,"id":73094924}],"tv":8915.65}]}
{"op":"mcm","clk":"12000364093","pt":1725074114126,"mc":[{"id":"1.232460189","rc":[{"trd":[[1.01,7105.8]],"batl":[[0,1.01,2191.99]],"ltp":1.01,"tv":8832.41,"id":2857968}],"tv":8917.29}]}
{"op":"mcm","clk":"12000364144","pt":1725074115150,"mc":[{"id":"1.232460189","rc":[{"batl":[[0,980,1.06],[1,1000,0.84]],"ltp":100.0,"tv":84.88,"id":73094924}]}]}
{"op":"mcm","clk":"12000364688","pt":1725074126342,"mc":[{"id":"1.232460189","rc":[{"trd":[[1.01,7402.83]],"batl":[[0,1.01,1894.96]],"ltp":1.01,"tv":9129.44,"id":2857968},{"trd":[[100,29.7]],"ltp":100.0,"tv":87.88,"id":73094924}],"tv":9217.32}]}
{"op":"mcm","clk":"12000364704","pt":1725074126653,"mc":[{"id":"1.232460189","rc":[{"batl":[[0,710,1.06],[1,1000,1.68]],"ltp":100.0,"tv":87.88,"id":73094924}]}]}
{"op":"mcm","clk":"12000365105","pt":1725074134671,"mc":[{"id":"1.232460189","rc":[{"batl":[[1,980,0.84]],"ltp":100.0,"tv":87.88,"id":73094924}]}]}
{"op":"mcm","clk":"12000365375","pt":1725074139769,"mc":[{"id":"1.232460189","rc":[{"batl":[[0,700,1.06],[1,980,1.68]],"ltp":100.0,"tv":87.88,"id":73094924}]}]}
{"op":"mcm","clk":"12000365457","pt":1725074140949,"mc":[{"id":"1.232460189","rc":[{"batl":[[0,1.01,1141.05]],"ltp":1.01,"tv":9129.44,"id":2857968}]}]}
{"op":"mcm","clk":"12000365484","pt":1725074141664,"mc":[{"id":"1.232460189","rc":[{"batl":[[1,710,0.84]],"ltp":100.0,"tv":87.88,"id":73094924}]}]}
{"op":"mcm","clk":"12000366100","pt":1725074154057,"mc":[{"id":"1.232460189","rc":[{"trd":[[1.01,7443.42]],"batl":[[0,1.01,1100.46]],"ltp":1.01,"tv":9170.03,"id":2857968},{"trd":[[100,30.11]],"ltp":100.0,"tv":88.29,"id":73094924}],"tv":9258.32}]}
{"op":"mcm","clk":"12000366382","pt":1725074160075,"mc":[{"id":"1.232460189","rc":[{"trd":[[1.01,7443.62]],"batl":[[0,1.01,1100.36]],"ltp":1.01,"tv":9170.23,"id":2857968}],"tv":9258.52}]}
{"op":"mcm","clk":"12000367410","pt":1725074179825,"mc":[{"id":"1.232460189","rc":[{"trd":[[1.01,7484.21]],"batl":[[0,1.01,1059.77]],"ltp":1.01,"tv":9210.82,"id":2857968},{"trd":[[100,30.52]],"ltp":100.0,"tv":88.7,"id":73094924}],"tv":9299.52}]}
{"op":"mcm","clk":"12000367633","pt":1725074184394,"mc":[{"id":"1.232460189","rc":[{"batl":[[0,510,1.06],[1,710,1.68]],"ltp":100.0,"tv":88.7,"id":73094924}]}]}
{"op":"mcm","clk":"12000367969","pt":1725074191103,"mc":[{"id":"1.232460189","rc":[{"batl":[[1,700,0.84]],"ltp":100.0,"tv":88.7,"id":73094924}]}]}
{"op":"mcm","clk":"12000368223","pt":1725074196339,"mc":[{"id":"1.232460189","rc":[{"batl":[[0,1.01,1054.33]],"ltp":1.01,"tv":9210.82,"id":2857968}]}]}
{"op":"mcm","clk":"12000368998","pt":1725074210240,"mc":[{"id":"1.232460189","rc":[{"batl":[[0,1.01,1012.49]],"ltp":1.01,"tv":9210.82,"id":2857968}]}]}
{"op":"mcm","clk":"12000369206","pt":1725074214038,"mc":[{"id":"1.232460189","rc":[{"trd":[[1.01,7484.41]],"batl":[[0,1.01,1012.39]],"ltp":1.01,"tv":9211.02,"id":2857968}],"tv":9299.72}]}
{"op":"mcm","clk":"12000369227","pt":1725074214447,"mc":[{"id":"1.232460189","rc":[{"batl":[[1,700,0]],"ltp":100.0,"tv":88.7,"id":73094924}]}]}
{"op":"mcm","clk":"12000369310","pt":1725074216040,"mc":[{"id":"1.232460189","rc":[{"trd":[[1.01,7494.08]],"batl":[[0,1.01,1002.72]],"ltp":1.01,"tv":9220.69,"id":2857968},{"trd":[[100,30.62]],"ltp":100.0,"tv":88.79,"id":73094924}],"tv":9309.49}]}
{"op":"mcm","clk":"12000369481","pt":1725074219544,"mc":[{"id":"1.232460189","rc":[{"batl":[[0,500,1.06],[1,510,0.84]],"ltp":100.0,"tv":88.79,"id":73094924}]}]}
{"op":"mcm","clk":"12000369962","pt":1725074227475,"mc":[{"id":"1.232460189","rc":[{"batl":[[0,1.01,985.96]],"ltp":1.01,"tv":9220.69,"id":2857968}]}]}
{"op":"mcm","clk":"12000372108","pt":1725074265018,"mc":[{"id":"1.232460189","rc":[{"trd":[[1.01,7503.75]],"batl":[[0,1.01,976.29]],"ltp":1.01,"tv":9230.36,"id":2857968},{"trd":[[100,30.72]],"ltp":100.0,"tv":88.89,"id":73094924}],"tv":9319.26}]}
{"op":"mcm","clk":"12000372836","pt":1725074278410,"mc":[{"id":"1.232460189","rc":[{"trd":[[1.01,7513.42]],"batl":[[0,1.01,966.62]],"ltp":1.01,"tv":9240.03,"id":2857968},{"trd":[[100,30.81]],"ltp":100.0,"tv":88.99,"id":73094924}],"tv":9329.02}]}
{"op":"mcm","clk":"12000375024","pt":1725074320457,"mc":[{"id":"1.232460189","rc":[{"trd":[[1.01,7523.09]],"batl":[[0,1.01,956.95]],"ltp":1.01,"tv":9249.7,"id":2857968},{"trd":[[100,30.91]],"ltp":100.0,"tv":89.09,"id":73094924}],"tv":9338.79}]}
{"op":"mcm","clk":"12000377845","pt":1725074372408,"mc":[{"id":"1.232460189","rc":[{"batl":[[0,1.01,952.76]],"ltp":1.01,"tv":9249.7,"id":2857968}]}]}
{"op":"mcm","clk":"12000378267","pt":1725074381816,"mc":[{"id":"1.232460189","rc":[{"batl":[[1,510,0]],"ltp":100.0,"tv":89.09,"id":73094924}]}]}
{"op":"mcm","clk":"12000379487","pt":1725074405661,"mc":[{"id":"1.232460189","rc":[{"trd":[[1.01,7531.89]],"batl":[[0,1.01,943.96]],"ltp":1.01,"tv":9258.5,"id":2857968},{"trd":[[100,31]],"ltp":100.0,"tv":89.17,"id":73094924}],"tv":9347.68}]}
{"op":"mcm","clk":"12000379550","pt":1725074406850,"mc":[{"id":"1.232460189","rc":[{"trd":[[1.01,7541.56]],"batl":[[0,1.01,934.29]],"ltp":1.01,"tv":9268.17,"id":2857968},{"trd":[[100,31.1]],"ltp":100.0,"tv":89.27,"id":73094924}],"tv":9357.45}]}
{"op":"mcm","clk":"12000380256","pt":1725074419976,"mc":[{"id":"1.232460189","rc":[{"trd":[[1.01,7541.74]],"batl":[[0,1.01,934.2]],"ltp":1.01,"tv":9268.35,"id":2857968}],"tv":9357.62}]}
{"op":"mcm","clk":"12000380318","pt":1725074421667,"mc":[{"id":"1.232460189","rc":[{"trd":[[1.01,7631.47]],"batl":[[0,1.01,844.47]],"ltp":1.01,"tv":9358.08,"id":2857968},{"trd":[[100,32]],"ltp":100.0,"tv":90.18,"id":73094924}],"tv":9448.26}]}
{"op":"mcm","clk":"12000380655","pt":1725074428981,"mc":[{"id":"1.232460189","rc":[{"trd":[[1.01,7631.65]],"batl":[[0,1.01,844.38]],"ltp":1.01,"tv":9358.26,"id":2857968}],"tv":9448.44}]}
{"op":"mcm","clk":"12000381073","pt":1725074437101,"mc":[{"id":"1.232460189","rc":[{"trd":[[1.01,7641.32]],"batl":[[0,1.01,834.71]],"ltp":1.01,"tv":9367.93,"id":2857968},{"trd":[[100,32.1]],"ltp":100.0,"tv":90.28,"id":73094924}],"tv":9458.21}]}
{"op":"mcm","clk":"12000381098","pt":1725074437631,"mc":[{"id":"1.232460189","rc":[{"trd":[[1.01,7641.49]],"batl":[[0,1.01,834.62]],"ltp":1.01,"tv":9368.1,"id":2857968}],"tv":9458.38}]}
{"op":"mcm","clk":"12000381200","pt":1725074440099,"mc":[{"id":"1.232460189","rc":[{"trd":[[1.01,8056.34]],"batl":[[0,1.01,419.77]],"ltp":1.01,"tv":9782.95,"id":2857968},{"trd":[[100,36.29]],"ltp":100.0,"tv":94.47,"id":73094924}],"tv":9877.42}]}
{"op":"mcm","clk":"12000381332","pt":1725074442372,"mc":[{"id":"1.232460189","rc":[{"batl":[[0,120,0.22]],"ltp":100.0,"tv":94.47,"id":73094924}]}]}
{"op":"mcm","clk":"12000381598","pt":1725074446896,"mc":[{"id":"1.232460189","rc":[{"trd":[[1.01,8056.52]],"batl":[[0,1.01,419.68]],"ltp":1.01,"tv":9783.13,"id":2857968}],"tv":9877.6}]}
{"op":"mcm","clk":"12000381630","pt":1725074447512,"mc":[{"id":"1.232460189","rc":[{"batl":[[0,1000,1.06]],"ltp":100.0,"tv":94.47,"id":73094924}]}]}
{"op":"mcm","clk":"12000381891","pt":1725074452187,"mc":[{"id":"1.232460189","rc":[{"trd":[[1.01,8139.69]],"batl":[[0,1.01,336.51]],"ltp":1.01,"tv":9866.3,"id":2857968},{"trd":[[100,37.13]],"batl":[[0,260,1.06],[1,1000,0.84]],"ltp":100.0,"tv":95.31,"id":73094924}],"tv":9961.61}]}
{"op":"mcm","clk":"12000382094","pt":1725074455792,"mc":[{"id":"1.232460189","rc":[{"trd":[[1.01,8189.95]],"batl":[[0,1.01,286.25]],"ltp":1.01,"tv":9916.56,"id":2857968},{"trd":[[100,37.64]],"ltp":100.0,"tv":95.81,"id":73094924}],"tv":10012.38}]}
{"op":"mcm","clk":"12000382127","pt":1725074456411,"mc":[{"id":"1.232460189","rc":[{"trd":[[1.01,8190.13]],"batl":[[0,1.01,281.97]],"ltp":1.01,"tv":9916.74,"id":2857968}],"tv":10012.56}]}
{"op":"mcm","clk":"12000382797","pt":1725074469320,"mc":[{"id":"1.232460189","rc":[{"trd":[[1.01,8190.31]],"batl":[[0,1.01,281.88]],"ltp":1.01,"tv":9916.92,"id":2857968}],"tv":10012.74}]}
{"op":"mcm","clk":"12000382962","pt":1725074471805,"mc":[{"id":"1.232460189","rc":[{"trd":[[1.01,8397.24]],"batl":[[0,1.01,74.95]],"ltp":1.01,"tv":10123.85,"id":2857968},{"trd":[[100,39.73]],"ltp":100.0,"tv":97.9,"id":73094924}],"tv":10221.76}]}
{"op":"mcm","clk":"12000383104","pt":1725074475038,"mc":[{"id":"1.232460189","rc":[{"trd":[[1.01,8406.91]],"batl":[[0,1.01,65.28]],"ltp":1.01,"tv":10133.52,"id":2857968},{"trd":[[100,39.83]],"ltp":100.0,"tv":98.0,"id":73094924}],"tv":10231.52}]}
{"op":"mcm","clk":"12000383304","pt":1725074478544,"mc":[{"id":"1.232460189","rc":[{"batl":[[1,1000,0]],"ltp":100.0,"tv":98.0,"id":73094924}]}]}
{"op":"mcm","clk":"12000383471","pt":1725074481237,"mc":[{"id":"1.232460189","rc":[{"trd":[[1.01,8407.09]],"batl":[[0,1.01,65.19]],"ltp":1.01,"tv":10133.69,"id":2857968}],"tv":10231.7}]}
{"op":"mcm","clk":"12000383612","pt":1725074483608,"mc":[{"id":"1.232460189","rc":[{"batl":[[0,250,1.06],[1,260,0.84]],"ltp":100.0,"tv":98.0,"id":73094924}]}]}
{"op":"mcm","clk":"12000383714","pt":1725074485532,"mc":[{"id":"1.232460189","rc":[{"batl":[[0,1.01,40.06]],"ltp":1.01,"tv":10133.69,"id":2857968}]}]}
{"op":"mcm","clk":"12000383879","pt":1725074488835,"mc":[{"id":"1.232460189","rc":[{"batl":[[1,1.02,165]],"ltp":1.01,"tv":10133.69,"id":2857968}]}]}
{"op":"mcm","clk":"12000383917","pt":1725074489609,"mc":[{"id":"1.232460189","rc":[{"trd":[[1.01,8407.26]],"batl":[[0,1.01,39.97]],"ltp":1.01,"tv":10133.87,"id":2857968}],"tv":10231.88}]}
{"op":"mcm","clk":"12000384027","pt":1725074491742,"mc":[{"id":"1.232460189","rc":[{"batl":[[1,260,0]],"ltp":100.0,"tv":98.0,"id":73094924}]}]}
{"op":"mcm","clk":"12000384428","pt":1725074500138,"mc":[{"id":"1.232460189","rc":[{"trd":[[1.01,8407.44]],"batl":[[0,1.01,39.88]],"ltp":1.01,"tv":10134.05,"id":2857968}],"tv":10232.06}]}
{"op":"mcm","clk":"12000384791","pt":1725074508747,"mc":[{"id":"1.232460189","rc":[{"trd":[[1.01,8407.62]],"batl":[[0,1.01,39.79]],"ltp":1.01,"tv":10134.23,"id":2857968},{"batb":[[0,30,1.75],[1,1.51,164.75],[2,1.46,2]],"ltp":100.0,"tv":98.0,"id":73094924}],"tv":10232.24}]}
{"op":"mcm","clk":"12000384991","pt":1725074513851,"mc":[{"id":"1.232460189","rc":[{"batb":[[1,17,1.68],[2,1.51,164.75]],"ltp":100.0,"tv":98.0,"id":73094924}]}]}
{"op":"mcm","clk":"12000385190","pt":1725074517747,"mc":[{"id":"1.232460189","rc":[{"trd":[[1.01,8407.8]],"batl":[[0,1.01,39.7]],"ltp":1.01,"tv":10134.41,"id":2857968}],"tv":10232.41}]}
{"op":"mcm","clk":"12000385548","pt":1725074526479,"mc":[{"id":"1.232460189","rc":[{"trd":[[1.01,8407.97]],"batl":[[0,1.01,39.61]],"ltp":1.01,"tv":10134.58,"id":2857968}],"tv":10232.59}]}
{"op":"mcm","clk":"12000385993","pt":1725074535878,"mc":[{"id":"1.232460189","rc":[{"trd":[[1.01,8408.15]],"batl":[[0,1.01,39.52]],"ltp":1.01,"tv":10134.76,"id":2857968}],"tv":10232.77}]}
{"op":"mcm","clk":"12000386027","pt":1725074536804,"mc":[{"id":"1.232460189","rc":[{"batb":[[0,17,2.52],[1,1.51,164.75],[2,1.46,2]],"ltp":100.0,"tv":98.0,"id":73094924}]}]}
{"op":"mcm","clk":"12000386525","pt":1725074546888,"mc":[{"id":"1.232460189","rc":[{"trd":[[1.01,8408.33]],"batl":[[0,1.01,39.43]],"ltp":1.01,"tv":10134.94,"id":2857968}],"tv":10232.95}]}
{"op":"mcm","clk":"12000387040","pt":1725074559304,"mc":[{"id":"1.232460189","rc":[{"trd":[[1.01,8408.73]],"batl":[[0,1.01,39.23]],"ltp":1.01,"tv":10135.34,"id":2857968}],"tv":10233.34}]}
{"op":"mcm","clk":"12000387110","pt":1725074560797,"mc":[{"id":"1.232460189","rc":[{"trd":[[1.01,8487.19]],"batb":[[0,1.01,286.58]],"batl":[[0,1.02,165],[1,1.03,41],[2,1.04,1286.52]],"ltp":1.01,"tv":10213.8,"id":2857968}],"tv":10311.81}]}
{"op":"mcm","clk":"12000387567","pt":1725074570349,"mc":[{"id":"1.232460189","rc":[{"batb":[[0,1.51,165.59],[1,1.46,2],[2,1.05,1.04]],"ltp":100.0,"tv":98.0,"id":73094924}]}]}
{"op":"mcm","clk":"12000387801","pt":1725074575430,"mc":[{"id":"1.232460189","rc":[{"batb":[[0,15,2.52],[1,1.51,164.75],[2,1.46,2]],"ltp":100.0,"tv":98.0,"id":73094924}]}]}
{"op":"mcm","clk":"12000387886","pt":1725074576611,"mc":[{"id":"1.232460189","rc":[{"trd":[[1.02,1234.62]],"batl":[[0,1.02,140.73]],"ltp":1.02,"tv":10238.07,"id":2857968},{"trd":[[50,15.78]],"ltp":50.0,"tv":98.5,"id":73094924}],"tv":10336.58}]}
{"op":"mcm","clk":"12000388148","pt":1725074581759,"mc":[{"id":"1.232460189","rc":[{"trd":[[1.02,1239.41]],"batl":[[0,1.02,135.94]],"ltp":1.02,"tv":10242.86,"id":2857968},{"trd":[[50,15.88]],"ltp":50.0,"tv":98.59,"id":73094924}],"tv":10341.46}]}
{"op":"mcm","clk":"12000388788","pt":1725074595674,"mc":[{"id":"1.232460189","rc":[{"trd":[[1.02,1244.2]],"batl":[[0,1.02,131.15]],"ltp":1.02,"tv":10247.65,"id":2857968},{"trd":[[50,15.98]],"ltp":50.0,"tv":98.69,"id":73094924}],"tv":10346.35}]}
{"op":"mcm","clk":"12000389043","pt":1725074599959,"mc":[{"id":"1.232460189","rc":[{"batl":[[0,1.02,214.82]],"ltp":1.02,"tv":10247.65,"id":2857968}]}]}
{"op":"mcm","clk":"12000389499","pt":1725074608953,"mc":[{"id":"1.232460189","rc":[{"batl":[[0,1.02,131.15]],"ltp":1.02,"tv":10247.65,"id":2857968}]}]}
{"op":"mcm","clk":"12000389989","pt":1725074619373,"mc":[{"id":"1.232460189","rc":[{"trd":[[1.02,1375.35]],"batb":[[0,1.01,286.68]],"batl":[[0,1.03,41],[1,1.04,1286.52],[2,1.08,3369.55]],"ltp":1.02,"tv":10378.8,"id":2857968},{"trd":[[50,18.66]],"batl":[[0,50,5.69],[1,250,1.06]],"ltp":50.0,"tv":101.37,"id":73094924}],"tv":10480.18}]}
{"op":"mcm","clk":"12000390158","pt":1725074623112,"mc":[{"id":"1.232460189","rc":[{"batl":[[0,50,5.79]],"ltp":50.0,"tv":101.37,"id":73094924}]}]}
{"op":"mcm","clk":"12000390178","pt":1725074623572,"mc":[{"id":"1.232460189","rc":[{"batb":[[0,1.02,325.91],[1,1.01,286.58]],"ltp":1.02,"tv":10378.8,"id":2857968}]}]}
{"op":"mcm","clk":"12000390255","pt":1725074625473,"mc":[{"id":"1.232460189","rc":[{"batl":[[0,50,5.91]],"ltp":50.0,"tv":101.37,"id":73094924}]}]}
{"op":"mcm","clk":"12000390373","pt":1725074628707,"mc":[{"id":"1.232460189","rc":[{"batl":[[0,50,5.81]],"ltp":50.0,"tv":101.37,"id":73094924}]}]}
{"op":"mcm","clk":"12000390450","pt":1725074630299,"mc":[{"id":"1.232460189","rc":[{"batb":[[1,3.95,3.61],[2,1.51,164.75]],"batl":[[2,630,1.55]],"ltp":50.0,"tv":101.37,"id":73094924}]}]}
{"op":"mcm","clk":"12000390511","pt":1725074631383,"mc":[{"id":"1.232460189","rc":[{"batb":[[0,1.02,326.01]],"ltp":1.02,"tv":10378.8,"id":2857968}]}]}
{"op":"mcm","clk":"12000390566","pt":1725074632572,"mc":[{"id":"1.232460189","rc":[{"batb":[[1,1.51,164.75],[2,1.46,2]],"ltp":50.0,"tv":101.37,"id":73094924}]}]}
{"op":"mcm","clk":"12000390845","pt":1725074637924,"mc":[{"id":"1.232460189","rc":[{"trd":[[1.03,182.47]],"batl":[[0,1.03,37.78]],"ltp":1.03,"tv":10382.02,"id":2857968},{"trd":[[34,4.04]],"batb":[[1,4.8,3.61],[2,1.51,164.75]],"ltp":34.0,"tv":101.47,"id":73094924}],"tv":10483.49}]}
{"op":"mcm","clk":"12000390881","pt":1725074638695,"mc":[{"id":"1.232460189","rc":[{"trd":[[1.03,185.69]],"batl":[[0,1.03,34.56]],"ltp":1.03,"tv":10385.24,"id":2857968},{"trd":[[34,4.13]],"ltp":34.0,"tv":101.57,"id":73094924}],"tv":10486.81}]}
{"op":"mcm","clk":"12000390931","pt":1725074639824,"mc":[{"id":"1.232460189","rc":[{"trd":[[1.02,1376.98]],"batb":[[0,1.02,325.1]],"ltp":1.02,"tv":10386.87,"id":2857968},{"batb":[[1,1.51,164.75],[2,1.46,2]],"batl":[[2,630,0]],"ltp":34.0,"tv":101.57,"id":73094924}],"tv":10488.44}]}
{"op":"mcm","clk":"12000391019","pt":1725074641779,"mc":[{"id":"1.232460189","rc":[{"trd":[[1.02,1378.81]],"batb":[[0,1.02,324.19]],"ltp":1.02,"tv":10388.7,"id":2857968}],"tv":10490.27}]}
{"op":"mcm","clk":"12000391182","pt":1725074645284,"mc":[{"id":"1.232460189","rc":[{"batl":[[0,1.03,118.23]],"ltp":1.02,"tv":10388.7,"id":2857968}]}]}
{"op":"mcm","clk":"12000391259","pt":1725074646721,"mc":[{"id":"1.232460189","rc":[{"trd":[[1.02,2121.83],[1.03,185.89]],"batb":[[0,1.01,286.58],[1,1.01,0]],"batl":[[0,1.03,118.13]],"ltp":1.02,"tv":11131.92,"id":2857968},{"trd":[[50,20.59]],"batl":[[0,50,3.88]],"ltp":50.0,"tv":103.5,"id":73094924}],"tv":11235.42}]}
{"op":"mcm","clk":"12000391479","pt":1725074651293,"mc":[{"id":"1.232460189","rc":[{"trd":[[1.02,2134.39]],"ltp":1.02,"tv":11144.48,"id":2857968},{"trd":[[50,20.85]],"batl":[[0,50,3.62]],"ltp":50.0,"tv":103.76,"id":73094924}],"tv":11248.24}]}
{"op":"mcm","clk":"12000391517","pt":1725074651808,"mc":[{"id":"1.232460189","rc":[{"trd":[[50,21.05]],"batl":[[0,50,3.52]],"ltp":50.0,"tv":103.96,"id":73094924}],"tv":11248.44}]}
{"op":"mcm","clk":"12000391746","pt":1725074656136,"mc":[{"id":"1.232460189","rc":[{"trd":[[1.02,2135.38]],"ltp":1.02,"tv":11145.47,"id":2857968},{"trd":[[50,21.07]],"batl":[[0,50,3.5]],"ltp":50.0,"tv":103.98,"id":73094924}],"tv":11249.45}]}
{"op":"mcm","clk":"12000391801","pt":1725074657217,"mc":[{"id":"1.232460189","rc":[{"batl":[[0,250,1.18],[1,250,0]],"ltp":50.0,"tv":103.98,"id":73094924}]}]}
{"op":"mcm","clk":"12000391838","pt":1725074657936,"mc":[{"id":"1.232460189","rc":[{"trd":[[1.02,2135.67]],"ltp":1.02,"tv":11145.76,"id":2857968},{"trd":[[50,21.07]],"batl":[[0,250,1.18]],"ltp":50.0,"tv":103.98,"id":73094924}],"tv":11249.75}]}
{"op":"mcm","clk":"12000391971","pt":1725074661026,"mc":[{"id":"1.232460189","rc":[{"trd":[[1.03,189.11]],"batl":[[0,1.03,114.91]],"ltp":1.03,"tv":11148.98,"id":2857968},{"trd":[[34,4.23]],"ltp":34.0,"tv":104.08,"id":73094924}],"tv":11253.06}]}
{"op":"mcm","clk":"12000392002","pt":1725074661644,"mc":[{"id":"1.232460189","rc":[{"batb":[[1,3.95,3.61],[2,1.51,164.75]],"batl":[[1,630,1.55]],"ltp":34.0,"tv":104.08,"id":73094924}]}]}
{"op":"mcm","clk":"12000392108","pt":1725074663852,"mc":[{"id":"1.232460189","rc":[{"batb":[[1,1.51,164.75],[2,1.46,2]],"ltp":34.0,"tv":104.08,"id":73094924}]}]}
{"op":"mcm","clk":"12000392295","pt":1725074668160,"mc":[{"id":"1.232460189","rc":[{"batb":[[0,36,8.38],[1,15,2.52],[2,1.51,164.75]],"batl":[[1,630,0]],"ltp":34.0,"tv":104.08,"id":73094924}]}]}
{"op":"mcm","clk":"12000392347","pt":1725074669340,"mc":[{"id":"1.232460189","rc":[{"trd":[[1.03,189.31]],"batl":[[0,1.03,114.81]],"ltp":1.03,"tv":11149.18,"id":2857968},{"batl":[[0,250,1.06]],"ltp":34.0,"tv":104.08,"id":73094924}],"tv":11253.26}]}
{"op":"mcm","clk":"12000392550","pt":1725074674773,"mc":[{"id":"1.232460189","rc":[{"batl":[[0,1.03,114.91]],"ltp":1.03,"tv":11149.18,"id":2857968}]}]}
{"op":"mcm","clk":"12000393313","pt":1725074691870,"mc":[{"id":"1.232460189","rc":[{"batl":[[0,1.03,114.81]],"ltp":1.03,"tv":11149.18,"id":2857968}]}]}
{"op":"mcm","clk":"12000393364","pt":1725074693152,"mc":[{"id":"1.232460189","rc":[{"batb":[[0,1.01,705.42]],"ltp":1.03,"tv":11149.18,"id":2857968}]}]}
{"op":"mcm","clk":"12000393406","pt":1725074693976,"mc":[{"id":"1.232460189","rc":[{"trd":[[1.01,9898.04]],"batl":[[0,1.01,3505.81],[1,1.03,114.81],[2,1.04,1286.52]],"ltp":1.01,"tv":12560.02,"id":2857968}],"tv":12664.11}]}
{"op":"mcm","clk":"12000394045","pt":1725074708991,"mc":[{"id":"1.232460189","rc":[{"batl":[[1,1.03,31.14]],"ltp":1.01,"tv":12560.02,"id":2857968}]}]}
{"op":"mcm","clk":"12000394300","pt":1725074713970,"mc":[{"id":"1.232460189","rc":[{"batl":[[0,120,0.22]],"ltp":34.0,"tv":104.08,"id":73094924}]}]}
{"op":"mcm","clk":"12000394339","pt":1725074714688,"mc":[{"id":"1.232460189","rc":[{"batl":[[1,1.02,1],[2,1.03,31.14]],"ltp":1.01,"tv":12560.02,"id":2857968}]}]}
{"op":"mcm","clk":"12000394376","pt":1725074715510,"mc":[{"id":"1.232460189","rc":[{"batb":[[0,15,2.52],[1,1.51,164.75],[2,1.46,2]],"ltp":34.0,"tv":104.08,"id":73094924}]}]}
{"op":"mcm","clk":"12000395802","pt":1725074744852,"mc":[{"id":"1.232460189","rc":[{"trd":[[1.01,9899.21]],"batl":[[0,1.01,3505.23]],"ltp":1.01,"tv":12561.19,"id":2857968}],"tv":12665.27}]}
{"op":"mcm","clk":"12000396055","pt":1725074749733,"mc":[{"id":"1.232460189","rc":[{"trd":[[1.01,9901.03]],"batl":[[0,1.01,3504.32]],"ltp":1.01,"tv":12563.01,"id":2857968}],"tv":12667.1}]}
{"op":"mcm","clk":"12000396474","pt":1725074758042,"mc":[{"id":"1.232460189","rc":[{"trd":[[1.01,9901.43]],"batl":[[0,1.01,3504.12]],"ltp":1.01,"tv":12563.42,"id":2857968}],"tv":12667.5}]}
{"op":"mcm","clk":"12000397012","pt":1725074768157,"mc":[{"id":"1.232460189","rc":[{"trd":[[1.01,9911.51]],"batl":[[0,1.01,3494.25]],"ltp":1.01,"tv":12573.49,"id":2857968},{"trd":[[100,39.93]],"ltp":100.0,"tv":104.18,"id":73094924}],"tv":12677.67}]}
{"op":"mcm","clk":"12000397267","pt":1725074772560,"mc":[{"id":"1.232460189","rc":[{"batb":[[0,110,4.19],[1,15,2.52],[2,1.51,164.75]],"ltp":100.0,"tv":104.18,"id":73094924}]}]}
{"op":"mcm","clk":"12000397598","pt":1725074778272,"mc":[{"id":"1.232460189","rc":[{"trd":[[1.01,9911.91]],"batl":[[0,1.01,3494.05]],"ltp":1.01,"tv":12573.9,"id":2857968}],"tv":12678.08}]}
{"op":"mcm","clk":"12000397855","pt":1725074782753,"mc":[{"id":"1.232460189","rc":[{"batb":[[0,15,2.52],[1,1.51,164.75],[2,1.46,2]],"ltp":100.0,"tv":104.18,"id":73094924}]}]}
{"op":"mcm","clk":"12000398273","pt":1725074790301,"mc":[{"id":"1.232460189","rc":[{"batb":[[0,1.51,165.59],[1,1.46,2],[2,1.11,418.84]],"ltp":100.0,"tv":104.18,"id":73094924}]}]}
{"op":"mcm","clk":"12000398548","pt":1725074795370,"mc":[{"id":"1.232460189","rc":[{"batb":[[0,26,2.52],[1,1.51,164.75],[2,1.46,2]],"ltp":100.0,"tv":104.18,"id":73094924}]}]}
{"op":"mcm","clk":"12000398685","pt":1725074797887,"mc":[{"id":"1.232460189","rc":[{"trd":[[1.01,9921.58]],"batl":[[0,1.01,3484.38]],"ltp":1.01,"tv":12583.57,"id":2857968},{"trd":[[100,40.02]],"ltp":100.0,"tv":104.27,"id":73094924}],"tv":12687.84}]}
{"op":"mcm","clk":"12000398743","pt":1725074799215,"mc":[{"id":"1.232460189","rc":[{"batb":[[0,1.51,165.59],[1,1.46,2],[2,1.11,418.84]],"ltp":100.0,"tv":104.27,"id":73094924}]}]}
{"op":"mcm","clk":"12000398994","pt":1725074804286,"mc":[{"id":"1.232460189","rc":[{"batb":[[0,27,2.52],[1,1.51,164.75],[2,1.46,2]],"ltp":100.0,"tv":104.27,"id":73094924}]}]}
{"op":"mcm","clk":"12000399583","pt":1725074815930,"mc":[{"id":"1.232460189","rc":[{"trd":[[1.01,9931.25]],"batl":[[0,1.01,3474.71]],"ltp":1.01,"tv":12593.23,"id":2857968},{"trd":[[100,40.12]],"ltp":100.0,"tv":104.37,"id":73094924}],"tv":12697.61}]}
{"op":"mcm","clk":"12000401755","pt":1725074860385,"mc":[{"id":"1.232460189","rc":[{"trd":[[1.01,9959.25]],"batl":[[0,1.01,3460.71]],"ltp":1.01,"tv":12621.23,"id":2857968}],"tv":12725.61}]}
{"op":"mcm","clk":"12000402447","pt":1725074875002,"mc":[{"id":"1.232460189","rc":[{"trd":[[1.01,9968.92]],"batl":[[0,1.01,3451.04]],"ltp":1.01,"tv":12630.9,"id":2857968},{"trd":[[100,40.22]],"ltp":100.0,"tv":104.47,"id":73094924}],"tv":12735.38}]}
{"op":"mcm","clk":"12000403131","pt":1725074889012,"mc":[{"id":"1.232460189","rc":[{"trd":[[1.01,9969.83]],"batl":[[0,1.01,3450.59]],"ltp":1.01,"tv":12631.81,"id":2857968}],"tv":12736.29}]}
{"op":"mcm","clk":"12000403544","pt":1725074897022,"mc":[{"id":"1.232460189","rc":[{"batl":[[1,1.02,2.83]],"ltp":1.01,"tv":12631.81,"id":2857968}]}]}
{"op":"mcm","clk":"12000404212","pt":1725074908645,"mc":[{"id":"1.232460189","rc":[{"trd":[[1.01,9987.33]],"batl":[[0,1.01,3433.08]],"ltp":1.01,"tv":12649.32,"id":2857968},{"trd":[[100,40.4]],"ltp":100.0,"tv":104.65,"id":73094924}],"tv":12753.97}]}
{"op":"mcm","clk":"12000404323","pt":1725074911359,"mc":[{"id":"1.232460189","rc":[{"batl":[[1,1.02,4.65]],"ltp":1.01,"tv":12649.32,"id":2857968}]}]}
{"op":"mcm","clk":"12000404524","pt":1725074914962,"mc":[{"id":"1.232460189","rc":[{"batl":[[0,1.02,4.65],[1,1.03,31.14],[2,1.04,1286.52]],"ltp":1.01,"tv":12649.32,"id":2857968},{"batb":[[0,1.51,165.59],[1,1.46,2],[2,1.11,418.84]],"ltp":100.0,"tv":104.65,"id":73094924}]}]}
{"op":"mcm","clk":"12000404801","pt":1725074920250,"mc":[{"id":"1.232460189","rc":[{"batl":[[0,1.02,1]],"ltp":1.01,"tv":12649.32,"id":2857968},{"batb":[[0,34,1.68],[1,1.51,165.59],[2,1.46,2]],"ltp":100.0,"tv":104.65,"id":73094924}]}]}
{"op":"mcm","clk":"12000405704","pt":1725074937191,"mc":[{"id":"1.232460189","rc":[{"batl":[[0,120,0.32]],"ltp":100.0,"tv":104.65,"id":73094924}]}]}
{"op":"mcm","clk":"12000406774","pt":1725074958403,"mc":[{"id":"1.232460189","rc":[{"trd":[[1.02,2136.67]],"batl":[[0,1.03,31.14],[1,1.04,1286.52],[2,1.08,3369.55]],"ltp":1.02,"tv":12650.32,"id":2857968},{"trd":[[34,4.38],[50,21.09]],"batb":[[0,34,1.61]],"ltp":34.0,"tv":104.82,"id":73094924}],"tv":12755.14}]}
{"op":"mcm","clk":"12000406843","pt":1725074959594,"mc":[{"id":"1.232460189","rc":[{"trd":[[34,4.58]],"batb":[[0,34,1.51]],"ltp":34.0,"tv":105.02,"id":73094924}],"tv":12755.34}]}
{"op":"mcm","clk":"12000407889","pt":1725074978017,"mc":[{"id":"1.232460189","rc":[{"batl":[[0,120,0.22]],"ltp":34.0,"tv":105.02,"id":73094924}]}]}
{"op":"mcm","clk":"12000408005","pt":1725074979618,"mc":[{"id":"1.232460189","rc":[{"batl":[[0,1.02,8.38],[1,1.03,31.14],[2,1.04,1286.52]],"ltp":1.02,"tv":12650.32,"id":2857968}]}]}
{"op":"mcm","clk":"12000408142","pt":1725074981729,"mc":[{"id":"1.232460189","rc":[{"batb":[[0,1.01,149.74]],"ltp":1.02,"tv":12650.32,"id":2857968}]}]}
{"op":"mcm","clk":"12000408198","pt":1725074982754,"mc":[{"id":"1.232460189","rc":[{"trd":[[1.01,9990.95]],"batb":[[0,1.01,147.93]],"ltp":1.01,"tv":12653.93,"id":2857968}],"tv":12758.95}]}
{"op":"mcm","clk":"12000408398","pt":1725074986942,"mc":[{"id":"1.232460189","rc":[{"trd":[[1.01,9991.69]],"batb":[[0,1.01,147.56]],"ltp":1.01,"tv":12654.67,"id":2857968}],"tv":12759.7}]}
{"op":"mcm","clk":"12000409092","pt":1725075002166,"mc":[{"id":"1.232460189","rc":[{"trd":[[1.02,2138.49]],"batl":[[0,1.02,7.47]],"ltp":1.02,"tv":12656.5,"id":2857968}],"tv":12761.52}]}
{"op":"mcm","clk":"12000409208","pt":1725075004234,"mc":[{"id":"1.232460189","rc":[{"batb":[[0,1.51,165.59],[1,1.46,2],[2,1.11,418.84]],"ltp":34.0,"tv":105.02,"id":73094924}]}]}
{"op":"mcm","clk":"12000409462","pt":1725075009363,"mc":[{"id":"1.232460189","rc":[{"batb":[[0,27,2.34],[1,1.51,164.75],[2,1.46,2]],"ltp":34.0,"tv":105.02,"id":73094924}]}]}
{"op":"mcm","clk":"12000410215","pt":1725075022477,"mc":[{"id":"1.232460189","rc":[{"batl":[[0,1.02,11.66]],"ltp":1.02,"tv":12656.5,"id":2857968}]}]}
{"op":"mcm","clk":"12000410558","pt":1725075029192,"mc":[{"id":"1.232460189","rc":[{"batl":[[0,1.02,11.81]],"ltp":1.02,"tv":12656.5,"id":2857968}]}]}
{"op":"mcm","clk":"12000410959","pt":1725075036914,"mc":[{"id":"1.232460189","rc":[{"batl":[[0,1.02,7.62]],"ltp":1.02,"tv":12656.5,"id":2857968}]}]}
{"op":"mcm","clk":"12000411024","pt":1725075038199,"mc":[{"id":"1.232460189","rc":[{"batl":[[0,1.02,7.76]],"ltp":1.02,"tv":12656.5,"id":2857968}]}]}
{"op":"mcm","clk":"12000412230","pt":1725075062238,"mc":[{"id":"1.232460189","rc":[{"batl":[[0,120,0.32]],"ltp":34.0,"tv":105.02,"id":73094924}]}]}
{"op":"mcm","clk":"12000412948","pt":1725075074231,"mc":[{"id":"1.232460189","rc":[{"trd":[[1.01,9995.88]],"ltp":1.01,"tv":12660.69,"id":2857968},{"trd":[[100,40.44]],"batl":[[0,120,0.28]],"ltp":100.0,"tv":105.06,"id":73094924}],"tv":12765.75}]}
{"op":"mcm","clk":"12000413037","pt":1725075076138,"mc":[{"id":"1.232460189","rc":[{"batb":[[0,40,7.54],[1,27,2.34],[2,1.51,164.75]],"ltp":100.0,"tv":105.06,"id":73094924}]}]}
{"op":"mcm","clk":"12000413113","pt":1725075077270,"mc":[{"id":"1.232460189","rc":[{"trd":[[1.02,2138.79]],"batl":[[0,1.02,7.61]],"ltp":1.02,"tv":12660.98,"id":2857968}],"tv":12766.05}]}
{"op":"mcm","clk":"12000413631","pt":1725075087568,"mc":[{"id":"1.232460189","rc":[{"trd":[[1.02,2139.09]],"batl":[[0,1.02,7.46]],"ltp":1.02,"tv":12661.28,"id":2857968}],"tv":12766.34}]}
{"op":"mcm","clk":"12000413926","pt":1725075094189,"mc":[{"id":"1.232460189","rc":[{"batb":[[0,40,7.64]],"ltp":100.0,"tv":105.06,"id":73094924}]}]}
{"op":"mcm","clk":"12000414021","pt":1725075095983,"mc":[{"id":"1.232460189","rc":[{"trd":[[1.01,10001.69]],"batl":[[0,1.01,1.96],[1,1.02,7.46],[2,1.03,31.14]],"ltp":1.01,"tv":12667.08,"id":2857968},{"trd":[[100,40.49]],"batl":[[0,120,0.22]],"ltp":100.0,"tv":105.12,"id":73094924}],"tv":12772.21}]}
{"op":"mcm","clk":"12000414058","pt":1725075096659,"mc":[{"id":"1.232460189","rc":[{"trd":[[1.01,10001.88]],"batl":[[0,1.01,1.86]],"ltp":1.01,"tv":12667.28,"id":2857968}],"tv":12772.4}]}
{"op":"mcm","clk":"12000414335","pt":1725075102187,"mc":[{"id":"1.232460189","rc":[{"batl":[[0,1.02,7.46],[1,1.03,31.14],[2,1.04,1286.52]],"ltp":1.01,"tv":12667.28,"id":2857968}]}]}
{"op":"mcm","clk":"12000414460","pt":1725075104385,"mc":[{"id":"1.232460189","rc":[{"trd":[[1.02,2139.38]],"batl":[[0,1.02,7.31]],"ltp":1.02,"tv":12667.58,"id":2857968}],"tv":12772.7}]}
{"op":"mcm","clk":"12000414848","pt":1725075110497,"mc":[{"id":"1.232460189","rc":[{"trd":[[1.02,2150.67]],"batl":[[0,1.02,1.67]],"ltp":1.02,"tv":12678.86,"id":2857968}],"tv":12783.98}]}
{"op":"mcm","clk":"12000414990","pt":1725075113012,"mc":[{"id":"1.232460189","rc":[{"trd":[[1.02,2150.96]],"batl":[[0,1.02,1.52]],"ltp":1.02,"tv":12679.16,"id":2857968}],"tv":12784.28}]}
{"op":"mcm","clk":"12000415189","pt":1725075117003,"mc":[{"id":"1.232460189","rc":[{"trd":[[1.02,2151.33]],"batl":[[0,1.02,1.34]],"ltp":1.02,"tv":12679.52,"id":2857968}],"tv":12784.64}]}
{"op":"mcm","clk":"12000415308","pt":1725075119407,"mc":[{"id":"1.232460189","rc":[{"trd":[[1.02,2151.43]],"batl":[[0,1.02,1.29]],"ltp":1.02,"tv":12679.62,"id":2857968},{"batb":[[0,40,7.74]],"ltp":100.0,"tv":105.12,"id":73094924}],"tv":12784.74}]}
{"op":"mcm","clk":"12000415340","pt":1725075120020,"mc":[{"id":"1.232460189","rc":[{"batb":[[0,30,1.03],[1,27,1.51]],"ltp":100.0,"tv":105.12,"id":73094924}]}]}
{"op":"mcm","clk":"12000415508","pt":1725075123220,"mc":[{"id":"1.232460189","rc":[{"trd":[[1.02,2151.73]],"batl":[[0,1.02,1.14]],"ltp":1.02,"tv":12679.92,"id":2857968}],"tv":12785.04}]}
{"op":"mcm","clk":"12000415613","pt":1725075125129,"mc":[{"id":"1.232460189","rc":[{"batb":[[0,60,7.64],[1,27,2.44]],"ltp":100.0,"tv":105.12,"id":73094924}]}]}
{"op":"mcm","clk":"12000416002","pt":1725075132406,"mc":[{"id":"1.232460189","rc":[{"batl":[[0,1.01,1.52],[1,1.02,1.14],[2,1.03,31.14]],"ltp":1.02,"tv":12679.92,"id":2857968}]}]}
{"op":"mcm","clk":"12000416122","pt":1725075134301,"mc":[{"id":"1.232460189","rc":[{"trd":[[1.01,10004.93]],"batb":[[0,1.01,691.64]],"batl":[[0,1.02,1.14],[1,1.03,31.14],[2,1.04,1286.52]],"ltp":1.01,"tv":12682.97,"id":2857968}],"tv":12788.09}]}
{"op":"mcm","clk":"12000416187","pt":1725075135322,"mc":[{"id":"1.232460189","rc":[{"trd":[[1.02,2152]],"batl":[[0,1.02,1]],"ltp":1.02,"tv":12683.24,"id":2857968}],"tv":12788.37}]}
{"op":"mcm","clk":"12000416669","pt":1725075143710,"mc":[{"id":"1.232460189","rc":[{"batb":[[0,60,7.54]],"ltp":100.0,"tv":105.12,"id":73094924}]}]}
{"op":"mcm","clk":"12000416792","pt":1725075146013,"mc":[{"id":"1.232460189","rc":[{"trd":[[1.02,2154.51]],"batl":[[0,1.03,31.14],[1,1.04,1286.52],[2,1.08,3369.4]],"ltp":1.02,"tv":12685.75,"id":2857968},{"trd":[[60,0.01]],"batb":[[0,60,7.53]],"ltp":60.0,"tv":105.13,"id":73094924}],"tv":12790.88}]}
{"op":"mcm","clk":"12000416894","pt":1725075148223,"mc":[{"id":"1.232460189","rc":[{"trd":[[60,0.21]],"batb":[[0,60,7.43],[1,27,2.34]],"ltp":60.0,"tv":105.32,"id":73094924}],"tv":12791.08}]}
{"op":"mcm","clk":"12000417018","pt":1725075150941,"mc":[{"id":"1.232460189","rc":[{"trd":[[60,1.05]],"batb":[[0,60,7.01]],"ltp":60.0,"tv":106.16,"id":73094924}],"tv":12791.92}]}
{"op":"mcm","clk":"12000417152","pt":1725075153621,"mc":[{"id":"1.232460189","rc":[{"trd":[[1.02,2155.42]],"ltp":1.02,"tv":12686.66,"id":2857968},{"trd":[[60,1.07]],"batb":[[0,60,6.99]],"ltp":60.0,"tv":106.18,"id":73094924}],"tv":12792.85}]}
{"op":"mcm","clk":"12000417228","pt":1725075155558,"mc":[{"id":"1.232460189","rc":[{"batl":[[2,1.1,51.93]],"ltp":1.02,"tv":12686.66,"id":2857968}]}]}
{"op":"mcm","clk":"12000417371","pt":1725075159032,"mc":[{"id":"1.232460189","rc":[{"trd":[[1.01,10008.58]],"batb":[[0,1.01,689.82]],"ltp":1.01,"tv":12690.32,"id":2857968},{"trd":[[60,1.27]],"batb":[[0,60,6.89]],"ltp":60.0,"tv":106.38,"id":73094924}],"tv":12796.7}]}
{"op":"mcm","clk":"12000417590","pt":1725075164570,"mc":[{"id":"1.232460189","rc":[{"batb":[[0,60,7.01]],"ltp":60.0,"tv":106.38,"id":73094924}]}]}
{"op":"mcm","clk":"12000417853","pt":1725075170984,"mc":[{"id":"1.232460189","rc":[{"trd":[[1.02,2155.62]],"ltp":1.02,"tv":12690.52,"id":2857968},{"trd":[[70,0]],"batb":[[0,60,7.01]],"ltp":70.0,"tv":106.38,"id":73094924}],"tv":12796.91}]}
{"op":"mcm","clk":"12000417882","pt":1725075171651,"mc":[{"id":"1.232460189","rc":[{"trd":[[1.02,2156.54]],"ltp":1.02,"tv":12691.43,"id":2857968},{"trd":[[70,0.02]],"batb":[[0,60,6.99]],"ltp":70.0,"tv":106.4,"id":73094924}],"tv":12797.83}]}
{"op":"mcm","clk":"12000417941","pt":1725075172877,"mc":[{"id":"1.232460189","rc":[{"trd":[[1.02,2156.68]],"ltp":1.02,"tv":12691.58,"id":2857968},{"trd":[[70,0.02]],"batb":[[0,60,6.99]],"ltp":70.0,"tv":106.4,"id":73094924}],"tv":12797.98}]}
{"op":"mcm","clk":"12000418205","pt":1725075179280,"mc":[{"id":"1.232460189","rc":[{"trd":[[1.02,2177.62]],"ltp":1.02,"tv":12712.52,"id":2857968},{"trd":[[60,1.51],[70,0.12]],"batb":[[0,60,6.65]],"ltp":60.0,"tv":106.74,"id":73094924}],"tv":12819.26}]}
{"op":"mcm","clk":"12000418265","pt":1725075180665,"mc":[{"id":"1.232460189","rc":[{"trd":[[1.01,10011.8]],"batb":[[0,1.01,688.21]],"ltp":1.01,"tv":12715.73,"id":2857968}],"tv":12822.48}]}
{"op":"mcm","clk":"12000418403","pt":1725075183546,"mc":[{"id":"1.232460189","rc":[{"trd":[[1.02,2177.83]],"ltp":1.02,"tv":12715.94,"id":2857968}],"tv":12822.68}]}
{"op":"mcm","clk":"12000418576","pt":1725075187553,"mc":[{"id":"1.232460189","rc":[{"batb":[[1,1.51,165.59],[2,1.46,2]],"ltp":60.0,"tv":106.74,"id":73094924}]}]}
{"op":"mcm","clk":"12000418681","pt":1725075189855,"mc":[{"id":"1.232460189","rc":[{"trd":[[1.02,2177.96]],"ltp":1.02,"tv":12716.07,"id":2857968}],"tv":12822.82}]}
{"op":"mcm","clk":"12000418859","pt":1725075193081,"mc":[{"id":"1.232460189","rc":[{"trd":[[1.02,2178.31]],"ltp":1.02,"tv":12716.42,"id":2857968},{"batb":[[1,15,2.34],[2,1.51,164.75]],"ltp":60.0,"tv":106.74,"id":73094924}],"tv":12823.17}]}
{"op":"mcm","clk":"12000419123","pt":1725075197865,"mc":[{"id":"1.232460189","rc":[{"trd":[[1.02,2178.46]],"ltp":1.02,"tv":12716.57,"id":2857968}],"tv":12823.32}]}
{"op":"mcm","clk":"12000419209","pt":1725075199565,"mc":[{"id":"1.232460189","rc":[{"trd":[[1.01,10015.45]],"batb":[[0,1.01,686.38]],"ltp":1.01,"tv":12720.22,"id":2857968}],"tv":12826.97}]}
{"op":"mcm","clk":"12000419267","pt":1725075200893,"mc":[{"id":"1.232460189","rc":[{"trd":[[1.02,2195.22]],"ltp":1.02,"tv":12736.98,"id":2857968},{"trd":[[60,1.79]],"batb":[[0,60,6.37]],"ltp":60.0,"tv":107.02,"id":73094924}],"tv":12844.01}]}
{"op":"mcm","clk":"12000419514","pt":1725075206297,"mc":[{"id":"1.232460189","rc":[{"trd":[[1.02,2198.57]],"ltp":1.02,"tv":12740.33,"id":2857968},{"trd":[[60,1.85]],"batb":[[0,60,6.31]],"batl":[[0,120,0.32]],"ltp":60.0,"tv":107.08,"id":73094924}],"tv":12847.42}]}
{"op":"mcm","clk":"12000419551","pt":1725075207029,"mc":[{"id":"1.232460189","rc":[{"trd":[[1.02,2198.72]],"ltp":1.02,"tv":12740.48,"id":2857968}],"tv":12847.57}]}
{"op":"mcm","clk":"12000419621","pt":1725075208407,"mc":[{"id":"1.232460189","rc":[{"trd":[[1.02,2211.28]],"ltp":1.02,"tv":12753.04,"id":2857968},{"trd":[[60,2.06]],"batb":[[0,60,6.1]],"ltp":60.0,"tv":107.29,"id":73094924}],"tv":12860.34}]}
{"op":"mcm","clk":"12000419652","pt":1725075209280,"mc":[{"id":"1.232460189","rc":[{"trd":[[1.02,2211.37]],"ltp":1.02,"tv":12753.14,"id":2857968},{"trd":[[60,2.88]],"batb":[[0,60,5.69]],"ltp":60.0,"tv":108.11,"id":73094924}],"tv":12861.25}]}
{"op":"mcm","clk":"12000419899","pt":1725075215010,"mc":[{"id":"1.232460189","rc":[{"trd":[[1.01,10023.83]],"batb":[[0,1.01,682.19]],"ltp":1.01,"tv":12761.51,"id":2857968}],"tv":12869.63}]}
{"op":"mcm","clk":"12000419920","pt":1725075215523,"mc":[{"id":"1.232460189","rc":[{"trd":[[1.01,10027.48]],"batb":[[0,1.01,680.37]],"ltp":1.01,"tv":12765.17,"id":2857968}],"tv":12873.28}]}
{"op":"mcm","clk":"12000420188","pt":1725075221729,"mc":[{"id":"1.232460189","rc":[{"trd":[[1.01,10031.14]],"batb":[[0,1.01,678.54]],"ltp":1.01,"tv":12768.82,"id":2857968}],"tv":12876.94}]}
{"op":"mcm","clk":"12000420258","pt":1725075222930,"mc":[{"id":"1.232460189","rc":[{"batb":[[0,15,2.34],[1,1.51,164.75],[2,1.46,2]],"ltp":60.0,"tv":108.11,"id":73094924}]}]}
{"op":"mcm","clk":"12000420398","pt":1725075225825,"mc":[{"id":"1.232460189","rc":[{"batb":[[0,1.01,678.74]],"ltp":1.01,"tv":12768.82,"id":2857968},{"batl":[[0,120,0.42]],"ltp":60.0,"tv":108.11,"id":73094924}]}]}
{"op":"mcm","clk":"12000420486","pt":1725075228026,"mc":[{"id":"1.232460189","rc":[{"trd":[[1.01,10032.56],[1.02,2211.78]],"batb":[[0,1.01,677.83]],"ltp":1.01,"tv":12770.65,"id":2857968},{"trd":[[60,3.07]],"batb":[[0,70,5.59],[1,15,2.34],[2,1.51,164.75]],"batl":[[0,120,0.32]],"ltp":60.0,"tv":108.31,"id":73094924}],"tv":12878.96}]}
{"op":"mcm","clk":"12000420634","pt":1725075230910,"mc":[{"id":"1.232460189","rc":[{"trd":[[1.01,10036.21],[1.02,2211.93]],"batb":[[0,1.01,676]],"ltp":1.01,"tv":12774.45,"id":2857968}],"tv":12882.76}]}
{"op":"mcm","clk":"12000420791","pt":1725075234004,"mc":[{"id":"1.232460189","rc":[{"batb":[[0,15,2.34],[1,1.51,164.75],[2,1.46,2]],"ltp":60.0,"tv":108.31,"id":73094924}]}]}
{"op":"mcm","clk":"12000421042","pt":1725075239111,"mc":[{"id":"1.232460189","rc":[{"batb":[[0,60,5.59],[1,15,2.34],[2,1.51,164.75]],"ltp":60.0,"tv":108.31,"id":73094924}]}]}
{"op":"mcm","clk":"12000421174","pt":1725075242746,"mc":[{"id":"1.232460189","rc":[{"trd":[[1.01,10039.86]],"batb":[[0,1.01,674.18]],"ltp":1.01,"tv":12778.1,"id":2857968}],"tv":12886.41}]}
{"op":"mcm","clk":"12000421453","pt":1725075248935,"mc":[{"id":"1.232460189","rc":[{"trd":[[1.02,2211.98]],"ltp":1.02,"tv":12778.16,"id":2857968}],"tv":12886.47}]}
{"op":"mcm","clk":"12000421583","pt":1725075251342,"mc":[{"id":"1.232460189","rc":[{"trd":[[1.01,10042.97],[1.02,2540.8]],"batb":[[0,1.02,89.56],[1,1.01,672.63]],"ltp":1.02,"tv":13110.08,"id":2857968},{"trd":[[60,8.66]],"batb":[[0,15,2.34],[1,1.51,164.75],[2,1.46,2]],"ltp":60.0,"tv":113.9,"id":73094924}],"tv":13223.99}]}
{"op":"mcm","clk":"12000421774","pt":1725075255033,"mc":[{"id":"1.232460189","rc":[{"batb":[[0,1.02,89.8]],"ltp":1.02,"tv":13110.08,"id":2857968}]}]}
{"op":"mcm","clk":"12000421870","pt":1725075257131,"mc":[{"id":"1.232460189","rc":[{"batb":[[0,1.02,89.95]],"ltp":1.02,"tv":13110.08,"id":2857968}]}]}
{"op":"mcm","clk":"12000421886","pt":1725075257447,"mc":[{"id":"1.232460189","rc":[{"batl":[[0,120,0.5]],"ltp":60.0,"tv":113.9,"id":73094924}]}]}
{"op":"mcm","clk":"12000422152","pt":1725075263638,"mc":[{"id":"1.232460189","rc":[{"trd":[[1.02,2544.46]],"batb":[[0,1.02,88.12]],"ltp":1.02,"tv":13113.74,"id":2857968}],"tv":13227.64}]}
{"op":"mcm","clk":"12000422253","pt":1725075266044,"mc":[{"id":"1.232460189","rc":[{"batb":[[0,1.02,83.93]],"ltp":1.02,"tv":13113.74,"id":2857968},{"batb":[[1,3.9,3.61],[2,1.51,164.75]],"batl":[[0,290,2.05]],"ltp":60.0,"tv":113.9,"id":73094924}]}]}
{"op":"mcm","clk":"12000422292","pt":1725075266966,"mc":[{"id":"1.232460189","rc":[{"batb":[[0,1.02,83.78]],"ltp":1.02,"tv":13113.74,"id":2857968}]}]}
{"op":"mcm","clk":"12000422365","pt":1725075268154,"mc":[{"id":"1.232460189","rc":[{"trd":[[1.02,2546.44],[1.03,189.61]],"batb":[[0,1.02,82.79]],"batl":[[0,1.03,30.99]],"ltp":1.02,"tv":13116.01,"id":2857968},{"batb":[[1,1.51,164.75],[2,1.46,2]],"ltp":60.0,"tv":113.9,"id":73094924}],"tv":13229.91}]}
{"op":"mcm","clk":"12000422504","pt":1725075271540,"mc":[{"id":"1.232460189","rc":[{"trd":[[1.02,2547.13]],"batb":[[0,1.02,82.44]],"ltp":1.02,"tv":13116.71,"id":2857968}],"tv":13230.61}]}
{"op":"mcm","clk":"12000422595","pt":1725075273083,"mc":[{"id":"1.232460189","rc":[{"batb":[[1,4.8,3.61],[2,1.51,164.75]],"ltp":60.0,"tv":113.9,"id":73094924}]}]}
{"op":"mcm","clk":"12000422743","pt":1725075275863,"mc":[{"id":"1.232460189","rc":[{"trd":[[1.02,2549.15]],"batb":[[0,1.02,81.43]],"ltp":1.02,"tv":13118.73,"id":2857968}],"tv":13232.63}]}
{"op":"mcm","clk":"12000422935","pt":1725075279974,"mc":[{"id":"1.232460189","rc":[{"trd":[[1.03,189.9]],"batl":[[0,1.03,30.84]],"ltp":1.03,"tv":13119.03,"id":2857968},{"batl":[[0,290,2.15]],"ltp":60.0,"tv":113.9,"id":73094924}],"tv":13232.93}]}
{"op":"mcm","clk":"12000423252","pt":1725075287075,"mc":[{"id":"1.232460189","rc":[{"trd":[[1.02,2552.81]],"batb":[[0,1.02,79.6]],"ltp":1.02,"tv":13122.68,"id":2857968}],"tv":13236.58}]}
{"op":"mcm","clk":"12000423414","pt":1725075289800,"mc":[{"id":"1.232460189","rc":[{"trd":[[1.03,193.12]],"batl":[[0,1.03,27.62]],"ltp":1.03,"tv":13125.9,"id":2857968},{"trd":[[34,4.68]],"ltp":34.0,"tv":114.0,"id":73094924}],"tv":13239.9}]}
{"op":"mcm","clk":"12000423513","pt":1725075292156,"mc":[{"id":"1.232460189","rc":[{"trd":[[1.03,193.42]],"batl":[[0,1.03,27.47]],"ltp":1.03,"tv":13126.2,"id":2857968}],"tv":13240.2}]}
{"op":"mcm","clk":"12000423744","pt":1725075297590,"mc":[{"id":"1.232460189","rc":[{"batb":[[1,1.51,164.75],[2,1.46,2]],"batl":[[0,120,0.6]],"ltp":34.0,"tv":114.0,"id":73094924}]}]}
{"op":"mcm","clk":"12000423816","pt":1725075299584,"mc":[{"id":"1.232460189","rc":[{"batl":[[0,120,0.42]],"ltp":34.0,"tv":114.0,"id":73094924}]}]}
{"op":"mcm","clk":"12000423909","pt":1725075302006,"mc":[{"id":"1.232460189","rc":[{"trd":[[1.02,2554.45]],"batb":[[0,1.02,78.78]],"ltp":1.02,"tv":13127.84,"id":2857968}],"tv":13241.84}]}
{"op":"mcm","clk":"12000423978","pt":1725075303192,"mc":[{"id":"1.232460189","rc":[{"trd":[[1.02,2554.95]],"batb":[[0,1.01,672.63],[1,1.01,0]],"batl":[[0,1.02,109.48],[1,1.03,27.47],[2,1.04,1286.52]],"ltp":1.02,"tv":13128.33,"id":2857968}],"tv":13242.34}]}
{"op":"mcm","clk":"12000424002","pt":1725075303703,"mc":[{"id":"1.232460189","rc":[{"trd":[[1.02,2555.62]],"batl":[[0,1.02,109.14]],"ltp":1.02,"tv":13129.01,"id":2857968}],"tv":13243.01}]}
{"op":"mcm","clk":"12000424266","pt":1725075307979,"mc":[{"id":"1.232460189","rc":[{"trd":[[1.02,2555.82]],"batl":[[0,1.02,109.04]],"ltp":1.02,"tv":13129.21,"id":2857968}],"tv":13243.21}]}
{"op":"mcm","clk":"12000424308","pt":1725075308698,"mc":[{"id":"1.232460189","rc":[{"trd":[[1.02,2555.88]],"batl":[[0,1.02,109.01]],"ltp":1.02,"tv":13129.27,"id":2857968}],"tv":13243.27}]}
{"op":"mcm","clk":"12000424375","pt":1725075309986,"mc":[{"id":"1.232460189","rc":[{"trd":[[1.02,2591.66]],"batl":[[0,1.02,73.23]],"ltp":1.02,"tv":13165.05,"id":2857968},{"trd":[[50,21.82]],"ltp":50.0,"tv":114.73,"id":73094924}],"tv":13279.78}]}
{"op":"mcm","clk":"12000424435","pt":1725075311008,"mc":[{"id":"1.232460189","rc":[{"batb":[[1,3.9,3.61],[2,1.51,164.75]],"batl":[[0,290,1.96]],"ltp":50.0,"tv":114.73,"id":73094924}]}]}
{"op":"mcm","clk":"12000424564","pt":1725075313323,"mc":[{"id":"1.232460189","rc":[{"batb":[[1,1.51,164.75],[2,1.46,2]],"ltp":50.0,"tv":114.73,"id":73094924}]}]}
{"op":"mcm","clk":"12000424839","pt":1725075318423,"mc":[{"id":"1.232460189","rc":[{"batb":[[1,4.8,3.61],[2,1.51,164.75]],"ltp":50.0,"tv":114.73,"id":73094924}]}]}
{"op":"mcm","clk":"12000424970","pt":1725075320834,"mc":[{"id":"1.232460189","rc":[{"batb":[[0,1.02,261.47],[1,1.01,672.63]],"batl":[[0,1.03,27.47],[1,1.04,1286.52],[2,1.1,51.93]],"ltp":1.02,"tv":13165.05,"id":2857968}]}]}
{"op":"mcm","clk":"12000425132","pt":1725075323711,"mc":[{"id":"1.232460189","rc":[{"batb":[[0,1.02,261.79]],"ltp":1.02,"tv":13165.05,"id":2857968}]}]}
{"op":"mcm","clk":"12000425370","pt":1725075328241,"mc":[{"id":"1.232460189","rc":[{"batb":[[0,1.02,387.3]],"ltp":1.02,"tv":13165.05,"id":2857968},{"batb":[[1,1.51,164.75],[2,1.46,2]],"batl":[[0,120,0.42]],"ltp":50.0,"tv":114.73,"id":73094924}]}]}
{"op":"mcm","clk":"12000425394","pt":1725075328706,"mc":[{"id":"1.232460189","rc":[{"trd":[[1.02,2595.32]],"batb":[[0,1.02,385.47]],"ltp":1.02,"tv":13168.7,"id":2857968}],"tv":13283.43}]}
{"op":"mcm","clk":"12000425455","pt":1725075330138,"mc":[{"id":"1.232460189","rc":[{"trd":[[1.03,196.64]],"batb":[[0,1.02,364.55]],"batl":[[0,1.03,24.25]],"ltp":1.03,"tv":13171.92,"id":2857968},{"trd":[[34,4.78]],"ltp":34.0,"tv":114.82,"id":73094924}],"tv":13286.75}]}
{"op":"mcm","clk":"12000425483","pt":1725075330905,"mc":[{"id":"1.232460189","rc":[{"trd":[[1.02,2595.4]],"batb":[[0,1.02,364.51]],"ltp":1.02,"tv":13172.0,"id":2857968}],"tv":13286.83}]}
{"op":"mcm","clk":"12000425668","pt":1725075334716,"mc":[{"id":"1.232460189","rc":[{"trd":[[1.02,2596.49]],"batb":[[0,1.02,363.96]],"ltp":1.02,"tv":13173.1,"id":2857968}],"tv":13287.93}]}
{"op":"mcm","clk":"12000425760","pt":1725075336005,"mc":[{"id":"1.232460189","rc":[{"trd":[[1.02,2601.76]],"batb":[[0,1.02,358.84]],"ltp":1.02,"tv":13178.37,"id":2857968},{"trd":[[55,9.02]],"ltp":55.0,"tv":114.92,"id":73094924}],"tv":13293.3}]}
{"op":"mcm","clk":"12000426020","pt":1725075340539,"mc":[{"id":"1.232460189","rc":[{"batb":[[1,3.9,3.61],[2,1.51,164.75]],"batl":[[0,290,1.96]],"ltp":55.0,"tv":114.92,"id":73094924}]}]}
{"op":"mcm","clk":"12000426127","pt":1725075342744,"mc":[{"id":"1.232460189","rc":[{"batb":[[1,1.51,164.75],[2,1.46,2]],"ltp":55.0,"tv":114.92,"id":73094924}]}]}
{"op":"mcm","clk":"12000426174","pt":1725075343615,"mc":[{"id":"1.232460189","rc":[{"trd":[[1.03,197.04]],"batl":[[0,1.03,24.05]],"ltp":1.03,"tv":13178.77,"id":2857968}],"tv":13293.7}]}
{"op":"mcm","clk":"12000426387","pt":1725075347831,"mc":[{"id":"1.232460189","rc":[{"batb":[[1,4.8,3.61],[2,1.51,164.75]],"ltp":55.0,"tv":114.92,"id":73094924}]}]}
{"op":"mcm","clk":"12000426486","pt":1725075350233,"mc":[{"id":"1.232460189","rc":[{"trd":[[1.03,197.34]],"batl":[[0,1.03,23.9]],"ltp":1.03,"tv":13179.07,"id":2857968}],"tv":13294.0}]}
{"op":"mcm","clk":"12000426551","pt":1725075352434,"mc":[{"id":"1.232460189","rc":[{"trd":[[1.03,197.54]],"batl":[[0,1.03,23.8]],"ltp":1.03,"tv":13179.27,"id":2857968}],"tv":13294.19}]}
{"op":"mcm","clk":"12000426626","pt":1725075353967,"mc":[{"id":"1.232460189","rc":[{"trd":[[1.03,200.76]],"batl":[[0,1.03,20.58]],"ltp":1.03,"tv":13182.49,"id":2857968},{"trd":[[34,4.88]],"ltp":34.0,"tv":115.02,"id":73094924}],"tv":13297.51}]}
{"op":"mcm","clk":"12000426654","pt":1725075354432,"mc":[{"id":"1.232460189","rc":[{"batb":[[0,1.02,356.33]],"ltp":1.03,"tv":13182.49,"id":2857968}]}]}
{"op":"mcm","clk":"12000426821","pt":1725075357256,"mc":[{"id":"1.232460189","rc":[{"trd":[[1.03,202.08]],"batl":[[0,1.03,19.92]],"ltp":1.03,"tv":13183.81,"id":2857968}],"tv":13298.83}]}
{"op":"mcm","clk":"12000426914","pt":1725075359458,"mc":[{"id":"1.232460189","rc":[{"trd":[[1.03,202.37]],"batl":[[0,1.03,19.77]],"ltp":1.03,"tv":13184.1,"id":2857968}],"tv":13299.13}]}
{"op":"mcm","clk":"12000427122","pt":1725075363365,"mc":[{"id":"1.232460189","rc":[{"trd":[[1.03,205.59]],"batl":[[0,1.03,16.55]],"ltp":1.03,"tv":13187.32,"id":2857968},{"trd":[[34,4.97]],"ltp":34.0,"tv":115.12,"id":73094924}],"tv":13302.45}]}
{"op":"mcm","clk":"12000427168","pt":1725075364344,"mc":[{"id":"1.232460189","rc":[{"batb":[[1,1.01,756.3]],"ltp":1.03,"tv":13187.32,"id":2857968}]}]}
{"op":"mcm","clk":"12000427332","pt":1725075367851,"mc":[{"id":"1.232460189","rc":[{"trd":[[1.03,207.61]],"batl":[[0,1.03,15.54]],"ltp":1.03,"tv":13189.35,"id":2857968}],"tv":13304.47}]}
{"op":"mcm","clk":"12000427648","pt":1725075374555,"mc":[{"id":"1.232460189","rc":[{"batb":[[0,32,8.38],[1,15,2.34],[2,4.8,3.61]],"ltp":34.0,"tv":115.12,"id":73094924}]}]}
{"op":"mcm","clk":"12000427745","pt":1725075376257,"mc":[{"id":"1.232460189","rc":[{"trd":[[1.03,207.91]],"batl":[[0,1.03,15.39]],"ltp":1.03,"tv":13189.64,"id":2857968}],"tv":13304.76}]}
{"op":"mcm","clk":"12000427990","pt":1725075380659,"mc":[{"id":"1.232460189","rc":[{"trd":[[1.02,2619.46]],"batb":[[0,1.02,347.48]],"ltp":1.02,"tv":13207.34,"id":2857968}],"tv":13322.46}]}
{"op":"mcm","clk":"12000428173","pt":1725075384660,"mc":[{"id":"1.232460189","rc":[{"trd":[[1.02,2619.79]],"batb":[[0,1.02,347.32]],"ltp":1.02,"tv":13207.67,"id":2857968}],"tv":13322.79}]}
{"op":"mcm","clk":"12000428238","pt":1725075385885,"mc":[{"id":"1.232460189","rc":[{"trd":[[1.03,208.21]],"batl":[[0,1.03,15.24]],"ltp":1.03,"tv":13207.96,"id":2857968},{"batb":[[0,15,2.34],[1,4.8,3.61],[2,1.51,164.75]],"ltp":34.0,"tv":115.12,"id":73094924}],"tv":13323.08}]}
{"op":"mcm","clk":"12000428296","pt":1725075386973,"mc":[{"id":"1.232460189","rc":[{"trd":[[1.03,211.43]],"batl":[[0,1.03,12.02]],"ltp":1.03,"tv":13211.18,"id":2857968},{"trd":[[34,5.07]],"ltp":34.0,"tv":115.21,"id":73094924}],"tv":13326.4}]}
{"op":"mcm","clk":"12000428318","pt":1725075387480,"mc":[{"id":"1.232460189","rc":[{"batb":[[1,1.51,164.75],[2,1.46,2]],"batl":[[0,120,0.42]],"ltp":34.0,"tv":115.21,"id":73094924}]}]}
{"op":"mcm","clk":"12000428454","pt":1725075390297,"mc":[{"id":"1.232460189","rc":[{"trd":[[1.03,211.72]],"batl":[[0,1.03,11.87]],"ltp":1.03,"tv":13211.48,"id":2857968}],"tv":13326.7}]}
{"op":"mcm","clk":"12000428803","pt":1725075397296,"mc":[{"id":"1.232460189","rc":[{"trd":[[1.03,214.94]],"batl":[[0,1.03,8.65]],"ltp":1.03,"tv":13214.7,"id":2857968},{"trd":[[34,5.17]],"ltp":34.0,"tv":115.31,"id":73094924}],"tv":13330.02}]}
{"op":"mcm","clk":"12000428901","pt":1725075399272,"mc":[{"id":"1.232460189","rc":[{"batl":[[0,1.03,92.42]],"ltp":1.03,"tv":13214.7,"id":2857968},{"batb":[[1,3.9,3.61],[2,1.51,164.75]],"batl":[[0,290,1.96]],"ltp":34.0,"tv":115.31,"id":73094924}]}]}
{"op":"mcm","clk":"12000428921","pt":1725075399585,"mc":[{"id":"1.232460189","rc":[{"trd":[[1.03,215.24]],"batl":[[0,1.03,92.27]],"ltp":1.03,"tv":13215.0,"id":2857968}],"tv":13330.31}]}
{"op":"mcm","clk":"12000428991","pt":1725075400772,"mc":[{"id":"1.232460189","rc":[{"trd":[[1.03,215.54]],"batl":[[0,1.03,50.23]],"ltp":1.03,"tv":13215.29,"id":2857968}],"tv":13330.61}]}
{"op":"mcm","clk":"12000429019","pt":1725075401492,"mc":[{"id":"1.232460189","rc":[{"batb":[[1,1.51,164.75],[2,1.46,2]],"ltp":34.0,"tv":115.31,"id":73094924}]}]}
{"op":"mcm","clk":"12000429142","pt":1725075403713,"mc":[{"id":"1.232460189","rc":[{"trd":[[1.03,215.73]],"batl":[[0,1.03,50.13]],"ltp":1.03,"tv":13215.49,"id":2857968}],"tv":13330.81}]}
