{"op":"mcm","clk":"11755676287","pt":1722594157058,"mc":[{"id":"1.231344876","marketDefinition":{"bspMarket":false,"turnInPlayEnabled":true,"persistenceEnabled":true,"marketBaseRate":5.0,"eventId":"33462684","eventTypeId":"4","numberOfWinners":1,"bettingType":"ODDS","marketType":"MATCH_ODDS","marketTime":"2024-08-04T10:00:00.000Z","suspendTime":"2024-08-04T10:00:00.000Z","bspReconciled":false,"complete":true,"inPlay":false,"crossMatching":false,"runnersVoidable":false,"numberOfActiveRunners":2,"betDelay":0,"status":"OPEN","runners":[{"status":"ACTIVE","sortPriority":1,"id":31379,"name":"Sussex"},{"status":"ACTIVE","sortPriority":2,"id":31377,"name":"Leicestershire"}],"regulators":["MR_INT"],"countryCode":"GB","discountAllowed":false,"timezone":"GMT","openDate":"2024-08-04T10:00:00.000Z","version":6051295537,"name":"Match Odds","eventName":"Sussex v Leicestershire"},"rc":[{"batb":[[0,1.03,200],[1,1.02,200],[2,1.01,220]],"ltp":0.0,"tv":0.0,"id":31379},{"batb":[[0,1.03,200],[1,1.02,200],[2,1.01,220]],"ltp":0.0,"tv":0.0,"id":31377}]}]}
{"op":"mcm","clk":"11755676422","pt":1722594158698,"mc":[{"id":"1.231344876","marketDefinition":{"bspMarket":false,"turnInPlayEnabled":true,"persistenceEnabled":true,"marketBaseRate":5.0,"eventId":"33462684","eventTypeId":"4","numberOfWinners":1,"bettingType":"ODDS","marketType":"MATCH_ODDS","marketTime":"2024-08-04T10:00:00.000Z","suspendTime":"2024-08-04T10:00:00.000Z","bspReconciled":false,"complete":true,"inPlay":false,"crossMatching":false,"runnersVoidable":false,"numberOfActiveRunners":2,"betDelay":0,"status":"OPEN","runners":[{"status":"ACTIVE","sortPriority":1,"id":31379,"name":"Sussex"},{"status":"ACTIVE","sortPriority":2,"id":31377,"name":"Leicestershire"}],"regulators":["MR_INT"],"countryCode":"GB","discountAllowed":true,"timezone":"GMT","openDate":"2024-08-04T10:00:00.000Z","version":6051295537,"name":"Match Odds","eventName":"Sussex v Leicestershire"}}]}
{"op":"mcm","clk":"11756207094","pt":1722599589733,"mc":[{"id":"1.231344876","rc":[{"batb":[[2,1.01,227.85]],"ltp":0.0,"tv":0.0,"id":31379},{"batb":[[2,1.01,227.85]],"ltp":0.0,"tv":0.0,"id":31377}]}]}
{"op":"mcm","clk":"11756208210","pt":1722599601512,"mc":[{"id":"1.231344876","rc":[{"batb":[[1,1.02,207.85]],"ltp":0.0,"tv":0.0,"id":31379},{"batb":[[1,1.02,207.85]],"ltp":0.0,"tv":0.0,"id":31377}]}]}
{"op":"mcm","clk":"11756209202","pt":1722599613145,"mc":[{"id":"1.231344876","rc":[{"batb":[[0,1.03,207.85]],"ltp":0.0,"tv":0.0,"id":31379},{"batb":[[0,1.03,207.85]],"ltp":0.0,"tv":0.0,"id":31377}]}]}
{"op":"mcm","clk":"11756210204","pt":1722599624537,"mc":[{"id":"1.231344876","rc":[{"batb":[[0,1.04,7.85],[1,1.03,207.85],[2,1.02,207.85]],"ltp":0.0,"tv":0.0,"id":31379},{"batb":[[0,1.04,7.85],[1,1.03,207.85],[2,1.02,207.85]],"ltp":0.0,"tv":0.0,"id":31377}]}]}
{"op":"mcm","clk":"11756211223","pt":1722599635868,"mc":[{"id":"1.231344876","rc":[{"batb":[[0,1.05,7.85],[1,1.04,7.85],[2,1.03,207.85]],"ltp":0.0,"tv":0.0,"id":31379},{"batb":[[0,1.05,7.85],[1,1.04,7.85],[2,1.03,207.85]],"ltp":0.0,"tv":0.0,"id":31377}]}]}
{"op":"mcm","clk":"11756212266","pt":1722599646804,"mc":[{"id":"1.231344876","rc":[{"batb":[[0,1.06,7.85],[1,1.05,7.85],[2,1.04,7.85]],"ltp":0.0,"tv":0.0,"id":31379},{"batb":[[0,1.06,7.85],[1,1.05,7.85],[2,1.04,7.85]],"ltp":0.0,"tv":0.0,"id":31377}]}]}
{"op":"mcm","clk":"11756213503","pt":1722599659308,"mc":[{"id":"1.231344876","rc":[{"batb":[[0,1.07,7.85],[1,1.06,7.85],[2,1.05,7.85]],"ltp":0.0,"tv":0.0,"id":31379},{"batb":[[0,1.07,7.85],[1,1.06,7.85],[2,1.05,7.85]],"ltp":0.0,"tv":0.0,"id":31377}]}]}
{"op":"mcm","clk":"11756214742","pt":1722599670929,"mc":[{"id":"1.231344876","rc":[{"batb":[[0,1.08,7.85],[1,1.07,7.85],[2,1.06,7.85]],"ltp":0.0,"tv":0.0,"id":31379},{"batb":[[0,1.08,7.85],[1,1.07,7.85],[2,1.06,7.85]],"ltp":0.0,"tv":0.0,"id":31377}]}]}
{"op":"mcm","clk":"11756699614","pt":1722604375207,"mc":[{"id":"1.231344876","rc":[{"batb":[[0,1.08,7.81],[1,1.07,7.81],[2,1.06,7.81]],"ltp":0.0,"tv":0.0,"id":31379},{"batb":[[0,1.08,7.81],[1,1.07,7.81],[2,1.06,7.81]],"ltp":0.0,"tv":0.0,"id":31377}]}]}
{"op":"mcm","clk":"11757260997","pt":1722609775163,"mc":[{"id":"1.231344876","rc":[{"batb":[[0,1.08,7.79],[1,1.07,7.79],[2,1.06,7.79]],"ltp":0.0,"tv":0.0,"id":31379},{"batb":[[0,1.08,7.79],[1,1.07,7.79],[2,1.06,7.79]],"ltp":0.0,"tv":0.0,"id":31377}]}]}
{"op":"mcm","clk":"11757934342","pt":1722615175108,"mc":[{"id":"1.231344876","rc":[{"batb":[[0,1.08,7.81],[1,1.07,7.81],[2,1.06,7.81]],"ltp":0.0,"tv":0.0,"id":31379},{"batb":[[0,1.08,7.81],[1,1.07,7.81],[2,1.06,7.81]],"ltp":0.0,"tv":0.0,"id":31377}]}]}
{"op":"mcm","clk":"11758327729","pt":1722617630549,"mc":[{"id":"1.231344876","rc":[{"batb":[[0,1.38,131.58],[1,1.33,151.52],[2,1.28,178.57]],"ltp":0.0,"tv":0.0,"id":31379},{"batb":[[0,1.38,131.58],[1,1.33,151.52],[2,1.28,178.57]],"ltp":0.0,"tv":0.0,"id":31377}]}]}
{"op":"mcm","clk":"11758329961","pt":1722617645911,"mc":[{"id":"1.231344876","marketDefinition":{"bspMarket":false,"turnInPlayEnabled":true,"persistenceEnabled":true,"marketBaseRate":5.0,"eventId":"33462684","eventTypeId":"4","numberOfWinners":1,"bettingType":"ODDS","marketType":"MATCH_ODDS","marketTime":"2024-08-04T10:00:00.000Z","suspendTime":"2024-08-04T10:00:00.000Z","bspReconciled":false,"complete":true,"inPlay":false,"crossMatching":true,"runnersVoidable":false,"numberOfActiveRunners":2,"betDelay":0,"status":"OPEN","runners":[{"status":"ACTIVE","sortPriority":1,"id":31379,"name":"Sussex"},{"status":"ACTIVE","sortPriority":2,"id":31377,"name":"Leicestershire"}],"regulators":["MR_INT"],"countryCode":"GB","discountAllowed":true,"timezone":"GMT","openDate":"2024-08-04T10:00:00.000Z","version":6051295537,"name":"Match Odds","eventName":"Sussex v Leicestershire"}}]}
{"op":"mcm","clk":"11758373299","pt":1722617966277,"mc":[{"id":"1.231344876","rc":[{"batb":[[0,1.33,151.52],[1,1.28,178.57],[2,1.23,217.39]],"ltp":0.0,"tv":0.0,"id":31377}]}]}
{"op":"mcm","clk":"11758917828","pt":1722620602032,"mc":[{"id":"1.231344876","rc":[{"batb":[[0,1.39,6.9],[1,1.38,131.58],[2,1.33,151.52]],"ltp":0.0,"tv":0.0,"id":31379},{"batb":[[0,1.34,6.37],[1,1.33,151.52],[2,1.28,178.57]],"ltp":0.0,"tv":0.0,"id":31377}]}]}
{"op":"mcm","clk":"11759968226","pt":1722625975152,"mc":[{"id":"1.231344876","rc":[{"batb":[[0,1.39,6.89]],"ltp":0.0,"tv":0.0,"id":31379},{"batb":[[0,1.34,6.36]],"ltp":0.0,"tv":0.0,"id":31377}]}]}
{"op":"mcm","clk":"11760019894","pt":1722626259061,"mc":[{"id":"1.231344876","rc":[{"batb":[[0,1.4,21.41],[1,1.39,6.89],[2,1.38,131.58]],"ltp":0.0,"tv":0.0,"id":31379},{"batb":[[0,1.35,24.47],[1,1.34,6.36],[2,1.33,151.52]],"ltp":0.0,"tv":0.0,"id":31377}]}]}
{"op":"mcm","clk":"11760278488","pt":1722628060582,"mc":[{"id":"1.231344876","rc":[{"batb":[[0,1.39,6.89],[1,1.38,131.58],[2,1.33,151.52]],"ltp":0.0,"tv":0.0,"id":31379},{"batb":[[0,1.34,6.36],[1,1.33,151.52],[2,1.28,178.57]],"ltp":0.0,"tv":0.0,"id":31377}]}]}
{"op":"mcm","clk":"11760281612","pt":1722628084209,"mc":[{"id":"1.231344876","rc":[{"batb":[[0,1.4,21.41],[1,1.39,6.89],[2,1.38,131.58]],"ltp":0.0,"tv":0.0,"id":31379},{"batb":[[0,1.35,24.47],[1,1.34,6.36],[2,1.33,151.52]],"ltp":0.0,"tv":0.0,"id":31377}]}]}
{"op":"mcm","clk":"11760488648","pt":1722629886642,"mc":[{"id":"1.231344876","rc":[{"batb":[[0,1.4,21.41],[1,1.39,6.89]],"ltp":0.0,"tv":0.0,"id":31379},{"batb":[[0,1.34,6.36],[1,1.33,151.52],[2,1.28,178.57]],"ltp":0.0,"tv":0.0,"id":31377}]}]}
{"op":"mcm","clk":"11760488660","pt":1722629886746,"mc":[{"id":"1.231344876","rc":[{"batb":[[0,1.39,6.89],[1,1.38,131.58],[2,1.33,151.52]],"ltp":0.0,"tv":0.0,"id":31379}]}]}
{"op":"mcm","clk":"11760505597","pt":1722630054053,"mc":[{"id":"1.231344876","rc":[{"batb":[[0,1.4,21.41],[1,1.39,6.89],[2,1.38,131.58]],"ltp":0.0,"tv":0.0,"id":31379},{"batb":[[0,1.35,24.47],[1,1.34,6.36],[2,1.33,151.52]],"ltp":0.0,"tv":0.0,"id":31377}]}]}
{"op":"mcm","clk":"11760638300","pt":1722631855628,"mc":[{"id":"1.231344876","rc":[{"batb":[[0,1.39,6.89],[1,1.38,131.58],[2,1.33,151.52]],"ltp":0.0,"tv":0.0,"id":31379}]}]}
{"op":"mcm","clk":"11760638308","pt":1722631855833,"mc":[{"id":"1.231344876","rc":[{"batb":[[0,1.34,6.36],[1,1.33,151.52],[2,1.28,178.57]],"ltp":0.0,"tv":0.0,"id":31377}]}]}
{"op":"mcm","clk":"11760642006","pt":1722631975262,"mc":[{"id":"1.231344876","rc":[{"batb":[[0,1.4,21.41],[1,1.39,6.89],[2,1.38,131.58]],"ltp":0.0,"tv":0.0,"id":31379},{"batb":[[0,1.35,24.47],[1,1.34,6.36],[2,1.33,151.52]],"ltp":0.0,"tv":0.0,"id":31377}]}]}
{"op":"mcm","clk":"11760710514","pt":1722633779503,"mc":[{"id":"1.231344876","rc":[{"batb":[[0,1.39,6.9],[1,1.38,131.58],[2,1.33,151.52]],"ltp":0.0,"tv":0.0,"id":31379},{"batb":[[0,1.34,6.36],[1,1.33,151.52],[2,1.28,178.57]],"ltp":0.0,"tv":0.0,"id":31377}]}]}
{"op":"mcm","clk":"11760713087","pt":1722633853870,"mc":[{"id":"1.231344876","rc":[{"batb":[[0,1.4,21.41],[1,1.39,6.9],[2,1.38,131.58]],"ltp":0.0,"tv":0.0,"id":31379},{"batb":[[0,1.35,24.47],[1,1.34,6.36],[2,1.33,151.52]],"ltp":0.0,"tv":0.0,"id":31377}]}]}
{"op":"mcm","clk":"11760766919","pt":1722635654381,"mc":[{"id":"1.231344876","rc":[{"batb":[[0,1.39,6.9],[1,1.38,131.58],[2,1.33,151.52]],"ltp":0.0,"tv":0.0,"id":31379},{"batb":[[0,1.34,6.36],[1,1.33,151.52],[2,1.28,178.57]],"ltp":0.0,"tv":0.0,"id":31377}]}]}
{"op":"mcm","clk":"11760768791","pt":1722635718695,"mc":[{"id":"1.231344876","rc":[{"batb":[[0,1.4,21.41],[1,1.39,6.9],[2,1.38,131.58]],"ltp":0.0,"tv":0.0,"id":31379},{"batb":[[0,1.35,24.47],[1,1.34,6.36],[2,1.33,151.52]],"ltp":0.0,"tv":0.0,"id":31377}]}]}
{"op":"mcm","clk":"11760774130","pt":1722635909360,"mc":[{"id":"1.231344876","rc":[{"batb":[[0,1.42,85.22],[1,1.4,21.41],[2,1.39,6.9]],"ltp":0.0,"tv":0.0,"id":31379}]}]}
{"op":"mcm","clk":"11760774162","pt":1722635910536,"mc":[{"id":"1.231344876","rc":[{"batb":[[0,1.38,85.22],[1,1.35,24.47],[2,1.34,6.36]],"ltp":0.0,"tv":0.0,"id":31377}]}]}
{"op":"mcm","clk":"11760808365","pt":1722636775095,"mc":[{"id":"1.231344876","rc":[{"batb":[[0,1.42,85.28],[1,1.4,21.41]],"ltp":0.0,"tv":0.0,"id":31379},{"batb":[[0,1.38,85.28],[1,1.35,24.47]],"ltp":0.0,"tv":0.0,"id":31377}]}]}
{"op":"mcm","clk":"11760834732","pt":1722637521009,"mc":[{"id":"1.231344876","rc":[{"batb":[[1,1.39,6.89],[2,1.38,131.58]],"ltp":0.0,"tv":0.0,"id":31379},{"batb":[[1,1.34,6.36],[2,1.33,151.52]],"ltp":0.0,"tv":0.0,"id":31377}]}]}
{"op":"mcm","clk":"11760836558","pt":1722637577969,"mc":[{"id":"1.231344876","rc":[{"batb":[[0,1.43,19.92],[1,1.42,85.28],[2,1.39,6.89]],"ltp":0.0,"tv":0.0,"id":31379},{"batb":[[0,1.39,21.96],[1,1.38,85.28],[2,1.34,6.36]],"ltp":0.0,"tv":0.0,"id":31377}]}]}
{"op":"mcm","clk":"11760855508","pt":1722638171690,"mc":[{"id":"1.231344876","rc":[{"batb":[[0,1.43,26.82],[2,1.38,131.58]],"ltp":0.0,"tv":0.0,"id":31379},{"batb":[[0,1.39,28.33],[2,1.33,151.52]],"ltp":0.0,"tv":0.0,"id":31377}]}]}
{"op":"mcm","clk":"11760888933","pt":1722639378574,"mc":[{"id":"1.231344876","rc":[{"batb":[[0,1.43,6.89]],"ltp":0.0,"tv":0.0,"id":31379},{"batb":[[0,1.39,6.36]],"ltp":0.0,"tv":0.0,"id":31377}]}]}
{"op":"mcm","clk":"11760890310","pt":1722639430534,"mc":[{"id":"1.231344876","rc":[{"batb":[[0,1.44,19.47],[1,1.43,6.89],[2,1.42,85.28]],"ltp":0.0,"tv":0.0,"id":31379},{"batb":[[0,1.4,21.41],[1,1.39,6.36],[2,1.38,85.28]],"ltp":0.0,"tv":0.0,"id":31377}]}]}
{"op":"mcm","clk":"11760943213","pt":1722641231119,"mc":[{"id":"1.231344876","rc":[{"batb":[[0,1.43,6.9],[1,1.42,85.28],[2,1.38,131.58]],"ltp":0.0,"tv":0.0,"id":31379},{"batb":[[0,1.39,6.36],[1,1.38,85.28],[2,1.33,151.52]],"ltp":0.0,"tv":0.0,"id":31377}]}]}
{"op":"mcm","clk":"11760944774","pt":1722641278479,"mc":[{"id":"1.231344876","rc":[{"batb":[[0,1.44,19.47],[1,1.43,6.9],[2,1.42,85.28]],"ltp":0.0,"tv":0.0,"id":31379},{"batb":[[0,1.4,21.41],[1,1.39,6.36],[2,1.38,85.28]],"ltp":0.0,"tv":0.0,"id":31377}]}]}
{"op":"mcm","clk":"11761010013","pt":1722643079652,"mc":[{"id":"1.231344876","rc":[{"batb":[[0,1.43,6.9],[1,1.42,85.28],[2,1.38,131.58]],"ltp":0.0,"tv":0.0,"id":31379},{"batb":[[0,1.39,6.36],[1,1.38,85.28],[2,1.33,151.52]],"ltp":0.0,"tv":0.0,"id":31377}]}]}
{"op":"mcm","clk":"11761010332","pt":1722643095874,"mc":[{"id":"1.231344876","rc":[{"batb":[[0,1.43,11.42]],"ltp":0.0,"tv":0.0,"id":31379}]}]}
{"op":"mcm","clk":"11761010354","pt":1722643096847,"mc":[{"id":"1.231344876","rc":[{"batb":[[0,1.43,6.9]],"ltp":0.0,"tv":0.0,"id":31379}]}]}
{"op":"mcm","clk":"11761010693","pt":1722643117372,"mc":[{"id":"1.231344876","rc":[{"batb":[[0,1.44,19.47],[1,1.43,6.9],[2,1.42,85.28]],"ltp":0.0,"tv":0.0,"id":31379},{"batb":[[0,1.4,21.41],[1,1.39,6.36],[2,1.38,85.28]],"ltp":0.0,"tv":0.0,"id":31377}]}]}
{"op":"mcm","clk":"11761035249","pt":1722643843869,"mc":[{"id":"1.231344876","rc":[{"batb":[[0,1.44,287],[1,1.4,21.41],[2,1.39,6.36]],"ltp":0.0,"tv":0.0,"id":31377}]}]}
{"op":"mcm","clk":"11761050458","pt":1722644249382,"mc":[{"id":"1.231344876","rc":[{"batb":[[0,1.45,6.36],[1,1.44,287],[2,1.4,21.41]],"ltp":0.0,"tv":0.0,"id":31377}]}]}
{"op":"mcm","clk":"11761077506","pt":1722644918564,"mc":[{"id":"1.231344876","rc":[{"batb":[[0,1.43,6.9],[1,1.42,85.28],[2,1.38,131.58]],"ltp":0.0,"tv":0.0,"id":31379},{"batb":[[2,1.38,85.28]],"ltp":0.0,"tv":0.0,"id":31377}]}]}
{"op":"mcm","clk":"11761078417","pt":1722644943190,"mc":[{"id":"1.231344876","rc":[{"batb":[[0,1.44,19.47],[1,1.43,6.9],[2,1.42,85.28]],"ltp":0.0,"tv":0.0,"id":31379},{"batb":[[0,1.46,18.62],[1,1.45,6.36],[2,1.44,287]],"ltp":0.0,"tv":0.0,"id":31377}]}]}
{"op":"mcm","clk":"11761090293","pt":1722645261070,"mc":[{"id":"1.231344876","rc":[{"batl":[[0,3.25,6.15]],"ltp":0.0,"tv":0.0,"id":31379}]}]}
{"op":"mcm","clk":"11761141600","pt":1722646744623,"mc":[{"id":"1.231344876","rc":[{"batb":[[0,1.43,6.9],[1,1.42,85.28],[2,1.38,131.58]],"ltp":0.0,"tv":0.0,"id":31379},{"batb":[[0,1.45,6.36],[1,1.44,287],[2,1.38,85.28]],"ltp":0.0,"tv":0.0,"id":31377}]}]}
{"op":"mcm","clk":"11761141630","pt":1722646745645,"mc":[{"id":"1.231344876","rc":[{"batb":[[0,1.43,11.42]],"ltp":0.0,"tv":0.0,"id":31379},{"batb":[[0,1.45,21.45]],"ltp":0.0,"tv":0.0,"id":31377}]}]}
{"op":"mcm","clk":"11761141758","pt":1722646750031,"mc":[{"id":"1.231344876","rc":[{"batb":[[0,1.43,6.9]],"ltp":0.0,"tv":0.0,"id":31379}]}]}
{"op":"mcm","clk":"11761141998","pt":1722646756843,"mc":[{"id":"1.231344876","rc":[{"batb":[[0,1.44,19.47],[1,1.43,6.9],[2,1.42,85.28]],"ltp":0.0,"tv":0.0,"id":31379},{"batb":[[0,1.46,18.62],[1,1.45,21.45],[2,1.44,287]],"ltp":0.0,"tv":0.0,"id":31377}]}]}
{"op":"mcm","clk":"11761142061","pt":1722646758853,"mc":[{"id":"1.231344876","rc":[{"batb":[[1,1.45,6.36]],"ltp":0.0,"tv":0.0,"id":31377}]}]}
{"op":"mcm","clk":"11761227933","pt":1722648558414,"mc":[{"id":"1.231344876","rc":[{"batb":[[0,1.43,6.9],[1,1.42,85.28],[2,1.38,131.58]],"ltp":0.0,"tv":0.0,"id":31379},{"batb":[[0,1.45,6.36],[1,1.44,287],[2,1.38,85.28]],"ltp":0.0,"tv":0.0,"id":31377}]}]}
{"op":"mcm","clk":"11761228385","pt":1722648567639,"mc":[{"id":"1.231344876","rc":[{"batb":[[0,1.44,19.47],[1,1.43,6.9],[2,1.42,85.28]],"ltp":0.0,"tv":0.0,"id":31379},{"batb":[[0,1.46,18.62],[1,1.45,6.36],[2,1.44,287]],"ltp":0.0,"tv":0.0,"id":31377}]}]}
{"op":"mcm","clk":"11761310192","pt":1722650368633,"mc":[{"id":"1.231344876","rc":[{"batb":[[0,1.45,6.36],[1,1.44,287],[2,1.38,85.28]],"ltp":0.0,"tv":0.0,"id":31377}]}]}
{"op":"mcm","clk":"11761310206","pt":1722650368945,"mc":[{"id":"1.231344876","rc":[{"batb":[[0,1.43,6.9],[1,1.42,85.28],[2,1.38,131.58]],"ltp":0.0,"tv":0.0,"id":31379},{"batb":[[0,1.45,21.45]],"ltp":0.0,"tv":0.0,"id":31377}]}]}
{"op":"mcm","clk":"11761310341","pt":1722650372025,"mc":[{"id":"1.231344876","rc":[{"batb":[[0,1.43,11.42]],"ltp":0.0,"tv":0.0,"id":31379}]}]}
{"op":"mcm","clk":"11761310388","pt":1722650373514,"mc":[{"id":"1.231344876","rc":[{"batb":[[0,1.44,19.47],[1,1.43,11.42],[2,1.42,85.28]],"ltp":0.0,"tv":0.0,"id":31379},{"batb":[[0,1.46,18.62],[1,1.45,21.45],[2,1.44,287]],"ltp":0.0,"tv":0.0,"id":31377}]}]}
{"op":"mcm","clk":"11761310473","pt":1722650375414,"mc":[{"id":"1.231344876","rc":[{"batb":[[1,1.43,6.9]],"ltp":0.0,"tv":0.0,"id":31379},{"batb":[[1,1.45,6.36]],"ltp":0.0,"tv":0.0,"id":31377}]}]}
{"op":"mcm","clk":"11761385404","pt":1722652174606,"mc":[{"id":"1.231344876","rc":[{"batb":[[0,1.43,6.9],[1,1.42,85.28],[2,1.38,131.58]],"ltp":0.0,"tv":0.0,"id":31379},{"batb":[[0,1.45,6.36],[1,1.44,287],[2,1.38,85.28]],"ltp":0.0,"tv":0.0,"id":31377}]}]}
{"op":"mcm","clk":"11761386901","pt":1722652209059,"mc":[{"id":"1.231344876","rc":[{"batb":[[0,1.43,11.42]],"ltp":0.0,"tv":0.0,"id":31379},{"batb":[[0,1.45,21.45]],"ltp":0.0,"tv":0.0,"id":31377}]}]}
{"op":"mcm","clk":"11761387069","pt":1722652212572,"mc":[{"id":"1.231344876","rc":[{"batb":[[0,1.43,6.9]],"ltp":0.0,"tv":0.0,"id":31379}]}]}
{"op":"mcm","clk":"11761392348","pt":1722652327403,"mc":[{"id":"1.231344876","rc":[{"batb":[[0,1.44,19.47],[1,1.43,6.9],[2,1.42,85.28]],"ltp":0.0,"tv":0.0,"id":31379},{"batb":[[0,1.46,18.62],[1,1.45,21.45],[2,1.44,287]],"ltp":0.0,"tv":0.0,"id":31377}]}]}
{"op":"mcm","clk":"11761392388","pt":1722652328797,"mc":[{"id":"1.231344876","rc":[{"batb":[[1,1.45,6.36]],"ltp":0.0,"tv":0.0,"id":31377}]}]}
{"op":"mcm","clk":"11761483379","pt":1722654128631,"mc":[{"id":"1.231344876","rc":[{"batb":[[0,1.45,6.36],[1,1.44,287],[2,1.38,85.28]],"ltp":0.0,"tv":0.0,"id":31377}]}]}
{"op":"mcm","clk":"11761483386","pt":1722654128841,"mc":[{"id":"1.231344876","rc":[{"batb":[[0,1.43,6.9],[1,1.42,85.28],[2,1.38,131.58]],"ltp":0.0,"tv":0.0,"id":31379}]}]}
{"op":"mcm","clk":"11761483582","pt":1722654133264,"mc":[{"id":"1.231344876","rc":[{"batb":[[0,1.43,11.42]],"ltp":0.0,"tv":0.0,"id":31379},{"batb":[[0,1.45,21.45]],"ltp":0.0,"tv":0.0,"id":31377}]}]}
{"op":"mcm","clk":"11761483870","pt":1722654139475,"mc":[{"id":"1.231344876","rc":[{"batb":[[0,1.43,6.9]],"ltp":0.0,"tv":0.0,"id":31379}]}]}
{"op":"mcm","clk":"11761490050","pt":1722654272645,"mc":[{"id":"1.231344876","rc":[{"batb":[[0,1.44,19.47],[1,1.43,6.9],[2,1.42,85.28]],"ltp":0.0,"tv":0.0,"id":31379},{"batb":[[0,1.46,18.62],[1,1.45,21.45],[2,1.44,287]],"ltp":0.0,"tv":0.0,"id":31377}]}]}
{"op":"mcm","clk":"11761490145","pt":1722654274655,"mc":[{"id":"1.231344876","rc":[{"batb":[[1,1.45,6.36]],"ltp":0.0,"tv":0.0,"id":31377}]}]}
{"op":"mcm","clk":"11761570103","pt":1722656074588,"mc":[{"id":"1.231344876","rc":[{"batb":[[0,1.43,6.9],[1,1.42,85.28],[2,1.38,131.58]],"ltp":0.0,"tv":0.0,"id":31379},{"batb":[[0,1.45,6.36],[1,1.44,287],[2,1.38,85.28]],"ltp":0.0,"tv":0.0,"id":31377}]}]}
{"op":"mcm","clk":"11761571568","pt":1722656108611,"mc":[{"id":"1.231344876","rc":[{"batb":[[0,1.43,11.42]],"ltp":0.0,"tv":0.0,"id":31379},{"batb":[[0,1.45,21.45]],"ltp":0.0,"tv":0.0,"id":31377}]}]}
{"op":"mcm","clk":"11761571748","pt":1722656112524,"mc":[{"id":"1.231344876","rc":[{"batb":[[0,1.43,6.9]],"ltp":0.0,"tv":0.0,"id":31379}]}]}
{"op":"mcm","clk":"11761575166","pt":1722656199497,"mc":[{"id":"1.231344876","rc":[{"batb":[[0,1.44,19.47],[1,1.43,6.9],[2,1.42,85.28]],"ltp":0.0,"tv":0.0,"id":31379},{"batb":[[0,1.46,18.62],[1,1.45,21.45],[2,1.44,287]],"ltp":0.0,"tv":0.0,"id":31377}]}]}
{"op":"mcm","clk":"11761575325","pt":1722656202791,"mc":[{"id":"1.231344876","rc":[{"batb":[[1,1.45,6.36]],"ltp":0.0,"tv":0.0,"id":31377}]}]}
{"op":"mcm","clk":"11761652846","pt":1722658000271,"mc":[{"id":"1.231344876","rc":[{"batb":[[0,1.43,6.9],[1,1.42,85.28],[2,1.38,131.58]],"ltp":0.0,"tv":0.0,"id":31379},{"batb":[[0,1.45,6.36],[1,1.44,287],[2,1.38,85.28]],"ltp":0.0,"tv":0.0,"id":31377}]}]}
{"op":"mcm","clk":"11761653980","pt":1722658029839,"mc":[{"id":"1.231344876","rc":[{"batb":[[0,1.43,11.42]],"ltp":0.0,"tv":0.0,"id":31379},{"batb":[[0,1.45,21.45]],"ltp":0.0,"tv":0.0,"id":31377}]}]}
{"op":"mcm","clk":"11761654085","pt":1722658033153,"mc":[{"id":"1.231344876","rc":[{"batb":[[0,1.43,6.9]],"ltp":0.0,"tv":0.0,"id":31379}]}]}
{"op":"mcm","clk":"11761657743","pt":1722658123794,"mc":[{"id":"1.231344876","rc":[{"batb":[[0,1.44,19.47],[1,1.43,6.9],[2,1.42,85.28]],"ltp":0.0,"tv":0.0,"id":31379},{"batb":[[0,1.46,18.62],[1,1.45,21.45],[2,1.44,287]],"ltp":0.0,"tv":0.0,"id":31377}]}]}
{"op":"mcm","clk":"11761657779","pt":1722658124775,"mc":[{"id":"1.231344876","rc":[{"batb":[[1,1.45,6.36]],"ltp":0.0,"tv":0.0,"id":31377}]}]}
{"op":"mcm","clk":"11761737088","pt":1722659925341,"mc":[{"id":"1.231344876","rc":[{"batb":[[0,1.43,6.9],[1,1.42,85.28],[2,1.38,131.58]],"ltp":0.0,"tv":0.0,"id":31379},{"batb":[[0,1.45,6.36],[1,1.44,287],[2,1.38,85.28]],"ltp":0.0,"tv":0.0,"id":31377}]}]}
{"op":"mcm","clk":"11761737851","pt":1722659950982,"mc":[{"id":"1.231344876","rc":[{"batb":[[0,1.43,11.42]],"ltp":0.0,"tv":0.0,"id":31379},{"batb":[[0,1.45,21.45]],"ltp":0.0,"tv":0.0,"id":31377}]}]}
{"op":"mcm","clk":"11761737929","pt":1722659954364,"mc":[{"id":"1.231344876","rc":[{"batb":[[0,1.43,6.9]],"ltp":0.0,"tv":0.0,"id":31379}]}]}
{"op":"mcm","clk":"11761740171","pt":1722660034863,"mc":[{"id":"1.231344876","rc":[{"batb":[[0,1.44,19.47],[1,1.43,6.9],[2,1.42,85.28]],"ltp":0.0,"tv":0.0,"id":31379},{"batb":[[0,1.46,18.62],[1,1.45,21.45],[2,1.44,287]],"ltp":0.0,"tv":0.0,"id":31377}]}]}
{"op":"mcm","clk":"11761740198","pt":1722660036491,"mc":[{"id":"1.231344876","rc":[{"batb":[[1,1.45,6.36]],"ltp":0.0,"tv":0.0,"id":31377}]}]}
{"op":"mcm","clk":"11761805321","pt":1722661836545,"mc":[{"id":"1.231344876","rc":[{"batb":[[0,1.43,6.9],[1,1.42,85.28],[2,1.38,131.58]],"ltp":0.0,"tv":0.0,"id":31379},{"batb":[[0,1.45,6.36],[1,1.44,287],[2,1.38,85.28]],"ltp":0.0,"tv":0.0,"id":31377}]}]}
{"op":"mcm","clk":"11761806765","pt":1722661869896,"mc":[{"id":"1.231344876","rc":[{"batb":[[0,1.43,11.42]],"ltp":0.0,"tv":0.0,"id":31379},{"batb":[[0,1.45,21.45]],"ltp":0.0,"tv":0.0,"id":31377}]}]}
{"op":"mcm","clk":"11761806925","pt":1722661873996,"mc":[{"id":"1.231344876","rc":[{"batb":[[0,1.43,6.9]],"ltp":0.0,"tv":0.0,"id":31379}]}]}
{"op":"mcm","clk":"11761808977","pt":1722661935817,"mc":[{"id":"1.231344876","rc":[{"batb":[[0,1.44,19.47],[1,1.43,6.9],[2,1.42,85.28]],"ltp":0.0,"tv":0.0,"id":31379},{"batb":[[0,1.46,18.62],[1,1.45,21.45],[2,1.44,287]],"ltp":0.0,"tv":0.0,"id":31377}]}]}
{"op":"mcm","clk":"11761809081","pt":1722661938683,"mc":[{"id":"1.231344876","rc":[{"batb":[[1,1.45,6.36]],"ltp":0.0,"tv":0.0,"id":31377}]}]}
{"op":"mcm","clk":"11761839723","pt":1722662901694,"mc":[{"id":"1.231344876","rc":[{"batb":[[0,1.5,3],[1,1.44,19.47],[2,1.43,6.9]],"ltp":0.0,"tv":0.0,"id":31379},{"batb":[[0,1.52,6],[1,1.46,18.62],[2,1.45,6.36]],"ltp":0.0,"tv":0.0,"id":31377}]}]}
{"op":"mcm","clk":"11761868804","pt":1722663736343,"mc":[{"id":"1.231344876","rc":[{"batb":[[1,1.43,6.9],[2,1.42,85.28]],"ltp":0.0,"tv":0.0,"id":31379},{"batb":[[1,1.45,6.36],[2,1.44,287]],"ltp":0.0,"tv":0.0,"id":31377}]}]}
{"op":"mcm","clk":"11761883177","pt":1722663798777,"mc":[{"id":"1.231344876","rc":[{"batl":[[0,3.25,6.44]],"ltp":0.0,"tv":0.0,"id":31379},{"batb":[[1,1.45,20.45]],"ltp":0.0,"tv":0.0,"id":31377}]}]}
{"op":"mcm","clk":"11761884819","pt":1722663836317,"mc":[{"id":"1.231344876","rc":[{"batb":[[0,1.51,16.8],[1,1.5,3],[2,1.43,6.9]],"ltp":0.0,"tv":0.0,"id":31379},{"batb":[[0,1.53,16.16],[1,1.52,6],[2,1.45,20.45]],"ltp":0.0,"tv":0.0,"id":31377}]}]}
{"op":"mcm","clk":"11761884874","pt":1722663837606,"mc":[{"id":"1.231344876","rc":[{"batb":[[2,1.45,6.36]],"ltp":0.0,"tv":0.0,"id":31377}]}]}
{"op":"mcm","clk":"11761916940","pt":1722664601591,"mc":[{"id":"1.231344876","rc":[{"batb":[[0,1.52,3],[1,1.51,16.8]],"ltp":0.0,"tv":0.0,"id":31379},{"batb":[[0,1.55,6],[1,1.53,16.16]],"ltp":0.0,"tv":0.0,"id":31377}]}]}
{"op":"mcm","clk":"11761954727","pt":1722665638189,"mc":[{"id":"1.231344876","rc":[{"batb":[[1,1.43,6.9],[2,1.42,85.28]],"ltp":0.0,"tv":0.0,"id":31379},{"batb":[[1,1.45,6.36],[2,1.44,287]],"ltp":0.0,"tv":0.0,"id":31377}]}]}
{"op":"mcm","clk":"11761959071","pt":1722665738744,"mc":[{"id":"1.231344876","rc":[{"batb":[[0,1.53,16.16],[1,1.52,3],[2,1.43,6.9]],"ltp":0.0,"tv":0.0,"id":31379},{"batb":[[0,1.56,15.3],[1,1.55,6],[2,1.45,6.36]],"ltp":0.0,"tv":0.0,"id":31377}]}]}
{"op":"mcm","clk":"11761965331","pt":1722665881099,"mc":[{"id":"1.231344876","rc":[{"batb":[[0,1.54,3],[1,1.53,16.16]],"ltp":0.0,"tv":0.0,"id":31379},{"batb":[[0,1.57,6],[1,1.56,15.3]],"ltp":0.0,"tv":0.0,"id":31377}]}]}
{"op":"mcm","clk":"11761969350","pt":1722665960474,"mc":[{"id":"1.231344876","rc":[{"batb":[[0,1.68,3]],"ltp":0.0,"tv":0.0,"id":31379}]}]}
{"op":"mcm","clk":"11762030630","pt":1722667540293,"mc":[{"id":"1.231344876","rc":[{"batb":[[1,1.43,6.9],[2,1.42,85.28]],"ltp":0.0,"tv":0.0,"id":31379},{"batb":[[1,1.45,6.36],[2,1.44,287]],"ltp":0.0,"tv":0.0,"id":31377}]}]}
{"op":"mcm","clk":"11762030975","pt":1722667550688,"mc":[{"id":"1.231344876","rc":[{"batl":[[0,3.25,6.46]],"ltp":0.0,"tv":0.0,"id":31379},{"batb":[[1,1.45,20.45]],"ltp":0.0,"tv":0.0,"id":31377}]}]}
{"op":"mcm","clk":"11762739077","pt":1722677085785,"mc":[{"id":"1.231344876","rc":[{"batb":[[2,1.38,85.28]],"ltp":0.0,"tv":0.0,"id":31377}]}]}
{"op":"mcm","clk":"11762739352","pt":1722677088279,"mc":[{"id":"1.231344876","rc":[{"batb":[[1,1.45,6.36]],"ltp":0.0,"tv":0.0,"id":31377}]}]}
{"op":"mcm","clk":"11762794519","pt":1722677553968,"mc":[{"id":"1.231344876","rc":[{"batb":[[1,1.39,6.36]],"ltp":0.0,"tv":0.0,"id":31377}]}]}
{"op":"mcm","clk":"11763623775","pt":1722683668280,"mc":[{"id":"1.231344876","rc":[{"batl":[[0,1.75,100]],"ltp":0.0,"tv":0.0,"id":31377}]}]}
{"op":"mcm","clk":"11763729430","pt":1722684315310,"mc":[{"id":"1.231344876","rc":[{"batb":[[1,1.42,85.28],[2,1.3,833.33]],"ltp":0.0,"tv":0.0,"id":31379}]}]}
{"op":"mcm","clk":"11763859561","pt":1722685055227,"mc":[{"id":"1.231344876","rc":[{"batl":[[0,1.74,4.91],[1,1.75,100]],"ltp":0.0,"tv":0.0,"id":31377}]}]}
{"op":"mcm","clk":"11763993671","pt":1722685794664,"mc":[{"id":"1.231344876","rc":[{"batl":[[0,1.73,100],[1,1.74,4.91]],"ltp":0.0,"tv":0.0,"id":31377}]}]}
{"op":"mcm","clk":"11763993896","pt":1722685796257,"mc":[{"id":"1.231344876","rc":[{"batl":[[1,1.74,0]],"ltp":0.0,"tv":0.0,"id":31377}]}]}
{"op":"mcm","clk":"11764219555","pt":1722687200461,"mc":[{"id":"1.231344876","rc":[{"batl":[[0,1.72,4.91],[1,1.73,100]],"ltp":0.0,"tv":0.0,"id":31377}]}]}
{"op":"mcm","clk":"11765097888","pt":1722691969025,"mc":[{"id":"1.231344876","rc":[{"batl":[[1,1.73,0]],"ltp":0.0,"tv":0.0,"id":31377}]}]}
{"op":"mcm","clk":"11765098348","pt":1722691971492,"mc":[{"id":"1.231344876","rc":[{"batb":[[1,1.43,4.51],[2,1.42,85.28]],"ltp":0.0,"tv":0.0,"id":31379}]}]}
{"op":"mcm","clk":"11765281126","pt":1722692921824,"mc":[{"id":"1.231344876","rc":[{"batb":[[1,1.43,11.73]],"ltp":0.0,"tv":0.0,"id":31379}]}]}
{"op":"mcm","clk":"11765281606","pt":1722692924247,"mc":[{"id":"1.231344876","rc":[{"batb":[[1,1.43,7.22]],"ltp":0.0,"tv":0.0,"id":31379}]}]}
{"op":"mcm","clk":"11765525928","pt":1722694215753,"mc":[{"id":"1.231344876","rc":[{"batb":[[0,2.32,33.7],[1,1.68,3],[2,1.43,7.22]],"ltp":0.0,"tv":0.0,"id":31379},{"batb":[[0,1.69,64.47],[1,1.57,6],[2,1.39,6.36]],"ltp":0.0,"tv":0.0,"id":31377}]}]}
{"op":"mcm","clk":"11765680401","pt":1722694908283,"mc":[{"id":"1.231344876","rc":[{"batb":[[0,2.32,30.6]],"ltp":0.0,"tv":0.0,"id":31379},{"batb":[[0,1.69,58.54]],"ltp":0.0,"tv":0.0,"id":31377}]}]}
{"op":"mcm","clk":"11765914042","pt":1722696006560,"mc":[{"id":"1.231344876","rc":[{"batb":[[2,1.42,85.28]],"ltp":0.0,"tv":0.0,"id":31379},{"batb":[[2,1.38,85.28]],"ltp":0.0,"tv":0.0,"id":31377}]}]}
{"op":"mcm","clk":"11767128245","pt":1722702648729,"mc":[{"id":"1.231344876","rc":[{"batl":[[0,1.72,100]],"ltp":0.0,"tv":0.0,"id":31377}]}]}
{"op":"mcm","clk":"11767176406","pt":1722702962514,"mc":[{"id":"1.231344876","rc":[{"batb":[[0,1.71,25.17],[1,1.69,58.54],[2,1.57,6]],"ltp":0.0,"tv":0.0,"id":31377}]}]}
{"op":"mcm","clk":"11767177990","pt":1722702972627,"mc":[{"id":"1.231344876","rc":[{"trd":[[1.69,115.66],[1.71,50.34]],"batb":[[0,1.65,62.85],[1,1.57,6],[2,1.38,85.28]],"ltp":1.69,"tv":166.0,"id":31377}],"tv":166.0}]}
{"op":"mcm","clk":"11767178006","pt":1722702972731,"mc":[{"id":"1.231344876","rc":[{"batb":[[0,1.65,62.14]],"ltp":1.69,"tv":166.0,"id":31377}]}]}
{"op":"mcm","clk":"11767214976","pt":1722703207577,"mc":[{"id":"1.231344876","rc":[{"trd":[[1.65,34]],"batb":[[0,1.65,45.14]],"ltp":1.65,"tv":200.0,"id":31377}],"tv":200.0}]}
{"op":"mcm","clk":"11767215166","pt":1722703208656,"mc":[{"id":"1.231344876","rc":[{"batb":[[0,1.65,62.14]],"ltp":1.65,"tv":200.0,"id":31377}]}]}
{"op":"mcm","clk":"11767243015","pt":1722703375639,"mc":[{"id":"1.231344876","rc":[{"batl":[[0,1.71,4.91],[1,1.72,100]],"ltp":1.65,"tv":200.0,"id":31377}]}]}
{"op":"mcm","clk":"11767339466","pt":1722704012529,"mc":[{"id":"1.231344876","rc":[{"trd":[[1.71,60.16]],"batb":[[0,1.71,50.34],[1,1.65,62.14],[2,1.57,6]],"batl":[[0,1.72,100],[1,1.72,0]],"ltp":1.71,"tv":209.82,"id":31377}],"tv":209.82}]}
{"op":"mcm","clk":"11767365113","pt":1722704257125,"mc":[{"id":"1.231344876","rc":[{"trd":[[2.38,68.82]],"ltp":2.38,"tv":68.82,"id":31379},{"trd":[[1.72,95.23]],"batl":[[0,1.72,4.77]],"ltp":1.72,"tv":305.05,"id":31377}],"tv":373.87}]}
{"op":"mcm","clk":"11767578403","pt":1722706078306,"mc":[{"id":"1.231344876","rc":[{"batl":[[1,1.75,100]],"ltp":1.72,"tv":305.05,"id":31377}]}]}
{"op":"mcm","clk":"11767578817","pt":1722706081794,"mc":[{"id":"1.231344876","rc":[{"batl":[[2,1.76,200]],"ltp":1.72,"tv":305.05,"id":31377}]}]}
{"op":"mcm","clk":"11767668492","pt":1722706800478,"mc":[{"id":"1.231344876","rc":[{"batb":[[0,2.34,5.37],[1,2.32,30.6],[2,1.68,3]],"ltp":2.38,"tv":68.82,"id":31379}]}]}
{"op":"mcm","clk":"11767996439","pt":1722709325097,"mc":[{"id":"1.231344876","rc":[{"batb":[[2,1.42,85.28]],"ltp":2.38,"tv":68.82,"id":31379},{"trd":[[1.71,60.17]],"batb":[[0,1.71,50.35],[2,1.38,85.28]],"ltp":1.72,"tv":305.05,"id":31377}],"tv":373.87}]}
{"op":"mcm","clk":"11768053491","pt":1722709822269,"mc":[{"id":"1.231344876","rc":[{"batb":[[1,1.67,35],[2,1.65,62.14]],"ltp":1.72,"tv":305.05,"id":31377}]}]}
{"op":"mcm","clk":"11768240173","pt":1722711218088,"mc":[{"id":"1.231344876","rc":[{"batb":[[0,2.4,187.41],[1,2.34,5.37],[2,2.32,30.6]],"ltp":2.38,"tv":68.82,"id":31379}]}]}
{"op":"mcm","clk":"11768240317","pt":1722711219345,"mc":[{"id":"1.231344876","rc":[{"batb":[[1,1.42,85.28],[2,1.3,633.33]],"ltp":2.38,"tv":68.82,"id":31379},{"batb":[[2,1.38,85.28]],"ltp":1.72,"tv":305.05,"id":31377}]}]}
{"op":"mcm","clk":"11768240385","pt":1722711220078,"mc":[{"id":"1.231344876","rc":[{"trd":[[2.4,374.82]],"batb":[[0,1.42,85.28],[1,1.3,633.33],[2,1.08,7.81]],"ltp":2.4,"tv":443.64,"id":31379}],"tv":748.7}]}
{"op":"mcm","clk":"11768240771","pt":1722711223686,"mc":[{"id":"1.231344876","rc":[{"batb":[[0,2.32,30.6],[1,1.42,85.28],[2,1.3,633.33]],"ltp":2.4,"tv":443.64,"id":31379},{"batb":[[2,1.65,62.14]],"ltp":1.72,"tv":305.05,"id":31377}]}]}
{"op":"mcm","clk":"11768240809","pt":1722711224064,"mc":[{"id":"1.231344876","rc":[{"batb":[[0,2.34,5.37],[1,2.32,30.6],[2,1.42,85.28]],"ltp":2.4,"tv":443.64,"id":31379}]}]}
{"op":"mcm","clk":"11768264963","pt":1722711443666,"mc":[{"id":"1.231344876","rc":[{"batb":[[0,2.4,351.4],[1,2.34,5.37],[2,2.32,30.6]],"ltp":2.4,"tv":443.64,"id":31379}]}]}
{"op":"mcm","clk":"11768265051","pt":1722711444398,"mc":[{"id":"1.231344876","rc":[{"batb":[[1,1.42,85.28],[2,1.3,633.33]],"ltp":2.4,"tv":443.64,"id":31379},{"batb":[[2,1.38,85.28]],"ltp":1.72,"tv":305.05,"id":31377}]}]}
{"op":"mcm","clk":"11768265328","pt":1722711447299,"mc":[{"id":"1.231344876","rc":[{"trd":[[2.4,1077.62]],"batb":[[0,1.42,85.28],[1,1.3,633.33],[2,1.08,7.81]],"ltp":2.4,"tv":1146.43,"id":31379}],"tv":1451.49}]}
{"op":"mcm","clk":"11768265569","pt":1722711449407,"mc":[{"id":"1.231344876","rc":[{"batb":[[0,2.32,30.6],[1,1.42,85.28],[2,1.3,633.33]],"ltp":2.4,"tv":1146.43,"id":31379},{"batb":[[2,1.65,62.14]],"ltp":1.72,"tv":305.05,"id":31377}]}]}
{"op":"mcm","clk":"11768265631","pt":1722711449891,"mc":[{"id":"1.231344876","rc":[{"batb":[[0,2.34,5.37],[1,2.32,30.6],[2,1.42,85.28]],"ltp":2.4,"tv":1146.43,"id":31379}]}]}
{"op":"mcm","clk":"11768265891","pt":1722711452420,"mc":[{"id":"1.231344876","rc":[{"batb":[[0,2.4,351.4],[1,2.34,5.37],[2,2.32,30.6]],"ltp":2.4,"tv":1146.43,"id":31379}]}]}
{"op":"mcm","clk":"11768266129","pt":1722711454494,"mc":[{"id":"1.231344876","rc":[{"batb":[[1,1.42,85.28],[2,1.3,633.33]],"ltp":2.4,"tv":1146.43,"id":31379},{"batb":[[2,1.38,85.28]],"ltp":1.72,"tv":305.05,"id":31377}]}]}
{"op":"mcm","clk":"11768266932","pt":1722711461923,"mc":[{"id":"1.231344876","rc":[{"trd":[[2.4,1780.42]],"batb":[[0,1.42,85.28],[1,1.3,633.33],[2,1.08,7.81]],"ltp":2.4,"tv":1849.23,"id":31379}],"tv":2154.29}]}
{"op":"mcm","clk":"11768267186","pt":1722711464414,"mc":[{"id":"1.231344876","rc":[{"batb":[[0,2.32,30.6],[1,1.42,85.28],[2,1.3,633.33]],"ltp":2.4,"tv":1849.23,"id":31379},{"batb":[[2,1.65,62.14]],"ltp":1.72,"tv":305.05,"id":31377}]}]}
{"op":"mcm","clk":"11768267494","pt":1722711467227,"mc":[{"id":"1.231344876","rc":[{"batb":[[0,2.4,351.4],[1,2.32,30.6],[2,1.42,85.28]],"ltp":2.4,"tv":1849.23,"id":31379}]}]}
{"op":"mcm","clk":"11768267735","pt":1722711469526,"mc":[{"id":"1.231344876","rc":[{"batb":[[1,1.42,85.28],[2,1.3,633.33]],"ltp":2.4,"tv":1849.23,"id":31379},{"batb":[[2,1.38,85.28]],"ltp":1.72,"tv":305.05,"id":31377}]}]}
{"op":"mcm","clk":"11768267948","pt":1722711471225,"mc":[{"id":"1.231344876","rc":[{"trd":[[2.4,2483.21]],"batb":[[0,1.42,85.28],[1,1.3,633.33],[2,1.08,7.81]],"ltp":2.4,"tv":2552.03,"id":31379}],"tv":2857.09}]}
{"op":"mcm","clk":"11768268313","pt":1722711474457,"mc":[{"id":"1.231344876","rc":[{"batb":[[0,2.32,30.6],[1,1.42,85.28],[2,1.3,633.33]],"ltp":2.4,"tv":2552.03,"id":31379},{"batb":[[2,1.65,62.14]],"ltp":1.72,"tv":305.05,"id":31377}]}]}
{"op":"mcm","clk":"11768268570","pt":1722711476874,"mc":[{"id":"1.231344876","rc":[{"batb":[[0,2.4,351.4],[1,2.32,30.6],[2,1.42,85.28]],"ltp":2.4,"tv":2552.03,"id":31379}]}]}
{"op":"mcm","clk":"11768268817","pt":1722711479558,"mc":[{"id":"1.231344876","rc":[{"batb":[[1,1.42,85.28],[2,1.3,633.33]],"ltp":2.4,"tv":2552.03,"id":31379},{"batb":[[2,1.38,85.28]],"ltp":1.72,"tv":305.05,"id":31377}]}]}
{"op":"mcm","clk":"11768269230","pt":1722711483192,"mc":[{"id":"1.231344876","rc":[{"trd":[[2.4,3186.01]],"batb":[[0,1.42,85.28],[1,1.3,633.33],[2,1.08,7.81]],"ltp":2.4,"tv":3254.82,"id":31379}],"tv":3559.88}]}
{"op":"mcm","clk":"11768269375","pt":1722711484596,"mc":[{"id":"1.231344876","rc":[{"batb":[[0,2.32,30.6],[1,1.42,85.28],[2,1.3,633.33]],"ltp":2.4,"tv":3254.82,"id":31379},{"batb":[[2,1.65,62.14]],"ltp":1.72,"tv":305.05,"id":31377}]}]}
{"op":"mcm","clk":"11768269836","pt":1722711488660,"mc":[{"id":"1.231344876","rc":[{"batb":[[0,2.4,351.4],[1,2.32,30.6],[2,1.42,85.28]],"ltp":2.4,"tv":3254.82,"id":31379}]}]}
{"op":"mcm","clk":"11768269929","pt":1722711489553,"mc":[{"id":"1.231344876","rc":[{"batb":[[1,1.42,85.28],[2,1.3,633.33]],"ltp":2.4,"tv":3254.82,"id":31379},{"batb":[[2,1.38,85.28]],"ltp":1.72,"tv":305.05,"id":31377}]}]}
{"op":"mcm","clk":"11768270302","pt":1722711492888,"mc":[{"id":"1.231344876","rc":[{"trd":[[2.4,3888.8]],"batb":[[0,1.42,85.28],[1,1.3,633.33],[2,1.08,7.81]],"ltp":2.4,"tv":3957.62,"id":31379}],"tv":4262.68}]}
{"op":"mcm","clk":"11768270488","pt":1722711494563,"mc":[{"id":"1.231344876","rc":[{"batb":[[0,2.32,30.6],[1,1.42,85.28],[2,1.3,633.33]],"ltp":2.4,"tv":3957.62,"id":31379},{"batb":[[2,1.65,62.14]],"ltp":1.72,"tv":305.05,"id":31377}]}]}
{"op":"mcm","clk":"11768270933","pt":1722711498286,"mc":[{"id":"1.231344876","rc":[{"batb":[[0,2.4,351.4],[1,2.32,30.6],[2,1.42,85.28]],"ltp":2.4,"tv":3957.62,"id":31379}]}]}
{"op":"mcm","clk":"11768271081","pt":1722711499703,"mc":[{"id":"1.231344876","rc":[{"batb":[[1,1.42,85.28],[2,1.3,633.33]],"ltp":2.4,"tv":3957.62,"id":31379},{"batb":[[2,1.38,85.28]],"ltp":1.72,"tv":305.05,"id":31377}]}]}
{"op":"mcm","clk":"11768271327","pt":1722711502386,"mc":[{"id":"1.231344876","rc":[{"trd":[[2.4,4591.6]],"batb":[[0,1.42,85.28],[1,1.3,633.33],[2,1.08,7.81]],"ltp":2.4,"tv":4660.41,"id":31379}],"tv":4965.47}]}
{"op":"mcm","clk":"11768271558","pt":1722711504598,"mc":[{"id":"1.231344876","rc":[{"batb":[[0,2.32,30.6],[1,1.42,85.28],[2,1.3,633.33]],"ltp":2.4,"tv":4660.41,"id":31379},{"batb":[[2,1.65,62.14]],"ltp":1.72,"tv":305.05,"id":31377}]}]}
{"op":"mcm","clk":"11768271844","pt":1722711507237,"mc":[{"id":"1.231344876","rc":[{"batb":[[0,2.34,10],[1,2.32,30.6],[2,1.42,85.28]],"batl":[[0,2.42,4]],"ltp":2.4,"tv":4660.41,"id":31379},{"batb":[[0,1.71,54.35]],"ltp":1.72,"tv":305.05,"id":31377}]}]}
{"op":"mcm","clk":"11768271919","pt":1722711507968,"mc":[{"id":"1.231344876","rc":[{"batb":[[0,2.4,351.4],[1,2.34,10],[2,2.32,30.6]],"ltp":2.4,"tv":4660.41,"id":31379}]}]}
{"op":"mcm","clk":"11768272075","pt":1722711509603,"mc":[{"id":"1.231344876","rc":[{"batb":[[2,1.42,85.28]],"ltp":2.4,"tv":4660.41,"id":31379},{"batb":[[0,1.71,50.35],[2,1.38,85.28]],"ltp":1.72,"tv":305.05,"id":31377}]}]}
{"op":"mcm","clk":"11768272193","pt":1722711510605,"mc":[{"id":"1.231344876","rc":[{"batb":[[1,1.42,85.28],[2,1.3,633.33]],"ltp":2.4,"tv":4660.41,"id":31379}]}]}
{"op":"mcm","clk":"11768272512","pt":1722711513408,"mc":[{"id":"1.231344876","rc":[{"trd":[[2.4,5294.39]],"batb":[[0,1.42,85.28],[1,1.3,633.33],[2,1.08,7.81]],"ltp":2.4,"tv":5363.21,"id":31379}],"tv":5668.27}]}
{"op":"mcm","clk":"11768272643","pt":1722711514673,"mc":[{"id":"1.231344876","rc":[{"batb":[[0,2.32,30.6],[1,1.42,85.28],[2,1.3,633.33]],"ltp":2.4,"tv":5363.21,"id":31379},{"batb":[[2,1.65,62.14]],"ltp":1.72,"tv":305.05,"id":31377}]}]}
{"op":"mcm","clk":"11768273117","pt":1722711519191,"mc":[{"id":"1.231344876","rc":[{"batb":[[0,2.4,351.4],[1,2.32,30.6],[2,1.42,85.28]],"ltp":2.4,"tv":5363.21,"id":31379}]}]}
{"op":"mcm","clk":"11768273178","pt":1722711519842,"mc":[{"id":"1.231344876","rc":[{"batb":[[1,1.42,85.28],[2,1.3,633.33]],"ltp":2.4,"tv":5363.21,"id":31379},{"batb":[[2,1.38,85.28]],"ltp":1.72,"tv":305.05,"id":31377}]}]}
{"op":"mcm","clk":"11768273447","pt":1722711522196,"mc":[{"id":"1.231344876","rc":[{"batb":[[0,2.4,355.4]],"ltp":2.4,"tv":5363.21,"id":31379},{"batl":[[0,1.72,8.77]],"ltp":1.72,"tv":305.05,"id":31377}]}]}
{"op":"mcm","clk":"11768273818","pt":1722711525458,"mc":[{"id":"1.231344876","rc":[{"trd":[[2.4,5997.19]],"batb":[[0,1.42,85.28],[1,1.3,633.33],[2,1.08,7.81]],"ltp":2.4,"tv":6066.0,"id":31379}],"tv":6371.06}]}
{"op":"mcm","clk":"11768273875","pt":1722711525919,"mc":[{"id":"1.231344876","rc":[{"batl":[[0,1.72,4.77]],"ltp":1.72,"tv":305.05,"id":31377}]}]}
{"op":"mcm","clk":"11768274308","pt":1722711529717,"mc":[{"id":"1.231344876","rc":[{"batb":[[0,2.32,30.6],[1,1.42,85.28],[2,1.3,633.33]],"ltp":2.4,"tv":6066.0,"id":31379},{"batb":[[2,1.65,62.14]],"ltp":1.72,"tv":305.05,"id":31377}]}]}
{"op":"mcm","clk":"11768274720","pt":1722711533419,"mc":[{"id":"1.231344876","rc":[{"batb":[[0,2.4,351.4],[1,2.32,30.6],[2,1.42,85.28]],"ltp":2.4,"tv":6066.0,"id":31379}]}]}
{"op":"mcm","clk":"11768274863","pt":1722711534825,"mc":[{"id":"1.231344876","rc":[{"batb":[[1,1.42,85.28],[2,1.3,633.33]],"ltp":2.4,"tv":6066.0,"id":31379},{"batb":[[2,1.38,85.28]],"ltp":1.72,"tv":305.05,"id":31377}]}]}
{"op":"mcm","clk":"11768274972","pt":1722711536037,"mc":[{"id":"1.231344876","rc":[{"trd":[[2.4,6697.19]],"batb":[[0,2.4,1.4]],"ltp":2.4,"tv":6766.0,"id":31379}],"tv":7071.06}]}
{"op":"mcm","clk":"11768275130","pt":1722711537649,"mc":[{"id":"1.231344876","rc":[{"trd":[[2.38,72.26],[2.4,6699.98]],"batb":[[0,1.43,10]],"batl":[[0,2.38,346.56],[1,2.42,4]],"ltp":2.38,"tv":6772.24,"id":31379},{"trd":[[1.72,100]],"batb":[[0,1.71,54.35]],"batl":[[0,1.75,100],[1,1.76,200],[2,1.77,300]],"ltp":1.72,"tv":309.82,"id":31377}],"tv":7082.07}]}
{"op":"mcm","clk":"11768275306","pt":1722711539468,"mc":[{"id":"1.231344876","rc":[{"batb":[[0,1.73,4.85],[1,1.71,49.44],[2,1.67,35]],"ltp":1.72,"tv":309.82,"id":31377}]}]}
{"op":"mcm","clk":"11768275343","pt":1722711539747,"mc":[{"id":"1.231344876","rc":[{"batb":[[0,2.32,30.6],[1,1.43,10],[2,1.42,85.28]],"ltp":2.38,"tv":6772.24,"id":31379}]}]}
{"op":"mcm","clk":"11768275474","pt":1722711540916,"mc":[{"id":"1.231344876","rc":[{"batb":[[1,1.42,85.28],[2,1.3,633.33]],"ltp":2.38,"tv":6772.24,"id":31379}]}]}
{"op":"mcm","clk":"11768276797","pt":1722711552589,"mc":[{"id":"1.231344876","rc":[{"batb":[[0,2.32,34.6]],"batl":[[0,2.38,350.56]],"ltp":2.38,"tv":6772.24,"id":31379},{"batb":[[0,1.73,8.85]],"batl":[[0,1.75,104]],"ltp":1.72,"tv":309.82,"id":31377}]}]}
{"op":"mcm","clk":"11768278198","pt":1722711565270,"mc":[{"id":"1.231344876","rc":[{"batl":[[0,1.74,112.5],[1,1.75,104],[2,1.76,200]],"ltp":1.72,"tv":309.82,"id":31377}]}]}
{"op":"mcm","clk":"11768278276","pt":1722711565957,"mc":[{"id":"1.231344876","rc":[{"batb":[[0,1.73,4.85]],"ltp":1.72,"tv":309.82,"id":31377}]}]}
{"op":"mcm","clk":"11768278457","pt":1722711567746,"mc":[{"id":"1.231344876","rc":[{"batb":[[0,2.34,4],[1,2.32,34.6],[2,1.42,85.28]],"ltp":2.38,"tv":6772.24,"id":31379},{"batl":[[0,1.74,116.5]],"ltp":1.72,"tv":309.82,"id":31377}]}]}
{"op":"mcm","clk":"11768285304","pt":1722711623543,"mc":[{"id":"1.231344876","rc":[{"trd":[[2.34,4]],"batb":[[0,2.32,34.6],[1,1.42,85.28],[2,1.3,633.33]],"ltp":2.34,"tv":6776.24,"id":31379},{"trd":[[1.71,60.16],[1.74,233],[1.75,213.35],[1.76,50.2]],"batb":[[1,1.71,45.43]],"batl":[[0,1.76,174.9],[1,1.77,300],[2,1.78,535.95]],"ltp":1.76,"tv":806.36,"id":31377}],"tv":7582.61}]}
{"op":"mcm","clk":"11768285430","pt":1722711624340,"mc":[{"id":"1.231344876","rc":[{"batb":[[0,1.72,4.89]],"ltp":1.76,"tv":806.36,"id":31377}]}]}
{"op":"mcm","clk":"11768285992","pt":1722711628353,"mc":[{"id":"1.231344876","rc":[{"batl":[[0,1.76,178.9]],"ltp":1.76,"tv":806.36,"id":31377}]}]}
{"op":"mcm","clk":"11768288823","pt":1722711648643,"mc":[{"id":"1.231344876","rc":[{"batl":[[0,2.36,351.4]],"ltp":2.34,"tv":6776.24,"id":31379}]}]}
{"op":"mcm","clk":"11768289088","pt":1722711650683,"mc":[{"id":"1.231344876","rc":[{"batb":[[0,1.71,45.43],[1,1.67,35],[2,1.65,62.14]],"ltp":1.76,"tv":806.36,"id":31377}]}]}
{"op":"mcm","clk":"11768289102","pt":1722711650740,"mc":[{"id":"1.231344876","rc":[{"batb":[[0,1.74,4.83],[1,1.71,45.43],[2,1.67,35]],"ltp":1.76,"tv":806.36,"id":31377}]}]}
{"op":"mcm","clk":"11768289698","pt":1722711655382,"mc":[{"id":"1.231344876","rc":[{"trd":[[2.36,312.35]],"batl":[[0,2.36,195.22]],"ltp":2.36,"tv":7088.6,"id":31379}],"tv":7894.97}]}
{"op":"mcm","clk":"11768290096","pt":1722711658477,"mc":[{"id":"1.231344876","rc":[{"batl":[[0,2.34,4],[1,2.36,199.22]],"ltp":2.36,"tv":7088.6,"id":31379},{"batb":[[0,1.74,8.83]],"ltp":1.76,"tv":806.36,"id":31377}]}]}
{"op":"mcm","clk":"11768291348","pt":1722711668463,"mc":[{"id":"1.231344876","rc":[{"batl":[[1,2.36,4]],"ltp":2.36,"tv":7088.6,"id":31379}]}]}
{"op":"mcm","clk":"11768291446","pt":1722711669193,"mc":[{"id":"1.231344876","rc":[{"batb":[[0,1.71,45.43],[1,1.67,35],[2,1.65,62.14]],"ltp":1.76,"tv":806.36,"id":31377}]}]}
{"op":"mcm","clk":"11768299639","pt":1722711731303,"mc":[{"id":"1.231344876","rc":[{"batb":[[0,1.72,4.89],[1,1.71,45.43],[2,1.67,35]],"ltp":1.76,"tv":806.36,"id":31377}]}]}
{"op":"mcm","clk":"11768300529","pt":1722711737940,"mc":[{"id":"1.231344876","rc":[{"batl":[[0,2.4,7.81]],"ltp":2.36,"tv":7088.6,"id":31379}]}]}
{"op":"mcm","clk":"11768312382","pt":1722711830151,"mc":[{"id":"1.231344876","rc":[{"trd":[[2.32,0.54]],"batb":[[0,2.32,34.33]],"ltp":2.32,"tv":7089.14,"id":31379}],"tv":7895.51}]}
{"op":"mcm","clk":"11768312472","pt":1722711830880,"mc":[{"id":"1.231344876","rc":[{"batb":[[0,2.32,34.6]],"ltp":2.32,"tv":7089.14,"id":31379}]}]}
{"op":"mcm","clk":"11768314222","pt":1722711843970,"mc":[{"id":"1.231344876","rc":[{"batl":[[1,2.5,0.27]],"ltp":2.32,"tv":7089.14,"id":31379}]}]}
{"op":"mcm","clk":"11768315301","pt":1722711851428,"mc":[{"id":"1.231344876","rc":[{"batl":[[1,2.48,141.34],[2,2.5,0.27]],"ltp":2.32,"tv":7089.14,"id":31379}]}]}
{"op":"mcm","clk":"11768315859","pt":1722711855403,"mc":[{"id":"1.231344876","rc":[{"batb":[[0,1.72,8.89]],"ltp":1.76,"tv":806.36,"id":31377}]}]}
{"op":"mcm","clk":"11768316179","pt":1722711857993,"mc":[{"id":"1.231344876","rc":[{"batl":[[2,3,0.82]],"ltp":2.32,"tv":7089.14,"id":31379}]}]}
{"op":"mcm","clk":"11768318147","pt":1722711872154,"mc":[{"id":"1.231344876","rc":[{"batl":[[2,4,1.09]],"ltp":2.32,"tv":7089.14,"id":31379}]}]}
{"op":"mcm","clk":"11768330269","pt":1722711959571,"mc":[{"id":"1.231344876","rc":[{"batl":[[0,2.48,141.34],[1,4,1.09],[2,8,1.09]],"ltp":2.32,"tv":7089.14,"id":31379}]}]}
{"op":"mcm","clk":"11768330299","pt":1722711959782,"mc":[{"id":"1.231344876","rc":[{"batb":[[0,2.34,10],[1,2.32,34.6],[2,1.42,85.28]],"ltp":2.32,"tv":7089.14,"id":31379}]}]}
{"op":"mcm","clk":"11768330572","pt":1722711961388,"mc":[{"id":"1.231344876","rc":[{"batb":[[0,2.34,14],[1,2.32,4]],"batl":[[0,2.4,4],[1,2.48,141.34],[2,4,1.09]],"ltp":2.32,"tv":7089.14,"id":31379},{"batl":[[0,1.75,4],[1,1.76,178.9],[2,1.77,300]],"ltp":1.76,"tv":806.36,"id":31377}]}]}
{"op":"mcm","clk":"11768330961","pt":1722711963473,"mc":[{"id":"1.231344876","rc":[{"batb":[[0,2.32,4],[1,1.42,85.28],[2,1.3,633.33]],"ltp":2.32,"tv":7089.14,"id":31379}]}]}
{"op":"mcm","clk":"11768331042","pt":1722711964059,"mc":[{"id":"1.231344876","rc":[{"batl":[[0,2.48,141.34],[1,4,1.09],[2,8,1.09]],"ltp":2.32,"tv":7089.14,"id":31379}]}]}
{"op":"mcm","clk":"11768331395","pt":1722711966391,"mc":[{"id":"1.231344876","rc":[{"batb":[[0,2.34,10],[1,2.32,34.6],[2,1.42,85.28]],"ltp":2.32,"tv":7089.14,"id":31379}]}]}
{"op":"mcm","clk":"11768331875","pt":1722711969580,"mc":[{"id":"1.231344876","rc":[{"batb":[[0,2.32,34.6],[1,1.42,85.28],[2,1.3,633.33]],"ltp":2.32,"tv":7089.14,"id":31379}]}]}
{"op":"mcm","clk":"11768332445","pt":1722711973182,"mc":[{"id":"1.231344876","rc":[{"batb":[[0,2.34,10],[1,2.32,34.6],[2,1.42,85.28]],"ltp":2.32,"tv":7089.14,"id":31379}]}]}
{"op":"mcm","clk":"11768332954","pt":1722711976585,"mc":[{"id":"1.231344876","rc":[{"batb":[[0,2.34,4],[1,2.32,4]],"batl":[[0,2.4,4],[1,2.48,141.34],[2,4,1.09]],"ltp":2.32,"tv":7089.14,"id":31379}]}]}
{"op":"mcm","clk":"11768333639","pt":1722711981276,"mc":[{"id":"1.231344876","rc":[{"batb":[[1,2.32,34.6]],"ltp":2.32,"tv":7089.14,"id":31379}]}]}
{"op":"mcm","clk":"11768334182","pt":1722711985088,"mc":[{"id":"1.231344876","rc":[{"batl":[[0,2.38,10.54],[1,2.4,4],[2,2.48,141.34]],"ltp":2.32,"tv":7089.14,"id":31379}]}]}
{"op":"mcm","clk":"11768335299","pt":1722711992095,"mc":[{"id":"1.231344876","rc":[{"batl":[[0,2.38,14.54]],"ltp":2.32,"tv":7089.14,"id":31379},{"batb":[[0,1.73,4],[1,1.72,4.89],[2,1.71,45.43]],"ltp":1.76,"tv":806.36,"id":31377}]}]}
{"op":"mcm","clk":"11768337752","pt":1722712007437,"mc":[{"id":"1.231344876","rc":[{"batl":[[0,2.38,10.54],[1,2.48,141.34],[2,4,1.09]],"ltp":2.32,"tv":7089.14,"id":31379},{"batb":[[0,1.72,4.89],[1,1.71,45.43],[2,1.67,35]],"ltp":1.76,"tv":806.36,"id":31377}]}]}
{"op":"mcm","clk":"11768338727","pt":1722712013436,"mc":[{"id":"1.231344876","rc":[{"trd":[[2.32,16.64],[2.34,8]],"batb":[[0,2.32,18.5],[1,1.42,85.28],[2,1.3,633.33]],"batl":[[1,4,1.09],[2,8,1.09]],"ltp":2.32,"tv":7109.24,"id":31379},{"trd":[[1.75,226.69],[1.76,429.21]],"batl":[[0,1.77,300],[1,1.78,535.95],[2,1.79,500]],"ltp":1.76,"tv":1198.73,"id":31377}],"tv":8307.97}]}
{"op":"mcm","clk":"11768339201","pt":1722712016462,"mc":[{"id":"1.231344876","rc":[{"batb":[[0,2.32,30.6]],"ltp":2.32,"tv":7109.24,"id":31379}]}]}
{"op":"mcm","clk":"11768340080","pt":1722712022151,"mc":[{"id":"1.231344876","rc":[{"batb":[[0,2.32,34.6]],"ltp":2.32,"tv":7109.24,"id":31379},{"batl":[[0,1.76,4],[1,1.77,300],[2,1.78,535.95]],"ltp":1.76,"tv":1198.73,"id":31377}]}]}
{"op":"mcm","clk":"11768341096","pt":1722712028358,"mc":[{"id":"1.231344876","rc":[{"batb":[[0,2.34,12],[1,2.32,34.6],[2,1.42,85.28]],"batl":[[0,4,1.09],[1,8,1.09],[2,20,1.45]],"ltp":2.32,"tv":7109.24,"id":31379}]}]}
{"op":"mcm","clk":"11768341481","pt":1722712030438,"mc":[{"id":"1.231344876","rc":[{"batb":[[0,2.34,10]],"ltp":2.32,"tv":7109.24,"id":31379}]}]}
{"op":"mcm","clk":"11768341676","pt":1722712031653,"mc":[{"id":"1.231344876","rc":[{"batb":[[0,2.32,34.6],[1,1.42,85.28],[2,1.3,633.33]],"ltp":2.32,"tv":7109.24,"id":31379}]}]}
{"op":"mcm","clk":"11768342103","pt":1722712034060,"mc":[{"id":"1.231344876","rc":[{"batb":[[0,2.34,12],[1,2.32,34.6],[2,1.42,85.28]],"ltp":2.32,"tv":7109.24,"id":31379}]}]}
{"op":"mcm","clk":"11768342504","pt":1722712036462,"mc":[{"id":"1.231344876","rc":[{"batb":[[0,2.34,10]],"ltp":2.32,"tv":7109.24,"id":31379}]}]}
{"op":"mcm","clk":"11768342612","pt":1722712037251,"mc":[{"id":"1.231344876","rc":[{"batb":[[0,2.34,4]],"batl":[[0,2.4,4],[1,4,1.09],[2,8,1.09]],"ltp":2.32,"tv":7109.24,"id":31379},{"batl":[[0,1.75,4],[1,1.76,4],[2,1.77,300]],"ltp":1.76,"tv":1198.73,"id":31377}]}]}
{"op":"mcm","clk":"11768345000","pt":1722712052382,"mc":[{"id":"1.231344876","rc":[{"batb":[[0,1.72,8.89]],"ltp":1.76,"tv":1198.73,"id":31377}]}]}
{"op":"mcm","clk":"11768373253","pt":1722712229523,"mc":[{"id":"1.231344876","rc":[{"trd":[[2.32,17.32],[2.34,12]],"batb":[[0,2.32,33.92],[1,1.42,85.28],[2,1.3,633.33]],"batl":[[0,4,1.09],[1,8,1.09],[2,20,1.45]],"ltp":2.32,"tv":7113.92,"id":31379},{"trd":[[1.75,240.04],[1.76,438.11]],"batb":[[0,1.72,4.89]],"batl":[[0,1.77,300],[1,1.78,535.95],[2,1.79,500]],"ltp":1.76,"tv":1220.97,"id":31377}],"tv":8334.9}]}
{"op":"mcm","clk":"11768373292","pt":1722712229726,"mc":[{"id":"1.231344876","rc":[{"batb":[[0,2.34,12],[1,2.32,33.92],[2,1.42,85.28]],"ltp":2.32,"tv":7113.92,"id":31379}]}]}
{"op":"mcm","clk":"11768373730","pt":1722712232223,"mc":[{"id":"1.231344876","rc":[{"batb":[[0,2.34,10],[1,2.32,34.6]],"ltp":2.32,"tv":7113.92,"id":31379}]}]}
{"op":"mcm","clk":"11768373847","pt":1722712233069,"mc":[{"id":"1.231344876","rc":[{"batb":[[0,2.32,34.6],[1,1.42,85.28],[2,1.3,633.33]],"ltp":2.32,"tv":7113.92,"id":31379}]}]}
{"op":"mcm","clk":"11768374025","pt":1722712233932,"mc":[{"id":"1.231344876","rc":[{"batl":[[0,1.76,4],[1,1.77,300],[2,1.78,535.95]],"ltp":1.76,"tv":1220.97,"id":31377}]}]}
{"op":"mcm","clk":"11768378828","pt":1722712264448,"mc":[{"id":"1.231344876","rc":[{"trd":[[2.34,22]],"ltp":2.34,"tv":7123.92,"id":31379},{"trd":[[1.75,253.41]],"batb":[[0,1.75,181.85],[1,1.72,4.89],[2,1.71,45.43]],"ltp":1.75,"tv":1234.34,"id":31377}],"tv":8358.27}]}
{"op":"mcm","clk":"11768378983","pt":1722712265464,"mc":[{"id":"1.231344876","rc":[{"batb":[[1,1.71,50.34],[2,1.67,35]],"ltp":1.75,"tv":1234.34,"id":31377}]}]}
{"op":"mcm","clk":"11768379094","pt":1722712266258,"mc":[{"id":"1.231344876","rc":[{"batb":[[0,2.34,2],[1,2.32,34.6],[2,1.42,85.28]],"ltp":2.34,"tv":7123.92,"id":31379},{"trd":[[1.75,617.11]],"batb":[[0,1.71,50.34],[1,1.67,35],[2,1.65,62.14]],"batl":[[0,1.72,13.37],[1,1.76,4],[2,1.77,300]],"ltp":1.75,"tv":1598.05,"id":31377}],"tv":8721.97}]}
{"op":"mcm","clk":"11768379431","pt":1722712268548,"mc":[{"id":"1.231344876","rc":[{"batb":[[0,2.32,34.6],[1,1.42,85.28],[2,1.3,633.33]],"ltp":2.34,"tv":7123.92,"id":31379}]}]}
{"op":"mcm","clk":"11768379463","pt":1722712268768,"mc":[{"id":"1.231344876","rc":[{"batb":[[0,2.34,10],[1,2.32,34.6],[2,1.42,85.28]],"ltp":2.34,"tv":7123.92,"id":31379}]}]}
{"op":"mcm","clk":"11768380016","pt":1722712272631,"mc":[{"id":"1.231344876","rc":[{"batb":[[0,2.34,2]],"ltp":2.34,"tv":7123.92,"id":31379},{"batl":[[0,1.76,4],[1,1.77,300],[2,1.78,535.95]],"ltp":1.75,"tv":1598.05,"id":31377}]}]}
{"op":"mcm","clk":"11768380405","pt":1722712275153,"mc":[{"id":"1.231344876","rc":[{"batb":[[0,2.34,10]],"ltp":2.34,"tv":7123.92,"id":31379}]}]}
{"op":"mcm","clk":"11768380887","pt":1722712278643,"mc":[{"id":"1.231344876","rc":[{"batb":[[0,2.32,34.6],[1,1.42,85.28],[2,1.3,633.33]],"ltp":2.34,"tv":7123.92,"id":31379}]}]}
{"op":"mcm","clk":"11768380901","pt":1722712278756,"mc":[{"id":"1.231344876","rc":[{"batb":[[0,2.34,2],[1,2.32,34.6],[2,1.42,85.28]],"ltp":2.34,"tv":7123.92,"id":31379}]}]}
{"op":"mcm","clk":"11768381282","pt":1722712281283,"mc":[{"id":"1.231344876","rc":[{"batb":[[0,2.34,10]],"ltp":2.34,"tv":7123.92,"id":31379}]}]}
{"op":"mcm","clk":"11768381731","pt":1722712284574,"mc":[{"id":"1.231344876","rc":[{"batb":[[0,2.32,34.6],[1,1.42,85.28],[2,1.3,633.33]],"ltp":2.34,"tv":7123.92,"id":31379}]}]}
{"op":"mcm","clk":"11768381757","pt":1722712284784,"mc":[{"id":"1.231344876","rc":[{"batb":[[0,2.34,2],[1,2.32,34.6],[2,1.42,85.28]],"ltp":2.34,"tv":7123.92,"id":31379}]}]}
{"op":"mcm","clk":"11768382128","pt":1722712287379,"mc":[{"id":"1.231344876","rc":[{"batb":[[0,2.34,10]],"ltp":2.34,"tv":7123.92,"id":31379}]}]}
{"op":"mcm","clk":"11768382599","pt":1722712290682,"mc":[{"id":"1.231344876","rc":[{"batb":[[0,2.32,34.6],[1,1.42,85.28],[2,1.3,633.33]],"ltp":2.34,"tv":7123.92,"id":31379}]}]}
{"op":"mcm","clk":"11768382681","pt":1722712291206,"mc":[{"id":"1.231344876","rc":[{"batb":[[0,2.34,2],[1,2.32,34.6],[2,1.42,85.28]],"ltp":2.34,"tv":7123.92,"id":31379}]}]}
{"op":"mcm","clk":"11768383078","pt":1722712293644,"mc":[{"id":"1.231344876","rc":[{"batb":[[0,2.32,34.6],[1,1.42,85.28],[2,1.3,633.33]],"ltp":2.34,"tv":7123.92,"id":31379}]}]}
{"op":"mcm","clk":"11768383107","pt":1722712293800,"mc":[{"id":"1.231344876","rc":[{"batb":[[0,2.34,10],[1,2.32,34.6],[2,1.42,85.28]],"ltp":2.34,"tv":7123.92,"id":31379}]}]}
{"op":"mcm","clk":"11768383575","pt":1722712297337,"mc":[{"id":"1.231344876","rc":[{"batb":[[0,2.34,2]],"ltp":2.34,"tv":7123.92,"id":31379}]}]}
{"op":"mcm","clk":"11768383944","pt":1722712299619,"mc":[{"id":"1.231344876","rc":[{"batb":[[0,2.32,34.6],[1,1.42,85.28],[2,1.3,633.33]],"ltp":2.34,"tv":7123.92,"id":31379}]}]}
{"op":"mcm","clk":"11768383959","pt":1722712299721,"mc":[{"id":"1.231344876","rc":[{"batb":[[0,2.34,10],[1,2.32,34.6],[2,1.42,85.28]],"ltp":2.34,"tv":7123.92,"id":31379}]}]}
{"op":"mcm","clk":"11768384425","pt":1722712303098,"mc":[{"id":"1.231344876","rc":[{"batb":[[0,2.34,2]],"ltp":2.34,"tv":7123.92,"id":31379}]}]}
{"op":"mcm","clk":"11768384786","pt":1722712305636,"mc":[{"id":"1.231344876","rc":[{"batb":[[0,2.32,34.6],[1,1.42,85.28],[2,1.3,633.33]],"ltp":2.34,"tv":7123.92,"id":31379}]}]}
{"op":"mcm","clk":"11768384797","pt":1722712305703,"mc":[{"id":"1.231344876","rc":[{"batb":[[0,2.34,10],[1,2.32,34.6],[2,1.42,85.28]],"ltp":2.34,"tv":7123.92,"id":31379}]}]}
{"op":"mcm","clk":"11768385309","pt":1722712309426,"mc":[{"id":"1.231344876","rc":[{"batb":[[0,2.34,6]],"batl":[[0,2.4,4],[1,2.42,4],[2,4,1.09]],"ltp":2.34,"tv":7123.92,"id":31379},{"batb":[[0,1.72,4],[1,1.71,54.34],[2,1.67,35]],"batl":[[0,1.75,4],[1,1.76,4],[2,1.77,300]],"ltp":1.75,"tv":1598.05,"id":31377}]}]}
{"op":"mcm","clk":"11768385371","pt":1722712309822,"mc":[{"id":"1.231344876","rc":[{"batb":[[0,1.71,50.34],[1,1.67,35],[2,1.65,62.14]],"ltp":1.75,"tv":1598.05,"id":31377}]}]}
{"op":"mcm","clk":"11768385692","pt":1722712312356,"mc":[{"id":"1.231344876","rc":[{"batb":[[0,2.32,30.6],[1,1.42,85.28],[2,1.3,633.33]],"ltp":2.34,"tv":7123.92,"id":31379},{"batb":[[0,1.73,351.4],[1,1.71,50.34],[2,1.67,35]],"ltp":1.75,"tv":1598.05,"id":31377}]}]}
{"op":"mcm","clk":"11768385840","pt":1722712313353,"mc":[{"id":"1.231344876","rc":[{"batl":[[0,2.36,12.54],[1,2.4,4],[2,2.42,4]],"ltp":2.34,"tv":7123.92,"id":31379},{"batb":[[0,1.74,21.87],[1,1.73,351.4],[2,1.71,45.43]],"ltp":1.75,"tv":1598.05,"id":31377}]}]}
{"op":"mcm","clk":"11768385981","pt":1722712314254,"mc":[{"id":"1.231344876","rc":[{"batl":[[0,1.76,4],[1,1.77,300],[2,1.78,535.95]],"ltp":1.75,"tv":1598.05,"id":31377}]}]}
{"op":"mcm","clk":"11768387001","pt":1722712321418,"mc":[{"id":"1.231344876","rc":[{"batl":[[1,4,1.09],[2,8,1.09]],"ltp":2.34,"tv":7123.92,"id":31379},{"batb":[[1,1.71,45.43],[2,1.67,35]],"ltp":1.75,"tv":1598.05,"id":31377}]}]}
{"op":"mcm","clk":"11768387226","pt":1722712323145,"mc":[{"id":"1.231344876","rc":[{"batb":[[0,2.34,12],[1,2.32,30.6],[2,1.42,85.28]],"batl":[[0,4,1.09],[1,8,1.09],[2,20,1.45]],"ltp":2.34,"tv":7123.92,"id":31379},{"batb":[[0,1.74,17.05]],"ltp":1.75,"tv":1598.05,"id":31377}]}]}
{"op":"mcm","clk":"11768387402","pt":1722712324481,"mc":[{"id":"1.231344876","rc":[{"batl":[[0,2.36,4],[1,4,1.09],[2,8,1.09]],"ltp":2.34,"tv":7123.92,"id":31379},{"batb":[[0,1.74,21.05]],"ltp":1.75,"tv":1598.05,"id":31377}]}]}
{"op":"mcm","clk":"11768387571","pt":1722712325539,"mc":[{"id":"1.231344876","rc":[{"batb":[[0,2.34,10]],"ltp":2.34,"tv":7123.92,"id":31379},{"batb":[[0,1.74,4],[1,1.72,4.89],[2,1.71,45.43]],"ltp":1.75,"tv":1598.05,"id":31377}]}]}
{"op":"mcm","clk":"11768387700","pt":1722712326544,"mc":[{"id":"1.231344876","rc":[{"batb":[[0,2.32,30.6],[1,1.42,85.28],[2,1.3,633.33]],"batl":[[0,4,1.09],[1,8,1.09],[2,20,1.45]],"ltp":2.34,"tv":7123.92,"id":31379},{"batb":[[0,1.72,4.89],[1,1.71,45.43],[2,1.67,35]],"ltp":1.75,"tv":1598.05,"id":31377}]}]}
{"op":"mcm","clk":"11768389438","pt":1722712339559,"mc":[{"id":"1.231344876","rc":[{"batb":[[0,2.32,34.6]],"ltp":2.34,"tv":7123.92,"id":31379}]}]}
{"op":"mcm","clk":"11768389527","pt":1722712340149,"mc":[{"id":"1.231344876","rc":[{"batb":[[0,2.34,12],[1,2.32,34.6],[2,1.42,85.28]],"ltp":2.34,"tv":7123.92,"id":31379}]}]}
{"op":"mcm","clk":"11768389826","pt":1722712342565,"mc":[{"id":"1.231344876","rc":[{"batb":[[0,2.34,10],[1,1.42,85.28],[2,1.3,633.33]],"ltp":2.34,"tv":7123.92,"id":31379},{"batb":[[0,1.73,351.4]],"ltp":1.75,"tv":1598.05,"id":31377}]}]}
{"op":"mcm","clk":"11768389997","pt":1722712343683,"mc":[{"id":"1.231344876","rc":[{"batb":[[0,1.42,85.28],[1,1.3,633.33],[2,1.08,7.81]],"ltp":2.34,"tv":7123.92,"id":31379},{"trd":[[1.73,702.8]],"batb":[[0,1.71,45.43],[1,1.67,35],[2,1.38,85.28]],"ltp":1.73,"tv":2300.84,"id":31377}],"tv":9424.77}]}
{"op":"mcm","clk":"11768390512","pt":1722712347585,"mc":[{"id":"1.231344876","rc":[{"batb":[[0,2.32,30.6],[1,1.42,85.28],[2,1.3,633.33]],"ltp":2.34,"tv":7123.92,"id":31379},{"batb":[[2,1.65,62.14]],"ltp":1.73,"tv":2300.84,"id":31377}]}]}
{"op":"mcm","clk":"11768390535","pt":1722712347759,"mc":[{"id":"1.231344876","rc":[{"batb":[[0,2.34,12],[1,2.32,30.6],[2,1.42,85.28]],"ltp":2.34,"tv":7123.92,"id":31379}]}]}
{"op":"mcm","clk":"11768390836","pt":1722712350299,"mc":[{"id":"1.231344876","rc":[{"batb":[[0,2.34,10]],"ltp":2.34,"tv":7123.92,"id":31379}]}]}
{"op":"mcm","clk":"11768390910","pt":1722712350975,"mc":[{"id":"1.231344876","rc":[{"batb":[[0,2.32,30.6],[1,1.42,85.28],[2,1.3,633.33]],"ltp":2.34,"tv":7123.92,"id":31379}]}]}
{"op":"mcm","clk":"11768391453","pt":1722712355180,"mc":[{"id":"1.231344876","rc":[{"batb":[[0,2.34,12],[1,2.32,34.6],[2,1.42,85.28]],"ltp":2.34,"tv":7123.92,"id":31379}]}]}
{"op":"mcm","clk":"11768391748","pt":1722712357601,"mc":[{"id":"1.231344876","rc":[{"batb":[[0,2.34,10]],"ltp":2.34,"tv":7123.92,"id":31379}]}]}
{"op":"mcm","clk":"11768391875","pt":1722712358507,"mc":[{"id":"1.231344876","rc":[{"batb":[[0,2.32,34.6],[1,1.42,85.28],[2,1.3,633.33]],"ltp":2.34,"tv":7123.92,"id":31379}]}]}
{"op":"mcm","clk":"11768392371","pt":1722712362608,"mc":[{"id":"1.231344876","rc":[{"batb":[[0,2.34,10],[1,2.32,34.6],[2,1.42,85.28]],"ltp":2.34,"tv":7123.92,"id":31379},{"batb":[[0,1.73,351.4],[1,1.71,45.43],[2,1.67,35]],"ltp":1.73,"tv":2300.84,"id":31377}]}]}
{"op":"mcm","clk":"11768392441","pt":1722712363185,"mc":[{"id":"1.231344876","rc":[{"batb":[[0,2.34,12],[1,2.32,30.6]],"ltp":2.34,"tv":7123.92,"id":31379},{"trd":[[1.73,1405.59]],"batb":[[0,1.71,45.43],[1,1.67,35],[2,1.65,62.14]],"ltp":1.73,"tv":3003.64,"id":31377}],"tv":10127.56}]}
{"op":"mcm","clk":"11768392652","pt":1722712364892,"mc":[{"id":"1.231344876","rc":[{"batb":[[0,2.34,10]],"ltp":2.34,"tv":7123.92,"id":31379}]}]}
{"op":"mcm","clk":"11768392776","pt":1722712365878,"mc":[{"id":"1.231344876","rc":[{"batb":[[0,2.32,30.6],[1,1.42,85.28],[2,1.3,633.33]],"ltp":2.34,"tv":7123.92,"id":31379}]}]}
{"op":"mcm","clk":"11768393304","pt":1722712369884,"mc":[{"id":"1.231344876","rc":[{"batb":[[0,2.34,12],[1,2.32,34.6],[2,1.42,85.28]],"ltp":2.34,"tv":7123.92,"id":31379}]}]}
{"op":"mcm","clk":"11768393608","pt":1722712372292,"mc":[{"id":"1.231344876","rc":[{"batb":[[0,2.34,10]],"ltp":2.34,"tv":7123.92,"id":31379}]}]}
{"op":"mcm","clk":"11768393737","pt":1722712373239,"mc":[{"id":"1.231344876","rc":[{"batb":[[0,2.32,34.6],[1,1.42,85.28],[2,1.3,633.33]],"ltp":2.34,"tv":7123.92,"id":31379}]}]}
{"op":"mcm","clk":"11768403093","pt":1722712378515,"mc":[{"id":"1.231344876","rc":[{"batb":[[0,2.34,12],[1,2.32,34.6],[2,1.42,85.28]],"ltp":2.34,"tv":7123.92,"id":31379},{"batb":[[0,1.73,351.4],[1,1.71,45.43],[2,1.67,35]],"ltp":1.73,"tv":3003.64,"id":31377}]}]}
{"op":"mcm","clk":"11768403170","pt":1722712378994,"mc":[{"id":"1.231344876","rc":[{"batb":[[1,2.32,30.6]],"ltp":2.34,"tv":7123.92,"id":31379},{"trd":[[1.73,2108.39]],"batb":[[0,1.71,45.43],[1,1.67,35],[2,1.65,62.14]],"ltp":1.73,"tv":3706.43,"id":31377}],"tv":10830.36}]}
{"op":"mcm","clk":"11768403399","pt":1722712380796,"mc":[{"id":"1.231344876","rc":[{"batb":[[0,2.34,10]],"ltp":2.34,"tv":7123.92,"id":31379}]}]}
{"op":"mcm","clk":"11768403545","pt":1722712381939,"mc":[{"id":"1.231344876","rc":[{"batb":[[0,2.32,30.6],[1,1.42,85.28],[2,1.3,633.33]],"ltp":2.34,"tv":7123.92,"id":31379}]}]}
{"op":"mcm","clk":"11768403956","pt":1722712385011,"mc":[{"id":"1.231344876","rc":[{"batb":[[0,2.34,12],[1,2.32,34.6],[2,1.42,85.28]],"ltp":2.34,"tv":7123.92,"id":31379}]}]}
{"op":"mcm","clk":"11768404265","pt":1722712387402,"mc":[{"id":"1.231344876","rc":[{"batb":[[0,2.34,10]],"ltp":2.34,"tv":7123.92,"id":31379}]}]}
{"op":"mcm","clk":"11768404356","pt":1722712388331,"mc":[{"id":"1.231344876","rc":[{"batb":[[0,2.32,34.6],[1,1.42,85.28],[2,1.3,633.33]],"ltp":2.34,"tv":7123.92,"id":31379}]}]}
{"op":"mcm","clk":"11768404856","pt":1722712392523,"mc":[{"id":"1.231344876","rc":[{"batb":[[0,2.34,12],[1,2.32,30.6],[2,1.42,85.28]],"ltp":2.34,"tv":7123.92,"id":31379},{"trd":[[1.73,2811.18]],"ltp":1.73,"tv":4409.23,"id":31377}],"tv":11533.15}]}
{"op":"mcm","clk":"11768405068","pt":1722712394210,"mc":[{"id":"1.231344876","rc":[{"batb":[[0,2.34,10]],"ltp":2.34,"tv":7123.92,"id":31379}]}]}
{"op":"mcm","clk":"11768405191","pt":1722712395209,"mc":[{"id":"1.231344876","rc":[{"batb":[[0,2.32,30.6],[1,1.42,85.28],[2,1.3,633.33]],"ltp":2.34,"tv":7123.92,"id":31379}]}]}
{"op":"mcm","clk":"11768405812","pt":1722712400035,"mc":[{"id":"1.231344876","rc":[{"batb":[[0,2.34,12],[1,2.32,34.6],[2,1.42,85.28]],"ltp":2.34,"tv":7123.92,"id":31379}]}]}
{"op":"mcm","clk":"11768406118","pt":1722712402522,"mc":[{"id":"1.231344876","rc":[{"batb":[[0,2.34,10]],"ltp":2.34,"tv":7123.92,"id":31379}]}]}
{"op":"mcm","clk":"11768406249","pt":1722712403430,"mc":[{"id":"1.231344876","rc":[{"batb":[[0,2.32,34.6],[1,1.42,85.28],[2,1.3,633.33]],"ltp":2.34,"tv":7123.92,"id":31379}]}]}
{"op":"mcm","clk":"11768407603","pt":1722712414485,"mc":[{"id":"1.231344876","rc":[{"batb":[[0,2.34,12],[1,2.32,34.6],[2,1.42,85.28]],"ltp":2.34,"tv":7123.92,"id":31379},{"batb":[[0,1.73,351.4],[1,1.71,45.43],[2,1.67,35]],"ltp":1.73,"tv":4409.23,"id":31377}]}]}
{"op":"mcm","clk":"11768407685","pt":1722712415173,"mc":[{"id":"1.231344876","rc":[{"batb":[[1,2.32,30.6]],"batl":[[0,2.36,4],[1,2.38,4],[2,4,1.09]],"ltp":2.34,"tv":7123.92,"id":31379},{"trd":[[1.73,3513.98]],"batb":[[0,1.74,4],[1,1.73,4],[2,1.71,45.43]],"ltp":1.73,"tv":5112.02,"id":31377}],"tv":12235.95}]}
{"op":"mcm","clk":"11768407987","pt":1722712417686,"mc":[{"id":"1.231344876","rc":[{"batb":[[0,2.34,10]],"batl":[[0,4,1.09],[1,8,1.09],[2,20,1.45]],"ltp":2.34,"tv":7123.92,"id":31379},{"batb":[[0,1.71,45.43],[1,1.67,35],[2,1.65,62.14]],"ltp":1.73,"tv":5112.02,"id":31377}]}]}
{"op":"mcm","clk":"11768408016","pt":1722712418002,"mc":[{"id":"1.231344876","rc":[{"batb":[[0,2.32,30.6],[1,1.42,85.28],[2,1.3,633.33]],"ltp":2.34,"tv":7123.92,"id":31379}]}]}
{"op":"mcm","clk":"11768409486","pt":1722712430598,"mc":[{"id":"1.231344876","rc":[{"batb":[[0,2.34,12],[1,2.32,34.6],[2,1.42,85.28]],"ltp":2.34,"tv":7123.92,"id":31379},{"batb":[[0,1.73,351.4],[1,1.71,45.43],[2,1.67,35]],"ltp":1.73,"tv":5112.02,"id":31377}]}]}
{"op":"mcm","clk":"11768409556","pt":1722712431117,"mc":[{"id":"1.231344876","rc":[{"batb":[[1,2.32,30.6]],"ltp":2.34,"tv":7123.92,"id":31379},{"trd":[[1.73,4216.77]],"batb":[[0,1.71,45.43],[1,1.67,35],[2,1.65,62.14]],"ltp":1.73,"tv":5814.82,"id":31377}],"tv":12938.74}]}
{"op":"mcm","clk":"11768409855","pt":1722712433633,"mc":[{"id":"1.231344876","rc":[{"batb":[[0,2.32,30.6],[1,1.42,85.28],[2,1.3,633.33]],"ltp":2.34,"tv":7123.92,"id":31379}]}]}
{"op":"mcm","clk":"11768410740","pt":1722712441126,"mc":[{"id":"1.231344876","rc":[{"batb":[[0,2.34,12],[1,2.32,30.6],[2,1.42,85.28]],"ltp":2.34,"tv":7123.92,"id":31379},{"batb":[[0,1.73,351.4],[1,1.71,45.43],[2,1.67,35]],"ltp":1.73,"tv":5814.82,"id":31377}]}]}
{"op":"mcm","clk":"11768410868","pt":1722712442130,"mc":[{"id":"1.231344876","rc":[{"trd":[[1.73,4919.57]],"batb":[[0,1.71,45.43],[1,1.67,35],[2,1.65,62.14]],"ltp":1.73,"tv":6517.61,"id":31377}],"tv":13641.54}]}
{"op":"mcm","clk":"11768411039","pt":1722712443410,"mc":[{"id":"1.231344876","rc":[{"batb":[[0,2.34,10]],"ltp":2.34,"tv":7123.92,"id":31379},{"batb":[[0,1.72,4.89],[1,1.71,45.43],[2,1.67,35]],"ltp":1.73,"tv":6517.61,"id":31377}]}]}
{"op":"mcm","clk":"11768411135","pt":1722712444238,"mc":[{"id":"1.231344876","rc":[{"batb":[[0,2.32,30.6],[1,1.42,85.28],[2,1.3,633.33]],"ltp":2.34,"tv":7123.92,"id":31379}]}]}
{"op":"mcm","clk":"11768411262","pt":1722712445244,"mc":[{"id":"1.231344876","rc":[{"batb":[[0,2.32,34.6]],"ltp":2.34,"tv":7123.92,"id":31379}]}]}
{"op":"mcm","clk":"11768412715","pt":1722712456363,"mc":[{"id":"1.231344876","rc":[{"batb":[[0,2.34,12],[1,2.32,34.6],[2,1.42,85.28]],"ltp":2.34,"tv":7123.92,"id":31379}]}]}
{"op":"mcm","clk":"11768413003","pt":1722712458668,"mc":[{"id":"1.231344876","rc":[{"batb":[[0,2.34,10]],"ltp":2.34,"tv":7123.92,"id":31379}]}]}
{"op":"mcm","clk":"11768413107","pt":1722712459475,"mc":[{"id":"1.231344876","rc":[{"batb":[[0,2.32,34.6],[1,1.42,85.28],[2,1.3,633.33]],"ltp":2.34,"tv":7123.92,"id":31379}]}]}
{"op":"mcm","clk":"11768413363","pt":1722712461544,"mc":[{"id":"1.231344876","rc":[{"batb":[[0,2.34,2],[1,2.32,34.6],[2,1.42,85.28]],"ltp":2.34,"tv":7123.92,"id":31379}]}]}
{"op":"mcm","clk":"11768413646","pt":1722712464055,"mc":[{"id":"1.231344876","rc":[{"batb":[[0,2.34,10]],"ltp":2.34,"tv":7123.92,"id":31379}]}]}
{"op":"mcm","clk":"11768414044","pt":1722712467379,"mc":[{"id":"1.231344876","rc":[{"batb":[[0,2.36,2]],"ltp":2.34,"tv":7123.92,"id":31379}]}]}
{"op":"mcm","clk":"11768414209","pt":1722712468861,"mc":[{"id":"1.231344876","rc":[{"trd":[[1.73,5622.36]],"ltp":1.73,"tv":7220.41,"id":31377}],"tv":14344.33}]}
{"op":"mcm","clk":"11768414337","pt":1722712469973,"mc":[{"id":"1.231344876","rc":[{"batb":[[0,2.34,10]],"ltp":2.34,"tv":7123.92,"id":31379}]}]}
{"op":"mcm","clk":"11768414731","pt":1722712473296,"mc":[{"id":"1.231344876","rc":[{"batb":[[0,2.34,2]],"ltp":2.34,"tv":7123.92,"id":31379}]}]}
{"op":"mcm","clk":"11768415028","pt":1722712475540,"mc":[{"id":"1.231344876","rc":[{"batb":[[0,2.34,4]],"batl":[[0,2.4,4],[1,4,1.09],[2,8,1.09]],"ltp":2.34,"tv":7123.92,"id":31379},{"batl":[[0,1.75,4],[1,1.76,4],[2,1.77,300]],"ltp":1.73,"tv":7220.41,"id":31377}]}]}
{"op":"mcm","clk":"11768415966","pt":1722712483448,"mc":[{"id":"1.231344876","rc":[{"batb":[[0,2.32,30.6],[1,1.42,85.28],[2,1.3,633.33]],"ltp":2.34,"tv":7123.92,"id":31379},{"batb":[[0,1.73,351.4],[1,1.72,4.89],[2,1.71,45.43]],"ltp":1.73,"tv":7220.41,"id":31377}]}]}
{"op":"mcm","clk":"11768416002","pt":1722712483730,"mc":[{"id":"1.231344876","rc":[{"trd":[[1.73,6325.16]],"batb":[[0,1.72,4.89],[1,1.71,45.43],[2,1.67,35]],"ltp":1.73,"tv":7923.21,"id":31377}],"tv":15047.13}]}
{"op":"mcm","clk":"11768416858","pt":1722712490657,"mc":[{"id":"1.231344876","rc":[{"batb":[[0,2.32,34.6]],"ltp":2.34,"tv":7123.92,"id":31379},{"batb":[[0,1.72,8.89]],"ltp":1.73,"tv":7923.21,"id":31377}]}]}
{"op":"mcm","clk":"11768416973","pt":1722712491560,"mc":[{"id":"1.231344876","rc":[{"batb":[[0,2.34,12],[1,2.32,34.6],[2,1.42,85.28]],"batl":[[0,4,1.09],[1,8,1.09],[2,20,1.45]],"ltp":2.34,"tv":7123.92,"id":31379},{"batb":[[0,1.72,4.89]],"ltp":1.73,"tv":7923.21,"id":31377}]}]}
{"op":"mcm","clk":"11768417213","pt":1722712493564,"mc":[{"id":"1.231344876","rc":[{"batb":[[0,2.34,10]],"ltp":2.34,"tv":7123.92,"id":31379}]}]}
{"op":"mcm","clk":"11768417323","pt":1722712494464,"mc":[{"id":"1.231344876","rc":[{"batb":[[0,2.32,34.6],[1,1.42,85.28],[2,1.3,633.33]],"ltp":2.34,"tv":7123.92,"id":31379}]}]}
{"op":"mcm","clk":"11768417937","pt":1722712499573,"mc":[{"id":"1.231344876","rc":[{"batb":[[0,2.34,12],[1,2.32,34.6],[2,1.42,85.28]],"ltp":2.34,"tv":7123.92,"id":31379},{"trd":[[1.73,7027.96]],"ltp":1.73,"tv":8626.0,"id":31377}],"tv":15749.93}]}
{"op":"mcm","clk":"11768417971","pt":1722712499842,"mc":[{"id":"1.231344876","rc":[{"batb":[[1,2.32,30.6]],"ltp":2.34,"tv":7123.92,"id":31379}]}]}
{"op":"mcm","clk":"11768418214","pt":1722712501567,"mc":[{"id":"1.231344876","rc":[{"batb":[[0,2.34,10]],"ltp":2.34,"tv":7123.92,"id":31379}]}]}
{"op":"mcm","clk":"11768418348","pt":1722712502573,"mc":[{"id":"1.231344876","rc":[{"batb":[[0,2.32,30.6],[1,1.42,85.28],[2,1.3,633.33]],"ltp":2.34,"tv":7123.92,"id":31379}]}]}
{"op":"mcm","clk":"11768418890","pt":1722712506259,"mc":[{"id":"1.231344876","rc":[{"batb":[[0,2.34,12],[1,2.32,30.6],[2,1.42,85.28]],"ltp":2.34,"tv":7123.92,"id":31379},{"batb":[[0,1.73,351.4],[1,1.72,4.89],[2,1.71,45.43]],"ltp":1.73,"tv":8626.0,"id":31377}]}]}
{"op":"mcm","clk":"11768419183","pt":1722712508374,"mc":[{"id":"1.231344876","rc":[{"batb":[[0,2.34,10],[1,1.42,85.28],[2,1.3,633.33]],"ltp":2.34,"tv":7123.92,"id":31379}]}]}
{"op":"mcm","clk":"11768419307","pt":1722712509266,"mc":[{"id":"1.231344876","rc":[{"batb":[[0,1.42,85.28],[1,1.3,633.33],[2,1.08,7.81]],"ltp":2.34,"tv":7123.92,"id":31379},{"trd":[[1.73,7730.75]],"batb":[[0,1.72,4.89],[1,1.71,45.43],[2,1.67,35]],"ltp":1.73,"tv":9328.8,"id":31377}],"tv":16452.72}]}
{"op":"mcm","clk":"11768419377","pt":1722712509787,"mc":[{"id":"1.231344876","rc":[{"batl":[[0,1.76,4],[1,1.77,300],[2,1.78,535.95]],"ltp":1.73,"tv":9328.8,"id":31377}]}]}
{"op":"mcm","clk":"11768419892","pt":1722712513275,"mc":[{"id":"1.231344876","rc":[{"batb":[[0,2.34,12],[1,2.32,30.6],[2,1.42,85.28]],"ltp":2.34,"tv":7123.92,"id":31379}]}]}
{"op":"mcm","clk":"11768420212","pt":1722712515794,"mc":[{"id":"1.231344876","rc":[{"batb":[[0,2.34,10]],"ltp":2.34,"tv":7123.92,"id":31379}]}]}
{"op":"mcm","clk":"11768420357","pt":1722712516777,"mc":[{"id":"1.231344876","rc":[{"batb":[[0,2.32,30.6],[1,1.42,85.28],[2,1.3,633.33]],"ltp":2.34,"tv":7123.92,"id":31379}]}]}
{"op":"mcm","clk":"11768420571","pt":1722712518511,"mc":[{"id":"1.231344876","rc":[{"batb":[[0,2.34,2],[1,2.32,30.6],[2,1.42,85.28]],"ltp":2.34,"tv":7123.92,"id":31379},{"batb":[[0,1.73,351.4],[1,1.72,4.89],[2,1.71,45.43]],"ltp":1.73,"tv":9328.8,"id":31377}]}]}
{"op":"mcm","clk":"11768420950","pt":1722712521276,"mc":[{"id":"1.231344876","rc":[{"batb":[[0,2.34,10]],"batl":[[0,2.36,4],[1,2.38,4],[2,4,1.09]],"ltp":2.34,"tv":7123.92,"id":31379},{"batb":[[0,1.74,4],[1,1.73,355.4],[2,1.72,4.89]],"batl":[[0,1.75,4],[1,1.76,4],[2,1.77,300]],"ltp":1.73,"tv":9328.8,"id":31377}]}]}
{"op":"mcm","clk":"11768421107","pt":1722712522498,"mc":[{"id":"1.231344876","rc":[{"trd":[[1.73,8425.55],[1.74,241]],"batb":[[0,1.73,8],[1,1.72,4.89],[2,1.71,45.43]],"ltp":1.73,"tv":10031.59,"id":31377}],"tv":17155.52}]}
{"op":"mcm","clk":"11768421206","pt":1722712523311,"mc":[{"id":"1.231344876","rc":[{"batb":[[0,2.36,2],[1,2.34,10]],"batl":[[0,4,1.09],[1,8,1.09],[2,20,1.45]],"ltp":2.34,"tv":7123.92,"id":31379},{"batb":[[0,1.73,4]],"ltp":1.73,"tv":10031.59,"id":31377}]}]}
{"op":"mcm","clk":"11768421372","pt":1722712524584,"mc":[{"id":"1.231344876","rc":[{"batb":[[1,1.42,85.28],[2,1.3,633.33]],"ltp":2.34,"tv":7123.92,"id":31379},{"batl":[[0,1.77,300],[1,1.78,535.95],[2,1.79,500]],"ltp":1.73,"tv":10031.59,"id":31377}]}]}
{"op":"mcm","clk":"11768421491","pt":1722712525520,"mc":[{"id":"1.231344876","rc":[{"batb":[[0,1.42,85.28],[1,1.3,633.33],[2,1.08,7.81]],"ltp":2.34,"tv":7123.92,"id":31379}]}]}
{"op":"mcm","clk":"11768421757","pt":1722712527481,"mc":[{"id":"1.231344876","rc":[{"batb":[[0,2.3,13.6],[1,1.43,10],[2,1.42,85.28]],"ltp":2.34,"tv":7123.92,"id":31379}]}]}
{"op":"mcm","clk":"11768421880","pt":1722712528323,"mc":[{"id":"1.231344876","rc":[{"batb":[[0,2.34,2],[1,2.32,30.6],[2,2.3,13.6]],"ltp":2.34,"tv":7123.92,"id":31379}]}]}
{"op":"mcm","clk":"11768422291","pt":1722712531412,"mc":[{"id":"1.231344876","rc":[{"batb":[[0,2.32,30.6],[1,2.3,13.6],[2,1.42,85.28]],"ltp":2.34,"tv":7123.92,"id":31379},{"trd":[[1.73,8433.55]],"batb":[[0,1.72,4.89],[1,1.71,45.43],[2,1.67,35]],"batl":[[0,1.77,300.69]],"ltp":1.73,"tv":10039.59,"id":31377}],"tv":17163.51}]}
{"op":"mcm","clk":"11768422560","pt":1722712533316,"mc":[{"id":"1.231344876","rc":[{"batb":[[0,2.34,12],[1,2.32,30.6],[2,2.3,13.6]],"ltp":2.34,"tv":7123.92,"id":31379},{"batl":[[0,1.77,300]],"ltp":1.73,"tv":10039.59,"id":31377}]}]}
{"op":"mcm","clk":"11768422728","pt":1722712534497,"mc":[{"id":"1.231344876","rc":[{"batb":[[2,1.42,85.28]],"ltp":2.34,"tv":7123.92,"id":31379}]}]}
{"op":"mcm","clk":"11768422851","pt":1722712535596,"mc":[{"id":"1.231344876","rc":[{"batb":[[0,2.34,10]],"ltp":2.34,"tv":7123.92,"id":31379}]}]}
{"op":"mcm","clk":"11768422973","pt":1722712536606,"mc":[{"id":"1.231344876","rc":[{"batb":[[0,2.34,4]],"ltp":2.34,"tv":7123.92,"id":31379},{"batl":[[0,1.75,4],[1,1.77,300],[2,1.78,535.95]],"ltp":1.73,"tv":10039.59,"id":31377}]}]}
{"op":"mcm","clk":"11768423290","pt":1722712539309,"mc":[{"id":"1.231344876","rc":[{"batb":[[0,2.36,12],[1,2.34,4],[2,2.32,30.6]],"ltp":2.34,"tv":7123.92,"id":31379},{"batb":[[0,1.73,351.4],[1,1.72,4.89],[2,1.71,45.43]],"ltp":1.73,"tv":10039.59,"id":31377}]}]}
{"op":"mcm","clk":"11768423375","pt":1722712539999,"mc":[{"id":"1.231344876","rc":[{"batb":[[1,2.32,30.6],[2,1.42,85.28]],"ltp":2.34,"tv":7123.92,"id":31379},{"batl":[[0,1.77,300],[1,1.78,535.95],[2,1.79,500]],"ltp":1.73,"tv":10039.59,"id":31377}]}]}
{"op":"mcm","clk":"11768423508","pt":1722712541209,"mc":[{"id":"1.231344876","rc":[{"trd":[[2.36,336.36]],"batb":[[0,2.32,30.6],[1,1.42,85.28],[2,1.3,633.33]],"batl":[[0,3,1.36],[1,6.6,1.09],[2,13,1]],"ltp":2.36,"tv":7147.93,"id":31379},{"batb":[[0,1.74,17.07],[1,1.73,356.25]],"ltp":1.73,"tv":10039.59,"id":31377}],"tv":17187.52}]}
{"op":"mcm","clk":"11768423868","pt":1722712544327,"mc":[{"id":"1.231344876","rc":[{"batb":[[0,2.34,12],[1,2.32,30.6],[2,1.42,85.28]],"ltp":2.36,"tv":7147.93,"id":31379},{"trd":[[1.73,9102.2],[1.74,275.14]],"batb":[[0,1.73,21.92],[1,1.71,45.43],[2,1.67,35]],"ltp":1.73,"tv":10742.39,"id":31377}],"tv":17890.32}]}
{"op":"mcm","clk":"11768423967","pt":1722712545223,"mc":[{"id":"1.231344876","rc":[{"batl":[[0,4,1.09],[1,8,1.09],[2,20,1.45]],"ltp":2.36,"tv":7147.93,"id":31379},{"batb":[[0,1.73,17.07]],"ltp":1.73,"tv":10742.39,"id":31377}]}]}
{"op":"mcm","clk":"11768424072","pt":1722712546223,"mc":[{"id":"1.231344876","rc":[{"batb":[[0,2.34,10]],"ltp":2.36,"tv":7147.93,"id":31379}]}]}
{"op":"mcm","clk":"11768424210","pt":1722712547441,"mc":[{"id":"1.231344876","rc":[{"batb":[[0,2.34,12.11]],"ltp":2.36,"tv":7147.93,"id":31379},{"batl":[[0,1.75,12.18],[1,1.77,300],[2,1.78,535.95]],"ltp":1.73,"tv":10742.39,"id":31377}]}]}
{"op":"mcm","clk":"11768424338","pt":1722712548400,"mc":[{"id":"1.231344876","rc":[{"batb":[[0,2.36,2],[1,2.34,12.11]],"ltp":2.36,"tv":7147.93,"id":31379}]}]}
{"op":"mcm","clk":"11768424467","pt":1722712549340,"mc":[{"id":"1.231344876","rc":[{"batb":[[1,1.42,85.28],[2,1.3,633.33]],"ltp":2.36,"tv":7147.93,"id":31379}]}]}
{"op":"mcm","clk":"11768424623","pt":1722712550610,"mc":[{"id":"1.231344876","rc":[{"batb":[[0,1.42,85.28],[1,1.3,633.33],[2,1.08,7.81]],"ltp":2.36,"tv":7147.93,"id":31379}]}]}
{"op":"mcm","clk":"11768424721","pt":1722712551552,"mc":[{"id":"1.231344876","rc":[{"batb":[[0,2.32,4],[1,1.43,10],[2,1.42,85.28]],"ltp":2.36,"tv":7147.93,"id":31379},{"batl":[[0,1.75,4],[1,1.76,14.73],[2,1.77,300]],"ltp":1.73,"tv":10742.39,"id":31377}]}]}
{"op":"mcm","clk":"11768424900","pt":1722712553337,"mc":[{"id":"1.231344876","rc":[{"batb":[[0,2.34,2],[1,2.32,34.6],[2,1.43,10]],"ltp":2.36,"tv":7147.93,"id":31379}]}]}
{"op":"mcm","clk":"11768425044","pt":1722712554432,"mc":[{"id":"1.231344876","rc":[{"batb":[[2,1.42,85.28]],"ltp":2.36,"tv":7147.93,"id":31379},{"batb":[[0,1.74,351.4],[1,1.73,17.07],[2,1.71,45.43]],"ltp":1.73,"tv":10742.39,"id":31377}]}]}
{"op":"mcm","clk":"11768425171","pt":1722712555639,"mc":[{"id":"1.231344876","rc":[{"batb":[[0,2.32,30.6],[1,1.42,85.28],[2,1.3,633.33]],"ltp":2.36,"tv":7147.93,"id":31379},{"batl":[[0,1.76,14.73],[1,1.77,300],[2,1.78,535.95]],"ltp":1.73,"tv":10742.39,"id":31377}]}]}
{"op":"mcm","clk":"11768425254","pt":1722712556332,"mc":[{"id":"1.231344876","rc":[{"batb":[[0,2.34,10],[1,2.32,30.6],[2,1.42,85.28]],"ltp":2.36,"tv":7147.93,"id":31379}]}]}
{"op":"mcm","clk":"11768425364","pt":1722712557332,"mc":[{"id":"1.231344876","rc":[{"trd":[[1.74,977.94]],"batb":[[0,1.73,17.07],[1,1.71,45.43],[2,1.67,35]],"ltp":1.74,"tv":11445.18,"id":31377}],"tv":18593.12}]}
{"op":"mcm","clk":"11768425506","pt":1722712558441,"mc":[{"id":"1.231344876","rc":[{"batb":[[0,2.36,2],[1,2.34,10]],"ltp":2.36,"tv":7147.93,"id":31379}]}]}
{"op":"mcm","clk":"11768425667","pt":1722712559732,"mc":[{"id":"1.231344876","rc":[{"batb":[[1,1.42,85.28],[2,1.3,633.33]],"ltp":2.36,"tv":7147.93,"id":31379}]}]}
{"op":"mcm","clk":"11768425788","pt":1722712560738,"mc":[{"id":"1.231344876","rc":[{"batb":[[0,1.42,85.28],[1,1.3,633.33],[2,1.08,7.81]],"ltp":2.36,"tv":7147.93,"id":31379}]}]}
{"op":"mcm","clk":"11768425991","pt":1722712562229,"mc":[{"id":"1.231344876","rc":[{"batb":[[0,1.43,10],[1,1.42,85.28],[2,1.3,633.33]],"ltp":2.36,"tv":7147.93,"id":31379}]}]}
{"op":"mcm","clk":"11768426168","pt":1722712563451,"mc":[{"id":"1.231344876","rc":[{"batb":[[0,2.34,2],[1,2.32,30.6],[2,1.43,10]],"ltp":2.36,"tv":7147.93,"id":31379}]}]}
{"op":"mcm","clk":"11768426257","pt":1722712564146,"mc":[{"id":"1.231344876","rc":[{"batb":[[0,1.74,351.4],[1,1.73,17.07],[2,1.71,45.43]],"ltp":1.74,"tv":11445.18,"id":31377}]}]}
{"op":"mcm","clk":"11768426409","pt":1722712565427,"mc":[{"id":"1.231344876","rc":[{"batb":[[2,1.42,85.28]],"ltp":2.36,"tv":7147.93,"id":31379}]}]}
{"op":"mcm","clk":"11768426516","pt":1722712566233,"mc":[{"id":"1.231344876","rc":[{"batb":[[0,2.32,30.6],[1,1.42,85.28],[2,1.3,633.33]],"batl":[[0,2.36,4],[1,4,1.09],[2,8,1.09]],"ltp":2.36,"tv":7147.93,"id":31379},{"batb":[[0,1.74,355.4]],"ltp":1.74,"tv":11445.18,"id":31377}]}]}
{"op":"mcm","clk":"11768426759","pt":1722712568330,"mc":[{"id":"1.231344876","rc":[{"batl":[[0,4,1.09],[1,8,1.09],[2,20,1.45]],"ltp":2.36,"tv":7147.93,"id":31379},{"trd":[[1.74,1680.73]],"batb":[[0,1.73,17.07],[1,1.71,45.43],[2,1.67,35]],"ltp":1.74,"tv":12147.98,"id":31377}],"tv":19295.91}]}
{"op":"mcm","clk":"11768426833","pt":1722712569024,"mc":[{"id":"1.231344876","rc":[{"batb":[[0,2.34,12],[1,2.32,30.6],[2,1.42,85.28]],"ltp":2.36,"tv":7147.93,"id":31379}]}]}
{"op":"mcm","clk":"11768427086","pt":1722712571144,"mc":[{"id":"1.231344876","rc":[{"batb":[[0,2.34,10]],"ltp":2.36,"tv":7147.93,"id":31379}]}]}
{"op":"mcm","clk":"11768427248","pt":1722712572327,"mc":[{"id":"1.231344876","rc":[{"batb":[[0,2.32,30.6],[1,1.42,85.28],[2,1.3,633.33]],"ltp":2.36,"tv":7147.93,"id":31379}]}]}
{"op":"mcm","clk":"11768427512","pt":1722712574168,"mc":[{"id":"1.231344876","rc":[{"batb":[[0,2.34,2],[1,2.32,30.6],[2,1.42,85.28]],"ltp":2.36,"tv":7147.93,"id":31379}]}]}
{"op":"mcm","clk":"11768427781","pt":1722712576662,"mc":[{"id":"1.231344876","rc":[{"batb":[[0,2.34,10]],"ltp":2.36,"tv":7147.93,"id":31379},{"batb":[[0,1.74,351.4],[1,1.73,17.07],[2,1.71,45.43]],"ltp":1.74,"tv":12147.98,"id":31377}]}]}
{"op":"mcm","clk":"11768427977","pt":1722712578350,"mc":[{"id":"1.231344876","rc":[{"batb":[[1,1.42,85.28],[2,1.3,633.33]],"ltp":2.36,"tv":7147.93,"id":31379}]}]}
{"op":"mcm","clk":"11768428236","pt":1722712580572,"mc":[{"id":"1.231344876","rc":[{"batb":[[0,2.3,12.32],[1,1.43,2],[2,1.42,85.28]],"ltp":2.36,"tv":7147.93,"id":31379},{"trd":[[1.74,2383.53]],"batb":[[0,1.73,17.07],[1,1.71,45.43],[2,1.67,35]],"ltp":1.74,"tv":12850.78,"id":31377}],"tv":19998.71}]}
{"op":"mcm","clk":"11768428331","pt":1722712581364,"mc":[{"id":"1.231344876","rc":[{"batb":[[0,2.3,16.32]],"ltp":2.36,"tv":7147.93,"id":31379},{"batl":[[0,1.76,18.73]],"ltp":1.74,"tv":12850.78,"id":31377}]}]}
{"op":"mcm","clk":"11768428436","pt":1722712582372,"mc":[{"id":"1.231344876","rc":[{"batb":[[0,2.32,10],[1,2.3,16.32]],"ltp":2.36,"tv":7147.93,"id":31379}]}]}
{"op":"mcm","clk":"11768428838","pt":1722712585546,"mc":[{"id":"1.231344876","rc":[{"batb":[[0,2.3,16.32],[1,1.42,85.28],[2,1.3,633.33]],"ltp":2.36,"tv":7147.93,"id":31379}]}]}
{"op":"mcm","clk":"11768428908","pt":1722712586174,"mc":[{"id":"1.231344876","rc":[{"batb":[[0,2.32,2],[1,2.3,16.32],[2,1.42,85.28]],"ltp":2.36,"tv":7147.93,"id":31379}]}]}
{"op":"mcm","clk":"11768429153","pt":1722712588387,"mc":[{"id":"1.231344876","rc":[{"batb":[[0,2.32,40.6]],"ltp":2.36,"tv":7147.93,"id":31379}]}]}
{"op":"mcm","clk":"11768429380","pt":1722712590179,"mc":[{"id":"1.231344876","rc":[{"batb":[[0,2.34,2],[1,2.32,40.6],[2,2.3,4]],"ltp":2.36,"tv":7147.93,"id":31379}]}]}
{"op":"mcm","clk":"11768429645","pt":1722712592686,"mc":[{"id":"1.231344876","rc":[{"batb":[[0,2.32,30.6],[1,2.3,4],[2,1.42,85.28]],"ltp":2.36,"tv":7147.93,"id":31379}]}]}
{"op":"mcm","clk":"11768430092","pt":1722712596592,"mc":[{"id":"1.231344876","rc":[{"batb":[[0,2.34,12],[1,2.32,34.6],[2,2.3,4]],"ltp":2.36,"tv":7147.93,"id":31379}]}]}
{"op":"mcm","clk":"11768430195","pt":1722712597600,"mc":[{"id":"1.231344876","rc":[{"batb":[[1,2.32,30.6],[2,1.42,85.28]],"ltp":2.36,"tv":7147.93,"id":31379},{"batb":[[0,1.74,351.4],[1,1.73,17.07],[2,1.71,45.43]],"ltp":1.74,"tv":12850.78,"id":31377}]}]}
{"op":"mcm","clk":"11768430310","pt":1722712598496,"mc":[{"id":"1.231344876","rc":[{"batb":[[1,1.42,85.28],[2,1.3,633.33]],"ltp":2.36,"tv":7147.93,"id":31379},{"trd":[[1.74,3086.32]],"batb":[[0,1.73,17.07],[1,1.71,45.43],[2,1.67,35]],"ltp":1.74,"tv":13553.57,"id":31377}],"tv":20701.5}]}
{"op":"mcm","clk":"11768430349","pt":1722712598804,"mc":[{"id":"1.231344876","rc":[{"batb":[[0,2.34,10]],"ltp":2.36,"tv":7147.93,"id":31379}]}]}
{"op":"mcm","clk":"11768430516","pt":1722712599985,"mc":[{"id":"1.231344876","rc":[{"batb":[[0,1.42,85.28],[1,1.3,633.33],[2,1.08,7.81]],"ltp":2.36,"tv":7147.93,"id":31379}]}]}
{"op":"mcm","clk":"11768430919","pt":1722712603501,"mc":[{"id":"1.231344876","rc":[{"batb":[[0,2.32,30.6],[1,1.42,85.28],[2,1.3,633.33]],"ltp":2.36,"tv":7147.93,"id":31379}]}]}
{"op":"mcm","clk":"11768430944","pt":1722712603710,"mc":[{"id":"1.231344876","rc":[{"batb":[[0,2.34,12],[1,2.32,30.6],[2,1.42,85.28]],"ltp":2.36,"tv":7147.93,"id":31379}]}]}
{"op":"mcm","clk":"11768431209","pt":1722712605921,"mc":[{"id":"1.231344876","rc":[{"batb":[[0,2.34,10]],"ltp":2.36,"tv":7147.93,"id":31379}]}]}
{"op":"mcm","clk":"11768431337","pt":1722712607099,"mc":[{"id":"1.231344876","rc":[{"batb":[[0,2.32,30.6],[1,1.42,85.28],[2,1.3,633.33]],"ltp":2.36,"tv":7147.93,"id":31379}]}]}
{"op":"mcm","clk":"11768431881","pt":1722712611621,"mc":[{"id":"1.231344876","rc":[{"batb":[[0,2.32,34.6]],"ltp":2.36,"tv":7147.93,"id":31379},{"batb":[[0,1.74,351.4],[1,1.73,17.07],[2,1.71,45.43]],"ltp":1.74,"tv":13553.57,"id":31377}]}]}
{"op":"mcm","clk":"11768431937","pt":1722712612108,"mc":[{"id":"1.231344876","rc":[{"batb":[[0,2.34,12],[1,2.32,34.6],[2,1.42,85.28]],"ltp":2.36,"tv":7147.93,"id":31379},{"trd":[[1.74,3789.12]],"batb":[[0,1.73,17.07],[1,1.71,45.43],[2,1.67,35]],"ltp":1.74,"tv":14256.37,"id":31377}],"tv":21404.3}]}
{"op":"mcm","clk":"11768432092","pt":1722712613514,"mc":[{"id":"1.231344876","rc":[{"batb":[[1,2.32,4]],"ltp":2.36,"tv":7147.93,"id":31379}]}]}
{"op":"mcm","clk":"11768432152","pt":1722712613999,"mc":[{"id":"1.231344876","rc":[{"batb":[[0,2.34,10]],"ltp":2.36,"tv":7147.93,"id":31379}]}]}
{"op":"mcm","clk":"11768432257","pt":1722712614999,"mc":[{"id":"1.231344876","rc":[{"batb":[[0,2.32,16.21],[1,1.42,85.28],[2,1.3,633.33]],"ltp":2.36,"tv":7147.93,"id":31379}]}]}
{"op":"mcm","clk":"11768433008","pt":1722712622319,"mc":[{"id":"1.231344876","rc":[{"batb":[[0,2.34,12],[1,2.32,16.21],[2,1.42,85.28]],"ltp":2.36,"tv":7147.93,"id":31379},{"batb":[[0,1.74,351.4],[1,1.73,17.07],[2,1.71,45.43]],"ltp":1.74,"tv":14256.37,"id":31377}]}]}
{"op":"mcm","clk":"11768433055","pt":1722712622720,"mc":[{"id":"1.231344876","rc":[{"batb":[[1,2.32,12.21]],"ltp":2.36,"tv":7147.93,"id":31379}]}]}
{"op":"mcm","clk":"11768433254","pt":1722712624529,"mc":[{"id":"1.231344876","rc":[{"batb":[[0,2.34,10]],"ltp":2.36,"tv":7147.93,"id":31379}]}]}
{"op":"mcm","clk":"11768433356","pt":1722712625636,"mc":[{"id":"1.231344876","rc":[{"batb":[[0,2.32,12.21],[1,1.42,85.28],[2,1.3,633.33]],"ltp":2.36,"tv":7147.93,"id":31379},{"trd":[[1.74,4491.91]],"batb":[[0,1.73,17.07],[1,1.71,45.43],[2,1.67,35]],"ltp":1.74,"tv":14959.16,"id":31377}],"tv":22107.09}]}
{"op":"mcm","clk":"11768433467","pt":1722712626641,"mc":[{"id":"1.231344876","rc":[{"batb":[[0,2.32,4]],"ltp":2.36,"tv":7147.93,"id":31379}]}]}
{"op":"mcm","clk":"11768433487","pt":1722712626810,"mc":[{"id":"1.231344876","rc":[{"batb":[[0,2.34,2],[1,2.32,4],[2,1.42,85.28]],"ltp":2.36,"tv":7147.93,"id":31379}]}]}
{"op":"mcm","clk":"11768433761","pt":1722712629222,"mc":[{"id":"1.231344876","rc":[{"batb":[[0,2.34,10]],"ltp":2.36,"tv":7147.93,"id":31379}]}]}
{"op":"mcm","clk":"11768434159","pt":1722712632645,"mc":[{"id":"1.231344876","rc":[{"batb":[[0,1.43,2],[1,1.42,85.28],[2,1.3,633.33]],"ltp":2.36,"tv":7147.93,"id":31379},{"batb":[[0,1.74,351.4],[1,1.73,17.07],[2,1.71,45.43]],"ltp":1.74,"tv":14959.16,"id":31377}]}]}
{"op":"mcm","clk":"11768434256","pt":1722712633537,"mc":[{"id":"1.231344876","rc":[{"batb":[[0,2.32,30.6],[1,1.43,2],[2,1.42,85.28]],"ltp":2.36,"tv":7147.93,"id":31379}]}]}
{"op":"mcm","clk":"11768434429","pt":1722712634978,"mc":[{"id":"1.231344876","rc":[{"batb":[[0,2.34,10],[1,2.32,30.6]],"ltp":2.36,"tv":7147.93,"id":31379}]}]}
{"op":"mcm","clk":"11768434531","pt":1722712635818,"mc":[{"id":"1.231344876","rc":[{"trd":[[1.74,5194.71]],"batb":[[0,1.73,17.07],[1,1.71,45.43],[2,1.67,35]],"ltp":1.74,"tv":15661.96,"id":31377}],"tv":22809.89}]}
{"op":"mcm","clk":"11768434845","pt":1722712638327,"mc":[{"id":"1.231344876","rc":[{"batb":[[0,2.34,2]],"ltp":2.36,"tv":7147.93,"id":31379}]}]}
{"op":"mcm","clk":"11768435288","pt":1722712641533,"mc":[{"id":"1.231344876","rc":[{"batb":[[0,2.34,10]],"ltp":2.36,"tv":7147.93,"id":31379},{"batb":[[0,1.74,351.4],[1,1.73,17.07],[2,1.71,45.43]],"ltp":1.74,"tv":15661.96,"id":31377}]}]}
{"op":"mcm","clk":"11768435381","pt":1722712642243,"mc":[{"id":"1.231344876","rc":[{"batl":[[0,2.38,4],[1,4,1.09],[2,8,1.09]],"ltp":2.36,"tv":7147.93,"id":31379},{"batb":[[1,1.73,21.07]],"ltp":1.74,"tv":15661.96,"id":31377}]}]}
{"op":"mcm","clk":"11768435546","pt":1722712643639,"mc":[{"id":"1.231344876","rc":[{"batb":[[1,1.42,85.28],[2,1.3,633.33]],"ltp":2.36,"tv":7147.93,"id":31379}]}]}
{"op":"mcm","clk":"11768435667","pt":1722712644551,"mc":[{"id":"1.231344876","rc":[{"batb":[[0,1.42,85.28],[1,1.3,633.33],[2,1.08,7.81]],"ltp":2.36,"tv":7147.93,"id":31379}]}]}
{"op":"mcm","clk":"11768435796","pt":1722712645540,"mc":[{"id":"1.231344876","rc":[{"trd":[[1.74,5897.51]],"batb":[[0,1.73,17.07],[1,1.71,45.43],[2,1.67,35]],"ltp":1.74,"tv":16364.75,"id":31377}],"tv":23512.69}]}
{"op":"mcm","clk":"11768435900","pt":1722712646358,"mc":[{"id":"1.231344876","rc":[{"batb":[[0,2.3,13.44],[1,1.42,85.28],[2,1.3,633.33]],"ltp":2.36,"tv":7147.93,"id":31379}]}]}
{"op":"mcm","clk":"11768436188","pt":1722712648663,"mc":[{"id":"1.231344876","rc":[{"batb":[[0,2.32,30.6],[1,2.3,13.44],[2,1.42,85.28]],"ltp":2.36,"tv":7147.93,"id":31379}]}]}
{"op":"mcm","clk":"11768436343","pt":1722712649668,"mc":[{"id":"1.231344876","rc":[{"batb":[[0,2.34,12],[1,2.32,30.6]],"batl":[[0,4,1.09],[1,8,1.09],[2,20,1.45]],"ltp":2.36,"tv":7147.93,"id":31379}]}]}
{"op":"mcm","clk":"11768436579","pt":1722712651648,"mc":[{"id":"1.231344876","rc":[{"batb":[[0,2.34,10]],"ltp":2.36,"tv":7147.93,"id":31379}]}]}
{"op":"mcm","clk":"11768436693","pt":1722712652540,"mc":[{"id":"1.231344876","rc":[{"batb":[[0,2.32,30.6],[1,1.42,85.28],[2,1.3,633.33]],"ltp":2.36,"tv":7147.93,"id":31379}]}]}
{"op":"mcm","clk":"11768436728","pt":1722712652856,"mc":[{"id":"1.231344876","rc":[{"batb":[[0,1.74,351.4],[1,1.73,17.07],[2,1.71,45.43]],"ltp":1.74,"tv":16364.75,"id":31377}]}]}
{"op":"mcm","clk":"11768437180","pt":1722712656384,"mc":[{"id":"1.231344876","rc":[{"batb":[[0,2.34,12],[1,2.32,30.6],[2,1.42,85.28]],"ltp":2.36,"tv":7147.93,"id":31379},{"trd":[[1.74,6600.3]],"batb":[[0,1.73,17.07],[1,1.71,45.43],[2,1.67,35]],"ltp":1.74,"tv":17067.55,"id":31377}],"tv":24215.48}]}
{"op":"mcm","clk":"11768437247","pt":1722712656860,"mc":[{"id":"1.231344876","rc":[{"batb":[[1,2.32,34.6]],"ltp":2.36,"tv":7147.93,"id":31379}]}]}
{"op":"mcm","clk":"11768437457","pt":1722712658768,"mc":[{"id":"1.231344876","rc":[{"batb":[[0,2.34,10],[1,2.32,4]],"ltp":2.36,"tv":7147.93,"id":31379}]}]}
{"op":"mcm","clk":"11768437590","pt":1722712659745,"mc":[{"id":"1.231344876","rc":[{"batb":[[0,2.32,4],[1,1.42,85.28],[2,1.3,633.33]],"ltp":2.36,"tv":7147.93,"id":31379}]}]}
{"op":"mcm","clk":"11768438019","pt":1722712663695,"mc":[{"id":"1.231344876","rc":[{"batb":[[0,2.32,34.6]],"ltp":2.36,"tv":7147.93,"id":31379}]}]}
{"op":"mcm","clk":"11768438075","pt":1722712664171,"mc":[{"id":"1.231344876","rc":[{"batb":[[0,2.34,24.11],[1,2.32,34.6],[2,1.42,85.28]],"ltp":2.36,"tv":7147.93,"id":31379}]}]}
{"op":"mcm","clk":"11768438332","pt":1722712666352,"mc":[{"id":"1.231344876","rc":[{"batb":[[0,2.34,22.11]],"ltp":2.36,"tv":7147.93,"id":31379},{"batl":[[0,1.74,12.25],[1,1.76,4],[2,1.77,300]],"ltp":1.74,"tv":17067.55,"id":31377}]}]}
{"op":"mcm","clk":"11768438446","pt":1722712667486,"mc":[{"id":"1.231344876","rc":[{"batb":[[0,2.34,12.11]],"ltp":2.36,"tv":7147.93,"id":31379},{"trd":[[1.74,6624.79]],"batb":[[0,1.74,339.15],[1,1.73,17.07],[2,1.71,45.43]],"batl":[[0,1.76,4],[1,1.77,300],[2,1.78,535.95]],"ltp":1.74,"tv":17092.04,"id":31377}],"tv":24239.97}]}
{"op":"mcm","clk":"11768438570","pt":1722712668494,"mc":[{"id":"1.231344876","rc":[{"batb":[[0,2.36,2],[1,2.34,12.11],[2,2.32,30.6]],"ltp":2.36,"tv":7147.93,"id":31379},{"trd":[[1.73,9126.69],[1.74,7303.1]],"batb":[[0,1.73,4.83],[1,1.71,45.43],[2,1.67,35]],"ltp":1.73,"tv":17794.83,"id":31377}],"tv":24942.77}]}
{"op":"mcm","clk":"11768438871","pt":1722712670986,"mc":[{"id":"1.231344876","rc":[{"batb":[[0,2.36,10]],"ltp":2.36,"tv":7147.93,"id":31379}]}]}
{"op":"mcm","clk":"11768438983","pt":1722712672092,"mc":[{"id":"1.231344876","rc":[{"batb":[[0,2.36,14]],"ltp":2.36,"tv":7147.93,"id":31379},{"batl":[[0,1.74,4],[1,1.76,4],[2,1.77,300]],"ltp":1.73,"tv":17794.83,"id":31377}]}]}
{"op":"mcm","clk":"11768439215","pt":1722712674198,"mc":[{"id":"1.231344876","rc":[{"batb":[[0,2.36,4],[1,1.42,85.28],[2,1.3,633.33]],"ltp":2.36,"tv":7147.93,"id":31379}]}]}
{"op":"mcm","clk":"11768439330","pt":1722712675091,"mc":[{"id":"1.231344876","rc":[{"batb":[[0,1.43,2]],"ltp":2.36,"tv":7147.93,"id":31379},{"batl":[[0,1.76,4],[1,1.77,300],[2,1.78,535.95]],"ltp":1.73,"tv":17794.83,"id":31377}]}]}
{"op":"mcm","clk":"11768439472","pt":1722712676293,"mc":[{"id":"1.231344876","rc":[{"batl":[[0,1.76,18.84]],"ltp":1.73,"tv":17794.83,"id":31377}]}]}
{"op":"mcm","clk":"11768439589","pt":1722712677501,"mc":[{"id":"1.231344876","rc":[{"batb":[[0,1.43,10]],"ltp":2.36,"tv":7147.93,"id":31379}]}]}
{"op":"mcm","clk":"11768439736","pt":1722712678776,"mc":[{"id":"1.231344876","rc":[{"batb":[[0,2.32,30.6],[1,1.43,10],[2,1.42,85.28]],"ltp":2.36,"tv":7147.93,"id":31379}]}]}
{"op":"mcm","clk":"11768440013","pt":1722712681087,"mc":[{"id":"1.231344876","rc":[{"batb":[[0,2.34,2],[1,2.32,30.6]],"ltp":2.36,"tv":7147.93,"id":31379}]}]}
{"op":"mcm","clk":"11768440283","pt":1722712683585,"mc":[{"id":"1.231344876","rc":[{"batb":[[0,2.34,10]],"ltp":2.36,"tv":7147.93,"id":31379}]}]}
{"op":"mcm","clk":"11768440689","pt":1722712687113,"mc":[{"id":"1.231344876","rc":[{"batb":[[0,2.34,6]],"ltp":2.36,"tv":7147.93,"id":31379},{"batl":[[0,1.75,4],[1,1.76,18.84],[2,1.77,300]],"ltp":1.73,"tv":17794.83,"id":31377}]}]}
{"op":"mcm","clk":"11768440933","pt":1722712689396,"mc":[{"id":"1.231344876","rc":[{"batb":[[0,2.36,10],[1,2.34,4],[2,2.32,30.6]],"ltp":2.36,"tv":7147.93,"id":31379}]}]}
{"op":"mcm","clk":"11768441104","pt":1722712690890,"mc":[{"id":"1.231344876","rc":[{"batl":[[1,1.76,4]],"ltp":1.73,"tv":17794.83,"id":31377}]}]}
{"op":"mcm","clk":"11768441322","pt":1722712692801,"mc":[{"id":"1.231344876","rc":[{"batb":[[0,2.36,2]],"ltp":2.36,"tv":7147.93,"id":31379}]}]}
{"op":"mcm","clk":"11768441605","pt":1722712695211,"mc":[{"id":"1.231344876","rc":[{"batb":[[0,2.36,10]],"ltp":2.36,"tv":7147.93,"id":31379}]}]}
{"op":"mcm","clk":"11768441975","pt":1722712698618,"mc":[{"id":"1.231344876","rc":[{"batb":[[0,2.36,2]],"ltp":2.36,"tv":7147.93,"id":31379}]}]}
{"op":"mcm","clk":"11768442250","pt":1722712700902,"mc":[{"id":"1.231344876","rc":[{"batb":[[0,2.36,10]],"ltp":2.36,"tv":7147.93,"id":31379}]}]}
{"op":"mcm","clk":"11768442403","pt":1722712702214,"mc":[{"id":"1.231344876","rc":[{"batb":[[0,2.36,14]],"ltp":2.36,"tv":7147.93,"id":31379},{"batl":[[0,1.74,4],[1,1.75,4],[2,1.76,4]],"ltp":1.73,"tv":17794.83,"id":31377}]}]}
{"op":"mcm","clk":"11768442668","pt":1722712704609,"mc":[{"id":"1.231344876","rc":[{"batb":[[0,1.42,85.28],[1,1.3,633.33],[2,1.08,7.81]],"ltp":2.36,"tv":7147.93,"id":31379},{"batl":[[0,1.77,300],[1,1.78,535.95],[2,1.79,500]],"ltp":1.73,"tv":17794.83,"id":31377}]}]}
{"op":"mcm","clk":"11768442695","pt":1722712704818,"mc":[{"id":"1.231344876","rc":[{"batb":[[0,2.3,12.32],[1,1.43,2],[2,1.42,85.28]],"ltp":2.36,"tv":7147.93,"id":31379}]}]}
{"op":"mcm","clk":"11768442955","pt":1722712707130,"mc":[{"id":"1.231344876","rc":[{"batb":[[0,2.32,10],[1,2.3,12.32]],"ltp":2.36,"tv":7147.93,"id":31379}]}]}
{"op":"mcm","clk":"11768443160","pt":1722712709129,"mc":[{"id":"1.231344876","rc":[{"batb":[[0,2.34,2],[1,2.32,40.6],[2,2.3,12.32]],"ltp":2.36,"tv":7147.93,"id":31379}]}]}
{"op":"mcm","clk":"11768443294","pt":1722712710312,"mc":[{"id":"1.231344876","rc":[{"batb":[[1,2.32,30.6]],"ltp":2.36,"tv":7147.93,"id":31379}]}]}
{"op":"mcm","clk":"11768443450","pt":1722712711622,"mc":[{"id":"1.231344876","rc":[{"batb":[[0,2.32,30.6],[1,2.3,12.32],[2,1.42,85.28]],"ltp":2.36,"tv":7147.93,"id":31379}]}]}
{"op":"mcm","clk":"11768443463","pt":1722712711721,"mc":[{"id":"1.231344876","rc":[{"batb":[[1,1.42,85.28],[2,1.3,633.33]],"ltp":2.36,"tv":7147.93,"id":31379}]}]}
{"op":"mcm","clk":"11768444111","pt":1722712717535,"mc":[{"id":"1.231344876","rc":[{"batb":[[0,2.34,12],[1,2.32,34.6],[2,1.42,85.28]],"ltp":2.36,"tv":7147.93,"id":31379},{"batl":[[0,1.76,4],[1,1.77,300],[2,1.78,535.95]],"ltp":1.73,"tv":17794.83,"id":31377}]}]}
{"op":"mcm","clk":"11768444362","pt":1722712719952,"mc":[{"id":"1.231344876","rc":[{"batb":[[0,2.34,10]],"ltp":2.36,"tv":7147.93,"id":31379}]}]}
{"op":"mcm","clk":"11768444470","pt":1722712720920,"mc":[{"id":"1.231344876","rc":[{"batb":[[0,2.32,34.6],[1,1.42,85.28],[2,1.3,633.33]],"ltp":2.36,"tv":7147.93,"id":31379}]}]}
{"op":"mcm","clk":"11768444775","pt":1722712723633,"mc":[{"id":"1.231344876","rc":[{"batb":[[0,2.34,12],[1,2.32,30.6],[2,1.42,85.28]],"ltp":2.36,"tv":7147.93,"id":31379},{"batb":[[0,1.74,351.4],[1,1.73,4.83],[2,1.71,45.43]],"ltp":1.73,"tv":17794.83,"id":31377}]}]}
{"op":"mcm","clk":"11768444798","pt":1722712723841,"mc":[{"id":"1.231344876","rc":[{"trd":[[1.74,8005.89]],"batb":[[0,1.73,4.83],[1,1.71,45.43],[2,1.67,35]],"ltp":1.74,"tv":18497.63,"id":31377}],"tv":25645.56}]}
{"op":"mcm","clk":"11768444957","pt":1722712725350,"mc":[{"id":"1.231344876","rc":[{"batb":[[0,2.34,10]],"ltp":2.36,"tv":7147.93,"id":31379}]}]}
{"op":"mcm","clk":"11768445072","pt":1722712726536,"mc":[{"id":"1.231344876","rc":[{"batb":[[0,2.32,30.6],[1,1.42,85.28],[2,1.3,633.33]],"ltp":2.36,"tv":7147.93,"id":31379}]}]}
{"op":"mcm","clk":"11768445685","pt":1722712732558,"mc":[{"id":"1.231344876","rc":[{"batb":[[0,2.34,12],[1,2.32,34.6],[2,1.42,85.28]],"ltp":2.36,"tv":7147.93,"id":31379}]}]}
{"op":"mcm","clk":"11768445899","pt":1722712734845,"mc":[{"id":"1.231344876","rc":[{"batb":[[0,2.34,10]],"ltp":2.36,"tv":7147.93,"id":31379}]}]}
{"op":"mcm","clk":"11768446000","pt":1722712735851,"mc":[{"id":"1.231344876","rc":[{"batb":[[0,2.32,34.6],[1,1.42,85.28],[2,1.3,633.33]],"ltp":2.36,"tv":7147.93,"id":31379}]}]}
{"op":"mcm","clk":"11768446752","pt":1722712743650,"mc":[{"id":"1.231344876","rc":[{"batl":[[0,1.74,351.4],[1,1.76,4],[2,1.77,300]],"ltp":1.74,"tv":18497.63,"id":31377}]}]}
{"op":"mcm","clk":"11768446763","pt":1722712743751,"mc":[{"id":"1.231344876","rc":[{"batb":[[0,2.34,12],[1,2.32,34.6],[2,1.42,85.28]],"ltp":2.36,"tv":7147.93,"id":31379}]}]}
{"op":"mcm","clk":"11768446930","pt":1722712745459,"mc":[{"id":"1.231344876","rc":[{"batb":[[0,2.36,12.01],[1,2.34,12],[2,2.32,34.6]],"ltp":2.36,"tv":7147.93,"id":31379}]}]}
{"op":"mcm","clk":"11768446998","pt":1722712746085,"mc":[{"id":"1.231344876","rc":[{"batb":[[1,2.34,10]],"ltp":2.36,"tv":7147.93,"id":31379},{"trd":[[1.74,8708.69]],"batl":[[0,1.76,4],[1,1.77,300],[2,1.78,535.95]],"ltp":1.74,"tv":19200.43,"id":31377}],"tv":26348.36}]}
{"op":"mcm","clk":"11768447203","pt":1722712747582,"mc":[{"id":"1.231344876","rc":[{"batb":[[0,2.36,16.01],[1,2.32,34.6],[2,1.42,85.28]],"ltp":2.36,"tv":7147.93,"id":31379},{"batl":[[0,1.74,4],[1,1.76,4],[2,1.77,300]],"ltp":1.74,"tv":19200.43,"id":31377}]}]}
{"op":"mcm","clk":"11768447278","pt":1722712748242,"mc":[{"id":"1.231344876","rc":[{"batb":[[0,2.36,4]],"ltp":2.36,"tv":7147.93,"id":31379}]}]}
{"op":"mcm","clk":"11768447363","pt":1722712749067,"mc":[{"id":"1.231344876","rc":[{"batb":[[0,2.34,12]],"ltp":2.36,"tv":7147.93,"id":31379},{"batl":[[0,1.76,4],[1,1.77,300],[2,1.78,535.95]],"ltp":1.74,"tv":19200.43,"id":31377}]}]}
{"op":"mcm","clk":"11768447641","pt":1722712751348,"mc":[{"id":"1.231344876","rc":[{"batb":[[0,2.34,10]],"ltp":2.36,"tv":7147.93,"id":31379}]}]}
{"op":"mcm","clk":"11768447724","pt":1722712752279,"mc":[{"id":"1.231344876","rc":[{"batb":[[0,2.32,34.6],[1,1.42,85.28],[2,1.3,633.33]],"ltp":2.36,"tv":7147.93,"id":31379}]}]}
{"op":"mcm","clk":"11768449155","pt":1722712765383,"mc":[{"id":"1.231344876","rc":[{"batb":[[0,2.34,12],[1,2.32,30.6],[2,1.42,85.28]],"ltp":2.36,"tv":7147.93,"id":31379},{"trd":[[1.74,9411.49]],"ltp":1.74,"tv":19903.22,"id":31377}],"tv":27051.15}]}
{"op":"mcm","clk":"11768449316","pt":1722712767001,"mc":[{"id":"1.231344876","rc":[{"batb":[[0,2.34,10]],"ltp":2.36,"tv":7147.93,"id":31379}]}]}
{"op":"mcm","clk":"11768449423","pt":1722712768182,"mc":[{"id":"1.231344876","rc":[{"batb":[[0,2.32,30.6],[1,1.42,85.28],[2,1.3,633.33]],"ltp":2.36,"tv":7147.93,"id":31379}]}]}
{"op":"mcm","clk":"11768450464","pt":1722712777690,"mc":[{"id":"1.231344876","rc":[{"batb":[[0,2.32,34.6]],"ltp":2.36,"tv":7147.93,"id":31379}]}]}
{"op":"mcm","clk":"11768450486","pt":1722712777895,"mc":[{"id":"1.231344876","rc":[{"batb":[[0,2.34,12],[1,2.32,34.6],[2,1.42,85.28]],"ltp":2.36,"tv":7147.93,"id":31379}]}]}
{"op":"mcm","clk":"11768450741","pt":1722712780305,"mc":[{"id":"1.231344876","rc":[{"batb":[[0,2.34,22.11]],"ltp":2.36,"tv":7147.93,"id":31379},{"batb":[[0,1.74,351.4],[1,1.73,4.83],[2,1.71,45.43]],"ltp":1.74,"tv":19903.22,"id":31377}]}]}
{"op":"mcm","clk":"11768450847","pt":1722712781284,"mc":[{"id":"1.231344876","rc":[{"batb":[[0,2.34,12.11]],"ltp":2.36,"tv":7147.93,"id":31379},{"trd":[[1.74,10114.28]],"batb":[[0,1.73,4.83],[1,1.71,45.43],[2,1.67,35]],"ltp":1.74,"tv":20606.02,"id":31377}],"tv":27753.95}]}
{"op":"mcm","clk":"11768452135","pt":1722712793000,"mc":[{"id":"1.231344876","rc":[{"batb":[[0,2.36,12],[1,2.34,16.11],[2,2.32,34.6]],"ltp":2.36,"tv":7147.93,"id":31379},{"batl":[[0,1.75,4],[1,1.76,4],[2,1.77,300]],"ltp":1.74,"tv":20606.02,"id":31377}]}]}
{"op":"mcm","clk":"11768452304","pt":1722712794620,"mc":[{"id":"1.231344876","rc":[{"batb":[[1,2.34,4],[2,2.32,4]],"ltp":2.36,"tv":7147.93,"id":31379}]}]}
{"op":"mcm","clk":"11768452395","pt":1722712795418,"mc":[{"id":"1.231344876","rc":[{"batb":[[0,2.36,10],[2,2.32,16.21]],"ltp":2.36,"tv":7147.93,"id":31379}]}]}
{"op":"mcm","clk":"11768452569","pt":1722712796759,"mc":[{"id":"1.231344876","rc":[{"batb":[[0,2.34,4],[1,2.32,16.21],[2,1.42,85.28]],"ltp":2.36,"tv":7147.93,"id":31379}]}]}
{"op":"mcm","clk":"11768452867","pt":1722712799333,"mc":[{"id":"1.231344876","rc":[{"batb":[[0,2.36,12],[1,2.34,4],[2,2.32,46.81]],"ltp":2.36,"tv":7147.93,"id":31379}]}]}
{"op":"mcm","clk":"11768453121","pt":1722712801546,"mc":[{"id":"1.231344876","rc":[{"batb":[[0,2.36,10]],"ltp":2.36,"tv":7147.93,"id":31379}]}]}
{"op":"mcm","clk":"11768453269","pt":1722712802722,"mc":[{"id":"1.231344876","rc":[{"batb":[[0,2.34,4],[1,2.32,46.81],[2,1.42,85.28]],"ltp":2.36,"tv":7147.93,"id":31379}]}]}
{"op":"mcm","clk":"11768462004","pt":1722712873636,"mc":[{"id":"1.231344876","rc":[{"trd":[[2.36,346.36]],"batb":[[0,2.34,2],[1,2.32,42.81]],"ltp":2.36,"tv":7157.93,"id":31379},{"trd":[[1.74,10803.51]],"batb":[[0,1.71,45.43],[1,1.67,35],[2,1.65,62.14]],"batl":[[0,1.73,8.74]],"ltp":1.74,"tv":21295.25,"id":31377}],"tv":28453.18}]}
{"op":"mcm","clk":"11768462285","pt":1722712876121,"mc":[{"id":"1.231344876","rc":[{"batb":[[0,2.34,10]],"ltp":2.36,"tv":7157.93,"id":31379}]}]}
{"op":"mcm","clk":"11768462674","pt":1722712879608,"mc":[{"id":"1.231344876","rc":[{"batb":[[0,2.34,2]],"ltp":2.36,"tv":7157.93,"id":31379}]}]}
{"op":"mcm","clk":"11768462967","pt":1722712882045,"mc":[{"id":"1.231344876","rc":[{"batb":[[0,2.34,10]],"ltp":2.36,"tv":7157.93,"id":31379}]}]}
{"op":"mcm","clk":"11768463160","pt":1722712883414,"mc":[{"id":"1.231344876","rc":[{"batb":[[0,2.36,4],[1,2.34,10],[2,2.32,42.81]],"batl":[[0,2.4,4],[1,2.42,4],[2,4,1.09]],"ltp":2.36,"tv":7157.93,"id":31379},{"batb":[[0,1.72,4],[1,1.71,49.43],[2,1.67,35]],"ltp":1.74,"tv":21295.25,"id":31377}]}]}
{"op":"mcm","clk":"11768463403","pt":1722712885317,"mc":[{"id":"1.231344876","rc":[{"batb":[[0,2.36,16.01],[1,2.32,30.6],[2,1.42,85.28]],"ltp":2.36,"tv":7157.93,"id":31379}]}]}
{"op":"mcm","clk":"11768463684","pt":1722712887425,"mc":[{"id":"1.231344876","rc":[{"batb":[[0,2.32,30.6],[1,1.42,85.28],[2,1.3,633.33]],"ltp":2.36,"tv":7157.93,"id":31379},{"batl":[[0,1.76,4],[1,1.77,300],[2,1.78,535.95]],"ltp":1.74,"tv":21295.25,"id":31377}]}]}
{"op":"mcm","clk":"11768463776","pt":1722712888159,"mc":[{"id":"1.231344876","rc":[{"batb":[[0,2.34,12],[1,2.32,30.6],[2,1.42,85.28]],"batl":[[0,4,1.09],[1,8,1.09],[2,20,1.45]],"ltp":2.36,"tv":7157.93,"id":31379},{"batb":[[0,1.71,45.43],[1,1.67,35],[2,1.65,62.14]],"ltp":1.74,"tv":21295.25,"id":31377}]}]}
{"op":"mcm","clk":"11768464078","pt":1722712890328,"mc":[{"id":"1.231344876","rc":[{"batb":[[0,2.34,10]],"ltp":2.36,"tv":7157.93,"id":31379}]}]}
{"op":"mcm","clk":"11768464241","pt":1722712891537,"mc":[{"id":"1.231344876","rc":[{"batb":[[0,2.32,30.6],[1,1.42,85.28],[2,1.3,633.33]],"ltp":2.36,"tv":7157.93,"id":31379}]}]}
{"op":"mcm","clk":"11768464699","pt":1722712895250,"mc":[{"id":"1.231344876","rc":[{"batb":[[0,2.36,12],[1,2.34,12.11],[2,2.32,30.6]],"ltp":2.36,"tv":7157.93,"id":31379}]}]}
{"op":"mcm","clk":"11768464896","pt":1722712896958,"mc":[{"id":"1.231344876","rc":[{"batl":[[0,1.72,3.9],[1,1.76,4],[2,1.77,300]],"ltp":1.74,"tv":21295.25,"id":31377}]}]}
{"op":"mcm","clk":"11768465085","pt":1722712898541,"mc":[{"id":"1.231344876","rc":[{"batb":[[0,2.38,4]],"batl":[[0,2.4,4],[1,2.42,4],[2,4,1.09]],"ltp":2.36,"tv":7157.93,"id":31379},{"batb":[[0,1.71,49.43]],"batl":[[1,1.77,300],[2,1.78,535.95]],"ltp":1.74,"tv":21295.25,"id":31377}]}]}
{"op":"mcm","clk":"11768465152","pt":1722712899120,"mc":[{"id":"1.231344876","rc":[{"batb":[[0,2.34,12.11],[1,2.32,30.6],[2,1.42,85.28]],"ltp":2.36,"tv":7157.93,"id":31379}]}]}
{"op":"mcm","clk":"11768468633","pt":1722712929001,"mc":[{"id":"1.231344876","rc":[{"batl":[[0,1.72,178.82]],"ltp":1.74,"tv":21295.25,"id":31377}]}]}
{"op":"mcm","clk":"11768468923","pt":1722712931271,"mc":[{"id":"1.231344876","rc":[{"trd":[[2.4,6707.98]],"batb":[[0,2.4,7.81]],"batl":[[0,2.42,4],[1,4,1.09],[2,8,1.09]],"ltp":2.4,"tv":7165.93,"id":31379},{"batb":[[0,1.71,45.43]],"ltp":1.74,"tv":21295.25,"id":31377}],"tv":28461.18}]}
{"op":"mcm","clk":"11768469321","pt":1722712934601,"mc":[{"id":"1.231344876","rc":[{"trd":[[2.4,6713.24]],"batb":[[0,2.4,2.56]],"ltp":2.4,"tv":7171.18,"id":31379},{"trd":[[1.72,457.16]],"batl":[[0,1.77,300],[1,1.78,535.95],[2,1.79,500]],"ltp":1.72,"tv":21652.41,"id":31377}],"tv":28823.59}]}
{"op":"mcm","clk":"11768469444","pt":1722712935500,"mc":[{"id":"1.231344876","rc":[{"batb":[[0,2.32,2],[1,2.3,2.67],[2,1.43,10]],"batl":[[0,4,1.09],[1,8,1.09],[2,20,1.45]],"ltp":2.4,"tv":7171.18,"id":31379},{"batb":[[2,1.38,85.28]],"ltp":1.72,"tv":21652.41,"id":31377}]}]}
{"op":"mcm","clk":"11768469843","pt":1722712938620,"mc":[{"id":"1.231344876","rc":[{"batb":[[0,2.3,2.67],[1,1.42,85.28],[2,1.3,633.33]],"ltp":2.4,"tv":7171.18,"id":31379}]}]}
{"op":"mcm","clk":"11768469965","pt":1722712939689,"mc":[{"id":"1.231344876","rc":[{"batb":[[0,2.32,30.6],[1,2.3,2.67],[2,1.42,85.28]],"ltp":2.4,"tv":7171.18,"id":31379},{"batb":[[2,1.65,62.14]],"ltp":1.72,"tv":21652.41,"id":31377}]}]}
{"op":"mcm","clk":"11768470229","pt":1722712941697,"mc":[{"id":"1.231344876","rc":[{"batb":[[0,2.34,12],[1,2.32,30.6]],"ltp":2.4,"tv":7171.18,"id":31379}]}]}
{"op":"mcm","clk":"11768470618","pt":1722712944601,"mc":[{"id":"1.231344876","rc":[{"batb":[[0,2.34,14]],"ltp":2.4,"tv":7171.18,"id":31379},{"batl":[[0,1.75,4],[1,1.77,300],[2,1.78,535.95]],"ltp":1.72,"tv":21652.41,"id":31377}]}]}
{"op":"mcm","clk":"11768470690","pt":1722712945126,"mc":[{"id":"1.231344876","rc":[{"batb":[[0,2.34,4]],"ltp":2.4,"tv":7171.18,"id":31379}]}]}
{"op":"mcm","clk":"11768472680","pt":1722712959207,"mc":[{"id":"1.231344876","rc":[{"batb":[[0,2.36,12],[1,2.34,4],[2,2.32,30.6]],"ltp":2.4,"tv":7171.18,"id":31379},{"batb":[[0,1.72,4],[1,1.71,49.43],[2,1.67,35]],"ltp":1.72,"tv":21652.41,"id":31377}]}]}
{"op":"mcm","clk":"11768472826","pt":1722712960345,"mc":[{"id":"1.231344876","rc":[{"batb":[[2,1.42,85.28]],"ltp":2.4,"tv":7171.18,"id":31379},{"trd":[[1.71,103.85],[1.72,465.16]],"batb":[[0,1.71,23.59],[1,1.67,35],[2,1.38,85.28]],"ltp":1.71,"tv":21704.09,"id":31377}],"tv":28875.27}]}
{"op":"mcm","clk":"11768472974","pt":1722712961413,"mc":[{"id":"1.231344876","rc":[{"batb":[[0,2.36,10]],"ltp":2.4,"tv":7171.18,"id":31379}]}]}
{"op":"mcm","clk":"11768473124","pt":1722712962514,"mc":[{"id":"1.231344876","rc":[{"batb":[[0,1.42,85.28],[1,1.3,633.33],[2,1.08,7.81]],"ltp":2.4,"tv":7171.18,"id":31379}]}]}
{"op":"mcm","clk":"11768473171","pt":1722712962834,"mc":[{"id":"1.231344876","rc":[{"batl":[[0,1.77,300],[1,1.78,535.95],[2,1.79,500]],"ltp":1.71,"tv":21704.09,"id":31377}]}]}
{"op":"mcm","clk":"11768473458","pt":1722712964913,"mc":[{"id":"1.231344876","rc":[{"batb":[[0,2.34,12],[1,2.32,30.6],[2,1.42,85.28]],"ltp":2.4,"tv":7171.18,"id":31379},{"batb":[[2,1.65,62.14]],"ltp":1.71,"tv":21704.09,"id":31377}]}]}
{"op":"mcm","clk":"11768473783","pt":1722712967126,"mc":[{"id":"1.231344876","rc":[{"batb":[[0,2.34,10]],"ltp":2.4,"tv":7171.18,"id":31379}]}]}
{"op":"mcm","clk":"11768473917","pt":1722712968332,"mc":[{"id":"1.231344876","rc":[{"batb":[[0,2.32,30.6],[1,1.42,85.28],[2,1.3,633.33]],"ltp":2.4,"tv":7171.18,"id":31379}]}]}
{"op":"mcm","clk":"11768474720","pt":1722712974439,"mc":[{"id":"1.231344876","rc":[{"batb":[[0,2.34,12],[1,2.32,34.6],[2,1.42,85.28]],"ltp":2.4,"tv":7171.18,"id":31379},{"batl":[[0,1.76,4],[1,1.77,300],[2,1.78,535.95]],"ltp":1.71,"tv":21704.09,"id":31377}]}]}
{"op":"mcm","clk":"11768474988","pt":1722712976648,"mc":[{"id":"1.231344876","rc":[{"batb":[[0,2.34,10]],"ltp":2.4,"tv":7171.18,"id":31379}]}]}
{"op":"mcm","clk":"11768475099","pt":1722712977543,"mc":[{"id":"1.231344876","rc":[{"batb":[[0,2.32,34.6],[1,1.42,85.28],[2,1.3,633.33]],"ltp":2.4,"tv":7171.18,"id":31379}]}]}
{"op":"mcm","clk":"11768479920","pt":1722713012001,"mc":[{"id":"1.231344876","rc":[{"batb":[[0,2.36,2],[1,2.34,2.62],[2,2.32,34.6]],"ltp":2.4,"tv":7171.18,"id":31379}]}]}
{"op":"mcm","clk":"11768480226","pt":1722713014224,"mc":[{"id":"1.231344876","rc":[{"batb":[[0,2.34,2.62],[1,2.32,34.6],[2,1.42,85.28]],"ltp":2.4,"tv":7171.18,"id":31379}]}]}
{"op":"mcm","clk":"11768480996","pt":1722713019692,"mc":[{"id":"1.231344876","rc":[{"batb":[[0,2.34,6.62]],"batl":[[0,2.4,4],[1,2.42,4],[2,4,1.09]],"ltp":2.4,"tv":7171.18,"id":31379},{"batb":[[0,1.72,4],[1,1.71,27.59],[2,1.67,35]],"batl":[[0,1.75,4],[1,1.76,4],[2,1.77,300]],"ltp":1.71,"tv":21704.09,"id":31377}]}]}
{"op":"mcm","clk":"11768481084","pt":1722713020318,"mc":[{"id":"1.231344876","rc":[{"batb":[[0,1.71,23.59],[1,1.67,35],[2,1.65,62.14]],"ltp":1.71,"tv":21704.09,"id":31377}]}]}
{"op":"mcm","clk":"11768811728","pt":1722715627425,"mc":[{"id":"1.231344876","rc":[{"batb":[[2,1.3,633.33]],"ltp":2.4,"tv":7171.18,"id":31379}]}]}
{"op":"mcm","clk":"11768882872","pt":1722716183696,"mc":[{"id":"1.231344876","rc":[{"batl":[[0,1.73,38.88],[1,1.75,4],[2,1.76,4]],"ltp":1.71,"tv":21704.09,"id":31377}]}]}
{"op":"mcm","clk":"11768883056","pt":1722716185415,"mc":[{"id":"1.231344876","rc":[{"batb":[[0,2.38,2.58],[1,2.34,4],[2,2.32,34.6]],"ltp":2.4,"tv":7171.18,"id":31379}]}]}
{"op":"mcm","clk":"11768884225","pt":1722716195429,"mc":[{"id":"1.231344876","rc":[{"batb":[[0,1.71,27.59]],"batl":[[0,1.73,42.88]],"ltp":1.71,"tv":21704.09,"id":31377}]}]}
{"op":"mcm","clk":"11769146639","pt":1722719033111,"mc":[{"id":"1.231344876","rc":[{"batb":[[1,1.68,112.5],[2,1.67,35]],"ltp":1.71,"tv":21704.09,"id":31377}]}]}
{"op":"mcm","clk":"11769273998","pt":1722720624373,"mc":[{"id":"1.231344876","rc":[{"batb":[[1,2.36,27.97],[2,2.34,4]],"ltp":2.4,"tv":7171.18,"id":31379},{"batb":[[1,1.7,38.65],[2,1.68,112.5]],"ltp":1.71,"tv":21704.09,"id":31377}]}]}
{"op":"mcm","clk":"11769276463","pt":1722720656016,"mc":[{"id":"1.231344876","rc":[{"batb":[[0,2.38,7.23]],"ltp":2.4,"tv":7171.18,"id":31379}]}]}
{"op":"mcm","clk":"11769277278","pt":1722720666212,"mc":[{"id":"1.231344876","rc":[{"batb":[[0,2.38,11.23]],"ltp":2.4,"tv":7171.18,"id":31379}]}]}
{"op":"mcm","clk":"11769458825","pt":1722722790314,"mc":[{"id":"1.231344876","rc":[{"trd":[[1.71,105.85]],"batb":[[0,1.71,26.59]],"ltp":1.71,"tv":21706.09,"id":31377}],"tv":28877.28}]}
{"op":"mcm","clk":"11770072839","pt":1722730522634,"mc":[{"id":"1.231344876","rc":[{"trd":[[1.71,135.99]],"batb":[[0,1.71,11.52]],"ltp":1.71,"tv":21736.23,"id":31377}],"tv":28907.42}]}
{"op":"mcm","clk":"11770072883","pt":1722730523307,"mc":[{"id":"1.231344876","rc":[{"batl":[[0,2.42,4],[1,4,1.09],[2,8,1.09]],"ltp":2.4,"tv":7171.18,"id":31379}]}]}
{"op":"mcm","clk":"11770075282","pt":1722730555944,"mc":[{"id":"1.231344876","rc":[{"batl":[[0,1.72,4.38],[1,1.73,42.88],[2,1.75,4]],"ltp":1.71,"tv":21736.23,"id":31377}]}]}
{"op":"mcm","clk":"11770076029","pt":1722730566569,"mc":[{"id":"1.231344876","rc":[{"batb":[[0,2.4,12],[1,2.38,11.23],[2,2.36,27.97]],"batl":[[0,4,1.09],[1,8,1.09],[2,20,1.45]],"ltp":2.4,"tv":7171.18,"id":31379},{"batb":[[0,1.71,7.52],[1,1.68,112.5],[2,1.67,35]],"ltp":1.71,"tv":21736.23,"id":31377}]}]}
{"op":"mcm","clk":"11770076141","pt":1722730568280,"mc":[{"id":"1.231344876","rc":[{"batb":[[0,2.4,16],[1,2.38,6.58]],"ltp":2.4,"tv":7171.18,"id":31379},{"batl":[[0,1.72,8.38]],"ltp":1.71,"tv":21736.23,"id":31377}]}]}
{"op":"mcm","clk":"11770076203","pt":1722730568959,"mc":[{"id":"1.231344876","rc":[{"batb":[[0,2.4,14]],"ltp":2.4,"tv":7171.18,"id":31379}]}]}
{"op":"mcm","clk":"11770076321","pt":1722730570459,"mc":[{"id":"1.231344876","rc":[{"batb":[[0,2.38,6.58],[1,2.36,27.97],[2,2.34,4]],"ltp":2.4,"tv":7171.18,"id":31379}]}]}
{"op":"mcm","clk":"11770076423","pt":1722730571551,"mc":[{"id":"1.231344876","rc":[{"batb":[[0,2.4,2],[1,2.38,6.58],[2,2.36,27.97]],"ltp":2.4,"tv":7171.18,"id":31379}]}]}
{"op":"mcm","clk":"11770076457","pt":1722730571966,"mc":[{"id":"1.231344876","rc":[{"batb":[[1,2.38,11.04]],"ltp":2.4,"tv":7171.18,"id":31379}]}]}
{"op":"mcm","clk":"11770076625","pt":1722730574040,"mc":[{"id":"1.231344876","rc":[{"batb":[[0,2.4,10]],"ltp":2.4,"tv":7171.18,"id":31379}]}]}
{"op":"mcm","clk":"11770076718","pt":1722730575382,"mc":[{"id":"1.231344876","rc":[{"batb":[[1,2.38,6.58]],"ltp":2.4,"tv":7171.18,"id":31379}]}]}
{"op":"mcm","clk":"11770076870","pt":1722730577465,"mc":[{"id":"1.231344876","rc":[{"batb":[[0,2.4,2]],"ltp":2.4,"tv":7171.18,"id":31379}]}]}
{"op":"mcm","clk":"11770077109","pt":1722730580050,"mc":[{"id":"1.231344876","rc":[{"batb":[[0,2.4,10]],"ltp":2.4,"tv":7171.18,"id":31379}]}]}
{"op":"mcm","clk":"11770077355","pt":1722730583389,"mc":[{"id":"1.231344876","rc":[{"batb":[[0,2.4,4]],"ltp":2.4,"tv":7171.18,"id":31379}]}]}
{"op":"mcm","clk":"11770077548","pt":1722730585681,"mc":[{"id":"1.231344876","rc":[{"trd":[[2.42,5.31]],"batb":[[0,2.44,2],[1,2.42,4.69],[2,2.4,4]],"ltp":2.42,"tv":7176.49,"id":31379},{"trd":[[1.71,143.5]],"batb":[[0,1.68,112.5],[1,1.67,35],[2,1.3,633.33]],"ltp":1.71,"tv":21743.75,"id":31377}],"tv":28920.24}]}
{"op":"mcm","clk":"11770077602","pt":1722730586406,"mc":[{"id":"1.231344876","rc":[{"batb":[[2,2.38,2.58]],"ltp":2.42,"tv":7176.49,"id":31379},{"batl":[[0,1.72,4.38],[1,1.73,38.88],[2,1.77,300]],"ltp":1.71,"tv":21743.75,"id":31377}]}]}
{"op":"mcm","clk":"11770077658","pt":1722730587091,"mc":[{"id":"1.231344876","rc":[{"batl":[[0,1.73,38.88],[1,1.77,300],[2,1.78,535.95]],"ltp":1.71,"tv":21743.75,"id":31377}]}]}
{"op":"mcm","clk":"11770077755","pt":1722730588387,"mc":[{"id":"1.231344876","rc":[{"batb":[[0,2.42,4.69],[1,2.38,2.58],[2,2.36,27.97]],"ltp":2.42,"tv":7176.49,"id":31379},{"batb":[[2,1.65,62.14]],"ltp":1.71,"tv":21743.75,"id":31377}]}]}
{"op":"mcm","clk":"11770077792","pt":1722730588875,"mc":[{"id":"1.231344876","rc":[{"batb":[[0,2.38,2.58],[1,2.36,27.97],[2,2.32,30.6]],"ltp":2.42,"tv":7176.49,"id":31379}]}]}
{"op":"mcm","clk":"11770078011","pt":1722730591661,"mc":[{"id":"1.231344876","rc":[{"batb":[[0,2.4,2],[1,2.38,2.58],[2,2.36,27.97]],"ltp":2.42,"tv":7176.49,"id":31379}]}]}
{"op":"mcm","clk":"11770078165","pt":1722730593890,"mc":[{"id":"1.231344876","rc":[{"batb":[[0,2.38,2.58],[1,2.36,27.97],[2,2.32,30.6]],"ltp":2.42,"tv":7176.49,"id":31379}]}]}
{"op":"mcm","clk":"11770078338","pt":1722730596381,"mc":[{"id":"1.231344876","rc":[{"batb":[[0,2.4,2],[1,2.38,2.58],[2,2.36,27.97]],"ltp":2.42,"tv":7176.49,"id":31379}]}]}
{"op":"mcm","clk":"11770078490","pt":1722730598603,"mc":[{"id":"1.231344876","rc":[{"batl":[[0,2.46,10.74],[1,2.48,4],[2,4,1.09]],"ltp":2.42,"tv":7176.49,"id":31379},{"batb":[[0,1.69,13.49],[1,1.68,116.5],[2,1.67,35]],"batl":[[0,1.72,4],[1,1.73,38.88],[2,1.77,300]],"ltp":1.71,"tv":21743.75,"id":31377}]}]}
{"op":"mcm","clk":"11770078509","pt":1722730598916,"mc":[{"id":"1.231344876","rc":[{"batb":[[0,2.38,2.58],[1,2.36,27.97],[2,2.32,30.6]],"ltp":2.42,"tv":7176.49,"id":31379}]}]}
{"op":"mcm","clk":"11770079585","pt":1722730613298,"mc":[{"id":"1.231344876","rc":[{"batb":[[0,2.38,6.58]],"ltp":2.42,"tv":7176.49,"id":31379}]}]}
{"op":"mcm","clk":"11770079894","pt":1722730617601,"mc":[{"id":"1.231344876","rc":[{"batb":[[1,2.32,30.6],[2,1.3,633.33]],"ltp":2.42,"tv":7176.49,"id":31379},{"batb":[[1,1.68,155.65]],"ltp":1.71,"tv":21743.75,"id":31377}]}]}
{"op":"mcm","clk":"11770089443","pt":1722730749188,"mc":[{"id":"1.231344876","rc":[{"batb":[[0,1.69,21.82]],"ltp":1.71,"tv":21743.75,"id":31377}]}]}
{"op":"mcm","clk":"11770715960","pt":1722740962826,"mc":[{"id":"1.231344876","rc":[{"batl":[[0,1.72,571]],"ltp":1.71,"tv":21743.75,"id":31377}]}]}
{"op":"mcm","clk":"11770716732","pt":1722740980248,"mc":[{"id":"1.231344876","rc":[{"batb":[[0,2.38,34.54]],"ltp":2.42,"tv":7176.49,"id":31379},{"batb":[[1,1.68,116.5],[2,1.67,74.66]],"ltp":1.71,"tv":21743.75,"id":31377}]}]}
{"op":"mcm","clk":"11770717387","pt":1722740994769,"mc":[{"id":"1.231344876","rc":[{"batb":[[0,2.4,12.36],[1,2.38,34.54],[2,2.32,30.6]],"ltp":2.42,"tv":7176.49,"id":31379},{"batl":[[0,1.71,17.06],[1,1.72,571],[2,1.73,38.88]],"ltp":1.71,"tv":21743.75,"id":31377}]}]}
{"op":"mcm","clk":"11770717496","pt":1722740997346,"mc":[{"id":"1.231344876","rc":[{"batb":[[0,2.42,2.53],[1,2.4,12.36],[2,2.38,31.97]],"ltp":2.42,"tv":7176.49,"id":31379}]}]}
{"op":"mcm","clk":"11770717983","pt":1722741007887,"mc":[{"id":"1.231344876","rc":[{"batb":[[0,2.42,6.53]],"ltp":2.42,"tv":7176.49,"id":31379},{"batl":[[0,1.71,21.06]],"ltp":1.71,"tv":21743.75,"id":31377}]}]}
{"op":"mcm","clk":"11770719084","pt":1722741031339,"mc":[{"id":"1.231344876","rc":[{"batb":[[2,2.38,4]],"ltp":2.42,"tv":7176.49,"id":31379},{"batb":[[1,1.68,155.65],[2,1.67,35]],"ltp":1.71,"tv":21743.75,"id":31377}]}]}
{"op":"mcm","clk":"11770728743","pt":1722741229400,"mc":[{"id":"1.231344876","rc":[{"batl":[[0,1.71,54.39]],"ltp":1.71,"tv":21743.75,"id":31377}]}]}
{"op":"mcm","clk":"11770729204","pt":1722741239573,"mc":[{"id":"1.231344876","rc":[{"batb":[[1,2.4,39.82]],"ltp":2.42,"tv":7176.49,"id":31379}]}]}
{"op":"mcm","clk":"11770796849","pt":1722742461984,"mc":[{"id":"1.231344876","rc":[{"trd":[[2.42,6.33]],"batb":[[0,2.42,6.02]],"ltp":2.42,"tv":7177.51,"id":31379}],"tv":28921.26}]}
{"op":"mcm","clk":"11770916240","pt":1722744679938,"mc":[{"id":"1.231344876","rc":[{"trd":[[1.69,133.83]],"batb":[[0,1.69,12.74]],"ltp":1.69,"tv":21761.92,"id":31377}],"tv":28939.43}]}
{"op":"mcm","clk":"11770916541","pt":1722744687462,"mc":[{"id":"1.231344876","rc":[{"batb":[[0,1.69,16.74]],"ltp":1.69,"tv":21761.92,"id":31377}]}]}
{"op":"mcm","clk":"11770949937","pt":1722745314005,"mc":[{"id":"1.231344876","rc":[{"batl":[[0,1.7,22.5],[1,1.71,54.39],[2,1.72,571]],"ltp":1.69,"tv":21761.92,"id":31377}]}]}
{"op":"mcm","clk":"11770949983","pt":1722745315135,"mc":[{"id":"1.231344876","rc":[{"batb":[[0,1.69,4]],"ltp":1.69,"tv":21761.92,"id":31377}]}]}
{"op":"mcm","clk":"11770950045","pt":1722745317137,"mc":[{"id":"1.231344876","rc":[{"trd":[[1.69,141.83]],"batb":[[0,1.68,155.65],[1,1.67,35],[2,1.3,633.33]],"batl":[[0,1.69,1.08],[1,1.7,22.5],[2,1.71,54.39]],"ltp":1.69,"tv":21769.92,"id":31377}],"tv":28947.43}]}
{"op":"mcm","clk":"11770950159","pt":1722745320230,"mc":[{"id":"1.231344876","rc":[{"trd":[[1.69,143.99]],"batl":[[0,1.7,1.08],[1,1.71,54.39],[2,1.72,571]],"ltp":1.69,"tv":21772.08,"id":31377}],"tv":28949.59}]}
{"op":"mcm","clk":"11770950265","pt":1722745322316,"mc":[{"id":"1.231344876","rc":[{"batb":[[0,1.69,21.83],[1,1.68,155.65],[2,1.67,35]],"ltp":1.69,"tv":21772.08,"id":31377}]}]}
{"op":"mcm","clk":"11770950979","pt":1722745335866,"mc":[{"id":"1.231344876","rc":[{"batb":[[0,1.69,25.83]],"ltp":1.69,"tv":21772.08,"id":31377}]}]}
{"op":"mcm","clk":"11770951047","pt":1722745337258,"mc":[{"id":"1.231344876","rc":[{"batb":[[0,1.69,17.5]],"ltp":1.69,"tv":21772.08,"id":31377}]}]}
{"op":"mcm","clk":"11771047258","pt":1722747720019,"mc":[{"id":"1.231344876","rc":[{"batb":[[0,2.44,156.18],[1,2.42,6.02],[2,2.4,39.97]],"ltp":2.42,"tv":7177.51,"id":31379},{"trd":[[1.71,143.93]],"batb":[[1,1.68,155.87]],"ltp":1.69,"tv":21772.5,"id":31377}],"tv":28950.02}]}
{"op":"mcm","clk":"11771047357","pt":1722747722498,"mc":[{"id":"1.231344876","rc":[{"batb":[[0,2.44,158.18],[1,2.42,4],[2,2.4,27.61]],"batl":[[0,2.46,4]],"ltp":2.42,"tv":7177.51,"id":31379},{"batb":[[0,1.68,151.87],[1,1.67,35],[2,1.3,633.33]],"batl":[[1,1.71,37.33]],"ltp":1.69,"tv":21772.5,"id":31377}]}]}
{"op":"mcm","clk":"11771047563","pt":1722747727698,"mc":[{"id":"1.231344876","rc":[{"trd":[[2.44,312.35]],"batb":[[0,2.44,2],[1,2.42,8.58]],"batl":[[0,2.46,12.32]],"ltp":2.44,"tv":7489.86,"id":31379},{"batb":[[0,1.69,11.85],[1,1.68,151.87],[2,1.67,35]],"ltp":1.69,"tv":21772.5,"id":31377}],"tv":29262.37}]}
{"op":"mcm","clk":"11771047600","pt":1722747729039,"mc":[{"id":"1.231344876","rc":[{"batb":[[0,2.42,10.6],[1,2.4,27.61],[2,2.38,4]],"ltp":2.44,"tv":7489.86,"id":31379},{"batb":[[0,1.69,20.1]],"ltp":1.69,"tv":21772.5,"id":31377}]}]}
{"op":"mcm","clk":"11771047737","pt":1722747733097,"mc":[{"id":"1.231344876","rc":[{"batb":[[0,1.69,24.1]],"ltp":1.69,"tv":21772.5,"id":31377}]}]}
{"op":"mcm","clk":"11771048657","pt":1722747755337,"mc":[{"id":"1.231344876","rc":[{"batb":[[0,2.44,312.35],[1,2.42,10.6],[2,2.4,27.61]],"ltp":2.44,"tv":7489.86,"id":31379},{"batb":[[0,1.69,20.1]],"ltp":1.69,"tv":21772.5,"id":31377}]}]}
{"op":"mcm","clk":"11771048697","pt":1722747756577,"mc":[{"id":"1.231344876","rc":[{"batb":[[1,2.42,6.02]],"batl":[[0,2.46,4]],"ltp":2.44,"tv":7489.86,"id":31379},{"batb":[[0,1.69,8.26]],"ltp":1.69,"tv":21772.5,"id":31377}]}]}
{"op":"mcm","clk":"11771048717","pt":1722747756937,"mc":[{"id":"1.231344876","rc":[{"batb":[[1,2.42,4]],"ltp":2.44,"tv":7489.86,"id":31379},{"batb":[[0,1.68,151.87],[1,1.67,35],[2,1.3,633.33]],"ltp":1.69,"tv":21772.5,"id":31377}]}]}
{"op":"mcm","clk":"11771048801","pt":1722747759361,"mc":[{"id":"1.231344876","rc":[{"trd":[[2.46,3.98]],"batl":[[0,2.46,2.01]],"ltp":2.46,"tv":7493.84,"id":31379}],"tv":29266.35}]}
{"op":"mcm","clk":"11771048832","pt":1722747760096,"mc":[{"id":"1.231344876","rc":[{"trd":[[2.44,318.6]],"batb":[[0,2.44,309.23]],"ltp":2.44,"tv":7500.09,"id":31379}],"tv":29272.6}]}
{"op":"mcm","clk":"11771048966","pt":1722747763268,"mc":[{"id":"1.231344876","rc":[{"batb":[[0,2.44,313.23]],"ltp":2.44,"tv":7500.09,"id":31379},{"batl":[[0,1.7,5.08]],"ltp":1.69,"tv":21772.5,"id":31377}]}]}
{"op":"mcm","clk":"11771049089","pt":1722747766574,"mc":[{"id":"1.231344876","rc":[{"trd":[[2.44,937.06]],"batb":[[0,2.42,4],[1,2.4,27.61],[2,2.38,4]],"ltp":2.44,"tv":8118.55,"id":31379},{"batb":[[0,1.69,58.54],[1,1.68,151.87],[2,1.67,35]],"ltp":1.69,"tv":21772.5,"id":31377}],"tv":29891.06}]}
{"op":"mcm","clk":"11771049099","pt":1722747766782,"mc":[{"id":"1.231344876","rc":[{"batl":[[0,1.7,1.08]],"ltp":1.69,"tv":21772.5,"id":31377}]}]}
{"op":"mcm","clk":"11771049561","pt":1722747778363,"mc":[{"id":"1.231344876","rc":[{"batb":[[0,1.69,62.54]],"ltp":1.69,"tv":21772.5,"id":31377}]}]}
{"op":"mcm","clk":"11771049708","pt":1722747781976,"mc":[{"id":"1.231344876","rc":[{"batb":[[1,2.38,4],[2,2.32,30.6]],"ltp":2.44,"tv":8118.55,"id":31379}]}]}
{"op":"mcm","clk":"11771051066","pt":1722747818413,"mc":[{"id":"1.231344876","rc":[{"batb":[[0,2.44,312.35],[1,2.42,4],[2,2.38,4]],"ltp":2.44,"tv":8118.55,"id":31379}]}]}
{"op":"mcm","clk":"11771051086","pt":1722747818886,"mc":[{"id":"1.231344876","rc":[{"batb":[[0,1.69,58.54]],"ltp":1.69,"tv":21772.5,"id":31377}]}]}
{"op":"mcm","clk":"11771051171","pt":1722747821558,"mc":[{"id":"1.231344876","rc":[{"trd":[[2.44,1561.77]],"batb":[[0,2.42,4],[1,2.38,4],[2,2.32,30.6]],"ltp":2.44,"tv":8743.26,"id":31379}],"tv":30515.76}]}
{"op":"mcm","clk":"11771051247","pt":1722747823620,"mc":[{"id":"1.231344876","rc":[{"batb":[[0,1.69,62.54]],"ltp":1.69,"tv":21772.5,"id":31377}]}]}
{"op":"mcm","clk":"11771051361","pt":1722747826958,"mc":[{"id":"1.231344876","rc":[{"batb":[[0,2.44,312.35],[1,2.42,4],[2,2.38,4]],"ltp":2.44,"tv":8743.26,"id":31379},{"batb":[[0,1.69,58.54]],"ltp":1.69,"tv":21772.5,"id":31377}]}]}
{"op":"mcm","clk":"11771051447","pt":1722747830146,"mc":[{"id":"1.231344876","rc":[{"trd":[[2.44,2186.48]],"batb":[[0,2.42,4],[1,2.38,4],[2,2.32,30.6]],"ltp":2.44,"tv":9367.96,"id":31379}],"tv":31140.47}]}
{"op":"mcm","clk":"11771051622","pt":1722747835428,"mc":[{"id":"1.231344876","rc":[{"batb":[[0,2.44,312.35],[1,2.42,4],[2,2.38,4]],"ltp":2.44,"tv":9367.96,"id":31379}]}]}
{"op":"mcm","clk":"11771051662","pt":1722747836757,"mc":[{"id":"1.231344876","rc":[{"batb":[[0,1.68,151.87],[1,1.67,35],[2,1.3,633.33]],"ltp":1.69,"tv":21772.5,"id":31377}]}]}
{"op":"mcm","clk":"11771051727","pt":1722747838655,"mc":[{"id":"1.231344876","rc":[{"batb":[[0,2.44,316.35]],"ltp":2.44,"tv":9367.96,"id":31379},{"batl":[[0,1.7,5.08]],"ltp":1.69,"tv":21772.5,"id":31377}]}]}
{"op":"mcm","clk":"11771051794","pt":1722747840450,"mc":[{"id":"1.231344876","rc":[{"trd":[[2.44,2811.18]],"batb":[[0,2.42,4],[1,2.38,4],[2,1.3,633.33]],"batl":[[0,2.46,10.19]],"ltp":2.44,"tv":9992.67,"id":31379},{"batb":[[0,1.69,11.62],[1,1.68,151.87],[2,1.67,35]],"ltp":1.69,"tv":21772.5,"id":31377}],"tv":31765.18}]}
{"op":"mcm","clk":"11771051806","pt":1722747840758,"mc":[{"id":"1.231344876","rc":[{"batb":[[0,1.69,19.73]],"ltp":1.69,"tv":21772.5,"id":31377}]}]}
{"op":"mcm","clk":"11771051855","pt":1722747842248,"mc":[{"id":"1.231344876","rc":[{"batb":[[2,2.32,30.6]],"ltp":2.44,"tv":9992.67,"id":31379},{"batb":[[0,1.69,70.16]],"batl":[[0,1.7,1.08]],"ltp":1.69,"tv":21772.5,"id":31377}]}]}
{"op":"mcm","clk":"11771052002","pt":1722747846964,"mc":[{"id":"1.231344876","rc":[{"batb":[[0,2.44,312.35],[1,2.42,4],[2,2.38,4]],"ltp":2.44,"tv":9992.67,"id":31379}]}]}
{"op":"mcm","clk":"11771052094","pt":1722747848980,"mc":[{"id":"1.231344876","rc":[{"batl":[[0,2.46,2.01]],"ltp":2.44,"tv":9992.67,"id":31379},{"batb":[[0,1.69,58.54]],"ltp":1.69,"tv":21772.5,"id":31377}]}]}
{"op":"mcm","clk":"11771052144","pt":1722747849963,"mc":[{"id":"1.231344876","rc":[{"trd":[[2.44,3435.89]],"batb":[[0,2.42,4],[1,2.38,4],[2,2.32,30.6]],"ltp":2.44,"tv":10617.38,"id":31379}],"tv":32389.89}]}
{"op":"mcm","clk":"11771052302","pt":1722747853772,"mc":[{"id":"1.231344876","rc":[{"batb":[[0,1.69,62.54]],"ltp":1.69,"tv":21772.5,"id":31377}]}]}
{"op":"mcm","clk":"11771052366","pt":1722747855368,"mc":[{"id":"1.231344876","rc":[{"batb":[[0,2.44,312.35],[1,2.42,4],[2,2.38,4]],"ltp":2.44,"tv":10617.38,"id":31379}]}]}
{"op":"mcm","clk":"11771052383","pt":1722747855784,"mc":[{"id":"1.231344876","rc":[{"batb":[[0,1.69,58.54]],"ltp":1.69,"tv":21772.5,"id":31377}]}]}
{"op":"mcm","clk":"11771052432","pt":1722747856862,"mc":[{"id":"1.231344876","rc":[{"batb":[[0,1.68,151.87],[1,1.67,35],[2,1.3,633.33]],"ltp":1.69,"tv":21772.5,"id":31377}]}]}
{"op":"mcm","clk":"11771052604","pt":1722747861585,"mc":[{"id":"1.231344876","rc":[{"trd":[[2.44,4060.6]],"batb":[[0,2.42,4],[1,2.38,4],[2,1.3,633.33]],"ltp":2.44,"tv":11242.08,"id":31379}],"tv":33014.59}]}
{"op":"mcm","clk":"11771052619","pt":1722747861895,"mc":[{"id":"1.231344876","rc":[{"batb":[[2,2.32,30.6]],"ltp":2.44,"tv":11242.08,"id":31379},{"batb":[[0,1.69,58.54],[1,1.68,151.87],[2,1.67,35]],"ltp":1.69,"tv":21772.5,"id":31377}]}]}
{"op":"mcm","clk":"11771052793","pt":1722747866577,"mc":[{"id":"1.231344876","rc":[{"batb":[[0,2.44,312.35],[1,2.42,4],[2,2.38,4]],"ltp":2.44,"tv":11242.08,"id":31379}]}]}
{"op":"mcm","clk":"11771052808","pt":1722747866886,"mc":[{"id":"1.231344876","rc":[{"batb":[[0,1.68,151.87],[1,1.67,35],[2,1.3,633.33]],"ltp":1.69,"tv":21772.5,"id":31377}]}]}
{"op":"mcm","clk":"11771052880","pt":1722747868905,"mc":[{"id":"1.231344876","rc":[{"batb":[[0,2.44,316.35]],"ltp":2.44,"tv":11242.08,"id":31379},{"batl":[[0,1.7,5.08]],"ltp":1.69,"tv":21772.5,"id":31377}]}]}
{"op":"mcm","clk":"11771052924","pt":1722747870298,"mc":[{"id":"1.231344876","rc":[{"trd":[[2.44,4685.3]],"batb":[[0,2.42,4],[1,2.38,4],[2,1.3,633.33]],"ltp":2.44,"tv":11866.79,"id":31379}],"tv":33639.3}]}
{"op":"mcm","clk":"11771052998","pt":1722747872121,"mc":[{"id":"1.231344876","rc":[{"batb":[[2,2.32,30.6]],"ltp":2.44,"tv":11866.79,"id":31379},{"batb":[[0,1.69,58.54],[1,1.68,151.87],[2,1.67,35]],"batl":[[0,1.7,1.08]],"ltp":1.69,"tv":21772.5,"id":31377}]}]}
{"op":"mcm","clk":"11771053080","pt":1722747874497,"mc":[{"id":"1.231344876","rc":[{"batb":[[0,2.44,312.35],[1,2.42,4],[2,2.38,4]],"ltp":2.44,"tv":11866.79,"id":31379}]}]}
{"op":"mcm","clk":"11771053163","pt":1722747877022,"mc":[{"id":"1.231344876","rc":[{"batb":[[0,1.68,151.87],[1,1.67,35],[2,1.3,633.33]],"ltp":1.69,"tv":21772.5,"id":31377}]}]}
{"op":"mcm","clk":"11771053192","pt":1722747877905,"mc":[{"id":"1.231344876","rc":[{"trd":[[2.44,5310.01]],"batb":[[0,2.42,4],[1,2.38,4],[2,1.3,633.33]],"ltp":2.44,"tv":12491.5,"id":31379}],"tv":34264.01}]}
{"op":"mcm","clk":"11771053294","pt":1722747880996,"mc":[{"id":"1.231344876","rc":[{"batb":[[0,1.68,112.5],[1,1.67,54.94]],"ltp":1.69,"tv":21772.5,"id":31377}]}]}
{"op":"mcm","clk":"11771053335","pt":1722747881923,"mc":[{"id":"1.231344876","rc":[{"batb":[[2,2.32,30.6]],"ltp":2.44,"tv":12491.5,"id":31379},{"batb":[[0,1.69,58.54],[1,1.68,112.5],[2,1.67,54.94]],"ltp":1.69,"tv":21772.5,"id":31377}]}]}
{"op":"mcm","clk":"11771053384","pt":1722747883415,"mc":[{"id":"1.231344876","rc":[{"batb":[[0,2.44,312.35],[1,2.42,4],[2,2.38,4]],"ltp":2.44,"tv":12491.5,"id":31379}]}]}
{"op":"mcm","clk":"11771053489","pt":1722747886294,"mc":[{"id":"1.231344876","rc":[{"trd":[[2.44,5934.72]],"batb":[[0,2.42,4],[1,2.38,4],[2,2.32,30.6]],"ltp":2.44,"tv":13116.21,"id":31379}],"tv":34888.71}]}
{"op":"mcm","clk":"11771053687","pt":1722747891136,"mc":[{"id":"1.231344876","rc":[{"batb":[[0,2.44,312.35],[1,2.42,4],[2,2.38,4]],"ltp":2.44,"tv":13116.21,"id":31379}]}]}
{"op":"mcm","clk":"11771053724","pt":1722747892007,"mc":[{"id":"1.231344876","rc":[{"batb":[[0,1.68,112.5],[1,1.67,54.94],[2,1.3,633.33]],"ltp":1.69,"tv":21772.5,"id":31377}]}]}
{"op":"mcm","clk":"11771053809","pt":1722747894419,"mc":[{"id":"1.231344876","rc":[{"trd":[[2.44,6559.43]],"batb":[[0,2.42,4],[1,2.38,4],[2,1.3,633.33]],"batl":[[0,2.46,8.18]],"ltp":2.44,"tv":13740.91,"id":31379},{"batb":[[0,1.69,8.67],[1,1.68,112.5],[2,1.67,54.94]],"ltp":1.69,"tv":21772.5,"id":31377}],"tv":35513.42}]}
{"op":"mcm","clk":"11771053905","pt":1722747897039,"mc":[{"id":"1.231344876","rc":[{"batb":[[2,2.32,30.6]],"ltp":2.44,"tv":13740.91,"id":31379},{"batb":[[0,1.69,67.21]],"ltp":1.69,"tv":21772.5,"id":31377}]}]}
{"op":"mcm","clk":"11771053985","pt":1722747899344,"mc":[{"id":"1.231344876","rc":[{"batb":[[0,2.44,312.35],[1,2.42,4],[2,2.38,4]],"ltp":2.44,"tv":13740.91,"id":31379}]}]}
{"op":"mcm","clk":"11771054006","pt":1722747900221,"mc":[{"id":"1.231344876","rc":[{"batl":[[0,2.46,2.01]],"ltp":2.44,"tv":13740.91,"id":31379},{"batb":[[0,1.69,58.54]],"ltp":1.69,"tv":21772.5,"id":31377}]}]}
{"op":"mcm","clk":"11771054099","pt":1722747902343,"mc":[{"id":"1.231344876","rc":[{"trd":[[2.44,7184.13]],"batb":[[0,2.42,4],[1,2.38,4],[2,1.3,633.33]],"ltp":2.44,"tv":14365.62,"id":31379},{"batb":[[0,1.68,112.5],[1,1.67,54.94],[2,1.3,633.33]],"ltp":1.69,"tv":21772.5,"id":31377}],"tv":36138.13}]}
{"op":"mcm","clk":"11771054307","pt":1722747907131,"mc":[{"id":"1.231344876","rc":[{"batb":[[2,2.32,30.6]],"ltp":2.44,"tv":14365.62,"id":31379},{"batb":[[0,1.69,58.54],[1,1.68,112.5],[2,1.67,54.94]],"ltp":1.69,"tv":21772.5,"id":31377}]}]}
{"op":"mcm","clk":"11771054402","pt":1722747909651,"mc":[{"id":"1.231344876","rc":[{"batb":[[0,2.44,312.35],[1,2.42,4],[2,2.38,4]],"ltp":2.44,"tv":14365.62,"id":31379}]}]}
{"op":"mcm","clk":"11771054454","pt":1722747910988,"mc":[{"id":"1.231344876","rc":[{"trd":[[2.44,7808.84]],"batb":[[0,2.42,4],[1,2.38,4],[2,2.32,30.6]],"ltp":2.44,"tv":14990.33,"id":31379}],"tv":36762.84}]}
{"op":"mcm","clk":"11771054551","pt":1722747914173,"mc":[{"id":"1.231344876","rc":[{"batb":[[0,1.69,62.54]],"ltp":1.69,"tv":21772.5,"id":31377}]}]}
{"op":"mcm","clk":"11771054703","pt":1722747918476,"mc":[{"id":"1.231344876","rc":[{"batb":[[0,2.44,312.35],[1,2.42,4],[2,2.38,4]],"ltp":2.44,"tv":14990.33,"id":31379},{"batb":[[0,1.69,58.54]],"ltp":1.69,"tv":21772.5,"id":31377}]}]}
{"op":"mcm","clk":"11771054821","pt":1722747921679,"mc":[{"id":"1.231344876","rc":[{"trd":[[2.44,8433.55]],"batb":[[0,2.42,4],[1,2.38,4],[2,2.32,30.6]],"ltp":2.44,"tv":15615.03,"id":31379}],"tv":37387.54}]}
{"op":"mcm","clk":"11771055061","pt":1722747926551,"mc":[{"id":"1.231344876","rc":[{"batb":[[0,2.44,312.35],[1,2.42,4],[2,2.38,4]],"ltp":2.44,"tv":15615.03,"id":31379}]}]}
{"op":"mcm","clk":"11771055087","pt":1722747927172,"mc":[{"id":"1.231344876","rc":[{"batb":[[0,1.68,112.5],[1,1.67,54.94],[2,1.3,633.33]],"ltp":1.69,"tv":21772.5,"id":31377}]}]}
{"op":"mcm","clk":"11771055169","pt":1722747929391,"mc":[{"id":"1.231344876","rc":[{"trd":[[2.44,9058.25]],"batb":[[0,2.44,4]],"ltp":2.44,"tv":16239.74,"id":31379},{"batl":[[0,1.7,5.08]],"ltp":1.69,"tv":21772.5,"id":31377}],"tv":38012.25}]}
{"op":"mcm","clk":"11771055282","pt":1722747932266,"mc":[{"id":"1.231344876","rc":[{"batb":[[0,2.42,4],[1,2.38,4],[2,1.3,633.33]],"ltp":2.44,"tv":16239.74,"id":31379},{"batb":[[0,1.68,132.44],[1,1.67,35]],"ltp":1.69,"tv":21772.5,"id":31377}]}]}
{"op":"mcm","clk":"11771055358","pt":1722747934005,"mc":[{"id":"1.231344876","rc":[{"batb":[[0,2.44,312.35],[1,2.42,4],[2,2.38,4]],"ltp":2.44,"tv":16239.74,"id":31379}]}]}
{"op":"mcm","clk":"11771055528","pt":1722747937695,"mc":[{"id":"1.231344876","rc":[{"trd":[[2.44,9682.96]],"batb":[[0,2.42,4],[1,2.38,4],[2,2.32,30.6]],"ltp":2.44,"tv":16864.45,"id":31379},{"batb":[[0,1.69,58.54],[1,1.68,132.44],[2,1.67,35]],"batl":[[0,1.7,1.08]],"ltp":1.69,"tv":21772.5,"id":31377}],"tv":38636.96}]}
{"op":"mcm","clk":"11771055748","pt":1722747942305,"mc":[{"id":"1.231344876","rc":[{"batb":[[0,2.44,312.35],[1,2.42,4],[2,2.38,4]],"ltp":2.44,"tv":16864.45,"id":31379},{"batb":[[0,1.68,132.44],[1,1.67,35],[2,1.3,633.33]],"ltp":1.69,"tv":21772.5,"id":31377}]}]}
{"op":"mcm","clk":"11771055832","pt":1722747944266,"mc":[{"id":"1.231344876","rc":[{"batb":[[0,2.44,316.35]],"ltp":2.44,"tv":16864.45,"id":31379},{"batl":[[0,1.7,5.08]],"ltp":1.69,"tv":21772.5,"id":31377}]}]}
{"op":"mcm","clk":"11771055888","pt":1722747945507,"mc":[{"id":"1.231344876","rc":[{"trd":[[2.44,10307.67]],"batb":[[0,2.42,4],[1,2.38,4],[2,1.3,633.33]],"batl":[[0,2.46,9.2]],"ltp":2.44,"tv":17489.16,"id":31379},{"batb":[[0,1.69,10.17],[1,1.68,132.44],[2,1.67,35]],"ltp":1.69,"tv":21772.5,"id":31377}],"tv":39261.66}]}
{"op":"mcm","clk":"11771055952","pt":1722747947609,"mc":[{"id":"1.231344876","rc":[{"batb":[[2,2.32,30.6]],"ltp":2.44,"tv":17489.16,"id":31379},{"batb":[[0,1.69,68.71]],"batl":[[0,1.7,1.08]],"ltp":1.69,"tv":21772.5,"id":31377}]}]}
{"op":"mcm","clk":"11771056012","pt":1722747949462,"mc":[{"id":"1.231344876","rc":[{"batb":[[0,2.44,312.35],[1,2.42,4],[2,2.38,4]],"ltp":2.44,"tv":17489.16,"id":31379}]}]}
{"op":"mcm","clk":"11771056051","pt":1722747950496,"mc":[{"id":"1.231344876","rc":[{"batl":[[0,2.46,2.01]],"ltp":2.44,"tv":17489.16,"id":31379},{"batb":[[0,1.69,58.54]],"ltp":1.69,"tv":21772.5,"id":31377}]}]}
{"op":"mcm","clk":"11771056133","pt":1722747952393,"mc":[{"id":"1.231344876","rc":[{"trd":[[2.44,10932.38]],"batb":[[0,2.42,4],[1,2.38,4],[2,1.3,633.33]],"ltp":2.44,"tv":18113.86,"id":31379},{"batb":[[0,1.68,132.44],[1,1.67,35],[2,1.3,633.33]],"ltp":1.69,"tv":21772.5,"id":31377}],"tv":39886.37}]}
{"op":"mcm","clk":"11771056308","pt":1722747957123,"mc":[{"id":"1.231344876","rc":[{"batb":[[0,2.44,312.35],[1,2.42,4],[2,2.38,4]],"ltp":2.44,"tv":18113.86,"id":31379}]}]}
{"op":"mcm","clk":"11771056409","pt":1722747959387,"mc":[{"id":"1.231344876","rc":[{"batb":[[0,2.44,316.35]],"ltp":2.44,"tv":18113.86,"id":31379},{"batl":[[0,1.7,5.08]],"ltp":1.69,"tv":21772.5,"id":31377}]}]}
{"op":"mcm","clk":"11771056447","pt":1722747960410,"mc":[{"id":"1.231344876","rc":[{"trd":[[2.44,11557.08]],"batb":[[0,2.44,4]],"ltp":2.44,"tv":18738.57,"id":31379}],"tv":40511.08}]}
{"op":"mcm","clk":"11771056457","pt":1722747960818,"mc":[{"id":"1.231344876","rc":[{"batb":[[0,2.42,4],[1,2.38,4],[2,1.3,633.33]],"ltp":2.44,"tv":18738.57,"id":31379}]}]}
{"op":"mcm","clk":"11771056524","pt":1722747962318,"mc":[{"id":"1.231344876","rc":[{"batb":[[2,2.32,30.6]],"ltp":2.44,"tv":18738.57,"id":31379},{"batb":[[0,1.69,58.54],[1,1.68,132.44],[2,1.67,35]],"ltp":1.69,"tv":21772.5,"id":31377}]}]}
{"op":"mcm","clk":"11771056549","pt":1722747962832,"mc":[{"id":"1.231344876","rc":[{"batl":[[0,1.7,1.08]],"ltp":1.69,"tv":21772.5,"id":31377}]}]}
{"op":"mcm","clk":"11771056669","pt":1722747965106,"mc":[{"id":"1.231344876","rc":[{"batb":[[0,2.44,312.35],[1,2.42,4],[2,2.38,4]],"ltp":2.44,"tv":18738.57,"id":31379}]}]}
{"op":"mcm","clk":"11771056749","pt":1722747967429,"mc":[{"id":"1.231344876","rc":[{"batb":[[0,1.68,132.44],[1,1.67,35],[2,1.3,633.33]],"ltp":1.69,"tv":21772.5,"id":31377}]}]}
{"op":"mcm","clk":"11771056786","pt":1722747968309,"mc":[{"id":"1.231344876","rc":[{"trd":[[2.44,12181.79]],"batb":[[0,2.42,4],[1,2.38,4],[2,1.3,633.33]],"ltp":2.44,"tv":19363.28,"id":31379}],"tv":41135.79}]}
{"op":"mcm","clk":"11771056930","pt":1722747972416,"mc":[{"id":"1.231344876","rc":[{"batb":[[2,2.32,30.6]],"ltp":2.44,"tv":19363.28,"id":31379},{"batb":[[0,1.69,58.54],[1,1.68,132.44],[2,1.67,35]],"ltp":1.69,"tv":21772.5,"id":31377}]}]}
{"op":"mcm","clk":"11771057012","pt":1722747974418,"mc":[{"id":"1.231344876","rc":[{"batb":[[0,2.44,316.35],[1,2.42,4],[2,2.38,4]],"ltp":2.44,"tv":19363.28,"id":31379},{"batl":[[0,1.7,5.08]],"ltp":1.69,"tv":21772.5,"id":31377}]}]}
{"op":"mcm","clk":"11771057133","pt":1722747977639,"mc":[{"id":"1.231344876","rc":[{"trd":[[2.44,12806.5]],"batb":[[0,1.3,633.33],[1,1.08,7.81],[2,1.07,7.81]],"ltp":2.44,"tv":19987.98,"id":31379},{"batb":[[0,1.68,132.44],[1,1.67,35],[2,1.3,633.33]],"batl":[[0,1.7,1.08]],"ltp":1.69,"tv":21772.5,"id":31377}],"tv":41760.49}]}
{"op":"mcm","clk":"11771057157","pt":1722747978250,"mc":[{"id":"1.231344876","rc":[{"batb":[[0,1.31,10],[1,1.3,633.33],[2,1.08,7.81]],"batl":[[0,2.46,6.45]],"ltp":2.44,"tv":19987.98,"id":31379},{"batb":[[0,1.69,6.56],[1,1.68,132.44],[2,1.67,35]],"ltp":1.69,"tv":21772.5,"id":31377}]}]}
{"op":"mcm","clk":"11771057237","pt":1722747981331,"mc":[{"id":"1.231344876","rc":[{"batb":[[0,1.3,633.33],[1,1.08,7.81],[2,1.07,7.81]],"ltp":2.44,"tv":19987.98,"id":31379}]}]}
{"op":"mcm","clk":"11771057279","pt":1722747982454,"mc":[{"id":"1.231344876","rc":[{"batb":[[0,2.32,30.6],[1,1.3,633.33],[2,1.08,7.81]],"ltp":2.44,"tv":19987.98,"id":31379},{"batb":[[0,1.69,65.1]],"ltp":1.69,"tv":21772.5,"id":31377}]}]}
{"op":"mcm","clk":"11771057332","pt":1722747983537,"mc":[{"id":"1.231344876","rc":[{"batb":[[0,2.44,326.16],[1,2.32,30.6],[2,1.3,633.33]],"batl":[[0,2.46,4.44],[1,4,1.09],[2,8,1.09]],"ltp":2.44,"tv":19987.98,"id":31379},{"batb":[[1,1.68,112.5],[2,1.67,54.94]],"ltp":1.69,"tv":21772.5,"id":31377}]}]}
{"op":"mcm","clk":"11771057372","pt":1722747984555,"mc":[{"id":"1.231344876","rc":[{"trd":[[2.46,13.98]],"batl":[[0,4,1.09],[1,8,1.09],[2,20,1.45]],"ltp":2.46,"tv":19997.98,"id":31379},{"trd":[[1.69,158.55]],"batb":[[0,1.69,43.98]],"ltp":1.69,"tv":21787.06,"id":31377}],"tv":41785.05}]}
{"op":"mcm","clk":"11771057391","pt":1722747985228,"mc":[{"id":"1.231344876","rc":[{"trd":[[2.44,13431.2]],"batb":[[0,2.44,13.81]],"ltp":2.44,"tv":20622.69,"id":31379}],"tv":42409.76}]}
{"op":"mcm","clk":"11771057458","pt":1722747987547,"mc":[{"id":"1.231344876","rc":[{"batb":[[0,2.46,10],[1,2.44,13.81]],"ltp":2.44,"tv":20622.69,"id":31379},{"batb":[[0,1.68,112.5],[1,1.67,54.94],[2,1.3,633.33]],"ltp":1.69,"tv":21787.06,"id":31377}]}]}
{"op":"mcm","clk":"11771057539","pt":1722747989549,"mc":[{"id":"1.231344876","rc":[{"batl":[[0,2.48,4],[1,4,1.09],[2,8,1.09]],"ltp":2.44,"tv":20622.69,"id":31379},{"batb":[[0,1.68,116.5]],"ltp":1.69,"tv":21787.06,"id":31377}]}]}
{"op":"mcm","clk":"11771057595","pt":1722747990936,"mc":[{"id":"1.231344876","rc":[{"batb":[[0,2.44,13.81],[1,1.3,633.33],[2,1.08,7.81]],"ltp":2.44,"tv":20622.69,"id":31379}]}]}
{"op":"mcm","clk":"11771057627","pt":1722747991855,"mc":[{"id":"1.231344876","rc":[{"batl":[[0,2.46,6.23],[1,2.48,4],[2,4,1.09]],"ltp":2.44,"tv":20622.69,"id":31379}]}]}
{"op":"mcm","clk":"11771058095","pt":1722748004676,"mc":[{"id":"1.231344876","rc":[{"batb":[[0,2.44,17.81]],"ltp":2.44,"tv":20622.69,"id":31379},{"batb":[[0,1.69,4],[1,1.68,116.5],[2,1.67,54.94]],"batl":[[0,1.7,5.08]],"ltp":1.69,"tv":21787.06,"id":31377}]}]}
{"op":"mcm","clk":"11771058167","pt":1722748006886,"mc":[{"id":"1.231344876","rc":[{"batl":[[0,2.48,4],[1,4,1.09],[2,8,1.09]],"ltp":2.44,"tv":20622.69,"id":31379}]}]}
{"op":"mcm","clk":"11771059284","pt":1722748036598,"mc":[{"id":"1.231344876","rc":[{"batb":[[0,1.3,633.33],[1,1.08,7.81],[2,1.07,7.81]],"ltp":2.44,"tv":20622.69,"id":31379},{"batb":[[1,1.68,136.44],[2,1.67,35]],"ltp":1.69,"tv":21787.06,"id":31377}]}]}
{"op":"mcm","clk":"11771059350","pt":1722748037684,"mc":[{"id":"1.231344876","rc":[{"batb":[[0,2.32,30.6],[1,1.31,10],[2,1.3,633.33]],"batl":[[0,2.46,6.43],[1,2.48,4],[2,4,1.09]],"ltp":2.44,"tv":20622.69,"id":31379},{"batb":[[0,1.69,71.59]],"ltp":1.69,"tv":21787.06,"id":31377}]}]}
{"op":"mcm","clk":"11771059371","pt":1722748038197,"mc":[{"id":"1.231344876","rc":[{"batl":[[0,1.7,1.08]],"ltp":1.69,"tv":21787.06,"id":31377}]}]}
{"op":"mcm","clk":"11771059465","pt":1722748040207,"mc":[{"id":"1.231344876","rc":[{"batb":[[1,1.3,633.33],[2,1.08,7.81]],"ltp":2.44,"tv":20622.69,"id":31379}]}]}
{"op":"mcm","clk":"11771059577","pt":1722748042527,"mc":[{"id":"1.231344876","rc":[{"batb":[[0,2.34,10],[1,2.32,30.6],[2,1.3,633.33]],"ltp":2.44,"tv":20622.69,"id":31379}]}]}
{"op":"mcm","clk":"11771059731","pt":1722748045916,"mc":[{"id":"1.231344876","rc":[{"batb":[[0,2.32,30.6],[1,1.3,633.33],[2,1.08,7.81]],"ltp":2.44,"tv":20622.69,"id":31379}]}]}
{"op":"mcm","clk":"11771059792","pt":1722748047302,"mc":[{"id":"1.231344876","rc":[{"batb":[[0,2.44,312.35],[1,2.32,30.6],[2,1.3,633.33]],"batl":[[0,4,1.09],[1,8,1.09],[2,20,1.45]],"ltp":2.44,"tv":20622.69,"id":31379},{"batb":[[0,1.69,58.54],[1,1.68,132.44]],"ltp":1.69,"tv":21787.06,"id":31377}]}]}
{"op":"mcm","clk":"11771059817","pt":1722748047919,"mc":[{"id":"1.231344876","rc":[{"batb":[[0,2.46,2],[1,2.44,312.35]],"ltp":2.44,"tv":20622.69,"id":31379},{"batb":[[0,1.68,132.44],[1,1.67,35],[2,1.3,633.33]],"ltp":1.69,"tv":21787.06,"id":31377}]}]}
{"op":"mcm","clk":"11771059920","pt":1722748050439,"mc":[{"id":"1.231344876","rc":[{"batb":[[0,2.44,312.35],[1,1.3,633.33],[2,1.08,7.81]],"batl":[[0,2.48,4],[1,4,1.09],[2,8,1.09]],"ltp":2.44,"tv":20622.69,"id":31379},{"batb":[[0,1.68,136.44]],"ltp":1.69,"tv":21787.06,"id":31377}]}]}
{"op":"mcm","clk":"11771060013","pt":1722748052651,"mc":[{"id":"1.231344876","rc":[{"batb":[[0,1.3,633.33],[1,1.08,7.81],[2,1.07,7.81]],"ltp":2.44,"tv":20622.69,"id":31379}]}]}
{"op":"mcm","clk":"11771060022","pt":1722748052806,"mc":[{"id":"1.231344876","rc":[{"batb":[[0,2.32,30.6],[1,1.31,10],[2,1.3,633.33]],"ltp":2.44,"tv":20622.69,"id":31379},{"batb":[[0,1.69,58.54],[1,1.68,136.44],[2,1.67,35]],"ltp":1.69,"tv":21787.06,"id":31377}]}]}
{"op":"mcm","clk":"11771060173","pt":1722748056049,"mc":[{"id":"1.231344876","rc":[{"batb":[[1,1.3,633.33],[2,1.08,7.81]],"ltp":2.44,"tv":20622.69,"id":31379}]}]}
{"op":"mcm","clk":"11771060268","pt":1722748058318,"mc":[{"id":"1.231344876","rc":[{"batb":[[0,2.34,10],[1,2.32,30.6],[2,1.3,633.33]],"ltp":2.44,"tv":20622.69,"id":31379}]}]}
{"op":"mcm","clk":"11771060421","pt":1722748061759,"mc":[{"id":"1.231344876","rc":[{"batb":[[0,2.32,30.6],[1,1.3,633.33],[2,1.08,7.81]],"ltp":2.44,"tv":20622.69,"id":31379}]}]}
{"op":"mcm","clk":"11771060541","pt":1722748064539,"mc":[{"id":"1.231344876","rc":[{"batb":[[0,2.36,36.84],[1,2.34,47.15],[2,2.32,30.6]],"batl":[[0,2.44,312.35],[1,2.48,4],[2,4,1.09]],"ltp":2.44,"tv":20622.69,"id":31379},{"batb":[[0,1.69,109.98]],"ltp":1.69,"tv":21787.06,"id":31377}]}]}
{"op":"mcm","clk":"11771060566","pt":1722748065158,"mc":[{"id":"1.231344876","rc":[{"trd":[[2.42,7.09]],"batb":[[0,2.4,40.99],[1,2.36,36.84],[2,2.34,47.15]],"batl":[[0,2.42,3.24],[1,2.44,316.35],[2,2.48,4]],"ltp":2.42,"tv":20623.45,"id":31379},{"trd":[[1.7,1.08]],"batb":[[0,1.69,113.98]],"batl":[[0,1.71,37.33],[1,1.72,571],[2,1.73,38.88]],"ltp":1.7,"tv":21788.14,"id":31377}],"tv":42411.6}]}
{"op":"mcm","clk":"11771060666","pt":1722748067566,"mc":[{"id":"1.231344876","rc":[{"batb":[[2,2.34,37.15]],"ltp":2.42,"tv":20623.45,"id":31379}]}]}
{"op":"mcm","clk":"11771060692","pt":1722748068337,"mc":[{"id":"1.231344876","rc":[{"trd":[[2.42,13.57],[2.44,14049.43]],"batl":[[0,2.44,7.24],[1,2.48,4],[2,4,1.09]],"ltp":2.44,"tv":21248.16,"id":31379},{"batb":[[0,1.69,55.44]],"ltp":1.7,"tv":21788.14,"id":31377}],"tv":43036.31}]}
{"op":"mcm","clk":"11771060747","pt":1722748069466,"mc":[{"id":"1.231344876","rc":[{"batb":[[0,2.42,5.07],[1,2.4,40.99],[2,2.36,36.84]],"ltp":2.44,"tv":21248.16,"id":31379}]}]}
{"op":"mcm","clk":"11771061185","pt":1722748080679,"mc":[{"id":"1.231344876","rc":[{"trd":[[2.44,14057.24]],"batl":[[0,2.44,3.34]],"ltp":2.44,"tv":21255.96,"id":31379}],"tv":43044.11}]}
{"op":"mcm","clk":"11771061581","pt":1722748088269,"mc":[{"id":"1.231344876","rc":[{"batb":[[1,2.4,54.8]],"ltp":2.44,"tv":21255.96,"id":31379}]}]}
{"op":"mcm","clk":"11771061864","pt":1722748095360,"mc":[{"id":"1.231344876","rc":[{"batb":[[0,2.42,9.07]],"ltp":2.44,"tv":21255.96,"id":31379}]}]}
{"op":"mcm","clk":"11771062174","pt":1722748103591,"mc":[{"id":"1.231344876","rc":[{"trd":[[2.44,14063.92]],"batb":[[0,2.44,312.13],[1,2.42,9.07],[2,2.4,54.8]],"batl":[[0,2.48,4],[1,4,1.09],[2,8,1.09]],"ltp":2.44,"tv":21262.65,"id":31379},{"batb":[[0,1.68,132.44],[1,1.67,35],[2,1.3,633.33]],"ltp":1.7,"tv":21788.14,"id":31377}],"tv":43050.79}]}
{"op":"mcm","clk":"11771062186","pt":1722748103793,"mc":[{"id":"1.231344876","rc":[{"batb":[[1,2.42,4]],"ltp":2.44,"tv":21262.65,"id":31379}]}]}
{"op":"mcm","clk":"11771062296","pt":1722748106509,"mc":[{"id":"1.231344876","rc":[{"trd":[[2.44,14688.19]],"batb":[[0,2.42,4],[1,2.4,54.8],[2,2.36,36.84]],"batl":[[0,2.46,7.27],[1,2.48,4],[2,4,1.09]],"ltp":2.44,"tv":21886.92,"id":31379},{"batb":[[0,1.69,9.97],[1,1.68,132.44],[2,1.67,35]],"ltp":1.7,"tv":21788.14,"id":31377}],"tv":43675.06}]}
{"op":"mcm","clk":"11771062388","pt":1722748108616,"mc":[{"id":"1.231344876","rc":[{"batl":[[0,2.46,7.05]],"ltp":2.44,"tv":21886.92,"id":31379}]}]}
{"op":"mcm","clk":"11771062474","pt":1722748110514,"mc":[{"id":"1.231344876","rc":[{"batl":[[0,2.44,4],[1,2.46,11.05],[2,2.48,4]],"ltp":2.44,"tv":21886.92,"id":31379},{"batb":[[0,1.69,13.97]],"ltp":1.7,"tv":21788.14,"id":31377}]}]}
{"op":"mcm","clk":"11771062502","pt":1722748111136,"mc":[{"id":"1.231344876","rc":[{"batl":[[0,2.46,7.05],[1,4,1.09],[2,8,1.09]],"ltp":2.44,"tv":21886.92,"id":31379}]}]}
{"op":"mcm","clk":"11771062664","pt":1722748115192,"mc":[{"id":"1.231344876","rc":[{"batb":[[0,1.69,20.89]],"ltp":1.7,"tv":21788.14,"id":31377}]}]}
{"op":"mcm","clk":"11771062823","pt":1722748119093,"mc":[{"id":"1.231344876","rc":[{"batb":[[0,2.42,10.41]],"ltp":2.44,"tv":21886.92,"id":31379}]}]}
{"op":"mcm","clk":"11771063090","pt":1722748125515,"mc":[{"id":"1.231344876","rc":[{"batl":[[0,2.46,11.05]],"ltp":2.44,"tv":21886.92,"id":31379}]}]}
{"op":"mcm","clk":"11771063178","pt":1722748127522,"mc":[{"id":"1.231344876","rc":[{"batb":[[0,2.44,312.35],[1,2.42,4],[2,2.4,54.8]],"batl":[[0,2.46,4]],"ltp":2.44,"tv":21886.92,"id":31379},{"batb":[[0,1.69,6.92]],"ltp":1.7,"tv":21788.14,"id":31377}]}]}
{"op":"mcm","clk":"11771063247","pt":1722748129229,"mc":[{"id":"1.231344876","rc":[{"batb":[[0,1.68,132.44],[1,1.67,35],[2,1.3,633.33]],"ltp":1.7,"tv":21788.14,"id":31377}]}]}
{"op":"mcm","clk":"11771063350","pt":1722748131536,"mc":[{"id":"1.231344876","rc":[{"trd":[[2.44,15312.89]],"batb":[[0,2.42,4],[1,2.4,54.8],[2,2.36,36.84]],"ltp":2.44,"tv":22511.62,"id":31379}],"tv":44299.77}]}
{"op":"mcm","clk":"11771063372","pt":1722748131944,"mc":[{"id":"1.231344876","rc":[{"batb":[[0,2.44,12],[1,2.42,4],[2,2.4,54.8]],"batl":[[0,4,1.09],[1,8,1.09],[2,20,1.45]],"ltp":2.44,"tv":22511.62,"id":31379}]}]}
{"op":"mcm","clk":"11771063481","pt":1722748134306,"mc":[{"id":"1.231344876","rc":[{"batb":[[0,2.44,10]],"ltp":2.44,"tv":22511.62,"id":31379}]}]}
{"op":"mcm","clk":"11771063523","pt":1722748135231,"mc":[{"id":"1.231344876","rc":[{"batb":[[0,2.42,4],[1,2.4,54.8],[2,2.36,36.84]],"ltp":2.44,"tv":22511.62,"id":31379}]}]}
{"op":"mcm","clk":"11771063629","pt":1722748137917,"mc":[{"id":"1.231344876","rc":[{"batb":[[0,2.44,12],[1,2.42,4],[2,2.4,54.8]],"ltp":2.44,"tv":22511.62,"id":31379}]}]}
{"op":"mcm","clk":"11771063747","pt":1722748140623,"mc":[{"id":"1.231344876","rc":[{"batb":[[0,2.44,14]],"ltp":2.44,"tv":22511.62,"id":31379}]}]}
{"op":"mcm","clk":"11771063786","pt":1722748141652,"mc":[{"id":"1.231344876","rc":[{"batb":[[0,2.42,4],[1,2.4,54.8],[2,2.36,36.84]],"batl":[[0,2.46,4],[1,2.48,4],[2,4,1.09]],"ltp":2.44,"tv":22511.62,"id":31379},{"batl":[[0,1.7,4],[1,1.71,37.33],[2,1.72,571]],"ltp":1.7,"tv":21788.14,"id":31377}]}]}
{"op":"mcm","clk":"11771063792","pt":1722748141756,"mc":[{"id":"1.231344876","rc":[{"batl":[[0,2.46,8.55]],"ltp":2.44,"tv":22511.62,"id":31379}]}]}
{"op":"mcm","clk":"11771063862","pt":1722748143153,"mc":[{"id":"1.231344876","rc":[{"batb":[[0,1.69,58.54],[1,1.68,132.44],[2,1.67,35]],"ltp":1.7,"tv":21788.14,"id":31377}]}]}
{"op":"mcm","clk":"11771063884","pt":1722748143718,"mc":[{"id":"1.231344876","rc":[{"batl":[[0,1.71,37.33],[1,1.72,571],[2,1.73,38.88]],"ltp":1.7,"tv":21788.14,"id":31377}]}]}
{"op":"mcm","clk":"11771063937","pt":1722748144957,"mc":[{"id":"1.231344876","rc":[{"trd":[[2.46,71.28]],"batb":[[0,2.46,263.6],[1,2.42,4],[2,2.4,54.8]],"batl":[[0,2.48,4],[1,4,1.09],[2,8,1.09]],"ltp":2.46,"tv":22568.93,"id":31379},{"trd":[[1.69,217.09]],"batb":[[0,1.68,132.44],[1,1.67,35],[2,1.3,633.33]],"ltp":1.69,"tv":21846.68,"id":31377}],"tv":44415.61}]}
{"op":"mcm","clk":"11771064009","pt":1722748146655,"mc":[{"id":"1.231344876","rc":[{"batb":[[0,2.46,268.14]],"ltp":2.46,"tv":22568.93,"id":31379}]}]}
{"op":"mcm","clk":"11771064054","pt":1722748147430,"mc":[{"id":"1.231344876","rc":[{"batb":[[2,2.4,40.99]],"ltp":2.46,"tv":22568.93,"id":31379},{"batb":[[0,1.68,112.5]],"ltp":1.69,"tv":21846.68,"id":31377}]}]}
{"op":"mcm","clk":"11771064201","pt":1722748150925,"mc":[{"id":"1.231344876","rc":[{"batb":[[0,2.46,4.55]],"ltp":2.46,"tv":22568.93,"id":31379}]}]}
{"op":"mcm","clk":"11771064269","pt":1722748152365,"mc":[{"id":"1.231344876","rc":[{"batb":[[0,2.42,8.62],[1,2.4,40.99],[2,2.36,36.84]],"ltp":2.46,"tv":22568.93,"id":31379}]}]}
{"op":"mcm","clk":"11771064471","pt":1722748157162,"mc":[{"id":"1.231344876","rc":[{"batl":[[0,2.46,6.02]],"ltp":2.46,"tv":22568.93,"id":31379},{"batb":[[0,1.69,8.45],[1,1.68,112.5],[2,1.67,35]],"ltp":1.69,"tv":21846.68,"id":31377}]}]}
{"op":"mcm","clk":"11771064899","pt":1722748168470,"mc":[{"id":"1.231344876","rc":[{"batb":[[0,2.42,13.7]],"ltp":2.46,"tv":22568.93,"id":31379}]}]}
{"op":"mcm","clk":"11771065245","pt":1722748177192,"mc":[{"id":"1.231344876","rc":[{"trd":[[2.42,40.12]],"batb":[[0,2.4,40.99],[1,2.36,36.84],[2,2.34,37.15]],"ltp":2.42,"tv":22595.48,"id":31379}],"tv":44442.17}]}
{"op":"mcm","clk":"11771066170","pt":1722748199104,"mc":[{"id":"1.231344876","rc":[{"batb":[[0,2.44,234.27],[1,2.4,40.99],[2,2.36,36.84]],"ltp":2.42,"tv":22595.48,"id":31379}]}]}
{"op":"mcm","clk":"11771066231","pt":1722748200337,"mc":[{"id":"1.231344876","rc":[{"batb":[[0,1.68,112.5],[1,1.67,35],[2,1.3,633.33]],"ltp":1.69,"tv":21846.68,"id":31377}]}]}
{"op":"mcm","clk":"11771066264","pt":1722748201019,"mc":[{"id":"1.231344876","rc":[{"batb":[[0,2.44,238.27]],"ltp":2.42,"tv":22595.48,"id":31379},{"batl":[[0,1.7,4],[1,1.71,37.33],[2,1.72,571]],"ltp":1.69,"tv":21846.68,"id":31377}]}]}
{"op":"mcm","clk":"11771066410","pt":1722748203794,"mc":[{"id":"1.231344876","rc":[{"batb":[[0,2.44,252.07]],"ltp":2.42,"tv":22595.48,"id":31379},{"batb":[[1,1.67,54.94]],"ltp":1.69,"tv":21846.68,"id":31377}]}]}
{"op":"mcm","clk":"11771066476","pt":1722748205330,"mc":[{"id":"1.231344876","rc":[{"trd":[[2.44,15781.42]],"batb":[[0,2.44,17.81]],"ltp":2.44,"tv":23064.01,"id":31379}],"tv":44910.7}]}
{"op":"mcm","clk":"11771067011","pt":1722748215414,"mc":[{"id":"1.231344876","rc":[{"trd":[[2.44,15815.79]],"batb":[[0,2.4,41.61],[1,2.36,36.84],[2,2.34,37.15]],"ltp":2.44,"tv":23098.37,"id":31379}],"tv":44945.06}]}
{"op":"mcm","clk":"11771067046","pt":1722748216135,"mc":[{"id":"1.231344876","rc":[{"batb":[[0,2.42,4.62],[1,2.4,40.99],[2,2.36,36.84]],"ltp":2.44,"tv":23098.37,"id":31379},{"batb":[[0,1.69,4],[1,1.68,116.5],[2,1.67,54.94]],"ltp":1.69,"tv":21846.68,"id":31377}]}]}
{"op":"mcm","clk":"11771067078","pt":1722748216749,"mc":[{"id":"1.231344876","rc":[{"batl":[[0,2.46,11.95]],"ltp":2.44,"tv":23098.37,"id":31379},{"batb":[[0,1.69,13.71]],"ltp":1.69,"tv":21846.68,"id":31377}]}]}
{"op":"mcm","clk":"11771067384","pt":1722748222610,"mc":[{"id":"1.231344876","rc":[{"batb":[[0,1.69,20.2]],"batl":[[0,1.71,37.33],[1,1.72,571],[2,1.73,38.88]],"ltp":1.69,"tv":21846.68,"id":31377}]}]}
{"op":"mcm","clk":"11771067788","pt":1722748230438,"mc":[{"id":"1.231344876","rc":[{"batb":[[0,2.44,234.89],[1,2.42,4],[2,2.4,40.99]],"ltp":2.44,"tv":23098.37,"id":31379},{"batb":[[0,1.69,16.2],[1,1.68,112.5]],"ltp":1.69,"tv":21846.68,"id":31377}]}]}
{"op":"mcm","clk":"11771067827","pt":1722748231266,"mc":[{"id":"1.231344876","rc":[{"batb":[[0,2.44,238.89]],"batl":[[0,2.46,6.02]],"ltp":2.44,"tv":23098.37,"id":31379},{"batb":[[0,1.68,112.5],[1,1.67,54.94],[2,1.3,633.33]],"batl":[[0,1.7,4],[1,1.71,37.33],[2,1.72,571]],"ltp":1.69,"tv":21846.68,"id":31377}]}]}
{"op":"mcm","clk":"11771068343","pt":1722748243355,"mc":[{"id":"1.231344876","rc":[{"trd":[[2.44,16292.13]],"batb":[[0,2.42,4.72],[1,2.4,40.99],[2,2.36,36.84]],"ltp":2.44,"tv":23574.71,"id":31379}],"tv":45421.4}]}
{"op":"mcm","clk":"11771068369","pt":1722748244075,"mc":[{"id":"1.231344876","rc":[{"batb":[[0,2.42,4]],"ltp":2.44,"tv":23574.71,"id":31379}]}]}
{"op":"mcm","clk":"11771068456","pt":1722748246383,"mc":[{"id":"1.231344876","rc":[{"batb":[[0,1.69,4],[1,1.68,116.5],[2,1.67,54.94]],"ltp":1.69,"tv":21846.68,"id":31377}]}]}
{"op":"mcm","clk":"11771068948","pt":1722748257674,"mc":[{"id":"1.231344876","rc":[{"batb":[[2,1.67,35]],"ltp":1.69,"tv":21846.68,"id":31377}]}]}
{"op":"mcm","clk":"11771068967","pt":1722748257980,"mc":[{"id":"1.231344876","rc":[{"batb":[[0,1.68,132.44],[1,1.67,35],[2,1.65,62.14]],"ltp":1.69,"tv":21846.68,"id":31377}]}]}
{"op":"mcm","clk":"11771069114","pt":1722748261479,"mc":[{"id":"1.231344876","rc":[{"batb":[[0,1.69,4],[1,1.68,136.44],[2,1.67,35]],"ltp":1.69,"tv":21846.68,"id":31377}]}]}
{"op":"mcm","clk":"11771069432","pt":1722748267717,"mc":[{"id":"1.231344876","rc":[{"batl":[[0,2.46,10.38]],"ltp":2.44,"tv":23574.71,"id":31379}]}]}
{"op":"mcm","clk":"11771069694","pt":1722748274121,"mc":[{"id":"1.231344876","rc":[{"batl":[[0,2.46,17.32]],"ltp":2.44,"tv":23574.71,"id":31379},{"batb":[[0,1.69,15.69]],"ltp":1.69,"tv":21846.68,"id":31377}]}]}
{"op":"mcm","clk":"11771069795","pt":1722748276501,"mc":[{"id":"1.231344876","rc":[{"batl":[[0,2.44,4],[1,2.46,21.32],[2,4,1.09]],"ltp":2.44,"tv":23574.71,"id":31379}]}]}
{"op":"mcm","clk":"11771069819","pt":1722748277011,"mc":[{"id":"1.231344876","rc":[{"batl":[[0,1.71,37.33],[1,1.72,571],[2,1.73,38.88]],"ltp":1.69,"tv":21846.68,"id":31377}]}]}
{"op":"mcm","clk":"11771070034","pt":1722748281501,"mc":[{"id":"1.231344876","rc":[{"trd":[[2.42,48.12]],"batb":[[0,2.4,40.99],[1,2.36,36.84],[2,2.34,37.15]],"batl":[[0,2.42,2.25],[1,2.44,4],[2,2.46,21.32]],"ltp":2.42,"tv":23582.71,"id":31379}],"tv":45429.4}]}
{"op":"mcm","clk":"11771070062","pt":1722748282115,"mc":[{"id":"1.231344876","rc":[{"batl":[[1,2.46,17.32],[2,4,1.09]],"ltp":2.42,"tv":23582.71,"id":31379}]}]}
{"op":"mcm","clk":"11771070146","pt":1722748284114,"mc":[{"id":"1.231344876","rc":[{"batl":[[0,2.46,17.32],[1,4,1.09],[2,8,1.09]],"ltp":2.42,"tv":23582.71,"id":31379}]}]}
{"op":"mcm","clk":"11771070531","pt":1722748291752,"mc":[{"id":"1.231344876","rc":[{"batl":[[0,2.46,21.32]],"ltp":2.42,"tv":23582.71,"id":31379}]}]}
{"op":"mcm","clk":"11771071157","pt":1722748304666,"mc":[{"id":"1.231344876","rc":[{"batb":[[0,2.44,312.35],[1,2.4,40.99],[2,2.36,36.84]],"batl":[[0,2.46,6.02]],"ltp":2.42,"tv":23582.71,"id":31379},{"batb":[[0,1.68,132.44],[1,1.67,35],[2,1.3,633.33]],"ltp":1.69,"tv":21846.68,"id":31377}]}]}
{"op":"mcm","clk":"11771071247","pt":1722748306773,"mc":[{"id":"1.231344876","rc":[{"trd":[[2.44,16916.83]],"batb":[[0,2.44,4]],"ltp":2.44,"tv":24207.42,"id":31379},{"batl":[[0,1.7,4],[1,1.71,37.33],[2,1.72,571]],"ltp":1.69,"tv":21846.68,"id":31377}],"tv":46054.1}]}
{"op":"mcm","clk":"11771071338","pt":1722748308783,"mc":[{"id":"1.231344876","rc":[{"batb":[[2,1.65,62.14]],"ltp":1.69,"tv":21846.68,"id":31377}]}]}
{"op":"mcm","clk":"11771071939","pt":1722748322084,"mc":[{"id":"1.231344876","rc":[{"batb":[[0,2.4,40.99],[1,2.36,36.84],[2,2.34,37.15]],"batl":[[0,2.46,10.02]],"ltp":2.44,"tv":24207.42,"id":31379},{"batb":[[0,1.69,4],[1,1.68,136.44],[2,1.67,35]],"ltp":1.69,"tv":21846.68,"id":31377}]}]}
{"op":"mcm","clk":"11771072036","pt":1722748324191,"mc":[{"id":"1.231344876","rc":[{"batb":[[0,1.69,11.53]],"ltp":1.69,"tv":21846.68,"id":31377}]}]}
{"op":"mcm","clk":"11771072106","pt":1722748325591,"mc":[{"id":"1.231344876","rc":[{"batb":[[0,2.44,312.35],[1,2.4,40.99],[2,2.36,36.84]],"ltp":2.44,"tv":24207.42,"id":31379},{"batb":[[0,1.69,7.53],[1,1.68,132.44]],"ltp":1.69,"tv":21846.68,"id":31377}]}]}
{"op":"mcm","clk":"11771072185","pt":1722748327388,"mc":[{"id":"1.231344876","rc":[{"batb":[[0,1.68,132.44],[1,1.67,35],[2,1.65,62.14]],"ltp":1.69,"tv":21846.68,"id":31377}]}]}
{"op":"mcm","clk":"11771072277","pt":1722748328996,"mc":[{"id":"1.231344876","rc":[{"batb":[[2,1.3,633.33]],"ltp":1.69,"tv":21846.68,"id":31377}]}]}
{"op":"mcm","clk":"11771072418","pt":1722748332083,"mc":[{"id":"1.231344876","rc":[{"trd":[[2.44,17541.54]],"batb":[[0,2.4,40.99],[1,2.36,36.84],[2,2.34,37.15]],"ltp":2.44,"tv":24832.12,"id":31379}],"tv":46678.81}]}
{"op":"mcm","clk":"11771072484","pt":1722748333476,"mc":[{"id":"1.231344876","rc":[{"batl":[[0,2.46,16.76]],"ltp":2.44,"tv":24832.12,"id":31379},{"batb":[[0,1.69,11.05],[1,1.68,132.44],[2,1.67,35]],"ltp":1.69,"tv":21846.68,"id":31377}]}]}
{"op":"mcm","clk":"11771072650","pt":1722748337698,"mc":[{"id":"1.231344876","rc":[{"trd":[[2.44,17549.54]],"batb":[[0,2.44,308.36],[1,2.42,4],[2,2.4,40.99]],"ltp":2.44,"tv":24840.12,"id":31379}],"tv":46686.81}]}
{"op":"mcm","clk":"11771072711","pt":1722748338912,"mc":[{"id":"1.231344876","rc":[{"batl":[[0,2.46,10.74]],"ltp":2.44,"tv":24840.12,"id":31379},{"batb":[[0,1.68,132.44],[1,1.67,35],[2,1.3,633.33]],"ltp":1.69,"tv":21846.68,"id":31377}]}]}
{"op":"mcm","clk":"11771072794","pt":1722748340509,"mc":[{"id":"1.231344876","rc":[{"trd":[[2.42,56.12],[2.44,18166.25]],"batb":[[0,2.4,40.99],[1,2.36,36.84],[2,2.34,37.15]],"ltp":2.42,"tv":25464.83,"id":31379}],"tv":47311.52}]}
{"op":"mcm","clk":"11771072965","pt":1722748344011,"mc":[{"id":"1.231344876","rc":[{"batb":[[2,1.65,62.14]],"ltp":1.69,"tv":21846.68,"id":31377}]}]}
{"op":"mcm","clk":"11771073143","pt":1722748347406,"mc":[{"id":"1.231344876","rc":[{"batb":[[0,2.44,312.35],[1,2.4,40.99],[2,2.36,36.84]],"ltp":2.42,"tv":25464.83,"id":31379}]}]}
{"op":"mcm","clk":"11771073229","pt":1722748348998,"mc":[{"id":"1.231344876","rc":[{"batb":[[2,1.3,633.33]],"ltp":1.69,"tv":21846.68,"id":31377}]}]}
{"op":"mcm","clk":"11771073313","pt":1722748350793,"mc":[{"id":"1.231344876","rc":[{"trd":[[2.44,18790.96]],"batb":[[0,2.4,40.99],[1,2.36,36.84],[2,2.34,37.15]],"ltp":2.44,"tv":26089.54,"id":31379}],"tv":47936.23}]}
{"op":"mcm","clk":"11771073384","pt":1722748352085,"mc":[{"id":"1.231344876","rc":[{"batb":[[0,2.42,4],[1,2.4,40.99],[2,2.36,36.84]],"ltp":2.44,"tv":26089.54,"id":31379},{"batb":[[0,1.69,4],[1,1.68,136.44],[2,1.67,35]],"ltp":1.69,"tv":21846.68,"id":31377}]}]}
{"op":"mcm","clk":"11771073554","pt":1722748356185,"mc":[{"id":"1.231344876","rc":[{"batb":[[0,2.44,312.35],[1,2.42,4],[2,2.4,40.99]],"ltp":2.44,"tv":26089.54,"id":31379},{"batb":[[0,1.68,132.44],[1,1.67,35],[2,1.65,62.14]],"ltp":1.69,"tv":21846.68,"id":31377}]}]}
{"op":"mcm","clk":"11771073713","pt":1722748359425,"mc":[{"id":"1.231344876","rc":[{"trd":[[2.44,19415.66]],"batb":[[0,2.42,4],[1,2.4,40.99],[2,2.36,36.84]],"ltp":2.44,"tv":26714.25,"id":31379},{"batb":[[2,1.3,633.33]],"ltp":1.69,"tv":21846.68,"id":31377}],"tv":48560.93}]}
{"op":"mcm","clk":"11771073904","pt":1722748364411,"mc":[{"id":"1.231344876","rc":[{"batb":[[0,2.44,312.35],[1,2.42,4],[2,2.4,40.99]],"ltp":2.44,"tv":26714.25,"id":31379},{"batb":[[2,1.65,62.14]],"ltp":1.69,"tv":21846.68,"id":31377}]}]}
{"op":"mcm","clk":"11771074029","pt":1722748367638,"mc":[{"id":"1.231344876","rc":[{"trd":[[2.44,20040.37]],"batb":[[0,2.44,4]],"ltp":2.44,"tv":27338.95,"id":31379}],"tv":49185.64}]}
{"op":"mcm","clk":"11771074050","pt":1722748368000,"mc":[{"id":"1.231344876","rc":[{"batb":[[0,2.42,4],[1,2.4,40.99],[2,2.36,36.84]],"ltp":2.44,"tv":27338.95,"id":31379}]}]}
{"op":"mcm","clk":"11771074257","pt":1722748372200,"mc":[{"id":"1.231344876","rc":[{"batb":[[0,2.44,312.35],[1,2.42,4],[2,2.4,40.99]],"ltp":2.44,"tv":27338.95,"id":31379}]}]}
{"op":"mcm","clk":"11771074343","pt":1722748374201,"mc":[{"id":"1.231344876","rc":[{"batb":[[2,1.3,633.33]],"ltp":1.69,"tv":21846.68,"id":31377}]}]}
{"op":"mcm","clk":"11771074406","pt":1722748375936,"mc":[{"id":"1.231344876","rc":[{"trd":[[2.44,20665.08]],"batb":[[0,2.42,4],[1,2.4,40.99],[2,2.36,36.84]],"ltp":2.44,"tv":27963.66,"id":31379}],"tv":49810.35}]}
{"op":"mcm","clk":"11771074541","pt":1722748379117,"mc":[{"id":"1.231344876","rc":[{"batb":[[2,1.65,62.14]],"ltp":1.69,"tv":21846.68,"id":31377}]}]}
{"op":"mcm","clk":"11771074621","pt":1722748380817,"mc":[{"id":"1.231344876","rc":[{"batb":[[0,2.44,312.35],[1,2.42,4],[2,2.4,40.99]],"ltp":2.44,"tv":27963.66,"id":31379}]}]}
{"op":"mcm","clk":"11771074683","pt":1722748382244,"mc":[{"id":"1.231344876","rc":[{"batb":[[0,2.44,316.35]],"ltp":2.44,"tv":27963.66,"id":31379}]}]}
{"op":"mcm","clk":"11771074771","pt":1722748384243,"mc":[{"id":"1.231344876","rc":[{"trd":[[2.44,21289.78]],"batb":[[0,2.42,4],[1,2.4,40.99],[2,2.36,36.84]],"ltp":2.44,"tv":28588.37,"id":31379},{"batb":[[2,1.3,633.33]],"ltp":1.69,"tv":21846.68,"id":31377}],"tv":50435.06}]}
{"op":"mcm","clk":"11771074952","pt":1722748388559,"mc":[{"id":"1.231344876","rc":[{"batb":[[0,2.44,312.35],[1,2.42,4],[2,2.4,40.99]],"ltp":2.44,"tv":28588.37,"id":31379}]}]}
{"op":"mcm","clk":"11771075070","pt":1722748391634,"mc":[{"id":"1.231344876","rc":[{"trd":[[2.44,21914.49]],"batb":[[0,2.42,4],[1,2.4,40.99],[2,2.36,36.84]],"ltp":2.44,"tv":29213.07,"id":31379}],"tv":51059.76}]}
{"op":"mcm","clk":"11771075122","pt":1722748393099,"mc":[{"id":"1.231344876","rc":[{"batl":[[0,2.46,17.47]],"ltp":2.44,"tv":29213.07,"id":31379},{"batb":[[0,1.69,11.13],[1,1.68,132.44],[2,1.67,35]],"ltp":1.69,"tv":21846.68,"id":31377}]}]}
{"op":"mcm","clk":"11771075258","pt":1722748396658,"mc":[{"id":"1.231344876","rc":[{"batb":[[0,2.44,312.35],[1,2.42,4],[2,2.4,40.99]],"ltp":2.44,"tv":29213.07,"id":31379}]}]}
{"op":"mcm","clk":"11771075281","pt":1722748397472,"mc":[{"id":"1.231344876","rc":[{"batb":[[0,2.44,316.35]],"ltp":2.44,"tv":29213.07,"id":31379}]}]}
{"op":"mcm","clk":"11771075325","pt":1722748398655,"mc":[{"id":"1.231344876","rc":[{"batl":[[0,2.46,10.74]],"ltp":2.44,"tv":29213.07,"id":31379},{"batb":[[0,1.68,132.44],[1,1.67,35],[2,1.3,633.33]],"ltp":1.69,"tv":21846.68,"id":31377}]}]}
{"op":"mcm","clk":"11771075365","pt":1722748399678,"mc":[{"id":"1.231344876","rc":[{"trd":[[2.44,22539.2]],"batb":[[0,2.44,4]],"ltp":2.44,"tv":29837.78,"id":31379}],"tv":51684.47}]}
{"op":"mcm","clk":"11771075377","pt":1722748399937,"mc":[{"id":"1.231344876","rc":[{"batb":[[0,2.42,4],[1,2.4,40.99],[2,2.36,36.84]],"ltp":2.44,"tv":29837.78,"id":31379}]}]}
{"op":"mcm","clk":"11771075576","pt":1722748404545,"mc":[{"id":"1.231344876","rc":[{"batb":[[0,2.44,312.35],[1,2.42,4],[2,2.4,40.99]],"ltp":2.44,"tv":29837.78,"id":31379},{"batb":[[2,1.65,62.14]],"ltp":1.69,"tv":21846.68,"id":31377}]}]}
{"op":"mcm","clk":"11771075716","pt":1722748408379,"mc":[{"id":"1.231344876","rc":[{"trd":[[2.44,23163.91]],"batb":[[0,2.42,4],[1,2.4,40.99],[2,2.36,36.84]],"ltp":2.44,"tv":30462.49,"id":31379}],"tv":52309.18}]}
{"op":"mcm","clk":"11771075888","pt":1722748412544,"mc":[{"id":"1.231344876","rc":[{"batb":[[0,1.69,4],[1,1.68,136.44],[2,1.67,35]],"ltp":1.69,"tv":21846.68,"id":31377}]}]}
{"op":"mcm","clk":"11771075983","pt":1722748414350,"mc":[{"id":"1.231344876","rc":[{"batb":[[0,2.44,312.35],[1,2.42,4],[2,2.4,40.99]],"ltp":2.44,"tv":30462.49,"id":31379},{"batb":[[0,1.68,132.44],[1,1.67,35],[2,1.3,633.33]],"ltp":1.69,"tv":21846.68,"id":31377}]}]}
{"op":"mcm","clk":"11771076118","pt":1722748416995,"mc":[{"id":"1.231344876","rc":[{"trd":[[2.44,23788.61]],"batb":[[0,2.42,4],[1,2.4,40.99],[2,2.36,36.84]],"ltp":2.44,"tv":31087.2,"id":31379}],"tv":52933.88}]}
{"op":"mcm","clk":"11771076210","pt":1722748419294,"mc":[{"id":"1.231344876","rc":[{"batb":[[2,1.65,62.14]],"ltp":1.69,"tv":21846.68,"id":31377}]}]}
{"op":"mcm","clk":"11771076330","pt":1722748422261,"mc":[{"id":"1.231344876","rc":[{"batb":[[0,2.44,312.35],[1,2.42,4],[2,2.4,40.99]],"ltp":2.44,"tv":31087.2,"id":31379}]}]}
{"op":"mcm","clk":"11771076409","pt":1722748424459,"mc":[{"id":"1.231344876","rc":[{"trd":[[2.44,24413.32]],"batb":[[0,2.42,4],[1,2.4,40.99],[2,2.36,36.84]],"ltp":2.44,"tv":31711.9,"id":31379},{"batb":[[2,1.3,633.33]],"ltp":1.69,"tv":21846.68,"id":31377}],"tv":53558.59}]}
{"op":"mcm","clk":"11771076416","pt":1722748424766,"mc":[{"id":"1.231344876","rc":[{"batb":[[0,1.69,7.19],[1,1.68,132.44],[2,1.67,35]],"ltp":1.69,"tv":21846.68,"id":31377}]}]}
{"op":"mcm","clk":"11771076522","pt":1722748427683,"mc":[{"id":"1.231344876","rc":[{"batb":[[0,1.69,11.19]],"ltp":1.69,"tv":21846.68,"id":31377}]}]}
{"op":"mcm","clk":"11771076621","pt":1722748429582,"mc":[{"id":"1.231344876","rc":[{"batb":[[0,2.44,312.35],[1,2.42,4],[2,2.4,40.99]],"ltp":2.44,"tv":31711.9,"id":31379}]}]}
{"op":"mcm","clk":"11771076651","pt":1722748430298,"mc":[{"id":"1.231344876","rc":[{"batb":[[0,1.68,132.44],[1,1.67,35],[2,1.3,633.33]],"ltp":1.69,"tv":21846.68,"id":31377}]}]}
{"op":"mcm","clk":"11771076713","pt":1722748432504,"mc":[{"id":"1.231344876","rc":[{"trd":[[2.44,25038.03]],"batb":[[0,2.42,4],[1,2.4,40.99],[2,2.36,36.84]],"ltp":2.44,"tv":32336.61,"id":31379}],"tv":54183.3}]}
{"op":"mcm","clk":"11771076806","pt":1722748434397,"mc":[{"id":"1.231344876","rc":[{"batb":[[2,1.65,62.14]],"ltp":1.69,"tv":21846.68,"id":31377}]}]}
{"op":"mcm","clk":"11771076930","pt":1722748437070,"mc":[{"id":"1.231344876","rc":[{"batb":[[0,2.44,312.35],[1,2.42,4],[2,2.4,40.99]],"ltp":2.44,"tv":32336.61,"id":31379}]}]}
{"op":"mcm","clk":"11771077011","pt":1722748439376,"mc":[{"id":"1.231344876","rc":[{"batb":[[2,1.3,633.33]],"ltp":1.69,"tv":21846.68,"id":31377}]}]}
{"op":"mcm","clk":"11771077055","pt":1722748440199,"mc":[{"id":"1.231344876","rc":[{"trd":[[2.44,25662.73]],"batb":[[0,2.42,4],[1,2.4,40.99],[2,2.36,36.84]],"ltp":2.44,"tv":32961.32,"id":31379}],"tv":54808.01}]}
{"op":"mcm","clk":"11771077159","pt":1722748442820,"mc":[{"id":"1.231344876","rc":[{"batb":[[0,1.69,4],[1,1.68,136.44],[2,1.67,35]],"ltp":1.69,"tv":21846.68,"id":31377}]}]}
{"op":"mcm","clk":"11771077262","pt":1722748445274,"mc":[{"id":"1.231344876","rc":[{"batb":[[0,2.44,312.35],[1,2.42,4],[2,2.4,40.99]],"ltp":2.44,"tv":32961.32,"id":31379}]}]}
{"op":"mcm","clk":"11771077293","pt":1722748445896,"mc":[{"id":"1.231344876","rc":[{"batb":[[0,1.68,132.44],[1,1.67,35],[2,1.65,62.14]],"ltp":1.69,"tv":21846.68,"id":31377}]}]}
{"op":"mcm","clk":"11771077406","pt":1722748448310,"mc":[{"id":"1.231344876","rc":[{"trd":[[2.44,26287.44]],"batb":[[0,2.42,4],[1,2.4,40.99],[2,2.36,36.84]],"ltp":2.44,"tv":33586.02,"id":31379}],"tv":55432.71}]}
{"op":"mcm","clk":"11771077451","pt":1722748449384,"mc":[{"id":"1.231344876","rc":[{"batl":[[0,2.46,17.47]],"ltp":2.44,"tv":33586.02,"id":31379},{"batb":[[0,1.69,11.13],[1,1.68,132.44],[2,1.67,35]],"ltp":1.69,"tv":21846.68,"id":31377}]}]}
{"op":"mcm","clk":"11771077633","pt":1722748453683,"mc":[{"id":"1.231344876","rc":[{"batb":[[0,2.44,312.35],[1,2.42,4],[2,2.4,40.99]],"ltp":2.44,"tv":33586.02,"id":31379}]}]}
{"op":"mcm","clk":"11771077675","pt":1722748454709,"mc":[{"id":"1.231344876","rc":[{"batl":[[0,2.46,10.74]],"ltp":2.44,"tv":33586.02,"id":31379},{"batb":[[0,1.68,132.44],[1,1.67,35],[2,1.3,633.33]],"ltp":1.69,"tv":21846.68,"id":31377}]}]}
{"op":"mcm","clk":"11771077770","pt":1722748456714,"mc":[{"id":"1.231344876","rc":[{"trd":[[2.44,26912.15]],"batb":[[0,2.42,4],[1,2.4,40.99],[2,2.36,36.84]],"ltp":2.44,"tv":34210.73,"id":31379}],"tv":56057.42}]}
{"op":"mcm","clk":"11771077818","pt":1722748457791,"mc":[{"id":"1.231344876","rc":[{"batb":[[0,1.69,4],[1,1.68,136.44],[2,1.67,35]],"ltp":1.69,"tv":21846.68,"id":31377}]}]}
{"op":"mcm","clk":"11771077987","pt":1722748462090,"mc":[{"id":"1.231344876","rc":[{"batb":[[0,2.44,312.35],[1,2.42,4],[2,2.4,40.99]],"ltp":2.44,"tv":34210.73,"id":31379}]}]}
{"op":"mcm","clk":"11771078009","pt":1722748462805,"mc":[{"id":"1.231344876","rc":[{"batb":[[0,1.68,132.44],[1,1.67,35],[2,1.65,62.14]],"ltp":1.69,"tv":21846.68,"id":31377}]}]}
{"op":"mcm","clk":"11771078071","pt":1722748464498,"mc":[{"id":"1.231344876","rc":[{"batb":[[0,1.68,112.5],[1,1.67,54.94],[2,1.3,633.33]],"ltp":1.69,"tv":21846.68,"id":31377}]}]}
{"op":"mcm","clk":"11771078110","pt":1722748465625,"mc":[{"id":"1.231344876","rc":[{"trd":[[2.44,27536.86]],"batb":[[0,2.42,4],[1,2.4,40.99],[2,2.36,36.84]],"ltp":2.44,"tv":34835.44,"id":31379}],"tv":56682.13}]}
{"op":"mcm","clk":"11771078247","pt":1722748469519,"mc":[{"id":"1.231344876","rc":[{"batb":[[2,1.65,62.14]],"ltp":1.69,"tv":21846.68,"id":31377}]}]}
{"op":"mcm","clk":"11771078272","pt":1722748470339,"mc":[{"id":"1.231344876","rc":[{"batb":[[0,2.44,312.35],[1,2.42,4],[2,2.4,40.99]],"ltp":2.44,"tv":34835.44,"id":31379}]}]}
{"op":"mcm","clk":"11771078407","pt":1722748473624,"mc":[{"id":"1.231344876","rc":[{"trd":[[2.44,28161.56]],"batb":[[0,2.44,4]],"ltp":2.44,"tv":35460.15,"id":31379}],"tv":57306.83}]}
{"op":"mcm","clk":"11771078432","pt":1722748474135,"mc":[{"id":"1.231344876","rc":[{"batb":[[0,2.42,4],[1,2.4,40.99],[2,2.36,36.84]],"ltp":2.44,"tv":35460.15,"id":31379}]}]}
{"op":"mcm","clk":"11771078673","pt":1722748479538,"mc":[{"id":"1.231344876","rc":[{"batb":[[0,2.44,312.35],[1,2.42,4],[2,2.4,40.99]],"ltp":2.44,"tv":35460.15,"id":31379},{"batb":[[2,1.3,633.33]],"ltp":1.69,"tv":21846.68,"id":31377}]}]}
{"op":"mcm","clk":"11771078776","pt":1722748482058,"mc":[{"id":"1.231344876","rc":[{"trd":[[2.44,28786.27]],"batb":[[0,2.42,4],[1,2.4,40.99],[2,2.36,36.84]],"ltp":2.44,"tv":36084.85,"id":31379}],"tv":57931.54}]}
{"op":"mcm","clk":"11771078875","pt":1722748484552,"mc":[{"id":"1.231344876","rc":[{"batb":[[2,1.65,62.14]],"ltp":1.69,"tv":21846.68,"id":31377}]}]}
{"op":"mcm","clk":"11771079009","pt":1722748487251,"mc":[{"id":"1.231344876","rc":[{"batb":[[0,2.44,312.35],[1,2.42,4],[2,2.4,40.99]],"ltp":2.44,"tv":36084.85,"id":31379}]}]}
{"op":"mcm","clk":"11771079054","pt":1722748488083,"mc":[{"id":"1.231344876","rc":[{"batb":[[0,2.44,316.35]],"ltp":2.44,"tv":36084.85,"id":31379}]}]}
{"op":"mcm","clk":"11771079148","pt":1722748489583,"mc":[{"id":"1.231344876","rc":[{"batb":[[2,1.3,633.33]],"ltp":1.69,"tv":21846.68,"id":31377}]}]}
{"op":"mcm","clk":"11771079221","pt":1722748490671,"mc":[{"id":"1.231344876","rc":[{"trd":[[2.44,29410.98]],"batb":[[0,2.44,4]],"ltp":2.44,"tv":36709.56,"id":31379}],"tv":58556.25}]}
{"op":"mcm","clk":"11771079262","pt":1722748491338,"mc":[{"id":"1.231344876","rc":[{"batb":[[0,2.42,4],[1,2.4,40.99],[2,2.36,36.84]],"ltp":2.44,"tv":36709.56,"id":31379}]}]}
{"op":"mcm","clk":"11771079398","pt":1722748494568,"mc":[{"id":"1.231344876","rc":[{"batb":[[2,1.65,62.14]],"ltp":1.69,"tv":21846.68,"id":31377}]}]}
{"op":"mcm","clk":"11771079522","pt":1722748497078,"mc":[{"id":"1.231344876","rc":[{"batb":[[0,2.44,312.35],[1,2.42,4],[2,2.4,40.99]],"ltp":2.44,"tv":36709.56,"id":31379}]}]}
{"op":"mcm","clk":"11771079627","pt":1722748499651,"mc":[{"id":"1.231344876","rc":[{"batb":[[2,1.3,633.33]],"ltp":1.69,"tv":21846.68,"id":31377}]}]}
{"op":"mcm","clk":"11771079647","pt":1722748500271,"mc":[{"id":"1.231344876","rc":[{"trd":[[2.44,30035.68]],"batb":[[0,2.42,4],[1,2.4,40.99],[2,2.36,36.84]],"ltp":2.44,"tv":37334.27,"id":31379}],"tv":59180.96}]}
{"op":"mcm","clk":"11771079786","pt":1722748503168,"mc":[{"id":"1.231344876","rc":[{"batb":[[0,1.69,4],[1,1.68,116.5],[2,1.67,54.94]],"ltp":1.69,"tv":21846.68,"id":31377}]}]}
{"op":"mcm","clk":"11771079828","pt":1722748504156,"mc":[{"id":"1.231344876","rc":[{"batl":[[0,2.46,16.66]],"ltp":2.44,"tv":37334.27,"id":31379},{"batb":[[0,1.69,14.23]],"ltp":1.69,"tv":21846.68,"id":31377}]}]}
{"op":"mcm","clk":"11771079881","pt":1722748505395,"mc":[{"id":"1.231344876","rc":[{"batb":[[0,2.44,312.35],[1,2.42,4],[2,2.4,40.99]],"ltp":2.44,"tv":37334.27,"id":31379},{"batb":[[0,1.69,10.23],[1,1.68,112.5]],"ltp":1.69,"tv":21846.68,"id":31377}]}]}
{"op":"mcm","clk":"11771079931","pt":1722748506475,"mc":[{"id":"1.231344876","rc":[{"batl":[[0,2.46,10.74]],"ltp":2.44,"tv":37334.27,"id":31379},{"batb":[[0,1.68,112.5],[1,1.67,54.94],[2,1.3,633.33]],"ltp":1.69,"tv":21846.68,"id":31377}]}]}
{"op":"mcm","clk":"11771080033","pt":1722748508883,"mc":[{"id":"1.231344876","rc":[{"trd":[[2.44,30660.39]],"batb":[[0,2.42,4],[1,2.4,40.99],[2,2.36,36.84]],"ltp":2.44,"tv":37958.97,"id":31379}],"tv":59805.66}]}
{"op":"mcm","clk":"11771080074","pt":1722748509707,"mc":[{"id":"1.231344876","rc":[{"batb":[[2,1.65,62.14]],"ltp":1.69,"tv":21846.68,"id":31377}]}]}
{"op":"mcm","clk":"11771080212","pt":1722748513086,"mc":[{"id":"1.231344876","rc":[{"batb":[[0,1.68,132.44],[1,1.67,35]],"ltp":1.69,"tv":21846.68,"id":31377}]}]}
{"op":"mcm","clk":"11771080281","pt":1722748514681,"mc":[{"id":"1.231344876","rc":[{"batb":[[0,2.44,312.35],[1,2.42,4],[2,2.4,40.99]],"ltp":2.44,"tv":37958.97,"id":31379}]}]}
{"op":"mcm","clk":"11771080413","pt":1722748518169,"mc":[{"id":"1.231344876","rc":[{"trd":[[2.44,31285.1]],"batb":[[0,2.44,4]],"ltp":2.44,"tv":38583.68,"id":31379}],"tv":60430.37}]}
{"op":"mcm","clk":"11771080446","pt":1722748518885,"mc":[{"id":"1.231344876","rc":[{"batb":[[0,2.42,4],[1,2.4,40.99],[2,2.36,36.84]],"ltp":2.44,"tv":38583.68,"id":31379}]}]}
{"op":"mcm","clk":"11771080626","pt":1722748522601,"mc":[{"id":"1.231344876","rc":[{"batb":[[0,2.44,312.35],[1,2.42,4],[2,2.4,40.99]],"ltp":2.44,"tv":38583.68,"id":31379}]}]}
{"op":"mcm","clk":"11771080629","pt":1722748522704,"mc":[{"id":"1.231344876","rc":[{"batb":[[0,1.69,7.19],[1,1.68,132.44],[2,1.67,35]],"ltp":1.69,"tv":21846.68,"id":31377}]}]}
{"op":"mcm","clk":"11771080677","pt":1722748523881,"mc":[{"id":"1.231344876","rc":[{"batb":[[0,1.68,132.44],[1,1.67,35],[2,1.65,62.14]],"ltp":1.69,"tv":21846.68,"id":31377}]}]}
{"op":"mcm","clk":"11771080718","pt":1722748524809,"mc":[{"id":"1.231344876","rc":[{"batb":[[2,1.3,633.33]],"ltp":1.69,"tv":21846.68,"id":31377}]}]}
{"op":"mcm","clk":"11771080774","pt":1722748526195,"mc":[{"id":"1.231344876","rc":[{"trd":[[2.44,31909.81]],"batb":[[0,2.42,4],[1,2.4,40.99],[2,2.36,36.84]],"ltp":2.44,"tv":39208.39,"id":31379}],"tv":61055.08}]}
{"op":"mcm","clk":"11771080907","pt":1722748529825,"mc":[{"id":"1.231344876","rc":[{"batb":[[2,1.65,62.14]],"ltp":1.69,"tv":21846.68,"id":31377}]}]}
{"op":"mcm","clk":"11771081008","pt":1722748532392,"mc":[{"id":"1.231344876","rc":[{"batb":[[0,2.44,312.35],[1,2.42,4],[2,2.4,40.99]],"ltp":2.44,"tv":39208.39,"id":31379}]}]}
{"op":"mcm","clk":"11771081052","pt":1722748533313,"mc":[{"id":"1.231344876","rc":[{"batb":[[0,2.44,316.35]],"ltp":2.44,"tv":39208.39,"id":31379}]}]}
{"op":"mcm","clk":"11771081148","pt":1722748535314,"mc":[{"id":"1.231344876","rc":[{"trd":[[2.44,32534.51]],"batb":[[0,2.44,4]],"ltp":2.44,"tv":39833.1,"id":31379},{"batb":[[2,1.3,633.33]],"ltp":1.69,"tv":21846.68,"id":31377}],"tv":61679.78}]}
{"op":"mcm","clk":"11771081172","pt":1722748535726,"mc":[{"id":"1.231344876","rc":[{"batb":[[0,2.42,4],[1,2.4,40.99],[2,2.36,36.84]],"ltp":2.44,"tv":39833.1,"id":31379}]}]}
{"op":"mcm","clk":"11771081387","pt":1722748539817,"mc":[{"id":"1.231344876","rc":[{"batb":[[2,1.65,62.14]],"ltp":1.69,"tv":21846.68,"id":31377}]}]}
{"op":"mcm","clk":"11771081465","pt":1722748541210,"mc":[{"id":"1.231344876","rc":[{"batb":[[0,2.44,312.35],[1,2.42,4],[2,2.4,40.99]],"ltp":2.44,"tv":39833.1,"id":31379}]}]}
{"op":"mcm","clk":"11771081596","pt":1722748544538,"mc":[{"id":"1.231344876","rc":[{"trd":[[2.44,33159.22]],"batb":[[0,2.42,4],[1,2.4,40.99],[2,2.36,36.84]],"ltp":2.44,"tv":40457.8,"id":31379}],"tv":62304.49}]}
{"op":"mcm","clk":"11771081775","pt":1722748548439,"mc":[{"id":"1.231344876","rc":[{"batb":[[0,1.69,4],[1,1.68,136.44],[2,1.67,35]],"ltp":1.69,"tv":21846.68,"id":31377}]}]}
{"op":"mcm","clk":"11771081869","pt":1722748550338,"mc":[{"id":"1.231344876","rc":[{"batb":[[0,2.44,312.35],[1,2.42,4],[2,2.4,40.99]],"ltp":2.44,"tv":40457.8,"id":31379},{"batb":[[0,1.68,132.44],[1,1.67,35],[2,1.65,62.14]],"ltp":1.69,"tv":21846.68,"id":31377}]}]}
{"op":"mcm","clk":"11771081980","pt":1722748552953,"mc":[{"id":"1.231344876","rc":[{"trd":[[2.44,33783.93]],"batb":[[0,2.42,4],[1,2.4,40.99],[2,2.36,36.84]],"ltp":2.44,"tv":41082.51,"id":31379}],"tv":62929.2}]}
{"op":"mcm","clk":"11771082256","pt":1722748558456,"mc":[{"id":"1.231344876","rc":[{"batb":[[0,2.44,312.35],[1,2.42,4],[2,2.4,40.99]],"batl":[[0,2.46,17.47]],"ltp":2.44,"tv":41082.51,"id":31379},{"batb":[[0,1.69,11.13],[1,1.68,132.44],[2,1.67,35]],"ltp":1.69,"tv":21846.68,"id":31377}]}]}
{"op":"mcm","clk":"11771082343","pt":1722748560656,"mc":[{"id":"1.231344876","rc":[{"batl":[[0,2.46,10.74]],"ltp":2.44,"tv":41082.51,"id":31379},{"batb":[[0,1.68,132.44],[1,1.67,35],[2,1.3,633.33]],"ltp":1.69,"tv":21846.68,"id":31377}]}]}
{"op":"mcm","clk":"11771082495","pt":1722748563629,"mc":[{"id":"1.231344876","rc":[{"trd":[[2.44,34408.64]],"batb":[[0,2.44,4]],"ltp":2.44,"tv":41707.22,"id":31379}],"tv":63553.91}]}
{"op":"mcm","clk":"11771082515","pt":1722748564038,"mc":[{"id":"1.231344876","rc":[{"batb":[[0,2.42,4],[1,2.4,40.99],[2,2.36,36.84]],"ltp":2.44,"tv":41707.22,"id":31379},{"batb":[[0,1.68,112.5],[1,1.67,54.94]],"ltp":1.69,"tv":21846.68,"id":31377}]}]}
{"op":"mcm","clk":"11771082563","pt":1722748564966,"mc":[{"id":"1.231344876","rc":[{"batb":[[2,1.65,62.14]],"ltp":1.69,"tv":21846.68,"id":31377}]}]}
{"op":"mcm","clk":"11771082788","pt":1722748569230,"mc":[{"id":"1.231344876","rc":[{"batb":[[0,2.44,312.35],[1,2.42,4],[2,2.4,40.99]],"ltp":2.44,"tv":41707.22,"id":31379}]}]}
{"op":"mcm","clk":"11771082817","pt":1722748570044,"mc":[{"id":"1.231344876","rc":[{"batb":[[2,1.3,633.33]],"ltp":1.69,"tv":21846.68,"id":31377}]}]}
{"op":"mcm","clk":"11771082927","pt":1722748572453,"mc":[{"id":"1.231344876","rc":[{"trd":[[2.44,35033.34]],"batb":[[0,2.42,4],[1,2.4,40.99],[2,2.36,36.84]],"ltp":2.44,"tv":42331.92,"id":31379}],"tv":64178.61}]}
{"op":"mcm","clk":"11771083043","pt":1722748575064,"mc":[{"id":"1.231344876","rc":[{"batb":[[2,1.65,62.14]],"ltp":1.69,"tv":21846.68,"id":31377}]}]}
{"op":"mcm","clk":"11771083158","pt":1722748578555,"mc":[{"id":"1.231344876","rc":[{"batb":[[0,1.69,4],[1,1.68,116.5],[2,1.67,54.94]],"ltp":1.69,"tv":21846.68,"id":31377}]}]}
{"op":"mcm","clk":"11771083524","pt":1722748587352,"mc":[{"id":"1.231344876","rc":[{"batb":[[0,2.44,312.35],[1,2.42,4],[2,2.4,40.99]],"ltp":2.44,"tv":42331.92,"id":31379},{"batb":[[0,1.68,112.5],[1,1.67,54.94],[2,1.65,62.14]],"ltp":1.69,"tv":21846.68,"id":31377}]}]}
{"op":"mcm","clk":"11771083681","pt":1722748590588,"mc":[{"id":"1.231344876","rc":[{"trd":[[2.44,35658.05]],"batb":[[0,2.42,4],[1,2.4,40.99],[2,2.36,36.84]],"ltp":2.44,"tv":42956.63,"id":31379},{"batb":[[2,1.3,633.33]],"ltp":1.69,"tv":21846.68,"id":31377}],"tv":64803.32}]}
{"op":"mcm","clk":"11771083847","pt":1722748593668,"mc":[{"id":"1.231344876","rc":[{"batb":[[0,1.68,116.5]],"ltp":1.69,"tv":21846.68,"id":31377}]}]}
{"op":"mcm","clk":"11771083850","pt":1722748593770,"mc":[{"id":"1.231344876","rc":[{"batb":[[0,1.69,4],[1,1.68,116.5],[2,1.67,54.94]],"ltp":1.69,"tv":21846.68,"id":31377}]}]}
{"op":"mcm","clk":"11771084589","pt":1722748611303,"mc":[{"id":"1.231344876","rc":[{"batl":[[0,2.46,16.66]],"ltp":2.44,"tv":42956.63,"id":31379},{"batb":[[0,1.69,14.23]],"ltp":1.69,"tv":21846.68,"id":31377}]}]}
{"op":"mcm","clk":"11771084640","pt":1722748612380,"mc":[{"id":"1.231344876","rc":[{"batb":[[1,1.68,136.44],[2,1.67,35]],"ltp":1.69,"tv":21846.68,"id":31377}]}]}
{"op":"mcm","clk":"11771085121","pt":1722748624418,"mc":[{"id":"1.231344876","rc":[{"batl":[[0,2.44,4],[1,2.46,16.66],[2,4,1.09]],"ltp":2.44,"tv":42956.63,"id":31379},{"batl":[[0,1.71,37.33],[1,1.72,571],[2,1.73,38.88]],"ltp":1.69,"tv":21846.68,"id":31377}]}]}
{"op":"mcm","clk":"11771087163","pt":1722748675682,"mc":[{"id":"1.231344876","rc":[{"batl":[[0,2.44,31.48]],"ltp":2.44,"tv":42956.63,"id":31379},{"batb":[[0,1.7,312.35],[1,1.69,14.23],[2,1.68,136.44]],"ltp":1.69,"tv":21846.68,"id":31377}]}]}
{"op":"mcm","clk":"11771087185","pt":1722748676196,"mc":[{"id":"1.231344876","rc":[{"batb":[[0,2.4,40.99],[1,2.36,36.84],[2,2.34,37.15]],"ltp":2.44,"tv":42956.63,"id":31379},{"batl":[[0,1.71,33.33]],"ltp":1.69,"tv":21846.68,"id":31377}]}]}
{"op":"mcm","clk":"11771087243","pt":1722748677679,"mc":[{"id":"1.231344876","rc":[{"batl":[[0,2.42,4.66],[1,4,1.09],[2,8,1.09]],"ltp":2.44,"tv":42956.63,"id":31379},{"trd":[[1.7,625.79]],"batb":[[0,1.69,4],[1,1.68,136.44],[2,1.67,35]],"ltp":1.7,"tv":22471.39,"id":31377}],"tv":65428.03}]}
{"op":"mcm","clk":"11771087258","pt":1722748678091,"mc":[{"id":"1.231344876","rc":[{"batb":[[0,1.68,132.44],[1,1.67,35],[2,1.3,633.33]],"ltp":1.7,"tv":22471.39,"id":31377}]}]}
{"op":"mcm","clk":"11771087320","pt":1722748679680,"mc":[{"id":"1.231344876","rc":[{"batl":[[0,4,1.09],[1,8,1.09],[2,20,1.45]],"ltp":2.44,"tv":42956.63,"id":31379}]}]}
{"op":"mcm","clk":"11771087323","pt":1722748679782,"mc":[{"id":"1.231344876","rc":[{"batb":[[0,2.42,12],[1,2.4,40.99],[2,2.36,36.84]],"batl":[[0,2.46,7.09],[1,4,1.09],[2,8,1.09]],"ltp":2.44,"tv":42956.63,"id":31379},{"batb":[[0,1.69,10.45],[1,1.68,132.44],[2,1.67,35]],"ltp":1.7,"tv":22471.39,"id":31377}]}]}
{"op":"mcm","clk":"11771087397","pt":1722748682013,"mc":[{"id":"1.231344876","rc":[{"batb":[[0,2.42,10]],"ltp":2.44,"tv":42956.63,"id":31379}]}]}
{"op":"mcm","clk":"11771087441","pt":1722748683092,"mc":[{"id":"1.231344876","rc":[{"batb":[[0,2.4,40.99],[1,2.36,36.84],[2,2.34,37.15]],"ltp":2.44,"tv":42956.63,"id":31379}]}]}
{"op":"mcm","clk":"11771087489","pt":1722748684272,"mc":[{"id":"1.231344876","rc":[{"batb":[[0,1.69,14.45]],"batl":[[0,1.71,37.33]],"ltp":1.7,"tv":22471.39,"id":31377}]}]}
{"op":"mcm","clk":"11771087551","pt":1722748685615,"mc":[{"id":"1.231344876","rc":[{"batb":[[0,1.69,21.37]],"ltp":1.7,"tv":22471.39,"id":31377}]}]}
{"op":"mcm","clk":"11771087827","pt":1722748693398,"mc":[{"id":"1.231344876","rc":[{"batl":[[0,2.44,26.62],[1,2.46,7.09],[2,4,1.09]],"ltp":2.44,"tv":42956.63,"id":31379},{"batb":[[0,1.7,312.35],[1,1.69,21.37],[2,1.68,132.44]],"ltp":1.7,"tv":22471.39,"id":31377}]}]}
{"op":"mcm","clk":"11771087837","pt":1722748693808,"mc":[{"id":"1.231344876","rc":[{"batl":[[0,1.71,33.33]],"ltp":1.7,"tv":22471.39,"id":31377}]}]}
{"op":"mcm","clk":"11771087880","pt":1722748694832,"mc":[{"id":"1.231344876","rc":[{"batl":[[0,2.48,24.77],[1,4,1.09],[2,8,1.09]],"ltp":2.44,"tv":42956.63,"id":31379},{"batb":[[1,1.69,4]],"ltp":1.7,"tv":22471.39,"id":31377}]}]}
{"op":"mcm","clk":"11771087948","pt":1722748696424,"mc":[{"id":"1.231344876","rc":[{"trd":[[1.7,1250.49]],"batb":[[0,1.69,4],[1,1.68,132.44],[2,1.67,35]],"ltp":1.7,"tv":23096.1,"id":31377}],"tv":66052.73}]}
{"op":"mcm","clk":"11771087969","pt":1722748697086,"mc":[{"id":"1.231344876","rc":[{"batl":[[0,2.46,5.58],[1,2.48,24.77],[2,4,1.09]],"ltp":2.44,"tv":42956.63,"id":31379}]}]}
{"op":"mcm","clk":"11771088002","pt":1722748698315,"mc":[{"id":"1.231344876","rc":[{"batl":[[0,2.46,10.16]],"ltp":2.44,"tv":42956.63,"id":31379}]}]}
{"op":"mcm","clk":"11771088043","pt":1722748699393,"mc":[{"id":"1.231344876","rc":[{"batl":[[0,2.46,14.16]],"ltp":2.44,"tv":42956.63,"id":31379},{"batl":[[0,1.71,37.33]],"ltp":1.7,"tv":23096.1,"id":31377}]}]}
{"op":"mcm","clk":"11771088366","pt":1722748708527,"mc":[{"id":"1.231344876","rc":[{"batl":[[0,2.44,37.56],[1,2.46,14.16],[2,2.48,24.77]],"ltp":2.44,"tv":42956.63,"id":31379},{"batb":[[0,1.7,468.53],[1,1.69,4],[2,1.68,112.5]],"batl":[[0,1.71,33.33]],"ltp":1.7,"tv":23096.1,"id":31377}]}]}
{"op":"mcm","clk":"11771088412","pt":1722748709508,"mc":[{"id":"1.231344876","rc":[{"batl":[[1,2.46,9.58]],"ltp":2.44,"tv":42956.63,"id":31379}]}]}
{"op":"mcm","clk":"11771088472","pt":1722748710632,"mc":[{"id":"1.231344876","rc":[{"batb":[[0,2.4,4]],"batl":[[1,2.46,4]],"ltp":2.44,"tv":42956.63,"id":31379}]}]}
{"op":"mcm","clk":"11771088538","pt":1722748712734,"mc":[{"id":"1.231344876","rc":[{"trd":[[1.7,2109.47]],"batb":[[0,1.7,39.04]],"ltp":1.7,"tv":23955.07,"id":31377}],"tv":66911.71}]}
{"op":"mcm","clk":"11771088603","pt":1722748714528,"mc":[{"id":"1.231344876","rc":[{"batl":[[0,2.44,41.56]],"ltp":2.44,"tv":42956.63,"id":31379},{"batb":[[0,1.7,43.04]],"ltp":1.7,"tv":23955.07,"id":31377}]}]}
{"op":"mcm","clk":"11771088831","pt":1722748720638,"mc":[{"id":"1.231344876","rc":[{"batl":[[0,2.48,24.77],[1,4,1.09],[2,8,1.09]],"ltp":2.44,"tv":42956.63,"id":31379},{"trd":[[1.7,2187.56]],"batb":[[0,1.68,112.5],[1,1.67,54.94],[2,1.65,62.14]],"ltp":1.7,"tv":24033.16,"id":31377}],"tv":66989.79}]}
{"op":"mcm","clk":"11771089121","pt":1722748728621,"mc":[{"id":"1.231344876","rc":[{"batb":[[0,1.7,468.53],[1,1.68,112.5],[2,1.67,54.94]],"ltp":1.7,"tv":24033.16,"id":31377}]}]}
{"op":"mcm","clk":"11771089141","pt":1722748729548,"mc":[{"id":"1.231344876","rc":[{"batl":[[0,2.42,4],[1,2.44,4],[2,2.48,24.77]],"ltp":2.44,"tv":42956.63,"id":31379},{"batb":[[0,1.7,472.53]],"ltp":1.7,"tv":24033.16,"id":31377}]}]}
{"op":"mcm","clk":"11771089149","pt":1722748729752,"mc":[{"id":"1.231344876","rc":[{"batl":[[0,2.42,8.66]],"ltp":2.44,"tv":42956.63,"id":31379}]}]}
{"op":"mcm","clk":"11771089254","pt":1722748732473,"mc":[{"id":"1.231344876","rc":[{"batl":[[0,2.42,4.66],[1,2.48,24.77],[2,4,1.09]],"ltp":2.44,"tv":42956.63,"id":31379},{"trd":[[1.7,3124.62]],"batb":[[0,1.68,112.5],[1,1.67,54.94],[2,1.65,62.14]],"ltp":1.7,"tv":24970.22,"id":31377}],"tv":67926.86}]}
{"op":"mcm","clk":"11771089308","pt":1722748733856,"mc":[{"id":"1.231344876","rc":[{"batl":[[0,2.46,7.93]],"ltp":2.44,"tv":42956.63,"id":31379},{"batb":[[0,1.69,8.95],[1,1.68,112.5],[2,1.67,54.94]],"ltp":1.7,"tv":24970.22,"id":31377}]}]}
{"op":"mcm","clk":"11771089525","pt":1722748740877,"mc":[{"id":"1.231344876","rc":[{"batl":[[0,2.44,37.34],[1,2.46,7.93],[2,2.48,24.77]],"ltp":2.44,"tv":42956.63,"id":31379},{"batb":[[0,1.7,468.53],[1,1.69,8.95],[2,1.68,112.5]],"ltp":1.7,"tv":24970.22,"id":31377}]}]}
{"op":"mcm","clk":"11771089579","pt":1722748742480,"mc":[{"id":"1.231344876","rc":[{"batl":[[0,2.48,24.77],[1,4,1.09],[2,8,1.09]],"ltp":2.44,"tv":42956.63,"id":31379},{"batb":[[1,1.68,112.5],[2,1.67,54.94]],"ltp":1.7,"tv":24970.22,"id":31377}]}]}
{"op":"mcm","clk":"11771089662","pt":1722748744647,"mc":[{"id":"1.231344876","rc":[{"batl":[[0,2.42,4],[1,2.48,24.77],[2,4,1.09]],"ltp":2.44,"tv":42956.63,"id":31379},{"trd":[[1.7,4061.68]],"batb":[[0,1.68,112.5],[1,1.67,54.94],[2,1.65,62.14]],"ltp":1.7,"tv":25907.28,"id":31377}],"tv":68863.92}]}
{"op":"mcm","clk":"11771089691","pt":1722748745271,"mc":[{"id":"1.231344876","rc":[{"batl":[[0,2.48,24.77],[1,4,1.09],[2,8,1.09]],"ltp":2.44,"tv":42956.63,"id":31379}]}]}
{"op":"mcm","clk":"11771089901","pt":1722748751683,"mc":[{"id":"1.231344876","rc":[{"batl":[[0,2.46,4.58],[1,2.48,24.77],[2,4,1.09]],"ltp":2.44,"tv":42956.63,"id":31379},{"batb":[[0,1.7,468.53],[1,1.68,112.5],[2,1.67,54.94]],"ltp":1.7,"tv":25907.28,"id":31377}]}]}
{"op":"mcm","clk":"11771089905","pt":1722748751784,"mc":[{"id":"1.231344876","rc":[{"batl":[[0,2.44,36.63],[1,2.46,4.58],[2,2.48,24.77]],"ltp":2.44,"tv":42956.63,"id":31379}]}]}
{"op":"mcm","clk":"11771089946","pt":1722748753063,"mc":[{"id":"1.231344876","rc":[{"batl":[[0,2.48,24.77],[1,4,1.09],[2,8,1.09]],"ltp":2.44,"tv":42956.63,"id":31379}]}]}
{"op":"mcm","clk":"11771090004","pt":1722748754687,"mc":[{"id":"1.231344876","rc":[{"trd":[[1.7,4998.74]],"batb":[[0,1.68,112.5],[1,1.67,54.94],[2,1.65,62.14]],"ltp":1.7,"tv":26844.34,"id":31377}],"tv":69800.98}]}
{"op":"mcm","clk":"11771090221","pt":1722748760587,"mc":[{"id":"1.231344876","rc":[{"batl":[[0,2.44,37.3],[1,2.46,4],[2,2.48,28.77]],"ltp":2.44,"tv":42956.63,"id":31379},{"batb":[[0,1.7,468.53],[1,1.69,4],[2,1.68,116.5]],"batl":[[0,1.71,37.33]],"ltp":1.7,"tv":26844.34,"id":31377}]}]}
{"op":"mcm","clk":"11771090243","pt":1722748761267,"mc":[{"id":"1.231344876","rc":[{"batl":[[0,1.71,33.33]],"ltp":1.7,"tv":26844.34,"id":31377}]}]}
{"op":"mcm","clk":"11771090299","pt":1722748762487,"mc":[{"id":"1.231344876","rc":[{"batb":[[0,1.7,487.96]],"ltp":1.7,"tv":26844.34,"id":31377}]}]}
{"op":"mcm","clk":"11771090358","pt":1722748763985,"mc":[{"id":"1.231344876","rc":[{"batl":[[0,2.46,4],[1,2.48,28.77],[2,4,1.09]],"ltp":2.44,"tv":42956.63,"id":31379},{"trd":[[1.7,5935.8]],"batb":[[0,1.7,19.43]],"ltp":1.7,"tv":27781.4,"id":31377}],"tv":70738.04}]}
{"op":"mcm","clk":"11771090408","pt":1722748765165,"mc":[{"id":"1.231344876","rc":[{"batl":[[0,2.48,24.77],[1,4,1.09],[2,8,1.09]],"ltp":2.44,"tv":42956.63,"id":31379},{"batb":[[1,1.68,112.5],[2,1.67,35]],"ltp":1.7,"tv":27781.4,"id":31377}]}]}
{"op":"mcm","clk":"11771090595","pt":1722748769492,"mc":[{"id":"1.231344876","rc":[{"batb":[[0,1.7,487.96]],"ltp":1.7,"tv":27781.4,"id":31377}]}]}
{"op":"mcm","clk":"11771090704","pt":1722748772785,"mc":[{"id":"1.231344876","rc":[{"batb":[[0,1.7,19.43]],"ltp":1.7,"tv":27781.4,"id":31377}]}]}
{"op":"mcm","clk":"11771090773","pt":1722748774889,"mc":[{"id":"1.231344876","rc":[{"batl":[[0,2.44,4],[1,2.48,24.77],[2,4,1.09]],"ltp":2.44,"tv":42956.63,"id":31379},{"batl":[[0,1.71,37.33]],"ltp":1.7,"tv":27781.4,"id":31377}]}]}
{"op":"mcm","clk":"11771091049","pt":1722748783115,"mc":[{"id":"1.231344876","rc":[{"batl":[[0,2.42,4.66]],"ltp":2.44,"tv":42956.63,"id":31379}]}]}
{"op":"mcm","clk":"11771092230","pt":1722748811460,"mc":[{"id":"1.231344876","rc":[{"batb":[[0,1.68,112.5],[1,1.67,35],[2,1.65,62.14]],"ltp":1.7,"tv":27781.4,"id":31377}]}]}
{"op":"mcm","clk":"11771092307","pt":1722748813051,"mc":[{"id":"1.231344876","rc":[{"batl":[[0,2.46,12.51]],"ltp":2.44,"tv":42956.63,"id":31379},{"batb":[[0,1.69,8.95],[1,1.68,112.5],[2,1.67,35]],"ltp":1.7,"tv":27781.4,"id":31377}]}]}
{"op":"mcm","clk":"11771092612","pt":1722748820292,"mc":[{"id":"1.231344876","rc":[{"batl":[[0,2.46,16.51]],"ltp":2.44,"tv":42956.63,"id":31379},{"batb":[[0,1.69,12.95]],"ltp":1.7,"tv":27781.4,"id":31377}]}]}
{"op":"mcm","clk":"11771092700","pt":1722748822062,"mc":[{"id":"1.231344876","rc":[{"batb":[[0,1.69,19.57]],"ltp":1.7,"tv":27781.4,"id":31377}]}]}
{"op":"mcm","clk":"11771092952","pt":1722748827685,"mc":[{"id":"1.231344876","rc":[{"batl":[[0,2.44,37.52],[1,2.46,16.51],[2,2.48,24.77]],"ltp":2.44,"tv":42956.63,"id":31379},{"batb":[[0,1.7,468.53],[1,1.69,19.57],[2,1.68,112.5]],"ltp":1.7,"tv":27781.4,"id":31377}]}]}
{"op":"mcm","clk":"11771092970","pt":1722748828371,"mc":[{"id":"1.231344876","rc":[{"batl":[[0,1.71,33.33]],"ltp":1.7,"tv":27781.4,"id":31377}]}]}
{"op":"mcm","clk":"11771092992","pt":1722748828876,"mc":[{"id":"1.231344876","rc":[{"batl":[[1,2.46,4]],"ltp":2.44,"tv":42956.63,"id":31379},{"batb":[[1,1.69,4]],"ltp":1.7,"tv":27781.4,"id":31377}]}]}
{"op":"mcm","clk":"11771093046","pt":1722748830366,"mc":[{"id":"1.231344876","rc":[{"batl":[[0,2.46,4],[1,2.48,24.77],[2,4,1.09]],"ltp":2.44,"tv":42956.63,"id":31379},{"trd":[[1.7,6872.86]],"batb":[[0,1.69,4],[1,1.68,112.5],[2,1.67,35]],"ltp":1.7,"tv":28718.46,"id":31377}],"tv":71675.1}]}
{"op":"mcm","clk":"11771093082","pt":1722748831085,"mc":[{"id":"1.231344876","rc":[{"batl":[[0,2.46,9.11]],"ltp":2.44,"tv":42956.63,"id":31379}]}]}
{"op":"mcm","clk":"11771093277","pt":1722748835672,"mc":[{"id":"1.231344876","rc":[{"batb":[[0,1.7,468.53],[1,1.69,4],[2,1.68,112.5]],"batl":[[0,1.71,37.33]],"ltp":1.7,"tv":28718.46,"id":31377}]}]}
{"op":"mcm","clk":"11771093301","pt":1722748836388,"mc":[{"id":"1.231344876","rc":[{"batl":[[0,2.44,36.15],[1,2.46,9.11],[2,2.48,24.77]],"ltp":2.44,"tv":42956.63,"id":31379},{"batl":[[0,1.71,33.33]],"ltp":1.7,"tv":28718.46,"id":31377}]}]}
{"op":"mcm","clk":"11771093330","pt":1722748837217,"mc":[{"id":"1.231344876","rc":[{"batl":[[1,2.46,4]],"ltp":2.44,"tv":42956.63,"id":31379}]}]}
{"op":"mcm","clk":"11771093357","pt":1722748837787,"mc":[{"id":"1.231344876","rc":[{"batl":[[0,2.42,4.66],[1,2.44,36.15],[2,2.46,4]],"ltp":2.44,"tv":42956.63,"id":31379}]}]}
{"op":"mcm","clk":"11771093463","pt":1722748840568,"mc":[{"id":"1.231344876","rc":[{"batl":[[1,2.48,24.77],[2,4,1.09]],"ltp":2.44,"tv":42956.63,"id":31379},{"trd":[[1.7,7809.92]],"batb":[[0,1.68,112.5],[1,1.67,35],[2,1.65,62.14]],"ltp":1.7,"tv":29655.52,"id":31377}],"tv":72612.16}]}
{"op":"mcm","clk":"11771093489","pt":1722748841494,"mc":[{"id":"1.231344876","rc":[{"batl":[[0,2.48,24.77],[1,4,1.09],[2,8,1.09]],"ltp":2.44,"tv":42956.63,"id":31379}]}]}
{"op":"mcm","clk":"11771093635","pt":1722748846010,"mc":[{"id":"1.231344876","rc":[{"batb":[[0,1.7,468.53],[1,1.68,112.5],[2,1.67,35]],"ltp":1.7,"tv":29655.52,"id":31377}]}]}
{"op":"mcm","clk":"11771093787","pt":1722748850496,"mc":[{"id":"1.231344876","rc":[{"batl":[[0,2.42,4],[1,2.44,4],[2,2.48,24.77]],"ltp":2.44,"tv":42956.63,"id":31379},{"batb":[[0,1.7,472.53]],"ltp":1.7,"tv":29655.52,"id":31377}]}]}
{"op":"mcm","clk":"11771093938","pt":1722748853429,"mc":[{"id":"1.231344876","rc":[{"trd":[[1.7,8746.98]],"batb":[[0,1.7,4]],"ltp":1.7,"tv":30592.58,"id":31377}],"tv":73549.22}]}
{"op":"mcm","clk":"11771093969","pt":1722748854046,"mc":[{"id":"1.231344876","rc":[{"batl":[[0,2.48,24.77],[1,4,1.09],[2,8,1.09]],"ltp":2.44,"tv":42956.63,"id":31379},{"batb":[[0,1.68,112.5],[1,1.67,35],[2,1.65,62.14]],"ltp":1.7,"tv":30592.58,"id":31377}]}]}
{"op":"mcm","clk":"11771094193","pt":1722748859543,"mc":[{"id":"1.231344876","rc":[{"batb":[[1,1.67,54.94]],"ltp":1.7,"tv":30592.58,"id":31377}]}]}
{"op":"mcm","clk":"11771094213","pt":1722748860010,"mc":[{"id":"1.231344876","rc":[{"batb":[[0,1.7,468.53],[1,1.68,112.5],[2,1.67,54.94]],"ltp":1.7,"tv":30592.58,"id":31377}]}]}
{"op":"mcm","clk":"11771094359","pt":1722748863667,"mc":[{"id":"1.231344876","rc":[{"trd":[[1.7,9684.04]],"batb":[[0,1.68,112.5],[1,1.67,54.94],[2,1.65,62.14]],"ltp":1.7,"tv":31529.64,"id":31377}],"tv":74486.28}]}
{"op":"mcm","clk":"11771094441","pt":1722748865624,"mc":[{"id":"1.231344876","rc":[{"batl":[[0,2.46,4],[1,2.48,28.77],[2,4,1.09]],"ltp":2.44,"tv":42956.63,"id":31379},{"batb":[[0,1.69,4],[1,1.68,116.5],[2,1.67,54.94]],"ltp":1.7,"tv":31529.64,"id":31377}]}]}
{"op":"mcm","clk":"11771094446","pt":1722748865730,"mc":[{"id":"1.231344876","rc":[{"batl":[[0,2.46,16.16]],"ltp":2.44,"tv":42956.63,"id":31379},{"batb":[[0,1.69,12.45]],"batl":[[0,1.71,37.33]],"ltp":1.7,"tv":31529.64,"id":31377}]}]}
{"op":"mcm","clk":"11771094621","pt":1722748870212,"mc":[{"id":"1.231344876","rc":[{"batl":[[0,2.44,38.66],[1,2.46,16.16],[2,2.48,28.77]],"ltp":2.44,"tv":42956.63,"id":31379},{"batb":[[0,1.7,468.53],[1,1.69,12.45],[2,1.68,116.5]],"batl":[[0,1.71,33.33]],"ltp":1.7,"tv":31529.64,"id":31377}]}]}
{"op":"mcm","clk":"11771094653","pt":1722748871133,"mc":[{"id":"1.231344876","rc":[{"batl":[[1,2.46,4]],"ltp":2.44,"tv":42956.63,"id":31379},{"batb":[[1,1.69,4]],"ltp":1.7,"tv":31529.64,"id":31377}]}]}
{"op":"mcm","clk":"11771094730","pt":1722748873359,"mc":[{"id":"1.231344876","rc":[{"batl":[[0,2.46,4],[1,2.48,28.77],[2,4,1.09]],"ltp":2.44,"tv":42956.63,"id":31379},{"trd":[[1.7,10621.1]],"batb":[[0,1.69,4],[1,1.68,116.5],[2,1.67,54.94]],"ltp":1.7,"tv":32466.71,"id":31377}],"tv":75423.34}]}
{"op":"mcm","clk":"11771094993","pt":1722748879933,"mc":[{"id":"1.231344876","rc":[{"batl":[[0,2.44,37.3],[1,2.46,4],[2,2.48,28.77]],"ltp":2.44,"tv":42956.63,"id":31379},{"batb":[[0,1.7,468.53],[1,1.69,4],[2,1.68,116.5]],"ltp":1.7,"tv":32466.71,"id":31377}]}]}
{"op":"mcm","clk":"11771095042","pt":1722748880807,"mc":[{"id":"1.231344876","rc":[{"batl":[[0,2.42,4],[1,2.44,41.3],[2,2.46,4]],"ltp":2.44,"tv":42956.63,"id":31379},{"batb":[[0,1.7,472.53]],"ltp":1.7,"tv":32466.71,"id":31377}]}]}
{"op":"mcm","clk":"11771095126","pt":1722748882660,"mc":[{"id":"1.231344876","rc":[{"trd":[[1.7,11558.16]],"batb":[[0,1.7,4]],"ltp":1.7,"tv":33403.77,"id":31377}],"tv":76360.4}]}
{"op":"mcm","clk":"11771095176","pt":1722748883532,"mc":[{"id":"1.231344876","rc":[{"batl":[[0,2.48,24.77],[1,4,1.09],[2,8,1.09]],"ltp":2.44,"tv":42956.63,"id":31379},{"batb":[[0,1.68,112.5],[1,1.67,54.94],[2,1.65,62.14]],"ltp":1.7,"tv":33403.77,"id":31377}]}]}
{"op":"mcm","clk":"11771095405","pt":1722748889343,"mc":[{"id":"1.231344876","rc":[{"batl":[[0,2.42,4.66],[1,2.48,24.77],[2,4,1.09]],"ltp":2.44,"tv":42956.63,"id":31379},{"batb":[[0,1.7,468.53],[1,1.68,112.5],[2,1.67,54.94]],"ltp":1.7,"tv":33403.77,"id":31377}]}]}
{"op":"mcm","clk":"11771095590","pt":1722748894790,"mc":[{"id":"1.231344876","rc":[{"trd":[[1.7,12495.22]],"batb":[[0,1.68,112.5],[1,1.67,54.94],[2,1.65,62.14]],"ltp":1.7,"tv":34340.83,"id":31377}],"tv":77297.46}]}
{"op":"mcm","clk":"11771095649","pt":1722748896335,"mc":[{"id":"1.231344876","rc":[{"batl":[[0,2.48,24.77],[1,4,1.09],[2,8,1.09]],"ltp":2.44,"tv":42956.63,"id":31379},{"batl":[[0,1.71,37.33]],"ltp":1.7,"tv":34340.83,"id":31377}]}]}
{"op":"mcm","clk":"11771095950","pt":1722748904532,"mc":[{"id":"1.231344876","rc":[{"batb":[[0,1.7,468.53],[1,1.68,112.5],[2,1.67,54.94]],"ltp":1.7,"tv":34340.83,"id":31377}]}]}
{"op":"mcm","clk":"11771095972","pt":1722748905246,"mc":[{"id":"1.231344876","rc":[{"batl":[[0,1.71,33.33]],"ltp":1.7,"tv":34340.83,"id":31377}]}]}
{"op":"mcm","clk":"11771096095","pt":1722748908730,"mc":[{"id":"1.231344876","rc":[{"trd":[[1.7,13432.28]],"batb":[[0,1.68,112.5],[1,1.67,54.94],[2,1.65,62.14]],"ltp":1.7,"tv":35277.89,"id":31377}],"tv":78234.52}]}
{"op":"mcm","clk":"11771096173","pt":1722748911042,"mc":[{"id":"1.231344876","rc":[{"batl":[[0,2.46,4],[1,2.48,28.77],[2,4,1.09]],"ltp":2.44,"tv":42956.63,"id":31379},{"batb":[[0,1.69,4],[1,1.68,116.5],[2,1.67,54.94]],"batl":[[0,1.71,37.33]],"ltp":1.7,"tv":35277.89,"id":31377}]}]}
{"op":"mcm","clk":"11771096238","pt":1722748912474,"mc":[{"id":"1.231344876","rc":[{"batb":[[2,1.67,35]],"ltp":1.7,"tv":35277.89,"id":31377}]}]}
{"op":"mcm","clk":"11771096327","pt":1722748914578,"mc":[{"id":"1.231344876","rc":[{"batl":[[0,2.44,36.28],[1,2.46,4],[2,2.48,28.77]],"ltp":2.44,"tv":42956.63,"id":31379},{"batb":[[0,1.7,468.53],[1,1.69,4],[2,1.68,116.5]],"batl":[[0,1.71,33.33]],"ltp":1.7,"tv":35277.89,"id":31377}]}]}
{"op":"mcm","clk":"11771096436","pt":1722748917656,"mc":[{"id":"1.231344876","rc":[{"batl":[[0,2.46,4],[1,2.48,28.77],[2,4,1.09]],"ltp":2.44,"tv":42956.63,"id":31379},{"trd":[[1.7,14369.34]],"batb":[[0,1.69,4],[1,1.68,116.5],[2,1.67,35]],"ltp":1.7,"tv":36214.95,"id":31377}],"tv":79171.58}]}
{"op":"mcm","clk":"11771096469","pt":1722748918579,"mc":[{"id":"1.231344876","rc":[{"batl":[[0,2.46,17.18]],"ltp":2.44,"tv":42956.63,"id":31379},{"batb":[[0,1.69,13.49]],"ltp":1.7,"tv":36214.95,"id":31377}]}]}
{"op":"mcm","clk":"11771096571","pt":1722748921446,"mc":[{"id":"1.231344876","rc":[{"batb":[[0,1.69,20.37]],"ltp":1.7,"tv":36214.95,"id":31377}]}]}
{"op":"mcm","clk":"11771096615","pt":1722748922478,"mc":[{"id":"1.231344876","rc":[{"batl":[[0,2.44,38.12],[1,2.46,17.18],[2,2.48,28.77]],"ltp":2.44,"tv":42956.63,"id":31379},{"batb":[[0,1.7,468.53],[1,1.69,20.37],[2,1.68,116.5]],"ltp":1.7,"tv":36214.95,"id":31377}]}]}
{"op":"mcm","clk":"11771096644","pt":1722748922943,"mc":[{"id":"1.231344876","rc":[{"batb":[[1,1.69,13.49]],"ltp":1.7,"tv":36214.95,"id":31377}]}]}
{"op":"mcm","clk":"11771096706","pt":1722748924279,"mc":[{"id":"1.231344876","rc":[{"batl":[[1,2.46,4]],"ltp":2.44,"tv":42956.63,"id":31379},{"batb":[[1,1.69,4]],"ltp":1.7,"tv":36214.95,"id":31377}]}]}
{"op":"mcm","clk":"11771096822","pt":1722748926693,"mc":[{"id":"1.231344876","rc":[{"batl":[[0,2.42,4],[1,2.44,4],[2,2.46,4]],"ltp":2.44,"tv":42956.63,"id":31379},{"trd":[[1.7,15306.41]],"batb":[[0,1.7,4]],"ltp":1.7,"tv":37152.01,"id":31377}],"tv":80108.65}]}
{"op":"mcm","clk":"11771096849","pt":1722748927364,"mc":[{"id":"1.231344876","rc":[{"batl":[[0,2.48,24.77],[1,4,1.09],[2,8,1.09]],"ltp":2.44,"tv":42956.63,"id":31379},{"batb":[[0,1.68,112.5],[1,1.67,35],[2,1.65,62.14]],"ltp":1.7,"tv":37152.01,"id":31377}]}]}
{"op":"mcm","clk":"11771097077","pt":1722748933992,"mc":[{"id":"1.231344876","rc":[{"batb":[[0,1.7,468.53],[1,1.68,112.5],[2,1.67,35]],"ltp":1.7,"tv":37152.01,"id":31377}]}]}
{"op":"mcm","clk":"11771097167","pt":1722748936972,"mc":[{"id":"1.231344876","rc":[{"trd":[[1.7,16243.47]],"batb":[[0,1.68,112.5],[1,1.67,35],[2,1.65,62.14]],"ltp":1.7,"tv":38089.07,"id":31377}],"tv":81045.71}]}
{"op":"mcm","clk":"11771097309","pt":1722748941271,"mc":[{"id":"1.231344876","rc":[{"batl":[[0,2.46,4],[1,2.48,28.77],[2,4,1.09]],"ltp":2.44,"tv":42956.63,"id":31379},{"batb":[[0,1.69,4],[1,1.68,116.5],[2,1.67,35]],"batl":[[0,1.71,37.33]],"ltp":1.7,"tv":38089.07,"id":31377}]}]}
{"op":"mcm","clk":"11771097357","pt":1722748942600,"mc":[{"id":"1.231344876","rc":[{"batl":[[0,2.44,36.28],[1,2.46,4],[2,2.48,28.77]],"ltp":2.44,"tv":42956.63,"id":31379},{"batb":[[0,1.7,468.53],[1,1.69,4],[2,1.68,116.5]],"ltp":1.7,"tv":38089.07,"id":31377}]}]}
{"op":"mcm","clk":"11771097367","pt":1722748943008,"mc":[{"id":"1.231344876","rc":[{"batl":[[0,1.71,33.33]],"ltp":1.7,"tv":38089.07,"id":31377}]}]}
{"op":"mcm","clk":"11771097403","pt":1722748944290,"mc":[{"id":"1.231344876","rc":[{"batl":[[0,2.42,4.66],[1,2.44,36.28],[2,2.46,4]],"ltp":2.44,"tv":42956.63,"id":31379}]}]}
{"op":"mcm","clk":"11771097470","pt":1722748946502,"mc":[{"id":"1.231344876","rc":[{"trd":[[1.7,17180.53]],"batb":[[0,1.69,4],[1,1.68,116.5],[2,1.67,35]],"ltp":1.7,"tv":39026.13,"id":31377}],"tv":81982.77}]}
