{"op":"mcm","clk":"11956114052","pt":1724540932600,"mc":[{"id":"1.232245129","marketDefinition":{"bspMarket":false,"turnInPlayEnabled":true,"persistenceEnabled":true,"marketBaseRate":5.0,"eventId":"33524813","eventTypeId":"4","numberOfWinners":1,"bettingType":"ODDS","marketType":"MATCH_ODDS","marketTime":"2024-08-25T16:30:00.000Z","suspendTime":"2024-08-25T16:30:00.000Z","bspReconciled":false,"complete":true,"inPlay":false,"crossMatching":true,"runnersVoidable":false,"numberOfActiveRunners":2,"betDelay":0,"status":"OPEN","runners":[{"status":"ACTIVE","sortPriority":1,"id":72922097,"name":"Caribbean Tigers"},{"status":"ACTIVE","sortPriority":2,"id":67083366,"name":"New York Strikers"}],"regulators":["MR_INT"],"countryCode":"GB","discountAllowed":false,"timezone":"GMT","openDate":"2024-08-25T16:30:00.000Z","version":6097441719,"name":"Match Odds","eventName":"Caribbean Tigers v New York Strikers"},"rc":[{"batb":[[0,1.03,200],[1,1.02,200],[2,1.01,220]],"ltp":0.0,"tv":0.0,"id":67083366},{"batb":[[0,1.03,200],[1,1.01,20]],"ltp":0.0,"tv":0.0,"id":72922097}]}]}
{"op":"mcm","clk":"11956114115","pt":1724540933521,"mc":[{"id":"1.232245129","rc":[{"batb":[[1,1.02,200],[2,1.01,220]],"ltp":0.0,"tv":0.0,"id":72922097}]}]}
{"op":"mcm","clk":"11956114184","pt":1724540934345,"mc":[{"id":"1.232245129","marketDefinition":{"bspMarket":false,"turnInPlayEnabled":true,"persistenceEnabled":true,"marketBaseRate":5.0,"eventId":"33524813","eventTypeId":"4","numberOfWinners":1,"bettingType":"ODDS","marketType":"MATCH_ODDS","marketTime":"2024-08-25T16:30:00.000Z","suspendTime":"2024-08-25T16:30:00.000Z","bspReconciled":false,"complete":true,"inPlay":false,"crossMatching":true,"runnersVoidable":false,"numberOfActiveRunners":2,"betDelay":0,"status":"OPEN","runners":[{"status":"ACTIVE","sortPriority":1,"id":72922097,"name":"Caribbean Tigers"},{"status":"ACTIVE","sortPriority":2,"id":67083366,"name":"New York Strikers"}],"regulators":["MR_INT"],"countryCode":"GB","discountAllowed":true,"timezone":"GMT","openDate":"2024-08-25T16:30:00.000Z","version":6097441719,"name":"Match Odds","eventName":"Caribbean Tigers v New York Strikers"}}]}
{"op":"mcm","clk":"11956304422","pt":1724543245270,"mc":[{"id":"1.232245129","rc":[{"batb":[[0,2.54,27.88],[1,1.03,200],[2,1.02,200]],"ltp":0.0,"tv":0.0,"id":67083366},{"batb":[[0,1.59,72.79],[1,1.03,200],[2,1.02,200]],"ltp":0.0,"tv":0.0,"id":72922097}]}]}
{"op":"mcm","clk":"11956586418","pt":1724546836575,"mc":[{"id":"1.232245129","rc":[{"batb":[[0,1.6,5.33],[1,1.59,72.79],[2,1.03,200]],"ltp":0.0,"tv":0.0,"id":72922097}]}]}
{"op":"mcm","clk":"11957463929","pt":1724558699718,"mc":[{"id":"1.232245129","rc":[{"trd":[[1.6,10.66]],"batb":[[0,1.59,72.79],[1,1.03,200],[2,1.02,200]],"batl":[[0,1.6,1725.44]],"ltp":1.6,"tv":10.66,"id":72922097}],"tv":10.66}]}
{"op":"mcm","clk":"11957671301","pt":1724562206979,"mc":[{"id":"1.232245129","rc":[{"batb":[[0,2.58,27.18]],"ltp":0.0,"tv":0.0,"id":67083366},{"batb":[[0,1.58,74.05]],"ltp":1.6,"tv":10.66,"id":72922097}]}]}
{"op":"mcm","clk":"11957679362","pt":1724562325962,"mc":[{"id":"1.232245129","rc":[{"trd":[[1.58,148.1]],"batb":[[0,1.03,200],[1,1.02,200],[2,1.01,480.16]],"batl":[[0,1.57,773.61],[1,1.6,1725.44]],"ltp":1.58,"tv":158.76,"id":72922097}],"tv":158.76}]}
{"op":"mcm","clk":"11957679436","pt":1724562327277,"mc":[{"id":"1.232245129","rc":[{"batb":[[0,1.54,79.53],[1,1.03,200],[2,1.02,200]],"ltp":1.58,"tv":158.76,"id":72922097}]}]}
{"op":"mcm","clk":"11957690601","pt":1724562519677,"mc":[{"id":"1.232245129","rc":[{"batb":[[1,1.1,1500],[2,1.03,200]],"ltp":1.58,"tv":158.76,"id":72922097}]}]}
{"op":"mcm","clk":"11957690802","pt":1724562524089,"mc":[{"id":"1.232245129","rc":[{"batb":[[1,1.1,1500],[2,1.03,200]],"ltp":0.0,"tv":0.0,"id":67083366}]}]}
{"op":"mcm","clk":"11957746361","pt":1724563338069,"mc":[{"id":"1.232245129","rc":[{"batl":[[0,1.56,17.28],[1,1.57,773.61],[2,1.6,1725.44]],"ltp":1.58,"tv":158.76,"id":72922097}]}]}
{"op":"mcm","clk":"11957750332","pt":1724563414868,"mc":[{"id":"1.232245129","rc":[{"trd":[[1.54,0.24]],"batb":[[0,1.54,79.41]],"ltp":1.54,"tv":159.0,"id":72922097}],"tv":159.0}]}
{"op":"mcm","clk":"11957750376","pt":1724563415746,"mc":[{"id":"1.232245129","rc":[{"batb":[[0,1.54,79.53]],"ltp":1.54,"tv":159.0,"id":72922097}]}]}
{"op":"mcm","clk":"11957766937","pt":1724563769669,"mc":[{"id":"1.232245129","rc":[{"trd":[[2.78,1.06]],"ltp":2.78,"tv":1.05,"id":67083366},{"trd":[[1.56,1.88]],"batl":[[0,1.56,15.4]],"ltp":1.56,"tv":160.88,"id":72922097}],"tv":161.94}]}
{"op":"mcm","clk":"11957769511","pt":1724563820125,"mc":[{"id":"1.232245129","rc":[{"batb":[[0,2.76,9.67],[1,2.58,27.18],[2,1.1,1500]],"ltp":2.78,"tv":1.05,"id":67083366}]}]}
{"op":"mcm","clk":"11957844076","pt":1724565196203,"mc":[{"id":"1.232245129","rc":[{"trd":[[1.56,21.88]],"batl":[[0,1.56,5.4]],"ltp":1.56,"tv":180.88,"id":72922097}],"tv":181.93}]}
{"op":"mcm","clk":"11957890850","pt":1724566034664,"mc":[{"id":"1.232245129","rc":[{"batb":[[1,1.32,126.2],[2,1.1,1500]],"ltp":1.56,"tv":180.88,"id":72922097}]}]}
{"op":"mcm","clk":"11957971958","pt":1724567241501,"mc":[{"id":"1.232245129","rc":[{"batb":[[2,1.03,200]],"ltp":2.78,"tv":1.05,"id":67083366},{"batb":[[2,1.03,200]],"ltp":1.56,"tv":180.88,"id":72922097}]}]}
{"op":"mcm","clk":"11957972727","pt":1724567255232,"mc":[{"id":"1.232245129","rc":[{"batb":[[2,1.1,3000]],"ltp":1.56,"tv":180.88,"id":72922097}]}]}
{"op":"mcm","clk":"11957972980","pt":1724567260354,"mc":[{"id":"1.232245129","rc":[{"batb":[[2,1.1,3000]],"ltp":2.78,"tv":1.05,"id":67083366}]}]}
{"op":"mcm","clk":"11958187984","pt":1724570452791,"mc":[{"id":"1.232245129","rc":[{"batb":[[0,2.78,4],[1,2.76,9.67],[2,2.58,27.18]],"batl":[[0,2.82,18],[1,2.84,1.18]],"ltp":2.78,"tv":1.05,"id":67083366}]}]}
{"op":"mcm","clk":"11958188115","pt":1724570454957,"mc":[{"id":"1.232245129","rc":[{"batb":[[0,2.76,9.67],[1,2.58,27.18],[2,1.1,3000]],"ltp":2.78,"tv":1.05,"id":67083366}]}]}
{"op":"mcm","clk":"11958188297","pt":1724570457970,"mc":[{"id":"1.232245129","rc":[{"batb":[[0,2.78,4],[1,2.76,9.67],[2,2.58,27.18]],"ltp":2.78,"tv":1.05,"id":67083366}]}]}
{"op":"mcm","clk":"11958188431","pt":1724570460276,"mc":[{"id":"1.232245129","rc":[{"batb":[[0,2.76,9.67],[1,2.58,27.18],[2,1.1,3000]],"ltp":2.78,"tv":1.05,"id":67083366}]}]}
{"op":"mcm","clk":"11958188590","pt":1724570462983,"mc":[{"id":"1.232245129","rc":[{"batb":[[0,2.78,4],[1,2.76,9.67],[2,2.58,27.18]],"ltp":2.78,"tv":1.05,"id":67083366}]}]}
{"op":"mcm","clk":"11958188768","pt":1724570465294,"mc":[{"id":"1.232245129","rc":[{"batb":[[0,2.76,9.67],[1,2.58,27.18],[2,1.1,3000]],"ltp":2.78,"tv":1.05,"id":67083366}]}]}
{"op":"mcm","clk":"11958188967","pt":1724570468080,"mc":[{"id":"1.232245129","rc":[{"batb":[[0,2.78,4],[1,2.76,9.67],[2,2.58,27.18]],"ltp":2.78,"tv":1.05,"id":67083366}]}]}
{"op":"mcm","clk":"11958189128","pt":1724570470378,"mc":[{"id":"1.232245129","rc":[{"batb":[[0,2.76,9.67],[1,2.58,27.18],[2,1.1,3000]],"ltp":2.78,"tv":1.05,"id":67083366}]}]}
{"op":"mcm","clk":"11958189361","pt":1724570473811,"mc":[{"id":"1.232245129","rc":[{"batb":[[0,2.78,4],[1,2.76,9.67],[2,2.58,27.18]],"ltp":2.78,"tv":1.05,"id":67083366}]}]}
{"op":"mcm","clk":"11958189522","pt":1724570476273,"mc":[{"id":"1.232245129","rc":[{"batb":[[0,2.76,9.67],[1,2.58,27.18],[2,1.1,3000]],"ltp":2.78,"tv":1.05,"id":67083366}]}]}
{"op":"mcm","clk":"11958189811","pt":1724570480675,"mc":[{"id":"1.232245129","rc":[{"batb":[[0,2.78,4],[1,2.76,9.67],[2,2.58,27.18]],"ltp":2.78,"tv":1.05,"id":67083366}]}]}
{"op":"mcm","clk":"11958189969","pt":1724570483135,"mc":[{"id":"1.232245129","rc":[{"batb":[[0,2.76,9.67],[1,2.58,27.18],[2,1.1,3000]],"ltp":2.78,"tv":1.05,"id":67083366}]}]}
{"op":"mcm","clk":"11958190282","pt":1724570487694,"mc":[{"id":"1.232245129","rc":[{"batb":[[0,2.78,4],[1,2.76,9.67],[2,2.58,27.18]],"ltp":2.78,"tv":1.05,"id":67083366}]}]}
{"op":"mcm","clk":"11958190450","pt":1724570490308,"mc":[{"id":"1.232245129","rc":[{"batb":[[0,2.76,9.67],[1,2.58,27.18],[2,1.1,3000]],"ltp":2.78,"tv":1.05,"id":67083366}]}]}
{"op":"mcm","clk":"11958190613","pt":1724570492508,"mc":[{"id":"1.232245129","rc":[{"batb":[[0,2.78,4],[1,2.76,9.67],[2,2.58,27.18]],"ltp":2.78,"tv":1.05,"id":67083366}]}]}
{"op":"mcm","clk":"11958190794","pt":1724570494811,"mc":[{"id":"1.232245129","rc":[{"batb":[[0,2.76,9.67],[1,2.58,27.18],[2,1.1,3000]],"ltp":2.78,"tv":1.05,"id":67083366}]}]}
{"op":"mcm","clk":"11958191040","pt":1724570498600,"mc":[{"id":"1.232245129","rc":[{"batb":[[0,2.78,4],[1,2.76,9.67],[2,2.58,27.18]],"ltp":2.78,"tv":1.05,"id":67083366}]}]}
{"op":"mcm","clk":"11958191169","pt":1724570500694,"mc":[{"id":"1.232245129","rc":[{"batb":[[0,2.76,9.67],[1,2.58,27.18],[2,1.1,3000]],"ltp":2.78,"tv":1.05,"id":67083366}]}]}
{"op":"mcm","clk":"11958191770","pt":1724570510321,"mc":[{"id":"1.232245129","rc":[{"batb":[[0,2.78,4],[1,2.76,9.67],[2,2.58,27.18]],"ltp":2.78,"tv":1.05,"id":67083366}]}]}
{"op":"mcm","clk":"11958191958","pt":1724570512824,"mc":[{"id":"1.232245129","rc":[{"batb":[[0,2.76,9.67],[1,2.58,27.18],[2,1.1,3000]],"ltp":2.78,"tv":1.05,"id":67083366}]}]}
{"op":"mcm","clk":"11958192194","pt":1724570516258,"mc":[{"id":"1.232245129","rc":[{"batb":[[0,2.78,4],[1,2.76,9.67],[2,2.58,27.18]],"ltp":2.78,"tv":1.05,"id":67083366}]}]}
{"op":"mcm","clk":"11958192356","pt":1724570518635,"mc":[{"id":"1.232245129","rc":[{"batb":[[0,2.76,9.67],[1,2.58,27.18],[2,1.1,3000]],"ltp":2.78,"tv":1.05,"id":67083366}]}]}
{"op":"mcm","clk":"11958192548","pt":1724570521022,"mc":[{"id":"1.232245129","rc":[{"batb":[[0,2.78,4],[1,2.76,9.67],[2,2.58,27.18]],"ltp":2.78,"tv":1.05,"id":67083366}]}]}
{"op":"mcm","clk":"11958192737","pt":1724570523577,"mc":[{"id":"1.232245129","rc":[{"batb":[[0,2.76,9.67],[1,2.58,27.18],[2,1.1,3000]],"ltp":2.78,"tv":1.05,"id":67083366}]}]}
{"op":"mcm","clk":"11958192978","pt":1724570527067,"mc":[{"id":"1.232245129","rc":[{"batb":[[0,2.78,4],[1,2.76,9.67],[2,2.58,27.18]],"ltp":2.78,"tv":1.05,"id":67083366}]}]}
{"op":"mcm","clk":"11958193128","pt":1724570529270,"mc":[{"id":"1.232245129","rc":[{"batb":[[0,2.76,9.67],[1,2.58,27.18],[2,1.1,3000]],"ltp":2.78,"tv":1.05,"id":67083366}]}]}
{"op":"mcm","clk":"11958193442","pt":1724570533887,"mc":[{"id":"1.232245129","rc":[{"batb":[[0,2.78,4],[1,2.76,9.67],[2,2.58,27.18]],"ltp":2.78,"tv":1.05,"id":67083366}]}]}
{"op":"mcm","clk":"11958193590","pt":1724570536200,"mc":[{"id":"1.232245129","rc":[{"batb":[[0,2.76,9.67],[1,2.58,27.18],[2,1.1,3000]],"ltp":2.78,"tv":1.05,"id":67083366}]}]}
{"op":"mcm","clk":"11958193807","pt":1724570539582,"mc":[{"id":"1.232245129","rc":[{"batb":[[0,2.78,4],[1,2.76,9.67],[2,2.58,27.18]],"ltp":2.78,"tv":1.05,"id":67083366}]}]}
{"op":"mcm","clk":"11958193963","pt":1724570541985,"mc":[{"id":"1.232245129","rc":[{"batb":[[0,2.76,9.67],[1,2.58,27.18],[2,1.1,3000]],"ltp":2.78,"tv":1.05,"id":67083366}]}]}
{"op":"mcm","clk":"11958194144","pt":1724570544289,"mc":[{"id":"1.232245129","rc":[{"batb":[[0,2.78,4],[1,2.76,9.67],[2,2.58,27.18]],"ltp":2.78,"tv":1.05,"id":67083366}]}]}
{"op":"mcm","clk":"11958194328","pt":1724570546645,"mc":[{"id":"1.232245129","rc":[{"batb":[[0,2.76,9.67],[1,2.58,27.18],[2,1.1,3000]],"ltp":2.78,"tv":1.05,"id":67083366}]}]}
{"op":"mcm","clk":"11958194626","pt":1724570550195,"mc":[{"id":"1.232245129","rc":[{"batb":[[0,2.78,4],[1,2.76,9.67],[2,2.58,27.18]],"ltp":2.78,"tv":1.05,"id":67083366}]}]}
{"op":"mcm","clk":"11958194766","pt":1724570552502,"mc":[{"id":"1.232245129","rc":[{"batb":[[0,2.76,9.67],[1,2.58,27.18],[2,1.1,3000]],"ltp":2.78,"tv":1.05,"id":67083366}]}]}
{"op":"mcm","clk":"11958194958","pt":1724570555223,"mc":[{"id":"1.232245129","rc":[{"batb":[[0,2.78,4],[1,2.76,9.67],[2,2.58,27.18]],"ltp":2.78,"tv":1.05,"id":67083366}]}]}
{"op":"mcm","clk":"11958195182","pt":1724570557743,"mc":[{"id":"1.232245129","rc":[{"batb":[[0,2.76,9.67],[1,2.58,27.18],[2,1.1,3000]],"ltp":2.78,"tv":1.05,"id":67083366}]}]}
{"op":"mcm","clk":"11958195538","pt":1724570562321,"mc":[{"id":"1.232245129","rc":[{"batb":[[0,2.78,4],[1,2.76,9.67],[2,2.58,27.18]],"ltp":2.78,"tv":1.05,"id":67083366}]}]}
{"op":"mcm","clk":"11958195704","pt":1724570564634,"mc":[{"id":"1.232245129","rc":[{"batb":[[0,2.76,9.67],[1,2.58,27.18],[2,1.1,3000]],"ltp":2.78,"tv":1.05,"id":67083366}]}]}
{"op":"mcm","clk":"11958195860","pt":1724570567237,"mc":[{"id":"1.232245129","rc":[{"batb":[[0,2.78,4],[1,2.76,9.67],[2,2.58,27.18]],"ltp":2.78,"tv":1.05,"id":67083366}]}]}
{"op":"mcm","clk":"11958196007","pt":1724570569433,"mc":[{"id":"1.232245129","rc":[{"batb":[[0,2.76,9.67],[1,2.58,27.18],[2,1.1,3000]],"ltp":2.78,"tv":1.05,"id":67083366}]}]}
{"op":"mcm","clk":"11958196181","pt":1724570571734,"mc":[{"id":"1.232245129","rc":[{"batb":[[0,2.78,4],[1,2.76,9.67],[2,2.58,27.18]],"ltp":2.78,"tv":1.05,"id":67083366}]}]}
{"op":"mcm","clk":"11958196402","pt":1724570573955,"mc":[{"id":"1.232245129","rc":[{"batb":[[0,2.76,9.67],[1,2.58,27.18],[2,1.1,3000]],"ltp":2.78,"tv":1.05,"id":67083366}]}]}
{"op":"mcm","clk":"11958196602","pt":1724570576427,"mc":[{"id":"1.232245129","rc":[{"batb":[[0,2.78,4],[1,2.76,9.67],[2,2.58,27.18]],"ltp":2.78,"tv":1.05,"id":67083366}]}]}
{"op":"mcm","clk":"11958196757","pt":1724570578726,"mc":[{"id":"1.232245129","rc":[{"batb":[[0,2.76,9.67],[1,2.58,27.18],[2,1.1,3000]],"ltp":2.78,"tv":1.05,"id":67083366}]}]}
{"op":"mcm","clk":"11958197257","pt":1724570585735,"mc":[{"id":"1.232245129","rc":[{"batb":[[0,2.78,4],[1,2.76,9.67],[2,2.58,27.18]],"ltp":2.78,"tv":1.05,"id":67083366}]}]}
{"op":"mcm","clk":"11958197403","pt":1724570588084,"mc":[{"id":"1.232245129","rc":[{"batb":[[0,2.76,9.67],[1,2.58,27.18],[2,1.1,3000]],"ltp":2.78,"tv":1.05,"id":67083366}]}]}
{"op":"mcm","clk":"11958197955","pt":1724570595573,"mc":[{"id":"1.232245129","rc":[{"batb":[[0,2.78,4],[1,2.76,9.67],[2,2.58,27.18]],"ltp":2.78,"tv":1.05,"id":67083366}]}]}
{"op":"mcm","clk":"11958198114","pt":1724570597886,"mc":[{"id":"1.232245129","rc":[{"batb":[[0,2.76,9.67],[1,2.58,27.18],[2,1.1,3000]],"ltp":2.78,"tv":1.05,"id":67083366}]}]}
{"op":"mcm","clk":"11958198420","pt":1724570602186,"mc":[{"id":"1.232245129","rc":[{"batb":[[0,2.78,4],[1,2.76,9.67],[2,2.58,27.18]],"ltp":2.78,"tv":1.05,"id":67083366}]}]}
{"op":"mcm","clk":"11958198657","pt":1724570604606,"mc":[{"id":"1.232245129","rc":[{"batb":[[0,2.76,9.67],[1,2.58,27.18],[2,1.1,3000]],"ltp":2.78,"tv":1.05,"id":67083366}]}]}
{"op":"mcm","clk":"11958198911","pt":1724570607983,"mc":[{"id":"1.232245129","rc":[{"batb":[[0,2.78,4],[1,2.76,9.67],[2,2.58,27.18]],"ltp":2.78,"tv":1.05,"id":67083366}]}]}
{"op":"mcm","clk":"11958199068","pt":1724570610390,"mc":[{"id":"1.232245129","rc":[{"batb":[[0,2.76,9.67],[1,2.58,27.18],[2,1.1,3000]],"ltp":2.78,"tv":1.05,"id":67083366}]}]}
{"op":"mcm","clk":"11958199406","pt":1724570615198,"mc":[{"id":"1.232245129","rc":[{"batb":[[0,2.78,4],[1,2.76,9.67],[2,2.58,27.18]],"ltp":2.78,"tv":1.05,"id":67083366}]}]}
{"op":"mcm","clk":"11958199561","pt":1724570617620,"mc":[{"id":"1.232245129","rc":[{"batb":[[0,2.76,9.67],[1,2.58,27.18],[2,1.1,3000]],"ltp":2.78,"tv":1.05,"id":67083366}]}]}
{"op":"mcm","clk":"11958199711","pt":1724570620025,"mc":[{"id":"1.232245129","rc":[{"batb":[[0,2.78,4],[1,2.76,9.67],[2,2.58,27.18]],"ltp":2.78,"tv":1.05,"id":67083366}]}]}
{"op":"mcm","clk":"11958199852","pt":1724570622435,"mc":[{"id":"1.232245129","rc":[{"batb":[[0,2.76,9.67],[1,2.58,27.18],[2,1.1,3000]],"ltp":2.78,"tv":1.05,"id":67083366}]}]}
{"op":"mcm","clk":"11958200087","pt":1724570625818,"mc":[{"id":"1.232245129","rc":[{"batb":[[0,2.78,4],[1,2.76,9.67],[2,2.58,27.18]],"ltp":2.78,"tv":1.05,"id":67083366}]}]}
{"op":"mcm","clk":"11958200207","pt":1724570628123,"mc":[{"id":"1.232245129","rc":[{"batb":[[0,2.76,9.67],[1,2.58,27.18],[2,1.1,3000]],"ltp":2.78,"tv":1.05,"id":67083366}]}]}
{"op":"mcm","clk":"11958200456","pt":1724570631815,"mc":[{"id":"1.232245129","rc":[{"batb":[[0,2.78,4],[1,2.76,9.67],[2,2.58,27.18]],"ltp":2.78,"tv":1.05,"id":67083366}]}]}
{"op":"mcm","clk":"11958200647","pt":1724570634216,"mc":[{"id":"1.232245129","rc":[{"batb":[[0,2.76,9.67],[1,2.58,27.18],[2,1.1,3000]],"ltp":2.78,"tv":1.05,"id":67083366}]}]}
{"op":"mcm","clk":"11958200896","pt":1724570637954,"mc":[{"id":"1.232245129","rc":[{"batb":[[0,2.78,4],[1,2.76,9.67],[2,2.58,27.18]],"ltp":2.78,"tv":1.05,"id":67083366}]}]}
{"op":"mcm","clk":"11958201059","pt":1724570640232,"mc":[{"id":"1.232245129","rc":[{"batb":[[0,2.76,9.67],[1,2.58,27.18],[2,1.1,3000]],"ltp":2.78,"tv":1.05,"id":67083366}]}]}
{"op":"mcm","clk":"11958201603","pt":1724570647455,"mc":[{"id":"1.232245129","rc":[{"batb":[[0,2.78,4],[1,2.76,9.67],[2,2.58,27.18]],"ltp":2.78,"tv":1.05,"id":67083366}]}]}
{"op":"mcm","clk":"11958201745","pt":1724570649961,"mc":[{"id":"1.232245129","rc":[{"batb":[[0,2.76,9.67],[1,2.58,27.18],[2,1.1,3000]],"ltp":2.78,"tv":1.05,"id":67083366}]}]}
{"op":"mcm","clk":"11958201960","pt":1724570654023,"mc":[{"id":"1.232245129","rc":[{"batb":[[0,2.78,4],[1,2.76,9.67],[2,2.58,27.18]],"ltp":2.78,"tv":1.05,"id":67083366}]}]}
{"op":"mcm","clk":"11958202125","pt":1724570656333,"mc":[{"id":"1.232245129","rc":[{"batb":[[0,2.76,9.67],[1,2.58,27.18],[2,1.1,3000]],"ltp":2.78,"tv":1.05,"id":67083366}]}]}
{"op":"mcm","clk":"11958202316","pt":1724570658754,"mc":[{"id":"1.232245129","rc":[{"batb":[[0,2.78,4],[1,2.76,9.67],[2,2.58,27.18]],"ltp":2.78,"tv":1.05,"id":67083366}]}]}
{"op":"mcm","clk":"11958202473","pt":1724570661066,"mc":[{"id":"1.232245129","rc":[{"batb":[[0,2.76,9.67],[1,2.58,27.18],[2,1.1,3000]],"ltp":2.78,"tv":1.05,"id":67083366}]}]}
{"op":"mcm","clk":"11958202688","pt":1724570664858,"mc":[{"id":"1.232245129","rc":[{"batb":[[0,2.78,4],[1,2.76,9.67],[2,2.58,27.18]],"ltp":2.78,"tv":1.05,"id":67083366}]}]}
{"op":"mcm","clk":"11958202837","pt":1724570667166,"mc":[{"id":"1.232245129","rc":[{"batb":[[0,2.76,9.67],[1,2.58,27.18],[2,1.1,3000]],"ltp":2.78,"tv":1.05,"id":67083366}]}]}
{"op":"mcm","clk":"11958203196","pt":1724570673879,"mc":[{"id":"1.232245129","rc":[{"batb":[[0,2.78,4],[1,2.76,9.67],[2,2.58,27.18]],"ltp":2.78,"tv":1.05,"id":67083366}]}]}
{"op":"mcm","clk":"11958203378","pt":1724570676294,"mc":[{"id":"1.232245129","rc":[{"batb":[[0,2.76,9.67],[1,2.58,27.18],[2,1.1,3000]],"ltp":2.78,"tv":1.05,"id":67083366}]}]}
{"op":"mcm","clk":"11958203499","pt":1724570678510,"mc":[{"id":"1.232245129","rc":[{"batb":[[0,2.78,4],[1,2.76,9.67],[2,2.58,27.18]],"ltp":2.78,"tv":1.05,"id":67083366}]}]}
{"op":"mcm","clk":"11958203654","pt":1724570680974,"mc":[{"id":"1.232245129","rc":[{"batb":[[0,2.76,9.67],[1,2.58,27.18],[2,1.1,3000]],"ltp":2.78,"tv":1.05,"id":67083366}]}]}
{"op":"mcm","clk":"11958203829","pt":1724570683171,"mc":[{"id":"1.232245129","rc":[{"batb":[[0,2.78,4],[1,2.76,9.67],[2,2.58,27.18]],"ltp":2.78,"tv":1.05,"id":67083366}]}]}
{"op":"mcm","clk":"11958204012","pt":1724570685833,"mc":[{"id":"1.232245129","rc":[{"batb":[[0,2.76,9.67],[1,2.58,27.18],[2,1.1,3000]],"ltp":2.78,"tv":1.05,"id":67083366}]}]}
{"op":"mcm","clk":"11958204203","pt":1724570688111,"mc":[{"id":"1.232245129","rc":[{"batb":[[0,2.78,4],[1,2.76,9.67],[2,2.58,27.18]],"ltp":2.78,"tv":1.05,"id":67083366}]}]}
{"op":"mcm","clk":"11958204353","pt":1724570690285,"mc":[{"id":"1.232245129","rc":[{"batb":[[0,2.76,9.67],[1,2.58,27.18],[2,1.1,3000]],"ltp":2.78,"tv":1.05,"id":67083366}]}]}
{"op":"mcm","clk":"11958204745","pt":1724570696506,"mc":[{"id":"1.232245129","rc":[{"batb":[[0,2.78,4],[1,2.76,9.67],[2,2.58,27.18]],"ltp":2.78,"tv":1.05,"id":67083366}]}]}
{"op":"mcm","clk":"11958204922","pt":1724570698819,"mc":[{"id":"1.232245129","rc":[{"batb":[[0,2.76,9.67],[1,2.58,27.18],[2,1.1,3000]],"ltp":2.78,"tv":1.05,"id":67083366}]}]}
{"op":"mcm","clk":"11958205236","pt":1724570702840,"mc":[{"id":"1.232245129","rc":[{"batb":[[0,2.78,4],[1,2.76,9.67],[2,2.58,27.18]],"ltp":2.78,"tv":1.05,"id":67083366}]}]}
{"op":"mcm","clk":"11958205429","pt":1724570705116,"mc":[{"id":"1.232245129","rc":[{"batb":[[0,2.76,9.67],[1,2.58,27.18],[2,1.1,3000]],"ltp":2.78,"tv":1.05,"id":67083366}]}]}
{"op":"mcm","clk":"11958205604","pt":1724570707539,"mc":[{"id":"1.232245129","rc":[{"batb":[[0,2.78,4],[1,2.76,9.67],[2,2.58,27.18]],"ltp":2.78,"tv":1.05,"id":67083366}]}]}
{"op":"mcm","clk":"11958205779","pt":1724570709743,"mc":[{"id":"1.232245129","rc":[{"batb":[[0,2.76,9.67],[1,2.58,27.18],[2,1.1,3000]],"ltp":2.78,"tv":1.05,"id":67083366}]}]}
{"op":"mcm","clk":"11958206443","pt":1724570719233,"mc":[{"id":"1.232245129","rc":[{"batb":[[0,2.78,4],[1,2.76,9.67],[2,2.58,27.18]],"ltp":2.78,"tv":1.05,"id":67083366}]}]}
{"op":"mcm","clk":"11958206580","pt":1724570721540,"mc":[{"id":"1.232245129","rc":[{"batb":[[0,2.76,9.67],[1,2.58,27.18],[2,1.1,3000]],"ltp":2.78,"tv":1.05,"id":67083366}]}]}
{"op":"mcm","clk":"11958206879","pt":1724570725958,"mc":[{"id":"1.232245129","rc":[{"batb":[[0,2.78,4],[1,2.76,9.67],[2,2.58,27.18]],"ltp":2.78,"tv":1.05,"id":67083366}]}]}
{"op":"mcm","clk":"11958207018","pt":1724570728478,"mc":[{"id":"1.232245129","rc":[{"batb":[[0,2.76,9.67],[1,2.58,27.18],[2,1.1,3000]],"ltp":2.78,"tv":1.05,"id":67083366}]}]}
{"op":"mcm","clk":"11958207172","pt":1724570730845,"mc":[{"id":"1.232245129","rc":[{"batb":[[0,2.78,4],[1,2.76,9.67],[2,2.58,27.18]],"ltp":2.78,"tv":1.05,"id":67083366}]}]}
{"op":"mcm","clk":"11958207338","pt":1724570733257,"mc":[{"id":"1.232245129","rc":[{"batb":[[0,2.76,9.67],[1,2.58,27.18],[2,1.1,3000]],"ltp":2.78,"tv":1.05,"id":67083366}]}]}
{"op":"mcm","clk":"11958207511","pt":1724570736174,"mc":[{"id":"1.232245129","rc":[{"batb":[[0,2.78,4],[1,2.76,9.67],[2,2.58,27.18]],"ltp":2.78,"tv":1.05,"id":67083366}]}]}
{"op":"mcm","clk":"11958207680","pt":1724570738579,"mc":[{"id":"1.232245129","rc":[{"batb":[[0,2.76,9.67],[1,2.58,27.18],[2,1.1,3000]],"ltp":2.78,"tv":1.05,"id":67083366}]}]}
{"op":"mcm","clk":"11958207877","pt":1724570741456,"mc":[{"id":"1.232245129","rc":[{"batb":[[0,2.78,4],[1,2.76,9.67],[2,2.58,27.18]],"ltp":2.78,"tv":1.05,"id":67083366}]}]}
{"op":"mcm","clk":"11958208022","pt":1724570743776,"mc":[{"id":"1.232245129","rc":[{"batb":[[0,2.76,9.67],[1,2.58,27.18],[2,1.1,3000]],"ltp":2.78,"tv":1.05,"id":67083366}]}]}
{"op":"mcm","clk":"11958208170","pt":1724570745956,"mc":[{"id":"1.232245129","rc":[{"batb":[[0,2.78,4],[1,2.76,9.67],[2,2.58,27.18]],"ltp":2.78,"tv":1.05,"id":67083366}]}]}
{"op":"mcm","clk":"11958208316","pt":1724570748260,"mc":[{"id":"1.232245129","rc":[{"batb":[[0,2.76,9.67],[1,2.58,27.18],[2,1.1,3000]],"ltp":2.78,"tv":1.05,"id":67083366}]}]}
{"op":"mcm","clk":"11958208614","pt":1724570753270,"mc":[{"id":"1.232245129","rc":[{"batb":[[0,2.78,4],[1,2.76,9.67],[2,2.58,27.18]],"ltp":2.78,"tv":1.05,"id":67083366}]}]}
{"op":"mcm","clk":"11958208766","pt":1724570755475,"mc":[{"id":"1.232245129","rc":[{"batb":[[0,2.76,9.67],[1,2.58,27.18],[2,1.1,3000]],"ltp":2.78,"tv":1.05,"id":67083366}]}]}
{"op":"mcm","clk":"11958209027","pt":1724570759779,"mc":[{"id":"1.232245129","rc":[{"batb":[[0,2.78,4],[1,2.76,9.67],[2,2.58,27.18]],"ltp":2.78,"tv":1.05,"id":67083366}]}]}
{"op":"mcm","clk":"11958209175","pt":1724570762087,"mc":[{"id":"1.232245129","rc":[{"batb":[[0,2.76,9.67],[1,2.58,27.18],[2,1.1,3000]],"ltp":2.78,"tv":1.05,"id":67083366}]}]}
{"op":"mcm","clk":"11958209465","pt":1724570766288,"mc":[{"id":"1.232245129","rc":[{"batb":[[0,2.78,4],[1,2.76,9.67],[2,2.58,27.18]],"ltp":2.78,"tv":1.05,"id":67083366}]}]}
{"op":"mcm","clk":"11958209602","pt":1724570768700,"mc":[{"id":"1.232245129","rc":[{"batb":[[0,2.76,9.67],[1,2.58,27.18],[2,1.1,3000]],"ltp":2.78,"tv":1.05,"id":67083366}]}]}
{"op":"mcm","clk":"11958209748","pt":1724570771005,"mc":[{"id":"1.232245129","rc":[{"batb":[[0,2.78,4],[1,2.76,9.67],[2,2.58,27.18]],"ltp":2.78,"tv":1.05,"id":67083366}]}]}
{"op":"mcm","clk":"11958209915","pt":1724570773205,"mc":[{"id":"1.232245129","rc":[{"batb":[[0,2.76,9.67],[1,2.58,27.18],[2,1.1,3000]],"ltp":2.78,"tv":1.05,"id":67083366}]}]}
{"op":"mcm","clk":"11958210370","pt":1724570779309,"mc":[{"id":"1.232245129","rc":[{"batb":[[0,2.78,4],[1,2.76,9.67],[2,2.58,27.18]],"ltp":2.78,"tv":1.05,"id":67083366}]}]}
{"op":"mcm","clk":"11958210523","pt":1724570781614,"mc":[{"id":"1.232245129","rc":[{"batb":[[0,2.76,9.67],[1,2.58,27.18],[2,1.1,3000]],"ltp":2.78,"tv":1.05,"id":67083366}]}]}
{"op":"mcm","clk":"11958210776","pt":1724570784995,"mc":[{"id":"1.232245129","rc":[{"batb":[[0,2.78,4],[1,2.76,9.67],[2,2.58,27.18]],"ltp":2.78,"tv":1.05,"id":67083366}]}]}
{"op":"mcm","clk":"11958210937","pt":1724570787365,"mc":[{"id":"1.232245129","rc":[{"batb":[[0,2.76,9.67],[1,2.58,27.18],[2,1.1,3000]],"ltp":2.78,"tv":1.05,"id":67083366}]}]}
{"op":"mcm","clk":"11958211190","pt":1724570790500,"mc":[{"id":"1.232245129","rc":[{"batb":[[0,2.78,4],[1,2.76,9.67],[2,2.58,27.18]],"ltp":2.78,"tv":1.05,"id":67083366}]}]}
{"op":"mcm","clk":"11958211329","pt":1724570792802,"mc":[{"id":"1.232245129","rc":[{"batb":[[0,2.76,9.67],[1,2.58,27.18],[2,1.1,3000]],"ltp":2.78,"tv":1.05,"id":67083366}]}]}
{"op":"mcm","clk":"11958211542","pt":1724570795816,"mc":[{"id":"1.232245129","rc":[{"batb":[[0,2.78,4],[1,2.76,9.67],[2,2.58,27.18]],"ltp":2.78,"tv":1.05,"id":67083366}]}]}
{"op":"mcm","clk":"11958211644","pt":1724570798133,"mc":[{"id":"1.232245129","rc":[{"batb":[[0,2.76,9.67],[1,2.58,27.18],[2,1.1,3000]],"ltp":2.78,"tv":1.05,"id":67083366}]}]}
{"op":"mcm","clk":"11958211910","pt":1724570801737,"mc":[{"id":"1.232245129","rc":[{"batb":[[0,2.78,4],[1,2.76,9.67],[2,2.58,27.18]],"ltp":2.78,"tv":1.05,"id":67083366}]}]}
{"op":"mcm","clk":"11958212078","pt":1724570803938,"mc":[{"id":"1.232245129","rc":[{"batb":[[0,2.76,9.67],[1,2.58,27.18],[2,1.1,3000]],"ltp":2.78,"tv":1.05,"id":67083366}]}]}
{"op":"mcm","clk":"11958212281","pt":1724570807463,"mc":[{"id":"1.232245129","rc":[{"batb":[[0,2.78,4],[1,2.76,9.67],[2,2.58,27.18]],"ltp":2.78,"tv":1.05,"id":67083366}]}]}
{"op":"mcm","clk":"11958212411","pt":1724570809670,"mc":[{"id":"1.232245129","rc":[{"batb":[[0,2.76,9.67],[1,2.58,27.18],[2,1.1,3000]],"ltp":2.78,"tv":1.05,"id":67083366}]}]}
{"op":"mcm","clk":"11958212556","pt":1724570811925,"mc":[{"id":"1.232245129","rc":[{"batb":[[0,2.78,4],[1,2.76,9.67],[2,2.58,27.18]],"ltp":2.78,"tv":1.05,"id":67083366}]}]}
{"op":"mcm","clk":"11958212730","pt":1724570814327,"mc":[{"id":"1.232245129","rc":[{"batb":[[0,2.76,9.67],[1,2.58,27.18],[2,1.1,3000]],"ltp":2.78,"tv":1.05,"id":67083366}]}]}
{"op":"mcm","clk":"11958212957","pt":1724570817653,"mc":[{"id":"1.232245129","rc":[{"batb":[[0,2.78,4],[1,2.76,9.67],[2,2.58,27.18]],"ltp":2.78,"tv":1.05,"id":67083366}]}]}
{"op":"mcm","clk":"11958213087","pt":1724570820063,"mc":[{"id":"1.232245129","rc":[{"batb":[[0,2.76,9.67],[1,2.58,27.18],[2,1.1,3000]],"ltp":2.78,"tv":1.05,"id":67083366}]}]}
{"op":"mcm","clk":"11958213329","pt":1724570823153,"mc":[{"id":"1.232245129","rc":[{"batb":[[0,2.78,4],[1,2.76,9.67],[2,2.58,27.18]],"ltp":2.78,"tv":1.05,"id":67083366}]}]}
{"op":"mcm","clk":"11958213495","pt":1724570825357,"mc":[{"id":"1.232245129","rc":[{"batb":[[0,2.76,9.67],[1,2.58,27.18],[2,1.1,3000]],"ltp":2.78,"tv":1.05,"id":67083366}]}]}
{"op":"mcm","clk":"11958213687","pt":1724570828752,"mc":[{"id":"1.232245129","rc":[{"batb":[[0,2.78,4],[1,2.76,9.67],[2,2.58,27.18]],"ltp":2.78,"tv":1.05,"id":67083366}]}]}
{"op":"mcm","clk":"11958213824","pt":1724570831063,"mc":[{"id":"1.232245129","rc":[{"batb":[[0,2.76,9.67],[1,2.58,27.18],[2,1.1,3000]],"ltp":2.78,"tv":1.05,"id":67083366}]}]}
{"op":"mcm","clk":"11958213990","pt":1724570833364,"mc":[{"id":"1.232245129","rc":[{"batb":[[0,2.78,4],[1,2.76,9.67],[2,2.58,27.18]],"ltp":2.78,"tv":1.05,"id":67083366}]}]}
{"op":"mcm","clk":"11958214124","pt":1724570835670,"mc":[{"id":"1.232245129","rc":[{"batb":[[0,2.76,9.67],[1,2.58,27.18],[2,1.1,3000]],"ltp":2.78,"tv":1.05,"id":67083366}]}]}
{"op":"mcm","clk":"11958214391","pt":1724570839377,"mc":[{"id":"1.232245129","rc":[{"batb":[[0,2.78,4],[1,2.76,9.67],[2,2.58,27.18]],"ltp":2.78,"tv":1.05,"id":67083366}]}]}
{"op":"mcm","clk":"11958214527","pt":1724570841682,"mc":[{"id":"1.232245129","rc":[{"batb":[[0,2.76,9.67],[1,2.58,27.18],[2,1.1,3000]],"ltp":2.78,"tv":1.05,"id":67083366}]}]}
{"op":"mcm","clk":"11958214943","pt":1724570847117,"mc":[{"id":"1.232245129","rc":[{"batb":[[0,2.78,4],[1,2.76,9.67],[2,2.58,27.18]],"ltp":2.78,"tv":1.05,"id":67083366}]}]}
{"op":"mcm","clk":"11958215127","pt":1724570849475,"mc":[{"id":"1.232245129","rc":[{"batb":[[0,2.76,9.67],[1,2.58,27.18],[2,1.1,3000]],"ltp":2.78,"tv":1.05,"id":67083366}]}]}
{"op":"mcm","clk":"11958215309","pt":1724570852087,"mc":[{"id":"1.232245129","rc":[{"batb":[[0,2.78,4],[1,2.76,9.67],[2,2.58,27.18]],"ltp":2.78,"tv":1.05,"id":67083366}]}]}
{"op":"mcm","clk":"11958215494","pt":1724570854614,"mc":[{"id":"1.232245129","rc":[{"batb":[[0,2.76,9.67],[1,2.58,27.18],[2,1.1,3000]],"ltp":2.78,"tv":1.05,"id":67083366}]}]}
{"op":"mcm","clk":"11958215674","pt":1724570857886,"mc":[{"id":"1.232245129","rc":[{"batb":[[0,2.78,4],[1,2.76,9.67],[2,2.58,27.18]],"ltp":2.78,"tv":1.05,"id":67083366}]}]}
{"op":"mcm","clk":"11958215825","pt":1724570860105,"mc":[{"id":"1.232245129","rc":[{"batb":[[0,2.76,9.67],[1,2.58,27.18],[2,1.1,3000]],"ltp":2.78,"tv":1.05,"id":67083366}]}]}
{"op":"mcm","clk":"11958216158","pt":1724570864111,"mc":[{"id":"1.232245129","rc":[{"batb":[[0,2.78,4],[1,2.76,9.67],[2,2.58,27.18]],"ltp":2.78,"tv":1.05,"id":67083366}]}]}
{"op":"mcm","clk":"11958216314","pt":1724570866318,"mc":[{"id":"1.232245129","rc":[{"batb":[[0,2.76,9.67],[1,2.58,27.18],[2,1.1,3000]],"ltp":2.78,"tv":1.05,"id":67083366}]}]}
{"op":"mcm","clk":"11958216446","pt":1724570868524,"mc":[{"id":"1.232245129","rc":[{"batb":[[0,2.78,4],[1,2.76,9.67],[2,2.58,27.18]],"ltp":2.78,"tv":1.05,"id":67083366}]}]}
{"op":"mcm","clk":"11958216586","pt":1724570870828,"mc":[{"id":"1.232245129","rc":[{"batb":[[0,2.76,9.67],[1,2.58,27.18],[2,1.1,3000]],"ltp":2.78,"tv":1.05,"id":67083366}]}]}
{"op":"mcm","clk":"11958216832","pt":1724570873535,"mc":[{"id":"1.232245129","rc":[{"batb":[[0,2.78,4],[1,2.76,9.67],[2,2.58,27.18]],"ltp":2.78,"tv":1.05,"id":67083366}]}]}
{"op":"mcm","clk":"11958217003","pt":1724570875847,"mc":[{"id":"1.232245129","rc":[{"batb":[[0,2.76,9.67],[1,2.58,27.18],[2,1.1,3000]],"ltp":2.78,"tv":1.05,"id":67083366}]}]}
{"op":"mcm","clk":"11958217341","pt":1724570880846,"mc":[{"id":"1.232245129","rc":[{"batb":[[0,2.78,4],[1,2.76,9.67],[2,2.58,27.18]],"ltp":2.78,"tv":1.05,"id":67083366}]}]}
{"op":"mcm","clk":"11958217525","pt":1724570883057,"mc":[{"id":"1.232245129","rc":[{"batb":[[0,2.76,9.67],[1,2.58,27.18],[2,1.1,3000]],"ltp":2.78,"tv":1.05,"id":67083366}]}]}
{"op":"mcm","clk":"11958217973","pt":1724570888756,"mc":[{"id":"1.232245129","rc":[{"batb":[[0,2.78,4],[1,2.76,9.67],[2,2.58,27.18]],"ltp":2.78,"tv":1.05,"id":67083366}]}]}
{"op":"mcm","clk":"11958218184","pt":1724570891129,"mc":[{"id":"1.232245129","rc":[{"batb":[[0,2.76,9.67],[1,2.58,27.18],[2,1.1,3000]],"ltp":2.78,"tv":1.05,"id":67083366}]}]}
{"op":"mcm","clk":"11958218391","pt":1724570893465,"mc":[{"id":"1.232245129","rc":[{"batb":[[0,2.78,4],[1,2.76,9.67],[2,2.58,27.18]],"ltp":2.78,"tv":1.05,"id":67083366}]}]}
{"op":"mcm","clk":"11958218568","pt":1724570895854,"mc":[{"id":"1.232245129","rc":[{"batb":[[0,2.76,9.67],[1,2.58,27.18],[2,1.1,3000]],"ltp":2.78,"tv":1.05,"id":67083366}]}]}
{"op":"mcm","clk":"11958218737","pt":1724570898469,"mc":[{"id":"1.232245129","rc":[{"batb":[[0,2.78,4],[1,2.76,9.67],[2,2.58,27.18]],"ltp":2.78,"tv":1.05,"id":67083366}]}]}
{"op":"mcm","clk":"11958218938","pt":1724570900757,"mc":[{"id":"1.232245129","rc":[{"batb":[[0,2.76,9.67],[1,2.58,27.18],[2,1.1,3000]],"ltp":2.78,"tv":1.05,"id":67083366}]}]}
{"op":"mcm","clk":"11958219123","pt":1724570903271,"mc":[{"id":"1.232245129","rc":[{"batb":[[0,2.78,4],[1,2.76,9.67],[2,2.58,27.18]],"ltp":2.78,"tv":1.05,"id":67083366}]}]}
{"op":"mcm","clk":"11958219267","pt":1724570905466,"mc":[{"id":"1.232245129","rc":[{"batb":[[0,2.76,9.67],[1,2.58,27.18],[2,1.1,3000]],"ltp":2.78,"tv":1.05,"id":67083366}]}]}
{"op":"mcm","clk":"11958219483","pt":1724570908789,"mc":[{"id":"1.232245129","rc":[{"batb":[[0,2.78,4],[1,2.76,9.67],[2,2.58,27.18]],"ltp":2.78,"tv":1.05,"id":67083366}]}]}
{"op":"mcm","clk":"11958219632","pt":1724570910986,"mc":[{"id":"1.232245129","rc":[{"batb":[[0,2.76,9.67],[1,2.58,27.18],[2,1.1,3000]],"ltp":2.78,"tv":1.05,"id":67083366}]}]}
{"op":"mcm","clk":"11958219835","pt":1724570913593,"mc":[{"id":"1.232245129","rc":[{"batb":[[0,2.78,4],[1,2.76,9.67],[2,2.58,27.18]],"ltp":2.78,"tv":1.05,"id":67083366}]}]}
{"op":"mcm","clk":"11958219972","pt":1724570916088,"mc":[{"id":"1.232245129","rc":[{"batb":[[0,2.76,9.67],[1,2.58,27.18],[2,1.1,3000]],"ltp":2.78,"tv":1.05,"id":67083366}]}]}
{"op":"mcm","clk":"11958220125","pt":1724570918408,"mc":[{"id":"1.232245129","rc":[{"batb":[[0,2.78,4],[1,2.76,9.67],[2,2.58,27.18]],"ltp":2.78,"tv":1.05,"id":67083366}]}]}
{"op":"mcm","clk":"11958220269","pt":1724570920762,"mc":[{"id":"1.232245129","rc":[{"batb":[[0,2.76,9.67],[1,2.58,27.18],[2,1.1,3000]],"ltp":2.78,"tv":1.05,"id":67083366}]}]}
{"op":"mcm","clk":"11958220486","pt":1724570924000,"mc":[{"id":"1.232245129","rc":[{"batb":[[0,2.78,4],[1,2.76,9.67],[2,2.58,27.18]],"ltp":2.78,"tv":1.05,"id":67083366}]}]}
{"op":"mcm","clk":"11958220655","pt":1724570926508,"mc":[{"id":"1.232245129","rc":[{"batb":[[0,2.76,9.67],[1,2.58,27.18],[2,1.1,3000]],"ltp":2.78,"tv":1.05,"id":67083366}]}]}
{"op":"mcm","clk":"11958220863","pt":1724570929908,"mc":[{"id":"1.232245129","rc":[{"batb":[[0,2.78,4],[1,2.76,9.67],[2,2.58,27.18]],"ltp":2.78,"tv":1.05,"id":67083366}]}]}
{"op":"mcm","clk":"11958221028","pt":1724570932277,"mc":[{"id":"1.232245129","rc":[{"batb":[[0,2.76,9.67],[1,2.58,27.18],[2,1.1,3000]],"ltp":2.78,"tv":1.05,"id":67083366}]}]}
{"op":"mcm","clk":"11958221250","pt":1724570935610,"mc":[{"id":"1.232245129","rc":[{"batb":[[0,2.78,4],[1,2.76,9.67],[2,2.58,27.18]],"ltp":2.78,"tv":1.05,"id":67083366}]}]}
{"op":"mcm","clk":"11958221394","pt":1724570938012,"mc":[{"id":"1.232245129","rc":[{"batb":[[0,2.76,9.67],[1,2.58,27.18],[2,1.1,3000]],"ltp":2.78,"tv":1.05,"id":67083366}]}]}
{"op":"mcm","clk":"11958221781","pt":1724570943802,"mc":[{"id":"1.232245129","rc":[{"batb":[[0,2.78,4],[1,2.76,9.67],[2,2.58,27.18]],"ltp":2.78,"tv":1.05,"id":67083366}]}]}
{"op":"mcm","clk":"11958221907","pt":1724570946006,"mc":[{"id":"1.232245129","rc":[{"batb":[[0,2.76,9.67],[1,2.58,27.18],[2,1.1,3000]],"ltp":2.78,"tv":1.05,"id":67083366}]}]}
{"op":"mcm","clk":"11958222130","pt":1724570949505,"mc":[{"id":"1.232245129","rc":[{"batb":[[0,2.78,4],[1,2.76,9.67],[2,2.58,27.18]],"ltp":2.78,"tv":1.05,"id":67083366}]}]}
{"op":"mcm","clk":"11958222304","pt":1724570951931,"mc":[{"id":"1.232245129","rc":[{"batb":[[0,2.76,9.67],[1,2.58,27.18],[2,1.1,3000]],"ltp":2.78,"tv":1.05,"id":67083366}]}]}
{"op":"mcm","clk":"11958222610","pt":1724570955523,"mc":[{"id":"1.232245129","rc":[{"batb":[[0,2.78,4],[1,2.76,9.67],[2,2.58,27.18]],"ltp":2.78,"tv":1.05,"id":67083366}]}]}
{"op":"mcm","clk":"11958222750","pt":1724570957929,"mc":[{"id":"1.232245129","rc":[{"batb":[[0,2.76,9.67],[1,2.58,27.18],[2,1.1,3000]],"ltp":2.78,"tv":1.05,"id":67083366}]}]}
{"op":"mcm","clk":"11958222945","pt":1724570961048,"mc":[{"id":"1.232245129","rc":[{"batb":[[0,2.78,4],[1,2.76,9.67],[2,2.58,27.18]],"ltp":2.78,"tv":1.05,"id":67083366}]}]}
{"op":"mcm","clk":"11958223127","pt":1724570963454,"mc":[{"id":"1.232245129","rc":[{"batb":[[0,2.76,9.67],[1,2.58,27.18],[2,1.1,3000]],"ltp":2.78,"tv":1.05,"id":67083366}]}]}
{"op":"mcm","clk":"11958223320","pt":1724570966653,"mc":[{"id":"1.232245129","rc":[{"batb":[[0,2.78,4],[1,2.76,9.67],[2,2.58,27.18]],"ltp":2.78,"tv":1.05,"id":67083366}]}]}
{"op":"mcm","clk":"11958223491","pt":1724570968967,"mc":[{"id":"1.232245129","rc":[{"batb":[[0,2.76,9.67],[1,2.58,27.18],[2,1.1,3000]],"ltp":2.78,"tv":1.05,"id":67083366}]}]}
{"op":"mcm","clk":"11958223782","pt":1724570973063,"mc":[{"id":"1.232245129","rc":[{"batb":[[0,2.78,4],[1,2.76,9.67],[2,2.58,27.18]],"ltp":2.78,"tv":1.05,"id":67083366}]}]}
{"op":"mcm","clk":"11958223915","pt":1724570975381,"mc":[{"id":"1.232245129","rc":[{"batb":[[0,2.76,9.67],[1,2.58,27.18],[2,1.1,3000]],"ltp":2.78,"tv":1.05,"id":67083366}]}]}
{"op":"mcm","clk":"11958224106","pt":1724570978463,"mc":[{"id":"1.232245129","rc":[{"batb":[[0,2.78,4],[1,2.76,9.67],[2,2.58,27.18]],"ltp":2.78,"tv":1.05,"id":67083366}]}]}
{"op":"mcm","clk":"11958224263","pt":1724570980765,"mc":[{"id":"1.232245129","rc":[{"batb":[[0,2.76,9.67],[1,2.58,27.18],[2,1.1,3000]],"ltp":2.78,"tv":1.05,"id":67083366}]}]}
{"op":"mcm","clk":"11958224460","pt":1724570982970,"mc":[{"id":"1.232245129","rc":[{"batb":[[0,2.78,4],[1,2.76,9.67],[2,2.58,27.18]],"ltp":2.78,"tv":1.05,"id":67083366}]}]}
{"op":"mcm","clk":"11958224644","pt":1724570985172,"mc":[{"id":"1.232245129","rc":[{"batb":[[0,2.76,9.67],[1,2.58,27.18],[2,1.1,3000]],"ltp":2.78,"tv":1.05,"id":67083366}]}]}
{"op":"mcm","clk":"11958224966","pt":1724570990761,"mc":[{"id":"1.232245129","rc":[{"batb":[[0,2.78,4],[1,2.76,9.67],[2,2.58,27.18]],"ltp":2.78,"tv":1.05,"id":67083366}]}]}
{"op":"mcm","clk":"11958225130","pt":1724570993061,"mc":[{"id":"1.232245129","rc":[{"batb":[[0,2.76,9.67],[1,2.58,27.18],[2,1.1,3000]],"ltp":2.78,"tv":1.05,"id":67083366}]}]}
{"op":"mcm","clk":"11958225292","pt":1724570995568,"mc":[{"id":"1.232245129","rc":[{"batb":[[0,2.78,4],[1,2.76,9.67],[2,2.58,27.18]],"ltp":2.78,"tv":1.05,"id":67083366}]}]}
{"op":"mcm","clk":"11958225438","pt":1724570997873,"mc":[{"id":"1.232245129","rc":[{"batb":[[0,2.76,9.67],[1,2.58,27.18],[2,1.1,3000]],"ltp":2.78,"tv":1.05,"id":67083366}]}]}
{"op":"mcm","clk":"11958225599","pt":1724571000290,"mc":[{"id":"1.232245129","rc":[{"batb":[[0,2.78,4],[1,2.76,9.67],[2,2.58,27.18]],"ltp":2.78,"tv":1.05,"id":67083366}]}]}
{"op":"mcm","clk":"11958225802","pt":1724571002615,"mc":[{"id":"1.232245129","rc":[{"batb":[[0,2.76,9.67],[1,2.58,27.18],[2,1.1,3000]],"ltp":2.78,"tv":1.05,"id":67083366}]}]}
{"op":"mcm","clk":"11958226087","pt":1724571005820,"mc":[{"id":"1.232245129","rc":[{"batb":[[0,2.78,4],[1,2.76,9.67],[2,2.58,27.18]],"ltp":2.78,"tv":1.05,"id":67083366}]}]}
{"op":"mcm","clk":"11958226254","pt":1724571008200,"mc":[{"id":"1.232245129","rc":[{"batb":[[0,2.76,9.67],[1,2.58,27.18],[2,1.1,3000]],"ltp":2.78,"tv":1.05,"id":67083366}]}]}
{"op":"mcm","clk":"11958226529","pt":1724571011808,"mc":[{"id":"1.232245129","rc":[{"batb":[[0,2.78,4],[1,2.76,9.67],[2,2.58,27.18]],"ltp":2.78,"tv":1.05,"id":67083366}]}]}
{"op":"mcm","clk":"11958226704","pt":1724571014220,"mc":[{"id":"1.232245129","rc":[{"batb":[[0,2.76,9.67],[1,2.58,27.18],[2,1.1,3000]],"ltp":2.78,"tv":1.05,"id":67083366}]}]}
{"op":"mcm","clk":"11958226992","pt":1724571018392,"mc":[{"id":"1.232245129","rc":[{"batb":[[0,2.78,4],[1,2.76,9.67],[2,2.58,27.18]],"ltp":2.78,"tv":1.05,"id":67083366}]}]}
{"op":"mcm","clk":"11958227168","pt":1724571021006,"mc":[{"id":"1.232245129","rc":[{"batb":[[0,2.76,9.67],[1,2.58,27.18],[2,1.1,3000]],"ltp":2.78,"tv":1.05,"id":67083366}]}]}
{"op":"mcm","clk":"11958227557","pt":1724571025119,"mc":[{"id":"1.232245129","rc":[{"batb":[[0,2.78,4],[1,2.76,9.67],[2,2.58,27.18]],"ltp":2.78,"tv":1.05,"id":67083366}]}]}
{"op":"mcm","clk":"11958227743","pt":1724571027528,"mc":[{"id":"1.232245129","rc":[{"batb":[[0,2.76,9.67],[1,2.58,27.18],[2,1.1,3000]],"ltp":2.78,"tv":1.05,"id":67083366}]}]}
{"op":"mcm","clk":"11958228258","pt":1724571033734,"mc":[{"id":"1.232245129","rc":[{"batb":[[0,2.78,4],[1,2.76,9.67],[2,2.58,27.18]],"ltp":2.78,"tv":1.05,"id":67083366}]}]}
{"op":"mcm","clk":"11958228396","pt":1724571036045,"mc":[{"id":"1.232245129","rc":[{"batb":[[0,2.76,9.67],[1,2.58,27.18],[2,1.1,3000]],"ltp":2.78,"tv":1.05,"id":67083366}]}]}
{"op":"mcm","clk":"11958228730","pt":1724571040755,"mc":[{"id":"1.232245129","rc":[{"batb":[[0,2.78,4],[1,2.76,9.67],[2,2.58,27.18]],"ltp":2.78,"tv":1.05,"id":67083366}]}]}
{"op":"mcm","clk":"11958228864","pt":1724571043064,"mc":[{"id":"1.232245129","rc":[{"batb":[[0,2.76,9.67],[1,2.58,27.18],[2,1.1,3000]],"ltp":2.78,"tv":1.05,"id":67083366}]}]}
{"op":"mcm","clk":"11958229247","pt":1724571048325,"mc":[{"id":"1.232245129","rc":[{"batb":[[0,2.78,4],[1,2.76,9.67],[2,2.58,27.18]],"ltp":2.78,"tv":1.05,"id":67083366}]}]}
{"op":"mcm","clk":"11958229403","pt":1724571050946,"mc":[{"id":"1.232245129","rc":[{"batb":[[0,2.76,9.67],[1,2.58,27.18],[2,1.1,3000]],"ltp":2.78,"tv":1.05,"id":67083366}]}]}
{"op":"mcm","clk":"11958229631","pt":1724571054940,"mc":[{"id":"1.232245129","rc":[{"batb":[[0,2.78,4],[1,2.76,9.67],[2,2.58,27.18]],"ltp":2.78,"tv":1.05,"id":67083366}]}]}
{"op":"mcm","clk":"11958229807","pt":1724571057345,"mc":[{"id":"1.232245129","rc":[{"batb":[[0,2.76,9.67],[1,2.58,27.18],[2,1.1,3000]],"ltp":2.78,"tv":1.05,"id":67083366}]}]}
{"op":"mcm","clk":"11958230007","pt":1724571060174,"mc":[{"id":"1.232245129","rc":[{"batb":[[0,2.78,4],[1,2.76,9.67],[2,2.58,27.18]],"ltp":2.78,"tv":1.05,"id":67083366}]}]}
{"op":"mcm","clk":"11958230184","pt":1724571062337,"mc":[{"id":"1.232245129","rc":[{"batb":[[0,2.76,9.67],[1,2.58,27.18],[2,1.1,3000]],"ltp":2.78,"tv":1.05,"id":67083366}]}]}
{"op":"mcm","clk":"11958230421","pt":1724571065854,"mc":[{"id":"1.232245129","rc":[{"batb":[[0,2.78,4],[1,2.76,9.67],[2,2.58,27.18]],"ltp":2.78,"tv":1.05,"id":67083366}]}]}
{"op":"mcm","clk":"11958230612","pt":1724571068275,"mc":[{"id":"1.232245129","rc":[{"batb":[[0,2.76,9.67],[1,2.58,27.18],[2,1.1,3000]],"ltp":2.78,"tv":1.05,"id":67083366}]}]}
{"op":"mcm","clk":"11958230834","pt":1724571071070,"mc":[{"id":"1.232245129","rc":[{"batb":[[0,2.78,4],[1,2.76,9.67],[2,2.58,27.18]],"ltp":2.78,"tv":1.05,"id":67083366}]}]}
{"op":"mcm","clk":"11958230985","pt":1724571073481,"mc":[{"id":"1.232245129","rc":[{"batb":[[0,2.76,9.67],[1,2.58,27.18],[2,1.1,3000]],"ltp":2.78,"tv":1.05,"id":67083366}]}]}
{"op":"mcm","clk":"11958231160","pt":1724571075950,"mc":[{"id":"1.232245129","rc":[{"batb":[[0,2.78,4],[1,2.76,9.67],[2,2.58,27.18]],"ltp":2.78,"tv":1.05,"id":67083366}]}]}
{"op":"mcm","clk":"11958231338","pt":1724571078105,"mc":[{"id":"1.232245129","rc":[{"batb":[[0,2.76,9.67],[1,2.58,27.18],[2,1.1,3000]],"ltp":2.78,"tv":1.05,"id":67083366}]}]}
{"op":"mcm","clk":"11958231566","pt":1724571080985,"mc":[{"id":"1.232245129","rc":[{"batb":[[0,2.78,4],[1,2.76,9.67],[2,2.58,27.18]],"ltp":2.78,"tv":1.05,"id":67083366}]}]}
{"op":"mcm","clk":"11958231726","pt":1724571083393,"mc":[{"id":"1.232245129","rc":[{"batb":[[0,2.76,9.67],[1,2.58,27.18],[2,1.1,3000]],"ltp":2.78,"tv":1.05,"id":67083366}]}]}
{"op":"mcm","clk":"11958231882","pt":1724571085813,"mc":[{"id":"1.232245129","rc":[{"batb":[[0,2.78,4],[1,2.76,9.67],[2,2.58,27.18]],"ltp":2.78,"tv":1.05,"id":67083366}]}]}
{"op":"mcm","clk":"11958232035","pt":1724571088179,"mc":[{"id":"1.232245129","rc":[{"batb":[[0,2.76,9.67],[1,2.58,27.18],[2,1.1,3000]],"ltp":2.78,"tv":1.05,"id":67083366}]}]}
{"op":"mcm","clk":"11958232668","pt":1724571096513,"mc":[{"id":"1.232245129","rc":[{"batb":[[0,2.78,4],[1,2.76,9.67],[2,2.58,27.18]],"ltp":2.78,"tv":1.05,"id":67083366}]}]}
{"op":"mcm","clk":"11958232839","pt":1724571098879,"mc":[{"id":"1.232245129","rc":[{"batb":[[0,2.76,9.67],[1,2.58,27.18],[2,1.1,3000]],"ltp":2.78,"tv":1.05,"id":67083366}]}]}
{"op":"mcm","clk":"11958233122","pt":1724571102683,"mc":[{"id":"1.232245129","rc":[{"batb":[[0,2.78,4],[1,2.76,9.67],[2,2.58,27.18]],"ltp":2.78,"tv":1.05,"id":67083366}]}]}
{"op":"mcm","clk":"11958233277","pt":1724571105105,"mc":[{"id":"1.232245129","rc":[{"batb":[[0,2.76,9.67],[1,2.58,27.18],[2,1.1,3000]],"ltp":2.78,"tv":1.05,"id":67083366}]}]}
{"op":"mcm","clk":"11958233451","pt":1724571107522,"mc":[{"id":"1.232245129","rc":[{"batb":[[0,2.78,4],[1,2.76,9.67],[2,2.58,27.18]],"ltp":2.78,"tv":1.05,"id":67083366}]}]}
{"op":"mcm","clk":"11958233574","pt":1724571109726,"mc":[{"id":"1.232245129","rc":[{"batb":[[0,2.76,9.67],[1,2.58,27.18],[2,1.1,3000]],"ltp":2.78,"tv":1.05,"id":67083366}]}]}
{"op":"mcm","clk":"11958234012","pt":1724571116132,"mc":[{"id":"1.232245129","rc":[{"batb":[[0,2.78,4],[1,2.76,9.67],[2,2.58,27.18]],"ltp":2.78,"tv":1.05,"id":67083366}]}]}
{"op":"mcm","clk":"11958234173","pt":1724571118496,"mc":[{"id":"1.232245129","rc":[{"batb":[[0,2.76,9.67],[1,2.58,27.18],[2,1.1,3000]],"ltp":2.78,"tv":1.05,"id":67083366}]}]}
{"op":"mcm","clk":"11958234288","pt":1724571120702,"mc":[{"id":"1.232245129","rc":[{"batb":[[0,2.78,4],[1,2.76,9.67],[2,2.58,27.18]],"ltp":2.78,"tv":1.05,"id":67083366}]}]}
{"op":"mcm","clk":"11958234449","pt":1724571123018,"mc":[{"id":"1.232245129","rc":[{"batb":[[0,2.76,9.67],[1,2.58,27.18],[2,1.1,3000]],"ltp":2.78,"tv":1.05,"id":67083366}]}]}
{"op":"mcm","clk":"11958234726","pt":1724571127338,"mc":[{"id":"1.232245129","rc":[{"batb":[[0,2.78,4],[1,2.76,9.67],[2,2.58,27.18]],"ltp":2.78,"tv":1.05,"id":67083366}]}]}
{"op":"mcm","clk":"11958234843","pt":1724571129744,"mc":[{"id":"1.232245129","rc":[{"batb":[[0,2.76,9.67],[1,2.58,27.18],[2,1.1,3000]],"ltp":2.78,"tv":1.05,"id":67083366}]}]}
{"op":"mcm","clk":"11958235144","pt":1724571134421,"mc":[{"id":"1.232245129","rc":[{"batb":[[0,2.78,4],[1,2.76,9.67],[2,2.58,27.18]],"ltp":2.78,"tv":1.05,"id":67083366}]}]}
{"op":"mcm","clk":"11958235340","pt":1724571136834,"mc":[{"id":"1.232245129","rc":[{"batb":[[0,2.76,9.67],[1,2.58,27.18],[2,1.1,3000]],"ltp":2.78,"tv":1.05,"id":67083366}]}]}
{"op":"mcm","clk":"11958235627","pt":1724571141763,"mc":[{"id":"1.232245129","rc":[{"batb":[[0,2.78,4],[1,2.76,9.67],[2,2.58,27.18]],"ltp":2.78,"tv":1.05,"id":67083366}]}]}
{"op":"mcm","clk":"11958235830","pt":1724571144133,"mc":[{"id":"1.232245129","rc":[{"batb":[[0,2.76,9.67],[1,2.58,27.18],[2,1.1,3000]],"ltp":2.78,"tv":1.05,"id":67083366}]}]}
{"op":"mcm","clk":"11958236176","pt":1724571148269,"mc":[{"id":"1.232245129","rc":[{"batb":[[0,2.78,4],[1,2.76,9.67],[2,2.58,27.18]],"ltp":2.78,"tv":1.05,"id":67083366}]}]}
{"op":"mcm","clk":"11958236345","pt":1724571150688,"mc":[{"id":"1.232245129","rc":[{"batb":[[0,2.76,9.67],[1,2.58,27.18],[2,1.1,3000]],"ltp":2.78,"tv":1.05,"id":67083366}]}]}
{"op":"mcm","clk":"11958236511","pt":1724571153159,"mc":[{"id":"1.232245129","rc":[{"batb":[[0,2.78,4],[1,2.76,9.67],[2,2.58,27.18]],"ltp":2.78,"tv":1.05,"id":67083366}]}]}
{"op":"mcm","clk":"11958236664","pt":1724571155479,"mc":[{"id":"1.232245129","rc":[{"batb":[[0,2.76,9.67],[1,2.58,27.18],[2,1.1,3000]],"ltp":2.78,"tv":1.05,"id":67083366}]}]}
{"op":"mcm","clk":"11958236934","pt":1724571159389,"mc":[{"id":"1.232245129","rc":[{"batb":[[0,2.78,4],[1,2.76,9.67],[2,2.58,27.18]],"ltp":2.78,"tv":1.05,"id":67083366}]}]}
{"op":"mcm","clk":"11958237104","pt":1724571161663,"mc":[{"id":"1.232245129","rc":[{"batb":[[0,2.76,9.67],[1,2.58,27.18],[2,1.1,3000]],"ltp":2.78,"tv":1.05,"id":67083366}]}]}
{"op":"mcm","clk":"11958237298","pt":1724571164087,"mc":[{"id":"1.232245129","rc":[{"batb":[[0,2.78,4],[1,2.76,9.67],[2,2.58,27.18]],"ltp":2.78,"tv":1.05,"id":67083366}]}]}
{"op":"mcm","clk":"11958237483","pt":1724571166400,"mc":[{"id":"1.232245129","rc":[{"batb":[[0,2.76,9.67],[1,2.58,27.18],[2,1.1,3000]],"ltp":2.78,"tv":1.05,"id":67083366}]}]}
{"op":"mcm","clk":"11958237773","pt":1724571171290,"mc":[{"id":"1.232245129","rc":[{"batb":[[0,2.78,4],[1,2.76,9.67],[2,2.58,27.18]],"ltp":2.78,"tv":1.05,"id":67083366}]}]}
{"op":"mcm","clk":"11958237931","pt":1724571173601,"mc":[{"id":"1.232245129","rc":[{"batb":[[0,2.76,9.67],[1,2.58,27.18],[2,1.1,3000]],"ltp":2.78,"tv":1.05,"id":67083366}]}]}
{"op":"mcm","clk":"11958238278","pt":1724571178374,"mc":[{"id":"1.232245129","rc":[{"batb":[[0,2.78,4],[1,2.76,9.67],[2,2.58,27.18]],"ltp":2.78,"tv":1.05,"id":67083366}]}]}
{"op":"mcm","clk":"11958238416","pt":1724571180780,"mc":[{"id":"1.232245129","rc":[{"batb":[[0,2.76,9.67],[1,2.58,27.18],[2,1.1,3000]],"ltp":2.78,"tv":1.05,"id":67083366}]}]}
{"op":"mcm","clk":"11958238658","pt":1724571184680,"mc":[{"id":"1.232245129","rc":[{"batb":[[0,2.78,4],[1,2.76,9.67],[2,2.58,27.18]],"ltp":2.78,"tv":1.05,"id":67083366}]}]}
{"op":"mcm","clk":"11958238813","pt":1724571187005,"mc":[{"id":"1.232245129","rc":[{"batb":[[0,2.76,9.67],[1,2.58,27.18],[2,1.1,3000]],"ltp":2.78,"tv":1.05,"id":67083366}]}]}
{"op":"mcm","clk":"11958239032","pt":1724571190792,"mc":[{"id":"1.232245129","rc":[{"batb":[[0,2.78,4],[1,2.76,9.67],[2,2.58,27.18]],"ltp":2.78,"tv":1.05,"id":67083366}]}]}
{"op":"mcm","clk":"11958239165","pt":1724571193208,"mc":[{"id":"1.232245129","rc":[{"batb":[[0,2.76,9.67],[1,2.58,27.18],[2,1.1,3000]],"ltp":2.78,"tv":1.05,"id":67083366}]}]}
{"op":"mcm","clk":"11958239327","pt":1724571195732,"mc":[{"id":"1.232245129","rc":[{"batb":[[0,2.78,4],[1,2.76,9.67],[2,2.58,27.18]],"ltp":2.78,"tv":1.05,"id":67083366}]}]}
{"op":"mcm","clk":"11958239398","pt":1724571197022,"mc":[{"id":"1.232245129","rc":[{"batb":[[0,1.55,5.63],[1,1.54,79.53],[2,1.32,126.2]],"ltp":1.56,"tv":180.88,"id":72922097}]}]}
{"op":"mcm","clk":"11958239471","pt":1724571198106,"mc":[{"id":"1.232245129","rc":[{"batb":[[0,2.76,9.67],[1,2.58,27.18],[2,1.1,3000]],"ltp":2.78,"tv":1.05,"id":67083366}]}]}
{"op":"mcm","clk":"11958239650","pt":1724571200827,"mc":[{"id":"1.232245129","rc":[{"batb":[[0,2.78,4],[1,2.76,9.67]],"ltp":2.78,"tv":1.05,"id":67083366},{"batb":[[1,1.32,126.2],[2,1.1,3000]],"ltp":1.56,"tv":180.88,"id":72922097}]}]}
{"op":"mcm","clk":"11958239800","pt":1724571203027,"mc":[{"id":"1.232245129","rc":[{"batb":[[0,2.76,9.67],[1,1.1,3000],[2,1.03,200]],"ltp":2.78,"tv":1.05,"id":67083366},{"batb":[[0,1.32,126.2],[1,1.1,3000],[2,1.03,200]],"ltp":1.56,"tv":180.88,"id":72922097}]}]}
{"op":"mcm","clk":"11958239984","pt":1724571205762,"mc":[{"id":"1.232245129","rc":[{"batb":[[0,2.78,4],[1,2.76,9.67],[2,2.58,27.18]],"ltp":2.78,"tv":1.05,"id":67083366},{"batb":[[0,1.54,79.53],[1,1.32,126.2],[2,1.1,3000]],"ltp":1.56,"tv":180.88,"id":72922097}]}]}
{"op":"mcm","clk":"11958240096","pt":1724571207552,"mc":[{"id":"1.232245129","rc":[{"batb":[[0,2.76,9.67],[1,2.58,27.18],[2,1.1,3000]],"ltp":2.78,"tv":1.05,"id":67083366}]}]}
{"op":"mcm","clk":"11958240519","pt":1724571215544,"mc":[{"id":"1.232245129","rc":[{"batb":[[0,2.78,4],[1,2.76,9.67],[2,2.58,27.18]],"ltp":2.78,"tv":1.05,"id":67083366}]}]}
{"op":"mcm","clk":"11958240643","pt":1724571217961,"mc":[{"id":"1.232245129","rc":[{"batb":[[0,2.76,9.67],[1,2.58,27.18],[2,1.1,3000]],"ltp":2.78,"tv":1.05,"id":67083366}]}]}
{"op":"mcm","clk":"11958240817","pt":1724571220230,"mc":[{"id":"1.232245129","rc":[{"batb":[[0,2.78,4],[1,2.76,9.67],[2,2.58,27.18]],"ltp":2.78,"tv":1.05,"id":67083366}]}]}
{"op":"mcm","clk":"11958240948","pt":1724571222440,"mc":[{"id":"1.232245129","rc":[{"batb":[[0,2.76,9.67],[1,2.58,27.18],[2,1.1,3000]],"ltp":2.78,"tv":1.05,"id":67083366}]}]}
{"op":"mcm","clk":"11958241171","pt":1724571225368,"mc":[{"id":"1.232245129","rc":[{"batb":[[0,2.78,4],[1,2.76,9.67],[2,2.58,27.18]],"ltp":2.78,"tv":1.05,"id":67083366}]}]}
{"op":"mcm","clk":"11958241331","pt":1724571227742,"mc":[{"id":"1.232245129","rc":[{"batb":[[0,2.76,9.67],[1,2.58,27.18],[2,1.1,3000]],"ltp":2.78,"tv":1.05,"id":67083366}]}]}
{"op":"mcm","clk":"11958241453","pt":1724571229946,"mc":[{"id":"1.232245129","rc":[{"batb":[[0,2.78,4],[1,2.76,9.67],[2,2.58,27.18]],"ltp":2.78,"tv":1.05,"id":67083366}]}]}
{"op":"mcm","clk":"11958241582","pt":1724571232254,"mc":[{"id":"1.232245129","rc":[{"batb":[[0,2.76,9.67],[1,2.58,27.18],[2,1.1,3000]],"ltp":2.78,"tv":1.05,"id":67083366}]}]}
{"op":"mcm","clk":"11958241735","pt":1724571234663,"mc":[{"id":"1.232245129","rc":[{"batb":[[0,2.78,4],[1,2.76,9.67],[2,2.58,27.18]],"ltp":2.78,"tv":1.05,"id":67083366}]}]}
{"op":"mcm","clk":"11958241892","pt":1724571237083,"mc":[{"id":"1.232245129","rc":[{"batb":[[0,2.76,9.67],[1,2.58,27.18],[2,1.1,3000]],"ltp":2.78,"tv":1.05,"id":67083366}]}]}
{"op":"mcm","clk":"11958242111","pt":1724571240398,"mc":[{"id":"1.232245129","rc":[{"batb":[[0,2.78,4],[1,2.76,9.67],[2,2.58,27.18]],"ltp":2.78,"tv":1.05,"id":67083366}]}]}
{"op":"mcm","clk":"11958242313","pt":1724571242770,"mc":[{"id":"1.232245129","rc":[{"batb":[[0,2.76,9.67],[1,2.58,27.18],[2,1.1,3000]],"ltp":2.78,"tv":1.05,"id":67083366}]}]}
{"op":"mcm","clk":"11958242622","pt":1724571247185,"mc":[{"id":"1.232245129","rc":[{"batb":[[0,2.78,4],[1,2.76,9.67],[2,2.58,27.18]],"ltp":2.78,"tv":1.05,"id":67083366}]}]}
{"op":"mcm","clk":"11958242759","pt":1724571249498,"mc":[{"id":"1.232245129","rc":[{"batb":[[0,2.76,9.67],[1,2.58,27.18],[2,1.1,3000]],"ltp":2.78,"tv":1.05,"id":67083366}]}]}
{"op":"mcm","clk":"11958242899","pt":1724571251811,"mc":[{"id":"1.232245129","rc":[{"batb":[[0,2.78,4],[1,2.76,9.67],[2,2.58,27.18]],"ltp":2.78,"tv":1.05,"id":67083366}]}]}
{"op":"mcm","clk":"11958243074","pt":1724571254118,"mc":[{"id":"1.232245129","rc":[{"batb":[[0,2.76,9.67],[1,2.58,27.18],[2,1.1,3000]],"ltp":2.78,"tv":1.05,"id":67083366}]}]}
{"op":"mcm","clk":"11958243247","pt":1724571256507,"mc":[{"id":"1.232245129","rc":[{"batb":[[0,2.78,4],[1,2.76,9.67],[2,2.58,27.18]],"ltp":2.78,"tv":1.05,"id":67083366}]}]}
{"op":"mcm","clk":"11958243415","pt":1724571258977,"mc":[{"id":"1.232245129","rc":[{"batb":[[0,2.76,9.67],[1,2.58,27.18],[2,1.1,3000]],"ltp":2.78,"tv":1.05,"id":67083366}]}]}
{"op":"mcm","clk":"11958243568","pt":1724571261284,"mc":[{"id":"1.232245129","rc":[{"batb":[[0,2.78,4],[1,2.76,9.67],[2,2.58,27.18]],"ltp":2.78,"tv":1.05,"id":67083366}]}]}
{"op":"mcm","clk":"11958243740","pt":1724571263600,"mc":[{"id":"1.232245129","rc":[{"batb":[[0,2.76,9.67],[1,2.58,27.18],[2,1.1,3000]],"ltp":2.78,"tv":1.05,"id":67083366}]}]}
{"op":"mcm","clk":"11958243994","pt":1724571267106,"mc":[{"id":"1.232245129","rc":[{"batb":[[0,2.78,4],[1,2.76,9.67],[2,2.58,27.18]],"ltp":2.78,"tv":1.05,"id":67083366}]}]}
{"op":"mcm","clk":"11958244138","pt":1724571269406,"mc":[{"id":"1.232245129","rc":[{"batb":[[0,2.76,9.67],[1,2.58,27.18],[2,1.1,3000]],"ltp":2.78,"tv":1.05,"id":67083366}]}]}
{"op":"mcm","clk":"11958244604","pt":1724571277003,"mc":[{"id":"1.232245129","rc":[{"batb":[[0,2.78,4],[1,2.76,9.67],[2,2.58,27.18]],"ltp":2.78,"tv":1.05,"id":67083366}]}]}
{"op":"mcm","clk":"11958244723","pt":1724571279518,"mc":[{"id":"1.232245129","rc":[{"batb":[[0,2.76,9.67],[1,2.58,27.18],[2,1.1,3000]],"ltp":2.78,"tv":1.05,"id":67083366}]}]}
{"op":"mcm","clk":"11958244914","pt":1724571282405,"mc":[{"id":"1.232245129","rc":[{"batb":[[0,2.78,4],[1,2.76,9.67],[2,2.58,27.18]],"ltp":2.78,"tv":1.05,"id":67083366}]}]}
{"op":"mcm","clk":"11958245068","pt":1724571284833,"mc":[{"id":"1.232245129","rc":[{"batb":[[0,2.76,9.67],[1,2.58,27.18],[2,1.1,3000]],"ltp":2.78,"tv":1.05,"id":67083366}]}]}
{"op":"mcm","clk":"11958245232","pt":1724571288213,"mc":[{"id":"1.232245129","rc":[{"batb":[[0,2.78,4],[1,2.76,9.67],[2,2.58,27.18]],"ltp":2.78,"tv":1.05,"id":67083366}]}]}
{"op":"mcm","clk":"11958245344","pt":1724571290429,"mc":[{"id":"1.232245129","rc":[{"batb":[[0,2.76,9.67],[1,2.58,27.18],[2,1.1,3000]],"ltp":2.78,"tv":1.05,"id":67083366}]}]}
{"op":"mcm","clk":"11958245681","pt":1724571296323,"mc":[{"id":"1.232245129","rc":[{"batb":[[0,2.78,4],[1,2.76,9.67],[2,2.58,27.18]],"ltp":2.78,"tv":1.05,"id":67083366}]}]}
{"op":"mcm","clk":"11958245803","pt":1724571298846,"mc":[{"id":"1.232245129","rc":[{"batb":[[0,2.76,9.67],[1,2.58,27.18],[2,1.1,3000]],"ltp":2.78,"tv":1.05,"id":67083366}]}]}
{"op":"mcm","clk":"11958246045","pt":1724571302638,"mc":[{"id":"1.232245129","rc":[{"batb":[[0,2.78,4],[1,2.76,9.67],[2,2.58,27.18]],"ltp":2.78,"tv":1.05,"id":67083366}]}]}
{"op":"mcm","clk":"11958246231","pt":1724571305115,"mc":[{"id":"1.232245129","rc":[{"batb":[[0,2.76,9.67],[1,2.58,27.18],[2,1.1,3000]],"ltp":2.78,"tv":1.05,"id":67083366}]}]}
{"op":"mcm","clk":"11958246748","pt":1724571313430,"mc":[{"id":"1.232245129","rc":[{"batb":[[0,2.78,4],[1,2.76,9.67],[2,2.58,27.18]],"ltp":2.78,"tv":1.05,"id":67083366}]}]}
{"op":"mcm","clk":"11958246891","pt":1724571315843,"mc":[{"id":"1.232245129","rc":[{"batb":[[0,2.76,9.67],[1,2.58,27.18],[2,1.1,3000]],"ltp":2.78,"tv":1.05,"id":67083366}]}]}
{"op":"mcm","clk":"11958247128","pt":1724571319645,"mc":[{"id":"1.232245129","rc":[{"batb":[[0,2.78,4],[1,2.76,9.67],[2,2.58,27.18]],"ltp":2.78,"tv":1.05,"id":67083366}]}]}
{"op":"mcm","clk":"11958247285","pt":1724571322157,"mc":[{"id":"1.232245129","rc":[{"batb":[[0,2.76,9.67],[1,2.58,27.18],[2,1.1,3000]],"ltp":2.78,"tv":1.05,"id":67083366}]}]}
{"op":"mcm","clk":"11958247665","pt":1724571327757,"mc":[{"id":"1.232245129","rc":[{"batb":[[0,2.78,4],[1,2.76,9.67],[2,2.58,27.18]],"ltp":2.78,"tv":1.05,"id":67083366}]}]}
{"op":"mcm","clk":"11958247796","pt":1724571330054,"mc":[{"id":"1.232245129","rc":[{"batb":[[0,2.76,9.67],[1,2.58,27.18],[2,1.1,3000]],"ltp":2.78,"tv":1.05,"id":67083366}]}]}
{"op":"mcm","clk":"11958248082","pt":1724571333864,"mc":[{"id":"1.232245129","rc":[{"batb":[[0,2.78,4],[1,2.76,9.67],[2,2.58,27.18]],"ltp":2.78,"tv":1.05,"id":67083366}]}]}
{"op":"mcm","clk":"11958248225","pt":1724571336072,"mc":[{"id":"1.232245129","rc":[{"batb":[[0,2.76,9.67],[1,2.58,27.18],[2,1.1,3000]],"ltp":2.78,"tv":1.05,"id":67083366}]}]}
{"op":"mcm","clk":"11958248553","pt":1724571340953,"mc":[{"id":"1.232245129","rc":[{"batb":[[0,2.78,4],[1,2.76,9.67],[2,2.58,27.18]],"ltp":2.78,"tv":1.05,"id":67083366}]}]}
{"op":"mcm","clk":"11958248769","pt":1724571343583,"mc":[{"id":"1.232245129","rc":[{"batb":[[0,2.76,9.67],[1,2.58,27.18],[2,1.1,3000]],"ltp":2.78,"tv":1.05,"id":67083366}]}]}
{"op":"mcm","clk":"11958248901","pt":1724571345796,"mc":[{"id":"1.232245129","rc":[{"batb":[[0,2.78,4],[1,2.76,9.67],[2,2.58,27.18]],"ltp":2.78,"tv":1.05,"id":67083366}]}]}
{"op":"mcm","clk":"11958249046","pt":1724571348197,"mc":[{"id":"1.232245129","rc":[{"batb":[[0,2.76,9.67],[1,2.58,27.18],[2,1.1,3000]],"ltp":2.78,"tv":1.05,"id":67083366}]}]}
{"op":"mcm","clk":"11958249402","pt":1724571354403,"mc":[{"id":"1.232245129","rc":[{"batb":[[0,2.78,4],[1,2.76,9.67],[2,2.58,27.18]],"ltp":2.78,"tv":1.05,"id":67083366}]}]}
{"op":"mcm","clk":"11958249554","pt":1724571356763,"mc":[{"id":"1.232245129","rc":[{"batb":[[0,2.76,9.67],[1,2.58,27.18],[2,1.1,3000]],"ltp":2.78,"tv":1.05,"id":67083366}]}]}
{"op":"mcm","clk":"11958249660","pt":1724571359168,"mc":[{"id":"1.232245129","rc":[{"batb":[[0,2.78,4],[1,2.76,9.67],[2,2.58,27.18]],"ltp":2.78,"tv":1.05,"id":67083366}]}]}
{"op":"mcm","clk":"11958249788","pt":1724571361490,"mc":[{"id":"1.232245129","rc":[{"batb":[[0,2.76,9.67],[1,2.58,27.18],[2,1.1,3000]],"ltp":2.78,"tv":1.05,"id":67083366}]}]}
{"op":"mcm","clk":"11958249975","pt":1724571364108,"mc":[{"id":"1.232245129","rc":[{"batb":[[0,2.78,4],[1,2.76,9.67],[2,2.58,27.18]],"ltp":2.78,"tv":1.05,"id":67083366}]}]}
{"op":"mcm","clk":"11958250240","pt":1724571368414,"mc":[{"id":"1.232245129","rc":[{"batb":[[0,2.76,9.67],[1,2.58,27.18],[2,1.1,3000]],"ltp":2.78,"tv":1.05,"id":67083366}]}]}
{"op":"mcm","clk":"11958250570","pt":1724571373802,"mc":[{"id":"1.232245129","rc":[{"batb":[[0,2.78,4],[1,2.76,9.67],[2,2.58,27.18]],"ltp":2.78,"tv":1.05,"id":67083366}]}]}
{"op":"mcm","clk":"11958250718","pt":1724571376007,"mc":[{"id":"1.232245129","rc":[{"batb":[[0,2.76,9.67],[1,2.58,27.18],[2,1.1,3000]],"ltp":2.78,"tv":1.05,"id":67083366}]}]}
{"op":"mcm","clk":"11958251136","pt":1724571382289,"mc":[{"id":"1.232245129","rc":[{"batb":[[0,2.78,4],[1,2.76,9.67],[2,2.58,27.18]],"ltp":2.78,"tv":1.05,"id":67083366}]}]}
{"op":"mcm","clk":"11958251307","pt":1724571384693,"mc":[{"id":"1.232245129","rc":[{"batb":[[0,2.76,9.67],[1,2.58,27.18],[2,1.1,3000]],"ltp":2.78,"tv":1.05,"id":67083366}]}]}
{"op":"mcm","clk":"11958251471","pt":1724571387209,"mc":[{"id":"1.232245129","rc":[{"batb":[[0,2.78,4],[1,2.76,9.67],[2,2.58,27.18]],"ltp":2.78,"tv":1.05,"id":67083366}]}]}
{"op":"mcm","clk":"11958251655","pt":1724571389623,"mc":[{"id":"1.232245129","rc":[{"batb":[[0,2.76,9.67],[1,2.58,27.18],[2,1.1,3000]],"ltp":2.78,"tv":1.05,"id":67083366}]}]}
{"op":"mcm","clk":"11958251907","pt":1724571394022,"mc":[{"id":"1.232245129","rc":[{"batb":[[0,2.78,4],[1,2.76,9.67],[2,2.58,27.18]],"ltp":2.78,"tv":1.05,"id":67083366}]}]}
{"op":"mcm","clk":"11958252086","pt":1724571396428,"mc":[{"id":"1.232245129","rc":[{"batb":[[0,2.76,9.67],[1,2.58,27.18],[2,1.1,3000]],"ltp":2.78,"tv":1.05,"id":67083366}]}]}
{"op":"mcm","clk":"11958252331","pt":1724571399752,"mc":[{"id":"1.232245129","rc":[{"batb":[[0,2.78,4],[1,2.76,9.67],[2,2.58,27.18]],"ltp":2.78,"tv":1.05,"id":67083366}]}]}
{"op":"mcm","clk":"11958252502","pt":1724571402164,"mc":[{"id":"1.232245129","rc":[{"batb":[[0,2.76,9.67],[1,2.58,27.18],[2,1.1,3000]],"ltp":2.78,"tv":1.05,"id":67083366}]}]}
{"op":"mcm","clk":"11958252856","pt":1724571406831,"mc":[{"id":"1.232245129","rc":[{"batb":[[0,2.78,4],[1,2.76,9.67],[2,2.58,27.18]],"ltp":2.78,"tv":1.05,"id":67083366}]}]}
{"op":"mcm","clk":"11958253037","pt":1724571409248,"mc":[{"id":"1.232245129","rc":[{"batb":[[0,2.76,9.67],[1,2.58,27.18],[2,1.1,3000]],"ltp":2.78,"tv":1.05,"id":67083366}]}]}
{"op":"mcm","clk":"11958253454","pt":1724571415152,"mc":[{"id":"1.232245129","rc":[{"batb":[[0,2.78,4],[1,2.76,9.67],[2,2.58,27.18]],"ltp":2.78,"tv":1.05,"id":67083366}]}]}
{"op":"mcm","clk":"11958253641","pt":1724571417370,"mc":[{"id":"1.232245129","rc":[{"batb":[[0,2.76,9.67],[1,2.58,27.18],[2,1.1,3000]],"ltp":2.78,"tv":1.05,"id":67083366}]}]}
{"op":"mcm","clk":"11958254007","pt":1724571423483,"mc":[{"id":"1.232245129","rc":[{"batb":[[0,2.78,4],[1,2.76,9.67],[2,2.58,27.18]],"ltp":2.78,"tv":1.05,"id":67083366}]}]}
{"op":"mcm","clk":"11958254162","pt":1724571425952,"mc":[{"id":"1.232245129","rc":[{"batb":[[0,2.76,9.67],[1,2.58,27.18],[2,1.1,3000]],"ltp":2.78,"tv":1.05,"id":67083366}]}]}
{"op":"mcm","clk":"11958254334","pt":1724571428464,"mc":[{"id":"1.232245129","rc":[{"batb":[[0,2.78,4],[1,2.76,9.67],[2,2.58,27.18]],"ltp":2.78,"tv":1.05,"id":67083366}]}]}
{"op":"mcm","clk":"11958254508","pt":1724571430789,"mc":[{"id":"1.232245129","rc":[{"batb":[[0,2.76,9.67],[1,2.58,27.18],[2,1.1,3000]],"ltp":2.78,"tv":1.05,"id":67083366}]}]}
{"op":"mcm","clk":"11958254651","pt":1724571433094,"mc":[{"id":"1.232245129","rc":[{"batb":[[0,2.78,4],[1,2.76,9.67],[2,2.58,27.18]],"ltp":2.78,"tv":1.05,"id":67083366}]}]}
{"op":"mcm","clk":"11958254818","pt":1724571435396,"mc":[{"id":"1.232245129","rc":[{"batb":[[0,2.76,9.67],[1,2.58,27.18],[2,1.1,3000]],"ltp":2.78,"tv":1.05,"id":67083366}]}]}
{"op":"mcm","clk":"11958255000","pt":1724571437812,"mc":[{"id":"1.232245129","rc":[{"batb":[[0,2.78,4],[1,2.76,9.67],[2,2.58,27.18]],"ltp":2.78,"tv":1.05,"id":67083366},{"batb":[[0,1.55,5.63],[1,1.54,79.53],[2,1.32,126.2]],"ltp":1.56,"tv":180.88,"id":72922097}]}]}
{"op":"mcm","clk":"11958255165","pt":1724571440219,"mc":[{"id":"1.232245129","rc":[{"batb":[[0,2.76,9.67],[1,2.58,27.18],[2,1.1,3000]],"ltp":2.78,"tv":1.05,"id":67083366}]}]}
{"op":"mcm","clk":"11958255327","pt":1724571442183,"mc":[{"id":"1.232245129","rc":[{"batb":[[1,1.1,3000],[2,1.03,200]],"ltp":2.78,"tv":1.05,"id":67083366},{"batb":[[0,1.32,126.2],[1,1.1,3000],[2,1.03,200]],"ltp":1.56,"tv":180.88,"id":72922097}]}]}
{"op":"mcm","clk":"11958255452","pt":1724571443824,"mc":[{"id":"1.232245129","rc":[{"batb":[[0,2.78,4],[1,2.76,9.67],[2,1.1,3000]],"ltp":2.78,"tv":1.05,"id":67083366}]}]}
{"op":"mcm","clk":"11958255597","pt":1724571446232,"mc":[{"id":"1.232245129","rc":[{"batb":[[0,2.76,9.67],[1,1.1,3000],[2,1.03,200]],"ltp":2.78,"tv":1.05,"id":67083366}]}]}
{"op":"mcm","clk":"11958255619","pt":1724571446488,"mc":[{"id":"1.232245129","rc":[{"batb":[[1,2.58,27.18],[2,1.1,3000]],"ltp":2.78,"tv":1.05,"id":67083366},{"batb":[[0,1.54,79.53],[1,1.32,126.2],[2,1.1,3000]],"ltp":1.56,"tv":180.88,"id":72922097}]}]}
{"op":"mcm","clk":"11958255766","pt":1724571449198,"mc":[{"id":"1.232245129","rc":[{"batb":[[0,2.78,4],[1,2.76,9.67],[2,2.58,27.18]],"ltp":2.78,"tv":1.05,"id":67083366}]}]}
{"op":"mcm","clk":"11958255886","pt":1724571451501,"mc":[{"id":"1.232245129","rc":[{"batb":[[0,2.76,9.67],[1,2.58,27.18],[2,1.1,3000]],"ltp":2.78,"tv":1.05,"id":67083366}]}]}
{"op":"mcm","clk":"11958256113","pt":1724571454490,"mc":[{"id":"1.232245129","rc":[{"batb":[[0,2.78,4],[1,2.76,9.67],[2,2.58,27.18]],"ltp":2.78,"tv":1.05,"id":67083366}]}]}
{"op":"mcm","clk":"11958256272","pt":1724571456792,"mc":[{"id":"1.232245129","rc":[{"batb":[[0,2.76,9.67],[1,2.58,27.18],[2,1.1,3000]],"ltp":2.78,"tv":1.05,"id":67083366}]}]}
{"op":"mcm","clk":"11958256516","pt":1724571460332,"mc":[{"id":"1.232245129","rc":[{"batb":[[0,2.78,4],[1,2.76,9.67],[2,2.58,27.18]],"ltp":2.78,"tv":1.05,"id":67083366}]}]}
{"op":"mcm","clk":"11958256723","pt":1724571462841,"mc":[{"id":"1.232245129","rc":[{"batb":[[0,2.76,9.67],[1,2.58,27.18],[2,1.1,3000]],"ltp":2.78,"tv":1.05,"id":67083366}]}]}
{"op":"mcm","clk":"11958257003","pt":1724571466339,"mc":[{"id":"1.232245129","rc":[{"batb":[[0,2.78,4],[1,2.76,9.67],[2,2.58,27.18]],"ltp":2.78,"tv":1.05,"id":67083366}]}]}
{"op":"mcm","clk":"11958257154","pt":1724571468651,"mc":[{"id":"1.232245129","rc":[{"batb":[[0,2.76,9.67],[1,2.58,27.18],[2,1.1,3000]],"ltp":2.78,"tv":1.05,"id":67083366}]}]}
{"op":"mcm","clk":"11958257437","pt":1724571473023,"mc":[{"id":"1.232245129","rc":[{"batb":[[0,2.78,4],[1,2.76,9.67],[2,2.58,27.18]],"ltp":2.78,"tv":1.05,"id":67083366}]}]}
{"op":"mcm","clk":"11958257598","pt":1724571475432,"mc":[{"id":"1.232245129","rc":[{"batb":[[0,2.76,9.67],[1,2.58,27.18],[2,1.1,3000]],"ltp":2.78,"tv":1.05,"id":67083366}]}]}
{"op":"mcm","clk":"11958257776","pt":1724571477948,"mc":[{"id":"1.232245129","rc":[{"batb":[[0,2.78,4],[1,2.76,9.67],[2,2.58,27.18]],"ltp":2.78,"tv":1.05,"id":67083366}]}]}
{"op":"mcm","clk":"11958257913","pt":1724571480154,"mc":[{"id":"1.232245129","rc":[{"batb":[[0,2.76,9.67],[1,2.58,27.18],[2,1.1,3000]],"ltp":2.78,"tv":1.05,"id":67083366}]}]}
{"op":"mcm","clk":"11958258106","pt":1724571482632,"mc":[{"id":"1.232245129","rc":[{"batb":[[0,2.78,4],[1,2.76,9.67],[2,2.58,27.18]],"ltp":2.78,"tv":1.05,"id":67083366}]}]}
{"op":"mcm","clk":"11958258248","pt":1724571485151,"mc":[{"id":"1.232245129","rc":[{"batb":[[0,2.76,9.67],[1,2.58,27.18],[2,1.1,3000]],"ltp":2.78,"tv":1.05,"id":67083366}]}]}
{"op":"mcm","clk":"11958258399","pt":1724571487575,"mc":[{"id":"1.232245129","rc":[{"batb":[[0,2.78,4],[1,2.76,9.67],[2,2.58,27.18]],"ltp":2.78,"tv":1.05,"id":67083366}]}]}
{"op":"mcm","clk":"11958258565","pt":1724571489838,"mc":[{"id":"1.232245129","rc":[{"batb":[[0,2.76,9.67],[1,2.58,27.18],[2,1.1,3000]],"ltp":2.78,"tv":1.05,"id":67083366}]}]}
{"op":"mcm","clk":"11958258892","pt":1724571494063,"mc":[{"id":"1.232245129","rc":[{"batb":[[0,2.78,4],[1,2.76,9.67],[2,2.58,27.18]],"ltp":2.78,"tv":1.05,"id":67083366}]}]}
{"op":"mcm","clk":"11958259046","pt":1724571496377,"mc":[{"id":"1.232245129","rc":[{"batb":[[0,2.76,9.67],[1,2.58,27.18],[2,1.1,3000]],"ltp":2.78,"tv":1.05,"id":67083366}]}]}
{"op":"mcm","clk":"11958259671","pt":1724571504602,"mc":[{"id":"1.232245129","rc":[{"batb":[[0,2.78,4],[1,2.76,9.67],[2,2.58,27.18]],"ltp":2.78,"tv":1.05,"id":67083366}]}]}
{"op":"mcm","clk":"11958259861","pt":1724571506976,"mc":[{"id":"1.232245129","rc":[{"batb":[[0,2.76,9.67],[1,2.58,27.18],[2,1.1,3000]],"ltp":2.78,"tv":1.05,"id":67083366}]}]}
{"op":"mcm","clk":"11958260066","pt":1724571510768,"mc":[{"id":"1.232245129","rc":[{"batb":[[0,2.78,4],[1,2.76,9.67],[2,2.58,27.18]],"ltp":2.78,"tv":1.05,"id":67083366}]}]}
{"op":"mcm","clk":"11958260276","pt":1724571513088,"mc":[{"id":"1.232245129","rc":[{"batb":[[0,2.76,9.67],[1,2.58,27.18],[2,1.1,3000]],"ltp":2.78,"tv":1.05,"id":67083366}]}]}
{"op":"mcm","clk":"11958260473","pt":1724571515592,"mc":[{"id":"1.232245129","rc":[{"batb":[[0,2.78,4],[1,2.76,9.67],[2,2.58,27.18]],"ltp":2.78,"tv":1.05,"id":67083366}]}]}
{"op":"mcm","clk":"11958260643","pt":1724571517902,"mc":[{"id":"1.232245129","rc":[{"batb":[[0,2.76,9.67],[1,2.58,27.18],[2,1.1,3000]],"ltp":2.78,"tv":1.05,"id":67083366}]}]}
{"op":"mcm","clk":"11958260800","pt":1724571520007,"mc":[{"id":"1.232245129","rc":[{"batb":[[0,2.78,4],[1,2.76,9.67],[2,2.58,27.18]],"ltp":2.78,"tv":1.05,"id":67083366}]}]}
{"op":"mcm","clk":"11958260990","pt":1724571522318,"mc":[{"id":"1.232245129","rc":[{"batb":[[0,2.76,9.67],[1,2.58,27.18],[2,1.1,3000]],"ltp":2.78,"tv":1.05,"id":67083366}]}]}
{"op":"mcm","clk":"11958261278","pt":1724571525814,"mc":[{"id":"1.232245129","rc":[{"batb":[[0,2.78,4],[1,2.76,9.67],[2,2.58,27.18]],"ltp":2.78,"tv":1.05,"id":67083366}]}]}
{"op":"mcm","clk":"11958261449","pt":1724571528228,"mc":[{"id":"1.232245129","rc":[{"batb":[[0,2.76,9.67],[1,2.58,27.18],[2,1.1,3000]],"ltp":2.78,"tv":1.05,"id":67083366}]}]}
{"op":"mcm","clk":"11958262033","pt":1724571534712,"mc":[{"id":"1.232245129","rc":[{"batb":[[0,2.78,4],[1,2.76,9.67],[2,2.58,27.18]],"ltp":2.78,"tv":1.05,"id":67083366}]}]}
{"op":"mcm","clk":"11958262283","pt":1724571537208,"mc":[{"id":"1.232245129","rc":[{"batb":[[0,2.76,9.67],[1,2.58,27.18],[2,1.1,3000]],"ltp":2.78,"tv":1.05,"id":67083366}]}]}
{"op":"mcm","clk":"11958262596","pt":1724571540744,"mc":[{"id":"1.232245129","rc":[{"batb":[[0,2.78,4],[1,2.76,9.67],[2,2.58,27.18]],"ltp":2.78,"tv":1.05,"id":67083366}]}]}
{"op":"mcm","clk":"11958262839","pt":1724571543009,"mc":[{"id":"1.232245129","rc":[{"batb":[[0,2.76,9.67],[1,2.58,27.18],[2,1.1,3000]],"ltp":2.78,"tv":1.05,"id":67083366}]}]}
{"op":"mcm","clk":"11958263476","pt":1724571550839,"mc":[{"id":"1.232245129","rc":[{"batb":[[0,2.78,4],[1,2.76,9.67],[2,2.58,27.18]],"ltp":2.78,"tv":1.05,"id":67083366}]}]}
{"op":"mcm","clk":"11958263672","pt":1724571553248,"mc":[{"id":"1.232245129","rc":[{"batb":[[0,2.76,9.67],[1,2.58,27.18],[2,1.1,3000]],"ltp":2.78,"tv":1.05,"id":67083366}]}]}
{"op":"mcm","clk":"11958264002","pt":1724571557057,"mc":[{"id":"1.232245129","rc":[{"batb":[[0,2.78,4],[1,2.76,9.67],[2,2.58,27.18]],"ltp":2.78,"tv":1.05,"id":67083366}]}]}
{"op":"mcm","clk":"11958264208","pt":1724571559300,"mc":[{"id":"1.232245129","rc":[{"batb":[[0,2.76,9.67],[1,2.58,27.18],[2,1.1,3000]],"ltp":2.78,"tv":1.05,"id":67083366}]}]}
{"op":"mcm","clk":"11958264460","pt":1724571562045,"mc":[{"id":"1.232245129","rc":[{"batb":[[0,2.78,4],[1,2.76,9.67],[2,2.58,27.18]],"ltp":2.78,"tv":1.05,"id":67083366}]}]}
{"op":"mcm","clk":"11958264668","pt":1724571564461,"mc":[{"id":"1.232245129","rc":[{"batb":[[0,2.76,9.67],[1,2.58,27.18],[2,1.1,3000]],"ltp":2.78,"tv":1.05,"id":67083366}]}]}
{"op":"mcm","clk":"11958265251","pt":1724571571442,"mc":[{"id":"1.232245129","rc":[{"batb":[[0,2.78,4],[1,2.76,9.67],[2,2.58,27.18]],"ltp":2.78,"tv":1.05,"id":67083366}]}]}
{"op":"mcm","clk":"11958265458","pt":1724571573856,"mc":[{"id":"1.232245129","rc":[{"batb":[[0,2.76,9.67],[1,2.58,27.18],[2,1.1,3000]],"ltp":2.78,"tv":1.05,"id":67083366}]}]}
{"op":"mcm","clk":"11958265757","pt":1724571577659,"mc":[{"id":"1.232245129","rc":[{"batb":[[0,2.78,4],[1,2.76,9.67],[2,2.58,27.18]],"ltp":2.78,"tv":1.05,"id":67083366}]}]}
{"op":"mcm","clk":"11958265915","pt":1724571579962,"mc":[{"id":"1.232245129","rc":[{"batb":[[0,2.76,9.67],[1,2.58,27.18],[2,1.1,3000]],"ltp":2.78,"tv":1.05,"id":67083366}]}]}
{"op":"mcm","clk":"11958266113","pt":1724571582394,"mc":[{"id":"1.232245129","rc":[{"batb":[[0,2.78,4],[1,2.76,9.67],[2,2.58,27.18]],"ltp":2.78,"tv":1.05,"id":67083366}]}]}
{"op":"mcm","clk":"11958266318","pt":1724571584663,"mc":[{"id":"1.232245129","rc":[{"batb":[[0,2.76,9.67],[1,2.58,27.18],[2,1.1,3000]],"ltp":2.78,"tv":1.05,"id":67083366}]}]}
{"op":"mcm","clk":"11958266540","pt":1724571587566,"mc":[{"id":"1.232245129","rc":[{"batb":[[0,2.78,4],[1,2.76,9.67],[2,2.58,27.18]],"ltp":2.78,"tv":1.05,"id":67083366}]}]}
{"op":"mcm","clk":"11958266711","pt":1724571589870,"mc":[{"id":"1.232245129","rc":[{"batb":[[0,2.76,9.67],[1,2.58,27.18],[2,1.1,3000]],"ltp":2.78,"tv":1.05,"id":67083366}]}]}
{"op":"mcm","clk":"11958267072","pt":1724571594595,"mc":[{"id":"1.232245129","rc":[{"batb":[[0,2.78,4],[1,2.76,9.67],[2,2.58,27.18]],"ltp":2.78,"tv":1.05,"id":67083366}]}]}
{"op":"mcm","clk":"11958267271","pt":1724571597014,"mc":[{"id":"1.232245129","rc":[{"batb":[[0,2.76,9.67],[1,2.58,27.18],[2,1.1,3000]],"ltp":2.78,"tv":1.05,"id":67083366}]}]}
{"op":"mcm","clk":"11958267765","pt":1724571602706,"mc":[{"id":"1.232245129","rc":[{"batb":[[0,2.78,4],[1,2.76,9.67],[2,2.58,27.18]],"ltp":2.78,"tv":1.05,"id":67083366}]}]}
{"op":"mcm","clk":"11958267968","pt":1724571605128,"mc":[{"id":"1.232245129","rc":[{"batb":[[0,2.76,9.67],[1,2.58,27.18],[2,1.1,3000]],"ltp":2.78,"tv":1.05,"id":67083366}]}]}
{"op":"mcm","clk":"11958268188","pt":1724571607601,"mc":[{"id":"1.232245129","rc":[{"batb":[[0,2.78,4],[1,2.76,9.67],[2,2.58,27.18]],"ltp":2.78,"tv":1.05,"id":67083366}]}]}
{"op":"mcm","clk":"11958268397","pt":1724571610032,"mc":[{"id":"1.232245129","rc":[{"batb":[[0,2.76,9.67],[1,2.58,27.18],[2,1.1,3000]],"ltp":2.78,"tv":1.05,"id":67083366}]}]}
{"op":"mcm","clk":"11958268620","pt":1724571612188,"mc":[{"id":"1.232245129","rc":[{"batb":[[0,2.78,4],[1,2.76,9.67],[2,2.58,27.18]],"ltp":2.78,"tv":1.05,"id":67083366}]}]}
{"op":"mcm","clk":"11958268827","pt":1724571614414,"mc":[{"id":"1.232245129","rc":[{"batb":[[0,2.76,9.67],[1,2.58,27.18],[2,1.1,3000]],"ltp":2.78,"tv":1.05,"id":67083366}]}]}
{"op":"mcm","clk":"11958269173","pt":1724571618799,"mc":[{"id":"1.232245129","rc":[{"batb":[[0,2.78,4],[1,2.76,9.67],[2,2.58,27.18]],"ltp":2.78,"tv":1.05,"id":67083366},{"batb":[[0,1.55,5.63],[1,1.54,79.53],[2,1.32,126.2]],"ltp":1.56,"tv":180.88,"id":72922097}]}]}
{"op":"mcm","clk":"11958269368","pt":1724571621105,"mc":[{"id":"1.232245129","rc":[{"batb":[[0,2.76,9.67],[1,2.58,27.18],[2,1.1,3000]],"ltp":2.78,"tv":1.05,"id":67083366}]}]}
{"op":"mcm","clk":"11958269441","pt":1724571621936,"mc":[{"id":"1.232245129","rc":[{"batb":[[1,1.1,3000],[2,1.03,200]],"ltp":2.78,"tv":1.05,"id":67083366},{"batb":[[1,1.32,126.2],[2,1.1,3000]],"ltp":1.56,"tv":180.88,"id":72922097}]}]}
{"op":"mcm","clk":"11958269531","pt":1724571623013,"mc":[{"id":"1.232245129","rc":[{"batb":[[0,1.32,126.2],[1,1.1,3000],[2,1.03,200]],"ltp":1.56,"tv":180.88,"id":72922097}]}]}
{"op":"mcm","clk":"11958269615","pt":1724571624241,"mc":[{"id":"1.232245129","rc":[{"batb":[[0,2.78,4],[1,2.76,9.67],[2,1.1,3000]],"ltp":2.78,"tv":1.05,"id":67083366}]}]}
{"op":"mcm","clk":"11958269798","pt":1724571626917,"mc":[{"id":"1.232245129","rc":[{"batb":[[0,2.76,9.67],[1,2.58,27.18]],"ltp":2.78,"tv":1.05,"id":67083366},{"batb":[[0,1.54,79.53],[1,1.32,126.2],[2,1.1,3000]],"ltp":1.56,"tv":180.88,"id":72922097}]}]}
{"op":"mcm","clk":"11958269942","pt":1724571628918,"mc":[{"id":"1.232245129","rc":[{"batb":[[0,2.78,4],[1,2.76,9.67],[2,2.58,27.18]],"ltp":2.78,"tv":1.05,"id":67083366}]}]}
{"op":"mcm","clk":"11958270092","pt":1724571631224,"mc":[{"id":"1.232245129","rc":[{"batb":[[0,2.76,9.67],[1,2.58,27.18],[2,1.1,3000]],"ltp":2.78,"tv":1.05,"id":67083366}]}]}
{"op":"mcm","clk":"11958270246","pt":1724571633636,"mc":[{"id":"1.232245129","rc":[{"batb":[[0,2.78,4],[1,2.76,9.67],[2,2.58,27.18]],"ltp":2.78,"tv":1.05,"id":67083366}]}]}
{"op":"mcm","clk":"11958270441","pt":1724571636154,"mc":[{"id":"1.232245129","rc":[{"batb":[[0,2.76,9.67],[1,2.58,27.18],[2,1.1,3000]],"ltp":2.78,"tv":1.05,"id":67083366}]}]}
{"op":"mcm","clk":"11958270603","pt":1724571638569,"mc":[{"id":"1.232245129","rc":[{"batb":[[0,2.78,4],[1,2.76,9.67],[2,2.58,27.18]],"ltp":2.78,"tv":1.05,"id":67083366}]}]}
{"op":"mcm","clk":"11958270808","pt":1724571640864,"mc":[{"id":"1.232245129","rc":[{"batb":[[0,2.76,9.67],[1,2.58,27.18],[2,1.1,3000]],"ltp":2.78,"tv":1.05,"id":67083366}]}]}
{"op":"mcm","clk":"11958271360","pt":1724571647277,"mc":[{"id":"1.232245129","rc":[{"batb":[[0,2.78,4],[1,2.76,9.67],[2,2.58,27.18]],"ltp":2.78,"tv":1.05,"id":67083366}]}]}
{"op":"mcm","clk":"11958271535","pt":1724571649750,"mc":[{"id":"1.232245129","rc":[{"batb":[[0,2.76,9.67],[1,2.58,27.18],[2,1.1,3000]],"ltp":2.78,"tv":1.05,"id":67083366}]}]}
{"op":"mcm","clk":"11958271974","pt":1724571655750,"mc":[{"id":"1.232245129","rc":[{"batb":[[0,2.78,4],[1,2.76,9.67],[2,2.58,27.18]],"ltp":2.78,"tv":1.05,"id":67083366}]}]}
{"op":"mcm","clk":"11958272202","pt":1724571658478,"mc":[{"id":"1.232245129","rc":[{"batb":[[0,2.76,9.67],[1,2.58,27.18],[2,1.1,3000]],"ltp":2.78,"tv":1.05,"id":67083366}]}]}
{"op":"mcm","clk":"11958272396","pt":1724571660749,"mc":[{"id":"1.232245129","rc":[{"batb":[[0,2.78,4],[1,2.76,9.67],[2,2.58,27.18]],"ltp":2.78,"tv":1.05,"id":67083366}]}]}
{"op":"mcm","clk":"11958272599","pt":1724571663073,"mc":[{"id":"1.232245129","rc":[{"batb":[[0,2.76,9.67],[1,2.58,27.18],[2,1.1,3000]],"ltp":2.78,"tv":1.05,"id":67083366}]}]}
{"op":"mcm","clk":"11958273285","pt":1724571671003,"mc":[{"id":"1.232245129","rc":[{"batb":[[0,2.78,4],[1,2.76,9.67],[2,2.58,27.18]],"ltp":2.78,"tv":1.05,"id":67083366}]}]}
{"op":"mcm","clk":"11958273463","pt":1724571673316,"mc":[{"id":"1.232245129","rc":[{"batb":[[0,2.76,9.67],[1,2.58,27.18],[2,1.1,3000]],"ltp":2.78,"tv":1.05,"id":67083366}]}]}
{"op":"mcm","clk":"11958273786","pt":1724571677205,"mc":[{"id":"1.232245129","rc":[{"batb":[[0,2.78,4],[1,2.76,9.67],[2,2.58,27.18]],"ltp":2.78,"tv":1.05,"id":67083366}]}]}
{"op":"mcm","clk":"11958274000","pt":1724571679782,"mc":[{"id":"1.232245129","rc":[{"batb":[[0,2.76,9.67],[1,2.58,27.18],[2,1.1,3000]],"ltp":2.78,"tv":1.05,"id":67083366}]}]}
{"op":"mcm","clk":"11958274514","pt":1724571685228,"mc":[{"id":"1.232245129","rc":[{"batb":[[0,2.78,4],[1,2.76,9.67],[2,2.58,27.18]],"ltp":2.78,"tv":1.05,"id":67083366}]}]}
{"op":"mcm","clk":"11958274752","pt":1724571687810,"mc":[{"id":"1.232245129","rc":[{"batb":[[0,2.76,9.67],[1,2.58,27.18],[2,1.1,3000]],"ltp":2.78,"tv":1.05,"id":67083366}]}]}
{"op":"mcm","clk":"11958275476","pt":1724571695139,"mc":[{"id":"1.232245129","rc":[{"batb":[[0,2.78,4],[1,2.76,9.67],[2,2.58,27.18]],"ltp":2.78,"tv":1.05,"id":67083366}]}]}
{"op":"mcm","clk":"11958275736","pt":1724571697622,"mc":[{"id":"1.232245129","rc":[{"batb":[[0,2.76,9.67],[1,2.58,27.18],[2,1.1,3000]],"ltp":2.78,"tv":1.05,"id":67083366}]}]}
{"op":"mcm","clk":"11958276074","pt":1724571701221,"mc":[{"id":"1.232245129","rc":[{"batb":[[0,2.78,4],[1,2.76,9.67],[2,2.58,27.18]],"ltp":2.78,"tv":1.05,"id":67083366}]}]}
{"op":"mcm","clk":"11958276310","pt":1724571703801,"mc":[{"id":"1.232245129","rc":[{"batb":[[0,2.76,9.67],[1,2.58,27.18],[2,1.1,3000]],"ltp":2.78,"tv":1.05,"id":67083366}]}]}
{"op":"mcm","clk":"11958276522","pt":1724571706215,"mc":[{"id":"1.232245129","rc":[{"batb":[[0,2.78,4],[1,2.76,9.67],[2,2.58,27.18]],"ltp":2.78,"tv":1.05,"id":67083366}]}]}
{"op":"mcm","clk":"11958276754","pt":1724571708709,"mc":[{"id":"1.232245129","rc":[{"batb":[[0,2.76,9.67],[1,2.58,27.18],[2,1.1,3000]],"ltp":2.78,"tv":1.05,"id":67083366}]}]}
{"op":"mcm","clk":"11958276981","pt":1724571711029,"mc":[{"id":"1.232245129","rc":[{"batb":[[0,2.78,4],[1,2.76,9.67],[2,2.58,27.18]],"ltp":2.78,"tv":1.05,"id":67083366}]}]}
{"op":"mcm","clk":"11958277204","pt":1724571713245,"mc":[{"id":"1.232245129","rc":[{"batb":[[0,2.76,9.67],[1,2.58,27.18],[2,1.1,3000]],"ltp":2.78,"tv":1.05,"id":67083366}]}]}
{"op":"mcm","clk":"11958277523","pt":1724571716752,"mc":[{"id":"1.232245129","rc":[{"batb":[[0,2.78,4],[1,2.76,9.67],[2,2.58,27.18]],"ltp":2.78,"tv":1.05,"id":67083366}]}]}
{"op":"mcm","clk":"11958277737","pt":1724571719026,"mc":[{"id":"1.232245129","rc":[{"batb":[[0,2.76,9.67],[1,2.58,27.18],[2,1.1,3000]],"ltp":2.78,"tv":1.05,"id":67083366}]}]}
{"op":"mcm","clk":"11958278076","pt":1724571723262,"mc":[{"id":"1.232245129","rc":[{"batb":[[0,2.78,4],[1,2.76,9.67],[2,2.58,27.18]],"ltp":2.78,"tv":1.05,"id":67083366}]}]}
{"op":"mcm","clk":"11958278301","pt":1724571725736,"mc":[{"id":"1.232245129","rc":[{"batb":[[0,2.76,9.67],[1,2.58,27.18],[2,1.1,3000]],"ltp":2.78,"tv":1.05,"id":67083366}]}]}
{"op":"mcm","clk":"11958278486","pt":1724571728272,"mc":[{"id":"1.232245129","rc":[{"batb":[[0,2.78,4],[1,2.76,9.67],[2,2.58,27.18]],"ltp":2.78,"tv":1.05,"id":67083366}]}]}
{"op":"mcm","clk":"11958278695","pt":1724571730638,"mc":[{"id":"1.232245129","rc":[{"batb":[[0,2.76,9.67],[1,2.58,27.18],[2,1.1,3000]],"ltp":2.78,"tv":1.05,"id":67083366}]}]}
{"op":"mcm","clk":"11958279563","pt":1724571739773,"mc":[{"id":"1.232245129","rc":[{"batb":[[0,2.78,4],[1,2.76,9.67],[2,2.58,27.18]],"ltp":2.78,"tv":1.05,"id":67083366}]}]}
{"op":"mcm","clk":"11958279766","pt":1724571742260,"mc":[{"id":"1.232245129","rc":[{"batb":[[0,2.76,9.67],[1,2.58,27.18],[2,1.1,3000]],"ltp":2.78,"tv":1.05,"id":67083366}]}]}
{"op":"mcm","clk":"11958280429","pt":1724571748256,"mc":[{"id":"1.232245129","rc":[{"batb":[[0,2.78,4],[1,2.76,9.67],[2,2.58,27.18]],"ltp":2.78,"tv":1.05,"id":67083366}]}]}
{"op":"mcm","clk":"11958280692","pt":1724571750899,"mc":[{"id":"1.232245129","rc":[{"batb":[[0,2.76,9.67],[1,2.58,27.18],[2,1.1,3000]],"ltp":2.78,"tv":1.05,"id":67083366}]}]}
{"op":"mcm","clk":"11958280918","pt":1724571753105,"mc":[{"id":"1.232245129","rc":[{"batb":[[0,2.78,4],[1,2.76,9.67],[2,2.58,27.18]],"ltp":2.78,"tv":1.05,"id":67083366}]}]}
{"op":"mcm","clk":"11958281164","pt":1724571755388,"mc":[{"id":"1.232245129","rc":[{"batb":[[0,2.76,9.67],[1,2.58,27.18],[2,1.1,3000]],"ltp":2.78,"tv":1.05,"id":67083366}]}]}
{"op":"mcm","clk":"11958281559","pt":1724571759815,"mc":[{"id":"1.232245129","rc":[{"batb":[[0,2.78,4],[1,2.76,9.67],[2,2.58,27.18]],"ltp":2.78,"tv":1.05,"id":67083366}]}]}
{"op":"mcm","clk":"11958281796","pt":1724571761987,"mc":[{"id":"1.232245129","rc":[{"batb":[[0,2.76,9.67],[1,2.58,27.18],[2,1.1,3000]],"ltp":2.78,"tv":1.05,"id":67083366}]}]}
{"op":"mcm","clk":"11958282138","pt":1724571765227,"mc":[{"id":"1.232245129","rc":[{"batb":[[0,2.78,4],[1,2.76,9.67],[2,2.58,27.18]],"ltp":2.78,"tv":1.05,"id":67083366}]}]}
{"op":"mcm","clk":"11958282311","pt":1724571767602,"mc":[{"id":"1.232245129","rc":[{"batb":[[0,2.76,9.67],[1,2.58,27.18],[2,1.1,3000]],"ltp":2.78,"tv":1.05,"id":67083366}]}]}
{"op":"mcm","clk":"11958282954","pt":1724571774021,"mc":[{"id":"1.232245129","rc":[{"batb":[[0,2.78,4],[1,2.76,9.67],[2,2.58,27.18]],"ltp":2.78,"tv":1.05,"id":67083366}]}]}
{"op":"mcm","clk":"11958283186","pt":1724571776515,"mc":[{"id":"1.232245129","rc":[{"batb":[[0,2.76,9.67],[1,2.58,27.18],[2,1.1,3000]],"ltp":2.78,"tv":1.05,"id":67083366}]}]}
{"op":"mcm","clk":"11958284431","pt":1724571789623,"mc":[{"id":"1.232245129","rc":[{"batb":[[0,2.78,4],[1,2.76,9.67],[2,2.58,27.18]],"ltp":2.78,"tv":1.05,"id":67083366}]}]}
{"op":"mcm","clk":"11958284664","pt":1724571792141,"mc":[{"id":"1.232245129","rc":[{"batb":[[0,2.76,9.67],[1,2.58,27.18],[2,1.1,3000]],"ltp":2.78,"tv":1.05,"id":67083366}]}]}
{"op":"mcm","clk":"11958285323","pt":1724571799096,"mc":[{"id":"1.232245129","rc":[{"batb":[[0,2.78,4],[1,2.76,9.67],[2,2.58,27.18]],"ltp":2.78,"tv":1.05,"id":67083366},{"batb":[[0,1.55,5.63],[1,1.54,79.53],[2,1.32,126.2]],"ltp":1.56,"tv":180.88,"id":72922097}]}]}
{"op":"mcm","clk":"11958285527","pt":1724571801361,"mc":[{"id":"1.232245129","rc":[{"batb":[[0,2.76,9.67],[1,2.58,27.18],[2,1.1,3000]],"ltp":2.78,"tv":1.05,"id":67083366}]}]}
{"op":"mcm","clk":"11958285620","pt":1724571802593,"mc":[{"id":"1.232245129","rc":[{"batb":[[1,1.1,3000],[2,1.03,200]],"ltp":2.78,"tv":1.05,"id":67083366},{"batb":[[1,1.32,126.2],[2,1.1,3000]],"ltp":1.56,"tv":180.88,"id":72922097}]}]}
{"op":"mcm","clk":"11958285710","pt":1724571803676,"mc":[{"id":"1.232245129","rc":[{"batb":[[0,2.78,4],[1,2.76,9.67],[2,1.1,3000]],"ltp":2.78,"tv":1.05,"id":67083366},{"batb":[[0,1.32,126.2],[1,1.1,3000],[2,1.03,200]],"ltp":1.56,"tv":180.88,"id":72922097}]}]}
{"op":"mcm","clk":"11958285906","pt":1724571806054,"mc":[{"id":"1.232245129","rc":[{"batb":[[0,2.76,9.67],[1,1.1,3000],[2,1.03,200]],"ltp":2.78,"tv":1.05,"id":67083366}]}]}
{"op":"mcm","clk":"11958286017","pt":1724571807502,"mc":[{"id":"1.232245129","rc":[{"batb":[[1,2.58,27.18],[2,1.1,3000]],"ltp":2.78,"tv":1.05,"id":67083366},{"batb":[[0,1.54,79.53],[1,1.32,126.2],[2,1.1,3000]],"ltp":1.56,"tv":180.88,"id":72922097}]}]}
{"op":"mcm","clk":"11958286134","pt":1724571808949,"mc":[{"id":"1.232245129","rc":[{"batb":[[0,2.78,4],[1,2.76,9.67],[2,2.58,27.18]],"ltp":2.78,"tv":1.05,"id":67083366}]}]}
{"op":"mcm","clk":"11958286333","pt":1724571811578,"mc":[{"id":"1.232245129","rc":[{"batb":[[0,2.76,9.67],[1,2.58,27.18],[2,1.1,3000]],"ltp":2.78,"tv":1.05,"id":67083366}]}]}
{"op":"mcm","clk":"11958286861","pt":1724571817590,"mc":[{"id":"1.232245129","rc":[{"batb":[[0,2.78,4],[1,2.76,9.67],[2,2.58,27.18]],"ltp":2.78,"tv":1.05,"id":67083366}]}]}
{"op":"mcm","clk":"11958287050","pt":1724571820053,"mc":[{"id":"1.232245129","rc":[{"batb":[[0,2.76,9.67],[1,2.58,27.18],[2,1.1,3000]],"ltp":2.78,"tv":1.05,"id":67083366}]}]}
{"op":"mcm","clk":"11958287436","pt":1724571824485,"mc":[{"id":"1.232245129","rc":[{"batb":[[0,2.78,4],[1,2.76,9.67],[2,2.58,27.18]],"ltp":2.78,"tv":1.05,"id":67083366}]}]}
{"op":"mcm","clk":"11958287629","pt":1724571826996,"mc":[{"id":"1.232245129","rc":[{"batb":[[0,2.76,9.67],[1,2.58,27.18],[2,1.1,3000]],"ltp":2.78,"tv":1.05,"id":67083366}]}]}
{"op":"mcm","clk":"11958287910","pt":1724571830392,"mc":[{"id":"1.232245129","rc":[{"batb":[[0,2.78,4],[1,2.76,9.67],[2,2.58,27.18]],"ltp":2.78,"tv":1.05,"id":67083366}]}]}
{"op":"mcm","clk":"11958288098","pt":1724571832797,"mc":[{"id":"1.232245129","rc":[{"batb":[[0,2.76,9.67],[1,2.58,27.18],[2,1.1,3000]],"ltp":2.78,"tv":1.05,"id":67083366}]}]}
{"op":"mcm","clk":"11958288499","pt":1724571837717,"mc":[{"id":"1.232245129","rc":[{"batb":[[0,2.78,4],[1,2.76,9.67],[2,2.58,27.18]],"ltp":2.78,"tv":1.05,"id":67083366}]}]}
{"op":"mcm","clk":"11958288679","pt":1724571840287,"mc":[{"id":"1.232245129","rc":[{"batb":[[0,2.76,9.67],[1,2.58,27.18],[2,1.1,3000]],"ltp":2.78,"tv":1.05,"id":67083366}]}]}
{"op":"mcm","clk":"11958288861","pt":1724571842598,"mc":[{"id":"1.232245129","rc":[{"batb":[[0,2.78,4],[1,2.76,9.67],[2,2.58,27.18]],"ltp":2.78,"tv":1.05,"id":67083366}]}]}
{"op":"mcm","clk":"11958289053","pt":1724571844917,"mc":[{"id":"1.232245129","rc":[{"batb":[[0,2.76,9.67],[1,2.58,27.18],[2,1.1,3000]],"ltp":2.78,"tv":1.05,"id":67083366}]}]}
{"op":"mcm","clk":"11958289591","pt":1724571851698,"mc":[{"id":"1.232245129","rc":[{"batb":[[0,2.78,4],[1,2.76,9.67],[2,2.58,27.18]],"ltp":2.78,"tv":1.05,"id":67083366}]}]}
{"op":"mcm","clk":"11958289790","pt":1724571854216,"mc":[{"id":"1.232245129","rc":[{"batb":[[0,2.76,9.67],[1,2.58,27.18],[2,1.1,3000]],"ltp":2.78,"tv":1.05,"id":67083366}]}]}
{"op":"mcm","clk":"11958290215","pt":1724571860101,"mc":[{"id":"1.232245129","rc":[{"batb":[[0,2.78,4],[1,2.76,9.67],[2,2.58,27.18]],"ltp":2.78,"tv":1.05,"id":67083366}]}]}
{"op":"mcm","clk":"11958290414","pt":1724571862518,"mc":[{"id":"1.232245129","rc":[{"batb":[[0,2.76,9.67],[1,2.58,27.18],[2,1.1,3000]],"ltp":2.78,"tv":1.05,"id":67083366}]}]}
{"op":"mcm","clk":"11958290614","pt":1724571865132,"mc":[{"id":"1.232245129","rc":[{"batb":[[0,2.78,4],[1,2.76,9.67],[2,2.58,27.18]],"ltp":2.78,"tv":1.05,"id":67083366}]}]}
{"op":"mcm","clk":"11958290815","pt":1724571867405,"mc":[{"id":"1.232245129","rc":[{"batb":[[0,2.76,9.67],[1,2.58,27.18],[2,1.1,3000]],"ltp":2.78,"tv":1.05,"id":67083366}]}]}
{"op":"mcm","clk":"11958291538","pt":1724571876034,"mc":[{"id":"1.232245129","rc":[{"batb":[[0,2.78,4],[1,2.76,9.67],[2,2.58,27.18]],"ltp":2.78,"tv":1.05,"id":67083366}]}]}
{"op":"mcm","clk":"11958291733","pt":1724571878441,"mc":[{"id":"1.232245129","rc":[{"batb":[[0,2.76,9.67],[1,2.58,27.18],[2,1.1,3000]],"ltp":2.78,"tv":1.05,"id":67083366}]}]}
{"op":"mcm","clk":"11958292329","pt":1724571884577,"mc":[{"id":"1.232245129","rc":[{"batb":[[0,2.78,4],[1,2.76,9.67],[2,2.58,27.18]],"ltp":2.78,"tv":1.05,"id":67083366}]}]}
{"op":"mcm","clk":"11958292567","pt":1724571886839,"mc":[{"id":"1.232245129","rc":[{"batb":[[0,2.76,9.67],[1,2.58,27.18],[2,1.1,3000]],"ltp":2.78,"tv":1.05,"id":67083366}]}]}
{"op":"mcm","clk":"11958300730","pt":1724571976773,"mc":[{"id":"1.232245129","rc":[{"batb":[[0,2.78,4],[1,2.76,9.67],[2,2.58,27.18]],"ltp":2.78,"tv":1.05,"id":67083366},{"batb":[[0,1.55,5.63],[1,1.54,79.53],[2,1.32,126.2]],"ltp":1.56,"tv":180.88,"id":72922097}]}]}
{"op":"mcm","clk":"11958300844","pt":1724571977958,"mc":[{"id":"1.232245129","rc":[{"batb":[[2,1.1,3000]],"ltp":2.78,"tv":1.05,"id":67083366},{"batb":[[1,1.32,126.2],[2,1.1,3000]],"ltp":1.56,"tv":180.88,"id":72922097}]}]}
{"op":"mcm","clk":"11958300934","pt":1724571978984,"mc":[{"id":"1.232245129","rc":[{"batb":[[0,2.76,9.67],[1,1.1,3000],[2,1.03,200]],"ltp":2.78,"tv":1.05,"id":67083366}]}]}
{"op":"mcm","clk":"11958301194","pt":1724571981763,"mc":[{"id":"1.232245129","rc":[{"batb":[[0,2.78,4],[1,2.76,9.67],[2,1.1,3000]],"ltp":2.78,"tv":1.05,"id":67083366},{"batb":[[0,1.32,126.2],[1,1.1,3000],[2,1.03,200]],"ltp":1.56,"tv":180.88,"id":72922097}]}]}
{"op":"mcm","clk":"11958301301","pt":1724571982998,"mc":[{"id":"1.232245129","rc":[{"batb":[[2,2.58,27.18]],"ltp":2.78,"tv":1.05,"id":67083366},{"batb":[[0,1.54,79.53],[1,1.32,126.2],[2,1.1,3000]],"ltp":1.56,"tv":180.88,"id":72922097}]}]}
{"op":"mcm","clk":"11958301391","pt":1724571983975,"mc":[{"id":"1.232245129","rc":[{"batb":[[0,2.76,9.67],[1,2.58,27.18],[2,1.1,3000]],"ltp":2.78,"tv":1.05,"id":67083366}]}]}
{"op":"mcm","clk":"11958306267","pt":1724572041624,"mc":[{"id":"1.232245129","rc":[{"batb":[[0,2.78,4],[1,2.76,9.67],[2,2.58,27.18]],"ltp":2.78,"tv":1.05,"id":67083366}]}]}
{"op":"mcm","clk":"11958306502","pt":1724572044032,"mc":[{"id":"1.232245129","rc":[{"batb":[[0,2.76,9.67],[1,2.58,27.18],[2,1.1,3000]],"ltp":2.78,"tv":1.05,"id":67083366}]}]}
{"op":"mcm","clk":"11958321618","pt":1724572217865,"mc":[{"id":"1.232245129","rc":[{"batb":[[0,2.78,4],[1,2.76,9.67],[2,2.58,27.18]],"ltp":2.78,"tv":1.05,"id":67083366},{"batb":[[0,1.55,5.63],[1,1.54,79.53],[2,1.32,126.2]],"ltp":1.56,"tv":180.88,"id":72922097}]}]}
{"op":"mcm","clk":"11958321671","pt":1724572218633,"mc":[{"id":"1.232245129","rc":[{"batb":[[2,1.1,3000]],"ltp":2.78,"tv":1.05,"id":67083366},{"batb":[[1,1.32,126.2],[2,1.1,3000]],"ltp":1.56,"tv":180.88,"id":72922097}]}]}
{"op":"mcm","clk":"11958321973","pt":1724572222673,"mc":[{"id":"1.232245129","rc":[{"batb":[[0,2.76,9.67],[1,1.1,3000],[2,1.03,200]],"ltp":2.78,"tv":1.05,"id":67083366}]}]}
{"op":"mcm","clk":"11958322053","pt":1724572223655,"mc":[{"id":"1.232245129","rc":[{"batb":[[1,2.58,27.18],[2,1.1,3000]],"ltp":2.78,"tv":1.05,"id":67083366},{"batb":[[0,1.54,79.53]],"ltp":1.56,"tv":180.88,"id":72922097}]}]}
{"op":"mcm","clk":"11958336529","pt":1724572402472,"mc":[{"id":"1.232245129","rc":[{"batb":[[0,2.78,4],[1,2.76,9.67],[2,2.58,27.18]],"ltp":2.78,"tv":1.05,"id":67083366},{"batb":[[0,1.55,5.63],[1,1.54,79.53],[2,1.32,126.2]],"ltp":1.56,"tv":180.88,"id":72922097}]}]}
{"op":"mcm","clk":"11958336718","pt":1724572404242,"mc":[{"id":"1.232245129","rc":[{"batb":[[2,1.1,3000]],"ltp":2.78,"tv":1.05,"id":67083366},{"batb":[[1,1.32,126.2],[2,1.1,3000]],"ltp":1.56,"tv":180.88,"id":72922097}]}]}
{"op":"mcm","clk":"11958336756","pt":1724572404654,"mc":[{"id":"1.232245129","rc":[{"batb":[[0,2.76,9.67],[1,1.1,3000],[2,1.03,200]],"ltp":2.78,"tv":1.05,"id":67083366}]}]}
{"op":"mcm","clk":"11958336956","pt":1724572406356,"mc":[{"id":"1.232245129","rc":[{"batb":[[0,1.32,126.2],[1,1.1,3000],[2,1.03,200]],"ltp":1.56,"tv":180.88,"id":72922097}]}]}
{"op":"mcm","clk":"11958337238","pt":1724572409282,"mc":[{"id":"1.232245129","rc":[{"batb":[[1,2.58,27.18],[2,1.1,3000]],"ltp":2.78,"tv":1.05,"id":67083366},{"batb":[[0,1.54,79.53],[1,1.32,126.2],[2,1.1,3000]],"ltp":1.56,"tv":180.88,"id":72922097}]}]}
{"op":"mcm","clk":"11958337252","pt":1724572409384,"mc":[{"id":"1.232245129","rc":[{"batb":[[0,2.78,4],[1,2.76,9.67],[2,2.58,27.18]],"ltp":2.78,"tv":1.05,"id":67083366}]}]}
{"op":"mcm","clk":"11958337474","pt":1724572411589,"mc":[{"id":"1.232245129","rc":[{"batb":[[0,2.76,9.67],[1,2.58,27.18],[2,1.1,3000]],"ltp":2.78,"tv":1.05,"id":67083366}]}]}
{"op":"mcm","clk":"11958346373","pt":1724572520208,"mc":[{"id":"1.232245129","rc":[{"batb":[[0,2.78,4],[1,2.76,9.67],[2,2.58,27.18]],"ltp":2.78,"tv":1.05,"id":67083366}]}]}
{"op":"mcm","clk":"11958346551","pt":1724572522516,"mc":[{"id":"1.232245129","rc":[{"batb":[[0,2.76,9.67],[1,2.58,27.18],[2,1.1,3000]],"ltp":2.78,"tv":1.05,"id":67083366}]}]}
{"op":"mcm","clk":"11958350568","pt":1724572573037,"mc":[{"id":"1.232245129","rc":[{"batb":[[0,2.78,4],[1,2.76,9.67],[2,2.58,27.18]],"ltp":2.78,"tv":1.05,"id":67083366}]}]}
{"op":"mcm","clk":"11958350739","pt":1724572575437,"mc":[{"id":"1.232245129","rc":[{"batb":[[0,2.76,9.67],[1,2.58,27.18],[2,1.1,3000]],"ltp":2.78,"tv":1.05,"id":67083366}]}]}
{"op":"mcm","clk":"11958350858","pt":1724572577180,"mc":[{"id":"1.232245129","rc":[{"batb":[[0,1.55,5.63],[1,1.54,79.53],[2,1.32,126.2]],"ltp":1.56,"tv":180.88,"id":72922097}]}]}
{"op":"mcm","clk":"11958351030","pt":1724572579952,"mc":[{"id":"1.232245129","rc":[{"batb":[[0,2.78,4],[1,2.76,9.67]],"ltp":2.78,"tv":1.05,"id":67083366},{"batb":[[1,1.32,126.2],[2,1.1,3000]],"ltp":1.56,"tv":180.88,"id":72922097}]}]}
{"op":"mcm","clk":"11958351167","pt":1724572582154,"mc":[{"id":"1.232245129","rc":[{"batb":[[0,2.76,9.67],[1,1.1,3000],[2,1.03,200]],"ltp":2.78,"tv":1.05,"id":67083366}]}]}
{"op":"mcm","clk":"11958351194","pt":1724572582665,"mc":[{"id":"1.232245129","rc":[{"batb":[[0,1.32,126.2],[1,1.1,3000],[2,1.03,200]],"ltp":1.56,"tv":180.88,"id":72922097}]}]}
{"op":"mcm","clk":"11958351344","pt":1724572584866,"mc":[{"id":"1.232245129","rc":[{"batb":[[0,2.78,4],[1,2.76,9.67],[2,2.58,27.18]],"ltp":2.78,"tv":1.05,"id":67083366},{"batb":[[0,1.54,79.53],[1,1.32,126.2],[2,1.1,3000]],"ltp":1.56,"tv":180.88,"id":72922097}]}]}
{"op":"mcm","clk":"11958351508","pt":1724572587292,"mc":[{"id":"1.232245129","rc":[{"batb":[[0,2.76,9.67],[1,2.58,27.18],[2,1.1,3000]],"ltp":2.78,"tv":1.05,"id":67083366}]}]}
{"op":"mcm","clk":"11958357089","pt":1724572660689,"mc":[{"id":"1.232245129","rc":[{"batb":[[0,2.78,4],[1,2.76,9.67],[2,2.58,27.18]],"ltp":2.78,"tv":1.05,"id":67083366},{"batb":[[1,1.33,138.46],[2,1.32,126.2]],"ltp":1.56,"tv":180.88,"id":72922097}]}]}
{"op":"mcm","clk":"11958357310","pt":1724572662880,"mc":[{"id":"1.232245129","rc":[{"batb":[[0,2.76,9.67],[1,2.58,27.18],[2,1.1,3000]],"ltp":2.78,"tv":1.05,"id":67083366}]}]}
{"op":"mcm","clk":"11958357731","pt":1724572668065,"mc":[{"id":"1.232245129","rc":[{"batb":[[0,2.78,4],[1,2.76,9.67],[2,2.58,27.18]],"ltp":2.78,"tv":1.05,"id":67083366}]}]}
{"op":"mcm","clk":"11958357886","pt":1724572670475,"mc":[{"id":"1.232245129","rc":[{"batb":[[0,2.76,9.67],[1,2.58,27.18],[2,1.1,3000]],"ltp":2.78,"tv":1.05,"id":67083366}]}]}
{"op":"mcm","clk":"11958358680","pt":1724572680899,"mc":[{"id":"1.232245129","rc":[{"batb":[[0,2.78,4],[1,2.76,9.67],[2,2.58,27.18]],"ltp":2.78,"tv":1.05,"id":67083366}]}]}
{"op":"mcm","clk":"11958358914","pt":1724572683428,"mc":[{"id":"1.232245129","rc":[{"batb":[[0,2.76,9.67],[1,2.58,27.18],[2,1.1,3000]],"ltp":2.78,"tv":1.05,"id":67083366}]}]}
{"op":"mcm","clk":"11958359638","pt":1724572692032,"mc":[{"id":"1.232245129","rc":[{"batb":[[0,2.78,4],[1,2.76,9.67],[2,2.58,27.18]],"ltp":2.78,"tv":1.05,"id":67083366}]}]}
{"op":"mcm","clk":"11958359904","pt":1724572694516,"mc":[{"id":"1.232245129","rc":[{"batb":[[0,2.76,9.67],[1,2.58,27.18],[2,1.1,3000]],"ltp":2.78,"tv":1.05,"id":67083366}]}]}
{"op":"mcm","clk":"11958361177","pt":1724572710333,"mc":[{"id":"1.232245129","rc":[{"batb":[[0,2.78,4],[1,2.76,9.67],[2,2.58,27.18]],"ltp":2.78,"tv":1.05,"id":67083366}]}]}
{"op":"mcm","clk":"11958361369","pt":1724572712762,"mc":[{"id":"1.232245129","rc":[{"batb":[[0,2.76,9.67],[1,2.58,27.18],[2,1.1,3000]],"ltp":2.78,"tv":1.05,"id":67083366}]}]}
{"op":"mcm","clk":"11958363723","pt":1724572740787,"mc":[{"id":"1.232245129","rc":[{"batb":[[0,2.78,4],[1,2.76,9.67],[2,2.58,27.18]],"ltp":2.78,"tv":1.05,"id":67083366}]}]}
{"op":"mcm","clk":"11958363931","pt":1724572743089,"mc":[{"id":"1.232245129","rc":[{"batb":[[0,2.76,9.67],[1,2.58,27.18],[2,1.1,3000]],"ltp":2.78,"tv":1.05,"id":67083366}]}]}
{"op":"mcm","clk":"11958364805","pt":1724572751868,"mc":[{"id":"1.232245129","rc":[{"batb":[[0,2.78,4],[1,2.76,9.67],[2,2.58,27.18]],"ltp":2.78,"tv":1.05,"id":67083366}]}]}
{"op":"mcm","clk":"11958365010","pt":1724572754088,"mc":[{"id":"1.232245129","rc":[{"batb":[[0,2.76,9.67],[1,2.58,27.18],[2,1.1,3000]],"ltp":2.78,"tv":1.05,"id":67083366}]}]}
{"op":"mcm","clk":"11958365394","pt":1724572758100,"mc":[{"id":"1.232245129","rc":[{"batb":[[0,2.78,4],[1,2.76,9.67],[2,2.58,27.18]],"ltp":2.78,"tv":1.05,"id":67083366},{"batb":[[0,1.55,5.63],[1,1.54,79.53],[2,1.33,138.46]],"ltp":1.56,"tv":180.88,"id":72922097}]}]}
{"op":"mcm","clk":"11958365628","pt":1724572760308,"mc":[{"id":"1.232245129","rc":[{"batb":[[0,2.76,9.67],[1,1.1,3000],[2,1.03,200]],"ltp":2.78,"tv":1.05,"id":67083366},{"batb":[[1,1.33,138.46],[2,1.32,126.2]],"ltp":1.56,"tv":180.88,"id":72922097}]}]}
{"op":"mcm","clk":"11958365932","pt":1724572763694,"mc":[{"id":"1.232245129","rc":[{"batb":[[0,2.78,4],[1,2.76,9.67],[2,1.1,3000]],"ltp":2.78,"tv":1.05,"id":67083366},{"batb":[[0,1.33,138.46],[1,1.32,126.2],[2,1.23,138.46]],"ltp":1.56,"tv":180.88,"id":72922097}]}]}
{"op":"mcm","clk":"11958366084","pt":1724572765199,"mc":[{"id":"1.232245129","rc":[{"batb":[[2,2.58,27.18]],"ltp":2.78,"tv":1.05,"id":67083366},{"batb":[[0,1.54,79.53],[1,1.33,138.46],[2,1.32,126.2]],"ltp":1.56,"tv":180.88,"id":72922097}]}]}
{"op":"mcm","clk":"11958366171","pt":1724572766070,"mc":[{"id":"1.232245129","rc":[{"batb":[[0,2.76,9.67],[1,2.58,27.18],[2,1.1,3000]],"ltp":2.78,"tv":1.05,"id":67083366}]}]}
{"op":"mcm","clk":"11958366935","pt":1724572774096,"mc":[{"id":"1.232245129","rc":[{"batb":[[0,2.78,4],[1,2.76,9.67],[2,2.58,27.18]],"ltp":2.78,"tv":1.05,"id":67083366}]}]}
{"op":"mcm","clk":"11958367165","pt":1724572776420,"mc":[{"id":"1.232245129","rc":[{"batb":[[0,2.76,9.67],[1,2.58,27.18],[2,1.1,3000]],"ltp":2.78,"tv":1.05,"id":67083366}]}]}
{"op":"mcm","clk":"11958367630","pt":1724572781521,"mc":[{"id":"1.232245129","rc":[{"batb":[[0,2.78,4],[1,2.76,9.67],[2,2.58,27.18]],"ltp":2.78,"tv":1.05,"id":67083366}]}]}
{"op":"mcm","clk":"11958367853","pt":1724572783938,"mc":[{"id":"1.232245129","rc":[{"batb":[[0,2.76,9.67],[1,2.58,27.18],[2,1.1,3000]],"ltp":2.78,"tv":1.05,"id":67083366}]}]}
{"op":"mcm","clk":"11958369327","pt":1724572801438,"mc":[{"id":"1.232245129","rc":[{"batb":[[0,2.78,4],[1,2.76,9.67],[2,2.58,27.18]],"ltp":2.78,"tv":1.05,"id":67083366}]}]}
{"op":"mcm","clk":"11958369717","pt":1724572804056,"mc":[{"id":"1.232245129","rc":[{"batb":[[0,2.76,9.67],[1,2.58,27.18],[2,1.1,3000]],"ltp":2.78,"tv":1.05,"id":67083366}]}]}
{"op":"mcm","clk":"11958374388","pt":1724572851906,"mc":[{"id":"1.232245129","rc":[{"batb":[[0,2.78,4],[1,2.76,9.67],[2,2.58,27.18]],"ltp":2.78,"tv":1.05,"id":67083366}]}]}
{"op":"mcm","clk":"11958374612","pt":1724572854124,"mc":[{"id":"1.232245129","rc":[{"batb":[[0,2.76,9.67],[1,2.58,27.18],[2,1.1,3000]],"ltp":2.78,"tv":1.05,"id":67083366}]}]}
{"op":"mcm","clk":"11958374960","pt":1724572858235,"mc":[{"id":"1.232245129","rc":[{"batb":[[0,2.78,4],[1,2.76,9.67],[2,2.58,27.18]],"ltp":2.78,"tv":1.05,"id":67083366}]}]}
{"op":"mcm","clk":"11958375145","pt":1724572860544,"mc":[{"id":"1.232245129","rc":[{"batb":[[0,2.76,9.67],[1,2.58,27.18],[2,1.1,3000]],"ltp":2.78,"tv":1.05,"id":67083366}]}]}
{"op":"mcm","clk":"11958375390","pt":1724572863333,"mc":[{"id":"1.232245129","rc":[{"batb":[[0,2.78,4],[1,2.76,9.67],[2,2.58,27.18]],"ltp":2.78,"tv":1.05,"id":67083366}]}]}
{"op":"mcm","clk":"11958375587","pt":1724572865499,"mc":[{"id":"1.232245129","rc":[{"batb":[[0,2.76,9.67],[1,2.58,27.18],[2,1.1,3000]],"ltp":2.78,"tv":1.05,"id":67083366}]}]}
{"op":"mcm","clk":"11958376038","pt":1724572872029,"mc":[{"id":"1.232245129","rc":[{"batb":[[0,2.78,4],[1,2.76,9.67],[2,2.58,27.18]],"ltp":2.78,"tv":1.05,"id":67083366}]}]}
{"op":"mcm","clk":"11958376217","pt":1724572874244,"mc":[{"id":"1.232245129","rc":[{"batb":[[0,2.76,9.67],[1,2.58,27.18],[2,1.1,3000]],"ltp":2.78,"tv":1.05,"id":67083366}]}]}
{"op":"mcm","clk":"11958376737","pt":1724572879855,"mc":[{"id":"1.232245129","rc":[{"batb":[[0,2.78,4],[1,2.76,9.67],[2,2.58,27.18]],"ltp":2.78,"tv":1.05,"id":67083366},{"batb":[[0,1.55,5.63],[1,1.54,79.53],[2,1.33,138.46]],"ltp":1.56,"tv":180.88,"id":72922097}]}]}
{"op":"mcm","clk":"11958376822","pt":1724572880733,"mc":[{"id":"1.232245129","rc":[{"batb":[[2,1.1,3000]],"ltp":2.78,"tv":1.05,"id":67083366},{"batb":[[1,1.33,138.46],[2,1.32,126.2]],"ltp":1.56,"tv":180.88,"id":72922097}]}]}
{"op":"mcm","clk":"11958376960","pt":1724572882021,"mc":[{"id":"1.232245129","rc":[{"batb":[[0,2.76,9.67],[1,1.1,3000],[2,1.03,200]],"ltp":2.78,"tv":1.05,"id":67083366}]}]}
{"op":"mcm","clk":"11958377110","pt":1724572883463,"mc":[{"id":"1.232245129","rc":[{"batb":[[0,1.33,138.46],[1,1.32,126.2],[2,1.23,138.46]],"ltp":1.56,"tv":180.88,"id":72922097}]}]}
{"op":"mcm","clk":"11958377399","pt":1724572886250,"mc":[{"id":"1.232245129","rc":[{"batb":[[1,2.58,27.18],[2,1.1,3000]],"ltp":2.78,"tv":1.05,"id":67083366},{"batb":[[0,1.54,79.53],[1,1.33,138.46],[2,1.32,126.2]],"ltp":1.56,"tv":180.88,"id":72922097}]}]}
{"op":"mcm","clk":"11958377406","pt":1724572886354,"mc":[{"id":"1.232245129","rc":[{"batb":[[0,2.78,4],[1,2.76,9.67],[2,2.58,27.18]],"ltp":2.78,"tv":1.05,"id":67083366}]}]}
{"op":"mcm","clk":"11958377640","pt":1724572888577,"mc":[{"id":"1.232245129","rc":[{"batb":[[0,2.76,9.67],[1,2.58,27.18],[2,1.1,3000]],"ltp":2.78,"tv":1.05,"id":67083366}]}]}
{"op":"mcm","clk":"11958378040","pt":1724572892252,"mc":[{"id":"1.232245129","rc":[{"batb":[[0,2.78,4],[1,2.76,9.67],[2,2.58,27.18]],"ltp":2.78,"tv":1.05,"id":67083366}]}]}
{"op":"mcm","clk":"11958378260","pt":1724572894778,"mc":[{"id":"1.232245129","rc":[{"batb":[[0,2.76,9.67],[1,2.58,27.18],[2,1.1,3000]],"ltp":2.78,"tv":1.05,"id":67083366}]}]}
{"op":"mcm","clk":"11958378786","pt":1724572900595,"mc":[{"id":"1.232245129","rc":[{"batb":[[0,2.78,4],[1,2.76,9.67],[2,2.58,27.18]],"ltp":2.78,"tv":1.05,"id":67083366}]}]}
{"op":"mcm","clk":"11958379015","pt":1724572902976,"mc":[{"id":"1.232245129","rc":[{"batb":[[0,2.76,9.67],[1,2.58,27.18],[2,1.1,3000]],"ltp":2.78,"tv":1.05,"id":67083366}]}]}
{"op":"mcm","clk":"11958379832","pt":1724572911881,"mc":[{"id":"1.232245129","rc":[{"batb":[[0,2.78,4],[1,2.76,9.67],[2,2.58,27.18]],"ltp":2.78,"tv":1.05,"id":67083366}]}]}
{"op":"mcm","clk":"11958380019","pt":1724572914398,"mc":[{"id":"1.232245129","rc":[{"batb":[[0,2.76,9.67],[1,2.58,27.18],[2,1.1,3000]],"ltp":2.78,"tv":1.05,"id":67083366}]}]}
{"op":"mcm","clk":"11958381525","pt":1724572931716,"mc":[{"id":"1.232245129","rc":[{"batb":[[0,2.78,4],[1,2.76,9.67],[2,2.58,27.18]],"ltp":2.78,"tv":1.05,"id":67083366}]}]}
{"op":"mcm","clk":"11958381731","pt":1724572934135,"mc":[{"id":"1.232245129","rc":[{"batb":[[0,2.76,9.67],[1,2.58,27.18],[2,1.1,3000]],"ltp":2.78,"tv":1.05,"id":67083366}]}]}
{"op":"mcm","clk":"11958383495","pt":1724572955432,"mc":[{"id":"1.232245129","rc":[{"batb":[[0,2.78,4],[1,2.76,9.67],[2,2.58,27.18]],"ltp":2.78,"tv":1.05,"id":67083366}]}]}
{"op":"mcm","clk":"11958383693","pt":1724572957945,"mc":[{"id":"1.232245129","rc":[{"batb":[[0,2.76,9.67],[1,2.58,27.18],[2,1.1,3000]],"ltp":2.78,"tv":1.05,"id":67083366}]}]}
{"op":"mcm","clk":"11958384140","pt":1724572964039,"mc":[{"id":"1.232245129","rc":[{"batb":[[0,2.78,4],[1,2.76,9.67],[2,2.58,27.18]],"ltp":2.78,"tv":1.05,"id":67083366}]}]}
{"op":"mcm","clk":"11958384395","pt":1724572966254,"mc":[{"id":"1.232245129","rc":[{"batb":[[0,2.76,9.67],[1,2.58,27.18],[2,1.1,3000]],"ltp":2.78,"tv":1.05,"id":67083366}]}]}
{"op":"mcm","clk":"11958392885","pt":1724573057291,"mc":[{"id":"1.232245129","rc":[{"batb":[[0,1.55,5.63],[1,1.54,79.53],[2,1.33,138.46]],"ltp":1.56,"tv":180.88,"id":72922097}]}]}
{"op":"mcm","clk":"11958392901","pt":1724573057396,"mc":[{"id":"1.232245129","rc":[{"batb":[[0,2.78,4],[1,2.76,9.67],[2,2.58,27.18]],"ltp":2.78,"tv":1.05,"id":67083366}]}]}
{"op":"mcm","clk":"11958393137","pt":1724573059611,"mc":[{"id":"1.232245129","rc":[{"batb":[[0,2.76,9.67],[1,2.58,27.18],[2,1.1,3000]],"ltp":2.78,"tv":1.05,"id":67083366}]}]}
{"op":"mcm","clk":"11958393376","pt":1724573061785,"mc":[{"id":"1.232245129","rc":[{"batb":[[0,2.78,4],[1,2.76,9.67]],"ltp":2.78,"tv":1.05,"id":67083366},{"batb":[[1,1.33,138.46],[2,1.32,126.2]],"ltp":1.56,"tv":180.88,"id":72922097}]}]}
{"op":"mcm","clk":"11958393567","pt":1724573064001,"mc":[{"id":"1.232245129","rc":[{"batb":[[0,2.76,9.67],[1,1.1,3000],[2,1.03,200]],"ltp":2.78,"tv":1.05,"id":67083366}]}]}
{"op":"mcm","clk":"11958393661","pt":1724573064983,"mc":[{"id":"1.232245129","rc":[{"batb":[[0,1.33,138.46],[1,1.32,126.2],[2,1.23,138.46]],"ltp":1.56,"tv":180.88,"id":72922097}]}]}
{"op":"mcm","clk":"11958393830","pt":1724573066799,"mc":[{"id":"1.232245129","rc":[{"batb":[[0,2.78,4],[1,2.76,9.67],[2,2.58,27.18]],"ltp":2.78,"tv":1.05,"id":67083366},{"batb":[[0,1.54,79.53],[1,1.33,138.46],[2,1.32,126.2]],"ltp":1.56,"tv":180.88,"id":72922097}]}]}
{"op":"mcm","clk":"11958394023","pt":1724573069013,"mc":[{"id":"1.232245129","rc":[{"batb":[[0,2.76,9.67],[1,2.58,27.18],[2,1.1,3000]],"ltp":2.78,"tv":1.05,"id":67083366}]}]}
{"op":"mcm","clk":"11958396335","pt":1724573095149,"mc":[{"id":"1.232245129","rc":[{"batb":[[0,2.78,4],[1,2.76,9.67],[2,2.58,27.18]],"ltp":2.78,"tv":1.05,"id":67083366}]}]}
{"op":"mcm","clk":"11958396559","pt":1724573097624,"mc":[{"id":"1.232245129","rc":[{"batb":[[0,2.76,9.67],[1,2.58,27.18],[2,1.1,3000]],"ltp":2.78,"tv":1.05,"id":67083366}]}]}
{"op":"mcm","clk":"11958411972","pt":1724573258455,"mc":[{"id":"1.232245129","rc":[{"batb":[[0,2.78,4],[1,2.76,9.67],[2,2.58,27.18]],"ltp":2.78,"tv":1.05,"id":67083366}]}]}
{"op":"mcm","clk":"11958412169","pt":1724573260868,"mc":[{"id":"1.232245129","rc":[{"batb":[[0,2.76,9.67],[1,2.58,27.18],[2,1.1,3000]],"ltp":2.78,"tv":1.05,"id":67083366}]}]}
{"op":"mcm","clk":"11958417914","pt":1724573322638,"mc":[{"id":"1.232245129","rc":[{"batb":[[0,2.78,4],[1,2.76,9.67],[2,2.58,27.18]],"ltp":2.78,"tv":1.05,"id":67083366}]}]}
{"op":"mcm","clk":"11958418179","pt":1724573325121,"mc":[{"id":"1.232245129","rc":[{"batb":[[0,2.76,9.67],[1,2.58,27.18],[2,1.1,3000]],"ltp":2.78,"tv":1.05,"id":67083366}]}]}
{"op":"mcm","clk":"11958421075","pt":1724573356867,"mc":[{"id":"1.232245129","rc":[{"batb":[[0,2.78,4],[1,2.76,9.67],[2,2.58,27.18]],"ltp":2.78,"tv":1.05,"id":67083366},{"batb":[[0,1.55,5.63],[1,1.54,79.53],[2,1.33,138.46]],"ltp":1.56,"tv":180.88,"id":72922097}]}]}
{"op":"mcm","clk":"11958421146","pt":1724573357695,"mc":[{"id":"1.232245129","rc":[{"batb":[[2,1.1,3000]],"ltp":2.78,"tv":1.05,"id":67083366},{"batb":[[1,1.33,138.46],[2,1.32,126.2]],"ltp":1.56,"tv":180.88,"id":72922097}]}]}
{"op":"mcm","clk":"11958421278","pt":1724573359094,"mc":[{"id":"1.232245129","rc":[{"batb":[[0,2.76,9.67],[1,1.1,3000],[2,1.03,200]],"ltp":2.78,"tv":1.05,"id":67083366}]}]}
{"op":"mcm","clk":"11958421452","pt":1724573361206,"mc":[{"id":"1.232245129","rc":[{"batb":[[0,1.33,138.46],[1,1.32,126.2],[2,1.23,138.46]],"ltp":1.56,"tv":180.88,"id":72922097}]}]}
{"op":"mcm","clk":"11958421476","pt":1724573361415,"mc":[{"id":"1.232245129","rc":[{"batb":[[0,2.78,4],[1,2.76,9.67],[2,1.1,3000]],"ltp":2.78,"tv":1.05,"id":67083366}]}]}
{"op":"mcm","clk":"11958421609","pt":1724573362709,"mc":[{"id":"1.232245129","rc":[{"batb":[[2,2.58,27.18]],"ltp":2.78,"tv":1.05,"id":67083366},{"batb":[[0,1.54,79.53],[1,1.33,138.46],[2,1.32,126.2]],"ltp":1.56,"tv":180.88,"id":72922097}]}]}
{"op":"mcm","clk":"11958421717","pt":1724573363591,"mc":[{"id":"1.232245129","rc":[{"batb":[[0,2.76,9.67],[1,2.58,27.18],[2,1.1,3000]],"ltp":2.78,"tv":1.05,"id":67083366}]}]}
{"op":"mcm","clk":"11958422468","pt":1724573371704,"mc":[{"id":"1.232245129","rc":[{"batb":[[0,2.78,4],[1,2.76,9.67],[2,2.58,27.18]],"ltp":2.78,"tv":1.05,"id":67083366}]}]}
{"op":"mcm","clk":"11958422682","pt":1724573373997,"mc":[{"id":"1.232245129","rc":[{"batb":[[0,2.76,9.67],[1,2.58,27.18],[2,1.1,3000]],"ltp":2.78,"tv":1.05,"id":67083366}]}]}
{"op":"mcm","clk":"11958424301","pt":1724573390037,"mc":[{"id":"1.232245129","rc":[{"batb":[[0,2.78,4],[1,2.76,9.67],[2,2.58,27.18]],"ltp":2.78,"tv":1.05,"id":67083366}]}]}
{"op":"mcm","clk":"11958424504","pt":1724573392350,"mc":[{"id":"1.232245129","rc":[{"batb":[[0,2.76,9.67],[1,2.58,27.18],[2,1.1,3000]],"ltp":2.78,"tv":1.05,"id":67083366}]}]}
{"op":"mcm","clk":"11958425325","pt":1724573401016,"mc":[{"id":"1.232245129","rc":[{"batb":[[0,2.78,4],[1,2.76,9.67],[2,2.58,27.18]],"ltp":2.78,"tv":1.05,"id":67083366}]}]}
{"op":"mcm","clk":"11958425499","pt":1724573403244,"mc":[{"id":"1.232245129","rc":[{"batb":[[0,2.76,9.67],[1,2.58,27.18],[2,1.1,3000]],"ltp":2.78,"tv":1.05,"id":67083366}]}]}
{"op":"mcm","clk":"11958426460","pt":1724573414179,"mc":[{"id":"1.232245129","rc":[{"batb":[[0,2.78,4],[1,2.76,9.67],[2,2.58,27.18]],"ltp":2.78,"tv":1.05,"id":67083366}]}]}
{"op":"mcm","clk":"11958426691","pt":1724573416440,"mc":[{"id":"1.232245129","rc":[{"batb":[[0,2.76,9.67],[1,2.58,27.18],[2,1.1,3000]],"ltp":2.78,"tv":1.05,"id":67083366}]}]}
{"op":"mcm","clk":"11958428171","pt":1724573433008,"mc":[{"id":"1.232245129","rc":[{"batb":[[0,2.78,4],[1,2.76,9.67],[2,2.58,27.18]],"ltp":2.78,"tv":1.05,"id":67083366}]}]}
{"op":"mcm","clk":"11958428409","pt":1724573435173,"mc":[{"id":"1.232245129","rc":[{"batb":[[0,2.76,9.67],[1,2.58,27.18],[2,1.1,3000]],"ltp":2.78,"tv":1.05,"id":67083366}]}]}
{"op":"mcm","clk":"11958429921","pt":1724573452214,"mc":[{"id":"1.232245129","rc":[{"batb":[[0,2.78,4],[1,2.76,9.67],[2,2.58,27.18]],"ltp":2.78,"tv":1.05,"id":67083366}]}]}
{"op":"mcm","clk":"11958430110","pt":1724573454485,"mc":[{"id":"1.232245129","rc":[{"batb":[[0,2.76,9.67],[1,2.58,27.18],[2,1.1,3000]],"ltp":2.78,"tv":1.05,"id":67083366}]}]}
{"op":"mcm","clk":"11958430383","pt":1724573457519,"mc":[{"id":"1.232245129","rc":[{"batb":[[0,2.78,4],[1,2.76,9.67],[2,2.58,27.18]],"ltp":2.78,"tv":1.05,"id":67083366}]}]}
{"op":"mcm","clk":"11958430554","pt":1724573459826,"mc":[{"id":"1.232245129","rc":[{"batb":[[0,2.76,9.67],[1,2.58,27.18],[2,1.1,3000]],"ltp":2.78,"tv":1.05,"id":67083366}]}]}
{"op":"mcm","clk":"11958433554","pt":1724573492587,"mc":[{"id":"1.232245129","rc":[{"batb":[[0,2.78,4],[1,2.76,9.67],[2,2.58,27.18]],"ltp":2.78,"tv":1.05,"id":67083366}]}]}
{"op":"mcm","clk":"11958433745","pt":1724573494789,"mc":[{"id":"1.232245129","rc":[{"batb":[[0,2.76,9.67],[1,2.58,27.18],[2,1.1,3000]],"ltp":2.78,"tv":1.05,"id":67083366}]}]}
{"op":"mcm","clk":"11958435320","pt":1724573511693,"mc":[{"id":"1.232245129","rc":[{"batb":[[0,2.78,4],[1,2.76,9.67],[2,2.58,27.18]],"ltp":2.78,"tv":1.05,"id":67083366}]}]}
{"op":"mcm","clk":"11958435548","pt":1724573514013,"mc":[{"id":"1.232245129","rc":[{"batb":[[0,2.76,9.67],[1,2.58,27.18],[2,1.1,3000]],"ltp":2.78,"tv":1.05,"id":67083366}]}]}
{"op":"mcm","clk":"11958438244","pt":1724573543543,"mc":[{"id":"1.232245129","rc":[{"batb":[[0,2.78,4],[1,2.76,9.67],[2,2.58,27.18]],"ltp":2.78,"tv":1.05,"id":67083366}]}]}
{"op":"mcm","clk":"11958438505","pt":1724573545850,"mc":[{"id":"1.232245129","rc":[{"batb":[[0,2.76,9.67],[1,2.58,27.18],[2,1.1,3000]],"ltp":2.78,"tv":1.05,"id":67083366}]}]}
{"op":"mcm","clk":"11958438962","pt":1724573550509,"mc":[{"id":"1.232245129","rc":[{"batb":[[0,2.78,4],[1,2.76,9.67],[2,2.58,27.18]],"ltp":2.78,"tv":1.05,"id":67083366}]}]}
{"op":"mcm","clk":"11958439136","pt":1724573552828,"mc":[{"id":"1.232245129","rc":[{"batb":[[0,2.76,9.67],[1,2.58,27.18],[2,1.1,3000]],"ltp":2.78,"tv":1.05,"id":67083366}]}]}
{"op":"mcm","clk":"11958440502","pt":1724573568634,"mc":[{"id":"1.232245129","rc":[{"batb":[[0,2.78,4],[1,2.76,9.67],[2,2.58,27.18]],"ltp":2.78,"tv":1.05,"id":67083366}]}]}
{"op":"mcm","clk":"11958440710","pt":1724573571051,"mc":[{"id":"1.232245129","rc":[{"batb":[[0,2.76,9.67],[1,2.58,27.18],[2,1.1,3000]],"ltp":2.78,"tv":1.05,"id":67083366}]}]}
{"op":"mcm","clk":"11958457226","pt":1724573598283,"mc":[{"id":"1.232245129","rc":[{"batb":[[0,2.78,4],[1,2.76,9.67]],"ltp":2.78,"tv":1.05,"id":67083366},{"batb":[[0,1.55,5.63]],"ltp":1.56,"tv":180.88,"id":72922097}]}]}
{"op":"mcm","clk":"11958457457","pt":1724573600462,"mc":[{"id":"1.232245129","rc":[{"batb":[[0,2.76,9.67],[1,1.1,3000],[2,1.03,200]],"ltp":2.78,"tv":1.05,"id":67083366}]}]}
{"op":"mcm","clk":"11958457598","pt":1724573602263,"mc":[{"id":"1.232245129","rc":[{"batb":[[0,1.33,138.46],[1,1.32,126.2],[2,1.23,138.46]],"ltp":1.56,"tv":180.88,"id":72922097}]}]}
{"op":"mcm","clk":"11958457678","pt":1724573603291,"mc":[{"id":"1.232245129","rc":[{"batb":[[1,2.58,27.18],[2,1.1,3000]],"ltp":2.78,"tv":1.05,"id":67083366},{"batb":[[0,1.54,79.53],[1,1.33,138.46],[2,1.32,126.2]],"ltp":1.56,"tv":180.88,"id":72922097}]}]}
{"op":"mcm","clk":"11958457688","pt":1724573603398,"mc":[{"id":"1.232245129","rc":[{"batb":[[0,2.78,4],[1,2.76,9.67],[2,2.58,27.18]],"ltp":2.78,"tv":1.05,"id":67083366}]}]}
{"op":"mcm","clk":"11958457908","pt":1724573605607,"mc":[{"id":"1.232245129","rc":[{"batb":[[0,2.76,9.67],[1,2.58,27.18],[2,1.1,3000]],"ltp":2.78,"tv":1.05,"id":67083366}]}]}
{"op":"mcm","clk":"11958460657","pt":1724573635944,"mc":[{"id":"1.232245129","rc":[{"batb":[[0,2.78,4],[1,2.76,9.67],[2,2.58,27.18]],"ltp":2.78,"tv":1.05,"id":67083366}]}]}
{"op":"mcm","clk":"11958460838","pt":1724573638152,"mc":[{"id":"1.232245129","rc":[{"batb":[[0,2.76,9.67],[1,2.58,27.18],[2,1.1,3000]],"ltp":2.78,"tv":1.05,"id":67083366}]}]}
{"op":"mcm","clk":"11958461267","pt":1724573642726,"mc":[{"id":"1.232245129","rc":[{"batb":[[0,2.78,4],[1,2.76,9.67],[2,2.58,27.18]],"ltp":2.78,"tv":1.05,"id":67083366}]}]}
{"op":"mcm","clk":"11958461459","pt":1724573645043,"mc":[{"id":"1.232245129","rc":[{"batb":[[0,2.76,9.67],[1,2.58,27.18],[2,1.1,3000]],"ltp":2.78,"tv":1.05,"id":67083366}]}]}
{"op":"mcm","clk":"11958461872","pt":1724573650175,"mc":[{"id":"1.232245129","rc":[{"batb":[[0,2.78,4],[1,2.76,9.67],[2,2.58,27.18]],"ltp":2.78,"tv":1.05,"id":67083366}]}]}
{"op":"mcm","clk":"11958462053","pt":1724573652548,"mc":[{"id":"1.232245129","rc":[{"batb":[[0,2.76,9.67],[1,2.58,27.18],[2,1.1,3000]],"ltp":2.78,"tv":1.05,"id":67083366}]}]}
{"op":"mcm","clk":"11958463307","pt":1724573667209,"mc":[{"id":"1.232245129","rc":[{"batb":[[0,2.78,4],[1,2.76,9.67],[2,2.58,27.18]],"ltp":2.78,"tv":1.05,"id":67083366}]}]}
{"op":"mcm","clk":"11958463494","pt":1724573669679,"mc":[{"id":"1.232245129","rc":[{"batb":[[0,2.76,9.67],[1,2.58,27.18],[2,1.1,3000]],"ltp":2.78,"tv":1.05,"id":67083366}]}]}
{"op":"mcm","clk":"11958463766","pt":1724573672815,"mc":[{"id":"1.232245129","rc":[{"batb":[[0,2.78,4],[1,2.76,9.67],[2,2.58,27.18]],"ltp":2.78,"tv":1.05,"id":67083366}]}]}
{"op":"mcm","clk":"11958463919","pt":1724573675187,"mc":[{"id":"1.232245129","rc":[{"batb":[[0,2.76,9.67],[1,2.58,27.18],[2,1.1,3000]],"ltp":2.78,"tv":1.05,"id":67083366}]}]}
{"op":"mcm","clk":"11958464333","pt":1724573680789,"mc":[{"id":"1.232245129","rc":[{"batb":[[0,2.78,4],[1,2.76,9.67],[2,2.58,27.18]],"ltp":2.78,"tv":1.05,"id":67083366}]}]}
{"op":"mcm","clk":"11958464536","pt":1724573683205,"mc":[{"id":"1.232245129","rc":[{"batb":[[0,2.76,9.67],[1,2.58,27.18],[2,1.1,3000]],"ltp":2.78,"tv":1.05,"id":67083366}]}]}
{"op":"mcm","clk":"11958464748","pt":1724573685932,"mc":[{"id":"1.232245129","rc":[{"batb":[[0,2.78,4],[1,2.76,9.67],[2,2.58,27.18]],"ltp":2.78,"tv":1.05,"id":67083366}]}]}
{"op":"mcm","clk":"11958464952","pt":1724573688291,"mc":[{"id":"1.232245129","rc":[{"batb":[[0,2.76,9.67],[1,2.58,27.18],[2,1.1,3000]],"ltp":2.78,"tv":1.05,"id":67083366}]}]}
{"op":"mcm","clk":"11958466971","pt":1724573709975,"mc":[{"id":"1.232245129","rc":[{"batb":[[0,2.78,4],[1,2.76,9.67],[2,2.58,27.18]],"ltp":2.78,"tv":1.05,"id":67083366}]}]}
{"op":"mcm","clk":"11958467191","pt":1724573712210,"mc":[{"id":"1.232245129","rc":[{"batb":[[0,2.76,9.67],[1,2.58,27.18],[2,1.1,3000]],"ltp":2.78,"tv":1.05,"id":67083366}]}]}
{"op":"mcm","clk":"11958469285","pt":1724573737031,"mc":[{"id":"1.232245129","rc":[{"batb":[[0,2.78,4],[1,2.76,9.67],[2,2.58,27.18]],"ltp":2.78,"tv":1.05,"id":67083366}]}]}
{"op":"mcm","clk":"11958469477","pt":1724573739349,"mc":[{"id":"1.232245129","rc":[{"batb":[[0,2.76,9.67],[1,2.58,27.18],[2,1.1,3000]],"ltp":2.78,"tv":1.05,"id":67083366}]}]}
{"op":"mcm","clk":"11958474116","pt":1724573789510,"mc":[{"id":"1.232245129","rc":[{"batb":[[0,2.78,4],[1,2.76,9.67],[2,2.58,27.18]],"ltp":2.78,"tv":1.05,"id":67083366}]}]}
{"op":"mcm","clk":"11958474371","pt":1724573791801,"mc":[{"id":"1.232245129","rc":[{"batb":[[0,2.76,9.67],[1,2.58,27.18],[2,1.1,3000]],"ltp":2.78,"tv":1.05,"id":67083366}]}]}
{"op":"mcm","clk":"11958474896","pt":1724573796917,"mc":[{"id":"1.232245129","rc":[{"batb":[[0,2.78,4],[1,2.76,9.67],[2,2.58,27.18]],"ltp":2.78,"tv":1.05,"id":67083366}]}]}
{"op":"mcm","clk":"11958475109","pt":1724573799287,"mc":[{"id":"1.232245129","rc":[{"batb":[[0,2.76,9.67],[1,2.58,27.18],[2,1.1,3000]],"ltp":2.78,"tv":1.05,"id":67083366}]}]}
{"op":"mcm","clk":"11958478387","pt":1724573833480,"mc":[{"id":"1.232245129","rc":[{"batb":[[0,2.78,4],[1,2.76,9.67],[2,2.58,27.18]],"ltp":2.78,"tv":1.05,"id":67083366}]}]}
{"op":"mcm","clk":"11958478586","pt":1724573835756,"mc":[{"id":"1.232245129","rc":[{"batb":[[0,2.76,9.67],[1,2.58,27.18],[2,1.1,3000]],"ltp":2.78,"tv":1.05,"id":67083366}]}]}
{"op":"mcm","clk":"11958478907","pt":1724573838844,"mc":[{"id":"1.232245129","rc":[{"batb":[[0,2.78,4],[1,2.76,9.67],[2,2.58,27.18]],"ltp":2.78,"tv":1.05,"id":67083366},{"batb":[[0,1.55,5.63],[1,1.54,79.53],[2,1.33,138.46]],"ltp":1.56,"tv":180.88,"id":72922097}]}]}
{"op":"mcm","clk":"11958478969","pt":1724573839470,"mc":[{"id":"1.232245129","rc":[{"batb":[[2,1.1,3000]],"ltp":2.78,"tv":1.05,"id":67083366},{"batb":[[1,1.33,138.46],[2,1.32,126.2]],"ltp":1.56,"tv":180.88,"id":72922097}]}]}
{"op":"mcm","clk":"11958479165","pt":1724573841174,"mc":[{"id":"1.232245129","rc":[{"batb":[[0,2.76,9.67],[1,1.1,3000],[2,1.03,200]],"ltp":2.78,"tv":1.05,"id":67083366}]}]}
{"op":"mcm","clk":"11958479343","pt":1724573842973,"mc":[{"id":"1.232245129","rc":[{"batb":[[0,1.33,138.46],[1,1.32,126.2],[2,1.23,138.46]],"ltp":1.56,"tv":180.88,"id":72922097}]}]}
{"op":"mcm","clk":"11958479511","pt":1724573844667,"mc":[{"id":"1.232245129","rc":[{"batb":[[0,2.78,4],[1,2.76,9.67],[2,2.58,27.18]],"ltp":2.78,"tv":1.05,"id":67083366},{"batb":[[0,1.54,79.53],[1,1.33,138.46],[2,1.32,126.2]],"ltp":1.56,"tv":180.88,"id":72922097}]}]}
{"op":"mcm","clk":"11958479760","pt":1724573847089,"mc":[{"id":"1.232245129","rc":[{"batb":[[0,2.76,9.67],[1,2.58,27.18],[2,1.1,3000]],"ltp":2.78,"tv":1.05,"id":67083366}]}]}
{"op":"mcm","clk":"11958480607","pt":1724573855995,"mc":[{"id":"1.232245129","rc":[{"batb":[[0,2.78,4],[1,2.76,9.67],[2,2.58,27.18]],"ltp":2.78,"tv":1.05,"id":67083366}]}]}
{"op":"mcm","clk":"11958480795","pt":1724573858411,"mc":[{"id":"1.232245129","rc":[{"batb":[[0,2.76,9.67],[1,2.58,27.18],[2,1.1,3000]],"ltp":2.78,"tv":1.05,"id":67083366}]}]}
{"op":"mcm","clk":"11958481317","pt":1724573864298,"mc":[{"id":"1.232245129","rc":[{"batb":[[0,2.78,4],[1,2.76,9.67],[2,2.58,27.18]],"ltp":2.78,"tv":1.05,"id":67083366}]}]}
{"op":"mcm","clk":"11958481540","pt":1724573866612,"mc":[{"id":"1.232245129","rc":[{"batb":[[0,2.76,9.67],[1,2.58,27.18],[2,1.1,3000]],"ltp":2.78,"tv":1.05,"id":67083366}]}]}
{"op":"mcm","clk":"11958482338","pt":1724573875703,"mc":[{"id":"1.232245129","rc":[{"batb":[[0,2.78,4],[1,2.76,9.67],[2,2.58,27.18]],"ltp":2.78,"tv":1.05,"id":67083366}]}]}
{"op":"mcm","clk":"11958482545","pt":1724573878119,"mc":[{"id":"1.232245129","rc":[{"batb":[[0,2.76,9.67],[1,2.58,27.18],[2,1.1,3000]],"ltp":2.78,"tv":1.05,"id":67083366}]}]}
{"op":"mcm","clk":"11958482863","pt":1724573881132,"mc":[{"id":"1.232245129","rc":[{"batb":[[0,2.78,4],[1,2.76,9.67],[2,2.58,27.18]],"ltp":2.78,"tv":1.05,"id":67083366}]}]}
{"op":"mcm","clk":"11958483141","pt":1724573883508,"mc":[{"id":"1.232245129","rc":[{"batb":[[0,2.76,9.67],[1,2.58,27.18],[2,1.1,3000]],"ltp":2.78,"tv":1.05,"id":67083366}]}]}
{"op":"mcm","clk":"11958486408","pt":1724573919159,"mc":[{"id":"1.232245129","rc":[{"batb":[[0,2.78,4],[1,2.76,9.67],[2,2.58,27.18]],"ltp":2.78,"tv":1.05,"id":67083366}]}]}
{"op":"mcm","clk":"11958486593","pt":1724573921533,"mc":[{"id":"1.232245129","rc":[{"batb":[[0,2.76,9.67],[1,2.58,27.18],[2,1.1,3000]],"ltp":2.78,"tv":1.05,"id":67083366}]}]}
{"op":"mcm","clk":"11958487615","pt":1724573934585,"mc":[{"id":"1.232245129","rc":[{"batb":[[0,2.78,4],[1,2.76,9.67],[2,2.58,27.18]],"ltp":2.78,"tv":1.05,"id":67083366}]}]}
{"op":"mcm","clk":"11958487765","pt":1724573936861,"mc":[{"id":"1.232245129","rc":[{"batb":[[0,2.76,9.67],[1,2.58,27.18],[2,1.1,3000]],"ltp":2.78,"tv":1.05,"id":67083366}]}]}
{"op":"mcm","clk":"11958489631","pt":1724573957591,"mc":[{"id":"1.232245129","rc":[{"batb":[[0,2.78,4],[1,2.76,9.67],[2,2.58,27.18]],"ltp":2.78,"tv":1.05,"id":67083366}]}]}
{"op":"mcm","clk":"11958489818","pt":1724573959810,"mc":[{"id":"1.232245129","rc":[{"batb":[[0,2.76,9.67],[1,2.58,27.18],[2,1.1,3000]],"ltp":2.78,"tv":1.05,"id":67083366}]}]}
{"op":"mcm","clk":"11958491554","pt":1724573980309,"mc":[{"id":"1.232245129","rc":[{"batb":[[0,2.78,4],[1,2.76,9.67],[2,2.58,27.18]],"ltp":2.78,"tv":1.05,"id":67083366}]}]}
{"op":"mcm","clk":"11958491799","pt":1724573983241,"mc":[{"id":"1.232245129","rc":[{"batb":[[0,2.76,9.67],[1,2.58,27.18],[2,1.1,3000]],"ltp":2.78,"tv":1.05,"id":67083366}]}]}
{"op":"mcm","clk":"11958501913","pt":1724574096410,"mc":[{"id":"1.232245129","rc":[{"batb":[[0,2.78,4],[1,2.76,9.67],[2,2.58,27.18]],"ltp":2.78,"tv":1.05,"id":67083366}]}]}
{"op":"mcm","clk":"11958502117","pt":1724574098674,"mc":[{"id":"1.232245129","rc":[{"batb":[[0,2.76,9.67],[1,2.58,27.18],[2,1.1,3000]],"ltp":2.78,"tv":1.05,"id":67083366}]}]}
{"op":"mcm","clk":"11958511415","pt":1724574200536,"mc":[{"id":"1.232245129","rc":[{"batb":[[0,2.78,4],[1,2.76,9.67]],"ltp":2.78,"tv":1.05,"id":67083366},{"batb":[[0,1.55,5.63]],"ltp":1.56,"tv":180.88,"id":72922097}]}]}
{"op":"mcm","clk":"11958511647","pt":1724574202696,"mc":[{"id":"1.232245129","rc":[{"batb":[[0,2.76,9.67],[1,1.1,3000],[2,1.03,200]],"ltp":2.78,"tv":1.05,"id":67083366}]}]}
{"op":"mcm","clk":"11958512023","pt":1724574207212,"mc":[{"id":"1.232245129","rc":[{"batb":[[0,2.78,4],[1,2.76,9.67],[2,1.1,3000]],"ltp":2.78,"tv":1.05,"id":67083366},{"batb":[[0,1.33,138.46],[1,1.32,126.2],[2,1.23,138.46]],"ltp":1.56,"tv":180.88,"id":72922097}]}]}
{"op":"mcm","clk":"11958512212","pt":1724574209431,"mc":[{"id":"1.232245129","rc":[{"batb":[[0,2.76,9.67],[1,1.1,3000],[2,1.03,200]],"ltp":2.78,"tv":1.05,"id":67083366}]}]}
{"op":"mcm","clk":"11958512332","pt":1724574210614,"mc":[{"id":"1.232245129","rc":[{"batb":[[1,2.58,27.18],[2,1.1,3000]],"ltp":2.78,"tv":1.05,"id":67083366},{"batb":[[0,1.54,79.53],[1,1.33,138.46],[2,1.32,126.2]],"ltp":1.56,"tv":180.88,"id":72922097}]}]}
{"op":"mcm","clk":"11958518265","pt":1724574271178,"mc":[{"id":"1.232245129","rc":[{"batb":[[0,2.78,4],[1,2.76,9.67],[2,2.58,27.18]],"ltp":2.78,"tv":1.05,"id":67083366}]}]}
{"op":"mcm","clk":"11958518553","pt":1724574273810,"mc":[{"id":"1.232245129","rc":[{"batb":[[0,2.76,9.67],[1,2.58,27.18],[2,1.1,3000]],"ltp":2.78,"tv":1.05,"id":67083366}]}]}
{"op":"mcm","clk":"11958523831","pt":1724574323655,"mc":[{"id":"1.232245129","rc":[{"batb":[[0,2.78,4],[1,2.76,9.67],[2,2.58,27.18]],"ltp":2.78,"tv":1.05,"id":67083366}]}]}
{"op":"mcm","clk":"11958524075","pt":1724574325865,"mc":[{"id":"1.232245129","rc":[{"batb":[[0,2.76,9.67],[1,2.58,27.18],[2,1.1,3000]],"ltp":2.78,"tv":1.05,"id":67083366}]}]}
{"op":"mcm","clk":"11958525206","pt":1724574336896,"mc":[{"id":"1.232245129","rc":[{"batb":[[0,2.78,4],[1,2.76,9.67],[2,2.58,27.18]],"ltp":2.78,"tv":1.05,"id":67083366}]}]}
{"op":"mcm","clk":"11958525412","pt":1724574339106,"mc":[{"id":"1.232245129","rc":[{"batb":[[0,2.76,9.67],[1,2.58,27.18],[2,1.1,3000]],"ltp":2.78,"tv":1.05,"id":67083366}]}]}
{"op":"mcm","clk":"11958528444","pt":1724574369641,"mc":[{"id":"1.232245129","rc":[{"batb":[[0,2.78,4],[1,2.76,9.67],[2,2.58,27.18]],"ltp":2.78,"tv":1.05,"id":67083366}]}]}
{"op":"mcm","clk":"11958528657","pt":1724574372062,"mc":[{"id":"1.232245129","rc":[{"batb":[[0,2.76,9.67],[1,2.58,27.18],[2,1.1,3000]],"ltp":2.78,"tv":1.05,"id":67083366}]}]}
{"op":"mcm","clk":"11958529038","pt":1724574376454,"mc":[{"id":"1.232245129","rc":[{"batb":[[0,2.78,4],[1,2.76,9.67],[2,2.58,27.18]],"ltp":2.78,"tv":1.05,"id":67083366}]}]}
{"op":"mcm","clk":"11958529225","pt":1724574377967,"mc":[{"id":"1.232245129","rc":[{"batb":[[0,1.55,5.63],[1,1.54,79.53],[2,1.33,138.46]],"ltp":1.56,"tv":180.88,"id":72922097}]}]}
{"op":"mcm","clk":"11958529327","pt":1724574378949,"mc":[{"id":"1.232245129","rc":[{"batb":[[0,2.76,9.67],[1,2.58,27.18],[2,1.1,3000]],"ltp":2.78,"tv":1.05,"id":67083366}]}]}
{"op":"mcm","clk":"11958529535","pt":1724574381164,"mc":[{"id":"1.232245129","rc":[{"batb":[[0,2.78,4],[1,2.76,9.67]],"ltp":2.78,"tv":1.05,"id":67083366},{"batb":[[1,1.33,138.46],[2,1.32,126.2]],"ltp":1.56,"tv":180.88,"id":72922097}]}]}
{"op":"mcm","clk":"11958529725","pt":1724574383067,"mc":[{"id":"1.232245129","rc":[{"batb":[[0,1.33,138.46],[1,1.32,126.2],[2,1.23,138.46]],"ltp":1.56,"tv":180.88,"id":72922097}]}]}
{"op":"mcm","clk":"11958529751","pt":1724574383379,"mc":[{"id":"1.232245129","rc":[{"batb":[[0,2.76,9.67],[1,1.1,3000],[2,1.03,200]],"ltp":2.78,"tv":1.05,"id":67083366}]}]}
{"op":"mcm","clk":"11958530028","pt":1724574386172,"mc":[{"id":"1.232245129","rc":[{"batb":[[0,2.78,4],[1,2.76,9.67],[2,2.58,27.18]],"ltp":2.78,"tv":1.05,"id":67083366},{"batb":[[0,1.54,79.53],[1,1.33,138.46],[2,1.32,126.2]],"ltp":1.56,"tv":180.88,"id":72922097}]}]}
{"op":"mcm","clk":"11958530283","pt":1724574388453,"mc":[{"id":"1.232245129","rc":[{"batb":[[0,2.76,9.67],[1,2.58,27.18],[2,1.1,3000]],"ltp":2.78,"tv":1.05,"id":67083366}]}]}
{"op":"mcm","clk":"11958531666","pt":1724574401894,"mc":[{"id":"1.232245129","rc":[{"batb":[[0,2.78,4],[1,2.76,9.67],[2,2.58,27.18]],"ltp":2.78,"tv":1.05,"id":67083366}]}]}
{"op":"mcm","clk":"11958531885","pt":1724574404370,"mc":[{"id":"1.232245129","rc":[{"batb":[[0,2.76,9.67],[1,2.58,27.18],[2,1.1,3000]],"ltp":2.78,"tv":1.05,"id":67083366}]}]}
{"op":"mcm","clk":"11958538591","pt":1724574473180,"mc":[{"id":"1.232245129","rc":[{"batb":[[0,2.78,4],[1,2.76,9.67],[2,2.58,27.18]],"ltp":2.78,"tv":1.05,"id":67083366}]}]}
{"op":"mcm","clk":"11958538808","pt":1724574475646,"mc":[{"id":"1.232245129","rc":[{"batb":[[0,2.76,9.67],[1,2.58,27.18],[2,1.1,3000]],"ltp":2.78,"tv":1.05,"id":67083366}]}]}
{"op":"mcm","clk":"11958542432","pt":1724574512999,"mc":[{"id":"1.232245129","rc":[{"batb":[[0,2.78,4],[1,2.76,9.67],[2,2.58,27.18]],"ltp":2.78,"tv":1.05,"id":67083366}]}]}
{"op":"mcm","clk":"11958542684","pt":1724574515614,"mc":[{"id":"1.232245129","rc":[{"batb":[[0,2.76,9.67],[1,2.58,27.18],[2,1.1,3000]],"ltp":2.78,"tv":1.05,"id":67083366}]}]}
{"op":"mcm","clk":"11958543122","pt":1724574519692,"mc":[{"id":"1.232245129","rc":[{"batb":[[0,2.78,4],[1,2.76,9.67],[2,2.58,27.18]],"ltp":2.78,"tv":1.05,"id":67083366}]}]}
{"op":"mcm","clk":"11958543369","pt":1724574522214,"mc":[{"id":"1.232245129","rc":[{"batb":[[0,2.76,9.67],[1,2.58,27.18],[2,1.1,3000]],"ltp":2.78,"tv":1.05,"id":67083366}]}]}
{"op":"mcm","clk":"11958543795","pt":1724574526498,"mc":[{"id":"1.232245129","rc":[{"batb":[[0,2.78,4],[1,2.76,9.67],[2,2.58,27.18]],"ltp":2.78,"tv":1.05,"id":67083366}]}]}
{"op":"mcm","clk":"11958544021","pt":1724574529136,"mc":[{"id":"1.232245129","rc":[{"batb":[[0,2.76,9.67],[1,2.58,27.18],[2,1.1,3000]],"ltp":2.78,"tv":1.05,"id":67083366}]}]}
{"op":"mcm","clk":"11958546152","pt":1724574551939,"mc":[{"id":"1.232245129","rc":[{"batb":[[0,2.78,4],[1,2.76,9.67],[2,2.58,27.18]],"ltp":2.78,"tv":1.05,"id":67083366}]}]}
{"op":"mcm","clk":"11958546387","pt":1724574554562,"mc":[{"id":"1.232245129","rc":[{"batb":[[0,2.76,9.67],[1,2.58,27.18],[2,1.1,3000]],"ltp":2.78,"tv":1.05,"id":67083366}]}]}
{"op":"mcm","clk":"11958546817","pt":1724574559150,"mc":[{"id":"1.232245129","rc":[{"batb":[[0,2.78,4],[1,2.76,9.67],[2,2.58,27.18]],"ltp":2.78,"tv":1.05,"id":67083366},{"batb":[[0,1.55,5.63],[1,1.54,79.53],[2,1.33,138.46]],"ltp":1.56,"tv":180.88,"id":72922097}]}]}
{"op":"mcm","clk":"11958547082","pt":1724574561673,"mc":[{"id":"1.232245129","rc":[{"batb":[[0,2.76,9.67],[1,1.1,3000],[2,1.03,200]],"ltp":2.78,"tv":1.05,"id":67083366},{"batb":[[1,1.33,138.46],[2,1.32,126.2]],"ltp":1.56,"tv":180.88,"id":72922097}]}]}
{"op":"mcm","clk":"11958547267","pt":1724574563583,"mc":[{"id":"1.232245129","rc":[{"batb":[[0,2.78,4],[1,2.76,9.67],[2,1.1,3000]],"ltp":2.78,"tv":1.05,"id":67083366},{"batb":[[0,1.33,138.46],[1,1.32,126.2],[2,1.23,138.46]],"ltp":1.56,"tv":180.88,"id":72922097}]}]}
{"op":"mcm","clk":"11958547475","pt":1724574565745,"mc":[{"id":"1.232245129","rc":[{"batb":[[0,2.76,9.67],[1,1.1,3000],[2,1.03,200]],"ltp":2.78,"tv":1.05,"id":67083366}]}]}
{"op":"mcm","clk":"11958547548","pt":1724574566669,"mc":[{"id":"1.232245129","rc":[{"batb":[[1,2.58,27.18],[2,1.1,3000]],"ltp":2.78,"tv":1.05,"id":67083366},{"batb":[[0,1.54,79.53],[1,1.33,138.46],[2,1.32,126.2]],"ltp":1.56,"tv":180.88,"id":72922097}]}]}
{"op":"mcm","clk":"11958547905","pt":1724574570890,"mc":[{"id":"1.232245129","rc":[{"batb":[[0,2.78,4],[1,2.76,9.67],[2,2.58,27.18]],"ltp":2.78,"tv":1.05,"id":67083366}]}]}
{"op":"mcm","clk":"11958548110","pt":1724574573206,"mc":[{"id":"1.232245129","rc":[{"batb":[[0,2.76,9.67],[1,2.58,27.18],[2,1.1,3000]],"ltp":2.78,"tv":1.05,"id":67083366}]}]}
{"op":"mcm","clk":"11958552465","pt":1724574612931,"mc":[{"id":"1.232245129","rc":[{"batb":[[0,2.78,4],[1,2.76,9.67],[2,2.58,27.18]],"ltp":2.78,"tv":1.05,"id":67083366}]}]}
{"op":"mcm","clk":"11958552703","pt":1724574615097,"mc":[{"id":"1.232245129","rc":[{"batb":[[0,2.76,9.67],[1,2.58,27.18],[2,1.1,3000]],"ltp":2.78,"tv":1.05,"id":67083366}]}]}
{"op":"mcm","clk":"11958554393","pt":1724574632332,"mc":[{"id":"1.232245129","rc":[{"batb":[[0,2.78,4],[1,2.76,9.67],[2,2.58,27.18]],"ltp":2.78,"tv":1.05,"id":67083366}]}]}
{"op":"mcm","clk":"11958554619","pt":1724574634551,"mc":[{"id":"1.232245129","rc":[{"batb":[[0,2.76,9.67],[1,2.58,27.18],[2,1.1,3000]],"ltp":2.78,"tv":1.05,"id":67083366}]}]}
{"op":"mcm","clk":"11958555024","pt":1724574638163,"mc":[{"id":"1.232245129","rc":[{"batb":[[0,2.78,4],[1,2.76,9.67],[2,2.58,27.18]],"ltp":2.78,"tv":1.05,"id":67083366},{"batl":[[1,1.6,1725.44],[2,1.6,0]],"ltp":1.56,"tv":180.88,"id":72922097}]}]}
{"op":"mcm","clk":"11958555207","pt":1724574639668,"mc":[{"id":"1.232245129","rc":[{"batb":[[1,2.58,27.18],[2,1.1,3000]],"ltp":2.78,"tv":1.05,"id":67083366},{"batl":[[0,1.6,1725.44],[1,1.6,0]],"ltp":1.56,"tv":180.88,"id":72922097}]}]}
{"op":"mcm","clk":"11958555314","pt":1724574640442,"mc":[{"id":"1.232245129","rc":[{"batb":[[0,2.6,5]],"ltp":2.78,"tv":1.05,"id":67083366}]}]}
{"op":"mcm","clk":"11958555526","pt":1724574642863,"mc":[{"id":"1.232245129","rc":[{"batb":[[0,2.62,4],[1,2.6,5],[2,2.58,27.18]],"ltp":2.78,"tv":1.05,"id":67083366},{"batb":[[0,1.55,11.96],[1,1.54,79.53],[2,1.33,138.46]],"ltp":1.56,"tv":180.88,"id":72922097}]}]}
{"op":"mcm","clk":"11958555660","pt":1724574644254,"mc":[{"id":"1.232245129","rc":[{"trd":[[2.82,18],[2.84,1.18]],"batb":[[1,2.58,27.18],[2,1.1,3000]],"ltp":2.84,"tv":20.23,"id":67083366},{"trd":[[1.54,194.44],[1.55,23.92]],"batb":[[0,1.33,138.46],[1,1.32,126.2],[2,1.23,138.46]],"batl":[[0,1.54,150.29],[1,1.6,1725.44]],"ltp":1.54,"tv":399.0,"id":72922097}],"tv":419.23}]}
{"op":"mcm","clk":"11958555738","pt":1724574645178,"mc":[{"id":"1.232245129","rc":[{"batb":[[0,2.58,27.18],[1,1.1,3000],[2,1.03,200]],"ltp":2.84,"tv":20.23,"id":67083366}]}]}
{"op":"mcm","clk":"11958555940","pt":1724574647187,"mc":[{"id":"1.232245129","rc":[{"batb":[[1,1.1,3003.05]],"ltp":2.84,"tv":20.23,"id":67083366},{"batb":[[0,1.5,85.9],[1,1.33,138.46],[2,1.32,126.2]],"ltp":1.54,"tv":399.0,"id":72922097}]}]}
{"op":"mcm","clk":"11958557063","pt":1724574658501,"mc":[{"id":"1.232245129","rc":[{"batl":[[0,1.6,1725.44],[1,1.6,0]],"ltp":1.54,"tv":399.0,"id":72922097}]}]}
{"op":"mcm","clk":"11958565546","pt":1724574740466,"mc":[{"id":"1.232245129","rc":[{"batl":[[0,1.54,69.23],[1,1.6,1725.44]],"ltp":1.54,"tv":399.0,"id":72922097}]}]}
{"op":"mcm","clk":"11958814146","pt":1724576947981,"mc":[{"id":"1.232245129","rc":[{"trd":[[2.84,2.18]],"ltp":2.84,"tv":21.23,"id":67083366},{"trd":[[1.54,196.28]],"batl":[[0,1.54,67.39]],"ltp":1.54,"tv":400.84,"id":72922097}],"tv":422.07}]}
{"op":"mcm","clk":"11958815047","pt":1724576955502,"mc":[{"id":"1.232245129","rc":[{"batl":[[2,2.5,1]],"ltp":1.54,"tv":400.84,"id":72922097}]}]}
{"op":"mcm","clk":"11958934865","pt":1724578051495,"mc":[{"id":"1.232245129","rc":[{"batb":[[0,2.98,1.38],[1,2.58,27.18],[2,1.1,3003.05]],"ltp":2.84,"tv":21.23,"id":67083366}]}]}
{"op":"mcm","clk":"11958936534","pt":1724578065547,"mc":[{"id":"1.232245129","rc":[{"batb":[[0,2.58,27.18],[1,1.1,3003.05],[2,1.03,200]],"ltp":2.84,"tv":21.23,"id":67083366}]}]}
{"op":"mcm","clk":"11959036752","pt":1724578859697,"mc":[{"id":"1.232245129","rc":[{"batb":[[1,1.4,164.97],[2,1.33,138.46]],"ltp":1.54,"tv":400.84,"id":72922097}]}]}
{"op":"mcm","clk":"11959037536","pt":1724578865731,"mc":[{"id":"1.232245129","rc":[{"batb":[[0,2.62,40.91],[1,2.58,27.18],[2,1.1,3003.05]],"ltp":2.84,"tv":21.23,"id":67083366}]}]}
{"op":"mcm","clk":"11959082704","pt":1724579138375,"mc":[{"id":"1.232245129","rc":[{"batl":[[2,2,573.68]],"ltp":1.54,"tv":400.84,"id":72922097}]}]}
{"op":"mcm","clk":"11959083856","pt":1724579147882,"mc":[{"id":"1.232245129","rc":[{"batl":[[2,2,1147.35]],"ltp":1.54,"tv":400.84,"id":72922097}]}]}
{"op":"mcm","clk":"11959084711","pt":1724579155305,"mc":[{"id":"1.232245129","rc":[{"batl":[[2,2,1721.03]],"ltp":1.54,"tv":400.84,"id":72922097}]}]}
{"op":"mcm","clk":"11959238032","pt":1724580354334,"mc":[{"id":"1.232245129","rc":[{"trd":[[2.84,2.21]],"ltp":2.84,"tv":21.26,"id":67083366},{"trd":[[1.54,196.33]],"batl":[[0,1.54,67.34]],"ltp":1.54,"tv":400.89,"id":72922097}],"tv":422.15}]}
{"op":"mcm","clk":"11959303561","pt":1724580796153,"mc":[{"id":"1.232245129","rc":[{"batb":[[0,2.64,9],[1,2.62,40.91],[2,2.58,27.18]],"batl":[[0,2.86,1.38]],"ltp":2.84,"tv":21.26,"id":67083366}]}]}
{"op":"mcm","clk":"11959303887","pt":1724580798501,"mc":[{"id":"1.232245129","rc":[{"batb":[[0,2.64,5]],"ltp":2.84,"tv":21.26,"id":67083366}]}]}
{"op":"mcm","clk":"11959304012","pt":1724580799392,"mc":[{"id":"1.232245129","rc":[{"batb":[[0,2.62,40.91],[1,2.58,27.18],[2,1.1,3003.05]],"ltp":2.84,"tv":21.26,"id":67083366}]}]}
{"op":"mcm","clk":"11959307090","pt":1724580820492,"mc":[{"id":"1.232245129","rc":[{"batb":[[0,2.64,9],[1,2.62,40.91],[2,2.58,27.18]],"ltp":2.84,"tv":21.26,"id":67083366}]}]}
{"op":"mcm","clk":"11959307416","pt":1724580822903,"mc":[{"id":"1.232245129","rc":[{"batb":[[0,2.64,5]],"ltp":2.84,"tv":21.26,"id":67083366}]}]}
{"op":"mcm","clk":"11959307568","pt":1724580823891,"mc":[{"id":"1.232245129","rc":[{"batb":[[0,2.62,40.91],[1,2.58,27.18],[2,1.1,3003.05]],"ltp":2.84,"tv":21.26,"id":67083366}]}]}
{"op":"mcm","clk":"11959308671","pt":1724580831681,"mc":[{"id":"1.232245129","rc":[{"batb":[[0,2.64,9],[1,2.62,40.91],[2,2.58,27.18]],"ltp":2.84,"tv":21.26,"id":67083366}]}]}
{"op":"mcm","clk":"11959309084","pt":1724580834306,"mc":[{"id":"1.232245129","rc":[{"batb":[[0,2.64,5]],"ltp":2.84,"tv":21.26,"id":67083366}]}]}
{"op":"mcm","clk":"11959309240","pt":1724580835314,"mc":[{"id":"1.232245129","rc":[{"batb":[[0,2.62,40.91],[1,2.58,27.18],[2,1.1,3003.05]],"ltp":2.84,"tv":21.26,"id":67083366}]}]}
{"op":"mcm","clk":"11959380888","pt":1724581299932,"mc":[{"id":"1.232245129","rc":[{"batb":[[2,1.32,126.2]],"ltp":1.54,"tv":400.89,"id":72922097}]}]}
{"op":"mcm","clk":"11959455433","pt":1724581776164,"mc":[{"id":"1.232245129","rc":[{"trd":[[1.5,12]],"batb":[[0,1.5,79.9]],"ltp":1.5,"tv":412.89,"id":72922097}],"tv":434.15}]}
{"op":"mcm","clk":"11959455812","pt":1724581778777,"mc":[{"id":"1.232245129","rc":[{"batb":[[0,1.5,85.9]],"ltp":1.5,"tv":412.89,"id":72922097}]}]}
{"op":"mcm","clk":"11959641748","pt":1724582977096,"mc":[{"id":"1.232245129","rc":[{"batb":[[1,1.4,173.2],[2,1.33,9.78]],"batl":[[2,1.9,5.66]],"ltp":1.5,"tv":412.89,"id":72922097}]}]}
{"op":"mcm","clk":"11959679623","pt":1724583238084,"mc":[{"id":"1.232245129","rc":[{"batb":[[0,1.51,6.45],[1,1.5,85.9],[2,1.4,173.2]],"batl":[[0,1.53,5.05],[1,1.54,67.34],[2,1.6,1725.44]],"ltp":1.5,"tv":412.89,"id":72922097}]}]}
{"op":"mcm","clk":"11959717616","pt":1724583501879,"mc":[{"id":"1.232245129","rc":[{"batb":[[0,1.51,10.99]],"ltp":1.5,"tv":412.89,"id":72922097}]}]}
{"op":"mcm","clk":"11959717893","pt":1724583503946,"mc":[{"id":"1.232245129","rc":[{"batb":[[0,1.51,6.45]],"ltp":1.5,"tv":412.89,"id":72922097}]}]}
{"op":"mcm","clk":"11959736258","pt":1724583624127,"mc":[{"id":"1.232245129","rc":[{"batb":[[0,1.51,10.99]],"ltp":1.5,"tv":412.89,"id":72922097}]}]}
{"op":"mcm","clk":"11959737843","pt":1724583633548,"mc":[{"id":"1.232245129","rc":[{"batb":[[0,1.51,6.45]],"ltp":1.5,"tv":412.89,"id":72922097}]}]}
{"op":"mcm","clk":"11959753031","pt":1724583717944,"mc":[{"id":"1.232245129","rc":[{"batl":[[1,1.6,1725.44],[2,1.9,5.66]],"ltp":1.5,"tv":412.89,"id":72922097}]}]}
{"op":"mcm","clk":"11959753273","pt":1724583719325,"mc":[{"id":"1.232245129","rc":[{"batl":[[0,1.6,1725.44],[1,1.9,5.66],[2,2,1721.03]],"ltp":1.5,"tv":412.89,"id":72922097}]}]}
{"op":"mcm","clk":"11959755147","pt":1724583728764,"mc":[{"id":"1.232245129","rc":[{"trd":[[1.51,12.9]],"batb":[[0,1.5,85.9],[1,1.4,173.2],[2,1.33,9.78]],"batl":[[0,1.51,68.04],[1,1.6,1725.44],[2,1.9,5.66]],"ltp":1.51,"tv":425.79,"id":72922097}],"tv":447.06}]}
{"op":"mcm","clk":"11959755287","pt":1724583729458,"mc":[{"id":"1.232245129","rc":[{"batl":[[0,1.51,74.49]],"ltp":1.51,"tv":425.79,"id":72922097}]}]}
{"op":"mcm","clk":"11959789053","pt":1724583919499,"mc":[{"id":"1.232245129","rc":[{"trd":[[1.51,16.98]],"batl":[[0,1.51,72.45]],"ltp":1.51,"tv":429.87,"id":72922097}],"tv":451.14}]}
{"op":"mcm","clk":"11959797577","pt":1724583968015,"mc":[{"id":"1.232245129","rc":[{"trd":[[1.51,55.18]],"batl":[[0,1.51,53.35]],"ltp":1.51,"tv":468.07,"id":72922097}],"tv":489.34}]}
{"op":"mcm","clk":"11959812044","pt":1724584044665,"mc":[{"id":"1.232245129","rc":[{"trd":[[1.51,90.42]],"batl":[[0,1.51,35.73]],"ltp":1.51,"tv":503.31,"id":72922097}],"tv":524.57}]}
{"op":"mcm","clk":"11959813972","pt":1724584054681,"mc":[{"id":"1.232245129","rc":[{"batl":[[2,1.87,5.66]],"ltp":1.51,"tv":503.31,"id":72922097}]}]}
{"op":"mcm","clk":"11959854461","pt":1724584270987,"mc":[{"id":"1.232245129","rc":[{"batb":[[1,1.4,164.97],[2,1.32,126.2]],"batl":[[2,2,1721.03]],"ltp":1.51,"tv":503.31,"id":72922097}]}]}
{"op":"mcm","clk":"11959854838","pt":1724584272970,"mc":[{"id":"1.232245129","rc":[{"batb":[[1,1.4,173.72],[2,1.33,9.78]],"batl":[[2,1.87,6.18]],"ltp":1.51,"tv":503.31,"id":72922097}]}]}
{"op":"mcm","clk":"11959857195","pt":1724584285684,"mc":[{"id":"1.232245129","rc":[{"trd":[[1.51,104.52]],"batl":[[0,1.51,28.68]],"ltp":1.51,"tv":517.4,"id":72922097}],"tv":538.67}]}
{"op":"mcm","clk":"11959858650","pt":1724584293711,"mc":[{"id":"1.232245129","rc":[{"batl":[[2,1.85,6.18]],"ltp":1.51,"tv":517.4,"id":72922097}]}]}
{"op":"mcm","clk":"11959902070","pt":1724584440715,"mc":[{"id":"1.232245129","rc":[{"trd":[[1.51,139.38]],"batl":[[0,1.51,11.25]],"ltp":1.51,"tv":552.27,"id":72922097}],"tv":573.53}]}
{"op":"mcm","clk":"11959902234","pt":1724584441712,"mc":[{"id":"1.232245129","rc":[{"batb":[[0,2.68,10.22],[1,2.62,40.91],[2,2.58,27.18]],"ltp":2.84,"tv":21.26,"id":67083366},{"batl":[[0,1.51,4.8]],"ltp":1.51,"tv":552.27,"id":72922097}]}]}
{"op":"mcm","clk":"11959902557","pt":1724584443406,"mc":[{"id":"1.232245129","rc":[{"batl":[[1,1.59,23.09],[2,1.6,1725.44]],"ltp":1.51,"tv":552.27,"id":72922097}]}]}
{"op":"mcm","clk":"11960072387","pt":1724585296202,"mc":[{"id":"1.232245129","rc":[{"trd":[[2.96,2]],"ltp":2.96,"tv":23.26,"id":67083366},{"trd":[[1.51,143.3]],"batl":[[0,1.59,23.97],[1,1.6,1725.44],[2,1.85,6.18]],"ltp":1.51,"tv":556.19,"id":72922097}],"tv":579.45}]}
{"op":"mcm","clk":"11960130278","pt":1724585582083,"mc":[{"id":"1.232245129","rc":[{"batb":[[1,1.41,16.76],[2,1.4,173.72]],"ltp":1.51,"tv":556.19,"id":72922097}]}]}
{"op":"mcm","clk":"11960136952","pt":1724585616159,"mc":[{"id":"1.232245129","rc":[{"batl":[[0,1.58,5.9],[1,1.59,23.09],[2,1.6,1725.44]],"ltp":1.51,"tv":556.19,"id":72922097}]}]}
{"op":"mcm","clk":"11960138190","pt":1724585622338,"mc":[{"id":"1.232245129","rc":[{"batl":[[0,1.59,23.97],[1,1.6,1725.44],[2,1.85,6.18]],"ltp":1.51,"tv":556.19,"id":72922097}]}]}
{"op":"mcm","clk":"11960376701","pt":1724586930260,"mc":[{"id":"1.232245129","rc":[{"trd":[[2.68,0.13],[2.96,2.45]],"batb":[[0,2.68,10.15]],"ltp":2.68,"tv":23.84,"id":67083366},{"trd":[[1.51,144.18]],"batl":[[0,1.59,23.09]],"ltp":1.51,"tv":557.07,"id":72922097}],"tv":580.91}]}
{"op":"mcm","clk":"11960505452","pt":1724587689212,"mc":[{"id":"1.232245129","rc":[{"batb":[[1,1.43,418.38],[2,1.41,16.76]],"ltp":1.51,"tv":557.07,"id":72922097}]}]}
{"op":"mcm","clk":"11960565550","pt":1724587981766,"mc":[{"id":"1.232245129","rc":[{"batb":[[1,1.41,16.76],[2,1.4,173.72]],"ltp":1.51,"tv":557.07,"id":72922097}]}]}
{"op":"mcm","clk":"11960693793","pt":1724588698709,"mc":[{"id":"1.232245129","rc":[{"batb":[[0,1.51,15.86],[1,1.5,85.9],[2,1.41,16.76]],"ltp":1.51,"tv":557.07,"id":72922097}]}]}
{"op":"mcm","clk":"11960923182","pt":1724589850233,"mc":[{"id":"1.232245129","rc":[{"batb":[[2,1.4,173.72]],"ltp":1.51,"tv":557.07,"id":72922097}]}]}
{"op":"mcm","clk":"11960995906","pt":1724590281541,"mc":[{"id":"1.232245129","rc":[{"batl":[[1,1.85,6.18],[2,2,1721.03]],"ltp":1.51,"tv":557.07,"id":72922097}]}]}
{"op":"mcm","clk":"11960996130","pt":1724590282956,"mc":[{"id":"1.232245129","rc":[{"batb":[[0,2.62,40.91],[1,2.58,27.18],[2,1.2,1250]],"ltp":2.68,"tv":23.84,"id":67083366},{"batl":[[0,1.59,16.96]],"ltp":1.51,"tv":557.07,"id":72922097}]}]}
{"op":"mcm","clk":"11960996376","pt":1724590284740,"mc":[{"id":"1.232245129","rc":[{"batl":[[0,1.61,6.06]],"ltp":1.51,"tv":557.07,"id":72922097}]}]}
{"op":"mcm","clk":"11961012171","pt":1724590393387,"mc":[{"id":"1.232245129","rc":[{"trd":[[1.51,144.2]],"batb":[[0,1.51,15.85]],"ltp":1.51,"tv":557.09,"id":72922097}],"tv":580.93}]}
{"op":"mcm","clk":"11961025331","pt":1724590495058,"mc":[{"id":"1.232245129","rc":[{"batl":[[0,1.61,11.48]],"ltp":1.51,"tv":557.09,"id":72922097}]}]}
{"op":"mcm","clk":"11961077852","pt":1724590851318,"mc":[{"id":"1.232245129","rc":[{"trd":[[1.61,0.05]],"batl":[[0,1.61,11.46]],"ltp":1.61,"tv":557.13,"id":72922097}],"tv":580.98}]}
{"op":"mcm","clk":"11961092652","pt":1724590936214,"mc":[{"id":"1.232245129","rc":[{"batl":[[0,1.61,12.22]],"ltp":1.61,"tv":557.13,"id":72922097}]}]}
{"op":"mcm","clk":"11961094178","pt":1724590945207,"mc":[{"id":"1.232245129","rc":[{"batb":[[0,1.51,16.77]],"ltp":1.61,"tv":557.13,"id":72922097}]}]}
{"op":"mcm","clk":"11961150360","pt":1724591275611,"mc":[{"id":"1.232245129","rc":[{"batb":[[0,1.54,16.76],[1,1.51,16.77],[2,1.5,85.9]],"ltp":1.61,"tv":557.13,"id":72922097}]}]}
{"op":"mcm","clk":"11961178083","pt":1724591430484,"mc":[{"id":"1.232245129","rc":[{"trd":[[2.62,1.44],[2.66,0.46]],"batb":[[0,2.62,40.19]],"ltp":2.62,"tv":25.74,"id":67083366},{"trd":[[1.6,11.42]],"batl":[[0,1.61,11.46]],"ltp":1.6,"tv":557.89,"id":72922097}],"tv":583.64}]}
{"op":"mcm","clk":"11961225964","pt":1724591686972,"mc":[{"id":"1.232245129","rc":[{"trd":[[2.62,2.26]],"batb":[[0,2.62,39.78]],"ltp":2.62,"tv":26.56,"id":67083366}],"tv":584.46}]}
{"op":"mcm","clk":"11961433882","pt":1724592914179,"mc":[{"id":"1.232245129","rc":[{"batb":[[1,2.58,24.33]],"ltp":2.62,"tv":26.56,"id":67083366},{"batb":[[2,1.5,76.89]],"ltp":1.6,"tv":557.89,"id":72922097}]}]}
{"op":"mcm","clk":"11961446139","pt":1724592985541,"mc":[{"id":"1.232245129","rc":[{"batb":[[0,1.54,17.53]],"ltp":1.6,"tv":557.89,"id":72922097}]}]}
{"op":"mcm","clk":"11961446677","pt":1724592988654,"mc":[{"id":"1.232245129","rc":[{"batb":[[1,1.51,15.85]],"ltp":1.6,"tv":557.89,"id":72922097}]}]}
{"op":"mcm","clk":"11961474733","pt":1724593153830,"mc":[{"id":"1.232245129","rc":[{"batb":[[1,1.5,76.89],[2,1.4,173.72]],"ltp":1.6,"tv":557.89,"id":72922097}]}]}
{"op":"mcm","clk":"11961696624","pt":1724594580265,"mc":[{"id":"1.232245129","rc":[{"batl":[[0,1.6,2],[1,1.61,11.46],[2,1.85,6.18]],"ltp":1.6,"tv":557.89,"id":72922097}]}]}
{"op":"mcm","clk":"11961721030","pt":1724594730647,"mc":[{"id":"1.232245129","rc":[{"batb":[[0,2.64,5],[1,2.62,39.78],[2,2.58,24.33]],"batl":[[0,5,0.51]],"ltp":2.62,"tv":26.56,"id":67083366}]}]}
{"op":"mcm","clk":"11961721590","pt":1724594733852,"mc":[{"id":"1.232245129","rc":[{"batb":[[0,2.62,39.78],[1,2.58,24.33],[2,1.2,1250]],"ltp":2.62,"tv":26.56,"id":67083366}]}]}
{"op":"mcm","clk":"11961727172","pt":1724594767808,"mc":[{"id":"1.232245129","rc":[{"batb":[[0,2.64,5],[1,2.62,39.78],[2,2.58,24.33]],"batl":[[0,60,1.03]],"ltp":2.62,"tv":26.56,"id":67083366}]}]}
{"op":"mcm","clk":"11961727658","pt":1724594771004,"mc":[{"id":"1.232245129","rc":[{"batb":[[0,2.62,39.78],[1,2.58,24.33],[2,1.2,1250]],"ltp":2.62,"tv":26.56,"id":67083366}]}]}
{"op":"mcm","clk":"11961728174","pt":1724594774099,"mc":[{"id":"1.232245129","rc":[{"batb":[[0,2.64,5],[1,2.62,39.78],[2,2.58,24.33]],"ltp":2.62,"tv":26.56,"id":67083366}]}]}
{"op":"mcm","clk":"11961728727","pt":1724594777514,"mc":[{"id":"1.232245129","rc":[{"batb":[[0,2.62,39.78],[1,2.58,24.33],[2,1.2,1250]],"ltp":2.62,"tv":26.56,"id":67083366}]}]}
{"op":"mcm","clk":"11961733705","pt":1724594808649,"mc":[{"id":"1.232245129","rc":[{"batb":[[0,2.64,5],[1,2.62,39.78],[2,2.58,24.33]],"batl":[[0,6,1.03],[1,60,0.51]],"ltp":2.62,"tv":26.56,"id":67083366}]}]}
{"op":"mcm","clk":"11961734188","pt":1724594811851,"mc":[{"id":"1.232245129","rc":[{"batb":[[0,2.62,39.78],[1,2.58,24.33],[2,1.2,1250]],"ltp":2.62,"tv":26.56,"id":67083366}]}]}
{"op":"mcm","clk":"11961737520","pt":1724594831277,"mc":[{"id":"1.232245129","rc":[{"batb":[[0,2.64,5],[1,2.62,39.78],[2,2.58,24.33]],"batl":[[1,70,1.03]],"ltp":2.62,"tv":26.56,"id":67083366}]}]}
{"op":"mcm","clk":"11961738095","pt":1724594834566,"mc":[{"id":"1.232245129","rc":[{"batb":[[0,2.62,39.78],[1,2.58,24.33],[2,1.2,1250]],"ltp":2.62,"tv":26.56,"id":67083366}]}]}
{"op":"mcm","clk":"11961746720","pt":1724594885336,"mc":[{"id":"1.232245129","rc":[{"batb":[[0,2.64,5],[1,2.62,39.78],[2,2.58,24.33]],"batl":[[2,80,0.51]],"ltp":2.62,"tv":26.56,"id":67083366}]}]}
{"op":"mcm","clk":"11961747282","pt":1724594888655,"mc":[{"id":"1.232245129","rc":[{"batb":[[0,2.62,39.78],[1,2.58,24.33],[2,1.2,1250]],"ltp":2.62,"tv":26.56,"id":67083366}]}]}
{"op":"mcm","clk":"11961755881","pt":1724594938513,"mc":[{"id":"1.232245129","rc":[{"batb":[[0,2.64,5],[1,2.62,39.78],[2,2.58,24.33]],"ltp":2.62,"tv":26.56,"id":67083366}]}]}
{"op":"mcm","clk":"11961756496","pt":1724594942017,"mc":[{"id":"1.232245129","rc":[{"batb":[[0,2.62,39.78],[1,2.58,24.33],[2,1.2,1250]],"ltp":2.62,"tv":26.56,"id":67083366}]}]}
{"op":"mcm","clk":"11961757052","pt":1724594945031,"mc":[{"id":"1.232245129","rc":[{"batb":[[0,2.64,5],[1,2.62,39.78],[2,2.58,24.33]],"batl":[[2,90,1.03]],"ltp":2.62,"tv":26.56,"id":67083366}]}]}
{"op":"mcm","clk":"11961757609","pt":1724594948419,"mc":[{"id":"1.232245129","rc":[{"batb":[[0,2.62,39.78],[1,2.58,24.33],[2,1.2,1250]],"ltp":2.62,"tv":26.56,"id":67083366}]}]}
{"op":"mcm","clk":"11961767500","pt":1724595008640,"mc":[{"id":"1.232245129","rc":[{"batb":[[0,2.64,5],[1,2.62,39.78],[2,2.58,24.33]],"batl":[[1,60,1.03],[2,80,1.03]],"ltp":2.62,"tv":26.56,"id":67083366}]}]}
{"op":"mcm","clk":"11961768098","pt":1724595011921,"mc":[{"id":"1.232245129","rc":[{"batb":[[0,2.62,39.78],[1,2.58,24.33],[2,1.2,1250]],"ltp":2.62,"tv":26.56,"id":67083366}]}]}
{"op":"mcm","clk":"11961769013","pt":1724595017224,"mc":[{"id":"1.232245129","rc":[{"batb":[[0,2.64,5],[1,2.62,39.78],[2,2.58,24.33]],"ltp":2.62,"tv":26.56,"id":67083366}]}]}
{"op":"mcm","clk":"11961769553","pt":1724595021058,"mc":[{"id":"1.232245129","rc":[{"batb":[[0,2.62,39.78],[1,2.58,24.33],[2,1.2,1250]],"ltp":2.62,"tv":26.56,"id":67083366}]}]}
{"op":"mcm","clk":"11961772797","pt":1724595039640,"mc":[{"id":"1.232245129","rc":[{"batb":[[0,2.64,5],[1,2.62,39.78],[2,2.58,24.33]],"ltp":2.62,"tv":26.56,"id":67083366}]}]}
{"op":"mcm","clk":"11961773356","pt":1724595042983,"mc":[{"id":"1.232245129","rc":[{"batb":[[0,2.62,39.78],[1,2.58,24.33],[2,1.2,1250]],"ltp":2.62,"tv":26.56,"id":67083366}]}]}
{"op":"mcm","clk":"11961776447","pt":1724595062175,"mc":[{"id":"1.232245129","rc":[{"batb":[[0,2.64,5],[1,2.62,39.78],[2,2.58,24.33]],"ltp":2.62,"tv":26.56,"id":67083366}]}]}
{"op":"mcm","clk":"11961777085","pt":1724595065568,"mc":[{"id":"1.232245129","rc":[{"batb":[[0,2.62,39.78],[1,2.58,24.33],[2,1.2,1250]],"ltp":2.62,"tv":26.56,"id":67083366}]}]}
{"op":"mcm","clk":"11961777214","pt":1724595066367,"mc":[{"id":"1.232245129","rc":[{"batl":[[1,11,1.03],[2,70,1.03]],"ltp":2.62,"tv":26.56,"id":67083366}]}]}
{"op":"mcm","clk":"11961787684","pt":1724595129182,"mc":[{"id":"1.232245129","rc":[{"batb":[[0,2.64,5],[1,2.62,39.78],[2,2.58,24.33]],"batl":[[2,60,1.03]],"ltp":2.62,"tv":26.56,"id":67083366}]}]}
{"op":"mcm","clk":"11961788242","pt":1724595132482,"mc":[{"id":"1.232245129","rc":[{"batb":[[0,2.62,39.78],[1,2.58,24.33],[2,1.2,1250]],"ltp":2.62,"tv":26.56,"id":67083366}]}]}
{"op":"mcm","clk":"11961792408","pt":1724595158309,"mc":[{"id":"1.232245129","rc":[{"batb":[[0,2.64,5],[1,2.62,39.78],[2,2.58,24.33]],"ltp":2.62,"tv":26.56,"id":67083366}]}]}
{"op":"mcm","clk":"11961792897","pt":1724595161644,"mc":[{"id":"1.232245129","rc":[{"batb":[[0,2.62,39.78],[1,2.58,24.33],[2,1.2,1250]],"ltp":2.62,"tv":26.56,"id":67083366}]}]}
{"op":"mcm","clk":"11961810306","pt":1724595181470,"mc":[{"id":"1.232245129","rc":[{"batb":[[0,2.64,5],[1,2.62,39.78],[2,2.58,24.33]],"ltp":2.62,"tv":26.56,"id":67083366}]}]}
{"op":"mcm","clk":"11961810866","pt":1724595184802,"mc":[{"id":"1.232245129","rc":[{"batb":[[0,2.62,39.78],[1,2.58,24.33],[2,1.2,1250]],"ltp":2.62,"tv":26.56,"id":67083366}]}]}
{"op":"mcm","clk":"11961813149","pt":1724595198218,"mc":[{"id":"1.232245129","rc":[{"batb":[[0,2.64,5],[1,2.62,39.78],[2,2.58,24.33]],"batl":[[2,13,1.03]],"ltp":2.62,"tv":26.56,"id":67083366}]}]}
{"op":"mcm","clk":"11961813719","pt":1724595201425,"mc":[{"id":"1.232245129","rc":[{"batb":[[0,2.62,39.78],[1,2.58,24.33],[2,1.2,1250]],"ltp":2.62,"tv":26.56,"id":67083366}]}]}
{"op":"mcm","clk":"11961821212","pt":1724595245758,"mc":[{"id":"1.232245129","rc":[{"batb":[[0,2.64,5],[1,2.62,39.78],[2,2.58,24.33]],"ltp":2.62,"tv":26.56,"id":67083366}]}]}
{"op":"mcm","clk":"11961821783","pt":1724595249092,"mc":[{"id":"1.232245129","rc":[{"batb":[[0,2.62,39.78],[1,2.58,24.33],[2,1.2,1250]],"ltp":2.62,"tv":26.56,"id":67083366}]}]}
{"op":"mcm","clk":"11961831964","pt":1724595306460,"mc":[{"id":"1.232245129","rc":[{"batb":[[0,2.64,5],[1,2.62,39.78],[2,2.58,24.33]],"ltp":2.62,"tv":26.56,"id":67083366}]}]}
{"op":"mcm","clk":"11961832688","pt":1724595309825,"mc":[{"id":"1.232245129","rc":[{"batb":[[0,2.62,39.78],[1,2.58,24.33],[2,1.2,1250]],"ltp":2.62,"tv":26.56,"id":67083366}]}]}
{"op":"mcm","clk":"11961836972","pt":1724595332941,"mc":[{"id":"1.232245129","rc":[{"batb":[[0,2.64,5],[1,2.62,39.78],[2,2.58,24.33]],"ltp":2.62,"tv":26.56,"id":67083366}]}]}
{"op":"mcm","clk":"11961837656","pt":1724595336200,"mc":[{"id":"1.232245129","rc":[{"batb":[[0,2.62,39.78],[1,2.58,24.33],[2,1.2,1250]],"ltp":2.62,"tv":26.56,"id":67083366}]}]}
{"op":"mcm","clk":"11961843084","pt":1724595366043,"mc":[{"id":"1.232245129","rc":[{"batb":[[0,2.64,5],[1,2.62,39.78],[2,2.58,24.33]],"ltp":2.62,"tv":26.56,"id":67083366}]}]}
{"op":"mcm","clk":"11961843743","pt":1724595369558,"mc":[{"id":"1.232245129","rc":[{"batb":[[0,2.62,39.78],[1,2.58,24.33],[2,1.2,1250]],"ltp":2.62,"tv":26.56,"id":67083366}]}]}
{"op":"mcm","clk":"11961854526","pt":1724595430535,"mc":[{"id":"1.232245129","rc":[{"batb":[[0,2.64,5],[1,2.62,39.78],[2,2.58,24.33]],"ltp":2.62,"tv":26.56,"id":67083366}]}]}
{"op":"mcm","clk":"11961855133","pt":1724595434036,"mc":[{"id":"1.232245129","rc":[{"batb":[[0,2.62,39.78],[1,2.58,24.33],[2,1.2,1250]],"ltp":2.62,"tv":26.56,"id":67083366}]}]}
{"op":"mcm","clk":"11961901060","pt":1724595694301,"mc":[{"id":"1.232245129","rc":[{"batb":[[0,2.64,9],[1,2.62,39.78],[2,2.58,24.33]],"batl":[[0,4,8.38],[1,6,1.03],[2,11,1.03]],"ltp":2.62,"tv":26.56,"id":67083366}]}]}
{"op":"mcm","clk":"11961901504","pt":1724595696597,"mc":[{"id":"1.232245129","rc":[{"batb":[[0,2.64,5]],"ltp":2.62,"tv":26.56,"id":67083366}]}]}
{"op":"mcm","clk":"11961901685","pt":1724595697492,"mc":[{"id":"1.232245129","rc":[{"batb":[[0,2.62,39.78],[1,2.58,24.33],[2,1.2,1250]],"ltp":2.62,"tv":26.56,"id":67083366}]}]}
{"op":"mcm","clk":"11961926483","pt":1724595841951,"mc":[{"id":"1.232245129","rc":[{"batb":[[0,2.64,9],[1,2.62,39.78],[2,2.58,24.33]],"ltp":2.62,"tv":26.56,"id":67083366}]}]}
{"op":"mcm","clk":"11961927117","pt":1724595845264,"mc":[{"id":"1.232245129","rc":[{"batb":[[0,2.62,39.78],[1,2.58,24.33],[2,1.2,1250]],"ltp":2.62,"tv":26.56,"id":67083366}]}]}
{"op":"mcm","clk":"11961930495","pt":1724595864989,"mc":[{"id":"1.232245129","rc":[{"batb":[[0,2.64,9],[1,2.62,39.78],[2,2.58,24.33]],"ltp":2.62,"tv":26.56,"id":67083366}]}]}
{"op":"mcm","clk":"11961930882","pt":1724595867605,"mc":[{"id":"1.232245129","rc":[{"batb":[[0,2.64,5]],"ltp":2.62,"tv":26.56,"id":67083366}]}]}
{"op":"mcm","clk":"11961931046","pt":1724595868510,"mc":[{"id":"1.232245129","rc":[{"batb":[[0,2.62,39.78],[1,2.58,24.33],[2,1.2,1250]],"ltp":2.62,"tv":26.56,"id":67083366}]}]}
{"op":"mcm","clk":"11961966775","pt":1724596071656,"mc":[{"id":"1.232245129","rc":[{"batb":[[0,2.64,9],[1,2.62,39.78],[2,2.58,24.33]],"ltp":2.62,"tv":26.56,"id":67083366}]}]}
{"op":"mcm","clk":"11961967191","pt":1724596073867,"mc":[{"id":"1.232245129","rc":[{"batb":[[0,2.64,5]],"ltp":2.62,"tv":26.56,"id":67083366}]}]}
{"op":"mcm","clk":"11961967368","pt":1724596074972,"mc":[{"id":"1.232245129","rc":[{"batb":[[0,2.62,39.78],[1,2.58,24.33],[2,1.2,1250]],"ltp":2.62,"tv":26.56,"id":67083366}]}]}
{"op":"mcm","clk":"11961989678","pt":1724596202035,"mc":[{"id":"1.232245129","rc":[{"batb":[[0,2.62,50.77]],"ltp":2.62,"tv":26.56,"id":67083366},{"batb":[[1,1.5,112.51]],"ltp":1.6,"tv":557.89,"id":72922097}]}]}
{"op":"mcm","clk":"11961989827","pt":1724596202681,"mc":[{"id":"1.232245129","rc":[{"batb":[[0,2.64,9],[1,2.62,50.77],[2,2.58,24.33]],"ltp":2.62,"tv":26.56,"id":67083366}]}]}
{"op":"mcm","clk":"11961990360","pt":1724596204836,"mc":[{"id":"1.232245129","rc":[{"batb":[[0,2.64,5]],"ltp":2.62,"tv":26.56,"id":67083366}]}]}
{"op":"mcm","clk":"11961990629","pt":1724596205957,"mc":[{"id":"1.232245129","rc":[{"batb":[[0,2.62,50.77],[1,2.58,24.33],[2,1.2,1250]],"ltp":2.62,"tv":26.56,"id":67083366}]}]}
{"op":"mcm","clk":"11961990922","pt":1724596207453,"mc":[{"id":"1.232245129","rc":[{"batb":[[0,2.64,4],[1,2.62,50.77],[2,2.58,24.33]],"ltp":2.62,"tv":26.56,"id":67083366},{"batl":[[1,1.61,6.03]],"ltp":1.6,"tv":557.89,"id":72922097}]}]}
{"op":"mcm","clk":"11961991420","pt":1724596209890,"mc":[{"id":"1.232245129","rc":[{"batb":[[0,2.64,5]],"ltp":2.62,"tv":26.56,"id":67083366}]}]}
{"op":"mcm","clk":"11961992130","pt":1724596213286,"mc":[{"id":"1.232245129","rc":[{"batb":[[0,2.64,4]],"ltp":2.62,"tv":26.56,"id":67083366}]}]}
{"op":"mcm","clk":"11961992575","pt":1724596215615,"mc":[{"id":"1.232245129","rc":[{"batb":[[0,2.64,5]],"ltp":2.62,"tv":26.56,"id":67083366}]}]}
{"op":"mcm","clk":"11961993245","pt":1724596218996,"mc":[{"id":"1.232245129","rc":[{"batb":[[0,2.64,4]],"ltp":2.62,"tv":26.56,"id":67083366}]}]}
{"op":"mcm","clk":"11961993691","pt":1724596221274,"mc":[{"id":"1.232245129","rc":[{"batb":[[0,2.62,50.77],[1,2.58,24.33],[2,1.2,1250]],"ltp":2.62,"tv":26.56,"id":67083366}]}]}
{"op":"mcm","clk":"11961993733","pt":1724596221489,"mc":[{"id":"1.232245129","rc":[{"batb":[[0,2.64,5],[1,2.62,50.77],[2,2.58,24.33]],"ltp":2.62,"tv":26.56,"id":67083366}]}]}
{"op":"mcm","clk":"11961994360","pt":1724596224815,"mc":[{"id":"1.232245129","rc":[{"batb":[[0,2.64,4]],"ltp":2.62,"tv":26.56,"id":67083366}]}]}
{"op":"mcm","clk":"11961994827","pt":1724596227202,"mc":[{"id":"1.232245129","rc":[{"batb":[[0,2.64,5]],"ltp":2.62,"tv":26.56,"id":67083366}]}]}
{"op":"mcm","clk":"11961995558","pt":1724596230580,"mc":[{"id":"1.232245129","rc":[{"batb":[[0,2.64,4]],"ltp":2.62,"tv":26.56,"id":67083366}]}]}
{"op":"mcm","clk":"11961996059","pt":1724596233022,"mc":[{"id":"1.232245129","rc":[{"batb":[[0,2.64,5]],"ltp":2.62,"tv":26.56,"id":67083366}]}]}
{"op":"mcm","clk":"11961996690","pt":1724596236252,"mc":[{"id":"1.232245129","rc":[{"batb":[[0,2.62,50.77],[1,2.58,24.33],[2,1.2,1250]],"ltp":2.62,"tv":26.56,"id":67083366}]}]}
{"op":"mcm","clk":"11961996732","pt":1724596236424,"mc":[{"id":"1.232245129","rc":[{"batb":[[0,2.64,4],[1,2.62,50.77],[2,2.58,24.33]],"ltp":2.62,"tv":26.56,"id":67083366}]}]}
{"op":"mcm","clk":"11961997193","pt":1724596238755,"mc":[{"id":"1.232245129","rc":[{"batb":[[0,2.64,5]],"ltp":2.62,"tv":26.56,"id":67083366}]}]}
{"op":"mcm","clk":"11961997879","pt":1724596242019,"mc":[{"id":"1.232245129","rc":[{"batb":[[0,2.64,4]],"ltp":2.62,"tv":26.56,"id":67083366}]}]}
{"op":"mcm","clk":"11961998495","pt":1724596244837,"mc":[{"id":"1.232245129","rc":[{"batb":[[0,2.64,5]],"ltp":2.62,"tv":26.56,"id":67083366}]}]}
{"op":"mcm","clk":"11961999126","pt":1724596248317,"mc":[{"id":"1.232245129","rc":[{"batb":[[0,2.64,4]],"ltp":2.62,"tv":26.56,"id":67083366}]}]}
{"op":"mcm","clk":"11961999596","pt":1724596250634,"mc":[{"id":"1.232245129","rc":[{"batb":[[0,2.64,5]],"ltp":2.62,"tv":26.56,"id":67083366}]}]}
{"op":"mcm","clk":"11962000266","pt":1724596254176,"mc":[{"id":"1.232245129","rc":[{"batb":[[0,2.64,4]],"ltp":2.62,"tv":26.56,"id":67083366}]}]}
{"op":"mcm","clk":"11962000725","pt":1724596256648,"mc":[{"id":"1.232245129","rc":[{"batb":[[0,2.64,5]],"ltp":2.62,"tv":26.56,"id":67083366}]}]}
{"op":"mcm","clk":"11962001309","pt":1724596259992,"mc":[{"id":"1.232245129","rc":[{"batb":[[0,2.64,4]],"ltp":2.62,"tv":26.56,"id":67083366}]}]}
{"op":"mcm","clk":"11962001787","pt":1724596262272,"mc":[{"id":"1.232245129","rc":[{"batb":[[0,2.64,5]],"ltp":2.62,"tv":26.56,"id":67083366}]}]}
{"op":"mcm","clk":"11962002546","pt":1724596265753,"mc":[{"id":"1.232245129","rc":[{"batb":[[0,2.64,4]],"ltp":2.62,"tv":26.56,"id":67083366}]}]}
{"op":"mcm","clk":"11962003001","pt":1724596268091,"mc":[{"id":"1.232245129","rc":[{"batb":[[0,2.64,5]],"ltp":2.62,"tv":26.56,"id":67083366}]}]}
{"op":"mcm","clk":"11962003568","pt":1724596271258,"mc":[{"id":"1.232245129","rc":[{"batb":[[0,2.62,50.77],[1,2.58,24.33],[2,1.2,1250]],"ltp":2.62,"tv":26.56,"id":67083366}]}]}
{"op":"mcm","clk":"11962003659","pt":1724596271780,"mc":[{"id":"1.232245129","rc":[{"batb":[[0,2.64,4],[1,2.62,50.77],[2,2.58,24.33]],"batl":[[0,4,8.89]],"ltp":2.62,"tv":26.56,"id":67083366}]}]}
{"op":"mcm","clk":"11962003985","pt":1724596273702,"mc":[{"id":"1.232245129","rc":[{"batb":[[0,2.64,5]],"ltp":2.62,"tv":26.56,"id":67083366}]}]}
{"op":"mcm","clk":"11962004609","pt":1724596277217,"mc":[{"id":"1.232245129","rc":[{"batb":[[0,2.64,4]],"ltp":2.62,"tv":26.56,"id":67083366}]}]}
{"op":"mcm","clk":"11962005028","pt":1724596279332,"mc":[{"id":"1.232245129","rc":[{"batb":[[0,2.62,50.77],[1,2.58,24.33],[2,1.2,1250]],"ltp":2.62,"tv":26.56,"id":67083366}]}]}
{"op":"mcm","clk":"11962005134","pt":1724596279803,"mc":[{"id":"1.232245129","rc":[{"batb":[[0,2.64,5],[1,2.62,50.77],[2,2.58,24.33]],"ltp":2.62,"tv":26.56,"id":67083366}]}]}
{"op":"mcm","clk":"11962005814","pt":1724596283304,"mc":[{"id":"1.232245129","rc":[{"batb":[[0,2.64,4]],"ltp":2.62,"tv":26.56,"id":67083366}]}]}
{"op":"mcm","clk":"11962006304","pt":1724596285799,"mc":[{"id":"1.232245129","rc":[{"batb":[[0,2.64,5]],"ltp":2.62,"tv":26.56,"id":67083366}]}]}
{"op":"mcm","clk":"11962006980","pt":1724596289290,"mc":[{"id":"1.232245129","rc":[{"batb":[[0,2.64,4]],"ltp":2.62,"tv":26.56,"id":67083366}]}]}
{"op":"mcm","clk":"11962007449","pt":1724596291592,"mc":[{"id":"1.232245129","rc":[{"batb":[[0,2.64,5]],"ltp":2.62,"tv":26.56,"id":67083366}]}]}
{"op":"mcm","clk":"11962008110","pt":1724596295113,"mc":[{"id":"1.232245129","rc":[{"batb":[[0,2.64,4]],"ltp":2.62,"tv":26.56,"id":67083366}]}]}
{"op":"mcm","clk":"11962008536","pt":1724596297328,"mc":[{"id":"1.232245129","rc":[{"batb":[[0,2.62,50.77],[1,2.58,24.33],[2,1.2,1250]],"ltp":2.62,"tv":26.56,"id":67083366}]}]}
{"op":"mcm","clk":"11962008582","pt":1724596297510,"mc":[{"id":"1.232245129","rc":[{"batb":[[0,2.64,5],[1,2.62,50.77],[2,2.58,24.33]],"ltp":2.62,"tv":26.56,"id":67083366}]}]}
{"op":"mcm","clk":"11962009241","pt":1724596300830,"mc":[{"id":"1.232245129","rc":[{"batb":[[0,2.64,4]],"ltp":2.62,"tv":26.56,"id":67083366}]}]}
{"op":"mcm","clk":"11962009685","pt":1724596303148,"mc":[{"id":"1.232245129","rc":[{"batb":[[0,2.64,5]],"ltp":2.62,"tv":26.56,"id":67083366}]}]}
{"op":"mcm","clk":"11962010448","pt":1724596306641,"mc":[{"id":"1.232245129","rc":[{"batb":[[0,2.64,4]],"ltp":2.62,"tv":26.56,"id":67083366}]}]}
{"op":"mcm","clk":"11962010890","pt":1724596308842,"mc":[{"id":"1.232245129","rc":[{"batb":[[0,2.64,5]],"ltp":2.62,"tv":26.56,"id":67083366}]}]}
{"op":"mcm","clk":"11962011537","pt":1724596312124,"mc":[{"id":"1.232245129","rc":[{"batb":[[0,2.64,4]],"ltp":2.62,"tv":26.56,"id":67083366}]}]}
{"op":"mcm","clk":"11962012048","pt":1724596314743,"mc":[{"id":"1.232245129","rc":[{"batb":[[0,2.64,5]],"ltp":2.62,"tv":26.56,"id":67083366}]}]}
{"op":"mcm","clk":"11962012732","pt":1724596318337,"mc":[{"id":"1.232245129","rc":[{"batb":[[0,2.64,4]],"ltp":2.62,"tv":26.56,"id":67083366}]}]}
{"op":"mcm","clk":"11962013191","pt":1724596320675,"mc":[{"id":"1.232245129","rc":[{"batb":[[0,2.64,5]],"ltp":2.62,"tv":26.56,"id":67083366}]}]}
{"op":"mcm","clk":"11962013865","pt":1724596324038,"mc":[{"id":"1.232245129","rc":[{"batb":[[0,2.64,4]],"ltp":2.62,"tv":26.56,"id":67083366}]}]}
{"op":"mcm","clk":"11962014252","pt":1724596326248,"mc":[{"id":"1.232245129","rc":[{"batb":[[0,2.62,50.77],[1,2.58,24.33],[2,1.2,1250]],"ltp":2.62,"tv":26.56,"id":67083366}]}]}
{"op":"mcm","clk":"11962014271","pt":1724596326356,"mc":[{"id":"1.232245129","rc":[{"batb":[[0,2.64,5],[1,2.62,50.77],[2,2.58,24.33]],"ltp":2.62,"tv":26.56,"id":67083366}]}]}
{"op":"mcm","clk":"11962014929","pt":1724596329654,"mc":[{"id":"1.232245129","rc":[{"batb":[[0,2.64,4]],"ltp":2.62,"tv":26.56,"id":67083366}]}]}
{"op":"mcm","clk":"11962015436","pt":1724596332257,"mc":[{"id":"1.232245129","rc":[{"batb":[[0,2.64,5]],"ltp":2.62,"tv":26.56,"id":67083366}]}]}
{"op":"mcm","clk":"11962016212","pt":1724596335852,"mc":[{"id":"1.232245129","rc":[{"batb":[[0,2.64,4]],"ltp":2.62,"tv":26.56,"id":67083366}]}]}
{"op":"mcm","clk":"11962016692","pt":1724596338298,"mc":[{"id":"1.232245129","rc":[{"batb":[[0,2.64,5]],"ltp":2.62,"tv":26.56,"id":67083366}]}]}
{"op":"mcm","clk":"11962017447","pt":1724596341880,"mc":[{"id":"1.232245129","rc":[{"batb":[[0,2.64,4]],"ltp":2.62,"tv":26.56,"id":67083366}]}]}
{"op":"mcm","clk":"11962017940","pt":1724596344327,"mc":[{"id":"1.232245129","rc":[{"batb":[[0,2.62,50.77],[1,2.58,24.33],[2,1.2,1250]],"ltp":2.62,"tv":26.56,"id":67083366}]}]}
{"op":"mcm","clk":"11962017994","pt":1724596344487,"mc":[{"id":"1.232245129","rc":[{"batb":[[0,2.64,5],[1,2.62,50.77],[2,2.58,24.33]],"ltp":2.62,"tv":26.56,"id":67083366}]}]}
{"op":"mcm","clk":"11962018695","pt":1724596347880,"mc":[{"id":"1.232245129","rc":[{"batb":[[0,2.64,4]],"ltp":2.62,"tv":26.56,"id":67083366}]}]}
{"op":"mcm","clk":"11962019200","pt":1724596350270,"mc":[{"id":"1.232245129","rc":[{"batb":[[0,2.62,50.77],[1,2.58,24.33],[2,1.2,1250]],"ltp":2.62,"tv":26.56,"id":67083366}]}]}
{"op":"mcm","clk":"11962019240","pt":1724596350373,"mc":[{"id":"1.232245129","rc":[{"batb":[[0,2.64,5],[1,2.62,50.77],[2,2.58,24.33]],"ltp":2.62,"tv":26.56,"id":67083366}]}]}
{"op":"mcm","clk":"11962020051","pt":1724596353928,"mc":[{"id":"1.232245129","rc":[{"batb":[[0,2.64,4]],"ltp":2.62,"tv":26.56,"id":67083366}]}]}
{"op":"mcm","clk":"11962020519","pt":1724596356296,"mc":[{"id":"1.232245129","rc":[{"batb":[[0,2.64,5]],"ltp":2.62,"tv":26.56,"id":67083366}]}]}
{"op":"mcm","clk":"11962021280","pt":1724596359794,"mc":[{"id":"1.232245129","rc":[{"batb":[[0,2.64,4]],"ltp":2.62,"tv":26.56,"id":67083366}]}]}
{"op":"mcm","clk":"11962021713","pt":1724596362137,"mc":[{"id":"1.232245129","rc":[{"batb":[[0,2.62,50.77],[1,2.58,24.33],[2,1.2,1250]],"ltp":2.62,"tv":26.56,"id":67083366}]}]}
{"op":"mcm","clk":"11962021747","pt":1724596362339,"mc":[{"id":"1.232245129","rc":[{"batb":[[0,2.64,5],[1,2.62,50.77],[2,2.58,24.33]],"ltp":2.62,"tv":26.56,"id":67083366}]}]}
{"op":"mcm","clk":"11962022445","pt":1724596365823,"mc":[{"id":"1.232245129","rc":[{"batb":[[0,2.64,4]],"ltp":2.62,"tv":26.56,"id":67083366}]}]}
{"op":"mcm","clk":"11962022920","pt":1724596368253,"mc":[{"id":"1.232245129","rc":[{"batb":[[0,2.64,5]],"ltp":2.62,"tv":26.56,"id":67083366}]}]}
{"op":"mcm","clk":"11962023673","pt":1724596371722,"mc":[{"id":"1.232245129","rc":[{"batb":[[0,2.64,4]],"ltp":2.62,"tv":26.56,"id":67083366}]}]}
{"op":"mcm","clk":"11962024130","pt":1724596374155,"mc":[{"id":"1.232245129","rc":[{"batb":[[0,2.62,50.77],[1,2.58,24.33],[2,1.2,1250]],"ltp":2.62,"tv":26.56,"id":67083366}]}]}
{"op":"mcm","clk":"11962024172","pt":1724596374350,"mc":[{"id":"1.232245129","rc":[{"batb":[[0,2.64,5],[1,2.62,50.77],[2,2.58,24.33]],"ltp":2.62,"tv":26.56,"id":67083366}]}]}
{"op":"mcm","clk":"11962024822","pt":1724596377843,"mc":[{"id":"1.232245129","rc":[{"batb":[[0,2.64,4]],"ltp":2.62,"tv":26.56,"id":67083366}]}]}
{"op":"mcm","clk":"11962025289","pt":1724596380151,"mc":[{"id":"1.232245129","rc":[{"batb":[[0,2.62,50.77],[1,2.58,24.33],[2,1.2,1250]],"ltp":2.62,"tv":26.56,"id":67083366}]}]}
{"op":"mcm","clk":"11962025331","pt":1724596380362,"mc":[{"id":"1.232245129","rc":[{"batb":[[0,2.64,5],[1,2.62,50.77],[2,2.58,24.33]],"ltp":2.62,"tv":26.56,"id":67083366}]}]}
{"op":"mcm","clk":"11962026066","pt":1724596383868,"mc":[{"id":"1.232245129","rc":[{"batb":[[0,2.64,4]],"ltp":2.62,"tv":26.56,"id":67083366}]}]}
{"op":"mcm","clk":"11962026558","pt":1724596386329,"mc":[{"id":"1.232245129","rc":[{"batb":[[0,2.64,5]],"ltp":2.62,"tv":26.56,"id":67083366}]}]}
{"op":"mcm","clk":"11962027300","pt":1724596389875,"mc":[{"id":"1.232245129","rc":[{"batb":[[0,2.64,4]],"ltp":2.62,"tv":26.56,"id":67083366}]}]}
{"op":"mcm","clk":"11962027787","pt":1724596392283,"mc":[{"id":"1.232245129","rc":[{"batb":[[0,2.62,50.77],[1,2.58,24.33],[2,1.2,1250]],"ltp":2.62,"tv":26.56,"id":67083366}]}]}
{"op":"mcm","clk":"11962027830","pt":1724596392450,"mc":[{"id":"1.232245129","rc":[{"batb":[[0,2.64,5],[1,2.62,50.77],[2,2.58,24.33]],"ltp":2.62,"tv":26.56,"id":67083366}]}]}
{"op":"mcm","clk":"11962028516","pt":1724596395976,"mc":[{"id":"1.232245129","rc":[{"batb":[[0,2.64,4]],"ltp":2.62,"tv":26.56,"id":67083366}]}]}
{"op":"mcm","clk":"11962029092","pt":1724596398663,"mc":[{"id":"1.232245129","rc":[{"batb":[[0,2.64,5]],"ltp":2.62,"tv":26.56,"id":67083366}]}]}
{"op":"mcm","clk":"11962029873","pt":1724596401977,"mc":[{"id":"1.232245129","rc":[{"batb":[[0,2.64,4]],"ltp":2.62,"tv":26.56,"id":67083366}]}]}
{"op":"mcm","clk":"11962030355","pt":1724596404056,"mc":[{"id":"1.232245129","rc":[{"batb":[[0,2.62,50.77],[1,2.58,24.33],[2,1.2,1250]],"ltp":2.62,"tv":26.56,"id":67083366}]}]}
{"op":"mcm","clk":"11962030537","pt":1724596404962,"mc":[{"id":"1.232245129","rc":[{"batb":[[0,2.64,5],[1,2.62,50.77],[2,2.58,24.33]],"batl":[[0,3.3,1.03],[1,4,8.38],[2,6,1.03]],"ltp":2.62,"tv":26.56,"id":67083366}]}]}
{"op":"mcm","clk":"11962031118","pt":1724596407885,"mc":[{"id":"1.232245129","rc":[{"batb":[[0,2.64,4]],"ltp":2.62,"tv":26.56,"id":67083366}]}]}
{"op":"mcm","clk":"11962031584","pt":1724596410246,"mc":[{"id":"1.232245129","rc":[{"batb":[[0,2.64,5]],"ltp":2.62,"tv":26.56,"id":67083366}]}]}
{"op":"mcm","clk":"11962032314","pt":1724596413793,"mc":[{"id":"1.232245129","rc":[{"batb":[[0,2.64,4]],"ltp":2.62,"tv":26.56,"id":67083366}]}]}
{"op":"mcm","clk":"11962032816","pt":1724596416207,"mc":[{"id":"1.232245129","rc":[{"batb":[[0,2.64,5]],"ltp":2.62,"tv":26.56,"id":67083366}]}]}
{"op":"mcm","clk":"11962033634","pt":1724596419691,"mc":[{"id":"1.232245129","rc":[{"batb":[[0,2.64,4]],"ltp":2.62,"tv":26.56,"id":67083366}]}]}
{"op":"mcm","clk":"11962034148","pt":1724596422071,"mc":[{"id":"1.232245129","rc":[{"batb":[[0,2.64,5]],"ltp":2.62,"tv":26.56,"id":67083366}]}]}
{"op":"mcm","clk":"11962034827","pt":1724596425326,"mc":[{"id":"1.232245129","rc":[{"batb":[[0,2.62,50.77],[1,2.58,24.33],[2,1.2,1250]],"ltp":2.62,"tv":26.56,"id":67083366}]}]}
{"op":"mcm","clk":"11962034929","pt":1724596425805,"mc":[{"id":"1.232245129","rc":[{"batb":[[0,2.64,4],[1,2.62,50.77],[2,2.58,24.33]],"ltp":2.62,"tv":26.56,"id":67083366}]}]}
{"op":"mcm","clk":"11962035496","pt":1724596428283,"mc":[{"id":"1.232245129","rc":[{"batb":[[0,2.64,5]],"ltp":2.62,"tv":26.56,"id":67083366}]}]}
{"op":"mcm","clk":"11962036286","pt":1724596431818,"mc":[{"id":"1.232245129","rc":[{"batb":[[0,2.64,4]],"ltp":2.62,"tv":26.56,"id":67083366}]}]}
{"op":"mcm","clk":"11962036751","pt":1724596434299,"mc":[{"id":"1.232245129","rc":[{"batb":[[0,2.64,5]],"ltp":2.62,"tv":26.56,"id":67083366}]}]}
{"op":"mcm","clk":"11962037513","pt":1724596437812,"mc":[{"id":"1.232245129","rc":[{"batb":[[0,2.64,4]],"ltp":2.62,"tv":26.56,"id":67083366}]}]}
{"op":"mcm","clk":"11962037969","pt":1724596440071,"mc":[{"id":"1.232245129","rc":[{"batb":[[0,2.64,5]],"ltp":2.62,"tv":26.56,"id":67083366}]}]}
{"op":"mcm","clk":"11962038711","pt":1724596443490,"mc":[{"id":"1.232245129","rc":[{"batb":[[0,2.64,4]],"ltp":2.62,"tv":26.56,"id":67083366}]}]}
{"op":"mcm","clk":"11962039299","pt":1724596445985,"mc":[{"id":"1.232245129","rc":[{"batb":[[0,2.64,5]],"ltp":2.62,"tv":26.56,"id":67083366}]}]}
{"op":"mcm","clk":"11962039997","pt":1724596449314,"mc":[{"id":"1.232245129","rc":[{"batb":[[0,2.62,50.77],[1,2.58,24.33],[2,1.2,1250]],"ltp":2.62,"tv":26.56,"id":67083366}]}]}
{"op":"mcm","clk":"11962040016","pt":1724596449411,"mc":[{"id":"1.232245129","rc":[{"batb":[[0,2.64,4],[1,2.62,50.77],[2,2.58,24.33]],"ltp":2.62,"tv":26.56,"id":67083366}]}]}
{"op":"mcm","clk":"11962040548","pt":1724596451823,"mc":[{"id":"1.232245129","rc":[{"batb":[[0,2.64,5]],"ltp":2.62,"tv":26.56,"id":67083366}]}]}
{"op":"mcm","clk":"11962041280","pt":1724596455213,"mc":[{"id":"1.232245129","rc":[{"batb":[[0,2.64,4]],"ltp":2.62,"tv":26.56,"id":67083366}]}]}
{"op":"mcm","clk":"11962041799","pt":1724596457702,"mc":[{"id":"1.232245129","rc":[{"batb":[[0,2.64,5]],"ltp":2.62,"tv":26.56,"id":67083366}]}]}
{"op":"mcm","clk":"11962042471","pt":1724596461236,"mc":[{"id":"1.232245129","rc":[{"batb":[[0,2.64,4]],"ltp":2.62,"tv":26.56,"id":67083366}]}]}
{"op":"mcm","clk":"11962042941","pt":1724596463630,"mc":[{"id":"1.232245129","rc":[{"batb":[[0,2.64,5]],"ltp":2.62,"tv":26.56,"id":67083366}]}]}
{"op":"mcm","clk":"11962043644","pt":1724596467242,"mc":[{"id":"1.232245129","rc":[{"batb":[[0,2.64,4]],"ltp":2.62,"tv":26.56,"id":67083366}]}]}
{"op":"mcm","clk":"11962044087","pt":1724596469565,"mc":[{"id":"1.232245129","rc":[{"batb":[[0,2.64,5]],"ltp":2.62,"tv":26.56,"id":67083366}]}]}
{"op":"mcm","clk":"11962044844","pt":1724596473170,"mc":[{"id":"1.232245129","rc":[{"batb":[[0,2.64,4]],"ltp":2.62,"tv":26.56,"id":67083366}]}]}
{"op":"mcm","clk":"11962045338","pt":1724596475557,"mc":[{"id":"1.232245129","rc":[{"batb":[[0,2.64,5]],"ltp":2.62,"tv":26.56,"id":67083366}]}]}
{"op":"mcm","clk":"11962046033","pt":1724596478946,"mc":[{"id":"1.232245129","rc":[{"batb":[[0,2.64,4]],"ltp":2.62,"tv":26.56,"id":67083366}]}]}
{"op":"mcm","clk":"11962046504","pt":1724596481479,"mc":[{"id":"1.232245129","rc":[{"batb":[[0,2.64,5]],"ltp":2.62,"tv":26.56,"id":67083366}]}]}
{"op":"mcm","clk":"11962047162","pt":1724596485180,"mc":[{"id":"1.232245129","rc":[{"batb":[[0,2.64,4]],"ltp":2.62,"tv":26.56,"id":67083366}]}]}
{"op":"mcm","clk":"11962047643","pt":1724596487991,"mc":[{"id":"1.232245129","rc":[{"batb":[[0,2.64,5]],"ltp":2.62,"tv":26.56,"id":67083366}]}]}
{"op":"mcm","clk":"11962048273","pt":1724596491276,"mc":[{"id":"1.232245129","rc":[{"batb":[[0,2.62,50.77],[1,2.58,24.33],[2,1.2,1250]],"ltp":2.62,"tv":26.56,"id":67083366}]}]}
{"op":"mcm","clk":"11962048307","pt":1724596491492,"mc":[{"id":"1.232245129","rc":[{"batb":[[0,2.64,4],[1,2.62,50.77],[2,2.58,24.33]],"ltp":2.62,"tv":26.56,"id":67083366}]}]}
{"op":"mcm","clk":"11962048789","pt":1724596493877,"mc":[{"id":"1.232245129","rc":[{"batb":[[0,2.64,5]],"ltp":2.62,"tv":26.56,"id":67083366}]}]}
{"op":"mcm","clk":"11962049382","pt":1724596497303,"mc":[{"id":"1.232245129","rc":[{"batb":[[0,2.62,50.77],[1,2.58,24.33],[2,1.2,1250]],"ltp":2.62,"tv":26.56,"id":67083366}]}]}
{"op":"mcm","clk":"11962049417","pt":1724596497457,"mc":[{"id":"1.232245129","rc":[{"batb":[[0,2.64,4],[1,2.62,50.77],[2,2.58,24.33]],"ltp":2.62,"tv":26.56,"id":67083366}]}]}
{"op":"mcm","clk":"11962049871","pt":1724596500068,"mc":[{"id":"1.232245129","rc":[{"batb":[[0,2.64,5]],"ltp":2.62,"tv":26.56,"id":67083366}]}]}
{"op":"mcm","clk":"11962050465","pt":1724596503293,"mc":[{"id":"1.232245129","rc":[{"batb":[[0,2.64,4]],"ltp":2.62,"tv":26.56,"id":67083366}]}]}
{"op":"mcm","clk":"11962050930","pt":1724596505784,"mc":[{"id":"1.232245129","rc":[{"batb":[[0,2.64,5]],"ltp":2.62,"tv":26.56,"id":67083366}]}]}
{"op":"mcm","clk":"11962051457","pt":1724596508293,"mc":[{"id":"1.232245129","rc":[{"batl":[[1,4,8.89]],"ltp":2.62,"tv":26.56,"id":67083366}]}]}
{"op":"mcm","clk":"11962051628","pt":1724596509179,"mc":[{"id":"1.232245129","rc":[{"batb":[[0,2.66,4]],"ltp":2.62,"tv":26.56,"id":67083366}]}]}
{"op":"mcm","clk":"11962051939","pt":1724596510673,"mc":[{"id":"1.232245129","rc":[{"batb":[[0,2.62,50.77],[1,2.58,24.33],[2,1.2,1250]],"ltp":2.62,"tv":26.56,"id":67083366}]}]}
{"op":"mcm","clk":"11962079296","pt":1724596652231,"mc":[{"id":"1.232245129","rc":[{"batb":[[0,2.64,9],[1,2.62,50.77],[2,2.58,24.33]],"ltp":2.62,"tv":26.56,"id":67083366}]}]}
{"op":"mcm","clk":"11962079815","pt":1724596653859,"mc":[{"id":"1.232245129","rc":[{"batb":[[0,2.64,5]],"ltp":2.62,"tv":26.56,"id":67083366}]}]}
{"op":"mcm","clk":"11962080025","pt":1724596654860,"mc":[{"id":"1.232245129","rc":[{"batb":[[0,2.62,50.77],[1,2.58,24.33],[2,1.2,1250]],"ltp":2.62,"tv":26.56,"id":67083366}]}]}
{"op":"mcm","clk":"11962082768","pt":1724596668451,"mc":[{"id":"1.232245129","rc":[{"batb":[[0,2.64,9],[1,2.62,50.77],[2,2.58,24.33]],"ltp":2.62,"tv":26.56,"id":67083366}]}]}
{"op":"mcm","clk":"11962083216","pt":1724596670855,"mc":[{"id":"1.232245129","rc":[{"batb":[[0,2.64,5]],"ltp":2.62,"tv":26.56,"id":67083366}]}]}
{"op":"mcm","clk":"11962083407","pt":1724596671757,"mc":[{"id":"1.232245129","rc":[{"batb":[[0,2.62,50.77],[1,2.58,24.33],[2,1.2,1250]],"ltp":2.62,"tv":26.56,"id":67083366}]}]}
{"op":"mcm","clk":"11962086790","pt":1724596689312,"mc":[{"id":"1.232245129","rc":[{"batb":[[0,2.64,9],[1,2.62,50.77],[2,2.58,24.33]],"batl":[[1,3.85,1.03],[2,4,8.38]],"ltp":2.62,"tv":26.56,"id":67083366}]}]}
{"op":"mcm","clk":"11962087086","pt":1724596690694,"mc":[{"id":"1.232245129","rc":[{"batb":[[0,2.64,5]],"ltp":2.62,"tv":26.56,"id":67083366}]}]}
{"op":"mcm","clk":"11962087302","pt":1724596691910,"mc":[{"id":"1.232245129","rc":[{"batb":[[0,2.62,50.77],[1,2.58,24.33],[2,1.2,1250]],"ltp":2.62,"tv":26.56,"id":67083366},{"batl":[[1,1.61,31.76]],"ltp":1.6,"tv":557.89,"id":72922097}]}]}
{"op":"mcm","clk":"11962091532","pt":1724596713031,"mc":[{"id":"1.232245129","rc":[{"batb":[[0,2.64,9],[1,2.62,50.77],[2,2.58,24.33]],"ltp":2.62,"tv":26.56,"id":67083366},{"batl":[[2,1.69,25.73]],"ltp":1.6,"tv":557.89,"id":72922097}]}]}
{"op":"mcm","clk":"11962092014","pt":1724596715248,"mc":[{"id":"1.232245129","rc":[{"batb":[[0,2.64,5]],"ltp":2.62,"tv":26.56,"id":67083366}]}]}
{"op":"mcm","clk":"11962092242","pt":1724596716434,"mc":[{"id":"1.232245129","rc":[{"batb":[[0,2.62,50.77],[1,2.58,24.33],[2,1.2,1250]],"ltp":2.62,"tv":26.56,"id":67083366}]}]}
{"op":"mcm","clk":"11962092813","pt":1724596719126,"mc":[{"id":"1.232245129","rc":[{"batb":[[0,2.64,9],[1,2.62,50.77],[2,2.58,24.33]],"ltp":2.62,"tv":26.56,"id":67083366}]}]}
{"op":"mcm","clk":"11962093271","pt":1724596721343,"mc":[{"id":"1.232245129","rc":[{"batb":[[0,2.64,5]],"ltp":2.62,"tv":26.56,"id":67083366}]}]}
{"op":"mcm","clk":"11962093503","pt":1724596722457,"mc":[{"id":"1.232245129","rc":[{"batb":[[0,2.62,50.77],[1,2.58,24.33],[2,1.2,1250]],"ltp":2.62,"tv":26.56,"id":67083366}]}]}
{"op":"mcm","clk":"11962094360","pt":1724596726644,"mc":[{"id":"1.232245129","rc":[{"trd":[[2.66,7.46]],"batb":[[0,2.66,5],[1,2.64,4],[2,2.62,50.77]],"ltp":2.66,"tv":33.56,"id":67083366},{"trd":[[1.6,13.42]],"batl":[[0,1.61,31.76],[1,1.69,25.73],[2,1.85,6.18]],"ltp":1.6,"tv":559.89,"id":72922097}],"tv":593.46}]}
{"op":"mcm","clk":"11962094805","pt":1724596728849,"mc":[{"id":"1.232245129","rc":[{"batb":[[1,2.62,50.77],[2,2.58,24.33]],"ltp":2.66,"tv":33.56,"id":67083366}]}]}
{"op":"mcm","clk":"11962095028","pt":1724596730046,"mc":[{"id":"1.232245129","rc":[{"batb":[[0,2.62,50.77],[1,2.58,24.33],[2,1.2,1250]],"ltp":2.66,"tv":33.56,"id":67083366}]}]}
{"op":"mcm","clk":"11962111376","pt":1724596810852,"mc":[{"id":"1.232245129","rc":[{"batb":[[0,2.64,9],[1,2.62,50.77],[2,2.58,24.33]],"ltp":2.66,"tv":33.56,"id":67083366}]}]}
{"op":"mcm","clk":"11962111833","pt":1724596813052,"mc":[{"id":"1.232245129","rc":[{"batb":[[0,2.64,5]],"ltp":2.66,"tv":33.56,"id":67083366}]}]}
{"op":"mcm","clk":"11962112113","pt":1724596814254,"mc":[{"id":"1.232245129","rc":[{"batb":[[0,2.62,50.77],[1,2.58,24.33],[2,1.2,1250]],"ltp":2.66,"tv":33.56,"id":67083366}]}]}
{"op":"mcm","clk":"11962122875","pt":1724596870016,"mc":[{"id":"1.232245129","rc":[{"batb":[[0,2.64,9],[1,2.62,50.77],[2,2.58,24.33]],"ltp":2.66,"tv":33.56,"id":67083366}]}]}
{"op":"mcm","clk":"11962123321","pt":1724596872313,"mc":[{"id":"1.232245129","rc":[{"batb":[[0,2.64,5]],"ltp":2.66,"tv":33.56,"id":67083366}]}]}
{"op":"mcm","clk":"11962123487","pt":1724596873315,"mc":[{"id":"1.232245129","rc":[{"batb":[[0,2.62,50.77],[1,2.58,24.33],[2,1.2,1250]],"ltp":2.66,"tv":33.56,"id":67083366}]}]}
{"op":"mcm","clk":"11962133633","pt":1724596925127,"mc":[{"id":"1.232245129","rc":[{"batb":[[0,2.64,9],[1,2.62,50.77],[2,2.58,24.33]],"ltp":2.66,"tv":33.56,"id":67083366}]}]}
{"op":"mcm","clk":"11962134079","pt":1724596927367,"mc":[{"id":"1.232245129","rc":[{"batb":[[0,2.64,5]],"ltp":2.66,"tv":33.56,"id":67083366}]}]}
{"op":"mcm","clk":"11962134292","pt":1724596928473,"mc":[{"id":"1.232245129","rc":[{"batb":[[0,2.62,50.77],[1,2.58,24.33],[2,1.2,1250]],"ltp":2.66,"tv":33.56,"id":67083366}]}]}
{"op":"mcm","clk":"11962148694","pt":1724597002596,"mc":[{"id":"1.232245129","rc":[{"trd":[[2.62,5.6]],"batb":[[0,2.64,9],[1,2.62,49.1],[2,2.58,24.33]],"ltp":2.62,"tv":36.9,"id":67083366}],"tv":596.8}]}
{"op":"mcm","clk":"11962149159","pt":1724597004914,"mc":[{"id":"1.232245129","rc":[{"batb":[[0,2.64,5]],"ltp":2.62,"tv":36.9,"id":67083366}]}]}
{"op":"mcm","clk":"11962149333","pt":1724597005768,"mc":[{"id":"1.232245129","rc":[{"batb":[[0,2.62,49.1],[1,2.58,24.33],[2,1.2,1250]],"ltp":2.62,"tv":36.9,"id":67083366}]}]}
{"op":"mcm","clk":"11962161040","pt":1724597065833,"mc":[{"id":"1.232245129","rc":[{"batb":[[0,2.64,9],[1,2.62,49.1],[2,2.58,24.33]],"ltp":2.62,"tv":36.9,"id":67083366},{"batl":[[0,1.6,117.69],[1,1.61,31.76],[2,1.69,25.73]],"ltp":1.6,"tv":559.89,"id":72922097}]}]}
{"op":"mcm","clk":"11962161502","pt":1724597068254,"mc":[{"id":"1.232245129","rc":[{"batb":[[0,2.64,15.86]],"ltp":2.62,"tv":36.9,"id":67083366},{"batl":[[0,1.59,6.11],[1,1.6,117.69],[2,1.61,25.73]],"ltp":1.6,"tv":559.89,"id":72922097}]}]}
{"op":"mcm","clk":"11962161690","pt":1724597069254,"mc":[{"id":"1.232245129","rc":[{"batb":[[0,2.66,10.73],[1,2.64,10.86],[2,2.62,49.1]],"ltp":2.62,"tv":36.9,"id":67083366}]}]}
{"op":"mcm","clk":"11962168153","pt":1724597102093,"mc":[{"id":"1.232245129","rc":[{"batb":[[0,2.68,9],[1,2.62,49.1],[2,2.58,24.33]],"ltp":2.62,"tv":36.9,"id":67083366},{"batl":[[1,1.61,25.73],[2,1.69,25.73]],"ltp":1.6,"tv":559.89,"id":72922097}]}]}
{"op":"mcm","clk":"11962168699","pt":1724597104399,"mc":[{"id":"1.232245129","rc":[{"batb":[[0,2.68,5]],"ltp":2.62,"tv":36.9,"id":67083366}]}]}
{"op":"mcm","clk":"11962169072","pt":1724597105994,"mc":[{"id":"1.232245129","rc":[{"batb":[[0,2.62,49.1],[1,2.58,24.33],[2,1.2,1250]],"ltp":2.62,"tv":36.9,"id":67083366},{"batl":[[0,1.6,6.06]],"ltp":1.6,"tv":559.89,"id":72922097}]}]}
{"op":"mcm","clk":"11962172045","pt":1724597120780,"mc":[{"id":"1.232245129","rc":[{"batb":[[0,2.64,9],[1,2.62,49.1],[2,2.58,24.33]],"ltp":2.62,"tv":36.9,"id":67083366},{"batl":[[0,1.59,235.38],[1,1.6,6.06],[2,1.61,25.73]],"ltp":1.6,"tv":559.89,"id":72922097}]}]}
{"op":"mcm","clk":"11962172276","pt":1724597122031,"mc":[{"id":"1.232245129","rc":[{"batl":[[0,1.58,6.14],[1,1.59,235.38]],"ltp":1.6,"tv":559.89,"id":72922097}]}]}
{"op":"mcm","clk":"11962172547","pt":1724597123287,"mc":[{"id":"1.232245129","rc":[{"batb":[[0,2.68,10.6],[1,2.64,5],[2,2.62,49.1]],"ltp":2.62,"tv":36.9,"id":67083366}]}]}
{"op":"mcm","clk":"11962172693","pt":1724597123991,"mc":[{"id":"1.232245129","rc":[{"batb":[[1,2.62,49.1],[2,2.58,24.33]],"ltp":2.62,"tv":36.9,"id":67083366}]}]}
{"op":"mcm","clk":"11962179678","pt":1724597159694,"mc":[{"id":"1.232245129","rc":[{"batb":[[0,2.7,9]],"ltp":2.62,"tv":36.9,"id":67083366},{"batl":[[1,1.61,25.73],[2,1.69,25.73]],"ltp":1.6,"tv":559.89,"id":72922097}]}]}
{"op":"mcm","clk":"11962180164","pt":1724597162206,"mc":[{"id":"1.232245129","rc":[{"batb":[[0,2.7,5]],"ltp":2.62,"tv":36.9,"id":67083366}]}]}
{"op":"mcm","clk":"11962180299","pt":1724597162884,"mc":[{"id":"1.232245129","rc":[{"batb":[[0,2.62,49.1],[1,2.58,24.33],[2,1.2,1250]],"ltp":2.62,"tv":36.9,"id":67083366},{"batl":[[0,1.61,25.73],[1,1.69,25.73],[2,1.85,6.18]],"ltp":1.6,"tv":559.89,"id":72922097}]}]}
{"op":"mcm","clk":"11962180778","pt":1724597165295,"mc":[{"id":"1.232245129","rc":[{"batb":[[0,2.64,9],[1,2.62,49.1],[2,2.58,24.33]],"ltp":2.62,"tv":36.9,"id":67083366}]}]}
{"op":"mcm","clk":"11962181254","pt":1724597167811,"mc":[{"id":"1.232245129","rc":[{"batb":[[0,2.64,5]],"ltp":2.62,"tv":36.9,"id":67083366},{"batl":[[0,1.6,6.06],[1,1.61,25.73],[2,1.69,25.73]],"ltp":1.6,"tv":559.89,"id":72922097}]}]}
{"op":"mcm","clk":"11962181404","pt":1724597168611,"mc":[{"id":"1.232245129","rc":[{"batb":[[0,2.62,49.1],[1,2.58,24.33],[2,1.2,1250]],"ltp":2.62,"tv":36.9,"id":67083366}]}]}
{"op":"mcm","clk":"11962196694","pt":1724597249462,"mc":[{"id":"1.232245129","rc":[{"trd":[[2.62,28.48],[2.66,11.11]],"batb":[[0,2.64,9],[1,2.62,37.66],[2,2.58,24.33]],"ltp":2.62,"tv":63.43,"id":67083366},{"trd":[[1.6,19.48]],"batl":[[0,1.61,25.73],[1,1.69,25.73],[2,1.85,6.18]],"ltp":1.6,"tv":565.96,"id":72922097}],"tv":629.4}]}
{"op":"mcm","clk":"11962197144","pt":1724597251736,"mc":[{"id":"1.232245129","rc":[{"batb":[[0,2.64,5]],"ltp":2.62,"tv":63.43,"id":67083366}]}]}
{"op":"mcm","clk":"11962197325","pt":1724597252767,"mc":[{"id":"1.232245129","rc":[{"batb":[[0,2.62,37.66],[1,2.58,24.33],[2,1.2,1250]],"ltp":2.62,"tv":63.43,"id":67083366}]}]}
{"op":"mcm","clk":"11962198536","pt":1724597259274,"mc":[{"id":"1.232245129","rc":[{"batb":[[0,2.64,9],[1,2.62,37.66],[2,2.58,24.33]],"ltp":2.62,"tv":63.43,"id":67083366},{"trd":[[1.54,229.85],[1.56,23.42]],"batb":[[0,1.5,76.89],[1,1.4,173.72],[2,1.35,9.78]],"batl":[[0,1.54,1713.24],[1,1.61,25.73],[2,1.69,25.73]],"ltp":1.54,"tv":601.02,"id":72922097}],"tv":664.46}]}
{"op":"mcm","clk":"11962198622","pt":1724597259748,"mc":[{"id":"1.232245129","rc":[{"batb":[[1,1.49,36.35],[2,1.4,173.72]],"ltp":1.54,"tv":601.02,"id":72922097}]}]}
{"op":"mcm","clk":"11962198792","pt":1724597260755,"mc":[{"id":"1.232245129","rc":[{"batb":[[0,2.82,9.79],[1,2.64,9],[2,2.62,37.66]],"ltp":2.62,"tv":63.43,"id":67083366}]}]}
{"op":"mcm","clk":"11962198952","pt":1724597261572,"mc":[{"id":"1.232245129","rc":[{"batb":[[1,2.64,5]],"ltp":2.62,"tv":63.43,"id":67083366}]}]}
{"op":"mcm","clk":"11962199124","pt":1724597262561,"mc":[{"id":"1.232245129","rc":[{"batb":[[1,2.62,37.66],[2,2.58,24.33]],"ltp":2.62,"tv":63.43,"id":67083366}]}]}
{"op":"mcm","clk":"11962225709","pt":1724597403053,"mc":[{"id":"1.232245129","rc":[{"batb":[[0,2.84,9],[1,2.82,9.79],[2,2.62,37.66]],"ltp":2.62,"tv":63.43,"id":67083366}]}]}
{"op":"mcm","clk":"11962226192","pt":1724597405543,"mc":[{"id":"1.232245129","rc":[{"batb":[[0,2.84,5]],"ltp":2.62,"tv":63.43,"id":67083366}]}]}
{"op":"mcm","clk":"11962226475","pt":1724597406865,"mc":[{"id":"1.232245129","rc":[{"batb":[[0,2.82,9.79],[1,2.62,37.66],[2,2.58,24.33]],"ltp":2.62,"tv":63.43,"id":67083366}]}]}
{"op":"mcm","clk":"11962238328","pt":1724597468008,"mc":[{"id":"1.232245129","rc":[{"batb":[[0,2.84,9],[1,2.82,9.79],[2,2.62,37.66]],"ltp":2.62,"tv":63.43,"id":67083366},{"batb":[[2,1.42,15.08]],"ltp":1.54,"tv":601.02,"id":72922097}]}]}
{"op":"mcm","clk":"11962238770","pt":1724597470423,"mc":[{"id":"1.232245129","rc":[{"batb":[[0,2.84,5]],"ltp":2.62,"tv":63.43,"id":67083366}]}]}
{"op":"mcm","clk":"11962238958","pt":1724597471421,"mc":[{"id":"1.232245129","rc":[{"batb":[[0,2.82,9.79],[1,2.62,37.66],[2,2.58,24.33]],"ltp":2.62,"tv":63.43,"id":67083366}]}]}
{"op":"mcm","clk":"11962255128","pt":1724597554331,"mc":[{"id":"1.232245129","rc":[{"batb":[[2,1.4,173.72]],"ltp":1.54,"tv":601.02,"id":72922097}]}]}
{"op":"mcm","clk":"11962255147","pt":1724597554384,"mc":[{"id":"1.232245129","rc":[{"batb":[[0,2.84,9],[1,2.82,9.79],[2,2.62,37.66]],"ltp":2.62,"tv":63.43,"id":67083366}]}]}
{"op":"mcm","clk":"11962255604","pt":1724597556715,"mc":[{"id":"1.232245129","rc":[{"batb":[[0,2.84,5]],"ltp":2.62,"tv":63.43,"id":67083366}]}]}
{"op":"mcm","clk":"11962255790","pt":1724597557705,"mc":[{"id":"1.232245129","rc":[{"batb":[[0,2.82,9.79],[1,2.62,37.66],[2,2.58,24.33]],"ltp":2.62,"tv":63.43,"id":67083366}]}]}
{"op":"mcm","clk":"11962262911","pt":1724597596754,"mc":[{"id":"1.232245129","rc":[{"batb":[[0,2.84,9],[1,2.82,9.79],[2,2.62,37.66]],"ltp":2.62,"tv":63.43,"id":67083366},{"batl":[[0,1.54,1738.97],[1,1.69,25.73],[2,1.85,6.18]],"ltp":1.54,"tv":601.02,"id":72922097}]}]}
{"op":"mcm","clk":"11962263359","pt":1724597599064,"mc":[{"id":"1.232245129","rc":[{"batb":[[0,2.84,5]],"ltp":2.62,"tv":63.43,"id":67083366}]}]}
{"op":"mcm","clk":"11962263531","pt":1724597600164,"mc":[{"id":"1.232245129","rc":[{"batb":[[0,2.82,9.79],[1,2.62,37.66],[2,2.58,24.33]],"ltp":2.62,"tv":63.43,"id":67083366}]}]}
{"op":"mcm","clk":"11962264358","pt":1724597605272,"mc":[{"id":"1.232245129","rc":[{"batl":[[0,1.54,1713.24]],"ltp":1.54,"tv":601.02,"id":72922097}]}]}
{"op":"mcm","clk":"11962264476","pt":1724597605982,"mc":[{"id":"1.232245129","rc":[{"batb":[[0,2.84,18.68],[1,2.82,9.79],[2,2.62,37.66]],"ltp":2.62,"tv":63.43,"id":67083366},{"batl":[[0,1.53,25.73],[1,1.54,1713.24],[2,1.69,25.73]],"ltp":1.54,"tv":601.02,"id":72922097}]}]}
{"op":"mcm","clk":"11962264820","pt":1724597607963,"mc":[{"id":"1.232245129","rc":[{"batb":[[0,2.86,9.58],[1,2.84,14.68],[2,2.82,9.79]],"ltp":2.62,"tv":63.43,"id":67083366}]}]}
{"op":"mcm","clk":"11962264948","pt":1724597608704,"mc":[{"id":"1.232245129","rc":[{"batb":[[1,2.84,9.68]],"ltp":2.62,"tv":63.43,"id":67083366}]}]}
{"op":"mcm","clk":"11962277062","pt":1724597674180,"mc":[{"id":"1.232245129","rc":[{"batb":[[0,2.88,9],[1,2.86,9.58],[2,2.84,9.68]],"ltp":2.62,"tv":63.43,"id":67083366},{"batb":[[2,1.42,15.08]],"ltp":1.54,"tv":601.02,"id":72922097}]}]}
{"op":"mcm","clk":"11962277496","pt":1724597676470,"mc":[{"id":"1.232245129","rc":[{"batb":[[0,2.88,5]],"ltp":2.62,"tv":63.43,"id":67083366}]}]}
{"op":"mcm","clk":"11962277662","pt":1724597677352,"mc":[{"id":"1.232245129","rc":[{"batb":[[0,2.86,9.58],[1,2.84,9.68],[2,2.82,9.79]],"ltp":2.62,"tv":63.43,"id":67083366}]}]}
{"op":"mcm","clk":"11962282216","pt":1724597702058,"mc":[{"id":"1.232245129","rc":[{"batb":[[0,2.88,9],[1,2.86,9.58],[2,2.84,9.68]],"ltp":2.62,"tv":63.43,"id":67083366}]}]}
{"op":"mcm","clk":"11962282700","pt":1724597704787,"mc":[{"id":"1.232245129","rc":[{"batb":[[0,2.88,5]],"ltp":2.62,"tv":63.43,"id":67083366}]}]}
{"op":"mcm","clk":"11962282944","pt":1724597705456,"mc":[{"id":"1.232245129","rc":[{"batb":[[0,2.86,9.58],[1,2.84,9.68],[2,2.82,9.79]],"ltp":2.62,"tv":63.43,"id":67083366}]}]}
{"op":"mcm","clk":"11962292882","pt":1724597756005,"mc":[{"id":"1.232245129","rc":[{"batb":[[0,2.88,9],[1,2.86,9.58],[2,2.84,9.68]],"ltp":2.62,"tv":63.43,"id":67083366}]}]}
{"op":"mcm","clk":"11962293339","pt":1724597758505,"mc":[{"id":"1.232245129","rc":[{"batb":[[0,2.88,5]],"ltp":2.62,"tv":63.43,"id":67083366}]}]}
{"op":"mcm","clk":"11962293521","pt":1724597759415,"mc":[{"id":"1.232245129","rc":[{"batb":[[0,2.86,9.58],[1,2.84,9.68],[2,2.82,9.79]],"ltp":2.62,"tv":63.43,"id":67083366}]}]}
{"op":"mcm","clk":"11962307727","pt":1724597834782,"mc":[{"id":"1.232245129","rc":[{"trd":[[2.88,0.26]],"batb":[[0,2.88,9],[1,2.86,9.58],[2,2.84,9.68]],"ltp":2.88,"tv":63.7,"id":67083366},{"trd":[[1.53,0.5]],"batl":[[0,1.53,25.23]],"ltp":1.53,"tv":601.52,"id":72922097}],"tv":665.22}]}
{"op":"mcm","clk":"11962308170","pt":1724597837084,"mc":[{"id":"1.232245129","rc":[{"batb":[[0,2.88,5]],"ltp":2.88,"tv":63.7,"id":67083366}]}]}
{"op":"mcm","clk":"11962308390","pt":1724597838181,"mc":[{"id":"1.232245129","rc":[{"batb":[[0,2.86,9.58],[1,2.84,9.68],[2,2.82,9.79]],"ltp":2.88,"tv":63.7,"id":67083366}]}]}
{"op":"mcm","clk":"11962315223","pt":1724597874814,"mc":[{"id":"1.232245129","rc":[{"batb":[[0,2.88,9],[1,2.86,9.58],[2,2.84,9.68]],"ltp":2.88,"tv":63.7,"id":67083366}]}]}
{"op":"mcm","clk":"11962315625","pt":1724597877221,"mc":[{"id":"1.232245129","rc":[{"batb":[[0,2.88,5]],"ltp":2.88,"tv":63.7,"id":67083366}]}]}
{"op":"mcm","clk":"11962315814","pt":1724597878210,"mc":[{"id":"1.232245129","rc":[{"batb":[[0,2.86,9.58],[1,2.84,9.68],[2,2.82,9.79]],"ltp":2.88,"tv":63.7,"id":67083366}]}]}
{"op":"mcm","clk":"11962320483","pt":1724597902295,"mc":[{"id":"1.232245129","rc":[{"batb":[[1,1.49,53.11]],"ltp":1.53,"tv":601.52,"id":72922097}]}]}
{"op":"mcm","clk":"11962320520","pt":1724597902495,"mc":[{"id":"1.232245129","rc":[{"batb":[[0,2.88,9],[1,2.86,9.58],[2,2.84,9.68]],"ltp":2.88,"tv":63.7,"id":67083366}]}]}
{"op":"mcm","clk":"11962320971","pt":1724597904810,"mc":[{"id":"1.232245129","rc":[{"batb":[[0,2.88,5]],"ltp":2.88,"tv":63.7,"id":67083366}]}]}
{"op":"mcm","clk":"11962321168","pt":1724597905771,"mc":[{"id":"1.232245129","rc":[{"batb":[[0,2.86,9.58],[1,2.84,9.68],[2,2.82,9.79]],"ltp":2.88,"tv":63.7,"id":67083366}]}]}
{"op":"mcm","clk":"11962344790","pt":1724598021817,"mc":[{"id":"1.232245129","rc":[{"batb":[[0,2.88,9],[1,2.86,9.58],[2,2.84,9.68]],"ltp":2.88,"tv":63.7,"id":67083366}]}]}
{"op":"mcm","clk":"11962345405","pt":1724598024257,"mc":[{"id":"1.232245129","rc":[{"batb":[[0,2.88,5]],"ltp":2.88,"tv":63.7,"id":67083366}]}]}
{"op":"mcm","clk":"11962345638","pt":1724598024950,"mc":[{"id":"1.232245129","rc":[{"batb":[[0,2.86,9.58],[1,2.84,9.68],[2,2.82,9.79]],"ltp":2.88,"tv":63.7,"id":67083366}]}]}
{"op":"mcm","clk":"11962351984","pt":1724598052763,"mc":[{"id":"1.232245129","rc":[{"batb":[[0,2.88,9],[1,2.86,9.58],[2,2.84,9.68]],"ltp":2.88,"tv":63.7,"id":67083366},{"trd":[[1.53,4.68]],"batl":[[0,1.53,23.14]],"ltp":1.53,"tv":605.7,"id":72922097}],"tv":669.4}]}
{"op":"mcm","clk":"11962352504","pt":1724598055076,"mc":[{"id":"1.232245129","rc":[{"batb":[[0,2.88,5]],"ltp":2.88,"tv":63.7,"id":67083366}]}]}
{"op":"mcm","clk":"11962352713","pt":1724598056041,"mc":[{"id":"1.232245129","rc":[{"batb":[[0,2.86,9.58],[1,2.84,9.68],[2,2.82,9.79]],"ltp":2.88,"tv":63.7,"id":67083366}]}]}
{"op":"mcm","clk":"11962354865","pt":1724598065137,"mc":[{"id":"1.232245129","rc":[{"batb":[[0,2.88,9],[1,2.86,9.58],[2,2.84,9.68]],"ltp":2.88,"tv":63.7,"id":67083366}]}]}
{"op":"mcm","clk":"11962355397","pt":1724598067669,"mc":[{"id":"1.232245129","rc":[{"batb":[[0,2.88,5]],"ltp":2.88,"tv":63.7,"id":67083366}]}]}
{"op":"mcm","clk":"11962355585","pt":1724598068579,"mc":[{"id":"1.232245129","rc":[{"batb":[[0,2.86,9.58],[1,2.84,9.68],[2,2.82,9.79]],"ltp":2.88,"tv":63.7,"id":67083366}]}]}
{"op":"mcm","clk":"11962358437","pt":1724598081767,"mc":[{"id":"1.232245129","rc":[{"batb":[[0,2.88,9],[1,2.86,9.58],[2,2.84,9.68]],"ltp":2.88,"tv":63.7,"id":67083366},{"batl":[[0,1.53,24.14]],"ltp":1.53,"tv":605.7,"id":72922097}]}]}
{"op":"mcm","clk":"11962358919","pt":1724598084100,"mc":[{"id":"1.232245129","rc":[{"batb":[[0,2.88,5]],"ltp":2.88,"tv":63.7,"id":67083366}]}]}
{"op":"mcm","clk":"11962359130","pt":1724598085092,"mc":[{"id":"1.232245129","rc":[{"batb":[[0,2.86,9.58],[1,2.84,9.68],[2,2.82,9.79]],"ltp":2.88,"tv":63.7,"id":67083366}]}]}
{"op":"mcm","clk":"11962368816","pt":1724598128770,"mc":[{"id":"1.232245129","rc":[{"batb":[[0,2.88,9],[1,2.86,9.58],[2,2.84,9.68]],"ltp":2.88,"tv":63.7,"id":67083366}]}]}
{"op":"mcm","clk":"11962369375","pt":1724598131290,"mc":[{"id":"1.232245129","rc":[{"batb":[[0,2.88,5]],"ltp":2.88,"tv":63.7,"id":67083366}]}]}
{"op":"mcm","clk":"11962369565","pt":1724598132181,"mc":[{"id":"1.232245129","rc":[{"batb":[[0,2.86,9.58],[1,2.84,9.68],[2,2.82,9.79]],"ltp":2.88,"tv":63.7,"id":67083366}]}]}
{"op":"mcm","clk":"11962379653","pt":1724598178219,"mc":[{"id":"1.232245129","rc":[{"batb":[[0,2.88,9],[1,2.86,9.58],[2,2.84,9.68]],"ltp":2.88,"tv":63.7,"id":67083366}]}]}
{"op":"mcm","clk":"11962380189","pt":1724598180638,"mc":[{"id":"1.232245129","rc":[{"batb":[[0,2.88,5]],"ltp":2.88,"tv":63.7,"id":67083366}]}]}
{"op":"mcm","clk":"11962380400","pt":1724598181512,"mc":[{"id":"1.232245129","rc":[{"batb":[[0,2.86,9.58],[1,2.84,9.68],[2,2.82,9.79]],"ltp":2.88,"tv":63.7,"id":67083366}]}]}
{"op":"mcm","clk":"11962382545","pt":1724598190517,"mc":[{"id":"1.232245129","rc":[{"batb":[[0,2.88,9],[1,2.86,9.58],[2,2.84,9.68]],"ltp":2.88,"tv":63.7,"id":67083366}]}]}
{"op":"mcm","clk":"11962383197","pt":1724598192643,"mc":[{"id":"1.232245129","rc":[{"batb":[[0,2.88,5]],"ltp":2.88,"tv":63.7,"id":67083366}]}]}
{"op":"mcm","clk":"11962383432","pt":1724598193639,"mc":[{"id":"1.232245129","rc":[{"batb":[[0,2.86,9.58],[1,2.84,9.68],[2,2.82,9.79]],"ltp":2.88,"tv":63.7,"id":67083366}]}]}
{"op":"mcm","clk":"11962388724","pt":1724598215206,"mc":[{"id":"1.232245129","rc":[{"trd":[[2.88,0.28]],"ltp":2.88,"tv":63.72,"id":67083366},{"trd":[[1.53,4.71]],"batl":[[0,1.53,24.11]],"ltp":1.53,"tv":605.73,"id":72922097}],"tv":669.45}]}
{"op":"mcm","clk":"11962388779","pt":1724598215395,"mc":[{"id":"1.232245129","rc":[{"batb":[[0,2.88,9],[1,2.86,9.58],[2,2.84,9.68]],"ltp":2.88,"tv":63.72,"id":67083366}]}]}
{"op":"mcm","clk":"11962389350","pt":1724598217579,"mc":[{"id":"1.232245129","rc":[{"batb":[[0,2.88,5]],"ltp":2.88,"tv":63.72,"id":67083366}]}]}
{"op":"mcm","clk":"11962389631","pt":1724598218799,"mc":[{"id":"1.232245129","rc":[{"batb":[[0,2.86,9.58],[1,2.84,9.68],[2,2.82,9.79]],"ltp":2.88,"tv":63.72,"id":67083366}]}]}
{"op":"mcm","clk":"11962394066","pt":1724598236309,"mc":[{"id":"1.232245129","rc":[{"batb":[[0,2.88,9],[1,2.86,9.58],[2,2.84,9.68]],"ltp":2.88,"tv":63.72,"id":67083366}]}]}
{"op":"mcm","clk":"11962394726","pt":1724598238808,"mc":[{"id":"1.232245129","rc":[{"batb":[[0,2.88,5]],"ltp":2.88,"tv":63.72,"id":67083366}]}]}
{"op":"mcm","clk":"11962394967","pt":1724598239732,"mc":[{"id":"1.232245129","rc":[{"batb":[[0,2.86,9.58],[1,2.84,9.68],[2,2.82,9.79]],"ltp":2.88,"tv":63.72,"id":67083366}]}]}
{"op":"mcm","clk":"11962400953","pt":1724598263943,"mc":[{"id":"1.232245129","rc":[{"batb":[[0,2.88,9],[1,2.86,9.58],[2,2.84,9.68]],"ltp":2.88,"tv":63.72,"id":67083366}]}]}
{"op":"mcm","clk":"11962401553","pt":1724598266441,"mc":[{"id":"1.232245129","rc":[{"batb":[[0,2.88,5]],"ltp":2.88,"tv":63.72,"id":67083366}]}]}
{"op":"mcm","clk":"11962401798","pt":1724598267458,"mc":[{"id":"1.232245129","rc":[{"batb":[[0,2.86,9.58],[1,2.84,9.68],[2,2.82,9.79]],"ltp":2.88,"tv":63.72,"id":67083366}]}]}
{"op":"mcm","clk":"11962404011","pt":1724598276970,"mc":[{"id":"1.232245129","rc":[{"batb":[[0,2.88,9],[1,2.86,9.58],[2,2.84,9.68]],"ltp":2.88,"tv":63.72,"id":67083366},{"trd":[[1.5,47.24]],"batb":[[0,1.5,59.27]],"ltp":1.5,"tv":640.97,"id":72922097}],"tv":704.69}]}
{"op":"mcm","clk":"11962404740","pt":1724598280294,"mc":[{"id":"1.232245129","rc":[{"batb":[[0,2.86,9.58],[1,2.84,9.68],[2,2.82,9.79]],"ltp":2.88,"tv":63.72,"id":67083366}]}]}
{"op":"mcm","clk":"11962404922","pt":1724598281084,"mc":[{"id":"1.232245129","rc":[{"batb":[[0,1.5,76.89]],"ltp":1.5,"tv":640.97,"id":72922097}]}]}
{"op":"mcm","clk":"11962421152","pt":1724598348276,"mc":[{"id":"1.232245129","rc":[{"trd":[[1.53,15.01]],"batl":[[0,1.53,18.96]],"ltp":1.53,"tv":651.26,"id":72922097}],"tv":714.98}]}
{"op":"mcm","clk":"11962421179","pt":1724598348384,"mc":[{"id":"1.232245129","rc":[{"batb":[[0,2.88,9],[1,2.86,9.58],[2,2.84,9.68]],"ltp":2.88,"tv":63.72,"id":67083366}]}]}
{"op":"mcm","clk":"11962421723","pt":1724598350678,"mc":[{"id":"1.232245129","rc":[{"batb":[[0,2.88,5]],"ltp":2.88,"tv":63.72,"id":67083366}]}]}
{"op":"mcm","clk":"11962422010","pt":1724598351849,"mc":[{"id":"1.232245129","rc":[{"batb":[[0,2.86,9.58],[1,2.84,9.68],[2,2.82,9.79]],"ltp":2.88,"tv":63.72,"id":67083366}]}]}
{"op":"mcm","clk":"11962422155","pt":1724598352482,"mc":[{"id":"1.232245129","rc":[{"batb":[[0,2.84,9.68],[1,2.82,9.79],[2,2.62,37.66]],"ltp":2.88,"tv":63.72,"id":67083366}]}]}
{"op":"mcm","clk":"11962427877","pt":1724598375611,"mc":[{"id":"1.232245129","rc":[{"batb":[[0,2.86,9],[1,2.84,9.68],[2,2.82,9.79]],"ltp":2.88,"tv":63.72,"id":67083366}]}]}
{"op":"mcm","clk":"11962428443","pt":1724598378113,"mc":[{"id":"1.232245129","rc":[{"batb":[[0,2.86,5]],"ltp":2.88,"tv":63.72,"id":67083366}]}]}
{"op":"mcm","clk":"11962428689","pt":1724598379120,"mc":[{"id":"1.232245129","rc":[{"batb":[[0,2.84,9.68],[1,2.82,9.79],[2,2.62,37.66]],"ltp":2.88,"tv":63.72,"id":67083366}]}]}
{"op":"mcm","clk":"11962433783","pt":1724598400370,"mc":[{"id":"1.232245129","rc":[{"batb":[[0,2.86,9],[1,2.84,9.68],[2,2.82,9.79]],"ltp":2.88,"tv":63.72,"id":67083366}]}]}
{"op":"mcm","clk":"11962434432","pt":1724598403035,"mc":[{"id":"1.232245129","rc":[{"batb":[[0,2.86,5]],"ltp":2.88,"tv":63.72,"id":67083366}]}]}
{"op":"mcm","clk":"11962434632","pt":1724598403939,"mc":[{"id":"1.232245129","rc":[{"batb":[[0,2.84,9.68],[1,2.82,9.79],[2,2.62,37.66]],"ltp":2.88,"tv":63.72,"id":67083366}]}]}
{"op":"mcm","clk":"11962452056","pt":1724598478254,"mc":[{"id":"1.232245129","rc":[{"batb":[[0,2.86,9],[1,2.84,9.68],[2,2.82,9.79]],"ltp":2.88,"tv":63.72,"id":67083366}]}]}
{"op":"mcm","clk":"11962452585","pt":1724598480707,"mc":[{"id":"1.232245129","rc":[{"batb":[[0,2.86,14.58]],"ltp":2.88,"tv":63.72,"id":67083366}]}]}
{"op":"mcm","clk":"11962452919","pt":1724598482059,"mc":[{"id":"1.232245129","rc":[{"batb":[[0,2.84,9.68],[1,2.82,9.79],[2,2.62,37.66]],"ltp":2.88,"tv":63.72,"id":67083366}]}]}
{"op":"mcm","clk":"11962456555","pt":1724598497351,"mc":[{"id":"1.232245129","rc":[{"batb":[[0,2.86,9],[1,2.84,9.68],[2,2.82,9.79]],"ltp":2.88,"tv":63.72,"id":67083366}]}]}
{"op":"mcm","clk":"11962457171","pt":1724598499853,"mc":[{"id":"1.232245129","rc":[{"batb":[[0,2.86,14.58]],"ltp":2.88,"tv":63.72,"id":67083366}]}]}
{"op":"mcm","clk":"11962457432","pt":1724598500839,"mc":[{"id":"1.232245129","rc":[{"batb":[[0,2.86,9.58]],"ltp":2.88,"tv":63.72,"id":67083366}]}]}
{"op":"mcm","clk":"11962457591","pt":1724598501571,"mc":[{"id":"1.232245129","rc":[{"batb":[[0,2.84,9.68],[1,2.82,9.79],[2,2.62,37.66]],"ltp":2.88,"tv":63.72,"id":67083366}]}]}
{"op":"mcm","clk":"11962461109","pt":1724598515759,"mc":[{"id":"1.232245129","rc":[{"batb":[[0,2.86,9],[1,2.84,9.68],[2,2.82,9.79]],"ltp":2.88,"tv":63.72,"id":67083366}]}]}
{"op":"mcm","clk":"11962461654","pt":1724598518000,"mc":[{"id":"1.232245129","rc":[{"batb":[[0,2.86,14.58]],"ltp":2.88,"tv":63.72,"id":67083366}]}]}
{"op":"mcm","clk":"11962461937","pt":1724598519190,"mc":[{"id":"1.232245129","rc":[{"batb":[[0,2.86,9.58]],"ltp":2.88,"tv":63.72,"id":67083366}]}]}
{"op":"mcm","clk":"11962462049","pt":1724598519690,"mc":[{"id":"1.232245129","rc":[{"batb":[[0,2.84,9.68],[1,2.82,9.79],[2,2.62,37.66]],"ltp":2.88,"tv":63.72,"id":67083366}]}]}
{"op":"mcm","clk":"11962466237","pt":1724598537315,"mc":[{"id":"1.232245129","rc":[{"batb":[[0,2.86,9],[1,2.84,9.68],[2,2.82,9.79]],"ltp":2.88,"tv":63.72,"id":67083366}]}]}
{"op":"mcm","clk":"11962466832","pt":1724598539922,"mc":[{"id":"1.232245129","rc":[{"batb":[[0,2.86,14.58]],"ltp":2.88,"tv":63.72,"id":67083366}]}]}
{"op":"mcm","clk":"11962467115","pt":1724598541223,"mc":[{"id":"1.232245129","rc":[{"batb":[[0,2.84,9.68],[1,2.82,9.79],[2,2.62,37.66]],"ltp":2.88,"tv":63.72,"id":67083366}]}]}
{"op":"mcm","clk":"11962468145","pt":1724598545215,"mc":[{"id":"1.232245129","rc":[{"batb":[[0,2.86,9],[1,2.84,9.68],[2,2.82,9.79]],"ltp":2.88,"tv":63.72,"id":67083366}]}]}
{"op":"mcm","clk":"11962468762","pt":1724598547743,"mc":[{"id":"1.232245129","rc":[{"batb":[[0,2.86,14.58]],"ltp":2.88,"tv":63.72,"id":67083366}]}]}
{"op":"mcm","clk":"11962469092","pt":1724598549138,"mc":[{"id":"1.232245129","rc":[{"batb":[[0,2.84,9.68],[1,2.82,9.79],[2,2.62,37.66]],"ltp":2.88,"tv":63.72,"id":67083366}]}]}
{"op":"mcm","clk":"11962487754","pt":1724598626505,"mc":[{"id":"1.232245129","rc":[{"batb":[[0,2.86,9],[1,2.84,9.68],[2,2.82,9.79]],"ltp":2.88,"tv":63.72,"id":67083366}]}]}
{"op":"mcm","clk":"11962488304","pt":1724598628749,"mc":[{"id":"1.232245129","rc":[{"batb":[[0,2.86,14.58]],"ltp":2.88,"tv":63.72,"id":67083366}]}]}
{"op":"mcm","clk":"11962488597","pt":1724598629929,"mc":[{"id":"1.232245129","rc":[{"batb":[[0,2.86,9.58]],"ltp":2.88,"tv":63.72,"id":67083366}]}]}
{"op":"mcm","clk":"11962488783","pt":1724598630627,"mc":[{"id":"1.232245129","rc":[{"batb":[[0,2.84,9.68],[1,2.82,9.79],[2,2.62,37.66]],"ltp":2.88,"tv":63.72,"id":67083366}]}]}
