{"op":"mcm","clk":"11949909336","pt":1724501855643,"mc":[{"id":"1.232224255","marketDefinition":{"bspMarket":false,"turnInPlayEnabled":true,"persistenceEnabled":true,"marketBaseRate":5.0,"eventId":"33523469","eventTypeId":"4","numberOfWinners":1,"bettingType":"ODDS","marketType":"MATCH_ODDS","marketTime":"2024-08-25T09:30:00.000Z","suspendTime":"2024-08-25T09:30:00.000Z","bspReconciled":false,"complete":true,"inPlay":false,"crossMatching":false,"runnersVoidable":false,"numberOfActiveRunners":2,"betDelay":0,"status":"OPEN","runners":[{"status":"ACTIVE","sortPriority":1,"id":61422697,"name":"Cyprus"},{"status":"ACTIVE","sortPriority":2,"id":60971788,"name":"Czechia"}],"regulators":["MR_INT"],"countryCode":"GB","discountAllowed":false,"timezone":"GMT","openDate":"2024-08-25T09:30:00.000Z","version":6094669313,"name":"Match Odds","eventName":"Cyprus v Czechia"},"rc":[{"batb":[[0,1.03,200],[1,1.02,200],[2,1.01,220]],"ltp":0.0,"tv":0.0,"id":61422697},{"batb":[[0,1.03,200],[1,1.02,200],[2,1.01,220]],"ltp":0.0,"tv":0.0,"id":60971788}]}]}
{"op":"mcm","clk":"11949909578","pt":1724501856912,"mc":[{"id":"1.232224255","marketDefinition":{"bspMarket":false,"turnInPlayEnabled":true,"persistenceEnabled":true,"marketBaseRate":5.0,"eventId":"33523469","eventTypeId":"4","numberOfWinners":1,"bettingType":"ODDS","marketType":"MATCH_ODDS","marketTime":"2024-08-25T09:30:00.000Z","suspendTime":"2024-08-25T09:30:00.000Z","bspReconciled":false,"complete":true,"inPlay":false,"crossMatching":false,"runnersVoidable":false,"numberOfActiveRunners":2,"betDelay":0,"status":"OPEN","runners":[{"status":"ACTIVE","sortPriority":1,"id":61422697,"name":"Cyprus"},{"status":"ACTIVE","sortPriority":2,"id":60971788,"name":"Czechia"}],"regulators":["MR_INT"],"countryCode":"GB","discountAllowed":true,"timezone":"GMT","openDate":"2024-08-25T09:30:00.000Z","version":6094669313,"name":"Match Odds","eventName":"Cyprus v Czechia"}}]}
{"op":"mcm","clk":"11950795930","pt":1724506522421,"mc":[{"id":"1.232224255","rc":[{"batb":[[0,1.05,200],[1,1.04,250],[2,1.03,533.33]],"ltp":0.0,"tv":0.0,"id":61422697},{"batb":[[0,1.05,200],[1,1.04,250],[2,1.03,533.33]],"ltp":0.0,"tv":0.0,"id":60971788}]}]}
{"op":"mcm","clk":"11950879054","pt":1724506958685,"mc":[{"id":"1.232224255","rc":[{"batb":[[0,1.05,200.7]],"ltp":0.0,"tv":0.0,"id":61422697}]}]}
{"op":"mcm","clk":"11950881620","pt":1724506971747,"mc":[{"id":"1.232224255","rc":[{"batb":[[0,1.06,7.04],[1,1.05,200],[2,1.04,250]],"ltp":0.0,"tv":0.0,"id":60971788}]}]}
{"op":"mcm","clk":"11950883557","pt":1724506982721,"mc":[{"id":"1.232224255","rc":[{"batb":[[0,1.06,5.11],[1,1.05,200],[2,1.04,250]],"ltp":0.0,"tv":0.0,"id":61422697}]}]}
{"op":"mcm","clk":"11950885286","pt":1724506990913,"mc":[{"id":"1.232224255","marketDefinition":{"bspMarket":false,"turnInPlayEnabled":true,"persistenceEnabled":true,"marketBaseRate":5.0,"eventId":"33523469","eventTypeId":"4","numberOfWinners":1,"bettingType":"ODDS","marketType":"MATCH_ODDS","marketTime":"2024-08-25T09:30:00.000Z","suspendTime":"2024-08-25T09:30:00.000Z","bspReconciled":false,"complete":true,"inPlay":false,"crossMatching":true,"runnersVoidable":false,"numberOfActiveRunners":2,"betDelay":0,"status":"OPEN","runners":[{"status":"ACTIVE","sortPriority":1,"id":61422697,"name":"Cyprus"},{"status":"ACTIVE","sortPriority":2,"id":60971788,"name":"Czechia"}],"regulators":["MR_INT"],"countryCode":"GB","discountAllowed":true,"timezone":"GMT","openDate":"2024-08-25T09:30:00.000Z","version":6094669313,"name":"Match Odds","eventName":"Cyprus v Czechia"}}]}
{"op":"mcm","clk":"11951233614","pt":1724508580935,"mc":[{"id":"1.232224255","rc":[{"batb":[[2,1.04,251.05]],"ltp":0.0,"tv":0.0,"id":61422697},{"batb":[[2,1.04,251.05]],"ltp":0.0,"tv":0.0,"id":60971788}]}]}
{"op":"mcm","clk":"11952140782","pt":1724511768751,"mc":[{"id":"1.232224255","rc":[{"batl":[[0,14,0.76]],"ltp":0.0,"tv":0.0,"id":61422697},{"batl":[[0,14,0.76]],"ltp":0.0,"tv":0.0,"id":60971788}]}]}
{"op":"mcm","clk":"11952142978","pt":1724511778635,"mc":[{"id":"1.232224255","rc":[{"batl":[[0,24,1.51]],"ltp":0.0,"tv":0.0,"id":61422697},{"batl":[[0,24,1.51]],"ltp":0.0,"tv":0.0,"id":60971788}]}]}
{"op":"mcm","clk":"11952496651","pt":1724513019788,"mc":[{"id":"1.232224255","rc":[{"batb":[[0,1.05,200.7],[1,1.04,251.05],[2,1.03,533.33]],"ltp":0.0,"tv":0.0,"id":61422697}]}]}
{"op":"mcm","clk":"11952498375","pt":1724513025791,"mc":[{"id":"1.232224255","rc":[{"batb":[[0,1.05,200],[1,1.04,251.05],[2,1.03,533.33]],"ltp":0.0,"tv":0.0,"id":60971788}]}]}
{"op":"mcm","clk":"11952500081","pt":1724513031825,"mc":[{"id":"1.232224255","rc":[{"batb":[[0,1.05,200]],"ltp":0.0,"tv":0.0,"id":61422697}]}]}
{"op":"mcm","clk":"11953085974","pt":1724520831887,"mc":[{"id":"1.232224255","rc":[{"batb":[[0,1.07,1428.57],[1,1.05,200],[2,1.04,251.05]],"ltp":0.0,"tv":0.0,"id":60971788}]}]}
{"op":"mcm","clk":"11953086114","pt":1724520833294,"mc":[{"id":"1.232224255","rc":[{"batb":[[0,1.07,1428.57],[1,1.05,200],[2,1.04,251.05]],"ltp":0.0,"tv":0.0,"id":61422697}]}]}
{"op":"mcm","clk":"11953243108","pt":1724522197691,"mc":[{"id":"1.232224255","rc":[{"batb":[[0,1.08,1.76],[1,1.07,1428.57],[2,1.05,200]],"ltp":0.0,"tv":0.0,"id":61422697}]}]}
{"op":"mcm","clk":"11953244022","pt":1724522206703,"mc":[{"id":"1.232224255","rc":[{"batb":[[0,1.08,1.76],[1,1.07,1428.57],[2,1.05,200]],"ltp":0.0,"tv":0.0,"id":60971788}]}]}
{"op":"mcm","clk":"11953278976","pt":1724522479863,"mc":[{"id":"1.232224255","rc":[{"batb":[[0,1.75,57.26],[1,1.08,1.76],[2,1.07,1428.57]],"ltp":0.0,"tv":0.0,"id":61422697},{"batb":[[0,2.22,35.2],[1,1.08,1.76],[2,1.07,1428.57]],"ltp":0.0,"tv":0.0,"id":60971788}]}]}
{"op":"mcm","clk":"11953942891","pt":1724525797786,"mc":[{"id":"1.232224255","rc":[{"batb":[[1,1.21,24.75],[2,1.08,1.76]],"ltp":0.0,"tv":0.0,"id":61422697}]}]}
{"op":"mcm","clk":"11953945318","pt":1724525811588,"mc":[{"id":"1.232224255","rc":[{"batb":[[1,1.21,24.75],[2,1.08,1.76]],"ltp":0.0,"tv":0.0,"id":60971788}]}]}
{"op":"mcm","clk":"11954591897","pt":1724528442966,"mc":[{"id":"1.232224255","rc":[{"trd":[[1.75,5]],"batb":[[0,1.75,54.76]],"ltp":1.75,"tv":5.0,"id":61422697}],"tv":5.0}]}
{"op":"mcm","clk":"11954592235","pt":1724528444379,"mc":[{"id":"1.232224255","rc":[{"batb":[[0,1.75,57.26]],"ltp":1.75,"tv":5.0,"id":61422697}]}]}
{"op":"mcm","clk":"11956593266","pt":1724546913899,"mc":[{"id":"1.232224255","rc":[{"trd":[[2.22,10]],"batb":[[0,2.22,30.2]],"ltp":2.22,"tv":10.0,"id":60971788}],"tv":15.0}]}
{"op":"mcm","clk":"11956593563","pt":1724546917567,"mc":[{"id":"1.232224255","rc":[{"batb":[[0,2.22,35.2]],"ltp":2.22,"tv":10.0,"id":60971788}]}]}
{"op":"mcm","clk":"11956898486","pt":1724551495762,"mc":[{"id":"1.232224255","rc":[{"trd":[[1.75,110.16]],"batb":[[0,1.76,5],[1,1.75,4.68],[2,1.21,24.75]],"ltp":1.75,"tv":110.16,"id":61422697},{"batb":[[0,2.24,5],[1,2.22,35.2],[2,1.21,24.75]],"ltp":2.22,"tv":10.0,"id":60971788}],"tv":120.16}]}
{"op":"mcm","clk":"11956898562","pt":1724551497561,"mc":[{"id":"1.232224255","rc":[{"batb":[[1,1.71,60.49]],"ltp":1.75,"tv":110.16,"id":61422697}]}]}
{"op":"mcm","clk":"11956898644","pt":1724551499156,"mc":[{"id":"1.232224255","rc":[{"batb":[[0,1.71,60.49],[1,1.21,24.75],[2,1.08,1.76]],"ltp":1.75,"tv":110.16,"id":61422697},{"batb":[[0,2.22,35.2],[1,1.21,24.75],[2,1.08,1.76]],"ltp":2.22,"tv":10.0,"id":60971788}]}]}
{"op":"mcm","clk":"11956898919","pt":1724551503390,"mc":[{"id":"1.232224255","rc":[{"batb":[[0,1.72,5],[1,1.71,60.49],[2,1.21,24.75]],"ltp":1.75,"tv":110.16,"id":61422697},{"batb":[[0,2.24,5],[1,2.22,35.2],[2,1.21,24.75]],"ltp":2.22,"tv":10.0,"id":60971788}]}]}
{"op":"mcm","clk":"11956899140","pt":1724551506791,"mc":[{"id":"1.232224255","rc":[{"batb":[[0,1.71,60.49],[1,1.21,24.75],[2,1.08,1.76]],"ltp":1.75,"tv":110.16,"id":61422697},{"batb":[[0,2.22,35.2],[1,1.21,24.75],[2,1.08,1.76]],"ltp":2.22,"tv":10.0,"id":60971788}]}]}
{"op":"mcm","clk":"11956899263","pt":1724551509182,"mc":[{"id":"1.232224255","rc":[{"batb":[[0,1.72,5],[1,1.71,60.49],[2,1.21,24.75]],"ltp":1.75,"tv":110.16,"id":61422697},{"batb":[[0,2.24,5],[1,2.22,35.2],[2,1.21,24.75]],"ltp":2.22,"tv":10.0,"id":60971788}]}]}
{"op":"mcm","clk":"11956899447","pt":1724551512579,"mc":[{"id":"1.232224255","rc":[{"batb":[[0,1.71,60.49],[1,1.21,24.75],[2,1.08,1.76]],"ltp":1.75,"tv":110.16,"id":61422697},{"batb":[[0,2.22,35.2],[1,1.21,24.75],[2,1.08,1.76]],"ltp":2.22,"tv":10.0,"id":60971788}]}]}
{"op":"mcm","clk":"11956899659","pt":1724551516196,"mc":[{"id":"1.232224255","rc":[{"batb":[[0,1.72,5],[1,1.71,60.49],[2,1.21,24.75]],"ltp":1.75,"tv":110.16,"id":61422697},{"batb":[[0,2.24,5],[1,2.22,35.2],[2,1.21,24.75]],"ltp":2.22,"tv":10.0,"id":60971788}]}]}
{"op":"mcm","clk":"11956899855","pt":1724551519494,"mc":[{"id":"1.232224255","rc":[{"batb":[[0,1.71,60.49],[1,1.21,24.75],[2,1.08,1.76]],"ltp":1.75,"tv":110.16,"id":61422697},{"batb":[[0,2.22,35.2],[1,1.21,24.75],[2,1.08,1.76]],"ltp":2.22,"tv":10.0,"id":60971788}]}]}
{"op":"mcm","clk":"11956899973","pt":1724551521599,"mc":[{"id":"1.232224255","rc":[{"batb":[[0,1.72,5],[1,1.71,60.49],[2,1.21,24.75]],"ltp":1.75,"tv":110.16,"id":61422697},{"batb":[[0,2.24,5],[1,2.22,35.2],[2,1.21,24.75]],"ltp":2.22,"tv":10.0,"id":60971788}]}]}
{"op":"mcm","clk":"11956900161","pt":1724551524967,"mc":[{"id":"1.232224255","rc":[{"batb":[[0,1.71,60.49],[1,1.21,24.75],[2,1.08,1.76]],"ltp":1.75,"tv":110.16,"id":61422697},{"batb":[[0,2.22,35.2],[1,1.21,24.75],[2,1.08,1.76]],"ltp":2.22,"tv":10.0,"id":60971788}]}]}
{"op":"mcm","clk":"11956900323","pt":1724551528099,"mc":[{"id":"1.232224255","rc":[{"batb":[[0,1.72,5],[1,1.71,60.49],[2,1.21,24.75]],"ltp":1.75,"tv":110.16,"id":61422697},{"batb":[[0,2.24,5],[1,2.22,35.2],[2,1.21,24.75]],"ltp":2.22,"tv":10.0,"id":60971788}]}]}
{"op":"mcm","clk":"11956900498","pt":1724551531413,"mc":[{"id":"1.232224255","rc":[{"batb":[[0,1.71,60.49],[1,1.21,24.75],[2,1.08,1.76]],"ltp":1.75,"tv":110.16,"id":61422697},{"batb":[[0,2.22,35.2],[1,1.21,24.75],[2,1.08,1.76]],"ltp":2.22,"tv":10.0,"id":60971788}]}]}
{"op":"mcm","clk":"11956900631","pt":1724551534091,"mc":[{"id":"1.232224255","rc":[{"batb":[[0,1.72,5],[1,1.71,60.49],[2,1.21,24.75]],"ltp":1.75,"tv":110.16,"id":61422697},{"batb":[[0,2.24,5],[1,2.22,35.2],[2,1.21,24.75]],"ltp":2.22,"tv":10.0,"id":60971788}]}]}
{"op":"mcm","clk":"11956900842","pt":1724551537389,"mc":[{"id":"1.232224255","rc":[{"batb":[[0,1.71,60.49],[1,1.21,24.75],[2,1.08,1.76]],"ltp":1.75,"tv":110.16,"id":61422697},{"batb":[[0,2.22,35.2],[1,1.21,24.75],[2,1.08,1.76]],"ltp":2.22,"tv":10.0,"id":60971788}]}]}
{"op":"mcm","clk":"11956900965","pt":1724551539594,"mc":[{"id":"1.232224255","rc":[{"batb":[[0,1.72,5],[1,1.71,60.49],[2,1.21,24.75]],"ltp":1.75,"tv":110.16,"id":61422697},{"batb":[[0,2.24,5],[1,2.22,35.2],[2,1.21,24.75]],"ltp":2.22,"tv":10.0,"id":60971788}]}]}
{"op":"mcm","clk":"11956901150","pt":1724551542789,"mc":[{"id":"1.232224255","rc":[{"batb":[[0,1.71,60.49],[1,1.21,24.75],[2,1.08,1.76]],"ltp":1.75,"tv":110.16,"id":61422697},{"batb":[[0,2.22,35.2],[1,1.21,24.75],[2,1.08,1.76]],"ltp":2.22,"tv":10.0,"id":60971788}]}]}
{"op":"mcm","clk":"11956901285","pt":1724551545620,"mc":[{"id":"1.232224255","rc":[{"batb":[[0,1.72,5],[1,1.71,60.49],[2,1.21,24.75]],"ltp":1.75,"tv":110.16,"id":61422697},{"batb":[[0,2.24,5],[1,2.22,35.2],[2,1.21,24.75]],"ltp":2.22,"tv":10.0,"id":60971788}]}]}
{"op":"mcm","clk":"11956901469","pt":1724551548892,"mc":[{"id":"1.232224255","rc":[{"batb":[[0,1.71,60.49],[1,1.21,24.75],[2,1.08,1.76]],"ltp":1.75,"tv":110.16,"id":61422697},{"batb":[[0,2.22,35.2],[1,1.21,24.75],[2,1.08,1.76]],"ltp":2.22,"tv":10.0,"id":60971788}]}]}
{"op":"mcm","clk":"11956901597","pt":1724551551018,"mc":[{"id":"1.232224255","rc":[{"batb":[[0,1.72,5],[1,1.71,60.49],[2,1.21,24.75]],"ltp":1.75,"tv":110.16,"id":61422697},{"batb":[[0,2.24,5],[1,2.22,35.2],[2,1.21,24.75]],"ltp":2.22,"tv":10.0,"id":60971788}]}]}
{"op":"mcm","clk":"11956901777","pt":1724551554506,"mc":[{"id":"1.232224255","rc":[{"batb":[[0,1.71,60.49],[1,1.21,24.75],[2,1.08,1.76]],"ltp":1.75,"tv":110.16,"id":61422697},{"batb":[[0,2.22,35.2],[1,1.21,24.75],[2,1.08,1.76]],"ltp":2.22,"tv":10.0,"id":60971788}]}]}
{"op":"mcm","clk":"11956901968","pt":1724551557793,"mc":[{"id":"1.232224255","rc":[{"batb":[[0,1.72,5],[1,1.71,60.49],[2,1.21,24.75]],"ltp":1.75,"tv":110.16,"id":61422697},{"batb":[[0,2.24,5],[1,2.22,35.2],[2,1.21,24.75]],"ltp":2.22,"tv":10.0,"id":60971788}]}]}
{"op":"mcm","clk":"11956902203","pt":1724551561212,"mc":[{"id":"1.232224255","rc":[{"batb":[[0,1.71,60.49],[1,1.21,24.75],[2,1.08,1.76]],"ltp":1.75,"tv":110.16,"id":61422697},{"batb":[[0,2.22,35.2],[1,1.21,24.75],[2,1.08,1.76]],"ltp":2.22,"tv":10.0,"id":60971788}]}]}
{"op":"mcm","clk":"11956902437","pt":1724551564146,"mc":[{"id":"1.232224255","rc":[{"batb":[[0,1.72,5],[1,1.71,60.49],[2,1.21,24.75]],"ltp":1.75,"tv":110.16,"id":61422697},{"batb":[[0,2.24,5],[1,2.22,35.2],[2,1.21,24.75]],"ltp":2.22,"tv":10.0,"id":60971788}]}]}
{"op":"mcm","clk":"11956902675","pt":1724551567655,"mc":[{"id":"1.232224255","rc":[{"batb":[[0,1.71,60.49],[1,1.21,24.75],[2,1.08,1.76]],"ltp":1.75,"tv":110.16,"id":61422697},{"batb":[[0,2.22,35.2],[1,1.21,24.75],[2,1.08,1.76]],"ltp":2.22,"tv":10.0,"id":60971788}]}]}
{"op":"mcm","clk":"11956902903","pt":1724551570857,"mc":[{"id":"1.232224255","rc":[{"batb":[[0,1.72,5],[1,1.71,60.49],[2,1.21,24.75]],"ltp":1.75,"tv":110.16,"id":61422697},{"batb":[[0,2.24,5],[1,2.22,35.2],[2,1.21,24.75]],"ltp":2.22,"tv":10.0,"id":60971788}]}]}
{"op":"mcm","clk":"11956903093","pt":1724551574162,"mc":[{"id":"1.232224255","rc":[{"batb":[[0,1.71,60.49],[1,1.21,24.75],[2,1.08,1.76]],"ltp":1.75,"tv":110.16,"id":61422697},{"batb":[[0,2.22,35.2],[1,1.21,24.75],[2,1.08,1.76]],"ltp":2.22,"tv":10.0,"id":60971788}]}]}
{"op":"mcm","clk":"11956903244","pt":1724551576546,"mc":[{"id":"1.232224255","rc":[{"batb":[[0,1.72,5],[1,1.71,60.49],[2,1.21,24.75]],"ltp":1.75,"tv":110.16,"id":61422697},{"batb":[[0,2.24,5],[1,2.22,35.2],[2,1.21,24.75]],"ltp":2.22,"tv":10.0,"id":60971788}]}]}
{"op":"mcm","clk":"11956903473","pt":1724551579753,"mc":[{"id":"1.232224255","rc":[{"batb":[[0,1.71,60.49],[1,1.21,24.75],[2,1.08,1.76]],"ltp":1.75,"tv":110.16,"id":61422697},{"batb":[[0,2.22,35.2],[1,1.21,24.75],[2,1.08,1.76]],"ltp":2.22,"tv":10.0,"id":60971788}]}]}
{"op":"mcm","clk":"11956903606","pt":1724551581959,"mc":[{"id":"1.232224255","rc":[{"batb":[[0,1.72,5],[1,1.71,60.49],[2,1.21,24.75]],"ltp":1.75,"tv":110.16,"id":61422697},{"batb":[[0,2.24,5],[1,2.22,35.2],[2,1.21,24.75]],"ltp":2.22,"tv":10.0,"id":60971788}]}]}
{"op":"mcm","clk":"11956903825","pt":1724551585254,"mc":[{"id":"1.232224255","rc":[{"batb":[[0,1.71,60.49],[1,1.21,24.75],[2,1.08,1.76]],"ltp":1.75,"tv":110.16,"id":61422697},{"batb":[[0,2.22,35.2],[1,1.21,24.75],[2,1.08,1.76]],"ltp":2.22,"tv":10.0,"id":60971788}]}]}
{"op":"mcm","clk":"11956903958","pt":1724551587468,"mc":[{"id":"1.232224255","rc":[{"batb":[[0,1.72,5],[1,1.71,60.49],[2,1.21,24.75]],"ltp":1.75,"tv":110.16,"id":61422697},{"batb":[[0,2.24,5],[1,2.22,35.2],[2,1.21,24.75]],"ltp":2.22,"tv":10.0,"id":60971788}]}]}
{"op":"mcm","clk":"11956904152","pt":1724551590764,"mc":[{"id":"1.232224255","rc":[{"batb":[[0,1.71,60.49],[1,1.21,24.75],[2,1.08,1.76]],"ltp":1.75,"tv":110.16,"id":61422697},{"batb":[[0,2.22,35.2],[1,1.21,24.75],[2,1.08,1.76]],"ltp":2.22,"tv":10.0,"id":60971788}]}]}
{"op":"mcm","clk":"11956904370","pt":1724551594062,"mc":[{"id":"1.232224255","rc":[{"batb":[[0,1.72,5],[1,1.71,60.49],[2,1.21,24.75]],"ltp":1.75,"tv":110.16,"id":61422697},{"batb":[[0,2.24,5],[1,2.22,35.2],[2,1.21,24.75]],"ltp":2.22,"tv":10.0,"id":60971788}]}]}
{"op":"mcm","clk":"11956904577","pt":1724551597375,"mc":[{"id":"1.232224255","rc":[{"batb":[[0,1.71,60.49],[1,1.21,24.75],[2,1.08,1.76]],"ltp":1.75,"tv":110.16,"id":61422697},{"batb":[[0,2.22,35.2],[1,1.21,24.75],[2,1.08,1.76]],"ltp":2.22,"tv":10.0,"id":60971788}]}]}
{"op":"mcm","clk":"11956904829","pt":1724551601174,"mc":[{"id":"1.232224255","rc":[{"batb":[[0,1.72,5],[1,1.71,60.49],[2,1.21,24.75]],"ltp":1.75,"tv":110.16,"id":61422697},{"batb":[[0,2.24,5],[1,2.22,35.2],[2,1.21,24.75]],"ltp":2.22,"tv":10.0,"id":60971788}]}]}
{"op":"mcm","clk":"11956905015","pt":1724551604574,"mc":[{"id":"1.232224255","rc":[{"batb":[[0,1.71,60.49],[1,1.21,24.75],[2,1.08,1.76]],"ltp":1.75,"tv":110.16,"id":61422697},{"batb":[[0,2.22,35.2],[1,1.21,24.75],[2,1.08,1.76]],"ltp":2.22,"tv":10.0,"id":60971788}]}]}
{"op":"mcm","clk":"11956905179","pt":1724551607002,"mc":[{"id":"1.232224255","rc":[{"batb":[[0,1.72,5],[1,1.71,60.49],[2,1.21,24.75]],"ltp":1.75,"tv":110.16,"id":61422697},{"batb":[[0,2.24,5],[1,2.22,35.2],[2,1.21,24.75]],"ltp":2.22,"tv":10.0,"id":60971788}]}]}
{"op":"mcm","clk":"11956905426","pt":1724551610511,"mc":[{"id":"1.232224255","rc":[{"batb":[[0,1.71,60.49],[1,1.21,24.75],[2,1.08,1.76]],"ltp":1.75,"tv":110.16,"id":61422697},{"batb":[[0,2.22,35.2],[1,1.21,24.75],[2,1.08,1.76]],"ltp":2.22,"tv":10.0,"id":60971788}]}]}
{"op":"mcm","clk":"11956905690","pt":1724551613814,"mc":[{"id":"1.232224255","rc":[{"batb":[[0,1.72,5],[1,1.71,60.49],[2,1.21,24.75]],"ltp":1.75,"tv":110.16,"id":61422697},{"batb":[[0,2.24,5],[1,2.22,35.2],[2,1.21,24.75]],"ltp":2.22,"tv":10.0,"id":60971788}]}]}
{"op":"mcm","clk":"11956905929","pt":1724551617216,"mc":[{"id":"1.232224255","rc":[{"batb":[[0,1.71,60.49],[1,1.21,24.75],[2,1.08,1.76]],"ltp":1.75,"tv":110.16,"id":61422697},{"batb":[[0,2.22,35.2],[1,1.21,24.75],[2,1.08,1.76]],"ltp":2.22,"tv":10.0,"id":60971788}]}]}
{"op":"mcm","clk":"11956906175","pt":1724551619978,"mc":[{"id":"1.232224255","rc":[{"batb":[[0,1.72,5],[1,1.71,60.49],[2,1.21,24.75]],"ltp":1.75,"tv":110.16,"id":61422697},{"batb":[[0,2.24,5],[1,2.22,35.2],[2,1.21,24.75]],"ltp":2.22,"tv":10.0,"id":60971788}]}]}
{"op":"mcm","clk":"11956906403","pt":1724551623185,"mc":[{"id":"1.232224255","rc":[{"batb":[[0,1.71,60.49],[1,1.21,24.75],[2,1.08,1.76]],"ltp":1.75,"tv":110.16,"id":61422697},{"batb":[[0,2.22,35.2],[1,1.21,24.75],[2,1.08,1.76]],"ltp":2.22,"tv":10.0,"id":60971788}]}]}
{"op":"mcm","clk":"11956906650","pt":1724551626596,"mc":[{"id":"1.232224255","rc":[{"batb":[[0,1.72,5],[1,1.71,60.49],[2,1.21,24.75]],"ltp":1.75,"tv":110.16,"id":61422697},{"batb":[[0,2.24,5],[1,2.22,35.2],[2,1.21,24.75]],"ltp":2.22,"tv":10.0,"id":60971788}]}]}
{"op":"mcm","clk":"11956906931","pt":1724551629799,"mc":[{"id":"1.232224255","rc":[{"batb":[[0,2.22,35.2],[1,1.21,24.75],[2,1.08,1.76]],"ltp":2.22,"tv":10.0,"id":60971788}]}]}
{"op":"mcm","clk":"11956906938","pt":1724551629901,"mc":[{"id":"1.232224255","rc":[{"batb":[[0,1.71,60.49],[1,1.21,24.75],[2,1.08,1.76]],"ltp":1.75,"tv":110.16,"id":61422697}]}]}
{"op":"mcm","clk":"11956907125","pt":1724551632424,"mc":[{"id":"1.232224255","rc":[{"batb":[[0,1.72,5],[1,1.71,60.49],[2,1.21,24.75]],"ltp":1.75,"tv":110.16,"id":61422697},{"batb":[[0,2.24,5],[1,2.22,35.2],[2,1.21,24.75]],"ltp":2.22,"tv":10.0,"id":60971788}]}]}
{"op":"mcm","clk":"11956907385","pt":1724551635737,"mc":[{"id":"1.232224255","rc":[{"batb":[[0,1.71,60.49],[1,1.21,24.75],[2,1.08,1.76]],"ltp":1.75,"tv":110.16,"id":61422697},{"batb":[[0,2.22,35.2],[1,1.21,24.75],[2,1.08,1.76]],"ltp":2.22,"tv":10.0,"id":60971788}]}]}
{"op":"mcm","clk":"11956907556","pt":1724551638130,"mc":[{"id":"1.232224255","rc":[{"batb":[[0,1.72,5],[1,1.71,60.49],[2,1.21,24.75]],"ltp":1.75,"tv":110.16,"id":61422697},{"batb":[[0,2.24,5],[1,2.22,35.2],[2,1.21,24.75]],"ltp":2.22,"tv":10.0,"id":60971788}]}]}
{"op":"mcm","clk":"11956907806","pt":1724551641432,"mc":[{"id":"1.232224255","rc":[{"batb":[[0,1.71,60.49],[1,1.21,24.75],[2,1.08,1.76]],"ltp":1.75,"tv":110.16,"id":61422697},{"batb":[[0,2.22,35.2],[1,1.21,24.75],[2,1.08,1.76]],"ltp":2.22,"tv":10.0,"id":60971788}]}]}
{"op":"mcm","clk":"11956907977","pt":1724551644216,"mc":[{"id":"1.232224255","rc":[{"batb":[[0,1.72,5],[1,1.71,60.49],[2,1.21,24.75]],"ltp":1.75,"tv":110.16,"id":61422697},{"batb":[[0,2.24,5],[1,2.22,35.2],[2,1.21,24.75]],"ltp":2.22,"tv":10.0,"id":60971788}]}]}
{"op":"mcm","clk":"11956908216","pt":1724551647522,"mc":[{"id":"1.232224255","rc":[{"batb":[[0,1.71,60.49],[1,1.21,24.75],[2,1.08,1.76]],"ltp":1.75,"tv":110.16,"id":61422697},{"batb":[[0,2.22,35.2],[1,1.21,24.75],[2,1.08,1.76]],"ltp":2.22,"tv":10.0,"id":60971788}]}]}
{"op":"mcm","clk":"11956908476","pt":1724551651029,"mc":[{"id":"1.232224255","rc":[{"batb":[[0,1.72,5],[1,1.71,60.49],[2,1.21,24.75]],"ltp":1.75,"tv":110.16,"id":61422697},{"batb":[[0,2.24,5],[1,2.22,35.2],[2,1.21,24.75]],"ltp":2.22,"tv":10.0,"id":60971788}]}]}
{"op":"mcm","clk":"11956908716","pt":1724551654325,"mc":[{"id":"1.232224255","rc":[{"batb":[[0,1.71,60.49],[1,1.21,24.75],[2,1.08,1.76]],"ltp":1.75,"tv":110.16,"id":61422697},{"batb":[[0,2.22,35.2],[1,1.21,24.75],[2,1.08,1.76]],"ltp":2.22,"tv":10.0,"id":60971788}]}]}
{"op":"mcm","clk":"11956908906","pt":1724551656844,"mc":[{"id":"1.232224255","rc":[{"batb":[[0,1.72,5],[1,1.71,60.49],[2,1.21,24.75]],"ltp":1.75,"tv":110.16,"id":61422697},{"batb":[[0,2.24,5],[1,2.22,35.2],[2,1.21,24.75]],"ltp":2.22,"tv":10.0,"id":60971788}]}]}
{"op":"mcm","clk":"11956909143","pt":1724551660151,"mc":[{"id":"1.232224255","rc":[{"batb":[[0,1.71,60.49],[1,1.21,24.75],[2,1.08,1.76]],"ltp":1.75,"tv":110.16,"id":61422697},{"batb":[[0,2.22,35.2],[1,1.21,24.75],[2,1.08,1.76]],"ltp":2.22,"tv":10.0,"id":60971788}]}]}
{"op":"mcm","clk":"11956909464","pt":1724551664277,"mc":[{"id":"1.232224255","rc":[{"batb":[[0,1.72,5],[1,1.71,60.49],[2,1.21,24.75]],"ltp":1.75,"tv":110.16,"id":61422697},{"batb":[[0,2.24,5],[1,2.22,35.2],[2,1.21,24.75]],"ltp":2.22,"tv":10.0,"id":60971788}]}]}
{"op":"mcm","clk":"11956909701","pt":1724551667475,"mc":[{"id":"1.232224255","rc":[{"batb":[[0,1.71,60.49],[1,1.21,24.75],[2,1.08,1.76]],"ltp":1.75,"tv":110.16,"id":61422697},{"batb":[[0,2.22,35.2],[1,1.21,24.75],[2,1.08,1.76]],"ltp":2.22,"tv":10.0,"id":60971788}]}]}
{"op":"mcm","clk":"11956909889","pt":1724551670152,"mc":[{"id":"1.232224255","rc":[{"batb":[[0,1.72,5],[1,1.71,60.49],[2,1.21,24.75]],"ltp":1.75,"tv":110.16,"id":61422697},{"batb":[[0,2.24,5],[1,2.22,35.2],[2,1.21,24.75]],"ltp":2.22,"tv":10.0,"id":60971788}]}]}
{"op":"mcm","clk":"11956910140","pt":1724551673493,"mc":[{"id":"1.232224255","rc":[{"batb":[[0,1.71,60.49],[1,1.21,24.75],[2,1.08,1.76]],"ltp":1.75,"tv":110.16,"id":61422697},{"batb":[[0,2.22,35.2],[1,1.21,24.75],[2,1.08,1.76]],"ltp":2.22,"tv":10.0,"id":60971788}]}]}
{"op":"mcm","clk":"11956910347","pt":1724551676685,"mc":[{"id":"1.232224255","rc":[{"batb":[[0,1.72,5],[1,1.71,60.49],[2,1.21,24.75]],"ltp":1.75,"tv":110.16,"id":61422697},{"batb":[[0,2.24,5],[1,2.22,35.2],[2,1.21,24.75]],"ltp":2.22,"tv":10.0,"id":60971788}]}]}
{"op":"mcm","clk":"11956910581","pt":1724551680076,"mc":[{"id":"1.232224255","rc":[{"batb":[[0,1.71,60.49],[1,1.21,24.75],[2,1.08,1.76]],"ltp":1.75,"tv":110.16,"id":61422697},{"batb":[[0,2.22,35.2],[1,1.21,24.75],[2,1.08,1.76]],"ltp":2.22,"tv":10.0,"id":60971788}]}]}
{"op":"mcm","clk":"11956910809","pt":1724551683379,"mc":[{"id":"1.232224255","rc":[{"batb":[[0,1.72,5],[1,1.71,60.49],[2,1.21,24.75]],"ltp":1.75,"tv":110.16,"id":61422697},{"batb":[[0,2.24,5],[1,2.22,35.2],[2,1.21,24.75]],"ltp":2.22,"tv":10.0,"id":60971788}]}]}
{"op":"mcm","clk":"11956911044","pt":1724551686776,"mc":[{"id":"1.232224255","rc":[{"batb":[[0,1.71,60.49],[1,1.21,24.75],[2,1.08,1.76]],"ltp":1.75,"tv":110.16,"id":61422697},{"batb":[[0,2.22,35.2],[1,1.21,24.75],[2,1.08,1.76]],"ltp":2.22,"tv":10.0,"id":60971788}]}]}
{"op":"mcm","clk":"11956911269","pt":1724551689763,"mc":[{"id":"1.232224255","rc":[{"batb":[[0,1.72,5],[1,1.71,60.49],[2,1.21,24.75]],"ltp":1.75,"tv":110.16,"id":61422697},{"batb":[[0,2.24,5],[1,2.22,35.2],[2,1.21,24.75]],"ltp":2.22,"tv":10.0,"id":60971788}]}]}
{"op":"mcm","clk":"11956911596","pt":1724551693082,"mc":[{"id":"1.232224255","rc":[{"batb":[[0,1.71,60.49],[1,1.21,24.75],[2,1.08,1.76]],"ltp":1.75,"tv":110.16,"id":61422697},{"batb":[[0,2.22,35.2],[1,1.21,24.75],[2,1.08,1.76]],"ltp":2.22,"tv":10.0,"id":60971788}]}]}
{"op":"mcm","clk":"11956911759","pt":1724551695521,"mc":[{"id":"1.232224255","rc":[{"batb":[[0,1.72,5],[1,1.71,60.49],[2,1.21,24.75]],"ltp":1.75,"tv":110.16,"id":61422697},{"batb":[[0,2.24,5],[1,2.22,35.2],[2,1.21,24.75]],"ltp":2.22,"tv":10.0,"id":60971788}]}]}
{"op":"mcm","clk":"11956912016","pt":1724551698878,"mc":[{"id":"1.232224255","rc":[{"batb":[[0,1.71,60.49],[1,1.21,24.75],[2,1.08,1.76]],"ltp":1.75,"tv":110.16,"id":61422697},{"batb":[[0,2.22,35.2],[1,1.21,24.75],[2,1.08,1.76]],"ltp":2.22,"tv":10.0,"id":60971788}]}]}
{"op":"mcm","clk":"11956912219","pt":1724551701705,"mc":[{"id":"1.232224255","rc":[{"batb":[[0,1.72,5],[1,1.71,60.49],[2,1.21,24.75]],"ltp":1.75,"tv":110.16,"id":61422697},{"batb":[[0,2.24,5],[1,2.22,35.2],[2,1.21,24.75]],"ltp":2.22,"tv":10.0,"id":60971788}]}]}
{"op":"mcm","clk":"11956912470","pt":1724551705112,"mc":[{"id":"1.232224255","rc":[{"batb":[[0,1.71,60.49],[1,1.21,24.75],[2,1.08,1.76]],"ltp":1.75,"tv":110.16,"id":61422697},{"batb":[[0,2.22,35.2],[1,1.21,24.75],[2,1.08,1.76]],"ltp":2.22,"tv":10.0,"id":60971788}]}]}
{"op":"mcm","clk":"11956912653","pt":1724551707986,"mc":[{"id":"1.232224255","rc":[{"batb":[[0,1.72,5],[1,1.71,60.49],[2,1.21,24.75]],"ltp":1.75,"tv":110.16,"id":61422697},{"batb":[[0,2.24,5],[1,2.22,35.2],[2,1.21,24.75]],"ltp":2.22,"tv":10.0,"id":60971788}]}]}
{"op":"mcm","clk":"11956912983","pt":1724551711490,"mc":[{"id":"1.232224255","rc":[{"batb":[[0,1.71,60.49],[1,1.21,24.75],[2,1.08,1.76]],"ltp":1.75,"tv":110.16,"id":61422697},{"batb":[[0,2.22,35.2],[1,1.21,24.75],[2,1.08,1.76]],"ltp":2.22,"tv":10.0,"id":60971788}]}]}
{"op":"mcm","clk":"11956913287","pt":1724551715308,"mc":[{"id":"1.232224255","rc":[{"batb":[[0,1.72,5],[1,1.71,60.49],[2,1.21,24.75]],"ltp":1.75,"tv":110.16,"id":61422697},{"batb":[[0,2.24,5],[1,2.22,35.2],[2,1.21,24.75]],"ltp":2.22,"tv":10.0,"id":60971788}]}]}
{"op":"mcm","clk":"11956913534","pt":1724551718723,"mc":[{"id":"1.232224255","rc":[{"batb":[[0,1.71,60.49],[1,1.21,24.75],[2,1.08,1.76]],"ltp":1.75,"tv":110.16,"id":61422697},{"batb":[[0,2.22,35.2],[1,1.21,24.75],[2,1.08,1.76]],"ltp":2.22,"tv":10.0,"id":60971788}]}]}
{"op":"mcm","clk":"11956913768","pt":1724551722125,"mc":[{"id":"1.232224255","rc":[{"batb":[[0,1.72,5],[1,1.71,60.49],[2,1.21,24.75]],"ltp":1.75,"tv":110.16,"id":61422697},{"batb":[[0,2.24,5],[1,2.22,35.2],[2,1.21,24.75]],"ltp":2.22,"tv":10.0,"id":60971788}]}]}
{"op":"mcm","clk":"11956914014","pt":1724551725730,"mc":[{"id":"1.232224255","rc":[{"batb":[[0,1.71,60.49],[1,1.21,24.75],[2,1.08,1.76]],"ltp":1.75,"tv":110.16,"id":61422697},{"batb":[[0,2.22,35.2],[1,1.21,24.75],[2,1.08,1.76]],"ltp":2.22,"tv":10.0,"id":60971788}]}]}
{"op":"mcm","clk":"11956914222","pt":1724551728217,"mc":[{"id":"1.232224255","rc":[{"batb":[[0,1.72,5],[1,1.71,60.49],[2,1.21,24.75]],"ltp":1.75,"tv":110.16,"id":61422697},{"batb":[[0,2.24,5],[1,2.22,35.2],[2,1.21,24.75]],"ltp":2.22,"tv":10.0,"id":60971788}]}]}
{"op":"mcm","clk":"11956914481","pt":1724551731559,"mc":[{"id":"1.232224255","rc":[{"batb":[[0,1.71,60.49],[1,1.21,24.75],[2,1.08,1.76]],"ltp":1.75,"tv":110.16,"id":61422697},{"batb":[[0,2.22,35.2],[1,1.21,24.75],[2,1.08,1.76]],"ltp":2.22,"tv":10.0,"id":60971788}]}]}
{"op":"mcm","clk":"11956914662","pt":1724551733933,"mc":[{"id":"1.232224255","rc":[{"batb":[[0,1.72,5],[1,1.71,60.49],[2,1.21,24.75]],"ltp":1.75,"tv":110.16,"id":61422697},{"batb":[[0,2.24,5],[1,2.22,35.2],[2,1.21,24.75]],"ltp":2.22,"tv":10.0,"id":60971788}]}]}
{"op":"mcm","clk":"11956914885","pt":1724551737281,"mc":[{"id":"1.232224255","rc":[{"batb":[[0,1.71,60.49],[1,1.21,24.75],[2,1.08,1.76]],"ltp":1.75,"tv":110.16,"id":61422697},{"batb":[[0,2.22,35.2],[1,1.21,24.75],[2,1.08,1.76]],"ltp":2.22,"tv":10.0,"id":60971788}]}]}
{"op":"mcm","clk":"11956915210","pt":1724551741460,"mc":[{"id":"1.232224255","rc":[{"batb":[[0,1.72,5],[1,1.71,60.49],[2,1.21,24.75]],"ltp":1.75,"tv":110.16,"id":61422697},{"batb":[[0,2.24,5],[1,2.22,35.2],[2,1.21,24.75]],"ltp":2.22,"tv":10.0,"id":60971788}]}]}
{"op":"mcm","clk":"11956915460","pt":1724551744883,"mc":[{"id":"1.232224255","rc":[{"batb":[[0,1.71,60.49],[1,1.21,24.75],[2,1.08,1.76]],"ltp":1.75,"tv":110.16,"id":61422697},{"batb":[[0,2.22,35.2],[1,1.21,24.75],[2,1.08,1.76]],"ltp":2.22,"tv":10.0,"id":60971788}]}]}
{"op":"mcm","clk":"11956915668","pt":1724551747367,"mc":[{"id":"1.232224255","rc":[{"batb":[[0,1.72,5],[1,1.71,60.49],[2,1.21,24.75]],"ltp":1.75,"tv":110.16,"id":61422697},{"batb":[[0,2.24,5],[1,2.22,35.2],[2,1.21,24.75]],"ltp":2.22,"tv":10.0,"id":60971788}]}]}
{"op":"mcm","clk":"11956915882","pt":1724551750672,"mc":[{"id":"1.232224255","rc":[{"batb":[[0,1.71,60.49],[1,1.21,24.75],[2,1.08,1.76]],"ltp":1.75,"tv":110.16,"id":61422697},{"batb":[[0,2.22,35.2],[1,1.21,24.75],[2,1.08,1.76]],"ltp":2.22,"tv":10.0,"id":60971788}]}]}
{"op":"mcm","clk":"11956916265","pt":1724551755880,"mc":[{"id":"1.232224255","rc":[{"batb":[[0,1.72,5],[1,1.71,60.49],[2,1.21,24.75]],"ltp":1.75,"tv":110.16,"id":61422697},{"batb":[[0,2.24,5],[1,2.22,35.2],[2,1.21,24.75]],"ltp":2.22,"tv":10.0,"id":60971788}]}]}
{"op":"mcm","clk":"11956916509","pt":1724551759185,"mc":[{"id":"1.232224255","rc":[{"batb":[[0,1.71,60.49],[1,1.21,24.75],[2,1.08,1.76]],"ltp":1.75,"tv":110.16,"id":61422697},{"batb":[[0,2.22,35.2],[1,1.21,24.75],[2,1.08,1.76]],"ltp":2.22,"tv":10.0,"id":60971788}]}]}
{"op":"mcm","clk":"11956916765","pt":1724551762282,"mc":[{"id":"1.232224255","rc":[{"batb":[[0,1.72,5],[1,1.71,60.49],[2,1.21,24.75]],"ltp":1.75,"tv":110.16,"id":61422697},{"batb":[[0,2.24,5],[1,2.22,35.2],[2,1.21,24.75]],"ltp":2.22,"tv":10.0,"id":60971788}]}]}
{"op":"mcm","clk":"11956917011","pt":1724551765574,"mc":[{"id":"1.232224255","rc":[{"batb":[[0,1.71,60.49],[1,1.21,24.75],[2,1.08,1.76]],"ltp":1.75,"tv":110.16,"id":61422697},{"batb":[[0,2.22,35.2],[1,1.21,24.75],[2,1.08,1.76]],"ltp":2.22,"tv":10.0,"id":60971788}]}]}
{"op":"mcm","clk":"11956917200","pt":1724551768091,"mc":[{"id":"1.232224255","rc":[{"batb":[[0,1.72,5],[1,1.71,60.49],[2,1.21,24.75]],"ltp":1.75,"tv":110.16,"id":61422697},{"batb":[[0,2.24,5],[1,2.22,35.2],[2,1.21,24.75]],"ltp":2.22,"tv":10.0,"id":60971788}]}]}
{"op":"mcm","clk":"11956917449","pt":1724551771377,"mc":[{"id":"1.232224255","rc":[{"batb":[[0,1.71,60.49],[1,1.21,24.75],[2,1.08,1.76]],"ltp":1.75,"tv":110.16,"id":61422697},{"batb":[[0,2.22,35.2],[1,1.21,24.75],[2,1.08,1.76]],"ltp":2.22,"tv":10.0,"id":60971788}]}]}
{"op":"mcm","clk":"11956917595","pt":1724551773596,"mc":[{"id":"1.232224255","rc":[{"batb":[[0,1.72,5],[1,1.71,60.49],[2,1.21,24.75]],"ltp":1.75,"tv":110.16,"id":61422697},{"batb":[[0,2.24,5],[1,2.22,35.2],[2,1.21,24.75]],"ltp":2.22,"tv":10.0,"id":60971788}]}]}
{"op":"mcm","clk":"11956917833","pt":1724551777219,"mc":[{"id":"1.232224255","rc":[{"batb":[[0,1.71,60.49],[1,1.21,24.75],[2,1.08,1.76]],"ltp":1.75,"tv":110.16,"id":61422697},{"batb":[[0,2.22,35.2],[1,1.21,24.75],[2,1.08,1.76]],"ltp":2.22,"tv":10.0,"id":60971788}]}]}
{"op":"mcm","clk":"11956918102","pt":1724551780824,"mc":[{"id":"1.232224255","rc":[{"batb":[[0,1.72,5],[1,1.71,60.49],[2,1.21,24.75]],"ltp":1.75,"tv":110.16,"id":61422697},{"batb":[[0,2.24,5],[1,2.22,35.2],[2,1.21,24.75]],"ltp":2.22,"tv":10.0,"id":60971788}]}]}
{"op":"mcm","clk":"11956918337","pt":1724551784113,"mc":[{"id":"1.232224255","rc":[{"batb":[[0,1.71,60.49],[1,1.21,24.75],[2,1.08,1.76]],"ltp":1.75,"tv":110.16,"id":61422697},{"batb":[[0,2.22,35.2],[1,1.21,24.75],[2,1.08,1.76]],"ltp":2.22,"tv":10.0,"id":60971788}]}]}
{"op":"mcm","clk":"11956918524","pt":1724551787109,"mc":[{"id":"1.232224255","rc":[{"batb":[[0,1.72,5],[1,1.71,60.49],[2,1.21,24.75]],"ltp":1.75,"tv":110.16,"id":61422697},{"batb":[[0,2.24,5],[1,2.22,35.2],[2,1.21,24.75]],"ltp":2.22,"tv":10.0,"id":60971788}]}]}
{"op":"mcm","clk":"11956918730","pt":1724551790514,"mc":[{"id":"1.232224255","rc":[{"batb":[[0,1.71,60.49],[1,1.21,24.75],[2,1.08,1.76]],"ltp":1.75,"tv":110.16,"id":61422697},{"batb":[[0,2.22,35.2],[1,1.21,24.75],[2,1.08,1.76]],"ltp":2.22,"tv":10.0,"id":60971788}]}]}
{"op":"mcm","clk":"11956918864","pt":1724551792729,"mc":[{"id":"1.232224255","rc":[{"batb":[[0,1.72,5],[1,1.71,60.49],[2,1.21,24.75]],"ltp":1.75,"tv":110.16,"id":61422697},{"batb":[[0,2.24,5],[1,2.22,35.2],[2,1.21,24.75]],"ltp":2.22,"tv":10.0,"id":60971788}]}]}
{"op":"mcm","clk":"11956919069","pt":1724551796127,"mc":[{"id":"1.232224255","rc":[{"batb":[[0,1.71,60.49],[1,1.21,24.75],[2,1.08,1.76]],"ltp":1.75,"tv":110.16,"id":61422697},{"batb":[[0,2.22,35.2],[1,1.21,24.75],[2,1.08,1.76]],"ltp":2.22,"tv":10.0,"id":60971788}]}]}
{"op":"mcm","clk":"11956919220","pt":1724551799219,"mc":[{"id":"1.232224255","rc":[{"batb":[[0,1.72,5],[1,1.71,60.49],[2,1.21,24.75]],"ltp":1.75,"tv":110.16,"id":61422697},{"batb":[[0,2.24,5],[1,2.22,35.2],[2,1.21,24.75]],"ltp":2.22,"tv":10.0,"id":60971788}]}]}
{"op":"mcm","clk":"11956919560","pt":1724551802510,"mc":[{"id":"1.232224255","rc":[{"batb":[[0,1.71,60.49],[1,1.21,24.75],[2,1.08,1.76]],"ltp":1.75,"tv":110.16,"id":61422697},{"batb":[[0,2.22,35.2],[1,1.21,24.75],[2,1.08,1.76]],"ltp":2.22,"tv":10.0,"id":60971788}]}]}
{"op":"mcm","clk":"11956919768","pt":1724551805607,"mc":[{"id":"1.232224255","rc":[{"batb":[[0,1.72,5],[1,1.71,60.49],[2,1.21,24.75]],"ltp":1.75,"tv":110.16,"id":61422697},{"batb":[[0,2.24,5],[1,2.22,35.2],[2,1.21,24.75]],"ltp":2.22,"tv":10.0,"id":60971788}]}]}
{"op":"mcm","clk":"11956919936","pt":1724551808907,"mc":[{"id":"1.232224255","rc":[{"batb":[[0,1.71,60.49],[1,1.21,24.75],[2,1.08,1.76]],"ltp":1.75,"tv":110.16,"id":61422697},{"batb":[[0,2.22,35.2],[1,1.21,24.75],[2,1.08,1.76]],"ltp":2.22,"tv":10.0,"id":60971788}]}]}
{"op":"mcm","clk":"11956920113","pt":1724551811430,"mc":[{"id":"1.232224255","rc":[{"batb":[[0,1.72,5],[1,1.71,60.49],[2,1.21,24.75]],"ltp":1.75,"tv":110.16,"id":61422697},{"batb":[[0,2.24,5],[1,2.22,35.2],[2,1.21,24.75]],"ltp":2.22,"tv":10.0,"id":60971788}]}]}
{"op":"mcm","clk":"11956920361","pt":1724551814748,"mc":[{"id":"1.232224255","rc":[{"batb":[[0,1.71,60.49],[1,1.21,24.75],[2,1.08,1.76]],"ltp":1.75,"tv":110.16,"id":61422697},{"batb":[[0,2.22,35.2],[1,1.21,24.75],[2,1.08,1.76]],"ltp":2.22,"tv":10.0,"id":60971788}]}]}
{"op":"mcm","clk":"11956920499","pt":1724551816918,"mc":[{"id":"1.232224255","rc":[{"batb":[[0,1.72,5],[1,1.71,60.49],[2,1.21,24.75]],"ltp":1.75,"tv":110.16,"id":61422697},{"batb":[[0,2.24,5],[1,2.22,35.2],[2,1.21,24.75]],"ltp":2.22,"tv":10.0,"id":60971788}]}]}
{"op":"mcm","clk":"11956920736","pt":1724551820265,"mc":[{"id":"1.232224255","rc":[{"batb":[[0,1.71,60.49],[1,1.21,24.75],[2,1.08,1.76]],"ltp":1.75,"tv":110.16,"id":61422697},{"batb":[[0,2.22,35.2],[1,1.21,24.75],[2,1.08,1.76]],"ltp":2.22,"tv":10.0,"id":60971788}]}]}
{"op":"mcm","clk":"11956920891","pt":1724551822442,"mc":[{"id":"1.232224255","rc":[{"batb":[[0,1.72,5],[1,1.71,60.49],[2,1.21,24.75]],"ltp":1.75,"tv":110.16,"id":61422697},{"batb":[[0,2.24,5],[1,2.22,35.2],[2,1.21,24.75]],"ltp":2.22,"tv":10.0,"id":60971788}]}]}
{"op":"mcm","clk":"11956921104","pt":1724551825739,"mc":[{"id":"1.232224255","rc":[{"batb":[[0,1.71,60.49],[1,1.21,24.75],[2,1.08,1.76]],"ltp":1.75,"tv":110.16,"id":61422697},{"batb":[[0,2.22,35.2],[1,1.21,24.75],[2,1.08,1.76]],"ltp":2.22,"tv":10.0,"id":60971788}]}]}
{"op":"mcm","clk":"11956921248","pt":1724551827958,"mc":[{"id":"1.232224255","rc":[{"batb":[[0,1.72,5],[1,1.71,60.49],[2,1.21,24.75]],"ltp":1.75,"tv":110.16,"id":61422697},{"batb":[[0,2.24,5],[1,2.22,35.2],[2,1.21,24.75]],"ltp":2.22,"tv":10.0,"id":60971788}]}]}
{"op":"mcm","clk":"11956921469","pt":1724551831264,"mc":[{"id":"1.232224255","rc":[{"batb":[[0,1.71,60.49],[1,1.21,24.75],[2,1.08,1.76]],"ltp":1.75,"tv":110.16,"id":61422697},{"batb":[[0,2.22,35.2],[1,1.21,24.75],[2,1.08,1.76]],"ltp":2.22,"tv":10.0,"id":60971788}]}]}
{"op":"mcm","clk":"11956921589","pt":1724551833378,"mc":[{"id":"1.232224255","rc":[{"batb":[[0,1.72,5],[1,1.71,60.49],[2,1.21,24.75]],"ltp":1.75,"tv":110.16,"id":61422697},{"batb":[[0,2.24,5],[1,2.22,35.2],[2,1.21,24.75]],"ltp":2.22,"tv":10.0,"id":60971788}]}]}
{"op":"mcm","clk":"11956921846","pt":1724551836783,"mc":[{"id":"1.232224255","rc":[{"batb":[[0,1.71,60.49],[1,1.21,24.75],[2,1.08,1.76]],"ltp":1.75,"tv":110.16,"id":61422697},{"batb":[[0,2.22,35.2],[1,1.21,24.75],[2,1.08,1.76]],"ltp":2.22,"tv":10.0,"id":60971788}]}]}
{"op":"mcm","clk":"11956922020","pt":1724551838948,"mc":[{"id":"1.232224255","rc":[{"batb":[[0,1.72,5],[1,1.71,60.49],[2,1.21,24.75]],"ltp":1.75,"tv":110.16,"id":61422697},{"batb":[[0,2.24,5],[1,2.22,35.2],[2,1.21,24.75]],"ltp":2.22,"tv":10.0,"id":60971788}]}]}
{"op":"mcm","clk":"11956922258","pt":1724551842255,"mc":[{"id":"1.232224255","rc":[{"batb":[[0,1.71,60.49],[1,1.21,24.75],[2,1.08,1.76]],"ltp":1.75,"tv":110.16,"id":61422697},{"batb":[[0,2.22,35.2],[1,1.21,24.75],[2,1.08,1.76]],"ltp":2.22,"tv":10.0,"id":60971788}]}]}
{"op":"mcm","clk":"11956922429","pt":1724551844670,"mc":[{"id":"1.232224255","rc":[{"batb":[[0,1.72,5],[1,1.71,60.49],[2,1.21,24.75]],"ltp":1.75,"tv":110.16,"id":61422697},{"batb":[[0,2.24,5],[1,2.22,35.2],[2,1.21,24.75]],"ltp":2.22,"tv":10.0,"id":60971788}]}]}
{"op":"mcm","clk":"11956922644","pt":1724551848069,"mc":[{"id":"1.232224255","rc":[{"batb":[[0,1.71,60.49],[1,1.21,24.75],[2,1.08,1.76]],"ltp":1.75,"tv":110.16,"id":61422697},{"batb":[[0,2.22,35.2],[1,1.21,24.75],[2,1.08,1.76]],"ltp":2.22,"tv":10.0,"id":60971788}]}]}
{"op":"mcm","clk":"11956922780","pt":1724551850183,"mc":[{"id":"1.232224255","rc":[{"batb":[[0,1.72,5],[1,1.71,60.49],[2,1.21,24.75]],"ltp":1.75,"tv":110.16,"id":61422697},{"batb":[[0,2.24,5],[1,2.22,35.2],[2,1.21,24.75]],"ltp":2.22,"tv":10.0,"id":60971788}]}]}
{"op":"mcm","clk":"11956922971","pt":1724551853467,"mc":[{"id":"1.232224255","rc":[{"batb":[[0,1.71,60.49],[1,1.21,24.75],[2,1.08,1.76]],"ltp":1.75,"tv":110.16,"id":61422697},{"batb":[[0,2.22,35.2],[1,1.21,24.75],[2,1.08,1.76]],"ltp":2.22,"tv":10.0,"id":60971788}]}]}
{"op":"mcm","clk":"11956923156","pt":1724551856090,"mc":[{"id":"1.232224255","rc":[{"batb":[[0,1.72,5],[1,1.71,60.49],[2,1.21,24.75]],"ltp":1.75,"tv":110.16,"id":61422697},{"batb":[[0,2.24,5],[1,2.22,35.2],[2,1.21,24.75]],"ltp":2.22,"tv":10.0,"id":60971788}]}]}
{"op":"mcm","clk":"11956923391","pt":1724551859493,"mc":[{"id":"1.232224255","rc":[{"batb":[[0,1.71,60.49],[1,1.21,24.75],[2,1.08,1.76]],"ltp":1.75,"tv":110.16,"id":61422697},{"batb":[[0,2.22,35.2],[1,1.21,24.75],[2,1.08,1.76]],"ltp":2.22,"tv":10.0,"id":60971788}]}]}
{"op":"mcm","clk":"11956923620","pt":1724551862690,"mc":[{"id":"1.232224255","rc":[{"batb":[[0,1.72,5],[1,1.71,60.49],[2,1.21,24.75]],"ltp":1.75,"tv":110.16,"id":61422697},{"batb":[[0,2.24,5],[1,2.22,35.2],[2,1.21,24.75]],"ltp":2.22,"tv":10.0,"id":60971788}]}]}
{"op":"mcm","clk":"11956923853","pt":1724551865999,"mc":[{"id":"1.232224255","rc":[{"batb":[[0,1.71,60.49],[1,1.21,24.75],[2,1.08,1.76]],"ltp":1.75,"tv":110.16,"id":61422697},{"batb":[[0,2.22,35.2],[1,1.21,24.75],[2,1.08,1.76]],"ltp":2.22,"tv":10.0,"id":60971788}]}]}
{"op":"mcm","clk":"11956924053","pt":1724551868525,"mc":[{"id":"1.232224255","rc":[{"batb":[[0,1.72,5],[1,1.71,60.49],[2,1.21,24.75]],"ltp":1.75,"tv":110.16,"id":61422697},{"batb":[[0,2.24,5],[1,2.22,35.2],[2,1.21,24.75]],"ltp":2.22,"tv":10.0,"id":60971788}]}]}
{"op":"mcm","clk":"11956924284","pt":1724551871929,"mc":[{"id":"1.232224255","rc":[{"batb":[[0,1.71,60.49],[1,1.21,24.75],[2,1.08,1.76]],"ltp":1.75,"tv":110.16,"id":61422697},{"batb":[[0,2.22,35.2],[1,1.21,24.75],[2,1.08,1.76]],"ltp":2.22,"tv":10.0,"id":60971788}]}]}
{"op":"mcm","clk":"11956924456","pt":1724551874123,"mc":[{"id":"1.232224255","rc":[{"batb":[[0,1.72,5],[1,1.71,60.49],[2,1.21,24.75]],"ltp":1.75,"tv":110.16,"id":61422697},{"batb":[[0,2.24,5],[1,2.22,35.2],[2,1.21,24.75]],"ltp":2.22,"tv":10.0,"id":60971788}]}]}
{"op":"mcm","clk":"11956924743","pt":1724551877430,"mc":[{"id":"1.232224255","rc":[{"batb":[[0,1.71,60.49],[1,1.21,24.75],[2,1.08,1.76]],"ltp":1.75,"tv":110.16,"id":61422697},{"batb":[[0,2.22,35.2],[1,1.21,24.75],[2,1.08,1.76]],"ltp":2.22,"tv":10.0,"id":60971788}]}]}
{"op":"mcm","clk":"11956924949","pt":1724551879704,"mc":[{"id":"1.232224255","rc":[{"batb":[[0,1.72,5],[1,1.71,60.49],[2,1.21,24.75]],"ltp":1.75,"tv":110.16,"id":61422697},{"batb":[[0,2.24,5],[1,2.22,35.2],[2,1.21,24.75]],"ltp":2.22,"tv":10.0,"id":60971788}]}]}
{"op":"mcm","clk":"11956925250","pt":1724551883206,"mc":[{"id":"1.232224255","rc":[{"batb":[[0,1.71,60.49],[1,1.21,24.75],[2,1.08,1.76]],"ltp":1.75,"tv":110.16,"id":61422697},{"batb":[[0,2.22,35.2],[1,1.21,24.75],[2,1.08,1.76]],"ltp":2.22,"tv":10.0,"id":60971788}]}]}
{"op":"mcm","clk":"11956925424","pt":1724551885423,"mc":[{"id":"1.232224255","rc":[{"batb":[[0,1.72,5],[1,1.71,60.49],[2,1.21,24.75]],"ltp":1.75,"tv":110.16,"id":61422697},{"batb":[[0,2.24,5],[1,2.22,35.2],[2,1.21,24.75]],"ltp":2.22,"tv":10.0,"id":60971788}]}]}
{"op":"mcm","clk":"11956925729","pt":1724551888622,"mc":[{"id":"1.232224255","rc":[{"batb":[[0,1.71,60.49],[1,1.21,24.75],[2,1.08,1.76]],"ltp":1.75,"tv":110.16,"id":61422697},{"batb":[[0,2.22,35.2],[1,1.21,24.75],[2,1.08,1.76]],"ltp":2.22,"tv":10.0,"id":60971788}]}]}
{"op":"mcm","clk":"11956925963","pt":1724551891512,"mc":[{"id":"1.232224255","rc":[{"batb":[[0,1.72,5],[1,1.71,60.49],[2,1.21,24.75]],"ltp":1.75,"tv":110.16,"id":61422697},{"batb":[[0,2.24,5],[1,2.22,35.2],[2,1.21,24.75]],"ltp":2.22,"tv":10.0,"id":60971788}]}]}
{"op":"mcm","clk":"11956926239","pt":1724551894712,"mc":[{"id":"1.232224255","rc":[{"batb":[[0,1.71,60.49],[1,1.21,24.75],[2,1.08,1.76]],"ltp":1.75,"tv":110.16,"id":61422697},{"batb":[[0,2.22,35.2],[1,1.21,24.75],[2,1.08,1.76]],"ltp":2.22,"tv":10.0,"id":60971788}]}]}
{"op":"mcm","clk":"11956926458","pt":1724551897240,"mc":[{"id":"1.232224255","rc":[{"batb":[[0,1.72,5],[1,1.71,60.49],[2,1.21,24.75]],"ltp":1.75,"tv":110.16,"id":61422697},{"batb":[[0,2.24,5],[1,2.22,35.2],[2,1.21,24.75]],"ltp":2.22,"tv":10.0,"id":60971788}]}]}
{"op":"mcm","clk":"11956926737","pt":1724551900652,"mc":[{"id":"1.232224255","rc":[{"batb":[[0,1.71,60.49],[1,1.21,24.75],[2,1.08,1.76]],"ltp":1.75,"tv":110.16,"id":61422697},{"batb":[[0,2.22,35.2],[1,1.21,24.75],[2,1.08,1.76]],"ltp":2.22,"tv":10.0,"id":60971788}]}]}
{"op":"mcm","clk":"11956926897","pt":1724551902820,"mc":[{"id":"1.232224255","rc":[{"batb":[[0,1.72,5],[1,1.71,60.49],[2,1.21,24.75]],"ltp":1.75,"tv":110.16,"id":61422697},{"batb":[[0,2.24,5],[1,2.22,35.2],[2,1.21,24.75]],"ltp":2.22,"tv":10.0,"id":60971788}]}]}
{"op":"mcm","clk":"11956927176","pt":1724551906430,"mc":[{"id":"1.232224255","rc":[{"batb":[[0,1.71,60.49],[1,1.21,24.75],[2,1.08,1.76]],"ltp":1.75,"tv":110.16,"id":61422697},{"batb":[[0,2.22,35.2],[1,1.21,24.75],[2,1.08,1.76]],"ltp":2.22,"tv":10.0,"id":60971788}]}]}
{"op":"mcm","clk":"11956927382","pt":1724551908854,"mc":[{"id":"1.232224255","rc":[{"batb":[[0,1.72,5],[1,1.71,60.49],[2,1.21,24.75]],"ltp":1.75,"tv":110.16,"id":61422697},{"batb":[[0,2.24,5],[1,2.22,35.2],[2,1.21,24.75]],"ltp":2.22,"tv":10.0,"id":60971788}]}]}
{"op":"mcm","clk":"11956927633","pt":1724551912260,"mc":[{"id":"1.232224255","rc":[{"batb":[[0,1.71,60.49],[1,1.21,24.75],[2,1.08,1.76]],"ltp":1.75,"tv":110.16,"id":61422697},{"batb":[[0,2.22,35.2],[1,1.21,24.75],[2,1.08,1.76]],"ltp":2.22,"tv":10.0,"id":60971788}]}]}
{"op":"mcm","clk":"11956927796","pt":1724551914428,"mc":[{"id":"1.232224255","rc":[{"batb":[[0,1.72,5],[1,1.71,60.49],[2,1.21,24.75]],"ltp":1.75,"tv":110.16,"id":61422697},{"batb":[[0,2.24,5],[1,2.22,35.2],[2,1.21,24.75]],"ltp":2.22,"tv":10.0,"id":60971788}]}]}
{"op":"mcm","clk":"11956928057","pt":1724551917836,"mc":[{"id":"1.232224255","rc":[{"batb":[[0,1.71,60.49],[1,1.21,24.75],[2,1.08,1.76]],"ltp":1.75,"tv":110.16,"id":61422697},{"batb":[[0,2.22,35.2],[1,1.21,24.75],[2,1.08,1.76]],"ltp":2.22,"tv":10.0,"id":60971788}]}]}
{"op":"mcm","clk":"11956928225","pt":1724551920152,"mc":[{"id":"1.232224255","rc":[{"batb":[[0,1.72,5],[1,1.71,60.49],[2,1.21,24.75]],"ltp":1.75,"tv":110.16,"id":61422697},{"batb":[[0,2.24,5],[1,2.22,35.2],[2,1.21,24.75]],"ltp":2.22,"tv":10.0,"id":60971788}]}]}
{"op":"mcm","clk":"11956928531","pt":1724551923477,"mc":[{"id":"1.232224255","rc":[{"batb":[[0,1.71,60.49],[1,1.21,24.75],[2,1.08,1.76]],"ltp":1.75,"tv":110.16,"id":61422697},{"batb":[[0,2.22,35.2],[1,1.21,24.75],[2,1.08,1.76]],"ltp":2.22,"tv":10.0,"id":60971788}]}]}
{"op":"mcm","clk":"11956928798","pt":1724551926961,"mc":[{"id":"1.232224255","rc":[{"batb":[[0,1.72,5],[1,1.71,60.49],[2,1.21,24.75]],"ltp":1.75,"tv":110.16,"id":61422697},{"batb":[[0,2.24,5],[1,2.22,35.2],[2,1.21,24.75]],"ltp":2.22,"tv":10.0,"id":60971788}]}]}
{"op":"mcm","clk":"11956929068","pt":1724551930382,"mc":[{"id":"1.232224255","rc":[{"batb":[[0,1.71,60.49],[1,1.21,24.75],[2,1.08,1.76]],"ltp":1.75,"tv":110.16,"id":61422697},{"batb":[[0,2.22,35.2],[1,1.21,24.75],[2,1.08,1.76]],"ltp":2.22,"tv":10.0,"id":60971788}]}]}
{"op":"mcm","clk":"11956929219","pt":1724551932601,"mc":[{"id":"1.232224255","rc":[{"batb":[[0,1.72,5],[1,1.71,60.49],[2,1.21,24.75]],"ltp":1.75,"tv":110.16,"id":61422697},{"batb":[[0,2.24,5],[1,2.22,35.2],[2,1.21,24.75]],"ltp":2.22,"tv":10.0,"id":60971788}]}]}
{"op":"mcm","clk":"11956929435","pt":1724551935792,"mc":[{"id":"1.232224255","rc":[{"batb":[[0,1.71,60.49],[1,1.21,24.75],[2,1.08,1.76]],"ltp":1.75,"tv":110.16,"id":61422697},{"batb":[[0,2.22,35.2],[1,1.21,24.75],[2,1.08,1.76]],"ltp":2.22,"tv":10.0,"id":60971788}]}]}
{"op":"mcm","clk":"11956929628","pt":1724551938211,"mc":[{"id":"1.232224255","rc":[{"batb":[[0,1.72,5],[1,1.71,60.49],[2,1.21,24.75]],"ltp":1.75,"tv":110.16,"id":61422697},{"batb":[[0,2.24,5],[1,2.22,35.2],[2,1.21,24.75]],"ltp":2.22,"tv":10.0,"id":60971788}]}]}
{"op":"mcm","clk":"11956929883","pt":1724551941612,"mc":[{"id":"1.232224255","rc":[{"batb":[[0,1.71,60.49],[1,1.21,24.75],[2,1.08,1.76]],"ltp":1.75,"tv":110.16,"id":61422697},{"batb":[[0,2.22,35.2],[1,1.21,24.75],[2,1.08,1.76]],"ltp":2.22,"tv":10.0,"id":60971788}]}]}
{"op":"mcm","clk":"11956930045","pt":1724551943780,"mc":[{"id":"1.232224255","rc":[{"batb":[[0,1.72,5],[1,1.71,60.49],[2,1.21,24.75]],"ltp":1.75,"tv":110.16,"id":61422697},{"batb":[[0,2.24,5],[1,2.22,35.2],[2,1.21,24.75]],"ltp":2.22,"tv":10.0,"id":60971788}]}]}
{"op":"mcm","clk":"11956930304","pt":1724551947291,"mc":[{"id":"1.232224255","rc":[{"batb":[[0,1.71,60.49],[1,1.21,24.75],[2,1.08,1.76]],"ltp":1.75,"tv":110.16,"id":61422697},{"batb":[[0,2.22,35.2],[1,1.21,24.75],[2,1.08,1.76]],"ltp":2.22,"tv":10.0,"id":60971788}]}]}
{"op":"mcm","clk":"11956930545","pt":1724551950398,"mc":[{"id":"1.232224255","rc":[{"batb":[[0,1.72,5],[1,1.71,60.49],[2,1.21,24.75]],"ltp":1.75,"tv":110.16,"id":61422697},{"batb":[[0,2.24,5],[1,2.22,35.2],[2,1.21,24.75]],"ltp":2.22,"tv":10.0,"id":60971788}]}]}
{"op":"mcm","clk":"11956930847","pt":1724551953707,"mc":[{"id":"1.232224255","rc":[{"batb":[[0,1.71,60.49],[1,1.21,24.75],[2,1.08,1.76]],"ltp":1.75,"tv":110.16,"id":61422697},{"batb":[[0,2.22,35.2],[1,1.21,24.75],[2,1.08,1.76]],"ltp":2.22,"tv":10.0,"id":60971788}]}]}
{"op":"mcm","clk":"11956931011","pt":1724551955922,"mc":[{"id":"1.232224255","rc":[{"batb":[[0,1.72,5],[1,1.71,60.49],[2,1.21,24.75]],"ltp":1.75,"tv":110.16,"id":61422697},{"batb":[[0,2.24,5],[1,2.22,35.2],[2,1.21,24.75]],"ltp":2.22,"tv":10.0,"id":60971788}]}]}
{"op":"mcm","clk":"11956931304","pt":1724551959227,"mc":[{"id":"1.232224255","rc":[{"batb":[[0,1.71,60.49],[1,1.21,24.75],[2,1.08,1.76]],"ltp":1.75,"tv":110.16,"id":61422697},{"batb":[[0,2.22,35.2],[1,1.21,24.75],[2,1.08,1.76]],"ltp":2.22,"tv":10.0,"id":60971788}]}]}
{"op":"mcm","clk":"11956931529","pt":1724551962022,"mc":[{"id":"1.232224255","rc":[{"batb":[[0,1.72,5],[1,1.71,60.49],[2,1.21,24.75]],"ltp":1.75,"tv":110.16,"id":61422697},{"batb":[[0,2.24,5],[1,2.22,35.2],[2,1.21,24.75]],"ltp":2.22,"tv":10.0,"id":60971788}]}]}
{"op":"mcm","clk":"11956931798","pt":1724551965616,"mc":[{"id":"1.232224255","rc":[{"batb":[[0,1.71,60.49],[1,1.21,24.75],[2,1.08,1.76]],"ltp":1.75,"tv":110.16,"id":61422697},{"batb":[[0,2.22,35.2],[1,1.21,24.75],[2,1.08,1.76]],"ltp":2.22,"tv":10.0,"id":60971788}]}]}
{"op":"mcm","clk":"11956931970","pt":1724551967850,"mc":[{"id":"1.232224255","rc":[{"batb":[[0,1.72,5],[1,1.71,60.49],[2,1.21,24.75]],"ltp":1.75,"tv":110.16,"id":61422697},{"batb":[[0,2.24,5],[1,2.22,35.2],[2,1.21,24.75]],"ltp":2.22,"tv":10.0,"id":60971788}]}]}
{"op":"mcm","clk":"11956932239","pt":1724551971140,"mc":[{"id":"1.232224255","rc":[{"batb":[[0,1.71,60.49],[1,1.21,24.75],[2,1.08,1.76]],"ltp":1.75,"tv":110.16,"id":61422697},{"batb":[[0,2.22,35.2],[1,1.21,24.75],[2,1.08,1.76]],"ltp":2.22,"tv":10.0,"id":60971788}]}]}
{"op":"mcm","clk":"11956932455","pt":1724551973349,"mc":[{"id":"1.232224255","rc":[{"batb":[[0,1.72,5],[1,1.71,60.49],[2,1.21,24.75]],"ltp":1.75,"tv":110.16,"id":61422697},{"batb":[[0,2.24,5],[1,2.22,35.2],[2,1.21,24.75]],"ltp":2.22,"tv":10.0,"id":60971788}]}]}
{"op":"mcm","clk":"11956947319","pt":1724551976638,"mc":[{"id":"1.232224255","rc":[{"batb":[[0,1.71,60.49],[1,1.21,24.75],[2,1.08,1.76]],"ltp":1.75,"tv":110.16,"id":61422697},{"batb":[[0,2.22,35.2],[1,1.21,24.75],[2,1.08,1.76]],"ltp":2.22,"tv":10.0,"id":60971788}]}]}
{"op":"mcm","clk":"11956947503","pt":1724551978909,"mc":[{"id":"1.232224255","rc":[{"batb":[[0,1.72,5],[1,1.71,60.49],[2,1.21,24.75]],"ltp":1.75,"tv":110.16,"id":61422697},{"batb":[[0,2.24,5],[1,2.22,35.2],[2,1.21,24.75]],"ltp":2.22,"tv":10.0,"id":60971788}]}]}
{"op":"mcm","clk":"11956947773","pt":1724551982227,"mc":[{"id":"1.232224255","rc":[{"batb":[[0,1.71,60.49],[1,1.21,24.75],[2,1.08,1.76]],"ltp":1.75,"tv":110.16,"id":61422697},{"batb":[[0,2.22,35.2],[1,1.21,24.75],[2,1.08,1.76]],"ltp":2.22,"tv":10.0,"id":60971788}]}]}
{"op":"mcm","clk":"11956947978","pt":1724551984563,"mc":[{"id":"1.232224255","rc":[{"batb":[[0,1.72,5],[1,1.71,60.49],[2,1.21,24.75]],"ltp":1.75,"tv":110.16,"id":61422697},{"batb":[[0,2.24,5],[1,2.22,35.2],[2,1.21,24.75]],"ltp":2.22,"tv":10.0,"id":60971788}]}]}
{"op":"mcm","clk":"11956948303","pt":1724551987859,"mc":[{"id":"1.232224255","rc":[{"batb":[[0,1.71,60.49],[1,1.21,24.75],[2,1.08,1.76]],"ltp":1.75,"tv":110.16,"id":61422697},{"batb":[[0,2.22,35.2],[1,1.21,24.75],[2,1.08,1.76]],"ltp":2.22,"tv":10.0,"id":60971788}]}]}
{"op":"mcm","clk":"11956948544","pt":1724551991166,"mc":[{"id":"1.232224255","rc":[{"batb":[[0,1.72,5],[1,1.71,60.49],[2,1.21,24.75]],"ltp":1.75,"tv":110.16,"id":61422697},{"batb":[[0,2.24,5],[1,2.22,35.2],[2,1.21,24.75]],"ltp":2.22,"tv":10.0,"id":60971788}]}]}
{"op":"mcm","clk":"11956948832","pt":1724551994475,"mc":[{"id":"1.232224255","rc":[{"batb":[[0,1.71,60.49],[1,1.21,24.75],[2,1.08,1.76]],"ltp":1.75,"tv":110.16,"id":61422697},{"batb":[[0,2.22,35.2],[1,1.21,24.75],[2,1.08,1.76]],"ltp":2.22,"tv":10.0,"id":60971788}]}]}
{"op":"mcm","clk":"11956949060","pt":1724551997479,"mc":[{"id":"1.232224255","rc":[{"batb":[[0,1.72,5],[1,1.71,60.49],[2,1.21,24.75]],"ltp":1.75,"tv":110.16,"id":61422697},{"batb":[[0,2.24,5],[1,2.22,35.2],[2,1.21,24.75]],"ltp":2.22,"tv":10.0,"id":60971788}]}]}
{"op":"mcm","clk":"11956949346","pt":1724552000855,"mc":[{"id":"1.232224255","rc":[{"batb":[[0,1.71,60.49],[1,1.21,24.75],[2,1.08,1.76]],"ltp":1.75,"tv":110.16,"id":61422697},{"batb":[[0,2.22,35.2],[1,1.21,24.75],[2,1.08,1.76]],"ltp":2.22,"tv":10.0,"id":60971788}]}]}
{"op":"mcm","clk":"11956949494","pt":1724552003070,"mc":[{"id":"1.232224255","rc":[{"batb":[[0,1.72,5],[1,1.71,60.49],[2,1.21,24.75]],"ltp":1.75,"tv":110.16,"id":61422697},{"batb":[[0,2.24,5],[1,2.22,35.2],[2,1.21,24.75]],"ltp":2.22,"tv":10.0,"id":60971788}]}]}
{"op":"mcm","clk":"11956949745","pt":1724552006365,"mc":[{"id":"1.232224255","rc":[{"batb":[[0,1.71,60.49],[1,1.21,24.75],[2,1.08,1.76]],"ltp":1.75,"tv":110.16,"id":61422697},{"batb":[[0,2.22,35.2],[1,1.21,24.75],[2,1.08,1.76]],"ltp":2.22,"tv":10.0,"id":60971788}]}]}
{"op":"mcm","clk":"11956949918","pt":1724552008792,"mc":[{"id":"1.232224255","rc":[{"batb":[[0,1.72,5],[1,1.71,60.49],[2,1.21,24.75]],"ltp":1.75,"tv":110.16,"id":61422697},{"batb":[[0,2.24,5],[1,2.22,35.2],[2,1.21,24.75]],"ltp":2.22,"tv":10.0,"id":60971788}]}]}
{"op":"mcm","clk":"11956950182","pt":1724552012179,"mc":[{"id":"1.232224255","rc":[{"batb":[[0,1.71,60.49],[1,1.21,24.75],[2,1.08,1.76]],"ltp":1.75,"tv":110.16,"id":61422697},{"batb":[[0,2.22,35.2],[1,1.21,24.75],[2,1.08,1.76]],"ltp":2.22,"tv":10.0,"id":60971788}]}]}
{"op":"mcm","clk":"11956950338","pt":1724552014458,"mc":[{"id":"1.232224255","rc":[{"batb":[[0,1.72,5],[1,1.71,60.49],[2,1.21,24.75]],"ltp":1.75,"tv":110.16,"id":61422697},{"batb":[[0,2.24,5],[1,2.22,35.2],[2,1.21,24.75]],"ltp":2.22,"tv":10.0,"id":60971788}]}]}
{"op":"mcm","clk":"11956950597","pt":1724552017758,"mc":[{"id":"1.232224255","rc":[{"batb":[[0,1.71,60.49],[1,1.21,24.75],[2,1.08,1.76]],"ltp":1.75,"tv":110.16,"id":61422697},{"batb":[[0,2.22,35.2],[1,1.21,24.75],[2,1.08,1.76]],"ltp":2.22,"tv":10.0,"id":60971788}]}]}
{"op":"mcm","clk":"11956950764","pt":1724552020185,"mc":[{"id":"1.232224255","rc":[{"batb":[[0,1.72,5],[1,1.71,60.49],[2,1.21,24.75]],"ltp":1.75,"tv":110.16,"id":61422697},{"batb":[[0,2.24,5],[1,2.22,35.2],[2,1.21,24.75]],"ltp":2.22,"tv":10.0,"id":60971788}]}]}
{"op":"mcm","clk":"11956951020","pt":1724552023485,"mc":[{"id":"1.232224255","rc":[{"batb":[[0,1.71,60.49],[1,1.21,24.75],[2,1.08,1.76]],"ltp":1.75,"tv":110.16,"id":61422697},{"batb":[[0,2.22,35.2],[1,1.21,24.75],[2,1.08,1.76]],"ltp":2.22,"tv":10.0,"id":60971788}]}]}
{"op":"mcm","clk":"11956951262","pt":1724552026687,"mc":[{"id":"1.232224255","rc":[{"batb":[[0,1.72,5],[1,1.71,60.49],[2,1.21,24.75]],"ltp":1.75,"tv":110.16,"id":61422697},{"batb":[[0,2.24,5],[1,2.22,35.2],[2,1.21,24.75]],"ltp":2.22,"tv":10.0,"id":60971788}]}]}
{"op":"mcm","clk":"11956951536","pt":1724552029880,"mc":[{"id":"1.232224255","rc":[{"batb":[[0,1.71,60.49],[1,1.21,24.75],[2,1.08,1.76]],"ltp":1.75,"tv":110.16,"id":61422697},{"batb":[[0,2.22,35.2],[1,1.21,24.75],[2,1.08,1.76]],"ltp":2.22,"tv":10.0,"id":60971788}]}]}
{"op":"mcm","clk":"11956951743","pt":1724552032097,"mc":[{"id":"1.232224255","rc":[{"batb":[[0,1.72,5],[1,1.71,60.49],[2,1.21,24.75]],"ltp":1.75,"tv":110.16,"id":61422697},{"batb":[[0,2.24,5],[1,2.22,35.2],[2,1.21,24.75]],"ltp":2.22,"tv":10.0,"id":60971788}]}]}
{"op":"mcm","clk":"11956952016","pt":1724552035400,"mc":[{"id":"1.232224255","rc":[{"batb":[[0,1.71,60.49],[1,1.21,24.75],[2,1.08,1.76]],"ltp":1.75,"tv":110.16,"id":61422697},{"batb":[[0,2.22,35.2],[1,1.21,24.75],[2,1.08,1.76]],"ltp":2.22,"tv":10.0,"id":60971788}]}]}
{"op":"mcm","clk":"11956952223","pt":1724552038083,"mc":[{"id":"1.232224255","rc":[{"batb":[[0,1.72,5],[1,1.71,60.49],[2,1.21,24.75]],"ltp":1.75,"tv":110.16,"id":61422697},{"batb":[[0,2.24,5],[1,2.22,35.2],[2,1.21,24.75]],"ltp":2.22,"tv":10.0,"id":60971788}]}]}
{"op":"mcm","clk":"11956952479","pt":1724552041411,"mc":[{"id":"1.232224255","rc":[{"batb":[[0,1.71,60.49],[1,1.21,24.75],[2,1.08,1.76]],"ltp":1.75,"tv":110.16,"id":61422697},{"batb":[[0,2.22,35.2],[1,1.21,24.75],[2,1.08,1.76]],"ltp":2.22,"tv":10.0,"id":60971788}]}]}
{"op":"mcm","clk":"11956952697","pt":1724552043811,"mc":[{"id":"1.232224255","rc":[{"batb":[[0,1.72,5],[1,1.71,60.49],[2,1.21,24.75]],"ltp":1.75,"tv":110.16,"id":61422697},{"batb":[[0,2.24,5],[1,2.22,35.2],[2,1.21,24.75]],"ltp":2.22,"tv":10.0,"id":60971788}]}]}
{"op":"mcm","clk":"11956953006","pt":1724552047118,"mc":[{"id":"1.232224255","rc":[{"batb":[[0,1.71,60.49],[1,1.21,24.75],[2,1.08,1.76]],"ltp":1.75,"tv":110.16,"id":61422697},{"batb":[[0,2.22,35.2],[1,1.21,24.75],[2,1.08,1.76]],"ltp":2.22,"tv":10.0,"id":60971788}]}]}
{"op":"mcm","clk":"11956953184","pt":1724552049332,"mc":[{"id":"1.232224255","rc":[{"batb":[[0,1.72,5],[1,1.71,60.49],[2,1.21,24.75]],"ltp":1.75,"tv":110.16,"id":61422697},{"batb":[[0,2.24,5],[1,2.22,35.2],[2,1.21,24.75]],"ltp":2.22,"tv":10.0,"id":60971788}]}]}
{"op":"mcm","clk":"11956953462","pt":1724552052625,"mc":[{"id":"1.232224255","rc":[{"batb":[[0,1.71,60.49],[1,1.21,24.75],[2,1.08,1.76]],"ltp":1.75,"tv":110.16,"id":61422697},{"batb":[[0,2.22,35.2],[1,1.21,24.75],[2,1.08,1.76]],"ltp":2.22,"tv":10.0,"id":60971788}]}]}
{"op":"mcm","clk":"11956953669","pt":1724552055300,"mc":[{"id":"1.232224255","rc":[{"batb":[[0,1.72,5],[1,1.71,60.49],[2,1.21,24.75]],"ltp":1.75,"tv":110.16,"id":61422697},{"batb":[[0,2.24,5],[1,2.22,35.2],[2,1.21,24.75]],"ltp":2.22,"tv":10.0,"id":60971788}]}]}
{"op":"mcm","clk":"11956953977","pt":1724552058651,"mc":[{"id":"1.232224255","rc":[{"batb":[[0,1.71,60.49],[1,1.21,24.75],[2,1.08,1.76]],"ltp":1.75,"tv":110.16,"id":61422697},{"batb":[[0,2.22,35.2],[1,1.21,24.75],[2,1.08,1.76]],"ltp":2.22,"tv":10.0,"id":60971788}]}]}
{"op":"mcm","clk":"11956954163","pt":1724552060829,"mc":[{"id":"1.232224255","rc":[{"batb":[[0,1.72,5],[1,1.71,60.49],[2,1.21,24.75]],"ltp":1.75,"tv":110.16,"id":61422697},{"batb":[[0,2.24,5],[1,2.22,35.2],[2,1.21,24.75]],"ltp":2.22,"tv":10.0,"id":60971788}]}]}
{"op":"mcm","clk":"11956954418","pt":1724552064120,"mc":[{"id":"1.232224255","rc":[{"batb":[[0,1.71,60.49],[1,1.21,24.75],[2,1.08,1.76]],"ltp":1.75,"tv":110.16,"id":61422697},{"batb":[[0,2.22,35.2],[1,1.21,24.75],[2,1.08,1.76]],"ltp":2.22,"tv":10.0,"id":60971788}]}]}
{"op":"mcm","clk":"11956954725","pt":1724552068244,"mc":[{"id":"1.232224255","rc":[{"batb":[[0,1.72,5],[1,1.71,60.49],[2,1.21,24.75]],"ltp":1.75,"tv":110.16,"id":61422697},{"batb":[[0,2.24,5],[1,2.22,35.2],[2,1.21,24.75]],"ltp":2.22,"tv":10.0,"id":60971788}]}]}
{"op":"mcm","clk":"11956954979","pt":1724552071548,"mc":[{"id":"1.232224255","rc":[{"batb":[[0,1.71,60.49],[1,1.21,24.75],[2,1.08,1.76]],"ltp":1.75,"tv":110.16,"id":61422697},{"batb":[[0,2.22,35.2],[1,1.21,24.75],[2,1.08,1.76]],"ltp":2.22,"tv":10.0,"id":60971788}]}]}
{"op":"mcm","clk":"11956955155","pt":1724552073818,"mc":[{"id":"1.232224255","rc":[{"batb":[[0,1.72,5],[1,1.71,60.49],[2,1.21,24.75]],"ltp":1.75,"tv":110.16,"id":61422697},{"batb":[[0,2.24,5],[1,2.22,35.2],[2,1.21,24.75]],"ltp":2.22,"tv":10.0,"id":60971788}]}]}
{"op":"mcm","clk":"11956955421","pt":1724552077118,"mc":[{"id":"1.232224255","rc":[{"batb":[[0,1.71,60.49],[1,1.21,24.75],[2,1.08,1.76]],"ltp":1.75,"tv":110.16,"id":61422697},{"batb":[[0,2.22,35.2],[1,1.21,24.75],[2,1.08,1.76]],"ltp":2.22,"tv":10.0,"id":60971788}]}]}
{"op":"mcm","clk":"11956955656","pt":1724552080061,"mc":[{"id":"1.232224255","rc":[{"batb":[[0,1.72,5],[1,1.71,60.49],[2,1.21,24.75]],"ltp":1.75,"tv":110.16,"id":61422697},{"batb":[[0,2.24,5],[1,2.22,35.2],[2,1.21,24.75]],"ltp":2.22,"tv":10.0,"id":60971788}]}]}
{"op":"mcm","clk":"11956955941","pt":1724552083468,"mc":[{"id":"1.232224255","rc":[{"batb":[[0,1.71,60.49],[1,1.21,24.75],[2,1.08,1.76]],"ltp":1.75,"tv":110.16,"id":61422697},{"batb":[[0,2.22,35.2],[1,1.21,24.75],[2,1.08,1.76]],"ltp":2.22,"tv":10.0,"id":60971788}]}]}
{"op":"mcm","clk":"11956956186","pt":1724552085637,"mc":[{"id":"1.232224255","rc":[{"batb":[[0,1.72,5],[1,1.71,60.49],[2,1.21,24.75]],"ltp":1.75,"tv":110.16,"id":61422697},{"batb":[[0,2.24,5],[1,2.22,35.2],[2,1.21,24.75]],"ltp":2.22,"tv":10.0,"id":60971788}]}]}
{"op":"mcm","clk":"11956956470","pt":1724552088938,"mc":[{"id":"1.232224255","rc":[{"batb":[[0,1.71,60.49],[1,1.21,24.75],[2,1.08,1.76]],"ltp":1.75,"tv":110.16,"id":61422697},{"batb":[[0,2.22,35.2],[1,1.21,24.75],[2,1.08,1.76]],"ltp":2.22,"tv":10.0,"id":60971788}]}]}
{"op":"mcm","clk":"11956956779","pt":1724552092606,"mc":[{"id":"1.232224255","rc":[{"batb":[[0,1.72,5],[1,1.71,60.49],[2,1.21,24.75]],"ltp":1.75,"tv":110.16,"id":61422697},{"batb":[[0,2.24,5],[1,2.22,35.2],[2,1.21,24.75]],"ltp":2.22,"tv":10.0,"id":60971788}]}]}
{"op":"mcm","clk":"11956957010","pt":1724552095870,"mc":[{"id":"1.232224255","rc":[{"batb":[[0,1.71,60.49],[1,1.21,24.75],[2,1.08,1.76]],"ltp":1.75,"tv":110.16,"id":61422697},{"batb":[[0,2.22,35.2],[1,1.21,24.75],[2,1.08,1.76]],"ltp":2.22,"tv":10.0,"id":60971788}]}]}
{"op":"mcm","clk":"11956957260","pt":1724552098810,"mc":[{"id":"1.232224255","rc":[{"batb":[[0,1.72,5],[1,1.71,60.49],[2,1.21,24.75]],"ltp":1.75,"tv":110.16,"id":61422697},{"batb":[[0,2.24,5],[1,2.22,35.2],[2,1.21,24.75]],"ltp":2.22,"tv":10.0,"id":60971788}]}]}
{"op":"mcm","clk":"11956957554","pt":1724552102080,"mc":[{"id":"1.232224255","rc":[{"batb":[[0,1.71,60.49],[1,1.21,24.75],[2,1.08,1.76]],"ltp":1.75,"tv":110.16,"id":61422697},{"batb":[[0,2.22,35.2],[1,1.21,24.75],[2,1.08,1.76]],"ltp":2.22,"tv":10.0,"id":60971788}]}]}
{"op":"mcm","clk":"11956957746","pt":1724552104500,"mc":[{"id":"1.232224255","rc":[{"batb":[[0,1.72,5],[1,1.71,60.49],[2,1.21,24.75]],"ltp":1.75,"tv":110.16,"id":61422697},{"batb":[[0,2.24,5],[1,2.22,35.2],[2,1.21,24.75]],"ltp":2.22,"tv":10.0,"id":60971788}]}]}
{"op":"mcm","clk":"11956958058","pt":1724552107809,"mc":[{"id":"1.232224255","rc":[{"batb":[[0,1.71,60.49],[1,1.21,24.75],[2,1.08,1.76]],"ltp":1.75,"tv":110.16,"id":61422697},{"batb":[[0,2.22,35.2],[1,1.21,24.75],[2,1.08,1.76]],"ltp":2.22,"tv":10.0,"id":60971788}]}]}
{"op":"mcm","clk":"11956958243","pt":1724552110076,"mc":[{"id":"1.232224255","rc":[{"batb":[[0,1.72,5],[1,1.71,60.49],[2,1.21,24.75]],"ltp":1.75,"tv":110.16,"id":61422697},{"batb":[[0,2.24,5],[1,2.22,35.2],[2,1.21,24.75]],"ltp":2.22,"tv":10.0,"id":60971788}]}]}
{"op":"mcm","clk":"11956958533","pt":1724552113424,"mc":[{"id":"1.232224255","rc":[{"batb":[[0,1.71,60.49],[1,1.21,24.75],[2,1.08,1.76]],"ltp":1.75,"tv":110.16,"id":61422697},{"batb":[[0,2.22,35.2],[1,1.21,24.75],[2,1.08,1.76]],"ltp":2.22,"tv":10.0,"id":60971788}]}]}
{"op":"mcm","clk":"11956958717","pt":1724552115602,"mc":[{"id":"1.232224255","rc":[{"batb":[[0,1.72,5],[1,1.71,60.49],[2,1.21,24.75]],"ltp":1.75,"tv":110.16,"id":61422697},{"batb":[[0,2.24,5],[1,2.22,35.2],[2,1.21,24.75]],"ltp":2.22,"tv":10.0,"id":60971788}]}]}
{"op":"mcm","clk":"11956958995","pt":1724552118806,"mc":[{"id":"1.232224255","rc":[{"batb":[[0,1.71,60.49],[1,1.21,24.75],[2,1.08,1.76]],"ltp":1.75,"tv":110.16,"id":61422697}]}]}
{"op":"mcm","clk":"11956959012","pt":1724552118915,"mc":[{"id":"1.232224255","rc":[{"batb":[[0,2.22,35.2],[1,1.21,24.75],[2,1.08,1.76]],"ltp":2.22,"tv":10.0,"id":60971788}]}]}
{"op":"mcm","clk":"11956959479","pt":1724552123110,"mc":[{"id":"1.232224255","rc":[{"batb":[[0,1.72,5],[1,1.71,60.49],[2,1.21,24.75]],"ltp":1.75,"tv":110.16,"id":61422697},{"batb":[[0,2.24,5],[1,2.22,35.2],[2,1.21,24.75]],"ltp":2.22,"tv":10.0,"id":60971788}]}]}
{"op":"mcm","clk":"11956959750","pt":1724552126413,"mc":[{"id":"1.232224255","rc":[{"batb":[[0,1.71,60.49],[1,1.21,24.75],[2,1.08,1.76]],"ltp":1.75,"tv":110.16,"id":61422697},{"batb":[[0,2.22,35.2],[1,1.21,24.75],[2,1.08,1.76]],"ltp":2.22,"tv":10.0,"id":60971788}]}]}
{"op":"mcm","clk":"11956960007","pt":1724552129301,"mc":[{"id":"1.232224255","rc":[{"batb":[[0,1.72,5],[1,1.71,60.49],[2,1.21,24.75]],"ltp":1.75,"tv":110.16,"id":61422697},{"batb":[[0,2.24,5],[1,2.22,35.2],[2,1.21,24.75]],"ltp":2.22,"tv":10.0,"id":60971788}]}]}
{"op":"mcm","clk":"11956960301","pt":1724552132634,"mc":[{"id":"1.232224255","rc":[{"batb":[[0,1.71,60.49],[1,1.21,24.75],[2,1.08,1.76]],"ltp":1.75,"tv":110.16,"id":61422697},{"batb":[[0,2.22,35.2],[1,1.21,24.75],[2,1.08,1.76]],"ltp":2.22,"tv":10.0,"id":60971788}]}]}
{"op":"mcm","clk":"11956960587","pt":1724552135938,"mc":[{"id":"1.232224255","rc":[{"batb":[[0,1.72,5],[1,1.71,60.49],[2,1.21,24.75]],"ltp":1.75,"tv":110.16,"id":61422697},{"batb":[[0,2.24,5],[1,2.22,35.2],[2,1.21,24.75]],"ltp":2.22,"tv":10.0,"id":60971788}]}]}
{"op":"mcm","clk":"11956960898","pt":1724552139256,"mc":[{"id":"1.232224255","rc":[{"batb":[[0,1.71,60.49],[1,1.21,24.75],[2,1.08,1.76]],"ltp":1.75,"tv":110.16,"id":61422697},{"batb":[[0,2.22,35.2],[1,1.21,24.75],[2,1.08,1.76]],"ltp":2.22,"tv":10.0,"id":60971788}]}]}
{"op":"mcm","clk":"11956961096","pt":1724552141430,"mc":[{"id":"1.232224255","rc":[{"batb":[[0,1.72,5],[1,1.71,60.49],[2,1.21,24.75]],"ltp":1.75,"tv":110.16,"id":61422697},{"batb":[[0,2.24,5],[1,2.22,35.2],[2,1.21,24.75]],"ltp":2.22,"tv":10.0,"id":60971788}]}]}
{"op":"mcm","clk":"11956961375","pt":1724552144736,"mc":[{"id":"1.232224255","rc":[{"batb":[[0,1.71,60.49],[1,1.21,24.75],[2,1.08,1.76]],"ltp":1.75,"tv":110.16,"id":61422697},{"batb":[[0,2.22,35.2],[1,1.21,24.75],[2,1.08,1.76]],"ltp":2.22,"tv":10.0,"id":60971788}]}]}
{"op":"mcm","clk":"11956961560","pt":1724552146954,"mc":[{"id":"1.232224255","rc":[{"batb":[[0,1.72,5],[1,1.71,60.49],[2,1.21,24.75]],"ltp":1.75,"tv":110.16,"id":61422697},{"batb":[[0,2.24,5],[1,2.22,35.2],[2,1.21,24.75]],"ltp":2.22,"tv":10.0,"id":60971788}]}]}
{"op":"mcm","clk":"11956961839","pt":1724552150158,"mc":[{"id":"1.232224255","rc":[{"batb":[[0,1.71,60.49],[1,1.21,24.75],[2,1.08,1.76]],"ltp":1.75,"tv":110.16,"id":61422697},{"batb":[[0,2.22,35.2],[1,1.21,24.75],[2,1.08,1.76]],"ltp":2.22,"tv":10.0,"id":60971788}]}]}
{"op":"mcm","clk":"11956962242","pt":1724552155275,"mc":[{"id":"1.232224255","rc":[{"batb":[[0,1.72,5],[1,1.71,60.49],[2,1.21,24.75]],"ltp":1.75,"tv":110.16,"id":61422697},{"batb":[[0,2.24,5],[1,2.22,35.2],[2,1.21,24.75]],"ltp":2.22,"tv":10.0,"id":60971788}]}]}
{"op":"mcm","clk":"11956962514","pt":1724552158576,"mc":[{"id":"1.232224255","rc":[{"batb":[[0,1.71,60.49],[1,1.21,24.75],[2,1.08,1.76]],"ltp":1.75,"tv":110.16,"id":61422697},{"batb":[[0,2.22,35.2],[1,1.21,24.75],[2,1.08,1.76]],"ltp":2.22,"tv":10.0,"id":60971788}]}]}
{"op":"mcm","clk":"11956962704","pt":1724552160757,"mc":[{"id":"1.232224255","rc":[{"batb":[[0,1.72,5],[1,1.71,60.49],[2,1.21,24.75]],"ltp":1.75,"tv":110.16,"id":61422697},{"batb":[[0,2.24,5],[1,2.22,35.2],[2,1.21,24.75]],"ltp":2.22,"tv":10.0,"id":60971788}]}]}
{"op":"mcm","clk":"11956963019","pt":1724552164072,"mc":[{"id":"1.232224255","rc":[{"batb":[[0,1.71,60.49],[1,1.21,24.75],[2,1.08,1.76]],"ltp":1.75,"tv":110.16,"id":61422697},{"batb":[[0,2.22,35.2],[1,1.21,24.75],[2,1.08,1.76]],"ltp":2.22,"tv":10.0,"id":60971788}]}]}
{"op":"mcm","clk":"11956963230","pt":1724552166858,"mc":[{"id":"1.232224255","rc":[{"batb":[[0,1.72,5],[1,1.71,60.49],[2,1.21,24.75]],"ltp":1.75,"tv":110.16,"id":61422697},{"batb":[[0,2.24,5],[1,2.22,35.2],[2,1.21,24.75]],"ltp":2.22,"tv":10.0,"id":60971788}]}]}
{"op":"mcm","clk":"11956963492","pt":1724552170189,"mc":[{"id":"1.232224255","rc":[{"batb":[[0,1.71,60.49],[1,1.21,24.75],[2,1.08,1.76]],"ltp":1.75,"tv":110.16,"id":61422697},{"batb":[[0,2.22,35.2],[1,1.21,24.75],[2,1.08,1.76]],"ltp":2.22,"tv":10.0,"id":60971788}]}]}
{"op":"mcm","clk":"11956963840","pt":1724552173786,"mc":[{"id":"1.232224255","rc":[{"batb":[[0,1.72,5],[1,1.71,60.49],[2,1.21,24.75]],"ltp":1.75,"tv":110.16,"id":61422697},{"batb":[[0,2.24,5],[1,2.22,35.2],[2,1.21,24.75]],"ltp":2.22,"tv":10.0,"id":60971788}]}]}
{"op":"mcm","clk":"11956964071","pt":1724552177163,"mc":[{"id":"1.232224255","rc":[{"batb":[[0,1.71,60.49],[1,1.21,24.75],[2,1.08,1.76]],"ltp":1.75,"tv":110.16,"id":61422697},{"batb":[[0,2.22,35.2],[1,1.21,24.75],[2,1.08,1.76]],"ltp":2.22,"tv":10.0,"id":60971788}]}]}
{"op":"mcm","clk":"11956964335","pt":1724552180668,"mc":[{"id":"1.232224255","rc":[{"batb":[[0,1.72,5],[1,1.71,60.49],[2,1.21,24.75]],"ltp":1.75,"tv":110.16,"id":61422697},{"batb":[[0,2.24,5],[1,2.22,35.2],[2,1.21,24.75]],"ltp":2.22,"tv":10.0,"id":60971788}]}]}
{"op":"mcm","clk":"11956964545","pt":1724552183898,"mc":[{"id":"1.232224255","rc":[{"batb":[[0,1.71,60.49],[1,1.21,24.75],[2,1.08,1.76]],"ltp":1.75,"tv":110.16,"id":61422697},{"batb":[[0,2.22,35.2],[1,1.21,24.75],[2,1.08,1.76]],"ltp":2.22,"tv":10.0,"id":60971788}]}]}
{"op":"mcm","clk":"11956964803","pt":1724552187093,"mc":[{"id":"1.232224255","rc":[{"batb":[[0,1.72,5],[1,1.71,60.49],[2,1.21,24.75]],"ltp":1.75,"tv":110.16,"id":61422697},{"batb":[[0,2.24,5],[1,2.22,35.2],[2,1.21,24.75]],"ltp":2.22,"tv":10.0,"id":60971788}]}]}
{"op":"mcm","clk":"11956965030","pt":1724552190392,"mc":[{"id":"1.232224255","rc":[{"batb":[[0,1.71,60.49],[1,1.21,24.75],[2,1.08,1.76]],"ltp":1.75,"tv":110.16,"id":61422697},{"batb":[[0,2.22,35.2],[1,1.21,24.75],[2,1.08,1.76]],"ltp":2.22,"tv":10.0,"id":60971788}]}]}
{"op":"mcm","clk":"11956965315","pt":1724552194114,"mc":[{"id":"1.232224255","rc":[{"batb":[[0,1.72,5],[1,1.71,60.49],[2,1.21,24.75]],"ltp":1.75,"tv":110.16,"id":61422697},{"batb":[[0,2.24,5],[1,2.22,35.2],[2,1.21,24.75]],"ltp":2.22,"tv":10.0,"id":60971788}]}]}
{"op":"mcm","clk":"11956965624","pt":1724552197472,"mc":[{"id":"1.232224255","rc":[{"batb":[[0,1.71,60.49],[1,1.21,24.75],[2,1.08,1.76]],"ltp":1.75,"tv":110.16,"id":61422697},{"batb":[[0,2.22,35.2],[1,1.21,24.75],[2,1.08,1.76]],"ltp":2.22,"tv":10.0,"id":60971788}]}]}
{"op":"mcm","clk":"11956965869","pt":1724552200309,"mc":[{"id":"1.232224255","rc":[{"batb":[[0,1.72,5],[1,1.71,60.49],[2,1.21,24.75]],"ltp":1.75,"tv":110.16,"id":61422697},{"batb":[[0,2.24,5],[1,2.22,35.2],[2,1.21,24.75]],"ltp":2.22,"tv":10.0,"id":60971788}]}]}
{"op":"mcm","clk":"11956966149","pt":1724552203918,"mc":[{"id":"1.232224255","rc":[{"batb":[[0,1.71,60.49],[1,1.21,24.75],[2,1.08,1.76]],"ltp":1.75,"tv":110.16,"id":61422697},{"batb":[[0,2.22,35.2],[1,1.21,24.75],[2,1.08,1.76]],"ltp":2.22,"tv":10.0,"id":60971788}]}]}
{"op":"mcm","clk":"11956966332","pt":1724552206294,"mc":[{"id":"1.232224255","rc":[{"batb":[[0,1.72,5],[1,1.71,60.49],[2,1.21,24.75]],"ltp":1.75,"tv":110.16,"id":61422697},{"batb":[[0,2.24,5],[1,2.22,35.2],[2,1.21,24.75]],"ltp":2.22,"tv":10.0,"id":60971788}]}]}
{"op":"mcm","clk":"11956966600","pt":1724552209598,"mc":[{"id":"1.232224255","rc":[{"batb":[[0,1.71,60.49],[1,1.21,24.75],[2,1.08,1.76]],"ltp":1.75,"tv":110.16,"id":61422697},{"batb":[[0,2.22,35.2],[1,1.21,24.75],[2,1.08,1.76]],"ltp":2.22,"tv":10.0,"id":60971788}]}]}
{"op":"mcm","clk":"11956966831","pt":1724552212632,"mc":[{"id":"1.232224255","rc":[{"batb":[[0,1.72,5],[1,1.71,60.49],[2,1.21,24.75]],"ltp":1.75,"tv":110.16,"id":61422697},{"batb":[[0,2.24,5],[1,2.22,35.2],[2,1.21,24.75]],"ltp":2.22,"tv":10.0,"id":60971788}]}]}
{"op":"mcm","clk":"11956967097","pt":1724552215936,"mc":[{"id":"1.232224255","rc":[{"batb":[[0,1.71,60.49],[1,1.21,24.75],[2,1.08,1.76]],"ltp":1.75,"tv":110.16,"id":61422697},{"batb":[[0,2.22,35.2],[1,1.21,24.75],[2,1.08,1.76]],"ltp":2.22,"tv":10.0,"id":60971788}]}]}
{"op":"mcm","clk":"11956967319","pt":1724552218824,"mc":[{"id":"1.232224255","rc":[{"batb":[[0,1.72,5],[1,1.71,60.49],[2,1.21,24.75]],"ltp":1.75,"tv":110.16,"id":61422697},{"batb":[[0,2.24,5],[1,2.22,35.2],[2,1.21,24.75]],"ltp":2.22,"tv":10.0,"id":60971788}]}]}
{"op":"mcm","clk":"11956967626","pt":1724552222308,"mc":[{"id":"1.232224255","rc":[{"batb":[[0,1.71,60.49],[1,1.21,24.75],[2,1.08,1.76]],"ltp":1.75,"tv":110.16,"id":61422697},{"batb":[[0,2.22,35.2],[1,1.21,24.75],[2,1.08,1.76]],"ltp":2.22,"tv":10.0,"id":60971788}]}]}
{"op":"mcm","clk":"11956967889","pt":1724552225308,"mc":[{"id":"1.232224255","rc":[{"batb":[[0,1.72,5],[1,1.71,60.49],[2,1.21,24.75]],"ltp":1.75,"tv":110.16,"id":61422697},{"batb":[[0,2.24,5],[1,2.22,35.2],[2,1.21,24.75]],"ltp":2.22,"tv":10.0,"id":60971788}]}]}
{"op":"mcm","clk":"11956968198","pt":1724552228913,"mc":[{"id":"1.232224255","rc":[{"batb":[[0,1.71,60.49],[1,1.21,24.75],[2,1.08,1.76]],"ltp":1.75,"tv":110.16,"id":61422697},{"batb":[[0,2.22,35.2],[1,1.21,24.75],[2,1.08,1.76]],"ltp":2.22,"tv":10.0,"id":60971788}]}]}
{"op":"mcm","clk":"11956968384","pt":1724552231026,"mc":[{"id":"1.232224255","rc":[{"batb":[[0,1.72,5],[1,1.71,60.49],[2,1.21,24.75]],"ltp":1.75,"tv":110.16,"id":61422697},{"batb":[[0,2.24,5],[1,2.22,35.2],[2,1.21,24.75]],"ltp":2.22,"tv":10.0,"id":60971788}]}]}
{"op":"mcm","clk":"11956968725","pt":1724552234550,"mc":[{"id":"1.232224255","rc":[{"batb":[[0,1.71,60.49],[1,1.21,24.75],[2,1.08,1.76]],"ltp":1.75,"tv":110.16,"id":61422697},{"batb":[[0,2.22,35.2],[1,1.21,24.75],[2,1.08,1.76]],"ltp":2.22,"tv":10.0,"id":60971788}]}]}
{"op":"mcm","clk":"11956969047","pt":1724552238845,"mc":[{"id":"1.232224255","rc":[{"batb":[[0,1.72,5],[1,1.71,60.49],[2,1.21,24.75]],"ltp":1.75,"tv":110.16,"id":61422697},{"batb":[[0,2.24,5],[1,2.22,35.2],[2,1.21,24.75]],"ltp":2.22,"tv":10.0,"id":60971788}]}]}
{"op":"mcm","clk":"11956969293","pt":1724552242152,"mc":[{"id":"1.232224255","rc":[{"batb":[[0,1.71,60.49],[1,1.21,24.75],[2,1.08,1.76]],"ltp":1.75,"tv":110.16,"id":61422697},{"batb":[[0,2.22,35.2],[1,1.21,24.75],[2,1.08,1.76]],"ltp":2.22,"tv":10.0,"id":60971788}]}]}
{"op":"mcm","clk":"11956969464","pt":1724552244538,"mc":[{"id":"1.232224255","rc":[{"batb":[[0,1.72,5],[1,1.71,60.49],[2,1.21,24.75]],"ltp":1.75,"tv":110.16,"id":61422697},{"batb":[[0,2.24,5],[1,2.22,35.2],[2,1.21,24.75]],"ltp":2.22,"tv":10.0,"id":60971788}]}]}
{"op":"mcm","clk":"11956969744","pt":1724552247863,"mc":[{"id":"1.232224255","rc":[{"batb":[[0,1.71,60.49],[1,1.21,24.75],[2,1.08,1.76]],"ltp":1.75,"tv":110.16,"id":61422697},{"batb":[[0,2.22,35.2],[1,1.21,24.75],[2,1.08,1.76]],"ltp":2.22,"tv":10.0,"id":60971788}]}]}
{"op":"mcm","clk":"11956969943","pt":1724552250242,"mc":[{"id":"1.232224255","rc":[{"batb":[[0,1.72,5],[1,1.71,60.49],[2,1.21,24.75]],"ltp":1.75,"tv":110.16,"id":61422697},{"batb":[[0,2.24,5],[1,2.22,35.2],[2,1.21,24.75]],"ltp":2.22,"tv":10.0,"id":60971788}]}]}
{"op":"mcm","clk":"11956970182","pt":1724552253549,"mc":[{"id":"1.232224255","rc":[{"batb":[[0,1.71,60.49],[1,1.21,24.75],[2,1.08,1.76]],"ltp":1.75,"tv":110.16,"id":61422697},{"batb":[[0,2.22,35.2],[1,1.21,24.75],[2,1.08,1.76]],"ltp":2.22,"tv":10.0,"id":60971788}]}]}
{"op":"mcm","clk":"11956970346","pt":1724552255762,"mc":[{"id":"1.232224255","rc":[{"batb":[[0,1.72,5],[1,1.71,60.49],[2,1.21,24.75]],"ltp":1.75,"tv":110.16,"id":61422697},{"batb":[[0,2.24,5],[1,2.22,35.2],[2,1.21,24.75]],"ltp":2.22,"tv":10.0,"id":60971788}]}]}
{"op":"mcm","clk":"11956970586","pt":1724552259065,"mc":[{"id":"1.232224255","rc":[{"batb":[[0,1.71,60.49],[1,1.21,24.75],[2,1.08,1.76]],"ltp":1.75,"tv":110.16,"id":61422697},{"batb":[[0,2.22,35.2],[1,1.21,24.75],[2,1.08,1.76]],"ltp":2.22,"tv":10.0,"id":60971788}]}]}
{"op":"mcm","clk":"11956970798","pt":1724552261844,"mc":[{"id":"1.232224255","rc":[{"batb":[[0,1.72,5],[1,1.71,60.49],[2,1.21,24.75]],"ltp":1.75,"tv":110.16,"id":61422697},{"batb":[[0,2.24,5],[1,2.22,35.2],[2,1.21,24.75]],"ltp":2.22,"tv":10.0,"id":60971788}]}]}
{"op":"mcm","clk":"11956971029","pt":1724552265392,"mc":[{"id":"1.232224255","rc":[{"batb":[[0,1.71,60.49],[1,1.21,24.75],[2,1.08,1.76]],"ltp":1.75,"tv":110.16,"id":61422697},{"batb":[[0,2.22,35.2],[1,1.21,24.75],[2,1.08,1.76]],"ltp":2.22,"tv":10.0,"id":60971788}]}]}
{"op":"mcm","clk":"11956971178","pt":1724552267568,"mc":[{"id":"1.232224255","rc":[{"batb":[[0,1.72,5],[1,1.71,60.49],[2,1.21,24.75]],"ltp":1.75,"tv":110.16,"id":61422697},{"batb":[[0,2.24,5],[1,2.22,35.2],[2,1.21,24.75]],"ltp":2.22,"tv":10.0,"id":60971788}]}]}
{"op":"mcm","clk":"11956971387","pt":1724552270958,"mc":[{"id":"1.232224255","rc":[{"batb":[[0,1.71,60.49],[1,1.21,24.75],[2,1.08,1.76]],"ltp":1.75,"tv":110.16,"id":61422697},{"batb":[[0,2.22,35.2],[1,1.21,24.75],[2,1.08,1.76]],"ltp":2.22,"tv":10.0,"id":60971788}]}]}
{"op":"mcm","clk":"11956971532","pt":1724552273172,"mc":[{"id":"1.232224255","rc":[{"batb":[[0,1.72,5],[1,1.71,60.49],[2,1.21,24.75]],"ltp":1.75,"tv":110.16,"id":61422697},{"batb":[[0,2.24,5],[1,2.22,35.2],[2,1.21,24.75]],"ltp":2.22,"tv":10.0,"id":60971788}]}]}
{"op":"mcm","clk":"11956971721","pt":1724552276489,"mc":[{"id":"1.232224255","rc":[{"batb":[[0,1.71,60.49],[1,1.21,24.75],[2,1.08,1.76]],"ltp":1.75,"tv":110.16,"id":61422697},{"batb":[[0,2.22,35.2],[1,1.21,24.75],[2,1.08,1.76]],"ltp":2.22,"tv":10.0,"id":60971788}]}]}
{"op":"mcm","clk":"11956971992","pt":1724552280574,"mc":[{"id":"1.232224255","rc":[{"batb":[[0,1.72,5],[1,1.71,60.49],[2,1.21,24.75]],"ltp":1.75,"tv":110.16,"id":61422697},{"batb":[[0,2.24,5],[1,2.22,35.2],[2,1.21,24.75]],"ltp":2.22,"tv":10.0,"id":60971788}]}]}
{"op":"mcm","clk":"11956972215","pt":1724552283890,"mc":[{"id":"1.232224255","rc":[{"batb":[[0,1.71,60.49],[1,1.21,24.75],[2,1.08,1.76]],"ltp":1.75,"tv":110.16,"id":61422697},{"batb":[[0,2.22,35.2],[1,1.21,24.75],[2,1.08,1.76]],"ltp":2.22,"tv":10.0,"id":60971788}]}]}
{"op":"mcm","clk":"11956972385","pt":1724552286074,"mc":[{"id":"1.232224255","rc":[{"batb":[[0,1.72,5],[1,1.71,60.49],[2,1.21,24.75]],"ltp":1.75,"tv":110.16,"id":61422697},{"batb":[[0,2.24,5],[1,2.22,35.2],[2,1.21,24.75]],"ltp":2.22,"tv":10.0,"id":60971788}]}]}
{"op":"mcm","clk":"11956972619","pt":1724552289273,"mc":[{"id":"1.232224255","rc":[{"batb":[[0,1.71,60.49],[1,1.21,24.75],[2,1.08,1.76]],"ltp":1.75,"tv":110.16,"id":61422697},{"batb":[[0,2.22,35.2],[1,1.21,24.75],[2,1.08,1.76]],"ltp":2.22,"tv":10.0,"id":60971788}]}]}
{"op":"mcm","clk":"11956972881","pt":1724552292595,"mc":[{"id":"1.232224255","rc":[{"batb":[[0,1.72,5],[1,1.71,60.49],[2,1.21,24.75]],"ltp":1.75,"tv":110.16,"id":61422697},{"batb":[[0,2.24,5],[1,2.22,35.2],[2,1.21,24.75]],"ltp":2.22,"tv":10.0,"id":60971788}]}]}
{"op":"mcm","clk":"11956973150","pt":1724552295803,"mc":[{"id":"1.232224255","rc":[{"batb":[[0,1.71,60.49],[1,1.21,24.75],[2,1.08,1.76]],"ltp":1.75,"tv":110.16,"id":61422697},{"batb":[[0,2.22,35.2],[1,1.21,24.75],[2,1.08,1.76]],"ltp":2.22,"tv":10.0,"id":60971788}]}]}
{"op":"mcm","clk":"11956973340","pt":1724552298125,"mc":[{"id":"1.232224255","rc":[{"batb":[[0,1.72,5],[1,1.71,60.49],[2,1.21,24.75]],"ltp":1.75,"tv":110.16,"id":61422697},{"batb":[[0,2.24,5],[1,2.22,35.2],[2,1.21,24.75]],"ltp":2.22,"tv":10.0,"id":60971788}]}]}
{"op":"mcm","clk":"11956973562","pt":1724552301387,"mc":[{"id":"1.232224255","rc":[{"batb":[[0,1.71,60.49],[1,1.21,24.75],[2,1.08,1.76]],"ltp":1.75,"tv":110.16,"id":61422697},{"batb":[[0,2.22,35.2],[1,1.21,24.75],[2,1.08,1.76]],"ltp":2.22,"tv":10.0,"id":60971788}]}]}
{"op":"mcm","clk":"11956973868","pt":1724552305619,"mc":[{"id":"1.232224255","rc":[{"batb":[[0,1.72,5],[1,1.71,60.49],[2,1.21,24.75]],"ltp":1.75,"tv":110.16,"id":61422697},{"batb":[[0,2.24,5],[1,2.22,35.2],[2,1.21,24.75]],"ltp":2.22,"tv":10.0,"id":60971788}]}]}
{"op":"mcm","clk":"11956974154","pt":1724552308920,"mc":[{"id":"1.232224255","rc":[{"batb":[[0,1.71,60.49],[1,1.21,24.75],[2,1.08,1.76]],"ltp":1.75,"tv":110.16,"id":61422697},{"batb":[[0,2.22,35.2],[1,1.21,24.75],[2,1.08,1.76]],"ltp":2.22,"tv":10.0,"id":60971788}]}]}
{"op":"mcm","clk":"11956974304","pt":1724552311133,"mc":[{"id":"1.232224255","rc":[{"batb":[[0,1.72,5],[1,1.71,60.49],[2,1.21,24.75]],"ltp":1.75,"tv":110.16,"id":61422697},{"batb":[[0,2.24,5],[1,2.22,35.2],[2,1.21,24.75]],"ltp":2.22,"tv":10.0,"id":60971788}]}]}
{"op":"mcm","clk":"11956974542","pt":1724552314434,"mc":[{"id":"1.232224255","rc":[{"batb":[[0,1.71,60.49],[1,1.21,24.75],[2,1.08,1.76]],"ltp":1.75,"tv":110.16,"id":61422697},{"batb":[[0,2.22,35.2],[1,1.21,24.75],[2,1.08,1.76]],"ltp":2.22,"tv":10.0,"id":60971788}]}]}
{"op":"mcm","clk":"11956974707","pt":1724552316720,"mc":[{"id":"1.232224255","rc":[{"batb":[[0,1.72,5],[1,1.71,60.49],[2,1.21,24.75]],"ltp":1.75,"tv":110.16,"id":61422697},{"batb":[[0,2.24,5],[1,2.22,35.2],[2,1.21,24.75]],"ltp":2.22,"tv":10.0,"id":60971788}]}]}
{"op":"mcm","clk":"11956974978","pt":1724552320233,"mc":[{"id":"1.232224255","rc":[{"batb":[[0,1.71,60.49],[1,1.21,24.75],[2,1.08,1.76]],"ltp":1.75,"tv":110.16,"id":61422697},{"batb":[[0,2.22,35.2],[1,1.21,24.75],[2,1.08,1.76]],"ltp":2.22,"tv":10.0,"id":60971788}]}]}
{"op":"mcm","clk":"11956975141","pt":1724552322449,"mc":[{"id":"1.232224255","rc":[{"batb":[[0,1.72,5],[1,1.71,60.49],[2,1.21,24.75]],"ltp":1.75,"tv":110.16,"id":61422697},{"batb":[[0,2.24,5],[1,2.22,35.2],[2,1.21,24.75]],"ltp":2.22,"tv":10.0,"id":60971788}]}]}
{"op":"mcm","clk":"11956975369","pt":1724552325756,"mc":[{"id":"1.232224255","rc":[{"batb":[[0,1.71,60.49],[1,1.21,24.75],[2,1.08,1.76]],"ltp":1.75,"tv":110.16,"id":61422697},{"batb":[[0,2.22,35.2],[1,1.21,24.75],[2,1.08,1.76]],"ltp":2.22,"tv":10.0,"id":60971788}]}]}
{"op":"mcm","clk":"11956975537","pt":1724552328029,"mc":[{"id":"1.232224255","rc":[{"batb":[[0,1.72,5],[1,1.71,60.49],[2,1.21,24.75]],"ltp":1.75,"tv":110.16,"id":61422697},{"batb":[[0,2.24,5],[1,2.22,35.2],[2,1.21,24.75]],"ltp":2.22,"tv":10.0,"id":60971788}]}]}
{"op":"mcm","clk":"11956975731","pt":1724552331271,"mc":[{"id":"1.232224255","rc":[{"batb":[[0,1.71,60.49],[1,1.21,24.75],[2,1.08,1.76]],"ltp":1.75,"tv":110.16,"id":61422697},{"batb":[[0,2.22,35.2],[1,1.21,24.75],[2,1.08,1.76]],"ltp":2.22,"tv":10.0,"id":60971788}]}]}
{"op":"mcm","clk":"11956975888","pt":1724552333448,"mc":[{"id":"1.232224255","rc":[{"batb":[[0,1.72,5],[1,1.71,60.49],[2,1.21,24.75]],"ltp":1.75,"tv":110.16,"id":61422697},{"batb":[[0,2.24,5],[1,2.22,35.2],[2,1.21,24.75]],"ltp":2.22,"tv":10.0,"id":60971788}]}]}
{"op":"mcm","clk":"11956976111","pt":1724552336649,"mc":[{"id":"1.232224255","rc":[{"batb":[[0,1.71,60.49],[1,1.21,24.75],[2,1.08,1.76]],"ltp":1.75,"tv":110.16,"id":61422697},{"batb":[[0,2.22,35.2],[1,1.21,24.75],[2,1.08,1.76]],"ltp":2.22,"tv":10.0,"id":60971788}]}]}
{"op":"mcm","clk":"11956976290","pt":1724552339174,"mc":[{"id":"1.232224255","rc":[{"batb":[[0,1.72,5],[1,1.71,60.49],[2,1.21,24.75]],"ltp":1.75,"tv":110.16,"id":61422697},{"batb":[[0,2.24,5],[1,2.22,35.2],[2,1.21,24.75]],"ltp":2.22,"tv":10.0,"id":60971788}]}]}
{"op":"mcm","clk":"11956976547","pt":1724552342378,"mc":[{"id":"1.232224255","rc":[{"batb":[[0,1.71,60.49],[1,1.21,24.75],[2,1.08,1.76]],"ltp":1.75,"tv":110.16,"id":61422697},{"batb":[[0,2.22,35.2],[1,1.21,24.75],[2,1.08,1.76]],"ltp":2.22,"tv":10.0,"id":60971788}]}]}
{"op":"mcm","clk":"11956976731","pt":1724552344756,"mc":[{"id":"1.232224255","rc":[{"batb":[[0,1.72,5],[1,1.71,60.49],[2,1.21,24.75]],"ltp":1.75,"tv":110.16,"id":61422697},{"batb":[[0,2.24,5],[1,2.22,35.2],[2,1.21,24.75]],"ltp":2.22,"tv":10.0,"id":60971788}]}]}
{"op":"mcm","clk":"11956976995","pt":1724552347973,"mc":[{"id":"1.232224255","rc":[{"batb":[[0,1.71,60.49],[1,1.21,24.75],[2,1.08,1.76]],"ltp":1.75,"tv":110.16,"id":61422697},{"batb":[[0,2.22,35.2],[1,1.21,24.75],[2,1.08,1.76]],"ltp":2.22,"tv":10.0,"id":60971788}]}]}
{"op":"mcm","clk":"11956977259","pt":1724552351173,"mc":[{"id":"1.232224255","rc":[{"batb":[[0,1.72,5],[1,1.71,60.49],[2,1.21,24.75]],"ltp":1.75,"tv":110.16,"id":61422697},{"batb":[[0,2.24,5],[1,2.22,35.2],[2,1.21,24.75]],"ltp":2.22,"tv":10.0,"id":60971788}]}]}
{"op":"mcm","clk":"11956977495","pt":1724552354582,"mc":[{"id":"1.232224255","rc":[{"batb":[[0,1.71,60.49],[1,1.21,24.75],[2,1.08,1.76]],"ltp":1.75,"tv":110.16,"id":61422697},{"batb":[[0,2.22,35.2],[1,1.21,24.75],[2,1.08,1.76]],"ltp":2.22,"tv":10.0,"id":60971788}]}]}
{"op":"mcm","clk":"11956977680","pt":1724552356860,"mc":[{"id":"1.232224255","rc":[{"batb":[[0,1.72,5],[1,1.71,60.49],[2,1.21,24.75]],"ltp":1.75,"tv":110.16,"id":61422697},{"batb":[[0,2.24,5],[1,2.22,35.2],[2,1.21,24.75]],"ltp":2.22,"tv":10.0,"id":60971788}]}]}
{"op":"mcm","clk":"11956977917","pt":1724552360073,"mc":[{"id":"1.232224255","rc":[{"batb":[[0,1.71,60.49],[1,1.21,24.75],[2,1.08,1.76]],"ltp":1.75,"tv":110.16,"id":61422697},{"batb":[[0,2.22,35.2],[1,1.21,24.75],[2,1.08,1.76]],"ltp":2.22,"tv":10.0,"id":60971788}]}]}
{"op":"mcm","clk":"11956978075","pt":1724552362299,"mc":[{"id":"1.232224255","rc":[{"batb":[[0,1.72,5],[1,1.71,60.49],[2,1.21,24.75]],"ltp":1.75,"tv":110.16,"id":61422697},{"batb":[[0,2.24,5],[1,2.22,35.2],[2,1.21,24.75]],"ltp":2.22,"tv":10.0,"id":60971788}]}]}
{"op":"mcm","clk":"11956978325","pt":1724552365666,"mc":[{"id":"1.232224255","rc":[{"batb":[[0,1.71,60.49],[1,1.21,24.75],[2,1.08,1.76]],"ltp":1.75,"tv":110.16,"id":61422697},{"batb":[[0,2.22,35.2],[1,1.21,24.75],[2,1.08,1.76]],"ltp":2.22,"tv":10.0,"id":60971788}]}]}
{"op":"mcm","clk":"11956978470","pt":1724552367775,"mc":[{"id":"1.232224255","rc":[{"batb":[[0,1.72,5],[1,1.71,60.49],[2,1.21,24.75]],"ltp":1.75,"tv":110.16,"id":61422697},{"batb":[[0,2.24,5],[1,2.22,35.2],[2,1.21,24.75]],"ltp":2.22,"tv":10.0,"id":60971788}]}]}
{"op":"mcm","clk":"11956978710","pt":1724552371322,"mc":[{"id":"1.232224255","rc":[{"batb":[[0,1.71,60.49],[1,1.21,24.75],[2,1.08,1.76]],"ltp":1.75,"tv":110.16,"id":61422697},{"batb":[[0,2.22,35.2],[1,1.21,24.75],[2,1.08,1.76]],"ltp":2.22,"tv":10.0,"id":60971788}]}]}
{"op":"mcm","clk":"11956978911","pt":1724552373800,"mc":[{"id":"1.232224255","rc":[{"batb":[[0,1.72,5],[1,1.71,60.49],[2,1.21,24.75]],"ltp":1.75,"tv":110.16,"id":61422697},{"batb":[[0,2.24,5],[1,2.22,35.2],[2,1.21,24.75]],"ltp":2.22,"tv":10.0,"id":60971788}]}]}
{"op":"mcm","clk":"11956979140","pt":1724552377206,"mc":[{"id":"1.232224255","rc":[{"batb":[[0,1.71,60.49],[1,1.21,24.75],[2,1.08,1.76]],"ltp":1.75,"tv":110.16,"id":61422697},{"batb":[[0,2.22,35.2],[1,1.21,24.75],[2,1.08,1.76]],"ltp":2.22,"tv":10.0,"id":60971788}]}]}
{"op":"mcm","clk":"11956979589","pt":1724552382592,"mc":[{"id":"1.232224255","rc":[{"batb":[[0,1.72,5],[1,1.71,60.49],[2,1.21,24.75]],"ltp":1.75,"tv":110.16,"id":61422697},{"batb":[[0,2.24,5],[1,2.22,35.2],[2,1.21,24.75]],"ltp":2.22,"tv":10.0,"id":60971788}]}]}
{"op":"mcm","clk":"11956979810","pt":1724552385898,"mc":[{"id":"1.232224255","rc":[{"batb":[[0,1.71,60.49],[1,1.21,24.75],[2,1.08,1.76]],"ltp":1.75,"tv":110.16,"id":61422697},{"batb":[[0,2.22,35.2],[1,1.21,24.75],[2,1.08,1.76]],"ltp":2.22,"tv":10.0,"id":60971788}]}]}
{"op":"mcm","clk":"11956979952","pt":1724552388523,"mc":[{"id":"1.232224255","rc":[{"batb":[[0,1.72,5],[1,1.71,60.49],[2,1.21,24.75]],"ltp":1.75,"tv":110.16,"id":61422697},{"batb":[[0,2.24,5],[1,2.22,35.2],[2,1.21,24.75]],"ltp":2.22,"tv":10.0,"id":60971788}]}]}
{"op":"mcm","clk":"11956980180","pt":1724552392025,"mc":[{"id":"1.232224255","rc":[{"batb":[[0,1.71,60.49],[1,1.21,24.75],[2,1.08,1.76]],"ltp":1.75,"tv":110.16,"id":61422697},{"batb":[[0,2.22,35.2],[1,1.21,24.75],[2,1.08,1.76]],"ltp":2.22,"tv":10.0,"id":60971788}]}]}
{"op":"mcm","clk":"11956980441","pt":1724552396307,"mc":[{"id":"1.232224255","rc":[{"batb":[[0,1.72,5],[1,1.71,60.49],[2,1.21,24.75]],"ltp":1.75,"tv":110.16,"id":61422697},{"batb":[[0,2.24,5],[1,2.22,35.2],[2,1.21,24.75]],"ltp":2.22,"tv":10.0,"id":60971788}]}]}
{"op":"mcm","clk":"11956980631","pt":1724552399650,"mc":[{"id":"1.232224255","rc":[{"batb":[[0,1.71,60.49],[1,1.21,24.75],[2,1.08,1.76]],"ltp":1.75,"tv":110.16,"id":61422697},{"batb":[[0,2.22,35.2],[1,1.21,24.75],[2,1.08,1.76]],"ltp":2.22,"tv":10.0,"id":60971788}]}]}
{"op":"mcm","clk":"11956980865","pt":1724552402815,"mc":[{"id":"1.232224255","rc":[{"batb":[[0,1.72,5],[1,1.71,60.49],[2,1.21,24.75]],"ltp":1.75,"tv":110.16,"id":61422697},{"batb":[[0,2.24,5],[1,2.22,35.2],[2,1.21,24.75]],"ltp":2.22,"tv":10.0,"id":60971788}]}]}
{"op":"mcm","clk":"11956981066","pt":1724552406134,"mc":[{"id":"1.232224255","rc":[{"batb":[[0,1.71,60.49],[1,1.21,24.75],[2,1.08,1.76]],"ltp":1.75,"tv":110.16,"id":61422697},{"batb":[[0,2.22,35.2],[1,1.21,24.75],[2,1.08,1.76]],"ltp":2.22,"tv":10.0,"id":60971788}]}]}
{"op":"mcm","clk":"11956981244","pt":1724552409128,"mc":[{"id":"1.232224255","rc":[{"batb":[[0,1.72,5],[1,1.71,60.49],[2,1.21,24.75]],"ltp":1.75,"tv":110.16,"id":61422697},{"batb":[[0,2.24,5],[1,2.22,35.2],[2,1.21,24.75]],"ltp":2.22,"tv":10.0,"id":60971788}]}]}
{"op":"mcm","clk":"11956981544","pt":1724552412668,"mc":[{"id":"1.232224255","rc":[{"batb":[[0,1.71,60.49],[1,1.21,24.75],[2,1.08,1.76]],"ltp":1.75,"tv":110.16,"id":61422697},{"batb":[[0,2.22,35.2],[1,1.21,24.75],[2,1.08,1.76]],"ltp":2.22,"tv":10.0,"id":60971788}]}]}
{"op":"mcm","clk":"11956981755","pt":1724552415453,"mc":[{"id":"1.232224255","rc":[{"batb":[[0,1.72,5],[1,1.71,60.49],[2,1.21,24.75]],"ltp":1.75,"tv":110.16,"id":61422697},{"batb":[[0,2.24,5],[1,2.22,35.2],[2,1.21,24.75]],"ltp":2.22,"tv":10.0,"id":60971788}]}]}
{"op":"mcm","clk":"11956982008","pt":1724552418744,"mc":[{"id":"1.232224255","rc":[{"batb":[[0,1.71,60.49],[1,1.21,24.75],[2,1.08,1.76]],"ltp":1.75,"tv":110.16,"id":61422697},{"batb":[[0,2.22,35.2],[1,1.21,24.75],[2,1.08,1.76]],"ltp":2.22,"tv":10.0,"id":60971788}]}]}
{"op":"mcm","clk":"11956982206","pt":1724552421372,"mc":[{"id":"1.232224255","rc":[{"batb":[[0,1.72,5],[1,1.71,60.49],[2,1.21,24.75]],"ltp":1.75,"tv":110.16,"id":61422697},{"batb":[[0,2.24,5],[1,2.22,35.2],[2,1.21,24.75]],"ltp":2.22,"tv":10.0,"id":60971788}]}]}
{"op":"mcm","clk":"11956982463","pt":1724552424676,"mc":[{"id":"1.232224255","rc":[{"batb":[[0,1.71,60.49],[1,1.21,24.75],[2,1.08,1.76]],"ltp":1.75,"tv":110.16,"id":61422697},{"batb":[[0,2.22,35.2],[1,1.21,24.75],[2,1.08,1.76]],"ltp":2.22,"tv":10.0,"id":60971788}]}]}
{"op":"mcm","clk":"11956982622","pt":1724552426896,"mc":[{"id":"1.232224255","rc":[{"batb":[[0,1.72,5],[1,1.71,60.49],[2,1.21,24.75]],"ltp":1.75,"tv":110.16,"id":61422697},{"batb":[[0,2.24,5],[1,2.22,35.2],[2,1.21,24.75]],"ltp":2.22,"tv":10.0,"id":60971788}]}]}
{"op":"mcm","clk":"11956983052","pt":1724552432684,"mc":[{"id":"1.232224255","rc":[{"batb":[[0,1.71,60.49],[1,1.21,24.75],[2,1.08,1.76]],"ltp":1.75,"tv":110.16,"id":61422697},{"batb":[[0,2.22,35.2],[1,1.21,24.75],[2,1.08,1.76]],"ltp":2.22,"tv":10.0,"id":60971788}]}]}
{"op":"mcm","clk":"11956983204","pt":1724552434904,"mc":[{"id":"1.232224255","rc":[{"batb":[[0,1.72,5],[1,1.71,60.49],[2,1.21,24.75]],"ltp":1.75,"tv":110.16,"id":61422697},{"batb":[[0,2.24,5],[1,2.22,35.2],[2,1.21,24.75]],"ltp":2.22,"tv":10.0,"id":60971788}]}]}
{"op":"mcm","clk":"11956983453","pt":1724552438115,"mc":[{"id":"1.232224255","rc":[{"batb":[[0,1.71,60.49],[1,1.21,24.75],[2,1.08,1.76]],"ltp":1.75,"tv":110.16,"id":61422697},{"batb":[[0,2.22,35.2],[1,1.21,24.75],[2,1.08,1.76]],"ltp":2.22,"tv":10.0,"id":60971788}]}]}
{"op":"mcm","clk":"11956983639","pt":1724552440385,"mc":[{"id":"1.232224255","rc":[{"batb":[[0,1.72,5],[1,1.71,60.49],[2,1.21,24.75]],"ltp":1.75,"tv":110.16,"id":61422697},{"batb":[[0,2.24,5],[1,2.22,35.2],[2,1.21,24.75]],"ltp":2.22,"tv":10.0,"id":60971788}]}]}
{"op":"mcm","clk":"11956983877","pt":1724552443615,"mc":[{"id":"1.232224255","rc":[{"batb":[[0,1.71,60.49],[1,1.21,24.75],[2,1.08,1.76]],"ltp":1.75,"tv":110.16,"id":61422697},{"batb":[[0,2.22,35.2],[1,1.21,24.75],[2,1.08,1.76]],"ltp":2.22,"tv":10.0,"id":60971788}]}]}
{"op":"mcm","clk":"11956984172","pt":1724552447175,"mc":[{"id":"1.232224255","rc":[{"batb":[[0,1.72,5],[1,1.71,60.49],[2,1.21,24.75]],"ltp":1.75,"tv":110.16,"id":61422697},{"batb":[[0,2.24,5],[1,2.22,35.2],[2,1.21,24.75]],"ltp":2.22,"tv":10.0,"id":60971788}]}]}
{"op":"mcm","clk":"11956984450","pt":1724552450487,"mc":[{"id":"1.232224255","rc":[{"batb":[[0,1.71,60.49],[1,1.21,24.75],[2,1.08,1.76]],"ltp":1.75,"tv":110.16,"id":61422697},{"batb":[[0,2.22,35.2],[1,1.21,24.75],[2,1.08,1.76]],"ltp":2.22,"tv":10.0,"id":60971788}]}]}
{"op":"mcm","clk":"11956984600","pt":1724552452798,"mc":[{"id":"1.232224255","rc":[{"batb":[[0,1.72,5],[1,1.71,60.49],[2,1.21,24.75]],"ltp":1.75,"tv":110.16,"id":61422697},{"batb":[[0,2.24,5],[1,2.22,35.2],[2,1.21,24.75]],"ltp":2.22,"tv":10.0,"id":60971788}]}]}
{"op":"mcm","clk":"11956984807","pt":1724552455992,"mc":[{"id":"1.232224255","rc":[{"batb":[[0,1.71,60.49],[1,1.21,24.75],[2,1.08,1.76]],"ltp":1.75,"tv":110.16,"id":61422697},{"batb":[[0,2.22,35.2],[1,1.21,24.75],[2,1.08,1.76]],"ltp":2.22,"tv":10.0,"id":60971788}]}]}
{"op":"mcm","clk":"11956984989","pt":1724552458308,"mc":[{"id":"1.232224255","rc":[{"batb":[[0,1.72,5],[1,1.71,60.49],[2,1.21,24.75]],"ltp":1.75,"tv":110.16,"id":61422697},{"batb":[[0,2.24,5],[1,2.22,35.2],[2,1.21,24.75]],"ltp":2.22,"tv":10.0,"id":60971788}]}]}
{"op":"mcm","clk":"11956985229","pt":1724552461708,"mc":[{"id":"1.232224255","rc":[{"batb":[[0,1.71,60.49],[1,1.21,24.75],[2,1.08,1.76]],"ltp":1.75,"tv":110.16,"id":61422697},{"batb":[[0,2.22,35.2],[1,1.21,24.75],[2,1.08,1.76]],"ltp":2.22,"tv":10.0,"id":60971788}]}]}
{"op":"mcm","clk":"11956985342","pt":1724552463924,"mc":[{"id":"1.232224255","rc":[{"batb":[[0,1.72,5],[1,1.71,60.49],[2,1.21,24.75]],"ltp":1.75,"tv":110.16,"id":61422697},{"batb":[[0,2.24,5],[1,2.22,35.2],[2,1.21,24.75]],"ltp":2.22,"tv":10.0,"id":60971788}]}]}
{"op":"mcm","clk":"11956985588","pt":1724552467220,"mc":[{"id":"1.232224255","rc":[{"batb":[[0,1.71,60.49],[1,1.21,24.75],[2,1.08,1.76]],"ltp":1.75,"tv":110.16,"id":61422697},{"batb":[[0,2.22,35.2],[1,1.21,24.75],[2,1.08,1.76]],"ltp":2.22,"tv":10.0,"id":60971788}]}]}
{"op":"mcm","clk":"11956985797","pt":1724552469442,"mc":[{"id":"1.232224255","rc":[{"batb":[[0,1.72,5],[1,1.71,60.49],[2,1.21,24.75]],"ltp":1.75,"tv":110.16,"id":61422697},{"batb":[[0,2.24,5],[1,2.22,35.2],[2,1.21,24.75]],"ltp":2.22,"tv":10.0,"id":60971788}]}]}
{"op":"mcm","clk":"11956986038","pt":1724552472944,"mc":[{"id":"1.232224255","rc":[{"batb":[[0,1.71,60.49],[1,1.21,24.75],[2,1.08,1.76]],"ltp":1.75,"tv":110.16,"id":61422697},{"batb":[[0,2.22,35.2],[1,1.21,24.75],[2,1.08,1.76]],"ltp":2.22,"tv":10.0,"id":60971788}]}]}
{"op":"mcm","clk":"11956986252","pt":1724552475533,"mc":[{"id":"1.232224255","rc":[{"batb":[[0,1.72,5],[1,1.71,60.49],[2,1.21,24.75]],"ltp":1.75,"tv":110.16,"id":61422697},{"batb":[[0,2.24,5],[1,2.22,35.2],[2,1.21,24.75]],"ltp":2.22,"tv":10.0,"id":60971788}]}]}
{"op":"mcm","clk":"11956986481","pt":1724552478821,"mc":[{"id":"1.232224255","rc":[{"batb":[[0,1.71,60.49],[1,1.21,24.75],[2,1.08,1.76]],"ltp":1.75,"tv":110.16,"id":61422697},{"batb":[[0,2.22,35.2],[1,1.21,24.75],[2,1.08,1.76]],"ltp":2.22,"tv":10.0,"id":60971788}]}]}
{"op":"mcm","clk":"11956986676","pt":1724552481556,"mc":[{"id":"1.232224255","rc":[{"batb":[[0,1.72,5],[1,1.71,60.49],[2,1.21,24.75]],"ltp":1.75,"tv":110.16,"id":61422697},{"batb":[[0,2.24,5],[1,2.22,35.2],[2,1.21,24.75]],"ltp":2.22,"tv":10.0,"id":60971788}]}]}
{"op":"mcm","clk":"11956986900","pt":1724552484848,"mc":[{"id":"1.232224255","rc":[{"batb":[[0,1.71,60.49],[1,1.21,24.75],[2,1.08,1.76]],"ltp":1.75,"tv":110.16,"id":61422697},{"batb":[[0,2.22,35.2],[1,1.21,24.75],[2,1.08,1.76]],"ltp":2.22,"tv":10.0,"id":60971788}]}]}
{"op":"mcm","clk":"11956987122","pt":1724552488060,"mc":[{"id":"1.232224255","rc":[{"batb":[[0,1.72,5],[1,1.71,60.49],[2,1.21,24.75]],"ltp":1.75,"tv":110.16,"id":61422697},{"batb":[[0,2.24,5],[1,2.22,35.2],[2,1.21,24.75]],"ltp":2.22,"tv":10.0,"id":60971788}]}]}
{"op":"mcm","clk":"11956987345","pt":1724552491459,"mc":[{"id":"1.232224255","rc":[{"batb":[[0,1.71,60.49],[1,1.21,24.75],[2,1.08,1.76]],"ltp":1.75,"tv":110.16,"id":61422697},{"batb":[[0,2.22,35.2],[1,1.21,24.75],[2,1.08,1.76]],"ltp":2.22,"tv":10.0,"id":60971788}]}]}
{"op":"mcm","clk":"11956987582","pt":1724552494657,"mc":[{"id":"1.232224255","rc":[{"batb":[[0,1.72,5],[1,1.71,60.49],[2,1.21,24.75]],"ltp":1.75,"tv":110.16,"id":61422697},{"batb":[[0,2.24,5],[1,2.22,35.2],[2,1.21,24.75]],"ltp":2.22,"tv":10.0,"id":60971788}]}]}
{"op":"mcm","clk":"11956987817","pt":1724552497967,"mc":[{"id":"1.232224255","rc":[{"batb":[[0,1.71,60.49],[1,1.21,24.75],[2,1.08,1.76]],"ltp":1.75,"tv":110.16,"id":61422697},{"batb":[[0,2.22,35.2],[1,1.21,24.75],[2,1.08,1.76]],"ltp":2.22,"tv":10.0,"id":60971788}]}]}
{"op":"mcm","clk":"11956987954","pt":1724552500284,"mc":[{"id":"1.232224255","rc":[{"batb":[[0,1.72,5],[1,1.71,60.49],[2,1.21,24.75]],"ltp":1.75,"tv":110.16,"id":61422697},{"batb":[[0,2.24,5],[1,2.22,35.2],[2,1.21,24.75]],"ltp":2.22,"tv":10.0,"id":60971788}]}]}
{"op":"mcm","clk":"11956988179","pt":1724552503557,"mc":[{"id":"1.232224255","rc":[{"batb":[[0,1.71,60.49],[1,1.21,24.75],[2,1.08,1.76]],"ltp":1.75,"tv":110.16,"id":61422697},{"batb":[[0,2.22,35.2],[1,1.21,24.75],[2,1.08,1.76]],"ltp":2.22,"tv":10.0,"id":60971788}]}]}
{"op":"mcm","clk":"11956988386","pt":1724552506179,"mc":[{"id":"1.232224255","rc":[{"batb":[[0,1.72,5],[1,1.71,60.49],[2,1.21,24.75]],"ltp":1.75,"tv":110.16,"id":61422697},{"batb":[[0,2.24,5],[1,2.22,35.2],[2,1.21,24.75]],"ltp":2.22,"tv":10.0,"id":60971788}]}]}
{"op":"mcm","clk":"11956988604","pt":1724552509477,"mc":[{"id":"1.232224255","rc":[{"batb":[[0,1.71,60.49],[1,1.21,24.75],[2,1.08,1.76]],"ltp":1.75,"tv":110.16,"id":61422697},{"batb":[[0,2.22,35.2],[1,1.21,24.75],[2,1.08,1.76]],"ltp":2.22,"tv":10.0,"id":60971788}]}]}
{"op":"mcm","clk":"11956988770","pt":1724552511693,"mc":[{"id":"1.232224255","rc":[{"batb":[[0,1.72,5],[1,1.71,60.49],[2,1.21,24.75]],"ltp":1.75,"tv":110.16,"id":61422697},{"batb":[[0,2.24,5],[1,2.22,35.2],[2,1.21,24.75]],"ltp":2.22,"tv":10.0,"id":60971788}]}]}
{"op":"mcm","clk":"11956988995","pt":1724552515090,"mc":[{"id":"1.232224255","rc":[{"batb":[[0,1.71,60.49],[1,1.21,24.75],[2,1.08,1.76]],"ltp":1.75,"tv":110.16,"id":61422697},{"batb":[[0,2.22,35.2],[1,1.21,24.75],[2,1.08,1.76]],"ltp":2.22,"tv":10.0,"id":60971788}]}]}
{"op":"mcm","clk":"11956989246","pt":1724552518710,"mc":[{"id":"1.232224255","rc":[{"batb":[[0,1.72,5],[1,1.71,60.49],[2,1.21,24.75]],"ltp":1.75,"tv":110.16,"id":61422697},{"batb":[[0,2.24,5],[1,2.22,35.2],[2,1.21,24.75]],"ltp":2.22,"tv":10.0,"id":60971788}]}]}
{"op":"mcm","clk":"11956989546","pt":1724552521978,"mc":[{"id":"1.232224255","rc":[{"batb":[[0,1.71,60.49],[1,1.21,24.75],[2,1.08,1.76]],"ltp":1.75,"tv":110.16,"id":61422697},{"batb":[[0,2.22,35.2],[1,1.21,24.75],[2,1.08,1.76]],"ltp":2.22,"tv":10.0,"id":60971788}]}]}
{"op":"mcm","clk":"11956989709","pt":1724552524201,"mc":[{"id":"1.232224255","rc":[{"batb":[[0,1.72,5],[1,1.71,60.49],[2,1.21,24.75]],"ltp":1.75,"tv":110.16,"id":61422697},{"batb":[[0,2.24,5],[1,2.22,35.2],[2,1.21,24.75]],"ltp":2.22,"tv":10.0,"id":60971788}]}]}
{"op":"mcm","clk":"11956989963","pt":1724552527598,"mc":[{"id":"1.232224255","rc":[{"batb":[[0,1.71,60.49],[1,1.21,24.75],[2,1.08,1.76]],"ltp":1.75,"tv":110.16,"id":61422697},{"batb":[[0,2.22,35.2],[1,1.21,24.75],[2,1.08,1.76]],"ltp":2.22,"tv":10.0,"id":60971788}]}]}
{"op":"mcm","clk":"11956990207","pt":1724552530800,"mc":[{"id":"1.232224255","rc":[{"batb":[[0,1.72,5],[1,1.71,60.49],[2,1.21,24.75]],"ltp":1.75,"tv":110.16,"id":61422697},{"batb":[[0,2.24,5],[1,2.22,35.2],[2,1.21,24.75]],"ltp":2.22,"tv":10.0,"id":60971788}]}]}
{"op":"mcm","clk":"11956990480","pt":1724552534098,"mc":[{"id":"1.232224255","rc":[{"batb":[[0,1.71,60.49],[1,1.21,24.75],[2,1.08,1.76]],"ltp":1.75,"tv":110.16,"id":61422697},{"batb":[[0,2.22,35.2],[1,1.21,24.75],[2,1.08,1.76]],"ltp":2.22,"tv":10.0,"id":60971788}]}]}
{"op":"mcm","clk":"11956990705","pt":1724552536835,"mc":[{"id":"1.232224255","rc":[{"batb":[[0,1.72,5],[1,1.71,60.49],[2,1.21,24.75]],"ltp":1.75,"tv":110.16,"id":61422697},{"batb":[[0,2.24,5],[1,2.22,35.2],[2,1.21,24.75]],"ltp":2.22,"tv":10.0,"id":60971788}]}]}
{"op":"mcm","clk":"11956990937","pt":1724552540131,"mc":[{"id":"1.232224255","rc":[{"batb":[[0,1.71,60.49],[1,1.21,24.75],[2,1.08,1.76]],"ltp":1.75,"tv":110.16,"id":61422697},{"batb":[[0,2.22,35.2],[1,1.21,24.75],[2,1.08,1.76]],"ltp":2.22,"tv":10.0,"id":60971788}]}]}
{"op":"mcm","clk":"11956991133","pt":1724552542305,"mc":[{"id":"1.232224255","rc":[{"batb":[[0,1.72,5],[1,1.71,60.49],[2,1.21,24.75]],"ltp":1.75,"tv":110.16,"id":61422697},{"batb":[[0,2.24,5],[1,2.22,35.2],[2,1.21,24.75]],"ltp":2.22,"tv":10.0,"id":60971788}]}]}
{"op":"mcm","clk":"11956991404","pt":1724552545619,"mc":[{"id":"1.232224255","rc":[{"batb":[[0,1.71,60.49],[1,1.21,24.75],[2,1.08,1.76]],"ltp":1.75,"tv":110.16,"id":61422697},{"batb":[[0,2.22,35.2],[1,1.21,24.75],[2,1.08,1.76]],"ltp":2.22,"tv":10.0,"id":60971788}]}]}
{"op":"mcm","clk":"11956991626","pt":1724552548408,"mc":[{"id":"1.232224255","rc":[{"batb":[[0,1.72,5],[1,1.71,60.49],[2,1.21,24.75]],"ltp":1.75,"tv":110.16,"id":61422697},{"batb":[[0,2.24,5],[1,2.22,35.2],[2,1.21,24.75]],"ltp":2.22,"tv":10.0,"id":60971788}]}]}
{"op":"mcm","clk":"11956991900","pt":1724552551728,"mc":[{"id":"1.232224255","rc":[{"batb":[[0,1.71,60.49],[1,1.21,24.75],[2,1.08,1.76]],"ltp":1.75,"tv":110.16,"id":61422697},{"batb":[[0,2.22,35.2],[1,1.21,24.75],[2,1.08,1.76]],"ltp":2.22,"tv":10.0,"id":60971788}]}]}
{"op":"mcm","clk":"11956992075","pt":1724552553941,"mc":[{"id":"1.232224255","rc":[{"batb":[[0,1.72,5],[1,1.71,60.49],[2,1.21,24.75]],"ltp":1.75,"tv":110.16,"id":61422697},{"batb":[[0,2.24,5],[1,2.22,35.2],[2,1.21,24.75]],"ltp":2.22,"tv":10.0,"id":60971788}]}]}
{"op":"mcm","clk":"11956992348","pt":1724552557247,"mc":[{"id":"1.232224255","rc":[{"batb":[[0,1.71,60.49],[1,1.21,24.75],[2,1.08,1.76]],"ltp":1.75,"tv":110.16,"id":61422697},{"batb":[[0,2.22,35.2],[1,1.21,24.75],[2,1.08,1.76]],"ltp":2.22,"tv":10.0,"id":60971788}]}]}
{"op":"mcm","clk":"11956992524","pt":1724552559470,"mc":[{"id":"1.232224255","rc":[{"batb":[[0,1.72,5],[1,1.71,60.49],[2,1.21,24.75]],"ltp":1.75,"tv":110.16,"id":61422697},{"batb":[[0,2.24,5],[1,2.22,35.2],[2,1.21,24.75]],"ltp":2.22,"tv":10.0,"id":60971788}]}]}
{"op":"mcm","clk":"11956992793","pt":1724552562757,"mc":[{"id":"1.232224255","rc":[{"batb":[[0,1.71,60.49],[1,1.21,24.75],[2,1.08,1.76]],"ltp":1.75,"tv":110.16,"id":61422697},{"batb":[[0,2.22,35.2],[1,1.21,24.75],[2,1.08,1.76]],"ltp":2.22,"tv":10.0,"id":60971788}]}]}
{"op":"mcm","clk":"11956993094","pt":1724552566776,"mc":[{"id":"1.232224255","rc":[{"batb":[[0,1.72,5],[1,1.71,60.49],[2,1.21,24.75]],"ltp":1.75,"tv":110.16,"id":61422697},{"batb":[[0,2.24,5],[1,2.22,35.2],[2,1.21,24.75]],"ltp":2.22,"tv":10.0,"id":60971788}]}]}
{"op":"mcm","clk":"11956993334","pt":1724552570067,"mc":[{"id":"1.232224255","rc":[{"batb":[[0,1.71,60.49],[1,1.21,24.75],[2,1.08,1.76]],"ltp":1.75,"tv":110.16,"id":61422697},{"batb":[[0,2.22,35.2],[1,1.21,24.75],[2,1.08,1.76]],"ltp":2.22,"tv":10.0,"id":60971788}]}]}
{"op":"mcm","clk":"11956993538","pt":1724552572794,"mc":[{"id":"1.232224255","rc":[{"batb":[[0,1.72,5],[1,1.71,60.49],[2,1.21,24.75]],"ltp":1.75,"tv":110.16,"id":61422697},{"batb":[[0,2.24,5],[1,2.22,35.2],[2,1.21,24.75]],"ltp":2.22,"tv":10.0,"id":60971788}]}]}
{"op":"mcm","clk":"11956993793","pt":1724552576089,"mc":[{"id":"1.232224255","rc":[{"batb":[[0,1.71,60.49],[1,1.21,24.75],[2,1.08,1.76]],"ltp":1.75,"tv":110.16,"id":61422697},{"batb":[[0,2.22,35.2],[1,1.21,24.75],[2,1.08,1.76]],"ltp":2.22,"tv":10.0,"id":60971788}]}]}
{"op":"mcm","clk":"11956994000","pt":1724552578883,"mc":[{"id":"1.232224255","rc":[{"batb":[[0,1.72,5],[1,1.71,60.49],[2,1.21,24.75]],"ltp":1.75,"tv":110.16,"id":61422697},{"batb":[[0,2.24,5],[1,2.22,35.2],[2,1.21,24.75]],"ltp":2.22,"tv":10.0,"id":60971788}]}]}
{"op":"mcm","clk":"11956994265","pt":1724552582080,"mc":[{"id":"1.232224255","rc":[{"batb":[[0,1.71,60.49],[1,1.21,24.75],[2,1.08,1.76]],"ltp":1.75,"tv":110.16,"id":61422697},{"batb":[[0,2.22,35.2],[1,1.21,24.75],[2,1.08,1.76]],"ltp":2.22,"tv":10.0,"id":60971788}]}]}
{"op":"mcm","clk":"11956994428","pt":1724552584296,"mc":[{"id":"1.232224255","rc":[{"batb":[[0,1.72,5],[1,1.71,60.49],[2,1.21,24.75]],"ltp":1.75,"tv":110.16,"id":61422697},{"batb":[[0,2.24,5],[1,2.22,35.2],[2,1.21,24.75]],"ltp":2.22,"tv":10.0,"id":60971788}]}]}
{"op":"mcm","clk":"11956994705","pt":1724552587707,"mc":[{"id":"1.232224255","rc":[{"batb":[[0,1.71,60.49],[1,1.21,24.75],[2,1.08,1.76]],"ltp":1.75,"tv":110.16,"id":61422697},{"batb":[[0,2.22,35.2],[1,1.21,24.75],[2,1.08,1.76]],"ltp":2.22,"tv":10.0,"id":60971788}]}]}
{"op":"mcm","clk":"11956994931","pt":1724552590597,"mc":[{"id":"1.232224255","rc":[{"batb":[[0,1.72,5],[1,1.71,60.49],[2,1.21,24.75]],"ltp":1.75,"tv":110.16,"id":61422697},{"batb":[[0,2.24,5],[1,2.22,35.2],[2,1.21,24.75]],"ltp":2.22,"tv":10.0,"id":60971788}]}]}
{"op":"mcm","clk":"11956995211","pt":1724552593894,"mc":[{"id":"1.232224255","rc":[{"batb":[[0,1.71,60.49],[1,1.21,24.75],[2,1.08,1.76]],"ltp":1.75,"tv":110.16,"id":61422697},{"batb":[[0,2.22,35.2],[1,1.21,24.75],[2,1.08,1.76]],"ltp":2.22,"tv":10.0,"id":60971788}]}]}
{"op":"mcm","clk":"11956995446","pt":1724552597088,"mc":[{"id":"1.232224255","rc":[{"batb":[[0,1.72,5],[1,1.71,60.49],[2,1.21,24.75]],"ltp":1.75,"tv":110.16,"id":61422697},{"batb":[[0,2.24,5],[1,2.22,35.2],[2,1.21,24.75]],"ltp":2.22,"tv":10.0,"id":60971788}]}]}
{"op":"mcm","clk":"11956995691","pt":1724552600379,"mc":[{"id":"1.232224255","rc":[{"batb":[[0,1.71,60.49],[1,1.21,24.75],[2,1.08,1.76]],"ltp":1.75,"tv":110.16,"id":61422697},{"batb":[[0,2.22,35.2],[1,1.21,24.75],[2,1.08,1.76]],"ltp":2.22,"tv":10.0,"id":60971788}]}]}
{"op":"mcm","clk":"11956995933","pt":1724552603723,"mc":[{"id":"1.232224255","rc":[{"batb":[[0,1.72,5],[1,1.71,60.49],[2,1.21,24.75]],"ltp":1.75,"tv":110.16,"id":61422697},{"batb":[[0,2.24,5],[1,2.22,35.2],[2,1.21,24.75]],"ltp":2.22,"tv":10.0,"id":60971788}]}]}
{"op":"mcm","clk":"11956996203","pt":1724552607028,"mc":[{"id":"1.232224255","rc":[{"batb":[[0,1.71,60.49],[1,1.21,24.75],[2,1.08,1.76]],"ltp":1.75,"tv":110.16,"id":61422697},{"batb":[[0,2.22,35.2],[1,1.21,24.75],[2,1.08,1.76]],"ltp":2.22,"tv":10.0,"id":60971788}]}]}
{"op":"mcm","clk":"11956996422","pt":1724552609497,"mc":[{"id":"1.232224255","rc":[{"batb":[[0,1.72,5],[1,1.71,60.49],[2,1.21,24.75]],"ltp":1.75,"tv":110.16,"id":61422697},{"batb":[[0,2.24,5],[1,2.22,35.2],[2,1.21,24.75]],"ltp":2.22,"tv":10.0,"id":60971788}]}]}
{"op":"mcm","clk":"11956996666","pt":1724552612692,"mc":[{"id":"1.232224255","rc":[{"batb":[[0,1.71,60.49],[1,1.21,24.75],[2,1.08,1.76]],"ltp":1.75,"tv":110.16,"id":61422697},{"batb":[[0,2.22,35.2],[1,1.21,24.75],[2,1.08,1.76]],"ltp":2.22,"tv":10.0,"id":60971788}]}]}
{"op":"mcm","clk":"11956996898","pt":1724552615623,"mc":[{"id":"1.232224255","rc":[{"batb":[[0,1.72,5],[1,1.71,60.49],[2,1.21,24.75]],"ltp":1.75,"tv":110.16,"id":61422697},{"batb":[[0,2.24,5],[1,2.22,35.2],[2,1.21,24.75]],"ltp":2.22,"tv":10.0,"id":60971788}]}]}
{"op":"mcm","clk":"11956997168","pt":1724552619138,"mc":[{"id":"1.232224255","rc":[{"batb":[[0,1.71,60.49],[1,1.21,24.75],[2,1.08,1.76]],"ltp":1.75,"tv":110.16,"id":61422697},{"batb":[[0,2.22,35.2],[1,1.21,24.75],[2,1.08,1.76]],"ltp":2.22,"tv":10.0,"id":60971788}]}]}
{"op":"mcm","clk":"11956997311","pt":1724552621346,"mc":[{"id":"1.232224255","rc":[{"batb":[[0,1.72,5],[1,1.71,60.49],[2,1.21,24.75]],"ltp":1.75,"tv":110.16,"id":61422697},{"batb":[[0,2.24,5],[1,2.22,35.2],[2,1.21,24.75]],"ltp":2.22,"tv":10.0,"id":60971788}]}]}
{"op":"mcm","clk":"11956997544","pt":1724552624642,"mc":[{"id":"1.232224255","rc":[{"batb":[[0,1.71,60.49],[1,1.21,24.75],[2,1.08,1.76]],"ltp":1.75,"tv":110.16,"id":61422697},{"batb":[[0,2.22,35.2],[1,1.21,24.75],[2,1.08,1.76]],"ltp":2.22,"tv":10.0,"id":60971788}]}]}
{"op":"mcm","clk":"11956997732","pt":1724552627339,"mc":[{"id":"1.232224255","rc":[{"batb":[[0,1.72,5],[1,1.71,60.49],[2,1.21,24.75]],"ltp":1.75,"tv":110.16,"id":61422697},{"batb":[[0,2.24,5],[1,2.22,35.2],[2,1.21,24.75]],"ltp":2.22,"tv":10.0,"id":60971788}]}]}
{"op":"mcm","clk":"11956997960","pt":1724552630733,"mc":[{"id":"1.232224255","rc":[{"batb":[[0,1.71,60.49],[1,1.21,24.75],[2,1.08,1.76]],"ltp":1.75,"tv":110.16,"id":61422697},{"batb":[[0,2.22,35.2],[1,1.21,24.75],[2,1.08,1.76]],"ltp":2.22,"tv":10.0,"id":60971788}]}]}
{"op":"mcm","clk":"11956998157","pt":1724552633615,"mc":[{"id":"1.232224255","rc":[{"batb":[[0,1.72,5],[1,1.71,60.49],[2,1.21,24.75]],"ltp":1.75,"tv":110.16,"id":61422697},{"batb":[[0,2.24,5],[1,2.22,35.2],[2,1.21,24.75]],"ltp":2.22,"tv":10.0,"id":60971788}]}]}
{"op":"mcm","clk":"11956998363","pt":1724552636850,"mc":[{"id":"1.232224255","rc":[{"batb":[[0,1.71,60.49],[1,1.21,24.75],[2,1.08,1.76]],"ltp":1.75,"tv":110.16,"id":61422697},{"batb":[[0,2.22,35.2],[1,1.21,24.75],[2,1.08,1.76]],"ltp":2.22,"tv":10.0,"id":60971788}]}]}
{"op":"mcm","clk":"11956998566","pt":1724552639419,"mc":[{"id":"1.232224255","rc":[{"batb":[[0,1.72,5],[1,1.71,60.49],[2,1.21,24.75]],"ltp":1.75,"tv":110.16,"id":61422697},{"batb":[[0,2.24,5],[1,2.22,35.2],[2,1.21,24.75]],"ltp":2.22,"tv":10.0,"id":60971788}]}]}
{"op":"mcm","clk":"11956998841","pt":1724552642867,"mc":[{"id":"1.232224255","rc":[{"batb":[[0,1.71,60.49],[1,1.21,24.75],[2,1.08,1.76]],"ltp":1.75,"tv":110.16,"id":61422697},{"batb":[[0,2.22,35.2],[1,1.21,24.75],[2,1.08,1.76]],"ltp":2.22,"tv":10.0,"id":60971788}]}]}
{"op":"mcm","clk":"11956999037","pt":1724552645442,"mc":[{"id":"1.232224255","rc":[{"batb":[[0,1.72,5],[1,1.71,60.49],[2,1.21,24.75]],"ltp":1.75,"tv":110.16,"id":61422697},{"batb":[[0,2.24,5],[1,2.22,35.2],[2,1.21,24.75]],"ltp":2.22,"tv":10.0,"id":60971788}]}]}
{"op":"mcm","clk":"11956999353","pt":1724552648737,"mc":[{"id":"1.232224255","rc":[{"batb":[[0,1.71,60.49],[1,1.21,24.75],[2,1.08,1.76]],"ltp":1.75,"tv":110.16,"id":61422697},{"batb":[[0,2.22,35.2],[1,1.21,24.75],[2,1.08,1.76]],"ltp":2.22,"tv":10.0,"id":60971788}]}]}
{"op":"mcm","clk":"11956999538","pt":1724552650949,"mc":[{"id":"1.232224255","rc":[{"batb":[[0,1.72,5],[1,1.71,60.49],[2,1.21,24.75]],"ltp":1.75,"tv":110.16,"id":61422697},{"batb":[[0,2.24,5],[1,2.22,35.2],[2,1.21,24.75]],"ltp":2.22,"tv":10.0,"id":60971788}]}]}
{"op":"mcm","clk":"11956999827","pt":1724552654352,"mc":[{"id":"1.232224255","rc":[{"batb":[[0,1.71,60.49],[1,1.21,24.75],[2,1.08,1.76]],"ltp":1.75,"tv":110.16,"id":61422697},{"batb":[[0,2.22,35.2],[1,1.21,24.75],[2,1.08,1.76]],"ltp":2.22,"tv":10.0,"id":60971788}]}]}
{"op":"mcm","clk":"11957000558","pt":1724552662869,"mc":[{"id":"1.232224255","rc":[{"batb":[[0,1.72,5],[1,1.71,60.49],[2,1.21,24.75]],"ltp":1.75,"tv":110.16,"id":61422697},{"batb":[[0,2.24,5],[1,2.22,35.2],[2,1.21,24.75]],"ltp":2.22,"tv":10.0,"id":60971788}]}]}
{"op":"mcm","clk":"11957000787","pt":1724552666173,"mc":[{"id":"1.232224255","rc":[{"batb":[[0,1.71,60.49],[1,1.21,24.75],[2,1.08,1.76]],"ltp":1.75,"tv":110.16,"id":61422697},{"batb":[[0,2.22,35.2],[1,1.21,24.75],[2,1.08,1.76]],"ltp":2.22,"tv":10.0,"id":60971788}]}]}
{"op":"mcm","clk":"11957001014","pt":1724552669201,"mc":[{"id":"1.232224255","rc":[{"batb":[[0,1.72,5],[1,1.71,60.49],[2,1.21,24.75]],"ltp":1.75,"tv":110.16,"id":61422697},{"batb":[[0,2.24,5],[1,2.22,35.2],[2,1.21,24.75]],"ltp":2.22,"tv":10.0,"id":60971788}]}]}
{"op":"mcm","clk":"11957001273","pt":1724552672607,"mc":[{"id":"1.232224255","rc":[{"batb":[[0,1.71,60.49],[1,1.21,24.75],[2,1.08,1.76]],"ltp":1.75,"tv":110.16,"id":61422697},{"batb":[[0,2.22,35.2],[1,1.21,24.75],[2,1.08,1.76]],"ltp":2.22,"tv":10.0,"id":60971788}]}]}
{"op":"mcm","clk":"11957001440","pt":1724552674796,"mc":[{"id":"1.232224255","rc":[{"batb":[[0,1.72,5],[1,1.71,60.49],[2,1.21,24.75]],"ltp":1.75,"tv":110.16,"id":61422697},{"batb":[[0,2.24,5],[1,2.22,35.2],[2,1.21,24.75]],"ltp":2.22,"tv":10.0,"id":60971788}]}]}
{"op":"mcm","clk":"11957001693","pt":1724552677992,"mc":[{"id":"1.232224255","rc":[{"batb":[[0,1.71,60.49],[1,1.21,24.75],[2,1.08,1.76]],"ltp":1.75,"tv":110.16,"id":61422697},{"batb":[[0,2.22,35.2],[1,1.21,24.75],[2,1.08,1.76]],"ltp":2.22,"tv":10.0,"id":60971788}]}]}
{"op":"mcm","clk":"11957001927","pt":1724552680909,"mc":[{"id":"1.232224255","rc":[{"batb":[[0,1.72,5],[1,1.71,60.49],[2,1.21,24.75]],"ltp":1.75,"tv":110.16,"id":61422697},{"batb":[[0,2.24,5],[1,2.22,35.2],[2,1.21,24.75]],"ltp":2.22,"tv":10.0,"id":60971788}]}]}
{"op":"mcm","clk":"11957002215","pt":1724552684292,"mc":[{"id":"1.232224255","rc":[{"batb":[[0,1.71,60.49],[1,1.21,24.75],[2,1.08,1.76]],"ltp":1.75,"tv":110.16,"id":61422697},{"batb":[[0,2.22,35.2],[1,1.21,24.75],[2,1.08,1.76]],"ltp":2.22,"tv":10.0,"id":60971788}]}]}
{"op":"mcm","clk":"11957002506","pt":1724552687607,"mc":[{"id":"1.232224255","rc":[{"batb":[[0,1.72,5],[1,1.71,60.49],[2,1.21,24.75]],"ltp":1.75,"tv":110.16,"id":61422697},{"batb":[[0,2.24,5],[1,2.22,35.2],[2,1.21,24.75]],"ltp":2.22,"tv":10.0,"id":60971788}]}]}
{"op":"mcm","clk":"11957002768","pt":1724552690923,"mc":[{"id":"1.232224255","rc":[{"batb":[[0,1.71,60.49],[1,1.21,24.75],[2,1.08,1.76]],"ltp":1.75,"tv":110.16,"id":61422697},{"batb":[[0,2.22,35.2],[1,1.21,24.75],[2,1.08,1.76]],"ltp":2.22,"tv":10.0,"id":60971788}]}]}
{"op":"mcm","clk":"11957002980","pt":1724552693348,"mc":[{"id":"1.232224255","rc":[{"batb":[[0,1.72,5],[1,1.71,60.49],[2,1.21,24.75]],"ltp":1.75,"tv":110.16,"id":61422697},{"batb":[[0,2.24,5],[1,2.22,35.2],[2,1.21,24.75]],"ltp":2.22,"tv":10.0,"id":60971788}]}]}
{"op":"mcm","clk":"11957003229","pt":1724552696638,"mc":[{"id":"1.232224255","rc":[{"batb":[[0,1.71,60.49],[1,1.21,24.75],[2,1.08,1.76]],"ltp":1.75,"tv":110.16,"id":61422697},{"batb":[[0,2.22,35.2],[1,1.21,24.75],[2,1.08,1.76]],"ltp":2.22,"tv":10.0,"id":60971788}]}]}
{"op":"mcm","clk":"11957003440","pt":1724552699457,"mc":[{"id":"1.232224255","rc":[{"batb":[[0,1.72,5],[1,1.71,60.49],[2,1.21,24.75]],"ltp":1.75,"tv":110.16,"id":61422697},{"batb":[[0,2.24,5],[1,2.22,35.2],[2,1.21,24.75]],"ltp":2.22,"tv":10.0,"id":60971788}]}]}
{"op":"mcm","clk":"11957003756","pt":1724552702889,"mc":[{"id":"1.232224255","rc":[{"batb":[[0,1.71,60.49],[1,1.21,24.75],[2,1.08,1.76]],"ltp":1.75,"tv":110.16,"id":61422697},{"batb":[[0,2.22,35.2],[1,1.21,24.75],[2,1.08,1.76]],"ltp":2.22,"tv":10.0,"id":60971788}]}]}
{"op":"mcm","clk":"11957003935","pt":1724552705069,"mc":[{"id":"1.232224255","rc":[{"batb":[[0,1.72,5],[1,1.71,60.49],[2,1.21,24.75]],"ltp":1.75,"tv":110.16,"id":61422697},{"batb":[[0,2.24,5],[1,2.22,35.2],[2,1.21,24.75]],"ltp":2.22,"tv":10.0,"id":60971788}]}]}
{"op":"mcm","clk":"11957004217","pt":1724552708378,"mc":[{"id":"1.232224255","rc":[{"batb":[[0,1.71,60.49],[1,1.21,24.75],[2,1.08,1.76]],"ltp":1.75,"tv":110.16,"id":61422697},{"batb":[[0,2.22,35.2],[1,1.21,24.75],[2,1.08,1.76]],"ltp":2.22,"tv":10.0,"id":60971788}]}]}
{"op":"mcm","clk":"11957004447","pt":1724552711380,"mc":[{"id":"1.232224255","rc":[{"batb":[[0,1.72,5],[1,1.71,60.49],[2,1.21,24.75]],"ltp":1.75,"tv":110.16,"id":61422697},{"batb":[[0,2.24,5],[1,2.22,35.2],[2,1.21,24.75]],"ltp":2.22,"tv":10.0,"id":60971788}]}]}
{"op":"mcm","clk":"11957004715","pt":1724552714693,"mc":[{"id":"1.232224255","rc":[{"batb":[[0,1.71,60.49],[1,1.21,24.75],[2,1.08,1.76]],"ltp":1.75,"tv":110.16,"id":61422697},{"batb":[[0,2.22,35.2],[1,1.21,24.75],[2,1.08,1.76]],"ltp":2.22,"tv":10.0,"id":60971788}]}]}
{"op":"mcm","clk":"11957004891","pt":1724552716905,"mc":[{"id":"1.232224255","rc":[{"batb":[[0,1.72,5],[1,1.71,60.49],[2,1.21,24.75]],"ltp":1.75,"tv":110.16,"id":61422697},{"batb":[[0,2.24,5],[1,2.22,35.2],[2,1.21,24.75]],"ltp":2.22,"tv":10.0,"id":60971788}]}]}
{"op":"mcm","clk":"11957005169","pt":1724552720275,"mc":[{"id":"1.232224255","rc":[{"batb":[[0,1.71,60.49],[1,1.21,24.75],[2,1.08,1.76]],"ltp":1.75,"tv":110.16,"id":61422697},{"batb":[[0,2.22,35.2],[1,1.21,24.75],[2,1.08,1.76]],"ltp":2.22,"tv":10.0,"id":60971788}]}]}
{"op":"mcm","clk":"11957005621","pt":1724552725503,"mc":[{"id":"1.232224255","rc":[{"batb":[[0,1.72,5],[1,1.71,60.49],[2,1.21,24.75]],"ltp":1.75,"tv":110.16,"id":61422697},{"batb":[[0,2.24,5],[1,2.22,35.2],[2,1.21,24.75]],"ltp":2.22,"tv":10.0,"id":60971788}]}]}
{"op":"mcm","clk":"11957005881","pt":1724552728816,"mc":[{"id":"1.232224255","rc":[{"batb":[[0,1.71,60.49],[1,1.21,24.75],[2,1.08,1.76]],"ltp":1.75,"tv":110.16,"id":61422697},{"batb":[[0,2.22,35.2],[1,1.21,24.75],[2,1.08,1.76]],"ltp":2.22,"tv":10.0,"id":60971788}]}]}
{"op":"mcm","clk":"11957006104","pt":1724552731596,"mc":[{"id":"1.232224255","rc":[{"batb":[[0,1.72,5],[1,1.71,60.49],[2,1.21,24.75]],"ltp":1.75,"tv":110.16,"id":61422697},{"batb":[[0,2.24,5],[1,2.22,35.2],[2,1.21,24.75]],"ltp":2.22,"tv":10.0,"id":60971788}]}]}
{"op":"mcm","clk":"11957006347","pt":1724552734905,"mc":[{"id":"1.232224255","rc":[{"batb":[[0,1.71,60.49],[1,1.21,24.75],[2,1.08,1.76]],"ltp":1.75,"tv":110.16,"id":61422697},{"batb":[[0,2.22,35.2],[1,1.21,24.75],[2,1.08,1.76]],"ltp":2.22,"tv":10.0,"id":60971788}]}]}
{"op":"mcm","clk":"11957006486","pt":1724552737017,"mc":[{"id":"1.232224255","rc":[{"batb":[[0,1.72,5],[1,1.71,60.49],[2,1.21,24.75]],"ltp":1.75,"tv":110.16,"id":61422697},{"batb":[[0,2.24,5],[1,2.22,35.2],[2,1.21,24.75]],"ltp":2.22,"tv":10.0,"id":60971788}]}]}
{"op":"mcm","clk":"11957006787","pt":1724552740317,"mc":[{"id":"1.232224255","rc":[{"batb":[[0,1.71,60.49],[1,1.21,24.75],[2,1.08,1.76]],"ltp":1.75,"tv":110.16,"id":61422697},{"batb":[[0,2.22,35.2],[1,1.21,24.75],[2,1.08,1.76]],"ltp":2.22,"tv":10.0,"id":60971788}]}]}
{"op":"mcm","clk":"11957006921","pt":1724552741816,"mc":[{"id":"1.232224255","rc":[{"batb":[[2,1.07,1428.57]],"ltp":2.22,"tv":10.0,"id":60971788}]}]}
{"op":"mcm","clk":"11957007162","pt":1724552744816,"mc":[{"id":"1.232224255","rc":[{"batb":[[0,1.72,5],[1,1.71,60.49],[2,1.21,24.75]],"ltp":1.75,"tv":110.16,"id":61422697},{"batb":[[0,2.24,5],[1,2.22,35.2],[2,1.21,24.75]],"ltp":2.22,"tv":10.0,"id":60971788}]}]}
{"op":"mcm","clk":"11957007447","pt":1724552748238,"mc":[{"id":"1.232224255","rc":[{"batb":[[0,1.71,60.49],[1,1.21,24.75],[2,1.07,1428.57]],"ltp":1.75,"tv":110.16,"id":61422697},{"batb":[[0,2.22,35.2],[1,1.21,24.75],[2,1.07,1428.57]],"ltp":2.22,"tv":10.0,"id":60971788}]}]}
{"op":"mcm","clk":"11957007795","pt":1724552752112,"mc":[{"id":"1.232224255","rc":[{"batb":[[0,1.72,5],[1,1.71,60.49],[2,1.21,24.75]],"ltp":1.75,"tv":110.16,"id":61422697},{"batb":[[0,2.24,5],[1,2.22,35.2],[2,1.21,24.75]],"ltp":2.22,"tv":10.0,"id":60971788}]}]}
{"op":"mcm","clk":"11957008098","pt":1724552755417,"mc":[{"id":"1.232224255","rc":[{"batb":[[0,1.71,60.49],[1,1.21,24.75],[2,1.07,1428.57]],"ltp":1.75,"tv":110.16,"id":61422697},{"batb":[[0,2.22,35.2],[1,1.21,24.75],[2,1.07,1428.57]],"ltp":2.22,"tv":10.0,"id":60971788}]}]}
{"op":"mcm","clk":"11957008291","pt":1724552757630,"mc":[{"id":"1.232224255","rc":[{"batb":[[0,1.72,5],[1,1.71,60.49],[2,1.21,24.75]],"ltp":1.75,"tv":110.16,"id":61422697},{"batb":[[0,2.24,5],[1,2.22,35.2],[2,1.21,24.75]],"ltp":2.22,"tv":10.0,"id":60971788}]}]}
{"op":"mcm","clk":"11957008589","pt":1724552760941,"mc":[{"id":"1.232224255","rc":[{"batb":[[0,1.71,60.49],[1,1.21,24.75],[2,1.07,1428.57]],"ltp":1.75,"tv":110.16,"id":61422697},{"batb":[[0,2.22,35.2],[1,1.21,24.75],[2,1.07,1428.57]],"ltp":2.22,"tv":10.0,"id":60971788}]}]}
{"op":"mcm","clk":"11957009164","pt":1724552766747,"mc":[{"id":"1.232224255","rc":[{"batb":[[0,1.72,5],[1,1.71,60.49],[2,1.21,24.75]],"ltp":1.75,"tv":110.16,"id":61422697},{"batb":[[0,2.24,5],[1,2.22,35.2],[2,1.21,24.75]],"ltp":2.22,"tv":10.0,"id":60971788}]}]}
{"op":"mcm","clk":"11957009463","pt":1724552770054,"mc":[{"id":"1.232224255","rc":[{"batb":[[0,1.71,60.49],[1,1.21,24.75],[2,1.07,1428.57]],"ltp":1.75,"tv":110.16,"id":61422697},{"batb":[[0,2.22,35.2],[1,1.21,24.75],[2,1.07,1428.57]],"ltp":2.22,"tv":10.0,"id":60971788}]}]}
{"op":"mcm","clk":"11957009931","pt":1724552775165,"mc":[{"id":"1.232224255","rc":[{"batb":[[0,1.72,5],[1,1.71,60.49],[2,1.21,24.75]],"ltp":1.75,"tv":110.16,"id":61422697},{"batb":[[0,2.24,5],[1,2.22,35.2],[2,1.21,24.75]],"ltp":2.22,"tv":10.0,"id":60971788}]}]}
{"op":"mcm","clk":"11957010244","pt":1724552778561,"mc":[{"id":"1.232224255","rc":[{"batb":[[0,1.71,60.49],[1,1.21,24.75],[2,1.07,1428.57]],"ltp":1.75,"tv":110.16,"id":61422697},{"batb":[[0,2.22,35.2],[1,1.21,24.75],[2,1.07,1428.57]],"ltp":2.22,"tv":10.0,"id":60971788}]}]}
{"op":"mcm","clk":"11957010477","pt":1724552781285,"mc":[{"id":"1.232224255","rc":[{"batb":[[0,1.72,5],[1,1.71,60.49],[2,1.21,24.75]],"ltp":1.75,"tv":110.16,"id":61422697},{"batb":[[0,2.24,5],[1,2.22,35.2],[2,1.21,24.75]],"ltp":2.22,"tv":10.0,"id":60971788}]}]}
{"op":"mcm","clk":"11957010774","pt":1724552784583,"mc":[{"id":"1.232224255","rc":[{"batb":[[0,1.71,60.49],[1,1.21,24.75],[2,1.07,1428.57]],"ltp":1.75,"tv":110.16,"id":61422697},{"batb":[[0,2.22,35.2],[1,1.21,24.75],[2,1.07,1428.57]],"ltp":2.22,"tv":10.0,"id":60971788}]}]}
{"op":"mcm","clk":"11957010978","pt":1724552786996,"mc":[{"id":"1.232224255","rc":[{"batb":[[0,1.72,5],[1,1.71,60.49],[2,1.21,24.75]],"ltp":1.75,"tv":110.16,"id":61422697},{"batb":[[0,2.24,5],[1,2.22,35.2],[2,1.21,24.75]],"ltp":2.22,"tv":10.0,"id":60971788}]}]}
{"op":"mcm","clk":"11957011256","pt":1724552790292,"mc":[{"id":"1.232224255","rc":[{"batb":[[0,1.71,60.49],[1,1.21,24.75],[2,1.07,1428.57]],"ltp":1.75,"tv":110.16,"id":61422697},{"batb":[[0,2.22,35.2],[1,1.21,24.75],[2,1.07,1428.57]],"ltp":2.22,"tv":10.0,"id":60971788}]}]}
{"op":"mcm","clk":"11957011535","pt":1724552793181,"mc":[{"id":"1.232224255","rc":[{"batb":[[0,1.72,5],[1,1.71,60.49],[2,1.21,24.75]],"ltp":1.75,"tv":110.16,"id":61422697},{"batb":[[0,2.24,5],[1,2.22,35.2],[2,1.21,24.75]],"ltp":2.22,"tv":10.0,"id":60971788}]}]}
{"op":"mcm","clk":"11957011859","pt":1724552796590,"mc":[{"id":"1.232224255","rc":[{"batb":[[0,1.71,60.49],[1,1.21,24.75],[2,1.07,1428.57]],"ltp":1.75,"tv":110.16,"id":61422697},{"batb":[[0,2.22,35.2],[1,1.21,24.75],[2,1.07,1428.57]],"ltp":2.22,"tv":10.0,"id":60971788}]}]}
{"op":"mcm","clk":"11957012028","pt":1724552798801,"mc":[{"id":"1.232224255","rc":[{"batb":[[0,1.72,5],[1,1.71,60.49],[2,1.21,24.75]],"ltp":1.75,"tv":110.16,"id":61422697},{"batb":[[0,2.24,5],[1,2.22,35.2],[2,1.21,24.75]],"ltp":2.22,"tv":10.0,"id":60971788}]}]}
{"op":"mcm","clk":"11957012329","pt":1724552802000,"mc":[{"id":"1.232224255","rc":[{"batb":[[0,1.71,60.49],[1,1.21,24.75],[2,1.07,1428.57]],"ltp":1.75,"tv":110.16,"id":61422697},{"batb":[[0,2.22,35.2],[1,1.21,24.75],[2,1.07,1428.57]],"ltp":2.22,"tv":10.0,"id":60971788}]}]}
{"op":"mcm","clk":"11957012522","pt":1724552804213,"mc":[{"id":"1.232224255","rc":[{"batb":[[0,1.72,5],[1,1.71,60.49],[2,1.21,24.75]],"ltp":1.75,"tv":110.16,"id":61422697},{"batb":[[0,2.24,5],[1,2.22,35.2],[2,1.21,24.75]],"ltp":2.22,"tv":10.0,"id":60971788}]}]}
{"op":"mcm","clk":"11957012803","pt":1724552807518,"mc":[{"id":"1.232224255","rc":[{"batb":[[0,1.71,60.49],[1,1.21,24.75],[2,1.07,1428.57]],"ltp":1.75,"tv":110.16,"id":61422697},{"batb":[[0,2.22,35.2],[1,1.21,24.75],[2,1.07,1428.57]],"ltp":2.22,"tv":10.0,"id":60971788}]}]}
{"op":"mcm","clk":"11957012989","pt":1724552809680,"mc":[{"id":"1.232224255","rc":[{"batb":[[0,1.72,5],[1,1.71,60.49],[2,1.21,24.75]],"ltp":1.75,"tv":110.16,"id":61422697},{"batb":[[0,2.24,5],[1,2.22,35.2],[2,1.21,24.75]],"ltp":2.22,"tv":10.0,"id":60971788}]}]}
{"op":"mcm","clk":"11957013254","pt":1724552813002,"mc":[{"id":"1.232224255","rc":[{"batb":[[0,1.71,60.49],[1,1.21,24.75],[2,1.07,1428.57]],"ltp":1.75,"tv":110.16,"id":61422697},{"batb":[[0,2.22,35.2],[1,1.21,24.75],[2,1.07,1428.57]],"ltp":2.22,"tv":10.0,"id":60971788}]}]}
{"op":"mcm","clk":"11957013452","pt":1724552815219,"mc":[{"id":"1.232224255","rc":[{"batb":[[0,1.72,5],[1,1.71,60.49],[2,1.21,24.75]],"ltp":1.75,"tv":110.16,"id":61422697},{"batb":[[0,2.24,5],[1,2.22,35.2],[2,1.21,24.75]],"ltp":2.22,"tv":10.0,"id":60971788}]}]}
{"op":"mcm","clk":"11957013745","pt":1724552818484,"mc":[{"id":"1.232224255","rc":[{"batb":[[0,1.71,60.49],[1,1.21,24.75],[2,1.07,1428.57]],"ltp":1.75,"tv":110.16,"id":61422697},{"batb":[[0,2.22,35.2],[1,1.21,24.75],[2,1.07,1428.57]],"ltp":2.22,"tv":10.0,"id":60971788}]}]}
{"op":"mcm","clk":"11957014043","pt":1724552821397,"mc":[{"id":"1.232224255","rc":[{"batb":[[0,1.72,5],[1,1.71,60.49],[2,1.21,24.75]],"ltp":1.75,"tv":110.16,"id":61422697},{"batb":[[0,2.24,5],[1,2.22,35.2],[2,1.21,24.75]],"ltp":2.22,"tv":10.0,"id":60971788}]}]}
{"op":"mcm","clk":"11957014305","pt":1724552824703,"mc":[{"id":"1.232224255","rc":[{"batb":[[0,1.71,60.49],[1,1.21,24.75],[2,1.07,1428.57]],"ltp":1.75,"tv":110.16,"id":61422697},{"batb":[[0,2.22,35.2],[1,1.21,24.75],[2,1.07,1428.57]],"ltp":2.22,"tv":10.0,"id":60971788}]}]}
{"op":"mcm","clk":"11957014482","pt":1724552827127,"mc":[{"id":"1.232224255","rc":[{"batb":[[0,1.72,5],[1,1.71,60.49],[2,1.21,24.75]],"ltp":1.75,"tv":110.16,"id":61422697},{"batb":[[0,2.24,5],[1,2.22,35.2],[2,1.21,24.75]],"ltp":2.22,"tv":10.0,"id":60971788}]}]}
{"op":"mcm","clk":"11957014723","pt":1724552830429,"mc":[{"id":"1.232224255","rc":[{"batb":[[0,1.71,60.49],[1,1.21,24.75],[2,1.07,1428.57]],"ltp":1.75,"tv":110.16,"id":61422697},{"batb":[[0,2.22,35.2],[1,1.21,24.75],[2,1.07,1428.57]],"ltp":2.22,"tv":10.0,"id":60971788}]}]}
{"op":"mcm","clk":"11957014948","pt":1724552833214,"mc":[{"id":"1.232224255","rc":[{"batb":[[0,1.72,5],[1,1.71,60.49],[2,1.21,24.75]],"ltp":1.75,"tv":110.16,"id":61422697},{"batb":[[0,2.24,5],[1,2.22,35.2],[2,1.21,24.75]],"ltp":2.22,"tv":10.0,"id":60971788}]}]}
{"op":"mcm","clk":"11957015254","pt":1724552836614,"mc":[{"id":"1.232224255","rc":[{"batb":[[0,1.71,60.49],[1,1.21,24.75],[2,1.07,1428.57]],"ltp":1.75,"tv":110.16,"id":61422697},{"batb":[[0,2.22,35.2],[1,1.21,24.75],[2,1.07,1428.57]],"ltp":2.22,"tv":10.0,"id":60971788}]}]}
{"op":"mcm","clk":"11957015432","pt":1724552838835,"mc":[{"id":"1.232224255","rc":[{"batb":[[0,1.72,5],[1,1.71,60.49],[2,1.21,24.75]],"ltp":1.75,"tv":110.16,"id":61422697},{"batb":[[0,2.24,5],[1,2.22,35.2],[2,1.21,24.75]],"ltp":2.22,"tv":10.0,"id":60971788}]}]}
{"op":"mcm","clk":"11957015701","pt":1724552842142,"mc":[{"id":"1.232224255","rc":[{"batb":[[0,1.71,60.49],[1,1.21,24.75],[2,1.07,1428.57]],"ltp":1.75,"tv":110.16,"id":61422697},{"batb":[[0,2.22,35.2],[1,1.21,24.75],[2,1.07,1428.57]],"ltp":2.22,"tv":10.0,"id":60971788}]}]}
{"op":"mcm","clk":"11957015932","pt":1724552845131,"mc":[{"id":"1.232224255","rc":[{"batb":[[0,1.72,5],[1,1.71,60.49],[2,1.21,24.75]],"ltp":1.75,"tv":110.16,"id":61422697},{"batb":[[0,2.24,5],[1,2.22,35.2],[2,1.21,24.75]],"ltp":2.22,"tv":10.0,"id":60971788}]}]}
{"op":"mcm","clk":"11957016217","pt":1724552848430,"mc":[{"id":"1.232224255","rc":[{"batb":[[0,1.71,60.49],[1,1.21,24.75],[2,1.07,1428.57]],"ltp":1.75,"tv":110.16,"id":61422697},{"batb":[[0,2.22,35.2],[1,1.21,24.75],[2,1.07,1428.57]],"ltp":2.22,"tv":10.0,"id":60971788}]}]}
{"op":"mcm","clk":"11957016542","pt":1724552852246,"mc":[{"id":"1.232224255","rc":[{"batb":[[0,1.72,5],[1,1.71,60.49],[2,1.21,24.75]],"ltp":1.75,"tv":110.16,"id":61422697},{"batb":[[0,2.24,5],[1,2.22,35.2],[2,1.21,24.75]],"ltp":2.22,"tv":10.0,"id":60971788}]}]}
{"op":"mcm","clk":"11957016843","pt":1724552855539,"mc":[{"id":"1.232224255","rc":[{"batb":[[0,1.71,60.49],[1,1.21,24.75],[2,1.07,1428.57]],"ltp":1.75,"tv":110.16,"id":61422697},{"batb":[[0,2.22,35.2],[1,1.21,24.75],[2,1.07,1428.57]],"ltp":2.22,"tv":10.0,"id":60971788}]}]}
{"op":"mcm","clk":"11957017023","pt":1724552857751,"mc":[{"id":"1.232224255","rc":[{"batb":[[0,1.72,5],[1,1.71,60.49],[2,1.21,24.75]],"ltp":1.75,"tv":110.16,"id":61422697},{"batb":[[0,2.24,5],[1,2.22,35.2],[2,1.21,24.75]],"ltp":2.22,"tv":10.0,"id":60971788}]}]}
{"op":"mcm","clk":"11957017304","pt":1724552861052,"mc":[{"id":"1.232224255","rc":[{"batb":[[0,1.71,60.49],[1,1.21,24.75],[2,1.07,1428.57]],"ltp":1.75,"tv":110.16,"id":61422697},{"batb":[[0,2.22,35.2],[1,1.21,24.75],[2,1.07,1428.57]],"ltp":2.22,"tv":10.0,"id":60971788}]}]}
{"op":"mcm","clk":"11957017515","pt":1724552863477,"mc":[{"id":"1.232224255","rc":[{"batb":[[0,1.72,5],[1,1.71,60.49],[2,1.21,24.75]],"ltp":1.75,"tv":110.16,"id":61422697},{"batb":[[0,2.24,5],[1,2.22,35.2],[2,1.21,24.75]],"ltp":2.22,"tv":10.0,"id":60971788}]}]}
{"op":"mcm","clk":"11957017800","pt":1724552866677,"mc":[{"id":"1.232224255","rc":[{"batb":[[0,1.71,60.49],[1,1.21,24.75],[2,1.07,1428.57]],"ltp":1.75,"tv":110.16,"id":61422697},{"batb":[[0,2.22,35.2],[1,1.21,24.75],[2,1.07,1428.57]],"ltp":2.22,"tv":10.0,"id":60971788}]}]}
{"op":"mcm","clk":"11957017978","pt":1724552868996,"mc":[{"id":"1.232224255","rc":[{"batb":[[0,1.72,5],[1,1.71,60.49],[2,1.21,24.75]],"ltp":1.75,"tv":110.16,"id":61422697},{"batb":[[0,2.24,5],[1,2.22,35.2],[2,1.21,24.75]],"ltp":2.22,"tv":10.0,"id":60971788}]}]}
{"op":"mcm","clk":"11957018259","pt":1724552872205,"mc":[{"id":"1.232224255","rc":[{"batb":[[0,1.71,60.49],[1,1.21,24.75],[2,1.07,1428.57]],"ltp":1.75,"tv":110.16,"id":61422697},{"batb":[[0,2.22,35.2],[1,1.21,24.75],[2,1.07,1428.57]],"ltp":2.22,"tv":10.0,"id":60971788}]}]}
{"op":"mcm","clk":"11957018453","pt":1724552874976,"mc":[{"id":"1.232224255","rc":[{"batb":[[0,1.72,5],[1,1.71,60.49],[2,1.21,24.75]],"ltp":1.75,"tv":110.16,"id":61422697},{"batb":[[0,2.24,5],[1,2.22,35.2],[2,1.21,24.75]],"ltp":2.22,"tv":10.0,"id":60971788}]}]}
{"op":"mcm","clk":"11957018705","pt":1724552878317,"mc":[{"id":"1.232224255","rc":[{"batb":[[0,1.71,60.49],[1,1.21,24.75],[2,1.07,1428.57]],"ltp":1.75,"tv":110.16,"id":61422697},{"batb":[[0,2.22,35.2],[1,1.21,24.75],[2,1.07,1428.57]],"ltp":2.22,"tv":10.0,"id":60971788}]}]}
{"op":"mcm","clk":"11957018915","pt":1724552880692,"mc":[{"id":"1.232224255","rc":[{"batb":[[0,1.72,5],[1,1.71,60.49],[2,1.21,24.75]],"ltp":1.75,"tv":110.16,"id":61422697},{"batb":[[0,2.24,5],[1,2.22,35.2],[2,1.21,24.75]],"ltp":2.22,"tv":10.0,"id":60971788}]}]}
{"op":"mcm","clk":"11957019272","pt":1724552884409,"mc":[{"id":"1.232224255","rc":[{"batb":[[0,1.71,60.49],[1,1.21,24.75],[2,1.07,1428.57]],"ltp":1.75,"tv":110.16,"id":61422697},{"batb":[[0,2.22,35.2],[1,1.21,24.75],[2,1.07,1428.57]],"ltp":2.22,"tv":10.0,"id":60971788}]}]}
{"op":"mcm","clk":"11957019605","pt":1724552888222,"mc":[{"id":"1.232224255","rc":[{"batb":[[0,1.72,5],[1,1.71,60.49],[2,1.21,24.75]],"ltp":1.75,"tv":110.16,"id":61422697},{"batb":[[0,2.24,5],[1,2.22,35.2],[2,1.21,24.75]],"ltp":2.22,"tv":10.0,"id":60971788}]}]}
{"op":"mcm","clk":"11957019915","pt":1724552891830,"mc":[{"id":"1.232224255","rc":[{"batb":[[0,1.71,60.49],[1,1.21,24.75],[2,1.07,1428.57]],"ltp":1.75,"tv":110.16,"id":61422697},{"batb":[[0,2.22,35.2],[1,1.21,24.75],[2,1.07,1428.57]],"ltp":2.22,"tv":10.0,"id":60971788}]}]}
{"op":"mcm","clk":"11957020244","pt":1724552895605,"mc":[{"id":"1.232224255","rc":[{"batb":[[0,1.72,5],[1,1.71,60.49],[2,1.21,24.75]],"ltp":1.75,"tv":110.16,"id":61422697},{"batb":[[0,2.24,5],[1,2.22,35.2],[2,1.21,24.75]],"ltp":2.22,"tv":10.0,"id":60971788}]}]}
{"op":"mcm","clk":"11957020560","pt":1724552898910,"mc":[{"id":"1.232224255","rc":[{"batb":[[0,1.71,60.49],[1,1.21,24.75],[2,1.07,1428.57]],"ltp":1.75,"tv":110.16,"id":61422697},{"batb":[[0,2.22,35.2],[1,1.21,24.75],[2,1.07,1428.57]],"ltp":2.22,"tv":10.0,"id":60971788}]}]}
{"op":"mcm","clk":"11957020736","pt":1724552901122,"mc":[{"id":"1.232224255","rc":[{"batb":[[0,1.72,5],[1,1.71,60.49],[2,1.21,24.75]],"ltp":1.75,"tv":110.16,"id":61422697},{"batb":[[0,2.24,5],[1,2.22,35.2],[2,1.21,24.75]],"ltp":2.22,"tv":10.0,"id":60971788}]}]}
{"op":"mcm","clk":"11957021033","pt":1724552904422,"mc":[{"id":"1.232224255","rc":[{"batb":[[0,1.71,60.49],[1,1.21,24.75],[2,1.07,1428.57]],"ltp":1.75,"tv":110.16,"id":61422697},{"batb":[[0,2.22,35.2],[1,1.21,24.75],[2,1.07,1428.57]],"ltp":2.22,"tv":10.0,"id":60971788}]}]}
{"op":"mcm","clk":"11957021241","pt":1724552906642,"mc":[{"id":"1.232224255","rc":[{"batb":[[0,1.72,5],[1,1.71,60.49],[2,1.21,24.75]],"ltp":1.75,"tv":110.16,"id":61422697},{"batb":[[0,2.24,5],[1,2.22,35.2],[2,1.21,24.75]],"ltp":2.22,"tv":10.0,"id":60971788}]}]}
{"op":"mcm","clk":"11957021535","pt":1724552909862,"mc":[{"id":"1.232224255","rc":[{"batb":[[0,1.71,60.49],[1,1.21,24.75],[2,1.07,1428.57]],"ltp":1.75,"tv":110.16,"id":61422697},{"batb":[[0,2.22,35.2],[1,1.21,24.75],[2,1.07,1428.57]],"ltp":2.22,"tv":10.0,"id":60971788}]}]}
{"op":"mcm","clk":"11957021753","pt":1724552912130,"mc":[{"id":"1.232224255","rc":[{"batb":[[0,1.72,5],[1,1.71,60.49],[2,1.21,24.75]],"ltp":1.75,"tv":110.16,"id":61422697},{"batb":[[0,2.24,5],[1,2.22,35.2],[2,1.21,24.75]],"ltp":2.22,"tv":10.0,"id":60971788}]}]}
{"op":"mcm","clk":"11957022051","pt":1724552915445,"mc":[{"id":"1.232224255","rc":[{"batb":[[0,1.71,60.49],[1,1.21,24.75],[2,1.07,1428.57]],"ltp":1.75,"tv":110.16,"id":61422697},{"batb":[[0,2.22,35.2],[1,1.21,24.75],[2,1.07,1428.57]],"ltp":2.22,"tv":10.0,"id":60971788}]}]}
{"op":"mcm","clk":"11957022297","pt":1724552918345,"mc":[{"id":"1.232224255","rc":[{"batb":[[0,1.72,5],[1,1.71,60.49],[2,1.21,24.75]],"ltp":1.75,"tv":110.16,"id":61422697},{"batb":[[0,2.24,5],[1,2.22,35.2],[2,1.21,24.75]],"ltp":2.22,"tv":10.0,"id":60971788}]}]}
{"op":"mcm","clk":"11957022606","pt":1724552921944,"mc":[{"id":"1.232224255","rc":[{"batb":[[0,1.71,60.49],[1,1.21,24.75],[2,1.07,1428.57]],"ltp":1.75,"tv":110.16,"id":61422697},{"batb":[[0,2.22,35.2],[1,1.21,24.75],[2,1.07,1428.57]],"ltp":2.22,"tv":10.0,"id":60971788}]}]}
{"op":"mcm","clk":"11957022950","pt":1724552926072,"mc":[{"id":"1.232224255","rc":[{"batb":[[0,1.72,5],[1,1.71,60.49],[2,1.21,24.75]],"ltp":1.75,"tv":110.16,"id":61422697},{"batb":[[0,2.24,5],[1,2.22,35.2],[2,1.21,24.75]],"ltp":2.22,"tv":10.0,"id":60971788}]}]}
{"op":"mcm","clk":"11957023265","pt":1724552929461,"mc":[{"id":"1.232224255","rc":[{"batb":[[0,1.71,60.49],[1,1.21,24.75],[2,1.07,1428.57]],"ltp":1.75,"tv":110.16,"id":61422697},{"batb":[[0,2.22,35.2],[1,1.21,24.75],[2,1.07,1428.57]],"ltp":2.22,"tv":10.0,"id":60971788}]}]}
{"op":"mcm","clk":"11957023554","pt":1724552932685,"mc":[{"id":"1.232224255","rc":[{"batb":[[0,1.72,5],[1,1.71,60.49],[2,1.21,24.75]],"ltp":1.75,"tv":110.16,"id":61422697},{"batb":[[0,2.24,5],[1,2.22,35.2],[2,1.21,24.75]],"ltp":2.22,"tv":10.0,"id":60971788}]}]}
{"op":"mcm","clk":"11957023849","pt":1724552935979,"mc":[{"id":"1.232224255","rc":[{"batb":[[0,1.71,60.49],[1,1.21,24.75],[2,1.07,1428.57]],"ltp":1.75,"tv":110.16,"id":61422697},{"batb":[[0,2.22,35.2],[1,1.21,24.75],[2,1.07,1428.57]],"ltp":2.22,"tv":10.0,"id":60971788}]}]}
{"op":"mcm","clk":"11957024095","pt":1724552938964,"mc":[{"id":"1.232224255","rc":[{"batb":[[0,1.72,5],[1,1.71,60.49],[2,1.21,24.75]],"ltp":1.75,"tv":110.16,"id":61422697},{"batb":[[0,2.24,5],[1,2.22,35.2],[2,1.21,24.75]],"ltp":2.22,"tv":10.0,"id":60971788}]}]}
{"op":"mcm","clk":"11957024379","pt":1724552942170,"mc":[{"id":"1.232224255","rc":[{"batb":[[0,1.71,60.49],[1,1.21,24.75],[2,1.07,1428.57]],"ltp":1.75,"tv":110.16,"id":61422697},{"batb":[[0,2.22,35.2],[1,1.21,24.75],[2,1.07,1428.57]],"ltp":2.22,"tv":10.0,"id":60971788}]}]}
{"op":"mcm","clk":"11957024621","pt":1724552944774,"mc":[{"id":"1.232224255","rc":[{"batb":[[0,1.72,5],[1,1.71,60.49],[2,1.21,24.75]],"ltp":1.75,"tv":110.16,"id":61422697},{"batb":[[0,2.24,5],[1,2.22,35.2],[2,1.21,24.75]],"ltp":2.22,"tv":10.0,"id":60971788}]}]}
{"op":"mcm","clk":"11957024958","pt":1724552948076,"mc":[{"id":"1.232224255","rc":[{"batb":[[0,1.71,60.49],[1,1.21,24.75],[2,1.07,1428.57]],"ltp":1.75,"tv":110.16,"id":61422697},{"batb":[[0,2.22,35.2],[1,1.21,24.75],[2,1.07,1428.57]],"ltp":2.22,"tv":10.0,"id":60971788}]}]}
{"op":"mcm","clk":"11957025182","pt":1724552950292,"mc":[{"id":"1.232224255","rc":[{"batb":[[0,1.72,5],[1,1.71,60.49],[2,1.21,24.75]],"ltp":1.75,"tv":110.16,"id":61422697},{"batb":[[0,2.24,5],[1,2.22,35.2],[2,1.21,24.75]],"ltp":2.22,"tv":10.0,"id":60971788}]}]}
{"op":"mcm","clk":"11957025515","pt":1724552953709,"mc":[{"id":"1.232224255","rc":[{"batb":[[0,1.71,60.49],[1,1.21,24.75],[2,1.07,1428.57]],"ltp":1.75,"tv":110.16,"id":61422697},{"batb":[[0,2.22,35.2],[1,1.21,24.75],[2,1.07,1428.57]],"ltp":2.22,"tv":10.0,"id":60971788}]}]}
{"op":"mcm","clk":"11957025807","pt":1724552957424,"mc":[{"id":"1.232224255","rc":[{"batb":[[0,1.72,5],[1,1.71,60.49],[2,1.21,24.75]],"ltp":1.75,"tv":110.16,"id":61422697},{"batb":[[0,2.24,5],[1,2.22,35.2],[2,1.21,24.75]],"ltp":2.22,"tv":10.0,"id":60971788}]}]}
{"op":"mcm","clk":"11957026060","pt":1724552960719,"mc":[{"id":"1.232224255","rc":[{"batb":[[0,1.71,60.49],[1,1.21,24.75],[2,1.07,1428.57]],"ltp":1.75,"tv":110.16,"id":61422697},{"batb":[[0,2.22,35.2],[1,1.21,24.75],[2,1.07,1428.57]],"ltp":2.22,"tv":10.0,"id":60971788}]}]}
{"op":"mcm","clk":"11957026254","pt":1724552962932,"mc":[{"id":"1.232224255","rc":[{"batb":[[0,1.72,5],[1,1.71,60.49],[2,1.21,24.75]],"ltp":1.75,"tv":110.16,"id":61422697},{"batb":[[0,2.24,5],[1,2.22,35.2],[2,1.21,24.75]],"ltp":2.22,"tv":10.0,"id":60971788}]}]}
{"op":"mcm","clk":"11957026572","pt":1724552966239,"mc":[{"id":"1.232224255","rc":[{"batb":[[0,1.71,60.49],[1,1.21,24.75],[2,1.07,1428.57]],"ltp":1.75,"tv":110.16,"id":61422697},{"batb":[[0,2.22,35.2],[1,1.21,24.75],[2,1.07,1428.57]],"ltp":2.22,"tv":10.0,"id":60971788}]}]}
{"op":"mcm","clk":"11957026763","pt":1724552968615,"mc":[{"id":"1.232224255","rc":[{"batb":[[0,1.72,5],[1,1.71,60.49],[2,1.21,24.75]],"ltp":1.75,"tv":110.16,"id":61422697},{"batb":[[0,2.24,5],[1,2.22,35.2],[2,1.21,24.75]],"ltp":2.22,"tv":10.0,"id":60971788}]}]}
{"op":"mcm","clk":"11957027085","pt":1724552972017,"mc":[{"id":"1.232224255","rc":[{"batb":[[0,1.71,60.49],[1,1.21,24.75],[2,1.07,1428.57]],"ltp":1.75,"tv":110.16,"id":61422697},{"batb":[[0,2.22,35.2],[1,1.21,24.75],[2,1.07,1428.57]],"ltp":2.22,"tv":10.0,"id":60971788}]}]}
{"op":"mcm","clk":"11957027321","pt":1724552975120,"mc":[{"id":"1.232224255","rc":[{"batb":[[0,1.72,5],[1,1.71,60.49],[2,1.21,24.75]],"ltp":1.75,"tv":110.16,"id":61422697},{"batb":[[0,2.24,5],[1,2.22,35.2],[2,1.21,24.75]],"ltp":2.22,"tv":10.0,"id":60971788}]}]}
{"op":"mcm","clk":"11957027607","pt":1724552978516,"mc":[{"id":"1.232224255","rc":[{"batb":[[0,1.71,60.49],[1,1.21,24.75],[2,1.07,1428.57]],"ltp":1.75,"tv":110.16,"id":61422697},{"batb":[[0,2.22,35.2],[1,1.21,24.75],[2,1.07,1428.57]],"ltp":2.22,"tv":10.0,"id":60971788}]}]}
{"op":"mcm","clk":"11957027808","pt":1724552980941,"mc":[{"id":"1.232224255","rc":[{"batb":[[0,1.72,5],[1,1.71,60.49],[2,1.21,24.75]],"ltp":1.75,"tv":110.16,"id":61422697},{"batb":[[0,2.24,5],[1,2.22,35.2],[2,1.21,24.75]],"ltp":2.22,"tv":10.0,"id":60971788}]}]}
{"op":"mcm","clk":"11957028098","pt":1724552984356,"mc":[{"id":"1.232224255","rc":[{"batb":[[0,1.71,60.49],[1,1.21,24.75],[2,1.07,1428.57]],"ltp":1.75,"tv":110.16,"id":61422697},{"batb":[[0,2.22,35.2],[1,1.21,24.75],[2,1.07,1428.57]],"ltp":2.22,"tv":10.0,"id":60971788}]}]}
{"op":"mcm","clk":"11957028310","pt":1724552987551,"mc":[{"id":"1.232224255","rc":[{"batb":[[0,1.72,5],[1,1.71,60.49],[2,1.21,24.75]],"ltp":1.75,"tv":110.16,"id":61422697},{"batb":[[0,2.24,5],[1,2.22,35.2],[2,1.21,24.75]],"ltp":2.22,"tv":10.0,"id":60971788}]}]}
{"op":"mcm","clk":"11957028515","pt":1724552991045,"mc":[{"id":"1.232224255","rc":[{"batb":[[0,1.71,60.49],[1,1.21,24.75],[2,1.07,1428.57]],"ltp":1.75,"tv":110.16,"id":61422697},{"batb":[[0,2.22,35.2],[1,1.21,24.75],[2,1.07,1428.57]],"ltp":2.22,"tv":10.0,"id":60971788}]}]}
{"op":"mcm","clk":"11957028683","pt":1724552993257,"mc":[{"id":"1.232224255","rc":[{"batb":[[0,1.72,5],[1,1.71,60.49],[2,1.21,24.75]],"ltp":1.75,"tv":110.16,"id":61422697},{"batb":[[0,2.24,5],[1,2.22,35.2],[2,1.21,24.75]],"ltp":2.22,"tv":10.0,"id":60971788}]}]}
{"op":"mcm","clk":"11957028907","pt":1724552996550,"mc":[{"id":"1.232224255","rc":[{"batb":[[0,1.71,60.49],[1,1.21,24.75],[2,1.07,1428.57]],"ltp":1.75,"tv":110.16,"id":61422697},{"batb":[[0,2.22,35.2],[1,1.21,24.75],[2,1.07,1428.57]],"ltp":2.22,"tv":10.0,"id":60971788}]}]}
{"op":"mcm","clk":"11957029097","pt":1724552999075,"mc":[{"id":"1.232224255","rc":[{"batb":[[0,1.72,5],[1,1.71,60.49],[2,1.21,24.75]],"ltp":1.75,"tv":110.16,"id":61422697},{"batb":[[0,2.24,5],[1,2.22,35.2],[2,1.21,24.75]],"ltp":2.22,"tv":10.0,"id":60971788}]}]}
{"op":"mcm","clk":"11957029386","pt":1724553002255,"mc":[{"id":"1.232224255","rc":[{"batb":[[0,1.71,60.49],[1,1.21,24.75],[2,1.07,1428.57]],"ltp":1.75,"tv":110.16,"id":61422697},{"batb":[[0,2.22,35.2],[1,1.21,24.75],[2,1.07,1428.57]],"ltp":2.22,"tv":10.0,"id":60971788}]}]}
{"op":"mcm","clk":"11957029774","pt":1724553006056,"mc":[{"id":"1.232224255","rc":[{"batb":[[0,1.72,5],[1,1.71,60.49],[2,1.21,24.75]],"ltp":1.75,"tv":110.16,"id":61422697},{"batb":[[0,2.24,5],[1,2.22,35.2],[2,1.21,24.75]],"ltp":2.22,"tv":10.0,"id":60971788}]}]}
{"op":"mcm","clk":"11957030047","pt":1724553009479,"mc":[{"id":"1.232224255","rc":[{"batb":[[0,1.71,60.49],[1,1.21,24.75],[2,1.07,1428.57]],"ltp":1.75,"tv":110.16,"id":61422697},{"batb":[[0,2.22,35.2],[1,1.21,24.75],[2,1.07,1428.57]],"ltp":2.22,"tv":10.0,"id":60971788}]}]}
{"op":"mcm","clk":"11957030243","pt":1724553011662,"mc":[{"id":"1.232224255","rc":[{"batb":[[0,1.72,5],[1,1.71,60.49],[2,1.21,24.75]],"ltp":1.75,"tv":110.16,"id":61422697},{"batb":[[0,2.24,5],[1,2.22,35.2],[2,1.21,24.75]],"ltp":2.22,"tv":10.0,"id":60971788}]}]}
{"op":"mcm","clk":"11957030464","pt":1724553014985,"mc":[{"id":"1.232224255","rc":[{"batb":[[0,1.71,60.49],[1,1.21,24.75],[2,1.07,1428.57]],"ltp":1.75,"tv":110.16,"id":61422697},{"batb":[[0,2.22,35.2],[1,1.21,24.75],[2,1.07,1428.57]],"ltp":2.22,"tv":10.0,"id":60971788}]}]}
{"op":"mcm","clk":"11957030723","pt":1724553017881,"mc":[{"id":"1.232224255","rc":[{"batb":[[0,1.72,5],[1,1.71,60.49],[2,1.21,24.75]],"ltp":1.75,"tv":110.16,"id":61422697},{"batb":[[0,2.24,5],[1,2.22,35.2],[2,1.21,24.75]],"ltp":2.22,"tv":10.0,"id":60971788}]}]}
{"op":"mcm","clk":"11957031062","pt":1724553021402,"mc":[{"id":"1.232224255","rc":[{"batb":[[0,1.71,60.49],[1,1.21,24.75],[2,1.07,1428.57]],"ltp":1.75,"tv":110.16,"id":61422697},{"batb":[[0,2.22,35.2],[1,1.21,24.75],[2,1.07,1428.57]],"ltp":2.22,"tv":10.0,"id":60971788}]}]}
{"op":"mcm","clk":"11957031268","pt":1724553023627,"mc":[{"id":"1.232224255","rc":[{"batb":[[0,1.72,5],[1,1.71,60.49],[2,1.21,24.75]],"ltp":1.75,"tv":110.16,"id":61422697},{"batb":[[0,2.24,5],[1,2.22,35.2],[2,1.21,24.75]],"ltp":2.22,"tv":10.0,"id":60971788}]}]}
{"op":"mcm","clk":"11957031479","pt":1724553026820,"mc":[{"id":"1.232224255","rc":[{"batb":[[0,1.71,60.49],[1,1.21,24.75],[2,1.07,1428.57]],"ltp":1.75,"tv":110.16,"id":61422697},{"batb":[[0,2.22,35.2],[1,1.21,24.75],[2,1.07,1428.57]],"ltp":2.22,"tv":10.0,"id":60971788}]}]}
{"op":"mcm","clk":"11957031675","pt":1724553029611,"mc":[{"id":"1.232224255","rc":[{"batb":[[0,1.72,5],[1,1.71,60.49],[2,1.21,24.75]],"ltp":1.75,"tv":110.16,"id":61422697},{"batb":[[0,2.24,5],[1,2.22,35.2],[2,1.21,24.75]],"ltp":2.22,"tv":10.0,"id":60971788}]}]}
{"op":"mcm","clk":"11957031884","pt":1724553032919,"mc":[{"id":"1.232224255","rc":[{"batb":[[0,1.71,60.49],[1,1.21,24.75],[2,1.07,1428.57]],"ltp":1.75,"tv":110.16,"id":61422697},{"batb":[[0,2.22,35.2],[1,1.21,24.75],[2,1.07,1428.57]],"ltp":2.22,"tv":10.0,"id":60971788}]}]}
{"op":"mcm","clk":"11957032116","pt":1724553036011,"mc":[{"id":"1.232224255","rc":[{"batb":[[0,1.72,5],[1,1.71,60.49],[2,1.21,24.75]],"ltp":1.75,"tv":110.16,"id":61422697},{"batb":[[0,2.24,5],[1,2.22,35.2],[2,1.21,24.75]],"ltp":2.22,"tv":10.0,"id":60971788}]}]}
{"op":"mcm","clk":"11957032350","pt":1724553039532,"mc":[{"id":"1.232224255","rc":[{"batb":[[0,1.71,60.49],[1,1.21,24.75],[2,1.07,1428.57]],"ltp":1.75,"tv":110.16,"id":61422697},{"batb":[[0,2.22,35.2],[1,1.21,24.75],[2,1.07,1428.57]],"ltp":2.22,"tv":10.0,"id":60971788}]}]}
{"op":"mcm","clk":"11957032478","pt":1724553041804,"mc":[{"id":"1.232224255","rc":[{"batb":[[0,1.72,5],[1,1.71,60.49],[2,1.21,24.75]],"ltp":1.75,"tv":110.16,"id":61422697},{"batb":[[0,2.24,5],[1,2.22,35.2],[2,1.21,24.75]],"ltp":2.22,"tv":10.0,"id":60971788}]}]}
{"op":"mcm","clk":"11957032764","pt":1724553045229,"mc":[{"id":"1.232224255","rc":[{"batb":[[0,1.71,60.49],[1,1.21,24.75],[2,1.07,1428.57]],"ltp":1.75,"tv":110.16,"id":61422697},{"batb":[[0,2.22,35.2],[1,1.21,24.75],[2,1.07,1428.57]],"ltp":2.22,"tv":10.0,"id":60971788}]}]}
{"op":"mcm","clk":"11957033098","pt":1724553049758,"mc":[{"id":"1.232224255","rc":[{"batb":[[0,1.72,5],[1,1.71,60.49],[2,1.21,24.75]],"ltp":1.75,"tv":110.16,"id":61422697},{"batb":[[0,2.24,5],[1,2.22,35.2],[2,1.21,24.75]],"ltp":2.22,"tv":10.0,"id":60971788}]}]}
{"op":"mcm","clk":"11957033320","pt":1724553053258,"mc":[{"id":"1.232224255","rc":[{"batb":[[0,1.71,60.49],[1,1.21,24.75],[2,1.07,1428.57]],"ltp":1.75,"tv":110.16,"id":61422697},{"batb":[[0,2.22,35.2],[1,1.21,24.75],[2,1.07,1428.57]],"ltp":2.22,"tv":10.0,"id":60971788}]}]}
{"op":"mcm","clk":"11957033659","pt":1724553057968,"mc":[{"id":"1.232224255","rc":[{"batb":[[0,1.72,5],[1,1.71,60.49],[2,1.21,24.75]],"ltp":1.75,"tv":110.16,"id":61422697},{"batb":[[0,2.24,5],[1,2.22,35.2],[2,1.21,24.75]],"ltp":2.22,"tv":10.0,"id":60971788}]}]}
{"op":"mcm","clk":"11957033894","pt":1724553061267,"mc":[{"id":"1.232224255","rc":[{"batb":[[0,1.71,60.49],[1,1.21,24.75],[2,1.07,1428.57]],"ltp":1.75,"tv":110.16,"id":61422697},{"batb":[[0,2.22,35.2],[1,1.21,24.75],[2,1.07,1428.57]],"ltp":2.22,"tv":10.0,"id":60971788}]}]}
{"op":"mcm","clk":"11957034172","pt":1724553064733,"mc":[{"id":"1.232224255","rc":[{"batb":[[0,1.72,5],[1,1.71,60.49],[2,1.21,24.75]],"ltp":1.75,"tv":110.16,"id":61422697},{"batb":[[0,2.24,5],[1,2.22,35.2],[2,1.21,24.75]],"ltp":2.22,"tv":10.0,"id":60971788}]}]}
{"op":"mcm","clk":"11957034424","pt":1724553068136,"mc":[{"id":"1.232224255","rc":[{"batb":[[0,1.71,60.49],[1,1.21,24.75],[2,1.07,1428.57]],"ltp":1.75,"tv":110.16,"id":61422697},{"batb":[[0,2.22,35.2],[1,1.21,24.75],[2,1.07,1428.57]],"ltp":2.22,"tv":10.0,"id":60971788}]}]}
{"op":"mcm","clk":"11957034644","pt":1724553071080,"mc":[{"id":"1.232224255","rc":[{"batb":[[0,1.72,5],[1,1.71,60.49],[2,1.21,24.75]],"ltp":1.75,"tv":110.16,"id":61422697},{"batb":[[0,2.24,5],[1,2.22,35.2],[2,1.21,24.75]],"ltp":2.22,"tv":10.0,"id":60971788}]}]}
{"op":"mcm","clk":"11957034946","pt":1724553074548,"mc":[{"id":"1.232224255","rc":[{"batb":[[0,1.71,60.49],[1,1.21,24.75],[2,1.07,1428.57]],"ltp":1.75,"tv":110.16,"id":61422697},{"batb":[[0,2.22,35.2],[1,1.21,24.75],[2,1.07,1428.57]],"ltp":2.22,"tv":10.0,"id":60971788}]}]}
{"op":"mcm","clk":"11957035302","pt":1724553079179,"mc":[{"id":"1.232224255","rc":[{"batb":[[0,1.72,5],[1,1.71,60.49],[2,1.21,24.75]],"ltp":1.75,"tv":110.16,"id":61422697},{"batb":[[0,2.24,5],[1,2.22,35.2],[2,1.21,24.75]],"ltp":2.22,"tv":10.0,"id":60971788}]}]}
{"op":"mcm","clk":"11957035582","pt":1724553082689,"mc":[{"id":"1.232224255","rc":[{"batb":[[0,1.71,60.49],[1,1.21,24.75],[2,1.07,1428.57]],"ltp":1.75,"tv":110.16,"id":61422697},{"batb":[[0,2.22,35.2],[1,1.21,24.75],[2,1.07,1428.57]],"ltp":2.22,"tv":10.0,"id":60971788}]}]}
{"op":"mcm","clk":"11957035757","pt":1724553084757,"mc":[{"id":"1.232224255","rc":[{"batb":[[0,1.72,5],[1,1.71,60.49],[2,1.21,24.75]],"ltp":1.75,"tv":110.16,"id":61422697},{"batb":[[0,2.24,5],[1,2.22,35.2],[2,1.21,24.75]],"ltp":2.22,"tv":10.0,"id":60971788}]}]}
{"op":"mcm","clk":"11957035997","pt":1724553088195,"mc":[{"id":"1.232224255","rc":[{"batb":[[0,1.71,60.49],[1,1.21,24.75],[2,1.07,1428.57]],"ltp":1.75,"tv":110.16,"id":61422697},{"batb":[[0,2.22,35.2],[1,1.21,24.75],[2,1.07,1428.57]],"ltp":2.22,"tv":10.0,"id":60971788}]}]}
{"op":"mcm","clk":"11957036160","pt":1724553090358,"mc":[{"id":"1.232224255","rc":[{"batb":[[0,1.72,5],[1,1.71,60.49],[2,1.21,24.75]],"ltp":1.75,"tv":110.16,"id":61422697},{"batb":[[0,2.24,5],[1,2.22,35.2],[2,1.21,24.75]],"ltp":2.22,"tv":10.0,"id":60971788}]}]}
{"op":"mcm","clk":"11957036376","pt":1724553093694,"mc":[{"id":"1.232224255","rc":[{"batb":[[0,1.71,60.49],[1,1.21,24.75],[2,1.07,1428.57]],"ltp":1.75,"tv":110.16,"id":61422697},{"batb":[[0,2.22,35.2],[1,1.21,24.75],[2,1.07,1428.57]],"ltp":2.22,"tv":10.0,"id":60971788}]}]}
{"op":"mcm","clk":"11957036519","pt":1724553095896,"mc":[{"id":"1.232224255","rc":[{"batb":[[0,1.72,5],[1,1.71,60.49],[2,1.21,24.75]],"ltp":1.75,"tv":110.16,"id":61422697},{"batb":[[0,2.24,5],[1,2.22,35.2],[2,1.21,24.75]],"ltp":2.22,"tv":10.0,"id":60971788}]}]}
{"op":"mcm","clk":"11957036737","pt":1724553099266,"mc":[{"id":"1.232224255","rc":[{"batb":[[0,1.71,60.49],[1,1.21,24.75],[2,1.07,1428.57]],"ltp":1.75,"tv":110.16,"id":61422697},{"batb":[[0,2.22,35.2],[1,1.21,24.75],[2,1.07,1428.57]],"ltp":2.22,"tv":10.0,"id":60971788}]}]}
{"op":"mcm","clk":"11957036898","pt":1724553102096,"mc":[{"id":"1.232224255","rc":[{"batb":[[0,1.72,5],[1,1.71,60.49],[2,1.21,24.75]],"ltp":1.75,"tv":110.16,"id":61422697},{"batb":[[0,2.24,5],[1,2.22,35.2],[2,1.21,24.75]],"ltp":2.22,"tv":10.0,"id":60971788}]}]}
{"op":"mcm","clk":"11957037132","pt":1724553105397,"mc":[{"id":"1.232224255","rc":[{"batb":[[0,1.71,60.49],[1,1.21,24.75],[2,1.07,1428.57]],"ltp":1.75,"tv":110.16,"id":61422697},{"batb":[[0,2.22,35.2],[1,1.21,24.75],[2,1.07,1428.57]],"ltp":2.22,"tv":10.0,"id":60971788}]}]}
{"op":"mcm","clk":"11957037293","pt":1724553108182,"mc":[{"id":"1.232224255","rc":[{"batb":[[0,1.72,5],[1,1.71,60.49],[2,1.21,24.75]],"ltp":1.75,"tv":110.16,"id":61422697},{"batb":[[0,2.24,5],[1,2.22,35.2],[2,1.21,24.75]],"ltp":2.22,"tv":10.0,"id":60971788}]}]}
{"op":"mcm","clk":"11957037487","pt":1724553111473,"mc":[{"id":"1.232224255","rc":[{"batb":[[0,1.71,60.49],[1,1.21,24.75],[2,1.07,1428.57]],"ltp":1.75,"tv":110.16,"id":61422697},{"batb":[[0,2.22,35.2],[1,1.21,24.75],[2,1.07,1428.57]],"ltp":2.22,"tv":10.0,"id":60971788}]}]}
{"op":"mcm","clk":"11957037647","pt":1724553113894,"mc":[{"id":"1.232224255","rc":[{"batb":[[0,1.72,5],[1,1.71,60.49],[2,1.21,24.75]],"ltp":1.75,"tv":110.16,"id":61422697},{"batb":[[0,2.24,5],[1,2.22,35.2],[2,1.21,24.75]],"ltp":2.22,"tv":10.0,"id":60971788}]}]}
{"op":"mcm","clk":"11957037874","pt":1724553117182,"mc":[{"id":"1.232224255","rc":[{"batb":[[0,1.71,60.49],[1,1.21,24.75],[2,1.07,1428.57]],"ltp":1.75,"tv":110.16,"id":61422697},{"batb":[[0,2.22,35.2],[1,1.21,24.75],[2,1.07,1428.57]],"ltp":2.22,"tv":10.0,"id":60971788}]}]}
{"op":"mcm","clk":"11957038139","pt":1724553120995,"mc":[{"id":"1.232224255","rc":[{"batb":[[0,1.72,5],[1,1.71,60.49],[2,1.21,24.75]],"ltp":1.75,"tv":110.16,"id":61422697},{"batb":[[0,2.24,5],[1,2.22,35.2],[2,1.21,24.75]],"ltp":2.22,"tv":10.0,"id":60971788}]}]}
{"op":"mcm","clk":"11957038365","pt":1724553124297,"mc":[{"id":"1.232224255","rc":[{"batb":[[0,1.71,60.49],[1,1.21,24.75],[2,1.07,1428.57]],"ltp":1.75,"tv":110.16,"id":61422697},{"batb":[[0,2.22,35.2],[1,1.21,24.75],[2,1.07,1428.57]],"ltp":2.22,"tv":10.0,"id":60971788}]}]}
{"op":"mcm","clk":"11957038503","pt":1724553126714,"mc":[{"id":"1.232224255","rc":[{"batb":[[0,1.72,5],[1,1.71,60.49],[2,1.21,24.75]],"ltp":1.75,"tv":110.16,"id":61422697},{"batb":[[0,2.24,5],[1,2.22,35.2],[2,1.21,24.75]],"ltp":2.22,"tv":10.0,"id":60971788}]}]}
{"op":"mcm","clk":"11957038742","pt":1724553130113,"mc":[{"id":"1.232224255","rc":[{"batb":[[0,1.71,60.49],[1,1.21,24.75],[2,1.07,1428.57]],"ltp":1.75,"tv":110.16,"id":61422697},{"batb":[[0,2.22,35.2],[1,1.21,24.75],[2,1.07,1428.57]],"ltp":2.22,"tv":10.0,"id":60971788}]}]}
{"op":"mcm","clk":"11957038892","pt":1724553132323,"mc":[{"id":"1.232224255","rc":[{"batb":[[0,1.72,5],[1,1.71,60.49],[2,1.21,24.75]],"ltp":1.75,"tv":110.16,"id":61422697},{"batb":[[0,2.24,5],[1,2.22,35.2],[2,1.21,24.75]],"ltp":2.22,"tv":10.0,"id":60971788}]}]}
{"op":"mcm","clk":"11957039168","pt":1724553135731,"mc":[{"id":"1.232224255","rc":[{"batb":[[0,1.71,60.49],[1,1.21,24.75],[2,1.07,1428.57]],"ltp":1.75,"tv":110.16,"id":61422697},{"batb":[[0,2.22,35.2],[1,1.21,24.75],[2,1.07,1428.57]],"ltp":2.22,"tv":10.0,"id":60971788}]}]}
{"op":"mcm","clk":"11957039400","pt":1724553138928,"mc":[{"id":"1.232224255","rc":[{"batb":[[0,1.72,5],[1,1.71,60.49],[2,1.21,24.75]],"ltp":1.75,"tv":110.16,"id":61422697},{"batb":[[0,2.24,5],[1,2.22,35.2],[2,1.21,24.75]],"ltp":2.22,"tv":10.0,"id":60971788}]}]}
{"op":"mcm","clk":"11957039643","pt":1724553142236,"mc":[{"id":"1.232224255","rc":[{"batb":[[0,1.71,60.49],[1,1.21,24.75],[2,1.07,1428.57]],"ltp":1.75,"tv":110.16,"id":61422697},{"batb":[[0,2.22,35.2],[1,1.21,24.75],[2,1.07,1428.57]],"ltp":2.22,"tv":10.0,"id":60971788}]}]}
{"op":"mcm","clk":"11957039946","pt":1724553145965,"mc":[{"id":"1.232224255","rc":[{"batb":[[0,1.72,5],[1,1.71,60.49],[2,1.21,24.75]],"ltp":1.75,"tv":110.16,"id":61422697},{"batb":[[0,2.24,5],[1,2.22,35.2],[2,1.21,24.75]],"ltp":2.22,"tv":10.0,"id":60971788}]}]}
{"op":"mcm","clk":"11957040191","pt":1724553149258,"mc":[{"id":"1.232224255","rc":[{"batb":[[0,1.71,60.49],[1,1.21,24.75],[2,1.07,1428.57]],"ltp":1.75,"tv":110.16,"id":61422697},{"batb":[[0,2.22,35.2],[1,1.21,24.75],[2,1.07,1428.57]],"ltp":2.22,"tv":10.0,"id":60971788}]}]}
{"op":"mcm","clk":"11957040413","pt":1724553152451,"mc":[{"id":"1.232224255","rc":[{"batb":[[0,1.72,5],[1,1.71,60.49],[2,1.21,24.75]],"ltp":1.75,"tv":110.16,"id":61422697},{"batb":[[0,2.24,5],[1,2.22,35.2],[2,1.21,24.75]],"ltp":2.22,"tv":10.0,"id":60971788}]}]}
{"op":"mcm","clk":"11957040644","pt":1724553155752,"mc":[{"id":"1.232224255","rc":[{"batb":[[0,1.71,60.49],[1,1.21,24.75],[2,1.07,1428.57]],"ltp":1.75,"tv":110.16,"id":61422697},{"batb":[[0,2.22,35.2],[1,1.21,24.75],[2,1.07,1428.57]],"ltp":2.22,"tv":10.0,"id":60971788}]}]}
{"op":"mcm","clk":"11957040873","pt":1724553158852,"mc":[{"id":"1.232224255","rc":[{"batb":[[0,1.72,5],[1,1.71,60.49],[2,1.21,24.75]],"ltp":1.75,"tv":110.16,"id":61422697},{"batb":[[0,2.24,5],[1,2.22,35.2],[2,1.21,24.75]],"ltp":2.22,"tv":10.0,"id":60971788}]}]}
{"op":"mcm","clk":"11957041122","pt":1724553162266,"mc":[{"id":"1.232224255","rc":[{"batb":[[0,1.71,60.49],[1,1.21,24.75],[2,1.07,1428.57]],"ltp":1.75,"tv":110.16,"id":61422697},{"batb":[[0,2.22,35.2],[1,1.21,24.75],[2,1.07,1428.57]],"ltp":2.22,"tv":10.0,"id":60971788}]}]}
{"op":"mcm","clk":"11957041297","pt":1724553164633,"mc":[{"id":"1.232224255","rc":[{"batb":[[0,1.72,5],[1,1.71,60.49],[2,1.21,24.75]],"ltp":1.75,"tv":110.16,"id":61422697},{"batb":[[0,2.24,5],[1,2.22,35.2],[2,1.21,24.75]],"ltp":2.22,"tv":10.0,"id":60971788}]}]}
{"op":"mcm","clk":"11957041524","pt":1724553167971,"mc":[{"id":"1.232224255","rc":[{"batb":[[0,1.71,60.49],[1,1.21,24.75],[2,1.07,1428.57]],"ltp":1.75,"tv":110.16,"id":61422697},{"batb":[[0,2.22,35.2],[1,1.21,24.75],[2,1.07,1428.57]],"ltp":2.22,"tv":10.0,"id":60971788}]}]}
{"op":"mcm","clk":"11957041843","pt":1724553173068,"mc":[{"id":"1.232224255","rc":[{"batb":[[0,1.72,5],[1,1.71,60.49],[2,1.21,24.75]],"ltp":1.75,"tv":110.16,"id":61422697},{"batb":[[0,2.24,5],[1,2.22,35.2],[2,1.21,24.75]],"ltp":2.22,"tv":10.0,"id":60971788}]}]}
{"op":"mcm","clk":"11957042058","pt":1724553176259,"mc":[{"id":"1.232224255","rc":[{"batb":[[0,1.71,60.49],[1,1.21,24.75],[2,1.07,1428.57]],"ltp":1.75,"tv":110.16,"id":61422697},{"batb":[[0,2.22,35.2],[1,1.21,24.75],[2,1.07,1428.57]],"ltp":2.22,"tv":10.0,"id":60971788}]}]}
{"op":"mcm","clk":"11957042215","pt":1724553178674,"mc":[{"id":"1.232224255","rc":[{"batb":[[0,1.72,5],[1,1.71,60.49],[2,1.21,24.75]],"ltp":1.75,"tv":110.16,"id":61422697},{"batb":[[0,2.24,5],[1,2.22,35.2],[2,1.21,24.75]],"ltp":2.22,"tv":10.0,"id":60971788}]}]}
{"op":"mcm","clk":"11957042446","pt":1724553182065,"mc":[{"id":"1.232224255","rc":[{"batb":[[0,1.71,60.49],[1,1.21,24.75],[2,1.07,1428.57]],"ltp":1.75,"tv":110.16,"id":61422697},{"batb":[[0,2.22,35.2],[1,1.21,24.75],[2,1.07,1428.57]],"ltp":2.22,"tv":10.0,"id":60971788}]}]}
{"op":"mcm","clk":"11957042698","pt":1724553185282,"mc":[{"id":"1.232224255","rc":[{"batb":[[0,1.72,5],[1,1.71,60.49],[2,1.21,24.75]],"ltp":1.75,"tv":110.16,"id":61422697},{"batb":[[0,2.24,5],[1,2.22,35.2],[2,1.21,24.75]],"ltp":2.22,"tv":10.0,"id":60971788}]}]}
{"op":"mcm","clk":"11957042912","pt":1724553188572,"mc":[{"id":"1.232224255","rc":[{"batb":[[0,1.71,60.49],[1,1.21,24.75],[2,1.07,1428.57]],"ltp":1.75,"tv":110.16,"id":61422697},{"batb":[[0,2.22,35.2],[1,1.21,24.75],[2,1.07,1428.57]],"ltp":2.22,"tv":10.0,"id":60971788}]}]}
{"op":"mcm","clk":"11957043098","pt":1724553191303,"mc":[{"id":"1.232224255","rc":[{"batb":[[0,1.72,5],[1,1.71,60.49],[2,1.21,24.75]],"ltp":1.75,"tv":110.16,"id":61422697},{"batb":[[0,2.24,5],[1,2.22,35.2],[2,1.21,24.75]],"ltp":2.22,"tv":10.0,"id":60971788}]}]}
{"op":"mcm","clk":"11957043360","pt":1724553194574,"mc":[{"id":"1.232224255","rc":[{"batb":[[0,1.71,60.49],[1,1.21,24.75],[2,1.07,1428.57]],"ltp":1.75,"tv":110.16,"id":61422697},{"batb":[[0,2.22,35.2],[1,1.21,24.75],[2,1.07,1428.57]],"ltp":2.22,"tv":10.0,"id":60971788}]}]}
{"op":"mcm","clk":"11957043853","pt":1724553201596,"mc":[{"id":"1.232224255","rc":[{"batb":[[0,1.72,5],[1,1.71,60.49],[2,1.21,24.75]],"ltp":1.75,"tv":110.16,"id":61422697},{"batb":[[0,2.24,5],[1,2.22,35.2],[2,1.21,24.75]],"ltp":2.22,"tv":10.0,"id":60971788}]}]}
{"op":"mcm","clk":"11957044098","pt":1724553204890,"mc":[{"id":"1.232224255","rc":[{"batb":[[0,1.71,60.49],[1,1.21,24.75],[2,1.07,1428.57]],"ltp":1.75,"tv":110.16,"id":61422697},{"batb":[[0,2.22,35.2],[1,1.21,24.75],[2,1.07,1428.57]],"ltp":2.22,"tv":10.0,"id":60971788}]}]}
{"op":"mcm","clk":"11957044292","pt":1724553208789,"mc":[{"id":"1.232224255","rc":[{"batb":[[0,1.72,5],[1,1.71,60.49],[2,1.21,24.75]],"ltp":1.75,"tv":110.16,"id":61422697},{"batb":[[0,2.24,5],[1,2.22,35.2],[2,1.21,24.75]],"ltp":2.22,"tv":10.0,"id":60971788}]}]}
{"op":"mcm","clk":"11957044513","pt":1724553212109,"mc":[{"id":"1.232224255","rc":[{"batb":[[0,1.71,60.49],[1,1.21,24.75],[2,1.07,1428.57]],"ltp":1.75,"tv":110.16,"id":61422697},{"batb":[[0,2.22,35.2],[1,1.21,24.75],[2,1.07,1428.57]],"ltp":2.22,"tv":10.0,"id":60971788}]}]}
{"op":"mcm","clk":"11957044712","pt":1724553214997,"mc":[{"id":"1.232224255","rc":[{"batb":[[0,1.72,5],[1,1.71,60.49],[2,1.21,24.75]],"ltp":1.75,"tv":110.16,"id":61422697},{"batb":[[0,2.24,5],[1,2.22,35.2],[2,1.21,24.75]],"ltp":2.22,"tv":10.0,"id":60971788}]}]}
{"op":"mcm","clk":"11957044984","pt":1724553218397,"mc":[{"id":"1.232224255","rc":[{"batb":[[0,1.71,60.49],[1,1.21,24.75],[2,1.07,1428.57]],"ltp":1.75,"tv":110.16,"id":61422697},{"batb":[[0,2.22,35.2],[1,1.21,24.75],[2,1.07,1428.57]],"ltp":2.22,"tv":10.0,"id":60971788}]}]}
{"op":"mcm","clk":"11957045281","pt":1724553224125,"mc":[{"id":"1.232224255","rc":[{"batb":[[0,1.72,5],[1,1.71,60.49],[2,1.21,24.75]],"ltp":1.75,"tv":110.16,"id":61422697},{"batb":[[0,2.24,5],[1,2.22,35.2],[2,1.21,24.75]],"ltp":2.22,"tv":10.0,"id":60971788}]}]}
{"op":"mcm","clk":"11957045460","pt":1724553227416,"mc":[{"id":"1.232224255","rc":[{"batb":[[0,1.71,60.49],[1,1.21,24.75],[2,1.07,1428.57]],"ltp":1.75,"tv":110.16,"id":61422697},{"batb":[[0,2.22,35.2],[1,1.21,24.75],[2,1.07,1428.57]],"ltp":2.22,"tv":10.0,"id":60971788}]}]}
{"op":"mcm","clk":"11957045930","pt":1724553234732,"mc":[{"id":"1.232224255","rc":[{"batb":[[0,1.72,5],[1,1.71,60.49],[2,1.21,24.75]],"ltp":1.75,"tv":110.16,"id":61422697},{"batb":[[0,2.24,5],[1,2.22,35.2],[2,1.21,24.75]],"ltp":2.22,"tv":10.0,"id":60971788}]}]}
{"op":"mcm","clk":"11957046102","pt":1724553238028,"mc":[{"id":"1.232224255","rc":[{"batb":[[0,1.71,60.49],[1,1.21,24.75],[2,1.07,1428.57]],"ltp":1.75,"tv":110.16,"id":61422697},{"batb":[[0,2.22,35.2],[1,1.21,24.75],[2,1.07,1428.57]],"ltp":2.22,"tv":10.0,"id":60971788}]}]}
{"op":"mcm","clk":"11957046262","pt":1724553240855,"mc":[{"id":"1.232224255","rc":[{"batb":[[0,1.72,5],[1,1.71,60.49],[2,1.21,24.75]],"ltp":1.75,"tv":110.16,"id":61422697},{"batb":[[0,2.24,5],[1,2.22,35.2],[2,1.21,24.75]],"ltp":2.22,"tv":10.0,"id":60971788}]}]}
{"op":"mcm","clk":"11957046439","pt":1724553244216,"mc":[{"id":"1.232224255","rc":[{"batb":[[0,1.71,60.49],[1,1.21,24.75],[2,1.07,1428.57]],"ltp":1.75,"tv":110.16,"id":61422697},{"batb":[[0,2.22,35.2],[1,1.21,24.75],[2,1.07,1428.57]],"ltp":2.22,"tv":10.0,"id":60971788}]}]}
{"op":"mcm","clk":"11957046601","pt":1724553247044,"mc":[{"id":"1.232224255","rc":[{"batb":[[0,1.72,5],[1,1.71,60.49],[2,1.21,24.75]],"ltp":1.75,"tv":110.16,"id":61422697},{"batb":[[0,2.24,5],[1,2.22,35.2],[2,1.21,24.75]],"ltp":2.22,"tv":10.0,"id":60971788}]}]}
{"op":"mcm","clk":"11957046799","pt":1724553250338,"mc":[{"id":"1.232224255","rc":[{"batb":[[0,1.71,60.49],[1,1.21,24.75],[2,1.07,1428.57]],"ltp":1.75,"tv":110.16,"id":61422697},{"batb":[[0,2.22,35.2],[1,1.21,24.75],[2,1.07,1428.57]],"ltp":2.22,"tv":10.0,"id":60971788}]}]}
{"op":"mcm","clk":"11957047125","pt":1724553255653,"mc":[{"id":"1.232224255","rc":[{"batb":[[0,1.72,5],[1,1.71,60.49],[2,1.21,24.75]],"ltp":1.75,"tv":110.16,"id":61422697},{"batb":[[0,2.24,5],[1,2.22,35.2],[2,1.21,24.75]],"ltp":2.22,"tv":10.0,"id":60971788}]}]}
{"op":"mcm","clk":"11957047322","pt":1724553259051,"mc":[{"id":"1.232224255","rc":[{"batb":[[0,1.71,60.49],[1,1.21,24.75],[2,1.07,1428.57]],"ltp":1.75,"tv":110.16,"id":61422697},{"batb":[[0,2.22,35.2],[1,1.21,24.75],[2,1.07,1428.57]],"ltp":2.22,"tv":10.0,"id":60971788}]}]}
{"op":"mcm","clk":"11957047771","pt":1724553266759,"mc":[{"id":"1.232224255","rc":[{"batb":[[0,1.72,5],[1,1.71,60.49],[2,1.21,24.75]],"ltp":1.75,"tv":110.16,"id":61422697},{"batb":[[0,2.24,5],[1,2.22,35.2],[2,1.21,24.75]],"ltp":2.22,"tv":10.0,"id":60971788}]}]}
{"op":"mcm","clk":"11957047947","pt":1724553269845,"mc":[{"id":"1.232224255","rc":[{"batb":[[0,2.22,35.2],[1,1.21,24.75],[2,1.07,1428.57]],"ltp":2.22,"tv":10.0,"id":60971788}]}]}
{"op":"mcm","clk":"11957047959","pt":1724553270049,"mc":[{"id":"1.232224255","rc":[{"batb":[[0,1.71,60.49],[1,1.21,24.75],[2,1.07,1428.57]],"ltp":1.75,"tv":110.16,"id":61422697}]}]}
{"op":"mcm","clk":"11957048127","pt":1724553272672,"mc":[{"id":"1.232224255","rc":[{"batb":[[0,1.72,5],[1,1.71,60.49],[2,1.21,24.75]],"ltp":1.75,"tv":110.16,"id":61422697},{"batb":[[0,2.24,5],[1,2.22,35.2],[2,1.21,24.75]],"ltp":2.22,"tv":10.0,"id":60971788}]}]}
{"op":"mcm","clk":"11957048393","pt":1724553276081,"mc":[{"id":"1.232224255","rc":[{"batb":[[0,1.71,60.49],[1,1.21,24.75],[2,1.07,1428.57]],"ltp":1.75,"tv":110.16,"id":61422697},{"batb":[[0,2.22,35.2],[1,1.21,24.75],[2,1.07,1428.57]],"ltp":2.22,"tv":10.0,"id":60971788}]}]}
{"op":"mcm","clk":"11957048613","pt":1724553279581,"mc":[{"id":"1.232224255","rc":[{"batb":[[0,1.72,5],[1,1.71,60.49],[2,1.21,24.75]],"ltp":1.75,"tv":110.16,"id":61422697},{"batb":[[0,2.24,5],[1,2.22,35.2],[2,1.21,24.75]],"ltp":2.22,"tv":10.0,"id":60971788}]}]}
{"op":"mcm","clk":"11957048830","pt":1724553282867,"mc":[{"id":"1.232224255","rc":[{"batb":[[0,1.71,60.49],[1,1.21,24.75],[2,1.07,1428.57]],"ltp":1.75,"tv":110.16,"id":61422697},{"batb":[[0,2.22,35.2],[1,1.21,24.75],[2,1.07,1428.57]],"ltp":2.22,"tv":10.0,"id":60971788}]}]}
{"op":"mcm","clk":"11957049018","pt":1724553286887,"mc":[{"id":"1.232224255","rc":[{"batb":[[0,1.72,5],[1,1.71,60.49],[2,1.21,24.75]],"ltp":1.75,"tv":110.16,"id":61422697},{"batb":[[0,2.24,5],[1,2.22,35.2],[2,1.21,24.75]],"ltp":2.22,"tv":10.0,"id":60971788}]}]}
{"op":"mcm","clk":"11957049225","pt":1724553290392,"mc":[{"id":"1.232224255","rc":[{"batb":[[0,1.71,60.49],[1,1.21,24.75],[2,1.07,1428.57]],"ltp":1.75,"tv":110.16,"id":61422697},{"batb":[[0,2.22,35.2],[1,1.21,24.75],[2,1.07,1428.57]],"ltp":2.22,"tv":10.0,"id":60971788}]}]}
{"op":"mcm","clk":"11957049460","pt":1724553294453,"mc":[{"id":"1.232224255","rc":[{"batb":[[0,1.72,5],[1,1.71,60.49],[2,1.21,24.75]],"ltp":1.75,"tv":110.16,"id":61422697},{"batb":[[0,2.24,5],[1,2.22,35.2],[2,1.21,24.75]],"ltp":2.22,"tv":10.0,"id":60971788}]}]}
{"op":"mcm","clk":"11957049626","pt":1724553297789,"mc":[{"id":"1.232224255","rc":[{"batb":[[0,1.71,60.49],[1,1.21,24.75],[2,1.07,1428.57]],"ltp":1.75,"tv":110.16,"id":61422697},{"batb":[[0,2.22,35.2],[1,1.21,24.75],[2,1.07,1428.57]],"ltp":2.22,"tv":10.0,"id":60971788}]}]}
{"op":"mcm","clk":"11957050195","pt":1724553307095,"mc":[{"id":"1.232224255","rc":[{"batb":[[0,1.72,5],[1,1.71,60.49],[2,1.21,24.75]],"ltp":1.75,"tv":110.16,"id":61422697},{"batb":[[0,2.24,5],[1,2.22,35.2],[2,1.21,24.75]],"ltp":2.22,"tv":10.0,"id":60971788}]}]}
{"op":"mcm","clk":"11957050405","pt":1724553310385,"mc":[{"id":"1.232224255","rc":[{"batb":[[0,1.71,60.49],[1,1.21,24.75],[2,1.07,1428.57]],"ltp":1.75,"tv":110.16,"id":61422697},{"batb":[[0,2.22,35.2],[1,1.21,24.75],[2,1.07,1428.57]],"ltp":2.22,"tv":10.0,"id":60971788}]}]}
{"op":"mcm","clk":"11957050573","pt":1724553313010,"mc":[{"id":"1.232224255","rc":[{"batb":[[0,1.72,5],[1,1.71,60.49],[2,1.21,24.75]],"ltp":1.75,"tv":110.16,"id":61422697},{"batb":[[0,2.24,5],[1,2.22,35.2],[2,1.21,24.75]],"ltp":2.22,"tv":10.0,"id":60971788}]}]}
{"op":"mcm","clk":"11957050785","pt":1724553316307,"mc":[{"id":"1.232224255","rc":[{"batb":[[0,1.71,60.49],[1,1.21,24.75],[2,1.07,1428.57]],"ltp":1.75,"tv":110.16,"id":61422697},{"batb":[[0,2.22,35.2],[1,1.21,24.75],[2,1.07,1428.57]],"ltp":2.22,"tv":10.0,"id":60971788}]}]}
{"op":"mcm","clk":"11957050941","pt":1724553318679,"mc":[{"id":"1.232224255","rc":[{"batb":[[0,1.72,5],[1,1.71,60.49],[2,1.21,24.75]],"ltp":1.75,"tv":110.16,"id":61422697},{"batb":[[0,2.24,5],[1,2.22,35.2],[2,1.21,24.75]],"ltp":2.22,"tv":10.0,"id":60971788}]}]}
{"op":"mcm","clk":"11957051253","pt":1724553322181,"mc":[{"id":"1.232224255","rc":[{"batb":[[0,1.71,60.49],[1,1.21,24.75],[2,1.07,1428.57]],"ltp":1.75,"tv":110.16,"id":61422697},{"batb":[[0,2.22,35.2],[1,1.21,24.75],[2,1.07,1428.57]],"ltp":2.22,"tv":10.0,"id":60971788}]}]}
{"op":"mcm","clk":"11957051457","pt":1724553324712,"mc":[{"id":"1.232224255","rc":[{"batb":[[0,1.72,5],[1,1.71,60.49],[2,1.21,24.75]],"ltp":1.75,"tv":110.16,"id":61422697},{"batb":[[0,2.24,5],[1,2.22,35.2],[2,1.21,24.75]],"ltp":2.22,"tv":10.0,"id":60971788}]}]}
{"op":"mcm","clk":"11957051685","pt":1724553328018,"mc":[{"id":"1.232224255","rc":[{"batb":[[0,1.71,60.49],[1,1.21,24.75],[2,1.07,1428.57]],"ltp":1.75,"tv":110.16,"id":61422697},{"batb":[[0,2.22,35.2],[1,1.21,24.75],[2,1.07,1428.57]],"ltp":2.22,"tv":10.0,"id":60971788}]}]}
{"op":"mcm","clk":"11957052017","pt":1724553333421,"mc":[{"id":"1.232224255","rc":[{"batb":[[0,1.72,5],[1,1.71,60.49],[2,1.21,24.75]],"ltp":1.75,"tv":110.16,"id":61422697},{"batb":[[0,2.24,5],[1,2.22,35.2],[2,1.21,24.75]],"ltp":2.22,"tv":10.0,"id":60971788}]}]}
{"op":"mcm","clk":"11957052213","pt":1724553336712,"mc":[{"id":"1.232224255","rc":[{"batb":[[0,1.71,60.49],[1,1.21,24.75],[2,1.07,1428.57]],"ltp":1.75,"tv":110.16,"id":61422697},{"batb":[[0,2.22,35.2],[1,1.21,24.75],[2,1.07,1428.57]],"ltp":2.22,"tv":10.0,"id":60971788}]}]}
{"op":"mcm","clk":"11957052628","pt":1724553342985,"mc":[{"id":"1.232224255","rc":[{"batb":[[0,1.72,5],[1,1.71,60.49],[2,1.21,24.75]],"ltp":1.75,"tv":110.16,"id":61422697},{"batb":[[0,2.24,5],[1,2.22,35.2],[2,1.21,24.75]],"ltp":2.22,"tv":10.0,"id":60971788}]}]}
{"op":"mcm","clk":"11957052884","pt":1724553346427,"mc":[{"id":"1.232224255","rc":[{"batb":[[0,1.71,60.49],[1,1.21,24.75],[2,1.07,1428.57]],"ltp":1.75,"tv":110.16,"id":61422697},{"batb":[[0,2.22,35.2],[1,1.21,24.75],[2,1.07,1428.57]],"ltp":2.22,"tv":10.0,"id":60971788}]}]}
{"op":"mcm","clk":"11957053044","pt":1724553348588,"mc":[{"id":"1.232224255","rc":[{"batb":[[0,1.72,5],[1,1.71,60.49],[2,1.21,24.75]],"ltp":1.75,"tv":110.16,"id":61422697},{"batb":[[0,2.24,5],[1,2.22,35.2],[2,1.21,24.75]],"ltp":2.22,"tv":10.0,"id":60971788}]}]}
{"op":"mcm","clk":"11957053252","pt":1724553351827,"mc":[{"id":"1.232224255","rc":[{"batb":[[0,1.71,60.49],[1,1.21,24.75],[2,1.07,1428.57]],"ltp":1.75,"tv":110.16,"id":61422697},{"batb":[[0,2.22,35.2],[1,1.21,24.75],[2,1.07,1428.57]],"ltp":2.22,"tv":10.0,"id":60971788}]}]}
{"op":"mcm","clk":"11957053485","pt":1724553355434,"mc":[{"id":"1.232224255","rc":[{"batb":[[0,1.72,5],[1,1.71,60.49],[2,1.21,24.75]],"ltp":1.75,"tv":110.16,"id":61422697},{"batb":[[0,2.24,5],[1,2.22,35.2],[2,1.21,24.75]],"ltp":2.22,"tv":10.0,"id":60971788}]}]}
{"op":"mcm","clk":"11957053740","pt":1724553358839,"mc":[{"id":"1.232224255","rc":[{"batb":[[0,1.71,60.49],[1,1.21,24.75],[2,1.07,1428.57]],"ltp":1.75,"tv":110.16,"id":61422697},{"batb":[[0,2.22,35.2],[1,1.21,24.75],[2,1.07,1428.57]],"ltp":2.22,"tv":10.0,"id":60971788}]}]}
{"op":"mcm","clk":"11957053897","pt":1724553360919,"mc":[{"id":"1.232224255","rc":[{"batb":[[0,1.72,5],[1,1.71,60.49],[2,1.21,24.75]],"ltp":1.75,"tv":110.16,"id":61422697},{"batb":[[0,2.24,5],[1,2.22,35.2],[2,1.21,24.75]],"ltp":2.22,"tv":10.0,"id":60971788}]}]}
{"op":"mcm","clk":"11957054151","pt":1724553364429,"mc":[{"id":"1.232224255","rc":[{"batb":[[0,1.71,60.49],[1,1.21,24.75],[2,1.07,1428.57]],"ltp":1.75,"tv":110.16,"id":61422697},{"batb":[[0,2.22,35.2],[1,1.21,24.75],[2,1.07,1428.57]],"ltp":2.22,"tv":10.0,"id":60971788}]}]}
{"op":"mcm","clk":"11957054286","pt":1724553366536,"mc":[{"id":"1.232224255","rc":[{"batb":[[0,1.72,5],[1,1.71,60.49],[2,1.21,24.75]],"ltp":1.75,"tv":110.16,"id":61422697},{"batb":[[0,2.24,5],[1,2.22,35.2],[2,1.21,24.75]],"ltp":2.22,"tv":10.0,"id":60971788}]}]}
{"op":"mcm","clk":"11957054523","pt":1724553369823,"mc":[{"id":"1.232224255","rc":[{"batb":[[0,1.71,60.49],[1,1.21,24.75],[2,1.07,1428.57]],"ltp":1.75,"tv":110.16,"id":61422697},{"batb":[[0,2.22,35.2],[1,1.21,24.75],[2,1.07,1428.57]],"ltp":2.22,"tv":10.0,"id":60971788}]}]}
{"op":"mcm","clk":"11957054708","pt":1724553372651,"mc":[{"id":"1.232224255","rc":[{"batb":[[0,1.72,5],[1,1.71,60.49],[2,1.21,24.75]],"ltp":1.75,"tv":110.16,"id":61422697},{"batb":[[0,2.24,5],[1,2.22,35.2],[2,1.21,24.75]],"ltp":2.22,"tv":10.0,"id":60971788}]}]}
{"op":"mcm","clk":"11957054917","pt":1724553375951,"mc":[{"id":"1.232224255","rc":[{"batb":[[0,1.71,60.49],[1,1.21,24.75],[2,1.07,1428.57]],"ltp":1.75,"tv":110.16,"id":61422697},{"batb":[[0,2.22,35.2],[1,1.21,24.75],[2,1.07,1428.57]],"ltp":2.22,"tv":10.0,"id":60971788}]}]}
{"op":"mcm","clk":"11957055143","pt":1724553378532,"mc":[{"id":"1.232224255","rc":[{"batb":[[0,1.72,5],[1,1.71,60.49],[2,1.21,24.75]],"ltp":1.75,"tv":110.16,"id":61422697},{"batb":[[0,2.24,5],[1,2.22,35.2],[2,1.21,24.75]],"ltp":2.22,"tv":10.0,"id":60971788}]}]}
{"op":"mcm","clk":"11957055399","pt":1724553381829,"mc":[{"id":"1.232224255","rc":[{"batb":[[0,1.71,60.49],[1,1.21,24.75],[2,1.07,1428.57]],"ltp":1.75,"tv":110.16,"id":61422697},{"batb":[[0,2.22,35.2],[1,1.21,24.75],[2,1.07,1428.57]],"ltp":2.22,"tv":10.0,"id":60971788}]}]}
{"op":"mcm","clk":"11957055754","pt":1724553387066,"mc":[{"id":"1.232224255","rc":[{"batb":[[0,1.72,5],[1,1.71,60.49],[2,1.21,24.75]],"ltp":1.75,"tv":110.16,"id":61422697},{"batb":[[0,2.24,5],[1,2.22,35.2],[2,1.21,24.75]],"ltp":2.22,"tv":10.0,"id":60971788}]}]}
{"op":"mcm","clk":"11957055993","pt":1724553390473,"mc":[{"id":"1.232224255","rc":[{"batb":[[0,1.71,60.49],[1,1.21,24.75],[2,1.07,1428.57]],"ltp":1.75,"tv":110.16,"id":61422697},{"batb":[[0,2.22,35.2],[1,1.21,24.75],[2,1.07,1428.57]],"ltp":2.22,"tv":10.0,"id":60971788}]}]}
{"op":"mcm","clk":"11957056318","pt":1724553394584,"mc":[{"id":"1.232224255","rc":[{"batb":[[0,1.72,5],[1,1.71,60.49],[2,1.21,24.75]],"ltp":1.75,"tv":110.16,"id":61422697},{"batb":[[0,2.24,5],[1,2.22,35.2],[2,1.21,24.75]],"ltp":2.22,"tv":10.0,"id":60971788}]}]}
{"op":"mcm","clk":"11957056612","pt":1724553397876,"mc":[{"id":"1.232224255","rc":[{"batb":[[0,1.71,60.49],[1,1.21,24.75],[2,1.07,1428.57]],"ltp":1.75,"tv":110.16,"id":61422697},{"batb":[[0,2.22,35.2],[1,1.21,24.75],[2,1.07,1428.57]],"ltp":2.22,"tv":10.0,"id":60971788}]}]}
{"op":"mcm","clk":"11957056844","pt":1724553400869,"mc":[{"id":"1.232224255","rc":[{"batb":[[0,1.72,5],[1,1.71,60.49],[2,1.21,24.75]],"ltp":1.75,"tv":110.16,"id":61422697},{"batb":[[0,2.24,5],[1,2.22,35.2],[2,1.21,24.75]],"ltp":2.22,"tv":10.0,"id":60971788}]}]}
{"op":"mcm","clk":"11957057084","pt":1724553404207,"mc":[{"id":"1.232224255","rc":[{"batb":[[0,1.71,60.49],[1,1.21,24.75],[2,1.07,1428.57]],"ltp":1.75,"tv":110.16,"id":61422697},{"batb":[[0,2.22,35.2],[1,1.21,24.75],[2,1.07,1428.57]],"ltp":2.22,"tv":10.0,"id":60971788}]}]}
{"op":"mcm","clk":"11957057248","pt":1724553406365,"mc":[{"id":"1.232224255","rc":[{"batb":[[0,1.72,5],[1,1.71,60.49],[2,1.21,24.75]],"ltp":1.75,"tv":110.16,"id":61422697},{"batb":[[0,2.24,5],[1,2.22,35.2],[2,1.21,24.75]],"ltp":2.22,"tv":10.0,"id":60971788}]}]}
{"op":"mcm","clk":"11957057486","pt":1724553409555,"mc":[{"id":"1.232224255","rc":[{"batb":[[0,1.71,60.49],[1,1.21,24.75],[2,1.07,1428.57]],"ltp":1.75,"tv":110.16,"id":61422697},{"batb":[[0,2.22,35.2],[1,1.21,24.75],[2,1.07,1428.57]],"ltp":2.22,"tv":10.0,"id":60971788}]}]}
{"op":"mcm","clk":"11957057730","pt":1724553412755,"mc":[{"id":"1.232224255","rc":[{"batb":[[0,1.72,5],[1,1.71,60.49],[2,1.21,24.75]],"ltp":1.75,"tv":110.16,"id":61422697},{"batb":[[0,2.24,5],[1,2.22,35.2],[2,1.21,24.75]],"ltp":2.22,"tv":10.0,"id":60971788}]}]}
{"op":"mcm","clk":"11957057981","pt":1724553416098,"mc":[{"id":"1.232224255","rc":[{"batb":[[0,1.71,60.49],[1,1.21,24.75],[2,1.07,1428.57]],"ltp":1.75,"tv":110.16,"id":61422697},{"batb":[[0,2.22,35.2],[1,1.21,24.75],[2,1.07,1428.57]],"ltp":2.22,"tv":10.0,"id":60971788}]}]}
{"op":"mcm","clk":"11957058593","pt":1724553424315,"mc":[{"id":"1.232224255","rc":[{"batb":[[0,1.72,5],[1,1.71,60.49],[2,1.21,24.75]],"ltp":1.75,"tv":110.16,"id":61422697},{"batb":[[0,2.24,5],[1,2.22,35.2],[2,1.21,24.75]],"ltp":2.22,"tv":10.0,"id":60971788}]}]}
{"op":"mcm","clk":"11957058853","pt":1724553427613,"mc":[{"id":"1.232224255","rc":[{"batb":[[0,1.71,60.49],[1,1.21,24.75],[2,1.07,1428.57]],"ltp":1.75,"tv":110.16,"id":61422697},{"batb":[[0,2.22,35.2],[1,1.21,24.75],[2,1.07,1428.57]],"ltp":2.22,"tv":10.0,"id":60971788}]}]}
{"op":"mcm","clk":"11957059145","pt":1724553431019,"mc":[{"id":"1.232224255","rc":[{"batb":[[0,1.72,5],[1,1.71,60.49],[2,1.21,24.75]],"ltp":1.75,"tv":110.16,"id":61422697},{"batb":[[0,2.24,5],[1,2.22,35.2],[2,1.21,24.75]],"ltp":2.22,"tv":10.0,"id":60971788}]}]}
{"op":"mcm","clk":"11957059410","pt":1724553434309,"mc":[{"id":"1.232224255","rc":[{"batb":[[0,1.71,60.49],[1,1.21,24.75],[2,1.07,1428.57]],"ltp":1.75,"tv":110.16,"id":61422697},{"batb":[[0,2.22,35.2],[1,1.21,24.75],[2,1.07,1428.57]],"ltp":2.22,"tv":10.0,"id":60971788}]}]}
{"op":"mcm","clk":"11957059574","pt":1724553436733,"mc":[{"id":"1.232224255","rc":[{"batb":[[0,1.72,5],[1,1.71,60.49],[2,1.21,24.75]],"ltp":1.75,"tv":110.16,"id":61422697},{"batb":[[0,2.24,5],[1,2.22,35.2],[2,1.21,24.75]],"ltp":2.22,"tv":10.0,"id":60971788}]}]}
{"op":"mcm","clk":"11957059873","pt":1724553440140,"mc":[{"id":"1.232224255","rc":[{"batb":[[0,1.71,60.49],[1,1.21,24.75],[2,1.07,1428.57]],"ltp":1.75,"tv":110.16,"id":61422697},{"batb":[[0,2.22,35.2],[1,1.21,24.75],[2,1.07,1428.57]],"ltp":2.22,"tv":10.0,"id":60971788}]}]}
{"op":"mcm","clk":"11957060464","pt":1724553446737,"mc":[{"id":"1.232224255","rc":[{"batb":[[0,1.72,5],[1,1.71,60.49],[2,1.21,24.75]],"ltp":1.75,"tv":110.16,"id":61422697},{"batb":[[0,2.24,5],[1,2.22,35.2],[2,1.21,24.75]],"ltp":2.22,"tv":10.0,"id":60971788}]}]}
{"op":"mcm","clk":"11957060695","pt":1724553449933,"mc":[{"id":"1.232224255","rc":[{"batb":[[0,1.71,60.49],[1,1.21,24.75],[2,1.07,1428.57]],"ltp":1.75,"tv":110.16,"id":61422697},{"batb":[[0,2.22,35.2],[1,1.21,24.75],[2,1.07,1428.57]],"ltp":2.22,"tv":10.0,"id":60971788}]}]}
{"op":"mcm","clk":"11957061176","pt":1724553456849,"mc":[{"id":"1.232224255","rc":[{"batb":[[0,1.72,5],[1,1.71,60.49],[2,1.21,24.75]],"ltp":1.75,"tv":110.16,"id":61422697},{"batb":[[0,2.24,5],[1,2.22,35.2],[2,1.21,24.75]],"ltp":2.22,"tv":10.0,"id":60971788}]}]}
{"op":"mcm","clk":"11957061411","pt":1724553460248,"mc":[{"id":"1.232224255","rc":[{"batb":[[0,1.71,60.49],[1,1.21,24.75],[2,1.07,1428.57]],"ltp":1.75,"tv":110.16,"id":61422697},{"batb":[[0,2.22,35.2],[1,1.21,24.75],[2,1.07,1428.57]],"ltp":2.22,"tv":10.0,"id":60971788}]}]}
{"op":"mcm","clk":"11957061606","pt":1724553463138,"mc":[{"id":"1.232224255","rc":[{"batb":[[0,1.72,5],[1,1.71,60.49],[2,1.21,24.75]],"ltp":1.75,"tv":110.16,"id":61422697},{"batb":[[0,2.24,5],[1,2.22,35.2],[2,1.21,24.75]],"ltp":2.22,"tv":10.0,"id":60971788}]}]}
{"op":"mcm","clk":"11957061828","pt":1724553466435,"mc":[{"id":"1.232224255","rc":[{"batb":[[0,1.71,60.49],[1,1.21,24.75],[2,1.07,1428.57]],"ltp":1.75,"tv":110.16,"id":61422697},{"batb":[[0,2.22,35.2],[1,1.21,24.75],[2,1.07,1428.57]],"ltp":2.22,"tv":10.0,"id":60971788}]}]}
{"op":"mcm","clk":"11957062034","pt":1724553469058,"mc":[{"id":"1.232224255","rc":[{"batb":[[0,1.72,5],[1,1.71,60.49],[2,1.21,24.75]],"ltp":1.75,"tv":110.16,"id":61422697},{"batb":[[0,2.24,5],[1,2.22,35.2],[2,1.21,24.75]],"ltp":2.22,"tv":10.0,"id":60971788}]}]}
{"op":"mcm","clk":"11957062283","pt":1724553472358,"mc":[{"id":"1.232224255","rc":[{"batb":[[0,1.71,60.49],[1,1.21,24.75],[2,1.07,1428.57]],"ltp":1.75,"tv":110.16,"id":61422697},{"batb":[[0,2.22,35.2],[1,1.21,24.75],[2,1.07,1428.57]],"ltp":2.22,"tv":10.0,"id":60971788}]}]}
{"op":"mcm","clk":"11957062691","pt":1724553477877,"mc":[{"id":"1.232224255","rc":[{"batb":[[0,1.72,5],[1,1.71,60.49],[2,1.21,24.75]],"ltp":1.75,"tv":110.16,"id":61422697},{"batb":[[0,2.24,5],[1,2.22,35.2],[2,1.21,24.75]],"ltp":2.22,"tv":10.0,"id":60971788}]}]}
{"op":"mcm","clk":"11957062951","pt":1724553481169,"mc":[{"id":"1.232224255","rc":[{"batb":[[0,1.71,60.49],[1,1.21,24.75],[2,1.07,1428.57]],"ltp":1.75,"tv":110.16,"id":61422697},{"batb":[[0,2.22,35.2],[1,1.21,24.75],[2,1.07,1428.57]],"ltp":2.22,"tv":10.0,"id":60971788}]}]}
{"op":"mcm","clk":"11957063242","pt":1724553485042,"mc":[{"id":"1.232224255","rc":[{"batb":[[0,1.72,5],[1,1.71,60.49],[2,1.21,24.75]],"ltp":1.75,"tv":110.16,"id":61422697},{"batb":[[0,2.24,5],[1,2.22,35.2],[2,1.21,24.75]],"ltp":2.22,"tv":10.0,"id":60971788}]}]}
{"op":"mcm","clk":"11957063485","pt":1724553488445,"mc":[{"id":"1.232224255","rc":[{"batb":[[0,1.71,60.49],[1,1.21,24.75],[2,1.07,1428.57]],"ltp":1.75,"tv":110.16,"id":61422697},{"batb":[[0,2.22,35.2],[1,1.21,24.75],[2,1.07,1428.57]],"ltp":2.22,"tv":10.0,"id":60971788}]}]}
{"op":"mcm","clk":"11957063750","pt":1724553491559,"mc":[{"id":"1.232224255","rc":[{"batb":[[0,1.72,5],[1,1.71,60.49],[2,1.21,24.75]],"ltp":1.75,"tv":110.16,"id":61422697},{"batb":[[0,2.24,5],[1,2.22,35.2],[2,1.21,24.75]],"ltp":2.22,"tv":10.0,"id":60971788}]}]}
{"op":"mcm","clk":"11957063979","pt":1724553494855,"mc":[{"id":"1.232224255","rc":[{"batb":[[0,1.71,60.49],[1,1.21,24.75],[2,1.07,1428.57]],"ltp":1.75,"tv":110.16,"id":61422697},{"batb":[[0,2.22,35.2],[1,1.21,24.75],[2,1.07,1428.57]],"ltp":2.22,"tv":10.0,"id":60971788}]}]}
{"op":"mcm","clk":"11957064425","pt":1724553501102,"mc":[{"id":"1.232224255","rc":[{"batb":[[0,1.72,5],[1,1.71,60.49],[2,1.21,24.75]],"ltp":1.75,"tv":110.16,"id":61422697},{"batb":[[0,2.24,5],[1,2.22,35.2],[2,1.21,24.75]],"ltp":2.22,"tv":10.0,"id":60971788}]}]}
{"op":"mcm","clk":"11957064717","pt":1724553504359,"mc":[{"id":"1.232224255","rc":[{"batb":[[0,1.71,60.49],[1,1.21,24.75],[2,1.07,1428.57]],"ltp":1.75,"tv":110.16,"id":61422697},{"batb":[[0,2.22,35.2],[1,1.21,24.75],[2,1.07,1428.57]],"ltp":2.22,"tv":10.0,"id":60971788}]}]}
{"op":"mcm","clk":"11957064910","pt":1724553506994,"mc":[{"id":"1.232224255","rc":[{"batb":[[0,1.72,5],[1,1.71,60.49],[2,1.21,24.75]],"ltp":1.75,"tv":110.16,"id":61422697},{"batb":[[0,2.24,5],[1,2.22,35.2],[2,1.21,24.75]],"ltp":2.22,"tv":10.0,"id":60971788}]}]}
{"op":"mcm","clk":"11957065189","pt":1724553510291,"mc":[{"id":"1.232224255","rc":[{"batb":[[0,1.71,60.49],[1,1.21,24.75],[2,1.07,1428.57]],"ltp":1.75,"tv":110.16,"id":61422697},{"batb":[[0,2.22,35.2],[1,1.21,24.75],[2,1.07,1428.57]],"ltp":2.22,"tv":10.0,"id":60971788}]}]}
{"op":"mcm","clk":"11957065377","pt":1724553512565,"mc":[{"id":"1.232224255","rc":[{"batb":[[0,1.72,5],[1,1.71,60.49],[2,1.21,24.75]],"ltp":1.75,"tv":110.16,"id":61422697},{"batb":[[0,2.24,5],[1,2.22,35.2],[2,1.21,24.75]],"ltp":2.22,"tv":10.0,"id":60971788}]}]}
{"op":"mcm","clk":"11957065614","pt":1724553515871,"mc":[{"id":"1.232224255","rc":[{"batb":[[0,1.71,60.49],[1,1.21,24.75],[2,1.07,1428.57]],"ltp":1.75,"tv":110.16,"id":61422697}]}]}
{"op":"mcm","clk":"11957065622","pt":1724553515974,"mc":[{"id":"1.232224255","rc":[{"batb":[[0,2.22,35.2],[1,1.21,24.75],[2,1.07,1428.57]],"ltp":2.22,"tv":10.0,"id":60971788}]}]}
{"op":"mcm","clk":"11957065798","pt":1724553518302,"mc":[{"id":"1.232224255","rc":[{"batb":[[0,1.72,5],[1,1.71,60.49],[2,1.21,24.75]],"ltp":1.75,"tv":110.16,"id":61422697},{"batb":[[0,2.24,5],[1,2.22,35.2],[2,1.21,24.75]],"ltp":2.22,"tv":10.0,"id":60971788}]}]}
{"op":"mcm","clk":"11957066065","pt":1724553521592,"mc":[{"id":"1.232224255","rc":[{"batb":[[0,1.71,60.49],[1,1.21,24.75],[2,1.07,1428.57]],"ltp":1.75,"tv":110.16,"id":61422697},{"batb":[[0,2.22,35.2],[1,1.21,24.75],[2,1.07,1428.57]],"ltp":2.22,"tv":10.0,"id":60971788}]}]}
{"op":"mcm","clk":"11957066228","pt":1724553523805,"mc":[{"id":"1.232224255","rc":[{"batb":[[0,1.72,5],[1,1.71,60.49],[2,1.21,24.75]],"ltp":1.75,"tv":110.16,"id":61422697},{"batb":[[0,2.24,5],[1,2.22,35.2],[2,1.21,24.75]],"ltp":2.22,"tv":10.0,"id":60971788}]}]}
{"op":"mcm","clk":"11957066473","pt":1724553527279,"mc":[{"id":"1.232224255","rc":[{"batb":[[0,1.71,60.49],[1,1.21,24.75],[2,1.07,1428.57]],"ltp":1.75,"tv":110.16,"id":61422697},{"batb":[[0,2.22,35.2],[1,1.21,24.75],[2,1.07,1428.57]],"ltp":2.22,"tv":10.0,"id":60971788}]}]}
{"op":"mcm","clk":"11957066721","pt":1724553530601,"mc":[{"id":"1.232224255","rc":[{"batb":[[0,1.72,5],[1,1.71,60.49],[2,1.21,24.75]],"ltp":1.75,"tv":110.16,"id":61422697},{"batb":[[0,2.24,5],[1,2.22,35.2],[2,1.21,24.75]],"ltp":2.22,"tv":10.0,"id":60971788}]}]}
{"op":"mcm","clk":"11957066943","pt":1724553533900,"mc":[{"id":"1.232224255","rc":[{"batb":[[0,1.71,60.49],[1,1.21,24.75],[2,1.07,1428.57]],"ltp":1.75,"tv":110.16,"id":61422697},{"batb":[[0,2.22,35.2],[1,1.21,24.75],[2,1.07,1428.57]],"ltp":2.22,"tv":10.0,"id":60971788}]}]}
{"op":"mcm","clk":"11957067133","pt":1724553536682,"mc":[{"id":"1.232224255","rc":[{"batb":[[0,1.72,5],[1,1.71,60.49],[2,1.21,24.75]],"ltp":1.75,"tv":110.16,"id":61422697},{"batb":[[0,2.24,5],[1,2.22,35.2],[2,1.21,24.75]],"ltp":2.22,"tv":10.0,"id":60971788}]}]}
{"op":"mcm","clk":"11957067396","pt":1724553539987,"mc":[{"id":"1.232224255","rc":[{"batb":[[0,1.71,60.49],[1,1.21,24.75],[2,1.07,1428.57]],"ltp":1.75,"tv":110.16,"id":61422697},{"batb":[[0,2.22,35.2],[1,1.21,24.75],[2,1.07,1428.57]],"ltp":2.22,"tv":10.0,"id":60971788}]}]}
{"op":"mcm","clk":"11957067643","pt":1724553543096,"mc":[{"id":"1.232224255","rc":[{"batb":[[0,1.72,5],[1,1.71,60.49],[2,1.21,24.75]],"ltp":1.75,"tv":110.16,"id":61422697},{"batb":[[0,2.24,5],[1,2.22,35.2],[2,1.21,24.75]],"ltp":2.22,"tv":10.0,"id":60971788}]}]}
{"op":"mcm","clk":"11957067910","pt":1724553546504,"mc":[{"id":"1.232224255","rc":[{"batb":[[0,1.71,60.49],[1,1.21,24.75],[2,1.07,1428.57]],"ltp":1.75,"tv":110.16,"id":61422697},{"batb":[[0,2.22,35.2],[1,1.21,24.75],[2,1.07,1428.57]],"ltp":2.22,"tv":10.0,"id":60971788}]}]}
{"op":"mcm","clk":"11957068079","pt":1724553548722,"mc":[{"id":"1.232224255","rc":[{"batb":[[0,1.72,5],[1,1.71,60.49],[2,1.21,24.75]],"ltp":1.75,"tv":110.16,"id":61422697},{"batb":[[0,2.24,5],[1,2.22,35.2],[2,1.21,24.75]],"ltp":2.22,"tv":10.0,"id":60971788}]}]}
{"op":"mcm","clk":"11957068337","pt":1724553552226,"mc":[{"id":"1.232224255","rc":[{"batb":[[0,1.71,60.49],[1,1.21,24.75],[2,1.07,1428.57]],"ltp":1.75,"tv":110.16,"id":61422697},{"batb":[[0,2.22,35.2],[1,1.21,24.75],[2,1.07,1428.57]],"ltp":2.22,"tv":10.0,"id":60971788}]}]}
{"op":"mcm","clk":"11957068528","pt":1724553554625,"mc":[{"id":"1.232224255","rc":[{"batb":[[0,1.72,5],[1,1.71,60.49],[2,1.21,24.75]],"ltp":1.75,"tv":110.16,"id":61422697},{"batb":[[0,2.24,5],[1,2.22,35.2],[2,1.21,24.75]],"ltp":2.22,"tv":10.0,"id":60971788}]}]}
{"op":"mcm","clk":"11957068789","pt":1724553557903,"mc":[{"id":"1.232224255","rc":[{"batb":[[0,1.71,60.49],[1,1.21,24.75],[2,1.07,1428.57]],"ltp":1.75,"tv":110.16,"id":61422697},{"batb":[[0,2.22,35.2],[1,1.21,24.75],[2,1.07,1428.57]],"ltp":2.22,"tv":10.0,"id":60971788}]}]}
{"op":"mcm","clk":"11957069073","pt":1724553561451,"mc":[{"id":"1.232224255","rc":[{"batb":[[0,1.72,5],[1,1.71,60.49],[2,1.21,24.75]],"ltp":1.75,"tv":110.16,"id":61422697},{"batb":[[0,2.24,5],[1,2.22,35.2],[2,1.21,24.75]],"ltp":2.22,"tv":10.0,"id":60971788}]}]}
{"op":"mcm","clk":"11957069302","pt":1724553564742,"mc":[{"id":"1.232224255","rc":[{"batb":[[0,2.22,35.2],[1,1.21,24.75],[2,1.07,1428.57]],"ltp":2.22,"tv":10.0,"id":60971788}]}]}
{"op":"mcm","clk":"11957069310","pt":1724553564947,"mc":[{"id":"1.232224255","rc":[{"batb":[[0,1.71,60.49],[1,1.21,24.75],[2,1.07,1428.57]],"ltp":1.75,"tv":110.16,"id":61422697}]}]}
{"op":"mcm","clk":"11957069833","pt":1724553571365,"mc":[{"id":"1.232224255","rc":[{"batb":[[0,1.72,5],[1,1.71,60.49],[2,1.21,24.75]],"ltp":1.75,"tv":110.16,"id":61422697},{"batb":[[0,2.24,5],[1,2.22,35.2],[2,1.21,24.75]],"ltp":2.22,"tv":10.0,"id":60971788}]}]}
{"op":"mcm","clk":"11957070083","pt":1724553574561,"mc":[{"id":"1.232224255","rc":[{"batb":[[0,1.71,60.49],[1,1.21,24.75],[2,1.07,1428.57]],"ltp":1.75,"tv":110.16,"id":61422697},{"batb":[[0,2.22,35.2],[1,1.21,24.75],[2,1.07,1428.57]],"ltp":2.22,"tv":10.0,"id":60971788}]}]}
{"op":"mcm","clk":"11957070309","pt":1724553577338,"mc":[{"id":"1.232224255","rc":[{"batb":[[0,1.72,5],[1,1.71,60.49],[2,1.21,24.75]],"ltp":1.75,"tv":110.16,"id":61422697},{"batb":[[0,2.24,5],[1,2.22,35.2],[2,1.21,24.75]],"ltp":2.22,"tv":10.0,"id":60971788}]}]}
{"op":"mcm","clk":"11957070570","pt":1724553580629,"mc":[{"id":"1.232224255","rc":[{"batb":[[0,1.71,60.49],[1,1.21,24.75],[2,1.07,1428.57]],"ltp":1.75,"tv":110.16,"id":61422697},{"batb":[[0,2.22,35.2],[1,1.21,24.75],[2,1.07,1428.57]],"ltp":2.22,"tv":10.0,"id":60971788}]}]}
{"op":"mcm","clk":"11957070926","pt":1724553585870,"mc":[{"id":"1.232224255","rc":[{"batb":[[0,1.72,5],[1,1.71,60.49],[2,1.21,24.75]],"ltp":1.75,"tv":110.16,"id":61422697},{"batb":[[0,2.24,5],[1,2.22,35.2],[2,1.21,24.75]],"ltp":2.22,"tv":10.0,"id":60971788}]}]}
{"op":"mcm","clk":"11957071176","pt":1724553589164,"mc":[{"id":"1.232224255","rc":[{"batb":[[0,1.71,60.49],[1,1.21,24.75],[2,1.07,1428.57]],"ltp":1.75,"tv":110.16,"id":61422697},{"batb":[[0,2.22,35.2],[1,1.21,24.75],[2,1.07,1428.57]],"ltp":2.22,"tv":10.0,"id":60971788}]}]}
{"op":"mcm","clk":"11957071797","pt":1724553597967,"mc":[{"id":"1.232224255","rc":[{"batb":[[0,1.72,5],[1,1.71,60.49],[2,1.21,24.75]],"ltp":1.75,"tv":110.16,"id":61422697},{"batb":[[0,2.24,5],[1,2.22,35.2],[2,1.21,24.75]],"ltp":2.22,"tv":10.0,"id":60971788}]}]}
{"op":"mcm","clk":"11957072006","pt":1724553601156,"mc":[{"id":"1.232224255","rc":[{"batb":[[0,1.71,60.49],[1,1.21,24.75],[2,1.07,1428.57]],"ltp":1.75,"tv":110.16,"id":61422697},{"batb":[[0,2.22,35.2],[1,1.21,24.75],[2,1.07,1428.57]],"ltp":2.22,"tv":10.0,"id":60971788}]}]}
{"op":"mcm","clk":"11957072170","pt":1724553603678,"mc":[{"id":"1.232224255","rc":[{"batb":[[0,1.72,5],[1,1.71,60.49],[2,1.21,24.75]],"ltp":1.75,"tv":110.16,"id":61422697},{"batb":[[0,2.24,5],[1,2.22,35.2],[2,1.21,24.75]],"ltp":2.22,"tv":10.0,"id":60971788}]}]}
{"op":"mcm","clk":"11957072421","pt":1724553606975,"mc":[{"id":"1.232224255","rc":[{"batb":[[0,1.71,60.49],[1,1.21,24.75],[2,1.07,1428.57]],"ltp":1.75,"tv":110.16,"id":61422697},{"batb":[[0,2.22,35.2],[1,1.21,24.75],[2,1.07,1428.57]],"ltp":2.22,"tv":10.0,"id":60971788}]}]}
{"op":"mcm","clk":"11957072865","pt":1724553612802,"mc":[{"id":"1.232224255","rc":[{"batb":[[0,1.72,5],[1,1.71,60.49],[2,1.21,24.75]],"ltp":1.75,"tv":110.16,"id":61422697},{"batb":[[0,2.24,5],[1,2.22,35.2],[2,1.21,24.75]],"ltp":2.22,"tv":10.0,"id":60971788}]}]}
{"op":"mcm","clk":"11957073103","pt":1724553616201,"mc":[{"id":"1.232224255","rc":[{"batb":[[0,1.71,60.49],[1,1.21,24.75],[2,1.07,1428.57]],"ltp":1.75,"tv":110.16,"id":61422697},{"batb":[[0,2.22,35.2],[1,1.21,24.75],[2,1.07,1428.57]],"ltp":2.22,"tv":10.0,"id":60971788}]}]}
{"op":"mcm","clk":"11957073550","pt":1724553622010,"mc":[{"id":"1.232224255","rc":[{"batb":[[0,1.72,5],[1,1.71,60.49],[2,1.21,24.75]],"ltp":1.75,"tv":110.16,"id":61422697},{"batb":[[0,2.24,5],[1,2.22,35.2],[2,1.21,24.75]],"ltp":2.22,"tv":10.0,"id":60971788}]}]}
{"op":"mcm","clk":"11957073796","pt":1724553625206,"mc":[{"id":"1.232224255","rc":[{"batb":[[0,1.71,60.49],[1,1.21,24.75],[2,1.07,1428.57]],"ltp":1.75,"tv":110.16,"id":61422697},{"batb":[[0,2.22,35.2],[1,1.21,24.75],[2,1.07,1428.57]],"ltp":2.22,"tv":10.0,"id":60971788}]}]}
{"op":"mcm","clk":"11957074130","pt":1724553630104,"mc":[{"id":"1.232224255","rc":[{"batb":[[0,1.72,5],[1,1.71,60.49],[2,1.21,24.75]],"ltp":1.75,"tv":110.16,"id":61422697},{"batb":[[0,2.24,5],[1,2.22,35.2],[2,1.21,24.75]],"ltp":2.22,"tv":10.0,"id":60971788}]}]}
{"op":"mcm","clk":"11957074344","pt":1724553633604,"mc":[{"id":"1.232224255","rc":[{"batb":[[0,1.71,60.49],[1,1.21,24.75],[2,1.07,1428.57]],"ltp":1.75,"tv":110.16,"id":61422697},{"batb":[[0,2.22,35.2],[1,1.21,24.75],[2,1.07,1428.57]],"ltp":2.22,"tv":10.0,"id":60971788}]}]}
{"op":"mcm","clk":"11957074766","pt":1724553639742,"mc":[{"id":"1.232224255","rc":[{"batb":[[0,1.72,5],[1,1.71,60.49],[2,1.21,24.75]],"ltp":1.75,"tv":110.16,"id":61422697},{"batb":[[0,2.24,5],[1,2.22,35.2],[2,1.21,24.75]],"ltp":2.22,"tv":10.0,"id":60971788}]}]}
{"op":"mcm","clk":"11957075014","pt":1724553642932,"mc":[{"id":"1.232224255","rc":[{"batb":[[0,1.71,60.49],[1,1.21,24.75],[2,1.07,1428.57]],"ltp":1.75,"tv":110.16,"id":61422697},{"batb":[[0,2.22,35.2],[1,1.21,24.75],[2,1.07,1428.57]],"ltp":2.22,"tv":10.0,"id":60971788}]}]}
{"op":"mcm","clk":"11957075192","pt":1724553646337,"mc":[{"id":"1.232224255","rc":[{"batb":[[0,1.72,5],[1,1.71,60.49],[2,1.21,24.75]],"ltp":1.75,"tv":110.16,"id":61422697},{"batb":[[0,2.24,5],[1,2.22,35.2],[2,1.21,24.75]],"ltp":2.22,"tv":10.0,"id":60971788}]}]}
{"op":"mcm","clk":"11957075400","pt":1724553649642,"mc":[{"id":"1.232224255","rc":[{"batb":[[0,1.71,60.49],[1,1.21,24.75],[2,1.07,1428.57]],"ltp":1.75,"tv":110.16,"id":61422697},{"batb":[[0,2.22,35.2],[1,1.21,24.75],[2,1.07,1428.57]],"ltp":2.22,"tv":10.0,"id":60971788}]}]}
{"op":"mcm","clk":"11957075542","pt":1724553652169,"mc":[{"id":"1.232224255","rc":[{"batb":[[0,1.72,5],[1,1.71,60.49],[2,1.21,24.75]],"ltp":1.75,"tv":110.16,"id":61422697},{"batb":[[0,2.24,5],[1,2.22,35.2],[2,1.21,24.75]],"ltp":2.22,"tv":10.0,"id":60971788}]}]}
{"op":"mcm","clk":"11957075741","pt":1724553655420,"mc":[{"id":"1.232224255","rc":[{"batb":[[0,1.71,60.49],[1,1.21,24.75],[2,1.07,1428.57]],"ltp":1.75,"tv":110.16,"id":61422697},{"batb":[[0,2.22,35.2],[1,1.21,24.75],[2,1.07,1428.57]],"ltp":2.22,"tv":10.0,"id":60971788}]}]}
{"op":"mcm","clk":"11957075928","pt":1724553658361,"mc":[{"id":"1.232224255","rc":[{"batb":[[0,1.72,5],[1,1.71,60.49],[2,1.21,24.75]],"ltp":1.75,"tv":110.16,"id":61422697},{"batb":[[0,2.24,5],[1,2.22,35.2],[2,1.21,24.75]],"ltp":2.22,"tv":10.0,"id":60971788}]}]}
{"op":"mcm","clk":"11957076225","pt":1724553663154,"mc":[{"id":"1.232224255","rc":[{"batb":[[0,1.71,60.49],[1,1.21,24.75],[2,1.07,1428.57]],"ltp":1.75,"tv":110.16,"id":61422697},{"batb":[[0,2.22,35.2],[1,1.21,24.75],[2,1.07,1428.57]],"ltp":2.22,"tv":10.0,"id":60971788}]}]}
{"op":"mcm","clk":"11957076450","pt":1724553666759,"mc":[{"id":"1.232224255","rc":[{"batb":[[0,1.72,5],[1,1.71,60.49],[2,1.21,24.75]],"ltp":1.75,"tv":110.16,"id":61422697},{"batb":[[0,2.24,5],[1,2.22,35.2],[2,1.21,24.75]],"ltp":2.22,"tv":10.0,"id":60971788}]}]}
{"op":"mcm","clk":"11957076651","pt":1724553670059,"mc":[{"id":"1.232224255","rc":[{"batb":[[0,1.71,60.49],[1,1.21,24.75],[2,1.07,1428.57]],"ltp":1.75,"tv":110.16,"id":61422697},{"batb":[[0,2.22,35.2],[1,1.21,24.75],[2,1.07,1428.57]],"ltp":2.22,"tv":10.0,"id":60971788}]}]}
{"op":"mcm","clk":"11957076827","pt":1724553672375,"mc":[{"id":"1.232224255","rc":[{"batb":[[0,1.72,5],[1,1.71,60.49],[2,1.21,24.75]],"ltp":1.75,"tv":110.16,"id":61422697},{"batb":[[0,2.24,5],[1,2.22,35.2],[2,1.21,24.75]],"ltp":2.22,"tv":10.0,"id":60971788}]}]}
{"op":"mcm","clk":"11957077027","pt":1724553675776,"mc":[{"id":"1.232224255","rc":[{"batb":[[0,1.71,60.49],[1,1.21,24.75],[2,1.07,1428.57]],"ltp":1.75,"tv":110.16,"id":61422697},{"batb":[[0,2.22,35.2],[1,1.21,24.75],[2,1.07,1428.57]],"ltp":2.22,"tv":10.0,"id":60971788}]}]}
{"op":"mcm","clk":"11957077321","pt":1724553680675,"mc":[{"id":"1.232224255","rc":[{"batb":[[0,1.72,5],[1,1.71,60.49],[2,1.21,24.75]],"ltp":1.75,"tv":110.16,"id":61422697},{"batb":[[0,2.24,5],[1,2.22,35.2],[2,1.21,24.75]],"ltp":2.22,"tv":10.0,"id":60971788}]}]}
{"op":"mcm","clk":"11957077513","pt":1724553683969,"mc":[{"id":"1.232224255","rc":[{"batb":[[0,1.71,60.49],[1,1.21,24.75],[2,1.07,1428.57]],"ltp":1.75,"tv":110.16,"id":61422697},{"batb":[[0,2.22,35.2],[1,1.21,24.75],[2,1.07,1428.57]],"ltp":2.22,"tv":10.0,"id":60971788}]}]}
{"op":"mcm","clk":"11957077633","pt":1724553686282,"mc":[{"id":"1.232224255","rc":[{"batb":[[0,1.72,5],[1,1.71,60.49],[2,1.21,24.75]],"ltp":1.75,"tv":110.16,"id":61422697},{"batb":[[0,2.24,5],[1,2.22,35.2],[2,1.21,24.75]],"ltp":2.22,"tv":10.0,"id":60971788}]}]}
{"op":"mcm","clk":"11957077833","pt":1724553689899,"mc":[{"id":"1.232224255","rc":[{"batb":[[0,1.71,60.49],[1,1.21,24.75],[2,1.07,1428.57]],"ltp":1.75,"tv":110.16,"id":61422697},{"batb":[[0,2.22,35.2],[1,1.21,24.75],[2,1.07,1428.57]],"ltp":2.22,"tv":10.0,"id":60971788}]}]}
{"op":"mcm","clk":"11957078199","pt":1724553695616,"mc":[{"id":"1.232224255","rc":[{"batb":[[0,1.72,5],[1,1.71,60.49],[2,1.21,24.75]],"ltp":1.75,"tv":110.16,"id":61422697},{"batb":[[0,2.24,5],[1,2.22,35.2],[2,1.21,24.75]],"ltp":2.22,"tv":10.0,"id":60971788}]}]}
{"op":"mcm","clk":"11957078418","pt":1724553698916,"mc":[{"id":"1.232224255","rc":[{"batb":[[0,1.71,60.49],[1,1.21,24.75],[2,1.07,1428.57]],"ltp":1.75,"tv":110.16,"id":61422697},{"batb":[[0,2.22,35.2],[1,1.21,24.75],[2,1.07,1428.57]],"ltp":2.22,"tv":10.0,"id":60971788}]}]}
{"op":"mcm","clk":"11957078796","pt":1724553704703,"mc":[{"id":"1.232224255","rc":[{"batb":[[0,1.72,5],[1,1.71,60.49],[2,1.21,24.75]],"ltp":1.75,"tv":110.16,"id":61422697},{"batb":[[0,2.24,5],[1,2.22,35.2],[2,1.21,24.75]],"ltp":2.22,"tv":10.0,"id":60971788}]}]}
{"op":"mcm","clk":"11957078981","pt":1724553707999,"mc":[{"id":"1.232224255","rc":[{"batb":[[0,1.71,60.49],[1,1.21,24.75],[2,1.07,1428.57]],"ltp":1.75,"tv":110.16,"id":61422697},{"batb":[[0,2.22,35.2],[1,1.21,24.75],[2,1.07,1428.57]],"ltp":2.22,"tv":10.0,"id":60971788}]}]}
{"op":"mcm","clk":"11957079165","pt":1724553710991,"mc":[{"id":"1.232224255","rc":[{"batb":[[0,1.72,5],[1,1.71,60.49],[2,1.21,24.75]],"ltp":1.75,"tv":110.16,"id":61422697},{"batb":[[0,2.24,5],[1,2.22,35.2],[2,1.21,24.75]],"ltp":2.22,"tv":10.0,"id":60971788}]}]}
{"op":"mcm","clk":"11957079350","pt":1724553714212,"mc":[{"id":"1.232224255","rc":[{"batb":[[0,1.71,60.49],[1,1.21,24.75],[2,1.07,1428.57]],"ltp":1.75,"tv":110.16,"id":61422697},{"batb":[[0,2.22,35.2],[1,1.21,24.75],[2,1.07,1428.57]],"ltp":2.22,"tv":10.0,"id":60971788}]}]}
{"op":"mcm","clk":"11957079607","pt":1724553718897,"mc":[{"id":"1.232224255","rc":[{"batb":[[0,1.72,5],[1,1.71,60.49],[2,1.21,24.75]],"ltp":1.75,"tv":110.16,"id":61422697},{"batb":[[0,2.24,5],[1,2.22,35.2],[2,1.21,24.75]],"ltp":2.22,"tv":10.0,"id":60971788}]}]}
{"op":"mcm","clk":"11957079776","pt":1724553722223,"mc":[{"id":"1.232224255","rc":[{"batb":[[0,1.71,60.49],[1,1.21,24.75],[2,1.07,1428.57]],"ltp":1.75,"tv":110.16,"id":61422697},{"batb":[[0,2.22,35.2],[1,1.21,24.75],[2,1.07,1428.57]],"ltp":2.22,"tv":10.0,"id":60971788}]}]}
{"op":"mcm","clk":"11957080291","pt":1724553731137,"mc":[{"id":"1.232224255","rc":[{"batb":[[0,1.72,5],[1,1.71,60.49],[2,1.21,24.75]],"ltp":1.75,"tv":110.16,"id":61422697},{"batb":[[0,2.24,5],[1,2.22,35.2],[2,1.21,24.75]],"ltp":2.22,"tv":10.0,"id":60971788}]}]}
{"op":"mcm","clk":"11957080506","pt":1724553734441,"mc":[{"id":"1.232224255","rc":[{"batb":[[0,1.71,60.49],[1,1.21,24.75],[2,1.07,1428.57]],"ltp":1.75,"tv":110.16,"id":61422697},{"batb":[[0,2.22,35.2],[1,1.21,24.75],[2,1.07,1428.57]],"ltp":2.22,"tv":10.0,"id":60971788}]}]}
{"op":"mcm","clk":"11957081087","pt":1724553743541,"mc":[{"id":"1.232224255","rc":[{"batb":[[0,1.72,5],[1,1.71,60.49],[2,1.21,24.75]],"ltp":1.75,"tv":110.16,"id":61422697},{"batb":[[0,2.24,5],[1,2.22,35.2],[2,1.21,24.75]],"ltp":2.22,"tv":10.0,"id":60971788}]}]}
{"op":"mcm","clk":"11957081291","pt":1724553746851,"mc":[{"id":"1.232224255","rc":[{"batb":[[0,1.71,60.49],[1,1.21,24.75],[2,1.07,1428.57]],"ltp":1.75,"tv":110.16,"id":61422697},{"batb":[[0,2.22,35.2],[1,1.21,24.75],[2,1.07,1428.57]],"ltp":2.22,"tv":10.0,"id":60971788}]}]}
{"op":"mcm","clk":"11957082109","pt":1724553758766,"mc":[{"id":"1.232224255","rc":[{"batb":[[0,1.72,5],[1,1.71,60.49],[2,1.21,24.75]],"ltp":1.75,"tv":110.16,"id":61422697},{"batb":[[0,2.24,5],[1,2.22,35.2],[2,1.21,24.75]],"ltp":2.22,"tv":10.0,"id":60971788}]}]}
{"op":"mcm","clk":"11957082333","pt":1724553762271,"mc":[{"id":"1.232224255","rc":[{"batb":[[0,1.71,60.49],[1,1.21,24.75],[2,1.07,1428.57]],"ltp":1.75,"tv":110.16,"id":61422697},{"batb":[[0,2.22,35.2],[1,1.21,24.75],[2,1.07,1428.57]],"ltp":2.22,"tv":10.0,"id":60971788}]}]}
{"op":"mcm","clk":"11957082523","pt":1724553765264,"mc":[{"id":"1.232224255","rc":[{"batb":[[0,1.72,5],[1,1.71,60.49],[2,1.21,24.75]],"ltp":1.75,"tv":110.16,"id":61422697},{"batb":[[0,2.24,5],[1,2.22,35.2],[2,1.21,24.75]],"ltp":2.22,"tv":10.0,"id":60971788}]}]}
{"op":"mcm","clk":"11957082703","pt":1724553768471,"mc":[{"id":"1.232224255","rc":[{"batb":[[0,1.71,60.49],[1,1.21,24.75],[2,1.07,1428.57]],"ltp":1.75,"tv":110.16,"id":61422697},{"batb":[[0,2.22,35.2],[1,1.21,24.75],[2,1.07,1428.57]],"ltp":2.22,"tv":10.0,"id":60971788}]}]}
{"op":"mcm","clk":"11957083053","pt":1724553773796,"mc":[{"id":"1.232224255","rc":[{"batb":[[0,1.72,5],[1,1.71,60.49],[2,1.21,24.75]],"ltp":1.75,"tv":110.16,"id":61422697},{"batb":[[0,2.24,5],[1,2.22,35.2],[2,1.21,24.75]],"ltp":2.22,"tv":10.0,"id":60971788}]}]}
{"op":"mcm","clk":"11957083271","pt":1724553777194,"mc":[{"id":"1.232224255","rc":[{"batb":[[0,1.71,60.49],[1,1.21,24.75],[2,1.07,1428.57]],"ltp":1.75,"tv":110.16,"id":61422697},{"batb":[[0,2.22,35.2],[1,1.21,24.75],[2,1.07,1428.57]],"ltp":2.22,"tv":10.0,"id":60971788}]}]}
{"op":"mcm","clk":"11957083508","pt":1724553781374,"mc":[{"id":"1.232224255","rc":[{"batb":[[0,1.72,5],[1,1.71,60.49],[2,1.21,24.75]],"ltp":1.75,"tv":110.16,"id":61422697},{"batb":[[0,2.24,5],[1,2.22,35.2],[2,1.21,24.75]],"ltp":2.22,"tv":10.0,"id":60971788}]}]}
{"op":"mcm","clk":"11957083729","pt":1724553784681,"mc":[{"id":"1.232224255","rc":[{"batb":[[0,1.71,60.49],[1,1.21,24.75],[2,1.07,1428.57]],"ltp":1.75,"tv":110.16,"id":61422697},{"batb":[[0,2.22,35.2],[1,1.21,24.75],[2,1.07,1428.57]],"ltp":2.22,"tv":10.0,"id":60971788}]}]}
{"op":"mcm","clk":"11957083911","pt":1724553787486,"mc":[{"id":"1.232224255","rc":[{"batb":[[0,1.72,5],[1,1.71,60.49],[2,1.21,24.75]],"ltp":1.75,"tv":110.16,"id":61422697},{"batb":[[0,2.24,5],[1,2.22,35.2],[2,1.21,24.75]],"ltp":2.22,"tv":10.0,"id":60971788}]}]}
{"op":"mcm","clk":"11957084174","pt":1724553790899,"mc":[{"id":"1.232224255","rc":[{"batb":[[0,1.71,60.49],[1,1.21,24.75],[2,1.07,1428.57]],"ltp":1.75,"tv":110.16,"id":61422697},{"batb":[[0,2.22,35.2],[1,1.21,24.75],[2,1.07,1428.57]],"ltp":2.22,"tv":10.0,"id":60971788}]}]}
{"op":"mcm","clk":"11957084439","pt":1724553794723,"mc":[{"id":"1.232224255","rc":[{"batb":[[0,1.72,5],[1,1.71,60.49],[2,1.21,24.75]],"ltp":1.75,"tv":110.16,"id":61422697},{"batb":[[0,2.24,5],[1,2.22,35.2],[2,1.21,24.75]],"ltp":2.22,"tv":10.0,"id":60971788}]}]}
{"op":"mcm","clk":"11957084672","pt":1724553797986,"mc":[{"id":"1.232224255","rc":[{"batb":[[0,1.71,60.49],[1,1.21,24.75],[2,1.07,1428.57]],"ltp":1.75,"tv":110.16,"id":61422697},{"batb":[[0,2.22,35.2],[1,1.21,24.75],[2,1.07,1428.57]],"ltp":2.22,"tv":10.0,"id":60971788}]}]}
{"op":"mcm","clk":"11957084968","pt":1724553802103,"mc":[{"id":"1.232224255","rc":[{"batb":[[0,1.72,5],[1,1.71,60.49],[2,1.21,24.75]],"ltp":1.75,"tv":110.16,"id":61422697},{"batb":[[0,2.24,5],[1,2.22,35.2],[2,1.21,24.75]],"ltp":2.22,"tv":10.0,"id":60971788}]}]}
{"op":"mcm","clk":"11957085204","pt":1724553805525,"mc":[{"id":"1.232224255","rc":[{"batb":[[0,1.71,60.49],[1,1.21,24.75],[2,1.07,1428.57]],"ltp":1.75,"tv":110.16,"id":61422697},{"batb":[[0,2.22,35.2],[1,1.21,24.75],[2,1.07,1428.57]],"ltp":2.22,"tv":10.0,"id":60971788}]}]}
{"op":"mcm","clk":"11957085399","pt":1724553808107,"mc":[{"id":"1.232224255","rc":[{"batb":[[0,1.72,5],[1,1.71,60.49],[2,1.21,24.75]],"ltp":1.75,"tv":110.16,"id":61422697},{"batb":[[0,2.24,5],[1,2.22,35.2],[2,1.21,24.75]],"ltp":2.22,"tv":10.0,"id":60971788}]}]}
{"op":"mcm","clk":"11957085612","pt":1724553811444,"mc":[{"id":"1.232224255","rc":[{"batb":[[0,1.71,60.49],[1,1.21,24.75],[2,1.07,1428.57]],"ltp":1.75,"tv":110.16,"id":61422697},{"batb":[[0,2.22,35.2],[1,1.21,24.75],[2,1.07,1428.57]],"ltp":2.22,"tv":10.0,"id":60971788}]}]}
{"op":"mcm","clk":"11957085953","pt":1724553816241,"mc":[{"id":"1.232224255","rc":[{"batb":[[0,1.72,5],[1,1.71,60.49],[2,1.21,24.75]],"ltp":1.75,"tv":110.16,"id":61422697},{"batb":[[0,2.24,5],[1,2.22,35.2],[2,1.21,24.75]],"ltp":2.22,"tv":10.0,"id":60971788}]}]}
{"op":"mcm","clk":"11957086195","pt":1724553819532,"mc":[{"id":"1.232224255","rc":[{"batb":[[0,1.71,60.49],[1,1.21,24.75],[2,1.07,1428.57]],"ltp":1.75,"tv":110.16,"id":61422697},{"batb":[[0,2.22,35.2],[1,1.21,24.75],[2,1.07,1428.57]],"ltp":2.22,"tv":10.0,"id":60971788}]}]}
{"op":"mcm","clk":"11957086361","pt":1724553822160,"mc":[{"id":"1.232224255","rc":[{"batb":[[0,1.72,5],[1,1.71,60.49],[2,1.21,24.75]],"ltp":1.75,"tv":110.16,"id":61422697},{"batb":[[0,2.24,5],[1,2.22,35.2],[2,1.21,24.75]],"ltp":2.22,"tv":10.0,"id":60971788}]}]}
{"op":"mcm","clk":"11957086570","pt":1724553825352,"mc":[{"id":"1.232224255","rc":[{"batb":[[0,1.71,60.49],[1,1.21,24.75],[2,1.07,1428.57]],"ltp":1.75,"tv":110.16,"id":61422697},{"batb":[[0,2.22,35.2],[1,1.21,24.75],[2,1.07,1428.57]],"ltp":2.22,"tv":10.0,"id":60971788}]}]}
{"op":"mcm","clk":"11957086805","pt":1724553829158,"mc":[{"id":"1.232224255","rc":[{"batb":[[0,1.72,5],[1,1.71,60.49],[2,1.21,24.75]],"ltp":1.75,"tv":110.16,"id":61422697},{"batb":[[0,2.24,5],[1,2.22,35.2],[2,1.21,24.75]],"ltp":2.22,"tv":10.0,"id":60971788}]}]}
{"op":"mcm","clk":"11957087015","pt":1724553832762,"mc":[{"id":"1.232224255","rc":[{"batb":[[0,1.71,60.49],[1,1.21,24.75],[2,1.07,1428.57]],"ltp":1.75,"tv":110.16,"id":61422697},{"batb":[[0,2.22,35.2],[1,1.21,24.75],[2,1.07,1428.57]],"ltp":2.22,"tv":10.0,"id":60971788}]}]}
{"op":"mcm","clk":"11957087455","pt":1724553839150,"mc":[{"id":"1.232224255","rc":[{"batb":[[0,1.72,5],[1,1.71,60.49],[2,1.21,24.75]],"ltp":1.75,"tv":110.16,"id":61422697},{"batb":[[0,2.24,5],[1,2.22,35.2],[2,1.21,24.75]],"ltp":2.22,"tv":10.0,"id":60971788}]}]}
{"op":"mcm","clk":"11957087723","pt":1724553842750,"mc":[{"id":"1.232224255","rc":[{"batb":[[0,1.71,60.49],[1,1.21,24.75],[2,1.07,1428.57]],"ltp":1.75,"tv":110.16,"id":61422697},{"batb":[[0,2.22,35.2],[1,1.21,24.75],[2,1.07,1428.57]],"ltp":2.22,"tv":10.0,"id":60971788}]}]}
{"op":"mcm","clk":"11957088320","pt":1724553850469,"mc":[{"id":"1.232224255","rc":[{"batb":[[0,1.72,5],[1,1.71,60.49],[2,1.21,24.75]],"ltp":1.75,"tv":110.16,"id":61422697},{"batb":[[0,2.24,5],[1,2.22,35.2],[2,1.21,24.75]],"ltp":2.22,"tv":10.0,"id":60971788}]}]}
{"op":"mcm","clk":"11957088560","pt":1724553853774,"mc":[{"id":"1.232224255","rc":[{"batb":[[0,1.71,60.49],[1,1.21,24.75],[2,1.07,1428.57]],"ltp":1.75,"tv":110.16,"id":61422697},{"batb":[[0,2.22,35.2],[1,1.21,24.75],[2,1.07,1428.57]],"ltp":2.22,"tv":10.0,"id":60971788}]}]}
{"op":"mcm","clk":"11957089173","pt":1724553862804,"mc":[{"id":"1.232224255","rc":[{"batb":[[0,1.72,5],[1,1.71,60.49],[2,1.21,24.75]],"ltp":1.75,"tv":110.16,"id":61422697},{"batb":[[0,2.24,5],[1,2.22,35.2],[2,1.21,24.75]],"ltp":2.22,"tv":10.0,"id":60971788}]}]}
