{"op":"mcm","clk":"11883624996","pt":1724070057707,"mc":[{"id":"1.232013126","marketDefinition":{"bspMarket":false,"turnInPlayEnabled":true,"persistenceEnabled":true,"marketBaseRate":5.0,"eventId":"33508015","eventTypeId":"4","numberOfWinners":1,"bettingType":"ODDS","marketType":"MATCH_ODDS","marketTime":"2024-08-26T09:30:00.000Z","suspendTime":"2024-08-26T09:30:00.000Z","bspReconciled":false,"complete":true,"inPlay":false,"crossMatching":false,"runnersVoidable":false,"numberOfActiveRunners":2,"betDelay":0,"status":"OPEN","runners":[{"status":"ACTIVE","sortPriority":1,"id":11445383,"name":"Western Storm"},{"status":"ACTIVE","sortPriority":2,"id":35736915,"name":"Central Sparks"}],"regulators":["MR_INT"],"countryCode":"GB","discountAllowed":false,"timezone":"GMT","openDate":"2024-08-26T09:30:00.000Z","version":6086372023,"name":"Match Odds","eventName":"Western Storm v Central Sparks"},"rc":[{"batb":[[0,1.03,200],[1,1.02,200],[2,1.01,220]],"ltp":0.0,"tv":0.0,"id":35736915},{"batb":[[0,1.03,200],[1,1.02,200],[2,1.01,220]],"ltp":0.0,"tv":0.0,"id":11445383}]}]}
{"op":"mcm","clk":"11883625104","pt":1724070060550,"mc":[{"id":"1.232013126","marketDefinition":{"bspMarket":false,"turnInPlayEnabled":true,"persistenceEnabled":true,"marketBaseRate":5.0,"eventId":"33508015","eventTypeId":"4","numberOfWinners":1,"bettingType":"ODDS","marketType":"MATCH_ODDS","marketTime":"2024-08-26T09:30:00.000Z","suspendTime":"2024-08-26T09:30:00.000Z","bspReconciled":false,"complete":true,"inPlay":false,"crossMatching":false,"runnersVoidable":false,"numberOfActiveRunners":2,"betDelay":0,"status":"OPEN","runners":[{"status":"ACTIVE","sortPriority":1,"id":11445383,"name":"Western Storm"},{"status":"ACTIVE","sortPriority":2,"id":35736915,"name":"Central Sparks"}],"regulators":["MR_INT"],"countryCode":"GB","discountAllowed":true,"timezone":"GMT","openDate":"2024-08-26T09:30:00.000Z","version":6086372023,"name":"Match Odds","eventName":"Western Storm v Central Sparks"}}]}
{"op":"mcm","clk":"11883669435","pt":1724071058092,"mc":[{"id":"1.232013126","rc":[{"batb":[[2,1.01,221.11]],"ltp":0.0,"tv":0.0,"id":11445383}]}]}
{"op":"mcm","clk":"11883743350","pt":1724073030163,"mc":[{"id":"1.232013126","rc":[{"batb":[[0,1.2,250],[1,1.03,200],[2,1.02,200]],"ltp":0.0,"tv":0.0,"id":35736915},{"batb":[[0,1.2,250],[1,1.03,200],[2,1.02,200]],"ltp":0.0,"tv":0.0,"id":11445383}]}]}
{"op":"mcm","clk":"11883743632","pt":1724073038070,"mc":[{"id":"1.232013126","marketDefinition":{"bspMarket":false,"turnInPlayEnabled":true,"persistenceEnabled":true,"marketBaseRate":5.0,"eventId":"33508015","eventTypeId":"4","numberOfWinners":1,"bettingType":"ODDS","marketType":"MATCH_ODDS","marketTime":"2024-08-26T09:30:00.000Z","suspendTime":"2024-08-26T09:30:00.000Z","bspReconciled":false,"complete":true,"inPlay":false,"crossMatching":true,"runnersVoidable":false,"numberOfActiveRunners":2,"betDelay":0,"status":"OPEN","runners":[{"status":"ACTIVE","sortPriority":1,"id":11445383,"name":"Western Storm"},{"status":"ACTIVE","sortPriority":2,"id":35736915,"name":"Central Sparks"}],"regulators":["MR_INT"],"countryCode":"GB","discountAllowed":true,"timezone":"GMT","openDate":"2024-08-26T09:30:00.000Z","version":6086372023,"name":"Match Odds","eventName":"Western Storm v Central Sparks"}}]}
{"op":"mcm","clk":"11883754493","pt":1724073411494,"mc":[{"id":"1.232013126","rc":[{"batb":[[0,1.21,6.4],[1,1.2,250],[2,1.03,200]],"ltp":0.0,"tv":0.0,"id":35736915},{"batb":[[0,1.21,7.2],[1,1.2,250],[2,1.03,200]],"ltp":0.0,"tv":0.0,"id":11445383}]}]}
{"op":"mcm","clk":"11884052524","pt":1724080375037,"mc":[{"id":"1.232013126","rc":[{"batb":[[0,1.21,6.38]],"ltp":0.0,"tv":0.0,"id":35736915},{"batb":[[0,1.21,7.18]],"ltp":0.0,"tv":0.0,"id":11445383}]}]}
{"op":"mcm","clk":"11884467287","pt":1724085775026,"mc":[{"id":"1.232013126","rc":[{"batb":[[0,1.21,6.39]],"ltp":0.0,"tv":0.0,"id":35736915},{"batb":[[0,1.21,7.19]],"ltp":0.0,"tv":0.0,"id":11445383}]}]}
{"op":"mcm","clk":"11885006407","pt":1724091175028,"mc":[{"id":"1.232013126","rc":[{"batb":[[0,1.21,6.38]],"ltp":0.0,"tv":0.0,"id":35736915},{"batb":[[0,1.21,7.18]],"ltp":0.0,"tv":0.0,"id":11445383}]}]}
{"op":"mcm","clk":"11885623547","pt":1724096575051,"mc":[{"id":"1.232013126","rc":[{"batb":[[0,1.21,6.38]],"ltp":0.0,"tv":0.0,"id":35736915},{"batb":[[0,1.21,7.18]],"ltp":0.0,"tv":0.0,"id":11445383}]}]}
{"op":"mcm","clk":"11885817105","pt":1724098897964,"mc":[{"id":"1.232013126","rc":[{"batb":[[0,1.21,7.18]],"ltp":0.0,"tv":0.0,"id":11445383}]}]}
{"op":"mcm","clk":"11886253231","pt":1724107375150,"mc":[{"id":"1.232013126","rc":[{"batb":[[0,1.21,7.18]],"ltp":0.0,"tv":0.0,"id":11445383}]}]}
{"op":"mcm","clk":"11886485555","pt":1724112775101,"mc":[{"id":"1.232013126","rc":[{"batb":[[0,1.21,6.38]],"ltp":0.0,"tv":0.0,"id":35736915},{"batb":[[0,1.21,7.18]],"ltp":0.0,"tv":0.0,"id":11445383}]}]}
{"op":"mcm","clk":"11886926008","pt":1724123575164,"mc":[{"id":"1.232013126","rc":[{"batb":[[0,1.21,6.39]],"ltp":0.0,"tv":0.0,"id":35736915},{"batb":[[0,1.21,7.19]],"ltp":0.0,"tv":0.0,"id":11445383}]}]}
{"op":"mcm","clk":"11887115878","pt":1724129287502,"mc":[{"id":"1.232013126","rc":[{"batb":[[0,1.22,38.99],[1,1.21,6.39],[2,1.2,250]],"ltp":0.0,"tv":0.0,"id":35736915},{"batb":[[0,1.22,38.99],[1,1.21,7.19],[2,1.2,250]],"ltp":0.0,"tv":0.0,"id":11445383}]}]}
{"op":"mcm","clk":"11887184627","pt":1724131088387,"mc":[{"id":"1.232013126","rc":[{"batb":[[0,1.21,6.39],[1,1.2,250],[2,1.03,200]],"ltp":0.0,"tv":0.0,"id":35736915},{"batb":[[0,1.21,7.19],[1,1.2,250],[2,1.03,200]],"ltp":0.0,"tv":0.0,"id":11445383}]}]}
{"op":"mcm","clk":"11887188278","pt":1724131154636,"mc":[{"id":"1.232013126","rc":[{"batb":[[0,1.22,38.99],[1,1.21,6.39],[2,1.2,250]],"ltp":0.0,"tv":0.0,"id":35736915},{"batb":[[0,1.22,38.99],[1,1.21,7.19],[2,1.2,250]],"ltp":0.0,"tv":0.0,"id":11445383}]}]}
{"op":"mcm","clk":"11887201400","pt":1724131423491,"mc":[{"id":"1.232013126","rc":[{"batb":[[1,1.2,250],[2,1.03,200]],"ltp":0.0,"tv":0.0,"id":11445383}]}]}
{"op":"mcm","clk":"11887201424","pt":1724131424053,"mc":[{"id":"1.232013126","rc":[{"batb":[[0,1.23,6.39],[1,1.22,38.99]],"ltp":0.0,"tv":0.0,"id":35736915},{"batb":[[0,1.23,7.19],[1,1.22,38.99],[2,1.2,250]],"ltp":0.0,"tv":0.0,"id":11445383}]}]}
{"op":"mcm","clk":"11887252514","pt":1724132955445,"mc":[{"id":"1.232013126","rc":[{"batb":[[1,1.2,250],[2,1.03,200]],"ltp":0.0,"tv":0.0,"id":11445383}]}]}
{"op":"mcm","clk":"11887252522","pt":1724132955651,"mc":[{"id":"1.232013126","rc":[{"batb":[[1,1.2,250],[2,1.03,200]],"ltp":0.0,"tv":0.0,"id":35736915}]}]}
{"op":"mcm","clk":"11887254593","pt":1724133021386,"mc":[{"id":"1.232013126","rc":[{"batb":[[0,1.24,35.74],[1,1.23,6.39],[2,1.2,250]],"ltp":0.0,"tv":0.0,"id":35736915},{"batb":[[0,1.24,35.74],[1,1.23,7.19],[2,1.2,250]],"ltp":0.0,"tv":0.0,"id":11445383}]}]}
{"op":"mcm","clk":"11887283763","pt":1724133705283,"mc":[{"id":"1.232013126","rc":[{"batb":[[0,1.25,6.39],[1,1.24,35.73]],"ltp":0.0,"tv":0.0,"id":35736915},{"batb":[[0,1.25,7.19],[1,1.24,35.73]],"ltp":0.0,"tv":0.0,"id":11445383}]}]}
{"op":"mcm","clk":"11887334271","pt":1724134823012,"mc":[{"id":"1.232013126","rc":[{"batb":[[1,1.2,250],[2,1.03,200]],"ltp":0.0,"tv":0.0,"id":35736915},{"batb":[[1,1.2,250],[2,1.03,200]],"ltp":0.0,"tv":0.0,"id":11445383}]}]}
{"op":"mcm","clk":"11887336389","pt":1724134887087,"mc":[{"id":"1.232013126","rc":[{"batb":[[0,1.26,32.98],[1,1.25,6.39],[2,1.2,250]],"ltp":0.0,"tv":0.0,"id":35736915},{"batb":[[0,1.26,32.98],[1,1.25,7.19],[2,1.2,250]],"ltp":0.0,"tv":0.0,"id":11445383}]}]}
{"op":"mcm","clk":"11887382636","pt":1724136015404,"mc":[{"id":"1.232013126","rc":[{"batb":[[0,1.27,7.19],[1,1.26,32.98]],"ltp":0.0,"tv":0.0,"id":11445383}]}]}
{"op":"mcm","clk":"11887382664","pt":1724136015867,"mc":[{"id":"1.232013126","rc":[{"batb":[[0,1.27,6.39],[1,1.26,32.98]],"ltp":0.0,"tv":0.0,"id":35736915}]}]}
{"op":"mcm","clk":"11887409174","pt":1724136687815,"mc":[{"id":"1.232013126","rc":[{"batb":[[1,1.2,250],[2,1.03,200]],"ltp":0.0,"tv":0.0,"id":35736915},{"batb":[[1,1.2,250],[2,1.03,200]],"ltp":0.0,"tv":0.0,"id":11445383}]}]}
{"op":"mcm","clk":"11887411066","pt":1724136751294,"mc":[{"id":"1.232013126","rc":[{"batb":[[0,1.28,30.63],[1,1.27,6.39],[2,1.2,250]],"ltp":0.0,"tv":0.0,"id":35736915},{"batb":[[0,1.28,30.63],[1,1.27,7.19],[2,1.2,250]],"ltp":0.0,"tv":0.0,"id":11445383}]}]}
{"op":"mcm","clk":"11887487169","pt":1724138552512,"mc":[{"id":"1.232013126","rc":[{"batb":[[0,1.27,6.38],[1,1.2,250],[2,1.03,200]],"ltp":0.0,"tv":0.0,"id":35736915},{"batb":[[0,1.27,7.18],[1,1.2,250],[2,1.03,200]],"ltp":0.0,"tv":0.0,"id":11445383}]}]}
{"op":"mcm","clk":"11887489759","pt":1724138614085,"mc":[{"id":"1.232013126","rc":[{"batb":[[0,1.28,30.61],[1,1.27,6.38],[2,1.2,250]],"ltp":0.0,"tv":0.0,"id":35736915},{"batb":[[0,1.28,30.61],[1,1.27,7.18],[2,1.2,250]],"ltp":0.0,"tv":0.0,"id":11445383}]}]}
{"op":"mcm","clk":"11887571976","pt":1724140414810,"mc":[{"id":"1.232013126","rc":[{"batb":[[0,1.27,6.38],[1,1.2,250],[2,1.03,200]],"ltp":0.0,"tv":0.0,"id":35736915},{"batb":[[0,1.27,7.18],[1,1.2,250],[2,1.03,200]],"ltp":0.0,"tv":0.0,"id":11445383}]}]}
{"op":"mcm","clk":"11887574548","pt":1724140477965,"mc":[{"id":"1.232013126","rc":[{"batb":[[0,1.28,30.61],[1,1.27,6.38],[2,1.2,250]],"ltp":0.0,"tv":0.0,"id":35736915},{"batb":[[0,1.28,30.61],[1,1.27,7.18],[2,1.2,250]],"ltp":0.0,"tv":0.0,"id":11445383}]}]}
{"op":"mcm","clk":"11887576501","pt":1724140523519,"mc":[{"id":"1.232013126","rc":[{"batb":[[0,1.28,31.15]],"ltp":0.0,"tv":0.0,"id":11445383}]}]}
{"op":"mcm","clk":"11887576794","pt":1724140532414,"mc":[{"id":"1.232013126","rc":[{"batb":[[0,1.28,31.15]],"ltp":0.0,"tv":0.0,"id":35736915}]}]}
{"op":"mcm","clk":"11887661048","pt":1724142278923,"mc":[{"id":"1.232013126","rc":[{"batb":[[0,1.27,6.91],[1,1.2,250],[2,1.03,200]],"ltp":0.0,"tv":0.0,"id":35736915},{"batb":[[0,1.27,7.71],[1,1.2,250],[2,1.03,200]],"ltp":0.0,"tv":0.0,"id":11445383}]}]}
{"op":"mcm","clk":"11887667387","pt":1724142402263,"mc":[{"id":"1.232013126","rc":[{"batb":[[0,1.28,31.14],[1,1.27,6.38],[2,1.2,250]],"ltp":0.0,"tv":0.0,"id":35736915},{"batb":[[0,1.28,31.14],[1,1.27,7.18],[2,1.2,250]],"ltp":0.0,"tv":0.0,"id":11445383}]}]}
{"op":"mcm","clk":"11887754081","pt":1724144202910,"mc":[{"id":"1.232013126","rc":[{"batb":[[0,1.27,6.91],[1,1.2,250],[2,1.03,200]],"ltp":0.0,"tv":0.0,"id":35736915},{"batb":[[0,1.27,7.71],[1,1.2,250],[2,1.03,200]],"ltp":0.0,"tv":0.0,"id":11445383}]}]}
{"op":"mcm","clk":"11887756145","pt":1724144245752,"mc":[{"id":"1.232013126","rc":[{"batb":[[0,1.28,31.14],[1,1.27,6.38],[2,1.2,250]],"ltp":0.0,"tv":0.0,"id":35736915},{"batb":[[0,1.28,31.14],[1,1.27,7.18],[2,1.2,250]],"ltp":0.0,"tv":0.0,"id":11445383}]}]}
{"op":"mcm","clk":"11887804963","pt":1724145175105,"mc":[{"id":"1.232013126","rc":[{"batb":[[0,1.28,31.13]],"ltp":0.0,"tv":0.0,"id":35736915},{"batb":[[0,1.28,31.13],[1,1.27,7.18]],"ltp":0.0,"tv":0.0,"id":11445383}]}]}
{"op":"mcm","clk":"11887839003","pt":1724146046293,"mc":[{"id":"1.232013126","rc":[{"batb":[[0,1.27,6.91],[1,1.2,250],[2,1.03,200]],"ltp":0.0,"tv":0.0,"id":35736915},{"batb":[[0,1.27,7.71],[1,1.2,250],[2,1.03,200]],"ltp":0.0,"tv":0.0,"id":11445383}]}]}
{"op":"mcm","clk":"11887841964","pt":1724146082857,"mc":[{"id":"1.232013126","rc":[{"batb":[[0,1.28,31.13],[1,1.27,6.38],[2,1.2,250]],"ltp":0.0,"tv":0.0,"id":35736915},{"batb":[[0,1.28,31.13],[1,1.27,7.18],[2,1.2,250]],"ltp":0.0,"tv":0.0,"id":11445383}]}]}
{"op":"mcm","clk":"11887926013","pt":1724147883400,"mc":[{"id":"1.232013126","rc":[{"batb":[[0,1.27,6.91],[1,1.2,250],[2,1.03,200]],"ltp":0.0,"tv":0.0,"id":35736915},{"batb":[[0,1.27,7.71],[1,1.2,250],[2,1.03,200]],"ltp":0.0,"tv":0.0,"id":11445383}]}]}
{"op":"mcm","clk":"11887927649","pt":1724147915359,"mc":[{"id":"1.232013126","rc":[{"batb":[[0,1.28,31.13],[1,1.27,6.38],[2,1.2,250]],"ltp":0.0,"tv":0.0,"id":35736915},{"batb":[[0,1.28,31.13],[1,1.27,7.18],[2,1.2,250]],"ltp":0.0,"tv":0.0,"id":11445383}]}]}
{"op":"mcm","clk":"11888019947","pt":1724149715999,"mc":[{"id":"1.232013126","rc":[{"batb":[[0,1.27,6.91],[1,1.2,250],[2,1.03,200]],"ltp":0.0,"tv":0.0,"id":35736915},{"batb":[[0,1.27,7.71],[1,1.2,250],[2,1.03,200]],"ltp":0.0,"tv":0.0,"id":11445383}]}]}
{"op":"mcm","clk":"11888021169","pt":1724149747017,"mc":[{"id":"1.232013126","rc":[{"batb":[[0,1.28,31.11],[1,1.27,6.38],[2,1.2,250]],"ltp":0.0,"tv":0.0,"id":35736915},{"batb":[[0,1.28,31.11],[1,1.27,7.18],[2,1.2,250]],"ltp":0.0,"tv":0.0,"id":11445383}]}]}
{"op":"mcm","clk":"11888114658","pt":1724151547357,"mc":[{"id":"1.232013126","rc":[{"batb":[[0,1.27,7.71],[1,1.2,250],[2,1.04,1.53]],"ltp":0.0,"tv":0.0,"id":11445383}]}]}
{"op":"mcm","clk":"11888114672","pt":1724151547561,"mc":[{"id":"1.232013126","rc":[{"batb":[[0,1.27,6.91],[1,1.2,250],[2,1.04,1.53]],"ltp":0.0,"tv":0.0,"id":35736915}]}]}
{"op":"mcm","clk":"11888115377","pt":1724151563460,"mc":[{"id":"1.232013126","rc":[{"batb":[[0,1.28,31.11],[1,1.27,6.38],[2,1.2,250]],"ltp":0.0,"tv":0.0,"id":35736915},{"batb":[[0,1.28,31.11],[1,1.27,7.18],[2,1.2,250]],"ltp":0.0,"tv":0.0,"id":11445383}]}]}
{"op":"mcm","clk":"11888210908","pt":1724153363809,"mc":[{"id":"1.232013126","rc":[{"batb":[[0,1.27,6.91],[1,1.2,250],[2,1.04,1.53]],"ltp":0.0,"tv":0.0,"id":35736915},{"batb":[[0,1.27,7.71],[1,1.2,250],[2,1.04,1.53]],"ltp":0.0,"tv":0.0,"id":11445383}]}]}
{"op":"mcm","clk":"11888210995","pt":1724153365504,"mc":[{"id":"1.232013126","rc":[{"batb":[[0,1.28,31.13],[1,1.27,6.37],[2,1.2,250]],"ltp":0.0,"tv":0.0,"id":35736915},{"batb":[[0,1.28,31.13],[1,1.27,7.17],[2,1.2,250]],"ltp":0.0,"tv":0.0,"id":11445383}]}]}
{"op":"mcm","clk":"11888293869","pt":1724155166396,"mc":[{"id":"1.232013126","rc":[{"batb":[[0,1.27,6.91],[1,1.2,250],[2,1.04,1.53]],"ltp":0.0,"tv":0.0,"id":35736915},{"batb":[[0,1.27,7.71],[1,1.2,250],[2,1.04,1.53]],"ltp":0.0,"tv":0.0,"id":11445383}]}]}
{"op":"mcm","clk":"11888298979","pt":1724155300640,"mc":[{"id":"1.232013126","rc":[{"batb":[[0,1.28,31.11],[1,1.27,6.37],[2,1.2,250]],"ltp":0.0,"tv":0.0,"id":35736915},{"batb":[[0,1.28,31.11],[1,1.27,7.17],[2,1.2,250]],"ltp":0.0,"tv":0.0,"id":11445383}]}]}
{"op":"mcm","clk":"11888391966","pt":1724157101249,"mc":[{"id":"1.232013126","rc":[{"batb":[[0,1.27,6.91],[1,1.2,250],[2,1.04,1.53]],"ltp":0.0,"tv":0.0,"id":35736915},{"batb":[[0,1.27,7.71],[1,1.2,250],[2,1.04,1.53]],"ltp":0.0,"tv":0.0,"id":11445383}]}]}
{"op":"mcm","clk":"11888393369","pt":1724157135476,"mc":[{"id":"1.232013126","rc":[{"batb":[[0,1.28,31.11],[1,1.27,6.37],[2,1.2,250]],"ltp":0.0,"tv":0.0,"id":35736915},{"batb":[[0,1.28,31.11],[1,1.27,7.17],[2,1.2,250]],"ltp":0.0,"tv":0.0,"id":11445383}]}]}
{"op":"mcm","clk":"11888457057","pt":1724158523465,"mc":[{"id":"1.232013126","rc":[{"batb":[[0,1.28,30.57]],"ltp":0.0,"tv":0.0,"id":35736915},{"batb":[[0,1.28,30.57]],"ltp":0.0,"tv":0.0,"id":11445383}]}]}
{"op":"mcm","clk":"11888473461","pt":1724158935845,"mc":[{"id":"1.232013126","rc":[{"batb":[[0,1.27,6.36],[1,1.2,250],[2,1.04,1.53]],"ltp":0.0,"tv":0.0,"id":35736915},{"batb":[[0,1.27,7.16],[1,1.2,250],[2,1.04,1.53]],"ltp":0.0,"tv":0.0,"id":11445383}]}]}
{"op":"mcm","clk":"11888474515","pt":1724158958897,"mc":[{"id":"1.232013126","rc":[{"batb":[[0,1.28,30.57],[1,1.27,6.36],[2,1.2,250]],"ltp":0.0,"tv":0.0,"id":35736915},{"batb":[[0,1.28,30.57],[1,1.27,7.16],[2,1.2,250]],"ltp":0.0,"tv":0.0,"id":11445383}]}]}
{"op":"mcm","clk":"11888566914","pt":1724160759450,"mc":[{"id":"1.232013126","rc":[{"batb":[[0,1.27,7.16],[1,1.2,250],[2,1.04,1.53]],"ltp":0.0,"tv":0.0,"id":11445383}]}]}
{"op":"mcm","clk":"11888566923","pt":1724160759558,"mc":[{"id":"1.232013126","rc":[{"batb":[[0,1.27,6.36],[1,1.2,250],[2,1.04,1.53]],"ltp":0.0,"tv":0.0,"id":35736915}]}]}
{"op":"mcm","clk":"11888567376","pt":1724160770576,"mc":[{"id":"1.232013126","rc":[{"batb":[[0,1.28,30.57],[1,1.27,6.36],[2,1.2,250]],"ltp":0.0,"tv":0.0,"id":35736915},{"batb":[[0,1.28,30.57],[1,1.27,7.16],[2,1.2,250]],"ltp":0.0,"tv":0.0,"id":11445383}]}]}
{"op":"mcm","clk":"11888665367","pt":1724162571240,"mc":[{"id":"1.232013126","rc":[{"batb":[[0,1.27,6.36],[1,1.2,250],[2,1.04,1.53]],"ltp":0.0,"tv":0.0,"id":35736915},{"batb":[[0,1.27,7.16],[1,1.2,250],[2,1.04,1.53]],"ltp":0.0,"tv":0.0,"id":11445383}]}]}
{"op":"mcm","clk":"11888665622","pt":1724162575659,"mc":[{"id":"1.232013126","rc":[{"batb":[[0,1.28,30.59],[1,1.27,6.36],[2,1.2,250]],"ltp":0.0,"tv":0.0,"id":35736915},{"batb":[[0,1.28,30.59],[1,1.27,7.16],[2,1.2,250]],"ltp":0.0,"tv":0.0,"id":11445383}]}]}
{"op":"mcm","clk":"11888767052","pt":1724164376479,"mc":[{"id":"1.232013126","rc":[{"batb":[[0,1.27,6.36],[1,1.2,250],[2,1.04,1.53]],"ltp":0.0,"tv":0.0,"id":35736915},{"batb":[[0,1.27,7.16],[1,1.2,250],[2,1.04,1.53]],"ltp":0.0,"tv":0.0,"id":11445383}]}]}
{"op":"mcm","clk":"11888777458","pt":1724164533432,"mc":[{"id":"1.232013126","rc":[{"batb":[[0,1.28,30.59],[1,1.27,6.36],[2,1.2,250]],"ltp":0.0,"tv":0.0,"id":35736915},{"batb":[[0,1.28,30.59],[1,1.27,7.16],[2,1.2,250]],"ltp":0.0,"tv":0.0,"id":11445383}]}]}
{"op":"mcm","clk":"11888895250","pt":1724166333866,"mc":[{"id":"1.232013126","rc":[{"batb":[[0,1.27,6.36],[1,1.2,250],[2,1.04,1.53]],"ltp":0.0,"tv":0.0,"id":35736915},{"batb":[[0,1.27,7.16],[1,1.2,250],[2,1.04,1.53]],"ltp":0.0,"tv":0.0,"id":11445383}]}]}
{"op":"mcm","clk":"11888904391","pt":1724166474137,"mc":[{"id":"1.232013126","rc":[{"batb":[[0,1.28,30.61],[1,1.27,6.36],[2,1.2,250]],"ltp":0.0,"tv":0.0,"id":35736915},{"batb":[[0,1.28,30.61],[1,1.27,7.16],[2,1.2,250]],"ltp":0.0,"tv":0.0,"id":11445383}]}]}
{"op":"mcm","clk":"11889065611","pt":1724168274731,"mc":[{"id":"1.232013126","rc":[{"batb":[[0,1.27,6.36],[1,1.2,250],[2,1.04,1.53]],"ltp":0.0,"tv":0.0,"id":35736915},{"batb":[[0,1.27,7.16],[1,1.2,250],[2,1.04,1.53]],"ltp":0.0,"tv":0.0,"id":11445383}]}]}
{"op":"mcm","clk":"11889077500","pt":1724168404889,"mc":[{"id":"1.232013126","rc":[{"batb":[[0,1.28,30.61],[1,1.27,6.36],[2,1.2,250]],"ltp":0.0,"tv":0.0,"id":35736915},{"batb":[[0,1.28,30.61],[1,1.27,7.16],[2,1.2,250]],"ltp":0.0,"tv":0.0,"id":11445383}]}]}
{"op":"mcm","clk":"11889238418","pt":1724170205378,"mc":[{"id":"1.232013126","rc":[{"batb":[[0,1.27,6.36],[1,1.2,250],[2,1.04,1.53]],"ltp":0.0,"tv":0.0,"id":35736915},{"batb":[[1,1.27,7.16]],"ltp":0.0,"tv":0.0,"id":11445383}]}]}
{"op":"mcm","clk":"11889238440","pt":1724170205589,"mc":[{"id":"1.232013126","rc":[{"batb":[[0,1.27,7.16],[1,1.2,250],[2,1.04,1.53]],"ltp":0.0,"tv":0.0,"id":11445383}]}]}
{"op":"mcm","clk":"11889250096","pt":1724170323353,"mc":[{"id":"1.232013126","rc":[{"batb":[[0,1.28,30.61],[1,1.27,6.36],[2,1.2,250]],"ltp":0.0,"tv":0.0,"id":35736915},{"batb":[[0,1.28,30.61],[1,1.27,7.16],[2,1.2,250]],"ltp":0.0,"tv":0.0,"id":11445383}]}]}
{"op":"mcm","clk":"11889409942","pt":1724172124004,"mc":[{"id":"1.232013126","rc":[{"batb":[[0,1.27,6.36],[1,1.2,250],[2,1.04,1.53]],"ltp":0.0,"tv":0.0,"id":35736915},{"batb":[[0,1.27,7.16],[1,1.2,250],[2,1.04,1.53]],"ltp":0.0,"tv":0.0,"id":11445383}]}]}
{"op":"mcm","clk":"11889429971","pt":1724172217381,"mc":[{"id":"1.232013126","rc":[{"batb":[[0,1.28,30.61],[1,1.27,6.36],[2,1.2,250]],"ltp":0.0,"tv":0.0,"id":35736915},{"batb":[[0,1.28,30.61],[1,1.27,7.16],[2,1.2,250]],"ltp":0.0,"tv":0.0,"id":11445383}]}]}
{"op":"mcm","clk":"11889627726","pt":1724174018165,"mc":[{"id":"1.232013126","rc":[{"batb":[[0,1.27,6.36],[1,1.2,250],[2,1.04,1.53]],"ltp":0.0,"tv":0.0,"id":35736915},{"batb":[[0,1.27,7.16],[1,1.2,250],[2,1.04,1.53]],"ltp":0.0,"tv":0.0,"id":11445383}]}]}
{"op":"mcm","clk":"11889636178","pt":1724174088633,"mc":[{"id":"1.232013126","rc":[{"batb":[[0,1.28,30.63],[1,1.27,6.36],[2,1.2,250]],"ltp":0.0,"tv":0.0,"id":35736915},{"batb":[[0,1.28,30.63],[1,1.27,7.16],[2,1.2,250]],"ltp":0.0,"tv":0.0,"id":11445383}]}]}
{"op":"mcm","clk":"11889861679","pt":1724175889379,"mc":[{"id":"1.232013126","rc":[{"batb":[[0,1.27,7.16],[1,1.2,250],[2,1.04,1.53]],"ltp":0.0,"tv":0.0,"id":11445383}]}]}
{"op":"mcm","clk":"11889861705","pt":1724175889586,"mc":[{"id":"1.232013126","rc":[{"batb":[[0,1.27,6.36],[1,1.2,250],[2,1.04,1.53]],"ltp":0.0,"tv":0.0,"id":35736915}]}]}
{"op":"mcm","clk":"11889866882","pt":1724175925532,"mc":[{"id":"1.232013126","rc":[{"batb":[[0,1.28,30.63],[1,1.27,6.36],[2,1.2,250]],"ltp":0.0,"tv":0.0,"id":35736915},{"batb":[[0,1.28,30.63],[1,1.27,7.16],[2,1.2,250]],"ltp":0.0,"tv":0.0,"id":11445383}]}]}
{"op":"mcm","clk":"11890104079","pt":1724177575096,"mc":[{"id":"1.232013126","rc":[{"batb":[[0,1.28,30.65],[1,1.27,6.37]],"ltp":0.0,"tv":0.0,"id":35736915},{"batb":[[0,1.28,30.65],[1,1.27,7.17]],"ltp":0.0,"tv":0.0,"id":11445383}]}]}
{"op":"mcm","clk":"11890130754","pt":1724177726483,"mc":[{"id":"1.232013126","rc":[{"batb":[[0,1.27,7.17],[1,1.2,250],[2,1.04,1.53]],"ltp":0.0,"tv":0.0,"id":11445383}]}]}
{"op":"mcm","clk":"11890130799","pt":1724177726651,"mc":[{"id":"1.232013126","rc":[{"batb":[[0,1.27,6.37],[1,1.2,250],[2,1.04,1.53]],"ltp":0.0,"tv":0.0,"id":35736915}]}]}
{"op":"mcm","clk":"11890132091","pt":1724177734586,"mc":[{"id":"1.232013126","rc":[{"batb":[[0,1.28,30.65],[1,1.27,6.37],[2,1.2,250]],"ltp":0.0,"tv":0.0,"id":35736915},{"batb":[[0,1.28,30.65],[1,1.27,7.17],[2,1.2,250]],"ltp":0.0,"tv":0.0,"id":11445383}]}]}
{"op":"mcm","clk":"11890395138","pt":1724179535047,"mc":[{"id":"1.232013126","rc":[{"batb":[[0,1.27,6.37],[1,1.2,250],[2,1.04,1.53]],"ltp":0.0,"tv":0.0,"id":35736915},{"batb":[[0,1.27,7.17],[1,1.2,250],[2,1.04,1.53]],"ltp":0.0,"tv":0.0,"id":11445383}]}]}
{"op":"mcm","clk":"11890414834","pt":1724179640290,"mc":[{"id":"1.232013126","rc":[{"batb":[[0,1.28,30.65],[1,1.27,6.37],[2,1.2,250]],"ltp":0.0,"tv":0.0,"id":35736915},{"batb":[[0,1.28,30.65],[1,1.27,7.17],[2,1.2,250]],"ltp":0.0,"tv":0.0,"id":11445383}]}]}
{"op":"mcm","clk":"11890760488","pt":1724181441120,"mc":[{"id":"1.232013126","rc":[{"batb":[[0,1.27,6.36],[1,1.2,250],[2,1.04,1.53]],"ltp":0.0,"tv":0.0,"id":35736915},{"batb":[[0,1.27,7.16],[1,1.2,250],[2,1.04,1.53]],"ltp":0.0,"tv":0.0,"id":11445383}]}]}
{"op":"mcm","clk":"11890771787","pt":1724181500922,"mc":[{"id":"1.232013126","rc":[{"batb":[[0,1.28,30.64],[1,1.27,6.36],[2,1.2,250]],"ltp":0.0,"tv":0.0,"id":35736915},{"batb":[[0,1.28,30.64],[1,1.27,7.16],[2,1.2,250]],"ltp":0.0,"tv":0.0,"id":11445383}]}]}
{"op":"mcm","clk":"11891081893","pt":1724183301444,"mc":[{"id":"1.232013126","rc":[{"batb":[[0,1.27,6.36],[1,1.2,250],[2,1.04,1.53]],"ltp":0.0,"tv":0.0,"id":35736915},{"batb":[[0,1.27,7.16],[1,1.2,250],[2,1.04,1.53]],"ltp":0.0,"tv":0.0,"id":11445383}]}]}
{"op":"mcm","clk":"11891088084","pt":1724183341463,"mc":[{"id":"1.232013126","rc":[{"batb":[[0,1.28,30.64],[1,1.27,6.36],[2,1.2,250]],"ltp":0.0,"tv":0.0,"id":35736915},{"batb":[[0,1.28,30.64],[1,1.27,7.16],[2,1.2,250]],"ltp":0.0,"tv":0.0,"id":11445383}]}]}
{"op":"mcm","clk":"11891379943","pt":1724185142374,"mc":[{"id":"1.232013126","rc":[{"batb":[[0,1.27,6.36],[1,1.2,250],[2,1.04,1.53]],"ltp":0.0,"tv":0.0,"id":35736915},{"batb":[[0,1.27,7.16],[1,1.2,250],[2,1.04,1.53]],"ltp":0.0,"tv":0.0,"id":11445383}]}]}
{"op":"mcm","clk":"11891400966","pt":1724185270636,"mc":[{"id":"1.232013126","rc":[{"batb":[[0,1.28,30.64],[1,1.27,6.36],[2,1.2,250]],"ltp":0.0,"tv":0.0,"id":35736915},{"batb":[[0,1.28,30.64],[1,1.27,7.16],[2,1.2,250]],"ltp":0.0,"tv":0.0,"id":11445383}]}]}
{"op":"mcm","clk":"11891590792","pt":1724187071518,"mc":[{"id":"1.232013126","rc":[{"batb":[[0,1.27,6.36],[1,1.2,250],[2,1.04,1.53]],"ltp":0.0,"tv":0.0,"id":35736915}]}]}
{"op":"mcm","clk":"11891590807","pt":1724187071724,"mc":[{"id":"1.232013126","rc":[{"batb":[[0,1.27,7.16],[1,1.2,250],[2,1.04,1.53]],"ltp":0.0,"tv":0.0,"id":11445383}]}]}
{"op":"mcm","clk":"11891594829","pt":1724187130472,"mc":[{"id":"1.232013126","rc":[{"batb":[[0,1.28,30.64],[1,1.27,6.36],[2,1.2,250]],"ltp":0.0,"tv":0.0,"id":35736915},{"batb":[[0,1.28,30.64],[1,1.27,7.16],[2,1.2,250]],"ltp":0.0,"tv":0.0,"id":11445383}]}]}
{"op":"mcm","clk":"11891678749","pt":1724188375118,"mc":[{"id":"1.232013126","rc":[{"batb":[[0,1.28,30.65]],"ltp":0.0,"tv":0.0,"id":35736915},{"batb":[[0,1.28,30.65]],"ltp":0.0,"tv":0.0,"id":11445383}]}]}
{"op":"mcm","clk":"11891710297","pt":1724188931484,"mc":[{"id":"1.232013126","rc":[{"batb":[[0,1.27,6.36],[1,1.2,250],[2,1.04,1.53]],"ltp":0.0,"tv":0.0,"id":35736915},{"batb":[[0,1.27,7.16],[1,1.2,250],[2,1.04,1.53]],"ltp":0.0,"tv":0.0,"id":11445383}]}]}
{"op":"mcm","clk":"11891715123","pt":1724189022505,"mc":[{"id":"1.232013126","rc":[{"batb":[[0,1.28,30.65],[1,1.27,6.36],[2,1.2,250]],"ltp":0.0,"tv":0.0,"id":35736915},{"batb":[[0,1.28,30.65],[1,1.27,7.16],[2,1.2,250]],"ltp":0.0,"tv":0.0,"id":11445383}]}]}
{"op":"mcm","clk":"11891813282","pt":1724190823433,"mc":[{"id":"1.232013126","rc":[{"batb":[[0,1.27,7.16],[1,1.2,250],[2,1.04,1.53]],"ltp":0.0,"tv":0.0,"id":11445383}]}]}
{"op":"mcm","clk":"11891813294","pt":1724190823591,"mc":[{"id":"1.232013126","rc":[{"batb":[[0,1.27,6.36],[1,1.2,250],[2,1.04,1.53]],"ltp":0.0,"tv":0.0,"id":35736915}]}]}
{"op":"mcm","clk":"11891816252","pt":1724190875165,"mc":[{"id":"1.232013126","rc":[{"batb":[[0,1.28,30.65],[1,1.27,6.36],[2,1.2,250]],"ltp":0.0,"tv":0.0,"id":35736915},{"batb":[[0,1.28,30.65],[1,1.27,7.16],[2,1.2,250]],"ltp":0.0,"tv":0.0,"id":11445383}]}]}
{"op":"mcm","clk":"11891902694","pt":1724192676331,"mc":[{"id":"1.232013126","rc":[{"batb":[[0,1.27,6.36],[1,1.2,250],[2,1.04,1.53]],"ltp":0.0,"tv":0.0,"id":35736915},{"batb":[[0,1.27,7.16],[1,1.2,250],[2,1.04,1.53]],"ltp":0.0,"tv":0.0,"id":11445383}]}]}
{"op":"mcm","clk":"11891904149","pt":1724192714033,"mc":[{"id":"1.232013126","rc":[{"batb":[[0,1.28,30.65],[1,1.27,6.36],[2,1.2,250]],"ltp":0.0,"tv":0.0,"id":35736915},{"batb":[[0,1.28,30.65],[1,1.27,7.16],[2,1.2,250]],"ltp":0.0,"tv":0.0,"id":11445383}]}]}
{"op":"mcm","clk":"11891998252","pt":1724194514789,"mc":[{"id":"1.232013126","rc":[{"batb":[[0,1.27,6.36],[1,1.2,250],[2,1.04,1.53]],"ltp":0.0,"tv":0.0,"id":35736915},{"batb":[[0,1.27,7.16],[1,1.2,250],[2,1.04,1.53]],"ltp":0.0,"tv":0.0,"id":11445383}]}]}
{"op":"mcm","clk":"11891999306","pt":1724194536319,"mc":[{"id":"1.232013126","rc":[{"batb":[[0,1.28,30.65],[1,1.27,6.36],[2,1.2,250]],"ltp":0.0,"tv":0.0,"id":35736915},{"batb":[[0,1.28,30.65],[1,1.27,7.16],[2,1.2,250]],"ltp":0.0,"tv":0.0,"id":11445383}]}]}
{"op":"mcm","clk":"11892095471","pt":1724196337472,"mc":[{"id":"1.232013126","rc":[{"batb":[[0,1.27,6.36],[1,1.2,250],[2,1.04,1.53]],"ltp":0.0,"tv":0.0,"id":35736915},{"batb":[[0,1.27,7.16],[1,1.2,250],[2,1.04,1.53]],"ltp":0.0,"tv":0.0,"id":11445383}]}]}
{"op":"mcm","clk":"11892101808","pt":1724196455089,"mc":[{"id":"1.232013126","rc":[{"batb":[[0,1.28,30.66],[1,1.27,6.36],[2,1.2,250]],"ltp":0.0,"tv":0.0,"id":35736915},{"batb":[[0,1.28,30.66],[1,1.27,7.16],[2,1.2,250]],"ltp":0.0,"tv":0.0,"id":11445383}]}]}
{"op":"mcm","clk":"11892200167","pt":1724198256349,"mc":[{"id":"1.232013126","rc":[{"batb":[[0,1.27,6.36],[1,1.2,250],[2,1.04,1.53]],"ltp":0.0,"tv":0.0,"id":35736915},{"batb":[[0,1.27,7.16],[1,1.2,250],[2,1.04,1.53]],"ltp":0.0,"tv":0.0,"id":11445383}]}]}
{"op":"mcm","clk":"11892205693","pt":1724198351968,"mc":[{"id":"1.232013126","rc":[{"batb":[[0,1.28,30.66],[1,1.27,6.36],[2,1.2,250]],"ltp":0.0,"tv":0.0,"id":35736915},{"batb":[[0,1.28,30.66],[1,1.27,7.16],[2,1.2,250]],"ltp":0.0,"tv":0.0,"id":11445383}]}]}
{"op":"mcm","clk":"11892261870","pt":1724199175200,"mc":[{"id":"1.232013126","rc":[{"batb":[[0,1.28,30.65],[1,1.27,6.36]],"ltp":0.0,"tv":0.0,"id":35736915},{"batb":[[0,1.28,30.65],[1,1.27,7.16]],"ltp":0.0,"tv":0.0,"id":11445383}]}]}
{"op":"mcm","clk":"11892323339","pt":1724200153005,"mc":[{"id":"1.232013126","rc":[{"batb":[[0,1.27,6.36],[1,1.2,250],[2,1.04,1.53]],"ltp":0.0,"tv":0.0,"id":35736915},{"batb":[[0,1.27,7.16],[1,1.2,250],[2,1.04,1.53]],"ltp":0.0,"tv":0.0,"id":11445383}]}]}
{"op":"mcm","clk":"11892323823","pt":1724200160518,"mc":[{"id":"1.232013126","rc":[{"batb":[[0,1.2,250],[1,1.04,1.53],[2,1.03,200]],"ltp":0.0,"tv":0.0,"id":11445383}]}]}
{"op":"mcm","clk":"11892323869","pt":1724200161038,"mc":[{"id":"1.232013126","rc":[{"batb":[[0,1.21,6.36]],"ltp":0.0,"tv":0.0,"id":35736915},{"batb":[[0,1.21,7.16],[1,1.2,250],[2,1.04,1.53]],"ltp":0.0,"tv":0.0,"id":11445383}]}]}
{"op":"mcm","clk":"11892327194","pt":1724200209185,"mc":[{"id":"1.232013126","rc":[{"batb":[[0,1.22,39],[1,1.21,6.36],[2,1.2,250]],"ltp":0.0,"tv":0.0,"id":35736915},{"batb":[[0,1.22,39],[1,1.21,7.16],[2,1.2,250]],"ltp":0.0,"tv":0.0,"id":11445383}]}]}
{"op":"mcm","clk":"11892427766","pt":1724202009818,"mc":[{"id":"1.232013126","rc":[{"batb":[[0,1.21,6.36],[1,1.2,250],[2,1.04,1.53]],"ltp":0.0,"tv":0.0,"id":35736915},{"batb":[[0,1.21,7.16],[1,1.2,250],[2,1.04,1.53]],"ltp":0.0,"tv":0.0,"id":11445383}]}]}
{"op":"mcm","clk":"11892429312","pt":1724202041240,"mc":[{"id":"1.232013126","rc":[{"batb":[[0,1.22,39],[1,1.21,6.36],[2,1.2,250]],"ltp":0.0,"tv":0.0,"id":35736915},{"batb":[[0,1.22,39],[1,1.21,7.16],[2,1.2,250]],"ltp":0.0,"tv":0.0,"id":11445383}]}]}
{"op":"mcm","clk":"11892433438","pt":1724202119334,"mc":[{"id":"1.232013126","rc":[{"batb":[[0,1.23,6.36],[1,1.22,39]],"ltp":0.0,"tv":0.0,"id":35736915},{"batb":[[0,1.23,7.16],[1,1.22,39]],"ltp":0.0,"tv":0.0,"id":11445383}]}]}
{"op":"mcm","clk":"11892524073","pt":1724203841860,"mc":[{"id":"1.232013126","rc":[{"batb":[[1,1.2,250],[2,1.04,1.53]],"ltp":0.0,"tv":0.0,"id":35736915},{"batb":[[1,1.2,250],[2,1.04,1.53]],"ltp":0.0,"tv":0.0,"id":11445383}]}]}
{"op":"mcm","clk":"11892524573","pt":1724203851353,"mc":[{"id":"1.232013126","rc":[{"batb":[[0,1.24,35.75],[1,1.23,6.36],[2,1.2,250]],"ltp":0.0,"tv":0.0,"id":35736915},{"batb":[[0,1.24,35.75],[1,1.23,7.16],[2,1.2,250]],"ltp":0.0,"tv":0.0,"id":11445383}]}]}
{"op":"mcm","clk":"11892539398","pt":1724204120536,"mc":[{"id":"1.232013126","rc":[{"batb":[[0,1.25,7.16],[1,1.24,35.75]],"ltp":0.0,"tv":0.0,"id":11445383}]}]}
{"op":"mcm","clk":"11892539422","pt":1724204120948,"mc":[{"id":"1.232013126","rc":[{"batb":[[0,1.25,6.36],[1,1.24,35.75]],"ltp":0.0,"tv":0.0,"id":35736915}]}]}
{"op":"mcm","clk":"11892618815","pt":1724205652313,"mc":[{"id":"1.232013126","rc":[{"batb":[[0,1.25,6.36],[1,1.2,250],[2,1.04,1.53]],"ltp":0.0,"tv":0.0,"id":35736915},{"batb":[[0,1.25,7.16],[1,1.2,250],[2,1.04,1.53]],"ltp":0.0,"tv":0.0,"id":11445383}]}]}
{"op":"mcm","clk":"11892622415","pt":1724205749172,"mc":[{"id":"1.232013126","rc":[{"batb":[[0,1.26,33.01],[1,1.25,6.36],[2,1.2,250]],"ltp":0.0,"tv":0.0,"id":35736915},{"batb":[[0,1.26,33.01],[1,1.25,7.16],[2,1.2,250]],"ltp":0.0,"tv":0.0,"id":11445383}]}]}
{"op":"mcm","clk":"11892638799","pt":1724206149422,"mc":[{"id":"1.232013126","rc":[{"batb":[[0,1.27,7.16],[1,1.26,33.01]],"ltp":0.0,"tv":0.0,"id":11445383}]}]}
{"op":"mcm","clk":"11892638819","pt":1724206149834,"mc":[{"id":"1.232013126","rc":[{"batb":[[0,1.27,6.36],[1,1.26,33.01]],"ltp":0.0,"tv":0.0,"id":35736915}]}]}
{"op":"mcm","clk":"11892696046","pt":1724207550133,"mc":[{"id":"1.232013126","rc":[{"batb":[[1,1.2,250],[2,1.04,1.53]],"ltp":0.0,"tv":0.0,"id":35736915},{"batb":[[1,1.2,250],[2,1.04,1.53]],"ltp":0.0,"tv":0.0,"id":11445383}]}]}
{"op":"mcm","clk":"11892698271","pt":1724207618083,"mc":[{"id":"1.232013126","rc":[{"batb":[[0,1.28,30.65],[1,1.27,6.36],[2,1.2,250]],"ltp":0.0,"tv":0.0,"id":35736915},{"batb":[[0,1.28,30.65],[1,1.27,7.16],[2,1.2,250]],"ltp":0.0,"tv":0.0,"id":11445383}]}]}
{"op":"mcm","clk":"11892765261","pt":1724209419178,"mc":[{"id":"1.232013126","rc":[{"batb":[[0,1.27,6.36],[1,1.2,250],[2,1.04,1.53]],"ltp":0.0,"tv":0.0,"id":35736915},{"batb":[[0,1.27,7.16],[1,1.2,250],[2,1.04,1.53]],"ltp":0.0,"tv":0.0,"id":11445383}]}]}
{"op":"mcm","clk":"11892767052","pt":1724209456310,"mc":[{"id":"1.232013126","rc":[{"batb":[[0,1.28,30.64],[1,1.27,6.36],[2,1.2,250]],"ltp":0.0,"tv":0.0,"id":35736915},{"batb":[[0,1.28,30.64],[1,1.27,7.16],[2,1.2,250]],"ltp":0.0,"tv":0.0,"id":11445383}]}]}
{"op":"mcm","clk":"11892860562","pt":1724211257356,"mc":[{"id":"1.232013126","rc":[{"batb":[[0,1.27,6.36],[1,1.2,250],[2,1.04,1.53]],"ltp":0.0,"tv":0.0,"id":35736915}]}]}
{"op":"mcm","clk":"11892860574","pt":1724211257561,"mc":[{"id":"1.232013126","rc":[{"batb":[[0,1.27,7.16],[1,1.2,250],[2,1.04,1.53]],"ltp":0.0,"tv":0.0,"id":11445383}]}]}
{"op":"mcm","clk":"11892861509","pt":1724211279285,"mc":[{"id":"1.232013126","rc":[{"batb":[[0,1.28,30.64],[1,1.27,6.36],[2,1.2,250]],"ltp":0.0,"tv":0.0,"id":35736915},{"batb":[[0,1.28,30.64],[1,1.27,7.16],[2,1.2,250]],"ltp":0.0,"tv":0.0,"id":11445383}]}]}
{"op":"mcm","clk":"11892965504","pt":1724213080386,"mc":[{"id":"1.232013126","rc":[{"batb":[[0,1.27,6.36],[1,1.2,250],[2,1.04,1.53]],"ltp":0.0,"tv":0.0,"id":35736915},{"batb":[[0,1.27,7.16],[1,1.2,250],[2,1.04,1.53]],"ltp":0.0,"tv":0.0,"id":11445383}]}]}
{"op":"mcm","clk":"11892966237","pt":1724213093835,"mc":[{"id":"1.232013126","rc":[{"batb":[[0,1.28,30.64],[1,1.27,6.36],[2,1.2,250]],"ltp":0.0,"tv":0.0,"id":35736915},{"batb":[[0,1.28,30.64],[1,1.27,7.16],[2,1.2,250]],"ltp":0.0,"tv":0.0,"id":11445383}]}]}
{"op":"mcm","clk":"11893062386","pt":1724214895109,"mc":[{"id":"1.232013126","rc":[{"batb":[[0,1.27,6.36],[1,1.2,250],[2,1.04,1.53]],"ltp":0.0,"tv":0.0,"id":35736915},{"batb":[[0,1.27,7.16],[1,1.2,250],[2,1.04,1.53]],"ltp":0.0,"tv":0.0,"id":11445383}]}]}
{"op":"mcm","clk":"11893067250","pt":1724214989275,"mc":[{"id":"1.232013126","rc":[{"batb":[[0,1.28,30.64],[1,1.27,6.36],[2,1.2,250]],"ltp":0.0,"tv":0.0,"id":35736915},{"batb":[[0,1.28,30.64],[1,1.27,7.16],[2,1.2,250]],"ltp":0.0,"tv":0.0,"id":11445383}]}]}
{"op":"mcm","clk":"11893158161","pt":1724216790401,"mc":[{"id":"1.232013126","rc":[{"batb":[[0,1.27,6.36],[1,1.2,250],[2,1.04,1.53]],"ltp":0.0,"tv":0.0,"id":35736915},{"batb":[[0,1.27,7.16],[1,1.2,250],[2,1.04,1.53]],"ltp":0.0,"tv":0.0,"id":11445383}]}]}
{"op":"mcm","clk":"11893162136","pt":1724216874410,"mc":[{"id":"1.232013126","rc":[{"batb":[[0,1.28,30.64],[1,1.27,6.36],[2,1.2,250]],"ltp":0.0,"tv":0.0,"id":35736915},{"batb":[[0,1.28,30.64],[1,1.27,7.16],[2,1.2,250]],"ltp":0.0,"tv":0.0,"id":11445383}]}]}
{"op":"mcm","clk":"11893246402","pt":1724218675519,"mc":[{"id":"1.232013126","rc":[{"batb":[[0,1.27,6.36],[1,1.2,250],[2,1.04,1.53]],"ltp":0.0,"tv":0.0,"id":35736915},{"batb":[[0,1.27,7.16],[1,1.2,250],[2,1.04,1.53]],"ltp":0.0,"tv":0.0,"id":11445383}]}]}
{"op":"mcm","clk":"11893250372","pt":1724218753708,"mc":[{"id":"1.232013126","rc":[{"batb":[[0,1.28,30.64],[1,1.27,6.36],[2,1.2,250]],"ltp":0.0,"tv":0.0,"id":35736915},{"batb":[[0,1.28,30.64],[1,1.27,7.16],[2,1.2,250]],"ltp":0.0,"tv":0.0,"id":11445383}]}]}
{"op":"mcm","clk":"11893338809","pt":1724220554510,"mc":[{"id":"1.232013126","rc":[{"batb":[[0,1.27,6.37],[1,1.2,250],[2,1.04,1.53]],"ltp":0.0,"tv":0.0,"id":35736915},{"batb":[[0,1.27,7.17],[1,1.2,250],[2,1.04,1.53]],"ltp":0.0,"tv":0.0,"id":11445383}]}]}
{"op":"mcm","clk":"11893343141","pt":1724220628627,"mc":[{"id":"1.232013126","rc":[{"batb":[[0,1.28,30.65],[1,1.27,6.37],[2,1.2,250]],"ltp":0.0,"tv":0.0,"id":35736915},{"batb":[[0,1.28,30.65],[1,1.27,7.17],[2,1.2,250]],"ltp":0.0,"tv":0.0,"id":11445383}]}]}
{"op":"mcm","clk":"11893439973","pt":1724222429084,"mc":[{"id":"1.232013126","rc":[{"batb":[[0,1.27,6.37],[1,1.2,250],[2,1.04,1.53]],"ltp":0.0,"tv":0.0,"id":35736915},{"batb":[[0,1.27,7.17],[1,1.2,250],[2,1.04,1.53]],"ltp":0.0,"tv":0.0,"id":11445383}]}]}
{"op":"mcm","clk":"11893443901","pt":1724222499506,"mc":[{"id":"1.232013126","rc":[{"batb":[[0,1.28,30.65],[1,1.27,6.37],[2,1.2,250]],"ltp":0.0,"tv":0.0,"id":35736915},{"batb":[[0,1.28,30.65],[1,1.27,7.17],[2,1.2,250]],"ltp":0.0,"tv":0.0,"id":11445383}]}]}
{"op":"mcm","clk":"11893526861","pt":1724224300188,"mc":[{"id":"1.232013126","rc":[{"batb":[[0,1.27,6.37],[1,1.2,250],[2,1.04,1.53]],"ltp":0.0,"tv":0.0,"id":35736915},{"batb":[[0,1.27,7.17],[1,1.2,250],[2,1.04,1.53]],"ltp":0.0,"tv":0.0,"id":11445383}]}]}
{"op":"mcm","clk":"11893530291","pt":1724224367765,"mc":[{"id":"1.232013126","rc":[{"batb":[[0,1.28,30.66],[1,1.27,6.37],[2,1.2,250]],"ltp":0.0,"tv":0.0,"id":35736915},{"batb":[[0,1.28,30.66],[1,1.27,7.17],[2,1.2,250]],"ltp":0.0,"tv":0.0,"id":11445383}]}]}
{"op":"mcm","clk":"11893602953","pt":1724226168773,"mc":[{"id":"1.232013126","rc":[{"batb":[[0,1.27,6.37],[1,1.2,250],[2,1.04,1.53]],"ltp":0.0,"tv":0.0,"id":35736915},{"batb":[[0,1.27,7.17],[1,1.2,250],[2,1.04,1.53]],"ltp":0.0,"tv":0.0,"id":11445383}]}]}
{"op":"mcm","clk":"11893614318","pt":1724226227779,"mc":[{"id":"1.232013126","rc":[{"batb":[[0,1.28,30.66],[1,1.27,6.37],[2,1.2,250]],"ltp":0.0,"tv":0.0,"id":35736915},{"batb":[[0,1.28,30.66],[1,1.27,7.17],[2,1.2,250]],"ltp":0.0,"tv":0.0,"id":11445383}]}]}
{"op":"mcm","clk":"11893696212","pt":1724228028368,"mc":[{"id":"1.232013126","rc":[{"batb":[[0,1.27,6.37],[1,1.2,250],[2,1.04,1.53]],"ltp":0.0,"tv":0.0,"id":35736915},{"batb":[[0,1.27,7.17],[1,1.2,250],[2,1.04,1.53]],"ltp":0.0,"tv":0.0,"id":11445383}]}]}
{"op":"mcm","clk":"11893699857","pt":1724228093845,"mc":[{"id":"1.232013126","rc":[{"batb":[[0,1.28,30.65],[1,1.27,6.37],[2,1.2,250]],"ltp":0.0,"tv":0.0,"id":35736915},{"batb":[[0,1.28,30.65],[1,1.27,7.17],[2,1.2,250]],"ltp":0.0,"tv":0.0,"id":11445383}]}]}
{"op":"mcm","clk":"11893795811","pt":1724229894754,"mc":[{"id":"1.232013126","rc":[{"batb":[[0,1.27,6.37],[1,1.2,250],[2,1.04,1.53]],"ltp":0.0,"tv":0.0,"id":35736915},{"batb":[[0,1.27,7.17],[1,1.2,250],[2,1.04,1.53]],"ltp":0.0,"tv":0.0,"id":11445383}]}]}
{"op":"mcm","clk":"11893798006","pt":1724229933315,"mc":[{"id":"1.232013126","rc":[{"batb":[[0,1.28,30.65],[1,1.27,6.37],[2,1.2,250]],"ltp":0.0,"tv":0.0,"id":35736915},{"batb":[[0,1.28,30.65],[1,1.27,7.17],[2,1.2,250]],"ltp":0.0,"tv":0.0,"id":11445383}]}]}
{"op":"mcm","clk":"11893897499","pt":1724231575108,"mc":[{"id":"1.232013126","rc":[{"batb":[[0,1.28,30.67]],"ltp":0.0,"tv":0.0,"id":35736915},{"batb":[[0,1.28,30.67]],"ltp":0.0,"tv":0.0,"id":11445383}]}]}
{"op":"mcm","clk":"11893908221","pt":1724231733760,"mc":[{"id":"1.232013126","rc":[{"batb":[[0,1.27,6.37],[1,1.2,250],[2,1.04,1.53]],"ltp":0.0,"tv":0.0,"id":35736915},{"batb":[[0,1.27,7.17],[1,1.2,250],[2,1.04,1.53]],"ltp":0.0,"tv":0.0,"id":11445383}]}]}
{"op":"mcm","clk":"11893911078","pt":1724231781309,"mc":[{"id":"1.232013126","rc":[{"batb":[[0,1.28,30.67],[1,1.27,6.37],[2,1.2,250]],"ltp":0.0,"tv":0.0,"id":35736915},{"batb":[[0,1.28,30.67],[1,1.27,7.17],[2,1.2,250]],"ltp":0.0,"tv":0.0,"id":11445383}]}]}
{"op":"mcm","clk":"11894004250","pt":1724233154288,"mc":[{"id":"1.232013126","rc":[{"batb":[[2,1.04,1.53]],"ltp":0.0,"tv":0.0,"id":35736915},{"batb":[[2,1.04,1.53]],"ltp":0.0,"tv":0.0,"id":11445383}]}]}
{"op":"mcm","clk":"11894010058","pt":1724233233029,"mc":[{"id":"1.232013126","rc":[{"batb":[[2,1.2,1105]],"ltp":0.0,"tv":0.0,"id":35736915},{"batb":[[2,1.2,1105]],"ltp":0.0,"tv":0.0,"id":11445383}]}]}
{"op":"mcm","clk":"11894036008","pt":1724233581710,"mc":[{"id":"1.232013126","rc":[{"batb":[[0,1.27,6.37],[1,1.2,1105],[2,1.04,1.53]],"ltp":0.0,"tv":0.0,"id":35736915},{"batb":[[0,1.27,7.17],[1,1.2,1105],[2,1.04,1.53]],"ltp":0.0,"tv":0.0,"id":11445383}]}]}
{"op":"mcm","clk":"11894039294","pt":1724233626676,"mc":[{"id":"1.232013126","rc":[{"batb":[[0,1.28,30.67],[1,1.27,6.37],[2,1.2,1105]],"ltp":0.0,"tv":0.0,"id":35736915},{"batb":[[0,1.28,30.67],[1,1.27,7.17],[2,1.2,1105]],"ltp":0.0,"tv":0.0,"id":11445383}]}]}
{"op":"mcm","clk":"11894185301","pt":1724235428230,"mc":[{"id":"1.232013126","rc":[{"batb":[[0,1.27,6.36],[1,1.2,1105],[2,1.04,1.53]],"batl":[[0,5.9,10.94]],"ltp":0.0,"tv":0.0,"id":35736915},{"batb":[[0,1.27,7.16],[1,1.2,1105],[2,1.04,1.53]],"batl":[[0,5.9,10.93]],"ltp":0.0,"tv":0.0,"id":11445383}]}]}
{"op":"mcm","clk":"11894188568","pt":1724235462067,"mc":[{"id":"1.232013126","rc":[{"batb":[[0,1.28,30.63],[1,1.27,6.36],[2,1.2,1105]],"ltp":0.0,"tv":0.0,"id":35736915},{"batb":[[0,1.28,30.63],[1,1.27,7.16],[2,1.2,1105]],"ltp":0.0,"tv":0.0,"id":11445383}]}]}
{"op":"mcm","clk":"11894367537","pt":1724237263024,"mc":[{"id":"1.232013126","rc":[{"batb":[[0,1.27,6.36],[1,1.2,1105],[2,1.04,1.53]],"ltp":0.0,"tv":0.0,"id":35736915},{"batb":[[0,1.27,7.16],[1,1.2,1105],[2,1.04,1.53]],"ltp":0.0,"tv":0.0,"id":11445383}]}]}
{"op":"mcm","clk":"11894368045","pt":1724237268437,"mc":[{"id":"1.232013126","rc":[{"batl":[[0,5.9,10.94]],"ltp":0.0,"tv":0.0,"id":35736915},{"batl":[[0,5.9,10.93]],"ltp":0.0,"tv":0.0,"id":11445383}]}]}
{"op":"mcm","clk":"11894370219","pt":1724237290493,"mc":[{"id":"1.232013126","rc":[{"batb":[[0,1.28,30.63],[1,1.27,6.36],[2,1.2,1105]],"ltp":0.0,"tv":0.0,"id":35736915},{"batb":[[0,1.28,30.63],[1,1.27,7.16],[2,1.2,1105]],"ltp":0.0,"tv":0.0,"id":11445383}]}]}
{"op":"mcm","clk":"11894529959","pt":1724239090994,"mc":[{"id":"1.232013126","rc":[{"batb":[[0,1.27,6.36],[1,1.2,1105],[2,1.04,1.53]],"batl":[[0,5.9,10.94]],"ltp":0.0,"tv":0.0,"id":35736915},{"batb":[[0,1.27,7.15],[1,1.2,1105],[2,1.04,1.53]],"batl":[[0,5.9,10.93]],"ltp":0.0,"tv":0.0,"id":11445383}]}]}
{"op":"mcm","clk":"11894532247","pt":1724239112527,"mc":[{"id":"1.232013126","rc":[{"batb":[[0,1.28,30.62],[1,1.27,6.36],[2,1.2,1105]],"ltp":0.0,"tv":0.0,"id":35736915},{"batb":[[0,1.28,30.62],[1,1.27,7.15],[2,1.2,1105]],"ltp":0.0,"tv":0.0,"id":11445383}]}]}
{"op":"mcm","clk":"11894702168","pt":1724240912482,"mc":[{"id":"1.232013126","rc":[{"batb":[[0,1.27,6.36],[1,1.2,1105],[2,1.04,1.53]],"ltp":0.0,"tv":0.0,"id":35736915},{"batb":[[0,1.27,7.15],[1,1.2,1105],[2,1.04,1.53]],"ltp":0.0,"tv":0.0,"id":11445383}]}]}
{"op":"mcm","clk":"11894703008","pt":1724240920684,"mc":[{"id":"1.232013126","rc":[{"batl":[[0,5.9,10.94]],"ltp":0.0,"tv":0.0,"id":35736915},{"batl":[[0,5.9,10.93]],"ltp":0.0,"tv":0.0,"id":11445383}]}]}
{"op":"mcm","clk":"11894712152","pt":1724241017280,"mc":[{"id":"1.232013126","rc":[{"batb":[[0,1.28,30.62],[1,1.27,6.36],[2,1.2,1105]],"ltp":0.0,"tv":0.0,"id":35736915},{"batb":[[0,1.28,30.62],[1,1.27,7.15],[2,1.2,1105]],"ltp":0.0,"tv":0.0,"id":11445383}]}]}
{"op":"mcm","clk":"11894819690","pt":1724242375149,"mc":[{"id":"1.232013126","rc":[{"batb":[[0,1.28,30.62],[1,1.27,6.36]],"ltp":0.0,"tv":0.0,"id":35736915},{"batb":[[0,1.28,30.62],[1,1.27,7.16]],"ltp":0.0,"tv":0.0,"id":11445383}]}]}
{"op":"mcm","clk":"11894848954","pt":1724242817884,"mc":[{"id":"1.232013126","rc":[{"batb":[[0,1.27,6.36],[1,1.2,1105],[2,1.04,1.53]],"ltp":0.0,"tv":0.0,"id":35736915},{"batb":[[0,1.27,7.16],[1,1.2,1105],[2,1.04,1.53]],"ltp":0.0,"tv":0.0,"id":11445383}]}]}
{"op":"mcm","clk":"11894849463","pt":1724242826171,"mc":[{"id":"1.232013126","rc":[{"batl":[[0,5.9,10.94]],"ltp":0.0,"tv":0.0,"id":35736915},{"batl":[[0,5.9,10.93]],"ltp":0.0,"tv":0.0,"id":11445383}]}]}
{"op":"mcm","clk":"11894854048","pt":1724242899559,"mc":[{"id":"1.232013126","rc":[{"batb":[[0,1.28,30.62],[1,1.27,6.36],[2,1.2,1105]],"ltp":0.0,"tv":0.0,"id":35736915},{"batb":[[0,1.28,30.62],[1,1.27,7.16],[2,1.2,1105]],"ltp":0.0,"tv":0.0,"id":11445383}]}]}
{"op":"mcm","clk":"11894964694","pt":1724244700504,"mc":[{"id":"1.232013126","rc":[{"batb":[[0,1.27,6.36],[1,1.2,1105],[2,1.04,1.53]],"ltp":0.0,"tv":0.0,"id":35736915},{"batb":[[0,1.27,7.16],[1,1.2,1105],[2,1.04,1.53]],"ltp":0.0,"tv":0.0,"id":11445383}]}]}
{"op":"mcm","clk":"11894965313","pt":1724244712088,"mc":[{"id":"1.232013126","rc":[{"batl":[[0,5.9,10.94]],"ltp":0.0,"tv":0.0,"id":35736915},{"batl":[[0,5.9,10.93]],"ltp":0.0,"tv":0.0,"id":11445383}]}]}
{"op":"mcm","clk":"11894967820","pt":1724244756449,"mc":[{"id":"1.232013126","rc":[{"batb":[[0,1.28,30.62],[1,1.27,6.36],[2,1.2,1105]],"ltp":0.0,"tv":0.0,"id":35736915},{"batb":[[0,1.28,30.62],[1,1.27,7.16],[2,1.2,1105]],"ltp":0.0,"tv":0.0,"id":11445383}]}]}
{"op":"mcm","clk":"11895076657","pt":1724246556856,"mc":[{"id":"1.232013126","rc":[{"batb":[[0,1.27,6.35],[1,1.2,1105],[2,1.04,1.53]],"ltp":0.0,"tv":0.0,"id":35736915},{"batb":[[0,1.27,7.15],[1,1.2,1105],[2,1.04,1.53]],"ltp":0.0,"tv":0.0,"id":11445383}]}]}
{"op":"mcm","clk":"11895077054","pt":1724246562864,"mc":[{"id":"1.232013126","rc":[{"batl":[[0,5.9,10.94]],"ltp":0.0,"tv":0.0,"id":35736915},{"batl":[[0,5.9,10.93]],"ltp":0.0,"tv":0.0,"id":11445383}]}]}
{"op":"mcm","clk":"11895079885","pt":1724246602703,"mc":[{"id":"1.232013126","rc":[{"batb":[[0,1.28,30.61],[1,1.27,6.35],[2,1.2,1105]],"ltp":0.0,"tv":0.0,"id":35736915},{"batb":[[0,1.28,30.61],[1,1.27,7.15],[2,1.2,1105]],"ltp":0.0,"tv":0.0,"id":11445383}]}]}
{"op":"mcm","clk":"11895214822","pt":1724248403145,"mc":[{"id":"1.232013126","rc":[{"batb":[[0,1.27,6.35],[1,1.2,1105],[2,1.04,1.53]],"ltp":0.0,"tv":0.0,"id":35736915},{"batb":[[0,1.27,7.15],[1,1.2,1105],[2,1.04,1.53]],"ltp":0.0,"tv":0.0,"id":11445383}]}]}
{"op":"mcm","clk":"11895215939","pt":1724248420593,"mc":[{"id":"1.232013126","rc":[{"batl":[[0,5.9,10.94]],"ltp":0.0,"tv":0.0,"id":35736915},{"batl":[[0,5.9,10.93]],"ltp":0.0,"tv":0.0,"id":11445383}]}]}
{"op":"mcm","clk":"11895216904","pt":1724248434699,"mc":[{"id":"1.232013126","rc":[{"batb":[[0,1.28,30.61],[1,1.27,6.35],[2,1.2,1105]],"ltp":0.0,"tv":0.0,"id":35736915},{"batb":[[0,1.28,30.61],[1,1.27,7.15],[2,1.2,1105]],"ltp":0.0,"tv":0.0,"id":11445383}]}]}
{"op":"mcm","clk":"11895368593","pt":1724250235229,"mc":[{"id":"1.232013126","rc":[{"batb":[[0,1.27,6.35],[1,1.2,1105],[2,1.04,1.53]],"ltp":0.0,"tv":0.0,"id":35736915},{"batb":[[0,1.27,7.15],[1,1.2,1105],[2,1.04,1.53]],"ltp":0.0,"tv":0.0,"id":11445383}]}]}
{"op":"mcm","clk":"11895368977","pt":1724250239279,"mc":[{"id":"1.232013126","rc":[{"batl":[[0,5.9,10.95]],"ltp":0.0,"tv":0.0,"id":35736915},{"batl":[[0,5.9,10.93]],"ltp":0.0,"tv":0.0,"id":11445383}]}]}
{"op":"mcm","clk":"11895370205","pt":1724250253921,"mc":[{"id":"1.232013126","rc":[{"batb":[[0,1.28,30.57],[1,1.27,6.35],[2,1.2,1105]],"ltp":0.0,"tv":0.0,"id":35736915},{"batb":[[0,1.28,30.57],[1,1.27,7.15],[2,1.2,1105]],"ltp":0.0,"tv":0.0,"id":11445383}]}]}
{"op":"mcm","clk":"11895533895","pt":1724252054372,"mc":[{"id":"1.232013126","rc":[{"batb":[[0,1.27,6.35],[1,1.2,1105],[2,1.04,1.53]],"ltp":0.0,"tv":0.0,"id":35736915},{"batb":[[0,1.27,7.15],[1,1.2,1105],[2,1.04,1.53]],"ltp":0.0,"tv":0.0,"id":11445383}]}]}
{"op":"mcm","clk":"11895535432","pt":1724252072092,"mc":[{"id":"1.232013126","rc":[{"batl":[[0,5.9,10.95]],"ltp":0.0,"tv":0.0,"id":35736915},{"batl":[[0,5.9,10.93]],"ltp":0.0,"tv":0.0,"id":11445383}]}]}
{"op":"mcm","clk":"11895543652","pt":1724252168110,"mc":[{"id":"1.232013126","rc":[{"batb":[[0,1.28,30.57],[1,1.27,6.35],[2,1.2,1105]],"ltp":0.0,"tv":0.0,"id":35736915},{"batb":[[0,1.28,30.57],[1,1.27,7.15],[2,1.2,1105]],"ltp":0.0,"tv":0.0,"id":11445383}]}]}
{"op":"mcm","clk":"11895660693","pt":1724253175133,"mc":[{"id":"1.232013126","rc":[{"batb":[[1,1.27,6.35]],"ltp":0.0,"tv":0.0,"id":35736915},{"batb":[[1,1.27,7.14]],"ltp":0.0,"tv":0.0,"id":11445383}]}]}
{"op":"mcm","clk":"11895766501","pt":1724253968935,"mc":[{"id":"1.232013126","rc":[{"batb":[[0,1.27,6.35],[1,1.2,1105],[2,1.04,1.53]],"ltp":0.0,"tv":0.0,"id":35736915},{"batb":[[0,1.27,7.14],[1,1.2,1105],[2,1.04,1.53]],"ltp":0.0,"tv":0.0,"id":11445383}]}]}
{"op":"mcm","clk":"11895767955","pt":1724253979418,"mc":[{"id":"1.232013126","rc":[{"batl":[[0,5.9,10.95]],"ltp":0.0,"tv":0.0,"id":35736915},{"batl":[[0,5.9,10.93]],"ltp":0.0,"tv":0.0,"id":11445383}]}]}
{"op":"mcm","clk":"11895787502","pt":1724254136788,"mc":[{"id":"1.232013126","rc":[{"batb":[[0,1.28,30.57],[1,1.27,6.35],[2,1.2,1105]],"ltp":0.0,"tv":0.0,"id":35736915},{"batb":[[0,1.28,30.57],[1,1.27,7.14],[2,1.2,1105]],"ltp":0.0,"tv":0.0,"id":11445383}]}]}
{"op":"mcm","clk":"11896053850","pt":1724255937814,"mc":[{"id":"1.232013126","rc":[{"batb":[[0,1.27,6.35],[1,1.2,1105],[2,1.04,1.53]],"ltp":0.0,"tv":0.0,"id":35736915},{"batb":[[0,1.27,7.14],[1,1.2,1105],[2,1.04,1.53]],"ltp":0.0,"tv":0.0,"id":11445383}]}]}
{"op":"mcm","clk":"11896054226","pt":1724255940716,"mc":[{"id":"1.232013126","rc":[{"batl":[[0,5.9,10.95]],"ltp":0.0,"tv":0.0,"id":35736915},{"batl":[[0,5.9,10.93]],"ltp":0.0,"tv":0.0,"id":11445383}]}]}
{"op":"mcm","clk":"11896078527","pt":1724256102468,"mc":[{"id":"1.232013126","rc":[{"batb":[[0,1.28,30.58],[1,1.27,6.34],[2,1.2,1105]],"batl":[[0,5.9,10.95]],"ltp":0.0,"tv":0.0,"id":35736915},{"batb":[[0,1.28,30.58],[1,1.27,7.13],[2,1.2,1105]],"batl":[[0,5.9,10.93]],"ltp":0.0,"tv":0.0,"id":11445383}]}]}
{"op":"mcm","clk":"11896372048","pt":1724257903205,"mc":[{"id":"1.232013126","rc":[{"batb":[[0,1.27,6.34],[1,1.2,1105],[2,1.04,1.53]],"ltp":0.0,"tv":0.0,"id":35736915},{"batb":[[0,1.27,7.13],[1,1.2,1105],[2,1.04,1.53]],"ltp":0.0,"tv":0.0,"id":11445383}]}]}
{"op":"mcm","clk":"11896373121","pt":1724257909520,"mc":[{"id":"1.232013126","rc":[{"batl":[[0,5.9,10.94]],"ltp":0.0,"tv":0.0,"id":35736915},{"batl":[[0,5.9,10.93]],"ltp":0.0,"tv":0.0,"id":11445383}]}]}
{"op":"mcm","clk":"11896396553","pt":1724258049046,"mc":[{"id":"1.232013126","rc":[{"batb":[[0,1.28,30.58],[1,1.27,6.34],[2,1.2,1105]],"ltp":0.0,"tv":0.0,"id":35736915},{"batb":[[0,1.28,30.58],[1,1.27,7.13],[2,1.2,1105]],"ltp":0.0,"tv":0.0,"id":11445383}]}]}
{"op":"mcm","clk":"11896723237","pt":1724259849433,"mc":[{"id":"1.232013126","rc":[{"batb":[[0,1.28,30.56],[1,1.27,6.33]],"ltp":0.0,"tv":0.0,"id":35736915},{"batb":[[0,1.27,7.13],[1,1.2,1105],[2,1.04,1.53]],"ltp":0.0,"tv":0.0,"id":11445383}]}]}
{"op":"mcm","clk":"11896723348","pt":1724259850021,"mc":[{"id":"1.232013126","rc":[{"batb":[[0,1.27,6.33],[1,1.2,1105],[2,1.04,1.53]],"batl":[[0,5.9,10.94]],"ltp":0.0,"tv":0.0,"id":35736915},{"batl":[[0,5.9,10.93]],"ltp":0.0,"tv":0.0,"id":11445383}]}]}
{"op":"mcm","clk":"11896750706","pt":1724260003378,"mc":[{"id":"1.232013126","rc":[{"batb":[[0,1.28,30.56],[1,1.27,6.33],[2,1.2,1105]],"ltp":0.0,"tv":0.0,"id":35736915},{"batb":[[0,1.28,30.56],[1,1.27,7.13],[2,1.2,1105]],"ltp":0.0,"tv":0.0,"id":11445383}]}]}
{"op":"mcm","clk":"11897050664","pt":1724261803925,"mc":[{"id":"1.232013126","rc":[{"batb":[[0,1.27,6.33],[1,1.2,1105],[2,1.04,1.53]],"ltp":0.0,"tv":0.0,"id":35736915},{"batb":[[0,1.27,7.13],[1,1.2,1105],[2,1.04,1.53]],"ltp":0.0,"tv":0.0,"id":11445383}]}]}
{"op":"mcm","clk":"11897051532","pt":1724261809206,"mc":[{"id":"1.232013126","rc":[{"batl":[[0,5.9,10.94]],"ltp":0.0,"tv":0.0,"id":35736915},{"batl":[[0,5.9,10.93]],"ltp":0.0,"tv":0.0,"id":11445383}]}]}
{"op":"mcm","clk":"11897069667","pt":1724261923366,"mc":[{"id":"1.232013126","rc":[{"batb":[[0,1.28,30.56],[1,1.27,6.33],[2,1.2,1105]],"ltp":0.0,"tv":0.0,"id":35736915},{"batb":[[0,1.28,30.56],[1,1.27,7.13],[2,1.2,1105]],"ltp":0.0,"tv":0.0,"id":11445383}]}]}
{"op":"mcm","clk":"11897339976","pt":1724263724194,"mc":[{"id":"1.232013126","rc":[{"batb":[[0,1.27,6.33],[1,1.2,1105],[2,1.04,1.53]],"ltp":0.0,"tv":0.0,"id":35736915},{"batb":[[0,1.27,7.12],[1,1.2,1105],[2,1.04,1.53]],"ltp":0.0,"tv":0.0,"id":11445383}]}]}
{"op":"mcm","clk":"11897341972","pt":1724263735041,"mc":[{"id":"1.232013126","rc":[{"batl":[[0,5.9,10.95]],"ltp":0.0,"tv":0.0,"id":35736915},{"batl":[[0,5.9,10.94]],"ltp":0.0,"tv":0.0,"id":11445383}]}]}
{"op":"mcm","clk":"11897350570","pt":1724263783175,"mc":[{"id":"1.232013126","rc":[{"batb":[[0,1.28,30.57],[1,1.27,6.33],[2,1.2,1105]],"ltp":0.0,"tv":0.0,"id":35736915},{"batb":[[0,1.28,30.57],[1,1.27,7.12],[2,1.2,1105]],"ltp":0.0,"tv":0.0,"id":11445383}]}]}
{"op":"mcm","clk":"11897699102","pt":1724265584329,"mc":[{"id":"1.232013126","rc":[{"batb":[[0,1.27,6.33],[1,1.2,1105],[2,1.04,1.53]],"ltp":0.0,"tv":0.0,"id":35736915},{"batb":[[0,1.27,7.12],[1,1.2,1105],[2,1.04,1.53]],"ltp":0.0,"tv":0.0,"id":11445383}]}]}
{"op":"mcm","clk":"11897699395","pt":1724265585924,"mc":[{"id":"1.232013126","rc":[{"batl":[[0,5.9,10.95]],"ltp":0.0,"tv":0.0,"id":35736915},{"batl":[[0,5.9,10.94]],"ltp":0.0,"tv":0.0,"id":11445383}]}]}
{"op":"mcm","clk":"11897704297","pt":1724265612189,"mc":[{"id":"1.232013126","rc":[{"batb":[[0,1.28,30.57],[1,1.27,6.33],[2,1.2,1105]],"ltp":0.0,"tv":0.0,"id":35736915},{"batb":[[0,1.28,30.57],[1,1.27,7.12],[2,1.2,1105]],"ltp":0.0,"tv":0.0,"id":11445383}]}]}
{"op":"mcm","clk":"11897987376","pt":1724267412844,"mc":[{"id":"1.232013126","rc":[{"batb":[[0,1.27,6.33],[1,1.2,1105],[2,1.04,1.53]],"ltp":0.0,"tv":0.0,"id":35736915},{"batb":[[0,1.27,7.12],[1,1.2,1105],[2,1.04,1.53]],"ltp":0.0,"tv":0.0,"id":11445383}]}]}
{"op":"mcm","clk":"11897989397","pt":1724267424215,"mc":[{"id":"1.232013126","rc":[{"batl":[[0,5.9,10.94]],"ltp":0.0,"tv":0.0,"id":35736915},{"batl":[[0,5.9,10.93]],"ltp":0.0,"tv":0.0,"id":11445383}]}]}
{"op":"mcm","clk":"11898017106","pt":1724267586354,"mc":[{"id":"1.232013126","rc":[{"batb":[[0,1.28,30.56],[1,1.27,6.33],[2,1.2,1105]],"ltp":0.0,"tv":0.0,"id":35736915},{"batb":[[0,1.28,30.56],[1,1.27,7.12],[2,1.2,1105]],"ltp":0.0,"tv":0.0,"id":11445383}]}]}
{"op":"mcm","clk":"11898289497","pt":1724269387337,"mc":[{"id":"1.232013126","rc":[{"batb":[[0,1.27,6.33],[1,1.2,1105],[2,1.04,1.53]],"ltp":0.0,"tv":0.0,"id":35736915},{"batb":[[0,1.27,7.12],[1,1.2,1105],[2,1.04,1.53]],"ltp":0.0,"tv":0.0,"id":11445383}]}]}
{"op":"mcm","clk":"11898290426","pt":1724269393642,"mc":[{"id":"1.232013126","rc":[{"batl":[[0,5.9,10.94]],"ltp":0.0,"tv":0.0,"id":35736915},{"batl":[[0,5.9,10.93]],"ltp":0.0,"tv":0.0,"id":11445383}]}]}
{"op":"mcm","clk":"11898304072","pt":1724269493464,"mc":[{"id":"1.232013126","rc":[{"batb":[[0,1.28,30.56],[1,1.27,6.33],[2,1.2,1105]],"ltp":0.0,"tv":0.0,"id":35736915},{"batb":[[0,1.28,30.56],[1,1.27,7.12],[2,1.2,1105]],"ltp":0.0,"tv":0.0,"id":11445383}]}]}
{"op":"mcm","clk":"11898474998","pt":1724271294375,"mc":[{"id":"1.232013126","rc":[{"batb":[[0,1.27,6.33],[1,1.2,1105],[2,1.04,1.53]],"ltp":0.0,"tv":0.0,"id":35736915},{"batb":[[0,1.27,7.13],[1,1.2,1105],[2,1.04,1.53]],"ltp":0.0,"tv":0.0,"id":11445383}]}]}
{"op":"mcm","clk":"11898475339","pt":1724271298207,"mc":[{"id":"1.232013126","rc":[{"batl":[[0,5.9,10.94]],"ltp":0.0,"tv":0.0,"id":35736915},{"batl":[[0,5.9,10.93]],"ltp":0.0,"tv":0.0,"id":11445383}]}]}
{"op":"mcm","clk":"11898487399","pt":1724271426191,"mc":[{"id":"1.232013126","rc":[{"batb":[[0,1.28,30.58],[1,1.27,6.33],[2,1.2,1105]],"ltp":0.0,"tv":0.0,"id":35736915},{"batb":[[0,1.28,30.58],[1,1.27,7.13],[2,1.2,1105]],"ltp":0.0,"tv":0.0,"id":11445383}]}]}
{"op":"mcm","clk":"11898634458","pt":1724273227428,"mc":[{"id":"1.232013126","rc":[{"batb":[[0,1.27,6.33],[1,1.2,1105],[2,1.04,1.53]],"ltp":0.0,"tv":0.0,"id":35736915}]}]}
{"op":"mcm","clk":"11898634473","pt":1724273227635,"mc":[{"id":"1.232013126","rc":[{"batb":[[0,1.27,7.13],[1,1.2,1105],[2,1.04,1.53]],"ltp":0.0,"tv":0.0,"id":11445383}]}]}
{"op":"mcm","clk":"11898634759","pt":1724273231439,"mc":[{"id":"1.232013126","rc":[{"batl":[[0,5.9,10.94]],"ltp":0.0,"tv":0.0,"id":35736915},{"batl":[[0,5.9,10.93]],"ltp":0.0,"tv":0.0,"id":11445383}]}]}
{"op":"mcm","clk":"11898638788","pt":1724273288673,"mc":[{"id":"1.232013126","rc":[{"batb":[[0,1.28,30.58],[1,1.27,6.33],[2,1.2,1105]],"ltp":0.0,"tv":0.0,"id":35736915},{"batb":[[0,1.28,30.58],[1,1.27,7.13],[2,1.2,1105]],"ltp":0.0,"tv":0.0,"id":11445383}]}]}
{"op":"mcm","clk":"11898721359","pt":1724274775081,"mc":[{"id":"1.232013126","rc":[{"batb":[[0,1.28,30.57]],"ltp":0.0,"tv":0.0,"id":35736915},{"batb":[[0,1.28,30.57]],"ltp":0.0,"tv":0.0,"id":11445383}]}]}
{"op":"mcm","clk":"11898735618","pt":1724275089765,"mc":[{"id":"1.232013126","rc":[{"batb":[[0,1.27,6.33],[1,1.2,1105],[2,1.04,1.53]],"ltp":0.0,"tv":0.0,"id":35736915},{"batb":[[0,1.27,7.13],[1,1.2,1105],[2,1.04,1.53]],"ltp":0.0,"tv":0.0,"id":11445383}]}]}
{"op":"mcm","clk":"11898736235","pt":1724275101656,"mc":[{"id":"1.232013126","rc":[{"batl":[[0,5.9,10.95]],"ltp":0.0,"tv":0.0,"id":35736915},{"batl":[[0,5.9,10.94]],"ltp":0.0,"tv":0.0,"id":11445383}]}]}
{"op":"mcm","clk":"11898736688","pt":1724275111790,"mc":[{"id":"1.232013126","rc":[{"batb":[[0,1.28,30.57],[1,1.27,6.33],[2,1.2,1105]],"ltp":0.0,"tv":0.0,"id":35736915},{"batb":[[0,1.28,30.57],[1,1.27,7.13],[2,1.2,1105]],"ltp":0.0,"tv":0.0,"id":11445383}]}]}
{"op":"mcm","clk":"11898816030","pt":1724276912859,"mc":[{"id":"1.232013126","rc":[{"batb":[[0,1.27,6.33],[1,1.2,1105],[2,1.04,1.53]],"ltp":0.0,"tv":0.0,"id":35736915},{"batb":[[0,1.27,7.13],[1,1.2,1105],[2,1.04,1.53]],"ltp":0.0,"tv":0.0,"id":11445383}]}]}
{"op":"mcm","clk":"11898816360","pt":1724276920094,"mc":[{"id":"1.232013126","rc":[{"batl":[[0,5.9,10.95]],"ltp":0.0,"tv":0.0,"id":35736915},{"batl":[[0,5.9,10.94]],"ltp":0.0,"tv":0.0,"id":11445383}]}]}
{"op":"mcm","clk":"11898824439","pt":1724277090286,"mc":[{"id":"1.232013126","rc":[{"batb":[[0,1.28,30.57],[1,1.27,6.33],[2,1.2,1105]],"ltp":0.0,"tv":0.0,"id":35736915},{"batb":[[0,1.28,30.57],[1,1.27,7.13],[2,1.2,1105]],"ltp":0.0,"tv":0.0,"id":11445383}]}]}
{"op":"mcm","clk":"11898923552","pt":1724278890973,"mc":[{"id":"1.232013126","rc":[{"batb":[[0,1.27,6.33],[1,1.2,1105],[2,1.04,1.53]],"ltp":0.0,"tv":0.0,"id":35736915},{"batb":[[0,1.27,7.13],[1,1.2,1105],[2,1.04,1.53]],"ltp":0.0,"tv":0.0,"id":11445383}]}]}
{"op":"mcm","clk":"11898924429","pt":1724278904505,"mc":[{"id":"1.232013126","rc":[{"batl":[[0,5.9,10.94]],"ltp":0.0,"tv":0.0,"id":35736915},{"batl":[[0,5.9,10.93]],"ltp":0.0,"tv":0.0,"id":11445383}]}]}
{"op":"mcm","clk":"11898932289","pt":1724279031542,"mc":[{"id":"1.232013126","rc":[{"batb":[[0,1.28,30.56],[1,1.27,6.33],[2,1.2,1105]],"ltp":0.0,"tv":0.0,"id":35736915},{"batb":[[0,1.28,30.56],[1,1.27,7.13],[2,1.2,1105]],"ltp":0.0,"tv":0.0,"id":11445383}]}]}
{"op":"mcm","clk":"11899045837","pt":1724280832454,"mc":[{"id":"1.232013126","rc":[{"batb":[[0,1.27,6.33],[1,1.2,1105],[2,1.04,1.53]],"ltp":0.0,"tv":0.0,"id":35736915},{"batb":[[0,1.27,7.13],[1,1.2,1105],[2,1.04,1.53]],"ltp":0.0,"tv":0.0,"id":11445383}]}]}
{"op":"mcm","clk":"11899046124","pt":1724280837588,"mc":[{"id":"1.232013126","rc":[{"batl":[[0,5.9,10.94]],"ltp":0.0,"tv":0.0,"id":35736915},{"batl":[[0,5.9,10.93]],"ltp":0.0,"tv":0.0,"id":11445383}]}]}
{"op":"mcm","clk":"11899051691","pt":1724280949329,"mc":[{"id":"1.232013126","rc":[{"batb":[[0,1.28,30.56],[1,1.27,6.33],[2,1.2,1105]],"ltp":0.0,"tv":0.0,"id":35736915},{"batb":[[0,1.28,30.56],[1,1.27,7.13],[2,1.2,1105]],"ltp":0.0,"tv":0.0,"id":11445383}]}]}
{"op":"mcm","clk":"11899138543","pt":1724282750260,"mc":[{"id":"1.232013126","rc":[{"batb":[[0,1.27,6.33],[1,1.2,1105],[2,1.04,1.53]],"ltp":0.0,"tv":0.0,"id":35736915},{"batb":[[0,1.27,7.13],[1,1.2,1105],[2,1.04,1.53]],"ltp":0.0,"tv":0.0,"id":11445383}]}]}
{"op":"mcm","clk":"11899138598","pt":1724282751036,"mc":[{"id":"1.232013126","rc":[{"batl":[[0,5.9,10.94]],"ltp":0.0,"tv":0.0,"id":35736915},{"batl":[[0,5.9,10.93]],"ltp":0.0,"tv":0.0,"id":11445383}]}]}
{"op":"mcm","clk":"11899142849","pt":1724282844072,"mc":[{"id":"1.232013126","rc":[{"batb":[[0,1.28,30.58],[1,1.27,6.33],[2,1.2,1105]],"ltp":0.0,"tv":0.0,"id":35736915},{"batb":[[0,1.28,30.58],[1,1.27,7.13],[2,1.2,1105]],"ltp":0.0,"tv":0.0,"id":11445383}]}]}
{"op":"mcm","clk":"11899223205","pt":1724284645201,"mc":[{"id":"1.232013126","rc":[{"batb":[[0,1.27,6.33],[1,1.2,1105],[2,1.04,1.53]],"ltp":0.0,"tv":0.0,"id":35736915},{"batb":[[0,1.27,7.13],[1,1.2,1105],[2,1.04,1.53]],"ltp":0.0,"tv":0.0,"id":11445383}]}]}
{"op":"mcm","clk":"11899223605","pt":1724284652513,"mc":[{"id":"1.232013126","rc":[{"batl":[[0,5.9,10.94]],"ltp":0.0,"tv":0.0,"id":35736915},{"batl":[[0,5.9,10.93]],"ltp":0.0,"tv":0.0,"id":11445383}]}]}
{"op":"mcm","clk":"11899227387","pt":1724284721285,"mc":[{"id":"1.232013126","rc":[{"batb":[[0,1.28,30.58],[1,1.27,6.33],[2,1.2,1105]],"ltp":0.0,"tv":0.0,"id":35736915},{"batb":[[0,1.28,30.58],[1,1.27,7.13],[2,1.2,1105]],"ltp":0.0,"tv":0.0,"id":11445383}]}]}
{"op":"mcm","clk":"11899333914","pt":1724286522154,"mc":[{"id":"1.232013126","rc":[{"batb":[[0,1.27,6.33],[1,1.2,1105],[2,1.04,1.53]],"ltp":0.0,"tv":0.0,"id":35736915},{"batb":[[0,1.27,7.13],[1,1.2,1105],[2,1.04,1.53]],"ltp":0.0,"tv":0.0,"id":11445383}]}]}
{"op":"mcm","clk":"11899334156","pt":1724286527185,"mc":[{"id":"1.232013126","rc":[{"batl":[[0,5.9,10.95]],"ltp":0.0,"tv":0.0,"id":35736915},{"batl":[[0,5.9,10.93]],"ltp":0.0,"tv":0.0,"id":11445383}]}]}
{"op":"mcm","clk":"11899336578","pt":1724286573697,"mc":[{"id":"1.232013126","rc":[{"batb":[[0,1.28,30.58],[1,1.27,6.33],[2,1.2,1105]],"ltp":0.0,"tv":0.0,"id":35736915},{"batb":[[0,1.28,30.58],[1,1.27,7.13],[2,1.2,1105]],"ltp":0.0,"tv":0.0,"id":11445383}]}]}
{"op":"mcm","clk":"11899441333","pt":1724288374396,"mc":[{"id":"1.232013126","rc":[{"batb":[[0,1.27,6.33],[1,1.2,1105],[2,1.04,1.53]],"ltp":0.0,"tv":0.0,"id":35736915}]}]}
{"op":"mcm","clk":"11899441344","pt":1724288374600,"mc":[{"id":"1.232013126","rc":[{"batb":[[0,1.27,7.13],[1,1.2,1105],[2,1.04,1.53]],"ltp":0.0,"tv":0.0,"id":11445383}]}]}
{"op":"mcm","clk":"11899441860","pt":1724288384173,"mc":[{"id":"1.232013126","rc":[{"batl":[[0,5.9,10.95]],"ltp":0.0,"tv":0.0,"id":35736915},{"batl":[[0,5.9,10.93]],"ltp":0.0,"tv":0.0,"id":11445383}]}]}
{"op":"mcm","clk":"11899443310","pt":1724288407603,"mc":[{"id":"1.232013126","rc":[{"batb":[[0,1.28,30.56],[1,1.27,6.33],[2,1.2,1105]],"batl":[[0,5.9,10.94]],"ltp":0.0,"tv":0.0,"id":35736915},{"batb":[[0,1.28,30.56],[1,1.27,7.13],[2,1.2,1105]],"batl":[[0,5.9,10.93]],"ltp":0.0,"tv":0.0,"id":11445383}]}]}
{"op":"mcm","clk":"11899548729","pt":1724290208753,"mc":[{"id":"1.232013126","rc":[{"batb":[[0,1.27,6.33],[1,1.2,1105],[2,1.04,1.53]],"ltp":0.0,"tv":0.0,"id":35736915},{"batb":[[0,1.27,7.13],[1,1.2,1105],[2,1.04,1.53]],"ltp":0.0,"tv":0.0,"id":11445383}]}]}
{"op":"mcm","clk":"11899549073","pt":1724290215334,"mc":[{"id":"1.232013126","rc":[{"batl":[[0,5.9,10.94]],"ltp":0.0,"tv":0.0,"id":35736915},{"batl":[[0,5.9,10.93]],"ltp":0.0,"tv":0.0,"id":11445383}]}]}
{"op":"mcm","clk":"11899549436","pt":1724290221648,"mc":[{"id":"1.232013126","rc":[{"batb":[[0,1.28,30.56],[1,1.27,6.33],[2,1.2,1105]],"ltp":0.0,"tv":0.0,"id":35736915},{"batb":[[0,1.28,30.56],[1,1.27,7.13],[2,1.2,1105]],"ltp":0.0,"tv":0.0,"id":11445383}]}]}
{"op":"mcm","clk":"11899650047","pt":1724292022301,"mc":[{"id":"1.232013126","rc":[{"batb":[[0,1.27,6.34],[1,1.2,1105],[2,1.04,1.53]],"ltp":0.0,"tv":0.0,"id":35736915},{"batb":[[0,1.27,7.13],[1,1.2,1105],[2,1.04,1.53]],"ltp":0.0,"tv":0.0,"id":11445383}]}]}
{"op":"mcm","clk":"11899650122","pt":1724292024198,"mc":[{"id":"1.232013126","rc":[{"batl":[[0,5.9,10.94]],"ltp":0.0,"tv":0.0,"id":35736915},{"batl":[[0,5.9,10.93]],"ltp":0.0,"tv":0.0,"id":11445383}]}]}
{"op":"mcm","clk":"11899656704","pt":1724292181153,"mc":[{"id":"1.232013126","rc":[{"batb":[[0,1.28,30.56],[1,1.27,6.34],[2,1.2,1105]],"ltp":0.0,"tv":0.0,"id":35736915},{"batb":[[0,1.28,30.56],[1,1.27,7.13],[2,1.2,1105]],"ltp":0.0,"tv":0.0,"id":11445383}]}]}
{"op":"mcm","clk":"11899726084","pt":1724293982300,"mc":[{"id":"1.232013126","rc":[{"batb":[[0,1.27,6.34],[1,1.2,1105],[2,1.04,1.53]],"ltp":0.0,"tv":0.0,"id":35736915},{"batb":[[0,1.27,7.13],[1,1.2,1105],[2,1.04,1.53]],"ltp":0.0,"tv":0.0,"id":11445383}]}]}
{"op":"mcm","clk":"11899730249","pt":1724294116538,"mc":[{"id":"1.232013126","rc":[{"batb":[[0,1.28,30.56],[1,1.27,6.34],[2,1.2,1105]],"ltp":0.0,"tv":0.0,"id":35736915},{"batb":[[0,1.28,30.56],[1,1.27,7.13],[2,1.2,1105]],"ltp":0.0,"tv":0.0,"id":11445383}]}]}
{"op":"mcm","clk":"11899800759","pt":1724295917377,"mc":[{"id":"1.232013126","rc":[{"batb":[[0,1.27,6.34],[1,1.2,1105],[2,1.04,1.53]],"ltp":0.0,"tv":0.0,"id":35736915},{"batb":[[0,1.27,7.13],[1,1.2,1105],[2,1.04,1.53]],"ltp":0.0,"tv":0.0,"id":11445383}]}]}
{"op":"mcm","clk":"11899801067","pt":1724295926996,"mc":[{"id":"1.232013126","rc":[{"batl":[[0,5.9,10.94]],"ltp":0.0,"tv":0.0,"id":35736915},{"batl":[[0,5.9,10.93]],"ltp":0.0,"tv":0.0,"id":11445383}]}]}
{"op":"mcm","clk":"11899804556","pt":1724296027997,"mc":[{"id":"1.232013126","rc":[{"batb":[[0,1.28,30.56],[1,1.27,6.34],[2,1.2,1105]],"ltp":0.0,"tv":0.0,"id":35736915},{"batb":[[0,1.28,30.56],[1,1.27,7.13],[2,1.2,1105]],"ltp":0.0,"tv":0.0,"id":11445383}]}]}
{"op":"mcm","clk":"11899881629","pt":1724297828989,"mc":[{"id":"1.232013126","rc":[{"batb":[[0,1.27,6.34],[1,1.2,1105],[2,1.04,1.53]],"ltp":0.0,"tv":0.0,"id":35736915},{"batb":[[0,1.27,7.13],[1,1.2,1105],[2,1.04,1.53]],"ltp":0.0,"tv":0.0,"id":11445383}]}]}
{"op":"mcm","clk":"11899881776","pt":1724297832686,"mc":[{"id":"1.232013126","rc":[{"batl":[[0,5.9,10.94]],"ltp":0.0,"tv":0.0,"id":35736915},{"batl":[[0,5.9,10.93]],"ltp":0.0,"tv":0.0,"id":11445383}]}]}
{"op":"mcm","clk":"11899884707","pt":1724297927250,"mc":[{"id":"1.232013126","rc":[{"batb":[[0,1.28,30.56],[1,1.27,6.34],[2,1.2,1105]],"ltp":0.0,"tv":0.0,"id":35736915},{"batb":[[0,1.28,30.56],[1,1.27,7.13],[2,1.2,1105]],"ltp":0.0,"tv":0.0,"id":11445383}]}]}
{"op":"mcm","clk":"11899943261","pt":1724299728769,"mc":[{"id":"1.232013126","rc":[{"batb":[[0,1.27,6.34],[1,1.2,1105],[2,1.04,1.53]],"ltp":0.0,"tv":0.0,"id":35736915},{"batb":[[0,1.27,7.13],[1,1.2,1105],[2,1.04,1.53]],"ltp":0.0,"tv":0.0,"id":11445383}]}]}
{"op":"mcm","clk":"11899943683","pt":1724299746582,"mc":[{"id":"1.232013126","rc":[{"batl":[[0,5.9,10.94]],"ltp":0.0,"tv":0.0,"id":35736915},{"batl":[[0,5.9,10.94]],"ltp":0.0,"tv":0.0,"id":11445383}]}]}
{"op":"mcm","clk":"11899945294","pt":1724299814345,"mc":[{"id":"1.232013126","rc":[{"batb":[[0,1.28,30.56],[1,1.27,6.34],[2,1.2,1105]],"ltp":0.0,"tv":0.0,"id":35736915},{"batb":[[0,1.28,30.56],[1,1.27,7.13],[2,1.2,1105]],"ltp":0.0,"tv":0.0,"id":11445383}]}]}
{"op":"mcm","clk":"11899986426","pt":1724301615523,"mc":[{"id":"1.232013126","rc":[{"batb":[[0,1.27,6.34],[1,1.2,1105],[2,1.04,1.53]],"ltp":0.0,"tv":0.0,"id":35736915},{"batb":[[0,1.27,7.13],[1,1.2,1105],[2,1.04,1.53]],"ltp":0.0,"tv":0.0,"id":11445383}]}]}
{"op":"mcm","clk":"11899986783","pt":1724301627799,"mc":[{"id":"1.232013126","rc":[{"batl":[[0,5.9,10.94]],"ltp":0.0,"tv":0.0,"id":35736915},{"batl":[[0,5.9,10.94]],"ltp":0.0,"tv":0.0,"id":11445383}]}]}
{"op":"mcm","clk":"11899988506","pt":1724301691825,"mc":[{"id":"1.232013126","rc":[{"batb":[[0,1.28,30.56],[1,1.27,6.34],[2,1.2,1105]],"ltp":0.0,"tv":0.0,"id":35736915},{"batb":[[0,1.28,30.56],[1,1.27,7.13],[2,1.2,1105]],"ltp":0.0,"tv":0.0,"id":11445383}]}]}
{"op":"mcm","clk":"11900044480","pt":1724303492896,"mc":[{"id":"1.232013126","rc":[{"batb":[[0,1.27,6.34],[1,1.2,1105],[2,1.04,1.53]],"ltp":0.0,"tv":0.0,"id":35736915},{"batb":[[0,1.27,7.13],[1,1.2,1105],[2,1.04,1.53]],"ltp":0.0,"tv":0.0,"id":11445383}]}]}
{"op":"mcm","clk":"11900044576","pt":1724303495249,"mc":[{"id":"1.232013126","rc":[{"batl":[[0,5.9,10.94]],"ltp":0.0,"tv":0.0,"id":35736915},{"batl":[[0,5.9,10.94]],"ltp":0.0,"tv":0.0,"id":11445383}]}]}
{"op":"mcm","clk":"11900046531","pt":1724303568714,"mc":[{"id":"1.232013126","rc":[{"batb":[[0,1.28,30.57],[1,1.27,6.34],[2,1.2,1105]],"ltp":0.0,"tv":0.0,"id":35736915},{"batb":[[0,1.28,30.57],[1,1.27,7.13],[2,1.2,1105]],"ltp":0.0,"tv":0.0,"id":11445383}]}]}
{"op":"mcm","clk":"11900095923","pt":1724305369810,"mc":[{"id":"1.232013126","rc":[{"batb":[[0,1.27,6.34],[1,1.2,1105],[2,1.04,1.53]],"ltp":0.0,"tv":0.0,"id":35736915},{"batb":[[0,1.27,7.13],[1,1.2,1105],[2,1.04,1.53]],"ltp":0.0,"tv":0.0,"id":11445383}]}]}
{"op":"mcm","clk":"11900095988","pt":1724305372874,"mc":[{"id":"1.232013126","rc":[{"batl":[[0,5.9,10.94]],"ltp":0.0,"tv":0.0,"id":35736915},{"batl":[[0,5.9,10.94]],"ltp":0.0,"tv":0.0,"id":11445383}]}]}
{"op":"mcm","clk":"11900098959","pt":1724305473793,"mc":[{"id":"1.232013126","rc":[{"batb":[[0,1.28,30.57],[1,1.27,6.34],[2,1.2,1105]],"ltp":0.0,"tv":0.0,"id":35736915},{"batb":[[0,1.28,30.57],[1,1.27,7.13],[2,1.2,1105]],"ltp":0.0,"tv":0.0,"id":11445383}]}]}
{"op":"mcm","clk":"11900157767","pt":1724307175201,"mc":[{"id":"1.232013126","rc":[{"batb":[[0,1.28,30.57]],"ltp":0.0,"tv":0.0,"id":35736915},{"batb":[[0,1.28,30.57]],"ltp":0.0,"tv":0.0,"id":11445383}]}]}
{"op":"mcm","clk":"11900162391","pt":1724307275344,"mc":[{"id":"1.232013126","rc":[{"batb":[[0,1.27,7.13],[1,1.2,1105],[2,1.04,1.53]],"ltp":0.0,"tv":0.0,"id":11445383}]}]}
{"op":"mcm","clk":"11900162404","pt":1724307275575,"mc":[{"id":"1.232013126","rc":[{"batb":[[0,1.27,6.34],[1,1.2,1105],[2,1.04,1.53]],"ltp":0.0,"tv":0.0,"id":35736915}]}]}
{"op":"mcm","clk":"11900162523","pt":1724307278762,"mc":[{"id":"1.232013126","rc":[{"batl":[[0,5.9,10.94]],"ltp":0.0,"tv":0.0,"id":35736915},{"batl":[[0,5.9,10.94]],"ltp":0.0,"tv":0.0,"id":11445383}]}]}
{"op":"mcm","clk":"11900167051","pt":1724307404300,"mc":[{"id":"1.232013126","rc":[{"batb":[[0,1.28,30.57],[1,1.27,6.34],[2,1.2,1105]],"ltp":0.0,"tv":0.0,"id":35736915},{"batb":[[0,1.28,30.57],[1,1.27,7.13],[2,1.2,1105]],"ltp":0.0,"tv":0.0,"id":11445383}]}]}
{"op":"mcm","clk":"11900222198","pt":1724309203866,"mc":[{"id":"1.232013126","rc":[{"batb":[[0,1.27,6.34],[1,1.2,1105],[2,1.04,1.53]],"ltp":0.0,"tv":0.0,"id":35736915},{"batb":[[0,1.27,7.13],[1,1.2,1105],[2,1.04,1.53]],"ltp":0.0,"tv":0.0,"id":11445383}]}]}
{"op":"mcm","clk":"11900222791","pt":1724309216763,"mc":[{"id":"1.232013126","rc":[{"batl":[[0,5.9,10.94]],"ltp":0.0,"tv":0.0,"id":35736915},{"batl":[[0,5.9,10.94]],"ltp":0.0,"tv":0.0,"id":11445383}]}]}
{"op":"mcm","clk":"11900227040","pt":1724309330199,"mc":[{"id":"1.232013126","rc":[{"batb":[[0,1.28,30.57],[1,1.27,6.34],[2,1.2,1105]],"ltp":0.0,"tv":0.0,"id":35736915},{"batb":[[0,1.28,30.57],[1,1.27,7.13],[2,1.2,1105]],"ltp":0.0,"tv":0.0,"id":11445383}]}]}
{"op":"mcm","clk":"11900293783","pt":1724311130818,"mc":[{"id":"1.232013126","rc":[{"batb":[[0,1.27,6.33],[1,1.2,1105],[2,1.04,1.53]],"ltp":0.0,"tv":0.0,"id":35736915},{"batb":[[0,1.27,7.13],[1,1.2,1105],[2,1.04,1.53]],"ltp":0.0,"tv":0.0,"id":11445383}]}]}
{"op":"mcm","clk":"11900294341","pt":1724311145711,"mc":[{"id":"1.232013126","rc":[{"batl":[[0,5.9,10.94]],"ltp":0.0,"tv":0.0,"id":35736915},{"batl":[[0,5.9,10.93]],"ltp":0.0,"tv":0.0,"id":11445383}]}]}
{"op":"mcm","clk":"11900298498","pt":1724311255139,"mc":[{"id":"1.232013126","rc":[{"batb":[[0,1.28,30.57],[1,1.27,6.33],[2,1.2,1105]],"ltp":0.0,"tv":0.0,"id":35736915},{"batb":[[0,1.28,30.57],[1,1.27,7.13],[2,1.2,1105]],"ltp":0.0,"tv":0.0,"id":11445383}]}]}
{"op":"mcm","clk":"11900382312","pt":1724313056221,"mc":[{"id":"1.232013126","rc":[{"batb":[[0,1.27,6.33],[1,1.2,1105],[2,1.04,1.53]],"ltp":0.0,"tv":0.0,"id":35736915},{"batb":[[0,1.27,7.13],[1,1.2,1105],[2,1.04,1.53]],"ltp":0.0,"tv":0.0,"id":11445383}]}]}
{"op":"mcm","clk":"11900382352","pt":1724313056987,"mc":[{"id":"1.232013126","rc":[{"batl":[[0,5.9,10.94]],"ltp":0.0,"tv":0.0,"id":35736915},{"batl":[[0,5.9,10.93]],"ltp":0.0,"tv":0.0,"id":11445383}]}]}
{"op":"mcm","clk":"11900387435","pt":1724313180933,"mc":[{"id":"1.232013126","rc":[{"batb":[[0,1.28,30.57],[1,1.27,6.33],[2,1.2,1105]],"ltp":0.0,"tv":0.0,"id":35736915},{"batb":[[0,1.28,30.57],[1,1.27,7.13],[2,1.2,1105]],"ltp":0.0,"tv":0.0,"id":11445383}]}]}
{"op":"mcm","clk":"11900404243","pt":1724313621039,"mc":[{"id":"1.232013126","rc":[{"batb":[[0,1.28,30.52],[1,1.27,6.33]],"batl":[[0,5.9,10.94]],"ltp":0.0,"tv":0.0,"id":35736915},{"batb":[[0,1.28,30.52],[1,1.27,7.12]],"batl":[[0,5.9,10.94]],"ltp":0.0,"tv":0.0,"id":11445383}]}]}
{"op":"mcm","clk":"11900472886","pt":1724314981373,"mc":[{"id":"1.232013126","rc":[{"batb":[[0,1.27,7.12],[1,1.2,1105],[2,1.04,1.53]],"ltp":0.0,"tv":0.0,"id":11445383}]}]}
{"op":"mcm","clk":"11900472895","pt":1724314981579,"mc":[{"id":"1.232013126","rc":[{"batb":[[0,1.27,6.33],[1,1.2,1105],[2,1.04,1.53]],"ltp":0.0,"tv":0.0,"id":35736915}]}]}
{"op":"mcm","clk":"11900473344","pt":1724314991248,"mc":[{"id":"1.232013126","rc":[{"batl":[[0,5.9,10.94]],"ltp":0.0,"tv":0.0,"id":35736915},{"batl":[[0,5.9,10.94]],"ltp":0.0,"tv":0.0,"id":11445383}]}]}
{"op":"mcm","clk":"11900478714","pt":1724315108798,"mc":[{"id":"1.232013126","rc":[{"batb":[[0,1.28,30.52],[1,1.27,6.33],[2,1.2,1105]],"ltp":0.0,"tv":0.0,"id":35736915},{"batb":[[0,1.28,30.52],[1,1.27,7.12],[2,1.2,1105]],"ltp":0.0,"tv":0.0,"id":11445383}]}]}
{"op":"mcm","clk":"11900571777","pt":1724316909377,"mc":[{"id":"1.232013126","rc":[{"batb":[[0,1.27,6.33],[1,1.2,1105],[2,1.04,1.53]],"ltp":0.0,"tv":0.0,"id":35736915},{"batb":[[0,1.27,7.12],[1,1.2,1105],[2,1.04,1.53]],"ltp":0.0,"tv":0.0,"id":11445383}]}]}
{"op":"mcm","clk":"11900572069","pt":1724316914573,"mc":[{"id":"1.232013126","rc":[{"batl":[[0,5.9,10.94]],"ltp":0.0,"tv":0.0,"id":35736915},{"batl":[[0,5.9,10.94]],"ltp":0.0,"tv":0.0,"id":11445383}]}]}
{"op":"mcm","clk":"11900580331","pt":1724317036089,"mc":[{"id":"1.232013126","rc":[{"batb":[[0,1.28,30.52],[1,1.27,6.33],[2,1.2,1105]],"ltp":0.0,"tv":0.0,"id":35736915},{"batb":[[0,1.28,30.52],[1,1.27,7.12],[2,1.2,1105]],"ltp":0.0,"tv":0.0,"id":11445383}]}]}
{"op":"mcm","clk":"11900660492","pt":1724317975202,"mc":[{"id":"1.232013126","rc":[{"batb":[[0,1.28,30.5],[1,1.27,6.32]],"ltp":0.0,"tv":0.0,"id":35736915},{"batb":[[0,1.28,30.5],[1,1.27,7.11]],"ltp":0.0,"tv":0.0,"id":11445383}]}]}
{"op":"mcm","clk":"11900733021","pt":1724318836508,"mc":[{"id":"1.232013126","rc":[{"batb":[[0,1.27,6.32],[1,1.2,1105],[2,1.04,1.53]],"ltp":0.0,"tv":0.0,"id":35736915},{"batb":[[0,1.27,7.11],[1,1.2,1105],[2,1.04,1.53]],"ltp":0.0,"tv":0.0,"id":11445383}]}]}
{"op":"mcm","clk":"11900733073","pt":1724318837382,"mc":[{"id":"1.232013126","rc":[{"batl":[[0,5.9,10.94]],"ltp":0.0,"tv":0.0,"id":35736915},{"batl":[[0,5.9,10.93]],"ltp":0.0,"tv":0.0,"id":11445383}]}]}
{"op":"mcm","clk":"11900735117","pt":1724318866449,"mc":[{"id":"1.232013126","rc":[{"batb":[[0,1.28,30.5],[1,1.27,6.32],[2,1.2,1105]],"ltp":0.0,"tv":0.0,"id":35736915},{"batb":[[0,1.28,30.5],[1,1.27,7.11],[2,1.2,1105]],"ltp":0.0,"tv":0.0,"id":11445383}]}]}
{"op":"mcm","clk":"11900875201","pt":1724320667162,"mc":[{"id":"1.232013126","rc":[{"batb":[[0,1.27,6.32],[1,1.2,1105],[2,1.04,1.53]],"ltp":0.0,"tv":0.0,"id":35736915},{"batb":[[0,1.27,7.11],[1,1.2,1105],[2,1.04,1.53]],"ltp":0.0,"tv":0.0,"id":11445383}]}]}
{"op":"mcm","clk":"11900876245","pt":1724320681002,"mc":[{"id":"1.232013126","rc":[{"batl":[[0,5.9,10.94]],"ltp":0.0,"tv":0.0,"id":35736915},{"batl":[[0,5.9,10.93]],"ltp":0.0,"tv":0.0,"id":11445383}]}]}
{"op":"mcm","clk":"11900878378","pt":1724320705927,"mc":[{"id":"1.232013126","rc":[{"batb":[[0,1.28,30.5],[1,1.27,6.32],[2,1.2,1105]],"ltp":0.0,"tv":0.0,"id":35736915},{"batb":[[0,1.28,30.5],[1,1.27,7.11],[2,1.2,1105]],"ltp":0.0,"tv":0.0,"id":11445383}]}]}
{"op":"mcm","clk":"11901031623","pt":1724322506340,"mc":[{"id":"1.232013126","rc":[{"batb":[[0,1.27,6.32],[1,1.2,1105],[2,1.04,1.53]],"ltp":0.0,"tv":0.0,"id":35736915},{"batb":[[0,1.27,7.11],[1,1.2,1105],[2,1.04,1.53]],"ltp":0.0,"tv":0.0,"id":11445383}]}]}
{"op":"mcm","clk":"11901032338","pt":1724322516251,"mc":[{"id":"1.232013126","rc":[{"batl":[[0,5.9,10.94]],"ltp":0.0,"tv":0.0,"id":35736915},{"batl":[[0,5.9,10.93]],"ltp":0.0,"tv":0.0,"id":11445383}]}]}
{"op":"mcm","clk":"11901034005","pt":1724322537864,"mc":[{"id":"1.232013126","rc":[{"batb":[[0,1.28,30.47],[1,1.27,6.32],[2,1.2,1105]],"ltp":0.0,"tv":0.0,"id":35736915},{"batb":[[0,1.28,30.47],[1,1.27,7.11],[2,1.2,1105]],"ltp":0.0,"tv":0.0,"id":11445383}]}]}
{"op":"mcm","clk":"11901204825","pt":1724324338119,"mc":[{"id":"1.232013126","rc":[{"batb":[[0,1.27,6.32],[1,1.2,1105],[2,1.04,1.53]],"ltp":0.0,"tv":0.0,"id":35736915},{"batb":[[0,1.27,7.11],[1,1.2,1105],[2,1.04,1.53]],"ltp":0.0,"tv":0.0,"id":11445383}]}]}
{"op":"mcm","clk":"11901205930","pt":1724324351042,"mc":[{"id":"1.232013126","rc":[{"batl":[[0,5.9,10.94]],"ltp":0.0,"tv":0.0,"id":35736915},{"batl":[[0,5.9,10.93]],"ltp":0.0,"tv":0.0,"id":11445383}]}]}
{"op":"mcm","clk":"11901206756","pt":1724324360362,"mc":[{"id":"1.232013126","rc":[{"batb":[[0,1.28,30.47],[1,1.27,6.32],[2,1.2,1105]],"ltp":0.0,"tv":0.0,"id":35736915},{"batb":[[0,1.28,30.47],[1,1.27,7.11],[2,1.2,1105]],"ltp":0.0,"tv":0.0,"id":11445383}]}]}
{"op":"mcm","clk":"11901367738","pt":1724326160992,"mc":[{"id":"1.232013126","rc":[{"batb":[[0,1.27,6.32],[1,1.2,1105],[2,1.04,1.53]],"ltp":0.0,"tv":0.0,"id":35736915},{"batb":[[0,1.27,7.11],[1,1.2,1105],[2,1.04,1.53]],"ltp":0.0,"tv":0.0,"id":11445383}]}]}
{"op":"mcm","clk":"11901368894","pt":1724326173225,"mc":[{"id":"1.232013126","rc":[{"batl":[[0,5.9,10.94]],"ltp":0.0,"tv":0.0,"id":35736915},{"batl":[[0,5.9,10.93]],"ltp":0.0,"tv":0.0,"id":11445383}]}]}
{"op":"mcm","clk":"11901369192","pt":1724326176214,"mc":[{"id":"1.232013126","rc":[{"batb":[[0,1.28,30.49],[1,1.27,6.32],[2,1.2,1105]],"ltp":0.0,"tv":0.0,"id":35736915},{"batb":[[0,1.28,30.49],[1,1.27,7.11],[2,1.2,1105]],"ltp":0.0,"tv":0.0,"id":11445383}]}]}
{"op":"mcm","clk":"11901437676","pt":1724326891749,"mc":[{"id":"1.232013126","rc":[{"trd":[[1.28,1.96]],"batb":[[0,1.28,29.52]],"ltp":1.28,"tv":1.95,"id":11445383}],"tv":1.95}]}
{"op":"mcm","clk":"11901533562","pt":1724327976943,"mc":[{"id":"1.232013126","rc":[{"batb":[[0,1.27,6.32],[1,1.2,1105],[2,1.04,1.53]],"ltp":0.0,"tv":0.0,"id":35736915},{"batb":[[0,1.27,7.11],[1,1.2,1105],[2,1.04,1.53]],"ltp":1.28,"tv":1.95,"id":11445383}]}]}
{"op":"mcm","clk":"11901534228","pt":1724327983381,"mc":[{"id":"1.232013126","rc":[{"batb":[[0,1.28,30.49],[1,1.27,6.32],[2,1.2,1105]],"ltp":0.0,"tv":0.0,"id":35736915}]}]}
{"op":"mcm","clk":"11901534709","pt":1724327987779,"mc":[{"id":"1.232013126","rc":[{"batl":[[0,5.9,10.94]],"ltp":0.0,"tv":0.0,"id":35736915}]}]}
{"op":"mcm","clk":"11901619722","pt":1724328775180,"mc":[{"id":"1.232013126","rc":[{"batb":[[0,1.28,30.49],[1,1.27,6.32]],"batl":[[0,5.9,10.94]],"ltp":0.0,"tv":0.0,"id":35736915},{"batb":[[0,1.27,7.12]],"ltp":1.28,"tv":1.95,"id":11445383}]}]}
{"op":"mcm","clk":"11901713916","pt":1724329784053,"mc":[{"id":"1.232013126","rc":[{"batb":[[0,1.27,6.32],[1,1.2,1105],[2,1.04,1.53]],"ltp":0.0,"tv":0.0,"id":35736915}]}]}
{"op":"mcm","clk":"11901714053","pt":1724329785591,"mc":[{"id":"1.232013126","rc":[{"batb":[[0,1.28,30.49],[1,1.27,6.32],[2,1.2,1105]],"ltp":0.0,"tv":0.0,"id":35736915}]}]}
{"op":"mcm","clk":"11901732571","pt":1724329990663,"mc":[{"id":"1.232013126","rc":[{"batb":[[0,1.21,7.12]],"ltp":1.28,"tv":1.95,"id":11445383}]}]}
{"op":"mcm","clk":"11901825797","pt":1724331157759,"mc":[{"id":"1.232013126","rc":[{"batb":[[0,1.29,15],[1,1.28,30.49],[2,1.27,6.32]],"ltp":0.0,"tv":0.0,"id":35736915},{"batb":[[0,1.22,15],[1,1.21,7.12],[2,1.2,1105]],"ltp":1.28,"tv":1.95,"id":11445383}]}]}
{"op":"mcm","clk":"11901861862","pt":1724331586399,"mc":[{"id":"1.232013126","rc":[{"batb":[[1,1.27,6.32],[2,1.2,1105]],"ltp":0.0,"tv":0.0,"id":35736915}]}]}
{"op":"mcm","clk":"11901861955","pt":1724331588201,"mc":[{"id":"1.232013126","rc":[{"batl":[[0,5.9,11.14]],"ltp":1.28,"tv":1.95,"id":11445383}]}]}
{"op":"mcm","clk":"11901875463","pt":1724331776056,"mc":[{"id":"1.232013126","rc":[{"batb":[[0,1.3,28.45],[1,1.29,15],[2,1.27,6.32]],"batl":[[0,5.9,10.94]],"ltp":0.0,"tv":0.0,"id":35736915},{"batb":[[1,1.21,7.11]],"batl":[[0,5.9,11.14]],"ltp":1.28,"tv":1.95,"id":11445383}]}]}
{"op":"mcm","clk":"11901905928","pt":1724332205131,"mc":[{"id":"1.232013126","rc":[{"batb":[[2,1.2,1105]],"ltp":0.0,"tv":0.0,"id":35736915}]}]}
{"op":"mcm","clk":"11902008255","pt":1724333577088,"mc":[{"id":"1.232013126","rc":[{"batb":[[0,1.29,15],[1,1.2,1105],[2,1.04,1.53]],"ltp":0.0,"tv":0.0,"id":35736915}]}]}
{"op":"mcm","clk":"11902008326","pt":1724333578433,"mc":[{"id":"1.232013126","rc":[{"batl":[[0,5.9,11.06]],"ltp":1.28,"tv":1.95,"id":11445383}]}]}
{"op":"mcm","clk":"11902019180","pt":1724333750466,"mc":[{"id":"1.232013126","rc":[{"batb":[[0,1.3,28.45],[1,1.29,15],[2,1.2,1105]],"ltp":0.0,"tv":0.0,"id":35736915}]}]}
{"op":"mcm","clk":"11902129889","pt":1724335418128,"mc":[{"id":"1.232013126","rc":[{"batb":[[0,1.3,28.43],[2,1.04,1.53]],"batl":[[0,5.9,10.93]],"ltp":0.0,"tv":0.0,"id":35736915},{"batb":[[1,1.21,7.12],[2,1.04,1.53]],"ltp":1.28,"tv":1.95,"id":11445383}]}]}
{"op":"mcm","clk":"11902130066","pt":1724335420242,"mc":[{"id":"1.232013126","rc":[{"batb":[[0,1.3,695.1]],"ltp":0.0,"tv":0.0,"id":35736915}]}]}
{"op":"mcm","clk":"11902130212","pt":1724335421942,"mc":[{"id":"1.232013126","rc":[{"batb":[[0,1.22,924.09]],"ltp":1.28,"tv":1.95,"id":11445383}]}]}
{"op":"mcm","clk":"11902140024","pt":1724335550992,"mc":[{"id":"1.232013126","rc":[{"batb":[[0,1.3,666.67]],"ltp":0.0,"tv":0.0,"id":35736915}]}]}
{"op":"mcm","clk":"11902151197","pt":1724335706655,"mc":[{"id":"1.232013126","rc":[{"batb":[[0,1.31,27.51],[1,1.3,666.67],[2,1.29,15]],"ltp":0.0,"tv":0.0,"id":35736915}]}]}
{"op":"mcm","clk":"11902223642","pt":1724336766479,"mc":[{"id":"1.232013126","rc":[{"batb":[[0,1.23,7.12],[1,1.22,924.09]],"ltp":1.28,"tv":1.95,"id":11445383}]}]}
{"op":"mcm","clk":"11902223657","pt":1724336766797,"mc":[{"id":"1.232013126","rc":[{"batb":[[0,1.32,7.33],[1,1.31,27.51],[2,1.3,666.67]],"ltp":0.0,"tv":0.0,"id":35736915}]}]}
{"op":"mcm","clk":"11902252568","pt":1724337246967,"mc":[{"id":"1.232013126","rc":[{"batl":[[0,5.5,9.97]],"ltp":0.0,"tv":0.0,"id":35736915}]}]}
{"op":"mcm","clk":"11902269328","pt":1724337507376,"mc":[{"id":"1.232013126","rc":[{"batb":[[1,1.3,666.67],[2,1.29,15]],"ltp":0.0,"tv":0.0,"id":35736915}]}]}
{"op":"mcm","clk":"11902276838","pt":1724337645423,"mc":[{"id":"1.232013126","rc":[{"batb":[[0,1.33,25.84],[1,1.32,7.33],[2,1.3,666.67]],"ltp":0.0,"tv":0.0,"id":35736915}]}]}
{"op":"mcm","clk":"11902392445","pt":1724339406526,"mc":[{"id":"1.232013126","rc":[{"batb":[[0,1.34,7.33],[1,1.33,25.83]],"batl":[[0,5.5,9.97]],"ltp":0.0,"tv":0.0,"id":35736915},{"batb":[[0,1.23,7.12]],"ltp":1.28,"tv":1.95,"id":11445383}]}]}
{"op":"mcm","clk":"11902395479","pt":1724339446276,"mc":[{"id":"1.232013126","rc":[{"batb":[[1,1.3,666.67],[2,1.29,15]],"ltp":0.0,"tv":0.0,"id":35736915}]}]}
{"op":"mcm","clk":"11902419358","pt":1724339575218,"mc":[{"id":"1.232013126","rc":[{"batb":[[0,1.35,24.36],[1,1.34,7.33],[2,1.3,666.67]],"ltp":0.0,"tv":0.0,"id":35736915}]}]}
{"op":"mcm","clk":"11902537657","pt":1724340916363,"mc":[{"id":"1.232013126","rc":[{"batb":[[2,1.29,15]],"ltp":0.0,"tv":0.0,"id":35736915},{"batb":[[1,1.22,15]],"ltp":1.28,"tv":1.95,"id":11445383}]}]}
{"op":"mcm","clk":"11902543871","pt":1724340990014,"mc":[{"id":"1.232013126","rc":[{"batb":[[0,1.23,1311.47]],"ltp":1.28,"tv":1.95,"id":11445383}]}]}
{"op":"mcm","clk":"11902544217","pt":1724340994199,"mc":[{"id":"1.232013126","rc":[{"batb":[[0,1.35,881.5]],"ltp":0.0,"tv":0.0,"id":35736915}]}]}
{"op":"mcm","clk":"11902576129","pt":1724341353351,"mc":[{"id":"1.232013126","rc":[{"batb":[[2,1.21,82.79]],"ltp":1.28,"tv":1.95,"id":11445383}]}]}
{"op":"mcm","clk":"11902578394","pt":1724341375788,"mc":[{"id":"1.232013126","rc":[{"batb":[[0,1.35,857.14]],"ltp":0.0,"tv":0.0,"id":35736915}]}]}
{"op":"mcm","clk":"11902590271","pt":1724341500591,"mc":[{"id":"1.232013126","rc":[{"batb":[[0,1.36,23.68],[1,1.35,857.14],[2,1.34,7.33]],"ltp":0.0,"tv":0.0,"id":35736915}]}]}
{"op":"mcm","clk":"11902632471","pt":1724341930145,"mc":[{"id":"1.232013126","rc":[{"batl":[[0,3.85,14.98]],"ltp":1.28,"tv":1.95,"id":11445383}]}]}
{"op":"mcm","clk":"11902653457","pt":1724342109889,"mc":[{"id":"1.232013126","rc":[{"batb":[[0,1.36,31.01],[2,1.29,15]],"ltp":0.0,"tv":0.0,"id":35736915}]}]}
{"op":"mcm","clk":"11902706533","pt":1724342536120,"mc":[{"id":"1.232013126","rc":[{"batb":[[0,1.36,31.03]],"batl":[[0,5.3,14.67]],"ltp":0.0,"tv":0.0,"id":35736915},{"trd":[[1.28,1.96]],"batb":[[0,1.23,1311.47],[2,1.21,82.85]],"ltp":1.28,"tv":1.95,"id":11445383}],"tv":1.95}]}
{"op":"mcm","clk":"11902811862","pt":1724343300895,"mc":[{"id":"1.232013126","rc":[{"batb":[[0,1.36,7.33]],"ltp":0.0,"tv":0.0,"id":35736915}]}]}
{"op":"mcm","clk":"11902812221","pt":1724343303422,"mc":[{"id":"1.232013126","rc":[{"batl":[[0,3.85,14.7]],"ltp":1.28,"tv":1.95,"id":11445383}]}]}
{"op":"mcm","clk":"11902828193","pt":1724343414336,"mc":[{"id":"1.232013126","rc":[{"batb":[[0,1.37,23.06],[1,1.36,7.33],[2,1.35,857.14]],"ltp":0.0,"tv":0.0,"id":35736915}]}]}
{"op":"mcm","clk":"11903084923","pt":1724345033449,"mc":[{"id":"1.232013126","rc":[{"batb":[[0,1.24,7.12],[1,1.23,1304.35],[2,1.22,15]],"ltp":1.28,"tv":1.95,"id":11445383}]}]}
{"op":"mcm","clk":"11903111700","pt":1724345214632,"mc":[{"id":"1.232013126","rc":[{"batb":[[0,1.36,7.33],[1,1.35,857.14],[2,1.29,15]],"ltp":0.0,"tv":0.0,"id":35736915}]}]}
{"op":"mcm","clk":"11903111849","pt":1724345215678,"mc":[{"id":"1.232013126","rc":[{"batl":[[0,3.85,14.7]],"ltp":1.28,"tv":1.95,"id":11445383}]}]}
{"op":"mcm","clk":"11903126368","pt":1724345313352,"mc":[{"id":"1.232013126","rc":[{"batb":[[0,1.37,23.06],[1,1.36,7.33],[2,1.35,857.14]],"ltp":0.0,"tv":0.0,"id":35736915}]}]}
{"op":"mcm","clk":"11903383383","pt":1724347114118,"mc":[{"id":"1.232013126","rc":[{"batb":[[0,1.36,7.34],[1,1.35,857.14],[2,1.29,15]],"batl":[[0,5.3,14.67]],"ltp":0.0,"tv":0.0,"id":35736915},{"trd":[[1.28,1.96]],"batb":[[0,1.24,7.13]],"ltp":1.28,"tv":1.95,"id":11445383}],"tv":1.95}]}
{"op":"mcm","clk":"11903383630","pt":1724347115535,"mc":[{"id":"1.232013126","rc":[{"batl":[[0,3.85,14.7]],"ltp":1.28,"tv":1.95,"id":11445383}]}]}
{"op":"mcm","clk":"11903394650","pt":1724347186516,"mc":[{"id":"1.232013126","rc":[{"batb":[[0,1.37,23.07],[1,1.36,7.34],[2,1.35,857.14]],"ltp":0.0,"tv":0.0,"id":35736915}]}]}
{"op":"mcm","clk":"11903701703","pt":1724348986882,"mc":[{"id":"1.232013126","rc":[{"batb":[[0,1.36,7.34],[1,1.35,857.14],[2,1.29,15]],"ltp":0.0,"tv":0.0,"id":35736915}]}]}
{"op":"mcm","clk":"11903704820","pt":1724349006982,"mc":[{"id":"1.232013126","rc":[{"batl":[[0,3.85,14.7]],"ltp":1.28,"tv":1.95,"id":11445383}]}]}
{"op":"mcm","clk":"11903710426","pt":1724349044415,"mc":[{"id":"1.232013126","rc":[{"batb":[[0,1.37,23.07],[1,1.36,7.34],[2,1.35,857.14]],"ltp":0.0,"tv":0.0,"id":35736915}]}]}
{"op":"mcm","clk":"11903934065","pt":1724350375181,"mc":[{"id":"1.232013126","rc":[{"batb":[[0,1.37,23.06],[1,1.36,7.34]],"batl":[[0,5.3,14.67]],"ltp":0.0,"tv":0.0,"id":35736915},{"batb":[[0,1.24,7.13]],"ltp":1.28,"tv":1.95,"id":11445383}]}]}
{"op":"mcm","clk":"11904017710","pt":1724350845363,"mc":[{"id":"1.232013126","rc":[{"batb":[[0,1.36,7.34],[1,1.35,857.14],[2,1.29,15]],"ltp":0.0,"tv":0.0,"id":35736915}]}]}
{"op":"mcm","clk":"11904021717","pt":1724350867257,"mc":[{"id":"1.232013126","rc":[{"batl":[[0,3.85,14.7]],"ltp":1.28,"tv":1.95,"id":11445383}]}]}
{"op":"mcm","clk":"11904021945","pt":1724350868475,"mc":[{"id":"1.232013126","rc":[{"batb":[[0,1.37,23.06],[1,1.36,7.34],[2,1.35,857.14]],"ltp":0.0,"tv":0.0,"id":35736915}]}]}
{"op":"mcm","clk":"11904328787","pt":1724352668787,"mc":[{"id":"1.232013126","rc":[{"batb":[[0,1.36,7.34],[1,1.35,857.14],[2,1.29,15]],"ltp":0.0,"tv":0.0,"id":35736915}]}]}
{"op":"mcm","clk":"11904328981","pt":1724352670110,"mc":[{"id":"1.232013126","rc":[{"batl":[[0,3.85,14.7]],"ltp":1.28,"tv":1.95,"id":11445383}]}]}
{"op":"mcm","clk":"11904338660","pt":1724352736014,"mc":[{"id":"1.232013126","rc":[{"batb":[[0,1.37,23.06],[1,1.36,7.34],[2,1.35,857.14]],"ltp":0.0,"tv":0.0,"id":35736915}]}]}
{"op":"mcm","clk":"11904616931","pt":1724354536679,"mc":[{"id":"1.232013126","rc":[{"batb":[[0,1.36,7.33],[1,1.35,857.14],[2,1.29,15]],"batl":[[0,5.3,14.66]],"ltp":0.0,"tv":0.0,"id":35736915},{"trd":[[1.28,1.96]],"batb":[[0,1.24,7.13]],"ltp":1.28,"tv":1.95,"id":11445383}],"tv":1.95}]}
{"op":"mcm","clk":"11904617128","pt":1724354538085,"mc":[{"id":"1.232013126","rc":[{"batl":[[0,3.85,14.7]],"ltp":1.28,"tv":1.95,"id":11445383}]}]}
{"op":"mcm","clk":"11904622806","pt":1724354578274,"mc":[{"id":"1.232013126","rc":[{"batb":[[0,1.37,23.05],[1,1.36,7.33],[2,1.35,857.14]],"ltp":0.0,"tv":0.0,"id":35736915}]}]}
{"op":"mcm","clk":"11904892432","pt":1724356378467,"mc":[{"id":"1.232013126","rc":[{"batb":[[0,1.36,7.33],[1,1.35,857.14],[2,1.29,15]],"ltp":0.0,"tv":0.0,"id":35736915}]}]}
{"op":"mcm","clk":"11904893674","pt":1724356387263,"mc":[{"id":"1.232013126","rc":[{"batl":[[0,3.85,14.7]],"ltp":1.28,"tv":1.95,"id":11445383}]}]}
{"op":"mcm","clk":"11904896098","pt":1724356404781,"mc":[{"id":"1.232013126","rc":[{"batb":[[0,1.37,23.05],[1,1.36,7.33],[2,1.35,857.14]],"ltp":0.0,"tv":0.0,"id":35736915}]}]}
{"op":"mcm","clk":"11905110651","pt":1724358205555,"mc":[{"id":"1.232013126","rc":[{"batb":[[0,1.36,7.34],[1,1.35,857.14],[2,1.29,15]],"batl":[[0,5.3,14.67]],"ltp":0.0,"tv":0.0,"id":35736915},{"batb":[[0,1.24,7.13]],"ltp":1.28,"tv":1.95,"id":11445383}]}]}
{"op":"mcm","clk":"11905114770","pt":1724358248615,"mc":[{"id":"1.232013126","rc":[{"batb":[[0,1.37,23.06],[1,1.36,7.34],[2,1.35,857.14]],"ltp":0.0,"tv":0.0,"id":35736915}]}]}
{"op":"mcm","clk":"11905262775","pt":1724360049289,"mc":[{"id":"1.232013126","rc":[{"batb":[[0,1.36,7.34],[1,1.35,857.14],[2,1.29,15]],"ltp":0.0,"tv":0.0,"id":35736915}]}]}
{"op":"mcm","clk":"11905262852","pt":1724360050792,"mc":[{"id":"1.232013126","rc":[{"batl":[[0,3.85,14.7]],"ltp":1.28,"tv":1.95,"id":11445383}]}]}
{"op":"mcm","clk":"11905265026","pt":1724360087899,"mc":[{"id":"1.232013126","rc":[{"batb":[[0,1.37,23.06],[1,1.36,7.34],[2,1.35,857.14]],"ltp":0.0,"tv":0.0,"id":35736915}]}]}
{"op":"mcm","clk":"11905355949","pt":1724361175175,"mc":[{"id":"1.232013126","rc":[{"batb":[[0,1.37,23.06],[1,1.36,7.33]],"batl":[[0,5.3,14.67]],"ltp":0.0,"tv":0.0,"id":35736915},{"trd":[[1.28,1.96]],"batb":[[0,1.24,7.13]],"ltp":1.28,"tv":1.95,"id":11445383}],"tv":1.95}]}
{"op":"mcm","clk":"11905405787","pt":1724361888274,"mc":[{"id":"1.232013126","rc":[{"batb":[[0,1.36,7.33],[1,1.35,857.14],[2,1.29,15]],"ltp":0.0,"tv":0.0,"id":35736915}]}]}
{"op":"mcm","clk":"11905406765","pt":1724361903658,"mc":[{"id":"1.232013126","rc":[{"batb":[[0,1.37,23.06],[1,1.36,7.33],[2,1.35,857.14]],"ltp":0.0,"tv":0.0,"id":35736915}]}]}
{"op":"mcm","clk":"11905504706","pt":1724363704132,"mc":[{"id":"1.232013126","rc":[{"batb":[[0,1.36,7.33],[1,1.35,857.14],[2,1.29,15]],"ltp":0.0,"tv":0.0,"id":35736915}]}]}
{"op":"mcm","clk":"11905504922","pt":1724363707884,"mc":[{"id":"1.232013126","rc":[{"batl":[[0,3.85,14.7]],"ltp":1.28,"tv":1.95,"id":11445383}]}]}
{"op":"mcm","clk":"11905506147","pt":1724363730279,"mc":[{"id":"1.232013126","rc":[{"batb":[[0,1.37,23.06],[1,1.36,7.33],[2,1.35,857.14]],"ltp":0.0,"tv":0.0,"id":35736915}]}]}
{"op":"mcm","clk":"11905601467","pt":1724365530856,"mc":[{"id":"1.232013126","rc":[{"batb":[[0,1.36,7.33],[1,1.35,857.14],[2,1.29,15]],"batl":[[0,5.3,14.67]],"ltp":0.0,"tv":0.0,"id":35736915}]}]}
{"op":"mcm","clk":"11905601541","pt":1724365532448,"mc":[{"id":"1.232013126","rc":[{"batl":[[0,3.85,14.69]],"ltp":1.28,"tv":1.95,"id":11445383}]}]}
{"op":"mcm","clk":"11905603134","pt":1724365559866,"mc":[{"id":"1.232013126","rc":[{"batb":[[0,1.37,23.06],[1,1.36,7.33],[2,1.35,857.14]],"ltp":0.0,"tv":0.0,"id":35736915}]}]}
{"op":"mcm","clk":"11905718304","pt":1724367360117,"mc":[{"id":"1.232013126","rc":[{"batb":[[0,1.36,7.33],[1,1.35,857.14],[2,1.29,15]],"ltp":0.0,"tv":0.0,"id":35736915}]}]}
{"op":"mcm","clk":"11905718755","pt":1724367369906,"mc":[{"id":"1.232013126","rc":[{"batl":[[0,3.85,14.69]],"ltp":1.28,"tv":1.95,"id":11445383}]}]}
{"op":"mcm","clk":"11905719172","pt":1724367380209,"mc":[{"id":"1.232013126","rc":[{"batb":[[0,1.37,23.06],[1,1.36,7.33],[2,1.35,857.14]],"ltp":0.0,"tv":0.0,"id":35736915}]}]}
{"op":"mcm","clk":"11905818885","pt":1724369180473,"mc":[{"id":"1.232013126","rc":[{"batb":[[0,1.36,7.33],[1,1.35,857.14],[2,1.29,15]],"ltp":0.0,"tv":0.0,"id":35736915},{"batb":[[0,1.24,7.13]],"ltp":1.28,"tv":1.95,"id":11445383}]}]}
{"op":"mcm","clk":"11905819017","pt":1724369183092,"mc":[{"id":"1.232013126","rc":[{"batl":[[0,3.85,14.69]],"ltp":1.28,"tv":1.95,"id":11445383}]}]}
{"op":"mcm","clk":"11905819393","pt":1724369190703,"mc":[{"id":"1.232013126","rc":[{"batb":[[0,1.37,23.06],[1,1.36,7.33],[2,1.35,857.14]],"ltp":0.0,"tv":0.0,"id":35736915}]}]}
{"op":"mcm","clk":"11905918947","pt":1724370991413,"mc":[{"id":"1.232013126","rc":[{"batb":[[0,1.36,7.33],[1,1.35,857.14],[2,1.29,15]],"ltp":0.0,"tv":0.0,"id":35736915}]}]}
{"op":"mcm","clk":"11905919025","pt":1724370993003,"mc":[{"id":"1.232013126","rc":[{"batl":[[0,3.85,14.69]],"ltp":1.28,"tv":1.95,"id":11445383}]}]}
{"op":"mcm","clk":"11905919380","pt":1724371001518,"mc":[{"id":"1.232013126","rc":[{"batb":[[0,1.37,23.06],[1,1.36,7.33],[2,1.35,857.14]],"ltp":0.0,"tv":0.0,"id":35736915}]}]}
{"op":"mcm","clk":"11905977627","pt":1724371975223,"mc":[{"id":"1.232013126","rc":[{"batb":[[1,1.36,7.33]],"ltp":0.0,"tv":0.0,"id":35736915},{"batb":[[0,1.24,7.12]],"ltp":1.28,"tv":1.95,"id":11445383}]}]}
{"op":"mcm","clk":"11906023094","pt":1724372801284,"mc":[{"id":"1.232013126","rc":[{"batb":[[0,1.36,7.33],[1,1.35,857.14],[2,1.29,15]],"ltp":0.0,"tv":0.0,"id":35736915}]}]}
{"op":"mcm","clk":"11906023163","pt":1724372803443,"mc":[{"id":"1.232013126","rc":[{"batl":[[0,3.85,14.69]],"ltp":1.28,"tv":1.95,"id":11445383}]}]}
{"op":"mcm","clk":"11906036930","pt":1724373055527,"mc":[{"id":"1.232013126","rc":[{"batb":[[0,1.37,23.06],[1,1.36,7.33],[2,1.35,857.14]],"ltp":0.0,"tv":0.0,"id":35736915}]}]}
{"op":"mcm","clk":"11906142481","pt":1724374856330,"mc":[{"id":"1.232013126","rc":[{"batb":[[0,1.36,7.33],[1,1.35,857.14],[2,1.29,15]],"batl":[[0,5.3,14.67]],"ltp":0.0,"tv":0.0,"id":35736915}]}]}
{"op":"mcm","clk":"11906143117","pt":1724374868325,"mc":[{"id":"1.232013126","rc":[{"batl":[[0,3.85,14.7]],"ltp":1.28,"tv":1.95,"id":11445383}]}]}
{"op":"mcm","clk":"11906154488","pt":1724375102891,"mc":[{"id":"1.232013126","rc":[{"batb":[[0,1.37,23.06],[1,1.36,7.33],[2,1.35,857.14]],"ltp":0.0,"tv":0.0,"id":35736915}]}]}
{"op":"mcm","clk":"11906244121","pt":1724376903177,"mc":[{"id":"1.232013126","rc":[{"batb":[[0,1.36,7.33],[1,1.35,857.14],[2,1.29,15]],"ltp":0.0,"tv":0.0,"id":35736915}]}]}
{"op":"mcm","clk":"11906244490","pt":1724376910801,"mc":[{"id":"1.232013126","rc":[{"batl":[[0,3.85,14.7]],"ltp":1.28,"tv":1.95,"id":11445383}]}]}
{"op":"mcm","clk":"11906256064","pt":1724377145986,"mc":[{"id":"1.232013126","rc":[{"batb":[[0,1.37,23.06],[1,1.36,7.33],[2,1.35,857.14]],"ltp":0.0,"tv":0.0,"id":35736915}]}]}
{"op":"mcm","clk":"11906370852","pt":1724378946404,"mc":[{"id":"1.232013126","rc":[{"batb":[[0,1.36,7.33],[1,1.35,857.14],[2,1.29,15]],"batl":[[0,5.3,14.67]],"ltp":0.0,"tv":0.0,"id":35736915},{"batb":[[0,1.24,7.12]],"ltp":1.28,"tv":1.95,"id":11445383}]}]}
{"op":"mcm","clk":"11906371085","pt":1724378950085,"mc":[{"id":"1.232013126","rc":[{"batl":[[0,3.85,14.7]],"ltp":1.28,"tv":1.95,"id":11445383}]}]}
{"op":"mcm","clk":"11906387165","pt":1724379174735,"mc":[{"id":"1.232013126","rc":[{"batb":[[0,1.37,23.07],[1,1.36,7.33],[2,1.35,857.14]],"ltp":0.0,"tv":0.0,"id":35736915}]}]}
{"op":"mcm","clk":"11906502465","pt":1724380975208,"mc":[{"id":"1.232013126","rc":[{"batb":[[0,1.36,7.33],[1,1.35,857.14],[2,1.29,15]],"ltp":0.0,"tv":0.0,"id":35736915}]}]}
{"op":"mcm","clk":"11906503508","pt":1724380990713,"mc":[{"id":"1.232013126","rc":[{"batl":[[0,3.85,14.7]],"ltp":1.28,"tv":1.95,"id":11445383}]}]}
{"op":"mcm","clk":"11906516453","pt":1724381190501,"mc":[{"id":"1.232013126","rc":[{"batb":[[0,1.37,23.07],[1,1.36,7.33],[2,1.35,857.14]],"ltp":0.0,"tv":0.0,"id":35736915}]}]}
{"op":"mcm","clk":"11906577623","pt":1724382194743,"mc":[{"id":"1.232013126","rc":[{"batb":[[0,1.37,23.06],[1,1.36,7.33]],"batl":[[0,5.3,14.67]],"ltp":0.0,"tv":0.0,"id":35736915},{"batb":[[0,1.24,7.12]],"batl":[[0,3.2,0.93]],"ltp":1.28,"tv":1.95,"id":11445383}]}]}
{"op":"mcm","clk":"11906578175","pt":1724382203643,"mc":[{"id":"1.232013126","rc":[{"batl":[[0,5.3,15.61]],"ltp":0.0,"tv":0.0,"id":35736915}]}]}
{"op":"mcm","clk":"11906642208","pt":1724382991046,"mc":[{"id":"1.232013126","rc":[{"batb":[[0,1.36,7.33],[1,1.35,857.14],[2,1.29,15]],"ltp":0.0,"tv":0.0,"id":35736915}]}]}
{"op":"mcm","clk":"11906644700","pt":1724383028730,"mc":[{"id":"1.232013126","rc":[{"batl":[[0,3.85,15.67]],"ltp":1.28,"tv":1.95,"id":11445383}]}]}
{"op":"mcm","clk":"11906654970","pt":1724383196519,"mc":[{"id":"1.232013126","rc":[{"batb":[[0,1.46,18.55],[1,1.36,7.33],[2,1.35,857.14]],"ltp":0.0,"tv":0.0,"id":35736915}]}]}
{"op":"mcm","clk":"11906655144","pt":1724383199244,"mc":[{"id":"1.232013126","rc":[{"batl":[[0,3.2,0.93]],"ltp":1.28,"tv":1.95,"id":11445383}]}]}
{"op":"mcm","clk":"11906780571","pt":1724384996797,"mc":[{"id":"1.232013126","rc":[{"batb":[[0,1.36,7.33],[1,1.35,857.14],[2,1.29,15]],"ltp":0.0,"tv":0.0,"id":35736915}]}]}
{"op":"mcm","clk":"11906781620","pt":1724385012800,"mc":[{"id":"1.232013126","rc":[{"batl":[[0,3.85,15.67]],"ltp":1.28,"tv":1.95,"id":11445383}]}]}
{"op":"mcm","clk":"11906793115","pt":1724385196568,"mc":[{"id":"1.232013126","rc":[{"batb":[[0,1.46,18.55],[1,1.36,7.33],[2,1.35,857.14]],"ltp":0.0,"tv":0.0,"id":35736915}]}]}
{"op":"mcm","clk":"11906793294","pt":1724385199135,"mc":[{"id":"1.232013126","rc":[{"batl":[[0,3.2,0.93]],"ltp":1.28,"tv":1.95,"id":11445383}]}]}
{"op":"mcm","clk":"11906899655","pt":1724386996984,"mc":[{"id":"1.232013126","rc":[{"batb":[[0,1.36,7.33],[1,1.35,857.14],[2,1.29,15]],"batl":[[0,5.3,15.6]],"ltp":0.0,"tv":0.0,"id":35736915}]}]}
{"op":"mcm","clk":"11906899789","pt":1724386998889,"mc":[{"id":"1.232013126","rc":[{"batl":[[0,3.85,15.67]],"ltp":1.28,"tv":1.95,"id":11445383}]}]}
{"op":"mcm","clk":"11906910264","pt":1724387191316,"mc":[{"id":"1.232013126","rc":[{"batb":[[0,1.46,18.55],[1,1.36,7.33],[2,1.35,857.14]],"ltp":0.0,"tv":0.0,"id":35736915}]}]}
{"op":"mcm","clk":"11906910277","pt":1724387191684,"mc":[{"id":"1.232013126","rc":[{"batl":[[0,3.2,0.93]],"ltp":1.28,"tv":1.95,"id":11445383}]}]}
{"op":"mcm","clk":"11907028374","pt":1724388991997,"mc":[{"id":"1.232013126","rc":[{"batb":[[0,1.36,7.33],[1,1.35,857.14],[2,1.29,15]],"ltp":0.0,"tv":0.0,"id":35736915}]}]}
{"op":"mcm","clk":"11907028456","pt":1724388993434,"mc":[{"id":"1.232013126","rc":[{"batl":[[0,3.85,15.67]],"ltp":1.28,"tv":1.95,"id":11445383}]}]}
{"op":"mcm","clk":"11907042505","pt":1724389173943,"mc":[{"id":"1.232013126","rc":[{"batb":[[0,1.46,18.55],[1,1.36,7.33],[2,1.35,857.14]],"ltp":0.0,"tv":0.0,"id":35736915}]}]}
{"op":"mcm","clk":"11907042731","pt":1724389177632,"mc":[{"id":"1.232013126","rc":[{"batl":[[0,3.2,0.93]],"ltp":1.28,"tv":1.95,"id":11445383}]}]}
{"op":"mcm","clk":"11907129145","pt":1724390680697,"mc":[{"id":"1.232013126","rc":[{"batb":[[0,1.46,18.55],[1,1.36,7.32]],"batl":[[0,5,1.82],[1,5.3,14.67]],"ltp":0.0,"tv":0.0,"id":35736915},{"batb":[[0,1.24,7.12]],"ltp":1.28,"tv":1.95,"id":11445383}]}]}
{"op":"mcm","clk":"11907129748","pt":1724390691812,"mc":[{"id":"1.232013126","rc":[{"batl":[[0,5,1.64]],"ltp":0.0,"tv":0.0,"id":35736915}]}]}
{"op":"mcm","clk":"11907133235","pt":1724390751789,"mc":[{"id":"1.232013126","rc":[{"batl":[[0,4.9,1.64]],"ltp":0.0,"tv":0.0,"id":35736915}]}]}
{"op":"mcm","clk":"11907144875","pt":1724390953787,"mc":[{"id":"1.232013126","rc":[{"batl":[[0,5.3,15.6],[1,5.3,0]],"ltp":0.0,"tv":0.0,"id":35736915}]}]}
{"op":"mcm","clk":"11907146100","pt":1724390974190,"mc":[{"id":"1.232013126","rc":[{"batb":[[0,1.36,7.32],[1,1.35,857.14],[2,1.29,15]],"ltp":0.0,"tv":0.0,"id":35736915}]}]}
{"op":"mcm","clk":"11907146388","pt":1724390979689,"mc":[{"id":"1.232013126","rc":[{"batl":[[0,5,1.64],[1,5.3,14.67]],"ltp":0.0,"tv":0.0,"id":35736915}]}]}
{"op":"mcm","clk":"11907147109","pt":1724390993728,"mc":[{"id":"1.232013126","rc":[{"batl":[[0,3.7,1.64]],"ltp":1.28,"tv":1.95,"id":11445383}]}]}
{"op":"mcm","clk":"11907148063","pt":1724391009841,"mc":[{"id":"1.232013126","rc":[{"batl":[[1,3.85,14.78]],"ltp":1.28,"tv":1.95,"id":11445383}]}]}
{"op":"mcm","clk":"11907156172","pt":1724391158798,"mc":[{"id":"1.232013126","rc":[{"batb":[[0,1.46,18.55],[1,1.36,7.32],[2,1.35,857.14]],"ltp":0.0,"tv":0.0,"id":35736915}]}]}
{"op":"mcm","clk":"11907156224","pt":1724391159785,"mc":[{"id":"1.232013126","rc":[{"batl":[[1,3.85,0]],"ltp":1.28,"tv":1.95,"id":11445383}]}]}
{"op":"mcm","clk":"11907172514","pt":1724391481442,"mc":[{"id":"1.232013126","rc":[{"batb":[[2,1.21,82.86]],"ltp":1.28,"tv":1.95,"id":11445383}]}]}
{"op":"mcm","clk":"11907172519","pt":1724391481544,"mc":[{"id":"1.232013126","rc":[{"batb":[[0,1.47,15],[1,1.46,18.55],[2,1.36,7.32]],"ltp":0.0,"tv":0.0,"id":35736915},{"batb":[[0,1.34,15],[1,1.24,7.12],[2,1.23,1304.35]],"ltp":1.28,"tv":1.95,"id":11445383}]}]}
{"op":"mcm","clk":"11907269011","pt":1724392959120,"mc":[{"id":"1.232013126","rc":[{"batb":[[1,1.36,7.32],[2,1.35,857.14]],"batl":[[1,5.3,14.66]],"ltp":0.0,"tv":0.0,"id":35736915}]}]}
{"op":"mcm","clk":"11907279544","pt":1724393135251,"mc":[{"id":"1.232013126","rc":[{"batb":[[0,1.48,17.77],[1,1.47,15],[2,1.36,7.32]],"ltp":0.0,"tv":0.0,"id":35736915}]}]}
{"op":"mcm","clk":"11907400168","pt":1724394935629,"mc":[{"id":"1.232013126","rc":[{"batb":[[0,1.47,15],[1,1.36,7.32],[2,1.35,857.14]],"ltp":0.0,"tv":0.0,"id":35736915}]}]}
{"op":"mcm","clk":"11907409909","pt":1724395091773,"mc":[{"id":"1.232013126","rc":[{"batl":[[0,4,1.64]],"ltp":0.0,"tv":0.0,"id":35736915}]}]}
{"op":"mcm","clk":"11907410990","pt":1724395108879,"mc":[{"id":"1.232013126","rc":[{"batl":[[0,3.2,1.64]],"ltp":1.28,"tv":1.95,"id":11445383}]}]}
{"op":"mcm","clk":"11907411193","pt":1724395112158,"mc":[{"id":"1.232013126","rc":[{"batb":[[0,1.48,17.77],[1,1.47,15],[2,1.36,7.32]],"ltp":0.0,"tv":0.0,"id":35736915}]}]}
{"op":"mcm","clk":"11907521736","pt":1724396912617,"mc":[{"id":"1.232013126","rc":[{"batb":[[0,1.47,15],[1,1.36,7.31],[2,1.35,857.14]],"batl":[[0,4,1.64],[1,5.3,14.65]],"ltp":0.0,"tv":0.0,"id":35736915},{"trd":[[1.28,1.95]],"batb":[[1,1.24,7.11]],"batl":[[0,3.2,1.64]],"ltp":1.28,"tv":1.95,"id":11445383}],"tv":1.95}]}
{"op":"mcm","clk":"11907533624","pt":1724397087919,"mc":[{"id":"1.232013126","rc":[{"batb":[[0,1.48,17.76],[1,1.47,15],[2,1.36,7.31]],"ltp":0.0,"tv":0.0,"id":35736915}]}]}
{"op":"mcm","clk":"11907644416","pt":1724398888433,"mc":[{"id":"1.232013126","rc":[{"batb":[[0,1.47,15],[1,1.36,7.31],[2,1.35,857.14]],"ltp":0.0,"tv":0.0,"id":35736915}]}]}
{"op":"mcm","clk":"11907671501","pt":1724399067573,"mc":[{"id":"1.232013126","rc":[{"batb":[[0,1.48,17.76],[1,1.47,15],[2,1.36,7.31]],"ltp":0.0,"tv":0.0,"id":35736915}]}]}
{"op":"mcm","clk":"11907789079","pt":1724400867819,"mc":[{"id":"1.232013126","rc":[{"batb":[[0,1.47,15],[1,1.36,7.32],[2,1.35,857.14]],"batl":[[1,5.3,14.65]],"ltp":0.0,"tv":0.0,"id":35736915},{"batb":[[1,1.24,7.11]],"ltp":1.28,"tv":1.95,"id":11445383}]}]}
{"op":"mcm","clk":"11907801407","pt":1724401042727,"mc":[{"id":"1.232013126","rc":[{"batb":[[0,1.48,17.75],[1,1.47,15],[2,1.36,7.32]],"ltp":0.0,"tv":0.0,"id":35736915}]}]}
{"op":"mcm","clk":"11907899768","pt":1724402842998,"mc":[{"id":"1.232013126","rc":[{"batb":[[0,1.47,15],[1,1.36,7.32],[2,1.35,857.14]],"ltp":0.0,"tv":0.0,"id":35736915}]}]}
{"op":"mcm","clk":"11907907196","pt":1724402984415,"mc":[{"id":"1.232013126","rc":[{"batb":[[0,1.48,17.75],[1,1.47,15],[2,1.36,7.32]],"ltp":0.0,"tv":0.0,"id":35736915}]}]}
{"op":"mcm","clk":"11908011927","pt":1724404375277,"mc":[{"id":"1.232013126","rc":[{"batb":[[0,1.48,17.74],[2,1.36,7.31]],"batl":[[0,4,1.64],[1,5.3,14.64]],"ltp":0.0,"tv":0.0,"id":35736915},{"trd":[[1.28,1.95]],"batb":[[1,1.24,7.11]],"batl":[[0,3.2,1.64]],"ltp":1.28,"tv":1.95,"id":11445383}],"tv":1.95}]}
{"op":"mcm","clk":"11908039680","pt":1724404784829,"mc":[{"id":"1.232013126","rc":[{"batb":[[0,1.47,15],[1,1.36,7.31],[2,1.35,857.14]],"ltp":0.0,"tv":0.0,"id":35736915}]}]}
{"op":"mcm","clk":"11908054099","pt":1724405016576,"mc":[{"id":"1.232013126","rc":[{"batb":[[0,1.48,17.74],[1,1.47,15],[2,1.36,7.31]],"ltp":0.0,"tv":0.0,"id":35736915}]}]}
{"op":"mcm","clk":"11908178230","pt":1724406817083,"mc":[{"id":"1.232013126","rc":[{"batb":[[0,1.47,15],[1,1.36,7.31],[2,1.35,857.14]],"ltp":0.0,"tv":0.0,"id":35736915}]}]}
{"op":"mcm","clk":"11908198477","pt":1724407061339,"mc":[{"id":"1.232013126","rc":[{"batb":[[0,1.48,17.74],[1,1.47,15],[2,1.36,7.31]],"ltp":0.0,"tv":0.0,"id":35736915}]}]}
{"op":"mcm","clk":"11908353289","pt":1724408861736,"mc":[{"id":"1.232013126","rc":[{"batb":[[0,1.47,15],[1,1.36,7.31],[2,1.35,857.14]],"batl":[[1,5.3,14.63]],"ltp":0.0,"tv":0.0,"id":35736915}]}]}
{"op":"mcm","clk":"11908373883","pt":1724409105485,"mc":[{"id":"1.232013126","rc":[{"batb":[[0,1.48,17.73],[1,1.47,15],[2,1.36,7.31]],"ltp":0.0,"tv":0.0,"id":35736915}]}]}
{"op":"mcm","clk":"11908507790","pt":1724410481241,"mc":[{"id":"1.232013126","rc":[{"batb":[[2,1.21,82.35]],"ltp":1.28,"tv":1.95,"id":11445383}]}]}
{"op":"mcm","clk":"11908507820","pt":1724410481549,"mc":[{"id":"1.232013126","rc":[{"batl":[[1,5.3,0]],"ltp":0.0,"tv":0.0,"id":35736915}]}]}
{"op":"mcm","clk":"11908534129","pt":1724410766456,"mc":[{"id":"1.232013126","rc":[{"batb":[[2,1.22,909.09]],"ltp":1.28,"tv":1.95,"id":11445383}]}]}
{"op":"mcm","clk":"11908548214","pt":1724410906040,"mc":[{"id":"1.232013126","rc":[{"batb":[[0,1.47,15],[1,1.36,7.32],[2,1.22,909.09]],"ltp":0.0,"tv":0.0,"id":35736915},{"trd":[[1.28,1.95]],"batb":[[1,1.24,7.11]],"ltp":1.28,"tv":1.95,"id":11445383}],"tv":1.95}]}
{"op":"mcm","clk":"11908570791","pt":1724411144727,"mc":[{"id":"1.232013126","rc":[{"batb":[[0,1.48,17.75],[1,1.47,15],[2,1.36,7.32]],"ltp":0.0,"tv":0.0,"id":35736915}]}]}
{"op":"mcm","clk":"11908576909","pt":1724411211279,"mc":[{"id":"1.232013126","rc":[{"batb":[[1,1.23,7.11]],"ltp":1.28,"tv":1.95,"id":11445383}]}]}
{"op":"mcm","clk":"11908576950","pt":1724411211691,"mc":[{"id":"1.232013126","rc":[{"batb":[[2,1.23,7.32]],"ltp":0.0,"tv":0.0,"id":35736915}]}]}
{"op":"mcm","clk":"11908690225","pt":1724412374476,"mc":[{"id":"1.232013126","rc":[{"batl":[[1,5.5,10.14]],"ltp":0.0,"tv":0.0,"id":35736915}]}]}
{"op":"mcm","clk":"11908749534","pt":1724412945174,"mc":[{"id":"1.232013126","rc":[{"batb":[[0,1.47,15],[1,1.23,7.32],[2,1.22,909.09]],"ltp":0.0,"tv":0.0,"id":35736915}]}]}
{"op":"mcm","clk":"11908774569","pt":1724413182343,"mc":[{"id":"1.232013126","rc":[{"batb":[[0,1.48,17.75],[1,1.47,15],[2,1.23,7.32]],"ltp":0.0,"tv":0.0,"id":35736915}]}]}
{"op":"mcm","clk":"11908961701","pt":1724414982790,"mc":[{"id":"1.232013126","rc":[{"batb":[[0,1.47,15],[1,1.23,7.31],[2,1.22,909.09]],"batl":[[1,5.5,10.13]],"ltp":0.0,"tv":0.0,"id":35736915},{"batb":[[1,1.23,7.11]],"ltp":1.28,"tv":1.95,"id":11445383}]}]}
{"op":"mcm","clk":"11909001512","pt":1724415205760,"mc":[{"id":"1.232013126","rc":[{"batb":[[0,1.48,17.74],[1,1.47,15],[2,1.23,7.31]],"ltp":0.0,"tv":0.0,"id":35736915}]}]}
{"op":"mcm","clk":"11909174685","pt":1724417006112,"mc":[{"id":"1.232013126","rc":[{"batb":[[0,1.47,15],[1,1.23,7.31],[2,1.22,909.09]],"ltp":0.0,"tv":0.0,"id":35736915}]}]}
{"op":"mcm","clk":"11909194102","pt":1724417216637,"mc":[{"id":"1.232013126","rc":[{"batb":[[0,1.48,17.74],[1,1.47,15],[2,1.23,7.31]],"ltp":0.0,"tv":0.0,"id":35736915}]}]}
{"op":"mcm","clk":"11909314345","pt":1724418433732,"mc":[{"id":"1.232013126","rc":[{"batb":[[0,1.48,17.74],[2,1.23,7.32]],"batl":[[1,5.5,10.13]],"ltp":0.0,"tv":0.0,"id":35736915},{"batb":[[1,1.23,7.11]],"batl":[[0,3.2,0.93]],"ltp":1.28,"tv":1.95,"id":11445383}]}]}
{"op":"mcm","clk":"11909315015","pt":1724418439748,"mc":[{"id":"1.232013126","rc":[{"batl":[[0,5.5,11.06],[1,5.5,0]],"ltp":0.0,"tv":0.0,"id":35736915}]}]}
{"op":"mcm","clk":"11909371361","pt":1724419017067,"mc":[{"id":"1.232013126","rc":[{"batb":[[0,1.47,15],[1,1.23,7.32],[2,1.22,909.09]],"ltp":0.0,"tv":0.0,"id":35736915}]}]}
{"op":"mcm","clk":"11909393781","pt":1724419225385,"mc":[{"id":"1.232013126","rc":[{"batb":[[0,1.48,17.74],[1,1.47,15],[2,1.23,7.32]],"ltp":0.0,"tv":0.0,"id":35736915}]}]}
{"op":"mcm","clk":"11909589028","pt":1724421025600,"mc":[{"id":"1.232013126","rc":[{"batb":[[0,1.47,15],[1,1.23,7.32],[2,1.22,909.09]],"ltp":0.0,"tv":0.0,"id":35736915}]}]}
{"op":"mcm","clk":"11909610065","pt":1724421222948,"mc":[{"id":"1.232013126","rc":[{"batb":[[0,1.48,17.74],[1,1.47,15],[2,1.23,7.32]],"ltp":0.0,"tv":0.0,"id":35736915}]}]}
{"op":"mcm","clk":"11909691517","pt":1724422042778,"mc":[{"id":"1.232013126","rc":[{"batb":[[0,1.49,15],[1,1.48,17.74],[2,1.23,7.32]],"ltp":0.0,"tv":0.0,"id":35736915},{"batb":[[1,1.23,7.11]],"ltp":1.28,"tv":1.95,"id":11445383}]}]}
{"op":"mcm","clk":"11909783719","pt":1724423023123,"mc":[{"id":"1.232013126","rc":[{"batb":[[1,1.23,7.32],[2,1.22,909.09]],"ltp":0.0,"tv":0.0,"id":35736915}]}]}
{"op":"mcm","clk":"11909801151","pt":1724423206708,"mc":[{"id":"1.232013126","rc":[{"batb":[[0,1.5,17.03],[1,1.49,15],[2,1.23,7.32]],"ltp":0.0,"tv":0.0,"id":35736915}]}]}
{"op":"mcm","clk":"11909877630","pt":1724423937864,"mc":[{"id":"1.232013126","rc":[{"batl":[[0,3,0.93]],"ltp":1.28,"tv":1.95,"id":11445383}]}]}
{"op":"mcm","clk":"11909982662","pt":1724425007402,"mc":[{"id":"1.232013126","rc":[{"batb":[[0,1.49,15],[1,1.23,7.32],[2,1.22,909.09]],"ltp":0.0,"tv":0.0,"id":35736915}]}]}
{"op":"mcm","clk":"11909997802","pt":1724425177645,"mc":[{"id":"1.232013126","rc":[{"batb":[[0,1.51,16.7],[1,1.49,15],[2,1.23,7.32]],"ltp":0.0,"tv":0.0,"id":35736915}]}]}
{"op":"mcm","clk":"11910106907","pt":1724425975334,"mc":[{"id":"1.232013126","rc":[{"batb":[[0,1.51,16.7],[2,1.23,7.28]],"ltp":0.0,"tv":0.0,"id":35736915},{"trd":[[1.28,1.95]],"batb":[[1,1.23,7.07]],"batl":[[0,3,0.93]],"ltp":1.28,"tv":1.94,"id":11445383}],"tv":1.94}]}
{"op":"mcm","clk":"11910222893","pt":1724426978253,"mc":[{"id":"1.232013126","rc":[{"batb":[[0,1.49,15],[1,1.23,7.28],[2,1.22,909.09]],"ltp":0.0,"tv":0.0,"id":35736915}]}]}
{"op":"mcm","clk":"11910244092","pt":1724427142231,"mc":[{"id":"1.232013126","rc":[{"batb":[[0,1.51,16.7],[1,1.49,15],[2,1.23,7.28]],"ltp":0.0,"tv":0.0,"id":35736915}]}]}
{"op":"mcm","clk":"11910481115","pt":1724428942565,"mc":[{"id":"1.232013126","rc":[{"batb":[[0,1.49,15],[1,1.23,7.28],[2,1.22,909.09]],"batl":[[0,5.5,11.06]],"ltp":0.0,"tv":0.0,"id":35736915}]}]}
{"op":"mcm","clk":"11910509585","pt":1724429103154,"mc":[{"id":"1.232013126","rc":[{"batb":[[0,1.51,16.69],[1,1.49,15],[2,1.23,7.28]],"ltp":0.0,"tv":0.0,"id":35736915}]}]}
{"op":"mcm","clk":"11910836501","pt":1724430904168,"mc":[{"id":"1.232013126","rc":[{"batb":[[0,1.49,15],[1,1.23,7.28],[2,1.22,909.09]],"ltp":0.0,"tv":0.0,"id":35736915}]}]}
{"op":"mcm","clk":"11910865106","pt":1724431058380,"mc":[{"id":"1.232013126","rc":[{"batb":[[0,1.51,16.69],[1,1.49,15],[2,1.23,7.28]],"ltp":0.0,"tv":0.0,"id":35736915}]}]}
{"op":"mcm","clk":"11911203677","pt":1724432859171,"mc":[{"id":"1.232013126","rc":[{"batb":[[0,1.49,15],[1,1.23,7.28],[2,1.22,909.09]],"batl":[[0,5.5,11.06]],"ltp":0.0,"tv":0.0,"id":35736915},{"batb":[[1,1.23,7.07]],"ltp":1.28,"tv":1.94,"id":11445383}]}]}
{"op":"mcm","clk":"11911232192","pt":1724433007126,"mc":[{"id":"1.232013126","rc":[{"batb":[[0,1.51,16.7],[1,1.49,15],[2,1.23,7.28]],"ltp":0.0,"tv":0.0,"id":35736915}]}]}
{"op":"mcm","clk":"11911491767","pt":1724434264202,"mc":[{"id":"1.232013126","rc":[{"batb":[[0,2.18,3.29],[1,1.51,16.7],[2,1.49,15]],"batl":[[0,3.95,0.93]],"ltp":0.0,"tv":0.0,"id":35736915},{"batb":[[0,1.77,5.04],[1,1.34,15],[2,1.23,7.07]],"ltp":1.28,"tv":1.94,"id":11445383}]}]}
{"op":"mcm","clk":"11911588659","pt":1724434700371,"mc":[{"id":"1.232013126","rc":[{"batb":[[2,1.22,909.09]],"ltp":1.28,"tv":1.94,"id":11445383}]}]}
{"op":"mcm","clk":"11911617465","pt":1724434827146,"mc":[{"id":"1.232013126","rc":[{"batb":[[1,1.49,15],[2,1.22,909.09]],"ltp":0.0,"tv":0.0,"id":35736915}]}]}
{"op":"mcm","clk":"11912093642","pt":1724436775400,"mc":[{"id":"1.232013126","rc":[{"batl":[[0,3.95,0.93]],"ltp":0.0,"tv":0.0,"id":35736915},{"trd":[[1.28,1.95]],"batl":[[0,3,0.93]],"ltp":1.28,"tv":1.94,"id":11445383}],"tv":1.94}]}
{"op":"mcm","clk":"11915506959","pt":1724467354813,"mc":[{"id":"1.232013126","rc":[{"batb":[[2,1.04,1.53]],"ltp":0.0,"tv":0.0,"id":35736915},{"batb":[[2,1.04,1.53]],"ltp":1.28,"tv":1.94,"id":11445383}]}]}
{"op":"mcm","clk":"11916062722","pt":1724473788039,"mc":[{"id":"1.232013126","rc":[{"batb":[[2,1.25,864]],"ltp":0.0,"tv":0.0,"id":35736915},{"batb":[[2,1.25,864]],"ltp":1.28,"tv":1.94,"id":11445383}]}]}
{"op":"mcm","clk":"11917478524","pt":1724491804167,"mc":[{"id":"1.232013126","rc":[{"batb":[[0,2.18,32.94]],"ltp":0.0,"tv":0.0,"id":35736915},{"batb":[[0,1.77,50.48]],"ltp":1.28,"tv":1.94,"id":11445383}]}]}
{"op":"mcm","clk":"11920068250","pt":1724506515955,"mc":[{"id":"1.232013126","rc":[{"batb":[[0,2.18,36.39]],"ltp":0.0,"tv":0.0,"id":35736915},{"batb":[[0,1.77,55.77]],"ltp":1.28,"tv":1.94,"id":11445383}]}]}
{"op":"mcm","clk":"11922833483","pt":1724519501195,"mc":[{"id":"1.232013126","rc":[{"batb":[[1,1.25,864],[2,1.04,1.53]],"ltp":0.0,"tv":0.0,"id":35736915},{"batb":[[1,1.25,864],[2,1.04,1.53]],"ltp":1.28,"tv":1.94,"id":11445383}]}]}
{"op":"mcm","clk":"11925236624","pt":1724537635298,"mc":[{"id":"1.232013126","rc":[{"trd":[[2.18,72.78]],"batb":[[0,1.26,5]],"batl":[[0,2.18,15.07]],"ltp":2.18,"tv":72.78,"id":35736915}],"tv":74.72}]}
{"op":"mcm","clk":"11925236641","pt":1724537635604,"mc":[{"id":"1.232013126","rc":[{"batb":[[0,1.48,153.85],[1,1.26,5],[2,1.25,864]],"ltp":2.18,"tv":72.78,"id":35736915}]}]}
{"op":"mcm","clk":"11925236771","pt":1724537638276,"mc":[{"id":"1.232013126","rc":[{"batb":[[0,2.1,39.04],[1,1.48,153.85],[2,1.26,5]],"ltp":2.18,"tv":72.78,"id":35736915}]}]}
{"op":"mcm","clk":"11925236796","pt":1724537638986,"mc":[{"id":"1.232013126","rc":[{"batb":[[2,1.25,864]],"ltp":2.18,"tv":72.78,"id":35736915}]}]}
{"op":"mcm","clk":"11925237329","pt":1724537650130,"mc":[{"id":"1.232013126","rc":[{"batb":[[1,1.25,864],[2,1.04,1.53]],"batl":[[0,2.18,66.54]],"ltp":2.18,"tv":72.78,"id":35736915}]}]}
{"op":"mcm","clk":"11925407938","pt":1724540707564,"mc":[{"id":"1.232013126","rc":[{"batb":[[0,1.84,51.13]],"ltp":1.28,"tv":1.94,"id":11445383}]}]}
{"op":"mcm","clk":"11925467934","pt":1724541678451,"mc":[{"id":"1.232013126","rc":[{"batb":[[0,1.85,6.38],[1,1.84,51.13],[2,1.25,864]],"ltp":1.28,"tv":1.94,"id":11445383}]}]}
{"op":"mcm","clk":"11925644955","pt":1724544351537,"mc":[{"id":"1.232013126","rc":[{"trd":[[2.1,77.16],[2.18,72.76]],"batb":[[0,1.25,864.46],[1,1.04,1.53],[2,1.03,200]],"batl":[[0,2.18,66.5]],"ltp":2.1,"tv":149.91,"id":35736915}],"tv":151.86}]}
{"op":"mcm","clk":"11925644965","pt":1724544351640,"mc":[{"id":"1.232013126","rc":[{"batb":[[0,1.5,151.16],[1,1.26,5],[2,1.25,864]],"ltp":2.1,"tv":149.91,"id":35736915}]}]}
{"op":"mcm","clk":"11925645098","pt":1724544353503,"mc":[{"id":"1.232013126","rc":[{"batb":[[0,2.02,42.56],[1,1.5,150.7],[2,1.26,5]],"ltp":2.1,"tv":149.91,"id":35736915}]}]}
{"op":"mcm","clk":"11925645104","pt":1724544353605,"mc":[{"id":"1.232013126","rc":[{"batb":[[0,2.02,42.1]],"ltp":2.1,"tv":149.91,"id":35736915}]}]}
{"op":"mcm","clk":"11925645188","pt":1724544354947,"mc":[{"id":"1.232013126","rc":[{"batb":[[2,1.25,864]],"ltp":2.1,"tv":149.91,"id":35736915}]}]}
{"op":"mcm","clk":"11925645354","pt":1724544357343,"mc":[{"id":"1.232013126","rc":[{"batb":[[0,2.04,5],[1,2.02,42.1],[2,1.5,150.7]],"ltp":2.1,"tv":149.91,"id":35736915}]}]}
{"op":"mcm","clk":"11925645616","pt":1724544360741,"mc":[{"id":"1.232013126","rc":[{"batb":[[0,2.02,42.1],[1,1.5,150.7],[2,1.25,864]],"ltp":2.1,"tv":149.91,"id":35736915}]}]}
{"op":"mcm","clk":"11925645774","pt":1724544362912,"mc":[{"id":"1.232013126","rc":[{"batb":[[0,2.04,5],[1,2.02,42.1],[2,1.5,150.7]],"ltp":2.1,"tv":149.91,"id":35736915}]}]}
{"op":"mcm","clk":"11925646034","pt":1724544366411,"mc":[{"id":"1.232013126","rc":[{"batb":[[0,2.02,42.1],[1,1.5,150.7],[2,1.25,864]],"ltp":2.1,"tv":149.91,"id":35736915}]}]}
{"op":"mcm","clk":"11925646044","pt":1724544366620,"mc":[{"id":"1.232013126","rc":[{"batb":[[1,1.25,864],[2,1.04,1.53]],"ltp":2.1,"tv":149.91,"id":35736915}]}]}
{"op":"mcm","clk":"11925646174","pt":1724544368528,"mc":[{"id":"1.232013126","rc":[{"batb":[[0,2.04,5],[1,2.02,42.1],[2,1.25,864]],"ltp":2.1,"tv":149.91,"id":35736915}]}]}
{"op":"mcm","clk":"11925646421","pt":1724544372026,"mc":[{"id":"1.232013126","rc":[{"batb":[[0,2.02,42.1],[1,1.25,864],[2,1.04,1.53]],"ltp":2.1,"tv":149.91,"id":35736915}]}]}
{"op":"mcm","clk":"11925646642","pt":1724544374762,"mc":[{"id":"1.232013126","rc":[{"batb":[[0,2.04,5],[1,2.02,42.1],[2,1.25,864]],"ltp":2.1,"tv":149.91,"id":35736915}]}]}
{"op":"mcm","clk":"11925646843","pt":1724544378135,"mc":[{"id":"1.232013126","rc":[{"batb":[[0,2.02,42.1],[1,1.25,864],[2,1.04,1.53]],"ltp":2.1,"tv":149.91,"id":35736915}]}]}
{"op":"mcm","clk":"11925647003","pt":1724544380863,"mc":[{"id":"1.232013126","rc":[{"batb":[[0,2.04,5],[1,2.02,42.1],[2,1.25,864]],"ltp":2.1,"tv":149.91,"id":35736915}]}]}
{"op":"mcm","clk":"11925647207","pt":1724544384375,"mc":[{"id":"1.232013126","rc":[{"batb":[[0,2.02,42.1],[1,1.25,864],[2,1.04,1.53]],"ltp":2.1,"tv":149.91,"id":35736915}]}]}
{"op":"mcm","clk":"11925647356","pt":1724544386650,"mc":[{"id":"1.232013126","rc":[{"batb":[[0,2.04,5],[1,2.02,42.1],[2,1.25,864]],"ltp":2.1,"tv":149.91,"id":35736915}]}]}
{"op":"mcm","clk":"11925647538","pt":1724544389941,"mc":[{"id":"1.232013126","rc":[{"batb":[[0,2.02,42.1],[1,1.25,864],[2,1.04,1.53]],"ltp":2.1,"tv":149.91,"id":35736915}]}]}
{"op":"mcm","clk":"11925647746","pt":1724544392684,"mc":[{"id":"1.232013126","rc":[{"batb":[[0,2.04,5],[1,2.02,42.1],[2,1.25,864]],"ltp":2.1,"tv":149.91,"id":35736915}]}]}
{"op":"mcm","clk":"11925648002","pt":1724544395971,"mc":[{"id":"1.232013126","rc":[{"batb":[[0,2.02,42.1],[1,1.25,864],[2,1.04,1.53]],"ltp":2.1,"tv":149.91,"id":35736915}]}]}
{"op":"mcm","clk":"11925648151","pt":1724544398447,"mc":[{"id":"1.232013126","rc":[{"batb":[[0,2.04,5],[1,2.02,42.1],[2,1.25,864]],"ltp":2.1,"tv":149.91,"id":35736915}]}]}
{"op":"mcm","clk":"11925648396","pt":1724544401791,"mc":[{"id":"1.232013126","rc":[{"batb":[[0,2.02,42.1],[1,1.25,864],[2,1.04,1.53]],"ltp":2.1,"tv":149.91,"id":35736915}]}]}
{"op":"mcm","clk":"11925648547","pt":1724544404112,"mc":[{"id":"1.232013126","rc":[{"batb":[[0,2.04,5],[1,2.02,42.1],[2,1.25,864]],"ltp":2.1,"tv":149.91,"id":35736915}]}]}
{"op":"mcm","clk":"11925648779","pt":1724544407471,"mc":[{"id":"1.232013126","rc":[{"batb":[[0,2.02,42.1],[1,1.25,864],[2,1.04,1.53]],"ltp":2.1,"tv":149.91,"id":35736915}]}]}
{"op":"mcm","clk":"11925648966","pt":1724544410103,"mc":[{"id":"1.232013126","rc":[{"batb":[[0,2.04,5],[1,2.02,42.1],[2,1.25,864]],"ltp":2.1,"tv":149.91,"id":35736915}]}]}
{"op":"mcm","clk":"11925649196","pt":1724544413296,"mc":[{"id":"1.232013126","rc":[{"batb":[[0,2.02,42.1],[1,1.25,864],[2,1.04,1.53]],"ltp":2.1,"tv":149.91,"id":35736915}]}]}
{"op":"mcm","clk":"11925649357","pt":1724544416006,"mc":[{"id":"1.232013126","rc":[{"batb":[[0,2.04,5],[1,2.02,42.1],[2,1.25,864]],"ltp":2.1,"tv":149.91,"id":35736915}]}]}
{"op":"mcm","clk":"11925649614","pt":1724544419502,"mc":[{"id":"1.232013126","rc":[{"batb":[[0,2.02,42.1],[1,1.25,864],[2,1.04,1.53]],"ltp":2.1,"tv":149.91,"id":35736915}]}]}
{"op":"mcm","clk":"11925649778","pt":1724544421792,"mc":[{"id":"1.232013126","rc":[{"batb":[[0,2.04,5],[1,2.02,42.1],[2,1.25,864]],"ltp":2.1,"tv":149.91,"id":35736915}]}]}
{"op":"mcm","clk":"11925650013","pt":1724544425194,"mc":[{"id":"1.232013126","rc":[{"batb":[[0,2.02,42.1],[1,1.25,864],[2,1.04,1.53]],"ltp":2.1,"tv":149.91,"id":35736915}]}]}
{"op":"mcm","clk":"11925650183","pt":1724544427626,"mc":[{"id":"1.232013126","rc":[{"batb":[[0,2.04,5],[1,2.02,42.1],[2,1.25,864]],"ltp":2.1,"tv":149.91,"id":35736915}]}]}
{"op":"mcm","clk":"11925650448","pt":1724544430911,"mc":[{"id":"1.232013126","rc":[{"batb":[[0,2.02,42.1],[1,1.25,864],[2,1.04,1.53]],"ltp":2.1,"tv":149.91,"id":35736915}]}]}
{"op":"mcm","clk":"11925650654","pt":1724544433594,"mc":[{"id":"1.232013126","rc":[{"batb":[[0,2.04,5],[1,2.02,42.1],[2,1.25,864]],"ltp":2.1,"tv":149.91,"id":35736915}]}]}
{"op":"mcm","clk":"11925650893","pt":1724544436999,"mc":[{"id":"1.232013126","rc":[{"batb":[[0,2.02,42.1],[1,1.25,864],[2,1.04,1.53]],"ltp":2.1,"tv":149.91,"id":35736915}]}]}
{"op":"mcm","clk":"11925651058","pt":1724544439425,"mc":[{"id":"1.232013126","rc":[{"batb":[[0,2.04,5],[1,2.02,42.1],[2,1.25,864]],"ltp":2.1,"tv":149.91,"id":35736915}]}]}
{"op":"mcm","clk":"11925651284","pt":1724544442731,"mc":[{"id":"1.232013126","rc":[{"batb":[[0,2.02,42.1],[1,1.25,864],[2,1.04,1.53]],"ltp":2.1,"tv":149.91,"id":35736915}]}]}
{"op":"mcm","clk":"11925651449","pt":1724544445045,"mc":[{"id":"1.232013126","rc":[{"batb":[[0,2.04,5],[1,2.02,42.1],[2,1.25,864]],"ltp":2.1,"tv":149.91,"id":35736915}]}]}
{"op":"mcm","clk":"11925651696","pt":1724544448353,"mc":[{"id":"1.232013126","rc":[{"batb":[[0,2.02,42.1],[1,1.25,864],[2,1.04,1.53]],"ltp":2.1,"tv":149.91,"id":35736915}]}]}
{"op":"mcm","clk":"11925651862","pt":1724544450825,"mc":[{"id":"1.232013126","rc":[{"batb":[[0,2.04,5],[1,2.02,42.1],[2,1.25,864]],"ltp":2.1,"tv":149.91,"id":35736915}]}]}
{"op":"mcm","clk":"11925652065","pt":1724544454218,"mc":[{"id":"1.232013126","rc":[{"batb":[[0,2.02,42.1],[1,1.25,864],[2,1.04,1.53]],"ltp":2.1,"tv":149.91,"id":35736915}]}]}
{"op":"mcm","clk":"11925652250","pt":1724544456646,"mc":[{"id":"1.232013126","rc":[{"batb":[[0,2.04,5],[1,2.02,42.1],[2,1.25,864]],"ltp":2.1,"tv":149.91,"id":35736915}]}]}
{"op":"mcm","clk":"11925652460","pt":1724544460053,"mc":[{"id":"1.232013126","rc":[{"batb":[[0,2.02,42.1],[1,1.25,864],[2,1.04,1.53]],"ltp":2.1,"tv":149.91,"id":35736915}]}]}
{"op":"mcm","clk":"11925652604","pt":1724544462452,"mc":[{"id":"1.232013126","rc":[{"batb":[[0,2.04,5],[1,2.02,42.1],[2,1.25,864]],"ltp":2.1,"tv":149.91,"id":35736915}]}]}
{"op":"mcm","clk":"11925652863","pt":1724544465857,"mc":[{"id":"1.232013126","rc":[{"batb":[[0,2.02,42.1],[1,1.25,864],[2,1.04,1.53]],"ltp":2.1,"tv":149.91,"id":35736915}]}]}
{"op":"mcm","clk":"11925653066","pt":1724544468341,"mc":[{"id":"1.232013126","rc":[{"batb":[[0,2.04,5],[1,2.02,42.1],[2,1.25,864]],"ltp":2.1,"tv":149.91,"id":35736915}]}]}
{"op":"mcm","clk":"11925653282","pt":1724544471744,"mc":[{"id":"1.232013126","rc":[{"batb":[[0,2.02,42.1],[1,1.25,864],[2,1.04,1.53]],"ltp":2.1,"tv":149.91,"id":35736915}]}]}
{"op":"mcm","clk":"11925653466","pt":1724544474274,"mc":[{"id":"1.232013126","rc":[{"batb":[[0,2.04,5],[1,2.02,42.1],[2,1.25,864]],"ltp":2.1,"tv":149.91,"id":35736915}]}]}
{"op":"mcm","clk":"11925653703","pt":1724544477584,"mc":[{"id":"1.232013126","rc":[{"batb":[[0,2.02,42.1],[1,1.25,864],[2,1.04,1.53]],"ltp":2.1,"tv":149.91,"id":35736915}]}]}
{"op":"mcm","clk":"11925653903","pt":1724544480469,"mc":[{"id":"1.232013126","rc":[{"batb":[[0,2.04,5],[1,2.02,42.1],[2,1.25,864]],"ltp":2.1,"tv":149.91,"id":35736915}]}]}
{"op":"mcm","clk":"11925654134","pt":1724544483779,"mc":[{"id":"1.232013126","rc":[{"batb":[[0,2.02,42.1],[1,1.25,864],[2,1.04,1.53]],"ltp":2.1,"tv":149.91,"id":35736915}]}]}
{"op":"mcm","clk":"11925654305","pt":1724544486265,"mc":[{"id":"1.232013126","rc":[{"batb":[[0,2.04,5],[1,2.02,42.1],[2,1.25,864]],"ltp":2.1,"tv":149.91,"id":35736915}]}]}
{"op":"mcm","clk":"11925654544","pt":1724544489561,"mc":[{"id":"1.232013126","rc":[{"batb":[[0,2.02,42.1],[1,1.25,864],[2,1.04,1.53]],"ltp":2.1,"tv":149.91,"id":35736915}]}]}
{"op":"mcm","clk":"11925654744","pt":1724544492090,"mc":[{"id":"1.232013126","rc":[{"batb":[[0,2.04,5],[1,2.02,42.1],[2,1.25,864]],"ltp":2.1,"tv":149.91,"id":35736915}]}]}
{"op":"mcm","clk":"11925654956","pt":1724544495599,"mc":[{"id":"1.232013126","rc":[{"batb":[[0,2.02,42.1],[1,1.25,864],[2,1.04,1.53]],"ltp":2.1,"tv":149.91,"id":35736915}]}]}
{"op":"mcm","clk":"11925655107","pt":1724544497768,"mc":[{"id":"1.232013126","rc":[{"batb":[[0,2.04,5],[1,2.02,42.1],[2,1.25,864]],"ltp":2.1,"tv":149.91,"id":35736915}]}]}
{"op":"mcm","clk":"11925655391","pt":1724544501173,"mc":[{"id":"1.232013126","rc":[{"batb":[[0,2.02,42.1],[1,1.25,864],[2,1.04,1.53]],"ltp":2.1,"tv":149.91,"id":35736915}]}]}
{"op":"mcm","clk":"11925655571","pt":1724544503398,"mc":[{"id":"1.232013126","rc":[{"batb":[[0,2.04,5],[1,2.02,42.1],[2,1.25,864]],"ltp":2.1,"tv":149.91,"id":35736915}]}]}
{"op":"mcm","clk":"11925655857","pt":1724544506811,"mc":[{"id":"1.232013126","rc":[{"batb":[[0,2.02,42.1],[1,1.25,864],[2,1.04,1.53]],"ltp":2.1,"tv":149.91,"id":35736915}]}]}
{"op":"mcm","clk":"11925656052","pt":1724544509187,"mc":[{"id":"1.232013126","rc":[{"batb":[[0,2.04,5],[1,2.02,42.1],[2,1.25,864]],"ltp":2.1,"tv":149.91,"id":35736915}]}]}
{"op":"mcm","clk":"11925656349","pt":1724544512705,"mc":[{"id":"1.232013126","rc":[{"batb":[[0,2.02,42.1],[1,1.25,864],[2,1.04,1.53]],"ltp":2.1,"tv":149.91,"id":35736915}]}]}
{"op":"mcm","clk":"11925656554","pt":1724544514885,"mc":[{"id":"1.232013126","rc":[{"batb":[[0,2.04,5],[1,2.02,42.1],[2,1.25,864]],"ltp":2.1,"tv":149.91,"id":35736915}]}]}
{"op":"mcm","clk":"11925656821","pt":1724544518078,"mc":[{"id":"1.232013126","rc":[{"batb":[[0,2.02,42.1],[1,1.25,864],[2,1.04,1.53]],"ltp":2.1,"tv":149.91,"id":35736915}]}]}
{"op":"mcm","clk":"11925657020","pt":1724544520707,"mc":[{"id":"1.232013126","rc":[{"batb":[[0,2.04,5],[1,2.02,42.1],[2,1.25,864]],"ltp":2.1,"tv":149.91,"id":35736915}]}]}
{"op":"mcm","clk":"11925657273","pt":1724544524008,"mc":[{"id":"1.232013126","rc":[{"batb":[[0,2.02,42.1],[1,1.25,864],[2,1.04,1.53]],"ltp":2.1,"tv":149.91,"id":35736915}]}]}
{"op":"mcm","clk":"11925657488","pt":1724544527126,"mc":[{"id":"1.232013126","rc":[{"batb":[[0,2.04,5],[1,2.02,42.1],[2,1.25,864]],"ltp":2.1,"tv":149.91,"id":35736915}]}]}
{"op":"mcm","clk":"11925657718","pt":1724544530328,"mc":[{"id":"1.232013126","rc":[{"batb":[[0,2.02,42.1],[1,1.25,864],[2,1.04,1.53]],"ltp":2.1,"tv":149.91,"id":35736915}]}]}
{"op":"mcm","clk":"11925657903","pt":1724544532907,"mc":[{"id":"1.232013126","rc":[{"batb":[[0,2.04,5],[1,2.02,42.1],[2,1.25,864]],"ltp":2.1,"tv":149.91,"id":35736915}]}]}
{"op":"mcm","clk":"11925658172","pt":1724544536106,"mc":[{"id":"1.232013126","rc":[{"batb":[[0,2.02,42.1],[1,1.25,864],[2,1.04,1.53]],"ltp":2.1,"tv":149.91,"id":35736915}]}]}
{"op":"mcm","clk":"11925658390","pt":1724544538526,"mc":[{"id":"1.232013126","rc":[{"batb":[[0,2.04,5],[1,2.02,42.1],[2,1.25,864]],"ltp":2.1,"tv":149.91,"id":35736915}]}]}
{"op":"mcm","clk":"11925658650","pt":1724544541845,"mc":[{"id":"1.232013126","rc":[{"batb":[[0,2.02,42.1],[1,1.25,864],[2,1.04,1.53]],"ltp":2.1,"tv":149.91,"id":35736915}]}]}
{"op":"mcm","clk":"11925658846","pt":1724544544424,"mc":[{"id":"1.232013126","rc":[{"batb":[[0,2.04,5],[1,2.02,42.1],[2,1.25,864]],"ltp":2.1,"tv":149.91,"id":35736915}]}]}
{"op":"mcm","clk":"11925659119","pt":1724544547726,"mc":[{"id":"1.232013126","rc":[{"batb":[[0,2.02,42.1],[1,1.25,864],[2,1.04,1.53]],"ltp":2.1,"tv":149.91,"id":35736915}]}]}
{"op":"mcm","clk":"11925659342","pt":1724544550207,"mc":[{"id":"1.232013126","rc":[{"batb":[[0,2.04,5],[1,2.02,42.1],[2,1.25,864]],"ltp":2.1,"tv":149.91,"id":35736915}]}]}
{"op":"mcm","clk":"11925659620","pt":1724544553516,"mc":[{"id":"1.232013126","rc":[{"batb":[[0,2.02,42.1],[1,1.25,864],[2,1.04,1.53]],"ltp":2.1,"tv":149.91,"id":35736915}]}]}
{"op":"mcm","clk":"11925659965","pt":1724544557957,"mc":[{"id":"1.232013126","rc":[{"batb":[[0,2.04,5],[1,2.02,42.1],[2,1.25,864]],"ltp":2.1,"tv":149.91,"id":35736915}]}]}
{"op":"mcm","clk":"11925660218","pt":1724544561463,"mc":[{"id":"1.232013126","rc":[{"batb":[[0,2.02,42.1],[1,1.25,864],[2,1.04,1.53]],"ltp":2.1,"tv":149.91,"id":35736915}]}]}
{"op":"mcm","clk":"11925660376","pt":1724544563727,"mc":[{"id":"1.232013126","rc":[{"batb":[[0,2.04,5],[1,2.02,42.1],[2,1.25,864]],"ltp":2.1,"tv":149.91,"id":35736915}]}]}
{"op":"mcm","clk":"11925660610","pt":1724544567138,"mc":[{"id":"1.232013126","rc":[{"batb":[[0,2.02,42.1],[1,1.25,864],[2,1.04,1.53]],"ltp":2.1,"tv":149.91,"id":35736915}]}]}
{"op":"mcm","clk":"11925660745","pt":1724544569050,"mc":[{"id":"1.232013126","rc":[{"batb":[[0,1.84,51.13],[1,1.25,864],[2,1.04,1.53]],"ltp":1.28,"tv":1.94,"id":11445383}]}]}
{"op":"mcm","clk":"11926120374","pt":1724550175186,"mc":[{"id":"1.232013126","rc":[{"trd":[[2.1,77.18],[2.18,72.78]],"ltp":2.1,"tv":149.96,"id":35736915}],"tv":151.9}]}
{"op":"mcm","clk":"11927619410","pt":1724578515014,"mc":[{"id":"1.232013126","rc":[{"batb":[[1,1.74,17.32],[2,1.25,864]],"ltp":2.1,"tv":149.96,"id":35736915},{"batb":[[1,1.74,17.32],[2,1.25,864]],"ltp":1.28,"tv":1.94,"id":11445383}]}]}
{"op":"mcm","clk":"11927771913","pt":1724580052489,"mc":[{"id":"1.232013126","rc":[{"trd":[[2.02,84.2]],"batb":[[0,1.75,67.91]],"batl":[[0,2.02,157.9]],"ltp":2.02,"tv":234.16,"id":35736915}],"tv":236.1}]}
{"op":"mcm","clk":"11927772006","pt":1724580053267,"mc":[{"id":"1.232013126","rc":[{"batb":[[0,1.97,37.25],[1,1.76,5],[2,1.75,67.91]],"ltp":2.02,"tv":234.16,"id":35736915}]}]}
{"op":"mcm","clk":"11927772350","pt":1724580056284,"mc":[{"id":"1.232013126","rc":[{"batb":[[1,1.75,67.91],[2,1.74,17.32]],"ltp":2.02,"tv":234.16,"id":35736915}]}]}
{"op":"mcm","clk":"11927773125","pt":1724580061592,"mc":[{"id":"1.232013126","rc":[{"trd":[[1.97,74.5]],"batb":[[0,1.75,67.91],[1,1.74,17.32],[2,1.25,864]],"batl":[[0,1.97,262.75],[1,2.02,157.9]],"ltp":1.97,"tv":308.66,"id":35736915}],"tv":310.6}]}
{"op":"mcm","clk":"11927774433","pt":1724580072111,"mc":[{"id":"1.232013126","rc":[{"trd":[[1.97,256.18]],"batl":[[0,1.86,350],[1,1.97,81.07],[2,2.02,157.9]],"ltp":1.97,"tv":490.34,"id":35736915},{"trd":[[2.02,177.19]],"ltp":2.02,"tv":179.13,"id":11445383}],"tv":669.47}]}
{"op":"mcm","clk":"11927775245","pt":1724580079706,"mc":[{"id":"1.232013126","rc":[{"trd":[[1.86,342.94]],"batl":[[0,1.86,7.06]],"ltp":1.86,"tv":833.28,"id":35736915},{"trd":[[2.16,295.31]],"ltp":2.16,"tv":474.44,"id":11445383}],"tv":1307.72}]}
{"op":"mcm","clk":"11927776547","pt":1724580090845,"mc":[{"id":"1.232013126","rc":[{"trd":[[1.86,350],[1.97,337.25]],"batb":[[0,1.76,5],[1,1.75,67.91],[2,1.74,17.32]],"batl":[[0,2.02,157.9],[1,1.97,0],[2,2.02,0]],"ltp":1.97,"tv":921.41,"id":35736915},{"trd":[[2.02,256.25],[2.16,301.39]],"batb":[[0,1.85,5],[1,1.84,51.13],[2,1.74,17.32]],"batl":[[0,2.02,3.45]],"ltp":2.02,"tv":559.58,"id":11445383}],"tv":1480.99}]}
{"op":"mcm","clk":"11927776965","pt":1724580094050,"mc":[{"id":"1.232013126","rc":[{"batb":[[0,1.75,67.91],[1,1.74,17.32],[2,1.25,864]],"ltp":1.97,"tv":921.41,"id":35736915},{"batb":[[0,1.84,51.13],[1,1.74,17.32],[2,1.25,864]],"ltp":2.02,"tv":559.58,"id":11445383}]}]}
{"op":"mcm","clk":"11927779023","pt":1724580109927,"mc":[{"id":"1.232013126","rc":[{"batb":[[0,1.76,5]],"ltp":1.97,"tv":921.41,"id":35736915},{"batb":[[0,1.85,5],[1,1.84,51.13],[2,1.74,17.32]],"ltp":2.02,"tv":559.58,"id":11445383}]}]}
{"op":"mcm","clk":"11927779378","pt":1724580113040,"mc":[{"id":"1.232013126","rc":[{"batb":[[0,1.74,17.32],[1,1.25,864],[2,1.04,1.53]],"ltp":1.97,"tv":921.41,"id":35736915},{"batb":[[0,1.84,51.13],[1,1.74,17.32],[2,1.25,864]],"ltp":2.02,"tv":559.58,"id":11445383}]}]}
{"op":"mcm","clk":"11927780225","pt":1724580121045,"mc":[{"id":"1.232013126","rc":[{"batb":[[0,1.75,5],[1,1.74,17.32],[2,1.25,864]],"ltp":1.97,"tv":921.41,"id":35736915},{"batb":[[0,1.85,5],[1,1.84,51.13],[2,1.74,17.32]],"ltp":2.02,"tv":559.58,"id":11445383}]}]}
{"op":"mcm","clk":"11927780634","pt":1724580124436,"mc":[{"id":"1.232013126","rc":[{"batb":[[0,1.74,17.32],[1,1.25,864],[2,1.04,1.53]],"ltp":1.97,"tv":921.41,"id":35736915},{"batb":[[0,1.84,51.13],[1,1.74,17.32],[2,1.25,864]],"ltp":2.02,"tv":559.58,"id":11445383}]}]}
{"op":"mcm","clk":"11927781317","pt":1724580130462,"mc":[{"id":"1.232013126","rc":[{"batb":[[0,1.75,5],[1,1.74,17.32],[2,1.25,864]],"ltp":1.97,"tv":921.41,"id":35736915},{"batb":[[0,1.85,5],[1,1.84,51.13],[2,1.74,17.32]],"ltp":2.02,"tv":559.58,"id":11445383}]}]}
{"op":"mcm","clk":"11927781758","pt":1724580133878,"mc":[{"id":"1.232013126","rc":[{"batb":[[0,1.74,17.32],[1,1.25,864],[2,1.04,1.53]],"ltp":1.97,"tv":921.41,"id":35736915},{"batb":[[0,1.84,51.13],[1,1.74,17.32],[2,1.25,864]],"ltp":2.02,"tv":559.58,"id":11445383}]}]}
{"op":"mcm","clk":"11927782154","pt":1724580137168,"mc":[{"id":"1.232013126","rc":[{"batb":[[0,1.75,5],[1,1.74,17.32],[2,1.25,864]],"ltp":1.97,"tv":921.41,"id":35736915},{"batb":[[0,1.85,5],[1,1.84,51.13],[2,1.74,17.32]],"ltp":2.02,"tv":559.58,"id":11445383}]}]}
{"op":"mcm","clk":"11927782495","pt":1724580140488,"mc":[{"id":"1.232013126","rc":[{"batb":[[0,1.74,17.32],[1,1.25,864],[2,1.04,1.53]],"ltp":1.97,"tv":921.41,"id":35736915},{"batb":[[0,1.84,51.13],[1,1.74,17.32],[2,1.25,864]],"ltp":2.02,"tv":559.58,"id":11445383}]}]}
{"op":"mcm","clk":"11927783528","pt":1724580149896,"mc":[{"id":"1.232013126","rc":[{"batb":[[0,1.75,5],[1,1.74,17.32],[2,1.25,864]],"ltp":1.97,"tv":921.41,"id":35736915},{"batb":[[0,1.85,5],[1,1.84,51.13],[2,1.74,17.32]],"ltp":2.02,"tv":559.58,"id":11445383}]}]}
{"op":"mcm","clk":"11927783933","pt":1724580153287,"mc":[{"id":"1.232013126","rc":[{"batb":[[0,1.74,17.32],[1,1.25,864],[2,1.04,1.53]],"ltp":1.97,"tv":921.41,"id":35736915},{"batb":[[0,1.84,51.13],[1,1.74,17.32],[2,1.25,864]],"ltp":2.02,"tv":559.58,"id":11445383}]}]}
{"op":"mcm","clk":"11927784550","pt":1724580159001,"mc":[{"id":"1.232013126","rc":[{"batb":[[0,1.75,5],[1,1.74,17.32],[2,1.25,864]],"ltp":1.97,"tv":921.41,"id":35736915},{"batb":[[0,1.85,5],[1,1.84,51.13],[2,1.74,17.32]],"ltp":2.02,"tv":559.58,"id":11445383}]}]}
{"op":"mcm","clk":"11927784866","pt":1724580162181,"mc":[{"id":"1.232013126","rc":[{"batb":[[0,1.74,17.32],[1,1.25,864],[2,1.04,1.53]],"ltp":1.97,"tv":921.41,"id":35736915},{"batb":[[0,1.84,51.13],[1,1.74,17.32],[2,1.25,864]],"ltp":2.02,"tv":559.58,"id":11445383}]}]}
{"op":"mcm","clk":"11927785978","pt":1724580172493,"mc":[{"id":"1.232013126","rc":[{"batb":[[0,1.75,5],[1,1.74,17.32],[2,1.25,864]],"ltp":1.97,"tv":921.41,"id":35736915},{"batb":[[0,1.85,5],[1,1.84,51.13],[2,1.74,17.32]],"ltp":2.02,"tv":559.58,"id":11445383}]}]}
{"op":"mcm","clk":"11927786326","pt":1724580175851,"mc":[{"id":"1.232013126","rc":[{"batb":[[0,1.74,17.32],[1,1.25,864],[2,1.04,1.53]],"ltp":1.97,"tv":921.41,"id":35736915},{"batb":[[0,1.84,51.13],[1,1.74,17.32],[2,1.25,864]],"ltp":2.02,"tv":559.58,"id":11445383}]}]}
{"op":"mcm","clk":"11927787859","pt":1724580189833,"mc":[{"id":"1.232013126","rc":[{"batb":[[0,1.75,5],[1,1.74,17.32],[2,1.25,864]],"ltp":1.97,"tv":921.41,"id":35736915},{"batb":[[0,1.85,5],[1,1.84,51.13],[2,1.74,17.32]],"ltp":2.02,"tv":559.58,"id":11445383}]}]}
{"op":"mcm","clk":"11927788236","pt":1724580192998,"mc":[{"id":"1.232013126","rc":[{"batb":[[0,1.74,17.32],[1,1.25,864],[2,1.04,1.53]],"ltp":1.97,"tv":921.41,"id":35736915},{"batb":[[0,1.84,51.13],[1,1.74,17.32],[2,1.25,864]],"ltp":2.02,"tv":559.58,"id":11445383}]}]}
{"op":"mcm","clk":"11927788832","pt":1724580198007,"mc":[{"id":"1.232013126","rc":[{"batb":[[0,1.75,5],[1,1.74,17.32],[2,1.25,864]],"ltp":1.97,"tv":921.41,"id":35736915},{"batb":[[0,1.85,5],[1,1.84,51.13],[2,1.74,17.32]],"ltp":2.02,"tv":559.58,"id":11445383}]}]}
{"op":"mcm","clk":"11927789326","pt":1724580201417,"mc":[{"id":"1.232013126","rc":[{"batb":[[0,1.74,17.32],[1,1.25,864],[2,1.04,1.53]],"ltp":1.97,"tv":921.41,"id":35736915},{"batb":[[0,1.84,51.13],[1,1.74,17.32],[2,1.25,864]],"ltp":2.02,"tv":559.58,"id":11445383}]}]}
{"op":"mcm","clk":"11927790551","pt":1724580210304,"mc":[{"id":"1.232013126","rc":[{"batb":[[0,1.75,5],[1,1.74,17.32],[2,1.25,864]],"ltp":1.97,"tv":921.41,"id":35736915},{"batb":[[0,1.85,5],[1,1.84,51.13],[2,1.74,17.32]],"ltp":2.02,"tv":559.58,"id":11445383}]}]}
{"op":"mcm","clk":"11927791056","pt":1724580213734,"mc":[{"id":"1.232013126","rc":[{"batb":[[0,1.74,17.32],[1,1.25,864],[2,1.04,1.53]],"ltp":1.97,"tv":921.41,"id":35736915},{"batb":[[0,1.84,51.13],[1,1.74,17.32],[2,1.25,864]],"ltp":2.02,"tv":559.58,"id":11445383}]}]}
{"op":"mcm","clk":"11927791367","pt":1724580216323,"mc":[{"id":"1.232013126","rc":[{"batb":[[0,1.75,5],[1,1.74,17.32],[2,1.25,864]],"ltp":1.97,"tv":921.41,"id":35736915},{"batb":[[0,1.85,5],[1,1.84,51.13],[2,1.74,17.32]],"ltp":2.02,"tv":559.58,"id":11445383}]}]}
{"op":"mcm","clk":"11927791819","pt":1724580219761,"mc":[{"id":"1.232013126","rc":[{"batb":[[0,1.74,17.32],[1,1.25,864],[2,1.04,1.53]],"ltp":1.97,"tv":921.41,"id":35736915},{"batb":[[0,1.84,51.13],[1,1.74,17.32],[2,1.25,864]],"ltp":2.02,"tv":559.58,"id":11445383}]}]}
{"op":"mcm","clk":"11927792840","pt":1724580227035,"mc":[{"id":"1.232013126","rc":[{"batb":[[0,1.75,5],[1,1.74,17.32],[2,1.25,864]],"ltp":1.97,"tv":921.41,"id":35736915},{"batb":[[0,1.85,5],[1,1.84,51.13],[2,1.74,17.32]],"ltp":2.02,"tv":559.58,"id":11445383}]}]}
{"op":"mcm","clk":"11927793331","pt":1724580230560,"mc":[{"id":"1.232013126","rc":[{"batb":[[0,1.74,17.32],[1,1.25,864],[2,1.04,1.53]],"ltp":1.97,"tv":921.41,"id":35736915},{"batb":[[0,1.84,51.13],[1,1.74,17.32],[2,1.25,864]],"ltp":2.02,"tv":559.58,"id":11445383}]}]}
{"op":"mcm","clk":"11927793673","pt":1724580233134,"mc":[{"id":"1.232013126","rc":[{"batb":[[0,1.75,5],[1,1.74,17.32],[2,1.25,864]],"ltp":1.97,"tv":921.41,"id":35736915},{"batb":[[0,1.85,5],[1,1.84,51.13],[2,1.74,17.32]],"ltp":2.02,"tv":559.58,"id":11445383}]}]}
{"op":"mcm","clk":"11927794092","pt":1724580236462,"mc":[{"id":"1.232013126","rc":[{"batb":[[0,1.74,17.32],[1,1.25,864],[2,1.04,1.53]],"ltp":1.97,"tv":921.41,"id":35736915},{"batb":[[0,1.84,51.13],[1,1.74,17.32],[2,1.25,864]],"ltp":2.02,"tv":559.58,"id":11445383}]}]}
{"op":"mcm","clk":"11927794380","pt":1724580238664,"mc":[{"id":"1.232013126","rc":[{"batb":[[0,1.75,5],[1,1.74,17.32],[2,1.25,864]],"ltp":1.97,"tv":921.41,"id":35736915},{"batb":[[0,1.85,5],[1,1.84,51.13],[2,1.74,17.32]],"ltp":2.02,"tv":559.58,"id":11445383}]}]}
{"op":"mcm","clk":"11927794818","pt":1724580241943,"mc":[{"id":"1.232013126","rc":[{"batb":[[0,1.74,17.32],[1,1.25,864],[2,1.04,1.53]],"ltp":1.97,"tv":921.41,"id":35736915},{"batb":[[0,1.84,51.13],[1,1.74,17.32],[2,1.25,864]],"ltp":2.02,"tv":559.58,"id":11445383}]}]}
{"op":"mcm","clk":"11927795836","pt":1724580249375,"mc":[{"id":"1.232013126","rc":[{"batb":[[0,1.75,5],[1,1.74,17.32],[2,1.25,864]],"ltp":1.97,"tv":921.41,"id":35736915},{"batb":[[0,1.85,5],[1,1.84,51.13],[2,1.74,17.32]],"ltp":2.02,"tv":559.58,"id":11445383}]}]}
{"op":"mcm","clk":"11927796277","pt":1724580252560,"mc":[{"id":"1.232013126","rc":[{"batb":[[0,1.74,17.32],[1,1.25,864],[2,1.04,1.53]],"ltp":1.97,"tv":921.41,"id":35736915},{"batb":[[0,1.84,51.13],[1,1.74,17.32],[2,1.25,864]],"ltp":2.02,"tv":559.58,"id":11445383}]}]}
{"op":"mcm","clk":"11927796977","pt":1724580258154,"mc":[{"id":"1.232013126","rc":[{"batb":[[0,1.75,5],[1,1.74,17.32],[2,1.25,864]],"ltp":1.97,"tv":921.41,"id":35736915},{"batb":[[0,1.85,5],[1,1.84,51.13],[2,1.74,17.32]],"ltp":2.02,"tv":559.58,"id":11445383}]}]}
{"op":"mcm","clk":"11927797171","pt":1724580259663,"mc":[{"id":"1.232013126","rc":[{"trd":[[2.02,261.38]],"batl":[[0,2.02,69.31]],"ltp":2.02,"tv":1098.59,"id":35736915}],"tv":1658.18}]}
{"op":"mcm","clk":"11927797398","pt":1724580261548,"mc":[{"id":"1.232013126","rc":[{"batb":[[0,1.74,17.32],[1,1.25,864],[2,1.04,1.53]],"ltp":2.02,"tv":1098.59,"id":35736915},{"batb":[[0,1.84,51.13],[1,1.74,17.32],[2,1.25,864]],"ltp":2.02,"tv":559.58,"id":11445383}]}]}
{"op":"mcm","clk":"11927797731","pt":1724580264304,"mc":[{"id":"1.232013126","rc":[{"batb":[[0,1.75,5],[1,1.74,17.32],[2,1.25,864]],"ltp":2.02,"tv":1098.59,"id":35736915},{"batb":[[0,1.85,5],[1,1.84,51.13],[2,1.74,17.32]],"ltp":2.02,"tv":559.58,"id":11445383}]}]}
{"op":"mcm","clk":"11927798184","pt":1724580267721,"mc":[{"id":"1.232013126","rc":[{"batb":[[0,1.74,17.32],[1,1.25,864],[2,1.04,1.53]],"ltp":2.02,"tv":1098.59,"id":35736915},{"batb":[[0,1.84,51.13],[1,1.74,17.32],[2,1.25,864]],"ltp":2.02,"tv":559.58,"id":11445383}]}]}
{"op":"mcm","clk":"11927799312","pt":1724580276281,"mc":[{"id":"1.232013126","rc":[{"batb":[[0,1.75,5],[1,1.74,17.32],[2,1.25,864]],"ltp":2.02,"tv":1098.59,"id":35736915},{"batb":[[0,1.85,5],[1,1.84,51.13],[2,1.74,17.32]],"ltp":2.02,"tv":559.58,"id":11445383}]}]}
{"op":"mcm","clk":"11927799701","pt":1724580279680,"mc":[{"id":"1.232013126","rc":[{"batb":[[0,1.74,17.32],[1,1.25,864],[2,1.04,1.53]],"ltp":2.02,"tv":1098.59,"id":35736915},{"batb":[[0,1.84,51.13],[1,1.74,17.32],[2,1.25,864]],"ltp":2.02,"tv":559.58,"id":11445383}]}]}
{"op":"mcm","clk":"11927800083","pt":1724580282912,"mc":[{"id":"1.232013126","rc":[{"trd":[[2.02,349.98]],"batb":[[0,1.75,5],[1,1.74,17.32],[2,1.25,864]],"batl":[[0,2.02,25.01]],"ltp":2.02,"tv":1187.19,"id":35736915},{"batb":[[0,1.85,5],[1,1.84,51.13],[2,1.74,17.32]],"ltp":2.02,"tv":559.58,"id":11445383}],"tv":1746.77}]}
{"op":"mcm","clk":"11927800472","pt":1724580286195,"mc":[{"id":"1.232013126","rc":[{"batb":[[0,1.74,17.32],[1,1.25,864],[2,1.04,1.53]],"ltp":2.02,"tv":1187.19,"id":35736915},{"batb":[[0,1.84,51.13],[1,1.74,17.32],[2,1.25,864]],"ltp":2.02,"tv":559.58,"id":11445383}]}]}
{"op":"mcm","clk":"11927801019","pt":1724580290888,"mc":[{"id":"1.232013126","rc":[{"batb":[[0,1.75,72.91],[1,1.74,17.32],[2,1.25,864]],"ltp":2.02,"tv":1187.19,"id":35736915}]}]}
{"op":"mcm","clk":"11927801420","pt":1724580294296,"mc":[{"id":"1.232013126","rc":[{"batb":[[0,1.75,67.91]],"ltp":2.02,"tv":1187.19,"id":35736915}]}]}
{"op":"mcm","clk":"11927801750","pt":1724580297130,"mc":[{"id":"1.232013126","rc":[{"batb":[[0,1.76,5],[1,1.75,67.91],[2,1.74,17.32]],"ltp":2.02,"tv":1187.19,"id":35736915}]}]}
{"op":"mcm","clk":"11927802140","pt":1724580300432,"mc":[{"id":"1.232013126","rc":[{"batb":[[0,1.75,67.91],[1,1.74,17.32],[2,1.25,864]],"ltp":2.02,"tv":1187.19,"id":35736915}]}]}
{"op":"mcm","clk":"11927802677","pt":1724580304234,"mc":[{"id":"1.232013126","rc":[{"batb":[[0,1.76,5],[1,1.75,67.91],[2,1.74,17.32]],"ltp":2.02,"tv":1187.19,"id":35736915}]}]}
{"op":"mcm","clk":"11927803096","pt":1724580307598,"mc":[{"id":"1.232013126","rc":[{"batb":[[0,1.75,67.91],[1,1.74,17.32],[2,1.25,864]],"ltp":2.02,"tv":1187.19,"id":35736915}]}]}
{"op":"mcm","clk":"11927805202","pt":1724580324634,"mc":[{"id":"1.232013126","rc":[{"batb":[[0,1.76,5],[1,1.75,67.91],[2,1.74,17.32]],"ltp":2.02,"tv":1187.19,"id":35736915}]}]}
{"op":"mcm","clk":"11927805608","pt":1724580328048,"mc":[{"id":"1.232013126","rc":[{"batb":[[0,1.75,67.91],[1,1.74,17.32],[2,1.25,864]],"ltp":2.02,"tv":1187.19,"id":35736915}]}]}
{"op":"mcm","clk":"11927807695","pt":1724580346690,"mc":[{"id":"1.232013126","rc":[{"batb":[[0,1.76,5],[1,1.75,67.91],[2,1.74,17.32]],"ltp":2.02,"tv":1187.19,"id":35736915}]}]}
{"op":"mcm","clk":"11927808112","pt":1724580350044,"mc":[{"id":"1.232013126","rc":[{"batb":[[0,1.75,67.91],[1,1.74,17.32],[2,1.25,864]],"ltp":2.02,"tv":1187.19,"id":35736915}]}]}
{"op":"mcm","clk":"11927809559","pt":1724580361605,"mc":[{"id":"1.232013126","rc":[{"batb":[[0,1.76,5],[1,1.75,67.91],[2,1.74,17.32]],"ltp":2.02,"tv":1187.19,"id":35736915}]}]}
{"op":"mcm","clk":"11927809973","pt":1724580364787,"mc":[{"id":"1.232013126","rc":[{"batb":[[0,1.75,67.91],[1,1.74,17.32],[2,1.25,864]],"ltp":2.02,"tv":1187.19,"id":35736915}]}]}
{"op":"mcm","clk":"11927810810","pt":1724580371700,"mc":[{"id":"1.232013126","rc":[{"batb":[[0,1.76,5],[1,1.75,67.91],[2,1.74,17.32]],"ltp":2.02,"tv":1187.19,"id":35736915}]}]}
{"op":"mcm","clk":"11927811261","pt":1724580375003,"mc":[{"id":"1.232013126","rc":[{"batb":[[0,1.75,67.91],[1,1.74,17.32],[2,1.25,864]],"ltp":2.02,"tv":1187.19,"id":35736915}]}]}
{"op":"mcm","clk":"11927812056","pt":1724580381110,"mc":[{"id":"1.232013126","rc":[{"batb":[[0,1.76,5],[1,1.75,67.91],[2,1.74,17.32]],"ltp":2.02,"tv":1187.19,"id":35736915}]}]}
{"op":"mcm","clk":"11927812470","pt":1724580384393,"mc":[{"id":"1.232013126","rc":[{"batb":[[0,1.75,67.91],[1,1.74,17.32],[2,1.25,864]],"ltp":2.02,"tv":1187.19,"id":35736915}]}]}
{"op":"mcm","clk":"11927814157","pt":1724580397819,"mc":[{"id":"1.232013126","rc":[{"batb":[[0,1.76,5],[1,1.75,67.91],[2,1.74,17.32]],"ltp":2.02,"tv":1187.19,"id":35736915}]}]}
{"op":"mcm","clk":"11927814624","pt":1724580401253,"mc":[{"id":"1.232013126","rc":[{"batb":[[0,1.75,67.91],[1,1.74,17.32],[2,1.25,864]],"ltp":2.02,"tv":1187.19,"id":35736915}]}]}
{"op":"mcm","clk":"11927815493","pt":1724580408219,"mc":[{"id":"1.232013126","rc":[{"batb":[[0,1.76,5],[1,1.75,67.91],[2,1.74,17.32]],"ltp":2.02,"tv":1187.19,"id":35736915}]}]}
{"op":"mcm","clk":"11927815941","pt":1724580411656,"mc":[{"id":"1.232013126","rc":[{"batb":[[0,1.75,67.91],[1,1.74,17.32],[2,1.25,864]],"ltp":2.02,"tv":1187.19,"id":35736915}]}]}
{"op":"mcm","clk":"11927817713","pt":1724580424662,"mc":[{"id":"1.232013126","rc":[{"batb":[[0,1.76,5],[1,1.75,67.91],[2,1.74,17.32]],"ltp":2.02,"tv":1187.19,"id":35736915}]}]}
{"op":"mcm","clk":"11927818167","pt":1724580427967,"mc":[{"id":"1.232013126","rc":[{"batb":[[0,1.75,67.91],[1,1.74,17.32],[2,1.25,864]],"ltp":2.02,"tv":1187.19,"id":35736915}]}]}
{"op":"mcm","clk":"11927819049","pt":1724580434162,"mc":[{"id":"1.232013126","rc":[{"batb":[[0,1.76,5],[1,1.75,67.91],[2,1.74,17.32]],"ltp":2.02,"tv":1187.19,"id":35736915}]}]}
{"op":"mcm","clk":"11927819485","pt":1724580437581,"mc":[{"id":"1.232013126","rc":[{"batb":[[0,1.75,67.91],[1,1.74,17.32],[2,1.25,864]],"ltp":2.02,"tv":1187.19,"id":35736915}]}]}
{"op":"mcm","clk":"11927820009","pt":1724580441051,"mc":[{"id":"1.232013126","rc":[{"batb":[[0,1.76,5],[1,1.75,67.91],[2,1.74,17.32]],"ltp":2.02,"tv":1187.19,"id":35736915}]}]}
{"op":"mcm","clk":"11927820467","pt":1724580444368,"mc":[{"id":"1.232013126","rc":[{"batb":[[0,1.75,67.91],[1,1.74,17.32],[2,1.25,864]],"ltp":2.02,"tv":1187.19,"id":35736915}]}]}
{"op":"mcm","clk":"11927821127","pt":1724580449570,"mc":[{"id":"1.232013126","rc":[{"batb":[[0,1.76,5],[1,1.75,67.91],[2,1.74,17.32]],"ltp":2.02,"tv":1187.19,"id":35736915}]}]}
{"op":"mcm","clk":"11927821535","pt":1724580452887,"mc":[{"id":"1.232013126","rc":[{"batb":[[0,1.75,67.91],[1,1.74,17.32],[2,1.25,864]],"ltp":2.02,"tv":1187.19,"id":35736915}]}]}
{"op":"mcm","clk":"11927821984","pt":1724580456160,"mc":[{"id":"1.232013126","rc":[{"batb":[[0,1.76,5],[1,1.75,67.91],[2,1.74,17.32]],"ltp":2.02,"tv":1187.19,"id":35736915}]}]}
{"op":"mcm","clk":"11927822431","pt":1724580459389,"mc":[{"id":"1.232013126","rc":[{"batb":[[0,1.75,67.91],[1,1.74,17.32],[2,1.25,864]],"ltp":2.02,"tv":1187.19,"id":35736915}]}]}
{"op":"mcm","clk":"11927822921","pt":1724580463104,"mc":[{"id":"1.232013126","rc":[{"batb":[[0,1.76,5],[1,1.75,67.91],[2,1.74,17.32]],"ltp":2.02,"tv":1187.19,"id":35736915}]}]}
{"op":"mcm","clk":"11927823349","pt":1724580466575,"mc":[{"id":"1.232013126","rc":[{"batb":[[0,1.75,67.91],[1,1.74,17.32],[2,1.25,864]],"ltp":2.02,"tv":1187.19,"id":35736915}]}]}
{"op":"mcm","clk":"11927824005","pt":1724580471610,"mc":[{"id":"1.232013126","rc":[{"batb":[[0,1.76,5],[1,1.75,67.91],[2,1.74,17.32]],"ltp":2.02,"tv":1187.19,"id":35736915}]}]}
{"op":"mcm","clk":"11927824542","pt":1724580475416,"mc":[{"id":"1.232013126","rc":[{"batb":[[0,1.75,67.91],[1,1.74,17.32],[2,1.25,864]],"ltp":2.02,"tv":1187.19,"id":35736915}]}]}
{"op":"mcm","clk":"11927824862","pt":1724580477820,"mc":[{"id":"1.232013126","rc":[{"batb":[[0,1.76,5],[1,1.75,67.91],[2,1.74,17.32]],"ltp":2.02,"tv":1187.19,"id":35736915}]}]}
{"op":"mcm","clk":"11927825307","pt":1724580481096,"mc":[{"id":"1.232013126","rc":[{"batb":[[0,1.75,67.91],[1,1.74,17.32],[2,1.25,864]],"ltp":2.02,"tv":1187.19,"id":35736915}]}]}
{"op":"mcm","clk":"11927829155","pt":1724580507353,"mc":[{"id":"1.232013126","rc":[{"batb":[[0,1.76,5],[1,1.75,67.91],[2,1.74,17.32]],"ltp":2.02,"tv":1187.19,"id":35736915}]}]}
{"op":"mcm","clk":"11927829627","pt":1724580510736,"mc":[{"id":"1.232013126","rc":[{"batb":[[0,1.75,67.91],[1,1.74,17.32],[2,1.25,864]],"ltp":2.02,"tv":1187.19,"id":35736915}]}]}
{"op":"mcm","clk":"11927830797","pt":1724580519232,"mc":[{"id":"1.232013126","rc":[{"batb":[[0,1.76,5],[1,1.75,67.91],[2,1.74,17.32]],"ltp":2.02,"tv":1187.19,"id":35736915}]}]}
{"op":"mcm","clk":"11927831251","pt":1724580522655,"mc":[{"id":"1.232013126","rc":[{"batb":[[0,1.75,67.91],[1,1.74,17.32],[2,1.25,864]],"ltp":2.02,"tv":1187.19,"id":35736915}]}]}
{"op":"mcm","clk":"11927834395","pt":1724580544378,"mc":[{"id":"1.232013126","rc":[{"batb":[[0,1.76,5],[1,1.75,67.91],[2,1.74,17.32]],"ltp":2.02,"tv":1187.19,"id":35736915}]}]}
{"op":"mcm","clk":"11927834830","pt":1724580547695,"mc":[{"id":"1.232013126","rc":[{"batb":[[0,1.75,67.91],[1,1.74,17.32],[2,1.25,864]],"ltp":2.02,"tv":1187.19,"id":35736915}]}]}
{"op":"mcm","clk":"11927836062","pt":1724580556601,"mc":[{"id":"1.232013126","rc":[{"batb":[[0,1.76,5],[1,1.75,67.91],[2,1.74,17.32]],"ltp":2.02,"tv":1187.19,"id":35736915}]}]}
{"op":"mcm","clk":"11927836537","pt":1724580559866,"mc":[{"id":"1.232013126","rc":[{"batb":[[0,1.75,67.91],[1,1.74,17.32],[2,1.25,864]],"ltp":2.02,"tv":1187.19,"id":35736915}]}]}
{"op":"mcm","clk":"11927838582","pt":1724580574601,"mc":[{"id":"1.232013126","rc":[{"batb":[[0,1.76,5],[1,1.75,67.91],[2,1.74,17.32]],"ltp":2.02,"tv":1187.19,"id":35736915}]}]}
{"op":"mcm","clk":"11927839031","pt":1724580577787,"mc":[{"id":"1.232013126","rc":[{"batb":[[0,1.75,67.91],[1,1.74,17.32],[2,1.25,864]],"ltp":2.02,"tv":1187.19,"id":35736915}]}]}
{"op":"mcm","clk":"11927839595","pt":1724580581608,"mc":[{"id":"1.232013126","rc":[{"batb":[[0,1.76,5],[1,1.75,67.91],[2,1.74,17.32]],"ltp":2.02,"tv":1187.19,"id":35736915}]}]}
{"op":"mcm","clk":"11927840046","pt":1724580585004,"mc":[{"id":"1.232013126","rc":[{"batb":[[0,1.75,67.91],[1,1.74,17.32],[2,1.25,864]],"ltp":2.02,"tv":1187.19,"id":35736915}]}]}
{"op":"mcm","clk":"11927844094","pt":1724580612616,"mc":[{"id":"1.232013126","rc":[{"batb":[[0,1.76,5],[1,1.75,67.91],[2,1.74,17.32]],"ltp":2.02,"tv":1187.19,"id":35736915}]}]}
{"op":"mcm","clk":"11927844526","pt":1724580616052,"mc":[{"id":"1.232013126","rc":[{"batb":[[0,1.75,67.91],[1,1.74,17.32],[2,1.25,864]],"ltp":2.02,"tv":1187.19,"id":35736915}]}]}
{"op":"mcm","clk":"11927846898","pt":1724580634357,"mc":[{"id":"1.232013126","rc":[{"batb":[[0,1.76,5],[1,1.75,67.91],[2,1.74,17.32]],"ltp":2.02,"tv":1187.19,"id":35736915}]}]}
{"op":"mcm","clk":"11927847300","pt":1724580637597,"mc":[{"id":"1.232013126","rc":[{"batb":[[0,1.75,67.91],[1,1.74,17.32],[2,1.25,864]],"ltp":2.02,"tv":1187.19,"id":35736915}]}]}
{"op":"mcm","clk":"11927849278","pt":1724580652485,"mc":[{"id":"1.232013126","rc":[{"batb":[[0,1.76,5],[1,1.75,67.91],[2,1.74,17.32]],"ltp":2.02,"tv":1187.19,"id":35736915}]}]}
{"op":"mcm","clk":"11927849684","pt":1724580655788,"mc":[{"id":"1.232013126","rc":[{"batb":[[0,1.75,67.91],[1,1.74,17.32],[2,1.25,864]],"ltp":2.02,"tv":1187.19,"id":35736915}]}]}
{"op":"mcm","clk":"11927852311","pt":1724580675601,"mc":[{"id":"1.232013126","rc":[{"batb":[[0,1.76,5],[1,1.75,67.91],[2,1.74,17.32]],"ltp":2.02,"tv":1187.19,"id":35736915}]}]}
{"op":"mcm","clk":"11927852856","pt":1724580679028,"mc":[{"id":"1.232013126","rc":[{"batb":[[0,1.75,67.91],[1,1.74,17.32],[2,1.25,864]],"ltp":2.02,"tv":1187.19,"id":35736915}]}]}
{"op":"mcm","clk":"11927853968","pt":1724580687032,"mc":[{"id":"1.232013126","rc":[{"batb":[[0,1.76,5],[1,1.75,67.91],[2,1.74,17.32]],"ltp":2.02,"tv":1187.19,"id":35736915}]}]}
{"op":"mcm","clk":"11927854379","pt":1724580690235,"mc":[{"id":"1.232013126","rc":[{"batb":[[0,1.75,67.91],[1,1.74,17.32],[2,1.25,864]],"ltp":2.02,"tv":1187.19,"id":35736915}]}]}
{"op":"mcm","clk":"11927855812","pt":1724580700232,"mc":[{"id":"1.232013126","rc":[{"batb":[[0,1.76,5],[1,1.75,67.91],[2,1.74,17.32]],"ltp":2.02,"tv":1187.19,"id":35736915}]}]}
{"op":"mcm","clk":"11927856145","pt":1724580703063,"mc":[{"id":"1.232013126","rc":[{"trd":[[2.02,364.62]],"batl":[[0,2.02,17.69]],"ltp":2.02,"tv":1201.83,"id":35736915}],"tv":1761.41}]}
{"op":"mcm","clk":"11927856204","pt":1724580703574,"mc":[{"id":"1.232013126","rc":[{"batb":[[0,1.75,67.91],[1,1.74,17.32],[2,1.25,864]],"ltp":2.02,"tv":1201.83,"id":35736915}]}]}
{"op":"mcm","clk":"11927856867","pt":1724580708790,"mc":[{"id":"1.232013126","rc":[{"batb":[[0,1.76,5],[1,1.75,67.91],[2,1.74,17.32]],"ltp":2.02,"tv":1201.83,"id":35736915}]}]}
{"op":"mcm","clk":"11927857296","pt":1724580712084,"mc":[{"id":"1.232013126","rc":[{"batb":[[0,1.75,67.91],[1,1.74,17.32],[2,1.25,864]],"ltp":2.02,"tv":1201.83,"id":35736915}]}]}
{"op":"mcm","clk":"11927857639","pt":1724580714586,"mc":[{"id":"1.232013126","rc":[{"batb":[[0,1.76,5],[1,1.75,67.91],[2,1.74,17.32]],"ltp":2.02,"tv":1201.83,"id":35736915}]}]}
{"op":"mcm","clk":"11927858080","pt":1724580717869,"mc":[{"id":"1.232013126","rc":[{"batb":[[0,1.75,67.91],[1,1.74,17.32],[2,1.25,864]],"ltp":2.02,"tv":1201.83,"id":35736915}]}]}
{"op":"mcm","clk":"11927859445","pt":1724580727088,"mc":[{"id":"1.232013126","rc":[{"batb":[[0,1.76,5],[1,1.75,67.91],[2,1.74,17.32]],"ltp":2.02,"tv":1201.83,"id":35736915}]}]}
{"op":"mcm","clk":"11927859897","pt":1724580730385,"mc":[{"id":"1.232013126","rc":[{"batb":[[0,1.75,67.91],[1,1.74,17.32],[2,1.25,864]],"ltp":2.02,"tv":1201.83,"id":35736915}]}]}
{"op":"mcm","clk":"11927861061","pt":1724580739133,"mc":[{"id":"1.232013126","rc":[{"batb":[[0,1.76,5],[1,1.75,67.91],[2,1.74,17.32]],"ltp":2.02,"tv":1201.83,"id":35736915}]}]}
{"op":"mcm","clk":"11927861518","pt":1724580742430,"mc":[{"id":"1.232013126","rc":[{"batb":[[0,1.75,67.91],[1,1.74,17.32],[2,1.25,864]],"ltp":2.02,"tv":1201.83,"id":35736915}]}]}
{"op":"mcm","clk":"11927862418","pt":1724580748729,"mc":[{"id":"1.232013126","rc":[{"batb":[[0,1.76,5],[1,1.75,67.91],[2,1.74,17.32]],"ltp":2.02,"tv":1201.83,"id":35736915}]}]}
{"op":"mcm","clk":"11927862947","pt":1724580752146,"mc":[{"id":"1.232013126","rc":[{"batb":[[0,1.75,67.91],[1,1.74,17.32],[2,1.25,864]],"ltp":2.02,"tv":1201.83,"id":35736915}]}]}
{"op":"mcm","clk":"11927864888","pt":1724580766226,"mc":[{"id":"1.232013126","rc":[{"batb":[[0,1.76,5],[1,1.75,67.91],[2,1.74,17.32]],"ltp":2.02,"tv":1201.83,"id":35736915}]}]}
{"op":"mcm","clk":"11927865365","pt":1724580769639,"mc":[{"id":"1.232013126","rc":[{"batb":[[0,1.75,67.91],[1,1.74,17.32],[2,1.25,864]],"ltp":2.02,"tv":1201.83,"id":35736915}]}]}
{"op":"mcm","clk":"11927867430","pt":1724580783945,"mc":[{"id":"1.232013126","rc":[{"batb":[[0,1.76,5],[1,1.75,67.91],[2,1.74,17.32]],"ltp":2.02,"tv":1201.83,"id":35736915}]}]}
{"op":"mcm","clk":"11927867888","pt":1724580787260,"mc":[{"id":"1.232013126","rc":[{"batb":[[0,1.75,67.91],[1,1.74,17.32],[2,1.25,864]],"ltp":2.02,"tv":1201.83,"id":35736915}]}]}
{"op":"mcm","clk":"11927871450","pt":1724580810681,"mc":[{"id":"1.232013126","rc":[{"batb":[[0,1.76,5],[1,1.75,67.91],[2,1.74,17.32]],"ltp":2.02,"tv":1201.83,"id":35736915}]}]}
{"op":"mcm","clk":"11927871950","pt":1724580814198,"mc":[{"id":"1.232013126","rc":[{"batb":[[0,1.75,67.91],[1,1.74,17.32],[2,1.25,864]],"ltp":2.02,"tv":1201.83,"id":35736915}]}]}
{"op":"mcm","clk":"11927873522","pt":1724580824986,"mc":[{"id":"1.232013126","rc":[{"batb":[[0,1.76,5],[1,1.75,67.91],[2,1.74,17.32]],"ltp":2.02,"tv":1201.83,"id":35736915}]}]}
{"op":"mcm","clk":"11927873999","pt":1724580828420,"mc":[{"id":"1.232013126","rc":[{"batb":[[0,1.75,67.91],[1,1.74,17.32],[2,1.25,864]],"ltp":2.02,"tv":1201.83,"id":35736915}]}]}
{"op":"mcm","clk":"11927874457","pt":1724580831680,"mc":[{"id":"1.232013126","rc":[{"batb":[[0,1.76,5],[1,1.75,67.91],[2,1.74,17.32]],"ltp":2.02,"tv":1201.83,"id":35736915}]}]}
{"op":"mcm","clk":"11927874929","pt":1724580835201,"mc":[{"id":"1.232013126","rc":[{"batb":[[0,1.75,67.91],[1,1.74,17.32],[2,1.25,864]],"ltp":2.02,"tv":1201.83,"id":35736915}]}]}
{"op":"mcm","clk":"11927878179","pt":1724580858537,"mc":[{"id":"1.232013126","rc":[{"batb":[[0,1.76,5],[1,1.75,67.91],[2,1.74,17.32]],"ltp":2.02,"tv":1201.83,"id":35736915}]}]}
{"op":"mcm","clk":"11927878626","pt":1724580861722,"mc":[{"id":"1.232013126","rc":[{"batb":[[0,1.75,67.91],[1,1.74,17.32],[2,1.25,864]],"ltp":2.02,"tv":1201.83,"id":35736915}]}]}
{"op":"mcm","clk":"11927886092","pt":1724580915306,"mc":[{"id":"1.232013126","rc":[{"batb":[[0,1.76,5],[1,1.75,67.91],[2,1.74,17.32]],"ltp":2.02,"tv":1201.83,"id":35736915}]}]}
{"op":"mcm","clk":"11927886554","pt":1724580918675,"mc":[{"id":"1.232013126","rc":[{"batb":[[0,1.75,67.91],[1,1.74,17.32],[2,1.25,864]],"ltp":2.02,"tv":1201.83,"id":35736915}]}]}
{"op":"mcm","clk":"11927888734","pt":1724580935092,"mc":[{"id":"1.232013126","rc":[{"batb":[[0,1.76,5],[1,1.75,67.91],[2,1.74,17.32]],"ltp":2.02,"tv":1201.83,"id":35736915}]}]}
{"op":"mcm","clk":"11927889132","pt":1724580938446,"mc":[{"id":"1.232013126","rc":[{"batb":[[0,1.75,67.91],[1,1.74,17.32],[2,1.25,864]],"ltp":2.02,"tv":1201.83,"id":35736915}]}]}
{"op":"mcm","clk":"11927896047","pt":1724580985865,"mc":[{"id":"1.232013126","rc":[{"batb":[[0,1.76,5],[1,1.75,67.91],[2,1.74,17.32]],"ltp":2.02,"tv":1201.83,"id":35736915}]}]}
{"op":"mcm","clk":"11927896493","pt":1724580989235,"mc":[{"id":"1.232013126","rc":[{"batb":[[0,1.75,67.91],[1,1.74,17.32],[2,1.25,864]],"ltp":2.02,"tv":1201.83,"id":35736915}]}]}
{"op":"mcm","clk":"11927897027","pt":1724580993235,"mc":[{"id":"1.232013126","rc":[{"batb":[[0,1.77,5],[1,1.76,5.1],[2,1.75,67.91]],"ltp":2.02,"tv":1201.83,"id":35736915}]}]}
{"op":"mcm","clk":"11927897498","pt":1724580996586,"mc":[{"id":"1.232013126","rc":[{"batb":[[0,1.76,5.1],[1,1.75,67.91],[2,1.74,17.32]],"ltp":2.02,"tv":1201.83,"id":35736915}]}]}
{"op":"mcm","clk":"11927898344","pt":1724581002571,"mc":[{"id":"1.232013126","rc":[{"batb":[[0,1.77,5],[1,1.76,5.1],[2,1.75,67.91]],"ltp":2.02,"tv":1201.83,"id":35736915}]}]}
{"op":"mcm","clk":"11927898885","pt":1724581006474,"mc":[{"id":"1.232013126","rc":[{"batb":[[0,1.77,43.68],[1,1.74,17.32],[2,1.25,864]],"ltp":2.02,"tv":1201.83,"id":35736915}]}]}
{"op":"mcm","clk":"11927899355","pt":1724581009604,"mc":[{"id":"1.232013126","rc":[{"batb":[[0,1.78,5],[1,1.77,43.68],[2,1.74,17.32]],"ltp":2.02,"tv":1201.83,"id":35736915}]}]}
{"op":"mcm","clk":"11927899816","pt":1724581012870,"mc":[{"id":"1.232013126","rc":[{"batb":[[0,1.77,43.68],[1,1.74,17.32],[2,1.25,864]],"ltp":2.02,"tv":1201.83,"id":35736915}]}]}
{"op":"mcm","clk":"11927901584","pt":1724581024909,"mc":[{"id":"1.232013126","rc":[{"batb":[[0,1.78,5],[1,1.77,43.68],[2,1.74,17.32]],"ltp":2.02,"tv":1201.83,"id":35736915}]}]}
{"op":"mcm","clk":"11927902090","pt":1724581028189,"mc":[{"id":"1.232013126","rc":[{"batb":[[0,1.77,43.68],[1,1.74,17.32],[2,1.25,864]],"ltp":2.02,"tv":1201.83,"id":35736915}]}]}
{"op":"mcm","clk":"11927906692","pt":1724581062514,"mc":[{"id":"1.232013126","rc":[{"batb":[[0,1.78,5],[1,1.77,43.68],[2,1.74,17.32]],"ltp":2.02,"tv":1201.83,"id":35736915}]}]}
{"op":"mcm","clk":"11927907134","pt":1724581065815,"mc":[{"id":"1.232013126","rc":[{"batb":[[0,1.77,43.68],[1,1.74,17.32],[2,1.25,864]],"ltp":2.02,"tv":1201.83,"id":35736915}]}]}
{"op":"mcm","clk":"11927908611","pt":1724581076837,"mc":[{"id":"1.232013126","rc":[{"batb":[[0,1.78,5],[1,1.77,43.68],[2,1.74,17.32]],"ltp":2.02,"tv":1201.83,"id":35736915}]}]}
{"op":"mcm","clk":"11927909118","pt":1724581080052,"mc":[{"id":"1.232013126","rc":[{"batb":[[0,1.77,43.68],[1,1.74,17.32],[2,1.25,864]],"ltp":2.02,"tv":1201.83,"id":35736915}]}]}
{"op":"mcm","clk":"11927910992","pt":1724581092362,"mc":[{"id":"1.232013126","rc":[{"batb":[[0,1.78,5],[1,1.77,43.68],[2,1.74,17.32]],"ltp":2.02,"tv":1201.83,"id":35736915}]}]}
{"op":"mcm","clk":"11927911427","pt":1724581095259,"mc":[{"id":"1.232013126","rc":[{"batb":[[0,1.78,5.92]],"ltp":2.02,"tv":1201.83,"id":35736915}]}]}
{"op":"mcm","clk":"11927911496","pt":1724581095645,"mc":[{"id":"1.232013126","rc":[{"batb":[[0,1.77,44.6],[1,1.74,17.32],[2,1.25,864]],"ltp":2.02,"tv":1201.83,"id":35736915}]}]}
{"op":"mcm","clk":"11927911908","pt":1724581098535,"mc":[{"id":"1.232013126","rc":[{"batb":[[0,1.78,5.92],[1,1.77,43.68],[2,1.74,17.32]],"ltp":2.02,"tv":1201.83,"id":35736915}]}]}
{"op":"mcm","clk":"11927912381","pt":1724581101960,"mc":[{"id":"1.232013126","rc":[{"batb":[[0,1.77,44.6],[1,1.74,17.32],[2,1.25,864]],"ltp":2.02,"tv":1201.83,"id":35736915}]}]}
{"op":"mcm","clk":"11927914724","pt":1724581119492,"mc":[{"id":"1.232013126","rc":[{"batb":[[0,1.78,5.92],[1,1.77,43.68],[2,1.74,17.32]],"ltp":2.02,"tv":1201.83,"id":35736915}]}]}
{"op":"mcm","clk":"11927915128","pt":1724581122888,"mc":[{"id":"1.232013126","rc":[{"batb":[[0,1.77,44.6],[1,1.74,17.32],[2,1.25,864]],"ltp":2.02,"tv":1201.83,"id":35736915}]}]}
{"op":"mcm","clk":"11927916684","pt":1724581134729,"mc":[{"id":"1.232013126","rc":[{"batb":[[0,1.78,5.92],[1,1.77,43.68],[2,1.74,17.32]],"ltp":2.02,"tv":1201.83,"id":35736915}]}]}
{"op":"mcm","clk":"11927917094","pt":1724581137984,"mc":[{"id":"1.232013126","rc":[{"batb":[[0,1.77,44.6],[1,1.74,17.32],[2,1.25,864]],"ltp":2.02,"tv":1201.83,"id":35736915}]}]}
{"op":"mcm","clk":"11927923693","pt":1724581187823,"mc":[{"id":"1.232013126","rc":[{"batb":[[0,1.78,5.92],[1,1.77,43.68],[2,1.74,17.32]],"ltp":2.02,"tv":1201.83,"id":35736915}]}]}
{"op":"mcm","clk":"11927924171","pt":1724581191203,"mc":[{"id":"1.232013126","rc":[{"batb":[[0,1.77,44.6],[1,1.74,17.32],[2,1.25,864]],"ltp":2.02,"tv":1201.83,"id":35736915}]}]}
{"op":"mcm","clk":"11927926065","pt":1724581203434,"mc":[{"id":"1.232013126","rc":[{"batb":[[0,1.78,5.92],[1,1.77,43.68],[2,1.74,17.32]],"ltp":2.02,"tv":1201.83,"id":35736915}]}]}
{"op":"mcm","clk":"11927926529","pt":1724581206668,"mc":[{"id":"1.232013126","rc":[{"batb":[[0,1.77,44.6],[1,1.74,17.32],[2,1.25,864]],"ltp":2.02,"tv":1201.83,"id":35736915}]}]}
{"op":"mcm","clk":"11927935657","pt":1724581271017,"mc":[{"id":"1.232013126","rc":[{"batb":[[0,1.78,5.92],[1,1.77,43.68],[2,1.74,17.32]],"ltp":2.02,"tv":1201.83,"id":35736915}]}]}
{"op":"mcm","clk":"11927936105","pt":1724581274222,"mc":[{"id":"1.232013126","rc":[{"batb":[[0,1.77,44.6],[1,1.74,17.32],[2,1.25,864]],"ltp":2.02,"tv":1201.83,"id":35736915}]}]}
{"op":"mcm","clk":"11927937049","pt":1724581280795,"mc":[{"id":"1.232013126","rc":[{"batb":[[0,1.78,5.92],[1,1.77,43.68],[2,1.74,17.32]],"ltp":2.02,"tv":1201.83,"id":35736915}]}]}
{"op":"mcm","clk":"11927937516","pt":1724581284316,"mc":[{"id":"1.232013126","rc":[{"batb":[[0,1.77,44.6],[1,1.74,17.32],[2,1.25,864]],"ltp":2.02,"tv":1201.83,"id":35736915}]}]}
{"op":"mcm","clk":"11927938586","pt":1724581292442,"mc":[{"id":"1.232013126","rc":[{"batb":[[0,1.78,5.92],[1,1.77,43.68],[2,1.74,17.32]],"ltp":2.02,"tv":1201.83,"id":35736915}]}]}
{"op":"mcm","clk":"11927939050","pt":1724581295746,"mc":[{"id":"1.232013126","rc":[{"batb":[[0,1.77,44.6],[1,1.74,17.32],[2,1.25,864]],"ltp":2.02,"tv":1201.83,"id":35736915}]}]}
{"op":"mcm","clk":"11927940519","pt":1724581306147,"mc":[{"id":"1.232013126","rc":[{"batb":[[0,1.78,5.92],[1,1.77,43.68],[2,1.74,17.32]],"ltp":2.02,"tv":1201.83,"id":35736915}]}]}
{"op":"mcm","clk":"11927940945","pt":1724581309448,"mc":[{"id":"1.232013126","rc":[{"batb":[[0,1.77,44.6],[1,1.74,17.32],[2,1.25,864]],"ltp":2.02,"tv":1201.83,"id":35736915}]}]}
{"op":"mcm","clk":"11927941306","pt":1724581312162,"mc":[{"id":"1.232013126","rc":[{"batb":[[0,1.78,5.92],[1,1.77,43.68],[2,1.74,17.32]],"ltp":2.02,"tv":1201.83,"id":35736915}]}]}
{"op":"mcm","clk":"11927941743","pt":1724581315465,"mc":[{"id":"1.232013126","rc":[{"batb":[[0,1.77,44.6],[1,1.74,17.32],[2,1.25,864]],"ltp":2.02,"tv":1201.83,"id":35736915}]}]}
{"op":"mcm","clk":"11927942517","pt":1724581321552,"mc":[{"id":"1.232013126","rc":[{"batb":[[0,1.78,5.92],[1,1.77,43.68],[2,1.74,17.32]],"ltp":2.02,"tv":1201.83,"id":35736915}]}]}
{"op":"mcm","clk":"11927942988","pt":1724581324858,"mc":[{"id":"1.232013126","rc":[{"batb":[[0,1.77,44.6],[1,1.74,17.32],[2,1.25,864]],"ltp":2.02,"tv":1201.83,"id":35736915}]}]}
{"op":"mcm","clk":"11927945325","pt":1724581341494,"mc":[{"id":"1.232013126","rc":[{"batb":[[0,1.78,5.92],[1,1.77,43.68],[2,1.74,17.32]],"ltp":2.02,"tv":1201.83,"id":35736915}]}]}
{"op":"mcm","clk":"11927945812","pt":1724581344780,"mc":[{"id":"1.232013126","rc":[{"batb":[[0,1.77,44.6],[1,1.74,17.32],[2,1.25,864]],"ltp":2.02,"tv":1201.83,"id":35736915}]}]}
{"op":"mcm","clk":"11927947138","pt":1724581354410,"mc":[{"id":"1.232013126","rc":[{"batb":[[0,1.78,5.92],[1,1.77,43.68],[2,1.74,17.32]],"ltp":2.02,"tv":1201.83,"id":35736915}]}]}
{"op":"mcm","clk":"11927947648","pt":1724581357703,"mc":[{"id":"1.232013126","rc":[{"batb":[[0,1.77,44.6],[1,1.74,17.32],[2,1.25,864]],"ltp":2.02,"tv":1201.83,"id":35736915}]}]}
{"op":"mcm","clk":"11927947839","pt":1724581358972,"mc":[{"id":"1.232013126","rc":[{"trd":[[2.02,396.12]],"batl":[[0,2.02,1.94]],"ltp":2.02,"tv":1233.33,"id":35736915}],"tv":1792.91}]}
{"op":"mcm","clk":"11927958070","pt":1724581430276,"mc":[{"id":"1.232013126","rc":[{"batl":[[0,2,79.77]],"ltp":2.02,"tv":559.58,"id":11445383}]}]}
{"op":"mcm","clk":"11927958269","pt":1724581431904,"mc":[{"id":"1.232013126","rc":[{"batb":[[0,1.78,5.92],[1,1.77,43.68],[2,1.74,17.32]],"ltp":2.02,"tv":1233.33,"id":35736915},{"batb":[[0,1.85,5],[1,1.84,51.13],[2,1.74,17.32]],"ltp":2.02,"tv":559.58,"id":11445383}]}]}
{"op":"mcm","clk":"11927958718","pt":1724581435114,"mc":[{"id":"1.232013126","rc":[{"batb":[[0,1.77,44.6],[1,1.74,17.32],[2,1.25,864]],"ltp":2.02,"tv":1233.33,"id":35736915},{"batb":[[0,1.84,51.13],[1,1.74,17.32],[2,1.25,864]],"ltp":2.02,"tv":559.58,"id":11445383}]}]}
{"op":"mcm","clk":"11927960731","pt":1724581450016,"mc":[{"id":"1.232013126","rc":[{"batb":[[0,1.78,5.92]],"ltp":2.02,"tv":1233.33,"id":35736915},{"batb":[[0,1.85,5],[1,1.84,51.13],[2,1.74,17.32]],"ltp":2.02,"tv":559.58,"id":11445383}]}]}
{"op":"mcm","clk":"11927961177","pt":1724581453143,"mc":[{"id":"1.232013126","rc":[{"batb":[[0,1.74,18.24],[1,1.25,864],[2,1.04,1.53]],"ltp":2.02,"tv":1233.33,"id":35736915},{"batb":[[0,1.84,51.13],[1,1.74,17.32],[2,1.25,864]],"ltp":2.02,"tv":559.58,"id":11445383}]}]}
{"op":"mcm","clk":"11927961572","pt":1724581456221,"mc":[{"id":"1.232013126","rc":[{"batb":[[0,1.75,5.92],[1,1.74,17.32],[2,1.25,864]],"ltp":2.02,"tv":1233.33,"id":35736915},{"batb":[[0,1.85,5],[1,1.84,51.13],[2,1.74,17.32]],"ltp":2.02,"tv":559.58,"id":11445383}]}]}
{"op":"mcm","clk":"11927962022","pt":1724581459543,"mc":[{"id":"1.232013126","rc":[{"batb":[[0,1.74,18.24],[1,1.25,864],[2,1.04,1.53]],"ltp":2.02,"tv":1233.33,"id":35736915},{"batb":[[0,1.84,51.13],[1,1.74,17.32],[2,1.25,864]],"ltp":2.02,"tv":559.58,"id":11445383}]}]}
{"op":"mcm","clk":"11927962318","pt":1724581461765,"mc":[{"id":"1.232013126","rc":[{"trd":[[2.02,400]],"batb":[[0,2.02,4.05],[1,1.74,18.24],[2,1.25,864]],"ltp":2.02,"tv":1237.21,"id":35736915},{"batb":[[0,1.85,5],[1,1.84,51.13],[2,1.74,17.32]],"ltp":2.02,"tv":559.58,"id":11445383}],"tv":1796.8}]}
{"op":"mcm","clk":"11927962769","pt":1724581464927,"mc":[{"id":"1.232013126","rc":[{"batb":[[0,1.84,51.13],[1,1.74,17.32],[2,1.25,864]],"ltp":2.02,"tv":559.58,"id":11445383}]}]}
{"op":"mcm","clk":"11927963509","pt":1724581469956,"mc":[{"id":"1.232013126","rc":[{"batb":[[0,1.85,5],[1,1.84,51.13],[2,1.74,17.32]],"ltp":2.02,"tv":559.58,"id":11445383}]}]}
{"op":"mcm","clk":"11927963648","pt":1724581471055,"mc":[{"id":"1.232013126","rc":[{"batl":[[0,2,80.69]],"ltp":2.02,"tv":559.58,"id":11445383}]}]}
{"op":"mcm","clk":"11927963948","pt":1724581473164,"mc":[{"id":"1.232013126","rc":[{"batb":[[0,1.84,51.13],[1,1.74,17.32],[2,1.25,864]],"ltp":2.02,"tv":559.58,"id":11445383}]}]}
{"op":"mcm","clk":"11927964318","pt":1724581475938,"mc":[{"id":"1.232013126","rc":[{"batb":[[0,1.85,5],[1,1.84,51.13],[2,1.74,17.32]],"ltp":2.02,"tv":559.58,"id":11445383}]}]}
{"op":"mcm","clk":"11927964785","pt":1724581479364,"mc":[{"id":"1.232013126","rc":[{"batb":[[0,1.84,51.13],[1,1.74,17.32],[2,1.25,864]],"ltp":2.02,"tv":559.58,"id":11445383}]}]}
{"op":"mcm","clk":"11927965481","pt":1724581484469,"mc":[{"id":"1.232013126","rc":[{"batb":[[0,1.85,5],[1,1.84,51.13],[2,1.74,17.32]],"ltp":2.02,"tv":559.58,"id":11445383}]}]}
{"op":"mcm","clk":"11927965589","pt":1724581485261,"mc":[{"id":"1.232013126","rc":[{"batb":[[0,1.85,5.92]],"ltp":2.02,"tv":559.58,"id":11445383}]}]}
{"op":"mcm","clk":"11927965907","pt":1724581487674,"mc":[{"id":"1.232013126","rc":[{"batb":[[0,1.84,52.05],[1,1.74,17.32],[2,1.25,864]],"ltp":2.02,"tv":559.58,"id":11445383}]}]}
{"op":"mcm","clk":"11927967554","pt":1724581499597,"mc":[{"id":"1.232013126","rc":[{"batb":[[0,1.85,5.92],[1,1.84,51.13],[2,1.74,17.32]],"ltp":2.02,"tv":559.58,"id":11445383}]}]}
{"op":"mcm","clk":"11927968089","pt":1724581502931,"mc":[{"id":"1.232013126","rc":[{"batb":[[0,1.84,52.05],[1,1.74,17.32],[2,1.25,864]],"ltp":2.02,"tv":559.58,"id":11445383}]}]}
{"op":"mcm","clk":"11927968457","pt":1724581505303,"mc":[{"id":"1.232013126","rc":[{"batb":[[0,1.85,5.92],[1,1.84,51.13],[2,1.74,17.32]],"ltp":2.02,"tv":559.58,"id":11445383}]}]}
{"op":"mcm","clk":"11927968918","pt":1724581508670,"mc":[{"id":"1.232013126","rc":[{"batb":[[0,1.84,52.05],[1,1.74,17.32],[2,1.25,864]],"ltp":2.02,"tv":559.58,"id":11445383}]}]}
{"op":"mcm","clk":"11927969410","pt":1724581512288,"mc":[{"id":"1.232013126","rc":[{"batb":[[0,1.85,5.92],[1,1.84,51.13],[2,1.74,17.32]],"ltp":2.02,"tv":559.58,"id":11445383}]}]}
{"op":"mcm","clk":"11927969868","pt":1724581515608,"mc":[{"id":"1.232013126","rc":[{"batb":[[0,1.84,52.05],[1,1.74,17.32],[2,1.25,864]],"ltp":2.02,"tv":559.58,"id":11445383}]}]}
{"op":"mcm","clk":"11927970878","pt":1724581523016,"mc":[{"id":"1.232013126","rc":[{"batb":[[0,1.85,5.92],[1,1.84,51.13],[2,1.74,17.32]],"ltp":2.02,"tv":559.58,"id":11445383}]}]}
{"op":"mcm","clk":"11927971426","pt":1724581526321,"mc":[{"id":"1.232013126","rc":[{"batb":[[0,1.84,52.05],[1,1.74,17.32],[2,1.25,864]],"ltp":2.02,"tv":559.58,"id":11445383}]}]}
{"op":"mcm","clk":"11927972317","pt":1724581532509,"mc":[{"id":"1.232013126","rc":[{"batb":[[0,1.85,5.92],[1,1.84,51.13],[2,1.74,17.32]],"ltp":2.02,"tv":559.58,"id":11445383}]}]}
{"op":"mcm","clk":"11927972762","pt":1724581535826,"mc":[{"id":"1.232013126","rc":[{"batb":[[0,1.84,52.05],[1,1.74,17.32],[2,1.25,864]],"ltp":2.02,"tv":559.58,"id":11445383}]}]}
{"op":"mcm","clk":"11927973124","pt":1724581538718,"mc":[{"id":"1.232013126","rc":[{"batb":[[0,1.85,5.92],[1,1.84,51.13],[2,1.74,17.32]],"ltp":2.02,"tv":559.58,"id":11445383}]}]}
{"op":"mcm","clk":"11927973567","pt":1724581542123,"mc":[{"id":"1.232013126","rc":[{"batb":[[0,1.84,52.05],[1,1.74,17.32],[2,1.25,864]],"ltp":2.02,"tv":559.58,"id":11445383}]}]}
{"op":"mcm","clk":"11927973873","pt":1724581544491,"mc":[{"id":"1.232013126","rc":[{"batb":[[0,1.85,5.92],[1,1.84,51.13],[2,1.74,17.32]],"ltp":2.02,"tv":559.58,"id":11445383}]}]}
{"op":"mcm","clk":"11927974349","pt":1724581547742,"mc":[{"id":"1.232013126","rc":[{"batb":[[0,1.84,52.05],[1,1.74,17.32],[2,1.25,864]],"ltp":2.02,"tv":559.58,"id":11445383}]}]}
{"op":"mcm","clk":"11927974923","pt":1724581552041,"mc":[{"id":"1.232013126","rc":[{"batb":[[0,1.85,5.92],[1,1.84,51.13],[2,1.74,17.32]],"ltp":2.02,"tv":559.58,"id":11445383}]}]}
{"op":"mcm","clk":"11927975380","pt":1724581555341,"mc":[{"id":"1.232013126","rc":[{"batb":[[0,1.84,52.05],[1,1.74,17.32],[2,1.25,864]],"ltp":2.02,"tv":559.58,"id":11445383}]}]}
{"op":"mcm","clk":"11927976954","pt":1724581567635,"mc":[{"id":"1.232013126","rc":[{"batb":[[0,1.85,5.92],[1,1.84,51.13],[2,1.74,17.32]],"ltp":2.02,"tv":559.58,"id":11445383}]}]}
{"op":"mcm","clk":"11927977389","pt":1724581570941,"mc":[{"id":"1.232013126","rc":[{"batb":[[0,1.84,52.05],[1,1.74,17.32],[2,1.25,864]],"ltp":2.02,"tv":559.58,"id":11445383}]}]}
{"op":"mcm","clk":"11927977974","pt":1724581575280,"mc":[{"id":"1.232013126","rc":[{"batb":[[0,1.85,5.92],[1,1.84,51.13],[2,1.74,17.32]],"ltp":2.02,"tv":559.58,"id":11445383}]}]}
{"op":"mcm","clk":"11927978408","pt":1724581578575,"mc":[{"id":"1.232013126","rc":[{"batb":[[0,1.84,52.05],[1,1.74,17.32],[2,1.25,864]],"ltp":2.02,"tv":559.58,"id":11445383}]}]}
{"op":"mcm","clk":"11927979103","pt":1724581583780,"mc":[{"id":"1.232013126","rc":[{"batb":[[0,1.85,5.92],[1,1.84,51.13],[2,1.74,17.32]],"ltp":2.02,"tv":559.58,"id":11445383}]}]}
{"op":"mcm","clk":"11927979581","pt":1724581587241,"mc":[{"id":"1.232013126","rc":[{"batb":[[0,1.84,52.05],[1,1.74,17.32],[2,1.25,864]],"ltp":2.02,"tv":559.58,"id":11445383}]}]}
{"op":"mcm","clk":"11927980038","pt":1724581590675,"mc":[{"id":"1.232013126","rc":[{"batb":[[0,1.85,5.92],[1,1.84,51.13],[2,1.74,17.32]],"ltp":2.02,"tv":559.58,"id":11445383}]}]}
{"op":"mcm","clk":"11927980496","pt":1724581593998,"mc":[{"id":"1.232013126","rc":[{"batb":[[0,1.84,52.05],[1,1.74,17.32],[2,1.25,864]],"ltp":2.02,"tv":559.58,"id":11445383}]}]}
{"op":"mcm","clk":"11927981929","pt":1724581604360,"mc":[{"id":"1.232013126","rc":[{"batb":[[0,1.85,5.92],[1,1.84,51.13],[2,1.74,17.32]],"ltp":2.02,"tv":559.58,"id":11445383}]}]}
{"op":"mcm","clk":"11927982352","pt":1724581607700,"mc":[{"id":"1.232013126","rc":[{"batb":[[0,1.84,52.05],[1,1.74,17.32],[2,1.25,864]],"ltp":2.02,"tv":559.58,"id":11445383}]}]}
{"op":"mcm","clk":"11927983251","pt":1724581614495,"mc":[{"id":"1.232013126","rc":[{"batb":[[0,1.85,5.92],[1,1.84,51.13],[2,1.74,17.32]],"ltp":2.02,"tv":559.58,"id":11445383}]}]}
{"op":"mcm","clk":"11927983690","pt":1724581617900,"mc":[{"id":"1.232013126","rc":[{"batb":[[0,1.84,52.05],[1,1.74,17.32],[2,1.25,864]],"ltp":2.02,"tv":559.58,"id":11445383}]}]}
{"op":"mcm","clk":"11927983970","pt":1724581620203,"mc":[{"id":"1.232013126","rc":[{"batb":[[0,1.85,5.92],[1,1.84,51.13],[2,1.74,17.32]],"ltp":2.02,"tv":559.58,"id":11445383}]}]}
{"op":"mcm","clk":"11927984434","pt":1724581623526,"mc":[{"id":"1.232013126","rc":[{"batb":[[0,1.84,52.05],[1,1.74,17.32],[2,1.25,864]],"ltp":2.02,"tv":559.58,"id":11445383}]}]}
{"op":"mcm","clk":"11927985006","pt":1724581627990,"mc":[{"id":"1.232013126","rc":[{"batb":[[0,1.85,5.92],[1,1.84,51.13],[2,1.74,17.32]],"ltp":2.02,"tv":559.58,"id":11445383}]}]}
{"op":"mcm","clk":"11927985481","pt":1724581631292,"mc":[{"id":"1.232013126","rc":[{"batb":[[0,1.84,52.05],[1,1.74,17.32],[2,1.25,864]],"ltp":2.02,"tv":559.58,"id":11445383}]}]}
{"op":"mcm","clk":"11927986541","pt":1724581639188,"mc":[{"id":"1.232013126","rc":[{"batb":[[0,1.85,5.92],[1,1.84,51.13],[2,1.74,17.32]],"ltp":2.02,"tv":559.58,"id":11445383}]}]}
{"op":"mcm","clk":"11927987071","pt":1724581643231,"mc":[{"id":"1.232013126","rc":[{"batb":[[0,1.84,52.05],[1,1.74,17.32],[2,1.25,864]],"batl":[[0,1.99,7.29],[1,2,79.77]],"ltp":2.02,"tv":559.58,"id":11445383}]}]}
{"op":"mcm","clk":"11927995597","pt":1724581709010,"mc":[{"id":"1.232013126","rc":[{"batb":[[1,1.74,17.32]],"ltp":2.02,"tv":1237.21,"id":35736915}]}]}
{"op":"mcm","clk":"11928014809","pt":1724581853356,"mc":[{"id":"1.232013126","rc":[{"batb":[[0,1.84,51.13]],"batl":[[0,1.99,6.37]],"ltp":2.02,"tv":559.58,"id":11445383}]}]}
{"op":"mcm","clk":"11928071026","pt":1724582300272,"mc":[{"id":"1.232013126","rc":[{"batb":[[0,2.02,8.47]],"ltp":2.02,"tv":1237.21,"id":35736915}]}]}
{"op":"mcm","clk":"11928864221","pt":1724588142830,"mc":[{"id":"1.232013126","rc":[{"batb":[[2,1.04,1.53]],"ltp":2.02,"tv":1237.21,"id":35736915},{"batb":[[2,1.04,1.53]],"ltp":2.02,"tv":559.58,"id":11445383}]}]}
{"op":"mcm","clk":"11928887757","pt":1724588297212,"mc":[{"id":"1.232013126","rc":[{"batb":[[2,1.2,1250]],"ltp":2.02,"tv":1237.21,"id":35736915},{"batb":[[2,1.2,1250]],"ltp":2.02,"tv":559.58,"id":11445383}]}]}
{"op":"mcm","clk":"11928910019","pt":1724588466497,"mc":[{"id":"1.232013126","rc":[{"batb":[[2,1.5,20.92]],"ltp":2.02,"tv":559.58,"id":11445383}]}]}
{"op":"mcm","clk":"11928912408","pt":1724588483179,"mc":[{"id":"1.232013126","rc":[{"batb":[[1,1.8,20.92],[2,1.74,17.32]],"ltp":2.02,"tv":1237.21,"id":35736915}]}]}
{"op":"mcm","clk":"11929553117","pt":1724592914103,"mc":[{"id":"1.232013126","rc":[{"batb":[[0,1.84,45.76]],"ltp":2.02,"tv":559.58,"id":11445383}]}]}
{"op":"mcm","clk":"11930146133","pt":1724597625634,"mc":[{"id":"1.232013126","rc":[{"batl":[[0,1.99,23.13]],"ltp":2.02,"tv":559.58,"id":11445383}]}]}
{"op":"mcm","clk":"11930147159","pt":1724597636877,"mc":[{"id":"1.232013126","rc":[{"batl":[[0,1.99,6.37]],"ltp":2.02,"tv":559.58,"id":11445383}]}]}
{"op":"mcm","clk":"11930148260","pt":1724597648090,"mc":[{"id":"1.232013126","rc":[{"batl":[[0,1.99,23.13]],"ltp":2.02,"tv":559.58,"id":11445383}]}]}
{"op":"mcm","clk":"11930148895","pt":1724597654904,"mc":[{"id":"1.232013126","rc":[{"batl":[[0,1.99,6.37]],"ltp":2.02,"tv":559.58,"id":11445383}]}]}
{"op":"mcm","clk":"11931128878","pt":1724604616421,"mc":[{"id":"1.232013126","rc":[{"batb":[[0,1.85,8.38],[1,1.84,45.76],[2,1.74,17.32]],"ltp":2.02,"tv":559.58,"id":11445383}]}]}
{"op":"mcm","clk":"11931195627","pt":1724605263313,"mc":[{"id":"1.232013126","rc":[{"batb":[[0,1.84,45.76],[1,1.74,17.32],[2,1.5,20.92]],"ltp":2.02,"tv":559.58,"id":11445383}]}]}
{"op":"mcm","clk":"11932244402","pt":1724612481530,"mc":[{"id":"1.232013126","rc":[{"batb":[[0,2.02,4.43]],"ltp":2.02,"tv":1237.21,"id":35736915}]}]}
{"op":"mcm","clk":"11932244520","pt":1724612482211,"mc":[{"id":"1.232013126","rc":[{"batb":[[0,1.81,24.1]],"ltp":2.02,"tv":1237.21,"id":35736915}]}]}
{"op":"mcm","clk":"11932244652","pt":1724612483106,"mc":[{"id":"1.232013126","rc":[{"batb":[[0,1.82,5],[1,1.81,24.1],[2,1.8,20.92]],"batl":[[0,2.18,1.8]],"ltp":2.02,"tv":1237.21,"id":35736915}]}]}
{"op":"mcm","clk":"11932245157","pt":1724612486418,"mc":[{"id":"1.232013126","rc":[{"batb":[[0,1.81,24.1],[1,1.8,20.92],[2,1.74,17.32]],"ltp":2.02,"tv":1237.21,"id":35736915}]}]}
{"op":"mcm","clk":"11932262500","pt":1724612605891,"mc":[{"id":"1.232013126","rc":[{"batb":[[0,1.82,5],[1,1.81,24.1],[2,1.8,20.92]],"ltp":2.02,"tv":1237.21,"id":35736915}]}]}
{"op":"mcm","clk":"11932262975","pt":1724612609270,"mc":[{"id":"1.232013126","rc":[{"batb":[[0,1.81,24.1],[1,1.8,20.92],[2,1.74,17.32]],"ltp":2.02,"tv":1237.21,"id":35736915}]}]}
{"op":"mcm","clk":"11932286055","pt":1724612761080,"mc":[{"id":"1.232013126","rc":[{"batb":[[0,1.82,5],[1,1.81,24.1],[2,1.8,20.92]],"ltp":2.02,"tv":1237.21,"id":35736915}]}]}
{"op":"mcm","clk":"11932286594","pt":1724612764502,"mc":[{"id":"1.232013126","rc":[{"batb":[[0,1.81,24.1],[1,1.8,20.92],[2,1.74,17.32]],"ltp":2.02,"tv":1237.21,"id":35736915}]}]}
{"op":"mcm","clk":"11932293432","pt":1724612806484,"mc":[{"id":"1.232013126","rc":[{"batb":[[0,1.82,5],[1,1.81,24.1],[2,1.8,20.92]],"ltp":2.02,"tv":1237.21,"id":35736915}]}]}
{"op":"mcm","clk":"11932293950","pt":1724612810002,"mc":[{"id":"1.232013126","rc":[{"batb":[[0,1.81,24.1],[1,1.8,20.92],[2,1.74,17.32]],"ltp":2.02,"tv":1237.21,"id":35736915}]}]}
{"op":"mcm","clk":"11932320491","pt":1724612980820,"mc":[{"id":"1.232013126","rc":[{"batb":[[0,1.82,5],[1,1.81,24.1],[2,1.8,20.92]],"ltp":2.02,"tv":1237.21,"id":35736915}]}]}
{"op":"mcm","clk":"11932321075","pt":1724612984708,"mc":[{"id":"1.232013126","rc":[{"batb":[[0,1.81,24.1],[1,1.8,20.92],[2,1.74,17.32]],"ltp":2.02,"tv":1237.21,"id":35736915}]}]}
{"op":"mcm","clk":"11932323541","pt":1724613001831,"mc":[{"id":"1.232013126","rc":[{"batb":[[0,1.82,5],[1,1.81,24.1],[2,1.8,20.92]],"ltp":2.02,"tv":1237.21,"id":35736915}]}]}
{"op":"mcm","clk":"11932324152","pt":1724613005430,"mc":[{"id":"1.232013126","rc":[{"batb":[[0,1.81,24.1],[1,1.8,20.92],[2,1.74,17.32]],"ltp":2.02,"tv":1237.21,"id":35736915}]}]}
{"op":"mcm","clk":"11932330455","pt":1724613046859,"mc":[{"id":"1.232013126","rc":[{"batb":[[0,1.82,5],[1,1.81,24.1],[2,1.8,20.92]],"ltp":2.02,"tv":1237.21,"id":35736915}]}]}
{"op":"mcm","clk":"11932330997","pt":1724613050363,"mc":[{"id":"1.232013126","rc":[{"batb":[[0,1.81,24.1],[1,1.8,20.92],[2,1.74,17.32]],"ltp":2.02,"tv":1237.21,"id":35736915}]}]}
{"op":"mcm","clk":"11932333825","pt":1724613068973,"mc":[{"id":"1.232013126","rc":[{"batb":[[0,1.82,5],[1,1.81,24.1],[2,1.8,20.92]],"ltp":2.02,"tv":1237.21,"id":35736915}]}]}
{"op":"mcm","clk":"11932334288","pt":1724613072399,"mc":[{"id":"1.232013126","rc":[{"batb":[[0,1.81,24.1],[1,1.8,20.92],[2,1.74,17.32]],"ltp":2.02,"tv":1237.21,"id":35736915}]}]}
{"op":"mcm","clk":"11932344011","pt":1724613136446,"mc":[{"id":"1.232013126","rc":[{"batb":[[0,1.82,5],[1,1.81,24.1],[2,1.8,20.92]],"ltp":2.02,"tv":1237.21,"id":35736915}]}]}
{"op":"mcm","clk":"11932344503","pt":1724613139818,"mc":[{"id":"1.232013126","rc":[{"batb":[[0,1.81,24.1],[1,1.8,20.92],[2,1.74,17.32]],"ltp":2.02,"tv":1237.21,"id":35736915}]}]}
{"op":"mcm","clk":"11932348462","pt":1724613164026,"mc":[{"id":"1.232013126","rc":[{"batb":[[0,1.82,5],[1,1.81,24.1],[2,1.8,20.92]],"ltp":2.02,"tv":1237.21,"id":35736915}]}]}
{"op":"mcm","clk":"11932349050","pt":1724613167529,"mc":[{"id":"1.232013126","rc":[{"batb":[[0,1.81,24.1],[1,1.8,20.92],[2,1.74,17.32]],"ltp":2.02,"tv":1237.21,"id":35736915}]}]}
{"op":"mcm","clk":"11932360925","pt":1724613244252,"mc":[{"id":"1.232013126","rc":[{"batb":[[0,1.82,5],[1,1.81,24.1],[2,1.8,20.92]],"ltp":2.02,"tv":1237.21,"id":35736915}]}]}
{"op":"mcm","clk":"11932361382","pt":1724613247523,"mc":[{"id":"1.232013126","rc":[{"batb":[[0,1.81,24.1],[1,1.8,20.92],[2,1.74,17.32]],"ltp":2.02,"tv":1237.21,"id":35736915}]}]}
{"op":"mcm","clk":"11932367536","pt":1724613291152,"mc":[{"id":"1.232013126","rc":[{"batb":[[0,1.82,5],[1,1.81,24.1],[2,1.8,20.92]],"ltp":2.02,"tv":1237.21,"id":35736915}]}]}
{"op":"mcm","clk":"11932367995","pt":1724613294616,"mc":[{"id":"1.232013126","rc":[{"batb":[[0,1.81,24.1],[1,1.8,20.92],[2,1.74,17.32]],"ltp":2.02,"tv":1237.21,"id":35736915}]}]}
{"op":"mcm","clk":"11932374405","pt":1724613338070,"mc":[{"id":"1.232013126","rc":[{"batb":[[0,1.82,5],[1,1.81,24.1],[2,1.8,20.92]],"ltp":2.02,"tv":1237.21,"id":35736915}]}]}
{"op":"mcm","clk":"11932374911","pt":1724613341561,"mc":[{"id":"1.232013126","rc":[{"batb":[[0,1.81,24.1],[1,1.8,20.92],[2,1.74,17.32]],"ltp":2.02,"tv":1237.21,"id":35736915}]}]}
{"op":"mcm","clk":"11932376509","pt":1724613352486,"mc":[{"id":"1.232013126","rc":[{"batb":[[0,1.82,5],[1,1.81,24.1],[2,1.8,20.92]],"ltp":2.02,"tv":1237.21,"id":35736915}]}]}
{"op":"mcm","clk":"11932377041","pt":1724613355907,"mc":[{"id":"1.232013126","rc":[{"batb":[[0,1.81,24.1],[1,1.8,20.92],[2,1.74,17.32]],"ltp":2.02,"tv":1237.21,"id":35736915}]}]}
{"op":"mcm","clk":"11932392841","pt":1724613463558,"mc":[{"id":"1.232013126","rc":[{"batb":[[0,1.82,5],[1,1.81,24.1],[2,1.8,20.92]],"ltp":2.02,"tv":1237.21,"id":35736915}]}]}
{"op":"mcm","clk":"11932393290","pt":1724613466897,"mc":[{"id":"1.232013126","rc":[{"batb":[[0,1.81,24.1],[1,1.8,20.92],[2,1.74,17.32]],"ltp":2.02,"tv":1237.21,"id":35736915}]}]}
{"op":"mcm","clk":"11932430089","pt":1724613702161,"mc":[{"id":"1.232013126","rc":[{"batb":[[0,1.82,5],[1,1.81,24.1],[2,1.8,20.92]],"ltp":2.02,"tv":1237.21,"id":35736915}]}]}
{"op":"mcm","clk":"11932430649","pt":1724613705618,"mc":[{"id":"1.232013126","rc":[{"batb":[[0,1.81,24.1],[1,1.8,20.92],[2,1.74,17.32]],"ltp":2.02,"tv":1237.21,"id":35736915}]}]}
{"op":"mcm","clk":"11932448119","pt":1724613807499,"mc":[{"id":"1.232013126","rc":[{"batb":[[0,1.82,5],[1,1.81,24.1],[2,1.8,20.92]],"ltp":2.02,"tv":1237.21,"id":35736915}]}]}
{"op":"mcm","clk":"11932448781","pt":1724613810884,"mc":[{"id":"1.232013126","rc":[{"batb":[[0,1.81,24.1],[1,1.8,20.92],[2,1.74,17.32]],"ltp":2.02,"tv":1237.21,"id":35736915}]}]}
{"op":"mcm","clk":"11932459075","pt":1724613873400,"mc":[{"id":"1.232013126","rc":[{"batb":[[0,1.82,5],[1,1.81,24.1],[2,1.8,20.92]],"ltp":2.02,"tv":1237.21,"id":35736915}]}]}
{"op":"mcm","clk":"11932459615","pt":1724613876723,"mc":[{"id":"1.232013126","rc":[{"batb":[[0,1.81,24.1],[1,1.8,20.92],[2,1.74,17.32]],"ltp":2.02,"tv":1237.21,"id":35736915}]}]}
{"op":"mcm","clk":"11932465664","pt":1724613913296,"mc":[{"id":"1.232013126","rc":[{"batb":[[0,1.82,5],[1,1.81,24.1],[2,1.8,20.92]],"ltp":2.02,"tv":1237.21,"id":35736915}]}]}
{"op":"mcm","clk":"11932466289","pt":1724613916877,"mc":[{"id":"1.232013126","rc":[{"batb":[[0,1.81,24.1],[1,1.8,20.92],[2,1.74,17.32]],"ltp":2.02,"tv":1237.21,"id":35736915}]}]}
{"op":"mcm","clk":"11932472508","pt":1724613956810,"mc":[{"id":"1.232013126","rc":[{"batb":[[0,1.82,5],[1,1.81,24.1],[2,1.8,20.92]],"ltp":2.02,"tv":1237.21,"id":35736915}]}]}
{"op":"mcm","clk":"11932473028","pt":1724613960428,"mc":[{"id":"1.232013126","rc":[{"batb":[[0,1.81,24.1],[1,1.8,20.92],[2,1.74,17.32]],"ltp":2.02,"tv":1237.21,"id":35736915}]}]}
{"op":"mcm","clk":"11932494801","pt":1724614102652,"mc":[{"id":"1.232013126","rc":[{"batb":[[0,1.82,5],[1,1.81,24.1],[2,1.8,20.92]],"ltp":2.02,"tv":1237.21,"id":35736915}]}]}
{"op":"mcm","clk":"11932495373","pt":1724614106057,"mc":[{"id":"1.232013126","rc":[{"batb":[[0,1.81,24.1],[1,1.8,20.92],[2,1.74,17.32]],"ltp":2.02,"tv":1237.21,"id":35736915}]}]}
{"op":"mcm","clk":"11932527290","pt":1724614303531,"mc":[{"id":"1.232013126","rc":[{"batb":[[0,1.82,5],[1,1.81,24.1],[2,1.8,20.92]],"ltp":2.02,"tv":1237.21,"id":35736915}]}]}
{"op":"mcm","clk":"11932527806","pt":1724614307028,"mc":[{"id":"1.232013126","rc":[{"batb":[[0,1.81,24.1],[1,1.8,20.92],[2,1.74,17.32]],"ltp":2.02,"tv":1237.21,"id":35736915}]}]}
{"op":"mcm","clk":"11932547036","pt":1724614434003,"mc":[{"id":"1.232013126","rc":[{"batb":[[0,1.82,5],[1,1.81,24.1],[2,1.8,20.92]],"ltp":2.02,"tv":1237.21,"id":35736915}]}]}
{"op":"mcm","clk":"11932547581","pt":1724614437286,"mc":[{"id":"1.232013126","rc":[{"batb":[[0,1.81,24.1],[1,1.8,20.92],[2,1.74,17.32]],"ltp":2.02,"tv":1237.21,"id":35736915}]}]}
{"op":"mcm","clk":"11932551240","pt":1724614460712,"mc":[{"id":"1.232013126","rc":[{"batb":[[0,1.82,5],[1,1.81,24.1],[2,1.8,20.92]],"ltp":2.02,"tv":1237.21,"id":35736915}]}]}
{"op":"mcm","clk":"11932551760","pt":1724614464038,"mc":[{"id":"1.232013126","rc":[{"batb":[[0,1.81,24.1],[1,1.8,20.92],[2,1.74,17.32]],"ltp":2.02,"tv":1237.21,"id":35736915}]}]}
{"op":"mcm","clk":"11932559805","pt":1724614517481,"mc":[{"id":"1.232013126","rc":[{"batb":[[0,1.82,5],[1,1.81,24.1],[2,1.8,20.92]],"ltp":2.02,"tv":1237.21,"id":35736915}]}]}
{"op":"mcm","clk":"11932560347","pt":1724614520764,"mc":[{"id":"1.232013126","rc":[{"batb":[[0,1.81,24.1],[1,1.8,20.92],[2,1.74,17.32]],"ltp":2.02,"tv":1237.21,"id":35736915}]}]}
{"op":"mcm","clk":"11932589593","pt":1724614712667,"mc":[{"id":"1.232013126","rc":[{"batb":[[0,1.82,5],[1,1.81,24.1],[2,1.8,20.92]],"ltp":2.02,"tv":1237.21,"id":35736915}]}]}
{"op":"mcm","clk":"11932590091","pt":1724614716181,"mc":[{"id":"1.232013126","rc":[{"batb":[[0,1.81,24.1],[1,1.8,20.92],[2,1.74,17.32]],"ltp":2.02,"tv":1237.21,"id":35736915}]}]}
{"op":"mcm","clk":"11932611259","pt":1724614863431,"mc":[{"id":"1.232013126","rc":[{"batb":[[0,1.82,5],[1,1.81,24.1],[2,1.8,20.92]],"ltp":2.02,"tv":1237.21,"id":35736915}]}]}
{"op":"mcm","clk":"11932611732","pt":1724614866748,"mc":[{"id":"1.232013126","rc":[{"batb":[[0,1.81,24.1],[1,1.8,20.92],[2,1.74,17.32]],"ltp":2.02,"tv":1237.21,"id":35736915}]}]}
{"op":"mcm","clk":"11932639379","pt":1724614985654,"mc":[{"id":"1.232013126","rc":[{"batb":[[0,1.82,5],[1,1.81,24.1],[2,1.8,20.92]],"ltp":2.02,"tv":1237.21,"id":35736915}]}]}
{"op":"mcm","clk":"11932639899","pt":1724614989168,"mc":[{"id":"1.232013126","rc":[{"batb":[[0,1.81,24.1],[1,1.8,20.92],[2,1.74,17.32]],"ltp":2.02,"tv":1237.21,"id":35736915}]}]}
{"op":"mcm","clk":"11932643432","pt":1724615012622,"mc":[{"id":"1.232013126","rc":[{"batb":[[0,1.82,5],[1,1.81,24.1],[2,1.8,20.92]],"ltp":2.02,"tv":1237.21,"id":35736915}]}]}
{"op":"mcm","clk":"11932643946","pt":1724615016210,"mc":[{"id":"1.232013126","rc":[{"batb":[[0,1.81,24.1],[1,1.8,20.92],[2,1.74,17.32]],"ltp":2.02,"tv":1237.21,"id":35736915}]}]}
{"op":"mcm","clk":"11932645729","pt":1724615028921,"mc":[{"id":"1.232013126","rc":[{"batb":[[0,1.82,5],[1,1.81,24.1],[2,1.8,20.92]],"ltp":2.02,"tv":1237.21,"id":35736915}]}]}
{"op":"mcm","clk":"11932646283","pt":1724615032796,"mc":[{"id":"1.232013126","rc":[{"batb":[[0,1.81,24.1],[1,1.8,20.92],[2,1.74,17.32]],"ltp":2.02,"tv":1237.21,"id":35736915}]}]}
{"op":"mcm","clk":"11932648058","pt":1724615045576,"mc":[{"id":"1.232013126","rc":[{"batb":[[0,1.82,5],[1,1.81,24.1],[2,1.8,20.92]],"ltp":2.02,"tv":1237.21,"id":35736915}]}]}
{"op":"mcm","clk":"11932648515","pt":1724615048806,"mc":[{"id":"1.232013126","rc":[{"batb":[[0,1.81,24.1],[1,1.8,20.92],[2,1.74,17.32]],"ltp":2.02,"tv":1237.21,"id":35736915}]}]}
{"op":"mcm","clk":"11932657759","pt":1724615109794,"mc":[{"id":"1.232013126","rc":[{"batb":[[0,1.82,5],[1,1.81,24.1],[2,1.8,20.92]],"ltp":2.02,"tv":1237.21,"id":35736915}]}]}
{"op":"mcm","clk":"11932658275","pt":1724615113370,"mc":[{"id":"1.232013126","rc":[{"batb":[[0,1.81,24.1],[1,1.8,20.92],[2,1.74,17.32]],"ltp":2.02,"tv":1237.21,"id":35736915}]}]}
{"op":"mcm","clk":"11932660911","pt":1724615130424,"mc":[{"id":"1.232013126","rc":[{"batb":[[0,1.82,5],[1,1.81,24.1],[2,1.8,20.92]],"ltp":2.02,"tv":1237.21,"id":35736915}]}]}
{"op":"mcm","clk":"11932661453","pt":1724615133719,"mc":[{"id":"1.232013126","rc":[{"batb":[[0,1.81,24.1],[1,1.8,20.92],[2,1.74,17.32]],"ltp":2.02,"tv":1237.21,"id":35736915}]}]}
{"op":"mcm","clk":"11932679527","pt":1724615257058,"mc":[{"id":"1.232013126","rc":[{"batb":[[0,1.82,5],[1,1.81,24.1],[2,1.8,20.92]],"ltp":2.02,"tv":1237.21,"id":35736915}]}]}
{"op":"mcm","clk":"11932680042","pt":1724615260692,"mc":[{"id":"1.232013126","rc":[{"batb":[[0,1.81,24.1],[1,1.8,20.92],[2,1.74,17.32]],"ltp":2.02,"tv":1237.21,"id":35736915}]}]}
{"op":"mcm","clk":"11932685098","pt":1724615297329,"mc":[{"id":"1.232013126","rc":[{"batb":[[0,1.82,5],[1,1.81,24.1],[2,1.8,20.92]],"ltp":2.02,"tv":1237.21,"id":35736915}]}]}
{"op":"mcm","clk":"11932685516","pt":1724615300770,"mc":[{"id":"1.232013126","rc":[{"batb":[[0,1.81,24.1],[1,1.8,20.92],[2,1.74,17.32]],"ltp":2.02,"tv":1237.21,"id":35736915}]}]}
{"op":"mcm","clk":"11932688198","pt":1724615320437,"mc":[{"id":"1.232013126","rc":[{"batb":[[0,1.82,5],[1,1.81,24.1],[2,1.8,20.92]],"ltp":2.02,"tv":1237.21,"id":35736915}]}]}
{"op":"mcm","clk":"11932688709","pt":1724615324055,"mc":[{"id":"1.232013126","rc":[{"batb":[[0,1.81,24.1],[1,1.8,20.92],[2,1.74,17.32]],"ltp":2.02,"tv":1237.21,"id":35736915}]}]}
{"op":"mcm","clk":"11932699228","pt":1724615404756,"mc":[{"id":"1.232013126","rc":[{"batb":[[0,1.82,5],[1,1.81,24.1],[2,1.8,20.92]],"ltp":2.02,"tv":1237.21,"id":35736915}]}]}
{"op":"mcm","clk":"11932699666","pt":1724615408147,"mc":[{"id":"1.232013126","rc":[{"batb":[[0,1.81,24.1],[1,1.8,20.92],[2,1.74,17.32]],"ltp":2.02,"tv":1237.21,"id":35736915}]}]}
{"op":"mcm","clk":"11932713110","pt":1724615511498,"mc":[{"id":"1.232013126","rc":[{"batb":[[0,1.82,5],[1,1.81,24.1],[2,1.8,20.92]],"ltp":2.02,"tv":1237.21,"id":35736915}]}]}
{"op":"mcm","clk":"11932713610","pt":1724615514837,"mc":[{"id":"1.232013126","rc":[{"batb":[[0,1.81,24.1],[1,1.8,20.92],[2,1.74,17.32]],"ltp":2.02,"tv":1237.21,"id":35736915}]}]}
{"op":"mcm","clk":"11932718066","pt":1724615547693,"mc":[{"id":"1.232013126","rc":[{"batb":[[0,1.82,5],[1,1.81,24.1],[2,1.8,20.92]],"ltp":2.02,"tv":1237.21,"id":35736915}]}]}
{"op":"mcm","clk":"11932718508","pt":1724615551181,"mc":[{"id":"1.232013126","rc":[{"batb":[[0,1.81,24.1],[1,1.8,20.92],[2,1.74,17.32]],"ltp":2.02,"tv":1237.21,"id":35736915}]}]}
{"op":"mcm","clk":"11932789776","pt":1724616077971,"mc":[{"id":"1.232013126","rc":[{"trd":[[2.02,400],[2.1,77.14],[2.18,72.74]],"batb":[[0,1.82,5],[1,1.81,24.1],[2,1.8,20.92]],"batl":[[0,2.18,1.8]],"ltp":2.02,"tv":1237.12,"id":35736915}],"tv":1796.71}]}
{"op":"mcm","clk":"11932790258","pt":1724616081368,"mc":[{"id":"1.232013126","rc":[{"batb":[[0,1.81,24.1],[1,1.8,20.92],[2,1.74,17.32]],"ltp":2.02,"tv":1237.12,"id":35736915}]}]}
{"op":"mcm","clk":"11932812530","pt":1724616253550,"mc":[{"id":"1.232013126","rc":[{"batb":[[0,1.82,5],[1,1.81,24.1],[2,1.8,20.92]],"ltp":2.02,"tv":1237.12,"id":35736915}]}]}
{"op":"mcm","clk":"11932812944","pt":1724616256932,"mc":[{"id":"1.232013126","rc":[{"batb":[[0,1.81,24.1],[1,1.8,20.92],[2,1.74,17.32]],"ltp":2.02,"tv":1237.12,"id":35736915}]}]}
{"op":"mcm","clk":"11932841332","pt":1724616497516,"mc":[{"id":"1.232013126","rc":[{"batb":[[0,1.82,5],[1,1.81,24.1],[2,1.8,20.92]],"ltp":2.02,"tv":1237.12,"id":35736915}]}]}
{"op":"mcm","clk":"11932841743","pt":1724616500864,"mc":[{"id":"1.232013126","rc":[{"batb":[[0,1.81,24.1],[1,1.8,20.92],[2,1.74,17.32]],"ltp":2.02,"tv":1237.12,"id":35736915}]}]}
{"op":"mcm","clk":"11932858330","pt":1724616634587,"mc":[{"id":"1.232013126","rc":[{"batb":[[0,1.82,5],[1,1.81,24.1],[2,1.8,20.92]],"ltp":2.02,"tv":1237.12,"id":35736915}]}]}
{"op":"mcm","clk":"11932858728","pt":1724616637968,"mc":[{"id":"1.232013126","rc":[{"batb":[[0,1.81,24.1],[1,1.8,20.92],[2,1.74,17.32]],"ltp":2.02,"tv":1237.12,"id":35736915}]}]}
{"op":"mcm","clk":"11932863806","pt":1724616677913,"mc":[{"id":"1.232013126","rc":[{"batb":[[0,1.82,5],[1,1.81,24.1],[2,1.8,20.92]],"ltp":2.02,"tv":1237.12,"id":35736915}]}]}
{"op":"mcm","clk":"11932864231","pt":1724616681430,"mc":[{"id":"1.232013126","rc":[{"batb":[[0,1.81,24.1],[1,1.8,20.92],[2,1.74,17.32]],"ltp":2.02,"tv":1237.12,"id":35736915}]}]}
{"op":"mcm","clk":"11932889023","pt":1724616875924,"mc":[{"id":"1.232013126","rc":[{"batb":[[0,1.82,5],[1,1.81,24.1],[2,1.8,20.92]],"ltp":2.02,"tv":1237.12,"id":35736915}]}]}
{"op":"mcm","clk":"11932889459","pt":1724616879356,"mc":[{"id":"1.232013126","rc":[{"batb":[[0,1.81,24.1],[1,1.8,20.92],[2,1.74,17.32]],"ltp":2.02,"tv":1237.12,"id":35736915}]}]}
{"op":"mcm","clk":"11932910565","pt":1724617048571,"mc":[{"id":"1.232013126","rc":[{"batb":[[0,1.82,5],[1,1.81,24.1],[2,1.8,20.92]],"ltp":2.02,"tv":1237.12,"id":35736915}]}]}
{"op":"mcm","clk":"11932911020","pt":1724617052083,"mc":[{"id":"1.232013126","rc":[{"batb":[[0,1.81,24.1],[1,1.8,20.92],[2,1.74,17.32]],"ltp":2.02,"tv":1237.12,"id":35736915}]}]}
{"op":"mcm","clk":"11932912376","pt":1724617064089,"mc":[{"id":"1.232013126","rc":[{"batb":[[0,1.82,5],[1,1.81,24.1],[2,1.8,20.92]],"ltp":2.02,"tv":1237.12,"id":35736915}]}]}
{"op":"mcm","clk":"11932912773","pt":1724617067683,"mc":[{"id":"1.232013126","rc":[{"batb":[[0,1.81,24.1],[1,1.8,20.92],[2,1.74,17.32]],"ltp":2.02,"tv":1237.12,"id":35736915}]}]}
{"op":"mcm","clk":"11932931968","pt":1724617218542,"mc":[{"id":"1.232013126","rc":[{"batb":[[0,1.82,5],[1,1.81,24.1],[2,1.8,20.92]],"ltp":2.02,"tv":1237.12,"id":35736915}]}]}
{"op":"mcm","clk":"11932932386","pt":1724617221878,"mc":[{"id":"1.232013126","rc":[{"batb":[[0,1.81,24.1],[1,1.8,20.92],[2,1.74,17.32]],"ltp":2.02,"tv":1237.12,"id":35736915}]}]}
{"op":"mcm","clk":"11932932765","pt":1724617224960,"mc":[{"id":"1.232013126","rc":[{"batb":[[0,1.82,5],[1,1.81,24.1],[2,1.8,20.92]],"ltp":2.02,"tv":1237.12,"id":35736915}]}]}
{"op":"mcm","clk":"11932933176","pt":1724617228455,"mc":[{"id":"1.232013126","rc":[{"batb":[[0,1.81,24.1],[1,1.8,20.92],[2,1.74,17.32]],"ltp":2.02,"tv":1237.12,"id":35736915}]}]}
{"op":"mcm","clk":"11932934385","pt":1724617238479,"mc":[{"id":"1.232013126","rc":[{"batb":[[0,1.82,5],[1,1.81,24.1],[2,1.8,20.92]],"ltp":2.02,"tv":1237.12,"id":35736915}]}]}
{"op":"mcm","clk":"11932934780","pt":1724617241872,"mc":[{"id":"1.232013126","rc":[{"batb":[[0,1.81,24.1],[1,1.8,20.92],[2,1.74,17.32]],"ltp":2.02,"tv":1237.12,"id":35736915}]}]}
{"op":"mcm","clk":"11932937056","pt":1724617260524,"mc":[{"id":"1.232013126","rc":[{"batb":[[0,1.82,5],[1,1.81,24.1],[2,1.8,20.92]],"ltp":2.02,"tv":1237.12,"id":35736915}]}]}
{"op":"mcm","clk":"11932937526","pt":1724617264092,"mc":[{"id":"1.232013126","rc":[{"batb":[[0,1.81,24.1],[1,1.8,20.92],[2,1.74,17.32]],"ltp":2.02,"tv":1237.12,"id":35736915}]}]}
{"op":"mcm","clk":"11932943310","pt":1724617310060,"mc":[{"id":"1.232013126","rc":[{"batb":[[0,1.82,5],[1,1.81,24.1],[2,1.8,20.92]],"ltp":2.02,"tv":1237.12,"id":35736915}]}]}
{"op":"mcm","clk":"11932943726","pt":1724617313850,"mc":[{"id":"1.232013126","rc":[{"batb":[[0,1.81,24.1],[1,1.8,20.92],[2,1.74,17.32]],"ltp":2.02,"tv":1237.12,"id":35736915}]}]}
{"op":"mcm","clk":"11932954328","pt":1724617403663,"mc":[{"id":"1.232013126","rc":[{"batb":[[0,1.82,5],[1,1.81,24.1],[2,1.8,20.92]],"ltp":2.02,"tv":1237.12,"id":35736915}]}]}
{"op":"mcm","clk":"11932954718","pt":1724617407177,"mc":[{"id":"1.232013126","rc":[{"batb":[[0,1.81,24.1],[1,1.8,20.92],[2,1.74,17.32]],"ltp":2.02,"tv":1237.12,"id":35736915}]}]}
{"op":"mcm","clk":"11932961858","pt":1724617472943,"mc":[{"id":"1.232013126","rc":[{"batb":[[0,1.91,5],[1,1.9,16.5],[2,1.81,24.1]],"ltp":2.02,"tv":1237.12,"id":35736915},{"batb":[[1,1.75,16.5],[2,1.74,17.32]],"ltp":2.02,"tv":559.58,"id":11445383}]}]}
{"op":"mcm","clk":"11932962211","pt":1724617476243,"mc":[{"id":"1.232013126","rc":[{"batb":[[0,1.9,16.5],[1,1.81,24.1],[2,1.8,20.92]],"ltp":2.02,"tv":1237.12,"id":35736915}]}]}
{"op":"mcm","clk":"11932963960","pt":1724617491953,"mc":[{"id":"1.232013126","rc":[{"batb":[[0,1.91,5],[1,1.9,16.5]],"ltp":2.02,"tv":1237.12,"id":35736915}]}]}
{"op":"mcm","clk":"11932964323","pt":1724617495134,"mc":[{"id":"1.232013126","rc":[{"batb":[[0,1.9,16.5],[1,1.8,20.92],[2,1.75,20.62]],"ltp":2.02,"tv":1237.12,"id":35736915}]}]}
{"op":"mcm","clk":"11932965661","pt":1724617507674,"mc":[{"id":"1.232013126","rc":[{"batb":[[0,1.91,5],[1,1.9,16.5],[2,1.8,20.92]],"ltp":2.02,"tv":1237.12,"id":35736915}]}]}
{"op":"mcm","clk":"11932966019","pt":1724617511286,"mc":[{"id":"1.232013126","rc":[{"batb":[[0,1.9,16.5],[1,1.8,20.92],[2,1.75,20.62]],"ltp":2.02,"tv":1237.12,"id":35736915}]}]}
{"op":"mcm","clk":"11932984761","pt":1724617676185,"mc":[{"id":"1.232013126","rc":[{"batb":[[0,1.91,5],[1,1.9,16.5],[2,1.8,20.92]],"ltp":2.02,"tv":1237.12,"id":35736915}]}]}
{"op":"mcm","clk":"11932985146","pt":1724617679565,"mc":[{"id":"1.232013126","rc":[{"batb":[[0,1.9,16.5],[1,1.8,20.92],[2,1.75,20.62]],"ltp":2.02,"tv":1237.12,"id":35736915}]}]}
{"op":"mcm","clk":"11932985534","pt":1724617682886,"mc":[{"id":"1.232013126","rc":[{"batb":[[0,1.91,5],[1,1.9,16.5],[2,1.8,20.92]],"ltp":2.02,"tv":1237.12,"id":35736915}]}]}
{"op":"mcm","clk":"11932985897","pt":1724617686321,"mc":[{"id":"1.232013126","rc":[{"batb":[[0,1.9,16.5],[1,1.8,20.92],[2,1.75,20.62]],"ltp":2.02,"tv":1237.12,"id":35736915}]}]}
{"op":"mcm","clk":"11933008191","pt":1724617894213,"mc":[{"id":"1.232013126","rc":[{"batb":[[0,1.91,5],[1,1.9,16.5],[2,1.8,20.92]],"ltp":2.02,"tv":1237.12,"id":35736915}]}]}
{"op":"mcm","clk":"11933008599","pt":1724617897828,"mc":[{"id":"1.232013126","rc":[{"batb":[[0,1.9,16.5],[1,1.8,20.92],[2,1.75,20.62]],"ltp":2.02,"tv":1237.12,"id":35736915}]}]}
{"op":"mcm","clk":"11933010031","pt":1724617910955,"mc":[{"id":"1.232013126","rc":[{"batb":[[0,1.91,5],[1,1.9,16.5],[2,1.8,20.92]],"ltp":2.02,"tv":1237.12,"id":35736915}]}]}
{"op":"mcm","clk":"11933010410","pt":1724617914621,"mc":[{"id":"1.232013126","rc":[{"batb":[[0,1.9,16.5],[1,1.8,20.92],[2,1.75,20.62]],"ltp":2.02,"tv":1237.12,"id":35736915}]}]}
{"op":"mcm","clk":"11933020720","pt":1724618017663,"mc":[{"id":"1.232013126","rc":[{"batb":[[0,1.91,5],[1,1.9,16.5],[2,1.8,20.92]],"ltp":2.02,"tv":1237.12,"id":35736915}]}]}
{"op":"mcm","clk":"11933021010","pt":1724618021169,"mc":[{"id":"1.232013126","rc":[{"batb":[[0,1.9,16.5],[1,1.8,20.92],[2,1.75,20.62]],"ltp":2.02,"tv":1237.12,"id":35736915}]}]}
{"op":"mcm","clk":"11933021482","pt":1724618026584,"mc":[{"id":"1.232013126","rc":[{"batb":[[0,1.91,5],[1,1.9,16.5],[2,1.8,20.92]],"ltp":2.02,"tv":1237.12,"id":35736915}]}]}
{"op":"mcm","clk":"11933021853","pt":1724618030045,"mc":[{"id":"1.232013126","rc":[{"batb":[[0,1.9,16.5],[1,1.8,20.92],[2,1.75,20.62]],"ltp":2.02,"tv":1237.12,"id":35736915}]}]}
{"op":"mcm","clk":"11933035094","pt":1724618162574,"mc":[{"id":"1.232013126","rc":[{"batb":[[0,1.91,5],[1,1.9,16.5],[2,1.8,20.92]],"ltp":2.02,"tv":1237.12,"id":35736915}]}]}
{"op":"mcm","clk":"11933035452","pt":1724618166057,"mc":[{"id":"1.232013126","rc":[{"batb":[[0,1.9,16.5],[1,1.8,20.92],[2,1.75,20.62]],"ltp":2.02,"tv":1237.12,"id":35736915}]}]}
{"op":"mcm","clk":"11933057417","pt":1724618399589,"mc":[{"id":"1.232013126","rc":[{"batb":[[0,1.91,5],[1,1.9,16.5],[2,1.8,20.92]],"ltp":2.02,"tv":1237.12,"id":35736915}]}]}
{"op":"mcm","clk":"11933057743","pt":1724618402965,"mc":[{"id":"1.232013126","rc":[{"batb":[[0,1.9,16.5],[1,1.8,20.92],[2,1.75,20.62]],"ltp":2.02,"tv":1237.12,"id":35736915}]}]}
{"op":"mcm","clk":"11933073473","pt":1724618574329,"mc":[{"id":"1.232013126","rc":[{"batb":[[0,1.91,5],[1,1.9,16.5],[2,1.8,20.92]],"ltp":2.02,"tv":1237.12,"id":35736915}]}]}
{"op":"mcm","clk":"11933073814","pt":1724618578047,"mc":[{"id":"1.232013126","rc":[{"batb":[[0,1.9,16.5],[1,1.8,20.92],[2,1.75,20.62]],"ltp":2.02,"tv":1237.12,"id":35736915}]}]}
{"op":"mcm","clk":"11933077293","pt":1724618616483,"mc":[{"id":"1.232013126","rc":[{"batb":[[0,1.91,5],[1,1.9,16.5],[2,1.8,20.92]],"ltp":2.02,"tv":1237.12,"id":35736915}]}]}
{"op":"mcm","clk":"11933077608","pt":1724618620068,"mc":[{"id":"1.232013126","rc":[{"batb":[[0,1.9,16.5],[1,1.8,20.92],[2,1.75,20.62]],"ltp":2.02,"tv":1237.12,"id":35736915}]}]}
{"op":"mcm","clk":"11933078570","pt":1724618630098,"mc":[{"id":"1.232013126","rc":[{"batb":[[0,1.91,5],[1,1.9,16.5],[2,1.8,20.92]],"ltp":2.02,"tv":1237.12,"id":35736915}]}]}
{"op":"mcm","clk":"11933078881","pt":1724618633497,"mc":[{"id":"1.232013126","rc":[{"batb":[[0,1.9,16.5],[1,1.8,20.92],[2,1.75,20.62]],"ltp":2.02,"tv":1237.12,"id":35736915}]}]}
{"op":"mcm","clk":"11933081029","pt":1724618656244,"mc":[{"id":"1.232013126","rc":[{"batb":[[0,1.91,5],[1,1.9,16.5],[2,1.8,20.92]],"ltp":2.02,"tv":1237.12,"id":35736915}]}]}
{"op":"mcm","clk":"11933081385","pt":1724618659640,"mc":[{"id":"1.232013126","rc":[{"batb":[[0,1.9,16.5],[1,1.8,20.92],[2,1.75,20.62]],"ltp":2.02,"tv":1237.12,"id":35736915}]}]}
{"op":"mcm","clk":"11933081519","pt":1724618661244,"mc":[{"id":"1.232013126","rc":[{"batb":[[0,1.85,7.52],[1,1.84,45.76],[2,1.75,16.5]],"ltp":2.02,"tv":559.58,"id":11445383}]}]}
{"op":"mcm","clk":"11933081590","pt":1724618662048,"mc":[{"id":"1.232013126","rc":[{"batb":[[0,1.91,5],[1,1.9,16.5],[2,1.8,20.92]],"ltp":2.02,"tv":1237.12,"id":35736915}]}]}
{"op":"mcm","clk":"11933081886","pt":1724618665451,"mc":[{"id":"1.232013126","rc":[{"batb":[[0,1.9,16.5],[1,1.8,20.92],[2,1.75,20.62]],"ltp":2.02,"tv":1237.12,"id":35736915}]}]}
{"op":"mcm","clk":"11933082954","pt":1724618678753,"mc":[{"id":"1.232013126","rc":[{"batb":[[0,1.91,5],[1,1.9,16.5],[2,1.8,20.92]],"ltp":2.02,"tv":1237.12,"id":35736915}]}]}
{"op":"mcm","clk":"11933083264","pt":1724618682069,"mc":[{"id":"1.232013126","rc":[{"batb":[[0,1.9,16.5],[1,1.8,20.92],[2,1.75,20.62]],"ltp":2.02,"tv":1237.12,"id":35736915}]}]}
{"op":"mcm","clk":"11933083812","pt":1724618688567,"mc":[{"id":"1.232013126","rc":[{"batb":[[0,1.91,5],[1,1.9,16.5],[2,1.8,20.92]],"ltp":2.02,"tv":1237.12,"id":35736915}]}]}
{"op":"mcm","clk":"11933084104","pt":1724618692058,"mc":[{"id":"1.232013126","rc":[{"batb":[[0,1.9,16.5],[1,1.8,20.92],[2,1.75,20.62]],"ltp":2.02,"tv":1237.12,"id":35736915}]}]}
{"op":"mcm","clk":"11933085109","pt":1724618703010,"mc":[{"id":"1.232013126","rc":[{"batb":[[0,1.91,5],[1,1.9,16.5],[2,1.8,20.92]],"ltp":2.02,"tv":1237.12,"id":35736915}]}]}
{"op":"mcm","clk":"11933085388","pt":1724618706609,"mc":[{"id":"1.232013126","rc":[{"batb":[[0,1.9,16.5],[1,1.8,20.92],[2,1.75,20.62]],"ltp":2.02,"tv":1237.12,"id":35736915}]}]}
