{"op":"mcm","clk":"11810980459","pt":1723305141514,"mc":[{"id":"1.231664751","marketDefinition":{"bspMarket":false,"turnInPlayEnabled":true,"persistenceEnabled":true,"marketBaseRate":5.0,"eventId":"33483618","eventTypeId":"4","numberOfWinners":1,"bettingType":"ODDS","marketType":"MATCH_ODDS","marketTime":"2024-08-10T16:00:00.000Z","suspendTime":"2024-08-10T16:00:00.000Z","bspReconciled":false,"complete":true,"inPlay":false,"crossMatching":true,"runnersVoidable":false,"numberOfActiveRunners":2,"betDelay":0,"status":"OPEN","runners":[{"status":"ACTIVE","sortPriority":1,"id":25173012,"name":"Brampton Wolves"},{"status":"ACTIVE","sortPriority":2,"id":19144236,"name":"Toronto Nationals"}],"regulators":["MR_INT"],"countryCode":"GB","discountAllowed":false,"timezone":"GMT","openDate":"2024-08-10T16:00:00.000Z","version":6066760818,"name":"Match Odds","eventName":"Brampton Wolves v Toronto Nationals"},"rc":[{"batb":[[0,1.01,20]],"ltp":0.0,"tv":0.0,"id":19144236},{"batb":[[0,1.01,20]],"ltp":0.0,"tv":0.0,"id":25173012}]}]}
{"op":"mcm","clk":"11810980496","pt":1723305141731,"mc":[{"id":"1.231664751","rc":[{"batb":[[0,1.03,200],[1,1.02,200],[2,1.01,220]],"ltp":0.0,"tv":0.0,"id":19144236},{"batb":[[0,1.03,200],[1,1.02,200],[2,1.01,220]],"ltp":0.0,"tv":0.0,"id":25173012}]}]}
{"op":"mcm","clk":"11810980878","pt":1723305143710,"mc":[{"id":"1.231664751","marketDefinition":{"bspMarket":false,"turnInPlayEnabled":true,"persistenceEnabled":true,"marketBaseRate":5.0,"eventId":"33483618","eventTypeId":"4","numberOfWinners":1,"bettingType":"ODDS","marketType":"MATCH_ODDS","marketTime":"2024-08-10T16:00:00.000Z","suspendTime":"2024-08-10T16:00:00.000Z","bspReconciled":false,"complete":true,"inPlay":false,"crossMatching":true,"runnersVoidable":false,"numberOfActiveRunners":2,"betDelay":0,"status":"OPEN","runners":[{"status":"ACTIVE","sortPriority":1,"id":25173012,"name":"Brampton Wolves"},{"status":"ACTIVE","sortPriority":2,"id":19144236,"name":"Toronto Nationals"}],"regulators":["MR_INT"],"countryCode":"GB","discountAllowed":true,"timezone":"GMT","openDate":"2024-08-10T16:00:00.000Z","version":6066760818,"name":"Match Odds","eventName":"Brampton Wolves v Toronto Nationals"}}]}
{"op":"mcm","clk":"11810995330","pt":1723305213626,"mc":[{"id":"1.231664751","rc":[{"batb":[[0,1.03,2364.67],[1,1.02,3396.4],[2,1.01,6424.97]],"ltp":0.0,"tv":0.0,"id":25173012}]}]}
{"op":"mcm","clk":"11810995505","pt":1723305214484,"mc":[{"id":"1.231664751","rc":[{"batb":[[0,1.04,1635.51],[1,1.03,2364.67],[2,1.02,3396.4]],"ltp":0.0,"tv":0.0,"id":19144236},{"batb":[[0,1.04,1635.51],[1,1.03,2364.67],[2,1.02,3396.4]],"ltp":0.0,"tv":0.0,"id":25173012}]}]}
{"op":"mcm","clk":"11811024811","pt":1723305370659,"mc":[{"id":"1.231664751","rc":[{"batb":[[0,1.54,1851.85],[1,1.04,1635.51],[2,1.03,2364.67]],"ltp":0.0,"tv":0.0,"id":25173012}]}]}
{"op":"mcm","clk":"11811025270","pt":1723305373252,"mc":[{"id":"1.231664751","rc":[{"batb":[[1,1.37,2702.7],[2,1.04,1635.51]],"ltp":0.0,"tv":0.0,"id":25173012}]}]}
{"op":"mcm","clk":"11811031682","pt":1723305410403,"mc":[{"id":"1.231664751","rc":[{"batb":[[0,1.77,1298.7],[1,1.04,1635.51],[2,1.03,2364.67]],"ltp":0.0,"tv":0.0,"id":19144236}]}]}
{"op":"mcm","clk":"11811042100","pt":1723305472361,"mc":[{"id":"1.231664751","rc":[{"batl":[[0,2.26,36.48]],"ltp":0.0,"tv":0.0,"id":25173012}]}]}
{"op":"mcm","clk":"11811045177","pt":1723305490887,"mc":[{"id":"1.231664751","rc":[{"batl":[[0,2.22,36.48]],"ltp":0.0,"tv":0.0,"id":25173012}]}]}
{"op":"mcm","clk":"11811049213","pt":1723305515003,"mc":[{"id":"1.231664751","rc":[{"batb":[[0,1.54,1871.54]],"ltp":0.0,"tv":0.0,"id":25173012}]}]}
{"op":"mcm","clk":"11811051137","pt":1723305526627,"mc":[{"id":"1.231664751","rc":[{"batb":[[0,1.81,9.85],[1,1.77,1298.7],[2,1.04,1635.51]],"ltp":0.0,"tv":0.0,"id":19144236}]}]}
{"op":"mcm","clk":"11811051965","pt":1723305531120,"mc":[{"id":"1.231664751","rc":[{"trd":[[1.81,2.2]],"batb":[[0,1.81,8.75]],"ltp":1.81,"tv":2.19,"id":19144236}],"tv":2.19}]}
{"op":"mcm","clk":"11811054102","pt":1723305543211,"mc":[{"id":"1.231664751","rc":[{"batb":[[0,1.77,1298.7],[1,1.04,1635.51],[2,1.03,2364.67]],"ltp":1.81,"tv":2.19,"id":19144236}]}]}
{"op":"mcm","clk":"11811055546","pt":1723305551277,"mc":[{"id":"1.231664751","rc":[{"batb":[[1,1.37,2712.55]],"ltp":0.0,"tv":0.0,"id":25173012}]}]}
{"op":"mcm","clk":"11811055912","pt":1723305553240,"mc":[{"id":"1.231664751","rc":[{"trd":[[1.81,2.36]],"ltp":1.81,"tv":2.35,"id":19144236},{"trd":[[2.22,0.13]],"batl":[[0,2.22,36.35]],"ltp":2.22,"tv":0.13,"id":25173012}],"tv":2.49}]}
{"op":"mcm","clk":"11811057585","pt":1723305562170,"mc":[{"id":"1.231664751","rc":[{"batb":[[1,1.37,2702.7]],"ltp":2.22,"tv":0.13,"id":25173012}]}]}
{"op":"mcm","clk":"11811058232","pt":1723305565457,"mc":[{"id":"1.231664751","rc":[{"batb":[[0,1.81,9.85],[1,1.77,1298.7],[2,1.04,1635.51]],"ltp":1.81,"tv":2.35,"id":19144236}]}]}
{"op":"mcm","clk":"11811061998","pt":1723305586935,"mc":[{"id":"1.231664751","rc":[{"batb":[[0,1.77,1298.7],[1,1.04,1635.51],[2,1.03,2364.67]],"ltp":1.81,"tv":2.35,"id":19144236}]}]}
{"op":"mcm","clk":"11811062668","pt":1723305590591,"mc":[{"id":"1.231664751","rc":[{"trd":[[1.81,2.39]],"ltp":1.81,"tv":2.39,"id":19144236},{"trd":[[2.22,0.16]],"batl":[[0,2.22,36.32]],"ltp":2.22,"tv":0.16,"id":25173012}],"tv":2.55}]}
{"op":"mcm","clk":"11811065119","pt":1723305603343,"mc":[{"id":"1.231664751","rc":[{"batb":[[1,1.04,1733.97]],"ltp":1.81,"tv":2.39,"id":19144236}]}]}
{"op":"mcm","clk":"11811067239","pt":1723305613070,"mc":[{"id":"1.231664751","marketDefinition":{"bspMarket":false,"turnInPlayEnabled":true,"persistenceEnabled":true,"marketBaseRate":5.0,"eventId":"33483618","eventTypeId":"4","numberOfWinners":1,"bettingType":"ODDS","marketType":"MATCH_ODDS","marketTime":"2024-08-10T16:00:00.000Z","suspendTime":"2024-08-10T16:00:00.000Z","bspReconciled":false,"complete":true,"inPlay":true,"crossMatching":true,"runnersVoidable":false,"numberOfActiveRunners":2,"betDelay":5,"status":"OPEN","runners":[{"status":"ACTIVE","sortPriority":1,"id":25173012,"name":"Brampton Wolves"},{"status":"ACTIVE","sortPriority":2,"id":19144236,"name":"Toronto Nationals"}],"regulators":["MR_INT"],"countryCode":"GB","discountAllowed":true,"timezone":"GMT","openDate":"2024-08-10T16:00:00.000Z","version":6066831970,"name":"Match Odds","eventName":"Brampton Wolves v Toronto Nationals"},"rc":[{"batb":[[1,1.04,1635.51]],"ltp":1.81,"tv":2.39,"id":19144236},{"batb":[[0,1.54,1851.85]],"ltp":2.22,"tv":0.16,"id":25173012}]}]}
{"op":"mcm","clk":"11811073309","pt":1723305643214,"mc":[{"id":"1.231664751","rc":[{"batl":[[0,1.55,1.02]],"ltp":2.22,"tv":0.16,"id":25173012}]}]}
{"op":"mcm","clk":"11811075584","pt":1723305654737,"mc":[{"id":"1.231664751","rc":[{"batb":[[0,1.55,1818.18],[1,1.54,1851.85],[2,1.37,2702.7]],"ltp":2.22,"tv":0.16,"id":25173012}]}]}
{"op":"mcm","clk":"11811076017","pt":1723305657025,"mc":[{"id":"1.231664751","rc":[{"batb":[[0,1.55,1819.13]],"ltp":2.22,"tv":0.16,"id":25173012}]}]}
{"op":"mcm","clk":"11811076147","pt":1723305657762,"mc":[{"id":"1.231664751","rc":[{"batb":[[0,1.57,190.45],[1,1.55,1819.13],[2,1.54,1851.85]],"ltp":2.22,"tv":0.16,"id":25173012}]}]}
{"op":"mcm","clk":"11811083446","pt":1723305691383,"mc":[{"id":"1.231664751","rc":[{"batb":[[0,1.6,2.03],[1,1.57,190.45],[2,1.55,1819.13]],"ltp":2.22,"tv":0.16,"id":25173012}]}]}
{"op":"mcm","clk":"11811084258","pt":1723305695173,"mc":[{"id":"1.231664751","rc":[{"batl":[[0,1.79,1.02]],"ltp":1.81,"tv":2.39,"id":19144236}]}]}
{"op":"mcm","clk":"11811086893","pt":1723305708163,"mc":[{"id":"1.231664751","rc":[{"batb":[[0,1.79,1.98],[1,1.77,1298.7],[2,1.04,1635.51]],"ltp":1.81,"tv":2.39,"id":19144236}]}]}
{"op":"mcm","clk":"11811087648","pt":1723305712172,"mc":[{"id":"1.231664751","rc":[{"batb":[[2,1.55,1818.18]],"ltp":2.22,"tv":0.16,"id":25173012}]}]}
{"op":"mcm","clk":"11811090798","pt":1723305728397,"mc":[{"id":"1.231664751","rc":[{"batl":[[0,2.7,1.73]],"ltp":1.81,"tv":2.39,"id":19144236}]}]}
{"op":"mcm","clk":"11811091221","pt":1723305730689,"mc":[{"id":"1.231664751","rc":[{"batl":[[0,2.22,36.48]],"ltp":2.22,"tv":0.16,"id":25173012}]}]}
{"op":"mcm","clk":"11811092604","pt":1723305737876,"mc":[{"id":"1.231664751","rc":[{"batb":[[0,1.57,190.45],[1,1.55,1818.18],[2,1.54,1851.85]],"ltp":2.22,"tv":0.16,"id":25173012}]}]}
{"op":"mcm","clk":"11811095455","pt":1723305751467,"mc":[{"id":"1.231664751","rc":[{"trd":[[1.81,8.05]],"ltp":1.81,"tv":8.04,"id":19144236},{"trd":[[2.22,4.77]],"batl":[[0,2.22,31.87]],"ltp":2.22,"tv":4.77,"id":25173012}],"tv":12.81}]}
{"op":"mcm","clk":"11811098315","pt":1723305765353,"mc":[{"id":"1.231664751","rc":[{"batb":[[0,1.62,13.26],[1,1.57,190.45],[2,1.55,1818.18]],"ltp":2.22,"tv":4.77,"id":25173012}]}]}
{"op":"mcm","clk":"11811099771","pt":1723305772548,"mc":[{"id":"1.231664751","rc":[{"batb":[[1,1.55,1818.18],[2,1.54,1851.85]],"ltp":2.22,"tv":4.77,"id":25173012}]}]}
{"op":"mcm","clk":"11811101628","pt":1723305782399,"mc":[{"id":"1.231664751","rc":[{"batb":[[0,1.62,14.22]],"ltp":2.22,"tv":4.77,"id":25173012}]}]}
{"op":"mcm","clk":"11811103029","pt":1723305789411,"mc":[{"id":"1.231664751","rc":[{"batb":[[0,1.63,10.84],[1,1.62,13.26],[2,1.55,1818.18]],"ltp":2.22,"tv":4.77,"id":25173012}]}]}
{"op":"mcm","clk":"11811106477","pt":1723305805619,"mc":[{"id":"1.231664751","rc":[{"trd":[[1.81,8.94]],"ltp":1.81,"tv":8.93,"id":19144236},{"trd":[[2.22,5.5]],"batl":[[0,2.22,31.15]],"ltp":2.22,"tv":5.49,"id":25173012}],"tv":14.43}]}
{"op":"mcm","clk":"11811107014","pt":1723305808321,"mc":[{"id":"1.231664751","rc":[{"batl":[[0,1.67,1.02],[1,2.22,31.15]],"ltp":2.22,"tv":5.49,"id":25173012}]}]}
{"op":"mcm","clk":"11811107651","pt":1723305811404,"mc":[{"id":"1.231664751","rc":[{"batb":[[0,1.63,9.88]],"ltp":2.22,"tv":5.49,"id":25173012}]}]}
{"op":"mcm","clk":"11811108694","pt":1723305816528,"mc":[{"id":"1.231664751","rc":[{"trd":[[1.67,1.92]],"batl":[[0,2.22,31.21],[1,2.22,0]],"ltp":1.67,"tv":7.41,"id":25173012}],"tv":16.34}]}
{"op":"mcm","clk":"11811108940","pt":1723305817613,"mc":[{"id":"1.231664751","rc":[{"batl":[[0,2.22,31.15]],"ltp":1.67,"tv":7.41,"id":25173012}]}]}
{"op":"mcm","clk":"11811111349","pt":1723305829446,"mc":[{"id":"1.231664751","rc":[{"trd":[[1.81,9.82]],"ltp":1.81,"tv":9.81,"id":19144236},{"trd":[[2.22,6.21]],"batl":[[0,2.22,30.43]],"ltp":2.22,"tv":8.13,"id":25173012}],"tv":17.94}]}
{"op":"mcm","clk":"11811111965","pt":1723305832342,"mc":[{"id":"1.231664751","rc":[{"batl":[[0,2.22,31.39]],"ltp":2.22,"tv":8.13,"id":25173012}]}]}
{"op":"mcm","clk":"11811116123","pt":1723305851723,"mc":[{"id":"1.231664751","rc":[{"batl":[[0,1.65,1.02],[1,2.22,31.39]],"ltp":2.22,"tv":8.13,"id":25173012}]}]}
{"op":"mcm","clk":"11811116717","pt":1723305854336,"mc":[{"id":"1.231664751","rc":[{"trd":[[1.65,1.92]],"batl":[[0,2,1.02],[1,2.22,30.43]],"ltp":1.65,"tv":10.04,"id":25173012}],"tv":19.86}]}
{"op":"mcm","clk":"11811117630","pt":1723305858545,"mc":[{"id":"1.231664751","rc":[{"batl":[[0,2.22,31.39],[1,2.22,0]],"ltp":1.65,"tv":10.04,"id":25173012}]}]}
{"op":"mcm","clk":"11811120438","pt":1723305871351,"mc":[{"id":"1.231664751","rc":[{"batl":[[0,2,1.92],[1,2.22,30.43]],"ltp":1.65,"tv":10.04,"id":25173012}]}]}
{"op":"mcm","clk":"11811120673","pt":1723305872469,"mc":[{"id":"1.231664751","rc":[{"batb":[[0,1.63,29.57]],"ltp":1.65,"tv":10.04,"id":25173012}]}]}
{"op":"mcm","clk":"11811120768","pt":1723305872845,"mc":[{"id":"1.231664751","rc":[{"batl":[[0,1.65,1.02],[1,2,1.92],[2,2.22,30.43]],"ltp":1.65,"tv":10.04,"id":25173012}]}]}
{"op":"mcm","clk":"11811122209","pt":1723305879555,"mc":[{"id":"1.231664751","rc":[{"batl":[[0,2,1.92],[1,2.22,30.43],[2,2.22,0]],"ltp":1.65,"tv":10.04,"id":25173012}]}]}
{"op":"mcm","clk":"11811123065","pt":1723305883579,"mc":[{"id":"1.231664751","rc":[{"batb":[[0,1.65,13.26],[1,1.63,19.69],[2,1.62,13.26]],"ltp":1.65,"tv":10.04,"id":25173012}]}]}
{"op":"mcm","clk":"11811123283","pt":1723305884481,"mc":[{"id":"1.231664751","rc":[{"batb":[[0,1.65,14.22]],"ltp":1.65,"tv":10.04,"id":25173012}]}]}
{"op":"mcm","clk":"11811124244","pt":1723305888578,"mc":[{"id":"1.231664751","rc":[{"trd":[[2,1.92]],"batl":[[0,2,98.08],[1,2.7,1.73]],"ltp":2.0,"tv":11.73,"id":19144236},{"trd":[[2,1.92]],"batb":[[2,1.55,1818.18]],"batl":[[0,2.22,30.43],[1,2.22,0]],"ltp":2.0,"tv":11.96,"id":25173012}],"tv":23.7}]}
{"op":"mcm","clk":"11811125207","pt":1723305893016,"mc":[{"id":"1.231664751","rc":[{"batb":[[1,1.55,1818.18],[2,1.54,1851.85]],"ltp":2.0,"tv":11.96,"id":25173012}]}]}
{"op":"mcm","clk":"11811126247","pt":1723305897491,"mc":[{"id":"1.231664751","rc":[{"batl":[[0,2.7,1.73],[1,2.7,0]],"ltp":2.0,"tv":11.73,"id":19144236}]}]}
{"op":"mcm","clk":"11811126665","pt":1723305899401,"mc":[{"id":"1.231664751","rc":[{"batb":[[0,1.65,33.91]],"ltp":2.0,"tv":11.96,"id":25173012}]}]}
{"op":"mcm","clk":"11811131134","pt":1723305919494,"mc":[{"id":"1.231664751","rc":[{"batb":[[0,1.68,12.31],[1,1.65,33.91],[2,1.55,1818.18]],"batl":[[0,2,17],[1,2.22,30.43]],"ltp":2.0,"tv":11.96,"id":25173012}]}]}
{"op":"mcm","clk":"11811132645","pt":1723305925724,"mc":[{"id":"1.231664751","rc":[{"batb":[[0,1.65,33.91],[1,1.55,1818.18],[2,1.54,1851.85]],"ltp":2.0,"tv":11.96,"id":25173012}]}]}
{"op":"mcm","clk":"11811132928","pt":1723305926822,"mc":[{"id":"1.231664751","rc":[{"batb":[[0,1.65,52.99]],"ltp":2.0,"tv":11.96,"id":25173012}]}]}
{"op":"mcm","clk":"11811133774","pt":1723305930447,"mc":[{"id":"1.231664751","rc":[{"batb":[[0,1.65,52.03]],"ltp":2.0,"tv":11.96,"id":25173012}]}]}
{"op":"mcm","clk":"11811134457","pt":1723305933327,"mc":[{"id":"1.231664751","rc":[{"trd":[[2,35.92]],"batb":[[0,2,63],[1,1.65,52.03],[2,1.55,1818.18]],"batl":[[0,2.22,30.43],[1,2.22,0]],"ltp":2.0,"tv":45.96,"id":25173012}],"tv":57.7}]}
{"op":"mcm","clk":"11811134915","pt":1723305935546,"mc":[{"id":"1.231664751","rc":[{"batb":[[1,1.65,52.99]],"ltp":2.0,"tv":45.96,"id":25173012}]}]}
{"op":"mcm","clk":"11811135439","pt":1723305938034,"mc":[{"id":"1.231664751","rc":[{"batb":[[1,1.98,1.02],[2,1.65,52.99]],"ltp":2.0,"tv":45.96,"id":25173012}]}]}
{"op":"mcm","clk":"11811136194","pt":1723305941541,"mc":[{"id":"1.231664751","rc":[{"batb":[[1,1.65,52.99],[2,1.55,1818.18]],"ltp":2.0,"tv":45.96,"id":25173012}]}]}
{"op":"mcm","clk":"11811136812","pt":1723305944423,"mc":[{"id":"1.231664751","rc":[{"batb":[[1,1.65,52.03]],"ltp":2.0,"tv":45.96,"id":25173012}]}]}
{"op":"mcm","clk":"11811137977","pt":1723305949531,"mc":[{"id":"1.231664751","rc":[{"trd":[[2.22,6.8]],"batl":[[0,2.22,30.14]],"ltp":2.22,"tv":46.55,"id":25173012}],"tv":58.29}]}
{"op":"mcm","clk":"11811140072","pt":1723305959371,"mc":[{"id":"1.231664751","rc":[{"batb":[[1,1.65,38.76]],"ltp":2.22,"tv":46.55,"id":25173012}]}]}
{"op":"mcm","clk":"11811140377","pt":1723305960753,"mc":[{"id":"1.231664751","rc":[{"batl":[[0,1.9,200],[1,2.7,1.73]],"ltp":2.0,"tv":11.73,"id":19144236}]}]}
{"op":"mcm","clk":"11811143359","pt":1723305973482,"mc":[{"id":"1.231664751","rc":[{"trd":[[1.9,13.26]],"batl":[[0,1.9,193.37]],"ltp":1.9,"tv":24.99,"id":19144236}],"tv":71.55}]}
{"op":"mcm","clk":"11811144144","pt":1723305976670,"mc":[{"id":"1.231664751","rc":[{"batb":[[0,1.79,2.94]],"ltp":1.9,"tv":24.99,"id":19144236}]}]}
{"op":"mcm","clk":"11811144715","pt":1723305978995,"mc":[{"id":"1.231664751","rc":[{"batl":[[1,2.1,17],[2,2.7,1.73]],"ltp":1.9,"tv":24.99,"id":19144236}]}]}
{"op":"mcm","clk":"11811145496","pt":1723305982367,"mc":[{"id":"1.231664751","rc":[{"batb":[[0,1.79,1.98]],"ltp":1.9,"tv":24.99,"id":19144236}]}]}
{"op":"mcm","clk":"11811146678","pt":1723305987466,"mc":[{"id":"1.231664751","rc":[{"batb":[[0,1.79,2.94]],"ltp":1.9,"tv":24.99,"id":19144236}]}]}
{"op":"mcm","clk":"11811148762","pt":1723305996409,"mc":[{"id":"1.231664751","rc":[{"trd":[[1.81,12.87],[1.83,1.92]],"batb":[[0,1.79,1.98]],"ltp":1.81,"tv":29.97,"id":19144236},{"trd":[[2.22,9.29]],"batl":[[0,2.22,27.65]],"ltp":2.22,"tv":49.04,"id":25173012}],"tv":79.01}]}
{"op":"mcm","clk":"11811152064","pt":1723306010690,"mc":[{"id":"1.231664751","rc":[{"batl":[[0,1.9,194.33]],"ltp":1.81,"tv":29.97,"id":19144236}]}]}
{"op":"mcm","clk":"11811154830","pt":1723306023527,"mc":[{"id":"1.231664751","rc":[{"trd":[[1.88,0.96],[1.9,14.33]],"batl":[[0,1.9,192.3]],"ltp":1.9,"tv":32.0,"id":19144236},{"trd":[[2.1,0.97],[2.12,0.85]],"ltp":2.1,"tv":50.86,"id":25173012}],"tv":82.86}]}
{"op":"mcm","clk":"11811155787","pt":1723306027720,"mc":[{"id":"1.231664751","rc":[{"trd":[[1.81,12.92]],"ltp":1.81,"tv":32.05,"id":19144236},{"trd":[[2.22,9.34]],"batl":[[0,2.22,27.6]],"ltp":2.22,"tv":50.91,"id":25173012}],"tv":82.96}]}
{"op":"mcm","clk":"11811156564","pt":1723306031226,"mc":[{"id":"1.231664751","rc":[{"trd":[[1.81,13.8]],"ltp":1.81,"tv":32.92,"id":19144236},{"trd":[[2.22,10.05]],"batl":[[0,2.22,26.89]],"ltp":2.22,"tv":51.62,"id":25173012}],"tv":84.54}]}
{"op":"mcm","clk":"11811156839","pt":1723306032453,"mc":[{"id":"1.231664751","rc":[{"batb":[[0,1.77,1298.7],[1,1.04,1635.51],[2,1.03,2364.67]],"ltp":1.81,"tv":32.92,"id":19144236}]}]}
{"op":"mcm","clk":"11811158910","pt":1723306041354,"mc":[{"id":"1.231664751","rc":[{"trd":[[1.9,14.39]],"batl":[[0,1.9,192.27]],"ltp":1.9,"tv":32.98,"id":19144236}],"tv":84.6}]}
{"op":"mcm","clk":"11811159049","pt":1723306042047,"mc":[{"id":"1.231664751","rc":[{"trd":[[1.9,124.92]],"batl":[[0,1.9,81.74]],"ltp":1.9,"tv":143.51,"id":19144236},{"trd":[[2.1,100.97]],"ltp":2.1,"tv":151.62,"id":25173012}],"tv":295.13}]}
{"op":"mcm","clk":"11811160165","pt":1723306046806,"mc":[{"id":"1.231664751","rc":[{"batl":[[0,1.87,90.41],[1,1.9,81.74],[2,2.1,17]],"ltp":1.9,"tv":143.51,"id":19144236}]}]}
{"op":"mcm","clk":"11811161060","pt":1723306050641,"mc":[{"id":"1.231664751","rc":[{"trd":[[1.81,13.86]],"ltp":1.81,"tv":143.57,"id":19144236},{"trd":[[2.22,10.1]],"batl":[[0,2.22,26.84]],"ltp":2.22,"tv":151.67,"id":25173012}],"tv":295.24}]}
{"op":"mcm","clk":"11811162125","pt":1723306055109,"mc":[{"id":"1.231664751","rc":[{"trd":[[1.81,46.78]],"batb":[[0,1.04,1635.51],[1,1.03,2164.67],[2,1.02,3196.4]],"batl":[[0,1.81,127.08],[1,1.87,90.41],[2,1.9,81.74]],"ltp":1.81,"tv":176.49,"id":19144236},{"trd":[[2.22,36.94]],"ltp":2.22,"tv":178.51,"id":25173012}],"tv":355.0}]}
{"op":"mcm","clk":"11811162780","pt":1723306057758,"mc":[{"id":"1.231664751","rc":[{"batl":[[0,1.87,90.41],[1,1.9,81.74],[2,2.1,17]],"ltp":1.81,"tv":176.49,"id":19144236}]}]}
{"op":"mcm","clk":"11811163254","pt":1723306059843,"mc":[{"id":"1.231664751","rc":[{"batb":[[0,1.69,1298.7],[1,1.04,1635.51],[2,1.03,2164.67]],"ltp":1.81,"tv":176.49,"id":19144236}]}]}
{"op":"mcm","clk":"11811163777","pt":1723306062140,"mc":[{"id":"1.231664751","rc":[{"batb":[[1,1.65,39.49]],"ltp":2.22,"tv":178.51,"id":25173012}]}]}
{"op":"mcm","clk":"11811164293","pt":1723306064463,"mc":[{"id":"1.231664751","rc":[{"batb":[[0,1.04,1635.51],[1,1.03,2164.67],[2,1.02,3196.4]],"ltp":1.81,"tv":176.49,"id":19144236}]}]}
{"op":"mcm","clk":"11811165538","pt":1723306069540,"mc":[{"id":"1.231664751","rc":[{"batb":[[0,1.59,1298.7],[1,1.04,1635.51],[2,1.03,2164.67]],"ltp":1.81,"tv":176.49,"id":19144236}]}]}
{"op":"mcm","clk":"11811167210","pt":1723306076347,"mc":[{"id":"1.231664751","rc":[{"batb":[[1,1.44,3.64],[2,1.04,1635.51]],"ltp":1.81,"tv":176.49,"id":19144236}]}]}
{"op":"mcm","clk":"11811167469","pt":1723306077466,"mc":[{"id":"1.231664751","rc":[{"batb":[[2,1.06,2.65]],"ltp":1.81,"tv":176.49,"id":19144236}]}]}
{"op":"mcm","clk":"11811168893","pt":1723306083358,"mc":[{"id":"1.231664751","rc":[{"batl":[[0,20,1.82]],"ltp":2.22,"tv":178.51,"id":25173012}]}]}
{"op":"mcm","clk":"11811171321","pt":1723306093358,"mc":[{"id":"1.231664751","rc":[{"batb":[[0,1.59,1299.66]],"ltp":1.81,"tv":176.49,"id":19144236}]}]}
{"op":"mcm","clk":"11811171821","pt":1723306095585,"mc":[{"id":"1.231664751","rc":[{"trd":[[1.87,0.63]],"batl":[[0,1.87,90.1]],"ltp":1.87,"tv":177.12,"id":19144236}],"tv":355.64}]}
{"op":"mcm","clk":"11811172303","pt":1723306097567,"mc":[{"id":"1.231664751","rc":[{"batb":[[0,1.61,120.96],[1,1.59,1298.7],[2,1.44,3.64]],"ltp":1.87,"tv":177.12,"id":19144236}]}]}
{"op":"mcm","clk":"11811173821","pt":1723306103788,"mc":[{"id":"1.231664751","rc":[{"batb":[[0,1.61,120]],"ltp":1.87,"tv":177.12,"id":19144236}]}]}
{"op":"mcm","clk":"11811175079","pt":1723306108476,"mc":[{"id":"1.231664751","rc":[{"batb":[[0,1.61,139]],"ltp":1.87,"tv":177.12,"id":19144236}]}]}
{"op":"mcm","clk":"11811175171","pt":1723306108901,"mc":[{"id":"1.231664751","rc":[{"batb":[[0,1.61,139.96]],"ltp":1.87,"tv":177.12,"id":19144236}]}]}
{"op":"mcm","clk":"11811176417","pt":1723306113892,"mc":[{"id":"1.231664751","rc":[{"batb":[[1,1.65,19.8]],"ltp":2.22,"tv":178.51,"id":25173012}]}]}
{"op":"mcm","clk":"11811177031","pt":1723306116395,"mc":[{"id":"1.231664751","rc":[{"trd":[[1.87,1.68]],"batl":[[0,1.87,89.05]],"ltp":1.87,"tv":178.17,"id":19144236},{"trd":[[2.14,0.91]],"ltp":2.14,"tv":179.42,"id":25173012}],"tv":357.59}]}
{"op":"mcm","clk":"11811178248","pt":1723306121509,"mc":[{"id":"1.231664751","rc":[{"batb":[[0,1.61,159.65]],"ltp":1.87,"tv":178.17,"id":19144236},{"batb":[[0,2.02,4],[1,2,63],[2,1.65,19.8]],"ltp":2.14,"tv":179.42,"id":25173012}]}]}
{"op":"mcm","clk":"11811178791","pt":1723306123706,"mc":[{"id":"1.231664751","rc":[{"batb":[[0,2,63],[1,1.65,19.8],[2,1.55,1818.18]],"ltp":2.14,"tv":179.42,"id":25173012}]}]}
{"op":"mcm","clk":"11811179220","pt":1723306125501,"mc":[{"id":"1.231664751","rc":[{"batl":[[0,1.87,90.01],[1,2.1,17],[2,2.7,1.73]],"ltp":1.87,"tv":178.17,"id":19144236}]}]}
{"op":"mcm","clk":"11811179994","pt":1723306128894,"mc":[{"id":"1.231664751","rc":[{"batl":[[0,1.65,1.02],[1,1.87,90.01],[2,2.1,17]],"ltp":1.87,"tv":178.17,"id":19144236}]}]}
{"op":"mcm","clk":"11811180444","pt":1723306130603,"mc":[{"id":"1.231664751","rc":[{"batl":[[1,1.86,82.7],[2,1.87,89.05]],"ltp":1.87,"tv":178.17,"id":19144236}]}]}
{"op":"mcm","clk":"11811181323","pt":1723306134413,"mc":[{"id":"1.231664751","rc":[{"batb":[[0,1.61,158.69]],"ltp":1.87,"tv":178.17,"id":19144236}]}]}
{"op":"mcm","clk":"11811182104","pt":1723306137712,"mc":[{"id":"1.231664751","rc":[{"batl":[[0,1.86,82.7],[1,1.87,89.05],[2,2.1,17]],"ltp":1.87,"tv":178.17,"id":19144236}]}]}
{"op":"mcm","clk":"11811182482","pt":1723306139523,"mc":[{"id":"1.231664751","rc":[{"batb":[[0,1.61,159.65]],"ltp":1.87,"tv":178.17,"id":19144236}]}]}
{"op":"mcm","clk":"11811184221","pt":1723306146716,"mc":[{"id":"1.231664751","rc":[{"batl":[[0,1.86,81.74]],"ltp":1.87,"tv":178.17,"id":19144236}]}]}
{"op":"mcm","clk":"11811185075","pt":1723306150420,"mc":[{"id":"1.231664751","rc":[{"batl":[[0,1.83,506.73],[1,1.86,81.74],[2,1.87,89.05]],"ltp":1.87,"tv":178.17,"id":19144236}]}]}
{"op":"mcm","clk":"11811185457","pt":1723306151814,"mc":[{"id":"1.231664751","rc":[{"batl":[[1,1.86,82.7]],"ltp":1.87,"tv":178.17,"id":19144236}]}]}
{"op":"mcm","clk":"11811190263","pt":1723306171350,"mc":[{"id":"1.231664751","rc":[{"trd":[[1.83,9.88]],"batl":[[0,1.82,44.71],[1,1.83,502.75],[2,1.86,82.7]],"ltp":1.83,"tv":186.13,"id":19144236}],"tv":365.55}]}
{"op":"mcm","clk":"11811190641","pt":1723306172853,"mc":[{"id":"1.231664751","rc":[{"batb":[[0,1.65,2.06],[1,1.61,158.69],[2,1.59,1298.7]],"ltp":1.83,"tv":186.13,"id":19144236}]}]}
{"op":"mcm","clk":"11811196768","pt":1723306198353,"mc":[{"id":"1.231664751","rc":[{"batb":[[1,1.61,139]],"ltp":1.83,"tv":186.13,"id":19144236}]}]}
{"op":"mcm","clk":"11811197195","pt":1723306200174,"mc":[{"id":"1.231664751","rc":[{"batl":[[0,1.81,93.6],[1,1.82,44.71],[2,1.83,502.75]],"ltp":1.83,"tv":186.13,"id":19144236}]}]}
{"op":"mcm","clk":"11811197772","pt":1723306202369,"mc":[{"id":"1.231664751","rc":[{"trd":[[1.81,48.82]],"batl":[[0,1.81,92.58]],"ltp":1.81,"tv":188.17,"id":19144236}],"tv":367.59}]}
{"op":"mcm","clk":"11811198582","pt":1723306205684,"mc":[{"id":"1.231664751","rc":[{"batb":[[0,1.65,21.75]],"ltp":1.81,"tv":188.17,"id":19144236}]}]}
{"op":"mcm","clk":"11811198682","pt":1723306206062,"mc":[{"id":"1.231664751","rc":[{"trd":[[1.81,205.9]],"batl":[[0,1.81,14.04]],"ltp":1.81,"tv":345.25,"id":19144236}],"tv":524.68}]}
{"op":"mcm","clk":"11811201332","pt":1723306216582,"mc":[{"id":"1.231664751","rc":[{"trd":[[1.65,2.25]],"batb":[[0,1.65,20.62]],"ltp":1.65,"tv":347.5,"id":19144236}],"tv":526.92}]}
{"op":"mcm","clk":"11811204612","pt":1723306229699,"mc":[{"id":"1.231664751","rc":[{"batb":[[0,1.68,145.6],[1,1.65,20.62],[2,1.61,139]],"ltp":1.65,"tv":347.5,"id":19144236}]}]}
{"op":"mcm","clk":"11811205811","pt":1723306234430,"mc":[{"id":"1.231664751","rc":[{"trd":[[1.68,235.62]],"batb":[[0,1.68,27.79]],"ltp":1.68,"tv":583.12,"id":19144236}],"tv":762.55}]}
{"op":"mcm","clk":"11811206112","pt":1723306235616,"mc":[{"id":"1.231664751","rc":[{"trd":[[1.78,1.92]],"batb":[[0,1.68,27.85]],"ltp":1.78,"tv":585.04,"id":19144236}],"tv":764.47}]}
{"op":"mcm","clk":"11811207420","pt":1723306240638,"mc":[{"id":"1.231664751","rc":[{"batb":[[0,1.68,27.79]],"ltp":1.78,"tv":585.04,"id":19144236}]}]}
{"op":"mcm","clk":"11811208394","pt":1723306244330,"mc":[{"id":"1.231664751","rc":[{"trd":[[1.68,267.04]],"batb":[[0,1.68,12.08]],"ltp":1.68,"tv":616.46,"id":19144236}],"tv":795.88}]}
{"op":"mcm","clk":"11811209493","pt":1723306248551,"mc":[{"id":"1.231664751","rc":[{"trd":[[1.81,206.04]],"batl":[[0,1.81,13.97]],"ltp":1.81,"tv":616.6,"id":19144236}],"tv":796.02}]}
{"op":"mcm","clk":"11811209682","pt":1723306249283,"mc":[{"id":"1.231664751","rc":[{"trd":[[1.68,269.07]],"batb":[[0,1.68,11.07]],"ltp":1.68,"tv":618.62,"id":19144236}],"tv":798.05}]}
{"op":"mcm","clk":"11811217304","pt":1723306278894,"mc":[{"id":"1.231664751","rc":[{"batb":[[0,1.79,1.02],[1,1.68,11.07],[2,1.65,20.62]],"ltp":1.68,"tv":618.62,"id":19144236}]}]}
{"op":"mcm","clk":"11811218649","pt":1723306284592,"mc":[{"id":"1.231664751","rc":[{"batb":[[0,1.68,11.07],[1,1.65,20.62],[2,1.61,139]],"ltp":1.68,"tv":618.62,"id":19144236}]}]}
{"op":"mcm","clk":"11811236339","pt":1723306358712,"mc":[{"id":"1.231664751","rc":[{"batb":[[0,1.65,19.8],[1,1.55,1818.18],[2,1.54,1851.85]],"ltp":2.14,"tv":179.42,"id":25173012}]}]}
{"op":"mcm","clk":"11811237764","pt":1723306364923,"mc":[{"id":"1.231664751","rc":[{"trd":[[1.68,291.21]],"batb":[[0,1.65,20.62],[1,1.61,139],[2,1.59,1298.7]],"batl":[[0,1.68,1.93],[1,1.81,13.97],[2,1.82,44.71]],"ltp":1.68,"tv":640.76,"id":19144236}],"tv":820.19}]}
{"op":"mcm","clk":"11811239648","pt":1723306373215,"mc":[{"id":"1.231664751","rc":[{"trd":[[1.68,291.37]],"batl":[[0,1.68,1.85]],"ltp":1.68,"tv":640.92,"id":19144236}],"tv":820.35}]}
{"op":"mcm","clk":"11811253991","pt":1723306377728,"mc":[{"id":"1.231664751","rc":[{"trd":[[1.68,293.29]],"batl":[[0,1.81,14.86],[1,1.82,44.71],[2,1.83,502.75]],"ltp":1.68,"tv":642.84,"id":19144236}],"tv":822.27}]}
{"op":"mcm","clk":"11811257063","pt":1723306391351,"mc":[{"id":"1.231664751","rc":[{"batl":[[0,1.78,1.85],[1,1.81,13.97],[2,1.82,44.71]],"ltp":1.68,"tv":642.84,"id":19144236}]}]}
{"op":"mcm","clk":"11811261334","pt":1723306409571,"mc":[{"id":"1.231664751","rc":[{"batl":[[0,1.81,14.94],[1,1.82,44.71],[2,1.83,502.75]],"ltp":1.68,"tv":642.84,"id":19144236}]}]}
{"op":"mcm","clk":"11811262512","pt":1723306414586,"mc":[{"id":"1.231664751","rc":[{"batl":[[0,1.76,1.81],[1,1.81,14.05],[2,1.82,44.71]],"ltp":1.68,"tv":642.84,"id":19144236}]}]}
{"op":"mcm","clk":"11811263972","pt":1723306420601,"mc":[{"id":"1.231664751","rc":[{"batb":[[0,1.55,1818.91],[1,1.54,1851.85],[2,1.37,2702.7]],"ltp":2.14,"tv":179.42,"id":25173012}]}]}
{"op":"mcm","clk":"11811265638","pt":1723306427654,"mc":[{"id":"1.231664751","rc":[{"batb":[[0,1.66,41.47],[1,1.65,20.62],[2,1.61,139]],"ltp":1.68,"tv":642.84,"id":19144236}]}]}
{"op":"mcm","clk":"11811267423","pt":1723306435117,"mc":[{"id":"1.231664751","rc":[{"batb":[[0,1.65,20.62],[1,1.61,139],[2,1.59,1298.7]],"ltp":1.68,"tv":642.84,"id":19144236}]}]}
{"op":"mcm","clk":"11811270726","pt":1723306448436,"mc":[{"id":"1.231664751","rc":[{"batb":[[0,1.55,1818.96]],"ltp":2.14,"tv":179.42,"id":25173012}]}]}
{"op":"mcm","clk":"11811272512","pt":1723306456478,"mc":[{"id":"1.231664751","rc":[{"trd":[[1.68,295.07]],"batb":[[0,1.7,38.15],[1,1.65,20.62],[2,1.61,139]],"batl":[[0,1.77,1],[1,1.81,13.97]],"ltp":1.68,"tv":644.62,"id":19144236}],"tv":824.05}]}
{"op":"mcm","clk":"11811275038","pt":1723306467007,"mc":[{"id":"1.231664751","rc":[{"trd":[[1.76,1.91],[1.77,0.16],[1.81,233.98]],"batb":[[0,1.81,39.94],[1,1.7,38.15],[2,1.65,20.62]],"batl":[[0,1.82,44.71],[1,1.83,502.75],[2,1.87,89.05]],"ltp":1.81,"tv":674.63,"id":19144236},{"trd":[[2.32,0.05]],"batb":[[0,1.55,1818.91]],"ltp":2.32,"tv":179.47,"id":25173012}],"tv":854.11}]}
{"op":"mcm","clk":"11811276030","pt":1723306471106,"mc":[{"id":"1.231664751","rc":[{"trd":[[1.81,254.78]],"batb":[[0,1.81,29.54]],"ltp":1.81,"tv":695.43,"id":19144236}],"tv":874.91}]}
{"op":"mcm","clk":"11811276281","pt":1723306472113,"mc":[{"id":"1.231664751","rc":[{"trd":[[1.81,269.99]],"batb":[[0,1.81,21.94]],"ltp":1.81,"tv":710.63,"id":19144236}],"tv":890.11}]}
{"op":"mcm","clk":"11811276534","pt":1723306473190,"mc":[{"id":"1.231664751","rc":[{"batb":[[0,1.7,38.15],[1,1.65,20.62],[2,1.59,1298.7]],"ltp":1.81,"tv":710.63,"id":19144236}]}]}
{"op":"mcm","clk":"11811278079","pt":1723306479922,"mc":[{"id":"1.231664751","rc":[{"batb":[[0,1.55,1818.18]],"ltp":2.32,"tv":179.47,"id":25173012}]}]}
{"op":"mcm","clk":"11811278794","pt":1723306482670,"mc":[{"id":"1.231664751","rc":[{"batb":[[0,1.65,20.62],[1,1.59,1298.7],[2,1.04,1635.51]],"batl":[[0,1.81,157.08],[1,1.82,44.71],[2,1.83,502.75]],"ltp":1.81,"tv":710.63,"id":19144236}]}]}
{"op":"mcm","clk":"11811282302","pt":1723306497410,"mc":[{"id":"1.231664751","rc":[{"batb":[[0,1.7,36.06],[1,1.65,20.62],[2,1.59,1298.7]],"ltp":1.81,"tv":710.63,"id":19144236},{"batl":[[0,2.46,0.05]],"ltp":2.32,"tv":179.47,"id":25173012}]}]}
{"op":"mcm","clk":"11811285831","pt":1723306511224,"mc":[{"id":"1.231664751","rc":[{"trd":[[1.81,270.11]],"batl":[[0,1.81,156.96]],"ltp":1.81,"tv":710.76,"id":19144236},{"trd":[[2.22,37.04]],"ltp":2.22,"tv":179.57,"id":25173012}],"tv":890.33}]}
{"op":"mcm","clk":"11811287862","pt":1723306519720,"mc":[{"id":"1.231664751","rc":[{"batb":[[0,1.71,50],[1,1.7,36.06],[2,1.65,20.62]],"ltp":1.81,"tv":710.76,"id":19144236}]}]}
{"op":"mcm","clk":"11811292820","pt":1723306540631,"mc":[{"id":"1.231664751","rc":[{"batb":[[2,1.65,19.69]],"ltp":1.81,"tv":710.76,"id":19144236}]}]}
{"op":"mcm","clk":"11811293410","pt":1723306542975,"mc":[{"id":"1.231664751","rc":[{"batb":[[0,1.71,50.06]],"ltp":1.81,"tv":710.76,"id":19144236}]}]}
{"op":"mcm","clk":"11811293833","pt":1723306544740,"mc":[{"id":"1.231664751","rc":[{"trd":[[1.71,0.08],[1.73,0.13]],"batb":[[0,1.71,49.96]],"ltp":1.71,"tv":710.96,"id":19144236}],"tv":890.54}]}
{"op":"mcm","clk":"11811296072","pt":1723306553969,"mc":[{"id":"1.231664751","rc":[{"trd":[[1.81,270.24]],"batl":[[0,1.81,156.83]],"ltp":1.81,"tv":711.09,"id":19144236},{"trd":[[2.22,37.14]],"ltp":2.22,"tv":179.67,"id":25173012}],"tv":890.77}]}
{"op":"mcm","clk":"11811297043","pt":1723306557868,"mc":[{"id":"1.231664751","rc":[{"trd":[[1.71,0.12]],"batb":[[0,1.71,49.94]],"ltp":1.71,"tv":711.13,"id":19144236}],"tv":890.81}]}
{"op":"mcm","clk":"11811298073","pt":1723306562065,"mc":[{"id":"1.231664751","rc":[{"trd":[[1.71,0.32]],"batb":[[0,1.71,49.84]],"ltp":1.71,"tv":711.33,"id":19144236}],"tv":891.01}]}
{"op":"mcm","clk":"11811303882","pt":1723306585961,"mc":[{"id":"1.231664751","rc":[{"batb":[[0,1.71,49.89]],"ltp":1.71,"tv":711.33,"id":19144236}]}]}
{"op":"mcm","clk":"11811308629","pt":1723306605186,"mc":[{"id":"1.231664751","rc":[{"trd":[[1.81,270.25]],"batl":[[0,1.81,156.82]],"ltp":1.81,"tv":711.35,"id":19144236},{"trd":[[2.22,37.15]],"ltp":2.22,"tv":179.68,"id":25173012}],"tv":891.03}]}
{"op":"mcm","clk":"11811309758","pt":1723306610101,"mc":[{"id":"1.231664751","rc":[{"trd":[[1.71,100]],"batb":[[0,1.7,36.06],[1,1.65,19.69],[2,1.59,1298.7]],"batl":[[0,1.71,37.75],[1,1.81,156.82],[2,1.82,44.71]],"ltp":1.71,"tv":811.03,"id":19144236}],"tv":990.71}]}
{"op":"mcm","clk":"11811310181","pt":1723306612000,"mc":[{"id":"1.231664751","rc":[{"trd":[[1.71,113.34]],"batl":[[0,1.71,31.08]],"ltp":1.71,"tv":824.37,"id":19144236}],"tv":1004.05}]}
{"op":"mcm","clk":"11811310948","pt":1723306615219,"mc":[{"id":"1.231664751","rc":[{"trd":[[1.71,137.88]],"batl":[[0,1.71,18.81]],"ltp":1.71,"tv":848.91,"id":19144236}],"tv":1028.59}]}
{"op":"mcm","clk":"11811311416","pt":1723306617102,"mc":[{"id":"1.231664751","rc":[{"trd":[[1.71,144.49]],"batl":[[0,1.71,12.2]],"ltp":1.71,"tv":855.51,"id":19144236},{"trd":[[2.4,4.71]],"ltp":2.4,"tv":184.39,"id":25173012}],"tv":1039.91}]}
{"op":"mcm","clk":"11811312270","pt":1723306620434,"mc":[{"id":"1.231664751","rc":[{"trd":[[1.71,151.14]],"batl":[[0,1.71,5.54]],"ltp":1.71,"tv":862.17,"id":19144236},{"trd":[[2.4,9.45]],"ltp":2.4,"tv":189.13,"id":25173012}],"tv":1051.31}]}
{"op":"mcm","clk":"11811312897","pt":1723306623231,"mc":[{"id":"1.231664751","rc":[{"trd":[[1.7,0.2]],"batb":[[0,1.7,35.96]],"ltp":1.7,"tv":862.37,"id":19144236}],"tv":1051.51}]}
{"op":"mcm","clk":"11811315639","pt":1723306634833,"mc":[{"id":"1.231664751","rc":[{"batl":[[0,1.71,1.79]],"ltp":1.7,"tv":862.37,"id":19144236}]}]}
{"op":"mcm","clk":"11811316577","pt":1723306638728,"mc":[{"id":"1.231664751","rc":[{"trd":[[1.71,154.72]],"batb":[[0,1.71,7.21],[1,1.7,35.96],[2,1.65,19.69]],"batl":[[0,1.81,156.82],[1,1.82,44.71],[2,1.83,502.75]],"ltp":1.71,"tv":865.95,"id":19144236}],"tv":1055.09}]}
{"op":"mcm","clk":"11811316882","pt":1723306639943,"mc":[{"id":"1.231664751","rc":[{"trd":[[1.7,5.26],[1.71,169.14]],"batb":[[0,1.7,33.43],[1,1.65,19.69],[2,1.59,1298.7]],"ltp":1.7,"tv":885.43,"id":19144236}],"tv":1074.57}]}
{"op":"mcm","clk":"11811317937","pt":1723306644458,"mc":[{"id":"1.231664751","rc":[{"batb":[[0,1.7,33.5]],"ltp":1.7,"tv":885.43,"id":19144236}]}]}
{"op":"mcm","clk":"11811319594","pt":1723306651383,"mc":[{"id":"1.231664751","rc":[{"batl":[[2,1.87,89.05]],"ltp":1.7,"tv":885.43,"id":19144236}]}]}
{"op":"mcm","clk":"11811320545","pt":1723306655461,"mc":[{"id":"1.231664751","rc":[{"batl":[[0,1.81,157.47]],"ltp":1.7,"tv":885.43,"id":19144236}]}]}
{"op":"mcm","clk":"11811321972","pt":1723306661060,"mc":[{"id":"1.231664751","rc":[{"batb":[[0,1.71,7.28],[1,1.7,33.43],[2,1.65,19.69]],"ltp":1.7,"tv":885.43,"id":19144236}]}]}
{"op":"mcm","clk":"11811322735","pt":1723306664556,"mc":[{"id":"1.231664751","rc":[{"trd":[[1.75,0.13]],"batb":[[0,1.71,7.21]],"batl":[[0,1.81,664.07]],"ltp":1.75,"tv":885.56,"id":19144236},{"trd":[[2.32,0.15]],"batb":[[0,1.55,1818.22]],"ltp":2.32,"tv":189.23,"id":25173012}],"tv":1074.8}]}
{"op":"mcm","clk":"11811323386","pt":1723306667407,"mc":[{"id":"1.231664751","rc":[{"batl":[[0,2.4,4.56]],"ltp":2.32,"tv":189.23,"id":25173012}]}]}
{"op":"mcm","clk":"11811324570","pt":1723306672348,"mc":[{"id":"1.231664751","rc":[{"batl":[[0,1.79,138.98],[1,1.81,663.55],[2,1.82,44.71]],"ltp":1.75,"tv":885.56,"id":19144236}]}]}
{"op":"mcm","clk":"11811325041","pt":1723306674235,"mc":[{"id":"1.231664751","rc":[{"batl":[[0,1.79,138.62]],"ltp":1.75,"tv":885.56,"id":19144236}]}]}
{"op":"mcm","clk":"11811326616","pt":1723306681068,"mc":[{"id":"1.231664751","rc":[{"trd":[[1.75,0.27]],"batb":[[2,1.65,19.79]],"batl":[[0,1.79,138.48]],"ltp":1.75,"tv":885.7,"id":19144236},{"trd":[[2.32,0.25]],"ltp":2.32,"tv":189.33,"id":25173012}],"tv":1075.03}]}
{"op":"mcm","clk":"11811327922","pt":1723306686483,"mc":[{"id":"1.231664751","rc":[{"trd":[[1.71,169.34]],"batb":[[0,1.71,7.11]],"ltp":1.71,"tv":885.9,"id":19144236}],"tv":1075.24}]}
{"op":"mcm","clk":"11811328924","pt":1723306690663,"mc":[{"id":"1.231664751","rc":[{"trd":[[1.71,170.62],[1.79,0.1]],"batb":[[0,1.71,6.47]],"batl":[[0,1.79,138.41]],"ltp":1.79,"tv":887.27,"id":19144236}],"tv":1076.61}]}
{"op":"mcm","clk":"11811330666","pt":1723306697888,"mc":[{"id":"1.231664751","rc":[{"trd":[[1.79,3.07]],"batl":[[0,1.79,135.44]],"ltp":1.79,"tv":890.24,"id":19144236},{"trd":[[2.26,2.35]],"ltp":2.26,"tv":191.69,"id":25173012}],"tv":1081.94}]}
{"op":"mcm","clk":"11811331627","pt":1723306701902,"mc":[{"id":"1.231664751","rc":[{"batl":[[0,1.79,135.49]],"ltp":1.79,"tv":890.24,"id":19144236}]}]}
{"op":"mcm","clk":"11811335061","pt":1723306716301,"mc":[{"id":"1.231664751","rc":[{"trd":[[1.77,0.2],[1.79,3.15]],"batl":[[0,1.79,135.36]],"ltp":1.79,"tv":890.37,"id":19144236},{"trd":[[2.26,2.42],[2.28,0.04]],"ltp":2.26,"tv":191.79,"id":25173012}],"tv":1082.16}]}
{"op":"mcm","clk":"11811335711","pt":1723306718875,"mc":[{"id":"1.231664751","rc":[{"trd":[[1.79,3.39]],"batl":[[0,1.79,135.12]],"ltp":1.79,"tv":890.61,"id":19144236},{"trd":[[2.26,2.61]],"ltp":2.26,"tv":191.98,"id":25173012}],"tv":1082.59}]}
{"op":"mcm","clk":"11811337862","pt":1723306728427,"mc":[{"id":"1.231664751","rc":[{"trd":[[1.79,12.78]],"batl":[[0,1.79,125.73]],"ltp":1.79,"tv":900.0,"id":19144236},{"trd":[[2.26,10.04]],"ltp":2.26,"tv":199.41,"id":25173012}],"tv":1099.42}]}
{"op":"mcm","clk":"11811338436","pt":1723306730301,"mc":[{"id":"1.231664751","rc":[{"trd":[[1.79,12.91]],"batl":[[0,1.79,125.6]],"ltp":1.79,"tv":900.13,"id":19144236},{"trd":[[2.26,10.14]],"ltp":2.26,"tv":199.51,"id":25173012}],"tv":1099.65}]}
{"op":"mcm","clk":"11811339202","pt":1723306735482,"mc":[{"id":"1.231664751","rc":[{"trd":[[1.71,171.94],[1.79,13.24]],"batb":[[0,1.71,5.81]],"batl":[[0,1.79,125.37]],"ltp":1.79,"tv":901.78,"id":19144236},{"trd":[[2.26,10.24]],"ltp":2.26,"tv":199.61,"id":25173012}],"tv":1101.4}]}
{"op":"mcm","clk":"11811339747","pt":1723306736118,"mc":[{"id":"1.231664751","rc":[{"trd":[[1.79,13.25]],"batl":[[0,1.79,125.36]],"ltp":1.79,"tv":901.79,"id":19144236},{"trd":[[2.26,10.25]],"ltp":2.26,"tv":199.62,"id":25173012}],"tv":1101.42}]}
{"op":"mcm","clk":"11811340085","pt":1723306737293,"mc":[{"id":"1.231664751","rc":[{"trd":[[1.79,13.34]],"batl":[[0,1.79,125.27]],"ltp":1.79,"tv":901.88,"id":19144236},{"trd":[[2.26,10.32]],"ltp":2.26,"tv":199.69,"id":25173012}],"tv":1101.57}]}
{"op":"mcm","clk":"11811341741","pt":1723306744645,"mc":[{"id":"1.231664751","rc":[{"batb":[[0,1.55,1818.18]],"ltp":2.26,"tv":199.69,"id":25173012}]}]}
{"op":"mcm","clk":"11811342713","pt":1723306748889,"mc":[{"id":"1.231664751","rc":[{"trd":[[1.79,13.94]],"batl":[[0,1.79,124.67]],"ltp":1.79,"tv":902.48,"id":19144236},{"trd":[[2.26,10.79]],"ltp":2.26,"tv":200.16,"id":25173012}],"tv":1102.65}]}
{"op":"mcm","clk":"11811343121","pt":1723306750546,"mc":[{"id":"1.231664751","rc":[{"trd":[[1.79,15.4]],"batl":[[0,1.79,123.94]],"ltp":1.79,"tv":903.94,"id":19144236}],"tv":1104.11}]}
{"op":"mcm","clk":"11811343605","pt":1723306752747,"mc":[{"id":"1.231664751","rc":[{"batl":[[0,1.79,124.45]],"ltp":1.79,"tv":903.94,"id":19144236}]}]}
{"op":"mcm","clk":"11811344506","pt":1723306756772,"mc":[{"id":"1.231664751","rc":[{"trd":[[1.78,2.43],[1.79,26.41]],"batl":[[0,1.79,112.93]],"ltp":1.79,"tv":915.46,"id":19144236},{"trd":[[2.26,19.52],[2.28,0.44]],"ltp":2.26,"tv":209.28,"id":25173012}],"tv":1124.75}]}
{"op":"mcm","clk":"11811347072","pt":1723306767971,"mc":[{"id":"1.231664751","rc":[{"trd":[[1.71,172.08]],"batb":[[0,1.71,5.67]],"ltp":1.71,"tv":915.6,"id":19144236},{"trd":[[2.42,0.1]],"ltp":2.42,"tv":209.39,"id":25173012}],"tv":1124.99}]}
{"op":"mcm","clk":"11811347329","pt":1723306768952,"mc":[{"id":"1.231664751","rc":[{"batb":[[0,1.71,5.75]],"ltp":1.71,"tv":915.6,"id":19144236}]}]}
{"op":"mcm","clk":"11811348707","pt":1723306774879,"mc":[{"id":"1.231664751","rc":[{"trd":[[1.79,26.53]],"batl":[[0,1.79,112.87]],"ltp":1.79,"tv":915.72,"id":19144236}],"tv":1125.11}]}
{"op":"mcm","clk":"11811349439","pt":1723306777990,"mc":[{"id":"1.231664751","rc":[{"trd":[[1.72,0.16]],"batb":[[0,1.7,33.43],[1,1.65,19.79],[2,1.59,1298.7]],"batl":[[0,1.71,12.29],[1,1.79,112.87],[2,1.81,663.55]],"ltp":1.72,"tv":915.88,"id":19144236}],"tv":1125.27}]}
{"op":"mcm","clk":"11811350922","pt":1723306783971,"mc":[{"id":"1.231664751","rc":[{"trd":[[1.71,172.22]],"batl":[[0,1.71,12.15]],"ltp":1.71,"tv":916.02,"id":19144236},{"trd":[[2.4,9.55]],"ltp":2.4,"tv":209.49,"id":25173012}],"tv":1125.51}]}
{"op":"mcm","clk":"11811351491","pt":1723306786372,"mc":[{"id":"1.231664751","rc":[{"trd":[[1.71,173.88]],"batl":[[0,1.71,10.49]],"ltp":1.71,"tv":917.68,"id":19144236},{"trd":[[2.4,10.73]],"ltp":2.4,"tv":210.67,"id":25173012}],"tv":1128.35}]}
{"op":"mcm","clk":"11811351807","pt":1723306787664,"mc":[{"id":"1.231664751","rc":[{"batl":[[1,1.78,45],[2,1.79,112.87]],"ltp":1.71,"tv":917.68,"id":19144236}]}]}
{"op":"mcm","clk":"11811352523","pt":1723306790702,"mc":[{"id":"1.231664751","rc":[{"trd":[[1.71,184.37]],"batl":[[0,1.78,45],[1,1.79,112.87],[2,1.81,663.55]],"ltp":1.71,"tv":928.17,"id":19144236},{"trd":[[2.4,18.21]],"batl":[[0,2.4,1.65]],"ltp":2.4,"tv":218.14,"id":25173012}],"tv":1146.32}]}
{"op":"mcm","clk":"11811353135","pt":1723306793484,"mc":[{"id":"1.231664751","rc":[{"batl":[[1,1.81,663.55],[2,1.82,44.71]],"ltp":1.71,"tv":928.17,"id":19144236}]}]}
{"op":"mcm","clk":"11811353228","pt":1723306793890,"mc":[{"id":"1.231664751","rc":[{"trd":[[1.69,0.2],[1.7,72.12],[1.71,186.68]],"batb":[[0,1.65,19.69],[1,1.59,1298.7],[2,1.04,1635.51]],"batl":[[0,1.69,74.93],[1,1.78,45],[2,1.81,663.55]],"ltp":1.69,"tv":997.54,"id":19144236},{"trd":[[2.4,19.85]],"ltp":2.4,"tv":219.79,"id":25173012}],"tv":1217.34}]}
{"op":"mcm","clk":"11811353409","pt":1723306794688,"mc":[{"id":"1.231664751","rc":[{"batl":[[1,1.78,45.1]],"ltp":1.69,"tv":997.54,"id":19144236}]}]}
{"op":"mcm","clk":"11811353723","pt":1723306795978,"mc":[{"id":"1.231664751","rc":[{"trd":[[1.69,0.23]],"batl":[[0,1.69,74.9]],"ltp":1.69,"tv":997.57,"id":19144236},{"trd":[[2.44,0.02]],"ltp":2.44,"tv":219.81,"id":25173012}],"tv":1217.39}]}
{"op":"mcm","clk":"11811355714","pt":1723306803722,"mc":[{"id":"1.231664751","rc":[{"trd":[[1.69,0.38]],"batl":[[0,1.69,74.75]],"ltp":1.69,"tv":997.72,"id":19144236},{"trd":[[2.44,0.12]],"ltp":2.44,"tv":219.91,"id":25173012}],"tv":1217.64}]}
{"op":"mcm","clk":"11811358997","pt":1723306816793,"mc":[{"id":"1.231664751","rc":[{"batb":[[1,1.04,1635.51],[2,1.03,2164.67]],"ltp":1.69,"tv":997.72,"id":19144236}]}]}
{"op":"mcm","clk":"11811360638","pt":1723306823465,"mc":[{"id":"1.231664751","rc":[{"trd":[[1.69,4.6]],"batb":[[1,1.5,20],[2,1.04,1635.51]],"batl":[[0,1.69,70.53]],"ltp":1.69,"tv":1001.94,"id":19144236},{"trd":[[2.44,3.05]],"ltp":2.44,"tv":222.83,"id":25173012}],"tv":1224.78}]}
{"op":"mcm","clk":"11811361156","pt":1723306825620,"mc":[{"id":"1.231664751","rc":[{"trd":[[1.69,4.75]],"batl":[[0,1.69,70.38]],"ltp":1.69,"tv":1002.09,"id":19144236},{"trd":[[2.44,3.15]],"ltp":2.44,"tv":222.93,"id":25173012}],"tv":1225.03}]}
{"op":"mcm","clk":"11811362112","pt":1723306829813,"mc":[{"id":"1.231664751","rc":[{"batl":[[2,1.8,57.48]],"ltp":1.69,"tv":1002.09,"id":19144236}]}]}
{"op":"mcm","clk":"11811365187","pt":1723306842315,"mc":[{"id":"1.231664751","rc":[{"trd":[[1.69,5.01]],"batl":[[0,1.69,70.25]],"ltp":1.69,"tv":1002.36,"id":19144236}],"tv":1225.3}]}
{"op":"mcm","clk":"11811365313","pt":1723306842907,"mc":[{"id":"1.231664751","rc":[{"batl":[[1,1.78,45.12]],"ltp":1.69,"tv":1002.36,"id":19144236}]}]}
{"op":"mcm","clk":"11811367449","pt":1723306851686,"mc":[{"id":"1.231664751","rc":[{"batb":[[0,1.72,17.13],[1,1.55,1818.18],[2,1.54,1851.85]],"ltp":2.44,"tv":222.93,"id":25173012}]}]}
{"op":"mcm","clk":"11811368016","pt":1723306854022,"mc":[{"id":"1.231664751","rc":[{"batb":[[0,1.72,17.19]],"ltp":2.44,"tv":222.93,"id":25173012}]}]}
{"op":"mcm","clk":"11811372386","pt":1723306872547,"mc":[{"id":"1.231664751","rc":[{"trd":[[1.69,5.8]],"batl":[[0,1.69,69.78]],"ltp":1.69,"tv":1003.14,"id":19144236},{"trd":[[2.44,3.25]],"ltp":2.44,"tv":223.04,"id":25173012}],"tv":1226.18}]}
{"op":"mcm","clk":"11811373193","pt":1723306876039,"mc":[{"id":"1.231664751","rc":[{"trd":[[1.69,5.95]],"batl":[[0,1.69,69.63]],"ltp":1.69,"tv":1003.29,"id":19144236},{"trd":[[2.44,3.35]],"ltp":2.44,"tv":223.14,"id":25173012}],"tv":1226.44}]}
{"op":"mcm","clk":"11811373727","pt":1723306878269,"mc":[{"id":"1.231664751","rc":[{"trd":[[1.65,41.63]],"batb":[[0,1.5,20],[1,1.04,1635.51],[2,1.03,2164.67]],"batl":[[0,1.65,3.31],[1,1.69,69.63],[2,1.78,45.12]],"ltp":1.65,"tv":1042.67,"id":19144236}],"tv":1265.82}]}
{"op":"mcm","clk":"11811376023","pt":1723306888182,"mc":[{"id":"1.231664751","rc":[{"trd":[[1.65,41.69]],"batl":[[0,1.65,3.28]],"ltp":1.65,"tv":1042.73,"id":19144236}],"tv":1265.87}]}
{"op":"mcm","clk":"11811376273","pt":1723306889256,"mc":[{"id":"1.231664751","rc":[{"trd":[[1.65,41.91]],"batl":[[0,1.65,3.06]],"ltp":1.65,"tv":1042.95,"id":19144236},{"trd":[[2.52,0.14]],"ltp":2.52,"tv":223.28,"id":25173012}],"tv":1266.23}]}
{"op":"mcm","clk":"11811377474","pt":1723306894163,"mc":[{"id":"1.231664751","rc":[{"trd":[[1.65,46.06]],"batl":[[0,1.69,70.61],[1,1.78,45.12],[2,1.8,57.48]],"ltp":1.65,"tv":1047.1,"id":19144236}],"tv":1270.39}]}
{"op":"mcm","clk":"11811377614","pt":1723306894860,"mc":[{"id":"1.231664751","rc":[{"batb":[[0,1.51,90],[1,1.5,20],[2,1.04,1635.51]],"ltp":1.65,"tv":1047.1,"id":19144236}]}]}
{"op":"mcm","clk":"11811379343","pt":1723306902166,"mc":[{"id":"1.231664751","rc":[{"trd":[[1.65,46.21]],"batl":[[0,1.69,70.46]],"ltp":1.65,"tv":1047.25,"id":19144236},{"trd":[[2.52,0.24]],"ltp":2.52,"tv":223.38,"id":25173012}],"tv":1270.64}]}
{"op":"mcm","clk":"11811379904","pt":1723306904769,"mc":[{"id":"1.231664751","rc":[{"batb":[[0,1.51,540]],"ltp":1.65,"tv":1047.25,"id":19144236}]}]}
{"op":"mcm","clk":"11811380912","pt":1723306909293,"mc":[{"id":"1.231664751","rc":[{"trd":[[1.65,46.26]],"batl":[[0,1.69,70.41]],"ltp":1.65,"tv":1047.3,"id":19144236},{"trd":[[2.52,0.27]],"ltp":2.52,"tv":223.41,"id":25173012}],"tv":1270.72}]}
{"op":"mcm","clk":"11811381232","pt":1723306910667,"mc":[{"id":"1.231664751","rc":[{"batl":[[0,2.96,0.1]],"ltp":2.52,"tv":223.41,"id":25173012}]}]}
{"op":"mcm","clk":"11811381613","pt":1723306912390,"mc":[{"id":"1.231664751","rc":[{"trd":[[1.65,46.36]],"batl":[[0,1.66,139.14],[1,1.69,69.63],[2,1.78,45.12]],"ltp":1.65,"tv":1047.4,"id":19144236},{"trd":[[2.52,0.34]],"ltp":2.52,"tv":223.47,"id":25173012}],"tv":1270.88}]}
{"op":"mcm","clk":"11811381870","pt":1723306913696,"mc":[{"id":"1.231664751","rc":[{"trd":[[1.65,47.72],[1.66,0.84]],"batl":[[0,1.66,138.04]],"ltp":1.66,"tv":1049.6,"id":19144236}],"tv":1273.08}]}
{"op":"mcm","clk":"11811382127","pt":1723306914703,"mc":[{"id":"1.231664751","rc":[{"trd":[[1.66,0.99]],"batl":[[0,1.66,137.89]],"ltp":1.66,"tv":1049.75,"id":19144236},{"trd":[[2.5,0.1]],"ltp":2.5,"tv":223.57,"id":25173012}],"tv":1273.33}]}
{"op":"mcm","clk":"11811385611","pt":1723306929408,"mc":[{"id":"1.231664751","rc":[{"batb":[[0,1.51,540.96]],"ltp":1.66,"tv":1049.75,"id":19144236}]}]}
{"op":"mcm","clk":"11811386599","pt":1723306933789,"mc":[{"id":"1.231664751","rc":[{"trd":[[1.66,3.18]],"batl":[[0,1.66,136.79]],"ltp":1.66,"tv":1051.95,"id":19144236}],"tv":1275.53}]}
{"op":"mcm","clk":"11811388603","pt":1723306942430,"mc":[{"id":"1.231664751","rc":[{"trd":[[1.66,193.63]],"batl":[[0,1.66,41.57]],"ltp":1.66,"tv":1242.39,"id":19144236}],"tv":1465.97}]}
{"op":"mcm","clk":"11811389837","pt":1723306947592,"mc":[{"id":"1.231664751","rc":[{"trd":[[1.66,197.23]],"batl":[[0,1.66,39.32]],"ltp":1.66,"tv":1246.0,"id":19144236},{"trd":[[2.5,0.69]],"ltp":2.5,"tv":224.16,"id":25173012}],"tv":1470.17}]}
{"op":"mcm","clk":"11811390948","pt":1723306952421,"mc":[{"id":"1.231664751","rc":[{"trd":[[1.66,197.38]],"batl":[[0,1.66,39.17]],"ltp":1.66,"tv":1246.15,"id":19144236},{"trd":[[2.5,0.79]],"ltp":2.5,"tv":224.26,"id":25173012}],"tv":1470.42}]}
{"op":"mcm","clk":"11811393292","pt":1723306962444,"mc":[{"id":"1.231664751","rc":[{"trd":[[1.66,197.53]],"batb":[[0,1.51,540]],"batl":[[0,1.66,39.02]],"ltp":1.66,"tv":1246.3,"id":19144236},{"trd":[[2.5,0.89]],"ltp":2.5,"tv":224.37,"id":25173012}],"tv":1470.67}]}
{"op":"mcm","clk":"11811394499","pt":1723306967651,"mc":[{"id":"1.231664751","rc":[{"batb":[[0,1.54,1.4],[1,1.51,540],[2,1.5,20]],"ltp":1.66,"tv":1246.3,"id":19144236}]}]}
{"op":"mcm","clk":"11811394837","pt":1723306969034,"mc":[{"id":"1.231664751","rc":[{"batb":[[0,1.55,150],[1,1.54,1.4],[2,1.51,540]],"ltp":1.66,"tv":1246.3,"id":19144236}]}]}
{"op":"mcm","clk":"11811396555","pt":1723306976142,"mc":[{"id":"1.231664751","rc":[{"batl":[[0,1.66,34.97]],"ltp":1.66,"tv":1246.3,"id":19144236}]}]}
{"op":"mcm","clk":"11811397885","pt":1723306981656,"mc":[{"id":"1.231664751","rc":[{"trd":[[1.66,198.89]],"batb":[[1,1.51,540],[2,1.5,20]],"batl":[[0,1.66,33.61]],"ltp":1.66,"tv":1247.66,"id":19144236},{"trd":[[2.5,1.79]],"ltp":2.5,"tv":225.27,"id":25173012}],"tv":1472.93}]}
{"op":"mcm","clk":"11811398272","pt":1723306983256,"mc":[{"id":"1.231664751","rc":[{"trd":[[1.66,199.09]],"batl":[[0,1.66,33.51]],"ltp":1.66,"tv":1247.86,"id":19144236}],"tv":1473.13}]}
{"op":"mcm","clk":"11811399091","pt":1723306986657,"mc":[{"id":"1.231664751","rc":[{"batb":[[0,1.57,1.4],[1,1.55,150],[2,1.51,540]],"ltp":1.66,"tv":1247.86,"id":19144236}]}]}
{"op":"mcm","clk":"11811399148","pt":1723306986861,"mc":[{"id":"1.231664751","rc":[{"trd":[[1.57,2.04]],"batb":[[0,1.55,150.38],[1,1.51,540],[2,1.5,20]],"ltp":1.57,"tv":1249.9,"id":19144236}],"tv":1475.17}]}
{"op":"mcm","clk":"11811399410","pt":1723306987945,"mc":[{"id":"1.231664751","rc":[{"batb":[[0,1.58,2.25],[1,1.55,150.38],[2,1.51,540]],"ltp":1.57,"tv":1249.9,"id":19144236}]}]}
{"op":"mcm","clk":"11811399800","pt":1723306989577,"mc":[{"id":"1.231664751","rc":[{"trd":[[1.66,199.24]],"batl":[[0,1.66,33.36]],"ltp":1.66,"tv":1250.05,"id":19144236},{"trd":[[2.5,1.89]],"ltp":2.5,"tv":225.37,"id":25173012}],"tv":1475.42}]}
{"op":"mcm","clk":"11811400200","pt":1723306991078,"mc":[{"id":"1.231664751","rc":[{"trd":[[1.66,199.39]],"batl":[[0,1.66,33.21]],"ltp":1.66,"tv":1250.2,"id":19144236},{"trd":[[2.5,1.99]],"ltp":2.5,"tv":225.47,"id":25173012}],"tv":1475.67}]}
{"op":"mcm","clk":"11811400817","pt":1723306993446,"mc":[{"id":"1.231664751","rc":[{"trd":[[1.66,199.6]],"batl":[[0,1.66,33.11]],"ltp":1.66,"tv":1250.4,"id":19144236}],"tv":1475.87}]}
{"op":"mcm","clk":"11811401516","pt":1723306996162,"mc":[{"id":"1.231664751","rc":[{"trd":[[1.58,0.38],[1.66,199.75]],"batb":[[0,1.58,2.06]],"batl":[[0,1.66,32.96]],"ltp":1.58,"tv":1250.93,"id":19144236},{"trd":[[2.5,2.09]],"ltp":2.5,"tv":225.57,"id":25173012}],"tv":1476.5}]}
{"op":"mcm","clk":"11811403167","pt":1723307003016,"mc":[{"id":"1.231664751","rc":[{"trd":[[1.66,200.71]],"batl":[[0,1.66,32]],"ltp":1.66,"tv":1251.89,"id":19144236},{"trd":[[2.5,2.73]],"ltp":2.5,"tv":226.2,"id":25173012}],"tv":1478.1}]}
{"op":"mcm","clk":"11811403581","pt":1723307004860,"mc":[{"id":"1.231664751","rc":[{"batl":[[0,1.66,32.96]],"ltp":1.66,"tv":1251.89,"id":19144236}]}]}
{"op":"mcm","clk":"11811404184","pt":1723307007066,"mc":[{"id":"1.231664751","rc":[{"trd":[[1.64,0.22]],"batl":[[0,1.66,32.74]],"ltp":1.64,"tv":1252.11,"id":19144236},{"trd":[[2.56,0.14]],"ltp":2.56,"tv":226.34,"id":25173012}],"tv":1478.46}]}
{"op":"mcm","clk":"11811404531","pt":1723307008509,"mc":[{"id":"1.231664751","rc":[{"batb":[[1,1.55,150]],"ltp":1.64,"tv":1252.11,"id":19144236}]}]}
{"op":"mcm","clk":"11811407862","pt":1723307021888,"mc":[{"id":"1.231664751","rc":[{"batb":[[1,1.51,540],[2,1.5,20]],"ltp":1.64,"tv":1252.11,"id":19144236}]}]}
{"op":"mcm","clk":"11811408822","pt":1723307026187,"mc":[{"id":"1.231664751","rc":[{"batl":[[0,1.59,1.02],[1,1.66,32.74],[2,1.69,69.63]],"ltp":1.64,"tv":1252.11,"id":19144236}]}]}
{"op":"mcm","clk":"11811409222","pt":1723307027933,"mc":[{"id":"1.231664751","rc":[{"trd":[[1.59,0.17]],"batl":[[0,1.64,1.59],[1,1.66,32]],"ltp":1.59,"tv":1252.28,"id":19144236},{"trd":[[2.68,0.1]],"ltp":2.68,"tv":226.45,"id":25173012}],"tv":1478.73}]}
{"op":"mcm","clk":"11811409855","pt":1723307030507,"mc":[{"id":"1.231664751","rc":[{"trd":[[1.59,0.35]],"batl":[[0,1.64,1.41]],"ltp":1.59,"tv":1252.46,"id":19144236},{"trd":[[2.68,0.2]],"ltp":2.68,"tv":226.55,"id":25173012}],"tv":1479.01}]}
{"op":"mcm","clk":"11811409910","pt":1723307030778,"mc":[{"id":"1.231664751","rc":[{"trd":[[1.59,0.52]],"batl":[[0,1.64,1.24]],"ltp":1.59,"tv":1252.63,"id":19144236},{"trd":[[2.68,0.3]],"ltp":2.68,"tv":226.65,"id":25173012}],"tv":1479.28}]}
{"op":"mcm","clk":"11811410451","pt":1723307033105,"mc":[{"id":"1.231664751","rc":[{"trd":[[1.59,1.02],[1.64,0.96],[1.66,213.1]],"batl":[[0,1.66,19.61],[1,1.69,69.63],[2,1.78,45.12]],"ltp":1.66,"tv":1266.26,"id":19144236},{"trd":[[2.5,10.96],[2.56,0.61],[2.68,0.6]],"ltp":2.5,"tv":235.65,"id":25173012}],"tv":1501.91}]}
{"op":"mcm","clk":"11811411112","pt":1723307036041,"mc":[{"id":"1.231664751","rc":[{"batb":[[0,1.58,4.31]],"ltp":1.66,"tv":1266.26,"id":19144236}]}]}
{"op":"mcm","clk":"11811411653","pt":1723307038400,"mc":[{"id":"1.231664751","rc":[{"batb":[[0,1.58,5.27]],"ltp":1.66,"tv":1266.26,"id":19144236}]}]}
{"op":"mcm","clk":"11811411895","pt":1723307039406,"mc":[{"id":"1.231664751","rc":[{"batb":[[0,1.64,45.08],[1,1.58,5.27],[2,1.51,540]],"ltp":1.66,"tv":1266.26,"id":19144236}]}]}
{"op":"mcm","clk":"11811412824","pt":1723307043176,"mc":[{"id":"1.231664751","rc":[{"trd":[[1.66,213.25]],"batl":[[0,1.66,19.46]],"ltp":1.66,"tv":1266.41,"id":19144236},{"trd":[[2.5,11.06]],"ltp":2.5,"tv":235.75,"id":25173012}],"tv":1502.16}]}
{"op":"mcm","clk":"11811413105","pt":1723307044401,"mc":[{"id":"1.231664751","rc":[{"trd":[[1.66,214.22]],"batl":[[0,1.66,18.49]],"ltp":1.66,"tv":1267.38,"id":19144236},{"trd":[[2.5,11.71]],"ltp":2.5,"tv":236.39,"id":25173012}],"tv":1503.78}]}
{"op":"mcm","clk":"11811413306","pt":1723307045313,"mc":[{"id":"1.231664751","rc":[{"trd":[[1.66,214.37]],"batl":[[0,1.66,18.34]],"ltp":1.66,"tv":1267.53,"id":19144236},{"trd":[[2.5,11.81]],"ltp":2.5,"tv":236.49,"id":25173012}],"tv":1504.03}]}
{"op":"mcm","clk":"11811416151","pt":1723307057229,"mc":[{"id":"1.231664751","rc":[{"trd":[[1.66,214.52]],"batl":[[0,1.66,18.19]],"ltp":1.66,"tv":1267.68,"id":19144236},{"trd":[[2.5,11.91]],"ltp":2.5,"tv":236.59,"id":25173012}],"tv":1504.28}]}
{"op":"mcm","clk":"11811416297","pt":1723307057817,"mc":[{"id":"1.231664751","rc":[{"batb":[[1,1.58,4.31]],"ltp":1.66,"tv":1267.68,"id":19144236}]}]}
{"op":"mcm","clk":"11811417556","pt":1723307063057,"mc":[{"id":"1.231664751","rc":[{"trd":[[1.64,0.98]],"batb":[[0,1.64,45.07]],"ltp":1.64,"tv":1267.7,"id":19144236}],"tv":1504.3}]}
{"op":"mcm","clk":"11811417776","pt":1723307063965,"mc":[{"id":"1.231664751","rc":[{"batb":[[1,1.58,2.06]],"ltp":1.64,"tv":1267.7,"id":19144236}]}]}
{"op":"mcm","clk":"11811418068","pt":1723307065287,"mc":[{"id":"1.231664751","rc":[{"trd":[[1.66,214.69]],"batl":[[0,1.66,18.02]],"ltp":1.66,"tv":1267.87,"id":19144236},{"trd":[[2.5,12.02]],"ltp":2.5,"tv":236.71,"id":25173012}],"tv":1504.58}]}
{"op":"mcm","clk":"11811421961","pt":1723307082076,"mc":[{"id":"1.231664751","rc":[{"trd":[[1.66,214.84]],"batl":[[0,1.66,17.87]],"ltp":1.66,"tv":1268.02,"id":19144236},{"trd":[[2.5,12.12]],"ltp":2.5,"tv":236.81,"id":25173012}],"tv":1504.83}]}
{"op":"mcm","clk":"11811422774","pt":1723307085766,"mc":[{"id":"1.231664751","rc":[{"trd":[[1.66,214.99]],"batl":[[0,1.66,17.72]],"ltp":1.66,"tv":1268.17,"id":19144236},{"trd":[[2.5,12.22]],"ltp":2.5,"tv":236.91,"id":25173012}],"tv":1505.08}]}
{"op":"mcm","clk":"11811423223","pt":1723307087864,"mc":[{"id":"1.231664751","rc":[{"trd":[[1.66,215.27]],"batl":[[0,1.66,17.44]],"ltp":1.66,"tv":1268.45,"id":19144236},{"trd":[[2.5,12.41]],"ltp":2.5,"tv":237.1,"id":25173012}],"tv":1505.55}]}
{"op":"mcm","clk":"11811423818","pt":1723307090482,"mc":[{"id":"1.231664751","rc":[{"batb":[[1,1.51,540],[2,1.5,20]],"ltp":1.66,"tv":1268.45,"id":19144236}]}]}
{"op":"mcm","clk":"11811425409","pt":1723307097317,"mc":[{"id":"1.231664751","rc":[{"trd":[[1.66,250.15]],"batb":[[0,1.66,27.56],[1,1.64,45.07],[2,1.51,540]],"batl":[[0,1.69,69.63],[1,1.78,45.12],[2,1.8,57.48]],"ltp":1.66,"tv":1303.33,"id":19144236}],"tv":1540.43}]}
{"op":"mcm","clk":"11811426190","pt":1723307100585,"mc":[{"id":"1.231664751","rc":[{"batl":[[0,2.5,0.1]],"ltp":2.5,"tv":237.1,"id":25173012}]}]}
{"op":"mcm","clk":"11811427876","pt":1723307107399,"mc":[{"id":"1.231664751","rc":[{"batb":[[0,1.66,29.63]],"ltp":1.66,"tv":1303.33,"id":19144236}]}]}
{"op":"mcm","clk":"11811428102","pt":1723307108410,"mc":[{"id":"1.231664751","rc":[{"batl":[[0,2.5,0.1]],"ltp":2.5,"tv":237.1,"id":25173012}]}]}
{"op":"mcm","clk":"11811429021","pt":1723307112303,"mc":[{"id":"1.231664751","rc":[{"batl":[[0,1.67,148.77],[1,1.69,69.63],[2,1.78,45.12]],"ltp":1.66,"tv":1303.33,"id":19144236}]}]}
{"op":"mcm","clk":"11811429183","pt":1723307113011,"mc":[{"id":"1.231664751","rc":[{"trd":[[1.67,0.2]],"batl":[[0,1.67,148.67]],"ltp":1.67,"tv":1303.53,"id":19144236}],"tv":1540.63}]}
{"op":"mcm","clk":"11811429588","pt":1723307114750,"mc":[{"id":"1.231664751","rc":[{"trd":[[1.67,6.97]],"batl":[[0,1.67,141.9]],"ltp":1.67,"tv":1310.3,"id":19144236},{"trd":[[2.48,4.56]],"ltp":2.48,"tv":241.66,"id":25173012}],"tv":1551.96}]}
{"op":"mcm","clk":"11811430018","pt":1723307116612,"mc":[{"id":"1.231664751","rc":[{"trd":[[1.67,52.64]],"batl":[[0,1.67,118.73]],"ltp":1.67,"tv":1355.97,"id":19144236},{"trd":[[2.48,5.01]],"ltp":2.48,"tv":242.11,"id":25173012}],"tv":1598.08}]}
{"op":"mcm","clk":"11811430256","pt":1723307117622,"mc":[{"id":"1.231664751","rc":[{"trd":[[1.66,251.46]],"batb":[[0,1.66,28.97]],"ltp":1.66,"tv":1357.29,"id":19144236}],"tv":1599.4}]}
{"op":"mcm","clk":"11811430455","pt":1723307118523,"mc":[{"id":"1.231664751","rc":[{"trd":[[1.67,53.98]],"batl":[[0,1.67,117.4]],"ltp":1.67,"tv":1358.63,"id":19144236},{"trd":[[2.48,5.91]],"ltp":2.48,"tv":243.01,"id":25173012}],"tv":1601.64}]}
{"op":"mcm","clk":"11811432291","pt":1723307126963,"mc":[{"id":"1.231664751","rc":[{"trd":[[1.67,54.13]],"batl":[[0,1.67,117.25]],"ltp":1.67,"tv":1358.78,"id":19144236},{"trd":[[2.48,6.01]],"ltp":2.48,"tv":243.11,"id":25173012}],"tv":1601.89}]}
{"op":"mcm","clk":"11811433220","pt":1723307131026,"mc":[{"id":"1.231664751","rc":[{"trd":[[1.67,54.28]],"batl":[[0,1.67,117.1]],"ltp":1.67,"tv":1358.93,"id":19144236},{"trd":[[2.48,6.11]],"ltp":2.48,"tv":243.21,"id":25173012}],"tv":1602.14}]}
{"op":"mcm","clk":"11811434966","pt":1723307138816,"mc":[{"id":"1.231664751","rc":[{"trd":[[1.67,57.01]],"batl":[[0,1.67,115.71]],"ltp":1.67,"tv":1361.66,"id":19144236},{"trd":[[2.48,6.13]],"ltp":2.48,"tv":243.23,"id":25173012}],"tv":1604.89}]}
{"op":"mcm","clk":"11811435438","pt":1723307141036,"mc":[{"id":"1.231664751","rc":[{"trd":[[1.67,57.16]],"batl":[[0,1.67,115.56]],"ltp":1.67,"tv":1361.81,"id":19144236},{"trd":[[2.48,6.23]],"ltp":2.48,"tv":243.33,"id":25173012}],"tv":1605.14}]}
{"op":"mcm","clk":"11811436186","pt":1723307144447,"mc":[{"id":"1.231664751","rc":[{"trd":[[1.67,57.31]],"batl":[[0,1.67,115.41]],"ltp":1.67,"tv":1361.96,"id":19144236},{"trd":[[2.48,6.33]],"ltp":2.48,"tv":243.43,"id":25173012}],"tv":1605.39}]}
{"op":"mcm","clk":"11811436598","pt":1723307146231,"mc":[{"id":"1.231664751","rc":[{"trd":[[1.67,57.35]],"batl":[[0,1.67,115.39]],"ltp":1.67,"tv":1362.0,"id":19144236}],"tv":1605.43}]}
{"op":"mcm","clk":"11811437661","pt":1723307151440,"mc":[{"id":"1.231664751","rc":[{"trd":[[1.67,57.5]],"batl":[[0,1.67,115.24]],"ltp":1.67,"tv":1362.15,"id":19144236},{"trd":[[2.48,6.43]],"ltp":2.48,"tv":243.53,"id":25173012}],"tv":1605.68}]}
{"op":"mcm","clk":"11811438019","pt":1723307152866,"mc":[{"id":"1.231664751","rc":[{"trd":[[1.67,57.78]],"batl":[[0,1.67,114.96]],"ltp":1.67,"tv":1362.43,"id":19144236},{"trd":[[2.48,6.62]],"ltp":2.48,"tv":243.72,"id":25173012}],"tv":1606.15}]}
{"op":"mcm","clk":"11811438812","pt":1723307156560,"mc":[{"id":"1.231664751","rc":[{"trd":[[1.67,59.38]],"batl":[[0,1.67,113.37]],"ltp":1.67,"tv":1364.03,"id":19144236},{"trd":[[2.48,7.7]],"ltp":2.48,"tv":244.79,"id":25173012}],"tv":1608.82}]}
{"op":"mcm","clk":"11811439099","pt":1723307157950,"mc":[{"id":"1.231664751","rc":[{"trd":[[1.67,59.66]],"batl":[[0,1.67,113.23]],"ltp":1.67,"tv":1364.31,"id":19144236}],"tv":1609.1}]}
{"op":"mcm","clk":"11811439270","pt":1723307158742,"mc":[{"id":"1.231664751","rc":[{"trd":[[1.67,61.14]],"batl":[[0,1.67,111.74]],"ltp":1.67,"tv":1365.79,"id":19144236},{"trd":[[2.48,8.7]],"ltp":2.48,"tv":245.79,"id":25173012}],"tv":1611.59}]}
{"op":"mcm","clk":"11811439676","pt":1723307160643,"mc":[{"id":"1.231664751","rc":[{"trd":[[1.67,101.14]],"batl":[[0,1.67,91.74]],"ltp":1.67,"tv":1405.79,"id":19144236}],"tv":1651.59}]}
{"op":"mcm","clk":"11811440310","pt":1723307163598,"mc":[{"id":"1.231664751","rc":[{"trd":[[1.66,251.66],[1.67,101.34]],"batb":[[0,1.66,28.87]],"batl":[[0,1.67,91.64]],"ltp":1.66,"tv":1406.19,"id":19144236}],"tv":1651.99}]}
{"op":"mcm","clk":"11811440459","pt":1723307164192,"mc":[{"id":"1.231664751","rc":[{"trd":[[1.67,106.66]],"batb":[[2,1.51,450]],"batl":[[0,1.67,86.33],[2,1.8,57.59]],"ltp":1.67,"tv":1411.51,"id":19144236},{"trd":[[2.48,12.27]],"ltp":2.48,"tv":249.37,"id":25173012}],"tv":1660.88}]}
{"op":"mcm","clk":"11811442419","pt":1723307173101,"mc":[{"id":"1.231664751","rc":[{"batl":[[0,7.8,0.54]],"ltp":2.48,"tv":249.37,"id":25173012}]}]}
{"op":"mcm","clk":"11811442923","pt":1723307175386,"mc":[{"id":"1.231664751","rc":[{"trd":[[1.67,126.5]],"batl":[[0,1.67,76.41]],"ltp":1.67,"tv":1431.35,"id":19144236}],"tv":1680.72}]}
{"op":"mcm","clk":"11811443618","pt":1723307178421,"mc":[{"id":"1.231664751","rc":[{"trd":[[1.67,135.5]],"batl":[[0,1.67,71.91]],"ltp":1.67,"tv":1440.35,"id":19144236}],"tv":1689.72}]}
{"op":"mcm","clk":"11811444073","pt":1723307180199,"mc":[{"id":"1.231664751","rc":[{"trd":[[1.66,252.98]],"batb":[[0,1.66,28.21]],"ltp":1.66,"tv":1441.67,"id":19144236}],"tv":1691.04}]}
{"op":"mcm","clk":"11811445479","pt":1723307186429,"mc":[{"id":"1.231664751","rc":[{"trd":[[1.67,135.87]],"batl":[[0,1.67,71.72]],"ltp":1.67,"tv":1442.04,"id":19144236}],"tv":1691.42}]}
{"op":"mcm","clk":"11811446234","pt":1723307189821,"mc":[{"id":"1.231664751","rc":[{"batb":[[1,1.65,9.85],[2,1.55,1818.18]],"ltp":2.48,"tv":249.37,"id":25173012}]}]}
{"op":"mcm","clk":"11811446921","pt":1723307192695,"mc":[{"id":"1.231664751","rc":[{"trd":[[1.67,136.07]],"batl":[[0,1.67,71.52]],"ltp":1.67,"tv":1442.24,"id":19144236},{"trd":[[2.48,12.41]],"ltp":2.48,"tv":249.5,"id":25173012}],"tv":1691.75}]}
{"op":"mcm","clk":"11811447737","pt":1723307196245,"mc":[{"id":"1.231664751","rc":[{"trd":[[1.67,136.27]],"batl":[[0,1.67,71.42]],"ltp":1.67,"tv":1442.44,"id":19144236}],"tv":1691.95}]}
{"op":"mcm","clk":"11811448450","pt":1723307199514,"mc":[{"id":"1.231664751","rc":[{"trd":[[1.67,138.08]],"batl":[[0,1.67,69.61]],"ltp":1.67,"tv":1444.25,"id":19144236},{"trd":[[2.48,13.62]],"ltp":2.48,"tv":250.72,"id":25173012}],"tv":1694.97}]}
{"op":"mcm","clk":"11811451375","pt":1723307212010,"mc":[{"id":"1.231664751","rc":[{"batl":[[0,1.69,69.63],[1,1.8,57.59],[2,2.1,17.66]],"ltp":1.67,"tv":1444.25,"id":19144236}]}]}
{"op":"mcm","clk":"11811451656","pt":1723307213227,"mc":[{"id":"1.231664751","rc":[{"trd":[[1.66,309.4]],"batb":[[0,1.64,45.07],[1,1.51,450],[2,1.5,20]],"batl":[[0,1.66,14.79],[1,1.69,69.63],[2,1.8,57.59]],"ltp":1.66,"tv":1500.67,"id":19144236}],"tv":1751.39}]}
{"op":"mcm","clk":"11811451992","pt":1723307214659,"mc":[{"id":"1.231664751","rc":[{"trd":[[1.66,309.44]],"batl":[[0,1.66,14.77]],"ltp":1.66,"tv":1500.71,"id":19144236}],"tv":1751.43}]}
{"op":"mcm","clk":"11811455967","pt":1723307231987,"mc":[{"id":"1.231664751","rc":[{"trd":[[1.66,338.98]],"batb":[[0,1.66,185.23],[1,1.64,45.07],[2,1.51,450]],"batl":[[0,1.69,69.63],[1,1.8,57.59],[2,2.1,17.66]],"ltp":1.66,"tv":1530.25,"id":19144236}],"tv":1780.97}]}
{"op":"mcm","clk":"11811457247","pt":1723307237773,"mc":[{"id":"1.231664751","rc":[{"batl":[[0,2.5,8.1],[1,7.8,0.54]],"ltp":2.48,"tv":250.72,"id":25173012}]}]}
{"op":"mcm","clk":"11811457558","pt":1723307239149,"mc":[{"id":"1.231664751","rc":[{"batb":[[0,1.66,186.17]],"ltp":1.66,"tv":1530.25,"id":19144236}]}]}
{"op":"mcm","clk":"11811458112","pt":1723307241404,"mc":[{"id":"1.231664751","rc":[{"batb":[[0,1.66,386.17]],"ltp":1.66,"tv":1530.25,"id":19144236}]}]}
{"op":"mcm","clk":"11811458266","pt":1723307242000,"mc":[{"id":"1.231664751","rc":[{"batl":[[1,7.8,0]],"ltp":2.48,"tv":250.72,"id":25173012}]}]}
{"op":"mcm","clk":"11811458591","pt":1723307243470,"mc":[{"id":"1.231664751","rc":[{"batb":[[0,1.66,186.17]],"ltp":1.66,"tv":1530.25,"id":19144236}]}]}
{"op":"mcm","clk":"11811458989","pt":1723307245479,"mc":[{"id":"1.231664751","rc":[{"trd":[[1.66,723.52]],"batb":[[0,1.51,450],[1,1.5,20],[2,1.38,2.25]],"batl":[[0,1.59,207.37],[1,1.69,69.63],[2,1.8,57.59]],"ltp":1.66,"tv":1914.79,"id":19144236},{"trd":[[2.5,20.51]],"ltp":2.5,"tv":258.82,"id":25173012}],"tv":2173.61}]}
{"op":"mcm","clk":"11811462445","pt":1723307261394,"mc":[{"id":"1.231664751","rc":[{"trd":[[1.59,402.32]],"batl":[[0,1.59,6.07]],"ltp":1.59,"tv":2316.09,"id":19144236},{"trd":[[2.68,1.37]],"ltp":2.68,"tv":259.59,"id":25173012}],"tv":2575.68}]}
{"op":"mcm","clk":"11811462860","pt":1723307263389,"mc":[{"id":"1.231664751","rc":[{"batl":[[0,1.69,69.63],[1,1.8,57.59],[2,2.1,17.66]],"ltp":1.59,"tv":2316.09,"id":19144236},{"batl":[[0,2.68,45.6]],"ltp":2.68,"tv":259.59,"id":25173012}]}]}
{"op":"mcm","clk":"11811463091","pt":1723307264490,"mc":[{"id":"1.231664751","rc":[{"batb":[[0,1.52,2.35],[1,1.51,450],[2,1.5,920]],"ltp":1.59,"tv":2316.09,"id":19144236}]}]}
{"op":"mcm","clk":"11811463686","pt":1723307267210,"mc":[{"id":"1.231664751","rc":[{"batb":[[0,1.53,143.95],[1,1.52,2.25],[2,1.51,450]],"ltp":1.59,"tv":2316.09,"id":19144236}]}]}
{"op":"mcm","clk":"11811464614","pt":1723307271381,"mc":[{"id":"1.231664751","rc":[{"batb":[[0,1.53,145.98]],"ltp":1.59,"tv":2316.09,"id":19144236}]}]}
{"op":"mcm","clk":"11811466648","pt":1723307280302,"mc":[{"id":"1.231664751","rc":[{"trd":[[1.69,5.97]],"batl":[[0,1.69,69.61]],"ltp":1.69,"tv":2316.11,"id":19144236},{"trd":[[2.44,3.36]],"ltp":2.44,"tv":259.6,"id":25173012}],"tv":2575.72}]}
{"op":"mcm","clk":"11811467212","pt":1723307282805,"mc":[{"id":"1.231664751","rc":[{"batb":[[0,1.9,9.91],[1,1.72,17.13],[2,1.65,9.85]],"ltp":2.44,"tv":259.6,"id":25173012}]}]}
{"op":"mcm","clk":"11811467713","pt":1723307285137,"mc":[{"id":"1.231664751","rc":[{"trd":[[1.69,6.12]],"batl":[[0,1.69,69.46]],"ltp":1.69,"tv":2316.26,"id":19144236},{"trd":[[2.44,3.46]],"ltp":2.44,"tv":259.7,"id":25173012}],"tv":2575.97}]}
{"op":"mcm","clk":"11811469362","pt":1723307292408,"mc":[{"id":"1.231664751","rc":[{"trd":[[1.59,402.41]],"batb":[[0,1.53,145.88]],"ltp":1.59,"tv":2316.35,"id":19144236},{"trd":[[2.68,1.42]],"batl":[[0,2.68,45.55]],"ltp":2.68,"tv":259.76,"id":25173012}],"tv":2576.11}]}
{"op":"mcm","clk":"11811471203","pt":1723307300444,"mc":[{"id":"1.231664751","rc":[{"batb":[[0,1.53,143.85]],"ltp":1.59,"tv":2316.35,"id":19144236}]}]}
{"op":"mcm","clk":"11811472016","pt":1723307304252,"mc":[{"id":"1.231664751","rc":[{"trd":[[1.69,6.27]],"batl":[[0,1.69,69.31]],"ltp":1.69,"tv":2316.5,"id":19144236},{"trd":[[2.44,3.56]],"ltp":2.44,"tv":259.86,"id":25173012}],"tv":2576.36}]}
{"op":"mcm","clk":"11811472322","pt":1723307305642,"mc":[{"id":"1.231664751","rc":[{"batb":[[0,1.56,2.03],[1,1.53,143.85],[2,1.52,2.25]],"ltp":1.69,"tv":2316.5,"id":19144236}]}]}
{"op":"mcm","clk":"11811472383","pt":1723307305928,"mc":[{"id":"1.231664751","rc":[{"trd":[[1.69,7.57]],"batl":[[0,1.69,68.01]],"ltp":1.69,"tv":2317.8,"id":19144236},{"trd":[[2.44,4.46]],"ltp":2.44,"tv":260.76,"id":25173012}],"tv":2578.56}]}
{"op":"mcm","clk":"11811473194","pt":1723307309434,"mc":[{"id":"1.231664751","rc":[{"trd":[[1.69,7.72]],"batl":[[0,1.69,67.86]],"ltp":1.69,"tv":2317.95,"id":19144236},{"trd":[[2.44,4.56]],"ltp":2.44,"tv":260.86,"id":25173012}],"tv":2578.81}]}
{"op":"mcm","clk":"11811473492","pt":1723307310925,"mc":[{"id":"1.231664751","rc":[{"trd":[[1.69,7.87]],"batl":[[0,1.69,67.71]],"ltp":1.69,"tv":2318.1,"id":19144236},{"trd":[[2.44,4.66]],"ltp":2.44,"tv":260.96,"id":25173012}],"tv":2579.06}]}
{"op":"mcm","clk":"11811475111","pt":1723307318159,"mc":[{"id":"1.231664751","rc":[{"trd":[[1.69,8.02]],"batl":[[0,1.69,67.56]],"ltp":1.69,"tv":2318.25,"id":19144236},{"trd":[[2.44,4.77]],"ltp":2.44,"tv":261.06,"id":25173012}],"tv":2579.31}]}
{"op":"mcm","clk":"11811475381","pt":1723307319344,"mc":[{"id":"1.231664751","rc":[{"trd":[[1.69,8.58]],"batl":[[0,1.69,67.28]],"ltp":1.69,"tv":2318.81,"id":19144236}],"tv":2579.87}]}
{"op":"mcm","clk":"11811476235","pt":1723307323243,"mc":[{"id":"1.231664751","rc":[{"trd":[[1.69,8.73]],"batl":[[0,1.69,67.13]],"ltp":1.69,"tv":2318.96,"id":19144236},{"trd":[[2.44,4.87]],"ltp":2.44,"tv":261.16,"id":25173012}],"tv":2580.12}]}
{"op":"mcm","clk":"11811476688","pt":1723307325450,"mc":[{"id":"1.231664751","rc":[{"trd":[[1.69,10.18]],"batl":[[0,1.69,65.68]],"ltp":1.69,"tv":2320.41,"id":19144236},{"trd":[[2.44,5.87]],"ltp":2.44,"tv":262.16,"id":25173012}],"tv":2582.57}]}
{"op":"mcm","clk":"11811477145","pt":1723307327640,"mc":[{"id":"1.231664751","rc":[{"trd":[[1.69,10.52]],"batl":[[0,1.69,65.51]],"ltp":1.69,"tv":2320.75,"id":19144236}],"tv":2582.91}]}
{"op":"mcm","clk":"11811477493","pt":1723307329539,"mc":[{"id":"1.231664751","rc":[{"batb":[[0,1.57,13.5],[1,1.56,2.03],[2,1.53,143.85]],"ltp":1.69,"tv":2320.75,"id":19144236}]}]}
{"op":"mcm","clk":"11811480783","pt":1723307344982,"mc":[{"id":"1.231664751","rc":[{"batl":[[0,2.52,0.1]],"ltp":2.44,"tv":262.16,"id":25173012}]}]}
{"op":"mcm","clk":"11811481258","pt":1723307347495,"mc":[{"id":"1.231664751","rc":[{"batb":[[0,1.6,150],[1,1.57,13.5],[2,1.56,2.03]],"ltp":1.69,"tv":2320.75,"id":19144236}]}]}
{"op":"mcm","clk":"11811481850","pt":1723307350376,"mc":[{"id":"1.231664751","rc":[{"batb":[[1,1.57,14.46]],"ltp":1.69,"tv":2320.75,"id":19144236}]}]}
{"op":"mcm","clk":"11811482505","pt":1723307353679,"mc":[{"id":"1.231664751","rc":[{"trd":[[1.69,36.86]],"batl":[[0,1.69,39.17]],"ltp":1.69,"tv":2347.09,"id":19144236},{"trd":[[2.44,24.11]],"ltp":2.44,"tv":280.4,"id":25173012}],"tv":2627.49}]}
{"op":"mcm","clk":"11811482655","pt":1723307354387,"mc":[{"id":"1.231664751","rc":[{"batb":[[1,1.57,13.5]],"ltp":1.69,"tv":2347.09,"id":19144236}]}]}
{"op":"mcm","clk":"11811483031","pt":1723307356192,"mc":[{"id":"1.231664751","rc":[{"trd":[[1.69,37.01]],"batl":[[0,1.69,39.02]],"ltp":1.69,"tv":2347.24,"id":19144236},{"trd":[[2.44,24.21]],"batl":[[0,2.6,0.1]],"ltp":2.44,"tv":280.5,"id":25173012}],"tv":2627.75}]}
{"op":"mcm","clk":"11811483524","pt":1723307358480,"mc":[{"id":"1.231664751","rc":[{"batl":[[0,2.72,0.2]],"ltp":2.44,"tv":280.5,"id":25173012}]}]}
{"op":"mcm","clk":"11811483951","pt":1723307360392,"mc":[{"id":"1.231664751","rc":[{"trd":[[1.69,73.09]],"batl":[[0,1.69,20.98]],"ltp":1.69,"tv":2383.32,"id":19144236}],"tv":2663.83}]}
{"op":"mcm","clk":"11811484006","pt":1723307360704,"mc":[{"id":"1.231664751","rc":[{"batb":[[0,1.61,2461.54],[1,1.6,150],[2,1.57,13.5]],"ltp":1.69,"tv":2383.32,"id":19144236}]}]}
{"op":"mcm","clk":"11811484374","pt":1723307362583,"mc":[{"id":"1.231664751","rc":[{"batl":[[1,1.71,1723.23],[2,1.8,57.48]],"ltp":1.69,"tv":2383.32,"id":19144236}]}]}
{"op":"mcm","clk":"11811484525","pt":1723307363387,"mc":[{"id":"1.231664751","rc":[{"trd":[[1.69,73.24]],"batb":[[1,1.6,151.82]],"batl":[[0,1.69,20.83],[1,1.8,57.59],[2,2.1,17.66]],"ltp":1.69,"tv":2383.47,"id":19144236},{"trd":[[2.44,24.31]],"ltp":2.44,"tv":280.6,"id":25173012}],"tv":2664.08}]}
{"op":"mcm","clk":"11811484615","pt":1723307363878,"mc":[{"id":"1.231664751","rc":[{"trd":[[1.69,73.39]],"batl":[[0,1.69,20.68]],"ltp":1.69,"tv":2383.62,"id":19144236},{"trd":[[2.44,24.41]],"ltp":2.44,"tv":280.7,"id":25173012}],"tv":2664.33}]}
{"op":"mcm","clk":"11811484803","pt":1723307364886,"mc":[{"id":"1.231664751","rc":[{"trd":[[1.69,74.29]],"batl":[[0,1.69,20.23]],"ltp":1.69,"tv":2384.52,"id":19144236}],"tv":2665.23}]}
{"op":"mcm","clk":"11811485084","pt":1723307366399,"mc":[{"id":"1.231664751","rc":[{"batb":[[1,1.6,150]],"ltp":1.69,"tv":2384.52,"id":19144236}]}]}
{"op":"mcm","clk":"11811485282","pt":1723307367388,"mc":[{"id":"1.231664751","rc":[{"trd":[[1.69,80.87]],"batl":[[0,1.69,13.65]],"ltp":1.69,"tv":2391.1,"id":19144236},{"trd":[[2.44,28.97]],"ltp":2.44,"tv":285.26,"id":25173012}],"tv":2676.37}]}
{"op":"mcm","clk":"11811486142","pt":1723307371834,"mc":[{"id":"1.231664751","rc":[{"trd":[[1.69,81.12]],"batl":[[0,1.69,13.4]],"ltp":1.69,"tv":2391.35,"id":19144236},{"trd":[[2.44,29.15]],"ltp":2.44,"tv":285.44,"id":25173012}],"tv":2676.79}]}
{"op":"mcm","clk":"11811486508","pt":1723307373604,"mc":[{"id":"1.231664751","rc":[{"trd":[[1.69,83]],"batl":[[0,1.69,12.46]],"ltp":1.69,"tv":2393.23,"id":19144236}],"tv":2678.67}]}
{"op":"mcm","clk":"11811487694","pt":1723307379906,"mc":[{"id":"1.231664751","rc":[{"batl":[[1,1.7,67.62],[2,1.8,57.48]],"ltp":1.69,"tv":2393.23,"id":19144236}]}]}
{"op":"mcm","clk":"11811487941","pt":1723307381102,"mc":[{"id":"1.231664751","rc":[{"trd":[[1.69,84.95]],"batl":[[0,1.69,10.51]],"ltp":1.69,"tv":2395.18,"id":19144236},{"trd":[[2.44,30.5]],"ltp":2.44,"tv":286.79,"id":25173012}],"tv":2681.97}]}
{"op":"mcm","clk":"11811488586","pt":1723307384203,"mc":[{"id":"1.231664751","rc":[{"trd":[[1.69,85.1]],"batl":[[0,1.69,10.36]],"ltp":1.69,"tv":2395.33,"id":19144236},{"trd":[[2.44,30.6]],"ltp":2.44,"tv":286.89,"id":25173012}],"tv":2682.22}]}
{"op":"mcm","clk":"11811488960","pt":1723307386119,"mc":[{"id":"1.231664751","rc":[{"trd":[[1.69,85.12]],"batl":[[0,1.69,10.34]],"ltp":1.69,"tv":2395.35,"id":19144236},{"trd":[[2.44,30.61]],"ltp":2.44,"tv":286.9,"id":25173012}],"tv":2682.26}]}
{"op":"mcm","clk":"11811489097","pt":1723307386860,"mc":[{"id":"1.231664751","rc":[{"batb":[[0,1.6,150],[1,1.57,13.5],[2,1.56,2.03]],"ltp":1.69,"tv":2395.35,"id":19144236}]}]}
{"op":"mcm","clk":"11811489370","pt":1723307388137,"mc":[{"id":"1.231664751","rc":[{"batl":[[0,3,0.58]],"ltp":2.44,"tv":286.9,"id":25173012}]}]}
{"op":"mcm","clk":"11811489999","pt":1723307390990,"mc":[{"id":"1.231664751","rc":[{"trd":[[1.69,85.66]],"batl":[[0,1.69,9.8]],"ltp":1.69,"tv":2395.89,"id":19144236},{"trd":[[2.44,30.99]],"ltp":2.44,"tv":287.28,"id":25173012}],"tv":2683.17}]}
{"op":"mcm","clk":"11811490356","pt":1723307392656,"mc":[{"id":"1.231664751","rc":[{"trd":[[1.69,85.81]],"batl":[[0,1.69,9.65]],"ltp":1.69,"tv":2396.04,"id":19144236},{"trd":[[2.44,31.09]],"ltp":2.44,"tv":287.38,"id":25173012}],"tv":2683.42}]}
{"op":"mcm","clk":"11811490729","pt":1723307394341,"mc":[{"id":"1.231664751","rc":[{"trd":[[1.62,0.1]],"ltp":1.62,"tv":2396.14,"id":19144236},{"trd":[[2.6,0.06]],"batl":[[0,3,0.52]],"ltp":2.6,"tv":287.44,"id":25173012}],"tv":2683.59}]}
{"op":"mcm","clk":"11811490908","pt":1723307395149,"mc":[{"id":"1.231664751","rc":[{"batb":[[1,1.56,2.03],[2,1.52,2.25]],"ltp":1.62,"tv":2396.14,"id":19144236}]}]}
{"op":"mcm","clk":"11811491222","pt":1723307396641,"mc":[{"id":"1.231664751","rc":[{"trd":[[1.69,86.25]],"batl":[[0,1.69,9.43]],"ltp":1.69,"tv":2396.58,"id":19144236}],"tv":2684.02}]}
{"op":"mcm","clk":"11811491630","pt":1723307398641,"mc":[{"id":"1.231664751","rc":[{"batl":[[0,1.67,3446.23],[1,1.69,9.43],[2,1.7,67.62]],"ltp":1.69,"tv":2396.58,"id":19144236}]}]}
{"op":"mcm","clk":"11811491709","pt":1723307398927,"mc":[{"id":"1.231664751","rc":[{"trd":[[1.67,138.44]],"batl":[[0,1.67,3445.86]],"ltp":1.67,"tv":2396.94,"id":19144236},{"trd":[[2.48,13.87]],"batl":[[0,3,0.48]],"ltp":2.48,"tv":287.69,"id":25173012}],"tv":2684.63}]}
{"op":"mcm","clk":"11811493236","pt":1723307405301,"mc":[{"id":"1.231664751","rc":[{"batb":[[0,1.72,17.19],[1,1.55,1818.18],[2,1.54,1851.85]],"ltp":2.48,"tv":287.69,"id":25173012}]}]}
{"op":"mcm","clk":"11811493536","pt":1723307406402,"mc":[{"id":"1.231664751","rc":[{"batl":[[0,2.62,2.64],[1,3,0.48]],"ltp":2.48,"tv":287.69,"id":25173012}]}]}
{"op":"mcm","clk":"11811494739","pt":1723307411445,"mc":[{"id":"1.231664751","rc":[{"trd":[[1.67,138.63]],"batl":[[0,1.67,3445.68]],"ltp":1.67,"tv":2397.13,"id":19144236},{"trd":[[2.48,14]],"ltp":2.48,"tv":287.81,"id":25173012}],"tv":2684.95}]}
{"op":"mcm","clk":"11811494828","pt":1723307411812,"mc":[{"id":"1.231664751","rc":[{"trd":[[1.67,140.03]],"batl":[[0,1.67,3444.28]],"ltp":1.67,"tv":2398.53,"id":19144236},{"trd":[[2.48,14.94]],"ltp":2.48,"tv":288.76,"id":25173012}],"tv":2687.29}]}
{"op":"mcm","clk":"11811495084","pt":1723307412937,"mc":[{"id":"1.231664751","rc":[{"trd":[[1.67,140.11]],"batl":[[0,1.67,3444.24]],"ltp":1.67,"tv":2398.61,"id":19144236}],"tv":2687.37}]}
{"op":"mcm","clk":"11811495503","pt":1723307414503,"mc":[{"id":"1.231664751","rc":[{"trd":[[1.61,0.67]],"ltp":1.61,"tv":2399.28,"id":19144236},{"trd":[[2.62,0.41]],"batl":[[0,2.62,3.13]],"ltp":2.62,"tv":289.17,"id":25173012}],"tv":2688.45}]}
{"op":"mcm","clk":"11811496132","pt":1723307417123,"mc":[{"id":"1.231664751","rc":[{"trd":[[1.67,140.28]],"batl":[[0,1.67,3444.07]],"ltp":1.67,"tv":2399.45,"id":19144236},{"trd":[[2.48,15.05]],"ltp":2.48,"tv":289.28,"id":25173012}],"tv":2688.73}]}
{"op":"mcm","clk":"11811496288","pt":1723307417739,"mc":[{"id":"1.231664751","rc":[{"trd":[[1.67,140.43]],"batl":[[0,1.67,3443.92]],"ltp":1.67,"tv":2399.6,"id":19144236},{"trd":[[2.48,15.15]],"ltp":2.48,"tv":289.38,"id":25173012}],"tv":2688.98}]}
{"op":"mcm","clk":"11811496698","pt":1723307419499,"mc":[{"id":"1.231664751","rc":[{"trd":[[1.67,5768.42]],"batl":[[0,1.67,629.93]],"ltp":1.67,"tv":8027.59,"id":19144236}],"tv":8316.97}]}
{"op":"mcm","clk":"11811497074","pt":1723307421066,"mc":[{"id":"1.231664751","rc":[{"trd":[[1.61,4.3],[1.66,724.88]],"batl":[[0,1.61,6295.33],[1,1.67,629.93],[2,1.69,9.43]],"ltp":1.61,"tv":8032.58,"id":19144236},{"trd":[[2.5,21.41],[2.62,2.64]],"batl":[[0,3,0.48],[1,3,0]],"ltp":2.62,"tv":292.51,"id":25173012}],"tv":8325.09}]}
{"op":"mcm","clk":"11811497345","pt":1723307422242,"mc":[{"id":"1.231664751","rc":[{"trd":[[1.61,4.46]],"batl":[[0,1.61,6295.17]],"ltp":1.61,"tv":8032.74,"id":19144236},{"trd":[[2.62,2.74]],"ltp":2.62,"tv":292.61,"id":25173012}],"tv":8325.35}]}
{"op":"mcm","clk":"11811497857","pt":1723307424540,"mc":[{"id":"1.231664751","rc":[{"trd":[[1.61,4.49]],"batl":[[0,1.61,6295.24]],"ltp":1.61,"tv":8032.77,"id":19144236},{"trd":[[2.62,2.76]],"ltp":2.62,"tv":292.63,"id":25173012}],"tv":8325.4}]}
{"op":"mcm","clk":"11811498107","pt":1723307425619,"mc":[{"id":"1.231664751","rc":[{"batl":[[0,1.61,6255.24]],"ltp":1.61,"tv":8032.77,"id":19144236}]}]}
{"op":"mcm","clk":"11811498340","pt":1723307426632,"mc":[{"id":"1.231664751","rc":[{"trd":[[1.61,5.57]],"batl":[[0,1.61,6254.16],[1,1.66,1.4],[2,1.67,629.93]],"ltp":1.61,"tv":8033.85,"id":19144236},{"trd":[[2.62,3.42]],"ltp":2.62,"tv":293.29,"id":25173012}],"tv":8327.14}]}
{"op":"mcm","clk":"11811498900","pt":1723307429350,"mc":[{"id":"1.231664751","rc":[{"trd":[[1.61,11311.57]],"batl":[[0,1.61,601.16]],"ltp":1.61,"tv":19339.85,"id":19144236}],"tv":19633.14}]}
{"op":"mcm","clk":"11811499036","pt":1723307430061,"mc":[{"id":"1.231664751","rc":[{"batb":[[0,1.59,2958]],"ltp":1.61,"tv":19339.85,"id":19144236}]}]}
{"op":"mcm","clk":"11811499197","pt":1723307430749,"mc":[{"id":"1.231664751","rc":[{"trd":[[1.61,11384.93]],"batl":[[0,1.61,527.8]],"ltp":1.61,"tv":19413.21,"id":19144236},{"trd":[[2.62,48.5]],"ltp":2.62,"tv":338.37,"id":25173012}],"tv":19751.58}]}
{"op":"mcm","clk":"11811499540","pt":1723307432368,"mc":[{"id":"1.231664751","rc":[{"batl":[[0,1.61,527.93],[2,1.69,9.43]],"ltp":1.61,"tv":19413.21,"id":19144236}]}]}
{"op":"mcm","clk":"11811499817","pt":1723307433670,"mc":[{"id":"1.231664751","rc":[{"trd":[[1.6,0.26],[1.61,11456.43]],"batl":[[0,1.61,492.05]],"ltp":1.61,"tv":19484.97,"id":19144236}],"tv":19823.34}]}
{"op":"mcm","clk":"11811499994","pt":1723307434471,"mc":[{"id":"1.231664751","rc":[{"trd":[[1.61,11456.87]],"batl":[[0,1.61,491.61]],"ltp":1.61,"tv":19485.41,"id":19144236},{"trd":[[2.62,48.77]],"ltp":2.62,"tv":338.64,"id":25173012}],"tv":19824.05}]}
{"op":"mcm","clk":"11811500190","pt":1723307435291,"mc":[{"id":"1.231664751","rc":[{"batb":[[2,1.54,300]],"ltp":1.61,"tv":19485.41,"id":19144236},{"batb":[[0,2.52,90.16],[1,1.72,17.19],[2,1.55,1818.18]],"ltp":2.62,"tv":338.64,"id":25173012}]}]}
{"op":"mcm","clk":"11811500532","pt":1723307436665,"mc":[{"id":"1.231664751","rc":[{"trd":[[1.61,11459.07]],"batl":[[0,1.61,483.31]],"ltp":1.61,"tv":19487.61,"id":19144236},{"batb":[[2,1.56,1000]],"ltp":2.62,"tv":338.64,"id":25173012}],"tv":19826.25}]}
{"op":"mcm","clk":"11811500662","pt":1723307437260,"mc":[{"id":"1.231664751","rc":[{"batb":[[2,1.56,2000]],"ltp":2.62,"tv":338.64,"id":25173012}]}]}
{"op":"mcm","clk":"11811500944","pt":1723307438544,"mc":[{"id":"1.231664751","rc":[{"trd":[[1.61,11459.16]],"batl":[[0,1.61,379.39]],"ltp":1.61,"tv":19487.7,"id":19144236},{"trd":[[2.62,48.82]],"batb":[[2,1.56,2500]],"ltp":2.62,"tv":338.69,"id":25173012}],"tv":19826.39}]}
{"op":"mcm","clk":"11811501163","pt":1723307439453,"mc":[{"id":"1.231664751","rc":[{"trd":[[1.61,12060.71]],"batl":[[0,1.61,77.84]],"ltp":1.61,"tv":20089.25,"id":19144236},{"trd":[[2.62,49.77]],"ltp":2.62,"tv":339.64,"id":25173012}],"tv":20428.9}]}
{"op":"mcm","clk":"11811501447","pt":1723307440462,"mc":[{"id":"1.231664751","rc":[{"trd":[[1.61,12060.94]],"batb":[[1,1.54,300],[2,1.52,2.25]],"batl":[[0,1.61,77.61]],"ltp":1.61,"tv":20089.48,"id":19144236},{"trd":[[2.62,49.91]],"ltp":2.62,"tv":339.78,"id":25173012}],"tv":20429.27}]}
{"op":"mcm","clk":"11811501737","pt":1723307441677,"mc":[{"id":"1.231664751","rc":[{"trd":[[1.61,12097.55]],"batb":[[0,1.6,461.22],[1,1.59,2958],[2,1.54,300]],"batl":[[0,1.61,41]],"ltp":1.61,"tv":20126.09,"id":19144236},{"trd":[[2.62,72.41]],"ltp":2.62,"tv":362.28,"id":25173012}],"tv":20488.38}]}
{"op":"mcm","clk":"11811501975","pt":1723307442657,"mc":[{"id":"1.231664751","rc":[{"trd":[[1.61,12100.48]],"batl":[[0,1.61,38.07]],"ltp":1.61,"tv":20129.02,"id":19144236},{"trd":[[2.62,74.21]],"ltp":2.62,"tv":364.08,"id":25173012}],"tv":20493.11}]}
{"op":"mcm","clk":"11811502138","pt":1723307443356,"mc":[{"id":"1.231664751","rc":[{"trd":[[1.6,2.06],[1.61,12101.65]],"batb":[[0,1.6,460.32]],"batl":[[0,1.61,36.9]],"ltp":1.61,"tv":20131.99,"id":19144236},{"trd":[[2.62,74.93]],"ltp":2.62,"tv":364.8,"id":25173012}],"tv":20496.8}]}
{"op":"mcm","clk":"11811502614","pt":1723307445347,"mc":[{"id":"1.231664751","rc":[{"trd":[[1.6,3.06],[1.61,12101.81]],"batb":[[0,1.6,459.82]],"batl":[[0,1.61,36.74]],"ltp":1.61,"tv":20133.15,"id":19144236},{"trd":[[2.62,75.03]],"ltp":2.62,"tv":364.9,"id":25173012}],"tv":20498.06}]}
{"op":"mcm","clk":"11811503055","pt":1723307447383,"mc":[{"id":"1.231664751","rc":[{"trd":[[1.61,12175.29]],"batl":[[0,1.66,21.09],[1,1.69,9.43],[2,1.7,67.62]],"ltp":1.61,"tv":20206.63,"id":19144236},{"batl":[[0,3,0.84]],"ltp":2.62,"tv":364.9,"id":25173012}],"tv":20571.54}]}
{"op":"mcm","clk":"11811503500","pt":1723307449455,"mc":[{"id":"1.231664751","rc":[{"batb":[[1,1.54,300],[2,1.5,24.5]],"ltp":1.61,"tv":20206.63,"id":19144236},{"batl":[[0,3,0.94]],"ltp":2.62,"tv":364.9,"id":25173012}]}]}
{"op":"mcm","clk":"11811503635","pt":1723307450051,"mc":[{"id":"1.231664751","rc":[{"batl":[[0,2.62,8.12],[1,3,0.48]],"ltp":2.62,"tv":364.9,"id":25173012}]}]}
{"op":"mcm","clk":"11811503940","pt":1723307451571,"mc":[{"id":"1.231664751","rc":[{"batb":[[0,1.6,460.29]],"batl":[[0,1.63,296.32],[1,1.66,21.09],[2,1.69,9.43]],"ltp":1.61,"tv":20206.63,"id":19144236}]}]}
{"op":"mcm","clk":"11811504163","pt":1723307452583,"mc":[{"id":"1.231664751","rc":[{"batb":[[0,1.6,612.29]],"ltp":1.61,"tv":20206.63,"id":19144236}]}]}
{"op":"mcm","clk":"11811504372","pt":1723307453443,"mc":[{"id":"1.231664751","rc":[{"trd":[[1.61,12177.65]],"batb":[[0,1.61,2921.26],[1,1.6,611.82],[2,1.54,300]],"ltp":1.61,"tv":20208.99,"id":19144236},{"trd":[[2.62,76.48]],"batl":[[0,2.62,6.77]],"ltp":2.62,"tv":366.35,"id":25173012}],"tv":20575.34}]}
{"op":"mcm","clk":"11811504576","pt":1723307454466,"mc":[{"id":"1.231664751","rc":[{"batb":[[0,1.61,2921.73]],"ltp":1.61,"tv":20208.99,"id":19144236}]}]}
{"op":"mcm","clk":"11811504816","pt":1723307455594,"mc":[{"id":"1.231664751","rc":[{"batb":[[1,1.54,300],[2,1.5,24.5]],"ltp":1.61,"tv":20208.99,"id":19144236}]}]}
{"op":"mcm","clk":"11811505014","pt":1723307456409,"mc":[{"id":"1.231664751","rc":[{"trd":[[1.63,1.2]],"batl":[[0,1.63,295.72],[1,1.66,19.69]],"ltp":1.63,"tv":20210.18,"id":19144236},{"batl":[[0,2.62,7.67]],"ltp":2.62,"tv":366.35,"id":25173012}],"tv":20576.54}]}
{"op":"mcm","clk":"11811505228","pt":1723307457267,"mc":[{"id":"1.231664751","rc":[{"trd":[[1.63,1.5]],"batl":[[0,1.63,295.57]],"ltp":1.63,"tv":20210.48,"id":19144236}],"tv":20576.84}]}
{"op":"mcm","clk":"11811505503","pt":1723307458547,"mc":[{"id":"1.231664751","rc":[{"trd":[[1.61,12179.91]],"batb":[[0,1.54,300],[1,1.5,24.5],[2,1.42,2380.95]],"batl":[[0,1.62,73.04],[1,1.63,295.57],[2,1.66,19.69]],"ltp":1.61,"tv":20212.74,"id":19144236},{"trd":[[2.62,76.68],[2.64,0.29]],"batb":[[0,2.68,19.09],[1,2.52,90.16],[2,1.72,17.19]],"batl":[[0,3,0.48],[1,3,0]],"ltp":2.64,"tv":366.84,"id":25173012}],"tv":20579.59}]}
{"op":"mcm","clk":"11811505656","pt":1723307459367,"mc":[{"id":"1.231664751","rc":[{"trd":[[2.68,1.62]],"batb":[[0,2.68,18.99]],"ltp":2.68,"tv":367.04,"id":25173012}],"tv":20579.79}]}
{"op":"mcm","clk":"11811505906","pt":1723307460496,"mc":[{"id":"1.231664751","rc":[{"trd":[[1.6,19.97]],"ltp":1.6,"tv":20229.65,"id":19144236},{"trd":[[2.68,11.71]],"batb":[[0,2.68,8.9]],"ltp":2.68,"tv":377.13,"id":25173012}],"tv":20606.79}]}
{"op":"mcm","clk":"11811506329","pt":1723307462477,"mc":[{"id":"1.231664751","rc":[{"batl":[[2,1.69,9.43]],"ltp":1.6,"tv":20229.65,"id":19144236}]}]}
{"op":"mcm","clk":"11811506458","pt":1723307463067,"mc":[{"id":"1.231664751","rc":[{"trd":[[2.68,11.92]],"batb":[[0,2.68,8.8]],"ltp":2.68,"tv":377.33,"id":25173012}],"tv":20606.99}]}
{"op":"mcm","clk":"11811506711","pt":1723307464271,"mc":[{"id":"1.231664751","rc":[{"trd":[[1.6,22.79]],"ltp":1.6,"tv":20232.47,"id":19144236},{"trd":[[2.68,13.61]],"batb":[[0,2.68,7.11]],"ltp":2.68,"tv":379.02,"id":25173012}],"tv":20611.5}]}
{"op":"mcm","clk":"11811506830","pt":1723307464861,"mc":[{"id":"1.231664751","rc":[{"batb":[[0,1.59,2957.1],[1,1.54,300],[2,1.5,24.5]],"ltp":1.6,"tv":20232.47,"id":19144236}]}]}
{"op":"mcm","clk":"11811507222","pt":1723307466681,"mc":[{"id":"1.231664751","rc":[{"trd":[[1.62,20.95]],"batl":[[0,1.6,125.88],[1,1.62,52.19],[2,1.63,295.57]],"ltp":1.62,"tv":20253.32,"id":19144236},{"trd":[[2.6,13.05],[2.68,27.83]],"batb":[[0,2.52,90.16],[1,1.72,17.19],[2,1.56,2500]],"ltp":2.6,"tv":406.23,"id":25173012}],"tv":20659.56}]}
{"op":"mcm","clk":"11811507601","pt":1723307468493,"mc":[{"id":"1.231664751","rc":[{"batb":[[1,1.58,182.13],[2,1.54,300]],"batl":[[0,1.6,125.99]],"ltp":1.62,"tv":20253.32,"id":19144236}]}]}
{"op":"mcm","clk":"11811507811","pt":1723307469396,"mc":[{"id":"1.231664751","rc":[{"trd":[[1.6,22.96]],"batb":[[2,1.56,103.83]],"batl":[[0,1.6,110.71]],"ltp":1.6,"tv":20253.49,"id":19144236},{"trd":[[2.66,0.1]],"ltp":2.66,"tv":406.33,"id":25173012}],"tv":20659.83}]}
{"op":"mcm","clk":"11811508107","pt":1723307470680,"mc":[{"id":"1.231664751","rc":[{"trd":[[1.6,28.2]],"batb":[[2,1.56,349.9]],"batl":[[0,1.6,105.48]],"ltp":1.6,"tv":20258.73,"id":19144236},{"trd":[[2.66,3.25]],"batl":[[0,3,0.58]],"ltp":2.66,"tv":409.48,"id":25173012}],"tv":20668.22}]}
{"op":"mcm","clk":"11811508280","pt":1723307471605,"mc":[{"id":"1.231664751","rc":[{"trd":[[1.6,28.22]],"batb":[[1,1.58,334.13],[2,1.57,52.58]],"batl":[[0,1.6,105.46]],"ltp":1.6,"tv":20258.75,"id":19144236}],"tv":20668.24}]}
{"op":"mcm","clk":"11811508681","pt":1723307473490,"mc":[{"id":"1.231664751","rc":[{"trd":[[1.59,402.88]],"batb":[[0,1.59,2956.86]],"ltp":1.59,"tv":20259.22,"id":19144236},{"batl":[[0,3,1.29]],"ltp":2.66,"tv":409.48,"id":25173012}],"tv":20668.71}]}
{"op":"mcm","clk":"11811508909","pt":1723307474666,"mc":[{"id":"1.231664751","rc":[{"trd":[[1.6,28.42]],"batl":[[0,1.6,93.28],[1,1.63,295.57],[2,1.69,9.43]],"ltp":1.6,"tv":20259.43,"id":19144236}],"tv":20668.91}]}
{"op":"mcm","clk":"11811509153","pt":1723307475682,"mc":[{"id":"1.231664751","rc":[{"trd":[[1.6,30.66]],"batl":[[0,1.6,92.16]],"ltp":1.6,"tv":20261.66,"id":19144236},{"batl":[[0,2.72,1.08],[1,3,0.38]],"ltp":2.66,"tv":409.48,"id":25173012}],"tv":20671.15}]}
{"op":"mcm","clk":"11811509261","pt":1723307476165,"mc":[{"id":"1.231664751","rc":[{"trd":[[1.6,39.92]],"batb":[[1,1.58,152]],"batl":[[0,1.6,87.53]],"ltp":1.6,"tv":20270.93,"id":19144236}],"tv":20680.42}]}
{"op":"mcm","clk":"11811509558","pt":1723307477582,"mc":[{"id":"1.231664751","rc":[{"trd":[[1.6,40.4]],"batb":[[2,1.55,80]],"batl":[[0,1.6,87.29]],"ltp":1.6,"tv":20271.4,"id":19144236},{"batl":[[0,3,1.36],[1,3,0]],"ltp":2.66,"tv":409.48,"id":25173012}],"tv":20680.89}]}
{"op":"mcm","clk":"11811509749","pt":1723307478483,"mc":[{"id":"1.231664751","rc":[{"trd":[[1.59,786.6],[1.6,65.97]],"batb":[[0,1.59,2765]],"batl":[[0,1.6,74.33]],"ltp":1.6,"tv":20680.69,"id":19144236},{"trd":[[2.66,3.46]],"batl":[[0,2.72,1.05],[1,3,0.38]],"ltp":2.66,"tv":409.7,"id":25173012}],"tv":21090.4}]}
{"op":"mcm","clk":"11811509973","pt":1723307479598,"mc":[{"id":"1.231664751","rc":[{"trd":[[1.59,795.6],[1.6,80.85]],"batb":[[0,1.59,2760.5]],"batl":[[0,1.6,66.87]],"ltp":1.6,"tv":20704.57,"id":19144236},{"trd":[[2.66,3.48]],"ltp":2.66,"tv":409.72,"id":25173012}],"tv":21114.29}]}
{"op":"mcm","clk":"11811510178","pt":1723307480595,"mc":[{"id":"1.231664751","rc":[{"trd":[[1.59,2687.16],[1.6,81.59]],"batb":[[0,1.59,1814.72]],"batl":[[0,1.6,66.13]],"ltp":1.59,"tv":22596.87,"id":19144236},{"trd":[[2.66,3.93]],"batl":[[0,2.68,1.33],[1,3,0.48]],"ltp":2.66,"tv":410.16,"id":25173012}],"tv":23007.04}]}
{"op":"mcm","clk":"11811510389","pt":1723307481601,"mc":[{"id":"1.231664751","rc":[{"trd":[[1.59,2687.72],[1.6,213.85]],"batb":[[0,1.61,5.91],[1,1.6,12.69],[2,1.59,1814.44]],"batl":[[0,1.63,295.57],[1,1.69,9.43],[2,1.7,67.6]],"ltp":1.6,"tv":22729.69,"id":19144236},{"batl":[[0,2.68,2.08]],"ltp":2.66,"tv":410.16,"id":25173012}],"tv":23139.86}]}
{"op":"mcm","clk":"11811510810","pt":1723307483680,"mc":[{"id":"1.231664751","rc":[{"batl":[[0,2.68,1.48]],"ltp":2.66,"tv":410.16,"id":25173012}]}]}
{"op":"mcm","clk":"11811510854","pt":1723307483896,"mc":[{"id":"1.231664751","rc":[{"batb":[[1,1.6,12.7]],"ltp":1.6,"tv":22729.69,"id":19144236}]}]}
{"op":"mcm","clk":"11811511482","pt":1723307486608,"mc":[{"id":"1.231664751","rc":[{"batb":[[1,1.6,28.47]],"ltp":1.6,"tv":22729.69,"id":19144236}]}]}
{"op":"mcm","clk":"11811511624","pt":1723307487299,"mc":[{"id":"1.231664751","rc":[{"batb":[[1,1.6,34.38]],"ltp":1.6,"tv":22729.69,"id":19144236},{"batl":[[0,2.66,1.51],[1,3,1.2]],"ltp":2.66,"tv":410.16,"id":25173012}]}]}
{"op":"mcm","clk":"11811511854","pt":1723307488482,"mc":[{"id":"1.231664751","rc":[{"batb":[[1,1.6,34.48]],"ltp":1.6,"tv":22729.69,"id":19144236}]}]}
{"op":"mcm","clk":"11811512260","pt":1723307490494,"mc":[{"id":"1.231664751","rc":[{"batb":[[1,1.6,34.46]],"ltp":1.6,"tv":22729.69,"id":19144236},{"batl":[[0,2.66,1.7]],"ltp":2.66,"tv":410.16,"id":25173012}]}]}
{"op":"mcm","clk":"11811512496","pt":1723307491590,"mc":[{"id":"1.231664751","rc":[{"trd":[[1.63,18.96]],"batb":[[1,1.6,36.98]],"batl":[[0,1.63,278.11]],"ltp":1.63,"tv":22747.15,"id":19144236},{"trd":[[2.58,11.03]],"batl":[[0,2.66,4.28]],"ltp":2.58,"tv":421.2,"id":25173012}],"tv":23168.35}]}
{"op":"mcm","clk":"11811512656","pt":1723307492393,"mc":[{"id":"1.231664751","rc":[{"batb":[[1,1.6,36.88]],"ltp":1.63,"tv":22747.15,"id":19144236}]}]}
{"op":"mcm","clk":"11811512890","pt":1723307493499,"mc":[{"id":"1.231664751","rc":[{"trd":[[1.61,12191.89],[1.63,20.52]],"batb":[[0,1.6,36.98],[1,1.59,1814.44],[2,1.55,80]],"batl":[[0,1.61,3440.15],[1,1.63,276.85],[2,1.69,9.43]],"ltp":1.61,"tv":22760.7,"id":19144236},{"trd":[[2.58,11.64],[2.62,76.78]],"batl":[[0,2.66,6.75]],"ltp":2.62,"tv":421.9,"id":25173012}],"tv":23182.61}]}
{"op":"mcm","clk":"11811513107","pt":1723307494512,"mc":[{"id":"1.231664751","rc":[{"trd":[[1.6,214.41]],"batb":[[0,1.6,36.7]],"ltp":1.6,"tv":22761.26,"id":19144236},{"batl":[[0,2.66,6.69]],"ltp":2.62,"tv":421.9,"id":25173012}],"tv":23183.17}]}
{"op":"mcm","clk":"11811513312","pt":1723307495480,"mc":[{"id":"1.231664751","rc":[{"trd":[[1.6,214.61],[1.61,12864.97]],"batb":[[0,1.6,36.6]],"batl":[[0,1.61,2767.07]],"ltp":1.6,"tv":23434.55,"id":19144236},{"trd":[[2.62,490.39]],"batl":[[1,2.68,2.51],[2,3,0.48]],"ltp":2.62,"tv":835.51,"id":25173012}],"tv":24270.06}]}
{"op":"mcm","clk":"11811513542","pt":1723307496585,"mc":[{"id":"1.231664751","rc":[{"trd":[[1.61,12866.85],[1.63,176.35]],"batl":[[0,1.63,198.94],[1,1.69,9.43],[2,1.7,67.6]],"ltp":1.63,"tv":23592.24,"id":19144236},{"trd":[[2.62,490.44]],"ltp":2.62,"tv":835.56,"id":25173012}],"tv":24427.81}]}
{"op":"mcm","clk":"11811513958","pt":1723307498679,"mc":[{"id":"1.231664751","rc":[{"trd":[[1.61,12867.01],[1.63,177.46]],"batb":[[1,1.56,152]],"batl":[[0,1.61,5.35],[1,1.63,198.38],[2,1.69,9.43]],"ltp":1.61,"tv":23593.53,"id":19144236},{"trd":[[2.62,490.54]],"batl":[[2,5,0.57]],"ltp":2.62,"tv":835.66,"id":25173012}],"tv":24429.19}]}
{"op":"mcm","clk":"11811514093","pt":1723307499422,"mc":[{"id":"1.231664751","rc":[{"trd":[[1.61,12867.04]],"batl":[[0,1.61,5.34]],"ltp":1.61,"tv":23593.56,"id":19144236}],"tv":24429.22}]}
{"op":"mcm","clk":"11811514344","pt":1723307500604,"mc":[{"id":"1.231664751","rc":[{"trd":[[1.61,12868.15]],"batl":[[0,1.61,4.23]],"ltp":1.61,"tv":23594.66,"id":19144236},{"trd":[[2.62,491.22]],"batl":[[0,2.66,5.8],[1,2.68,2.59]],"ltp":2.62,"tv":836.34,"id":25173012}],"tv":24431.01}]}
{"op":"mcm","clk":"11811514526","pt":1723307501628,"mc":[{"id":"1.231664751","rc":[{"trd":[[1.61,12868.53],[1.63,232.43]],"batl":[[0,1.63,170.9],[1,1.69,9.43],[2,1.7,67.6]],"ltp":1.63,"tv":23650.01,"id":19144236},{"batl":[[1,2.68,2.3]],"ltp":2.62,"tv":836.34,"id":25173012}],"tv":24486.35}]}
{"op":"mcm","clk":"11811514665","pt":1723307502316,"mc":[{"id":"1.231664751","rc":[{"trd":[[1.61,12868.81],[1.63,233.22]],"batl":[[0,1.63,170.41]],"ltp":1.61,"tv":23651.08,"id":19144236},{"trd":[[2.58,11.76],[2.62,491.39]],"batl":[[0,2.62,2.91],[1,2.66,5.8],[2,2.68,2.3]],"ltp":2.62,"tv":836.63,"id":25173012}],"tv":24487.72}]}
{"op":"mcm","clk":"11811514952","pt":1723307503600,"mc":[{"id":"1.231664751","rc":[{"trd":[[1.56,304],[1.58,0.55],[1.59,2691.6],[1.6,280.59],[1.61,13043.39]],"batb":[[0,1.55,80],[1,1.54,300],[2,1.51,300]],"batl":[[0,1.56,388.82],[1,1.61,411.16],[2,1.63,170.41]],"ltp":1.56,"tv":24199.69,"id":19144236},{"trd":[[2.62,496.89],[2.66,9.73],[2.68,30.13],[2.72,0.1]],"batl":[[0,5,0.47],[1,2.66,0],[2,2.68,0]],"ltp":2.72,"tv":850.33,"id":25173012}],"tv":25050.02}]}
{"op":"mcm","clk":"11811515174","pt":1723307504687,"mc":[{"id":"1.231664751","rc":[{"trd":[[1.56,1081.29]],"batb":[[0,1.6,2098.11],[1,1.55,80],[2,1.54,300]],"batl":[[0,1.61,411.16],[1,1.63,170.41],[2,1.69,9.43]],"ltp":1.56,"tv":24976.98,"id":19144236},{"trd":[[2.78,0.2]],"ltp":2.78,"tv":850.53,"id":25173012}],"tv":25827.51}]}
{"op":"mcm","clk":"11811515354","pt":1723307505591,"mc":[{"id":"1.231664751","rc":[{"trd":[[1.6,282.4],[1.61,13048.53]],"batb":[[0,1.6,2097.2]],"batl":[[0,1.61,408.54]],"ltp":1.61,"tv":24983.93,"id":19144236},{"trd":[[2.62,496.95]],"ltp":2.62,"tv":850.59,"id":25173012}],"tv":25834.52}]}
{"op":"mcm","clk":"11811515567","pt":1723307506608,"mc":[{"id":"1.231664751","rc":[{"trd":[[1.6,469.68],[1.61,13053.77]],"batb":[[0,1.6,2003.56]],"batl":[[0,1.61,403.3]],"ltp":1.61,"tv":25176.45,"id":19144236},{"trd":[[2.62,500.17]],"ltp":2.62,"tv":853.81,"id":25173012}],"tv":26030.26}]}
{"op":"mcm","clk":"11811515710","pt":1723307507308,"mc":[{"id":"1.231664751","rc":[{"trd":[[1.6,808.4],[1.61,13053.97]],"batb":[[0,1.6,1834.2],[1,1.59,30.21],[2,1.55,80]],"batl":[[0,1.61,403.2]],"ltp":1.6,"tv":25515.37,"id":19144236}],"tv":26369.19}]}
{"op":"mcm","clk":"11811515962","pt":1723307508645,"mc":[{"id":"1.231664751","rc":[{"trd":[[1.61,13054.28]],"batl":[[0,1.61,402.89]],"ltp":1.61,"tv":25515.68,"id":19144236},{"trd":[[2.62,500.36]],"ltp":2.62,"tv":854.0,"id":25173012}],"tv":26369.69}]}
{"op":"mcm","clk":"11811516202","pt":1723307509598,"mc":[{"id":"1.231664751","rc":[{"trd":[[1.61,13063.57]],"batb":[[2,1.54,300]],"batl":[[0,1.61,396.11]],"ltp":1.61,"tv":25524.98,"id":19144236},{"trd":[[2.62,502.98]],"ltp":2.62,"tv":856.62,"id":25173012}],"tv":26381.61}]}
{"op":"mcm","clk":"11811516391","pt":1723307510512,"mc":[{"id":"1.231664751","rc":[{"trd":[[1.6,1033.82],[1.61,13067.27]],"batb":[[0,1.6,1721.49]],"batl":[[0,1.61,393.79],[1,1.69,9.43],[2,1.7,67.6]],"ltp":1.61,"tv":25754.1,"id":19144236},{"trd":[[2.62,505.25]],"ltp":2.62,"tv":858.89,"id":25173012}],"tv":26613.0}]}
{"op":"mcm","clk":"11811516606","pt":1723307511626,"mc":[{"id":"1.231664751","rc":[{"trd":[[1.61,13067.64]],"batl":[[0,1.61,393.53]],"ltp":1.61,"tv":25754.46,"id":19144236},{"trd":[[2.62,505.35]],"ltp":2.62,"tv":858.99,"id":25173012}],"tv":26613.46}]}
{"op":"mcm","clk":"11811516777","pt":1723307512521,"mc":[{"id":"1.231664751","rc":[{"trd":[[1.61,13068.77]],"batl":[[0,1.61,392.4],[1,1.66,19.69],[2,1.69,9.43]],"ltp":1.61,"tv":25755.59,"id":19144236},{"trd":[[2.62,506.05]],"ltp":2.62,"tv":859.69,"id":25173012}],"tv":26615.28}]}
{"op":"mcm","clk":"11811517006","pt":1723307513644,"mc":[{"id":"1.231664751","rc":[{"trd":[[1.6,1036.4],[1.61,13068.93]],"batb":[[0,1.6,1720.2],[2,1.56,6.38]],"batl":[[0,1.61,392.24]],"ltp":1.61,"tv":25758.33,"id":19144236},{"trd":[[2.62,506.15]],"batl":[[0,9,0.5]],"ltp":2.62,"tv":859.79,"id":25173012}],"tv":26618.13}]}
{"op":"mcm","clk":"11811517232","pt":1723307514505,"mc":[{"id":"1.231664751","rc":[{"trd":[[1.6,1383.6],[1.61,13085.35]],"batb":[[0,1.6,1546.6],[2,1.57,405.73]],"batl":[[0,1.61,384.03],[1,1.65,4307.78],[2,1.66,19.69]],"ltp":1.61,"tv":26121.95,"id":19144236}],"tv":26981.75}]}
{"op":"mcm","clk":"11811517407","pt":1723307515421,"mc":[{"id":"1.231664751","rc":[{"trd":[[1.61,13103.95]],"batl":[[0,1.61,366.37],[1,1.65,5169.34]],"ltp":1.61,"tv":26140.55,"id":19144236},{"trd":[[2.62,516.43]],"ltp":2.62,"tv":870.07,"id":25173012}],"tv":27010.63}]}
{"op":"mcm","clk":"11811517591","pt":1723307516336,"mc":[{"id":"1.231664751","rc":[{"trd":[[1.6,1535.81],[1.61,13108.45]],"batb":[[0,1.6,1470.5]],"batl":[[0,1.61,362.07]],"ltp":1.61,"tv":26297.26,"id":19144236},{"trd":[[2.62,518.95]],"ltp":2.62,"tv":872.59,"id":25173012}],"tv":27169.85}]}
{"op":"mcm","clk":"11811517830","pt":1723307517613,"mc":[{"id":"1.231664751","rc":[{"trd":[[1.6,2056.13],[1.61,13113.74]],"batb":[[0,1.6,1210.34]],"batl":[[0,1.61,357.01]],"ltp":1.61,"tv":26822.87,"id":19144236},{"trd":[[2.62,521.91]],"ltp":2.62,"tv":875.55,"id":25173012}],"tv":27698.43}]}
{"op":"mcm","clk":"11811517942","pt":1723307518241,"mc":[{"id":"1.231664751","rc":[{"trd":[[1.6,2090.57],[1.61,13128.39]],"batb":[[0,1.6,1193.12]],"batl":[[0,1.61,342.36]],"ltp":1.6,"tv":26871.96,"id":19144236},{"trd":[[2.62,530.91]],"ltp":2.62,"tv":884.55,"id":25173012}],"tv":27756.52}]}
{"op":"mcm","clk":"11811518072","pt":1723307518833,"mc":[{"id":"1.231664751","rc":[{"trd":[[1.61,13128.7]],"batl":[[0,1.61,342.05]],"ltp":1.61,"tv":26872.27,"id":19144236},{"trd":[[2.62,531.09]],"ltp":2.62,"tv":884.74,"id":25173012}],"tv":27757.02}]}
{"op":"mcm","clk":"11811518309","pt":1723307520030,"mc":[{"id":"1.231664751","rc":[{"trd":[[1.6,2270.57]],"batb":[[0,1.6,1103.12]],"ltp":1.6,"tv":27052.27,"id":19144236}],"tv":27937.02}]}
{"op":"mcm","clk":"11811518603","pt":1723307521560,"mc":[{"id":"1.231664751","rc":[{"trd":[[1.6,2289.86],[1.61,13144.01]],"batb":[[0,1.6,1093.47]],"batl":[[0,1.61,326.74]],"ltp":1.61,"tv":27086.88,"id":19144236},{"trd":[[2.62,540.51]],"ltp":2.62,"tv":894.15,"id":25173012}],"tv":27981.03}]}
{"op":"mcm","clk":"11811518809","pt":1723307522558,"mc":[{"id":"1.231664751","rc":[{"trd":[[1.6,2313.71],[1.61,13144.33]],"batb":[[0,1.6,1081.55]],"batl":[[0,1.61,326.42]],"ltp":1.6,"tv":27111.04,"id":19144236},{"trd":[[2.62,540.71]],"ltp":2.62,"tv":894.35,"id":25173012}],"tv":28005.4}]}
{"op":"mcm","clk":"11811518983","pt":1723307523431,"mc":[{"id":"1.231664751","rc":[{"trd":[[1.6,2319.36],[1.61,13144.35]],"batb":[[0,1.6,1078.73]],"batl":[[0,1.61,326.4],[2,1.69,9.43]],"ltp":1.6,"tv":27116.71,"id":19144236},{"trd":[[2.62,540.72]],"ltp":2.62,"tv":894.36,"id":25173012}],"tv":28011.08}]}
{"op":"mcm","clk":"11811519223","pt":1723307524665,"mc":[{"id":"1.231664751","rc":[{"trd":[[1.61,13181.22]],"batl":[[0,1.61,292.86]],"ltp":1.61,"tv":27153.57,"id":19144236},{"trd":[[2.62,559.29]],"ltp":2.62,"tv":912.93,"id":25173012}],"tv":28066.51}]}
{"op":"mcm","clk":"11811519446","pt":1723307525676,"mc":[{"id":"1.231664751","rc":[{"trd":[[1.6,2476.99],[1.61,13182.22]],"batb":[[0,1.6,999.91]],"batl":[[0,1.61,291.86]],"ltp":1.61,"tv":27312.2,"id":19144236},{"trd":[[2.62,559.91]],"ltp":2.62,"tv":913.55,"id":25173012}],"tv":28225.76}]}
{"op":"mcm","clk":"11811519678","pt":1723307526634,"mc":[{"id":"1.231664751","rc":[{"trd":[[1.61,13214.26]],"batl":[[0,1.61,275.68]],"ltp":1.61,"tv":27344.25,"id":19144236},{"trd":[[2.62,560.11]],"batl":[[0,15,0.53]],"ltp":2.62,"tv":913.75,"id":25173012}],"tv":28258.01}]}
{"op":"mcm","clk":"11811519881","pt":1723307527638,"mc":[{"id":"1.231664751","rc":[{"trd":[[1.61,13765.62]],"batb":[[0,1.61,9730.36],[1,1.6,999.91],[2,1.59,30.21]],"batl":[[0,1.65,5169.34],[1,1.69,9.43],[2,1.7,67.6]],"ltp":1.61,"tv":27895.61,"id":19144236},{"batl":[[0,2.62,1.1],[1,15,0.53]],"ltp":2.62,"tv":913.75,"id":25173012}],"tv":28809.37}]}
{"op":"mcm","clk":"11811520057","pt":1723307528549,"mc":[{"id":"1.231664751","rc":[{"trd":[[1.61,13765.66]],"batb":[[0,1.61,6.04]],"batl":[[0,1.69,9.43],[1,1.7,67.6],[2,1.75,500]],"ltp":1.61,"tv":27895.65,"id":19144236},{"batl":[[0,2.62,2.67]],"ltp":2.62,"tv":913.75,"id":25173012}],"tv":28809.4}]}
{"op":"mcm","clk":"11811520178","pt":1723307529175,"mc":[{"id":"1.231664751","rc":[{"batl":[[0,2.62,2.78]],"ltp":2.62,"tv":913.75,"id":25173012}]}]}
{"op":"mcm","clk":"11811520506","pt":1723307530675,"mc":[{"id":"1.231664751","rc":[{"batb":[[1,1.59,30.21],[2,1.57,405.73]],"ltp":1.61,"tv":27895.65,"id":19144236},{"batl":[[0,2.62,12.03]],"ltp":2.62,"tv":913.75,"id":25173012}]}]}
{"op":"mcm","clk":"11811520684","pt":1723307531650,"mc":[{"id":"1.231664751","rc":[{"trd":[[1.61,13777.58]],"batb":[[0,1.59,30.44],[1,1.57,405.73],[2,1.56,6.38]],"ltp":1.61,"tv":27907.57,"id":19144236},{"batl":[[0,2.62,18.07]],"ltp":2.62,"tv":913.75,"id":25173012}],"tv":28821.33}]}
{"op":"mcm","clk":"11811520844","pt":1723307532550,"mc":[{"id":"1.231664751","rc":[{"trd":[[1.61,13796.52]],"batb":[[0,1.59,30.21]],"ltp":1.61,"tv":27926.51,"id":19144236},{"trd":[[2.62,571.22]],"batl":[[0,2.62,7.15]],"ltp":2.62,"tv":924.86,"id":25173012}],"tv":28851.38}]}
{"op":"mcm","clk":"11811521057","pt":1723307533658,"mc":[{"id":"1.231664751","rc":[{"trd":[[1.61,13808.33]],"batl":[[0,1.6,2330.96],[1,1.69,9.43],[2,1.7,67.6]],"ltp":1.61,"tv":27938.31,"id":19144236},{"trd":[[2.62,578.48]],"batl":[[0,15,0.53],[1,15,0]],"ltp":2.62,"tv":932.12,"id":25173012}],"tv":28870.44}]}
{"op":"mcm","clk":"11811521242","pt":1723307534673,"mc":[{"id":"1.231664751","rc":[{"trd":[[1.6,4471.47]],"batl":[[0,1.6,1333.74]],"ltp":1.6,"tv":29932.8,"id":19144236},{"trd":[[2.66,9.83]],"ltp":2.66,"tv":932.22,"id":25173012}],"tv":30865.02}]}
{"op":"mcm","clk":"11811521421","pt":1723307535562,"mc":[{"id":"1.231664751","rc":[{"trd":[[1.6,4471.82]],"batl":[[0,1.6,1340.07]],"ltp":1.6,"tv":29933.15,"id":19144236},{"trd":[[2.66,10.04]],"ltp":2.66,"tv":932.43,"id":25173012}],"tv":30865.58}]}
{"op":"mcm","clk":"11811521556","pt":1723307536363,"mc":[{"id":"1.231664751","rc":[{"trd":[[1.59,2692.36],[1.6,4497.71]],"batb":[[0,1.59,29.84]],"batl":[[0,1.6,1326.79]],"ltp":1.59,"tv":29959.79,"id":19144236},{"trd":[[2.66,10.44]],"ltp":2.66,"tv":932.83,"id":25173012}],"tv":30892.63}]}
{"op":"mcm","clk":"11811521669","pt":1723307536956,"mc":[{"id":"1.231664751","rc":[{"trd":[[1.6,4500.94]],"batl":[[0,1.6,1323.66],[1,1.64,2.52],[2,1.69,9.43]],"ltp":1.6,"tv":29963.03,"id":19144236},{"trd":[[2.66,12.26]],"ltp":2.66,"tv":934.66,"id":25173012}],"tv":30897.69}]}
{"op":"mcm","clk":"11811522034","pt":1723307538668,"mc":[{"id":"1.231664751","rc":[{"trd":[[1.6,4501.83]],"batl":[[0,1.6,1322.89]],"ltp":1.6,"tv":29963.91,"id":19144236},{"trd":[[2.66,12.65]],"ltp":2.66,"tv":935.05,"id":25173012}],"tv":30898.96}]}
{"op":"mcm","clk":"11811522231","pt":1723307539686,"mc":[{"id":"1.231664751","rc":[{"trd":[[1.59,2752.03],[1.6,4502.4]],"batb":[[0,1.57,405.73],[1,1.56,6.38],[2,1.54,300]],"batl":[[0,1.6,1322.61],[1,1.61,9.15],[2,1.64,2.52]],"ltp":1.6,"tv":30024.15,"id":19144236}],"tv":30959.2}]}
{"op":"mcm","clk":"11811522292","pt":1723307539947,"mc":[{"id":"1.231664751","rc":[{"batl":[[0,15,0.56]],"ltp":2.66,"tv":935.05,"id":25173012}]}]}
{"op":"mcm","clk":"11811522618","pt":1723307541652,"mc":[{"id":"1.231664751","rc":[{"trd":[[1.6,4575.04]],"batl":[[0,1.6,1286.13],[2,1.64,1725.63]],"ltp":1.6,"tv":30096.8,"id":19144236},{"trd":[[2.66,12.84]],"ltp":2.66,"tv":935.23,"id":25173012}],"tv":31032.04}]}
{"op":"mcm","clk":"11811522805","pt":1723307542492,"mc":[{"id":"1.231664751","rc":[{"trd":[[1.6,4575.78]],"batb":[[0,1.58,52.58],[1,1.57,405.73],[2,1.56,6.38]],"batl":[[0,1.6,1285.49],[2,1.64,3448.74]],"ltp":1.6,"tv":30097.54,"id":19144236},{"trd":[[2.66,13.04]],"batl":[[0,15,0.66]],"ltp":2.66,"tv":935.44,"id":25173012}],"tv":31032.98}]}
{"op":"mcm","clk":"11811522957","pt":1723307543302,"mc":[{"id":"1.231664751","rc":[{"trd":[[1.6,7146.76],[1.61,13809.84]],"batb":[[0,1.6,8714.51],[1,1.58,52.58],[2,1.57,405.73]],"batl":[[0,1.61,8.24],[1,1.64,3448.74],[2,1.65,103.83]],"ltp":1.61,"tv":32670.04,"id":19144236},{"batl":[[0,15,0.63]],"ltp":2.66,"tv":935.44,"id":25173012}],"tv":33605.48}]}
{"op":"mcm","clk":"11811523192","pt":1723307544594,"mc":[{"id":"1.231664751","rc":[{"trd":[[1.6,7162.53],[1.61,13810]],"batb":[[0,1.58,52.58],[1,1.57,498.06],[2,1.56,6.38]],"batl":[[0,1.61,8.08]],"ltp":1.6,"tv":32685.96,"id":19144236},{"trd":[[2.62,578.58]],"batl":[[0,2.66,3.73],[1,15,0.63]],"ltp":2.62,"tv":935.54,"id":25173012}],"tv":33621.5}]}
{"op":"mcm","clk":"11811523378","pt":1723307545603,"mc":[{"id":"1.231664751","rc":[{"trd":[[1.61,13810.91]],"batb":[[0,1.6,22.07],[1,1.58,52.58],[2,1.57,498.06]],"batl":[[0,1.61,7.27]],"ltp":1.61,"tv":32686.87,"id":19144236},{"trd":[[2.62,579.14]],"batl":[[0,2.66,6.75]],"ltp":2.62,"tv":936.1,"id":25173012}],"tv":33622.97}]}
{"op":"mcm","clk":"11811523599","pt":1723307546684,"mc":[{"id":"1.231664751","rc":[{"trd":[[1.61,13811.52]],"batb":[[0,1.6,38.76],[1,1.59,90],[2,1.58,52.58]],"batl":[[0,1.61,6.66]],"ltp":1.61,"tv":32687.48,"id":19144236},{"trd":[[2.62,579.52]],"batl":[[0,2.66,17.24],[1,2.68,2.72],[2,15,0.63]],"ltp":2.62,"tv":936.47,"id":25173012}],"tv":33623.96}]}
{"op":"mcm","clk":"11811523759","pt":1723307547414,"mc":[{"id":"1.231664751","rc":[{"trd":[[1.6,7167.56]],"batb":[[0,1.6,36.24],[1,1.59,272.13]],"ltp":1.6,"tv":32692.51,"id":19144236},{"batl":[[2,15,0.53]],"ltp":2.62,"tv":936.47,"id":25173012}],"tv":33628.99}]}
{"op":"mcm","clk":"11811523977","pt":1723307548621,"mc":[{"id":"1.231664751","rc":[{"batb":[[0,1.6,36.4]],"batl":[[0,1.61,6.56]],"ltp":1.6,"tv":32692.51,"id":19144236},{"batl":[[0,2.66,17.94]],"ltp":2.62,"tv":936.47,"id":25173012}]}]}
{"op":"mcm","clk":"11811524189","pt":1723307549685,"mc":[{"id":"1.231664751","rc":[{"batb":[[0,1.6,15.41]],"ltp":1.6,"tv":32692.51,"id":19144236},{"batl":[[0,2.66,19.28]],"ltp":2.62,"tv":936.47,"id":25173012}]}]}
{"op":"mcm","clk":"11811524369","pt":1723307550484,"mc":[{"id":"1.231664751","rc":[{"trd":[[1.61,13811.68]],"batl":[[0,1.61,6.4]],"ltp":1.61,"tv":32692.67,"id":19144236},{"trd":[[2.62,579.62]],"batl":[[0,2.66,20.38]],"ltp":2.62,"tv":936.58,"id":25173012}],"tv":33629.25}]}
{"op":"mcm","clk":"11811524582","pt":1723307551637,"mc":[{"id":"1.231664751","rc":[{"trd":[[1.6,7172.6]],"batb":[[0,1.6,18.94]],"batl":[[1,1.64,3448.86]],"ltp":1.6,"tv":32697.71,"id":19144236},{"batl":[[0,2.66,20.61]],"ltp":2.62,"tv":936.58,"id":25173012}],"tv":33634.29}]}
{"op":"mcm","clk":"11811524742","pt":1723307552429,"mc":[{"id":"1.231664751","rc":[{"batl":[[1,1.63,1542],[2,1.64,3448.74]],"ltp":1.6,"tv":32697.71,"id":19144236},{"batl":[[0,2.66,20.76]],"ltp":2.62,"tv":936.58,"id":25173012}]}]}
{"op":"mcm","clk":"11811524983","pt":1723307553609,"mc":[{"id":"1.231664751","rc":[{"trd":[[1.6,7173.31],[1.61,13813.32]],"batb":[[0,1.6,18.58]],"batl":[[0,1.61,4.76]],"ltp":1.61,"tv":32700.06,"id":19144236},{"trd":[[2.62,580.63]],"batl":[[0,2.66,36.32]],"ltp":2.62,"tv":937.59,"id":25173012}],"tv":33637.66}]}
{"op":"mcm","clk":"11811525154","pt":1723307554405,"mc":[{"id":"1.231664751","rc":[{"trd":[[1.6,7175.19]],"batb":[[0,1.6,17.64]],"ltp":1.6,"tv":32701.95,"id":19144236},{"batl":[[0,2.66,32.67]],"ltp":2.62,"tv":937.59,"id":25173012}],"tv":33639.54}]}
{"op":"mcm","clk":"11811525426","pt":1723307555591,"mc":[{"id":"1.231664751","rc":[{"trd":[[1.6,7186.8]],"batb":[[0,1.6,12.31],[2,1.58,56.23]],"batl":[[0,1.61,4.23]],"ltp":1.6,"tv":32713.55,"id":19144236},{"batl":[[0,2.66,35.88]],"ltp":2.62,"tv":937.59,"id":25173012}],"tv":33651.15}]}
{"op":"mcm","clk":"11811525602","pt":1723307556602,"mc":[{"id":"1.231664751","rc":[{"trd":[[1.61,13822.05]],"batl":[[0,1.63,1542],[1,1.64,3448.74],[2,1.65,103.83]],"ltp":1.61,"tv":32722.28,"id":19144236},{"trd":[[2.62,581.46]],"batl":[[0,2.66,35.85]],"ltp":2.62,"tv":938.42,"id":25173012}],"tv":33660.7}]}
{"op":"mcm","clk":"11811525843","pt":1723307557641,"mc":[{"id":"1.231664751","rc":[{"trd":[[1.6,7273.55],[1.61,13833.23]],"batb":[[0,1.59,272.13],[1,1.58,56.23],[2,1.57,498.06]],"batl":[[0,1.6,213.24],[1,1.63,1542],[2,1.64,3448.74]],"ltp":1.6,"tv":32820.21,"id":19144236},{"trd":[[2.62,588.32],[2.66,53.85]],"batl":[[0,2.68,2.72],[1,15,0.62],[2,15,0]],"ltp":2.66,"tv":986.09,"id":25173012}],"tv":33806.3}]}
{"op":"mcm","clk":"11811526070","pt":1723307558656,"mc":[{"id":"1.231664751","rc":[{"trd":[[1.6,7327.75]],"batb":[[0,1.59,90]],"batl":[[0,1.6,193.34]],"ltp":1.6,"tv":32874.41,"id":19144236},{"trd":[[2.66,54.82]],"batl":[[1,15,0.68]],"ltp":2.66,"tv":987.05,"id":25173012}],"tv":33861.47}]}
{"op":"mcm","clk":"11811526262","pt":1723307559563,"mc":[{"id":"1.231664751","rc":[{"trd":[[1.6,7344.46]],"batl":[[0,1.6,179.25]],"ltp":1.6,"tv":32891.13,"id":19144236},{"trd":[[2.66,61.71]],"ltp":2.66,"tv":993.94,"id":25173012}],"tv":33885.07}]}
{"op":"mcm","clk":"11811526472","pt":1723307560521,"mc":[{"id":"1.231664751","rc":[{"trd":[[1.6,7481.05]],"batb":[[1,1.58,52.58],[2,1.57,405.73]],"batl":[[0,1.6,95.26]],"ltp":1.6,"tv":33027.71,"id":19144236},{"trd":[[2.66,80.6]],"ltp":2.66,"tv":1012.83,"id":25173012}],"tv":34040.55}]}
{"op":"mcm","clk":"11811526696","pt":1723307561639,"mc":[{"id":"1.231664751","rc":[{"trd":[[1.6,7518.05]],"batb":[[1,1.57,405.73],[2,1.54,300.47]],"batl":[[0,1.6,67.39],[1,1.64,3448.86],[2,1.66,19.69]],"ltp":1.6,"tv":33064.72,"id":19144236},{"trd":[[2.66,91.86]],"ltp":2.66,"tv":1024.1,"id":25173012}],"tv":34088.82}]}
{"op":"mcm","clk":"11811526866","pt":1723307562399,"mc":[{"id":"1.231664751","rc":[{"trd":[[1.6,7590.61],[1.61,13833.43]],"batb":[[0,1.61,10.52],[1,1.59,90],[2,1.57,405.73]],"batl":[[0,1.64,3448.86],[1,1.66,19.69],[2,1.69,9.43]],"ltp":1.61,"tv":33137.47,"id":19144236},{"trd":[[2.66,129.5]],"ltp":2.66,"tv":1061.73,"id":25173012}],"tv":34199.21}]}
{"op":"mcm","clk":"11811527066","pt":1723307563661,"mc":[{"id":"1.231664751","rc":[{"batb":[[0,1.61,21.04]],"ltp":1.61,"tv":33137.47,"id":19144236},{"batl":[[0,2.68,2.86]],"ltp":2.66,"tv":1061.73,"id":25173012}]}]}
{"op":"mcm","clk":"11811527277","pt":1723307564647,"mc":[{"id":"1.231664751","rc":[{"batb":[[0,1.61,66.36]],"ltp":1.61,"tv":33137.47,"id":19144236},{"batb":[[0,2.6,40],[1,2.52,90.16],[2,1.72,17.19]],"batl":[[0,2.62,7.3],[1,2.68,2.76],[2,15,0.68]],"ltp":2.66,"tv":1061.73,"id":25173012}]}]}
{"op":"mcm","clk":"11811527493","pt":1723307565604,"mc":[{"id":"1.231664751","rc":[{"batb":[[0,1.61,69.6],[1,1.6,3.65],[2,1.59,90]],"ltp":1.61,"tv":33137.47,"id":19144236}]}]}
{"op":"mcm","clk":"11811527681","pt":1723307566659,"mc":[{"id":"1.231664751","rc":[{"trd":[[1.61,13833.47]],"batb":[[0,1.61,67.48]],"ltp":1.61,"tv":33137.51,"id":19144236},{"batl":[[0,2.62,7.5]],"ltp":2.66,"tv":1061.73,"id":25173012}],"tv":34199.24}]}
{"op":"mcm","clk":"11811527867","pt":1723307567514,"mc":[{"id":"1.231664751","rc":[{"trd":[[1.61,13835.47],[1.62,21.19],[1.63,233.25]],"batb":[[0,1.61,63.84],[1,1.6,10012.65]],"batl":[[0,1.64,3448.74]],"ltp":1.61,"tv":33139.78,"id":19144236},{"trd":[[2.6,13.27]],"batb":[[0,2.6,39.88]],"batl":[[0,2.62,8.15]],"ltp":2.6,"tv":1061.95,"id":25173012}],"tv":34201.73}]}
{"op":"mcm","clk":"11811528092","pt":1723307568649,"mc":[{"id":"1.231664751","rc":[{"trd":[[1.63,234.76]],"batb":[[0,1.61,90.14],[1,1.6,10017.77]],"ltp":1.63,"tv":33141.29,"id":19144236},{"trd":[[2.6,14.22]],"batb":[[0,2.6,58.93]],"batl":[[0,2.62,8.18],[1,2.68,3.16]],"ltp":2.6,"tv":1062.9,"id":25173012}],"tv":34204.19}]}
{"op":"mcm","clk":"11811528286","pt":1723307569642,"mc":[{"id":"1.231664751","rc":[{"batb":[[0,1.62,11.78],[1,1.61,100.13],[2,1.6,17.77]],"ltp":1.63,"tv":33141.29,"id":19144236},{"trd":[[2.62,590.32]],"batb":[[0,2.52,90.16],[1,1.72,17.19],[2,1.56,2500]],"batl":[[0,2.62,7.15]],"ltp":2.62,"tv":1064.9,"id":25173012}],"tv":34206.19}]}
{"op":"mcm","clk":"11811528486","pt":1723307570620,"mc":[{"id":"1.231664751","rc":[{"trd":[[1.62,41.33]],"batb":[[0,1.63,10.52],[1,1.62,1.71],[2,1.61,100.81]],"ltp":1.62,"tv":33161.43,"id":19144236},{"batb":[[2,1.55,1818.18]],"batl":[[1,2.66,9.46],[2,2.68,2.72]],"ltp":2.62,"tv":1064.9,"id":25173012}],"tv":34226.33}]}
{"op":"mcm","clk":"11811528660","pt":1723307571476,"mc":[{"id":"1.231664751","rc":[{"trd":[[1.63,243.15]],"batb":[[0,1.63,2.13]],"ltp":1.63,"tv":33169.82,"id":19144236},{"trd":[[2.6,19.48]],"batl":[[1,2.66,9.78]],"ltp":2.6,"tv":1070.16,"id":25173012}],"tv":34239.98}]}
{"op":"mcm","clk":"11811528840","pt":1723307572374,"mc":[{"id":"1.231664751","rc":[{"batl":[[0,1.64,2.52]],"ltp":1.63,"tv":33169.82,"id":19144236}]}]}
{"op":"mcm","clk":"11811529087","pt":1723307573601,"mc":[{"id":"1.231664751","rc":[{"batb":[[1,1.61,95.54],[2,1.6,19.57]],"batl":[[1,1.69,9.43],[2,1.7,4375.38]],"ltp":1.63,"tv":33169.82,"id":19144236},{"batl":[[0,2.62,7.05],[1,2.66,9.63]],"ltp":2.6,"tv":1070.16,"id":25173012}]}]}
{"op":"mcm","clk":"11811529248","pt":1723307574301,"mc":[{"id":"1.231664751","rc":[{"batb":[[0,1.63,1.53]],"ltp":1.63,"tv":33169.82,"id":19144236},{"batl":[[0,2.62,6.6],[1,2.68,3.33],[2,2.74,21]],"ltp":2.6,"tv":1070.16,"id":25173012}]}]}
{"op":"mcm","clk":"11811529524","pt":1723307575588,"mc":[{"id":"1.231664751","rc":[{"trd":[[1.61,14037.29],[1.63,246.21]],"batb":[[0,1.6,19.57],[1,1.59,90],[2,1.58,360.99]],"batl":[[0,1.61,638.79],[1,1.64,2.52],[2,1.69,9.43]],"ltp":1.61,"tv":33374.7,"id":19144236},{"trd":[[2.62,596.92],[2.64,0.49]],"batb":[[0,2.64,3.51],[1,2.52,90.16],[2,1.72,17.19]],"batl":[[0,2.68,3.33],[1,2.74,21],[2,15,0.59]],"ltp":2.64,"tv":1076.96,"id":25173012}],"tv":34451.67}]}
{"op":"mcm","clk":"11811529685","pt":1723307576416,"mc":[{"id":"1.231664751","rc":[{"trd":[[1.61,14053.07]],"batl":[[0,1.61,630.9]],"ltp":1.61,"tv":33390.48,"id":19144236},{"trd":[[2.64,0.53]],"batb":[[0,2.64,2.96]],"batl":[[0,2.68,3.23]],"ltp":2.64,"tv":1077.0,"id":25173012}],"tv":34467.48}]}
{"op":"mcm","clk":"11811529961","pt":1723307577579,"mc":[{"id":"1.231664751","rc":[{"trd":[[1.61,14071.11]],"batl":[[0,1.61,621.88]],"ltp":1.61,"tv":33408.52,"id":19144236},{"trd":[[2.64,0.93]],"batb":[[0,2.64,2.76]],"batl":[[0,2.66,1.57],[1,2.68,2.72],[2,2.74,21]],"ltp":2.64,"tv":1077.4,"id":25173012}],"tv":34485.93}]}
{"op":"mcm","clk":"11811530147","pt":1723307578489,"mc":[{"id":"1.231664751","rc":[{"trd":[[1.6,7647.18],[1.61,14073.21]],"batb":[[0,1.59,90],[1,1.58,360.99],[2,1.57,498.06]],"batl":[[0,1.6,11790.09],[1,1.61,662.91],[2,1.64,2.52]],"ltp":1.6,"tv":33467.19,"id":19144236},{"trd":[[2.66,131.12]],"batb":[[1,2.62,2.63],[2,2.52,90.16]],"batl":[[0,2.68,2.72],[1,2.74,21],[2,15,0.59]],"ltp":2.66,"tv":1079.03,"id":25173012}],"tv":34546.22}]}
{"op":"mcm","clk":"11811530329","pt":1723307579315,"mc":[{"id":"1.231664751","rc":[{"trd":[[1.6,7653.02]],"batl":[[0,1.6,11784.7]],"ltp":1.6,"tv":33473.03,"id":19144236},{"trd":[[2.66,134.09]],"batl":[[2,15,0.68]],"ltp":2.66,"tv":1082.0,"id":25173012}],"tv":34555.03}]}
{"op":"mcm","clk":"11811530554","pt":1723307580506,"mc":[{"id":"1.231664751","rc":[{"trd":[[1.6,7851.8]],"batl":[[0,1.6,11685.1]],"ltp":1.6,"tv":33671.81,"id":19144236},{"trd":[[2.66,134.34]],"ltp":2.66,"tv":1082.25,"id":25173012}],"tv":34754.06}]}
{"op":"mcm","clk":"11811530804","pt":1723307581505,"mc":[{"id":"1.231664751","rc":[{"trd":[[1.6,8028.75]],"batl":[[0,1.6,11589.04]],"ltp":1.6,"tv":33848.76,"id":19144236},{"trd":[[2.66,143.46]],"batl":[[2,16,0.76]],"ltp":2.66,"tv":1091.37,"id":25173012}],"tv":34940.14}]}
{"op":"mcm","clk":"11811530969","pt":1723307582306,"mc":[{"id":"1.231664751","rc":[{"trd":[[1.6,8029.91]],"batl":[[0,1.6,11588.46]],"ltp":1.6,"tv":33849.92,"id":19144236}],"tv":34941.3}]}
{"op":"mcm","clk":"11811531257","pt":1723307583604,"mc":[{"id":"1.231664751","rc":[{"trd":[[1.6,8084.19]],"batl":[[0,1.6,11560.49],[1,1.61,651.19]],"ltp":1.6,"tv":33904.2,"id":19144236},{"trd":[[2.66,144.47]],"batb":[[1,2.52,90.16],[2,1.72,17.19]],"ltp":2.66,"tv":1092.38,"id":25173012}],"tv":34996.58}]}
{"op":"mcm","clk":"11811531536","pt":1723307584630,"mc":[{"id":"1.231664751","rc":[{"trd":[[1.6,8091.03]],"batl":[[0,1.6,11554.8],[2,1.63,1.32]],"ltp":1.6,"tv":33911.04,"id":19144236},{"trd":[[2.66,147.2]],"ltp":2.66,"tv":1095.11,"id":25173012}],"tv":35006.15}]}
{"op":"mcm","clk":"11811531685","pt":1723307585405,"mc":[{"id":"1.231664751","rc":[{"trd":[[1.6,8107.26]],"batl":[[0,1.6,11539.16]],"ltp":1.6,"tv":33927.27,"id":19144236},{"trd":[[2.66,156.24]],"ltp":2.66,"tv":1104.15,"id":25173012}],"tv":35031.43}]}
{"op":"mcm","clk":"11811531839","pt":1723307586107,"mc":[{"id":"1.231664751","rc":[{"trd":[[1.6,9051.26]],"batl":[[0,1.6,11066.91]],"ltp":1.6,"tv":34871.27,"id":19144236},{"trd":[[2.66,156.55]],"ltp":2.66,"tv":1104.46,"id":25173012}],"tv":35975.73}]}
{"op":"mcm","clk":"11811532154","pt":1723307587587,"mc":[{"id":"1.231664751","rc":[{"trd":[[1.6,9125.24]],"batl":[[0,1.6,11026.23]],"ltp":1.6,"tv":34945.25,"id":19144236},{"trd":[[2.66,160.99]],"ltp":2.66,"tv":1108.9,"id":25173012}],"tv":36054.16}]}
{"op":"mcm","clk":"11811532355","pt":1723307588611,"mc":[{"id":"1.231664751","rc":[{"trd":[[1.59,2792.69],[1.6,9169.24]],"batb":[[0,1.59,69.67],[1,1.58,255.83]],"batl":[[0,1.6,10992.03]],"ltp":1.6,"tv":35029.91,"id":19144236},{"trd":[[2.66,161.45]],"ltp":2.66,"tv":1109.35,"id":25173012}],"tv":36139.26}]}
{"op":"mcm","clk":"11811532592","pt":1723307589513,"mc":[{"id":"1.231664751","rc":[{"trd":[[1.59,2793.29],[1.6,9909.75]],"batb":[[0,1.59,69.37]],"batl":[[0,1.6,10613.68],[1,1.61,651.36]],"ltp":1.6,"tv":35771.02,"id":19144236},{"trd":[[2.66,171.3]],"ltp":2.66,"tv":1119.2,"id":25173012}],"tv":36890.23}]}
{"op":"mcm","clk":"11811532799","pt":1723307590651,"mc":[{"id":"1.231664751","rc":[{"trd":[[1.6,16135.27]],"batl":[[0,1.6,7497.88]],"ltp":1.6,"tv":41996.54,"id":19144236},{"trd":[[2.66,174.97]],"batb":[[1,2.6,10],[2,2.52,90.16]],"ltp":2.66,"tv":1122.87,"id":25173012}],"tv":43119.42}]}
{"op":"mcm","clk":"11811533004","pt":1723307591628,"mc":[{"id":"1.231664751","rc":[{"trd":[[1.6,17063.11]],"batl":[[0,1.6,7032.88]],"ltp":1.6,"tv":42924.38,"id":19144236},{"trd":[[2.66,176.26]],"ltp":2.66,"tv":1124.17,"id":25173012}],"tv":44048.55}]}
{"op":"mcm","clk":"11811533165","pt":1723307592369,"mc":[{"id":"1.231664751","rc":[{"trd":[[1.6,17594.08]],"batl":[[0,1.6,6766.52]],"ltp":1.6,"tv":43455.35,"id":19144236},{"trd":[[2.66,177.31]],"ltp":2.66,"tv":1125.22,"id":25173012}],"tv":44580.57}]}
{"op":"mcm","clk":"11811533430","pt":1723307593616,"mc":[{"id":"1.231664751","rc":[{"trd":[[1.6,17616.5]],"batl":[[0,1.6,6754.33]],"ltp":1.6,"tv":43477.77,"id":19144236},{"trd":[[2.66,179.96]],"ltp":2.66,"tv":1127.87,"id":25173012}],"tv":44605.64}]}
{"op":"mcm","clk":"11811533625","pt":1723307594528,"mc":[{"id":"1.231664751","rc":[{"trd":[[1.6,17617.45]],"batl":[[0,1.6,6753.38]],"ltp":1.6,"tv":43478.72,"id":19144236},{"trd":[[2.66,180.53]],"ltp":2.66,"tv":1128.44,"id":25173012}],"tv":44607.16}]}
{"op":"mcm","clk":"11811533824","pt":1723307595605,"mc":[{"id":"1.231664751","rc":[{"trd":[[1.58,304.59],[1.59,2936.61],[1.6,17644.63]],"batb":[[0,1.57,498.06],[1,1.54,300.47],[2,1.51,300]],"batl":[[0,1.58,35.01],[1,1.6,6737.42],[2,1.61,651.36]],"ltp":1.58,"tv":43953.26,"id":19144236},{"trd":[[2.66,183.38],[2.68,32.85],[2.72,0.12]],"batl":[[0,2.74,21],[1,16,0.76],[2,16,0]],"ltp":2.72,"tv":1134.03,"id":25173012}],"tv":45087.3}]}
{"op":"mcm","clk":"11811533970","pt":1723307596280,"mc":[{"id":"1.231664751","rc":[{"trd":[[1.58,306.89]],"batl":[[0,1.58,33.86]],"ltp":1.58,"tv":43955.56,"id":19144236}],"tv":45089.6}]}
{"op":"mcm","clk":"11811534247","pt":1723307597614,"mc":[{"id":"1.231664751","rc":[{"trd":[[1.58,342.33],[1.6,17803.41]],"batl":[[0,1.6,6628.23],[1,1.61,651.36],[2,1.63,5.69]],"ltp":1.6,"tv":44149.79,"id":19144236},{"trd":[[2.66,219.24],[2.72,18.88]],"ltp":2.66,"tv":1188.64,"id":25173012}],"tv":45338.43}]}
{"op":"mcm","clk":"11811534454","pt":1723307598637,"mc":[{"id":"1.231664751","rc":[{"trd":[[1.6,17806.28]],"batl":[[0,1.6,6614.1]],"ltp":1.6,"tv":44152.65,"id":19144236},{"trd":[[2.66,220.29]],"ltp":2.66,"tv":1189.69,"id":25173012}],"tv":45342.34}]}
{"op":"mcm","clk":"11811534587","pt":1723307599208,"mc":[{"id":"1.231664751","rc":[{"trd":[[1.6,17816.76]],"batl":[[0,1.6,6603.62]],"ltp":1.6,"tv":44163.13,"id":19144236},{"trd":[[2.66,226.59]],"ltp":2.66,"tv":1195.99,"id":25173012}],"tv":45359.13}]}
{"op":"mcm","clk":"11811534878","pt":1723307600590,"mc":[{"id":"1.231664751","rc":[{"trd":[[1.6,31023.96]],"batb":[[0,1.57,498.69]],"batl":[[0,1.61,651.36],[1,1.63,5.69],[2,1.64,2.52]],"ltp":1.6,"tv":57370.33,"id":19144236},{"trd":[[2.66,226.61]],"batl":[[0,2.66,2.91],[1,2.74,21],[2,16,0.76]],"ltp":2.66,"tv":1196.01,"id":25173012}],"tv":58566.35}]}
{"op":"mcm","clk":"11811535099","pt":1723307601585,"mc":[{"id":"1.231664751","rc":[{"batb":[[0,1.6,2.83],[1,1.57,498.06],[2,1.54,300.47]],"ltp":1.6,"tv":57370.33,"id":19144236},{"batl":[[0,2.66,47.19]],"ltp":2.66,"tv":1196.01,"id":25173012}]}]}
{"op":"mcm","clk":"11811535275","pt":1723307602424,"mc":[{"id":"1.231664751","rc":[{"batb":[[0,1.6,3.62]],"ltp":1.6,"tv":57370.33,"id":19144236},{"batl":[[0,2.66,51.19]],"ltp":2.66,"tv":1196.01,"id":25173012}]}]}
{"op":"mcm","clk":"11811535479","pt":1723307603497,"mc":[{"id":"1.231664751","rc":[{"batb":[[0,1.6,4.65]],"ltp":1.6,"tv":57370.33,"id":19144236},{"batl":[[0,2.66,51.59]],"ltp":2.66,"tv":1196.01,"id":25173012}]}]}
{"op":"mcm","clk":"11811535699","pt":1723307604608,"mc":[{"id":"1.231664751","rc":[{"batb":[[0,1.6,9.91]],"ltp":1.6,"tv":57370.33,"id":19144236},{"batl":[[0,2.66,51.39]],"ltp":2.66,"tv":1196.01,"id":25173012}]}]}
{"op":"mcm","clk":"11811535835","pt":1723307605332,"mc":[{"id":"1.231664751","rc":[{"trd":[[1.6,31036.3]],"batb":[[0,1.57,498.06],[1,1.54,300.47],[2,1.51,300]],"ltp":1.6,"tv":57382.67,"id":19144236},{"trd":[[2.66,233.3]],"batl":[[0,2.66,44.7]],"ltp":2.66,"tv":1202.7,"id":25173012}],"tv":58585.38}]}
{"op":"mcm","clk":"11811536118","pt":1723307606630,"mc":[{"id":"1.231664751","rc":[{"batb":[[0,1.57,498.25]],"ltp":1.6,"tv":57382.67,"id":19144236},{"batl":[[0,2.66,41.38],[1,2.72,10],[2,2.74,21]],"ltp":2.66,"tv":1202.7,"id":25173012}]}]}
{"op":"mcm","clk":"11811536234","pt":1723307607226,"mc":[{"id":"1.231664751","rc":[{"batl":[[0,2.66,41.92]],"ltp":2.66,"tv":1202.7,"id":25173012}]}]}
{"op":"mcm","clk":"11811536501","pt":1723307608544,"mc":[{"id":"1.231664751","rc":[{"batl":[[0,2.66,42.29]],"ltp":2.66,"tv":1202.7,"id":25173012}]}]}
{"op":"mcm","clk":"11811536689","pt":1723307609395,"mc":[{"id":"1.231664751","rc":[{"trd":[[1.61,14076.91]],"batb":[[0,1.57,406.54]],"batl":[[0,1.61,649.51]],"ltp":1.61,"tv":57386.37,"id":19144236},{"batl":[[0,2.66,42.32]],"ltp":2.66,"tv":1202.7,"id":25173012}],"tv":58589.08}]}
{"op":"mcm","clk":"11811536916","pt":1723307610526,"mc":[{"id":"1.231664751","rc":[{"trd":[[1.61,14077.31]],"batb":[[0,1.58,53.39],[1,1.57,405.73],[2,1.54,300.47]],"batl":[[0,1.61,649.31]],"ltp":1.61,"tv":57386.77,"id":19144236},{"batb":[[0,2.6,10],[1,2.52,90.16],[2,2.4,10]],"batl":[[0,2.64,4.92],[1,2.66,42.32],[2,2.72,10]],"ltp":2.66,"tv":1202.7,"id":25173012}],"tv":58589.48}]}
{"op":"mcm","clk":"11811537123","pt":1723307611520,"mc":[{"id":"1.231664751","rc":[{"trd":[[1.6,31121.81]],"batb":[[0,1.57,406.35],[1,1.54,300.47],[2,1.51,300]],"batl":[[0,1.6,68.26],[1,1.61,649.31],[2,1.63,5.69]],"ltp":1.6,"tv":57472.28,"id":19144236},{"trd":[[2.64,5.95],[2.66,277.62]],"batl":[[0,2.72,10],[1,2.74,21],[2,6,1.01]],"ltp":2.66,"tv":1252.04,"id":25173012}],"tv":58724.33}]}
{"op":"mcm","clk":"11811537386","pt":1723307612630,"mc":[{"id":"1.231664751","rc":[{"trd":[[1.6,31158.83]],"batl":[[0,1.6,31.34]],"ltp":1.6,"tv":57509.3,"id":19144236},{"trd":[[2.66,299.76]],"batl":[[0,2.72,12.52]],"ltp":2.66,"tv":1274.19,"id":25173012}],"tv":58783.5}]}
{"op":"mcm","clk":"11811537631","pt":1723307613646,"mc":[{"id":"1.231664751","rc":[{"trd":[[1.6,31163.02]],"batb":[[0,1.56,2.47],[1,1.54,300]],"batl":[[0,1.6,27.15]],"ltp":1.6,"tv":57513.49,"id":19144236},{"trd":[[2.66,302.28]],"ltp":2.66,"tv":1276.71,"id":25173012}],"tv":58790.2}]}
{"op":"mcm","clk":"11811537801","pt":1723307614469,"mc":[{"id":"1.231664751","rc":[{"trd":[[1.6,31177.85]],"batl":[[0,1.6,20.79]],"ltp":1.6,"tv":57528.32,"id":19144236},{"trd":[[2.66,302.91]],"ltp":2.66,"tv":1277.34,"id":25173012}],"tv":58805.67}]}
{"op":"mcm","clk":"11811538014","pt":1723307615318,"mc":[{"id":"1.231664751","rc":[{"trd":[[1.58,343.03],[1.6,31182.97]],"batb":[[0,1.56,2.12]],"batl":[[0,1.6,16.3]],"ltp":1.6,"tv":57534.14,"id":19144236},{"trd":[[2.66,305.23]],"batl":[[0,2.72,10]],"ltp":2.66,"tv":1279.66,"id":25173012}],"tv":58813.81}]}
{"op":"mcm","clk":"11811538275","pt":1723307616562,"mc":[{"id":"1.231664751","rc":[{"trd":[[1.6,31195.84]],"batl":[[0,1.6,286.18]],"ltp":1.6,"tv":57547.01,"id":19144236},{"trd":[[2.66,312.97]],"ltp":2.66,"tv":1287.4,"id":25173012}],"tv":58834.42}]}
{"op":"mcm","clk":"11811538514","pt":1723307617622,"mc":[{"id":"1.231664751","rc":[{"trd":[[1.6,31289.59]],"batl":[[0,1.6,206.21]],"ltp":1.6,"tv":57640.76,"id":19144236},{"trd":[[2.66,365.56]],"ltp":2.66,"tv":1339.99,"id":25173012}],"tv":58980.76}]}
{"op":"mcm","clk":"11811538702","pt":1723307618524,"mc":[{"id":"1.231664751","rc":[{"trd":[[1.6,31311.48]],"batl":[[0,1.6,187.27]],"ltp":1.6,"tv":57662.65,"id":19144236},{"trd":[[2.66,375.56]],"ltp":2.66,"tv":1349.99,"id":25173012}],"tv":59012.65}]}
{"op":"mcm","clk":"11811538918","pt":1723307619440,"mc":[{"id":"1.231664751","rc":[{"trd":[[1.6,31315.78]],"batl":[[0,1.6,185.48]],"ltp":1.6,"tv":57666.95,"id":19144236},{"trd":[[2.66,375.77]],"ltp":2.66,"tv":1350.19,"id":25173012}],"tv":59017.15}]}
{"op":"mcm","clk":"11811539125","pt":1723307620355,"mc":[{"id":"1.231664751","rc":[{"trd":[[1.6,31317.34]],"batl":[[0,1.6,184.45]],"ltp":1.6,"tv":57668.51,"id":19144236},{"trd":[[2.66,376.07]],"ltp":2.66,"tv":1350.5,"id":25173012}],"tv":59019.01}]}
{"op":"mcm","clk":"11811539368","pt":1723307621470,"mc":[{"id":"1.231664751","rc":[{"trd":[[1.6,31434.81]],"batl":[[0,1.6,124.2]],"ltp":1.6,"tv":57785.98,"id":19144236},{"trd":[[2.66,377.89]],"batl":[[2,4,1.02]],"ltp":2.66,"tv":1352.32,"id":25173012}],"tv":59138.31}]}
{"op":"mcm","clk":"11811539540","pt":1723307622314,"mc":[{"id":"1.231664751","rc":[{"batl":[[0,1.6,124.22]],"ltp":1.6,"tv":57785.98,"id":19144236},{"batl":[[0,2.72,11]],"ltp":2.66,"tv":1352.32,"id":25173012}]}]}
{"op":"mcm","clk":"11811539754","pt":1723307623674,"mc":[{"id":"1.231664751","rc":[{"trd":[[1.6,31473.24]],"batl":[[0,1.6,102.51]],"ltp":1.6,"tv":57824.41,"id":19144236},{"trd":[[2.66,380.89]],"ltp":2.66,"tv":1355.32,"id":25173012}],"tv":59179.73}]}
{"op":"mcm","clk":"11811539902","pt":1723307624480,"mc":[{"id":"1.231664751","rc":[{"trd":[[1.6,31477.56]],"batb":[[0,1.56,1.85]],"batl":[[0,1.6,98.19]],"ltp":1.6,"tv":57828.73,"id":19144236},{"trd":[[2.66,383.49]],"ltp":2.66,"tv":1357.91,"id":25173012}],"tv":59186.65}]}
{"op":"mcm","clk":"11811540139","pt":1723307625556,"mc":[{"id":"1.231664751","rc":[{"trd":[[1.6,31483.16]],"batl":[[0,1.6,92.74]],"ltp":1.6,"tv":57834.33,"id":19144236},{"trd":[[2.66,386.68]],"ltp":2.66,"tv":1361.1,"id":25173012}],"tv":59195.44}]}
{"op":"mcm","clk":"11811540342","pt":1723307626642,"mc":[{"id":"1.231664751","rc":[{"trd":[[1.6,31668.47]],"batb":[[0,1.6,359.74],[1,1.56,1.85],[2,1.55,92.33]],"batl":[[0,1.61,649.31],[1,1.63,5.69],[2,1.64,2.52]],"ltp":1.6,"tv":58019.64,"id":19144236},{"trd":[[2.66,386.78]],"batl":[[0,2.72,11.72]],"ltp":2.66,"tv":1361.2,"id":25173012}],"tv":59380.85}]}
{"op":"mcm","clk":"11811540538","pt":1723307627634,"mc":[{"id":"1.231664751","rc":[{"batl":[[0,1.61,42.35]],"ltp":1.6,"tv":58019.64,"id":19144236},{"batl":[[0,2.72,11.85]],"ltp":2.66,"tv":1361.2,"id":25173012}]}]}
{"op":"mcm","clk":"11811540736","pt":1723307628557,"mc":[{"id":"1.231664751","rc":[{"batb":[[0,1.6,362.48],[1,1.56,54.43]],"ltp":1.6,"tv":58019.64,"id":19144236},{"batl":[[0,2.66,55.1],[1,2.72,11],[2,2.74,21]],"ltp":2.66,"tv":1361.2,"id":25173012}]}]}
{"op":"mcm","clk":"11811540955","pt":1723307629674,"mc":[{"id":"1.231664751","rc":[{"batb":[[0,1.6,363.39]],"ltp":1.6,"tv":58019.64,"id":19144236},{"batl":[[0,2.66,55.38]],"ltp":2.66,"tv":1361.2,"id":25173012}]}]}
{"op":"mcm","clk":"11811541098","pt":1723307630437,"mc":[{"id":"1.231664751","rc":[{"batl":[[0,2.66,72.06]],"ltp":2.66,"tv":1361.2,"id":25173012}]}]}
{"op":"mcm","clk":"11811541333","pt":1723307631656,"mc":[{"id":"1.231664751","rc":[{"batb":[[0,1.6,372.6],[1,1.56,54.96],[2,1.54,300]],"ltp":1.6,"tv":58019.64,"id":19144236},{"batl":[[0,2.66,72.21]],"ltp":2.66,"tv":1361.2,"id":25173012}]}]}
{"op":"mcm","clk":"11811541524","pt":1723307632665,"mc":[{"id":"1.231664751","rc":[{"batb":[[0,1.6,373.16]],"ltp":1.6,"tv":58019.64,"id":19144236},{"batl":[[0,2.66,74.65]],"ltp":2.66,"tv":1361.2,"id":25173012}]}]}
{"op":"mcm","clk":"11811541675","pt":1723307633462,"mc":[{"id":"1.231664751","rc":[{"batb":[[0,1.6,373.79],[1,1.56,2.38]],"batl":[[0,1.61,39.72]],"ltp":1.6,"tv":58019.64,"id":19144236},{"batl":[[0,2.66,75.35]],"ltp":2.66,"tv":1361.2,"id":25173012}]}]}
{"op":"mcm","clk":"11811541912","pt":1723307634593,"mc":[{"id":"1.231664751","rc":[{"trd":[[1.6,31773.65]],"batb":[[0,1.6,334.47]],"ltp":1.6,"tv":58124.82,"id":19144236},{"batl":[[0,2.66,75.55]],"ltp":2.66,"tv":1361.2,"id":25173012}],"tv":59486.03}]}
{"op":"mcm","clk":"11811542146","pt":1723307635555,"mc":[{"id":"1.231664751","rc":[{"trd":[[1.6,31797.29]],"batb":[[0,1.6,338.4],[1,1.56,1]],"ltp":1.6,"tv":58148.46,"id":19144236}],"tv":59509.67}]}
{"op":"mcm","clk":"11811542368","pt":1723307636670,"mc":[{"id":"1.231664751","rc":[{"trd":[[1.61,14083.35]],"batb":[[0,1.6,341.81]],"batl":[[0,1.61,36.7]],"ltp":1.61,"tv":58154.5,"id":19144236},{"batl":[[0,2.66,75.46]],"ltp":2.66,"tv":1361.2,"id":25173012}],"tv":59515.71}]}
{"op":"mcm","clk":"11811542575","pt":1723307637654,"mc":[{"id":"1.231664751","rc":[{"trd":[[1.61,14084.26]],"batb":[[0,1.6,352.86]],"batl":[[0,1.61,19.96]],"ltp":1.61,"tv":58155.41,"id":19144236},{"trd":[[2.62,597.48]],"batl":[[0,2.66,76.51]],"ltp":2.62,"tv":1361.76,"id":25173012}],"tv":59517.18}]}
{"op":"mcm","clk":"11811542752","pt":1723307638651,"mc":[{"id":"1.231664751","rc":[{"trd":[[1.6,31797.75],[1.61,14084.28]],"batb":[[0,1.6,351.73]],"batl":[[0,1.61,17.32]],"ltp":1.6,"tv":58155.89,"id":19144236},{"batb":[[2,2.5,5.26]],"batl":[[0,2.66,61.16],[1,2.72,10]],"ltp":2.62,"tv":1361.76,"id":25173012}],"tv":59517.66}]}
{"op":"mcm","clk":"11811542959","pt":1723307639646,"mc":[{"id":"1.231664751","rc":[{"trd":[[1.61,14089.2]],"batb":[[0,1.61,5.26],[1,1.6,312.44],[2,1.56,1]],"batl":[[0,1.63,5.69],[1,1.64,2.52],[2,1.66,25.3]],"ltp":1.61,"tv":58160.81,"id":19144236},{"trd":[[2.62,600.5]],"batl":[[0,2.66,61.21]],"ltp":2.62,"tv":1364.78,"id":25173012}],"tv":59525.6}]}
{"op":"mcm","clk":"11811543166","pt":1723307640554,"mc":[{"id":"1.231664751","rc":[{"batb":[[0,1.61,5.64]],"ltp":1.61,"tv":58160.81,"id":19144236},{"batl":[[0,2.62,1.51],[1,2.66,63.7],[2,2.72,10]],"ltp":2.62,"tv":1364.78,"id":25173012}]}]}
{"op":"mcm","clk":"11811543353","pt":1723307641576,"mc":[{"id":"1.231664751","rc":[{"trd":[[1.63,273.54],[1.64,6.02],[1.65,194.81]],"batb":[[0,1.65,9902.29],[1,1.61,5.94],[2,1.6,346]],"batl":[[0,1.66,25.3],[1,1.69,9.43],[2,1.7,67.6]],"ltp":1.65,"tv":58340.27,"id":19144236},{"trd":[[2.6,29.48],[2.62,600.8]],"batb":[[0,2.52,90.16],[1,2.5,5.26],[2,2.4,10]],"batl":[[0,2.62,2.37]],"ltp":2.6,"tv":1375.09,"id":25173012}],"tv":59715.36}]}
{"op":"mcm","clk":"11811543547","pt":1723307642484,"mc":[{"id":"1.231664751","rc":[{"trd":[[1.65,303.56]],"batb":[[0,1.65,27149.65],[2,1.6,852.38]],"ltp":1.65,"tv":58449.01,"id":19144236},{"trd":[[2.54,70.51]],"batl":[[0,2.62,2.47]],"ltp":2.54,"tv":1445.6,"id":25173012}],"tv":59894.61}]}
{"op":"mcm","clk":"11811543778","pt":1723307643668,"mc":[{"id":"1.231664751","rc":[{"trd":[[1.66,912.35],[1.67,5776.29],[1.69,119.15]],"batb":[[0,1.69,9813.51],[1,1.65,9793.65],[2,1.64,1409.91]],"batl":[[0,1.7,67.6],[1,1.76,2000],[2,1.78,78.89]],"ltp":1.69,"tv":58677.25,"id":19144236},{"trd":[[2.5,26.67],[2.52,90.5]],"batb":[[0,2.4,10],[1,2.2,10.06],[2,1.72,17.13]],"batl":[[0,2.62,54.28]],"ltp":2.5,"tv":1541.02,"id":25173012}],"tv":60218.28}]}
{"op":"mcm","clk":"11811543974","pt":1723307644677,"mc":[{"id":"1.231664751","rc":[{"trd":[[1.7,210.34]],"batb":[[0,1.7,9930.89],[1,1.67,391.55],[2,1.65,10498.61]],"batl":[[0,1.76,2000],[1,1.78,78.89],[2,1.8,141.62]],"ltp":1.7,"tv":58815.47,"id":19144236},{"batl":[[0,2.62,56.31]],"ltp":2.5,"tv":1541.02,"id":25173012}],"tv":60356.5}]}
{"op":"mcm","clk":"11811544143","pt":1723307645572,"mc":[{"id":"1.231664751","rc":[{"batb":[[0,1.67,391.55],[1,1.65,10498.61],[2,1.64,1409.91]],"batl":[[0,1.75,2584.67],[1,1.76,2000],[2,1.78,78.89]],"ltp":1.7,"tv":58815.47,"id":19144236},{"batl":[[1,2.66,63.6]],"ltp":2.5,"tv":1541.02,"id":25173012}]}]}
{"op":"mcm","clk":"11811544313","pt":1723307646489,"mc":[{"id":"1.231664751","rc":[{"batb":[[0,1.67,764.17]],"batl":[[0,1.75,3446.23]],"ltp":1.7,"tv":58815.47,"id":19144236},{"batl":[[0,2.62,56.81],[1,2.66,60.01]],"ltp":2.5,"tv":1541.02,"id":25173012}]}]}
{"op":"mcm","clk":"11811544585","pt":1723307647596,"mc":[{"id":"1.231664751","rc":[{"batb":[[1,1.65,10798.61]],"batl":[[0,1.76,2000],[1,1.78,78.89],[2,1.8,141.62]],"ltp":1.7,"tv":58815.47,"id":19144236},{"batl":[[0,2.62,57.2]],"ltp":2.5,"tv":1541.02,"id":25173012}]}]}
{"op":"mcm","clk":"11811544788","pt":1723307648678,"mc":[{"id":"1.231664751","rc":[{"batb":[[1,1.66,300],[2,1.65,10498.61]],"ltp":1.7,"tv":58815.47,"id":19144236},{"batl":[[0,2.62,66.11],[1,2.66,59.91]],"ltp":2.5,"tv":1541.02,"id":25173012}]}]}
{"op":"mcm","clk":"11811544970","pt":1723307649601,"mc":[{"id":"1.231664751","rc":[{"trd":[[1.67,5776.49]],"batb":[[0,1.67,764.07]],"ltp":1.67,"tv":58815.68,"id":19144236}],"tv":60356.7}]}
{"op":"mcm","clk":"11811545167","pt":1723307650564,"mc":[{"id":"1.231664751","rc":[{"trd":[[1.67,5777.55]],"batb":[[0,1.67,763.54],[2,1.65,9793.65]],"ltp":1.67,"tv":58816.74,"id":19144236},{"batl":[[0,2.62,67.1],[1,2.66,59.31]],"ltp":2.5,"tv":1541.02,"id":25173012}],"tv":60357.76}]}
{"op":"mcm","clk":"11811545376","pt":1723307651687,"mc":[{"id":"1.231664751","rc":[{"batb":[[1,1.66,301.13]],"ltp":1.67,"tv":58816.74,"id":19144236},{"batl":[[0,2.62,59.62],[1,2.66,56.58]],"ltp":2.5,"tv":1541.02,"id":25173012}]}]}
{"op":"mcm","clk":"11811545561","pt":1723307652665,"mc":[{"id":"1.231664751","rc":[{"batl":[[0,1.71,48.34],[1,1.76,2000],[2,1.78,78.89]],"ltp":1.67,"tv":58816.74,"id":19144236},{"batl":[[0,2.62,58.67]],"ltp":2.5,"tv":1541.02,"id":25173012}]}]}
{"op":"mcm","clk":"11811545728","pt":1723307653571,"mc":[{"id":"1.231664751","rc":[{"batl":[[0,2.62,56.83],[1,2.66,56.05]],"ltp":2.5,"tv":1541.02,"id":25173012}]}]}
{"op":"mcm","clk":"11811545935","pt":1723307654608,"mc":[{"id":"1.231664751","rc":[{"batl":[[0,1.7,90],[1,1.71,48.34],[2,1.76,2000]],"ltp":1.67,"tv":58816.74,"id":19144236},{"trd":[[2.4,20.2]],"batb":[[0,2.4,9.83]],"batl":[[0,2.62,59.27]],"ltp":2.4,"tv":1541.36,"id":25173012}],"tv":60358.1}]}
{"op":"mcm","clk":"11811546162","pt":1723307655672,"mc":[{"id":"1.231664751","rc":[{"trd":[[1.67,5779.67],[1.7,215.87]],"batb":[[0,1.67,762.48]],"batl":[[0,1.7,85.43],[2,1.72,182.13]],"ltp":1.7,"tv":58824.38,"id":19144236},{"trd":[[2.42,2.64]],"batl":[[0,2.62,58.98]],"ltp":2.42,"tv":1543.9,"id":25173012}],"tv":60368.29}]}
{"op":"mcm","clk":"11811546343","pt":1723307656592,"mc":[{"id":"1.231664751","rc":[{"trd":[[1.67,5784.34]],"batb":[[0,1.67,760.15]],"batl":[[0,1.69,26.3],[1,1.7,85.43],[2,1.71,48.34]],"ltp":1.67,"tv":58829.05,"id":19144236}],"tv":60372.96}]}
{"op":"mcm","clk":"11811546569","pt":1723307657601,"mc":[{"id":"1.231664751","rc":[{"trd":[[1.69,120.36]],"batb":[[1,1.65,9793.65],[2,1.64,145.7]],"batl":[[0,1.69,25.7]],"ltp":1.69,"tv":58830.26,"id":19144236},{"batl":[[0,2.5,21],[1,2.62,58.07],[2,2.66,56.05]],"ltp":2.42,"tv":1543.9,"id":25173012}],"tv":60374.16}]}
{"op":"mcm","clk":"11811546725","pt":1723307658293,"mc":[{"id":"1.231664751","rc":[{"trd":[[1.67,7304.64],[1.69,121.04]],"batb":[[0,1.65,9793.65],[1,1.64,145.7],[2,1.63,350.12]],"batl":[[0,1.67,71.02],[1,1.69,25.52],[2,1.7,85.43]],"ltp":1.67,"tv":60351.23,"id":19144236},{"trd":[[2.44,31.56]],"ltp":2.44,"tv":1544.37,"id":25173012}],"tv":61895.61}]}
{"op":"mcm","clk":"11811546999","pt":1723307659672,"mc":[{"id":"1.231664751","rc":[{"trd":[[1.67,7319.24]],"batb":[[2,1.63,50.12]],"batl":[[0,1.67,56.42]],"ltp":1.67,"tv":60365.83,"id":19144236},{"trd":[[2.48,24.98],[2.5,28.97]],"batl":[[0,2.5,19.85],[1,2.62,57.97]],"ltp":2.48,"tv":1556.5,"id":25173012}],"tv":61922.34}]}
{"op":"mcm","clk":"11811547214","pt":1723307660686,"mc":[{"id":"1.231664751","rc":[{"trd":[[1.66,912.37],[1.67,7429.94],[1.69,122.05]],"batl":[[0,1.69,24.51],[1,1.7,85.43],[2,1.71,48.34]],"ltp":1.69,"tv":60477.56,"id":19144236},{"trd":[[2.44,32.26],[2.48,28.7],[2.5,28.98]],"batl":[[0,2.5,19.84]],"ltp":2.44,"tv":1560.93,"id":25173012}],"tv":62038.5}]}
{"op":"mcm","clk":"11811547390","pt":1723307661606,"mc":[{"id":"1.231664751","rc":[{"trd":[[1.69,170.81],[1.71,289.74]],"batb":[[0,1.71,450.98],[1,1.65,9793.65],[2,1.64,145.7]],"batl":[[0,1.73,103.83],[1,1.76,2000],[2,1.78,78.89]],"ltp":1.71,"tv":60629.39,"id":19144236},{"trd":[[2.4,36.02],[2.42,7.15],[2.44,32.44]],"batb":[[0,2.4,1.92]],"batl":[[1,2.62,57.82]],"ltp":2.42,"tv":1581.44,"id":25173012}],"tv":62210.83}]}
{"op":"mcm","clk":"11811547576","pt":1723307662569,"mc":[{"id":"1.231664751","rc":[{"trd":[[1.71,402.02]],"batb":[[0,1.71,2131.72]],"batl":[[0,1.76,2000],[1,1.78,78.89],[2,1.8,141.62]],"ltp":1.71,"tv":60741.67,"id":19144236}],"tv":62323.11}]}
{"op":"mcm","clk":"11811547792","pt":1723307663596,"mc":[{"id":"1.231664751","rc":[{"trd":[[1.71,404.04]],"batb":[[0,1.71,2135.98],[1,1.65,9794.17]],"ltp":1.71,"tv":60743.68,"id":19144236},{"trd":[[2.4,37.46]],"batb":[[0,2.4,1.2]],"batl":[[1,2.62,57.68]],"ltp":2.4,"tv":1582.88,"id":25173012}],"tv":62326.57}]}
{"op":"mcm","clk":"11811547975","pt":1723307664499,"mc":[{"id":"1.231664751","rc":[{"trd":[[1.71,407.38],[1.72,1.83]],"batb":[[0,1.71,2134.31],[2,1.64,146.23]],"ltp":1.71,"tv":60748.69,"id":19144236},{"trd":[[2.4,38.66]],"batb":[[0,2.2,10.06],[1,1.72,17.13],[2,1.56,1500]],"ltp":2.4,"tv":1584.08,"id":25173012}],"tv":62332.78}]}
{"op":"mcm","clk":"11811548161","pt":1723307665499,"mc":[{"id":"1.231664751","rc":[{"trd":[[1.74,1.8]],"batb":[[0,1.71,2155.2],[1,1.7,1.34],[2,1.65,9793.65]],"batl":[[0,1.72,1722.21],[1,1.76,2000],[2,1.78,78.89]],"ltp":1.74,"tv":60750.49,"id":19144236},{"batl":[[0,2.4,1.31],[1,2.5,19.84],[2,2.62,57.68]],"ltp":2.4,"tv":1584.08,"id":25173012}],"tv":62334.58}]}
{"op":"mcm","clk":"11811548379","pt":1723307666624,"mc":[{"id":"1.231664751","rc":[{"trd":[[1.72,1.97]],"batb":[[0,1.71,426.72],[1,1.7,3.97],[2,1.69,13.14]],"batl":[[0,1.72,3445.19]],"ltp":1.72,"tv":60750.63,"id":19144236},{"trd":[[2.38,0.1]],"batl":[[0,2.4,1.67],[1,2.48,131.23],[2,2.5,19.84]],"ltp":2.38,"tv":1584.18,"id":25173012}],"tv":62334.82}]}
{"op":"mcm","clk":"11811548586","pt":1723307667599,"mc":[{"id":"1.231664751","rc":[{"trd":[[1.71,1228.06]],"batb":[[0,1.71,16.37]],"ltp":1.71,"tv":61571.32,"id":19144236},{"batl":[[1,2.48,134.94]],"ltp":2.38,"tv":1584.18,"id":25173012}],"tv":63155.51}]}
{"op":"mcm","clk":"11811548793","pt":1723307668601,"mc":[{"id":"1.231664751","rc":[{"trd":[[1.71,1231.66]],"batb":[[0,1.71,14.57],[1,1.7,1665.66],[2,1.69,14.72]],"ltp":1.71,"tv":61574.92,"id":19144236},{"batl":[[0,2.44,53.6],[1,2.48,134.87]],"ltp":2.38,"tv":1584.18,"id":25173012}],"tv":63159.11}]}
{"op":"mcm","clk":"11811548938","pt":1723307669395,"mc":[{"id":"1.231664751","rc":[{"batb":[[1,1.7,1664.74]],"ltp":1.71,"tv":61574.92,"id":19144236},{"batl":[[0,2.44,53.7]],"ltp":2.38,"tv":1584.18,"id":25173012}]}]}
{"op":"mcm","clk":"11811549153","pt":1723307670526,"mc":[{"id":"1.231664751","rc":[{"trd":[[1.7,221.97],[1.71,1261.4],[1.72,279.03]],"batb":[[0,1.7,1416.44],[1,1.69,16],[2,1.67,116.43]],"batl":[[0,1.72,3306.66]],"ltp":1.72,"tv":61887.83,"id":19144236},{"trd":[[2.4,39.08]],"batl":[[0,2.44,53.38]],"ltp":2.4,"tv":1584.6,"id":25173012}],"tv":63472.44}]}
{"op":"mcm","clk":"11811549356","pt":1723307671549,"mc":[{"id":"1.231664751","rc":[{"trd":[[1.71,1261.42]],"ltp":1.71,"tv":61887.84,"id":19144236},{"trd":[[2.4,39.09]],"batl":[[0,2.44,55.21],[1,2.48,135.66],[2,2.5,20.89]],"ltp":2.4,"tv":1584.61,"id":25173012}],"tv":63472.46}]}
{"op":"mcm","clk":"11811549581","pt":1723307672670,"mc":[{"id":"1.231664751","rc":[{"trd":[[1.71,1261.55]],"batb":[[1,1.69,8.12]],"batl":[[0,1.72,3306.68]],"ltp":1.71,"tv":61887.97,"id":19144236},{"trd":[[2.4,39.18]],"batl":[[0,2.44,55.12],[1,2.48,136.71]],"ltp":2.4,"tv":1584.7,"id":25173012}],"tv":63472.68}]}
{"op":"mcm","clk":"11811549763","pt":1723307673545,"mc":[{"id":"1.231664751","rc":[{"trd":[[1.7,223.03],[1.71,1263.11]],"batb":[[0,1.7,1415.91],[2,1.67,120.04]],"batl":[[0,1.71,6.85],[1,1.72,3306.66],[2,1.76,2000]],"ltp":1.71,"tv":61890.59,"id":19144236},{"trd":[[2.4,40.29]],"batl":[[0,2.44,55.22],[1,2.48,136.91]],"ltp":2.4,"tv":1585.81,"id":25173012}],"tv":63476.41}]}
{"op":"mcm","clk":"11811550003","pt":1723307674655,"mc":[{"id":"1.231664751","rc":[{"trd":[[1.71,1280.3],[1.72,279.48]],"batb":[[0,1.71,1.33],[1,1.7,1415.91],[2,1.69,8.12]],"batl":[[0,1.72,3306.44],[1,1.76,2000],[2,1.8,141.62]],"ltp":1.72,"tv":61908.23,"id":19144236},{"trd":[[2.4,41.39]],"batl":[[0,2.42,1.58],[1,2.44,59.81],[2,2.48,136.91]],"ltp":2.4,"tv":1586.91,"id":25173012}],"tv":63495.15}]}
{"op":"mcm","clk":"11811550216","pt":1723307675669,"mc":[{"id":"1.231664751","rc":[{"trd":[[1.71,1280.86],[1.72,4716.03]],"batb":[[0,1.71,1.05]],"batl":[[0,1.72,1088.09]],"ltp":1.72,"tv":66345.34,"id":19144236},{"trd":[[2.38,0.2]],"batl":[[1,2.44,59.02]],"ltp":2.38,"tv":1587.01,"id":25173012}],"tv":67932.36}]}
{"op":"mcm","clk":"11811550407","pt":1723307676534,"mc":[{"id":"1.231664751","rc":[{"trd":[[1.71,1287.44],[1.72,4844.73]],"batb":[[0,1.7,1415.91],[1,1.69,7.59],[2,1.67,88.62]],"batl":[[0,1.72,1023.74]],"ltp":1.72,"tv":66480.62,"id":19144236},{"trd":[[2.4,43.2]],"batl":[[0,2.44,59.69],[1,2.48,136.91],[2,2.5,20.89]],"ltp":2.4,"tv":1588.82,"id":25173012}],"tv":68069.44}]}
{"op":"mcm","clk":"11811550619","pt":1723307677660,"mc":[{"id":"1.231664751","rc":[{"trd":[[1.71,1290.56],[1.72,6889.86],[1.76,2416.05]],"batl":[[0,1.71,1.6],[1,1.76,792.93]],"ltp":1.76,"tv":70943.01,"id":19144236},{"trd":[[2.38,1.9],[2.4,43.27]],"ltp":2.38,"tv":1590.59,"id":25173012}],"tv":72533.6}]}
{"op":"mcm","clk":"11811550818","pt":1723307678659,"mc":[{"id":"1.231664751","rc":[{"trd":[[1.71,1295.12],[1.72,6892.23]],"batl":[[0,1.71,1961.48]],"ltp":1.71,"tv":70949.93,"id":19144236},{"trd":[[2.38,2.47],[2.4,44.23]],"batl":[[1,2.48,136.71]],"ltp":2.4,"tv":1592.12,"id":25173012}],"tv":72542.06}]}
{"op":"mcm","clk":"11811551011","pt":1723307679674,"mc":[{"id":"1.231664751","rc":[{"trd":[[1.7,3057.55],[1.71,1298.65]],"batb":[[0,1.69,7.49],[1,1.67,88.62],[2,1.61,5.79]],"batl":[[0,1.7,511.34],[1,1.71,1957.95],[2,1.76,792.93]],"ltp":1.7,"tv":73787.99,"id":19144236},{"trd":[[2.4,46.75],[2.42,9.04]],"batl":[[0,2.44,58.92],[1,2.48,135.66]],"ltp":2.42,"tv":1596.54,"id":25173012}],"tv":75384.53}]}
{"op":"mcm","clk":"11811551170","pt":1723307680556,"mc":[{"id":"1.231664751","rc":[{"trd":[[1.7,4119.41],[1.71,2522.91]],"batl":[[0,1.7,355.28],[1,1.71,1345.82]],"ltp":1.7,"tv":76074.1,"id":19144236},{"trd":[[2.42,32.49]],"ltp":2.42,"tv":1619.98,"id":25173012}],"tv":77694.09}]}
{"op":"mcm","clk":"11811551373","pt":1723307681682,"mc":[{"id":"1.231664751","rc":[{"trd":[[1.7,4153.67],[1.71,2532.96]],"batb":[[1,1.68,90],[2,1.67,88.62]],"batl":[[0,1.71,1343.31],[1,1.8,141.62],[2,2,32.56]],"ltp":1.71,"tv":76118.41,"id":19144236},{"trd":[[2.42,33.33]],"batb":[[0,2.42,10.1],[1,2.2,10.06],[2,1.72,17.13]],"batl":[[0,2.44,53.66]],"ltp":2.42,"tv":1620.82,"id":25173012}],"tv":77739.24}]}
{"op":"mcm","clk":"11811551514","pt":1723307682392,"mc":[{"id":"1.231664751","rc":[{"trd":[[1.71,2649.28]],"batl":[[0,1.71,1279.59]],"ltp":1.71,"tv":76234.73,"id":19144236},{"trd":[[2.4,54.68],[2.42,53.53]],"batb":[[0,2.2,10.06],[1,1.72,17.13],[2,1.56,1500]],"ltp":2.4,"tv":1648.95,"id":25173012}],"tv":77883.68}]}
{"op":"mcm","clk":"11811551696","pt":1723307683400,"mc":[{"id":"1.231664751","rc":[{"trd":[[1.69,252.82],[1.7,4153.81],[1.71,2649.76]],"batb":[[0,1.68,90],[1,1.67,88.62],[2,1.61,5.79]],"batl":[[0,1.71,1279.35]],"ltp":1.71,"tv":76317.36,"id":19144236},{"trd":[[2.42,53.63],[2.44,78.87]],"batl":[[0,2.44,7.23]],"ltp":2.44,"tv":1695.48,"id":25173012}],"tv":78012.85}]}
{"op":"mcm","clk":"11811551901","pt":1723307684485,"mc":[{"id":"1.231664751","rc":[{"trd":[[1.69,262.89],[1.71,5219.64]],"batb":[[0,1.71,2196.04],[1,1.68,90],[2,1.67,88.62]],"batl":[[0,1.75,8678],[1,1.76,392.76],[2,1.8,141.62]],"ltp":1.71,"tv":78897.31,"id":19144236},{"trd":[[2.4,54.78],[2.44,85.84]],"batl":[[0,2.48,135.91],[1,2.5,20.89],[2,2.6,11.03]],"ltp":2.4,"tv":1702.55,"id":25173012}],"tv":80599.87}]}
{"op":"mcm","clk":"11811552034","pt":1723307685175,"mc":[{"id":"1.231664751","rc":[{"trd":[[1.71,5234.71]],"batb":[[0,1.71,2188.51]],"batl":[[0,1.76,392.76],[1,1.8,141.62],[2,2,32.56]],"ltp":1.71,"tv":78912.38,"id":19144236},{"batl":[[0,2.4,5.26],[1,2.48,135.91],[2,2.5,20.89]],"ltp":2.4,"tv":1702.55,"id":25173012}],"tv":80614.94}]}
{"op":"mcm","clk":"11811552435","pt":1723307687582,"mc":[{"id":"1.231664751","rc":[{"trd":[[1.71,5415.03]],"batb":[[0,1.72,18.19],[1,1.71,2098.35],[2,1.7,1300.45]],"batl":[[2,1.9,1.45]],"ltp":1.71,"tv":79092.7,"id":19144236},{"batb":[[2,1.5,1.51]],"batl":[[0,2.38,10.53],[1,2.4,5.26],[2,2.48,135.91]],"ltp":2.4,"tv":1702.55,"id":25173012}],"tv":80795.26}]}
{"op":"mcm","clk":"11811552627","pt":1723307688486,"mc":[{"id":"1.231664751","rc":[{"trd":[[1.72,6894.59],[1.76,2419.21]],"batb":[[0,1.72,17.01]],"batl":[[0,1.76,391.18]],"ltp":1.72,"tv":79098.22,"id":19144236},{"batl":[[1,2.4,6.32]],"ltp":2.4,"tv":1702.55,"id":25173012}],"tv":80800.78}]}
{"op":"mcm","clk":"11811552833","pt":1723307689599,"mc":[{"id":"1.231664751","rc":[{"trd":[[1.73,5.65],[1.76,2442.97]],"batb":[[0,1.73,17.48],[1,1.72,17.01],[2,1.71,2112.54]],"batl":[[0,1.76,367.42],[2,1.83,2000.79]],"ltp":1.73,"tv":79127.5,"id":19144236},{"trd":[[2.3,18.3]],"batb":[[0,2.2,10]],"batl":[[0,2.38,10.63],[1,2.4,6.42]],"ltp":2.3,"tv":1720.86,"id":25173012}],"tv":80848.36}]}
{"op":"mcm","clk":"11811553045","pt":1723307690601,"mc":[{"id":"1.231664751","rc":[{"trd":[[1.72,6937.88],[1.73,40.61],[1.74,1.94]],"batb":[[0,1.71,2120.42],[1,1.7,1308.33],[2,1.68,90]],"ltp":1.72,"tv":79205.89,"id":19144236},{"trd":[[2.34,0.1],[2.38,11.92]],"batl":[[0,2.38,1.18]],"ltp":2.38,"tv":1730.41,"id":25173012}],"tv":80936.3}]}
{"op":"mcm","clk":"11811553232","pt":1723307691590,"mc":[{"id":"1.231664751","rc":[{"batb":[[1,1.7,1309.84]],"ltp":1.72,"tv":79205.89,"id":19144236},{"batl":[[1,2.4,6.52],[2,2.42,3.18]],"ltp":2.38,"tv":1730.41,"id":25173012}]}]}
{"op":"mcm","clk":"11811553396","pt":1723307692495,"mc":[{"id":"1.231664751","rc":[{"trd":[[1.72,6937.98]],"batb":[[0,1.71,2173.01]],"ltp":1.72,"tv":79205.99,"id":19144236},{"trd":[[2.38,11.99]],"batl":[[0,2.38,3.63],[1,2.4,7.05]],"ltp":2.38,"tv":1730.48,"id":25173012}],"tv":80936.47}]}
{"op":"mcm","clk":"11811553591","pt":1723307693472,"mc":[{"id":"1.231664751","rc":[{"batb":[[1,1.7,1314.8]],"ltp":1.72,"tv":79205.99,"id":19144236},{"batl":[[0,2.38,4],[1,2.4,9.68],[2,2.42,5.69]],"ltp":2.38,"tv":1730.48,"id":25173012}]}]}
{"op":"mcm","clk":"11811553745","pt":1723307694393,"mc":[{"id":"1.231664751","rc":[{"trd":[[1.74,37.11]],"batb":[[0,1.71,2173.99]],"batl":[[0,1.74,164.54],[1,1.76,367.42],[2,1.8,141.62]],"ltp":1.74,"tv":79241.17,"id":19144236},{"batl":[[1,2.4,9.58]],"ltp":2.38,"tv":1730.48,"id":25173012}],"tv":80971.65}]}
{"op":"mcm","clk":"11811553966","pt":1723307695620,"mc":[{"id":"1.231664751","rc":[{"trd":[[1.71,5913.07],[1.72,6943.51]],"batb":[[0,1.71,1924.97]],"batl":[[1,1.8,141.62],[2,1.83,5447.02]],"ltp":1.71,"tv":79744.74,"id":19144236},{"trd":[[2.38,15.99]],"batl":[[0,2.4,9.58],[1,2.42,5.69],[2,2.48,135.91]],"ltp":2.38,"tv":1734.47,"id":25173012}],"tv":81479.22}]}
{"op":"mcm","clk":"11811554175","pt":1723307696593,"mc":[{"id":"1.231664751","rc":[{"trd":[[1.71,5918.33]],"batb":[[0,1.71,1928.25],[1,1.7,1264.02]],"ltp":1.71,"tv":79750.0,"id":19144236},{"batb":[[2,1.6,112.5]],"ltp":2.38,"tv":1734.47,"id":25173012}],"tv":81484.48}]}
{"op":"mcm","clk":"11811554339","pt":1723307697392,"mc":[{"id":"1.231664751","rc":[{"trd":[[1.74,41.13]],"batl":[[0,1.74,160.52]],"ltp":1.74,"tv":79754.02,"id":19144236},{"trd":[[2.34,3.09]],"ltp":2.34,"tv":1737.46,"id":25173012}],"tv":81491.49}]}
{"op":"mcm","clk":"11811554485","pt":1723307698198,"mc":[{"id":"1.231664751","rc":[{"trd":[[1.71,5918.61],[1.74,44.57]],"batb":[[0,1.71,1928.26],[1,1.7,1256.14]],"batl":[[0,1.74,158.78]],"ltp":1.74,"tv":79757.73,"id":19144236},{"trd":[[2.34,3.13]],"batl":[[0,2.4,6.85]],"ltp":2.34,"tv":1737.5,"id":25173012}],"tv":81495.24}]}
{"op":"mcm","clk":"11811554740","pt":1723307699513,"mc":[{"id":"1.231664751","rc":[{"trd":[[1.72,6946.72],[1.74,79.14]],"batb":[[0,1.73,49.89],[1,1.71,1929.39],[2,1.7,1256.14]],"batl":[[0,1.74,134.43]],"ltp":1.74,"tv":79795.52,"id":19144236},{"trd":[[2.34,13.64],[2.38,16]],"ltp":2.34,"tv":1748.02,"id":25173012}],"tv":81543.55}]}
{"op":"mcm","clk":"11811554874","pt":1723307700145,"mc":[{"id":"1.231664751","rc":[{"trd":[[1.73,140.4],[1.74,88.18]],"batb":[[0,1.71,1929.3],[1,1.7,1256.14],[2,1.68,90]],"batl":[[0,1.72,9.32],[1,1.73,52.59],[2,1.74,129.9]],"ltp":1.73,"tv":79904.35,"id":19144236},{"trd":[[2.34,13.66]],"batl":[[1,2.42,3.18]],"ltp":2.34,"tv":1748.04,"id":25173012}],"tv":81652.39}]}
{"op":"mcm","clk":"11811555161","pt":1723307701525,"mc":[{"id":"1.231664751","rc":[{"trd":[[1.71,5919.82],[1.72,6959.79],[1.73,140.54]],"batb":[[0,1.71,1928.69]],"batl":[[0,1.73,50.79],[1,1.74,10.52],[2,1.75,1.38]],"ltp":1.73,"tv":79918.76,"id":19144236},{"trd":[[2.36,0.1],[2.38,20.02]],"batl":[[0,2.4,5.95],[2,2.48,134.82]],"ltp":2.36,"tv":1752.16,"id":25173012}],"tv":81670.93}]}
{"op":"mcm","clk":"11811555404","pt":1723307702608,"mc":[{"id":"1.231664751","rc":[{"trd":[[1.73,142.34]],"batl":[[0,1.73,22.69],[2,1.8,141.62]],"ltp":1.73,"tv":79920.56,"id":19144236},{"trd":[[2.36,1.41]],"ltp":2.36,"tv":1753.47,"id":25173012}],"tv":81674.04}]}
{"op":"mcm","clk":"11811555600","pt":1723307703612,"mc":[{"id":"1.231664751","rc":[{"trd":[[1.73,142.48]],"batb":[[0,1.71,1928.54]],"batl":[[0,1.73,23.08]],"ltp":1.73,"tv":79920.7,"id":19144236},{"trd":[[2.36,1.51]],"ltp":2.36,"tv":1753.57,"id":25173012}],"tv":81674.28}]}
{"op":"mcm","clk":"11811555757","pt":1723307704427,"mc":[{"id":"1.231664751","rc":[{"trd":[[1.72,7091.66],[1.73,180.91],[1.74,109.22],[1.8,18.22]],"batl":[[0,1.8,132.51],[1,1.83,5447.02],[2,1.84,78.89]],"ltp":1.8,"tv":80130.26,"id":19144236},{"trd":[[2.36,6.4],[2.38,20.5]],"batb":[[1,2,80],[2,1.72,17.13]],"ltp":2.38,"tv":1758.94,"id":25173012}],"tv":81889.21}]}
{"op":"mcm","clk":"11811555927","pt":1723307705331,"mc":[{"id":"1.231664751","rc":[{"trd":[[1.72,7093.11]],"batl":[[0,1.72,15.69],[1,1.8,132.51],[2,1.83,5447.02]],"ltp":1.72,"tv":80131.71,"id":19144236},{"trd":[[2.38,21.55],[2.4,55.1],[2.42,53.67]],"batl":[[0,2.42,1.24],[1,2.48,134.82],[2,2.5,19.84]],"ltp":2.38,"tv":1760.35,"id":25173012}],"tv":81892.06}]}
{"op":"mcm","clk":"11811556197","pt":1723307706608,"mc":[{"id":"1.231664751","rc":[{"trd":[[1.71,6463.64],[1.72,7095.06]],"batb":[[0,1.71,1655.74]],"batl":[[0,1.72,13.74],[1,1.73,4.16],[2,1.8,132.51]],"ltp":1.72,"tv":80677.48,"id":19144236},{"trd":[[2.38,22.96]],"ltp":2.38,"tv":1761.76,"id":25173012}],"tv":82439.25}]}
{"op":"mcm","clk":"11811556397","pt":1723307707623,"mc":[{"id":"1.231664751","rc":[{"trd":[[1.72,7095.9]],"batb":[[0,1.71,1641.55],[1,1.7,6.47]],"batl":[[0,1.72,12.9],[2,1.79,76]],"ltp":1.72,"tv":80678.32,"id":19144236},{"trd":[[2.38,23.56]],"batl":[[1,2.48,134.03]],"ltp":2.38,"tv":1762.37,"id":25173012}],"tv":82440.69}]}
{"op":"mcm","clk":"11811556591","pt":1723307708619,"mc":[{"id":"1.231664751","rc":[{"trd":[[1.72,7105.7]],"batl":[[0,1.72,6.21]],"ltp":1.72,"tv":80688.13,"id":19144236},{"trd":[[2.38,26.3]],"batl":[[0,2.42,1.77]],"ltp":2.38,"tv":1765.1,"id":25173012}],"tv":82453.23}]}
{"op":"mcm","clk":"11811556748","pt":1723307709412,"mc":[{"id":"1.231664751","rc":[{"trd":[[1.71,6481.38],[1.72,7118.12],[1.73,182.91]],"batb":[[0,1.78,8678],[1,1.74,1.06],[2,1.73,45.53]],"batl":[[0,1.79,76],[1,1.8,132.51],[2,1.84,79.68]],"ltp":1.71,"tv":80720.29,"id":19144236},{"batl":[[0,2.42,1.96]],"ltp":2.38,"tv":1765.1,"id":25173012}],"tv":82485.39}]}
{"op":"mcm","clk":"11811556966","pt":1723307710599,"mc":[{"id":"1.231664751","rc":[{"trd":[[1.79,178.53],[1.8,283.24],[1.81,271.83]],"batb":[[0,1.83,9790.7],[1,1.79,704.96],[2,1.78,9382.96]],"batl":[[0,1.84,78.89],[1,1.95,11.18],[2,2,31.9]],"ltp":1.81,"tv":81138.88,"id":19144236},{"batl":[[0,2.42,2.16]],"ltp":2.38,"tv":1765.1,"id":25173012}],"tv":82903.99}]}
{"op":"mcm","clk":"11811557157","pt":1723307711607,"mc":[{"id":"1.231664751","rc":[{"batb":[[0,1.79,1409.91],[1,1.78,9382.96],[2,1.77,1409.91]],"ltp":1.81,"tv":81138.88,"id":19144236},{"batl":[[0,2.34,3.99],[1,2.42,1.87],[2,2.48,134.03]],"ltp":2.38,"tv":1765.1,"id":25173012}]}]}
{"op":"mcm","clk":"11811557356","pt":1723307712620,"mc":[{"id":"1.231664751","rc":[{"trd":[[1.79,2569.61],[1.81,1054.94]],"batb":[[0,1.79,214.38]],"ltp":1.79,"tv":84313.06,"id":19144236},{"batl":[[0,2.34,4.95],[1,2.36,7.65],[2,2.42,2.71]],"ltp":2.38,"tv":1765.1,"id":25173012}],"tv":86078.16}]}
{"op":"mcm","clk":"11811557567","pt":1723307713641,"mc":[{"id":"1.231664751","rc":[{"trd":[[1.78,4.99],[1.81,1055.54]],"batb":[[0,1.78,9381.68],[1,1.77,1409.91],[2,1.74,1.16]],"batl":[[1,1.87,2000],[2,1.95,11.18]],"ltp":1.78,"tv":84316.23,"id":19144236},{"batl":[[0,2.34,5.14],[2,2.38,19.94]],"ltp":2.38,"tv":1765.1,"id":25173012}],"tv":86081.33}]}
{"op":"mcm","clk":"11811557769","pt":1723307714612,"mc":[{"id":"1.231664751","rc":[{"batb":[[0,1.82,260.83],[1,1.78,704.96],[2,1.74,3.79]],"ltp":1.78,"tv":84316.23,"id":19144236},{"batl":[[0,2.34,5.36],[2,2.38,20.16]],"ltp":2.38,"tv":1765.1,"id":25173012}]}]}
{"op":"mcm","clk":"11811557931","pt":1723307715431,"mc":[{"id":"1.231664751","rc":[{"trd":[[1.82,4]],"batb":[[0,1.82,258.83],[1,1.78,705.06]],"ltp":1.82,"tv":84320.23,"id":19144236},{"batl":[[0,2.34,5.67],[2,2.38,20.61]],"ltp":2.38,"tv":1765.1,"id":25173012}],"tv":86085.33}]}
{"op":"mcm","clk":"11811558168","pt":1723307716619,"mc":[{"id":"1.231664751","rc":[{"trd":[[1.82,4.36]],"batb":[[0,1.82,258.65]],"ltp":1.82,"tv":84320.59,"id":19144236},{"batb":[[2,1.73,1000]],"batl":[[0,2.34,4.43],[1,2.38,20.71],[2,2.42,1.16]],"ltp":2.38,"tv":1765.1,"id":25173012}],"tv":86085.69}]}
{"op":"mcm","clk":"11811558386","pt":1723307717619,"mc":[{"id":"1.231664751","rc":[{"trd":[[1.82,4.49]],"batb":[[0,1.82,258.59],[1,1.8,92.43]],"ltp":1.82,"tv":84320.72,"id":19144236},{"batl":[[1,2.38,4.42],[2,2.4,19.94]],"ltp":2.38,"tv":1765.1,"id":25173012}],"tv":86085.82}]}
{"op":"mcm","clk":"11811558577","pt":1723307718608,"mc":[{"id":"1.231664751","rc":[{"trd":[[1.82,31.6]],"batb":[[0,1.82,245.03],[1,1.74,3.89],[2,1.73,1054.87]],"ltp":1.82,"tv":84347.83,"id":19144236},{"batl":[[0,2.34,3.54],[1,2.38,5.91]],"ltp":2.38,"tv":1765.1,"id":25173012}],"tv":86112.93}]}
{"op":"mcm","clk":"11811558779","pt":1723307719624,"mc":[{"id":"1.231664751","rc":[{"trd":[[1.77,49.43],[1.82,521.67]],"batb":[[0,1.74,3.79],[1,1.73,1054.87],[2,1.72,150.91]],"batl":[[0,1.82,146.92],[1,1.83,59.11],[2,1.84,78.89]],"ltp":1.77,"tv":84887.12,"id":19144236},{"trd":[[2.3,56.39]],"batb":[[0,2.3,7.09],[1,2.2,10],[2,2,80]],"batl":[[0,2.34,3.44],[1,2.38,6.43]],"ltp":2.3,"tv":1803.19,"id":25173012}],"tv":86690.31}]}
{"op":"mcm","clk":"11811559006","pt":1723307720631,"mc":[{"id":"1.231664751","rc":[{"trd":[[1.77,58.64],[1.78,5.79],[1.8,285.77]],"batb":[[0,1.8,14.84],[1,1.79,1483.02],[2,1.74,3.79]],"batl":[[0,1.82,146.52]],"ltp":1.8,"tv":84899.68,"id":19144236},{"trd":[[2.3,63.48]],"batb":[[0,2.2,10],[1,2,80],[2,1.73,1000]],"batl":[[0,2.34,3.59]],"ltp":2.3,"tv":1810.28,"id":25173012}],"tv":86709.96}]}
{"op":"mcm","clk":"11811559226","pt":1723307721613,"mc":[{"id":"1.231664751","rc":[{"trd":[[1.8,290.03],[1.82,2027.31]],"batb":[[0,1.8,12.71]],"batl":[[0,1.82,569.53]],"ltp":1.82,"tv":86409.58,"id":19144236}],"tv":88219.86}]}
{"op":"mcm","clk":"11811559447","pt":1723307722637,"mc":[{"id":"1.231664751","rc":[{"trd":[[1.82,2029.09]],"batl":[[0,1.82,568.66]],"ltp":1.82,"tv":86411.36,"id":19144236},{"batb":[[0,2.24,9.02],[1,2.2,10],[2,2,80]],"batl":[[0,2.34,3.49],[1,2.38,3.62]],"ltp":2.3,"tv":1810.28,"id":25173012}],"tv":88221.64}]}
{"op":"mcm","clk":"11811559652","pt":1723307723626,"mc":[{"id":"1.231664751","rc":[{"batl":[[1,1.83,64.37]],"ltp":1.82,"tv":86411.36,"id":19144236},{"batl":[[0,2.34,3.34],[1,2.38,2.76]],"ltp":2.3,"tv":1810.28,"id":25173012}]}]}
{"op":"mcm","clk":"11811559854","pt":1723307724631,"mc":[{"id":"1.231664751","rc":[{"batb":[[1,1.79,1485.54]],"batl":[[0,1.82,578.94]],"ltp":1.82,"tv":86411.36,"id":19144236},{"trd":[[2.24,15.58]],"batb":[[0,2.24,1.23]],"batl":[[0,2.34,3.44]],"ltp":2.24,"tv":1825.86,"id":25173012}],"tv":88237.23}]}
{"op":"mcm","clk":"11811560044","pt":1723307725631,"mc":[{"id":"1.231664751","rc":[{"trd":[[1.82,2029.39]],"batl":[[0,1.82,578.89]],"ltp":1.82,"tv":86411.66,"id":19144236},{"trd":[[2.2,4.48],[2.24,18.04]],"batb":[[0,2.22,3.09],[1,2.2,7.76]],"batl":[[1,2.38,2.23]],"ltp":2.2,"tv":1832.8,"id":25173012}],"tv":88244.47}]}
{"op":"mcm","clk":"11811560257","pt":1723307726647,"mc":[{"id":"1.231664751","rc":[{"trd":[[1.82,2109.96]],"batb":[[0,1.79,1485.54],[1,1.74,1.16],[2,1.73,1052.36]],"batl":[[0,1.82,733.31]],"ltp":1.82,"tv":86492.23,"id":19144236},{"trd":[[2.22,38.97]],"batb":[[0,2.22,3.23]],"batl":[[0,2.34,3.25],[1,2.38,2.19]],"ltp":2.22,"tv":1834.62,"id":25173012}],"tv":88326.85}]}
{"op":"mcm","clk":"11811560445","pt":1723307727637,"mc":[{"id":"1.231664751","rc":[{"trd":[[1.82,2112.07]],"batl":[[0,1.82,740.03]],"ltp":1.82,"tv":86494.34,"id":19144236}],"tv":88328.97}]}
{"op":"mcm","clk":"11811560614","pt":1723307728569,"mc":[{"id":"1.231664751","rc":[{"trd":[[1.82,3187.15]],"batb":[[1,1.77,76],[2,1.74,1.16]],"batl":[[0,1.82,175.02]],"ltp":1.82,"tv":87569.43,"id":19144236}],"tv":89404.05}]}
{"op":"mcm","clk":"11811560826","pt":1723307729657,"mc":[{"id":"1.231664751","rc":[{"trd":[[1.79,2570.51],[1.82,3191.46]],"batb":[[0,1.79,1485.09]],"batl":[[0,1.8,80],[1,1.82,172.87],[2,1.83,64.37]],"ltp":1.79,"tv":87574.63,"id":19144236},{"batl":[[0,2.34,3.15],[1,2.38,2.09]],"ltp":2.22,"tv":1834.62,"id":25173012}],"tv":89409.26}]}
{"op":"mcm","clk":"11811561048","pt":1723307730628,"mc":[{"id":"1.231664751","rc":[{"trd":[[1.79,2570.71],[1.8,311.45]],"batb":[[0,1.79,1484.99],[1,1.78,84.14],[2,1.77,76]],"batl":[[0,1.8,24.23],[1,1.82,172.97]],"ltp":1.8,"tv":87596.25,"id":19144236},{"trd":[[2.24,18.35]],"ltp":2.24,"tv":1834.92,"id":25173012}],"tv":89431.18}]}
{"op":"mcm","clk":"11811561259","pt":1723307731661,"mc":[{"id":"1.231664751","rc":[{"trd":[[1.79,2600.92],[1.8,313.15]],"batb":[[0,1.79,1469.88],[2,1.77,76.08]],"batl":[[0,1.8,28.61],[1,1.82,154.29]],"ltp":1.8,"tv":87628.16,"id":19144236},{"trd":[[2.24,19.35]],"batl":[[0,2.34,3.17],[2,2.4,19.84]],"ltp":2.24,"tv":1835.92,"id":25173012}],"tv":89464.09}]}
{"op":"mcm","clk":"11811561497","pt":1723307732633,"mc":[{"id":"1.231664751","rc":[{"trd":[[1.8,365.75]],"batl":[[0,1.8,69.44],[1,1.81,149.05],[2,1.82,154.29]],"ltp":1.8,"tv":87680.76,"id":19144236},{"batb":[[0,2.22,4.28]],"ltp":2.24,"tv":1835.92,"id":25173012}],"tv":89516.68}]}
{"op":"mcm","clk":"11811561710","pt":1723307733569,"mc":[{"id":"1.231664751","rc":[{"trd":[[1.79,2603.02],[1.8,383.2]],"batb":[[0,1.79,1468.83]],"batl":[[0,1.8,78.15],[2,1.82,203.52]],"ltp":1.8,"tv":87700.31,"id":19144236},{"trd":[[2.24,19.41]],"batl":[[0,2.34,3.27],[1,2.38,2.06]],"ltp":2.24,"tv":1835.98,"id":25173012}],"tv":89536.3}]}
{"op":"mcm","clk":"11811561857","pt":1723307734347,"mc":[{"id":"1.231664751","rc":[{"trd":[[1.8,410.2]],"batl":[[0,1.8,57.49]],"ltp":1.8,"tv":87727.31,"id":19144236},{"trd":[[2.24,24.82]],"ltp":2.24,"tv":1841.39,"id":25173012}],"tv":89568.71}]}
{"op":"mcm","clk":"11811562028","pt":1723307735218,"mc":[{"id":"1.231664751","rc":[{"trd":[[1.8,503.71],[1.81,1072.58]],"batl":[[0,1.81,140.63],[1,1.82,203.52],[2,1.83,64.37]],"ltp":1.81,"tv":87837.86,"id":19144236},{"trd":[[2.24,35.34]],"ltp":2.24,"tv":1851.91,"id":25173012}],"tv":89689.78}]}
{"op":"mcm","clk":"11811562307","pt":1723307736658,"mc":[{"id":"1.231664751","rc":[{"trd":[[1.8,503.81],[1.81,1093.9]],"batb":[[2,1.77,76]],"batl":[[0,1.81,119.21],[1,1.82,198.26],[2,1.83,59.11]],"ltp":1.81,"tv":87859.28,"id":19144236},{"trd":[[2.22,60.61],[2.24,35.42]],"batb":[[0,2.2,7.76],[1,2,80],[2,1.72,17.13]],"ltp":2.22,"tv":1873.63,"id":25173012}],"tv":89732.92}]}
{"op":"mcm","clk":"11811562501","pt":1723307737552,"mc":[{"id":"1.231664751","rc":[{"trd":[[1.8,504.71],[1.81,1113.36]],"batl":[[0,1.81,108.77]],"ltp":1.8,"tv":87879.64,"id":19144236},{"trd":[[2.22,61.77],[2.26,20.24]],"batb":[[0,2.26,9.8],[1,2.2,7.76],[2,2,80]],"batl":[[2,2.42,1.06]],"ltp":2.26,"tv":1875.51,"id":25173012}],"tv":89755.16}]}
{"op":"mcm","clk":"11811562721","pt":1723307738632,"mc":[{"id":"1.231664751","rc":[{"trd":[[1.8,674.17]],"batl":[[0,1.8,423.26],[1,1.81,108.77],[2,1.82,207.32]],"ltp":1.8,"tv":88049.1,"id":19144236},{"trd":[[2.26,20.42]],"batb":[[0,2.26,7.08]],"ltp":2.26,"tv":1875.69,"id":25173012}],"tv":89924.8}]}
{"op":"mcm","clk":"11811562920","pt":1723307739542,"mc":[{"id":"1.231664751","rc":[{"trd":[[1.79,2604.58],[1.8,1273.72],[1.81,1330.9],[1.82,3220.08]],"batb":[[0,1.82,736.17],[1,1.8,2.52],[2,1.79,1468.05]],"batl":[[0,1.83,59.11],[1,1.84,78.89],[2,1.87,1.38]],"ltp":1.82,"tv":88896.38,"id":19144236},{"trd":[[2.26,27.5]],"batb":[[0,2.2,7.76],[1,2,80],[2,1.72,17.22]],"batl":[[0,2.26,1.39],[1,2.34,3.17],[2,2.38,2.06]],"ltp":2.26,"tv":1882.77,"id":25173012}],"tv":90779.15}]}
{"op":"mcm","clk":"11811563150","pt":1723307740635,"mc":[{"id":"1.231664751","rc":[{"trd":[[1.82,3220.28],[1.83,128.1],[1.84,13.32]],"batb":[[0,1.83,3264.25],[1,1.82,789.21],[2,1.8,7.97]],"batl":[[0,1.84,65.57],[1,1.87,1.38],[2,1.95,11.18]],"ltp":1.84,"tv":89028.12,"id":19144236},{"trd":[[2.18,11.24],[2.2,20]],"batb":[[0,2,80],[1,1.72,17.22],[2,1.7,1000]],"batl":[[0,2.24,1.46],[1,2.34,3.73]],"ltp":2.18,"tv":1909.53,"id":25173012}],"tv":90937.66}]}
{"op":"mcm","clk":"11811563347","pt":1723307741634,"mc":[{"id":"1.231664751","rc":[{"batb":[[2,1.8,21.76]],"ltp":1.84,"tv":89028.12,"id":19144236},{"batl":[[0,2.24,7.12]],"ltp":2.18,"tv":1909.53,"id":25173012}]}]}
{"op":"mcm","clk":"11811563533","pt":1723307742667,"mc":[{"id":"1.231664751","rc":[{"trd":[[1.83,130.1]],"batb":[[0,1.83,1298.55],[2,1.8,29.86]],"batl":[[1,1.95,11.18],[2,2,2031.9]],"ltp":1.83,"tv":89030.12,"id":19144236},{"trd":[[2.22,63.45]],"batl":[[0,2.24,9.77],[1,2.3,20.52],[2,2.34,3.05]],"ltp":2.22,"tv":1911.21,"id":25173012}],"tv":90941.34}]}
{"op":"mcm","clk":"11811563697","pt":1723307743657,"mc":[{"id":"1.231664751","rc":[{"trd":[[1.83,260.81]],"batb":[[0,1.83,1233.2],[2,1.8,38.71]],"ltp":1.83,"tv":89160.82,"id":19144236},{"batl":[[0,2.24,10.02]],"ltp":2.22,"tv":1911.21,"id":25173012}],"tv":91072.04}]}
{"op":"mcm","clk":"11811563850","pt":1723307744566,"mc":[{"id":"1.231664751","rc":[{"trd":[[1.83,407.53]],"batb":[[0,1.83,1085.31],[1,1.82,790.79],[2,1.81,26.38]],"ltp":1.83,"tv":89307.54,"id":19144236}],"tv":91218.76}]}
{"op":"mcm","clk":"11811564069","pt":1723307745649,"mc":[{"id":"1.231664751","rc":[{"trd":[[1.83,444.74]],"batb":[[0,1.83,1066.7]],"ltp":1.83,"tv":89344.76,"id":19144236},{"batl":[[0,2.24,11.59]],"ltp":2.22,"tv":1911.21,"id":25173012}],"tv":91255.98}]}
{"op":"mcm","clk":"11811564267","pt":1723307746659,"mc":[{"id":"1.231664751","rc":[{"trd":[[1.84,144.46],[1.85,10.7]],"batb":[[0,1.85,17284.99],[1,1.84,10000],[2,1.83,6102.1]],"batl":[[0,1.95,11.18],[1,2,31.9],[2,2.04,3.15]],"ltp":1.85,"tv":89486.6,"id":19144236},{"trd":[[2.18,11.39]],"batl":[[0,2.24,12.74]],"ltp":2.18,"tv":1911.37,"id":25173012}],"tv":91397.97}]}
{"op":"mcm","clk":"11811564461","pt":1723307747655,"mc":[{"id":"1.231664751","rc":[{"trd":[[1.87,2.29]],"batb":[[0,1.88,2517.7],[1,1.87,2517.09],[2,1.85,22320.39]],"ltp":1.87,"tv":89487.21,"id":19144236},{"trd":[[2.16,0.53]],"batl":[[0,2.22,2.54],[1,2.24,12.84],[2,2.34,3.73]],"ltp":2.16,"tv":1911.9,"id":25173012}],"tv":91399.11}]}
{"op":"mcm","clk":"11811564666","pt":1723307748649,"mc":[{"id":"1.231664751","rc":[{"trd":[[1.88,12.68],[1.9,126.24]],"batb":[[0,1.91,390.89],[1,1.88,2511.24],[2,1.87,12517.09]],"batl":[[0,1.95,10.52]],"ltp":1.9,"tv":89500.26,"id":19144236},{"trd":[[2.14,1.96]],"batl":[[1,2.24,12.88]],"ltp":2.14,"tv":1912.95,"id":25173012}],"tv":91413.21}]}
{"op":"mcm","clk":"11811564840","pt":1723307749445,"mc":[{"id":"1.231664751","rc":[{"trd":[[1.88,3967.26],[1.91,781.78]],"batb":[[0,1.88,533.95],[1,1.87,2517.09],[2,1.85,22320.39]],"ltp":1.88,"tv":94236.62,"id":19144236},{"batl":[[1,2.24,10.78]],"ltp":2.14,"tv":1912.95,"id":25173012}],"tv":96149.57}]}
{"op":"mcm","clk":"11811565051","pt":1723307750574,"mc":[{"id":"1.231664751","rc":[{"trd":[[1.88,3977.98]],"batb":[[0,1.88,528.59],[2,1.85,7388.34]],"ltp":1.88,"tv":94247.34,"id":19144236},{"batl":[[1,2.24,11.54],[2,2.34,3.72]],"ltp":2.14,"tv":1912.95,"id":25173012}],"tv":96160.29}]}
{"op":"mcm","clk":"11811565248","pt":1723307751564,"mc":[{"id":"1.231664751","rc":[{"trd":[[1.87,17.54],[1.88,3981.42]],"batb":[[0,1.87,2509.46],[1,1.85,7388.34],[2,1.84,843.96]],"ltp":1.87,"tv":94266.04,"id":19144236},{"batl":[[1,2.24,11.64]],"ltp":2.14,"tv":1912.95,"id":25173012}],"tv":96178.99}]}
{"op":"mcm","clk":"11811565467","pt":1723307752442,"mc":[{"id":"1.231664751","rc":[{"trd":[[1.85,31.74],[1.87,23.11]],"batb":[[0,1.85,7377.82],[1,1.83,6102.1],[2,1.82,1.94]],"ltp":1.85,"tv":94292.64,"id":19144236},{"batl":[[0,2.2,396.56],[1,2.22,2.54],[2,2.24,11.64]],"ltp":2.14,"tv":1912.95,"id":25173012}],"tv":96205.59}]}
{"op":"mcm","clk":"11811565716","pt":1723307753662,"mc":[{"id":"1.231664751","rc":[{"trd":[[1.85,74.88]],"batb":[[0,1.85,2352.41],[1,1.84,3.84],[2,1.83,6102.1]],"ltp":1.85,"tv":94335.78,"id":19144236},{"batl":[[1,2.22,22.38],[2,2.24,11.54]],"ltp":2.14,"tv":1912.95,"id":25173012}],"tv":96248.73}]}
{"op":"mcm","clk":"11811565868","pt":1723307754443,"mc":[{"id":"1.231664751","rc":[{"trd":[[1.85,75.94]],"batb":[[0,1.85,2351.88],[2,1.83,1066.7]],"batl":[[0,1.89,69.16],[1,1.95,10.52],[2,2,31.9]],"ltp":1.85,"tv":94336.84,"id":19144236},{"batl":[[2,2.24,10.6]],"ltp":2.14,"tv":1912.95,"id":25173012}],"tv":96249.79}]}
{"op":"mcm","clk":"11811566106","pt":1723307755648,"mc":[{"id":"1.231664751","rc":[{"trd":[[1.85,86.92]],"batb":[[0,1.85,2346.39]],"ltp":1.85,"tv":94347.82,"id":19144236}],"tv":96260.77}]}
{"op":"mcm","clk":"11811566250","pt":1723307756463,"mc":[{"id":"1.231664751","rc":[{"trd":[[1.85,89.56],[1.89,31.52]],"batb":[[0,1.85,2345.07],[1,1.84,4.59]],"batl":[[0,1.89,53.4],[1,1.92,391.55],[2,1.95,10.52]],"ltp":1.89,"tv":94381.98,"id":19144236},{"batl":[[0,2.2,396.59],[1,2.22,2.52],[2,2.24,5.23]],"ltp":2.14,"tv":1912.95,"id":25173012}],"tv":96294.93}]}
{"op":"mcm","clk":"11811566512","pt":1723307757657,"mc":[{"id":"1.231664751","rc":[{"trd":[[1.86,0.2],[1.89,31.69]],"batb":[[0,1.86,92.23],[1,1.85,2345.07],[2,1.84,4.59]],"batl":[[0,1.89,53.23],[1,1.9,197.89],[2,1.91,1.01]],"ltp":1.86,"tv":94382.35,"id":19144236},{"trd":[[2.12,1]],"batb":[[1,1.92,111],[2,1.72,17.22]],"batl":[[0,2.22,2.85],[1,2.24,5.23],[2,2.34,3.15]],"ltp":2.12,"tv":1913.1,"id":25173012}],"tv":96295.45}]}
{"op":"mcm","clk":"11811566683","pt":1723307758563,"mc":[{"id":"1.231664751","rc":[{"trd":[[1.86,2.14]],"batb":[[0,1.86,90.82]],"ltp":1.86,"tv":94384.29,"id":19144236},{"trd":[[2.18,12.74]],"batb":[[0,2.1,5.26],[1,2,80],[2,1.92,111]],"batl":[[0,2.22,2.55]],"ltp":2.18,"tv":1914.45,"id":25173012}],"tv":96298.75}]}
{"op":"mcm","clk":"11811566848","pt":1723307759583,"mc":[{"id":"1.231664751","rc":[{"trd":[[1.89,32.75]],"batb":[[2,1.84,4.68]],"batl":[[0,1.89,52.7],[2,1.91,1.23]],"ltp":1.89,"tv":94385.35,"id":19144236},{"batl":[[1,2.24,4.37],[2,2.34,3.34]],"ltp":2.18,"tv":1914.45,"id":25173012}],"tv":96299.81}]}
{"op":"mcm","clk":"11811567052","pt":1723307760577,"mc":[{"id":"1.231664751","rc":[{"trd":[[1.86,14.79]],"batb":[[0,1.86,84.5]],"batl":[[0,1.88,2038.11],[1,1.89,52.7],[2,1.9,18.88]],"ltp":1.86,"tv":94398.0,"id":19144236},{"batl":[[2,2.34,3.24]],"ltp":2.18,"tv":1914.45,"id":25173012}],"tv":96312.45}]}
{"op":"mcm","clk":"11811567270","pt":1723307761580,"mc":[{"id":"1.231664751","rc":[{"trd":[[1.86,14.99],[1.88,5647.74]],"batb":[[0,1.86,84.4]],"batl":[[0,1.88,1204.95]],"ltp":1.88,"tv":96064.52,"id":19144236},{"batl":[[0,2.16,19.84],[1,2.22,2.65],[2,2.24,4.32]],"ltp":2.18,"tv":1914.45,"id":25173012}],"tv":97978.97}]}
{"op":"mcm","clk":"11811567498","pt":1723307762667,"mc":[{"id":"1.231664751","rc":[{"trd":[[1.86,16.7],[1.88,5647.89]],"batb":[[0,1.86,83.54]],"batl":[[0,1.88,1204.8]],"ltp":1.88,"tv":96066.38,"id":19144236},{"trd":[[2.12,1.13],[2.16,1.59]],"batl":[[0,2.16,415.57]],"ltp":2.12,"tv":1915.64,"id":25173012}],"tv":97982.03}]}
{"op":"mcm","clk":"11811567710","pt":1723307763677,"mc":[{"id":"1.231664751","rc":[{"trd":[[1.87,44.6],[1.88,5648.38]],"batl":[[0,1.87,11.85],[1,1.88,1204.56],[2,1.89,52.7]],"ltp":1.87,"tv":96088.36,"id":19144236},{"trd":[[2.14,20.31]],"ltp":2.14,"tv":1933.98,"id":25173012}],"tv":98022.35}]}
{"op":"mcm","clk":"11811567920","pt":1723307764660,"mc":[{"id":"1.231664751","rc":[{"trd":[[1.86,16.9],[1.87,115.48],[1.88,5739.08]],"batb":[[0,1.86,83.44]],"batl":[[0,1.88,1159.2],[1,1.89,52.7],[2,1.9,18.88]],"ltp":1.88,"tv":96250.15,"id":19144236},{"trd":[[2.14,20.41]],"ltp":2.14,"tv":1934.08,"id":25173012}],"tv":98184.23}]}
{"op":"mcm","clk":"11811568157","pt":1723307765669,"mc":[{"id":"1.231664751","rc":[{"trd":[[1.86,173.43],[1.87,115.59],[1.88,6654.44]],"batb":[[0,1.85,2345.07],[1,1.84,4.68],[2,1.83,1066.7]],"batl":[[0,1.87,20.04],[1,1.88,701.52],[2,1.89,52.7]],"ltp":1.87,"tv":97322.15,"id":19144236},{"trd":[[2.14,20.51],[2.16,136.38]],"batl":[[0,2.16,280.78]],"ltp":2.14,"tv":2068.97,"id":25173012}],"tv":99391.13}]}
{"op":"mcm","clk":"11811568354","pt":1723307766597,"mc":[{"id":"1.231664751","rc":[{"trd":[[1.87,222.89]],"batb":[[0,1.84,4.68],[1,1.83,1066.7],[2,1.82,1.94]],"batl":[[0,1.87,163.36]],"ltp":1.87,"tv":97429.45,"id":19144236},{"trd":[[2.14,25.02]],"ltp":2.14,"tv":2073.48,"id":25173012}],"tv":99502.93}]}
{"op":"mcm","clk":"11811568558","pt":1723307767660,"mc":[{"id":"1.231664751","rc":[{"trd":[[1.86,231.68],[1.87,385.66]],"batb":[[0,1.84,3.36]],"batl":[[0,1.87,81.97]],"ltp":1.87,"tv":97650.46,"id":19144236},{"trd":[[2.16,186.53]],"batl":[[0,2.16,230.63],[1,2.24,4.45],[2,2.34,3.24]],"ltp":2.16,"tv":2123.64,"id":25173012}],"tv":99774.1}]}
{"op":"mcm","clk":"11811568692","pt":1723307768490,"mc":[{"id":"1.231664751","rc":[{"trd":[[1.87,549.6],[1.88,6751.03]],"batb":[[0,1.87,1320.97],[1,1.84,3.36],[2,1.83,1066.7]],"batl":[[0,1.88,653.23],[1,1.89,52.7],[2,1.9,18.88]],"ltp":1.88,"tv":97910.99,"id":19144236},{"batl":[[2,2.34,4.81]],"ltp":2.16,"tv":2123.64,"id":25173012}],"tv":100034.63}]}
{"op":"mcm","clk":"11811568918","pt":1723307769574,"mc":[{"id":"1.231664751","rc":[{"trd":[[1.87,562.8],[1.88,6770.76]],"batb":[[0,1.87,1314.37]],"batl":[[0,1.88,640.99]],"ltp":1.87,"tv":97943.92,"id":19144236},{"trd":[[2.12,7.42],[2.16,186.73]],"batl":[[0,2.16,230.53]],"ltp":2.12,"tv":2130.12,"id":25173012}],"tv":100074.05}]}
{"op":"mcm","clk":"11811569146","pt":1723307770656,"mc":[{"id":"1.231664751","rc":[{"trd":[[1.87,1391.81],[1.88,7734.72]],"batb":[[0,1.87,899.86]],"batl":[[0,1.88,153.22],[2,1.91,28.82]],"ltp":1.88,"tv":99736.9,"id":19144236},{"trd":[[2.12,17.68],[2.16,187.79]],"batl":[[0,2.16,230],[2,2.34,4.58]],"ltp":2.12,"tv":2141.44,"id":25173012}],"tv":101878.34}]}
{"op":"mcm","clk":"11811569334","pt":1723307771676,"mc":[{"id":"1.231664751","rc":[{"trd":[[1.87,1396.85],[1.88,7734.84]],"batb":[[0,1.87,897.34],[1,1.83,1067.55],[2,1.82,1.94]],"batl":[[0,1.88,153.11]],"ltp":1.87,"tv":99742.05,"id":19144236},{"trd":[[2.12,17.78],[2.16,198.31]],"batl":[[0,2.16,224.74]],"ltp":2.16,"tv":2152.06,"id":25173012}],"tv":101894.11}]}
{"op":"mcm","clk":"11811569489","pt":1723307772568,"mc":[{"id":"1.231664751","rc":[{"trd":[[1.87,1896.67]],"batb":[[0,1.87,647.53]],"ltp":1.87,"tv":100241.87,"id":19144236},{"batl":[[0,2.16,224.82]],"ltp":2.16,"tv":2152.06,"id":25173012}],"tv":102393.94}]}
{"op":"mcm","clk":"11811569638","pt":1723307773372,"mc":[{"id":"1.231664751","rc":[{"trd":[[1.88,8041.06],[1.89,973.18]],"batb":[[0,1.89,169.6],[1,1.87,653.44],[2,1.83,1067.55]],"batl":[[0,1.91,28.82],[1,1.95,10.52],[2,1.97,44.71]],"ltp":1.89,"tv":101488.52,"id":19144236},{"trd":[[2.14,37.69]],"batl":[[0,2.16,224.74],[1,2.24,4.49]],"ltp":2.14,"tv":2164.73,"id":25173012}],"tv":103653.25}]}
{"op":"mcm","clk":"11811569834","pt":1723307774449,"mc":[{"id":"1.231664751","rc":[{"trd":[[1.87,2055.06],[1.88,8041.26],[1.89,1312.38]],"batb":[[0,1.87,574.63],[1,1.85,52.59]],"batl":[[1,1.92,5.26],[2,1.95,10.52]],"ltp":1.87,"tv":101986.31,"id":19144236},{"trd":[[2.12,22.81],[2.16,247.37]],"batl":[[0,2.16,200.21]],"ltp":2.16,"tv":2218.83,"id":25173012}],"tv":104205.14}]}
{"op":"mcm","clk":"11811570050","pt":1723307775582,"mc":[{"id":"1.231664751","rc":[{"batb":[[0,1.87,606.29]],"ltp":1.87,"tv":101986.31,"id":19144236},{"batl":[[0,2.16,200.61]],"ltp":2.16,"tv":2218.83,"id":25173012}]}]}
{"op":"mcm","clk":"11811570254","pt":1723307776672,"mc":[{"id":"1.231664751","rc":[{"trd":[[1.91,842.17]],"batb":[[0,1.91,55351.53],[1,1.89,3.15],[2,1.88,1.05]],"batl":[[0,1.92,5.26],[1,1.95,861.56],[2,1.97,44.71]],"ltp":1.91,"tv":102046.71,"id":19144236},{"trd":[[2.1,106.23],[2.12,26.41]],"batb":[[0,2,80],[1,1.92,111],[2,1.9,84.14]],"batl":[[0,2.12,3.84],[1,2.14,1.14],[2,2.16,200.21]],"ltp":2.1,"tv":2227.69,"id":25173012}],"tv":104274.4}]}
{"op":"mcm","clk":"11811570425","pt":1723307777547,"mc":[{"id":"1.231664751","rc":[{"trd":[[1.91,965.8]],"batb":[[0,1.91,53629.35]],"batl":[[1,1.95,6030.9]],"ltp":1.91,"tv":102170.34,"id":19144236},{"trd":[[2.1,196.39]],"batl":[[0,2.12,3.95],[1,2.14,12.56]],"ltp":2.1,"tv":2317.85,"id":25173012}],"tv":104488.19}]}
{"op":"mcm","clk":"11811570630","pt":1723307778515,"mc":[{"id":"1.231664751","rc":[{"trd":[[1.91,1067.46]],"batb":[[0,1.91,53578.52]],"batl":[[1,1.97,44.71],[2,2,31.9]],"ltp":1.91,"tv":102271.99,"id":19144236},{"batl":[[1,2.14,24.39]],"ltp":2.1,"tv":2317.85,"id":25173012}],"tv":104589.84}]}
{"op":"mcm","clk":"11811570842","pt":1723307779583,"mc":[{"id":"1.231664751","rc":[{"trd":[[1.91,1198]],"batb":[[0,1.91,53511.76],[1,1.89,12.15],[2,1.88,30.62]],"ltp":1.91,"tv":102402.53,"id":19144236},{"trd":[[2.1,199.1]],"batl":[[0,2.12,62.71],[1,2.14,25.67]],"ltp":2.1,"tv":2320.56,"id":25173012}],"tv":104723.09}]}
{"op":"mcm","clk":"11811570983","pt":1723307780383,"mc":[{"id":"1.231664751","rc":[{"trd":[[1.91,1198.21]],"batb":[[0,1.91,53511.55]],"ltp":1.91,"tv":102402.74,"id":19144236},{"trd":[[2.1,199.29]],"ltp":2.1,"tv":2320.75,"id":25173012}],"tv":104723.49}]}
{"op":"mcm","clk":"11811571231","pt":1723307781580,"mc":[{"id":"1.231664751","rc":[{"trd":[[1.91,1230.21]],"batb":[[0,1.91,53079.56],[2,1.88,29.57]],"ltp":1.91,"tv":102434.74,"id":19144236},{"batl":[[0,2.12,63.24],[1,2.14,24.62]],"ltp":2.1,"tv":2320.75,"id":25173012}],"tv":104755.5}]}
{"op":"mcm","clk":"11811571421","pt":1723307782599,"mc":[{"id":"1.231664751","rc":[{"trd":[[1.91,1903.32]],"batb":[[0,1.91,52743.01],[2,1.88,30.88]],"ltp":1.91,"tv":103107.85,"id":19144236},{"batl":[[0,2.12,64.1],[2,2.24,4.49]],"ltp":2.1,"tv":2320.75,"id":25173012}],"tv":105428.6}]}
{"op":"mcm","clk":"11811571604","pt":1723307783514,"mc":[{"id":"1.231664751","rc":[{"trd":[[1.91,1916.46]],"batb":[[0,1.91,52736.44]],"ltp":1.91,"tv":103120.99,"id":19144236},{"batb":[[1,1.9,84.14],[2,1.73,111.09]],"batl":[[1,2.14,23.42]],"ltp":2.1,"tv":2320.75,"id":25173012}],"tv":105441.74}]}
{"op":"mcm","clk":"11811571813","pt":1723307784596,"mc":[{"id":"1.231664751","rc":[{"trd":[[1.91,1920.22]],"batb":[[0,1.91,52770.69],[2,1.88,32.9]],"ltp":1.91,"tv":103124.75,"id":19144236},{"batl":[[0,2.12,64.2],[1,2.14,24.28]],"ltp":2.1,"tv":2320.75,"id":25173012}],"tv":105445.51}]}
{"op":"mcm","clk":"11811572042","pt":1723307785612,"mc":[{"id":"1.231664751","rc":[{"trd":[[1.91,5926.54]],"batb":[[0,1.91,50777.19],[2,1.88,19.1]],"ltp":1.91,"tv":107131.07,"id":19144236},{"batb":[[2,1.72,17.22]],"batl":[[0,2.1,6.67],[1,2.12,64.2],[2,2.14,13.76]],"ltp":2.1,"tv":2320.75,"id":25173012}],"tv":109451.83}]}
{"op":"mcm","clk":"11811572249","pt":1723307786575,"mc":[{"id":"1.231664751","rc":[{"trd":[[1.92,2.6]],"batb":[[0,1.92,552.14],[1,1.91,50779.71],[2,1.89,12.15]],"batl":[[0,1.97,44.71],[1,2,31.9],[2,2.04,3.15]],"ltp":1.92,"tv":107133.67,"id":19144236},{"batl":[[0,2.1,6.68],[1,2.12,62.93],[2,2.14,1.94]],"ltp":2.1,"tv":2320.75,"id":25173012}],"tv":109454.43}]}
{"op":"mcm","clk":"11811572501","pt":1723307787607,"mc":[{"id":"1.231664751","rc":[{"trd":[[1.92,438.73]],"batb":[[0,1.92,1998.27],[2,1.89,3.15]],"ltp":1.92,"tv":107569.81,"id":19144236},{"batl":[[0,2.08,200.21],[1,2.1,6.76],[2,2.12,62.93]],"ltp":2.1,"tv":2320.75,"id":25173012}],"tv":109890.56}]}
{"op":"mcm","clk":"11811572699","pt":1723307788684,"mc":[{"id":"1.231664751","rc":[{"trd":[[1.92,578.01],[1.97,20.14]],"batb":[[0,1.92,1935.47]],"batl":[[0,1.97,34.64]],"ltp":1.97,"tv":107729.23,"id":19144236},{"batb":[[1,1.9,1084.14]],"batl":[[0,2.08,204.52],[1,2.1,25.83],[2,2.12,62.07]],"ltp":2.1,"tv":2320.75,"id":25173012}],"tv":110049.98}]}
{"op":"mcm","clk":"11811572872","pt":1723307789586,"mc":[{"id":"1.231664751","rc":[{"trd":[[1.92,606.09]],"batb":[[0,1.92,1924.23]],"ltp":1.92,"tv":107757.3,"id":19144236},{"batl":[[0,2.08,209.3]],"ltp":2.1,"tv":2320.75,"id":25173012}],"tv":110078.06}]}
{"op":"mcm","clk":"11811573036","pt":1723307790402,"mc":[{"id":"1.231664751","rc":[{"trd":[[1.92,612.36]],"batb":[[0,1.92,1921.14]],"ltp":1.92,"tv":107763.57,"id":19144236},{"batb":[[0,2,472.76]],"batl":[[0,2.08,219.17],[1,2.1,26.96]],"ltp":2.1,"tv":2320.75,"id":25173012}],"tv":110084.33}]}
{"op":"mcm","clk":"11811573288","pt":1723307791591,"mc":[{"id":"1.231664751","rc":[{"trd":[[1.92,663.54]],"batb":[[0,1.92,1895.54],[1,1.91,50783.36],[2,1.89,2003.15]],"ltp":1.92,"tv":107814.76,"id":19144236},{"batl":[[0,2.08,219.85]],"ltp":2.1,"tv":2320.75,"id":25173012}],"tv":110135.51}]}
{"op":"mcm","clk":"11811573489","pt":1723307792608,"mc":[{"id":"1.231664751","rc":[{"trd":[[1.92,1074.8]],"batb":[[0,1.92,1726.04]],"ltp":1.92,"tv":108226.02,"id":19144236},{"batl":[[0,2.08,220.37],[1,2.1,27.83],[2,2.12,61.54]],"ltp":2.1,"tv":2320.75,"id":25173012}],"tv":110546.77}]}
{"op":"mcm","clk":"11811573673","pt":1723307793509,"mc":[{"id":"1.231664751","rc":[{"trd":[[1.92,1107.88]],"batb":[[0,1.92,1710.55]],"ltp":1.92,"tv":108259.1,"id":19144236},{"batl":[[0,2.08,218.22],[1,2.1,24.93]],"ltp":2.1,"tv":2320.75,"id":25173012}],"tv":110579.85}]}
{"op":"mcm","clk":"11811573895","pt":1723307794596,"mc":[{"id":"1.231664751","rc":[{"trd":[[1.92,1231.26]],"batb":[[0,1.92,1648.86]],"batl":[[0,1.97,44.49]],"ltp":1.92,"tv":108382.47,"id":19144236},{"trd":[[2.08,0.36]],"batl":[[0,2.08,218.04],[1,2.1,6.24]],"ltp":2.08,"tv":2321.11,"id":25173012}],"tv":110703.59}]}
{"op":"mcm","clk":"11811574107","pt":1723307795522,"mc":[{"id":"1.231664751","rc":[{"trd":[[1.92,1243.33],[1.97,23.78]],"batb":[[0,1.92,1669.63]],"batl":[[0,1.97,40.86]],"ltp":1.97,"tv":108398.19,"id":19144236},{"trd":[[2.02,3.55]],"batl":[[0,2.08,247.71]],"ltp":2.02,"tv":2324.66,"id":25173012}],"tv":110722.85}]}
{"op":"mcm","clk":"11811574336","pt":1723307796594,"mc":[{"id":"1.231664751","rc":[{"trd":[[1.91,5926.74],[1.92,4851.47],[1.94,3.02],[1.97,23.92]],"batb":[[0,1.91,50092.67],[1,1.89,2003.15],[2,1.88,2.01]],"batl":[[0,1.92,13.2],[1,1.97,40.71],[2,2,31.9]],"ltp":1.91,"tv":112009.69,"id":19144236},{"trd":[[2.02,3.69],[2.08,248.54]],"batl":[[0,2.1,6.16],[1,2.12,61.54],[2,2.14,7.11]],"ltp":2.08,"tv":2572.97,"id":25173012}],"tv":114582.67}]}
{"op":"mcm","clk":"11811574540","pt":1723307797614,"mc":[{"id":"1.231664751","rc":[{"trd":[[1.91,5937.98],[1.92,4861.3]],"batb":[[0,1.91,50082.36],[1,1.89,3.15]],"batl":[[0,1.92,4.78]],"ltp":1.91,"tv":112030.76,"id":19144236},{"trd":[[2.08,257.42],[2.1,214.52]],"batl":[[0,2.12,61.54],[1,2.14,1.2],[2,2.24,4.38]],"ltp":2.1,"tv":2597.09,"id":25173012}],"tv":114627.86}]}
{"op":"mcm","clk":"11811574742","pt":1723307798589,"mc":[{"id":"1.231664751","rc":[{"trd":[[1.91,5938.08],[1.92,4867.52],[1.97,64.64]],"batb":[[0,1.91,50082.26]],"batl":[[0,2,31.9],[1,2.04,3.15],[2,2.06,2000.11]],"ltp":1.97,"tv":112077.79,"id":19144236},{"trd":[[2,918.24],[2.02,43.39],[2.08,261.58],[2.1,214.61]],"batb":[[0,2,31.6]],"batl":[[0,2.12,61.62]],"ltp":2.0,"tv":3523.36,"id":25173012}],"tv":115601.16}]}
{"op":"mcm","clk":"11811574912","pt":1723307799485,"mc":[{"id":"1.231664751","rc":[{"trd":[[1.91,5948.6],[1.92,4869.05],[1.97,65.08]],"batb":[[0,1.97,13.06],[1,1.91,50077],[2,1.89,3.15]],"ltp":1.92,"tv":112090.29,"id":19144236},{"trd":[[2,937.98],[2.08,261.65]],"batb":[[0,2,21.73]],"batl":[[0,2.12,8.93]],"ltp":2.08,"tv":3543.18,"id":25173012}],"tv":115633.47}]}
{"op":"mcm","clk":"11811575098","pt":1723307800504,"mc":[{"id":"1.231664751","rc":[{"trd":[[1.97,71.13],[1.98,3.65]],"batb":[[0,1.97,20.42],[1,1.92,2.52],[2,1.91,50077]],"batl":[[0,2.04,3.3],[1,2.06,2000.11],[2,2.1,27.52]],"ltp":1.97,"tv":112099.99,"id":19144236},{"trd":[[2.02,46.97]],"batb":[[2,1.76,6.62]],"ltp":2.02,"tv":3546.76,"id":25173012}],"tv":115646.75}]}
{"op":"mcm","clk":"11811575327","pt":1723307801596,"mc":[{"id":"1.231664751","rc":[{"trd":[[1.97,80.68],[1.98,3.73]],"batb":[[0,1.97,14.61]],"ltp":1.97,"tv":112109.62,"id":19144236},{"trd":[[2,951.74],[2.02,53.57],[2.04,2]],"batb":[[0,2,14.85]],"ltp":2.02,"tv":3569.11,"id":25173012}],"tv":115678.73}]}
{"op":"mcm","clk":"11811575546","pt":1723307802675,"mc":[{"id":"1.231664751","rc":[{"trd":[[1.97,103.96]],"batb":[[0,1.97,10.42]],"ltp":1.97,"tv":112132.9,"id":19144236},{"trd":[[2.04,4.63]],"batb":[[2,1.76,6.85]],"batl":[[1,2.14,1.13]],"ltp":2.04,"tv":3571.74,"id":25173012}],"tv":115704.65}]}
{"op":"mcm","clk":"11811575709","pt":1723307803400,"mc":[{"id":"1.231664751","rc":[{"trd":[[1.97,117.61],[1.98,11.72]],"batb":[[0,1.97,3.6]],"ltp":1.98,"tv":112154.54,"id":19144236},{"trd":[[2.02,61.4]],"batl":[[0,2.02,22.61],[1,2.12,8.93],[2,2.24,4.61]],"ltp":2.02,"tv":3579.58,"id":25173012}],"tv":115734.12}]}
{"op":"mcm","clk":"11811575959","pt":1723307804601,"mc":[{"id":"1.231664751","rc":[{"trd":[[1.98,18.17]],"batb":[[0,1.97,69.35]],"ltp":1.98,"tv":112160.99,"id":19144236},{"trd":[[2.02,68.62]],"batl":[[0,2.02,34.53],[1,2.12,7.74],[2,2.24,4.5]],"ltp":2.02,"tv":3586.8,"id":25173012}],"tv":115747.79}]}
{"op":"mcm","clk":"11811576088","pt":1723307805138,"mc":[{"id":"1.231664751","rc":[{"trd":[[1.97,142.57],[1.98,53.77]],"batb":[[0,1.97,59.12]],"ltp":1.98,"tv":112221.54,"id":19144236},{"trd":[[2.02,103.51]],"batl":[[0,2.02,13.31]],"ltp":2.02,"tv":3621.69,"id":25173012}],"tv":115843.23}]}
{"op":"mcm","clk":"11811576385","pt":1723307806625,"mc":[{"id":"1.231664751","rc":[{"trd":[[1.97,219.64],[1.98,67.35]],"batb":[[0,1.97,23.9]],"ltp":1.97,"tv":112312.2,"id":19144236},{"trd":[[2.02,116.82]],"batl":[[0,2.02,1.1]],"ltp":2.02,"tv":3634.99,"id":25173012}],"tv":115947.2}]}
{"op":"mcm","clk":"11811576606","pt":1723307807625,"mc":[{"id":"1.231664751","rc":[{"trd":[[1.98,67.6]],"batl":[[1,2.1,27.63],[2,2.3,64.7]],"ltp":1.98,"tv":112312.46,"id":19144236},{"trd":[[2.02,117.07]],"batb":[[1,1.9,1084.2]],"batl":[[0,2.02,3.86],[1,2.08,2.52],[2,2.12,7.74]],"ltp":2.02,"tv":3635.25,"id":25173012}],"tv":115947.71}]}
{"op":"mcm","clk":"11811576779","pt":1723307808641,"mc":[{"id":"1.231664751","rc":[{"trd":[[1.97,231.16],[1.98,71.55]],"batb":[[0,1.97,10.52],[1,1.94,1536.89],[2,1.92,2.52]],"ltp":1.97,"tv":112327.92,"id":19144236},{"trd":[[2,967.2],[2.02,121.99]],"batb":[[0,2,7.12],[1,1.9,84.2]],"batl":[[0,2.08,13.9],[1,2.12,7.74],[2,2.24,5.41]],"ltp":2.0,"tv":3655.63,"id":25173012}],"tv":115983.55}]}
{"op":"mcm","clk":"11811577008","pt":1723307809624,"mc":[{"id":"1.231664751","rc":[{"trd":[[1.94,22.02],[1.97,244.07]],"batb":[[0,1.94,1527.39],[1,1.92,2.52],[2,1.91,50077]],"batl":[[0,1.97,25.68],[1,2.04,3.31],[2,2.1,27.63]],"ltp":1.94,"tv":112359.83,"id":19144236},{"batb":[[1,1.96,111],[2,1.9,84.2]],"batl":[[0,2.08,11.48],[2,2.24,5.31]],"ltp":2.0,"tv":3655.63,"id":25173012}],"tv":116015.46}]}
{"op":"mcm","clk":"11811577198","pt":1723307810621,"mc":[{"id":"1.231664751","rc":[{"trd":[[1.97,271.37],[1.98,71.56],[2,2.07],[2.04,3.15],[2.06,1.01]],"batb":[[1,1.93,182.13],[2,1.92,2.55]],"batl":[[0,2.1,27.52],[1,2.3,64.7],[2,2.42,4.01]],"ltp":2.06,"tv":112391.45,"id":19144236},{"trd":[[1.94,1.07],[1.96,3.28],[2,981.59],[2.02,148.62]],"batb":[[0,1.9,84.14],[1,1.76,6.85],[2,1.72,17.13]],"batl":[[0,1.94,4.91],[1,2,18.69],[2,2.08,122.48]],"ltp":1.94,"tv":3701.0,"id":25173012}],"tv":116092.45}]}
{"op":"mcm","clk":"11811577401","pt":1723307811609,"mc":[{"id":"1.231664751","rc":[{"trd":[[1.94,3076.8],[2,26.67],[2.06,5.63]],"batb":[[0,1.92,2.55],[1,1.91,50077],[2,1.89,3.15]],"batl":[[0,1.93,882.77],[1,2.1,27.52],[2,2.3,64.7]],"ltp":1.94,"tv":115475.45,"id":19144236},{"trd":[[1.94,5.98],[2,1006.19]],"batl":[[0,2.08,10.62],[1,2.12,7.74],[2,2.24,5.31]],"ltp":2.0,"tv":3730.51,"id":25173012}],"tv":119205.96}]}
{"op":"mcm","clk":"11811577613","pt":1723307812620,"mc":[{"id":"1.231664751","rc":[{"trd":[[1.92,5080.63],[1.93,0.02]],"batb":[[0,1.92,13.48]],"batl":[[0,1.93,882.75],[1,1.97,5.14],[2,1.98,52.76]],"ltp":1.92,"tv":115687.05,"id":19144236},{"trd":[[2.06,0.02],[2.08,272.27]],"batl":[[0,2.12,5],[1,2.24,5.31],[2,2.34,3.26]],"ltp":2.08,"tv":3741.15,"id":25173012}],"tv":119428.2}]}
{"op":"mcm","clk":"11811577793","pt":1723307813623,"mc":[{"id":"1.231664751","rc":[{"trd":[[1.92,5083.59],[1.93,1.47]],"batb":[[0,1.92,21.85]],"batl":[[0,1.93,881.3],[2,1.98,76.93]],"ltp":1.92,"tv":115691.46,"id":19144236},{"trd":[[2.06,1.38]],"batl":[[0,2.12,5.05]],"ltp":2.06,"tv":3742.51,"id":25173012}],"tv":119433.97}]}
{"op":"mcm","clk":"11811578002","pt":1723307814632,"mc":[{"id":"1.231664751","rc":[{"batl":[[1,1.97,25.01],[2,1.98,81.79]],"ltp":1.92,"tv":115691.46,"id":19144236},{"batb":[[0,2.02,2.63],[1,1.9,84.67],[2,1.76,6.85]],"ltp":2.06,"tv":3742.51,"id":25173012}]}]}
{"op":"mcm","clk":"11811578166","pt":1723307815442,"mc":[{"id":"1.231664751","rc":[{"trd":[[1.93,26.97]],"batl":[[0,1.93,864.94],[2,1.98,100.32]],"ltp":1.93,"tv":115716.95,"id":19144236},{"trd":[[2.06,8.15]],"batl":[[0,2.12,5.35]],"ltp":2.06,"tv":3749.28,"id":25173012}],"tv":119466.24}]}
{"op":"mcm","clk":"11811578380","pt":1723307816520,"mc":[{"id":"1.231664751","rc":[{"trd":[[1.92,5088.85],[1.93,27.13]],"batb":[[0,1.92,19.22]],"batl":[[0,1.93,864.78],[1,1.97,51.41],[2,1.98,103.05]],"ltp":1.93,"tv":115722.37,"id":19144236},{"trd":[[2.06,8.3]],"ltp":2.06,"tv":3749.43,"id":25173012}],"tv":119471.81}]}
{"op":"mcm","clk":"11811578598","pt":1723307817649,"mc":[{"id":"1.231664751","rc":[{"trd":[[1.93,30.21]],"batb":[[1,1.91,50076.84]],"batl":[[0,1.93,861.7],[1,1.97,51.29]],"ltp":1.93,"tv":115725.45,"id":19144236},{"trd":[[2.06,11.19]],"batb":[[1,1.96,391.55],[2,1.9,84.67]],"ltp":2.06,"tv":3752.32,"id":25173012}],"tv":119477.78}]}
{"op":"mcm","clk":"11811578785","pt":1723307818658,"mc":[{"id":"1.231664751","rc":[{"trd":[[1.92,5126.21],[1.93,252.82]],"batb":[[0,1.91,50077.38],[1,1.89,3.15],[2,1.87,12.42]],"batl":[[0,1.93,750.09],[1,1.97,105.2]],"ltp":1.93,"tv":115985.42,"id":19144236},{"trd":[[2.06,11.76]],"batb":[[0,1.91,1000],[1,1.9,84.67],[2,1.76,6.85]],"ltp":2.06,"tv":3752.89,"id":25173012}],"tv":119738.32}]}
{"op":"mcm","clk":"11811578968","pt":1723307819647,"mc":[{"id":"1.231664751","rc":[{"trd":[[1.92,5127.87]],"batb":[[0,1.91,50076.84]],"batl":[[0,1.92,1998.88],[1,1.93,750.09],[2,1.97,107.83]],"ltp":1.92,"tv":115987.08,"id":19144236},{"trd":[[2.08,272.81]],"batb":[[0,1.93,5169.34],[1,1.92,111],[2,1.91,1000]],"batl":[[0,2.12,5]],"ltp":2.08,"tv":3753.43,"id":25173012}],"tv":119740.51}]}
{"op":"mcm","clk":"11811579135","pt":1723307820397,"mc":[{"id":"1.231664751","rc":[{"batl":[[0,1.93,750.09],[1,1.94,52.59],[2,1.97,116.73]],"ltp":1.92,"tv":115987.08,"id":19144236},{"batb":[[0,2.02,1.8],[1,1.93,5169.34],[2,1.92,111]],"ltp":2.08,"tv":3753.43,"id":25173012}]}]}
{"op":"mcm","clk":"11811579444","pt":1723307821629,"mc":[{"id":"1.231664751","rc":[{"trd":[[1.92,5128.59],[1.93,257.57]],"batb":[[0,1.91,49996.95]],"batl":[[0,1.93,747.59],[2,1.97,112.01]],"ltp":1.93,"tv":115992.55,"id":19144236},{"trd":[[2.06,11.99],[2.08,272.91]],"batb":[[0,2.02,2.08],[2,1.91,1000]],"ltp":2.06,"tv":3753.76,"id":25173012}],"tv":119746.31}]}
{"op":"mcm","clk":"11811579605","pt":1723307822448,"mc":[{"id":"1.231664751","rc":[{"trd":[[1.93,425.36]],"batl":[[0,1.94,52.73],[1,1.97,95.7],[2,1.98,118.18]],"ltp":1.93,"tv":116160.34,"id":19144236},{"trd":[[2.06,21.36]],"batb":[[1,1.93,5169.44]],"ltp":2.06,"tv":3763.13,"id":25173012}],"tv":119923.47}]}
{"op":"mcm","clk":"11811579819","pt":1723307823551,"mc":[{"id":"1.231664751","rc":[{"trd":[[1.92,5128.87],[1.94,3076.99]],"batb":[[0,1.93,415.18],[1,1.91,49996.95],[2,1.89,3.15]],"batl":[[0,1.94,97.48],[1,1.97,93.07],[2,1.98,75.97]],"ltp":1.94,"tv":116160.81,"id":19144236},{"trd":[[2.06,21.53]],"ltp":2.06,"tv":3763.3,"id":25173012}],"tv":119924.12}]}
{"op":"mcm","clk":"11811580063","pt":1723307824672,"mc":[{"id":"1.231664751","rc":[{"trd":[[1.93,427.82],[1.94,3088.72]],"batb":[[0,1.93,414.6]],"batl":[[0,1.94,85.75]],"ltp":1.94,"tv":116175.0,"id":19144236},{"trd":[[2.06,32.57]],"batl":[[0,2.12,5.02],[1,2.24,5.28]],"ltp":2.06,"tv":3774.34,"id":25173012}],"tv":119949.35}]}
{"op":"mcm","clk":"11811580241","pt":1723307825490,"mc":[{"id":"1.231664751","rc":[{"trd":[[1.93,428.22],[1.94,3090.65]],"batb":[[0,1.93,421.71]],"batl":[[0,1.94,83.82],[2,1.98,53.5]],"ltp":1.94,"tv":116177.33,"id":19144236},{"trd":[[2.06,34.39],[2.08,272.94]],"batl":[[0,2.12,5],[1,2.24,5.25]],"ltp":2.06,"tv":3776.2,"id":25173012}],"tv":119953.53}]}
{"op":"mcm","clk":"11811580478","pt":1723307826654,"mc":[{"id":"1.231664751","rc":[{"trd":[[1.93,438.83],[1.94,3090.66]],"batb":[[0,1.93,415.92]],"batl":[[0,1.94,83.81],[2,1.98,53.48]],"ltp":1.93,"tv":116187.95,"id":19144236},{"trd":[[2.06,34.4],[2.08,273.84]],"batl":[[1,2.24,4.19]],"ltp":2.08,"tv":3777.11,"id":25173012}],"tv":119965.06}]}
{"op":"mcm","clk":"11811580681","pt":1723307827684,"mc":[{"id":"1.231664751","rc":[{"trd":[[1.94,3093.33]],"batb":[[0,1.93,444.65]],"batl":[[0,1.94,81.14],[1,1.97,83.17],[2,1.98,53.68]],"ltp":1.94,"tv":116190.62,"id":19144236},{"trd":[[2.06,36.92]],"batb":[[1,2,111],[2,1.93,5169.44]],"ltp":2.06,"tv":3779.63,"id":25173012}],"tv":119970.25}]}
{"op":"mcm","clk":"11811580814","pt":1723307828370,"mc":[{"id":"1.231664751","rc":[{"trd":[[1.93,440.35],[1.94,3095.04]],"batb":[[0,1.93,4976.47],[1,1.92,205.63],[2,1.91,49996.95]],"batl":[[0,1.94,74.17]],"ltp":1.94,"tv":116193.85,"id":19144236},{"trd":[[2.06,38.53]],"batb":[[0,2,111.28],[1,1.95,111.1],[2,1.93,5169.34]],"ltp":2.06,"tv":3781.24,"id":25173012}],"tv":119975.09}]}
{"op":"mcm","clk":"11811581089","pt":1723307829679,"mc":[{"id":"1.231664751","rc":[{"trd":[[1.93,622.73],[1.94,3140.12],[1.97,354.54],[1.98,127.87]],"batb":[[0,1.93,4885.04],[1,1.92,206.68]],"batl":[[0,2,1.15],[1,2.06,45.09],[2,2.1,27.52]],"ltp":1.93,"tv":116560.79,"id":19144236},{"trd":[[2.02,285.5],[2.06,81.14],[2.08,274.29]],"batb":[[0,2,503.76]],"ltp":2.08,"tv":3961.17,"id":25173012}],"tv":120521.97}]}
{"op":"mcm","clk":"11811581291","pt":1723307830685,"mc":[{"id":"1.231664751","rc":[{"trd":[[1.93,823.09]],"batb":[[0,1.93,4791.85],[1,1.92,214.57]],"ltp":1.93,"tv":116761.15,"id":19144236},{"batl":[[0,2.12,5.52]],"ltp":2.08,"tv":3961.17,"id":25173012}],"tv":120722.33}]}
{"op":"mcm","clk":"11811581491","pt":1723307831586,"mc":[{"id":"1.231664751","rc":[{"trd":[[1.93,1026.27],[1.94,3140.66]],"batb":[[0,1.93,4688.83]],"ltp":1.93,"tv":116964.87,"id":19144236},{"trd":[[2.06,81.66],[2.08,276.95]],"batl":[[0,2.12,5],[1,2.24,5.1]],"ltp":2.08,"tv":3964.34,"id":25173012}],"tv":120929.22}]}
{"op":"mcm","clk":"11811581710","pt":1723307832658,"mc":[{"id":"1.231664751","rc":[{"trd":[[1.93,1115.1]],"batb":[[0,1.93,4644.71],[1,1.92,101.27]],"ltp":1.93,"tv":117053.7,"id":19144236},{"trd":[[2.06,85.3],[2.08,277.75]],"batb":[[1,1.93,5169.44],[2,1.91,1000]],"ltp":2.08,"tv":3968.79,"id":25173012}],"tv":121022.5}]}
{"op":"mcm","clk":"11811581920","pt":1723307833581,"mc":[{"id":"1.231664751","rc":[{"trd":[[1.93,1285.49],[1.94,3141.23]],"batb":[[0,1.93,4559.52]],"ltp":1.93,"tv":117224.65,"id":19144236},{"trd":[[2.06,85.83]],"ltp":2.06,"tv":3969.32,"id":25173012}],"tv":121193.97}]}
{"op":"mcm","clk":"11811582090","pt":1723307834572,"mc":[{"id":"1.231664751","rc":[{"trd":[[1.93,1308.76],[1.94,3141.33]],"batb":[[0,1.93,4548.43]],"ltp":1.93,"tv":117248.03,"id":19144236},{"trd":[[2.06,85.93]],"ltp":2.06,"tv":3969.42,"id":25173012}],"tv":121217.46}]}
{"op":"mcm","clk":"11811582268","pt":1723307835489,"mc":[{"id":"1.231664751","rc":[{"trd":[[1.93,1430.07]],"batb":[[0,1.93,4487.95],[2,1.91,49960.83]],"ltp":1.93,"tv":117369.34,"id":19144236},{"batl":[[0,2.06,2.62],[1,2.12,5],[2,2.24,5.1]],"ltp":2.06,"tv":3969.42,"id":25173012}],"tv":121338.77}]}
{"op":"mcm","clk":"11811582509","pt":1723307836672,"mc":[{"id":"1.231664751","rc":[{"trd":[[1.93,1456.37],[1.94,3153.05]],"batb":[[0,1.94,26.8],[1,1.93,4461.22],[2,1.92,101.27]],"ltp":1.94,"tv":117407.36,"id":19144236},{"trd":[[2.06,93.13],[2.08,301.43]],"batl":[[0,2.06,1.82],[2,2.24,3.89]],"ltp":2.06,"tv":4000.29,"id":25173012}],"tv":121407.66}]}
{"op":"mcm","clk":"11811582686","pt":1723307837473,"mc":[{"id":"1.231664751","rc":[{"trd":[[1.93,1794.95],[1.94,3208.87]],"batb":[[0,1.93,4291.93],[1,1.92,93.38],[2,1.91,49960.83]],"ltp":1.94,"tv":117801.76,"id":19144236},{"trd":[[2.06,95.04]],"batl":[[0,2.06,2.82]],"ltp":2.06,"tv":4002.2,"id":25173012}],"tv":121803.97}]}
{"op":"mcm","clk":"11811582914","pt":1723307838583,"mc":[{"id":"1.231664751","rc":[{"trd":[[1.93,1839.58],[1.94,3211.87]],"batb":[[0,1.93,4269.33]],"batl":[[0,1.98,111],[1,2,1.15],[2,2.06,45.09]],"ltp":1.93,"tv":117849.39,"id":19144236},{"trd":[[2.06,97.86],[2.08,301.96]],"batl":[[0,2.12,5],[1,2.24,3.89],[2,2.34,3.26]],"ltp":2.08,"tv":4005.56,"id":25173012}],"tv":121854.95}]}
{"op":"mcm","clk":"11811583121","pt":1723307839664,"mc":[{"id":"1.231664751","rc":[{"trd":[[1.93,1874.68],[1.94,3211.97],[1.98,127.89]],"batb":[[0,1.93,4251.78]],"batl":[[0,1.98,194.04]],"ltp":1.93,"tv":117884.61,"id":19144236},{"trd":[[2.02,285.52],[2.06,98.16],[2.08,303.12]],"batl":[[0,2.08,3.07],[1,2.12,5],[2,2.24,3.89]],"ltp":2.08,"tv":4007.03,"id":25173012}],"tv":121891.65}]}
{"op":"mcm","clk":"11811583250","pt":1723307840293,"mc":[{"id":"1.231664751","rc":[{"trd":[[1.93,1895.92]],"batb":[[0,1.93,4241.16]],"batl":[[0,1.97,42.21],[1,1.98,194.04],[2,2,1.15]],"ltp":1.93,"tv":117905.85,"id":19144236},{"trd":[[2.08,303.29]],"batb":[[0,2.02,533.33],[1,2,503.76],[2,1.93,5169.44]],"batl":[[0,2.08,2.98]],"ltp":2.08,"tv":4007.2,"id":25173012}],"tv":121913.06}]}
{"op":"mcm","clk":"11811583523","pt":1723307841665,"mc":[{"id":"1.231664751","rc":[{"trd":[[1.93,5031.6],[1.94,3212.5],[1.96,18.99],[1.97,374.68]],"batb":[[0,1.93,1100.43]],"batl":[[0,1.96,104.09],[1,1.97,32.14],[2,1.98,194.04]],"ltp":1.96,"tv":121081.2,"id":19144236},{"trd":[[2.04,22.87],[2.06,98.62],[2.08,3218.9]],"batl":[[0,2.06,1.05]],"ltp":2.04,"tv":6941.51,"id":25173012}],"tv":128022.72}]}
{"op":"mcm","clk":"11811583734","pt":1723307842577,"mc":[{"id":"1.231664751","rc":[{"trd":[[1.93,5094.7],[1.94,3220.89],[1.96,20.45]],"batb":[[0,1.93,1068.88]],"batl":[[0,1.94,2.63],[1,1.96,103.36],[2,1.97,32.14]],"ltp":1.93,"tv":121154.14,"id":19144236},{"trd":[[2.06,99.67],[2.08,3220.7]],"batb":[[1,2,504.04]],"batl":[[0,2.12,5],[1,2.24,3.89],[2,2.34,3.26]],"ltp":2.08,"tv":6944.36,"id":25173012}],"tv":128098.51}]}
{"op":"mcm","clk":"11811583905","pt":1723307843377,"mc":[{"id":"1.231664751","rc":[{"trd":[[1.93,5098.1],[1.94,3220.93]],"batb":[[0,1.93,1067.18],[2,1.91,49958.31]],"batl":[[0,1.94,2.61]],"ltp":1.94,"tv":121157.58,"id":19144236},{"batb":[[1,2,393.04]],"ltp":2.08,"tv":6944.36,"id":25173012}],"tv":128101.95}]}
{"op":"mcm","clk":"11811584181","pt":1723307844656,"mc":[{"id":"1.231664751","rc":[{"trd":[[1.93,5249.86],[1.94,3231.8],[1.96,28.72]],"batb":[[0,1.94,2.39],[1,1.93,986.04],[2,1.92,93.38]],"batl":[[0,1.96,95.09],[1,1.97,32.14],[2,1.98,213.88]],"ltp":1.96,"tv":121328.48,"id":19144236},{"trd":[[2.04,30.82],[2.06,109.91]],"ltp":2.04,"tv":6962.55,"id":25173012}],"tv":128291.03}]}
{"op":"mcm","clk":"11811584355","pt":1723307845555,"mc":[{"id":"1.231664751","rc":[{"trd":[[1.93,5254.8],[1.96,103]],"batb":[[0,1.93,983.57],[1,1.92,92.33],[2,1.91,49958.31]],"batl":[[0,1.96,57.95]],"ltp":1.96,"tv":121407.69,"id":19144236}],"tv":128370.25}]}
{"op":"mcm","clk":"11811584528","pt":1723307846382,"mc":[{"id":"1.231664751","rc":[{"trd":[[1.93,5278.44],[1.96,103.95]],"batb":[[0,1.93,971.75]],"batl":[[0,1.96,57]],"ltp":1.96,"tv":121432.29,"id":19144236},{"trd":[[2.04,31.73]],"ltp":2.04,"tv":6963.46,"id":25173012}],"tv":128395.75}]}
{"op":"mcm","clk":"11811584774","pt":1723307847598,"mc":[{"id":"1.231664751","rc":[{"trd":[[1.94,3235.85],[1.96,113.37]],"batl":[[0,1.94,26.38],[1,1.96,50.93],[2,1.97,32.14]],"ltp":1.96,"tv":121445.76,"id":19144236},{"trd":[[2.04,34.34],[2.06,112.59]],"batb":[[0,2.06,1.58],[1,2.02,533.33],[2,2,393.04]],"ltp":2.04,"tv":6968.75,"id":25173012}],"tv":128414.52}]}
{"op":"mcm","clk":"11811584965","pt":1723307848603,"mc":[{"id":"1.231664751","rc":[{"trd":[[1.93,5296.24],[1.94,3235.89],[1.95,52.46]],"batb":[[0,1.93,962.85]],"batl":[[0,1.95,21.45]],"ltp":1.95,"tv":121516.06,"id":19144236},{"batb":[[0,2.06,3.29]],"ltp":2.04,"tv":6968.75,"id":25173012}],"tv":128484.82}]}
{"op":"mcm","clk":"11811585202","pt":1723307849681,"mc":[{"id":"1.231664751","rc":[{"trd":[[1.93,5307.03],[1.95,68.24]],"batb":[[0,1.93,957.44]],"batl":[[0,1.95,13.56],[1,1.96,52.73]],"ltp":1.95,"tv":121542.63,"id":19144236},{"trd":[[2.06,112.62],[2.08,3220.73]],"batb":[[0,2.06,3.27]],"ltp":2.08,"tv":6968.82,"id":25173012}],"tv":128511.45}]}
{"op":"mcm","clk":"11811585406","pt":1723307850684,"mc":[{"id":"1.231664751","rc":[{"trd":[[1.93,5311.23]],"batb":[[0,1.93,956.39],[1,1.91,49958.31],[2,1.89,3.15]],"batl":[[0,1.95,124.6]],"ltp":1.93,"tv":121546.83,"id":19144236},{"trd":[[2.06,112.95]],"batb":[[0,2.06,3.11]],"ltp":2.06,"tv":6969.14,"id":25173012}],"tv":128515.98}]}
{"op":"mcm","clk":"11811585576","pt":1723307851494,"mc":[{"id":"1.231664751","rc":[{"trd":[[1.93,5311.33],[1.94,3241.8],[1.95,68.53]],"batb":[[0,1.93,956.34]],"batl":[[0,1.95,123.17]],"ltp":1.93,"tv":121553.14,"id":19144236},{"trd":[[2.04,34.62],[2.06,119.17]],"batb":[[0,2.02,533.33],[1,2,393.04],[2,1.93,5169.44]],"ltp":2.04,"tv":6975.65,"id":25173012}],"tv":128528.79}]}
{"op":"mcm","clk":"11811585788","pt":1723307852556,"mc":[{"id":"1.231664751","rc":[{"trd":[[1.94,3242.4],[1.95,89.44]],"batb":[[0,1.94,8.7],[1,1.93,956.34],[2,1.91,49958.31]],"batl":[[0,1.95,112.67]],"ltp":1.94,"tv":121574.64,"id":19144236},{"trd":[[2.04,34.72]],"ltp":2.04,"tv":6975.75,"id":25173012}],"tv":128550.4}]}
{"op":"mcm","clk":"11811585987","pt":1723307853563,"mc":[{"id":"1.231664751","rc":[{"trd":[[1.93,5731.53],[1.94,3242.5]],"batb":[[0,1.93,746.24],[1,1.91,49958.31],[2,1.89,3.15]],"batl":[[0,1.94,13.01],[1,1.95,112.67],[2,1.96,52.73]],"ltp":1.94,"tv":121994.94,"id":19144236},{"batb":[[0,2,393.04],[1,1.93,5169.44],[2,1.91,2.63]],"ltp":2.04,"tv":6975.75,"id":25173012}],"tv":128970.69}]}
{"op":"mcm","clk":"11811586168","pt":1723307854520,"mc":[{"id":"1.231664751","rc":[{"trd":[[1.93,5742.94],[1.94,3242.7]],"batb":[[0,1.91,49958.31],[1,1.89,3.15],[2,1.87,12.32]],"batl":[[0,1.93,496.62],[1,1.94,13.21],[2,1.95,112.67]],"ltp":1.93,"tv":122006.55,"id":19144236},{"trd":[[2.06,119.93]],"ltp":2.06,"tv":6976.51,"id":25173012}],"tv":128983.06}]}
