{"op":"mcm","clk":"11795140934","pt":1723108867847,"mc":[{"id":"1.231582170","marketDefinition":{"bspMarket":false,"turnInPlayEnabled":true,"persistenceEnabled":true,"marketBaseRate":5.0,"eventId":"33477738","eventTypeId":"4","numberOfWinners":1,"bettingType":"ODDS","marketType":"MATCH_ODDS","marketTime":"2024-08-11T10:00:00.000Z","suspendTime":"2024-08-11T10:00:00.000Z","bspReconciled":false,"complete":true,"inPlay":false,"crossMatching":false,"runnersVoidable":false,"numberOfActiveRunners":2,"betDelay":0,"status":"OPEN","runners":[{"status":"ACTIVE","sortPriority":1,"id":475559,"name":"Northamptonshire"},{"status":"ACTIVE","sortPriority":2,"id":424679,"name":"Lancashire"}],"regulators":["MR_INT"],"countryCode":"GB","discountAllowed":false,"timezone":"GMT","openDate":"2024-08-11T10:00:00.000Z","version":6061697158,"name":"Match Odds","eventName":"Northamptonshire v Lancashire"},"rc":[{"batb":[[0,1.01,20]],"ltp":0.0,"tv":0.0,"id":424679},{"batb":[[0,1.01,20]],"ltp":0.0,"tv":0.0,"id":475559}]}]}
{"op":"mcm","clk":"11795141006","pt":1723108868925,"mc":[{"id":"1.231582170","marketDefinition":{"bspMarket":false,"turnInPlayEnabled":true,"persistenceEnabled":true,"marketBaseRate":5.0,"eventId":"33477738","eventTypeId":"4","numberOfWinners":1,"bettingType":"ODDS","marketType":"MATCH_ODDS","marketTime":"2024-08-11T10:00:00.000Z","suspendTime":"2024-08-11T10:00:00.000Z","bspReconciled":false,"complete":true,"inPlay":false,"crossMatching":false,"runnersVoidable":false,"numberOfActiveRunners":2,"betDelay":0,"status":"OPEN","runners":[{"status":"ACTIVE","sortPriority":1,"id":475559,"name":"Northamptonshire"},{"status":"ACTIVE","sortPriority":2,"id":424679,"name":"Lancashire"}],"regulators":["MR_INT"],"countryCode":"GB","discountAllowed":true,"timezone":"GMT","openDate":"2024-08-11T10:00:00.000Z","version":6061697158,"name":"Match Odds","eventName":"Northamptonshire v Lancashire"},"rc":[{"batb":[[0,1.03,200],[1,1.02,200],[2,1.01,220]],"ltp":0.0,"tv":0.0,"id":424679},{"batb":[[0,1.03,200],[1,1.02,200],[2,1.01,220]],"ltp":0.0,"tv":0.0,"id":475559}]}]}
{"op":"mcm","clk":"11795422886","pt":1723113713915,"mc":[{"id":"1.231582170","rc":[{"batb":[[2,1.01,227.89]],"ltp":0.0,"tv":0.0,"id":424679},{"batb":[[2,1.01,227.89]],"ltp":0.0,"tv":0.0,"id":475559}]}]}
{"op":"mcm","clk":"11795423880","pt":1723113729023,"mc":[{"id":"1.231582170","rc":[{"batb":[[1,1.02,207.89]],"ltp":0.0,"tv":0.0,"id":424679},{"batb":[[1,1.02,207.89]],"ltp":0.0,"tv":0.0,"id":475559}]}]}
{"op":"mcm","clk":"11795425688","pt":1723113760566,"mc":[{"id":"1.231582170","rc":[{"batb":[[1,1.02,247.34]],"ltp":0.0,"tv":0.0,"id":424679},{"batb":[[1,1.02,247.34]],"ltp":0.0,"tv":0.0,"id":475559}]}]}
{"op":"mcm","clk":"11795426459","pt":1723113775299,"mc":[{"id":"1.231582170","rc":[{"batb":[[0,1.03,207.89]],"ltp":0.0,"tv":0.0,"id":424679},{"batb":[[0,1.03,207.89]],"ltp":0.0,"tv":0.0,"id":475559}]}]}
{"op":"mcm","clk":"11795427102","pt":1723113787895,"mc":[{"id":"1.231582170","rc":[{"batb":[[0,1.04,7.89],[1,1.03,207.89],[2,1.02,247.34]],"ltp":0.0,"tv":0.0,"id":424679},{"batb":[[0,1.04,7.89],[1,1.03,207.89],[2,1.02,247.34]],"ltp":0.0,"tv":0.0,"id":475559}]}]}
{"op":"mcm","clk":"11795427798","pt":1723113800705,"mc":[{"id":"1.231582170","rc":[{"batb":[[0,1.05,7.89],[1,1.04,7.89],[2,1.03,207.89]],"ltp":0.0,"tv":0.0,"id":424679},{"batb":[[0,1.05,7.89],[1,1.04,7.89],[2,1.03,207.89]],"ltp":0.0,"tv":0.0,"id":475559}]}]}
{"op":"mcm","clk":"11795428675","pt":1723113817712,"mc":[{"id":"1.231582170","rc":[{"batb":[[0,1.06,7.89],[1,1.05,7.89],[2,1.04,7.89]],"ltp":0.0,"tv":0.0,"id":424679},{"batb":[[0,1.06,7.89],[1,1.05,7.89],[2,1.04,7.89]],"ltp":0.0,"tv":0.0,"id":475559}]}]}
{"op":"mcm","clk":"11795429478","pt":1723113832100,"mc":[{"id":"1.231582170","rc":[{"batb":[[0,1.07,7.89],[1,1.06,7.89],[2,1.05,7.89]],"ltp":0.0,"tv":0.0,"id":424679},{"batb":[[0,1.07,7.89],[1,1.06,7.89],[2,1.05,7.89]],"ltp":0.0,"tv":0.0,"id":475559}]}]}
{"op":"mcm","clk":"11795430553","pt":1723113852478,"mc":[{"id":"1.231582170","rc":[{"batb":[[0,1.08,7.89],[1,1.07,7.89],[2,1.06,7.89]],"ltp":0.0,"tv":0.0,"id":424679},{"batb":[[0,1.08,7.89],[1,1.07,7.89],[2,1.06,7.89]],"ltp":0.0,"tv":0.0,"id":475559}]}]}
{"op":"mcm","clk":"11795534491","pt":1723115784485,"mc":[{"id":"1.231582170","rc":[{"batb":[[0,1.08,7.88],[1,1.07,7.88],[2,1.06,7.88]],"ltp":0.0,"tv":0.0,"id":424679},{"batb":[[0,1.08,7.88],[1,1.07,7.88],[2,1.06,7.88]],"ltp":0.0,"tv":0.0,"id":475559}]}]}
{"op":"mcm","clk":"11795535251","pt":1723115799113,"mc":[{"id":"1.231582170","marketDefinition":{"bspMarket":false,"turnInPlayEnabled":true,"persistenceEnabled":true,"marketBaseRate":5.0,"eventId":"33477738","eventTypeId":"4","numberOfWinners":1,"bettingType":"ODDS","marketType":"MATCH_ODDS","marketTime":"2024-08-11T10:00:00.000Z","suspendTime":"2024-08-11T10:00:00.000Z","bspReconciled":false,"complete":true,"inPlay":false,"crossMatching":true,"runnersVoidable":false,"numberOfActiveRunners":2,"betDelay":0,"status":"OPEN","runners":[{"status":"ACTIVE","sortPriority":1,"id":475559,"name":"Northamptonshire"},{"status":"ACTIVE","sortPriority":2,"id":424679,"name":"Lancashire"}],"regulators":["MR_INT"],"countryCode":"GB","discountAllowed":true,"timezone":"GMT","openDate":"2024-08-11T10:00:00.000Z","version":6061697158,"name":"Match Odds","eventName":"Northamptonshire v Lancashire"}}]}
{"op":"mcm","clk":"11795880055","pt":1723122775110,"mc":[{"id":"1.231582170","rc":[{"batb":[[0,1.08,7.89],[1,1.07,7.89],[2,1.06,7.89]],"ltp":0.0,"tv":0.0,"id":424679},{"batb":[[0,1.08,7.89],[1,1.07,7.89],[2,1.06,7.89]],"ltp":0.0,"tv":0.0,"id":475559}]}]}
{"op":"mcm","clk":"11796164548","pt":1723128175145,"mc":[{"id":"1.231582170","rc":[{"batb":[[0,1.08,7.87],[1,1.07,7.87],[2,1.06,7.87]],"ltp":0.0,"tv":0.0,"id":424679},{"batb":[[0,1.08,7.87],[1,1.07,7.87],[2,1.06,7.87]],"ltp":0.0,"tv":0.0,"id":475559}]}]}
{"op":"mcm","clk":"11796260655","pt":1723129858815,"mc":[{"id":"1.231582170","rc":[{"batb":[[0,1.25,100],[1,1.08,7.86],[2,1.07,7.86]],"ltp":0.0,"tv":0.0,"id":424679},{"batb":[[0,1.25,100],[1,1.08,7.86],[2,1.07,7.86]],"ltp":0.0,"tv":0.0,"id":475559}]}]}
{"op":"mcm","clk":"11796564431","pt":1723133575169,"mc":[{"id":"1.231582170","rc":[{"batb":[[1,1.08,7.85],[2,1.07,7.85]],"ltp":0.0,"tv":0.0,"id":424679},{"batb":[[1,1.08,7.85],[2,1.07,7.85]],"ltp":0.0,"tv":0.0,"id":475559}]}]}
{"op":"mcm","clk":"11797117452","pt":1723139008324,"mc":[{"id":"1.231582170","rc":[{"batb":[[0,1.26,2.75],[1,1.25,100],[2,1.08,7.85]],"ltp":0.0,"tv":0.0,"id":475559}]}]}
{"op":"mcm","clk":"11797118716","pt":1723139019374,"mc":[{"id":"1.231582170","rc":[{"batb":[[0,1.26,3.71]],"ltp":0.0,"tv":0.0,"id":475559}]}]}
{"op":"mcm","clk":"11797121026","pt":1723139037395,"mc":[{"id":"1.231582170","rc":[{"batb":[[0,1.29,2.79],[1,1.25,100],[2,1.08,7.85]],"ltp":0.0,"tv":0.0,"id":424679}]}]}
{"op":"mcm","clk":"11797122450","pt":1723139048397,"mc":[{"id":"1.231582170","rc":[{"batb":[[0,1.29,3.75]],"ltp":0.0,"tv":0.0,"id":424679}]}]}
{"op":"mcm","clk":"11797871949","pt":1723144375187,"mc":[{"id":"1.231582170","rc":[{"batb":[[0,1.29,3.75],[2,1.08,7.84]],"ltp":0.0,"tv":0.0,"id":424679},{"batb":[[0,1.26,3.71],[2,1.08,7.84]],"ltp":0.0,"tv":0.0,"id":475559}]}]}
{"op":"mcm","clk":"11798425790","pt":1723149775141,"mc":[{"id":"1.231582170","rc":[{"batb":[[0,1.29,3.75],[2,1.08,7.85]],"ltp":0.0,"tv":0.0,"id":424679},{"batb":[[0,1.26,3.71],[2,1.08,7.85]],"ltp":0.0,"tv":0.0,"id":475559}]}]}
{"op":"mcm","clk":"11798509606","pt":1723151675169,"mc":[{"id":"1.231582170","rc":[{"batb":[[0,1.29,3.75],[2,1.08,7.84]],"ltp":0.0,"tv":0.0,"id":424679},{"batb":[[0,1.26,3.71],[2,1.08,7.84]],"ltp":0.0,"tv":0.0,"id":475559}]}]}
{"op":"mcm","clk":"11798874636","pt":1723160575186,"mc":[{"id":"1.231582170","rc":[{"batb":[[0,1.29,3.75],[2,1.08,7.85]],"ltp":0.0,"tv":0.0,"id":424679},{"batb":[[0,1.26,3.71],[2,1.08,7.85]],"ltp":0.0,"tv":0.0,"id":475559}]}]}
{"op":"mcm","clk":"11799075393","pt":1723165975226,"mc":[{"id":"1.231582170","rc":[{"batb":[[0,1.29,3.75],[2,1.08,7.85]],"ltp":0.0,"tv":0.0,"id":424679},{"batb":[[0,1.26,3.71],[2,1.08,7.85]],"ltp":0.0,"tv":0.0,"id":475559}]}]}
{"op":"mcm","clk":"11799290904","pt":1723171375207,"mc":[{"id":"1.231582170","rc":[{"batb":[[0,1.29,3.75],[2,1.08,7.84]],"ltp":0.0,"tv":0.0,"id":424679},{"batb":[[0,1.26,3.71],[2,1.08,7.84]],"ltp":0.0,"tv":0.0,"id":475559}]}]}
{"op":"mcm","clk":"11799476784","pt":1723176775213,"mc":[{"id":"1.231582170","rc":[{"batb":[[0,1.29,3.74],[2,1.08,7.84]],"ltp":0.0,"tv":0.0,"id":424679},{"batb":[[0,1.26,3.7],[2,1.08,7.84]],"ltp":0.0,"tv":0.0,"id":475559}]}]}
{"op":"mcm","clk":"11799651751","pt":1723182175203,"mc":[{"id":"1.231582170","rc":[{"batb":[[0,1.29,3.75],[2,1.08,7.84]],"ltp":0.0,"tv":0.0,"id":424679},{"batb":[[0,1.26,3.71],[2,1.08,7.84]],"ltp":0.0,"tv":0.0,"id":475559}]}]}
{"op":"mcm","clk":"11799801582","pt":1723187575204,"mc":[{"id":"1.231582170","rc":[{"batb":[[0,1.29,3.74],[2,1.08,7.83]],"ltp":0.0,"tv":0.0,"id":424679},{"batb":[[0,1.26,3.7],[2,1.08,7.83]],"ltp":0.0,"tv":0.0,"id":475559}]}]}
{"op":"mcm","clk":"11799851706","pt":1723189567009,"mc":[{"id":"1.231582170","rc":[{"batl":[[0,1000,0.02]],"ltp":0.0,"tv":0.0,"id":424679},{"batl":[[0,1000,0.02]],"ltp":0.0,"tv":0.0,"id":475559}]}]}
{"op":"mcm","clk":"11799976373","pt":1723192975213,"mc":[{"id":"1.231582170","rc":[{"batb":[[0,1.29,3.74],[2,1.08,7.84]],"ltp":0.0,"tv":0.0,"id":424679},{"batb":[[0,1.26,3.7],[2,1.08,7.84]],"ltp":0.0,"tv":0.0,"id":475559}]}]}
{"op":"mcm","clk":"11800347096","pt":1723198375253,"mc":[{"id":"1.231582170","rc":[{"batb":[[2,1.08,7.84]],"ltp":0.0,"tv":0.0,"id":424679},{"batb":[[2,1.08,7.84]],"ltp":0.0,"tv":0.0,"id":475559}]}]}
{"op":"mcm","clk":"11800802836","pt":1723203775293,"mc":[{"id":"1.231582170","rc":[{"batb":[[0,1.29,3.75],[2,1.08,7.85]],"ltp":0.0,"tv":0.0,"id":424679},{"batb":[[0,1.26,3.71],[2,1.08,7.85]],"ltp":0.0,"tv":0.0,"id":475559}]}]}
{"op":"mcm","clk":"11801223272","pt":1723209175244,"mc":[{"id":"1.231582170","rc":[{"batb":[[0,1.29,3.75],[2,1.08,7.85]],"ltp":0.0,"tv":0.0,"id":424679},{"batb":[[0,1.26,3.71],[2,1.08,7.85]],"ltp":0.0,"tv":0.0,"id":475559}]}]}
{"op":"mcm","clk":"11801575705","pt":1723214575226,"mc":[{"id":"1.231582170","rc":[{"batb":[[0,1.29,3.75],[2,1.08,7.85]],"ltp":0.0,"tv":0.0,"id":424679},{"batb":[[0,1.26,3.71],[2,1.08,7.85]],"ltp":0.0,"tv":0.0,"id":475559}]}]}
{"op":"mcm","clk":"11802004736","pt":1723219975302,"mc":[{"id":"1.231582170","rc":[{"batb":[[0,1.29,3.74],[2,1.08,7.84]],"ltp":0.0,"tv":0.0,"id":424679},{"batb":[[0,1.26,3.7],[2,1.08,7.84]],"ltp":0.0,"tv":0.0,"id":475559}]}]}
{"op":"mcm","clk":"11802207097","pt":1723221507446,"mc":[{"id":"1.231582170","rc":[{"batb":[[1,1.08,7.84],[2,1.07,7.84]],"ltp":0.0,"tv":0.0,"id":424679},{"batb":[[1,1.08,7.84],[2,1.07,7.84]],"ltp":0.0,"tv":0.0,"id":475559}]}]}
{"op":"mcm","clk":"11802215222","pt":1723221559169,"mc":[{"id":"1.231582170","rc":[{"batb":[[1,1.08,320.34]],"ltp":0.0,"tv":0.0,"id":475559}]}]}
{"op":"mcm","clk":"11802215399","pt":1723221560153,"mc":[{"id":"1.231582170","rc":[{"batb":[[0,1.48,52.08],[1,1.43,58.14],[2,1.38,65.79]],"ltp":0.0,"tv":0.0,"id":424679},{"batb":[[0,1.48,52.08],[1,1.43,58.14],[2,1.38,65.79]],"ltp":0.0,"tv":0.0,"id":475559}]}]}
{"op":"mcm","clk":"11802338837","pt":1723222458499,"mc":[{"id":"1.231582170","rc":[{"batb":[[0,1.49,7.49],[1,1.48,52.08],[2,1.43,58.14]],"ltp":0.0,"tv":0.0,"id":424679},{"batb":[[0,1.49,7.44],[1,1.48,52.08],[2,1.43,58.14]],"ltp":0.0,"tv":0.0,"id":475559}]}]}
{"op":"mcm","clk":"11802549989","pt":1723223796580,"mc":[{"id":"1.231582170","rc":[{"batb":[[0,1.91,45.92],[1,1.49,7.49],[2,1.48,52.08]],"ltp":0.0,"tv":0.0,"id":424679},{"batb":[[0,2,41.78],[1,1.49,7.44],[2,1.48,52.08]],"ltp":0.0,"tv":0.0,"id":475559}]}]}
{"op":"mcm","clk":"11802963681","pt":1723226040408,"mc":[{"id":"1.231582170","rc":[{"batb":[[1,1.48,52.08],[2,1.43,58.14]],"ltp":0.0,"tv":0.0,"id":424679},{"batb":[[1,1.48,52.08],[2,1.43,58.14]],"ltp":0.0,"tv":0.0,"id":475559}]}]}
{"op":"mcm","clk":"11804601295","pt":1723240302168,"mc":[{"id":"1.231582170","rc":[{"trd":[[2,80]],"batb":[[0,2,1.78]],"ltp":2.0,"tv":80.0,"id":475559}],"tv":80.0}]}
{"op":"mcm","clk":"11804601322","pt":1723240303855,"mc":[{"id":"1.231582170","rc":[{"batb":[[0,1.96,43.53]],"ltp":2.0,"tv":80.0,"id":475559}]}]}
{"op":"mcm","clk":"11804611088","pt":1723240800851,"mc":[{"id":"1.231582170","rc":[{"batb":[[0,1.97,10],[1,1.96,43.53],[2,1.48,52.08]],"ltp":2.0,"tv":80.0,"id":475559}]}]}
{"op":"mcm","clk":"11804611269","pt":1723240804719,"mc":[{"id":"1.231582170","rc":[{"batb":[[0,1.96,43.53],[1,1.48,52.08],[2,1.43,58.14]],"ltp":2.0,"tv":80.0,"id":475559}]}]}
{"op":"mcm","clk":"11804611350","pt":1723240807034,"mc":[{"id":"1.231582170","rc":[{"batb":[[0,1.97,10],[1,1.96,43.53],[2,1.48,52.08]],"ltp":2.0,"tv":80.0,"id":475559}]}]}
{"op":"mcm","clk":"11804611442","pt":1723240810476,"mc":[{"id":"1.231582170","rc":[{"batb":[[0,1.96,43.53],[1,1.48,52.08],[2,1.43,58.14]],"ltp":2.0,"tv":80.0,"id":475559}]}]}
{"op":"mcm","clk":"11804611501","pt":1723240812629,"mc":[{"id":"1.231582170","rc":[{"batb":[[0,1.97,10],[1,1.96,43.53],[2,1.48,52.08]],"ltp":2.0,"tv":80.0,"id":475559}]}]}
{"op":"mcm","clk":"11804611578","pt":1723240815971,"mc":[{"id":"1.231582170","rc":[{"batb":[[0,1.96,43.53],[1,1.48,52.08],[2,1.43,58.14]],"ltp":2.0,"tv":80.0,"id":475559}]}]}
{"op":"mcm","clk":"11804611670","pt":1723240819254,"mc":[{"id":"1.231582170","rc":[{"batb":[[0,1.97,10],[1,1.96,43.53],[2,1.48,52.08]],"ltp":2.0,"tv":80.0,"id":475559}]}]}
{"op":"mcm","clk":"11804611781","pt":1723240822949,"mc":[{"id":"1.231582170","rc":[{"batb":[[0,1.96,43.53],[1,1.48,52.08],[2,1.43,58.14]],"ltp":2.0,"tv":80.0,"id":475559}]}]}
{"op":"mcm","clk":"11804611844","pt":1723240826182,"mc":[{"id":"1.231582170","rc":[{"batb":[[0,1.97,10],[1,1.96,43.53],[2,1.48,52.08]],"ltp":2.0,"tv":80.0,"id":475559}]}]}
{"op":"mcm","clk":"11804611895","pt":1723240829460,"mc":[{"id":"1.231582170","rc":[{"batb":[[0,1.96,43.53],[1,1.48,52.08],[2,1.43,58.14]],"ltp":2.0,"tv":80.0,"id":475559}]}]}
{"op":"mcm","clk":"11804611951","pt":1723240832379,"mc":[{"id":"1.231582170","rc":[{"batb":[[0,1.97,10],[1,1.96,43.53],[2,1.48,52.08]],"ltp":2.0,"tv":80.0,"id":475559}]}]}
{"op":"mcm","clk":"11804612017","pt":1723240835667,"mc":[{"id":"1.231582170","rc":[{"batb":[[0,1.96,43.53],[1,1.48,52.08],[2,1.43,58.14]],"ltp":2.0,"tv":80.0,"id":475559}]}]}
{"op":"mcm","clk":"11804612089","pt":1723240837971,"mc":[{"id":"1.231582170","rc":[{"batb":[[0,1.97,10],[1,1.96,43.53],[2,1.48,52.08]],"ltp":2.0,"tv":80.0,"id":475559}]}]}
{"op":"mcm","clk":"11804612183","pt":1723240841461,"mc":[{"id":"1.231582170","rc":[{"batb":[[0,1.96,43.53],[1,1.48,52.08],[2,1.43,58.14]],"ltp":2.0,"tv":80.0,"id":475559}]}]}
{"op":"mcm","clk":"11804612230","pt":1723240843769,"mc":[{"id":"1.231582170","rc":[{"batb":[[0,1.97,10],[1,1.96,43.53],[2,1.48,52.08]],"ltp":2.0,"tv":80.0,"id":475559}]}]}
{"op":"mcm","clk":"11804612315","pt":1723240847165,"mc":[{"id":"1.231582170","rc":[{"batb":[[0,1.96,43.53],[1,1.48,52.08],[2,1.43,58.14]],"ltp":2.0,"tv":80.0,"id":475559}]}]}
{"op":"mcm","clk":"11804612351","pt":1723240849382,"mc":[{"id":"1.231582170","rc":[{"batb":[[0,1.97,10],[1,1.96,43.53],[2,1.48,52.08]],"ltp":2.0,"tv":80.0,"id":475559}]}]}
{"op":"mcm","clk":"11804612420","pt":1723240852718,"mc":[{"id":"1.231582170","rc":[{"batb":[[0,1.96,43.53],[1,1.48,52.08],[2,1.43,58.14]],"ltp":2.0,"tv":80.0,"id":475559}]}]}
{"op":"mcm","clk":"11804612478","pt":1723240855123,"mc":[{"id":"1.231582170","rc":[{"batb":[[0,1.97,10],[1,1.96,43.53],[2,1.48,52.08]],"ltp":2.0,"tv":80.0,"id":475559}]}]}
{"op":"mcm","clk":"11804612555","pt":1723240858498,"mc":[{"id":"1.231582170","rc":[{"batb":[[0,1.96,43.53],[1,1.48,52.08],[2,1.43,58.14]],"ltp":2.0,"tv":80.0,"id":475559}]}]}
{"op":"mcm","clk":"11804612625","pt":1723240862802,"mc":[{"id":"1.231582170","rc":[{"batb":[[0,1.97,10],[1,1.96,43.53],[2,1.48,52.08]],"ltp":2.0,"tv":80.0,"id":475559}]}]}
{"op":"mcm","clk":"11804612678","pt":1723240866099,"mc":[{"id":"1.231582170","rc":[{"batb":[[0,1.96,43.53],[1,1.48,52.08],[2,1.43,58.14]],"ltp":2.0,"tv":80.0,"id":475559}]}]}
{"op":"mcm","clk":"11804612859","pt":1723240869422,"mc":[{"id":"1.231582170","rc":[{"batb":[[0,1.97,10],[1,1.96,43.53],[2,1.48,52.08]],"ltp":2.0,"tv":80.0,"id":475559}]}]}
{"op":"mcm","clk":"11804613065","pt":1723240872811,"mc":[{"id":"1.231582170","rc":[{"batb":[[0,1.96,43.53],[1,1.48,52.08],[2,1.43,58.14]],"ltp":2.0,"tv":80.0,"id":475559}]}]}
{"op":"mcm","clk":"11804613135","pt":1723240876186,"mc":[{"id":"1.231582170","rc":[{"batb":[[0,1.97,10],[1,1.96,43.53],[2,1.48,52.08]],"ltp":2.0,"tv":80.0,"id":475559}]}]}
{"op":"mcm","clk":"11804613256","pt":1723240880301,"mc":[{"id":"1.231582170","rc":[{"batb":[[0,1.96,43.53],[1,1.48,52.08],[2,1.43,58.14]],"ltp":2.0,"tv":80.0,"id":475559}]}]}
{"op":"mcm","clk":"11804613312","pt":1723240882558,"mc":[{"id":"1.231582170","rc":[{"batb":[[0,1.97,10],[1,1.96,43.53],[2,1.48,52.08]],"ltp":2.0,"tv":80.0,"id":475559}]}]}
{"op":"mcm","clk":"11804613390","pt":1723240885767,"mc":[{"id":"1.231582170","rc":[{"batb":[[0,1.96,43.53],[1,1.48,52.08],[2,1.43,58.14]],"ltp":2.0,"tv":80.0,"id":475559}]}]}
{"op":"mcm","clk":"11804613495","pt":1723240890931,"mc":[{"id":"1.231582170","rc":[{"batb":[[0,1.97,10],[1,1.96,43.53],[2,1.48,52.08]],"ltp":2.0,"tv":80.0,"id":475559}]}]}
{"op":"mcm","clk":"11804613575","pt":1723240894230,"mc":[{"id":"1.231582170","rc":[{"batb":[[0,1.96,43.53],[1,1.48,52.08],[2,1.43,58.14]],"ltp":2.0,"tv":80.0,"id":475559}]}]}
{"op":"mcm","clk":"11804613616","pt":1723240896437,"mc":[{"id":"1.231582170","rc":[{"batb":[[0,1.97,10],[1,1.96,43.53],[2,1.48,52.08]],"ltp":2.0,"tv":80.0,"id":475559}]}]}
{"op":"mcm","clk":"11804613663","pt":1723240899761,"mc":[{"id":"1.231582170","rc":[{"batb":[[0,1.96,43.53],[1,1.48,52.08],[2,1.43,58.14]],"ltp":2.0,"tv":80.0,"id":475559}]}]}
{"op":"mcm","clk":"11804613734","pt":1723240902539,"mc":[{"id":"1.231582170","rc":[{"batb":[[0,1.97,10],[1,1.96,43.53],[2,1.48,52.08]],"ltp":2.0,"tv":80.0,"id":475559}]}]}
{"op":"mcm","clk":"11804613818","pt":1723240905822,"mc":[{"id":"1.231582170","rc":[{"batb":[[0,1.96,43.53],[1,1.48,52.08],[2,1.43,58.14]],"ltp":2.0,"tv":80.0,"id":475559}]}]}
{"op":"mcm","clk":"11804613886","pt":1723240908335,"mc":[{"id":"1.231582170","rc":[{"batb":[[0,1.97,10],[1,1.96,43.53],[2,1.48,52.08]],"ltp":2.0,"tv":80.0,"id":475559}]}]}
{"op":"mcm","clk":"11804613957","pt":1723240911868,"mc":[{"id":"1.231582170","rc":[{"batb":[[0,1.96,43.53],[1,1.48,52.08],[2,1.43,58.14]],"ltp":2.0,"tv":80.0,"id":475559}]}]}
{"op":"mcm","clk":"11804614026","pt":1723240915245,"mc":[{"id":"1.231582170","rc":[{"batb":[[0,1.97,10],[1,1.96,43.53],[2,1.48,52.08]],"ltp":2.0,"tv":80.0,"id":475559}]}]}
{"op":"mcm","clk":"11804614084","pt":1723240918485,"mc":[{"id":"1.231582170","rc":[{"batb":[[0,1.96,43.53],[1,1.48,52.08],[2,1.43,58.14]],"ltp":2.0,"tv":80.0,"id":475559}]}]}
{"op":"mcm","clk":"11804614122","pt":1723240920882,"mc":[{"id":"1.231582170","rc":[{"batb":[[0,1.97,10],[1,1.96,43.53],[2,1.48,52.08]],"ltp":2.0,"tv":80.0,"id":475559}]}]}
{"op":"mcm","clk":"11804614194","pt":1723240924171,"mc":[{"id":"1.231582170","rc":[{"batb":[[0,1.96,43.53],[1,1.48,52.08],[2,1.43,58.14]],"ltp":2.0,"tv":80.0,"id":475559}]}]}
{"op":"mcm","clk":"11804614250","pt":1723240926676,"mc":[{"id":"1.231582170","rc":[{"batb":[[0,1.97,10],[1,1.96,43.53],[2,1.48,52.08]],"ltp":2.0,"tv":80.0,"id":475559}]}]}
{"op":"mcm","clk":"11804614348","pt":1723240930373,"mc":[{"id":"1.231582170","rc":[{"batb":[[0,1.96,43.53],[1,1.48,52.08],[2,1.43,58.14]],"ltp":2.0,"tv":80.0,"id":475559}]}]}
{"op":"mcm","clk":"11804614423","pt":1723240933912,"mc":[{"id":"1.231582170","rc":[{"batb":[[0,1.97,10],[1,1.96,43.53],[2,1.48,52.08]],"ltp":2.0,"tv":80.0,"id":475559}]}]}
{"op":"mcm","clk":"11804614501","pt":1723240937392,"mc":[{"id":"1.231582170","rc":[{"batb":[[0,1.96,43.53],[1,1.48,52.08],[2,1.43,58.14]],"ltp":2.0,"tv":80.0,"id":475559}]}]}
{"op":"mcm","clk":"11804614549","pt":1723240939594,"mc":[{"id":"1.231582170","rc":[{"batb":[[0,1.97,10],[1,1.96,43.53],[2,1.48,52.08]],"ltp":2.0,"tv":80.0,"id":475559}]}]}
{"op":"mcm","clk":"11804614625","pt":1723240943003,"mc":[{"id":"1.231582170","rc":[{"batb":[[0,1.96,43.53],[1,1.48,52.08],[2,1.43,58.14]],"ltp":2.0,"tv":80.0,"id":475559}]}]}
{"op":"mcm","clk":"11804614673","pt":1723240945201,"mc":[{"id":"1.231582170","rc":[{"batb":[[0,1.97,10],[1,1.96,43.53],[2,1.48,52.08]],"ltp":2.0,"tv":80.0,"id":475559}]}]}
{"op":"mcm","clk":"11804614738","pt":1723240948433,"mc":[{"id":"1.231582170","rc":[{"batb":[[0,1.96,43.53],[1,1.48,52.08],[2,1.43,58.14]],"ltp":2.0,"tv":80.0,"id":475559}]}]}
{"op":"mcm","clk":"11804614772","pt":1723240950839,"mc":[{"id":"1.231582170","rc":[{"batb":[[0,1.97,10],[1,1.96,43.53],[2,1.48,52.08]],"ltp":2.0,"tv":80.0,"id":475559}]}]}
{"op":"mcm","clk":"11804614845","pt":1723240954336,"mc":[{"id":"1.231582170","rc":[{"batb":[[0,1.96,43.53],[1,1.48,52.08],[2,1.43,58.14]],"ltp":2.0,"tv":80.0,"id":475559}]}]}
{"op":"mcm","clk":"11804614907","pt":1723240956516,"mc":[{"id":"1.231582170","rc":[{"batb":[[0,1.97,10],[1,1.96,43.53],[2,1.48,52.08]],"ltp":2.0,"tv":80.0,"id":475559}]}]}
{"op":"mcm","clk":"11804614991","pt":1723240959948,"mc":[{"id":"1.231582170","rc":[{"batb":[[0,1.96,43.53],[1,1.48,52.08],[2,1.43,58.14]],"ltp":2.0,"tv":80.0,"id":475559}]}]}
{"op":"mcm","clk":"11804615056","pt":1723240963231,"mc":[{"id":"1.231582170","rc":[{"batb":[[0,1.97,10],[1,1.96,43.53],[2,1.48,52.08]],"ltp":2.0,"tv":80.0,"id":475559}]}]}
{"op":"mcm","clk":"11804615120","pt":1723240966612,"mc":[{"id":"1.231582170","rc":[{"batb":[[0,1.96,43.53],[1,1.48,52.08],[2,1.43,58.14]],"ltp":2.0,"tv":80.0,"id":475559}]}]}
{"op":"mcm","clk":"11804615175","pt":1723240969132,"mc":[{"id":"1.231582170","rc":[{"batb":[[0,1.97,10],[1,1.96,43.53],[2,1.48,52.08]],"ltp":2.0,"tv":80.0,"id":475559}]}]}
{"op":"mcm","clk":"11804615243","pt":1723240972527,"mc":[{"id":"1.231582170","rc":[{"batb":[[0,1.96,43.53],[1,1.48,52.08],[2,1.43,58.14]],"ltp":2.0,"tv":80.0,"id":475559}]}]}
{"op":"mcm","clk":"11804615304","pt":1723240975138,"mc":[{"id":"1.231582170","rc":[{"batb":[[0,1.97,10],[1,1.96,43.53],[2,1.48,52.08]],"ltp":2.0,"tv":80.0,"id":475559}]}]}
{"op":"mcm","clk":"11804615378","pt":1723240978363,"mc":[{"id":"1.231582170","rc":[{"batb":[[0,1.96,43.53],[1,1.48,52.08],[2,1.43,58.14]],"ltp":2.0,"tv":80.0,"id":475559}]}]}
{"op":"mcm","clk":"11804615418","pt":1723240980664,"mc":[{"id":"1.231582170","rc":[{"batb":[[0,1.97,10],[1,1.96,43.53],[2,1.48,52.08]],"ltp":2.0,"tv":80.0,"id":475559}]}]}
{"op":"mcm","clk":"11804615485","pt":1723240983947,"mc":[{"id":"1.231582170","rc":[{"batb":[[0,1.96,43.53],[1,1.48,52.08],[2,1.43,58.14]],"ltp":2.0,"tv":80.0,"id":475559}]}]}
{"op":"mcm","clk":"11804615561","pt":1723240986766,"mc":[{"id":"1.231582170","rc":[{"batb":[[0,1.97,10],[1,1.96,43.53],[2,1.48,52.08]],"ltp":2.0,"tv":80.0,"id":475559}]}]}
{"op":"mcm","clk":"11804615645","pt":1723240990050,"mc":[{"id":"1.231582170","rc":[{"batb":[[0,1.96,43.53],[1,1.48,52.08],[2,1.43,58.14]],"ltp":2.0,"tv":80.0,"id":475559}]}]}
{"op":"mcm","clk":"11804615727","pt":1723240993072,"mc":[{"id":"1.231582170","rc":[{"batb":[[0,1.97,10],[1,1.96,43.53],[2,1.48,52.08]],"ltp":2.0,"tv":80.0,"id":475559}]}]}
{"op":"mcm","clk":"11804615797","pt":1723240996461,"mc":[{"id":"1.231582170","rc":[{"batb":[[0,1.96,43.53],[1,1.48,52.08],[2,1.43,58.14]],"ltp":2.0,"tv":80.0,"id":475559}]}]}
{"op":"mcm","clk":"11804615860","pt":1723240999181,"mc":[{"id":"1.231582170","rc":[{"batb":[[0,1.97,10],[1,1.96,43.53],[2,1.48,52.08]],"ltp":2.0,"tv":80.0,"id":475559}]}]}
{"op":"mcm","clk":"11804615929","pt":1723241002576,"mc":[{"id":"1.231582170","rc":[{"batb":[[0,1.96,43.53],[1,1.48,52.08],[2,1.43,58.14]],"ltp":2.0,"tv":80.0,"id":475559}]}]}
{"op":"mcm","clk":"11804615997","pt":1723241005302,"mc":[{"id":"1.231582170","rc":[{"batb":[[0,1.97,10],[1,1.96,43.53],[2,1.48,52.08]],"ltp":2.0,"tv":80.0,"id":475559}]}]}
{"op":"mcm","clk":"11804616072","pt":1723241008684,"mc":[{"id":"1.231582170","rc":[{"batb":[[0,1.96,43.53],[1,1.48,52.08],[2,1.43,58.14]],"ltp":2.0,"tv":80.0,"id":475559}]}]}
{"op":"mcm","clk":"11804616098","pt":1723241010991,"mc":[{"id":"1.231582170","rc":[{"batb":[[0,1.97,10],[1,1.96,43.53],[2,1.48,52.08]],"ltp":2.0,"tv":80.0,"id":475559}]}]}
{"op":"mcm","clk":"11804616142","pt":1723241014273,"mc":[{"id":"1.231582170","rc":[{"batb":[[0,1.96,43.53],[1,1.48,52.08],[2,1.43,58.14]],"ltp":2.0,"tv":80.0,"id":475559}]}]}
{"op":"mcm","clk":"11804616199","pt":1723241016594,"mc":[{"id":"1.231582170","rc":[{"batb":[[0,1.97,10],[1,1.96,43.53],[2,1.48,52.08]],"ltp":2.0,"tv":80.0,"id":475559}]}]}
{"op":"mcm","clk":"11804616250","pt":1723241020081,"mc":[{"id":"1.231582170","rc":[{"batb":[[0,1.96,43.53],[1,1.48,52.08],[2,1.43,58.14]],"ltp":2.0,"tv":80.0,"id":475559}]}]}
{"op":"mcm","clk":"11804616315","pt":1723241024285,"mc":[{"id":"1.231582170","rc":[{"batb":[[0,1.97,10],[1,1.96,43.53],[2,1.48,52.08]],"ltp":2.0,"tv":80.0,"id":475559}]}]}
{"op":"mcm","clk":"11804616457","pt":1723241027587,"mc":[{"id":"1.231582170","rc":[{"batb":[[0,1.96,43.53],[1,1.48,52.08],[2,1.43,58.14]],"ltp":2.0,"tv":80.0,"id":475559}]}]}
{"op":"mcm","clk":"11804616505","pt":1723241030209,"mc":[{"id":"1.231582170","rc":[{"batb":[[0,1.97,10],[1,1.96,43.53],[2,1.48,52.08]],"ltp":2.0,"tv":80.0,"id":475559}]}]}
{"op":"mcm","clk":"11804616622","pt":1723241033511,"mc":[{"id":"1.231582170","rc":[{"batb":[[0,1.96,43.53],[1,1.48,52.08],[2,1.43,58.14]],"ltp":2.0,"tv":80.0,"id":475559}]}]}
{"op":"mcm","clk":"11804616665","pt":1723241035823,"mc":[{"id":"1.231582170","rc":[{"batb":[[0,1.97,10],[1,1.96,43.53],[2,1.48,52.08]],"ltp":2.0,"tv":80.0,"id":475559}]}]}
{"op":"mcm","clk":"11804616726","pt":1723241039093,"mc":[{"id":"1.231582170","rc":[{"batb":[[0,1.96,43.53],[1,1.48,52.08],[2,1.43,58.14]],"ltp":2.0,"tv":80.0,"id":475559}]}]}
{"op":"mcm","clk":"11804616780","pt":1723241041396,"mc":[{"id":"1.231582170","rc":[{"batb":[[0,1.97,10],[1,1.96,43.53],[2,1.48,52.08]],"ltp":2.0,"tv":80.0,"id":475559}]}]}
{"op":"mcm","clk":"11804616860","pt":1723241044730,"mc":[{"id":"1.231582170","rc":[{"batb":[[0,1.96,43.53],[1,1.48,52.08],[2,1.43,58.14]],"ltp":2.0,"tv":80.0,"id":475559}]}]}
{"op":"mcm","clk":"11804616902","pt":1723241046996,"mc":[{"id":"1.231582170","rc":[{"batb":[[0,1.97,10],[1,1.96,43.53],[2,1.48,52.08]],"ltp":2.0,"tv":80.0,"id":475559}]}]}
{"op":"mcm","clk":"11804616961","pt":1723241050338,"mc":[{"id":"1.231582170","rc":[{"batb":[[0,1.96,43.53],[1,1.48,52.08],[2,1.43,58.14]],"ltp":2.0,"tv":80.0,"id":475559}]}]}
{"op":"mcm","clk":"11804617006","pt":1723241052600,"mc":[{"id":"1.231582170","rc":[{"batb":[[0,1.97,10],[1,1.96,43.53],[2,1.48,52.08]],"ltp":2.0,"tv":80.0,"id":475559}]}]}
{"op":"mcm","clk":"11804617091","pt":1723241056152,"mc":[{"id":"1.231582170","rc":[{"batb":[[0,1.96,43.53],[1,1.48,52.08],[2,1.43,58.14]],"ltp":2.0,"tv":80.0,"id":475559}]}]}
{"op":"mcm","clk":"11804617191","pt":1723241059638,"mc":[{"id":"1.231582170","rc":[{"batb":[[0,1.97,10],[1,1.96,43.53],[2,1.48,52.08]],"ltp":2.0,"tv":80.0,"id":475559}]}]}
{"op":"mcm","clk":"11804617290","pt":1723241063035,"mc":[{"id":"1.231582170","rc":[{"batb":[[0,1.96,43.53],[1,1.48,52.08],[2,1.43,58.14]],"ltp":2.0,"tv":80.0,"id":475559}]}]}
{"op":"mcm","clk":"11804617358","pt":1723241065735,"mc":[{"id":"1.231582170","rc":[{"batb":[[0,1.97,10],[1,1.96,43.53],[2,1.48,52.08]],"ltp":2.0,"tv":80.0,"id":475559}]}]}
{"op":"mcm","clk":"11804617417","pt":1723241068916,"mc":[{"id":"1.231582170","rc":[{"batb":[[0,1.96,43.53],[1,1.48,52.08],[2,1.43,58.14]],"ltp":2.0,"tv":80.0,"id":475559}]}]}
{"op":"mcm","clk":"11804617470","pt":1723241071429,"mc":[{"id":"1.231582170","rc":[{"batb":[[0,1.97,10],[1,1.96,43.53],[2,1.48,52.08]],"ltp":2.0,"tv":80.0,"id":475559}]}]}
{"op":"mcm","clk":"11804617564","pt":1723241074934,"mc":[{"id":"1.231582170","rc":[{"batb":[[0,1.96,43.53],[1,1.48,52.08],[2,1.43,58.14]],"ltp":2.0,"tv":80.0,"id":475559}]}]}
{"op":"mcm","clk":"11804617627","pt":1723241077346,"mc":[{"id":"1.231582170","rc":[{"batb":[[0,1.97,10],[1,1.96,43.53],[2,1.48,52.08]],"ltp":2.0,"tv":80.0,"id":475559}]}]}
{"op":"mcm","clk":"11804617711","pt":1723241080840,"mc":[{"id":"1.231582170","rc":[{"batb":[[0,1.96,43.53],[1,1.48,52.08],[2,1.43,58.14]],"ltp":2.0,"tv":80.0,"id":475559}]}]}
{"op":"mcm","clk":"11804617754","pt":1723241083353,"mc":[{"id":"1.231582170","rc":[{"batb":[[0,1.97,10],[1,1.96,43.53],[2,1.48,52.08]],"ltp":2.0,"tv":80.0,"id":475559}]}]}
{"op":"mcm","clk":"11804617837","pt":1723241086644,"mc":[{"id":"1.231582170","rc":[{"batb":[[0,1.96,43.53],[1,1.48,52.08],[2,1.43,58.14]],"ltp":2.0,"tv":80.0,"id":475559}]}]}
{"op":"mcm","clk":"11804617892","pt":1723241089070,"mc":[{"id":"1.231582170","rc":[{"batb":[[0,1.97,10],[1,1.96,43.53],[2,1.48,52.08]],"ltp":2.0,"tv":80.0,"id":475559}]}]}
{"op":"mcm","clk":"11804617988","pt":1723241092662,"mc":[{"id":"1.231582170","rc":[{"batb":[[0,1.96,43.53],[1,1.48,52.08],[2,1.43,58.14]],"ltp":2.0,"tv":80.0,"id":475559}]}]}
{"op":"mcm","clk":"11804618026","pt":1723241094978,"mc":[{"id":"1.231582170","rc":[{"batb":[[0,1.97,10],[1,1.96,43.53],[2,1.48,52.08]],"ltp":2.0,"tv":80.0,"id":475559}]}]}
{"op":"mcm","clk":"11804618117","pt":1723241098265,"mc":[{"id":"1.231582170","rc":[{"batb":[[0,1.96,43.53],[1,1.48,52.08],[2,1.43,58.14]],"ltp":2.0,"tv":80.0,"id":475559}]}]}
{"op":"mcm","clk":"11804618167","pt":1723241100680,"mc":[{"id":"1.231582170","rc":[{"batb":[[0,1.97,10],[1,1.96,43.53],[2,1.48,52.08]],"ltp":2.0,"tv":80.0,"id":475559}]}]}
{"op":"mcm","clk":"11804618241","pt":1723241104071,"mc":[{"id":"1.231582170","rc":[{"batb":[[0,1.96,43.53],[1,1.48,52.08],[2,1.43,58.14]],"ltp":2.0,"tv":80.0,"id":475559}]}]}
{"op":"mcm","clk":"11804618317","pt":1723241107261,"mc":[{"id":"1.231582170","rc":[{"batb":[[0,1.97,10],[1,1.96,43.53],[2,1.48,52.08]],"ltp":2.0,"tv":80.0,"id":475559}]}]}
{"op":"mcm","clk":"11804618407","pt":1723241110485,"mc":[{"id":"1.231582170","rc":[{"batb":[[0,1.96,43.53],[1,1.48,52.08],[2,1.43,58.14]],"ltp":2.0,"tv":80.0,"id":475559}]}]}
{"op":"mcm","clk":"11804618464","pt":1723241113202,"mc":[{"id":"1.231582170","rc":[{"batb":[[0,1.97,10],[1,1.96,43.53],[2,1.48,52.08]],"ltp":2.0,"tv":80.0,"id":475559}]}]}
{"op":"mcm","clk":"11804618544","pt":1723241116694,"mc":[{"id":"1.231582170","rc":[{"batb":[[0,1.96,43.53],[1,1.48,52.08],[2,1.43,58.14]],"ltp":2.0,"tv":80.0,"id":475559}]}]}
{"op":"mcm","clk":"11804618581","pt":1723241119000,"mc":[{"id":"1.231582170","rc":[{"batb":[[0,1.97,10],[1,1.96,43.53],[2,1.48,52.08]],"ltp":2.0,"tv":80.0,"id":475559}]}]}
{"op":"mcm","clk":"11804618659","pt":1723241122504,"mc":[{"id":"1.231582170","rc":[{"batb":[[0,1.96,43.53],[1,1.48,52.08],[2,1.43,58.14]],"ltp":2.0,"tv":80.0,"id":475559}]}]}
{"op":"mcm","clk":"11804618706","pt":1723241124804,"mc":[{"id":"1.231582170","rc":[{"batb":[[0,1.97,10],[1,1.96,43.53],[2,1.48,52.08]],"ltp":2.0,"tv":80.0,"id":475559}]}]}
{"op":"mcm","clk":"11804618764","pt":1723241128193,"mc":[{"id":"1.231582170","rc":[{"batb":[[0,1.96,43.53],[1,1.48,52.08],[2,1.43,58.14]],"ltp":2.0,"tv":80.0,"id":475559}]}]}
{"op":"mcm","clk":"11804618827","pt":1723241130510,"mc":[{"id":"1.231582170","rc":[{"batb":[[0,1.97,10],[1,1.96,43.53],[2,1.48,52.08]],"ltp":2.0,"tv":80.0,"id":475559}]}]}
{"op":"mcm","clk":"11804618892","pt":1723241133802,"mc":[{"id":"1.231582170","rc":[{"batb":[[0,1.96,43.53],[1,1.48,52.08],[2,1.43,58.14]],"ltp":2.0,"tv":80.0,"id":475559}]}]}
{"op":"mcm","clk":"11804618956","pt":1723241136420,"mc":[{"id":"1.231582170","rc":[{"batb":[[0,1.97,10],[1,1.96,43.53],[2,1.48,52.08]],"ltp":2.0,"tv":80.0,"id":475559}]}]}
{"op":"mcm","clk":"11804619038","pt":1723241139714,"mc":[{"id":"1.231582170","rc":[{"batb":[[0,1.96,43.53],[1,1.48,52.08],[2,1.43,58.14]],"ltp":2.0,"tv":80.0,"id":475559}]}]}
{"op":"mcm","clk":"11804619087","pt":1723241142022,"mc":[{"id":"1.231582170","rc":[{"batb":[[0,1.97,10],[1,1.96,43.53],[2,1.48,52.08]],"ltp":2.0,"tv":80.0,"id":475559}]}]}
{"op":"mcm","clk":"11804619188","pt":1723241145419,"mc":[{"id":"1.231582170","rc":[{"batb":[[0,1.96,43.53],[1,1.48,52.08],[2,1.43,58.14]],"ltp":2.0,"tv":80.0,"id":475559}]}]}
{"op":"mcm","clk":"11804619230","pt":1723241147829,"mc":[{"id":"1.231582170","rc":[{"batb":[[0,1.97,10],[1,1.96,43.53],[2,1.48,52.08]],"ltp":2.0,"tv":80.0,"id":475559}]}]}
{"op":"mcm","clk":"11804619305","pt":1723241151015,"mc":[{"id":"1.231582170","rc":[{"batb":[[0,1.96,43.53],[1,1.48,52.08],[2,1.43,58.14]],"ltp":2.0,"tv":80.0,"id":475559}]}]}
{"op":"mcm","clk":"11804619386","pt":1723241153436,"mc":[{"id":"1.231582170","rc":[{"batb":[[0,1.97,10],[1,1.96,43.53],[2,1.48,52.08]],"ltp":2.0,"tv":80.0,"id":475559}]}]}
{"op":"mcm","clk":"11804619466","pt":1723241156813,"mc":[{"id":"1.231582170","rc":[{"batb":[[0,1.96,43.53],[1,1.48,52.08],[2,1.43,58.14]],"ltp":2.0,"tv":80.0,"id":475559}]}]}
{"op":"mcm","clk":"11804619502","pt":1723241159121,"mc":[{"id":"1.231582170","rc":[{"batb":[[0,1.97,10],[1,1.96,43.53],[2,1.48,52.08]],"ltp":2.0,"tv":80.0,"id":475559}]}]}
{"op":"mcm","clk":"11804619577","pt":1723241162622,"mc":[{"id":"1.231582170","rc":[{"batb":[[0,1.96,43.53],[1,1.48,52.08],[2,1.43,58.14]],"ltp":2.0,"tv":80.0,"id":475559}]}]}
{"op":"mcm","clk":"11804619643","pt":1723241165646,"mc":[{"id":"1.231582170","rc":[{"batb":[[0,1.97,10],[1,1.96,43.53],[2,1.48,52.08]],"ltp":2.0,"tv":80.0,"id":475559}]}]}
{"op":"mcm","clk":"11804619738","pt":1723241169352,"mc":[{"id":"1.231582170","rc":[{"batb":[[0,1.96,43.53],[1,1.48,52.08],[2,1.43,58.14]],"ltp":2.0,"tv":80.0,"id":475559}]}]}
{"op":"mcm","clk":"11804619802","pt":1723241171711,"mc":[{"id":"1.231582170","rc":[{"batb":[[0,1.97,10],[1,1.96,43.53],[2,1.48,52.08]],"ltp":2.0,"tv":80.0,"id":475559}]}]}
{"op":"mcm","clk":"11804619880","pt":1723241175464,"mc":[{"id":"1.231582170","rc":[{"batb":[[0,1.96,43.53],[1,1.48,52.08],[2,1.43,58.14]],"ltp":2.0,"tv":80.0,"id":475559}]}]}
{"op":"mcm","clk":"11804619929","pt":1723241177818,"mc":[{"id":"1.231582170","rc":[{"batb":[[0,1.97,10],[1,1.96,43.53],[2,1.48,52.08]],"ltp":2.0,"tv":80.0,"id":475559}]}]}
{"op":"mcm","clk":"11804620002","pt":1723241181256,"mc":[{"id":"1.231582170","rc":[{"batb":[[0,1.96,43.53],[1,1.48,52.08],[2,1.43,58.14]],"ltp":2.0,"tv":80.0,"id":475559}]}]}
{"op":"mcm","clk":"11804620073","pt":1723241183771,"mc":[{"id":"1.231582170","rc":[{"batb":[[0,1.97,10],[1,1.96,43.53],[2,1.48,52.08]],"ltp":2.0,"tv":80.0,"id":475559}]}]}
{"op":"mcm","clk":"11804620136","pt":1723241187051,"mc":[{"id":"1.231582170","rc":[{"batb":[[0,1.96,43.53],[1,1.48,52.08],[2,1.43,58.14]],"ltp":2.0,"tv":80.0,"id":475559}]}]}
{"op":"mcm","clk":"11804620194","pt":1723241189471,"mc":[{"id":"1.231582170","rc":[{"batb":[[0,1.97,10],[1,1.96,43.53],[2,1.48,52.08]],"ltp":2.0,"tv":80.0,"id":475559}]}]}
{"op":"mcm","clk":"11804620261","pt":1723241192852,"mc":[{"id":"1.231582170","rc":[{"batb":[[0,1.96,43.53],[1,1.48,52.08],[2,1.43,58.14]],"ltp":2.0,"tv":80.0,"id":475559}]}]}
{"op":"mcm","clk":"11804620329","pt":1723241196188,"mc":[{"id":"1.231582170","rc":[{"batb":[[0,1.97,10],[1,1.96,43.53],[2,1.48,52.08]],"ltp":2.0,"tv":80.0,"id":475559}]}]}
{"op":"mcm","clk":"11804620394","pt":1723241199475,"mc":[{"id":"1.231582170","rc":[{"batb":[[0,1.96,43.53],[1,1.48,52.08],[2,1.43,58.14]],"ltp":2.0,"tv":80.0,"id":475559}]}]}
{"op":"mcm","clk":"11804620477","pt":1723241203375,"mc":[{"id":"1.231582170","rc":[{"batb":[[0,1.97,10],[1,1.96,43.53],[2,1.48,52.08]],"ltp":2.0,"tv":80.0,"id":475559}]}]}
{"op":"mcm","clk":"11804620544","pt":1723241206662,"mc":[{"id":"1.231582170","rc":[{"batb":[[0,1.96,43.53],[1,1.48,52.08],[2,1.43,58.14]],"ltp":2.0,"tv":80.0,"id":475559}]}]}
{"op":"mcm","clk":"11804620603","pt":1723241208864,"mc":[{"id":"1.231582170","rc":[{"batb":[[0,1.97,10],[1,1.96,43.53],[2,1.48,52.08]],"ltp":2.0,"tv":80.0,"id":475559}]}]}
{"op":"mcm","clk":"11804620683","pt":1723241212356,"mc":[{"id":"1.231582170","rc":[{"batb":[[0,1.96,43.53],[1,1.48,52.08],[2,1.43,58.14]],"ltp":2.0,"tv":80.0,"id":475559}]}]}
{"op":"mcm","clk":"11804620732","pt":1723241214884,"mc":[{"id":"1.231582170","rc":[{"batb":[[0,1.97,10],[1,1.96,43.53],[2,1.48,52.08]],"ltp":2.0,"tv":80.0,"id":475559}]}]}
{"op":"mcm","clk":"11804620775","pt":1723241218308,"mc":[{"id":"1.231582170","rc":[{"batb":[[0,1.96,43.53],[1,1.48,52.08],[2,1.43,58.14]],"ltp":2.0,"tv":80.0,"id":475559}]}]}
{"op":"mcm","clk":"11804620816","pt":1723241220615,"mc":[{"id":"1.231582170","rc":[{"batb":[[0,1.97,10],[1,1.96,43.53],[2,1.48,52.08]],"ltp":2.0,"tv":80.0,"id":475559}]}]}
{"op":"mcm","clk":"11804620879","pt":1723241224107,"mc":[{"id":"1.231582170","rc":[{"batb":[[0,1.96,43.53],[1,1.48,52.08],[2,1.43,58.14]],"ltp":2.0,"tv":80.0,"id":475559}]}]}
{"op":"mcm","clk":"11804620942","pt":1723241227394,"mc":[{"id":"1.231582170","rc":[{"batb":[[0,1.97,10],[1,1.96,43.53],[2,1.48,52.08]],"ltp":2.0,"tv":80.0,"id":475559}]}]}
{"op":"mcm","clk":"11804621009","pt":1723241231183,"mc":[{"id":"1.231582170","rc":[{"batb":[[0,1.96,43.53],[1,1.48,52.08],[2,1.43,58.14]],"ltp":2.0,"tv":80.0,"id":475559}]}]}
{"op":"mcm","clk":"11804621064","pt":1723241233615,"mc":[{"id":"1.231582170","rc":[{"batb":[[0,1.97,10],[1,1.96,43.53],[2,1.48,52.08]],"ltp":2.0,"tv":80.0,"id":475559}]}]}
{"op":"mcm","clk":"11804621140","pt":1723241236892,"mc":[{"id":"1.231582170","rc":[{"batb":[[0,1.96,43.53],[1,1.48,52.08],[2,1.43,58.14]],"ltp":2.0,"tv":80.0,"id":475559}]}]}
{"op":"mcm","clk":"11804621185","pt":1723241239707,"mc":[{"id":"1.231582170","rc":[{"batb":[[0,1.97,10],[1,1.96,43.53],[2,1.48,52.08]],"ltp":2.0,"tv":80.0,"id":475559}]}]}
{"op":"mcm","clk":"11804621248","pt":1723241243092,"mc":[{"id":"1.231582170","rc":[{"batb":[[0,1.96,43.53],[1,1.48,52.08],[2,1.43,58.14]],"ltp":2.0,"tv":80.0,"id":475559}]}]}
{"op":"mcm","clk":"11804621311","pt":1723241245836,"mc":[{"id":"1.231582170","rc":[{"batb":[[0,1.97,10],[1,1.96,43.53],[2,1.48,52.08]],"ltp":2.0,"tv":80.0,"id":475559}]}]}
{"op":"mcm","clk":"11804621394","pt":1723241249149,"mc":[{"id":"1.231582170","rc":[{"batb":[[0,1.96,43.53],[1,1.48,52.08],[2,1.43,58.14]],"ltp":2.0,"tv":80.0,"id":475559}]}]}
{"op":"mcm","clk":"11804621468","pt":1723241252031,"mc":[{"id":"1.231582170","rc":[{"batb":[[0,1.97,10],[1,1.96,43.53],[2,1.48,52.08]],"ltp":2.0,"tv":80.0,"id":475559}]}]}
{"op":"mcm","clk":"11804621742","pt":1723241255321,"mc":[{"id":"1.231582170","rc":[{"batb":[[0,1.96,43.53],[1,1.48,52.08],[2,1.43,58.14]],"ltp":2.0,"tv":80.0,"id":475559}]}]}
{"op":"mcm","clk":"11804621792","pt":1723241257728,"mc":[{"id":"1.231582170","rc":[{"batb":[[0,1.97,10],[1,1.96,43.53],[2,1.48,52.08]],"ltp":2.0,"tv":80.0,"id":475559}]}]}
{"op":"mcm","clk":"11804621869","pt":1723241261163,"mc":[{"id":"1.231582170","rc":[{"batb":[[0,1.96,43.53],[1,1.48,52.08],[2,1.43,58.14]],"ltp":2.0,"tv":80.0,"id":475559}]}]}
{"op":"mcm","clk":"11804621918","pt":1723241264240,"mc":[{"id":"1.231582170","rc":[{"batb":[[0,1.97,10],[1,1.96,43.53],[2,1.48,52.08]],"ltp":2.0,"tv":80.0,"id":475559}]}]}
{"op":"mcm","clk":"11804621978","pt":1723241267869,"mc":[{"id":"1.231582170","rc":[{"batb":[[0,1.96,43.53],[1,1.48,52.08],[2,1.43,58.14]],"ltp":2.0,"tv":80.0,"id":475559}]}]}
{"op":"mcm","clk":"11804622024","pt":1723241270328,"mc":[{"id":"1.231582170","rc":[{"batb":[[0,1.97,10],[1,1.96,43.53],[2,1.48,52.08]],"ltp":2.0,"tv":80.0,"id":475559}]}]}
{"op":"mcm","clk":"11804622068","pt":1723241273867,"mc":[{"id":"1.231582170","rc":[{"batb":[[0,1.96,43.53],[1,1.48,52.08],[2,1.43,58.14]],"ltp":2.0,"tv":80.0,"id":475559}]}]}
{"op":"mcm","clk":"11804622124","pt":1723241277148,"mc":[{"id":"1.231582170","rc":[{"batb":[[0,1.97,10],[1,1.96,43.53],[2,1.48,52.08]],"ltp":2.0,"tv":80.0,"id":475559}]}]}
{"op":"mcm","clk":"11804622177","pt":1723241280483,"mc":[{"id":"1.231582170","rc":[{"batb":[[0,1.96,43.53],[1,1.48,52.08],[2,1.43,58.14]],"ltp":2.0,"tv":80.0,"id":475559}]}]}
{"op":"mcm","clk":"11804622206","pt":1723241282690,"mc":[{"id":"1.231582170","rc":[{"batb":[[0,1.97,10],[1,1.96,43.53],[2,1.48,52.08]],"ltp":2.0,"tv":80.0,"id":475559}]}]}
{"op":"mcm","clk":"11804622259","pt":1723241286281,"mc":[{"id":"1.231582170","rc":[{"batb":[[0,1.96,43.53],[1,1.48,52.08],[2,1.43,58.14]],"ltp":2.0,"tv":80.0,"id":475559}]}]}
{"op":"mcm","clk":"11804622306","pt":1723241289050,"mc":[{"id":"1.231582170","rc":[{"batb":[[0,1.97,10],[1,1.96,43.53],[2,1.48,52.08]],"ltp":2.0,"tv":80.0,"id":475559}]}]}
{"op":"mcm","clk":"11804622367","pt":1723241292399,"mc":[{"id":"1.231582170","rc":[{"batb":[[0,1.96,43.53],[1,1.48,52.08],[2,1.43,58.14]],"ltp":2.0,"tv":80.0,"id":475559}]}]}
{"op":"mcm","clk":"11804622450","pt":1723241295185,"mc":[{"id":"1.231582170","rc":[{"batb":[[0,1.97,10],[1,1.96,43.53],[2,1.48,52.08]],"ltp":2.0,"tv":80.0,"id":475559}]}]}
{"op":"mcm","clk":"11804622569","pt":1723241298583,"mc":[{"id":"1.231582170","rc":[{"batb":[[0,1.96,43.53],[1,1.48,52.08],[2,1.43,58.14]],"ltp":2.0,"tv":80.0,"id":475559}]}]}
{"op":"mcm","clk":"11804622606","pt":1723241300889,"mc":[{"id":"1.231582170","rc":[{"batb":[[0,1.97,10],[1,1.96,43.53],[2,1.48,52.08]],"ltp":2.0,"tv":80.0,"id":475559}]}]}
{"op":"mcm","clk":"11804622657","pt":1723241304279,"mc":[{"id":"1.231582170","rc":[{"batb":[[0,1.96,43.53],[1,1.48,52.08],[2,1.43,58.14]],"ltp":2.0,"tv":80.0,"id":475559}]}]}
{"op":"mcm","clk":"11804622718","pt":1723241307107,"mc":[{"id":"1.231582170","rc":[{"batb":[[0,1.97,10],[1,1.96,43.53],[2,1.48,52.08]],"ltp":2.0,"tv":80.0,"id":475559}]}]}
{"op":"mcm","clk":"11804622795","pt":1723241310495,"mc":[{"id":"1.231582170","rc":[{"batb":[[0,1.96,43.53],[1,1.48,52.08],[2,1.43,58.14]],"ltp":2.0,"tv":80.0,"id":475559}]}]}
{"op":"mcm","clk":"11804622838","pt":1723241312911,"mc":[{"id":"1.231582170","rc":[{"batb":[[0,1.97,10],[1,1.96,43.53],[2,1.48,52.08]],"ltp":2.0,"tv":80.0,"id":475559}]}]}
{"op":"mcm","clk":"11804622898","pt":1723241316194,"mc":[{"id":"1.231582170","rc":[{"batb":[[0,1.96,43.53],[1,1.48,52.08],[2,1.43,58.14]],"ltp":2.0,"tv":80.0,"id":475559}]}]}
{"op":"mcm","clk":"11804622945","pt":1723241318505,"mc":[{"id":"1.231582170","rc":[{"batb":[[0,1.97,10],[1,1.96,43.53],[2,1.48,52.08]],"ltp":2.0,"tv":80.0,"id":475559}]}]}
{"op":"mcm","clk":"11804622994","pt":1723241321896,"mc":[{"id":"1.231582170","rc":[{"batb":[[0,1.96,43.53],[1,1.48,52.08],[2,1.43,58.14]],"ltp":2.0,"tv":80.0,"id":475559}]}]}
{"op":"mcm","clk":"11804623034","pt":1723241323998,"mc":[{"id":"1.231582170","rc":[{"batb":[[0,1.97,10],[1,1.96,43.53],[2,1.48,52.08]],"ltp":2.0,"tv":80.0,"id":475559}]}]}
{"op":"mcm","clk":"11804623094","pt":1723241327229,"mc":[{"id":"1.231582170","rc":[{"batb":[[0,1.96,43.53],[1,1.48,52.08],[2,1.43,58.14]],"ltp":2.0,"tv":80.0,"id":475559}]}]}
{"op":"mcm","clk":"11804623140","pt":1723241329592,"mc":[{"id":"1.231582170","rc":[{"batb":[[0,1.97,10],[1,1.96,43.53],[2,1.48,52.08]],"ltp":2.0,"tv":80.0,"id":475559}]}]}
{"op":"mcm","clk":"11804623223","pt":1723241332934,"mc":[{"id":"1.231582170","rc":[{"batb":[[0,1.96,43.53],[1,1.48,52.08],[2,1.43,58.14]],"ltp":2.0,"tv":80.0,"id":475559}]}]}
{"op":"mcm","clk":"11804623264","pt":1723241335304,"mc":[{"id":"1.231582170","rc":[{"batb":[[0,1.97,10],[1,1.96,43.53],[2,1.48,52.08]],"ltp":2.0,"tv":80.0,"id":475559}]}]}
{"op":"mcm","clk":"11804623331","pt":1723241338737,"mc":[{"id":"1.231582170","rc":[{"batb":[[0,1.96,43.53],[1,1.48,52.08],[2,1.43,58.14]],"ltp":2.0,"tv":80.0,"id":475559}]}]}
{"op":"mcm","clk":"11804623390","pt":1723241341819,"mc":[{"id":"1.231582170","rc":[{"batb":[[0,1.97,10],[1,1.96,43.53],[2,1.48,52.08]],"ltp":2.0,"tv":80.0,"id":475559}]}]}
{"op":"mcm","clk":"11804623446","pt":1723241345205,"mc":[{"id":"1.231582170","rc":[{"batb":[[0,1.96,43.53],[1,1.48,52.08],[2,1.43,58.14]],"ltp":2.0,"tv":80.0,"id":475559}]}]}
{"op":"mcm","clk":"11804623502","pt":1723241348234,"mc":[{"id":"1.231582170","rc":[{"batb":[[0,1.97,10],[1,1.96,43.53],[2,1.48,52.08]],"ltp":2.0,"tv":80.0,"id":475559}]}]}
{"op":"mcm","clk":"11804623566","pt":1723241351546,"mc":[{"id":"1.231582170","rc":[{"batb":[[0,1.96,43.53],[1,1.48,52.08],[2,1.43,58.14]],"ltp":2.0,"tv":80.0,"id":475559}]}]}
{"op":"mcm","clk":"11804623665","pt":1723241355133,"mc":[{"id":"1.231582170","rc":[{"batb":[[0,1.97,10],[1,1.96,43.53],[2,1.48,52.08]],"ltp":2.0,"tv":80.0,"id":475559}]}]}
{"op":"mcm","clk":"11804623754","pt":1723241358518,"mc":[{"id":"1.231582170","rc":[{"batb":[[0,1.96,43.53],[1,1.48,52.08],[2,1.43,58.14]],"ltp":2.0,"tv":80.0,"id":475559}]}]}
{"op":"mcm","clk":"11804623824","pt":1723241360832,"mc":[{"id":"1.231582170","rc":[{"batb":[[0,1.97,10],[1,1.96,43.53],[2,1.48,52.08]],"ltp":2.0,"tv":80.0,"id":475559}]}]}
{"op":"mcm","clk":"11804623894","pt":1723241364219,"mc":[{"id":"1.231582170","rc":[{"batb":[[0,1.96,43.53],[1,1.48,52.08],[2,1.43,58.14]],"ltp":2.0,"tv":80.0,"id":475559}]}]}
{"op":"mcm","clk":"11804623946","pt":1723241366628,"mc":[{"id":"1.231582170","rc":[{"batb":[[0,1.97,10],[1,1.96,43.53],[2,1.48,52.08]],"ltp":2.0,"tv":80.0,"id":475559}]}]}
{"op":"mcm","clk":"11804624018","pt":1723241369957,"mc":[{"id":"1.231582170","rc":[{"batb":[[0,1.96,43.53],[1,1.48,52.08],[2,1.43,58.14]],"ltp":2.0,"tv":80.0,"id":475559}]}]}
{"op":"mcm","clk":"11804624062","pt":1723241372362,"mc":[{"id":"1.231582170","rc":[{"batb":[[0,1.97,10],[1,1.96,43.53],[2,1.48,52.08]],"ltp":2.0,"tv":80.0,"id":475559}]}]}
{"op":"mcm","clk":"11804624127","pt":1723241375760,"mc":[{"id":"1.231582170","rc":[{"batb":[[0,1.96,43.53],[1,1.48,52.08],[2,1.43,58.14]],"ltp":2.0,"tv":80.0,"id":475559}]}]}
{"op":"mcm","clk":"11804624180","pt":1723241378163,"mc":[{"id":"1.231582170","rc":[{"batb":[[0,1.97,10],[1,1.96,43.53],[2,1.48,52.08]],"ltp":2.0,"tv":80.0,"id":475559}]}]}
{"op":"mcm","clk":"11804624255","pt":1723241381452,"mc":[{"id":"1.231582170","rc":[{"batb":[[0,1.96,43.53],[1,1.48,52.08],[2,1.43,58.14]],"ltp":2.0,"tv":80.0,"id":475559}]}]}
{"op":"mcm","clk":"11804624320","pt":1723241383959,"mc":[{"id":"1.231582170","rc":[{"batb":[[0,1.97,10],[1,1.96,43.53],[2,1.48,52.08]],"ltp":2.0,"tv":80.0,"id":475559}]}]}
{"op":"mcm","clk":"11804624430","pt":1723241387151,"mc":[{"id":"1.231582170","rc":[{"batb":[[0,1.96,43.53],[1,1.48,52.08],[2,1.43,58.14]],"ltp":2.0,"tv":80.0,"id":475559}]}]}
{"op":"mcm","clk":"11804624474","pt":1723241389762,"mc":[{"id":"1.231582170","rc":[{"batb":[[0,1.97,10],[1,1.96,43.53],[2,1.48,52.08]],"ltp":2.0,"tv":80.0,"id":475559}]}]}
{"op":"mcm","clk":"11804624569","pt":1723241393152,"mc":[{"id":"1.231582170","rc":[{"batb":[[0,1.96,43.53],[1,1.48,52.08],[2,1.43,58.14]],"ltp":2.0,"tv":80.0,"id":475559}]}]}
{"op":"mcm","clk":"11804624613","pt":1723241395671,"mc":[{"id":"1.231582170","rc":[{"batb":[[0,1.97,10],[1,1.96,43.53],[2,1.48,52.08]],"ltp":2.0,"tv":80.0,"id":475559}]}]}
{"op":"mcm","clk":"11804624681","pt":1723241398848,"mc":[{"id":"1.231582170","rc":[{"batb":[[0,1.96,43.53],[1,1.48,52.08],[2,1.43,58.14]],"ltp":2.0,"tv":80.0,"id":475559}]}]}
{"op":"mcm","clk":"11804624738","pt":1723241401663,"mc":[{"id":"1.231582170","rc":[{"batb":[[0,1.97,10],[1,1.96,43.53],[2,1.48,52.08]],"ltp":2.0,"tv":80.0,"id":475559}]}]}
{"op":"mcm","clk":"11804624806","pt":1723241404999,"mc":[{"id":"1.231582170","rc":[{"batb":[[0,1.96,43.53],[1,1.48,52.08],[2,1.43,58.14]],"ltp":2.0,"tv":80.0,"id":475559}]}]}
{"op":"mcm","clk":"11804624849","pt":1723241407268,"mc":[{"id":"1.231582170","rc":[{"batb":[[0,1.97,10],[1,1.96,43.53],[2,1.48,52.08]],"ltp":2.0,"tv":80.0,"id":475559}]}]}
{"op":"mcm","clk":"11804624916","pt":1723241410701,"mc":[{"id":"1.231582170","rc":[{"batb":[[0,1.96,43.53],[1,1.48,52.08],[2,1.43,58.14]],"ltp":2.0,"tv":80.0,"id":475559}]}]}
{"op":"mcm","clk":"11804625001","pt":1723241413583,"mc":[{"id":"1.231582170","rc":[{"batb":[[0,1.97,10],[1,1.96,43.53],[2,1.48,52.08]],"ltp":2.0,"tv":80.0,"id":475559}]}]}
{"op":"mcm","clk":"11804625056","pt":1723241416966,"mc":[{"id":"1.231582170","rc":[{"batb":[[0,1.96,43.53],[1,1.48,52.08],[2,1.43,58.14]],"ltp":2.0,"tv":80.0,"id":475559}]}]}
{"op":"mcm","clk":"11804625101","pt":1723241419380,"mc":[{"id":"1.231582170","rc":[{"batb":[[0,1.97,10],[1,1.96,43.53],[2,1.48,52.08]],"ltp":2.0,"tv":80.0,"id":475559}]}]}
{"op":"mcm","clk":"11804625160","pt":1723241422609,"mc":[{"id":"1.231582170","rc":[{"batb":[[0,1.96,43.53],[1,1.48,52.08],[2,1.43,58.14]],"ltp":2.0,"tv":80.0,"id":475559}]}]}
{"op":"mcm","clk":"11804625224","pt":1723241426002,"mc":[{"id":"1.231582170","rc":[{"batb":[[0,1.97,10],[1,1.96,43.53],[2,1.48,52.08]],"ltp":2.0,"tv":80.0,"id":475559}]}]}
{"op":"mcm","clk":"11804625295","pt":1723241429174,"mc":[{"id":"1.231582170","rc":[{"batb":[[0,1.96,43.53],[1,1.48,52.08],[2,1.43,58.14]],"ltp":2.0,"tv":80.0,"id":475559}]}]}
{"op":"mcm","clk":"11804625337","pt":1723241432318,"mc":[{"id":"1.231582170","rc":[{"batb":[[0,1.97,10],[1,1.96,43.53],[2,1.48,52.08]],"ltp":2.0,"tv":80.0,"id":475559}]}]}
{"op":"mcm","clk":"11804625392","pt":1723241435509,"mc":[{"id":"1.231582170","rc":[{"batb":[[0,1.96,43.53],[1,1.48,52.08],[2,1.43,58.14]],"ltp":2.0,"tv":80.0,"id":475559}]}]}
{"op":"mcm","clk":"11804625431","pt":1723241438023,"mc":[{"id":"1.231582170","rc":[{"batb":[[0,1.97,10],[1,1.96,43.53],[2,1.48,52.08]],"ltp":2.0,"tv":80.0,"id":475559}]}]}
{"op":"mcm","clk":"11804625519","pt":1723241441298,"mc":[{"id":"1.231582170","rc":[{"batb":[[0,1.96,43.53],[1,1.48,52.08],[2,1.43,58.14]],"ltp":2.0,"tv":80.0,"id":475559}]}]}
{"op":"mcm","clk":"11804625564","pt":1723241443415,"mc":[{"id":"1.231582170","rc":[{"batb":[[0,1.97,10],[1,1.96,43.53],[2,1.48,52.08]],"ltp":2.0,"tv":80.0,"id":475559}]}]}
{"op":"mcm","clk":"11804625623","pt":1723241446815,"mc":[{"id":"1.231582170","rc":[{"batb":[[0,1.96,43.53],[1,1.48,52.08],[2,1.43,58.14]],"ltp":2.0,"tv":80.0,"id":475559}]}]}
{"op":"mcm","clk":"11804625709","pt":1723241450309,"mc":[{"id":"1.231582170","rc":[{"batb":[[0,1.97,10],[1,1.96,43.53],[2,1.48,52.08]],"ltp":2.0,"tv":80.0,"id":475559}]}]}
{"op":"mcm","clk":"11804625779","pt":1723241453841,"mc":[{"id":"1.231582170","rc":[{"batb":[[0,1.96,43.53],[1,1.48,52.08],[2,1.43,58.14]],"ltp":2.0,"tv":80.0,"id":475559}]}]}
{"op":"mcm","clk":"11804625830","pt":1723241457434,"mc":[{"id":"1.231582170","rc":[{"batb":[[0,1.97,10],[1,1.96,43.53],[2,1.48,52.08]],"ltp":2.0,"tv":80.0,"id":475559}]}]}
{"op":"mcm","clk":"11804625889","pt":1723241460812,"mc":[{"id":"1.231582170","rc":[{"batb":[[0,1.96,43.53],[1,1.48,52.08],[2,1.43,58.14]],"ltp":2.0,"tv":80.0,"id":475559}]}]}
{"op":"mcm","clk":"11804625923","pt":1723241463333,"mc":[{"id":"1.231582170","rc":[{"batb":[[0,1.97,10],[1,1.96,43.53],[2,1.48,52.08]],"ltp":2.0,"tv":80.0,"id":475559}]}]}
{"op":"mcm","clk":"11804625978","pt":1723241466917,"mc":[{"id":"1.231582170","rc":[{"batb":[[0,1.96,43.53],[1,1.48,52.08],[2,1.43,58.14]],"ltp":2.0,"tv":80.0,"id":475559}]}]}
{"op":"mcm","clk":"11804626042","pt":1723241470661,"mc":[{"id":"1.231582170","rc":[{"batb":[[0,1.97,10],[1,1.96,43.53],[2,1.48,52.08]],"ltp":2.0,"tv":80.0,"id":475559}]}]}
{"op":"mcm","clk":"11804626109","pt":1723241474054,"mc":[{"id":"1.231582170","rc":[{"batb":[[0,1.96,43.53],[1,1.48,52.08],[2,1.43,58.14]],"ltp":2.0,"tv":80.0,"id":475559}]}]}
{"op":"mcm","clk":"11804626160","pt":1723241476262,"mc":[{"id":"1.231582170","rc":[{"batb":[[0,1.97,10],[1,1.96,43.53],[2,1.48,52.08]],"ltp":2.0,"tv":80.0,"id":475559}]}]}
{"op":"mcm","clk":"11804626205","pt":1723241479564,"mc":[{"id":"1.231582170","rc":[{"batb":[[0,1.96,43.53],[1,1.48,52.08],[2,1.43,58.14]],"ltp":2.0,"tv":80.0,"id":475559}]}]}
{"op":"mcm","clk":"11804626243","pt":1723241481973,"mc":[{"id":"1.231582170","rc":[{"batb":[[0,1.97,10],[1,1.96,43.53],[2,1.48,52.08]],"ltp":2.0,"tv":80.0,"id":475559}]}]}
{"op":"mcm","clk":"11804626324","pt":1723241485261,"mc":[{"id":"1.231582170","rc":[{"batb":[[0,1.96,43.53],[1,1.48,52.08],[2,1.43,58.14]],"ltp":2.0,"tv":80.0,"id":475559}]}]}
{"op":"mcm","clk":"11804626382","pt":1723241488955,"mc":[{"id":"1.231582170","rc":[{"batb":[[0,1.97,10],[1,1.96,43.53],[2,1.48,52.08]],"ltp":2.0,"tv":80.0,"id":475559}]}]}
{"op":"mcm","clk":"11804626464","pt":1723241492290,"mc":[{"id":"1.231582170","rc":[{"batb":[[0,1.96,43.53],[1,1.48,52.08],[2,1.43,58.14]],"ltp":2.0,"tv":80.0,"id":475559}]}]}
{"op":"mcm","clk":"11804626531","pt":1723241495363,"mc":[{"id":"1.231582170","rc":[{"batb":[[0,1.97,10],[1,1.96,43.53],[2,1.48,52.08]],"ltp":2.0,"tv":80.0,"id":475559}]}]}
{"op":"mcm","clk":"11804626575","pt":1723241498696,"mc":[{"id":"1.231582170","rc":[{"batb":[[0,1.96,43.53],[1,1.48,52.08],[2,1.43,58.14]],"ltp":2.0,"tv":80.0,"id":475559}]}]}
{"op":"mcm","clk":"11804626629","pt":1723241501690,"mc":[{"id":"1.231582170","rc":[{"batb":[[0,1.97,10],[1,1.96,43.53],[2,1.48,52.08]],"ltp":2.0,"tv":80.0,"id":475559}]}]}
{"op":"mcm","clk":"11804626672","pt":1723241505172,"mc":[{"id":"1.231582170","rc":[{"batb":[[0,1.96,43.53],[1,1.48,52.08],[2,1.43,58.14]],"ltp":2.0,"tv":80.0,"id":475559}]}]}
{"op":"mcm","clk":"11804626714","pt":1723241508401,"mc":[{"id":"1.231582170","rc":[{"batb":[[0,1.97,10],[1,1.96,43.53],[2,1.48,52.08]],"ltp":2.0,"tv":80.0,"id":475559}]}]}
{"op":"mcm","clk":"11804626761","pt":1723241511698,"mc":[{"id":"1.231582170","rc":[{"batb":[[0,1.96,43.53],[1,1.48,52.08],[2,1.43,58.14]],"ltp":2.0,"tv":80.0,"id":475559}]}]}
{"op":"mcm","clk":"11804626816","pt":1723241514575,"mc":[{"id":"1.231582170","rc":[{"batb":[[0,1.97,10],[1,1.96,43.53],[2,1.48,52.08]],"ltp":2.0,"tv":80.0,"id":475559}]}]}
{"op":"mcm","clk":"11804626885","pt":1723241518103,"mc":[{"id":"1.231582170","rc":[{"batb":[[0,1.96,43.53],[1,1.48,52.08],[2,1.43,58.14]],"ltp":2.0,"tv":80.0,"id":475559}]}]}
{"op":"mcm","clk":"11804626937","pt":1723241521590,"mc":[{"id":"1.231582170","rc":[{"batb":[[0,1.97,10],[1,1.96,43.53],[2,1.48,52.08]],"ltp":2.0,"tv":80.0,"id":475559}]}]}
{"op":"mcm","clk":"11804626994","pt":1723241525123,"mc":[{"id":"1.231582170","rc":[{"batb":[[0,1.96,43.53],[1,1.48,52.08],[2,1.43,58.14]],"ltp":2.0,"tv":80.0,"id":475559}]}]}
{"op":"mcm","clk":"11804627062","pt":1723241528000,"mc":[{"id":"1.231582170","rc":[{"batb":[[0,1.97,10],[1,1.96,43.53],[2,1.48,52.08]],"ltp":2.0,"tv":80.0,"id":475559}]}]}
{"op":"mcm","clk":"11804627147","pt":1723241531288,"mc":[{"id":"1.231582170","rc":[{"batb":[[0,1.96,43.53],[1,1.48,52.08],[2,1.43,58.14]],"ltp":2.0,"tv":80.0,"id":475559}]}]}
{"op":"mcm","clk":"11804627209","pt":1723241533700,"mc":[{"id":"1.231582170","rc":[{"batb":[[0,1.97,10],[1,1.96,43.53],[2,1.48,52.08]],"ltp":2.0,"tv":80.0,"id":475559}]}]}
{"op":"mcm","clk":"11804627274","pt":1723241537232,"mc":[{"id":"1.231582170","rc":[{"batb":[[0,1.96,43.53],[1,1.48,52.08],[2,1.43,58.14]],"ltp":2.0,"tv":80.0,"id":475559}]}]}
{"op":"mcm","clk":"11804627325","pt":1723241539808,"mc":[{"id":"1.231582170","rc":[{"batb":[[0,1.97,10],[1,1.96,43.53],[2,1.48,52.08]],"ltp":2.0,"tv":80.0,"id":475559}]}]}
{"op":"mcm","clk":"11804627386","pt":1723241543192,"mc":[{"id":"1.231582170","rc":[{"batb":[[0,1.96,43.53],[1,1.48,52.08],[2,1.43,58.14]],"ltp":2.0,"tv":80.0,"id":475559}]}]}
{"op":"mcm","clk":"11804627451","pt":1723241546935,"mc":[{"id":"1.231582170","rc":[{"batb":[[0,1.97,10],[1,1.96,43.53],[2,1.48,52.08]],"ltp":2.0,"tv":80.0,"id":475559}]}]}
{"op":"mcm","clk":"11804627531","pt":1723241550739,"mc":[{"id":"1.231582170","rc":[{"batb":[[0,1.96,43.53],[1,1.48,52.08],[2,1.43,58.14]],"ltp":2.0,"tv":80.0,"id":475559}]}]}
{"op":"mcm","clk":"11804627603","pt":1723241553916,"mc":[{"id":"1.231582170","rc":[{"batb":[[0,1.97,10],[1,1.96,43.53],[2,1.48,52.08]],"ltp":2.0,"tv":80.0,"id":475559}]}]}
{"op":"mcm","clk":"11804627663","pt":1723241557350,"mc":[{"id":"1.231582170","rc":[{"batb":[[0,1.96,43.53],[1,1.48,52.08],[2,1.43,58.14]],"ltp":2.0,"tv":80.0,"id":475559}]}]}
{"op":"mcm","clk":"11804627744","pt":1723241559919,"mc":[{"id":"1.231582170","rc":[{"batb":[[0,1.97,10],[1,1.96,43.53],[2,1.48,52.08]],"ltp":2.0,"tv":80.0,"id":475559}]}]}
{"op":"mcm","clk":"11804627811","pt":1723241563456,"mc":[{"id":"1.231582170","rc":[{"batb":[[0,1.96,43.53],[1,1.48,52.08],[2,1.43,58.14]],"ltp":2.0,"tv":80.0,"id":475559}]}]}
{"op":"mcm","clk":"11804627879","pt":1723241566637,"mc":[{"id":"1.231582170","rc":[{"batb":[[0,1.97,10],[1,1.96,43.53],[2,1.48,52.08]],"ltp":2.0,"tv":80.0,"id":475559}]}]}
{"op":"mcm","clk":"11804627969","pt":1723241570080,"mc":[{"id":"1.231582170","rc":[{"batb":[[0,1.96,43.53],[1,1.48,52.08],[2,1.43,58.14]],"ltp":2.0,"tv":80.0,"id":475559}]}]}
{"op":"mcm","clk":"11804628014","pt":1723241572439,"mc":[{"id":"1.231582170","rc":[{"batb":[[0,1.97,10],[1,1.96,43.53],[2,1.48,52.08]],"ltp":2.0,"tv":80.0,"id":475559}]}]}
{"op":"mcm","clk":"11804642122","pt":1723241575731,"mc":[{"id":"1.231582170","rc":[{"batb":[[0,1.96,43.53],[1,1.48,52.08],[2,1.43,58.14]],"ltp":2.0,"tv":80.0,"id":475559}]}]}
{"op":"mcm","clk":"11804642184","pt":1723241579475,"mc":[{"id":"1.231582170","rc":[{"batb":[[0,1.97,10],[1,1.96,43.53],[2,1.48,52.08]],"ltp":2.0,"tv":80.0,"id":475559}]}]}
{"op":"mcm","clk":"11804642246","pt":1723241582760,"mc":[{"id":"1.231582170","rc":[{"batb":[[0,1.96,43.53],[1,1.48,52.08],[2,1.43,58.14]],"ltp":2.0,"tv":80.0,"id":475559}]}]}
{"op":"mcm","clk":"11804642323","pt":1723241586050,"mc":[{"id":"1.231582170","rc":[{"batb":[[0,1.97,10],[1,1.96,43.53],[2,1.48,52.08]],"ltp":2.0,"tv":80.0,"id":475559}]}]}
{"op":"mcm","clk":"11804642405","pt":1723241589556,"mc":[{"id":"1.231582170","rc":[{"batb":[[0,1.96,43.53],[1,1.48,52.08],[2,1.43,58.14]],"ltp":2.0,"tv":80.0,"id":475559}]}]}
{"op":"mcm","clk":"11804642477","pt":1723241591868,"mc":[{"id":"1.231582170","rc":[{"batb":[[0,1.97,10],[1,1.96,43.53],[2,1.48,52.08]],"ltp":2.0,"tv":80.0,"id":475559}]}]}
{"op":"mcm","clk":"11804642549","pt":1723241595253,"mc":[{"id":"1.231582170","rc":[{"batb":[[0,1.96,43.53],[1,1.48,52.08],[2,1.43,58.14]],"ltp":2.0,"tv":80.0,"id":475559}]}]}
{"op":"mcm","clk":"11804642591","pt":1723241597980,"mc":[{"id":"1.231582170","rc":[{"batb":[[0,1.97,10],[1,1.96,43.53],[2,1.48,52.08]],"ltp":2.0,"tv":80.0,"id":475559}]}]}
{"op":"mcm","clk":"11804642650","pt":1723241601370,"mc":[{"id":"1.231582170","rc":[{"batb":[[0,1.96,43.53],[1,1.48,52.08],[2,1.43,58.14]],"ltp":2.0,"tv":80.0,"id":475559}]}]}
{"op":"mcm","clk":"11804642721","pt":1723241603884,"mc":[{"id":"1.231582170","rc":[{"batb":[[0,1.97,10],[1,1.96,43.53],[2,1.48,52.08]],"ltp":2.0,"tv":80.0,"id":475559}]}]}
{"op":"mcm","clk":"11804642781","pt":1723241607275,"mc":[{"id":"1.231582170","rc":[{"batb":[[0,1.96,43.53],[1,1.48,52.08],[2,1.43,58.14]],"ltp":2.0,"tv":80.0,"id":475559}]}]}
{"op":"mcm","clk":"11804642829","pt":1723241609589,"mc":[{"id":"1.231582170","rc":[{"batb":[[0,1.97,10],[1,1.96,43.53],[2,1.48,52.08]],"ltp":2.0,"tv":80.0,"id":475559}]}]}
{"op":"mcm","clk":"11804642913","pt":1723241613120,"mc":[{"id":"1.231582170","rc":[{"batb":[[0,1.96,43.53],[1,1.48,52.08],[2,1.43,58.14]],"ltp":2.0,"tv":80.0,"id":475559}]}]}
{"op":"mcm","clk":"11804642950","pt":1723241615379,"mc":[{"id":"1.231582170","rc":[{"batb":[[0,1.97,10],[1,1.96,43.53],[2,1.48,52.08]],"ltp":2.0,"tv":80.0,"id":475559}]}]}
{"op":"mcm","clk":"11804643008","pt":1723241618824,"mc":[{"id":"1.231582170","rc":[{"batb":[[0,1.96,43.53],[1,1.48,52.08],[2,1.43,58.14]],"ltp":2.0,"tv":80.0,"id":475559}]}]}
{"op":"mcm","clk":"11804643052","pt":1723241621284,"mc":[{"id":"1.231582170","rc":[{"batb":[[0,1.97,10],[1,1.96,43.53],[2,1.48,52.08]],"ltp":2.0,"tv":80.0,"id":475559}]}]}
{"op":"mcm","clk":"11804643120","pt":1723241624724,"mc":[{"id":"1.231582170","rc":[{"batb":[[0,1.96,43.53],[1,1.48,52.08],[2,1.43,58.14]],"ltp":2.0,"tv":80.0,"id":475559}]}]}
{"op":"mcm","clk":"11804643175","pt":1723241627194,"mc":[{"id":"1.231582170","rc":[{"batb":[[0,1.97,10],[1,1.96,43.53],[2,1.48,52.08]],"ltp":2.0,"tv":80.0,"id":475559}]}]}
{"op":"mcm","clk":"11804643330","pt":1723241630899,"mc":[{"id":"1.231582170","rc":[{"batb":[[0,1.96,43.53],[1,1.48,52.08],[2,1.43,58.14]],"ltp":2.0,"tv":80.0,"id":475559}]}]}
{"op":"mcm","clk":"11804643447","pt":1723241633529,"mc":[{"id":"1.231582170","rc":[{"batb":[[0,1.97,10],[1,1.96,43.53],[2,1.48,52.08]],"ltp":2.0,"tv":80.0,"id":475559}]}]}
{"op":"mcm","clk":"11804643506","pt":1723241637139,"mc":[{"id":"1.231582170","rc":[{"batb":[[0,1.96,43.53],[1,1.48,52.08],[2,1.43,58.14]],"ltp":2.0,"tv":80.0,"id":475559}]}]}
{"op":"mcm","clk":"11804643560","pt":1723241640428,"mc":[{"id":"1.231582170","rc":[{"batb":[[0,1.97,10],[1,1.96,43.53],[2,1.48,52.08]],"ltp":2.0,"tv":80.0,"id":475559}]}]}
{"op":"mcm","clk":"11804643610","pt":1723241643612,"mc":[{"id":"1.231582170","rc":[{"batb":[[0,1.96,43.53],[1,1.48,52.08],[2,1.43,58.14]],"ltp":2.0,"tv":80.0,"id":475559}]}]}
{"op":"mcm","clk":"11804643651","pt":1723241646125,"mc":[{"id":"1.231582170","rc":[{"batb":[[0,1.97,10],[1,1.96,43.53],[2,1.48,52.08]],"ltp":2.0,"tv":80.0,"id":475559}]}]}
{"op":"mcm","clk":"11804643699","pt":1723241649454,"mc":[{"id":"1.231582170","rc":[{"batb":[[0,1.96,43.53],[1,1.48,52.08],[2,1.43,58.14]],"ltp":2.0,"tv":80.0,"id":475559}]}]}
{"op":"mcm","clk":"11804643755","pt":1723241651961,"mc":[{"id":"1.231582170","rc":[{"batb":[[0,1.97,10],[1,1.96,43.53],[2,1.48,52.08]],"ltp":2.0,"tv":80.0,"id":475559}]}]}
{"op":"mcm","clk":"11804643844","pt":1723241655349,"mc":[{"id":"1.231582170","rc":[{"batb":[[0,1.96,43.53],[1,1.48,52.08],[2,1.43,58.14]],"ltp":2.0,"tv":80.0,"id":475559}]}]}
{"op":"mcm","clk":"11804643910","pt":1723241658060,"mc":[{"id":"1.231582170","rc":[{"batb":[[0,1.97,10],[1,1.96,43.53],[2,1.48,52.08]],"ltp":2.0,"tv":80.0,"id":475559}]}]}
{"op":"mcm","clk":"11804644004","pt":1723241661358,"mc":[{"id":"1.231582170","rc":[{"batb":[[0,1.96,43.53],[1,1.48,52.08],[2,1.43,58.14]],"ltp":2.0,"tv":80.0,"id":475559}]}]}
{"op":"mcm","clk":"11804644064","pt":1723241664175,"mc":[{"id":"1.231582170","rc":[{"batb":[[0,1.97,10],[1,1.96,43.53],[2,1.48,52.08]],"ltp":2.0,"tv":80.0,"id":475559}]}]}
{"op":"mcm","clk":"11804644133","pt":1723241667589,"mc":[{"id":"1.231582170","rc":[{"batb":[[0,1.96,43.53],[1,1.48,52.08],[2,1.43,58.14]],"ltp":2.0,"tv":80.0,"id":475559}]}]}
{"op":"mcm","clk":"11804644193","pt":1723241670660,"mc":[{"id":"1.231582170","rc":[{"batb":[[0,1.97,10],[1,1.96,43.53],[2,1.48,52.08]],"ltp":2.0,"tv":80.0,"id":475559}]}]}
{"op":"mcm","clk":"11804644249","pt":1723241673988,"mc":[{"id":"1.231582170","rc":[{"batb":[[0,1.96,43.53],[1,1.48,52.08],[2,1.43,58.14]],"ltp":2.0,"tv":80.0,"id":475559}]}]}
{"op":"mcm","clk":"11804644293","pt":1723241676566,"mc":[{"id":"1.231582170","rc":[{"batb":[[0,1.97,10],[1,1.96,43.53],[2,1.48,52.08]],"ltp":2.0,"tv":80.0,"id":475559}]}]}
{"op":"mcm","clk":"11804644356","pt":1723241679951,"mc":[{"id":"1.231582170","rc":[{"batb":[[0,1.96,43.53],[1,1.48,52.08],[2,1.43,58.14]],"ltp":2.0,"tv":80.0,"id":475559}]}]}
{"op":"mcm","clk":"11804644407","pt":1723241682265,"mc":[{"id":"1.231582170","rc":[{"batb":[[0,1.97,10],[1,1.96,43.53],[2,1.48,52.08]],"ltp":2.0,"tv":80.0,"id":475559}]}]}
{"op":"mcm","clk":"11804644500","pt":1723241685555,"mc":[{"id":"1.231582170","rc":[{"batb":[[0,1.96,43.53],[1,1.48,52.08],[2,1.43,58.14]],"ltp":2.0,"tv":80.0,"id":475559}]}]}
{"op":"mcm","clk":"11804644553","pt":1723241687967,"mc":[{"id":"1.231582170","rc":[{"batb":[[0,1.97,10],[1,1.96,43.53],[2,1.48,52.08]],"ltp":2.0,"tv":80.0,"id":475559}]}]}
{"op":"mcm","clk":"11804644633","pt":1723241691460,"mc":[{"id":"1.231582170","rc":[{"batb":[[0,1.96,43.53],[1,1.48,52.08],[2,1.43,58.14]],"ltp":2.0,"tv":80.0,"id":475559}]}]}
{"op":"mcm","clk":"11804644678","pt":1723241693774,"mc":[{"id":"1.231582170","rc":[{"batb":[[0,1.97,10],[1,1.96,43.53],[2,1.48,52.08]],"ltp":2.0,"tv":80.0,"id":475559}]}]}
{"op":"mcm","clk":"11804644722","pt":1723241697171,"mc":[{"id":"1.231582170","rc":[{"batb":[[0,1.96,43.53],[1,1.48,52.08],[2,1.43,58.14]],"ltp":2.0,"tv":80.0,"id":475559}]}]}
{"op":"mcm","clk":"11804644792","pt":1723241700612,"mc":[{"id":"1.231582170","rc":[{"batb":[[0,1.97,10],[1,1.96,43.53],[2,1.48,52.08]],"ltp":2.0,"tv":80.0,"id":475559}]}]}
{"op":"mcm","clk":"11804644877","pt":1723241704131,"mc":[{"id":"1.231582170","rc":[{"batb":[[0,1.96,43.53],[1,1.48,52.08],[2,1.43,58.14]],"ltp":2.0,"tv":80.0,"id":475559}]}]}
{"op":"mcm","clk":"11804644926","pt":1723241706388,"mc":[{"id":"1.231582170","rc":[{"batb":[[0,1.97,10],[1,1.96,43.53],[2,1.48,52.08]],"ltp":2.0,"tv":80.0,"id":475559}]}]}
{"op":"mcm","clk":"11804645022","pt":1723241709787,"mc":[{"id":"1.231582170","rc":[{"batb":[[0,1.96,43.53],[1,1.48,52.08],[2,1.43,58.14]],"ltp":2.0,"tv":80.0,"id":475559}]}]}
{"op":"mcm","clk":"11804645092","pt":1723241712202,"mc":[{"id":"1.231582170","rc":[{"batb":[[0,1.97,10],[1,1.96,43.53],[2,1.48,52.08]],"ltp":2.0,"tv":80.0,"id":475559}]}]}
{"op":"mcm","clk":"11804645185","pt":1723241715388,"mc":[{"id":"1.231582170","rc":[{"batb":[[0,1.96,43.53],[1,1.48,52.08],[2,1.43,58.14]],"ltp":2.0,"tv":80.0,"id":475559}]}]}
{"op":"mcm","clk":"11804645292","pt":1723241719391,"mc":[{"id":"1.231582170","rc":[{"batb":[[0,1.97,10],[1,1.96,43.53],[2,1.48,52.08]],"ltp":2.0,"tv":80.0,"id":475559}]}]}
{"op":"mcm","clk":"11804645360","pt":1723241722834,"mc":[{"id":"1.231582170","rc":[{"batb":[[0,1.96,43.53],[1,1.48,52.08],[2,1.43,58.14]],"ltp":2.0,"tv":80.0,"id":475559}]}]}
{"op":"mcm","clk":"11804645424","pt":1723241725340,"mc":[{"id":"1.231582170","rc":[{"batb":[[0,1.97,10],[1,1.96,43.53],[2,1.48,52.08]],"ltp":2.0,"tv":80.0,"id":475559}]}]}
{"op":"mcm","clk":"11804645507","pt":1723241728625,"mc":[{"id":"1.231582170","rc":[{"batb":[[0,1.96,43.53],[1,1.48,52.08],[2,1.43,58.14]],"ltp":2.0,"tv":80.0,"id":475559}]}]}
{"op":"mcm","clk":"11804645562","pt":1723241731542,"mc":[{"id":"1.231582170","rc":[{"batb":[[0,1.97,10],[1,1.96,43.53],[2,1.48,52.08]],"ltp":2.0,"tv":80.0,"id":475559}]}]}
{"op":"mcm","clk":"11804645628","pt":1723241735125,"mc":[{"id":"1.231582170","rc":[{"batb":[[0,1.96,43.53],[1,1.48,52.08],[2,1.43,58.14]],"ltp":2.0,"tv":80.0,"id":475559}]}]}
{"op":"mcm","clk":"11804645670","pt":1723241737430,"mc":[{"id":"1.231582170","rc":[{"batb":[[0,1.97,10],[1,1.96,43.53],[2,1.48,52.08]],"ltp":2.0,"tv":80.0,"id":475559}]}]}
{"op":"mcm","clk":"11804645758","pt":1723241740770,"mc":[{"id":"1.231582170","rc":[{"batb":[[0,1.96,43.53],[1,1.48,52.08],[2,1.43,58.14]],"ltp":2.0,"tv":80.0,"id":475559}]}]}
{"op":"mcm","clk":"11804645821","pt":1723241743222,"mc":[{"id":"1.231582170","rc":[{"batb":[[0,1.97,10],[1,1.96,43.53],[2,1.48,52.08]],"ltp":2.0,"tv":80.0,"id":475559}]}]}
{"op":"mcm","clk":"11804645902","pt":1723241746769,"mc":[{"id":"1.231582170","rc":[{"batb":[[0,1.96,43.53],[1,1.48,52.08],[2,1.43,58.14]],"ltp":2.0,"tv":80.0,"id":475559}]}]}
{"op":"mcm","clk":"11804645952","pt":1723241749269,"mc":[{"id":"1.231582170","rc":[{"batb":[[0,1.97,10],[1,1.96,43.53],[2,1.48,52.08]],"ltp":2.0,"tv":80.0,"id":475559}]}]}
{"op":"mcm","clk":"11804646028","pt":1723241752751,"mc":[{"id":"1.231582170","rc":[{"batb":[[0,1.96,43.53],[1,1.48,52.08],[2,1.43,58.14]],"ltp":2.0,"tv":80.0,"id":475559}]}]}
{"op":"mcm","clk":"11804646056","pt":1723241754951,"mc":[{"id":"1.231582170","rc":[{"batb":[[0,1.97,10],[1,1.96,43.53],[2,1.48,52.08]],"ltp":2.0,"tv":80.0,"id":475559}]}]}
{"op":"mcm","clk":"11804646114","pt":1723241758234,"mc":[{"id":"1.231582170","rc":[{"batb":[[0,1.96,43.53],[1,1.48,52.08],[2,1.43,58.14]],"ltp":2.0,"tv":80.0,"id":475559}]}]}
{"op":"mcm","clk":"11804646191","pt":1723241761665,"mc":[{"id":"1.231582170","rc":[{"batb":[[0,1.97,10],[1,1.96,43.53],[2,1.48,52.08]],"ltp":2.0,"tv":80.0,"id":475559}]}]}
{"op":"mcm","clk":"11804646253","pt":1723241765156,"mc":[{"id":"1.231582170","rc":[{"batb":[[0,1.96,43.53],[1,1.48,52.08],[2,1.43,58.14]],"ltp":2.0,"tv":80.0,"id":475559}]}]}
{"op":"mcm","clk":"11804646308","pt":1723241767460,"mc":[{"id":"1.231582170","rc":[{"batb":[[0,1.97,10],[1,1.96,43.53],[2,1.48,52.08]],"ltp":2.0,"tv":80.0,"id":475559}]}]}
{"op":"mcm","clk":"11804646409","pt":1723241770800,"mc":[{"id":"1.231582170","rc":[{"batb":[[0,1.96,43.53],[1,1.48,52.08],[2,1.43,58.14]],"ltp":2.0,"tv":80.0,"id":475559}]}]}
{"op":"mcm","clk":"11804646469","pt":1723241773099,"mc":[{"id":"1.231582170","rc":[{"batb":[[0,1.97,10],[1,1.96,43.53],[2,1.48,52.08]],"ltp":2.0,"tv":80.0,"id":475559}]}]}
{"op":"mcm","clk":"11804646554","pt":1723241776480,"mc":[{"id":"1.231582170","rc":[{"batb":[[0,1.96,43.53],[1,1.48,52.08],[2,1.43,58.14]],"ltp":2.0,"tv":80.0,"id":475559}]}]}
{"op":"mcm","clk":"11804646601","pt":1723241778890,"mc":[{"id":"1.231582170","rc":[{"batb":[[0,1.97,10],[1,1.96,43.53],[2,1.48,52.08]],"ltp":2.0,"tv":80.0,"id":475559}]}]}
{"op":"mcm","clk":"11804646670","pt":1723241782177,"mc":[{"id":"1.231582170","rc":[{"batb":[[0,1.96,43.53],[1,1.48,52.08],[2,1.43,58.14]],"ltp":2.0,"tv":80.0,"id":475559}]}]}
{"op":"mcm","clk":"11804646757","pt":1723241786294,"mc":[{"id":"1.231582170","rc":[{"batb":[[0,1.97,10],[1,1.96,43.53],[2,1.48,52.08]],"ltp":2.0,"tv":80.0,"id":475559}]}]}
{"op":"mcm","clk":"11804646824","pt":1723241789613,"mc":[{"id":"1.231582170","rc":[{"batb":[[0,1.96,43.53],[1,1.48,52.08],[2,1.43,58.14]],"ltp":2.0,"tv":80.0,"id":475559}]}]}
{"op":"mcm","clk":"11804646878","pt":1723241791778,"mc":[{"id":"1.231582170","rc":[{"batb":[[0,1.97,10],[1,1.96,43.53],[2,1.48,52.08]],"ltp":2.0,"tv":80.0,"id":475559}]}]}
{"op":"mcm","clk":"11804646937","pt":1723241795104,"mc":[{"id":"1.231582170","rc":[{"batb":[[0,1.96,43.53],[1,1.48,52.08],[2,1.43,58.14]],"ltp":2.0,"tv":80.0,"id":475559}]}]}
{"op":"mcm","clk":"11804646992","pt":1723241797720,"mc":[{"id":"1.231582170","rc":[{"batb":[[0,1.97,10],[1,1.96,43.53],[2,1.48,52.08]],"ltp":2.0,"tv":80.0,"id":475559}]}]}
{"op":"mcm","clk":"11804647061","pt":1723241801098,"mc":[{"id":"1.231582170","rc":[{"batb":[[0,1.96,43.53],[1,1.48,52.08],[2,1.43,58.14]],"ltp":2.0,"tv":80.0,"id":475559}]}]}
{"op":"mcm","clk":"11804647125","pt":1723241803501,"mc":[{"id":"1.231582170","rc":[{"batb":[[0,1.97,10],[1,1.96,43.53],[2,1.48,52.08]],"ltp":2.0,"tv":80.0,"id":475559}]}]}
{"op":"mcm","clk":"11804647187","pt":1723241806837,"mc":[{"id":"1.231582170","rc":[{"batb":[[0,1.96,43.53],[1,1.48,52.08],[2,1.43,58.14]],"ltp":2.0,"tv":80.0,"id":475559}]}]}
{"op":"mcm","clk":"11804647222","pt":1723241809298,"mc":[{"id":"1.231582170","rc":[{"batb":[[0,1.97,10],[1,1.96,43.53],[2,1.48,52.08]],"ltp":2.0,"tv":80.0,"id":475559}]}]}
{"op":"mcm","clk":"11804647284","pt":1723241812697,"mc":[{"id":"1.231582170","rc":[{"batb":[[0,1.96,43.53],[1,1.48,52.08],[2,1.43,58.14]],"ltp":2.0,"tv":80.0,"id":475559}]}]}
{"op":"mcm","clk":"11804647336","pt":1723241815308,"mc":[{"id":"1.231582170","rc":[{"batb":[[0,1.97,10],[1,1.96,43.53],[2,1.48,52.08]],"ltp":2.0,"tv":80.0,"id":475559}]}]}
{"op":"mcm","clk":"11804647407","pt":1723241818795,"mc":[{"id":"1.231582170","rc":[{"batb":[[0,1.96,43.53],[1,1.48,52.08],[2,1.43,58.14]],"ltp":2.0,"tv":80.0,"id":475559}]}]}
{"op":"mcm","clk":"11804647495","pt":1723241822025,"mc":[{"id":"1.231582170","rc":[{"batb":[[0,1.97,10],[1,1.96,43.53],[2,1.48,52.08]],"ltp":2.0,"tv":80.0,"id":475559}]}]}
{"op":"mcm","clk":"11804647563","pt":1723241825319,"mc":[{"id":"1.231582170","rc":[{"batb":[[0,1.96,43.53],[1,1.48,52.08],[2,1.43,58.14]],"ltp":2.0,"tv":80.0,"id":475559}]}]}
{"op":"mcm","clk":"11804647623","pt":1723241828598,"mc":[{"id":"1.231582170","rc":[{"batb":[[0,1.97,10],[1,1.96,43.53],[2,1.48,52.08]],"ltp":2.0,"tv":80.0,"id":475559}]}]}
{"op":"mcm","clk":"11804647698","pt":1723241831929,"mc":[{"id":"1.231582170","rc":[{"batb":[[0,1.96,43.53],[1,1.48,52.08],[2,1.43,58.14]],"ltp":2.0,"tv":80.0,"id":475559}]}]}
{"op":"mcm","clk":"11804647765","pt":1723241834549,"mc":[{"id":"1.231582170","rc":[{"batb":[[0,1.97,10],[1,1.96,43.53],[2,1.48,52.08]],"ltp":2.0,"tv":80.0,"id":475559}]}]}
{"op":"mcm","clk":"11804647835","pt":1723241838037,"mc":[{"id":"1.231582170","rc":[{"batb":[[0,1.96,43.53],[1,1.48,52.08],[2,1.43,58.14]],"ltp":2.0,"tv":80.0,"id":475559}]}]}
{"op":"mcm","clk":"11804647913","pt":1723241840866,"mc":[{"id":"1.231582170","rc":[{"batb":[[0,1.97,10],[1,1.96,43.53],[2,1.48,52.08]],"ltp":2.0,"tv":80.0,"id":475559}]}]}
{"op":"mcm","clk":"11804647996","pt":1723241844220,"mc":[{"id":"1.231582170","rc":[{"batb":[[0,1.96,43.53],[1,1.48,52.08],[2,1.43,58.14]],"ltp":2.0,"tv":80.0,"id":475559}]}]}
{"op":"mcm","clk":"11804648078","pt":1723241847561,"mc":[{"id":"1.231582170","rc":[{"batb":[[0,1.97,10],[1,1.96,43.53],[2,1.48,52.08]],"ltp":2.0,"tv":80.0,"id":475559}]}]}
{"op":"mcm","clk":"11804648145","pt":1723241850846,"mc":[{"id":"1.231582170","rc":[{"batb":[[0,1.96,43.53],[1,1.48,52.08],[2,1.43,58.14]],"ltp":2.0,"tv":80.0,"id":475559}]}]}
{"op":"mcm","clk":"11804648193","pt":1723241853571,"mc":[{"id":"1.231582170","rc":[{"batb":[[0,1.97,10],[1,1.96,43.53],[2,1.48,52.08]],"ltp":2.0,"tv":80.0,"id":475559}]}]}
{"op":"mcm","clk":"11804648283","pt":1723241856978,"mc":[{"id":"1.231582170","rc":[{"batb":[[0,1.96,43.53],[1,1.48,52.08],[2,1.43,58.14]],"ltp":2.0,"tv":80.0,"id":475559}]}]}
{"op":"mcm","clk":"11804648348","pt":1723241859637,"mc":[{"id":"1.231582170","rc":[{"batb":[[0,1.97,10],[1,1.96,43.53],[2,1.48,52.08]],"ltp":2.0,"tv":80.0,"id":475559}]}]}
{"op":"mcm","clk":"11804648416","pt":1723241862980,"mc":[{"id":"1.231582170","rc":[{"batb":[[0,1.96,43.53],[1,1.48,52.08],[2,1.43,58.14]],"ltp":2.0,"tv":80.0,"id":475559}]}]}
{"op":"mcm","clk":"11804648462","pt":1723241865342,"mc":[{"id":"1.231582170","rc":[{"batb":[[0,1.97,10],[1,1.96,43.53],[2,1.48,52.08]],"ltp":2.0,"tv":80.0,"id":475559}]}]}
{"op":"mcm","clk":"11804648516","pt":1723241868682,"mc":[{"id":"1.231582170","rc":[{"batb":[[0,1.96,43.53],[1,1.48,52.08],[2,1.43,58.14]],"ltp":2.0,"tv":80.0,"id":475559}]}]}
{"op":"mcm","clk":"11804648594","pt":1723241871971,"mc":[{"id":"1.231582170","rc":[{"batb":[[0,1.97,10],[1,1.96,43.53],[2,1.48,52.08]],"ltp":2.0,"tv":80.0,"id":475559}]}]}
{"op":"mcm","clk":"11804648665","pt":1723241875665,"mc":[{"id":"1.231582170","rc":[{"batb":[[0,1.96,43.53],[1,1.48,52.08],[2,1.43,58.14]],"ltp":2.0,"tv":80.0,"id":475559}]}]}
{"op":"mcm","clk":"11804648715","pt":1723241878279,"mc":[{"id":"1.231582170","rc":[{"batb":[[0,1.97,10],[1,1.96,43.53],[2,1.48,52.08]],"ltp":2.0,"tv":80.0,"id":475559}]}]}
{"op":"mcm","clk":"11804648790","pt":1723241881563,"mc":[{"id":"1.231582170","rc":[{"batb":[[0,1.96,43.53],[1,1.48,52.08],[2,1.43,58.14]],"ltp":2.0,"tv":80.0,"id":475559}]}]}
{"op":"mcm","clk":"11804648854","pt":1723241884186,"mc":[{"id":"1.231582170","rc":[{"batb":[[0,1.97,10],[1,1.96,43.53],[2,1.48,52.08]],"ltp":2.0,"tv":80.0,"id":475559}]}]}
{"op":"mcm","clk":"11804648949","pt":1723241887575,"mc":[{"id":"1.231582170","rc":[{"batb":[[0,1.96,43.53],[1,1.48,52.08],[2,1.43,58.14]],"ltp":2.0,"tv":80.0,"id":475559}]}]}
{"op":"mcm","clk":"11804649017","pt":1723241890498,"mc":[{"id":"1.231582170","rc":[{"batb":[[0,1.97,10],[1,1.96,43.53],[2,1.48,52.08]],"ltp":2.0,"tv":80.0,"id":475559}]}]}
{"op":"mcm","clk":"11804649084","pt":1723241893897,"mc":[{"id":"1.231582170","rc":[{"batb":[[0,1.96,43.53],[1,1.48,52.08],[2,1.43,58.14]],"ltp":2.0,"tv":80.0,"id":475559}]}]}
{"op":"mcm","clk":"11804649175","pt":1723241897586,"mc":[{"id":"1.231582170","rc":[{"batb":[[0,1.97,10],[1,1.96,43.53],[2,1.48,52.08]],"ltp":2.0,"tv":80.0,"id":475559}]}]}
{"op":"mcm","clk":"11804649237","pt":1723241901081,"mc":[{"id":"1.231582170","rc":[{"batb":[[0,1.96,43.53],[1,1.48,52.08],[2,1.43,58.14]],"ltp":2.0,"tv":80.0,"id":475559}]}]}
{"op":"mcm","clk":"11804649299","pt":1723241904114,"mc":[{"id":"1.231582170","rc":[{"batb":[[0,1.97,10],[1,1.96,43.53],[2,1.48,52.08]],"ltp":2.0,"tv":80.0,"id":475559}]}]}
{"op":"mcm","clk":"11804649373","pt":1723241907599,"mc":[{"id":"1.231582170","rc":[{"batb":[[0,1.96,43.53],[1,1.48,52.08],[2,1.43,58.14]],"ltp":2.0,"tv":80.0,"id":475559}]}]}
{"op":"mcm","clk":"11804649414","pt":1723241909914,"mc":[{"id":"1.231582170","rc":[{"batb":[[0,1.97,10],[1,1.96,43.53],[2,1.48,52.08]],"ltp":2.0,"tv":80.0,"id":475559}]}]}
{"op":"mcm","clk":"11804649469","pt":1723241913403,"mc":[{"id":"1.231582170","rc":[{"batb":[[0,1.96,43.53],[1,1.48,52.08],[2,1.43,58.14]],"ltp":2.0,"tv":80.0,"id":475559}]}]}
{"op":"mcm","clk":"11804649535","pt":1723241915992,"mc":[{"id":"1.231582170","rc":[{"batb":[[0,1.97,10],[1,1.96,43.53],[2,1.48,52.08]],"ltp":2.0,"tv":80.0,"id":475559}]}]}
{"op":"mcm","clk":"11804649655","pt":1723241919325,"mc":[{"id":"1.231582170","rc":[{"batb":[[0,1.96,43.53],[1,1.48,52.08],[2,1.43,58.14]],"ltp":2.0,"tv":80.0,"id":475559}]}]}
{"op":"mcm","clk":"11804649726","pt":1723241921699,"mc":[{"id":"1.231582170","rc":[{"batb":[[0,1.97,10],[1,1.96,43.53],[2,1.48,52.08]],"ltp":2.0,"tv":80.0,"id":475559}]}]}
{"op":"mcm","clk":"11804649796","pt":1723241924928,"mc":[{"id":"1.231582170","rc":[{"batb":[[0,1.96,43.53],[1,1.48,52.08],[2,1.43,58.14]],"ltp":2.0,"tv":80.0,"id":475559}]}]}
{"op":"mcm","clk":"11804649890","pt":1723241927625,"mc":[{"id":"1.231582170","rc":[{"batb":[[0,1.97,10],[1,1.96,43.53],[2,1.48,52.08]],"ltp":2.0,"tv":80.0,"id":475559}]}]}
{"op":"mcm","clk":"11804650277","pt":1723241930951,"mc":[{"id":"1.231582170","rc":[{"batb":[[0,1.96,43.53],[1,1.48,52.08],[2,1.43,58.14]],"ltp":2.0,"tv":80.0,"id":475559}]}]}
{"op":"mcm","clk":"11804650394","pt":1723241934289,"mc":[{"id":"1.231582170","rc":[{"batb":[[0,1.97,10],[1,1.96,43.53],[2,1.48,52.08]],"ltp":2.0,"tv":80.0,"id":475559}]}]}
{"op":"mcm","clk":"11804650510","pt":1723241937496,"mc":[{"id":"1.231582170","rc":[{"batb":[[0,1.96,43.53],[1,1.48,52.08],[2,1.43,58.14]],"ltp":2.0,"tv":80.0,"id":475559}]}]}
{"op":"mcm","clk":"11804650563","pt":1723241939907,"mc":[{"id":"1.231582170","rc":[{"batb":[[0,1.97,10],[1,1.96,43.53],[2,1.48,52.08]],"ltp":2.0,"tv":80.0,"id":475559}]}]}
{"op":"mcm","clk":"11804650633","pt":1723241943305,"mc":[{"id":"1.231582170","rc":[{"batb":[[0,1.96,43.53],[1,1.48,52.08],[2,1.43,58.14]],"ltp":2.0,"tv":80.0,"id":475559}]}]}
{"op":"mcm","clk":"11804650717","pt":1723241945791,"mc":[{"id":"1.231582170","rc":[{"batb":[[0,1.97,10],[1,1.96,43.53],[2,1.48,52.08]],"ltp":2.0,"tv":80.0,"id":475559}]}]}
{"op":"mcm","clk":"11804650818","pt":1723241949188,"mc":[{"id":"1.231582170","rc":[{"batb":[[0,1.96,43.53],[1,1.48,52.08],[2,1.43,58.14]],"ltp":2.0,"tv":80.0,"id":475559}]}]}
{"op":"mcm","clk":"11804650872","pt":1723241951502,"mc":[{"id":"1.231582170","rc":[{"batb":[[0,1.97,10],[1,1.96,43.53],[2,1.48,52.08]],"ltp":2.0,"tv":80.0,"id":475559}]}]}
{"op":"mcm","clk":"11804650958","pt":1723241954899,"mc":[{"id":"1.231582170","rc":[{"batb":[[0,1.96,43.53],[1,1.48,52.08],[2,1.43,58.14]],"ltp":2.0,"tv":80.0,"id":475559}]}]}
{"op":"mcm","clk":"11804651024","pt":1723241958507,"mc":[{"id":"1.231582170","rc":[{"batb":[[0,1.97,10],[1,1.96,43.53],[2,1.48,52.08]],"ltp":2.0,"tv":80.0,"id":475559}]}]}
{"op":"mcm","clk":"11804651095","pt":1723241961909,"mc":[{"id":"1.231582170","rc":[{"batb":[[0,1.96,43.53],[1,1.48,52.08],[2,1.43,58.14]],"ltp":2.0,"tv":80.0,"id":475559}]}]}
{"op":"mcm","clk":"11804651146","pt":1723241964442,"mc":[{"id":"1.231582170","rc":[{"batb":[[0,1.97,10],[1,1.96,43.53],[2,1.48,52.08]],"ltp":2.0,"tv":80.0,"id":475559}]}]}
{"op":"mcm","clk":"11804651204","pt":1723241967842,"mc":[{"id":"1.231582170","rc":[{"batb":[[0,1.96,43.53],[1,1.48,52.08],[2,1.43,58.14]],"ltp":2.0,"tv":80.0,"id":475559}]}]}
{"op":"mcm","clk":"11804651257","pt":1723241970727,"mc":[{"id":"1.231582170","rc":[{"batb":[[0,1.97,10],[1,1.96,43.53],[2,1.48,52.08]],"ltp":2.0,"tv":80.0,"id":475559}]}]}
{"op":"mcm","clk":"11804651332","pt":1723241974121,"mc":[{"id":"1.231582170","rc":[{"batb":[[0,1.96,43.53],[1,1.48,52.08],[2,1.43,58.14]],"ltp":2.0,"tv":80.0,"id":475559}]}]}
{"op":"mcm","clk":"11804651378","pt":1723241976539,"mc":[{"id":"1.231582170","rc":[{"batb":[[0,1.97,10],[1,1.96,43.53],[2,1.48,52.08]],"ltp":2.0,"tv":80.0,"id":475559}]}]}
{"op":"mcm","clk":"11804651456","pt":1723241979932,"mc":[{"id":"1.231582170","rc":[{"batb":[[0,1.96,43.53],[1,1.48,52.08],[2,1.43,58.14]],"ltp":2.0,"tv":80.0,"id":475559}]}]}
{"op":"mcm","clk":"11804651524","pt":1723241982453,"mc":[{"id":"1.231582170","rc":[{"batb":[[0,1.97,10],[1,1.96,43.53],[2,1.48,52.08]],"ltp":2.0,"tv":80.0,"id":475559}]}]}
{"op":"mcm","clk":"11804651613","pt":1723241985939,"mc":[{"id":"1.231582170","rc":[{"batb":[[0,1.96,43.53],[1,1.48,52.08],[2,1.43,58.14]],"ltp":2.0,"tv":80.0,"id":475559}]}]}
{"op":"mcm","clk":"11804651682","pt":1723241988264,"mc":[{"id":"1.231582170","rc":[{"batb":[[0,1.97,10],[1,1.96,43.53],[2,1.48,52.08]],"ltp":2.0,"tv":80.0,"id":475559}]}]}
{"op":"mcm","clk":"11804651757","pt":1723241991562,"mc":[{"id":"1.231582170","rc":[{"batb":[[0,1.96,43.53],[1,1.48,52.08],[2,1.43,58.14]],"ltp":2.0,"tv":80.0,"id":475559}]}]}
{"op":"mcm","clk":"11804651826","pt":1723241994219,"mc":[{"id":"1.231582170","rc":[{"batb":[[0,1.97,10],[1,1.96,43.53],[2,1.48,52.08]],"ltp":2.0,"tv":80.0,"id":475559}]}]}
{"op":"mcm","clk":"11804651930","pt":1723241998434,"mc":[{"id":"1.231582170","rc":[{"batb":[[0,1.96,43.53],[1,1.48,52.08],[2,1.43,58.14]],"ltp":2.0,"tv":80.0,"id":475559}]}]}
{"op":"mcm","clk":"11804651980","pt":1723242000856,"mc":[{"id":"1.231582170","rc":[{"batb":[[0,1.97,10],[1,1.96,43.53],[2,1.48,52.08]],"ltp":2.0,"tv":80.0,"id":475559}]}]}
{"op":"mcm","clk":"11804652081","pt":1723242004349,"mc":[{"id":"1.231582170","rc":[{"batb":[[0,1.96,43.53],[1,1.48,52.08],[2,1.43,58.14]],"ltp":2.0,"tv":80.0,"id":475559}]}]}
{"op":"mcm","clk":"11804652173","pt":1723242006571,"mc":[{"id":"1.231582170","rc":[{"batb":[[0,1.97,10],[1,1.96,43.53],[2,1.48,52.08]],"ltp":2.0,"tv":80.0,"id":475559}]}]}
{"op":"mcm","clk":"11804652267","pt":1723242009749,"mc":[{"id":"1.231582170","rc":[{"batb":[[0,1.96,43.53],[1,1.48,52.08],[2,1.43,58.14]],"ltp":2.0,"tv":80.0,"id":475559}]}]}
{"op":"mcm","clk":"11804652333","pt":1723242012216,"mc":[{"id":"1.231582170","rc":[{"batb":[[0,1.97,10],[1,1.96,43.53],[2,1.48,52.08]],"ltp":2.0,"tv":80.0,"id":475559}]}]}
{"op":"mcm","clk":"11804652419","pt":1723242015657,"mc":[{"id":"1.231582170","rc":[{"batb":[[0,1.96,43.53],[1,1.48,52.08],[2,1.43,58.14]],"ltp":2.0,"tv":80.0,"id":475559}]}]}
{"op":"mcm","clk":"11804652493","pt":1723242017970,"mc":[{"id":"1.231582170","rc":[{"batb":[[0,1.97,10],[1,1.96,43.53],[2,1.48,52.08]],"ltp":2.0,"tv":80.0,"id":475559}]}]}
{"op":"mcm","clk":"11804652557","pt":1723242021365,"mc":[{"id":"1.231582170","rc":[{"batb":[[0,1.96,43.53],[1,1.48,52.08],[2,1.43,58.14]],"ltp":2.0,"tv":80.0,"id":475559}]}]}
{"op":"mcm","clk":"11804652636","pt":1723242023790,"mc":[{"id":"1.231582170","rc":[{"batb":[[0,1.97,10],[1,1.96,43.53],[2,1.48,52.08]],"ltp":2.0,"tv":80.0,"id":475559}]}]}
{"op":"mcm","clk":"11804652719","pt":1723242027296,"mc":[{"id":"1.231582170","rc":[{"batb":[[0,1.96,43.53],[1,1.48,52.08],[2,1.43,58.14]],"ltp":2.0,"tv":80.0,"id":475559}]}]}
{"op":"mcm","clk":"11804652798","pt":1723242030586,"mc":[{"id":"1.231582170","rc":[{"batb":[[0,1.97,10],[1,1.96,43.53],[2,1.48,52.08]],"ltp":2.0,"tv":80.0,"id":475559}]}]}
{"op":"mcm","clk":"11804652887","pt":1723242033975,"mc":[{"id":"1.231582170","rc":[{"batb":[[0,1.96,43.53],[1,1.48,52.08],[2,1.43,58.14]],"ltp":2.0,"tv":80.0,"id":475559}]}]}
{"op":"mcm","clk":"11804652966","pt":1723242036703,"mc":[{"id":"1.231582170","rc":[{"batb":[[0,1.97,10],[1,1.96,43.53],[2,1.48,52.08]],"ltp":2.0,"tv":80.0,"id":475559}]}]}
{"op":"mcm","clk":"11804653048","pt":1723242039895,"mc":[{"id":"1.231582170","rc":[{"batb":[[0,1.96,43.53],[1,1.48,52.08],[2,1.43,58.14]],"ltp":2.0,"tv":80.0,"id":475559}]}]}
{"op":"mcm","clk":"11804653147","pt":1723242043704,"mc":[{"id":"1.231582170","rc":[{"batb":[[0,1.97,10],[1,1.96,43.53],[2,1.48,52.08]],"ltp":2.0,"tv":80.0,"id":475559}]}]}
{"op":"mcm","clk":"11804653225","pt":1723242047001,"mc":[{"id":"1.231582170","rc":[{"batb":[[0,1.96,43.53],[1,1.48,52.08],[2,1.43,58.14]],"ltp":2.0,"tv":80.0,"id":475559}]}]}
{"op":"mcm","clk":"11804653285","pt":1723242049786,"mc":[{"id":"1.231582170","rc":[{"batb":[[0,1.97,10],[1,1.96,43.53],[2,1.48,52.08]],"ltp":2.0,"tv":80.0,"id":475559}]}]}
{"op":"mcm","clk":"11804653361","pt":1723242053089,"mc":[{"id":"1.231582170","rc":[{"batb":[[0,1.96,43.53],[1,1.48,52.08],[2,1.43,58.14]],"ltp":2.0,"tv":80.0,"id":475559}]}]}
{"op":"mcm","clk":"11804653422","pt":1723242056118,"mc":[{"id":"1.231582170","rc":[{"batb":[[0,1.97,10],[1,1.96,43.53],[2,1.48,52.08]],"ltp":2.0,"tv":80.0,"id":475559}]}]}
{"op":"mcm","clk":"11804653486","pt":1723242059398,"mc":[{"id":"1.231582170","rc":[{"batb":[[0,1.96,43.53],[1,1.48,52.08],[2,1.43,58.14]],"ltp":2.0,"tv":80.0,"id":475559}]}]}
{"op":"mcm","clk":"11804653540","pt":1723242061812,"mc":[{"id":"1.231582170","rc":[{"batb":[[0,1.97,10],[1,1.96,43.53],[2,1.48,52.08]],"ltp":2.0,"tv":80.0,"id":475559}]}]}
{"op":"mcm","clk":"11804653614","pt":1723242065221,"mc":[{"id":"1.231582170","rc":[{"batb":[[0,1.96,43.53],[1,1.48,52.08],[2,1.43,58.14]],"ltp":2.0,"tv":80.0,"id":475559}]}]}
{"op":"mcm","clk":"11804653797","pt":1723242071030,"mc":[{"id":"1.231582170","rc":[{"batb":[[0,1.97,10],[1,1.96,43.53],[2,1.48,52.08]],"ltp":2.0,"tv":80.0,"id":475559}]}]}
{"op":"mcm","clk":"11804653892","pt":1723242074526,"mc":[{"id":"1.231582170","rc":[{"batb":[[0,1.96,43.53],[1,1.48,52.08],[2,1.43,58.14]],"ltp":2.0,"tv":80.0,"id":475559}]}]}
{"op":"mcm","clk":"11804653950","pt":1723242076798,"mc":[{"id":"1.231582170","rc":[{"batb":[[0,1.97,10],[1,1.96,43.53],[2,1.48,52.08]],"ltp":2.0,"tv":80.0,"id":475559}]}]}
{"op":"mcm","clk":"11804654030","pt":1723242080136,"mc":[{"id":"1.231582170","rc":[{"batb":[[0,1.96,43.53],[1,1.48,52.08],[2,1.43,58.14]],"ltp":2.0,"tv":80.0,"id":475559}]}]}
{"op":"mcm","clk":"11804654091","pt":1723242082609,"mc":[{"id":"1.231582170","rc":[{"batb":[[0,1.97,10],[1,1.96,43.53],[2,1.48,52.08]],"ltp":2.0,"tv":80.0,"id":475559}]}]}
{"op":"mcm","clk":"11804654178","pt":1723242085914,"mc":[{"id":"1.231582170","rc":[{"batb":[[0,1.96,43.53],[1,1.48,52.08],[2,1.43,58.14]],"ltp":2.0,"tv":80.0,"id":475559}]}]}
{"op":"mcm","clk":"11804654228","pt":1723242089244,"mc":[{"id":"1.231582170","rc":[{"batb":[[0,1.97,10],[1,1.96,43.53],[2,1.48,52.08]],"ltp":2.0,"tv":80.0,"id":475559}]}]}
{"op":"mcm","clk":"11804654281","pt":1723242092424,"mc":[{"id":"1.231582170","rc":[{"batb":[[0,1.96,43.53],[1,1.48,52.08],[2,1.43,58.14]],"ltp":2.0,"tv":80.0,"id":475559}]}]}
{"op":"mcm","clk":"11804654351","pt":1723242095927,"mc":[{"id":"1.231582170","rc":[{"batb":[[0,1.97,10],[1,1.96,43.53],[2,1.48,52.08]],"ltp":2.0,"tv":80.0,"id":475559}]}]}
{"op":"mcm","clk":"11804654414","pt":1723242099374,"mc":[{"id":"1.231582170","rc":[{"batb":[[0,1.96,43.53],[1,1.48,52.08],[2,1.43,58.14]],"ltp":2.0,"tv":80.0,"id":475559}]}]}
{"op":"mcm","clk":"11804654469","pt":1723242102764,"mc":[{"id":"1.231582170","rc":[{"batb":[[0,1.97,10],[1,1.96,43.53],[2,1.48,52.08]],"ltp":2.0,"tv":80.0,"id":475559}]}]}
{"op":"mcm","clk":"11804654519","pt":1723242106363,"mc":[{"id":"1.231582170","rc":[{"batb":[[0,1.96,43.53],[1,1.48,52.08],[2,1.43,58.14]],"ltp":2.0,"tv":80.0,"id":475559}]}]}
{"op":"mcm","clk":"11804654583","pt":1723242109982,"mc":[{"id":"1.231582170","rc":[{"batb":[[0,1.97,10],[1,1.96,43.53],[2,1.48,52.08]],"ltp":2.0,"tv":80.0,"id":475559}]}]}
{"op":"mcm","clk":"11804654655","pt":1723242113192,"mc":[{"id":"1.231582170","rc":[{"batb":[[0,1.96,43.53],[1,1.48,52.08],[2,1.43,58.14]],"ltp":2.0,"tv":80.0,"id":475559}]}]}
{"op":"mcm","clk":"11804654696","pt":1723242115563,"mc":[{"id":"1.231582170","rc":[{"batb":[[0,1.97,10],[1,1.96,43.53],[2,1.48,52.08]],"ltp":2.0,"tv":80.0,"id":475559}]}]}
{"op":"mcm","clk":"11804654772","pt":1723242119099,"mc":[{"id":"1.231582170","rc":[{"batb":[[0,1.96,43.53],[1,1.48,52.08],[2,1.43,58.14]],"ltp":2.0,"tv":80.0,"id":475559}]}]}
{"op":"mcm","clk":"11804654818","pt":1723242121364,"mc":[{"id":"1.231582170","rc":[{"batb":[[0,1.97,10],[1,1.96,43.53],[2,1.48,52.08]],"ltp":2.0,"tv":80.0,"id":475559}]}]}
{"op":"mcm","clk":"11804654901","pt":1723242124806,"mc":[{"id":"1.231582170","rc":[{"batb":[[0,1.96,43.53],[1,1.48,52.08],[2,1.43,58.14]],"ltp":2.0,"tv":80.0,"id":475559}]}]}
{"op":"mcm","clk":"11804654950","pt":1723242127166,"mc":[{"id":"1.231582170","rc":[{"batb":[[0,1.97,10],[1,1.96,43.53],[2,1.48,52.08]],"ltp":2.0,"tv":80.0,"id":475559}]}]}
{"op":"mcm","clk":"11804655015","pt":1723242130703,"mc":[{"id":"1.231582170","rc":[{"batb":[[0,1.96,43.53],[1,1.48,52.08],[2,1.43,58.14]],"ltp":2.0,"tv":80.0,"id":475559}]}]}
{"op":"mcm","clk":"11804655092","pt":1723242133078,"mc":[{"id":"1.231582170","rc":[{"batb":[[0,1.97,10],[1,1.96,43.53],[2,1.48,52.08]],"ltp":2.0,"tv":80.0,"id":475559}]}]}
{"op":"mcm","clk":"11804655184","pt":1723242136476,"mc":[{"id":"1.231582170","rc":[{"batb":[[0,1.96,43.53],[1,1.48,52.08],[2,1.43,58.14]],"ltp":2.0,"tv":80.0,"id":475559}]}]}
{"op":"mcm","clk":"11804655254","pt":1723242138990,"mc":[{"id":"1.231582170","rc":[{"batb":[[0,1.97,10],[1,1.96,43.53],[2,1.48,52.08]],"ltp":2.0,"tv":80.0,"id":475559}]}]}
{"op":"mcm","clk":"11804655324","pt":1723242142277,"mc":[{"id":"1.231582170","rc":[{"batb":[[0,1.96,43.53],[1,1.48,52.08],[2,1.43,58.14]],"ltp":2.0,"tv":80.0,"id":475559}]}]}
{"op":"mcm","clk":"11804655398","pt":1723242145304,"mc":[{"id":"1.231582170","rc":[{"batb":[[0,1.97,10],[1,1.96,43.53],[2,1.48,52.08]],"ltp":2.0,"tv":80.0,"id":475559}]}]}
{"op":"mcm","clk":"11804655459","pt":1723242148582,"mc":[{"id":"1.231582170","rc":[{"batb":[[0,1.96,43.53],[1,1.48,52.08],[2,1.43,58.14]],"ltp":2.0,"tv":80.0,"id":475559}]}]}
{"op":"mcm","clk":"11804655506","pt":1723242151098,"mc":[{"id":"1.231582170","rc":[{"batb":[[0,1.97,10],[1,1.96,43.53],[2,1.48,52.08]],"ltp":2.0,"tv":80.0,"id":475559}]}]}
{"op":"mcm","clk":"11804655588","pt":1723242154331,"mc":[{"id":"1.231582170","rc":[{"batb":[[0,1.96,43.53],[1,1.48,52.08],[2,1.43,58.14]],"ltp":2.0,"tv":80.0,"id":475559}]}]}
{"op":"mcm","clk":"11804655622","pt":1723242156535,"mc":[{"id":"1.231582170","rc":[{"batb":[[0,1.97,10],[1,1.96,43.53],[2,1.48,52.08]],"ltp":2.0,"tv":80.0,"id":475559}]}]}
{"op":"mcm","clk":"11804655728","pt":1723242159932,"mc":[{"id":"1.231582170","rc":[{"batb":[[0,1.96,43.53],[1,1.48,52.08],[2,1.43,58.14]],"ltp":2.0,"tv":80.0,"id":475559}]}]}
{"op":"mcm","clk":"11804655789","pt":1723242162196,"mc":[{"id":"1.231582170","rc":[{"batb":[[0,1.97,10],[1,1.96,43.53],[2,1.48,52.08]],"ltp":2.0,"tv":80.0,"id":475559}]}]}
{"op":"mcm","clk":"11804655844","pt":1723242165531,"mc":[{"id":"1.231582170","rc":[{"batb":[[0,1.96,43.53],[1,1.48,52.08],[2,1.43,58.14]],"ltp":2.0,"tv":80.0,"id":475559}]}]}
{"op":"mcm","clk":"11804655918","pt":1723242169040,"mc":[{"id":"1.231582170","rc":[{"batb":[[0,1.97,10],[1,1.96,43.53],[2,1.48,52.08]],"ltp":2.0,"tv":80.0,"id":475559}]}]}
{"op":"mcm","clk":"11804656005","pt":1723242172232,"mc":[{"id":"1.231582170","rc":[{"batb":[[0,1.96,43.53],[1,1.48,52.08],[2,1.43,58.14]],"ltp":2.0,"tv":80.0,"id":475559}]}]}
{"op":"mcm","clk":"11804656060","pt":1723242175315,"mc":[{"id":"1.231582170","rc":[{"batb":[[0,1.97,10],[1,1.96,43.53],[2,1.48,52.08]],"ltp":2.0,"tv":80.0,"id":475559}]}]}
{"op":"mcm","clk":"11804656141","pt":1723242179356,"mc":[{"id":"1.231582170","rc":[{"batb":[[0,1.96,43.53],[1,1.48,52.08],[2,1.43,58.14]],"ltp":2.0,"tv":80.0,"id":475559}]}]}
{"op":"mcm","clk":"11804656189","pt":1723242181927,"mc":[{"id":"1.231582170","rc":[{"batb":[[0,1.97,10],[1,1.96,43.53],[2,1.48,52.08]],"ltp":2.0,"tv":80.0,"id":475559}]}]}
{"op":"mcm","clk":"11804656287","pt":1723242185952,"mc":[{"id":"1.231582170","rc":[{"batb":[[0,1.96,43.53],[1,1.48,52.08],[2,1.43,58.14]],"ltp":2.0,"tv":80.0,"id":475559}]}]}
{"op":"mcm","clk":"11804656361","pt":1723242188928,"mc":[{"id":"1.231582170","rc":[{"batb":[[0,1.97,10],[1,1.96,43.53],[2,1.48,52.08]],"ltp":2.0,"tv":80.0,"id":475559}]}]}
{"op":"mcm","clk":"11804656429","pt":1723242192231,"mc":[{"id":"1.231582170","rc":[{"batb":[[0,1.96,43.53],[1,1.48,52.08],[2,1.43,58.14]],"ltp":2.0,"tv":80.0,"id":475559}]}]}
{"op":"mcm","clk":"11804656483","pt":1723242195161,"mc":[{"id":"1.231582170","rc":[{"batb":[[0,1.97,10],[1,1.96,43.53],[2,1.48,52.08]],"ltp":2.0,"tv":80.0,"id":475559}]}]}
{"op":"mcm","clk":"11804656563","pt":1723242198443,"mc":[{"id":"1.231582170","rc":[{"batb":[[0,1.96,43.53],[1,1.48,52.08],[2,1.43,58.14]],"ltp":2.0,"tv":80.0,"id":475559}]}]}
{"op":"mcm","clk":"11804656631","pt":1723242200937,"mc":[{"id":"1.231582170","rc":[{"batb":[[0,1.97,10],[1,1.96,43.53],[2,1.48,52.08]],"ltp":2.0,"tv":80.0,"id":475559}]}]}
{"op":"mcm","clk":"11804656692","pt":1723242204164,"mc":[{"id":"1.231582170","rc":[{"batb":[[0,1.96,43.53],[1,1.48,52.08],[2,1.43,58.14]],"ltp":2.0,"tv":80.0,"id":475559}]}]}
{"op":"mcm","clk":"11804656743","pt":1723242207144,"mc":[{"id":"1.231582170","rc":[{"batb":[[0,1.97,10],[1,1.96,43.53],[2,1.48,52.08]],"ltp":2.0,"tv":80.0,"id":475559}]}]}
{"op":"mcm","clk":"11804656818","pt":1723242210539,"mc":[{"id":"1.231582170","rc":[{"batb":[[0,1.96,43.53],[1,1.48,52.08],[2,1.43,58.14]],"ltp":2.0,"tv":80.0,"id":475559}]}]}
{"op":"mcm","clk":"11804687477","pt":1723243601885,"mc":[{"id":"1.231582170","rc":[{"trd":[[1.96,80]],"batb":[[0,1.96,3.53]],"ltp":1.96,"tv":160.0,"id":475559}],"tv":160.0}]}
{"op":"mcm","clk":"11804687506","pt":1723243602959,"mc":[{"id":"1.231582170","rc":[{"batb":[[0,1.92,45.42]],"ltp":1.96,"tv":160.0,"id":475559}]}]}
{"op":"mcm","clk":"11804705639","pt":1723244400859,"mc":[{"id":"1.231582170","rc":[{"batb":[[0,1.93,10],[1,1.92,45.42],[2,1.48,52.08]],"ltp":1.96,"tv":160.0,"id":475559}]}]}
{"op":"mcm","clk":"11804705822","pt":1723244404151,"mc":[{"id":"1.231582170","rc":[{"batb":[[0,1.92,45.42],[1,1.48,52.08],[2,1.43,58.14]],"ltp":1.96,"tv":160.0,"id":475559}]}]}
{"op":"mcm","clk":"11804705928","pt":1723244406674,"mc":[{"id":"1.231582170","rc":[{"batb":[[0,1.93,10],[1,1.92,45.42],[2,1.48,52.08]],"ltp":1.96,"tv":160.0,"id":475559}]}]}
{"op":"mcm","clk":"11804706070","pt":1723244409960,"mc":[{"id":"1.231582170","rc":[{"batb":[[0,1.92,45.42],[1,1.48,52.08],[2,1.43,58.14]],"ltp":1.96,"tv":160.0,"id":475559}]}]}
{"op":"mcm","clk":"11804706146","pt":1723244412331,"mc":[{"id":"1.231582170","rc":[{"batb":[[0,1.93,10],[1,1.92,45.42],[2,1.48,52.08]],"ltp":1.96,"tv":160.0,"id":475559}]}]}
{"op":"mcm","clk":"11804706262","pt":1723244415625,"mc":[{"id":"1.231582170","rc":[{"batb":[[0,1.92,45.42],[1,1.48,52.08],[2,1.43,58.14]],"ltp":1.96,"tv":160.0,"id":475559}]}]}
{"op":"mcm","clk":"11804706333","pt":1723244417840,"mc":[{"id":"1.231582170","rc":[{"batb":[[0,1.93,10],[1,1.92,45.42],[2,1.48,52.08]],"ltp":1.96,"tv":160.0,"id":475559}]}]}
{"op":"mcm","clk":"11804706471","pt":1723244421233,"mc":[{"id":"1.231582170","rc":[{"batb":[[0,1.92,45.42],[1,1.48,52.08],[2,1.43,58.14]],"ltp":1.96,"tv":160.0,"id":475559}]}]}
{"op":"mcm","clk":"11804706566","pt":1723244423858,"mc":[{"id":"1.231582170","rc":[{"batb":[[0,1.93,10],[1,1.92,45.42],[2,1.48,52.08]],"ltp":1.96,"tv":160.0,"id":475559}]}]}
{"op":"mcm","clk":"11804706663","pt":1723244427349,"mc":[{"id":"1.231582170","rc":[{"batb":[[0,1.92,45.42],[1,1.48,52.08],[2,1.43,58.14]],"ltp":1.96,"tv":160.0,"id":475559}]}]}
{"op":"mcm","clk":"11804706746","pt":1723244429864,"mc":[{"id":"1.231582170","rc":[{"batb":[[0,1.93,10],[1,1.92,45.42],[2,1.48,52.08]],"ltp":1.96,"tv":160.0,"id":475559}]}]}
{"op":"mcm","clk":"11804706861","pt":1723244434178,"mc":[{"id":"1.231582170","rc":[{"batb":[[0,1.92,45.42],[1,1.48,52.08],[2,1.43,58.14]],"ltp":1.96,"tv":160.0,"id":475559}]}]}
{"op":"mcm","clk":"11804706919","pt":1723244436949,"mc":[{"id":"1.231582170","rc":[{"batb":[[0,1.93,10],[1,1.92,45.42],[2,1.48,52.08]],"ltp":1.96,"tv":160.0,"id":475559}]}]}
{"op":"mcm","clk":"11804707027","pt":1723244440391,"mc":[{"id":"1.231582170","rc":[{"batb":[[0,1.92,45.42],[1,1.48,52.08],[2,1.43,58.14]],"ltp":1.96,"tv":160.0,"id":475559}]}]}
{"op":"mcm","clk":"11804707089","pt":1723244442697,"mc":[{"id":"1.231582170","rc":[{"batb":[[0,1.93,10],[1,1.92,45.42],[2,1.48,52.08]],"ltp":1.96,"tv":160.0,"id":475559}]}]}
{"op":"mcm","clk":"11804707160","pt":1723244445984,"mc":[{"id":"1.231582170","rc":[{"batb":[[0,1.92,45.42],[1,1.48,52.08],[2,1.43,58.14]],"ltp":1.96,"tv":160.0,"id":475559}]}]}
{"op":"mcm","clk":"11804707271","pt":1723244449174,"mc":[{"id":"1.231582170","rc":[{"batb":[[0,1.93,10],[1,1.92,45.42],[2,1.48,52.08]],"ltp":1.96,"tv":160.0,"id":475559}]}]}
{"op":"mcm","clk":"11804707355","pt":1723244452399,"mc":[{"id":"1.231582170","rc":[{"batb":[[0,1.92,45.42],[1,1.48,52.08],[2,1.43,58.14]],"ltp":1.96,"tv":160.0,"id":475559}]}]}
{"op":"mcm","clk":"11804707433","pt":1723244455284,"mc":[{"id":"1.231582170","rc":[{"batb":[[0,1.93,10],[1,1.92,45.42],[2,1.48,52.08]],"ltp":1.96,"tv":160.0,"id":475559}]}]}
{"op":"mcm","clk":"11804707520","pt":1723244458565,"mc":[{"id":"1.231582170","rc":[{"batb":[[0,1.92,45.42],[1,1.48,52.08],[2,1.43,58.14]],"ltp":1.96,"tv":160.0,"id":475559}]}]}
{"op":"mcm","clk":"11804707588","pt":1723244461079,"mc":[{"id":"1.231582170","rc":[{"batb":[[0,1.93,10],[1,1.92,45.42],[2,1.48,52.08]],"ltp":1.96,"tv":160.0,"id":475559}]}]}
{"op":"mcm","clk":"11804707671","pt":1723244464468,"mc":[{"id":"1.231582170","rc":[{"batb":[[0,1.92,45.42],[1,1.48,52.08],[2,1.43,58.14]],"ltp":1.96,"tv":160.0,"id":475559}]}]}
{"op":"mcm","clk":"11804707749","pt":1723244467901,"mc":[{"id":"1.231582170","rc":[{"batb":[[0,1.93,10],[1,1.92,45.42],[2,1.48,52.08]],"ltp":1.96,"tv":160.0,"id":475559}]}]}
{"op":"mcm","clk":"11804707837","pt":1723244471195,"mc":[{"id":"1.231582170","rc":[{"batb":[[0,1.92,45.42],[1,1.48,52.08],[2,1.43,58.14]],"ltp":1.96,"tv":160.0,"id":475559}]}]}
{"op":"mcm","clk":"11804707895","pt":1723244473602,"mc":[{"id":"1.231582170","rc":[{"batb":[[0,1.93,10],[1,1.92,45.42],[2,1.48,52.08]],"ltp":1.96,"tv":160.0,"id":475559}]}]}
{"op":"mcm","clk":"11804708009","pt":1723244476891,"mc":[{"id":"1.231582170","rc":[{"batb":[[0,1.92,45.42],[1,1.48,52.08],[2,1.43,58.14]],"ltp":1.96,"tv":160.0,"id":475559}]}]}
{"op":"mcm","clk":"11804708085","pt":1723244479763,"mc":[{"id":"1.231582170","rc":[{"batb":[[0,1.93,10],[1,1.92,45.42],[2,1.48,52.08]],"ltp":1.96,"tv":160.0,"id":475559}]}]}
{"op":"mcm","clk":"11804708201","pt":1723244482717,"mc":[{"id":"1.231582170","rc":[{"batb":[[0,1.92,45.42],[1,1.48,52.08],[2,1.43,58.14]],"ltp":1.96,"tv":160.0,"id":475559}]}]}
{"op":"mcm","clk":"11804708353","pt":1723244486911,"mc":[{"id":"1.231582170","rc":[{"batb":[[0,1.93,10],[1,1.92,45.42],[2,1.48,52.08]],"ltp":1.96,"tv":160.0,"id":475559}]}]}
{"op":"mcm","clk":"11804708435","pt":1723244490216,"mc":[{"id":"1.231582170","rc":[{"batb":[[0,1.92,45.42],[1,1.48,52.08],[2,1.43,58.14]],"ltp":1.96,"tv":160.0,"id":475559}]}]}
{"op":"mcm","clk":"11804708508","pt":1723244493097,"mc":[{"id":"1.231582170","rc":[{"batb":[[0,1.93,10],[1,1.92,45.42],[2,1.48,52.08]],"ltp":1.96,"tv":160.0,"id":475559}]}]}
{"op":"mcm","clk":"11804708595","pt":1723244496504,"mc":[{"id":"1.231582170","rc":[{"batb":[[0,1.92,45.42],[1,1.48,52.08],[2,1.43,58.14]],"ltp":1.96,"tv":160.0,"id":475559}]}]}
{"op":"mcm","clk":"11804708693","pt":1723244499738,"mc":[{"id":"1.231582170","rc":[{"batb":[[0,1.93,10],[1,1.92,45.42],[2,1.48,52.08]],"ltp":1.96,"tv":160.0,"id":475559}]}]}
{"op":"mcm","clk":"11804708791","pt":1723244503123,"mc":[{"id":"1.231582170","rc":[{"batb":[[0,1.92,45.42],[1,1.48,52.08],[2,1.43,58.14]],"ltp":1.96,"tv":160.0,"id":475559}]}]}
{"op":"mcm","clk":"11804708889","pt":1723244506818,"mc":[{"id":"1.231582170","rc":[{"batb":[[0,1.93,10],[1,1.92,45.42],[2,1.48,52.08]],"ltp":1.96,"tv":160.0,"id":475559}]}]}
{"op":"mcm","clk":"11804709011","pt":1723244510151,"mc":[{"id":"1.231582170","rc":[{"batb":[[0,1.92,45.42],[1,1.48,52.08],[2,1.43,58.14]],"ltp":1.96,"tv":160.0,"id":475559}]}]}
{"op":"mcm","clk":"11804709088","pt":1723244512935,"mc":[{"id":"1.231582170","rc":[{"batb":[[0,1.93,10],[1,1.92,45.42],[2,1.48,52.08]],"ltp":1.96,"tv":160.0,"id":475559}]}]}
{"op":"mcm","clk":"11804709150","pt":1723244516229,"mc":[{"id":"1.231582170","rc":[{"batb":[[0,1.92,45.42],[1,1.48,52.08],[2,1.43,58.14]],"ltp":1.96,"tv":160.0,"id":475559}]}]}
{"op":"mcm","clk":"11804709203","pt":1723244518538,"mc":[{"id":"1.231582170","rc":[{"batb":[[0,1.93,10],[1,1.92,45.42],[2,1.48,52.08]],"ltp":1.96,"tv":160.0,"id":475559}]}]}
{"op":"mcm","clk":"11804709293","pt":1723244521827,"mc":[{"id":"1.231582170","rc":[{"batb":[[0,1.92,45.42],[1,1.48,52.08],[2,1.43,58.14]],"ltp":1.96,"tv":160.0,"id":475559}]}]}
{"op":"mcm","clk":"11804709366","pt":1723244524664,"mc":[{"id":"1.231582170","rc":[{"batb":[[0,1.93,10],[1,1.92,45.42],[2,1.48,52.08]],"ltp":1.96,"tv":160.0,"id":475559}]}]}
{"op":"mcm","clk":"11804709460","pt":1723244528533,"mc":[{"id":"1.231582170","rc":[{"batb":[[0,1.92,45.42],[1,1.48,52.08],[2,1.43,58.14]],"ltp":1.96,"tv":160.0,"id":475559}]}]}
{"op":"mcm","clk":"11804709538","pt":1723244531350,"mc":[{"id":"1.231582170","rc":[{"batb":[[0,1.93,10],[1,1.92,45.42],[2,1.48,52.08]],"ltp":1.96,"tv":160.0,"id":475559}]}]}
{"op":"mcm","clk":"11804709643","pt":1723244534546,"mc":[{"id":"1.231582170","rc":[{"batb":[[0,1.92,45.42],[1,1.48,52.08],[2,1.43,58.14]],"ltp":1.96,"tv":160.0,"id":475559}]}]}
{"op":"mcm","clk":"11804709731","pt":1723244538032,"mc":[{"id":"1.231582170","rc":[{"batb":[[0,1.93,10],[1,1.92,45.42],[2,1.48,52.08]],"ltp":1.96,"tv":160.0,"id":475559}]}]}
{"op":"mcm","clk":"11804709842","pt":1723244541373,"mc":[{"id":"1.231582170","rc":[{"batb":[[0,1.92,45.42],[1,1.48,52.08],[2,1.43,58.14]],"ltp":1.96,"tv":160.0,"id":475559}]}]}
{"op":"mcm","clk":"11804709921","pt":1723244544355,"mc":[{"id":"1.231582170","rc":[{"batb":[[0,1.93,10],[1,1.92,45.42],[2,1.48,52.08]],"ltp":1.96,"tv":160.0,"id":475559}]}]}
{"op":"mcm","clk":"11804710019","pt":1723244547766,"mc":[{"id":"1.231582170","rc":[{"batb":[[0,1.92,45.42],[1,1.48,52.08],[2,1.43,58.14]],"ltp":1.96,"tv":160.0,"id":475559}]}]}
{"op":"mcm","clk":"11804710129","pt":1723244550084,"mc":[{"id":"1.231582170","rc":[{"batb":[[0,1.93,10],[1,1.92,45.42],[2,1.48,52.08]],"ltp":1.96,"tv":160.0,"id":475559}]}]}
{"op":"mcm","clk":"11804710219","pt":1723244553480,"mc":[{"id":"1.231582170","rc":[{"batb":[[0,1.92,45.42],[1,1.48,52.08],[2,1.43,58.14]],"ltp":1.96,"tv":160.0,"id":475559}]}]}
{"op":"mcm","clk":"11804710280","pt":1723244555852,"mc":[{"id":"1.231582170","rc":[{"batb":[[0,1.93,10],[1,1.92,45.42],[2,1.48,52.08]],"ltp":1.96,"tv":160.0,"id":475559}]}]}
{"op":"mcm","clk":"11804710357","pt":1723244559185,"mc":[{"id":"1.231582170","rc":[{"batb":[[0,1.92,45.42],[1,1.48,52.08],[2,1.43,58.14]],"ltp":1.96,"tv":160.0,"id":475559}]}]}
{"op":"mcm","clk":"11804710430","pt":1723244561665,"mc":[{"id":"1.231582170","rc":[{"batb":[[0,1.93,10],[1,1.92,45.42],[2,1.48,52.08]],"ltp":1.96,"tv":160.0,"id":475559}]}]}
{"op":"mcm","clk":"11804710503","pt":1723244565105,"mc":[{"id":"1.231582170","rc":[{"batb":[[0,1.92,45.42],[1,1.48,52.08],[2,1.43,58.14]],"ltp":1.96,"tv":160.0,"id":475559}]}]}
{"op":"mcm","clk":"11804710550","pt":1723244567671,"mc":[{"id":"1.231582170","rc":[{"batb":[[0,1.93,10],[1,1.92,45.42],[2,1.48,52.08]],"ltp":1.96,"tv":160.0,"id":475559}]}]}
{"op":"mcm","clk":"11804710643","pt":1723244571165,"mc":[{"id":"1.231582170","rc":[{"batb":[[0,1.92,45.42],[1,1.48,52.08],[2,1.43,58.14]],"ltp":1.96,"tv":160.0,"id":475559}]}]}
{"op":"mcm","clk":"11804710690","pt":1723244573267,"mc":[{"id":"1.231582170","rc":[{"batb":[[0,1.93,10],[1,1.92,45.42],[2,1.48,52.08]],"ltp":1.96,"tv":160.0,"id":475559}]}]}
{"op":"mcm","clk":"11804710750","pt":1723244576606,"mc":[{"id":"1.231582170","rc":[{"batb":[[0,1.92,45.42],[1,1.48,52.08],[2,1.43,58.14]],"ltp":1.96,"tv":160.0,"id":475559}]}]}
{"op":"mcm","clk":"11804710797","pt":1723244578809,"mc":[{"id":"1.231582170","rc":[{"batb":[[0,1.93,10],[1,1.92,45.42],[2,1.48,52.08]],"ltp":1.96,"tv":160.0,"id":475559}]}]}
{"op":"mcm","clk":"11804710899","pt":1723244582103,"mc":[{"id":"1.231582170","rc":[{"batb":[[0,1.92,45.42],[1,1.48,52.08],[2,1.43,58.14]],"ltp":1.96,"tv":160.0,"id":475559}]}]}
{"op":"mcm","clk":"11804710964","pt":1723244585082,"mc":[{"id":"1.231582170","rc":[{"batb":[[0,1.93,10],[1,1.92,45.42],[2,1.48,52.08]],"ltp":1.96,"tv":160.0,"id":475559}]}]}
{"op":"mcm","clk":"11804711028","pt":1723244588528,"mc":[{"id":"1.231582170","rc":[{"batb":[[0,1.92,45.42],[1,1.48,52.08],[2,1.43,58.14]],"ltp":1.96,"tv":160.0,"id":475559}]}]}
{"op":"mcm","clk":"11804711084","pt":1723244590881,"mc":[{"id":"1.231582170","rc":[{"batb":[[0,1.93,10],[1,1.92,45.42],[2,1.48,52.08]],"ltp":1.96,"tv":160.0,"id":475559}]}]}
{"op":"mcm","clk":"11804711186","pt":1723244594126,"mc":[{"id":"1.231582170","rc":[{"batb":[[0,1.92,45.42],[1,1.48,52.08],[2,1.43,58.14]],"ltp":1.96,"tv":160.0,"id":475559}]}]}
{"op":"mcm","clk":"11804711253","pt":1723244596794,"mc":[{"id":"1.231582170","rc":[{"batb":[[0,1.93,10],[1,1.92,45.42],[2,1.48,52.08]],"ltp":1.96,"tv":160.0,"id":475559}]}]}
{"op":"mcm","clk":"11804711336","pt":1723244600029,"mc":[{"id":"1.231582170","rc":[{"batb":[[0,1.92,45.42],[1,1.48,52.08],[2,1.43,58.14]],"ltp":1.96,"tv":160.0,"id":475559}]}]}
{"op":"mcm","clk":"11804711445","pt":1723244603528,"mc":[{"id":"1.231582170","rc":[{"batb":[[0,1.93,10],[1,1.92,45.42],[2,1.48,52.08]],"ltp":1.96,"tv":160.0,"id":475559}]}]}
{"op":"mcm","clk":"11804711530","pt":1723244606920,"mc":[{"id":"1.231582170","rc":[{"batb":[[0,1.92,45.42],[1,1.48,52.08],[2,1.43,58.14]],"ltp":1.96,"tv":160.0,"id":475559}]}]}
{"op":"mcm","clk":"11804711605","pt":1723244610214,"mc":[{"id":"1.231582170","rc":[{"batb":[[0,1.93,10],[1,1.92,45.42],[2,1.48,52.08]],"ltp":1.96,"tv":160.0,"id":475559}]}]}
{"op":"mcm","clk":"11804711681","pt":1723244613600,"mc":[{"id":"1.231582170","rc":[{"batb":[[0,1.92,45.42],[1,1.48,52.08],[2,1.43,58.14]],"ltp":1.96,"tv":160.0,"id":475559}]}]}
{"op":"mcm","clk":"11804711797","pt":1723244616230,"mc":[{"id":"1.231582170","rc":[{"batb":[[0,1.93,10],[1,1.92,45.42],[2,1.48,52.08]],"ltp":1.96,"tv":160.0,"id":475559}]}]}
{"op":"mcm","clk":"11804711888","pt":1723244619526,"mc":[{"id":"1.231582170","rc":[{"batb":[[0,1.92,45.42],[1,1.48,52.08],[2,1.43,58.14]],"ltp":1.96,"tv":160.0,"id":475559}]}]}
{"op":"mcm","clk":"11804711947","pt":1723244622310,"mc":[{"id":"1.231582170","rc":[{"batb":[[0,1.93,10],[1,1.92,45.42],[2,1.48,52.08]],"ltp":1.96,"tv":160.0,"id":475559}]}]}
{"op":"mcm","clk":"11804712046","pt":1723244625549,"mc":[{"id":"1.231582170","rc":[{"batb":[[0,1.92,45.42],[1,1.48,52.08],[2,1.43,58.14]],"ltp":1.96,"tv":160.0,"id":475559}]}]}
{"op":"mcm","clk":"11804712176","pt":1723244629154,"mc":[{"id":"1.231582170","rc":[{"batb":[[0,1.93,10],[1,1.92,45.42],[2,1.48,52.08]],"ltp":1.96,"tv":160.0,"id":475559}]}]}
{"op":"mcm","clk":"11804712260","pt":1723244632414,"mc":[{"id":"1.231582170","rc":[{"batb":[[0,1.92,45.42],[1,1.48,52.08],[2,1.43,58.14]],"ltp":1.96,"tv":160.0,"id":475559}]}]}
{"op":"mcm","clk":"11804712341","pt":1723244635448,"mc":[{"id":"1.231582170","rc":[{"batb":[[0,1.93,10],[1,1.92,45.42],[2,1.48,52.08]],"ltp":1.96,"tv":160.0,"id":475559}]}]}
{"op":"mcm","clk":"11804712428","pt":1723244638746,"mc":[{"id":"1.231582170","rc":[{"batb":[[0,1.92,45.42],[1,1.48,52.08],[2,1.43,58.14]],"ltp":1.96,"tv":160.0,"id":475559}]}]}
{"op":"mcm","clk":"11804712521","pt":1723244641733,"mc":[{"id":"1.231582170","rc":[{"batb":[[0,1.93,10],[1,1.92,45.42],[2,1.48,52.08]],"ltp":1.96,"tv":160.0,"id":475559}]}]}
{"op":"mcm","clk":"11804712604","pt":1723244645133,"mc":[{"id":"1.231582170","rc":[{"batb":[[0,1.92,45.42],[1,1.48,52.08],[2,1.43,58.14]],"ltp":1.96,"tv":160.0,"id":475559}]}]}
{"op":"mcm","clk":"11804712690","pt":1723244647858,"mc":[{"id":"1.231582170","rc":[{"batb":[[0,1.93,10],[1,1.92,45.42],[2,1.48,52.08]],"ltp":1.96,"tv":160.0,"id":475559}]}]}
{"op":"mcm","clk":"11804712780","pt":1723244651237,"mc":[{"id":"1.231582170","rc":[{"batb":[[0,1.92,45.42],[1,1.48,52.08],[2,1.43,58.14]],"ltp":1.96,"tv":160.0,"id":475559}]}]}
{"op":"mcm","clk":"11804712878","pt":1723244654363,"mc":[{"id":"1.231582170","rc":[{"batb":[[0,1.93,10],[1,1.92,45.42],[2,1.48,52.08]],"ltp":1.96,"tv":160.0,"id":475559}]}]}
{"op":"mcm","clk":"11804712950","pt":1723244657662,"mc":[{"id":"1.231582170","rc":[{"batb":[[0,1.92,45.42],[1,1.48,52.08],[2,1.43,58.14]],"ltp":1.96,"tv":160.0,"id":475559}]}]}
{"op":"mcm","clk":"11804713026","pt":1723244660783,"mc":[{"id":"1.231582170","rc":[{"batb":[[0,1.93,10],[1,1.92,45.42],[2,1.48,52.08]],"ltp":1.96,"tv":160.0,"id":475559}]}]}
{"op":"mcm","clk":"11804713115","pt":1723244664171,"mc":[{"id":"1.231582170","rc":[{"batb":[[0,1.92,45.42],[1,1.48,52.08],[2,1.43,58.14]],"ltp":1.96,"tv":160.0,"id":475559}]}]}
{"op":"mcm","clk":"11804713175","pt":1723244666643,"mc":[{"id":"1.231582170","rc":[{"batb":[[0,1.93,10],[1,1.92,45.42],[2,1.48,52.08]],"ltp":1.96,"tv":160.0,"id":475559}]}]}
{"op":"mcm","clk":"11804713265","pt":1723244670055,"mc":[{"id":"1.231582170","rc":[{"batb":[[0,1.92,45.42],[1,1.48,52.08],[2,1.43,58.14]],"ltp":1.96,"tv":160.0,"id":475559}]}]}
{"op":"mcm","clk":"11804713357","pt":1723244673164,"mc":[{"id":"1.231582170","rc":[{"batb":[[0,1.93,10],[1,1.92,45.42],[2,1.48,52.08]],"ltp":1.96,"tv":160.0,"id":475559}]}]}
{"op":"mcm","clk":"11804713470","pt":1723244676488,"mc":[{"id":"1.231582170","rc":[{"batb":[[0,1.92,45.42],[1,1.48,52.08],[2,1.43,58.14]],"ltp":1.96,"tv":160.0,"id":475559}]}]}
{"op":"mcm","clk":"11804713590","pt":1723244680298,"mc":[{"id":"1.231582170","rc":[{"batb":[[0,1.93,10],[1,1.92,45.42],[2,1.48,52.08]],"ltp":1.96,"tv":160.0,"id":475559}]}]}
{"op":"mcm","clk":"11804713679","pt":1723244683689,"mc":[{"id":"1.231582170","rc":[{"batb":[[0,1.92,45.42],[1,1.48,52.08],[2,1.43,58.14]],"ltp":1.96,"tv":160.0,"id":475559}]}]}
{"op":"mcm","clk":"11804713739","pt":1723244685902,"mc":[{"id":"1.231582170","rc":[{"batb":[[0,1.93,10],[1,1.92,45.42],[2,1.48,52.08]],"ltp":1.96,"tv":160.0,"id":475559}]}]}
{"op":"mcm","clk":"11804713839","pt":1723244689193,"mc":[{"id":"1.231582170","rc":[{"batb":[[0,1.92,45.42],[1,1.48,52.08],[2,1.43,58.14]],"ltp":1.96,"tv":160.0,"id":475559}]}]}
{"op":"mcm","clk":"11804713931","pt":1723244692707,"mc":[{"id":"1.231582170","rc":[{"batb":[[0,1.93,10],[1,1.92,45.42],[2,1.48,52.08]],"ltp":1.96,"tv":160.0,"id":475559}]}]}
{"op":"mcm","clk":"11804714026","pt":1723244696200,"mc":[{"id":"1.231582170","rc":[{"batb":[[0,1.92,45.42],[1,1.48,52.08],[2,1.43,58.14]],"ltp":1.96,"tv":160.0,"id":475559}]}]}
{"op":"mcm","clk":"11804714080","pt":1723244698681,"mc":[{"id":"1.231582170","rc":[{"batb":[[0,1.93,10],[1,1.92,45.42],[2,1.48,52.08]],"ltp":1.96,"tv":160.0,"id":475559}]}]}
{"op":"mcm","clk":"11804714197","pt":1723244701889,"mc":[{"id":"1.231582170","rc":[{"batb":[[0,1.92,45.42],[1,1.48,52.08],[2,1.43,58.14]],"ltp":1.96,"tv":160.0,"id":475559}]}]}
{"op":"mcm","clk":"11804714317","pt":1723244705284,"mc":[{"id":"1.231582170","rc":[{"batb":[[0,1.93,10],[1,1.92,45.42],[2,1.48,52.08]],"ltp":1.96,"tv":160.0,"id":475559}]}]}
{"op":"mcm","clk":"11804714412","pt":1723244708626,"mc":[{"id":"1.231582170","rc":[{"batb":[[0,1.92,45.42],[1,1.48,52.08],[2,1.43,58.14]],"ltp":1.96,"tv":160.0,"id":475559}]}]}
{"op":"mcm","clk":"11804714484","pt":1723244711312,"mc":[{"id":"1.231582170","rc":[{"batb":[[0,1.93,10],[1,1.92,45.42],[2,1.48,52.08]],"ltp":1.96,"tv":160.0,"id":475559}]}]}
{"op":"mcm","clk":"11804714668","pt":1723244714724,"mc":[{"id":"1.231582170","rc":[{"batb":[[0,1.92,45.42],[1,1.48,52.08],[2,1.43,58.14]],"ltp":1.96,"tv":160.0,"id":475559}]}]}
{"op":"mcm","clk":"11804714806","pt":1723244717611,"mc":[{"id":"1.231582170","rc":[{"batb":[[0,1.93,10],[1,1.92,45.42],[2,1.48,52.08]],"ltp":1.96,"tv":160.0,"id":475559}]}]}
{"op":"mcm","clk":"11804714907","pt":1723244721014,"mc":[{"id":"1.231582170","rc":[{"batb":[[0,1.92,45.42],[1,1.48,52.08],[2,1.43,58.14]],"ltp":1.96,"tv":160.0,"id":475559}]}]}
{"op":"mcm","clk":"11804714969","pt":1723244723436,"mc":[{"id":"1.231582170","rc":[{"batb":[[0,1.93,10],[1,1.92,45.42],[2,1.48,52.08]],"ltp":1.96,"tv":160.0,"id":475559}]}]}
{"op":"mcm","clk":"11804715058","pt":1723244726836,"mc":[{"id":"1.231582170","rc":[{"batb":[[0,1.92,45.42],[1,1.48,52.08],[2,1.43,58.14]],"ltp":1.96,"tv":160.0,"id":475559}]}]}
{"op":"mcm","clk":"11804715179","pt":1723244730440,"mc":[{"id":"1.231582170","rc":[{"batb":[[0,1.93,10],[1,1.92,45.42],[2,1.48,52.08]],"ltp":1.96,"tv":160.0,"id":475559}]}]}
{"op":"mcm","clk":"11804715287","pt":1723244733753,"mc":[{"id":"1.231582170","rc":[{"batb":[[0,1.92,45.42],[1,1.48,52.08],[2,1.43,58.14]],"ltp":1.96,"tv":160.0,"id":475559}]}]}
{"op":"mcm","clk":"11804715356","pt":1723244736223,"mc":[{"id":"1.231582170","rc":[{"batb":[[0,1.93,10],[1,1.92,45.42],[2,1.48,52.08]],"ltp":1.96,"tv":160.0,"id":475559}]}]}
{"op":"mcm","clk":"11804715433","pt":1723244739719,"mc":[{"id":"1.231582170","rc":[{"batb":[[0,1.92,45.42],[1,1.48,52.08],[2,1.43,58.14]],"ltp":1.96,"tv":160.0,"id":475559}]}]}
{"op":"mcm","clk":"11804715497","pt":1723244742239,"mc":[{"id":"1.231582170","rc":[{"batb":[[0,1.93,10],[1,1.92,45.42],[2,1.48,52.08]],"ltp":1.96,"tv":160.0,"id":475559}]}]}
{"op":"mcm","clk":"11804715599","pt":1723244745837,"mc":[{"id":"1.231582170","rc":[{"batb":[[0,1.92,45.42],[1,1.48,52.08],[2,1.43,58.14]],"ltp":1.96,"tv":160.0,"id":475559}]}]}
{"op":"mcm","clk":"11804715665","pt":1723244748356,"mc":[{"id":"1.231582170","rc":[{"batb":[[0,1.93,10],[1,1.92,45.42],[2,1.48,52.08]],"ltp":1.96,"tv":160.0,"id":475559}]}]}
{"op":"mcm","clk":"11804715758","pt":1723244751855,"mc":[{"id":"1.231582170","rc":[{"batb":[[0,1.92,45.42],[1,1.48,52.08],[2,1.43,58.14]],"ltp":1.96,"tv":160.0,"id":475559}]}]}
{"op":"mcm","clk":"11804715821","pt":1723244754232,"mc":[{"id":"1.231582170","rc":[{"batb":[[0,1.93,10],[1,1.92,45.42],[2,1.48,52.08]],"ltp":1.96,"tv":160.0,"id":475559}]}]}
{"op":"mcm","clk":"11804715946","pt":1723244757643,"mc":[{"id":"1.231582170","rc":[{"batb":[[0,1.92,45.42],[1,1.48,52.08],[2,1.43,58.14]],"ltp":1.96,"tv":160.0,"id":475559}]}]}
{"op":"mcm","clk":"11804716054","pt":1723244761147,"mc":[{"id":"1.231582170","rc":[{"batb":[[0,1.93,10],[1,1.92,45.42],[2,1.48,52.08]],"ltp":1.96,"tv":160.0,"id":475559}]}]}
{"op":"mcm","clk":"11804716164","pt":1723244764485,"mc":[{"id":"1.231582170","rc":[{"batb":[[0,1.92,45.42],[1,1.48,52.08],[2,1.43,58.14]],"ltp":1.96,"tv":160.0,"id":475559}]}]}
{"op":"mcm","clk":"11804716231","pt":1723244767277,"mc":[{"id":"1.231582170","rc":[{"batb":[[0,1.93,10],[1,1.92,45.42],[2,1.48,52.08]],"ltp":1.96,"tv":160.0,"id":475559}]}]}
{"op":"mcm","clk":"11804716366","pt":1723244770874,"mc":[{"id":"1.231582170","rc":[{"batb":[[0,1.92,45.42],[1,1.48,52.08],[2,1.43,58.14]],"ltp":1.96,"tv":160.0,"id":475559}]}]}
{"op":"mcm","clk":"11804716462","pt":1723244774262,"mc":[{"id":"1.231582170","rc":[{"batb":[[0,1.93,10],[1,1.92,45.42],[2,1.48,52.08]],"ltp":1.96,"tv":160.0,"id":475559}]}]}
{"op":"mcm","clk":"11804716570","pt":1723244777769,"mc":[{"id":"1.231582170","rc":[{"batb":[[0,1.92,45.42],[1,1.48,52.08],[2,1.43,58.14]],"ltp":1.96,"tv":160.0,"id":475559}]}]}
{"op":"mcm","clk":"11804716647","pt":1723244780583,"mc":[{"id":"1.231582170","rc":[{"batb":[[0,1.93,10],[1,1.92,45.42],[2,1.48,52.08]],"ltp":1.96,"tv":160.0,"id":475559}]}]}
{"op":"mcm","clk":"11804716744","pt":1723244783886,"mc":[{"id":"1.231582170","rc":[{"batb":[[0,1.92,45.42],[1,1.48,52.08],[2,1.43,58.14]],"ltp":1.96,"tv":160.0,"id":475559}]}]}
{"op":"mcm","clk":"11804716852","pt":1723244788204,"mc":[{"id":"1.231582170","rc":[{"batb":[[0,1.93,10],[1,1.92,45.42],[2,1.48,52.08]],"ltp":1.96,"tv":160.0,"id":475559}]}]}
{"op":"mcm","clk":"11804716957","pt":1723244791611,"mc":[{"id":"1.231582170","rc":[{"batb":[[0,1.92,45.42],[1,1.48,52.08],[2,1.43,58.14]],"ltp":1.96,"tv":160.0,"id":475559}]}]}
{"op":"mcm","clk":"11804717068","pt":1723244795481,"mc":[{"id":"1.231582170","rc":[{"batb":[[0,1.93,10],[1,1.92,45.42],[2,1.48,52.08]],"ltp":1.96,"tv":160.0,"id":475559}]}]}
{"op":"mcm","clk":"11804717157","pt":1723244798779,"mc":[{"id":"1.231582170","rc":[{"batb":[[0,1.92,45.42],[1,1.48,52.08],[2,1.43,58.14]],"ltp":1.96,"tv":160.0,"id":475559}]}]}
{"op":"mcm","clk":"11804717259","pt":1723244801522,"mc":[{"id":"1.231582170","rc":[{"batb":[[0,1.93,10],[1,1.92,45.42],[2,1.48,52.08]],"ltp":1.96,"tv":160.0,"id":475559}]}]}
{"op":"mcm","clk":"11804717342","pt":1723244804702,"mc":[{"id":"1.231582170","rc":[{"batb":[[0,1.92,45.42],[1,1.48,52.08],[2,1.43,58.14]],"ltp":1.96,"tv":160.0,"id":475559}]}]}
{"op":"mcm","clk":"11804717460","pt":1723244808208,"mc":[{"id":"1.231582170","rc":[{"batb":[[0,1.93,10],[1,1.92,45.42],[2,1.48,52.08]],"ltp":1.96,"tv":160.0,"id":475559}]}]}
{"op":"mcm","clk":"11804717568","pt":1723244811510,"mc":[{"id":"1.231582170","rc":[{"batb":[[0,1.92,45.42],[1,1.48,52.08],[2,1.43,58.14]],"ltp":1.96,"tv":160.0,"id":475559}]}]}
{"op":"mcm","clk":"11804717639","pt":1723244814334,"mc":[{"id":"1.231582170","rc":[{"batb":[[0,1.93,10],[1,1.92,45.42],[2,1.48,52.08]],"ltp":1.96,"tv":160.0,"id":475559}]}]}
{"op":"mcm","clk":"11804717721","pt":1723244817625,"mc":[{"id":"1.231582170","rc":[{"batb":[[0,1.92,45.42],[1,1.48,52.08],[2,1.43,58.14]],"ltp":1.96,"tv":160.0,"id":475559}]}]}
{"op":"mcm","clk":"11804717774","pt":1723244819938,"mc":[{"id":"1.231582170","rc":[{"batb":[[0,1.93,10],[1,1.92,45.42],[2,1.48,52.08]],"ltp":1.96,"tv":160.0,"id":475559}]}]}
{"op":"mcm","clk":"11804717851","pt":1723244823248,"mc":[{"id":"1.231582170","rc":[{"batb":[[0,1.92,45.42],[1,1.48,52.08],[2,1.43,58.14]],"ltp":1.96,"tv":160.0,"id":475559}]}]}
{"op":"mcm","clk":"11804717921","pt":1723244826518,"mc":[{"id":"1.231582170","rc":[{"batb":[[0,1.93,10],[1,1.92,45.42],[2,1.48,52.08]],"ltp":1.96,"tv":160.0,"id":475559}]}]}
{"op":"mcm","clk":"11804718011","pt":1723244829761,"mc":[{"id":"1.231582170","rc":[{"batb":[[0,1.92,45.42],[1,1.48,52.08],[2,1.43,58.14]],"ltp":1.96,"tv":160.0,"id":475559}]}]}
{"op":"mcm","clk":"11804718098","pt":1723244832444,"mc":[{"id":"1.231582170","rc":[{"batb":[[0,1.93,10],[1,1.92,45.42],[2,1.48,52.08]],"ltp":1.96,"tv":160.0,"id":475559}]}]}
{"op":"mcm","clk":"11804718218","pt":1723244835751,"mc":[{"id":"1.231582170","rc":[{"batb":[[0,1.92,45.42],[1,1.48,52.08],[2,1.43,58.14]],"ltp":1.96,"tv":160.0,"id":475559}]}]}
{"op":"mcm","clk":"11804718365","pt":1723244839278,"mc":[{"id":"1.231582170","rc":[{"batb":[[0,1.93,10],[1,1.92,45.42],[2,1.48,52.08]],"ltp":1.96,"tv":160.0,"id":475559}]}]}
{"op":"mcm","clk":"11804718446","pt":1723244842572,"mc":[{"id":"1.231582170","rc":[{"batb":[[0,1.92,45.42],[1,1.48,52.08],[2,1.43,58.14]],"ltp":1.96,"tv":160.0,"id":475559}]}]}
{"op":"mcm","clk":"11804718548","pt":1723244845757,"mc":[{"id":"1.231582170","rc":[{"batb":[[0,1.93,10],[1,1.92,45.42],[2,1.48,52.08]],"ltp":1.96,"tv":160.0,"id":475559}]}]}
{"op":"mcm","clk":"11804718658","pt":1723244849052,"mc":[{"id":"1.231582170","rc":[{"batb":[[0,1.92,45.42],[1,1.48,52.08],[2,1.43,58.14]],"ltp":1.96,"tv":160.0,"id":475559}]}]}
{"op":"mcm","clk":"11804718741","pt":1723244851575,"mc":[{"id":"1.231582170","rc":[{"batb":[[0,1.93,10],[1,1.92,45.42],[2,1.48,52.08]],"ltp":1.96,"tv":160.0,"id":475559}]}]}
{"op":"mcm","clk":"11804718856","pt":1723244855545,"mc":[{"id":"1.231582170","rc":[{"batb":[[0,1.92,45.42],[1,1.48,52.08],[2,1.43,58.14]],"ltp":1.96,"tv":160.0,"id":475559}]}]}
{"op":"mcm","clk":"11804718945","pt":1723244858390,"mc":[{"id":"1.231582170","rc":[{"batb":[[0,1.93,10],[1,1.92,45.42],[2,1.48,52.08]],"ltp":1.96,"tv":160.0,"id":475559}]}]}
{"op":"mcm","clk":"11804719049","pt":1723244861693,"mc":[{"id":"1.231582170","rc":[{"batb":[[0,1.92,45.42],[1,1.48,52.08],[2,1.43,58.14]],"ltp":1.96,"tv":160.0,"id":475559}]}]}
{"op":"mcm","clk":"11804719151","pt":1723244864998,"mc":[{"id":"1.231582170","rc":[{"batb":[[0,1.93,10],[1,1.92,45.42],[2,1.48,52.08]],"ltp":1.96,"tv":160.0,"id":475559}]}]}
{"op":"mcm","clk":"11804719249","pt":1723244868398,"mc":[{"id":"1.231582170","rc":[{"batb":[[0,1.92,45.42],[1,1.48,52.08],[2,1.43,58.14]],"ltp":1.96,"tv":160.0,"id":475559}]}]}
{"op":"mcm","clk":"11804719344","pt":1723244871284,"mc":[{"id":"1.231582170","rc":[{"batb":[[0,1.93,10],[1,1.92,45.42],[2,1.48,52.08]],"ltp":1.96,"tv":160.0,"id":475559}]}]}
{"op":"mcm","clk":"11804719443","pt":1723244874817,"mc":[{"id":"1.231582170","rc":[{"batb":[[0,1.92,45.42],[1,1.48,52.08],[2,1.43,58.14]],"ltp":1.96,"tv":160.0,"id":475559}]}]}
{"op":"mcm","clk":"11804719517","pt":1723244877205,"mc":[{"id":"1.231582170","rc":[{"batb":[[0,1.93,10],[1,1.92,45.42],[2,1.48,52.08]],"ltp":1.96,"tv":160.0,"id":475559}]}]}
{"op":"mcm","clk":"11804719593","pt":1723244880596,"mc":[{"id":"1.231582170","rc":[{"batb":[[0,1.92,45.42],[1,1.48,52.08],[2,1.43,58.14]],"ltp":1.96,"tv":160.0,"id":475559}]}]}
{"op":"mcm","clk":"11804719683","pt":1723244883218,"mc":[{"id":"1.231582170","rc":[{"batb":[[0,1.93,10],[1,1.92,45.42],[2,1.48,52.08]],"ltp":1.96,"tv":160.0,"id":475559}]}]}
{"op":"mcm","clk":"11804719789","pt":1723244886513,"mc":[{"id":"1.231582170","rc":[{"batb":[[0,1.92,45.42],[1,1.48,52.08],[2,1.43,58.14]],"ltp":1.96,"tv":160.0,"id":475559}]}]}
{"op":"mcm","clk":"11804719892","pt":1723244890281,"mc":[{"id":"1.231582170","rc":[{"batb":[[0,1.93,10],[1,1.92,45.42],[2,1.48,52.08]],"ltp":1.96,"tv":160.0,"id":475559}]}]}
{"op":"mcm","clk":"11804720004","pt":1723244893516,"mc":[{"id":"1.231582170","rc":[{"batb":[[0,1.92,45.42],[1,1.48,52.08],[2,1.43,58.14]],"ltp":1.96,"tv":160.0,"id":475559}]}]}
{"op":"mcm","clk":"11804720148","pt":1723244897017,"mc":[{"id":"1.231582170","rc":[{"batb":[[0,1.93,10],[1,1.92,45.42],[2,1.48,52.08]],"ltp":1.96,"tv":160.0,"id":475559}]}]}
{"op":"mcm","clk":"11804720282","pt":1723244900510,"mc":[{"id":"1.231582170","rc":[{"batb":[[0,1.92,45.42],[1,1.48,52.08],[2,1.43,58.14]],"ltp":1.96,"tv":160.0,"id":475559}]}]}
{"op":"mcm","clk":"11804720436","pt":1723244905746,"mc":[{"id":"1.231582170","rc":[{"batb":[[0,1.93,10],[1,1.92,45.42],[2,1.48,52.08]],"ltp":1.96,"tv":160.0,"id":475559}]}]}
{"op":"mcm","clk":"11804720576","pt":1723244909041,"mc":[{"id":"1.231582170","rc":[{"batb":[[0,1.92,45.42],[1,1.48,52.08],[2,1.43,58.14]],"ltp":1.96,"tv":160.0,"id":475559}]}]}
{"op":"mcm","clk":"11804720677","pt":1723244911568,"mc":[{"id":"1.231582170","rc":[{"batb":[[0,1.93,10],[1,1.92,45.42],[2,1.48,52.08]],"ltp":1.96,"tv":160.0,"id":475559}]}]}
{"op":"mcm","clk":"11804720819","pt":1723244914915,"mc":[{"id":"1.231582170","rc":[{"batb":[[0,1.92,45.42],[1,1.48,52.08],[2,1.43,58.14]],"ltp":1.96,"tv":160.0,"id":475559}]}]}
{"op":"mcm","clk":"11804720902","pt":1723244917541,"mc":[{"id":"1.231582170","rc":[{"batb":[[0,1.93,10],[1,1.92,45.42],[2,1.48,52.08]],"ltp":1.96,"tv":160.0,"id":475559}]}]}
{"op":"mcm","clk":"11804721014","pt":1723244920930,"mc":[{"id":"1.231582170","rc":[{"batb":[[0,1.92,45.42],[1,1.48,52.08],[2,1.43,58.14]],"ltp":1.96,"tv":160.0,"id":475559}]}]}
{"op":"mcm","clk":"11804721099","pt":1723244923543,"mc":[{"id":"1.231582170","rc":[{"batb":[[0,1.93,10],[1,1.92,45.42],[2,1.48,52.08]],"ltp":1.96,"tv":160.0,"id":475559}]}]}
{"op":"mcm","clk":"11804721215","pt":1723244927452,"mc":[{"id":"1.231582170","rc":[{"batb":[[0,1.92,45.42],[1,1.48,52.08],[2,1.43,58.14]],"ltp":1.96,"tv":160.0,"id":475559}]}]}
{"op":"mcm","clk":"11804721315","pt":1723244930476,"mc":[{"id":"1.231582170","rc":[{"batb":[[0,1.93,10],[1,1.92,45.42],[2,1.48,52.08]],"ltp":1.96,"tv":160.0,"id":475559}]}]}
{"op":"mcm","clk":"11804721408","pt":1723244933970,"mc":[{"id":"1.231582170","rc":[{"batb":[[0,1.92,45.42],[1,1.48,52.08],[2,1.43,58.14]],"ltp":1.96,"tv":160.0,"id":475559}]}]}
{"op":"mcm","clk":"11804721493","pt":1723244937046,"mc":[{"id":"1.231582170","rc":[{"batb":[[0,1.93,10],[1,1.92,45.42],[2,1.48,52.08]],"ltp":1.96,"tv":160.0,"id":475559}]}]}
{"op":"mcm","clk":"11804721591","pt":1723244940385,"mc":[{"id":"1.231582170","rc":[{"batb":[[0,1.92,45.42],[1,1.48,52.08],[2,1.43,58.14]],"ltp":1.96,"tv":160.0,"id":475559}]}]}
{"op":"mcm","clk":"11804721647","pt":1723244942651,"mc":[{"id":"1.231582170","rc":[{"batb":[[0,1.93,10],[1,1.92,45.42],[2,1.48,52.08]],"ltp":1.96,"tv":160.0,"id":475559}]}]}
{"op":"mcm","clk":"11804721734","pt":1723244946094,"mc":[{"id":"1.231582170","rc":[{"batb":[[0,1.92,45.42],[1,1.48,52.08],[2,1.43,58.14]],"ltp":1.96,"tv":160.0,"id":475559}]}]}
{"op":"mcm","clk":"11804721823","pt":1723244948309,"mc":[{"id":"1.231582170","rc":[{"batb":[[0,1.93,10],[1,1.92,45.42],[2,1.48,52.08]],"ltp":1.96,"tv":160.0,"id":475559}]}]}
{"op":"mcm","clk":"11804721988","pt":1723244951885,"mc":[{"id":"1.231582170","rc":[{"batb":[[0,1.92,45.42],[1,1.48,52.08],[2,1.43,58.14]],"ltp":1.96,"tv":160.0,"id":475559}]}]}
{"op":"mcm","clk":"11804722117","pt":1723244955521,"mc":[{"id":"1.231582170","rc":[{"batb":[[0,1.93,10],[1,1.92,45.42],[2,1.48,52.08]],"ltp":1.96,"tv":160.0,"id":475559}]}]}
{"op":"mcm","clk":"11804722243","pt":1723244958712,"mc":[{"id":"1.231582170","rc":[{"batb":[[0,1.92,45.42],[1,1.48,52.08],[2,1.43,58.14]],"ltp":1.96,"tv":160.0,"id":475559}]}]}
{"op":"mcm","clk":"11804722335","pt":1723244961126,"mc":[{"id":"1.231582170","rc":[{"batb":[[0,1.93,10],[1,1.92,45.42],[2,1.48,52.08]],"ltp":1.96,"tv":160.0,"id":475559}]}]}
{"op":"mcm","clk":"11804722466","pt":1723244964627,"mc":[{"id":"1.231582170","rc":[{"batb":[[0,1.92,45.42],[1,1.48,52.08],[2,1.43,58.14]],"ltp":1.96,"tv":160.0,"id":475559}]}]}
{"op":"mcm","clk":"11804722585","pt":1723244967805,"mc":[{"id":"1.231582170","rc":[{"batb":[[0,1.93,10],[1,1.92,45.42],[2,1.48,52.08]],"ltp":1.96,"tv":160.0,"id":475559}]}]}
{"op":"mcm","clk":"11804722706","pt":1723244971101,"mc":[{"id":"1.231582170","rc":[{"batb":[[0,1.92,45.42],[1,1.48,52.08],[2,1.43,58.14]],"ltp":1.96,"tv":160.0,"id":475559}]}]}
{"op":"mcm","clk":"11804722873","pt":1723244976801,"mc":[{"id":"1.231582170","rc":[{"batb":[[0,1.93,10],[1,1.92,45.42],[2,1.48,52.08]],"ltp":1.96,"tv":160.0,"id":475559}]}]}
{"op":"mcm","clk":"11804722973","pt":1723244980344,"mc":[{"id":"1.231582170","rc":[{"batb":[[0,1.92,45.42],[1,1.48,52.08],[2,1.43,58.14]],"ltp":1.96,"tv":160.0,"id":475559}]}]}
{"op":"mcm","clk":"11804723053","pt":1723244982914,"mc":[{"id":"1.231582170","rc":[{"batb":[[0,1.93,10],[1,1.92,45.42],[2,1.48,52.08]],"ltp":1.96,"tv":160.0,"id":475559}]}]}
{"op":"mcm","clk":"11804723163","pt":1723244986209,"mc":[{"id":"1.231582170","rc":[{"batb":[[0,1.92,45.42],[1,1.48,52.08],[2,1.43,58.14]],"ltp":1.96,"tv":160.0,"id":475559}]}]}
{"op":"mcm","clk":"11804723277","pt":1723244988745,"mc":[{"id":"1.231582170","rc":[{"batb":[[0,1.93,10],[1,1.92,45.42],[2,1.48,52.08]],"ltp":1.96,"tv":160.0,"id":475559}]}]}
{"op":"mcm","clk":"11804723411","pt":1723244992336,"mc":[{"id":"1.231582170","rc":[{"batb":[[0,1.92,45.42],[1,1.48,52.08],[2,1.43,58.14]],"ltp":1.96,"tv":160.0,"id":475559}]}]}
{"op":"mcm","clk":"11804723525","pt":1723244996960,"mc":[{"id":"1.231582170","rc":[{"batb":[[0,1.93,10],[1,1.92,45.42],[2,1.48,52.08]],"ltp":1.96,"tv":160.0,"id":475559}]}]}
{"op":"mcm","clk":"11804723623","pt":1723245000457,"mc":[{"id":"1.231582170","rc":[{"batb":[[0,1.92,45.42],[1,1.48,52.08],[2,1.43,58.14]],"ltp":1.96,"tv":160.0,"id":475559}]}]}
{"op":"mcm","clk":"11804723789","pt":1723245005452,"mc":[{"id":"1.231582170","rc":[{"batb":[[0,1.93,10],[1,1.92,45.42],[2,1.48,52.08]],"ltp":1.96,"tv":160.0,"id":475559}]}]}
{"op":"mcm","clk":"11804723919","pt":1723245008746,"mc":[{"id":"1.231582170","rc":[{"batb":[[0,1.92,45.42],[1,1.48,52.08],[2,1.43,58.14]],"ltp":1.96,"tv":160.0,"id":475559}]}]}
{"op":"mcm","clk":"11804724011","pt":1723245011371,"mc":[{"id":"1.231582170","rc":[{"batb":[[0,1.93,10],[1,1.92,45.42],[2,1.48,52.08]],"ltp":1.96,"tv":160.0,"id":475559}]}]}
{"op":"mcm","clk":"11804724124","pt":1723245014769,"mc":[{"id":"1.231582170","rc":[{"batb":[[0,1.92,45.42],[1,1.48,52.08],[2,1.43,58.14]],"ltp":1.96,"tv":160.0,"id":475559}]}]}
{"op":"mcm","clk":"11804724244","pt":1723245018990,"mc":[{"id":"1.231582170","rc":[{"batb":[[0,1.93,10],[1,1.92,45.42],[2,1.48,52.08]],"ltp":1.96,"tv":160.0,"id":475559}]}]}
{"op":"mcm","clk":"11804724328","pt":1723245022894,"mc":[{"id":"1.231582170","rc":[{"batb":[[0,1.92,45.42],[1,1.48,52.08],[2,1.43,58.14]],"ltp":1.96,"tv":160.0,"id":475559}]}]}
{"op":"mcm","clk":"11804724431","pt":1723245026491,"mc":[{"id":"1.231582170","rc":[{"batb":[[0,1.93,10],[1,1.92,45.42],[2,1.48,52.08]],"ltp":1.96,"tv":160.0,"id":475559}]}]}
{"op":"mcm","clk":"11804724516","pt":1723245029885,"mc":[{"id":"1.231582170","rc":[{"batb":[[0,1.92,45.42],[1,1.48,52.08],[2,1.43,58.14]],"ltp":1.96,"tv":160.0,"id":475559}]}]}
{"op":"mcm","clk":"11804724574","pt":1723245031997,"mc":[{"id":"1.231582170","rc":[{"batb":[[0,1.93,10],[1,1.92,45.42],[2,1.48,52.08]],"ltp":1.96,"tv":160.0,"id":475559}]}]}
{"op":"mcm","clk":"11804724690","pt":1723245035290,"mc":[{"id":"1.231582170","rc":[{"batb":[[0,1.92,45.42],[1,1.48,52.08],[2,1.43,58.14]],"ltp":1.96,"tv":160.0,"id":475559}]}]}
{"op":"mcm","clk":"11804724759","pt":1723245037699,"mc":[{"id":"1.231582170","rc":[{"batb":[[0,1.93,10],[1,1.92,45.42],[2,1.48,52.08]],"ltp":1.96,"tv":160.0,"id":475559}]}]}
{"op":"mcm","clk":"11804724886","pt":1723245041193,"mc":[{"id":"1.231582170","rc":[{"batb":[[0,1.92,45.42],[1,1.48,52.08],[2,1.43,58.14]],"ltp":1.96,"tv":160.0,"id":475559}]}]}
{"op":"mcm","clk":"11804724981","pt":1723245043610,"mc":[{"id":"1.231582170","rc":[{"batb":[[0,1.93,10],[1,1.92,45.42],[2,1.48,52.08]],"ltp":1.96,"tv":160.0,"id":475559}]}]}
{"op":"mcm","clk":"11804725076","pt":1723245046993,"mc":[{"id":"1.231582170","rc":[{"batb":[[0,1.92,45.42],[1,1.48,52.08],[2,1.43,58.14]],"ltp":1.96,"tv":160.0,"id":475559}]}]}
{"op":"mcm","clk":"11804725192","pt":1723245050536,"mc":[{"id":"1.231582170","rc":[{"batb":[[0,1.93,10],[1,1.92,45.42],[2,1.48,52.08]],"ltp":1.96,"tv":160.0,"id":475559}]}]}
{"op":"mcm","clk":"11804725297","pt":1723245053835,"mc":[{"id":"1.231582170","rc":[{"batb":[[0,1.92,45.42],[1,1.48,52.08],[2,1.43,58.14]],"ltp":1.96,"tv":160.0,"id":475559}]}]}
{"op":"mcm","clk":"11804725406","pt":1723245057222,"mc":[{"id":"1.231582170","rc":[{"batb":[[0,1.93,10],[1,1.92,45.42],[2,1.48,52.08]],"ltp":1.96,"tv":160.0,"id":475559}]}]}
{"op":"mcm","clk":"11804725505","pt":1723245060649,"mc":[{"id":"1.231582170","rc":[{"batb":[[0,1.92,45.42],[1,1.48,52.08],[2,1.43,58.14]],"ltp":1.96,"tv":160.0,"id":475559}]}]}
{"op":"mcm","clk":"11804725580","pt":1723245063066,"mc":[{"id":"1.231582170","rc":[{"batb":[[0,1.93,10],[1,1.92,45.42],[2,1.48,52.08]],"ltp":1.96,"tv":160.0,"id":475559}]}]}
{"op":"mcm","clk":"11804725699","pt":1723245066260,"mc":[{"id":"1.231582170","rc":[{"batb":[[0,1.92,45.42],[1,1.48,52.08],[2,1.43,58.14]],"ltp":1.96,"tv":160.0,"id":475559}]}]}
{"op":"mcm","clk":"11804725788","pt":1723245069084,"mc":[{"id":"1.231582170","rc":[{"batb":[[0,1.93,10],[1,1.92,45.42],[2,1.48,52.08]],"ltp":1.96,"tv":160.0,"id":475559}]}]}
{"op":"mcm","clk":"11804725923","pt":1723245072359,"mc":[{"id":"1.231582170","rc":[{"batb":[[0,1.92,45.42],[1,1.48,52.08],[2,1.43,58.14]],"ltp":1.96,"tv":160.0,"id":475559}]}]}
{"op":"mcm","clk":"11804726009","pt":1723245074769,"mc":[{"id":"1.231582170","rc":[{"batb":[[0,1.93,10],[1,1.92,45.42],[2,1.48,52.08]],"ltp":1.96,"tv":160.0,"id":475559}]}]}
{"op":"mcm","clk":"11804726102","pt":1723245078161,"mc":[{"id":"1.231582170","rc":[{"batb":[[0,1.92,45.42],[1,1.48,52.08],[2,1.43,58.14]],"ltp":1.96,"tv":160.0,"id":475559}]}]}
{"op":"mcm","clk":"11804726191","pt":1723245080874,"mc":[{"id":"1.231582170","rc":[{"batb":[[0,1.93,10],[1,1.92,45.42],[2,1.48,52.08]],"ltp":1.96,"tv":160.0,"id":475559}]}]}
{"op":"mcm","clk":"11804726281","pt":1723245084163,"mc":[{"id":"1.231582170","rc":[{"batb":[[0,1.92,45.42],[1,1.48,52.08],[2,1.43,58.14]],"ltp":1.96,"tv":160.0,"id":475559}]}]}
{"op":"mcm","clk":"11804726384","pt":1723245087656,"mc":[{"id":"1.231582170","rc":[{"batb":[[0,1.93,10],[1,1.92,45.42],[2,1.48,52.08]],"ltp":1.96,"tv":160.0,"id":475559}]}]}
{"op":"mcm","clk":"11804726471","pt":1723245091057,"mc":[{"id":"1.231582170","rc":[{"batb":[[0,1.92,45.42],[1,1.48,52.08],[2,1.43,58.14]],"ltp":1.96,"tv":160.0,"id":475559}]}]}
{"op":"mcm","clk":"11804726549","pt":1723245093686,"mc":[{"id":"1.231582170","rc":[{"batb":[[0,1.93,10],[1,1.92,45.42],[2,1.48,52.08]],"ltp":1.96,"tv":160.0,"id":475559}]}]}
{"op":"mcm","clk":"11804726657","pt":1723245096970,"mc":[{"id":"1.231582170","rc":[{"batb":[[0,1.92,45.42],[1,1.48,52.08],[2,1.43,58.14]],"ltp":1.96,"tv":160.0,"id":475559}]}]}
{"op":"mcm","clk":"11804726754","pt":1723245099692,"mc":[{"id":"1.231582170","rc":[{"batb":[[0,1.93,10],[1,1.92,45.42],[2,1.48,52.08]],"ltp":1.96,"tv":160.0,"id":475559}]}]}
{"op":"mcm","clk":"11804726840","pt":1723245103082,"mc":[{"id":"1.231582170","rc":[{"batb":[[0,1.92,45.42],[1,1.48,52.08],[2,1.43,58.14]],"ltp":1.96,"tv":160.0,"id":475559}]}]}
{"op":"mcm","clk":"11804726938","pt":1723245106776,"mc":[{"id":"1.231582170","rc":[{"batb":[[0,1.93,10],[1,1.92,45.42],[2,1.48,52.08]],"ltp":1.96,"tv":160.0,"id":475559}]}]}
{"op":"mcm","clk":"11804727018","pt":1723245110314,"mc":[{"id":"1.231582170","rc":[{"batb":[[0,1.92,45.42],[1,1.48,52.08],[2,1.43,58.14]],"ltp":1.96,"tv":160.0,"id":475559}]}]}
{"op":"mcm","clk":"11804727096","pt":1723245113086,"mc":[{"id":"1.231582170","rc":[{"batb":[[0,1.93,10],[1,1.92,45.42],[2,1.48,52.08]],"ltp":1.96,"tv":160.0,"id":475559}]}]}
{"op":"mcm","clk":"11804727193","pt":1723245116525,"mc":[{"id":"1.231582170","rc":[{"batb":[[0,1.92,45.42],[1,1.48,52.08],[2,1.43,58.14]],"ltp":1.96,"tv":160.0,"id":475559}]}]}
{"op":"mcm","clk":"11804727260","pt":1723245118885,"mc":[{"id":"1.231582170","rc":[{"batb":[[0,1.93,10],[1,1.92,45.42],[2,1.48,52.08]],"ltp":1.96,"tv":160.0,"id":475559}]}]}
{"op":"mcm","clk":"11804727364","pt":1723245122334,"mc":[{"id":"1.231582170","rc":[{"batb":[[0,1.92,45.42],[1,1.48,52.08],[2,1.43,58.14]],"ltp":1.96,"tv":160.0,"id":475559}]}]}
{"op":"mcm","clk":"11804727471","pt":1723245125901,"mc":[{"id":"1.231582170","rc":[{"batb":[[0,1.93,10],[1,1.92,45.42],[2,1.48,52.08]],"ltp":1.96,"tv":160.0,"id":475559}]}]}
{"op":"mcm","clk":"11804727567","pt":1723245129239,"mc":[{"id":"1.231582170","rc":[{"batb":[[0,1.92,45.42],[1,1.48,52.08],[2,1.43,58.14]],"ltp":1.96,"tv":160.0,"id":475559}]}]}
{"op":"mcm","clk":"11804727675","pt":1723245131606,"mc":[{"id":"1.231582170","rc":[{"batb":[[0,1.93,10],[1,1.92,45.42],[2,1.48,52.08]],"ltp":1.96,"tv":160.0,"id":475559}]}]}
{"op":"mcm","clk":"11804727809","pt":1723245135043,"mc":[{"id":"1.231582170","rc":[{"batb":[[0,1.92,45.42],[1,1.48,52.08],[2,1.43,58.14]],"ltp":1.96,"tv":160.0,"id":475559}]}]}
{"op":"mcm","clk":"11804727897","pt":1723245137353,"mc":[{"id":"1.231582170","rc":[{"batb":[[0,1.93,10],[1,1.92,45.42],[2,1.48,52.08]],"ltp":1.96,"tv":160.0,"id":475559}]}]}
{"op":"mcm","clk":"11804728003","pt":1723245140634,"mc":[{"id":"1.231582170","rc":[{"batb":[[0,1.92,45.42],[1,1.48,52.08],[2,1.43,58.14]],"ltp":1.96,"tv":160.0,"id":475559}]}]}
{"op":"mcm","clk":"11804728080","pt":1723245143154,"mc":[{"id":"1.231582170","rc":[{"batb":[[0,1.93,10],[1,1.92,45.42],[2,1.48,52.08]],"ltp":1.96,"tv":160.0,"id":475559}]}]}
{"op":"mcm","clk":"11804728235","pt":1723245146956,"mc":[{"id":"1.231582170","rc":[{"batb":[[0,1.92,45.42],[1,1.48,52.08],[2,1.43,58.14]],"ltp":1.96,"tv":160.0,"id":475559}]}]}
{"op":"mcm","clk":"11804728358","pt":1723245150856,"mc":[{"id":"1.231582170","rc":[{"batb":[[0,1.93,10],[1,1.92,45.42],[2,1.48,52.08]],"ltp":1.96,"tv":160.0,"id":475559}]}]}
{"op":"mcm","clk":"11804728471","pt":1723245154343,"mc":[{"id":"1.231582170","rc":[{"batb":[[0,1.92,45.42],[1,1.48,52.08],[2,1.43,58.14]],"ltp":1.96,"tv":160.0,"id":475559}]}]}
{"op":"mcm","clk":"11804728569","pt":1723245157372,"mc":[{"id":"1.231582170","rc":[{"batb":[[0,1.93,10],[1,1.92,45.42],[2,1.48,52.08]],"ltp":1.96,"tv":160.0,"id":475559}]}]}
{"op":"mcm","clk":"11804728713","pt":1723245160975,"mc":[{"id":"1.231582170","rc":[{"batb":[[0,1.92,45.42],[1,1.48,52.08],[2,1.43,58.14]],"ltp":1.96,"tv":160.0,"id":475559}]}]}
{"op":"mcm","clk":"11804728832","pt":1723245164567,"mc":[{"id":"1.231582170","rc":[{"batb":[[0,1.93,10],[1,1.92,45.42],[2,1.48,52.08]],"ltp":1.96,"tv":160.0,"id":475559}]}]}
{"op":"mcm","clk":"11804728957","pt":1723245167853,"mc":[{"id":"1.231582170","rc":[{"batb":[[0,1.92,45.42],[1,1.48,52.08],[2,1.43,58.14]],"ltp":1.96,"tv":160.0,"id":475559}]}]}
{"op":"mcm","clk":"11804729054","pt":1723245170380,"mc":[{"id":"1.231582170","rc":[{"batb":[[0,1.93,10],[1,1.92,45.42],[2,1.48,52.08]],"ltp":1.96,"tv":160.0,"id":475559}]}]}
{"op":"mcm","clk":"11804729143","pt":1723245173665,"mc":[{"id":"1.231582170","rc":[{"batb":[[0,1.92,45.42],[1,1.48,52.08],[2,1.43,58.14]],"ltp":1.96,"tv":160.0,"id":475559}]}]}
{"op":"mcm","clk":"11804729237","pt":1723245176356,"mc":[{"id":"1.231582170","rc":[{"batb":[[0,1.93,10],[1,1.92,45.42],[2,1.48,52.08]],"ltp":1.96,"tv":160.0,"id":475559}]}]}
{"op":"mcm","clk":"11804729351","pt":1723245179800,"mc":[{"id":"1.231582170","rc":[{"batb":[[0,1.92,45.42],[1,1.48,52.08],[2,1.43,58.14]],"ltp":1.96,"tv":160.0,"id":475559}]}]}
{"op":"mcm","clk":"11804729450","pt":1723245182802,"mc":[{"id":"1.231582170","rc":[{"batb":[[0,1.93,10],[1,1.92,45.42],[2,1.48,52.08]],"ltp":1.96,"tv":160.0,"id":475559}]}]}
{"op":"mcm","clk":"11804729589","pt":1723245186288,"mc":[{"id":"1.231582170","rc":[{"batb":[[0,1.92,45.42],[1,1.48,52.08],[2,1.43,58.14]],"ltp":1.96,"tv":160.0,"id":475559}]}]}
{"op":"mcm","clk":"11804729747","pt":1723245189781,"mc":[{"id":"1.231582170","rc":[{"batb":[[0,1.93,10],[1,1.92,45.42],[2,1.48,52.08]],"ltp":1.96,"tv":160.0,"id":475559}]}]}
{"op":"mcm","clk":"11804729870","pt":1723245193013,"mc":[{"id":"1.231582170","rc":[{"batb":[[0,1.92,45.42],[1,1.48,52.08],[2,1.43,58.14]],"ltp":1.96,"tv":160.0,"id":475559}]}]}
{"op":"mcm","clk":"11804729996","pt":1723245196765,"mc":[{"id":"1.231582170","rc":[{"batb":[[0,1.93,10],[1,1.92,45.42],[2,1.48,52.08]],"ltp":1.96,"tv":160.0,"id":475559}]}]}
{"op":"mcm","clk":"11804730122","pt":1723245200099,"mc":[{"id":"1.231582170","rc":[{"batb":[[0,1.92,45.42],[1,1.48,52.08],[2,1.43,58.14]],"ltp":1.96,"tv":160.0,"id":475559}]}]}
{"op":"mcm","clk":"11804730244","pt":1723245203507,"mc":[{"id":"1.231582170","rc":[{"batb":[[0,1.93,10],[1,1.92,45.42],[2,1.48,52.08]],"ltp":1.96,"tv":160.0,"id":475559}]}]}
{"op":"mcm","clk":"11804730376","pt":1723245206787,"mc":[{"id":"1.231582170","rc":[{"batb":[[0,1.92,45.42],[1,1.48,52.08],[2,1.43,58.14]],"ltp":1.96,"tv":160.0,"id":475559}]}]}
{"op":"mcm","clk":"11804730484","pt":1723245210125,"mc":[{"id":"1.231582170","rc":[{"batb":[[0,1.93,10],[1,1.92,45.42],[2,1.48,52.08]],"ltp":1.96,"tv":160.0,"id":475559}]}]}
{"op":"mcm","clk":"11804730606","pt":1723245213823,"mc":[{"id":"1.231582170","rc":[{"batb":[[0,1.92,45.42],[1,1.48,52.08],[2,1.43,58.14]],"ltp":1.96,"tv":160.0,"id":475559}]}]}
{"op":"mcm","clk":"11804730695","pt":1723245216518,"mc":[{"id":"1.231582170","rc":[{"batb":[[0,1.93,10],[1,1.92,45.42],[2,1.48,52.08]],"ltp":1.96,"tv":160.0,"id":475559}]}]}
{"op":"mcm","clk":"11804730800","pt":1723245220006,"mc":[{"id":"1.231582170","rc":[{"batb":[[0,1.92,45.42],[1,1.48,52.08],[2,1.43,58.14]],"ltp":1.96,"tv":160.0,"id":475559}]}]}
{"op":"mcm","clk":"11804730863","pt":1723245222320,"mc":[{"id":"1.231582170","rc":[{"batb":[[0,1.93,10],[1,1.92,45.42],[2,1.48,52.08]],"ltp":1.96,"tv":160.0,"id":475559}]}]}
{"op":"mcm","clk":"11804730990","pt":1723245225810,"mc":[{"id":"1.231582170","rc":[{"batb":[[0,1.92,45.42],[1,1.48,52.08],[2,1.43,58.14]],"ltp":1.96,"tv":160.0,"id":475559}]}]}
{"op":"mcm","clk":"11804731046","pt":1723245228026,"mc":[{"id":"1.231582170","rc":[{"batb":[[0,1.93,10],[1,1.92,45.42],[2,1.48,52.08]],"ltp":1.96,"tv":160.0,"id":475559}]}]}
{"op":"mcm","clk":"11804731150","pt":1723245231328,"mc":[{"id":"1.231582170","rc":[{"batb":[[0,1.92,45.42],[1,1.48,52.08],[2,1.43,58.14]],"ltp":1.96,"tv":160.0,"id":475559}]}]}
{"op":"mcm","clk":"11804731227","pt":1723245233842,"mc":[{"id":"1.231582170","rc":[{"batb":[[0,1.93,10],[1,1.92,45.42],[2,1.48,52.08]],"ltp":1.96,"tv":160.0,"id":475559}]}]}
{"op":"mcm","clk":"11804731334","pt":1723245237237,"mc":[{"id":"1.231582170","rc":[{"batb":[[0,1.92,45.42],[1,1.48,52.08],[2,1.43,58.14]],"ltp":1.96,"tv":160.0,"id":475559}]}]}
{"op":"mcm","clk":"11804731469","pt":1723245241656,"mc":[{"id":"1.231582170","rc":[{"batb":[[0,1.93,10],[1,1.92,45.42],[2,1.48,52.08]],"ltp":1.96,"tv":160.0,"id":475559}]}]}
{"op":"mcm","clk":"11804731593","pt":1723245245151,"mc":[{"id":"1.231582170","rc":[{"batb":[[0,1.92,45.42],[1,1.48,52.08],[2,1.43,58.14]],"ltp":1.96,"tv":160.0,"id":475559}]}]}
{"op":"mcm","clk":"11804731665","pt":1723245247561,"mc":[{"id":"1.231582170","rc":[{"batb":[[0,1.93,10],[1,1.92,45.42],[2,1.48,52.08]],"ltp":1.96,"tv":160.0,"id":475559}]}]}
{"op":"mcm","clk":"11804731765","pt":1723245250950,"mc":[{"id":"1.231582170","rc":[{"batb":[[0,1.92,45.42],[1,1.48,52.08],[2,1.43,58.14]],"ltp":1.96,"tv":160.0,"id":475559}]}]}
{"op":"mcm","clk":"11804731815","pt":1723245253149,"mc":[{"id":"1.231582170","rc":[{"batb":[[0,1.93,10],[1,1.92,45.42],[2,1.48,52.08]],"ltp":1.96,"tv":160.0,"id":475559}]}]}
{"op":"mcm","clk":"11804731901","pt":1723245256653,"mc":[{"id":"1.231582170","rc":[{"batb":[[0,1.92,45.42],[1,1.48,52.08],[2,1.43,58.14]],"ltp":1.96,"tv":160.0,"id":475559}]}]}
{"op":"mcm","clk":"11804731974","pt":1723245259158,"mc":[{"id":"1.231582170","rc":[{"batb":[[0,1.93,10],[1,1.92,45.42],[2,1.48,52.08]],"ltp":1.96,"tv":160.0,"id":475559}]}]}
{"op":"mcm","clk":"11804732081","pt":1723245262653,"mc":[{"id":"1.231582170","rc":[{"batb":[[0,1.92,45.42],[1,1.48,52.08],[2,1.43,58.14]],"ltp":1.96,"tv":160.0,"id":475559}]}]}
{"op":"mcm","clk":"11804732151","pt":1723245265167,"mc":[{"id":"1.231582170","rc":[{"batb":[[0,1.93,10],[1,1.92,45.42],[2,1.48,52.08]],"ltp":1.96,"tv":160.0,"id":475559}]}]}
{"op":"mcm","clk":"11804732252","pt":1723245268459,"mc":[{"id":"1.231582170","rc":[{"batb":[[0,1.92,45.42],[1,1.48,52.08],[2,1.43,58.14]],"ltp":1.96,"tv":160.0,"id":475559}]}]}
{"op":"mcm","clk":"11804732357","pt":1723245272154,"mc":[{"id":"1.231582170","rc":[{"batb":[[0,1.93,10],[1,1.92,45.42],[2,1.48,52.08]],"ltp":1.96,"tv":160.0,"id":475559}]}]}
{"op":"mcm","clk":"11804732451","pt":1723245275660,"mc":[{"id":"1.231582170","rc":[{"batb":[[0,1.92,45.42],[1,1.48,52.08],[2,1.43,58.14]],"ltp":1.96,"tv":160.0,"id":475559}]}]}
{"op":"mcm","clk":"11804732519","pt":1723245277965,"mc":[{"id":"1.231582170","rc":[{"batb":[[0,1.93,10],[1,1.92,45.42],[2,1.48,52.08]],"ltp":1.96,"tv":160.0,"id":475559}]}]}
{"op":"mcm","clk":"11804732628","pt":1723245281264,"mc":[{"id":"1.231582170","rc":[{"batb":[[0,1.92,45.42],[1,1.48,52.08],[2,1.43,58.14]],"ltp":1.96,"tv":160.0,"id":475559}]}]}
{"op":"mcm","clk":"11804732709","pt":1723245283880,"mc":[{"id":"1.231582170","rc":[{"batb":[[0,1.93,10],[1,1.92,45.42],[2,1.48,52.08]],"ltp":1.96,"tv":160.0,"id":475559}]}]}
{"op":"mcm","clk":"11804732808","pt":1723245287375,"mc":[{"id":"1.231582170","rc":[{"batb":[[0,1.92,45.42],[1,1.48,52.08],[2,1.43,58.14]],"ltp":1.96,"tv":160.0,"id":475559}]}]}
{"op":"mcm","clk":"11804732937","pt":1723245291084,"mc":[{"id":"1.231582170","rc":[{"batb":[[0,1.93,10],[1,1.92,45.42],[2,1.48,52.08]],"ltp":1.96,"tv":160.0,"id":475559}]}]}
{"op":"mcm","clk":"11804733026","pt":1723245294386,"mc":[{"id":"1.231582170","rc":[{"batb":[[0,1.92,45.42],[1,1.48,52.08],[2,1.43,58.14]],"ltp":1.96,"tv":160.0,"id":475559}]}]}
{"op":"mcm","clk":"11804733090","pt":1723245296693,"mc":[{"id":"1.231582170","rc":[{"batb":[[0,1.93,10],[1,1.92,45.42],[2,1.48,52.08]],"ltp":1.96,"tv":160.0,"id":475559}]}]}
{"op":"mcm","clk":"11804733192","pt":1723245300172,"mc":[{"id":"1.231582170","rc":[{"batb":[[0,1.92,45.42],[1,1.48,52.08],[2,1.43,58.14]],"ltp":1.96,"tv":160.0,"id":475559}]}]}
{"op":"mcm","clk":"11804733271","pt":1723245302493,"mc":[{"id":"1.231582170","rc":[{"batb":[[0,1.93,10],[1,1.92,45.42],[2,1.48,52.08]],"ltp":1.96,"tv":160.0,"id":475559}]}]}
{"op":"mcm","clk":"11804733378","pt":1723245305793,"mc":[{"id":"1.231582170","rc":[{"batb":[[0,1.92,45.42],[1,1.48,52.08],[2,1.43,58.14]],"ltp":1.96,"tv":160.0,"id":475559}]}]}
{"op":"mcm","clk":"11804733495","pt":1723245308985,"mc":[{"id":"1.231582170","rc":[{"batb":[[0,1.93,10],[1,1.92,45.42],[2,1.48,52.08]],"ltp":1.96,"tv":160.0,"id":475559}]}]}
{"op":"mcm","clk":"11804733593","pt":1723245312181,"mc":[{"id":"1.231582170","rc":[{"batb":[[0,1.92,45.42],[1,1.48,52.08],[2,1.43,58.14]],"ltp":1.96,"tv":160.0,"id":475559}]}]}
{"op":"mcm","clk":"11804733684","pt":1723245314500,"mc":[{"id":"1.231582170","rc":[{"batb":[[0,1.93,10],[1,1.92,45.42],[2,1.48,52.08]],"ltp":1.96,"tv":160.0,"id":475559}]}]}
{"op":"mcm","clk":"11804733790","pt":1723245317797,"mc":[{"id":"1.231582170","rc":[{"batb":[[0,1.92,45.42],[1,1.48,52.08],[2,1.43,58.14]],"ltp":1.96,"tv":160.0,"id":475559}]}]}
{"op":"mcm","clk":"11804733920","pt":1723245321306,"mc":[{"id":"1.231582170","rc":[{"batb":[[0,1.93,10],[1,1.92,45.42],[2,1.48,52.08]],"ltp":1.96,"tv":160.0,"id":475559}]}]}
{"op":"mcm","clk":"11804734029","pt":1723245324704,"mc":[{"id":"1.231582170","rc":[{"batb":[[0,1.92,45.42],[1,1.48,52.08],[2,1.43,58.14]],"ltp":1.96,"tv":160.0,"id":475559}]}]}
{"op":"mcm","clk":"11804734117","pt":1723245327113,"mc":[{"id":"1.231582170","rc":[{"batb":[[0,1.93,10],[1,1.92,45.42],[2,1.48,52.08]],"ltp":1.96,"tv":160.0,"id":475559}]}]}
{"op":"mcm","clk":"11804734244","pt":1723245330511,"mc":[{"id":"1.231582170","rc":[{"batb":[[0,1.92,45.42],[1,1.48,52.08],[2,1.43,58.14]],"ltp":1.96,"tv":160.0,"id":475559}]}]}
{"op":"mcm","clk":"11804734350","pt":1723245334220,"mc":[{"id":"1.231582170","rc":[{"batb":[[0,1.93,10],[1,1.92,45.42],[2,1.48,52.08]],"ltp":1.96,"tv":160.0,"id":475559}]}]}
{"op":"mcm","clk":"11804734459","pt":1723245337509,"mc":[{"id":"1.231582170","rc":[{"batb":[[0,1.92,45.42],[1,1.48,52.08],[2,1.43,58.14]],"ltp":1.96,"tv":160.0,"id":475559}]}]}
{"op":"mcm","clk":"11804734579","pt":1723245340503,"mc":[{"id":"1.231582170","rc":[{"batb":[[0,1.93,10],[1,1.92,45.42],[2,1.48,52.08]],"ltp":1.96,"tv":160.0,"id":475559}]}]}
{"op":"mcm","clk":"11804734717","pt":1723245343945,"mc":[{"id":"1.231582170","rc":[{"batb":[[0,1.92,45.42],[1,1.48,52.08],[2,1.43,58.14]],"ltp":1.96,"tv":160.0,"id":475559}]}]}
{"op":"mcm","clk":"11804734828","pt":1723245347432,"mc":[{"id":"1.231582170","rc":[{"batb":[[0,1.93,10],[1,1.92,45.42],[2,1.48,52.08]],"ltp":1.96,"tv":160.0,"id":475559}]}]}
{"op":"mcm","clk":"11804734948","pt":1723245350835,"mc":[{"id":"1.231582170","rc":[{"batb":[[0,1.92,45.42],[1,1.48,52.08],[2,1.43,58.14]],"ltp":1.96,"tv":160.0,"id":475559}]}]}
{"op":"mcm","clk":"11804735029","pt":1723245353644,"mc":[{"id":"1.231582170","rc":[{"batb":[[0,1.93,10],[1,1.92,45.42],[2,1.48,52.08]],"ltp":1.96,"tv":160.0,"id":475559}]}]}
{"op":"mcm","clk":"11804735158","pt":1723245357220,"mc":[{"id":"1.231582170","rc":[{"batb":[[0,1.92,45.42],[1,1.48,52.08],[2,1.43,58.14]],"ltp":1.96,"tv":160.0,"id":475559}]}]}
{"op":"mcm","clk":"11804735263","pt":1723245360361,"mc":[{"id":"1.231582170","rc":[{"batb":[[0,1.93,10],[1,1.92,45.42],[2,1.48,52.08]],"ltp":1.96,"tv":160.0,"id":475559}]}]}
{"op":"mcm","clk":"11804735404","pt":1723245363860,"mc":[{"id":"1.231582170","rc":[{"batb":[[0,1.92,45.42],[1,1.48,52.08],[2,1.43,58.14]],"ltp":1.96,"tv":160.0,"id":475559}]}]}
{"op":"mcm","clk":"11804735522","pt":1723245367046,"mc":[{"id":"1.231582170","rc":[{"batb":[[0,1.93,10],[1,1.92,45.42],[2,1.48,52.08]],"ltp":1.96,"tv":160.0,"id":475559}]}]}
{"op":"mcm","clk":"11804735660","pt":1723245370338,"mc":[{"id":"1.231582170","rc":[{"batb":[[0,1.92,45.42],[1,1.48,52.08],[2,1.43,58.14]],"ltp":1.96,"tv":160.0,"id":475559}]}]}
{"op":"mcm","clk":"11804735800","pt":1723245373838,"mc":[{"id":"1.231582170","rc":[{"batb":[[0,1.93,10],[1,1.92,45.42],[2,1.48,52.08]],"ltp":1.96,"tv":160.0,"id":475559}]}]}
{"op":"mcm","clk":"11804735903","pt":1723245377125,"mc":[{"id":"1.231582170","rc":[{"batb":[[0,1.92,45.42],[1,1.48,52.08],[2,1.43,58.14]],"ltp":1.96,"tv":160.0,"id":475559}]}]}
{"op":"mcm","clk":"11804736008","pt":1723245379649,"mc":[{"id":"1.231582170","rc":[{"batb":[[0,1.93,10],[1,1.92,45.42],[2,1.48,52.08]],"ltp":1.96,"tv":160.0,"id":475559}]}]}
{"op":"mcm","clk":"11804736116","pt":1723245382960,"mc":[{"id":"1.231582170","rc":[{"batb":[[0,1.92,45.42],[1,1.48,52.08],[2,1.43,58.14]],"ltp":1.96,"tv":160.0,"id":475559}]}]}
{"op":"mcm","clk":"11804736228","pt":1723245386465,"mc":[{"id":"1.231582170","rc":[{"batb":[[0,1.93,10],[1,1.92,45.42],[2,1.48,52.08]],"ltp":1.96,"tv":160.0,"id":475559}]}]}
{"op":"mcm","clk":"11804736347","pt":1723245389959,"mc":[{"id":"1.231582170","rc":[{"batb":[[0,1.92,45.42],[1,1.48,52.08],[2,1.43,58.14]],"ltp":1.96,"tv":160.0,"id":475559}]}]}
{"op":"mcm","clk":"11804736450","pt":1723245393051,"mc":[{"id":"1.231582170","rc":[{"batb":[[0,1.93,10],[1,1.92,45.42],[2,1.48,52.08]],"ltp":1.96,"tv":160.0,"id":475559}]}]}
{"op":"mcm","clk":"11804736572","pt":1723245396345,"mc":[{"id":"1.231582170","rc":[{"batb":[[0,1.92,45.42],[1,1.48,52.08],[2,1.43,58.14]],"ltp":1.96,"tv":160.0,"id":475559}]}]}
{"op":"mcm","clk":"11804736640","pt":1723245398960,"mc":[{"id":"1.231582170","rc":[{"batb":[[0,1.93,10],[1,1.92,45.42],[2,1.48,52.08]],"ltp":1.96,"tv":160.0,"id":475559}]}]}
{"op":"mcm","clk":"11804736755","pt":1723245402358,"mc":[{"id":"1.231582170","rc":[{"batb":[[0,1.92,45.42],[1,1.48,52.08],[2,1.43,58.14]],"ltp":1.96,"tv":160.0,"id":475559}]}]}
{"op":"mcm","clk":"11804736858","pt":1723245404979,"mc":[{"id":"1.231582170","rc":[{"batb":[[0,1.93,10],[1,1.92,45.42],[2,1.48,52.08]],"ltp":1.96,"tv":160.0,"id":475559}]}]}
{"op":"mcm","clk":"11804736975","pt":1723245408268,"mc":[{"id":"1.231582170","rc":[{"batb":[[0,1.92,45.42],[1,1.48,52.08],[2,1.43,58.14]],"ltp":1.96,"tv":160.0,"id":475559}]}]}
{"op":"mcm","clk":"11804737186","pt":1723245413886,"mc":[{"id":"1.231582170","rc":[{"batb":[[0,1.93,10],[1,1.92,45.42],[2,1.48,52.08]],"ltp":1.96,"tv":160.0,"id":475559}]}]}
{"op":"mcm","clk":"11804737293","pt":1723245417166,"mc":[{"id":"1.231582170","rc":[{"batb":[[0,1.92,45.42],[1,1.48,52.08],[2,1.43,58.14]],"ltp":1.96,"tv":160.0,"id":475559}]}]}
{"op":"mcm","clk":"11804737374","pt":1723245420150,"mc":[{"id":"1.231582170","rc":[{"batb":[[0,1.93,10],[1,1.92,45.42],[2,1.48,52.08]],"ltp":1.96,"tv":160.0,"id":475559}]}]}
{"op":"mcm","clk":"11804737498","pt":1723245423402,"mc":[{"id":"1.231582170","rc":[{"batb":[[0,1.92,45.42],[1,1.48,52.08],[2,1.43,58.14]],"ltp":1.96,"tv":160.0,"id":475559}]}]}
{"op":"mcm","clk":"11804737619","pt":1723245426895,"mc":[{"id":"1.231582170","rc":[{"batb":[[0,1.93,10],[1,1.92,45.42],[2,1.48,52.08]],"ltp":1.96,"tv":160.0,"id":475559}]}]}
{"op":"mcm","clk":"11804737755","pt":1723245430583,"mc":[{"id":"1.231582170","rc":[{"batb":[[0,1.92,45.42],[1,1.48,52.08],[2,1.43,58.14]],"ltp":1.96,"tv":160.0,"id":475559}]}]}
{"op":"mcm","clk":"11804737827","pt":1723245432890,"mc":[{"id":"1.231582170","rc":[{"batb":[[0,1.93,10],[1,1.92,45.42],[2,1.48,52.08]],"ltp":1.96,"tv":160.0,"id":475559}]}]}
{"op":"mcm","clk":"11804737940","pt":1723245436282,"mc":[{"id":"1.231582170","rc":[{"batb":[[0,1.92,45.42],[1,1.48,52.08],[2,1.43,58.14]],"ltp":1.96,"tv":160.0,"id":475559}]}]}
{"op":"mcm","clk":"11804738039","pt":1723245438605,"mc":[{"id":"1.231582170","rc":[{"batb":[[0,1.93,10],[1,1.92,45.42],[2,1.48,52.08]],"ltp":1.96,"tv":160.0,"id":475559}]}]}
{"op":"mcm","clk":"11804738144","pt":1723245442002,"mc":[{"id":"1.231582170","rc":[{"batb":[[0,1.92,45.42],[1,1.48,52.08],[2,1.43,58.14]],"ltp":1.96,"tv":160.0,"id":475559}]}]}
{"op":"mcm","clk":"11804738230","pt":1723245444316,"mc":[{"id":"1.231582170","rc":[{"batb":[[0,1.93,10],[1,1.92,45.42],[2,1.48,52.08]],"ltp":1.96,"tv":160.0,"id":475559}]}]}
{"op":"mcm","clk":"11804738345","pt":1723245447706,"mc":[{"id":"1.231582170","rc":[{"batb":[[0,1.92,45.42],[1,1.48,52.08],[2,1.43,58.14]],"ltp":1.96,"tv":160.0,"id":475559}]}]}
{"op":"mcm","clk":"11804738433","pt":1723245450439,"mc":[{"id":"1.231582170","rc":[{"batb":[[0,1.93,10],[1,1.92,45.42],[2,1.48,52.08]],"ltp":1.96,"tv":160.0,"id":475559}]}]}
{"op":"mcm","clk":"11804738544","pt":1723245453936,"mc":[{"id":"1.231582170","rc":[{"batb":[[0,1.92,45.42],[1,1.48,52.08],[2,1.43,58.14]],"ltp":1.96,"tv":160.0,"id":475559}]}]}
{"op":"mcm","clk":"11804738674","pt":1723245457235,"mc":[{"id":"1.231582170","rc":[{"batb":[[0,1.93,10],[1,1.92,45.42],[2,1.48,52.08]],"ltp":1.96,"tv":160.0,"id":475559}]}]}
{"op":"mcm","clk":"11804738791","pt":1723245460526,"mc":[{"id":"1.231582170","rc":[{"batb":[[0,1.92,45.42],[1,1.48,52.08],[2,1.43,58.14]],"ltp":1.96,"tv":160.0,"id":475559}]}]}
{"op":"mcm","clk":"11804738882","pt":1723245464028,"mc":[{"id":"1.231582170","rc":[{"batb":[[0,1.93,10],[1,1.92,45.42],[2,1.48,52.08]],"ltp":1.96,"tv":160.0,"id":475559}]}]}
{"op":"mcm","clk":"11804738962","pt":1723245467524,"mc":[{"id":"1.231582170","rc":[{"batb":[[0,1.92,45.42],[1,1.48,52.08],[2,1.43,58.14]],"ltp":1.96,"tv":160.0,"id":475559}]}]}
{"op":"mcm","clk":"11804739084","pt":1723245470724,"mc":[{"id":"1.231582170","rc":[{"batb":[[0,1.93,10],[1,1.92,45.42],[2,1.48,52.08]],"ltp":1.96,"tv":160.0,"id":475559}]}]}
{"op":"mcm","clk":"11804739184","pt":1723245473969,"mc":[{"id":"1.231582170","rc":[{"batb":[[0,1.92,45.42],[1,1.48,52.08],[2,1.43,58.14]],"ltp":1.96,"tv":160.0,"id":475559}]}]}
{"op":"mcm","clk":"11804739293","pt":1723245477350,"mc":[{"id":"1.231582170","rc":[{"batb":[[0,1.93,10],[1,1.92,45.42],[2,1.48,52.08]],"ltp":1.96,"tv":160.0,"id":475559}]}]}
{"op":"mcm","clk":"11804739394","pt":1723245480681,"mc":[{"id":"1.231582170","rc":[{"batb":[[0,1.92,45.42],[1,1.48,52.08],[2,1.43,58.14]],"ltp":1.96,"tv":160.0,"id":475559}]}]}
{"op":"mcm","clk":"11804739497","pt":1723245483562,"mc":[{"id":"1.231582170","rc":[{"batb":[[0,1.93,10],[1,1.92,45.42],[2,1.48,52.08]],"ltp":1.96,"tv":160.0,"id":475559}]}]}
{"op":"mcm","clk":"11804739630","pt":1723245487074,"mc":[{"id":"1.231582170","rc":[{"batb":[[0,1.92,45.42],[1,1.48,52.08],[2,1.43,58.14]],"ltp":1.96,"tv":160.0,"id":475559}]}]}
{"op":"mcm","clk":"11804739723","pt":1723245489399,"mc":[{"id":"1.231582170","rc":[{"batb":[[0,1.93,10],[1,1.92,45.42],[2,1.48,52.08]],"ltp":1.96,"tv":160.0,"id":475559}]}]}
{"op":"mcm","clk":"11804739841","pt":1723245492800,"mc":[{"id":"1.231582170","rc":[{"batb":[[0,1.92,45.42],[1,1.48,52.08],[2,1.43,58.14]],"ltp":1.96,"tv":160.0,"id":475559}]}]}
{"op":"mcm","clk":"11804739938","pt":1723245495101,"mc":[{"id":"1.231582170","rc":[{"batb":[[0,1.93,10],[1,1.92,45.42],[2,1.48,52.08]],"ltp":1.96,"tv":160.0,"id":475559}]}]}
{"op":"mcm","clk":"11804740071","pt":1723245498397,"mc":[{"id":"1.231582170","rc":[{"batb":[[0,1.92,45.42],[1,1.48,52.08],[2,1.43,58.14]],"ltp":1.96,"tv":160.0,"id":475559}]}]}
{"op":"mcm","clk":"11804740160","pt":1723245500998,"mc":[{"id":"1.231582170","rc":[{"batb":[[0,1.93,10],[1,1.92,45.42],[2,1.48,52.08]],"ltp":1.96,"tv":160.0,"id":475559}]}]}
{"op":"mcm","clk":"11804740280","pt":1723245504499,"mc":[{"id":"1.231582170","rc":[{"batb":[[0,1.92,45.42],[1,1.48,52.08],[2,1.43,58.14]],"ltp":1.96,"tv":160.0,"id":475559}]}]}
{"op":"mcm","clk":"11804740384","pt":1723245508111,"mc":[{"id":"1.231582170","rc":[{"batb":[[0,1.93,10],[1,1.92,45.42],[2,1.48,52.08]],"ltp":1.96,"tv":160.0,"id":475559}]}]}
{"op":"mcm","clk":"11804740491","pt":1723245511617,"mc":[{"id":"1.231582170","rc":[{"batb":[[0,1.92,45.42],[1,1.48,52.08],[2,1.43,58.14]],"ltp":1.96,"tv":160.0,"id":475559}]}]}
{"op":"mcm","clk":"11804740645","pt":1723245515899,"mc":[{"id":"1.231582170","rc":[{"batb":[[0,1.93,10],[1,1.92,45.42],[2,1.48,52.08]],"ltp":1.96,"tv":160.0,"id":475559}]}]}
{"op":"mcm","clk":"11804740743","pt":1723245519200,"mc":[{"id":"1.231582170","rc":[{"batb":[[0,1.92,45.42],[1,1.48,52.08],[2,1.43,58.14]],"ltp":1.96,"tv":160.0,"id":475559}]}]}
{"op":"mcm","clk":"11804740903","pt":1723245524288,"mc":[{"id":"1.231582170","rc":[{"batb":[[0,1.93,10],[1,1.92,45.42],[2,1.48,52.08]],"ltp":1.96,"tv":160.0,"id":475559}]}]}
{"op":"mcm","clk":"11804740998","pt":1723245527625,"mc":[{"id":"1.231582170","rc":[{"batb":[[0,1.92,45.42],[1,1.48,52.08],[2,1.43,58.14]],"ltp":1.96,"tv":160.0,"id":475559}]}]}
{"op":"mcm","clk":"11804741103","pt":1723245530422,"mc":[{"id":"1.231582170","rc":[{"batb":[[0,1.93,10],[1,1.92,45.42],[2,1.48,52.08]],"ltp":1.96,"tv":160.0,"id":475559}]}]}
{"op":"mcm","clk":"11804741230","pt":1723245533824,"mc":[{"id":"1.231582170","rc":[{"batb":[[0,1.92,45.42],[1,1.48,52.08],[2,1.43,58.14]],"ltp":1.96,"tv":160.0,"id":475559}]}]}
{"op":"mcm","clk":"11804741324","pt":1723245536509,"mc":[{"id":"1.231582170","rc":[{"batb":[[0,1.93,10],[1,1.92,45.42],[2,1.48,52.08]],"ltp":1.96,"tv":160.0,"id":475559}]}]}
{"op":"mcm","clk":"11804741430","pt":1723245539801,"mc":[{"id":"1.231582170","rc":[{"batb":[[0,1.92,45.42],[1,1.48,52.08],[2,1.43,58.14]],"ltp":1.96,"tv":160.0,"id":475559}]}]}
{"op":"mcm","clk":"11804741547","pt":1723245543322,"mc":[{"id":"1.231582170","rc":[{"batb":[[0,1.93,10],[1,1.92,45.42],[2,1.48,52.08]],"ltp":1.96,"tv":160.0,"id":475559}]}]}
{"op":"mcm","clk":"11804741640","pt":1723245546627,"mc":[{"id":"1.231582170","rc":[{"batb":[[0,1.92,45.42],[1,1.48,52.08],[2,1.43,58.14]],"ltp":1.96,"tv":160.0,"id":475559}]}]}
{"op":"mcm","clk":"11804741745","pt":1723245549919,"mc":[{"id":"1.231582170","rc":[{"batb":[[0,1.93,10],[1,1.92,45.42],[2,1.48,52.08]],"ltp":1.96,"tv":160.0,"id":475559}]}]}
{"op":"mcm","clk":"11804741846","pt":1723245553325,"mc":[{"id":"1.231582170","rc":[{"batb":[[0,1.92,45.42],[1,1.48,52.08],[2,1.43,58.14]],"ltp":1.96,"tv":160.0,"id":475559}]}]}
{"op":"mcm","clk":"11804741911","pt":1723245555638,"mc":[{"id":"1.231582170","rc":[{"batb":[[0,1.93,10],[1,1.92,45.42],[2,1.48,52.08]],"ltp":1.96,"tv":160.0,"id":475559}]}]}
{"op":"mcm","clk":"11804742021","pt":1723245559037,"mc":[{"id":"1.231582170","rc":[{"batb":[[0,1.92,45.42],[1,1.48,52.08],[2,1.43,58.14]],"ltp":1.96,"tv":160.0,"id":475559}]}]}
{"op":"mcm","clk":"11804742143","pt":1723245563056,"mc":[{"id":"1.231582170","rc":[{"batb":[[0,1.93,10],[1,1.92,45.42],[2,1.48,52.08]],"ltp":1.96,"tv":160.0,"id":475559}]}]}
{"op":"mcm","clk":"11804742233","pt":1723245566341,"mc":[{"id":"1.231582170","rc":[{"batb":[[0,1.92,45.42],[1,1.48,52.08],[2,1.43,58.14]],"ltp":1.96,"tv":160.0,"id":475559}]}]}
{"op":"mcm","clk":"11804742334","pt":1723245568966,"mc":[{"id":"1.231582170","rc":[{"batb":[[0,1.93,10],[1,1.92,45.42],[2,1.48,52.08]],"ltp":1.96,"tv":160.0,"id":475559}]}]}
{"op":"mcm","clk":"11804742492","pt":1723245573857,"mc":[{"id":"1.231582170","rc":[{"batb":[[0,1.92,45.42],[1,1.48,52.08],[2,1.43,58.14]],"ltp":1.96,"tv":160.0,"id":475559}]}]}
{"op":"mcm","clk":"11804742592","pt":1723245576330,"mc":[{"id":"1.231582170","rc":[{"batb":[[0,1.93,10],[1,1.92,45.42],[2,1.48,52.08]],"ltp":1.96,"tv":160.0,"id":475559}]}]}
{"op":"mcm","clk":"11804742709","pt":1723245579877,"mc":[{"id":"1.231582170","rc":[{"batb":[[0,1.92,45.42],[1,1.48,52.08],[2,1.43,58.14]],"ltp":1.96,"tv":160.0,"id":475559}]}]}
{"op":"mcm","clk":"11804742816","pt":1723245583178,"mc":[{"id":"1.231582170","rc":[{"batb":[[0,1.93,10],[1,1.92,45.42],[2,1.48,52.08]],"ltp":1.96,"tv":160.0,"id":475559}]}]}
{"op":"mcm","clk":"11804742931","pt":1723245586676,"mc":[{"id":"1.231582170","rc":[{"batb":[[0,1.92,45.42],[1,1.48,52.08],[2,1.43,58.14]],"ltp":1.96,"tv":160.0,"id":475559}]}]}
{"op":"mcm","clk":"11804743015","pt":1723245588993,"mc":[{"id":"1.231582170","rc":[{"batb":[[0,1.93,10],[1,1.92,45.42],[2,1.48,52.08]],"ltp":1.96,"tv":160.0,"id":475559}]}]}
{"op":"mcm","clk":"11804743149","pt":1723245592257,"mc":[{"id":"1.231582170","rc":[{"batb":[[0,1.92,45.42],[1,1.48,52.08],[2,1.43,58.14]],"ltp":1.96,"tv":160.0,"id":475559}]}]}
{"op":"mcm","clk":"11804743222","pt":1723245594774,"mc":[{"id":"1.231582170","rc":[{"batb":[[0,1.93,10],[1,1.92,45.42],[2,1.48,52.08]],"ltp":1.96,"tv":160.0,"id":475559}]}]}
{"op":"mcm","clk":"11804743316","pt":1723245598208,"mc":[{"id":"1.231582170","rc":[{"batb":[[0,1.92,45.42],[1,1.48,52.08],[2,1.43,58.14]],"ltp":1.96,"tv":160.0,"id":475559}]}]}
{"op":"mcm","clk":"11804743454","pt":1723245602097,"mc":[{"id":"1.231582170","rc":[{"batb":[[0,1.93,10],[1,1.92,45.42],[2,1.48,52.08]],"ltp":1.96,"tv":160.0,"id":475559}]}]}
{"op":"mcm","clk":"11804743591","pt":1723245605452,"mc":[{"id":"1.231582170","rc":[{"batb":[[0,1.92,45.42],[1,1.48,52.08],[2,1.43,58.14]],"ltp":1.96,"tv":160.0,"id":475559}]}]}
{"op":"mcm","clk":"11804743708","pt":1723245608081,"mc":[{"id":"1.231582170","rc":[{"batb":[[0,1.93,10],[1,1.92,45.42],[2,1.48,52.08]],"ltp":1.96,"tv":160.0,"id":475559}]}]}
{"op":"mcm","clk":"11804743819","pt":1723245611583,"mc":[{"id":"1.231582170","rc":[{"batb":[[0,1.92,45.42],[1,1.48,52.08],[2,1.43,58.14]],"ltp":1.96,"tv":160.0,"id":475559}]}]}
{"op":"mcm","clk":"11804743947","pt":1723245615419,"mc":[{"id":"1.231582170","rc":[{"batb":[[0,1.93,10],[1,1.92,45.42],[2,1.48,52.08]],"ltp":1.96,"tv":160.0,"id":475559}]}]}
{"op":"mcm","clk":"11804744081","pt":1723245618720,"mc":[{"id":"1.231582170","rc":[{"batb":[[0,1.92,45.42],[1,1.48,52.08],[2,1.43,58.14]],"ltp":1.96,"tv":160.0,"id":475559}]}]}
{"op":"mcm","clk":"11804744287","pt":1723245623712,"mc":[{"id":"1.231582170","rc":[{"batb":[[0,1.93,10],[1,1.92,45.42],[2,1.48,52.08]],"ltp":1.96,"tv":160.0,"id":475559}]}]}
{"op":"mcm","clk":"11804744409","pt":1723245627221,"mc":[{"id":"1.231582170","rc":[{"batb":[[0,1.92,45.42],[1,1.48,52.08],[2,1.43,58.14]],"ltp":1.96,"tv":160.0,"id":475559}]}]}
{"op":"mcm","clk":"11804744484","pt":1723245629533,"mc":[{"id":"1.231582170","rc":[{"batb":[[0,1.93,10],[1,1.92,45.42],[2,1.48,52.08]],"ltp":1.96,"tv":160.0,"id":475559}]}]}
{"op":"mcm","clk":"11804744574","pt":1723245632937,"mc":[{"id":"1.231582170","rc":[{"batb":[[0,1.92,45.42],[1,1.48,52.08],[2,1.43,58.14]],"ltp":1.96,"tv":160.0,"id":475559}]}]}
{"op":"mcm","clk":"11804744654","pt":1723245635716,"mc":[{"id":"1.231582170","rc":[{"batb":[[0,1.93,10],[1,1.92,45.42],[2,1.48,52.08]],"ltp":1.96,"tv":160.0,"id":475559}]}]}
{"op":"mcm","clk":"11804744768","pt":1723245640014,"mc":[{"id":"1.231582170","rc":[{"batb":[[0,1.92,45.42],[1,1.48,52.08],[2,1.43,58.14]],"ltp":1.96,"tv":160.0,"id":475559}]}]}
{"op":"mcm","clk":"11804744824","pt":1723245642542,"mc":[{"id":"1.231582170","rc":[{"batb":[[0,1.93,10],[1,1.92,45.42],[2,1.48,52.08]],"ltp":1.96,"tv":160.0,"id":475559}]}]}
{"op":"mcm","clk":"11804744936","pt":1723245645843,"mc":[{"id":"1.231582170","rc":[{"batb":[[0,1.92,45.42],[1,1.48,52.08],[2,1.43,58.14]],"ltp":1.96,"tv":160.0,"id":475559}]}]}
{"op":"mcm","clk":"11804745020","pt":1723245648424,"mc":[{"id":"1.231582170","rc":[{"batb":[[0,1.93,10],[1,1.92,45.42],[2,1.48,52.08]],"ltp":1.96,"tv":160.0,"id":475559}]}]}
{"op":"mcm","clk":"11804745139","pt":1723245651720,"mc":[{"id":"1.231582170","rc":[{"batb":[[0,1.92,45.42],[1,1.48,52.08],[2,1.43,58.14]],"ltp":1.96,"tv":160.0,"id":475559}]}]}
{"op":"mcm","clk":"11804745216","pt":1723245654345,"mc":[{"id":"1.231582170","rc":[{"batb":[[0,1.93,10],[1,1.92,45.42],[2,1.48,52.08]],"ltp":1.96,"tv":160.0,"id":475559}]}]}
{"op":"mcm","clk":"11804745305","pt":1723245657647,"mc":[{"id":"1.231582170","rc":[{"batb":[[0,1.92,45.42],[1,1.48,52.08],[2,1.43,58.14]],"ltp":1.96,"tv":160.0,"id":475559}]}]}
{"op":"mcm","clk":"11804745365","pt":1723245660371,"mc":[{"id":"1.231582170","rc":[{"batb":[[0,1.93,10],[1,1.92,45.42],[2,1.48,52.08]],"ltp":1.96,"tv":160.0,"id":475559}]}]}
{"op":"mcm","clk":"11804745463","pt":1723245663740,"mc":[{"id":"1.231582170","rc":[{"batb":[[0,1.92,45.42],[1,1.48,52.08],[2,1.43,58.14]],"ltp":1.96,"tv":160.0,"id":475559}]}]}
{"op":"mcm","clk":"11804745539","pt":1723245666048,"mc":[{"id":"1.231582170","rc":[{"batb":[[0,1.93,10],[1,1.92,45.42],[2,1.48,52.08]],"ltp":1.96,"tv":160.0,"id":475559}]}]}
{"op":"mcm","clk":"11804745641","pt":1723245669446,"mc":[{"id":"1.231582170","rc":[{"batb":[[0,1.92,45.42],[1,1.48,52.08],[2,1.43,58.14]],"ltp":1.96,"tv":160.0,"id":475559}]}]}
{"op":"mcm","clk":"11804745779","pt":1723245673977,"mc":[{"id":"1.231582170","rc":[{"batb":[[0,1.93,10],[1,1.92,45.42],[2,1.48,52.08]],"ltp":1.96,"tv":160.0,"id":475559}]}]}
{"op":"mcm","clk":"11804745868","pt":1723245677346,"mc":[{"id":"1.231582170","rc":[{"batb":[[0,1.92,45.42],[1,1.48,52.08],[2,1.43,58.14]],"ltp":1.96,"tv":160.0,"id":475559}]}]}
{"op":"mcm","clk":"11804746002","pt":1723245680855,"mc":[{"id":"1.231582170","rc":[{"batb":[[0,1.93,10],[1,1.92,45.42],[2,1.48,52.08]],"ltp":1.96,"tv":160.0,"id":475559}]}]}
{"op":"mcm","clk":"11804746091","pt":1723245684251,"mc":[{"id":"1.231582170","rc":[{"batb":[[0,1.92,45.42],[1,1.48,52.08],[2,1.43,58.14]],"ltp":1.96,"tv":160.0,"id":475559}]}]}
{"op":"mcm","clk":"11804746153","pt":1723245687090,"mc":[{"id":"1.231582170","rc":[{"batb":[[0,1.93,10],[1,1.92,45.42],[2,1.48,52.08]],"ltp":1.96,"tv":160.0,"id":475559}]}]}
{"op":"mcm","clk":"11804746227","pt":1723245690492,"mc":[{"id":"1.231582170","rc":[{"batb":[[0,1.92,45.42],[1,1.48,52.08],[2,1.43,58.14]],"ltp":1.96,"tv":160.0,"id":475559}]}]}
{"op":"mcm","clk":"11804746378","pt":1723245694473,"mc":[{"id":"1.231582170","rc":[{"batb":[[0,1.93,10],[1,1.92,45.42],[2,1.48,52.08]],"ltp":1.96,"tv":160.0,"id":475559}]}]}
{"op":"mcm","clk":"11804746468","pt":1723245697873,"mc":[{"id":"1.231582170","rc":[{"batb":[[0,1.92,45.42],[1,1.48,52.08],[2,1.43,58.14]],"ltp":1.96,"tv":160.0,"id":475559}]}]}
{"op":"mcm","clk":"11804746553","pt":1723245700605,"mc":[{"id":"1.231582170","rc":[{"batb":[[0,1.93,10],[1,1.92,45.42],[2,1.48,52.08]],"ltp":1.96,"tv":160.0,"id":475559}]}]}
{"op":"mcm","clk":"11804746649","pt":1723245703897,"mc":[{"id":"1.231582170","rc":[{"batb":[[0,1.92,45.42],[1,1.48,52.08],[2,1.43,58.14]],"ltp":1.96,"tv":160.0,"id":475559}]}]}
{"op":"mcm","clk":"11804746703","pt":1723245706784,"mc":[{"id":"1.231582170","rc":[{"batb":[[0,1.93,10],[1,1.92,45.42],[2,1.48,52.08]],"ltp":1.96,"tv":160.0,"id":475559}]}]}
{"op":"mcm","clk":"11804746811","pt":1723245710118,"mc":[{"id":"1.231582170","rc":[{"batb":[[0,1.92,45.42],[1,1.48,52.08],[2,1.43,58.14]],"ltp":1.96,"tv":160.0,"id":475559}]}]}
{"op":"mcm","clk":"11804746881","pt":1723245712605,"mc":[{"id":"1.231582170","rc":[{"batb":[[0,1.93,10],[1,1.92,45.42],[2,1.48,52.08]],"ltp":1.96,"tv":160.0,"id":475559}]}]}
{"op":"mcm","clk":"11804746972","pt":1723245715905,"mc":[{"id":"1.231582170","rc":[{"batb":[[0,1.92,45.42],[1,1.48,52.08],[2,1.43,58.14]],"ltp":1.96,"tv":160.0,"id":475559}]}]}
{"op":"mcm","clk":"11804747039","pt":1723245718418,"mc":[{"id":"1.231582170","rc":[{"batb":[[0,1.93,10],[1,1.92,45.42],[2,1.48,52.08]],"ltp":1.96,"tv":160.0,"id":475559}]}]}
{"op":"mcm","clk":"11804747111","pt":1723245721716,"mc":[{"id":"1.231582170","rc":[{"batb":[[0,1.92,45.42],[1,1.48,52.08],[2,1.43,58.14]],"ltp":1.96,"tv":160.0,"id":475559}]}]}
{"op":"mcm","clk":"11804747176","pt":1723245724245,"mc":[{"id":"1.231582170","rc":[{"batb":[[0,1.93,10],[1,1.92,45.42],[2,1.48,52.08]],"ltp":1.96,"tv":160.0,"id":475559}]}]}
{"op":"mcm","clk":"11804747266","pt":1723245727608,"mc":[{"id":"1.231582170","rc":[{"batb":[[0,1.92,45.42],[1,1.48,52.08],[2,1.43,58.14]],"ltp":1.96,"tv":160.0,"id":475559}]}]}
{"op":"mcm","clk":"11804747323","pt":1723245730029,"mc":[{"id":"1.231582170","rc":[{"batb":[[0,1.93,10],[1,1.92,45.42],[2,1.48,52.08]],"ltp":1.96,"tv":160.0,"id":475559}]}]}
{"op":"mcm","clk":"11804747436","pt":1723245733428,"mc":[{"id":"1.231582170","rc":[{"batb":[[0,1.92,45.42],[1,1.48,52.08],[2,1.43,58.14]],"ltp":1.96,"tv":160.0,"id":475559}]}]}
{"op":"mcm","clk":"11804852628","pt":1723248000533,"mc":[{"id":"1.231582170","rc":[{"batb":[[0,1.93,10],[1,1.92,45.42],[2,1.48,52.08]],"ltp":1.96,"tv":160.0,"id":475559}]}]}
{"op":"mcm","clk":"11804852872","pt":1723248003828,"mc":[{"id":"1.231582170","rc":[{"batb":[[0,1.92,45.42],[1,1.48,52.08],[2,1.43,58.14]],"ltp":1.96,"tv":160.0,"id":475559}]}]}
{"op":"mcm","clk":"11804853090","pt":1723248006612,"mc":[{"id":"1.231582170","rc":[{"batb":[[0,1.93,10],[1,1.92,45.42],[2,1.48,52.08]],"ltp":1.96,"tv":160.0,"id":475559}]}]}
{"op":"mcm","clk":"11804853299","pt":1723248010150,"mc":[{"id":"1.231582170","rc":[{"batb":[[0,1.92,45.42],[1,1.48,52.08],[2,1.43,58.14]],"ltp":1.96,"tv":160.0,"id":475559}]}]}
{"op":"mcm","clk":"11804853427","pt":1723248012541,"mc":[{"id":"1.231582170","rc":[{"batb":[[0,1.93,10],[1,1.92,45.42],[2,1.48,52.08]],"ltp":1.96,"tv":160.0,"id":475559}]}]}
{"op":"mcm","clk":"11804853614","pt":1723248016025,"mc":[{"id":"1.231582170","rc":[{"batb":[[0,1.92,45.42],[1,1.48,52.08],[2,1.43,58.14]],"ltp":1.96,"tv":160.0,"id":475559}]}]}
{"op":"mcm","clk":"11804853805","pt":1723248019549,"mc":[{"id":"1.231582170","rc":[{"batb":[[0,1.93,10],[1,1.92,45.42],[2,1.48,52.08]],"ltp":1.96,"tv":160.0,"id":475559}]}]}
{"op":"mcm","clk":"11804854004","pt":1723248022926,"mc":[{"id":"1.231582170","rc":[{"batb":[[0,1.92,45.42],[1,1.48,52.08],[2,1.43,58.14]],"ltp":1.96,"tv":160.0,"id":475559}]}]}
{"op":"mcm","clk":"11804854130","pt":1723248025357,"mc":[{"id":"1.231582170","rc":[{"batb":[[0,1.93,10],[1,1.92,45.42],[2,1.48,52.08]],"ltp":1.96,"tv":160.0,"id":475559}]}]}
{"op":"mcm","clk":"11804854347","pt":1723248028846,"mc":[{"id":"1.231582170","rc":[{"batb":[[0,1.92,45.42],[1,1.48,52.08],[2,1.43,58.14]],"ltp":1.96,"tv":160.0,"id":475559}]}]}
{"op":"mcm","clk":"11804854485","pt":1723248031171,"mc":[{"id":"1.231582170","rc":[{"batb":[[0,1.93,10],[1,1.92,45.42],[2,1.48,52.08]],"ltp":1.96,"tv":160.0,"id":475559}]}]}
{"op":"mcm","clk":"11804854665","pt":1723248034460,"mc":[{"id":"1.231582170","rc":[{"batb":[[0,1.92,45.42],[1,1.48,52.08],[2,1.43,58.14]],"ltp":1.96,"tv":160.0,"id":475559}]}]}
{"op":"mcm","clk":"11804854804","pt":1723248037166,"mc":[{"id":"1.231582170","rc":[{"batb":[[0,1.93,10],[1,1.92,45.42],[2,1.48,52.08]],"ltp":1.96,"tv":160.0,"id":475559}]}]}
{"op":"mcm","clk":"11804854966","pt":1723248040450,"mc":[{"id":"1.231582170","rc":[{"batb":[[0,1.92,45.42],[1,1.48,52.08],[2,1.43,58.14]],"ltp":1.96,"tv":160.0,"id":475559}]}]}
{"op":"mcm","clk":"11804855096","pt":1723248042894,"mc":[{"id":"1.231582170","rc":[{"batb":[[0,1.93,10],[1,1.92,45.42],[2,1.48,52.08]],"ltp":1.96,"tv":160.0,"id":475559}]}]}
{"op":"mcm","clk":"11804855289","pt":1723248046156,"mc":[{"id":"1.231582170","rc":[{"batb":[[0,1.92,45.42],[1,1.48,52.08],[2,1.43,58.14]],"ltp":1.96,"tv":160.0,"id":475559}]}]}
{"op":"mcm","clk":"11804855445","pt":1723248048596,"mc":[{"id":"1.231582170","rc":[{"batb":[[0,1.93,10],[1,1.92,45.42],[2,1.48,52.08]],"ltp":1.96,"tv":160.0,"id":475559}]}]}
{"op":"mcm","clk":"11804855700","pt":1723248051859,"mc":[{"id":"1.231582170","rc":[{"batb":[[0,1.92,45.42],[1,1.48,52.08],[2,1.43,58.14]],"ltp":1.96,"tv":160.0,"id":475559}]}]}
{"op":"mcm","clk":"11804855852","pt":1723248054363,"mc":[{"id":"1.231582170","rc":[{"batb":[[0,1.93,10],[1,1.92,45.42],[2,1.48,52.08]],"ltp":1.96,"tv":160.0,"id":475559}]}]}
{"op":"mcm","clk":"11804856017","pt":1723248057714,"mc":[{"id":"1.231582170","rc":[{"batb":[[0,1.92,45.42],[1,1.48,52.08],[2,1.43,58.14]],"ltp":1.96,"tv":160.0,"id":475559}]}]}
{"op":"mcm","clk":"11804856172","pt":1723248060607,"mc":[{"id":"1.231582170","rc":[{"batb":[[0,1.93,10],[1,1.92,45.42],[2,1.48,52.08]],"ltp":1.96,"tv":160.0,"id":475559}]}]}
{"op":"mcm","clk":"11804856356","pt":1723248063987,"mc":[{"id":"1.231582170","rc":[{"batb":[[0,1.92,45.42],[1,1.48,52.08],[2,1.43,58.14]],"ltp":1.96,"tv":160.0,"id":475559}]}]}
{"op":"mcm","clk":"11804856491","pt":1723248066418,"mc":[{"id":"1.231582170","rc":[{"batb":[[0,1.93,10],[1,1.92,45.42],[2,1.48,52.08]],"ltp":1.96,"tv":160.0,"id":475559}]}]}
{"op":"mcm","clk":"11804856699","pt":1723248069812,"mc":[{"id":"1.231582170","rc":[{"batb":[[0,1.92,45.42],[1,1.48,52.08],[2,1.43,58.14]],"ltp":1.96,"tv":160.0,"id":475559}]}]}
{"op":"mcm","clk":"11804856821","pt":1723248072192,"mc":[{"id":"1.231582170","rc":[{"batb":[[0,1.93,10],[1,1.92,45.42],[2,1.48,52.08]],"ltp":1.96,"tv":160.0,"id":475559}]}]}
{"op":"mcm","clk":"11804856994","pt":1723248075701,"mc":[{"id":"1.231582170","rc":[{"batb":[[0,1.92,45.42],[1,1.48,52.08],[2,1.43,58.14]],"ltp":1.96,"tv":160.0,"id":475559}]}]}
{"op":"mcm","clk":"11804857155","pt":1723248078804,"mc":[{"id":"1.231582170","rc":[{"batb":[[0,1.93,10],[1,1.92,45.42],[2,1.48,52.08]],"ltp":1.96,"tv":160.0,"id":475559}]}]}
{"op":"mcm","clk":"11804857335","pt":1723248082410,"mc":[{"id":"1.231582170","rc":[{"batb":[[0,1.92,45.42],[1,1.48,52.08],[2,1.43,58.14]],"ltp":1.96,"tv":160.0,"id":475559}]}]}
{"op":"mcm","clk":"11804857511","pt":1723248085317,"mc":[{"id":"1.231582170","rc":[{"batb":[[0,1.93,10],[1,1.92,45.42],[2,1.48,52.08]],"ltp":1.96,"tv":160.0,"id":475559}]}]}
{"op":"mcm","clk":"11804857701","pt":1723248088618,"mc":[{"id":"1.231582170","rc":[{"batb":[[0,1.92,45.42],[1,1.48,52.08],[2,1.43,58.14]],"ltp":1.96,"tv":160.0,"id":475559}]}]}
{"op":"mcm","clk":"11804857872","pt":1723248091114,"mc":[{"id":"1.231582170","rc":[{"batb":[[0,1.93,10],[1,1.92,45.42],[2,1.48,52.08]],"ltp":1.96,"tv":160.0,"id":475559}]}]}
{"op":"mcm","clk":"11804858061","pt":1723248094538,"mc":[{"id":"1.231582170","rc":[{"batb":[[0,1.92,45.42],[1,1.48,52.08],[2,1.43,58.14]],"ltp":1.96,"tv":160.0,"id":475559}]}]}
{"op":"mcm","clk":"11804858229","pt":1723248097339,"mc":[{"id":"1.231582170","rc":[{"batb":[[0,1.93,10],[1,1.92,45.42],[2,1.48,52.08]],"ltp":1.96,"tv":160.0,"id":475559}]}]}
{"op":"mcm","clk":"11804858406","pt":1723248100708,"mc":[{"id":"1.231582170","rc":[{"batb":[[0,1.92,45.42],[1,1.48,52.08],[2,1.43,58.14]],"ltp":1.96,"tv":160.0,"id":475559}]}]}
{"op":"mcm","clk":"11804858582","pt":1723248103913,"mc":[{"id":"1.231582170","rc":[{"batb":[[0,1.93,10],[1,1.92,45.42],[2,1.48,52.08]],"ltp":1.96,"tv":160.0,"id":475559}]}]}
{"op":"mcm","clk":"11804858778","pt":1723248107633,"mc":[{"id":"1.231582170","rc":[{"batb":[[0,1.92,45.42],[1,1.48,52.08],[2,1.43,58.14]],"ltp":1.96,"tv":160.0,"id":475559}]}]}
{"op":"mcm","clk":"11804858924","pt":1723248110330,"mc":[{"id":"1.231582170","rc":[{"batb":[[0,1.93,10],[1,1.92,45.42],[2,1.48,52.08]],"ltp":1.96,"tv":160.0,"id":475559}]}]}
{"op":"mcm","clk":"11804859114","pt":1723248113749,"mc":[{"id":"1.231582170","rc":[{"batb":[[0,1.92,45.42],[1,1.48,52.08],[2,1.43,58.14]],"ltp":1.96,"tv":160.0,"id":475559}]}]}
{"op":"mcm","clk":"11804859255","pt":1723248116038,"mc":[{"id":"1.231582170","rc":[{"batb":[[0,1.93,10],[1,1.92,45.42],[2,1.48,52.08]],"ltp":1.96,"tv":160.0,"id":475559}]}]}
{"op":"mcm","clk":"11804859445","pt":1723248119649,"mc":[{"id":"1.231582170","rc":[{"batb":[[0,1.92,45.42],[1,1.48,52.08],[2,1.43,58.14]],"ltp":1.96,"tv":160.0,"id":475559}]}]}
{"op":"mcm","clk":"11804859574","pt":1723248122042,"mc":[{"id":"1.231582170","rc":[{"batb":[[0,1.93,10],[1,1.92,45.42],[2,1.48,52.08]],"ltp":1.96,"tv":160.0,"id":475559}]}]}
{"op":"mcm","clk":"11804859745","pt":1723248125462,"mc":[{"id":"1.231582170","rc":[{"batb":[[0,1.92,45.42],[1,1.48,52.08],[2,1.43,58.14]],"ltp":1.96,"tv":160.0,"id":475559}]}]}
{"op":"mcm","clk":"11804859974","pt":1723248129673,"mc":[{"id":"1.231582170","rc":[{"batb":[[0,1.93,10],[1,1.92,45.42],[2,1.48,52.08]],"ltp":1.96,"tv":160.0,"id":475559}]}]}
{"op":"mcm","clk":"11804860146","pt":1723248132950,"mc":[{"id":"1.231582170","rc":[{"batb":[[0,1.92,45.42],[1,1.48,52.08],[2,1.43,58.14]],"ltp":1.96,"tv":160.0,"id":475559}]}]}
{"op":"mcm","clk":"11804860338","pt":1723248136043,"mc":[{"id":"1.231582170","rc":[{"batb":[[0,1.93,10],[1,1.92,45.42],[2,1.48,52.08]],"ltp":1.96,"tv":160.0,"id":475559}]}]}
{"op":"mcm","clk":"11804860513","pt":1723248139389,"mc":[{"id":"1.231582170","rc":[{"batb":[[0,1.92,45.42],[1,1.48,52.08],[2,1.43,58.14]],"ltp":1.96,"tv":160.0,"id":475559}]}]}
{"op":"mcm","clk":"11804860642","pt":1723248142068,"mc":[{"id":"1.231582170","rc":[{"batb":[[0,1.93,10],[1,1.92,45.42],[2,1.48,52.08]],"ltp":1.96,"tv":160.0,"id":475559}]}]}
{"op":"mcm","clk":"11804860811","pt":1723248145564,"mc":[{"id":"1.231582170","rc":[{"batb":[[0,1.92,45.42],[1,1.48,52.08],[2,1.43,58.14]],"ltp":1.96,"tv":160.0,"id":475559}]}]}
{"op":"mcm","clk":"11804860946","pt":1723248148185,"mc":[{"id":"1.231582170","rc":[{"batb":[[0,1.93,10],[1,1.92,45.42],[2,1.48,52.08]],"ltp":1.96,"tv":160.0,"id":475559}]}]}
{"op":"mcm","clk":"11804861116","pt":1723248151594,"mc":[{"id":"1.231582170","rc":[{"batb":[[0,1.92,45.42],[1,1.48,52.08],[2,1.43,58.14]],"ltp":1.96,"tv":160.0,"id":475559}]}]}
{"op":"mcm","clk":"11804861274","pt":1723248154301,"mc":[{"id":"1.231582170","rc":[{"batb":[[0,1.93,10],[1,1.92,45.42],[2,1.48,52.08]],"ltp":1.96,"tv":160.0,"id":475559}]}]}
{"op":"mcm","clk":"11804861465","pt":1723248157773,"mc":[{"id":"1.231582170","rc":[{"batb":[[0,1.92,45.42],[1,1.48,52.08],[2,1.43,58.14]],"ltp":1.96,"tv":160.0,"id":475559}]}]}
{"op":"mcm","clk":"11804861571","pt":1723248160606,"mc":[{"id":"1.231582170","rc":[{"batb":[[0,1.93,10],[1,1.92,45.42],[2,1.48,52.08]],"ltp":1.96,"tv":160.0,"id":475559}]}]}
{"op":"mcm","clk":"11804861739","pt":1723248164066,"mc":[{"id":"1.231582170","rc":[{"batb":[[0,1.92,45.42],[1,1.48,52.08],[2,1.43,58.14]],"ltp":1.96,"tv":160.0,"id":475559}]}]}
{"op":"mcm","clk":"11804861860","pt":1723248166714,"mc":[{"id":"1.231582170","rc":[{"batb":[[0,1.93,10],[1,1.92,45.42],[2,1.48,52.08]],"ltp":1.96,"tv":160.0,"id":475559}]}]}
{"op":"mcm","clk":"11804861995","pt":1723248169979,"mc":[{"id":"1.231582170","rc":[{"batb":[[0,1.92,45.42],[1,1.48,52.08],[2,1.43,58.14]],"ltp":1.96,"tv":160.0,"id":475559}]}]}
{"op":"mcm","clk":"11804862106","pt":1723248172710,"mc":[{"id":"1.231582170","rc":[{"batb":[[0,1.93,10],[1,1.92,45.42],[2,1.48,52.08]],"ltp":1.96,"tv":160.0,"id":475559}]}]}
{"op":"mcm","clk":"11804862268","pt":1723248176012,"mc":[{"id":"1.231582170","rc":[{"batb":[[0,1.92,45.42],[1,1.48,52.08],[2,1.43,58.14]],"ltp":1.96,"tv":160.0,"id":475559}]}]}
{"op":"mcm","clk":"11804862382","pt":1723248178495,"mc":[{"id":"1.231582170","rc":[{"batb":[[0,1.93,10],[1,1.92,45.42],[2,1.48,52.08]],"ltp":1.96,"tv":160.0,"id":475559}]}]}
{"op":"mcm","clk":"11804862552","pt":1723248181913,"mc":[{"id":"1.231582170","rc":[{"batb":[[0,1.92,45.42],[1,1.48,52.08],[2,1.43,58.14]],"ltp":1.96,"tv":160.0,"id":475559}]}]}
{"op":"mcm","clk":"11804862668","pt":1723248184925,"mc":[{"id":"1.231582170","rc":[{"batb":[[0,1.93,10],[1,1.92,45.42],[2,1.48,52.08]],"ltp":1.96,"tv":160.0,"id":475559}]}]}
{"op":"mcm","clk":"11804862824","pt":1723248188389,"mc":[{"id":"1.231582170","rc":[{"batb":[[0,1.92,45.42],[1,1.48,52.08],[2,1.43,58.14]],"ltp":1.96,"tv":160.0,"id":475559}]}]}
{"op":"mcm","clk":"11804862945","pt":1723248190814,"mc":[{"id":"1.231582170","rc":[{"batb":[[0,1.93,10],[1,1.92,45.42],[2,1.48,52.08]],"ltp":1.96,"tv":160.0,"id":475559}]}]}
{"op":"mcm","clk":"11804863119","pt":1723248194233,"mc":[{"id":"1.231582170","rc":[{"batb":[[0,1.92,45.42],[1,1.48,52.08],[2,1.43,58.14]],"ltp":1.96,"tv":160.0,"id":475559}]}]}
{"op":"mcm","clk":"11804863249","pt":1723248197011,"mc":[{"id":"1.231582170","rc":[{"batb":[[0,1.93,10],[1,1.92,45.42],[2,1.48,52.08]],"ltp":1.96,"tv":160.0,"id":475559}]}]}
{"op":"mcm","clk":"11804863389","pt":1723248200518,"mc":[{"id":"1.231582170","rc":[{"batb":[[0,1.92,45.42],[1,1.48,52.08],[2,1.43,58.14]],"ltp":1.96,"tv":160.0,"id":475559}]}]}
{"op":"mcm","clk":"11804863504","pt":1723248203049,"mc":[{"id":"1.231582170","rc":[{"batb":[[0,1.93,10],[1,1.92,45.42],[2,1.48,52.08]],"ltp":1.96,"tv":160.0,"id":475559}]}]}
{"op":"mcm","clk":"11804863645","pt":1723248206348,"mc":[{"id":"1.231582170","rc":[{"batb":[[0,1.92,45.42],[1,1.48,52.08],[2,1.43,58.14]],"ltp":1.96,"tv":160.0,"id":475559}]}]}
{"op":"mcm","clk":"11804863870","pt":1723248211458,"mc":[{"id":"1.231582170","rc":[{"batb":[[0,1.93,10],[1,1.92,45.42],[2,1.48,52.08]],"ltp":1.96,"tv":160.0,"id":475559}]}]}
{"op":"mcm","clk":"11804864033","pt":1723248214962,"mc":[{"id":"1.231582170","rc":[{"batb":[[0,1.92,45.42],[1,1.48,52.08],[2,1.43,58.14]],"ltp":1.96,"tv":160.0,"id":475559}]}]}
{"op":"mcm","clk":"11804864175","pt":1723248217750,"mc":[{"id":"1.231582170","rc":[{"batb":[[0,1.93,10],[1,1.92,45.42],[2,1.48,52.08]],"ltp":1.96,"tv":160.0,"id":475559}]}]}
{"op":"mcm","clk":"11804864360","pt":1723248221165,"mc":[{"id":"1.231582170","rc":[{"batb":[[0,1.92,45.42],[1,1.48,52.08],[2,1.43,58.14]],"ltp":1.96,"tv":160.0,"id":475559}]}]}
{"op":"mcm","clk":"11804864464","pt":1723248223451,"mc":[{"id":"1.231582170","rc":[{"batb":[[0,1.93,10],[1,1.92,45.42],[2,1.48,52.08]],"ltp":1.96,"tv":160.0,"id":475559}]}]}
{"op":"mcm","clk":"11804864635","pt":1723248226961,"mc":[{"id":"1.231582170","rc":[{"batb":[[0,1.92,45.42],[1,1.48,52.08],[2,1.43,58.14]],"ltp":1.96,"tv":160.0,"id":475559}]}]}
{"op":"mcm","clk":"11804864798","pt":1723248230364,"mc":[{"id":"1.231582170","rc":[{"batb":[[0,1.93,10],[1,1.92,45.42],[2,1.48,52.08]],"ltp":1.96,"tv":160.0,"id":475559}]}]}
{"op":"mcm","clk":"11804864940","pt":1723248233667,"mc":[{"id":"1.231582170","rc":[{"batb":[[0,1.92,45.42],[1,1.48,52.08],[2,1.43,58.14]],"ltp":1.96,"tv":160.0,"id":475559}]}]}
{"op":"mcm","clk":"11804865056","pt":1723248236260,"mc":[{"id":"1.231582170","rc":[{"batb":[[0,1.93,10],[1,1.92,45.42],[2,1.48,52.08]],"ltp":1.96,"tv":160.0,"id":475559}]}]}
{"op":"mcm","clk":"11804865204","pt":1723248239760,"mc":[{"id":"1.231582170","rc":[{"batb":[[0,1.92,45.42],[1,1.48,52.08],[2,1.43,58.14]],"ltp":1.96,"tv":160.0,"id":475559}]}]}
{"op":"mcm","clk":"11804865340","pt":1723248242658,"mc":[{"id":"1.231582170","rc":[{"batb":[[0,1.93,10],[1,1.92,45.42],[2,1.48,52.08]],"ltp":1.96,"tv":160.0,"id":475559}]}]}
{"op":"mcm","clk":"11804865465","pt":1723248245963,"mc":[{"id":"1.231582170","rc":[{"batb":[[0,1.92,45.42],[1,1.48,52.08],[2,1.43,58.14]],"ltp":1.96,"tv":160.0,"id":475559}]}]}
{"op":"mcm","clk":"11804865601","pt":1723248248997,"mc":[{"id":"1.231582170","rc":[{"batb":[[0,1.93,10],[1,1.92,45.42],[2,1.48,52.08]],"ltp":1.96,"tv":160.0,"id":475559}]}]}
{"op":"mcm","clk":"11804865734","pt":1723248252356,"mc":[{"id":"1.231582170","rc":[{"batb":[[0,1.92,45.42],[1,1.48,52.08],[2,1.43,58.14]],"ltp":1.96,"tv":160.0,"id":475559}]}]}
{"op":"mcm","clk":"11804865984","pt":1723248257265,"mc":[{"id":"1.231582170","rc":[{"batb":[[0,1.93,10],[1,1.92,45.42],[2,1.48,52.08]],"ltp":1.96,"tv":160.0,"id":475559}]}]}
{"op":"mcm","clk":"11804866128","pt":1723248260712,"mc":[{"id":"1.231582170","rc":[{"batb":[[0,1.92,45.42],[1,1.48,52.08],[2,1.43,58.14]],"ltp":1.96,"tv":160.0,"id":475559}]}]}
{"op":"mcm","clk":"11804866212","pt":1723248263602,"mc":[{"id":"1.231582170","rc":[{"batb":[[0,1.93,10],[1,1.92,45.42],[2,1.48,52.08]],"ltp":1.96,"tv":160.0,"id":475559}]}]}
{"op":"mcm","clk":"11804866361","pt":1723248267107,"mc":[{"id":"1.231582170","rc":[{"batb":[[0,1.92,45.42],[1,1.48,52.08],[2,1.43,58.14]],"ltp":1.96,"tv":160.0,"id":475559}]}]}
{"op":"mcm","clk":"11804866454","pt":1723248269377,"mc":[{"id":"1.231582170","rc":[{"batb":[[0,1.93,10],[1,1.92,45.42],[2,1.48,52.08]],"ltp":1.96,"tv":160.0,"id":475559}]}]}
{"op":"mcm","clk":"11804866600","pt":1723248272877,"mc":[{"id":"1.231582170","rc":[{"batb":[[0,1.92,45.42],[1,1.48,52.08],[2,1.43,58.14]],"ltp":1.96,"tv":160.0,"id":475559}]}]}
{"op":"mcm","clk":"11804866708","pt":1723248275816,"mc":[{"id":"1.231582170","rc":[{"batb":[[0,1.93,10],[1,1.92,45.42],[2,1.48,52.08]],"ltp":1.96,"tv":160.0,"id":475559}]}]}
{"op":"mcm","clk":"11804866842","pt":1723248279233,"mc":[{"id":"1.231582170","rc":[{"batb":[[0,1.92,45.42],[1,1.48,52.08],[2,1.43,58.14]],"ltp":1.96,"tv":160.0,"id":475559}]}]}
{"op":"mcm","clk":"11804866991","pt":1723248281816,"mc":[{"id":"1.231582170","rc":[{"batb":[[0,1.93,10],[1,1.92,45.42],[2,1.48,52.08]],"ltp":1.96,"tv":160.0,"id":475559}]}]}
{"op":"mcm","clk":"11804867139","pt":1723248285497,"mc":[{"id":"1.231582170","rc":[{"batb":[[0,1.92,45.42],[1,1.48,52.08],[2,1.43,58.14]],"ltp":1.96,"tv":160.0,"id":475559}]}]}
{"op":"mcm","clk":"11804867253","pt":1723248288229,"mc":[{"id":"1.231582170","rc":[{"batb":[[0,1.93,10],[1,1.92,45.42],[2,1.48,52.08]],"ltp":1.96,"tv":160.0,"id":475559}]}]}
{"op":"mcm","clk":"11804867412","pt":1723248291747,"mc":[{"id":"1.231582170","rc":[{"batb":[[0,1.92,45.42],[1,1.48,52.08],[2,1.43,58.14]],"ltp":1.96,"tv":160.0,"id":475559}]}]}
{"op":"mcm","clk":"11804867545","pt":1723248294732,"mc":[{"id":"1.231582170","rc":[{"batb":[[0,1.93,10],[1,1.92,45.42],[2,1.48,52.08]],"ltp":1.96,"tv":160.0,"id":475559}]}]}
{"op":"mcm","clk":"11804867688","pt":1723248298134,"mc":[{"id":"1.231582170","rc":[{"batb":[[0,1.92,45.42],[1,1.48,52.08],[2,1.43,58.14]],"ltp":1.96,"tv":160.0,"id":475559}]}]}
{"op":"mcm","clk":"11804867845","pt":1723248301705,"mc":[{"id":"1.231582170","rc":[{"batb":[[0,1.93,10],[1,1.92,45.42],[2,1.48,52.08]],"ltp":1.96,"tv":160.0,"id":475559}]}]}
{"op":"mcm","clk":"11804868003","pt":1723248305026,"mc":[{"id":"1.231582170","rc":[{"batb":[[0,1.92,45.42],[1,1.48,52.08],[2,1.43,58.14]],"ltp":1.96,"tv":160.0,"id":475559}]}]}
{"op":"mcm","clk":"11804868123","pt":1723248307700,"mc":[{"id":"1.231582170","rc":[{"batb":[[0,1.93,10],[1,1.92,45.42],[2,1.48,52.08]],"ltp":1.96,"tv":160.0,"id":475559}]}]}
{"op":"mcm","clk":"11804868286","pt":1723248311018,"mc":[{"id":"1.231582170","rc":[{"batb":[[0,1.92,45.42],[1,1.48,52.08],[2,1.43,58.14]],"ltp":1.96,"tv":160.0,"id":475559}]}]}
{"op":"mcm","clk":"11804868584","pt":1723248317015,"mc":[{"id":"1.231582170","rc":[{"batb":[[0,1.93,10],[1,1.92,45.42],[2,1.48,52.08]],"ltp":1.96,"tv":160.0,"id":475559}]}]}
{"op":"mcm","clk":"11804868733","pt":1723248320331,"mc":[{"id":"1.231582170","rc":[{"batb":[[0,1.92,45.42],[1,1.48,52.08],[2,1.43,58.14]],"ltp":1.96,"tv":160.0,"id":475559}]}]}
{"op":"mcm","clk":"11804868928","pt":1723248324047,"mc":[{"id":"1.231582170","rc":[{"batb":[[0,1.93,10],[1,1.92,45.42],[2,1.48,52.08]],"ltp":1.96,"tv":160.0,"id":475559}]}]}
{"op":"mcm","clk":"11804869124","pt":1723248327463,"mc":[{"id":"1.231582170","rc":[{"batb":[[0,1.92,45.42],[1,1.48,52.08],[2,1.43,58.14]],"ltp":1.96,"tv":160.0,"id":475559}]}]}
{"op":"mcm","clk":"11804869245","pt":1723248330034,"mc":[{"id":"1.231582170","rc":[{"batb":[[0,1.93,10],[1,1.92,45.42],[2,1.48,52.08]],"ltp":1.96,"tv":160.0,"id":475559}]}]}
{"op":"mcm","clk":"11804869409","pt":1723248333459,"mc":[{"id":"1.231582170","rc":[{"batb":[[0,1.92,45.42],[1,1.48,52.08],[2,1.43,58.14]],"ltp":1.96,"tv":160.0,"id":475559}]}]}
{"op":"mcm","clk":"11804869612","pt":1723248337647,"mc":[{"id":"1.231582170","rc":[{"batb":[[0,1.93,10],[1,1.92,45.42],[2,1.48,52.08]],"ltp":1.96,"tv":160.0,"id":475559}]}]}
{"op":"mcm","clk":"11804869800","pt":1723248340964,"mc":[{"id":"1.231582170","rc":[{"batb":[[0,1.92,45.42],[1,1.48,52.08],[2,1.43,58.14]],"ltp":1.96,"tv":160.0,"id":475559}]}]}
{"op":"mcm","clk":"11804869938","pt":1723248343777,"mc":[{"id":"1.231582170","rc":[{"batb":[[0,1.93,10],[1,1.92,45.42],[2,1.48,52.08]],"ltp":1.96,"tv":160.0,"id":475559}]}]}
{"op":"mcm","clk":"11804870081","pt":1723248347052,"mc":[{"id":"1.231582170","rc":[{"batb":[[0,1.92,45.42],[1,1.48,52.08],[2,1.43,58.14]],"ltp":1.96,"tv":160.0,"id":475559}]}]}
{"op":"mcm","clk":"11804870305","pt":1723248351880,"mc":[{"id":"1.231582170","rc":[{"batb":[[0,1.93,10],[1,1.92,45.42],[2,1.48,52.08]],"ltp":1.96,"tv":160.0,"id":475559}]}]}
{"op":"mcm","clk":"11804870487","pt":1723248355280,"mc":[{"id":"1.231582170","rc":[{"batb":[[0,1.92,45.42],[1,1.48,52.08],[2,1.43,58.14]],"ltp":1.96,"tv":160.0,"id":475559}]}]}
{"op":"mcm","clk":"11804870676","pt":1723248358757,"mc":[{"id":"1.231582170","rc":[{"batb":[[0,1.93,10],[1,1.92,45.42],[2,1.48,52.08]],"ltp":1.96,"tv":160.0,"id":475559}]}]}
{"op":"mcm","clk":"11804870859","pt":1723248362288,"mc":[{"id":"1.231582170","rc":[{"batb":[[0,1.92,45.42],[1,1.48,52.08],[2,1.43,58.14]],"ltp":1.96,"tv":160.0,"id":475559}]}]}
{"op":"mcm","clk":"11804870986","pt":1723248364876,"mc":[{"id":"1.231582170","rc":[{"batb":[[0,1.93,10],[1,1.92,45.42],[2,1.48,52.08]],"ltp":1.96,"tv":160.0,"id":475559}]}]}
{"op":"mcm","clk":"11804871177","pt":1723248368172,"mc":[{"id":"1.231582170","rc":[{"batb":[[0,1.92,45.42],[1,1.48,52.08],[2,1.43,58.14]],"ltp":1.96,"tv":160.0,"id":475559}]}]}
{"op":"mcm","clk":"11804871354","pt":1723248371592,"mc":[{"id":"1.231582170","rc":[{"batb":[[0,1.93,10],[1,1.92,45.42],[2,1.48,52.08]],"ltp":1.96,"tv":160.0,"id":475559}]}]}
{"op":"mcm","clk":"11804871559","pt":1723248374958,"mc":[{"id":"1.231582170","rc":[{"batb":[[0,1.92,45.42],[1,1.48,52.08],[2,1.43,58.14]],"ltp":1.96,"tv":160.0,"id":475559}]}]}
{"op":"mcm","clk":"11804871761","pt":1723248378783,"mc":[{"id":"1.231582170","rc":[{"batb":[[0,1.93,10],[1,1.92,45.42],[2,1.48,52.08]],"ltp":1.96,"tv":160.0,"id":475559}]}]}
{"op":"mcm","clk":"11804871931","pt":1723248382071,"mc":[{"id":"1.231582170","rc":[{"batb":[[0,1.92,45.42],[1,1.48,52.08],[2,1.43,58.14]],"ltp":1.96,"tv":160.0,"id":475559}]}]}
{"op":"mcm","clk":"11804872057","pt":1723248384598,"mc":[{"id":"1.231582170","rc":[{"batb":[[0,1.93,10],[1,1.92,45.42],[2,1.48,52.08]],"ltp":1.96,"tv":160.0,"id":475559}]}]}
{"op":"mcm","clk":"11804872251","pt":1723248388020,"mc":[{"id":"1.231582170","rc":[{"batb":[[0,1.92,45.42],[1,1.48,52.08],[2,1.43,58.14]],"ltp":1.96,"tv":160.0,"id":475559}]}]}
{"op":"mcm","clk":"11804872359","pt":1723248390604,"mc":[{"id":"1.231582170","rc":[{"batb":[[0,1.93,10],[1,1.92,45.42],[2,1.48,52.08]],"ltp":1.96,"tv":160.0,"id":475559}]}]}
{"op":"mcm","clk":"11804872521","pt":1723248393915,"mc":[{"id":"1.231582170","rc":[{"batb":[[0,1.92,45.42],[1,1.48,52.08],[2,1.43,58.14]],"ltp":1.96,"tv":160.0,"id":475559}]}]}
{"op":"mcm","clk":"11804872702","pt":1723248396808,"mc":[{"id":"1.231582170","rc":[{"batb":[[0,1.93,10],[1,1.92,45.42],[2,1.48,52.08]],"ltp":1.96,"tv":160.0,"id":475559}]}]}
{"op":"mcm","clk":"11804872886","pt":1723248400108,"mc":[{"id":"1.231582170","rc":[{"batb":[[0,1.92,45.42],[1,1.48,52.08],[2,1.43,58.14]],"ltp":1.96,"tv":160.0,"id":475559}]}]}
{"op":"mcm","clk":"11804873034","pt":1723248402904,"mc":[{"id":"1.231582170","rc":[{"batb":[[0,1.93,10],[1,1.92,45.42],[2,1.48,52.08]],"ltp":1.96,"tv":160.0,"id":475559}]}]}
{"op":"mcm","clk":"11804873210","pt":1723248406313,"mc":[{"id":"1.231582170","rc":[{"batb":[[0,1.92,45.42],[1,1.48,52.08],[2,1.43,58.14]],"ltp":1.96,"tv":160.0,"id":475559}]}]}
{"op":"mcm","clk":"11804873320","pt":1723248408533,"mc":[{"id":"1.231582170","rc":[{"batb":[[0,1.93,10],[1,1.92,45.42],[2,1.48,52.08]],"ltp":1.96,"tv":160.0,"id":475559}]}]}
{"op":"mcm","clk":"11804873475","pt":1723248411805,"mc":[{"id":"1.231582170","rc":[{"batb":[[0,1.92,45.42],[1,1.48,52.08],[2,1.43,58.14]],"ltp":1.96,"tv":160.0,"id":475559}]}]}
{"op":"mcm","clk":"11804873622","pt":1723248414433,"mc":[{"id":"1.231582170","rc":[{"batb":[[0,1.93,10],[1,1.92,45.42],[2,1.48,52.08]],"ltp":1.96,"tv":160.0,"id":475559}]}]}
{"op":"mcm","clk":"11804873805","pt":1723248417739,"mc":[{"id":"1.231582170","rc":[{"batb":[[0,1.92,45.42],[1,1.48,52.08],[2,1.43,58.14]],"ltp":1.96,"tv":160.0,"id":475559}]}]}
{"op":"mcm","clk":"11804873949","pt":1723248420533,"mc":[{"id":"1.231582170","rc":[{"batb":[[0,1.93,10],[1,1.92,45.42],[2,1.48,52.08]],"ltp":1.96,"tv":160.0,"id":475559}]}]}
{"op":"mcm","clk":"11804874095","pt":1723248423709,"mc":[{"id":"1.231582170","rc":[{"batb":[[0,1.92,45.42],[1,1.48,52.08],[2,1.43,58.14]],"ltp":1.96,"tv":160.0,"id":475559}]}]}
{"op":"mcm","clk":"11804874336","pt":1723248428329,"mc":[{"id":"1.231582170","rc":[{"batb":[[0,1.93,10],[1,1.92,45.42],[2,1.48,52.08]],"ltp":1.96,"tv":160.0,"id":475559}]}]}
{"op":"mcm","clk":"11804874522","pt":1723248431946,"mc":[{"id":"1.231582170","rc":[{"batb":[[0,1.92,45.42],[1,1.48,52.08],[2,1.43,58.14]],"ltp":1.96,"tv":160.0,"id":475559}]}]}
{"op":"mcm","clk":"11804874704","pt":1723248435214,"mc":[{"id":"1.231582170","rc":[{"batb":[[0,1.93,10],[1,1.92,45.42],[2,1.48,52.08]],"ltp":1.96,"tv":160.0,"id":475559}]}]}
{"op":"mcm","clk":"11804874871","pt":1723248438720,"mc":[{"id":"1.231582170","rc":[{"batb":[[0,1.92,45.42],[1,1.48,52.08],[2,1.43,58.14]],"ltp":1.96,"tv":160.0,"id":475559}]}]}
{"op":"mcm","clk":"11804874985","pt":1723248441519,"mc":[{"id":"1.231582170","rc":[{"batb":[[0,1.93,10],[1,1.92,45.42],[2,1.48,52.08]],"ltp":1.96,"tv":160.0,"id":475559}]}]}
{"op":"mcm","clk":"11804875174","pt":1723248444935,"mc":[{"id":"1.231582170","rc":[{"batb":[[0,1.92,45.42],[1,1.48,52.08],[2,1.43,58.14]],"ltp":1.96,"tv":160.0,"id":475559}]}]}
{"op":"mcm","clk":"11804875319","pt":1723248447561,"mc":[{"id":"1.231582170","rc":[{"batb":[[0,1.93,10],[1,1.92,45.42],[2,1.48,52.08]],"ltp":1.96,"tv":160.0,"id":475559}]}]}
{"op":"mcm","clk":"11804875497","pt":1723248450836,"mc":[{"id":"1.231582170","rc":[{"batb":[[0,1.92,45.42],[1,1.48,52.08],[2,1.43,58.14]],"ltp":1.96,"tv":160.0,"id":475559}]}]}
{"op":"mcm","clk":"11804875647","pt":1723248453735,"mc":[{"id":"1.231582170","rc":[{"batb":[[0,1.93,10],[1,1.92,45.42],[2,1.48,52.08]],"ltp":1.96,"tv":160.0,"id":475559}]}]}
{"op":"mcm","clk":"11804875837","pt":1723248457145,"mc":[{"id":"1.231582170","rc":[{"batb":[[0,1.92,45.42],[1,1.48,52.08],[2,1.43,58.14]],"ltp":1.96,"tv":160.0,"id":475559}]}]}
{"op":"mcm","clk":"11804876111","pt":1723248462369,"mc":[{"id":"1.231582170","rc":[{"batb":[[0,1.93,10],[1,1.92,45.42],[2,1.48,52.08]],"ltp":1.96,"tv":160.0,"id":475559}]}]}
{"op":"mcm","clk":"11804876369","pt":1723248465884,"mc":[{"id":"1.231582170","rc":[{"batb":[[0,1.92,45.42],[1,1.48,52.08],[2,1.43,58.14]],"ltp":1.96,"tv":160.0,"id":475559}]}]}
{"op":"mcm","clk":"11804876548","pt":1723248468471,"mc":[{"id":"1.231582170","rc":[{"batb":[[0,1.93,10],[1,1.92,45.42],[2,1.48,52.08]],"ltp":1.96,"tv":160.0,"id":475559}]}]}
{"op":"mcm","clk":"11804876723","pt":1723248471984,"mc":[{"id":"1.231582170","rc":[{"batb":[[0,1.92,45.42],[1,1.48,52.08],[2,1.43,58.14]],"ltp":1.96,"tv":160.0,"id":475559}]}]}
{"op":"mcm","clk":"11804876911","pt":1723248475556,"mc":[{"id":"1.231582170","rc":[{"batb":[[0,1.93,10],[1,1.92,45.42],[2,1.48,52.08]],"ltp":1.96,"tv":160.0,"id":475559}]}]}
{"op":"mcm","clk":"11804877065","pt":1723248478966,"mc":[{"id":"1.231582170","rc":[{"batb":[[0,1.92,45.42],[1,1.48,52.08],[2,1.43,58.14]],"ltp":1.96,"tv":160.0,"id":475559}]}]}
{"op":"mcm","clk":"11804877208","pt":1723248481875,"mc":[{"id":"1.231582170","rc":[{"batb":[[0,1.93,10],[1,1.92,45.42],[2,1.48,52.08]],"ltp":1.96,"tv":160.0,"id":475559}]}]}
{"op":"mcm","clk":"11804877365","pt":1723248485187,"mc":[{"id":"1.231582170","rc":[{"batb":[[0,1.92,45.42],[1,1.48,52.08],[2,1.43,58.14]],"ltp":1.96,"tv":160.0,"id":475559}]}]}
{"op":"mcm","clk":"11804877518","pt":1723248488088,"mc":[{"id":"1.231582170","rc":[{"batb":[[0,1.93,10],[1,1.92,45.42],[2,1.48,52.08]],"ltp":1.96,"tv":160.0,"id":475559}]}]}
{"op":"mcm","clk":"11804877693","pt":1723248491597,"mc":[{"id":"1.231582170","rc":[{"batb":[[0,1.92,45.42],[1,1.48,52.08],[2,1.43,58.14]],"ltp":1.96,"tv":160.0,"id":475559}]}]}
{"op":"mcm","clk":"11804877803","pt":1723248493983,"mc":[{"id":"1.231582170","rc":[{"batb":[[0,1.93,10],[1,1.92,45.42],[2,1.48,52.08]],"ltp":1.96,"tv":160.0,"id":475559}]}]}
{"op":"mcm","clk":"11804878010","pt":1723248497401,"mc":[{"id":"1.231582170","rc":[{"batb":[[0,1.92,45.42],[1,1.48,52.08],[2,1.43,58.14]],"ltp":1.96,"tv":160.0,"id":475559}]}]}
{"op":"mcm","clk":"11804878162","pt":1723248500095,"mc":[{"id":"1.231582170","rc":[{"batb":[[0,1.93,10],[1,1.92,45.42],[2,1.48,52.08]],"ltp":1.96,"tv":160.0,"id":475559}]}]}
{"op":"mcm","clk":"11804878325","pt":1723248503376,"mc":[{"id":"1.231582170","rc":[{"batb":[[0,1.92,45.42],[1,1.48,52.08],[2,1.43,58.14]],"ltp":1.96,"tv":160.0,"id":475559}]}]}
{"op":"mcm","clk":"11804878469","pt":1723248506183,"mc":[{"id":"1.231582170","rc":[{"batb":[[0,1.93,10],[1,1.92,45.42],[2,1.48,52.08]],"ltp":1.96,"tv":160.0,"id":475559}]}]}
{"op":"mcm","clk":"11804878650","pt":1723248509687,"mc":[{"id":"1.231582170","rc":[{"batb":[[0,1.92,45.42],[1,1.48,52.08],[2,1.43,58.14]],"ltp":1.96,"tv":160.0,"id":475559}]}]}
{"op":"mcm","clk":"11804878875","pt":1723248513723,"mc":[{"id":"1.231582170","rc":[{"batb":[[0,1.93,10],[1,1.92,45.42],[2,1.48,52.08]],"ltp":1.96,"tv":160.0,"id":475559}]}]}
{"op":"mcm","clk":"11804879031","pt":1723248517291,"mc":[{"id":"1.231582170","rc":[{"batb":[[0,1.92,45.42],[1,1.48,52.08],[2,1.43,58.14]],"ltp":1.96,"tv":160.0,"id":475559}]}]}
{"op":"mcm","clk":"11804879191","pt":1723248520394,"mc":[{"id":"1.231582170","rc":[{"batb":[[0,1.93,10],[1,1.92,45.42],[2,1.48,52.08]],"ltp":1.96,"tv":160.0,"id":475559}]}]}
{"op":"mcm","clk":"11804879355","pt":1723248523815,"mc":[{"id":"1.231582170","rc":[{"batb":[[0,1.92,45.42],[1,1.48,52.08],[2,1.43,58.14]],"ltp":1.96,"tv":160.0,"id":475559}]}]}
{"op":"mcm","clk":"11804879531","pt":1723248526916,"mc":[{"id":"1.231582170","rc":[{"batb":[[0,1.93,10],[1,1.92,45.42],[2,1.48,52.08]],"ltp":1.96,"tv":160.0,"id":475559}]}]}
{"op":"mcm","clk":"11804879725","pt":1723248530298,"mc":[{"id":"1.231582170","rc":[{"batb":[[0,1.92,45.42],[1,1.48,52.08],[2,1.43,58.14]],"ltp":1.96,"tv":160.0,"id":475559}]}]}
{"op":"mcm","clk":"11804879885","pt":1723248532933,"mc":[{"id":"1.231582170","rc":[{"batb":[[0,1.93,10],[1,1.92,45.42],[2,1.48,52.08]],"ltp":1.96,"tv":160.0,"id":475559}]}]}
{"op":"mcm","clk":"11804880071","pt":1723248536232,"mc":[{"id":"1.231582170","rc":[{"batb":[[0,1.92,45.42],[1,1.48,52.08],[2,1.43,58.14]],"ltp":1.96,"tv":160.0,"id":475559}]}]}
{"op":"mcm","clk":"11804880362","pt":1723248542560,"mc":[{"id":"1.231582170","rc":[{"batb":[[0,1.93,10],[1,1.92,45.42],[2,1.48,52.08]],"ltp":1.96,"tv":160.0,"id":475559}]}]}
{"op":"mcm","clk":"11804880500","pt":1723248546036,"mc":[{"id":"1.231582170","rc":[{"batb":[[0,1.92,45.42],[1,1.48,52.08],[2,1.43,58.14]],"ltp":1.96,"tv":160.0,"id":475559}]}]}
{"op":"mcm","clk":"11804880691","pt":1723248549352,"mc":[{"id":"1.231582170","rc":[{"batb":[[0,1.93,10],[1,1.92,45.42],[2,1.48,52.08]],"ltp":1.96,"tv":160.0,"id":475559}]}]}
{"op":"mcm","clk":"11804880831","pt":1723248552660,"mc":[{"id":"1.231582170","rc":[{"batb":[[0,1.92,45.42],[1,1.48,52.08],[2,1.43,58.14]],"ltp":1.96,"tv":160.0,"id":475559}]}]}
{"op":"mcm","clk":"11804881100","pt":1723248557661,"mc":[{"id":"1.231582170","rc":[{"batb":[[0,1.93,10],[1,1.92,45.42],[2,1.48,52.08]],"ltp":1.96,"tv":160.0,"id":475559}]}]}
{"op":"mcm","clk":"11804881230","pt":1723248560974,"mc":[{"id":"1.231582170","rc":[{"batb":[[0,1.92,45.42],[1,1.48,52.08],[2,1.43,58.14]],"ltp":1.96,"tv":160.0,"id":475559}]}]}
{"op":"mcm","clk":"11804881356","pt":1723248563869,"mc":[{"id":"1.231582170","rc":[{"batb":[[0,1.93,10],[1,1.92,45.42],[2,1.48,52.08]],"ltp":1.96,"tv":160.0,"id":475559}]}]}
{"op":"mcm","clk":"11804881508","pt":1723248567134,"mc":[{"id":"1.231582170","rc":[{"batb":[[0,1.92,45.42],[1,1.48,52.08],[2,1.43,58.14]],"ltp":1.96,"tv":160.0,"id":475559}]}]}
{"op":"mcm","clk":"11804881613","pt":1723248569668,"mc":[{"id":"1.231582170","rc":[{"batb":[[0,1.93,10],[1,1.92,45.42],[2,1.48,52.08]],"ltp":1.96,"tv":160.0,"id":475559}]}]}
{"op":"mcm","clk":"11804881820","pt":1723248573146,"mc":[{"id":"1.231582170","rc":[{"batb":[[0,1.92,45.42],[1,1.48,52.08],[2,1.43,58.14]],"ltp":1.96,"tv":160.0,"id":475559}]}]}
{"op":"mcm","clk":"11804881936","pt":1723248575580,"mc":[{"id":"1.231582170","rc":[{"batb":[[0,1.93,10],[1,1.92,45.42],[2,1.48,52.08]],"ltp":1.96,"tv":160.0,"id":475559}]}]}
{"op":"mcm","clk":"11804882067","pt":1723248578941,"mc":[{"id":"1.231582170","rc":[{"batb":[[0,1.92,45.42],[1,1.48,52.08],[2,1.43,58.14]],"ltp":1.96,"tv":160.0,"id":475559}]}]}
{"op":"mcm","clk":"11804882239","pt":1723248582360,"mc":[{"id":"1.231582170","rc":[{"batb":[[0,1.93,10],[1,1.92,45.42],[2,1.48,52.08]],"ltp":1.96,"tv":160.0,"id":475559}]}]}
{"op":"mcm","clk":"11804882429","pt":1723248586153,"mc":[{"id":"1.231582170","rc":[{"batb":[[0,1.92,45.42],[1,1.48,52.08],[2,1.43,58.14]],"ltp":1.96,"tv":160.0,"id":475559}]}]}
{"op":"mcm","clk":"11804882533","pt":1723248588380,"mc":[{"id":"1.231582170","rc":[{"batb":[[0,1.93,10],[1,1.92,45.42],[2,1.48,52.08]],"ltp":1.96,"tv":160.0,"id":475559}]}]}
{"op":"mcm","clk":"11804882674","pt":1723248591858,"mc":[{"id":"1.231582170","rc":[{"batb":[[0,1.92,45.42],[1,1.48,52.08],[2,1.43,58.14]],"ltp":1.96,"tv":160.0,"id":475559}]}]}
{"op":"mcm","clk":"11804882801","pt":1723248594589,"mc":[{"id":"1.231582170","rc":[{"batb":[[0,1.93,10],[1,1.92,45.42],[2,1.48,52.08]],"ltp":1.96,"tv":160.0,"id":475559}]}]}
{"op":"mcm","clk":"11804882974","pt":1723248597979,"mc":[{"id":"1.231582170","rc":[{"batb":[[0,1.92,45.42],[1,1.48,52.08],[2,1.43,58.14]],"ltp":1.96,"tv":160.0,"id":475559}]}]}
{"op":"mcm","clk":"11804883174","pt":1723248601781,"mc":[{"id":"1.231582170","rc":[{"batb":[[0,1.93,10],[1,1.92,45.42],[2,1.48,52.08]],"ltp":1.96,"tv":160.0,"id":475559}]}]}
{"op":"mcm","clk":"11804883369","pt":1723248605276,"mc":[{"id":"1.231582170","rc":[{"batb":[[0,1.92,45.42],[1,1.48,52.08],[2,1.43,58.14]],"ltp":1.96,"tv":160.0,"id":475559}]}]}
{"op":"mcm","clk":"11804883493","pt":1723248607413,"mc":[{"id":"1.231582170","rc":[{"batb":[[0,1.93,10],[1,1.92,45.42],[2,1.48,52.08]],"ltp":1.96,"tv":160.0,"id":475559}]}]}
{"op":"mcm","clk":"11804883701","pt":1723248610773,"mc":[{"id":"1.231582170","rc":[{"batb":[[0,1.92,45.42],[1,1.48,52.08],[2,1.43,58.14]],"ltp":1.96,"tv":160.0,"id":475559}]}]}
{"op":"mcm","clk":"11804883848","pt":1723248613544,"mc":[{"id":"1.231582170","rc":[{"batb":[[0,1.93,10],[1,1.92,45.42],[2,1.48,52.08]],"ltp":1.96,"tv":160.0,"id":475559}]}]}
{"op":"mcm","clk":"11804884056","pt":1723248617014,"mc":[{"id":"1.231582170","rc":[{"batb":[[0,1.92,45.42],[1,1.48,52.08],[2,1.43,58.14]],"ltp":1.96,"tv":160.0,"id":475559}]}]}
{"op":"mcm","clk":"11804884231","pt":1723248619890,"mc":[{"id":"1.231582170","rc":[{"batb":[[0,1.93,10],[1,1.92,45.42],[2,1.48,52.08]],"ltp":1.96,"tv":160.0,"id":475559}]}]}
{"op":"mcm","clk":"11804884431","pt":1723248623422,"mc":[{"id":"1.231582170","rc":[{"batb":[[0,1.92,45.42],[1,1.48,52.08],[2,1.43,58.14]],"ltp":1.96,"tv":160.0,"id":475559}]}]}
{"op":"mcm","clk":"11804884638","pt":1723248626919,"mc":[{"id":"1.231582170","rc":[{"batb":[[0,1.93,10],[1,1.92,45.42],[2,1.48,52.08]],"ltp":1.96,"tv":160.0,"id":475559}]}]}
