{"op":"mcm","clk":"11907882538","pt":1724402549061,"mc":[{"id":"1.232184480","marketDefinition":{"bspMarket":false,"turnInPlayEnabled":true,"persistenceEnabled":true,"marketBaseRate":5.0,"eventId":"33520609","eventTypeId":"4","numberOfWinners":1,"bettingType":"ODDS","marketType":"MATCH_ODDS","marketTime":"2024-08-24T02:30:00.000Z","suspendTime":"2024-08-24T02:30:00.000Z","bspReconciled":false,"complete":true,"inPlay":false,"crossMatching":false,"runnersVoidable":false,"numberOfActiveRunners":2,"betDelay":0,"status":"OPEN","runners":[{"status":"ACTIVE","sortPriority":1,"id":247649,"name":"Hong Kong"},{"status":"ACTIVE","sortPriority":2,"id":8858694,"name":"Kuwait"}],"regulators":["MR_INT"],"countryCode":"GB","discountAllowed":false,"timezone":"GMT","openDate":"2024-08-24T02:30:00.000Z","version":6091990126,"name":"Match Odds","eventName":"Hong Kong v Kuwait"},"rc":[{"batb":[[0,1.03,200],[1,1.02,200],[2,1.01,220]],"ltp":0.0,"tv":0.0,"id":247649},{"batb":[[0,1.03,200],[1,1.02,200],[2,1.01,220]],"ltp":0.0,"tv":0.0,"id":8858694}]}]}
{"op":"mcm","clk":"11907882614","pt":1724402550696,"mc":[{"id":"1.232184480","marketDefinition":{"bspMarket":false,"turnInPlayEnabled":true,"persistenceEnabled":true,"marketBaseRate":5.0,"eventId":"33520609","eventTypeId":"4","numberOfWinners":1,"bettingType":"ODDS","marketType":"MATCH_ODDS","marketTime":"2024-08-24T02:30:00.000Z","suspendTime":"2024-08-24T02:30:00.000Z","bspReconciled":false,"complete":true,"inPlay":false,"crossMatching":false,"runnersVoidable":false,"numberOfActiveRunners":2,"betDelay":0,"status":"OPEN","runners":[{"status":"ACTIVE","sortPriority":1,"id":247649,"name":"Hong Kong"},{"status":"ACTIVE","sortPriority":2,"id":8858694,"name":"Kuwait"}],"regulators":["MR_INT"],"countryCode":"GB","discountAllowed":true,"timezone":"GMT","openDate":"2024-08-24T02:30:00.000Z","version":6091990126,"name":"Match Odds","eventName":"Hong Kong v Kuwait"}}]}
{"op":"mcm","clk":"11907887462","pt":1724402636682,"mc":[{"id":"1.232184480","rc":[{"batb":[[1,1.02,3359.28],[2,1.01,6352.92]],"ltp":0.0,"tv":0.0,"id":247649}]}]}
{"op":"mcm","clk":"11907887511","pt":1724402637346,"mc":[{"id":"1.232184480","rc":[{"batb":[[0,1.04,1616.51],[1,1.03,2339.53],[2,1.02,3359.28]],"ltp":0.0,"tv":0.0,"id":247649},{"batb":[[0,1.04,1616.51],[1,1.03,2339.53],[2,1.02,3359.28]],"ltp":0.0,"tv":0.0,"id":8858694}]}]}
{"op":"mcm","clk":"11908012014","pt":1724404375280,"mc":[{"id":"1.232184480","rc":[{"batb":[[0,1.04,1615.69],[1,1.03,2338.44],[2,1.02,3357.67]],"ltp":0.0,"tv":0.0,"id":247649},{"batb":[[0,1.04,1615.69],[1,1.03,2338.44],[2,1.02,3357.67]],"ltp":0.0,"tv":0.0,"id":8858694}]}]}
{"op":"mcm","clk":"11908028607","pt":1724404604101,"mc":[{"id":"1.232184480","rc":[{"batb":[[0,1.04,1617.22]],"ltp":0.0,"tv":0.0,"id":247649},{"batb":[[0,1.04,1617.22]],"ltp":0.0,"tv":0.0,"id":8858694}]}]}
{"op":"mcm","clk":"11908030443","pt":1724404631594,"mc":[{"id":"1.232184480","marketDefinition":{"bspMarket":false,"turnInPlayEnabled":true,"persistenceEnabled":true,"marketBaseRate":5.0,"eventId":"33520609","eventTypeId":"4","numberOfWinners":1,"bettingType":"ODDS","marketType":"MATCH_ODDS","marketTime":"2024-08-24T02:30:00.000Z","suspendTime":"2024-08-24T02:30:00.000Z","bspReconciled":false,"complete":true,"inPlay":false,"crossMatching":true,"runnersVoidable":false,"numberOfActiveRunners":2,"betDelay":0,"status":"OPEN","runners":[{"status":"ACTIVE","sortPriority":1,"id":247649,"name":"Hong Kong"},{"status":"ACTIVE","sortPriority":2,"id":8858694,"name":"Kuwait"}],"regulators":["MR_INT"],"countryCode":"GB","discountAllowed":true,"timezone":"GMT","openDate":"2024-08-24T02:30:00.000Z","version":6091990126,"name":"Match Odds","eventName":"Hong Kong v Kuwait"}}]}
{"op":"mcm","clk":"11908445126","pt":1724409775305,"mc":[{"id":"1.232184480","rc":[{"batb":[[0,1.04,1616.26],[1,1.03,2337.17],[2,1.02,3355.8]],"ltp":0.0,"tv":0.0,"id":247649},{"batb":[[0,1.04,1616.26],[1,1.03,2337.17],[2,1.02,3355.8]],"ltp":0.0,"tv":0.0,"id":8858694}]}]}
{"op":"mcm","clk":"11908517761","pt":1724410598583,"mc":[{"id":"1.232184480","rc":[{"batb":[[0,1.05,4000],[1,1.04,1616.26],[2,1.03,2337.17]],"ltp":0.0,"tv":0.0,"id":247649}]}]}
{"op":"mcm","clk":"11908518746","pt":1724410610265,"mc":[{"id":"1.232184480","rc":[{"batb":[[0,1.5,400],[1,1.04,1616.26],[2,1.03,2337.17]],"ltp":0.0,"tv":0.0,"id":8858694}]}]}
{"op":"mcm","clk":"11908536227","pt":1724410790439,"mc":[{"id":"1.232184480","rc":[{"batb":[[0,1.51,6.2],[1,1.5,400],[2,1.04,1616.26]],"ltp":0.0,"tv":0.0,"id":8858694}]}]}
{"op":"mcm","clk":"11908536928","pt":1724410797861,"mc":[{"id":"1.232184480","rc":[{"batb":[[0,1.06,141.85],[1,1.05,4000],[2,1.04,1616.26]],"ltp":0.0,"tv":0.0,"id":247649},{"batb":[[0,1.52,16.37],[1,1.51,6.2],[2,1.5,400]],"ltp":0.0,"tv":0.0,"id":8858694}]}]}
{"op":"mcm","clk":"11908684234","pt":1724412314753,"mc":[{"id":"1.232184480","rc":[{"batb":[[0,1.06,141.97],[2,1.04,1617.63]],"batl":[[0,2.98,9.82]],"ltp":0.0,"tv":0.0,"id":247649},{"batb":[[0,1.52,16.38],[1,1.51,6.2]],"ltp":0.0,"tv":0.0,"id":8858694}]}]}
{"op":"mcm","clk":"11908712409","pt":1724412598287,"mc":[{"id":"1.232184480","rc":[{"batb":[[0,1.05,4000],[1,1.04,1617.63],[2,1.03,2338.98]],"ltp":0.0,"tv":0.0,"id":247649},{"batb":[[0,1.51,6.2],[1,1.5,400],[2,1.04,1617.63]],"ltp":0.0,"tv":0.0,"id":8858694}]}]}
{"op":"mcm","clk":"11908714308","pt":1724412614966,"mc":[{"id":"1.232184480","rc":[{"batb":[[0,1.51,22.96]],"ltp":0.0,"tv":0.0,"id":8858694}]}]}
{"op":"mcm","clk":"11908738146","pt":1724412838079,"mc":[{"id":"1.232184480","rc":[{"batb":[[0,1.06,141.97],[1,1.05,4000],[2,1.04,1617.63]],"ltp":0.0,"tv":0.0,"id":247649},{"batb":[[0,1.52,16.38],[1,1.51,22.96],[2,1.5,400]],"ltp":0.0,"tv":0.0,"id":8858694}]}]}
{"op":"mcm","clk":"11908874606","pt":1724414172722,"mc":[{"id":"1.232184480","rc":[{"batb":[[0,1.2,1.77],[1,1.06,141.97],[2,1.05,4000]],"ltp":0.0,"tv":0.0,"id":247649}]}]}
{"op":"mcm","clk":"11908875485","pt":1724414181730,"mc":[{"id":"1.232184480","rc":[{"batb":[[0,1.53,1.77],[1,1.52,16.38],[2,1.51,22.96]],"ltp":0.0,"tv":0.0,"id":8858694}]}]}
{"op":"mcm","clk":"11908875622","pt":1724414183067,"mc":[{"id":"1.232184480","rc":[{"batb":[[2,1.51,6.2]],"ltp":0.0,"tv":0.0,"id":8858694}]}]}
{"op":"mcm","clk":"11908926430","pt":1724414638517,"mc":[{"id":"1.232184480","rc":[{"batb":[[1,1.05,4000],[2,1.04,1617.36]],"batl":[[0,2.98,9.82]],"ltp":0.0,"tv":0.0,"id":247649},{"batb":[[1,1.51,6.2],[2,1.5,400]],"ltp":0.0,"tv":0.0,"id":8858694}]}]}
{"op":"mcm","clk":"11908946701","pt":1724414832302,"mc":[{"id":"1.232184480","rc":[{"batb":[[1,1.51,23.56]],"ltp":0.0,"tv":0.0,"id":8858694}]}]}
{"op":"mcm","clk":"11908949615","pt":1724414861262,"mc":[{"id":"1.232184480","rc":[{"batb":[[0,1.21,40.56],[1,1.2,1.77],[2,1.05,4000]],"ltp":0.0,"tv":0.0,"id":247649},{"batb":[[0,1.54,15.77],[1,1.53,1.77],[2,1.51,23.56]],"ltp":0.0,"tv":0.0,"id":8858694}]}]}
{"op":"mcm","clk":"11908949690","pt":1724414862132,"mc":[{"id":"1.232184480","rc":[{"batb":[[2,1.51,6.2]],"ltp":0.0,"tv":0.0,"id":8858694}]}]}
{"op":"mcm","clk":"11909119062","pt":1724416431216,"mc":[{"id":"1.232184480","rc":[{"batb":[[0,1.48,92.42],[1,1.21,40.56],[2,1.2,1.77]],"ltp":0.0,"tv":0.0,"id":247649},{"batb":[[0,2.92,23.1],[1,1.54,15.77],[2,1.53,1.77]],"ltp":0.0,"tv":0.0,"id":8858694}]}]}
{"op":"mcm","clk":"11909143419","pt":1724416661646,"mc":[{"id":"1.232184480","rc":[{"batb":[[1,1.2,1.77],[2,1.05,4000]],"ltp":0.0,"tv":0.0,"id":247649}]}]}
{"op":"mcm","clk":"11909143436","pt":1724416661853,"mc":[{"id":"1.232184480","rc":[{"batb":[[1,1.53,1.77],[2,1.51,6.2]],"ltp":0.0,"tv":0.0,"id":8858694}]}]}
{"op":"mcm","clk":"11909154563","pt":1724416772601,"mc":[{"id":"1.232184480","rc":[{"batb":[[0,1.45,98.59]],"ltp":0.0,"tv":0.0,"id":247649},{"batb":[[0,2.98,22.4]],"ltp":0.0,"tv":0.0,"id":8858694}]}]}
{"op":"mcm","clk":"11909337394","pt":1724418679569,"mc":[{"id":"1.232184480","rc":[{"batb":[[0,1.46,4.84],[1,1.45,98.59],[2,1.2,1.77]],"ltp":0.0,"tv":0.0,"id":247649}]}]}
{"op":"mcm","clk":"11909484561","pt":1724420116878,"mc":[{"id":"1.232184480","rc":[{"batb":[[1,1.45,86.38]],"ltp":0.0,"tv":0.0,"id":247649},{"batb":[[0,2.98,19.63]],"ltp":0.0,"tv":0.0,"id":8858694}]}]}
{"op":"mcm","clk":"11909666602","pt":1724421796793,"mc":[{"id":"1.232184480","rc":[{"batb":[[2,1.5,400]],"ltp":0.0,"tv":0.0,"id":8858694}]}]}
{"op":"mcm","clk":"11909703042","pt":1724422155430,"mc":[{"id":"1.232184480","rc":[{"batl":[[0,1.5,2]],"ltp":0.0,"tv":0.0,"id":247649}]}]}
{"op":"mcm","clk":"11909718812","pt":1724422318938,"mc":[{"id":"1.232184480","rc":[{"batl":[[1,1.51,51.31]],"ltp":0.0,"tv":0.0,"id":247649}]}]}
{"op":"mcm","clk":"11909720568","pt":1724422335939,"mc":[{"id":"1.232184480","rc":[{"trd":[[1.46,9.23]],"batb":[[0,1.45,86.6],[1,1.2,1.77],[2,1.05,4000]],"ltp":1.46,"tv":9.23,"id":247649}],"tv":9.23}]}
{"op":"mcm","clk":"11909720678","pt":1724422337263,"mc":[{"id":"1.232184480","rc":[{"batb":[[0,1.45,86.38]],"ltp":1.46,"tv":9.23,"id":247649}]}]}
{"op":"mcm","clk":"11909721101","pt":1724422341369,"mc":[{"id":"1.232184480","rc":[{"batl":[[0,1.5,6.5]],"ltp":1.46,"tv":9.23,"id":247649}]}]}
{"op":"mcm","clk":"11909786698","pt":1724423054324,"mc":[{"id":"1.232184480","rc":[{"batl":[[0,1.5,11.24]],"ltp":1.46,"tv":9.23,"id":247649}]}]}
{"op":"mcm","clk":"11909841376","pt":1724423584836,"mc":[{"id":"1.232184480","rc":[{"batb":[[1,1.05,4000],[2,1.04,1616.95]],"ltp":1.46,"tv":9.23,"id":247649}]}]}
{"op":"mcm","clk":"11909841895","pt":1724423589740,"mc":[{"id":"1.232184480","rc":[{"batb":[[1,1.5,400],[2,1.04,1616.95]],"ltp":0.0,"tv":0.0,"id":8858694}]}]}
{"op":"mcm","clk":"11910107003","pt":1724425975337,"mc":[{"id":"1.232184480","rc":[{"trd":[[1.46,9.24]],"batb":[[2,1.04,1617.63]],"batl":[[0,1.5,11.25],[1,1.51,51.33]],"ltp":1.46,"tv":9.23,"id":247649},{"batb":[[2,1.04,1617.63]],"ltp":0.0,"tv":0.0,"id":8858694}],"tv":9.23}]}
{"op":"mcm","clk":"11910469702","pt":1724428875087,"mc":[{"id":"1.232184480","rc":[{"trd":[[1.46,9.24]],"batb":[[1,1.04,1616.67],[2,1.03,2337.71]],"batl":[[0,1.5,11.24],[1,1.51,51.38]],"ltp":1.46,"tv":9.24,"id":247649},{"batb":[[1,1.04,1616.67],[2,1.03,2337.71]],"ltp":0.0,"tv":0.0,"id":8858694}],"tv":9.24}]}
{"op":"mcm","clk":"11910542005","pt":1724429278810,"mc":[{"id":"1.232184480","rc":[{"batb":[[0,3.05,221.26],[1,2.98,19.63],[2,1.04,1616.67]],"ltp":0.0,"tv":0.0,"id":8858694}]}]}
{"op":"mcm","clk":"11910542225","pt":1724429280116,"mc":[{"id":"1.232184480","rc":[{"batl":[[0,1.48,4.56],[1,1.5,2],[2,1.51,51.38]],"ltp":1.46,"tv":9.24,"id":247649}]}]}
{"op":"mcm","clk":"11910543344","pt":1724429285933,"mc":[{"id":"1.232184480","rc":[{"trd":[[3.05,439.66]],"batb":[[0,2.98,19.63],[1,1.04,1616.67],[2,1.03,2337.71]],"ltp":3.05,"tv":439.66,"id":8858694}],"tv":448.9}]}
{"op":"mcm","clk":"11910543922","pt":1724429288922,"mc":[{"id":"1.232184480","rc":[{"batl":[[0,1.5,6.5],[1,1.51,51.38],[2,1.51,0]],"ltp":1.46,"tv":9.24,"id":247649}]}]}
{"op":"mcm","clk":"11910548933","pt":1724429316646,"mc":[{"id":"1.232184480","rc":[{"batb":[[0,3.05,331.17],[1,2.98,19.63],[2,1.04,1616.67]],"ltp":3.05,"tv":439.66,"id":8858694}]}]}
{"op":"mcm","clk":"11910548968","pt":1724429316854,"mc":[{"id":"1.232184480","rc":[{"batl":[[0,1.5,2]],"ltp":1.46,"tv":9.24,"id":247649}]}]}
{"op":"mcm","clk":"11910549534","pt":1724429320056,"mc":[{"id":"1.232184480","rc":[{"trd":[[3.05,1099.15]],"batb":[[0,2.98,19.63],[1,1.04,1616.67],[2,1.03,2337.71]],"ltp":3.05,"tv":1099.15,"id":8858694}],"tv":1108.39}]}
{"op":"mcm","clk":"11910552974","pt":1724429339993,"mc":[{"id":"1.232184480","rc":[{"batb":[[0,3.05,310.79],[1,2.98,19.63],[2,1.04,1616.67]],"ltp":3.05,"tv":1099.15,"id":8858694}]}]}
{"op":"mcm","clk":"11910555708","pt":1724429355409,"mc":[{"id":"1.232184480","rc":[{"trd":[[3.05,1720.74]],"batb":[[0,2.98,19.63],[1,1.04,1616.67],[2,1.03,2337.71]],"ltp":3.05,"tv":1720.73,"id":8858694}],"tv":1729.97}]}
{"op":"mcm","clk":"11910557058","pt":1724429363112,"mc":[{"id":"1.232184480","rc":[{"batb":[[0,3.05,312.22],[1,2.98,19.63],[2,1.04,1616.67]],"ltp":3.05,"tv":1720.73,"id":8858694}]}]}
{"op":"mcm","clk":"11910557734","pt":1724429367192,"mc":[{"id":"1.232184480","rc":[{"trd":[[3.05,2342.33]],"batb":[[0,2.98,19.63],[1,1.04,1616.67],[2,1.03,2337.71]],"ltp":3.05,"tv":2342.32,"id":8858694}],"tv":2351.56}]}
{"op":"mcm","clk":"11910558247","pt":1724429370221,"mc":[{"id":"1.232184480","rc":[{"batb":[[0,3.05,312.22],[1,2.98,19.63],[2,1.04,1616.67]],"ltp":3.05,"tv":2342.32,"id":8858694}]}]}
{"op":"mcm","clk":"11910558658","pt":1724429372530,"mc":[{"id":"1.232184480","rc":[{"trd":[[3.1,1.52]],"batb":[[0,3.1,3.24],[1,3.05,312.22],[2,2.98,19.63]],"ltp":3.1,"tv":2343.84,"id":8858694}],"tv":2353.08}]}
{"op":"mcm","clk":"11910559024","pt":1724429374626,"mc":[{"id":"1.232184480","rc":[{"batb":[[0,3.05,312.22],[1,2.98,19.63],[2,1.04,1616.67]],"ltp":3.1,"tv":2343.84,"id":8858694}]}]}
{"op":"mcm","clk":"11910559647","pt":1724429378229,"mc":[{"id":"1.232184480","rc":[{"trd":[[3.05,2963.92]],"batb":[[0,2.98,19.63],[1,1.04,1616.67],[2,1.03,2337.71]],"ltp":3.05,"tv":2965.43,"id":8858694}],"tv":2974.67}]}
{"op":"mcm","clk":"11910560284","pt":1724429381918,"mc":[{"id":"1.232184480","rc":[{"batb":[[0,3,4],[1,2.98,19.63],[2,1.04,1616.67]],"batl":[[0,3.05,310.79]],"ltp":3.05,"tv":2965.43,"id":8858694}]}]}
{"op":"mcm","clk":"11910560695","pt":1724429384321,"mc":[{"id":"1.232184480","rc":[{"batb":[[0,2.98,19.63],[1,1.04,1616.67],[2,1.03,2337.71]],"ltp":3.05,"tv":2965.43,"id":8858694}]}]}
{"op":"mcm","clk":"11910561474","pt":1724429388835,"mc":[{"id":"1.232184480","rc":[{"batb":[[0,3.05,312.22],[1,2.98,19.63],[2,1.04,1616.67]],"ltp":3.05,"tv":2965.43,"id":8858694}]}]}
{"op":"mcm","clk":"11910562056","pt":1724429392140,"mc":[{"id":"1.232184480","rc":[{"trd":[[3.05,3585.51]],"batb":[[0,2.98,19.63],[1,1.04,1616.67],[2,1.03,2337.71]],"ltp":3.05,"tv":3587.02,"id":8858694}],"tv":3596.26}]}
{"op":"mcm","clk":"11910562582","pt":1724429395237,"mc":[{"id":"1.232184480","rc":[{"trd":[[3.05,4207.1]],"ltp":3.05,"tv":4208.61,"id":8858694}],"tv":4217.85}]}
{"op":"mcm","clk":"11910563923","pt":1724429403356,"mc":[{"id":"1.232184480","rc":[{"batb":[[0,3.05,312.22],[1,2.98,19.63],[2,1.04,1616.67]],"ltp":3.05,"tv":4208.61,"id":8858694}]}]}
{"op":"mcm","clk":"11910565027","pt":1724429409479,"mc":[{"id":"1.232184480","rc":[{"trd":[[3.05,4828.68]],"batb":[[0,2.98,19.63],[1,1.04,1616.67],[2,1.03,2337.71]],"ltp":3.05,"tv":4830.2,"id":8858694}],"tv":4839.44}]}
{"op":"mcm","clk":"11910565164","pt":1724429410260,"mc":[{"id":"1.232184480","rc":[{"batb":[[0,1.46,4],[1,1.45,90.38],[2,1.04,1616.67]],"ltp":1.46,"tv":9.24,"id":247649},{"batb":[[0,3.05,9],[1,3,4],[2,2.98,19.63]],"batl":[[0,3.25,4]],"ltp":3.05,"tv":4830.2,"id":8858694}]}]}
{"op":"mcm","clk":"11910565514","pt":1724429412264,"mc":[{"id":"1.232184480","rc":[{"trd":[[3.05,4846.69]],"batb":[[0,2.98,19.63],[1,1.04,1616.67],[2,1.03,2337.71]],"batl":[[0,3.05,301.79],[1,3.25,4]],"ltp":3.05,"tv":4848.2,"id":8858694}],"tv":4857.44}]}
{"op":"mcm","clk":"11910566860","pt":1724429420102,"mc":[{"id":"1.232184480","rc":[{"trd":[[3.05,5450.27]],"batb":[[0,3.1,4],[1,3.05,9.01],[2,2.98,19.63]],"batl":[[0,3.25,4],[1,3.3,1.02]],"ltp":3.05,"tv":5451.78,"id":8858694}],"tv":5461.02}]}
{"op":"mcm","clk":"11910567271","pt":1724429422411,"mc":[{"id":"1.232184480","rc":[{"batl":[[0,1.48,4.56],[1,1.5,2],[2,1.51,51.38]],"ltp":1.46,"tv":9.24,"id":247649},{"batb":[[0,3.05,9.01],[1,2.98,19.63],[2,1.04,1616.67]],"ltp":3.05,"tv":5451.78,"id":8858694}]}]}
{"op":"mcm","clk":"11910567836","pt":1724429425390,"mc":[{"id":"1.232184480","rc":[{"batb":[[0,3.1,8],[1,3.05,13.01],[2,2.98,19.63]],"batl":[[0,3.15,3.03],[1,3.2,4],[2,3.25,4]],"ltp":3.05,"tv":5451.78,"id":8858694}]}]}
{"op":"mcm","clk":"11910568189","pt":1724429427699,"mc":[{"id":"1.232184480","rc":[{"batb":[[0,3.1,4]],"ltp":3.05,"tv":5451.78,"id":8858694}]}]}
{"op":"mcm","clk":"11910570554","pt":1724429440535,"mc":[{"id":"1.232184480","rc":[{"batl":[[0,1.48,8.56]],"ltp":1.46,"tv":9.24,"id":247649},{"trd":[[3.15,6.06]],"batb":[[0,3.1,4.97]],"batl":[[0,3.2,4],[1,3.25,4],[2,3.3,1.02]],"ltp":3.15,"tv":5457.84,"id":8858694}],"tv":5467.08}]}
{"op":"mcm","clk":"11910570975","pt":1724429442724,"mc":[{"id":"1.232184480","rc":[{"batb":[[0,3.1,4]],"ltp":3.15,"tv":5457.84,"id":8858694}]}]}
{"op":"mcm","clk":"11910572301","pt":1724429449541,"mc":[{"id":"1.232184480","rc":[{"batb":[[0,3.15,4],[1,2.98,19.63],[2,1.04,1616.67]],"ltp":3.15,"tv":5457.84,"id":8858694}]}]}
{"op":"mcm","clk":"11910572402","pt":1724429450123,"mc":[{"id":"1.232184480","rc":[{"batl":[[0,1.48,4.56]],"ltp":1.46,"tv":9.24,"id":247649}]}]}
{"op":"mcm","clk":"11910572656","pt":1724429451515,"mc":[{"id":"1.232184480","rc":[{"batl":[[0,1.5,6.5],[1,1.51,51.38],[2,1.51,0]],"ltp":1.46,"tv":9.24,"id":247649},{"batb":[[0,2.98,19.63],[1,1.04,1616.67],[2,1.03,2337.71]],"ltp":3.15,"tv":5457.84,"id":8858694}]}]}
{"op":"mcm","clk":"11910572694","pt":1724429451725,"mc":[{"id":"1.232184480","rc":[{"batb":[[0,3,5],[1,2.98,19.63],[2,1.04,1616.67]],"ltp":3.15,"tv":5457.84,"id":8858694}]}]}
{"op":"mcm","clk":"11910573416","pt":1724429455566,"mc":[{"id":"1.232184480","rc":[{"batl":[[0,1.5,10.5]],"ltp":1.46,"tv":9.24,"id":247649},{"batb":[[0,3,8]],"ltp":3.15,"tv":5457.84,"id":8858694}]}]}
{"op":"mcm","clk":"11910573810","pt":1724429457635,"mc":[{"id":"1.232184480","rc":[{"batb":[[0,3,4]],"ltp":3.15,"tv":5457.84,"id":8858694}]}]}
{"op":"mcm","clk":"11910603899","pt":1724429613557,"mc":[{"id":"1.232184480","rc":[{"batb":[[0,1.45,86.38],[1,1.04,1616.67],[2,1.03,2337.71]],"ltp":1.46,"tv":9.24,"id":247649},{"batb":[[0,3.15,4],[1,3.1,312.19],[2,3,4]],"ltp":3.15,"tv":5457.84,"id":8858694}]}]}
{"op":"mcm","clk":"11910604182","pt":1724429615141,"mc":[{"id":"1.232184480","rc":[{"trd":[[3.1,615.1],[3.15,14.06]],"batb":[[0,3.1,4],[1,3,4],[2,2.98,19.63]],"ltp":3.1,"tv":6079.43,"id":8858694}],"tv":6088.67}]}
{"op":"mcm","clk":"11910605329","pt":1724429621668,"mc":[{"id":"1.232184480","rc":[{"batb":[[0,1.46,4],[1,1.45,90.38],[2,1.04,1616.67]],"ltp":1.46,"tv":9.24,"id":247649},{"batb":[[0,3.15,4],[1,3.1,4],[2,3,4]],"batl":[[0,3.25,4],[1,3.3,1.02]],"ltp":3.1,"tv":6079.43,"id":8858694}]}]}
{"op":"mcm","clk":"11910605463","pt":1724429622442,"mc":[{"id":"1.232184480","rc":[{"batl":[[0,1.5,6.5]],"ltp":1.46,"tv":9.24,"id":247649},{"batb":[[2,2.98,19.63]],"ltp":3.1,"tv":6079.43,"id":8858694}]}]}
{"op":"mcm","clk":"11910605888","pt":1724429624669,"mc":[{"id":"1.232184480","rc":[{"batb":[[0,1.04,1616.67],[1,1.03,2337.71],[2,1.02,3356.6]],"ltp":1.46,"tv":9.24,"id":247649},{"batb":[[0,3.15,310.79],[2,1.04,1616.67]],"ltp":3.1,"tv":6079.43,"id":8858694}]}]}
{"op":"mcm","clk":"11910606049","pt":1724429625549,"mc":[{"id":"1.232184480","rc":[{"batl":[[0,1.5,2]],"ltp":1.46,"tv":9.24,"id":247649}]}]}
{"op":"mcm","clk":"11910606084","pt":1724429625765,"mc":[{"id":"1.232184480","rc":[{"batl":[[0,1.46,4.62],[1,1.5,2],[2,1.51,51.38]],"ltp":1.46,"tv":9.24,"id":247649}]}]}
{"op":"mcm","clk":"11910606449","pt":1724429627764,"mc":[{"id":"1.232184480","rc":[{"trd":[[3.15,635.65]],"batb":[[0,3.1,4],[1,1.04,1616.67],[2,1.03,2337.71]],"ltp":3.15,"tv":6701.02,"id":8858694}],"tv":6710.26}]}
{"op":"mcm","clk":"11910606703","pt":1724429629067,"mc":[{"id":"1.232184480","rc":[{"batb":[[0,1.45,86.38],[1,1.04,1616.67],[2,1.03,2337.71]],"batl":[[0,1.5,6.5],[1,1.51,51.38],[2,1.51,0]],"ltp":1.46,"tv":9.24,"id":247649},{"batb":[[1,2.98,19.63],[2,1.04,1616.67]],"ltp":3.15,"tv":6701.02,"id":8858694}]}]}
{"op":"mcm","clk":"11910608011","pt":1724429636647,"mc":[{"id":"1.232184480","rc":[{"batb":[[0,1.46,4],[1,1.45,90.38],[2,1.04,1616.67]],"ltp":1.46,"tv":9.24,"id":247649},{"batb":[[0,3.15,310.79],[1,3.1,4],[2,2.98,19.63]],"batl":[[0,3.25,4]],"ltp":3.15,"tv":6701.02,"id":8858694}]}]}
{"op":"mcm","clk":"11910608164","pt":1724429637488,"mc":[{"id":"1.232184480","rc":[{"batb":[[0,1.45,86.38],[1,1.04,1616.67],[2,1.03,2337.71]],"batl":[[0,1.5,2]],"ltp":1.46,"tv":9.24,"id":247649},{"batb":[[0,3.2,4],[1,3.15,310.79],[2,3.1,4]],"ltp":3.15,"tv":6701.02,"id":8858694}]}]}
{"op":"mcm","clk":"11910608497","pt":1724429639387,"mc":[{"id":"1.232184480","rc":[{"batb":[[0,3.15,310.79],[1,3.1,4],[2,2.98,19.63]],"ltp":3.15,"tv":6701.02,"id":8858694}]}]}
{"op":"mcm","clk":"11910609152","pt":1724429643079,"mc":[{"id":"1.232184480","rc":[{"trd":[[3.15,1257.24]],"batb":[[0,3.1,4],[1,2.98,19.63],[2,1.04,1616.67]],"ltp":3.15,"tv":7322.61,"id":8858694}],"tv":7331.85}]}
{"op":"mcm","clk":"11910609715","pt":1724429646163,"mc":[{"id":"1.232184480","rc":[{"batb":[[1,1.08,209.19],[2,1.04,1616.67]],"ltp":1.46,"tv":9.24,"id":247649}]}]}
{"op":"mcm","clk":"11910610027","pt":1724429647906,"mc":[{"id":"1.232184480","rc":[{"trd":[[3.15,1265.24]],"batl":[[0,3.15,306.79]],"ltp":3.15,"tv":7330.61,"id":8858694}],"tv":7339.85}]}
{"op":"mcm","clk":"11910610751","pt":1724429651791,"mc":[{"id":"1.232184480","rc":[{"batb":[[0,1.47,4],[1,1.46,4],[2,1.45,86.38]],"ltp":1.46,"tv":9.24,"id":247649},{"batl":[[0,3.15,310.79]],"ltp":3.15,"tv":7330.61,"id":8858694}]}]}
{"op":"mcm","clk":"11910613291","pt":1724429666101,"mc":[{"id":"1.232184480","rc":[{"trd":[[3.15,1886.83]],"ltp":3.15,"tv":7952.2,"id":8858694}],"tv":7961.44}]}
{"op":"mcm","clk":"11910613391","pt":1724429666730,"mc":[{"id":"1.232184480","rc":[{"batb":[[0,1.46,4],[1,1.45,86.38],[2,1.08,209.19]],"ltp":1.46,"tv":9.24,"id":247649}]}]}
{"op":"mcm","clk":"11910613906","pt":1724429669596,"mc":[{"id":"1.232184480","rc":[{"trd":[[3.15,1894.83]],"batl":[[0,3.15,306.79]],"ltp":3.15,"tv":7960.2,"id":8858694}],"tv":7969.44}]}
{"op":"mcm","clk":"11910614220","pt":1724429671402,"mc":[{"id":"1.232184480","rc":[{"trd":[[3.15,2508.42]],"batb":[[0,3.15,4],[1,3.1,4],[2,2.98,19.63]],"ltp":3.15,"tv":8573.78,"id":8858694}],"tv":8583.02}]}
{"op":"mcm","clk":"11910614612","pt":1724429673829,"mc":[{"id":"1.232184480","rc":[{"batl":[[0,1.49,4.52],[1,1.5,2],[2,1.51,51.38]],"ltp":1.46,"tv":9.24,"id":247649}]}]}
{"op":"mcm","clk":"11910615754","pt":1724429680109,"mc":[{"id":"1.232184480","rc":[{"batl":[[0,1.5,2],[1,1.51,51.38],[2,1.51,0]],"ltp":1.46,"tv":9.24,"id":247649},{"trd":[[3.15,2516.42]],"batb":[[0,3.1,4],[1,2.98,19.63],[2,1.04,1616.67]],"batl":[[0,3.15,302.79]],"ltp":3.15,"tv":8581.78,"id":8858694}],"tv":8591.02}]}
{"op":"mcm","clk":"11910616047","pt":1724429681953,"mc":[{"id":"1.232184480","rc":[{"batb":[[0,1.47,4],[1,1.46,4],[2,1.45,86.38]],"ltp":1.46,"tv":9.24,"id":247649},{"batl":[[0,3.15,306.79]],"ltp":3.15,"tv":8581.78,"id":8858694}]}]}
{"op":"mcm","clk":"11910616510","pt":1724429684935,"mc":[{"id":"1.232184480","rc":[{"trd":[[1.47,4]],"batb":[[0,1.46,4],[1,1.45,86.38],[2,1.08,209.19]],"ltp":1.47,"tv":13.24,"id":247649},{"trd":[[3.15,3131.87]],"batb":[[0,3.15,2.14],[1,3.1,4],[2,2.98,19.63]],"ltp":3.15,"tv":9197.23,"id":8858694}],"tv":9210.47}]}
{"op":"mcm","clk":"11910616941","pt":1724429687254,"mc":[{"id":"1.232184480","rc":[{"batb":[[0,3.15,312.93]],"ltp":3.15,"tv":9197.23,"id":8858694}]}]}
{"op":"mcm","clk":"11910617052","pt":1724429687846,"mc":[{"id":"1.232184480","rc":[{"batb":[[0,1.45,86.38],[1,1.08,209.19],[2,1.04,1616.67]],"ltp":1.47,"tv":13.24,"id":247649},{"trd":[[3.15,3749.18]],"batb":[[0,3.15,2.14]],"ltp":3.15,"tv":9814.54,"id":8858694}],"tv":9827.78}]}
{"op":"mcm","clk":"11910617946","pt":1724429693045,"mc":[{"id":"1.232184480","rc":[{"batb":[[0,3.15,312.93]],"ltp":3.15,"tv":9814.54,"id":8858694}]}]}
{"op":"mcm","clk":"11910618293","pt":1724429695040,"mc":[{"id":"1.232184480","rc":[{"trd":[[3.15,4366.49]],"batb":[[0,3.15,2.14]],"ltp":3.15,"tv":10431.86,"id":8858694}],"tv":10445.1}]}
{"op":"mcm","clk":"11910618622","pt":1724429697133,"mc":[{"id":"1.232184480","rc":[{"batb":[[0,1.45,90.38]],"ltp":1.47,"tv":13.24,"id":247649},{"batb":[[0,3.2,4],[1,3.15,2.14],[2,3.1,4]],"batl":[[0,3.25,4],[1,3.3,1.02]],"ltp":3.15,"tv":10431.86,"id":8858694}]}]}
{"op":"mcm","clk":"11910618993","pt":1724429699338,"mc":[{"id":"1.232184480","rc":[{"batb":[[0,3.15,2.14],[1,3.1,4],[2,2.98,19.63]],"ltp":3.15,"tv":10431.86,"id":8858694}]}]}
{"op":"mcm","clk":"11910619385","pt":1724429701560,"mc":[{"id":"1.232184480","rc":[{"batb":[[0,3.2,4],[1,3.15,312.93],[2,3.1,4]],"ltp":3.15,"tv":10431.86,"id":8858694}]}]}
{"op":"mcm","clk":"11910619510","pt":1724429702255,"mc":[{"id":"1.232184480","rc":[{"batb":[[0,1.45,86.38]],"ltp":1.47,"tv":13.24,"id":247649}]}]}
{"op":"mcm","clk":"11910619810","pt":1724429703825,"mc":[{"id":"1.232184480","rc":[{"batb":[[0,3.15,312.93],[1,3.1,4],[2,2.98,19.63]],"ltp":3.15,"tv":10431.86,"id":8858694}]}]}
{"op":"mcm","clk":"11910620181","pt":1724429705845,"mc":[{"id":"1.232184480","rc":[{"trd":[[3.15,4983.81]],"batb":[[0,3.15,2.14]],"ltp":3.15,"tv":11049.17,"id":8858694}],"tv":11062.41}]}
{"op":"mcm","clk":"11910620604","pt":1724429708339,"mc":[{"id":"1.232184480","rc":[{"batb":[[0,3.15,312.93]],"ltp":3.15,"tv":11049.17,"id":8858694}]}]}
{"op":"mcm","clk":"11910621119","pt":1724429711140,"mc":[{"id":"1.232184480","rc":[{"trd":[[3.15,5601.12]],"batb":[[0,3.15,2.14]],"ltp":3.15,"tv":11666.48,"id":8858694}],"tv":11679.72}]}
{"op":"mcm","clk":"11910621304","pt":1724429712356,"mc":[{"id":"1.232184480","rc":[{"batb":[[0,1.45,90.38]],"ltp":1.47,"tv":13.24,"id":247649},{"batb":[[0,3.2,4],[1,3.15,2.14],[2,3.1,4]],"batl":[[0,3.25,4],[1,3.3,1.02]],"ltp":3.15,"tv":11666.48,"id":8858694}]}]}
{"op":"mcm","clk":"11910621710","pt":1724429714566,"mc":[{"id":"1.232184480","rc":[{"batl":[[0,1.47,4.58],[1,1.5,2],[2,1.51,51.38]],"ltp":1.47,"tv":13.24,"id":247649},{"batb":[[0,3.15,2.14],[1,3.1,4],[2,2.98,19.63]],"ltp":3.15,"tv":11666.48,"id":8858694}]}]}
{"op":"mcm","clk":"11910622238","pt":1724429717261,"mc":[{"id":"1.232184480","rc":[{"batb":[[0,3.2,4],[1,3.15,312.93],[2,3.1,4]],"ltp":3.15,"tv":11666.48,"id":8858694}]}]}
{"op":"mcm","clk":"11910622362","pt":1724429717935,"mc":[{"id":"1.232184480","rc":[{"batb":[[0,1.45,86.38]],"ltp":1.47,"tv":13.24,"id":247649}]}]}
{"op":"mcm","clk":"11910622781","pt":1724429720330,"mc":[{"id":"1.232184480","rc":[{"trd":[[3.15,6218.43]],"batb":[[0,3.15,2.14],[1,3.1,4],[2,2.98,19.63]],"ltp":3.15,"tv":12283.8,"id":8858694}],"tv":12297.04}]}
{"op":"mcm","clk":"11910622999","pt":1724429721649,"mc":[{"id":"1.232184480","rc":[{"batb":[[0,3.1,4],[1,2.98,19.63],[2,1.04,1616.67]],"batl":[[0,3.15,308.66]],"ltp":3.15,"tv":12283.8,"id":8858694}]}]}
{"op":"mcm","clk":"11910623282","pt":1724429723167,"mc":[{"id":"1.232184480","rc":[{"batl":[[0,1.5,2],[1,1.51,51.38],[2,1.51,0]],"ltp":1.47,"tv":13.24,"id":247649},{"trd":[[3.15,6835.75]],"batb":[[0,3.15,6.14],[1,3.1,4],[2,2.98,19.63]],"ltp":3.15,"tv":12901.11,"id":8858694}],"tv":12914.35}]}
{"op":"mcm","clk":"11910623741","pt":1724429725663,"mc":[{"id":"1.232184480","rc":[{"batb":[[0,3.15,2.14]],"ltp":3.15,"tv":12901.11,"id":8858694}]}]}
{"op":"mcm","clk":"11910624039","pt":1724429727483,"mc":[{"id":"1.232184480","rc":[{"batb":[[0,1.45,90.38]],"ltp":1.47,"tv":13.24,"id":247649},{"batb":[[0,3.15,312.93]],"batl":[[0,3.25,4],[1,3.3,1.02]],"ltp":3.15,"tv":12901.11,"id":8858694}]}]}
{"op":"mcm","clk":"11910624124","pt":1724429727881,"mc":[{"id":"1.232184480","rc":[{"batb":[[0,1.45,86.38]],"ltp":1.47,"tv":13.24,"id":247649},{"batb":[[0,3.2,4],[1,3.15,312.93],[2,3.1,4]],"ltp":3.15,"tv":12901.11,"id":8858694}]}]}
{"op":"mcm","clk":"11910624581","pt":1724429730345,"mc":[{"id":"1.232184480","rc":[{"trd":[[3.15,7453.06]],"batb":[[0,3.15,2.14],[1,3.1,4],[2,2.98,19.63]],"ltp":3.15,"tv":13518.43,"id":8858694}],"tv":13531.67}]}
{"op":"mcm","clk":"11910624788","pt":1724429731456,"mc":[{"id":"1.232184480","rc":[{"batb":[[0,3.1,4],[1,2.98,19.63],[2,1.04,1616.67]],"batl":[[0,3.15,308.66]],"ltp":3.15,"tv":13518.43,"id":8858694}]}]}
{"op":"mcm","clk":"11910625083","pt":1724429733045,"mc":[{"id":"1.232184480","rc":[{"trd":[[3.15,8070.37]],"batb":[[0,3.15,2.14],[1,3.1,4],[2,2.98,19.63]],"ltp":3.15,"tv":14135.74,"id":8858694}],"tv":14148.98}]}
{"op":"mcm","clk":"11910626723","pt":1724429742606,"mc":[{"id":"1.232184480","rc":[{"batb":[[0,1.45,90.38]],"ltp":1.47,"tv":13.24,"id":247649},{"batb":[[0,3.2,4],[1,3.15,2.14],[2,3.1,4]],"batl":[[0,3.25,4],[1,3.3,1.02]],"ltp":3.15,"tv":14135.74,"id":8858694}]}]}
{"op":"mcm","clk":"11910627137","pt":1724429744978,"mc":[{"id":"1.232184480","rc":[{"batb":[[0,3.1,4],[1,2.98,19.63],[2,1.04,1616.67]],"ltp":3.15,"tv":14135.74,"id":8858694}]}]}
{"op":"mcm","clk":"11910628113","pt":1724429750901,"mc":[{"id":"1.232184480","rc":[{"batb":[[0,3,9]],"ltp":3.15,"tv":14135.74,"id":8858694}]}]}
{"op":"mcm","clk":"11910628450","pt":1724429753117,"mc":[{"id":"1.232184480","rc":[{"batb":[[0,3,5]],"ltp":3.15,"tv":14135.74,"id":8858694}]}]}
{"op":"mcm","clk":"11910628685","pt":1724429754435,"mc":[{"id":"1.232184480","rc":[{"batb":[[0,2.98,19.63],[1,1.04,1616.67],[2,1.03,2337.71]],"ltp":3.15,"tv":14135.74,"id":8858694}]}]}
{"op":"mcm","clk":"11910629263","pt":1724429757609,"mc":[{"id":"1.232184480","rc":[{"batl":[[0,1.5,6]],"ltp":1.47,"tv":13.24,"id":247649},{"batb":[[0,3.05,9],[1,3,4],[2,2.98,19.63]],"ltp":3.15,"tv":14135.74,"id":8858694}]}]}
{"op":"mcm","clk":"11910629660","pt":1724429760090,"mc":[{"id":"1.232184480","rc":[{"batl":[[0,1.48,4.56],[1,1.5,6],[2,1.51,51.38]],"ltp":1.47,"tv":13.24,"id":247649},{"batb":[[0,3.05,5]],"ltp":3.15,"tv":14135.74,"id":8858694}]}]}
{"op":"mcm","clk":"11910629831","pt":1724429761002,"mc":[{"id":"1.232184480","rc":[{"batb":[[0,3,4],[1,2.98,19.63],[2,1.04,1616.67]],"ltp":3.15,"tv":14135.74,"id":8858694}]}]}
{"op":"mcm","clk":"11910630138","pt":1724429762511,"mc":[{"id":"1.232184480","rc":[{"batb":[[0,1.45,86.38]],"ltp":1.47,"tv":13.24,"id":247649},{"batb":[[0,3.2,310.79],[1,3,4],[2,2.98,19.63]],"batl":[[0,3.3,1.02],[1,3.3,0]],"ltp":3.15,"tv":14135.74,"id":8858694}]}]}
{"op":"mcm","clk":"11910630211","pt":1724429762933,"mc":[{"id":"1.232184480","rc":[{"batl":[[0,1.5,6],[1,1.51,51.38],[2,1.51,0]],"ltp":1.47,"tv":13.24,"id":247649}]}]}
{"op":"mcm","clk":"11910630435","pt":1724429764007,"mc":[{"id":"1.232184480","rc":[{"trd":[[3.2,621.59]],"batb":[[0,3,4],[1,2.98,19.63],[2,1.04,1616.67]],"ltp":3.2,"tv":14757.33,"id":8858694}],"tv":14770.57}]}
{"op":"mcm","clk":"11910630971","pt":1724429766678,"mc":[{"id":"1.232184480","rc":[{"batb":[[0,3.2,310.79],[1,3,4],[2,2.98,19.63]],"ltp":3.2,"tv":14757.33,"id":8858694}]}]}
{"op":"mcm","clk":"11910631306","pt":1724429768436,"mc":[{"id":"1.232184480","rc":[{"batl":[[0,1.5,2]],"ltp":1.47,"tv":13.24,"id":247649},{"trd":[[3.2,1243.18]],"batb":[[0,3,4],[1,2.98,19.63],[2,1.04,1616.67]],"ltp":3.2,"tv":15378.92,"id":8858694}],"tv":15392.16}]}
{"op":"mcm","clk":"11910631550","pt":1724429769728,"mc":[{"id":"1.232184480","rc":[{"batl":[[0,1.5,6.5]],"ltp":1.47,"tv":13.24,"id":247649}]}]}
{"op":"mcm","clk":"11910632122","pt":1724429772611,"mc":[{"id":"1.232184480","rc":[{"batb":[[0,1.45,90.38]],"ltp":1.47,"tv":13.24,"id":247649},{"batb":[[0,3.2,310.79],[1,3,4],[2,2.98,19.63]],"batl":[[0,3.25,4]],"ltp":3.2,"tv":15378.92,"id":8858694}]}]}
{"op":"mcm","clk":"11910632331","pt":1724429773721,"mc":[{"id":"1.232184480","rc":[{"trd":[[3.2,1864.77]],"batb":[[0,3,4],[1,2.98,19.63],[2,1.04,1616.67]],"ltp":3.2,"tv":16000.51,"id":8858694}],"tv":16013.75}]}
{"op":"mcm","clk":"11910632948","pt":1724429776627,"mc":[{"id":"1.232184480","rc":[{"batb":[[0,3.2,310.79],[1,3,4],[2,2.98,19.63]],"ltp":3.2,"tv":16000.51,"id":8858694}]}]}
{"op":"mcm","clk":"11910633120","pt":1724429777620,"mc":[{"id":"1.232184480","rc":[{"batb":[[0,1.45,86.38]],"ltp":1.47,"tv":13.24,"id":247649},{"trd":[[3.2,2486.36]],"batb":[[0,3,4],[1,2.98,19.63],[2,1.04,1616.67]],"ltp":3.2,"tv":16622.09,"id":8858694}],"tv":16635.33}]}
{"op":"mcm","clk":"11910634066","pt":1724429782794,"mc":[{"id":"1.232184480","rc":[{"batb":[[0,3.2,310.79],[1,3,4],[2,2.98,19.63]],"ltp":3.2,"tv":16622.09,"id":8858694}]}]}
{"op":"mcm","clk":"11910634712","pt":1724429786137,"mc":[{"id":"1.232184480","rc":[{"batl":[[0,1.46,4.62],[1,1.5,2],[2,1.51,51.38]],"ltp":1.47,"tv":13.24,"id":247649}]}]}
{"op":"mcm","clk":"11910635181","pt":1724429788554,"mc":[{"id":"1.232184480","rc":[{"trd":[[3.2,3107.94]],"batb":[[0,2.98,19.63],[1,1.04,1616.67],[2,1.03,2337.71]],"ltp":3.2,"tv":17243.68,"id":8858694}],"tv":17256.92}]}
{"op":"mcm","clk":"11910635563","pt":1724429790540,"mc":[{"id":"1.232184480","rc":[{"batb":[[0,3.2,310.79],[1,2.98,19.63],[2,1.04,1616.67]],"ltp":3.2,"tv":17243.68,"id":8858694}]}]}
{"op":"mcm","clk":"11910635758","pt":1724429791442,"mc":[{"id":"1.232184480","rc":[{"trd":[[3.2,3729.53]],"batb":[[0,2.98,19.63],[1,1.04,1616.67],[2,1.03,2337.71]],"ltp":3.2,"tv":17865.27,"id":8858694}],"tv":17878.51}]}
{"op":"mcm","clk":"11910636147","pt":1724429793629,"mc":[{"id":"1.232184480","rc":[{"batl":[[0,1.5,2],[1,1.51,51.38],[2,1.51,0]],"ltp":1.47,"tv":13.24,"id":247649}]}]}
{"op":"mcm","clk":"11910636620","pt":1724429796229,"mc":[{"id":"1.232184480","rc":[{"batb":[[0,3.2,310.79],[1,2.98,19.63],[2,1.04,1616.67]],"ltp":3.2,"tv":17865.27,"id":8858694}]}]}
{"op":"mcm","clk":"11910636921","pt":1724429797853,"mc":[{"id":"1.232184480","rc":[{"trd":[[3.2,4351.12]],"batb":[[0,2.98,19.63],[1,1.04,1616.67],[2,1.03,2337.71]],"ltp":3.2,"tv":18486.86,"id":8858694}],"tv":18500.1}]}
{"op":"mcm","clk":"11910637296","pt":1724429800149,"mc":[{"id":"1.232184480","rc":[{"batb":[[0,3.2,310.79],[1,2.98,19.63],[2,1.04,1616.67]],"ltp":3.2,"tv":18486.86,"id":8858694}]}]}
{"op":"mcm","clk":"11910637560","pt":1724429801822,"mc":[{"id":"1.232184480","rc":[{"trd":[[3.2,4972.71]],"batb":[[0,2.98,19.63],[1,1.04,1616.67],[2,1.03,2337.71]],"ltp":3.2,"tv":19108.45,"id":8858694}],"tv":19121.69}]}
{"op":"mcm","clk":"11910637759","pt":1724429803026,"mc":[{"id":"1.232184480","rc":[{"batb":[[0,1.45,90.38]],"ltp":1.47,"tv":13.24,"id":247649},{"batb":[[0,3.05,9],[1,3,4],[2,2.98,19.63]],"batl":[[0,3.25,4]],"ltp":3.2,"tv":19108.45,"id":8858694}]}]}
{"op":"mcm","clk":"11910638211","pt":1724429805537,"mc":[{"id":"1.232184480","rc":[{"batb":[[0,3.05,5],[1,2.98,19.63],[2,1.04,1616.67]],"ltp":3.2,"tv":19108.45,"id":8858694}]}]}
{"op":"mcm","clk":"11910638377","pt":1724429806563,"mc":[{"id":"1.232184480","rc":[{"batb":[[0,1.45,86.38]],"ltp":1.47,"tv":13.24,"id":247649},{"batb":[[0,3.2,310.79]],"batl":[[0,3.3,1.02]],"ltp":3.2,"tv":19108.45,"id":8858694}]}]}
{"op":"mcm","clk":"11910638770","pt":1724429808863,"mc":[{"id":"1.232184480","rc":[{"trd":[[3.2,5594.3]],"batb":[[0,2.98,19.63],[1,1.04,1616.67],[2,1.03,2337.71]],"ltp":3.2,"tv":19730.04,"id":8858694}],"tv":19743.28}]}
{"op":"mcm","clk":"11910639206","pt":1724429811473,"mc":[{"id":"1.232184480","rc":[{"batb":[[0,3,9],[1,2.98,19.63],[2,1.04,1616.67]],"batl":[[0,3.2,310.79]],"ltp":3.2,"tv":19730.04,"id":8858694}]}]}
{"op":"mcm","clk":"11910639377","pt":1724429812568,"mc":[{"id":"1.232184480","rc":[{"trd":[[3.2,6215.89]],"ltp":3.2,"tv":20351.63,"id":8858694}],"tv":20364.87}]}
{"op":"mcm","clk":"11910639566","pt":1724429813731,"mc":[{"id":"1.232184480","rc":[{"batb":[[0,3,5]],"ltp":3.2,"tv":20351.63,"id":8858694}]}]}
{"op":"mcm","clk":"11910639774","pt":1724429814734,"mc":[{"id":"1.232184480","rc":[{"batb":[[0,2.98,19.63],[1,1.04,1616.67],[2,1.03,2337.71]],"ltp":3.2,"tv":20351.63,"id":8858694}]}]}
{"op":"mcm","clk":"11910639972","pt":1724429815838,"mc":[{"id":"1.232184480","rc":[{"batb":[[0,3.2,310.79],[1,2.98,19.63],[2,1.04,1616.67]],"ltp":3.2,"tv":20351.63,"id":8858694}]}]}
{"op":"mcm","clk":"11910640309","pt":1724429817943,"mc":[{"id":"1.232184480","rc":[{"batl":[[0,1.46,4],[1,1.5,2],[2,1.51,51.38]],"ltp":1.47,"tv":13.24,"id":247649},{"batb":[[0,3.2,314.79]],"ltp":3.2,"tv":20351.63,"id":8858694}]}]}
{"op":"mcm","clk":"11910641110","pt":1724429822550,"mc":[{"id":"1.232184480","rc":[{"batl":[[0,1.5,2],[1,1.51,51.38],[2,1.51,0]],"ltp":1.47,"tv":13.24,"id":247649},{"trd":[[3.2,6837.48]],"batb":[[0,2.98,19.63],[1,1.04,1616.67],[2,1.03,2337.71]],"ltp":3.2,"tv":20973.22,"id":8858694}],"tv":20986.46}]}
{"op":"mcm","clk":"11910641590","pt":1724429825285,"mc":[{"id":"1.232184480","rc":[{"trd":[[3.2,7459.07]],"ltp":3.2,"tv":21594.81,"id":8858694}],"tv":21608.05}]}
{"op":"mcm","clk":"11910642689","pt":1724429831371,"mc":[{"id":"1.232184480","rc":[{"batb":[[0,3.2,310.79],[1,2.98,19.63],[2,1.04,1616.67]],"ltp":3.2,"tv":21594.81,"id":8858694}]}]}
{"op":"mcm","clk":"11910643007","pt":1724429833257,"mc":[{"id":"1.232184480","rc":[{"trd":[[3.2,8080.65]],"batb":[[0,2.98,19.63],[1,1.04,1616.67],[2,1.03,2337.71]],"ltp":3.2,"tv":22216.39,"id":8858694}],"tv":22229.63}]}
{"op":"mcm","clk":"11910643401","pt":1724429835292,"mc":[{"id":"1.232184480","rc":[{"batb":[[0,3.2,310.79],[1,2.98,19.63],[2,1.04,1616.67]],"ltp":3.2,"tv":22216.39,"id":8858694}]}]}
{"op":"mcm","clk":"11910643505","pt":1724429835871,"mc":[{"id":"1.232184480","rc":[{"batl":[[0,1.49,12.56],[1,1.5,2],[2,1.51,51.38]],"ltp":1.47,"tv":13.24,"id":247649}]}]}
{"op":"mcm","clk":"11910643845","pt":1724429837759,"mc":[{"id":"1.232184480","rc":[{"trd":[[3.2,8702.24]],"batb":[[0,2.98,19.63],[1,1.04,1616.67],[2,1.03,2337.71]],"ltp":3.2,"tv":22837.98,"id":8858694}],"tv":22851.22}]}
{"op":"mcm","clk":"11910644635","pt":1724429842491,"mc":[{"id":"1.232184480","rc":[{"trd":[[3.2,9323.83]],"ltp":3.2,"tv":23459.57,"id":8858694}],"tv":23472.81}]}
{"op":"mcm","clk":"11910644997","pt":1724429844683,"mc":[{"id":"1.232184480","rc":[{"batb":[[0,1.45,101.16]],"ltp":1.47,"tv":13.24,"id":247649}]}]}
{"op":"mcm","clk":"11910645116","pt":1724429845421,"mc":[{"id":"1.232184480","rc":[{"batb":[[0,3.2,310.79],[1,2.98,19.63],[2,1.04,1616.67]],"ltp":3.2,"tv":23459.57,"id":8858694}]}]}
{"op":"mcm","clk":"11910645461","pt":1724429847580,"mc":[{"id":"1.232184480","rc":[{"trd":[[3.2,9945.42]],"batb":[[0,2.98,19.63],[1,1.04,1616.67],[2,1.03,2337.71]],"ltp":3.2,"tv":24081.16,"id":8858694}],"tv":24094.4}]}
{"op":"mcm","clk":"11910645594","pt":1724429848312,"mc":[{"id":"1.232184480","rc":[{"batb":[[0,1.45,105.16]],"ltp":1.47,"tv":13.24,"id":247649},{"batb":[[0,3.05,9],[1,3,4],[2,2.98,19.63]],"batl":[[0,3.25,4]],"ltp":3.2,"tv":24081.16,"id":8858694}]}]}
{"op":"mcm","clk":"11910645968","pt":1724429850584,"mc":[{"id":"1.232184480","rc":[{"batb":[[0,3.05,5]],"ltp":3.2,"tv":24081.16,"id":8858694}]}]}
{"op":"mcm","clk":"11910646279","pt":1724429852201,"mc":[{"id":"1.232184480","rc":[{"batl":[[0,1.49,17.08]],"ltp":1.47,"tv":13.24,"id":247649},{"trd":[[3.2,10567.01]],"batb":[[0,3,4],[1,2.98,19.63],[2,1.04,1616.67]],"batl":[[0,3.15,16.94],[1,3.25,4]],"ltp":3.2,"tv":24702.75,"id":8858694}],"tv":24715.99}]}
{"op":"mcm","clk":"11910646820","pt":1724429855399,"mc":[{"id":"1.232184480","rc":[{"batb":[[0,3.05,9],[1,3,4],[2,2.98,19.63]],"batl":[[0,3.25,4],[1,3.25,0]],"ltp":3.2,"tv":24702.75,"id":8858694}]}]}
{"op":"mcm","clk":"11910647227","pt":1724429857604,"mc":[{"id":"1.232184480","rc":[{"batb":[[0,3.2,310.79],[1,3.05,5],[2,3,4]],"batl":[[1,3.3,1.02]],"ltp":3.2,"tv":24702.75,"id":8858694}]}]}
{"op":"mcm","clk":"11910647420","pt":1724429858602,"mc":[{"id":"1.232184480","rc":[{"batb":[[0,1.45,101.16]],"batl":[[0,1.49,12.56]],"ltp":1.47,"tv":13.24,"id":247649},{"trd":[[3.2,11188.6]],"batb":[[0,3,4],[1,2.98,19.63],[2,1.04,1616.67]],"ltp":3.2,"tv":25324.34,"id":8858694}],"tv":25337.58}]}
{"op":"mcm","clk":"11910648040","pt":1724429861775,"mc":[{"id":"1.232184480","rc":[{"batb":[[0,1.46,14.78],[1,1.45,86.38],[2,1.08,209.19]],"ltp":1.47,"tv":13.24,"id":247649}]}]}
{"op":"mcm","clk":"11910648336","pt":1724429863529,"mc":[{"id":"1.232184480","rc":[{"batb":[[0,1.46,18.78]],"batl":[[0,1.49,16.56]],"ltp":1.47,"tv":13.24,"id":247649},{"batb":[[0,3.05,4],[1,3,4],[2,2.98,19.63]],"batl":[[0,3.2,4],[1,3.25,1.02]],"ltp":3.2,"tv":25324.34,"id":8858694}]}]}
{"op":"mcm","clk":"11910648766","pt":1724429865495,"mc":[{"id":"1.232184480","rc":[{"batb":[[0,3,4],[1,2.98,19.63],[2,1.04,1616.67]],"ltp":3.2,"tv":25324.34,"id":8858694}]}]}
{"op":"mcm","clk":"11910648885","pt":1724429866333,"mc":[{"id":"1.232184480","rc":[{"trd":[[1.46,28.02]],"batb":[[0,1.45,86.38],[1,1.08,209.19],[2,1.04,1616.67]],"ltp":1.46,"tv":32.01,"id":247649},{"trd":[[3.2,11801.62]],"batl":[[0,3.2,12.57],[1,3.25,0]],"ltp":3.2,"tv":25937.36,"id":8858694}],"tv":25969.38}]}
{"op":"mcm","clk":"11910648957","pt":1724429866711,"mc":[{"id":"1.232184480","rc":[{"batl":[[0,1.49,12.56]],"ltp":1.46,"tv":32.01,"id":247649}]}]}
{"op":"mcm","clk":"11910649634","pt":1724429870729,"mc":[{"id":"1.232184480","rc":[{"batb":[[0,3.2,298.23],[1,3,4],[2,2.98,19.63]],"ltp":3.2,"tv":25937.36,"id":8858694}]}]}
{"op":"mcm","clk":"11910650134","pt":1724429873621,"mc":[{"id":"1.232184480","rc":[{"trd":[[3.2,12398.07]],"batb":[[0,3,4],[1,2.98,19.63],[2,1.04,1616.67]],"batl":[[0,3.2,12.57]],"ltp":3.2,"tv":26533.81,"id":8858694}],"tv":26565.83}]}
{"op":"mcm","clk":"11910650207","pt":1724429874024,"mc":[{"id":"1.232184480","rc":[{"batb":[[0,3.05,4],[1,3,4],[2,2.98,19.63]],"batl":[[1,3.25,1.02]],"ltp":3.2,"tv":26533.81,"id":8858694}]}]}
{"op":"mcm","clk":"11910650548","pt":1724429876133,"mc":[{"id":"1.232184480","rc":[{"batb":[[0,3,4],[1,2.98,19.63],[2,1.04,1616.67]],"ltp":3.2,"tv":26533.81,"id":8858694}]}]}
{"op":"mcm","clk":"11910650886","pt":1724429878452,"mc":[{"id":"1.232184480","rc":[{"batb":[[0,1.45,90.38]],"batl":[[0,1.49,16.56]],"ltp":1.46,"tv":32.01,"id":247649},{"batb":[[0,3.05,4],[1,3,4],[2,2.98,19.63]],"batl":[[0,3.2,16.57]],"ltp":3.2,"tv":26533.81,"id":8858694}]}]}
{"op":"mcm","clk":"11910650956","pt":1724429878835,"mc":[{"id":"1.232184480","rc":[{"batl":[[0,3.2,4]],"ltp":3.2,"tv":26533.81,"id":8858694}]}]}
{"op":"mcm","clk":"11910651342","pt":1724429881051,"mc":[{"id":"1.232184480","rc":[{"batb":[[0,3,4],[1,2.98,19.63],[2,1.04,1616.67]],"ltp":3.2,"tv":26533.81,"id":8858694}]}]}
{"op":"mcm","clk":"11910652353","pt":1724429886424,"mc":[{"id":"1.232184480","rc":[{"trd":[[3.2,12406.07]],"batb":[[0,3.15,310.79],[1,3,4],[2,2.98,19.63]],"ltp":3.2,"tv":26541.81,"id":8858694}],"tv":26573.83}]}
{"op":"mcm","clk":"11910652757","pt":1724429888549,"mc":[{"id":"1.232184480","rc":[{"batl":[[0,1.49,12.56]],"ltp":1.46,"tv":32.01,"id":247649},{"trd":[[3.15,8691.96]],"batb":[[0,3,4],[1,2.98,19.63],[2,1.04,1616.67]],"ltp":3.15,"tv":27163.4,"id":8858694}],"tv":27195.42}]}
{"op":"mcm","clk":"11910652995","pt":1724429889754,"mc":[{"id":"1.232184480","rc":[{"batl":[[0,1.49,27.34]],"ltp":1.46,"tv":32.01,"id":247649}]}]}
{"op":"mcm","clk":"11910653324","pt":1724429891547,"mc":[{"id":"1.232184480","rc":[{"batb":[[0,3.15,310.79],[1,3,4],[2,2.98,19.63]],"ltp":3.15,"tv":27163.4,"id":8858694}]}]}
{"op":"mcm","clk":"11910653406","pt":1724429892032,"mc":[{"id":"1.232184480","rc":[{"trd":[[3.15,9313.55]],"batb":[[0,3,4],[1,2.98,19.63],[2,1.04,1616.67]],"ltp":3.15,"tv":27784.99,"id":8858694}],"tv":27817.01}]}
{"op":"mcm","clk":"11910653698","pt":1724429893627,"mc":[{"id":"1.232184480","rc":[{"batb":[[0,3.05,9],[1,3,4],[2,2.98,19.63]],"batl":[[0,3.25,4]],"ltp":3.15,"tv":27784.99,"id":8858694}]}]}
{"op":"mcm","clk":"11910654141","pt":1724429896029,"mc":[{"id":"1.232184480","rc":[{"batb":[[0,3.05,5]],"ltp":3.15,"tv":27784.99,"id":8858694}]}]}
{"op":"mcm","clk":"11910654321","pt":1724429897043,"mc":[{"id":"1.232184480","rc":[{"batb":[[0,2.98,19.63],[1,1.04,1616.67],[2,1.03,2337.71]],"batl":[[0,3.15,310.79],[1,3.25,4]],"ltp":3.15,"tv":27784.99,"id":8858694}]}]}
{"op":"mcm","clk":"11910654486","pt":1724429897838,"mc":[{"id":"1.232184480","rc":[{"trd":[[3.15,9935.14]],"batl":[[0,3.25,4],[1,3.25,0]],"ltp":3.15,"tv":28406.58,"id":8858694}],"tv":28438.59}]}
{"op":"mcm","clk":"11910655386","pt":1724429903054,"mc":[{"id":"1.232184480","rc":[{"batl":[[0,1.48,14.78],[1,1.49,12.56],[2,1.5,2]],"ltp":1.46,"tv":32.01,"id":247649},{"batb":[[0,3,4],[1,2.98,19.63],[2,1.04,1616.67]],"batl":[[0,3.15,310.79],[1,3.25,4]],"ltp":3.15,"tv":28406.58,"id":8858694}]}]}
{"op":"mcm","clk":"11910655646","pt":1724429904470,"mc":[{"id":"1.232184480","rc":[{"batl":[[0,1.48,19.33]],"ltp":1.46,"tv":32.01,"id":247649},{"trd":[[3.15,10556.73]],"batb":[[0,3.05,5],[1,3,4],[2,2.98,19.63]],"batl":[[0,3.25,4],[1,3.25,0]],"ltp":3.15,"tv":29028.17,"id":8858694}],"tv":29060.18}]}
{"op":"mcm","clk":"11910655792","pt":1724429905139,"mc":[{"id":"1.232184480","rc":[{"batb":[[1,2.98,19.63],[2,1.04,1616.67]],"ltp":3.15,"tv":29028.17,"id":8858694}]}]}
{"op":"mcm","clk":"11910656271","pt":1724429907581,"mc":[{"id":"1.232184480","rc":[{"batb":[[0,3.2,4],[1,3.15,310.79],[2,3.05,5]],"batl":[[1,3.3,1.02]],"ltp":3.15,"tv":29028.17,"id":8858694}]}]}
{"op":"mcm","clk":"11910656481","pt":1724429908555,"mc":[{"id":"1.232184480","rc":[{"batl":[[0,1.48,14.78]],"ltp":1.46,"tv":32.01,"id":247649},{"batb":[[2,2.98,19.63]],"batl":[[1,3.3,0]],"ltp":3.15,"tv":29028.17,"id":8858694}]}]}
{"op":"mcm","clk":"11910656516","pt":1724429908759,"mc":[{"id":"1.232184480","rc":[{"batl":[[1,3.3,1.02]],"ltp":3.15,"tv":29028.17,"id":8858694}]}]}
{"op":"mcm","clk":"11910656752","pt":1724429909955,"mc":[{"id":"1.232184480","rc":[{"batb":[[0,3.15,310.79],[1,2.98,19.63],[2,1.04,1616.67]],"ltp":3.15,"tv":29028.17,"id":8858694}]}]}
{"op":"mcm","clk":"11910657016","pt":1724429911480,"mc":[{"id":"1.232184480","rc":[{"trd":[[3.15,11178.32]],"batb":[[0,3,5]],"ltp":3.15,"tv":29649.76,"id":8858694}],"tv":29681.77}]}
{"op":"mcm","clk":"11910657093","pt":1724429911844,"mc":[{"id":"1.232184480","rc":[{"batl":[[0,3.15,310.79],[1,3.25,4],[2,3.3,1.02]],"ltp":3.15,"tv":29649.76,"id":8858694}]}]}
{"op":"mcm","clk":"11910657489","pt":1724429914044,"mc":[{"id":"1.232184480","rc":[{"trd":[[3.15,11799.91]],"batb":[[0,3.05,4],[1,3,5],[2,2.98,19.63]],"batl":[[0,3.25,4],[1,3.3,1.02],[2,3.3,0]],"ltp":3.15,"tv":30271.34,"id":8858694}],"tv":30303.36}]}
{"op":"mcm","clk":"11910657629","pt":1724429914769,"mc":[{"id":"1.232184480","rc":[{"batb":[[1,2.98,19.63],[2,1.04,1616.67]],"ltp":3.15,"tv":30271.34,"id":8858694}]}]}
{"op":"mcm","clk":"11910657999","pt":1724429916657,"mc":[{"id":"1.232184480","rc":[{"batb":[[0,3.15,310.79]],"ltp":3.15,"tv":30271.34,"id":8858694}]}]}
{"op":"mcm","clk":"11910658162","pt":1724429917169,"mc":[{"id":"1.232184480","rc":[{"batb":[[0,1.45,86.38]],"ltp":1.46,"tv":32.01,"id":247649}]}]}
{"op":"mcm","clk":"11910658476","pt":1724429918870,"mc":[{"id":"1.232184480","rc":[{"trd":[[3.15,12421.5]],"batb":[[0,2.98,19.63],[1,1.04,1616.67],[2,1.03,2337.71]],"ltp":3.15,"tv":30892.93,"id":8858694}],"tv":30924.95}]}
{"op":"mcm","clk":"11910658906","pt":1724429921469,"mc":[{"id":"1.232184480","rc":[{"batb":[[0,3,4],[1,2.98,19.63],[2,1.04,1616.67]],"batl":[[0,3.15,310.79]],"ltp":3.15,"tv":30892.93,"id":8858694}]}]}
{"op":"mcm","clk":"11910659277","pt":1724429923675,"mc":[{"id":"1.232184480","rc":[{"batb":[[0,1.45,90.38]],"ltp":1.46,"tv":32.01,"id":247649},{"trd":[[3.15,13043.09]],"batb":[[0,3.05,4],[1,3,4],[2,2.98,19.63]],"batl":[[0,3.25,4]],"ltp":3.15,"tv":31514.52,"id":8858694}],"tv":31546.54}]}
{"op":"mcm","clk":"11910659431","pt":1724429924570,"mc":[{"id":"1.232184480","rc":[{"batb":[[0,3,5],[1,2.98,19.63],[2,1.04,1616.67]],"ltp":3.15,"tv":31514.52,"id":8858694}]}]}
{"op":"mcm","clk":"11910659627","pt":1724429925670,"mc":[{"id":"1.232184480","rc":[{"batb":[[0,3.15,310.79],[1,3,5],[2,2.98,19.63]],"ltp":3.15,"tv":31514.52,"id":8858694}]}]}
{"op":"mcm","clk":"11910659825","pt":1724429926683,"mc":[{"id":"1.232184480","rc":[{"batb":[[0,1.45,86.38]],"ltp":1.46,"tv":32.01,"id":247649},{"batb":[[0,3.2,4],[1,3.15,310.79],[2,3,5]],"ltp":3.15,"tv":31514.52,"id":8858694}]}]}
{"op":"mcm","clk":"11910660125","pt":1724429928393,"mc":[{"id":"1.232184480","rc":[{"batb":[[0,3.15,310.79],[1,2.98,19.63],[2,1.04,1616.67]],"ltp":3.15,"tv":31514.52,"id":8858694}]}]}
{"op":"mcm","clk":"11910660303","pt":1724429929267,"mc":[{"id":"1.232184480","rc":[{"batl":[[0,1.46,4.62],[1,1.48,14.78],[2,1.49,12.56]],"ltp":1.46,"tv":32.01,"id":247649}]}]}
{"op":"mcm","clk":"11910660538","pt":1724429930665,"mc":[{"id":"1.232184480","rc":[{"trd":[[3.15,13664.67]],"batb":[[0,2.98,19.63],[1,1.04,1616.67],[2,1.03,2337.71]],"ltp":3.15,"tv":32136.11,"id":8858694}],"tv":32168.13}]}
{"op":"mcm","clk":"11910660777","pt":1724429932285,"mc":[{"id":"1.232184480","rc":[{"batl":[[0,1.47,4.58]],"ltp":1.46,"tv":32.01,"id":247649}]}]}
{"op":"mcm","clk":"11910661022","pt":1724429933586,"mc":[{"id":"1.232184480","rc":[{"trd":[[3.15,14286.26]],"ltp":3.15,"tv":32757.7,"id":8858694}],"tv":32789.72}]}
{"op":"mcm","clk":"11910661985","pt":1724429938576,"mc":[{"id":"1.232184480","rc":[{"batb":[[0,3.15,310.79],[1,2.98,19.63],[2,1.04,1616.67]],"ltp":3.15,"tv":32757.7,"id":8858694}]}]}
{"op":"mcm","clk":"11910662027","pt":1724429938846,"mc":[{"id":"1.232184480","rc":[{"batb":[[0,1.45,90.38]],"ltp":1.46,"tv":32.01,"id":247649},{"batb":[[0,3.2,4],[1,3.15,310.79],[2,2.98,19.63]],"batl":[[0,3.25,4]],"ltp":3.15,"tv":32757.7,"id":8858694}]}]}
{"op":"mcm","clk":"11910662228","pt":1724429940068,"mc":[{"id":"1.232184480","rc":[{"trd":[[3.15,14899.85],[3.2,12414.07]],"batb":[[0,3.15,4],[1,2.98,19.63],[2,1.04,1616.67]],"batl":[[1,3.3,1.02]],"ltp":3.15,"tv":33379.29,"id":8858694}],"tv":33411.3}]}
{"op":"mcm","clk":"11910662685","pt":1724429942671,"mc":[{"id":"1.232184480","rc":[{"batb":[[0,3.15,314.8]],"ltp":3.15,"tv":33379.29,"id":8858694}]}]}
{"op":"mcm","clk":"11910662778","pt":1724429943198,"mc":[{"id":"1.232184480","rc":[{"batb":[[0,1.45,86.38]],"ltp":1.46,"tv":32.01,"id":247649},{"trd":[[3.15,15505.43],[3.2,12422.08]],"batb":[[0,3.15,8]],"ltp":3.15,"tv":33992.87,"id":8858694}],"tv":34024.88}]}
{"op":"mcm","clk":"11910663776","pt":1724429948688,"mc":[{"id":"1.232184480","rc":[{"trd":[[3.15,16111.01]],"ltp":3.15,"tv":34598.45,"id":8858694}],"tv":34630.46}]}
{"op":"mcm","clk":"11910664239","pt":1724429951469,"mc":[{"id":"1.232184480","rc":[{"batb":[[0,3.15,318.8]],"ltp":3.15,"tv":34598.45,"id":8858694}]}]}
{"op":"mcm","clk":"11910664349","pt":1724429952101,"mc":[{"id":"1.232184480","rc":[{"trd":[[3.15,16716.58]],"batb":[[0,3.15,8]],"ltp":3.15,"tv":35204.03,"id":8858694}],"tv":35236.04}]}
{"op":"mcm","clk":"11910664798","pt":1724429954501,"mc":[{"id":"1.232184480","rc":[{"batb":[[0,1.45,90.38]],"ltp":1.46,"tv":32.01,"id":247649},{"batb":[[0,3.2,4],[1,3.15,8],[2,2.98,19.63]],"batl":[[0,3.25,4],[1,3.3,1.02]],"ltp":3.15,"tv":35204.03,"id":8858694}]}]}
{"op":"mcm","clk":"11910665183","pt":1724429956598,"mc":[{"id":"1.232184480","rc":[{"batb":[[0,3.15,8],[1,2.98,19.63],[2,1.04,1616.67]],"ltp":3.15,"tv":35204.03,"id":8858694}]}]}
{"op":"mcm","clk":"11910665355","pt":1724429957514,"mc":[{"id":"1.232184480","rc":[{"batb":[[0,1.45,86.38]],"ltp":1.46,"tv":32.01,"id":247649},{"batb":[[0,3.15,318.8]],"ltp":3.15,"tv":35204.03,"id":8858694}]}]}
{"op":"mcm","clk":"11910665455","pt":1724429957968,"mc":[{"id":"1.232184480","rc":[{"trd":[[3.15,17322.16]],"batb":[[0,3.15,8]],"ltp":3.15,"tv":35809.6,"id":8858694}],"tv":35841.62}]}
{"op":"mcm","clk":"11910665924","pt":1724429960289,"mc":[{"id":"1.232184480","rc":[{"batb":[[0,3.15,318.8]],"ltp":3.15,"tv":35809.6,"id":8858694}]}]}
{"op":"mcm","clk":"11910667104","pt":1724429966229,"mc":[{"id":"1.232184480","rc":[{"trd":[[3.15,17927.74]],"batb":[[0,3.15,8]],"ltp":3.15,"tv":36415.18,"id":8858694}],"tv":36447.2}]}
{"op":"mcm","clk":"11910667726","pt":1724429969408,"mc":[{"id":"1.232184480","rc":[{"batb":[[0,1.45,90.38]],"ltp":1.46,"tv":32.01,"id":247649},{"batb":[[0,3.2,4],[1,3.15,8],[2,2.98,19.63]],"batl":[[0,3.25,4],[1,3.3,1.02]],"ltp":3.15,"tv":36415.18,"id":8858694}]}]}
{"op":"mcm","clk":"11910668119","pt":1724429971612,"mc":[{"id":"1.232184480","rc":[{"batb":[[0,1.45,86.38]],"ltp":1.46,"tv":32.01,"id":247649},{"batb":[[0,3.15,318.8],[1,2.98,19.63],[2,1.04,1616.67]],"ltp":3.15,"tv":36415.18,"id":8858694}]}]}
{"op":"mcm","clk":"11910669705","pt":1724429980336,"mc":[{"id":"1.232184480","rc":[{"trd":[[3.15,18533.32]],"batb":[[0,3.15,8]],"ltp":3.15,"tv":37020.76,"id":8858694}],"tv":37052.78}]}
{"op":"mcm","clk":"11910670312","pt":1724429983605,"mc":[{"id":"1.232184480","rc":[{"trd":[[3.15,19138.9]],"ltp":3.15,"tv":37626.34,"id":8858694}],"tv":37658.36}]}
{"op":"mcm","clk":"11910670482","pt":1724429984594,"mc":[{"id":"1.232184480","rc":[{"batb":[[0,1.45,90.38]],"batl":[[0,1.46,4],[1,1.47,8.58],[2,1.48,14.78]],"ltp":1.46,"tv":32.01,"id":247649},{"batb":[[0,3.2,4],[1,3.15,12],[2,2.98,19.63]],"batl":[[0,3.25,4],[1,3.3,1.02]],"ltp":3.15,"tv":37626.34,"id":8858694}]}]}
{"op":"mcm","clk":"11910670678","pt":1724429985654,"mc":[{"id":"1.232184480","rc":[{"batl":[[0,1.47,4.58],[1,1.48,14.78],[2,1.49,12.56]],"ltp":1.46,"tv":32.01,"id":247649},{"batb":[[1,3.15,8]],"batl":[[1,3.3,0]],"ltp":3.15,"tv":37626.34,"id":8858694}]}]}
{"op":"mcm","clk":"11910670718","pt":1724429985813,"mc":[{"id":"1.232184480","rc":[{"batl":[[1,3.3,1.02]],"ltp":3.15,"tv":37626.34,"id":8858694}]}]}
{"op":"mcm","clk":"11910670961","pt":1724429987343,"mc":[{"id":"1.232184480","rc":[{"batb":[[0,3.15,8],[1,2.98,19.63],[2,1.04,1616.67]],"ltp":3.15,"tv":37626.34,"id":8858694}]}]}
{"op":"mcm","clk":"11910672226","pt":1724429994347,"mc":[{"id":"1.232184480","rc":[{"batb":[[0,1.45,86.38]],"ltp":1.46,"tv":32.01,"id":247649},{"batb":[[0,3.2,4],[1,3.15,318.8],[2,2.98,19.63]],"batl":[[0,3.3,1.02],[1,3.3,0]],"ltp":3.15,"tv":37626.34,"id":8858694}]}]}
{"op":"mcm","clk":"11910672619","pt":1724429996465,"mc":[{"id":"1.232184480","rc":[{"batb":[[0,3.15,318.8],[1,2.98,19.63],[2,1.04,1616.67]],"ltp":3.15,"tv":37626.34,"id":8858694}]}]}
{"op":"mcm","clk":"11910673171","pt":1724429999635,"mc":[{"id":"1.232184480","rc":[{"batb":[[0,1.45,90.38]],"batl":[[0,1.46,4],[1,1.47,8.58],[2,1.48,14.78]],"ltp":1.46,"tv":32.01,"id":247649},{"trd":[[3.15,19736.48],[3.2,12430.08]],"batb":[[0,3.2,4],[1,3.15,16.01],[2,2.98,19.63]],"batl":[[0,3.25,4],[1,3.3,1.02]],"ltp":3.15,"tv":38231.92,"id":8858694}],"tv":38263.94}]}
{"op":"mcm","clk":"11910673711","pt":1724430002660,"mc":[{"id":"1.232184480","rc":[{"batb":[[0,1.45,86.38]],"ltp":1.46,"tv":32.01,"id":247649},{"batb":[[0,3.15,326.8],[1,2.98,19.63],[2,1.04,1616.67]],"ltp":3.15,"tv":38231.92,"id":8858694}]}]}
{"op":"mcm","clk":"11910674740","pt":1724430008501,"mc":[{"id":"1.232184480","rc":[{"batl":[[0,1.47,4.58],[1,1.48,14.78],[2,1.49,12.56]],"ltp":1.46,"tv":32.01,"id":247649},{"trd":[[3.15,20334.05]],"batb":[[0,3.15,16.01]],"ltp":3.15,"tv":38829.49,"id":8858694}],"tv":38861.51}]}
{"op":"mcm","clk":"11910675670","pt":1724430013582,"mc":[{"id":"1.232184480","rc":[{"batb":[[0,3,4]],"batl":[[0,3.15,294.78]],"ltp":3.15,"tv":38829.49,"id":8858694}]}]}
{"op":"mcm","clk":"11910675830","pt":1724430014393,"mc":[{"id":"1.232184480","rc":[{"trd":[[1.47,8.58]],"batb":[[0,1.46,4],[1,1.45,86.38],[2,1.08,209.19]],"batl":[[0,1.48,14.78],[1,1.49,12.56],[2,1.5,2]],"ltp":1.47,"tv":36.59,"id":247649},{"trd":[[3.1,617.28]],"batl":[[0,3.1,14.76],[1,3.15,298.78]],"ltp":3.1,"tv":38831.67,"id":8858694}],"tv":38868.27}]}
{"op":"mcm","clk":"11910676076","pt":1724430015790,"mc":[{"id":"1.232184480","rc":[{"batb":[[0,2.98,19.63],[1,1.04,1616.67],[2,1.03,2337.71]],"ltp":3.1,"tv":38831.67,"id":8858694}]}]}
{"op":"mcm","clk":"11910676299","pt":1724430017157,"mc":[{"id":"1.232184480","rc":[{"trd":[[3.1,646.8],[3.15,20910.96]],"batl":[[0,3.15,10.33],[1,3.15,0]],"ltp":3.15,"tv":39438.1,"id":8858694}],"tv":39474.7}]}
{"op":"mcm","clk":"11910676442","pt":1724430017997,"mc":[{"id":"1.232184480","rc":[{"batb":[[0,3,21.51],[1,2.98,19.63],[2,1.04,1616.67]],"batl":[[0,3.15,6.33]],"ltp":3.15,"tv":39438.1,"id":8858694}]}]}
{"op":"mcm","clk":"11910676892","pt":1724430020583,"mc":[{"id":"1.232184480","rc":[{"trd":[[1.46,32.02]],"batb":[[0,1.45,86.38],[1,1.08,209.19],[2,1.04,1616.67]],"ltp":1.46,"tv":40.59,"id":247649},{"trd":[[3.2,12431.91]],"batb":[[0,3.2,302.64],[1,3,17.51],[2,2.98,19.63]],"ltp":3.2,"tv":39439.93,"id":8858694}],"tv":39480.53}]}
{"op":"mcm","clk":"11910677091","pt":1724430021898,"mc":[{"id":"1.232184480","rc":[{"batb":[[1,2.98,19.63],[2,1.04,1616.67]],"ltp":3.2,"tv":39439.93,"id":8858694}]}]}
{"op":"mcm","clk":"11910678037","pt":1724430026674,"mc":[{"id":"1.232184480","rc":[{"trd":[[3.2,13037.18]],"batb":[[0,2.98,19.63],[1,1.04,1616.67],[2,1.03,2337.71]],"batl":[[0,3.2,0.58]],"ltp":3.2,"tv":40045.2,"id":8858694}],"tv":40085.8}]}
{"op":"mcm","clk":"11910678064","pt":1724430026780,"mc":[{"id":"1.232184480","rc":[{"batb":[[0,3,5],[1,2.98,19.63],[2,1.04,1616.67]],"ltp":3.2,"tv":40045.2,"id":8858694}]}]}
{"op":"mcm","clk":"11910678577","pt":1724430029593,"mc":[{"id":"1.232184480","rc":[{"batb":[[0,1.45,90.38]],"ltp":1.46,"tv":40.59,"id":247649},{"batb":[[0,3.1,4],[1,3.05,4],[2,3,5]],"batl":[[0,3.25,4]],"ltp":3.2,"tv":40045.2,"id":8858694}]}]}
{"op":"mcm","clk":"11910678660","pt":1724430030009,"mc":[{"id":"1.232184480","rc":[{"batb":[[1,2.98,19.63],[2,1.04,1616.67]],"batl":[[1,3.3,1.02]],"ltp":3.2,"tv":40045.2,"id":8858694}]}]}
{"op":"mcm","clk":"11910679018","pt":1724430031883,"mc":[{"id":"1.232184480","rc":[{"batb":[[0,2.98,19.63],[1,1.04,1616.67],[2,1.03,2337.71]],"ltp":3.2,"tv":40045.2,"id":8858694}]}]}
{"op":"mcm","clk":"11910679471","pt":1724430034422,"mc":[{"id":"1.232184480","rc":[{"batb":[[0,3.05,17.22],[1,3,9],[2,2.98,19.63]],"batl":[[0,3.2,310.79],[1,3.25,4],[2,3.3,1.02]],"ltp":3.2,"tv":40045.2,"id":8858694}]}]}
{"op":"mcm","clk":"11910679781","pt":1724430036309,"mc":[{"id":"1.232184480","rc":[{"batb":[[1,3,5]],"ltp":3.2,"tv":40045.2,"id":8858694}]}]}
{"op":"mcm","clk":"11910679919","pt":1724430037202,"mc":[{"id":"1.232184480","rc":[{"batb":[[1,2.98,19.63],[2,1.04,1616.67]],"ltp":3.2,"tv":40045.2,"id":8858694}]}]}
{"op":"mcm","clk":"11910680159","pt":1724430038514,"mc":[{"id":"1.232184480","rc":[{"trd":[[3.2,13045.18]],"batb":[[0,3.15,310.79]],"batl":[[0,3.2,306.79]],"ltp":3.2,"tv":40053.2,"id":8858694}],"tv":40093.8}]}
{"op":"mcm","clk":"11910681336","pt":1724430044541,"mc":[{"id":"1.232184480","rc":[{"batl":[[0,1.47,4],[1,1.48,14.78],[2,1.49,12.56]],"ltp":1.46,"tv":40.59,"id":247649},{"batb":[[0,3.15,314.79]],"ltp":3.2,"tv":40053.2,"id":8858694}]}]}
{"op":"mcm","clk":"11910681369","pt":1724430044752,"mc":[{"id":"1.232184480","rc":[{"trd":[[3.2,13053.19]],"batl":[[0,3.2,302.79]],"ltp":3.2,"tv":40061.21,"id":8858694}],"tv":40101.81}]}
{"op":"mcm","clk":"11910682039","pt":1724430048439,"mc":[{"id":"1.232184480","rc":[{"batb":[[0,1.45,86.38]],"ltp":1.46,"tv":40.59,"id":247649},{"batb":[[0,3.2,4],[1,3.15,314.79],[2,2.98,19.63]],"ltp":3.2,"tv":40061.21,"id":8858694}]}]}
{"op":"mcm","clk":"11910682442","pt":1724430050429,"mc":[{"id":"1.232184480","rc":[{"batb":[[0,3.15,314.79],[1,2.98,19.63],[2,1.04,1616.67]],"ltp":3.2,"tv":40061.21,"id":8858694}]}]}
{"op":"mcm","clk":"11910682506","pt":1724430050756,"mc":[{"id":"1.232184480","rc":[{"batb":[[0,3.2,16.41],[1,3.15,314.79],[2,2.98,19.63]],"ltp":3.2,"tv":40061.21,"id":8858694}]}]}
{"op":"mcm","clk":"11910682841","pt":1724430052633,"mc":[{"id":"1.232184480","rc":[{"trd":[[3.15,21499.72],[3.2,13086.01]],"batb":[[0,3.15,20.41],[1,2.98,19.63],[2,1.04,1616.67]],"ltp":3.15,"tv":40682.8,"id":8858694}],"tv":40723.4}]}
{"op":"mcm","clk":"11910683279","pt":1724430055411,"mc":[{"id":"1.232184480","rc":[{"batb":[[0,3.2,310.79],[1,3.15,20.41],[2,2.98,19.63]],"ltp":3.15,"tv":40682.8,"id":8858694}]}]}
{"op":"mcm","clk":"11910684078","pt":1724430059737,"mc":[{"id":"1.232184480","rc":[{"batl":[[0,1.46,4],[1,1.47,4],[2,1.48,14.78]],"ltp":1.46,"tv":40.59,"id":247649},{"batb":[[0,3.2,314.79]],"ltp":3.15,"tv":40682.8,"id":8858694}]}]}
{"op":"mcm","clk":"11910684370","pt":1724430061320,"mc":[{"id":"1.232184480","rc":[{"batl":[[0,1.48,14.78],[1,1.49,12.56],[2,1.5,2]],"ltp":1.46,"tv":40.59,"id":247649},{"trd":[[3.2,13707.6]],"batb":[[0,3.15,16.41],[1,2.98,19.63],[2,1.04,1616.67]],"ltp":3.2,"tv":41304.39,"id":8858694}],"tv":41344.99}]}
{"op":"mcm","clk":"11910685335","pt":1724430066340,"mc":[{"id":"1.232184480","rc":[{"batb":[[0,3.2,310.79],[1,3.15,16.41],[2,2.98,19.63]],"ltp":3.2,"tv":41304.39,"id":8858694}]}]}
{"op":"mcm","clk":"11910685798","pt":1724430068948,"mc":[{"id":"1.232184480","rc":[{"trd":[[3.2,14329.19]],"batb":[[0,3.15,16.41],[1,2.98,19.63],[2,1.04,1616.67]],"ltp":3.2,"tv":41925.98,"id":8858694}],"tv":41966.58}]}
{"op":"mcm","clk":"11910686999","pt":1724430075169,"mc":[{"id":"1.232184480","rc":[{"batb":[[0,1.45,90.38]],"ltp":1.46,"tv":40.59,"id":247649},{"batb":[[0,3.2,4],[1,3.15,20.41],[2,2.98,19.63]],"batl":[[0,3.25,4],[1,3.3,1.02]],"ltp":3.2,"tv":41925.98,"id":8858694}]}]}
{"op":"mcm","clk":"11910687357","pt":1724430077281,"mc":[{"id":"1.232184480","rc":[{"batb":[[0,3.15,20.41],[1,2.98,19.63],[2,1.04,1616.67]],"ltp":3.2,"tv":41925.98,"id":8858694}]}]}
{"op":"mcm","clk":"11910689639","pt":1724430090159,"mc":[{"id":"1.232184480","rc":[{"batl":[[0,1.47,4],[1,1.48,14.78],[2,1.49,12.56]],"ltp":1.46,"tv":40.59,"id":247649},{"batb":[[0,3.2,4],[1,3.15,20.41],[2,2.98,19.63]],"ltp":3.2,"tv":41925.98,"id":8858694}]}]}
{"op":"mcm","clk":"11910690123","pt":1724430092774,"mc":[{"id":"1.232184480","rc":[{"batb":[[0,3.15,20.41],[1,2.98,19.63],[2,1.04,1616.67]],"ltp":3.2,"tv":41925.98,"id":8858694}]}]}
{"op":"mcm","clk":"11910691743","pt":1724430102293,"mc":[{"id":"1.232184480","rc":[{"batb":[[0,1.46,682.23],[1,1.45,90.38],[2,1.08,209.19]],"ltp":1.46,"tv":40.59,"id":247649}]}]}
{"op":"mcm","clk":"11910691809","pt":1724430103669,"mc":[{"id":"1.232184480","rc":[{"batl":[[0,1.48,14.78],[1,1.49,12.56],[2,1.5,2]],"ltp":1.46,"tv":40.59,"id":247649},{"batb":[[0,3.15,16.41]],"ltp":3.2,"tv":41925.98,"id":8858694}]}]}
{"op":"mcm","clk":"11910692138","pt":1724430104606,"mc":[{"id":"1.232184480","rc":[{"trd":[[3.15,21532.55]],"batb":[[0,3,9]],"ltp":3.15,"tv":41958.8,"id":8858694}],"tv":41999.4}]}
{"op":"mcm","clk":"11910692228","pt":1724430105092,"mc":[{"id":"1.232184480","rc":[{"batb":[[0,1.46,686.23]],"ltp":1.46,"tv":40.59,"id":247649},{"batl":[[0,3.2,4],[1,3.25,4],[2,3.3,1.02]],"ltp":3.15,"tv":41958.8,"id":8858694}]}]}
{"op":"mcm","clk":"11910692400","pt":1724430106002,"mc":[{"id":"1.232184480","rc":[{"trd":[[1.46,1396.48]],"batb":[[0,1.46,4]],"ltp":1.46,"tv":1405.06,"id":247649}],"tv":43363.86}]}
{"op":"mcm","clk":"11910692672","pt":1724430107584,"mc":[{"id":"1.232184480","rc":[{"batb":[[0,1.46,11.75]],"ltp":1.46,"tv":1405.06,"id":247649},{"batb":[[0,3,5]],"ltp":3.15,"tv":41958.8,"id":8858694}]}]}
{"op":"mcm","clk":"11910692730","pt":1724430107903,"mc":[{"id":"1.232184480","rc":[{"batb":[[0,2.98,19.63],[1,1.04,1616.67],[2,1.03,2337.71]],"ltp":3.15,"tv":41958.8,"id":8858694}]}]}
{"op":"mcm","clk":"11910693013","pt":1724430109517,"mc":[{"id":"1.232184480","rc":[{"batb":[[0,1.46,693.98]],"ltp":1.46,"tv":1405.06,"id":247649},{"batb":[[0,3,21.23],[1,2.98,19.63],[2,1.04,1616.67]],"ltp":3.15,"tv":41958.8,"id":8858694}]}]}
{"op":"mcm","clk":"11910693499","pt":1724430112204,"mc":[{"id":"1.232184480","rc":[{"trd":[[1.46,2760.94]],"batb":[[0,1.46,11.75]],"ltp":1.46,"tv":2769.52,"id":247649},{"batb":[[0,3,17.23]],"ltp":3.15,"tv":41958.8,"id":8858694}],"tv":44728.33}]}
{"op":"mcm","clk":"11910693824","pt":1724430114211,"mc":[{"id":"1.232184480","rc":[{"batl":[[0,1.48,22.43]],"ltp":1.46,"tv":2769.52,"id":247649},{"batb":[[0,3.05,4],[1,3,17.23],[2,2.98,19.63]],"ltp":3.15,"tv":41958.8,"id":8858694}]}]}
{"op":"mcm","clk":"11910694201","pt":1724430116427,"mc":[{"id":"1.232184480","rc":[{"batb":[[0,3,17.23],[1,2.98,19.63],[2,1.04,1616.67]],"ltp":3.15,"tv":41958.8,"id":8858694}]}]}
{"op":"mcm","clk":"11910694412","pt":1724430117823,"mc":[{"id":"1.232184480","rc":[{"batb":[[0,1.46,693.98]],"ltp":1.46,"tv":2769.52,"id":247649}]}]}
{"op":"mcm","clk":"11910694698","pt":1724430119611,"mc":[{"id":"1.232184480","rc":[{"trd":[[1.46,4101.91]],"batb":[[0,1.46,11.75]],"ltp":1.46,"tv":4110.49,"id":247649}],"tv":46069.29}]}
{"op":"mcm","clk":"11910694830","pt":1724430120302,"mc":[{"id":"1.232184480","rc":[{"batb":[[0,1.46,15.75]],"batl":[[0,1.48,26.43]],"ltp":1.46,"tv":4110.49,"id":247649},{"batb":[[0,3.1,4],[1,3.05,8],[2,3,17.23]],"ltp":3.15,"tv":41958.8,"id":8858694}]}]}
{"op":"mcm","clk":"11910694908","pt":1724430120730,"mc":[{"id":"1.232184480","rc":[{"batb":[[2,2.98,19.63]],"ltp":3.15,"tv":41958.8,"id":8858694}]}]}
{"op":"mcm","clk":"11910695181","pt":1724430122135,"mc":[{"id":"1.232184480","rc":[{"batb":[[1,3.05,4]],"ltp":3.15,"tv":41958.8,"id":8858694}]}]}
{"op":"mcm","clk":"11910695583","pt":1724430124519,"mc":[{"id":"1.232184480","rc":[{"trd":[[1.46,4109.91]],"batb":[[0,1.45,86.38],[1,1.08,209.19],[2,1.04,1616.67]],"batl":[[0,1.46,666.48],[1,1.48,26.43],[2,1.49,12.56]],"ltp":1.46,"tv":4118.49,"id":247649},{"batb":[[0,3.15,4],[1,3.1,4],[2,3.05,4]],"ltp":3.15,"tv":41958.8,"id":8858694}],"tv":46077.29}]}
{"op":"mcm","clk":"11910695952","pt":1724430126520,"mc":[{"id":"1.232184480","rc":[{"batl":[[1,1.48,18.78]],"ltp":1.46,"tv":4118.49,"id":247649},{"batb":[[0,3.1,4],[1,3.05,4],[2,2.98,19.63]],"ltp":3.15,"tv":41958.8,"id":8858694}]}]}
{"op":"mcm","clk":"11910696274","pt":1724430128142,"mc":[{"id":"1.232184480","rc":[{"trd":[[1.46,5458.62]],"batl":[[0,1.48,18.78],[1,1.49,12.56],[2,1.5,2]],"ltp":1.46,"tv":5467.2,"id":247649},{"trd":[[3.2,14336.38]],"batb":[[0,3.2,8.96],[1,3.1,4],[2,3.05,4]],"ltp":3.2,"tv":41965.99,"id":8858694}],"tv":47433.2}]}
{"op":"mcm","clk":"11910696467","pt":1724430129190,"mc":[{"id":"1.232184480","rc":[{"trd":[[1.46,5478.26]],"batb":[[0,1.46,662.59],[1,1.45,86.38],[2,1.08,209.19]],"batl":[[0,1.48,14.78]],"ltp":1.46,"tv":5486.84,"id":247649},{"trd":[[3.2,14345.34]],"batb":[[0,2.98,19.63],[1,1.04,1616.67],[2,1.03,2337.71]],"ltp":3.2,"tv":41974.95,"id":8858694}],"tv":47461.8}]}
{"op":"mcm","clk":"11910697127","pt":1724430132641,"mc":[{"id":"1.232184480","rc":[{"trd":[[1.46,6803.44]],"batb":[[0,1.45,86.38],[1,1.08,209.19],[2,1.04,1616.67]],"batl":[[0,1.46,19.64],[1,1.48,14.78],[2,1.49,12.56]],"ltp":1.46,"tv":6812.02,"id":247649}],"tv":48786.98}]}
{"op":"mcm","clk":"11910697497","pt":1724430134625,"mc":[{"id":"1.232184480","rc":[{"batl":[[0,1.46,27.39]],"ltp":1.46,"tv":6812.02,"id":247649}]}]}
{"op":"mcm","clk":"11910697674","pt":1724430135621,"mc":[{"id":"1.232184480","rc":[{"trd":[[1.46,8128.63]],"batb":[[0,1.45,90.38]],"batl":[[0,1.46,27.39]],"ltp":1.46,"tv":8137.21,"id":247649},{"batb":[[0,3,9],[1,2.98,19.63],[2,1.04,1616.67]],"batl":[[0,3.25,4]],"ltp":3.2,"tv":41974.95,"id":8858694}],"tv":50112.16}]}
{"op":"mcm","clk":"11910698101","pt":1724430137952,"mc":[{"id":"1.232184480","rc":[{"batb":[[0,3,5]],"ltp":3.2,"tv":41974.95,"id":8858694}]}]}
{"op":"mcm","clk":"11910698263","pt":1724430138749,"mc":[{"id":"1.232184480","rc":[{"batb":[[0,2.98,19.63],[1,1.04,1616.67],[2,1.03,2337.71]],"ltp":3.2,"tv":41974.95,"id":8858694}]}]}
{"op":"mcm","clk":"11910698489","pt":1724430140144,"mc":[{"id":"1.232184480","rc":[{"batb":[[0,1.46,654.84],[1,1.45,90.38],[2,1.08,209.19]],"batl":[[0,1.48,14.78],[1,1.49,12.56],[2,1.5,2]],"ltp":1.46,"tv":8137.21,"id":247649},{"batb":[[0,3,4],[1,2.98,19.63],[2,1.04,1616.67]],"ltp":3.2,"tv":41974.95,"id":8858694}]}]}
{"op":"mcm","clk":"11910698746","pt":1724430141413,"mc":[{"id":"1.232184480","rc":[{"trd":[[1.46,9438.32]],"batb":[[0,1.45,90.38],[1,1.08,209.19],[2,1.04,1616.67]],"batl":[[0,1.46,27.39],[1,1.48,14.78],[2,1.49,12.56]],"ltp":1.46,"tv":9446.89,"id":247649},{"batb":[[0,3.05,5],[1,3,4],[2,2.98,19.63]],"ltp":3.2,"tv":41974.95,"id":8858694}],"tv":51421.85}]}
{"op":"mcm","clk":"11910698965","pt":1724430142536,"mc":[{"id":"1.232184480","rc":[{"batb":[[1,2.98,19.63],[2,1.04,1616.67]],"ltp":3.2,"tv":41974.95,"id":8858694}]}]}
{"op":"mcm","clk":"11910699414","pt":1724430145041,"mc":[{"id":"1.232184480","rc":[{"trd":[[1.46,10748]],"ltp":1.46,"tv":10756.58,"id":247649},{"batb":[[0,3.1,4]],"ltp":3.2,"tv":41974.95,"id":8858694}],"tv":52731.54}]}
{"op":"mcm","clk":"11910699822","pt":1724430147351,"mc":[{"id":"1.232184480","rc":[{"batb":[[0,3,5]],"ltp":3.2,"tv":41974.95,"id":8858694}]}]}
{"op":"mcm","clk":"11910700448","pt":1724430150555,"mc":[{"id":"1.232184480","rc":[{"batb":[[0,1.46,654.84],[1,1.45,90.38],[2,1.08,209.19]],"batl":[[0,1.48,14.78],[1,1.49,12.56],[2,1.5,2]],"ltp":1.46,"tv":10756.58,"id":247649},{"batb":[[0,3.15,4],[1,3.05,4],[2,2.98,19.63]],"ltp":3.2,"tv":41974.95,"id":8858694}]}]}
{"op":"mcm","clk":"11910700748","pt":1724430152142,"mc":[{"id":"1.232184480","rc":[{"trd":[[1.46,12057.69]],"batb":[[0,1.45,90.38],[1,1.08,209.19],[2,1.04,1616.67]],"batl":[[0,1.46,27.39],[1,1.48,14.78],[2,1.49,12.56]],"ltp":1.46,"tv":12066.27,"id":247649},{"batl":[[1,3.3,1.02]],"ltp":3.2,"tv":41974.95,"id":8858694}],"tv":54041.23}]}
{"op":"mcm","clk":"11910700919","pt":1724430152938,"mc":[{"id":"1.232184480","rc":[{"batb":[[1,2.98,19.63],[2,1.04,1616.67]],"ltp":3.2,"tv":41974.95,"id":8858694}]}]}
{"op":"mcm","clk":"11910701769","pt":1724430157232,"mc":[{"id":"1.232184480","rc":[{"trd":[[1.46,13367.38]],"ltp":1.46,"tv":13375.96,"id":247649},{"batb":[[0,3.2,4],[1,3.15,4],[2,2.98,19.63]],"ltp":3.2,"tv":41974.95,"id":8858694}],"tv":55350.91}]}
{"op":"mcm","clk":"11910702229","pt":1724430159572,"mc":[{"id":"1.232184480","rc":[{"batb":[[0,3.15,4],[1,2.98,19.63],[2,1.04,1616.67]],"ltp":3.2,"tv":41974.95,"id":8858694}]}]}
{"op":"mcm","clk":"11910702662","pt":1724430161959,"mc":[{"id":"1.232184480","rc":[{"trd":[[1.46,14677.07]],"ltp":1.46,"tv":14685.64,"id":247649},{"batb":[[0,3.2,4],[1,3.15,4],[2,2.98,19.63]],"ltp":3.2,"tv":41974.95,"id":8858694}],"tv":56660.6}]}
{"op":"mcm","clk":"11910703131","pt":1724430164334,"mc":[{"id":"1.232184480","rc":[{"batb":[[0,3.15,4],[1,2.98,19.63],[2,1.04,1616.67]],"ltp":3.2,"tv":41974.95,"id":8858694}]}]}
{"op":"mcm","clk":"11910703787","pt":1724430167649,"mc":[{"id":"1.232184480","rc":[{"batb":[[0,1.45,86.38]],"batl":[[0,1.46,709.62]],"ltp":1.46,"tv":14685.64,"id":247649},{"batb":[[0,3.2,4],[1,3.15,4],[2,2.98,19.63]],"ltp":3.2,"tv":41974.95,"id":8858694}]}]}
{"op":"mcm","clk":"11910704091","pt":1724430169258,"mc":[{"id":"1.232184480","rc":[{"trd":[[1.46,15986.76]],"batl":[[0,1.46,27.39]],"ltp":1.46,"tv":15995.33,"id":247649},{"batb":[[0,3.15,4],[1,2.98,19.63],[2,1.04,1616.67]],"ltp":3.2,"tv":41974.95,"id":8858694}],"tv":57970.29}]}
{"op":"mcm","clk":"11910704474","pt":1724430171352,"mc":[{"id":"1.232184480","rc":[{"batb":[[0,1.46,654.84],[1,1.45,86.38],[2,1.08,209.19]],"batl":[[0,1.48,14.78],[1,1.49,12.56],[2,1.5,2]],"ltp":1.46,"tv":15995.33,"id":247649}]}]}
{"op":"mcm","clk":"11910704698","pt":1724430172556,"mc":[{"id":"1.232184480","rc":[{"trd":[[1.46,17296.44]],"batb":[[0,1.45,86.38],[1,1.08,209.19],[2,1.04,1616.67]],"batl":[[0,1.46,27.39],[1,1.48,14.78],[2,1.49,12.56]],"ltp":1.46,"tv":17305.02,"id":247649},{"batb":[[0,2.98,19.63],[1,1.04,1616.67],[2,1.03,2337.71]],"ltp":3.2,"tv":41974.95,"id":8858694}],"tv":59279.98}]}
{"op":"mcm","clk":"11910705424","pt":1724430176451,"mc":[{"id":"1.232184480","rc":[{"batb":[[0,1.46,654.84],[1,1.45,86.38],[2,1.08,209.19]],"batl":[[0,1.48,14.78],[1,1.49,12.56],[2,1.5,2]],"ltp":1.46,"tv":17305.02,"id":247649}]}]}
{"op":"mcm","clk":"11910705524","pt":1724430176974,"mc":[{"id":"1.232184480","rc":[{"trd":[[1.46,18606.13]],"batb":[[0,1.45,86.38],[1,1.08,209.19],[2,1.04,1616.67]],"batl":[[0,1.46,27.39],[1,1.48,14.78],[2,1.49,12.56]],"ltp":1.46,"tv":18614.71,"id":247649}],"tv":60589.67}]}
{"op":"mcm","clk":"11910706203","pt":1724430180688,"mc":[{"id":"1.232184480","rc":[{"batb":[[0,1.45,90.38]],"ltp":1.46,"tv":18614.71,"id":247649},{"batl":[[0,3.25,4]],"ltp":3.2,"tv":41974.95,"id":8858694}]}]}
{"op":"mcm","clk":"11910706331","pt":1724430181386,"mc":[{"id":"1.232184480","rc":[{"trd":[[1.46,19915.82]],"ltp":1.46,"tv":19924.4,"id":247649},{"batb":[[0,3,9],[1,2.98,19.63],[2,1.04,1616.67]],"ltp":3.2,"tv":41974.95,"id":8858694}],"tv":61899.35}]}
{"op":"mcm","clk":"11910706709","pt":1724430183457,"mc":[{"id":"1.232184480","rc":[{"batb":[[0,3,5]],"ltp":3.2,"tv":41974.95,"id":8858694}]}]}
{"op":"mcm","clk":"11910706912","pt":1724430184567,"mc":[{"id":"1.232184480","rc":[{"batb":[[0,2.98,19.63],[1,1.04,1616.67],[2,1.03,2337.71]],"ltp":3.2,"tv":41974.95,"id":8858694}]}]}
{"op":"mcm","clk":"11910706971","pt":1724430184884,"mc":[{"id":"1.232184480","rc":[{"batb":[[0,1.46,654.84],[1,1.45,90.38],[2,1.08,209.19]],"batl":[[0,1.48,14.78],[1,1.49,12.56],[2,1.5,2]],"ltp":1.46,"tv":19924.4,"id":247649}]}]}
{"op":"mcm","clk":"11910707226","pt":1724430186258,"mc":[{"id":"1.232184480","rc":[{"trd":[[1.46,21235.95],[1.47,42.46]],"batb":[[0,1.45,90.38],[1,1.08,209.19],[2,1.04,1616.67]],"ltp":1.46,"tv":21278.41,"id":247649},{"trd":[[3.15,21537.39]],"batb":[[0,3,4],[1,2.98,19.63],[2,1.04,1616.67]],"batl":[[0,3.15,11.31],[1,3.25,4]],"ltp":3.15,"tv":41979.8,"id":8858694}],"tv":63258.21}]}
{"op":"mcm","clk":"11910707631","pt":1724430188063,"mc":[{"id":"1.232184480","rc":[{"batb":[[0,2.98,19.63],[1,1.04,1616.67],[2,1.03,2337.71]],"ltp":3.15,"tv":41979.8,"id":8858694}]}]}
{"op":"mcm","clk":"11910707857","pt":1724430189162,"mc":[{"id":"1.232184480","rc":[{"batl":[[0,1.48,31.6]],"ltp":1.46,"tv":21278.41,"id":247649},{"batb":[[0,3,5],[1,2.98,19.63],[2,1.04,1616.67]],"batl":[[0,3.25,4],[1,3.25,0]],"ltp":3.15,"tv":41979.8,"id":8858694}]}]}
{"op":"mcm","clk":"11910708129","pt":1724430190684,"mc":[{"id":"1.232184480","rc":[{"batb":[[0,1.45,86.38]],"batl":[[0,1.46,682.23],[1,1.48,31.6],[2,1.49,12.56]],"ltp":1.46,"tv":21278.41,"id":247649},{"batb":[[0,3.05,4],[1,3,5],[2,2.98,19.63]],"ltp":3.15,"tv":41979.8,"id":8858694}]}]}
{"op":"mcm","clk":"11910708440","pt":1724430192372,"mc":[{"id":"1.232184480","rc":[{"batl":[[1,1.48,14.78]],"ltp":1.46,"tv":21278.41,"id":247649},{"batb":[[1,2.98,19.63],[2,1.04,1616.67]],"ltp":3.15,"tv":41979.8,"id":8858694}]}]}
{"op":"mcm","clk":"11910708602","pt":1724430193168,"mc":[{"id":"1.232184480","rc":[{"trd":[[1.46,22600.41]],"batl":[[0,1.48,14.78],[1,1.49,12.56],[2,1.5,2]],"ltp":1.46,"tv":22642.87,"id":247649},{"batb":[[0,2.98,19.63],[1,1.04,1616.67],[2,1.03,2337.71]],"ltp":3.15,"tv":41979.8,"id":8858694}],"tv":64622.68}]}
{"op":"mcm","clk":"11910708712","pt":1724430193802,"mc":[{"id":"1.232184480","rc":[{"batb":[[0,3,5.09],[1,2.98,19.63],[2,1.04,1616.67]],"ltp":3.15,"tv":41979.8,"id":8858694}]}]}
{"op":"mcm","clk":"11910709066","pt":1724430195653,"mc":[{"id":"1.232184480","rc":[{"batb":[[0,1.46,682.23],[1,1.45,86.38],[2,1.08,209.19]],"ltp":1.46,"tv":22642.87,"id":247649},{"batb":[[0,3.05,9],[1,3,5.09],[2,2.98,19.63]],"ltp":3.15,"tv":41979.8,"id":8858694}]}]}
{"op":"mcm","clk":"11910709205","pt":1724430196375,"mc":[{"id":"1.232184480","rc":[{"batb":[[1,1.45,90.38]],"ltp":1.46,"tv":22642.87,"id":247649},{"batb":[[1,2.98,19.63],[2,1.04,1616.67]],"ltp":3.15,"tv":41979.8,"id":8858694}]}]}
{"op":"mcm","clk":"11910709461","pt":1724430197893,"mc":[{"id":"1.232184480","rc":[{"trd":[[1.46,23964.88]],"batb":[[0,1.45,90.38],[1,1.08,209.19],[2,1.04,1616.67]],"ltp":1.46,"tv":24007.34,"id":247649},{"batb":[[0,3.05,5]],"ltp":3.15,"tv":41979.8,"id":8858694}],"tv":65987.14}]}
{"op":"mcm","clk":"11910709764","pt":1724430199668,"mc":[{"id":"1.232184480","rc":[{"batb":[[0,1.45,86.38]],"batl":[[0,1.46,682.23],[1,1.48,14.78],[2,1.49,12.56]],"ltp":1.46,"tv":24007.34,"id":247649},{"batb":[[0,2.98,19.63],[1,1.04,1616.67],[2,1.03,2337.71]],"ltp":3.15,"tv":41979.8,"id":8858694}]}]}
{"op":"mcm","clk":"11910710183","pt":1724430202093,"mc":[{"id":"1.232184480","rc":[{"batb":[[0,3.2,4.77],[1,2.98,19.63],[2,1.04,1616.67]],"ltp":3.15,"tv":41979.8,"id":8858694}]}]}
{"op":"mcm","clk":"11910710353","pt":1724430203092,"mc":[{"id":"1.232184480","rc":[{"trd":[[1.46,25329.34]],"batl":[[0,1.48,14.78],[1,1.49,12.56],[2,1.5,2]],"ltp":1.46,"tv":25371.8,"id":247649}],"tv":67351.6}]}
{"op":"mcm","clk":"11910710624","pt":1724430204676,"mc":[{"id":"1.232184480","rc":[{"batb":[[0,3,4]],"ltp":3.15,"tv":41979.8,"id":8858694}]}]}
{"op":"mcm","clk":"11910710690","pt":1724430205084,"mc":[{"id":"1.232184480","rc":[{"batb":[[0,1.46,682.23],[1,1.45,86.38],[2,1.08,209.19]],"batl":[[0,1.47,16.94],[1,1.48,14.78],[2,1.49,12.56]],"ltp":1.46,"tv":25371.8,"id":247649},{"batb":[[0,3,9]],"ltp":3.15,"tv":41979.8,"id":8858694}]}]}
{"op":"mcm","clk":"11910711022","pt":1724430207172,"mc":[{"id":"1.232184480","rc":[{"batl":[[0,1.48,14.78],[1,1.49,12.56],[2,1.5,2]],"ltp":1.46,"tv":25371.8,"id":247649},{"batb":[[0,3.05,5.01],[1,3,5],[2,2.98,19.63]],"ltp":3.15,"tv":41979.8,"id":8858694}]}]}
{"op":"mcm","clk":"11910711178","pt":1724430208114,"mc":[{"id":"1.232184480","rc":[{"trd":[[1.46,26693.8]],"batb":[[0,1.45,86.38],[1,1.08,209.19],[2,1.04,1616.67]],"ltp":1.46,"tv":26736.26,"id":247649},{"batb":[[1,2.98,19.63],[2,1.04,1616.67]],"ltp":3.15,"tv":41979.8,"id":8858694}],"tv":68716.07}]}
{"op":"mcm","clk":"11910711590","pt":1724430210684,"mc":[{"id":"1.232184480","rc":[{"batb":[[0,3.05,5],[1,3,4],[2,2.98,19.63]],"ltp":3.15,"tv":41979.8,"id":8858694}]}]}
{"op":"mcm","clk":"11910711647","pt":1724430210997,"mc":[{"id":"1.232184480","rc":[{"batb":[[0,1.45,90.38]],"batl":[[0,1.46,682.23],[1,1.48,14.78],[2,1.49,12.56]],"ltp":1.46,"tv":26736.26,"id":247649},{"batb":[[0,3.05,9]],"ltp":3.15,"tv":41979.8,"id":8858694}]}]}
{"op":"mcm","clk":"11910711838","pt":1724430212089,"mc":[{"id":"1.232184480","rc":[{"batl":[[0,1.46,699.29]],"ltp":1.46,"tv":26736.26,"id":247649}]}]}
{"op":"mcm","clk":"11910712096","pt":1724430213404,"mc":[{"id":"1.232184480","rc":[{"trd":[[1.46,28058.27]],"batl":[[0,1.46,17.06]],"ltp":1.46,"tv":28100.73,"id":247649},{"batb":[[1,2.98,19.63],[2,1.04,1616.67]],"ltp":3.15,"tv":41979.8,"id":8858694}],"tv":70080.53}]}
{"op":"mcm","clk":"11910712293","pt":1724430214504,"mc":[{"id":"1.232184480","rc":[{"batl":[[0,1.48,14.78],[1,1.49,12.56],[2,1.5,2]],"ltp":1.46,"tv":28100.73,"id":247649},{"batb":[[0,2.98,19.63],[1,1.04,1616.67],[2,1.03,2337.71]],"ltp":3.15,"tv":41979.8,"id":8858694}]}]}
{"op":"mcm","clk":"11910712637","pt":1724430216503,"mc":[{"id":"1.232184480","rc":[{"batb":[[0,1.46,682.23],[1,1.45,90.38],[2,1.08,209.19]],"ltp":1.46,"tv":28100.73,"id":247649},{"batb":[[0,3,9],[1,2.98,19.63],[2,1.04,1616.67]],"ltp":3.15,"tv":41979.8,"id":8858694}]}]}
{"op":"mcm","clk":"11910712862","pt":1724430217930,"mc":[{"id":"1.232184480","rc":[{"trd":[[1.46,29422.73]],"batb":[[0,1.45,90.38],[1,1.08,209.19],[2,1.04,1616.67]],"ltp":1.46,"tv":29465.19,"id":247649}],"tv":71444.99}]}
{"op":"mcm","clk":"11910713012","pt":1724430218721,"mc":[{"id":"1.232184480","rc":[{"batb":[[0,3,5]],"ltp":3.15,"tv":41979.8,"id":8858694}]}]}
{"op":"mcm","clk":"11910713306","pt":1724430220623,"mc":[{"id":"1.232184480","rc":[{"batl":[[0,1.46,682.23],[1,1.48,14.78],[2,1.49,12.56]],"ltp":1.46,"tv":29465.19,"id":247649},{"batb":[[0,2.98,19.63],[1,1.04,1616.67],[2,1.03,2337.71]],"ltp":3.15,"tv":41979.8,"id":8858694}]}]}
{"op":"mcm","clk":"11910713383","pt":1724430221100,"mc":[{"id":"1.232184480","rc":[{"batb":[[0,1.45,86.38]],"ltp":1.46,"tv":29465.19,"id":247649},{"batb":[[0,3,4],[1,2.98,19.63],[2,1.04,1616.67]],"ltp":3.15,"tv":41979.8,"id":8858694}]}]}
{"op":"mcm","clk":"11910713790","pt":1724430223412,"mc":[{"id":"1.232184480","rc":[{"trd":[[1.46,30787.19]],"batl":[[0,1.48,14.78],[1,1.49,12.56],[2,1.5,2]],"ltp":1.46,"tv":30829.65,"id":247649},{"batb":[[0,3.05,5]],"ltp":3.15,"tv":41979.8,"id":8858694}],"tv":72809.46}]}
{"op":"mcm","clk":"11910714020","pt":1724430224927,"mc":[{"id":"1.232184480","rc":[{"batb":[[0,1.46,682.23],[1,1.45,86.38],[2,1.08,209.19]],"ltp":1.46,"tv":30829.65,"id":247649}]}]}
{"op":"mcm","clk":"11910714230","pt":1724430226238,"mc":[{"id":"1.232184480","rc":[{"batb":[[0,1.46,686.23]],"ltp":1.46,"tv":30829.65,"id":247649},{"batb":[[0,3.1,4]],"batl":[[0,3.2,4],[1,3.25,4]],"ltp":3.15,"tv":41979.8,"id":8858694}]}]}
{"op":"mcm","clk":"11910714418","pt":1724430227234,"mc":[{"id":"1.232184480","rc":[{"trd":[[1.46,32151.66]],"batb":[[0,1.46,4]],"ltp":1.46,"tv":32194.12,"id":247649}],"tv":74173.92}]}
{"op":"mcm","clk":"11910714689","pt":1724430228610,"mc":[{"id":"1.232184480","rc":[{"batb":[[0,3,5]],"ltp":3.15,"tv":41979.8,"id":8858694}]}]}
{"op":"mcm","clk":"11910714851","pt":1724430229411,"mc":[{"id":"1.232184480","rc":[{"trd":[[1.46,32159.66]],"batb":[[0,1.45,86.38],[1,1.08,209.19],[2,1.04,1616.67]],"batl":[[0,1.46,678.23],[1,1.48,14.78],[2,1.49,12.56]],"ltp":1.46,"tv":32202.12,"id":247649}],"tv":74181.92}]}
{"op":"mcm","clk":"11910715317","pt":1724430232035,"mc":[{"id":"1.232184480","rc":[{"trd":[[1.46,33516.12]],"batb":[[0,1.46,4],[1,1.45,86.38],[2,1.08,209.19]],"batl":[[0,1.48,14.78],[1,1.49,12.56],[2,1.5,2]],"ltp":1.46,"tv":33558.58,"id":247649},{"batb":[[0,2.98,19.63],[1,1.04,1616.67],[2,1.03,2337.71]],"ltp":3.15,"tv":41979.8,"id":8858694}],"tv":75538.38}]}
{"op":"mcm","clk":"11910715549","pt":1724430233341,"mc":[{"id":"1.232184480","rc":[{"batb":[[0,1.46,686.23]],"ltp":1.46,"tv":33558.58,"id":247649}]}]}
{"op":"mcm","clk":"11910716517","pt":1724430239265,"mc":[{"id":"1.232184480","rc":[{"batb":[[0,1.46,682.23]],"ltp":1.46,"tv":33558.58,"id":247649}]}]}
{"op":"mcm","clk":"11910716853","pt":1724430241255,"mc":[{"id":"1.232184480","rc":[{"batb":[[0,1.46,686.23]],"ltp":1.46,"tv":33558.58,"id":247649},{"batb":[[0,3,9],[1,2.98,19.63],[2,1.04,1616.67]],"batl":[[0,3.2,4]],"ltp":3.15,"tv":41979.8,"id":8858694}]}]}
{"op":"mcm","clk":"11910717246","pt":1724430243461,"mc":[{"id":"1.232184480","rc":[{"batb":[[0,3,5]],"ltp":3.15,"tv":41979.8,"id":8858694}]}]}
{"op":"mcm","clk":"11910717432","pt":1724430244469,"mc":[{"id":"1.232184480","rc":[{"batb":[[0,2.98,19.63],[1,1.04,1616.67],[2,1.03,2337.71]],"ltp":3.15,"tv":41979.8,"id":8858694}]}]}
{"op":"mcm","clk":"11910718784","pt":1724430251679,"mc":[{"id":"1.232184480","rc":[{"trd":[[1.46,34376.47]],"batb":[[0,1.46,256.05]],"ltp":1.46,"tv":34418.93,"id":247649}],"tv":76398.73}]}
{"op":"mcm","clk":"11910718821","pt":1724430251888,"mc":[{"id":"1.232184480","rc":[{"batb":[[0,3,9],[1,2.98,19.63],[2,1.04,1616.67]],"ltp":3.15,"tv":41979.8,"id":8858694}]}]}
{"op":"mcm","clk":"11910719271","pt":1724430254250,"mc":[{"id":"1.232184480","rc":[{"batb":[[0,3,5]],"ltp":3.15,"tv":41979.8,"id":8858694}]}]}
{"op":"mcm","clk":"11910719436","pt":1724430255190,"mc":[{"id":"1.232184480","rc":[{"batb":[[0,2.98,19.63],[1,1.04,1616.67],[2,1.03,2337.71]],"ltp":3.15,"tv":41979.8,"id":8858694}]}]}
{"op":"mcm","clk":"11910720515","pt":1724430261592,"mc":[{"id":"1.232184480","rc":[{"batb":[[0,1.46,4]],"ltp":1.46,"tv":34418.93,"id":247649}]}]}
{"op":"mcm","clk":"11910720697","pt":1724430262691,"mc":[{"id":"1.232184480","rc":[{"batl":[[0,1.48,31.6]],"ltp":1.46,"tv":34418.93,"id":247649},{"batb":[[0,3,9],[1,2.98,19.63],[2,1.04,1616.67]],"ltp":3.15,"tv":41979.8,"id":8858694}]}]}
{"op":"mcm","clk":"11910720926","pt":1724430263998,"mc":[{"id":"1.232184480","rc":[{"batb":[[0,3,5]],"ltp":3.15,"tv":41979.8,"id":8858694}]}]}
{"op":"mcm","clk":"11910721109","pt":1724430264992,"mc":[{"id":"1.232184480","rc":[{"batb":[[0,2.98,19.63],[1,1.04,1616.67],[2,1.03,2337.71]],"ltp":3.15,"tv":41979.8,"id":8858694}]}]}
{"op":"mcm","clk":"11910721509","pt":1724430267396,"mc":[{"id":"1.232184480","rc":[{"batb":[[0,3.05,4],[1,3,5.09],[2,2.98,19.63]],"batl":[[1,3.25,1.02]],"ltp":3.15,"tv":41979.8,"id":8858694}]}]}
{"op":"mcm","clk":"11910721879","pt":1724430269620,"mc":[{"id":"1.232184480","rc":[{"batb":[[0,3,5],[1,2.98,19.63],[2,1.04,1616.67]],"ltp":3.15,"tv":41979.8,"id":8858694}]}]}
{"op":"mcm","clk":"11910722214","pt":1724430271388,"mc":[{"id":"1.232184480","rc":[{"batl":[[0,1.47,4],[1,1.48,35.6],[2,1.49,12.56]],"ltp":1.46,"tv":34418.93,"id":247649},{"batb":[[0,3.1,4],[1,3.05,4],[2,3,5]],"ltp":3.15,"tv":41979.8,"id":8858694}]}]}
{"op":"mcm","clk":"11910722496","pt":1724430273014,"mc":[{"id":"1.232184480","rc":[{"batb":[[0,3.15,4],[1,3.1,4],[2,3.05,4]],"ltp":3.15,"tv":41979.8,"id":8858694}]}]}
{"op":"mcm","clk":"11910722876","pt":1724430275221,"mc":[{"id":"1.232184480","rc":[{"batb":[[0,3.1,4],[1,3.05,4],[2,2.98,19.63]],"ltp":3.15,"tv":41979.8,"id":8858694}]}]}
{"op":"mcm","clk":"11910723084","pt":1724430276583,"mc":[{"id":"1.232184480","rc":[{"trd":[[1.46,34384.48]],"batb":[[0,1.45,86.38],[1,1.08,209.19],[2,1.04,1616.67]],"batl":[[0,1.46,22.53],[1,1.47,4],[2,1.48,35.6]],"ltp":1.46,"tv":34426.93,"id":247649}],"tv":76406.74}]}
{"op":"mcm","clk":"11910723250","pt":1724430277428,"mc":[{"id":"1.232184480","rc":[{"batl":[[1,1.48,14.78],[2,1.49,12.56]],"ltp":1.46,"tv":34426.93,"id":247649}]}]}
{"op":"mcm","clk":"11910723311","pt":1724430277744,"mc":[{"id":"1.232184480","rc":[{"batb":[[0,3.15,4],[1,3.1,4],[2,3.05,4]],"ltp":3.15,"tv":41979.8,"id":8858694}]}]}
{"op":"mcm","clk":"11910723733","pt":1724430280142,"mc":[{"id":"1.232184480","rc":[{"batb":[[0,3.1,4],[1,3.05,4],[2,2.98,19.63]],"ltp":3.15,"tv":41979.8,"id":8858694}]}]}
{"op":"mcm","clk":"11910724171","pt":1724430282663,"mc":[{"id":"1.232184480","rc":[{"batb":[[0,3.15,4],[1,3.1,8.92],[2,3.05,4]],"ltp":3.15,"tv":41979.8,"id":8858694}]}]}
{"op":"mcm","clk":"11910724633","pt":1724430285349,"mc":[{"id":"1.232184480","rc":[{"batl":[[0,1.46,39.59]],"ltp":1.46,"tv":34426.93,"id":247649},{"batb":[[0,3.1,8.92],[1,3.05,4],[2,2.98,19.63]],"ltp":3.15,"tv":41979.8,"id":8858694}]}]}
{"op":"mcm","clk":"11910724837","pt":1724430286558,"mc":[{"id":"1.232184480","rc":[{"batb":[[0,1.45,90.38]],"ltp":1.46,"tv":34426.93,"id":247649},{"batb":[[0,3.15,4],[1,3.1,8.92],[2,3.05,4]],"batl":[[0,3.25,4],[1,3.25,0]],"ltp":3.15,"tv":41979.8,"id":8858694}]}]}
{"op":"mcm","clk":"11910725017","pt":1724430287654,"mc":[{"id":"1.232184480","rc":[{"batb":[[0,3.2,8.77],[1,3.15,4],[2,3.1,4]],"batl":[[1,3.3,1.01]],"ltp":3.15,"tv":41979.8,"id":8858694}]}]}
{"op":"mcm","clk":"11910725392","pt":1724430289868,"mc":[{"id":"1.232184480","rc":[{"batb":[[0,3.2,4.77]],"ltp":3.15,"tv":41979.8,"id":8858694}]}]}
{"op":"mcm","clk":"11910789346","pt":1724430654522,"mc":[{"id":"1.232184480","rc":[{"trd":[[1.45,41.88]],"batb":[[0,1.45,69.44]],"ltp":1.45,"tv":34468.81,"id":247649}],"tv":76448.62}]}
{"op":"mcm","clk":"11910790114","pt":1724430658944,"mc":[{"id":"1.232184480","rc":[{"batb":[[0,1.45,90.38]],"ltp":1.45,"tv":34468.81,"id":247649}]}]}
{"op":"mcm","clk":"11910884473","pt":1724431157021,"mc":[{"id":"1.232184480","rc":[{"batl":[[2,1.5,2]],"ltp":1.45,"tv":34468.81,"id":247649}]}]}
{"op":"mcm","clk":"11910919370","pt":1724431340537,"mc":[{"id":"1.232184480","rc":[{"batb":[[1,1.08,216.77]],"ltp":1.45,"tv":34468.81,"id":247649}]}]}
{"op":"mcm","clk":"11910922601","pt":1724431357080,"mc":[{"id":"1.232184480","rc":[{"batb":[[2,1.04,1635.62]],"ltp":1.45,"tv":34468.81,"id":247649}]}]}
{"op":"mcm","clk":"11910945842","pt":1724431381720,"mc":[{"id":"1.232184480","rc":[{"batb":[[2,1.06,7.58]],"ltp":1.45,"tv":34468.81,"id":247649}]}]}
{"op":"mcm","clk":"11910949571","pt":1724431401813,"mc":[{"id":"1.232184480","rc":[{"batb":[[2,1.07,7.58]],"ltp":1.45,"tv":34468.81,"id":247649}]}]}
{"op":"mcm","clk":"11911001638","pt":1724431686433,"mc":[{"id":"1.232184480","rc":[{"batl":[[1,7,0.76]],"ltp":3.15,"tv":41979.8,"id":8858694}]}]}
{"op":"mcm","clk":"11911004884","pt":1724431703605,"mc":[{"id":"1.232184480","rc":[{"batl":[[1,9,1.52]],"ltp":3.15,"tv":41979.8,"id":8858694}]}]}
{"op":"mcm","clk":"11911007282","pt":1724431717265,"mc":[{"id":"1.232184480","rc":[{"batl":[[1,7,1.52],[2,9,0.76]],"ltp":3.15,"tv":41979.8,"id":8858694}]}]}
{"op":"mcm","clk":"11911010108","pt":1724431732696,"mc":[{"id":"1.232184480","rc":[{"batl":[[2,11,1.52]],"ltp":3.15,"tv":41979.8,"id":8858694}]}]}
{"op":"mcm","clk":"11911079696","pt":1724432148500,"mc":[{"id":"1.232184480","rc":[{"batl":[[1,1.47,2],[2,1.48,14.78]],"ltp":1.45,"tv":34468.81,"id":247649}]}]}
{"op":"mcm","clk":"11911245794","pt":1724433075330,"mc":[{"id":"1.232184480","rc":[{"trd":[[1.46,34393.76],[1.47,42.47]],"batb":[[1,1.08,216.77],[2,1.07,7.58]],"batl":[[0,1.46,37.56],[2,1.48,14.78]],"ltp":1.46,"tv":34478.1,"id":247649},{"trd":[[3.05,5451.09],[3.1,646.9],[3.15,21540.65],[3.2,14347.51]],"ltp":3.15,"tv":41986.15,"id":8858694}],"tv":76464.26}]}
{"op":"mcm","clk":"11911260031","pt":1724433142643,"mc":[{"id":"1.232184480","rc":[{"trd":[[3.2,14348.33]],"batb":[[0,3.2,4.36]],"ltp":3.2,"tv":41986.97,"id":8858694}],"tv":76465.07}]}
{"op":"mcm","clk":"11911309317","pt":1724433367452,"mc":[{"id":"1.232184480","rc":[{"trd":[[3.2,14356.71]],"batb":[[0,3.15,4.17],[1,3.1,4],[2,3.05,4]],"ltp":3.2,"tv":41995.35,"id":8858694}],"tv":76473.46}]}
{"op":"mcm","clk":"11911309430","pt":1724433367984,"mc":[{"id":"1.232184480","rc":[{"batb":[[0,3.2,4],[1,3.15,4],[2,3.1,4]],"ltp":3.2,"tv":41995.35,"id":8858694}]}]}
{"op":"mcm","clk":"11911309926","pt":1724433370161,"mc":[{"id":"1.232184480","rc":[{"batb":[[0,3.15,4],[1,3.1,4],[2,3.05,4]],"ltp":3.2,"tv":41995.35,"id":8858694}]}]}
{"op":"mcm","clk":"11911317297","pt":1724433403045,"mc":[{"id":"1.232184480","rc":[{"batb":[[0,3.2,4],[1,3.15,4],[2,3.1,4]],"ltp":3.2,"tv":41995.35,"id":8858694}]}]}
{"op":"mcm","clk":"11911317792","pt":1724433405319,"mc":[{"id":"1.232184480","rc":[{"batb":[[0,3.15,4],[1,3.1,4],[2,3.05,4]],"ltp":3.2,"tv":41995.35,"id":8858694}]}]}
{"op":"mcm","clk":"11911321341","pt":1724433422193,"mc":[{"id":"1.232184480","rc":[{"batb":[[0,3.2,4],[1,3.15,4],[2,3.1,4]],"ltp":3.2,"tv":41995.35,"id":8858694}]}]}
{"op":"mcm","clk":"11911321904","pt":1724433424673,"mc":[{"id":"1.232184480","rc":[{"batb":[[0,3.15,4],[1,3.1,4],[2,3.05,4]],"ltp":3.2,"tv":41995.35,"id":8858694}]}]}
{"op":"mcm","clk":"11911327145","pt":1724433449605,"mc":[{"id":"1.232184480","rc":[{"batb":[[0,3.2,4],[1,3.15,4],[2,3.1,4]],"ltp":3.2,"tv":41995.35,"id":8858694}]}]}
{"op":"mcm","clk":"11911327600","pt":1724433451809,"mc":[{"id":"1.232184480","rc":[{"batb":[[0,3.15,4],[1,3.1,4],[2,3.05,4]],"ltp":3.2,"tv":41995.35,"id":8858694}]}]}
{"op":"mcm","clk":"11911329016","pt":1724433458394,"mc":[{"id":"1.232184480","rc":[{"batb":[[0,3.2,4],[1,3.15,4],[2,3.1,4]],"ltp":3.2,"tv":41995.35,"id":8858694}]}]}
{"op":"mcm","clk":"11911329538","pt":1724433460735,"mc":[{"id":"1.232184480","rc":[{"batb":[[0,3.15,4],[1,3.1,4],[2,3.05,4]],"ltp":3.2,"tv":41995.35,"id":8858694}]}]}
{"op":"mcm","clk":"11911330792","pt":1724433466522,"mc":[{"id":"1.232184480","rc":[{"batb":[[0,3.2,4],[1,3.15,4],[2,3.1,4]],"ltp":3.2,"tv":41995.35,"id":8858694}]}]}
{"op":"mcm","clk":"11911331337","pt":1724433469019,"mc":[{"id":"1.232184480","rc":[{"batb":[[0,3.15,4],[1,3.1,4],[2,3.05,4]],"ltp":3.2,"tv":41995.35,"id":8858694}]}]}
{"op":"mcm","clk":"11911332974","pt":1724433477228,"mc":[{"id":"1.232184480","rc":[{"batb":[[0,3.2,4],[1,3.15,4],[2,3.1,4]],"ltp":3.2,"tv":41995.35,"id":8858694}]}]}
{"op":"mcm","clk":"11911333483","pt":1724433479628,"mc":[{"id":"1.232184480","rc":[{"batb":[[0,3.15,4],[1,3.1,4],[2,3.05,4]],"ltp":3.2,"tv":41995.35,"id":8858694}]}]}
{"op":"mcm","clk":"11911359857","pt":1724433599691,"mc":[{"id":"1.232184480","rc":[{"batb":[[0,3.2,4],[1,3.15,4],[2,3.1,4]],"ltp":3.2,"tv":41995.35,"id":8858694}]}]}
{"op":"mcm","clk":"11911360455","pt":1724433602085,"mc":[{"id":"1.232184480","rc":[{"batb":[[0,3.15,4],[1,3.1,4],[2,3.05,4]],"ltp":3.2,"tv":41995.35,"id":8858694}]}]}
{"op":"mcm","clk":"11911374295","pt":1724433665233,"mc":[{"id":"1.232184480","rc":[{"batb":[[0,3.2,4],[1,3.15,4],[2,3.1,4]],"ltp":3.2,"tv":41995.35,"id":8858694}]}]}
{"op":"mcm","clk":"11911374765","pt":1724433667647,"mc":[{"id":"1.232184480","rc":[{"batb":[[0,3.15,4],[1,3.1,4],[2,3.05,4]],"ltp":3.2,"tv":41995.35,"id":8858694}]}]}
{"op":"mcm","clk":"11911376385","pt":1724433675677,"mc":[{"id":"1.232184480","rc":[{"batb":[[0,3.2,4],[1,3.15,4],[2,3.1,4]],"ltp":3.2,"tv":41995.35,"id":8858694}]}]}
{"op":"mcm","clk":"11911376874","pt":1724433678169,"mc":[{"id":"1.232184480","rc":[{"batb":[[0,3.15,4],[1,3.1,4],[2,3.05,4]],"ltp":3.2,"tv":41995.35,"id":8858694}]}]}
{"op":"mcm","clk":"11911378979","pt":1724433689304,"mc":[{"id":"1.232184480","rc":[{"batb":[[0,3.2,4],[1,3.15,4],[2,3.1,4]],"ltp":3.2,"tv":41995.35,"id":8858694}]}]}
{"op":"mcm","clk":"11911379412","pt":1724433691672,"mc":[{"id":"1.232184480","rc":[{"batb":[[0,3.15,4],[1,3.1,4],[2,3.05,4]],"ltp":3.2,"tv":41995.35,"id":8858694}]}]}
{"op":"mcm","clk":"11911380860","pt":1724433699430,"mc":[{"id":"1.232184480","rc":[{"batb":[[0,3.2,4],[1,3.15,4],[2,3.1,4]],"ltp":3.2,"tv":41995.35,"id":8858694}]}]}
{"op":"mcm","clk":"11911381340","pt":1724433701863,"mc":[{"id":"1.232184480","rc":[{"batb":[[0,3.15,4],[1,3.1,4],[2,3.05,4]],"ltp":3.2,"tv":41995.35,"id":8858694}]}]}
{"op":"mcm","clk":"11911382241","pt":1724433706427,"mc":[{"id":"1.232184480","rc":[{"batb":[[0,3.2,4],[1,3.15,4],[2,3.1,4]],"ltp":3.2,"tv":41995.35,"id":8858694}]}]}
{"op":"mcm","clk":"11911382712","pt":1724433708852,"mc":[{"id":"1.232184480","rc":[{"batb":[[0,3.15,4],[1,3.1,4],[2,3.05,4]],"ltp":3.2,"tv":41995.35,"id":8858694}]}]}
{"op":"mcm","clk":"11911383146","pt":1724433711033,"mc":[{"id":"1.232184480","rc":[{"batb":[[0,3.2,4],[1,3.15,4],[2,3.1,4]],"ltp":3.2,"tv":41995.35,"id":8858694}]}]}
{"op":"mcm","clk":"11911383585","pt":1724433713353,"mc":[{"id":"1.232184480","rc":[{"batb":[[0,3.15,4],[1,3.1,4],[2,3.05,4]],"ltp":3.2,"tv":41995.35,"id":8858694}]}]}
{"op":"mcm","clk":"11911384437","pt":1724433717753,"mc":[{"id":"1.232184480","rc":[{"batb":[[0,3.2,4],[1,3.15,4],[2,3.1,4]],"ltp":3.2,"tv":41995.35,"id":8858694}]}]}
{"op":"mcm","clk":"11911384911","pt":1724433720022,"mc":[{"id":"1.232184480","rc":[{"batb":[[0,3.15,4],[1,3.1,4],[2,3.05,4]],"ltp":3.2,"tv":41995.35,"id":8858694}]}]}
{"op":"mcm","clk":"11911386122","pt":1724433726032,"mc":[{"id":"1.232184480","rc":[{"batb":[[0,3.2,4],[1,3.15,4],[2,3.1,4]],"ltp":3.2,"tv":41995.35,"id":8858694}]}]}
{"op":"mcm","clk":"11911386637","pt":1724433728471,"mc":[{"id":"1.232184480","rc":[{"batb":[[0,3.15,4],[1,3.1,4],[2,3.05,4]],"ltp":3.2,"tv":41995.35,"id":8858694}]}]}
{"op":"mcm","clk":"11911387912","pt":1724433734683,"mc":[{"id":"1.232184480","rc":[{"batb":[[0,3.2,4],[1,3.15,4],[2,3.1,4]],"ltp":3.2,"tv":41995.35,"id":8858694}]}]}
{"op":"mcm","clk":"11911388411","pt":1724433736970,"mc":[{"id":"1.232184480","rc":[{"batb":[[0,3.15,4],[1,3.1,4],[2,3.05,4]],"ltp":3.2,"tv":41995.35,"id":8858694}]}]}
{"op":"mcm","clk":"11911389626","pt":1724433742559,"mc":[{"id":"1.232184480","rc":[{"batb":[[0,3.2,4],[1,3.15,4],[2,3.1,4]],"ltp":3.2,"tv":41995.35,"id":8858694}]}]}
{"op":"mcm","clk":"11911390073","pt":1724433744994,"mc":[{"id":"1.232184480","rc":[{"batb":[[0,3.15,4],[1,3.1,4],[2,3.05,4]],"ltp":3.2,"tv":41995.35,"id":8858694}]}]}
{"op":"mcm","clk":"11911393619","pt":1724433763948,"mc":[{"id":"1.232184480","rc":[{"batb":[[0,3.2,4],[1,3.15,4],[2,3.1,4]],"ltp":3.2,"tv":41995.35,"id":8858694}]}]}
{"op":"mcm","clk":"11911394139","pt":1724433766370,"mc":[{"id":"1.232184480","rc":[{"batb":[[0,3.15,4],[1,3.1,4],[2,3.05,4]],"ltp":3.2,"tv":41995.35,"id":8858694}]}]}
{"op":"mcm","clk":"11911394830","pt":1724433770075,"mc":[{"id":"1.232184480","rc":[{"batb":[[0,3.2,4],[1,3.15,4],[2,3.1,4]],"ltp":3.2,"tv":41995.35,"id":8858694}]}]}
{"op":"mcm","clk":"11911395272","pt":1724433772661,"mc":[{"id":"1.232184480","rc":[{"batb":[[0,3.15,4],[1,3.1,4],[2,3.05,4]],"ltp":3.2,"tv":41995.35,"id":8858694}]}]}
{"op":"mcm","clk":"11911395742","pt":1724433775068,"mc":[{"id":"1.232184480","rc":[{"batb":[[0,3.2,4],[1,3.15,4],[2,3.1,4]],"ltp":3.2,"tv":41995.35,"id":8858694}]}]}
{"op":"mcm","clk":"11911396244","pt":1724433777683,"mc":[{"id":"1.232184480","rc":[{"batb":[[0,3.15,4],[1,3.1,4],[2,3.05,4]],"ltp":3.2,"tv":41995.35,"id":8858694}]}]}
{"op":"mcm","clk":"11911397492","pt":1724433784663,"mc":[{"id":"1.232184480","rc":[{"batb":[[0,3.2,4],[1,3.15,4],[2,3.1,4]],"ltp":3.2,"tv":41995.35,"id":8858694}]}]}
{"op":"mcm","clk":"11911397764","pt":1724433786199,"mc":[{"id":"1.232184480","rc":[{"batb":[[0,3.15,4],[1,3.1,4],[2,3.05,4]],"ltp":3.2,"tv":41995.35,"id":8858694}]}]}
{"op":"mcm","clk":"11911400534","pt":1724433799792,"mc":[{"id":"1.232184480","rc":[{"batb":[[0,3.2,4],[1,3.15,4],[2,3.1,4]],"ltp":3.2,"tv":41995.35,"id":8858694}]}]}
{"op":"mcm","clk":"11911401019","pt":1724433802425,"mc":[{"id":"1.232184480","rc":[{"batb":[[0,3.15,4],[1,3.1,4],[2,3.05,4]],"ltp":3.2,"tv":41995.35,"id":8858694}]}]}
{"op":"mcm","clk":"11911401840","pt":1724433806434,"mc":[{"id":"1.232184480","rc":[{"batb":[[0,3.2,4],[1,3.15,4],[2,3.1,4]],"ltp":3.2,"tv":41995.35,"id":8858694}]}]}
{"op":"mcm","clk":"11911402312","pt":1724433808902,"mc":[{"id":"1.232184480","rc":[{"batb":[[0,3.15,4],[1,3.1,4],[2,3.05,4]],"ltp":3.2,"tv":41995.35,"id":8858694}]}]}
{"op":"mcm","clk":"11911404899","pt":1724433822029,"mc":[{"id":"1.232184480","rc":[{"batb":[[0,3.2,4],[1,3.15,4],[2,3.1,4]],"ltp":3.2,"tv":41995.35,"id":8858694}]}]}
{"op":"mcm","clk":"11911405358","pt":1724433824358,"mc":[{"id":"1.232184480","rc":[{"batb":[[0,3.15,4],[1,3.1,4],[2,3.05,4]],"ltp":3.2,"tv":41995.35,"id":8858694}]}]}
{"op":"mcm","clk":"11911405889","pt":1724433826923,"mc":[{"id":"1.232184480","rc":[{"batb":[[0,3.2,4],[1,3.15,4],[2,3.1,4]],"ltp":3.2,"tv":41995.35,"id":8858694}]}]}
{"op":"mcm","clk":"11911406348","pt":1724433829266,"mc":[{"id":"1.232184480","rc":[{"batb":[[0,3.15,4],[1,3.1,4],[2,3.05,4]],"ltp":3.2,"tv":41995.35,"id":8858694}]}]}
{"op":"mcm","clk":"11911406877","pt":1724433832036,"mc":[{"id":"1.232184480","rc":[{"batb":[[0,3.2,4],[1,3.15,4],[2,3.1,4]],"ltp":3.2,"tv":41995.35,"id":8858694}]}]}
{"op":"mcm","clk":"11911407364","pt":1724433834268,"mc":[{"id":"1.232184480","rc":[{"batb":[[0,3.15,4],[1,3.1,4],[2,3.05,4]],"ltp":3.2,"tv":41995.35,"id":8858694}]}]}
{"op":"mcm","clk":"11911408876","pt":1724433841690,"mc":[{"id":"1.232184480","rc":[{"batb":[[0,3.2,4],[1,3.15,4],[2,3.1,4]],"ltp":3.2,"tv":41995.35,"id":8858694}]}]}
{"op":"mcm","clk":"11911409448","pt":1724433844084,"mc":[{"id":"1.232184480","rc":[{"batb":[[0,3.15,4],[1,3.1,4],[2,3.05,4]],"ltp":3.2,"tv":41995.35,"id":8858694}]}]}
{"op":"mcm","clk":"11911410894","pt":1724433851074,"mc":[{"id":"1.232184480","rc":[{"batb":[[0,3.2,4],[1,3.15,4],[2,3.1,4]],"ltp":3.2,"tv":41995.35,"id":8858694}]}]}
{"op":"mcm","clk":"11911411466","pt":1724433853995,"mc":[{"id":"1.232184480","rc":[{"batb":[[0,3.15,4],[1,3.1,4],[2,3.05,4]],"ltp":3.2,"tv":41995.35,"id":8858694}]}]}
{"op":"mcm","clk":"11911412203","pt":1724433857959,"mc":[{"id":"1.232184480","rc":[{"batb":[[0,3.2,4],[1,3.15,4],[2,3.1,4]],"ltp":3.2,"tv":41995.35,"id":8858694}]}]}
{"op":"mcm","clk":"11911412657","pt":1724433860476,"mc":[{"id":"1.232184480","rc":[{"batb":[[0,3.15,4],[1,3.1,4],[2,3.05,4]],"ltp":3.2,"tv":41995.35,"id":8858694}]}]}
{"op":"mcm","clk":"11911415028","pt":1724433873099,"mc":[{"id":"1.232184480","rc":[{"batb":[[0,3.2,4],[1,3.15,4],[2,3.1,4]],"ltp":3.2,"tv":41995.35,"id":8858694}]}]}
{"op":"mcm","clk":"11911415527","pt":1724433875393,"mc":[{"id":"1.232184480","rc":[{"batb":[[0,3.15,4],[1,3.1,4],[2,3.05,4]],"ltp":3.2,"tv":41995.35,"id":8858694}]}]}
{"op":"mcm","clk":"11911416300","pt":1724433879385,"mc":[{"id":"1.232184480","rc":[{"batb":[[0,3.2,4],[1,3.15,4],[2,3.1,4]],"ltp":3.2,"tv":41995.35,"id":8858694}]}]}
{"op":"mcm","clk":"11911416884","pt":1724433882396,"mc":[{"id":"1.232184480","rc":[{"batb":[[0,3.15,4],[1,3.1,4],[2,3.05,4]],"ltp":3.2,"tv":41995.35,"id":8858694}]}]}
{"op":"mcm","clk":"11911417522","pt":1724433885518,"mc":[{"id":"1.232184480","rc":[{"trd":[[1.45,41.9]],"batb":[[0,1.45,90.37]],"ltp":1.45,"tv":34478.12,"id":247649},{"batb":[[0,3.2,4],[1,3.15,4],[2,3.1,4]],"ltp":3.2,"tv":41995.35,"id":8858694}],"tv":76473.48}]}
{"op":"mcm","clk":"11911417902","pt":1724433887390,"mc":[{"id":"1.232184480","rc":[{"batb":[[0,3.15,4],[1,3.1,4],[2,3.05,4]],"ltp":3.2,"tv":41995.35,"id":8858694}]}]}
{"op":"mcm","clk":"11911418739","pt":1724433891817,"mc":[{"id":"1.232184480","rc":[{"batb":[[0,3.2,4],[1,3.15,4],[2,3.1,4]],"ltp":3.2,"tv":41995.35,"id":8858694}]}]}
{"op":"mcm","clk":"11911419173","pt":1724433894187,"mc":[{"id":"1.232184480","rc":[{"batb":[[0,3.15,4],[1,3.1,4],[2,3.05,4]],"ltp":3.2,"tv":41995.35,"id":8858694}]}]}
{"op":"mcm","clk":"11911419931","pt":1724433898206,"mc":[{"id":"1.232184480","rc":[{"batb":[[0,3.2,4],[1,3.15,4],[2,3.1,4]],"ltp":3.2,"tv":41995.35,"id":8858694}]}]}
{"op":"mcm","clk":"11911420444","pt":1724433900835,"mc":[{"id":"1.232184480","rc":[{"batb":[[0,3.15,4],[1,3.1,4],[2,3.05,4]],"ltp":3.2,"tv":41995.35,"id":8858694}]}]}
{"op":"mcm","clk":"11911422800","pt":1724433912128,"mc":[{"id":"1.232184480","rc":[{"batb":[[0,3.2,4],[1,3.15,4],[2,3.1,4]],"ltp":3.2,"tv":41995.35,"id":8858694}]}]}
{"op":"mcm","clk":"11911423313","pt":1724433914646,"mc":[{"id":"1.232184480","rc":[{"batb":[[0,3.15,4],[1,3.1,4],[2,3.05,4]],"ltp":3.2,"tv":41995.35,"id":8858694}]}]}
{"op":"mcm","clk":"11911424182","pt":1724433918837,"mc":[{"id":"1.232184480","rc":[{"batb":[[0,3.2,4],[1,3.15,4],[2,3.1,4]],"ltp":3.2,"tv":41995.35,"id":8858694}]}]}
{"op":"mcm","clk":"11911424744","pt":1724433921546,"mc":[{"id":"1.232184480","rc":[{"batb":[[0,3.15,4],[1,3.1,4],[2,3.05,4]],"ltp":3.2,"tv":41995.35,"id":8858694}]}]}
{"op":"mcm","clk":"11911425844","pt":1724433927208,"mc":[{"id":"1.232184480","rc":[{"batb":[[0,3.2,4],[1,3.15,4],[2,3.1,4]],"ltp":3.2,"tv":41995.35,"id":8858694}]}]}
{"op":"mcm","clk":"11911426309","pt":1724433929736,"mc":[{"id":"1.232184480","rc":[{"batb":[[0,3.15,4],[1,3.1,4],[2,3.05,4]],"ltp":3.2,"tv":41995.35,"id":8858694}]}]}
{"op":"mcm","clk":"11911427901","pt":1724433938158,"mc":[{"id":"1.232184480","rc":[{"batb":[[0,3.2,4],[1,3.15,4],[2,3.1,4]],"ltp":3.2,"tv":41995.35,"id":8858694}]}]}
{"op":"mcm","clk":"11911428306","pt":1724433940382,"mc":[{"id":"1.232184480","rc":[{"batb":[[0,3.15,4],[1,3.1,4],[2,3.05,4]],"ltp":3.2,"tv":41995.35,"id":8858694}]}]}
{"op":"mcm","clk":"11911430257","pt":1724433949974,"mc":[{"id":"1.232184480","rc":[{"batb":[[0,3.2,4],[1,3.15,4],[2,3.1,4]],"ltp":3.2,"tv":41995.35,"id":8858694}]}]}
{"op":"mcm","clk":"11911430739","pt":1724433952454,"mc":[{"id":"1.232184480","rc":[{"batb":[[0,3.15,4],[1,3.1,4],[2,3.05,4]],"ltp":3.2,"tv":41995.35,"id":8858694}]}]}
{"op":"mcm","clk":"11911432274","pt":1724433960100,"mc":[{"id":"1.232184480","rc":[{"batb":[[0,3.2,4],[1,3.15,4],[2,3.1,4]],"ltp":3.2,"tv":41995.35,"id":8858694}]}]}
{"op":"mcm","clk":"11911432827","pt":1724433962775,"mc":[{"id":"1.232184480","rc":[{"batb":[[0,3.15,4],[1,3.1,4],[2,3.05,4]],"ltp":3.2,"tv":41995.35,"id":8858694}]}]}
{"op":"mcm","clk":"11911434012","pt":1724433968717,"mc":[{"id":"1.232184480","rc":[{"batb":[[0,3.2,4],[1,3.15,4],[2,3.1,4]],"ltp":3.2,"tv":41995.35,"id":8858694}]}]}
{"op":"mcm","clk":"11911434503","pt":1724433971188,"mc":[{"id":"1.232184480","rc":[{"batb":[[0,3.15,4],[1,3.1,4],[2,3.05,4]],"ltp":3.2,"tv":41995.35,"id":8858694}]}]}
{"op":"mcm","clk":"11911435035","pt":1724433973703,"mc":[{"id":"1.232184480","rc":[{"batb":[[0,3.2,4],[1,3.15,4],[2,3.1,4]],"ltp":3.2,"tv":41995.35,"id":8858694}]}]}
{"op":"mcm","clk":"11911435543","pt":1724433976071,"mc":[{"id":"1.232184480","rc":[{"batb":[[0,3.15,4],[1,3.1,4],[2,3.05,4]],"ltp":3.2,"tv":41995.35,"id":8858694}]}]}
{"op":"mcm","clk":"11911437082","pt":1724433983498,"mc":[{"id":"1.232184480","rc":[{"batb":[[0,3.2,4],[1,3.15,4],[2,3.1,4]],"ltp":3.2,"tv":41995.35,"id":8858694}]}]}
{"op":"mcm","clk":"11911437565","pt":1724433986135,"mc":[{"id":"1.232184480","rc":[{"batb":[[0,3.15,4],[1,3.1,4],[2,3.05,4]],"ltp":3.2,"tv":41995.35,"id":8858694}]}]}
{"op":"mcm","clk":"11911438110","pt":1724433989254,"mc":[{"id":"1.232184480","rc":[{"batb":[[0,3.2,4],[1,3.15,4],[2,3.1,4]],"ltp":3.2,"tv":41995.35,"id":8858694}]}]}
{"op":"mcm","clk":"11911438567","pt":1724433991100,"mc":[{"id":"1.232184480","rc":[{"batb":[[0,3.15,4],[1,3.1,4],[2,3.05,4]],"ltp":3.2,"tv":41995.35,"id":8858694}]}]}
{"op":"mcm","clk":"11911439380","pt":1724433995594,"mc":[{"id":"1.232184480","rc":[{"batb":[[0,3.2,4],[1,3.15,4],[2,3.1,4]],"ltp":3.2,"tv":41995.35,"id":8858694}]}]}
{"op":"mcm","clk":"11911439889","pt":1724433998342,"mc":[{"id":"1.232184480","rc":[{"batb":[[0,3.15,4],[1,3.1,4],[2,3.05,4]],"ltp":3.2,"tv":41995.35,"id":8858694}]}]}
{"op":"mcm","clk":"11911442036","pt":1724434010546,"mc":[{"id":"1.232184480","rc":[{"batb":[[0,3.2,4],[1,3.15,4],[2,3.1,4]],"ltp":3.2,"tv":41995.35,"id":8858694}]}]}
{"op":"mcm","clk":"11911442465","pt":1724434012910,"mc":[{"id":"1.232184480","rc":[{"batb":[[0,3.15,4],[1,3.1,4],[2,3.05,4]],"ltp":3.2,"tv":41995.35,"id":8858694}]}]}
{"op":"mcm","clk":"11911452925","pt":1724434067728,"mc":[{"id":"1.232184480","rc":[{"batb":[[0,3.2,4],[1,3.15,4],[2,3.1,4]],"ltp":3.2,"tv":41995.35,"id":8858694}]}]}
{"op":"mcm","clk":"11911453383","pt":1724434070097,"mc":[{"id":"1.232184480","rc":[{"batb":[[0,3.15,4],[1,3.1,4],[2,3.05,4]],"ltp":3.2,"tv":41995.35,"id":8858694}]}]}
{"op":"mcm","clk":"11911454321","pt":1724434074911,"mc":[{"id":"1.232184480","rc":[{"batb":[[0,3.2,4],[1,3.15,4],[2,3.1,4]],"ltp":3.2,"tv":41995.35,"id":8858694}]}]}
{"op":"mcm","clk":"11911454727","pt":1724434077097,"mc":[{"id":"1.232184480","rc":[{"batb":[[0,3.15,4],[1,3.1,4],[2,3.05,4]],"ltp":3.2,"tv":41995.35,"id":8858694}]}]}
{"op":"mcm","clk":"11911456517","pt":1724434086229,"mc":[{"id":"1.232184480","rc":[{"batb":[[0,3.2,4],[1,3.15,4],[2,3.1,4]],"ltp":3.2,"tv":41995.35,"id":8858694}]}]}
{"op":"mcm","clk":"11911456977","pt":1724434088688,"mc":[{"id":"1.232184480","rc":[{"batb":[[0,3.15,4],[1,3.1,4],[2,3.05,4]],"ltp":3.2,"tv":41995.35,"id":8858694}]}]}
{"op":"mcm","clk":"11911458152","pt":1724434093889,"mc":[{"id":"1.232184480","rc":[{"batb":[[0,3.2,4],[1,3.15,4],[2,3.1,4]],"ltp":3.2,"tv":41995.35,"id":8858694}]}]}
{"op":"mcm","clk":"11911458677","pt":1724434096579,"mc":[{"id":"1.232184480","rc":[{"batb":[[0,3.15,4],[1,3.1,4],[2,3.05,4]],"ltp":3.2,"tv":41995.35,"id":8858694}]}]}
{"op":"mcm","clk":"11911459171","pt":1724434099003,"mc":[{"id":"1.232184480","rc":[{"batb":[[0,3.2,4],[1,3.15,4],[2,3.1,4]],"ltp":3.2,"tv":41995.35,"id":8858694}]}]}
{"op":"mcm","clk":"11911459651","pt":1724434101610,"mc":[{"id":"1.232184480","rc":[{"batb":[[0,3.15,4],[1,3.1,4],[2,3.05,4]],"ltp":3.2,"tv":41995.35,"id":8858694}]}]}
{"op":"mcm","clk":"11911461419","pt":1724434111469,"mc":[{"id":"1.232184480","rc":[{"batb":[[0,3.2,4],[1,3.15,4],[2,3.1,4]],"ltp":3.2,"tv":41995.35,"id":8858694}]}]}
{"op":"mcm","clk":"11911461892","pt":1724434114060,"mc":[{"id":"1.232184480","rc":[{"batb":[[0,3.15,4],[1,3.1,4],[2,3.05,4]],"ltp":3.2,"tv":41995.35,"id":8858694}]}]}
{"op":"mcm","clk":"11911463841","pt":1724434124468,"mc":[{"id":"1.232184480","rc":[{"batb":[[0,3.2,4],[1,3.15,4],[2,3.1,4]],"ltp":3.2,"tv":41995.35,"id":8858694}]}]}
{"op":"mcm","clk":"11911464273","pt":1724434126995,"mc":[{"id":"1.232184480","rc":[{"batb":[[0,3.15,4],[1,3.1,4],[2,3.05,4]],"ltp":3.2,"tv":41995.35,"id":8858694}]}]}
{"op":"mcm","clk":"11911464866","pt":1724434130106,"mc":[{"id":"1.232184480","rc":[{"batb":[[0,3.2,4],[1,3.15,4],[2,3.1,4]],"ltp":3.2,"tv":41995.35,"id":8858694}]}]}
{"op":"mcm","clk":"11911465371","pt":1724434132808,"mc":[{"id":"1.232184480","rc":[{"batb":[[0,3.15,4],[1,3.1,4],[2,3.05,4]],"ltp":3.2,"tv":41995.35,"id":8858694}]}]}
{"op":"mcm","clk":"11911467443","pt":1724434143698,"mc":[{"id":"1.232184480","rc":[{"batb":[[0,3.2,4],[1,3.15,4],[2,3.1,4]],"ltp":3.2,"tv":41995.35,"id":8858694}]}]}
{"op":"mcm","clk":"11911467917","pt":1724434146220,"mc":[{"id":"1.232184480","rc":[{"batb":[[0,3.15,4],[1,3.1,4],[2,3.05,4]],"ltp":3.2,"tv":41995.35,"id":8858694}]}]}
{"op":"mcm","clk":"11911469699","pt":1724434155304,"mc":[{"id":"1.232184480","rc":[{"batb":[[0,3.2,4],[1,3.15,4],[2,3.1,4]],"ltp":3.2,"tv":41995.35,"id":8858694}]}]}
{"op":"mcm","clk":"11911470290","pt":1724434158129,"mc":[{"id":"1.232184480","rc":[{"batb":[[0,3.15,4],[1,3.1,4],[2,3.05,4]],"ltp":3.2,"tv":41995.35,"id":8858694}]}]}
{"op":"mcm","clk":"11911473958","pt":1724434176538,"mc":[{"id":"1.232184480","rc":[{"batb":[[0,3.2,4],[1,3.15,4],[2,3.1,4]],"ltp":3.2,"tv":41995.35,"id":8858694}]}]}
{"op":"mcm","clk":"11911474473","pt":1724434179375,"mc":[{"id":"1.232184480","rc":[{"batb":[[0,3.15,4],[1,3.1,4],[2,3.05,4]],"ltp":3.2,"tv":41995.35,"id":8858694}]}]}
{"op":"mcm","clk":"11911476616","pt":1724434190760,"mc":[{"id":"1.232184480","rc":[{"batb":[[0,3.2,4],[1,3.15,4],[2,3.1,4]],"ltp":3.2,"tv":41995.35,"id":8858694}]}]}
{"op":"mcm","clk":"11911477037","pt":1724434193280,"mc":[{"id":"1.232184480","rc":[{"batb":[[0,3.15,4],[1,3.1,4],[2,3.05,4]],"ltp":3.2,"tv":41995.35,"id":8858694}]}]}
{"op":"mcm","clk":"11911478227","pt":1724434199377,"mc":[{"id":"1.232184480","rc":[{"batb":[[0,3.2,4],[1,3.15,4],[2,3.1,4]],"ltp":3.2,"tv":41995.35,"id":8858694}]}]}
{"op":"mcm","clk":"11911478781","pt":1724434201583,"mc":[{"id":"1.232184480","rc":[{"batb":[[0,3.15,4],[1,3.1,4],[2,3.05,4]],"ltp":3.2,"tv":41995.35,"id":8858694}]}]}
{"op":"mcm","clk":"11911480234","pt":1724434208207,"mc":[{"id":"1.232184480","rc":[{"batb":[[0,3.2,4],[1,3.15,4],[2,3.1,4]],"ltp":3.2,"tv":41995.35,"id":8858694}]}]}
{"op":"mcm","clk":"11911480785","pt":1724434210800,"mc":[{"id":"1.232184480","rc":[{"batb":[[0,3.15,4],[1,3.1,4],[2,3.05,4]],"ltp":3.2,"tv":41995.35,"id":8858694}]}]}
{"op":"mcm","clk":"11911481693","pt":1724434215189,"mc":[{"id":"1.232184480","rc":[{"batb":[[0,3.2,4],[1,3.15,4],[2,3.1,4]],"ltp":3.2,"tv":41995.35,"id":8858694}]}]}
{"op":"mcm","clk":"11911482224","pt":1724434217721,"mc":[{"id":"1.232184480","rc":[{"batb":[[0,3.15,4],[1,3.1,4],[2,3.05,4]],"ltp":3.2,"tv":41995.35,"id":8858694}]}]}
{"op":"mcm","clk":"11911482918","pt":1724434221189,"mc":[{"id":"1.232184480","rc":[{"batb":[[0,3.2,4],[1,3.15,4],[2,3.1,4]],"ltp":3.2,"tv":41995.35,"id":8858694}]}]}
{"op":"mcm","clk":"11911483388","pt":1724434223721,"mc":[{"id":"1.232184480","rc":[{"batb":[[0,3.15,4],[1,3.1,4],[2,3.05,4]],"ltp":3.2,"tv":41995.35,"id":8858694}]}]}
{"op":"mcm","clk":"11911483900","pt":1724434226197,"mc":[{"id":"1.232184480","rc":[{"batb":[[0,3.2,4],[1,3.15,4],[2,3.1,4]],"ltp":3.2,"tv":41995.35,"id":8858694}]}]}
{"op":"mcm","clk":"11911484331","pt":1724434228627,"mc":[{"id":"1.232184480","rc":[{"batb":[[0,3.15,4],[1,3.1,4],[2,3.05,4]],"ltp":3.2,"tv":41995.35,"id":8858694}]}]}
{"op":"mcm","clk":"11911485015","pt":1724434232224,"mc":[{"id":"1.232184480","rc":[{"batb":[[0,3.2,4],[1,3.15,4],[2,3.1,4]],"ltp":3.2,"tv":41995.35,"id":8858694}]}]}
{"op":"mcm","clk":"11911485559","pt":1724434234900,"mc":[{"id":"1.232184480","rc":[{"batb":[[0,3.15,4],[1,3.1,4],[2,3.05,4]],"ltp":3.2,"tv":41995.35,"id":8858694}]}]}
{"op":"mcm","clk":"11911486424","pt":1724434238959,"mc":[{"id":"1.232184480","rc":[{"batb":[[0,3.2,4],[1,3.15,4],[2,3.1,4]],"ltp":3.2,"tv":41995.35,"id":8858694}]}]}
{"op":"mcm","clk":"11911486996","pt":1724434241517,"mc":[{"id":"1.232184480","rc":[{"batb":[[0,3.15,4],[1,3.1,4],[2,3.05,4]],"ltp":3.2,"tv":41995.35,"id":8858694}]}]}
{"op":"mcm","clk":"11911489515","pt":1724434253651,"mc":[{"id":"1.232184480","rc":[{"batb":[[0,3.2,4],[1,3.15,4],[2,3.1,4]],"ltp":3.2,"tv":41995.35,"id":8858694}]}]}
{"op":"mcm","clk":"11911490069","pt":1724434256241,"mc":[{"id":"1.232184480","rc":[{"batb":[[0,3.15,4],[1,3.1,4],[2,3.05,4]],"ltp":3.2,"tv":41995.35,"id":8858694}]}]}
{"op":"mcm","clk":"11911490995","pt":1724434260745,"mc":[{"id":"1.232184480","rc":[{"batb":[[0,3.2,4],[1,3.15,4],[2,3.1,4]],"ltp":3.2,"tv":41995.35,"id":8858694}]}]}
{"op":"mcm","clk":"11911491630","pt":1724434263565,"mc":[{"id":"1.232184480","rc":[{"batb":[[0,3.15,4],[1,3.1,4],[2,3.05,4]],"ltp":3.2,"tv":41995.35,"id":8858694}]}]}
{"op":"mcm","clk":"11911492512","pt":1724434267877,"mc":[{"id":"1.232184480","rc":[{"batb":[[0,3.2,4],[1,3.15,4],[2,3.1,4]],"ltp":3.2,"tv":41995.35,"id":8858694}]}]}
{"op":"mcm","clk":"11911493090","pt":1724434270479,"mc":[{"id":"1.232184480","rc":[{"batb":[[0,3.15,4],[1,3.1,4],[2,3.05,4]],"ltp":3.2,"tv":41995.35,"id":8858694}]}]}
{"op":"mcm","clk":"11911493904","pt":1724434274206,"mc":[{"id":"1.232184480","rc":[{"batb":[[0,3.2,4],[1,3.15,4],[2,3.1,4]],"ltp":3.2,"tv":41995.35,"id":8858694}]}]}
{"op":"mcm","clk":"11911494546","pt":1724434277011,"mc":[{"id":"1.232184480","rc":[{"batb":[[0,3.15,4],[1,3.1,4],[2,3.05,4]],"ltp":3.2,"tv":41995.35,"id":8858694}]}]}
{"op":"mcm","clk":"11911496790","pt":1724434287108,"mc":[{"id":"1.232184480","rc":[{"batb":[[0,3.2,4],[1,3.15,4],[2,3.1,4]],"ltp":3.2,"tv":41995.35,"id":8858694}]}]}
{"op":"mcm","clk":"11911497425","pt":1724434289917,"mc":[{"id":"1.232184480","rc":[{"batb":[[0,3.15,4],[1,3.1,4],[2,3.05,4]],"ltp":3.2,"tv":41995.35,"id":8858694}]}]}
{"op":"mcm","clk":"11911499196","pt":1724434298217,"mc":[{"id":"1.232184480","rc":[{"batb":[[0,3.2,4],[1,3.15,4],[2,3.1,4]],"ltp":3.2,"tv":41995.35,"id":8858694}]}]}
{"op":"mcm","clk":"11911499770","pt":1724434300826,"mc":[{"id":"1.232184480","rc":[{"batb":[[0,3.15,4],[1,3.1,4],[2,3.05,4]],"ltp":3.2,"tv":41995.35,"id":8858694}]}]}
{"op":"mcm","clk":"11911500536","pt":1724434304448,"mc":[{"id":"1.232184480","rc":[{"batb":[[0,3.2,4],[1,3.15,4],[2,3.1,4]],"ltp":3.2,"tv":41995.35,"id":8858694}]}]}
{"op":"mcm","clk":"11911501096","pt":1724434306936,"mc":[{"id":"1.232184480","rc":[{"batb":[[0,3.15,4],[1,3.1,4],[2,3.05,4]],"ltp":3.2,"tv":41995.35,"id":8858694}]}]}
{"op":"mcm","clk":"11911501641","pt":1724434309454,"mc":[{"id":"1.232184480","rc":[{"batb":[[0,3.2,4],[1,3.15,4],[2,3.1,4]],"ltp":3.2,"tv":41995.35,"id":8858694}]}]}
{"op":"mcm","clk":"11911502259","pt":1724434312272,"mc":[{"id":"1.232184480","rc":[{"batb":[[0,3.15,4],[1,3.1,4],[2,3.05,4]],"ltp":3.2,"tv":41995.35,"id":8858694}]}]}
{"op":"mcm","clk":"11911503361","pt":1724434317424,"mc":[{"id":"1.232184480","rc":[{"batb":[[0,3.2,4],[1,3.15,4],[2,3.1,4]],"ltp":3.2,"tv":41995.35,"id":8858694}]}]}
{"op":"mcm","clk":"11911503911","pt":1724434319940,"mc":[{"id":"1.232184480","rc":[{"batb":[[0,3.15,4],[1,3.1,4],[2,3.05,4]],"ltp":3.2,"tv":41995.35,"id":8858694}]}]}
{"op":"mcm","clk":"11911504647","pt":1724434323355,"mc":[{"id":"1.232184480","rc":[{"batb":[[0,3.2,4],[1,3.15,4],[2,3.1,4]],"ltp":3.2,"tv":41995.35,"id":8858694}]}]}
{"op":"mcm","clk":"11911505191","pt":1724434326065,"mc":[{"id":"1.232184480","rc":[{"batb":[[0,3.15,4],[1,3.1,4],[2,3.05,4]],"ltp":3.2,"tv":41995.35,"id":8858694}]}]}
{"op":"mcm","clk":"11911506376","pt":1724434331948,"mc":[{"id":"1.232184480","rc":[{"batb":[[0,3.2,4],[1,3.15,4],[2,3.1,4]],"ltp":3.2,"tv":41995.35,"id":8858694}]}]}
{"op":"mcm","clk":"11911506857","pt":1724434334163,"mc":[{"id":"1.232184480","rc":[{"batb":[[0,3.15,4],[1,3.1,4],[2,3.05,4]],"ltp":3.2,"tv":41995.35,"id":8858694}]}]}
{"op":"mcm","clk":"11911507713","pt":1724434338374,"mc":[{"id":"1.232184480","rc":[{"batb":[[0,3.2,4],[1,3.15,4],[2,3.1,4]],"ltp":3.2,"tv":41995.35,"id":8858694}]}]}
{"op":"mcm","clk":"11911508293","pt":1724434340973,"mc":[{"id":"1.232184480","rc":[{"batb":[[0,3.15,4],[1,3.1,4],[2,3.05,4]],"ltp":3.2,"tv":41995.35,"id":8858694}]}]}
{"op":"mcm","clk":"11911509146","pt":1724434344996,"mc":[{"id":"1.232184480","rc":[{"batb":[[0,3.2,4],[1,3.15,4],[2,3.1,4]],"ltp":3.2,"tv":41995.35,"id":8858694}]}]}
{"op":"mcm","clk":"11911509636","pt":1724434347364,"mc":[{"id":"1.232184480","rc":[{"batb":[[0,3.15,4],[1,3.1,4],[2,3.05,4]],"ltp":3.2,"tv":41995.35,"id":8858694}]}]}
{"op":"mcm","clk":"11911511234","pt":1724434355692,"mc":[{"id":"1.232184480","rc":[{"batb":[[0,3.2,4],[1,3.15,4],[2,3.1,4]],"ltp":3.2,"tv":41995.35,"id":8858694}]}]}
{"op":"mcm","clk":"11911511741","pt":1724434358302,"mc":[{"id":"1.232184480","rc":[{"batb":[[0,3.15,4],[1,3.1,4],[2,3.05,4]],"ltp":3.2,"tv":41995.35,"id":8858694}]}]}
{"op":"mcm","clk":"11911512518","pt":1724434361883,"mc":[{"id":"1.232184480","rc":[{"batb":[[0,3.2,4],[1,3.15,4],[2,3.1,4]],"ltp":3.2,"tv":41995.35,"id":8858694}]}]}
{"op":"mcm","clk":"11911512979","pt":1724434364521,"mc":[{"id":"1.232184480","rc":[{"batb":[[0,3.15,4],[1,3.1,4],[2,3.05,4]],"ltp":3.2,"tv":41995.35,"id":8858694}]}]}
{"op":"mcm","clk":"11911513562","pt":1724434367534,"mc":[{"id":"1.232184480","rc":[{"batb":[[0,3.2,4],[1,3.15,4],[2,3.1,4]],"ltp":3.2,"tv":41995.35,"id":8858694}]}]}
{"op":"mcm","clk":"11911514042","pt":1724434370009,"mc":[{"id":"1.232184480","rc":[{"batb":[[0,3.15,4],[1,3.1,4],[2,3.05,4]],"ltp":3.2,"tv":41995.35,"id":8858694}]}]}
{"op":"mcm","clk":"11911515044","pt":1724434374758,"mc":[{"id":"1.232184480","rc":[{"batb":[[0,3.2,4],[1,3.15,4],[2,3.1,4]],"ltp":3.2,"tv":41995.35,"id":8858694}]}]}
{"op":"mcm","clk":"11911515582","pt":1724434377246,"mc":[{"id":"1.232184480","rc":[{"batb":[[0,3.15,4],[1,3.1,4],[2,3.05,4]],"ltp":3.2,"tv":41995.35,"id":8858694}]}]}
{"op":"mcm","clk":"11911516044","pt":1724434379620,"mc":[{"id":"1.232184480","rc":[{"batb":[[0,3.2,4],[1,3.15,4],[2,3.1,4]],"ltp":3.2,"tv":41995.35,"id":8858694}]}]}
{"op":"mcm","clk":"11911516495","pt":1724434381857,"mc":[{"id":"1.232184480","rc":[{"batb":[[0,3.15,4],[1,3.1,4],[2,3.05,4]],"ltp":3.2,"tv":41995.35,"id":8858694}]}]}
{"op":"mcm","clk":"11911518443","pt":1724434390788,"mc":[{"id":"1.232184480","rc":[{"batb":[[0,3.2,4],[1,3.15,4],[2,3.1,4]],"ltp":3.2,"tv":41995.35,"id":8858694}]}]}
{"op":"mcm","clk":"11911519084","pt":1724434393627,"mc":[{"id":"1.232184480","rc":[{"batb":[[0,3.15,4],[1,3.1,4],[2,3.05,4]],"ltp":3.2,"tv":41995.35,"id":8858694}]}]}
{"op":"mcm","clk":"11911520501","pt":1724434400003,"mc":[{"id":"1.232184480","rc":[{"batb":[[0,3.2,4],[1,3.15,4],[2,3.1,4]],"ltp":3.2,"tv":41995.35,"id":8858694}]}]}
{"op":"mcm","clk":"11911521139","pt":1724434402812,"mc":[{"id":"1.232184480","rc":[{"batb":[[0,3.15,4],[1,3.1,4],[2,3.05,4]],"ltp":3.2,"tv":41995.35,"id":8858694}]}]}
{"op":"mcm","clk":"11911522906","pt":1724434410656,"mc":[{"id":"1.232184480","rc":[{"batb":[[0,3.2,4],[1,3.15,4],[2,3.1,4]],"ltp":3.2,"tv":41995.35,"id":8858694}]}]}
{"op":"mcm","clk":"11911523483","pt":1724434413111,"mc":[{"id":"1.232184480","rc":[{"batb":[[0,3.15,4],[1,3.1,4],[2,3.05,4]],"ltp":3.2,"tv":41995.35,"id":8858694}]}]}
{"op":"mcm","clk":"11911524274","pt":1724434416842,"mc":[{"id":"1.232184480","rc":[{"batb":[[0,3.2,4],[1,3.15,4],[2,3.1,4]],"ltp":3.2,"tv":41995.35,"id":8858694}]}]}
{"op":"mcm","clk":"11911524773","pt":1724434419418,"mc":[{"id":"1.232184480","rc":[{"batb":[[0,3.15,4],[1,3.1,4],[2,3.05,4]],"ltp":3.2,"tv":41995.35,"id":8858694}]}]}
{"op":"mcm","clk":"11911525342","pt":1724434422129,"mc":[{"id":"1.232184480","rc":[{"batb":[[0,3.2,4],[1,3.15,4],[2,3.1,4]],"ltp":3.2,"tv":41995.35,"id":8858694}]}]}
{"op":"mcm","clk":"11911525847","pt":1724434424571,"mc":[{"id":"1.232184480","rc":[{"batb":[[0,3.15,4],[1,3.1,4],[2,3.05,4]],"ltp":3.2,"tv":41995.35,"id":8858694}]}]}
{"op":"mcm","clk":"11911526519","pt":1724434427437,"mc":[{"id":"1.232184480","rc":[{"batb":[[0,3.2,4],[1,3.15,4],[2,3.1,4]],"ltp":3.2,"tv":41995.35,"id":8858694}]}]}
{"op":"mcm","clk":"11911526999","pt":1724434429730,"mc":[{"id":"1.232184480","rc":[{"batb":[[0,3.15,4],[1,3.1,4],[2,3.05,4]],"ltp":3.2,"tv":41995.35,"id":8858694}]}]}
{"op":"mcm","clk":"11911527655","pt":1724434432642,"mc":[{"id":"1.232184480","rc":[{"batb":[[0,3.2,4],[1,3.15,4],[2,3.1,4]],"ltp":3.2,"tv":41995.35,"id":8858694}]}]}
{"op":"mcm","clk":"11911528189","pt":1724434435156,"mc":[{"id":"1.232184480","rc":[{"batb":[[0,3.15,4],[1,3.1,4],[2,3.05,4]],"ltp":3.2,"tv":41995.35,"id":8858694}]}]}
{"op":"mcm","clk":"11911531209","pt":1724434448617,"mc":[{"id":"1.232184480","rc":[{"batb":[[0,3.2,4],[1,3.15,4],[2,3.1,4]],"ltp":3.2,"tv":41995.35,"id":8858694}]}]}
{"op":"mcm","clk":"11911531710","pt":1724434450813,"mc":[{"id":"1.232184480","rc":[{"batb":[[0,3.15,4],[1,3.1,4],[2,3.05,4]],"ltp":3.2,"tv":41995.35,"id":8858694}]}]}
{"op":"mcm","clk":"11911538910","pt":1724434482185,"mc":[{"id":"1.232184480","rc":[{"batb":[[0,3.2,4],[1,3.15,4],[2,3.1,4]],"ltp":3.2,"tv":41995.35,"id":8858694}]}]}
{"op":"mcm","clk":"11911539466","pt":1724434484776,"mc":[{"id":"1.232184480","rc":[{"batb":[[0,3.15,4],[1,3.1,4],[2,3.05,4]],"ltp":3.2,"tv":41995.35,"id":8858694}]}]}
{"op":"mcm","clk":"11911543183","pt":1724434502004,"mc":[{"id":"1.232184480","rc":[{"batb":[[0,3.2,4],[1,3.15,4],[2,3.1,4]],"ltp":3.2,"tv":41995.35,"id":8858694}]}]}
{"op":"mcm","clk":"11911543805","pt":1724434504627,"mc":[{"id":"1.232184480","rc":[{"batb":[[0,3.15,4],[1,3.1,4],[2,3.05,4]],"ltp":3.2,"tv":41995.35,"id":8858694}]}]}
{"op":"mcm","clk":"11911547395","pt":1724434520330,"mc":[{"id":"1.232184480","rc":[{"batb":[[0,3.2,4],[1,3.15,4],[2,3.1,4]],"ltp":3.2,"tv":41995.35,"id":8858694}]}]}
{"op":"mcm","clk":"11911548065","pt":1724434523111,"mc":[{"id":"1.232184480","rc":[{"batb":[[0,3.15,4],[1,3.1,4],[2,3.05,4]],"ltp":3.2,"tv":41995.35,"id":8858694}]}]}
{"op":"mcm","clk":"11911548748","pt":1724434525822,"mc":[{"id":"1.232184480","rc":[{"batb":[[0,3.2,4],[1,3.15,4],[2,3.1,4]],"ltp":3.2,"tv":41995.35,"id":8858694}]}]}
{"op":"mcm","clk":"11911549356","pt":1724434528364,"mc":[{"id":"1.232184480","rc":[{"batb":[[0,3.15,4],[1,3.1,4],[2,3.05,4]],"ltp":3.2,"tv":41995.35,"id":8858694}]}]}
{"op":"mcm","clk":"11911550317","pt":1724434532660,"mc":[{"id":"1.232184480","rc":[{"batb":[[0,3.2,4],[1,3.15,4],[2,3.1,4]],"ltp":3.2,"tv":41995.35,"id":8858694}]}]}
{"op":"mcm","clk":"11911550936","pt":1724434535357,"mc":[{"id":"1.232184480","rc":[{"batb":[[0,3.15,4],[1,3.1,4],[2,3.05,4]],"ltp":3.2,"tv":41995.35,"id":8858694}]}]}
{"op":"mcm","clk":"11911552823","pt":1724434543698,"mc":[{"id":"1.232184480","rc":[{"batb":[[0,3.2,4],[1,3.15,4],[2,3.1,4]],"ltp":3.2,"tv":41995.35,"id":8858694}]}]}
{"op":"mcm","clk":"11911553455","pt":1724434546514,"mc":[{"id":"1.232184480","rc":[{"batb":[[0,3.15,4],[1,3.1,4],[2,3.05,4]],"ltp":3.2,"tv":41995.35,"id":8858694}]}]}
{"op":"mcm","clk":"11911553985","pt":1724434548710,"mc":[{"id":"1.232184480","rc":[{"batb":[[0,3.2,4],[1,3.15,4],[2,3.1,4]],"ltp":3.2,"tv":41995.35,"id":8858694}]}]}
{"op":"mcm","clk":"11911554540","pt":1724434551329,"mc":[{"id":"1.232184480","rc":[{"batb":[[0,3.15,4],[1,3.1,4],[2,3.05,4]],"ltp":3.2,"tv":41995.35,"id":8858694}]}]}
{"op":"mcm","clk":"11911555374","pt":1724434555135,"mc":[{"id":"1.232184480","rc":[{"batb":[[0,3.2,4],[1,3.15,4],[2,3.1,4]],"ltp":3.2,"tv":41995.35,"id":8858694}]}]}
{"op":"mcm","clk":"11911555901","pt":1724434557733,"mc":[{"id":"1.232184480","rc":[{"batb":[[0,3.15,4],[1,3.1,4],[2,3.05,4]],"ltp":3.2,"tv":41995.35,"id":8858694}]}]}
{"op":"mcm","clk":"11911556341","pt":1724434559939,"mc":[{"id":"1.232184480","rc":[{"batb":[[0,3.2,4],[1,3.15,4],[2,3.1,4]],"ltp":3.2,"tv":41995.35,"id":8858694}]}]}
{"op":"mcm","clk":"11911556932","pt":1724434562664,"mc":[{"id":"1.232184480","rc":[{"batb":[[0,3.15,4],[1,3.1,4],[2,3.05,4]],"ltp":3.2,"tv":41995.35,"id":8858694}]}]}
{"op":"mcm","clk":"11911557563","pt":1724434565834,"mc":[{"id":"1.232184480","rc":[{"batb":[[0,3.2,4],[1,3.15,4],[2,3.1,4]],"ltp":3.2,"tv":41995.35,"id":8858694}]}]}
{"op":"mcm","clk":"11911558323","pt":1724434569646,"mc":[{"id":"1.232184480","rc":[{"batb":[[0,3.15,4],[1,3.1,4],[2,3.05,4]],"ltp":3.2,"tv":41995.35,"id":8858694}]}]}
{"op":"mcm","clk":"11911559735","pt":1724434576228,"mc":[{"id":"1.232184480","rc":[{"batb":[[0,3.2,4],[1,3.15,4],[2,3.1,4]],"ltp":3.2,"tv":41995.35,"id":8858694}]}]}
{"op":"mcm","clk":"11911560278","pt":1724434578858,"mc":[{"id":"1.232184480","rc":[{"batb":[[0,3.15,4],[1,3.1,4],[2,3.05,4]],"ltp":3.2,"tv":41995.35,"id":8858694}]}]}
{"op":"mcm","clk":"11911562719","pt":1724434590272,"mc":[{"id":"1.232184480","rc":[{"batb":[[0,3.2,4],[1,3.15,4],[2,3.1,4]],"ltp":3.2,"tv":41995.35,"id":8858694}]}]}
{"op":"mcm","clk":"11911563319","pt":1724434593094,"mc":[{"id":"1.232184480","rc":[{"batb":[[0,3.15,4],[1,3.1,4],[2,3.05,4]],"ltp":3.2,"tv":41995.35,"id":8858694}]}]}
{"op":"mcm","clk":"11911563834","pt":1724434595270,"mc":[{"id":"1.232184480","rc":[{"batb":[[0,3.2,4],[1,3.15,4],[2,3.1,4]],"ltp":3.2,"tv":41995.35,"id":8858694}]}]}
{"op":"mcm","clk":"11911564514","pt":1724434598069,"mc":[{"id":"1.232184480","rc":[{"batb":[[0,3.15,4],[1,3.1,4],[2,3.05,4]],"ltp":3.2,"tv":41995.35,"id":8858694}]}]}
{"op":"mcm","clk":"11911566279","pt":1724434605403,"mc":[{"id":"1.232184480","rc":[{"batb":[[0,3.2,4],[1,3.15,4],[2,3.1,4]],"ltp":3.2,"tv":41995.35,"id":8858694}]}]}
{"op":"mcm","clk":"11911566788","pt":1724434607728,"mc":[{"id":"1.232184480","rc":[{"batb":[[0,3.15,4],[1,3.1,4],[2,3.05,4]],"ltp":3.2,"tv":41995.35,"id":8858694}]}]}
{"op":"mcm","clk":"11911569458","pt":1724434619336,"mc":[{"id":"1.232184480","rc":[{"batb":[[0,3.2,4],[1,3.15,4],[2,3.1,4]],"ltp":3.2,"tv":41995.35,"id":8858694}]}]}
{"op":"mcm","clk":"11911570040","pt":1724434621709,"mc":[{"id":"1.232184480","rc":[{"batb":[[0,3.15,4],[1,3.1,4],[2,3.05,4]],"ltp":3.2,"tv":41995.35,"id":8858694}]}]}
{"op":"mcm","clk":"11911572191","pt":1724434630641,"mc":[{"id":"1.232184480","rc":[{"batb":[[0,3.2,4],[1,3.15,4],[2,3.1,4]],"ltp":3.2,"tv":41995.35,"id":8858694}]}]}
{"op":"mcm","clk":"11911572798","pt":1724434633020,"mc":[{"id":"1.232184480","rc":[{"batb":[[0,3.15,4],[1,3.1,4],[2,3.05,4]],"ltp":3.2,"tv":41995.35,"id":8858694}]}]}
{"op":"mcm","clk":"11911573723","pt":1724434636857,"mc":[{"id":"1.232184480","rc":[{"batb":[[0,3.2,4],[1,3.15,4],[2,3.1,4]],"ltp":3.2,"tv":41995.35,"id":8858694}]}]}
{"op":"mcm","clk":"11911574331","pt":1724434639450,"mc":[{"id":"1.232184480","rc":[{"batb":[[0,3.15,4],[1,3.1,4],[2,3.05,4]],"ltp":3.2,"tv":41995.35,"id":8858694}]}]}
{"op":"mcm","clk":"11911575173","pt":1724434642980,"mc":[{"id":"1.232184480","rc":[{"batb":[[0,3.2,4],[1,3.15,4],[2,3.1,4]],"ltp":3.2,"tv":41995.35,"id":8858694}]}]}
{"op":"mcm","clk":"11911575776","pt":1724434645481,"mc":[{"id":"1.232184480","rc":[{"batb":[[0,3.15,4],[1,3.1,4],[2,3.05,4]],"ltp":3.2,"tv":41995.35,"id":8858694}]}]}
{"op":"mcm","clk":"11911576390","pt":1724434648027,"mc":[{"id":"1.232184480","rc":[{"batb":[[0,3.2,4],[1,3.15,4],[2,3.1,4]],"ltp":3.2,"tv":41995.35,"id":8858694}]}]}
{"op":"mcm","clk":"11911577019","pt":1724434650585,"mc":[{"id":"1.232184480","rc":[{"batb":[[0,3.15,4],[1,3.1,4],[2,3.05,4]],"ltp":3.2,"tv":41995.35,"id":8858694}]}]}
{"op":"mcm","clk":"11911577579","pt":1724434652896,"mc":[{"id":"1.232184480","rc":[{"batb":[[0,3.2,4],[1,3.15,4],[2,3.1,4]],"ltp":3.2,"tv":41995.35,"id":8858694}]}]}
{"op":"mcm","clk":"11911578200","pt":1724434655610,"mc":[{"id":"1.232184480","rc":[{"batb":[[0,3.15,4],[1,3.1,4],[2,3.05,4]],"ltp":3.2,"tv":41995.35,"id":8858694}]}]}
{"op":"mcm","clk":"11911579620","pt":1724434661618,"mc":[{"id":"1.232184480","rc":[{"batb":[[0,3.2,4],[1,3.15,4],[2,3.1,4]],"ltp":3.2,"tv":41995.35,"id":8858694}]}]}
{"op":"mcm","clk":"11911580171","pt":1724434664018,"mc":[{"id":"1.232184480","rc":[{"batb":[[0,3.15,4],[1,3.1,4],[2,3.05,4]],"ltp":3.2,"tv":41995.35,"id":8858694}]}]}
{"op":"mcm","clk":"11911580917","pt":1724434667329,"mc":[{"id":"1.232184480","rc":[{"batb":[[0,3.2,4],[1,3.15,4],[2,3.1,4]],"ltp":3.2,"tv":41995.35,"id":8858694}]}]}
{"op":"mcm","clk":"11911581437","pt":1724434669729,"mc":[{"id":"1.232184480","rc":[{"batb":[[0,3.15,4],[1,3.1,4],[2,3.05,4]],"ltp":3.2,"tv":41995.35,"id":8858694}]}]}
{"op":"mcm","clk":"11911581976","pt":1724434672118,"mc":[{"id":"1.232184480","rc":[{"batb":[[0,3.2,4],[1,3.15,4],[2,3.1,4]],"ltp":3.2,"tv":41995.35,"id":8858694}]}]}
{"op":"mcm","clk":"11911582493","pt":1724434674539,"mc":[{"id":"1.232184480","rc":[{"batb":[[0,3.15,4],[1,3.1,4],[2,3.05,4]],"ltp":3.2,"tv":41995.35,"id":8858694}]}]}
{"op":"mcm","clk":"11911583219","pt":1724434677535,"mc":[{"id":"1.232184480","rc":[{"batb":[[0,3.2,4],[1,3.15,4],[2,3.1,4]],"ltp":3.2,"tv":41995.35,"id":8858694}]}]}
{"op":"mcm","clk":"11911583760","pt":1724434679912,"mc":[{"id":"1.232184480","rc":[{"batb":[[0,3.15,4],[1,3.1,4],[2,3.05,4]],"ltp":3.2,"tv":41995.35,"id":8858694}]}]}
{"op":"mcm","clk":"11911585195","pt":1724434686022,"mc":[{"id":"1.232184480","rc":[{"batb":[[0,3.2,4],[1,3.15,4],[2,3.1,4]],"ltp":3.2,"tv":41995.35,"id":8858694}]}]}
{"op":"mcm","clk":"11911585782","pt":1724434688523,"mc":[{"id":"1.232184480","rc":[{"batb":[[0,3.15,4],[1,3.1,4],[2,3.05,4]],"ltp":3.2,"tv":41995.35,"id":8858694}]}]}
{"op":"mcm","clk":"11911587247","pt":1724434694621,"mc":[{"id":"1.232184480","rc":[{"batb":[[0,3.2,4],[1,3.15,4],[2,3.1,4]],"ltp":3.2,"tv":41995.35,"id":8858694}]}]}
{"op":"mcm","clk":"11911587852","pt":1724434697153,"mc":[{"id":"1.232184480","rc":[{"batb":[[0,3.15,4],[1,3.1,4],[2,3.05,4]],"ltp":3.2,"tv":41995.35,"id":8858694}]}]}
{"op":"mcm","clk":"11911589190","pt":1724434702769,"mc":[{"id":"1.232184480","rc":[{"batb":[[0,3.2,4],[1,3.15,4],[2,3.1,4]],"ltp":3.2,"tv":41995.35,"id":8858694}]}]}
{"op":"mcm","clk":"11911589757","pt":1724434705336,"mc":[{"id":"1.232184480","rc":[{"batb":[[0,3.15,4],[1,3.1,4],[2,3.05,4]],"ltp":3.2,"tv":41995.35,"id":8858694}]}]}
{"op":"mcm","clk":"11911591565","pt":1724434713285,"mc":[{"id":"1.232184480","rc":[{"batb":[[0,3.2,4],[1,3.15,4],[2,3.1,4]],"ltp":3.2,"tv":41995.35,"id":8858694}]}]}
{"op":"mcm","clk":"11911592104","pt":1724434715535,"mc":[{"id":"1.232184480","rc":[{"batb":[[0,3.15,4],[1,3.1,4],[2,3.05,4]],"ltp":3.2,"tv":41995.35,"id":8858694}]}]}
{"op":"mcm","clk":"11911593724","pt":1724434722378,"mc":[{"id":"1.232184480","rc":[{"batb":[[0,3.2,4],[1,3.15,4],[2,3.1,4]],"ltp":3.2,"tv":41995.35,"id":8858694}]}]}
{"op":"mcm","clk":"11911594310","pt":1724434724824,"mc":[{"id":"1.232184480","rc":[{"batb":[[0,3.15,4],[1,3.1,4],[2,3.05,4]],"ltp":3.2,"tv":41995.35,"id":8858694}]}]}
{"op":"mcm","clk":"11911595031","pt":1724434727700,"mc":[{"id":"1.232184480","rc":[{"batb":[[0,3.2,4],[1,3.15,4],[2,3.1,4]],"ltp":3.2,"tv":41995.35,"id":8858694}]}]}
{"op":"mcm","clk":"11911595579","pt":1724434730012,"mc":[{"id":"1.232184480","rc":[{"batb":[[0,3.15,4],[1,3.1,4],[2,3.05,4]],"ltp":3.2,"tv":41995.35,"id":8858694}]}]}
{"op":"mcm","clk":"11911597147","pt":1724434737023,"mc":[{"id":"1.232184480","rc":[{"batb":[[0,3.2,4],[1,3.15,4],[2,3.1,4]],"ltp":3.2,"tv":41995.35,"id":8858694}]}]}
{"op":"mcm","clk":"11911597724","pt":1724434739520,"mc":[{"id":"1.232184480","rc":[{"batb":[[0,3.15,4],[1,3.1,4],[2,3.05,4]],"ltp":3.2,"tv":41995.35,"id":8858694}]}]}
{"op":"mcm","clk":"11911598382","pt":1724434742311,"mc":[{"id":"1.232184480","rc":[{"batb":[[0,3.2,4],[1,3.15,4],[2,3.1,4]],"ltp":3.2,"tv":41995.35,"id":8858694}]}]}
{"op":"mcm","clk":"11911598988","pt":1724434744719,"mc":[{"id":"1.232184480","rc":[{"batb":[[0,3.15,4],[1,3.1,4],[2,3.05,4]],"ltp":3.2,"tv":41995.35,"id":8858694}]}]}
{"op":"mcm","clk":"11911599489","pt":1724434746947,"mc":[{"id":"1.232184480","rc":[{"batb":[[0,3.2,4],[1,3.15,4],[2,3.1,4]],"ltp":3.2,"tv":41995.35,"id":8858694}]}]}
{"op":"mcm","clk":"11911600021","pt":1724434749228,"mc":[{"id":"1.232184480","rc":[{"batb":[[0,3.15,4],[1,3.1,4],[2,3.05,4]],"ltp":3.2,"tv":41995.35,"id":8858694}]}]}
{"op":"mcm","clk":"11911600877","pt":1724434752918,"mc":[{"id":"1.232184480","rc":[{"batb":[[0,3.2,4],[1,3.15,4],[2,3.1,4]],"ltp":3.2,"tv":41995.35,"id":8858694}]}]}
{"op":"mcm","clk":"11911601409","pt":1724434755216,"mc":[{"id":"1.232184480","rc":[{"batb":[[0,3.15,4],[1,3.1,4],[2,3.05,4]],"ltp":3.2,"tv":41995.35,"id":8858694}]}]}
{"op":"mcm","clk":"11911601909","pt":1724434757444,"mc":[{"id":"1.232184480","rc":[{"batb":[[0,3.2,4],[1,3.15,4],[2,3.1,4]],"ltp":3.2,"tv":41995.35,"id":8858694}]}]}
{"op":"mcm","clk":"11911602470","pt":1724434759736,"mc":[{"id":"1.232184480","rc":[{"batb":[[0,3.15,4],[1,3.1,4],[2,3.05,4]],"ltp":3.2,"tv":41995.35,"id":8858694}]}]}
{"op":"mcm","clk":"11911603250","pt":1724434763166,"mc":[{"id":"1.232184480","rc":[{"batb":[[0,3.2,4],[1,3.15,4],[2,3.1,4]],"ltp":3.2,"tv":41995.35,"id":8858694}]}]}
{"op":"mcm","clk":"11911603853","pt":1724434765805,"mc":[{"id":"1.232184480","rc":[{"batb":[[0,3.15,4],[1,3.1,4],[2,3.05,4]],"ltp":3.2,"tv":41995.35,"id":8858694}]}]}
{"op":"mcm","clk":"11911606285","pt":1724434777159,"mc":[{"id":"1.232184480","rc":[{"batb":[[0,3.2,4],[1,3.15,4],[2,3.1,4]],"ltp":3.2,"tv":41995.35,"id":8858694}]}]}
{"op":"mcm","clk":"11911606758","pt":1724434779563,"mc":[{"id":"1.232184480","rc":[{"batb":[[0,3.15,4],[1,3.1,4],[2,3.05,4]],"ltp":3.2,"tv":41995.35,"id":8858694}]}]}
{"op":"mcm","clk":"11911608060","pt":1724434785769,"mc":[{"id":"1.232184480","rc":[{"batb":[[0,3.2,4],[1,3.15,4],[2,3.1,4]],"ltp":3.2,"tv":41995.35,"id":8858694}]}]}
{"op":"mcm","clk":"11911608857","pt":1724434789588,"mc":[{"id":"1.232184480","rc":[{"batb":[[0,3.15,4],[1,3.1,4],[2,3.05,4]],"ltp":3.2,"tv":41995.35,"id":8858694}]}]}
{"op":"mcm","clk":"11911609537","pt":1724434792692,"mc":[{"id":"1.232184480","rc":[{"batb":[[0,3.2,4],[1,3.15,4],[2,3.1,4]],"ltp":3.2,"tv":41995.35,"id":8858694}]}]}
{"op":"mcm","clk":"11911610154","pt":1724434795586,"mc":[{"id":"1.232184480","rc":[{"batb":[[0,3.15,4],[1,3.1,4],[2,3.05,4]],"ltp":3.2,"tv":41995.35,"id":8858694}]}]}
{"op":"mcm","clk":"11911611332","pt":1724434801183,"mc":[{"id":"1.232184480","rc":[{"batb":[[0,3.2,4],[1,3.15,4],[2,3.1,4]],"ltp":3.2,"tv":41995.35,"id":8858694}]}]}
{"op":"mcm","clk":"11911611912","pt":1724434803481,"mc":[{"id":"1.232184480","rc":[{"batb":[[0,3.15,4],[1,3.1,4],[2,3.05,4]],"ltp":3.2,"tv":41995.35,"id":8858694}]}]}
{"op":"mcm","clk":"11911613508","pt":1724434810222,"mc":[{"id":"1.232184480","rc":[{"batb":[[0,3.2,4],[1,3.15,4],[2,3.1,4]],"ltp":3.2,"tv":41995.35,"id":8858694}]}]}
{"op":"mcm","clk":"11911614105","pt":1724434812547,"mc":[{"id":"1.232184480","rc":[{"batb":[[0,3.15,4],[1,3.1,4],[2,3.05,4]],"ltp":3.2,"tv":41995.35,"id":8858694}]}]}
{"op":"mcm","clk":"11911614662","pt":1724434814848,"mc":[{"id":"1.232184480","rc":[{"batb":[[0,3.2,4],[1,3.15,4],[2,3.1,4]],"ltp":3.2,"tv":41995.35,"id":8858694}]}]}
{"op":"mcm","clk":"11911615181","pt":1724434817121,"mc":[{"id":"1.232184480","rc":[{"batb":[[0,3.15,4],[1,3.1,4],[2,3.05,4]],"ltp":3.2,"tv":41995.35,"id":8858694}]}]}
{"op":"mcm","clk":"11911615988","pt":1724434820940,"mc":[{"id":"1.232184480","rc":[{"batb":[[0,3.2,4],[1,3.15,4],[2,3.1,4]],"ltp":3.2,"tv":41995.35,"id":8858694}]}]}
{"op":"mcm","clk":"11911616657","pt":1724434823817,"mc":[{"id":"1.232184480","rc":[{"batb":[[0,3.15,4],[1,3.1,4],[2,3.05,4]],"ltp":3.2,"tv":41995.35,"id":8858694}]}]}
{"op":"mcm","clk":"11911619827","pt":1724434837790,"mc":[{"id":"1.232184480","rc":[{"batb":[[0,3.2,4],[1,3.15,4],[2,3.1,4]],"ltp":3.2,"tv":41995.35,"id":8858694}]}]}
{"op":"mcm","clk":"11911620375","pt":1724434840133,"mc":[{"id":"1.232184480","rc":[{"batb":[[0,3.15,4],[1,3.1,4],[2,3.05,4]],"ltp":3.2,"tv":41995.35,"id":8858694}]}]}
{"op":"mcm","clk":"11911621037","pt":1724434842850,"mc":[{"id":"1.232184480","rc":[{"batb":[[0,3.2,4],[1,3.15,4],[2,3.1,4]],"ltp":3.2,"tv":41995.35,"id":8858694}]}]}
{"op":"mcm","clk":"11911621603","pt":1724434845361,"mc":[{"id":"1.232184480","rc":[{"batb":[[0,3.15,4],[1,3.1,4],[2,3.05,4]],"ltp":3.2,"tv":41995.35,"id":8858694}]}]}
{"op":"mcm","clk":"11911622901","pt":1724434851166,"mc":[{"id":"1.232184480","rc":[{"batb":[[0,3.2,4],[1,3.15,4],[2,3.1,4]],"ltp":3.2,"tv":41995.35,"id":8858694}]}]}
{"op":"mcm","clk":"11911623442","pt":1724434853597,"mc":[{"id":"1.232184480","rc":[{"batb":[[0,3.15,4],[1,3.1,4],[2,3.05,4]],"ltp":3.2,"tv":41995.35,"id":8858694}]}]}
{"op":"mcm","clk":"11911624282","pt":1724434857378,"mc":[{"id":"1.232184480","rc":[{"batb":[[0,3.2,4],[1,3.15,4],[2,3.1,4]],"ltp":3.2,"tv":41995.35,"id":8858694}]}]}
{"op":"mcm","clk":"11911624839","pt":1724434859674,"mc":[{"id":"1.232184480","rc":[{"batb":[[0,3.15,4],[1,3.1,4],[2,3.05,4]],"ltp":3.2,"tv":41995.35,"id":8858694}]}]}
{"op":"mcm","clk":"11911625978","pt":1724434864499,"mc":[{"id":"1.232184480","rc":[{"batb":[[0,3.2,4],[1,3.15,4],[2,3.1,4]],"ltp":3.2,"tv":41995.35,"id":8858694}]}]}
{"op":"mcm","clk":"11911626556","pt":1724434867015,"mc":[{"id":"1.232184480","rc":[{"batb":[[0,3.15,4],[1,3.1,4],[2,3.05,4]],"ltp":3.2,"tv":41995.35,"id":8858694}]}]}
{"op":"mcm","clk":"11911627248","pt":1724434870126,"mc":[{"id":"1.232184480","rc":[{"batb":[[0,3.2,4],[1,3.15,4],[2,3.1,4]],"ltp":3.2,"tv":41995.35,"id":8858694}]}]}
{"op":"mcm","clk":"11911627742","pt":1724434872307,"mc":[{"id":"1.232184480","rc":[{"batb":[[0,3.15,4],[1,3.1,4],[2,3.05,4]],"ltp":3.2,"tv":41995.35,"id":8858694}]}]}
{"op":"mcm","clk":"11911628647","pt":1724434876290,"mc":[{"id":"1.232184480","rc":[{"batb":[[0,3.2,4],[1,3.15,4],[2,3.1,4]],"ltp":3.2,"tv":41995.35,"id":8858694}]}]}
{"op":"mcm","clk":"11911629216","pt":1724434878611,"mc":[{"id":"1.232184480","rc":[{"batb":[[0,3.15,4],[1,3.1,4],[2,3.05,4]],"ltp":3.2,"tv":41995.35,"id":8858694}]}]}
{"op":"mcm","clk":"11911630117","pt":1724434882428,"mc":[{"id":"1.232184480","rc":[{"batb":[[0,3.2,4],[1,3.15,4],[2,3.1,4]],"ltp":3.2,"tv":41995.35,"id":8858694}]}]}
{"op":"mcm","clk":"11911630705","pt":1724434885110,"mc":[{"id":"1.232184480","rc":[{"batb":[[0,3.15,4],[1,3.1,4],[2,3.05,4]],"ltp":3.2,"tv":41995.35,"id":8858694}]}]}
{"op":"mcm","clk":"11911631684","pt":1724434889539,"mc":[{"id":"1.232184480","rc":[{"batb":[[0,3.2,4],[1,3.15,4],[2,3.1,4]],"ltp":3.2,"tv":41995.35,"id":8858694}]}]}
{"op":"mcm","clk":"11911632252","pt":1724434892131,"mc":[{"id":"1.232184480","rc":[{"batb":[[0,3.15,4],[1,3.1,4],[2,3.05,4]],"ltp":3.2,"tv":41995.35,"id":8858694}]}]}
{"op":"mcm","clk":"11911632826","pt":1724434894703,"mc":[{"id":"1.232184480","rc":[{"batb":[[0,3.2,4],[1,3.15,4],[2,3.1,4]],"ltp":3.2,"tv":41995.35,"id":8858694}]}]}
{"op":"mcm","clk":"11911633279","pt":1724434896909,"mc":[{"id":"1.232184480","rc":[{"batb":[[0,3.15,4],[1,3.1,4],[2,3.05,4]],"ltp":3.2,"tv":41995.35,"id":8858694}]}]}
{"op":"mcm","clk":"11911634193","pt":1724434901221,"mc":[{"id":"1.232184480","rc":[{"batb":[[0,3.2,4],[1,3.15,4],[2,3.1,4]],"ltp":3.2,"tv":41995.35,"id":8858694}]}]}
{"op":"mcm","clk":"11911634767","pt":1724434903660,"mc":[{"id":"1.232184480","rc":[{"batb":[[0,3.15,4],[1,3.1,4],[2,3.05,4]],"ltp":3.2,"tv":41995.35,"id":8858694}]}]}
{"op":"mcm","clk":"11911636456","pt":1724434911089,"mc":[{"id":"1.232184480","rc":[{"batb":[[0,3.2,4],[1,3.15,4],[2,3.1,4]],"ltp":3.2,"tv":41995.35,"id":8858694}]}]}
{"op":"mcm","clk":"11911636981","pt":1724434913364,"mc":[{"id":"1.232184480","rc":[{"batb":[[0,3.15,4],[1,3.1,4],[2,3.05,4]],"ltp":3.2,"tv":41995.35,"id":8858694}]}]}
{"op":"mcm","clk":"11911638491","pt":1724434919977,"mc":[{"id":"1.232184480","rc":[{"batb":[[0,3.2,4],[1,3.15,4],[2,3.1,4]],"ltp":3.2,"tv":41995.35,"id":8858694}]}]}
{"op":"mcm","clk":"11911639077","pt":1724434922607,"mc":[{"id":"1.232184480","rc":[{"batb":[[0,3.15,4],[1,3.1,4],[2,3.05,4]],"ltp":3.2,"tv":41995.35,"id":8858694}]}]}
{"op":"mcm","clk":"11911645500","pt":1724434950653,"mc":[{"id":"1.232184480","rc":[{"batb":[[0,3.2,4],[1,3.15,4],[2,3.1,4]],"ltp":3.2,"tv":41995.35,"id":8858694}]}]}
{"op":"mcm","clk":"11911646064","pt":1724434953147,"mc":[{"id":"1.232184480","rc":[{"batb":[[0,3.15,4],[1,3.1,4],[2,3.05,4]],"ltp":3.2,"tv":41995.35,"id":8858694}]}]}
{"op":"mcm","clk":"11911647153","pt":1724434957927,"mc":[{"id":"1.232184480","rc":[{"batb":[[0,3.2,4],[1,3.15,4],[2,3.1,4]],"ltp":3.2,"tv":41995.35,"id":8858694}]}]}
{"op":"mcm","clk":"11911647689","pt":1724434960456,"mc":[{"id":"1.232184480","rc":[{"batb":[[0,3.15,4],[1,3.1,4],[2,3.05,4]],"ltp":3.2,"tv":41995.35,"id":8858694}]}]}
{"op":"mcm","clk":"11911648176","pt":1724434962622,"mc":[{"id":"1.232184480","rc":[{"batb":[[0,3.2,4],[1,3.15,4],[2,3.1,4]],"ltp":3.2,"tv":41995.35,"id":8858694}]}]}
{"op":"mcm","clk":"11911648713","pt":1724434964952,"mc":[{"id":"1.232184480","rc":[{"batb":[[0,3.15,4],[1,3.1,4],[2,3.05,4]],"ltp":3.2,"tv":41995.35,"id":8858694}]}]}
{"op":"mcm","clk":"11911649307","pt":1724434967545,"mc":[{"id":"1.232184480","rc":[{"batb":[[0,3.2,4],[1,3.15,4],[2,3.1,4]],"ltp":3.2,"tv":41995.35,"id":8858694}]}]}
{"op":"mcm","clk":"11911649793","pt":1724434969935,"mc":[{"id":"1.232184480","rc":[{"batb":[[0,3.15,4],[1,3.1,4],[2,3.05,4]],"ltp":3.2,"tv":41995.35,"id":8858694}]}]}
{"op":"mcm","clk":"11911650310","pt":1724434972152,"mc":[{"id":"1.232184480","rc":[{"batb":[[0,3.2,4],[1,3.15,4],[2,3.1,4]],"ltp":3.2,"tv":41995.35,"id":8858694}]}]}
{"op":"mcm","clk":"11911650871","pt":1724434974539,"mc":[{"id":"1.232184480","rc":[{"batb":[[0,3.15,4],[1,3.1,4],[2,3.05,4]],"ltp":3.2,"tv":41995.35,"id":8858694}]}]}
{"op":"mcm","clk":"11911655003","pt":1724434993164,"mc":[{"id":"1.232184480","rc":[{"batb":[[0,3.2,4],[1,3.15,4],[2,3.1,4]],"ltp":3.2,"tv":41995.35,"id":8858694}]}]}
{"op":"mcm","clk":"11911655597","pt":1724434995658,"mc":[{"id":"1.232184480","rc":[{"batb":[[0,3.15,4],[1,3.1,4],[2,3.05,4]],"ltp":3.2,"tv":41995.35,"id":8858694}]}]}
{"op":"mcm","clk":"11911657225","pt":1724435003272,"mc":[{"id":"1.232184480","rc":[{"batb":[[0,3.2,4],[1,3.15,4],[2,3.1,4]],"ltp":3.2,"tv":41995.35,"id":8858694}]}]}
{"op":"mcm","clk":"11911657816","pt":1724435005734,"mc":[{"id":"1.232184480","rc":[{"batb":[[0,3.15,4],[1,3.1,4],[2,3.05,4]],"ltp":3.2,"tv":41995.35,"id":8858694}]}]}
{"op":"mcm","clk":"11911659702","pt":1724435014498,"mc":[{"id":"1.232184480","rc":[{"batb":[[0,3.2,4],[1,3.15,4],[2,3.1,4]],"ltp":3.2,"tv":41995.35,"id":8858694}]}]}
{"op":"mcm","clk":"11911660286","pt":1724435017198,"mc":[{"id":"1.232184480","rc":[{"batb":[[0,3.15,4],[1,3.1,4],[2,3.05,4]],"ltp":3.2,"tv":41995.35,"id":8858694}]}]}
{"op":"mcm","clk":"11911663073","pt":1724435029632,"mc":[{"id":"1.232184480","rc":[{"batb":[[0,3.2,4],[1,3.15,4],[2,3.1,4]],"ltp":3.2,"tv":41995.35,"id":8858694}]}]}
{"op":"mcm","clk":"11911663658","pt":1724435032369,"mc":[{"id":"1.232184480","rc":[{"batb":[[0,3.15,4],[1,3.1,4],[2,3.05,4]],"ltp":3.2,"tv":41995.35,"id":8858694}]}]}
{"op":"mcm","clk":"11911664575","pt":1724435036381,"mc":[{"id":"1.232184480","rc":[{"batb":[[0,3.2,4],[1,3.15,4],[2,3.1,4]],"ltp":3.2,"tv":41995.35,"id":8858694}]}]}
{"op":"mcm","clk":"11911665112","pt":1724435038910,"mc":[{"id":"1.232184480","rc":[{"batb":[[0,3.15,4],[1,3.1,4],[2,3.05,4]],"ltp":3.2,"tv":41995.35,"id":8858694}]}]}
{"op":"mcm","clk":"11911665829","pt":1724435041887,"mc":[{"id":"1.232184480","rc":[{"batb":[[0,3.2,4],[1,3.15,4],[2,3.1,4]],"ltp":3.2,"tv":41995.35,"id":8858694}]}]}
{"op":"mcm","clk":"11911666404","pt":1724435044321,"mc":[{"id":"1.232184480","rc":[{"batb":[[0,3.15,4],[1,3.1,4],[2,3.05,4]],"ltp":3.2,"tv":41995.35,"id":8858694}]}]}
{"op":"mcm","clk":"11911668428","pt":1724435053099,"mc":[{"id":"1.232184480","rc":[{"batb":[[0,3.2,4],[1,3.15,4],[2,3.1,4]],"ltp":3.2,"tv":41995.35,"id":8858694}]}]}
{"op":"mcm","clk":"11911668977","pt":1724435055508,"mc":[{"id":"1.232184480","rc":[{"batb":[[0,3.15,4],[1,3.1,4],[2,3.05,4]],"ltp":3.2,"tv":41995.35,"id":8858694}]}]}
{"op":"mcm","clk":"11911671307","pt":1724435065918,"mc":[{"id":"1.232184480","rc":[{"batb":[[0,3.2,4],[1,3.15,4],[2,3.1,4]],"ltp":3.2,"tv":41995.35,"id":8858694}]}]}
{"op":"mcm","clk":"11911671932","pt":1724435068552,"mc":[{"id":"1.232184480","rc":[{"batb":[[0,3.15,4],[1,3.1,4],[2,3.05,4]],"ltp":3.2,"tv":41995.35,"id":8858694}]}]}
{"op":"mcm","clk":"11911673534","pt":1724435075453,"mc":[{"id":"1.232184480","rc":[{"batb":[[0,3.2,4],[1,3.15,4],[2,3.1,4]],"ltp":3.2,"tv":41995.35,"id":8858694}]}]}
{"op":"mcm","clk":"11911674083","pt":1724435077882,"mc":[{"id":"1.232184480","rc":[{"batb":[[0,3.15,4],[1,3.1,4],[2,3.05,4]],"ltp":3.2,"tv":41995.35,"id":8858694}]}]}
{"op":"mcm","clk":"11911675442","pt":1724435084002,"mc":[{"id":"1.232184480","rc":[{"batb":[[0,3.2,4],[1,3.15,4],[2,3.1,4]],"ltp":3.2,"tv":41995.35,"id":8858694}]}]}
{"op":"mcm","clk":"11911675985","pt":1724435086293,"mc":[{"id":"1.232184480","rc":[{"batb":[[0,3.15,4],[1,3.1,4],[2,3.05,4]],"ltp":3.2,"tv":41995.35,"id":8858694}]}]}
{"op":"mcm","clk":"11911676640","pt":1724435089276,"mc":[{"id":"1.232184480","rc":[{"batb":[[0,3.2,4],[1,3.15,4],[2,3.1,4]],"ltp":3.2,"tv":41995.35,"id":8858694}]}]}
{"op":"mcm","clk":"11911677206","pt":1724435091711,"mc":[{"id":"1.232184480","rc":[{"batb":[[0,3.15,4],[1,3.1,4],[2,3.05,4]],"ltp":3.2,"tv":41995.35,"id":8858694}]}]}
{"op":"mcm","clk":"11911680294","pt":1724435104545,"mc":[{"id":"1.232184480","rc":[{"batb":[[0,3.2,4],[1,3.15,4],[2,3.1,4]],"ltp":3.2,"tv":41995.35,"id":8858694}]}]}
{"op":"mcm","clk":"11911680899","pt":1724435107095,"mc":[{"id":"1.232184480","rc":[{"batb":[[0,3.15,4],[1,3.1,4],[2,3.05,4]],"ltp":3.2,"tv":41995.35,"id":8858694}]}]}
{"op":"mcm","clk":"11911682472","pt":1724435113615,"mc":[{"id":"1.232184480","rc":[{"batb":[[0,3.2,4],[1,3.15,4],[2,3.1,4]],"ltp":3.2,"tv":41995.35,"id":8858694}]}]}
{"op":"mcm","clk":"11911683065","pt":1724435115983,"mc":[{"id":"1.232184480","rc":[{"batb":[[0,3.15,4],[1,3.1,4],[2,3.05,4]],"ltp":3.2,"tv":41995.35,"id":8858694}]}]}
{"op":"mcm","clk":"11911686363","pt":1724435130095,"mc":[{"id":"1.232184480","rc":[{"batb":[[0,3.2,4],[1,3.15,4],[2,3.1,4]],"ltp":3.2,"tv":41995.35,"id":8858694}]}]}
{"op":"mcm","clk":"11911686912","pt":1724435132427,"mc":[{"id":"1.232184480","rc":[{"batb":[[0,3.15,4],[1,3.1,4],[2,3.05,4]],"ltp":3.2,"tv":41995.35,"id":8858694}]}]}
{"op":"mcm","clk":"11911689716","pt":1724435144910,"mc":[{"id":"1.232184480","rc":[{"batb":[[0,3.2,4],[1,3.15,4],[2,3.1,4]],"ltp":3.2,"tv":41995.35,"id":8858694}]}]}
{"op":"mcm","clk":"11911690233","pt":1724435147409,"mc":[{"id":"1.232184480","rc":[{"batb":[[0,3.15,4],[1,3.1,4],[2,3.05,4]],"ltp":3.2,"tv":41995.35,"id":8858694}]}]}
{"op":"mcm","clk":"11911691938","pt":1724435154812,"mc":[{"id":"1.232184480","rc":[{"batb":[[0,3.2,4],[1,3.15,4],[2,3.1,4]],"ltp":3.2,"tv":41995.35,"id":8858694}]}]}
{"op":"mcm","clk":"11911692463","pt":1724435157341,"mc":[{"id":"1.232184480","rc":[{"batb":[[0,3.15,4],[1,3.1,4],[2,3.05,4]],"ltp":3.2,"tv":41995.35,"id":8858694}]}]}
{"op":"mcm","clk":"11911695883","pt":1724435172755,"mc":[{"id":"1.232184480","rc":[{"batb":[[0,3.2,4],[1,3.15,4],[2,3.1,4]],"ltp":3.2,"tv":41995.35,"id":8858694}]}]}
{"op":"mcm","clk":"11911696430","pt":1724435175187,"mc":[{"id":"1.232184480","rc":[{"batb":[[0,3.15,4],[1,3.1,4],[2,3.05,4]],"ltp":3.2,"tv":41995.35,"id":8858694}]}]}
{"op":"mcm","clk":"11911700649","pt":1724435192829,"mc":[{"id":"1.232184480","rc":[{"batb":[[0,3.2,4],[1,3.15,4],[2,3.1,4]],"ltp":3.2,"tv":41995.35,"id":8858694}]}]}
{"op":"mcm","clk":"11911701275","pt":1724435195344,"mc":[{"id":"1.232184480","rc":[{"batb":[[0,3.15,4],[1,3.1,4],[2,3.05,4]],"ltp":3.2,"tv":41995.35,"id":8858694}]}]}
{"op":"mcm","clk":"11911703355","pt":1724435204097,"mc":[{"id":"1.232184480","rc":[{"batb":[[0,3.2,4],[1,3.15,4],[2,3.1,4]],"ltp":3.2,"tv":41995.35,"id":8858694}]}]}
{"op":"mcm","clk":"11911703935","pt":1724435206631,"mc":[{"id":"1.232184480","rc":[{"batb":[[0,3.15,4],[1,3.1,4],[2,3.05,4]],"ltp":3.2,"tv":41995.35,"id":8858694}]}]}
{"op":"mcm","clk":"11911706182","pt":1724435215647,"mc":[{"id":"1.232184480","rc":[{"batb":[[0,3.2,4],[1,3.15,4],[2,3.1,4]],"ltp":3.2,"tv":41995.35,"id":8858694}]}]}
{"op":"mcm","clk":"11911706711","pt":1724435218127,"mc":[{"id":"1.232184480","rc":[{"batb":[[0,3.15,4],[1,3.1,4],[2,3.05,4]],"ltp":3.2,"tv":41995.35,"id":8858694}]}]}
{"op":"mcm","clk":"11911708114","pt":1724435224178,"mc":[{"id":"1.232184480","rc":[{"batb":[[0,3.2,4],[1,3.15,4],[2,3.1,4]],"ltp":3.2,"tv":41995.35,"id":8858694}]}]}
{"op":"mcm","clk":"11911708666","pt":1724435226484,"mc":[{"id":"1.232184480","rc":[{"batb":[[0,3.15,4],[1,3.1,4],[2,3.05,4]],"ltp":3.2,"tv":41995.35,"id":8858694}]}]}
{"op":"mcm","clk":"11911710171","pt":1724435232844,"mc":[{"id":"1.232184480","rc":[{"batb":[[0,3.2,4],[1,3.15,4],[2,3.1,4]],"ltp":3.2,"tv":41995.35,"id":8858694}]}]}
{"op":"mcm","clk":"11911710788","pt":1724435235367,"mc":[{"id":"1.232184480","rc":[{"batb":[[0,3.15,4],[1,3.1,4],[2,3.05,4]],"ltp":3.2,"tv":41995.35,"id":8858694}]}]}
{"op":"mcm","clk":"11911713353","pt":1724435245873,"mc":[{"id":"1.232184480","rc":[{"batb":[[0,3.2,4],[1,3.15,4],[2,3.1,4]],"ltp":3.2,"tv":41995.35,"id":8858694}]}]}
{"op":"mcm","clk":"11911713944","pt":1724435248362,"mc":[{"id":"1.232184480","rc":[{"batb":[[0,3.15,4],[1,3.1,4],[2,3.05,4]],"ltp":3.2,"tv":41995.35,"id":8858694}]}]}
{"op":"mcm","clk":"11911714542","pt":1724435250714,"mc":[{"id":"1.232184480","rc":[{"batb":[[0,3.2,4],[1,3.15,4],[2,3.1,4]],"ltp":3.2,"tv":41995.35,"id":8858694}]}]}
{"op":"mcm","clk":"11911715050","pt":1724435253025,"mc":[{"id":"1.232184480","rc":[{"batb":[[0,3.15,4],[1,3.1,4],[2,3.05,4]],"ltp":3.2,"tv":41995.35,"id":8858694}]}]}
{"op":"mcm","clk":"11911716464","pt":1724435258939,"mc":[{"id":"1.232184480","rc":[{"batb":[[0,3.2,4],[1,3.15,4],[2,3.1,4]],"ltp":3.2,"tv":41995.35,"id":8858694}]}]}
{"op":"mcm","clk":"11911717012","pt":1724435261227,"mc":[{"id":"1.232184480","rc":[{"batb":[[0,3.15,4],[1,3.1,4],[2,3.05,4]],"ltp":3.2,"tv":41995.35,"id":8858694}]}]}
{"op":"mcm","clk":"11911717903","pt":1724435265128,"mc":[{"id":"1.232184480","rc":[{"batb":[[0,3.2,4],[1,3.15,4],[2,3.1,4]],"ltp":3.2,"tv":41995.35,"id":8858694}]}]}
{"op":"mcm","clk":"11911718484","pt":1724435267619,"mc":[{"id":"1.232184480","rc":[{"batb":[[0,3.15,4],[1,3.1,4],[2,3.05,4]],"ltp":3.2,"tv":41995.35,"id":8858694}]}]}
{"op":"mcm","clk":"11911720638","pt":1724435277438,"mc":[{"id":"1.232184480","rc":[{"batb":[[0,3.2,4],[1,3.15,4],[2,3.1,4]],"ltp":3.2,"tv":41995.35,"id":8858694}]}]}
{"op":"mcm","clk":"11911721088","pt":1724435279750,"mc":[{"id":"1.232184480","rc":[{"batb":[[0,3.15,4],[1,3.1,4],[2,3.05,4]],"ltp":3.2,"tv":41995.35,"id":8858694}]}]}
{"op":"mcm","clk":"11911722591","pt":1724435286533,"mc":[{"id":"1.232184480","rc":[{"batb":[[0,3.2,4],[1,3.15,4],[2,3.1,4]],"ltp":3.2,"tv":41995.35,"id":8858694}]}]}
{"op":"mcm","clk":"11911723174","pt":1724435289007,"mc":[{"id":"1.232184480","rc":[{"batb":[[0,3.15,4],[1,3.1,4],[2,3.05,4]],"ltp":3.2,"tv":41995.35,"id":8858694}]}]}
{"op":"mcm","clk":"11911723990","pt":1724435292719,"mc":[{"id":"1.232184480","rc":[{"batb":[[0,3.2,4],[1,3.15,4],[2,3.1,4]],"ltp":3.2,"tv":41995.35,"id":8858694}]}]}
{"op":"mcm","clk":"11911724561","pt":1724435295247,"mc":[{"id":"1.232184480","rc":[{"trd":[[1.45,57.9]],"batb":[[0,1.45,82.37]],"ltp":1.45,"tv":34494.12,"id":247649},{"batb":[[0,3.15,4],[1,3.1,4],[2,3.05,4]],"ltp":3.2,"tv":41995.35,"id":8858694}],"tv":76489.48}]}
{"op":"mcm","clk":"11911725112","pt":1724435297422,"mc":[{"id":"1.232184480","rc":[{"batb":[[0,1.45,86.38]],"ltp":1.45,"tv":34494.12,"id":247649},{"batb":[[0,3.2,4],[1,3.15,4],[2,3.1,4]],"ltp":3.2,"tv":41995.35,"id":8858694}]}]}
{"op":"mcm","clk":"11911725605","pt":1724435299630,"mc":[{"id":"1.232184480","rc":[{"batb":[[0,3.15,4],[1,3.1,4],[2,3.05,4]],"ltp":3.2,"tv":41995.35,"id":8858694}]}]}
{"op":"mcm","clk":"11911726334","pt":1724435302856,"mc":[{"id":"1.232184480","rc":[{"batb":[[0,1.45,90.38]],"ltp":1.45,"tv":34494.12,"id":247649}]}]}
{"op":"mcm","clk":"11911726836","pt":1724435305153,"mc":[{"id":"1.232184480","rc":[{"batb":[[0,3.2,4],[1,3.15,4],[2,3.1,4]],"ltp":3.2,"tv":41995.35,"id":8858694}]}]}
{"op":"mcm","clk":"11911727397","pt":1724435307731,"mc":[{"id":"1.232184480","rc":[{"batb":[[0,3.15,4],[1,3.1,4],[2,3.05,4]],"ltp":3.2,"tv":41995.35,"id":8858694}]}]}
{"op":"mcm","clk":"11911728423","pt":1724435312149,"mc":[{"id":"1.232184480","rc":[{"batb":[[0,3.2,4],[1,3.15,4],[2,3.1,4]],"ltp":3.2,"tv":41995.35,"id":8858694}]}]}
{"op":"mcm","clk":"11911728971","pt":1724435314661,"mc":[{"id":"1.232184480","rc":[{"batb":[[0,3.15,4],[1,3.1,4],[2,3.05,4]],"ltp":3.2,"tv":41995.35,"id":8858694}]}]}
{"op":"mcm","clk":"11911730292","pt":1724435321043,"mc":[{"id":"1.232184480","rc":[{"batb":[[0,3.2,4],[1,3.15,4],[2,3.1,4]],"ltp":3.2,"tv":41995.35,"id":8858694}]}]}
{"op":"mcm","clk":"11911730761","pt":1724435323454,"mc":[{"id":"1.232184480","rc":[{"batb":[[0,3.15,4],[1,3.1,4],[2,3.05,4]],"ltp":3.2,"tv":41995.35,"id":8858694}]}]}
{"op":"mcm","clk":"11911731751","pt":1724435327955,"mc":[{"id":"1.232184480","rc":[{"batb":[[0,3.2,4],[1,3.15,4],[2,3.1,4]],"ltp":3.2,"tv":41995.35,"id":8858694}]}]}
{"op":"mcm","clk":"11911732282","pt":1724435330249,"mc":[{"id":"1.232184480","rc":[{"batb":[[0,3.15,4],[1,3.1,4],[2,3.05,4]],"ltp":3.2,"tv":41995.35,"id":8858694}]}]}
{"op":"mcm","clk":"11911733758","pt":1724435336551,"mc":[{"id":"1.232184480","rc":[{"batb":[[0,3.2,4],[1,3.15,4],[2,3.1,4]],"ltp":3.2,"tv":41995.35,"id":8858694}]}]}
{"op":"mcm","clk":"11911734122","pt":1724435338339,"mc":[{"id":"1.232184480","rc":[{"batb":[[1,1.41,41.84],[2,1.08,216.77]],"ltp":1.45,"tv":34494.12,"id":247649}]}]}
{"op":"mcm","clk":"11911734224","pt":1724435338861,"mc":[{"id":"1.232184480","rc":[{"batb":[[0,3.15,4],[1,3.1,4],[2,3.05,4]],"ltp":3.2,"tv":41995.35,"id":8858694}]}]}
{"op":"mcm","clk":"11911736004","pt":1724435347285,"mc":[{"id":"1.232184480","rc":[{"batb":[[0,3.2,4],[1,3.15,4],[2,3.1,4]],"ltp":3.2,"tv":41995.35,"id":8858694}]}]}
{"op":"mcm","clk":"11911736484","pt":1724435349677,"mc":[{"id":"1.232184480","rc":[{"batb":[[0,3.15,4],[1,3.1,4],[2,3.05,4]],"ltp":3.2,"tv":41995.35,"id":8858694}]}]}
{"op":"mcm","clk":"11911737894","pt":1724435356448,"mc":[{"id":"1.232184480","rc":[{"batb":[[0,3.2,4],[1,3.15,4],[2,3.1,4]],"ltp":3.2,"tv":41995.35,"id":8858694}]}]}
{"op":"mcm","clk":"11911738443","pt":1724435358982,"mc":[{"id":"1.232184480","rc":[{"batb":[[0,3.15,4],[1,3.1,4],[2,3.05,4]],"ltp":3.2,"tv":41995.35,"id":8858694}]}]}
{"op":"mcm","clk":"11911741395","pt":1724435372235,"mc":[{"id":"1.232184480","rc":[{"batb":[[0,3.2,4],[1,3.15,4],[2,3.1,4]],"ltp":3.2,"tv":41995.35,"id":8858694}]}]}
{"op":"mcm","clk":"11911741953","pt":1724435374700,"mc":[{"id":"1.232184480","rc":[{"batb":[[0,3.15,4],[1,3.1,4],[2,3.05,4]],"ltp":3.2,"tv":41995.35,"id":8858694}]}]}
{"op":"mcm","clk":"11911743425","pt":1724435381817,"mc":[{"id":"1.232184480","rc":[{"batb":[[0,3.2,4],[1,3.15,4],[2,3.1,4]],"ltp":3.2,"tv":41995.35,"id":8858694}]}]}
{"op":"mcm","clk":"11911743901","pt":1724435384224,"mc":[{"id":"1.232184480","rc":[{"batb":[[0,3.15,4],[1,3.1,4],[2,3.05,4]],"ltp":3.2,"tv":41995.35,"id":8858694}]}]}
{"op":"mcm","clk":"11911745443","pt":1724435391129,"mc":[{"id":"1.232184480","rc":[{"batb":[[0,3.2,4],[1,3.15,4],[2,3.1,4]],"ltp":3.2,"tv":41995.35,"id":8858694}]}]}
{"op":"mcm","clk":"11911745897","pt":1724435393340,"mc":[{"id":"1.232184480","rc":[{"batb":[[0,3.15,4],[1,3.1,4],[2,3.05,4]],"ltp":3.2,"tv":41995.35,"id":8858694}]}]}
{"op":"mcm","clk":"11911747941","pt":1724435401987,"mc":[{"id":"1.232184480","rc":[{"batb":[[0,3.2,4],[1,3.15,4],[2,3.1,4]],"ltp":3.2,"tv":41995.35,"id":8858694}]}]}
{"op":"mcm","clk":"11911748547","pt":1724435404248,"mc":[{"id":"1.232184480","rc":[{"batb":[[0,3.15,4],[1,3.1,4],[2,3.05,4]],"ltp":3.2,"tv":41995.35,"id":8858694}]}]}
{"op":"mcm","clk":"11911749255","pt":1724435407164,"mc":[{"id":"1.232184480","rc":[{"batb":[[0,3.2,4],[1,3.15,4],[2,3.1,4]],"ltp":3.2,"tv":41995.35,"id":8858694}]}]}
{"op":"mcm","clk":"11911749842","pt":1724435409657,"mc":[{"id":"1.232184480","rc":[{"batb":[[0,3.15,4],[1,3.1,4],[2,3.05,4]],"ltp":3.2,"tv":41995.35,"id":8858694}]}]}
{"op":"mcm","clk":"11911752729","pt":1724435421860,"mc":[{"id":"1.232184480","rc":[{"batb":[[0,3.2,4],[1,3.15,4],[2,3.1,4]],"ltp":3.2,"tv":41995.35,"id":8858694}]}]}
{"op":"mcm","clk":"11911753291","pt":1724435424292,"mc":[{"id":"1.232184480","rc":[{"batb":[[0,3.15,4],[1,3.1,4],[2,3.05,4]],"ltp":3.2,"tv":41995.35,"id":8858694}]}]}
{"op":"mcm","clk":"11911758684","pt":1724435447249,"mc":[{"id":"1.232184480","rc":[{"batb":[[0,3.2,4],[1,3.15,4],[2,3.1,4]],"ltp":3.2,"tv":41995.35,"id":8858694}]}]}
{"op":"mcm","clk":"11911759208","pt":1724435449711,"mc":[{"id":"1.232184480","rc":[{"batb":[[0,3.15,4],[1,3.1,4],[2,3.05,4]],"ltp":3.2,"tv":41995.35,"id":8858694}]}]}
{"op":"mcm","clk":"11911760976","pt":1724435457571,"mc":[{"id":"1.232184480","rc":[{"batb":[[0,3.2,4],[1,3.15,4],[2,3.1,4]],"ltp":3.2,"tv":41995.35,"id":8858694}]}]}
{"op":"mcm","clk":"11911761519","pt":1724435459953,"mc":[{"id":"1.232184480","rc":[{"batb":[[0,3.15,4],[1,3.1,4],[2,3.05,4]],"ltp":3.2,"tv":41995.35,"id":8858694}]}]}
{"op":"mcm","clk":"11911764827","pt":1724435474133,"mc":[{"id":"1.232184480","rc":[{"batb":[[0,3.2,4],[1,3.15,4],[2,3.1,4]],"ltp":3.2,"tv":41995.35,"id":8858694}]}]}
{"op":"mcm","clk":"11911765339","pt":1724435476491,"mc":[{"id":"1.232184480","rc":[{"batb":[[0,3.15,4],[1,3.1,4],[2,3.05,4]],"ltp":3.2,"tv":41995.35,"id":8858694}]}]}
{"op":"mcm","clk":"11911767602","pt":1724435486684,"mc":[{"id":"1.232184480","rc":[{"batb":[[0,3.2,4],[1,3.15,4],[2,3.1,4]],"ltp":3.2,"tv":41995.35,"id":8858694}]}]}
{"op":"mcm","clk":"11911768143","pt":1724435488945,"mc":[{"id":"1.232184480","rc":[{"batb":[[0,3.15,4],[1,3.1,4],[2,3.05,4]],"ltp":3.2,"tv":41995.35,"id":8858694}]}]}
{"op":"mcm","clk":"11911775960","pt":1724435522880,"mc":[{"id":"1.232184480","rc":[{"batb":[[0,3.2,4],[1,3.15,4],[2,3.1,4]],"ltp":3.2,"tv":41995.35,"id":8858694}]}]}
{"op":"mcm","clk":"11911776502","pt":1724435525295,"mc":[{"id":"1.232184480","rc":[{"batb":[[0,3.15,4],[1,3.1,4],[2,3.05,4]],"ltp":3.2,"tv":41995.35,"id":8858694}]}]}
{"op":"mcm","clk":"11911780179","pt":1724435541434,"mc":[{"id":"1.232184480","rc":[{"batb":[[0,3.2,4],[1,3.15,4],[2,3.1,4]],"ltp":3.2,"tv":41995.35,"id":8858694}]}]}
{"op":"mcm","clk":"11911780803","pt":1724435544218,"mc":[{"id":"1.232184480","rc":[{"batb":[[0,3.15,4],[1,3.1,4],[2,3.05,4]],"ltp":3.2,"tv":41995.35,"id":8858694}]}]}
{"op":"mcm","clk":"11911781989","pt":1724435550037,"mc":[{"id":"1.232184480","rc":[{"batb":[[0,3.2,4],[1,3.15,4],[2,3.1,4]],"ltp":3.2,"tv":41995.35,"id":8858694}]}]}
{"op":"mcm","clk":"11911782439","pt":1724435552244,"mc":[{"id":"1.232184480","rc":[{"batb":[[0,3.15,4],[1,3.1,4],[2,3.05,4]],"ltp":3.2,"tv":41995.35,"id":8858694}]}]}
{"op":"mcm","clk":"11911783386","pt":1724435557025,"mc":[{"id":"1.232184480","rc":[{"batb":[[0,3.2,4],[1,3.15,4],[2,3.1,4]],"ltp":3.2,"tv":41995.35,"id":8858694}]}]}
{"op":"mcm","clk":"11911783863","pt":1724435559346,"mc":[{"id":"1.232184480","rc":[{"batb":[[0,3.15,4],[1,3.1,4],[2,3.05,4]],"ltp":3.2,"tv":41995.35,"id":8858694}]}]}
{"op":"mcm","clk":"11911786355","pt":1724435571773,"mc":[{"id":"1.232184480","rc":[{"batb":[[0,3.2,4],[1,3.15,4],[2,3.1,4]],"ltp":3.2,"tv":41995.35,"id":8858694}]}]}
{"op":"mcm","clk":"11911786976","pt":1724435574773,"mc":[{"id":"1.232184480","rc":[{"batb":[[0,3.15,4],[1,3.1,4],[2,3.05,4]],"ltp":3.2,"tv":41995.35,"id":8858694}]}]}
{"op":"mcm","clk":"11911787731","pt":1724435578472,"mc":[{"id":"1.232184480","rc":[{"batb":[[0,3.2,4],[1,3.15,4],[2,3.1,4]],"ltp":3.2,"tv":41995.35,"id":8858694}]}]}
{"op":"mcm","clk":"11911788249","pt":1724435580728,"mc":[{"id":"1.232184480","rc":[{"batb":[[0,3.15,4],[1,3.1,4],[2,3.05,4]],"ltp":3.2,"tv":41995.35,"id":8858694}]}]}
{"op":"mcm","clk":"11911789049","pt":1724435584242,"mc":[{"id":"1.232184480","rc":[{"batb":[[0,3.2,4],[1,3.15,4],[2,3.1,4]],"ltp":3.2,"tv":41995.35,"id":8858694}]}]}
{"op":"mcm","clk":"11911789540","pt":1724435586501,"mc":[{"id":"1.232184480","rc":[{"batb":[[0,3.15,4],[1,3.1,4],[2,3.05,4]],"ltp":3.2,"tv":41995.35,"id":8858694}]}]}
{"op":"mcm","clk":"11911790038","pt":1724435588789,"mc":[{"id":"1.232184480","rc":[{"batb":[[0,3.2,4],[1,3.15,4],[2,3.1,4]],"ltp":3.2,"tv":41995.35,"id":8858694}]}]}
{"op":"mcm","clk":"11911790532","pt":1724435591290,"mc":[{"id":"1.232184480","rc":[{"batb":[[0,3.15,4],[1,3.1,4],[2,3.05,4]],"ltp":3.2,"tv":41995.35,"id":8858694}]}]}
{"op":"mcm","clk":"11911792905","pt":1724435602340,"mc":[{"id":"1.232184480","rc":[{"batb":[[0,3.2,4],[1,3.15,4],[2,3.1,4]],"ltp":3.2,"tv":41995.35,"id":8858694}]}]}
{"op":"mcm","clk":"11911793421","pt":1724435604547,"mc":[{"id":"1.232184480","rc":[{"batb":[[0,3.15,4],[1,3.1,4],[2,3.05,4]],"ltp":3.2,"tv":41995.35,"id":8858694}]}]}
{"op":"mcm","clk":"11911795112","pt":1724435612776,"mc":[{"id":"1.232184480","rc":[{"batb":[[0,3.2,4],[1,3.15,4],[2,3.1,4]],"ltp":3.2,"tv":41995.35,"id":8858694}]}]}
{"op":"mcm","clk":"11911795646","pt":1724435615138,"mc":[{"id":"1.232184480","rc":[{"batb":[[0,3.15,4],[1,3.1,4],[2,3.05,4]],"ltp":3.2,"tv":41995.35,"id":8858694}]}]}
{"op":"mcm","clk":"11911796287","pt":1724435618451,"mc":[{"id":"1.232184480","rc":[{"batb":[[0,3.2,4],[1,3.15,4],[2,3.1,4]],"ltp":3.2,"tv":41995.35,"id":8858694}]}]}
{"op":"mcm","clk":"11911796866","pt":1724435620962,"mc":[{"id":"1.232184480","rc":[{"batb":[[0,3.15,4],[1,3.1,4],[2,3.05,4]],"ltp":3.2,"tv":41995.35,"id":8858694}]}]}
{"op":"mcm","clk":"11911797607","pt":1724435624620,"mc":[{"id":"1.232184480","rc":[{"batb":[[0,3.2,4],[1,3.15,4],[2,3.1,4]],"ltp":3.2,"tv":41995.35,"id":8858694}]}]}
{"op":"mcm","clk":"11911798048","pt":1724435627040,"mc":[{"id":"1.232184480","rc":[{"batb":[[0,3.15,4],[1,3.1,4],[2,3.05,4]],"ltp":3.2,"tv":41995.35,"id":8858694}]}]}
{"op":"mcm","clk":"11911798528","pt":1724435629763,"mc":[{"id":"1.232184480","rc":[{"batb":[[0,3.2,4],[1,3.15,4],[2,3.1,4]],"ltp":3.2,"tv":41995.35,"id":8858694}]}]}
{"op":"mcm","clk":"11911799057","pt":1724435632165,"mc":[{"id":"1.232184480","rc":[{"batb":[[0,3.15,4],[1,3.1,4],[2,3.05,4]],"ltp":3.2,"tv":41995.35,"id":8858694}]}]}
{"op":"mcm","clk":"11911799760","pt":1724435635752,"mc":[{"id":"1.232184480","rc":[{"batb":[[0,3.2,4],[1,3.15,4],[2,3.1,4]],"ltp":3.2,"tv":41995.35,"id":8858694}]}]}
{"op":"mcm","clk":"11911800215","pt":1724435638162,"mc":[{"id":"1.232184480","rc":[{"batb":[[0,3.15,4],[1,3.1,4],[2,3.05,4]],"ltp":3.2,"tv":41995.35,"id":8858694}]}]}
{"op":"mcm","clk":"11911803614","pt":1724435654067,"mc":[{"id":"1.232184480","rc":[{"batb":[[0,3.2,4],[1,3.15,4],[2,3.1,4]],"ltp":3.2,"tv":41995.35,"id":8858694}]}]}
{"op":"mcm","clk":"11911804114","pt":1724435656388,"mc":[{"id":"1.232184480","rc":[{"batb":[[0,3.15,4],[1,3.1,4],[2,3.05,4]],"ltp":3.2,"tv":41995.35,"id":8858694}]}]}
{"op":"mcm","clk":"11911805139","pt":1724435661497,"mc":[{"id":"1.232184480","rc":[{"batb":[[0,3.2,4],[1,3.15,4],[2,3.1,4]],"ltp":3.2,"tv":41995.35,"id":8858694}]}]}
{"op":"mcm","clk":"11911805704","pt":1724435664297,"mc":[{"id":"1.232184480","rc":[{"batb":[[0,3.15,4],[1,3.1,4],[2,3.05,4]],"ltp":3.2,"tv":41995.35,"id":8858694}]}]}
{"op":"mcm","clk":"11911806231","pt":1724435666911,"mc":[{"id":"1.232184480","rc":[{"batb":[[0,3.2,4],[1,3.15,4],[2,3.1,4]],"ltp":3.2,"tv":41995.35,"id":8858694}]}]}
{"op":"mcm","clk":"11911806694","pt":1724435669316,"mc":[{"id":"1.232184480","rc":[{"batb":[[0,3.15,4],[1,3.1,4],[2,3.05,4]],"ltp":3.2,"tv":41995.35,"id":8858694}]}]}
{"op":"mcm","clk":"11911808227","pt":1724435676745,"mc":[{"id":"1.232184480","rc":[{"batb":[[0,3.2,4],[1,3.15,4],[2,3.1,4]],"ltp":3.2,"tv":41995.35,"id":8858694}]}]}
{"op":"mcm","clk":"11911808732","pt":1724435679218,"mc":[{"id":"1.232184480","rc":[{"batb":[[0,3.15,4],[1,3.1,4],[2,3.05,4]],"ltp":3.2,"tv":41995.35,"id":8858694}]}]}
{"op":"mcm","clk":"11911809186","pt":1724435681430,"mc":[{"id":"1.232184480","rc":[{"batb":[[0,3.2,4],[1,3.15,4],[2,3.1,4]],"ltp":3.2,"tv":41995.35,"id":8858694}]}]}
{"op":"mcm","clk":"11911809672","pt":1724435683942,"mc":[{"id":"1.232184480","rc":[{"batb":[[0,3.15,4],[1,3.1,4],[2,3.05,4]],"ltp":3.2,"tv":41995.35,"id":8858694}]}]}
{"op":"mcm","clk":"11911810488","pt":1724435687889,"mc":[{"id":"1.232184480","rc":[{"batb":[[0,3.2,4],[1,3.15,4],[2,3.1,4]],"ltp":3.2,"tv":41995.35,"id":8858694}]}]}
{"op":"mcm","clk":"11911810931","pt":1724435690266,"mc":[{"id":"1.232184480","rc":[{"batb":[[0,3.15,4],[1,3.1,4],[2,3.05,4]],"ltp":3.2,"tv":41995.35,"id":8858694}]}]}
{"op":"mcm","clk":"11911812664","pt":1724435699792,"mc":[{"id":"1.232184480","rc":[{"batb":[[0,3.2,4],[1,3.15,4],[2,3.1,4]],"ltp":3.2,"tv":41995.35,"id":8858694}]}]}
{"op":"mcm","clk":"11911813244","pt":1724435702235,"mc":[{"id":"1.232184480","rc":[{"batb":[[0,3.15,4],[1,3.1,4],[2,3.05,4]],"ltp":3.2,"tv":41995.35,"id":8858694}]}]}
{"op":"mcm","clk":"11911814131","pt":1724435706163,"mc":[{"id":"1.232184480","rc":[{"batb":[[0,3.2,4],[1,3.15,4],[2,3.1,4]],"ltp":3.2,"tv":41995.35,"id":8858694}]}]}
{"op":"mcm","clk":"11911814633","pt":1724435708399,"mc":[{"id":"1.232184480","rc":[{"batb":[[0,3.15,4],[1,3.1,4],[2,3.05,4]],"ltp":3.2,"tv":41995.35,"id":8858694}]}]}
{"op":"mcm","clk":"11911816358","pt":1724435716530,"mc":[{"id":"1.232184480","rc":[{"batb":[[0,3.2,4],[1,3.15,4],[2,3.1,4]],"ltp":3.2,"tv":41995.35,"id":8858694}]}]}
{"op":"mcm","clk":"11911816796","pt":1724435718447,"mc":[{"id":"1.232184480","rc":[{"batb":[[1,1.08,216.77],[2,1.07,7.58]],"ltp":1.45,"tv":34494.12,"id":247649}]}]}
{"op":"mcm","clk":"11911816862","pt":1724435718711,"mc":[{"id":"1.232184480","rc":[{"batb":[[0,3.15,4],[1,3.1,4],[2,3.05,4]],"ltp":3.2,"tv":41995.35,"id":8858694}]}]}
{"op":"mcm","clk":"11911817467","pt":1724435721515,"mc":[{"id":"1.232184480","rc":[{"batb":[[0,3.2,4],[1,3.15,4],[2,3.1,4]],"ltp":3.2,"tv":41995.35,"id":8858694}]}]}
{"op":"mcm","clk":"11911817928","pt":1724435723842,"mc":[{"id":"1.232184480","rc":[{"batb":[[0,3.15,4],[1,3.1,4],[2,3.05,4]],"ltp":3.2,"tv":41995.35,"id":8858694}]}]}
{"op":"mcm","clk":"11911818493","pt":1724435726535,"mc":[{"id":"1.232184480","rc":[{"batb":[[0,3.2,4],[1,3.15,4],[2,3.1,4]],"ltp":3.2,"tv":41995.35,"id":8858694}]}]}
{"op":"mcm","clk":"11911819020","pt":1724435728924,"mc":[{"id":"1.232184480","rc":[{"batb":[[0,3.15,4],[1,3.1,4],[2,3.05,4]],"ltp":3.2,"tv":41995.35,"id":8858694}]}]}
{"op":"mcm","clk":"11911819745","pt":1724435732562,"mc":[{"id":"1.232184480","rc":[{"batb":[[0,3.2,4],[1,3.15,4],[2,3.1,4]],"ltp":3.2,"tv":41995.35,"id":8858694}]}]}
{"op":"mcm","clk":"11911820231","pt":1724435734882,"mc":[{"id":"1.232184480","rc":[{"batb":[[0,3.15,4],[1,3.1,4],[2,3.05,4]],"ltp":3.2,"tv":41995.35,"id":8858694}]}]}
{"op":"mcm","clk":"11911821147","pt":1724435739930,"mc":[{"id":"1.232184480","rc":[{"batb":[[0,3.2,4],[1,3.15,4],[2,3.1,4]],"ltp":3.2,"tv":41995.35,"id":8858694}]}]}
{"op":"mcm","clk":"11911821611","pt":1724435742048,"mc":[{"id":"1.232184480","rc":[{"batb":[[0,3.15,4],[1,3.1,4],[2,3.05,4]],"ltp":3.2,"tv":41995.35,"id":8858694}]}]}
{"op":"mcm","clk":"11911823212","pt":1724435749995,"mc":[{"id":"1.232184480","rc":[{"batb":[[0,3.2,4],[1,3.15,4],[2,3.1,4]],"ltp":3.2,"tv":41995.35,"id":8858694}]}]}
{"op":"mcm","clk":"11911823668","pt":1724435752267,"mc":[{"id":"1.232184480","rc":[{"batb":[[0,3.15,4],[1,3.1,4],[2,3.05,4]],"ltp":3.2,"tv":41995.35,"id":8858694}]}]}
{"op":"mcm","clk":"11911825949","pt":1724435763702,"mc":[{"id":"1.232184480","rc":[{"batb":[[0,3.2,4],[1,3.15,4],[2,3.1,4]],"ltp":3.2,"tv":41995.35,"id":8858694}]}]}
{"op":"mcm","clk":"11911826484","pt":1724435766081,"mc":[{"id":"1.232184480","rc":[{"batb":[[0,3.15,4],[1,3.1,4],[2,3.05,4]],"ltp":3.2,"tv":41995.35,"id":8858694}]}]}
{"op":"mcm","clk":"11911827709","pt":1724435773277,"mc":[{"id":"1.232184480","rc":[{"batb":[[0,3.2,4],[1,3.15,4],[2,3.1,4]],"ltp":3.2,"tv":41995.35,"id":8858694}]}]}
{"op":"mcm","clk":"11911828162","pt":1724435775793,"mc":[{"id":"1.232184480","rc":[{"batb":[[0,3.15,4],[1,3.1,4],[2,3.05,4]],"ltp":3.2,"tv":41995.35,"id":8858694}]}]}
{"op":"mcm","clk":"11911828883","pt":1724435779714,"mc":[{"id":"1.232184480","rc":[{"batb":[[0,3.2,4],[1,3.15,4],[2,3.1,4]],"ltp":3.2,"tv":41995.35,"id":8858694}]}]}
{"op":"mcm","clk":"11911829333","pt":1724435781915,"mc":[{"id":"1.232184480","rc":[{"batb":[[0,3.15,4],[1,3.1,4],[2,3.05,4]],"ltp":3.2,"tv":41995.35,"id":8858694}]}]}
{"op":"mcm","clk":"11911829845","pt":1724435784498,"mc":[{"id":"1.232184480","rc":[{"batb":[[0,3.2,4],[1,3.15,4],[2,3.1,4]],"ltp":3.2,"tv":41995.35,"id":8858694}]}]}
{"op":"mcm","clk":"11911830319","pt":1724435786906,"mc":[{"id":"1.232184480","rc":[{"batb":[[0,3.15,4],[1,3.1,4],[2,3.05,4]],"ltp":3.2,"tv":41995.35,"id":8858694}]}]}
{"op":"mcm","clk":"11911831117","pt":1724435790853,"mc":[{"id":"1.232184480","rc":[{"batb":[[0,3.2,4],[1,3.15,4],[2,3.1,4]],"ltp":3.2,"tv":41995.35,"id":8858694}]}]}
{"op":"mcm","clk":"11911831610","pt":1724435793318,"mc":[{"id":"1.232184480","rc":[{"batb":[[0,3.15,4],[1,3.1,4],[2,3.05,4]],"ltp":3.2,"tv":41995.35,"id":8858694}]}]}
{"op":"mcm","clk":"11911833855","pt":1724435805230,"mc":[{"id":"1.232184480","rc":[{"batb":[[0,3.2,4],[1,3.15,4],[2,3.1,4]],"ltp":3.2,"tv":41995.35,"id":8858694}]}]}
{"op":"mcm","clk":"11911834287","pt":1724435807975,"mc":[{"id":"1.232184480","rc":[{"batb":[[0,3.15,4],[1,3.1,4],[2,3.05,4]],"ltp":3.2,"tv":41995.35,"id":8858694}]}]}
{"op":"mcm","clk":"11911835716","pt":1724435815781,"mc":[{"id":"1.232184480","rc":[{"batb":[[0,3.2,4],[1,3.15,4],[2,3.1,4]],"ltp":3.2,"tv":41995.35,"id":8858694}]}]}
{"op":"mcm","clk":"11911836182","pt":1724435818161,"mc":[{"id":"1.232184480","rc":[{"batb":[[0,3.15,4],[1,3.1,4],[2,3.05,4]],"ltp":3.2,"tv":41995.35,"id":8858694}]}]}
{"op":"mcm","clk":"11911838077","pt":1724435827716,"mc":[{"id":"1.232184480","rc":[{"batb":[[0,3.2,4],[1,3.15,4],[2,3.1,4]],"ltp":3.2,"tv":41995.35,"id":8858694}]}]}
{"op":"mcm","clk":"11911838546","pt":1724435830061,"mc":[{"id":"1.232184480","rc":[{"batb":[[0,3.15,4],[1,3.1,4],[2,3.05,4]],"ltp":3.2,"tv":41995.35,"id":8858694}]}]}
{"op":"mcm","clk":"11911840079","pt":1724435837898,"mc":[{"id":"1.232184480","rc":[{"batb":[[0,3.2,4],[1,3.15,4],[2,3.1,4]],"ltp":3.2,"tv":41995.35,"id":8858694}]}]}
{"op":"mcm","clk":"11911840470","pt":1724435840160,"mc":[{"id":"1.232184480","rc":[{"batb":[[0,3.15,4],[1,3.1,4],[2,3.05,4]],"ltp":3.2,"tv":41995.35,"id":8858694}]}]}
{"op":"mcm","clk":"11911840934","pt":1724435842777,"mc":[{"id":"1.232184480","rc":[{"batb":[[0,3.2,4],[1,3.15,4],[2,3.1,4]],"ltp":3.2,"tv":41995.35,"id":8858694}]}]}
{"op":"mcm","clk":"11911841344","pt":1724435845138,"mc":[{"id":"1.232184480","rc":[{"batb":[[0,3.15,4],[1,3.1,4],[2,3.05,4]],"ltp":3.2,"tv":41995.35,"id":8858694}]}]}
{"op":"mcm","clk":"11911842578","pt":1724435851949,"mc":[{"id":"1.232184480","rc":[{"batb":[[0,3.2,4],[1,3.15,4],[2,3.1,4]],"ltp":3.2,"tv":41995.35,"id":8858694}]}]}
{"op":"mcm","clk":"11911843053","pt":1724435854413,"mc":[{"id":"1.232184480","rc":[{"batb":[[0,3.15,4],[1,3.1,4],[2,3.05,4]],"ltp":3.2,"tv":41995.35,"id":8858694}]}]}
{"op":"mcm","clk":"11911844879","pt":1724435862906,"mc":[{"id":"1.232184480","rc":[{"batb":[[0,3.2,4],[1,3.15,4],[2,3.1,4]],"ltp":3.2,"tv":41995.35,"id":8858694}]}]}
{"op":"mcm","clk":"11911845332","pt":1724435865100,"mc":[{"id":"1.232184480","rc":[{"batb":[[0,3.15,4],[1,3.1,4],[2,3.05,4]],"ltp":3.2,"tv":41995.35,"id":8858694}]}]}
{"op":"mcm","clk":"11911846680","pt":1724435872323,"mc":[{"id":"1.232184480","rc":[{"batb":[[0,3.2,4],[1,3.15,4],[2,3.1,4]],"ltp":3.2,"tv":41995.35,"id":8858694}]}]}
{"op":"mcm","clk":"11911847086","pt":1724435874837,"mc":[{"id":"1.232184480","rc":[{"batb":[[0,3.15,4],[1,3.1,4],[2,3.05,4]],"ltp":3.2,"tv":41995.35,"id":8858694}]}]}
{"op":"mcm","clk":"11911847564","pt":1724435877612,"mc":[{"id":"1.232184480","rc":[{"batb":[[0,3.2,4],[1,3.15,4],[2,3.1,4]],"ltp":3.2,"tv":41995.35,"id":8858694}]}]}
{"op":"mcm","clk":"11911848036","pt":1724435880016,"mc":[{"id":"1.232184480","rc":[{"batb":[[0,3.15,4],[1,3.1,4],[2,3.05,4]],"ltp":3.2,"tv":41995.35,"id":8858694}]}]}
{"op":"mcm","clk":"11911848794","pt":1724435883749,"mc":[{"id":"1.232184480","rc":[{"batb":[[0,3.2,4],[1,3.15,4],[2,3.1,4]],"ltp":3.2,"tv":41995.35,"id":8858694}]}]}
{"op":"mcm","clk":"11911849355","pt":1724435886231,"mc":[{"id":"1.232184480","rc":[{"batb":[[0,3.15,4],[1,3.1,4],[2,3.05,4]],"ltp":3.2,"tv":41995.35,"id":8858694}]}]}
{"op":"mcm","clk":"11911849773","pt":1724435888440,"mc":[{"id":"1.232184480","rc":[{"batb":[[0,3.2,4],[1,3.15,4],[2,3.1,4]],"ltp":3.2,"tv":41995.35,"id":8858694}]}]}
{"op":"mcm","clk":"11911850296","pt":1724435890950,"mc":[{"id":"1.232184480","rc":[{"batb":[[0,3.15,4],[1,3.1,4],[2,3.05,4]],"ltp":3.2,"tv":41995.35,"id":8858694}]}]}
{"op":"mcm","clk":"11911850870","pt":1724435894081,"mc":[{"id":"1.232184480","rc":[{"batb":[[0,3.2,4],[1,3.15,4],[2,3.1,4]],"ltp":3.2,"tv":41995.35,"id":8858694}]}]}
{"op":"mcm","clk":"11911851345","pt":1724435896355,"mc":[{"id":"1.232184480","rc":[{"batb":[[0,3.15,4],[1,3.1,4],[2,3.05,4]],"ltp":3.2,"tv":41995.35,"id":8858694}]}]}
{"op":"mcm","clk":"11911852088","pt":1724435900354,"mc":[{"id":"1.232184480","rc":[{"batb":[[0,3.2,4],[1,3.15,4],[2,3.1,4]],"ltp":3.2,"tv":41995.35,"id":8858694}]}]}
{"op":"mcm","clk":"11911852566","pt":1724435902863,"mc":[{"id":"1.232184480","rc":[{"batb":[[0,3.15,4],[1,3.1,4],[2,3.05,4]],"ltp":3.2,"tv":41995.35,"id":8858694}]}]}
{"op":"mcm","clk":"11911853024","pt":1724435905374,"mc":[{"id":"1.232184480","rc":[{"batb":[[0,3.2,4],[1,3.15,4],[2,3.1,4]],"ltp":3.2,"tv":41995.35,"id":8858694}]}]}
{"op":"mcm","clk":"11911853497","pt":1724435907881,"mc":[{"id":"1.232184480","rc":[{"batb":[[0,3.15,4],[1,3.1,4],[2,3.05,4]],"ltp":3.2,"tv":41995.35,"id":8858694}]}]}
{"op":"mcm","clk":"11911854281","pt":1724435911981,"mc":[{"id":"1.232184480","rc":[{"batb":[[0,3.2,4],[1,3.15,4],[2,3.1,4]],"ltp":3.2,"tv":41995.35,"id":8858694}]}]}
{"op":"mcm","clk":"11911854683","pt":1724435914193,"mc":[{"id":"1.232184480","rc":[{"batb":[[0,3.15,4],[1,3.1,4],[2,3.05,4]],"ltp":3.2,"tv":41995.35,"id":8858694}]}]}
{"op":"mcm","clk":"11911855887","pt":1724435920590,"mc":[{"id":"1.232184480","rc":[{"batb":[[0,3.2,4],[1,3.15,4],[2,3.1,4]],"ltp":3.2,"tv":41995.35,"id":8858694}]}]}
{"op":"mcm","clk":"11911856277","pt":1724435922797,"mc":[{"id":"1.232184480","rc":[{"batb":[[0,3.15,4],[1,3.1,4],[2,3.05,4]],"ltp":3.2,"tv":41995.35,"id":8858694}]}]}
{"op":"mcm","clk":"11911856673","pt":1724435925204,"mc":[{"id":"1.232184480","rc":[{"batb":[[0,3.2,4],[1,3.15,4],[2,3.1,4]],"ltp":3.2,"tv":41995.35,"id":8858694}]}]}
{"op":"mcm","clk":"11911857086","pt":1724435927552,"mc":[{"id":"1.232184480","rc":[{"batb":[[0,3.15,4],[1,3.1,4],[2,3.05,4]],"ltp":3.2,"tv":41995.35,"id":8858694}]}]}
{"op":"mcm","clk":"11911857662","pt":1724435931386,"mc":[{"id":"1.232184480","rc":[{"batb":[[0,3.2,4],[1,3.15,4],[2,3.1,4]],"ltp":3.2,"tv":41995.35,"id":8858694}]}]}
{"op":"mcm","clk":"11911858162","pt":1724435934002,"mc":[{"id":"1.232184480","rc":[{"batb":[[0,3.15,4],[1,3.1,4],[2,3.05,4]],"ltp":3.2,"tv":41995.35,"id":8858694}]}]}
{"op":"mcm","clk":"11911859556","pt":1724435941505,"mc":[{"id":"1.232184480","rc":[{"batb":[[0,3.2,4],[1,3.15,4],[2,3.1,4]],"ltp":3.2,"tv":41995.35,"id":8858694}]}]}
{"op":"mcm","clk":"11911860136","pt":1724435944009,"mc":[{"id":"1.232184480","rc":[{"batb":[[0,3.15,4],[1,3.1,4],[2,3.05,4]],"ltp":3.2,"tv":41995.35,"id":8858694}]}]}
{"op":"mcm","clk":"11911861462","pt":1724435950520,"mc":[{"id":"1.232184480","rc":[{"batb":[[0,3.2,4],[1,3.15,4],[2,3.1,4]],"ltp":3.2,"tv":41995.35,"id":8858694}]}]}
{"op":"mcm","clk":"11911861998","pt":1724435953210,"mc":[{"id":"1.232184480","rc":[{"batb":[[0,3.15,4],[1,3.1,4],[2,3.05,4]],"ltp":3.2,"tv":41995.35,"id":8858694}]}]}
{"op":"mcm","clk":"11911862623","pt":1724435956413,"mc":[{"id":"1.232184480","rc":[{"batb":[[0,3.2,4],[1,3.15,4],[2,3.1,4]],"ltp":3.2,"tv":41995.35,"id":8858694}]}]}
{"op":"mcm","clk":"11911863072","pt":1724435958726,"mc":[{"id":"1.232184480","rc":[{"batb":[[0,3.15,4],[1,3.1,4],[2,3.05,4]],"ltp":3.2,"tv":41995.35,"id":8858694}]}]}
{"op":"mcm","clk":"11911863528","pt":1724435961129,"mc":[{"id":"1.232184480","rc":[{"batb":[[0,3.2,4],[1,3.15,4],[2,3.1,4]],"ltp":3.2,"tv":41995.35,"id":8858694}]}]}
{"op":"mcm","clk":"11911864043","pt":1724435963628,"mc":[{"id":"1.232184480","rc":[{"batb":[[0,3.15,4],[1,3.1,4],[2,3.05,4]],"ltp":3.2,"tv":41995.35,"id":8858694}]}]}
{"op":"mcm","clk":"11911864621","pt":1724435966851,"mc":[{"id":"1.232184480","rc":[{"batb":[[0,3.2,4],[1,3.15,4],[2,3.1,4]],"ltp":3.2,"tv":41995.35,"id":8858694}]}]}
{"op":"mcm","clk":"11911865053","pt":1724435969150,"mc":[{"id":"1.232184480","rc":[{"batb":[[0,3.15,4],[1,3.1,4],[2,3.05,4]],"ltp":3.2,"tv":41995.35,"id":8858694}]}]}
{"op":"mcm","clk":"11911866275","pt":1724435975441,"mc":[{"id":"1.232184480","rc":[{"batb":[[0,3.2,4],[1,3.15,4],[2,3.1,4]],"ltp":3.2,"tv":41995.35,"id":8858694}]}]}
{"op":"mcm","clk":"11911866683","pt":1724435977648,"mc":[{"id":"1.232184480","rc":[{"batb":[[0,3.15,4],[1,3.1,4],[2,3.05,4]],"ltp":3.2,"tv":41995.35,"id":8858694}]}]}
{"op":"mcm","clk":"11911869180","pt":1724435991334,"mc":[{"id":"1.232184480","rc":[{"batb":[[0,3.2,4],[1,3.15,4],[2,3.1,4]],"ltp":3.2,"tv":41995.35,"id":8858694}]}]}
{"op":"mcm","clk":"11911869704","pt":1724435993950,"mc":[{"id":"1.232184480","rc":[{"batb":[[0,3.15,4],[1,3.1,4],[2,3.05,4]],"ltp":3.2,"tv":41995.35,"id":8858694}]}]}
{"op":"mcm","clk":"11911871363","pt":1724436002038,"mc":[{"id":"1.232184480","rc":[{"batb":[[0,3.2,4],[1,3.15,4],[2,3.1,4]],"ltp":3.2,"tv":41995.35,"id":8858694}]}]}
{"op":"mcm","clk":"11911871995","pt":1724436004341,"mc":[{"id":"1.232184480","rc":[{"trd":[[1.46,34336.57],[1.47,42.44]],"batb":[[1,1.08,216.76],[2,1.07,7.57]],"batl":[[0,1.46,37.53],[2,1.48,14.76]],"ltp":1.45,"tv":34436.91,"id":247649},{"trd":[[3.05,5442.03],[3.1,645.85],[3.15,21504.88],[3.2,14332.94]],"batb":[[0,3.15,4],[1,3.1,4],[2,3.05,4]],"batl":[[1,7,1.51],[2,11,1.51]],"ltp":3.2,"tv":41925.69,"id":8858694}],"tv":76362.61}]}
{"op":"mcm","clk":"11911873127","pt":1724436008852,"mc":[{"id":"1.232184480","rc":[{"batb":[[0,3.2,4],[1,3.15,4],[2,3.1,4]],"ltp":3.2,"tv":41925.69,"id":8858694}]}]}
{"op":"mcm","clk":"11911873790","pt":1724436011348,"mc":[{"id":"1.232184480","rc":[{"batb":[[0,3.15,4],[1,3.1,4],[2,3.05,4]],"ltp":3.2,"tv":41925.69,"id":8858694}]}]}
{"op":"mcm","clk":"11911875375","pt":1724436018714,"mc":[{"id":"1.232184480","rc":[{"batb":[[0,3.2,4],[1,3.15,4],[2,3.1,4]],"ltp":3.2,"tv":41925.69,"id":8858694}]}]}
{"op":"mcm","clk":"11911875863","pt":1724436020867,"mc":[{"id":"1.232184480","rc":[{"batb":[[0,3.15,4],[1,3.1,4],[2,3.05,4]],"ltp":3.2,"tv":41925.69,"id":8858694}]}]}
{"op":"mcm","clk":"11911876798","pt":1724436025136,"mc":[{"id":"1.232184480","rc":[{"batb":[[0,3.2,4],[1,3.15,4],[2,3.1,4]],"ltp":3.2,"tv":41925.69,"id":8858694}]}]}
{"op":"mcm","clk":"11911877373","pt":1724436027638,"mc":[{"id":"1.232184480","rc":[{"batb":[[0,3.15,4],[1,3.1,4],[2,3.05,4]],"ltp":3.2,"tv":41925.69,"id":8858694}]}]}
{"op":"mcm","clk":"11911879054","pt":1724436035459,"mc":[{"id":"1.232184480","rc":[{"batb":[[0,3.2,4],[1,3.15,4],[2,3.1,4]],"ltp":3.2,"tv":41925.69,"id":8858694}]}]}
{"op":"mcm","clk":"11911879606","pt":1724436037963,"mc":[{"id":"1.232184480","rc":[{"batb":[[0,3.15,4],[1,3.1,4],[2,3.05,4]],"ltp":3.2,"tv":41925.69,"id":8858694}]}]}
{"op":"mcm","clk":"11911880087","pt":1724436040175,"mc":[{"id":"1.232184480","rc":[{"batb":[[0,3.2,4],[1,3.15,4],[2,3.1,4]],"ltp":3.2,"tv":41925.69,"id":8858694}]}]}
{"op":"mcm","clk":"11911880655","pt":1724436042653,"mc":[{"id":"1.232184480","rc":[{"batb":[[0,3.15,4],[1,3.1,4],[2,3.05,4]],"ltp":3.2,"tv":41925.69,"id":8858694}]}]}
{"op":"mcm","clk":"11911881882","pt":1724436048365,"mc":[{"id":"1.232184480","rc":[{"batb":[[0,3.2,4],[1,3.15,4],[2,3.1,4]],"ltp":3.2,"tv":41925.69,"id":8858694}]}]}
{"op":"mcm","clk":"11911882439","pt":1724436050858,"mc":[{"id":"1.232184480","rc":[{"batb":[[0,3.15,4],[1,3.1,4],[2,3.05,4]],"ltp":3.2,"tv":41925.69,"id":8858694}]}]}
{"op":"mcm","clk":"11911882931","pt":1724436053177,"mc":[{"id":"1.232184480","rc":[{"batb":[[0,3.2,4],[1,3.15,4],[2,3.1,4]],"ltp":3.2,"tv":41925.69,"id":8858694}]}]}
{"op":"mcm","clk":"11911883431","pt":1724436055570,"mc":[{"id":"1.232184480","rc":[{"batb":[[0,3.15,4],[1,3.1,4],[2,3.05,4]],"ltp":3.2,"tv":41925.69,"id":8858694}]}]}
{"op":"mcm","clk":"11911884228","pt":1724436059302,"mc":[{"id":"1.232184480","rc":[{"batb":[[0,3.2,4],[1,3.15,4],[2,3.1,4]],"ltp":3.2,"tv":41925.69,"id":8858694}]}]}
{"op":"mcm","clk":"11911884738","pt":1724436061822,"mc":[{"id":"1.232184480","rc":[{"batb":[[0,3.15,4],[1,3.1,4],[2,3.05,4]],"ltp":3.2,"tv":41925.69,"id":8858694}]}]}
{"op":"mcm","clk":"11911886087","pt":1724436068092,"mc":[{"id":"1.232184480","rc":[{"batb":[[0,3.2,4],[1,3.15,4],[2,3.1,4]],"ltp":3.2,"tv":41925.69,"id":8858694}]}]}
{"op":"mcm","clk":"11911886604","pt":1724436070402,"mc":[{"id":"1.232184480","rc":[{"batb":[[0,3.15,4],[1,3.1,4],[2,3.05,4]],"ltp":3.2,"tv":41925.69,"id":8858694}]}]}
{"op":"mcm","clk":"11911888556","pt":1724436078716,"mc":[{"id":"1.232184480","rc":[{"batb":[[0,3.2,4],[1,3.15,4],[2,3.1,4]],"ltp":3.2,"tv":41925.69,"id":8858694}]}]}
{"op":"mcm","clk":"11911889033","pt":1724436081110,"mc":[{"id":"1.232184480","rc":[{"batb":[[0,3.15,4],[1,3.1,4],[2,3.05,4]],"ltp":3.2,"tv":41925.69,"id":8858694}]}]}
{"op":"mcm","clk":"11911889971","pt":1724436085244,"mc":[{"id":"1.232184480","rc":[{"batb":[[0,3.2,4],[1,3.15,4],[2,3.1,4]],"ltp":3.2,"tv":41925.69,"id":8858694}]}]}
{"op":"mcm","clk":"11911890553","pt":1724436087704,"mc":[{"id":"1.232184480","rc":[{"batb":[[0,3.15,4],[1,3.1,4],[2,3.05,4]],"ltp":3.2,"tv":41925.69,"id":8858694}]}]}
{"op":"mcm","clk":"11911891194","pt":1724436090625,"mc":[{"id":"1.232184480","rc":[{"batb":[[0,3.2,4],[1,3.15,4],[2,3.1,4]],"ltp":3.2,"tv":41925.69,"id":8858694}]}]}
{"op":"mcm","clk":"11911891736","pt":1724436093028,"mc":[{"id":"1.232184480","rc":[{"batb":[[0,3.15,4],[1,3.1,4],[2,3.05,4]],"ltp":3.2,"tv":41925.69,"id":8858694}]}]}
{"op":"mcm","clk":"11911892796","pt":1724436097516,"mc":[{"id":"1.232184480","rc":[{"batb":[[0,3.2,4],[1,3.15,4],[2,3.1,4]],"ltp":3.2,"tv":41925.69,"id":8858694}]}]}
{"op":"mcm","clk":"11911893371","pt":1724436099921,"mc":[{"id":"1.232184480","rc":[{"batb":[[0,3.15,4],[1,3.1,4],[2,3.05,4]],"ltp":3.2,"tv":41925.69,"id":8858694}]}]}
{"op":"mcm","clk":"11911895062","pt":1724436106949,"mc":[{"id":"1.232184480","rc":[{"batb":[[0,3.2,4],[1,3.15,4],[2,3.1,4]],"ltp":3.2,"tv":41925.69,"id":8858694}]}]}
{"op":"mcm","clk":"11911895654","pt":1724436109370,"mc":[{"id":"1.232184480","rc":[{"batb":[[0,3.15,4],[1,3.1,4],[2,3.05,4]],"ltp":3.2,"tv":41925.69,"id":8858694}]}]}
{"op":"mcm","clk":"11911897121","pt":1724436115463,"mc":[{"id":"1.232184480","rc":[{"batb":[[0,3.2,4],[1,3.15,4],[2,3.1,4]],"ltp":3.2,"tv":41925.69,"id":8858694}]}]}
{"op":"mcm","clk":"11911897692","pt":1724436117793,"mc":[{"id":"1.232184480","rc":[{"batb":[[0,3.15,4],[1,3.1,4],[2,3.05,4]],"ltp":3.2,"tv":41925.69,"id":8858694}]}]}
{"op":"mcm","clk":"11911898248","pt":1724436120048,"mc":[{"id":"1.232184480","rc":[{"batb":[[0,3.2,4],[1,3.15,4],[2,3.1,4]],"ltp":3.2,"tv":41925.69,"id":8858694}]}]}
{"op":"mcm","clk":"11911898847","pt":1724436122476,"mc":[{"id":"1.232184480","rc":[{"batb":[[0,3.15,4],[1,3.1,4],[2,3.05,4]],"ltp":3.2,"tv":41925.69,"id":8858694}]}]}
{"op":"mcm","clk":"11911899573","pt":1724436125087,"mc":[{"id":"1.232184480","rc":[{"batb":[[0,3.2,4],[1,3.15,4],[2,3.1,4]],"ltp":3.2,"tv":41925.69,"id":8858694}]}]}
{"op":"mcm","clk":"11911900147","pt":1724436127403,"mc":[{"id":"1.232184480","rc":[{"batb":[[0,3.15,4],[1,3.1,4],[2,3.05,4]],"ltp":3.2,"tv":41925.69,"id":8858694}]}]}
{"op":"mcm","clk":"11911901943","pt":1724436134723,"mc":[{"id":"1.232184480","rc":[{"batb":[[0,3.2,4],[1,3.15,4],[2,3.1,4]],"ltp":3.2,"tv":41925.69,"id":8858694}]}]}
{"op":"mcm","clk":"11911902565","pt":1724436137199,"mc":[{"id":"1.232184480","rc":[{"batb":[[0,3.15,4],[1,3.1,4],[2,3.05,4]],"ltp":3.2,"tv":41925.69,"id":8858694}]}]}
{"op":"mcm","clk":"11911903654","pt":1724436141439,"mc":[{"id":"1.232184480","rc":[{"batb":[[0,3.2,4],[1,3.15,4],[2,3.1,4]],"ltp":3.2,"tv":41925.69,"id":8858694}]}]}
{"op":"mcm","clk":"11911904335","pt":1724436144228,"mc":[{"id":"1.232184480","rc":[{"batb":[[0,3.15,4],[1,3.1,4],[2,3.05,4]],"ltp":3.2,"tv":41925.69,"id":8858694}]}]}
{"op":"mcm","clk":"11911904926","pt":1724436146494,"mc":[{"id":"1.232184480","rc":[{"batb":[[0,3.2,4],[1,3.15,4],[2,3.1,4]],"ltp":3.2,"tv":41925.69,"id":8858694}]}]}
{"op":"mcm","clk":"11911905562","pt":1724436149033,"mc":[{"id":"1.232184480","rc":[{"batb":[[0,3.15,4],[1,3.1,4],[2,3.05,4]],"ltp":3.2,"tv":41925.69,"id":8858694}]}]}
{"op":"mcm","clk":"11911907356","pt":1724436155941,"mc":[{"id":"1.232184480","rc":[{"batb":[[0,3.2,4],[1,3.15,4],[2,3.1,4]],"ltp":3.2,"tv":41925.69,"id":8858694}]}]}
{"op":"mcm","clk":"11911907896","pt":1724436158296,"mc":[{"id":"1.232184480","rc":[{"batb":[[0,3.15,4],[1,3.1,4],[2,3.05,4]],"ltp":3.2,"tv":41925.69,"id":8858694}]}]}
{"op":"mcm","clk":"11911909612","pt":1724436164883,"mc":[{"id":"1.232184480","rc":[{"batb":[[0,3.2,4],[1,3.15,4],[2,3.1,4]],"ltp":3.2,"tv":41925.69,"id":8858694}]}]}
{"op":"mcm","clk":"11911910217","pt":1724436167152,"mc":[{"id":"1.232184480","rc":[{"batb":[[0,3.15,4],[1,3.1,4],[2,3.05,4]],"ltp":3.2,"tv":41925.69,"id":8858694}]}]}
{"op":"mcm","clk":"11911912226","pt":1724436174784,"mc":[{"id":"1.232184480","rc":[{"batb":[[0,3.2,4],[1,3.15,4],[2,3.1,4]],"ltp":3.2,"tv":41925.69,"id":8858694}]}]}
{"op":"mcm","clk":"11911912817","pt":1724436177228,"mc":[{"id":"1.232184480","rc":[{"batb":[[0,3.15,4],[1,3.1,4],[2,3.05,4]],"ltp":3.2,"tv":41925.69,"id":8858694}]}]}
{"op":"mcm","clk":"11911913456","pt":1724436179777,"mc":[{"id":"1.232184480","rc":[{"batb":[[0,3.2,4],[1,3.15,4],[2,3.1,4]],"ltp":3.2,"tv":41925.69,"id":8858694}]}]}
{"op":"mcm","clk":"11911914200","pt":1724436182605,"mc":[{"id":"1.232184480","rc":[{"batb":[[0,3.15,4],[1,3.1,4],[2,3.05,4]],"ltp":3.2,"tv":41925.69,"id":8858694}]}]}
{"op":"mcm","clk":"11911915103","pt":1724436185910,"mc":[{"id":"1.232184480","rc":[{"batb":[[0,3.2,4],[1,3.15,4],[2,3.1,4]],"ltp":3.2,"tv":41925.69,"id":8858694}]}]}
{"op":"mcm","clk":"11911915786","pt":1724436188527,"mc":[{"id":"1.232184480","rc":[{"batb":[[0,3.15,4],[1,3.1,4],[2,3.05,4]],"ltp":3.2,"tv":41925.69,"id":8858694}]}]}
{"op":"mcm","clk":"11911917697","pt":1724436195592,"mc":[{"id":"1.232184480","rc":[{"batb":[[0,3.2,4],[1,3.15,4],[2,3.1,4]],"ltp":3.2,"tv":41925.69,"id":8858694}]}]}
{"op":"mcm","clk":"11911918309","pt":1724436197910,"mc":[{"id":"1.232184480","rc":[{"batb":[[0,3.15,4],[1,3.1,4],[2,3.05,4]],"ltp":3.2,"tv":41925.69,"id":8858694}]}]}
{"op":"mcm","clk":"11911923984","pt":1724436219771,"mc":[{"id":"1.232184480","rc":[{"batb":[[0,3.2,4],[1,3.15,4],[2,3.1,4]],"ltp":3.2,"tv":41925.69,"id":8858694}]}]}
{"op":"mcm","clk":"11911924687","pt":1724436222343,"mc":[{"id":"1.232184480","rc":[{"batb":[[0,3.15,4],[1,3.1,4],[2,3.05,4]],"ltp":3.2,"tv":41925.69,"id":8858694}]}]}
{"op":"mcm","clk":"11911927577","pt":1724436233398,"mc":[{"id":"1.232184480","rc":[{"batb":[[0,3.2,4],[1,3.15,4],[2,3.1,4]],"ltp":3.2,"tv":41925.69,"id":8858694}]}]}
{"op":"mcm","clk":"11911928212","pt":1724436235812,"mc":[{"id":"1.232184480","rc":[{"batb":[[0,3.15,4],[1,3.1,4],[2,3.05,4]],"ltp":3.2,"tv":41925.69,"id":8858694}]}]}
{"op":"mcm","clk":"11911930520","pt":1724436244521,"mc":[{"id":"1.232184480","rc":[{"batb":[[0,3.2,4],[1,3.15,4],[2,3.1,4]],"ltp":3.2,"tv":41925.69,"id":8858694}]}]}
{"op":"mcm","clk":"11911931234","pt":1724436247107,"mc":[{"id":"1.232184480","rc":[{"batb":[[0,3.15,4],[1,3.1,4],[2,3.05,4]],"ltp":3.2,"tv":41925.69,"id":8858694}]}]}
{"op":"mcm","clk":"11911932108","pt":1724436250202,"mc":[{"id":"1.232184480","rc":[{"batb":[[0,3.2,4],[1,3.15,4],[2,3.1,4]],"ltp":3.2,"tv":41925.69,"id":8858694}]}]}
{"op":"mcm","clk":"11911932770","pt":1724436252527,"mc":[{"id":"1.232184480","rc":[{"batb":[[0,3.15,4],[1,3.1,4],[2,3.05,4]],"ltp":3.2,"tv":41925.69,"id":8858694}]}]}
{"op":"mcm","clk":"11911936966","pt":1724436268033,"mc":[{"id":"1.232184480","rc":[{"batb":[[0,3.2,4],[1,3.15,4],[2,3.1,4]],"ltp":3.2,"tv":41925.69,"id":8858694}]}]}
{"op":"mcm","clk":"11911937597","pt":1724436270446,"mc":[{"id":"1.232184480","rc":[{"batb":[[0,3.15,4],[1,3.1,4],[2,3.05,4]],"ltp":3.2,"tv":41925.69,"id":8858694}]}]}
{"op":"mcm","clk":"11911939397","pt":1724436276868,"mc":[{"id":"1.232184480","rc":[{"batb":[[0,3.2,4],[1,3.15,4],[2,3.1,4]],"ltp":3.2,"tv":41925.69,"id":8858694}]}]}
{"op":"mcm","clk":"11911940064","pt":1724436279366,"mc":[{"id":"1.232184480","rc":[{"batb":[[0,3.15,4],[1,3.1,4],[2,3.05,4]],"ltp":3.2,"tv":41925.69,"id":8858694}]}]}
{"op":"mcm","clk":"11911940723","pt":1724436281961,"mc":[{"id":"1.232184480","rc":[{"batb":[[0,3.2,4],[1,3.15,4],[2,3.1,4]],"ltp":3.2,"tv":41925.69,"id":8858694}]}]}
{"op":"mcm","clk":"11911941323","pt":1724436284258,"mc":[{"id":"1.232184480","rc":[{"batb":[[0,3.15,4],[1,3.1,4],[2,3.05,4]],"ltp":3.2,"tv":41925.69,"id":8858694}]}]}
{"op":"mcm","clk":"11911942447","pt":1724436288348,"mc":[{"id":"1.232184480","rc":[{"batb":[[0,3.2,4],[1,3.15,4],[2,3.1,4]],"ltp":3.2,"tv":41925.69,"id":8858694}]}]}
{"op":"mcm","clk":"11911943059","pt":1724436290791,"mc":[{"id":"1.232184480","rc":[{"batb":[[0,3.15,4],[1,3.1,4],[2,3.05,4]],"ltp":3.2,"tv":41925.69,"id":8858694}]}]}
{"op":"mcm","clk":"11911944664","pt":1724436296569,"mc":[{"id":"1.232184480","rc":[{"batb":[[0,3.2,4],[1,3.15,4],[2,3.1,4]],"ltp":3.2,"tv":41925.69,"id":8858694}]}]}
{"op":"mcm","clk":"11911945331","pt":1724436299270,"mc":[{"id":"1.232184480","rc":[{"batb":[[0,3.15,4],[1,3.1,4],[2,3.05,4]],"ltp":3.2,"tv":41925.69,"id":8858694}]}]}
{"op":"mcm","clk":"11911946065","pt":1724436301993,"mc":[{"id":"1.232184480","rc":[{"batb":[[0,3.2,4],[1,3.15,4],[2,3.1,4]],"ltp":3.2,"tv":41925.69,"id":8858694}]}]}
{"op":"mcm","clk":"11911946719","pt":1724436304417,"mc":[{"id":"1.232184480","rc":[{"batb":[[0,3.15,4],[1,3.1,4],[2,3.05,4]],"ltp":3.2,"tv":41925.69,"id":8858694}]}]}
{"op":"mcm","clk":"11911947632","pt":1724436307708,"mc":[{"id":"1.232184480","rc":[{"batb":[[0,3.2,4],[1,3.15,4],[2,3.1,4]],"ltp":3.2,"tv":41925.69,"id":8858694}]}]}
{"op":"mcm","clk":"11911948303","pt":1724436310128,"mc":[{"id":"1.232184480","rc":[{"batb":[[0,3.15,4],[1,3.1,4],[2,3.05,4]],"ltp":3.2,"tv":41925.69,"id":8858694}]}]}
{"op":"mcm","clk":"11911949408","pt":1724436314118,"mc":[{"id":"1.232184480","rc":[{"batb":[[0,3.2,4],[1,3.15,4],[2,3.1,4]],"ltp":3.2,"tv":41925.69,"id":8858694}]}]}
{"op":"mcm","clk":"11911950046","pt":1724436316630,"mc":[{"id":"1.232184480","rc":[{"batb":[[0,3.15,4],[1,3.1,4],[2,3.05,4]],"ltp":3.2,"tv":41925.69,"id":8858694}]}]}
{"op":"mcm","clk":"11911952183","pt":1724436324634,"mc":[{"id":"1.232184480","rc":[{"batb":[[0,3.2,4],[1,3.15,4],[2,3.1,4]],"ltp":3.2,"tv":41925.69,"id":8858694}]}]}
{"op":"mcm","clk":"11911952858","pt":1724436327153,"mc":[{"id":"1.232184480","rc":[{"batb":[[0,3.15,4],[1,3.1,4],[2,3.05,4]],"ltp":3.2,"tv":41925.69,"id":8858694}]}]}
{"op":"mcm","clk":"11911954864","pt":1724436334147,"mc":[{"id":"1.232184480","rc":[{"batb":[[0,3.2,4],[1,3.15,4],[2,3.1,4]],"ltp":3.2,"tv":41925.69,"id":8858694}]}]}
{"op":"mcm","clk":"11911955501","pt":1724436336398,"mc":[{"id":"1.232184480","rc":[{"batb":[[0,3.15,4],[1,3.1,4],[2,3.05,4]],"ltp":3.2,"tv":41925.69,"id":8858694}]}]}
{"op":"mcm","clk":"11911957436","pt":1724436343692,"mc":[{"id":"1.232184480","rc":[{"batb":[[0,3.2,4],[1,3.15,4],[2,3.1,4]],"ltp":3.2,"tv":41925.69,"id":8858694}]}]}
{"op":"mcm","clk":"11911958020","pt":1724436346106,"mc":[{"id":"1.232184480","rc":[{"batb":[[0,3.15,4],[1,3.1,4],[2,3.05,4]],"ltp":3.2,"tv":41925.69,"id":8858694}]}]}
{"op":"mcm","clk":"11911959047","pt":1724436349922,"mc":[{"id":"1.232184480","rc":[{"batb":[[0,3.2,4],[1,3.15,4],[2,3.1,4]],"ltp":3.2,"tv":41925.69,"id":8858694}]}]}
{"op":"mcm","clk":"11911959658","pt":1724436352312,"mc":[{"id":"1.232184480","rc":[{"batb":[[0,3.15,4],[1,3.1,4],[2,3.05,4]],"ltp":3.2,"tv":41925.69,"id":8858694}]}]}
{"op":"mcm","clk":"11911967067","pt":1724436378913,"mc":[{"id":"1.232184480","rc":[{"batb":[[0,3.2,4],[1,3.15,4],[2,3.1,4]],"ltp":3.2,"tv":41925.69,"id":8858694}]}]}
{"op":"mcm","clk":"11911967720","pt":1724436381419,"mc":[{"id":"1.232184480","rc":[{"batb":[[0,3.15,4],[1,3.1,4],[2,3.05,4]],"ltp":3.2,"tv":41925.69,"id":8858694}]}]}
{"op":"mcm","clk":"11911969483","pt":1724436387885,"mc":[{"id":"1.232184480","rc":[{"batb":[[0,3.2,4],[1,3.15,4],[2,3.1,4]],"ltp":3.2,"tv":41925.69,"id":8858694}]}]}
{"op":"mcm","clk":"11911970114","pt":1724436390380,"mc":[{"id":"1.232184480","rc":[{"batb":[[0,3.15,4],[1,3.1,4],[2,3.05,4]],"ltp":3.2,"tv":41925.69,"id":8858694}]}]}
{"op":"mcm","clk":"11911971098","pt":1724436394201,"mc":[{"id":"1.232184480","rc":[{"batb":[[0,3.2,4],[1,3.15,4],[2,3.1,4]],"ltp":3.2,"tv":41925.69,"id":8858694}]}]}
{"op":"mcm","clk":"11911971693","pt":1724436396630,"mc":[{"id":"1.232184480","rc":[{"batb":[[0,3.15,4],[1,3.1,4],[2,3.05,4]],"ltp":3.2,"tv":41925.69,"id":8858694}]}]}
{"op":"mcm","clk":"11911972299","pt":1724436398930,"mc":[{"id":"1.232184480","rc":[{"batb":[[0,3.2,4],[1,3.15,4],[2,3.1,4]],"ltp":3.2,"tv":41925.69,"id":8858694}]}]}
{"op":"mcm","clk":"11911972953","pt":1724436401435,"mc":[{"id":"1.232184480","rc":[{"batb":[[0,3.15,4],[1,3.1,4],[2,3.05,4]],"ltp":3.2,"tv":41925.69,"id":8858694}]}]}
{"op":"mcm","clk":"11911973923","pt":1724436405229,"mc":[{"id":"1.232184480","rc":[{"batb":[[0,3.2,4],[1,3.15,4],[2,3.1,4]],"ltp":3.2,"tv":41925.69,"id":8858694}]}]}
{"op":"mcm","clk":"11911974623","pt":1724436407842,"mc":[{"id":"1.232184480","rc":[{"batb":[[0,3.15,4],[1,3.1,4],[2,3.05,4]],"ltp":3.2,"tv":41925.69,"id":8858694}]}]}
{"op":"mcm","clk":"11911975463","pt":1724436410927,"mc":[{"id":"1.232184480","rc":[{"batb":[[0,3.2,4],[1,3.15,4],[2,3.1,4]],"ltp":3.2,"tv":41925.69,"id":8858694}]}]}
{"op":"mcm","clk":"11911976154","pt":1724436413345,"mc":[{"id":"1.232184480","rc":[{"batb":[[0,3.15,4],[1,3.1,4],[2,3.05,4]],"ltp":3.2,"tv":41925.69,"id":8858694}]}]}
{"op":"mcm","clk":"11911978959","pt":1724436423398,"mc":[{"id":"1.232184480","rc":[{"batb":[[0,3.2,4],[1,3.15,4],[2,3.1,4]],"ltp":3.2,"tv":41925.69,"id":8858694}]}]}
{"op":"mcm","clk":"11911979875","pt":1724436426678,"mc":[{"id":"1.232184480","rc":[{"batb":[[0,3.15,4],[1,3.1,4],[2,3.05,4]],"ltp":3.2,"tv":41925.69,"id":8858694}]}]}
{"op":"mcm","clk":"11911980774","pt":1724436430011,"mc":[{"id":"1.232184480","rc":[{"batb":[[0,3.2,4],[1,3.15,4],[2,3.1,4]],"ltp":3.2,"tv":41925.69,"id":8858694}]}]}
{"op":"mcm","clk":"11911981490","pt":1724436432604,"mc":[{"id":"1.232184480","rc":[{"batb":[[0,3.15,4],[1,3.1,4],[2,3.05,4]],"ltp":3.2,"tv":41925.69,"id":8858694}]}]}
{"op":"mcm","clk":"11911983854","pt":1724436441031,"mc":[{"id":"1.232184480","rc":[{"batb":[[0,3.2,4],[1,3.15,4],[2,3.1,4]],"ltp":3.2,"tv":41925.69,"id":8858694}]}]}
{"op":"mcm","clk":"11911984526","pt":1724436443449,"mc":[{"id":"1.232184480","rc":[{"batb":[[0,3.15,4],[1,3.1,4],[2,3.05,4]],"ltp":3.2,"tv":41925.69,"id":8858694}]}]}
{"op":"mcm","clk":"11911986217","pt":1724436449556,"mc":[{"id":"1.232184480","rc":[{"batb":[[0,3.2,4],[1,3.15,4],[2,3.1,4]],"ltp":3.2,"tv":41925.69,"id":8858694}]}]}
{"op":"mcm","clk":"11911986858","pt":1724436451967,"mc":[{"id":"1.232184480","rc":[{"batb":[[0,3.15,4],[1,3.1,4],[2,3.05,4]],"ltp":3.2,"tv":41925.69,"id":8858694}]}]}
{"op":"mcm","clk":"11911987638","pt":1724436454863,"mc":[{"id":"1.232184480","rc":[{"batb":[[0,3.2,4],[1,3.15,4],[2,3.1,4]],"ltp":3.2,"tv":41925.69,"id":8858694}]}]}
{"op":"mcm","clk":"11911988311","pt":1724436457137,"mc":[{"id":"1.232184480","rc":[{"batb":[[0,3.15,4],[1,3.1,4],[2,3.05,4]],"ltp":3.2,"tv":41925.69,"id":8858694}]}]}
{"op":"mcm","clk":"11911990266","pt":1724436464052,"mc":[{"id":"1.232184480","rc":[{"batb":[[0,3.2,4],[1,3.15,4],[2,3.1,4]],"ltp":3.2,"tv":41925.69,"id":8858694}]}]}
{"op":"mcm","clk":"11911990903","pt":1724436466401,"mc":[{"id":"1.232184480","rc":[{"batb":[[0,3.15,4],[1,3.1,4],[2,3.05,4]],"ltp":3.2,"tv":41925.69,"id":8858694}]}]}
{"op":"mcm","clk":"11911991603","pt":1724436468995,"mc":[{"id":"1.232184480","rc":[{"batb":[[0,3.2,4],[1,3.15,4],[2,3.1,4]],"ltp":3.2,"tv":41925.69,"id":8858694}]}]}
{"op":"mcm","clk":"11911992209","pt":1724436471259,"mc":[{"id":"1.232184480","rc":[{"batb":[[0,3.15,4],[1,3.1,4],[2,3.05,4]],"ltp":3.2,"tv":41925.69,"id":8858694}]}]}
{"op":"mcm","clk":"11911994708","pt":1724436479695,"mc":[{"id":"1.232184480","rc":[{"batb":[[0,3.2,4],[1,3.15,4],[2,3.1,4]],"ltp":3.2,"tv":41925.69,"id":8858694}]}]}
{"op":"mcm","clk":"11911995339","pt":1724436481966,"mc":[{"id":"1.232184480","rc":[{"batb":[[0,3.15,4],[1,3.1,4],[2,3.05,4]],"ltp":3.2,"tv":41925.69,"id":8858694}]}]}
{"op":"mcm","clk":"11911997017","pt":1724436488187,"mc":[{"id":"1.232184480","rc":[{"batb":[[0,3.2,4],[1,3.15,4],[2,3.1,4]],"ltp":3.2,"tv":41925.69,"id":8858694}]}]}
{"op":"mcm","clk":"11911997659","pt":1724436490471,"mc":[{"id":"1.232184480","rc":[{"batb":[[0,3.15,4],[1,3.1,4],[2,3.05,4]],"ltp":3.2,"tv":41925.69,"id":8858694}]}]}
{"op":"mcm","clk":"11911998229","pt":1724436492799,"mc":[{"id":"1.232184480","rc":[{"batb":[[0,3.2,4],[1,3.15,4],[2,3.1,4]],"ltp":3.2,"tv":41925.69,"id":8858694}]}]}
{"op":"mcm","clk":"11911998837","pt":1724436495085,"mc":[{"id":"1.232184480","rc":[{"batb":[[0,3.15,4],[1,3.1,4],[2,3.05,4]],"ltp":3.2,"tv":41925.69,"id":8858694}]}]}
{"op":"mcm","clk":"11912000763","pt":1724436502493,"mc":[{"id":"1.232184480","rc":[{"batb":[[0,3.2,4],[1,3.15,4],[2,3.1,4]],"ltp":3.2,"tv":41925.69,"id":8858694}]}]}
{"op":"mcm","clk":"11912001388","pt":1724436504788,"mc":[{"id":"1.232184480","rc":[{"batb":[[0,3.15,4],[1,3.1,4],[2,3.05,4]],"ltp":3.2,"tv":41925.69,"id":8858694}]}]}
{"op":"mcm","clk":"11912002460","pt":1724436509231,"mc":[{"id":"1.232184480","rc":[{"batb":[[0,3.2,4],[1,3.15,4],[2,3.1,4]],"ltp":3.2,"tv":41925.69,"id":8858694}]}]}
{"op":"mcm","clk":"11912003080","pt":1724436511688,"mc":[{"id":"1.232184480","rc":[{"batb":[[0,3.15,4],[1,3.1,4],[2,3.05,4]],"ltp":3.2,"tv":41925.69,"id":8858694}]}]}
{"op":"mcm","clk":"11912004025","pt":1724436515224,"mc":[{"id":"1.232184480","rc":[{"batb":[[0,3.2,4],[1,3.15,4],[2,3.1,4]],"ltp":3.2,"tv":41925.69,"id":8858694}]}]}
{"op":"mcm","clk":"11912004640","pt":1724436517488,"mc":[{"id":"1.232184480","rc":[{"batb":[[0,3.15,4],[1,3.1,4],[2,3.05,4]],"ltp":3.2,"tv":41925.69,"id":8858694}]}]}
{"op":"mcm","clk":"11912005332","pt":1724436519992,"mc":[{"id":"1.232184480","rc":[{"batb":[[0,3.2,4],[1,3.15,4],[2,3.1,4]],"ltp":3.2,"tv":41925.69,"id":8858694}]}]}
{"op":"mcm","clk":"11912005969","pt":1724436522486,"mc":[{"id":"1.232184480","rc":[{"batb":[[0,3.15,4],[1,3.1,4],[2,3.05,4]],"ltp":3.2,"tv":41925.69,"id":8858694}]}]}
{"op":"mcm","clk":"11912007323","pt":1724436527548,"mc":[{"id":"1.232184480","rc":[{"batb":[[0,3.2,4],[1,3.15,4],[2,3.1,4]],"ltp":3.2,"tv":41925.69,"id":8858694}]}]}
{"op":"mcm","clk":"11912007977","pt":1724436529847,"mc":[{"id":"1.232184480","rc":[{"batb":[[0,3.15,4],[1,3.1,4],[2,3.05,4]],"ltp":3.2,"tv":41925.69,"id":8858694}]}]}
{"op":"mcm","clk":"11912008657","pt":1724436532223,"mc":[{"id":"1.232184480","rc":[{"batb":[[0,3.2,4],[1,3.15,4],[2,3.1,4]],"ltp":3.2,"tv":41925.69,"id":8858694}]}]}
{"op":"mcm","clk":"11912009321","pt":1724436534657,"mc":[{"id":"1.232184480","rc":[{"batb":[[0,3.15,4],[1,3.1,4],[2,3.05,4]],"ltp":3.2,"tv":41925.69,"id":8858694}]}]}
{"op":"mcm","clk":"11912010421","pt":1724436538739,"mc":[{"id":"1.232184480","rc":[{"batb":[[0,3.2,4],[1,3.15,4],[2,3.1,4]],"ltp":3.2,"tv":41925.69,"id":8858694}]}]}
{"op":"mcm","clk":"11912011096","pt":1724436541232,"mc":[{"id":"1.232184480","rc":[{"batb":[[0,3.15,4],[1,3.1,4],[2,3.05,4]],"ltp":3.2,"tv":41925.69,"id":8858694}]}]}
{"op":"mcm","clk":"11912011742","pt":1724436543660,"mc":[{"id":"1.232184480","rc":[{"batb":[[0,3.2,4],[1,3.15,4],[2,3.1,4]],"ltp":3.2,"tv":41925.69,"id":8858694}]}]}
{"op":"mcm","clk":"11912012312","pt":1724436545823,"mc":[{"id":"1.232184480","rc":[{"batb":[[0,3.15,4],[1,3.1,4],[2,3.05,4]],"ltp":3.2,"tv":41925.69,"id":8858694}]}]}
{"op":"mcm","clk":"11912013028","pt":1724436548645,"mc":[{"id":"1.232184480","rc":[{"batb":[[0,3.2,4],[1,3.15,4],[2,3.1,4]],"ltp":3.2,"tv":41925.69,"id":8858694}]}]}
{"op":"mcm","clk":"11912013700","pt":1724436551151,"mc":[{"id":"1.232184480","rc":[{"batb":[[0,3.15,4],[1,3.1,4],[2,3.05,4]],"ltp":3.2,"tv":41925.69,"id":8858694}]}]}
{"op":"mcm","clk":"11912015355","pt":1724436557281,"mc":[{"id":"1.232184480","rc":[{"batb":[[0,3.2,4],[1,3.15,4],[2,3.1,4]],"ltp":3.2,"tv":41925.69,"id":8858694}]}]}
{"op":"mcm","clk":"11912016035","pt":1724436559777,"mc":[{"id":"1.232184480","rc":[{"batb":[[0,3.15,4],[1,3.1,4],[2,3.05,4]],"ltp":3.2,"tv":41925.69,"id":8858694}]}]}
{"op":"mcm","clk":"11912016849","pt":1724436562681,"mc":[{"id":"1.232184480","rc":[{"batb":[[0,3.2,4],[1,3.15,4],[2,3.1,4]],"ltp":3.2,"tv":41925.69,"id":8858694}]}]}
{"op":"mcm","clk":"11912017353","pt":1724436564584,"mc":[{"id":"1.232184480","rc":[{"batb":[[1,1.4,59.31],[2,1.08,216.76]],"ltp":1.45,"tv":34436.91,"id":247649}]}]}
{"op":"mcm","clk":"11912017446","pt":1724436564951,"mc":[{"id":"1.232184480","rc":[{"batb":[[0,3.15,4],[1,3.1,4],[2,3.05,4]],"batl":[[1,3.5,23.96],[2,7,1.51]],"ltp":3.2,"tv":41925.69,"id":8858694}]}]}
{"op":"mcm","clk":"11912018460","pt":1724436568705,"mc":[{"id":"1.232184480","rc":[{"batb":[[0,3.2,4],[1,3.15,4],[2,3.1,4]],"ltp":3.2,"tv":41925.69,"id":8858694}]}]}
{"op":"mcm","clk":"11912019204","pt":1724436571270,"mc":[{"id":"1.232184480","rc":[{"batb":[[0,3.15,4],[1,3.1,4],[2,3.05,4]],"ltp":3.2,"tv":41925.69,"id":8858694}]}]}
{"op":"mcm","clk":"11912020294","pt":1724436575264,"mc":[{"id":"1.232184480","rc":[{"batb":[[0,3.2,4],[1,3.15,4],[2,3.1,4]],"ltp":3.2,"tv":41925.69,"id":8858694}]}]}
{"op":"mcm","clk":"11912021010","pt":1724436577915,"mc":[{"id":"1.232184480","rc":[{"batb":[[0,3.15,4],[1,3.1,4],[2,3.05,4]],"ltp":3.2,"tv":41925.69,"id":8858694}]}]}
{"op":"mcm","clk":"11912021834","pt":1724436580801,"mc":[{"id":"1.232184480","rc":[{"batb":[[0,3.2,4],[1,3.15,4],[2,3.1,4]],"ltp":3.2,"tv":41925.69,"id":8858694}]}]}
{"op":"mcm","clk":"11912022476","pt":1724436583071,"mc":[{"id":"1.232184480","rc":[{"batb":[[0,3.15,4],[1,3.1,4],[2,3.05,4]],"ltp":3.2,"tv":41925.69,"id":8858694}]}]}
{"op":"mcm","clk":"11912024404","pt":1724436589623,"mc":[{"id":"1.232184480","rc":[{"batb":[[0,3.2,4],[1,3.15,4],[2,3.1,4]],"ltp":3.2,"tv":41925.69,"id":8858694}]}]}
{"op":"mcm","clk":"11912025137","pt":1724436592005,"mc":[{"id":"1.232184480","rc":[{"batb":[[0,3.15,4],[1,3.1,4],[2,3.05,4]],"ltp":3.2,"tv":41925.69,"id":8858694}]}]}
{"op":"mcm","clk":"11912025963","pt":1724436595057,"mc":[{"id":"1.232184480","rc":[{"batb":[[0,3.2,4],[1,3.15,4],[2,3.1,4]],"ltp":3.2,"tv":41925.69,"id":8858694}]}]}
{"op":"mcm","clk":"11912026669","pt":1724436597488,"mc":[{"id":"1.232184480","rc":[{"batb":[[0,3.15,4],[1,3.1,4],[2,3.05,4]],"ltp":3.2,"tv":41925.69,"id":8858694}]}]}
{"op":"mcm","clk":"11912028590","pt":1724436604111,"mc":[{"id":"1.232184480","rc":[{"batb":[[0,3.2,4],[1,3.15,4],[2,3.1,4]],"ltp":3.2,"tv":41925.69,"id":8858694}]}]}
{"op":"mcm","clk":"11912029258","pt":1724436606354,"mc":[{"id":"1.232184480","rc":[{"batb":[[0,3.15,4],[1,3.1,4],[2,3.05,4]],"ltp":3.2,"tv":41925.69,"id":8858694}]}]}
{"op":"mcm","clk":"11912030522","pt":1724436610959,"mc":[{"id":"1.232184480","rc":[{"batb":[[0,3.2,4],[1,3.15,4],[2,3.1,4]],"ltp":3.2,"tv":41925.69,"id":8858694}]}]}
{"op":"mcm","clk":"11912031285","pt":1724436613547,"mc":[{"id":"1.232184480","rc":[{"batb":[[0,3.15,4],[1,3.1,4],[2,3.05,4]],"ltp":3.2,"tv":41925.69,"id":8858694}]}]}
