{"op":"mcm","clk":"11797220377","pt":1723021406382,"mc":[{"id":"1.231540820","marketDefinition":{"bspMarket":false,"turnInPlayEnabled":true,"persistenceEnabled":true,"marketBaseRate":5.0,"eventId":"33475024","eventTypeId":"4","numberOfWinners":1,"bettingType":"ODDS","marketType":"MATCH_ODDS","marketTime":"2024-08-09T10:00:00.000Z","suspendTime":"2024-08-09T10:00:00.000Z","bspReconciled":false,"complete":true,"inPlay":false,"crossMatching":false,"runnersVoidable":false,"numberOfActiveRunners":2,"betDelay":0,"status":"OPEN","runners":[{"status":"ACTIVE","sortPriority":1,"id":2780,"name":"Nottinghamshire"},{"status":"ACTIVE","sortPriority":2,"id":2219,"name":"Gloucestershire"}],"regulators":["MR_INT"],"countryCode":"GB","discountAllowed":false,"timezone":"GMT","openDate":"2024-08-09T10:00:00.000Z","version":6060462866,"name":"Match Odds","eventName":"Nottinghamshire v Gloucestershire"},"rc":[{"batb":[[0,1.03,200],[1,1.02,200],[2,1.01,220]],"ltp":0.0,"tv":0.0,"id":2780},{"batb":[[0,1.03,200],[1,1.02,200],[2,1.01,220]],"ltp":0.0,"tv":0.0,"id":2219}]}]}
{"op":"mcm","clk":"11797220484","pt":1723021407772,"mc":[{"id":"1.231540820","marketDefinition":{"bspMarket":false,"turnInPlayEnabled":true,"persistenceEnabled":true,"marketBaseRate":5.0,"eventId":"33475024","eventTypeId":"4","numberOfWinners":1,"bettingType":"ODDS","marketType":"MATCH_ODDS","marketTime":"2024-08-09T10:00:00.000Z","suspendTime":"2024-08-09T10:00:00.000Z","bspReconciled":false,"complete":true,"inPlay":false,"crossMatching":false,"runnersVoidable":false,"numberOfActiveRunners":2,"betDelay":0,"status":"OPEN","runners":[{"status":"ACTIVE","sortPriority":1,"id":2780,"name":"Nottinghamshire"},{"status":"ACTIVE","sortPriority":2,"id":2219,"name":"Gloucestershire"}],"regulators":["MR_INT"],"countryCode":"GB","discountAllowed":true,"timezone":"GMT","openDate":"2024-08-09T10:00:00.000Z","version":6060462866,"name":"Match Odds","eventName":"Nottinghamshire v Gloucestershire"}}]}
{"op":"mcm","clk":"11797277153","pt":1723022270079,"mc":[{"id":"1.231540820","rc":[{"batb":[[0,1.25,100],[1,1.03,200],[2,1.02,200]],"ltp":0.0,"tv":0.0,"id":2780},{"batb":[[0,1.25,100],[1,1.03,200],[2,1.02,200]],"ltp":0.0,"tv":0.0,"id":2219}]}]}
{"op":"mcm","clk":"11797330860","pt":1723023095860,"mc":[{"id":"1.231540820","marketDefinition":{"bspMarket":false,"turnInPlayEnabled":true,"persistenceEnabled":true,"marketBaseRate":5.0,"eventId":"33475024","eventTypeId":"4","numberOfWinners":1,"bettingType":"ODDS","marketType":"MATCH_ODDS","marketTime":"2024-08-09T10:00:00.000Z","suspendTime":"2024-08-09T10:00:00.000Z","bspReconciled":false,"complete":true,"inPlay":false,"crossMatching":true,"runnersVoidable":false,"numberOfActiveRunners":2,"betDelay":0,"status":"OPEN","runners":[{"status":"ACTIVE","sortPriority":1,"id":2780,"name":"Nottinghamshire"},{"status":"ACTIVE","sortPriority":2,"id":2219,"name":"Gloucestershire"}],"regulators":["MR_INT"],"countryCode":"GB","discountAllowed":true,"timezone":"GMT","openDate":"2024-08-09T10:00:00.000Z","version":6060462866,"name":"Match Odds","eventName":"Nottinghamshire v Gloucestershire"}}]}
{"op":"mcm","clk":"11797657407","pt":1723026958276,"mc":[{"id":"1.231540820","rc":[{"batb":[[2,1.02,239.34]],"ltp":0.0,"tv":0.0,"id":2780},{"batb":[[2,1.02,239.34]],"ltp":0.0,"tv":0.0,"id":2219}]}]}
{"op":"mcm","clk":"11797658539","pt":1723026970501,"mc":[{"id":"1.231540820","rc":[{"batb":[[2,1.02,247.21]],"ltp":0.0,"tv":0.0,"id":2780},{"batb":[[2,1.02,247.21]],"ltp":0.0,"tv":0.0,"id":2219}]}]}
{"op":"mcm","clk":"11797660212","pt":1723026987890,"mc":[{"id":"1.231540820","rc":[{"batb":[[1,1.03,207.87]],"ltp":0.0,"tv":0.0,"id":2780},{"batb":[[1,1.03,207.87]],"ltp":0.0,"tv":0.0,"id":2219}]}]}
{"op":"mcm","clk":"11797661418","pt":1723027000124,"mc":[{"id":"1.231540820","rc":[{"batb":[[1,1.04,7.87],[2,1.03,207.87]],"ltp":0.0,"tv":0.0,"id":2780},{"batb":[[1,1.04,7.87],[2,1.03,207.87]],"ltp":0.0,"tv":0.0,"id":2219}]}]}
{"op":"mcm","clk":"11797662547","pt":1723027011524,"mc":[{"id":"1.231540820","rc":[{"batb":[[1,1.05,7.87],[2,1.04,7.87]],"ltp":0.0,"tv":0.0,"id":2780},{"batb":[[1,1.05,7.87],[2,1.04,7.87]],"ltp":0.0,"tv":0.0,"id":2219}]}]}
{"op":"mcm","clk":"11797664124","pt":1723027027456,"mc":[{"id":"1.231540820","rc":[{"batb":[[1,1.06,7.87],[2,1.05,7.87]],"ltp":0.0,"tv":0.0,"id":2780},{"batb":[[1,1.06,7.87],[2,1.05,7.87]],"ltp":0.0,"tv":0.0,"id":2219}]}]}
{"op":"mcm","clk":"11797665727","pt":1723027042411,"mc":[{"id":"1.231540820","rc":[{"batb":[[1,1.07,7.87],[2,1.06,7.87]],"ltp":0.0,"tv":0.0,"id":2780},{"batb":[[1,1.07,7.87],[2,1.06,7.87]],"ltp":0.0,"tv":0.0,"id":2219}]}]}
{"op":"mcm","clk":"11797667631","pt":1723027061240,"mc":[{"id":"1.231540820","rc":[{"batb":[[1,1.08,7.87],[2,1.07,7.87]],"ltp":0.0,"tv":0.0,"id":2780},{"batb":[[1,1.08,7.87],[2,1.07,7.87]],"ltp":0.0,"tv":0.0,"id":2219}]}]}
{"op":"mcm","clk":"11798097809","pt":1723031537963,"mc":[{"id":"1.231540820","rc":[{"batb":[[0,1.26,3.27],[1,1.25,100],[2,1.08,7.86]],"ltp":0.0,"tv":0.0,"id":2780},{"batb":[[1,1.08,7.86],[2,1.07,7.86]],"ltp":0.0,"tv":0.0,"id":2219}]}]}
{"op":"mcm","clk":"11798098908","pt":1723031550984,"mc":[{"id":"1.231540820","rc":[{"batb":[[0,1.29,3.17],[1,1.26,3.27],[2,1.25,100]],"ltp":0.0,"tv":0.0,"id":2780}]}]}
{"op":"mcm","clk":"11798099981","pt":1723031563999,"mc":[{"id":"1.231540820","rc":[{"batb":[[0,1.26,3.27],[1,1.25,100],[2,1.08,7.86]],"ltp":0.0,"tv":0.0,"id":2219}]}]}
{"op":"mcm","clk":"11798100888","pt":1723031575021,"mc":[{"id":"1.231540820","rc":[{"batb":[[0,1.3,3.27],[1,1.26,3.27],[2,1.25,100]],"ltp":0.0,"tv":0.0,"id":2219}]}]}
{"op":"mcm","clk":"11798166955","pt":1723032326380,"mc":[{"id":"1.231540820","rc":[{"batb":[[0,1.29,3.16],[1,1.26,3.27]],"ltp":0.0,"tv":0.0,"id":2780},{"trd":[[1.3,0.14]],"batb":[[0,1.3,3.2],[1,1.26,3.27]],"ltp":1.3,"tv":0.13,"id":2219}],"tv":0.13}]}
{"op":"mcm","clk":"11798335489","pt":1723034736134,"mc":[{"id":"1.231540820","rc":[{"trd":[[1.3,0.28]],"batb":[[0,1.3,3.13]],"ltp":1.3,"tv":0.27,"id":2219}],"tv":0.27}]}
{"op":"mcm","clk":"11798476782","pt":1723037136582,"mc":[{"id":"1.231540820","rc":[{"trd":[[1.3,0.42]],"batb":[[0,1.3,3.06]],"ltp":1.3,"tv":0.41,"id":2219}],"tv":0.41}]}
{"op":"mcm","clk":"11798560415","pt":1723038355053,"mc":[{"id":"1.231540820","rc":[{"trd":[[1.3,0.56]],"batb":[[0,1.3,2.99]],"ltp":1.3,"tv":0.55,"id":2219}],"tv":0.55}]}
{"op":"mcm","clk":"11798643326","pt":1723039536002,"mc":[{"id":"1.231540820","rc":[{"batb":[[0,1.29,3.16],[1,1.26,3.27]],"ltp":0.0,"tv":0.0,"id":2780},{"trd":[[1.3,0.7]],"batb":[[0,1.3,2.93],[1,1.26,3.27]],"ltp":1.3,"tv":0.69,"id":2219}],"tv":0.69}]}
{"op":"mcm","clk":"11798662448","pt":1723039808165,"mc":[{"id":"1.231540820","rc":[{"batb":[[0,1.3,28.76],[1,1.29,3.16],[2,1.26,3.27]],"ltp":0.0,"tv":0.0,"id":2780},{"batb":[[0,1.31,27.84],[1,1.3,2.93],[2,1.26,3.27]],"ltp":1.3,"tv":0.69,"id":2219}]}]}
{"op":"mcm","clk":"11798794373","pt":1723041610710,"mc":[{"id":"1.231540820","rc":[{"batb":[[0,1.3,2.93],[1,1.26,3.27],[2,1.25,100]],"ltp":1.3,"tv":0.69,"id":2219}]}]}
{"op":"mcm","clk":"11798794386","pt":1723041610760,"mc":[{"id":"1.231540820","rc":[{"batb":[[0,1.29,3.16],[1,1.26,3.27],[2,1.25,100]],"ltp":0.0,"tv":0.0,"id":2780}]}]}
{"op":"mcm","clk":"11798798641","pt":1723041665123,"mc":[{"id":"1.231540820","rc":[{"batb":[[0,1.3,28.76],[1,1.29,3.16],[2,1.26,3.27]],"ltp":0.0,"tv":0.0,"id":2780},{"batb":[[0,1.31,27.84],[1,1.3,2.93],[2,1.26,3.27]],"ltp":1.3,"tv":0.69,"id":2219}]}]}
{"op":"mcm","clk":"11798811531","pt":1723041823069,"mc":[{"id":"1.231540820","rc":[{"batb":[[0,1.31,6.87],[1,1.3,28.76],[2,1.29,3.16]],"ltp":0.0,"tv":0.0,"id":2780},{"batb":[[0,1.32,7.46],[1,1.31,27.84],[2,1.3,2.93]],"ltp":1.3,"tv":0.69,"id":2219}]}]}
{"op":"mcm","clk":"11798814982","pt":1723041863125,"mc":[{"id":"1.231540820","rc":[{"batb":[[0,1.32,10.73]],"ltp":1.3,"tv":0.69,"id":2219}]}]}
{"op":"mcm","clk":"11798815704","pt":1723041873128,"mc":[{"id":"1.231540820","rc":[{"batb":[[0,1.31,10.03],[2,1.26,3.27]],"ltp":0.0,"tv":0.0,"id":2780}]}]}
{"op":"mcm","clk":"11798816173","pt":1723041879429,"mc":[{"id":"1.231540820","rc":[{"batb":[[0,1.31,13.3],[2,1.25,100]],"ltp":0.0,"tv":0.0,"id":2780}]}]}
{"op":"mcm","clk":"11798946526","pt":1723043469661,"mc":[{"id":"1.231540820","rc":[{"batb":[[0,1.31,13.3],[1,1.25,100],[2,1.08,7.86]],"ltp":0.0,"tv":0.0,"id":2780},{"batb":[[0,1.32,10.72],[1,1.3,2.92],[2,1.25,100]],"ltp":1.3,"tv":0.69,"id":2219}]}]}
{"op":"mcm","clk":"11798950916","pt":1723043513798,"mc":[{"id":"1.231540820","rc":[{"batb":[[0,1.32,26.99],[1,1.31,13.3],[2,1.25,100]],"ltp":0.0,"tv":0.0,"id":2780},{"batb":[[0,1.33,26.17],[1,1.32,10.72],[2,1.3,2.92]],"ltp":1.3,"tv":0.69,"id":2219}]}]}
{"op":"mcm","clk":"11799109965","pt":1723044945463,"mc":[{"id":"1.231540820","rc":[{"batb":[[0,1.33,6.86],[1,1.32,26.99],[2,1.31,6.43]],"ltp":0.0,"tv":0.0,"id":2780},{"batb":[[0,1.34,7.45],[1,1.33,26.17],[2,1.32,3.27]],"ltp":1.3,"tv":0.69,"id":2219}]}]}
{"op":"mcm","clk":"11799149278","pt":1723045314872,"mc":[{"id":"1.231540820","rc":[{"batb":[[1,1.31,6.43],[2,1.25,100]],"ltp":0.0,"tv":0.0,"id":2780},{"batb":[[1,1.32,3.27],[2,1.3,2.92]],"ltp":1.3,"tv":0.69,"id":2219}]}]}
{"op":"mcm","clk":"11799154043","pt":1723045360507,"mc":[{"id":"1.231540820","rc":[{"batb":[[0,1.34,25.4],[1,1.33,6.86],[2,1.31,6.43]],"ltp":0.0,"tv":0.0,"id":2780},{"batb":[[0,1.35,24.68],[1,1.34,7.45],[2,1.32,3.27]],"ltp":1.3,"tv":0.69,"id":2219}]}]}
{"op":"mcm","clk":"11799264863","pt":1723046475397,"mc":[{"id":"1.231540820","rc":[{"batb":[[0,1.35,6.87],[1,1.34,25.4],[2,1.31,6.44]],"ltp":0.0,"tv":0.0,"id":2780},{"batb":[[0,1.35,24.67],[1,1.32,3.27],[2,1.3,2.93]],"ltp":1.3,"tv":0.69,"id":2219}]}]}
{"op":"mcm","clk":"11799333517","pt":1723047161104,"mc":[{"id":"1.231540820","rc":[{"batb":[[1,1.31,6.44],[2,1.25,100]],"ltp":0.0,"tv":0.0,"id":2780},{"batb":[[0,1.32,3.27],[1,1.3,2.93],[2,1.26,7.46]],"ltp":1.3,"tv":0.69,"id":2219}]}]}
{"op":"mcm","clk":"11799337983","pt":1723047201332,"mc":[{"id":"1.231540820","rc":[{"batb":[[0,1.36,23.99],[1,1.35,6.87],[2,1.31,6.44]],"ltp":0.0,"tv":0.0,"id":2780},{"batb":[[0,1.33,26.17],[1,1.32,3.27],[2,1.3,2.93]],"ltp":1.3,"tv":0.69,"id":2219}]}]}
{"op":"mcm","clk":"11799413952","pt":1723047990717,"mc":[{"id":"1.231540820","rc":[{"batb":[[1,1.31,6.44],[2,1.26,6.87]],"ltp":0.0,"tv":0.0,"id":2780},{"batb":[[0,1.34,7.46],[1,1.33,26.17],[2,1.32,3.27]],"ltp":1.3,"tv":0.69,"id":2219}]}]}
{"op":"mcm","clk":"11799516733","pt":1723049001661,"mc":[{"id":"1.231540820","rc":[{"batb":[[1,1.32,3.27],[2,1.3,2.93]],"ltp":1.3,"tv":0.69,"id":2219}]}]}
{"op":"mcm","clk":"11799516749","pt":1723049001869,"mc":[{"id":"1.231540820","rc":[{"batb":[[0,1.31,6.44],[1,1.26,6.87],[2,1.25,100]],"ltp":0.0,"tv":0.0,"id":2780}]}]}
{"op":"mcm","clk":"11799518000","pt":1723049018575,"mc":[{"id":"1.231540820","rc":[{"batb":[[0,1.32,26.98],[1,1.31,6.44],[2,1.26,6.87]],"ltp":0.0,"tv":0.0,"id":2780},{"batb":[[0,1.35,24.67],[1,1.34,7.46],[2,1.32,3.27]],"ltp":1.3,"tv":0.69,"id":2219}]}]}
{"op":"mcm","clk":"11799556619","pt":1723049512704,"mc":[{"id":"1.231540820","rc":[{"batb":[[0,1.33,6.87],[1,1.32,26.98],[2,1.31,6.44]],"ltp":0.0,"tv":0.0,"id":2780},{"batb":[[1,1.32,3.27],[2,1.3,2.93]],"ltp":1.3,"tv":0.69,"id":2219}]}]}
{"op":"mcm","clk":"11799675368","pt":1723050819947,"mc":[{"id":"1.231540820","rc":[{"batb":[[0,1.33,6.87],[1,1.31,6.44],[2,1.25,100]],"ltp":0.0,"tv":0.0,"id":2780},{"batb":[[0,1.32,3.28],[1,1.3,2.93],[2,1.26,7.46]],"ltp":1.3,"tv":0.69,"id":2219}]}]}
{"op":"mcm","clk":"11799687366","pt":1723050952703,"mc":[{"id":"1.231540820","rc":[{"batb":[[0,1.34,25.41],[1,1.33,6.87],[2,1.31,6.44]],"ltp":0.0,"tv":0.0,"id":2780},{"batb":[[0,1.33,26.18],[1,1.32,3.28],[2,1.3,2.93]],"ltp":1.3,"tv":0.69,"id":2219}]}]}
{"op":"mcm","clk":"11799696052","pt":1723051045716,"mc":[{"id":"1.231540820","rc":[{"batb":[[0,1.35,6.87],[1,1.34,25.41]],"ltp":0.0,"tv":0.0,"id":2780}]}]}
{"op":"mcm","clk":"11799696059","pt":1723051045823,"mc":[{"id":"1.231540820","rc":[{"batb":[[0,1.34,7.46],[1,1.33,26.18],[2,1.32,3.28]],"ltp":1.3,"tv":0.69,"id":2219}]}]}
{"op":"mcm","clk":"11799777153","pt":1723051877914,"mc":[{"id":"1.231540820","rc":[{"batb":[[0,1.35,7.42]],"ltp":0.0,"tv":0.0,"id":2780}]}]}
{"op":"mcm","clk":"11799778203","pt":1723051886925,"mc":[{"id":"1.231540820","rc":[{"batb":[[0,1.34,8.01]],"ltp":1.3,"tv":0.69,"id":2219}]}]}
{"op":"mcm","clk":"11799884509","pt":1723052753210,"mc":[{"id":"1.231540820","rc":[{"batb":[[1,1.31,6.44],[2,1.25,100]],"ltp":0.0,"tv":0.0,"id":2780},{"batb":[[1,1.32,3.28],[2,1.3,2.93]],"ltp":1.3,"tv":0.69,"id":2219}]}]}
{"op":"mcm","clk":"11799904481","pt":1723052918640,"mc":[{"id":"1.231540820","rc":[{"batb":[[0,1.36,24.54],[1,1.35,6.87],[2,1.31,6.44]],"ltp":0.0,"tv":0.0,"id":2780},{"batb":[[0,1.35,25.23],[1,1.34,7.46],[2,1.32,3.28]],"ltp":1.3,"tv":0.69,"id":2219}]}]}
{"op":"mcm","clk":"11800009535","pt":1723053832733,"mc":[{"id":"1.231540820","rc":[{"batb":[[0,1.91,48.8],[1,1.36,24.57],[2,1.35,6.88]],"ltp":0.0,"tv":0.0,"id":2780},{"batb":[[0,2,44.4],[1,1.35,25.25],[2,1.34,7.47]],"ltp":1.3,"tv":0.69,"id":2219}]}]}
{"op":"mcm","clk":"11800031515","pt":1723053985326,"mc":[{"id":"1.231540820","rc":[{"batb":[[1,1.36,24.02]],"ltp":0.0,"tv":0.0,"id":2780}]}]}
{"op":"mcm","clk":"11800032088","pt":1723053989108,"mc":[{"id":"1.231540820","rc":[{"batb":[[1,1.35,24.71]],"ltp":1.3,"tv":0.69,"id":2219}]}]}
{"op":"mcm","clk":"11800044214","pt":1723054073698,"mc":[{"id":"1.231540820","rc":[{"batb":[[2,1.31,6.45]],"ltp":0.0,"tv":0.0,"id":2780}]}]}
{"op":"mcm","clk":"11800044284","pt":1723054074126,"mc":[{"id":"1.231540820","rc":[{"batb":[[2,1.32,3.28]],"ltp":1.3,"tv":0.69,"id":2219}]}]}
{"op":"mcm","clk":"11800151052","pt":1723054719290,"mc":[{"id":"1.231540820","rc":[{"batb":[[1,1.31,6.45],[2,1.25,100]],"ltp":0.0,"tv":0.0,"id":2780},{"batb":[[1,1.32,3.28],[2,1.3,2.93]],"ltp":1.3,"tv":0.69,"id":2219}]}]}
{"op":"mcm","clk":"11800236177","pt":1723055344391,"mc":[{"id":"1.231540820","rc":[{"trd":[[2,88]],"batb":[[0,1.32,3.68],[1,1.3,2.93],[2,1.25,100]],"ltp":2.0,"tv":88.69,"id":2219}],"tv":88.69}]}
{"op":"mcm","clk":"11800236824","pt":1723055349124,"mc":[{"id":"1.231540820","rc":[{"batb":[[0,1.96,46.26],[1,1.32,3.28],[2,1.3,2.93]],"ltp":2.0,"tv":88.69,"id":2219}]}]}
{"op":"mcm","clk":"11800237732","pt":1723055356123,"mc":[{"id":"1.231540820","rc":[{"batb":[[0,1.97,10],[1,1.96,46.26],[2,1.32,3.28]],"batl":[[0,2.1,50]],"ltp":2.0,"tv":88.69,"id":2219}]}]}
{"op":"mcm","clk":"11800238155","pt":1723055359406,"mc":[{"id":"1.231540820","rc":[{"batb":[[0,1.96,46.26],[1,1.32,3.28],[2,1.3,2.93]],"ltp":2.0,"tv":88.69,"id":2219}]}]}
{"op":"mcm","clk":"11800256626","pt":1723055492286,"mc":[{"id":"1.231540820","rc":[{"batb":[[0,1.97,10],[1,1.96,46.26],[2,1.32,3.28]],"ltp":2.0,"tv":88.69,"id":2219}]}]}
{"op":"mcm","clk":"11800257226","pt":1723055496365,"mc":[{"id":"1.231540820","rc":[{"batb":[[0,1.96,46.26],[1,1.32,3.28],[2,1.3,2.93]],"ltp":2.0,"tv":88.69,"id":2219}]}]}
{"op":"mcm","clk":"11800308596","pt":1723055821785,"mc":[{"id":"1.231540820","rc":[{"batb":[[0,1.97,10],[1,1.96,46.26],[2,1.32,3.28]],"ltp":2.0,"tv":88.69,"id":2219}]}]}
{"op":"mcm","clk":"11800309136","pt":1723055825100,"mc":[{"id":"1.231540820","rc":[{"batb":[[0,1.96,46.26],[1,1.32,3.28],[2,1.3,2.93]],"ltp":2.0,"tv":88.69,"id":2219}]}]}
{"op":"mcm","clk":"11800361526","pt":1723056146068,"mc":[{"id":"1.231540820","rc":[{"batb":[[0,1.97,10],[1,1.96,46.26],[2,1.32,3.28]],"batl":[[0,2.08,4.64],[1,2.1,50]],"ltp":2.0,"tv":88.69,"id":2219}]}]}
{"op":"mcm","clk":"11800362049","pt":1723056149563,"mc":[{"id":"1.231540820","rc":[{"batb":[[0,1.96,46.26],[1,1.32,3.28],[2,1.3,2.93]],"ltp":2.0,"tv":88.69,"id":2219}]}]}
{"op":"mcm","clk":"11800364852","pt":1723056167904,"mc":[{"id":"1.231540820","rc":[{"batb":[[0,1.97,10],[1,1.96,46.26],[2,1.32,3.28]],"ltp":2.0,"tv":88.69,"id":2219}]}]}
{"op":"mcm","clk":"11800365516","pt":1723056172078,"mc":[{"id":"1.231540820","rc":[{"batb":[[0,1.96,46.26],[1,1.32,3.28],[2,1.3,2.93]],"ltp":2.0,"tv":88.69,"id":2219}]}]}
{"op":"mcm","clk":"11800411383","pt":1723056471176,"mc":[{"id":"1.231540820","rc":[{"batb":[[0,1.97,10],[1,1.96,46.26],[2,1.32,3.28]],"ltp":2.0,"tv":88.69,"id":2219}]}]}
{"op":"mcm","clk":"11800411823","pt":1723056474571,"mc":[{"id":"1.231540820","rc":[{"batb":[[0,1.96,46.26],[1,1.32,3.28],[2,1.3,2.93]],"ltp":2.0,"tv":88.69,"id":2219}]}]}
{"op":"mcm","clk":"11800428899","pt":1723056596878,"mc":[{"id":"1.231540820","rc":[{"batb":[[0,1.97,10],[1,1.96,46.26],[2,1.32,3.28]],"ltp":2.0,"tv":88.69,"id":2219}]}]}
{"op":"mcm","clk":"11800429325","pt":1723056600417,"mc":[{"id":"1.231540820","rc":[{"batb":[[0,1.96,46.26],[1,1.32,3.28],[2,1.3,2.93]],"ltp":2.0,"tv":88.69,"id":2219}]}]}
{"op":"mcm","clk":"11800434908","pt":1723056643871,"mc":[{"id":"1.231540820","rc":[{"batb":[[0,1.97,10],[1,1.96,46.26],[2,1.32,3.28]],"ltp":2.0,"tv":88.69,"id":2219}]}]}
{"op":"mcm","clk":"11800435360","pt":1723056647440,"mc":[{"id":"1.231540820","rc":[{"batb":[[0,1.96,46.26],[1,1.32,3.28],[2,1.3,2.93]],"ltp":2.0,"tv":88.69,"id":2219}]}]}
{"op":"mcm","clk":"11800554084","pt":1723057553152,"mc":[{"id":"1.231540820","rc":[{"batb":[[1,1.31,6.45]],"ltp":0.0,"tv":0.0,"id":2780},{"batb":[[0,1.97,10],[1,1.96,46.26],[2,1.32,3.28]],"batl":[[0,2.08,4.64]],"ltp":2.0,"tv":88.69,"id":2219}]}]}
{"op":"mcm","clk":"11800554615","pt":1723057557308,"mc":[{"id":"1.231540820","rc":[{"batb":[[0,1.96,46.26],[1,1.32,3.28],[2,1.3,2.93]],"ltp":2.0,"tv":88.69,"id":2219}]}]}
{"op":"mcm","clk":"11800635966","pt":1723058143253,"mc":[{"id":"1.231540820","rc":[{"batb":[[0,1.97,10],[1,1.96,46.26],[2,1.32,3.28]],"ltp":2.0,"tv":88.69,"id":2219}]}]}
{"op":"mcm","clk":"11800636594","pt":1723058147493,"mc":[{"id":"1.231540820","rc":[{"batb":[[0,1.96,46.26],[1,1.32,3.28],[2,1.3,2.93]],"ltp":2.0,"tv":88.69,"id":2219}]}]}
{"op":"mcm","clk":"11800787369","pt":1723059351726,"mc":[{"id":"1.231540820","rc":[{"batb":[[0,1.97,10],[1,1.96,46.26],[2,1.32,3.28]],"ltp":2.0,"tv":88.69,"id":2219}]}]}
{"op":"mcm","clk":"11800787822","pt":1723059355312,"mc":[{"id":"1.231540820","rc":[{"batb":[[0,1.96,46.26],[1,1.32,3.28],[2,1.3,2.93]],"ltp":2.0,"tv":88.69,"id":2219}]}]}
{"op":"mcm","clk":"11800821061","pt":1723059603056,"mc":[{"id":"1.231540820","rc":[{"batb":[[0,1.97,10],[1,1.96,46.26],[2,1.32,3.28]],"ltp":2.0,"tv":88.69,"id":2219}]}]}
{"op":"mcm","clk":"11800821630","pt":1723059607277,"mc":[{"id":"1.231540820","rc":[{"batb":[[0,1.96,46.26],[1,1.32,3.28],[2,1.3,2.93]],"ltp":2.0,"tv":88.69,"id":2219}]}]}
{"op":"mcm","clk":"11800909256","pt":1723060279570,"mc":[{"id":"1.231540820","rc":[{"batb":[[0,1.97,10],[1,1.96,46.26],[2,1.32,3.28]],"ltp":2.0,"tv":88.69,"id":2219}]}]}
{"op":"mcm","clk":"11800909704","pt":1723060283357,"mc":[{"id":"1.231540820","rc":[{"batb":[[0,1.96,46.26],[1,1.32,3.28],[2,1.3,2.93]],"ltp":2.0,"tv":88.69,"id":2219}]}]}
{"op":"mcm","clk":"11800969919","pt":1723060923936,"mc":[{"id":"1.231540820","rc":[{"batb":[[1,1.31,6.45]],"ltp":0.0,"tv":0.0,"id":2780},{"batb":[[0,1.97,10],[1,1.96,46.26],[2,1.32,3.28]],"ltp":2.0,"tv":88.69,"id":2219}]}]}
{"op":"mcm","clk":"11800970366","pt":1723060928334,"mc":[{"id":"1.231540820","rc":[{"batb":[[0,1.96,46.26],[1,1.32,3.28],[2,1.3,2.93]],"ltp":2.0,"tv":88.69,"id":2219}]}]}
{"op":"mcm","clk":"11801034359","pt":1723061608427,"mc":[{"id":"1.231540820","rc":[{"batb":[[0,1.97,10],[1,1.96,46.26],[2,1.32,3.28]],"ltp":2.0,"tv":88.69,"id":2219}]}]}
{"op":"mcm","clk":"11801034708","pt":1723061612046,"mc":[{"id":"1.231540820","rc":[{"batb":[[0,1.96,46.26],[1,1.32,3.28],[2,1.3,2.93]],"ltp":2.0,"tv":88.69,"id":2219}]}]}
{"op":"mcm","clk":"11801064076","pt":1723061978133,"mc":[{"id":"1.231540820","rc":[{"batb":[[0,1.97,10],[1,1.96,46.26],[2,1.32,3.28]],"ltp":2.0,"tv":88.69,"id":2219}]}]}
{"op":"mcm","clk":"11801064321","pt":1723061981738,"mc":[{"id":"1.231540820","rc":[{"batb":[[0,1.96,46.26],[1,1.32,3.28],[2,1.3,2.93]],"ltp":2.0,"tv":88.69,"id":2219}]}]}
{"op":"mcm","clk":"11801066206","pt":1723062004898,"mc":[{"id":"1.231540820","rc":[{"batb":[[0,1.97,10],[1,1.96,46.26],[2,1.32,3.28]],"ltp":2.0,"tv":88.69,"id":2219}]}]}
{"op":"mcm","clk":"11801066509","pt":1723062008500,"mc":[{"id":"1.231540820","rc":[{"batb":[[0,1.96,46.26],[1,1.32,3.28],[2,1.3,2.93]],"ltp":2.0,"tv":88.69,"id":2219}]}]}
{"op":"mcm","clk":"11801068450","pt":1723062033336,"mc":[{"id":"1.231540820","rc":[{"batb":[[0,1.97,10],[1,1.96,46.26],[2,1.32,3.28]],"ltp":2.0,"tv":88.69,"id":2219}]}]}
{"op":"mcm","clk":"11801068748","pt":1723062036847,"mc":[{"id":"1.231540820","rc":[{"batb":[[0,1.96,46.26],[1,1.32,3.28],[2,1.3,2.93]],"ltp":2.0,"tv":88.69,"id":2219}]}]}
{"op":"mcm","clk":"11801069559","pt":1723062047066,"mc":[{"id":"1.231540820","rc":[{"batb":[[0,1.97,10],[1,1.96,46.26],[2,1.32,3.28]],"ltp":2.0,"tv":88.69,"id":2219}]}]}
{"op":"mcm","clk":"11801069905","pt":1723062051077,"mc":[{"id":"1.231540820","rc":[{"batb":[[0,1.96,46.26],[1,1.32,3.28],[2,1.3,2.93]],"ltp":2.0,"tv":88.69,"id":2219}]}]}
{"op":"mcm","clk":"11801070441","pt":1723062057879,"mc":[{"id":"1.231540820","rc":[{"batb":[[0,1.97,10],[1,1.96,46.26],[2,1.32,3.28]],"ltp":2.0,"tv":88.69,"id":2219}]}]}
{"op":"mcm","clk":"11801070712","pt":1723062061377,"mc":[{"id":"1.231540820","rc":[{"batb":[[0,1.96,46.26],[1,1.32,3.28],[2,1.3,2.93]],"ltp":2.0,"tv":88.69,"id":2219}]}]}
{"op":"mcm","clk":"11801070954","pt":1723062064174,"mc":[{"id":"1.231540820","rc":[{"batb":[[0,1.97,10],[1,1.96,46.26],[2,1.32,3.28]],"ltp":2.0,"tv":88.69,"id":2219}]}]}
{"op":"mcm","clk":"11801071268","pt":1723062067881,"mc":[{"id":"1.231540820","rc":[{"batb":[[0,1.96,46.26],[1,1.32,3.28],[2,1.3,2.93]],"ltp":2.0,"tv":88.69,"id":2219}]}]}
{"op":"mcm","clk":"11801071942","pt":1723062077107,"mc":[{"id":"1.231540820","rc":[{"batb":[[0,1.97,10],[1,1.96,46.26],[2,1.32,3.28]],"ltp":2.0,"tv":88.69,"id":2219}]}]}
{"op":"mcm","clk":"11801072357","pt":1723062081706,"mc":[{"id":"1.231540820","rc":[{"batb":[[0,1.96,46.26],[1,1.32,3.28],[2,1.3,2.93]],"ltp":2.0,"tv":88.69,"id":2219}]}]}
{"op":"mcm","clk":"11801072515","pt":1723062083879,"mc":[{"id":"1.231540820","rc":[{"batb":[[0,1.97,10],[1,1.96,46.26],[2,1.32,3.28]],"ltp":2.0,"tv":88.69,"id":2219}]}]}
{"op":"mcm","clk":"11801072798","pt":1723062087404,"mc":[{"id":"1.231540820","rc":[{"batb":[[0,1.96,46.26],[1,1.32,3.28],[2,1.3,2.93]],"ltp":2.0,"tv":88.69,"id":2219}]}]}
{"op":"mcm","clk":"11801073221","pt":1723062092616,"mc":[{"id":"1.231540820","rc":[{"batb":[[0,1.97,10],[1,1.96,46.26],[2,1.32,3.28]],"ltp":2.0,"tv":88.69,"id":2219}]}]}
{"op":"mcm","clk":"11801073591","pt":1723062096812,"mc":[{"id":"1.231540820","rc":[{"batb":[[0,1.96,46.26],[1,1.32,3.28],[2,1.3,2.93]],"ltp":2.0,"tv":88.69,"id":2219}]}]}
{"op":"mcm","clk":"11801073764","pt":1723062099230,"mc":[{"id":"1.231540820","rc":[{"batb":[[0,1.97,10],[1,1.96,46.26],[2,1.32,3.28]],"ltp":2.0,"tv":88.69,"id":2219}]}]}
{"op":"mcm","clk":"11801074069","pt":1723062102848,"mc":[{"id":"1.231540820","rc":[{"batb":[[0,1.96,46.26],[1,1.32,3.28],[2,1.3,2.93]],"ltp":2.0,"tv":88.69,"id":2219}]}]}
{"op":"mcm","clk":"11801074426","pt":1723062106936,"mc":[{"id":"1.231540820","rc":[{"batb":[[0,1.97,10],[1,1.96,46.26],[2,1.32,3.28]],"ltp":2.0,"tv":88.69,"id":2219}]}]}
{"op":"mcm","clk":"11801074752","pt":1723062110346,"mc":[{"id":"1.231540820","rc":[{"batb":[[0,1.96,46.26],[1,1.32,3.28],[2,1.3,2.93]],"ltp":2.0,"tv":88.69,"id":2219}]}]}
{"op":"mcm","clk":"11801075006","pt":1723062113446,"mc":[{"id":"1.231540820","rc":[{"batb":[[0,1.97,10],[1,1.96,46.26],[2,1.32,3.28]],"ltp":2.0,"tv":88.69,"id":2219}]}]}
{"op":"mcm","clk":"11801075234","pt":1723062116768,"mc":[{"id":"1.231540820","rc":[{"batb":[[0,1.96,46.26],[1,1.32,3.28],[2,1.3,2.93]],"ltp":2.0,"tv":88.69,"id":2219}]}]}
{"op":"mcm","clk":"11801075443","pt":1723062119346,"mc":[{"id":"1.231540820","rc":[{"batb":[[0,1.97,10],[1,1.96,46.26],[2,1.32,3.28]],"ltp":2.0,"tv":88.69,"id":2219}]}]}
{"op":"mcm","clk":"11801075732","pt":1723062122880,"mc":[{"id":"1.231540820","rc":[{"batb":[[0,1.96,46.26],[1,1.32,3.28],[2,1.3,2.93]],"ltp":2.0,"tv":88.69,"id":2219}]}]}
{"op":"mcm","clk":"11801076017","pt":1723062126288,"mc":[{"id":"1.231540820","rc":[{"batb":[[0,1.97,10],[1,1.96,46.26],[2,1.32,3.28]],"ltp":2.0,"tv":88.69,"id":2219}]}]}
{"op":"mcm","clk":"11801076339","pt":1723062129757,"mc":[{"id":"1.231540820","rc":[{"batb":[[0,1.96,46.26],[1,1.32,3.28],[2,1.3,2.93]],"ltp":2.0,"tv":88.69,"id":2219}]}]}
{"op":"mcm","clk":"11801076544","pt":1723062132280,"mc":[{"id":"1.231540820","rc":[{"batb":[[0,1.97,10],[1,1.96,46.26],[2,1.32,3.28]],"ltp":2.0,"tv":88.69,"id":2219}]}]}
{"op":"mcm","clk":"11801076851","pt":1723062135679,"mc":[{"id":"1.231540820","rc":[{"batb":[[0,1.96,46.26],[1,1.32,3.28],[2,1.3,2.93]],"ltp":2.0,"tv":88.69,"id":2219}]}]}
{"op":"mcm","clk":"11801077087","pt":1723062138263,"mc":[{"id":"1.231540820","rc":[{"batb":[[0,1.97,10],[1,1.96,46.26],[2,1.32,3.28]],"ltp":2.0,"tv":88.69,"id":2219}]}]}
{"op":"mcm","clk":"11801077373","pt":1723062141580,"mc":[{"id":"1.231540820","rc":[{"batb":[[0,1.96,46.26],[1,1.32,3.28],[2,1.3,2.93]],"ltp":2.0,"tv":88.69,"id":2219}]}]}
{"op":"mcm","clk":"11801077701","pt":1723062145098,"mc":[{"id":"1.231540820","rc":[{"batb":[[0,1.97,10],[1,1.96,46.26],[2,1.32,3.28]],"ltp":2.0,"tv":88.69,"id":2219}]}]}
{"op":"mcm","clk":"11801077965","pt":1723062148688,"mc":[{"id":"1.231540820","rc":[{"batb":[[0,1.96,46.26],[1,1.32,3.28],[2,1.3,2.93]],"ltp":2.0,"tv":88.69,"id":2219}]}]}
{"op":"mcm","clk":"11801078192","pt":1723062151618,"mc":[{"id":"1.231540820","rc":[{"batb":[[0,1.97,10],[1,1.96,46.26],[2,1.32,3.28]],"ltp":2.0,"tv":88.69,"id":2219}]}]}
{"op":"mcm","clk":"11801078420","pt":1723062154914,"mc":[{"id":"1.231540820","rc":[{"batb":[[0,1.96,46.26],[1,1.32,3.28],[2,1.3,2.93]],"ltp":2.0,"tv":88.69,"id":2219}]}]}
{"op":"mcm","clk":"11801078632","pt":1723062158100,"mc":[{"id":"1.231540820","rc":[{"batb":[[0,1.97,10],[1,1.96,46.26],[2,1.32,3.28]],"ltp":2.0,"tv":88.69,"id":2219}]}]}
{"op":"mcm","clk":"11801078890","pt":1723062161710,"mc":[{"id":"1.231540820","rc":[{"batb":[[0,1.96,46.26],[1,1.32,3.28],[2,1.3,2.93]],"ltp":2.0,"tv":88.69,"id":2219}]}]}
{"op":"mcm","clk":"11801079073","pt":1723062164134,"mc":[{"id":"1.231540820","rc":[{"batb":[[0,1.97,10],[1,1.96,46.26],[2,1.32,3.28]],"ltp":2.0,"tv":88.69,"id":2219}]}]}
{"op":"mcm","clk":"11801079307","pt":1723062167427,"mc":[{"id":"1.231540820","rc":[{"batb":[[0,1.96,46.26],[1,1.32,3.28],[2,1.3,2.93]],"ltp":2.0,"tv":88.69,"id":2219}]}]}
{"op":"mcm","clk":"11801079495","pt":1723062170210,"mc":[{"id":"1.231540820","rc":[{"batb":[[0,1.97,10],[1,1.96,46.26],[2,1.32,3.28]],"ltp":2.0,"tv":88.69,"id":2219}]}]}
{"op":"mcm","clk":"11801079806","pt":1723062174636,"mc":[{"id":"1.231540820","rc":[{"batb":[[0,1.96,46.26],[1,1.32,3.28],[2,1.3,2.93]],"ltp":2.0,"tv":88.69,"id":2219}]}]}
{"op":"mcm","clk":"11801079957","pt":1723062176952,"mc":[{"id":"1.231540820","rc":[{"batb":[[0,1.97,10],[1,1.96,46.26],[2,1.32,3.28]],"ltp":2.0,"tv":88.69,"id":2219}]}]}
{"op":"mcm","clk":"11801080183","pt":1723062180358,"mc":[{"id":"1.231540820","rc":[{"batb":[[0,1.96,46.26],[1,1.32,3.28],[2,1.3,2.93]],"ltp":2.0,"tv":88.69,"id":2219}]}]}
{"op":"mcm","clk":"11801080426","pt":1723062183317,"mc":[{"id":"1.231540820","rc":[{"batb":[[0,1.97,10],[1,1.96,46.26],[2,1.32,3.28]],"ltp":2.0,"tv":88.69,"id":2219}]}]}
{"op":"mcm","clk":"11801080681","pt":1723062186711,"mc":[{"id":"1.231540820","rc":[{"batb":[[0,1.96,46.26],[1,1.32,3.28],[2,1.3,2.93]],"ltp":2.0,"tv":88.69,"id":2219}]}]}
{"op":"mcm","clk":"11801080913","pt":1723062189544,"mc":[{"id":"1.231540820","rc":[{"batb":[[0,1.97,10],[1,1.96,46.26],[2,1.32,3.28]],"ltp":2.0,"tv":88.69,"id":2219}]}]}
{"op":"mcm","clk":"11801081208","pt":1723062193046,"mc":[{"id":"1.231540820","rc":[{"batb":[[0,1.96,46.26],[1,1.32,3.28],[2,1.3,2.93]],"ltp":2.0,"tv":88.69,"id":2219}]}]}
{"op":"mcm","clk":"11801081473","pt":1723062196542,"mc":[{"id":"1.231540820","rc":[{"batb":[[0,1.97,10],[1,1.96,46.26],[2,1.32,3.28]],"ltp":2.0,"tv":88.69,"id":2219}]}]}
{"op":"mcm","clk":"11801081759","pt":1723062199844,"mc":[{"id":"1.231540820","rc":[{"batb":[[0,1.96,46.26],[1,1.32,3.28],[2,1.3,2.93]],"ltp":2.0,"tv":88.69,"id":2219}]}]}
{"op":"mcm","clk":"11801081947","pt":1723062202372,"mc":[{"id":"1.231540820","rc":[{"batb":[[0,1.97,10],[1,1.96,46.26],[2,1.32,3.28]],"ltp":2.0,"tv":88.69,"id":2219}]}]}
{"op":"mcm","clk":"11801082168","pt":1723062205765,"mc":[{"id":"1.231540820","rc":[{"batb":[[0,1.96,46.26],[1,1.32,3.28],[2,1.3,2.93]],"ltp":2.0,"tv":88.69,"id":2219}]}]}
{"op":"mcm","clk":"11801082411","pt":1723062209576,"mc":[{"id":"1.231540820","rc":[{"batb":[[0,1.97,10],[1,1.96,46.26],[2,1.32,3.28]],"ltp":2.0,"tv":88.69,"id":2219}]}]}
{"op":"mcm","clk":"11801082679","pt":1723062212974,"mc":[{"id":"1.231540820","rc":[{"batb":[[0,1.96,46.26],[1,1.32,3.28],[2,1.3,2.93]],"ltp":2.0,"tv":88.69,"id":2219}]}]}
{"op":"mcm","clk":"11801082924","pt":1723062215679,"mc":[{"id":"1.231540820","rc":[{"batb":[[0,1.97,10],[1,1.96,46.26],[2,1.32,3.28]],"ltp":2.0,"tv":88.69,"id":2219}]}]}
{"op":"mcm","clk":"11801083153","pt":1723062219002,"mc":[{"id":"1.231540820","rc":[{"batb":[[0,1.96,46.26],[1,1.32,3.28],[2,1.3,2.93]],"ltp":2.0,"tv":88.69,"id":2219}]}]}
{"op":"mcm","clk":"11801083337","pt":1723062221574,"mc":[{"id":"1.231540820","rc":[{"batb":[[0,1.97,10],[1,1.96,46.26],[2,1.32,3.28]],"ltp":2.0,"tv":88.69,"id":2219}]}]}
{"op":"mcm","clk":"11801083551","pt":1723062225118,"mc":[{"id":"1.231540820","rc":[{"batb":[[0,1.96,46.26],[1,1.32,3.28],[2,1.3,2.93]],"ltp":2.0,"tv":88.69,"id":2219}]}]}
{"op":"mcm","clk":"11801083711","pt":1723062227634,"mc":[{"id":"1.231540820","rc":[{"batb":[[0,1.97,10],[1,1.96,46.26],[2,1.32,3.28]],"ltp":2.0,"tv":88.69,"id":2219}]}]}
{"op":"mcm","clk":"11801083943","pt":1723062230918,"mc":[{"id":"1.231540820","rc":[{"batb":[[0,1.96,46.26],[1,1.32,3.28],[2,1.3,2.93]],"ltp":2.0,"tv":88.69,"id":2219}]}]}
{"op":"mcm","clk":"11801084126","pt":1723062233596,"mc":[{"id":"1.231540820","rc":[{"batb":[[0,1.97,10],[1,1.96,46.26],[2,1.32,3.28]],"ltp":2.0,"tv":88.69,"id":2219}]}]}
{"op":"mcm","clk":"11801084341","pt":1723062237243,"mc":[{"id":"1.231540820","rc":[{"batb":[[0,1.96,46.26],[1,1.32,3.28],[2,1.3,2.93]],"ltp":2.0,"tv":88.69,"id":2219}]}]}
{"op":"mcm","clk":"11801084565","pt":1723062240328,"mc":[{"id":"1.231540820","rc":[{"batb":[[0,1.97,10],[1,1.96,46.26],[2,1.32,3.28]],"ltp":2.0,"tv":88.69,"id":2219}]}]}
{"op":"mcm","clk":"11801084816","pt":1723062243822,"mc":[{"id":"1.231540820","rc":[{"batb":[[0,1.96,46.26],[1,1.32,3.28],[2,1.3,2.93]],"ltp":2.0,"tv":88.69,"id":2219}]}]}
{"op":"mcm","clk":"11801085052","pt":1723062246756,"mc":[{"id":"1.231540820","rc":[{"batb":[[0,1.97,10],[1,1.96,46.26],[2,1.32,3.28]],"ltp":2.0,"tv":88.69,"id":2219}]}]}
{"op":"mcm","clk":"11801085305","pt":1723062250157,"mc":[{"id":"1.231540820","rc":[{"batb":[[0,1.96,46.26],[1,1.32,3.28],[2,1.3,2.93]],"ltp":2.0,"tv":88.69,"id":2219}]}]}
{"op":"mcm","clk":"11801085521","pt":1723062253035,"mc":[{"id":"1.231540820","rc":[{"batb":[[0,1.97,10],[1,1.96,46.26],[2,1.32,3.28]],"ltp":2.0,"tv":88.69,"id":2219}]}]}
{"op":"mcm","clk":"11801085790","pt":1723062256473,"mc":[{"id":"1.231540820","rc":[{"batb":[[0,1.96,46.26],[1,1.32,3.28],[2,1.3,2.93]],"ltp":2.0,"tv":88.69,"id":2219}]}]}
{"op":"mcm","clk":"11801086035","pt":1723062259627,"mc":[{"id":"1.231540820","rc":[{"batb":[[0,1.97,10],[1,1.96,46.26],[2,1.32,3.28]],"ltp":2.0,"tv":88.69,"id":2219}]}]}
{"op":"mcm","clk":"11801086287","pt":1723062263132,"mc":[{"id":"1.231540820","rc":[{"batb":[[0,1.96,46.26],[1,1.32,3.28],[2,1.3,2.93]],"ltp":2.0,"tv":88.69,"id":2219}]}]}
{"op":"mcm","clk":"11801086559","pt":1723062267161,"mc":[{"id":"1.231540820","rc":[{"batb":[[0,1.97,10],[1,1.96,46.26],[2,1.32,3.28]],"ltp":2.0,"tv":88.69,"id":2219}]}]}
{"op":"mcm","clk":"11801086797","pt":1723062270342,"mc":[{"id":"1.231540820","rc":[{"batb":[[0,1.96,46.26],[1,1.32,3.28],[2,1.3,2.93]],"ltp":2.0,"tv":88.69,"id":2219}]}]}
{"op":"mcm","clk":"11801087027","pt":1723062273580,"mc":[{"id":"1.231540820","rc":[{"batb":[[0,1.97,10],[1,1.96,46.26],[2,1.32,3.28]],"ltp":2.0,"tv":88.69,"id":2219}]}]}
{"op":"mcm","clk":"11801087248","pt":1723062277076,"mc":[{"id":"1.231540820","rc":[{"batb":[[0,1.96,46.26],[1,1.32,3.28],[2,1.3,2.93]],"ltp":2.0,"tv":88.69,"id":2219}]}]}
{"op":"mcm","clk":"11801087471","pt":1723062280691,"mc":[{"id":"1.231540820","rc":[{"batb":[[0,1.97,10],[1,1.96,46.26],[2,1.32,3.28]],"ltp":2.0,"tv":88.69,"id":2219}]}]}
{"op":"mcm","clk":"11801087713","pt":1723062284292,"mc":[{"id":"1.231540820","rc":[{"batb":[[0,1.96,46.26],[1,1.32,3.28],[2,1.3,2.93]],"ltp":2.0,"tv":88.69,"id":2219}]}]}
{"op":"mcm","clk":"11801087967","pt":1723062287685,"mc":[{"id":"1.231540820","rc":[{"batb":[[0,1.97,10],[1,1.96,46.26],[2,1.32,3.28]],"ltp":2.0,"tv":88.69,"id":2219}]}]}
{"op":"mcm","clk":"11801088224","pt":1723062291290,"mc":[{"id":"1.231540820","rc":[{"batb":[[0,1.96,46.26],[1,1.32,3.28],[2,1.3,2.93]],"ltp":2.0,"tv":88.69,"id":2219}]}]}
{"op":"mcm","clk":"11801088422","pt":1723062294686,"mc":[{"id":"1.231540820","rc":[{"batb":[[0,1.97,10],[1,1.96,46.26],[2,1.32,3.28]],"ltp":2.0,"tv":88.69,"id":2219}]}]}
{"op":"mcm","clk":"11801088601","pt":1723062297980,"mc":[{"id":"1.231540820","rc":[{"batb":[[0,1.96,46.26],[1,1.32,3.28],[2,1.3,2.93]],"ltp":2.0,"tv":88.69,"id":2219}]}]}
{"op":"mcm","clk":"11801088742","pt":1723062300808,"mc":[{"id":"1.231540820","rc":[{"batb":[[0,1.97,10],[1,1.96,46.26],[2,1.32,3.28]],"ltp":2.0,"tv":88.69,"id":2219}]}]}
{"op":"mcm","clk":"11801088998","pt":1723062304517,"mc":[{"id":"1.231540820","rc":[{"batb":[[0,1.96,46.26],[1,1.32,3.28],[2,1.3,2.93]],"ltp":2.0,"tv":88.69,"id":2219}]}]}
{"op":"mcm","clk":"11801089226","pt":1723062307713,"mc":[{"id":"1.231540820","rc":[{"batb":[[0,1.97,10],[1,1.96,46.26],[2,1.32,3.28]],"ltp":2.0,"tv":88.69,"id":2219}]}]}
{"op":"mcm","clk":"11801089451","pt":1723062311106,"mc":[{"id":"1.231540820","rc":[{"batb":[[0,1.96,46.26],[1,1.32,3.28],[2,1.3,2.93]],"ltp":2.0,"tv":88.69,"id":2219}]}]}
{"op":"mcm","clk":"11801089652","pt":1723062313944,"mc":[{"id":"1.231540820","rc":[{"batb":[[0,1.97,10],[1,1.96,46.26],[2,1.32,3.28]],"ltp":2.0,"tv":88.69,"id":2219}]}]}
{"op":"mcm","clk":"11801089890","pt":1723062317447,"mc":[{"id":"1.231540820","rc":[{"batb":[[0,1.96,46.26],[1,1.32,3.28],[2,1.3,2.93]],"ltp":2.0,"tv":88.69,"id":2219}]}]}
{"op":"mcm","clk":"11801090063","pt":1723062319931,"mc":[{"id":"1.231540820","rc":[{"batb":[[0,1.97,10],[1,1.96,46.26],[2,1.32,3.28]],"ltp":2.0,"tv":88.69,"id":2219}]}]}
{"op":"mcm","clk":"11801090340","pt":1723062323729,"mc":[{"id":"1.231540820","rc":[{"batb":[[0,1.96,46.26],[1,1.32,3.28],[2,1.3,2.93]],"ltp":2.0,"tv":88.69,"id":2219}]}]}
{"op":"mcm","clk":"11801090517","pt":1723062326453,"mc":[{"id":"1.231540820","rc":[{"batb":[[0,1.97,10],[1,1.96,46.26],[2,1.32,3.28]],"ltp":2.0,"tv":88.69,"id":2219}]}]}
{"op":"mcm","clk":"11801090726","pt":1723062329951,"mc":[{"id":"1.231540820","rc":[{"batb":[[0,1.96,46.26],[1,1.32,3.28],[2,1.3,2.93]],"ltp":2.0,"tv":88.69,"id":2219}]}]}
{"op":"mcm","clk":"11801090893","pt":1723062332371,"mc":[{"id":"1.231540820","rc":[{"batb":[[0,1.97,10],[1,1.96,46.26],[2,1.32,3.28]],"ltp":2.0,"tv":88.69,"id":2219}]}]}
{"op":"mcm","clk":"11801091152","pt":1723062335970,"mc":[{"id":"1.231540820","rc":[{"batb":[[0,1.96,46.26],[1,1.32,3.28],[2,1.3,2.93]],"ltp":2.0,"tv":88.69,"id":2219}]}]}
{"op":"mcm","clk":"11801091317","pt":1723062338696,"mc":[{"id":"1.231540820","rc":[{"batb":[[0,1.97,10],[1,1.96,46.26],[2,1.32,3.28]],"ltp":2.0,"tv":88.69,"id":2219}]}]}
{"op":"mcm","clk":"11801091569","pt":1723062342149,"mc":[{"id":"1.231540820","rc":[{"batb":[[0,1.96,46.26],[1,1.32,3.28],[2,1.3,2.93]],"ltp":2.0,"tv":88.69,"id":2219}]}]}
{"op":"mcm","clk":"11801091738","pt":1723062344772,"mc":[{"id":"1.231540820","rc":[{"batb":[[0,1.97,10],[1,1.96,46.26],[2,1.32,3.28]],"ltp":2.0,"tv":88.69,"id":2219}]}]}
{"op":"mcm","clk":"11801091964","pt":1723062348176,"mc":[{"id":"1.231540820","rc":[{"batb":[[0,1.96,46.26],[1,1.32,3.28],[2,1.3,2.93]],"ltp":2.0,"tv":88.69,"id":2219}]}]}
{"op":"mcm","clk":"11801092221","pt":1723062351890,"mc":[{"id":"1.231540820","rc":[{"batb":[[0,1.97,10],[1,1.96,46.26],[2,1.32,3.28]],"ltp":2.0,"tv":88.69,"id":2219}]}]}
{"op":"mcm","clk":"11801092448","pt":1723062355479,"mc":[{"id":"1.231540820","rc":[{"batb":[[0,1.96,46.26],[1,1.32,3.28],[2,1.3,2.93]],"ltp":2.0,"tv":88.69,"id":2219}]}]}
{"op":"mcm","clk":"11801092625","pt":1723062358302,"mc":[{"id":"1.231540820","rc":[{"batb":[[0,1.97,10],[1,1.96,46.26],[2,1.32,3.28]],"ltp":2.0,"tv":88.69,"id":2219}]}]}
{"op":"mcm","clk":"11801092854","pt":1723062362022,"mc":[{"id":"1.231540820","rc":[{"batb":[[0,1.96,46.26],[1,1.32,3.28],[2,1.3,2.93]],"ltp":2.0,"tv":88.69,"id":2219}]}]}
{"op":"mcm","clk":"11801093077","pt":1723062365313,"mc":[{"id":"1.231540820","rc":[{"batb":[[0,1.97,10],[1,1.96,46.26],[2,1.32,3.28]],"ltp":2.0,"tv":88.69,"id":2219}]}]}
{"op":"mcm","clk":"11801093319","pt":1723062368810,"mc":[{"id":"1.231540820","rc":[{"batb":[[0,1.96,46.26],[1,1.32,3.28],[2,1.3,2.93]],"ltp":2.0,"tv":88.69,"id":2219}]}]}
{"op":"mcm","clk":"11801093482","pt":1723062371323,"mc":[{"id":"1.231540820","rc":[{"batb":[[0,1.97,10],[1,1.96,46.26],[2,1.32,3.28]],"ltp":2.0,"tv":88.69,"id":2219}]}]}
{"op":"mcm","clk":"11801093727","pt":1723062374834,"mc":[{"id":"1.231540820","rc":[{"batb":[[0,1.96,46.26],[1,1.32,3.28],[2,1.3,2.93]],"ltp":2.0,"tv":88.69,"id":2219}]}]}
{"op":"mcm","clk":"11801093954","pt":1723062378437,"mc":[{"id":"1.231540820","rc":[{"batb":[[0,1.97,10],[1,1.96,46.26],[2,1.32,3.28]],"ltp":2.0,"tv":88.69,"id":2219}]}]}
{"op":"mcm","clk":"11801094146","pt":1723062381722,"mc":[{"id":"1.231540820","rc":[{"batb":[[0,1.96,46.26],[1,1.32,3.28],[2,1.3,2.93]],"ltp":2.0,"tv":88.69,"id":2219}]}]}
{"op":"mcm","clk":"11801094318","pt":1723062384195,"mc":[{"id":"1.231540820","rc":[{"batb":[[0,1.97,10],[1,1.96,46.26],[2,1.32,3.28]],"ltp":2.0,"tv":88.69,"id":2219}]}]}
{"op":"mcm","clk":"11801094515","pt":1723062387542,"mc":[{"id":"1.231540820","rc":[{"batb":[[0,1.96,46.26],[1,1.32,3.28],[2,1.3,2.93]],"ltp":2.0,"tv":88.69,"id":2219}]}]}
{"op":"mcm","clk":"11801094685","pt":1723062390430,"mc":[{"id":"1.231540820","rc":[{"batb":[[0,1.97,10],[1,1.96,46.26],[2,1.32,3.28]],"ltp":2.0,"tv":88.69,"id":2219}]}]}
{"op":"mcm","clk":"11801094900","pt":1723062393936,"mc":[{"id":"1.231540820","rc":[{"batb":[[0,1.96,46.26],[1,1.32,3.28],[2,1.3,2.93]],"ltp":2.0,"tv":88.69,"id":2219}]}]}
{"op":"mcm","clk":"11801095036","pt":1723062396346,"mc":[{"id":"1.231540820","rc":[{"batb":[[0,1.97,10],[1,1.96,46.26],[2,1.32,3.28]],"ltp":2.0,"tv":88.69,"id":2219}]}]}
{"op":"mcm","clk":"11801095226","pt":1723062399733,"mc":[{"id":"1.231540820","rc":[{"batb":[[0,1.96,46.26],[1,1.32,3.28],[2,1.3,2.93]],"ltp":2.0,"tv":88.69,"id":2219}]}]}
{"op":"mcm","clk":"11801095630","pt":1723062405855,"mc":[{"id":"1.231540820","rc":[{"batb":[[0,1.97,10],[1,1.96,46.26],[2,1.32,3.28]],"ltp":2.0,"tv":88.69,"id":2219}]}]}
{"op":"mcm","clk":"11801095841","pt":1723062409248,"mc":[{"id":"1.231540820","rc":[{"batb":[[0,1.96,46.26],[1,1.32,3.28],[2,1.3,2.93]],"ltp":2.0,"tv":88.69,"id":2219}]}]}
{"op":"mcm","clk":"11801096153","pt":1723062414856,"mc":[{"id":"1.231540820","rc":[{"batb":[[0,1.97,10],[1,1.96,46.26],[2,1.32,3.28]],"ltp":2.0,"tv":88.69,"id":2219}]}]}
{"op":"mcm","clk":"11801096346","pt":1723062418155,"mc":[{"id":"1.231540820","rc":[{"batb":[[0,1.96,46.26],[1,1.32,3.28],[2,1.3,2.93]],"ltp":2.0,"tv":88.69,"id":2219}]}]}
{"op":"mcm","clk":"11801096539","pt":1723062421244,"mc":[{"id":"1.231540820","rc":[{"batb":[[0,1.97,10],[1,1.96,46.26],[2,1.32,3.28]],"ltp":2.0,"tv":88.69,"id":2219}]}]}
{"op":"mcm","clk":"11801096758","pt":1723062424751,"mc":[{"id":"1.231540820","rc":[{"batb":[[0,1.96,46.26],[1,1.32,3.28],[2,1.3,2.93]],"ltp":2.0,"tv":88.69,"id":2219}]}]}
{"op":"mcm","clk":"11801096996","pt":1723062428468,"mc":[{"id":"1.231540820","rc":[{"batb":[[0,1.97,10],[1,1.96,46.26],[2,1.32,3.28]],"ltp":2.0,"tv":88.69,"id":2219}]}]}
{"op":"mcm","clk":"11801097276","pt":1723062432590,"mc":[{"id":"1.231540820","rc":[{"batb":[[0,1.96,46.26],[1,1.32,3.28],[2,1.3,2.93]],"ltp":2.0,"tv":88.69,"id":2219}]}]}
{"op":"mcm","clk":"11801097441","pt":1723062435083,"mc":[{"id":"1.231540820","rc":[{"batb":[[0,1.97,10],[1,1.96,46.26],[2,1.32,3.28]],"ltp":2.0,"tv":88.69,"id":2219}]}]}
{"op":"mcm","clk":"11801097659","pt":1723062438396,"mc":[{"id":"1.231540820","rc":[{"batb":[[0,1.96,46.26],[1,1.32,3.28],[2,1.3,2.93]],"ltp":2.0,"tv":88.69,"id":2219}]}]}
{"op":"mcm","clk":"11801097814","pt":1723062440978,"mc":[{"id":"1.231540820","rc":[{"batb":[[0,1.97,10],[1,1.96,46.26],[2,1.32,3.28]],"ltp":2.0,"tv":88.69,"id":2219}]}]}
{"op":"mcm","clk":"11801098008","pt":1723062444473,"mc":[{"id":"1.231540820","rc":[{"batb":[[0,1.96,46.26],[1,1.32,3.28],[2,1.3,2.93]],"ltp":2.0,"tv":88.69,"id":2219}]}]}
{"op":"mcm","clk":"11801098158","pt":1723062446908,"mc":[{"id":"1.231540820","rc":[{"batb":[[0,1.97,10],[1,1.96,46.26],[2,1.32,3.28]],"ltp":2.0,"tv":88.69,"id":2219}]}]}
{"op":"mcm","clk":"11801098364","pt":1723062450321,"mc":[{"id":"1.231540820","rc":[{"batb":[[0,1.96,46.26],[1,1.32,3.28],[2,1.3,2.93]],"ltp":2.0,"tv":88.69,"id":2219}]}]}
{"op":"mcm","clk":"11801098566","pt":1723062452905,"mc":[{"id":"1.231540820","rc":[{"batb":[[0,1.97,10],[1,1.96,46.26],[2,1.32,3.28]],"ltp":2.0,"tv":88.69,"id":2219}]}]}
{"op":"mcm","clk":"11801098788","pt":1723062456210,"mc":[{"id":"1.231540820","rc":[{"batb":[[0,1.96,46.26],[1,1.32,3.28],[2,1.3,2.93]],"ltp":2.0,"tv":88.69,"id":2219}]}]}
{"op":"mcm","clk":"11801098961","pt":1723062458889,"mc":[{"id":"1.231540820","rc":[{"batb":[[0,1.97,10],[1,1.96,46.26],[2,1.32,3.28]],"ltp":2.0,"tv":88.69,"id":2219}]}]}
{"op":"mcm","clk":"11801099151","pt":1723062462590,"mc":[{"id":"1.231540820","rc":[{"batb":[[0,1.96,46.26],[1,1.32,3.28],[2,1.3,2.93]],"ltp":2.0,"tv":88.69,"id":2219}]}]}
{"op":"mcm","clk":"11801099355","pt":1723062466305,"mc":[{"id":"1.231540820","rc":[{"batb":[[0,1.97,10],[1,1.96,46.26],[2,1.32,3.28]],"ltp":2.0,"tv":88.69,"id":2219}]}]}
{"op":"mcm","clk":"11801099556","pt":1723062469509,"mc":[{"id":"1.231540820","rc":[{"batb":[[0,1.96,46.26],[1,1.32,3.28],[2,1.3,2.93]],"ltp":2.0,"tv":88.69,"id":2219}]}]}
{"op":"mcm","clk":"11801099772","pt":1723062473136,"mc":[{"id":"1.231540820","rc":[{"batb":[[0,1.97,10],[1,1.96,46.26],[2,1.32,3.28]],"ltp":2.0,"tv":88.69,"id":2219}]}]}
{"op":"mcm","clk":"11801099984","pt":1723062476549,"mc":[{"id":"1.231540820","rc":[{"batb":[[0,1.96,46.26],[1,1.32,3.28],[2,1.3,2.93]],"ltp":2.0,"tv":88.69,"id":2219}]}]}
{"op":"mcm","clk":"11801100141","pt":1723062479014,"mc":[{"id":"1.231540820","rc":[{"batb":[[0,1.97,10],[1,1.96,46.26],[2,1.32,3.28]],"ltp":2.0,"tv":88.69,"id":2219}]}]}
{"op":"mcm","clk":"11801100360","pt":1723062482231,"mc":[{"id":"1.231540820","rc":[{"batb":[[0,1.96,46.26],[1,1.32,3.28],[2,1.3,2.93]],"ltp":2.0,"tv":88.69,"id":2219}]}]}
{"op":"mcm","clk":"11801100534","pt":1723062485020,"mc":[{"id":"1.231540820","rc":[{"batb":[[0,1.97,10],[1,1.96,46.26],[2,1.32,3.28]],"ltp":2.0,"tv":88.69,"id":2219}]}]}
{"op":"mcm","clk":"11801100778","pt":1723062488737,"mc":[{"id":"1.231540820","rc":[{"batb":[[0,1.96,46.26],[1,1.32,3.28],[2,1.3,2.93]],"ltp":2.0,"tv":88.69,"id":2219}]}]}
{"op":"mcm","clk":"11801100985","pt":1723062491937,"mc":[{"id":"1.231540820","rc":[{"batb":[[0,1.97,10],[1,1.96,46.26],[2,1.32,3.28]],"ltp":2.0,"tv":88.69,"id":2219}]}]}
{"op":"mcm","clk":"11801101206","pt":1723062495280,"mc":[{"id":"1.231540820","rc":[{"batb":[[0,1.96,46.26],[1,1.32,3.28],[2,1.3,2.93]],"ltp":2.0,"tv":88.69,"id":2219}]}]}
{"op":"mcm","clk":"11801101431","pt":1723062498278,"mc":[{"id":"1.231540820","rc":[{"batb":[[0,1.97,10],[1,1.96,46.26],[2,1.32,3.28]],"ltp":2.0,"tv":88.69,"id":2219}]}]}
{"op":"mcm","clk":"11801101683","pt":1723062501779,"mc":[{"id":"1.231540820","rc":[{"batb":[[0,1.96,46.26],[1,1.32,3.28],[2,1.3,2.93]],"ltp":2.0,"tv":88.69,"id":2219}]}]}
{"op":"mcm","clk":"11801101863","pt":1723062504766,"mc":[{"id":"1.231540820","rc":[{"batb":[[0,1.97,10],[1,1.96,46.26],[2,1.32,3.28]],"ltp":2.0,"tv":88.69,"id":2219}]}]}
{"op":"mcm","clk":"11801101992","pt":1723062508163,"mc":[{"id":"1.231540820","rc":[{"batb":[[0,1.96,46.26],[1,1.32,3.28],[2,1.3,2.93]],"ltp":2.0,"tv":88.69,"id":2219}]}]}
{"op":"mcm","clk":"11801102147","pt":1723062511388,"mc":[{"id":"1.231540820","rc":[{"batb":[[0,1.97,10],[1,1.96,46.26],[2,1.32,3.28]],"ltp":2.0,"tv":88.69,"id":2219}]}]}
{"op":"mcm","clk":"11801102333","pt":1723062514675,"mc":[{"id":"1.231540820","rc":[{"batb":[[0,1.96,46.26],[1,1.32,3.28],[2,1.3,2.93]],"ltp":2.0,"tv":88.69,"id":2219}]}]}
{"op":"mcm","clk":"11801102490","pt":1723062517759,"mc":[{"id":"1.231540820","rc":[{"batb":[[0,1.97,10],[1,1.96,46.26],[2,1.32,3.28]],"ltp":2.0,"tv":88.69,"id":2219}]}]}
{"op":"mcm","clk":"11801102694","pt":1723062521708,"mc":[{"id":"1.231540820","rc":[{"batb":[[0,1.96,46.26],[1,1.32,3.28],[2,1.3,2.93]],"ltp":2.0,"tv":88.69,"id":2219}]}]}
{"op":"mcm","clk":"11801102920","pt":1723062525811,"mc":[{"id":"1.231540820","rc":[{"batb":[[0,1.97,10],[1,1.96,46.26],[2,1.32,3.28]],"ltp":2.0,"tv":88.69,"id":2219}]}]}
{"op":"mcm","clk":"11801103128","pt":1723062529107,"mc":[{"id":"1.231540820","rc":[{"batb":[[0,1.96,46.26],[1,1.32,3.28],[2,1.3,2.93]],"ltp":2.0,"tv":88.69,"id":2219}]}]}
{"op":"mcm","clk":"11801103460","pt":1723062535784,"mc":[{"id":"1.231540820","rc":[{"batb":[[0,1.97,10],[1,1.96,46.26],[2,1.32,3.28]],"ltp":2.0,"tv":88.69,"id":2219}]}]}
{"op":"mcm","clk":"11801103642","pt":1723062539218,"mc":[{"id":"1.231540820","rc":[{"batb":[[0,1.96,46.26],[1,1.32,3.28],[2,1.3,2.93]],"ltp":2.0,"tv":88.69,"id":2219}]}]}
{"op":"mcm","clk":"11801103830","pt":1723062542407,"mc":[{"id":"1.231540820","rc":[{"batb":[[0,1.97,10],[1,1.96,46.26],[2,1.32,3.28]],"ltp":2.0,"tv":88.69,"id":2219}]}]}
{"op":"mcm","clk":"11801103983","pt":1723062545618,"mc":[{"id":"1.231540820","rc":[{"batb":[[0,1.96,46.26],[1,1.32,3.28],[2,1.3,2.93]],"ltp":2.0,"tv":88.69,"id":2219}]}]}
{"op":"mcm","clk":"11801104124","pt":1723062548037,"mc":[{"id":"1.231540820","rc":[{"batb":[[0,1.97,10],[1,1.96,46.26],[2,1.32,3.28]],"ltp":2.0,"tv":88.69,"id":2219}]}]}
{"op":"mcm","clk":"11801104325","pt":1723062551435,"mc":[{"id":"1.231540820","rc":[{"batb":[[0,1.96,46.26],[1,1.32,3.28],[2,1.3,2.93]],"ltp":2.0,"tv":88.69,"id":2219}]}]}
{"op":"mcm","clk":"11801104483","pt":1723062554355,"mc":[{"id":"1.231540820","rc":[{"batb":[[0,1.97,10],[1,1.96,46.26],[2,1.32,3.28]],"ltp":2.0,"tv":88.69,"id":2219}]}]}
{"op":"mcm","clk":"11801104631","pt":1723062557542,"mc":[{"id":"1.231540820","rc":[{"batb":[[0,1.96,46.26],[1,1.32,3.28],[2,1.3,2.93]],"ltp":2.0,"tv":88.69,"id":2219}]}]}
{"op":"mcm","clk":"11801104820","pt":1723062561443,"mc":[{"id":"1.231540820","rc":[{"batb":[[0,1.97,10],[1,1.96,46.26],[2,1.32,3.28]],"ltp":2.0,"tv":88.69,"id":2219}]}]}
{"op":"mcm","clk":"11801105001","pt":1723062564741,"mc":[{"id":"1.231540820","rc":[{"batb":[[0,1.96,46.26],[1,1.32,3.28],[2,1.3,2.93]],"ltp":2.0,"tv":88.69,"id":2219}]}]}
{"op":"mcm","clk":"11801105194","pt":1723062568242,"mc":[{"id":"1.231540820","rc":[{"batb":[[0,1.97,10],[1,1.96,46.26],[2,1.32,3.28]],"ltp":2.0,"tv":88.69,"id":2219}]}]}
{"op":"mcm","clk":"11801105427","pt":1723062572148,"mc":[{"id":"1.231540820","rc":[{"batb":[[0,1.96,46.26],[1,1.32,3.28],[2,1.3,2.93]],"ltp":2.0,"tv":88.69,"id":2219}]}]}
{"op":"mcm","clk":"11801105572","pt":1723062574874,"mc":[{"id":"1.231540820","rc":[{"batb":[[0,1.97,10],[1,1.96,46.26],[2,1.32,3.28]],"ltp":2.0,"tv":88.69,"id":2219}]}]}
{"op":"mcm","clk":"11801105760","pt":1723062578168,"mc":[{"id":"1.231540820","rc":[{"batb":[[0,1.96,46.26],[1,1.32,3.28],[2,1.3,2.93]],"ltp":2.0,"tv":88.69,"id":2219}]}]}
{"op":"mcm","clk":"11801105900","pt":1723062581147,"mc":[{"id":"1.231540820","rc":[{"batb":[[0,1.97,10],[1,1.96,46.26],[2,1.32,3.28]],"ltp":2.0,"tv":88.69,"id":2219}]}]}
{"op":"mcm","clk":"11801106075","pt":1723062584587,"mc":[{"id":"1.231540820","rc":[{"batb":[[0,1.96,46.26],[1,1.32,3.28],[2,1.3,2.93]],"ltp":2.0,"tv":88.69,"id":2219}]}]}
{"op":"mcm","clk":"11801106322","pt":1723062588367,"mc":[{"id":"1.231540820","rc":[{"batb":[[0,1.97,10],[1,1.96,46.26],[2,1.32,3.28]],"ltp":2.0,"tv":88.69,"id":2219}]}]}
{"op":"mcm","clk":"11801106495","pt":1723062591701,"mc":[{"id":"1.231540820","rc":[{"batb":[[0,1.96,46.26],[1,1.32,3.28],[2,1.3,2.93]],"ltp":2.0,"tv":88.69,"id":2219}]}]}
{"op":"mcm","clk":"11801106633","pt":1723062594680,"mc":[{"id":"1.231540820","rc":[{"batb":[[0,1.97,10],[1,1.96,46.26],[2,1.32,3.28]],"ltp":2.0,"tv":88.69,"id":2219}]}]}
{"op":"mcm","clk":"11801106799","pt":1723062597977,"mc":[{"id":"1.231540820","rc":[{"batb":[[0,1.96,46.26],[1,1.32,3.28],[2,1.3,2.93]],"ltp":2.0,"tv":88.69,"id":2219}]}]}
{"op":"mcm","clk":"11801106899","pt":1723062600289,"mc":[{"id":"1.231540820","rc":[{"batb":[[0,1.97,10],[1,1.96,46.26],[2,1.32,3.28]],"ltp":2.0,"tv":88.69,"id":2219}]}]}
{"op":"mcm","clk":"11801107105","pt":1723062603384,"mc":[{"id":"1.231540820","rc":[{"batb":[[0,1.96,46.26],[1,1.32,3.28],[2,1.3,2.93]],"ltp":2.0,"tv":88.69,"id":2219}]}]}
{"op":"mcm","clk":"11801107253","pt":1723062605806,"mc":[{"id":"1.231540820","rc":[{"batb":[[0,1.97,10],[1,1.96,46.26],[2,1.32,3.28]],"ltp":2.0,"tv":88.69,"id":2219}]}]}
{"op":"mcm","clk":"11801107439","pt":1723062609098,"mc":[{"id":"1.231540820","rc":[{"batb":[[0,1.96,46.26],[1,1.32,3.28],[2,1.3,2.93]],"ltp":2.0,"tv":88.69,"id":2219}]}]}
{"op":"mcm","clk":"11801107608","pt":1723062612137,"mc":[{"id":"1.231540820","rc":[{"batb":[[0,1.97,10],[1,1.96,46.26],[2,1.32,3.28]],"ltp":2.0,"tv":88.69,"id":2219}]}]}
{"op":"mcm","clk":"11801107823","pt":1723062615539,"mc":[{"id":"1.231540820","rc":[{"batb":[[0,1.96,46.26],[1,1.32,3.28],[2,1.3,2.93]],"ltp":2.0,"tv":88.69,"id":2219}]}]}
{"op":"mcm","clk":"11801108053","pt":1723062619550,"mc":[{"id":"1.231540820","rc":[{"batb":[[0,1.97,10],[1,1.96,46.26],[2,1.32,3.28]],"ltp":2.0,"tv":88.69,"id":2219}]}]}
{"op":"mcm","clk":"11801108228","pt":1723062622740,"mc":[{"id":"1.231540820","rc":[{"batb":[[0,1.96,46.26],[1,1.32,3.28],[2,1.3,2.93]],"ltp":2.0,"tv":88.69,"id":2219}]}]}
{"op":"mcm","clk":"11801108454","pt":1723062626850,"mc":[{"id":"1.231540820","rc":[{"batb":[[0,1.97,10],[1,1.96,46.26],[2,1.32,3.28]],"ltp":2.0,"tv":88.69,"id":2219}]}]}
{"op":"mcm","clk":"11801108625","pt":1723062630343,"mc":[{"id":"1.231540820","rc":[{"batb":[[0,1.96,46.26],[1,1.32,3.28],[2,1.3,2.93]],"ltp":2.0,"tv":88.69,"id":2219}]}]}
{"op":"mcm","clk":"11801108793","pt":1723062633281,"mc":[{"id":"1.231540820","rc":[{"batb":[[0,1.97,10],[1,1.96,46.26],[2,1.32,3.28]],"ltp":2.0,"tv":88.69,"id":2219}]}]}
{"op":"mcm","clk":"11801108990","pt":1723062636878,"mc":[{"id":"1.231540820","rc":[{"batb":[[0,1.96,46.26],[1,1.32,3.28],[2,1.3,2.93]],"ltp":2.0,"tv":88.69,"id":2219}]}]}
{"op":"mcm","clk":"11801109175","pt":1723062639967,"mc":[{"id":"1.231540820","rc":[{"batb":[[0,1.97,10],[1,1.96,46.26],[2,1.32,3.28]],"ltp":2.0,"tv":88.69,"id":2219}]}]}
{"op":"mcm","clk":"11801109384","pt":1723062643265,"mc":[{"id":"1.231540820","rc":[{"batb":[[0,1.96,46.26],[1,1.32,3.28],[2,1.3,2.93]],"ltp":2.0,"tv":88.69,"id":2219}]}]}
{"op":"mcm","clk":"11801109543","pt":1723062645890,"mc":[{"id":"1.231540820","rc":[{"batb":[[0,1.97,10],[1,1.96,46.26],[2,1.32,3.28]],"ltp":2.0,"tv":88.69,"id":2219}]}]}
{"op":"mcm","clk":"11801109714","pt":1723062649186,"mc":[{"id":"1.231540820","rc":[{"batb":[[0,1.96,46.26],[1,1.32,3.28],[2,1.3,2.93]],"ltp":2.0,"tv":88.69,"id":2219}]}]}
{"op":"mcm","clk":"11801109978","pt":1723062653306,"mc":[{"id":"1.231540820","rc":[{"batb":[[0,1.97,10],[1,1.96,46.26],[2,1.32,3.28]],"ltp":2.0,"tv":88.69,"id":2219}]}]}
{"op":"mcm","clk":"11801110168","pt":1723062656599,"mc":[{"id":"1.231540820","rc":[{"batb":[[0,1.96,46.26],[1,1.32,3.28],[2,1.3,2.93]],"ltp":2.0,"tv":88.69,"id":2219}]}]}
{"op":"mcm","clk":"11801110317","pt":1723062659116,"mc":[{"id":"1.231540820","rc":[{"batb":[[0,1.97,10],[1,1.96,46.26],[2,1.32,3.28]],"ltp":2.0,"tv":88.69,"id":2219}]}]}
{"op":"mcm","clk":"11801110525","pt":1723062662615,"mc":[{"id":"1.231540820","rc":[{"batb":[[0,1.96,46.26],[1,1.32,3.28],[2,1.3,2.93]],"ltp":2.0,"tv":88.69,"id":2219}]}]}
{"op":"mcm","clk":"11801110700","pt":1723062665293,"mc":[{"id":"1.231540820","rc":[{"batb":[[0,1.97,10],[1,1.96,46.26],[2,1.32,3.28]],"ltp":2.0,"tv":88.69,"id":2219}]}]}
{"op":"mcm","clk":"11801110908","pt":1723062668789,"mc":[{"id":"1.231540820","rc":[{"batb":[[0,1.96,46.26],[1,1.32,3.28],[2,1.3,2.93]],"ltp":2.0,"tv":88.69,"id":2219}]}]}
{"op":"mcm","clk":"11801111045","pt":1723062671714,"mc":[{"id":"1.231540820","rc":[{"batb":[[0,1.97,10],[1,1.96,46.26],[2,1.32,3.28]],"ltp":2.0,"tv":88.69,"id":2219}]}]}
{"op":"mcm","clk":"11801111201","pt":1723062675204,"mc":[{"id":"1.231540820","rc":[{"batb":[[0,1.96,46.26],[1,1.32,3.28],[2,1.3,2.93]],"ltp":2.0,"tv":88.69,"id":2219}]}]}
{"op":"mcm","clk":"11801111373","pt":1723062678439,"mc":[{"id":"1.231540820","rc":[{"batb":[[0,1.97,10],[1,1.96,46.26],[2,1.32,3.28]],"ltp":2.0,"tv":88.69,"id":2219}]}]}
{"op":"mcm","clk":"11801111626","pt":1723062683122,"mc":[{"id":"1.231540820","rc":[{"batb":[[0,1.96,46.26],[1,1.32,3.28],[2,1.3,2.93]],"ltp":2.0,"tv":88.69,"id":2219}]}]}
{"op":"mcm","clk":"11801111879","pt":1723062687548,"mc":[{"id":"1.231540820","rc":[{"batb":[[0,1.97,10],[1,1.96,46.26],[2,1.32,3.28]],"ltp":2.0,"tv":88.69,"id":2219}]}]}
{"op":"mcm","clk":"11801112055","pt":1723062690942,"mc":[{"id":"1.231540820","rc":[{"batb":[[0,1.96,46.26],[1,1.32,3.28],[2,1.3,2.93]],"ltp":2.0,"tv":88.69,"id":2219}]}]}
{"op":"mcm","clk":"11801112212","pt":1723062694026,"mc":[{"id":"1.231540820","rc":[{"batb":[[0,1.97,10],[1,1.96,46.26],[2,1.32,3.28]],"ltp":2.0,"tv":88.69,"id":2219}]}]}
{"op":"mcm","clk":"11801112398","pt":1723062697366,"mc":[{"id":"1.231540820","rc":[{"batb":[[0,1.96,46.26],[1,1.32,3.28],[2,1.3,2.93]],"ltp":2.0,"tv":88.69,"id":2219}]}]}
{"op":"mcm","clk":"11801112598","pt":1723062701060,"mc":[{"id":"1.231540820","rc":[{"batb":[[0,1.97,10],[1,1.96,46.26],[2,1.32,3.28]],"ltp":2.0,"tv":88.69,"id":2219}]}]}
{"op":"mcm","clk":"11801112797","pt":1723062704457,"mc":[{"id":"1.231540820","rc":[{"batb":[[0,1.96,46.26],[1,1.32,3.28],[2,1.3,2.93]],"ltp":2.0,"tv":88.69,"id":2219}]}]}
{"op":"mcm","clk":"11801112929","pt":1723062707276,"mc":[{"id":"1.231540820","rc":[{"batb":[[0,1.97,10],[1,1.96,46.26],[2,1.32,3.28]],"ltp":2.0,"tv":88.69,"id":2219}]}]}
{"op":"mcm","clk":"11801113129","pt":1723062710781,"mc":[{"id":"1.231540820","rc":[{"batb":[[0,1.96,46.26],[1,1.32,3.28],[2,1.3,2.93]],"ltp":2.0,"tv":88.69,"id":2219}]}]}
{"op":"mcm","clk":"11801113323","pt":1723062714077,"mc":[{"id":"1.231540820","rc":[{"batb":[[0,1.97,10],[1,1.96,46.26],[2,1.32,3.28]],"ltp":2.0,"tv":88.69,"id":2219}]}]}
{"op":"mcm","clk":"11801113497","pt":1723062717371,"mc":[{"id":"1.231540820","rc":[{"batb":[[0,1.96,46.26],[1,1.32,3.28],[2,1.3,2.93]],"ltp":2.0,"tv":88.69,"id":2219}]}]}
{"op":"mcm","clk":"11801113646","pt":1723062719989,"mc":[{"id":"1.231540820","rc":[{"batb":[[0,1.97,10],[1,1.96,46.26],[2,1.32,3.28]],"ltp":2.0,"tv":88.69,"id":2219}]}]}
{"op":"mcm","clk":"11801113853","pt":1723062723498,"mc":[{"id":"1.231540820","rc":[{"batb":[[0,1.96,46.26],[1,1.32,3.28],[2,1.3,2.93]],"ltp":2.0,"tv":88.69,"id":2219}]}]}
{"op":"mcm","clk":"11801114014","pt":1723062726282,"mc":[{"id":"1.231540820","rc":[{"batb":[[0,1.97,10],[1,1.96,46.26],[2,1.32,3.28]],"ltp":2.0,"tv":88.69,"id":2219}]}]}
{"op":"mcm","clk":"11801114205","pt":1723062729580,"mc":[{"id":"1.231540820","rc":[{"batb":[[0,1.96,46.26],[1,1.32,3.28],[2,1.3,2.93]],"ltp":2.0,"tv":88.69,"id":2219}]}]}
{"op":"mcm","clk":"11801114339","pt":1723062731892,"mc":[{"id":"1.231540820","rc":[{"batb":[[0,1.97,10],[1,1.96,46.26],[2,1.32,3.28]],"ltp":2.0,"tv":88.69,"id":2219}]}]}
{"op":"mcm","clk":"11801114553","pt":1723062735290,"mc":[{"id":"1.231540820","rc":[{"batb":[[0,1.96,46.26],[1,1.32,3.28],[2,1.3,2.93]],"ltp":2.0,"tv":88.69,"id":2219}]}]}
{"op":"mcm","clk":"11801114741","pt":1723062738220,"mc":[{"id":"1.231540820","rc":[{"batb":[[0,1.97,10],[1,1.96,46.26],[2,1.32,3.28]],"ltp":2.0,"tv":88.69,"id":2219}]}]}
{"op":"mcm","clk":"11801114957","pt":1723062741625,"mc":[{"id":"1.231540820","rc":[{"batb":[[0,1.96,46.26],[1,1.32,3.28],[2,1.3,2.93]],"ltp":2.0,"tv":88.69,"id":2219}]}]}
{"op":"mcm","clk":"11801115123","pt":1723062744307,"mc":[{"id":"1.231540820","rc":[{"batb":[[0,1.97,10],[1,1.96,46.26],[2,1.32,3.28]],"ltp":2.0,"tv":88.69,"id":2219}]}]}
{"op":"mcm","clk":"11801115321","pt":1723062747700,"mc":[{"id":"1.231540820","rc":[{"batb":[[0,1.96,46.26],[1,1.32,3.28],[2,1.3,2.93]],"ltp":2.0,"tv":88.69,"id":2219}]}]}
{"op":"mcm","clk":"11801115465","pt":1723062750628,"mc":[{"id":"1.231540820","rc":[{"batb":[[0,1.97,10],[1,1.96,46.26],[2,1.32,3.28]],"ltp":2.0,"tv":88.69,"id":2219}]}]}
{"op":"mcm","clk":"11801115700","pt":1723062754801,"mc":[{"id":"1.231540820","rc":[{"batb":[[0,1.96,46.26],[1,1.32,3.28],[2,1.3,2.93]],"ltp":2.0,"tv":88.69,"id":2219}]}]}
{"op":"mcm","clk":"11801115866","pt":1723062757698,"mc":[{"id":"1.231540820","rc":[{"batb":[[0,1.97,10],[1,1.96,46.26],[2,1.32,3.28]],"ltp":2.0,"tv":88.69,"id":2219}]}]}
{"op":"mcm","clk":"11801116067","pt":1723062761134,"mc":[{"id":"1.231540820","rc":[{"batb":[[0,1.96,46.26],[1,1.32,3.28],[2,1.3,2.93]],"ltp":2.0,"tv":88.69,"id":2219}]}]}
{"op":"mcm","clk":"11801116302","pt":1723062765308,"mc":[{"id":"1.231540820","rc":[{"batb":[[0,1.97,10],[1,1.96,46.26],[2,1.32,3.28]],"ltp":2.0,"tv":88.69,"id":2219}]}]}
{"op":"mcm","clk":"11801116491","pt":1723062768928,"mc":[{"id":"1.231540820","rc":[{"batb":[[0,1.96,46.26],[1,1.32,3.28],[2,1.3,2.93]],"ltp":2.0,"tv":88.69,"id":2219}]}]}
{"op":"mcm","clk":"11801116649","pt":1723062771909,"mc":[{"id":"1.231540820","rc":[{"batb":[[0,1.97,10],[1,1.96,46.26],[2,1.32,3.28]],"ltp":2.0,"tv":88.69,"id":2219}]}]}
{"op":"mcm","clk":"11801116846","pt":1723062775554,"mc":[{"id":"1.231540820","rc":[{"batb":[[0,1.96,46.26],[1,1.32,3.28],[2,1.3,2.93]],"ltp":2.0,"tv":88.69,"id":2219}]}]}
{"op":"mcm","clk":"11801117004","pt":1723062778439,"mc":[{"id":"1.231540820","rc":[{"batb":[[0,1.97,10],[1,1.96,46.26],[2,1.32,3.28]],"ltp":2.0,"tv":88.69,"id":2219}]}]}
{"op":"mcm","clk":"11801117214","pt":1723062781937,"mc":[{"id":"1.231540820","rc":[{"batb":[[0,1.96,46.26],[1,1.32,3.28],[2,1.3,2.93]],"ltp":2.0,"tv":88.69,"id":2219}]}]}
{"op":"mcm","clk":"11801117365","pt":1723062784459,"mc":[{"id":"1.231540820","rc":[{"batb":[[0,1.97,10],[1,1.96,46.26],[2,1.32,3.28]],"ltp":2.0,"tv":88.69,"id":2219}]}]}
{"op":"mcm","clk":"11801117552","pt":1723062787757,"mc":[{"id":"1.231540820","rc":[{"batb":[[0,1.96,46.26],[1,1.32,3.28],[2,1.3,2.93]],"ltp":2.0,"tv":88.69,"id":2219}]}]}
{"op":"mcm","clk":"11801117712","pt":1723062790451,"mc":[{"id":"1.231540820","rc":[{"batb":[[0,1.97,10],[1,1.96,46.26],[2,1.32,3.28]],"ltp":2.0,"tv":88.69,"id":2219}]}]}
{"op":"mcm","clk":"11801117893","pt":1723062793857,"mc":[{"id":"1.231540820","rc":[{"batb":[[0,1.96,46.26],[1,1.32,3.28],[2,1.3,2.93]],"ltp":2.0,"tv":88.69,"id":2219}]}]}
{"op":"mcm","clk":"11801118082","pt":1723062797051,"mc":[{"id":"1.231540820","rc":[{"batb":[[0,1.97,10],[1,1.96,46.26],[2,1.32,3.28]],"ltp":2.0,"tv":88.69,"id":2219}]}]}
{"op":"mcm","clk":"11801118308","pt":1723062800963,"mc":[{"id":"1.231540820","rc":[{"batb":[[0,1.96,46.26],[1,1.32,3.28],[2,1.3,2.93]],"ltp":2.0,"tv":88.69,"id":2219}]}]}
{"op":"mcm","clk":"11801118520","pt":1723062804564,"mc":[{"id":"1.231540820","rc":[{"batb":[[0,1.97,10],[1,1.96,46.26],[2,1.32,3.28]],"ltp":2.0,"tv":88.69,"id":2219}]}]}
{"op":"mcm","clk":"11801118727","pt":1723062808160,"mc":[{"id":"1.231540820","rc":[{"batb":[[0,1.96,46.26],[1,1.32,3.28],[2,1.3,2.93]],"ltp":2.0,"tv":88.69,"id":2219}]}]}
{"op":"mcm","clk":"11801118987","pt":1723062812377,"mc":[{"id":"1.231540820","rc":[{"batb":[[0,1.97,10],[1,1.96,46.26],[2,1.32,3.28]],"ltp":2.0,"tv":88.69,"id":2219}]}]}
{"op":"mcm","clk":"11801119207","pt":1723062815775,"mc":[{"id":"1.231540820","rc":[{"batb":[[0,1.96,46.26],[1,1.32,3.28],[2,1.3,2.93]],"ltp":2.0,"tv":88.69,"id":2219}]}]}
{"op":"mcm","clk":"11801119596","pt":1723062822151,"mc":[{"id":"1.231540820","rc":[{"batb":[[0,1.97,10],[1,1.96,46.26],[2,1.32,3.28]],"ltp":2.0,"tv":88.69,"id":2219}]}]}
{"op":"mcm","clk":"11801119804","pt":1723062825495,"mc":[{"id":"1.231540820","rc":[{"batb":[[0,1.96,46.26],[1,1.32,3.28],[2,1.3,2.93]],"ltp":2.0,"tv":88.69,"id":2219}]}]}
{"op":"mcm","clk":"11801120118","pt":1723062830180,"mc":[{"id":"1.231540820","rc":[{"batb":[[0,1.97,10],[1,1.96,46.26],[2,1.32,3.28]],"ltp":2.0,"tv":88.69,"id":2219}]}]}
{"op":"mcm","clk":"11801120378","pt":1723062833574,"mc":[{"id":"1.231540820","rc":[{"batb":[[0,1.96,46.26],[1,1.32,3.28],[2,1.3,2.93]],"ltp":2.0,"tv":88.69,"id":2219}]}]}
{"op":"mcm","clk":"11801120562","pt":1723062836096,"mc":[{"id":"1.231540820","rc":[{"batb":[[0,1.97,10],[1,1.96,46.26],[2,1.32,3.28]],"ltp":2.0,"tv":88.69,"id":2219}]}]}
{"op":"mcm","clk":"11801120788","pt":1723062839598,"mc":[{"id":"1.231540820","rc":[{"batb":[[0,1.96,46.26],[1,1.32,3.28],[2,1.3,2.93]],"ltp":2.0,"tv":88.69,"id":2219}]}]}
{"op":"mcm","clk":"11801121009","pt":1723062842690,"mc":[{"id":"1.231540820","rc":[{"batb":[[0,1.97,10],[1,1.96,46.26],[2,1.32,3.28]],"ltp":2.0,"tv":88.69,"id":2219}]}]}
{"op":"mcm","clk":"11801121232","pt":1723062846196,"mc":[{"id":"1.231540820","rc":[{"batb":[[0,1.96,46.26],[1,1.32,3.28],[2,1.3,2.93]],"ltp":2.0,"tv":88.69,"id":2219}]}]}
{"op":"mcm","clk":"11801121402","pt":1723062848917,"mc":[{"id":"1.231540820","rc":[{"batb":[[0,1.97,10],[1,1.96,46.26],[2,1.32,3.28]],"ltp":2.0,"tv":88.69,"id":2219}]}]}
{"op":"mcm","clk":"11801121600","pt":1723062852210,"mc":[{"id":"1.231540820","rc":[{"batb":[[0,1.96,46.26],[1,1.32,3.28],[2,1.3,2.93]],"ltp":2.0,"tv":88.69,"id":2219}]}]}
{"op":"mcm","clk":"11801121793","pt":1723062855809,"mc":[{"id":"1.231540820","rc":[{"batb":[[0,1.97,10],[1,1.96,46.26],[2,1.32,3.28]],"ltp":2.0,"tv":88.69,"id":2219}]}]}
{"op":"mcm","clk":"11801122037","pt":1723062859112,"mc":[{"id":"1.231540820","rc":[{"batb":[[0,1.96,46.26],[1,1.32,3.28],[2,1.3,2.93]],"ltp":2.0,"tv":88.69,"id":2219}]}]}
{"op":"mcm","clk":"11801122208","pt":1723062862238,"mc":[{"id":"1.231540820","rc":[{"batb":[[0,1.97,10],[1,1.96,46.26],[2,1.32,3.28]],"ltp":2.0,"tv":88.69,"id":2219}]}]}
{"op":"mcm","clk":"11801122404","pt":1723062865633,"mc":[{"id":"1.231540820","rc":[{"batb":[[0,1.96,46.26],[1,1.32,3.28],[2,1.3,2.93]],"ltp":2.0,"tv":88.69,"id":2219}]}]}
{"op":"mcm","clk":"11801122590","pt":1723062868620,"mc":[{"id":"1.231540820","rc":[{"batb":[[0,1.97,10],[1,1.96,46.26],[2,1.32,3.28]],"ltp":2.0,"tv":88.69,"id":2219}]}]}
{"op":"mcm","clk":"11801122788","pt":1723062872020,"mc":[{"id":"1.231540820","rc":[{"batb":[[0,1.96,46.26],[1,1.32,3.28],[2,1.3,2.93]],"ltp":2.0,"tv":88.69,"id":2219}]}]}
{"op":"mcm","clk":"11801123012","pt":1723062875723,"mc":[{"id":"1.231540820","rc":[{"batb":[[0,1.97,10],[1,1.96,46.26],[2,1.32,3.28]],"ltp":2.0,"tv":88.69,"id":2219}]}]}
{"op":"mcm","clk":"11801123253","pt":1723062879326,"mc":[{"id":"1.231540820","rc":[{"batb":[[0,1.96,46.26],[1,1.32,3.28],[2,1.3,2.93]],"ltp":2.0,"tv":88.69,"id":2219}]}]}
{"op":"mcm","clk":"11801123434","pt":1723062881839,"mc":[{"id":"1.231540820","rc":[{"batb":[[0,1.97,10],[1,1.96,46.26],[2,1.32,3.28]],"ltp":2.0,"tv":88.69,"id":2219}]}]}
{"op":"mcm","clk":"11801123633","pt":1723062885325,"mc":[{"id":"1.231540820","rc":[{"batb":[[0,1.96,46.26],[1,1.32,3.28],[2,1.3,2.93]],"ltp":2.0,"tv":88.69,"id":2219}]}]}
{"op":"mcm","clk":"11801123897","pt":1723062889753,"mc":[{"id":"1.231540820","rc":[{"batb":[[0,1.97,10],[1,1.96,46.26],[2,1.32,3.28]],"ltp":2.0,"tv":88.69,"id":2219}]}]}
{"op":"mcm","clk":"11801124086","pt":1723062893348,"mc":[{"id":"1.231540820","rc":[{"batb":[[0,1.96,46.26],[1,1.32,3.28],[2,1.3,2.93]],"ltp":2.0,"tv":88.69,"id":2219}]}]}
{"op":"mcm","clk":"11801124230","pt":1723062896127,"mc":[{"id":"1.231540820","rc":[{"batb":[[0,1.97,10],[1,1.96,46.26],[2,1.32,3.28]],"ltp":2.0,"tv":88.69,"id":2219}]}]}
{"op":"mcm","clk":"11801124436","pt":1723062899733,"mc":[{"id":"1.231540820","rc":[{"batb":[[0,1.96,46.26],[1,1.32,3.28],[2,1.3,2.93]],"ltp":2.0,"tv":88.69,"id":2219}]}]}
{"op":"mcm","clk":"11801124634","pt":1723062902775,"mc":[{"id":"1.231540820","rc":[{"batb":[[0,1.97,10],[1,1.96,46.26],[2,1.32,3.28]],"ltp":2.0,"tv":88.69,"id":2219}]}]}
{"op":"mcm","clk":"11801124817","pt":1723062906165,"mc":[{"id":"1.231540820","rc":[{"batb":[[0,1.96,46.26],[1,1.32,3.28],[2,1.3,2.93]],"ltp":2.0,"tv":88.69,"id":2219}]}]}
{"op":"mcm","clk":"11801124968","pt":1723062908479,"mc":[{"id":"1.231540820","rc":[{"batb":[[0,1.97,10],[1,1.96,46.26],[2,1.32,3.28]],"ltp":2.0,"tv":88.69,"id":2219}]}]}
{"op":"mcm","clk":"11801125173","pt":1723062911975,"mc":[{"id":"1.231540820","rc":[{"batb":[[0,1.96,46.26],[1,1.32,3.28],[2,1.3,2.93]],"ltp":2.0,"tv":88.69,"id":2219}]}]}
{"op":"mcm","clk":"11801125320","pt":1723062914589,"mc":[{"id":"1.231540820","rc":[{"batb":[[0,1.97,10],[1,1.96,46.26],[2,1.32,3.28]],"ltp":2.0,"tv":88.69,"id":2219}]}]}
{"op":"mcm","clk":"11801125511","pt":1723062918084,"mc":[{"id":"1.231540820","rc":[{"batb":[[0,1.96,46.26],[1,1.32,3.28],[2,1.3,2.93]],"ltp":2.0,"tv":88.69,"id":2219}]}]}
{"op":"mcm","clk":"11801125687","pt":1723062921466,"mc":[{"id":"1.231540820","rc":[{"batb":[[0,1.97,10],[1,1.96,46.26],[2,1.32,3.28]],"ltp":2.0,"tv":88.69,"id":2219}]}]}
{"op":"mcm","clk":"11801125860","pt":1723062924694,"mc":[{"id":"1.231540820","rc":[{"batb":[[0,1.96,46.26],[1,1.32,3.28],[2,1.3,2.93]],"ltp":2.0,"tv":88.69,"id":2219}]}]}
{"op":"mcm","clk":"11801126050","pt":1723062927985,"mc":[{"id":"1.231540820","rc":[{"batb":[[0,1.97,10],[1,1.96,46.26],[2,1.32,3.28]],"ltp":2.0,"tv":88.69,"id":2219}]}]}
{"op":"mcm","clk":"11801126246","pt":1723062931422,"mc":[{"id":"1.231540820","rc":[{"batb":[[0,1.96,46.26],[1,1.32,3.28],[2,1.3,2.93]],"ltp":2.0,"tv":88.69,"id":2219}]}]}
{"op":"mcm","clk":"11801126393","pt":1723062933897,"mc":[{"id":"1.231540820","rc":[{"batb":[[0,1.97,10],[1,1.96,46.26],[2,1.32,3.28]],"ltp":2.0,"tv":88.69,"id":2219}]}]}
{"op":"mcm","clk":"11801126570","pt":1723062937396,"mc":[{"id":"1.231540820","rc":[{"batb":[[0,1.96,46.26],[1,1.32,3.28],[2,1.3,2.93]],"ltp":2.0,"tv":88.69,"id":2219}]}]}
{"op":"mcm","clk":"11801126879","pt":1723062942892,"mc":[{"id":"1.231540820","rc":[{"batb":[[0,1.97,10],[1,1.96,46.26],[2,1.32,3.28]],"ltp":2.0,"tv":88.69,"id":2219}]}]}
{"op":"mcm","clk":"11801127116","pt":1723062946436,"mc":[{"id":"1.231540820","rc":[{"batb":[[0,1.96,46.26],[1,1.32,3.28],[2,1.3,2.93]],"ltp":2.0,"tv":88.69,"id":2219}]}]}
{"op":"mcm","clk":"11801127267","pt":1723062948904,"mc":[{"id":"1.231540820","rc":[{"batb":[[0,1.97,10],[1,1.96,46.26],[2,1.32,3.28]],"ltp":2.0,"tv":88.69,"id":2219}]}]}
{"op":"mcm","clk":"11801127487","pt":1723062952547,"mc":[{"id":"1.231540820","rc":[{"batb":[[0,1.96,46.26],[1,1.32,3.28],[2,1.3,2.93]],"ltp":2.0,"tv":88.69,"id":2219}]}]}
{"op":"mcm","clk":"11801127625","pt":1723062954810,"mc":[{"id":"1.231540820","rc":[{"batb":[[0,1.97,10],[1,1.96,46.26],[2,1.32,3.28]],"ltp":2.0,"tv":88.69,"id":2219}]}]}
{"op":"mcm","clk":"11801127837","pt":1723062958350,"mc":[{"id":"1.231540820","rc":[{"batb":[[0,1.96,46.26],[1,1.32,3.28],[2,1.3,2.93]],"ltp":2.0,"tv":88.69,"id":2219}]}]}
{"op":"mcm","clk":"11801128040","pt":1723062961544,"mc":[{"id":"1.231540820","rc":[{"batb":[[0,1.97,10],[1,1.96,46.26],[2,1.32,3.28]],"ltp":2.0,"tv":88.69,"id":2219}]}]}
{"op":"mcm","clk":"11801128264","pt":1723062965044,"mc":[{"id":"1.231540820","rc":[{"batb":[[0,1.96,46.26],[1,1.32,3.28],[2,1.3,2.93]],"ltp":2.0,"tv":88.69,"id":2219}]}]}
{"op":"mcm","clk":"11801128423","pt":1723062967924,"mc":[{"id":"1.231540820","rc":[{"batb":[[0,1.97,10],[1,1.96,46.26],[2,1.32,3.28]],"ltp":2.0,"tv":88.69,"id":2219}]}]}
{"op":"mcm","clk":"11801128643","pt":1723062971429,"mc":[{"id":"1.231540820","rc":[{"batb":[[0,1.96,46.26],[1,1.32,3.28],[2,1.3,2.93]],"ltp":2.0,"tv":88.69,"id":2219}]}]}
{"op":"mcm","clk":"11801128819","pt":1723062974666,"mc":[{"id":"1.231540820","rc":[{"batb":[[0,1.97,10],[1,1.96,46.26],[2,1.32,3.28]],"ltp":2.0,"tv":88.69,"id":2219}]}]}
{"op":"mcm","clk":"11801129043","pt":1723062978060,"mc":[{"id":"1.231540820","rc":[{"batb":[[0,1.96,46.26],[1,1.32,3.28],[2,1.3,2.93]],"ltp":2.0,"tv":88.69,"id":2219}]}]}
{"op":"mcm","clk":"11801129202","pt":1723062980638,"mc":[{"id":"1.231540820","rc":[{"batb":[[0,1.97,10],[1,1.96,46.26],[2,1.32,3.28]],"ltp":2.0,"tv":88.69,"id":2219}]}]}
{"op":"mcm","clk":"11801129422","pt":1723062984037,"mc":[{"id":"1.231540820","rc":[{"batb":[[0,1.96,46.26],[1,1.32,3.28],[2,1.3,2.93]],"ltp":2.0,"tv":88.69,"id":2219}]}]}
{"op":"mcm","clk":"11801129564","pt":1723062986455,"mc":[{"id":"1.231540820","rc":[{"batb":[[0,1.97,10],[1,1.96,46.26],[2,1.32,3.28]],"ltp":2.0,"tv":88.69,"id":2219}]}]}
{"op":"mcm","clk":"11801129739","pt":1723062989855,"mc":[{"id":"1.231540820","rc":[{"batb":[[0,1.96,46.26],[1,1.32,3.28],[2,1.3,2.93]],"ltp":2.0,"tv":88.69,"id":2219}]}]}
{"op":"mcm","clk":"11801129887","pt":1723062992578,"mc":[{"id":"1.231540820","rc":[{"batb":[[0,1.97,10],[1,1.96,46.26],[2,1.32,3.28]],"ltp":2.0,"tv":88.69,"id":2219}]}]}
{"op":"mcm","clk":"11801130077","pt":1723062996074,"mc":[{"id":"1.231540820","rc":[{"batb":[[0,1.96,46.26],[1,1.32,3.28],[2,1.3,2.93]],"ltp":2.0,"tv":88.69,"id":2219}]}]}
{"op":"mcm","clk":"11801130273","pt":1723062999561,"mc":[{"id":"1.231540820","rc":[{"batb":[[0,1.97,10],[1,1.96,46.26],[2,1.32,3.28]],"ltp":2.0,"tv":88.69,"id":2219}]}]}
{"op":"mcm","clk":"11801130445","pt":1723063003099,"mc":[{"id":"1.231540820","rc":[{"batb":[[0,1.96,46.26],[1,1.32,3.28],[2,1.3,2.93]],"ltp":2.0,"tv":88.69,"id":2219}]}]}
{"op":"mcm","clk":"11801130576","pt":1723063005562,"mc":[{"id":"1.231540820","rc":[{"batb":[[0,1.97,10],[1,1.96,46.26],[2,1.32,3.28]],"ltp":2.0,"tv":88.69,"id":2219}]}]}
{"op":"mcm","clk":"11801130733","pt":1723063008892,"mc":[{"id":"1.231540820","rc":[{"batb":[[0,1.96,46.26],[1,1.32,3.28],[2,1.3,2.93]],"ltp":2.0,"tv":88.69,"id":2219}]}]}
{"op":"mcm","clk":"11801130868","pt":1723063011102,"mc":[{"id":"1.231540820","rc":[{"batb":[[0,1.97,10],[1,1.96,46.26],[2,1.32,3.28]],"ltp":2.0,"tv":88.69,"id":2219}]}]}
{"op":"mcm","clk":"11801131042","pt":1723063014701,"mc":[{"id":"1.231540820","rc":[{"batb":[[0,1.96,46.26],[1,1.32,3.28],[2,1.3,2.93]],"ltp":2.0,"tv":88.69,"id":2219}]}]}
{"op":"mcm","clk":"11801131161","pt":1723063017169,"mc":[{"id":"1.231540820","rc":[{"batb":[[0,1.97,10],[1,1.96,46.26],[2,1.32,3.28]],"ltp":2.0,"tv":88.69,"id":2219}]}]}
{"op":"mcm","clk":"11801131371","pt":1723063020616,"mc":[{"id":"1.231540820","rc":[{"batb":[[0,1.96,46.26],[1,1.32,3.28],[2,1.3,2.93]],"ltp":2.0,"tv":88.69,"id":2219}]}]}
{"op":"mcm","clk":"11801131524","pt":1723063023089,"mc":[{"id":"1.231540820","rc":[{"batb":[[0,1.97,10],[1,1.96,46.26],[2,1.32,3.28]],"ltp":2.0,"tv":88.69,"id":2219}]}]}
{"op":"mcm","clk":"11801131755","pt":1723063026592,"mc":[{"id":"1.231540820","rc":[{"batb":[[0,1.96,46.26],[1,1.32,3.28],[2,1.3,2.93]],"ltp":2.0,"tv":88.69,"id":2219}]}]}
{"op":"mcm","clk":"11801131907","pt":1723063029114,"mc":[{"id":"1.231540820","rc":[{"batb":[[0,1.97,10],[1,1.96,46.26],[2,1.32,3.28]],"ltp":2.0,"tv":88.69,"id":2219}]}]}
{"op":"mcm","clk":"11801132122","pt":1723063032513,"mc":[{"id":"1.231540820","rc":[{"batb":[[0,1.96,46.26],[1,1.32,3.28],[2,1.3,2.93]],"ltp":2.0,"tv":88.69,"id":2219}]}]}
{"op":"mcm","clk":"11801132320","pt":1723063036010,"mc":[{"id":"1.231540820","rc":[{"batb":[[0,1.97,10],[1,1.96,46.26],[2,1.32,3.28]],"ltp":2.0,"tv":88.69,"id":2219}]}]}
{"op":"mcm","clk":"11801132532","pt":1723063039513,"mc":[{"id":"1.231540820","rc":[{"batb":[[0,1.96,46.26],[1,1.32,3.28],[2,1.3,2.93]],"ltp":2.0,"tv":88.69,"id":2219}]}]}
{"op":"mcm","clk":"11801132778","pt":1723063043528,"mc":[{"id":"1.231540820","rc":[{"batb":[[0,1.97,10],[1,1.96,46.26],[2,1.32,3.28]],"ltp":2.0,"tv":88.69,"id":2219}]}]}
{"op":"mcm","clk":"11801133010","pt":1723063047024,"mc":[{"id":"1.231540820","rc":[{"batb":[[0,1.96,46.26],[1,1.32,3.28],[2,1.3,2.93]],"ltp":2.0,"tv":88.69,"id":2219}]}]}
{"op":"mcm","clk":"11801133157","pt":1723063049804,"mc":[{"id":"1.231540820","rc":[{"batb":[[0,1.97,10],[1,1.96,46.26],[2,1.32,3.28]],"ltp":2.0,"tv":88.69,"id":2219}]}]}
{"op":"mcm","clk":"11801133377","pt":1723063053145,"mc":[{"id":"1.231540820","rc":[{"batb":[[0,1.96,46.26],[1,1.32,3.28],[2,1.3,2.93]],"ltp":2.0,"tv":88.69,"id":2219}]}]}
{"op":"mcm","clk":"11801133537","pt":1723063055513,"mc":[{"id":"1.231540820","rc":[{"batb":[[0,1.97,10],[1,1.96,46.26],[2,1.32,3.28]],"ltp":2.0,"tv":88.69,"id":2219}]}]}
{"op":"mcm","clk":"11801133755","pt":1723063059111,"mc":[{"id":"1.231540820","rc":[{"batb":[[0,1.96,46.26],[1,1.32,3.28],[2,1.3,2.93]],"ltp":2.0,"tv":88.69,"id":2219}]}]}
{"op":"mcm","clk":"11801133926","pt":1723063061830,"mc":[{"id":"1.231540820","rc":[{"batb":[[0,1.97,10],[1,1.96,46.26],[2,1.32,3.28]],"ltp":2.0,"tv":88.69,"id":2219}]}]}
{"op":"mcm","clk":"11801134102","pt":1723063065321,"mc":[{"id":"1.231540820","rc":[{"batb":[[0,1.96,46.26],[1,1.32,3.28],[2,1.3,2.93]],"ltp":2.0,"tv":88.69,"id":2219}]}]}
{"op":"mcm","clk":"11801134316","pt":1723063069069,"mc":[{"id":"1.231540820","rc":[{"batb":[[0,1.97,10],[1,1.96,46.26],[2,1.32,3.28]],"ltp":2.0,"tv":88.69,"id":2219}]}]}
{"op":"mcm","clk":"11801134499","pt":1723063072561,"mc":[{"id":"1.231540820","rc":[{"batb":[[0,1.96,46.26],[1,1.32,3.28],[2,1.3,2.93]],"ltp":2.0,"tv":88.69,"id":2219}]}]}
{"op":"mcm","clk":"11801134622","pt":1723063074770,"mc":[{"id":"1.231540820","rc":[{"batb":[[0,1.97,10],[1,1.96,46.26],[2,1.32,3.28]],"ltp":2.0,"tv":88.69,"id":2219}]}]}
{"op":"mcm","clk":"11801134858","pt":1723063079033,"mc":[{"id":"1.231540820","rc":[{"batb":[[0,1.96,46.26],[1,1.32,3.28],[2,1.3,2.93]],"ltp":2.0,"tv":88.69,"id":2219}]}]}
{"op":"mcm","clk":"11801135015","pt":1723063081760,"mc":[{"id":"1.231540820","rc":[{"batb":[[0,1.97,10],[1,1.96,46.26],[2,1.32,3.28]],"ltp":2.0,"tv":88.69,"id":2219}]}]}
{"op":"mcm","clk":"11801135216","pt":1723063085352,"mc":[{"id":"1.231540820","rc":[{"batb":[[0,1.96,46.26],[1,1.32,3.28],[2,1.3,2.93]],"ltp":2.0,"tv":88.69,"id":2219}]}]}
{"op":"mcm","clk":"11801135377","pt":1723063088330,"mc":[{"id":"1.231540820","rc":[{"batb":[[0,1.97,10],[1,1.96,46.26],[2,1.32,3.28]],"ltp":2.0,"tv":88.69,"id":2219}]}]}
{"op":"mcm","clk":"11801135566","pt":1723063091658,"mc":[{"id":"1.231540820","rc":[{"batb":[[0,1.96,46.26],[1,1.32,3.28],[2,1.3,2.93]],"ltp":2.0,"tv":88.69,"id":2219}]}]}
{"op":"mcm","clk":"11801135775","pt":1723063095861,"mc":[{"id":"1.231540820","rc":[{"batb":[[0,1.97,10],[1,1.96,46.26],[2,1.32,3.28]],"ltp":2.0,"tv":88.69,"id":2219}]}]}
{"op":"mcm","clk":"11801135947","pt":1723063099148,"mc":[{"id":"1.231540820","rc":[{"batb":[[0,1.96,46.26],[1,1.32,3.28],[2,1.3,2.93]],"ltp":2.0,"tv":88.69,"id":2219}]}]}
{"op":"mcm","clk":"11801136109","pt":1723063102073,"mc":[{"id":"1.231540820","rc":[{"batb":[[0,1.97,10],[1,1.96,46.26],[2,1.32,3.28]],"ltp":2.0,"tv":88.69,"id":2219}]}]}
{"op":"mcm","clk":"11801136313","pt":1723063105466,"mc":[{"id":"1.231540820","rc":[{"batb":[[0,1.96,46.26],[1,1.32,3.28],[2,1.3,2.93]],"ltp":2.0,"tv":88.69,"id":2219}]}]}
{"op":"mcm","clk":"11801136441","pt":1723063107669,"mc":[{"id":"1.231540820","rc":[{"batb":[[0,1.97,10],[1,1.96,46.26],[2,1.32,3.28]],"ltp":2.0,"tv":88.69,"id":2219}]}]}
{"op":"mcm","clk":"11801136654","pt":1723063111260,"mc":[{"id":"1.231540820","rc":[{"batb":[[0,1.96,46.26],[1,1.32,3.28],[2,1.3,2.93]],"ltp":2.0,"tv":88.69,"id":2219}]}]}
{"op":"mcm","clk":"11801136794","pt":1723063113670,"mc":[{"id":"1.231540820","rc":[{"batb":[[0,1.97,10],[1,1.96,46.26],[2,1.32,3.28]],"ltp":2.0,"tv":88.69,"id":2219}]}]}
{"op":"mcm","clk":"11801136990","pt":1723063117205,"mc":[{"id":"1.231540820","rc":[{"batb":[[0,1.96,46.26],[1,1.32,3.28],[2,1.3,2.93]],"ltp":2.0,"tv":88.69,"id":2219}]}]}
{"op":"mcm","clk":"11801137285","pt":1723063121786,"mc":[{"id":"1.231540820","rc":[{"batb":[[0,1.97,10],[1,1.96,46.26],[2,1.32,3.28]],"ltp":2.0,"tv":88.69,"id":2219}]}]}
{"op":"mcm","clk":"11801137458","pt":1723063125115,"mc":[{"id":"1.231540820","rc":[{"batb":[[0,1.96,46.26],[1,1.32,3.28],[2,1.3,2.93]],"ltp":2.0,"tv":88.69,"id":2219}]}]}
{"op":"mcm","clk":"11801137638","pt":1723063127883,"mc":[{"id":"1.231540820","rc":[{"batb":[[0,1.97,10],[1,1.96,46.26],[2,1.32,3.28]],"ltp":2.0,"tv":88.69,"id":2219}]}]}
{"op":"mcm","clk":"11801137835","pt":1723063131315,"mc":[{"id":"1.231540820","rc":[{"batb":[[0,1.96,46.26],[1,1.32,3.28],[2,1.3,2.93]],"ltp":2.0,"tv":88.69,"id":2219}]}]}
{"op":"mcm","clk":"11801137980","pt":1723063134185,"mc":[{"id":"1.231540820","rc":[{"batb":[[0,1.97,10],[1,1.96,46.26],[2,1.32,3.28]],"ltp":2.0,"tv":88.69,"id":2219}]}]}
{"op":"mcm","clk":"11801138170","pt":1723063137616,"mc":[{"id":"1.231540820","rc":[{"batb":[[0,1.96,46.26],[1,1.32,3.28],[2,1.3,2.93]],"ltp":2.0,"tv":88.69,"id":2219}]}]}
{"op":"mcm","clk":"11801138348","pt":1723063141108,"mc":[{"id":"1.231540820","rc":[{"batb":[[0,1.97,10],[1,1.96,46.26],[2,1.32,3.28]],"ltp":2.0,"tv":88.69,"id":2219}]}]}
{"op":"mcm","clk":"11801138544","pt":1723063144493,"mc":[{"id":"1.231540820","rc":[{"batb":[[0,1.96,46.26],[1,1.32,3.28],[2,1.3,2.93]],"ltp":2.0,"tv":88.69,"id":2219}]}]}
{"op":"mcm","clk":"11801138700","pt":1723063147218,"mc":[{"id":"1.231540820","rc":[{"batb":[[0,1.97,10],[1,1.96,46.26],[2,1.32,3.28]],"ltp":2.0,"tv":88.69,"id":2219}]}]}
{"op":"mcm","clk":"11801138879","pt":1723063150398,"mc":[{"id":"1.231540820","rc":[{"batb":[[0,1.96,46.26],[1,1.32,3.28],[2,1.3,2.93]],"ltp":2.0,"tv":88.69,"id":2219}]}]}
{"op":"mcm","clk":"11801139033","pt":1723063153318,"mc":[{"id":"1.231540820","rc":[{"batb":[[0,1.97,10],[1,1.96,46.26],[2,1.32,3.28]],"ltp":2.0,"tv":88.69,"id":2219}]}]}
{"op":"mcm","clk":"11801139194","pt":1723063156601,"mc":[{"id":"1.231540820","rc":[{"batb":[[0,1.96,46.26],[1,1.32,3.28],[2,1.3,2.93]],"ltp":2.0,"tv":88.69,"id":2219}]}]}
{"op":"mcm","clk":"11801139329","pt":1723063159318,"mc":[{"id":"1.231540820","rc":[{"batb":[[0,1.97,10],[1,1.96,46.26],[2,1.32,3.28]],"ltp":2.0,"tv":88.69,"id":2219}]}]}
{"op":"mcm","clk":"11801139483","pt":1723063162610,"mc":[{"id":"1.231540820","rc":[{"batb":[[0,1.96,46.26],[1,1.32,3.28],[2,1.3,2.93]],"ltp":2.0,"tv":88.69,"id":2219}]}]}
{"op":"mcm","clk":"11801139668","pt":1723063166107,"mc":[{"id":"1.231540820","rc":[{"batb":[[0,1.97,10],[1,1.96,46.26],[2,1.32,3.28]],"ltp":2.0,"tv":88.69,"id":2219}]}]}
{"op":"mcm","clk":"11801139854","pt":1723063169535,"mc":[{"id":"1.231540820","rc":[{"batb":[[0,1.96,46.26],[1,1.32,3.28],[2,1.3,2.93]],"ltp":2.0,"tv":88.69,"id":2219}]}]}
{"op":"mcm","clk":"11801140032","pt":1723063172860,"mc":[{"id":"1.231540820","rc":[{"batb":[[0,1.97,10],[1,1.96,46.26],[2,1.32,3.28]],"ltp":2.0,"tv":88.69,"id":2219}]}]}
{"op":"mcm","clk":"11801140176","pt":1723063176253,"mc":[{"id":"1.231540820","rc":[{"batb":[[0,1.96,46.26],[1,1.32,3.28],[2,1.3,2.93]],"ltp":2.0,"tv":88.69,"id":2219}]}]}
{"op":"mcm","clk":"11801140277","pt":1723063178720,"mc":[{"id":"1.231540820","rc":[{"batb":[[0,1.97,10],[1,1.96,46.26],[2,1.32,3.28]],"ltp":2.0,"tv":88.69,"id":2219}]}]}
{"op":"mcm","clk":"11801140440","pt":1723063182157,"mc":[{"id":"1.231540820","rc":[{"batb":[[0,1.96,46.26],[1,1.32,3.28],[2,1.3,2.93]],"ltp":2.0,"tv":88.69,"id":2219}]}]}
{"op":"mcm","clk":"11801140604","pt":1723063185642,"mc":[{"id":"1.231540820","rc":[{"batb":[[0,1.97,10],[1,1.96,46.26],[2,1.32,3.28]],"ltp":2.0,"tv":88.69,"id":2219}]}]}
{"op":"mcm","clk":"11801140757","pt":1723063189178,"mc":[{"id":"1.231540820","rc":[{"batb":[[0,1.96,46.26],[1,1.32,3.28],[2,1.3,2.93]],"ltp":2.0,"tv":88.69,"id":2219}]}]}
{"op":"mcm","clk":"11801140867","pt":1723063191745,"mc":[{"id":"1.231540820","rc":[{"batb":[[0,1.97,10],[1,1.96,46.26],[2,1.32,3.28]],"ltp":2.0,"tv":88.69,"id":2219}]}]}
{"op":"mcm","clk":"11801141005","pt":1723063195081,"mc":[{"id":"1.231540820","rc":[{"batb":[[0,1.96,46.26],[1,1.32,3.28],[2,1.3,2.93]],"ltp":2.0,"tv":88.69,"id":2219}]}]}
{"op":"mcm","clk":"11801141185","pt":1723063198679,"mc":[{"id":"1.231540820","rc":[{"batb":[[0,1.97,10],[1,1.96,46.26],[2,1.32,3.28]],"ltp":2.0,"tv":88.69,"id":2219}]}]}
{"op":"mcm","clk":"11801141395","pt":1723063202173,"mc":[{"id":"1.231540820","rc":[{"batb":[[0,1.96,46.26],[1,1.32,3.28],[2,1.3,2.93]],"ltp":2.0,"tv":88.69,"id":2219}]}]}
{"op":"mcm","clk":"11801141530","pt":1723063204483,"mc":[{"id":"1.231540820","rc":[{"batb":[[0,1.97,10],[1,1.96,46.26],[2,1.32,3.28]],"ltp":2.0,"tv":88.69,"id":2219}]}]}
{"op":"mcm","clk":"11801141711","pt":1723063207976,"mc":[{"id":"1.231540820","rc":[{"batb":[[0,1.96,46.26],[1,1.32,3.28],[2,1.3,2.93]],"ltp":2.0,"tv":88.69,"id":2219}]}]}
{"op":"mcm","clk":"11801142021","pt":1723063213679,"mc":[{"id":"1.231540820","rc":[{"batb":[[0,1.97,10],[1,1.96,46.26],[2,1.32,3.28]],"ltp":2.0,"tv":88.69,"id":2219}]}]}
{"op":"mcm","clk":"11801142183","pt":1723063217065,"mc":[{"id":"1.231540820","rc":[{"batb":[[0,1.96,46.26],[1,1.32,3.28],[2,1.3,2.93]],"ltp":2.0,"tv":88.69,"id":2219}]}]}
{"op":"mcm","clk":"11801142305","pt":1723063219486,"mc":[{"id":"1.231540820","rc":[{"batb":[[0,1.97,10],[1,1.96,46.26],[2,1.32,3.28]],"ltp":2.0,"tv":88.69,"id":2219}]}]}
{"op":"mcm","clk":"11801142465","pt":1723063222876,"mc":[{"id":"1.231540820","rc":[{"batb":[[0,1.96,46.26],[1,1.32,3.28],[2,1.3,2.93]],"ltp":2.0,"tv":88.69,"id":2219}]}]}
{"op":"mcm","clk":"11801142595","pt":1723063225089,"mc":[{"id":"1.231540820","rc":[{"batb":[[0,1.97,10],[1,1.96,46.26],[2,1.32,3.28]],"ltp":2.0,"tv":88.69,"id":2219}]}]}
{"op":"mcm","clk":"11801142772","pt":1723063228582,"mc":[{"id":"1.231540820","rc":[{"batb":[[0,1.96,46.26],[1,1.32,3.28],[2,1.3,2.93]],"ltp":2.0,"tv":88.69,"id":2219}]}]}
{"op":"mcm","clk":"11801142915","pt":1723063231103,"mc":[{"id":"1.231540820","rc":[{"batb":[[0,1.97,10],[1,1.96,46.26],[2,1.32,3.28]],"ltp":2.0,"tv":88.69,"id":2219}]}]}
{"op":"mcm","clk":"11801143103","pt":1723063234394,"mc":[{"id":"1.231540820","rc":[{"batb":[[0,1.96,46.26],[1,1.32,3.28],[2,1.3,2.93]],"ltp":2.0,"tv":88.69,"id":2219}]}]}
{"op":"mcm","clk":"11801143322","pt":1723063238308,"mc":[{"id":"1.231540820","rc":[{"batb":[[0,1.97,10],[1,1.96,46.26],[2,1.32,3.28]],"ltp":2.0,"tv":88.69,"id":2219}]}]}
{"op":"mcm","clk":"11801143527","pt":1723063241900,"mc":[{"id":"1.231540820","rc":[{"batb":[[0,1.96,46.26],[1,1.32,3.28],[2,1.3,2.93]],"ltp":2.0,"tv":88.69,"id":2219}]}]}
{"op":"mcm","clk":"11801143670","pt":1723063244420,"mc":[{"id":"1.231540820","rc":[{"batb":[[0,1.97,10],[1,1.96,46.26],[2,1.32,3.28]],"ltp":2.0,"tv":88.69,"id":2219}]}]}
{"op":"mcm","clk":"11801143850","pt":1723063247707,"mc":[{"id":"1.231540820","rc":[{"batb":[[0,1.96,46.26],[1,1.32,3.28],[2,1.3,2.93]],"ltp":2.0,"tv":88.69,"id":2219}]}]}
{"op":"mcm","clk":"11801143995","pt":1723063250190,"mc":[{"id":"1.231540820","rc":[{"batb":[[0,1.97,10],[1,1.96,46.26],[2,1.32,3.28]],"ltp":2.0,"tv":88.69,"id":2219}]}]}
{"op":"mcm","clk":"11801144185","pt":1723063253723,"mc":[{"id":"1.231540820","rc":[{"batb":[[0,1.96,46.26],[1,1.32,3.28],[2,1.3,2.93]],"ltp":2.0,"tv":88.69,"id":2219}]}]}
{"op":"mcm","clk":"11801144333","pt":1723063256598,"mc":[{"id":"1.231540820","rc":[{"batb":[[0,1.97,10],[1,1.96,46.26],[2,1.32,3.28]],"ltp":2.0,"tv":88.69,"id":2219}]}]}
{"op":"mcm","clk":"11801144524","pt":1723063260244,"mc":[{"id":"1.231540820","rc":[{"batb":[[0,1.96,46.26],[1,1.32,3.28],[2,1.3,2.93]],"ltp":2.0,"tv":88.69,"id":2219}]}]}
{"op":"mcm","clk":"11801144749","pt":1723063263542,"mc":[{"id":"1.231540820","rc":[{"batb":[[0,1.97,10],[1,1.96,46.26],[2,1.32,3.28]],"ltp":2.0,"tv":88.69,"id":2219}]}]}
{"op":"mcm","clk":"11801144960","pt":1723063266834,"mc":[{"id":"1.231540820","rc":[{"batb":[[0,1.96,46.26],[1,1.32,3.28],[2,1.3,2.93]],"ltp":2.0,"tv":88.69,"id":2219}]}]}
{"op":"mcm","clk":"11801145140","pt":1723063269917,"mc":[{"id":"1.231540820","rc":[{"batb":[[0,1.97,10],[1,1.96,46.26],[2,1.32,3.28]],"ltp":2.0,"tv":88.69,"id":2219}]}]}
{"op":"mcm","clk":"11801145365","pt":1723063273927,"mc":[{"id":"1.231540820","rc":[{"batb":[[0,1.96,46.26],[1,1.32,3.28],[2,1.3,2.93]],"ltp":2.0,"tv":88.69,"id":2219}]}]}
{"op":"mcm","clk":"11801145521","pt":1723063276645,"mc":[{"id":"1.231540820","rc":[{"batb":[[0,1.97,10],[1,1.96,46.26],[2,1.32,3.28]],"ltp":2.0,"tv":88.69,"id":2219}]}]}
{"op":"mcm","clk":"11801145718","pt":1723063280029,"mc":[{"id":"1.231540820","rc":[{"batb":[[0,1.96,46.26],[1,1.32,3.28],[2,1.3,2.93]],"ltp":2.0,"tv":88.69,"id":2219}]}]}
{"op":"mcm","clk":"11801145856","pt":1723063282447,"mc":[{"id":"1.231540820","rc":[{"batb":[[0,1.97,10],[1,1.96,46.26],[2,1.32,3.28]],"ltp":2.0,"tv":88.69,"id":2219}]}]}
{"op":"mcm","clk":"11801146043","pt":1723063286140,"mc":[{"id":"1.231540820","rc":[{"batb":[[0,1.96,46.26],[1,1.32,3.28],[2,1.3,2.93]],"ltp":2.0,"tv":88.69,"id":2219}]}]}
{"op":"mcm","clk":"11801146191","pt":1723063288653,"mc":[{"id":"1.231540820","rc":[{"batb":[[0,1.97,10],[1,1.96,46.26],[2,1.32,3.28]],"ltp":2.0,"tv":88.69,"id":2219}]}]}
{"op":"mcm","clk":"11801146394","pt":1723063292155,"mc":[{"id":"1.231540820","rc":[{"batb":[[0,1.96,46.26],[1,1.32,3.28],[2,1.3,2.93]],"ltp":2.0,"tv":88.69,"id":2219}]}]}
{"op":"mcm","clk":"11801146657","pt":1723063296631,"mc":[{"id":"1.231540820","rc":[{"batb":[[0,1.97,10],[1,1.96,46.26],[2,1.32,3.28]],"ltp":2.0,"tv":88.69,"id":2219}]}]}
{"op":"mcm","clk":"11801146845","pt":1723063299966,"mc":[{"id":"1.231540820","rc":[{"batb":[[0,1.96,46.26],[1,1.32,3.28],[2,1.3,2.93]],"ltp":2.0,"tv":88.69,"id":2219}]}]}
{"op":"mcm","clk":"11801146975","pt":1723063302376,"mc":[{"id":"1.231540820","rc":[{"batb":[[0,1.97,10],[1,1.96,46.26],[2,1.32,3.28]],"ltp":2.0,"tv":88.69,"id":2219}]}]}
{"op":"mcm","clk":"11801147144","pt":1723063305758,"mc":[{"id":"1.231540820","rc":[{"batb":[[0,1.96,46.26],[1,1.32,3.28],[2,1.3,2.93]],"ltp":2.0,"tv":88.69,"id":2219}]}]}
{"op":"mcm","clk":"11801147272","pt":1723063308349,"mc":[{"id":"1.231540820","rc":[{"batb":[[0,1.97,10],[1,1.96,46.26],[2,1.32,3.28]],"ltp":2.0,"tv":88.69,"id":2219}]}]}
{"op":"mcm","clk":"11801147484","pt":1723063311846,"mc":[{"id":"1.231540820","rc":[{"batb":[[0,1.96,46.26],[1,1.32,3.28],[2,1.3,2.93]],"ltp":2.0,"tv":88.69,"id":2219}]}]}
{"op":"mcm","clk":"11801200401","pt":1723064400761,"mc":[{"id":"1.231540820","rc":[{"batb":[[0,1.97,10],[1,1.96,46.26],[2,1.32,3.28]],"ltp":2.0,"tv":88.69,"id":2219}]}]}
{"op":"mcm","clk":"11801200606","pt":1723064404114,"mc":[{"id":"1.231540820","rc":[{"batb":[[1,1.31,6.45]],"ltp":0.0,"tv":0.0,"id":2780},{"batb":[[0,1.96,46.26],[1,1.32,3.28],[2,1.3,2.93]],"ltp":2.0,"tv":88.69,"id":2219}]}]}
{"op":"mcm","clk":"11801200822","pt":1723064407345,"mc":[{"id":"1.231540820","rc":[{"batb":[[0,1.97,10],[1,1.96,46.26],[2,1.32,3.28]],"ltp":2.0,"tv":88.69,"id":2219}]}]}
{"op":"mcm","clk":"11801201011","pt":1723064410829,"mc":[{"id":"1.231540820","rc":[{"batb":[[0,1.96,46.26],[1,1.32,3.28],[2,1.3,2.93]],"ltp":2.0,"tv":88.69,"id":2219}]}]}
{"op":"mcm","clk":"11801201200","pt":1723064414625,"mc":[{"id":"1.231540820","rc":[{"batb":[[0,1.97,10],[1,1.96,46.26],[2,1.32,3.28]],"ltp":2.0,"tv":88.69,"id":2219}]}]}
{"op":"mcm","clk":"11801201373","pt":1723064418140,"mc":[{"id":"1.231540820","rc":[{"batb":[[0,1.96,46.26],[1,1.32,3.28],[2,1.3,2.93]],"ltp":2.0,"tv":88.69,"id":2219}]}]}
{"op":"mcm","clk":"11801201558","pt":1723064421423,"mc":[{"id":"1.231540820","rc":[{"batb":[[0,1.97,10],[1,1.96,46.26],[2,1.32,3.28]],"ltp":2.0,"tv":88.69,"id":2219}]}]}
{"op":"mcm","clk":"11801201714","pt":1723064425056,"mc":[{"id":"1.231540820","rc":[{"batb":[[0,1.96,46.26],[1,1.32,3.28],[2,1.3,2.93]],"ltp":2.0,"tv":88.69,"id":2219}]}]}
{"op":"mcm","clk":"11801201819","pt":1723064427568,"mc":[{"id":"1.231540820","rc":[{"batb":[[0,1.97,10],[1,1.96,46.26],[2,1.32,3.28]],"ltp":2.0,"tv":88.69,"id":2219}]}]}
{"op":"mcm","clk":"11801202007","pt":1723064431160,"mc":[{"id":"1.231540820","rc":[{"batb":[[0,1.96,46.26],[1,1.32,3.28],[2,1.3,2.93]],"ltp":2.0,"tv":88.69,"id":2219}]}]}
{"op":"mcm","clk":"11801202151","pt":1723064434141,"mc":[{"id":"1.231540820","rc":[{"batb":[[0,1.97,10],[1,1.96,46.26],[2,1.32,3.28]],"ltp":2.0,"tv":88.69,"id":2219}]}]}
{"op":"mcm","clk":"11801202312","pt":1723064437470,"mc":[{"id":"1.231540820","rc":[{"batb":[[0,1.96,46.26],[1,1.32,3.28],[2,1.3,2.93]],"ltp":2.0,"tv":88.69,"id":2219}]}]}
{"op":"mcm","clk":"11801202425","pt":1723064440086,"mc":[{"id":"1.231540820","rc":[{"batb":[[0,1.97,10],[1,1.96,46.26],[2,1.32,3.28]],"ltp":2.0,"tv":88.69,"id":2219}]}]}
{"op":"mcm","clk":"11801202551","pt":1723064443572,"mc":[{"id":"1.231540820","rc":[{"batb":[[0,1.96,46.26],[1,1.32,3.28],[2,1.3,2.93]],"ltp":2.0,"tv":88.69,"id":2219}]}]}
{"op":"mcm","clk":"11801202691","pt":1723064447455,"mc":[{"id":"1.231540820","rc":[{"batb":[[0,1.97,10],[1,1.96,46.26],[2,1.32,3.28]],"ltp":2.0,"tv":88.69,"id":2219}]}]}
{"op":"mcm","clk":"11801202913","pt":1723064450997,"mc":[{"id":"1.231540820","rc":[{"batb":[[0,1.96,46.26],[1,1.32,3.28],[2,1.3,2.93]],"ltp":2.0,"tv":88.69,"id":2219}]}]}
{"op":"mcm","clk":"11801203085","pt":1723064455286,"mc":[{"id":"1.231540820","rc":[{"batb":[[0,1.97,10],[1,1.96,46.26],[2,1.32,3.28]],"ltp":2.0,"tv":88.69,"id":2219}]}]}
{"op":"mcm","clk":"11801203236","pt":1723064458983,"mc":[{"id":"1.231540820","rc":[{"batb":[[0,1.96,46.26],[1,1.32,3.28],[2,1.3,2.93]],"ltp":2.0,"tv":88.69,"id":2219}]}]}
{"op":"mcm","clk":"11801203373","pt":1723064461697,"mc":[{"id":"1.231540820","rc":[{"batb":[[0,1.97,10],[1,1.96,46.26],[2,1.32,3.28]],"ltp":2.0,"tv":88.69,"id":2219}]}]}
{"op":"mcm","clk":"11801203570","pt":1723064465298,"mc":[{"id":"1.231540820","rc":[{"batb":[[0,1.96,46.26],[1,1.32,3.28],[2,1.3,2.93]],"ltp":2.0,"tv":88.69,"id":2219}]}]}
{"op":"mcm","clk":"11801203697","pt":1723064467909,"mc":[{"id":"1.231540820","rc":[{"batb":[[0,1.97,10],[1,1.96,46.26],[2,1.32,3.28]],"ltp":2.0,"tv":88.69,"id":2219}]}]}
{"op":"mcm","clk":"11801203865","pt":1723064471503,"mc":[{"id":"1.231540820","rc":[{"batb":[[0,1.96,46.26],[1,1.32,3.28],[2,1.3,2.93]],"ltp":2.0,"tv":88.69,"id":2219}]}]}
{"op":"mcm","clk":"11801203956","pt":1723064473713,"mc":[{"id":"1.231540820","rc":[{"batb":[[0,1.97,10],[1,1.96,46.26],[2,1.32,3.28]],"ltp":2.0,"tv":88.69,"id":2219}]}]}
{"op":"mcm","clk":"11801204153","pt":1723064477212,"mc":[{"id":"1.231540820","rc":[{"batb":[[0,1.96,46.26],[1,1.32,3.28],[2,1.3,2.93]],"ltp":2.0,"tv":88.69,"id":2219}]}]}
{"op":"mcm","clk":"11801204306","pt":1723064479991,"mc":[{"id":"1.231540820","rc":[{"batb":[[0,1.97,10],[1,1.96,46.26],[2,1.32,3.28]],"ltp":2.0,"tv":88.69,"id":2219}]}]}
{"op":"mcm","clk":"11801204503","pt":1723064483430,"mc":[{"id":"1.231540820","rc":[{"batb":[[0,1.96,46.26],[1,1.32,3.28],[2,1.3,2.93]],"ltp":2.0,"tv":88.69,"id":2219}]}]}
{"op":"mcm","clk":"11801204582","pt":1723064485592,"mc":[{"id":"1.231540820","rc":[{"batb":[[0,1.97,10],[1,1.96,46.26],[2,1.32,3.28]],"ltp":2.0,"tv":88.69,"id":2219}]}]}
{"op":"mcm","clk":"11801204722","pt":1723064489131,"mc":[{"id":"1.231540820","rc":[{"batb":[[0,1.96,46.26],[1,1.32,3.28],[2,1.3,2.93]],"ltp":2.0,"tv":88.69,"id":2219}]}]}
{"op":"mcm","clk":"11801204805","pt":1723064491333,"mc":[{"id":"1.231540820","rc":[{"batb":[[0,1.97,10],[1,1.96,46.26],[2,1.32,3.28]],"ltp":2.0,"tv":88.69,"id":2219}]}]}
{"op":"mcm","clk":"11801204996","pt":1723064494622,"mc":[{"id":"1.231540820","rc":[{"batb":[[0,1.96,46.26],[1,1.32,3.28],[2,1.3,2.93]],"ltp":2.0,"tv":88.69,"id":2219}]}]}
{"op":"mcm","clk":"11801205129","pt":1723064497960,"mc":[{"id":"1.231540820","rc":[{"batb":[[0,1.97,10],[1,1.96,46.26],[2,1.32,3.28]],"ltp":2.0,"tv":88.69,"id":2219}]}]}
{"op":"mcm","clk":"11801205265","pt":1723064501445,"mc":[{"id":"1.231540820","rc":[{"batb":[[0,1.96,46.26],[1,1.32,3.28],[2,1.3,2.93]],"ltp":2.0,"tv":88.69,"id":2219}]}]}
{"op":"mcm","clk":"11801205342","pt":1723064503664,"mc":[{"id":"1.231540820","rc":[{"batb":[[0,1.97,10],[1,1.96,46.26],[2,1.32,3.28]],"ltp":2.0,"tv":88.69,"id":2219}]}]}
{"op":"mcm","clk":"11801205487","pt":1723064507143,"mc":[{"id":"1.231540820","rc":[{"batb":[[0,1.96,46.26],[1,1.32,3.28],[2,1.3,2.93]],"ltp":2.0,"tv":88.69,"id":2219}]}]}
{"op":"mcm","clk":"11801205606","pt":1723064509869,"mc":[{"id":"1.231540820","rc":[{"batb":[[0,1.97,10],[1,1.96,46.26],[2,1.32,3.28]],"ltp":2.0,"tv":88.69,"id":2219}]}]}
{"op":"mcm","clk":"11801205741","pt":1723064513155,"mc":[{"id":"1.231540820","rc":[{"batb":[[0,1.96,46.26],[1,1.32,3.28],[2,1.3,2.93]],"ltp":2.0,"tv":88.69,"id":2219}]}]}
{"op":"mcm","clk":"11801205845","pt":1723064515871,"mc":[{"id":"1.231540820","rc":[{"batb":[[0,1.97,10],[1,1.96,46.26],[2,1.32,3.28]],"ltp":2.0,"tv":88.69,"id":2219}]}]}
{"op":"mcm","clk":"11801205986","pt":1723064519357,"mc":[{"id":"1.231540820","rc":[{"batb":[[0,1.96,46.26],[1,1.32,3.28],[2,1.3,2.93]],"ltp":2.0,"tv":88.69,"id":2219}]}]}
{"op":"mcm","clk":"11801206121","pt":1723064522283,"mc":[{"id":"1.231540820","rc":[{"batb":[[0,1.97,10],[1,1.96,46.26],[2,1.32,3.28]],"ltp":2.0,"tv":88.69,"id":2219}]}]}
{"op":"mcm","clk":"11801206290","pt":1723064525773,"mc":[{"id":"1.231540820","rc":[{"batb":[[0,1.96,46.26],[1,1.32,3.28],[2,1.3,2.93]],"ltp":2.0,"tv":88.69,"id":2219}]}]}
{"op":"mcm","clk":"11801206444","pt":1723064529007,"mc":[{"id":"1.231540820","rc":[{"batb":[[0,1.97,10],[1,1.96,46.26],[2,1.32,3.28]],"ltp":2.0,"tv":88.69,"id":2219}]}]}
{"op":"mcm","clk":"11801206607","pt":1723064532499,"mc":[{"id":"1.231540820","rc":[{"batb":[[0,1.96,46.26],[1,1.32,3.28],[2,1.3,2.93]],"ltp":2.0,"tv":88.69,"id":2219}]}]}
{"op":"mcm","clk":"11801206748","pt":1723064536083,"mc":[{"id":"1.231540820","rc":[{"batb":[[0,1.97,10],[1,1.96,46.26],[2,1.32,3.28]],"ltp":2.0,"tv":88.69,"id":2219}]}]}
{"op":"mcm","clk":"11801206901","pt":1723064539573,"mc":[{"id":"1.231540820","rc":[{"batb":[[0,1.96,46.26],[1,1.32,3.28],[2,1.3,2.93]],"ltp":2.0,"tv":88.69,"id":2219}]}]}
{"op":"mcm","clk":"11801207013","pt":1723064542184,"mc":[{"id":"1.231540820","rc":[{"batb":[[0,1.97,10],[1,1.96,46.26],[2,1.32,3.28]],"ltp":2.0,"tv":88.69,"id":2219}]}]}
{"op":"mcm","clk":"11801207163","pt":1723064545681,"mc":[{"id":"1.231540820","rc":[{"batb":[[0,1.96,46.26],[1,1.32,3.28],[2,1.3,2.93]],"ltp":2.0,"tv":88.69,"id":2219}]}]}
{"op":"mcm","clk":"11801207265","pt":1723064548392,"mc":[{"id":"1.231540820","rc":[{"batb":[[0,1.97,10],[1,1.96,46.26],[2,1.32,3.28]],"ltp":2.0,"tv":88.69,"id":2219}]}]}
{"op":"mcm","clk":"11801207437","pt":1723064551892,"mc":[{"id":"1.231540820","rc":[{"batb":[[0,1.96,46.26],[1,1.32,3.28],[2,1.3,2.93]],"ltp":2.0,"tv":88.69,"id":2219}]}]}
{"op":"mcm","clk":"11801207773","pt":1723064560005,"mc":[{"id":"1.231540820","rc":[{"batb":[[0,1.97,10],[1,1.96,46.26],[2,1.32,3.28]],"ltp":2.0,"tv":88.69,"id":2219}]}]}
{"op":"mcm","clk":"11801207909","pt":1723064563548,"mc":[{"id":"1.231540820","rc":[{"batb":[[0,1.96,46.26],[1,1.32,3.28],[2,1.3,2.93]],"ltp":2.0,"tv":88.69,"id":2219}]}]}
{"op":"mcm","clk":"11801208051","pt":1723064566940,"mc":[{"id":"1.231540820","rc":[{"batb":[[0,1.97,10],[1,1.96,46.26],[2,1.32,3.28]],"ltp":2.0,"tv":88.69,"id":2219}]}]}
{"op":"mcm","clk":"11801208202","pt":1723064570433,"mc":[{"id":"1.231540820","rc":[{"batb":[[0,1.96,46.26],[1,1.32,3.28],[2,1.3,2.93]],"ltp":2.0,"tv":88.69,"id":2219}]}]}
{"op":"mcm","clk":"11801208285","pt":1723064572745,"mc":[{"id":"1.231540820","rc":[{"batb":[[0,1.97,10],[1,1.96,46.26],[2,1.32,3.28]],"ltp":2.0,"tv":88.69,"id":2219}]}]}
{"op":"mcm","clk":"11801208414","pt":1723064576239,"mc":[{"id":"1.231540820","rc":[{"batb":[[0,1.96,46.26],[1,1.32,3.28],[2,1.3,2.93]],"ltp":2.0,"tv":88.69,"id":2219}]}]}
{"op":"mcm","clk":"11801208509","pt":1723064578651,"mc":[{"id":"1.231540820","rc":[{"batb":[[0,1.97,10],[1,1.96,46.26],[2,1.32,3.28]],"ltp":2.0,"tv":88.69,"id":2219}]}]}
{"op":"mcm","clk":"11801208663","pt":1723064581945,"mc":[{"id":"1.231540820","rc":[{"batb":[[0,1.96,46.26],[1,1.32,3.28],[2,1.3,2.93]],"ltp":2.0,"tv":88.69,"id":2219}]}]}
{"op":"mcm","clk":"11801208816","pt":1723064585621,"mc":[{"id":"1.231540820","rc":[{"batb":[[0,1.97,10],[1,1.96,46.26],[2,1.32,3.28]],"ltp":2.0,"tv":88.69,"id":2219}]}]}
{"op":"mcm","clk":"11801208935","pt":1723064589052,"mc":[{"id":"1.231540820","rc":[{"batb":[[0,1.96,46.26],[1,1.32,3.28],[2,1.3,2.93]],"ltp":2.0,"tv":88.69,"id":2219}]}]}
{"op":"mcm","clk":"11801209056","pt":1723064591767,"mc":[{"id":"1.231540820","rc":[{"batb":[[0,1.97,10],[1,1.96,46.26],[2,1.32,3.28]],"ltp":2.0,"tv":88.69,"id":2219}]}]}
{"op":"mcm","clk":"11801209168","pt":1723064595260,"mc":[{"id":"1.231540820","rc":[{"batb":[[0,1.96,46.26],[1,1.32,3.28],[2,1.3,2.93]],"ltp":2.0,"tv":88.69,"id":2219}]}]}
{"op":"mcm","clk":"11801209285","pt":1723064597575,"mc":[{"id":"1.231540820","rc":[{"batb":[[0,1.97,10],[1,1.96,46.26],[2,1.32,3.28]],"ltp":2.0,"tv":88.69,"id":2219}]}]}
{"op":"mcm","clk":"11801209474","pt":1723064601161,"mc":[{"id":"1.231540820","rc":[{"batb":[[0,1.96,46.26],[1,1.32,3.28],[2,1.3,2.93]],"ltp":2.0,"tv":88.69,"id":2219}]}]}
{"op":"mcm","clk":"11801209625","pt":1723064604564,"mc":[{"id":"1.231540820","rc":[{"batb":[[0,1.97,10],[1,1.96,46.26],[2,1.32,3.28]],"ltp":2.0,"tv":88.69,"id":2219}]}]}
{"op":"mcm","clk":"11801209812","pt":1723064608145,"mc":[{"id":"1.231540820","rc":[{"batb":[[0,1.96,46.26],[1,1.32,3.28],[2,1.3,2.93]],"ltp":2.0,"tv":88.69,"id":2219}]}]}
{"op":"mcm","clk":"11801209979","pt":1723064610866,"mc":[{"id":"1.231540820","rc":[{"batb":[[0,1.97,10],[1,1.96,46.26],[2,1.32,3.28]],"ltp":2.0,"tv":88.69,"id":2219}]}]}
{"op":"mcm","clk":"11801210162","pt":1723064615377,"mc":[{"id":"1.231540820","rc":[{"batb":[[0,1.96,46.26],[1,1.32,3.28],[2,1.3,2.93]],"ltp":2.0,"tv":88.69,"id":2219}]}]}
{"op":"mcm","clk":"11801210254","pt":1723064617578,"mc":[{"id":"1.231540820","rc":[{"batb":[[0,1.97,10],[1,1.96,46.26],[2,1.32,3.28]],"ltp":2.0,"tv":88.69,"id":2219}]}]}
{"op":"mcm","clk":"11801210407","pt":1723064621010,"mc":[{"id":"1.231540820","rc":[{"batb":[[0,1.96,46.26],[1,1.32,3.28],[2,1.3,2.93]],"ltp":2.0,"tv":88.69,"id":2219}]}]}
{"op":"mcm","clk":"11801210553","pt":1723064623881,"mc":[{"id":"1.231540820","rc":[{"batb":[[0,1.97,10],[1,1.96,46.26],[2,1.32,3.28]],"ltp":2.0,"tv":88.69,"id":2219}]}]}
{"op":"mcm","clk":"11801210674","pt":1723064627312,"mc":[{"id":"1.231540820","rc":[{"batb":[[0,1.96,46.26],[1,1.32,3.28],[2,1.3,2.93]],"ltp":2.0,"tv":88.69,"id":2219}]}]}
{"op":"mcm","clk":"11801210818","pt":1723064630698,"mc":[{"id":"1.231540820","rc":[{"batb":[[0,1.97,10],[1,1.96,46.26],[2,1.32,3.28]],"ltp":2.0,"tv":88.69,"id":2219}]}]}
{"op":"mcm","clk":"11801210969","pt":1723064634088,"mc":[{"id":"1.231540820","rc":[{"batb":[[0,1.96,46.26],[1,1.32,3.28],[2,1.3,2.93]],"ltp":2.0,"tv":88.69,"id":2219}]}]}
{"op":"mcm","clk":"11801211080","pt":1723064636803,"mc":[{"id":"1.231540820","rc":[{"batb":[[0,1.97,10],[1,1.96,46.26],[2,1.32,3.28]],"ltp":2.0,"tv":88.69,"id":2219}]}]}
{"op":"mcm","clk":"11801211239","pt":1723064640438,"mc":[{"id":"1.231540820","rc":[{"batb":[[0,1.96,46.26],[1,1.32,3.28],[2,1.3,2.93]],"ltp":2.0,"tv":88.69,"id":2219}]}]}
{"op":"mcm","clk":"11801211466","pt":1723064646002,"mc":[{"id":"1.231540820","rc":[{"batb":[[0,1.97,10],[1,1.96,46.26],[2,1.32,3.28]],"ltp":2.0,"tv":88.69,"id":2219}]}]}
{"op":"mcm","clk":"11801211621","pt":1723064649551,"mc":[{"id":"1.231540820","rc":[{"batb":[[0,1.96,46.26],[1,1.32,3.28],[2,1.3,2.93]],"ltp":2.0,"tv":88.69,"id":2219}]}]}
{"op":"mcm","clk":"11801211883","pt":1723064654949,"mc":[{"id":"1.231540820","rc":[{"batb":[[0,1.97,10],[1,1.96,46.26],[2,1.32,3.28]],"ltp":2.0,"tv":88.69,"id":2219}]}]}
{"op":"mcm","clk":"11801212075","pt":1723064659055,"mc":[{"id":"1.231540820","rc":[{"batb":[[0,1.96,46.26],[1,1.32,3.28],[2,1.3,2.93]],"ltp":2.0,"tv":88.69,"id":2219}]}]}
{"op":"mcm","clk":"11801212160","pt":1723064661259,"mc":[{"id":"1.231540820","rc":[{"batb":[[0,1.97,10],[1,1.96,46.26],[2,1.32,3.28]],"ltp":2.0,"tv":88.69,"id":2219}]}]}
{"op":"mcm","clk":"11801212301","pt":1723064664743,"mc":[{"id":"1.231540820","rc":[{"batb":[[0,1.96,46.26],[1,1.32,3.28],[2,1.3,2.93]],"ltp":2.0,"tv":88.69,"id":2219}]}]}
{"op":"mcm","clk":"11801212426","pt":1723064667461,"mc":[{"id":"1.231540820","rc":[{"batb":[[0,1.97,10],[1,1.96,46.26],[2,1.32,3.28]],"ltp":2.0,"tv":88.69,"id":2219}]}]}
{"op":"mcm","clk":"11801212600","pt":1723064670952,"mc":[{"id":"1.231540820","rc":[{"batb":[[0,1.96,46.26],[1,1.32,3.28],[2,1.3,2.93]],"ltp":2.0,"tv":88.69,"id":2219}]}]}
{"op":"mcm","clk":"11801212903","pt":1723064678149,"mc":[{"id":"1.231540820","rc":[{"batb":[[0,1.97,10],[1,1.96,46.26],[2,1.32,3.28]],"ltp":2.0,"tv":88.69,"id":2219}]}]}
{"op":"mcm","clk":"11801213029","pt":1723064681581,"mc":[{"id":"1.231540820","rc":[{"batb":[[0,1.96,46.26],[1,1.32,3.28],[2,1.3,2.93]],"ltp":2.0,"tv":88.69,"id":2219}]}]}
{"op":"mcm","clk":"11801213126","pt":1723064683954,"mc":[{"id":"1.231540820","rc":[{"batb":[[0,1.97,10],[1,1.96,46.26],[2,1.32,3.28]],"ltp":2.0,"tv":88.69,"id":2219}]}]}
{"op":"mcm","clk":"11801213261","pt":1723064687386,"mc":[{"id":"1.231540820","rc":[{"batb":[[0,1.96,46.26],[1,1.32,3.28],[2,1.3,2.93]],"ltp":2.0,"tv":88.69,"id":2219}]}]}
{"op":"mcm","clk":"11801213351","pt":1723064689788,"mc":[{"id":"1.231540820","rc":[{"batb":[[0,1.97,10],[1,1.96,46.26],[2,1.32,3.28]],"ltp":2.0,"tv":88.69,"id":2219}]}]}
{"op":"mcm","clk":"11801213514","pt":1723064693586,"mc":[{"id":"1.231540820","rc":[{"batb":[[0,1.96,46.26],[1,1.32,3.28],[2,1.3,2.93]],"ltp":2.0,"tv":88.69,"id":2219}]}]}
{"op":"mcm","clk":"11801213669","pt":1723064697081,"mc":[{"id":"1.231540820","rc":[{"batb":[[0,1.97,10],[1,1.96,46.26],[2,1.32,3.28]],"ltp":2.0,"tv":88.69,"id":2219}]}]}
{"op":"mcm","clk":"11801213815","pt":1723064700473,"mc":[{"id":"1.231540820","rc":[{"batb":[[0,1.96,46.26],[1,1.32,3.28],[2,1.3,2.93]],"ltp":2.0,"tv":88.69,"id":2219}]}]}
{"op":"mcm","clk":"11801213943","pt":1723064703097,"mc":[{"id":"1.231540820","rc":[{"batb":[[0,1.97,10],[1,1.96,46.26],[2,1.32,3.28]],"ltp":2.0,"tv":88.69,"id":2219}]}]}
{"op":"mcm","clk":"11801214090","pt":1723064706391,"mc":[{"id":"1.231540820","rc":[{"batb":[[0,1.96,46.26],[1,1.32,3.28],[2,1.3,2.93]],"ltp":2.0,"tv":88.69,"id":2219}]}]}
{"op":"mcm","clk":"11801214242","pt":1723064709987,"mc":[{"id":"1.231540820","rc":[{"batb":[[0,1.97,10],[1,1.96,46.26],[2,1.32,3.28]],"ltp":2.0,"tv":88.69,"id":2219}]}]}
{"op":"mcm","clk":"11801214368","pt":1723064713528,"mc":[{"id":"1.231540820","rc":[{"batb":[[0,1.96,46.26],[1,1.32,3.28],[2,1.3,2.93]],"ltp":2.0,"tv":88.69,"id":2219}]}]}
{"op":"mcm","clk":"11801214504","pt":1723064716407,"mc":[{"id":"1.231540820","rc":[{"batb":[[0,1.97,10],[1,1.96,46.26],[2,1.32,3.28]],"ltp":2.0,"tv":88.69,"id":2219}]}]}
{"op":"mcm","clk":"11801214675","pt":1723064719898,"mc":[{"id":"1.231540820","rc":[{"batb":[[0,1.96,46.26],[1,1.32,3.28],[2,1.3,2.93]],"ltp":2.0,"tv":88.69,"id":2219}]}]}
{"op":"mcm","clk":"11801214804","pt":1723064723124,"mc":[{"id":"1.231540820","rc":[{"batb":[[0,1.97,10],[1,1.96,46.26],[2,1.32,3.28]],"ltp":2.0,"tv":88.69,"id":2219}]}]}
{"op":"mcm","clk":"11801214951","pt":1723064726628,"mc":[{"id":"1.231540820","rc":[{"batb":[[0,1.96,46.26],[1,1.32,3.28],[2,1.3,2.93]],"ltp":2.0,"tv":88.69,"id":2219}]}]}
{"op":"mcm","clk":"11801215088","pt":1723064730016,"mc":[{"id":"1.231540820","rc":[{"batb":[[0,1.97,10],[1,1.96,46.26],[2,1.32,3.28]],"ltp":2.0,"tv":88.69,"id":2219}]}]}
{"op":"mcm","clk":"11801215249","pt":1723064733398,"mc":[{"id":"1.231540820","rc":[{"batb":[[0,1.96,46.26],[1,1.32,3.28],[2,1.3,2.93]],"ltp":2.0,"tv":88.69,"id":2219}]}]}
{"op":"mcm","clk":"11801215343","pt":1723064735903,"mc":[{"id":"1.231540820","rc":[{"batb":[[0,1.97,10],[1,1.96,46.26],[2,1.32,3.28]],"ltp":2.0,"tv":88.69,"id":2219}]}]}
{"op":"mcm","clk":"11801215500","pt":1723064739336,"mc":[{"id":"1.231540820","rc":[{"batb":[[0,1.96,46.26],[1,1.32,3.28],[2,1.3,2.93]],"ltp":2.0,"tv":88.69,"id":2219}]}]}
{"op":"mcm","clk":"11801215640","pt":1723064742639,"mc":[{"id":"1.231540820","rc":[{"batb":[[0,1.97,10],[1,1.96,46.26],[2,1.32,3.28]],"ltp":2.0,"tv":88.69,"id":2219}]}]}
{"op":"mcm","clk":"11801215783","pt":1723064746145,"mc":[{"id":"1.231540820","rc":[{"batb":[[0,1.96,46.26],[1,1.32,3.28],[2,1.3,2.93]],"ltp":2.0,"tv":88.69,"id":2219}]}]}
{"op":"mcm","clk":"11801215935","pt":1723064749852,"mc":[{"id":"1.231540820","rc":[{"batb":[[0,1.97,10],[1,1.96,46.26],[2,1.32,3.28]],"ltp":2.0,"tv":88.69,"id":2219}]}]}
{"op":"mcm","clk":"11801216061","pt":1723064753246,"mc":[{"id":"1.231540820","rc":[{"batb":[[0,1.96,46.26],[1,1.32,3.28],[2,1.3,2.93]],"ltp":2.0,"tv":88.69,"id":2219}]}]}
{"op":"mcm","clk":"11801216230","pt":1723064757170,"mc":[{"id":"1.231540820","rc":[{"batb":[[0,1.97,10],[1,1.96,46.26],[2,1.32,3.28]],"ltp":2.0,"tv":88.69,"id":2219}]}]}
{"op":"mcm","clk":"11801216373","pt":1723064760561,"mc":[{"id":"1.231540820","rc":[{"batb":[[0,1.96,46.26],[1,1.32,3.28],[2,1.3,2.93]],"ltp":2.0,"tv":88.69,"id":2219}]}]}
{"op":"mcm","clk":"11801216640","pt":1723064766257,"mc":[{"id":"1.231540820","rc":[{"batb":[[0,1.97,10],[1,1.96,46.26],[2,1.32,3.28]],"ltp":2.0,"tv":88.69,"id":2219}]}]}
{"op":"mcm","clk":"11801216782","pt":1723064769692,"mc":[{"id":"1.231540820","rc":[{"batb":[[0,1.96,46.26],[1,1.32,3.28],[2,1.3,2.93]],"ltp":2.0,"tv":88.69,"id":2219}]}]}
{"op":"mcm","clk":"11801216870","pt":1723064771897,"mc":[{"id":"1.231540820","rc":[{"batb":[[0,1.97,10],[1,1.96,46.26],[2,1.32,3.28]],"ltp":2.0,"tv":88.69,"id":2219}]}]}
{"op":"mcm","clk":"11801216989","pt":1723064775278,"mc":[{"id":"1.231540820","rc":[{"batb":[[0,1.96,46.26],[1,1.32,3.28],[2,1.3,2.93]],"ltp":2.0,"tv":88.69,"id":2219}]}]}
{"op":"mcm","clk":"11801217110","pt":1723064778101,"mc":[{"id":"1.231540820","rc":[{"batb":[[0,1.97,10],[1,1.96,46.26],[2,1.32,3.28]],"ltp":2.0,"tv":88.69,"id":2219}]}]}
{"op":"mcm","clk":"11801217261","pt":1723064781491,"mc":[{"id":"1.231540820","rc":[{"batb":[[0,1.96,46.26],[1,1.32,3.28],[2,1.3,2.93]],"ltp":2.0,"tv":88.69,"id":2219}]}]}
{"op":"mcm","clk":"11801217397","pt":1723064784609,"mc":[{"id":"1.231540820","rc":[{"batb":[[0,1.97,10],[1,1.96,46.26],[2,1.32,3.28]],"ltp":2.0,"tv":88.69,"id":2219}]}]}
{"op":"mcm","clk":"11801217529","pt":1723064788094,"mc":[{"id":"1.231540820","rc":[{"batb":[[0,1.96,46.26],[1,1.32,3.28],[2,1.3,2.93]],"ltp":2.0,"tv":88.69,"id":2219}]}]}
{"op":"mcm","clk":"11801217629","pt":1723064790401,"mc":[{"id":"1.231540820","rc":[{"batb":[[0,1.97,10],[1,1.96,46.26],[2,1.32,3.28]],"ltp":2.0,"tv":88.69,"id":2219}]}]}
{"op":"mcm","clk":"11801217830","pt":1723064793890,"mc":[{"id":"1.231540820","rc":[{"batb":[[0,1.96,46.26],[1,1.32,3.28],[2,1.3,2.93]],"ltp":2.0,"tv":88.69,"id":2219}]}]}
{"op":"mcm","clk":"11801217922","pt":1723064796411,"mc":[{"id":"1.231540820","rc":[{"batb":[[0,1.97,10],[1,1.96,46.26],[2,1.32,3.28]],"ltp":2.0,"tv":88.69,"id":2219}]}]}
{"op":"mcm","clk":"11801218091","pt":1723064799793,"mc":[{"id":"1.231540820","rc":[{"batb":[[0,1.96,46.26],[1,1.32,3.28],[2,1.3,2.93]],"ltp":2.0,"tv":88.69,"id":2219}]}]}
{"op":"mcm","clk":"11801218222","pt":1723064802412,"mc":[{"id":"1.231540820","rc":[{"batb":[[0,1.97,10],[1,1.96,46.26],[2,1.32,3.28]],"ltp":2.0,"tv":88.69,"id":2219}]}]}
{"op":"mcm","clk":"11801218356","pt":1723064805998,"mc":[{"id":"1.231540820","rc":[{"batb":[[0,1.96,46.26],[1,1.32,3.28],[2,1.3,2.93]],"ltp":2.0,"tv":88.69,"id":2219}]}]}
{"op":"mcm","clk":"11801218429","pt":1723064808201,"mc":[{"id":"1.231540820","rc":[{"batb":[[0,1.97,10],[1,1.96,46.26],[2,1.32,3.28]],"ltp":2.0,"tv":88.69,"id":2219}]}]}
{"op":"mcm","clk":"11801218568","pt":1723064811634,"mc":[{"id":"1.231540820","rc":[{"batb":[[0,1.96,46.26],[1,1.32,3.28],[2,1.3,2.93]],"ltp":2.0,"tv":88.69,"id":2219}]}]}
{"op":"mcm","clk":"11801218827","pt":1723064817416,"mc":[{"id":"1.231540820","rc":[{"batb":[[0,1.97,10],[1,1.96,46.26],[2,1.32,3.28]],"ltp":2.0,"tv":88.69,"id":2219}]}]}
{"op":"mcm","clk":"11801218995","pt":1723064821049,"mc":[{"id":"1.231540820","rc":[{"batb":[[0,1.96,46.26],[1,1.32,3.28],[2,1.3,2.93]],"ltp":2.0,"tv":88.69,"id":2219}]}]}
{"op":"mcm","clk":"11801219121","pt":1723064823459,"mc":[{"id":"1.231540820","rc":[{"batb":[[0,1.97,10],[1,1.96,46.26],[2,1.32,3.28]],"ltp":2.0,"tv":88.69,"id":2219}]}]}
{"op":"mcm","clk":"11801219248","pt":1723064826843,"mc":[{"id":"1.231540820","rc":[{"batb":[[0,1.96,46.26],[1,1.32,3.28],[2,1.3,2.93]],"ltp":2.0,"tv":88.69,"id":2219}]}]}
{"op":"mcm","clk":"11801219375","pt":1723064829765,"mc":[{"id":"1.231540820","rc":[{"batb":[[0,1.97,10],[1,1.96,46.26],[2,1.32,3.28]],"ltp":2.0,"tv":88.69,"id":2219}]}]}
{"op":"mcm","clk":"11801219500","pt":1723064833263,"mc":[{"id":"1.231540820","rc":[{"batb":[[0,1.96,46.26],[1,1.32,3.28],[2,1.3,2.93]],"ltp":2.0,"tv":88.69,"id":2219}]}]}
{"op":"mcm","clk":"11801219623","pt":1723064836132,"mc":[{"id":"1.231540820","rc":[{"batb":[[0,1.97,10],[1,1.96,46.26],[2,1.32,3.28]],"ltp":2.0,"tv":88.69,"id":2219}]}]}
{"op":"mcm","clk":"11801219757","pt":1723064839666,"mc":[{"id":"1.231540820","rc":[{"batb":[[0,1.96,46.26],[1,1.32,3.28],[2,1.3,2.93]],"ltp":2.0,"tv":88.69,"id":2219}]}]}
{"op":"mcm","clk":"11801219885","pt":1723064843048,"mc":[{"id":"1.231540820","rc":[{"batb":[[0,1.97,10],[1,1.96,46.26],[2,1.32,3.28]],"ltp":2.0,"tv":88.69,"id":2219}]}]}
{"op":"mcm","clk":"11801220034","pt":1723064846483,"mc":[{"id":"1.231540820","rc":[{"batb":[[0,1.96,46.26],[1,1.32,3.28],[2,1.3,2.93]],"ltp":2.0,"tv":88.69,"id":2219}]}]}
{"op":"mcm","clk":"11801220136","pt":1723064848847,"mc":[{"id":"1.231540820","rc":[{"batb":[[0,1.97,10],[1,1.96,46.26],[2,1.32,3.28]],"ltp":2.0,"tv":88.69,"id":2219}]}]}
{"op":"mcm","clk":"11801220314","pt":1723064852471,"mc":[{"id":"1.231540820","rc":[{"batb":[[0,1.96,46.26],[1,1.32,3.28],[2,1.3,2.93]],"ltp":2.0,"tv":88.69,"id":2219}]}]}
{"op":"mcm","clk":"11801220411","pt":1723064854889,"mc":[{"id":"1.231540820","rc":[{"batb":[[0,1.97,10],[1,1.96,46.26],[2,1.32,3.28]],"ltp":2.0,"tv":88.69,"id":2219}]}]}
{"op":"mcm","clk":"11801220596","pt":1723064858280,"mc":[{"id":"1.231540820","rc":[{"batb":[[0,1.96,46.26],[1,1.32,3.28],[2,1.3,2.93]],"ltp":2.0,"tv":88.69,"id":2219}]}]}
{"op":"mcm","clk":"11801220696","pt":1723064860793,"mc":[{"id":"1.231540820","rc":[{"batb":[[0,1.97,10],[1,1.96,46.26],[2,1.32,3.28]],"ltp":2.0,"tv":88.69,"id":2219}]}]}
{"op":"mcm","clk":"11801220812","pt":1723064864074,"mc":[{"id":"1.231540820","rc":[{"batb":[[0,1.96,46.26],[1,1.32,3.28],[2,1.3,2.93]],"ltp":2.0,"tv":88.69,"id":2219}]}]}
{"op":"mcm","clk":"11801220955","pt":1723064867666,"mc":[{"id":"1.231540820","rc":[{"batb":[[0,1.97,10],[1,1.96,46.26],[2,1.32,3.28]],"ltp":2.0,"tv":88.69,"id":2219}]}]}
{"op":"mcm","clk":"11801221077","pt":1723064871196,"mc":[{"id":"1.231540820","rc":[{"batb":[[0,1.96,46.26],[1,1.32,3.28],[2,1.3,2.93]],"ltp":2.0,"tv":88.69,"id":2219}]}]}
{"op":"mcm","clk":"11801221199","pt":1723064874320,"mc":[{"id":"1.231540820","rc":[{"batb":[[0,1.97,10],[1,1.96,46.26],[2,1.32,3.28]],"ltp":2.0,"tv":88.69,"id":2219}]}]}
{"op":"mcm","clk":"11801221318","pt":1723064877706,"mc":[{"id":"1.231540820","rc":[{"batb":[[0,1.96,46.26],[1,1.32,3.28],[2,1.3,2.93]],"ltp":2.0,"tv":88.69,"id":2219}]}]}
{"op":"mcm","clk":"11801221428","pt":1723064880826,"mc":[{"id":"1.231540820","rc":[{"batb":[[0,1.97,10],[1,1.96,46.26],[2,1.32,3.28]],"ltp":2.0,"tv":88.69,"id":2219}]}]}
{"op":"mcm","clk":"11801221625","pt":1723064884318,"mc":[{"id":"1.231540820","rc":[{"batb":[[0,1.96,46.26],[1,1.32,3.28],[2,1.3,2.93]],"ltp":2.0,"tv":88.69,"id":2219}]}]}
{"op":"mcm","clk":"11801221733","pt":1723064886825,"mc":[{"id":"1.231540820","rc":[{"batb":[[0,1.97,10],[1,1.96,46.26],[2,1.32,3.28]],"ltp":2.0,"tv":88.69,"id":2219}]}]}
{"op":"mcm","clk":"11801221857","pt":1723064890106,"mc":[{"id":"1.231540820","rc":[{"batb":[[0,1.96,46.26],[1,1.32,3.28],[2,1.3,2.93]],"ltp":2.0,"tv":88.69,"id":2219}]}]}
{"op":"mcm","clk":"11801221963","pt":1723064893025,"mc":[{"id":"1.231540820","rc":[{"batb":[[0,1.97,10],[1,1.96,46.26],[2,1.32,3.28]],"ltp":2.0,"tv":88.69,"id":2219}]}]}
{"op":"mcm","clk":"11801222122","pt":1723064896417,"mc":[{"id":"1.231540820","rc":[{"batb":[[0,1.96,46.26],[1,1.32,3.28],[2,1.3,2.93]],"ltp":2.0,"tv":88.69,"id":2219}]}]}
{"op":"mcm","clk":"11801222246","pt":1723064899648,"mc":[{"id":"1.231540820","rc":[{"batb":[[0,1.97,10],[1,1.96,46.26],[2,1.32,3.28]],"ltp":2.0,"tv":88.69,"id":2219}]}]}
{"op":"mcm","clk":"11801222385","pt":1723064903037,"mc":[{"id":"1.231540820","rc":[{"batb":[[0,1.96,46.26],[1,1.32,3.28],[2,1.3,2.93]],"ltp":2.0,"tv":88.69,"id":2219}]}]}
{"op":"mcm","clk":"11801222492","pt":1723064905854,"mc":[{"id":"1.231540820","rc":[{"batb":[[0,1.97,10],[1,1.96,46.26],[2,1.32,3.28]],"ltp":2.0,"tv":88.69,"id":2219}]}]}
{"op":"mcm","clk":"11801222652","pt":1723064909440,"mc":[{"id":"1.231540820","rc":[{"batb":[[0,1.96,46.26],[1,1.32,3.28],[2,1.3,2.93]],"ltp":2.0,"tv":88.69,"id":2219}]}]}
{"op":"mcm","clk":"11801222739","pt":1723064911851,"mc":[{"id":"1.231540820","rc":[{"batb":[[0,1.97,10],[1,1.96,46.26],[2,1.32,3.28]],"ltp":2.0,"tv":88.69,"id":2219}]}]}
{"op":"mcm","clk":"11801222857","pt":1723064915233,"mc":[{"id":"1.231540820","rc":[{"batb":[[0,1.96,46.26],[1,1.32,3.28],[2,1.3,2.93]],"ltp":2.0,"tv":88.69,"id":2219}]}]}
{"op":"mcm","clk":"11801222977","pt":1723064917747,"mc":[{"id":"1.231540820","rc":[{"batb":[[0,1.97,10],[1,1.96,46.26],[2,1.32,3.28]],"ltp":2.0,"tv":88.69,"id":2219}]}]}
{"op":"mcm","clk":"11801223176","pt":1723064921285,"mc":[{"id":"1.231540820","rc":[{"batb":[[0,1.96,46.26],[1,1.32,3.28],[2,1.3,2.93]],"ltp":2.0,"tv":88.69,"id":2219}]}]}
{"op":"mcm","clk":"11801223317","pt":1723064924150,"mc":[{"id":"1.231540820","rc":[{"batb":[[0,1.97,10],[1,1.96,46.26],[2,1.32,3.28]],"ltp":2.0,"tv":88.69,"id":2219}]}]}
{"op":"mcm","clk":"11801223469","pt":1723064927578,"mc":[{"id":"1.231540820","rc":[{"batb":[[0,1.96,46.26],[1,1.32,3.28],[2,1.3,2.93]],"ltp":2.0,"tv":88.69,"id":2219}]}]}
{"op":"mcm","clk":"11801223577","pt":1723064930350,"mc":[{"id":"1.231540820","rc":[{"batb":[[0,1.97,10],[1,1.96,46.26],[2,1.32,3.28]],"ltp":2.0,"tv":88.69,"id":2219}]}]}
{"op":"mcm","clk":"11801223727","pt":1723064934096,"mc":[{"id":"1.231540820","rc":[{"batb":[[0,1.96,46.26],[1,1.32,3.28],[2,1.3,2.93]],"ltp":2.0,"tv":88.69,"id":2219}]}]}
{"op":"mcm","clk":"11801223837","pt":1723064936366,"mc":[{"id":"1.231540820","rc":[{"batb":[[0,1.97,10],[1,1.96,46.26],[2,1.32,3.28]],"ltp":2.0,"tv":88.69,"id":2219}]}]}
{"op":"mcm","clk":"11801224045","pt":1723064939565,"mc":[{"id":"1.231540820","rc":[{"batb":[[0,1.96,46.26],[1,1.32,3.28],[2,1.3,2.93]],"ltp":2.0,"tv":88.69,"id":2219}]}]}
{"op":"mcm","clk":"11801224162","pt":1723064941987,"mc":[{"id":"1.231540820","rc":[{"batb":[[0,1.97,10],[1,1.96,46.26],[2,1.32,3.28]],"ltp":2.0,"tv":88.69,"id":2219}]}]}
{"op":"mcm","clk":"11801224306","pt":1723064945373,"mc":[{"id":"1.231540820","rc":[{"batb":[[0,1.96,46.26],[1,1.32,3.28],[2,1.3,2.93]],"ltp":2.0,"tv":88.69,"id":2219}]}]}
{"op":"mcm","clk":"11801224423","pt":1723064947888,"mc":[{"id":"1.231540820","rc":[{"batb":[[0,1.97,10],[1,1.96,46.26],[2,1.32,3.28]],"ltp":2.0,"tv":88.69,"id":2219}]}]}
{"op":"mcm","clk":"11801224580","pt":1723064951178,"mc":[{"id":"1.231540820","rc":[{"batb":[[0,1.96,46.26],[1,1.32,3.28],[2,1.3,2.93]],"ltp":2.0,"tv":88.69,"id":2219}]}]}
{"op":"mcm","clk":"11801224691","pt":1723064954215,"mc":[{"id":"1.231540820","rc":[{"batb":[[0,1.97,10],[1,1.96,46.26],[2,1.32,3.28]],"ltp":2.0,"tv":88.69,"id":2219}]}]}
{"op":"mcm","clk":"11801224822","pt":1723064957710,"mc":[{"id":"1.231540820","rc":[{"batb":[[0,1.96,46.26],[1,1.32,3.28],[2,1.3,2.93]],"ltp":2.0,"tv":88.69,"id":2219}]}]}
{"op":"mcm","clk":"11801224962","pt":1723064960800,"mc":[{"id":"1.231540820","rc":[{"batb":[[0,1.97,10],[1,1.96,46.26],[2,1.32,3.28]],"ltp":2.0,"tv":88.69,"id":2219}]}]}
{"op":"mcm","clk":"11801225120","pt":1723064964501,"mc":[{"id":"1.231540820","rc":[{"batb":[[0,1.96,46.26],[1,1.32,3.28],[2,1.3,2.93]],"ltp":2.0,"tv":88.69,"id":2219}]}]}
{"op":"mcm","clk":"11801225238","pt":1723064967526,"mc":[{"id":"1.231540820","rc":[{"batb":[[0,1.97,10],[1,1.96,46.26],[2,1.32,3.28]],"ltp":2.0,"tv":88.69,"id":2219}]}]}
{"op":"mcm","clk":"11801225375","pt":1723064971532,"mc":[{"id":"1.231540820","rc":[{"batb":[[0,1.96,46.26],[1,1.32,3.28],[2,1.3,2.93]],"ltp":2.0,"tv":88.69,"id":2219}]}]}
{"op":"mcm","clk":"11801225449","pt":1723064973740,"mc":[{"id":"1.231540820","rc":[{"batb":[[0,1.97,10],[1,1.96,46.26],[2,1.32,3.28]],"ltp":2.0,"tv":88.69,"id":2219}]}]}
{"op":"mcm","clk":"11801225586","pt":1723064977131,"mc":[{"id":"1.231540820","rc":[{"batb":[[0,1.96,46.26],[1,1.32,3.28],[2,1.3,2.93]],"ltp":2.0,"tv":88.69,"id":2219}]}]}
{"op":"mcm","clk":"11801225676","pt":1723064979339,"mc":[{"id":"1.231540820","rc":[{"batb":[[0,1.97,10],[1,1.96,46.26],[2,1.32,3.28]],"ltp":2.0,"tv":88.69,"id":2219}]}]}
{"op":"mcm","clk":"11801225833","pt":1723064982721,"mc":[{"id":"1.231540820","rc":[{"batb":[[0,1.96,46.26],[1,1.32,3.28],[2,1.3,2.93]],"ltp":2.0,"tv":88.69,"id":2219}]}]}
{"op":"mcm","clk":"11801226024","pt":1723064987442,"mc":[{"id":"1.231540820","rc":[{"batb":[[0,1.97,10],[1,1.96,46.26],[2,1.32,3.28]],"ltp":2.0,"tv":88.69,"id":2219}]}]}
{"op":"mcm","clk":"11801226188","pt":1723064991039,"mc":[{"id":"1.231540820","rc":[{"batb":[[0,1.96,46.26],[1,1.32,3.28],[2,1.3,2.93]],"ltp":2.0,"tv":88.69,"id":2219}]}]}
{"op":"mcm","clk":"11801226377","pt":1723064994736,"mc":[{"id":"1.231540820","rc":[{"batb":[[0,1.97,10],[1,1.96,46.26],[2,1.32,3.28]],"ltp":2.0,"tv":88.69,"id":2219}]}]}
{"op":"mcm","clk":"11801226545","pt":1723064998273,"mc":[{"id":"1.231540820","rc":[{"batb":[[0,1.96,46.26],[1,1.32,3.28],[2,1.3,2.93]],"ltp":2.0,"tv":88.69,"id":2219}]}]}
{"op":"mcm","clk":"11801226643","pt":1723065000840,"mc":[{"id":"1.231540820","rc":[{"batb":[[0,1.97,10],[1,1.96,46.26],[2,1.32,3.28]],"ltp":2.0,"tv":88.69,"id":2219}]}]}
{"op":"mcm","clk":"11801226797","pt":1723065004283,"mc":[{"id":"1.231540820","rc":[{"batb":[[0,1.96,46.26],[1,1.32,3.28],[2,1.3,2.93]],"ltp":2.0,"tv":88.69,"id":2219}]}]}
{"op":"mcm","clk":"11801226972","pt":1723065008087,"mc":[{"id":"1.231540820","rc":[{"batb":[[0,1.97,10],[1,1.96,46.26],[2,1.32,3.28]],"ltp":2.0,"tv":88.69,"id":2219}]}]}
{"op":"mcm","clk":"11801227122","pt":1723065011381,"mc":[{"id":"1.231540820","rc":[{"batb":[[0,1.96,46.26],[1,1.32,3.28],[2,1.3,2.93]],"ltp":2.0,"tv":88.69,"id":2219}]}]}
{"op":"mcm","clk":"11801227268","pt":1723065014368,"mc":[{"id":"1.231540820","rc":[{"batb":[[0,1.97,10],[1,1.96,46.26],[2,1.32,3.28]],"ltp":2.0,"tv":88.69,"id":2219}]}]}
{"op":"mcm","clk":"11801227435","pt":1723065017764,"mc":[{"id":"1.231540820","rc":[{"batb":[[0,1.96,46.26],[1,1.32,3.28],[2,1.3,2.93]],"ltp":2.0,"tv":88.69,"id":2219}]}]}
{"op":"mcm","clk":"11801227551","pt":1723065020385,"mc":[{"id":"1.231540820","rc":[{"batb":[[0,1.97,10],[1,1.96,46.26],[2,1.32,3.28]],"ltp":2.0,"tv":88.69,"id":2219}]}]}
{"op":"mcm","clk":"11801227701","pt":1723065023774,"mc":[{"id":"1.231540820","rc":[{"batb":[[0,1.96,46.26],[1,1.32,3.28],[2,1.3,2.93]],"ltp":2.0,"tv":88.69,"id":2219}]}]}
{"op":"mcm","clk":"11801227849","pt":1723065026905,"mc":[{"id":"1.231540820","rc":[{"batb":[[0,1.97,10],[1,1.96,46.26],[2,1.32,3.28]],"ltp":2.0,"tv":88.69,"id":2219}]}]}
{"op":"mcm","clk":"11801228011","pt":1723065030499,"mc":[{"id":"1.231540820","rc":[{"batb":[[0,1.96,46.26],[1,1.32,3.28],[2,1.3,2.93]],"ltp":2.0,"tv":88.69,"id":2219}]}]}
{"op":"mcm","clk":"11801228166","pt":1723065034197,"mc":[{"id":"1.231540820","rc":[{"batb":[[0,1.97,10],[1,1.96,46.26],[2,1.32,3.28]],"ltp":2.0,"tv":88.69,"id":2219}]}]}
{"op":"mcm","clk":"11801228315","pt":1723065037535,"mc":[{"id":"1.231540820","rc":[{"batb":[[0,1.96,46.26],[1,1.32,3.28],[2,1.3,2.93]],"ltp":2.0,"tv":88.69,"id":2219}]}]}
{"op":"mcm","clk":"11801228429","pt":1723065040097,"mc":[{"id":"1.231540820","rc":[{"batb":[[0,1.97,10],[1,1.96,46.26],[2,1.32,3.28]],"ltp":2.0,"tv":88.69,"id":2219}]}]}
{"op":"mcm","clk":"11801228586","pt":1723065043436,"mc":[{"id":"1.231540820","rc":[{"batb":[[0,1.96,46.26],[1,1.32,3.28],[2,1.3,2.93]],"ltp":2.0,"tv":88.69,"id":2219}]}]}
{"op":"mcm","clk":"11801228720","pt":1723065046627,"mc":[{"id":"1.231540820","rc":[{"batb":[[0,1.97,10],[1,1.96,46.26],[2,1.32,3.28]],"ltp":2.0,"tv":88.69,"id":2219}]}]}
{"op":"mcm","clk":"11801228868","pt":1723065050114,"mc":[{"id":"1.231540820","rc":[{"batb":[[0,1.96,46.26],[1,1.32,3.28],[2,1.3,2.93]],"ltp":2.0,"tv":88.69,"id":2219}]}]}
{"op":"mcm","clk":"11801228992","pt":1723065052628,"mc":[{"id":"1.231540820","rc":[{"batb":[[0,1.97,10],[1,1.96,46.26],[2,1.32,3.28]],"ltp":2.0,"tv":88.69,"id":2219}]}]}
{"op":"mcm","clk":"11801229158","pt":1723065056366,"mc":[{"id":"1.231540820","rc":[{"batb":[[0,1.96,46.26],[1,1.32,3.28],[2,1.3,2.93]],"ltp":2.0,"tv":88.69,"id":2219}]}]}
{"op":"mcm","clk":"11801229291","pt":1723065060058,"mc":[{"id":"1.231540820","rc":[{"batb":[[0,1.97,10],[1,1.96,46.26],[2,1.32,3.28]],"ltp":2.0,"tv":88.69,"id":2219}]}]}
{"op":"mcm","clk":"11801229436","pt":1723065063540,"mc":[{"id":"1.231540820","rc":[{"batb":[[0,1.96,46.26],[1,1.32,3.28],[2,1.3,2.93]],"ltp":2.0,"tv":88.69,"id":2219}]}]}
{"op":"mcm","clk":"11801229555","pt":1723065066868,"mc":[{"id":"1.231540820","rc":[{"batb":[[0,1.97,10],[1,1.96,46.26],[2,1.32,3.28]],"ltp":2.0,"tv":88.69,"id":2219}]}]}
{"op":"mcm","clk":"11801229718","pt":1723065070146,"mc":[{"id":"1.231540820","rc":[{"batb":[[0,1.96,46.26],[1,1.32,3.28],[2,1.3,2.93]],"ltp":2.0,"tv":88.69,"id":2219}]}]}
{"op":"mcm","clk":"11801229823","pt":1723065072246,"mc":[{"id":"1.231540820","rc":[{"batb":[[0,1.97,10],[1,1.96,46.26],[2,1.32,3.28]],"ltp":2.0,"tv":88.69,"id":2219}]}]}
{"op":"mcm","clk":"11801229977","pt":1723065075851,"mc":[{"id":"1.231540820","rc":[{"batb":[[0,1.96,46.26],[1,1.32,3.28],[2,1.3,2.93]],"ltp":2.0,"tv":88.69,"id":2219}]}]}
{"op":"mcm","clk":"11801230110","pt":1723065078773,"mc":[{"id":"1.231540820","rc":[{"batb":[[0,1.97,10],[1,1.96,46.26],[2,1.32,3.28]],"ltp":2.0,"tv":88.69,"id":2219}]}]}
{"op":"mcm","clk":"11801230257","pt":1723065082157,"mc":[{"id":"1.231540820","rc":[{"batb":[[0,1.96,46.26],[1,1.32,3.28],[2,1.3,2.93]],"ltp":2.0,"tv":88.69,"id":2219}]}]}
{"op":"mcm","clk":"11801230353","pt":1723065084268,"mc":[{"id":"1.231540820","rc":[{"batb":[[0,1.97,10],[1,1.96,46.26],[2,1.32,3.28]],"ltp":2.0,"tv":88.69,"id":2219}]}]}
{"op":"mcm","clk":"11801230476","pt":1723065087553,"mc":[{"id":"1.231540820","rc":[{"batb":[[0,1.96,46.26],[1,1.32,3.28],[2,1.3,2.93]],"ltp":2.0,"tv":88.69,"id":2219}]}]}
{"op":"mcm","clk":"11801230599","pt":1723065090370,"mc":[{"id":"1.231540820","rc":[{"batb":[[0,1.97,10],[1,1.96,46.26],[2,1.32,3.28]],"ltp":2.0,"tv":88.69,"id":2219}]}]}
{"op":"mcm","clk":"11801230785","pt":1723065093759,"mc":[{"id":"1.231540820","rc":[{"batb":[[0,1.96,46.26],[1,1.32,3.28],[2,1.3,2.93]],"ltp":2.0,"tv":88.69,"id":2219}]}]}
{"op":"mcm","clk":"11801230893","pt":1723065096269,"mc":[{"id":"1.231540820","rc":[{"batb":[[0,1.97,10],[1,1.96,46.26],[2,1.32,3.28]],"ltp":2.0,"tv":88.69,"id":2219}]}]}
{"op":"mcm","clk":"11801231067","pt":1723065099710,"mc":[{"id":"1.231540820","rc":[{"batb":[[0,1.96,46.26],[1,1.32,3.28],[2,1.3,2.93]],"ltp":2.0,"tv":88.69,"id":2219}]}]}
{"op":"mcm","clk":"11801231240","pt":1723065103199,"mc":[{"id":"1.231540820","rc":[{"batb":[[0,1.97,10],[1,1.96,46.26],[2,1.32,3.28]],"ltp":2.0,"tv":88.69,"id":2219}]}]}
{"op":"mcm","clk":"11801231409","pt":1723065106483,"mc":[{"id":"1.231540820","rc":[{"batb":[[0,1.96,46.26],[1,1.32,3.28],[2,1.3,2.93]],"ltp":2.0,"tv":88.69,"id":2219}]}]}
{"op":"mcm","clk":"11801231570","pt":1723065109824,"mc":[{"id":"1.231540820","rc":[{"batb":[[0,1.97,10],[1,1.96,46.26],[2,1.32,3.28]],"ltp":2.0,"tv":88.69,"id":2219}]}]}
{"op":"mcm","clk":"11801231944","pt":1723065113413,"mc":[{"id":"1.231540820","rc":[{"batb":[[0,1.96,46.26],[1,1.32,3.28],[2,1.3,2.93]],"ltp":2.0,"tv":88.69,"id":2219}]}]}
{"op":"mcm","clk":"11801232069","pt":1723065115627,"mc":[{"id":"1.231540820","rc":[{"batb":[[0,1.97,10],[1,1.96,46.26],[2,1.32,3.28]],"ltp":2.0,"tv":88.69,"id":2219}]}]}
{"op":"mcm","clk":"11801232212","pt":1723065119009,"mc":[{"id":"1.231540820","rc":[{"batb":[[0,1.96,46.26],[1,1.32,3.28],[2,1.3,2.93]],"ltp":2.0,"tv":88.69,"id":2219}]}]}
{"op":"mcm","clk":"11801232359","pt":1723065121931,"mc":[{"id":"1.231540820","rc":[{"batb":[[0,1.97,10],[1,1.96,46.26],[2,1.32,3.28]],"ltp":2.0,"tv":88.69,"id":2219}]}]}
{"op":"mcm","clk":"11801232530","pt":1723065125319,"mc":[{"id":"1.231540820","rc":[{"batb":[[0,1.96,46.26],[1,1.32,3.28],[2,1.3,2.93]],"ltp":2.0,"tv":88.69,"id":2219}]}]}
{"op":"mcm","clk":"11801232647","pt":1723065127728,"mc":[{"id":"1.231540820","rc":[{"batb":[[0,1.97,10],[1,1.96,46.26],[2,1.32,3.28]],"ltp":2.0,"tv":88.69,"id":2219}]}]}
{"op":"mcm","clk":"11801232801","pt":1723065131012,"mc":[{"id":"1.231540820","rc":[{"batb":[[0,1.96,46.26],[1,1.32,3.28],[2,1.3,2.93]],"ltp":2.0,"tv":88.69,"id":2219}]}]}
{"op":"mcm","clk":"11801232923","pt":1723065133931,"mc":[{"id":"1.231540820","rc":[{"batb":[[0,1.97,10],[1,1.96,46.26],[2,1.32,3.28]],"ltp":2.0,"tv":88.69,"id":2219}]}]}
{"op":"mcm","clk":"11801233098","pt":1723065137438,"mc":[{"id":"1.231540820","rc":[{"batb":[[0,1.96,46.26],[1,1.32,3.28],[2,1.3,2.93]],"ltp":2.0,"tv":88.69,"id":2219}]}]}
{"op":"mcm","clk":"11801233206","pt":1723065140357,"mc":[{"id":"1.231540820","rc":[{"batb":[[0,1.97,10],[1,1.96,46.26],[2,1.32,3.28]],"ltp":2.0,"tv":88.69,"id":2219}]}]}
{"op":"mcm","clk":"11801233377","pt":1723065143741,"mc":[{"id":"1.231540820","rc":[{"batb":[[0,1.96,46.26],[1,1.32,3.28],[2,1.3,2.93]],"ltp":2.0,"tv":88.69,"id":2219}]}]}
{"op":"mcm","clk":"11801233504","pt":1723065146252,"mc":[{"id":"1.231540820","rc":[{"batb":[[0,1.97,10],[1,1.96,46.26],[2,1.32,3.28]],"ltp":2.0,"tv":88.69,"id":2219}]}]}
{"op":"mcm","clk":"11801233674","pt":1723065149638,"mc":[{"id":"1.231540820","rc":[{"batb":[[0,1.96,46.26],[1,1.32,3.28],[2,1.3,2.93]],"ltp":2.0,"tv":88.69,"id":2219}]}]}
{"op":"mcm","clk":"11801233802","pt":1723065152043,"mc":[{"id":"1.231540820","rc":[{"batb":[[0,1.97,10],[1,1.96,46.26],[2,1.32,3.28]],"ltp":2.0,"tv":88.69,"id":2219}]}]}
{"op":"mcm","clk":"11801233997","pt":1723065155634,"mc":[{"id":"1.231540820","rc":[{"batb":[[0,1.96,46.26],[1,1.32,3.28],[2,1.3,2.93]],"ltp":2.0,"tv":88.69,"id":2219}]}]}
{"op":"mcm","clk":"11801234175","pt":1723065158964,"mc":[{"id":"1.231540820","rc":[{"batb":[[0,1.97,10],[1,1.96,46.26],[2,1.32,3.28]],"ltp":2.0,"tv":88.69,"id":2219}]}]}
{"op":"mcm","clk":"11801234363","pt":1723065162356,"mc":[{"id":"1.231540820","rc":[{"batb":[[0,1.96,46.26],[1,1.32,3.28],[2,1.3,2.93]],"ltp":2.0,"tv":88.69,"id":2219}]}]}
{"op":"mcm","clk":"11801234565","pt":1723065166155,"mc":[{"id":"1.231540820","rc":[{"batb":[[0,1.97,10],[1,1.96,46.26],[2,1.32,3.28]],"ltp":2.0,"tv":88.69,"id":2219}]}]}
{"op":"mcm","clk":"11801234776","pt":1723065169485,"mc":[{"id":"1.231540820","rc":[{"batb":[[0,1.96,46.26],[1,1.32,3.28],[2,1.3,2.93]],"ltp":2.0,"tv":88.69,"id":2219}]}]}
{"op":"mcm","clk":"11801234914","pt":1723065171955,"mc":[{"id":"1.231540820","rc":[{"batb":[[0,1.97,10],[1,1.96,46.26],[2,1.32,3.28]],"ltp":2.0,"tv":88.69,"id":2219}]}]}
{"op":"mcm","clk":"11801243947","pt":1723065175283,"mc":[{"id":"1.231540820","rc":[{"batb":[[0,1.96,46.26],[1,1.32,3.28],[2,1.3,2.93]],"ltp":2.0,"tv":88.69,"id":2219}]}]}
{"op":"mcm","clk":"11801244076","pt":1723065177794,"mc":[{"id":"1.231540820","rc":[{"batb":[[0,1.97,10],[1,1.96,46.26],[2,1.32,3.28]],"ltp":2.0,"tv":88.69,"id":2219}]}]}
{"op":"mcm","clk":"11801244291","pt":1723065181592,"mc":[{"id":"1.231540820","rc":[{"batb":[[0,1.96,46.26],[1,1.32,3.28],[2,1.3,2.93]],"ltp":2.0,"tv":88.69,"id":2219}]}]}
{"op":"mcm","clk":"11801244454","pt":1723065184624,"mc":[{"id":"1.231540820","rc":[{"batb":[[0,1.97,10],[1,1.96,46.26],[2,1.32,3.28]],"ltp":2.0,"tv":88.69,"id":2219}]}]}
{"op":"mcm","clk":"11801244648","pt":1723065188196,"mc":[{"id":"1.231540820","rc":[{"batb":[[0,1.96,46.26],[1,1.32,3.28],[2,1.3,2.93]],"ltp":2.0,"tv":88.69,"id":2219}]}]}
{"op":"mcm","clk":"11801244807","pt":1723065190716,"mc":[{"id":"1.231540820","rc":[{"batb":[[0,1.97,10],[1,1.96,46.26],[2,1.32,3.28]],"ltp":2.0,"tv":88.69,"id":2219}]}]}
{"op":"mcm","clk":"11801245011","pt":1723065194109,"mc":[{"id":"1.231540820","rc":[{"batb":[[0,1.96,46.26],[1,1.32,3.28],[2,1.3,2.93]],"ltp":2.0,"tv":88.69,"id":2219}]}]}
{"op":"mcm","clk":"11801245123","pt":1723065196317,"mc":[{"id":"1.231540820","rc":[{"batb":[[0,1.97,10],[1,1.96,46.26],[2,1.32,3.28]],"ltp":2.0,"tv":88.69,"id":2219}]}]}
{"op":"mcm","clk":"11801245327","pt":1723065199907,"mc":[{"id":"1.231540820","rc":[{"batb":[[0,1.96,46.26],[1,1.32,3.28],[2,1.3,2.93]],"ltp":2.0,"tv":88.69,"id":2219}]}]}
{"op":"mcm","clk":"11801245603","pt":1723065204537,"mc":[{"id":"1.231540820","rc":[{"batb":[[0,1.97,10],[1,1.96,46.26],[2,1.32,3.28]],"ltp":2.0,"tv":88.69,"id":2219}]}]}
{"op":"mcm","clk":"11801245873","pt":1723065208923,"mc":[{"id":"1.231540820","rc":[{"batb":[[0,1.96,46.26],[1,1.32,3.28],[2,1.3,2.93]],"ltp":2.0,"tv":88.69,"id":2219}]}]}
{"op":"mcm","clk":"11801246044","pt":1723065212048,"mc":[{"id":"1.231540820","rc":[{"batb":[[0,1.97,10],[1,1.96,46.26],[2,1.32,3.28]],"ltp":2.0,"tv":88.69,"id":2219}]}]}
{"op":"mcm","clk":"11801246228","pt":1723065215423,"mc":[{"id":"1.231540820","rc":[{"batb":[[0,1.96,46.26],[1,1.32,3.28],[2,1.3,2.93]],"ltp":2.0,"tv":88.69,"id":2219}]}]}
{"op":"mcm","clk":"11801246356","pt":1723065217729,"mc":[{"id":"1.231540820","rc":[{"batb":[[0,1.97,10],[1,1.96,46.26],[2,1.32,3.28]],"ltp":2.0,"tv":88.69,"id":2219}]}]}
{"op":"mcm","clk":"11801246565","pt":1723065221318,"mc":[{"id":"1.231540820","rc":[{"batb":[[0,1.96,46.26],[1,1.32,3.28],[2,1.3,2.93]],"ltp":2.0,"tv":88.69,"id":2219}]}]}
{"op":"mcm","clk":"11801246814","pt":1723065225531,"mc":[{"id":"1.231540820","rc":[{"batb":[[0,1.97,10],[1,1.96,46.26],[2,1.32,3.28]],"ltp":2.0,"tv":88.69,"id":2219}]}]}
{"op":"mcm","clk":"11801246968","pt":1723065228864,"mc":[{"id":"1.231540820","rc":[{"batb":[[0,1.96,46.26],[1,1.32,3.28],[2,1.3,2.93]],"ltp":2.0,"tv":88.69,"id":2219}]}]}
{"op":"mcm","clk":"11801247137","pt":1723065232152,"mc":[{"id":"1.231540820","rc":[{"batb":[[0,1.97,10],[1,1.96,46.26],[2,1.32,3.28]],"ltp":2.0,"tv":88.69,"id":2219}]}]}
{"op":"mcm","clk":"11801247325","pt":1723065235844,"mc":[{"id":"1.231540820","rc":[{"batb":[[0,1.96,46.26],[1,1.32,3.28],[2,1.3,2.93]],"ltp":2.0,"tv":88.69,"id":2219}]}]}
{"op":"mcm","clk":"11801247445","pt":1723065238358,"mc":[{"id":"1.231540820","rc":[{"batb":[[0,1.97,10],[1,1.96,46.26],[2,1.32,3.28]],"ltp":2.0,"tv":88.69,"id":2219}]}]}
{"op":"mcm","clk":"11801247591","pt":1723065241839,"mc":[{"id":"1.231540820","rc":[{"batb":[[0,1.96,46.26],[1,1.32,3.28],[2,1.3,2.93]],"ltp":2.0,"tv":88.69,"id":2219}]}]}
{"op":"mcm","clk":"11801247714","pt":1723065244352,"mc":[{"id":"1.231540820","rc":[{"batb":[[0,1.97,10],[1,1.96,46.26],[2,1.32,3.28]],"ltp":2.0,"tv":88.69,"id":2219}]}]}
{"op":"mcm","clk":"11801247882","pt":1723065247888,"mc":[{"id":"1.231540820","rc":[{"batb":[[0,1.96,46.26],[1,1.32,3.28],[2,1.3,2.93]],"ltp":2.0,"tv":88.69,"id":2219}]}]}
{"op":"mcm","clk":"11801248052","pt":1723065250959,"mc":[{"id":"1.231540820","rc":[{"batb":[[0,1.97,10],[1,1.96,46.26],[2,1.32,3.28]],"ltp":2.0,"tv":88.69,"id":2219}]}]}
{"op":"mcm","clk":"11801248211","pt":1723065254392,"mc":[{"id":"1.231540820","rc":[{"batb":[[0,1.96,46.26],[1,1.32,3.28],[2,1.3,2.93]],"ltp":2.0,"tv":88.69,"id":2219}]}]}
{"op":"mcm","clk":"11801248362","pt":1723065257978,"mc":[{"id":"1.231540820","rc":[{"batb":[[0,1.97,10],[1,1.96,46.26],[2,1.32,3.28]],"ltp":2.0,"tv":88.69,"id":2219}]}]}
{"op":"mcm","clk":"11801248527","pt":1723065261365,"mc":[{"id":"1.231540820","rc":[{"batb":[[0,1.96,46.26],[1,1.32,3.28],[2,1.3,2.93]],"ltp":2.0,"tv":88.69,"id":2219}]}]}
{"op":"mcm","clk":"11801248628","pt":1723065263676,"mc":[{"id":"1.231540820","rc":[{"batb":[[0,1.97,10],[1,1.96,46.26],[2,1.32,3.28]],"ltp":2.0,"tv":88.69,"id":2219}]}]}
{"op":"mcm","clk":"11801248794","pt":1723065267315,"mc":[{"id":"1.231540820","rc":[{"batb":[[0,1.96,46.26],[1,1.32,3.28],[2,1.3,2.93]],"ltp":2.0,"tv":88.69,"id":2219}]}]}
{"op":"mcm","clk":"11801248901","pt":1723065269518,"mc":[{"id":"1.231540820","rc":[{"batb":[[0,1.97,10],[1,1.96,46.26],[2,1.32,3.28]],"ltp":2.0,"tv":88.69,"id":2219}]}]}
{"op":"mcm","clk":"11801249078","pt":1723065272902,"mc":[{"id":"1.231540820","rc":[{"batb":[[0,1.96,46.26],[1,1.32,3.28],[2,1.3,2.93]],"ltp":2.0,"tv":88.69,"id":2219}]}]}
{"op":"mcm","clk":"11801249228","pt":1723065275920,"mc":[{"id":"1.231540820","rc":[{"batb":[[0,1.97,10],[1,1.96,46.26],[2,1.32,3.28]],"ltp":2.0,"tv":88.69,"id":2219}]}]}
{"op":"mcm","clk":"11801249376","pt":1723065279306,"mc":[{"id":"1.231540820","rc":[{"batb":[[0,1.96,46.26],[1,1.32,3.28],[2,1.3,2.93]],"ltp":2.0,"tv":88.69,"id":2219}]}]}
{"op":"mcm","clk":"11801249567","pt":1723065283714,"mc":[{"id":"1.231540820","rc":[{"batb":[[0,1.97,10],[1,1.96,46.26],[2,1.32,3.28]],"ltp":2.0,"tv":88.69,"id":2219}]}]}
{"op":"mcm","clk":"11801249715","pt":1723065287247,"mc":[{"id":"1.231540820","rc":[{"batb":[[0,1.96,46.26],[1,1.32,3.28],[2,1.3,2.93]],"ltp":2.0,"tv":88.69,"id":2219}]}]}
{"op":"mcm","clk":"11801249866","pt":1723065290633,"mc":[{"id":"1.231540820","rc":[{"batb":[[0,1.97,10],[1,1.96,46.26],[2,1.32,3.28]],"ltp":2.0,"tv":88.69,"id":2219}]}]}
{"op":"mcm","clk":"11801250046","pt":1723065294221,"mc":[{"id":"1.231540820","rc":[{"batb":[[0,1.96,46.26],[1,1.32,3.28],[2,1.3,2.93]],"ltp":2.0,"tv":88.69,"id":2219}]}]}
{"op":"mcm","clk":"11801250138","pt":1723065296531,"mc":[{"id":"1.231540820","rc":[{"batb":[[0,1.97,10],[1,1.96,46.26],[2,1.32,3.28]],"ltp":2.0,"tv":88.69,"id":2219}]}]}
{"op":"mcm","clk":"11801250268","pt":1723065299967,"mc":[{"id":"1.231540820","rc":[{"batb":[[0,1.96,46.26],[1,1.32,3.28],[2,1.3,2.93]],"ltp":2.0,"tv":88.69,"id":2219}]}]}
{"op":"mcm","clk":"11801250395","pt":1723065302346,"mc":[{"id":"1.231540820","rc":[{"batb":[[0,1.97,10],[1,1.96,46.26],[2,1.32,3.28]],"ltp":2.0,"tv":88.69,"id":2219}]}]}
{"op":"mcm","clk":"11801250544","pt":1723065305941,"mc":[{"id":"1.231540820","rc":[{"batb":[[0,1.96,46.26],[1,1.32,3.28],[2,1.3,2.93]],"ltp":2.0,"tv":88.69,"id":2219}]}]}
{"op":"mcm","clk":"11801250627","pt":1723065308250,"mc":[{"id":"1.231540820","rc":[{"batb":[[0,1.97,10],[1,1.96,46.26],[2,1.32,3.28]],"ltp":2.0,"tv":88.69,"id":2219}]}]}
{"op":"mcm","clk":"11801250766","pt":1723065311641,"mc":[{"id":"1.231540820","rc":[{"batb":[[0,1.96,46.26],[1,1.32,3.28],[2,1.3,2.93]],"ltp":2.0,"tv":88.69,"id":2219}]}]}
{"op":"mcm","clk":"11801250851","pt":1723065313952,"mc":[{"id":"1.231540820","rc":[{"batb":[[0,1.97,10],[1,1.96,46.26],[2,1.32,3.28]],"ltp":2.0,"tv":88.69,"id":2219}]}]}
{"op":"mcm","clk":"11801250984","pt":1723065317445,"mc":[{"id":"1.231540820","rc":[{"batb":[[0,1.96,46.26],[1,1.32,3.28],[2,1.3,2.93]],"ltp":2.0,"tv":88.69,"id":2219}]}]}
{"op":"mcm","clk":"11801251135","pt":1723065320780,"mc":[{"id":"1.231540820","rc":[{"batb":[[0,1.97,10],[1,1.96,46.26],[2,1.32,3.28]],"ltp":2.0,"tv":88.69,"id":2219}]}]}
{"op":"mcm","clk":"11801251301","pt":1723065324176,"mc":[{"id":"1.231540820","rc":[{"batb":[[0,1.96,46.26],[1,1.32,3.28],[2,1.3,2.93]],"ltp":2.0,"tv":88.69,"id":2219}]}]}
{"op":"mcm","clk":"11801251430","pt":1723065326898,"mc":[{"id":"1.231540820","rc":[{"batb":[[0,1.97,10],[1,1.96,46.26],[2,1.32,3.28]],"ltp":2.0,"tv":88.69,"id":2219}]}]}
{"op":"mcm","clk":"11801251589","pt":1723065330403,"mc":[{"id":"1.231540820","rc":[{"batb":[[0,1.96,46.26],[1,1.32,3.28],[2,1.3,2.93]],"ltp":2.0,"tv":88.69,"id":2219}]}]}
{"op":"mcm","clk":"11801251677","pt":1723065333022,"mc":[{"id":"1.231540820","rc":[{"batb":[[0,1.97,10],[1,1.96,46.26],[2,1.32,3.28]],"ltp":2.0,"tv":88.69,"id":2219}]}]}
{"op":"mcm","clk":"11801251844","pt":1723065336416,"mc":[{"id":"1.231540820","rc":[{"batb":[[0,1.96,46.26],[1,1.32,3.28],[2,1.3,2.93]],"ltp":2.0,"tv":88.69,"id":2219}]}]}
{"op":"mcm","clk":"11801251994","pt":1723065339707,"mc":[{"id":"1.231540820","rc":[{"batb":[[0,1.97,10],[1,1.96,46.26],[2,1.32,3.28]],"ltp":2.0,"tv":88.69,"id":2219}]}]}
{"op":"mcm","clk":"11801252119","pt":1723065342999,"mc":[{"id":"1.231540820","rc":[{"batb":[[0,1.96,46.26],[1,1.32,3.28],[2,1.3,2.93]],"ltp":2.0,"tv":88.69,"id":2219}]}]}
{"op":"mcm","clk":"11801252344","pt":1723065347819,"mc":[{"id":"1.231540820","rc":[{"batb":[[0,1.97,10],[1,1.96,46.26],[2,1.32,3.28]],"ltp":2.0,"tv":88.69,"id":2219}]}]}
{"op":"mcm","clk":"11801252488","pt":1723065351212,"mc":[{"id":"1.231540820","rc":[{"batb":[[0,1.96,46.26],[1,1.32,3.28],[2,1.3,2.93]],"ltp":2.0,"tv":88.69,"id":2219}]}]}
{"op":"mcm","clk":"11801252588","pt":1723065353932,"mc":[{"id":"1.231540820","rc":[{"batb":[[0,1.97,10],[1,1.96,46.26],[2,1.32,3.28]],"ltp":2.0,"tv":88.69,"id":2219}]}]}
{"op":"mcm","clk":"11801252720","pt":1723065357534,"mc":[{"id":"1.231540820","rc":[{"batb":[[0,1.96,46.26],[1,1.32,3.28],[2,1.3,2.93]],"ltp":2.0,"tv":88.69,"id":2219}]}]}
{"op":"mcm","clk":"11801252867","pt":1723065360673,"mc":[{"id":"1.231540820","rc":[{"batb":[[0,1.97,10],[1,1.96,46.26],[2,1.32,3.28]],"ltp":2.0,"tv":88.69,"id":2219}]}]}
{"op":"mcm","clk":"11801253009","pt":1723065364069,"mc":[{"id":"1.231540820","rc":[{"batb":[[0,1.96,46.26],[1,1.32,3.28],[2,1.3,2.93]],"ltp":2.0,"tv":88.69,"id":2219}]}]}
{"op":"mcm","clk":"11801253123","pt":1723065366644,"mc":[{"id":"1.231540820","rc":[{"batb":[[0,1.97,10],[1,1.96,46.26],[2,1.32,3.28]],"ltp":2.0,"tv":88.69,"id":2219}]}]}
{"op":"mcm","clk":"11801253269","pt":1723065369977,"mc":[{"id":"1.231540820","rc":[{"batb":[[0,1.96,46.26],[1,1.32,3.28],[2,1.3,2.93]],"ltp":2.0,"tv":88.69,"id":2219}]}]}
{"op":"mcm","clk":"11801253365","pt":1723065372546,"mc":[{"id":"1.231540820","rc":[{"batb":[[0,1.97,10],[1,1.96,46.26],[2,1.32,3.28]],"ltp":2.0,"tv":88.69,"id":2219}]}]}
{"op":"mcm","clk":"11801253511","pt":1723065376086,"mc":[{"id":"1.231540820","rc":[{"batb":[[0,1.96,46.26],[1,1.32,3.28],[2,1.3,2.93]],"ltp":2.0,"tv":88.69,"id":2219}]}]}
{"op":"mcm","clk":"11801253609","pt":1723065378549,"mc":[{"id":"1.231540820","rc":[{"batb":[[0,1.97,10],[1,1.96,46.26],[2,1.32,3.28]],"ltp":2.0,"tv":88.69,"id":2219}]}]}
{"op":"mcm","clk":"11801253736","pt":1723065381879,"mc":[{"id":"1.231540820","rc":[{"batb":[[0,1.96,46.26],[1,1.32,3.28],[2,1.3,2.93]],"ltp":2.0,"tv":88.69,"id":2219}]}]}
{"op":"mcm","clk":"11801253833","pt":1723065384594,"mc":[{"id":"1.231540820","rc":[{"batb":[[0,1.97,10],[1,1.96,46.26],[2,1.32,3.28]],"ltp":2.0,"tv":88.69,"id":2219}]}]}
{"op":"mcm","clk":"11801253961","pt":1723065387978,"mc":[{"id":"1.231540820","rc":[{"batb":[[0,1.96,46.26],[1,1.32,3.28],[2,1.3,2.93]],"ltp":2.0,"tv":88.69,"id":2219}]}]}
{"op":"mcm","clk":"11801254049","pt":1723065390301,"mc":[{"id":"1.231540820","rc":[{"batb":[[0,1.97,10],[1,1.96,46.26],[2,1.32,3.28]],"ltp":2.0,"tv":88.69,"id":2219}]}]}
{"op":"mcm","clk":"11801254181","pt":1723065393994,"mc":[{"id":"1.231540820","rc":[{"batb":[[0,1.96,46.26],[1,1.32,3.28],[2,1.3,2.93]],"ltp":2.0,"tv":88.69,"id":2219}]}]}
{"op":"mcm","clk":"11801254272","pt":1723065396509,"mc":[{"id":"1.231540820","rc":[{"batb":[[0,1.97,10],[1,1.96,46.26],[2,1.32,3.28]],"ltp":2.0,"tv":88.69,"id":2219}]}]}
{"op":"mcm","clk":"11801254403","pt":1723065399893,"mc":[{"id":"1.231540820","rc":[{"batb":[[0,1.96,46.26],[1,1.32,3.28],[2,1.3,2.93]],"ltp":2.0,"tv":88.69,"id":2219}]}]}
{"op":"mcm","clk":"11801254497","pt":1723065402098,"mc":[{"id":"1.231540820","rc":[{"batb":[[0,1.97,10],[1,1.96,46.26],[2,1.32,3.28]],"ltp":2.0,"tv":88.69,"id":2219}]}]}
{"op":"mcm","clk":"11801254653","pt":1723065405491,"mc":[{"id":"1.231540820","rc":[{"batb":[[0,1.96,46.26],[1,1.32,3.28],[2,1.3,2.93]],"ltp":2.0,"tv":88.69,"id":2219}]}]}
{"op":"mcm","clk":"11801254784","pt":1723065408721,"mc":[{"id":"1.231540820","rc":[{"batb":[[0,1.97,10],[1,1.96,46.26],[2,1.32,3.28]],"ltp":2.0,"tv":88.69,"id":2219}]}]}
{"op":"mcm","clk":"11801254891","pt":1723065412120,"mc":[{"id":"1.231540820","rc":[{"batb":[[0,1.96,46.26],[1,1.32,3.28],[2,1.3,2.93]],"ltp":2.0,"tv":88.69,"id":2219}]}]}
{"op":"mcm","clk":"11801254993","pt":1723065414637,"mc":[{"id":"1.231540820","rc":[{"batb":[[0,1.97,10],[1,1.96,46.26],[2,1.32,3.28]],"ltp":2.0,"tv":88.69,"id":2219}]}]}
{"op":"mcm","clk":"11801255145","pt":1723065418233,"mc":[{"id":"1.231540820","rc":[{"batb":[[0,1.96,46.26],[1,1.32,3.28],[2,1.3,2.93]],"ltp":2.0,"tv":88.69,"id":2219}]}]}
{"op":"mcm","clk":"11801255398","pt":1723065424133,"mc":[{"id":"1.231540820","rc":[{"batb":[[0,1.97,10],[1,1.96,46.26],[2,1.32,3.28]],"ltp":2.0,"tv":88.69,"id":2219}]}]}
{"op":"mcm","clk":"11801255555","pt":1723065427419,"mc":[{"id":"1.231540820","rc":[{"batb":[[0,1.96,46.26],[1,1.32,3.28],[2,1.3,2.93]],"ltp":2.0,"tv":88.69,"id":2219}]}]}
{"op":"mcm","clk":"11801255757","pt":1723065432343,"mc":[{"id":"1.231540820","rc":[{"batb":[[0,1.97,10],[1,1.96,46.26],[2,1.32,3.28]],"ltp":2.0,"tv":88.69,"id":2219}]}]}
{"op":"mcm","clk":"11801255915","pt":1723065435727,"mc":[{"id":"1.231540820","rc":[{"batb":[[0,1.96,46.26],[1,1.32,3.28],[2,1.3,2.93]],"ltp":2.0,"tv":88.69,"id":2219}]}]}
{"op":"mcm","clk":"11801256044","pt":1723065438444,"mc":[{"id":"1.231540820","rc":[{"batb":[[0,1.97,10],[1,1.96,46.26],[2,1.32,3.28]],"ltp":2.0,"tv":88.69,"id":2219}]}]}
{"op":"mcm","clk":"11801256227","pt":1723065441878,"mc":[{"id":"1.231540820","rc":[{"batb":[[0,1.96,46.26],[1,1.32,3.28],[2,1.3,2.93]],"ltp":2.0,"tv":88.69,"id":2219}]}]}
{"op":"mcm","clk":"11801256329","pt":1723065444185,"mc":[{"id":"1.231540820","rc":[{"batb":[[0,1.97,10],[1,1.96,46.26],[2,1.32,3.28]],"ltp":2.0,"tv":88.69,"id":2219}]}]}
{"op":"mcm","clk":"11801256531","pt":1723065447891,"mc":[{"id":"1.231540820","rc":[{"batb":[[0,1.96,46.26],[1,1.32,3.28],[2,1.3,2.93]],"ltp":2.0,"tv":88.69,"id":2219}]}]}
{"op":"mcm","clk":"11801256652","pt":1723065450154,"mc":[{"id":"1.231540820","rc":[{"batb":[[0,1.97,10],[1,1.96,46.26],[2,1.32,3.28]],"ltp":2.0,"tv":88.69,"id":2219}]}]}
{"op":"mcm","clk":"11801256858","pt":1723065453592,"mc":[{"id":"1.231540820","rc":[{"batb":[[0,1.96,46.26],[1,1.32,3.28],[2,1.3,2.93]],"ltp":2.0,"tv":88.69,"id":2219}]}]}
{"op":"mcm","clk":"11801257012","pt":1723065456472,"mc":[{"id":"1.231540820","rc":[{"batb":[[0,1.97,10],[1,1.96,46.26],[2,1.32,3.28]],"ltp":2.0,"tv":88.69,"id":2219}]}]}
{"op":"mcm","clk":"11801257209","pt":1723065459968,"mc":[{"id":"1.231540820","rc":[{"batb":[[0,1.96,46.26],[1,1.32,3.28],[2,1.3,2.93]],"ltp":2.0,"tv":88.69,"id":2219}]}]}
{"op":"mcm","clk":"11801257345","pt":1723065462381,"mc":[{"id":"1.231540820","rc":[{"batb":[[0,1.97,10],[1,1.96,46.26],[2,1.32,3.28]],"ltp":2.0,"tv":88.69,"id":2219}]}]}
{"op":"mcm","clk":"11801257528","pt":1723065465772,"mc":[{"id":"1.231540820","rc":[{"batb":[[0,1.96,46.26],[1,1.32,3.28],[2,1.3,2.93]],"ltp":2.0,"tv":88.69,"id":2219}]}]}
{"op":"mcm","clk":"11801257670","pt":1723065468288,"mc":[{"id":"1.231540820","rc":[{"batb":[[0,1.97,10],[1,1.96,46.26],[2,1.32,3.28]],"ltp":2.0,"tv":88.69,"id":2219}]}]}
{"op":"mcm","clk":"11801257826","pt":1723065471881,"mc":[{"id":"1.231540820","rc":[{"batb":[[0,1.96,46.26],[1,1.32,3.28],[2,1.3,2.93]],"ltp":2.0,"tv":88.69,"id":2219}]}]}
{"op":"mcm","clk":"11801257938","pt":1723065474403,"mc":[{"id":"1.231540820","rc":[{"batb":[[0,1.97,10],[1,1.96,46.26],[2,1.32,3.28]],"ltp":2.0,"tv":88.69,"id":2219}]}]}
{"op":"mcm","clk":"11801258108","pt":1723065477685,"mc":[{"id":"1.231540820","rc":[{"batb":[[0,1.96,46.26],[1,1.32,3.28],[2,1.3,2.93]],"ltp":2.0,"tv":88.69,"id":2219}]}]}
{"op":"mcm","clk":"11801258259","pt":1723065480206,"mc":[{"id":"1.231540820","rc":[{"batb":[[0,1.97,10],[1,1.96,46.26],[2,1.32,3.28]],"ltp":2.0,"tv":88.69,"id":2219}]}]}
{"op":"mcm","clk":"11801258460","pt":1723065483497,"mc":[{"id":"1.231540820","rc":[{"batb":[[0,1.96,46.26],[1,1.32,3.28],[2,1.3,2.93]],"ltp":2.0,"tv":88.69,"id":2219}]}]}
{"op":"mcm","clk":"11801258588","pt":1723065486425,"mc":[{"id":"1.231540820","rc":[{"batb":[[0,1.97,10],[1,1.96,46.26],[2,1.32,3.28]],"ltp":2.0,"tv":88.69,"id":2219}]}]}
{"op":"mcm","clk":"11801258770","pt":1723065489744,"mc":[{"id":"1.231540820","rc":[{"batb":[[0,1.96,46.26],[1,1.32,3.28],[2,1.3,2.93]],"ltp":2.0,"tv":88.69,"id":2219}]}]}
{"op":"mcm","clk":"11801259041","pt":1723065494723,"mc":[{"id":"1.231540820","rc":[{"batb":[[0,1.97,10],[1,1.96,46.26],[2,1.32,3.28]],"ltp":2.0,"tv":88.69,"id":2219}]}]}
{"op":"mcm","clk":"11801259215","pt":1723065498012,"mc":[{"id":"1.231540820","rc":[{"batb":[[0,1.96,46.26],[1,1.32,3.28],[2,1.3,2.93]],"ltp":2.0,"tv":88.69,"id":2219}]}]}
{"op":"mcm","clk":"11801259330","pt":1723065500421,"mc":[{"id":"1.231540820","rc":[{"batb":[[0,1.97,10],[1,1.96,46.26],[2,1.32,3.28]],"ltp":2.0,"tv":88.69,"id":2219}]}]}
{"op":"mcm","clk":"11801259501","pt":1723065503959,"mc":[{"id":"1.231540820","rc":[{"batb":[[0,1.96,46.26],[1,1.32,3.28],[2,1.3,2.93]],"ltp":2.0,"tv":88.69,"id":2219}]}]}
{"op":"mcm","clk":"11801259719","pt":1723065508069,"mc":[{"id":"1.231540820","rc":[{"batb":[[0,1.97,10],[1,1.96,46.26],[2,1.32,3.28]],"ltp":2.0,"tv":88.69,"id":2219}]}]}
{"op":"mcm","clk":"11801259879","pt":1723065511361,"mc":[{"id":"1.231540820","rc":[{"batb":[[0,1.96,46.26],[1,1.32,3.28],[2,1.3,2.93]],"ltp":2.0,"tv":88.69,"id":2219}]}]}
{"op":"mcm","clk":"11801259995","pt":1723065513567,"mc":[{"id":"1.231540820","rc":[{"batb":[[0,1.97,10],[1,1.96,46.26],[2,1.32,3.28]],"ltp":2.0,"tv":88.69,"id":2219}]}]}
{"op":"mcm","clk":"11801260179","pt":1723065516748,"mc":[{"id":"1.231540820","rc":[{"batb":[[0,1.96,46.26],[1,1.32,3.28],[2,1.3,2.93]],"ltp":2.0,"tv":88.69,"id":2219}]}]}
{"op":"mcm","clk":"11801260283","pt":1723065519470,"mc":[{"id":"1.231540820","rc":[{"batb":[[0,1.97,10],[1,1.96,46.26],[2,1.32,3.28]],"ltp":2.0,"tv":88.69,"id":2219}]}]}
{"op":"mcm","clk":"11801260422","pt":1723065523056,"mc":[{"id":"1.231540820","rc":[{"batb":[[0,1.96,46.26],[1,1.32,3.28],[2,1.3,2.93]],"ltp":2.0,"tv":88.69,"id":2219}]}]}
{"op":"mcm","clk":"11801260517","pt":1723065525362,"mc":[{"id":"1.231540820","rc":[{"batb":[[0,1.97,10],[1,1.96,46.26],[2,1.32,3.28]],"ltp":2.0,"tv":88.69,"id":2219}]}]}
{"op":"mcm","clk":"11801260750","pt":1723065529097,"mc":[{"id":"1.231540820","rc":[{"batb":[[0,1.96,46.26],[1,1.32,3.28],[2,1.3,2.93]],"ltp":2.0,"tv":88.69,"id":2219}]}]}
{"op":"mcm","clk":"11801260924","pt":1723065531663,"mc":[{"id":"1.231540820","rc":[{"batb":[[0,1.97,10],[1,1.96,46.26],[2,1.32,3.28]],"ltp":2.0,"tv":88.69,"id":2219}]}]}
{"op":"mcm","clk":"11801261091","pt":1723065535096,"mc":[{"id":"1.231540820","rc":[{"batb":[[0,1.96,46.26],[1,1.32,3.28],[2,1.3,2.93]],"ltp":2.0,"tv":88.69,"id":2219}]}]}
{"op":"mcm","clk":"11801261174","pt":1723065537399,"mc":[{"id":"1.231540820","rc":[{"batb":[[0,1.97,10],[1,1.96,46.26],[2,1.32,3.28]],"ltp":2.0,"tv":88.69,"id":2219}]}]}
{"op":"mcm","clk":"11801261311","pt":1723065540786,"mc":[{"id":"1.231540820","rc":[{"batb":[[0,1.96,46.26],[1,1.32,3.28],[2,1.3,2.93]],"ltp":2.0,"tv":88.69,"id":2219}]}]}
{"op":"mcm","clk":"11801261434","pt":1723065543711,"mc":[{"id":"1.231540820","rc":[{"batb":[[0,1.97,10],[1,1.96,46.26],[2,1.32,3.28]],"ltp":2.0,"tv":88.69,"id":2219}]}]}
{"op":"mcm","clk":"11801261586","pt":1723065547205,"mc":[{"id":"1.231540820","rc":[{"batb":[[0,1.96,46.26],[1,1.32,3.28],[2,1.3,2.93]],"ltp":2.0,"tv":88.69,"id":2219}]}]}
{"op":"mcm","clk":"11801261710","pt":1723065549508,"mc":[{"id":"1.231540820","rc":[{"batb":[[0,1.97,10],[1,1.96,46.26],[2,1.32,3.28]],"ltp":2.0,"tv":88.69,"id":2219}]}]}
{"op":"mcm","clk":"11801261918","pt":1723065553197,"mc":[{"id":"1.231540820","rc":[{"batb":[[0,1.96,46.26],[1,1.32,3.28],[2,1.3,2.93]],"ltp":2.0,"tv":88.69,"id":2219}]}]}
{"op":"mcm","clk":"11801262161","pt":1723065557399,"mc":[{"id":"1.231540820","rc":[{"batb":[[0,1.97,10],[1,1.96,46.26],[2,1.32,3.28]],"ltp":2.0,"tv":88.69,"id":2219}]}]}
{"op":"mcm","clk":"11801262340","pt":1723065560933,"mc":[{"id":"1.231540820","rc":[{"batb":[[0,1.96,46.26],[1,1.32,3.28],[2,1.3,2.93]],"ltp":2.0,"tv":88.69,"id":2219}]}]}
{"op":"mcm","clk":"11801262479","pt":1723065563440,"mc":[{"id":"1.231540820","rc":[{"batb":[[0,1.97,10],[1,1.96,46.26],[2,1.32,3.28]],"ltp":2.0,"tv":88.69,"id":2219}]}]}
{"op":"mcm","clk":"11801262625","pt":1723065566622,"mc":[{"id":"1.231540820","rc":[{"batb":[[0,1.96,46.26],[1,1.32,3.28],[2,1.3,2.93]],"ltp":2.0,"tv":88.69,"id":2219}]}]}
{"op":"mcm","clk":"11801262955","pt":1723065573442,"mc":[{"id":"1.231540820","rc":[{"batb":[[0,1.97,10],[1,1.96,46.26],[2,1.32,3.28]],"ltp":2.0,"tv":88.69,"id":2219}]}]}
{"op":"mcm","clk":"11801263095","pt":1723065576725,"mc":[{"id":"1.231540820","rc":[{"batb":[[0,1.96,46.26],[1,1.32,3.28],[2,1.3,2.93]],"ltp":2.0,"tv":88.69,"id":2219}]}]}
{"op":"mcm","clk":"11801263207","pt":1723065579238,"mc":[{"id":"1.231540820","rc":[{"batb":[[0,1.97,10],[1,1.96,46.26],[2,1.32,3.28]],"ltp":2.0,"tv":88.69,"id":2219}]}]}
{"op":"mcm","clk":"11801263346","pt":1723065582673,"mc":[{"id":"1.231540820","rc":[{"batb":[[0,1.96,46.26],[1,1.32,3.28],[2,1.3,2.93]],"ltp":2.0,"tv":88.69,"id":2219}]}]}
{"op":"mcm","clk":"11801263462","pt":1723065585137,"mc":[{"id":"1.231540820","rc":[{"batb":[[0,1.97,10],[1,1.96,46.26],[2,1.32,3.28]],"ltp":2.0,"tv":88.69,"id":2219}]}]}
{"op":"mcm","clk":"11801263652","pt":1723065589238,"mc":[{"id":"1.231540820","rc":[{"batb":[[0,1.96,46.26],[1,1.32,3.28],[2,1.3,2.93]],"ltp":2.0,"tv":88.69,"id":2219}]}]}
{"op":"mcm","clk":"11801263796","pt":1723065592670,"mc":[{"id":"1.231540820","rc":[{"batb":[[0,1.97,10],[1,1.96,46.26],[2,1.32,3.28]],"ltp":2.0,"tv":88.69,"id":2219}]}]}
{"op":"mcm","clk":"11801263937","pt":1723065596058,"mc":[{"id":"1.231540820","rc":[{"batb":[[0,1.96,46.26],[1,1.32,3.28],[2,1.3,2.93]],"ltp":2.0,"tv":88.69,"id":2219}]}]}
{"op":"mcm","clk":"11801264046","pt":1723065598881,"mc":[{"id":"1.231540820","rc":[{"batb":[[0,1.97,10],[1,1.96,46.26],[2,1.32,3.28]],"ltp":2.0,"tv":88.69,"id":2219}]}]}
{"op":"mcm","clk":"11801264210","pt":1723065602370,"mc":[{"id":"1.231540820","rc":[{"batb":[[0,1.96,46.26],[1,1.32,3.28],[2,1.3,2.93]],"ltp":2.0,"tv":88.69,"id":2219}]}]}
{"op":"mcm","clk":"11801264374","pt":1723065605555,"mc":[{"id":"1.231540820","rc":[{"batb":[[0,1.97,10],[1,1.96,46.26],[2,1.32,3.28]],"ltp":2.0,"tv":88.69,"id":2219}]}]}
{"op":"mcm","clk":"11801264541","pt":1723065609208,"mc":[{"id":"1.231540820","rc":[{"batb":[[0,1.96,46.26],[1,1.32,3.28],[2,1.3,2.93]],"ltp":2.0,"tv":88.69,"id":2219}]}]}
{"op":"mcm","clk":"11801264818","pt":1723065615380,"mc":[{"id":"1.231540820","rc":[{"batb":[[0,1.97,10],[1,1.96,46.26],[2,1.32,3.28]],"ltp":2.0,"tv":88.69,"id":2219}]}]}
{"op":"mcm","clk":"11801264996","pt":1723065619022,"mc":[{"id":"1.231540820","rc":[{"batb":[[0,1.96,46.26],[1,1.32,3.28],[2,1.3,2.93]],"ltp":2.0,"tv":88.69,"id":2219}]}]}
{"op":"mcm","clk":"11801265110","pt":1723065621484,"mc":[{"id":"1.231540820","rc":[{"batb":[[0,1.97,10],[1,1.96,46.26],[2,1.32,3.28]],"ltp":2.0,"tv":88.69,"id":2219}]}]}
{"op":"mcm","clk":"11801265252","pt":1723065624917,"mc":[{"id":"1.231540820","rc":[{"batb":[[0,1.96,46.26],[1,1.32,3.28],[2,1.3,2.93]],"ltp":2.0,"tv":88.69,"id":2219}]}]}
{"op":"mcm","clk":"11801265440","pt":1723065629737,"mc":[{"id":"1.231540820","rc":[{"batb":[[0,1.97,10],[1,1.96,46.26],[2,1.32,3.28]],"ltp":2.0,"tv":88.69,"id":2219}]}]}
{"op":"mcm","clk":"11801265590","pt":1723065633041,"mc":[{"id":"1.231540820","rc":[{"batb":[[0,1.96,46.26],[1,1.32,3.28],[2,1.3,2.93]],"ltp":2.0,"tv":88.69,"id":2219}]}]}
{"op":"mcm","clk":"11801265856","pt":1723065638732,"mc":[{"id":"1.231540820","rc":[{"batb":[[0,1.97,10],[1,1.96,46.26],[2,1.32,3.28]],"ltp":2.0,"tv":88.69,"id":2219}]}]}
{"op":"mcm","clk":"11801266030","pt":1723065642120,"mc":[{"id":"1.231540820","rc":[{"batb":[[0,1.96,46.26],[1,1.32,3.28],[2,1.3,2.93]],"ltp":2.0,"tv":88.69,"id":2219}]}]}
{"op":"mcm","clk":"11801266185","pt":1723065644839,"mc":[{"id":"1.231540820","rc":[{"batb":[[0,1.97,10],[1,1.96,46.26],[2,1.32,3.28]],"ltp":2.0,"tv":88.69,"id":2219}]}]}
{"op":"mcm","clk":"11801266345","pt":1723065648432,"mc":[{"id":"1.231540820","rc":[{"batb":[[0,1.96,46.26],[1,1.32,3.28],[2,1.3,2.93]],"ltp":2.0,"tv":88.69,"id":2219}]}]}
{"op":"mcm","clk":"11801266456","pt":1723065651039,"mc":[{"id":"1.231540820","rc":[{"batb":[[0,1.97,10],[1,1.96,46.26],[2,1.32,3.28]],"ltp":2.0,"tv":88.69,"id":2219}]}]}
{"op":"mcm","clk":"11801266578","pt":1723065654574,"mc":[{"id":"1.231540820","rc":[{"batb":[[0,1.96,46.26],[1,1.32,3.28],[2,1.3,2.93]],"ltp":2.0,"tv":88.69,"id":2219}]}]}
{"op":"mcm","clk":"11801266692","pt":1723065657858,"mc":[{"id":"1.231540820","rc":[{"batb":[[0,1.97,10],[1,1.96,46.26],[2,1.32,3.28]],"ltp":2.0,"tv":88.69,"id":2219}]}]}
{"op":"mcm","clk":"11801266826","pt":1723065661346,"mc":[{"id":"1.231540820","rc":[{"batb":[[0,1.96,46.26],[1,1.32,3.28],[2,1.3,2.93]],"ltp":2.0,"tv":88.69,"id":2219}]}]}
{"op":"mcm","clk":"11801266957","pt":1723065664271,"mc":[{"id":"1.231540820","rc":[{"batb":[[0,1.97,10],[1,1.96,46.26],[2,1.32,3.28]],"ltp":2.0,"tv":88.69,"id":2219}]}]}
{"op":"mcm","clk":"11801267094","pt":1723065667651,"mc":[{"id":"1.231540820","rc":[{"batb":[[0,1.96,46.26],[1,1.32,3.28],[2,1.3,2.93]],"ltp":2.0,"tv":88.69,"id":2219}]}]}
{"op":"mcm","clk":"11801267200","pt":1723065670266,"mc":[{"id":"1.231540820","rc":[{"batb":[[0,1.97,10],[1,1.96,46.26],[2,1.32,3.28]],"ltp":2.0,"tv":88.69,"id":2219}]}]}
{"op":"mcm","clk":"11801267325","pt":1723065673652,"mc":[{"id":"1.231540820","rc":[{"batb":[[0,1.96,46.26],[1,1.32,3.28],[2,1.3,2.93]],"ltp":2.0,"tv":88.69,"id":2219}]}]}
{"op":"mcm","clk":"11801267531","pt":1723065677709,"mc":[{"id":"1.231540820","rc":[{"batb":[[0,1.97,10],[1,1.96,46.26],[2,1.32,3.28]],"ltp":2.0,"tv":88.69,"id":2219}]}]}
{"op":"mcm","clk":"11801267676","pt":1723065681198,"mc":[{"id":"1.231540820","rc":[{"batb":[[0,1.96,46.26],[1,1.32,3.28],[2,1.3,2.93]],"ltp":2.0,"tv":88.69,"id":2219}]}]}
{"op":"mcm","clk":"11801267781","pt":1723065683601,"mc":[{"id":"1.231540820","rc":[{"batb":[[0,1.97,10],[1,1.96,46.26],[2,1.32,3.28]],"ltp":2.0,"tv":88.69,"id":2219}]}]}
{"op":"mcm","clk":"11801267962","pt":1723065687197,"mc":[{"id":"1.231540820","rc":[{"batb":[[0,1.96,46.26],[1,1.32,3.28],[2,1.3,2.93]],"ltp":2.0,"tv":88.69,"id":2219}]}]}
{"op":"mcm","clk":"11801268060","pt":1723065689511,"mc":[{"id":"1.231540820","rc":[{"batb":[[0,1.97,10],[1,1.96,46.26],[2,1.32,3.28]],"ltp":2.0,"tv":88.69,"id":2219}]}]}
{"op":"mcm","clk":"11801268209","pt":1723065692993,"mc":[{"id":"1.231540820","rc":[{"batb":[[0,1.96,46.26],[1,1.32,3.28],[2,1.3,2.93]],"ltp":2.0,"tv":88.69,"id":2219}]}]}
{"op":"mcm","clk":"11801268384","pt":1723065696781,"mc":[{"id":"1.231540820","rc":[{"batb":[[0,1.97,10],[1,1.96,46.26],[2,1.32,3.28]],"ltp":2.0,"tv":88.69,"id":2219}]}]}
{"op":"mcm","clk":"11801268505","pt":1723065700210,"mc":[{"id":"1.231540820","rc":[{"batb":[[0,1.96,46.26],[1,1.32,3.28],[2,1.3,2.93]],"ltp":2.0,"tv":88.69,"id":2219}]}]}
{"op":"mcm","clk":"11801268632","pt":1723065703027,"mc":[{"id":"1.231540820","rc":[{"batb":[[0,1.97,10],[1,1.96,46.26],[2,1.32,3.28]],"ltp":2.0,"tv":88.69,"id":2219}]}]}
{"op":"mcm","clk":"11801268778","pt":1723065706510,"mc":[{"id":"1.231540820","rc":[{"batb":[[0,1.96,46.26],[1,1.32,3.28],[2,1.3,2.93]],"ltp":2.0,"tv":88.69,"id":2219}]}]}
{"op":"mcm","clk":"11801268916","pt":1723065709447,"mc":[{"id":"1.231540820","rc":[{"batb":[[0,1.97,10],[1,1.96,46.26],[2,1.32,3.28]],"ltp":2.0,"tv":88.69,"id":2219}]}]}
{"op":"mcm","clk":"11801269080","pt":1723065713019,"mc":[{"id":"1.231540820","rc":[{"batb":[[0,1.96,46.26],[1,1.32,3.28],[2,1.3,2.93]],"ltp":2.0,"tv":88.69,"id":2219}]}]}
{"op":"mcm","clk":"11801269200","pt":1723065715732,"mc":[{"id":"1.231540820","rc":[{"batb":[[0,1.97,10],[1,1.96,46.26],[2,1.32,3.28]],"ltp":2.0,"tv":88.69,"id":2219}]}]}
{"op":"mcm","clk":"11801269354","pt":1723065719119,"mc":[{"id":"1.231540820","rc":[{"batb":[[0,1.96,46.26],[1,1.32,3.28],[2,1.3,2.93]],"ltp":2.0,"tv":88.69,"id":2219}]}]}
{"op":"mcm","clk":"11801269546","pt":1723065723646,"mc":[{"id":"1.231540820","rc":[{"batb":[[0,1.97,10],[1,1.96,46.26],[2,1.32,3.28]],"ltp":2.0,"tv":88.69,"id":2219}]}]}
{"op":"mcm","clk":"11801269698","pt":1723065727245,"mc":[{"id":"1.231540820","rc":[{"batb":[[0,1.96,46.26],[1,1.32,3.28],[2,1.3,2.93]],"ltp":2.0,"tv":88.69,"id":2219}]}]}
{"op":"mcm","clk":"11801269771","pt":1723065729552,"mc":[{"id":"1.231540820","rc":[{"batb":[[0,1.97,10],[1,1.96,46.26],[2,1.32,3.28]],"ltp":2.0,"tv":88.69,"id":2219}]}]}
{"op":"mcm","clk":"11801269903","pt":1723065732940,"mc":[{"id":"1.231540820","rc":[{"batb":[[0,1.96,46.26],[1,1.32,3.28],[2,1.3,2.93]],"ltp":2.0,"tv":88.69,"id":2219}]}]}
{"op":"mcm","clk":"11801270090","pt":1723065736839,"mc":[{"id":"1.231540820","rc":[{"batb":[[0,1.97,10],[1,1.96,46.26],[2,1.32,3.28]],"ltp":2.0,"tv":88.69,"id":2219}]}]}
{"op":"mcm","clk":"11801270237","pt":1723065740333,"mc":[{"id":"1.231540820","rc":[{"batb":[[0,1.96,46.26],[1,1.32,3.28],[2,1.3,2.93]],"ltp":2.0,"tv":88.69,"id":2219}]}]}
{"op":"mcm","clk":"11801270376","pt":1723065742964,"mc":[{"id":"1.231540820","rc":[{"batb":[[0,1.97,10],[1,1.96,46.26],[2,1.32,3.28]],"ltp":2.0,"tv":88.69,"id":2219}]}]}
{"op":"mcm","clk":"11801270533","pt":1723065746647,"mc":[{"id":"1.231540820","rc":[{"batb":[[0,1.96,46.26],[1,1.32,3.28],[2,1.3,2.93]],"ltp":2.0,"tv":88.69,"id":2219}]}]}
{"op":"mcm","clk":"11801270688","pt":1723065749979,"mc":[{"id":"1.231540820","rc":[{"batb":[[0,1.97,10],[1,1.96,46.26],[2,1.32,3.28]],"ltp":2.0,"tv":88.69,"id":2219}]}]}
{"op":"mcm","clk":"11801270851","pt":1723065753572,"mc":[{"id":"1.231540820","rc":[{"batb":[[0,1.96,46.26],[1,1.32,3.28],[2,1.3,2.93]],"ltp":2.0,"tv":88.69,"id":2219}]}]}
{"op":"mcm","clk":"11801271004","pt":1723065756805,"mc":[{"id":"1.231540820","rc":[{"batb":[[0,1.97,10],[1,1.96,46.26],[2,1.32,3.28]],"ltp":2.0,"tv":88.69,"id":2219}]}]}
{"op":"mcm","clk":"11801271150","pt":1723065760612,"mc":[{"id":"1.231540820","rc":[{"batb":[[0,1.96,46.26],[1,1.32,3.28],[2,1.3,2.93]],"ltp":2.0,"tv":88.69,"id":2219}]}]}
{"op":"mcm","clk":"11801271223","pt":1723065762923,"mc":[{"id":"1.231540820","rc":[{"batb":[[0,1.97,10],[1,1.96,46.26],[2,1.32,3.28]],"ltp":2.0,"tv":88.69,"id":2219}]}]}
{"op":"mcm","clk":"11801271338","pt":1723065766311,"mc":[{"id":"1.231540820","rc":[{"batb":[[0,1.96,46.26],[1,1.32,3.28],[2,1.3,2.93]],"ltp":2.0,"tv":88.69,"id":2219}]}]}
{"op":"mcm","clk":"11801271431","pt":1723065768826,"mc":[{"id":"1.231540820","rc":[{"batb":[[0,1.97,10],[1,1.96,46.26],[2,1.32,3.28]],"ltp":2.0,"tv":88.69,"id":2219}]}]}
{"op":"mcm","clk":"11801271560","pt":1723065772107,"mc":[{"id":"1.231540820","rc":[{"batb":[[0,1.96,46.26],[1,1.32,3.28],[2,1.3,2.93]],"ltp":2.0,"tv":88.69,"id":2219}]}]}
{"op":"mcm","clk":"11801271668","pt":1723065774624,"mc":[{"id":"1.231540820","rc":[{"batb":[[0,1.97,10],[1,1.96,46.26],[2,1.32,3.28]],"ltp":2.0,"tv":88.69,"id":2219}]}]}
{"op":"mcm","clk":"11801271790","pt":1723065778116,"mc":[{"id":"1.231540820","rc":[{"batb":[[0,1.96,46.26],[1,1.32,3.28],[2,1.3,2.93]],"ltp":2.0,"tv":88.69,"id":2219}]}]}
{"op":"mcm","clk":"11801271932","pt":1723065781710,"mc":[{"id":"1.231540820","rc":[{"batb":[[0,1.97,10],[1,1.96,46.26],[2,1.32,3.28]],"ltp":2.0,"tv":88.69,"id":2219}]}]}
{"op":"mcm","clk":"11801272067","pt":1723065785036,"mc":[{"id":"1.231540820","rc":[{"batb":[[0,1.96,46.26],[1,1.32,3.28],[2,1.3,2.93]],"ltp":2.0,"tv":88.69,"id":2219}]}]}
{"op":"mcm","clk":"11801272174","pt":1723065788055,"mc":[{"id":"1.231540820","rc":[{"batb":[[0,1.97,10],[1,1.96,46.26],[2,1.32,3.28]],"ltp":2.0,"tv":88.69,"id":2219}]}]}
{"op":"mcm","clk":"11801272313","pt":1723065791444,"mc":[{"id":"1.231540820","rc":[{"batb":[[0,1.96,46.26],[1,1.32,3.28],[2,1.3,2.93]],"ltp":2.0,"tv":88.69,"id":2219}]}]}
{"op":"mcm","clk":"11801272440","pt":1723065794224,"mc":[{"id":"1.231540820","rc":[{"batb":[[0,1.97,10],[1,1.96,46.26],[2,1.32,3.28]],"ltp":2.0,"tv":88.69,"id":2219}]}]}
{"op":"mcm","clk":"11801272572","pt":1723065797764,"mc":[{"id":"1.231540820","rc":[{"batb":[[0,1.96,46.26],[1,1.32,3.28],[2,1.3,2.93]],"ltp":2.0,"tv":88.69,"id":2219}]}]}
{"op":"mcm","clk":"11801272673","pt":1723065800124,"mc":[{"id":"1.231540820","rc":[{"batb":[[0,1.97,10],[1,1.96,46.26],[2,1.32,3.28]],"ltp":2.0,"tv":88.69,"id":2219}]}]}
{"op":"mcm","clk":"11801272848","pt":1723065804449,"mc":[{"id":"1.231540820","rc":[{"batb":[[0,1.96,46.26],[1,1.32,3.28],[2,1.3,2.93]],"ltp":2.0,"tv":88.69,"id":2219}]}]}
{"op":"mcm","clk":"11801272960","pt":1723065806863,"mc":[{"id":"1.231540820","rc":[{"batb":[[0,1.97,10],[1,1.96,46.26],[2,1.32,3.28]],"ltp":2.0,"tv":88.69,"id":2219}]}]}
{"op":"mcm","clk":"11801273160","pt":1723065810454,"mc":[{"id":"1.231540820","rc":[{"batb":[[0,1.96,46.26],[1,1.32,3.28],[2,1.3,2.93]],"ltp":2.0,"tv":88.69,"id":2219}]}]}
{"op":"mcm","clk":"11801273279","pt":1723065812964,"mc":[{"id":"1.231540820","rc":[{"batb":[[0,1.97,10],[1,1.96,46.26],[2,1.32,3.28]],"ltp":2.0,"tv":88.69,"id":2219}]}]}
{"op":"mcm","clk":"11801273440","pt":1723065816411,"mc":[{"id":"1.231540820","rc":[{"batb":[[0,1.96,46.26],[1,1.32,3.28],[2,1.3,2.93]],"ltp":2.0,"tv":88.69,"id":2219}]}]}
{"op":"mcm","clk":"11801273584","pt":1723065819801,"mc":[{"id":"1.231540820","rc":[{"batb":[[0,1.97,10],[1,1.96,46.26],[2,1.32,3.28]],"ltp":2.0,"tv":88.69,"id":2219}]}]}
{"op":"mcm","clk":"11801273741","pt":1723065823195,"mc":[{"id":"1.231540820","rc":[{"batb":[[0,1.96,46.26],[1,1.32,3.28],[2,1.3,2.93]],"ltp":2.0,"tv":88.69,"id":2219}]}]}
{"op":"mcm","clk":"11801273860","pt":1723065825880,"mc":[{"id":"1.231540820","rc":[{"batb":[[0,1.97,10],[1,1.96,46.26],[2,1.32,3.28]],"ltp":2.0,"tv":88.69,"id":2219}]}]}
{"op":"mcm","clk":"11801273992","pt":1723065829312,"mc":[{"id":"1.231540820","rc":[{"batb":[[0,1.96,46.26],[1,1.32,3.28],[2,1.3,2.93]],"ltp":2.0,"tv":88.69,"id":2219}]}]}
{"op":"mcm","clk":"11801274105","pt":1723065831979,"mc":[{"id":"1.231540820","rc":[{"batb":[[0,1.97,10],[1,1.96,46.26],[2,1.32,3.28]],"ltp":2.0,"tv":88.69,"id":2219}]}]}
{"op":"mcm","clk":"11801274262","pt":1723065835508,"mc":[{"id":"1.231540820","rc":[{"batb":[[0,1.96,46.26],[1,1.32,3.28],[2,1.3,2.93]],"ltp":2.0,"tv":88.69,"id":2219}]}]}
{"op":"mcm","clk":"11801274368","pt":1723065837918,"mc":[{"id":"1.231540820","rc":[{"batb":[[0,1.97,10],[1,1.96,46.26],[2,1.32,3.28]],"ltp":2.0,"tv":88.69,"id":2219}]}]}
{"op":"mcm","clk":"11801274516","pt":1723065841404,"mc":[{"id":"1.231540820","rc":[{"batb":[[0,1.96,46.26],[1,1.32,3.28],[2,1.3,2.93]],"ltp":2.0,"tv":88.69,"id":2219}]}]}
{"op":"mcm","clk":"11801274710","pt":1723065844905,"mc":[{"id":"1.231540820","rc":[{"batb":[[0,1.97,10],[1,1.96,46.26],[2,1.32,3.28]],"ltp":2.0,"tv":88.69,"id":2219}]}]}
{"op":"mcm","clk":"11801274869","pt":1723065848315,"mc":[{"id":"1.231540820","rc":[{"batb":[[0,1.96,46.26],[1,1.32,3.28],[2,1.3,2.93]],"ltp":2.0,"tv":88.69,"id":2219}]}]}
{"op":"mcm","clk":"11801275008","pt":1723065851453,"mc":[{"id":"1.231540820","rc":[{"batb":[[0,1.97,10],[1,1.96,46.26],[2,1.32,3.28]],"ltp":2.0,"tv":88.69,"id":2219}]}]}
{"op":"mcm","clk":"11801275177","pt":1723065855455,"mc":[{"id":"1.231540820","rc":[{"batb":[[0,1.96,46.26],[1,1.32,3.28],[2,1.3,2.93]],"ltp":2.0,"tv":88.69,"id":2219}]}]}
{"op":"mcm","clk":"11801275286","pt":1723065858123,"mc":[{"id":"1.231540820","rc":[{"batb":[[0,1.97,10],[1,1.96,46.26],[2,1.32,3.28]],"ltp":2.0,"tv":88.69,"id":2219}]}]}
{"op":"mcm","clk":"11801275435","pt":1723065861557,"mc":[{"id":"1.231540820","rc":[{"batb":[[0,1.96,46.26],[1,1.32,3.28],[2,1.3,2.93]],"ltp":2.0,"tv":88.69,"id":2219}]}]}
{"op":"mcm","clk":"11801275590","pt":1723065864733,"mc":[{"id":"1.231540820","rc":[{"batb":[[0,1.97,10],[1,1.96,46.26],[2,1.32,3.28]],"ltp":2.0,"tv":88.69,"id":2219}]}]}
{"op":"mcm","clk":"11801275750","pt":1723065868366,"mc":[{"id":"1.231540820","rc":[{"batb":[[0,1.96,46.26],[1,1.32,3.28],[2,1.3,2.93]],"ltp":2.0,"tv":88.69,"id":2219}]}]}
{"op":"mcm","clk":"11801275844","pt":1723065870979,"mc":[{"id":"1.231540820","rc":[{"batb":[[0,1.97,10],[1,1.96,46.26],[2,1.32,3.28]],"ltp":2.0,"tv":88.69,"id":2219}]}]}
{"op":"mcm","clk":"11801276006","pt":1723065874359,"mc":[{"id":"1.231540820","rc":[{"batb":[[0,1.96,46.26],[1,1.32,3.28],[2,1.3,2.93]],"ltp":2.0,"tv":88.69,"id":2219}]}]}
{"op":"mcm","clk":"11801276112","pt":1723065877075,"mc":[{"id":"1.231540820","rc":[{"batb":[[0,1.97,10],[1,1.96,46.26],[2,1.32,3.28]],"ltp":2.0,"tv":88.69,"id":2219}]}]}
{"op":"mcm","clk":"11801276255","pt":1723065880559,"mc":[{"id":"1.231540820","rc":[{"batb":[[0,1.96,46.26],[1,1.32,3.28],[2,1.3,2.93]],"ltp":2.0,"tv":88.69,"id":2219}]}]}
{"op":"mcm","clk":"11801276358","pt":1723065882962,"mc":[{"id":"1.231540820","rc":[{"batb":[[0,1.97,10],[1,1.96,46.26],[2,1.32,3.28]],"ltp":2.0,"tv":88.69,"id":2219}]}]}
{"op":"mcm","clk":"11801276487","pt":1723065886697,"mc":[{"id":"1.231540820","rc":[{"batb":[[0,1.96,46.26],[1,1.32,3.28],[2,1.3,2.93]],"ltp":2.0,"tv":88.69,"id":2219}]}]}
{"op":"mcm","clk":"11801276631","pt":1723065890184,"mc":[{"id":"1.231540820","rc":[{"batb":[[0,1.97,10],[1,1.96,46.26],[2,1.32,3.28]],"ltp":2.0,"tv":88.69,"id":2219}]}]}
{"op":"mcm","clk":"11801276766","pt":1723065893714,"mc":[{"id":"1.231540820","rc":[{"batb":[[0,1.96,46.26],[1,1.32,3.28],[2,1.3,2.93]],"ltp":2.0,"tv":88.69,"id":2219}]}]}
{"op":"mcm","clk":"11801276856","pt":1723065896121,"mc":[{"id":"1.231540820","rc":[{"batb":[[0,1.97,10],[1,1.96,46.26],[2,1.32,3.28]],"ltp":2.0,"tv":88.69,"id":2219}]}]}
{"op":"mcm","clk":"11801276986","pt":1723065899400,"mc":[{"id":"1.231540820","rc":[{"batb":[[0,1.96,46.26],[1,1.32,3.28],[2,1.3,2.93]],"ltp":2.0,"tv":88.69,"id":2219}]}]}
{"op":"mcm","clk":"11801277105","pt":1723065901913,"mc":[{"id":"1.231540820","rc":[{"batb":[[0,1.97,10],[1,1.96,46.26],[2,1.32,3.28]],"ltp":2.0,"tv":88.69,"id":2219}]}]}
{"op":"mcm","clk":"11801277288","pt":1723065905398,"mc":[{"id":"1.231540820","rc":[{"batb":[[0,1.96,46.26],[1,1.32,3.28],[2,1.3,2.93]],"ltp":2.0,"tv":88.69,"id":2219}]}]}
{"op":"mcm","clk":"11801277425","pt":1723065908934,"mc":[{"id":"1.231540820","rc":[{"batb":[[0,1.97,10],[1,1.96,46.26],[2,1.32,3.28]],"ltp":2.0,"tv":88.69,"id":2219}]}]}
{"op":"mcm","clk":"11801277578","pt":1723065912317,"mc":[{"id":"1.231540820","rc":[{"batb":[[0,1.96,46.26],[1,1.32,3.28],[2,1.3,2.93]],"ltp":2.0,"tv":88.69,"id":2219}]}]}
{"op":"mcm","clk":"11801277719","pt":1723065915027,"mc":[{"id":"1.231540820","rc":[{"batb":[[0,1.97,10],[1,1.96,46.26],[2,1.32,3.28]],"ltp":2.0,"tv":88.69,"id":2219}]}]}
{"op":"mcm","clk":"11801277913","pt":1723065918423,"mc":[{"id":"1.231540820","rc":[{"batb":[[0,1.96,46.26],[1,1.32,3.28],[2,1.3,2.93]],"ltp":2.0,"tv":88.69,"id":2219}]}]}
{"op":"mcm","clk":"11801278045","pt":1723065921355,"mc":[{"id":"1.231540820","rc":[{"batb":[[0,1.97,10],[1,1.96,46.26],[2,1.32,3.28]],"ltp":2.0,"tv":88.69,"id":2219}]}]}
{"op":"mcm","clk":"11801278183","pt":1723065924842,"mc":[{"id":"1.231540820","rc":[{"batb":[[0,1.96,46.26],[1,1.32,3.28],[2,1.3,2.93]],"ltp":2.0,"tv":88.69,"id":2219}]}]}
{"op":"mcm","clk":"11801278311","pt":1723065927459,"mc":[{"id":"1.231540820","rc":[{"batb":[[0,1.97,10],[1,1.96,46.26],[2,1.32,3.28]],"ltp":2.0,"tv":88.69,"id":2219}]}]}
{"op":"mcm","clk":"11801278443","pt":1723065930949,"mc":[{"id":"1.231540820","rc":[{"batb":[[0,1.96,46.26],[1,1.32,3.28],[2,1.3,2.93]],"ltp":2.0,"tv":88.69,"id":2219}]}]}
{"op":"mcm","clk":"11801278641","pt":1723065935560,"mc":[{"id":"1.231540820","rc":[{"batb":[[0,1.97,10],[1,1.96,46.26],[2,1.32,3.28]],"ltp":2.0,"tv":88.69,"id":2219}]}]}
{"op":"mcm","clk":"11801278776","pt":1723065938946,"mc":[{"id":"1.231540820","rc":[{"batb":[[0,1.96,46.26],[1,1.32,3.28],[2,1.3,2.93]],"ltp":2.0,"tv":88.69,"id":2219}]}]}
{"op":"mcm","clk":"11801278883","pt":1723065941506,"mc":[{"id":"1.231540820","rc":[{"batb":[[0,1.97,10],[1,1.96,46.26],[2,1.32,3.28]],"ltp":2.0,"tv":88.69,"id":2219}]}]}
{"op":"mcm","clk":"11801279055","pt":1723065944689,"mc":[{"id":"1.231540820","rc":[{"batb":[[0,1.96,46.26],[1,1.32,3.28],[2,1.3,2.93]],"ltp":2.0,"tv":88.69,"id":2219}]}]}
{"op":"mcm","clk":"11801279172","pt":1723065947278,"mc":[{"id":"1.231540820","rc":[{"batb":[[0,1.97,10],[1,1.96,46.26],[2,1.32,3.28]],"ltp":2.0,"tv":88.69,"id":2219}]}]}
{"op":"mcm","clk":"11801279322","pt":1723065950618,"mc":[{"id":"1.231540820","rc":[{"batb":[[0,1.96,46.26],[1,1.32,3.28],[2,1.3,2.93]],"ltp":2.0,"tv":88.69,"id":2219}]}]}
{"op":"mcm","clk":"11801279452","pt":1723065953290,"mc":[{"id":"1.231540820","rc":[{"batb":[[0,1.97,10],[1,1.96,46.26],[2,1.32,3.28]],"ltp":2.0,"tv":88.69,"id":2219}]}]}
{"op":"mcm","clk":"11801279590","pt":1723065956578,"mc":[{"id":"1.231540820","rc":[{"batb":[[0,1.96,46.26],[1,1.32,3.28],[2,1.3,2.93]],"ltp":2.0,"tv":88.69,"id":2219}]}]}
{"op":"mcm","clk":"11801279704","pt":1723065959098,"mc":[{"id":"1.231540820","rc":[{"batb":[[0,1.97,10],[1,1.96,46.26],[2,1.32,3.28]],"ltp":2.0,"tv":88.69,"id":2219}]}]}
{"op":"mcm","clk":"11801279858","pt":1723065962499,"mc":[{"id":"1.231540820","rc":[{"batb":[[0,1.96,46.26],[1,1.32,3.28],[2,1.3,2.93]],"ltp":2.0,"tv":88.69,"id":2219}]}]}
{"op":"mcm","clk":"11801279964","pt":1723065964912,"mc":[{"id":"1.231540820","rc":[{"batb":[[0,1.97,10],[1,1.96,46.26],[2,1.32,3.28]],"ltp":2.0,"tv":88.69,"id":2219}]}]}
{"op":"mcm","clk":"11801280104","pt":1723065968308,"mc":[{"id":"1.231540820","rc":[{"batb":[[0,1.96,46.26],[1,1.32,3.28],[2,1.3,2.93]],"ltp":2.0,"tv":88.69,"id":2219}]}]}
{"op":"mcm","clk":"11801280224","pt":1723065970615,"mc":[{"id":"1.231540820","rc":[{"batb":[[0,1.97,10],[1,1.96,46.26],[2,1.32,3.28]],"ltp":2.0,"tv":88.69,"id":2219}]}]}
{"op":"mcm","clk":"11801280358","pt":1723065974009,"mc":[{"id":"1.231540820","rc":[{"batb":[[0,1.96,46.26],[1,1.32,3.28],[2,1.3,2.93]],"ltp":2.0,"tv":88.69,"id":2219}]}]}
{"op":"mcm","clk":"11801280477","pt":1723065976522,"mc":[{"id":"1.231540820","rc":[{"batb":[[0,1.97,10],[1,1.96,46.26],[2,1.32,3.28]],"ltp":2.0,"tv":88.69,"id":2219}]}]}
{"op":"mcm","clk":"11801280634","pt":1723065979953,"mc":[{"id":"1.231540820","rc":[{"batb":[[0,1.96,46.26],[1,1.32,3.28],[2,1.3,2.93]],"ltp":2.0,"tv":88.69,"id":2219}]}]}
{"op":"mcm","clk":"11801280770","pt":1723065982625,"mc":[{"id":"1.231540820","rc":[{"batb":[[0,1.97,10],[1,1.96,46.26],[2,1.32,3.28]],"ltp":2.0,"tv":88.69,"id":2219}]}]}
{"op":"mcm","clk":"11801280934","pt":1723065986057,"mc":[{"id":"1.231540820","rc":[{"batb":[[0,1.96,46.26],[1,1.32,3.28],[2,1.3,2.93]],"ltp":2.0,"tv":88.69,"id":2219}]}]}
{"op":"mcm","clk":"11801281043","pt":1723065988965,"mc":[{"id":"1.231540820","rc":[{"batb":[[0,1.97,10],[1,1.96,46.26],[2,1.32,3.28]],"ltp":2.0,"tv":88.69,"id":2219}]}]}
{"op":"mcm","clk":"11801281161","pt":1723065992238,"mc":[{"id":"1.231540820","rc":[{"batb":[[0,1.96,46.26],[1,1.32,3.28],[2,1.3,2.93]],"ltp":2.0,"tv":88.69,"id":2219}]}]}
{"op":"mcm","clk":"11801281262","pt":1723065994744,"mc":[{"id":"1.231540820","rc":[{"batb":[[0,1.97,10],[1,1.96,46.26],[2,1.32,3.28]],"ltp":2.0,"tv":88.69,"id":2219}]}]}
{"op":"mcm","clk":"11801281387","pt":1723065998268,"mc":[{"id":"1.231540820","rc":[{"batb":[[0,1.96,46.26],[1,1.32,3.28],[2,1.3,2.93]],"ltp":2.0,"tv":88.69,"id":2219}]}]}
{"op":"mcm","clk":"11801281466","pt":1723066000677,"mc":[{"id":"1.231540820","rc":[{"batb":[[0,1.97,10],[1,1.96,46.26],[2,1.32,3.28]],"ltp":2.0,"tv":88.69,"id":2219}]}]}
{"op":"mcm","clk":"11801281585","pt":1723066004157,"mc":[{"id":"1.231540820","rc":[{"batb":[[0,1.96,46.26],[1,1.32,3.28],[2,1.3,2.93]],"ltp":2.0,"tv":88.69,"id":2219}]}]}
{"op":"mcm","clk":"11801281691","pt":1723066006972,"mc":[{"id":"1.231540820","rc":[{"batb":[[0,1.97,10],[1,1.96,46.26],[2,1.32,3.28]],"ltp":2.0,"tv":88.69,"id":2219}]}]}
{"op":"mcm","clk":"11801281814","pt":1723066010355,"mc":[{"id":"1.231540820","rc":[{"batb":[[0,1.96,46.26],[1,1.32,3.28],[2,1.3,2.93]],"ltp":2.0,"tv":88.69,"id":2219}]}]}
{"op":"mcm","clk":"11801281978","pt":1723066013580,"mc":[{"id":"1.231540820","rc":[{"batb":[[0,1.97,10],[1,1.96,46.26],[2,1.32,3.28]],"ltp":2.0,"tv":88.69,"id":2219}]}]}
{"op":"mcm","clk":"11801282218","pt":1723066017056,"mc":[{"id":"1.231540820","rc":[{"batb":[[0,1.96,46.26],[1,1.32,3.28],[2,1.3,2.93]],"ltp":2.0,"tv":88.69,"id":2219}]}]}
{"op":"mcm","clk":"11801282296","pt":1723066019567,"mc":[{"id":"1.231540820","rc":[{"batb":[[0,1.97,10],[1,1.96,46.26],[2,1.32,3.28]],"ltp":2.0,"tv":88.69,"id":2219}]}]}
{"op":"mcm","clk":"11801282433","pt":1723066023004,"mc":[{"id":"1.231540820","rc":[{"batb":[[0,1.96,46.26],[1,1.32,3.28],[2,1.3,2.93]],"ltp":2.0,"tv":88.69,"id":2219}]}]}
{"op":"mcm","clk":"11801282538","pt":1723066025308,"mc":[{"id":"1.231540820","rc":[{"batb":[[0,1.97,10],[1,1.96,46.26],[2,1.32,3.28]],"ltp":2.0,"tv":88.69,"id":2219}]}]}
{"op":"mcm","clk":"11801282666","pt":1723066028688,"mc":[{"id":"1.231540820","rc":[{"batb":[[0,1.96,46.26],[1,1.32,3.28],[2,1.3,2.93]],"ltp":2.0,"tv":88.69,"id":2219}]}]}
{"op":"mcm","clk":"11801282774","pt":1723066031193,"mc":[{"id":"1.231540820","rc":[{"batb":[[0,1.97,10],[1,1.96,46.26],[2,1.32,3.28]],"ltp":2.0,"tv":88.69,"id":2219}]}]}
{"op":"mcm","clk":"11801282917","pt":1723066034424,"mc":[{"id":"1.231540820","rc":[{"batb":[[0,1.96,46.26],[1,1.32,3.28],[2,1.3,2.93]],"ltp":2.0,"tv":88.69,"id":2219}]}]}
{"op":"mcm","clk":"11801283207","pt":1723066041703,"mc":[{"id":"1.231540820","rc":[{"batb":[[0,1.97,10],[1,1.96,46.26],[2,1.32,3.28]],"ltp":2.0,"tv":88.69,"id":2219}]}]}
{"op":"mcm","clk":"11801283347","pt":1723066045136,"mc":[{"id":"1.231540820","rc":[{"batb":[[0,1.96,46.26],[1,1.32,3.28],[2,1.3,2.93]],"ltp":2.0,"tv":88.69,"id":2219}]}]}
{"op":"mcm","clk":"11801283481","pt":1723066047543,"mc":[{"id":"1.231540820","rc":[{"batb":[[0,1.97,10],[1,1.96,46.26],[2,1.32,3.28]],"ltp":2.0,"tv":88.69,"id":2219}]}]}
{"op":"mcm","clk":"11801283612","pt":1723066051025,"mc":[{"id":"1.231540820","rc":[{"batb":[[0,1.96,46.26],[1,1.32,3.28],[2,1.3,2.93]],"ltp":2.0,"tv":88.69,"id":2219}]}]}
{"op":"mcm","clk":"11801283701","pt":1723066053428,"mc":[{"id":"1.231540820","rc":[{"batb":[[0,1.97,10],[1,1.96,46.26],[2,1.32,3.28]],"ltp":2.0,"tv":88.69,"id":2219}]}]}
{"op":"mcm","clk":"11801283862","pt":1723066056911,"mc":[{"id":"1.231540820","rc":[{"batb":[[0,1.96,46.26],[1,1.32,3.28],[2,1.3,2.93]],"ltp":2.0,"tv":88.69,"id":2219}]}]}
{"op":"mcm","clk":"11801284014","pt":1723066060128,"mc":[{"id":"1.231540820","rc":[{"batb":[[0,1.97,10],[1,1.96,46.26],[2,1.32,3.28]],"ltp":2.0,"tv":88.69,"id":2219}]}]}
{"op":"mcm","clk":"11801284194","pt":1723066063559,"mc":[{"id":"1.231540820","rc":[{"batb":[[0,1.96,46.26],[1,1.32,3.28],[2,1.3,2.93]],"ltp":2.0,"tv":88.69,"id":2219}]}]}
{"op":"mcm","clk":"11801284327","pt":1723066067044,"mc":[{"id":"1.231540820","rc":[{"batb":[[0,1.97,10],[1,1.96,46.26],[2,1.32,3.28]],"ltp":2.0,"tv":88.69,"id":2219}]}]}
{"op":"mcm","clk":"11801284505","pt":1723066070632,"mc":[{"id":"1.231540820","rc":[{"batb":[[0,1.96,46.26],[1,1.32,3.28],[2,1.3,2.93]],"ltp":2.0,"tv":88.69,"id":2219}]}]}
{"op":"mcm","clk":"11801284622","pt":1723066073663,"mc":[{"id":"1.231540820","rc":[{"batb":[[0,1.97,10],[1,1.96,46.26],[2,1.32,3.28]],"ltp":2.0,"tv":88.69,"id":2219}]}]}
{"op":"mcm","clk":"11801284774","pt":1723066077192,"mc":[{"id":"1.231540820","rc":[{"batb":[[0,1.96,46.26],[1,1.32,3.28],[2,1.3,2.93]],"ltp":2.0,"tv":88.69,"id":2219}]}]}
{"op":"mcm","clk":"11801284903","pt":1723066079648,"mc":[{"id":"1.231540820","rc":[{"batb":[[0,1.97,10],[1,1.96,46.26],[2,1.32,3.28]],"ltp":2.0,"tv":88.69,"id":2219}]}]}
{"op":"mcm","clk":"11801285059","pt":1723066083087,"mc":[{"id":"1.231540820","rc":[{"batb":[[0,1.96,46.26],[1,1.32,3.28],[2,1.3,2.93]],"ltp":2.0,"tv":88.69,"id":2219}]}]}
{"op":"mcm","clk":"11801285164","pt":1723066085494,"mc":[{"id":"1.231540820","rc":[{"batb":[[0,1.97,10],[1,1.96,46.26],[2,1.32,3.28]],"ltp":2.0,"tv":88.69,"id":2219}]}]}
{"op":"mcm","clk":"11801285306","pt":1723066088674,"mc":[{"id":"1.231540820","rc":[{"batb":[[0,1.96,46.26],[1,1.32,3.28],[2,1.3,2.93]],"ltp":2.0,"tv":88.69,"id":2219}]}]}
{"op":"mcm","clk":"11801285398","pt":1723066091182,"mc":[{"id":"1.231540820","rc":[{"batb":[[0,1.97,10],[1,1.96,46.26],[2,1.32,3.28]],"ltp":2.0,"tv":88.69,"id":2219}]}]}
{"op":"mcm","clk":"11801285563","pt":1723066094624,"mc":[{"id":"1.231540820","rc":[{"batb":[[0,1.96,46.26],[1,1.32,3.28],[2,1.3,2.93]],"ltp":2.0,"tv":88.69,"id":2219}]}]}
{"op":"mcm","clk":"11801285721","pt":1723066098008,"mc":[{"id":"1.231540820","rc":[{"batb":[[0,1.97,10],[1,1.96,46.26],[2,1.32,3.28]],"ltp":2.0,"tv":88.69,"id":2219}]}]}
{"op":"mcm","clk":"11801285905","pt":1723066101499,"mc":[{"id":"1.231540820","rc":[{"batb":[[0,1.96,46.26],[1,1.32,3.28],[2,1.3,2.93]],"ltp":2.0,"tv":88.69,"id":2219}]}]}
{"op":"mcm","clk":"11801286046","pt":1723066104118,"mc":[{"id":"1.231540820","rc":[{"batb":[[0,1.97,10],[1,1.96,46.26],[2,1.32,3.28]],"ltp":2.0,"tv":88.69,"id":2219}]}]}
{"op":"mcm","clk":"11801286251","pt":1723066107647,"mc":[{"id":"1.231540820","rc":[{"batb":[[0,1.96,46.26],[1,1.32,3.28],[2,1.3,2.93]],"ltp":2.0,"tv":88.69,"id":2219}]}]}
{"op":"mcm","clk":"11801286357","pt":1723066109852,"mc":[{"id":"1.231540820","rc":[{"batb":[[0,1.97,10],[1,1.96,46.26],[2,1.32,3.28]],"ltp":2.0,"tv":88.69,"id":2219}]}]}
{"op":"mcm","clk":"11801286495","pt":1723066113335,"mc":[{"id":"1.231540820","rc":[{"batb":[[0,1.96,46.26],[1,1.32,3.28],[2,1.3,2.93]],"ltp":2.0,"tv":88.69,"id":2219}]}]}
{"op":"mcm","clk":"11801286587","pt":1723066115652,"mc":[{"id":"1.231540820","rc":[{"batb":[[0,1.97,10],[1,1.96,46.26],[2,1.32,3.28]],"ltp":2.0,"tv":88.69,"id":2219}]}]}
{"op":"mcm","clk":"11801286751","pt":1723066119125,"mc":[{"id":"1.231540820","rc":[{"batb":[[0,1.96,46.26],[1,1.32,3.28],[2,1.3,2.93]],"ltp":2.0,"tv":88.69,"id":2219}]}]}
{"op":"mcm","clk":"11801286853","pt":1723066121943,"mc":[{"id":"1.231540820","rc":[{"batb":[[0,1.97,10],[1,1.96,46.26],[2,1.32,3.28]],"ltp":2.0,"tv":88.69,"id":2219}]}]}
{"op":"mcm","clk":"11801286996","pt":1723066125436,"mc":[{"id":"1.231540820","rc":[{"batb":[[0,1.96,46.26],[1,1.32,3.28],[2,1.3,2.93]],"ltp":2.0,"tv":88.69,"id":2219}]}]}
{"op":"mcm","clk":"11801287077","pt":1723066127775,"mc":[{"id":"1.231540820","rc":[{"batb":[[0,1.97,10],[1,1.96,46.26],[2,1.32,3.28]],"ltp":2.0,"tv":88.69,"id":2219}]}]}
{"op":"mcm","clk":"11801287246","pt":1723066131437,"mc":[{"id":"1.231540820","rc":[{"batb":[[0,1.96,46.26],[1,1.32,3.28],[2,1.3,2.93]],"ltp":2.0,"tv":88.69,"id":2219}]}]}
{"op":"mcm","clk":"11801287407","pt":1723066134255,"mc":[{"id":"1.231540820","rc":[{"batb":[[0,1.97,10],[1,1.96,46.26],[2,1.32,3.28]],"ltp":2.0,"tv":88.69,"id":2219}]}]}
{"op":"mcm","clk":"11801287584","pt":1723066137640,"mc":[{"id":"1.231540820","rc":[{"batb":[[0,1.96,46.26],[1,1.32,3.28],[2,1.3,2.93]],"ltp":2.0,"tv":88.69,"id":2219}]}]}
{"op":"mcm","clk":"11801287726","pt":1723066140965,"mc":[{"id":"1.231540820","rc":[{"batb":[[0,1.97,10],[1,1.96,46.26],[2,1.32,3.28]],"ltp":2.0,"tv":88.69,"id":2219}]}]}
{"op":"mcm","clk":"11801287902","pt":1723066144259,"mc":[{"id":"1.231540820","rc":[{"batb":[[0,1.96,46.26],[1,1.32,3.28],[2,1.3,2.93]],"ltp":2.0,"tv":88.69,"id":2219}]}]}
{"op":"mcm","clk":"11801288050","pt":1723066146875,"mc":[{"id":"1.231540820","rc":[{"batb":[[0,1.97,10],[1,1.96,46.26],[2,1.32,3.28]],"ltp":2.0,"tv":88.69,"id":2219}]}]}
{"op":"mcm","clk":"11801288219","pt":1723066150272,"mc":[{"id":"1.231540820","rc":[{"batb":[[0,1.96,46.26],[1,1.32,3.28],[2,1.3,2.93]],"ltp":2.0,"tv":88.69,"id":2219}]}]}
{"op":"mcm","clk":"11801288388","pt":1723066154174,"mc":[{"id":"1.231540820","rc":[{"batb":[[0,1.97,10],[1,1.96,46.26],[2,1.32,3.28]],"ltp":2.0,"tv":88.69,"id":2219}]}]}
{"op":"mcm","clk":"11801288546","pt":1723066157566,"mc":[{"id":"1.231540820","rc":[{"batb":[[0,1.96,46.26],[1,1.32,3.28],[2,1.3,2.93]],"ltp":2.0,"tv":88.69,"id":2219}]}]}
{"op":"mcm","clk":"11801288749","pt":1723066162189,"mc":[{"id":"1.231540820","rc":[{"batb":[[0,1.97,10],[1,1.96,46.26],[2,1.32,3.28]],"ltp":2.0,"tv":88.69,"id":2219}]}]}
{"op":"mcm","clk":"11801288905","pt":1723066165679,"mc":[{"id":"1.231540820","rc":[{"batb":[[0,1.96,46.26],[1,1.32,3.28],[2,1.3,2.93]],"ltp":2.0,"tv":88.69,"id":2219}]}]}
{"op":"mcm","clk":"11801289061","pt":1723066169271,"mc":[{"id":"1.231540820","rc":[{"batb":[[0,1.97,10],[1,1.96,46.26],[2,1.32,3.28]],"ltp":2.0,"tv":88.69,"id":2219}]}]}
{"op":"mcm","clk":"11801289220","pt":1723066172610,"mc":[{"id":"1.231540820","rc":[{"batb":[[0,1.96,46.26],[1,1.32,3.28],[2,1.3,2.93]],"ltp":2.0,"tv":88.69,"id":2219}]}]}
{"op":"mcm","clk":"11801289362","pt":1723066175681,"mc":[{"id":"1.231540820","rc":[{"batb":[[0,1.97,10],[1,1.96,46.26],[2,1.32,3.28]],"ltp":2.0,"tv":88.69,"id":2219}]}]}
{"op":"mcm","clk":"11801289525","pt":1723066179222,"mc":[{"id":"1.231540820","rc":[{"batb":[[0,1.96,46.26],[1,1.32,3.28],[2,1.3,2.93]],"ltp":2.0,"tv":88.69,"id":2219}]}]}
{"op":"mcm","clk":"11801289673","pt":1723066181889,"mc":[{"id":"1.231540820","rc":[{"batb":[[0,1.97,10],[1,1.96,46.26],[2,1.32,3.28]],"ltp":2.0,"tv":88.69,"id":2219}]}]}
{"op":"mcm","clk":"11801289854","pt":1723066185328,"mc":[{"id":"1.231540820","rc":[{"batb":[[0,1.96,46.26],[1,1.32,3.28],[2,1.3,2.93]],"ltp":2.0,"tv":88.69,"id":2219}]}]}
{"op":"mcm","clk":"11801289967","pt":1723066188213,"mc":[{"id":"1.231540820","rc":[{"batb":[[0,1.97,10],[1,1.96,46.26],[2,1.32,3.28]],"ltp":2.0,"tv":88.69,"id":2219}]}]}
{"op":"mcm","clk":"11801290110","pt":1723066191541,"mc":[{"id":"1.231540820","rc":[{"batb":[[0,1.96,46.26],[1,1.32,3.28],[2,1.3,2.93]],"ltp":2.0,"tv":88.69,"id":2219}]}]}
{"op":"mcm","clk":"11801290262","pt":1723066194731,"mc":[{"id":"1.231540820","rc":[{"batb":[[0,1.97,10],[1,1.96,46.26],[2,1.32,3.28]],"ltp":2.0,"tv":88.69,"id":2219}]}]}
{"op":"mcm","clk":"11801290412","pt":1723066198119,"mc":[{"id":"1.231540820","rc":[{"batb":[[0,1.96,46.26],[1,1.32,3.28],[2,1.3,2.93]],"ltp":2.0,"tv":88.69,"id":2219}]}]}
{"op":"mcm","clk":"11801290510","pt":1723066200336,"mc":[{"id":"1.231540820","rc":[{"batb":[[0,1.97,10],[1,1.96,46.26],[2,1.32,3.28]],"ltp":2.0,"tv":88.69,"id":2219}]}]}
{"op":"mcm","clk":"11801290699","pt":1723066203640,"mc":[{"id":"1.231540820","rc":[{"batb":[[0,1.96,46.26],[1,1.32,3.28],[2,1.3,2.93]],"ltp":2.0,"tv":88.69,"id":2219}]}]}
{"op":"mcm","clk":"11801290834","pt":1723066207075,"mc":[{"id":"1.231540820","rc":[{"batb":[[0,1.97,10],[1,1.96,46.26],[2,1.32,3.28]],"ltp":2.0,"tv":88.69,"id":2219}]}]}
{"op":"mcm","clk":"11801290987","pt":1723066210460,"mc":[{"id":"1.231540820","rc":[{"batb":[[0,1.96,46.26],[1,1.32,3.28],[2,1.3,2.93]],"ltp":2.0,"tv":88.69,"id":2219}]}]}
{"op":"mcm","clk":"11801291135","pt":1723066213857,"mc":[{"id":"1.231540820","rc":[{"batb":[[0,1.97,10],[1,1.96,46.26],[2,1.32,3.28]],"ltp":2.0,"tv":88.69,"id":2219}]}]}
{"op":"mcm","clk":"11801291279","pt":1723066217146,"mc":[{"id":"1.231540820","rc":[{"batb":[[0,1.96,46.26],[1,1.32,3.28],[2,1.3,2.93]],"ltp":2.0,"tv":88.69,"id":2219}]}]}
{"op":"mcm","clk":"11801291434","pt":1723066220271,"mc":[{"id":"1.231540820","rc":[{"batb":[[0,1.97,10],[1,1.96,46.26],[2,1.32,3.28]],"ltp":2.0,"tv":88.69,"id":2219}]}]}
{"op":"mcm","clk":"11801291573","pt":1723066223554,"mc":[{"id":"1.231540820","rc":[{"batb":[[0,1.96,46.26],[1,1.32,3.28],[2,1.3,2.93]],"ltp":2.0,"tv":88.69,"id":2219}]}]}
{"op":"mcm","clk":"11801291686","pt":1723066225973,"mc":[{"id":"1.231540820","rc":[{"batb":[[0,1.97,10],[1,1.96,46.26],[2,1.32,3.28]],"ltp":2.0,"tv":88.69,"id":2219}]}]}
{"op":"mcm","clk":"11801291865","pt":1723066229665,"mc":[{"id":"1.231540820","rc":[{"batb":[[0,1.96,46.26],[1,1.32,3.28],[2,1.3,2.93]],"ltp":2.0,"tv":88.69,"id":2219}]}]}
{"op":"mcm","clk":"11801292011","pt":1723066232795,"mc":[{"id":"1.231540820","rc":[{"batb":[[0,1.97,10],[1,1.96,46.26],[2,1.32,3.28]],"ltp":2.0,"tv":88.69,"id":2219}]}]}
{"op":"mcm","clk":"11801292207","pt":1723066236183,"mc":[{"id":"1.231540820","rc":[{"batb":[[0,1.96,46.26],[1,1.32,3.28],[2,1.3,2.93]],"ltp":2.0,"tv":88.69,"id":2219}]}]}
{"op":"mcm","clk":"11801292354","pt":1723066239780,"mc":[{"id":"1.231540820","rc":[{"batb":[[0,1.97,10],[1,1.96,46.26],[2,1.32,3.28]],"ltp":2.0,"tv":88.69,"id":2219}]}]}
{"op":"mcm","clk":"11801292522","pt":1723066243007,"mc":[{"id":"1.231540820","rc":[{"batb":[[0,1.96,46.26],[1,1.32,3.28],[2,1.3,2.93]],"ltp":2.0,"tv":88.69,"id":2219}]}]}
{"op":"mcm","clk":"11801292640","pt":1723066245472,"mc":[{"id":"1.231540820","rc":[{"batb":[[0,1.97,10],[1,1.96,46.26],[2,1.32,3.28]],"ltp":2.0,"tv":88.69,"id":2219}]}]}
{"op":"mcm","clk":"11801292784","pt":1723066248798,"mc":[{"id":"1.231540820","rc":[{"batb":[[0,1.96,46.26],[1,1.32,3.28],[2,1.3,2.93]],"ltp":2.0,"tv":88.69,"id":2219}]}]}
{"op":"mcm","clk":"11801292921","pt":1723066251206,"mc":[{"id":"1.231540820","rc":[{"batb":[[0,1.97,10],[1,1.96,46.26],[2,1.32,3.28]],"ltp":2.0,"tv":88.69,"id":2219}]}]}
{"op":"mcm","clk":"11801293101","pt":1723066254694,"mc":[{"id":"1.231540820","rc":[{"batb":[[0,1.96,46.26],[1,1.32,3.28],[2,1.3,2.93]],"ltp":2.0,"tv":88.69,"id":2219}]}]}
{"op":"mcm","clk":"11801293263","pt":1723066258385,"mc":[{"id":"1.231540820","rc":[{"batb":[[0,1.97,10],[1,1.96,46.26],[2,1.32,3.28]],"ltp":2.0,"tv":88.69,"id":2219}]}]}
{"op":"mcm","clk":"11801293440","pt":1723066261929,"mc":[{"id":"1.231540820","rc":[{"batb":[[0,1.96,46.26],[1,1.32,3.28],[2,1.3,2.93]],"ltp":2.0,"tv":88.69,"id":2219}]}]}
{"op":"mcm","clk":"11801293686","pt":1723066266506,"mc":[{"id":"1.231540820","rc":[{"batb":[[0,1.97,10],[1,1.96,46.26],[2,1.32,3.28]],"ltp":2.0,"tv":88.69,"id":2219}]}]}
{"op":"mcm","clk":"11801293875","pt":1723066269944,"mc":[{"id":"1.231540820","rc":[{"batb":[[0,1.96,46.26],[1,1.32,3.28],[2,1.3,2.93]],"ltp":2.0,"tv":88.69,"id":2219}]}]}
{"op":"mcm","clk":"11801294010","pt":1723066272248,"mc":[{"id":"1.231540820","rc":[{"batb":[[0,1.97,10],[1,1.96,46.26],[2,1.32,3.28]],"ltp":2.0,"tv":88.69,"id":2219}]}]}
{"op":"mcm","clk":"11801294197","pt":1723066275433,"mc":[{"id":"1.231540820","rc":[{"batb":[[0,1.96,46.26],[1,1.32,3.28],[2,1.3,2.93]],"ltp":2.0,"tv":88.69,"id":2219}]}]}
{"op":"mcm","clk":"11801294315","pt":1723066277842,"mc":[{"id":"1.231540820","rc":[{"batb":[[0,1.97,10],[1,1.96,46.26],[2,1.32,3.28]],"ltp":2.0,"tv":88.69,"id":2219}]}]}
{"op":"mcm","clk":"11801294487","pt":1723066281325,"mc":[{"id":"1.231540820","rc":[{"batb":[[0,1.96,46.26],[1,1.32,3.28],[2,1.3,2.93]],"ltp":2.0,"tv":88.69,"id":2219}]}]}
{"op":"mcm","clk":"11801294600","pt":1723066284036,"mc":[{"id":"1.231540820","rc":[{"batb":[[0,1.97,10],[1,1.96,46.26],[2,1.32,3.28]],"ltp":2.0,"tv":88.69,"id":2219}]}]}
{"op":"mcm","clk":"11801294758","pt":1723066287534,"mc":[{"id":"1.231540820","rc":[{"batb":[[0,1.96,46.26],[1,1.32,3.28],[2,1.3,2.93]],"ltp":2.0,"tv":88.69,"id":2219}]}]}
{"op":"mcm","clk":"11801294881","pt":1723066289953,"mc":[{"id":"1.231540820","rc":[{"batb":[[0,1.97,10],[1,1.96,46.26],[2,1.32,3.28]],"ltp":2.0,"tv":88.69,"id":2219}]}]}
{"op":"mcm","clk":"11801295055","pt":1723066293349,"mc":[{"id":"1.231540820","rc":[{"batb":[[0,1.96,46.26],[1,1.32,3.28],[2,1.3,2.93]],"ltp":2.0,"tv":88.69,"id":2219}]}]}
{"op":"mcm","clk":"11801295198","pt":1723066296168,"mc":[{"id":"1.231540820","rc":[{"batb":[[0,1.97,10],[1,1.96,46.26],[2,1.32,3.28]],"ltp":2.0,"tv":88.69,"id":2219}]}]}
{"op":"mcm","clk":"11801295333","pt":1723066299557,"mc":[{"id":"1.231540820","rc":[{"batb":[[0,1.96,46.26],[1,1.32,3.28],[2,1.3,2.93]],"ltp":2.0,"tv":88.69,"id":2219}]}]}
{"op":"mcm","clk":"11801295461","pt":1723066302171,"mc":[{"id":"1.231540820","rc":[{"batb":[[0,1.97,10],[1,1.96,46.26],[2,1.32,3.28]],"ltp":2.0,"tv":88.69,"id":2219}]}]}
{"op":"mcm","clk":"11801295621","pt":1723066305558,"mc":[{"id":"1.231540820","rc":[{"batb":[[0,1.96,46.26],[1,1.32,3.28],[2,1.3,2.93]],"ltp":2.0,"tv":88.69,"id":2219}]}]}
{"op":"mcm","clk":"11801295763","pt":1723066308644,"mc":[{"id":"1.231540820","rc":[{"batb":[[0,1.97,10],[1,1.96,46.26],[2,1.32,3.28]],"ltp":2.0,"tv":88.69,"id":2219}]}]}
{"op":"mcm","clk":"11801295918","pt":1723066312074,"mc":[{"id":"1.231540820","rc":[{"batb":[[0,1.96,46.26],[1,1.32,3.28],[2,1.3,2.93]],"ltp":2.0,"tv":88.69,"id":2219}]}]}
{"op":"mcm","clk":"11801296088","pt":1723066316175,"mc":[{"id":"1.231540820","rc":[{"batb":[[0,1.97,10],[1,1.96,46.26],[2,1.32,3.28]],"ltp":2.0,"tv":88.69,"id":2219}]}]}
{"op":"mcm","clk":"11801296249","pt":1723066319673,"mc":[{"id":"1.231540820","rc":[{"batb":[[0,1.96,46.26],[1,1.32,3.28],[2,1.3,2.93]],"ltp":2.0,"tv":88.69,"id":2219}]}]}
{"op":"mcm","clk":"11801296386","pt":1723066322961,"mc":[{"id":"1.231540820","rc":[{"batb":[[0,1.97,10],[1,1.96,46.26],[2,1.32,3.28]],"ltp":2.0,"tv":88.69,"id":2219}]}]}
{"op":"mcm","clk":"11801296507","pt":1723066326182,"mc":[{"id":"1.231540820","rc":[{"batb":[[0,1.96,46.26],[1,1.32,3.28],[2,1.3,2.93]],"ltp":2.0,"tv":88.69,"id":2219}]}]}
{"op":"mcm","clk":"11801296619","pt":1723066328393,"mc":[{"id":"1.231540820","rc":[{"batb":[[0,1.97,10],[1,1.96,46.26],[2,1.32,3.28]],"ltp":2.0,"tv":88.69,"id":2219}]}]}
{"op":"mcm","clk":"11801296773","pt":1723066331981,"mc":[{"id":"1.231540820","rc":[{"batb":[[0,1.96,46.26],[1,1.32,3.28],[2,1.3,2.93]],"ltp":2.0,"tv":88.69,"id":2219}]}]}
{"op":"mcm","clk":"11801296942","pt":1723066335270,"mc":[{"id":"1.231540820","rc":[{"batb":[[0,1.97,10],[1,1.96,46.26],[2,1.32,3.28]],"ltp":2.0,"tv":88.69,"id":2219}]}]}
{"op":"mcm","clk":"11801297103","pt":1723066338702,"mc":[{"id":"1.231540820","rc":[{"batb":[[0,1.96,46.26],[1,1.32,3.28],[2,1.3,2.93]],"ltp":2.0,"tv":88.69,"id":2219}]}]}
{"op":"mcm","clk":"11801297266","pt":1723066341886,"mc":[{"id":"1.231540820","rc":[{"batb":[[0,1.97,10],[1,1.96,46.26],[2,1.32,3.28]],"ltp":2.0,"tv":88.69,"id":2219}]}]}
{"op":"mcm","clk":"11801297380","pt":1723066345223,"mc":[{"id":"1.231540820","rc":[{"batb":[[0,1.96,46.26],[1,1.32,3.28],[2,1.3,2.93]],"ltp":2.0,"tv":88.69,"id":2219}]}]}
{"op":"mcm","clk":"11801297501","pt":1723066348200,"mc":[{"id":"1.231540820","rc":[{"batb":[[0,1.97,10],[1,1.96,46.26],[2,1.32,3.28]],"ltp":2.0,"tv":88.69,"id":2219}]}]}
{"op":"mcm","clk":"11801297668","pt":1723066351995,"mc":[{"id":"1.231540820","rc":[{"batb":[[0,1.96,46.26],[1,1.32,3.28],[2,1.3,2.93]],"ltp":2.0,"tv":88.69,"id":2219}]}]}
{"op":"mcm","clk":"11801297778","pt":1723066354613,"mc":[{"id":"1.231540820","rc":[{"batb":[[0,1.97,10],[1,1.96,46.26],[2,1.32,3.28]],"ltp":2.0,"tv":88.69,"id":2219}]}]}
{"op":"mcm","clk":"11801297908","pt":1723066358101,"mc":[{"id":"1.231540820","rc":[{"batb":[[0,1.96,46.26],[1,1.32,3.28],[2,1.3,2.93]],"ltp":2.0,"tv":88.69,"id":2219}]}]}
{"op":"mcm","clk":"11801298031","pt":1723066360817,"mc":[{"id":"1.231540820","rc":[{"batb":[[0,1.97,10],[1,1.96,46.26],[2,1.32,3.28]],"ltp":2.0,"tv":88.69,"id":2219}]}]}
{"op":"mcm","clk":"11801298174","pt":1723066364212,"mc":[{"id":"1.231540820","rc":[{"batb":[[0,1.96,46.26],[1,1.32,3.28],[2,1.3,2.93]],"ltp":2.0,"tv":88.69,"id":2219}]}]}
{"op":"mcm","clk":"11801298296","pt":1723066366923,"mc":[{"id":"1.231540820","rc":[{"batb":[[0,1.97,10],[1,1.96,46.26],[2,1.32,3.28]],"ltp":2.0,"tv":88.69,"id":2219}]}]}
{"op":"mcm","clk":"11801298429","pt":1723066370413,"mc":[{"id":"1.231540820","rc":[{"batb":[[0,1.96,46.26],[1,1.32,3.28],[2,1.3,2.93]],"ltp":2.0,"tv":88.69,"id":2219}]}]}
{"op":"mcm","clk":"11801298582","pt":1723066374618,"mc":[{"id":"1.231540820","rc":[{"batb":[[0,1.97,10],[1,1.96,46.26],[2,1.32,3.28]],"ltp":2.0,"tv":88.69,"id":2219}]}]}
{"op":"mcm","clk":"11801298742","pt":1723066378049,"mc":[{"id":"1.231540820","rc":[{"batb":[[0,1.96,46.26],[1,1.32,3.28],[2,1.3,2.93]],"ltp":2.0,"tv":88.69,"id":2219}]}]}
{"op":"mcm","clk":"11801298839","pt":1723066380352,"mc":[{"id":"1.231540820","rc":[{"batb":[[0,1.97,10],[1,1.96,46.26],[2,1.32,3.28]],"ltp":2.0,"tv":88.69,"id":2219}]}]}
{"op":"mcm","clk":"11801298998","pt":1723066383948,"mc":[{"id":"1.231540820","rc":[{"batb":[[0,1.96,46.26],[1,1.32,3.28],[2,1.3,2.93]],"ltp":2.0,"tv":88.69,"id":2219}]}]}
{"op":"mcm","clk":"11801299135","pt":1723066387134,"mc":[{"id":"1.231540820","rc":[{"batb":[[0,1.97,10],[1,1.96,46.26],[2,1.32,3.28]],"ltp":2.0,"tv":88.69,"id":2219}]}]}
{"op":"mcm","clk":"11801299275","pt":1723066390628,"mc":[{"id":"1.231540820","rc":[{"batb":[[0,1.96,46.26],[1,1.32,3.28],[2,1.3,2.93]],"ltp":2.0,"tv":88.69,"id":2219}]}]}
{"op":"mcm","clk":"11801299388","pt":1723066393145,"mc":[{"id":"1.231540820","rc":[{"batb":[[0,1.97,10],[1,1.96,46.26],[2,1.32,3.28]],"ltp":2.0,"tv":88.69,"id":2219}]}]}
{"op":"mcm","clk":"11801299556","pt":1723066396777,"mc":[{"id":"1.231540820","rc":[{"batb":[[0,1.96,46.26],[1,1.32,3.28],[2,1.3,2.93]],"ltp":2.0,"tv":88.69,"id":2219}]}]}
{"op":"mcm","clk":"11801299713","pt":1723066399546,"mc":[{"id":"1.231540820","rc":[{"batb":[[0,1.97,10],[1,1.96,46.26],[2,1.32,3.28]],"ltp":2.0,"tv":88.69,"id":2219}]}]}
{"op":"mcm","clk":"11801299861","pt":1723066403189,"mc":[{"id":"1.231540820","rc":[{"batb":[[0,1.96,46.26],[1,1.32,3.28],[2,1.3,2.93]],"ltp":2.0,"tv":88.69,"id":2219}]}]}
{"op":"mcm","clk":"11801299960","pt":1723066405755,"mc":[{"id":"1.231540820","rc":[{"batb":[[0,1.97,10],[1,1.96,46.26],[2,1.32,3.28]],"ltp":2.0,"tv":88.69,"id":2219}]}]}
{"op":"mcm","clk":"11801300159","pt":1723066409290,"mc":[{"id":"1.231540820","rc":[{"batb":[[0,1.96,46.26],[1,1.32,3.28],[2,1.3,2.93]],"ltp":2.0,"tv":88.69,"id":2219}]}]}
{"op":"mcm","clk":"11801300271","pt":1723066411700,"mc":[{"id":"1.231540820","rc":[{"batb":[[0,1.97,10],[1,1.96,46.26],[2,1.32,3.28]],"ltp":2.0,"tv":88.69,"id":2219}]}]}
{"op":"mcm","clk":"11801300422","pt":1723066415392,"mc":[{"id":"1.231540820","rc":[{"batb":[[0,1.96,46.26],[1,1.32,3.28],[2,1.3,2.93]],"ltp":2.0,"tv":88.69,"id":2219}]}]}
{"op":"mcm","clk":"11801300537","pt":1723066418364,"mc":[{"id":"1.231540820","rc":[{"batb":[[0,1.97,10],[1,1.96,46.26],[2,1.32,3.28]],"ltp":2.0,"tv":88.69,"id":2219}]}]}
{"op":"mcm","clk":"11801300688","pt":1723066421794,"mc":[{"id":"1.231540820","rc":[{"batb":[[0,1.96,46.26],[1,1.32,3.28],[2,1.3,2.93]],"ltp":2.0,"tv":88.69,"id":2219}]}]}
{"op":"mcm","clk":"11801300848","pt":1723066424976,"mc":[{"id":"1.231540820","rc":[{"batb":[[0,1.97,10],[1,1.96,46.26],[2,1.32,3.28]],"ltp":2.0,"tv":88.69,"id":2219}]}]}
{"op":"mcm","clk":"11801301022","pt":1723066428564,"mc":[{"id":"1.231540820","rc":[{"batb":[[0,1.96,46.26],[1,1.32,3.28],[2,1.3,2.93]],"ltp":2.0,"tv":88.69,"id":2219}]}]}
{"op":"mcm","clk":"11801301122","pt":1723066430976,"mc":[{"id":"1.231540820","rc":[{"batb":[[0,1.97,10],[1,1.96,46.26],[2,1.32,3.28]],"ltp":2.0,"tv":88.69,"id":2219}]}]}
{"op":"mcm","clk":"11801301344","pt":1723066436003,"mc":[{"id":"1.231540820","rc":[{"batb":[[0,1.96,46.26],[1,1.32,3.28],[2,1.3,2.93]],"ltp":2.0,"tv":88.69,"id":2219}]}]}
{"op":"mcm","clk":"11801301462","pt":1723066438419,"mc":[{"id":"1.231540820","rc":[{"batb":[[0,1.97,10],[1,1.96,46.26],[2,1.32,3.28]],"ltp":2.0,"tv":88.69,"id":2219}]}]}
{"op":"mcm","clk":"11801301623","pt":1723066441914,"mc":[{"id":"1.231540820","rc":[{"batb":[[0,1.96,46.26],[1,1.32,3.28],[2,1.3,2.93]],"ltp":2.0,"tv":88.69,"id":2219}]}]}
{"op":"mcm","clk":"11801301738","pt":1723066444380,"mc":[{"id":"1.231540820","rc":[{"batb":[[0,1.97,10],[1,1.96,46.26],[2,1.32,3.28]],"ltp":2.0,"tv":88.69,"id":2219}]}]}
{"op":"mcm","clk":"11801301892","pt":1723066447708,"mc":[{"id":"1.231540820","rc":[{"batb":[[0,1.96,46.26],[1,1.32,3.28],[2,1.3,2.93]],"ltp":2.0,"tv":88.69,"id":2219}]}]}
{"op":"mcm","clk":"11801302026","pt":1723066450480,"mc":[{"id":"1.231540820","rc":[{"batb":[[0,1.97,10],[1,1.96,46.26],[2,1.32,3.28]],"ltp":2.0,"tv":88.69,"id":2219}]}]}
{"op":"mcm","clk":"11801302183","pt":1723066453806,"mc":[{"id":"1.231540820","rc":[{"batb":[[0,1.96,46.26],[1,1.32,3.28],[2,1.3,2.93]],"ltp":2.0,"tv":88.69,"id":2219}]}]}
{"op":"mcm","clk":"11801302380","pt":1723066457496,"mc":[{"id":"1.231540820","rc":[{"batb":[[0,1.97,10],[1,1.96,46.26],[2,1.32,3.28]],"ltp":2.0,"tv":88.69,"id":2219}]}]}
{"op":"mcm","clk":"11801302615","pt":1723066462413,"mc":[{"id":"1.231540820","rc":[{"batb":[[0,1.96,46.26],[1,1.32,3.28],[2,1.3,2.93]],"ltp":2.0,"tv":88.69,"id":2219}]}]}
{"op":"mcm","clk":"11801302760","pt":1723066465133,"mc":[{"id":"1.231540820","rc":[{"batb":[[0,1.97,10],[1,1.96,46.26],[2,1.32,3.28]],"ltp":2.0,"tv":88.69,"id":2219}]}]}
{"op":"mcm","clk":"11801302934","pt":1723066468415,"mc":[{"id":"1.231540820","rc":[{"batb":[[0,1.96,46.26],[1,1.32,3.28],[2,1.3,2.93]],"ltp":2.0,"tv":88.69,"id":2219}]}]}
{"op":"mcm","clk":"11801303093","pt":1723066471444,"mc":[{"id":"1.231540820","rc":[{"batb":[[0,1.97,10],[1,1.96,46.26],[2,1.32,3.28]],"ltp":2.0,"tv":88.69,"id":2219}]}]}
{"op":"mcm","clk":"11801303304","pt":1723066474736,"mc":[{"id":"1.231540820","rc":[{"batb":[[0,1.96,46.26],[1,1.32,3.28],[2,1.3,2.93]],"ltp":2.0,"tv":88.69,"id":2219}]}]}
{"op":"mcm","clk":"11801303423","pt":1723066477505,"mc":[{"id":"1.231540820","rc":[{"batb":[[0,1.97,10],[1,1.96,46.26],[2,1.32,3.28]],"ltp":2.0,"tv":88.69,"id":2219}]}]}
{"op":"mcm","clk":"11801303549","pt":1723066480941,"mc":[{"id":"1.231540820","rc":[{"batb":[[0,1.96,46.26],[1,1.32,3.28],[2,1.3,2.93]],"ltp":2.0,"tv":88.69,"id":2219}]}]}
{"op":"mcm","clk":"11801303648","pt":1723066483152,"mc":[{"id":"1.231540820","rc":[{"batb":[[0,1.97,10],[1,1.96,46.26],[2,1.32,3.28]],"ltp":2.0,"tv":88.69,"id":2219}]}]}
{"op":"mcm","clk":"11801303823","pt":1723066486637,"mc":[{"id":"1.231540820","rc":[{"batb":[[0,1.96,46.26],[1,1.32,3.28],[2,1.3,2.93]],"ltp":2.0,"tv":88.69,"id":2219}]}]}
{"op":"mcm","clk":"11801303958","pt":1723066489712,"mc":[{"id":"1.231540820","rc":[{"batb":[[0,1.97,10],[1,1.96,46.26],[2,1.32,3.28]],"ltp":2.0,"tv":88.69,"id":2219}]}]}
{"op":"mcm","clk":"11801304120","pt":1723066493348,"mc":[{"id":"1.231540820","rc":[{"batb":[[0,1.96,46.26],[1,1.32,3.28],[2,1.3,2.93]],"ltp":2.0,"tv":88.69,"id":2219}]}]}
{"op":"mcm","clk":"11801304240","pt":1723066496267,"mc":[{"id":"1.231540820","rc":[{"batb":[[0,1.97,10],[1,1.96,46.26],[2,1.32,3.28]],"ltp":2.0,"tv":88.69,"id":2219}]}]}
{"op":"mcm","clk":"11801304430","pt":1723066500066,"mc":[{"id":"1.231540820","rc":[{"batb":[[0,1.96,46.26],[1,1.32,3.28],[2,1.3,2.93]],"ltp":2.0,"tv":88.69,"id":2219}]}]}
{"op":"mcm","clk":"11801304574","pt":1723066502538,"mc":[{"id":"1.231540820","rc":[{"batb":[[0,1.97,10],[1,1.96,46.26],[2,1.32,3.28]],"ltp":2.0,"tv":88.69,"id":2219}]}]}
{"op":"mcm","clk":"11801304779","pt":1723066506033,"mc":[{"id":"1.231540820","rc":[{"batb":[[0,1.96,46.26],[1,1.32,3.28],[2,1.3,2.93]],"ltp":2.0,"tv":88.69,"id":2219}]}]}
{"op":"mcm","clk":"11801304991","pt":1723066509676,"mc":[{"id":"1.231540820","rc":[{"batb":[[0,1.97,10],[1,1.96,46.26],[2,1.32,3.28]],"ltp":2.0,"tv":88.69,"id":2219}]}]}
{"op":"mcm","clk":"11801305148","pt":1723066512857,"mc":[{"id":"1.231540820","rc":[{"batb":[[0,1.96,46.26],[1,1.32,3.28],[2,1.3,2.93]],"ltp":2.0,"tv":88.69,"id":2219}]}]}
{"op":"mcm","clk":"11801305331","pt":1723066516250,"mc":[{"id":"1.231540820","rc":[{"batb":[[0,1.97,10],[1,1.96,46.26],[2,1.32,3.28]],"ltp":2.0,"tv":88.69,"id":2219}]}]}
{"op":"mcm","clk":"11801305526","pt":1723066519581,"mc":[{"id":"1.231540820","rc":[{"batb":[[0,1.96,46.26],[1,1.32,3.28],[2,1.3,2.93]],"ltp":2.0,"tv":88.69,"id":2219}]}]}
{"op":"mcm","clk":"11801305703","pt":1723066523298,"mc":[{"id":"1.231540820","rc":[{"batb":[[0,1.97,10],[1,1.96,46.26],[2,1.32,3.28]],"ltp":2.0,"tv":88.69,"id":2219}]}]}
{"op":"mcm","clk":"11801305857","pt":1723066526681,"mc":[{"id":"1.231540820","rc":[{"batb":[[0,1.96,46.26],[1,1.32,3.28],[2,1.3,2.93]],"ltp":2.0,"tv":88.69,"id":2219}]}]}
{"op":"mcm","clk":"11801306125","pt":1723066532792,"mc":[{"id":"1.231540820","rc":[{"batb":[[0,1.97,10],[1,1.96,46.26],[2,1.32,3.28]],"ltp":2.0,"tv":88.69,"id":2219}]}]}
{"op":"mcm","clk":"11801306304","pt":1723066536489,"mc":[{"id":"1.231540820","rc":[{"batb":[[0,1.96,46.26],[1,1.32,3.28],[2,1.3,2.93]],"ltp":2.0,"tv":88.69,"id":2219}]}]}
{"op":"mcm","clk":"11801306408","pt":1723066538897,"mc":[{"id":"1.231540820","rc":[{"batb":[[0,1.97,10],[1,1.96,46.26],[2,1.32,3.28]],"ltp":2.0,"tv":88.69,"id":2219}]}]}
{"op":"mcm","clk":"11801306570","pt":1723066542492,"mc":[{"id":"1.231540820","rc":[{"batb":[[0,1.96,46.26],[1,1.32,3.28],[2,1.3,2.93]],"ltp":2.0,"tv":88.69,"id":2219}]}]}
{"op":"mcm","clk":"11801306727","pt":1723066545680,"mc":[{"id":"1.231540820","rc":[{"batb":[[0,1.97,10],[1,1.96,46.26],[2,1.32,3.28]],"ltp":2.0,"tv":88.69,"id":2219}]}]}
{"op":"mcm","clk":"11801306960","pt":1723066549380,"mc":[{"id":"1.231540820","rc":[{"batb":[[0,1.96,46.26],[1,1.32,3.28],[2,1.3,2.93]],"ltp":2.0,"tv":88.69,"id":2219}]}]}
{"op":"mcm","clk":"11801307094","pt":1723066551895,"mc":[{"id":"1.231540820","rc":[{"batb":[[0,1.97,10],[1,1.96,46.26],[2,1.32,3.28]],"ltp":2.0,"tv":88.69,"id":2219}]}]}
{"op":"mcm","clk":"11801307249","pt":1723066555485,"mc":[{"id":"1.231540820","rc":[{"batb":[[0,1.96,46.26],[1,1.32,3.28],[2,1.3,2.93]],"ltp":2.0,"tv":88.69,"id":2219}]}]}
{"op":"mcm","clk":"11801307381","pt":1723066557902,"mc":[{"id":"1.231540820","rc":[{"batb":[[0,1.97,10],[1,1.96,46.26],[2,1.32,3.28]],"ltp":2.0,"tv":88.69,"id":2219}]}]}
{"op":"mcm","clk":"11801307541","pt":1723066561387,"mc":[{"id":"1.231540820","rc":[{"batb":[[0,1.96,46.26],[1,1.32,3.28],[2,1.3,2.93]],"ltp":2.0,"tv":88.69,"id":2219}]}]}
{"op":"mcm","clk":"11801307657","pt":1723066563697,"mc":[{"id":"1.231540820","rc":[{"batb":[[0,1.97,10],[1,1.96,46.26],[2,1.32,3.28]],"ltp":2.0,"tv":88.69,"id":2219}]}]}
{"op":"mcm","clk":"11801307834","pt":1723066567333,"mc":[{"id":"1.231540820","rc":[{"batb":[[0,1.96,46.26],[1,1.32,3.28],[2,1.3,2.93]],"ltp":2.0,"tv":88.69,"id":2219}]}]}
{"op":"mcm","clk":"11801307952","pt":1723066569798,"mc":[{"id":"1.231540820","rc":[{"batb":[[0,1.97,10],[1,1.96,46.26],[2,1.32,3.28]],"ltp":2.0,"tv":88.69,"id":2219}]}]}
{"op":"mcm","clk":"11801308116","pt":1723066573134,"mc":[{"id":"1.231540820","rc":[{"batb":[[0,1.96,46.26],[1,1.32,3.28],[2,1.3,2.93]],"ltp":2.0,"tv":88.69,"id":2219}]}]}
