{"op":"mcm","clk":"11888405514","pt":1724157426719,"mc":[{"id":"1.232049325","marketDefinition":{"bspMarket":false,"turnInPlayEnabled":true,"persistenceEnabled":true,"marketBaseRate":5.0,"eventId":"33511213","eventTypeId":"4","numberOfWinners":1,"bettingType":"ODDS","marketType":"MATCH_ODDS","marketTime":"2024-08-21T21:15:00.000Z","suspendTime":"2024-08-21T21:15:00.000Z","bspReconciled":false,"complete":true,"inPlay":false,"crossMatching":true,"runnersVoidable":false,"numberOfActiveRunners":2,"betDelay":0,"status":"OPEN","runners":[{"status":"ACTIVE","sortPriority":1,"id":67083366,"name":"New York Strikers"},{"status":"ACTIVE","sortPriority":2,"id":72857115,"name":"Miami Lions"}],"regulators":["MR_INT"],"countryCode":"GB","discountAllowed":false,"timezone":"GMT","openDate":"2024-08-21T21:15:00.000Z","version":6087505565,"name":"Match Odds","eventName":"New York Strikers v Miami Lions"},"rc":[{"batb":[[0,1.01,20]],"ltp":0.0,"tv":0.0,"id":67083366},{"batb":[[0,1.01,20]],"ltp":0.0,"tv":0.0,"id":72857115}]}]}
{"op":"mcm","clk":"11888405572","pt":1724157427804,"mc":[{"id":"1.232049325","rc":[{"batb":[[0,1.03,200],[1,1.02,200],[2,1.01,220]],"ltp":0.0,"tv":0.0,"id":67083366},{"batb":[[0,1.03,200],[1,1.02,200],[2,1.01,220]],"ltp":0.0,"tv":0.0,"id":72857115}]}]}
{"op":"mcm","clk":"11888405609","pt":1724157428590,"mc":[{"id":"1.232049325","marketDefinition":{"bspMarket":false,"turnInPlayEnabled":true,"persistenceEnabled":true,"marketBaseRate":5.0,"eventId":"33511213","eventTypeId":"4","numberOfWinners":1,"bettingType":"ODDS","marketType":"MATCH_ODDS","marketTime":"2024-08-21T21:15:00.000Z","suspendTime":"2024-08-21T21:15:00.000Z","bspReconciled":false,"complete":true,"inPlay":false,"crossMatching":true,"runnersVoidable":false,"numberOfActiveRunners":2,"betDelay":0,"status":"OPEN","runners":[{"status":"ACTIVE","sortPriority":1,"id":67083366,"name":"New York Strikers"},{"status":"ACTIVE","sortPriority":2,"id":72857115,"name":"Miami Lions"}],"regulators":["MR_INT"],"countryCode":"GB","discountAllowed":true,"timezone":"GMT","openDate":"2024-08-21T21:15:00.000Z","version":6087505565,"name":"Match Odds","eventName":"New York Strikers v Miami Lions"}}]}
{"op":"mcm","clk":"11888561850","pt":1724160657571,"mc":[{"id":"1.232049325","rc":[{"batb":[[2,1.01,481.95]],"ltp":0.0,"tv":0.0,"id":67083366}]}]}
{"op":"mcm","clk":"11888561859","pt":1724160657777,"mc":[{"id":"1.232049325","rc":[{"batb":[[2,1.01,481.95]],"ltp":0.0,"tv":0.0,"id":72857115}]}]}
{"op":"mcm","clk":"11888937413","pt":1724166775131,"mc":[{"id":"1.232049325","rc":[{"batb":[[2,1.01,482.36]],"ltp":0.0,"tv":0.0,"id":67083366},{"batb":[[2,1.01,482.36]],"ltp":0.0,"tv":0.0,"id":72857115}]}]}
{"op":"mcm","clk":"11889036938","pt":1724167951445,"mc":[{"id":"1.232049325","rc":[{"batb":[[0,1.43,116.28],[1,1.33,151.52],[2,1.28,178.57]],"ltp":0.0,"tv":0.0,"id":67083366},{"batb":[[0,1.43,116.28],[1,1.33,151.52],[2,1.28,178.57]],"ltp":0.0,"tv":0.0,"id":72857115}]}]}
{"op":"mcm","clk":"11889128927","pt":1724168989463,"mc":[{"id":"1.232049325","rc":[{"batb":[[0,1.44,6.03],[1,1.43,116.28],[2,1.33,151.52]],"ltp":0.0,"tv":0.0,"id":67083366}]}]}
{"op":"mcm","clk":"11889128950","pt":1724168989669,"mc":[{"id":"1.232049325","rc":[{"batb":[[0,1.44,6.98],[1,1.43,116.28],[2,1.33,151.52]],"ltp":0.0,"tv":0.0,"id":72857115}]}]}
{"op":"mcm","clk":"11889158766","pt":1724169296911,"mc":[{"id":"1.232049325","rc":[{"batb":[[0,1.44,12.04]],"ltp":0.0,"tv":0.0,"id":67083366},{"batb":[[0,1.44,13.03]],"ltp":0.0,"tv":0.0,"id":72857115}]}]}
{"op":"mcm","clk":"11889423959","pt":1724172175126,"mc":[{"id":"1.232049325","rc":[{"batb":[[0,1.44,12.04]],"ltp":0.0,"tv":0.0,"id":67083366},{"batb":[[0,1.44,13.03]],"ltp":0.0,"tv":0.0,"id":72857115}]}]}
{"op":"mcm","clk":"11890104594","pt":1724177575113,"mc":[{"id":"1.232049325","rc":[{"batb":[[0,1.44,12.05]],"ltp":0.0,"tv":0.0,"id":67083366},{"batb":[[0,1.44,13.04]],"ltp":0.0,"tv":0.0,"id":72857115}]}]}
{"op":"mcm","clk":"11890948896","pt":1724182490533,"mc":[{"id":"1.232049325","rc":[{"batb":[[0,1.44,12.04]],"ltp":0.0,"tv":0.0,"id":67083366},{"batb":[[0,1.44,13.04]],"ltp":0.0,"tv":0.0,"id":72857115}]}]}
{"op":"mcm","clk":"11891957101","pt":1724193775198,"mc":[{"id":"1.232049325","rc":[{"batb":[[0,1.44,12.04]],"ltp":0.0,"tv":0.0,"id":67083366},{"batb":[[0,1.44,13.04]],"ltp":0.0,"tv":0.0,"id":72857115}]}]}
{"op":"mcm","clk":"11892262319","pt":1724199175215,"mc":[{"id":"1.232049325","rc":[{"batb":[[0,1.44,12.04]],"ltp":0.0,"tv":0.0,"id":67083366},{"batb":[[0,1.44,13.04]],"ltp":0.0,"tv":0.0,"id":72857115}]}]}
{"op":"mcm","clk":"11892572227","pt":1724204575196,"mc":[{"id":"1.232049325","rc":[{"batb":[[0,1.44,12.04]],"ltp":0.0,"tv":0.0,"id":67083366},{"batb":[[0,1.44,13.03]],"ltp":0.0,"tv":0.0,"id":72857115}]}]}
{"op":"mcm","clk":"11892799229","pt":1724209975225,"mc":[{"id":"1.232049325","rc":[{"batb":[[0,1.44,12.04]],"ltp":0.0,"tv":0.0,"id":67083366},{"batb":[[0,1.44,13.04]],"ltp":0.0,"tv":0.0,"id":72857115}]}]}
{"op":"mcm","clk":"11893078003","pt":1724215220902,"mc":[{"id":"1.232049325","rc":[{"batb":[[0,1.44,12.98]],"ltp":0.0,"tv":0.0,"id":67083366}]}]}
{"op":"mcm","clk":"11893078561","pt":1724215230509,"mc":[{"id":"1.232049325","rc":[{"batb":[[0,1.44,13.98]],"ltp":0.0,"tv":0.0,"id":72857115}]}]}
{"op":"mcm","clk":"11893298154","pt":1724219809845,"mc":[{"id":"1.232049325","rc":[{"batb":[[0,1.54,1.47],[1,1.44,12.04],[2,1.43,116.28]],"ltp":0.0,"tv":0.0,"id":67083366}]}]}
{"op":"mcm","clk":"11893298464","pt":1724219818421,"mc":[{"id":"1.232049325","rc":[{"batb":[[0,1.54,1.47],[1,1.44,13.04],[2,1.43,116.28]],"ltp":0.0,"tv":0.0,"id":72857115}]}]}
{"op":"mcm","clk":"11893359700","pt":1724220775143,"mc":[{"id":"1.232049325","rc":[{"batb":[[1,1.44,12.05]],"ltp":0.0,"tv":0.0,"id":67083366},{"batb":[[1,1.44,13.04]],"ltp":0.0,"tv":0.0,"id":72857115}]}]}
{"op":"mcm","clk":"11893611698","pt":1724226175200,"mc":[{"id":"1.232049325","rc":[{"batb":[[1,1.44,12.05]],"ltp":0.0,"tv":0.0,"id":67083366},{"batb":[[1,1.44,13.05]],"ltp":0.0,"tv":0.0,"id":72857115}]}]}
{"op":"mcm","clk":"11893789517","pt":1724229780418,"mc":[{"id":"1.232049325","rc":[{"batb":[[1,1.45,19.07],[2,1.44,12.05]],"ltp":0.0,"tv":0.0,"id":67083366},{"batb":[[1,1.45,19.07],[2,1.44,13.05]],"ltp":0.0,"tv":0.0,"id":72857115}]}]}
{"op":"mcm","clk":"11893789646","pt":1724229782435,"mc":[{"id":"1.232049325","rc":[{"batb":[[2,1.44,6.04]],"ltp":0.0,"tv":0.0,"id":67083366},{"batb":[[2,1.44,6.98]],"ltp":0.0,"tv":0.0,"id":72857115}]}]}
{"op":"mcm","clk":"11893897909","pt":1724231575120,"mc":[{"id":"1.232049325","rc":[{"batb":[[1,1.45,19.08]],"ltp":0.0,"tv":0.0,"id":67083366},{"batb":[[1,1.45,19.08]],"ltp":0.0,"tv":0.0,"id":72857115}]}]}
{"op":"mcm","clk":"11893899111","pt":1724231580841,"mc":[{"id":"1.232049325","rc":[{"batb":[[1,1.44,6.04],[2,1.43,116.28]],"ltp":0.0,"tv":0.0,"id":67083366},{"batb":[[1,1.44,6.98],[2,1.43,116.28]],"ltp":0.0,"tv":0.0,"id":72857115}]}]}
{"op":"mcm","clk":"11893899563","pt":1724231587837,"mc":[{"id":"1.232049325","rc":[{"batb":[[1,1.44,12.11]],"ltp":0.0,"tv":0.0,"id":67083366},{"batb":[[1,1.44,13.11]],"ltp":0.0,"tv":0.0,"id":72857115}]}]}
{"op":"mcm","clk":"11893902017","pt":1724231630692,"mc":[{"id":"1.232049325","rc":[{"batb":[[1,1.45,19.08],[2,1.44,12.11]],"ltp":0.0,"tv":0.0,"id":67083366},{"batb":[[1,1.45,19.08],[2,1.44,13.11]],"ltp":0.0,"tv":0.0,"id":72857115}]}]}
{"op":"mcm","clk":"11893902162","pt":1724231633432,"mc":[{"id":"1.232049325","rc":[{"batb":[[2,1.44,6.04]],"ltp":0.0,"tv":0.0,"id":67083366},{"batb":[[2,1.44,6.98]],"ltp":0.0,"tv":0.0,"id":72857115}]}]}
{"op":"mcm","clk":"11893969609","pt":1724232616918,"mc":[{"id":"1.232049325","rc":[{"batb":[[0,1.45,20.02],[1,1.44,6.04],[2,1.04,1.53]],"ltp":0.0,"tv":0.0,"id":67083366}]}]}
{"op":"mcm","clk":"11893971158","pt":1724232640538,"mc":[{"id":"1.232049325","rc":[{"batb":[[0,1.45,20.02],[1,1.44,6.98],[2,1.04,1.53]],"ltp":0.0,"tv":0.0,"id":72857115}]}]}
{"op":"mcm","clk":"11894024982","pt":1724233431164,"mc":[{"id":"1.232049325","rc":[{"batb":[[0,1.44,6.98],[1,1.04,1.53],[2,1.03,200]],"ltp":0.0,"tv":0.0,"id":67083366},{"batb":[[0,1.44,7.92],[1,1.04,1.53],[2,1.03,200]],"ltp":0.0,"tv":0.0,"id":72857115}]}]}
{"op":"mcm","clk":"11894027909","pt":1724233473615,"mc":[{"id":"1.232049325","rc":[{"batb":[[0,1.45,20.02],[1,1.44,6.04],[2,1.04,1.53]],"ltp":0.0,"tv":0.0,"id":67083366},{"batb":[[0,1.45,20.02],[1,1.44,6.98],[2,1.04,1.53]],"ltp":0.0,"tv":0.0,"id":72857115}]}]}
{"op":"mcm","clk":"11894113829","pt":1724234626484,"mc":[{"id":"1.232049325","rc":[{"batb":[[0,1.45,20],[1,1.04,1.53],[2,1.03,200]],"ltp":0.0,"tv":0.0,"id":67083366},{"batb":[[0,1.45,20],[1,1.04,1.53],[2,1.03,200]],"ltp":0.0,"tv":0.0,"id":72857115}]}]}
{"op":"mcm","clk":"11894171178","pt":1724235273956,"mc":[{"id":"1.232049325","rc":[{"batb":[[0,1.04,2.47],[1,1.03,200],[2,1.02,200]],"ltp":0.0,"tv":0.0,"id":67083366},{"batb":[[0,1.04,2.47],[1,1.03,200],[2,1.02,200]],"ltp":0.0,"tv":0.0,"id":72857115}]}]}
{"op":"mcm","clk":"11894190616","pt":1724235483394,"mc":[{"id":"1.232049325","rc":[{"trd":[[1.03,1.06],[1.04,3.06],[1.58,1.88]],"batb":[[0,1.02,200],[1,1.01,483.09],[2,1.02,0]],"ltp":1.03,"tv":5.99,"id":67083366}],"tv":5.99}]}
{"op":"mcm","clk":"11894195050","pt":1724235532857,"mc":[{"id":"1.232049325","rc":[{"batb":[[0,1.04,2.47],[1,1.02,200],[2,1.01,483.09]],"ltp":1.03,"tv":5.99,"id":67083366}]}]}
{"op":"mcm","clk":"11894200370","pt":1724235588500,"mc":[{"id":"1.232049325","rc":[{"batl":[[0,5,0.94]],"ltp":1.03,"tv":5.99,"id":67083366}]}]}
{"op":"mcm","clk":"11894201714","pt":1724235604418,"mc":[{"id":"1.232049325","rc":[{"batl":[[0,5,1.88]],"ltp":1.03,"tv":5.99,"id":67083366}]}]}
{"op":"mcm","clk":"11894201897","pt":1724235606442,"mc":[{"id":"1.232049325","rc":[{"batb":[[0,1.4,1.47],[1,1.04,1.53],[2,1.03,200]],"ltp":0.0,"tv":0.0,"id":72857115}]}]}
{"op":"mcm","clk":"11894202969","pt":1724235617566,"mc":[{"id":"1.232049325","rc":[{"batb":[[0,1.04,2.47],[1,1.03,200],[2,1.02,200]],"ltp":0.0,"tv":0.0,"id":72857115}]}]}
{"op":"mcm","clk":"11894203009","pt":1724235617881,"mc":[{"id":"1.232049325","rc":[{"batb":[[0,1.04,3.4]],"ltp":1.03,"tv":5.99,"id":67083366},{"batb":[[0,1.45,1.44],[1,1.04,1.53],[2,1.03,200]],"ltp":0.0,"tv":0.0,"id":72857115}]}]}
{"op":"mcm","clk":"11894204022","pt":1724235628996,"mc":[{"id":"1.232049325","rc":[{"batl":[[0,5,0.94]],"ltp":1.03,"tv":5.99,"id":67083366}]}]}
{"op":"mcm","clk":"11894204168","pt":1724235630470,"mc":[{"id":"1.232049325","rc":[{"batb":[[0,1.39,1.47],[1,1.04,2.47],[2,1.02,200]],"ltp":1.03,"tv":5.99,"id":67083366}]}]}
{"op":"mcm","clk":"11894205021","pt":1724235639495,"mc":[{"id":"1.232049325","rc":[{"batb":[[0,1.04,3.4],[1,1.02,200],[2,1.01,483.09]],"ltp":1.03,"tv":5.99,"id":67083366}]}]}
{"op":"mcm","clk":"11894205026","pt":1724235639596,"mc":[{"id":"1.232049325","rc":[{"batb":[[0,1.39,1.44],[1,1.04,2.47],[2,1.02,200]],"ltp":1.03,"tv":5.99,"id":67083366}]}]}
{"op":"mcm","clk":"11894205159","pt":1724235641104,"mc":[{"id":"1.232049325","rc":[{"batl":[[0,5,1.97]],"ltp":1.03,"tv":5.99,"id":67083366}]}]}
{"op":"mcm","clk":"11894206369","pt":1724235653979,"mc":[{"id":"1.232049325","rc":[{"batb":[[0,1.47,1.44]],"ltp":0.0,"tv":0.0,"id":72857115}]}]}
{"op":"mcm","clk":"11894206599","pt":1724235656516,"mc":[{"id":"1.232049325","rc":[{"batb":[[0,1.45,1.44],[1,1.04,3.4]],"ltp":1.03,"tv":5.99,"id":67083366}]}]}
{"op":"mcm","clk":"11894207337","pt":1724235664023,"mc":[{"id":"1.232049325","rc":[{"batb":[[0,1.45,2.38],[1,1.04,2.47]],"ltp":1.03,"tv":5.99,"id":67083366}]}]}
{"op":"mcm","clk":"11894208529","pt":1724235676549,"mc":[{"id":"1.232049325","rc":[{"batb":[[0,1.45,1.44]],"ltp":1.03,"tv":5.99,"id":67083366}]}]}
{"op":"mcm","clk":"11894208536","pt":1724235676597,"mc":[{"id":"1.232049325","rc":[{"batb":[[0,1.45,3.2]],"ltp":1.03,"tv":5.99,"id":67083366}]}]}
{"op":"mcm","clk":"11894208715","pt":1724235678207,"mc":[{"id":"1.232049325","rc":[{"batb":[[0,1.46,19.58],[1,1.45,2.26],[2,1.04,2.47]],"ltp":1.03,"tv":5.99,"id":67083366},{"batb":[[1,1.26,32.99],[2,1.04,1.53]],"ltp":0.0,"tv":0.0,"id":72857115}]}]}
{"op":"mcm","clk":"11894297974","pt":1724236609893,"mc":[{"id":"1.232049325","rc":[{"batl":[[0,1.53,1.15],[1,5,1.97]],"ltp":1.03,"tv":5.99,"id":67083366}]}]}
{"op":"mcm","clk":"11894298129","pt":1724236612115,"mc":[{"id":"1.232049325","rc":[{"batl":[[0,5,1.97],[1,5,0]],"ltp":1.03,"tv":5.99,"id":67083366}]}]}
{"op":"mcm","clk":"11894298671","pt":1724236618893,"mc":[{"id":"1.232049325","rc":[{"batl":[[0,1.62,1.15]],"ltp":0.0,"tv":0.0,"id":72857115}]}]}
{"op":"mcm","clk":"11894300423","pt":1724236638435,"mc":[{"id":"1.232049325","rc":[{"batl":[[0,1.52,1.15],[1,5,1.97]],"ltp":1.03,"tv":5.99,"id":67083366}]}]}
{"op":"mcm","clk":"11894300567","pt":1724236640113,"mc":[{"id":"1.232049325","rc":[{"batl":[[0,5,1.97],[1,5,0]],"ltp":1.03,"tv":5.99,"id":67083366}]}]}
{"op":"mcm","clk":"11894300981","pt":1724236645198,"mc":[{"id":"1.232049325","rc":[{"batl":[[0,1.62,1.15]],"ltp":0.0,"tv":0.0,"id":72857115}]}]}
{"op":"mcm","clk":"11894304154","pt":1724236683678,"mc":[{"id":"1.232049325","rc":[{"batl":[[0,1.5,1.15],[1,5,1.97]],"ltp":1.03,"tv":5.99,"id":67083366}]}]}
{"op":"mcm","clk":"11894304293","pt":1724236685182,"mc":[{"id":"1.232049325","rc":[{"batl":[[0,5,1.97],[1,5,0]],"ltp":1.03,"tv":5.99,"id":67083366}]}]}
{"op":"mcm","clk":"11894304806","pt":1724236690860,"mc":[{"id":"1.232049325","rc":[{"batl":[[0,1.5,1.15],[1,5,1.97]],"ltp":1.03,"tv":5.99,"id":67083366}]}]}
{"op":"mcm","clk":"11894304995","pt":1724236693196,"mc":[{"id":"1.232049325","rc":[{"batl":[[0,5,1.97],[1,5,0]],"ltp":1.03,"tv":5.99,"id":67083366}]}]}
{"op":"mcm","clk":"11894306667","pt":1724236714007,"mc":[{"id":"1.232049325","rc":[{"batl":[[0,1.6,1.15]],"ltp":0.0,"tv":0.0,"id":72857115}]}]}
{"op":"mcm","clk":"11894309014","pt":1724236740844,"mc":[{"id":"1.232049325","rc":[{"batl":[[0,1.5,1.15],[1,5,1.97]],"ltp":1.03,"tv":5.99,"id":67083366}]}]}
{"op":"mcm","clk":"11894309208","pt":1724236743033,"mc":[{"id":"1.232049325","rc":[{"batl":[[0,5,1.97],[1,5,0]],"ltp":1.03,"tv":5.99,"id":67083366}]}]}
{"op":"mcm","clk":"11894311029","pt":1724236764173,"mc":[{"id":"1.232049325","rc":[{"batl":[[0,1.6,1.15]],"ltp":0.0,"tv":0.0,"id":72857115}]}]}
{"op":"mcm","clk":"11894312581","pt":1724236782885,"mc":[{"id":"1.232049325","rc":[{"batl":[[0,1.5,1.15],[1,5,1.97]],"ltp":1.03,"tv":5.99,"id":67083366}]}]}
{"op":"mcm","clk":"11894312814","pt":1724236785487,"mc":[{"id":"1.232049325","rc":[{"batl":[[0,5,1.97],[1,5,0]],"ltp":1.03,"tv":5.99,"id":67083366}]}]}
{"op":"mcm","clk":"11894314062","pt":1724236800714,"mc":[{"id":"1.232049325","rc":[{"batl":[[0,1.6,1.15]],"ltp":0.0,"tv":0.0,"id":72857115}]}]}
{"op":"mcm","clk":"11894316299","pt":1724236827437,"mc":[{"id":"1.232049325","rc":[{"batl":[[0,1.5,1.15],[1,5,1.97]],"ltp":1.03,"tv":5.99,"id":67083366}]}]}
{"op":"mcm","clk":"11894316497","pt":1724236830037,"mc":[{"id":"1.232049325","rc":[{"batl":[[0,5,1.97],[1,5,0]],"ltp":1.03,"tv":5.99,"id":67083366}]}]}
{"op":"mcm","clk":"11894319966","pt":1724236870481,"mc":[{"id":"1.232049325","rc":[{"batl":[[0,1.5,1.15],[1,5,1.97]],"ltp":1.03,"tv":5.99,"id":67083366}]}]}
{"op":"mcm","clk":"11894320162","pt":1724236872971,"mc":[{"id":"1.232049325","rc":[{"batl":[[0,5,1.97],[1,5,0]],"ltp":1.03,"tv":5.99,"id":67083366}]}]}
{"op":"mcm","clk":"11894324217","pt":1724236914254,"mc":[{"id":"1.232049325","rc":[{"batl":[[0,1.6,1.15]],"ltp":0.0,"tv":0.0,"id":72857115}]}]}
{"op":"mcm","clk":"11894353743","pt":1724237127541,"mc":[{"id":"1.232049325","rc":[{"batb":[[2,1.02,200]],"ltp":1.03,"tv":5.99,"id":67083366}]}]}
{"op":"mcm","clk":"11894387535","pt":1724237478446,"mc":[{"id":"1.232049325","rc":[{"batb":[[1,1.04,1.53],[2,1.03,200]],"ltp":0.0,"tv":0.0,"id":72857115}]}]}
{"op":"mcm","clk":"11894387553","pt":1724237478606,"mc":[{"id":"1.232049325","rc":[{"batb":[[0,1.45,3.2],[1,1.02,200],[2,1.01,483.09]],"ltp":1.03,"tv":5.99,"id":67083366}]}]}
{"op":"mcm","clk":"11894389765","pt":1724237504950,"mc":[{"id":"1.232049325","rc":[{"batb":[[0,1.46,19.58],[1,1.45,2.26],[2,1.02,200]],"ltp":1.03,"tv":5.99,"id":67083366},{"batb":[[1,1.26,32.99],[2,1.04,1.53]],"ltp":0.0,"tv":0.0,"id":72857115}]}]}
{"op":"mcm","clk":"11894403637","pt":1724237692530,"mc":[{"id":"1.232049325","rc":[{"batb":[[1,1.45,1.76]],"ltp":1.03,"tv":5.99,"id":67083366},{"batb":[[0,1.26,33.93],[1,1.04,1.53],[2,1.03,200]],"ltp":0.0,"tv":0.0,"id":72857115}]}]}
{"op":"mcm","clk":"11894471693","pt":1724238498522,"mc":[{"id":"1.232049325","rc":[{"trd":[[1.58,1.88]],"batb":[[0,1.46,19.58],[1,1.45,1.76]],"ltp":1.03,"tv":5.99,"id":67083366},{"batb":[[0,1.26,33.91]],"ltp":0.0,"tv":0.0,"id":72857115}],"tv":5.99}]}
{"op":"mcm","clk":"11894471712","pt":1724238498721,"mc":[{"id":"1.232049325","rc":[{"batl":[[0,3,0.94]],"ltp":1.03,"tv":5.99,"id":67083366}]}]}
{"op":"mcm","clk":"11894472587","pt":1724238506729,"mc":[{"id":"1.232049325","rc":[{"batl":[[0,2.98,0.94]],"ltp":1.03,"tv":5.99,"id":67083366}]}]}
{"op":"mcm","clk":"11894551359","pt":1724239305381,"mc":[{"id":"1.232049325","rc":[{"batb":[[0,1.45,2.7],[1,1.02,200],[2,1.01,483]],"ltp":1.03,"tv":5.99,"id":67083366},{"batb":[[0,1.04,2.47],[1,1.03,200],[2,1.02,200]],"ltp":0.0,"tv":0.0,"id":72857115}]}]}
{"op":"mcm","clk":"11894554310","pt":1724239335774,"mc":[{"id":"1.232049325","rc":[{"batb":[[0,1.46,19.58],[1,1.45,1.76],[2,1.02,200]],"ltp":1.03,"tv":5.99,"id":67083366},{"batb":[[0,1.51,17.75],[1,1.04,1.53],[2,1.03,200]],"ltp":0.0,"tv":0.0,"id":72857115}]}]}
{"op":"mcm","clk":"11894722488","pt":1724241136046,"mc":[{"id":"1.232049325","rc":[{"batb":[[0,1.45,2.7],[1,1.02,200],[2,1.01,483]],"ltp":1.03,"tv":5.99,"id":67083366},{"batb":[[0,1.04,2.47],[1,1.03,200],[2,1.02,200]],"ltp":0.0,"tv":0.0,"id":72857115}]}]}
{"op":"mcm","clk":"11894731619","pt":1724241239724,"mc":[{"id":"1.232049325","rc":[{"batb":[[0,1.46,19.58],[1,1.45,1.76],[2,1.02,200]],"ltp":1.03,"tv":5.99,"id":67083366},{"batb":[[0,1.51,17.75],[1,1.04,1.53],[2,1.03,200]],"ltp":0.0,"tv":0.0,"id":72857115}]}]}
{"op":"mcm","clk":"11894750106","pt":1724241464805,"mc":[{"id":"1.232049325","rc":[{"batl":[[0,2.58,0.94]],"ltp":1.03,"tv":5.99,"id":67083366}]}]}
{"op":"mcm","clk":"11894783978","pt":1724241963852,"mc":[{"id":"1.232049325","rc":[{"batb":[[1,1.45,1.76]],"ltp":1.03,"tv":5.99,"id":67083366},{"batb":[[0,1.58,1.83],[1,1.51,16.81],[2,1.04,1.53]],"ltp":0.0,"tv":0.0,"id":72857115}]}]}
{"op":"mcm","clk":"11894863242","pt":1724243040061,"mc":[{"id":"1.232049325","rc":[{"batb":[[0,1.45,2.7],[1,1.02,200],[2,1.01,483.05]],"ltp":1.03,"tv":5.99,"id":67083366},{"batb":[[1,1.04,1.53],[2,1.03,200]],"ltp":0.0,"tv":0.0,"id":72857115}]}]}
{"op":"mcm","clk":"11894868729","pt":1724243116878,"mc":[{"id":"1.232049325","rc":[{"batb":[[0,1.46,19.58],[1,1.45,1.76],[2,1.02,200]],"ltp":1.03,"tv":5.99,"id":67083366},{"batb":[[0,1.64,14.29],[1,1.04,2.47]],"ltp":0.0,"tv":0.0,"id":72857115}]}]}
{"op":"mcm","clk":"11894869384","pt":1724243125853,"mc":[{"id":"1.232049325","rc":[{"batb":[[0,3,1.07],[1,1.64,14.29],[2,1.04,2.47]],"ltp":0.0,"tv":0.0,"id":72857115}]}]}
{"op":"mcm","clk":"11894869544","pt":1724243128585,"mc":[{"id":"1.232049325","rc":[{"batb":[[0,1.64,14.29],[1,1.04,2.47],[2,1.03,200]],"ltp":0.0,"tv":0.0,"id":72857115}]}]}
{"op":"mcm","clk":"11894871166","pt":1724243151083,"mc":[{"id":"1.232049325","rc":[{"batb":[[0,3,1.07],[1,1.64,14.29],[2,1.04,2.47]],"ltp":0.0,"tv":0.0,"id":72857115}]}]}
{"op":"mcm","clk":"11894871285","pt":1724243152794,"mc":[{"id":"1.232049325","rc":[{"batb":[[0,1.64,14.29],[1,1.04,2.47],[2,1.03,200]],"ltp":0.0,"tv":0.0,"id":72857115}]}]}
{"op":"mcm","clk":"11894872444","pt":1724243168535,"mc":[{"id":"1.232049325","rc":[{"batb":[[0,3,1.07],[1,1.64,14.29],[2,1.04,2.47]],"ltp":0.0,"tv":0.0,"id":72857115}]}]}
{"op":"mcm","clk":"11894872700","pt":1724243171967,"mc":[{"id":"1.232049325","rc":[{"batb":[[0,1.64,14.29],[1,1.04,2.47],[2,1.03,200]],"ltp":0.0,"tv":0.0,"id":72857115}]}]}
{"op":"mcm","clk":"11894876026","pt":1724243222306,"mc":[{"id":"1.232049325","rc":[{"batb":[[0,2.3,1.07],[1,1.46,19.58],[2,1.45,1.76]],"ltp":1.03,"tv":5.99,"id":67083366}]}]}
{"op":"mcm","clk":"11894876383","pt":1724243227210,"mc":[{"id":"1.232049325","rc":[{"batb":[[0,1.46,19.58],[1,1.45,1.76],[2,1.02,200]],"ltp":1.03,"tv":5.99,"id":67083366}]}]}
{"op":"mcm","clk":"11894881240","pt":1724243301199,"mc":[{"id":"1.232049325","rc":[{"batb":[[0,3,1.07],[1,1.64,14.29],[2,1.04,2.47]],"ltp":0.0,"tv":0.0,"id":72857115}]}]}
{"op":"mcm","clk":"11894881414","pt":1724243304235,"mc":[{"id":"1.232049325","rc":[{"batb":[[0,1.64,14.29],[1,1.04,2.47],[2,1.03,200]],"ltp":0.0,"tv":0.0,"id":72857115}]}]}
{"op":"mcm","clk":"11894882693","pt":1724243322941,"mc":[{"id":"1.232049325","rc":[{"batb":[[0,2.34,1.07],[1,1.46,19.58],[2,1.45,1.76]],"ltp":1.03,"tv":5.99,"id":67083366}]}]}
{"op":"mcm","clk":"11894882895","pt":1724243325485,"mc":[{"id":"1.232049325","rc":[{"batb":[[0,1.46,19.58],[1,1.45,1.76],[2,1.02,200]],"ltp":1.03,"tv":5.99,"id":67083366}]}]}
{"op":"mcm","clk":"11894884145","pt":1724243342292,"mc":[{"id":"1.232049325","rc":[{"batb":[[0,3,1.07],[1,1.64,14.29],[2,1.04,2.47]],"ltp":0.0,"tv":0.0,"id":72857115}]}]}
{"op":"mcm","clk":"11894884330","pt":1724243345288,"mc":[{"id":"1.232049325","rc":[{"batb":[[0,1.64,14.29],[1,1.04,2.47],[2,1.03,200]],"ltp":0.0,"tv":0.0,"id":72857115}]}]}
{"op":"mcm","clk":"11894884375","pt":1724243345911,"mc":[{"id":"1.232049325","rc":[{"batb":[[0,1.5,3.57],[1,1.46,19.58],[2,1.45,1.76]],"ltp":1.03,"tv":5.99,"id":67083366}]}]}
{"op":"mcm","clk":"11894884687","pt":1724243350481,"mc":[{"id":"1.232049325","rc":[{"batb":[[0,1.46,19.58],[1,1.45,1.76],[2,1.02,200]],"ltp":1.03,"tv":5.99,"id":67083366}]}]}
{"op":"mcm","clk":"11894885656","pt":1724243363993,"mc":[{"id":"1.232049325","rc":[{"batb":[[0,2.3,1.07],[1,1.46,19.58],[2,1.45,1.76]],"ltp":1.03,"tv":5.99,"id":67083366}]}]}
{"op":"mcm","clk":"11894885855","pt":1724243367341,"mc":[{"id":"1.232049325","rc":[{"batb":[[0,1.46,19.58],[1,1.45,1.76],[2,1.02,200]],"ltp":1.03,"tv":5.99,"id":67083366}]}]}
{"op":"mcm","clk":"11894886833","pt":1724243383226,"mc":[{"id":"1.232049325","rc":[{"batb":[[0,2.3,1.07],[1,1.46,19.58],[2,1.45,1.76]],"ltp":1.03,"tv":5.99,"id":67083366}]}]}
{"op":"mcm","clk":"11894887031","pt":1724243386222,"mc":[{"id":"1.232049325","rc":[{"batb":[[0,1.46,19.58],[1,1.45,1.76],[2,1.02,200]],"ltp":1.03,"tv":5.99,"id":67083366}]}]}
{"op":"mcm","clk":"11894895155","pt":1724243520192,"mc":[{"id":"1.232049325","rc":[{"batb":[[0,3,1.07],[1,1.64,14.29],[2,1.04,2.47]],"ltp":0.0,"tv":0.0,"id":72857115}]}]}
{"op":"mcm","clk":"11894895304","pt":1724243522741,"mc":[{"id":"1.232049325","rc":[{"batb":[[0,1.64,14.29],[1,1.04,2.47],[2,1.03,200]],"ltp":0.0,"tv":0.0,"id":72857115}]}]}
{"op":"mcm","clk":"11894896585","pt":1724243543564,"mc":[{"id":"1.232049325","rc":[{"batb":[[0,1.64,13.4]],"ltp":0.0,"tv":0.0,"id":72857115}]}]}
{"op":"mcm","clk":"11894896593","pt":1724243543666,"mc":[{"id":"1.232049325","rc":[{"batb":[[0,1.64,14.29]],"ltp":0.0,"tv":0.0,"id":72857115}]}]}
{"op":"mcm","clk":"11894897066","pt":1724243550343,"mc":[{"id":"1.232049325","rc":[{"batb":[[0,3,1.07],[1,1.64,14.29],[2,1.04,2.47]],"ltp":0.0,"tv":0.0,"id":72857115}]}]}
{"op":"mcm","clk":"11894897233","pt":1724243552835,"mc":[{"id":"1.232049325","rc":[{"trd":[[1.5,2.15]],"batb":[[0,1.5,1.42],[1,1.46,19.58],[2,1.45,1.76]],"ltp":1.5,"tv":8.14,"id":67083366},{"trd":[[3,1.07]],"batb":[[0,1.64,14.29],[1,1.04,2.47],[2,1.03,200]],"ltp":3.0,"tv":1.07,"id":72857115}],"tv":9.22}]}
{"op":"mcm","clk":"11894897531","pt":1724243557557,"mc":[{"id":"1.232049325","rc":[{"batb":[[0,1.46,19.58],[1,1.45,1.76],[2,1.02,200]],"ltp":1.5,"tv":8.14,"id":67083366}]}]}
{"op":"mcm","clk":"11894909538","pt":1724243777987,"mc":[{"id":"1.232049325","rc":[{"trd":[[2.5,0.6]],"batb":[[0,1.48,1.41],[1,1.46,18.64],[2,1.45,1.76]],"ltp":2.5,"tv":8.74,"id":67083366},{"trd":[[1.67,0.89]],"batb":[[0,1.64,13.4]],"ltp":1.67,"tv":1.96,"id":72857115}],"tv":10.71}]}
{"op":"mcm","clk":"11894909751","pt":1724243782213,"mc":[{"id":"1.232049325","rc":[{"batb":[[0,1.46,19.58],[1,1.45,1.76],[2,1.02,200]],"ltp":2.5,"tv":8.74,"id":67083366}]}]}
{"op":"mcm","clk":"11894909938","pt":1724243785808,"mc":[{"id":"1.232049325","rc":[{"trd":[[1.64,2.1]],"batb":[[0,1.64,12.34]],"ltp":1.64,"tv":4.06,"id":72857115}],"tv":12.81}]}
{"op":"mcm","clk":"11894911665","pt":1724243816128,"mc":[{"id":"1.232049325","rc":[{"batb":[[0,2.6,1.07],[1,1.64,12.34],[2,1.04,2.47]],"ltp":1.64,"tv":4.06,"id":72857115}]}]}
{"op":"mcm","clk":"11894911980","pt":1724243821452,"mc":[{"id":"1.232049325","rc":[{"trd":[[1.63,0.89]],"ltp":1.63,"tv":9.63,"id":67083366},{"trd":[[2.6,0.56]],"batb":[[0,1.64,12.86],[1,1.04,2.47],[2,1.03,200]],"ltp":2.6,"tv":4.62,"id":72857115}],"tv":14.26}]}
{"op":"mcm","clk":"11894912042","pt":1724243822438,"mc":[{"id":"1.232049325","rc":[{"trd":[[1.63,1.71]],"batb":[[0,1.63,2.75],[1,1.46,19.58],[2,1.45,1.76]],"ltp":1.63,"tv":10.45,"id":67083366},{"trd":[[2.6,1.07]],"batb":[[0,1.64,12.34]],"ltp":2.6,"tv":5.14,"id":72857115}],"tv":15.6}]}
{"op":"mcm","clk":"11894912339","pt":1724243827450,"mc":[{"id":"1.232049325","rc":[{"batb":[[0,1.46,19.58],[1,1.45,1.76],[2,1.02,200]],"ltp":1.63,"tv":10.45,"id":67083366}]}]}
{"op":"mcm","clk":"11894912567","pt":1724243831830,"mc":[{"id":"1.232049325","rc":[{"batb":[[0,1.64,13.24]],"ltp":2.6,"tv":5.14,"id":72857115}]}]}
{"op":"mcm","clk":"11894912926","pt":1724243837293,"mc":[{"id":"1.232049325","rc":[{"trd":[[1.64,3.68],[1.67,2.67]],"batb":[[0,1.64,11.55]],"ltp":1.64,"tv":8.5,"id":72857115}],"tv":18.96}]}
{"op":"mcm","clk":"11894913791","pt":1724243851796,"mc":[{"id":"1.232049325","rc":[{"batb":[[0,1.64,12.45]],"ltp":1.64,"tv":8.5,"id":72857115}]}]}
{"op":"mcm","clk":"11894924160","pt":1724244023958,"mc":[{"id":"1.232049325","rc":[{"batl":[[0,1.7,1.07]],"ltp":1.64,"tv":8.5,"id":72857115}]}]}
{"op":"mcm","clk":"11894926274","pt":1724244060784,"mc":[{"id":"1.232049325","rc":[{"batl":[[0,1.52,1.07],[1,2.58,0.94]],"ltp":1.63,"tv":10.45,"id":67083366}]}]}
{"op":"mcm","clk":"11894926452","pt":1724244063476,"mc":[{"id":"1.232049325","rc":[{"batl":[[0,2.58,0.94],[1,2.58,0]],"ltp":1.63,"tv":10.45,"id":67083366}]}]}
{"op":"mcm","clk":"11894927597","pt":1724244080716,"mc":[{"id":"1.232049325","rc":[{"batl":[[0,1.52,1.07],[1,2.58,0.94]],"ltp":1.63,"tv":10.45,"id":67083366}]}]}
{"op":"mcm","clk":"11894927827","pt":1724244083913,"mc":[{"id":"1.232049325","rc":[{"batl":[[0,2.58,0.94],[1,2.58,0]],"ltp":1.63,"tv":10.45,"id":67083366}]}]}
{"op":"mcm","clk":"11894927985","pt":1724244086494,"mc":[{"id":"1.232049325","rc":[{"batb":[[0,1.52,3.57],[1,1.46,19.58],[2,1.45,1.76]],"ltp":1.63,"tv":10.45,"id":67083366}]}]}
{"op":"mcm","clk":"11894928174","pt":1724244089935,"mc":[{"id":"1.232049325","rc":[{"batb":[[0,1.46,19.58],[1,1.45,1.76],[2,1.02,200]],"ltp":1.63,"tv":10.45,"id":67083366}]}]}
{"op":"mcm","clk":"11894928539","pt":1724244095508,"mc":[{"id":"1.232049325","rc":[{"batl":[[0,1.7,1.1]],"ltp":1.64,"tv":8.5,"id":72857115}]}]}
{"op":"mcm","clk":"11894928761","pt":1724244099432,"mc":[{"id":"1.232049325","rc":[{"batb":[[0,1.7,3.57],[1,1.64,12.45],[2,1.04,2.47]],"ltp":1.64,"tv":8.5,"id":72857115}]}]}
{"op":"mcm","clk":"11894930183","pt":1724244123450,"mc":[{"id":"1.232049325","rc":[{"batb":[[0,1.64,12.45],[1,1.04,2.47],[2,1.03,200]],"ltp":1.64,"tv":8.5,"id":72857115}]}]}
{"op":"mcm","clk":"11894930562","pt":1724244127579,"mc":[{"id":"1.232049325","rc":[{"batl":[[0,1.72,1.07]],"ltp":1.64,"tv":8.5,"id":72857115}]}]}
{"op":"mcm","clk":"11894931833","pt":1724244147934,"mc":[{"id":"1.232049325","rc":[{"batl":[[0,1.52,1.07],[1,2.58,0.94]],"ltp":1.63,"tv":10.45,"id":67083366}]}]}
{"op":"mcm","clk":"11894931917","pt":1724244149523,"mc":[{"id":"1.232049325","rc":[{"batl":[[0,2.58,0.94],[1,2.58,0]],"ltp":1.63,"tv":10.45,"id":67083366}]}]}
{"op":"mcm","clk":"11894932675","pt":1724244163326,"mc":[{"id":"1.232049325","rc":[{"batl":[[0,1.52,1.07],[1,2.58,0.94]],"ltp":1.63,"tv":10.45,"id":67083366}]}]}
{"op":"mcm","clk":"11894932875","pt":1724244166666,"mc":[{"id":"1.232049325","rc":[{"batl":[[0,2.58,0.94],[1,2.58,0]],"ltp":1.63,"tv":10.45,"id":67083366}]}]}
{"op":"mcm","clk":"11894934291","pt":1724244194960,"mc":[{"id":"1.232049325","rc":[{"batl":[[0,1.72,1.07]],"ltp":1.64,"tv":8.5,"id":72857115}]}]}
{"op":"mcm","clk":"11894934409","pt":1724244196864,"mc":[{"id":"1.232049325","rc":[{"trd":[[1.72,2.15]],"batb":[[0,1.72,2.49],[1,1.64,12.45],[2,1.04,2.47]],"ltp":1.72,"tv":10.65,"id":72857115}],"tv":21.11}]}
{"op":"mcm","clk":"11894934979","pt":1724244205603,"mc":[{"id":"1.232049325","rc":[{"trd":[[1.46,0.61],[1.48,1.87]],"batb":[[0,1.46,18.33]],"ltp":1.46,"tv":12.94,"id":67083366}],"tv":23.6}]}
{"op":"mcm","clk":"11894977014","pt":1724244917183,"mc":[{"id":"1.232049325","rc":[{"batb":[[0,1.45,1.76],[1,1.02,200],[2,1.01,483.05]],"ltp":1.46,"tv":12.94,"id":67083366},{"batb":[[1,1.58,1.83],[2,1.04,1.53]],"ltp":1.72,"tv":10.65,"id":72857115}]}]}
{"op":"mcm","clk":"11895141449","pt":1724247512808,"mc":[{"id":"1.232049325","rc":[{"trd":[[1.48,1.87],[1.5,2.15],[1.63,1.71]],"batb":[[0,1.45,1.76],[2,1.01,483.22]],"ltp":1.46,"tv":12.93,"id":67083366},{"trd":[[1.64,3.68],[1.67,2.67],[1.72,2.15],[2.6,1.07],[3,1.07]],"batb":[[0,1.72,2.49],[1,1.58,1.83]],"batl":[[0,4,4]],"ltp":1.72,"tv":10.64,"id":72857115}],"tv":23.58}]}
{"op":"mcm","clk":"11895143086","pt":1724247539671,"mc":[{"id":"1.232049325","rc":[{"batl":[[0,2.1,10],[1,2.58,0.94]],"ltp":1.46,"tv":12.93,"id":67083366}]}]}
{"op":"mcm","clk":"11895147111","pt":1724247600524,"mc":[{"id":"1.232049325","rc":[{"trd":[[2.1,19.6]],"batl":[[0,2.58,1.14],[1,2.58,0]],"ltp":2.1,"tv":32.54,"id":67083366}],"tv":43.18}]}
{"op":"mcm","clk":"11895150433","pt":1724247657973,"mc":[{"id":"1.232049325","rc":[{"batb":[[0,1.58,1.83],[1,1.04,1.53],[2,1.03,200]],"ltp":1.72,"tv":10.64,"id":72857115}]}]}
{"op":"mcm","clk":"11895217436","pt":1724248442114,"mc":[{"id":"1.232049325","rc":[{"batl":[[0,2.58,0.94]],"ltp":2.1,"tv":32.54,"id":67083366}]}]}
{"op":"mcm","clk":"11895218346","pt":1724248454604,"mc":[{"id":"1.232049325","rc":[{"batb":[[0,1.46,13],[1,1.45,1.76],[2,1.02,200]],"ltp":2.1,"tv":32.54,"id":67083366}]}]}
{"op":"mcm","clk":"11895219567","pt":1724248473408,"mc":[{"id":"1.232049325","rc":[{"batl":[[0,2.1,7],[1,2.58,0.94]],"ltp":2.1,"tv":32.54,"id":67083366}]}]}
{"op":"mcm","clk":"11895221506","pt":1724248504437,"mc":[{"id":"1.232049325","rc":[{"trd":[[2.1,26.73]],"batl":[[0,2.1,3.44]],"ltp":2.1,"tv":39.66,"id":67083366}],"tv":50.3}]}
{"op":"mcm","clk":"11895222186","pt":1724248513484,"mc":[{"id":"1.232049325","rc":[{"trd":[[2.1,33.61]],"batb":[[0,1.46,13.12]],"batl":[[0,2.58,0.94],[1,2.58,0]],"ltp":2.1,"tv":46.54,"id":67083366}],"tv":57.18}]}
{"op":"mcm","clk":"11895222664","pt":1724248519961,"mc":[{"id":"1.232049325","rc":[{"batb":[[0,1.46,13]],"ltp":2.1,"tv":46.54,"id":67083366}]}]}
{"op":"mcm","clk":"11895242786","pt":1724248802548,"mc":[{"id":"1.232049325","rc":[{"batb":[[0,1.47,10],[1,1.46,13],[2,1.45,1.76]],"ltp":2.1,"tv":46.54,"id":67083366}]}]}
{"op":"mcm","clk":"11895242859","pt":1724248803120,"mc":[{"id":"1.232049325","rc":[{"trd":[[1.64,3.68]],"batb":[[0,1.6,10.89],[1,1.59,4],[2,1.04,2.47]],"ltp":1.72,"tv":10.64,"id":72857115}],"tv":57.18}]}
{"op":"mcm","clk":"11895243151","pt":1724248805151,"mc":[{"id":"1.232049325","rc":[{"batb":[[1,1.04,2.47],[2,1.03,200]],"ltp":1.72,"tv":10.64,"id":72857115}]}]}
{"op":"mcm","clk":"11895243244","pt":1724248806124,"mc":[{"id":"1.232049325","rc":[{"batb":[[0,1.46,13],[1,1.45,1.76],[2,1.02,200]],"ltp":2.1,"tv":46.54,"id":67083366}]}]}
{"op":"mcm","clk":"11895243346","pt":1724248807467,"mc":[{"id":"1.232049325","rc":[{"batb":[[0,1.58,1.83],[1,1.04,1.53]],"ltp":1.72,"tv":10.64,"id":72857115}]}]}
{"op":"mcm","clk":"11895243400","pt":1724248808034,"mc":[{"id":"1.232049325","rc":[{"batb":[[0,1.59,4.89],[1,1.04,2.47]],"ltp":1.72,"tv":10.64,"id":72857115}]}]}
{"op":"mcm","clk":"11895243466","pt":1724248808758,"mc":[{"id":"1.232049325","rc":[{"batb":[[0,1.47,10],[1,1.46,13],[2,1.45,1.76]],"ltp":2.1,"tv":46.54,"id":67083366}]}]}
{"op":"mcm","clk":"11895243621","pt":1724248810663,"mc":[{"id":"1.232049325","rc":[{"batb":[[0,1.58,1.83],[1,1.04,1.53]],"ltp":1.72,"tv":10.64,"id":72857115}]}]}
{"op":"mcm","clk":"11895243748","pt":1724248812265,"mc":[{"id":"1.232049325","rc":[{"batb":[[0,1.46,13],[1,1.45,1.76],[2,1.02,200]],"ltp":2.1,"tv":46.54,"id":67083366}]}]}
{"op":"mcm","clk":"11895243885","pt":1724248813926,"mc":[{"id":"1.232049325","rc":[{"batb":[[0,1.59,4.89],[1,1.04,2.47]],"ltp":1.72,"tv":10.64,"id":72857115}]}]}
{"op":"mcm","clk":"11895243948","pt":1724248814746,"mc":[{"id":"1.232049325","rc":[{"batb":[[0,1.47,10],[1,1.46,13],[2,1.45,1.76]],"ltp":2.1,"tv":46.54,"id":67083366},{"batb":[[0,1.6,10.89],[1,1.59,4],[2,1.04,2.47]],"ltp":1.72,"tv":10.64,"id":72857115}]}]}
{"op":"mcm","clk":"11895244115","pt":1724248816968,"mc":[{"id":"1.232049325","rc":[{"batb":[[1,1.04,2.47],[2,1.03,200]],"ltp":1.72,"tv":10.64,"id":72857115}]}]}
{"op":"mcm","clk":"11895244248","pt":1724248818570,"mc":[{"id":"1.232049325","rc":[{"batb":[[0,1.46,13],[1,1.45,1.76],[2,1.02,200]],"ltp":2.1,"tv":46.54,"id":67083366},{"batb":[[0,1.58,1.83],[1,1.04,1.53]],"ltp":1.72,"tv":10.64,"id":72857115}]}]}
{"op":"mcm","clk":"11895244507","pt":1724248822541,"mc":[{"id":"1.232049325","rc":[{"batb":[[0,1.47,10],[1,1.46,13],[2,1.45,1.76]],"ltp":2.1,"tv":46.54,"id":67083366},{"batb":[[0,1.6,10.89],[1,1.59,4],[2,1.04,2.47]],"ltp":1.72,"tv":10.64,"id":72857115}]}]}
{"op":"mcm","clk":"11895244682","pt":1724248824766,"mc":[{"id":"1.232049325","rc":[{"batb":[[1,1.04,2.47],[2,1.03,200]],"ltp":1.72,"tv":10.64,"id":72857115}]}]}
{"op":"mcm","clk":"11895244762","pt":1724248825844,"mc":[{"id":"1.232049325","rc":[{"batb":[[0,1.46,13],[1,1.45,1.76],[2,1.02,200]],"ltp":2.1,"tv":46.54,"id":67083366}]}]}
{"op":"mcm","clk":"11895244805","pt":1724248826664,"mc":[{"id":"1.232049325","rc":[{"batb":[[0,1.58,1.83],[1,1.04,1.53]],"ltp":1.72,"tv":10.64,"id":72857115}]}]}
{"op":"mcm","clk":"11895245186","pt":1724248831170,"mc":[{"id":"1.232049325","rc":[{"batb":[[0,1.47,10],[1,1.46,13],[2,1.45,1.76]],"ltp":2.1,"tv":46.54,"id":67083366},{"batb":[[0,1.59,4.89],[1,1.04,2.47]],"ltp":1.72,"tv":10.64,"id":72857115}]}]}
{"op":"mcm","clk":"11895245253","pt":1724248831949,"mc":[{"id":"1.232049325","rc":[{"batb":[[0,1.6,10.89],[1,1.59,4],[2,1.04,2.47]],"ltp":1.72,"tv":10.64,"id":72857115}]}]}
{"op":"mcm","clk":"11895245454","pt":1724248834388,"mc":[{"id":"1.232049325","rc":[{"batb":[[1,1.04,2.47],[2,1.03,200]],"ltp":1.72,"tv":10.64,"id":72857115}]}]}
{"op":"mcm","clk":"11895245508","pt":1724248835531,"mc":[{"id":"1.232049325","rc":[{"batb":[[0,1.46,13],[1,1.45,1.76],[2,1.02,200]],"ltp":2.1,"tv":46.54,"id":67083366}]}]}
{"op":"mcm","clk":"11895245539","pt":1724248835670,"mc":[{"id":"1.232049325","rc":[{"batb":[[0,1.58,1.83],[1,1.04,1.53]],"ltp":1.72,"tv":10.64,"id":72857115}]}]}
{"op":"mcm","clk":"11895245927","pt":1724248841099,"mc":[{"id":"1.232049325","rc":[{"batb":[[0,1.47,10],[1,1.46,13],[2,1.45,1.76]],"ltp":2.1,"tv":46.54,"id":67083366},{"batb":[[0,1.59,4.89],[1,1.04,2.47]],"ltp":1.72,"tv":10.64,"id":72857115}]}]}
{"op":"mcm","clk":"11895246022","pt":1724248842189,"mc":[{"id":"1.232049325","rc":[{"batb":[[0,1.6,10.89],[1,1.59,4],[2,1.04,2.47]],"ltp":1.72,"tv":10.64,"id":72857115}]}]}
{"op":"mcm","clk":"11895246177","pt":1724248844194,"mc":[{"id":"1.232049325","rc":[{"batb":[[1,1.04,2.47],[2,1.03,200]],"ltp":1.72,"tv":10.64,"id":72857115}]}]}
{"op":"mcm","clk":"11895246236","pt":1724248844966,"mc":[{"id":"1.232049325","rc":[{"batb":[[0,1.46,13],[1,1.45,1.76],[2,1.02,200]],"ltp":2.1,"tv":46.54,"id":67083366}]}]}
{"op":"mcm","clk":"11895246321","pt":1724248846306,"mc":[{"id":"1.232049325","rc":[{"batb":[[0,1.59,4.89]],"ltp":1.72,"tv":10.64,"id":72857115}]}]}
{"op":"mcm","clk":"11895246476","pt":1724248849088,"mc":[{"id":"1.232049325","rc":[{"batb":[[0,1.47,10],[1,1.46,13],[2,1.45,1.76]],"ltp":2.1,"tv":46.54,"id":67083366},{"batb":[[0,1.58,1.83],[1,1.04,1.53]],"ltp":1.72,"tv":10.64,"id":72857115}]}]}
{"op":"mcm","clk":"11895246747","pt":1724248852500,"mc":[{"id":"1.232049325","rc":[{"batb":[[0,1.46,13],[1,1.45,1.76],[2,1.02,200]],"ltp":2.1,"tv":46.54,"id":67083366},{"batb":[[0,1.59,4.89],[1,1.04,2.47]],"ltp":1.72,"tv":10.64,"id":72857115}]}]}
{"op":"mcm","clk":"11895246771","pt":1724248852809,"mc":[{"id":"1.232049325","rc":[{"batb":[[0,1.6,10.89],[1,1.59,4],[2,1.04,2.47]],"ltp":1.72,"tv":10.64,"id":72857115}]}]}
{"op":"mcm","clk":"11895246984","pt":1724248855506,"mc":[{"id":"1.232049325","rc":[{"batb":[[0,1.47,10],[1,1.46,13],[2,1.45,1.76]],"ltp":2.1,"tv":46.54,"id":67083366},{"batb":[[1,1.04,2.47],[2,1.03,200]],"ltp":1.72,"tv":10.64,"id":72857115}]}]}
{"op":"mcm","clk":"11895247052","pt":1724248856379,"mc":[{"id":"1.232049325","rc":[{"batb":[[0,1.58,1.83],[1,1.04,1.53]],"ltp":1.72,"tv":10.64,"id":72857115}]}]}
{"op":"mcm","clk":"11895247370","pt":1724248859209,"mc":[{"id":"1.232049325","rc":[{"batb":[[0,1.46,13],[1,1.45,1.76],[2,1.02,200]],"ltp":2.1,"tv":46.54,"id":67083366},{"batb":[[0,1.6,10.89],[1,1.59,4],[2,1.04,2.47]],"ltp":1.72,"tv":10.64,"id":72857115}]}]}
{"op":"mcm","clk":"11895247641","pt":1724248861398,"mc":[{"id":"1.232049325","rc":[{"batb":[[1,1.04,2.47],[2,1.03,200]],"ltp":1.72,"tv":10.64,"id":72857115}]}]}
{"op":"mcm","clk":"11895247745","pt":1724248862396,"mc":[{"id":"1.232049325","rc":[{"batb":[[0,1.47,10],[1,1.46,13],[2,1.45,1.76]],"ltp":2.1,"tv":46.54,"id":67083366},{"batb":[[0,1.58,1.83],[1,1.04,1.53]],"ltp":1.72,"tv":10.64,"id":72857115}]}]}
{"op":"mcm","clk":"11895248059","pt":1724248865581,"mc":[{"id":"1.232049325","rc":[{"batb":[[0,1.46,13],[1,1.45,1.76],[2,1.02,200]],"ltp":2.1,"tv":46.54,"id":67083366}]}]}
{"op":"mcm","clk":"11895248107","pt":1724248866200,"mc":[{"id":"1.232049325","rc":[{"batb":[[0,1.6,10.89],[1,1.59,4],[2,1.04,2.47]],"ltp":1.72,"tv":10.64,"id":72857115}]}]}
{"op":"mcm","clk":"11895248252","pt":1724248868414,"mc":[{"id":"1.232049325","rc":[{"batb":[[1,1.04,2.47],[2,1.03,200]],"ltp":1.72,"tv":10.64,"id":72857115}]}]}
{"op":"mcm","clk":"11895248275","pt":1724248868621,"mc":[{"id":"1.232049325","rc":[{"batb":[[0,1.47,10],[1,1.46,13],[2,1.45,1.76]],"ltp":2.1,"tv":46.54,"id":67083366}]}]}
{"op":"mcm","clk":"11895248350","pt":1724248869602,"mc":[{"id":"1.232049325","rc":[{"batb":[[0,1.58,1.83],[1,1.04,1.53]],"ltp":1.72,"tv":10.64,"id":72857115}]}]}
{"op":"mcm","clk":"11895248586","pt":1724248872388,"mc":[{"id":"1.232049325","rc":[{"batb":[[0,1.46,13],[1,1.45,1.76],[2,1.02,200]],"ltp":2.1,"tv":46.54,"id":67083366},{"batb":[[0,1.6,10.89],[1,1.59,4],[2,1.04,2.47]],"ltp":1.72,"tv":10.64,"id":72857115}]}]}
{"op":"mcm","clk":"11895248787","pt":1724248874815,"mc":[{"id":"1.232049325","rc":[{"batb":[[0,1.47,10],[1,1.46,13],[2,1.45,1.76]],"ltp":2.1,"tv":46.54,"id":67083366},{"batb":[[1,1.04,2.47],[2,1.03,200]],"ltp":1.72,"tv":10.64,"id":72857115}]}]}
{"op":"mcm","clk":"11895248871","pt":1724248875799,"mc":[{"id":"1.232049325","rc":[{"batb":[[0,1.58,1.83],[1,1.04,1.53]],"ltp":1.72,"tv":10.64,"id":72857115}]}]}
{"op":"mcm","clk":"11895249076","pt":1724248878531,"mc":[{"id":"1.232049325","rc":[{"batb":[[0,1.46,13],[1,1.45,1.76],[2,1.02,200]],"ltp":2.1,"tv":46.54,"id":67083366},{"batb":[[0,1.6,10.89],[1,1.59,4],[2,1.04,2.47]],"ltp":1.72,"tv":10.64,"id":72857115}]}]}
{"op":"mcm","clk":"11895249251","pt":1724248880533,"mc":[{"id":"1.232049325","rc":[{"batb":[[1,1.04,2.47],[2,1.03,200]],"ltp":1.72,"tv":10.64,"id":72857115}]}]}
{"op":"mcm","clk":"11895249275","pt":1724248880790,"mc":[{"id":"1.232049325","rc":[{"batb":[[0,1.47,10],[1,1.46,13],[2,1.45,1.76]],"ltp":2.1,"tv":46.54,"id":67083366}]}]}
{"op":"mcm","clk":"11895249396","pt":1724248881823,"mc":[{"id":"1.232049325","rc":[{"batb":[[0,1.58,1.83],[1,1.04,1.53]],"ltp":1.72,"tv":10.64,"id":72857115}]}]}
{"op":"mcm","clk":"11895249630","pt":1724248884402,"mc":[{"id":"1.232049325","rc":[{"batb":[[0,1.46,13],[1,1.45,1.76],[2,1.02,200]],"ltp":2.1,"tv":46.54,"id":67083366},{"batb":[[0,1.59,4.89],[1,1.04,2.47]],"ltp":1.72,"tv":10.64,"id":72857115}]}]}
{"op":"mcm","clk":"11895249662","pt":1724248884817,"mc":[{"id":"1.232049325","rc":[{"batb":[[0,1.6,10.89],[1,1.59,4],[2,1.04,2.47]],"ltp":1.72,"tv":10.64,"id":72857115}]}]}
{"op":"mcm","clk":"11895249845","pt":1724248887027,"mc":[{"id":"1.232049325","rc":[{"batb":[[0,1.47,10],[1,1.46,13],[2,1.45,1.76]],"ltp":2.1,"tv":46.54,"id":67083366},{"batb":[[1,1.04,2.47],[2,1.03,200]],"ltp":1.72,"tv":10.64,"id":72857115}]}]}
{"op":"mcm","clk":"11895249941","pt":1724248888415,"mc":[{"id":"1.232049325","rc":[{"batb":[[0,1.58,1.83],[1,1.04,1.53]],"ltp":1.72,"tv":10.64,"id":72857115}]}]}
{"op":"mcm","clk":"11895250087","pt":1724248890329,"mc":[{"id":"1.232049325","rc":[{"batb":[[0,1.46,13],[1,1.45,1.76],[2,1.02,200]],"ltp":2.1,"tv":46.54,"id":67083366},{"batb":[[0,1.59,4.89],[1,1.04,2.47]],"ltp":1.72,"tv":10.64,"id":72857115}]}]}
{"op":"mcm","clk":"11895250109","pt":1724248890637,"mc":[{"id":"1.232049325","rc":[{"batb":[[0,1.6,10.89],[1,1.59,4],[2,1.04,2.47]],"ltp":1.72,"tv":10.64,"id":72857115}]}]}
{"op":"mcm","clk":"11895250284","pt":1724248893008,"mc":[{"id":"1.232049325","rc":[{"batb":[[0,1.47,10],[1,1.46,13],[2,1.45,1.76]],"ltp":2.1,"tv":46.54,"id":67083366},{"batb":[[1,1.04,2.47],[2,1.03,200]],"ltp":1.72,"tv":10.64,"id":72857115}]}]}
{"op":"mcm","clk":"11895250366","pt":1724248894043,"mc":[{"id":"1.232049325","rc":[{"batb":[[0,1.58,1.83],[1,1.04,1.53]],"ltp":1.72,"tv":10.64,"id":72857115}]}]}
{"op":"mcm","clk":"11895250575","pt":1724248896418,"mc":[{"id":"1.232049325","rc":[{"batb":[[0,1.46,13],[1,1.45,1.76],[2,1.02,200]],"ltp":2.1,"tv":46.54,"id":67083366}]}]}
{"op":"mcm","clk":"11895250600","pt":1724248896827,"mc":[{"id":"1.232049325","rc":[{"batb":[[0,1.6,10.89],[1,1.59,4],[2,1.04,2.47]],"ltp":1.72,"tv":10.64,"id":72857115}]}]}
{"op":"mcm","clk":"11895250819","pt":1724248899361,"mc":[{"id":"1.232049325","rc":[{"batb":[[0,1.47,10],[1,1.46,13],[2,1.45,1.76]],"ltp":2.1,"tv":46.54,"id":67083366},{"batb":[[1,1.04,2.47],[2,1.03,200]],"ltp":1.72,"tv":10.64,"id":72857115}]}]}
{"op":"mcm","clk":"11895250903","pt":1724248900344,"mc":[{"id":"1.232049325","rc":[{"batb":[[0,1.58,1.83],[1,1.04,1.53]],"ltp":1.72,"tv":10.64,"id":72857115}]}]}
{"op":"mcm","clk":"11895251145","pt":1724248903122,"mc":[{"id":"1.232049325","rc":[{"batb":[[0,1.46,13],[1,1.45,1.76],[2,1.02,200]],"ltp":2.1,"tv":46.54,"id":67083366},{"batb":[[0,1.6,10.89],[1,1.59,4],[2,1.04,2.47]],"ltp":1.72,"tv":10.64,"id":72857115}]}]}
{"op":"mcm","clk":"11895251320","pt":1724248905545,"mc":[{"id":"1.232049325","rc":[{"batb":[[0,1.47,10],[1,1.46,13],[2,1.45,1.76]],"ltp":2.1,"tv":46.54,"id":67083366},{"batb":[[1,1.04,2.47],[2,1.03,200]],"ltp":1.72,"tv":10.64,"id":72857115}]}]}
{"op":"mcm","clk":"11895251414","pt":1724248906634,"mc":[{"id":"1.232049325","rc":[{"batb":[[0,1.58,1.83],[1,1.04,1.53]],"ltp":1.72,"tv":10.64,"id":72857115}]}]}
{"op":"mcm","clk":"11895251657","pt":1724248909328,"mc":[{"id":"1.232049325","rc":[{"batb":[[0,1.46,13],[1,1.45,1.76],[2,1.02,200]],"ltp":2.1,"tv":46.54,"id":67083366},{"batb":[[0,1.6,10.89],[1,1.59,4],[2,1.04,2.47]],"ltp":1.72,"tv":10.64,"id":72857115}]}]}
{"op":"mcm","clk":"11895251859","pt":1724248911445,"mc":[{"id":"1.232049325","rc":[{"batb":[[1,1.04,2.47],[2,1.03,200]],"ltp":1.72,"tv":10.64,"id":72857115}]}]}
{"op":"mcm","clk":"11895251896","pt":1724248911853,"mc":[{"id":"1.232049325","rc":[{"batb":[[0,1.47,10],[1,1.46,13],[2,1.45,1.76]],"ltp":2.1,"tv":46.54,"id":67083366}]}]}
{"op":"mcm","clk":"11895251985","pt":1724248912630,"mc":[{"id":"1.232049325","rc":[{"batb":[[0,1.58,1.83],[1,1.04,1.53]],"ltp":1.72,"tv":10.64,"id":72857115}]}]}
{"op":"mcm","clk":"11895252195","pt":1724248915274,"mc":[{"id":"1.232049325","rc":[{"batb":[[0,1.46,13],[1,1.45,1.76],[2,1.02,200]],"ltp":2.1,"tv":46.54,"id":67083366}]}]}
{"op":"mcm","clk":"11895252249","pt":1724248915945,"mc":[{"id":"1.232049325","rc":[{"batb":[[0,1.6,10.89],[1,1.59,4],[2,1.04,2.47]],"ltp":1.72,"tv":10.64,"id":72857115}]}]}
{"op":"mcm","clk":"11895252466","pt":1724248918276,"mc":[{"id":"1.232049325","rc":[{"batb":[[0,1.47,10],[1,1.46,13],[2,1.45,1.76]],"ltp":2.1,"tv":46.54,"id":67083366},{"batb":[[1,1.04,2.47],[2,1.03,200]],"ltp":1.72,"tv":10.64,"id":72857115}]}]}
{"op":"mcm","clk":"11895252573","pt":1724248919567,"mc":[{"id":"1.232049325","rc":[{"batb":[[0,1.58,1.83],[1,1.04,1.53]],"ltp":1.72,"tv":10.64,"id":72857115}]}]}
{"op":"mcm","clk":"11895252822","pt":1724248922159,"mc":[{"id":"1.232049325","rc":[{"batb":[[0,1.46,13],[1,1.45,1.76],[2,1.02,200]],"ltp":2.1,"tv":46.54,"id":67083366},{"batb":[[0,1.6,10.89],[1,1.59,4],[2,1.04,2.47]],"ltp":1.72,"tv":10.64,"id":72857115}]}]}
{"op":"mcm","clk":"11895253042","pt":1724248924388,"mc":[{"id":"1.232049325","rc":[{"batb":[[0,1.47,10],[1,1.46,13],[2,1.45,1.76]],"ltp":2.1,"tv":46.54,"id":67083366},{"batb":[[1,1.04,2.47],[2,1.03,200]],"ltp":1.72,"tv":10.64,"id":72857115}]}]}
{"op":"mcm","clk":"11895253160","pt":1724248925570,"mc":[{"id":"1.232049325","rc":[{"batb":[[0,1.58,1.83],[1,1.04,1.53]],"ltp":1.72,"tv":10.64,"id":72857115}]}]}
{"op":"mcm","clk":"11895253388","pt":1724248928256,"mc":[{"id":"1.232049325","rc":[{"batb":[[0,1.46,13],[1,1.45,1.76],[2,1.02,200]],"ltp":2.1,"tv":46.54,"id":67083366},{"batb":[[0,1.6,10.89],[1,1.59,4],[2,1.04,2.47]],"ltp":1.72,"tv":10.64,"id":72857115}]}]}
{"op":"mcm","clk":"11895253535","pt":1724248930362,"mc":[{"id":"1.232049325","rc":[{"batb":[[1,1.04,2.47],[2,1.03,200]],"ltp":1.72,"tv":10.64,"id":72857115}]}]}
{"op":"mcm","clk":"11895253634","pt":1724248931549,"mc":[{"id":"1.232049325","rc":[{"batb":[[0,1.47,10],[1,1.46,13],[2,1.45,1.76]],"ltp":2.1,"tv":46.54,"id":67083366},{"batb":[[0,1.58,1.83],[1,1.04,1.53]],"ltp":1.72,"tv":10.64,"id":72857115}]}]}
{"op":"mcm","clk":"11895253889","pt":1724248934380,"mc":[{"id":"1.232049325","rc":[{"batb":[[0,1.46,13],[1,1.45,1.76],[2,1.02,200]],"ltp":2.1,"tv":46.54,"id":67083366},{"batb":[[0,1.59,4.89],[1,1.04,2.47]],"ltp":1.72,"tv":10.64,"id":72857115}]}]}
{"op":"mcm","clk":"11895253918","pt":1724248934690,"mc":[{"id":"1.232049325","rc":[{"batb":[[0,1.6,10.89],[1,1.59,4],[2,1.04,2.47]],"ltp":1.72,"tv":10.64,"id":72857115}]}]}
{"op":"mcm","clk":"11895254101","pt":1724248937064,"mc":[{"id":"1.232049325","rc":[{"batb":[[0,1.47,10],[1,1.46,13],[2,1.45,1.76]],"ltp":2.1,"tv":46.54,"id":67083366},{"batb":[[1,1.04,2.47],[2,1.03,200]],"ltp":1.72,"tv":10.64,"id":72857115}]}]}
{"op":"mcm","clk":"11895254192","pt":1724248937996,"mc":[{"id":"1.232049325","rc":[{"batb":[[0,1.58,1.83],[1,1.04,1.53]],"ltp":1.72,"tv":10.64,"id":72857115}]}]}
{"op":"mcm","clk":"11895254435","pt":1724248940489,"mc":[{"id":"1.232049325","rc":[{"batb":[[0,1.46,13],[1,1.45,1.76],[2,1.02,200]],"ltp":2.1,"tv":46.54,"id":67083366}]}]}
{"op":"mcm","clk":"11895254480","pt":1724248940953,"mc":[{"id":"1.232049325","rc":[{"batb":[[0,1.6,10.89],[1,1.59,4],[2,1.04,2.47]],"ltp":1.72,"tv":10.64,"id":72857115}]}]}
{"op":"mcm","clk":"11895254689","pt":1724248943277,"mc":[{"id":"1.232049325","rc":[{"batb":[[0,1.47,10],[1,1.46,13],[2,1.45,1.76]],"ltp":2.1,"tv":46.54,"id":67083366},{"batb":[[1,1.04,2.47],[2,1.03,200]],"ltp":1.72,"tv":10.64,"id":72857115}]}]}
{"op":"mcm","clk":"11895254772","pt":1724248944167,"mc":[{"id":"1.232049325","rc":[{"batb":[[0,1.58,1.83],[1,1.04,1.53]],"ltp":1.72,"tv":10.64,"id":72857115}]}]}
{"op":"mcm","clk":"11895255055","pt":1724248947479,"mc":[{"id":"1.232049325","rc":[{"batb":[[0,1.46,13],[1,1.45,1.76],[2,1.02,200]],"ltp":2.1,"tv":46.54,"id":67083366},{"batb":[[0,1.6,10.89],[1,1.59,4],[2,1.04,2.47]],"ltp":1.72,"tv":10.64,"id":72857115}]}]}
{"op":"mcm","clk":"11895255203","pt":1724248949494,"mc":[{"id":"1.232049325","rc":[{"batb":[[1,1.04,2.47],[2,1.03,200]],"ltp":1.72,"tv":10.64,"id":72857115}]}]}
{"op":"mcm","clk":"11895255221","pt":1724248949700,"mc":[{"id":"1.232049325","rc":[{"batb":[[0,1.47,10],[1,1.46,13],[2,1.45,1.76]],"ltp":2.1,"tv":46.54,"id":67083366}]}]}
{"op":"mcm","clk":"11895255327","pt":1724248950990,"mc":[{"id":"1.232049325","rc":[{"batb":[[0,1.58,1.83],[1,1.04,1.53]],"ltp":1.72,"tv":10.64,"id":72857115}]}]}
{"op":"mcm","clk":"11895255518","pt":1724248953406,"mc":[{"id":"1.232049325","rc":[{"batb":[[0,1.46,13],[1,1.45,1.76],[2,1.02,200]],"ltp":2.1,"tv":46.54,"id":67083366},{"batb":[[0,1.59,4.89],[1,1.04,2.47]],"ltp":1.72,"tv":10.64,"id":72857115}]}]}
{"op":"mcm","clk":"11895255544","pt":1724248953678,"mc":[{"id":"1.232049325","rc":[{"batb":[[0,1.6,10.89],[1,1.59,4],[2,1.04,2.47]],"ltp":1.72,"tv":10.64,"id":72857115}]}]}
{"op":"mcm","clk":"11895255718","pt":1724248955707,"mc":[{"id":"1.232049325","rc":[{"batb":[[0,1.47,10],[1,1.46,13],[2,1.45,1.76]],"ltp":2.1,"tv":46.54,"id":67083366},{"batb":[[1,1.04,2.47],[2,1.03,200]],"ltp":1.72,"tv":10.64,"id":72857115}]}]}
{"op":"mcm","clk":"11895255826","pt":1724248957098,"mc":[{"id":"1.232049325","rc":[{"batb":[[0,1.58,1.83],[1,1.04,1.53]],"ltp":1.72,"tv":10.64,"id":72857115}]}]}
{"op":"mcm","clk":"11895256027","pt":1724248959519,"mc":[{"id":"1.232049325","rc":[{"batb":[[0,1.46,13],[1,1.45,1.76],[2,1.02,200]],"ltp":2.1,"tv":46.54,"id":67083366},{"batb":[[0,1.59,4.89],[1,1.04,2.47]],"ltp":1.72,"tv":10.64,"id":72857115}]}]}
{"op":"mcm","clk":"11895256078","pt":1724248960092,"mc":[{"id":"1.232049325","rc":[{"batb":[[0,1.6,10.89],[1,1.59,4],[2,1.04,2.47]],"ltp":1.72,"tv":10.64,"id":72857115}]}]}
{"op":"mcm","clk":"11895256264","pt":1724248962314,"mc":[{"id":"1.232049325","rc":[{"batb":[[0,1.47,10],[1,1.46,13],[2,1.45,1.76]],"ltp":2.1,"tv":46.54,"id":67083366},{"batb":[[1,1.04,2.47],[2,1.03,200]],"ltp":1.72,"tv":10.64,"id":72857115}]}]}
{"op":"mcm","clk":"11895256409","pt":1724248963417,"mc":[{"id":"1.232049325","rc":[{"batb":[[0,1.58,1.83],[1,1.04,1.53]],"ltp":1.72,"tv":10.64,"id":72857115}]}]}
{"op":"mcm","clk":"11895256703","pt":1724248966389,"mc":[{"id":"1.232049325","rc":[{"batb":[[0,1.46,13],[1,1.45,1.76],[2,1.02,200]],"ltp":2.1,"tv":46.54,"id":67083366},{"batb":[[0,1.6,10.89],[1,1.59,4],[2,1.04,2.47]],"ltp":1.72,"tv":10.64,"id":72857115}]}]}
{"op":"mcm","clk":"11895256902","pt":1724248968516,"mc":[{"id":"1.232049325","rc":[{"batb":[[1,1.04,2.47],[2,1.03,200]],"ltp":1.72,"tv":10.64,"id":72857115}]}]}
{"op":"mcm","clk":"11895256937","pt":1724248968827,"mc":[{"id":"1.232049325","rc":[{"batb":[[0,1.47,10],[1,1.46,13],[2,1.45,1.76]],"ltp":2.1,"tv":46.54,"id":67083366}]}]}
{"op":"mcm","clk":"11895257046","pt":1724248969818,"mc":[{"id":"1.232049325","rc":[{"batb":[[0,1.58,1.83],[1,1.04,1.53]],"ltp":1.72,"tv":10.64,"id":72857115}]}]}
{"op":"mcm","clk":"11895257293","pt":1724248972511,"mc":[{"id":"1.232049325","rc":[{"batb":[[0,1.46,13],[1,1.45,1.76],[2,1.02,200]],"ltp":2.1,"tv":46.54,"id":67083366},{"batb":[[0,1.59,4.89],[1,1.04,2.47]],"ltp":1.72,"tv":10.64,"id":72857115}]}]}
{"op":"mcm","clk":"11895257306","pt":1724248972615,"mc":[{"id":"1.232049325","rc":[{"batb":[[0,1.6,10.89],[1,1.59,4],[2,1.04,2.47]],"ltp":1.72,"tv":10.64,"id":72857115}]}]}
{"op":"mcm","clk":"11895257551","pt":1724248975006,"mc":[{"id":"1.232049325","rc":[{"batb":[[0,1.47,10],[1,1.46,13],[2,1.45,1.76]],"ltp":2.1,"tv":46.54,"id":67083366},{"batb":[[1,1.04,2.47],[2,1.03,200]],"ltp":1.72,"tv":10.64,"id":72857115}]}]}
{"op":"mcm","clk":"11895257644","pt":1724248976100,"mc":[{"id":"1.232049325","rc":[{"batb":[[0,1.58,1.83],[1,1.04,1.53]],"ltp":1.72,"tv":10.64,"id":72857115}]}]}
{"op":"mcm","clk":"11895257868","pt":1724248978329,"mc":[{"id":"1.232049325","rc":[{"batb":[[0,1.46,13],[1,1.45,1.76],[2,1.02,200]],"ltp":2.1,"tv":46.54,"id":67083366}]}]}
{"op":"mcm","clk":"11895257932","pt":1724248978898,"mc":[{"id":"1.232049325","rc":[{"batb":[[0,1.6,10.89],[1,1.59,4],[2,1.04,2.47]],"ltp":1.72,"tv":10.64,"id":72857115}]}]}
{"op":"mcm","clk":"11895258211","pt":1724248981497,"mc":[{"id":"1.232049325","rc":[{"batb":[[0,1.47,10],[1,1.46,13],[2,1.45,1.76]],"ltp":2.1,"tv":46.54,"id":67083366},{"batb":[[1,1.04,2.47],[2,1.03,200]],"ltp":1.72,"tv":10.64,"id":72857115}]}]}
{"op":"mcm","clk":"11895258383","pt":1724248983144,"mc":[{"id":"1.232049325","rc":[{"batb":[[0,1.59,4.89]],"ltp":1.72,"tv":10.64,"id":72857115}]}]}
{"op":"mcm","clk":"11895258594","pt":1724248985112,"mc":[{"id":"1.232049325","rc":[{"batb":[[0,1.46,13],[1,1.45,1.76],[2,1.02,200]],"ltp":2.1,"tv":46.54,"id":67083366},{"batb":[[0,1.6,10.89],[1,1.59,4],[2,1.04,2.47]],"ltp":1.72,"tv":10.64,"id":72857115}]}]}
{"op":"mcm","clk":"11895258636","pt":1724248985609,"mc":[{"id":"1.232049325","rc":[{"batb":[[1,1.04,2.47],[2,1.03,200]],"ltp":1.72,"tv":10.64,"id":72857115}]}]}
{"op":"mcm","clk":"11895258896","pt":1724248988542,"mc":[{"id":"1.232049325","rc":[{"batb":[[0,1.58,1.83],[1,1.04,1.53]],"ltp":1.72,"tv":10.64,"id":72857115}]}]}
{"op":"mcm","clk":"11895258927","pt":1724248988848,"mc":[{"id":"1.232049325","rc":[{"batb":[[0,1.47,10],[1,1.46,13],[2,1.45,1.76]],"ltp":2.1,"tv":46.54,"id":67083366},{"batb":[[0,1.59,4.89],[1,1.04,2.47]],"ltp":1.72,"tv":10.64,"id":72857115}]}]}
{"op":"mcm","clk":"11895259186","pt":1724248991323,"mc":[{"id":"1.232049325","rc":[{"batb":[[0,1.58,1.83],[1,1.04,1.53]],"ltp":1.72,"tv":10.64,"id":72857115}]}]}
{"op":"mcm","clk":"11895259257","pt":1724248992145,"mc":[{"id":"1.232049325","rc":[{"batb":[[0,1.46,13],[1,1.45,1.76],[2,1.02,200]],"ltp":2.1,"tv":46.54,"id":67083366}]}]}
{"op":"mcm","clk":"11895295288","pt":1724249379338,"mc":[{"id":"1.232049325","rc":[{"batb":[[0,1.47,10],[1,1.46,13],[2,1.45,1.76]],"ltp":2.1,"tv":46.54,"id":67083366},{"batb":[[0,1.6,10.89],[1,1.59,4],[2,1.04,2.47]],"ltp":1.72,"tv":10.64,"id":72857115}]}]}
{"op":"mcm","clk":"11895295562","pt":1724249381720,"mc":[{"id":"1.232049325","rc":[{"batb":[[1,1.04,2.47],[2,1.03,200]],"ltp":1.72,"tv":10.64,"id":72857115}]}]}
{"op":"mcm","clk":"11895295648","pt":1724249382595,"mc":[{"id":"1.232049325","rc":[{"batb":[[0,1.46,13],[1,1.45,1.76],[2,1.02,200]],"ltp":2.1,"tv":46.54,"id":67083366}]}]}
{"op":"mcm","clk":"11895295739","pt":1724249383624,"mc":[{"id":"1.232049325","rc":[{"batb":[[0,1.58,1.83],[1,1.04,1.53]],"ltp":1.72,"tv":10.64,"id":72857115}]}]}
{"op":"mcm","clk":"11895309179","pt":1724249523571,"mc":[{"id":"1.232049325","rc":[{"batb":[[0,1.47,10],[1,1.46,13],[2,1.45,1.76]],"ltp":2.1,"tv":46.54,"id":67083366},{"batb":[[0,1.59,4.89],[1,1.04,2.47]],"ltp":1.72,"tv":10.64,"id":72857115}]}]}
{"op":"mcm","clk":"11895309278","pt":1724249524552,"mc":[{"id":"1.232049325","rc":[{"batb":[[0,1.6,10.89],[1,1.59,4],[2,1.04,2.47]],"ltp":1.72,"tv":10.64,"id":72857115}]}]}
{"op":"mcm","clk":"11895309450","pt":1724249526574,"mc":[{"id":"1.232049325","rc":[{"batb":[[1,1.04,2.47],[2,1.03,200]],"ltp":1.72,"tv":10.64,"id":72857115}]}]}
{"op":"mcm","clk":"11895309518","pt":1724249527486,"mc":[{"id":"1.232049325","rc":[{"batb":[[0,1.46,13],[1,1.45,1.76],[2,1.02,200]],"ltp":2.1,"tv":46.54,"id":67083366}]}]}
{"op":"mcm","clk":"11895309596","pt":1724249528471,"mc":[{"id":"1.232049325","rc":[{"batb":[[0,1.58,1.83],[1,1.04,1.53]],"ltp":1.72,"tv":10.64,"id":72857115}]}]}
{"op":"mcm","clk":"11895309622","pt":1724249528787,"mc":[{"id":"1.232049325","rc":[{"batb":[[0,1.59,4.89],[1,1.04,2.47]],"ltp":1.72,"tv":10.64,"id":72857115}]}]}
{"op":"mcm","clk":"11895309851","pt":1724249531278,"mc":[{"id":"1.232049325","rc":[{"batb":[[0,1.58,1.83],[1,1.04,1.53]],"ltp":1.72,"tv":10.64,"id":72857115}]}]}
{"op":"mcm","clk":"11895309891","pt":1724249531684,"mc":[{"id":"1.232049325","rc":[{"batb":[[0,1.47,10],[1,1.46,13],[2,1.45,1.76]],"ltp":2.1,"tv":46.54,"id":67083366}]}]}
{"op":"mcm","clk":"11895310226","pt":1724249535576,"mc":[{"id":"1.232049325","rc":[{"batb":[[0,1.46,13],[1,1.45,1.76],[2,1.02,200]],"ltp":2.1,"tv":46.54,"id":67083366},{"batb":[[0,1.59,4.89],[1,1.04,2.47]],"ltp":1.72,"tv":10.64,"id":72857115}]}]}
{"op":"mcm","clk":"11895310232","pt":1724249535680,"mc":[{"id":"1.232049325","rc":[{"batb":[[0,1.6,10.89],[1,1.59,4],[2,1.04,2.47]],"ltp":1.72,"tv":10.64,"id":72857115}]}]}
{"op":"mcm","clk":"11895310408","pt":1724249538074,"mc":[{"id":"1.232049325","rc":[{"batb":[[0,1.47,10],[1,1.46,13],[2,1.45,1.76]],"ltp":2.1,"tv":46.54,"id":67083366},{"batb":[[1,1.04,2.47],[2,1.03,200]],"ltp":1.72,"tv":10.64,"id":72857115}]}]}
{"op":"mcm","clk":"11895310500","pt":1724249539104,"mc":[{"id":"1.232049325","rc":[{"batb":[[0,1.58,1.83],[1,1.04,1.53]],"ltp":1.72,"tv":10.64,"id":72857115}]}]}
{"op":"mcm","clk":"11895310722","pt":1724249541399,"mc":[{"id":"1.232049325","rc":[{"batb":[[0,1.46,13],[1,1.45,1.76],[2,1.02,200]],"ltp":2.1,"tv":46.54,"id":67083366}]}]}
{"op":"mcm","clk":"11895310861","pt":1724249541871,"mc":[{"id":"1.232049325","rc":[{"batb":[[0,1.6,10.89],[1,1.59,4],[2,1.04,2.47]],"ltp":1.72,"tv":10.64,"id":72857115}]}]}
{"op":"mcm","clk":"11895311124","pt":1724249544191,"mc":[{"id":"1.232049325","rc":[{"batb":[[0,1.47,10],[1,1.46,13],[2,1.45,1.76]],"ltp":2.1,"tv":46.54,"id":67083366},{"batb":[[1,1.04,2.47],[2,1.03,200]],"ltp":1.72,"tv":10.64,"id":72857115}]}]}
{"op":"mcm","clk":"11895311293","pt":1724249546089,"mc":[{"id":"1.232049325","rc":[{"batb":[[0,1.59,4.89]],"ltp":1.72,"tv":10.64,"id":72857115}]}]}
{"op":"mcm","clk":"11895311404","pt":1724249547483,"mc":[{"id":"1.232049325","rc":[{"batb":[[0,1.46,13],[1,1.45,1.76],[2,1.02,200]],"ltp":2.1,"tv":46.54,"id":67083366}]}]}
{"op":"mcm","clk":"11895311503","pt":1724249548970,"mc":[{"id":"1.232049325","rc":[{"batb":[[0,1.58,1.83],[1,1.04,1.53]],"ltp":1.72,"tv":10.64,"id":72857115}]}]}
{"op":"mcm","clk":"11895321625","pt":1724249669403,"mc":[{"id":"1.232049325","rc":[{"batb":[[0,1.47,10],[1,1.46,13],[2,1.45,1.76]],"ltp":2.1,"tv":46.54,"id":67083366},{"batb":[[0,1.59,4.89],[1,1.04,2.47]],"ltp":1.72,"tv":10.64,"id":72857115}]}]}
{"op":"mcm","clk":"11895321854","pt":1724249672500,"mc":[{"id":"1.232049325","rc":[{"batb":[[0,1.58,1.83],[1,1.04,1.53]],"ltp":1.72,"tv":10.64,"id":72857115}]}]}
{"op":"mcm","clk":"11895321942","pt":1724249673841,"mc":[{"id":"1.232049325","rc":[{"batb":[[0,1.46,13],[1,1.45,1.76],[2,1.02,200]],"ltp":2.1,"tv":46.54,"id":67083366},{"batb":[[0,1.6,10.89],[1,1.04,2.47]],"ltp":1.72,"tv":10.64,"id":72857115}]}]}
{"op":"mcm","clk":"11895322310","pt":1724249679008,"mc":[{"id":"1.232049325","rc":[{"batb":[[0,1.48,10],[1,1.46,13],[2,1.45,1.76]],"ltp":2.1,"tv":46.54,"id":67083366},{"batb":[[1,1.59,4],[2,1.04,2.47]],"ltp":1.72,"tv":10.64,"id":72857115}]}]}
{"op":"mcm","clk":"11895322649","pt":1724249683475,"mc":[{"id":"1.232049325","rc":[{"batb":[[0,1.59,4.89],[1,1.04,2.47],[2,1.03,200]],"ltp":1.72,"tv":10.64,"id":72857115}]}]}
{"op":"mcm","clk":"11895322940","pt":1724249687707,"mc":[{"id":"1.232049325","rc":[{"batb":[[0,1.61,10.89],[1,1.59,4],[2,1.04,2.47]],"ltp":1.72,"tv":10.64,"id":72857115}]}]}
{"op":"mcm","clk":"11895323207","pt":1724249689925,"mc":[{"id":"1.232049325","rc":[{"batb":[[1,1.04,2.47],[2,1.03,200]],"ltp":1.72,"tv":10.64,"id":72857115}]}]}
{"op":"mcm","clk":"11895323271","pt":1724249690958,"mc":[{"id":"1.232049325","rc":[{"batb":[[0,1.46,13],[1,1.45,1.76],[2,1.02,200]],"ltp":2.1,"tv":46.54,"id":67083366}]}]}
{"op":"mcm","clk":"11895323527","pt":1724249693958,"mc":[{"id":"1.232049325","rc":[{"batb":[[0,1.49,10],[1,1.46,13],[2,1.45,1.76]],"ltp":2.1,"tv":46.54,"id":67083366},{"batb":[[0,1.62,4.89],[1,1.61,10],[2,1.04,2.47]],"ltp":1.72,"tv":10.64,"id":72857115}]}]}
{"op":"mcm","clk":"11895323730","pt":1724249696845,"mc":[{"id":"1.232049325","rc":[{"batb":[[1,1.04,2.47],[2,1.03,200]],"ltp":1.72,"tv":10.64,"id":72857115}]}]}
{"op":"mcm","clk":"11895324043","pt":1724249701248,"mc":[{"id":"1.232049325","rc":[{"batb":[[0,1.63,10.89]],"ltp":1.72,"tv":10.64,"id":72857115}]}]}
{"op":"mcm","clk":"11895324077","pt":1724249701773,"mc":[{"id":"1.232049325","rc":[{"batb":[[0,1.46,13],[1,1.45,1.76],[2,1.02,200]],"ltp":2.1,"tv":46.54,"id":67083366}]}]}
{"op":"mcm","clk":"11895324329","pt":1724249704541,"mc":[{"id":"1.232049325","rc":[{"batb":[[1,1.59,4],[2,1.04,2.47]],"ltp":1.72,"tv":10.64,"id":72857115}]}]}
{"op":"mcm","clk":"11895324334","pt":1724249704647,"mc":[{"id":"1.232049325","rc":[{"batb":[[0,1.5,10],[1,1.46,13],[2,1.45,1.76]],"ltp":2.1,"tv":46.54,"id":67083366}]}]}
{"op":"mcm","clk":"11895324753","pt":1724249708175,"mc":[{"id":"1.232049325","rc":[{"batb":[[0,1.59,4.89],[1,1.04,2.47],[2,1.03,200]],"ltp":1.72,"tv":10.64,"id":72857115}]}]}
{"op":"mcm","clk":"11895324999","pt":1724249709967,"mc":[{"id":"1.232049325","rc":[{"batb":[[0,1.58,1.83],[1,1.04,1.53]],"ltp":1.72,"tv":10.64,"id":72857115}]}]}
{"op":"mcm","clk":"11895325142","pt":1724249711385,"mc":[{"id":"1.232049325","rc":[{"batb":[[0,1.46,13],[1,1.45,1.76],[2,1.02,200]],"ltp":2.1,"tv":46.54,"id":67083366},{"batb":[[0,1.6,10.89],[1,1.04,2.47]],"ltp":1.72,"tv":10.64,"id":72857115}]}]}
{"op":"mcm","clk":"11895325221","pt":1724249712263,"mc":[{"id":"1.232049325","rc":[{"batb":[[1,1.59,4],[2,1.04,2.47]],"ltp":1.72,"tv":10.64,"id":72857115}]}]}
{"op":"mcm","clk":"11895325395","pt":1724249713779,"mc":[{"id":"1.232049325","rc":[{"batb":[[0,1.47,10],[1,1.46,13],[2,1.45,1.76]],"ltp":2.1,"tv":46.54,"id":67083366}]}]}
{"op":"mcm","clk":"11895325669","pt":1724249716443,"mc":[{"id":"1.232049325","rc":[{"batb":[[0,1.59,4.89],[1,1.04,2.47],[2,1.03,200]],"ltp":1.72,"tv":10.64,"id":72857115}]}]}
{"op":"mcm","clk":"11895325710","pt":1724249716961,"mc":[{"id":"1.232049325","rc":[{"batb":[[0,1.58,1.83],[1,1.04,1.53]],"ltp":1.72,"tv":10.64,"id":72857115}]}]}
{"op":"mcm","clk":"11895325851","pt":1724249718867,"mc":[{"id":"1.232049325","rc":[{"batb":[[0,1.46,13],[1,1.45,1.76],[2,1.02,200]],"ltp":2.1,"tv":46.54,"id":67083366}]}]}
{"op":"mcm","clk":"11895325967","pt":1724249719955,"mc":[{"id":"1.232049325","rc":[{"batb":[[0,1.59,4.89],[1,1.04,2.47]],"ltp":1.72,"tv":10.64,"id":72857115}]}]}
{"op":"mcm","clk":"11895326075","pt":1724249721192,"mc":[{"id":"1.232049325","rc":[{"batb":[[0,1.47,10],[1,1.46,13],[2,1.45,1.76]],"ltp":2.1,"tv":46.54,"id":67083366},{"batb":[[0,1.6,10.89],[1,1.59,4],[2,1.04,2.47]],"ltp":1.72,"tv":10.64,"id":72857115}]}]}
{"op":"mcm","clk":"11895326245","pt":1724249723053,"mc":[{"id":"1.232049325","rc":[{"batb":[[1,1.04,2.47],[2,1.03,200]],"ltp":1.72,"tv":10.64,"id":72857115}]}]}
{"op":"mcm","clk":"11895326437","pt":1724249725380,"mc":[{"id":"1.232049325","rc":[{"batb":[[0,1.46,13],[1,1.45,1.76],[2,1.02,200]],"ltp":2.1,"tv":46.54,"id":67083366},{"batb":[[0,1.59,4.89]],"ltp":1.72,"tv":10.64,"id":72857115}]}]}
{"op":"mcm","clk":"11895326652","pt":1724249727999,"mc":[{"id":"1.232049325","rc":[{"batb":[[0,1.47,10],[1,1.46,13],[2,1.45,1.76]],"ltp":2.1,"tv":46.54,"id":67083366},{"batb":[[0,1.58,1.83],[1,1.04,1.53]],"ltp":1.72,"tv":10.64,"id":72857115}]}]}
{"op":"mcm","clk":"11895326951","pt":1724249731556,"mc":[{"id":"1.232049325","rc":[{"batb":[[0,1.46,13],[1,1.45,1.76],[2,1.02,200]],"batl":[[0,2.46,5.97],[1,2.58,0.94]],"ltp":2.1,"tv":46.54,"id":67083366},{"batb":[[0,1.59,4.89],[1,1.04,2.47]],"ltp":1.72,"tv":10.64,"id":72857115}]}]}
{"op":"mcm","clk":"11895326966","pt":1724249731762,"mc":[{"id":"1.232049325","rc":[{"batb":[[0,1.6,10.89],[1,1.59,4],[2,1.04,2.47]],"ltp":1.72,"tv":10.64,"id":72857115}]}]}
{"op":"mcm","clk":"11895327147","pt":1724249734087,"mc":[{"id":"1.232049325","rc":[{"batb":[[0,1.47,10],[1,1.46,13],[2,1.45,1.76]],"ltp":2.1,"tv":46.54,"id":67083366},{"batb":[[1,1.04,2.47],[2,1.03,200]],"ltp":1.72,"tv":10.64,"id":72857115}]}]}
{"op":"mcm","clk":"11895327249","pt":1724249735276,"mc":[{"id":"1.232049325","rc":[{"batb":[[0,1.58,1.83],[1,1.04,1.53]],"ltp":1.72,"tv":10.64,"id":72857115}]}]}
{"op":"mcm","clk":"11895327398","pt":1724249737506,"mc":[{"id":"1.232049325","rc":[{"batb":[[0,1.46,13],[1,1.45,1.76],[2,1.02,200]],"ltp":2.1,"tv":46.54,"id":67083366}]}]}
{"op":"mcm","clk":"11895327431","pt":1724249738421,"mc":[{"id":"1.232049325","rc":[{"batb":[[0,1.6,10.89],[1,1.59,4],[2,1.04,2.47]],"ltp":1.72,"tv":10.64,"id":72857115}]}]}
{"op":"mcm","clk":"11895327571","pt":1724249740477,"mc":[{"id":"1.232049325","rc":[{"batb":[[0,1.47,10],[1,1.46,13],[2,1.45,1.76]],"ltp":2.1,"tv":46.54,"id":67083366},{"batb":[[1,1.04,2.47],[2,1.03,200]],"ltp":1.72,"tv":10.64,"id":72857115}]}]}
{"op":"mcm","clk":"11895327653","pt":1724249741568,"mc":[{"id":"1.232049325","rc":[{"batb":[[0,1.58,1.83],[1,1.04,1.53]],"ltp":1.72,"tv":10.64,"id":72857115}]}]}
{"op":"mcm","clk":"11895327904","pt":1724249744576,"mc":[{"id":"1.232049325","rc":[{"batb":[[0,1.46,13],[1,1.45,1.76],[2,1.02,200]],"batl":[[0,2.46,6.91],[1,2.58,0]],"ltp":2.1,"tv":46.54,"id":67083366},{"batb":[[0,1.6,10.89],[1,1.59,4],[2,1.04,2.47]],"ltp":1.72,"tv":10.64,"id":72857115}]}]}
{"op":"mcm","clk":"11895328103","pt":1724249746806,"mc":[{"id":"1.232049325","rc":[{"batb":[[0,1.47,10],[1,1.46,13],[2,1.45,1.76]],"ltp":2.1,"tv":46.54,"id":67083366},{"batb":[[1,1.04,2.47],[2,1.03,200]],"ltp":1.72,"tv":10.64,"id":72857115}]}]}
{"op":"mcm","clk":"11895328181","pt":1724249747690,"mc":[{"id":"1.232049325","rc":[{"batb":[[0,1.58,1.83],[1,1.04,1.53]],"ltp":1.72,"tv":10.64,"id":72857115}]}]}
{"op":"mcm","clk":"11895328420","pt":1724249750585,"mc":[{"id":"1.232049325","rc":[{"batb":[[0,1.46,13],[1,1.45,1.76],[2,1.02,200]],"ltp":2.1,"tv":46.54,"id":67083366},{"batb":[[0,1.59,4.89],[1,1.04,2.47]],"ltp":1.72,"tv":10.64,"id":72857115}]}]}
{"op":"mcm","clk":"11895328434","pt":1724249750791,"mc":[{"id":"1.232049325","rc":[{"batb":[[0,1.6,10.89],[1,1.59,4],[2,1.04,2.47]],"ltp":1.72,"tv":10.64,"id":72857115}]}]}
{"op":"mcm","clk":"11895328639","pt":1724249753479,"mc":[{"id":"1.232049325","rc":[{"batb":[[0,1.47,10],[1,1.46,13],[2,1.45,1.76]],"ltp":2.1,"tv":46.54,"id":67083366},{"batb":[[1,1.04,2.47],[2,1.03,200]],"ltp":1.72,"tv":10.64,"id":72857115}]}]}
{"op":"mcm","clk":"11895328685","pt":1724249753997,"mc":[{"id":"1.232049325","rc":[{"batb":[[0,1.58,1.83],[1,1.04,1.53]],"ltp":1.72,"tv":10.64,"id":72857115}]}]}
{"op":"mcm","clk":"11895328917","pt":1724249757402,"mc":[{"id":"1.232049325","rc":[{"batb":[[0,1.47,1.76],[2,1.02,200]],"ltp":2.1,"tv":46.54,"id":67083366},{"batb":[[0,1.6,10.89],[1,1.59,4],[2,1.04,2.47]],"ltp":1.72,"tv":10.64,"id":72857115}]}]}
{"op":"mcm","clk":"11895329068","pt":1724249759420,"mc":[{"id":"1.232049325","rc":[{"batb":[[1,1.04,2.47],[2,1.03,200]],"ltp":1.72,"tv":10.64,"id":72857115}]}]}
{"op":"mcm","clk":"11895329236","pt":1724249761409,"mc":[{"id":"1.232049325","rc":[{"batb":[[0,1.58,1.83],[1,1.04,1.53]],"ltp":1.72,"tv":10.64,"id":72857115}]}]}
{"op":"mcm","clk":"11895329289","pt":1724249761980,"mc":[{"id":"1.232049325","rc":[{"batb":[[0,1.59,4.89],[1,1.04,2.47]],"ltp":1.72,"tv":10.64,"id":72857115}]}]}
{"op":"mcm","clk":"11895329525","pt":1724249764715,"mc":[{"id":"1.232049325","rc":[{"batb":[[0,1.58,1.83],[1,1.04,1.53]],"ltp":1.72,"tv":10.64,"id":72857115}]}]}
{"op":"mcm","clk":"11895330472","pt":1724249777334,"mc":[{"id":"1.232049325","rc":[{"batb":[[0,1.6,10.89],[1,1.59,4],[2,1.04,2.47]],"ltp":1.72,"tv":10.64,"id":72857115}]}]}
{"op":"mcm","clk":"11895330612","pt":1724249779205,"mc":[{"id":"1.232049325","rc":[{"batb":[[1,1.04,2.47],[2,1.03,200]],"ltp":1.72,"tv":10.64,"id":72857115}]}]}
{"op":"mcm","clk":"11895330758","pt":1724249781008,"mc":[{"id":"1.232049325","rc":[{"batb":[[0,1.58,1.83],[1,1.04,1.53]],"ltp":1.72,"tv":10.64,"id":72857115}]}]}
{"op":"mcm","clk":"11895330893","pt":1724249782714,"mc":[{"id":"1.232049325","rc":[{"batl":[[0,1.98,1.45],[1,2.46,5.97]],"ltp":2.1,"tv":46.54,"id":67083366},{"batb":[[0,1.59,4.89],[1,1.04,2.47]],"ltp":1.72,"tv":10.64,"id":72857115}]}]}
{"op":"mcm","clk":"11895331086","pt":1724249785108,"mc":[{"id":"1.232049325","rc":[{"batb":[[0,1.58,1.83],[1,1.04,1.53]],"ltp":1.72,"tv":10.64,"id":72857115}]}]}
{"op":"mcm","clk":"11895331529","pt":1724249790536,"mc":[{"id":"1.232049325","rc":[{"batb":[[0,1.04,2.42],[1,1.03,200],[2,1.02,200]],"ltp":1.72,"tv":10.64,"id":72857115}]}]}
{"op":"mcm","clk":"11895331573","pt":1724249790955,"mc":[{"id":"1.232049325","rc":[{"batb":[[0,1.06,10.89],[1,1.05,4],[2,1.04,1.53]],"ltp":1.72,"tv":10.64,"id":72857115}]}]}
{"op":"mcm","clk":"11895331757","pt":1724249793147,"mc":[{"id":"1.232049325","rc":[{"batb":[[1,1.04,1.53],[2,1.03,200]],"ltp":1.72,"tv":10.64,"id":72857115}]}]}
{"op":"mcm","clk":"11895331863","pt":1724249794338,"mc":[{"id":"1.232049325","rc":[{"batb":[[0,1.04,2.42],[1,1.03,200],[2,1.02,200]],"ltp":1.72,"tv":10.64,"id":72857115}]}]}
{"op":"mcm","clk":"11895332383","pt":1724249801557,"mc":[{"id":"1.232049325","rc":[{"batl":[[0,2.46,5.97],[1,2.46,0]],"ltp":2.1,"tv":46.54,"id":67083366}]}]}
{"op":"mcm","clk":"11895332469","pt":1724249802536,"mc":[{"id":"1.232049325","rc":[{"batl":[[0,2,1.44],[1,2.46,5.97]],"ltp":2.1,"tv":46.54,"id":67083366},{"batb":[[0,1.06,10.89],[1,1.05,4],[2,1.04,1.53]],"ltp":1.72,"tv":10.64,"id":72857115}]}]}
{"op":"mcm","clk":"11895332606","pt":1724249804447,"mc":[{"id":"1.232049325","rc":[{"batb":[[1,1.04,1.53],[2,1.03,200]],"ltp":1.72,"tv":10.64,"id":72857115}]}]}
{"op":"mcm","clk":"11895332692","pt":1724249805747,"mc":[{"id":"1.232049325","rc":[{"batb":[[0,1.04,2.42],[1,1.03,200],[2,1.02,200]],"ltp":1.72,"tv":10.64,"id":72857115}]}]}
{"op":"mcm","clk":"11895332919","pt":1724249808468,"mc":[{"id":"1.232049325","rc":[{"trd":[[2,2.87]],"batb":[[0,2,2.13],[1,1.47,1.76],[2,1.46,13]],"batl":[[0,2.46,5.97],[1,2.46,0]],"ltp":2.0,"tv":49.41,"id":67083366}],"tv":60.05}]}
{"op":"mcm","clk":"11895332956","pt":1724249808949,"mc":[{"id":"1.232049325","rc":[{"batb":[[0,1.06,10.89],[1,1.05,4],[2,1.04,1.53]],"ltp":1.72,"tv":10.64,"id":72857115}]}]}
{"op":"mcm","clk":"11895333111","pt":1724249811042,"mc":[{"id":"1.232049325","rc":[{"batb":[[1,1.04,1.53],[2,1.03,200]],"ltp":1.72,"tv":10.64,"id":72857115}]}]}
{"op":"mcm","clk":"11895333204","pt":1724249812262,"mc":[{"id":"1.232049325","rc":[{"batb":[[0,1.04,2.42],[1,1.03,200],[2,1.02,200]],"ltp":1.72,"tv":10.64,"id":72857115}]}]}
{"op":"mcm","clk":"11895333367","pt":1724249814069,"mc":[{"id":"1.232049325","rc":[{"batb":[[0,1.47,1.76],[1,1.46,13],[2,1.02,200]],"ltp":2.0,"tv":49.41,"id":67083366},{"batb":[[0,1.05,4.89],[1,1.04,1.53],[2,1.03,200]],"ltp":1.72,"tv":10.64,"id":72857115}]}]}
{"op":"mcm","clk":"11895333565","pt":1724249816280,"mc":[{"id":"1.232049325","rc":[{"batb":[[0,1.04,2.42],[1,1.03,200],[2,1.02,200]],"ltp":1.72,"tv":10.64,"id":72857115}]}]}
{"op":"mcm","clk":"11895334273","pt":1724249825191,"mc":[{"id":"1.232049325","rc":[{"batl":[[0,2.46,6.91]],"ltp":2.0,"tv":49.41,"id":67083366},{"batb":[[0,1.06,10.89],[1,1.05,4],[2,1.04,1.53]],"ltp":1.72,"tv":10.64,"id":72857115}]}]}
{"op":"mcm","clk":"11895334517","pt":1724249827666,"mc":[{"id":"1.232049325","rc":[{"batb":[[1,1.04,1.53],[2,1.03,200]],"ltp":1.72,"tv":10.64,"id":72857115}]}]}
{"op":"mcm","clk":"11895334617","pt":1724249828798,"mc":[{"id":"1.232049325","rc":[{"batb":[[0,1.04,2.42],[1,1.03,200],[2,1.02,200]],"ltp":1.72,"tv":10.64,"id":72857115}]}]}
{"op":"mcm","clk":"11895335349","pt":1724249837490,"mc":[{"id":"1.232049325","rc":[{"batb":[[0,1.47,2.69]],"ltp":2.0,"tv":49.41,"id":67083366}]}]}
{"op":"mcm","clk":"11895335385","pt":1724249838004,"mc":[{"id":"1.232049325","rc":[{"batb":[[0,1.06,10.89],[1,1.05,4],[2,1.04,1.53]],"ltp":1.72,"tv":10.64,"id":72857115}]}]}
{"op":"mcm","clk":"11895335544","pt":1724249839873,"mc":[{"id":"1.232049325","rc":[{"batb":[[1,1.04,1.53],[2,1.03,200]],"ltp":1.72,"tv":10.64,"id":72857115}]}]}
{"op":"mcm","clk":"11895335667","pt":1724249841421,"mc":[{"id":"1.232049325","rc":[{"batb":[[0,1.04,2.42],[1,1.03,200],[2,1.02,200]],"ltp":1.72,"tv":10.64,"id":72857115}]}]}
{"op":"mcm","clk":"11895343704","pt":1724249932269,"mc":[{"id":"1.232049325","rc":[{"batb":[[0,1.05,4.89],[1,1.04,1.53],[2,1.03,200]],"ltp":1.72,"tv":10.64,"id":72857115}]}]}
{"op":"mcm","clk":"11895343786","pt":1724249933195,"mc":[{"id":"1.232049325","rc":[{"batb":[[0,1.06,10.89],[1,1.05,4],[2,1.04,1.53]],"ltp":1.72,"tv":10.64,"id":72857115}]}]}
{"op":"mcm","clk":"11895343948","pt":1724249935204,"mc":[{"id":"1.232049325","rc":[{"batb":[[1,1.04,1.53],[2,1.03,200]],"ltp":1.72,"tv":10.64,"id":72857115}]}]}
{"op":"mcm","clk":"11895344071","pt":1724249936710,"mc":[{"id":"1.232049325","rc":[{"batb":[[0,1.04,2.42],[1,1.03,200],[2,1.02,200]],"ltp":1.72,"tv":10.64,"id":72857115}]}]}
{"op":"mcm","clk":"11895345571","pt":1724249953111,"mc":[{"id":"1.232049325","rc":[{"batb":[[0,1.05,4.89],[1,1.04,1.53],[2,1.03,200]],"ltp":1.72,"tv":10.64,"id":72857115}]}]}
{"op":"mcm","clk":"11895345633","pt":1724249953725,"mc":[{"id":"1.232049325","rc":[{"batb":[[0,1.06,10.89],[1,1.05,4],[2,1.04,1.53]],"ltp":1.72,"tv":10.64,"id":72857115}]}]}
{"op":"mcm","clk":"11895345811","pt":1724249955627,"mc":[{"id":"1.232049325","rc":[{"batb":[[1,1.04,1.53],[2,1.03,200]],"ltp":1.72,"tv":10.64,"id":72857115}]}]}
{"op":"mcm","clk":"11895345958","pt":1724249957528,"mc":[{"id":"1.232049325","rc":[{"batb":[[0,1.04,2.42],[1,1.03,200],[2,1.02,200]],"ltp":1.72,"tv":10.64,"id":72857115}]}]}
{"op":"mcm","clk":"11895345976","pt":1724249957836,"mc":[{"id":"1.232049325","rc":[{"batb":[[0,1.05,4.89],[1,1.04,1.53],[2,1.03,200]],"ltp":1.72,"tv":10.64,"id":72857115}]}]}
{"op":"mcm","clk":"11895346153","pt":1724249960310,"mc":[{"id":"1.232049325","rc":[{"batb":[[0,1.04,2.42],[1,1.03,200],[2,1.02,200]],"ltp":1.72,"tv":10.64,"id":72857115}]}]}
{"op":"mcm","clk":"11895347231","pt":1724249972918,"mc":[{"id":"1.232049325","rc":[{"batb":[[0,1.06,10.89],[1,1.05,4],[2,1.04,1.53]],"ltp":1.72,"tv":10.64,"id":72857115}]}]}
{"op":"mcm","clk":"11895347439","pt":1724249975540,"mc":[{"id":"1.232049325","rc":[{"batb":[[1,1.04,1.53],[2,1.03,200]],"ltp":1.72,"tv":10.64,"id":72857115}]}]}
{"op":"mcm","clk":"11895347554","pt":1724249976933,"mc":[{"id":"1.232049325","rc":[{"batb":[[0,1.04,2.42],[1,1.03,200],[2,1.02,200]],"ltp":1.72,"tv":10.64,"id":72857115}]}]}
{"op":"mcm","clk":"11895350442","pt":1724250012495,"mc":[{"id":"1.232049325","rc":[{"batb":[[0,1.05,4.89],[1,1.04,1.53],[2,1.03,200]],"ltp":1.72,"tv":10.64,"id":72857115}]}]}
{"op":"mcm","clk":"11895350513","pt":1724250013177,"mc":[{"id":"1.232049325","rc":[{"batb":[[0,1.06,10.89],[1,1.05,4],[2,1.04,1.53]],"ltp":1.72,"tv":10.64,"id":72857115}]}]}
{"op":"mcm","clk":"11895350707","pt":1724250015373,"mc":[{"id":"1.232049325","rc":[{"batb":[[1,1.04,1.53],[2,1.03,200]],"ltp":1.72,"tv":10.64,"id":72857115}]}]}
{"op":"mcm","clk":"11895350901","pt":1724250017582,"mc":[{"id":"1.232049325","rc":[{"batb":[[0,1.05,4.89]],"ltp":1.72,"tv":10.64,"id":72857115}]}]}
{"op":"mcm","clk":"11895351104","pt":1724250019899,"mc":[{"id":"1.232049325","rc":[{"batb":[[0,1.04,2.42],[1,1.03,200],[2,1.02,200]],"ltp":1.72,"tv":10.64,"id":72857115}]}]}
{"op":"mcm","clk":"11895352762","pt":1724250041269,"mc":[{"id":"1.232049325","rc":[{"batb":[[0,1.05,4.89],[1,1.04,1.53],[2,1.03,200]],"ltp":1.72,"tv":10.64,"id":72857115}]}]}
{"op":"mcm","clk":"11895352799","pt":1724250041632,"mc":[{"id":"1.232049325","rc":[{"batb":[[0,1.06,10.89],[1,1.05,4],[2,1.04,1.53]],"ltp":1.72,"tv":10.64,"id":72857115}]}]}
{"op":"mcm","clk":"11895352963","pt":1724250043538,"mc":[{"id":"1.232049325","rc":[{"batb":[[1,1.04,1.53],[2,1.03,200]],"ltp":1.72,"tv":10.64,"id":72857115}]}]}
{"op":"mcm","clk":"11895353139","pt":1724250045345,"mc":[{"id":"1.232049325","rc":[{"batb":[[0,1.04,2.42],[1,1.03,200],[2,1.02,200]],"ltp":1.72,"tv":10.64,"id":72857115}]}]}
{"op":"mcm","clk":"11895355375","pt":1724250070789,"mc":[{"id":"1.232049325","rc":[{"batb":[[0,1.05,4.89],[1,1.04,1.53],[2,1.03,200]],"ltp":1.72,"tv":10.64,"id":72857115}]}]}
{"op":"mcm","clk":"11895355490","pt":1724250072177,"mc":[{"id":"1.232049325","rc":[{"batb":[[0,1.06,10.89],[1,1.05,4],[2,1.04,1.53]],"ltp":1.72,"tv":10.64,"id":72857115}]}]}
{"op":"mcm","clk":"11895355700","pt":1724250074492,"mc":[{"id":"1.232049325","rc":[{"batb":[[1,1.04,1.53],[2,1.03,200]],"ltp":1.72,"tv":10.64,"id":72857115}]}]}
{"op":"mcm","clk":"11895355855","pt":1724250076293,"mc":[{"id":"1.232049325","rc":[{"batb":[[0,1.04,2.42],[1,1.03,200],[2,1.02,200]],"ltp":1.72,"tv":10.64,"id":72857115}]}]}
{"op":"mcm","clk":"11895356487","pt":1724250084418,"mc":[{"id":"1.232049325","rc":[{"batb":[[0,1.05,4.89],[1,1.04,1.53],[2,1.03,200]],"ltp":1.72,"tv":10.64,"id":72857115}]}]}
{"op":"mcm","clk":"11895356502","pt":1724250084626,"mc":[{"id":"1.232049325","rc":[{"batb":[[0,1.06,10.89],[1,1.05,4],[2,1.04,1.53]],"ltp":1.72,"tv":10.64,"id":72857115}]}]}
{"op":"mcm","clk":"11895356642","pt":1724250086688,"mc":[{"id":"1.232049325","rc":[{"batb":[[1,1.04,1.53],[2,1.03,200]],"ltp":1.72,"tv":10.64,"id":72857115}]}]}
{"op":"mcm","clk":"11895356840","pt":1724250089305,"mc":[{"id":"1.232049325","rc":[{"batb":[[0,1.05,4.89]],"ltp":1.72,"tv":10.64,"id":72857115}]}]}
{"op":"mcm","clk":"11895357027","pt":1724250091826,"mc":[{"id":"1.232049325","rc":[{"batb":[[0,1.04,2.42],[1,1.03,200],[2,1.02,200]],"ltp":1.72,"tv":10.64,"id":72857115}]}]}
{"op":"mcm","clk":"11895359927","pt":1724250129446,"mc":[{"id":"1.232049325","rc":[{"batb":[[0,1.06,10.89],[1,1.05,4],[2,1.04,1.53]],"ltp":1.72,"tv":10.64,"id":72857115}]}]}
{"op":"mcm","clk":"11895360137","pt":1724250131671,"mc":[{"id":"1.232049325","rc":[{"batb":[[1,1.04,1.53],[2,1.03,200]],"ltp":1.72,"tv":10.64,"id":72857115}]}]}
{"op":"mcm","clk":"11895360264","pt":1724250133166,"mc":[{"id":"1.232049325","rc":[{"batb":[[0,1.04,2.42],[1,1.03,200],[2,1.02,200]],"ltp":1.72,"tv":10.64,"id":72857115}]}]}
{"op":"mcm","clk":"11895360741","pt":1724250138471,"mc":[{"id":"1.232049325","rc":[{"batb":[[0,1.06,10.89],[1,1.05,4],[2,1.04,1.53]],"ltp":1.72,"tv":10.64,"id":72857115}]}]}
{"op":"mcm","clk":"11895360899","pt":1724250140374,"mc":[{"id":"1.232049325","rc":[{"batb":[[1,1.04,1.53],[2,1.03,200]],"ltp":1.72,"tv":10.64,"id":72857115}]}]}
{"op":"mcm","clk":"11895361092","pt":1724250142536,"mc":[{"id":"1.232049325","rc":[{"batb":[[0,1.05,4.89]],"ltp":1.72,"tv":10.64,"id":72857115}]}]}
{"op":"mcm","clk":"11895361273","pt":1724250144851,"mc":[{"id":"1.232049325","rc":[{"batb":[[0,1.04,2.42],[1,1.03,200],[2,1.02,200]],"ltp":1.72,"tv":10.64,"id":72857115}]}]}
{"op":"mcm","clk":"11895361874","pt":1724250152300,"mc":[{"id":"1.232049325","rc":[{"batb":[[0,1.05,4.89],[1,1.04,1.53],[2,1.03,200]],"ltp":1.72,"tv":10.64,"id":72857115}]}]}
{"op":"mcm","clk":"11895361925","pt":1724250152869,"mc":[{"id":"1.232049325","rc":[{"batb":[[0,1.06,10.89],[1,1.05,4],[2,1.04,1.53]],"ltp":1.72,"tv":10.64,"id":72857115}]}]}
{"op":"mcm","clk":"11895362099","pt":1724250155085,"mc":[{"id":"1.232049325","rc":[{"batb":[[1,1.04,1.53],[2,1.03,200]],"ltp":1.72,"tv":10.64,"id":72857115}]}]}
{"op":"mcm","clk":"11895362236","pt":1724250156581,"mc":[{"id":"1.232049325","rc":[{"batb":[[0,1.04,2.42],[1,1.03,200],[2,1.02,200]],"ltp":1.72,"tv":10.64,"id":72857115}]}]}
{"op":"mcm","clk":"11895364744","pt":1724250188393,"mc":[{"id":"1.232049325","rc":[{"batb":[[0,1.05,4.89],[1,1.04,1.53],[2,1.03,200]],"ltp":1.72,"tv":10.64,"id":72857115}]}]}
{"op":"mcm","clk":"11895364763","pt":1724250188701,"mc":[{"id":"1.232049325","rc":[{"batb":[[0,1.06,10.89],[1,1.05,4],[2,1.04,1.53]],"ltp":1.72,"tv":10.64,"id":72857115}]}]}
{"op":"mcm","clk":"11895364923","pt":1724250190819,"mc":[{"id":"1.232049325","rc":[{"batb":[[1,1.04,1.53],[2,1.03,200]],"ltp":1.72,"tv":10.64,"id":72857115}]}]}
{"op":"mcm","clk":"11895365046","pt":1724250192509,"mc":[{"id":"1.232049325","rc":[{"batb":[[0,1.04,2.42],[1,1.03,200],[2,1.02,200]],"ltp":1.72,"tv":10.64,"id":72857115}]}]}
{"op":"mcm","clk":"11895367159","pt":1724250217430,"mc":[{"id":"1.232049325","rc":[{"batb":[[0,1.05,4.89],[1,1.04,1.53],[2,1.03,200]],"ltp":1.72,"tv":10.64,"id":72857115}]}]}
{"op":"mcm","clk":"11895367406","pt":1724250220778,"mc":[{"id":"1.232049325","rc":[{"batb":[[0,1.06,10.89],[1,1.05,4],[2,1.04,1.53]],"ltp":1.72,"tv":10.64,"id":72857115}]}]}
{"op":"mcm","clk":"11895367578","pt":1724250222943,"mc":[{"id":"1.232049325","rc":[{"batb":[[1,1.04,1.53],[2,1.03,200]],"ltp":1.72,"tv":10.64,"id":72857115}]}]}
{"op":"mcm","clk":"11895367816","pt":1724250226039,"mc":[{"id":"1.232049325","rc":[{"batb":[[0,1.04,2.42],[1,1.03,200],[2,1.02,200]],"ltp":1.72,"tv":10.64,"id":72857115}]}]}
{"op":"mcm","clk":"11895367859","pt":1724250226655,"mc":[{"id":"1.232049325","rc":[{"batb":[[0,1.05,4.89],[1,1.04,1.53],[2,1.03,200]],"ltp":1.72,"tv":10.64,"id":72857115}]}]}
{"op":"mcm","clk":"11895368140","pt":1724250229540,"mc":[{"id":"1.232049325","rc":[{"batb":[[0,1.04,2.42],[1,1.03,200],[2,1.02,200]],"ltp":1.72,"tv":10.64,"id":72857115}]}]}
{"op":"mcm","clk":"11895369411","pt":1724250244263,"mc":[{"id":"1.232049325","rc":[{"batb":[[0,1.05,4.89],[1,1.04,1.53],[2,1.03,200]],"ltp":1.72,"tv":10.64,"id":72857115}]}]}
{"op":"mcm","clk":"11895369471","pt":1724250244886,"mc":[{"id":"1.232049325","rc":[{"batb":[[0,1.06,10.89],[1,1.05,4],[2,1.04,1.53]],"ltp":1.72,"tv":10.64,"id":72857115}]}]}
{"op":"mcm","clk":"11895369655","pt":1724250246998,"mc":[{"id":"1.232049325","rc":[{"batb":[[1,1.04,1.53],[2,1.03,200]],"ltp":1.72,"tv":10.64,"id":72857115}]}]}
{"op":"mcm","clk":"11895369801","pt":1724250248800,"mc":[{"id":"1.232049325","rc":[{"batb":[[0,1.04,2.42],[1,1.03,200],[2,1.02,200]],"ltp":1.72,"tv":10.64,"id":72857115}]}]}
{"op":"mcm","clk":"11895374774","pt":1724250309283,"mc":[{"id":"1.232049325","rc":[{"batb":[[0,1.05,4.89],[1,1.04,1.53],[2,1.03,200]],"ltp":1.72,"tv":10.64,"id":72857115}]}]}
{"op":"mcm","clk":"11895374816","pt":1724250309854,"mc":[{"id":"1.232049325","rc":[{"batb":[[0,1.06,10.89],[1,1.05,4],[2,1.04,1.53]],"ltp":1.72,"tv":10.64,"id":72857115}]}]}
{"op":"mcm","clk":"11895374971","pt":1724250311863,"mc":[{"id":"1.232049325","rc":[{"batb":[[1,1.04,1.53],[2,1.03,200]],"ltp":1.72,"tv":10.64,"id":72857115}]}]}
{"op":"mcm","clk":"11895375111","pt":1724250313461,"mc":[{"id":"1.232049325","rc":[{"batb":[[0,1.04,2.42],[1,1.03,200],[2,1.02,200]],"ltp":1.72,"tv":10.64,"id":72857115}]}]}
{"op":"mcm","clk":"11895376001","pt":1724250324176,"mc":[{"id":"1.232049325","rc":[{"batb":[[0,1.05,4.89],[1,1.04,1.53],[2,1.03,200]],"ltp":1.72,"tv":10.64,"id":72857115}]}]}
{"op":"mcm","clk":"11895376068","pt":1724250325056,"mc":[{"id":"1.232049325","rc":[{"batb":[[0,1.06,10.89],[1,1.05,4],[2,1.04,1.53]],"ltp":1.72,"tv":10.64,"id":72857115}]}]}
{"op":"mcm","clk":"11895376207","pt":1724250326869,"mc":[{"id":"1.232049325","rc":[{"batb":[[1,1.04,1.53],[2,1.03,200]],"ltp":1.72,"tv":10.64,"id":72857115}]}]}
{"op":"mcm","clk":"11895376358","pt":1724250328568,"mc":[{"id":"1.232049325","rc":[{"batb":[[0,1.04,2.42],[1,1.03,200],[2,1.02,200]],"ltp":1.72,"tv":10.64,"id":72857115}]}]}
{"op":"mcm","clk":"11895378144","pt":1724250350498,"mc":[{"id":"1.232049325","rc":[{"batb":[[0,1.05,4.89],[1,1.04,1.53],[2,1.03,200]],"ltp":1.72,"tv":10.64,"id":72857115}]}]}
{"op":"mcm","clk":"11895378164","pt":1724250350702,"mc":[{"id":"1.232049325","rc":[{"batb":[[0,1.06,10.89],[1,1.05,4],[2,1.04,1.53]],"ltp":1.72,"tv":10.64,"id":72857115}]}]}
{"op":"mcm","clk":"11895378339","pt":1724250352922,"mc":[{"id":"1.232049325","rc":[{"batb":[[1,1.04,1.53],[2,1.03,200]],"ltp":1.72,"tv":10.64,"id":72857115}]}]}
{"op":"mcm","clk":"11895378435","pt":1724250354626,"mc":[{"id":"1.232049325","rc":[{"batb":[[0,1.04,2.42],[1,1.03,200],[2,1.02,200]],"ltp":1.72,"tv":10.64,"id":72857115}]}]}
{"op":"mcm","clk":"11895378550","pt":1724250356136,"mc":[{"id":"1.232049325","rc":[{"batb":[[0,1.05,4.89],[1,1.04,1.53],[2,1.03,200]],"ltp":1.72,"tv":10.64,"id":72857115}]}]}
{"op":"mcm","clk":"11895378700","pt":1724250357927,"mc":[{"id":"1.232049325","rc":[{"batb":[[0,1.06,10.89],[1,1.05,4],[2,1.04,1.53]],"ltp":1.72,"tv":10.64,"id":72857115}]}]}
{"op":"mcm","clk":"11895378752","pt":1724250358703,"mc":[{"id":"1.232049325","rc":[{"batb":[[1,1.04,1.53],[2,1.03,200]],"ltp":1.72,"tv":10.64,"id":72857115}]}]}
{"op":"mcm","clk":"11895378949","pt":1724250361505,"mc":[{"id":"1.232049325","rc":[{"batb":[[0,1.04,2.42],[1,1.03,200],[2,1.02,200]],"ltp":1.72,"tv":10.64,"id":72857115}]}]}
{"op":"mcm","clk":"11895378979","pt":1724250361823,"mc":[{"id":"1.232049325","rc":[{"batb":[[0,1.05,4.89],[1,1.04,1.53],[2,1.03,200]],"ltp":1.72,"tv":10.64,"id":72857115}]}]}
{"op":"mcm","clk":"11895379178","pt":1724250364030,"mc":[{"id":"1.232049325","rc":[{"batb":[[0,1.04,2.42],[1,1.03,200],[2,1.02,200]],"ltp":1.72,"tv":10.64,"id":72857115}]}]}
{"op":"mcm","clk":"11895380506","pt":1724250380428,"mc":[{"id":"1.232049325","rc":[{"batb":[[0,1.05,4.89],[1,1.04,1.53],[2,1.03,200]],"ltp":1.72,"tv":10.64,"id":72857115}]}]}
{"op":"mcm","clk":"11895380558","pt":1724250381250,"mc":[{"id":"1.232049325","rc":[{"batb":[[0,1.06,10.89],[1,1.05,4],[2,1.04,1.53]],"ltp":1.72,"tv":10.64,"id":72857115}]}]}
{"op":"mcm","clk":"11895380711","pt":1724250383155,"mc":[{"id":"1.232049325","rc":[{"batb":[[1,1.04,1.53],[2,1.03,200]],"ltp":1.72,"tv":10.64,"id":72857115}]}]}
{"op":"mcm","clk":"11895380829","pt":1724250384642,"mc":[{"id":"1.232049325","rc":[{"batb":[[0,1.04,2.42],[1,1.03,200],[2,1.02,200]],"ltp":1.72,"tv":10.64,"id":72857115}]}]}
{"op":"mcm","clk":"11895382534","pt":1724250406267,"mc":[{"id":"1.232049325","rc":[{"batb":[[0,1.05,4.89],[1,1.04,1.53],[2,1.03,200]],"ltp":1.72,"tv":10.64,"id":72857115}]}]}
{"op":"mcm","clk":"11895382599","pt":1724250406990,"mc":[{"id":"1.232049325","rc":[{"batb":[[0,1.06,10.89],[1,1.05,4],[2,1.04,1.53]],"ltp":1.72,"tv":10.64,"id":72857115}]}]}
{"op":"mcm","clk":"11895382766","pt":1724250408683,"mc":[{"id":"1.232049325","rc":[{"batb":[[1,1.04,1.53],[2,1.03,200]],"ltp":1.72,"tv":10.64,"id":72857115}]}]}
{"op":"mcm","clk":"11895382958","pt":1724250410796,"mc":[{"id":"1.232049325","rc":[{"batb":[[0,1.05,4.89]],"ltp":1.72,"tv":10.64,"id":72857115}]}]}
{"op":"mcm","clk":"11895383150","pt":1724250413105,"mc":[{"id":"1.232049325","rc":[{"batb":[[0,1.04,2.42],[1,1.03,200],[2,1.02,200]],"ltp":1.72,"tv":10.64,"id":72857115}]}]}
{"op":"mcm","clk":"11895385731","pt":1724250444404,"mc":[{"id":"1.232049325","rc":[{"batb":[[0,1.05,4.89],[1,1.04,1.53],[2,1.03,200]],"ltp":1.72,"tv":10.64,"id":72857115}]}]}
{"op":"mcm","clk":"11895385778","pt":1724250445019,"mc":[{"id":"1.232049325","rc":[{"batb":[[0,1.06,10.89],[1,1.05,4],[2,1.04,1.53]],"ltp":1.72,"tv":10.64,"id":72857115}]}]}
{"op":"mcm","clk":"11895385976","pt":1724250447148,"mc":[{"id":"1.232049325","rc":[{"batb":[[1,1.04,1.53],[2,1.03,200]],"ltp":1.72,"tv":10.64,"id":72857115}]}]}
{"op":"mcm","clk":"11895386120","pt":1724250448840,"mc":[{"id":"1.232049325","rc":[{"batb":[[0,1.04,2.42],[1,1.03,200],[2,1.02,200]],"ltp":1.72,"tv":10.64,"id":72857115}]}]}
{"op":"mcm","clk":"11895386657","pt":1724250455134,"mc":[{"id":"1.232049325","rc":[{"batb":[[0,1.05,4.89],[1,1.04,1.53],[2,1.03,200]],"ltp":1.72,"tv":10.64,"id":72857115}]}]}
{"op":"mcm","clk":"11895386714","pt":1724250455652,"mc":[{"id":"1.232049325","rc":[{"batb":[[0,1.06,10.89],[1,1.05,4],[2,1.04,1.53]],"ltp":1.72,"tv":10.64,"id":72857115}]}]}
{"op":"mcm","clk":"11895386922","pt":1724250458137,"mc":[{"id":"1.232049325","rc":[{"batb":[[1,1.04,1.53],[2,1.03,200]],"ltp":1.72,"tv":10.64,"id":72857115}]}]}
{"op":"mcm","clk":"11895387022","pt":1724250459461,"mc":[{"id":"1.232049325","rc":[{"batb":[[0,1.04,2.42],[1,1.03,200],[2,1.02,200]],"ltp":1.72,"tv":10.64,"id":72857115}]}]}
{"op":"mcm","clk":"11895387607","pt":1724250465581,"mc":[{"id":"1.232049325","rc":[{"batb":[[0,1.05,4.89],[1,1.04,1.53],[2,1.03,200]],"ltp":1.72,"tv":10.64,"id":72857115}]}]}
{"op":"mcm","clk":"11895387663","pt":1724250466149,"mc":[{"id":"1.232049325","rc":[{"batb":[[0,1.06,10.89],[1,1.05,4],[2,1.04,1.53]],"ltp":1.72,"tv":10.64,"id":72857115}]}]}
{"op":"mcm","clk":"11895387833","pt":1724250468353,"mc":[{"id":"1.232049325","rc":[{"batb":[[1,1.04,1.53],[2,1.03,200]],"ltp":1.72,"tv":10.64,"id":72857115}]}]}
{"op":"mcm","clk":"11895387941","pt":1724250469846,"mc":[{"id":"1.232049325","rc":[{"batb":[[0,1.04,2.42],[1,1.03,200],[2,1.02,200]],"ltp":1.72,"tv":10.64,"id":72857115}]}]}
{"op":"mcm","clk":"11895389411","pt":1724250485649,"mc":[{"id":"1.232049325","rc":[{"batb":[[0,1.05,4.89],[1,1.04,1.53],[2,1.03,200]],"ltp":1.72,"tv":10.64,"id":72857115}]}]}
{"op":"mcm","clk":"11895389501","pt":1724250486596,"mc":[{"id":"1.232049325","rc":[{"batb":[[0,1.06,10.89],[1,1.05,4],[2,1.04,1.53]],"ltp":1.72,"tv":10.64,"id":72857115}]}]}
{"op":"mcm","clk":"11895389688","pt":1724250488506,"mc":[{"id":"1.232049325","rc":[{"batb":[[1,1.04,1.53],[2,1.03,200]],"ltp":1.72,"tv":10.64,"id":72857115}]}]}
{"op":"mcm","clk":"11895389913","pt":1724250490174,"mc":[{"id":"1.232049325","rc":[{"batb":[[0,1.04,2.42],[1,1.03,200],[2,1.02,200]],"ltp":1.72,"tv":10.64,"id":72857115}]}]}
{"op":"mcm","clk":"11895391137","pt":1724250502423,"mc":[{"id":"1.232049325","rc":[{"batb":[[0,1.06,10.89],[1,1.05,4],[2,1.04,1.53]],"ltp":1.72,"tv":10.64,"id":72857115}]}]}
{"op":"mcm","clk":"11895391339","pt":1724250504492,"mc":[{"id":"1.232049325","rc":[{"batb":[[1,1.04,1.53],[2,1.03,200]],"ltp":1.72,"tv":10.64,"id":72857115}]}]}
{"op":"mcm","clk":"11895391477","pt":1724250505899,"mc":[{"id":"1.232049325","rc":[{"batb":[[0,1.04,2.42],[1,1.03,200],[2,1.02,200]],"ltp":1.72,"tv":10.64,"id":72857115}]}]}
{"op":"mcm","clk":"11895394751","pt":1724250542068,"mc":[{"id":"1.232049325","rc":[{"batb":[[0,1.05,4.89],[1,1.04,1.53],[2,1.03,200]],"ltp":1.72,"tv":10.64,"id":72857115}]}]}
{"op":"mcm","clk":"11895394808","pt":1724250542645,"mc":[{"id":"1.232049325","rc":[{"batb":[[0,1.06,10.89],[1,1.05,4],[2,1.04,1.53]],"ltp":1.72,"tv":10.64,"id":72857115}]}]}
{"op":"mcm","clk":"11895395013","pt":1724250544777,"mc":[{"id":"1.232049325","rc":[{"batb":[[1,1.04,1.53],[2,1.03,200]],"ltp":1.72,"tv":10.64,"id":72857115}]}]}
{"op":"mcm","clk":"11895395231","pt":1724250547062,"mc":[{"id":"1.232049325","rc":[{"batb":[[0,1.05,4.89]],"ltp":1.72,"tv":10.64,"id":72857115}]}]}
{"op":"mcm","clk":"11895395429","pt":1724250549264,"mc":[{"id":"1.232049325","rc":[{"batb":[[0,1.04,2.42],[1,1.03,200],[2,1.02,200]],"ltp":1.72,"tv":10.64,"id":72857115}]}]}
{"op":"mcm","clk":"11895396394","pt":1724250559456,"mc":[{"id":"1.232049325","rc":[{"batb":[[0,1.05,4.89],[1,1.04,1.53],[2,1.03,200]],"ltp":1.72,"tv":10.64,"id":72857115}]}]}
{"op":"mcm","clk":"11895396444","pt":1724250560072,"mc":[{"id":"1.232049325","rc":[{"batb":[[0,1.06,10.89],[1,1.05,4],[2,1.04,1.53]],"ltp":1.72,"tv":10.64,"id":72857115}]}]}
{"op":"mcm","clk":"11895396646","pt":1724250562345,"mc":[{"id":"1.232049325","rc":[{"batb":[[1,1.04,1.53],[2,1.03,200]],"ltp":1.72,"tv":10.64,"id":72857115}]}]}
{"op":"mcm","clk":"11895396776","pt":1724250563684,"mc":[{"id":"1.232049325","rc":[{"batb":[[0,1.04,2.42],[1,1.03,200],[2,1.02,200]],"ltp":1.72,"tv":10.64,"id":72857115}]}]}
{"op":"mcm","clk":"11895397090","pt":1724250567184,"mc":[{"id":"1.232049325","rc":[{"batb":[[0,1.05,4.89],[1,1.04,1.53],[2,1.03,200]],"ltp":1.72,"tv":10.64,"id":72857115}]}]}
{"op":"mcm","clk":"11895397145","pt":1724250567799,"mc":[{"id":"1.232049325","rc":[{"batb":[[0,1.06,10.89],[1,1.05,4],[2,1.04,1.53]],"ltp":1.72,"tv":10.64,"id":72857115}]}]}
{"op":"mcm","clk":"11895397348","pt":1724250569866,"mc":[{"id":"1.232049325","rc":[{"batb":[[1,1.04,1.53],[2,1.03,200]],"ltp":1.72,"tv":10.64,"id":72857115}]}]}
{"op":"mcm","clk":"11895397491","pt":1724250571476,"mc":[{"id":"1.232049325","rc":[{"batb":[[0,1.04,2.42],[1,1.03,200],[2,1.02,200]],"ltp":1.72,"tv":10.64,"id":72857115}]}]}
{"op":"mcm","clk":"11895399802","pt":1724250599008,"mc":[{"id":"1.232049325","rc":[{"batb":[[0,1.06,10.89],[1,1.05,4],[2,1.04,1.53]],"ltp":1.72,"tv":10.64,"id":72857115}]}]}
{"op":"mcm","clk":"11895400045","pt":1724250601440,"mc":[{"id":"1.232049325","rc":[{"batb":[[1,1.04,1.53],[2,1.03,200]],"ltp":1.72,"tv":10.64,"id":72857115}]}]}
{"op":"mcm","clk":"11895400244","pt":1724250603107,"mc":[{"id":"1.232049325","rc":[{"batb":[[0,1.04,2.42],[1,1.03,200],[2,1.02,200]],"ltp":1.72,"tv":10.64,"id":72857115}]}]}
{"op":"mcm","clk":"11895400332","pt":1724250603834,"mc":[{"id":"1.232049325","rc":[{"batb":[[0,1.05,4.89],[1,1.04,1.53],[2,1.03,200]],"ltp":1.72,"tv":10.64,"id":72857115}]}]}
{"op":"mcm","clk":"11895400611","pt":1724250606329,"mc":[{"id":"1.232049325","rc":[{"batb":[[0,1.04,2.42],[1,1.03,200],[2,1.02,200]],"ltp":1.72,"tv":10.64,"id":72857115}]}]}
{"op":"mcm","clk":"11895401260","pt":1724250613433,"mc":[{"id":"1.232049325","rc":[{"batb":[[0,1.05,4.89],[1,1.04,1.53],[2,1.03,200]],"ltp":1.72,"tv":10.64,"id":72857115}]}]}
{"op":"mcm","clk":"11895401324","pt":1724250614036,"mc":[{"id":"1.232049325","rc":[{"batb":[[0,1.06,10.89],[1,1.05,4],[2,1.04,1.53]],"ltp":1.72,"tv":10.64,"id":72857115}]}]}
{"op":"mcm","clk":"11895401490","pt":1724250615850,"mc":[{"id":"1.232049325","rc":[{"batb":[[1,1.04,1.53],[2,1.03,200]],"ltp":1.72,"tv":10.64,"id":72857115}]}]}
{"op":"mcm","clk":"11895401644","pt":1724250617517,"mc":[{"id":"1.232049325","rc":[{"batb":[[0,1.04,2.42],[1,1.03,200],[2,1.02,200]],"ltp":1.72,"tv":10.64,"id":72857115}]}]}
{"op":"mcm","clk":"11895403127","pt":1724250634168,"mc":[{"id":"1.232049325","rc":[{"batb":[[0,1.06,10.89],[1,1.05,4],[2,1.04,1.53]],"ltp":1.72,"tv":10.64,"id":72857115}]}]}
{"op":"mcm","clk":"11895403336","pt":1724250636352,"mc":[{"id":"1.232049325","rc":[{"batb":[[1,1.04,1.53],[2,1.03,200]],"ltp":1.72,"tv":10.64,"id":72857115}]}]}
{"op":"mcm","clk":"11895403434","pt":1724250637842,"mc":[{"id":"1.232049325","rc":[{"batb":[[0,1.04,2.42],[1,1.03,200],[2,1.02,200]],"ltp":1.72,"tv":10.64,"id":72857115}]}]}
{"op":"mcm","clk":"11895404639","pt":1724250652462,"mc":[{"id":"1.232049325","rc":[{"batb":[[0,1.05,4.89],[1,1.04,1.53],[2,1.03,200]],"ltp":1.72,"tv":10.64,"id":72857115}]}]}
{"op":"mcm","clk":"11895404704","pt":1724250653178,"mc":[{"id":"1.232049325","rc":[{"batb":[[0,1.06,10.89],[1,1.05,4],[2,1.04,1.53]],"ltp":1.72,"tv":10.64,"id":72857115}]}]}
{"op":"mcm","clk":"11895404875","pt":1724250655343,"mc":[{"id":"1.232049325","rc":[{"batb":[[1,1.04,1.53],[2,1.03,200]],"ltp":1.72,"tv":10.64,"id":72857115}]}]}
{"op":"mcm","clk":"11895404986","pt":1724250656783,"mc":[{"id":"1.232049325","rc":[{"batb":[[0,1.04,2.42],[1,1.03,200],[2,1.02,200]],"ltp":1.72,"tv":10.64,"id":72857115}]}]}
{"op":"mcm","clk":"11895406850","pt":1724250679099,"mc":[{"id":"1.232049325","rc":[{"batb":[[0,1.06,10.89],[1,1.05,4],[2,1.04,1.53]],"ltp":1.72,"tv":10.64,"id":72857115}]}]}
{"op":"mcm","clk":"11895407075","pt":1724250681575,"mc":[{"id":"1.232049325","rc":[{"batb":[[1,1.04,1.53],[2,1.03,200]],"ltp":1.72,"tv":10.64,"id":72857115}]}]}
{"op":"mcm","clk":"11895407148","pt":1724250682602,"mc":[{"id":"1.232049325","rc":[{"batb":[[0,1.04,2.42],[1,1.03,200],[2,1.02,200]],"ltp":1.72,"tv":10.64,"id":72857115}]}]}
{"op":"mcm","clk":"11895407941","pt":1724250692205,"mc":[{"id":"1.232049325","rc":[{"batb":[[0,1.06,10.89],[1,1.05,4],[2,1.04,1.53]],"ltp":1.72,"tv":10.64,"id":72857115}]}]}
{"op":"mcm","clk":"11895408087","pt":1724250694318,"mc":[{"id":"1.232049325","rc":[{"batb":[[1,1.04,1.53],[2,1.03,200]],"ltp":1.72,"tv":10.64,"id":72857115}]}]}
{"op":"mcm","clk":"11895408206","pt":1724250695710,"mc":[{"id":"1.232049325","rc":[{"batb":[[0,1.04,2.42],[1,1.03,200],[2,1.02,200]],"ltp":1.72,"tv":10.64,"id":72857115}]}]}
{"op":"mcm","clk":"11895409625","pt":1724250712813,"mc":[{"id":"1.232049325","rc":[{"batb":[[0,1.06,10.89],[1,1.05,4],[2,1.04,1.53]],"ltp":1.72,"tv":10.64,"id":72857115}]}]}
{"op":"mcm","clk":"11895409835","pt":1724250715323,"mc":[{"id":"1.232049325","rc":[{"batb":[[1,1.04,1.53],[2,1.03,200]],"ltp":1.72,"tv":10.64,"id":72857115}]}]}
{"op":"mcm","clk":"11895409895","pt":1724250716215,"mc":[{"id":"1.232049325","rc":[{"batb":[[0,1.04,2.42],[1,1.03,200],[2,1.02,200]],"ltp":1.72,"tv":10.64,"id":72857115}]}]}
{"op":"mcm","clk":"11895411329","pt":1724250734535,"mc":[{"id":"1.232049325","rc":[{"batb":[[0,1.05,4.89],[1,1.04,1.53],[2,1.03,200]],"ltp":1.72,"tv":10.64,"id":72857115}]}]}
{"op":"mcm","clk":"11895411336","pt":1724250734647,"mc":[{"id":"1.232049325","rc":[{"batb":[[0,1.06,10.89],[1,1.05,4],[2,1.04,1.53]],"ltp":1.72,"tv":10.64,"id":72857115}]}]}
{"op":"mcm","clk":"11895411503","pt":1724250736895,"mc":[{"id":"1.232049325","rc":[{"batb":[[1,1.04,1.53],[2,1.03,200]],"ltp":1.72,"tv":10.64,"id":72857115}]}]}
{"op":"mcm","clk":"11895411607","pt":1724250738245,"mc":[{"id":"1.232049325","rc":[{"batb":[[0,1.04,2.42],[1,1.03,200],[2,1.02,200]],"ltp":1.72,"tv":10.64,"id":72857115}]}]}
{"op":"mcm","clk":"11895411825","pt":1724250741526,"mc":[{"id":"1.232049325","rc":[{"batb":[[0,1.06,10.89],[1,1.05,4],[2,1.04,1.53]],"ltp":1.72,"tv":10.64,"id":72857115}]}]}
{"op":"mcm","clk":"11895411957","pt":1724250743436,"mc":[{"id":"1.232049325","rc":[{"batb":[[1,1.04,1.53],[2,1.03,200]],"ltp":1.72,"tv":10.64,"id":72857115}]}]}
{"op":"mcm","clk":"11895412067","pt":1724250745073,"mc":[{"id":"1.232049325","rc":[{"batb":[[0,1.04,2.42],[1,1.03,200],[2,1.02,200]],"ltp":1.72,"tv":10.64,"id":72857115}]}]}
{"op":"mcm","clk":"11895414860","pt":1724250782415,"mc":[{"id":"1.232049325","rc":[{"batb":[[0,1.05,4.89],[1,1.04,1.53],[2,1.03,200]],"ltp":1.72,"tv":10.64,"id":72857115}]}]}
{"op":"mcm","clk":"11895414910","pt":1724250782986,"mc":[{"id":"1.232049325","rc":[{"batb":[[0,1.06,10.89],[1,1.05,4],[2,1.04,1.53]],"ltp":1.72,"tv":10.64,"id":72857115}]}]}
{"op":"mcm","clk":"11895415073","pt":1724250785196,"mc":[{"id":"1.232049325","rc":[{"batb":[[1,1.04,1.53],[2,1.03,200]],"ltp":1.72,"tv":10.64,"id":72857115}]}]}
{"op":"mcm","clk":"11895415181","pt":1724250786585,"mc":[{"id":"1.232049325","rc":[{"batb":[[0,1.04,2.42],[1,1.03,200],[2,1.02,200]],"ltp":1.72,"tv":10.64,"id":72857115}]}]}
{"op":"mcm","clk":"11895418684","pt":1724250833564,"mc":[{"id":"1.232049325","rc":[{"batb":[[0,1.05,4.89],[1,1.04,1.53],[2,1.03,200]],"ltp":1.72,"tv":10.64,"id":72857115}]}]}
{"op":"mcm","clk":"11895418723","pt":1724250834028,"mc":[{"id":"1.232049325","rc":[{"batb":[[0,1.06,10.89],[1,1.05,4],[2,1.04,1.53]],"ltp":1.72,"tv":10.64,"id":72857115}]}]}
{"op":"mcm","clk":"11895418885","pt":1724250835835,"mc":[{"id":"1.232049325","rc":[{"batb":[[1,1.04,1.53],[2,1.03,200]],"ltp":1.72,"tv":10.64,"id":72857115}]}]}
{"op":"mcm","clk":"11895419009","pt":1724250837429,"mc":[{"id":"1.232049325","rc":[{"batb":[[0,1.04,2.42],[1,1.03,200],[2,1.02,200]],"ltp":1.72,"tv":10.64,"id":72857115}]}]}
{"op":"mcm","clk":"11895422912","pt":1724250883824,"mc":[{"id":"1.232049325","rc":[{"batb":[[0,1.05,4.89],[1,1.04,1.53],[2,1.03,200]],"ltp":1.72,"tv":10.64,"id":72857115}]}]}
{"op":"mcm","clk":"11895422983","pt":1724250884689,"mc":[{"id":"1.232049325","rc":[{"batb":[[0,1.06,10.89],[1,1.05,4],[2,1.04,1.53]],"ltp":1.72,"tv":10.64,"id":72857115}]}]}
{"op":"mcm","clk":"11895423146","pt":1724250886513,"mc":[{"id":"1.232049325","rc":[{"batb":[[1,1.04,1.53],[2,1.03,200]],"ltp":1.72,"tv":10.64,"id":72857115}]}]}
{"op":"mcm","clk":"11895423296","pt":1724250888224,"mc":[{"id":"1.232049325","rc":[{"batb":[[0,1.04,2.42],[1,1.03,200],[2,1.02,200]],"ltp":1.72,"tv":10.64,"id":72857115}]}]}
{"op":"mcm","clk":"11895433765","pt":1724251009151,"mc":[{"id":"1.232049325","rc":[{"batb":[[0,1.05,4.89],[1,1.04,1.53],[2,1.03,200]],"ltp":1.72,"tv":10.64,"id":72857115}]}]}
{"op":"mcm","clk":"11895434144","pt":1724251013273,"mc":[{"id":"1.232049325","rc":[{"batb":[[0,1.06,10.89],[1,1.05,4],[2,1.04,1.53]],"ltp":1.72,"tv":10.64,"id":72857115}]}]}
{"op":"mcm","clk":"11895434304","pt":1724251015243,"mc":[{"id":"1.232049325","rc":[{"batb":[[1,1.04,1.53],[2,1.03,200]],"ltp":1.72,"tv":10.64,"id":72857115}]}]}
{"op":"mcm","clk":"11895434616","pt":1724251018953,"mc":[{"id":"1.232049325","rc":[{"batb":[[0,1.04,2.42],[1,1.03,200],[2,1.02,200]],"ltp":1.72,"tv":10.64,"id":72857115}]}]}
{"op":"mcm","clk":"11895434715","pt":1724251019844,"mc":[{"id":"1.232049325","rc":[{"batb":[[0,1.05,4.89],[1,1.04,1.53],[2,1.03,200]],"ltp":1.72,"tv":10.64,"id":72857115}]}]}
{"op":"mcm","clk":"11895434965","pt":1724251022687,"mc":[{"id":"1.232049325","rc":[{"batb":[[0,1.04,2.42],[1,1.03,200],[2,1.02,200]],"ltp":1.72,"tv":10.64,"id":72857115}]}]}
{"op":"mcm","clk":"11895436948","pt":1724251045906,"mc":[{"id":"1.232049325","rc":[{"batb":[[0,1.05,4.89],[1,1.04,1.53],[2,1.03,200]],"ltp":1.72,"tv":10.64,"id":72857115}]}]}
{"op":"mcm","clk":"11895437388","pt":1724251051707,"mc":[{"id":"1.232049325","rc":[{"batb":[[0,1.06,10.89],[1,1.05,4],[2,1.04,1.53]],"ltp":1.72,"tv":10.64,"id":72857115}]}]}
{"op":"mcm","clk":"11895437533","pt":1724251053611,"mc":[{"id":"1.232049325","rc":[{"batb":[[1,1.04,1.53],[2,1.03,200]],"ltp":1.72,"tv":10.64,"id":72857115}]}]}
{"op":"mcm","clk":"11895437758","pt":1724251056597,"mc":[{"id":"1.232049325","rc":[{"batb":[[0,1.07,4.89],[1,1.06,10],[2,1.04,1.53]],"ltp":1.72,"tv":10.64,"id":72857115}]}]}
{"op":"mcm","clk":"11895437915","pt":1724251058609,"mc":[{"id":"1.232049325","rc":[{"batb":[[1,1.04,1.53],[2,1.03,200]],"ltp":1.72,"tv":10.64,"id":72857115}]}]}
{"op":"mcm","clk":"11895438312","pt":1724251063106,"mc":[{"id":"1.232049325","rc":[{"batb":[[0,1.08,10.89],[1,1.07,4],[2,1.04,1.53]],"ltp":1.72,"tv":10.64,"id":72857115}]}]}
{"op":"mcm","clk":"11895438481","pt":1724251065223,"mc":[{"id":"1.232049325","rc":[{"batb":[[1,1.04,1.53],[2,1.03,200]],"ltp":1.72,"tv":10.64,"id":72857115}]}]}
{"op":"mcm","clk":"11895438845","pt":1724251070227,"mc":[{"id":"1.232049325","rc":[{"batb":[[0,1.09,4.89],[1,1.08,10],[2,1.04,1.53]],"ltp":1.72,"tv":10.64,"id":72857115}]}]}
{"op":"mcm","clk":"11895439056","pt":1724251073112,"mc":[{"id":"1.232049325","rc":[{"batb":[[1,1.04,1.53],[2,1.03,200]],"ltp":1.72,"tv":10.64,"id":72857115}]}]}
{"op":"mcm","clk":"11895439380","pt":1724251077243,"mc":[{"id":"1.232049325","rc":[{"batb":[[0,1.1,10.89]],"ltp":1.72,"tv":10.64,"id":72857115}]}]}
{"op":"mcm","clk":"11895439558","pt":1724251079519,"mc":[{"id":"1.232049325","rc":[{"batb":[[1,1.05,4],[2,1.04,1.53]],"ltp":1.72,"tv":10.64,"id":72857115}]}]}
{"op":"mcm","clk":"11895439880","pt":1724251083201,"mc":[{"id":"1.232049325","rc":[{"batb":[[0,1.05,4.89],[1,1.04,1.53],[2,1.03,200]],"ltp":1.72,"tv":10.64,"id":72857115}]}]}
{"op":"mcm","clk":"11895439984","pt":1724251084443,"mc":[{"id":"1.232049325","rc":[{"batb":[[0,1.04,2.42],[1,1.03,200],[2,1.02,200]],"ltp":1.72,"tv":10.64,"id":72857115}]}]}
{"op":"mcm","clk":"11895446790","pt":1724251166712,"mc":[{"id":"1.232049325","rc":[{"batb":[[0,1.05,4.89],[1,1.04,1.53],[2,1.03,200]],"ltp":1.72,"tv":10.64,"id":72857115}]}]}
{"op":"mcm","clk":"11895447024","pt":1724251169120,"mc":[{"id":"1.232049325","rc":[{"batb":[[0,1.06,10.89],[1,1.05,4],[2,1.04,1.53]],"ltp":1.72,"tv":10.64,"id":72857115}]}]}
{"op":"mcm","clk":"11895447200","pt":1724251171021,"mc":[{"id":"1.232049325","rc":[{"batb":[[1,1.04,1.53],[2,1.03,200]],"ltp":1.72,"tv":10.64,"id":72857115}]}]}
{"op":"mcm","clk":"11895447492","pt":1724251174624,"mc":[{"id":"1.232049325","rc":[{"batb":[[0,1.07,4.89],[1,1.06,10],[2,1.04,1.53]],"ltp":1.72,"tv":10.64,"id":72857115}]}]}
{"op":"mcm","clk":"11895447609","pt":1724251176013,"mc":[{"id":"1.232049325","rc":[{"batb":[[1,1.04,1.53],[2,1.03,200]],"ltp":1.72,"tv":10.64,"id":72857115}]}]}
{"op":"mcm","clk":"11895447883","pt":1724251179045,"mc":[{"id":"1.232049325","rc":[{"batb":[[0,1.08,10.89],[1,1.07,4],[2,1.04,1.53]],"ltp":1.72,"tv":10.64,"id":72857115}]}]}
{"op":"mcm","clk":"11895448058","pt":1724251180946,"mc":[{"id":"1.232049325","rc":[{"batb":[[1,1.04,1.53],[2,1.03,200]],"ltp":1.72,"tv":10.64,"id":72857115}]}]}
{"op":"mcm","clk":"11895448250","pt":1724251183361,"mc":[{"id":"1.232049325","rc":[{"batb":[[0,1.09,4.89],[1,1.08,10],[2,1.04,1.53]],"ltp":1.72,"tv":10.64,"id":72857115}]}]}
{"op":"mcm","clk":"11895448410","pt":1724251184953,"mc":[{"id":"1.232049325","rc":[{"batb":[[1,1.04,1.53],[2,1.03,200]],"ltp":1.72,"tv":10.64,"id":72857115}]}]}
{"op":"mcm","clk":"11895448573","pt":1724251187473,"mc":[{"id":"1.232049325","rc":[{"batb":[[0,1.04,2.42],[1,1.03,200],[2,1.02,200]],"ltp":1.72,"tv":10.64,"id":72857115}]}]}
{"op":"mcm","clk":"11895449097","pt":1724251194866,"mc":[{"id":"1.232049325","rc":[{"batb":[[0,1.06,10.89],[1,1.05,4],[2,1.04,1.53]],"ltp":1.72,"tv":10.64,"id":72857115}]}]}
{"op":"mcm","clk":"11895449265","pt":1724251197070,"mc":[{"id":"1.232049325","rc":[{"batb":[[1,1.04,1.53],[2,1.03,200]],"ltp":1.72,"tv":10.64,"id":72857115}]}]}
{"op":"mcm","clk":"11895449350","pt":1724251198045,"mc":[{"id":"1.232049325","rc":[{"batb":[[0,1.04,2.42],[1,1.03,200],[2,1.02,200]],"ltp":1.72,"tv":10.64,"id":72857115}]}]}
{"op":"mcm","clk":"11895454115","pt":1724251252525,"mc":[{"id":"1.232049325","rc":[{"batb":[[0,1.05,4.89],[1,1.04,1.53],[2,1.03,200]],"ltp":1.72,"tv":10.64,"id":72857115}]}]}
{"op":"mcm","clk":"11895454458","pt":1724251256126,"mc":[{"id":"1.232049325","rc":[{"batb":[[0,1.06,10.89],[1,1.05,4],[2,1.04,1.53]],"ltp":1.72,"tv":10.64,"id":72857115}]}]}
{"op":"mcm","clk":"11895454788","pt":1724251259038,"mc":[{"id":"1.232049325","rc":[{"batb":[[1,1.04,1.53],[2,1.03,200]],"ltp":1.72,"tv":10.64,"id":72857115}]}]}
{"op":"mcm","clk":"11895455138","pt":1724251262047,"mc":[{"id":"1.232049325","rc":[{"batb":[[0,1.07,4.89],[1,1.06,10],[2,1.04,1.53]],"ltp":1.72,"tv":10.64,"id":72857115}]}]}
{"op":"mcm","clk":"11895455617","pt":1724251265275,"mc":[{"id":"1.232049325","rc":[{"batb":[[1,1.04,1.53],[2,1.03,200]],"ltp":1.72,"tv":10.64,"id":72857115}]}]}
{"op":"mcm","clk":"11895455950","pt":1724251267588,"mc":[{"id":"1.232049325","rc":[{"batb":[[0,1.07,14.89]],"ltp":1.72,"tv":10.64,"id":72857115}]}]}
{"op":"mcm","clk":"11895456267","pt":1724251269850,"mc":[{"id":"1.232049325","rc":[{"batb":[[0,1.07,10.89]],"ltp":1.72,"tv":10.64,"id":72857115}]}]}
{"op":"mcm","clk":"11895456859","pt":1724251274293,"mc":[{"id":"1.232049325","rc":[{"batb":[[0,1.08,4.89]],"ltp":1.72,"tv":10.64,"id":72857115}]}]}
{"op":"mcm","clk":"11895457167","pt":1724251276473,"mc":[{"id":"1.232049325","rc":[{"batb":[[0,1.09,10.89],[1,1.08,4],[2,1.04,1.53]],"ltp":1.72,"tv":10.64,"id":72857115}]}]}
{"op":"mcm","clk":"11895457403","pt":1724251277998,"mc":[{"id":"1.232049325","rc":[{"batb":[[1,1.04,1.53],[2,1.03,200]],"ltp":1.72,"tv":10.64,"id":72857115}]}]}
{"op":"mcm","clk":"11895457984","pt":1724251281225,"mc":[{"id":"1.232049325","rc":[{"batb":[[0,1.05,4.89]],"ltp":1.72,"tv":10.64,"id":72857115}]}]}
{"op":"mcm","clk":"11895458375","pt":1724251283513,"mc":[{"id":"1.232049325","rc":[{"batb":[[0,1.04,2.42],[1,1.03,200],[2,1.02,200]],"ltp":1.72,"tv":10.64,"id":72857115}]}]}
{"op":"mcm","clk":"11895458390","pt":1724251283612,"mc":[{"id":"1.232049325","rc":[{"batb":[[0,1.06,10.89],[1,1.04,1.53],[2,1.03,200]],"ltp":1.72,"tv":10.64,"id":72857115}]}]}
{"op":"mcm","clk":"11895458837","pt":1724251287181,"mc":[{"id":"1.232049325","rc":[{"batb":[[0,1.04,2.42],[1,1.03,200],[2,1.02,200]],"ltp":1.72,"tv":10.64,"id":72857115}]}]}
{"op":"mcm","clk":"11895458899","pt":1724251287696,"mc":[{"id":"1.232049325","rc":[{"batb":[[0,1.05,4.89],[1,1.04,1.53],[2,1.03,200]],"ltp":1.72,"tv":10.64,"id":72857115}]}]}
{"op":"mcm","clk":"11895459193","pt":1724251290081,"mc":[{"id":"1.232049325","rc":[{"batb":[[0,1.04,2.42],[1,1.03,200],[2,1.02,200]],"ltp":1.72,"tv":10.64,"id":72857115}]}]}
{"op":"mcm","clk":"11895463958","pt":1724251337560,"mc":[{"id":"1.232049325","rc":[{"batb":[[0,1.06,10.89],[1,1.05,4],[2,1.04,1.53]],"ltp":1.72,"tv":10.64,"id":72857115}]}]}
{"op":"mcm","clk":"11895464114","pt":1724251339562,"mc":[{"id":"1.232049325","rc":[{"batb":[[1,1.04,1.53],[2,1.03,200]],"ltp":1.72,"tv":10.64,"id":72857115}]}]}
{"op":"mcm","clk":"11895464229","pt":1724251340866,"mc":[{"id":"1.232049325","rc":[{"batb":[[0,1.04,2.42],[1,1.03,200],[2,1.02,200]],"ltp":1.72,"tv":10.64,"id":72857115}]}]}
{"op":"mcm","clk":"11895464642","pt":1724251345351,"mc":[{"id":"1.232049325","rc":[{"batb":[[0,1.05,4.89],[1,1.04,1.53],[2,1.03,200]],"ltp":1.72,"tv":10.64,"id":72857115}]}]}
{"op":"mcm","clk":"11895464677","pt":1724251345766,"mc":[{"id":"1.232049325","rc":[{"batb":[[0,1.06,10.89],[1,1.05,4],[2,1.04,1.53]],"ltp":1.72,"tv":10.64,"id":72857115}]}]}
{"op":"mcm","clk":"11895464845","pt":1724251347877,"mc":[{"id":"1.232049325","rc":[{"batb":[[1,1.04,1.53],[2,1.03,200]],"ltp":1.72,"tv":10.64,"id":72857115}]}]}
{"op":"mcm","clk":"11895464991","pt":1724251349835,"mc":[{"id":"1.232049325","rc":[{"batb":[[0,1.04,2.42],[1,1.03,200],[2,1.02,200]],"ltp":1.72,"tv":10.64,"id":72857115}]}]}
{"op":"mcm","clk":"11895467320","pt":1724251377006,"mc":[{"id":"1.232049325","rc":[{"batb":[[0,1.06,10.89],[1,1.05,4],[2,1.04,1.53]],"ltp":1.72,"tv":10.64,"id":72857115}]}]}
{"op":"mcm","clk":"11895467528","pt":1724251379320,"mc":[{"id":"1.232049325","rc":[{"batb":[[1,1.04,1.53],[2,1.03,200]],"ltp":1.72,"tv":10.64,"id":72857115}]}]}
{"op":"mcm","clk":"11895467613","pt":1724251380403,"mc":[{"id":"1.232049325","rc":[{"batb":[[0,1.04,2.42],[1,1.03,200],[2,1.02,200]],"ltp":1.72,"tv":10.64,"id":72857115}]}]}
{"op":"mcm","clk":"11895473314","pt":1724251438073,"mc":[{"id":"1.232049325","rc":[{"batb":[[0,1.06,10.89],[1,1.05,4],[2,1.04,1.53]],"ltp":1.72,"tv":10.64,"id":72857115}]}]}
{"op":"mcm","clk":"11895473480","pt":1724251439983,"mc":[{"id":"1.232049325","rc":[{"batb":[[1,1.04,1.53],[2,1.03,200]],"ltp":1.72,"tv":10.64,"id":72857115}]}]}
{"op":"mcm","clk":"11895473638","pt":1724251441656,"mc":[{"id":"1.232049325","rc":[{"batb":[[0,1.04,2.42],[1,1.03,200],[2,1.02,200]],"ltp":1.72,"tv":10.64,"id":72857115}]}]}
{"op":"mcm","clk":"11895476128","pt":1724251468799,"mc":[{"id":"1.232049325","rc":[{"batb":[[0,1.06,10.89],[1,1.05,4],[2,1.04,1.53]],"ltp":1.72,"tv":10.64,"id":72857115}]}]}
{"op":"mcm","clk":"11895476366","pt":1724251471214,"mc":[{"id":"1.232049325","rc":[{"batb":[[1,1.04,1.53],[2,1.03,200]],"ltp":1.72,"tv":10.64,"id":72857115}]}]}
{"op":"mcm","clk":"11895476488","pt":1724251472508,"mc":[{"id":"1.232049325","rc":[{"batb":[[0,1.04,2.42],[1,1.03,200],[2,1.02,200]],"ltp":1.72,"tv":10.64,"id":72857115}]}]}
{"op":"mcm","clk":"11895476788","pt":1724251475700,"mc":[{"id":"1.232049325","rc":[{"batb":[[0,1.07,14.89],[1,1.04,1.53],[2,1.03,200]],"ltp":1.72,"tv":10.64,"id":72857115}]}]}
{"op":"mcm","clk":"11895477438","pt":1724251482742,"mc":[{"id":"1.232049325","rc":[{"batb":[[0,1.07,10.89]],"ltp":1.72,"tv":10.64,"id":72857115}]}]}
{"op":"mcm","clk":"11895477544","pt":1724251483822,"mc":[{"id":"1.232049325","rc":[{"batb":[[0,1.04,2.42],[1,1.03,200],[2,1.02,200]],"ltp":1.72,"tv":10.64,"id":72857115}]}]}
{"op":"mcm","clk":"11895477736","pt":1724251485944,"mc":[{"id":"1.232049325","rc":[{"batb":[[0,1.08,4.89],[1,1.04,1.53],[2,1.03,200]],"ltp":1.72,"tv":10.64,"id":72857115}]}]}
{"op":"mcm","clk":"11895477959","pt":1724251488317,"mc":[{"id":"1.232049325","rc":[{"batb":[[0,1.09,10.89],[1,1.08,4],[2,1.04,1.53]],"ltp":1.72,"tv":10.64,"id":72857115}]}]}
{"op":"mcm","clk":"11895478178","pt":1724251490623,"mc":[{"id":"1.232049325","rc":[{"batb":[[1,1.04,1.53],[2,1.03,200]],"ltp":1.72,"tv":10.64,"id":72857115}]}]}
{"op":"mcm","clk":"11895478464","pt":1724251494016,"mc":[{"id":"1.232049325","rc":[{"batb":[[0,1.04,2.42],[1,1.03,200],[2,1.02,200]],"ltp":1.72,"tv":10.64,"id":72857115}]}]}
{"op":"mcm","clk":"11895478545","pt":1724251495044,"mc":[{"id":"1.232049325","rc":[{"batb":[[0,1.05,4.89],[1,1.04,1.53],[2,1.03,200]],"ltp":1.72,"tv":10.64,"id":72857115}]}]}
{"op":"mcm","clk":"11895478792","pt":1724251497863,"mc":[{"id":"1.232049325","rc":[{"batb":[[0,1.04,2.42],[1,1.03,200],[2,1.02,200]],"ltp":1.72,"tv":10.64,"id":72857115}]}]}
{"op":"mcm","clk":"11895481203","pt":1724251520478,"mc":[{"id":"1.232049325","rc":[{"batb":[[0,1.67,1.78],[1,1.04,1.53],[2,1.03,200]],"ltp":1.72,"tv":10.64,"id":72857115}]}]}
{"op":"mcm","clk":"11895481229","pt":1724251520736,"mc":[{"id":"1.232049325","rc":[{"batb":[[0,1.69,10.89],[1,1.68,4],[2,1.04,2.42]],"ltp":1.72,"tv":10.64,"id":72857115}]}]}
{"op":"mcm","clk":"11895481456","pt":1724251523172,"mc":[{"id":"1.232049325","rc":[{"batb":[[1,1.04,2.42],[2,1.03,200]],"ltp":1.72,"tv":10.64,"id":72857115}]}]}
{"op":"mcm","clk":"11895481569","pt":1724251524272,"mc":[{"id":"1.232049325","rc":[{"batb":[[0,1.67,1.78],[1,1.04,1.53]],"ltp":1.72,"tv":10.64,"id":72857115}]}]}
{"op":"mcm","clk":"11895488339","pt":1724251591896,"mc":[{"id":"1.232049325","rc":[{"batb":[[0,1.69,10.89],[1,1.68,4],[2,1.04,2.42]],"ltp":1.72,"tv":10.64,"id":72857115}]}]}
{"op":"mcm","clk":"11895488621","pt":1724251594215,"mc":[{"id":"1.232049325","rc":[{"batb":[[1,1.04,2.42],[2,1.03,200]],"ltp":1.72,"tv":10.64,"id":72857115}]}]}
{"op":"mcm","clk":"11895488743","pt":1724251595492,"mc":[{"id":"1.232049325","rc":[{"batb":[[0,1.67,1.78],[1,1.04,1.53]],"ltp":1.72,"tv":10.64,"id":72857115}]}]}
{"op":"mcm","clk":"11895490023","pt":1724251607438,"mc":[{"id":"1.232049325","rc":[{"batb":[[0,1.68,4.89],[1,1.04,2.42]],"ltp":1.72,"tv":10.64,"id":72857115}]}]}
{"op":"mcm","clk":"11895490096","pt":1724251608124,"mc":[{"id":"1.232049325","rc":[{"batb":[[0,1.69,10.89],[1,1.68,4],[2,1.04,2.42]],"ltp":1.72,"tv":10.64,"id":72857115}]}]}
{"op":"mcm","clk":"11895490272","pt":1724251610092,"mc":[{"id":"1.232049325","rc":[{"batb":[[1,1.04,2.42],[2,1.03,200]],"ltp":1.72,"tv":10.64,"id":72857115}]}]}
{"op":"mcm","clk":"11895490470","pt":1724251611519,"mc":[{"id":"1.232049325","rc":[{"batb":[[0,1.67,1.78],[1,1.04,1.53]],"ltp":1.72,"tv":10.64,"id":72857115}]}]}
{"op":"mcm","clk":"11895493791","pt":1724251644476,"mc":[{"id":"1.232049325","rc":[{"batb":[[0,1.69,10.89],[1,1.68,4],[2,1.04,2.42]],"ltp":1.72,"tv":10.64,"id":72857115}]}]}
{"op":"mcm","clk":"11895494022","pt":1724251646542,"mc":[{"id":"1.232049325","rc":[{"batb":[[1,1.04,2.42],[2,1.03,200]],"ltp":1.72,"tv":10.64,"id":72857115}]}]}
{"op":"mcm","clk":"11895494149","pt":1724251647879,"mc":[{"id":"1.232049325","rc":[{"batb":[[0,1.67,1.78],[1,1.04,1.53]],"ltp":1.72,"tv":10.64,"id":72857115}]}]}
{"op":"mcm","clk":"11895495049","pt":1724251656246,"mc":[{"id":"1.232049325","rc":[{"batb":[[0,1.69,10.89],[1,1.68,4],[2,1.04,2.42]],"ltp":1.72,"tv":10.64,"id":72857115}]}]}
{"op":"mcm","clk":"11895495263","pt":1724251658289,"mc":[{"id":"1.232049325","rc":[{"batb":[[1,1.04,2.42],[2,1.03,200]],"ltp":1.72,"tv":10.64,"id":72857115}]}]}
{"op":"mcm","clk":"11895495420","pt":1724251659890,"mc":[{"id":"1.232049325","rc":[{"batb":[[0,1.67,1.78],[1,1.04,1.53]],"ltp":1.72,"tv":10.64,"id":72857115}]}]}
{"op":"mcm","clk":"11895496042","pt":1724251665977,"mc":[{"id":"1.232049325","rc":[{"batb":[[0,1.69,10.89],[1,1.68,4],[2,1.04,2.42]],"ltp":1.72,"tv":10.64,"id":72857115}]}]}
{"op":"mcm","clk":"11895496262","pt":1724251668094,"mc":[{"id":"1.232049325","rc":[{"batb":[[1,1.04,2.42],[2,1.03,200]],"ltp":1.72,"tv":10.64,"id":72857115}]}]}
{"op":"mcm","clk":"11895496423","pt":1724251669800,"mc":[{"id":"1.232049325","rc":[{"batb":[[0,1.67,1.78],[1,1.04,1.53]],"ltp":1.72,"tv":10.64,"id":72857115}]}]}
{"op":"mcm","clk":"11895497020","pt":1724251676395,"mc":[{"id":"1.232049325","rc":[{"batb":[[0,1.68,4.89],[1,1.04,2.42]],"ltp":1.72,"tv":10.64,"id":72857115}]}]}
{"op":"mcm","clk":"11895497076","pt":1724251676973,"mc":[{"id":"1.232049325","rc":[{"batb":[[0,1.69,10.89],[1,1.68,4],[2,1.04,2.42]],"ltp":1.72,"tv":10.64,"id":72857115}]}]}
{"op":"mcm","clk":"11895497251","pt":1724251678980,"mc":[{"id":"1.232049325","rc":[{"batb":[[1,1.04,2.42],[2,1.03,200]],"ltp":1.72,"tv":10.64,"id":72857115}]}]}
{"op":"mcm","clk":"11895497399","pt":1724251680591,"mc":[{"id":"1.232049325","rc":[{"batb":[[0,1.67,1.78],[1,1.04,1.53]],"ltp":1.72,"tv":10.64,"id":72857115}]}]}
{"op":"mcm","clk":"11895500069","pt":1724251708336,"mc":[{"id":"1.232049325","rc":[{"batb":[[0,1.69,10.89],[1,1.68,4],[2,1.04,2.42]],"ltp":1.72,"tv":10.64,"id":72857115}]}]}
{"op":"mcm","clk":"11895500353","pt":1724251710356,"mc":[{"id":"1.232049325","rc":[{"batb":[[1,1.04,2.42],[2,1.03,200]],"ltp":1.72,"tv":10.64,"id":72857115}]}]}
{"op":"mcm","clk":"11895500561","pt":1724251711755,"mc":[{"id":"1.232049325","rc":[{"batb":[[0,1.67,1.78],[1,1.04,1.53]],"ltp":1.72,"tv":10.64,"id":72857115}]}]}
{"op":"mcm","clk":"11895501816","pt":1724251721330,"mc":[{"id":"1.232049325","rc":[{"batb":[[0,1.69,10.89],[1,1.68,4],[2,1.04,2.42]],"ltp":1.72,"tv":10.64,"id":72857115}]}]}
{"op":"mcm","clk":"11895501987","pt":1724251723346,"mc":[{"id":"1.232049325","rc":[{"batb":[[1,1.04,2.42],[2,1.03,200]],"ltp":1.72,"tv":10.64,"id":72857115}]}]}
{"op":"mcm","clk":"11895502121","pt":1724251724751,"mc":[{"id":"1.232049325","rc":[{"batb":[[0,1.67,1.78],[1,1.04,1.53]],"ltp":1.72,"tv":10.64,"id":72857115}]}]}
{"op":"mcm","clk":"11895502827","pt":1724251732074,"mc":[{"id":"1.232049325","rc":[{"batb":[[0,1.69,10.89],[1,1.68,4],[2,1.04,2.42]],"ltp":1.72,"tv":10.64,"id":72857115}]}]}
{"op":"mcm","clk":"11895503065","pt":1724251734358,"mc":[{"id":"1.232049325","rc":[{"batb":[[1,1.04,2.42],[2,1.03,200]],"ltp":1.72,"tv":10.64,"id":72857115}]}]}
{"op":"mcm","clk":"11895503190","pt":1724251735559,"mc":[{"id":"1.232049325","rc":[{"batb":[[0,1.67,1.78],[1,1.04,1.53]],"ltp":1.72,"tv":10.64,"id":72857115}]}]}
{"op":"mcm","clk":"11895504716","pt":1724251750252,"mc":[{"id":"1.232049325","rc":[{"batb":[[0,1.68,4.89],[1,1.04,2.42]],"ltp":1.72,"tv":10.64,"id":72857115}]}]}
{"op":"mcm","clk":"11895504784","pt":1724251750870,"mc":[{"id":"1.232049325","rc":[{"batb":[[0,1.69,10.89],[1,1.68,4],[2,1.04,2.42]],"ltp":1.72,"tv":10.64,"id":72857115}]}]}
{"op":"mcm","clk":"11895504988","pt":1724251752958,"mc":[{"id":"1.232049325","rc":[{"batb":[[1,1.04,2.42],[2,1.03,200]],"ltp":1.72,"tv":10.64,"id":72857115}]}]}
{"op":"mcm","clk":"11895505118","pt":1724251754575,"mc":[{"id":"1.232049325","rc":[{"batb":[[0,1.67,1.78],[1,1.04,1.53]],"ltp":1.72,"tv":10.64,"id":72857115}]}]}
{"op":"mcm","clk":"11895505378","pt":1724251757262,"mc":[{"id":"1.232049325","rc":[{"batb":[[0,1.69,10.89],[1,1.68,4],[2,1.04,2.42]],"ltp":1.72,"tv":10.64,"id":72857115}]}]}
{"op":"mcm","clk":"11895505568","pt":1724251759382,"mc":[{"id":"1.232049325","rc":[{"batb":[[1,1.04,2.42],[2,1.03,200]],"ltp":1.72,"tv":10.64,"id":72857115}]}]}
{"op":"mcm","clk":"11895505704","pt":1724251761093,"mc":[{"id":"1.232049325","rc":[{"batb":[[0,1.67,1.78],[1,1.04,1.53]],"ltp":1.72,"tv":10.64,"id":72857115}]}]}
{"op":"mcm","clk":"11895507212","pt":1724251778285,"mc":[{"id":"1.232049325","rc":[{"batb":[[0,1.72,10],[1,1.71,4],[2,1.7,1.51]],"ltp":1.72,"tv":10.64,"id":72857115}]}]}
{"op":"mcm","clk":"11895507376","pt":1724251780301,"mc":[{"id":"1.232049325","rc":[{"batb":[[1,1.7,1.51],[2,1.67,1.78]],"ltp":1.72,"tv":10.64,"id":72857115}]}]}
{"op":"mcm","clk":"11895507484","pt":1724251781608,"mc":[{"id":"1.232049325","rc":[{"batb":[[0,1.7,1.51],[1,1.67,1.78],[2,1.04,1.53]],"ltp":1.72,"tv":10.64,"id":72857115}]}]}
{"op":"mcm","clk":"11895508263","pt":1724251790790,"mc":[{"id":"1.232049325","rc":[{"batb":[[0,1.71,1.51],[1,1.68,4.89],[2,1.04,2.42]],"ltp":1.72,"tv":10.64,"id":72857115}]}]}
{"op":"mcm","clk":"11895508481","pt":1724251793538,"mc":[{"id":"1.232049325","rc":[{"batb":[[1,1.67,1.78],[2,1.04,1.53]],"ltp":1.72,"tv":10.64,"id":72857115}]}]}
{"op":"mcm","clk":"11895510691","pt":1724251814927,"mc":[{"id":"1.232049325","rc":[{"batb":[[0,1.73,10],[1,1.72,4],[2,1.71,1.51]],"ltp":1.72,"tv":10.64,"id":72857115}]}]}
{"op":"mcm","clk":"11895510920","pt":1724251817257,"mc":[{"id":"1.232049325","rc":[{"batb":[[1,1.71,1.51],[2,1.67,1.78]],"ltp":1.72,"tv":10.64,"id":72857115}]}]}
{"op":"mcm","clk":"11895511070","pt":1724251818625,"mc":[{"id":"1.232049325","rc":[{"batb":[[0,1.71,1.51],[1,1.67,1.78],[2,1.04,1.53]],"ltp":1.72,"tv":10.64,"id":72857115}]}]}
{"op":"mcm","clk":"11895511384","pt":1724251821569,"mc":[{"id":"1.232049325","rc":[{"batb":[[0,1.73,10],[1,1.72,4],[2,1.71,1.51]],"ltp":1.72,"tv":10.64,"id":72857115}]}]}
{"op":"mcm","clk":"11895511592","pt":1724251823634,"mc":[{"id":"1.232049325","rc":[{"batb":[[1,1.71,1.51],[2,1.67,1.78]],"ltp":1.72,"tv":10.64,"id":72857115}]}]}
{"op":"mcm","clk":"11895511730","pt":1724251825336,"mc":[{"id":"1.232049325","rc":[{"batb":[[0,1.71,1.51],[1,1.67,1.78],[2,1.04,1.53]],"ltp":1.72,"tv":10.64,"id":72857115}]}]}
{"op":"mcm","clk":"11895512992","pt":1724251839543,"mc":[{"id":"1.232049325","rc":[{"batb":[[0,1.72,4],[1,1.71,1.51],[2,1.67,1.78]],"ltp":1.72,"tv":10.64,"id":72857115}]}]}
{"op":"mcm","clk":"11895513013","pt":1724251839752,"mc":[{"id":"1.232049325","rc":[{"batb":[[0,1.73,10],[1,1.72,4],[2,1.71,1.51]],"ltp":1.72,"tv":10.64,"id":72857115}]}]}
{"op":"mcm","clk":"11895513241","pt":1724251841867,"mc":[{"id":"1.232049325","rc":[{"batb":[[1,1.71,1.51],[2,1.67,1.78]],"ltp":1.72,"tv":10.64,"id":72857115}]}]}
{"op":"mcm","clk":"11895513463","pt":1724251844387,"mc":[{"id":"1.232049325","rc":[{"batb":[[0,1.72,4]],"ltp":1.72,"tv":10.64,"id":72857115}]}]}
{"op":"mcm","clk":"11895513707","pt":1724251847176,"mc":[{"id":"1.232049325","rc":[{"batb":[[0,1.71,1.51],[1,1.67,1.78],[2,1.04,1.53]],"ltp":1.72,"tv":10.64,"id":72857115}]}]}
{"op":"mcm","clk":"11895514297","pt":1724251853392,"mc":[{"id":"1.232049325","rc":[{"batb":[[0,1.72,4],[1,1.71,1.51],[2,1.67,1.78]],"ltp":1.72,"tv":10.64,"id":72857115}]}]}
{"op":"mcm","clk":"11895514337","pt":1724251853759,"mc":[{"id":"1.232049325","rc":[{"batb":[[0,1.73,10],[1,1.72,4],[2,1.71,1.51]],"ltp":1.72,"tv":10.64,"id":72857115}]}]}
{"op":"mcm","clk":"11895514559","pt":1724251856182,"mc":[{"id":"1.232049325","rc":[{"batb":[[1,1.71,1.51],[2,1.67,1.78]],"ltp":1.72,"tv":10.64,"id":72857115}]}]}
{"op":"mcm","clk":"11895514671","pt":1724251857491,"mc":[{"id":"1.232049325","rc":[{"batb":[[0,1.71,1.51],[1,1.67,1.78],[2,1.04,1.53]],"ltp":1.72,"tv":10.64,"id":72857115}]}]}
{"op":"mcm","clk":"11895515653","pt":1724251868211,"mc":[{"id":"1.232049325","rc":[{"batb":[[0,1.72,4],[1,1.71,1.51],[2,1.67,1.78]],"ltp":1.72,"tv":10.64,"id":72857115}]}]}
{"op":"mcm","clk":"11895515696","pt":1724251868676,"mc":[{"id":"1.232049325","rc":[{"batb":[[0,1.73,10],[1,1.72,4],[2,1.71,1.51]],"ltp":1.72,"tv":10.64,"id":72857115}]}]}
{"op":"mcm","clk":"11895515911","pt":1724251870922,"mc":[{"id":"1.232049325","rc":[{"batb":[[1,1.71,1.51],[2,1.67,1.78]],"ltp":1.72,"tv":10.64,"id":72857115}]}]}
{"op":"mcm","clk":"11895516020","pt":1724251872112,"mc":[{"id":"1.232049325","rc":[{"batb":[[0,1.71,1.51],[1,1.67,1.78],[2,1.04,1.53]],"ltp":1.72,"tv":10.64,"id":72857115}]}]}
{"op":"mcm","clk":"11895517438","pt":1724251887037,"mc":[{"id":"1.232049325","rc":[{"batb":[[0,1.73,10],[1,1.72,4],[2,1.71,1.51]],"ltp":1.72,"tv":10.64,"id":72857115}]}]}
{"op":"mcm","clk":"11895517644","pt":1724251889406,"mc":[{"id":"1.232049325","rc":[{"batb":[[1,1.71,1.51],[2,1.67,1.78]],"ltp":1.72,"tv":10.64,"id":72857115}]}]}
{"op":"mcm","clk":"11895517767","pt":1724251890951,"mc":[{"id":"1.232049325","rc":[{"batb":[[0,1.71,1.51],[1,1.67,1.78],[2,1.04,1.53]],"ltp":1.72,"tv":10.64,"id":72857115}]}]}
{"op":"mcm","clk":"11895518208","pt":1724251896112,"mc":[{"id":"1.232049325","rc":[{"batb":[[0,1.73,10],[1,1.72,4],[2,1.71,1.51]],"ltp":1.72,"tv":10.64,"id":72857115}]}]}
{"op":"mcm","clk":"11895518378","pt":1724251898319,"mc":[{"id":"1.232049325","rc":[{"batb":[[1,1.71,1.51],[2,1.67,1.78]],"ltp":1.72,"tv":10.64,"id":72857115}]}]}
{"op":"mcm","clk":"11895518502","pt":1724251899770,"mc":[{"id":"1.232049325","rc":[{"batb":[[0,1.71,1.51],[1,1.67,1.78],[2,1.04,1.53]],"ltp":1.72,"tv":10.64,"id":72857115}]}]}
{"op":"mcm","clk":"11895521169","pt":1724251925289,"mc":[{"id":"1.232049325","rc":[{"batb":[[0,1.72,4],[1,1.71,1.51],[2,1.67,1.78]],"ltp":1.72,"tv":10.64,"id":72857115}]}]}
{"op":"mcm","clk":"11895521253","pt":1724251925957,"mc":[{"id":"1.232049325","rc":[{"batb":[[0,1.73,10],[1,1.72,4],[2,1.71,1.51]],"ltp":1.72,"tv":10.64,"id":72857115}]}]}
{"op":"mcm","clk":"11895521433","pt":1724251927872,"mc":[{"id":"1.232049325","rc":[{"batb":[[1,1.71,1.51],[2,1.67,1.78]],"ltp":1.72,"tv":10.64,"id":72857115}]}]}
{"op":"mcm","clk":"11895521584","pt":1724251929570,"mc":[{"id":"1.232049325","rc":[{"batb":[[0,1.71,1.51],[1,1.67,1.78],[2,1.04,1.53]],"ltp":1.72,"tv":10.64,"id":72857115}]}]}
{"op":"mcm","clk":"11895521756","pt":1724251931277,"mc":[{"id":"1.232049325","rc":[{"batb":[[0,1.72,4],[1,1.71,1.51],[2,1.67,1.78]],"ltp":1.72,"tv":10.64,"id":72857115}]}]}
{"op":"mcm","clk":"11895522002","pt":1724251933857,"mc":[{"id":"1.232049325","rc":[{"batb":[[0,1.71,1.51],[1,1.67,1.78],[2,1.04,1.53]],"ltp":1.72,"tv":10.64,"id":72857115}]}]}
{"op":"mcm","clk":"11895522833","pt":1724251943180,"mc":[{"id":"1.232049325","rc":[{"batb":[[0,1.72,4],[1,1.71,1.51],[2,1.67,1.78]],"ltp":1.72,"tv":10.64,"id":72857115}]}]}
{"op":"mcm","clk":"11895522970","pt":1724251944312,"mc":[{"id":"1.232049325","rc":[{"batb":[[0,1.73,10],[1,1.72,4],[2,1.71,1.51]],"ltp":1.72,"tv":10.64,"id":72857115}]}]}
{"op":"mcm","clk":"11895523180","pt":1724251946381,"mc":[{"id":"1.232049325","rc":[{"batb":[[1,1.71,1.51],[2,1.67,1.78]],"ltp":1.72,"tv":10.64,"id":72857115}]}]}
{"op":"mcm","clk":"11895523323","pt":1724251947975,"mc":[{"id":"1.232049325","rc":[{"batb":[[0,1.71,1.51],[1,1.67,1.78],[2,1.04,1.53]],"ltp":1.72,"tv":10.64,"id":72857115}]}]}
{"op":"mcm","clk":"11895523789","pt":1724251953396,"mc":[{"id":"1.232049325","rc":[{"batb":[[0,1.72,4],[1,1.71,1.51],[2,1.67,1.78]],"ltp":1.72,"tv":10.64,"id":72857115}]}]}
{"op":"mcm","clk":"11895523806","pt":1724251953601,"mc":[{"id":"1.232049325","rc":[{"batb":[[0,1.73,10],[1,1.72,4],[2,1.71,1.51]],"ltp":1.72,"tv":10.64,"id":72857115}]}]}
{"op":"mcm","clk":"11895524031","pt":1724251956026,"mc":[{"id":"1.232049325","rc":[{"batb":[[1,1.71,1.51],[2,1.67,1.78]],"ltp":1.72,"tv":10.64,"id":72857115}]}]}
{"op":"mcm","clk":"11895524193","pt":1724251957727,"mc":[{"id":"1.232049325","rc":[{"batb":[[0,1.71,1.51],[1,1.67,1.78],[2,1.04,1.53]],"ltp":1.72,"tv":10.64,"id":72857115}]}]}
{"op":"mcm","clk":"11895525117","pt":1724251968508,"mc":[{"id":"1.232049325","rc":[{"batb":[[0,1.72,4],[1,1.71,1.51],[2,1.67,1.78]],"ltp":1.72,"tv":10.64,"id":72857115}]}]}
{"op":"mcm","clk":"11895525139","pt":1724251968714,"mc":[{"id":"1.232049325","rc":[{"batb":[[0,1.73,10],[1,1.72,4],[2,1.71,1.51]],"ltp":1.72,"tv":10.64,"id":72857115}]}]}
{"op":"mcm","clk":"11895525353","pt":1724251971035,"mc":[{"id":"1.232049325","rc":[{"batb":[[1,1.71,1.51],[2,1.67,1.78]],"ltp":1.72,"tv":10.64,"id":72857115}]}]}
{"op":"mcm","clk":"11895525494","pt":1724251972627,"mc":[{"id":"1.232049325","rc":[{"batb":[[0,1.71,1.51],[1,1.67,1.78],[2,1.04,1.53]],"ltp":1.72,"tv":10.64,"id":72857115}]}]}
{"op":"mcm","clk":"11895525864","pt":1724251977310,"mc":[{"id":"1.232049325","rc":[{"batb":[[0,1.72,4],[1,1.71,1.51],[2,1.67,1.78]],"ltp":1.72,"tv":10.64,"id":72857115}]}]}
{"op":"mcm","clk":"11895525914","pt":1724251977931,"mc":[{"id":"1.232049325","rc":[{"batb":[[0,1.73,10],[1,1.72,4],[2,1.71,1.51]],"ltp":1.72,"tv":10.64,"id":72857115}]}]}
{"op":"mcm","clk":"11895526095","pt":1724251980349,"mc":[{"id":"1.232049325","rc":[{"batb":[[1,1.71,1.51],[2,1.67,1.78]],"ltp":1.72,"tv":10.64,"id":72857115}]}]}
{"op":"mcm","clk":"11895526224","pt":1724251981852,"mc":[{"id":"1.232049325","rc":[{"batb":[[0,1.71,1.51],[1,1.67,1.78],[2,1.04,1.53]],"ltp":1.72,"tv":10.64,"id":72857115}]}]}
{"op":"mcm","clk":"11895526709","pt":1724251987359,"mc":[{"id":"1.232049325","rc":[{"batb":[[0,1.73,10],[1,1.72,4],[2,1.71,1.51]],"ltp":1.72,"tv":10.64,"id":72857115}]}]}
{"op":"mcm","clk":"11895526878","pt":1724251989225,"mc":[{"id":"1.232049325","rc":[{"batb":[[1,1.71,1.51],[2,1.67,1.78]],"ltp":1.72,"tv":10.64,"id":72857115}]}]}
{"op":"mcm","clk":"11895527055","pt":1724251991281,"mc":[{"id":"1.232049325","rc":[{"batb":[[0,1.71,1.51],[1,1.67,1.78],[2,1.04,1.53]],"ltp":1.72,"tv":10.64,"id":72857115}]}]}
{"op":"mcm","clk":"11895527092","pt":1724251991643,"mc":[{"id":"1.232049325","rc":[{"batb":[[0,1.72,4],[1,1.71,1.51],[2,1.67,1.78]],"ltp":1.72,"tv":10.64,"id":72857115}]}]}
{"op":"mcm","clk":"11895527296","pt":1724251993959,"mc":[{"id":"1.232049325","rc":[{"batb":[[0,1.71,1.51],[1,1.67,1.78],[2,1.04,1.53]],"ltp":1.72,"tv":10.64,"id":72857115}]}]}
{"op":"mcm","clk":"11895528535","pt":1724252007945,"mc":[{"id":"1.232049325","rc":[{"batb":[[0,1.72,4],[1,1.71,1.51],[2,1.67,1.78]],"ltp":1.72,"tv":10.64,"id":72857115}]}]}
{"op":"mcm","clk":"11895528609","pt":1724252008667,"mc":[{"id":"1.232049325","rc":[{"batb":[[0,1.73,10],[1,1.72,4],[2,1.71,1.51]],"ltp":1.72,"tv":10.64,"id":72857115}]}]}
{"op":"mcm","clk":"11895528848","pt":1724252010367,"mc":[{"id":"1.232049325","rc":[{"batb":[[1,1.71,1.51],[2,1.67,1.78]],"ltp":1.72,"tv":10.64,"id":72857115}]}]}
{"op":"mcm","clk":"11895529091","pt":1724252012279,"mc":[{"id":"1.232049325","rc":[{"batb":[[0,1.71,1.51],[1,1.67,1.78],[2,1.04,1.53]],"ltp":1.72,"tv":10.64,"id":72857115}]}]}
{"op":"mcm","clk":"11895533114","pt":1724252046495,"mc":[{"id":"1.232049325","rc":[{"batb":[[0,1.72,4],[1,1.71,1.51],[2,1.67,1.78]],"ltp":1.72,"tv":10.64,"id":72857115}]}]}
{"op":"mcm","clk":"11895533207","pt":1724252047116,"mc":[{"id":"1.232049325","rc":[{"batb":[[0,1.73,10],[1,1.72,4],[2,1.71,1.51]],"ltp":1.72,"tv":10.64,"id":72857115}]}]}
{"op":"mcm","clk":"11895533426","pt":1724252049228,"mc":[{"id":"1.232049325","rc":[{"batb":[[1,1.71,1.51],[2,1.67,1.78]],"ltp":1.72,"tv":10.64,"id":72857115}]}]}
{"op":"mcm","clk":"11895533599","pt":1724252050889,"mc":[{"id":"1.232049325","rc":[{"batb":[[0,1.71,1.51],[1,1.67,1.78],[2,1.04,1.53]],"ltp":1.72,"tv":10.64,"id":72857115}]}]}
{"op":"mcm","clk":"11895534075","pt":1724252056452,"mc":[{"id":"1.232049325","rc":[{"batb":[[0,1.72,4],[1,1.71,1.51],[2,1.67,1.78]],"ltp":1.72,"tv":10.64,"id":72857115}]}]}
{"op":"mcm","clk":"11895534663","pt":1724252063017,"mc":[{"id":"1.232049325","rc":[{"batb":[[0,1.73,10],[1,1.72,4],[2,1.71,1.51]],"ltp":1.72,"tv":10.64,"id":72857115}]}]}
{"op":"mcm","clk":"11895534834","pt":1724252065137,"mc":[{"id":"1.232049325","rc":[{"batb":[[1,1.71,1.51],[2,1.67,1.78]],"ltp":1.72,"tv":10.64,"id":72857115}]}]}
{"op":"mcm","clk":"11895535111","pt":1724252068318,"mc":[{"id":"1.232049325","rc":[{"batb":[[0,1.74,4],[1,1.73,10],[2,1.71,1.51]],"ltp":1.72,"tv":10.64,"id":72857115}]}]}
{"op":"mcm","clk":"11895535379","pt":1724252071370,"mc":[{"id":"1.232049325","rc":[{"batb":[[1,1.71,1.51],[2,1.67,1.78]],"ltp":1.72,"tv":10.64,"id":72857115}]}]}
{"op":"mcm","clk":"11895535625","pt":1724252074436,"mc":[{"id":"1.232049325","rc":[{"batb":[[0,1.75,10],[1,1.74,4],[2,1.71,1.51]],"ltp":1.72,"tv":10.64,"id":72857115}]}]}
{"op":"mcm","clk":"11895535651","pt":1724252074741,"mc":[{"id":"1.232049325","rc":[{"batb":[[1,1.71,1.51],[2,1.67,1.78]],"ltp":1.72,"tv":10.64,"id":72857115}]}]}
{"op":"mcm","clk":"11895535850","pt":1724252077122,"mc":[{"id":"1.232049325","rc":[{"batb":[[0,1.76,4],[1,1.75,10],[2,1.71,1.51]],"ltp":1.72,"tv":10.64,"id":72857115}]}]}
{"op":"mcm","clk":"11895536099","pt":1724252080437,"mc":[{"id":"1.232049325","rc":[{"batb":[[1,1.71,1.51],[2,1.67,1.78]],"ltp":1.72,"tv":10.64,"id":72857115}]}]}
{"op":"mcm","clk":"11895536209","pt":1724252081932,"mc":[{"id":"1.232049325","rc":[{"batb":[[0,1.71,1.51],[1,1.67,1.78],[2,1.04,1.53]],"ltp":1.72,"tv":10.64,"id":72857115}]}]}
{"op":"mcm","clk":"11895536390","pt":1724252084152,"mc":[{"id":"1.232049325","rc":[{"batb":[[0,1.72,4],[1,1.71,1.51],[2,1.67,1.78]],"ltp":1.72,"tv":10.64,"id":72857115}]}]}
{"op":"mcm","clk":"11895536585","pt":1724252086654,"mc":[{"id":"1.232049325","rc":[{"batb":[[0,1.73,10],[1,1.72,4],[2,1.71,1.51]],"ltp":1.72,"tv":10.64,"id":72857115}]}]}
{"op":"mcm","clk":"11895536759","pt":1724252088753,"mc":[{"id":"1.232049325","rc":[{"batb":[[1,1.71,1.51],[2,1.67,1.78]],"ltp":1.72,"tv":10.64,"id":72857115}]}]}
{"op":"mcm","clk":"11895536950","pt":1724252091069,"mc":[{"id":"1.232049325","rc":[{"batb":[[0,1.74,4],[1,1.73,10],[2,1.71,1.51]],"ltp":1.72,"tv":10.64,"id":72857115}]}]}
{"op":"mcm","clk":"11895537029","pt":1724252091847,"mc":[{"id":"1.232049325","rc":[{"batb":[[1,1.71,1.51],[2,1.67,1.78]],"ltp":1.72,"tv":10.64,"id":72857115}]}]}
{"op":"mcm","clk":"11895537232","pt":1724252094473,"mc":[{"id":"1.232049325","rc":[{"batb":[[0,1.71,1.51],[1,1.67,1.78],[2,1.04,1.53]],"ltp":1.72,"tv":10.64,"id":72857115}]}]}
{"op":"mcm","clk":"11895537618","pt":1724252098954,"mc":[{"id":"1.232049325","rc":[{"batb":[[0,1.72,4],[1,1.71,1.51],[2,1.67,1.78]],"ltp":1.72,"tv":10.64,"id":72857115}]}]}
{"op":"mcm","clk":"11895537692","pt":1724252099989,"mc":[{"id":"1.232049325","rc":[{"batb":[[0,1.73,10],[1,1.72,4],[2,1.71,1.51]],"ltp":1.72,"tv":10.64,"id":72857115}]}]}
{"op":"mcm","clk":"11895537864","pt":1724252102084,"mc":[{"id":"1.232049325","rc":[{"batb":[[1,1.71,1.51],[2,1.67,1.78]],"ltp":1.72,"tv":10.64,"id":72857115}]}]}
{"op":"mcm","clk":"11895538008","pt":1724252103493,"mc":[{"id":"1.232049325","rc":[{"batb":[[0,1.71,1.51],[1,1.67,1.78],[2,1.04,1.53]],"ltp":1.72,"tv":10.64,"id":72857115}]}]}
{"op":"mcm","clk":"11895539862","pt":1724252123867,"mc":[{"id":"1.232049325","rc":[{"batb":[[0,1.73,10],[1,1.72,4],[2,1.71,1.51]],"ltp":1.72,"tv":10.64,"id":72857115}]}]}
{"op":"mcm","clk":"11895540023","pt":1724252125986,"mc":[{"id":"1.232049325","rc":[{"batb":[[1,1.71,1.51],[2,1.67,1.78]],"ltp":1.72,"tv":10.64,"id":72857115}]}]}
{"op":"mcm","clk":"11895540160","pt":1724252127701,"mc":[{"id":"1.232049325","rc":[{"batb":[[0,1.71,1.51],[1,1.67,1.78],[2,1.04,1.53]],"ltp":1.72,"tv":10.64,"id":72857115}]}]}
{"op":"mcm","clk":"11895540349","pt":1724252130193,"mc":[{"id":"1.232049325","rc":[{"batb":[[0,1.73,10],[1,1.72,4],[2,1.71,1.51]],"ltp":1.72,"tv":10.64,"id":72857115}]}]}
{"op":"mcm","clk":"11895540551","pt":1724252132688,"mc":[{"id":"1.232049325","rc":[{"batb":[[1,1.71,1.51],[2,1.67,1.78]],"ltp":1.72,"tv":10.64,"id":72857115}]}]}
{"op":"mcm","clk":"11895540638","pt":1724252133981,"mc":[{"id":"1.232049325","rc":[{"batb":[[0,1.71,1.51],[1,1.67,1.78],[2,1.04,1.53]],"ltp":1.72,"tv":10.64,"id":72857115}]}]}
{"op":"mcm","clk":"11895540869","pt":1724252137193,"mc":[{"id":"1.232049325","rc":[{"batb":[[0,1.72,4],[1,1.71,1.51],[2,1.67,1.78]],"ltp":1.72,"tv":10.64,"id":72857115}]}]}
{"op":"mcm","clk":"11895540936","pt":1724252138017,"mc":[{"id":"1.232049325","rc":[{"batb":[[0,1.73,10],[1,1.72,4],[2,1.71,1.51]],"ltp":1.72,"tv":10.64,"id":72857115}]}]}
{"op":"mcm","clk":"11895541154","pt":1724252140190,"mc":[{"id":"1.232049325","rc":[{"batb":[[1,1.71,1.51],[2,1.67,1.78]],"ltp":1.72,"tv":10.64,"id":72857115}]}]}
{"op":"mcm","clk":"11895541311","pt":1724252141895,"mc":[{"id":"1.232049325","rc":[{"batb":[[0,1.71,1.51],[1,1.67,1.78],[2,1.04,1.53]],"ltp":1.72,"tv":10.64,"id":72857115}]}]}
{"op":"mcm","clk":"11895543109","pt":1724252162164,"mc":[{"id":"1.232049325","rc":[{"batb":[[0,1.72,4],[1,1.71,1.51],[2,1.67,1.78]],"ltp":1.72,"tv":10.64,"id":72857115}]}]}
{"op":"mcm","clk":"11895543169","pt":1724252162756,"mc":[{"id":"1.232049325","rc":[{"batb":[[0,1.73,10],[1,1.72,4],[2,1.71,1.51]],"ltp":1.72,"tv":10.64,"id":72857115}]}]}
{"op":"mcm","clk":"11895543355","pt":1724252164965,"mc":[{"id":"1.232049325","rc":[{"batb":[[1,1.71,1.51],[2,1.67,1.78]],"ltp":1.72,"tv":10.64,"id":72857115}]}]}
{"op":"mcm","clk":"11895543493","pt":1724252166459,"mc":[{"id":"1.232049325","rc":[{"batb":[[0,1.71,1.51],[1,1.67,1.78],[2,1.04,1.53]],"ltp":1.72,"tv":10.64,"id":72857115}]}]}
{"op":"mcm","clk":"11895546181","pt":1724252195106,"mc":[{"id":"1.232049325","rc":[{"batb":[[0,1.72,4],[1,1.71,1.51],[2,1.67,1.78]],"ltp":1.72,"tv":10.64,"id":72857115}]}]}
{"op":"mcm","clk":"11895546261","pt":1724252195882,"mc":[{"id":"1.232049325","rc":[{"batb":[[0,1.73,10],[1,1.72,4],[2,1.71,1.51]],"ltp":1.72,"tv":10.64,"id":72857115}]}]}
{"op":"mcm","clk":"11895546401","pt":1724252197590,"mc":[{"id":"1.232049325","rc":[{"batb":[[1,1.71,1.51],[2,1.67,1.78]],"ltp":1.72,"tv":10.64,"id":72857115}]}]}
{"op":"mcm","clk":"11895546589","pt":1724252199915,"mc":[{"id":"1.232049325","rc":[{"batb":[[0,1.72,4]],"ltp":1.72,"tv":10.64,"id":72857115}]}]}
{"op":"mcm","clk":"11895546765","pt":1724252202289,"mc":[{"id":"1.232049325","rc":[{"batb":[[0,1.71,1.51],[1,1.67,1.78],[2,1.04,1.53]],"ltp":1.72,"tv":10.64,"id":72857115}]}]}
{"op":"mcm","clk":"11895547417","pt":1724252210124,"mc":[{"id":"1.232049325","rc":[{"batb":[[0,1.72,4],[1,1.71,1.51],[2,1.67,1.78]],"ltp":1.72,"tv":10.64,"id":72857115}]}]}
{"op":"mcm","clk":"11895547463","pt":1724252210804,"mc":[{"id":"1.232049325","rc":[{"batb":[[0,1.73,10],[1,1.72,4],[2,1.71,1.51]],"ltp":1.72,"tv":10.64,"id":72857115}]}]}
{"op":"mcm","clk":"11895547613","pt":1724252212817,"mc":[{"id":"1.232049325","rc":[{"batb":[[1,1.71,1.51],[2,1.67,1.78]],"ltp":1.72,"tv":10.64,"id":72857115}]}]}
{"op":"mcm","clk":"11895547749","pt":1724252214720,"mc":[{"id":"1.232049325","rc":[{"batb":[[0,1.71,1.51],[1,1.67,1.78],[2,1.04,1.53]],"ltp":1.72,"tv":10.64,"id":72857115}]}]}
{"op":"mcm","clk":"11895548525","pt":1724252225144,"mc":[{"id":"1.232049325","rc":[{"batb":[[0,1.72,4],[1,1.71,1.51],[2,1.67,1.78]],"ltp":1.72,"tv":10.64,"id":72857115}]}]}
{"op":"mcm","clk":"11895548558","pt":1724252225656,"mc":[{"id":"1.232049325","rc":[{"batb":[[0,1.73,10],[1,1.72,4],[2,1.71,1.51]],"ltp":1.72,"tv":10.64,"id":72857115}]}]}
{"op":"mcm","clk":"11895548707","pt":1724252227835,"mc":[{"id":"1.232049325","rc":[{"batb":[[1,1.71,1.51],[2,1.67,1.78]],"ltp":1.72,"tv":10.64,"id":72857115}]}]}
{"op":"mcm","clk":"11895548807","pt":1724252229258,"mc":[{"id":"1.232049325","rc":[{"batb":[[0,1.71,1.51],[1,1.67,1.78],[2,1.04,1.53]],"ltp":1.72,"tv":10.64,"id":72857115}]}]}
{"op":"mcm","clk":"11895550535","pt":1724252253574,"mc":[{"id":"1.232049325","rc":[{"batb":[[0,1.73,10],[1,1.72,4],[2,1.71,1.51]],"ltp":1.72,"tv":10.64,"id":72857115}]}]}
{"op":"mcm","clk":"11895550683","pt":1724252255778,"mc":[{"id":"1.232049325","rc":[{"batb":[[1,1.71,1.51],[2,1.67,1.78]],"ltp":1.72,"tv":10.64,"id":72857115}]}]}
{"op":"mcm","clk":"11895550850","pt":1724252258089,"mc":[{"id":"1.232049325","rc":[{"batb":[[0,1.72,4]],"ltp":1.72,"tv":10.64,"id":72857115}]}]}
{"op":"mcm","clk":"11895551009","pt":1724252260568,"mc":[{"id":"1.232049325","rc":[{"batb":[[0,1.71,1.51],[1,1.67,1.78],[2,1.04,1.53]],"ltp":1.72,"tv":10.64,"id":72857115}]}]}
{"op":"mcm","clk":"11895551418","pt":1724252266470,"mc":[{"id":"1.232049325","rc":[{"batb":[[0,1.72,4],[1,1.71,1.51],[2,1.67,1.78]],"ltp":1.72,"tv":10.64,"id":72857115}]}]}
{"op":"mcm","clk":"11895551461","pt":1724252266978,"mc":[{"id":"1.232049325","rc":[{"batb":[[0,1.73,10],[1,1.72,4],[2,1.71,1.51]],"ltp":1.72,"tv":10.64,"id":72857115}]}]}
{"op":"mcm","clk":"11895551733","pt":1724252269107,"mc":[{"id":"1.232049325","rc":[{"batb":[[1,1.71,1.51],[2,1.67,1.78]],"ltp":1.72,"tv":10.64,"id":72857115}]}]}
{"op":"mcm","clk":"11895551943","pt":1724252270698,"mc":[{"id":"1.232049325","rc":[{"batb":[[0,1.71,1.51],[1,1.67,1.78],[2,1.04,1.53]],"ltp":1.72,"tv":10.64,"id":72857115}]}]}
{"op":"mcm","clk":"11895552521","pt":1724252277398,"mc":[{"id":"1.232049325","rc":[{"batb":[[0,1.73,10],[1,1.72,4],[2,1.71,1.51]],"ltp":1.72,"tv":10.64,"id":72857115}]}]}
{"op":"mcm","clk":"11895552718","pt":1724252279504,"mc":[{"id":"1.232049325","rc":[{"batb":[[1,1.71,1.51],[2,1.67,1.78]],"ltp":1.72,"tv":10.64,"id":72857115}]}]}
{"op":"mcm","clk":"11895552829","pt":1724252280492,"mc":[{"id":"1.232049325","rc":[{"batb":[[0,1.47,1.76]],"ltp":2.0,"tv":49.41,"id":67083366}]}]}
{"op":"mcm","clk":"11895552943","pt":1724252281415,"mc":[{"id":"1.232049325","rc":[{"batb":[[0,1.71,1.51],[1,1.67,1.78],[2,1.04,1.53]],"ltp":1.72,"tv":10.64,"id":72857115}]}]}
{"op":"mcm","clk":"11895552998","pt":1724252281828,"mc":[{"id":"1.232049325","rc":[{"batb":[[0,1.72,4],[1,1.71,1.51],[2,1.67,1.78]],"ltp":1.72,"tv":10.64,"id":72857115}]}]}
{"op":"mcm","clk":"11895553248","pt":1724252284503,"mc":[{"id":"1.232049325","rc":[{"batb":[[0,1.71,1.51],[1,1.67,1.78],[2,1.04,1.53]],"ltp":1.72,"tv":10.64,"id":72857115}]}]}
{"op":"mcm","clk":"11895555393","pt":1724252306827,"mc":[{"id":"1.232049325","rc":[{"batb":[[0,1.72,4],[1,1.71,1.51],[2,1.67,1.78]],"ltp":1.72,"tv":10.64,"id":72857115}]}]}
{"op":"mcm","clk":"11895556030","pt":1724252311430,"mc":[{"id":"1.232049325","rc":[{"batb":[[0,1.73,10],[1,1.72,4],[2,1.71,1.51]],"ltp":1.72,"tv":10.64,"id":72857115}]}]}
{"op":"mcm","clk":"11895556207","pt":1724252313043,"mc":[{"id":"1.232049325","rc":[{"batb":[[1,1.71,1.51],[2,1.67,1.78]],"ltp":1.72,"tv":10.64,"id":72857115}]}]}
{"op":"mcm","clk":"11895556694","pt":1724252315311,"mc":[{"id":"1.232049325","rc":[{"batb":[[0,1.74,4],[1,1.73,10],[2,1.71,1.51]],"ltp":1.72,"tv":10.64,"id":72857115}]}]}
{"op":"mcm","clk":"11895557011","pt":1724252318553,"mc":[{"id":"1.232049325","rc":[{"batb":[[1,1.71,1.51],[2,1.67,1.78]],"ltp":1.72,"tv":10.64,"id":72857115}]}]}
{"op":"mcm","clk":"11895557194","pt":1724252320825,"mc":[{"id":"1.232049325","rc":[{"batb":[[0,1.71,1.51],[1,1.67,1.78],[2,1.04,1.53]],"ltp":1.72,"tv":10.64,"id":72857115}]}]}
{"op":"mcm","clk":"11895557340","pt":1724252322427,"mc":[{"id":"1.232049325","rc":[{"batb":[[0,1.75,10],[1,1.71,1.51],[2,1.67,1.78]],"ltp":1.72,"tv":10.64,"id":72857115}]}]}
{"op":"mcm","clk":"11895557489","pt":1724252324125,"mc":[{"id":"1.232049325","rc":[{"batb":[[1,1.72,4],[2,1.71,1.51]],"ltp":1.72,"tv":10.64,"id":72857115}]}]}
{"op":"mcm","clk":"11895557866","pt":1724252328652,"mc":[{"id":"1.232049325","rc":[{"batb":[[0,1.72,4],[1,1.71,1.51],[2,1.67,1.78]],"ltp":1.72,"tv":10.64,"id":72857115}]}]}
{"op":"mcm","clk":"11895557967","pt":1724252329637,"mc":[{"id":"1.232049325","rc":[{"batb":[[0,1.71,1.51],[1,1.67,1.78],[2,1.04,1.53]],"ltp":1.72,"tv":10.64,"id":72857115}]}]}
{"op":"mcm","clk":"11895558102","pt":1724252331240,"mc":[{"id":"1.232049325","rc":[{"batb":[[0,1.73,10],[1,1.71,1.51],[2,1.67,1.78]],"ltp":1.72,"tv":10.64,"id":72857115}]}]}
{"op":"mcm","clk":"11895558170","pt":1724252331961,"mc":[{"id":"1.232049325","rc":[{"batb":[[1,1.72,4],[2,1.71,1.51]],"ltp":1.72,"tv":10.64,"id":72857115}]}]}
{"op":"mcm","clk":"11895558548","pt":1724252336457,"mc":[{"id":"1.232049325","rc":[{"batb":[[0,1.71,1.51],[1,1.67,1.78],[2,1.04,1.53]],"ltp":1.72,"tv":10.64,"id":72857115}]}]}
{"op":"mcm","clk":"11895559898","pt":1724252351369,"mc":[{"id":"1.232049325","rc":[{"batb":[[0,1.72,4],[1,1.71,1.51],[2,1.67,1.78]],"ltp":1.72,"tv":10.64,"id":72857115}]}]}
{"op":"mcm","clk":"11895559945","pt":1724252351981,"mc":[{"id":"1.232049325","rc":[{"batb":[[0,1.73,10],[1,1.72,4],[2,1.71,1.51]],"ltp":1.72,"tv":10.64,"id":72857115}]}]}
{"op":"mcm","clk":"11895560098","pt":1724252353883,"mc":[{"id":"1.232049325","rc":[{"batb":[[1,1.71,1.51],[2,1.67,1.78]],"ltp":1.72,"tv":10.64,"id":72857115}]}]}
{"op":"mcm","clk":"11895560257","pt":1724252355581,"mc":[{"id":"1.232049325","rc":[{"batb":[[0,1.71,1.51],[1,1.67,1.78],[2,1.04,1.53]],"ltp":1.72,"tv":10.64,"id":72857115}]}]}
{"op":"mcm","clk":"11895569922","pt":1724252461500,"mc":[{"id":"1.232049325","rc":[{"trd":[[1.48,1.87],[1.5,2.14],[1.58,1.88],[1.63,1.71],[2,2.87],[2.1,33.59]],"batb":[[0,1.47,1.76]],"batl":[[0,2.46,6.9]],"ltp":2.0,"tv":49.38,"id":67083366},{"trd":[[1.64,3.68],[1.67,2.67],[1.72,2.14],[2.6,1.07],[3,1.07]],"batb":[[0,1.72,4],[1,1.71,1.51],[2,1.67,1.78]],"ltp":1.72,"tv":10.63,"id":72857115}],"tv":60.01}]}
{"op":"mcm","clk":"11895570050","pt":1724252462594,"mc":[{"id":"1.232049325","rc":[{"batb":[[0,1.73,10],[1,1.72,4],[2,1.71,1.51]],"ltp":1.72,"tv":10.63,"id":72857115}]}]}
{"op":"mcm","clk":"11895570222","pt":1724252464343,"mc":[{"id":"1.232049325","rc":[{"batb":[[1,1.71,1.51],[2,1.67,1.78]],"ltp":1.72,"tv":10.63,"id":72857115}]}]}
{"op":"mcm","clk":"11895570479","pt":1724252466418,"mc":[{"id":"1.232049325","rc":[{"batb":[[0,1.71,1.51],[1,1.67,1.78],[2,1.04,1.53]],"ltp":1.72,"tv":10.63,"id":72857115}]}]}
{"op":"mcm","clk":"11895570553","pt":1724252467198,"mc":[{"id":"1.232049325","rc":[{"batb":[[0,1.72,4],[1,1.71,1.51],[2,1.67,1.78]],"ltp":1.72,"tv":10.63,"id":72857115}]}]}
{"op":"mcm","clk":"11895570849","pt":1724252470103,"mc":[{"id":"1.232049325","rc":[{"batb":[[0,1.71,1.51],[1,1.67,1.78],[2,1.04,1.53]],"ltp":1.72,"tv":10.63,"id":72857115}]}]}
{"op":"mcm","clk":"11895573671","pt":1724252498425,"mc":[{"id":"1.232049325","rc":[{"batb":[[0,1.72,4],[1,1.71,1.51],[2,1.67,1.78]],"ltp":1.72,"tv":10.63,"id":72857115}]}]}
{"op":"mcm","clk":"11895573738","pt":1724252499039,"mc":[{"id":"1.232049325","rc":[{"batb":[[0,1.73,10],[1,1.72,4],[2,1.71,1.51]],"ltp":1.72,"tv":10.63,"id":72857115}]}]}
{"op":"mcm","clk":"11895573929","pt":1724252501168,"mc":[{"id":"1.232049325","rc":[{"batb":[[1,1.71,1.51],[2,1.67,1.78]],"ltp":1.72,"tv":10.63,"id":72857115}]}]}
{"op":"mcm","clk":"11895574104","pt":1724252502921,"mc":[{"id":"1.232049325","rc":[{"batb":[[0,1.71,1.51],[1,1.67,1.78],[2,1.04,1.53]],"ltp":1.72,"tv":10.63,"id":72857115}]}]}
{"op":"mcm","clk":"11895577987","pt":1724252541532,"mc":[{"id":"1.232049325","rc":[{"batb":[[0,1.72,4],[1,1.71,1.51],[2,1.67,1.78]],"ltp":1.72,"tv":10.63,"id":72857115}]}]}
{"op":"mcm","clk":"11895578043","pt":1724252542009,"mc":[{"id":"1.232049325","rc":[{"batb":[[0,1.73,10],[1,1.72,4],[2,1.71,1.51]],"ltp":1.72,"tv":10.63,"id":72857115}]}]}
{"op":"mcm","clk":"11895578264","pt":1724252544016,"mc":[{"id":"1.232049325","rc":[{"batb":[[1,1.71,1.51],[2,1.67,1.78]],"ltp":1.72,"tv":10.63,"id":72857115}]}]}
{"op":"mcm","clk":"11895578443","pt":1724252546207,"mc":[{"id":"1.232049325","rc":[{"batb":[[0,1.71,1.51],[1,1.67,1.78],[2,1.04,1.53]],"ltp":1.72,"tv":10.63,"id":72857115}]}]}
{"op":"mcm","clk":"11895578546","pt":1724252547232,"mc":[{"id":"1.232049325","rc":[{"batb":[[0,1.72,4],[1,1.71,1.51],[2,1.67,1.78]],"ltp":1.72,"tv":10.63,"id":72857115}]}]}
{"op":"mcm","clk":"11895578758","pt":1724252549231,"mc":[{"id":"1.232049325","rc":[{"batb":[[0,1.73,10],[1,1.72,4],[2,1.71,1.51]],"ltp":1.72,"tv":10.63,"id":72857115}]}]}
{"op":"mcm","clk":"11895578834","pt":1724252550209,"mc":[{"id":"1.232049325","rc":[{"batb":[[1,1.71,1.51],[2,1.67,1.78]],"ltp":1.72,"tv":10.63,"id":72857115}]}]}
{"op":"mcm","clk":"11895579086","pt":1724252553323,"mc":[{"id":"1.232049325","rc":[{"batb":[[0,1.71,1.51],[1,1.67,1.78],[2,1.04,1.53]],"ltp":1.72,"tv":10.63,"id":72857115}]}]}
{"op":"mcm","clk":"11895579163","pt":1724252554039,"mc":[{"id":"1.232049325","rc":[{"batb":[[0,1.72,4],[1,1.71,1.51],[2,1.67,1.78]],"ltp":1.72,"tv":10.63,"id":72857115}]}]}
{"op":"mcm","clk":"11895579386","pt":1724252556439,"mc":[{"id":"1.232049325","rc":[{"batb":[[0,1.71,1.51],[1,1.67,1.78],[2,1.04,1.53]],"ltp":1.72,"tv":10.63,"id":72857115}]}]}
{"op":"mcm","clk":"11895580178","pt":1724252565439,"mc":[{"id":"1.232049325","rc":[{"batb":[[0,1.72,4],[1,1.71,1.51],[2,1.67,1.78]],"ltp":1.72,"tv":10.63,"id":72857115}]}]}
{"op":"mcm","clk":"11895580266","pt":1724252566270,"mc":[{"id":"1.232049325","rc":[{"batb":[[0,1.73,10],[1,1.72,4],[2,1.71,1.51]],"ltp":1.72,"tv":10.63,"id":72857115}]}]}
{"op":"mcm","clk":"11895580479","pt":1724252568343,"mc":[{"id":"1.232049325","rc":[{"batb":[[1,1.71,1.51],[2,1.67,1.78]],"ltp":1.72,"tv":10.63,"id":72857115}]}]}
{"op":"mcm","clk":"11895580618","pt":1724252570058,"mc":[{"id":"1.232049325","rc":[{"batb":[[0,1.71,1.51],[1,1.67,1.78],[2,1.04,1.53]],"ltp":1.72,"tv":10.63,"id":72857115}]}]}
{"op":"mcm","clk":"11895582884","pt":1724252593471,"mc":[{"id":"1.232049325","rc":[{"batb":[[0,1.72,4],[1,1.71,1.51],[2,1.67,1.78]],"ltp":1.72,"tv":10.63,"id":72857115}]}]}
{"op":"mcm","clk":"11895582957","pt":1724252594094,"mc":[{"id":"1.232049325","rc":[{"batb":[[0,1.73,10],[1,1.72,4],[2,1.71,1.51]],"ltp":1.72,"tv":10.63,"id":72857115}]}]}
{"op":"mcm","clk":"11895583132","pt":1724252595791,"mc":[{"id":"1.232049325","rc":[{"batb":[[1,1.71,1.51],[2,1.67,1.78]],"ltp":1.72,"tv":10.63,"id":72857115}]}]}
{"op":"mcm","clk":"11895583397","pt":1724252598119,"mc":[{"id":"1.232049325","rc":[{"batb":[[0,1.72,4]],"ltp":1.72,"tv":10.63,"id":72857115}]}]}
{"op":"mcm","clk":"11895583606","pt":1724252600291,"mc":[{"id":"1.232049325","rc":[{"batb":[[0,1.71,1.51],[1,1.67,1.78],[2,1.04,1.53]],"ltp":1.72,"tv":10.63,"id":72857115}]}]}
{"op":"mcm","clk":"11895584003","pt":1724252604111,"mc":[{"id":"1.232049325","rc":[{"batb":[[0,1.73,10],[1,1.72,4],[2,1.71,1.51]],"ltp":1.72,"tv":10.63,"id":72857115}]}]}
{"op":"mcm","clk":"11895584238","pt":1724252606328,"mc":[{"id":"1.232049325","rc":[{"batb":[[1,1.71,1.51],[2,1.67,1.78]],"ltp":1.72,"tv":10.63,"id":72857115}]}]}
{"op":"mcm","clk":"11895584360","pt":1724252607415,"mc":[{"id":"1.232049325","rc":[{"batb":[[0,1.71,1.51],[1,1.67,1.78],[2,1.04,1.53]],"ltp":1.72,"tv":10.63,"id":72857115}]}]}
{"op":"mcm","clk":"11895584538","pt":1724252609005,"mc":[{"id":"1.232049325","rc":[{"batb":[[0,1.72,4],[1,1.71,1.51],[2,1.67,1.78]],"ltp":1.72,"tv":10.63,"id":72857115}]}]}
{"op":"mcm","clk":"11895584940","pt":1724252611713,"mc":[{"id":"1.232049325","rc":[{"batb":[[0,1.71,1.51],[1,1.67,1.78],[2,1.04,1.53]],"ltp":1.72,"tv":10.63,"id":72857115}]}]}
{"op":"mcm","clk":"11895586386","pt":1724252626224,"mc":[{"id":"1.232049325","rc":[{"batb":[[0,1.72,4],[1,1.71,1.51],[2,1.67,1.78]],"ltp":1.72,"tv":10.63,"id":72857115}]}]}
{"op":"mcm","clk":"11895586451","pt":1724252626940,"mc":[{"id":"1.232049325","rc":[{"batb":[[0,1.73,10],[1,1.72,4],[2,1.71,1.51]],"ltp":1.72,"tv":10.63,"id":72857115}]}]}
{"op":"mcm","clk":"11895586674","pt":1724252629135,"mc":[{"id":"1.232049325","rc":[{"batb":[[1,1.71,1.51],[2,1.67,1.78]],"ltp":1.72,"tv":10.63,"id":72857115}]}]}
{"op":"mcm","clk":"11895586852","pt":1724252630739,"mc":[{"id":"1.232049325","rc":[{"batb":[[0,1.71,1.51],[1,1.67,1.78],[2,1.04,1.53]],"ltp":1.72,"tv":10.63,"id":72857115}]}]}
{"op":"mcm","clk":"11895587423","pt":1724252636053,"mc":[{"id":"1.232049325","rc":[{"batb":[[0,1.72,4],[1,1.71,1.51],[2,1.67,1.78]],"ltp":1.72,"tv":10.63,"id":72857115}]}]}
{"op":"mcm","clk":"11895588012","pt":1724252641273,"mc":[{"id":"1.232049325","rc":[{"batb":[[0,1.73,10],[1,1.72,4],[2,1.71,1.51]],"ltp":1.72,"tv":10.63,"id":72857115}]}]}
{"op":"mcm","clk":"11895588229","pt":1724252643353,"mc":[{"id":"1.232049325","rc":[{"batb":[[1,1.71,1.51],[2,1.67,1.78]],"ltp":1.72,"tv":10.63,"id":72857115}]}]}
{"op":"mcm","clk":"11895588542","pt":1724252645965,"mc":[{"id":"1.232049325","rc":[{"batb":[[0,1.74,4],[1,1.73,10],[2,1.71,1.51]],"ltp":1.72,"tv":10.63,"id":72857115}]}]}
{"op":"mcm","clk":"11895588846","pt":1724252648969,"mc":[{"id":"1.232049325","rc":[{"batb":[[1,1.71,1.51],[2,1.67,1.78]],"ltp":1.72,"tv":10.63,"id":72857115}]}]}
{"op":"mcm","clk":"11895589109","pt":1724252651458,"mc":[{"id":"1.232049325","rc":[{"batb":[[0,1.75,10]],"ltp":1.72,"tv":10.63,"id":72857115}]}]}
{"op":"mcm","clk":"11895589652","pt":1724252656276,"mc":[{"id":"1.232049325","rc":[{"batb":[[0,1.71,1.51],[1,1.67,1.78],[2,1.04,1.53]],"ltp":1.72,"tv":10.63,"id":72857115}]}]}
{"op":"mcm","clk":"11895589803","pt":1724252657473,"mc":[{"id":"1.232049325","rc":[{"batb":[[0,1.72,4],[1,1.71,1.51],[2,1.67,1.78]],"ltp":1.72,"tv":10.63,"id":72857115}]}]}
{"op":"mcm","clk":"11895589916","pt":1724252658564,"mc":[{"id":"1.232049325","rc":[{"batb":[[0,1.73,10],[1,1.72,4],[2,1.71,1.51]],"ltp":1.72,"tv":10.63,"id":72857115}]}]}
{"op":"mcm","clk":"11895590120","pt":1724252660579,"mc":[{"id":"1.232049325","rc":[{"batb":[[1,1.71,1.51],[2,1.67,1.78]],"ltp":1.72,"tv":10.63,"id":72857115}]}]}
{"op":"mcm","clk":"11895590316","pt":1724252662389,"mc":[{"id":"1.232049325","rc":[{"batb":[[0,1.71,1.51],[1,1.67,1.78],[2,1.04,1.53]],"ltp":1.72,"tv":10.63,"id":72857115}]}]}
{"op":"mcm","clk":"11895591370","pt":1724252672127,"mc":[{"id":"1.232049325","rc":[{"batb":[[0,1.72,4],[1,1.71,1.51],[2,1.67,1.78]],"ltp":1.72,"tv":10.63,"id":72857115}]}]}
{"op":"mcm","clk":"11895591437","pt":1724252672796,"mc":[{"id":"1.232049325","rc":[{"batb":[[0,1.73,10],[1,1.72,4],[2,1.71,1.51]],"ltp":1.72,"tv":10.63,"id":72857115}]}]}
{"op":"mcm","clk":"11895591651","pt":1724252674781,"mc":[{"id":"1.232049325","rc":[{"batb":[[1,1.71,1.51],[2,1.67,1.78]],"ltp":1.72,"tv":10.63,"id":72857115}]}]}
{"op":"mcm","clk":"11895591813","pt":1724252676477,"mc":[{"id":"1.232049325","rc":[{"batb":[[0,1.71,1.51],[1,1.67,1.78],[2,1.04,1.53]],"ltp":1.72,"tv":10.63,"id":72857115}]}]}
{"op":"mcm","clk":"11895595030","pt":1724252706111,"mc":[{"id":"1.232049325","rc":[{"batb":[[0,1.73,10],[1,1.72,4],[2,1.71,1.51]],"ltp":1.72,"tv":10.63,"id":72857115}]}]}
{"op":"mcm","clk":"11895595263","pt":1724252708234,"mc":[{"id":"1.232049325","rc":[{"batb":[[1,1.71,1.51],[2,1.67,1.78]],"ltp":1.72,"tv":10.63,"id":72857115}]}]}
{"op":"mcm","clk":"11895595442","pt":1724252709941,"mc":[{"id":"1.232049325","rc":[{"batb":[[0,1.71,1.51],[1,1.67,1.78],[2,1.04,1.53]],"ltp":1.72,"tv":10.63,"id":72857115}]}]}
{"op":"mcm","clk":"11895595965","pt":1724252714143,"mc":[{"id":"1.232049325","rc":[{"batb":[[0,1.73,10],[1,1.72,4],[2,1.71,1.51]],"ltp":1.72,"tv":10.63,"id":72857115}]}]}
{"op":"mcm","clk":"11895596186","pt":1724252716021,"mc":[{"id":"1.232049325","rc":[{"batb":[[1,1.71,1.51],[2,1.67,1.78]],"ltp":1.72,"tv":10.63,"id":72857115}]}]}
{"op":"mcm","clk":"11895596377","pt":1724252717737,"mc":[{"id":"1.232049325","rc":[{"batb":[[0,1.71,1.51],[1,1.67,1.78],[2,1.04,1.53]],"ltp":1.72,"tv":10.63,"id":72857115}]}]}
{"op":"mcm","clk":"11895597751","pt":1724252729171,"mc":[{"id":"1.232049325","rc":[{"batb":[[0,1.73,10],[1,1.72,4],[2,1.71,1.51]],"ltp":1.72,"tv":10.63,"id":72857115}]}]}
{"op":"mcm","clk":"11895598000","pt":1724252731470,"mc":[{"id":"1.232049325","rc":[{"batb":[[1,1.71,1.51],[2,1.67,1.78]],"ltp":1.72,"tv":10.63,"id":72857115}]}]}
{"op":"mcm","clk":"11895598177","pt":1724252732842,"mc":[{"id":"1.232049325","rc":[{"batb":[[0,1.71,1.51],[1,1.67,1.78],[2,1.04,1.53]],"ltp":1.72,"tv":10.63,"id":72857115}]}]}
{"op":"mcm","clk":"11895598523","pt":1724252736165,"mc":[{"id":"1.232049325","rc":[{"batb":[[0,1.72,4],[1,1.71,1.51],[2,1.67,1.78]],"ltp":1.72,"tv":10.63,"id":72857115}]}]}
{"op":"mcm","clk":"11895598575","pt":1724252736638,"mc":[{"id":"1.232049325","rc":[{"batb":[[0,1.73,10],[1,1.72,4],[2,1.71,1.51]],"ltp":1.72,"tv":10.63,"id":72857115}]}]}
{"op":"mcm","clk":"11895598776","pt":1724252738550,"mc":[{"id":"1.232049325","rc":[{"batb":[[1,1.71,1.51],[2,1.67,1.78]],"ltp":1.72,"tv":10.63,"id":72857115}]}]}
{"op":"mcm","clk":"11895598959","pt":1724252740273,"mc":[{"id":"1.232049325","rc":[{"batb":[[0,1.71,1.51],[1,1.67,1.78],[2,1.04,1.53]],"ltp":1.72,"tv":10.63,"id":72857115}]}]}
{"op":"mcm","clk":"11895599047","pt":1724252740961,"mc":[{"id":"1.232049325","rc":[{"batb":[[0,1.72,4],[1,1.71,1.51],[2,1.67,1.78]],"ltp":1.72,"tv":10.63,"id":72857115}]}]}
{"op":"mcm","clk":"11895599284","pt":1724252743246,"mc":[{"id":"1.232049325","rc":[{"batb":[[0,1.71,1.51],[1,1.67,1.78],[2,1.04,1.53]],"ltp":1.72,"tv":10.63,"id":72857115}]}]}
{"op":"mcm","clk":"11895600132","pt":1724252750462,"mc":[{"id":"1.232049325","rc":[{"batb":[[0,1.72,4],[1,1.71,1.51],[2,1.67,1.78]],"ltp":1.72,"tv":10.63,"id":72857115}]}]}
{"op":"mcm","clk":"11895600191","pt":1724252750875,"mc":[{"id":"1.232049325","rc":[{"batb":[[0,1.73,10],[1,1.72,4],[2,1.71,1.51]],"ltp":1.72,"tv":10.63,"id":72857115}]}]}
{"op":"mcm","clk":"11895600468","pt":1724252753163,"mc":[{"id":"1.232049325","rc":[{"batb":[[1,1.71,1.51],[2,1.67,1.78]],"ltp":1.72,"tv":10.63,"id":72857115}]}]}
{"op":"mcm","clk":"11895600627","pt":1724252754568,"mc":[{"id":"1.232049325","rc":[{"batb":[[0,1.71,1.51],[1,1.67,1.78],[2,1.04,1.53]],"ltp":1.72,"tv":10.63,"id":72857115}]}]}
{"op":"mcm","clk":"11895600739","pt":1724252755496,"mc":[{"id":"1.232049325","rc":[{"batb":[[0,1.72,4],[1,1.71,1.51],[2,1.67,1.78]],"ltp":1.72,"tv":10.63,"id":72857115}]}]}
{"op":"mcm","clk":"11895601040","pt":1724252758089,"mc":[{"id":"1.232049325","rc":[{"batb":[[0,1.71,1.51],[1,1.67,1.78],[2,1.04,1.53]],"ltp":1.72,"tv":10.63,"id":72857115}]}]}
{"op":"mcm","clk":"11895602636","pt":1724252772379,"mc":[{"id":"1.232049325","rc":[{"batb":[[0,1.73,10],[1,1.72,4],[2,1.71,1.51]],"ltp":1.72,"tv":10.63,"id":72857115}]}]}
{"op":"mcm","clk":"11895602812","pt":1724252773974,"mc":[{"id":"1.232049325","rc":[{"batb":[[1,1.71,1.51],[2,1.67,1.78]],"ltp":1.72,"tv":10.63,"id":72857115}]}]}
{"op":"mcm","clk":"11895603086","pt":1724252776297,"mc":[{"id":"1.232049325","rc":[{"batb":[[0,1.71,1.51],[1,1.67,1.78],[2,1.04,1.53]],"ltp":1.72,"tv":10.63,"id":72857115}]}]}
{"op":"mcm","clk":"11895603120","pt":1724252776604,"mc":[{"id":"1.232049325","rc":[{"batb":[[0,1.72,4],[1,1.71,1.51],[2,1.67,1.78]],"ltp":1.72,"tv":10.63,"id":72857115}]}]}
{"op":"mcm","clk":"11895603431","pt":1724252779000,"mc":[{"id":"1.232049325","rc":[{"batb":[[0,1.71,1.51],[1,1.67,1.78],[2,1.04,1.53]],"ltp":1.72,"tv":10.63,"id":72857115}]}]}
{"op":"mcm","clk":"11895609122","pt":1724252828496,"mc":[{"id":"1.232049325","rc":[{"batb":[[0,1.73,10],[1,1.72,4],[2,1.71,1.51]],"ltp":1.72,"tv":10.63,"id":72857115}]}]}
{"op":"mcm","clk":"11895609332","pt":1724252830307,"mc":[{"id":"1.232049325","rc":[{"batb":[[1,1.71,1.51],[2,1.67,1.78]],"ltp":1.72,"tv":10.63,"id":72857115}]}]}
{"op":"mcm","clk":"11895609593","pt":1724252832279,"mc":[{"id":"1.232049325","rc":[{"batb":[[0,1.71,1.51],[1,1.67,1.78],[2,1.04,1.53]],"ltp":1.72,"tv":10.63,"id":72857115}]}]}
{"op":"mcm","clk":"11895609625","pt":1724252832589,"mc":[{"id":"1.232049325","rc":[{"batb":[[0,1.72,4],[1,1.71,1.51],[2,1.67,1.78]],"ltp":1.72,"tv":10.63,"id":72857115}]}]}
{"op":"mcm","clk":"11895609909","pt":1724252835488,"mc":[{"id":"1.232049325","rc":[{"batb":[[0,1.71,1.51],[1,1.67,1.78],[2,1.04,1.53]],"ltp":1.72,"tv":10.63,"id":72857115}]}]}
{"op":"mcm","clk":"11895611051","pt":1724252845414,"mc":[{"id":"1.232049325","rc":[{"batb":[[0,1.73,10],[1,1.72,4],[2,1.71,1.51]],"ltp":1.72,"tv":10.63,"id":72857115}]}]}
{"op":"mcm","clk":"11895611264","pt":1724252847386,"mc":[{"id":"1.232049325","rc":[{"batb":[[1,1.71,1.51],[2,1.67,1.78]],"ltp":1.72,"tv":10.63,"id":72857115}]}]}
{"op":"mcm","clk":"11895611485","pt":1724252849197,"mc":[{"id":"1.232049325","rc":[{"batb":[[0,1.71,1.51],[1,1.67,1.78],[2,1.04,1.53]],"ltp":1.72,"tv":10.63,"id":72857115}]}]}
{"op":"mcm","clk":"11895612090","pt":1724252855324,"mc":[{"id":"1.232049325","rc":[{"batb":[[0,1.72,4],[1,1.71,1.51],[2,1.67,1.78]],"ltp":1.72,"tv":10.63,"id":72857115}]}]}
{"op":"mcm","clk":"11895612151","pt":1724252855803,"mc":[{"id":"1.232049325","rc":[{"batb":[[0,1.73,10],[1,1.72,4],[2,1.71,1.51]],"ltp":1.72,"tv":10.63,"id":72857115}]}]}
{"op":"mcm","clk":"11895612367","pt":1724252858001,"mc":[{"id":"1.232049325","rc":[{"batb":[[1,1.71,1.51],[2,1.67,1.78]],"ltp":1.72,"tv":10.63,"id":72857115}]}]}
{"op":"mcm","clk":"11895612568","pt":1724252859812,"mc":[{"id":"1.232049325","rc":[{"batb":[[0,1.71,1.51],[1,1.67,1.78],[2,1.04,1.53]],"ltp":1.72,"tv":10.63,"id":72857115}]}]}
{"op":"mcm","clk":"11895613499","pt":1724252867984,"mc":[{"id":"1.232049325","rc":[{"batb":[[0,1.73,10],[1,1.72,4],[2,1.71,1.51]],"ltp":1.72,"tv":10.63,"id":72857115}]}]}
{"op":"mcm","clk":"11895613872","pt":1724252870328,"mc":[{"id":"1.232049325","rc":[{"batb":[[1,1.71,1.51],[2,1.67,1.78]],"ltp":1.72,"tv":10.63,"id":72857115}]}]}
{"op":"mcm","clk":"11895614070","pt":1724252871735,"mc":[{"id":"1.232049325","rc":[{"batb":[[0,1.71,1.51],[1,1.67,1.78],[2,1.04,1.53]],"ltp":1.72,"tv":10.63,"id":72857115}]}]}
{"op":"mcm","clk":"11895614931","pt":1724252878029,"mc":[{"id":"1.232049325","rc":[{"batb":[[0,1.73,10],[1,1.72,4],[2,1.71,1.51]],"ltp":1.72,"tv":10.63,"id":72857115}]}]}
{"op":"mcm","clk":"11895615259","pt":1724252880031,"mc":[{"id":"1.232049325","rc":[{"batb":[[1,1.71,1.51],[2,1.67,1.78]],"ltp":1.72,"tv":10.63,"id":72857115}]}]}
{"op":"mcm","clk":"11895615519","pt":1724252881734,"mc":[{"id":"1.232049325","rc":[{"batb":[[0,1.71,1.51],[1,1.67,1.78],[2,1.04,1.53]],"ltp":1.72,"tv":10.63,"id":72857115}]}]}
{"op":"mcm","clk":"11895618040","pt":1724252900284,"mc":[{"id":"1.232049325","rc":[{"batb":[[0,1.72,4],[1,1.71,1.51],[2,1.67,1.78]],"ltp":1.72,"tv":10.63,"id":72857115}]}]}
{"op":"mcm","clk":"11895618099","pt":1724252900792,"mc":[{"id":"1.232049325","rc":[{"batb":[[0,1.73,10],[1,1.72,4],[2,1.71,1.51]],"ltp":1.72,"tv":10.63,"id":72857115}]}]}
{"op":"mcm","clk":"11895618366","pt":1724252902767,"mc":[{"id":"1.232049325","rc":[{"batb":[[1,1.71,1.51],[2,1.67,1.78]],"ltp":1.72,"tv":10.63,"id":72857115}]}]}
{"op":"mcm","clk":"11895618579","pt":1724252904603,"mc":[{"id":"1.232049325","rc":[{"batb":[[0,1.71,1.51],[1,1.67,1.78],[2,1.04,1.53]],"ltp":1.72,"tv":10.63,"id":72857115}]}]}
{"op":"mcm","clk":"11895619586","pt":1724252912003,"mc":[{"id":"1.232049325","rc":[{"batb":[[0,1.72,4],[1,1.71,1.51],[2,1.67,1.78]],"ltp":1.72,"tv":10.63,"id":72857115}]}]}
{"op":"mcm","clk":"11895619704","pt":1724252912892,"mc":[{"id":"1.232049325","rc":[{"batb":[[0,1.73,10],[1,1.72,4],[2,1.71,1.51]],"ltp":1.72,"tv":10.63,"id":72857115}]}]}
{"op":"mcm","clk":"11895619922","pt":1724252914818,"mc":[{"id":"1.232049325","rc":[{"batb":[[1,1.71,1.51],[2,1.67,1.78]],"ltp":1.72,"tv":10.63,"id":72857115}]}]}
{"op":"mcm","clk":"11895620245","pt":1724252917503,"mc":[{"id":"1.232049325","rc":[{"batb":[[0,1.72,4]],"ltp":1.72,"tv":10.63,"id":72857115}]}]}
{"op":"mcm","clk":"11895620553","pt":1724252919895,"mc":[{"id":"1.232049325","rc":[{"batb":[[0,1.71,1.51],[1,1.67,1.78],[2,1.04,1.53]],"ltp":1.72,"tv":10.63,"id":72857115}]}]}
{"op":"mcm","clk":"11895621278","pt":1724252925128,"mc":[{"id":"1.232049325","rc":[{"batb":[[0,1.73,10],[1,1.72,4],[2,1.71,1.51]],"ltp":1.72,"tv":10.63,"id":72857115}]}]}
{"op":"mcm","clk":"11895621531","pt":1724252926910,"mc":[{"id":"1.232049325","rc":[{"batb":[[1,1.71,1.51],[2,1.67,1.78]],"ltp":1.72,"tv":10.63,"id":72857115}]}]}
{"op":"mcm","clk":"11895621816","pt":1724252929213,"mc":[{"id":"1.232049325","rc":[{"batb":[[0,1.72,4]],"ltp":1.72,"tv":10.63,"id":72857115}]}]}
{"op":"mcm","clk":"11895622139","pt":1724252931708,"mc":[{"id":"1.232049325","rc":[{"batb":[[0,1.71,1.51],[1,1.67,1.78],[2,1.04,1.53]],"ltp":1.72,"tv":10.63,"id":72857115}]}]}
{"op":"mcm","clk":"11895625504","pt":1724252957355,"mc":[{"id":"1.232049325","rc":[{"batb":[[0,1.73,10],[1,1.72,4],[2,1.71,1.51]],"ltp":1.72,"tv":10.63,"id":72857115}]}]}
{"op":"mcm","clk":"11895625774","pt":1724252959569,"mc":[{"id":"1.232049325","rc":[{"batb":[[1,1.71,1.51],[2,1.67,1.78]],"ltp":1.72,"tv":10.63,"id":72857115}]}]}
{"op":"mcm","clk":"11895625973","pt":1724252961283,"mc":[{"id":"1.232049325","rc":[{"batb":[[0,1.71,1.51],[1,1.67,1.78],[2,1.04,1.53]],"ltp":1.72,"tv":10.63,"id":72857115}]}]}
{"op":"mcm","clk":"11895627680","pt":1724252975461,"mc":[{"id":"1.232049325","rc":[{"batb":[[0,1.73,10],[1,1.72,4],[2,1.71,1.51]],"ltp":1.72,"tv":10.63,"id":72857115}]}]}
{"op":"mcm","clk":"11895627915","pt":1724252977693,"mc":[{"id":"1.232049325","rc":[{"batb":[[1,1.71,1.51],[2,1.67,1.78]],"ltp":1.72,"tv":10.63,"id":72857115}]}]}
{"op":"mcm","clk":"11895628107","pt":1724252979352,"mc":[{"id":"1.232049325","rc":[{"batb":[[0,1.71,1.51],[1,1.67,1.78],[2,1.04,1.53]],"ltp":1.72,"tv":10.63,"id":72857115}]}]}
{"op":"mcm","clk":"11895628167","pt":1724252979876,"mc":[{"id":"1.232049325","rc":[{"batb":[[0,1.72,4],[1,1.71,1.51],[2,1.67,1.78]],"ltp":1.72,"tv":10.63,"id":72857115}]}]}
{"op":"mcm","clk":"11895628446","pt":1724252982290,"mc":[{"id":"1.232049325","rc":[{"batb":[[0,1.71,1.51],[1,1.67,1.78],[2,1.04,1.53]],"ltp":1.72,"tv":10.63,"id":72857115}]}]}
{"op":"mcm","clk":"11895628896","pt":1724252986475,"mc":[{"id":"1.232049325","rc":[{"batb":[[0,1.73,10],[1,1.72,4],[2,1.71,1.51]],"ltp":1.72,"tv":10.63,"id":72857115}]}]}
{"op":"mcm","clk":"11895629128","pt":1724252988494,"mc":[{"id":"1.232049325","rc":[{"batb":[[1,1.71,1.51],[2,1.67,1.78]],"ltp":1.72,"tv":10.63,"id":72857115}]}]}
{"op":"mcm","clk":"11895629353","pt":1724252990490,"mc":[{"id":"1.232049325","rc":[{"batb":[[0,1.71,1.51],[1,1.67,1.78],[2,1.04,1.53]],"ltp":1.72,"tv":10.63,"id":72857115}]}]}
{"op":"mcm","clk":"11895629382","pt":1724252990791,"mc":[{"id":"1.232049325","rc":[{"batb":[[0,1.72,4],[1,1.71,1.51],[2,1.67,1.78]],"ltp":1.72,"tv":10.63,"id":72857115}]}]}
{"op":"mcm","clk":"11895629653","pt":1724252993310,"mc":[{"id":"1.232049325","rc":[{"batb":[[0,1.71,1.51],[1,1.67,1.78],[2,1.04,1.53]],"ltp":1.72,"tv":10.63,"id":72857115}]}]}
{"op":"mcm","clk":"11895630116","pt":1724252997217,"mc":[{"id":"1.232049325","rc":[{"batb":[[0,1.72,4],[1,1.71,1.51],[2,1.67,1.78]],"ltp":1.72,"tv":10.63,"id":72857115}]}]}
{"op":"mcm","clk":"11895630257","pt":1724252998104,"mc":[{"id":"1.232049325","rc":[{"batb":[[0,1.73,10],[1,1.72,4],[2,1.71,1.51]],"ltp":1.72,"tv":10.63,"id":72857115}]}]}
{"op":"mcm","clk":"11895630511","pt":1724253000092,"mc":[{"id":"1.232049325","rc":[{"batb":[[1,1.71,1.51],[2,1.67,1.78]],"ltp":1.72,"tv":10.63,"id":72857115}]}]}
{"op":"mcm","clk":"11895630808","pt":1724253002423,"mc":[{"id":"1.232049325","rc":[{"batb":[[0,1.71,1.51],[1,1.67,1.78],[2,1.04,1.53]],"ltp":1.72,"tv":10.63,"id":72857115}]}]}
{"op":"mcm","clk":"11895630870","pt":1724253002817,"mc":[{"id":"1.232049325","rc":[{"batb":[[0,1.72,4],[1,1.71,1.51],[2,1.67,1.78]],"ltp":1.72,"tv":10.63,"id":72857115}]}]}
{"op":"mcm","clk":"11895631176","pt":1724253005433,"mc":[{"id":"1.232049325","rc":[{"batb":[[0,1.71,1.51],[1,1.67,1.78],[2,1.04,1.53]],"ltp":1.72,"tv":10.63,"id":72857115}]}]}
{"op":"mcm","clk":"11895632711","pt":1724253018111,"mc":[{"id":"1.232049325","rc":[{"batb":[[0,1.72,4],[1,1.71,1.51],[2,1.67,1.78]],"ltp":1.72,"tv":10.63,"id":72857115}]}]}
{"op":"mcm","clk":"11895632825","pt":1724253019114,"mc":[{"id":"1.232049325","rc":[{"batb":[[0,1.73,10],[1,1.72,4],[2,1.71,1.51]],"ltp":1.72,"tv":10.63,"id":72857115}]}]}
{"op":"mcm","clk":"11895633010","pt":1724253020814,"mc":[{"id":"1.232049325","rc":[{"batb":[[1,1.71,1.51],[2,1.67,1.78]],"ltp":1.72,"tv":10.63,"id":72857115}]}]}
{"op":"mcm","clk":"11895633295","pt":1724253023216,"mc":[{"id":"1.232049325","rc":[{"batb":[[0,1.72,4]],"ltp":1.72,"tv":10.63,"id":72857115}]}]}
{"op":"mcm","clk":"11895633625","pt":1724253025837,"mc":[{"id":"1.232049325","rc":[{"batb":[[0,1.71,1.51],[1,1.67,1.78],[2,1.04,1.53]],"ltp":1.72,"tv":10.63,"id":72857115}]}]}
{"op":"mcm","clk":"11895637460","pt":1724253057984,"mc":[{"id":"1.232049325","rc":[{"batb":[[0,1.72,4],[1,1.71,1.51],[2,1.67,1.78]],"ltp":1.72,"tv":10.63,"id":72857115}]}]}
{"op":"mcm","clk":"11895638783","pt":1724253067901,"mc":[{"id":"1.232049325","rc":[{"batb":[[0,1.73,10],[1,1.72,4],[2,1.71,1.51]],"ltp":1.72,"tv":10.63,"id":72857115}]}]}
{"op":"mcm","clk":"11895639023","pt":1724253069995,"mc":[{"id":"1.232049325","rc":[{"batb":[[1,1.71,1.51],[2,1.67,1.78]],"ltp":1.72,"tv":10.63,"id":72857115}]}]}
{"op":"mcm","clk":"11895639649","pt":1724253075084,"mc":[{"id":"1.232049325","rc":[{"batb":[[0,1.71,1.51],[1,1.67,1.78],[2,1.04,1.53]],"ltp":1.72,"tv":10.63,"id":72857115}]}]}
{"op":"mcm","clk":"11895639799","pt":1724253076382,"mc":[{"id":"1.232049325","rc":[{"batb":[[0,1.74,4],[1,1.71,1.51],[2,1.67,1.78]],"ltp":1.72,"tv":10.63,"id":72857115}]}]}
{"op":"mcm","clk":"11895640118","pt":1724253078681,"mc":[{"id":"1.232049325","rc":[{"batb":[[0,1.74,14]],"ltp":1.72,"tv":10.63,"id":72857115}]}]}
{"op":"mcm","clk":"11895640877","pt":1724253084915,"mc":[{"id":"1.232049325","rc":[{"batb":[[0,1.74,10]],"ltp":1.72,"tv":10.63,"id":72857115}]}]}
{"op":"mcm","clk":"11895641282","pt":1724253088197,"mc":[{"id":"1.232049325","rc":[{"batb":[[0,1.75,4]],"ltp":1.72,"tv":10.63,"id":72857115}]}]}
{"op":"mcm","clk":"11895641637","pt":1724253091312,"mc":[{"id":"1.232049325","rc":[{"batb":[[0,1.76,10],[1,1.75,4],[2,1.71,1.51]],"ltp":1.72,"tv":10.63,"id":72857115}]}]}
{"op":"mcm","clk":"11895641913","pt":1724253093642,"mc":[{"id":"1.232049325","rc":[{"batb":[[1,1.71,1.51],[2,1.67,1.78]],"ltp":1.72,"tv":10.63,"id":72857115}]}]}
{"op":"mcm","clk":"11895642171","pt":1724253095930,"mc":[{"id":"1.232049325","rc":[{"batb":[[0,1.77,4],[1,1.76,10],[2,1.71,1.51]],"ltp":1.72,"tv":10.63,"id":72857115}]}]}
{"op":"mcm","clk":"11895642437","pt":1724253098129,"mc":[{"id":"1.232049325","rc":[{"batb":[[1,1.71,1.51],[2,1.67,1.78]],"ltp":1.72,"tv":10.63,"id":72857115}]}]}
{"op":"mcm","clk":"11895642748","pt":1724253101037,"mc":[{"id":"1.232049325","rc":[{"batb":[[0,1.78,10],[1,1.77,4],[2,1.71,1.51]],"ltp":1.72,"tv":10.63,"id":72857115}]}]}
{"op":"mcm","clk":"11895642824","pt":1724253101624,"mc":[{"id":"1.232049325","rc":[{"batb":[[1,1.71,1.51],[2,1.67,1.78]],"ltp":1.72,"tv":10.63,"id":72857115}]}]}
{"op":"mcm","clk":"11895643159","pt":1724253104261,"mc":[{"id":"1.232049325","rc":[{"batb":[[0,1.79,4],[1,1.78,10],[2,1.71,1.51]],"ltp":1.72,"tv":10.63,"id":72857115}]}]}
{"op":"mcm","clk":"11895643394","pt":1724253106248,"mc":[{"id":"1.232049325","rc":[{"batb":[[1,1.71,1.51],[2,1.67,1.78]],"ltp":1.72,"tv":10.63,"id":72857115}]}]}
{"op":"mcm","clk":"11895643549","pt":1724253107551,"mc":[{"id":"1.232049325","rc":[{"batb":[[0,1.71,1.51],[1,1.67,1.78],[2,1.04,1.53]],"ltp":1.72,"tv":10.63,"id":72857115}]}]}
{"op":"mcm","clk":"11895645645","pt":1724253124069,"mc":[{"id":"1.232049325","rc":[{"batb":[[0,1.73,10],[1,1.72,4],[2,1.71,1.51]],"ltp":1.72,"tv":10.63,"id":72857115}]}]}
{"op":"mcm","clk":"11895645946","pt":1724253126563,"mc":[{"id":"1.232049325","rc":[{"batb":[[1,1.71,1.51],[2,1.67,1.78]],"ltp":1.72,"tv":10.63,"id":72857115}]}]}
{"op":"mcm","clk":"11895646128","pt":1724253128075,"mc":[{"id":"1.232049325","rc":[{"batb":[[0,1.71,1.51],[1,1.67,1.78],[2,1.04,1.53]],"ltp":1.72,"tv":10.63,"id":72857115}]}]}
{"op":"mcm","clk":"11895646528","pt":1724253131396,"mc":[{"id":"1.232049325","rc":[{"batb":[[0,1.72,4],[1,1.71,1.51],[2,1.67,1.78]],"ltp":1.72,"tv":10.63,"id":72857115}]}]}
{"op":"mcm","clk":"11895646571","pt":1724253131687,"mc":[{"id":"1.232049325","rc":[{"batb":[[0,1.73,10],[1,1.72,4],[2,1.71,1.51]],"ltp":1.72,"tv":10.63,"id":72857115}]}]}
{"op":"mcm","clk":"11895646802","pt":1724253133669,"mc":[{"id":"1.232049325","rc":[{"batb":[[1,1.71,1.51],[2,1.67,1.78]],"ltp":1.72,"tv":10.63,"id":72857115}]}]}
{"op":"mcm","clk":"11895647033","pt":1724253135492,"mc":[{"id":"1.232049325","rc":[{"batb":[[0,1.71,1.51],[1,1.67,1.78],[2,1.04,1.53]],"ltp":1.72,"tv":10.63,"id":72857115}]}]}
{"op":"mcm","clk":"11895648547","pt":1724253147310,"mc":[{"id":"1.232049325","rc":[{"batb":[[0,1.72,4],[1,1.71,1.51],[2,1.67,1.78]],"ltp":1.72,"tv":10.63,"id":72857115}]}]}
{"op":"mcm","clk":"11895648630","pt":1724253147995,"mc":[{"id":"1.232049325","rc":[{"batb":[[0,1.73,10],[1,1.72,4],[2,1.71,1.51]],"ltp":1.72,"tv":10.63,"id":72857115}]}]}
{"op":"mcm","clk":"11895648853","pt":1724253149908,"mc":[{"id":"1.232049325","rc":[{"batb":[[1,1.71,1.51],[2,1.67,1.78]],"ltp":1.72,"tv":10.63,"id":72857115}]}]}
{"op":"mcm","clk":"11895649023","pt":1724253151305,"mc":[{"id":"1.232049325","rc":[{"batb":[[0,1.71,1.51],[1,1.67,1.78],[2,1.04,1.53]],"ltp":1.72,"tv":10.63,"id":72857115}]}]}
{"op":"mcm","clk":"11895649748","pt":1724253157285,"mc":[{"id":"1.232049325","rc":[{"batb":[[0,1.72,4],[1,1.71,1.51],[2,1.67,1.78]],"ltp":1.72,"tv":10.63,"id":72857115}]}]}
{"op":"mcm","clk":"11895649794","pt":1724253157698,"mc":[{"id":"1.232049325","rc":[{"batb":[[0,1.73,10],[1,1.72,4],[2,1.71,1.51]],"ltp":1.72,"tv":10.63,"id":72857115}]}]}
{"op":"mcm","clk":"11895650063","pt":1724253160031,"mc":[{"id":"1.232049325","rc":[{"batb":[[1,1.71,1.51],[2,1.67,1.78]],"ltp":1.72,"tv":10.63,"id":72857115}]}]}
{"op":"mcm","clk":"11895650226","pt":1724253161506,"mc":[{"id":"1.232049325","rc":[{"batb":[[0,1.71,1.51],[1,1.67,1.78],[2,1.04,1.53]],"ltp":1.72,"tv":10.63,"id":72857115}]}]}
{"op":"mcm","clk":"11895650622","pt":1724253164609,"mc":[{"id":"1.232049325","rc":[{"batb":[[0,1.72,4],[1,1.71,1.51],[2,1.67,1.78]],"ltp":1.72,"tv":10.63,"id":72857115}]}]}
{"op":"mcm","clk":"11895650773","pt":1724253165835,"mc":[{"id":"1.232049325","rc":[{"batb":[[0,1.73,10],[1,1.72,4],[2,1.71,1.51]],"ltp":1.72,"tv":10.63,"id":72857115}]}]}
{"op":"mcm","clk":"11895650925","pt":1724253167311,"mc":[{"id":"1.232049325","rc":[{"batb":[[1,1.71,1.51],[2,1.67,1.78]],"ltp":1.72,"tv":10.63,"id":72857115}]}]}
{"op":"mcm","clk":"11895651215","pt":1724253169750,"mc":[{"id":"1.232049325","rc":[{"batb":[[0,1.71,1.51],[1,1.67,1.78],[2,1.04,1.53]],"ltp":1.72,"tv":10.63,"id":72857115}]}]}
{"op":"mcm","clk":"11895651335","pt":1724253170844,"mc":[{"id":"1.232049325","rc":[{"batb":[[0,1.72,4],[1,1.71,1.51],[2,1.67,1.78]],"ltp":1.72,"tv":10.63,"id":72857115}]}]}
{"op":"mcm","clk":"11895651635","pt":1724253173619,"mc":[{"id":"1.232049325","rc":[{"batb":[[0,1.71,1.51],[1,1.67,1.78],[2,1.04,1.53]],"ltp":1.72,"tv":10.63,"id":72857115}]}]}
{"op":"mcm","clk":"11895665331","pt":1724253201268,"mc":[{"id":"1.232049325","rc":[{"batb":[[0,1.72,4],[1,1.71,1.51],[2,1.67,1.78]],"ltp":1.72,"tv":10.63,"id":72857115}]}]}
{"op":"mcm","clk":"11895665415","pt":1724253202062,"mc":[{"id":"1.232049325","rc":[{"batb":[[0,1.73,10],[1,1.72,4],[2,1.71,1.51]],"ltp":1.72,"tv":10.63,"id":72857115}]}]}
{"op":"mcm","clk":"11895665667","pt":1724253204273,"mc":[{"id":"1.232049325","rc":[{"batb":[[1,1.71,1.51],[2,1.67,1.78]],"ltp":1.72,"tv":10.63,"id":72857115}]}]}
{"op":"mcm","clk":"11895665881","pt":1724253205878,"mc":[{"id":"1.232049325","rc":[{"batb":[[0,1.71,1.51],[1,1.67,1.78],[2,1.04,1.53]],"ltp":1.72,"tv":10.63,"id":72857115}]}]}
{"op":"mcm","clk":"11895666377","pt":1724253209998,"mc":[{"id":"1.232049325","rc":[{"batb":[[0,1.72,4],[1,1.71,1.51],[2,1.67,1.78]],"ltp":1.72,"tv":10.63,"id":72857115}]}]}
{"op":"mcm","clk":"11895666478","pt":1724253210891,"mc":[{"id":"1.232049325","rc":[{"batb":[[0,1.73,10],[1,1.72,4],[2,1.71,1.51]],"ltp":1.72,"tv":10.63,"id":72857115}]}]}
{"op":"mcm","clk":"11895666707","pt":1724253212981,"mc":[{"id":"1.232049325","rc":[{"batb":[[1,1.71,1.51],[2,1.67,1.78]],"ltp":1.72,"tv":10.63,"id":72857115}]}]}
{"op":"mcm","clk":"11895666919","pt":1724253214605,"mc":[{"id":"1.232049325","rc":[{"batb":[[0,1.71,1.51],[1,1.67,1.78],[2,1.04,1.53]],"ltp":1.72,"tv":10.63,"id":72857115}]}]}
{"op":"mcm","clk":"11895667242","pt":1724253217297,"mc":[{"id":"1.232049325","rc":[{"batb":[[0,1.72,4],[1,1.71,1.51],[2,1.67,1.78]],"ltp":1.72,"tv":10.63,"id":72857115}]}]}
{"op":"mcm","clk":"11895667344","pt":1724253218294,"mc":[{"id":"1.232049325","rc":[{"batb":[[0,1.73,10],[1,1.72,4],[2,1.71,1.51]],"ltp":1.72,"tv":10.63,"id":72857115}]}]}
{"op":"mcm","clk":"11895667581","pt":1724253220114,"mc":[{"id":"1.232049325","rc":[{"batb":[[1,1.71,1.51],[2,1.67,1.78]],"ltp":1.72,"tv":10.63,"id":72857115}]}]}
{"op":"mcm","clk":"11895667781","pt":1724253221789,"mc":[{"id":"1.232049325","rc":[{"batb":[[0,1.71,1.51],[1,1.67,1.78],[2,1.04,1.53]],"ltp":1.72,"tv":10.63,"id":72857115}]}]}
{"op":"mcm","clk":"11895668048","pt":1724253224389,"mc":[{"id":"1.232049325","rc":[{"batb":[[0,1.73,10],[1,1.72,4],[2,1.71,1.51]],"ltp":1.72,"tv":10.63,"id":72857115}]}]}
{"op":"mcm","clk":"11895668323","pt":1724253226498,"mc":[{"id":"1.232049325","rc":[{"batb":[[1,1.71,1.51],[2,1.67,1.78]],"ltp":1.72,"tv":10.63,"id":72857115}]}]}
{"op":"mcm","clk":"11895668527","pt":1724253228310,"mc":[{"id":"1.232049325","rc":[{"batb":[[0,1.71,1.51],[1,1.67,1.78],[2,1.04,1.53]],"ltp":1.72,"tv":10.63,"id":72857115}]}]}
{"op":"mcm","clk":"11895668591","pt":1724253228793,"mc":[{"id":"1.232049325","rc":[{"batb":[[0,1.72,4],[1,1.71,1.51],[2,1.67,1.78]],"ltp":1.72,"tv":10.63,"id":72857115}]}]}
{"op":"mcm","clk":"11895668898","pt":1724253231331,"mc":[{"id":"1.232049325","rc":[{"batb":[[0,1.71,1.51],[1,1.67,1.78],[2,1.04,1.53]],"ltp":1.72,"tv":10.63,"id":72857115}]}]}
{"op":"mcm","clk":"11895670338","pt":1724253242502,"mc":[{"id":"1.232049325","rc":[{"batb":[[0,1.72,4],[1,1.71,1.51],[2,1.67,1.78]],"ltp":1.72,"tv":10.63,"id":72857115}]}]}
{"op":"mcm","clk":"11895670462","pt":1724253243541,"mc":[{"id":"1.232049325","rc":[{"batb":[[0,1.73,10],[1,1.72,4],[2,1.71,1.51]],"ltp":1.72,"tv":10.63,"id":72857115}]}]}
{"op":"mcm","clk":"11895670651","pt":1724253245118,"mc":[{"id":"1.232049325","rc":[{"batb":[[1,1.71,1.51],[2,1.67,1.78]],"ltp":1.72,"tv":10.63,"id":72857115}]}]}
{"op":"mcm","clk":"11895670935","pt":1724253247408,"mc":[{"id":"1.232049325","rc":[{"batb":[[0,1.71,1.51],[1,1.67,1.78],[2,1.04,1.53]],"ltp":1.72,"tv":10.63,"id":72857115}]}]}
{"op":"mcm","clk":"11895670965","pt":1724253247719,"mc":[{"id":"1.232049325","rc":[{"batb":[[0,1.72,4],[1,1.71,1.51],[2,1.67,1.78]],"ltp":1.72,"tv":10.63,"id":72857115}]}]}
{"op":"mcm","clk":"11895671237","pt":1724253250014,"mc":[{"id":"1.232049325","rc":[{"batb":[[0,1.71,1.51],[1,1.67,1.78],[2,1.04,1.53]],"ltp":1.72,"tv":10.63,"id":72857115}]}]}
{"op":"mcm","clk":"11895672536","pt":1724253260517,"mc":[{"id":"1.232049325","rc":[{"batb":[[0,1.73,10],[1,1.72,4],[2,1.71,1.51]],"ltp":1.72,"tv":10.63,"id":72857115}]}]}
{"op":"mcm","clk":"11895672825","pt":1724253262739,"mc":[{"id":"1.232049325","rc":[{"batb":[[1,1.71,1.51],[2,1.67,1.78]],"ltp":1.72,"tv":10.63,"id":72857115}]}]}
{"op":"mcm","clk":"11895673033","pt":1724253264554,"mc":[{"id":"1.232049325","rc":[{"batb":[[0,1.71,1.51],[1,1.67,1.78],[2,1.04,1.53]],"ltp":1.72,"tv":10.63,"id":72857115}]}]}
{"op":"mcm","clk":"11895673077","pt":1724253264920,"mc":[{"id":"1.232049325","rc":[{"batb":[[0,1.72,4],[1,1.71,1.51],[2,1.67,1.78]],"ltp":1.72,"tv":10.63,"id":72857115}]}]}
{"op":"mcm","clk":"11895673426","pt":1724253267823,"mc":[{"id":"1.232049325","rc":[{"batb":[[0,1.71,1.51],[1,1.67,1.78],[2,1.04,1.53]],"ltp":1.72,"tv":10.63,"id":72857115}]}]}
{"op":"mcm","clk":"11895675027","pt":1724253280478,"mc":[{"id":"1.232049325","rc":[{"batb":[[0,1.72,4],[1,1.71,1.51],[2,1.67,1.78]],"ltp":1.72,"tv":10.63,"id":72857115}]}]}
{"op":"mcm","clk":"11895675146","pt":1724253281456,"mc":[{"id":"1.232049325","rc":[{"batb":[[0,1.73,10],[1,1.72,4],[2,1.71,1.51]],"ltp":1.72,"tv":10.63,"id":72857115}]}]}
{"op":"mcm","clk":"11895675410","pt":1724253283468,"mc":[{"id":"1.232049325","rc":[{"batb":[[1,1.71,1.51],[2,1.67,1.78]],"ltp":1.72,"tv":10.63,"id":72857115}]}]}
{"op":"mcm","clk":"11895675643","pt":1724253285178,"mc":[{"id":"1.232049325","rc":[{"batb":[[0,1.71,1.51],[1,1.67,1.78],[2,1.04,1.53]],"ltp":1.72,"tv":10.63,"id":72857115}]}]}
{"op":"mcm","clk":"11895675726","pt":1724253285799,"mc":[{"id":"1.232049325","rc":[{"batb":[[0,1.72,4],[1,1.71,1.51],[2,1.67,1.78]],"ltp":1.72,"tv":10.63,"id":72857115}]}]}
{"op":"mcm","clk":"11895676088","pt":1724253288593,"mc":[{"id":"1.232049325","rc":[{"batb":[[0,1.71,1.51],[1,1.67,1.78],[2,1.04,1.53]],"ltp":1.72,"tv":10.63,"id":72857115}]}]}
{"op":"mcm","clk":"11895676751","pt":1724253293388,"mc":[{"id":"1.232049325","rc":[{"batb":[[0,1.73,10],[1,1.72,4],[2,1.71,1.51]],"ltp":1.72,"tv":10.63,"id":72857115}]}]}
{"op":"mcm","clk":"11895676995","pt":1724253295671,"mc":[{"id":"1.232049325","rc":[{"batb":[[1,1.71,1.51],[2,1.67,1.78]],"ltp":1.72,"tv":10.63,"id":72857115}]}]}
{"op":"mcm","clk":"11895677209","pt":1724253297381,"mc":[{"id":"1.232049325","rc":[{"batb":[[0,1.71,1.51],[1,1.67,1.78],[2,1.04,1.53]],"ltp":1.72,"tv":10.63,"id":72857115}]}]}
{"op":"mcm","clk":"11895679759","pt":1724253315403,"mc":[{"id":"1.232049325","rc":[{"batb":[[0,1.72,4],[1,1.71,1.51],[2,1.67,1.78]],"ltp":1.72,"tv":10.63,"id":72857115}]}]}
{"op":"mcm","clk":"11895679792","pt":1724253315612,"mc":[{"id":"1.232049325","rc":[{"batb":[[0,1.73,10],[1,1.72,4],[2,1.71,1.51]],"ltp":1.72,"tv":10.63,"id":72857115}]}]}
{"op":"mcm","clk":"11895680142","pt":1724253318205,"mc":[{"id":"1.232049325","rc":[{"batb":[[1,1.71,1.51],[2,1.67,1.78]],"ltp":1.72,"tv":10.63,"id":72857115}]}]}
{"op":"mcm","clk":"11895680318","pt":1724253319705,"mc":[{"id":"1.232049325","rc":[{"batb":[[0,1.71,1.51],[1,1.67,1.78],[2,1.04,1.53]],"ltp":1.72,"tv":10.63,"id":72857115}]}]}
{"op":"mcm","clk":"11895681123","pt":1724253326215,"mc":[{"id":"1.232049325","rc":[{"batb":[[0,1.73,10],[1,1.72,4],[2,1.71,1.51]],"ltp":1.72,"tv":10.63,"id":72857115}]}]}
{"op":"mcm","clk":"11895681395","pt":1724253328319,"mc":[{"id":"1.232049325","rc":[{"batb":[[1,1.71,1.51],[2,1.67,1.78]],"ltp":1.72,"tv":10.63,"id":72857115}]}]}
{"op":"mcm","clk":"11895681564","pt":1724253329729,"mc":[{"id":"1.232049325","rc":[{"batb":[[0,1.71,1.51],[1,1.67,1.78],[2,1.04,1.53]],"ltp":1.72,"tv":10.63,"id":72857115}]}]}
{"op":"mcm","clk":"11895682686","pt":1724253338241,"mc":[{"id":"1.232049325","rc":[{"batb":[[0,1.72,4],[1,1.71,1.51],[2,1.67,1.78]],"ltp":1.72,"tv":10.63,"id":72857115}]}]}
{"op":"mcm","clk":"11895682922","pt":1724253339843,"mc":[{"id":"1.232049325","rc":[{"batb":[[0,1.73,10],[1,1.72,4],[2,1.71,1.51]],"ltp":1.72,"tv":10.63,"id":72857115}]}]}
{"op":"mcm","clk":"11895683184","pt":1724253341932,"mc":[{"id":"1.232049325","rc":[{"batb":[[1,1.71,1.51],[2,1.67,1.78]],"ltp":1.72,"tv":10.63,"id":72857115}]}]}
{"op":"mcm","clk":"11895683507","pt":1724253344437,"mc":[{"id":"1.232049325","rc":[{"batb":[[0,1.71,1.51],[1,1.67,1.78],[2,1.04,1.53]],"ltp":1.72,"tv":10.63,"id":72857115}]}]}
{"op":"mcm","clk":"11895683555","pt":1724253344844,"mc":[{"id":"1.232049325","rc":[{"batb":[[0,1.72,4],[1,1.71,1.51],[2,1.67,1.78]],"ltp":1.72,"tv":10.63,"id":72857115}]}]}
{"op":"mcm","clk":"11895683843","pt":1724253347238,"mc":[{"id":"1.232049325","rc":[{"batb":[[0,1.73,10]],"ltp":1.72,"tv":10.63,"id":72857115}]}]}
{"op":"mcm","clk":"11895684371","pt":1724253351041,"mc":[{"id":"1.232049325","rc":[{"batb":[[0,1.71,1.51],[1,1.67,1.78],[2,1.04,1.53]],"ltp":1.72,"tv":10.63,"id":72857115}]}]}
{"op":"mcm","clk":"11895684443","pt":1724253351659,"mc":[{"id":"1.232049325","rc":[{"batb":[[0,1.72,4],[1,1.71,1.51],[2,1.67,1.78]],"ltp":1.72,"tv":10.63,"id":72857115}]}]}
{"op":"mcm","clk":"11895684760","pt":1724253354549,"mc":[{"id":"1.232049325","rc":[{"batb":[[0,1.71,1.51],[1,1.67,1.78],[2,1.04,1.53]],"ltp":1.72,"tv":10.63,"id":72857115}]}]}
{"op":"mcm","clk":"11895687907","pt":1724253378423,"mc":[{"id":"1.232049325","rc":[{"batb":[[0,1.73,10],[1,1.72,4],[2,1.71,1.51]],"ltp":1.72,"tv":10.63,"id":72857115}]}]}
{"op":"mcm","clk":"11895688214","pt":1724253380653,"mc":[{"id":"1.232049325","rc":[{"batb":[[1,1.71,1.51],[2,1.67,1.78]],"ltp":1.72,"tv":10.63,"id":72857115}]}]}
{"op":"mcm","clk":"11895688506","pt":1724253382833,"mc":[{"id":"1.232049325","rc":[{"batb":[[0,1.72,4]],"ltp":1.72,"tv":10.63,"id":72857115}]}]}
{"op":"mcm","clk":"11895688803","pt":1724253385326,"mc":[{"id":"1.232049325","rc":[{"batb":[[0,1.71,1.51],[1,1.67,1.78],[2,1.04,1.53]],"ltp":1.72,"tv":10.63,"id":72857115}]}]}
{"op":"mcm","clk":"11895689305","pt":1724253389004,"mc":[{"id":"1.232049325","rc":[{"batb":[[0,1.73,10],[1,1.72,4],[2,1.71,1.51]],"ltp":1.72,"tv":10.63,"id":72857115}]}]}
{"op":"mcm","clk":"11895689628","pt":1724253391647,"mc":[{"id":"1.232049325","rc":[{"batb":[[1,1.71,1.51],[2,1.67,1.78]],"ltp":1.72,"tv":10.63,"id":72857115}]}]}
{"op":"mcm","clk":"11895689778","pt":1724253392948,"mc":[{"id":"1.232049325","rc":[{"batb":[[0,1.71,1.51],[1,1.67,1.78],[2,1.04,1.53]],"ltp":1.72,"tv":10.63,"id":72857115}]}]}
{"op":"mcm","clk":"11895690680","pt":1724253400541,"mc":[{"id":"1.232049325","rc":[{"batb":[[0,1.73,10],[1,1.72,4],[2,1.71,1.51]],"ltp":1.72,"tv":10.63,"id":72857115}]}]}
{"op":"mcm","clk":"11895690965","pt":1724253402743,"mc":[{"id":"1.232049325","rc":[{"batb":[[1,1.71,1.51],[2,1.67,1.78]],"ltp":1.72,"tv":10.63,"id":72857115}]}]}
{"op":"mcm","clk":"11895691166","pt":1724253404344,"mc":[{"id":"1.232049325","rc":[{"batb":[[0,1.71,1.51],[1,1.67,1.78],[2,1.04,1.53]],"ltp":1.72,"tv":10.63,"id":72857115}]}]}
{"op":"mcm","clk":"11895693924","pt":1724253426252,"mc":[{"id":"1.232049325","rc":[{"batb":[[0,1.73,10],[1,1.72,4],[2,1.71,1.51]],"ltp":1.72,"tv":10.63,"id":72857115}]}]}
{"op":"mcm","clk":"11895694289","pt":1724253429154,"mc":[{"id":"1.232049325","rc":[{"batb":[[1,1.71,1.51],[2,1.67,1.78]],"ltp":1.72,"tv":10.63,"id":72857115}]}]}
{"op":"mcm","clk":"11895694395","pt":1724253430292,"mc":[{"id":"1.232049325","rc":[{"batb":[[0,1.71,1.51],[1,1.67,1.78],[2,1.04,1.53]],"ltp":1.72,"tv":10.63,"id":72857115}]}]}
{"op":"mcm","clk":"11895694876","pt":1724253434191,"mc":[{"id":"1.232049325","rc":[{"batb":[[0,1.73,10],[1,1.72,4],[2,1.71,1.51]],"ltp":1.72,"tv":10.63,"id":72857115}]}]}
{"op":"mcm","clk":"11895695222","pt":1724253436789,"mc":[{"id":"1.232049325","rc":[{"batb":[[1,1.71,1.51],[2,1.67,1.78]],"ltp":1.72,"tv":10.63,"id":72857115}]}]}
{"op":"mcm","clk":"11895695386","pt":1724253438102,"mc":[{"id":"1.232049325","rc":[{"batb":[[0,1.71,1.51],[1,1.67,1.78],[2,1.04,1.53]],"ltp":1.72,"tv":10.63,"id":72857115}]}]}
{"op":"mcm","clk":"11895696153","pt":1724253444496,"mc":[{"id":"1.232049325","rc":[{"batb":[[0,1.73,10],[1,1.72,4],[2,1.71,1.51]],"ltp":1.72,"tv":10.63,"id":72857115}]}]}
{"op":"mcm","clk":"11895696491","pt":1724253447305,"mc":[{"id":"1.232049325","rc":[{"batb":[[1,1.71,1.51],[2,1.67,1.78]],"ltp":1.72,"tv":10.63,"id":72857115}]}]}
{"op":"mcm","clk":"11895696607","pt":1724253448399,"mc":[{"id":"1.232049325","rc":[{"batb":[[0,1.71,1.51],[1,1.67,1.78],[2,1.04,1.53]],"ltp":1.72,"tv":10.63,"id":72857115}]}]}
{"op":"mcm","clk":"11895697683","pt":1724253457105,"mc":[{"id":"1.232049325","rc":[{"batb":[[0,1.72,4],[1,1.71,1.51],[2,1.67,1.78]],"ltp":1.72,"tv":10.63,"id":72857115}]}]}
{"op":"mcm","clk":"11895697770","pt":1724253457885,"mc":[{"id":"1.232049325","rc":[{"batb":[[0,1.73,10],[1,1.72,4],[2,1.71,1.51]],"ltp":1.72,"tv":10.63,"id":72857115}]}]}
{"op":"mcm","clk":"11895698034","pt":1724253460015,"mc":[{"id":"1.232049325","rc":[{"batb":[[1,1.71,1.51],[2,1.67,1.78]],"ltp":1.72,"tv":10.63,"id":72857115}]}]}
{"op":"mcm","clk":"11895698250","pt":1724253461629,"mc":[{"id":"1.232049325","rc":[{"batb":[[0,1.71,1.51],[1,1.67,1.78],[2,1.04,1.53]],"ltp":1.72,"tv":10.63,"id":72857115}]}]}
{"op":"mcm","clk":"11895698480","pt":1724253463290,"mc":[{"id":"1.232049325","rc":[{"batb":[[0,1.72,4],[1,1.71,1.51],[2,1.67,1.78]],"ltp":1.72,"tv":10.63,"id":72857115}]}]}
{"op":"mcm","clk":"11895698819","pt":1724253466091,"mc":[{"id":"1.232049325","rc":[{"batb":[[0,1.71,1.51],[1,1.67,1.78],[2,1.04,1.53]],"ltp":1.72,"tv":10.63,"id":72857115}]}]}
{"op":"mcm","clk":"11895699695","pt":1724253473053,"mc":[{"id":"1.232049325","rc":[{"batb":[[0,1.72,4],[1,1.71,1.51],[2,1.67,1.78]],"ltp":1.72,"tv":10.63,"id":72857115}]}]}
{"op":"mcm","clk":"11895699866","pt":1724253474308,"mc":[{"id":"1.232049325","rc":[{"batb":[[0,1.73,10],[1,1.72,4],[2,1.71,1.51]],"ltp":1.72,"tv":10.63,"id":72857115}]}]}
{"op":"mcm","clk":"11895700031","pt":1724253475710,"mc":[{"id":"1.232049325","rc":[{"batb":[[1,1.71,1.51],[2,1.67,1.78]],"ltp":1.72,"tv":10.63,"id":72857115}]}]}
{"op":"mcm","clk":"11895700339","pt":1724253478349,"mc":[{"id":"1.232049325","rc":[{"batb":[[0,1.71,1.51],[1,1.67,1.78],[2,1.04,1.53]],"ltp":1.72,"tv":10.63,"id":72857115}]}]}
{"op":"mcm","clk":"11895700382","pt":1724253478725,"mc":[{"id":"1.232049325","rc":[{"batb":[[0,1.72,4],[1,1.71,1.51],[2,1.67,1.78]],"ltp":1.72,"tv":10.63,"id":72857115}]}]}
{"op":"mcm","clk":"11895700711","pt":1724253481157,"mc":[{"id":"1.232049325","rc":[{"batb":[[0,1.71,1.51],[1,1.67,1.78],[2,1.04,1.53]],"ltp":1.72,"tv":10.63,"id":72857115}]}]}
{"op":"mcm","clk":"11895706312","pt":1724253525291,"mc":[{"id":"1.232049325","rc":[{"batb":[[0,1.72,4],[1,1.71,1.51],[2,1.67,1.78]],"ltp":1.72,"tv":10.63,"id":72857115}]}]}
{"op":"mcm","clk":"11895706416","pt":1724253526079,"mc":[{"id":"1.232049325","rc":[{"batb":[[0,1.73,10],[1,1.72,4],[2,1.71,1.51]],"ltp":1.72,"tv":10.63,"id":72857115}]}]}
{"op":"mcm","clk":"11895706662","pt":1724253528108,"mc":[{"id":"1.232049325","rc":[{"batb":[[1,1.71,1.51],[2,1.67,1.78]],"ltp":1.72,"tv":10.63,"id":72857115}]}]}
{"op":"mcm","clk":"11895706901","pt":1724253529711,"mc":[{"id":"1.232049325","rc":[{"batb":[[0,1.71,1.51],[1,1.67,1.78],[2,1.04,1.53]],"ltp":1.72,"tv":10.63,"id":72857115}]}]}
{"op":"mcm","clk":"11895708760","pt":1724253543533,"mc":[{"id":"1.232049325","rc":[{"batb":[[0,1.72,4],[1,1.71,1.51],[2,1.67,1.78]],"ltp":1.72,"tv":10.63,"id":72857115}]}]}
{"op":"mcm","clk":"11895708821","pt":1724253543925,"mc":[{"id":"1.232049325","rc":[{"batb":[[0,1.73,10],[1,1.72,4],[2,1.71,1.51]],"ltp":1.72,"tv":10.63,"id":72857115}]}]}
{"op":"mcm","clk":"11895709130","pt":1724253546398,"mc":[{"id":"1.232049325","rc":[{"batb":[[1,1.71,1.51],[2,1.67,1.78]],"ltp":1.72,"tv":10.63,"id":72857115}]}]}
{"op":"mcm","clk":"11895709304","pt":1724253547905,"mc":[{"id":"1.232049325","rc":[{"batb":[[0,1.71,1.51],[1,1.67,1.78],[2,1.04,1.53]],"ltp":1.72,"tv":10.63,"id":72857115}]}]}
{"op":"mcm","clk":"11895710170","pt":1724253554530,"mc":[{"id":"1.232049325","rc":[{"batb":[[0,1.72,4],[1,1.71,1.51],[2,1.67,1.78]],"ltp":1.72,"tv":10.63,"id":72857115}]}]}
{"op":"mcm","clk":"11895710270","pt":1724253555359,"mc":[{"id":"1.232049325","rc":[{"batb":[[0,1.73,10],[1,1.72,4],[2,1.71,1.51]],"ltp":1.72,"tv":10.63,"id":72857115}]}]}
{"op":"mcm","clk":"11895710541","pt":1724253557540,"mc":[{"id":"1.232049325","rc":[{"batb":[[1,1.71,1.51],[2,1.67,1.78]],"ltp":1.72,"tv":10.63,"id":72857115}]}]}
{"op":"mcm","clk":"11895710745","pt":1724253559147,"mc":[{"id":"1.232049325","rc":[{"batb":[[0,1.71,1.51],[1,1.67,1.78],[2,1.04,1.53]],"ltp":1.72,"tv":10.63,"id":72857115}]}]}
{"op":"mcm","clk":"11895711182","pt":1724253562421,"mc":[{"id":"1.232049325","rc":[{"batb":[[0,1.72,4],[1,1.71,1.51],[2,1.67,1.78]],"ltp":1.72,"tv":10.63,"id":72857115}]}]}
{"op":"mcm","clk":"11895711278","pt":1724253563356,"mc":[{"id":"1.232049325","rc":[{"batb":[[0,1.73,10],[1,1.72,4],[2,1.71,1.51]],"ltp":1.72,"tv":10.63,"id":72857115}]}]}
{"op":"mcm","clk":"11895711499","pt":1724253565266,"mc":[{"id":"1.232049325","rc":[{"batb":[[1,1.71,1.51],[2,1.67,1.78]],"ltp":1.72,"tv":10.63,"id":72857115}]}]}
{"op":"mcm","clk":"11895711755","pt":1724253567447,"mc":[{"id":"1.232049325","rc":[{"batb":[[0,1.72,4]],"ltp":1.72,"tv":10.63,"id":72857115}]}]}
{"op":"mcm","clk":"11895712070","pt":1724253570041,"mc":[{"id":"1.232049325","rc":[{"batb":[[0,1.71,1.51],[1,1.67,1.78],[2,1.04,1.53]],"ltp":1.72,"tv":10.63,"id":72857115}]}]}
{"op":"mcm","clk":"11895723803","pt":1724253659985,"mc":[{"id":"1.232049325","rc":[{"batb":[[0,1.82,1.96],[1,1.68,4.89],[2,1.04,2.42]],"ltp":1.72,"tv":10.63,"id":72857115}]}]}
{"op":"mcm","clk":"11895724122","pt":1724253662288,"mc":[{"id":"1.232049325","rc":[{"batb":[[1,1.67,1.78],[2,1.04,1.53]],"ltp":1.72,"tv":10.63,"id":72857115}]}]}
{"op":"mcm","clk":"11895734133","pt":1724253734170,"mc":[{"id":"1.232049325","rc":[{"batb":[[0,1.84,10],[1,1.83,4],[2,1.82,1.96]],"ltp":1.72,"tv":10.63,"id":72857115}]}]}
{"op":"mcm","clk":"11895734424","pt":1724253736060,"mc":[{"id":"1.232049325","rc":[{"batb":[[1,1.82,1.96],[2,1.67,1.78]],"ltp":1.72,"tv":10.63,"id":72857115}]}]}
{"op":"mcm","clk":"11895734756","pt":1724253738376,"mc":[{"id":"1.232049325","rc":[{"batb":[[0,1.83,4]],"ltp":1.72,"tv":10.63,"id":72857115}]}]}
{"op":"mcm","clk":"11895735069","pt":1724253740674,"mc":[{"id":"1.232049325","rc":[{"batb":[[0,1.82,1.96],[1,1.67,1.78],[2,1.04,1.53]],"ltp":1.72,"tv":10.63,"id":72857115}]}]}
{"op":"mcm","clk":"11895736982","pt":1724253754469,"mc":[{"id":"1.232049325","rc":[{"batb":[[0,1.84,10],[1,1.83,4],[2,1.82,1.96]],"ltp":1.72,"tv":10.63,"id":72857115}]}]}
{"op":"mcm","clk":"11895737273","pt":1724253756600,"mc":[{"id":"1.232049325","rc":[{"batb":[[1,1.82,1.96],[2,1.67,1.78]],"ltp":1.72,"tv":10.63,"id":72857115}]}]}
{"op":"mcm","clk":"11895737508","pt":1724253758271,"mc":[{"id":"1.232049325","rc":[{"batb":[[0,1.82,1.96],[1,1.67,1.78],[2,1.04,1.53]],"ltp":1.72,"tv":10.63,"id":72857115}]}]}
{"op":"mcm","clk":"11895738836","pt":1724253767567,"mc":[{"id":"1.232049325","rc":[{"batb":[[0,1.84,10],[1,1.83,4],[2,1.82,1.96]],"ltp":1.72,"tv":10.63,"id":72857115}]}]}
{"op":"mcm","clk":"11895739180","pt":1724253769810,"mc":[{"id":"1.232049325","rc":[{"batb":[[1,1.82,1.96],[2,1.67,1.78]],"ltp":1.72,"tv":10.63,"id":72857115}]}]}
{"op":"mcm","clk":"11895739394","pt":1724253771473,"mc":[{"id":"1.232049325","rc":[{"batb":[[0,1.82,1.96],[1,1.67,1.78],[2,1.04,1.53]],"ltp":1.72,"tv":10.63,"id":72857115}]}]}
{"op":"mcm","clk":"11895744845","pt":1724253810560,"mc":[{"id":"1.232049325","rc":[{"batb":[[0,1.83,4],[1,1.82,1.96],[2,1.67,1.78]],"ltp":1.72,"tv":10.63,"id":72857115}]}]}
{"op":"mcm","clk":"11895744924","pt":1724253811178,"mc":[{"id":"1.232049325","rc":[{"batb":[[0,1.84,10],[1,1.83,4],[2,1.82,1.96]],"ltp":1.72,"tv":10.63,"id":72857115}]}]}
{"op":"mcm","clk":"11895745207","pt":1724253813180,"mc":[{"id":"1.232049325","rc":[{"batb":[[1,1.82,1.96],[2,1.67,1.78]],"ltp":1.72,"tv":10.63,"id":72857115}]}]}
{"op":"mcm","clk":"11895745438","pt":1724253814792,"mc":[{"id":"1.232049325","rc":[{"batb":[[0,1.82,1.96],[1,1.67,1.78],[2,1.04,1.53]],"ltp":1.72,"tv":10.63,"id":72857115}]}]}
{"op":"mcm","clk":"11895748039","pt":1724253833565,"mc":[{"id":"1.232049325","rc":[{"batb":[[0,1.84,10],[1,1.83,4],[2,1.82,1.96]],"ltp":1.72,"tv":10.63,"id":72857115}]}]}
{"op":"mcm","clk":"11895748308","pt":1724253835629,"mc":[{"id":"1.232049325","rc":[{"batb":[[1,1.82,1.96],[2,1.67,1.78]],"ltp":1.72,"tv":10.63,"id":72857115}]}]}
{"op":"mcm","clk":"11895748581","pt":1724253837503,"mc":[{"id":"1.232049325","rc":[{"batb":[[0,1.82,1.96],[1,1.67,1.78],[2,1.04,1.53]],"ltp":1.72,"tv":10.63,"id":72857115}]}]}
{"op":"mcm","clk":"11895748635","pt":1724253837915,"mc":[{"id":"1.232049325","rc":[{"batb":[[0,1.83,4],[1,1.82,1.96],[2,1.67,1.78]],"ltp":1.72,"tv":10.63,"id":72857115}]}]}
{"op":"mcm","clk":"11895748926","pt":1724253840209,"mc":[{"id":"1.232049325","rc":[{"batb":[[0,1.82,1.96],[1,1.67,1.78],[2,1.04,1.53]],"ltp":1.72,"tv":10.63,"id":72857115}]}]}
{"op":"mcm","clk":"11895753357","pt":1724253872157,"mc":[{"id":"1.232049325","rc":[{"batb":[[0,1.83,4],[1,1.82,1.96],[2,1.67,1.78]],"ltp":1.72,"tv":10.63,"id":72857115}]}]}
{"op":"mcm","clk":"11895753436","pt":1724253872634,"mc":[{"id":"1.232049325","rc":[{"batb":[[0,1.84,10],[1,1.83,4],[2,1.82,1.96]],"ltp":1.72,"tv":10.63,"id":72857115}]}]}
{"op":"mcm","clk":"11895753705","pt":1724253874739,"mc":[{"id":"1.232049325","rc":[{"batb":[[1,1.82,1.96],[2,1.67,1.78]],"ltp":1.72,"tv":10.63,"id":72857115}]}]}
{"op":"mcm","clk":"11895753927","pt":1724253876460,"mc":[{"id":"1.232049325","rc":[{"batb":[[0,1.82,1.96],[1,1.67,1.78],[2,1.04,1.53]],"ltp":1.72,"tv":10.63,"id":72857115}]}]}
{"op":"mcm","clk":"11895755672","pt":1724253889578,"mc":[{"id":"1.232049325","rc":[{"batb":[[0,1.83,4],[1,1.82,1.96],[2,1.67,1.78]],"ltp":1.72,"tv":10.63,"id":72857115}]}]}
{"op":"mcm","clk":"11895755727","pt":1724253889958,"mc":[{"id":"1.232049325","rc":[{"batb":[[0,1.84,10],[1,1.83,4],[2,1.82,1.96]],"ltp":1.72,"tv":10.63,"id":72857115}]}]}
{"op":"mcm","clk":"11895755976","pt":1724253891900,"mc":[{"id":"1.232049325","rc":[{"batb":[[1,1.82,1.96],[2,1.67,1.78]],"ltp":1.72,"tv":10.63,"id":72857115}]}]}
{"op":"mcm","clk":"11895756267","pt":1724253894090,"mc":[{"id":"1.232049325","rc":[{"batb":[[0,1.83,4]],"ltp":1.72,"tv":10.63,"id":72857115}]}]}
{"op":"mcm","clk":"11895756591","pt":1724253896369,"mc":[{"id":"1.232049325","rc":[{"batb":[[0,1.82,1.96],[1,1.67,1.78],[2,1.04,1.53]],"ltp":1.72,"tv":10.63,"id":72857115}]}]}
{"op":"mcm","clk":"11895761357","pt":1724253929517,"mc":[{"id":"1.232049325","rc":[{"batb":[[0,1.84,10],[1,1.83,4],[2,1.82,1.96]],"ltp":1.72,"tv":10.63,"id":72857115}]}]}
{"op":"mcm","clk":"11895761645","pt":1724253931653,"mc":[{"id":"1.232049325","rc":[{"batb":[[1,1.82,1.96],[2,1.67,1.78]],"ltp":1.72,"tv":10.63,"id":72857115}]}]}
{"op":"mcm","clk":"11895761890","pt":1724253933447,"mc":[{"id":"1.232049325","rc":[{"batb":[[0,1.82,1.96],[1,1.67,1.78],[2,1.04,1.53]],"ltp":1.72,"tv":10.63,"id":72857115}]}]}
{"op":"mcm","clk":"11895761953","pt":1724253933816,"mc":[{"id":"1.232049325","rc":[{"batb":[[0,1.83,4],[1,1.82,1.96],[2,1.67,1.78]],"ltp":1.72,"tv":10.63,"id":72857115}]}]}
{"op":"mcm","clk":"11895762251","pt":1724253936139,"mc":[{"id":"1.232049325","rc":[{"batb":[[0,1.82,1.96],[1,1.67,1.78],[2,1.04,1.53]],"ltp":1.72,"tv":10.63,"id":72857115}]}]}
{"op":"mcm","clk":"11895764662","pt":1724253954964,"mc":[{"id":"1.232049325","rc":[{"batb":[[0,1.83,4],[1,1.82,1.96],[2,1.67,1.78]],"ltp":1.72,"tv":10.63,"id":72857115}]}]}
{"op":"mcm","clk":"11895764760","pt":1724253955752,"mc":[{"id":"1.232049325","rc":[{"batb":[[0,1.84,10],[1,1.83,4],[2,1.82,1.96]],"ltp":1.72,"tv":10.63,"id":72857115}]}]}
{"op":"mcm","clk":"11895765031","pt":1724253957938,"mc":[{"id":"1.232049325","rc":[{"batb":[[1,1.82,1.96],[2,1.67,1.78]],"ltp":1.72,"tv":10.63,"id":72857115}]}]}
{"op":"mcm","clk":"11895765271","pt":1724253959771,"mc":[{"id":"1.232049325","rc":[{"batb":[[0,1.82,1.96],[1,1.67,1.78],[2,1.04,1.53]],"ltp":1.72,"tv":10.63,"id":72857115}]}]}
{"op":"mcm","clk":"11895765645","pt":1724253962582,"mc":[{"id":"1.232049325","rc":[{"batb":[[0,1.83,4],[1,1.82,1.96],[2,1.67,1.78]],"ltp":1.72,"tv":10.63,"id":72857115}]}]}
{"op":"mcm","clk":"11895765699","pt":1724253962944,"mc":[{"id":"1.232049325","rc":[{"batb":[[0,1.84,10],[1,1.83,4],[2,1.82,1.96]],"ltp":1.72,"tv":10.63,"id":72857115}]}]}
{"op":"mcm","clk":"11895766616","pt":1724253969775,"mc":[{"id":"1.232049325","rc":[{"batb":[[1,1.82,1.96],[2,1.67,1.78]],"ltp":1.72,"tv":10.63,"id":72857115}]}]}
{"op":"mcm","clk":"11895767116","pt":1724253973376,"mc":[{"id":"1.232049325","rc":[{"batb":[[0,1.83,4]],"ltp":1.72,"tv":10.63,"id":72857115}]}]}
{"op":"mcm","clk":"11895767483","pt":1724253975972,"mc":[{"id":"1.232049325","rc":[{"batb":[[0,1.82,1.96],[1,1.67,1.78],[2,1.04,1.53]],"ltp":1.72,"tv":10.63,"id":72857115}]}]}
{"op":"mcm","clk":"11895767838","pt":1724253978583,"mc":[{"id":"1.232049325","rc":[{"batb":[[0,1.83,4],[1,1.82,1.96],[2,1.67,1.78]],"ltp":1.72,"tv":10.63,"id":72857115}]}]}
{"op":"mcm","clk":"11895767944","pt":1724253979368,"mc":[{"id":"1.232049325","rc":[{"batb":[[0,1.84,10],[1,1.83,4],[2,1.82,1.96]],"ltp":1.72,"tv":10.63,"id":72857115}]}]}
{"op":"mcm","clk":"11895768235","pt":1724253981584,"mc":[{"id":"1.232049325","rc":[{"batb":[[1,1.82,1.96],[2,1.67,1.78]],"ltp":1.72,"tv":10.63,"id":72857115}]}]}
{"op":"mcm","clk":"11895768466","pt":1724253983265,"mc":[{"id":"1.232049325","rc":[{"batb":[[0,1.82,1.96],[1,1.67,1.78],[2,1.04,1.53]],"ltp":1.72,"tv":10.63,"id":72857115}]}]}
{"op":"mcm","clk":"11895769278","pt":1724253989781,"mc":[{"id":"1.232049325","rc":[{"batb":[[0,1.83,4],[1,1.82,1.96],[2,1.67,1.78]],"ltp":1.72,"tv":10.63,"id":72857115}]}]}
{"op":"mcm","clk":"11895769432","pt":1724253990876,"mc":[{"id":"1.232049325","rc":[{"batb":[[0,1.84,10],[1,1.83,4],[2,1.82,1.96]],"ltp":1.72,"tv":10.63,"id":72857115}]}]}
{"op":"mcm","clk":"11895769609","pt":1724253992363,"mc":[{"id":"1.232049325","rc":[{"batb":[[1,1.82,1.96],[2,1.67,1.78]],"ltp":1.72,"tv":10.63,"id":72857115}]}]}
{"op":"mcm","clk":"11895769911","pt":1724253994959,"mc":[{"id":"1.232049325","rc":[{"batb":[[0,1.83,4]],"ltp":1.72,"tv":10.63,"id":72857115}]}]}
{"op":"mcm","clk":"11895770147","pt":1724253997283,"mc":[{"id":"1.232049325","rc":[{"batb":[[0,1.82,1.96],[1,1.67,1.78],[2,1.04,1.53]],"ltp":1.72,"tv":10.63,"id":72857115}]}]}
{"op":"mcm","clk":"11895771731","pt":1724254010206,"mc":[{"id":"1.232049325","rc":[{"batb":[[0,1.69,10.89],[1,1.68,4],[2,1.04,2.42]],"ltp":1.72,"tv":10.63,"id":72857115}]}]}
{"op":"mcm","clk":"11895771972","pt":1724254012326,"mc":[{"id":"1.232049325","rc":[{"batb":[[1,1.04,2.42],[2,1.03,200]],"ltp":1.72,"tv":10.63,"id":72857115}]}]}
{"op":"mcm","clk":"11895772130","pt":1724254013684,"mc":[{"id":"1.232049325","rc":[{"batb":[[0,1.67,1.78],[1,1.04,1.53]],"ltp":1.72,"tv":10.63,"id":72857115}]}]}
{"op":"mcm","clk":"11895772295","pt":1724254014930,"mc":[{"id":"1.232049325","rc":[{"batb":[[0,1.68,4.89],[1,1.04,2.42]],"ltp":1.72,"tv":10.63,"id":72857115}]}]}
{"op":"mcm","clk":"11895772642","pt":1724254017832,"mc":[{"id":"1.232049325","rc":[{"batb":[[0,1.67,1.78],[1,1.04,1.53]],"ltp":1.72,"tv":10.63,"id":72857115}]}]}
{"op":"mcm","clk":"11895773505","pt":1724254024441,"mc":[{"id":"1.232049325","rc":[{"batb":[[0,1.69,10.89],[1,1.68,4],[2,1.04,2.42]],"ltp":1.72,"tv":10.63,"id":72857115}]}]}
{"op":"mcm","clk":"11895773802","pt":1724254026833,"mc":[{"id":"1.232049325","rc":[{"batb":[[1,1.04,2.42],[2,1.03,200]],"ltp":1.72,"tv":10.63,"id":72857115}]}]}
{"op":"mcm","clk":"11895773996","pt":1724254028453,"mc":[{"id":"1.232049325","rc":[{"batb":[[0,1.67,1.78],[1,1.04,1.53]],"ltp":1.72,"tv":10.63,"id":72857115}]}]}
{"op":"mcm","clk":"11895776075","pt":1724254044161,"mc":[{"id":"1.232049325","rc":[{"batb":[[0,1.68,4.89],[1,1.04,2.42]],"ltp":1.72,"tv":10.63,"id":72857115}]}]}
{"op":"mcm","clk":"11895776184","pt":1724254045040,"mc":[{"id":"1.232049325","rc":[{"batb":[[0,1.69,10.89],[1,1.68,4],[2,1.04,2.42]],"ltp":1.72,"tv":10.63,"id":72857115}]}]}
{"op":"mcm","clk":"11895776428","pt":1724254047086,"mc":[{"id":"1.232049325","rc":[{"batb":[[1,1.04,2.42],[2,1.03,200]],"ltp":1.72,"tv":10.63,"id":72857115}]}]}
{"op":"mcm","clk":"11895776654","pt":1724254048851,"mc":[{"id":"1.232049325","rc":[{"batb":[[0,1.67,1.78],[1,1.04,1.53]],"ltp":1.72,"tv":10.63,"id":72857115}]}]}
{"op":"mcm","clk":"11895777303","pt":1724254053500,"mc":[{"id":"1.232049325","rc":[{"batb":[[0,1.47,2.91]],"ltp":2.0,"tv":49.38,"id":67083366},{"batb":[[0,1.69,1.89],[1,1.68,4],[2,1.04,2.42]],"ltp":1.72,"tv":10.63,"id":72857115}]}]}
{"op":"mcm","clk":"11895777592","pt":1724254055659,"mc":[{"id":"1.232049325","rc":[{"batb":[[1,1.04,2.42],[2,1.03,200]],"ltp":1.72,"tv":10.63,"id":72857115}]}]}
{"op":"mcm","clk":"11895779929","pt":1724254074269,"mc":[{"id":"1.232049325","rc":[{"batb":[[0,1.71,10],[1,1.7,4],[2,1.69,1.89]],"ltp":1.72,"tv":10.63,"id":72857115}]}]}
{"op":"mcm","clk":"11895780204","pt":1724254076461,"mc":[{"id":"1.232049325","rc":[{"batb":[[1,1.69,1.89],[2,1.04,2.42]],"ltp":1.72,"tv":10.63,"id":72857115}]}]}
{"op":"mcm","clk":"11895780426","pt":1724254078384,"mc":[{"id":"1.232049325","rc":[{"batb":[[0,1.69,1.89],[1,1.04,2.42],[2,1.03,200]],"ltp":1.72,"tv":10.63,"id":72857115}]}]}
{"op":"mcm","clk":"11895780461","pt":1724254078697,"mc":[{"id":"1.232049325","rc":[{"batb":[[0,1.7,4],[1,1.69,1.89],[2,1.04,2.42]],"ltp":1.72,"tv":10.63,"id":72857115}]}]}
{"op":"mcm","clk":"11895780760","pt":1724254081073,"mc":[{"id":"1.232049325","rc":[{"batb":[[0,1.69,1.89],[1,1.04,2.42],[2,1.03,200]],"ltp":1.72,"tv":10.63,"id":72857115}]}]}
{"op":"mcm","clk":"11895782385","pt":1724254093509,"mc":[{"id":"1.232049325","rc":[{"batb":[[0,1.7,4],[1,1.69,1.89],[2,1.04,2.42]],"ltp":1.72,"tv":10.63,"id":72857115}]}]}
