{"op":"mcm","clk":"11836520785","pt":1723456851528,"mc":[{"id":"1.231732748","marketDefinition":{"bspMarket":false,"turnInPlayEnabled":true,"persistenceEnabled":true,"marketBaseRate":5.0,"eventId":"33488437","eventTypeId":"4","numberOfWinners":1,"bettingType":"ODDS","marketType":"MATCH_ODDS","marketTime":"2024-08-15T14:00:00.000Z","suspendTime":"2024-08-15T14:00:00.000Z","bspReconciled":false,"complete":true,"inPlay":false,"crossMatching":true,"runnersVoidable":false,"numberOfActiveRunners":2,"betDelay":0,"status":"OPEN","runners":[{"status":"ACTIVE","sortPriority":1,"id":40296819,"name":"Birmingham Phoenix W"},{"status":"ACTIVE","sortPriority":2,"id":40296818,"name":"Manchester Originals W"}],"regulators":["MR_INT"],"countryCode":"GB","discountAllowed":false,"timezone":"GMT","openDate":"2024-08-15T14:00:00.000Z","version":6071662662,"name":"Match Odds","eventName":"Birmingham Phoenix W v Manchester Originals W"},"rc":[{"batb":[[0,1.03,200],[1,1.01,20]],"ltp":0.0,"tv":0.0,"id":40296818},{"batb":[[0,1.01,20]],"ltp":0.0,"tv":0.0,"id":40296819}]}]}
{"op":"mcm","clk":"11836520820","pt":1723456852207,"mc":[{"id":"1.231732748","rc":[{"batb":[[1,1.02,200],[2,1.01,220]],"ltp":0.0,"tv":0.0,"id":40296818},{"batb":[[0,1.03,200],[1,1.02,200],[2,1.01,220]],"ltp":0.0,"tv":0.0,"id":40296819}]}]}
{"op":"mcm","clk":"11836520882","pt":1723456853033,"mc":[{"id":"1.231732748","marketDefinition":{"bspMarket":false,"turnInPlayEnabled":true,"persistenceEnabled":true,"marketBaseRate":5.0,"eventId":"33488437","eventTypeId":"4","numberOfWinners":1,"bettingType":"ODDS","marketType":"MATCH_ODDS","marketTime":"2024-08-15T14:00:00.000Z","suspendTime":"2024-08-15T14:00:00.000Z","bspReconciled":false,"complete":true,"inPlay":false,"crossMatching":true,"runnersVoidable":false,"numberOfActiveRunners":2,"betDelay":0,"status":"OPEN","runners":[{"status":"ACTIVE","sortPriority":1,"id":40296819,"name":"Birmingham Phoenix W"},{"status":"ACTIVE","sortPriority":2,"id":40296818,"name":"Manchester Originals W"}],"regulators":["MR_INT"],"countryCode":"GB","discountAllowed":true,"timezone":"GMT","openDate":"2024-08-15T14:00:00.000Z","version":6071662662,"name":"Match Odds","eventName":"Birmingham Phoenix W v Manchester Originals W"}}]}
{"op":"mcm","clk":"11836579798","pt":1723458521529,"mc":[{"id":"1.231732748","rc":[{"batb":[[2,1.01,8056.99]],"ltp":0.0,"tv":0.0,"id":40296819}]}]}
{"op":"mcm","clk":"11836580105","pt":1723458530048,"mc":[{"id":"1.231732748","rc":[{"batb":[[2,1.01,8056.99]],"ltp":0.0,"tv":0.0,"id":40296818}]}]}
{"op":"mcm","clk":"11836584596","pt":1723458653775,"mc":[{"id":"1.231732748","rc":[{"batb":[[2,1.01,8317.48]],"ltp":0.0,"tv":0.0,"id":40296819}]}]}
{"op":"mcm","clk":"11836584610","pt":1723458654084,"mc":[{"id":"1.231732748","rc":[{"batb":[[2,1.01,8317.48]],"ltp":0.0,"tv":0.0,"id":40296818}]}]}
{"op":"mcm","clk":"11836620401","pt":1723459421952,"mc":[{"id":"1.231732748","rc":[{"batb":[[0,1.1,25000],[1,1.09,25000],[2,1.08,25000]],"ltp":0.0,"tv":0.0,"id":40296818},{"batb":[[0,1.1,25000],[1,1.09,25000],[2,1.08,25000]],"ltp":0.0,"tv":0.0,"id":40296819}]}]}
{"op":"mcm","clk":"11836622021","pt":1723459462996,"mc":[{"id":"1.231732748","rc":[{"batb":[[0,1.11,78.24],[1,1.1,25000],[2,1.09,25000]],"ltp":0.0,"tv":0.0,"id":40296818},{"batb":[[0,1.11,78.24],[1,1.08,25000],[2,1.07,25000]],"ltp":0.0,"tv":0.0,"id":40296819}]}]}
{"op":"mcm","clk":"11836622042","pt":1723459463512,"mc":[{"id":"1.231732748","rc":[{"batb":[[1,1.07,25000],[2,1.06,25000]],"ltp":0.0,"tv":0.0,"id":40296819}]}]}
{"op":"mcm","clk":"11836622111","pt":1723459465016,"mc":[{"id":"1.231732748","rc":[{"batb":[[1,1.05,25000],[2,1.04,25000]],"ltp":0.0,"tv":0.0,"id":40296819}]}]}
{"op":"mcm","clk":"11836622394","pt":1723459472011,"mc":[{"id":"1.231732748","rc":[{"batb":[[1,1.09,15000],[2,1.08,25000]],"ltp":0.0,"tv":0.0,"id":40296818}]}]}
{"op":"mcm","clk":"11836622453","pt":1723459472993,"mc":[{"id":"1.231732748","rc":[{"batb":[[1,1.07,10000],[2,1.06,25000]],"ltp":0.0,"tv":0.0,"id":40296818}]}]}
{"op":"mcm","clk":"11836622462","pt":1723459473202,"mc":[{"id":"1.231732748","rc":[{"batb":[[1,1.06,25000],[2,1.05,25000]],"ltp":0.0,"tv":0.0,"id":40296818}]}]}
{"op":"mcm","clk":"11836622512","pt":1723459474234,"mc":[{"id":"1.231732748","rc":[{"batb":[[1,1.05,25000],[2,1.04,25000]],"ltp":0.0,"tv":0.0,"id":40296818}]}]}
{"op":"mcm","clk":"11836687956","pt":1723461262633,"mc":[{"id":"1.231732748","rc":[{"batb":[[0,1.05,25000],[1,1.04,25000],[2,1.03,25200]],"ltp":0.0,"tv":0.0,"id":40296818},{"batb":[[0,1.05,25000],[1,1.04,25000],[2,1.03,25200]],"ltp":0.0,"tv":0.0,"id":40296819}]}]}
{"op":"mcm","clk":"11836690236","pt":1723461318074,"mc":[{"id":"1.231732748","rc":[{"batb":[[0,1.06,143.42],[1,1.05,25000],[2,1.04,25000]],"ltp":0.0,"tv":0.0,"id":40296818},{"batb":[[0,1.06,143.42],[1,1.05,25000],[2,1.04,25000]],"ltp":0.0,"tv":0.0,"id":40296819}]}]}
{"op":"mcm","clk":"11836745846","pt":1723463118513,"mc":[{"id":"1.231732748","rc":[{"batb":[[0,1.05,25000],[1,1.04,25000],[2,1.03,25200]],"ltp":0.0,"tv":0.0,"id":40296818},{"batb":[[0,1.05,25000],[1,1.04,25000],[2,1.03,25200]],"ltp":0.0,"tv":0.0,"id":40296819}]}]}
{"op":"mcm","clk":"11836746965","pt":1723463157193,"mc":[{"id":"1.231732748","rc":[{"batb":[[0,1.06,143.42],[1,1.05,25000],[2,1.04,25000]],"ltp":0.0,"tv":0.0,"id":40296818},{"batb":[[0,1.06,143.42],[1,1.05,25000],[2,1.04,25000]],"ltp":0.0,"tv":0.0,"id":40296819}]}]}
{"op":"mcm","clk":"11836795847","pt":1723464774889,"mc":[{"id":"1.231732748","rc":[{"batb":[[0,1.06,143.32]],"ltp":0.0,"tv":0.0,"id":40296818},{"batb":[[0,1.06,143.32]],"ltp":0.0,"tv":0.0,"id":40296819}]}]}
{"op":"mcm","clk":"11836804956","pt":1723464957624,"mc":[{"id":"1.231732748","rc":[{"batb":[[0,1.05,25000],[1,1.04,25000],[2,1.03,25200]],"ltp":0.0,"tv":0.0,"id":40296818},{"batb":[[0,1.05,25000],[1,1.04,25000],[2,1.03,25200]],"ltp":0.0,"tv":0.0,"id":40296819}]}]}
{"op":"mcm","clk":"11836805833","pt":1723464982534,"mc":[{"id":"1.231732748","rc":[{"batb":[[0,1.06,143.32],[1,1.05,25000],[2,1.04,25000]],"ltp":0.0,"tv":0.0,"id":40296818},{"batb":[[0,1.06,143.32],[1,1.05,25000],[2,1.04,25000]],"ltp":0.0,"tv":0.0,"id":40296819}]}]}
{"op":"mcm","clk":"11836858475","pt":1723466782935,"mc":[{"id":"1.231732748","rc":[{"batb":[[0,1.05,25000],[1,1.04,25000],[2,1.03,25200]],"ltp":0.0,"tv":0.0,"id":40296818},{"batb":[[0,1.05,25000],[1,1.04,25000],[2,1.03,25200]],"ltp":0.0,"tv":0.0,"id":40296819}]}]}
{"op":"mcm","clk":"11836858865","pt":1723466796685,"mc":[{"id":"1.231732748","rc":[{"batb":[[0,1.06,143.32],[1,1.05,25000],[2,1.04,25000]],"ltp":0.0,"tv":0.0,"id":40296818},{"batb":[[0,1.06,143.32],[1,1.05,25000],[2,1.04,25000]],"ltp":0.0,"tv":0.0,"id":40296819}]}]}
{"op":"mcm","clk":"11836867655","pt":1723467076889,"mc":[{"id":"1.231732748","rc":[{"batb":[[0,1.25,100],[1,1.06,143.32],[2,1.05,25000]],"ltp":0.0,"tv":0.0,"id":40296818},{"batb":[[0,1.25,100],[1,1.06,143.32],[2,1.05,25000]],"ltp":0.0,"tv":0.0,"id":40296819}]}]}
{"op":"mcm","clk":"11836908499","pt":1723468596985,"mc":[{"id":"1.231732748","rc":[{"batb":[[1,1.05,25000],[2,1.04,25000]],"ltp":0.0,"tv":0.0,"id":40296818},{"batb":[[1,1.06,143.3]],"ltp":0.0,"tv":0.0,"id":40296819}]}]}
{"op":"mcm","clk":"11836908512","pt":1723468597288,"mc":[{"id":"1.231732748","rc":[{"batb":[[1,1.05,25000],[2,1.04,25000]],"ltp":0.0,"tv":0.0,"id":40296819}]}]}
{"op":"mcm","clk":"11836908623","pt":1723468601504,"mc":[{"id":"1.231732748","rc":[{"batb":[[0,1.26,33.07],[1,1.25,100],[2,1.05,25000]],"ltp":0.0,"tv":0.0,"id":40296818},{"batb":[[0,1.26,33.07],[1,1.25,100],[2,1.05,25000]],"ltp":0.0,"tv":0.0,"id":40296819}]}]}
{"op":"mcm","clk":"11836938360","pt":1723469480880,"mc":[{"id":"1.231732748","rc":[{"batb":[[0,1.27,5.93],[1,1.26,33.07],[2,1.25,100]],"ltp":0.0,"tv":0.0,"id":40296819}]}]}
{"op":"mcm","clk":"11836938369","pt":1723469481041,"mc":[{"id":"1.231732748","rc":[{"batb":[[0,1.27,7.72],[1,1.26,33.07],[2,1.25,100]],"ltp":0.0,"tv":0.0,"id":40296818}]}]}
{"op":"mcm","clk":"11836975245","pt":1723470401897,"mc":[{"id":"1.231732748","rc":[{"batb":[[1,1.25,100],[2,1.05,25000]],"ltp":0.0,"tv":0.0,"id":40296818},{"batb":[[1,1.25,100],[2,1.05,25000]],"ltp":0.0,"tv":0.0,"id":40296819}]}]}
{"op":"mcm","clk":"11836976897","pt":1723470454065,"mc":[{"id":"1.231732748","rc":[{"batb":[[0,1.28,30.71],[1,1.27,7.72],[2,1.25,100]],"ltp":0.0,"tv":0.0,"id":40296818},{"batb":[[0,1.28,30.71],[1,1.27,5.93],[2,1.25,100]],"ltp":0.0,"tv":0.0,"id":40296819}]}]}
{"op":"mcm","clk":"11836995475","pt":1723471163973,"mc":[{"id":"1.231732748","rc":[{"batb":[[0,1.29,7.72],[1,1.28,30.71]],"ltp":0.0,"tv":0.0,"id":40296818},{"batb":[[0,1.29,5.93],[1,1.28,30.71]],"ltp":0.0,"tv":0.0,"id":40296819}]}]}
{"op":"mcm","clk":"11837039228","pt":1723472251530,"mc":[{"id":"1.231732748","rc":[{"batb":[[0,1.3,25],[1,1.29,7.72],[2,1.28,30.71]],"ltp":0.0,"tv":0.0,"id":40296818},{"batb":[[0,1.29,5.93],[1,1.28,30.71]],"ltp":0.0,"tv":0.0,"id":40296819}]}]}
{"op":"mcm","clk":"11837039359","pt":1723472254533,"mc":[{"id":"1.231732748","rc":[{"batb":[[2,1.25,100]],"ltp":0.0,"tv":0.0,"id":40296818},{"batb":[[1,1.25,100],[2,1.05,25000]],"ltp":0.0,"tv":0.0,"id":40296819}]}]}
{"op":"mcm","clk":"11837040102","pt":1723472274484,"mc":[{"id":"1.231732748","rc":[{"batb":[[0,1.3,25],[1,1.29,5.93],[2,1.25,100]],"ltp":0.0,"tv":0.0,"id":40296819}]}]}
{"op":"mcm","clk":"11837041901","pt":1723472327112,"mc":[{"id":"1.231732748","rc":[{"batb":[[0,1.31,27.74],[1,1.3,25],[2,1.29,7.72]],"ltp":0.0,"tv":0.0,"id":40296818},{"batb":[[0,1.31,27.74],[1,1.3,25],[2,1.29,5.93]],"ltp":0.0,"tv":0.0,"id":40296819}]}]}
{"op":"mcm","clk":"11837057618","pt":1723472832022,"mc":[{"id":"1.231732748","rc":[{"batb":[[2,1.25,100]],"ltp":0.0,"tv":0.0,"id":40296819}]}]}
{"op":"mcm","clk":"11837057636","pt":1723472832641,"mc":[{"id":"1.231732748","rc":[{"batb":[[0,1.32,7.72],[1,1.31,27.74],[2,1.3,25]],"ltp":0.0,"tv":0.0,"id":40296818},{"batb":[[0,1.32,5.93],[1,1.31,27.74],[2,1.3,25]],"ltp":0.0,"tv":0.0,"id":40296819}]}]}
{"op":"mcm","clk":"11837103382","pt":1723474127671,"mc":[{"id":"1.231732748","rc":[{"batb":[[1,1.3,25],[2,1.25,100]],"ltp":0.0,"tv":0.0,"id":40296818},{"batb":[[1,1.3,25],[2,1.25,100]],"ltp":0.0,"tv":0.0,"id":40296819}]}]}
{"op":"mcm","clk":"11837105701","pt":1723474191482,"mc":[{"id":"1.231732748","rc":[{"batb":[[0,1.33,26.06],[1,1.32,7.72],[2,1.3,25]],"ltp":0.0,"tv":0.0,"id":40296818},{"batb":[[0,1.33,26.06],[1,1.32,5.93],[2,1.3,25]],"ltp":0.0,"tv":0.0,"id":40296819}]}]}
{"op":"mcm","clk":"11837117958","pt":1723474519941,"mc":[{"id":"1.231732748","rc":[{"batb":[[0,1.34,7.72],[1,1.33,26.06]],"ltp":0.0,"tv":0.0,"id":40296818},{"batb":[[0,1.34,5.93],[1,1.33,26.06]],"ltp":0.0,"tv":0.0,"id":40296819}]}]}
{"op":"mcm","clk":"11837162914","pt":1723475574901,"mc":[{"id":"1.231732748","rc":[{"batb":[[0,1.34,7.71],[1,1.33,26.03]],"ltp":0.0,"tv":0.0,"id":40296818},{"batb":[[0,1.34,5.92],[1,1.33,26.03]],"ltp":0.0,"tv":0.0,"id":40296819}]}]}
{"op":"mcm","clk":"11837183766","pt":1723475991915,"mc":[{"id":"1.231732748","rc":[{"batb":[[1,1.3,25],[2,1.25,100]],"ltp":0.0,"tv":0.0,"id":40296818},{"batb":[[1,1.3,25],[2,1.25,100]],"ltp":0.0,"tv":0.0,"id":40296819}]}]}
{"op":"mcm","clk":"11837185779","pt":1723476050901,"mc":[{"id":"1.231732748","rc":[{"batb":[[0,1.35,24.55],[1,1.34,7.71],[2,1.3,25]],"ltp":0.0,"tv":0.0,"id":40296818},{"batb":[[0,1.35,24.55],[1,1.34,5.92],[2,1.3,25]],"ltp":0.0,"tv":0.0,"id":40296819}]}]}
{"op":"mcm","clk":"11837192719","pt":1723476231922,"mc":[{"id":"1.231732748","rc":[{"batb":[[1,1.3,25],[2,1.26,5.92]],"ltp":0.0,"tv":0.0,"id":40296819}]}]}
{"op":"mcm","clk":"11837192738","pt":1723476232430,"mc":[{"id":"1.231732748","rc":[{"batb":[[1,1.3,25],[2,1.26,7.71]],"ltp":0.0,"tv":0.0,"id":40296818}]}]}
{"op":"mcm","clk":"11837263168","pt":1723477851379,"mc":[{"id":"1.231732748","rc":[{"batb":[[0,1.3,25],[1,1.26,7.71],[2,1.25,100]],"ltp":0.0,"tv":0.0,"id":40296818},{"batb":[[0,1.3,25],[1,1.26,5.92],[2,1.25,100]],"ltp":0.0,"tv":0.0,"id":40296819}]}]}
{"op":"mcm","clk":"11837265200","pt":1723477900734,"mc":[{"id":"1.231732748","rc":[{"batb":[[0,1.31,27.72],[1,1.3,25],[2,1.26,7.71]],"ltp":0.0,"tv":0.0,"id":40296818},{"batb":[[0,1.31,27.72],[1,1.3,25],[2,1.26,5.92]],"ltp":0.0,"tv":0.0,"id":40296819}]}]}
{"op":"mcm","clk":"11837267123","pt":1723477943552,"mc":[{"id":"1.231732748","rc":[{"batb":[[0,1.32,7.71],[1,1.31,27.72],[2,1.3,25]],"ltp":0.0,"tv":0.0,"id":40296818},{"batb":[[0,1.32,5.92],[1,1.31,27.72],[2,1.3,25]],"ltp":0.0,"tv":0.0,"id":40296819}]}]}
{"op":"mcm","clk":"11837358734","pt":1723479701007,"mc":[{"id":"1.231732748","rc":[{"batb":[[0,1.32,7.72],[1,1.3,25],[2,1.25,100]],"ltp":0.0,"tv":0.0,"id":40296818},{"batb":[[0,1.32,5.93],[1,1.31,27.74]],"ltp":0.0,"tv":0.0,"id":40296819}]}]}
{"op":"mcm","clk":"11837358745","pt":1723479701219,"mc":[{"id":"1.231732748","rc":[{"batb":[[1,1.3,25],[2,1.25,100]],"ltp":0.0,"tv":0.0,"id":40296819}]}]}
{"op":"mcm","clk":"11837360409","pt":1723479733775,"mc":[{"id":"1.231732748","rc":[{"batb":[[0,1.33,26.06],[1,1.32,7.72],[2,1.3,25]],"ltp":0.0,"tv":0.0,"id":40296818},{"batb":[[0,1.33,26.06],[1,1.32,5.93],[2,1.3,25]],"ltp":0.0,"tv":0.0,"id":40296819}]}]}
{"op":"mcm","clk":"11837442048","pt":1723481293932,"mc":[{"id":"1.231732748","rc":[{"batb":[[0,1.34,5.93],[1,1.33,26.06]],"ltp":0.0,"tv":0.0,"id":40296819}]}]}
{"op":"mcm","clk":"11837442070","pt":1723481294451,"mc":[{"id":"1.231732748","rc":[{"batb":[[0,1.34,7.72],[1,1.33,26.06]],"ltp":0.0,"tv":0.0,"id":40296818}]}]}
{"op":"mcm","clk":"11837450733","pt":1723481534253,"mc":[{"id":"1.231732748","rc":[{"batb":[[1,1.3,25],[2,1.25,100]],"ltp":0.0,"tv":0.0,"id":40296818},{"batb":[[1,1.3,25],[2,1.25,100]],"ltp":0.0,"tv":0.0,"id":40296819}]}]}
{"op":"mcm","clk":"11837451396","pt":1723481553971,"mc":[{"id":"1.231732748","rc":[{"batb":[[0,1.35,24.57],[1,1.34,5.93],[2,1.3,25]],"ltp":0.0,"tv":0.0,"id":40296819}]}]}
{"op":"mcm","clk":"11837451401","pt":1723481554074,"mc":[{"id":"1.231732748","rc":[{"batb":[[0,1.35,24.57],[1,1.34,7.72],[2,1.3,25]],"ltp":0.0,"tv":0.0,"id":40296818}]}]}
{"op":"mcm","clk":"11837534873","pt":1723482921749,"mc":[{"id":"1.231732748","rc":[{"batb":[[0,1.35,24.58],[1,1.34,7.73]],"ltp":0.0,"tv":0.0,"id":40296818},{"batb":[[0,1.35,24.58],[1,1.3,25],[2,1.26,5.93]],"ltp":0.0,"tv":0.0,"id":40296819}]}]}
{"op":"mcm","clk":"11837534907","pt":1723482922269,"mc":[{"id":"1.231732748","rc":[{"batb":[[1,1.3,25],[2,1.26,7.73]],"ltp":0.0,"tv":0.0,"id":40296818}]}]}
{"op":"mcm","clk":"11837569608","pt":1723483354529,"mc":[{"id":"1.231732748","rc":[{"batb":[[0,1.3,25],[1,1.26,7.73],[2,1.25,100]],"ltp":0.0,"tv":0.0,"id":40296818},{"batb":[[0,1.3,25],[1,1.26,5.93],[2,1.25,100]],"ltp":0.0,"tv":0.0,"id":40296819}]}]}
{"op":"mcm","clk":"11837579354","pt":1723483480436,"mc":[{"id":"1.231732748","rc":[{"batb":[[0,1.31,27.76],[1,1.3,25],[2,1.26,7.73]],"ltp":0.0,"tv":0.0,"id":40296818},{"batb":[[0,1.31,27.76],[1,1.3,25],[2,1.26,5.93]],"ltp":0.0,"tv":0.0,"id":40296819}]}]}
{"op":"mcm","clk":"11837580337","pt":1723483494183,"mc":[{"id":"1.231732748","rc":[{"batb":[[0,1.32,5],[1,1.31,27.76],[2,1.3,25]],"ltp":0.0,"tv":0.0,"id":40296818},{"batb":[[0,1.32,5],[1,1.31,27.76],[2,1.3,25]],"ltp":0.0,"tv":0.0,"id":40296819}]}]}
{"op":"mcm","clk":"11837666881","pt":1723484548783,"mc":[{"id":"1.231732748","rc":[{"batb":[[0,1.32,12.73]],"ltp":0.0,"tv":0.0,"id":40296818},{"batb":[[0,1.32,10.93]],"ltp":0.0,"tv":0.0,"id":40296819}]}]}
{"op":"mcm","clk":"11837719574","pt":1723485280941,"mc":[{"id":"1.231732748","rc":[{"batb":[[1,1.3,25],[2,1.25,100]],"ltp":0.0,"tv":0.0,"id":40296818},{"batb":[[1,1.3,25],[2,1.25,100]],"ltp":0.0,"tv":0.0,"id":40296819}]}]}
{"op":"mcm","clk":"11837724598","pt":1723485356923,"mc":[{"id":"1.231732748","rc":[{"batb":[[0,1.33,26.07],[1,1.32,12.73],[2,1.3,25]],"ltp":0.0,"tv":0.0,"id":40296818},{"batb":[[0,1.33,26.07],[1,1.32,10.93],[2,1.3,25]],"ltp":0.0,"tv":0.0,"id":40296819}]}]}
{"op":"mcm","clk":"11837786259","pt":1723486146832,"mc":[{"id":"1.231732748","rc":[{"batb":[[0,1.34,7.72],[1,1.33,26.08],[2,1.32,5]],"ltp":0.0,"tv":0.0,"id":40296818},{"batb":[[0,1.34,5.93],[1,1.33,26.08],[2,1.32,5]],"ltp":0.0,"tv":0.0,"id":40296819}]}]}
{"op":"mcm","clk":"11837890172","pt":1723487157222,"mc":[{"id":"1.231732748","rc":[{"batb":[[1,1.32,5],[2,1.3,25]],"ltp":0.0,"tv":0.0,"id":40296818},{"batb":[[1,1.32,5],[2,1.3,25]],"ltp":0.0,"tv":0.0,"id":40296819}]}]}
{"op":"mcm","clk":"11837894512","pt":1723487202449,"mc":[{"id":"1.231732748","rc":[{"batb":[[0,1.35,24.59],[1,1.34,7.72],[2,1.32,5]],"ltp":0.0,"tv":0.0,"id":40296818},{"batb":[[0,1.35,24.59],[1,1.34,5.93],[2,1.32,5]],"ltp":0.0,"tv":0.0,"id":40296819}]}]}
{"op":"mcm","clk":"11837939742","pt":1723487673765,"mc":[{"id":"1.231732748","rc":[{"batb":[[1,1.32,5],[2,1.3,25]],"ltp":0.0,"tv":0.0,"id":40296818},{"batb":[[1,1.32,5],[2,1.3,25]],"ltp":0.0,"tv":0.0,"id":40296819}]}]}
{"op":"mcm","clk":"11838030239","pt":1723488599083,"mc":[{"id":"1.231732748","rc":[{"batb":[[0,1.36,172],[1,1.35,24.59],[2,1.32,5]],"ltp":0.0,"tv":0.0,"id":40296818},{"batb":[[0,1.5,157.31],[1,1.35,24.59],[2,1.32,5]],"ltp":0.0,"tv":0.0,"id":40296819}]}]}
{"op":"mcm","clk":"11838059000","pt":1723489002882,"mc":[{"id":"1.231732748","rc":[{"batb":[[1,1.32,5],[2,1.3,25]],"ltp":0.0,"tv":0.0,"id":40296818},{"batb":[[1,1.32,5],[2,1.3,25]],"ltp":0.0,"tv":0.0,"id":40296819}]}]}
{"op":"mcm","clk":"11838066145","pt":1723489108716,"mc":[{"id":"1.231732748","rc":[{"batb":[[0,1.37,23.26],[1,1.36,172],[2,1.32,5]],"ltp":0.0,"tv":0.0,"id":40296818},{"batb":[[0,1.51,16.88],[1,1.5,157.31],[2,1.32,5]],"ltp":0.0,"tv":0.0,"id":40296819}]}]}
{"op":"mcm","clk":"11838071652","pt":1723489197781,"mc":[{"id":"1.231732748","rc":[{"batb":[[0,1.43,163.46],[1,1.37,23.26]],"ltp":0.0,"tv":0.0,"id":40296818},{"batb":[[0,1.63,144.61],[1,1.51,16.88]],"ltp":0.0,"tv":0.0,"id":40296819}]}]}
{"op":"mcm","clk":"11838073296","pt":1723489221741,"mc":[{"id":"1.231732748","rc":[{"batb":[[1,1.37,23.25]],"ltp":0.0,"tv":0.0,"id":40296818},{"batb":[[0,1.64,5.93],[1,1.63,144.61],[2,1.51,16.87]],"ltp":0.0,"tv":0.0,"id":40296819}]}]}
{"op":"mcm","clk":"11838073320","pt":1723489222151,"mc":[{"id":"1.231732748","rc":[{"batb":[[0,1.44,7.72],[1,1.43,163.46],[2,1.37,23.25]],"ltp":0.0,"tv":0.0,"id":40296818}]}]}
{"op":"mcm","clk":"11838080400","pt":1723489338661,"mc":[{"id":"1.231732748","rc":[{"batb":[[0,1.52,153.65],[1,1.44,7.72]],"ltp":0.0,"tv":0.0,"id":40296818},{"batb":[[0,1.68,140.25],[1,1.64,5.93]],"ltp":0.0,"tv":0.0,"id":40296819}]}]}
{"op":"mcm","clk":"11838175447","pt":1723490669347,"mc":[{"id":"1.231732748","rc":[{"batb":[[0,1.53,7.54],[1,1.52,153.65],[2,1.44,7.72]],"batl":[[0,2.46,4.66]],"ltp":0.0,"tv":0.0,"id":40296818},{"batb":[[0,1.69,6.89],[1,1.68,140.25],[2,1.64,5.93]],"ltp":0.0,"tv":0.0,"id":40296819}]}]}
{"op":"mcm","clk":"11838179328","pt":1723490718834,"mc":[{"id":"1.231732748","rc":[{"batb":[[0,1.54,151.63],[1,1.53,15.26],[2,1.37,23.25]],"ltp":0.0,"tv":0.0,"id":40296818},{"batb":[[0,1.7,138.58],[1,1.69,12.82],[2,1.51,16.87]],"ltp":0.0,"tv":0.0,"id":40296819}]}]}
{"op":"mcm","clk":"11838179468","pt":1723490720442,"mc":[{"id":"1.231732748","rc":[{"batb":[[1,1.53,7.72]],"ltp":0.0,"tv":0.0,"id":40296818},{"batb":[[1,1.69,5.93]],"ltp":0.0,"tv":0.0,"id":40296819}]}]}
{"op":"mcm","clk":"11838194157","pt":1723490908972,"mc":[{"id":"1.231732748","rc":[{"batb":[[2,1.32,5]],"ltp":0.0,"tv":0.0,"id":40296818}]}]}
{"op":"mcm","clk":"11838194192","pt":1723490909284,"mc":[{"id":"1.231732748","rc":[{"batb":[[2,1.32,5]],"ltp":0.0,"tv":0.0,"id":40296819}]}]}
{"op":"mcm","clk":"11838283774","pt":1723492044246,"mc":[{"id":"1.231732748","rc":[{"batb":[[0,1.55,7.45],[1,1.54,151.63],[2,1.53,7.72]],"batl":[[0,2.42,4.74]],"ltp":0.0,"tv":0.0,"id":40296818},{"batb":[[0,1.71,6.8],[1,1.7,138.58],[2,1.69,5.93]],"ltp":0.0,"tv":0.0,"id":40296819}]}]}
{"op":"mcm","clk":"11838293458","pt":1723492200548,"mc":[{"id":"1.231732748","rc":[{"batb":[[0,1.56,149.66],[1,1.55,7.45]],"ltp":0.0,"tv":0.0,"id":40296818},{"batb":[[0,1.72,136.95],[1,1.71,6.8]],"ltp":0.0,"tv":0.0,"id":40296819}]}]}
{"op":"mcm","clk":"11838293524","pt":1723492201741,"mc":[{"id":"1.231732748","rc":[{"batb":[[1,1.53,7.72],[2,1.32,5]],"ltp":0.0,"tv":0.0,"id":40296818},{"batb":[[1,1.69,5.93],[2,1.32,5]],"ltp":0.0,"tv":0.0,"id":40296819}]}]}
{"op":"mcm","clk":"11838294359","pt":1723492214756,"mc":[{"id":"1.231732748","rc":[{"batb":[[0,1.73,5.93],[1,1.72,136.95]],"ltp":0.0,"tv":0.0,"id":40296819}]}]}
{"op":"mcm","clk":"11838294387","pt":1723492215170,"mc":[{"id":"1.231732748","rc":[{"batb":[[0,1.57,7.72],[1,1.56,149.66]],"ltp":0.0,"tv":0.0,"id":40296818}]}]}
{"op":"mcm","clk":"11838296545","pt":1723492245969,"mc":[{"id":"1.231732748","rc":[{"batb":[[0,1.58,147.74],[1,1.57,7.72]],"ltp":0.0,"tv":0.0,"id":40296818},{"batb":[[0,1.74,135.36],[1,1.73,5.93]],"ltp":0.0,"tv":0.0,"id":40296819}]}]}
{"op":"mcm","clk":"11838341928","pt":1723493106821,"mc":[{"id":"1.231732748","rc":[{"batb":[[0,1.59,5],[1,1.58,147.74],[2,1.57,7.72]],"ltp":0.0,"tv":0.0,"id":40296818},{"batb":[[0,1.75,5],[1,1.74,135.36],[2,1.73,5.93]],"ltp":0.0,"tv":0.0,"id":40296819}]}]}
{"op":"mcm","clk":"11838358310","pt":1723493576912,"mc":[{"id":"1.231732748","rc":[{"batb":[[0,1.59,12.5]],"batl":[[0,2.34,5.09]],"ltp":0.0,"tv":0.0,"id":40296818},{"batb":[[0,1.75,11.89]],"ltp":0.0,"tv":0.0,"id":40296819}]}]}
{"op":"mcm","clk":"11838358325","pt":1723493577322,"mc":[{"id":"1.231732748","rc":[{"batb":[[0,1.6,145.87],[1,1.59,12.5]],"ltp":0.0,"tv":0.0,"id":40296818},{"batb":[[0,1.77,112.42],[1,1.75,11.89]],"ltp":0.0,"tv":0.0,"id":40296819}]}]}
{"op":"mcm","clk":"11838358399","pt":1723493579637,"mc":[{"id":"1.231732748","rc":[{"batb":[[1,1.59,5]],"ltp":0.0,"tv":0.0,"id":40296818},{"batb":[[1,1.75,5]],"ltp":0.0,"tv":0.0,"id":40296819}]}]}
{"op":"mcm","clk":"11838362188","pt":1723493697771,"mc":[{"id":"1.231732748","rc":[{"batb":[[2,1.3,25]],"ltp":0.0,"tv":0.0,"id":40296819}]}]}
{"op":"mcm","clk":"11838362205","pt":1723493698252,"mc":[{"id":"1.231732748","rc":[{"batb":[[0,1.61,7.72],[1,1.6,145.87],[2,1.59,5]],"ltp":0.0,"tv":0.0,"id":40296818}]}]}
{"op":"mcm","clk":"11838363575","pt":1723493737185,"mc":[{"id":"1.231732748","rc":[{"batb":[[0,1.62,144.05],[1,1.61,7.72]],"ltp":0.0,"tv":0.0,"id":40296818}]}]}
{"op":"mcm","clk":"11838364471","pt":1723493763216,"mc":[{"id":"1.231732748","rc":[{"batb":[[2,1.25,100]],"ltp":0.0,"tv":0.0,"id":40296819}]}]}
{"op":"mcm","clk":"11838409109","pt":1723494901036,"mc":[{"id":"1.231732748","rc":[{"batb":[[0,1.78,5.52],[1,1.77,112.42],[2,1.75,5]],"ltp":0.0,"tv":0.0,"id":40296819}]}]}
{"op":"mcm","clk":"11838411606","pt":1723494969955,"mc":[{"id":"1.231732748","rc":[{"batb":[[1,1.75,5],[2,1.25,100]],"ltp":0.0,"tv":0.0,"id":40296819}]}]}
{"op":"mcm","clk":"11838411615","pt":1723494970116,"mc":[{"id":"1.231732748","rc":[{"batb":[[0,1.79,111.15],[1,1.78,5.52],[2,1.75,5]],"ltp":0.0,"tv":0.0,"id":40296819}]}]}
{"op":"mcm","clk":"11838411648","pt":1723494971250,"mc":[{"id":"1.231732748","rc":[{"batb":[[1,1.75,5],[2,1.25,100]],"ltp":0.0,"tv":0.0,"id":40296819}]}]}
{"op":"mcm","clk":"11838414927","pt":1723495071225,"mc":[{"id":"1.231732748","rc":[{"batb":[[0,1.63,7.07],[1,1.62,144.05],[2,1.61,7.72]],"ltp":0.0,"tv":0.0,"id":40296818},{"batl":[[0,2.6,4.38]],"ltp":0.0,"tv":0.0,"id":40296819}]}]}
{"op":"mcm","clk":"11838418247","pt":1723495179014,"mc":[{"id":"1.231732748","rc":[{"batb":[[0,1.65,70.53],[1,1.63,14.79],[2,1.59,5]],"ltp":0.0,"tv":0.0,"id":40296818}]}]}
{"op":"mcm","clk":"11838418261","pt":1723495179429,"mc":[{"id":"1.231732748","rc":[{"batb":[[1,1.63,7.72]],"ltp":0.0,"tv":0.0,"id":40296818}]}]}
{"op":"mcm","clk":"11838458104","pt":1723496301018,"mc":[{"id":"1.231732748","rc":[{"batl":[[0,2.26,4.28]],"ltp":0.0,"tv":0.0,"id":40296818},{"batb":[[0,1.8,5.45],[1,1.79,111.15],[2,1.75,5]],"ltp":0.0,"tv":0.0,"id":40296819}]}]}
{"op":"mcm","clk":"11838468661","pt":1723496589535,"mc":[{"id":"1.231732748","rc":[{"batl":[[0,2.26,4.28]],"ltp":0.0,"tv":0.0,"id":40296818},{"batb":[[0,1.81,90.69],[1,1.8,5.46]],"ltp":0.0,"tv":0.0,"id":40296819}]}]}
{"op":"mcm","clk":"11838468695","pt":1723496590145,"mc":[{"id":"1.231732748","rc":[{"batb":[[1,1.75,5],[2,1.25,100]],"ltp":0.0,"tv":0.0,"id":40296819}]}]}
{"op":"mcm","clk":"11838471846","pt":1723496675994,"mc":[{"id":"1.231732748","rc":[{"batb":[[1,1.59,5],[2,1.25,100]],"ltp":0.0,"tv":0.0,"id":40296818}]}]}
{"op":"mcm","clk":"11838513899","pt":1723497912412,"mc":[{"id":"1.231732748","rc":[{"batb":[[0,1.82,4.45],[1,1.81,90.69],[2,1.75,5]],"ltp":0.0,"tv":0.0,"id":40296819}]}]}
{"op":"mcm","clk":"11838992073","pt":1723506486197,"mc":[{"id":"1.231732748","rc":[{"batb":[[0,1.59,5],[1,1.25,100],[2,1.05,25000]],"ltp":0.0,"tv":0.0,"id":40296818},{"batb":[[1,1.75,5],[2,1.25,100]],"ltp":0.0,"tv":0.0,"id":40296819}]}]}
{"op":"mcm","clk":"11838992150","pt":1723506487282,"mc":[{"id":"1.231732748","rc":[{"batb":[[0,1.75,5],[1,1.25,100],[2,1.05,25000]],"ltp":0.0,"tv":0.0,"id":40296819}]}]}
{"op":"mcm","clk":"11839534481","pt":1723521789115,"mc":[{"id":"1.231732748","rc":[{"batb":[[0,1.6,2.73],[1,1.59,5],[2,1.25,100]],"ltp":0.0,"tv":0.0,"id":40296818}]}]}
{"op":"mcm","clk":"11839534744","pt":1723521801120,"mc":[{"id":"1.231732748","rc":[{"batb":[[0,1.76,2.73],[1,1.75,5],[2,1.25,100]],"ltp":0.0,"tv":0.0,"id":40296819}]}]}
{"op":"mcm","clk":"11839699002","pt":1723527322335,"mc":[{"id":"1.231732748","rc":[{"batb":[[0,1.65,444],[1,1.6,2.73],[2,1.59,5]],"ltp":0.0,"tv":0.0,"id":40296818}]}]}
{"op":"mcm","clk":"11839699184","pt":1723527327311,"mc":[{"id":"1.231732748","rc":[{"batb":[[0,1.66,444]],"ltp":0.0,"tv":0.0,"id":40296818}]}]}
{"op":"mcm","clk":"11839699615","pt":1723527341313,"mc":[{"id":"1.231732748","rc":[{"batb":[[0,1.85,444],[1,1.76,2.73],[2,1.75,5]],"ltp":0.0,"tv":0.0,"id":40296819}]}]}
{"op":"mcm","clk":"11839746415","pt":1723528653254,"mc":[{"id":"1.231732748","rc":[{"batb":[[0,1.67,16.91],[1,1.66,444],[2,1.6,2.73]],"ltp":0.0,"tv":0.0,"id":40296818},{"batl":[[0,2.5,14.36]],"ltp":0.0,"tv":0.0,"id":40296819}]}]}
{"op":"mcm","clk":"11839747140","pt":1723528673367,"mc":[{"id":"1.231732748","rc":[{"batl":[[0,2.16,16.77]],"ltp":0.0,"tv":0.0,"id":40296818},{"batb":[[0,1.86,16.77],[1,1.85,444],[2,1.76,2.73]],"ltp":0.0,"tv":0.0,"id":40296819}]}]}
{"op":"mcm","clk":"11839752187","pt":1723528823873,"mc":[{"id":"1.231732748","rc":[{"batb":[[0,1.67,23.8]],"batl":[[0,2.16,16.77]],"ltp":0.0,"tv":0.0,"id":40296818},{"batb":[[0,1.86,22.69]],"batl":[[0,2.5,14.36]],"ltp":0.0,"tv":0.0,"id":40296819}]}]}
{"op":"mcm","clk":"11839951994","pt":1723534974914,"mc":[{"id":"1.231732748","rc":[{"batb":[[0,1.67,23.75],[2,1.6,2.72]],"batl":[[0,2.16,16.73]],"ltp":0.0,"tv":0.0,"id":40296818},{"batb":[[0,1.86,22.63],[2,1.76,2.72]],"batl":[[0,2.5,14.32]],"ltp":0.0,"tv":0.0,"id":40296819}]}]}
{"op":"mcm","clk":"11839961392","pt":1723535227445,"mc":[{"id":"1.231732748","rc":[{"trd":[[1.86,0.56]],"batb":[[0,1.86,22.35]],"ltp":1.86,"tv":0.56,"id":40296819}],"tv":0.56}]}
{"op":"mcm","clk":"11839962494","pt":1723535277010,"mc":[{"id":"1.231732748","rc":[{"batl":[[0,1.69,2.7],[1,2.16,16.73]],"ltp":0.0,"tv":0.0,"id":40296818}]}]}
{"op":"mcm","clk":"11839962684","pt":1723535283722,"mc":[{"id":"1.231732748","rc":[{"trd":[[1.69,5.4]],"batb":[[0,1.69,135.76],[1,1.67,23.75],[2,1.66,444]],"batl":[[0,2.16,16.73],[1,2.16,0]],"ltp":1.69,"tv":5.4,"id":40296818}],"tv":5.96}]}
{"op":"mcm","clk":"11839962711","pt":1723535284538,"mc":[{"id":"1.231732748","rc":[{"batb":[[1,1.67,6.88]],"ltp":1.69,"tv":5.4,"id":40296818}]}]}
{"op":"mcm","clk":"11839962912","pt":1723535292436,"mc":[{"id":"1.231732748","rc":[{"trd":[[2.16,4.22]],"batl":[[0,2.16,14.62]],"ltp":2.16,"tv":9.62,"id":40296818}],"tv":10.18}]}
{"op":"mcm","clk":"11839963183","pt":1723535303951,"mc":[{"id":"1.231732748","rc":[{"batl":[[0,1.89,2.13]],"ltp":1.86,"tv":0.56,"id":40296819}]}]}
{"op":"mcm","clk":"11839963461","pt":1723535313953,"mc":[{"id":"1.231732748","rc":[{"trd":[[1.89,4.26]],"batb":[[0,1.89,136.33],[1,1.86,22.35],[2,1.85,444]],"ltp":1.89,"tv":4.82,"id":40296819}],"tv":14.44}]}
{"op":"mcm","clk":"11839963513","pt":1723535315748,"mc":[{"id":"1.231732748","rc":[{"batb":[[1,1.86,5.9]],"ltp":1.89,"tv":4.82,"id":40296819}]}]}
{"op":"mcm","clk":"11839963554","pt":1723535318149,"mc":[{"id":"1.231732748","rc":[{"batb":[[0,1.7,2.68],[1,1.69,135.76],[2,1.67,6.88]],"ltp":2.16,"tv":9.62,"id":40296818}]}]}
{"op":"mcm","clk":"11839963683","pt":1723535324454,"mc":[{"id":"1.231732748","rc":[{"trd":[[1.7,4.74]],"batb":[[0,1.69,136.07],[1,1.67,6.88],[2,1.66,444]],"ltp":1.7,"tv":14.36,"id":40296818}],"tv":19.19}]}
{"op":"mcm","clk":"11839963720","pt":1723535326191,"mc":[{"id":"1.231732748","rc":[{"batb":[[0,1.69,135.76]],"ltp":1.7,"tv":14.36,"id":40296818}]}]}
{"op":"mcm","clk":"11839963781","pt":1723535329566,"mc":[{"id":"1.231732748","rc":[{"batb":[[0,1.67,6.88],[1,1.66,444],[2,1.6,2.72]],"ltp":1.7,"tv":14.36,"id":40296818},{"batb":[[0,1.86,5.9],[1,1.85,444],[2,1.76,2.72]],"ltp":1.89,"tv":4.82,"id":40296819}]}]}
{"op":"mcm","clk":"11839964960","pt":1723535405088,"mc":[{"id":"1.231732748","rc":[{"batl":[[0,1.69,1.42]],"ltp":1.7,"tv":14.36,"id":40296818}]}]}
{"op":"mcm","clk":"11839965080","pt":1723535410201,"mc":[{"id":"1.231732748","rc":[{"trd":[[1.69,8.24]],"batb":[[0,1.69,26.27],[1,1.67,6.88],[2,1.66,444]],"ltp":1.69,"tv":17.21,"id":40296818}],"tv":22.03}]}
{"op":"mcm","clk":"11839965184","pt":1723535415779,"mc":[{"id":"1.231732748","rc":[{"batb":[[0,1.67,6.88],[1,1.66,444],[2,1.6,2.72]],"ltp":1.69,"tv":17.21,"id":40296818}]}]}
{"op":"mcm","clk":"11839965271","pt":1723535421979,"mc":[{"id":"1.231732748","rc":[{"trd":[[1.86,3.14]],"batb":[[0,1.86,4.62]],"ltp":1.86,"tv":7.4,"id":40296819}],"tv":24.61}]}
{"op":"mcm","clk":"11839985963","pt":1723536083113,"mc":[{"id":"1.231732748","rc":[{"trd":[[1.69,8.24],[1.7,4.74],[2.16,4.22]],"batb":[[0,1.67,24.13],[2,1.6,2.72]],"batl":[[0,2.16,17.25]],"ltp":1.69,"tv":17.2,"id":40296818},{"trd":[[1.86,3.14],[1.89,4.26]],"batb":[[0,1.86,21.63],[2,1.76,2.72]],"batl":[[0,2.5,14.58]],"ltp":1.86,"tv":7.4,"id":40296819}],"tv":24.6}]}
{"op":"mcm","clk":"11840127636","pt":1723540374899,"mc":[{"id":"1.231732748","rc":[{"trd":[[1.69,8.25],[1.7,4.74],[2.16,4.22]],"batb":[[0,1.67,24.14],[2,1.6,2.73]],"batl":[[0,2.16,17.26]],"ltp":1.69,"tv":17.21,"id":40296818},{"trd":[[1.86,3.14],[1.89,4.26]],"batb":[[0,1.86,21.64],[2,1.76,2.73]],"batl":[[0,2.5,14.59]],"ltp":1.86,"tv":7.4,"id":40296819}],"tv":24.62}]}
{"op":"mcm","clk":"11840144722","pt":1723540714171,"mc":[{"id":"1.231732748","rc":[{"batb":[[2,1.59,5]],"ltp":1.69,"tv":17.21,"id":40296818}]}]}
{"op":"mcm","clk":"11840144916","pt":1723540719303,"mc":[{"id":"1.231732748","rc":[{"batb":[[2,1.75,5]],"ltp":1.86,"tv":7.4,"id":40296819}]}]}
{"op":"mcm","clk":"11840397858","pt":1723545774904,"mc":[{"id":"1.231732748","rc":[{"batb":[[0,1.67,24.15]],"batl":[[0,2.16,17.26]],"ltp":1.69,"tv":17.21,"id":40296818},{"batb":[[0,1.86,21.64]],"batl":[[0,2.5,14.59]],"ltp":1.86,"tv":7.4,"id":40296819}],"tv":24.62}]}
{"op":"mcm","clk":"11840491777","pt":1723547529897,"mc":[{"id":"1.231732748","rc":[{"trd":[[1.69,8.25],[1.7,4.75],[2.16,4.23]],"batb":[[0,1.74,17.32],[1,1.67,24.17],[2,1.66,444]],"batl":[[0,2.16,17.28]],"ltp":1.69,"tv":17.22,"id":40296818},{"trd":[[1.86,3.15],[1.89,4.27]],"batb":[[0,1.86,21.66]],"batl":[[0,2.5,14.6]],"ltp":1.86,"tv":7.41,"id":40296819}],"tv":24.63}]}
{"op":"mcm","clk":"11840491863","pt":1723547530987,"mc":[{"id":"1.231732748","rc":[{"batb":[[1,1.67,6.89]],"ltp":1.69,"tv":17.22,"id":40296818}]}]}
{"op":"mcm","clk":"11840716933","pt":1723551174881,"mc":[{"id":"1.231732748","rc":[{"trd":[[1.69,8.25],[1.7,4.75],[2.16,4.23]],"batb":[[1,1.67,6.89]],"batl":[[0,2.16,17.28]],"ltp":1.69,"tv":17.21,"id":40296818},{"trd":[[1.86,3.14],[1.89,4.26]],"ltp":1.86,"tv":7.4,"id":40296819}],"tv":24.62}]}
{"op":"mcm","clk":"11840885664","pt":1723553700515,"mc":[{"id":"1.231732748","rc":[{"trd":[[1.86,7.15]],"batb":[[0,1.86,19.66]],"ltp":1.86,"tv":11.4,"id":40296819}],"tv":28.62}]}
{"op":"mcm","clk":"11840897712","pt":1723553948830,"mc":[{"id":"1.231732748","rc":[{"trd":[[1.86,11.15]],"batb":[[0,1.86,17.66]],"ltp":1.86,"tv":15.41,"id":40296819}],"tv":32.63}]}
{"op":"mcm","clk":"11840916491","pt":1723554295956,"mc":[{"id":"1.231732748","rc":[{"trd":[[1.7,4.75],[2.16,4.22]],"batb":[[0,1.75,6.88],[1,1.74,17.32]],"batl":[[0,2.16,17.27]],"ltp":1.69,"tv":17.21,"id":40296818},{"trd":[[1.86,11.14]],"batb":[[0,1.86,17.65]],"ltp":1.86,"tv":15.4,"id":40296819}],"tv":32.62}]}
{"op":"mcm","clk":"11840978512","pt":1723555403958,"mc":[{"id":"1.231732748","rc":[{"trd":[[1.86,13.02]],"batb":[[0,1.86,16.71]],"ltp":1.86,"tv":17.28,"id":40296819}],"tv":34.5}]}
{"op":"mcm","clk":"11840985496","pt":1723555546465,"mc":[{"id":"1.231732748","rc":[{"trd":[[1.86,16.78]],"batb":[[0,1.86,14.83]],"ltp":1.86,"tv":21.04,"id":40296819}],"tv":38.25}]}
{"op":"mcm","clk":"11840996685","pt":1723555782932,"mc":[{"id":"1.231732748","rc":[{"batb":[[1,1.81,444]],"ltp":1.86,"tv":21.04,"id":40296819}]}]}
{"op":"mcm","clk":"11840996732","pt":1723555783968,"mc":[{"id":"1.231732748","rc":[{"batb":[[0,1.81,444],[1,1.75,5],[2,1.74,17.32]],"ltp":1.86,"tv":21.04,"id":40296819}]}]}
{"op":"mcm","clk":"11840996820","pt":1723555785836,"mc":[{"id":"1.231732748","rc":[{"batl":[[0,2.34,1.97]],"ltp":1.86,"tv":21.04,"id":40296819}]}]}
{"op":"mcm","clk":"11840997772","pt":1723555804775,"mc":[{"id":"1.231732748","rc":[{"batb":[[0,1.82,6.93],[1,1.81,444],[2,1.75,5]],"ltp":1.86,"tv":21.04,"id":40296819}]}]}
{"op":"mcm","clk":"11841033547","pt":1723556506239,"mc":[{"id":"1.231732748","rc":[{"batl":[[0,2.22,16.74]],"ltp":1.69,"tv":17.21,"id":40296818}]}]}
{"op":"mcm","clk":"11841277843","pt":1723561974884,"mc":[{"id":"1.231732748","rc":[{"trd":[[1.69,8.24],[1.7,4.74],[2.16,4.22]],"batb":[[0,1.75,6.87]],"batl":[[0,2.22,16.74]],"ltp":1.69,"tv":17.2,"id":40296818},{"trd":[[1.86,16.77],[1.89,4.26]],"batb":[[0,1.82,6.93]],"ltp":1.86,"tv":21.02,"id":40296819}],"tv":38.23}]}
{"op":"mcm","clk":"11841634010","pt":1723566210869,"mc":[{"id":"1.231732748","rc":[{"trd":[[1.69,8.24],[1.7,4.74],[2.16,4.22]],"batb":[[0,1.75,6.87],[2,1.59,5]],"batl":[[0,2.22,16.73]],"ltp":1.69,"tv":17.2,"id":40296818},{"trd":[[1.86,16.76]],"batb":[[0,1.82,6.92],[1,1.75,5],[2,1.74,17.32]],"batl":[[0,2.34,1.97]],"ltp":1.86,"tv":21.02,"id":40296819}],"tv":38.22}]}
{"op":"mcm","clk":"11841700475","pt":1723566834659,"mc":[{"id":"1.231732748","rc":[{"batb":[[0,1.75,5],[1,1.74,17.32],[2,1.26,6.92]],"ltp":1.86,"tv":21.02,"id":40296819}]}]}
{"op":"mcm","clk":"11841703973","pt":1723566865775,"mc":[{"id":"1.231732748","rc":[{"batb":[[0,1.8,444],[1,1.75,5],[2,1.74,17.32]],"ltp":1.86,"tv":21.02,"id":40296819}]}]}
{"op":"mcm","clk":"11841789635","pt":1723567587739,"mc":[{"id":"1.231732748","rc":[{"batl":[[0,2.24,17.12]],"ltp":1.69,"tv":17.2,"id":40296818}]}]}
{"op":"mcm","clk":"11841802400","pt":1723567715866,"mc":[{"id":"1.231732748","rc":[{"batb":[[2,1.25,100]],"ltp":1.69,"tv":17.2,"id":40296818},{"batb":[[1,1.74,17.32],[2,1.26,6.92]],"ltp":1.86,"tv":21.02,"id":40296819}]}]}
{"op":"mcm","clk":"11841869358","pt":1723568419577,"mc":[{"id":"1.231732748","rc":[{"trd":[[1.69,8.25],[1.7,4.75],[2.16,4.22]],"batb":[[0,1.75,6.86]],"batl":[[0,2.24,17.13]],"ltp":1.69,"tv":17.21,"id":40296818},{"trd":[[1.86,16.75],[1.89,4.26]],"batb":[[0,1.81,6.91],[1,1.8,444],[2,1.74,17.32]],"ltp":1.86,"tv":21.01,"id":40296819}],"tv":38.23}]}
{"op":"mcm","clk":"11841937699","pt":1723569148081,"mc":[{"id":"1.231732748","rc":[{"batb":[[0,2.16,3.89],[1,1.75,6.86],[2,1.74,17.32]],"ltp":1.69,"tv":17.21,"id":40296818}]}]}
{"op":"mcm","clk":"11841938589","pt":1723569156901,"mc":[{"id":"1.231732748","rc":[{"batb":[[0,1.75,6.86],[1,1.74,17.32],[2,1.25,100]],"ltp":1.69,"tv":17.21,"id":40296818}]}]}
{"op":"mcm","clk":"11841998733","pt":1723569804565,"mc":[{"id":"1.231732748","rc":[{"batb":[[0,2.14,3.89],[1,1.75,6.86],[2,1.74,17.32]],"ltp":1.69,"tv":17.21,"id":40296818}]}]}
{"op":"mcm","clk":"11841999137","pt":1723569809236,"mc":[{"id":"1.231732748","rc":[{"trd":[[2.14,7.23]],"batb":[[0,1.75,7.14],[1,1.74,17.32],[2,1.25,100]],"ltp":2.14,"tv":24.44,"id":40296818}],"tv":45.45}]}
{"op":"mcm","clk":"11841999554","pt":1723569813662,"mc":[{"id":"1.231732748","rc":[{"batb":[[0,1.75,6.86]],"ltp":2.14,"tv":24.44,"id":40296818}]}]}
{"op":"mcm","clk":"11842004148","pt":1723569870628,"mc":[{"id":"1.231732748","rc":[{"batb":[[0,2.26,3.89],[1,1.81,6.91],[2,1.8,444]],"ltp":1.86,"tv":21.01,"id":40296819}]}]}
{"op":"mcm","clk":"11842004543","pt":1723569875811,"mc":[{"id":"1.231732748","rc":[{"batb":[[0,1.76,10],[1,1.75,6.86],[2,1.74,17.32]],"ltp":2.14,"tv":24.44,"id":40296818},{"trd":[[2.26,7.23]],"batb":[[0,1.82,10.28]],"ltp":2.26,"tv":28.24,"id":40296819}],"tv":52.68}]}
{"op":"mcm","clk":"11842004680","pt":1723569877621,"mc":[{"id":"1.231732748","rc":[{"batb":[[0,1.82,10]],"ltp":2.26,"tv":28.24,"id":40296819}]}]}
{"op":"mcm","clk":"11842004841","pt":1723569879528,"mc":[{"id":"1.231732748","rc":[{"batb":[[0,1.75,6.86],[1,1.74,17.32],[2,1.25,100]],"ltp":2.14,"tv":24.44,"id":40296818},{"batb":[[0,1.81,6.91],[1,1.8,444],[2,1.74,17.32]],"ltp":2.26,"tv":28.24,"id":40296819}]}]}
{"op":"mcm","clk":"11842013922","pt":1723569988768,"mc":[{"id":"1.231732748","rc":[{"batb":[[0,1.76,10],[1,1.75,6.86],[2,1.74,17.32]],"ltp":2.14,"tv":24.44,"id":40296818},{"batb":[[0,1.82,10],[1,1.81,6.91],[2,1.8,444]],"ltp":2.26,"tv":28.24,"id":40296819}]}]}
{"op":"mcm","clk":"11842014464","pt":1723569994780,"mc":[{"id":"1.231732748","rc":[{"batb":[[0,1.75,6.86],[1,1.74,17.32],[2,1.25,100]],"ltp":2.14,"tv":24.44,"id":40296818},{"batb":[[0,1.81,6.91],[1,1.8,444],[2,1.74,17.32]],"ltp":2.26,"tv":28.24,"id":40296819}]}]}
{"op":"mcm","clk":"11842249009","pt":1723572336381,"mc":[{"id":"1.231732748","rc":[{"trd":[[1.69,8.25],[2.14,7.22]],"batb":[[0,1.76,10],[1,1.75,6.85],[2,1.74,17.32]],"batl":[[0,2.24,17.12]],"ltp":2.14,"tv":24.44,"id":40296818},{"trd":[[1.86,16.75],[1.89,4.27],[2.26,7.22]],"batb":[[0,1.82,10],[1,1.81,6.91],[2,1.8,444]],"ltp":2.26,"tv":28.23,"id":40296819}],"tv":52.67}]}
{"op":"mcm","clk":"11842249521","pt":1723572340346,"mc":[{"id":"1.231732748","rc":[{"batb":[[0,1.75,6.85],[1,1.74,17.32],[2,1.25,100]],"ltp":2.14,"tv":24.44,"id":40296818},{"batb":[[0,1.81,6.91],[1,1.8,444],[2,1.74,17.32]],"ltp":2.26,"tv":28.23,"id":40296819}]}]}
{"op":"mcm","clk":"11842249850","pt":1723572343656,"mc":[{"id":"1.231732748","rc":[{"batb":[[0,1.77,10],[1,1.75,6.85],[2,1.74,17.32]],"ltp":2.14,"tv":24.44,"id":40296818},{"batb":[[0,1.83,10],[1,1.81,6.91],[2,1.8,444]],"ltp":2.26,"tv":28.23,"id":40296819}]}]}
{"op":"mcm","clk":"11842250819","pt":1723572354167,"mc":[{"id":"1.231732748","rc":[{"batb":[[0,1.75,6.85],[1,1.74,17.32],[2,1.25,100]],"ltp":2.14,"tv":24.44,"id":40296818},{"batb":[[0,1.81,6.91],[1,1.8,444],[2,1.74,17.32]],"ltp":2.26,"tv":28.23,"id":40296819}]}]}
{"op":"mcm","clk":"11842251243","pt":1723572358557,"mc":[{"id":"1.231732748","rc":[{"batb":[[0,1.76,10],[1,1.75,6.85],[2,1.74,17.32]],"ltp":2.14,"tv":24.44,"id":40296818},{"batb":[[0,1.82,10],[1,1.81,6.91],[2,1.8,444]],"ltp":2.26,"tv":28.23,"id":40296819}]}]}
{"op":"mcm","clk":"11842251982","pt":1723572364977,"mc":[{"id":"1.231732748","rc":[{"batb":[[0,1.75,6.85],[1,1.74,17.32],[2,1.25,100]],"ltp":2.14,"tv":24.44,"id":40296818},{"batb":[[0,1.81,6.91],[1,1.8,444],[2,1.74,17.32]],"ltp":2.26,"tv":28.23,"id":40296819}]}]}
{"op":"mcm","clk":"11842446443","pt":1723574122696,"mc":[{"id":"1.231732748","rc":[{"batb":[[0,1.76,10],[1,1.75,6.85],[2,1.74,17.32]],"ltp":2.14,"tv":24.44,"id":40296818},{"batb":[[0,1.82,10],[1,1.81,6.91],[2,1.8,444]],"ltp":2.26,"tv":28.23,"id":40296819}]}]}
{"op":"mcm","clk":"11842446916","pt":1723574126732,"mc":[{"id":"1.231732748","rc":[{"batb":[[0,1.75,6.85],[1,1.74,17.32],[2,1.25,100]],"ltp":2.14,"tv":24.44,"id":40296818},{"batb":[[0,1.81,6.91],[1,1.8,444],[2,1.74,17.32]],"ltp":2.26,"tv":28.23,"id":40296819}]}]}
{"op":"mcm","clk":"11842448250","pt":1723574137785,"mc":[{"id":"1.231732748","rc":[{"batb":[[0,1.76,10],[1,1.75,6.85],[2,1.74,17.32]],"ltp":2.14,"tv":24.44,"id":40296818},{"batb":[[0,1.82,10],[1,1.81,6.91],[2,1.8,444]],"ltp":2.26,"tv":28.23,"id":40296819}]}]}
{"op":"mcm","clk":"11842448682","pt":1723574141337,"mc":[{"id":"1.231732748","rc":[{"batb":[[0,1.75,6.85],[1,1.74,17.32],[2,1.25,100]],"ltp":2.14,"tv":24.44,"id":40296818},{"batb":[[0,1.81,6.91],[1,1.8,444],[2,1.74,17.32]],"ltp":2.26,"tv":28.23,"id":40296819}]}]}
{"op":"mcm","clk":"11842473716","pt":1723574352632,"mc":[{"id":"1.231732748","rc":[{"batb":[[0,1.76,10],[1,1.75,6.85],[2,1.74,17.32]],"ltp":2.14,"tv":24.44,"id":40296818},{"batb":[[0,1.82,10],[1,1.81,6.91],[2,1.8,444]],"ltp":2.26,"tv":28.23,"id":40296819}]}]}
{"op":"mcm","clk":"11842474096","pt":1723574356121,"mc":[{"id":"1.231732748","rc":[{"batb":[[0,1.75,6.85],[1,1.74,17.32],[2,1.25,100]],"ltp":2.14,"tv":24.44,"id":40296818},{"batb":[[0,1.81,6.91],[1,1.8,444],[2,1.74,17.32]],"ltp":2.26,"tv":28.23,"id":40296819}]}]}
{"op":"mcm","clk":"11842491776","pt":1723574495687,"mc":[{"id":"1.231732748","rc":[{"batb":[[0,1.76,10],[1,1.75,6.85],[2,1.74,17.32]],"ltp":2.14,"tv":24.44,"id":40296818},{"batb":[[0,1.82,10],[1,1.81,6.91],[2,1.8,444]],"ltp":2.26,"tv":28.23,"id":40296819}]}]}
{"op":"mcm","clk":"11842492275","pt":1723574499279,"mc":[{"id":"1.231732748","rc":[{"batb":[[0,1.75,6.85],[1,1.74,17.32],[2,1.25,100]],"ltp":2.14,"tv":24.44,"id":40296818},{"batb":[[0,1.81,6.91],[1,1.8,444],[2,1.74,17.32]],"ltp":2.26,"tv":28.23,"id":40296819}]}]}
{"op":"mcm","clk":"11842516704","pt":1723574678610,"mc":[{"id":"1.231732748","rc":[{"batb":[[0,1.76,10],[1,1.75,6.85],[2,1.74,17.32]],"ltp":2.14,"tv":24.44,"id":40296818},{"batb":[[0,1.82,10],[1,1.81,6.91],[2,1.8,444]],"ltp":2.26,"tv":28.23,"id":40296819}]}]}
{"op":"mcm","clk":"11842517233","pt":1723574682611,"mc":[{"id":"1.231732748","rc":[{"batb":[[0,1.75,6.85],[1,1.74,17.32],[2,1.25,100]],"ltp":2.14,"tv":24.44,"id":40296818},{"batb":[[0,1.81,6.91],[1,1.8,444],[2,1.74,17.32]],"ltp":2.26,"tv":28.23,"id":40296819}]}]}
{"op":"mcm","clk":"11842530983","pt":1723574767306,"mc":[{"id":"1.231732748","rc":[{"batb":[[0,1.76,10],[1,1.75,6.85],[2,1.74,17.32]],"ltp":2.14,"tv":24.44,"id":40296818},{"batb":[[0,1.82,10],[1,1.81,6.91],[2,1.8,444]],"ltp":2.26,"tv":28.23,"id":40296819}]}]}
{"op":"mcm","clk":"11842531565","pt":1723574770768,"mc":[{"id":"1.231732748","rc":[{"batb":[[0,1.75,6.85],[1,1.74,17.32],[2,1.25,100]],"ltp":2.14,"tv":24.44,"id":40296818},{"batb":[[0,1.81,6.91],[1,1.8,444],[2,1.74,17.32]],"ltp":2.26,"tv":28.23,"id":40296819}]}]}
{"op":"mcm","clk":"11842551245","pt":1723574890947,"mc":[{"id":"1.231732748","rc":[{"batb":[[0,1.76,10],[1,1.75,6.85],[2,1.74,17.32]],"ltp":2.14,"tv":24.44,"id":40296818},{"batb":[[0,1.82,10],[1,1.81,6.91],[2,1.8,444]],"ltp":2.26,"tv":28.23,"id":40296819}]}]}
{"op":"mcm","clk":"11842551881","pt":1723574894870,"mc":[{"id":"1.231732748","rc":[{"batb":[[0,1.75,6.85],[1,1.74,17.32],[2,1.25,100]],"ltp":2.14,"tv":24.44,"id":40296818},{"batb":[[0,1.81,6.91],[1,1.8,444],[2,1.74,17.32]],"ltp":2.26,"tv":28.23,"id":40296819}]}]}
{"op":"mcm","clk":"11842560093","pt":1723574943621,"mc":[{"id":"1.231732748","rc":[{"batb":[[0,1.76,10],[1,1.75,6.85],[2,1.74,17.32]],"ltp":2.14,"tv":24.44,"id":40296818},{"batb":[[0,1.82,10],[1,1.81,6.91],[2,1.8,444]],"ltp":2.26,"tv":28.23,"id":40296819}]}]}
{"op":"mcm","clk":"11842560648","pt":1723574947212,"mc":[{"id":"1.231732748","rc":[{"batb":[[0,1.75,6.85],[1,1.74,17.32],[2,1.25,100]],"ltp":2.14,"tv":24.44,"id":40296818},{"batb":[[0,1.81,6.91],[1,1.8,444],[2,1.74,17.32]],"ltp":2.26,"tv":28.23,"id":40296819}]}]}
{"op":"mcm","clk":"11842594842","pt":1723575140950,"mc":[{"id":"1.231732748","rc":[{"batb":[[0,1.76,10],[1,1.75,6.85],[2,1.74,17.32]],"ltp":2.14,"tv":24.44,"id":40296818},{"batb":[[0,1.82,10],[1,1.81,6.91],[2,1.8,444]],"ltp":2.26,"tv":28.23,"id":40296819}]}]}
{"op":"mcm","clk":"11842595614","pt":1723575145073,"mc":[{"id":"1.231732748","rc":[{"batb":[[0,1.75,6.85],[1,1.74,17.32],[2,1.25,100]],"ltp":2.14,"tv":24.44,"id":40296818},{"batb":[[0,1.81,6.91],[1,1.8,444],[2,1.74,17.32]],"ltp":2.26,"tv":28.23,"id":40296819}]}]}
{"op":"mcm","clk":"11842595991","pt":1723575147266,"mc":[{"id":"1.231732748","rc":[{"batb":[[0,1.76,10],[1,1.75,6.85],[2,1.74,17.32]],"ltp":2.14,"tv":24.44,"id":40296818},{"batb":[[0,1.82,10],[1,1.81,6.91],[2,1.8,444]],"ltp":2.26,"tv":28.23,"id":40296819}]}]}
{"op":"mcm","clk":"11842597000","pt":1723575152987,"mc":[{"id":"1.231732748","rc":[{"batb":[[0,1.75,6.85],[1,1.74,17.32],[2,1.25,100]],"ltp":2.14,"tv":24.44,"id":40296818},{"batb":[[0,1.81,6.91],[1,1.8,444],[2,1.74,17.32]],"ltp":2.26,"tv":28.23,"id":40296819}]}]}
{"op":"mcm","clk":"11842653451","pt":1723575474049,"mc":[{"id":"1.231732748","rc":[{"batb":[[0,1.76,10],[1,1.75,6.85],[2,1.74,17.32]],"ltp":2.14,"tv":24.44,"id":40296818},{"batb":[[0,1.82,10],[1,1.81,6.91],[2,1.8,444]],"ltp":2.26,"tv":28.23,"id":40296819}]}]}
{"op":"mcm","clk":"11842654045","pt":1723575477383,"mc":[{"id":"1.231732748","rc":[{"batb":[[0,1.75,6.85],[1,1.74,17.32],[2,1.25,100]],"ltp":2.14,"tv":24.44,"id":40296818},{"batb":[[0,1.81,6.91],[1,1.8,444],[2,1.74,17.32]],"ltp":2.26,"tv":28.23,"id":40296819}]}]}
{"op":"mcm","clk":"11842658422","pt":1723575502309,"mc":[{"id":"1.231732748","rc":[{"batb":[[0,1.76,10],[1,1.75,6.85],[2,1.74,17.32]],"ltp":2.14,"tv":24.44,"id":40296818},{"batb":[[0,1.82,10],[1,1.81,6.91],[2,1.8,444]],"ltp":2.26,"tv":28.23,"id":40296819}]}]}
{"op":"mcm","clk":"11842659052","pt":1723575506133,"mc":[{"id":"1.231732748","rc":[{"batb":[[0,1.75,6.85],[1,1.74,17.32],[2,1.25,100]],"ltp":2.14,"tv":24.44,"id":40296818},{"batb":[[0,1.81,6.91],[1,1.8,444],[2,1.74,17.32]],"ltp":2.26,"tv":28.23,"id":40296819}]}]}
{"op":"mcm","clk":"11842664223","pt":1723575534663,"mc":[{"id":"1.231732748","rc":[{"batb":[[0,1.76,10],[1,1.75,6.85],[2,1.74,17.32]],"ltp":2.14,"tv":24.44,"id":40296818},{"batb":[[0,1.82,10],[1,1.81,6.91],[2,1.8,444]],"ltp":2.26,"tv":28.23,"id":40296819}]}]}
{"op":"mcm","clk":"11842664784","pt":1723575538230,"mc":[{"id":"1.231732748","rc":[{"batb":[[0,1.75,6.85],[1,1.74,17.32],[2,1.25,100]],"ltp":2.14,"tv":24.44,"id":40296818},{"batb":[[0,1.81,6.91],[1,1.8,444],[2,1.74,17.32]],"ltp":2.26,"tv":28.23,"id":40296819}]}]}
{"op":"mcm","clk":"11842671218","pt":1723575576243,"mc":[{"id":"1.231732748","rc":[{"batb":[[0,1.76,10],[1,1.75,6.85],[2,1.74,17.32]],"ltp":2.14,"tv":24.44,"id":40296818},{"batb":[[0,1.82,10],[1,1.81,6.91],[2,1.8,444]],"ltp":2.26,"tv":28.23,"id":40296819}]}]}
{"op":"mcm","clk":"11842671825","pt":1723575579644,"mc":[{"id":"1.231732748","rc":[{"batb":[[0,1.75,6.85],[1,1.74,17.32],[2,1.25,100]],"ltp":2.14,"tv":24.44,"id":40296818},{"batb":[[0,1.81,6.91],[1,1.8,444],[2,1.74,17.32]],"ltp":2.26,"tv":28.23,"id":40296819}]}]}
{"op":"mcm","clk":"11842673567","pt":1723575589138,"mc":[{"id":"1.231732748","rc":[{"batb":[[0,1.76,10],[1,1.75,6.85],[2,1.74,17.32]],"ltp":2.14,"tv":24.44,"id":40296818},{"batb":[[0,1.82,10],[1,1.81,6.91],[2,1.8,444]],"ltp":2.26,"tv":28.23,"id":40296819}]}]}
{"op":"mcm","clk":"11842674213","pt":1723575592768,"mc":[{"id":"1.231732748","rc":[{"batb":[[0,1.75,6.85],[1,1.74,17.32],[2,1.25,100]],"ltp":2.14,"tv":24.44,"id":40296818},{"batb":[[0,1.81,6.91],[1,1.8,444],[2,1.74,17.32]],"ltp":2.26,"tv":28.23,"id":40296819}]}]}
{"op":"mcm","clk":"11842682637","pt":1723575637622,"mc":[{"id":"1.231732748","rc":[{"trd":[[1.69,8.25],[1.7,4.75],[2.14,7.22],[2.16,4.23]],"batb":[[0,1.76,10],[1,1.75,6.85],[2,1.74,17.32]],"batl":[[0,2.24,17.14]],"ltp":2.14,"tv":24.44,"id":40296818},{"trd":[[1.86,16.74],[2.26,7.22]],"batb":[[0,1.82,10],[1,1.81,6.9],[2,1.8,444]],"batl":[[0,2.34,1.97]],"ltp":2.26,"tv":28.21,"id":40296819}],"tv":52.66}]}
{"op":"mcm","clk":"11842683307","pt":1723575641292,"mc":[{"id":"1.231732748","rc":[{"batb":[[0,1.75,6.85],[1,1.74,17.32],[2,1.25,100]],"ltp":2.14,"tv":24.44,"id":40296818},{"batb":[[0,1.81,6.9],[1,1.8,444],[2,1.74,17.32]],"ltp":2.26,"tv":28.21,"id":40296819}]}]}
{"op":"mcm","clk":"11842687129","pt":1723575661877,"mc":[{"id":"1.231732748","rc":[{"batb":[[0,1.76,10],[1,1.75,6.85],[2,1.74,17.32]],"ltp":2.14,"tv":24.44,"id":40296818},{"batb":[[0,1.82,10],[1,1.81,6.9],[2,1.8,444]],"ltp":2.26,"tv":28.21,"id":40296819}]}]}
{"op":"mcm","clk":"11842687862","pt":1723575665843,"mc":[{"id":"1.231732748","rc":[{"batb":[[0,1.75,6.85],[1,1.74,17.32],[2,1.25,100]],"ltp":2.14,"tv":24.44,"id":40296818},{"batb":[[0,1.81,6.9],[1,1.8,444],[2,1.74,17.32]],"ltp":2.26,"tv":28.21,"id":40296819}]}]}
{"op":"mcm","clk":"11842690156","pt":1723575677553,"mc":[{"id":"1.231732748","rc":[{"batb":[[0,1.76,10],[1,1.75,6.85],[2,1.74,17.32]],"ltp":2.14,"tv":24.44,"id":40296818},{"batb":[[0,1.82,10],[1,1.81,6.9],[2,1.8,444]],"ltp":2.26,"tv":28.21,"id":40296819}]}]}
{"op":"mcm","clk":"11842690797","pt":1723575681264,"mc":[{"id":"1.231732748","rc":[{"batb":[[0,1.75,6.85],[1,1.74,17.32],[2,1.25,100]],"ltp":2.14,"tv":24.44,"id":40296818},{"batb":[[0,1.81,6.9],[1,1.8,444],[2,1.74,17.32]],"ltp":2.26,"tv":28.21,"id":40296819}]}]}
{"op":"mcm","clk":"11842693684","pt":1723575697741,"mc":[{"id":"1.231732748","rc":[{"batb":[[0,1.76,10],[1,1.75,6.85],[2,1.74,17.32]],"ltp":2.14,"tv":24.44,"id":40296818},{"batb":[[0,1.82,10],[1,1.81,6.9],[2,1.8,444]],"ltp":2.26,"tv":28.21,"id":40296819}]}]}
{"op":"mcm","clk":"11842694343","pt":1723575701481,"mc":[{"id":"1.231732748","rc":[{"batb":[[0,1.75,6.85],[1,1.74,17.32],[2,1.25,100]],"ltp":2.14,"tv":24.44,"id":40296818},{"batb":[[0,1.81,6.9],[1,1.8,444],[2,1.74,17.32]],"ltp":2.26,"tv":28.21,"id":40296819}]}]}
{"op":"mcm","clk":"11842695150","pt":1723575706164,"mc":[{"id":"1.231732748","rc":[{"batb":[[0,1.76,10],[1,1.75,6.85],[2,1.74,17.32]],"ltp":2.14,"tv":24.44,"id":40296818},{"batb":[[0,1.82,10],[1,1.81,6.9],[2,1.8,444]],"ltp":2.26,"tv":28.21,"id":40296819}]}]}
{"op":"mcm","clk":"11842695658","pt":1723575709564,"mc":[{"id":"1.231732748","rc":[{"batb":[[0,1.75,6.85],[1,1.74,17.32],[2,1.25,100]],"ltp":2.14,"tv":24.44,"id":40296818},{"batb":[[0,1.81,6.9],[1,1.8,444],[2,1.74,17.32]],"ltp":2.26,"tv":28.21,"id":40296819}]}]}
{"op":"mcm","clk":"11842702074","pt":1723575748727,"mc":[{"id":"1.231732748","rc":[{"batb":[[0,1.76,10],[1,1.75,6.85],[2,1.74,17.32]],"ltp":2.14,"tv":24.44,"id":40296818},{"batb":[[0,1.82,10],[1,1.81,6.9],[2,1.8,444]],"ltp":2.26,"tv":28.21,"id":40296819}]}]}
{"op":"mcm","clk":"11842702714","pt":1723575752511,"mc":[{"id":"1.231732748","rc":[{"batb":[[0,1.75,6.85],[1,1.74,17.32],[2,1.25,100]],"ltp":2.14,"tv":24.44,"id":40296818},{"batb":[[0,1.81,6.9],[1,1.8,444],[2,1.74,17.32]],"ltp":2.26,"tv":28.21,"id":40296819}]}]}
{"op":"mcm","clk":"11842703380","pt":1723575755851,"mc":[{"id":"1.231732748","rc":[{"batb":[[0,1.76,10],[1,1.75,6.85],[2,1.74,17.32]],"ltp":2.14,"tv":24.44,"id":40296818},{"batb":[[0,1.82,10],[1,1.81,6.9],[2,1.8,444]],"ltp":2.26,"tv":28.21,"id":40296819}]}]}
{"op":"mcm","clk":"11842703919","pt":1723575759316,"mc":[{"id":"1.231732748","rc":[{"batb":[[0,1.75,6.85],[1,1.74,17.32],[2,1.25,100]],"ltp":2.14,"tv":24.44,"id":40296818},{"batb":[[0,1.81,6.9],[1,1.8,444],[2,1.74,17.32]],"ltp":2.26,"tv":28.21,"id":40296819}]}]}
{"op":"mcm","clk":"11842705417","pt":1723575768348,"mc":[{"id":"1.231732748","rc":[{"batb":[[0,1.76,10],[1,1.75,6.85],[2,1.74,17.32]],"ltp":2.14,"tv":24.44,"id":40296818},{"batb":[[0,1.82,10],[1,1.81,6.9],[2,1.8,444]],"ltp":2.26,"tv":28.21,"id":40296819}]}]}
{"op":"mcm","clk":"11842706075","pt":1723575771951,"mc":[{"id":"1.231732748","rc":[{"batb":[[0,1.75,6.85],[1,1.74,17.32],[2,1.25,100]],"ltp":2.14,"tv":24.44,"id":40296818},{"batb":[[0,1.81,6.9],[1,1.8,444],[2,1.74,17.32]],"ltp":2.26,"tv":28.21,"id":40296819}]}]}
{"op":"mcm","clk":"11842706544","pt":1723575774777,"mc":[{"id":"1.231732748","rc":[{"batb":[[0,1.76,10],[1,1.75,6.85],[2,1.74,17.32]],"ltp":2.14,"tv":24.44,"id":40296818},{"batb":[[0,1.82,10],[1,1.81,6.9],[2,1.8,444]],"ltp":2.26,"tv":28.21,"id":40296819}]}]}
{"op":"mcm","clk":"11842707147","pt":1723575778261,"mc":[{"id":"1.231732748","rc":[{"batb":[[0,1.75,6.85],[1,1.74,17.32],[2,1.25,100]],"ltp":2.14,"tv":24.44,"id":40296818},{"batb":[[0,1.81,6.9],[1,1.8,444],[2,1.74,17.32]],"ltp":2.26,"tv":28.21,"id":40296819}]}]}
{"op":"mcm","clk":"11842708314","pt":1723575784481,"mc":[{"id":"1.231732748","rc":[{"batb":[[0,1.76,10],[1,1.75,6.85],[2,1.74,17.32]],"ltp":2.14,"tv":24.44,"id":40296818},{"batb":[[0,1.82,10],[1,1.81,6.9],[2,1.8,444]],"ltp":2.26,"tv":28.21,"id":40296819}]}]}
{"op":"mcm","clk":"11842708999","pt":1723575788095,"mc":[{"id":"1.231732748","rc":[{"batb":[[0,1.75,6.85],[1,1.74,17.32],[2,1.25,100]],"ltp":2.14,"tv":24.44,"id":40296818},{"batb":[[0,1.81,6.9],[1,1.8,444],[2,1.74,17.32]],"ltp":2.26,"tv":28.21,"id":40296819}]}]}
{"op":"mcm","clk":"11842711758","pt":1723575803600,"mc":[{"id":"1.231732748","rc":[{"batb":[[0,1.76,10],[1,1.75,6.85],[2,1.74,17.32]],"ltp":2.14,"tv":24.44,"id":40296818},{"batb":[[0,1.82,10],[1,1.81,6.9],[2,1.8,444]],"ltp":2.26,"tv":28.21,"id":40296819}]}]}
{"op":"mcm","clk":"11842712330","pt":1723575807673,"mc":[{"id":"1.231732748","rc":[{"batb":[[0,1.75,6.85],[1,1.74,17.32],[2,1.25,100]],"ltp":2.14,"tv":24.44,"id":40296818},{"batb":[[0,1.81,6.9],[1,1.8,444],[2,1.74,17.32]],"ltp":2.26,"tv":28.21,"id":40296819}]}]}
{"op":"mcm","clk":"11842714817","pt":1723575821486,"mc":[{"id":"1.231732748","rc":[{"batb":[[0,1.76,10],[1,1.75,6.85],[2,1.74,17.32]],"ltp":2.14,"tv":24.44,"id":40296818},{"batb":[[0,1.82,10],[1,1.81,6.9],[2,1.8,444]],"ltp":2.26,"tv":28.21,"id":40296819}]}]}
{"op":"mcm","clk":"11842715515","pt":1723575825513,"mc":[{"id":"1.231732748","rc":[{"batb":[[0,1.75,6.85],[1,1.74,17.32],[2,1.25,100]],"ltp":2.14,"tv":24.44,"id":40296818},{"batb":[[0,1.81,6.9],[1,1.8,444],[2,1.74,17.32]],"ltp":2.26,"tv":28.21,"id":40296819}]}]}
{"op":"mcm","clk":"11842716992","pt":1723575833919,"mc":[{"id":"1.231732748","rc":[{"batb":[[0,1.76,10],[1,1.75,6.85],[2,1.74,17.32]],"ltp":2.14,"tv":24.44,"id":40296818},{"batb":[[0,1.82,10],[1,1.81,6.9],[2,1.8,444]],"ltp":2.26,"tv":28.21,"id":40296819}]}]}
{"op":"mcm","clk":"11842717644","pt":1723575837634,"mc":[{"id":"1.231732748","rc":[{"batb":[[0,1.75,6.85],[1,1.74,17.32],[2,1.25,100]],"ltp":2.14,"tv":24.44,"id":40296818},{"batb":[[0,1.81,6.9],[1,1.8,444],[2,1.74,17.32]],"ltp":2.26,"tv":28.21,"id":40296819}]}]}
{"op":"mcm","clk":"11842721532","pt":1723575857965,"mc":[{"id":"1.231732748","rc":[{"batb":[[0,1.76,10],[1,1.75,6.85],[2,1.74,17.32]],"ltp":2.14,"tv":24.44,"id":40296818},{"batb":[[0,1.82,10],[1,1.81,6.9],[2,1.8,444]],"ltp":2.26,"tv":28.21,"id":40296819}]}]}
{"op":"mcm","clk":"11842722230","pt":1723575861601,"mc":[{"id":"1.231732748","rc":[{"batb":[[0,1.75,6.85],[1,1.74,17.32],[2,1.25,100]],"ltp":2.14,"tv":24.44,"id":40296818},{"batb":[[0,1.81,6.9],[1,1.8,444],[2,1.74,17.32]],"ltp":2.26,"tv":28.21,"id":40296819}]}]}
{"op":"mcm","clk":"11842724526","pt":1723575874082,"mc":[{"id":"1.231732748","rc":[{"batb":[[0,1.76,10],[1,1.75,6.85],[2,1.74,17.32]],"ltp":2.14,"tv":24.44,"id":40296818},{"batb":[[0,1.82,10],[1,1.81,6.9],[2,1.8,444]],"ltp":2.26,"tv":28.21,"id":40296819}]}]}
{"op":"mcm","clk":"11842725147","pt":1723575877684,"mc":[{"id":"1.231732748","rc":[{"batb":[[0,1.75,6.85],[1,1.74,17.32],[2,1.25,100]],"ltp":2.14,"tv":24.44,"id":40296818},{"batb":[[0,1.81,6.9],[1,1.8,444],[2,1.74,17.32]],"ltp":2.26,"tv":28.21,"id":40296819}]}]}
{"op":"mcm","clk":"11842726112","pt":1723575883005,"mc":[{"id":"1.231732748","rc":[{"batb":[[0,1.76,10],[1,1.75,6.85],[2,1.74,17.32]],"ltp":2.14,"tv":24.44,"id":40296818},{"batb":[[0,1.82,10],[1,1.81,6.9],[2,1.8,444]],"ltp":2.26,"tv":28.21,"id":40296819}]}]}
{"op":"mcm","clk":"11842726806","pt":1723575886705,"mc":[{"id":"1.231732748","rc":[{"batb":[[0,1.75,6.85],[1,1.74,17.32],[2,1.25,100]],"ltp":2.14,"tv":24.44,"id":40296818},{"batb":[[0,1.81,6.9],[1,1.8,444],[2,1.74,17.32]],"ltp":2.26,"tv":28.21,"id":40296819}]}]}
{"op":"mcm","clk":"11842727321","pt":1723575889505,"mc":[{"id":"1.231732748","rc":[{"batb":[[0,1.76,10],[1,1.75,6.85],[2,1.74,17.32]],"ltp":2.14,"tv":24.44,"id":40296818},{"batb":[[0,1.82,10],[1,1.81,6.9],[2,1.8,444]],"ltp":2.26,"tv":28.21,"id":40296819}]}]}
{"op":"mcm","clk":"11842727921","pt":1723575892927,"mc":[{"id":"1.231732748","rc":[{"batb":[[0,1.75,6.85],[1,1.74,17.32],[2,1.25,100]],"ltp":2.14,"tv":24.44,"id":40296818},{"batb":[[0,1.81,6.9],[1,1.8,444],[2,1.74,17.32]],"ltp":2.26,"tv":28.21,"id":40296819}]}]}
{"op":"mcm","clk":"11842732323","pt":1723575915745,"mc":[{"id":"1.231732748","rc":[{"batb":[[0,1.76,10],[1,1.75,6.85],[2,1.74,17.32]],"ltp":2.14,"tv":24.44,"id":40296818},{"batb":[[0,1.82,10],[1,1.81,6.9],[2,1.8,444]],"ltp":2.26,"tv":28.21,"id":40296819}]}]}
{"op":"mcm","clk":"11842733057","pt":1723575919440,"mc":[{"id":"1.231732748","rc":[{"batb":[[0,1.75,6.85],[1,1.74,17.32],[2,1.25,100]],"ltp":2.14,"tv":24.44,"id":40296818},{"batb":[[0,1.81,6.9],[1,1.8,444],[2,1.74,17.32]],"ltp":2.26,"tv":28.21,"id":40296819}]}]}
{"op":"mcm","clk":"11842735673","pt":1723575933279,"mc":[{"id":"1.231732748","rc":[{"batb":[[0,1.76,10],[1,1.75,6.85],[2,1.74,17.32]],"ltp":2.14,"tv":24.44,"id":40296818},{"batb":[[0,1.82,10],[1,1.81,6.9],[2,1.8,444]],"ltp":2.26,"tv":28.21,"id":40296819}]}]}
{"op":"mcm","clk":"11842736304","pt":1723575936643,"mc":[{"id":"1.231732748","rc":[{"batb":[[0,1.75,6.85],[1,1.74,17.32],[2,1.25,100]],"ltp":2.14,"tv":24.44,"id":40296818},{"batb":[[0,1.81,6.9],[1,1.8,444],[2,1.74,17.32]],"ltp":2.26,"tv":28.21,"id":40296819}]}]}
{"op":"mcm","clk":"11842737695","pt":1723575944739,"mc":[{"id":"1.231732748","rc":[{"batb":[[0,1.76,10],[1,1.75,6.85],[2,1.74,17.32]],"ltp":2.14,"tv":24.44,"id":40296818},{"batb":[[0,1.82,10],[1,1.81,6.9],[2,1.8,444]],"ltp":2.26,"tv":28.21,"id":40296819}]}]}
{"op":"mcm","clk":"11842738392","pt":1723575948312,"mc":[{"id":"1.231732748","rc":[{"batb":[[0,1.75,6.85],[1,1.74,17.32],[2,1.25,100]],"ltp":2.14,"tv":24.44,"id":40296818},{"batb":[[0,1.81,6.9],[1,1.8,444],[2,1.74,17.32]],"ltp":2.26,"tv":28.21,"id":40296819}]}]}
{"op":"mcm","clk":"11842739355","pt":1723575953259,"mc":[{"id":"1.231732748","rc":[{"batb":[[0,1.76,10],[1,1.75,6.85],[2,1.74,17.32]],"ltp":2.14,"tv":24.44,"id":40296818},{"batb":[[0,1.82,10],[1,1.81,6.9],[2,1.8,444]],"ltp":2.26,"tv":28.21,"id":40296819}]}]}
{"op":"mcm","clk":"11842740043","pt":1723575956814,"mc":[{"id":"1.231732748","rc":[{"batb":[[0,1.75,6.85],[1,1.74,17.32],[2,1.25,100]],"ltp":2.14,"tv":24.44,"id":40296818},{"batb":[[0,1.81,6.9],[1,1.8,444],[2,1.74,17.32]],"ltp":2.26,"tv":28.21,"id":40296819}]}]}
{"op":"mcm","clk":"11842741181","pt":1723575962190,"mc":[{"id":"1.231732748","rc":[{"batb":[[0,1.76,10],[1,1.75,6.85],[2,1.74,17.32]],"ltp":2.14,"tv":24.44,"id":40296818},{"batb":[[0,1.82,10],[1,1.81,6.9],[2,1.8,444]],"ltp":2.26,"tv":28.21,"id":40296819}]}]}
{"op":"mcm","clk":"11842741863","pt":1723575965764,"mc":[{"id":"1.231732748","rc":[{"batb":[[0,1.75,6.85],[1,1.74,17.32],[2,1.25,100]],"ltp":2.14,"tv":24.44,"id":40296818},{"batb":[[0,1.81,6.9],[1,1.8,444],[2,1.74,17.32]],"ltp":2.26,"tv":28.21,"id":40296819}]}]}
{"op":"mcm","clk":"11842745023","pt":1723575982307,"mc":[{"id":"1.231732748","rc":[{"batb":[[0,1.76,10],[1,1.75,6.85],[2,1.74,17.32]],"ltp":2.14,"tv":24.44,"id":40296818},{"batb":[[0,1.82,10],[1,1.81,6.9],[2,1.8,444]],"ltp":2.26,"tv":28.21,"id":40296819}]}]}
{"op":"mcm","clk":"11842745699","pt":1723575985683,"mc":[{"id":"1.231732748","rc":[{"batb":[[0,1.75,6.85],[1,1.74,17.32],[2,1.25,100]],"ltp":2.14,"tv":24.44,"id":40296818},{"batb":[[0,1.81,6.9],[1,1.8,444],[2,1.74,17.32]],"ltp":2.26,"tv":28.21,"id":40296819}]}]}
{"op":"mcm","clk":"11842748628","pt":1723576000536,"mc":[{"id":"1.231732748","rc":[{"batb":[[0,1.76,10],[1,1.75,6.85],[2,1.74,17.32]],"ltp":2.14,"tv":24.44,"id":40296818},{"batb":[[0,1.82,10],[1,1.81,6.9],[2,1.8,444]],"ltp":2.26,"tv":28.21,"id":40296819}]}]}
{"op":"mcm","clk":"11842749311","pt":1723576004121,"mc":[{"id":"1.231732748","rc":[{"batb":[[0,1.75,6.85],[1,1.74,17.32],[2,1.25,100]],"ltp":2.14,"tv":24.44,"id":40296818},{"batb":[[0,1.81,6.9],[1,1.8,444],[2,1.74,17.32]],"ltp":2.26,"tv":28.21,"id":40296819}]}]}
{"op":"mcm","clk":"11842750627","pt":1723576010811,"mc":[{"id":"1.231732748","rc":[{"batb":[[0,1.76,10],[1,1.75,6.85],[2,1.74,17.32]],"ltp":2.14,"tv":24.44,"id":40296818},{"batb":[[0,1.82,10],[1,1.81,6.9],[2,1.8,444]],"ltp":2.26,"tv":28.21,"id":40296819}]}]}
{"op":"mcm","clk":"11842751956","pt":1723576017746,"mc":[{"id":"1.231732748","rc":[{"batb":[[0,1.75,6.85],[1,1.74,17.32],[2,1.25,100]],"ltp":2.14,"tv":24.44,"id":40296818},{"batb":[[0,1.81,6.9],[1,1.8,444],[2,1.74,17.32]],"ltp":2.26,"tv":28.21,"id":40296819}]}]}
{"op":"mcm","clk":"11842753158","pt":1723576023770,"mc":[{"id":"1.231732748","rc":[{"batb":[[0,1.77,10],[1,1.75,6.85],[2,1.74,17.32]],"ltp":2.14,"tv":24.44,"id":40296818},{"batb":[[0,1.82,10],[1,1.81,6.9],[2,1.8,444]],"ltp":2.26,"tv":28.21,"id":40296819}]}]}
{"op":"mcm","clk":"11842754774","pt":1723576032658,"mc":[{"id":"1.231732748","rc":[{"batb":[[0,1.75,6.85],[1,1.74,17.32],[2,1.25,100]],"ltp":2.14,"tv":24.44,"id":40296818},{"batb":[[0,1.81,6.9],[1,1.8,444],[2,1.74,17.32]],"ltp":2.26,"tv":28.21,"id":40296819}]}]}
{"op":"mcm","clk":"11842755574","pt":1723576036942,"mc":[{"id":"1.231732748","rc":[{"batb":[[0,1.76,10],[1,1.75,6.85],[2,1.74,17.32]],"ltp":2.14,"tv":24.44,"id":40296818},{"batb":[[0,1.83,10],[1,1.81,6.9],[2,1.8,444]],"ltp":2.26,"tv":28.21,"id":40296819}]}]}
{"op":"mcm","clk":"11842756590","pt":1723576042658,"mc":[{"id":"1.231732748","rc":[{"batb":[[0,1.75,6.85],[1,1.74,17.32],[2,1.25,100]],"ltp":2.14,"tv":24.44,"id":40296818},{"batb":[[0,1.81,6.9],[1,1.8,444],[2,1.74,17.32]],"ltp":2.26,"tv":28.21,"id":40296819}]}]}
{"op":"mcm","clk":"11842758090","pt":1723576050375,"mc":[{"id":"1.231732748","rc":[{"batb":[[0,1.76,10],[1,1.75,6.85],[2,1.74,17.32]],"ltp":2.14,"tv":24.44,"id":40296818},{"batb":[[0,1.82,10],[1,1.81,6.9],[2,1.8,444]],"ltp":2.26,"tv":28.21,"id":40296819}]}]}
{"op":"mcm","clk":"11842758745","pt":1723576053884,"mc":[{"id":"1.231732748","rc":[{"batb":[[0,1.75,6.85],[1,1.74,17.32],[2,1.25,100]],"ltp":2.14,"tv":24.44,"id":40296818},{"batb":[[0,1.81,6.9],[1,1.8,444],[2,1.74,17.32]],"ltp":2.26,"tv":28.21,"id":40296819}]}]}
{"op":"mcm","clk":"11842761133","pt":1723576066273,"mc":[{"id":"1.231732748","rc":[{"batb":[[0,1.76,10],[1,1.75,6.85],[2,1.74,17.32]],"ltp":2.14,"tv":24.44,"id":40296818},{"batb":[[0,1.82,10],[1,1.81,6.9],[2,1.8,444]],"ltp":2.26,"tv":28.21,"id":40296819}]}]}
{"op":"mcm","clk":"11842761872","pt":1723576069880,"mc":[{"id":"1.231732748","rc":[{"batb":[[0,1.75,6.85],[1,1.74,17.32],[2,1.25,100]],"ltp":2.14,"tv":24.44,"id":40296818},{"batb":[[0,1.81,6.9],[1,1.8,444],[2,1.74,17.32]],"ltp":2.26,"tv":28.21,"id":40296819}]}]}
{"op":"mcm","clk":"11842785734","pt":1723576204118,"mc":[{"id":"1.231732748","rc":[{"batb":[[0,1.76,10],[1,1.75,6.85],[2,1.74,17.32]],"ltp":2.14,"tv":24.44,"id":40296818},{"batb":[[0,1.82,10],[1,1.81,6.9],[2,1.8,444]],"ltp":2.26,"tv":28.21,"id":40296819}]}]}
{"op":"mcm","clk":"11842786359","pt":1723576207497,"mc":[{"id":"1.231732748","rc":[{"batb":[[0,1.75,6.85],[1,1.74,17.32],[2,1.25,100]],"ltp":2.14,"tv":24.44,"id":40296818},{"batb":[[0,1.81,6.9],[1,1.8,444],[2,1.74,17.32]],"ltp":2.26,"tv":28.21,"id":40296819}]}]}
{"op":"mcm","clk":"11842921344","pt":1723576901597,"mc":[{"id":"1.231732748","rc":[{"batb":[[0,1.76,10],[1,1.75,6.85],[2,1.74,17.32]],"ltp":2.14,"tv":24.44,"id":40296818},{"batb":[[0,1.82,10],[1,1.81,6.9],[2,1.8,444]],"ltp":2.26,"tv":28.21,"id":40296819}]}]}
{"op":"mcm","clk":"11842922108","pt":1723576905897,"mc":[{"id":"1.231732748","rc":[{"batb":[[0,1.75,6.85],[1,1.74,17.32],[2,1.25,100]],"ltp":2.14,"tv":24.44,"id":40296818},{"batb":[[0,1.81,6.9],[1,1.8,444],[2,1.74,17.32]],"ltp":2.26,"tv":28.21,"id":40296819}]}]}
{"op":"mcm","clk":"11842951996","pt":1723577068534,"mc":[{"id":"1.231732748","rc":[{"batb":[[0,1.76,10],[1,1.75,6.85],[2,1.74,17.32]],"ltp":2.14,"tv":24.44,"id":40296818},{"batb":[[0,1.82,10],[1,1.81,6.9],[2,1.8,444]],"ltp":2.26,"tv":28.21,"id":40296819}]}]}
{"op":"mcm","clk":"11842952673","pt":1723577072044,"mc":[{"id":"1.231732748","rc":[{"batb":[[0,1.75,6.85],[1,1.74,17.32],[2,1.25,100]],"ltp":2.14,"tv":24.44,"id":40296818},{"batb":[[0,1.81,6.9],[1,1.8,444],[2,1.74,17.32]],"ltp":2.26,"tv":28.21,"id":40296819}]}]}
{"op":"mcm","clk":"11843019017","pt":1723577441500,"mc":[{"id":"1.231732748","rc":[{"batb":[[0,1.76,10],[1,1.75,6.85],[2,1.74,17.32]],"ltp":2.14,"tv":24.44,"id":40296818},{"batb":[[0,1.82,10],[1,1.81,6.9],[2,1.8,444]],"ltp":2.26,"tv":28.21,"id":40296819}]}]}
{"op":"mcm","clk":"11843019752","pt":1723577445313,"mc":[{"id":"1.231732748","rc":[{"batb":[[0,1.75,6.85],[1,1.74,17.32],[2,1.25,100]],"ltp":2.14,"tv":24.44,"id":40296818},{"batb":[[0,1.81,6.9],[1,1.8,444],[2,1.74,17.32]],"ltp":2.26,"tv":28.21,"id":40296819}]}]}
{"op":"mcm","clk":"11843020420","pt":1723577449006,"mc":[{"id":"1.231732748","rc":[{"batb":[[0,1.76,10],[1,1.75,6.85],[2,1.74,17.32]],"ltp":2.14,"tv":24.44,"id":40296818},{"batb":[[0,1.82,10],[1,1.81,6.9],[2,1.8,444]],"ltp":2.26,"tv":28.21,"id":40296819}]}]}
{"op":"mcm","clk":"11843021044","pt":1723577452593,"mc":[{"id":"1.231732748","rc":[{"batb":[[0,1.75,6.85],[1,1.74,17.32],[2,1.25,100]],"ltp":2.14,"tv":24.44,"id":40296818},{"batb":[[0,1.81,6.9],[1,1.8,444],[2,1.74,17.32]],"ltp":2.26,"tv":28.21,"id":40296819}]}]}
{"op":"mcm","clk":"11843022758","pt":1723577462207,"mc":[{"id":"1.231732748","rc":[{"batb":[[0,1.76,10],[1,1.75,6.85],[2,1.74,17.32]],"ltp":2.14,"tv":24.44,"id":40296818},{"batb":[[0,1.82,10],[1,1.81,6.9],[2,1.8,444]],"ltp":2.26,"tv":28.21,"id":40296819}]}]}
{"op":"mcm","clk":"11843023535","pt":1723577465903,"mc":[{"id":"1.231732748","rc":[{"batb":[[0,1.75,6.85],[1,1.74,17.32],[2,1.25,100]],"ltp":2.14,"tv":24.44,"id":40296818},{"batb":[[0,1.81,6.9],[1,1.8,444],[2,1.74,17.32]],"ltp":2.26,"tv":28.21,"id":40296819}]}]}
{"op":"mcm","clk":"11843028677","pt":1723577492893,"mc":[{"id":"1.231732748","rc":[{"batb":[[0,1.76,10],[1,1.75,6.85],[2,1.74,17.32]],"ltp":2.14,"tv":24.44,"id":40296818},{"batb":[[0,1.82,10],[1,1.81,6.9],[2,1.8,444]],"ltp":2.26,"tv":28.21,"id":40296819}]}]}
{"op":"mcm","clk":"11843029280","pt":1723577496350,"mc":[{"id":"1.231732748","rc":[{"batb":[[0,1.75,6.85],[1,1.74,17.32],[2,1.25,100]],"ltp":2.14,"tv":24.44,"id":40296818},{"batb":[[0,1.81,6.9],[1,1.8,444],[2,1.74,17.32]],"ltp":2.26,"tv":28.21,"id":40296819}]}]}
{"op":"mcm","clk":"11843034296","pt":1723577526684,"mc":[{"id":"1.231732748","rc":[{"batb":[[0,1.76,10],[1,1.75,6.85],[2,1.74,17.32]],"ltp":2.14,"tv":24.44,"id":40296818},{"batb":[[0,1.82,10],[1,1.81,6.9],[2,1.8,444]],"ltp":2.26,"tv":28.21,"id":40296819}]}]}
{"op":"mcm","clk":"11843034896","pt":1723577530216,"mc":[{"id":"1.231732748","rc":[{"batb":[[0,1.75,6.85],[1,1.74,17.32],[2,1.25,100]],"ltp":2.14,"tv":24.44,"id":40296818},{"batb":[[0,1.81,6.9],[1,1.8,444],[2,1.74,17.32]],"ltp":2.26,"tv":28.21,"id":40296819}]}]}
{"op":"mcm","clk":"11843035266","pt":1723577532408,"mc":[{"id":"1.231732748","rc":[{"batb":[[0,1.76,10],[1,1.75,6.85],[2,1.74,17.32]],"ltp":2.14,"tv":24.44,"id":40296818},{"batb":[[0,1.82,10],[1,1.81,6.9],[2,1.8,444]],"ltp":2.26,"tv":28.21,"id":40296819}]}]}
{"op":"mcm","clk":"11843035970","pt":1723577535882,"mc":[{"id":"1.231732748","rc":[{"batb":[[0,1.75,6.85],[1,1.74,17.32],[2,1.25,100]],"ltp":2.14,"tv":24.44,"id":40296818},{"batb":[[0,1.81,6.9],[1,1.8,444],[2,1.74,17.32]],"ltp":2.26,"tv":28.21,"id":40296819}]}]}
{"op":"mcm","clk":"11843037777","pt":1723577546600,"mc":[{"id":"1.231732748","rc":[{"batb":[[0,1.76,10],[1,1.75,6.85],[2,1.74,17.32]],"ltp":2.14,"tv":24.44,"id":40296818},{"batb":[[0,1.82,10],[1,1.81,6.9],[2,1.8,444]],"ltp":2.26,"tv":28.21,"id":40296819}]}]}
{"op":"mcm","clk":"11843038369","pt":1723577549894,"mc":[{"id":"1.231732748","rc":[{"batb":[[0,1.75,6.85],[1,1.74,17.32],[2,1.25,100]],"ltp":2.14,"tv":24.44,"id":40296818},{"batb":[[0,1.81,6.9],[1,1.8,444],[2,1.74,17.32]],"ltp":2.26,"tv":28.21,"id":40296819}]}]}
{"op":"mcm","clk":"11843041191","pt":1723577567041,"mc":[{"id":"1.231732748","rc":[{"batb":[[0,1.76,10],[1,1.75,6.85],[2,1.74,17.32]],"ltp":2.14,"tv":24.44,"id":40296818},{"batb":[[0,1.82,10],[1,1.81,6.9],[2,1.8,444]],"ltp":2.26,"tv":28.21,"id":40296819}]}]}
{"op":"mcm","clk":"11843041809","pt":1723577570555,"mc":[{"id":"1.231732748","rc":[{"batb":[[0,1.75,6.85],[1,1.74,17.32],[2,1.25,100]],"ltp":2.14,"tv":24.44,"id":40296818},{"batb":[[0,1.81,6.9],[1,1.8,444],[2,1.74,17.32]],"ltp":2.26,"tv":28.21,"id":40296819}]}]}
{"op":"mcm","clk":"11843052844","pt":1723577639212,"mc":[{"id":"1.231732748","rc":[{"batb":[[0,1.76,10],[1,1.75,6.85],[2,1.74,17.32]],"ltp":2.14,"tv":24.44,"id":40296818},{"batb":[[0,1.82,10],[1,1.81,6.9],[2,1.8,444]],"ltp":2.26,"tv":28.21,"id":40296819}]}]}
{"op":"mcm","clk":"11843053425","pt":1723577642927,"mc":[{"id":"1.231732748","rc":[{"batb":[[0,1.75,6.85],[1,1.74,17.32],[2,1.25,100]],"ltp":2.14,"tv":24.44,"id":40296818},{"batb":[[0,1.81,6.9],[1,1.8,444],[2,1.74,17.32]],"ltp":2.26,"tv":28.21,"id":40296819}]}]}
{"op":"mcm","clk":"11843055699","pt":1723577657461,"mc":[{"id":"1.231732748","rc":[{"batb":[[0,1.76,10],[1,1.75,6.85],[2,1.74,17.32]],"ltp":2.14,"tv":24.44,"id":40296818},{"batb":[[0,1.82,10],[1,1.81,6.9],[2,1.8,444]],"ltp":2.26,"tv":28.21,"id":40296819}]}]}
{"op":"mcm","clk":"11843056291","pt":1723577661452,"mc":[{"id":"1.231732748","rc":[{"batb":[[0,1.75,6.85],[1,1.74,17.32],[2,1.25,100]],"ltp":2.14,"tv":24.44,"id":40296818},{"batb":[[0,1.81,6.9],[1,1.8,444],[2,1.74,17.32]],"ltp":2.26,"tv":28.21,"id":40296819}]}]}
{"op":"mcm","clk":"11843056851","pt":1723577665167,"mc":[{"id":"1.231732748","rc":[{"batb":[[0,1.76,10],[1,1.75,6.85],[2,1.74,17.32]],"ltp":2.14,"tv":24.44,"id":40296818},{"batb":[[0,1.82,10],[1,1.81,6.9],[2,1.8,444]],"ltp":2.26,"tv":28.21,"id":40296819}]}]}
{"op":"mcm","clk":"11843057390","pt":1723577668968,"mc":[{"id":"1.231732748","rc":[{"batb":[[0,1.75,6.85],[1,1.74,17.32],[2,1.25,100]],"ltp":2.14,"tv":24.44,"id":40296818},{"batb":[[0,1.81,6.9],[1,1.8,444],[2,1.74,17.32]],"ltp":2.26,"tv":28.21,"id":40296819}]}]}
{"op":"mcm","clk":"11843058135","pt":1723577673972,"mc":[{"id":"1.231732748","rc":[{"batb":[[0,1.76,10],[1,1.75,6.85],[2,1.74,17.32]],"ltp":2.14,"tv":24.44,"id":40296818},{"batb":[[0,1.82,10],[1,1.81,6.9],[2,1.8,444]],"ltp":2.26,"tv":28.21,"id":40296819}]}]}
{"op":"mcm","clk":"11843058660","pt":1723577677468,"mc":[{"id":"1.231732748","rc":[{"batb":[[0,1.75,6.85],[1,1.74,17.32],[2,1.25,100]],"ltp":2.14,"tv":24.44,"id":40296818},{"batb":[[0,1.81,6.9],[1,1.8,444],[2,1.74,17.32]],"ltp":2.26,"tv":28.21,"id":40296819}]}]}
{"op":"mcm","clk":"11843063761","pt":1723577714400,"mc":[{"id":"1.231732748","rc":[{"batb":[[0,1.76,10],[1,1.75,6.85],[2,1.74,17.32]],"ltp":2.14,"tv":24.44,"id":40296818},{"batb":[[0,1.82,10],[1,1.81,6.9],[2,1.8,444]],"ltp":2.26,"tv":28.21,"id":40296819}]}]}
{"op":"mcm","clk":"11843064225","pt":1723577717821,"mc":[{"id":"1.231732748","rc":[{"batb":[[0,1.75,6.85],[1,1.74,17.32],[2,1.25,100]],"ltp":2.14,"tv":24.44,"id":40296818},{"batb":[[0,1.81,6.9],[1,1.8,444],[2,1.74,17.32]],"ltp":2.26,"tv":28.21,"id":40296819}]}]}
{"op":"mcm","clk":"11843075045","pt":1723577802510,"mc":[{"id":"1.231732748","rc":[{"batb":[[0,1.76,10],[1,1.75,6.85],[2,1.74,17.32]],"ltp":2.14,"tv":24.44,"id":40296818},{"batb":[[0,1.82,10],[1,1.81,6.9],[2,1.8,444]],"ltp":2.26,"tv":28.21,"id":40296819}]}]}
{"op":"mcm","clk":"11843075534","pt":1723577806503,"mc":[{"id":"1.231732748","rc":[{"batb":[[0,1.75,6.85],[1,1.74,17.32],[2,1.25,100]],"ltp":2.14,"tv":24.44,"id":40296818},{"batb":[[0,1.81,6.9],[1,1.8,444],[2,1.74,17.32]],"ltp":2.26,"tv":28.21,"id":40296819}]}]}
{"op":"mcm","clk":"11843077461","pt":1723577822235,"mc":[{"id":"1.231732748","rc":[{"batb":[[0,1.76,10],[1,1.75,6.85],[2,1.74,17.32]],"ltp":2.14,"tv":24.44,"id":40296818},{"batb":[[0,1.82,10],[1,1.81,6.9],[2,1.8,444]],"ltp":2.26,"tv":28.21,"id":40296819}]}]}
{"op":"mcm","clk":"11843077921","pt":1723577825839,"mc":[{"id":"1.231732748","rc":[{"batb":[[0,1.75,6.85],[1,1.74,17.32],[2,1.25,100]],"ltp":2.14,"tv":24.44,"id":40296818},{"batb":[[0,1.81,6.9],[1,1.8,444],[2,1.74,17.32]],"ltp":2.26,"tv":28.21,"id":40296819}]}]}
{"op":"mcm","clk":"11843081384","pt":1723577852161,"mc":[{"id":"1.231732748","rc":[{"batb":[[0,1.76,10],[1,1.75,6.85],[2,1.74,17.32]],"ltp":2.14,"tv":24.44,"id":40296818},{"batb":[[0,1.82,10],[1,1.81,6.9],[2,1.8,444]],"ltp":2.26,"tv":28.21,"id":40296819}]}]}
{"op":"mcm","clk":"11843081859","pt":1723577855967,"mc":[{"id":"1.231732748","rc":[{"batb":[[0,1.75,6.85],[1,1.74,17.32],[2,1.25,100]],"ltp":2.14,"tv":24.44,"id":40296818},{"batb":[[0,1.81,6.9],[1,1.8,444],[2,1.74,17.32]],"ltp":2.26,"tv":28.21,"id":40296819}]}]}
{"op":"mcm","clk":"11843082956","pt":1723577864964,"mc":[{"id":"1.231732748","rc":[{"batb":[[0,1.76,10],[1,1.75,6.85],[2,1.74,17.32]],"ltp":2.14,"tv":24.44,"id":40296818},{"batb":[[0,1.82,10],[1,1.81,6.9],[2,1.8,444]],"ltp":2.26,"tv":28.21,"id":40296819}]}]}
{"op":"mcm","clk":"11843083422","pt":1723577868656,"mc":[{"id":"1.231732748","rc":[{"batb":[[0,1.75,6.85],[1,1.74,17.32],[2,1.25,100]],"ltp":2.14,"tv":24.44,"id":40296818},{"batb":[[0,1.81,6.9],[1,1.8,444],[2,1.74,17.32]],"ltp":2.26,"tv":28.21,"id":40296819}]}]}
{"op":"mcm","clk":"11843084199","pt":1723577875571,"mc":[{"id":"1.231732748","rc":[{"batb":[[0,1.76,10],[1,1.75,6.85],[2,1.74,17.32]],"ltp":2.14,"tv":24.44,"id":40296818},{"batb":[[0,1.82,10],[1,1.81,6.9],[2,1.8,444]],"ltp":2.26,"tv":28.21,"id":40296819}]}]}
{"op":"mcm","clk":"11843084569","pt":1723577878996,"mc":[{"id":"1.231732748","rc":[{"batb":[[0,1.75,6.85],[1,1.74,17.32],[2,1.25,100]],"ltp":2.14,"tv":24.44,"id":40296818},{"batb":[[0,1.81,6.9],[1,1.8,444],[2,1.74,17.32]],"ltp":2.26,"tv":28.21,"id":40296819}]}]}
{"op":"mcm","clk":"11843087008","pt":1723577898410,"mc":[{"id":"1.231732748","rc":[{"batb":[[0,1.76,10],[1,1.75,6.85],[2,1.74,17.32]],"ltp":2.14,"tv":24.44,"id":40296818},{"batb":[[0,1.82,10],[1,1.81,6.9],[2,1.8,444]],"ltp":2.26,"tv":28.21,"id":40296819}]}]}
{"op":"mcm","clk":"11843087438","pt":1723577902004,"mc":[{"id":"1.231732748","rc":[{"batb":[[0,1.75,6.85],[1,1.74,17.32],[2,1.25,100]],"ltp":2.14,"tv":24.44,"id":40296818}]}]}
{"op":"mcm","clk":"11843087450","pt":1723577902104,"mc":[{"id":"1.231732748","rc":[{"batb":[[0,1.81,6.9],[1,1.8,444],[2,1.74,17.32]],"ltp":2.26,"tv":28.21,"id":40296819}]}]}
{"op":"mcm","clk":"11843088225","pt":1723577908816,"mc":[{"id":"1.231732748","rc":[{"batb":[[0,1.76,10],[1,1.75,6.85],[2,1.74,17.32]],"ltp":2.14,"tv":24.44,"id":40296818},{"batb":[[0,1.82,10],[1,1.81,6.9],[2,1.8,444]],"ltp":2.26,"tv":28.21,"id":40296819}]}]}
{"op":"mcm","clk":"11843088639","pt":1723577912419,"mc":[{"id":"1.231732748","rc":[{"batb":[[0,1.75,6.85],[1,1.74,17.32],[2,1.25,100]],"ltp":2.14,"tv":24.44,"id":40296818},{"batb":[[0,1.81,6.9],[1,1.8,444],[2,1.74,17.32]],"ltp":2.26,"tv":28.21,"id":40296819}]}]}
{"op":"mcm","clk":"11843089898","pt":1723577923755,"mc":[{"id":"1.231732748","rc":[{"batb":[[0,1.76,10],[1,1.75,6.85],[2,1.74,17.32]],"ltp":2.14,"tv":24.44,"id":40296818},{"batb":[[0,1.82,10],[1,1.81,6.9],[2,1.8,444]],"ltp":2.26,"tv":28.21,"id":40296819}]}]}
{"op":"mcm","clk":"11843090375","pt":1723577927766,"mc":[{"id":"1.231732748","rc":[{"batb":[[0,1.75,6.85],[1,1.74,17.32],[2,1.25,100]],"ltp":2.14,"tv":24.44,"id":40296818},{"batb":[[0,1.81,6.9],[1,1.8,444],[2,1.74,17.32]],"ltp":2.26,"tv":28.21,"id":40296819}]}]}
{"op":"mcm","clk":"11843091529","pt":1723577937772,"mc":[{"id":"1.231732748","rc":[{"batb":[[0,1.76,10],[1,1.75,6.85],[2,1.74,17.32]],"ltp":2.14,"tv":24.44,"id":40296818},{"batb":[[0,1.82,10],[1,1.81,6.9],[2,1.8,444]],"ltp":2.26,"tv":28.21,"id":40296819}]}]}
{"op":"mcm","clk":"11843092221","pt":1723577943137,"mc":[{"id":"1.231732748","rc":[{"batb":[[0,1.75,6.85],[1,1.74,17.32],[2,1.25,100]],"ltp":2.14,"tv":24.44,"id":40296818},{"batb":[[0,1.81,6.9],[1,1.8,444],[2,1.74,17.32]],"ltp":2.26,"tv":28.21,"id":40296819}]}]}
{"op":"mcm","clk":"11843092907","pt":1723577948507,"mc":[{"id":"1.231732748","rc":[{"batb":[[0,1.76,10],[1,1.75,6.85],[2,1.74,17.32]],"ltp":2.14,"tv":24.44,"id":40296818},{"batb":[[0,1.82,10],[1,1.81,6.9],[2,1.8,444]],"ltp":2.26,"tv":28.21,"id":40296819}]}]}
{"op":"mcm","clk":"11843093314","pt":1723577951832,"mc":[{"id":"1.231732748","rc":[{"batb":[[0,1.75,6.85],[1,1.74,17.32],[2,1.25,100]],"ltp":2.14,"tv":24.44,"id":40296818},{"batb":[[0,1.81,6.9],[1,1.8,444],[2,1.74,17.32]],"ltp":2.26,"tv":28.21,"id":40296819}]}]}
{"op":"mcm","clk":"11843094022","pt":1723577957452,"mc":[{"id":"1.231732748","rc":[{"batb":[[0,1.76,10],[1,1.75,6.85],[2,1.74,17.32]],"ltp":2.14,"tv":24.44,"id":40296818},{"batb":[[0,1.82,10],[1,1.81,6.9],[2,1.8,444]],"ltp":2.26,"tv":28.21,"id":40296819}]}]}
{"op":"mcm","clk":"11843094526","pt":1723577961156,"mc":[{"id":"1.231732748","rc":[{"batb":[[0,1.75,6.85],[1,1.74,17.32],[2,1.25,100]],"ltp":2.14,"tv":24.44,"id":40296818},{"batb":[[0,1.81,6.9],[1,1.8,444],[2,1.74,17.32]],"ltp":2.26,"tv":28.21,"id":40296819}]}]}
{"op":"mcm","clk":"11843094853","pt":1723577963341,"mc":[{"id":"1.231732748","rc":[{"batb":[[0,1.76,10],[1,1.75,6.85],[2,1.74,17.32]],"ltp":2.14,"tv":24.44,"id":40296818},{"batb":[[0,1.82,10],[1,1.81,6.9],[2,1.8,444]],"ltp":2.26,"tv":28.21,"id":40296819}]}]}
{"op":"mcm","clk":"11843095276","pt":1723577966833,"mc":[{"id":"1.231732748","rc":[{"batb":[[0,1.75,6.85],[1,1.74,17.32],[2,1.25,100]],"ltp":2.14,"tv":24.44,"id":40296818},{"batb":[[0,1.81,6.9],[1,1.8,444],[2,1.74,17.32]],"ltp":2.26,"tv":28.21,"id":40296819}]}]}
{"op":"mcm","clk":"11843096646","pt":1723577977949,"mc":[{"id":"1.231732748","rc":[{"batb":[[0,1.76,10],[1,1.75,6.85],[2,1.74,17.32]],"ltp":2.14,"tv":24.44,"id":40296818},{"batb":[[0,1.82,10],[1,1.81,6.9],[2,1.8,444]],"ltp":2.26,"tv":28.21,"id":40296819}]}]}
{"op":"mcm","clk":"11843097015","pt":1723577981277,"mc":[{"id":"1.231732748","rc":[{"batb":[[0,1.75,6.85],[1,1.74,17.32],[2,1.25,100]],"ltp":2.14,"tv":24.44,"id":40296818},{"batb":[[0,1.81,6.9],[1,1.8,444],[2,1.74,17.32]],"ltp":2.26,"tv":28.21,"id":40296819}]}]}
{"op":"mcm","clk":"11843098452","pt":1723577993168,"mc":[{"id":"1.231732748","rc":[{"batb":[[0,1.76,10],[1,1.75,6.85],[2,1.74,17.32]],"ltp":2.14,"tv":24.44,"id":40296818},{"batb":[[0,1.82,10],[1,1.81,6.9],[2,1.8,444]],"ltp":2.26,"tv":28.21,"id":40296819}]}]}
{"op":"mcm","clk":"11843098878","pt":1723577996647,"mc":[{"id":"1.231732748","rc":[{"batb":[[0,1.75,6.85],[1,1.74,17.32],[2,1.25,100]],"ltp":2.14,"tv":24.44,"id":40296818},{"batb":[[0,1.81,6.9],[1,1.8,444],[2,1.74,17.32]],"ltp":2.26,"tv":28.21,"id":40296819}]}]}
{"op":"mcm","clk":"11843099245","pt":1723577999763,"mc":[{"id":"1.231732748","rc":[{"batb":[[0,1.76,10],[1,1.75,6.85],[2,1.74,17.32]],"ltp":2.14,"tv":24.44,"id":40296818},{"batb":[[0,1.82,10],[1,1.81,6.9],[2,1.8,444]],"ltp":2.26,"tv":28.21,"id":40296819}]}]}
{"op":"mcm","clk":"11843099688","pt":1723578003586,"mc":[{"id":"1.231732748","rc":[{"batb":[[0,1.75,6.85],[1,1.74,17.32],[2,1.25,100]],"ltp":2.14,"tv":24.44,"id":40296818},{"batb":[[0,1.81,6.9],[1,1.8,444],[2,1.74,17.32]],"ltp":2.26,"tv":28.21,"id":40296819}]}]}
{"op":"mcm","clk":"11843100084","pt":1723578006994,"mc":[{"id":"1.231732748","rc":[{"batb":[[0,1.76,10],[1,1.75,6.85],[2,1.74,17.32]],"ltp":2.14,"tv":24.44,"id":40296818},{"batb":[[0,1.82,10],[1,1.81,6.9],[2,1.8,444]],"ltp":2.26,"tv":28.21,"id":40296819}]}]}
{"op":"mcm","clk":"11843100561","pt":1723578010976,"mc":[{"id":"1.231732748","rc":[{"batb":[[0,1.81,6.9],[1,1.8,444],[2,1.74,17.32]],"ltp":2.26,"tv":28.21,"id":40296819}]}]}
{"op":"mcm","clk":"11843100571","pt":1723578011103,"mc":[{"id":"1.231732748","rc":[{"batb":[[0,1.75,6.85],[1,1.74,17.32],[2,1.25,100]],"ltp":2.14,"tv":24.44,"id":40296818}]}]}
{"op":"mcm","clk":"11843100899","pt":1723578013812,"mc":[{"id":"1.231732748","rc":[{"batb":[[0,1.76,10],[1,1.75,6.85],[2,1.74,17.32]],"ltp":2.14,"tv":24.44,"id":40296818},{"batb":[[0,1.82,10],[1,1.81,6.9],[2,1.8,444]],"ltp":2.26,"tv":28.21,"id":40296819}]}]}
{"op":"mcm","clk":"11843101434","pt":1723578017730,"mc":[{"id":"1.231732748","rc":[{"batb":[[0,1.75,6.85],[1,1.74,17.32],[2,1.25,100]],"ltp":2.14,"tv":24.44,"id":40296818},{"batb":[[0,1.81,6.9],[1,1.8,444],[2,1.74,17.32]],"ltp":2.26,"tv":28.21,"id":40296819}]}]}
{"op":"mcm","clk":"11843101800","pt":1723578020807,"mc":[{"id":"1.231732748","rc":[{"batb":[[0,1.76,10],[1,1.75,6.85],[2,1.74,17.32]],"ltp":2.14,"tv":24.44,"id":40296818},{"batb":[[0,1.82,10],[1,1.81,6.9],[2,1.8,444]],"ltp":2.26,"tv":28.21,"id":40296819}]}]}
{"op":"mcm","clk":"11843102294","pt":1723578024605,"mc":[{"id":"1.231732748","rc":[{"batb":[[0,1.75,6.85],[1,1.74,17.32],[2,1.25,100]],"ltp":2.14,"tv":24.44,"id":40296818},{"batb":[[0,1.81,6.9],[1,1.8,444],[2,1.74,17.32]],"ltp":2.26,"tv":28.21,"id":40296819}]}]}
{"op":"mcm","clk":"11843102725","pt":1723578027990,"mc":[{"id":"1.231732748","rc":[{"batb":[[0,1.76,10],[1,1.75,6.85],[2,1.74,17.32]],"ltp":2.14,"tv":24.44,"id":40296818},{"batb":[[0,1.82,10],[1,1.81,6.9],[2,1.8,444]],"ltp":2.26,"tv":28.21,"id":40296819}]}]}
{"op":"mcm","clk":"11843103192","pt":1723578031424,"mc":[{"id":"1.231732748","rc":[{"batb":[[0,1.75,6.85],[1,1.74,17.32],[2,1.25,100]],"ltp":2.14,"tv":24.44,"id":40296818},{"batb":[[0,1.81,6.9],[1,1.8,444],[2,1.74,17.32]],"ltp":2.26,"tv":28.21,"id":40296819}]}]}
{"op":"mcm","clk":"11843103508","pt":1723578033826,"mc":[{"id":"1.231732748","rc":[{"batb":[[0,1.76,10],[1,1.75,6.85],[2,1.74,17.32]],"ltp":2.14,"tv":24.44,"id":40296818},{"batb":[[0,1.82,10],[1,1.81,6.9],[2,1.8,444]],"ltp":2.26,"tv":28.21,"id":40296819}]}]}
{"op":"mcm","clk":"11843103958","pt":1723578037419,"mc":[{"id":"1.231732748","rc":[{"batb":[[0,1.75,6.85],[1,1.74,17.32],[2,1.25,100]],"ltp":2.14,"tv":24.44,"id":40296818},{"batb":[[0,1.81,6.9],[1,1.8,444],[2,1.74,17.32]],"ltp":2.26,"tv":28.21,"id":40296819}]}]}
{"op":"mcm","clk":"11843104502","pt":1723578041327,"mc":[{"id":"1.231732748","rc":[{"batb":[[0,1.76,10],[1,1.75,6.85],[2,1.74,17.32]],"ltp":2.14,"tv":24.44,"id":40296818},{"batb":[[0,1.82,10],[1,1.81,6.9],[2,1.8,444]],"ltp":2.26,"tv":28.21,"id":40296819}]}]}
{"op":"mcm","clk":"11843105017","pt":1723578044837,"mc":[{"id":"1.231732748","rc":[{"batb":[[0,1.75,6.85],[1,1.74,17.32],[2,1.25,100]],"ltp":2.14,"tv":24.44,"id":40296818},{"batb":[[0,1.81,6.9],[1,1.8,444],[2,1.74,17.32]],"ltp":2.26,"tv":28.21,"id":40296819}]}]}
{"op":"mcm","clk":"11843106123","pt":1723578053632,"mc":[{"id":"1.231732748","rc":[{"batb":[[0,1.76,10],[1,1.75,6.85],[2,1.74,17.32]],"ltp":2.14,"tv":24.44,"id":40296818},{"batb":[[0,1.82,10],[1,1.81,6.9],[2,1.8,444]],"ltp":2.26,"tv":28.21,"id":40296819}]}]}
{"op":"mcm","clk":"11843106576","pt":1723578057436,"mc":[{"id":"1.231732748","rc":[{"batb":[[0,1.75,6.85],[1,1.74,17.32],[2,1.25,100]],"ltp":2.14,"tv":24.44,"id":40296818},{"batb":[[0,1.81,6.9],[1,1.8,444],[2,1.74,17.32]],"ltp":2.26,"tv":28.21,"id":40296819}]}]}
{"op":"mcm","clk":"11843107312","pt":1723578063285,"mc":[{"id":"1.231732748","rc":[{"batb":[[0,1.76,10],[1,1.75,6.85],[2,1.74,17.32]],"ltp":2.14,"tv":24.44,"id":40296818},{"batb":[[0,1.82,10],[1,1.81,6.9],[2,1.8,444]],"ltp":2.26,"tv":28.21,"id":40296819}]}]}
{"op":"mcm","clk":"11843107718","pt":1723578066684,"mc":[{"id":"1.231732748","rc":[{"batb":[[0,1.75,6.85],[1,1.74,17.32],[2,1.25,100]],"ltp":2.14,"tv":24.44,"id":40296818},{"batb":[[0,1.81,6.9],[1,1.8,444],[2,1.74,17.32]],"ltp":2.26,"tv":28.21,"id":40296819}]}]}
{"op":"mcm","clk":"11843108153","pt":1723578069554,"mc":[{"id":"1.231732748","rc":[{"batb":[[0,1.76,10],[1,1.75,6.85],[2,1.74,17.32]],"ltp":2.14,"tv":24.44,"id":40296818},{"batb":[[0,1.82,10],[1,1.81,6.9],[2,1.8,444]],"ltp":2.26,"tv":28.21,"id":40296819}]}]}
{"op":"mcm","clk":"11843108578","pt":1723578073290,"mc":[{"id":"1.231732748","rc":[{"batb":[[0,1.75,6.85],[1,1.74,17.32],[2,1.25,100]],"ltp":2.14,"tv":24.44,"id":40296818},{"batb":[[0,1.81,6.9],[1,1.8,444],[2,1.74,17.32]],"ltp":2.26,"tv":28.21,"id":40296819}]}]}
{"op":"mcm","clk":"11843108919","pt":1723578076003,"mc":[{"id":"1.231732748","rc":[{"batb":[[0,1.76,10],[1,1.75,6.85],[2,1.74,17.32]],"ltp":2.14,"tv":24.44,"id":40296818},{"batb":[[0,1.82,10],[1,1.81,6.9],[2,1.8,444]],"ltp":2.26,"tv":28.21,"id":40296819}]}]}
{"op":"mcm","clk":"11843109368","pt":1723578079507,"mc":[{"id":"1.231732748","rc":[{"batb":[[0,1.75,6.85],[1,1.74,17.32],[2,1.25,100]],"ltp":2.14,"tv":24.44,"id":40296818},{"batb":[[0,1.81,6.9],[1,1.8,444],[2,1.74,17.32]],"ltp":2.26,"tv":28.21,"id":40296819}]}]}
{"op":"mcm","clk":"11843109770","pt":1723578082688,"mc":[{"id":"1.231732748","rc":[{"batb":[[0,1.76,10],[1,1.75,6.85],[2,1.74,17.32]],"ltp":2.14,"tv":24.44,"id":40296818},{"batb":[[0,1.82,10],[1,1.81,6.9],[2,1.8,444]],"ltp":2.26,"tv":28.21,"id":40296819}]}]}
{"op":"mcm","clk":"11843110282","pt":1723578086380,"mc":[{"id":"1.231732748","rc":[{"batb":[[0,1.75,6.85],[1,1.74,17.32],[2,1.25,100]],"ltp":2.14,"tv":24.44,"id":40296818},{"batb":[[0,1.81,6.9],[1,1.8,444],[2,1.74,17.32]],"ltp":2.26,"tv":28.21,"id":40296819}]}]}
{"op":"mcm","clk":"11843110792","pt":1723578090186,"mc":[{"id":"1.231732748","rc":[{"batb":[[0,1.76,10],[1,1.75,6.85],[2,1.74,17.32]],"ltp":2.14,"tv":24.44,"id":40296818},{"batb":[[0,1.82,10],[1,1.81,6.9],[2,1.8,444]],"ltp":2.26,"tv":28.21,"id":40296819}]}]}
{"op":"mcm","clk":"11843111264","pt":1723578094018,"mc":[{"id":"1.231732748","rc":[{"batb":[[0,1.75,6.85],[1,1.74,17.32],[2,1.25,100]],"ltp":2.14,"tv":24.44,"id":40296818},{"batb":[[0,1.81,6.9],[1,1.8,444],[2,1.74,17.32]],"ltp":2.26,"tv":28.21,"id":40296819}]}]}
{"op":"mcm","clk":"11843111925","pt":1723578099329,"mc":[{"id":"1.231732748","rc":[{"batb":[[0,1.76,10],[1,1.75,6.85],[2,1.74,17.32]],"ltp":2.14,"tv":24.44,"id":40296818},{"batb":[[0,1.82,10],[1,1.81,6.9],[2,1.8,444]],"ltp":2.26,"tv":28.21,"id":40296819}]}]}
{"op":"mcm","clk":"11843112396","pt":1723578102850,"mc":[{"id":"1.231732748","rc":[{"batb":[[0,1.75,6.85],[1,1.74,17.32],[2,1.25,100]],"ltp":2.14,"tv":24.44,"id":40296818},{"batb":[[0,1.81,6.9],[1,1.8,444],[2,1.74,17.32]],"ltp":2.26,"tv":28.21,"id":40296819}]}]}
{"op":"mcm","clk":"11843112746","pt":1723578106074,"mc":[{"id":"1.231732748","rc":[{"batb":[[0,1.76,10],[1,1.75,6.85],[2,1.74,17.32]],"ltp":2.14,"tv":24.44,"id":40296818},{"batb":[[0,1.82,10],[1,1.81,6.9],[2,1.8,444]],"ltp":2.26,"tv":28.21,"id":40296819}]}]}
{"op":"mcm","clk":"11843113227","pt":1723578109716,"mc":[{"id":"1.231732748","rc":[{"batb":[[0,1.75,6.85],[1,1.74,17.32],[2,1.25,100]],"ltp":2.14,"tv":24.44,"id":40296818},{"batb":[[0,1.81,6.9],[1,1.8,444],[2,1.74,17.32]],"ltp":2.26,"tv":28.21,"id":40296819}]}]}
{"op":"mcm","clk":"11843114264","pt":1723578117638,"mc":[{"id":"1.231732748","rc":[{"batb":[[0,1.76,10],[1,1.75,6.85],[2,1.74,17.32]],"ltp":2.14,"tv":24.44,"id":40296818},{"batb":[[0,1.82,10],[1,1.81,6.9],[2,1.8,444]],"ltp":2.26,"tv":28.21,"id":40296819}]}]}
{"op":"mcm","clk":"11843114731","pt":1723578121087,"mc":[{"id":"1.231732748","rc":[{"batb":[[0,1.75,6.85],[1,1.74,17.32],[2,1.25,100]],"ltp":2.14,"tv":24.44,"id":40296818},{"batb":[[0,1.81,6.9],[1,1.8,444],[2,1.74,17.32]],"ltp":2.26,"tv":28.21,"id":40296819}]}]}
{"op":"mcm","clk":"11843115424","pt":1723578125945,"mc":[{"id":"1.231732748","rc":[{"batb":[[0,1.76,10],[1,1.75,6.85],[2,1.74,17.32]],"ltp":2.14,"tv":24.44,"id":40296818},{"batb":[[0,1.82,10],[1,1.81,6.9],[2,1.8,444]],"ltp":2.26,"tv":28.21,"id":40296819}]}]}
{"op":"mcm","clk":"11843115945","pt":1723578129441,"mc":[{"id":"1.231732748","rc":[{"batb":[[0,1.75,6.85],[1,1.74,17.32],[2,1.25,100]],"ltp":2.14,"tv":24.44,"id":40296818},{"batb":[[0,1.81,6.9],[1,1.8,444],[2,1.74,17.32]],"ltp":2.26,"tv":28.21,"id":40296819}]}]}
{"op":"mcm","clk":"11843116981","pt":1723578136893,"mc":[{"id":"1.231732748","rc":[{"batb":[[0,1.76,10],[1,1.75,6.85],[2,1.74,17.32]],"ltp":2.14,"tv":24.44,"id":40296818},{"batb":[[0,1.82,10],[1,1.81,6.9],[2,1.8,444]],"ltp":2.26,"tv":28.21,"id":40296819}]}]}
{"op":"mcm","clk":"11843117409","pt":1723578140171,"mc":[{"id":"1.231732748","rc":[{"batb":[[0,1.75,6.85],[1,1.74,17.32],[2,1.25,100]],"ltp":2.14,"tv":24.44,"id":40296818},{"batb":[[0,1.81,6.9],[1,1.8,444],[2,1.74,17.32]],"ltp":2.26,"tv":28.21,"id":40296819}]}]}
{"op":"mcm","clk":"11843117808","pt":1723578143149,"mc":[{"id":"1.231732748","rc":[{"batb":[[0,1.76,10],[1,1.75,6.85],[2,1.74,17.32]],"ltp":2.14,"tv":24.44,"id":40296818},{"batb":[[0,1.82,10],[1,1.81,6.9],[2,1.8,444]],"ltp":2.26,"tv":28.21,"id":40296819}]}]}
{"op":"mcm","clk":"11843118307","pt":1723578146636,"mc":[{"id":"1.231732748","rc":[{"batb":[[0,1.75,6.85],[1,1.74,17.32],[2,1.25,100]],"ltp":2.14,"tv":24.44,"id":40296818},{"batb":[[0,1.81,6.9],[1,1.8,444],[2,1.74,17.32]],"ltp":2.26,"tv":28.21,"id":40296819}]}]}
{"op":"mcm","clk":"11843119331","pt":1723578154334,"mc":[{"id":"1.231732748","rc":[{"batb":[[0,1.76,10],[1,1.75,6.85],[2,1.74,17.32]],"ltp":2.14,"tv":24.44,"id":40296818},{"batb":[[0,1.82,10],[1,1.81,6.9],[2,1.8,444]],"ltp":2.26,"tv":28.21,"id":40296819}]}]}
{"op":"mcm","clk":"11843119823","pt":1723578157857,"mc":[{"id":"1.231732748","rc":[{"batb":[[0,1.75,6.85],[1,1.74,17.32],[2,1.25,100]],"ltp":2.14,"tv":24.44,"id":40296818},{"batb":[[0,1.81,6.9],[1,1.8,444],[2,1.74,17.32]],"ltp":2.26,"tv":28.21,"id":40296819}]}]}
{"op":"mcm","clk":"11843120218","pt":1723578160771,"mc":[{"id":"1.231732748","rc":[{"batb":[[0,1.76,10],[1,1.75,6.85],[2,1.74,17.32]],"ltp":2.14,"tv":24.44,"id":40296818},{"batb":[[0,1.82,10],[1,1.81,6.9],[2,1.8,444]],"ltp":2.26,"tv":28.21,"id":40296819}]}]}
{"op":"mcm","clk":"11843120638","pt":1723578164259,"mc":[{"id":"1.231732748","rc":[{"batb":[[0,1.75,6.85],[1,1.74,17.32],[2,1.25,100]],"ltp":2.14,"tv":24.44,"id":40296818},{"batb":[[0,1.81,6.9],[1,1.8,444],[2,1.74,17.32]],"ltp":2.26,"tv":28.21,"id":40296819}]}]}
{"op":"mcm","clk":"11843121417","pt":1723578170158,"mc":[{"id":"1.231732748","rc":[{"batb":[[0,1.76,10],[1,1.75,6.85],[2,1.74,17.32]],"ltp":2.14,"tv":24.44,"id":40296818},{"batb":[[0,1.82,10],[1,1.81,6.9],[2,1.8,444]],"ltp":2.26,"tv":28.21,"id":40296819}]}]}
{"op":"mcm","clk":"11843126189","pt":1723578174898,"mc":[{"id":"1.231732748","rc":[{"batb":[[0,1.75,6.85],[1,1.74,17.32],[2,1.25,100]],"ltp":2.14,"tv":24.44,"id":40296818},{"batb":[[0,1.81,6.9],[1,1.8,444],[2,1.74,17.32]],"ltp":2.26,"tv":28.21,"id":40296819}]}]}
{"op":"mcm","clk":"11843130317","pt":1723578176865,"mc":[{"id":"1.231732748","rc":[{"batb":[[0,1.76,10],[1,1.75,6.85],[2,1.74,17.32]],"ltp":2.14,"tv":24.44,"id":40296818},{"batb":[[0,1.82,10],[1,1.81,6.9],[2,1.8,444]],"ltp":2.26,"tv":28.21,"id":40296819}]}]}
{"op":"mcm","clk":"11843130805","pt":1723578180668,"mc":[{"id":"1.231732748","rc":[{"batb":[[0,1.75,6.85],[1,1.74,17.32],[2,1.25,100]],"ltp":2.14,"tv":24.44,"id":40296818},{"batb":[[0,1.81,6.9],[1,1.8,444],[2,1.74,17.32]],"ltp":2.26,"tv":28.21,"id":40296819}]}]}
{"op":"mcm","clk":"11843131182","pt":1723578183787,"mc":[{"id":"1.231732748","rc":[{"batb":[[0,1.76,10],[1,1.75,6.85],[2,1.74,17.32]],"ltp":2.14,"tv":24.44,"id":40296818},{"batb":[[0,1.82,10],[1,1.81,6.9],[2,1.8,444]],"ltp":2.26,"tv":28.21,"id":40296819}]}]}
{"op":"mcm","clk":"11843131612","pt":1723578187340,"mc":[{"id":"1.231732748","rc":[{"batb":[[0,1.75,6.85],[1,1.74,17.32],[2,1.25,100]],"ltp":2.14,"tv":24.44,"id":40296818},{"batb":[[0,1.81,6.9],[1,1.8,444],[2,1.74,17.32]],"ltp":2.26,"tv":28.21,"id":40296819}]}]}
{"op":"mcm","clk":"11843132019","pt":1723578190476,"mc":[{"id":"1.231732748","rc":[{"batb":[[0,1.76,10],[1,1.75,6.85],[2,1.74,17.32]],"ltp":2.14,"tv":24.44,"id":40296818},{"batb":[[0,1.82,10],[1,1.81,6.9],[2,1.8,444]],"ltp":2.26,"tv":28.21,"id":40296819}]}]}
{"op":"mcm","clk":"11843132471","pt":1723578194172,"mc":[{"id":"1.231732748","rc":[{"batb":[[0,1.75,6.85],[1,1.74,17.32],[2,1.25,100]],"ltp":2.14,"tv":24.44,"id":40296818},{"batb":[[0,1.81,6.9],[1,1.8,444],[2,1.74,17.32]],"ltp":2.26,"tv":28.21,"id":40296819}]}]}
{"op":"mcm","clk":"11843132952","pt":1723578198399,"mc":[{"id":"1.231732748","rc":[{"batb":[[0,1.76,10],[1,1.75,6.85],[2,1.74,17.32]],"ltp":2.14,"tv":24.44,"id":40296818},{"batb":[[0,1.82,10],[1,1.81,6.9],[2,1.8,444]],"ltp":2.26,"tv":28.21,"id":40296819}]}]}
{"op":"mcm","clk":"11843133370","pt":1723578201918,"mc":[{"id":"1.231732748","rc":[{"batb":[[0,1.75,6.85],[1,1.74,17.32],[2,1.25,100]],"ltp":2.14,"tv":24.44,"id":40296818},{"batb":[[0,1.81,6.9],[1,1.8,444],[2,1.74,17.32]],"ltp":2.26,"tv":28.21,"id":40296819}]}]}
{"op":"mcm","clk":"11843134194","pt":1723578208677,"mc":[{"id":"1.231732748","rc":[{"batb":[[0,1.76,10],[1,1.75,6.85],[2,1.74,17.32]],"ltp":2.14,"tv":24.44,"id":40296818},{"batb":[[0,1.82,10],[1,1.81,6.9],[2,1.8,444]],"ltp":2.26,"tv":28.21,"id":40296819}]}]}
{"op":"mcm","clk":"11843134636","pt":1723578212104,"mc":[{"id":"1.231732748","rc":[{"batb":[[0,1.75,6.85],[1,1.74,17.32],[2,1.25,100]],"ltp":2.14,"tv":24.44,"id":40296818},{"batb":[[0,1.81,6.9],[1,1.8,444],[2,1.74,17.32]],"ltp":2.26,"tv":28.21,"id":40296819}]}]}
{"op":"mcm","clk":"11843134987","pt":1723578215126,"mc":[{"id":"1.231732748","rc":[{"batb":[[0,1.76,10],[1,1.75,6.85],[2,1.74,17.32]],"ltp":2.14,"tv":24.44,"id":40296818},{"batb":[[0,1.82,10],[1,1.81,6.9],[2,1.8,444]],"ltp":2.26,"tv":28.21,"id":40296819}]}]}
{"op":"mcm","clk":"11843135436","pt":1723578218932,"mc":[{"id":"1.231732748","rc":[{"batb":[[0,1.75,6.85],[1,1.74,17.32],[2,1.25,100]],"ltp":2.14,"tv":24.44,"id":40296818},{"batb":[[0,1.81,6.9],[1,1.8,444],[2,1.74,17.32]],"ltp":2.26,"tv":28.21,"id":40296819}]}]}
{"op":"mcm","clk":"11843135745","pt":1723578221519,"mc":[{"id":"1.231732748","rc":[{"batb":[[0,1.76,10],[1,1.75,6.85],[2,1.74,17.32]],"ltp":2.14,"tv":24.44,"id":40296818},{"batb":[[0,1.82,10],[1,1.81,6.9],[2,1.8,444]],"ltp":2.26,"tv":28.21,"id":40296819}]}]}
{"op":"mcm","clk":"11843136149","pt":1723578225053,"mc":[{"id":"1.231732748","rc":[{"batb":[[0,1.75,6.85],[1,1.74,17.32],[2,1.25,100]],"ltp":2.14,"tv":24.44,"id":40296818},{"batb":[[0,1.81,6.9],[1,1.8,444],[2,1.74,17.32]],"ltp":2.26,"tv":28.21,"id":40296819}]}]}
{"op":"mcm","clk":"11843136728","pt":1723578230258,"mc":[{"id":"1.231732748","rc":[{"batb":[[0,1.76,10],[1,1.75,6.85],[2,1.74,17.32]],"ltp":2.14,"tv":24.44,"id":40296818},{"batb":[[0,1.82,10],[1,1.81,6.9],[2,1.8,444]],"ltp":2.26,"tv":28.21,"id":40296819}]}]}
{"op":"mcm","clk":"11843137147","pt":1723578233955,"mc":[{"id":"1.231732748","rc":[{"batb":[[0,1.75,6.85],[1,1.74,17.32],[2,1.25,100]],"ltp":2.14,"tv":24.44,"id":40296818},{"batb":[[0,1.81,6.9],[1,1.8,444],[2,1.74,17.32]],"ltp":2.26,"tv":28.21,"id":40296819}]}]}
{"op":"mcm","clk":"11843137526","pt":1723578237020,"mc":[{"id":"1.231732748","rc":[{"batb":[[0,1.76,10],[1,1.75,6.85],[2,1.74,17.32]],"ltp":2.14,"tv":24.44,"id":40296818},{"batb":[[0,1.82,10],[1,1.81,6.9],[2,1.8,444]],"ltp":2.26,"tv":28.21,"id":40296819}]}]}
{"op":"mcm","clk":"11843137989","pt":1723578240475,"mc":[{"id":"1.231732748","rc":[{"batb":[[0,1.75,6.85],[1,1.74,17.32],[2,1.25,100]],"ltp":2.14,"tv":24.44,"id":40296818},{"batb":[[0,1.81,6.9],[1,1.8,444],[2,1.74,17.32]],"ltp":2.26,"tv":28.21,"id":40296819}]}]}
{"op":"mcm","clk":"11843138341","pt":1723578243166,"mc":[{"id":"1.231732748","rc":[{"batb":[[0,1.76,10],[1,1.75,6.85],[2,1.74,17.32]],"ltp":2.14,"tv":24.44,"id":40296818},{"batb":[[0,1.82,10],[1,1.81,6.9],[2,1.8,444]],"ltp":2.26,"tv":28.21,"id":40296819}]}]}
{"op":"mcm","clk":"11843138849","pt":1723578246964,"mc":[{"id":"1.231732748","rc":[{"batb":[[0,1.75,6.85],[1,1.74,17.32],[2,1.25,100]],"ltp":2.14,"tv":24.44,"id":40296818},{"batb":[[0,1.81,6.9],[1,1.8,444],[2,1.74,17.32]],"ltp":2.26,"tv":28.21,"id":40296819}]}]}
{"op":"mcm","clk":"11843139205","pt":1723578249611,"mc":[{"id":"1.231732748","rc":[{"batb":[[0,1.76,10],[1,1.75,6.85],[2,1.74,17.32]],"ltp":2.14,"tv":24.44,"id":40296818},{"batb":[[0,1.82,10],[1,1.81,6.9],[2,1.8,444]],"ltp":2.26,"tv":28.21,"id":40296819}]}]}
{"op":"mcm","clk":"11843139752","pt":1723578253804,"mc":[{"id":"1.231732748","rc":[{"batb":[[0,1.75,6.85],[1,1.74,17.32],[2,1.25,100]],"ltp":2.14,"tv":24.44,"id":40296818},{"batb":[[0,1.81,6.9],[1,1.8,444],[2,1.74,17.32]],"ltp":2.26,"tv":28.21,"id":40296819}]}]}
{"op":"mcm","clk":"11843140048","pt":1723578255973,"mc":[{"id":"1.231732748","rc":[{"batb":[[0,1.76,10],[1,1.75,6.85],[2,1.74,17.32]],"ltp":2.14,"tv":24.44,"id":40296818},{"batb":[[0,1.82,10],[1,1.81,6.9],[2,1.8,444]],"ltp":2.26,"tv":28.21,"id":40296819}]}]}
{"op":"mcm","clk":"11843140542","pt":1723578259869,"mc":[{"id":"1.231732748","rc":[{"batb":[[0,1.75,6.85],[1,1.74,17.32],[2,1.25,100]],"ltp":2.14,"tv":24.44,"id":40296818},{"batb":[[0,1.81,6.9],[1,1.8,444],[2,1.74,17.32]],"ltp":2.26,"tv":28.21,"id":40296819}]}]}
{"op":"mcm","clk":"11843140965","pt":1723578263344,"mc":[{"id":"1.231732748","rc":[{"batb":[[0,1.76,10],[1,1.75,6.85],[2,1.74,17.32]],"ltp":2.14,"tv":24.44,"id":40296818},{"batb":[[0,1.82,10],[1,1.81,6.9],[2,1.8,444]],"ltp":2.26,"tv":28.21,"id":40296819}]}]}
{"op":"mcm","clk":"11843141406","pt":1723578266778,"mc":[{"id":"1.231732748","rc":[{"batb":[[0,1.75,6.85],[1,1.74,17.32],[2,1.25,100]],"ltp":2.14,"tv":24.44,"id":40296818},{"batb":[[0,1.81,6.9],[1,1.8,444],[2,1.74,17.32]],"ltp":2.26,"tv":28.21,"id":40296819}]}]}
{"op":"mcm","clk":"11843141884","pt":1723578270265,"mc":[{"id":"1.231732748","rc":[{"batb":[[0,1.76,10],[1,1.75,6.85],[2,1.74,17.32]],"ltp":2.14,"tv":24.44,"id":40296818},{"batb":[[0,1.82,10],[1,1.81,6.9],[2,1.8,444]],"ltp":2.26,"tv":28.21,"id":40296819}]}]}
{"op":"mcm","clk":"11843142333","pt":1723578273860,"mc":[{"id":"1.231732748","rc":[{"batb":[[0,1.75,6.85],[1,1.74,17.32],[2,1.25,100]],"ltp":2.14,"tv":24.44,"id":40296818},{"batb":[[0,1.81,6.9],[1,1.8,444],[2,1.74,17.32]],"ltp":2.26,"tv":28.21,"id":40296819}]}]}
{"op":"mcm","clk":"11843142662","pt":1723578276667,"mc":[{"id":"1.231732748","rc":[{"batb":[[0,1.76,10],[1,1.75,6.85],[2,1.74,17.32]],"ltp":2.14,"tv":24.44,"id":40296818},{"batb":[[0,1.82,10],[1,1.81,6.9],[2,1.8,444]],"ltp":2.26,"tv":28.21,"id":40296819}]}]}
{"op":"mcm","clk":"11843143104","pt":1723578280361,"mc":[{"id":"1.231732748","rc":[{"batb":[[0,1.75,6.85],[1,1.74,17.32],[2,1.25,100]],"ltp":2.14,"tv":24.44,"id":40296818},{"batb":[[0,1.81,6.9],[1,1.8,444],[2,1.74,17.32]],"ltp":2.26,"tv":28.21,"id":40296819}]}]}
{"op":"mcm","clk":"11843143983","pt":1723578286790,"mc":[{"id":"1.231732748","rc":[{"batb":[[0,1.76,10],[1,1.75,6.85],[2,1.74,17.32]],"ltp":2.14,"tv":24.44,"id":40296818},{"batb":[[0,1.82,10],[1,1.81,6.9],[2,1.8,444]],"ltp":2.26,"tv":28.21,"id":40296819}]}]}
{"op":"mcm","clk":"11843144499","pt":1723578290515,"mc":[{"id":"1.231732748","rc":[{"batb":[[0,1.75,6.85],[1,1.74,17.32],[2,1.25,100]],"ltp":2.14,"tv":24.44,"id":40296818},{"batb":[[0,1.81,6.9],[1,1.8,444],[2,1.74,17.32]],"ltp":2.26,"tv":28.21,"id":40296819}]}]}
{"op":"mcm","clk":"11843145075","pt":1723578294796,"mc":[{"id":"1.231732748","rc":[{"batb":[[0,1.76,10],[1,1.75,6.85],[2,1.74,17.32]],"ltp":2.14,"tv":24.44,"id":40296818},{"batb":[[0,1.82,10],[1,1.81,6.9],[2,1.8,444]],"ltp":2.26,"tv":28.21,"id":40296819}]}]}
{"op":"mcm","clk":"11843145606","pt":1723578298604,"mc":[{"id":"1.231732748","rc":[{"batb":[[0,1.75,6.85],[1,1.74,17.32],[2,1.25,100]],"ltp":2.14,"tv":24.44,"id":40296818},{"batb":[[0,1.81,6.9],[1,1.8,444],[2,1.74,17.32]],"ltp":2.26,"tv":28.21,"id":40296819}]}]}
{"op":"mcm","clk":"11843145990","pt":1723578301471,"mc":[{"id":"1.231732748","rc":[{"batb":[[0,1.76,10],[1,1.75,6.85],[2,1.74,17.32]],"ltp":2.14,"tv":24.44,"id":40296818},{"batb":[[0,1.82,10],[1,1.81,6.9],[2,1.8,444]],"ltp":2.26,"tv":28.21,"id":40296819}]}]}
{"op":"mcm","clk":"11843146500","pt":1723578305301,"mc":[{"id":"1.231732748","rc":[{"batb":[[0,1.75,6.85],[1,1.74,17.32],[2,1.25,100]],"ltp":2.14,"tv":24.44,"id":40296818},{"batb":[[0,1.81,6.9],[1,1.8,444],[2,1.74,17.32]],"ltp":2.26,"tv":28.21,"id":40296819}]}]}
{"op":"mcm","clk":"11843147495","pt":1723578313510,"mc":[{"id":"1.231732748","rc":[{"batb":[[0,1.76,10],[1,1.75,6.85],[2,1.74,17.32]],"ltp":2.14,"tv":24.44,"id":40296818},{"batb":[[0,1.82,10],[1,1.81,6.9],[2,1.8,444]],"ltp":2.26,"tv":28.21,"id":40296819}]}]}
{"op":"mcm","clk":"11843148039","pt":1723578317416,"mc":[{"id":"1.231732748","rc":[{"batb":[[0,1.75,6.85],[1,1.74,17.32],[2,1.25,100]],"ltp":2.14,"tv":24.44,"id":40296818},{"batb":[[0,1.81,6.9],[1,1.8,444],[2,1.74,17.32]],"ltp":2.26,"tv":28.21,"id":40296819}]}]}
{"op":"mcm","clk":"11843148359","pt":1723578320023,"mc":[{"id":"1.231732748","rc":[{"batb":[[0,1.76,10],[1,1.75,6.85],[2,1.74,17.32]],"ltp":2.14,"tv":24.44,"id":40296818},{"batb":[[0,1.82,10],[1,1.81,6.9],[2,1.8,444]],"ltp":2.26,"tv":28.21,"id":40296819}]}]}
{"op":"mcm","clk":"11843148842","pt":1723578324024,"mc":[{"id":"1.231732748","rc":[{"batb":[[0,1.75,6.85],[1,1.74,17.32],[2,1.25,100]],"ltp":2.14,"tv":24.44,"id":40296818},{"batb":[[0,1.81,6.9],[1,1.8,444],[2,1.74,17.32]],"ltp":2.26,"tv":28.21,"id":40296819}]}]}
{"op":"mcm","clk":"11843149489","pt":1723578329230,"mc":[{"id":"1.231732748","rc":[{"batb":[[0,1.76,10],[1,1.75,6.85],[2,1.74,17.32]],"ltp":2.14,"tv":24.44,"id":40296818},{"batb":[[0,1.82,10],[1,1.81,6.9],[2,1.8,444]],"ltp":2.26,"tv":28.21,"id":40296819}]}]}
{"op":"mcm","clk":"11843149921","pt":1723578332822,"mc":[{"id":"1.231732748","rc":[{"batb":[[0,1.75,6.85],[1,1.74,17.32],[2,1.25,100]],"ltp":2.14,"tv":24.44,"id":40296818},{"batb":[[0,1.81,6.9],[1,1.8,444],[2,1.74,17.32]],"ltp":2.26,"tv":28.21,"id":40296819}]}]}
{"op":"mcm","clk":"11843150209","pt":1723578335267,"mc":[{"id":"1.231732748","rc":[{"batb":[[0,1.76,10],[1,1.75,6.85],[2,1.74,17.32]],"ltp":2.14,"tv":24.44,"id":40296818},{"batb":[[0,1.82,10],[1,1.81,6.9],[2,1.8,444]],"ltp":2.26,"tv":28.21,"id":40296819}]}]}
{"op":"mcm","clk":"11843150618","pt":1723578339141,"mc":[{"id":"1.231732748","rc":[{"batb":[[0,1.75,6.85],[1,1.74,17.32],[2,1.25,100]],"ltp":2.14,"tv":24.44,"id":40296818},{"batb":[[0,1.81,6.9],[1,1.8,444],[2,1.74,17.32]],"ltp":2.26,"tv":28.21,"id":40296819}]}]}
{"op":"mcm","clk":"11843150895","pt":1723578341741,"mc":[{"id":"1.231732748","rc":[{"batb":[[0,1.76,10],[1,1.75,6.85],[2,1.74,17.32]],"ltp":2.14,"tv":24.44,"id":40296818},{"batb":[[0,1.82,10],[1,1.81,6.9],[2,1.8,444]],"ltp":2.26,"tv":28.21,"id":40296819}]}]}
{"op":"mcm","clk":"11843151298","pt":1723578345236,"mc":[{"id":"1.231732748","rc":[{"batb":[[0,1.75,6.85],[1,1.74,17.32],[2,1.25,100]],"ltp":2.14,"tv":24.44,"id":40296818},{"batb":[[0,1.81,6.9],[1,1.8,444],[2,1.74,17.32]],"ltp":2.26,"tv":28.21,"id":40296819}]}]}
{"op":"mcm","clk":"11843151615","pt":1723578348250,"mc":[{"id":"1.231732748","rc":[{"batb":[[0,1.76,10],[1,1.75,6.85],[2,1.74,17.32]],"ltp":2.14,"tv":24.44,"id":40296818},{"batb":[[0,1.82,10],[1,1.81,6.9],[2,1.8,444]],"ltp":2.26,"tv":28.21,"id":40296819}]}]}
{"op":"mcm","clk":"11843151984","pt":1723578351878,"mc":[{"id":"1.231732748","rc":[{"batb":[[0,1.75,6.85],[1,1.74,17.32],[2,1.25,100]],"ltp":2.14,"tv":24.44,"id":40296818},{"batb":[[0,1.81,6.9],[1,1.8,444],[2,1.74,17.32]],"ltp":2.26,"tv":28.21,"id":40296819}]}]}
{"op":"mcm","clk":"11843152354","pt":1723578355358,"mc":[{"id":"1.231732748","rc":[{"batb":[[0,1.76,10],[1,1.75,6.85],[2,1.74,17.32]],"ltp":2.14,"tv":24.44,"id":40296818},{"batb":[[0,1.82,10],[1,1.81,6.9],[2,1.8,444]],"ltp":2.26,"tv":28.21,"id":40296819}]}]}
{"op":"mcm","clk":"11843152726","pt":1723578359055,"mc":[{"id":"1.231732748","rc":[{"batb":[[0,1.75,6.85],[1,1.74,17.32],[2,1.25,100]],"ltp":2.14,"tv":24.44,"id":40296818},{"batb":[[0,1.81,6.9],[1,1.8,444],[2,1.74,17.32]],"ltp":2.26,"tv":28.21,"id":40296819}]}]}
{"op":"mcm","clk":"11843153111","pt":1723578362786,"mc":[{"id":"1.231732748","rc":[{"batb":[[0,1.76,10],[1,1.75,6.85],[2,1.74,17.32]],"ltp":2.14,"tv":24.44,"id":40296818},{"batb":[[0,1.82,10],[1,1.81,6.9],[2,1.8,444]],"ltp":2.26,"tv":28.21,"id":40296819}]}]}
{"op":"mcm","clk":"11843153512","pt":1723578366270,"mc":[{"id":"1.231732748","rc":[{"batb":[[0,1.75,6.85],[1,1.74,17.32],[2,1.25,100]],"ltp":2.14,"tv":24.44,"id":40296818},{"batb":[[0,1.81,6.9],[1,1.8,444],[2,1.74,17.32]],"ltp":2.26,"tv":28.21,"id":40296819}]}]}
{"op":"mcm","clk":"11843153855","pt":1723578369379,"mc":[{"id":"1.231732748","rc":[{"batb":[[0,1.76,10],[1,1.75,6.85],[2,1.74,17.32]],"ltp":2.14,"tv":24.44,"id":40296818},{"batb":[[0,1.82,10],[1,1.81,6.9],[2,1.8,444]],"ltp":2.26,"tv":28.21,"id":40296819}]}]}
{"op":"mcm","clk":"11843154261","pt":1723578373285,"mc":[{"id":"1.231732748","rc":[{"batb":[[0,1.75,6.85],[1,1.74,17.32],[2,1.25,100]],"ltp":2.14,"tv":24.44,"id":40296818},{"batb":[[0,1.81,6.9],[1,1.8,444],[2,1.74,17.32]],"ltp":2.26,"tv":28.21,"id":40296819}]}]}
{"op":"mcm","clk":"11843154739","pt":1723578376884,"mc":[{"id":"1.231732748","rc":[{"batb":[[0,1.76,10],[1,1.75,6.85],[2,1.74,17.32]],"ltp":2.14,"tv":24.44,"id":40296818},{"batb":[[0,1.82,10],[1,1.81,6.9],[2,1.8,444]],"ltp":2.26,"tv":28.21,"id":40296819}]}]}
{"op":"mcm","clk":"11843155153","pt":1723578380684,"mc":[{"id":"1.231732748","rc":[{"batb":[[0,1.75,6.85],[1,1.74,17.32],[2,1.25,100]],"ltp":2.14,"tv":24.44,"id":40296818},{"batb":[[0,1.81,6.9],[1,1.8,444],[2,1.74,17.32]],"ltp":2.26,"tv":28.21,"id":40296819}]}]}
{"op":"mcm","clk":"11843155931","pt":1723578387229,"mc":[{"id":"1.231732748","rc":[{"batb":[[0,1.76,10],[1,1.75,6.85],[2,1.74,17.32]],"ltp":2.14,"tv":24.44,"id":40296818},{"batb":[[0,1.82,10],[1,1.81,6.9],[2,1.8,444]],"ltp":2.26,"tv":28.21,"id":40296819}]}]}
{"op":"mcm","clk":"11843156378","pt":1723578390626,"mc":[{"id":"1.231732748","rc":[{"batb":[[0,1.75,6.85],[1,1.74,17.32],[2,1.25,100]],"ltp":2.14,"tv":24.44,"id":40296818},{"batb":[[0,1.81,6.9],[1,1.8,444],[2,1.74,17.32]],"ltp":2.26,"tv":28.21,"id":40296819}]}]}
{"op":"mcm","clk":"11843156852","pt":1723578394337,"mc":[{"id":"1.231732748","rc":[{"batb":[[0,1.76,10],[1,1.75,6.85],[2,1.74,17.32]],"ltp":2.14,"tv":24.44,"id":40296818},{"batb":[[0,1.82,10],[1,1.81,6.9],[2,1.8,444]],"ltp":2.26,"tv":28.21,"id":40296819}]}]}
{"op":"mcm","clk":"11843157338","pt":1723578398198,"mc":[{"id":"1.231732748","rc":[{"batb":[[0,1.75,6.85],[1,1.74,17.32],[2,1.25,100]],"ltp":2.14,"tv":24.44,"id":40296818},{"batb":[[0,1.81,6.9],[1,1.8,444],[2,1.74,17.32]],"ltp":2.26,"tv":28.21,"id":40296819}]}]}
{"op":"mcm","clk":"11843157664","pt":1723578401056,"mc":[{"id":"1.231732748","rc":[{"batb":[[0,1.76,10],[1,1.75,6.85],[2,1.74,17.32]],"ltp":2.14,"tv":24.44,"id":40296818},{"batb":[[0,1.82,10],[1,1.81,6.9],[2,1.8,444]],"ltp":2.26,"tv":28.21,"id":40296819}]}]}
{"op":"mcm","clk":"11843158054","pt":1723578404654,"mc":[{"id":"1.231732748","rc":[{"batb":[[0,1.75,6.85],[1,1.74,17.32],[2,1.25,100]],"ltp":2.14,"tv":24.44,"id":40296818},{"batb":[[0,1.81,6.9],[1,1.8,444],[2,1.74,17.32]],"ltp":2.26,"tv":28.21,"id":40296819}]}]}
{"op":"mcm","clk":"11843158571","pt":1723578409285,"mc":[{"id":"1.231732748","rc":[{"batb":[[0,1.76,10],[1,1.75,6.85],[2,1.74,17.32]],"ltp":2.14,"tv":24.44,"id":40296818},{"batb":[[0,1.82,10],[1,1.81,6.9],[2,1.8,444]],"ltp":2.26,"tv":28.21,"id":40296819}]}]}
{"op":"mcm","clk":"11843159013","pt":1723578412778,"mc":[{"id":"1.231732748","rc":[{"batb":[[0,1.75,6.85],[1,1.74,17.32],[2,1.25,100]],"ltp":2.14,"tv":24.44,"id":40296818},{"batb":[[0,1.81,6.9],[1,1.8,444],[2,1.74,17.32]],"ltp":2.26,"tv":28.21,"id":40296819}]}]}
{"op":"mcm","clk":"11843159432","pt":1723578415919,"mc":[{"id":"1.231732748","rc":[{"batb":[[0,1.76,10],[1,1.75,6.85],[2,1.74,17.32]],"ltp":2.14,"tv":24.44,"id":40296818},{"batb":[[0,1.82,10],[1,1.81,6.9],[2,1.8,444]],"ltp":2.26,"tv":28.21,"id":40296819}]}]}
{"op":"mcm","clk":"11843159870","pt":1723578419735,"mc":[{"id":"1.231732748","rc":[{"batb":[[0,1.75,6.85],[1,1.74,17.32],[2,1.25,100]],"ltp":2.14,"tv":24.44,"id":40296818},{"batb":[[0,1.81,6.9],[1,1.8,444],[2,1.74,17.32]],"ltp":2.26,"tv":28.21,"id":40296819}]}]}
{"op":"mcm","clk":"11843160031","pt":1723578420908,"mc":[{"id":"1.231732748","rc":[{"batb":[[0,2.32,1.17],[1,1.81,6.9],[2,1.8,444]],"ltp":2.26,"tv":28.21,"id":40296819}]}]}
{"op":"mcm","clk":"11843160305","pt":1723578422931,"mc":[{"id":"1.231732748","rc":[{"trd":[[1.76,1.54]],"batb":[[0,1.76,8.46],[1,1.75,6.85],[2,1.74,17.32]],"ltp":1.76,"tv":25.98,"id":40296818},{"trd":[[2.32,1.17]],"batb":[[0,1.81,6.9],[1,1.8,444],[2,1.74,17.32]],"ltp":2.32,"tv":29.38,"id":40296819}],"tv":55.36}]}
{"op":"mcm","clk":"11843160332","pt":1723578423086,"mc":[{"id":"1.231732748","rc":[{"batb":[[0,1.82,10],[1,1.81,6.9],[2,1.8,444]],"ltp":2.32,"tv":29.38,"id":40296819}]}]}
{"op":"mcm","clk":"11843160841","pt":1723578426882,"mc":[{"id":"1.231732748","rc":[{"batb":[[0,1.75,6.85],[1,1.74,17.32],[2,1.25,100]],"ltp":1.76,"tv":25.98,"id":40296818},{"batb":[[0,1.81,6.9],[1,1.8,444],[2,1.74,17.32]],"ltp":2.32,"tv":29.38,"id":40296819}]}]}
{"op":"mcm","clk":"11843161287","pt":1723578429874,"mc":[{"id":"1.231732748","rc":[{"batb":[[0,1.76,10],[1,1.75,6.85],[2,1.74,17.32]],"ltp":1.76,"tv":25.98,"id":40296818},{"trd":[[1.82,2.96]],"batb":[[0,1.82,8.52],[1,1.81,6.9],[2,1.8,444]],"ltp":1.82,"tv":32.34,"id":40296819}],"tv":58.33}]}
{"op":"mcm","clk":"11843161739","pt":1723578433173,"mc":[{"id":"1.231732748","rc":[{"batb":[[0,1.75,6.85],[1,1.74,17.32],[2,1.25,100]],"ltp":1.76,"tv":25.98,"id":40296818},{"batb":[[0,1.81,6.9],[1,1.8,444],[2,1.74,17.32]],"ltp":1.82,"tv":32.34,"id":40296819}]}]}
{"op":"mcm","clk":"11843162273","pt":1723578436780,"mc":[{"id":"1.231732748","rc":[{"batb":[[0,1.76,10],[1,1.75,6.85],[2,1.74,17.32]],"ltp":1.76,"tv":25.98,"id":40296818},{"batb":[[0,1.82,10],[1,1.81,6.9],[2,1.8,444]],"ltp":1.82,"tv":32.34,"id":40296819}]}]}
{"op":"mcm","clk":"11843162577","pt":1723578439183,"mc":[{"id":"1.231732748","rc":[{"batb":[[0,2.2,1.17],[1,1.76,10],[2,1.75,6.85]],"ltp":1.76,"tv":25.98,"id":40296818}]}]}
{"op":"mcm","clk":"11843162730","pt":1723578440412,"mc":[{"id":"1.231732748","rc":[{"batb":[[1,1.75,6.85],[2,1.74,17.32]],"ltp":1.76,"tv":25.98,"id":40296818},{"batb":[[0,1.81,6.9],[1,1.8,444],[2,1.74,17.32]],"ltp":1.82,"tv":32.34,"id":40296819}]}]}
{"op":"mcm","clk":"11843163059","pt":1723578442956,"mc":[{"id":"1.231732748","rc":[{"batb":[[0,1.82,10],[1,1.81,6.9],[2,1.8,444]],"ltp":1.82,"tv":32.34,"id":40296819}]}]}
{"op":"mcm","clk":"11843163476","pt":1723578446492,"mc":[{"id":"1.231732748","rc":[{"batb":[[0,1.81,6.9],[1,1.8,444],[2,1.74,17.32]],"ltp":1.82,"tv":32.34,"id":40296819}]}]}
{"op":"mcm","clk":"11843164082","pt":1723578451094,"mc":[{"id":"1.231732748","rc":[{"batb":[[0,1.82,10],[1,1.81,6.9],[2,1.8,444]],"ltp":1.82,"tv":32.34,"id":40296819}]}]}
{"op":"mcm","clk":"11843164547","pt":1723578454892,"mc":[{"id":"1.231732748","rc":[{"batb":[[0,1.81,6.9],[1,1.8,444],[2,1.74,17.32]],"ltp":1.82,"tv":32.34,"id":40296819}]}]}
{"op":"mcm","clk":"11843164900","pt":1723578457497,"mc":[{"id":"1.231732748","rc":[{"batb":[[0,1.82,10],[1,1.81,6.9],[2,1.8,444]],"ltp":1.82,"tv":32.34,"id":40296819}]}]}
{"op":"mcm","clk":"11843165381","pt":1723578461214,"mc":[{"id":"1.231732748","rc":[{"batb":[[0,1.81,6.9],[1,1.8,444],[2,1.74,17.32]],"ltp":1.82,"tv":32.34,"id":40296819}]}]}
{"op":"mcm","clk":"11843165785","pt":1723578464514,"mc":[{"id":"1.231732748","rc":[{"batb":[[0,1.82,10],[1,1.81,6.9],[2,1.8,444]],"ltp":1.82,"tv":32.34,"id":40296819}]}]}
{"op":"mcm","clk":"11843166170","pt":1723578467833,"mc":[{"id":"1.231732748","rc":[{"batb":[[0,1.81,6.9],[1,1.8,444],[2,1.74,17.32]],"ltp":1.82,"tv":32.34,"id":40296819}]}]}
{"op":"mcm","clk":"11843166487","pt":1723578470409,"mc":[{"id":"1.231732748","rc":[{"batb":[[0,1.82,10],[1,1.81,6.9],[2,1.8,444]],"ltp":1.82,"tv":32.34,"id":40296819}]}]}
{"op":"mcm","clk":"11843166906","pt":1723578473714,"mc":[{"id":"1.231732748","rc":[{"batb":[[0,1.81,6.9],[1,1.8,444],[2,1.74,17.32]],"ltp":1.82,"tv":32.34,"id":40296819}]}]}
{"op":"mcm","clk":"11843167324","pt":1723578476935,"mc":[{"id":"1.231732748","rc":[{"batb":[[0,1.82,10],[1,1.81,6.9],[2,1.8,444]],"ltp":1.82,"tv":32.34,"id":40296819}]}]}
{"op":"mcm","clk":"11843167783","pt":1723578480451,"mc":[{"id":"1.231732748","rc":[{"batb":[[0,1.81,6.9],[1,1.8,444],[2,1.74,17.32]],"ltp":1.82,"tv":32.34,"id":40296819}]}]}
{"op":"mcm","clk":"11843168133","pt":1723578483244,"mc":[{"id":"1.231732748","rc":[{"batb":[[0,1.82,10],[1,1.81,6.9],[2,1.8,444]],"ltp":1.82,"tv":32.34,"id":40296819}]}]}
{"op":"mcm","clk":"11843168645","pt":1723578486955,"mc":[{"id":"1.231732748","rc":[{"batb":[[0,1.81,6.9],[1,1.8,444],[2,1.74,17.32]],"ltp":1.82,"tv":32.34,"id":40296819}]}]}
{"op":"mcm","clk":"11843169189","pt":1723578490937,"mc":[{"id":"1.231732748","rc":[{"batb":[[0,1.82,10],[1,1.81,6.9],[2,1.8,444]],"ltp":1.82,"tv":32.34,"id":40296819}]}]}
{"op":"mcm","clk":"11843169655","pt":1723578494364,"mc":[{"id":"1.231732748","rc":[{"batb":[[0,1.81,6.9],[1,1.8,444],[2,1.74,17.32]],"ltp":1.82,"tv":32.34,"id":40296819}]}]}
{"op":"mcm","clk":"11843170081","pt":1723578497376,"mc":[{"id":"1.231732748","rc":[{"batb":[[0,1.82,10],[1,1.81,6.9],[2,1.8,444]],"ltp":1.82,"tv":32.34,"id":40296819}]}]}
{"op":"mcm","clk":"11843170563","pt":1723578500679,"mc":[{"id":"1.231732748","rc":[{"batb":[[0,1.81,6.9],[1,1.8,444],[2,1.74,17.32]],"ltp":1.82,"tv":32.34,"id":40296819}]}]}
{"op":"mcm","clk":"11843171170","pt":1723578504671,"mc":[{"id":"1.231732748","rc":[{"batb":[[0,1.82,10],[1,1.81,6.9],[2,1.8,444]],"ltp":1.82,"tv":32.34,"id":40296819}]}]}
{"op":"mcm","clk":"11843171639","pt":1723578508062,"mc":[{"id":"1.231732748","rc":[{"batb":[[0,1.81,6.9],[1,1.8,444],[2,1.74,17.32]],"ltp":1.82,"tv":32.34,"id":40296819}]}]}
{"op":"mcm","clk":"11843172114","pt":1723578510683,"mc":[{"id":"1.231732748","rc":[{"batb":[[0,1.82,10],[1,1.81,6.9],[2,1.8,444]],"ltp":1.82,"tv":32.34,"id":40296819}]}]}
{"op":"mcm","clk":"11843172672","pt":1723578514394,"mc":[{"id":"1.231732748","rc":[{"batb":[[0,1.81,6.9],[1,1.8,444],[2,1.74,17.32]],"ltp":1.82,"tv":32.34,"id":40296819}]}]}
{"op":"mcm","clk":"11843172864","pt":1723578515701,"mc":[{"id":"1.231732748","rc":[{"batb":[[0,1.75,6.85],[1,1.74,17.32],[2,1.25,100]],"ltp":1.76,"tv":25.98,"id":40296818}]}]}
{"op":"mcm","clk":"11843173003","pt":1723578516607,"mc":[{"id":"1.231732748","rc":[{"batb":[[0,1.76,10],[1,1.75,6.85],[2,1.74,17.32]],"ltp":1.76,"tv":25.98,"id":40296818},{"batb":[[0,1.82,10],[1,1.81,6.9],[2,1.8,444]],"ltp":1.82,"tv":32.34,"id":40296819}]}]}
{"op":"mcm","clk":"11843173535","pt":1723578520315,"mc":[{"id":"1.231732748","rc":[{"batb":[[0,1.75,6.85],[1,1.74,17.32],[2,1.25,100]],"ltp":1.76,"tv":25.98,"id":40296818},{"batb":[[0,1.81,6.9],[1,1.8,444],[2,1.74,17.32]],"ltp":1.82,"tv":32.34,"id":40296819}]}]}
{"op":"mcm","clk":"11843174052","pt":1723578523734,"mc":[{"id":"1.231732748","rc":[{"batb":[[0,1.76,10],[1,1.75,6.85],[2,1.74,17.32]],"ltp":1.76,"tv":25.98,"id":40296818},{"batb":[[0,1.82,10],[1,1.81,6.9],[2,1.8,444]],"ltp":1.82,"tv":32.34,"id":40296819}]}]}
{"op":"mcm","clk":"11843174656","pt":1723578527734,"mc":[{"id":"1.231732748","rc":[{"batb":[[0,1.75,6.85],[1,1.74,17.32],[2,1.25,100]],"ltp":1.76,"tv":25.98,"id":40296818},{"batb":[[0,1.81,6.9],[1,1.8,444],[2,1.74,17.32]],"ltp":1.82,"tv":32.34,"id":40296819}]}]}
{"op":"mcm","clk":"11843175093","pt":1723578530726,"mc":[{"id":"1.231732748","rc":[{"batb":[[0,1.76,10],[1,1.75,6.85],[2,1.74,17.32]],"ltp":1.76,"tv":25.98,"id":40296818},{"batb":[[0,1.82,10],[1,1.81,6.9],[2,1.8,444]],"ltp":1.82,"tv":32.34,"id":40296819}]}]}
{"op":"mcm","clk":"11843175553","pt":1723578534035,"mc":[{"id":"1.231732748","rc":[{"batb":[[0,1.75,6.85],[1,1.74,17.32],[2,1.25,100]],"ltp":1.76,"tv":25.98,"id":40296818},{"batb":[[0,1.81,6.9],[1,1.8,444],[2,1.74,17.32]],"ltp":1.82,"tv":32.34,"id":40296819}]}]}
{"op":"mcm","clk":"11843175937","pt":1723578536762,"mc":[{"id":"1.231732748","rc":[{"batb":[[0,1.76,10],[1,1.75,6.85],[2,1.74,17.32]],"ltp":1.76,"tv":25.98,"id":40296818},{"batb":[[0,1.82,10],[1,1.81,6.9],[2,1.8,444]],"ltp":1.82,"tv":32.34,"id":40296819}]}]}
{"op":"mcm","clk":"11843176485","pt":1723578540323,"mc":[{"id":"1.231732748","rc":[{"batb":[[0,1.75,6.85],[1,1.74,17.32],[2,1.25,100]],"ltp":1.76,"tv":25.98,"id":40296818},{"batb":[[0,1.81,6.9],[1,1.8,444],[2,1.74,17.32]],"ltp":1.82,"tv":32.34,"id":40296819}]}]}
{"op":"mcm","clk":"11843177648","pt":1723578547644,"mc":[{"id":"1.231732748","rc":[{"batb":[[0,1.76,10],[1,1.75,6.85],[2,1.74,17.32]],"ltp":1.76,"tv":25.98,"id":40296818},{"batb":[[0,1.82,10],[1,1.81,6.9],[2,1.8,444]],"ltp":1.82,"tv":32.34,"id":40296819}]}]}
{"op":"mcm","clk":"11843178183","pt":1723578551056,"mc":[{"id":"1.231732748","rc":[{"batb":[[0,1.75,6.85],[1,1.74,17.32],[2,1.25,100]],"ltp":1.76,"tv":25.98,"id":40296818},{"batb":[[0,1.81,6.9],[1,1.8,444],[2,1.74,17.32]],"ltp":1.82,"tv":32.34,"id":40296819}]}]}
{"op":"mcm","clk":"11843179085","pt":1723578556765,"mc":[{"id":"1.231732748","rc":[{"batb":[[0,1.76,10],[1,1.75,6.85],[2,1.74,17.32]],"ltp":1.76,"tv":25.98,"id":40296818},{"batb":[[0,1.82,10],[1,1.81,6.9],[2,1.8,444]],"ltp":1.82,"tv":32.34,"id":40296819}]}]}
{"op":"mcm","clk":"11843179634","pt":1723578560242,"mc":[{"id":"1.231732748","rc":[{"batb":[[0,1.75,6.85],[1,1.74,17.32],[2,1.25,100]],"ltp":1.76,"tv":25.98,"id":40296818},{"batb":[[0,1.81,6.9],[1,1.8,444],[2,1.74,17.32]],"ltp":1.82,"tv":32.34,"id":40296819}]}]}
{"op":"mcm","clk":"11843180246","pt":1723578564075,"mc":[{"id":"1.231732748","rc":[{"batb":[[0,1.76,10],[1,1.75,6.85],[2,1.74,17.32]],"ltp":1.76,"tv":25.98,"id":40296818},{"batb":[[0,1.82,10],[1,1.81,6.9],[2,1.8,444]],"ltp":1.82,"tv":32.34,"id":40296819}]}]}
{"op":"mcm","clk":"11843180943","pt":1723578568197,"mc":[{"id":"1.231732748","rc":[{"batb":[[0,1.75,6.85],[1,1.74,17.32],[2,1.25,100]],"ltp":1.76,"tv":25.98,"id":40296818},{"batb":[[0,1.81,6.9],[1,1.8,444],[2,1.74,17.32]],"ltp":1.82,"tv":32.34,"id":40296819}]}]}
{"op":"mcm","clk":"11843182163","pt":1723578576071,"mc":[{"id":"1.231732748","rc":[{"batb":[[0,1.76,10],[1,1.75,6.85],[2,1.74,17.32]],"ltp":1.76,"tv":25.98,"id":40296818},{"batb":[[0,1.82,10],[1,1.81,6.9],[2,1.8,444]],"ltp":1.82,"tv":32.34,"id":40296819}]}]}
{"op":"mcm","clk":"11843182705","pt":1723578579388,"mc":[{"id":"1.231732748","rc":[{"batb":[[0,1.75,6.85],[1,1.74,17.32],[2,1.25,100]],"ltp":1.76,"tv":25.98,"id":40296818},{"batb":[[0,1.81,6.9],[1,1.8,444],[2,1.74,17.32]],"ltp":1.82,"tv":32.34,"id":40296819}]}]}
{"op":"mcm","clk":"11843183674","pt":1723578585515,"mc":[{"id":"1.231732748","rc":[{"batb":[[0,1.76,10],[1,1.75,6.85],[2,1.74,17.32]],"ltp":1.76,"tv":25.98,"id":40296818},{"batb":[[0,1.82,10],[1,1.81,6.9],[2,1.8,444]],"ltp":1.82,"tv":32.34,"id":40296819}]}]}
{"op":"mcm","clk":"11843184223","pt":1723578589105,"mc":[{"id":"1.231732748","rc":[{"batb":[[0,1.75,6.85],[1,1.74,17.32],[2,1.25,100]],"ltp":1.76,"tv":25.98,"id":40296818},{"batb":[[0,1.81,6.9],[1,1.8,444],[2,1.74,17.32]],"ltp":1.82,"tv":32.34,"id":40296819}]}]}
{"op":"mcm","clk":"11843184828","pt":1723578592734,"mc":[{"id":"1.231732748","rc":[{"batb":[[0,1.76,10],[1,1.75,6.85],[2,1.74,17.32]],"ltp":1.76,"tv":25.98,"id":40296818},{"batb":[[0,1.82,10],[1,1.81,6.9],[2,1.8,444]],"ltp":1.82,"tv":32.34,"id":40296819}]}]}
{"op":"mcm","clk":"11843185353","pt":1723578596092,"mc":[{"id":"1.231732748","rc":[{"batb":[[0,1.75,6.85],[1,1.74,17.32],[2,1.25,100]],"ltp":1.76,"tv":25.98,"id":40296818},{"batb":[[0,1.81,6.9],[1,1.8,444],[2,1.74,17.32]],"ltp":1.82,"tv":32.34,"id":40296819}]}]}
{"op":"mcm","clk":"11843185841","pt":1723578599218,"mc":[{"id":"1.231732748","rc":[{"batb":[[0,1.76,10],[1,1.75,6.85],[2,1.74,17.32]],"ltp":1.76,"tv":25.98,"id":40296818},{"batb":[[0,1.82,10],[1,1.81,6.9],[2,1.8,444]],"ltp":1.82,"tv":32.34,"id":40296819}]}]}
{"op":"mcm","clk":"11843186439","pt":1723578603097,"mc":[{"id":"1.231732748","rc":[{"batb":[[0,1.75,6.85],[1,1.74,17.32],[2,1.25,100]],"ltp":1.76,"tv":25.98,"id":40296818},{"batb":[[0,1.81,6.9],[1,1.8,444],[2,1.74,17.32]],"ltp":1.82,"tv":32.34,"id":40296819}]}]}
{"op":"mcm","clk":"11843187100","pt":1723578607446,"mc":[{"id":"1.231732748","rc":[{"batb":[[0,1.76,10],[1,1.75,6.85],[2,1.74,17.32]],"ltp":1.76,"tv":25.98,"id":40296818},{"batb":[[0,1.82,10],[1,1.81,6.9],[2,1.8,444]],"ltp":1.82,"tv":32.34,"id":40296819}]}]}
{"op":"mcm","clk":"11843187622","pt":1723578610716,"mc":[{"id":"1.231732748","rc":[{"batb":[[0,1.75,6.85],[1,1.74,17.32],[2,1.25,100]],"ltp":1.76,"tv":25.98,"id":40296818},{"batb":[[0,1.81,6.9],[1,1.8,444],[2,1.74,17.32]],"ltp":1.82,"tv":32.34,"id":40296819}]}]}
{"op":"mcm","clk":"11843187961","pt":1723578612934,"mc":[{"id":"1.231732748","rc":[{"batl":[[0,1.77,1.17],[1,2.24,17.14]],"ltp":1.76,"tv":25.98,"id":40296818},{"batb":[[0,1.82,10],[1,1.81,6.9],[2,1.8,444]],"ltp":1.82,"tv":32.34,"id":40296819}]}]}
{"op":"mcm","clk":"11843188515","pt":1723578616412,"mc":[{"id":"1.231732748","rc":[{"batb":[[0,1.81,6.9],[1,1.8,444],[2,1.74,17.32]],"ltp":1.82,"tv":32.34,"id":40296819}]}]}
{"op":"mcm","clk":"11843189213","pt":1723578620828,"mc":[{"id":"1.231732748","rc":[{"batb":[[0,1.82,10],[1,1.81,6.9],[2,1.8,444]],"ltp":1.82,"tv":32.34,"id":40296819}]}]}
{"op":"mcm","clk":"11843189767","pt":1723578624363,"mc":[{"id":"1.231732748","rc":[{"batb":[[0,1.81,6.9],[1,1.8,444],[2,1.74,17.32]],"ltp":1.82,"tv":32.34,"id":40296819}]}]}
{"op":"mcm","clk":"11843190295","pt":1723578627370,"mc":[{"id":"1.231732748","rc":[{"batb":[[0,1.82,10],[1,1.81,6.9],[2,1.8,444]],"ltp":1.82,"tv":32.34,"id":40296819}]}]}
{"op":"mcm","clk":"11843190953","pt":1723578631132,"mc":[{"id":"1.231732748","rc":[{"batb":[[0,1.81,6.9],[1,1.8,444],[2,1.74,17.32]],"ltp":1.82,"tv":32.34,"id":40296819}]}]}
{"op":"mcm","clk":"11843191371","pt":1723578633781,"mc":[{"id":"1.231732748","rc":[{"batb":[[0,1.82,10],[1,1.81,6.9],[2,1.8,444]],"ltp":1.82,"tv":32.34,"id":40296819}]}]}
{"op":"mcm","clk":"11843192012","pt":1723578637179,"mc":[{"id":"1.231732748","rc":[{"batb":[[0,1.81,6.9],[1,1.8,444],[2,1.74,17.32]],"ltp":1.82,"tv":32.34,"id":40296819}]}]}
{"op":"mcm","clk":"11843192378","pt":1723578639480,"mc":[{"id":"1.231732748","rc":[{"batb":[[0,1.82,10],[1,1.81,6.9],[2,1.8,444]],"ltp":1.82,"tv":32.34,"id":40296819}]}]}
{"op":"mcm","clk":"11843192948","pt":1723578642863,"mc":[{"id":"1.231732748","rc":[{"batb":[[0,1.81,6.9],[1,1.8,444],[2,1.74,17.32]],"ltp":1.82,"tv":32.34,"id":40296819}]}]}
{"op":"mcm","clk":"11843193478","pt":1723578646171,"mc":[{"id":"1.231732748","rc":[{"batb":[[0,1.82,10],[1,1.81,6.9],[2,1.8,444]],"ltp":1.82,"tv":32.34,"id":40296819}]}]}
{"op":"mcm","clk":"11843194027","pt":1723578649558,"mc":[{"id":"1.231732748","rc":[{"batb":[[0,1.81,6.9],[1,1.8,444],[2,1.74,17.32]],"ltp":1.82,"tv":32.34,"id":40296819}]}]}
{"op":"mcm","clk":"11843194518","pt":1723578652452,"mc":[{"id":"1.231732748","rc":[{"batb":[[0,1.82,10],[1,1.81,6.9],[2,1.8,444]],"ltp":1.82,"tv":32.34,"id":40296819}]}]}
{"op":"mcm","clk":"11843195053","pt":1723578655873,"mc":[{"id":"1.231732748","rc":[{"batb":[[0,1.81,6.9],[1,1.8,444],[2,1.74,17.32]],"ltp":1.82,"tv":32.34,"id":40296819}]}]}
{"op":"mcm","clk":"11843195598","pt":1723578659461,"mc":[{"id":"1.231732748","rc":[{"batb":[[0,1.82,10],[1,1.81,6.9],[2,1.8,444]],"ltp":1.82,"tv":32.34,"id":40296819}]}]}
{"op":"mcm","clk":"11843196128","pt":1723578662898,"mc":[{"id":"1.231732748","rc":[{"batb":[[0,1.81,6.9],[1,1.8,444],[2,1.74,17.32]],"ltp":1.82,"tv":32.34,"id":40296819}]}]}
{"op":"mcm","clk":"11843196827","pt":1723578667386,"mc":[{"id":"1.231732748","rc":[{"batb":[[0,1.82,10],[1,1.81,6.9],[2,1.8,444]],"ltp":1.82,"tv":32.34,"id":40296819}]}]}
{"op":"mcm","clk":"11843197383","pt":1723578670886,"mc":[{"id":"1.231732748","rc":[{"batb":[[0,1.81,6.9],[1,1.8,444],[2,1.74,17.32]],"ltp":1.82,"tv":32.34,"id":40296819}]}]}
{"op":"mcm","clk":"11843197837","pt":1723578673416,"mc":[{"id":"1.231732748","rc":[{"batb":[[0,1.82,10],[1,1.81,6.9],[2,1.8,444]],"ltp":1.82,"tv":32.34,"id":40296819}]}]}
{"op":"mcm","clk":"11843198486","pt":1723578676811,"mc":[{"id":"1.231732748","rc":[{"batb":[[0,1.81,6.9],[1,1.8,444],[2,1.74,17.32]],"ltp":1.82,"tv":32.34,"id":40296819}]}]}
{"op":"mcm","clk":"11843199089","pt":1723578680612,"mc":[{"id":"1.231732748","rc":[{"batb":[[0,1.82,10],[1,1.81,6.9],[2,1.8,444]],"ltp":1.82,"tv":32.34,"id":40296819}]}]}
{"op":"mcm","clk":"11843199654","pt":1723578684006,"mc":[{"id":"1.231732748","rc":[{"batb":[[0,1.81,6.9],[1,1.8,444],[2,1.74,17.32]],"ltp":1.82,"tv":32.34,"id":40296819}]}]}
{"op":"mcm","clk":"11843200078","pt":1723578686503,"mc":[{"id":"1.231732748","rc":[{"batl":[[0,2.24,17.14],[1,2.24,0]],"ltp":1.76,"tv":25.98,"id":40296818}]}]}
{"op":"mcm","clk":"11843200794","pt":1723578690622,"mc":[{"id":"1.231732748","rc":[{"batb":[[0,1.76,10],[1,1.75,6.85],[2,1.74,17.32]],"ltp":1.76,"tv":25.98,"id":40296818},{"batb":[[0,1.82,10],[1,1.81,6.9],[2,1.8,444]],"ltp":1.82,"tv":32.34,"id":40296819}]}]}
{"op":"mcm","clk":"11843201524","pt":1723578694869,"mc":[{"id":"1.231732748","rc":[{"batb":[[0,1.75,6.85],[1,1.74,17.32],[2,1.25,100]],"ltp":1.76,"tv":25.98,"id":40296818},{"batb":[[0,1.81,6.9],[1,1.8,444],[2,1.74,17.32]],"ltp":1.82,"tv":32.34,"id":40296819}]}]}
{"op":"mcm","clk":"11843201998","pt":1723578697717,"mc":[{"id":"1.231732748","rc":[{"batb":[[0,1.76,10],[1,1.75,6.85],[2,1.74,17.32]],"ltp":1.76,"tv":25.98,"id":40296818},{"batb":[[0,1.82,10],[1,1.81,6.9],[2,1.8,444]],"ltp":1.82,"tv":32.34,"id":40296819}]}]}
{"op":"mcm","clk":"11843202601","pt":1723578701263,"mc":[{"id":"1.231732748","rc":[{"batb":[[0,1.75,6.85],[1,1.74,17.32],[2,1.25,100]],"ltp":1.76,"tv":25.98,"id":40296818},{"batb":[[0,1.81,6.9],[1,1.8,444],[2,1.74,17.32]],"ltp":1.82,"tv":32.34,"id":40296819}]}]}
{"op":"mcm","clk":"11843203288","pt":1723578705335,"mc":[{"id":"1.231732748","rc":[{"batb":[[0,1.76,10],[1,1.75,6.85],[2,1.74,17.32]],"ltp":1.76,"tv":25.98,"id":40296818},{"batb":[[0,1.82,10],[1,1.81,6.9],[2,1.8,444]],"ltp":1.82,"tv":32.34,"id":40296819}]}]}
{"op":"mcm","clk":"11843203751","pt":1723578707971,"mc":[{"id":"1.231732748","rc":[{"batl":[[0,1.83,1.17],[1,2.34,1.97]],"ltp":1.82,"tv":32.34,"id":40296819}]}]}
{"op":"mcm","clk":"11843203933","pt":1723578709036,"mc":[{"id":"1.231732748","rc":[{"batb":[[0,1.75,6.85],[1,1.74,17.32],[2,1.25,100]],"ltp":1.76,"tv":25.98,"id":40296818},{"batb":[[0,1.81,6.9],[1,1.8,444],[2,1.74,17.32]],"ltp":1.82,"tv":32.34,"id":40296819}]}]}
{"op":"mcm","clk":"11843204336","pt":1723578711467,"mc":[{"id":"1.231732748","rc":[{"batb":[[0,1.76,10],[1,1.75,6.85],[2,1.74,17.32]],"ltp":1.76,"tv":25.98,"id":40296818}]}]}
{"op":"mcm","clk":"11843204976","pt":1723578715151,"mc":[{"id":"1.231732748","rc":[{"batb":[[0,1.75,6.85],[1,1.74,17.32],[2,1.25,100]],"ltp":1.76,"tv":25.98,"id":40296818}]}]}
{"op":"mcm","clk":"11843205521","pt":1723578718375,"mc":[{"id":"1.231732748","rc":[{"batb":[[0,1.76,10],[1,1.75,6.85],[2,1.74,17.32]],"ltp":1.76,"tv":25.98,"id":40296818}]}]}
{"op":"mcm","clk":"11843206020","pt":1723578721682,"mc":[{"id":"1.231732748","rc":[{"batb":[[0,1.75,6.85],[1,1.74,17.32],[2,1.25,100]],"ltp":1.76,"tv":25.98,"id":40296818}]}]}
{"op":"mcm","clk":"11843206543","pt":1723578724764,"mc":[{"id":"1.231732748","rc":[{"batb":[[0,1.76,10],[1,1.75,6.85],[2,1.74,17.32]],"ltp":1.76,"tv":25.98,"id":40296818}]}]}
{"op":"mcm","clk":"11843207087","pt":1723578728079,"mc":[{"id":"1.231732748","rc":[{"batb":[[0,1.75,6.85],[1,1.74,17.32],[2,1.25,100]],"ltp":1.76,"tv":25.98,"id":40296818}]}]}
{"op":"mcm","clk":"11843207721","pt":1723578731991,"mc":[{"id":"1.231732748","rc":[{"batb":[[0,1.76,10],[1,1.75,6.85],[2,1.74,17.32]],"ltp":1.76,"tv":25.98,"id":40296818}]}]}
{"op":"mcm","clk":"11843208283","pt":1723578735479,"mc":[{"id":"1.231732748","rc":[{"batb":[[0,1.75,6.85],[1,1.74,17.32],[2,1.25,100]],"ltp":1.76,"tv":25.98,"id":40296818}]}]}
{"op":"mcm","clk":"11843209249","pt":1723578741080,"mc":[{"id":"1.231732748","rc":[{"batb":[[0,1.76,10],[1,1.75,6.85],[2,1.74,17.32]],"ltp":1.76,"tv":25.98,"id":40296818}]}]}
{"op":"mcm","clk":"11843209719","pt":1723578743904,"mc":[{"id":"1.231732748","rc":[{"batb":[[0,1.82,10],[1,1.81,6.9],[2,1.8,444]],"batl":[[0,2.34,1.97],[1,2.34,0]],"ltp":1.82,"tv":32.34,"id":40296819}]}]}
{"op":"mcm","clk":"11843209808","pt":1723578744382,"mc":[{"id":"1.231732748","rc":[{"batb":[[0,1.75,6.85],[1,1.74,17.32],[2,1.25,100]],"ltp":1.76,"tv":25.98,"id":40296818}]}]}
{"op":"mcm","clk":"11843210254","pt":1723578747185,"mc":[{"id":"1.231732748","rc":[{"batb":[[0,1.76,10],[1,1.75,6.85],[2,1.74,17.32]],"ltp":1.76,"tv":25.98,"id":40296818},{"batb":[[0,1.81,6.9],[1,1.8,444],[2,1.74,17.32]],"ltp":1.82,"tv":32.34,"id":40296819}]}]}
{"op":"mcm","clk":"11843210606","pt":1723578749508,"mc":[{"id":"1.231732748","rc":[{"batb":[[0,1.82,10],[1,1.81,6.9],[2,1.8,444]],"ltp":1.82,"tv":32.34,"id":40296819}]}]}
{"op":"mcm","clk":"11843210768","pt":1723578750508,"mc":[{"id":"1.231732748","rc":[{"batb":[[0,1.75,6.85],[1,1.74,17.32],[2,1.25,100]],"ltp":1.76,"tv":25.98,"id":40296818}]}]}
{"op":"mcm","clk":"11843211170","pt":1723578752902,"mc":[{"id":"1.231732748","rc":[{"batb":[[0,1.81,6.9],[1,1.8,444],[2,1.74,17.32]],"ltp":1.82,"tv":32.34,"id":40296819}]}]}
{"op":"mcm","clk":"11843211204","pt":1723578753113,"mc":[{"id":"1.231732748","rc":[{"batb":[[0,1.76,10],[1,1.75,6.85],[2,1.74,17.32]],"ltp":1.76,"tv":25.98,"id":40296818}]}]}
{"op":"mcm","clk":"11843211745","pt":1723578756386,"mc":[{"id":"1.231732748","rc":[{"batb":[[0,1.75,6.85],[1,1.74,17.32],[2,1.25,100]],"ltp":1.76,"tv":25.98,"id":40296818},{"batb":[[0,1.82,10],[1,1.81,6.9],[2,1.8,444]],"ltp":1.82,"tv":32.34,"id":40296819}]}]}
{"op":"mcm","clk":"11843212268","pt":1723578760006,"mc":[{"id":"1.231732748","rc":[{"batb":[[0,1.81,6.9],[1,1.8,444],[2,1.74,17.32]],"ltp":1.82,"tv":32.34,"id":40296819}]}]}
{"op":"mcm","clk":"11843212324","pt":1723578760422,"mc":[{"id":"1.231732748","rc":[{"batb":[[0,1.76,10],[1,1.75,6.85],[2,1.74,17.32]],"ltp":1.76,"tv":25.98,"id":40296818}]}]}
{"op":"mcm","clk":"11843212885","pt":1723578763917,"mc":[{"id":"1.231732748","rc":[{"batb":[[0,1.75,6.85],[1,1.74,17.32],[2,1.25,100]],"ltp":1.76,"tv":25.98,"id":40296818},{"batb":[[0,1.82,10],[1,1.81,6.9],[2,1.8,444]],"ltp":1.82,"tv":32.34,"id":40296819}]}]}
{"op":"mcm","clk":"11843213338","pt":1723578766818,"mc":[{"id":"1.231732748","rc":[{"batb":[[0,1.76,10],[1,1.75,6.85],[2,1.74,17.32]],"ltp":1.76,"tv":25.98,"id":40296818}]}]}
{"op":"mcm","clk":"11843213367","pt":1723578767028,"mc":[{"id":"1.231732748","rc":[{"batb":[[0,1.81,6.9],[1,1.8,444],[2,1.74,17.32]],"ltp":1.82,"tv":32.34,"id":40296819}]}]}
{"op":"mcm","clk":"11843213804","pt":1723578769824,"mc":[{"id":"1.231732748","rc":[{"batb":[[0,1.82,10],[1,1.81,6.9],[2,1.8,444]],"ltp":1.82,"tv":32.34,"id":40296819}]}]}
{"op":"mcm","clk":"11843213856","pt":1723578770206,"mc":[{"id":"1.231732748","rc":[{"batb":[[0,1.75,6.85],[1,1.74,17.32],[2,1.25,100]],"ltp":1.76,"tv":25.98,"id":40296818}]}]}
{"op":"mcm","clk":"11843214411","pt":1723578773726,"mc":[{"id":"1.231732748","rc":[{"batb":[[0,1.76,10],[1,1.75,6.85],[2,1.74,17.32]],"ltp":1.76,"tv":25.98,"id":40296818},{"batb":[[0,1.81,6.9],[1,1.8,444],[2,1.74,17.32]],"ltp":1.82,"tv":32.34,"id":40296819}]}]}
{"op":"mcm","clk":"11843214761","pt":1723578776037,"mc":[{"id":"1.231732748","rc":[{"batb":[[0,1.82,10],[1,1.81,6.9],[2,1.8,444]],"ltp":1.82,"tv":32.34,"id":40296819}]}]}
{"op":"mcm","clk":"11843214925","pt":1723578777133,"mc":[{"id":"1.231732748","rc":[{"batb":[[0,1.75,6.85],[1,1.74,17.32],[2,1.25,100]],"ltp":1.76,"tv":25.98,"id":40296818}]}]}
{"op":"mcm","clk":"11843215304","pt":1723578779757,"mc":[{"id":"1.231732748","rc":[{"batb":[[0,1.76,10],[1,1.75,6.85],[2,1.74,17.32]],"ltp":1.76,"tv":25.98,"id":40296818},{"batb":[[0,1.81,6.9],[1,1.8,444],[2,1.74,17.32]],"ltp":1.82,"tv":32.34,"id":40296819}]}]}
{"op":"mcm","clk":"11843215824","pt":1723578782935,"mc":[{"id":"1.231732748","rc":[{"batb":[[0,1.82,10],[1,1.81,6.9],[2,1.8,444]],"ltp":1.82,"tv":32.34,"id":40296819}]}]}
{"op":"mcm","clk":"11843215858","pt":1723578783143,"mc":[{"id":"1.231732748","rc":[{"batb":[[0,1.75,6.85],[1,1.74,17.32],[2,1.25,100]],"ltp":1.76,"tv":25.98,"id":40296818}]}]}
{"op":"mcm","clk":"11843216464","pt":1723578786936,"mc":[{"id":"1.231732748","rc":[{"batb":[[0,1.76,10],[1,1.75,6.85],[2,1.74,17.32]],"ltp":1.76,"tv":25.98,"id":40296818},{"batb":[[0,1.81,6.9],[1,1.8,444],[2,1.74,17.32]],"ltp":1.82,"tv":32.34,"id":40296819}]}]}
{"op":"mcm","clk":"11843216858","pt":1723578789497,"mc":[{"id":"1.231732748","rc":[{"batb":[[0,1.82,10],[1,1.81,6.9],[2,1.8,444]],"ltp":1.82,"tv":32.34,"id":40296819}]}]}
{"op":"mcm","clk":"11843216944","pt":1723578790075,"mc":[{"id":"1.231732748","rc":[{"batb":[[0,1.75,6.85],[1,1.74,17.32],[2,1.25,100]],"ltp":1.76,"tv":25.98,"id":40296818}]}]}
{"op":"mcm","clk":"11843217479","pt":1723578793552,"mc":[{"id":"1.231732748","rc":[{"batb":[[0,1.76,10],[1,1.75,6.85],[2,1.74,17.32]],"ltp":1.76,"tv":25.98,"id":40296818},{"batb":[[0,1.81,6.9],[1,1.8,444],[2,1.74,17.32]],"ltp":1.82,"tv":32.34,"id":40296819}]}]}
{"op":"mcm","clk":"11843218007","pt":1723578796998,"mc":[{"id":"1.231732748","rc":[{"batb":[[0,1.75,6.85],[1,1.74,17.32],[2,1.25,100]],"ltp":1.76,"tv":25.98,"id":40296818},{"batb":[[0,1.82,10],[1,1.81,6.9],[2,1.8,444]],"ltp":1.82,"tv":32.34,"id":40296819}]}]}
{"op":"mcm","clk":"11843218439","pt":1723578799894,"mc":[{"id":"1.231732748","rc":[{"batb":[[0,1.81,6.9],[1,1.8,444],[2,1.74,17.32]],"ltp":1.82,"tv":32.34,"id":40296819}]}]}
{"op":"mcm","clk":"11843218490","pt":1723578800210,"mc":[{"id":"1.231732748","rc":[{"batb":[[0,1.76,10],[1,1.75,6.85],[2,1.74,17.32]],"ltp":1.76,"tv":25.98,"id":40296818}]}]}
{"op":"mcm","clk":"11843219081","pt":1723578803790,"mc":[{"id":"1.231732748","rc":[{"batb":[[0,1.75,6.85],[1,1.74,17.32],[2,1.25,100]],"ltp":1.76,"tv":25.98,"id":40296818},{"batb":[[0,1.82,10],[1,1.81,6.9],[2,1.8,444]],"ltp":1.82,"tv":32.34,"id":40296819}]}]}
{"op":"mcm","clk":"11843219474","pt":1723578806316,"mc":[{"id":"1.231732748","rc":[{"batb":[[0,1.76,10],[1,1.75,6.85],[2,1.74,17.32]],"ltp":1.76,"tv":25.98,"id":40296818}]}]}
{"op":"mcm","clk":"11843219675","pt":1723578807325,"mc":[{"id":"1.231732748","rc":[{"batb":[[0,1.81,6.9],[1,1.8,444],[2,1.74,17.32]],"ltp":1.82,"tv":32.34,"id":40296819}]}]}
{"op":"mcm","clk":"11843220081","pt":1723578809905,"mc":[{"id":"1.231732748","rc":[{"batb":[[0,1.75,6.85],[1,1.74,17.32],[2,1.25,100]],"ltp":1.76,"tv":25.98,"id":40296818},{"batb":[[0,1.82,10],[1,1.81,6.9],[2,1.8,444]],"ltp":1.82,"tv":32.34,"id":40296819}]}]}
{"op":"mcm","clk":"11843220538","pt":1723578812811,"mc":[{"id":"1.231732748","rc":[{"batb":[[0,1.76,10],[1,1.75,6.85],[2,1.74,17.32]],"ltp":1.76,"tv":25.98,"id":40296818}]}]}
{"op":"mcm","clk":"11843220646","pt":1723578813338,"mc":[{"id":"1.231732748","rc":[{"batb":[[0,1.81,6.9],[1,1.8,444],[2,1.74,17.32]],"ltp":1.82,"tv":32.34,"id":40296819}]}]}
{"op":"mcm","clk":"11843221234","pt":1723578817019,"mc":[{"id":"1.231732748","rc":[{"batb":[[0,1.75,6.85],[1,1.74,17.32],[2,1.25,100]],"ltp":1.76,"tv":25.98,"id":40296818},{"batb":[[0,1.82,10],[1,1.81,6.9],[2,1.8,444]],"ltp":1.82,"tv":32.34,"id":40296819}]}]}
{"op":"mcm","clk":"11843221677","pt":1723578819818,"mc":[{"id":"1.231732748","rc":[{"batb":[[0,1.76,10],[1,1.75,6.85],[2,1.74,17.32]],"ltp":1.76,"tv":25.98,"id":40296818}]}]}
{"op":"mcm","clk":"11843221784","pt":1723578820541,"mc":[{"id":"1.231732748","rc":[{"batb":[[0,1.81,6.9],[1,1.8,444],[2,1.74,17.32]],"ltp":1.82,"tv":32.34,"id":40296819}]}]}
{"op":"mcm","clk":"11843222351","pt":1723578823966,"mc":[{"id":"1.231732748","rc":[{"batb":[[0,1.75,6.85],[1,1.74,17.32],[2,1.25,100]],"ltp":1.76,"tv":25.98,"id":40296818},{"batb":[[0,1.82,10],[1,1.81,6.9],[2,1.8,444]],"ltp":1.82,"tv":32.34,"id":40296819}]}]}
{"op":"mcm","clk":"11843222711","pt":1723578826428,"mc":[{"id":"1.231732748","rc":[{"batb":[[0,1.76,10],[1,1.75,6.85],[2,1.74,17.32]],"ltp":1.76,"tv":25.98,"id":40296818}]}]}
{"op":"mcm","clk":"11843222881","pt":1723578827433,"mc":[{"id":"1.231732748","rc":[{"batb":[[0,1.81,6.9],[1,1.8,444],[2,1.74,17.32]],"ltp":1.82,"tv":32.34,"id":40296819}]}]}
{"op":"mcm","clk":"11843223269","pt":1723578829772,"mc":[{"id":"1.231732748","rc":[{"batb":[[0,1.75,6.85],[1,1.74,17.32],[2,1.25,100]],"ltp":1.76,"tv":25.98,"id":40296818}]}]}
{"op":"mcm","clk":"11843223318","pt":1723578830077,"mc":[{"id":"1.231732748","rc":[{"batb":[[0,1.82,10],[1,1.81,6.9],[2,1.8,444]],"ltp":1.82,"tv":32.34,"id":40296819}]}]}
{"op":"mcm","clk":"11843223708","pt":1723578832543,"mc":[{"id":"1.231732748","rc":[{"batb":[[0,1.76,10],[1,1.75,6.85],[2,1.74,17.32]],"ltp":1.76,"tv":25.98,"id":40296818}]}]}
{"op":"mcm","clk":"11843224037","pt":1723578834554,"mc":[{"id":"1.231732748","rc":[{"batl":[[0,1.77,1.17],[1,2.24,17.14]],"ltp":1.76,"tv":25.98,"id":40296818},{"batb":[[0,1.81,6.9],[1,1.8,444],[2,1.74,17.32]],"ltp":1.82,"tv":32.34,"id":40296819}]}]}
{"op":"mcm","clk":"11843224297","pt":1723578836392,"mc":[{"id":"1.231732748","rc":[{"batb":[[0,1.82,10],[1,1.81,6.9],[2,1.8,444]],"ltp":1.82,"tv":32.34,"id":40296819}]}]}
{"op":"mcm","clk":"11843224409","pt":1723578837077,"mc":[{"id":"1.231732748","rc":[{"batb":[[0,1.75,6.85],[1,1.74,17.32],[2,1.25,100]],"ltp":1.76,"tv":25.98,"id":40296818}]}]}
{"op":"mcm","clk":"11843224860","pt":1723578839782,"mc":[{"id":"1.231732748","rc":[{"batb":[[0,1.81,6.9],[1,1.8,444],[2,1.74,17.32]],"ltp":1.82,"tv":32.34,"id":40296819}]}]}
{"op":"mcm","clk":"11843225414","pt":1723578843399,"mc":[{"id":"1.231732748","rc":[{"batb":[[0,1.82,10],[1,1.81,6.9],[2,1.8,444]],"ltp":1.82,"tv":32.34,"id":40296819}]}]}
{"op":"mcm","clk":"11843225967","pt":1723578846984,"mc":[{"id":"1.231732748","rc":[{"batb":[[0,1.81,6.9],[1,1.8,444],[2,1.74,17.32]],"ltp":1.82,"tv":32.34,"id":40296819}]}]}
{"op":"mcm","clk":"11843226519","pt":1723578850392,"mc":[{"id":"1.231732748","rc":[{"batb":[[0,1.82,10],[1,1.81,6.9],[2,1.8,444]],"ltp":1.82,"tv":32.34,"id":40296819}]}]}
{"op":"mcm","clk":"11843227054","pt":1723578854020,"mc":[{"id":"1.231732748","rc":[{"batb":[[0,1.81,6.9],[1,1.8,444],[2,1.74,17.32]],"ltp":1.82,"tv":32.34,"id":40296819}]}]}
{"op":"mcm","clk":"11843227601","pt":1723578857359,"mc":[{"id":"1.231732748","rc":[{"batb":[[0,1.82,10],[1,1.81,6.9],[2,1.8,444]],"ltp":1.82,"tv":32.34,"id":40296819}]}]}
{"op":"mcm","clk":"11843228118","pt":1723578860707,"mc":[{"id":"1.231732748","rc":[{"batb":[[0,1.81,6.9],[1,1.8,444],[2,1.74,17.32]],"ltp":1.82,"tv":32.34,"id":40296819}]}]}
{"op":"mcm","clk":"11843228442","pt":1723578862900,"mc":[{"id":"1.231732748","rc":[{"batb":[[0,1.82,10],[1,1.81,6.9],[2,1.8,444]],"ltp":1.82,"tv":32.34,"id":40296819}]}]}
{"op":"mcm","clk":"11843228978","pt":1723578866391,"mc":[{"id":"1.231732748","rc":[{"batb":[[0,1.81,6.9],[1,1.8,444],[2,1.74,17.32]],"ltp":1.82,"tv":32.34,"id":40296819}]}]}
{"op":"mcm","clk":"11843229467","pt":1723578869400,"mc":[{"id":"1.231732748","rc":[{"batb":[[0,1.82,10],[1,1.81,6.9],[2,1.8,444]],"ltp":1.82,"tv":32.34,"id":40296819}]}]}
{"op":"mcm","clk":"11843230021","pt":1723578872909,"mc":[{"id":"1.231732748","rc":[{"batb":[[0,1.81,6.9],[1,1.8,444],[2,1.74,17.32]],"ltp":1.82,"tv":32.34,"id":40296819}]}]}
{"op":"mcm","clk":"11843230478","pt":1723578876064,"mc":[{"id":"1.231732748","rc":[{"batb":[[0,1.82,10],[1,1.81,6.9],[2,1.8,444]],"ltp":1.82,"tv":32.34,"id":40296819}]}]}
{"op":"mcm","clk":"11843231088","pt":1723578880206,"mc":[{"id":"1.231732748","rc":[{"batb":[[0,1.81,6.9],[1,1.8,444],[2,1.74,17.32]],"ltp":1.82,"tv":32.34,"id":40296819}]}]}
{"op":"mcm","clk":"11843231526","pt":1723578883257,"mc":[{"id":"1.231732748","rc":[{"batb":[[0,1.82,10],[1,1.81,6.9],[2,1.8,444]],"ltp":1.82,"tv":32.34,"id":40296819}]}]}
{"op":"mcm","clk":"11843232127","pt":1723578887028,"mc":[{"id":"1.231732748","rc":[{"batb":[[0,1.81,6.9],[1,1.8,444],[2,1.74,17.32]],"ltp":1.82,"tv":32.34,"id":40296819}]}]}
{"op":"mcm","clk":"11843232554","pt":1723578889756,"mc":[{"id":"1.231732748","rc":[{"batb":[[0,1.82,10],[1,1.81,6.9],[2,1.8,444]],"ltp":1.82,"tv":32.34,"id":40296819}]}]}
{"op":"mcm","clk":"11843233113","pt":1723578893645,"mc":[{"id":"1.231732748","rc":[{"batb":[[0,1.81,6.9],[1,1.8,444],[2,1.74,17.32]],"ltp":1.82,"tv":32.34,"id":40296819}]}]}
{"op":"mcm","clk":"11843233575","pt":1723578896641,"mc":[{"id":"1.231732748","rc":[{"batb":[[0,1.82,10],[1,1.81,6.9],[2,1.8,444]],"ltp":1.82,"tv":32.34,"id":40296819}]}]}
{"op":"mcm","clk":"11843234122","pt":1723578900143,"mc":[{"id":"1.231732748","rc":[{"batb":[[0,1.81,6.9],[1,1.8,444],[2,1.74,17.32]],"ltp":1.82,"tv":32.34,"id":40296819}]}]}
{"op":"mcm","clk":"11843234702","pt":1723578903837,"mc":[{"id":"1.231732748","rc":[{"batb":[[0,1.82,10],[1,1.81,6.9],[2,1.8,444]],"ltp":1.82,"tv":32.34,"id":40296819}]}]}
{"op":"mcm","clk":"11843235268","pt":1723578907361,"mc":[{"id":"1.231732748","rc":[{"batb":[[0,1.81,6.9],[1,1.8,444],[2,1.74,17.32]],"ltp":1.82,"tv":32.34,"id":40296819}]}]}
{"op":"mcm","clk":"11843235780","pt":1723578910564,"mc":[{"id":"1.231732748","rc":[{"batb":[[0,1.82,10],[1,1.81,6.9],[2,1.8,444]],"ltp":1.82,"tv":32.34,"id":40296819}]}]}
{"op":"mcm","clk":"11843236417","pt":1723578914566,"mc":[{"id":"1.231732748","rc":[{"batb":[[0,1.81,6.9],[1,1.8,444],[2,1.74,17.32]],"ltp":1.82,"tv":32.34,"id":40296819}]}]}
{"op":"mcm","clk":"11843237156","pt":1723578919147,"mc":[{"id":"1.231732748","rc":[{"batb":[[0,1.82,10],[1,1.81,6.9],[2,1.8,444]],"ltp":1.82,"tv":32.34,"id":40296819}]}]}
{"op":"mcm","clk":"11843237778","pt":1723578922568,"mc":[{"id":"1.231732748","rc":[{"batb":[[0,1.81,6.9],[1,1.8,444],[2,1.74,17.32]],"ltp":1.82,"tv":32.34,"id":40296819}]}]}
{"op":"mcm","clk":"11843238404","pt":1723578926761,"mc":[{"id":"1.231732748","rc":[{"batb":[[0,1.82,10],[1,1.81,6.9],[2,1.8,444]],"ltp":1.82,"tv":32.34,"id":40296819}]}]}
{"op":"mcm","clk":"11843238945","pt":1723578930377,"mc":[{"id":"1.231732748","rc":[{"batb":[[0,1.81,6.9],[1,1.8,444],[2,1.74,17.32]],"ltp":1.82,"tv":32.34,"id":40296819}]}]}
{"op":"mcm","clk":"11843239318","pt":1723578932972,"mc":[{"id":"1.231732748","rc":[{"batb":[[0,1.82,10],[1,1.81,6.9],[2,1.8,444]],"ltp":1.82,"tv":32.34,"id":40296819}]}]}
{"op":"mcm","clk":"11843239800","pt":1723578936379,"mc":[{"id":"1.231732748","rc":[{"batb":[[0,1.81,6.9],[1,1.8,444],[2,1.74,17.32]],"ltp":1.82,"tv":32.34,"id":40296819}]}]}
{"op":"mcm","clk":"11843240490","pt":1723578941090,"mc":[{"id":"1.231732748","rc":[{"batb":[[0,1.82,10],[1,1.81,6.9],[2,1.8,444]],"ltp":1.82,"tv":32.34,"id":40296819}]}]}
{"op":"mcm","clk":"11843240991","pt":1723578944360,"mc":[{"id":"1.231732748","rc":[{"batb":[[0,1.81,6.9],[1,1.8,444],[2,1.74,17.32]],"ltp":1.82,"tv":32.34,"id":40296819}]}]}
{"op":"mcm","clk":"11843241639","pt":1723578948781,"mc":[{"id":"1.231732748","rc":[{"batb":[[0,1.76,10],[1,1.75,6.85],[2,1.74,17.32]],"batl":[[0,2.24,17.14],[1,2.24,0]],"ltp":1.76,"tv":25.98,"id":40296818},{"batb":[[0,1.82,10],[1,1.81,6.9],[2,1.8,444]],"ltp":1.82,"tv":32.34,"id":40296819}]}]}
{"op":"mcm","clk":"11843242127","pt":1723578952091,"mc":[{"id":"1.231732748","rc":[{"batb":[[0,1.75,6.85],[1,1.74,17.32],[2,1.25,100]],"ltp":1.76,"tv":25.98,"id":40296818},{"batb":[[0,1.81,6.9],[1,1.8,444],[2,1.74,17.32]],"ltp":1.82,"tv":32.34,"id":40296819}]}]}
{"op":"mcm","clk":"11843242736","pt":1723578955707,"mc":[{"id":"1.231732748","rc":[{"batb":[[0,1.76,10],[1,1.75,6.85],[2,1.74,17.32]],"ltp":1.76,"tv":25.98,"id":40296818},{"batb":[[0,1.82,10],[1,1.81,6.9],[2,1.8,444]],"ltp":1.82,"tv":32.34,"id":40296819}]}]}
{"op":"mcm","clk":"11843243272","pt":1723578959318,"mc":[{"id":"1.231732748","rc":[{"batb":[[0,1.75,6.85],[1,1.74,17.32],[2,1.25,100]],"ltp":1.76,"tv":25.98,"id":40296818},{"batb":[[0,1.81,6.9],[1,1.8,444],[2,1.74,17.32]],"ltp":1.82,"tv":32.34,"id":40296819}]}]}
{"op":"mcm","clk":"11843243489","pt":1723578960634,"mc":[{"id":"1.231732748","rc":[{"batl":[[0,1.83,1.17],[1,2.34,1.97]],"ltp":1.82,"tv":32.34,"id":40296819}]}]}
{"op":"mcm","clk":"11843244010","pt":1723578963707,"mc":[{"id":"1.231732748","rc":[{"batb":[[0,1.76,10],[1,1.75,6.85],[2,1.74,17.32]],"ltp":1.76,"tv":25.98,"id":40296818}]}]}
{"op":"mcm","clk":"11843244624","pt":1723578967525,"mc":[{"id":"1.231732748","rc":[{"batb":[[0,1.75,6.85],[1,1.74,17.32],[2,1.25,100]],"ltp":1.76,"tv":25.98,"id":40296818}]}]}
{"op":"mcm","clk":"11843245254","pt":1723578971409,"mc":[{"id":"1.231732748","rc":[{"batb":[[0,1.76,10],[1,1.75,6.85],[2,1.74,17.32]],"ltp":1.76,"tv":25.98,"id":40296818}]}]}
{"op":"mcm","clk":"11843245840","pt":1723578974936,"mc":[{"id":"1.231732748","rc":[{"batb":[[0,1.75,6.85],[1,1.74,17.32],[2,1.25,100]],"ltp":1.76,"tv":25.98,"id":40296818}]}]}
{"op":"mcm","clk":"11843246224","pt":1723578977143,"mc":[{"id":"1.231732748","rc":[{"batb":[[0,1.76,10],[1,1.75,6.85],[2,1.74,17.32]],"ltp":1.76,"tv":25.98,"id":40296818}]}]}
{"op":"mcm","clk":"11843246753","pt":1723578980520,"mc":[{"id":"1.231732748","rc":[{"batb":[[0,1.75,6.85],[1,1.74,17.32],[2,1.25,100]],"ltp":1.76,"tv":25.98,"id":40296818}]}]}
{"op":"mcm","clk":"11843247423","pt":1723578984425,"mc":[{"id":"1.231732748","rc":[{"batb":[[0,1.76,10],[1,1.75,6.85],[2,1.74,17.32]],"ltp":1.76,"tv":25.98,"id":40296818}]}]}
{"op":"mcm","clk":"11843248042","pt":1723578988239,"mc":[{"id":"1.231732748","rc":[{"batb":[[0,1.75,6.85],[1,1.74,17.32],[2,1.25,100]],"ltp":1.76,"tv":25.98,"id":40296818}]}]}
{"op":"mcm","clk":"11843248614","pt":1723578991551,"mc":[{"id":"1.231732748","rc":[{"batb":[[0,1.76,10],[1,1.75,6.85],[2,1.74,17.32]],"ltp":1.76,"tv":25.98,"id":40296818}]}]}
{"op":"mcm","clk":"11843249154","pt":1723578995045,"mc":[{"id":"1.231732748","rc":[{"batb":[[0,1.75,6.85],[1,1.74,17.32],[2,1.25,100]],"ltp":1.76,"tv":25.98,"id":40296818}]}]}
{"op":"mcm","clk":"11843249590","pt":1723578997954,"mc":[{"id":"1.231732748","rc":[{"batb":[[0,1.76,10],[1,1.75,6.85],[2,1.74,17.32]],"ltp":1.76,"tv":25.98,"id":40296818}]}]}
{"op":"mcm","clk":"11843249841","pt":1723578999655,"mc":[{"id":"1.231732748","rc":[{"batb":[[0,1.82,10],[1,1.81,6.9],[2,1.8,444]],"batl":[[0,2.34,1.97],[1,2.34,0]],"ltp":1.82,"tv":32.34,"id":40296819}]}]}
{"op":"mcm","clk":"11843250142","pt":1723579001592,"mc":[{"id":"1.231732748","rc":[{"batb":[[0,1.75,6.85],[1,1.74,17.32],[2,1.25,100]],"ltp":1.76,"tv":25.98,"id":40296818}]}]}
{"op":"mcm","clk":"11843250428","pt":1723579003165,"mc":[{"id":"1.231732748","rc":[{"batb":[[0,1.81,6.9],[1,1.8,444],[2,1.74,17.32]],"ltp":1.82,"tv":32.34,"id":40296819}]}]}
{"op":"mcm","clk":"11843250690","pt":1723579004762,"mc":[{"id":"1.231732748","rc":[{"batb":[[0,1.76,10],[1,1.75,6.85],[2,1.74,17.32]],"ltp":1.76,"tv":25.98,"id":40296818}]}]}
{"op":"mcm","clk":"11843251111","pt":1723579007658,"mc":[{"id":"1.231732748","rc":[{"batb":[[0,1.82,10],[1,1.81,6.9],[2,1.8,444]],"ltp":1.82,"tv":32.34,"id":40296819}]}]}
{"op":"mcm","clk":"11843251247","pt":1723579008540,"mc":[{"id":"1.231732748","rc":[{"batb":[[0,1.75,6.85],[1,1.74,17.32],[2,1.25,100]],"batl":[[0,1.77,1.17],[1,2.24,17.14]],"ltp":1.76,"tv":25.98,"id":40296818}]}]}
{"op":"mcm","clk":"11843251640","pt":1723579011165,"mc":[{"id":"1.231732748","rc":[{"batb":[[0,1.81,6.9],[1,1.8,444],[2,1.74,17.32]],"ltp":1.82,"tv":32.34,"id":40296819}]}]}
{"op":"mcm","clk":"11843252374","pt":1723579016188,"mc":[{"id":"1.231732748","rc":[{"batb":[[0,1.82,10],[1,1.81,6.9],[2,1.8,444]],"ltp":1.82,"tv":32.34,"id":40296819}]}]}
{"op":"mcm","clk":"11843252882","pt":1723579019573,"mc":[{"id":"1.231732748","rc":[{"batb":[[0,1.81,6.9],[1,1.8,444],[2,1.74,17.32]],"ltp":1.82,"tv":32.34,"id":40296819}]}]}
{"op":"mcm","clk":"11843253323","pt":1723579022572,"mc":[{"id":"1.231732748","rc":[{"batb":[[0,1.82,10],[1,1.81,6.9],[2,1.8,444]],"ltp":1.82,"tv":32.34,"id":40296819}]}]}
{"op":"mcm","clk":"11843253933","pt":1723579026474,"mc":[{"id":"1.231732748","rc":[{"batb":[[0,1.81,6.9],[1,1.8,444],[2,1.74,17.32]],"ltp":1.82,"tv":32.34,"id":40296819}]}]}
{"op":"mcm","clk":"11843254373","pt":1723579028773,"mc":[{"id":"1.231732748","rc":[{"batb":[[0,1.82,10],[1,1.81,6.9],[2,1.8,444]],"ltp":1.82,"tv":32.34,"id":40296819}]}]}
{"op":"mcm","clk":"11843254885","pt":1723579032296,"mc":[{"id":"1.231732748","rc":[{"batb":[[0,1.81,6.9],[1,1.8,444],[2,1.74,17.32]],"ltp":1.82,"tv":32.34,"id":40296819}]}]}
{"op":"mcm","clk":"11843255267","pt":1723579034779,"mc":[{"id":"1.231732748","rc":[{"batb":[[0,1.82,10],[1,1.81,6.9],[2,1.8,444]],"ltp":1.82,"tv":32.34,"id":40296819}]}]}
{"op":"mcm","clk":"11843255828","pt":1723579038286,"mc":[{"id":"1.231732748","rc":[{"batb":[[0,1.81,6.9],[1,1.8,444],[2,1.74,17.32]],"ltp":1.82,"tv":32.34,"id":40296819}]}]}
{"op":"mcm","clk":"11843256489","pt":1723579042348,"mc":[{"id":"1.231732748","rc":[{"batb":[[0,1.82,10],[1,1.81,6.9],[2,1.8,444]],"ltp":1.82,"tv":32.34,"id":40296819}]}]}
{"op":"mcm","clk":"11843257091","pt":1723579045983,"mc":[{"id":"1.231732748","rc":[{"batb":[[0,1.81,6.9],[1,1.8,444],[2,1.74,17.32]],"ltp":1.82,"tv":32.34,"id":40296819}]}]}
{"op":"mcm","clk":"11843257746","pt":1723579050248,"mc":[{"id":"1.231732748","rc":[{"batb":[[0,1.82,10],[1,1.81,6.9],[2,1.8,444]],"ltp":1.82,"tv":32.34,"id":40296819}]}]}
{"op":"mcm","clk":"11843258274","pt":1723579053711,"mc":[{"id":"1.231732748","rc":[{"batb":[[0,1.81,6.9],[1,1.8,444],[2,1.74,17.32]],"ltp":1.82,"tv":32.34,"id":40296819}]}]}
{"op":"mcm","clk":"11843258897","pt":1723579057817,"mc":[{"id":"1.231732748","rc":[{"batb":[[0,1.82,10],[1,1.81,6.9],[2,1.8,444]],"ltp":1.82,"tv":32.34,"id":40296819}]}]}
{"op":"mcm","clk":"11843259380","pt":1723579061215,"mc":[{"id":"1.231732748","rc":[{"batb":[[0,1.81,6.9],[1,1.8,444],[2,1.74,17.32]],"ltp":1.82,"tv":32.34,"id":40296819}]}]}
{"op":"mcm","clk":"11843259869","pt":1723579064534,"mc":[{"id":"1.231732748","rc":[{"batb":[[0,1.82,10],[1,1.81,6.9],[2,1.8,444]],"ltp":1.82,"tv":32.34,"id":40296819}]}]}
{"op":"mcm","clk":"11843260432","pt":1723579068033,"mc":[{"id":"1.231732748","rc":[{"batb":[[0,1.81,6.9],[1,1.8,444],[2,1.74,17.32]],"ltp":1.82,"tv":32.34,"id":40296819}]}]}
{"op":"mcm","clk":"11843260962","pt":1723579070824,"mc":[{"id":"1.231732748","rc":[{"batb":[[0,1.82,10],[1,1.81,6.9],[2,1.8,444]],"ltp":1.82,"tv":32.34,"id":40296819}]}]}
{"op":"mcm","clk":"11843261525","pt":1723579074330,"mc":[{"id":"1.231732748","rc":[{"batb":[[0,1.81,6.9],[1,1.8,444],[2,1.74,17.32]],"ltp":1.82,"tv":32.34,"id":40296819}]}]}
{"op":"mcm","clk":"11843261990","pt":1723579077335,"mc":[{"id":"1.231732748","rc":[{"batb":[[0,1.82,10],[1,1.81,6.9],[2,1.8,444]],"ltp":1.82,"tv":32.34,"id":40296819}]}]}
{"op":"mcm","clk":"11843262534","pt":1723579080812,"mc":[{"id":"1.231732748","rc":[{"batb":[[0,1.81,6.9],[1,1.8,444],[2,1.74,17.32]],"ltp":1.82,"tv":32.34,"id":40296819}]}]}
{"op":"mcm","clk":"11843263126","pt":1723579084756,"mc":[{"id":"1.231732748","rc":[{"batb":[[0,1.82,10],[1,1.81,6.9],[2,1.8,444]],"ltp":1.82,"tv":32.34,"id":40296819}]}]}
{"op":"mcm","clk":"11843263466","pt":1723579086865,"mc":[{"id":"1.231732748","rc":[{"batb":[[0,1.76,10],[1,1.75,6.85],[2,1.74,17.32]],"batl":[[0,2.24,17.14],[1,2.24,0]],"ltp":1.76,"tv":25.98,"id":40296818}]}]}
{"op":"mcm","clk":"11843263760","pt":1723579088755,"mc":[{"id":"1.231732748","rc":[{"batb":[[0,1.81,6.9],[1,1.8,444],[2,1.74,17.32]],"ltp":1.82,"tv":32.34,"id":40296819}]}]}
{"op":"mcm","clk":"11843263998","pt":1723579090137,"mc":[{"id":"1.231732748","rc":[{"batb":[[0,1.75,6.85],[1,1.74,17.32],[2,1.25,100]],"ltp":1.76,"tv":25.98,"id":40296818}]}]}
{"op":"mcm","clk":"11843264390","pt":1723579092766,"mc":[{"id":"1.231732748","rc":[{"batb":[[0,1.76,10],[1,1.75,6.85],[2,1.74,17.32]],"ltp":1.76,"tv":25.98,"id":40296818},{"batb":[[0,1.82,10],[1,1.81,6.9],[2,1.8,444]],"ltp":1.82,"tv":32.34,"id":40296819}]}]}
{"op":"mcm","clk":"11843265050","pt":1723579096812,"mc":[{"id":"1.231732748","rc":[{"batb":[[0,1.75,6.85],[1,1.74,17.32],[2,1.25,100]],"ltp":1.76,"tv":25.98,"id":40296818},{"batb":[[0,1.81,6.9],[1,1.8,444],[2,1.74,17.32]],"ltp":1.82,"tv":32.34,"id":40296819}]}]}
{"op":"mcm","clk":"11843265524","pt":1723579099475,"mc":[{"id":"1.231732748","rc":[{"batb":[[0,1.76,10],[1,1.75,6.85],[2,1.74,17.32]],"ltp":1.76,"tv":25.98,"id":40296818},{"batb":[[0,1.82,10],[1,1.81,6.9],[2,1.8,444]],"ltp":1.82,"tv":32.34,"id":40296819}]}]}
{"op":"mcm","clk":"11843265731","pt":1723579100797,"mc":[{"id":"1.231732748","rc":[{"batl":[[0,1.83,1.17],[1,2.34,1.97]],"ltp":1.82,"tv":32.34,"id":40296819}]}]}
{"op":"mcm","clk":"11843266072","pt":1723579103662,"mc":[{"id":"1.231732748","rc":[{"batb":[[0,1.75,6.85],[1,1.74,17.32],[2,1.25,100]],"ltp":1.76,"tv":25.98,"id":40296818},{"batb":[[0,1.81,6.9],[1,1.8,444],[2,1.74,17.32]],"ltp":1.82,"tv":32.34,"id":40296819}]}]}
{"op":"mcm","clk":"11843267568","pt":1723579111767,"mc":[{"id":"1.231732748","rc":[{"batb":[[0,1.76,10],[1,1.75,6.85],[2,1.74,17.32]],"ltp":1.76,"tv":25.98,"id":40296818}]}]}
{"op":"mcm","clk":"11843269072","pt":1723579121786,"mc":[{"id":"1.231732748","rc":[{"batb":[[0,1.75,6.85],[1,1.74,17.32],[2,1.25,100]],"ltp":1.76,"tv":25.98,"id":40296818}]}]}
{"op":"mcm","clk":"11843269664","pt":1723579125999,"mc":[{"id":"1.231732748","rc":[{"batb":[[0,1.76,10],[1,1.75,6.85],[2,1.74,17.32]],"ltp":1.76,"tv":25.98,"id":40296818}]}]}
{"op":"mcm","clk":"11843270676","pt":1723579132399,"mc":[{"id":"1.231732748","rc":[{"batb":[[0,1.75,6.85],[1,1.74,17.32],[2,1.25,100]],"ltp":1.76,"tv":25.98,"id":40296818}]}]}
{"op":"mcm","clk":"11843271049","pt":1723579134775,"mc":[{"id":"1.231732748","rc":[{"batb":[[0,1.76,10],[1,1.75,6.85],[2,1.74,17.32]],"ltp":1.76,"tv":25.98,"id":40296818}]}]}
{"op":"mcm","clk":"11843271656","pt":1723579138900,"mc":[{"id":"1.231732748","rc":[{"batb":[[0,1.75,6.85],[1,1.74,17.32],[2,1.25,100]],"ltp":1.76,"tv":25.98,"id":40296818}]}]}
{"op":"mcm","clk":"11843272116","pt":1723579141727,"mc":[{"id":"1.231732748","rc":[{"batb":[[0,1.76,10],[1,1.75,6.85],[2,1.74,17.32]],"ltp":1.76,"tv":25.98,"id":40296818}]}]}
{"op":"mcm","clk":"11843272762","pt":1723579145593,"mc":[{"id":"1.231732748","rc":[{"batb":[[0,1.75,6.85],[1,1.74,17.32],[2,1.25,100]],"ltp":1.76,"tv":25.98,"id":40296818}]}]}
{"op":"mcm","clk":"11843273474","pt":1723579150014,"mc":[{"id":"1.231732748","rc":[{"batb":[[0,1.76,10],[1,1.75,6.85],[2,1.74,17.32]],"ltp":1.76,"tv":25.98,"id":40296818}]}]}
{"op":"mcm","clk":"11843274028","pt":1723579153331,"mc":[{"id":"1.231732748","rc":[{"batb":[[0,1.75,6.85],[1,1.74,17.32],[2,1.25,100]],"ltp":1.76,"tv":25.98,"id":40296818}]}]}
{"op":"mcm","clk":"11843275588","pt":1723579162700,"mc":[{"id":"1.231732748","rc":[{"batb":[[0,1.76,10],[1,1.75,6.85],[2,1.74,17.32]],"ltp":1.76,"tv":25.98,"id":40296818}]}]}
{"op":"mcm","clk":"11843276183","pt":1723579166456,"mc":[{"id":"1.231732748","rc":[{"batb":[[0,1.75,6.85],[1,1.74,17.32],[2,1.25,100]],"ltp":1.76,"tv":25.98,"id":40296818}]}]}
{"op":"mcm","clk":"11843277027","pt":1723579171751,"mc":[{"id":"1.231732748","rc":[{"batb":[[0,1.76,10],[1,1.75,6.85],[2,1.74,17.32]],"ltp":1.76,"tv":25.98,"id":40296818}]}]}
{"op":"mcm","clk":"11843277863","pt":1723579176611,"mc":[{"id":"1.231732748","rc":[{"batb":[[0,1.75,6.85],[1,1.74,17.32],[2,1.25,100]],"ltp":1.76,"tv":25.98,"id":40296818}]}]}
{"op":"mcm","clk":"11843278570","pt":1723579181029,"mc":[{"id":"1.231732748","rc":[{"batb":[[0,1.77,10],[1,1.75,6.85],[2,1.74,17.32]],"ltp":1.76,"tv":25.98,"id":40296818}]}]}
{"op":"mcm","clk":"11843280489","pt":1723579192620,"mc":[{"id":"1.231732748","rc":[{"batb":[[0,1.75,6.85],[1,1.74,17.32],[2,1.25,100]],"ltp":1.76,"tv":25.98,"id":40296818}]}]}
{"op":"mcm","clk":"11843280899","pt":1723579195038,"mc":[{"id":"1.231732748","rc":[{"batb":[[0,1.78,10],[1,1.75,6.85],[2,1.74,17.32]],"ltp":1.76,"tv":25.98,"id":40296818}]}]}
{"op":"mcm","clk":"11843282184","pt":1723579202725,"mc":[{"id":"1.231732748","rc":[{"batb":[[0,1.75,6.85],[1,1.74,17.32],[2,1.25,100]],"ltp":1.76,"tv":25.98,"id":40296818}]}]}
{"op":"mcm","clk":"11843282663","pt":1723579205358,"mc":[{"id":"1.231732748","rc":[{"trd":[[1.69,8.26],[1.7,4.75],[2.14,7.22],[2.16,4.23]],"batb":[[0,1.76,10],[1,1.75,6.85],[2,1.74,17.32]],"batl":[[0,2.24,17.14]],"ltp":1.76,"tv":25.99,"id":40296818},{"trd":[[1.86,16.74],[1.89,4.27],[2.26,7.22]],"batb":[[0,1.81,6.9]],"ltp":1.82,"tv":32.35,"id":40296819}],"tv":58.35}]}
{"op":"mcm","clk":"11843283727","pt":1723579211749,"mc":[{"id":"1.231732748","rc":[{"batb":[[0,1.75,6.85],[1,1.74,17.32],[2,1.25,100]],"ltp":1.76,"tv":25.99,"id":40296818}]}]}
{"op":"mcm","clk":"11843284158","pt":1723579214354,"mc":[{"id":"1.231732748","rc":[{"batb":[[0,1.76,10],[1,1.75,6.85],[2,1.74,17.32]],"ltp":1.76,"tv":25.99,"id":40296818}]}]}
{"op":"mcm","clk":"11843284998","pt":1723579219253,"mc":[{"id":"1.231732748","rc":[{"batb":[[0,1.75,6.85],[1,1.74,17.32],[2,1.25,100]],"ltp":1.76,"tv":25.99,"id":40296818}]}]}
{"op":"mcm","clk":"11843285182","pt":1723579220267,"mc":[{"id":"1.231732748","rc":[{"batl":[[0,2.34,1.97],[1,2.34,0]],"ltp":1.82,"tv":32.35,"id":40296819}]}]}
{"op":"mcm","clk":"11843285402","pt":1723579221576,"mc":[{"id":"1.231732748","rc":[{"batb":[[0,1.76,10],[1,1.75,6.85],[2,1.74,17.32]],"ltp":1.76,"tv":25.99,"id":40296818},{"batb":[[0,1.82,10],[1,1.81,6.9],[2,1.8,444]],"ltp":1.82,"tv":32.35,"id":40296819}]}]}
{"op":"mcm","clk":"11843286049","pt":1723579225579,"mc":[{"id":"1.231732748","rc":[{"batb":[[0,1.75,6.85],[1,1.74,17.32],[2,1.25,100]],"ltp":1.76,"tv":25.99,"id":40296818},{"batb":[[0,1.81,6.9],[1,1.8,444],[2,1.74,17.32]],"ltp":1.82,"tv":32.35,"id":40296819}]}]}
{"op":"mcm","clk":"11843286820","pt":1723579230361,"mc":[{"id":"1.231732748","rc":[{"batb":[[0,1.76,10],[1,1.75,6.85],[2,1.74,17.32]],"ltp":1.76,"tv":25.99,"id":40296818},{"batb":[[0,1.82,10],[1,1.81,6.9],[2,1.8,444]],"ltp":1.82,"tv":32.35,"id":40296819}]}]}
{"op":"mcm","clk":"11843287417","pt":1723579233892,"mc":[{"id":"1.231732748","rc":[{"batb":[[0,1.75,6.85],[1,1.74,17.32],[2,1.25,100]],"ltp":1.76,"tv":25.99,"id":40296818},{"batb":[[0,1.81,6.9],[1,1.8,444],[2,1.74,17.32]],"ltp":1.82,"tv":32.35,"id":40296819}]}]}
{"op":"mcm","clk":"11843287868","pt":1723579236688,"mc":[{"id":"1.231732748","rc":[{"batb":[[0,1.76,10],[1,1.75,6.85],[2,1.74,17.32]],"ltp":1.76,"tv":25.99,"id":40296818},{"batb":[[0,1.82,10],[1,1.81,6.9],[2,1.8,444]],"ltp":1.82,"tv":32.35,"id":40296819}]}]}
{"op":"mcm","clk":"11843288436","pt":1723579240310,"mc":[{"id":"1.231732748","rc":[{"batb":[[0,1.75,6.85],[1,1.74,17.32],[2,1.25,100]],"ltp":1.76,"tv":25.99,"id":40296818},{"batb":[[0,1.81,6.9],[1,1.8,444],[2,1.74,17.32]],"ltp":1.82,"tv":32.35,"id":40296819}]}]}
{"op":"mcm","clk":"11843288917","pt":1723579243320,"mc":[{"id":"1.231732748","rc":[{"batb":[[0,1.76,10],[1,1.75,6.85],[2,1.74,17.32]],"ltp":1.76,"tv":25.99,"id":40296818},{"batb":[[0,1.82,10],[1,1.81,6.9],[2,1.8,444]],"ltp":1.82,"tv":32.35,"id":40296819}]}]}
{"op":"mcm","clk":"11843289074","pt":1723579244210,"mc":[{"id":"1.231732748","rc":[{"batl":[[0,1.77,1.17],[1,2.24,17.14]],"ltp":1.76,"tv":25.99,"id":40296818}]}]}
{"op":"mcm","clk":"11843289492","pt":1723579246680,"mc":[{"id":"1.231732748","rc":[{"batb":[[0,1.75,6.85],[1,1.74,17.32],[2,1.25,100]],"ltp":1.76,"tv":25.99,"id":40296818},{"batb":[[0,1.81,6.9],[1,1.8,444],[2,1.74,17.32]],"ltp":1.82,"tv":32.35,"id":40296819}]}]}
{"op":"mcm","clk":"11843290168","pt":1723579250772,"mc":[{"id":"1.231732748","rc":[{"batb":[[0,1.82,10],[1,1.81,6.9],[2,1.8,444]],"ltp":1.82,"tv":32.35,"id":40296819}]}]}
{"op":"mcm","clk":"11843290748","pt":1723579254389,"mc":[{"id":"1.231732748","rc":[{"batb":[[0,1.81,6.9],[1,1.8,444],[2,1.74,17.32]],"ltp":1.82,"tv":32.35,"id":40296819}]}]}
{"op":"mcm","clk":"11843291278","pt":1723579257784,"mc":[{"id":"1.231732748","rc":[{"batb":[[0,1.82,10],[1,1.81,6.9],[2,1.8,444]],"ltp":1.82,"tv":32.35,"id":40296819}]}]}
{"op":"mcm","clk":"11843291811","pt":1723579261203,"mc":[{"id":"1.231732748","rc":[{"batb":[[0,1.81,6.9],[1,1.8,444],[2,1.74,17.32]],"ltp":1.82,"tv":32.35,"id":40296819}]}]}
{"op":"mcm","clk":"11843292300","pt":1723579264105,"mc":[{"id":"1.231732748","rc":[{"batb":[[0,1.82,10],[1,1.81,6.9],[2,1.8,444]],"ltp":1.82,"tv":32.35,"id":40296819}]}]}
{"op":"mcm","clk":"11843292893","pt":1723579267510,"mc":[{"id":"1.231732748","rc":[{"batb":[[0,1.81,6.9],[1,1.8,444],[2,1.74,17.32]],"ltp":1.82,"tv":32.35,"id":40296819}]}]}
{"op":"mcm","clk":"11843293482","pt":1723579271019,"mc":[{"id":"1.231732748","rc":[{"batb":[[0,1.82,10],[1,1.81,6.9],[2,1.8,444]],"ltp":1.82,"tv":32.35,"id":40296819}]}]}
{"op":"mcm","clk":"11843294139","pt":1723579275217,"mc":[{"id":"1.231732748","rc":[{"batb":[[0,1.81,6.9],[1,1.8,444],[2,1.74,17.32]],"ltp":1.82,"tv":32.35,"id":40296819}]}]}
{"op":"mcm","clk":"11843294568","pt":1723579277927,"mc":[{"id":"1.231732748","rc":[{"batb":[[0,1.82,10],[1,1.81,6.9],[2,1.8,444]],"ltp":1.82,"tv":32.35,"id":40296819}]}]}
{"op":"mcm","clk":"11843295193","pt":1723579282021,"mc":[{"id":"1.231732748","rc":[{"batb":[[0,1.81,6.9],[1,1.8,444],[2,1.74,17.32]],"ltp":1.82,"tv":32.35,"id":40296819}]}]}
{"op":"mcm","clk":"11843295674","pt":1723579285024,"mc":[{"id":"1.231732748","rc":[{"batb":[[0,1.82,10],[1,1.81,6.9],[2,1.8,444]],"ltp":1.82,"tv":32.35,"id":40296819}]}]}
{"op":"mcm","clk":"11843296253","pt":1723579288683,"mc":[{"id":"1.231732748","rc":[{"batb":[[0,1.81,6.9],[1,1.8,444],[2,1.74,17.32]],"ltp":1.82,"tv":32.35,"id":40296819}]}]}
{"op":"mcm","clk":"11843297271","pt":1723579294853,"mc":[{"id":"1.231732748","rc":[{"batb":[[0,1.82,10],[1,1.81,6.9],[2,1.8,444]],"ltp":1.82,"tv":32.35,"id":40296819}]}]}
{"op":"mcm","clk":"11843297819","pt":1723579298259,"mc":[{"id":"1.231732748","rc":[{"batb":[[0,1.81,6.9],[1,1.8,444],[2,1.74,17.32]],"ltp":1.82,"tv":32.35,"id":40296819}]}]}
{"op":"mcm","clk":"11843298463","pt":1723579302046,"mc":[{"id":"1.231732748","rc":[{"batb":[[0,1.82,10],[1,1.81,6.9],[2,1.8,444]],"ltp":1.82,"tv":32.35,"id":40296819}]}]}
{"op":"mcm","clk":"11843299072","pt":1723579305763,"mc":[{"id":"1.231732748","rc":[{"batb":[[0,1.81,6.9],[1,1.8,444],[2,1.74,17.32]],"ltp":1.82,"tv":32.35,"id":40296819}]}]}
{"op":"mcm","clk":"11843299867","pt":1723579310697,"mc":[{"id":"1.231732748","rc":[{"batb":[[0,1.82,10],[1,1.81,6.9],[2,1.8,444]],"ltp":1.82,"tv":32.35,"id":40296819}]}]}
{"op":"mcm","clk":"11843300421","pt":1723579314173,"mc":[{"id":"1.231732748","rc":[{"batb":[[0,1.81,6.9],[1,1.8,444],[2,1.74,17.32]],"ltp":1.82,"tv":32.35,"id":40296819}]}]}
{"op":"mcm","clk":"11843300891","pt":1723579317081,"mc":[{"id":"1.231732748","rc":[{"batb":[[0,1.82,10],[1,1.81,6.9],[2,1.8,444]],"ltp":1.82,"tv":32.35,"id":40296819}]}]}
{"op":"mcm","clk":"11843301515","pt":1723579321073,"mc":[{"id":"1.231732748","rc":[{"batb":[[0,1.81,6.9],[1,1.8,444],[2,1.74,17.32]],"ltp":1.82,"tv":32.35,"id":40296819}]}]}
{"op":"mcm","clk":"11843302006","pt":1723579323858,"mc":[{"id":"1.231732748","rc":[{"batb":[[0,1.82,10],[1,1.81,6.9],[2,1.8,444]],"ltp":1.82,"tv":32.35,"id":40296819}]}]}
{"op":"mcm","clk":"11843302574","pt":1723579327297,"mc":[{"id":"1.231732748","rc":[{"batb":[[0,1.81,6.9],[1,1.8,444],[2,1.74,17.32]],"ltp":1.82,"tv":32.35,"id":40296819}]}]}
{"op":"mcm","clk":"11843303394","pt":1723579332094,"mc":[{"id":"1.231732748","rc":[{"batb":[[0,1.82,10],[1,1.81,6.9],[2,1.8,444]],"ltp":1.82,"tv":32.35,"id":40296819}]}]}
{"op":"mcm","clk":"11843303937","pt":1723579335498,"mc":[{"id":"1.231732748","rc":[{"batb":[[0,1.81,6.9],[1,1.8,444],[2,1.74,17.32]],"ltp":1.82,"tv":32.35,"id":40296819}]}]}
{"op":"mcm","clk":"11843304487","pt":1723579338906,"mc":[{"id":"1.231732748","rc":[{"batb":[[0,1.82,10],[1,1.81,6.9],[2,1.8,444]],"ltp":1.82,"tv":32.35,"id":40296819}]}]}
{"op":"mcm","clk":"11843305045","pt":1723579342408,"mc":[{"id":"1.231732748","rc":[{"batb":[[0,1.81,6.9],[1,1.8,444],[2,1.74,17.32]],"ltp":1.82,"tv":32.35,"id":40296819}]}]}
{"op":"mcm","clk":"11843305710","pt":1723579346875,"mc":[{"id":"1.231732748","rc":[{"batb":[[0,1.82,10],[1,1.81,6.9],[2,1.8,444]],"ltp":1.82,"tv":32.35,"id":40296819}]}]}
{"op":"mcm","clk":"11843305984","pt":1723579348806,"mc":[{"id":"1.231732748","rc":[{"batb":[[0,1.76,10],[1,1.75,6.85],[2,1.74,17.32]],"batl":[[0,2.24,17.14],[1,2.24,0]],"ltp":1.76,"tv":25.99,"id":40296818}]}]}
{"op":"mcm","clk":"11843306261","pt":1723579350500,"mc":[{"id":"1.231732748","rc":[{"batb":[[0,1.81,6.9],[1,1.8,444],[2,1.74,17.32]],"ltp":1.82,"tv":32.35,"id":40296819}]}]}
{"op":"mcm","clk":"11843306606","pt":1723579352419,"mc":[{"id":"1.231732748","rc":[{"batb":[[0,1.75,6.85],[1,1.74,17.32],[2,1.25,100]],"ltp":1.76,"tv":25.99,"id":40296818}]}]}
{"op":"mcm","clk":"11843306823","pt":1723579353637,"mc":[{"id":"1.231732748","rc":[{"batb":[[0,1.82,10],[1,1.81,6.9],[2,1.8,444]],"ltp":1.82,"tv":32.35,"id":40296819}]}]}
{"op":"mcm","clk":"11843307534","pt":1723579357752,"mc":[{"id":"1.231732748","rc":[{"batb":[[0,1.76,10],[1,1.75,6.85],[2,1.74,17.32]],"ltp":1.76,"tv":25.99,"id":40296818},{"batb":[[0,1.81,6.9],[1,1.8,444],[2,1.74,17.32]],"ltp":1.82,"tv":32.35,"id":40296819}]}]}
{"op":"mcm","clk":"11843308181","pt":1723579361545,"mc":[{"id":"1.231732748","rc":[{"batb":[[0,1.75,6.85],[1,1.74,17.32],[2,1.25,100]],"ltp":1.76,"tv":25.99,"id":40296818},{"batb":[[0,1.82,10],[1,1.81,6.9],[2,1.8,444]],"ltp":1.82,"tv":32.35,"id":40296819}]}]}
{"op":"mcm","clk":"11843308756","pt":1723579364927,"mc":[{"id":"1.231732748","rc":[{"batb":[[0,1.76,10],[1,1.75,6.85],[2,1.74,17.32]],"ltp":1.76,"tv":25.99,"id":40296818},{"batb":[[0,1.81,6.9],[1,1.8,444],[2,1.74,17.32]],"ltp":1.82,"tv":32.35,"id":40296819}]}]}
{"op":"mcm","clk":"11843309285","pt":1723579367815,"mc":[{"id":"1.231732748","rc":[{"batb":[[0,1.75,6.85],[1,1.74,17.32],[2,1.25,100]],"ltp":1.76,"tv":25.99,"id":40296818}]}]}
{"op":"mcm","clk":"11843309350","pt":1723579368228,"mc":[{"id":"1.231732748","rc":[{"batb":[[0,1.82,10],[1,1.81,6.9],[2,1.8,444]],"ltp":1.82,"tv":32.35,"id":40296819}]}]}
{"op":"mcm","clk":"11843310000","pt":1723579371955,"mc":[{"id":"1.231732748","rc":[{"batb":[[0,1.76,10],[1,1.75,6.85],[2,1.74,17.32]],"ltp":1.76,"tv":25.99,"id":40296818},{"batb":[[0,1.81,6.9],[1,1.8,444],[2,1.74,17.32]],"ltp":1.82,"tv":32.35,"id":40296819}]}]}
{"op":"mcm","clk":"11843310431","pt":1723579374422,"mc":[{"id":"1.231732748","rc":[{"batb":[[0,1.82,10],[1,1.81,6.9],[2,1.8,444]],"ltp":1.82,"tv":32.35,"id":40296819}]}]}
{"op":"mcm","clk":"11843310588","pt":1723579375223,"mc":[{"id":"1.231732748","rc":[{"batb":[[0,1.75,6.85],[1,1.74,17.32],[2,1.25,100]],"ltp":1.76,"tv":25.99,"id":40296818}]}]}
{"op":"mcm","clk":"11843311180","pt":1723579378544,"mc":[{"id":"1.231732748","rc":[{"batb":[[0,1.76,10],[1,1.75,6.85],[2,1.74,17.32]],"ltp":1.76,"tv":25.99,"id":40296818},{"batb":[[0,1.81,6.9],[1,1.8,444],[2,1.74,17.32]],"ltp":1.82,"tv":32.35,"id":40296819}]}]}
{"op":"mcm","clk":"11843311568","pt":1723579380857,"mc":[{"id":"1.231732748","rc":[{"batb":[[0,1.82,10],[1,1.81,6.9],[2,1.8,444]],"ltp":1.82,"tv":32.35,"id":40296819}]}]}
{"op":"mcm","clk":"11843311739","pt":1723579381859,"mc":[{"id":"1.231732748","rc":[{"batb":[[0,1.75,6.85],[1,1.74,17.32],[2,1.25,100]],"ltp":1.76,"tv":25.99,"id":40296818}]}]}
{"op":"mcm","clk":"11843312158","pt":1723579384332,"mc":[{"id":"1.231732748","rc":[{"batb":[[0,1.76,10],[1,1.75,6.85],[2,1.74,17.32]],"ltp":1.76,"tv":25.99,"id":40296818},{"batb":[[0,1.81,6.9],[1,1.8,444],[2,1.74,17.32]],"ltp":1.82,"tv":32.35,"id":40296819}]}]}
{"op":"mcm","clk":"11843312698","pt":1723579387442,"mc":[{"id":"1.231732748","rc":[{"batb":[[0,1.75,6.85],[1,1.74,17.32],[2,1.25,100]],"ltp":1.76,"tv":25.99,"id":40296818},{"batb":[[0,1.82,10],[1,1.81,6.9],[2,1.8,444]],"ltp":1.82,"tv":32.35,"id":40296819}]}]}
{"op":"mcm","clk":"11843313139","pt":1723579390074,"mc":[{"id":"1.231732748","rc":[{"batb":[[0,1.76,10],[1,1.75,6.85],[2,1.74,17.32]],"ltp":1.76,"tv":25.99,"id":40296818}]}]}
{"op":"mcm","clk":"11843313315","pt":1723579391031,"mc":[{"id":"1.231732748","rc":[{"batb":[[0,1.81,6.9],[1,1.8,444],[2,1.74,17.32]],"ltp":1.82,"tv":32.35,"id":40296819}]}]}
{"op":"mcm","clk":"11843313766","pt":1723579393569,"mc":[{"id":"1.231732748","rc":[{"batb":[[0,1.75,6.85],[1,1.74,17.32],[2,1.25,100]],"ltp":1.76,"tv":25.99,"id":40296818},{"batb":[[0,1.82,10],[1,1.81,6.9],[2,1.8,444]],"ltp":1.82,"tv":32.35,"id":40296819}]}]}
{"op":"mcm","clk":"11843314332","pt":1723579396985,"mc":[{"id":"1.231732748","rc":[{"batb":[[0,1.81,6.9],[1,1.8,444],[2,1.74,17.32]],"ltp":1.82,"tv":32.35,"id":40296819}]}]}
{"op":"mcm","clk":"11843314403","pt":1723579397351,"mc":[{"id":"1.231732748","rc":[{"batb":[[0,1.76,10],[1,1.75,6.85],[2,1.74,17.32]],"ltp":1.76,"tv":25.99,"id":40296818}]}]}
{"op":"mcm","clk":"11843314868","pt":1723579399881,"mc":[{"id":"1.231732748","rc":[{"batb":[[0,1.82,10],[1,1.81,6.9],[2,1.8,444]],"ltp":1.82,"tv":32.35,"id":40296819}]}]}
{"op":"mcm","clk":"11843315093","pt":1723579401048,"mc":[{"id":"1.231732748","rc":[{"batb":[[0,1.75,6.85],[1,1.74,17.32],[2,1.25,100]],"ltp":1.76,"tv":25.99,"id":40296818}]}]}
{"op":"mcm","clk":"11843315514","pt":1723579403579,"mc":[{"id":"1.231732748","rc":[{"batb":[[0,1.76,10],[1,1.75,6.85],[2,1.74,17.32]],"ltp":1.76,"tv":25.99,"id":40296818},{"batb":[[0,1.81,6.9],[1,1.8,444],[2,1.74,17.32]],"batl":[[0,1.83,1.17],[1,2.34,1.97]],"ltp":1.82,"tv":32.35,"id":40296819}]}]}
{"op":"mcm","clk":"11843316196","pt":1723579407206,"mc":[{"id":"1.231732748","rc":[{"batb":[[0,1.75,6.85],[1,1.74,17.32],[2,1.25,100]],"ltp":1.76,"tv":25.99,"id":40296818}]}]}
{"op":"mcm","clk":"11843316908","pt":1723579411390,"mc":[{"id":"1.231732748","rc":[{"batb":[[0,1.76,10],[1,1.75,6.85],[2,1.74,17.32]],"ltp":1.76,"tv":25.99,"id":40296818}]}]}
{"op":"mcm","clk":"11843317492","pt":1723579414792,"mc":[{"id":"1.231732748","rc":[{"batb":[[0,1.75,6.85],[1,1.74,17.32],[2,1.25,100]],"ltp":1.76,"tv":25.99,"id":40296818}]}]}
{"op":"mcm","clk":"11843318449","pt":1723579419888,"mc":[{"id":"1.231732748","rc":[{"batb":[[0,1.76,10],[1,1.75,6.85],[2,1.74,17.32]],"ltp":1.76,"tv":25.99,"id":40296818}]}]}
{"op":"mcm","clk":"11843319109","pt":1723579423690,"mc":[{"id":"1.231732748","rc":[{"batb":[[0,1.75,6.85],[1,1.74,17.32],[2,1.25,100]],"ltp":1.76,"tv":25.99,"id":40296818}]}]}
{"op":"mcm","clk":"11843319658","pt":1723579427011,"mc":[{"id":"1.231732748","rc":[{"batb":[[0,1.76,10],[1,1.75,6.85],[2,1.74,17.32]],"ltp":1.76,"tv":25.99,"id":40296818}]}]}
{"op":"mcm","clk":"11843320227","pt":1723579430425,"mc":[{"id":"1.231732748","rc":[{"batb":[[0,1.75,6.85],[1,1.74,17.32],[2,1.25,100]],"ltp":1.76,"tv":25.99,"id":40296818}]}]}
{"op":"mcm","clk":"11843321055","pt":1723579435508,"mc":[{"id":"1.231732748","rc":[{"batb":[[0,1.76,10],[1,1.75,6.85],[2,1.74,17.32]],"ltp":1.76,"tv":25.99,"id":40296818}]}]}
{"op":"mcm","clk":"11843321655","pt":1723579439232,"mc":[{"id":"1.231732748","rc":[{"batb":[[0,1.75,6.85],[1,1.74,17.32],[2,1.25,100]],"ltp":1.76,"tv":25.99,"id":40296818}]}]}
{"op":"mcm","clk":"11843322015","pt":1723579441410,"mc":[{"id":"1.231732748","rc":[{"batb":[[0,1.76,10],[1,1.75,6.85],[2,1.74,17.32]],"ltp":1.76,"tv":25.99,"id":40296818}]}]}
{"op":"mcm","clk":"11843322632","pt":1723579445194,"mc":[{"id":"1.231732748","rc":[{"batb":[[0,1.75,6.85],[1,1.74,17.32],[2,1.25,100]],"ltp":1.76,"tv":25.99,"id":40296818}]}]}
{"op":"mcm","clk":"11843323165","pt":1723579448111,"mc":[{"id":"1.231732748","rc":[{"batb":[[0,1.76,10],[1,1.75,6.85],[2,1.74,17.32]],"ltp":1.76,"tv":25.99,"id":40296818}]}]}
{"op":"mcm","clk":"11843323817","pt":1723579451829,"mc":[{"id":"1.231732748","rc":[{"batb":[[0,1.75,6.85],[1,1.74,17.32],[2,1.25,100]],"ltp":1.76,"tv":25.99,"id":40296818}]}]}
{"op":"mcm","clk":"11843324417","pt":1723579455331,"mc":[{"id":"1.231732748","rc":[{"batb":[[0,1.76,10],[1,1.75,6.85],[2,1.74,17.32]],"ltp":1.76,"tv":25.99,"id":40296818}]}]}
{"op":"mcm","clk":"11843325007","pt":1723579459019,"mc":[{"id":"1.231732748","rc":[{"batb":[[0,1.75,6.85],[1,1.74,17.32],[2,1.25,100]],"ltp":1.76,"tv":25.99,"id":40296818}]}]}
{"op":"mcm","clk":"11843325736","pt":1723579463544,"mc":[{"id":"1.231732748","rc":[{"batb":[[0,1.76,10],[1,1.75,6.85],[2,1.74,17.32]],"ltp":1.76,"tv":25.99,"id":40296818}]}]}
{"op":"mcm","clk":"11843326388","pt":1723579467326,"mc":[{"id":"1.231732748","rc":[{"batb":[[0,1.75,6.85],[1,1.74,17.32],[2,1.25,100]],"ltp":1.76,"tv":25.99,"id":40296818}]}]}
{"op":"mcm","clk":"11843326745","pt":1723579469629,"mc":[{"id":"1.231732748","rc":[{"batb":[[0,1.76,10],[1,1.75,6.85],[2,1.74,17.32]],"ltp":1.76,"tv":25.99,"id":40296818}]}]}
{"op":"mcm","clk":"11843327313","pt":1723579473150,"mc":[{"id":"1.231732748","rc":[{"batb":[[0,1.75,6.85],[1,1.74,17.32],[2,1.25,100]],"ltp":1.76,"tv":25.99,"id":40296818}]}]}
{"op":"mcm","clk":"11843328519","pt":1723579480677,"mc":[{"id":"1.231732748","rc":[{"batb":[[0,1.76,10],[1,1.75,6.85],[2,1.74,17.32]],"ltp":1.76,"tv":25.99,"id":40296818}]}]}
{"op":"mcm","clk":"11843329070","pt":1723579484287,"mc":[{"id":"1.231732748","rc":[{"batb":[[0,1.75,6.85],[1,1.74,17.32],[2,1.25,100]],"ltp":1.76,"tv":25.99,"id":40296818}]}]}
{"op":"mcm","clk":"11843329696","pt":1723579488245,"mc":[{"id":"1.231732748","rc":[{"batb":[[0,1.76,10],[1,1.75,6.85],[2,1.74,17.32]],"ltp":1.76,"tv":25.99,"id":40296818}]}]}
{"op":"mcm","clk":"11843330286","pt":1723579491687,"mc":[{"id":"1.231732748","rc":[{"batb":[[0,1.75,6.85],[1,1.74,17.32],[2,1.25,100]],"ltp":1.76,"tv":25.99,"id":40296818}]}]}
{"op":"mcm","clk":"11843331036","pt":1723579495554,"mc":[{"id":"1.231732748","rc":[{"batb":[[0,1.76,10],[1,1.75,6.85],[2,1.74,17.32]],"ltp":1.76,"tv":25.99,"id":40296818}]}]}
{"op":"mcm","clk":"11843331629","pt":1723579499164,"mc":[{"id":"1.231732748","rc":[{"batb":[[0,1.75,6.85],[1,1.74,17.32],[2,1.25,100]],"ltp":1.76,"tv":25.99,"id":40296818}]}]}
{"op":"mcm","clk":"11843332089","pt":1723579501860,"mc":[{"id":"1.231732748","rc":[{"batb":[[0,1.76,10],[1,1.75,6.85],[2,1.74,17.32]],"ltp":1.76,"tv":25.99,"id":40296818}]}]}
{"op":"mcm","clk":"11843332718","pt":1723579505540,"mc":[{"id":"1.231732748","rc":[{"batb":[[0,1.75,6.85],[1,1.74,17.32],[2,1.25,100]],"ltp":1.76,"tv":25.99,"id":40296818}]}]}
{"op":"mcm","clk":"11843333166","pt":1723579508151,"mc":[{"id":"1.231732748","rc":[{"batb":[[0,1.76,10],[1,1.75,6.85],[2,1.74,17.32]],"ltp":1.76,"tv":25.99,"id":40296818}]}]}
{"op":"mcm","clk":"11843333748","pt":1723579511660,"mc":[{"id":"1.231732748","rc":[{"batb":[[0,1.75,6.85],[1,1.74,17.32],[2,1.25,100]],"ltp":1.76,"tv":25.99,"id":40296818}]}]}
{"op":"mcm","clk":"11843334381","pt":1723579515285,"mc":[{"id":"1.231732748","rc":[{"batb":[[0,1.76,10],[1,1.75,6.85],[2,1.74,17.32]],"ltp":1.76,"tv":25.99,"id":40296818}]}]}
{"op":"mcm","clk":"11843335041","pt":1723579519267,"mc":[{"id":"1.231732748","rc":[{"batb":[[0,1.75,6.85],[1,1.74,17.32],[2,1.25,100]],"ltp":1.76,"tv":25.99,"id":40296818}]}]}
{"op":"mcm","clk":"11843335447","pt":1723579521585,"mc":[{"id":"1.231732748","rc":[{"batb":[[0,1.76,10],[1,1.75,6.85],[2,1.74,17.32]],"ltp":1.76,"tv":25.99,"id":40296818}]}]}
{"op":"mcm","clk":"11843335969","pt":1723579524995,"mc":[{"id":"1.231732748","rc":[{"batb":[[0,1.75,6.85],[1,1.74,17.32],[2,1.25,100]],"ltp":1.76,"tv":25.99,"id":40296818}]}]}
{"op":"mcm","clk":"11843336509","pt":1723579528205,"mc":[{"id":"1.231732748","rc":[{"batb":[[0,1.76,10],[1,1.75,6.85],[2,1.74,17.32]],"ltp":1.76,"tv":25.99,"id":40296818}]}]}
{"op":"mcm","clk":"11843337103","pt":1723579532086,"mc":[{"id":"1.231732748","rc":[{"batb":[[0,1.75,6.85],[1,1.74,17.32],[2,1.25,100]],"ltp":1.76,"tv":25.99,"id":40296818}]}]}
{"op":"mcm","clk":"11843337549","pt":1723579534830,"mc":[{"id":"1.231732748","rc":[{"batb":[[0,1.76,10],[1,1.75,6.85],[2,1.74,17.32]],"ltp":1.76,"tv":25.99,"id":40296818}]}]}
{"op":"mcm","clk":"11843338197","pt":1723579538495,"mc":[{"id":"1.231732748","rc":[{"batb":[[0,1.75,6.85],[1,1.74,17.32],[2,1.25,100]],"ltp":1.76,"tv":25.99,"id":40296818}]}]}
{"op":"mcm","clk":"11843338653","pt":1723579541300,"mc":[{"id":"1.231732748","rc":[{"batb":[[0,1.76,10],[1,1.75,6.85],[2,1.74,17.32]],"ltp":1.76,"tv":25.99,"id":40296818}]}]}
{"op":"mcm","clk":"11843339177","pt":1723579544826,"mc":[{"id":"1.231732748","rc":[{"batb":[[0,1.75,6.85],[1,1.74,17.32],[2,1.25,100]],"ltp":1.76,"tv":25.99,"id":40296818}]}]}
{"op":"mcm","clk":"11843339683","pt":1723579548118,"mc":[{"id":"1.231732748","rc":[{"batb":[[0,1.76,10],[1,1.75,6.85],[2,1.74,17.32]],"ltp":1.76,"tv":25.99,"id":40296818}]}]}
{"op":"mcm","clk":"11843340284","pt":1723579552066,"mc":[{"id":"1.231732748","rc":[{"batb":[[0,1.75,6.85],[1,1.74,17.32],[2,1.25,100]],"ltp":1.76,"tv":25.99,"id":40296818}]}]}
{"op":"mcm","clk":"11843340773","pt":1723579555231,"mc":[{"id":"1.231732748","rc":[{"batb":[[0,1.76,10],[1,1.75,6.85],[2,1.74,17.32]],"ltp":1.76,"tv":25.99,"id":40296818}]}]}
{"op":"mcm","clk":"11843341077","pt":1723579557232,"mc":[{"id":"1.231732748","rc":[{"batb":[[0,1.82,10],[1,1.81,6.9],[2,1.8,444]],"batl":[[0,2.34,1.97],[1,2.34,0]],"ltp":1.82,"tv":32.35,"id":40296819}]}]}
{"op":"mcm","clk":"11843341277","pt":1723579558539,"mc":[{"id":"1.231732748","rc":[{"batb":[[0,1.75,6.85],[1,1.74,17.32],[2,1.25,100]],"ltp":1.76,"tv":25.99,"id":40296818}]}]}
{"op":"mcm","clk":"11843341673","pt":1723579560858,"mc":[{"id":"1.231732748","rc":[{"batb":[[0,1.76,10],[1,1.75,6.85],[2,1.74,17.32]],"ltp":1.76,"tv":25.99,"id":40296818},{"batb":[[0,1.81,6.9],[1,1.8,444],[2,1.74,17.32]],"ltp":1.82,"tv":32.35,"id":40296819}]}]}
{"op":"mcm","clk":"11843342251","pt":1723579563910,"mc":[{"id":"1.231732748","rc":[{"batb":[[0,1.82,10],[1,1.81,6.9],[2,1.8,444]],"ltp":1.82,"tv":32.35,"id":40296819}]}]}
{"op":"mcm","clk":"11843342288","pt":1723579564122,"mc":[{"id":"1.231732748","rc":[{"batb":[[0,1.75,6.85],[1,1.74,17.32],[2,1.25,100]],"ltp":1.76,"tv":25.99,"id":40296818}]}]}
{"op":"mcm","clk":"11843342814","pt":1723579567631,"mc":[{"id":"1.231732748","rc":[{"batb":[[0,1.76,10],[1,1.75,6.85],[2,1.74,17.32]],"ltp":1.76,"tv":25.99,"id":40296818},{"batb":[[0,1.81,6.9],[1,1.8,444],[2,1.74,17.32]],"ltp":1.82,"tv":32.35,"id":40296819}]}]}
{"op":"mcm","clk":"11843343308","pt":1723579570953,"mc":[{"id":"1.231732748","rc":[{"batb":[[0,1.75,6.85],[1,1.74,17.32],[2,1.25,100]],"batl":[[0,1.77,1.17],[1,2.24,17.14]],"ltp":1.76,"tv":25.99,"id":40296818},{"batb":[[0,1.82,10],[1,1.81,6.9],[2,1.8,444]],"ltp":1.82,"tv":32.35,"id":40296819}]}]}
{"op":"mcm","clk":"11843343696","pt":1723579573357,"mc":[{"id":"1.231732748","rc":[{"batb":[[0,1.81,6.9],[1,1.8,444],[2,1.74,17.32]],"ltp":1.82,"tv":32.35,"id":40296819}]}]}
{"op":"mcm","clk":"11843344345","pt":1723579577565,"mc":[{"id":"1.231732748","rc":[{"batb":[[0,1.82,10],[1,1.81,6.9],[2,1.8,444]],"ltp":1.82,"tv":32.35,"id":40296819}]}]}
{"op":"mcm","clk":"11843344822","pt":1723579580838,"mc":[{"id":"1.231732748","rc":[{"batb":[[0,1.81,6.9],[1,1.8,444],[2,1.74,17.32]],"ltp":1.82,"tv":32.35,"id":40296819}]}]}
{"op":"mcm","clk":"11843345233","pt":1723579583465,"mc":[{"id":"1.231732748","rc":[{"batb":[[0,1.82,10],[1,1.81,6.9],[2,1.8,444]],"ltp":1.82,"tv":32.35,"id":40296819}]}]}
{"op":"mcm","clk":"11843345796","pt":1723579587078,"mc":[{"id":"1.231732748","rc":[{"batb":[[0,1.81,6.9],[1,1.8,444],[2,1.74,17.32]],"ltp":1.82,"tv":32.35,"id":40296819}]}]}
{"op":"mcm","clk":"11843346235","pt":1723579590171,"mc":[{"id":"1.231732748","rc":[{"batb":[[0,1.82,10],[1,1.81,6.9],[2,1.8,444]],"ltp":1.82,"tv":32.35,"id":40296819}]}]}
{"op":"mcm","clk":"11843346815","pt":1723579593689,"mc":[{"id":"1.231732748","rc":[{"batb":[[0,1.81,6.9],[1,1.8,444],[2,1.74,17.32]],"ltp":1.82,"tv":32.35,"id":40296819}]}]}
{"op":"mcm","clk":"11843347458","pt":1723579597690,"mc":[{"id":"1.231732748","rc":[{"batb":[[0,1.82,10],[1,1.81,6.9],[2,1.8,444]],"ltp":1.82,"tv":32.35,"id":40296819}]}]}
{"op":"mcm","clk":"11843347979","pt":1723579601069,"mc":[{"id":"1.231732748","rc":[{"batb":[[0,1.81,6.9],[1,1.8,444],[2,1.74,17.32]],"ltp":1.82,"tv":32.35,"id":40296819}]}]}
{"op":"mcm","clk":"11843348707","pt":1723579605496,"mc":[{"id":"1.231732748","rc":[{"batb":[[0,1.82,10],[1,1.81,6.9],[2,1.8,444]],"ltp":1.82,"tv":32.35,"id":40296819}]}]}
{"op":"mcm","clk":"11843349313","pt":1723579609170,"mc":[{"id":"1.231732748","rc":[{"batb":[[0,1.81,6.9],[1,1.8,444],[2,1.74,17.32]],"ltp":1.82,"tv":32.35,"id":40296819}]}]}
{"op":"mcm","clk":"11843349784","pt":1723579612061,"mc":[{"id":"1.231732748","rc":[{"batb":[[0,1.82,10],[1,1.81,6.9],[2,1.8,444]],"ltp":1.82,"tv":32.35,"id":40296819}]}]}
{"op":"mcm","clk":"11843350366","pt":1723579615494,"mc":[{"id":"1.231732748","rc":[{"batb":[[0,1.81,6.9],[1,1.8,444],[2,1.74,17.32]],"ltp":1.82,"tv":32.35,"id":40296819}]}]}
{"op":"mcm","clk":"11843351042","pt":1723579619708,"mc":[{"id":"1.231732748","rc":[{"batb":[[0,1.82,10],[1,1.81,6.9],[2,1.8,444]],"ltp":1.82,"tv":32.35,"id":40296819}]}]}
{"op":"mcm","clk":"11843351619","pt":1723579623280,"mc":[{"id":"1.231732748","rc":[{"batb":[[0,1.81,6.9],[1,1.8,444],[2,1.74,17.32]],"ltp":1.82,"tv":32.35,"id":40296819}]}]}
{"op":"mcm","clk":"11843352122","pt":1723579626603,"mc":[{"id":"1.231732748","rc":[{"batb":[[0,1.82,10],[1,1.81,6.9],[2,1.8,444]],"ltp":1.82,"tv":32.35,"id":40296819}]}]}
{"op":"mcm","clk":"11843353407","pt":1723579634305,"mc":[{"id":"1.231732748","rc":[{"batb":[[0,1.81,6.9],[1,1.8,444],[2,1.74,17.32]],"ltp":1.82,"tv":32.35,"id":40296819}]}]}
{"op":"mcm","clk":"11843354827","pt":1723579642125,"mc":[{"id":"1.231732748","rc":[{"batb":[[0,1.82,10],[1,1.81,6.9],[2,1.8,444]],"ltp":1.82,"tv":32.35,"id":40296819}]}]}
{"op":"mcm","clk":"11843356386","pt":1723579651725,"mc":[{"id":"1.231732748","rc":[{"batb":[[0,1.81,6.9],[1,1.8,444],[2,1.74,17.32]],"ltp":1.82,"tv":32.35,"id":40296819}]}]}
{"op":"mcm","clk":"11843356740","pt":1723579653936,"mc":[{"id":"1.231732748","rc":[{"batb":[[0,1.83,10],[1,1.81,6.9],[2,1.8,444]],"ltp":1.82,"tv":32.35,"id":40296819}]}]}
{"op":"mcm","clk":"11843357956","pt":1723579660944,"mc":[{"id":"1.231732748","rc":[{"batb":[[0,1.81,6.9],[1,1.8,444],[2,1.74,17.32]],"ltp":1.82,"tv":32.35,"id":40296819}]}]}
{"op":"mcm","clk":"11843358378","pt":1723579663320,"mc":[{"id":"1.231732748","rc":[{"batb":[[0,1.84,10],[1,1.81,6.9],[2,1.8,444]],"ltp":1.82,"tv":32.35,"id":40296819}]}]}
{"op":"mcm","clk":"11843359422","pt":1723579669235,"mc":[{"id":"1.231732748","rc":[{"batb":[[0,1.81,6.9],[1,1.8,444],[2,1.74,17.32]],"ltp":1.82,"tv":32.35,"id":40296819}]}]}
{"op":"mcm","clk":"11843360210","pt":1723579674170,"mc":[{"id":"1.231732748","rc":[{"batb":[[0,1.82,10],[1,1.81,6.9],[2,1.8,444]],"ltp":1.82,"tv":32.35,"id":40296819}]}]}
{"op":"mcm","clk":"11843360837","pt":1723579677760,"mc":[{"id":"1.231732748","rc":[{"batb":[[0,1.81,6.9],[1,1.8,444],[2,1.74,17.32]],"ltp":1.82,"tv":32.35,"id":40296819}]}]}
{"op":"mcm","clk":"11843361175","pt":1723579679937,"mc":[{"id":"1.231732748","rc":[{"batb":[[0,1.82,10],[1,1.81,6.9],[2,1.8,444]],"ltp":1.82,"tv":32.35,"id":40296819}]}]}
{"op":"mcm","clk":"11843361761","pt":1723579683462,"mc":[{"id":"1.231732748","rc":[{"batb":[[0,1.81,6.9],[1,1.8,444],[2,1.74,17.32]],"ltp":1.82,"tv":32.35,"id":40296819}]}]}
{"op":"mcm","clk":"11843362193","pt":1723579685985,"mc":[{"id":"1.231732748","rc":[{"batb":[[0,1.82,10],[1,1.81,6.9],[2,1.8,444]],"ltp":1.82,"tv":32.35,"id":40296819}]}]}
{"op":"mcm","clk":"11843362799","pt":1723579689773,"mc":[{"id":"1.231732748","rc":[{"batb":[[0,1.81,6.9],[1,1.8,444],[2,1.74,17.32]],"ltp":1.82,"tv":32.35,"id":40296819}]}]}
{"op":"mcm","clk":"11843363443","pt":1723579693696,"mc":[{"id":"1.231732748","rc":[{"batb":[[0,1.82,10],[1,1.81,6.9],[2,1.8,444]],"ltp":1.82,"tv":32.35,"id":40296819}]}]}
{"op":"mcm","clk":"11843363978","pt":1723579697287,"mc":[{"id":"1.231732748","rc":[{"batb":[[0,1.81,6.9],[1,1.8,444],[2,1.74,17.32]],"ltp":1.82,"tv":32.35,"id":40296819}]}]}
{"op":"mcm","clk":"11843364428","pt":1723579699979,"mc":[{"id":"1.231732748","rc":[{"batb":[[0,1.82,10],[1,1.81,6.9],[2,1.8,444]],"ltp":1.82,"tv":32.35,"id":40296819}]}]}
{"op":"mcm","clk":"11843364978","pt":1723579703411,"mc":[{"id":"1.231732748","rc":[{"batb":[[0,1.81,6.9],[1,1.8,444],[2,1.74,17.32]],"ltp":1.82,"tv":32.35,"id":40296819}]}]}
{"op":"mcm","clk":"11843365495","pt":1723579706318,"mc":[{"id":"1.231732748","rc":[{"batb":[[0,1.82,10],[1,1.81,6.9],[2,1.8,444]],"ltp":1.82,"tv":32.35,"id":40296819}]}]}
{"op":"mcm","clk":"11843366189","pt":1723579710186,"mc":[{"id":"1.231732748","rc":[{"batb":[[0,1.81,6.9],[1,1.8,444],[2,1.74,17.32]],"ltp":1.82,"tv":32.35,"id":40296819}]}]}
{"op":"mcm","clk":"11843366604","pt":1723579712703,"mc":[{"id":"1.231732748","rc":[{"batb":[[0,1.82,10],[1,1.81,6.9],[2,1.8,444]],"ltp":1.82,"tv":32.35,"id":40296819}]}]}
{"op":"mcm","clk":"11843367169","pt":1723579716009,"mc":[{"id":"1.231732748","rc":[{"batb":[[0,1.81,6.9],[1,1.8,444],[2,1.74,17.32]],"ltp":1.82,"tv":32.35,"id":40296819}]}]}
{"op":"mcm","clk":"11843367860","pt":1723579719904,"mc":[{"id":"1.231732748","rc":[{"batb":[[0,1.82,10],[1,1.81,6.9],[2,1.8,444]],"ltp":1.82,"tv":32.35,"id":40296819}]}]}
{"op":"mcm","clk":"11843368473","pt":1723579723590,"mc":[{"id":"1.231732748","rc":[{"batb":[[0,1.81,6.9],[1,1.8,444],[2,1.74,17.32]],"ltp":1.82,"tv":32.35,"id":40296819}]}]}
{"op":"mcm","clk":"11843369854","pt":1723579731883,"mc":[{"id":"1.231732748","rc":[{"batb":[[0,1.82,10],[1,1.81,6.9],[2,1.8,444]],"ltp":1.82,"tv":32.35,"id":40296819}]}]}
{"op":"mcm","clk":"11843370530","pt":1723579735688,"mc":[{"id":"1.231732748","rc":[{"batb":[[0,1.81,6.9],[1,1.8,444],[2,1.74,17.32]],"ltp":1.82,"tv":32.35,"id":40296819}]}]}
{"op":"mcm","clk":"11843370926","pt":1723579738009,"mc":[{"id":"1.231732748","rc":[{"batl":[[0,2.24,17.14],[1,2.24,0]],"ltp":1.76,"tv":25.99,"id":40296818}]}]}
{"op":"mcm","clk":"11843370968","pt":1723579738219,"mc":[{"id":"1.231732748","rc":[{"batb":[[0,1.76,10],[1,1.75,6.85],[2,1.74,17.32]],"ltp":1.76,"tv":25.99,"id":40296818},{"batb":[[0,1.82,10],[1,1.81,6.9],[2,1.8,444]],"ltp":1.82,"tv":32.35,"id":40296819}]}]}
{"op":"mcm","clk":"11843371579","pt":1723579741602,"mc":[{"id":"1.231732748","rc":[{"batb":[[0,1.75,6.85],[1,1.74,17.32],[2,1.25,100]],"ltp":1.76,"tv":25.99,"id":40296818},{"batb":[[0,1.81,6.9],[1,1.8,444],[2,1.74,17.32]],"ltp":1.82,"tv":32.35,"id":40296819}]}]}
{"op":"mcm","clk":"11843372151","pt":1723579744815,"mc":[{"id":"1.231732748","rc":[{"batb":[[0,1.76,10],[1,1.75,6.85],[2,1.74,17.32]],"ltp":1.76,"tv":25.99,"id":40296818},{"batb":[[0,1.82,10],[1,1.81,6.9],[2,1.8,444]],"ltp":1.82,"tv":32.35,"id":40296819}]}]}
{"op":"mcm","clk":"11843372755","pt":1723579748277,"mc":[{"id":"1.231732748","rc":[{"batb":[[0,1.75,6.85],[1,1.74,17.32],[2,1.25,100]],"ltp":1.76,"tv":25.99,"id":40296818},{"batb":[[0,1.81,6.9],[1,1.8,444],[2,1.74,17.32]],"ltp":1.82,"tv":32.35,"id":40296819}]}]}
{"op":"mcm","clk":"11843372978","pt":1723579749449,"mc":[{"id":"1.231732748","rc":[{"batl":[[0,1.83,1.17],[1,2.34,1.97]],"ltp":1.82,"tv":32.35,"id":40296819}]}]}
{"op":"mcm","clk":"11843373419","pt":1723579751876,"mc":[{"id":"1.231732748","rc":[{"batb":[[0,1.76,10],[1,1.75,6.85],[2,1.74,17.32]],"ltp":1.76,"tv":25.99,"id":40296818}]}]}
{"op":"mcm","clk":"11843374134","pt":1723579755680,"mc":[{"id":"1.231732748","rc":[{"batb":[[0,1.75,6.85],[1,1.74,17.32],[2,1.25,100]],"ltp":1.76,"tv":25.99,"id":40296818}]}]}
{"op":"mcm","clk":"11843374657","pt":1723579758783,"mc":[{"id":"1.231732748","rc":[{"batb":[[0,1.76,10],[1,1.75,6.85],[2,1.74,17.32]],"ltp":1.76,"tv":25.99,"id":40296818}]}]}
{"op":"mcm","clk":"11843375310","pt":1723579762495,"mc":[{"id":"1.231732748","rc":[{"batb":[[0,1.75,6.85],[1,1.74,17.32],[2,1.25,100]],"ltp":1.76,"tv":25.99,"id":40296818}]}]}
{"op":"mcm","clk":"11843375918","pt":1723579765566,"mc":[{"id":"1.231732748","rc":[{"batb":[[0,1.76,10],[1,1.75,6.85],[2,1.74,17.32]],"ltp":1.76,"tv":25.99,"id":40296818}]}]}
{"op":"mcm","clk":"11843376530","pt":1723579769230,"mc":[{"id":"1.231732748","rc":[{"batb":[[0,1.75,6.85],[1,1.74,17.32],[2,1.25,100]],"ltp":1.76,"tv":25.99,"id":40296818}]}]}
{"op":"mcm","clk":"11843377068","pt":1723579772684,"mc":[{"id":"1.231732748","rc":[{"batb":[[0,1.76,10],[1,1.75,6.85],[2,1.74,17.32]],"ltp":1.76,"tv":25.99,"id":40296818}]}]}
{"op":"mcm","clk":"11843377595","pt":1723579776298,"mc":[{"id":"1.231732748","rc":[{"batb":[[0,1.75,6.85],[1,1.74,17.32],[2,1.25,100]],"ltp":1.76,"tv":25.99,"id":40296818}]}]}
{"op":"mcm","clk":"11843378626","pt":1723579782978,"mc":[{"id":"1.231732748","rc":[{"batb":[[0,1.76,10],[1,1.75,6.85],[2,1.74,17.32]],"ltp":1.76,"tv":25.99,"id":40296818}]}]}
{"op":"mcm","clk":"11843379205","pt":1723579786902,"mc":[{"id":"1.231732748","rc":[{"batb":[[0,1.75,6.85],[1,1.74,17.32],[2,1.25,100]],"ltp":1.76,"tv":25.99,"id":40296818}]}]}
{"op":"mcm","clk":"11843379786","pt":1723579790197,"mc":[{"id":"1.231732748","rc":[{"batb":[[0,1.76,10],[1,1.75,6.85],[2,1.74,17.32]],"ltp":1.76,"tv":25.99,"id":40296818}]}]}
{"op":"mcm","clk":"11843380289","pt":1723579793615,"mc":[{"id":"1.231732748","rc":[{"batb":[[0,1.75,6.85],[1,1.74,17.32],[2,1.25,100]],"ltp":1.76,"tv":25.99,"id":40296818}]}]}
{"op":"mcm","clk":"11843380955","pt":1723579797824,"mc":[{"id":"1.231732748","rc":[{"batb":[[0,1.76,10],[1,1.75,6.85],[2,1.74,17.32]],"ltp":1.76,"tv":25.99,"id":40296818}]}]}
{"op":"mcm","clk":"11843381533","pt":1723579801409,"mc":[{"id":"1.231732748","rc":[{"batb":[[0,1.75,6.85],[1,1.74,17.32],[2,1.25,100]],"ltp":1.76,"tv":25.99,"id":40296818}]}]}
{"op":"mcm","clk":"11843381934","pt":1723579803999,"mc":[{"id":"1.231732748","rc":[{"batb":[[0,1.76,10],[1,1.75,6.85],[2,1.74,17.32]],"ltp":1.76,"tv":25.99,"id":40296818}]}]}
{"op":"mcm","clk":"11843382544","pt":1723579807835,"mc":[{"id":"1.231732748","rc":[{"batb":[[0,1.75,6.85],[1,1.74,17.32],[2,1.25,100]],"ltp":1.76,"tv":25.99,"id":40296818}]}]}
{"op":"mcm","clk":"11843383560","pt":1723579813930,"mc":[{"id":"1.231732748","rc":[{"batb":[[0,1.76,10],[1,1.75,6.85],[2,1.74,17.32]],"ltp":1.76,"tv":25.99,"id":40296818}]}]}
{"op":"mcm","clk":"11843384170","pt":1723579817636,"mc":[{"id":"1.231732748","rc":[{"batb":[[0,1.75,6.85],[1,1.74,17.32],[2,1.25,100]],"ltp":1.76,"tv":25.99,"id":40296818}]}]}
{"op":"mcm","clk":"11843384895","pt":1723579822133,"mc":[{"id":"1.231732748","rc":[{"batb":[[0,1.76,10],[1,1.75,6.85],[2,1.74,17.32]],"ltp":1.76,"tv":25.99,"id":40296818}]}]}
{"op":"mcm","clk":"11843385535","pt":1723579825819,"mc":[{"id":"1.231732748","rc":[{"batb":[[0,1.75,6.85],[1,1.74,17.32],[2,1.25,100]],"ltp":1.76,"tv":25.99,"id":40296818}]}]}
{"op":"mcm","clk":"11843385964","pt":1723579828652,"mc":[{"id":"1.231732748","rc":[{"batb":[[0,1.76,10],[1,1.75,6.85],[2,1.74,17.32]],"ltp":1.76,"tv":25.99,"id":40296818}]}]}
{"op":"mcm","clk":"11843386640","pt":1723579832721,"mc":[{"id":"1.231732748","rc":[{"batb":[[0,1.75,6.85],[1,1.74,17.32],[2,1.25,100]],"ltp":1.76,"tv":25.99,"id":40296818}]}]}
{"op":"mcm","clk":"11843387090","pt":1723579835625,"mc":[{"id":"1.231732748","rc":[{"batb":[[0,1.76,10],[1,1.75,6.85],[2,1.74,17.32]],"ltp":1.76,"tv":25.99,"id":40296818}]}]}
{"op":"mcm","clk":"11843387375","pt":1723579837652,"mc":[{"id":"1.231732748","rc":[{"batl":[[0,2.34,1.97],[1,2.34,0]],"ltp":1.82,"tv":32.35,"id":40296819}]}]}
{"op":"mcm","clk":"11843387471","pt":1723579838221,"mc":[{"id":"1.231732748","rc":[{"batb":[[0,1.82,10],[1,1.81,6.9],[2,1.8,444]],"ltp":1.82,"tv":32.35,"id":40296819}]}]}
{"op":"mcm","clk":"11843387699","pt":1723579839554,"mc":[{"id":"1.231732748","rc":[{"batb":[[0,1.75,6.85],[1,1.74,17.32],[2,1.25,100]],"ltp":1.76,"tv":25.99,"id":40296818}]}]}
{"op":"mcm","clk":"11843388034","pt":1723579841738,"mc":[{"id":"1.231732748","rc":[{"batb":[[0,1.81,6.9],[1,1.8,444],[2,1.74,17.32]],"ltp":1.82,"tv":32.35,"id":40296819}]}]}
{"op":"mcm","clk":"11843388082","pt":1723579842050,"mc":[{"id":"1.231732748","rc":[{"batb":[[0,1.76,10],[1,1.75,6.85],[2,1.74,17.32]],"ltp":1.76,"tv":25.99,"id":40296818}]}]}
{"op":"mcm","clk":"11843388630","pt":1723579845539,"mc":[{"id":"1.231732748","rc":[{"batb":[[0,1.75,6.85],[1,1.74,17.32],[2,1.25,100]],"ltp":1.76,"tv":25.99,"id":40296818},{"batb":[[0,1.82,10],[1,1.81,6.9],[2,1.8,444]],"ltp":1.82,"tv":32.35,"id":40296819}]}]}
{"op":"mcm","clk":"11843389085","pt":1723579848649,"mc":[{"id":"1.231732748","rc":[{"batb":[[0,1.76,10],[1,1.75,6.85],[2,1.74,17.32]],"ltp":1.76,"tv":25.99,"id":40296818},{"batb":[[0,1.81,6.9],[1,1.8,444],[2,1.74,17.32]],"ltp":1.82,"tv":32.35,"id":40296819}]}]}
{"op":"mcm","clk":"11843389427","pt":1723579850852,"mc":[{"id":"1.231732748","rc":[{"batb":[[0,1.82,10],[1,1.81,6.9],[2,1.8,444]],"ltp":1.82,"tv":32.35,"id":40296819}]}]}
{"op":"mcm","clk":"11843389600","pt":1723579852164,"mc":[{"id":"1.231732748","rc":[{"batb":[[0,1.75,6.85],[1,1.74,17.32],[2,1.25,100]],"ltp":1.76,"tv":25.99,"id":40296818}]}]}
{"op":"mcm","clk":"11843390032","pt":1723579854749,"mc":[{"id":"1.231732748","rc":[{"batb":[[0,1.76,10],[1,1.75,6.85],[2,1.74,17.32]],"ltp":1.76,"tv":25.99,"id":40296818},{"batb":[[0,1.81,6.9],[1,1.8,444],[2,1.74,17.32]],"ltp":1.82,"tv":32.35,"id":40296819}]}]}
{"op":"mcm","clk":"11843390433","pt":1723579857262,"mc":[{"id":"1.231732748","rc":[{"batb":[[0,1.82,10],[1,1.81,6.9],[2,1.8,444]],"ltp":1.82,"tv":32.35,"id":40296819}]}]}
{"op":"mcm","clk":"11843390604","pt":1723579858271,"mc":[{"id":"1.231732748","rc":[{"batb":[[0,1.75,6.85],[1,1.74,17.32],[2,1.25,100]],"ltp":1.76,"tv":25.99,"id":40296818}]}]}
{"op":"mcm","clk":"11843390967","pt":1723579860750,"mc":[{"id":"1.231732748","rc":[{"batb":[[0,1.76,10],[1,1.75,6.85],[2,1.74,17.32]],"ltp":1.76,"tv":25.99,"id":40296818},{"batb":[[0,1.81,6.9],[1,1.8,444],[2,1.74,17.32]],"ltp":1.82,"tv":32.35,"id":40296819}]}]}
{"op":"mcm","clk":"11843391456","pt":1723579863651,"mc":[{"id":"1.231732748","rc":[{"batb":[[0,1.82,10],[1,1.81,6.9],[2,1.8,444]],"ltp":1.82,"tv":32.35,"id":40296819}]}]}
{"op":"mcm","clk":"11843391564","pt":1723579864283,"mc":[{"id":"1.231732748","rc":[{"batb":[[0,1.75,6.85],[1,1.74,17.32],[2,1.25,100]],"ltp":1.76,"tv":25.99,"id":40296818}]}]}
{"op":"mcm","clk":"11843391943","pt":1723579866892,"mc":[{"id":"1.231732748","rc":[{"batb":[[0,1.76,10],[1,1.75,6.85],[2,1.74,17.32]],"ltp":1.76,"tv":25.99,"id":40296818}]}]}
{"op":"mcm","clk":"11843392003","pt":1723579867366,"mc":[{"id":"1.231732748","rc":[{"batb":[[0,1.81,6.9],[1,1.8,444],[2,1.74,17.32]],"ltp":1.82,"tv":32.35,"id":40296819}]}]}
{"op":"mcm","clk":"11843392493","pt":1723579870583,"mc":[{"id":"1.231732748","rc":[{"batb":[[0,1.75,6.85],[1,1.74,17.32],[2,1.25,100]],"ltp":1.76,"tv":25.99,"id":40296818},{"batb":[[0,1.82,10],[1,1.81,6.9],[2,1.8,444]],"ltp":1.82,"tv":32.35,"id":40296819}]}]}
{"op":"mcm","clk":"11843393020","pt":1723579873854,"mc":[{"id":"1.231732748","rc":[{"batb":[[0,1.81,6.9],[1,1.8,444],[2,1.74,17.32]],"ltp":1.82,"tv":32.35,"id":40296819}]}]}
{"op":"mcm","clk":"11843393051","pt":1723579874062,"mc":[{"id":"1.231732748","rc":[{"batb":[[0,1.76,10],[1,1.75,6.85],[2,1.74,17.32]],"ltp":1.76,"tv":25.99,"id":40296818}]}]}
{"op":"mcm","clk":"11843393473","pt":1723579876989,"mc":[{"id":"1.231732748","rc":[{"batb":[[0,1.82,10],[1,1.81,6.9],[2,1.8,444]],"ltp":1.82,"tv":32.35,"id":40296819}]}]}
{"op":"mcm","clk":"11843393580","pt":1723579877468,"mc":[{"id":"1.231732748","rc":[{"batb":[[0,1.75,6.85],[1,1.74,17.32],[2,1.25,100]],"ltp":1.76,"tv":25.99,"id":40296818}]}]}
{"op":"mcm","clk":"11843394001","pt":1723579880467,"mc":[{"id":"1.231732748","rc":[{"batb":[[0,1.76,10],[1,1.75,6.85],[2,1.74,17.32]],"ltp":1.76,"tv":25.99,"id":40296818},{"batb":[[0,1.81,6.9],[1,1.8,444],[2,1.74,17.32]],"ltp":1.82,"tv":32.35,"id":40296819}]}]}
{"op":"mcm","clk":"11843394563","pt":1723579884417,"mc":[{"id":"1.231732748","rc":[{"batb":[[0,1.75,6.85],[1,1.74,17.32],[2,1.25,100]],"ltp":1.76,"tv":25.99,"id":40296818},{"batb":[[0,1.82,10],[1,1.81,6.9],[2,1.8,444]],"ltp":1.82,"tv":32.35,"id":40296819}]}]}
{"op":"mcm","clk":"11843394949","pt":1723579886668,"mc":[{"id":"1.231732748","rc":[{"batb":[[0,1.76,10],[1,1.75,6.85],[2,1.74,17.32]],"ltp":1.76,"tv":25.99,"id":40296818}]}]}
{"op":"mcm","clk":"11843395093","pt":1723579887874,"mc":[{"id":"1.231732748","rc":[{"batb":[[0,1.81,6.9],[1,1.8,444],[2,1.74,17.32]],"ltp":1.82,"tv":32.35,"id":40296819}]}]}
{"op":"mcm","clk":"11843395486","pt":1723579890721,"mc":[{"id":"1.231732748","rc":[{"batb":[[0,1.75,6.85],[1,1.74,17.32],[2,1.25,100]],"ltp":1.76,"tv":25.99,"id":40296818},{"batb":[[0,1.82,10],[1,1.81,6.9],[2,1.8,444]],"ltp":1.82,"tv":32.35,"id":40296819}]}]}
{"op":"mcm","clk":"11843395935","pt":1723579893802,"mc":[{"id":"1.231732748","rc":[{"batb":[[0,1.76,10],[1,1.75,6.85],[2,1.74,17.32]],"ltp":1.76,"tv":25.99,"id":40296818}]}]}
{"op":"mcm","clk":"11843395979","pt":1723579894120,"mc":[{"id":"1.231732748","rc":[{"batb":[[0,1.81,6.9],[1,1.8,444],[2,1.74,17.32]],"ltp":1.82,"tv":32.35,"id":40296819}]}]}
{"op":"mcm","clk":"11843396440","pt":1723579897431,"mc":[{"id":"1.231732748","rc":[{"batb":[[0,1.75,6.85],[1,1.74,17.32],[2,1.25,100]],"ltp":1.76,"tv":25.99,"id":40296818},{"batb":[[0,1.82,10],[1,1.81,6.9],[2,1.8,444]],"ltp":1.82,"tv":32.35,"id":40296819}]}]}
{"op":"mcm","clk":"11843396823","pt":1723579900004,"mc":[{"id":"1.231732748","rc":[{"batb":[[0,1.76,10],[1,1.75,6.85],[2,1.74,17.32]],"ltp":1.76,"tv":25.99,"id":40296818}]}]}
{"op":"mcm","clk":"11843396952","pt":1723579900925,"mc":[{"id":"1.231732748","rc":[{"batb":[[0,1.81,6.9],[1,1.8,444],[2,1.74,17.32]],"ltp":1.82,"tv":32.35,"id":40296819}]}]}
{"op":"mcm","clk":"11843397364","pt":1723579903808,"mc":[{"id":"1.231732748","rc":[{"batb":[[0,1.75,6.85],[1,1.74,17.32],[2,1.25,100]],"ltp":1.76,"tv":25.99,"id":40296818},{"batb":[[0,1.82,10],[1,1.81,6.9],[2,1.8,444]],"ltp":1.82,"tv":32.35,"id":40296819}]}]}
{"op":"mcm","clk":"11843397615","pt":1723579905595,"mc":[{"id":"1.231732748","rc":[{"batb":[[0,1.76,10],[1,1.75,6.85],[2,1.74,17.32]],"ltp":1.76,"tv":25.99,"id":40296818}]}]}
{"op":"mcm","clk":"11843397854","pt":1723579907314,"mc":[{"id":"1.231732748","rc":[{"batb":[[0,1.81,6.9],[1,1.8,444],[2,1.74,17.32]],"ltp":1.82,"tv":32.35,"id":40296819}]}]}
{"op":"mcm","clk":"11843398211","pt":1723579909719,"mc":[{"id":"1.231732748","rc":[{"batb":[[0,1.75,6.85],[1,1.74,17.32],[2,1.25,100]],"ltp":1.76,"tv":25.99,"id":40296818},{"batb":[[0,1.82,10],[1,1.81,6.9],[2,1.8,444]],"ltp":1.82,"tv":32.35,"id":40296819}]}]}
{"op":"mcm","clk":"11843398439","pt":1723579911389,"mc":[{"id":"1.231732748","rc":[{"batb":[[0,1.76,10],[1,1.75,6.85],[2,1.74,17.32]],"ltp":1.76,"tv":25.99,"id":40296818}]}]}
{"op":"mcm","clk":"11843398676","pt":1723579913314,"mc":[{"id":"1.231732748","rc":[{"batb":[[0,1.81,6.9],[1,1.8,444],[2,1.74,17.32]],"ltp":1.82,"tv":32.35,"id":40296819}]}]}
{"op":"mcm","clk":"11843398878","pt":1723579914822,"mc":[{"id":"1.231732748","rc":[{"batb":[[0,1.75,6.85],[1,1.74,17.32],[2,1.25,100]],"ltp":1.76,"tv":25.99,"id":40296818}]}]}
{"op":"mcm","clk":"11843399258","pt":1723579917205,"mc":[{"id":"1.231732748","rc":[{"batb":[[0,1.76,10],[1,1.75,6.85],[2,1.74,17.32]],"ltp":1.76,"tv":25.99,"id":40296818},{"batb":[[0,1.82,10],[1,1.81,6.9],[2,1.8,444]],"ltp":1.82,"tv":32.35,"id":40296819}]}]}
{"op":"mcm","clk":"11843399655","pt":1723579920572,"mc":[{"id":"1.231732748","rc":[{"batb":[[0,1.75,6.85],[1,1.74,17.32],[2,1.25,100]],"ltp":1.76,"tv":25.99,"id":40296818},{"batb":[[0,1.81,6.9],[1,1.8,444],[2,1.74,17.32]],"ltp":1.82,"tv":32.35,"id":40296819}]}]}
{"op":"mcm","clk":"11843400090","pt":1723579923570,"mc":[{"id":"1.231732748","rc":[{"batb":[[0,1.76,10],[1,1.75,6.85],[2,1.74,17.32]],"ltp":1.76,"tv":25.99,"id":40296818},{"batb":[[0,1.82,10],[1,1.81,6.9],[2,1.8,444]],"ltp":1.82,"tv":32.35,"id":40296819}]}]}
{"op":"mcm","clk":"11843400587","pt":1723579927168,"mc":[{"id":"1.231732748","rc":[{"batb":[[0,1.75,6.85],[1,1.74,17.32],[2,1.25,100]],"ltp":1.76,"tv":25.99,"id":40296818},{"batb":[[0,1.81,6.9],[1,1.8,444],[2,1.74,17.32]],"ltp":1.82,"tv":32.35,"id":40296819}]}]}
{"op":"mcm","clk":"11843400930","pt":1723579929679,"mc":[{"id":"1.231732748","rc":[{"batb":[[0,1.76,10],[1,1.75,6.85],[2,1.74,17.32]],"ltp":1.76,"tv":25.99,"id":40296818},{"batb":[[0,1.82,10],[1,1.81,6.9],[2,1.8,444]],"ltp":1.82,"tv":32.35,"id":40296819}]}]}
{"op":"mcm","clk":"11843401475","pt":1723579933505,"mc":[{"id":"1.231732748","rc":[{"batb":[[0,1.75,6.85],[1,1.74,17.32],[2,1.25,100]],"ltp":1.76,"tv":25.99,"id":40296818},{"batb":[[0,1.81,6.9],[1,1.8,444],[2,1.74,17.32]],"ltp":1.82,"tv":32.35,"id":40296819}]}]}
{"op":"mcm","clk":"11843401858","pt":1723579936197,"mc":[{"id":"1.231732748","rc":[{"batb":[[0,1.76,10],[1,1.75,6.85],[2,1.74,17.32]],"ltp":1.76,"tv":25.99,"id":40296818},{"batb":[[0,1.82,10],[1,1.81,6.9],[2,1.8,444]],"ltp":1.82,"tv":32.35,"id":40296819}]}]}
{"op":"mcm","clk":"11843402368","pt":1723579939996,"mc":[{"id":"1.231732748","rc":[{"batb":[[0,1.75,6.85],[1,1.74,17.32],[2,1.25,100]],"ltp":1.76,"tv":25.99,"id":40296818},{"batb":[[0,1.81,6.9],[1,1.8,444],[2,1.74,17.32]],"ltp":1.82,"tv":32.35,"id":40296819}]}]}
{"op":"mcm","clk":"11843402699","pt":1723579942474,"mc":[{"id":"1.231732748","rc":[{"batb":[[0,1.76,10],[1,1.75,6.85],[2,1.74,17.32]],"ltp":1.76,"tv":25.99,"id":40296818},{"batb":[[0,1.82,10],[1,1.81,6.9],[2,1.8,444]],"ltp":1.82,"tv":32.35,"id":40296819}]}]}
{"op":"mcm","clk":"11843403253","pt":1723579946279,"mc":[{"id":"1.231732748","rc":[{"batb":[[0,1.75,6.85],[1,1.74,17.32],[2,1.25,100]],"ltp":1.76,"tv":25.99,"id":40296818},{"batb":[[0,1.81,6.9],[1,1.8,444],[2,1.74,17.32]],"ltp":1.82,"tv":32.35,"id":40296819}]}]}
{"op":"mcm","clk":"11843403743","pt":1723579949830,"mc":[{"id":"1.231732748","rc":[{"batb":[[0,1.76,10],[1,1.75,6.85],[2,1.74,17.32]],"ltp":1.76,"tv":25.99,"id":40296818},{"batb":[[0,1.82,10],[1,1.81,6.9],[2,1.8,444]],"ltp":1.82,"tv":32.35,"id":40296819}]}]}
{"op":"mcm","clk":"11843404364","pt":1723579954127,"mc":[{"id":"1.231732748","rc":[{"batb":[[0,1.75,6.85],[1,1.74,17.32],[2,1.25,100]],"ltp":1.76,"tv":25.99,"id":40296818},{"batb":[[0,1.81,6.9],[1,1.8,444],[2,1.74,17.32]],"ltp":1.82,"tv":32.35,"id":40296819}]}]}
{"op":"mcm","clk":"11843404717","pt":1723579956496,"mc":[{"id":"1.231732748","rc":[{"batb":[[0,1.76,10],[1,1.75,6.85],[2,1.74,17.32]],"ltp":1.76,"tv":25.99,"id":40296818},{"batb":[[0,1.82,10],[1,1.81,6.9],[2,1.8,444]],"ltp":1.82,"tv":32.35,"id":40296819}]}]}
{"op":"mcm","clk":"11843405221","pt":1723579960084,"mc":[{"id":"1.231732748","rc":[{"batb":[[0,1.75,6.85],[1,1.74,17.32],[2,1.25,100]],"ltp":1.76,"tv":25.99,"id":40296818},{"batb":[[0,1.81,6.9],[1,1.8,444],[2,1.74,17.32]],"ltp":1.82,"tv":32.35,"id":40296819}]}]}
