{"op":"mcm","clk":"11836462140","pt":1723454840826,"mc":[{"id":"1.231730206","marketDefinition":{"bspMarket":false,"turnInPlayEnabled":true,"persistenceEnabled":true,"marketBaseRate":5.0,"eventId":"33488374","eventTypeId":"4","numberOfWinners":1,"bettingType":"ODDS","marketType":"MATCH_ODDS","marketTime":"2024-08-14T14:00:00.000Z","suspendTime":"2024-08-14T14:00:00.000Z","bspReconciled":false,"complete":true,"inPlay":false,"crossMatching":true,"runnersVoidable":false,"numberOfActiveRunners":2,"betDelay":0,"status":"OPEN","runners":[{"status":"ACTIVE","sortPriority":1,"id":40096580,"name":"Trent Rockets Women"},{"status":"ACTIVE","sortPriority":2,"id":40096582,"name":"Oval Invincibles Women"}],"regulators":["MR_INT"],"countryCode":"GB","discountAllowed":false,"timezone":"GMT","openDate":"2024-08-14T14:00:00.000Z","version":6071648764,"name":"Match Odds","eventName":"Trent Rockets Women v Oval Invincibles Women"},"rc":[{"batb":[[0,1.03,200],[1,1.02,200],[2,1.01,220]],"ltp":0.0,"tv":0.0,"id":40096580},{"batb":[[0,1.03,200],[1,1.02,200],[2,1.01,220]],"ltp":0.0,"tv":0.0,"id":40096582}]}]}
{"op":"mcm","clk":"11836462198","pt":1723454842269,"mc":[{"id":"1.231730206","marketDefinition":{"bspMarket":false,"turnInPlayEnabled":true,"persistenceEnabled":true,"marketBaseRate":5.0,"eventId":"33488374","eventTypeId":"4","numberOfWinners":1,"bettingType":"ODDS","marketType":"MATCH_ODDS","marketTime":"2024-08-14T14:00:00.000Z","suspendTime":"2024-08-14T14:00:00.000Z","bspReconciled":false,"complete":true,"inPlay":false,"crossMatching":true,"runnersVoidable":false,"numberOfActiveRunners":2,"betDelay":0,"status":"OPEN","runners":[{"status":"ACTIVE","sortPriority":1,"id":40096580,"name":"Trent Rockets Women"},{"status":"ACTIVE","sortPriority":2,"id":40096582,"name":"Oval Invincibles Women"}],"regulators":["MR_INT"],"countryCode":"GB","discountAllowed":true,"timezone":"GMT","openDate":"2024-08-14T14:00:00.000Z","version":6071648764,"name":"Match Odds","eventName":"Trent Rockets Women v Oval Invincibles Women"}}]}
{"op":"mcm","clk":"11836580928","pt":1723458553307,"mc":[{"id":"1.231730206","rc":[{"batb":[[2,1.01,8056.99]],"ltp":0.0,"tv":0.0,"id":40096580}]}]}
{"op":"mcm","clk":"11836581254","pt":1723458562100,"mc":[{"id":"1.231730206","rc":[{"batb":[[2,1.01,8056.99]],"ltp":0.0,"tv":0.0,"id":40096582}]}]}
{"op":"mcm","clk":"11836584194","pt":1723458643022,"mc":[{"id":"1.231730206","rc":[{"batb":[[2,1.01,8317.48]],"ltp":0.0,"tv":0.0,"id":40096580},{"batb":[[2,1.01,8317.48]],"ltp":0.0,"tv":0.0,"id":40096582}]}]}
{"op":"mcm","clk":"11836730118","pt":1723462514007,"mc":[{"id":"1.231730206","rc":[{"trd":[[1.03,1.22]],"batb":[[0,1.02,200],[1,1.01,8316.74],[2,1.01,0]],"ltp":1.03,"tv":1.22,"id":40096580},{"batb":[[2,1.01,8316.74]],"ltp":0.0,"tv":0.0,"id":40096582}],"tv":1.22}]}
{"op":"mcm","clk":"11836741445","pt":1723462960136,"mc":[{"id":"1.231730206","rc":[{"batb":[[0,1.03,200],[1,1.02,200],[2,1.01,8316.74]],"ltp":1.03,"tv":1.22,"id":40096580}]}]}
{"op":"mcm","clk":"11836795654","pt":1723464774883,"mc":[{"id":"1.231730206","rc":[{"batb":[[0,1.03,199.87],[2,1.01,8312.16]],"ltp":1.03,"tv":1.22,"id":40096580},{"batb":[[2,1.01,8312.16]],"ltp":0.0,"tv":0.0,"id":40096582}]}]}
{"op":"mcm","clk":"11836842721","pt":1723466143901,"mc":[{"id":"1.231730206","rc":[{"batl":[[0,1.05,1.57]],"ltp":0.0,"tv":0.0,"id":40096582}]}]}
{"op":"mcm","clk":"11836863818","pt":1723466953584,"mc":[{"id":"1.231730206","rc":[{"batb":[[0,2.02,1.57],[1,1.03,199.87],[2,1.02,200]],"ltp":1.03,"tv":1.22,"id":40096580}]}]}
{"op":"mcm","clk":"11836864023","pt":1723466960310,"mc":[{"id":"1.231730206","rc":[{"batb":[[0,1.03,199.87],[1,1.02,200],[2,1.01,8312.16]],"ltp":1.03,"tv":1.22,"id":40096580}]}]}
{"op":"mcm","clk":"11836866235","pt":1723467038406,"mc":[{"id":"1.231730206","rc":[{"batl":[[0,1.07,1.57]],"ltp":1.03,"tv":1.22,"id":40096580}]}]}
{"op":"mcm","clk":"11836866412","pt":1723467043910,"mc":[{"id":"1.231730206","rc":[{"trd":[[1.07,0.6]],"batl":[[0,1.07,1.27]],"ltp":1.07,"tv":1.82,"id":40096580}],"tv":1.82}]}
{"op":"mcm","clk":"11836866576","pt":1723467048335,"mc":[{"id":"1.231730206","rc":[{"trd":[[1.07,1.2]],"batl":[[0,1.07,0.97]],"ltp":1.07,"tv":2.41,"id":40096580}],"tv":2.41}]}
{"op":"mcm","clk":"11836866696","pt":1723467051582,"mc":[{"id":"1.231730206","rc":[{"trd":[[1.07,1.79]],"batl":[[0,1.07,0.67]],"ltp":1.07,"tv":3.01,"id":40096580}],"tv":3.01}]}
{"op":"mcm","clk":"11836867660","pt":1723467077042,"mc":[{"id":"1.231730206","rc":[{"batb":[[0,1.25,100],[1,1.03,199.87],[2,1.02,200]],"ltp":1.07,"tv":3.01,"id":40096580},{"batb":[[0,1.25,100],[1,1.03,200],[2,1.02,200]],"ltp":0.0,"tv":0.0,"id":40096582}]}]}
{"op":"mcm","clk":"11836867866","pt":1723467083614,"mc":[{"id":"1.231730206","rc":[{"trd":[[1.25,0.6]],"batb":[[0,1.25,99.7]],"ltp":1.25,"tv":3.61,"id":40096580}],"tv":3.61}]}
{"op":"mcm","clk":"11836867936","pt":1723467086530,"mc":[{"id":"1.231730206","rc":[{"trd":[[1.25,1.2]],"batb":[[0,1.25,99.4]],"ltp":1.25,"tv":4.21,"id":40096580}],"tv":4.21}]}
{"op":"mcm","clk":"11836868659","pt":1723467110351,"mc":[{"id":"1.231730206","rc":[{"batb":[[0,1.25,100.17]],"ltp":1.25,"tv":4.21,"id":40096580}]}]}
{"op":"mcm","clk":"11836868729","pt":1723467112962,"mc":[{"id":"1.231730206","rc":[{"batb":[[0,1.25,99.4]],"ltp":1.25,"tv":4.21,"id":40096580}]}]}
{"op":"mcm","clk":"11836868829","pt":1723467116191,"mc":[{"id":"1.231730206","rc":[{"batb":[[0,1.25,100.17]],"ltp":1.25,"tv":4.21,"id":40096580}]}]}
{"op":"mcm","clk":"11836868906","pt":1723467118188,"mc":[{"id":"1.231730206","rc":[{"batb":[[0,1.25,99.4]],"ltp":1.25,"tv":4.21,"id":40096580}]}]}
{"op":"mcm","clk":"11836870815","pt":1723467180423,"mc":[{"id":"1.231730206","rc":[{"batb":[[0,1.26,33.07],[1,1.25,99.4],[2,1.03,199.87]],"ltp":1.25,"tv":4.21,"id":40096580},{"batb":[[0,1.26,33.07],[1,1.25,100],[2,1.03,200]],"ltp":0.0,"tv":0.0,"id":40096582}]}]}
{"op":"mcm","clk":"11836871899","pt":1723467216542,"mc":[{"id":"1.231730206","rc":[{"trd":[[1.26,0.3]],"batb":[[0,1.26,32.92]],"ltp":1.26,"tv":4.51,"id":40096580}],"tv":4.51}]}
{"op":"mcm","clk":"11836906459","pt":1723468529997,"mc":[{"id":"1.231730206","rc":[{"batb":[[0,1.27,7.25],[1,1.26,32.92],[2,1.25,99.4]],"ltp":1.26,"tv":4.51,"id":40096580},{"batb":[[0,1.26,33.07]],"ltp":0.0,"tv":0.0,"id":40096582}]}]}
{"op":"mcm","clk":"11836906470","pt":1723468530308,"mc":[{"id":"1.231730206","rc":[{"batb":[[0,1.27,6.73],[1,1.26,33.07],[2,1.25,100]],"ltp":0.0,"tv":0.0,"id":40096582}]}]}
{"op":"mcm","clk":"11836921521","pt":1723468981005,"mc":[{"id":"1.231730206","rc":[{"batb":[[1,1.25,99.4],[2,1.03,200.01]],"ltp":1.26,"tv":4.51,"id":40096580},{"batb":[[1,1.25,100],[2,1.03,200]],"ltp":0.0,"tv":0.0,"id":40096582}]}]}
{"op":"mcm","clk":"11836921583","pt":1723468983193,"mc":[{"id":"1.231730206","rc":[{"batb":[[0,1.28,30.71],[1,1.27,6.73],[2,1.25,100]],"ltp":0.0,"tv":0.0,"id":40096582}]}]}
{"op":"mcm","clk":"11836934074","pt":1723469363155,"mc":[{"id":"1.231730206","rc":[{"batb":[[0,1.28,3.64],[1,1.27,7.25],[2,1.25,99.4]],"ltp":1.26,"tv":4.51,"id":40096580}]}]}
{"op":"mcm","clk":"11836934576","pt":1723469374151,"mc":[{"id":"1.231730206","rc":[{"batb":[[0,1.29,3.64],[1,1.28,30.71],[2,1.27,6.73]],"ltp":0.0,"tv":0.0,"id":40096582}]}]}
{"op":"mcm","clk":"11836940029","pt":1723469530814,"mc":[{"id":"1.231730206","rc":[{"batb":[[0,1.29,5],[1,1.28,3.64],[2,1.27,7.25]],"ltp":1.26,"tv":4.51,"id":40096580},{"batb":[[0,1.3,5],[1,1.29,3.64],[2,1.28,30.71]],"ltp":0.0,"tv":0.0,"id":40096582}]}]}
{"op":"mcm","clk":"11836968997","pt":1723470218164,"mc":[{"id":"1.231730206","rc":[{"batb":[[2,1.26,7.25]],"ltp":1.26,"tv":4.51,"id":40096580},{"batb":[[1,1.29,10.37]],"ltp":0.0,"tv":0.0,"id":40096582}]}]}
{"op":"mcm","clk":"11836971679","pt":1723470297486,"mc":[{"id":"1.231730206","rc":[{"trd":[[1.3,0.14]],"batb":[[0,1.3,4.93]],"ltp":1.3,"tv":0.14,"id":40096582}],"tv":4.65}]}
{"op":"mcm","clk":"11836985349","pt":1723470783566,"mc":[{"id":"1.231730206","rc":[{"batb":[[2,1.25,100]],"ltp":1.3,"tv":0.14,"id":40096582}]}]}
{"op":"mcm","clk":"11836987014","pt":1723470854611,"mc":[{"id":"1.231730206","rc":[{"batb":[[0,1.31,27.74],[1,1.3,4.93],[2,1.29,10.37]],"ltp":1.3,"tv":0.14,"id":40096582}]}]}
{"op":"mcm","clk":"11837027041","pt":1723471909022,"mc":[{"id":"1.231730206","rc":[{"batb":[[2,1.25,99.4]],"ltp":1.26,"tv":4.51,"id":40096580},{"batb":[[0,1.31,27.74],[2,1.29,10.37]],"ltp":1.3,"tv":0.14,"id":40096582}]}]}
{"op":"mcm","clk":"11837027058","pt":1723471909381,"mc":[{"id":"1.231730206","rc":[{"batb":[[0,1.32,6.73],[1,1.31,27.74],[2,1.3,4.93]],"ltp":1.3,"tv":0.14,"id":40096582}]}]}
{"op":"mcm","clk":"11837048175","pt":1723472524403,"mc":[{"id":"1.231730206","rc":[{"batb":[[0,1.3,3.64],[1,1.29,5]],"ltp":1.26,"tv":4.51,"id":40096580}]}]}
{"op":"mcm","clk":"11837048460","pt":1723472534346,"mc":[{"id":"1.231730206","rc":[{"batb":[[0,1.33,3.64],[1,1.32,6.73],[2,1.31,27.74]],"ltp":1.3,"tv":0.14,"id":40096582}]}]}
{"op":"mcm","clk":"11837052277","pt":1723472655256,"mc":[{"id":"1.231730206","rc":[{"batb":[[2,1.3,4.93]],"ltp":1.3,"tv":0.14,"id":40096582}]}]}
{"op":"mcm","clk":"11837053577","pt":1723472698373,"mc":[{"id":"1.231730206","rc":[{"trd":[[1.3,0.14]],"batb":[[0,1.3,3.57]],"ltp":1.3,"tv":4.65,"id":40096580}],"tv":4.79}]}
{"op":"mcm","clk":"11837054375","pt":1723472724377,"mc":[{"id":"1.231730206","rc":[{"batb":[[0,1.34,25.29],[1,1.33,3.64],[2,1.32,6.73]],"ltp":1.3,"tv":0.14,"id":40096582}]}]}
{"op":"mcm","clk":"11837083401","pt":1723473567718,"mc":[{"id":"1.231730206","rc":[{"batb":[[0,1.35,6.73],[1,1.34,25.29],[2,1.33,3.64]],"ltp":1.3,"tv":0.14,"id":40096582}]}]}
{"op":"mcm","clk":"11837095041","pt":1723473898511,"mc":[{"id":"1.231730206","rc":[{"trd":[[1.3,0.28]],"batb":[[0,1.3,3.5]],"ltp":1.3,"tv":4.79,"id":40096580}],"tv":4.93}]}
{"op":"mcm","clk":"11837118132","pt":1723474524865,"mc":[{"id":"1.231730206","rc":[{"batb":[[1,1.33,3.64],[2,1.3,4.93]],"ltp":1.3,"tv":0.14,"id":40096582}]}]}
{"op":"mcm","clk":"11837120268","pt":1723474585042,"mc":[{"id":"1.231730206","rc":[{"batb":[[0,1.36,23.89],[1,1.35,6.73],[2,1.33,3.64]],"ltp":1.3,"tv":0.14,"id":40096582}]}]}
{"op":"mcm","clk":"11837147047","pt":1723475259203,"mc":[{"id":"1.231730206","rc":[{"trd":[[1.07,1.79]],"batb":[[0,1.3,3.5]],"ltp":1.3,"tv":4.79,"id":40096580},{"batb":[[0,1.36,23.87],[1,1.33,3.64],[2,1.3,4.93]],"ltp":1.3,"tv":0.14,"id":40096582}],"tv":4.93}]}
{"op":"mcm","clk":"11837200029","pt":1723476385395,"mc":[{"id":"1.231730206","rc":[{"batb":[[0,1.33,3.64],[1,1.3,4.93],[2,1.26,6.72]],"ltp":1.3,"tv":0.14,"id":40096582}]}]}
{"op":"mcm","clk":"11837202878","pt":1723476445265,"mc":[{"id":"1.231730206","rc":[{"batb":[[0,1.34,25.27],[1,1.33,3.64],[2,1.3,4.93]],"ltp":1.3,"tv":0.14,"id":40096582}]}]}
{"op":"mcm","clk":"11837225659","pt":1723476976890,"mc":[{"id":"1.231730206","rc":[{"batb":[[0,1.35,6.72],[1,1.34,25.27],[2,1.33,3.64]],"ltp":1.3,"tv":0.14,"id":40096582}]}]}
{"op":"mcm","clk":"11837247645","pt":1723477497752,"mc":[{"id":"1.231730206","rc":[{"trd":[[1.3,0.42]],"batb":[[0,1.3,3.43]],"ltp":1.3,"tv":4.93,"id":40096580}],"tv":5.07}]}
{"op":"mcm","clk":"11837281856","pt":1723478245541,"mc":[{"id":"1.231730206","rc":[{"batb":[[1,1.33,3.64],[2,1.3,4.93]],"ltp":1.3,"tv":0.14,"id":40096582}]}]}
{"op":"mcm","clk":"11837284331","pt":1723478292017,"mc":[{"id":"1.231730206","rc":[{"batb":[[0,1.36,23.87],[1,1.35,6.72],[2,1.33,3.64]],"ltp":1.3,"tv":0.14,"id":40096582}]}]}
{"op":"mcm","clk":"11837304261","pt":1723478660666,"mc":[{"id":"1.231730206","rc":[{"batb":[[0,1.3,3.43]],"ltp":1.3,"tv":4.93,"id":40096580},{"batb":[[0,1.36,23.88],[1,1.33,3.64],[2,1.3,4.93]],"ltp":1.3,"tv":0.14,"id":40096582}],"tv":5.07}]}
{"op":"mcm","clk":"11837379439","pt":1723480092418,"mc":[{"id":"1.231730206","rc":[{"batb":[[0,1.33,3.64],[1,1.3,4.93],[2,1.26,6.73]],"ltp":1.3,"tv":0.14,"id":40096582}]}]}
{"op":"mcm","clk":"11837381047","pt":1723480123081,"mc":[{"id":"1.231730206","rc":[{"batb":[[0,1.34,25.29],[1,1.33,3.64],[2,1.3,4.93]],"ltp":1.3,"tv":0.14,"id":40096582}]}]}
{"op":"mcm","clk":"11837389142","pt":1723480267712,"mc":[{"id":"1.231730206","rc":[{"batb":[[0,1.31,5],[1,1.3,3.43]],"ltp":1.3,"tv":4.93,"id":40096580},{"batb":[[0,1.35,4.93],[1,1.34,25.29],[2,1.33,3.64]],"ltp":1.3,"tv":0.14,"id":40096582}]}]}
{"op":"mcm","clk":"11837392969","pt":1723480332863,"mc":[{"id":"1.231730206","rc":[{"batb":[[0,1.35,11.66]],"ltp":1.3,"tv":0.14,"id":40096582}]}]}
{"op":"mcm","clk":"11837421988","pt":1723480934420,"mc":[{"id":"1.231730206","rc":[{"batb":[[0,1.72,975.08],[1,1.31,5],[2,1.3,3.43]],"ltp":1.3,"tv":4.93,"id":40096580}]}]}
{"op":"mcm","clk":"11837422902","pt":1723480961006,"mc":[{"id":"1.231730206","rc":[{"batb":[[0,1.43,975.08],[1,1.35,11.66],[2,1.34,25.29]],"ltp":1.3,"tv":0.14,"id":40096582}]}]}
{"op":"mcm","clk":"11837456162","pt":1723481677384,"mc":[{"id":"1.231730206","rc":[{"batb":[[0,1.73,17.33],[1,1.72,975.08],[2,1.31,5]],"ltp":1.3,"tv":4.93,"id":40096580},{"batl":[[0,2.38,17.33]],"ltp":1.3,"tv":0.14,"id":40096582}]}]}
{"op":"mcm","clk":"11837457010","pt":1723481696314,"mc":[{"id":"1.231730206","rc":[{"batl":[[0,3.3,17.22]],"ltp":1.3,"tv":4.93,"id":40096580},{"batb":[[0,1.44,17.22],[1,1.43,975.08],[2,1.35,11.66]],"ltp":1.3,"tv":0.14,"id":40096582}]}]}
{"op":"mcm","clk":"11837467384","pt":1723481937983,"mc":[{"id":"1.231730206","rc":[{"batb":[[0,1.45,19.11],[1,1.44,17.22],[2,1.43,975.08]],"ltp":1.3,"tv":0.14,"id":40096582}]}]}
{"op":"mcm","clk":"11837467414","pt":1723481938603,"mc":[{"id":"1.231730206","rc":[{"batb":[[1,1.43,975.08],[2,1.35,11.66]],"ltp":1.3,"tv":0.14,"id":40096582}]}]}
{"op":"mcm","clk":"11837469811","pt":1723481989751,"mc":[{"id":"1.231730206","rc":[{"batb":[[0,1.73,23.31]],"ltp":1.3,"tv":4.93,"id":40096580},{"batb":[[1,1.44,6.73],[2,1.43,975.08]],"ltp":1.3,"tv":0.14,"id":40096582}]}]}
{"op":"mcm","clk":"11837490312","pt":1723482303181,"mc":[{"id":"1.231730206","rc":[{"batb":[[0,1.73,23.33]],"batl":[[0,3.3,17.23]],"ltp":1.3,"tv":4.93,"id":40096580},{"batb":[[0,1.45,19.12],[1,1.44,6.73]],"batl":[[0,2.38,17.34]],"ltp":1.3,"tv":0.14,"id":40096582}],"tv":5.07}]}
{"op":"mcm","clk":"11837576900","pt":1723483445946,"mc":[{"id":"1.231730206","rc":[{"batb":[[0,1.74,5],[1,1.73,23.33],[2,1.72,975.08]],"ltp":1.3,"tv":4.93,"id":40096580},{"batb":[[0,1.46,4.93],[1,1.45,19.12],[2,1.44,6.73]],"ltp":1.3,"tv":0.14,"id":40096582}]}]}
{"op":"mcm","clk":"11837599563","pt":1723483738907,"mc":[{"id":"1.231730206","rc":[{"batb":[[1,1.44,24.04],[2,1.43,975.08]],"ltp":1.3,"tv":0.14,"id":40096582}]}]}
{"op":"mcm","clk":"11837606344","pt":1723483819580,"mc":[{"id":"1.231730206","rc":[{"batb":[[0,3.1,1.57],[1,1.74,5],[2,1.73,23.33]],"ltp":1.3,"tv":4.93,"id":40096580}]}]}
{"op":"mcm","clk":"11837607712","pt":1723483833910,"mc":[{"id":"1.231730206","rc":[{"batb":[[0,1.74,5],[1,1.73,23.33],[2,1.72,975.08]],"ltp":1.3,"tv":4.93,"id":40096580}]}]}
{"op":"mcm","clk":"11837610288","pt":1723483863149,"mc":[{"id":"1.231730206","rc":[{"batb":[[0,1.47,18.31],[1,1.46,4.93],[2,1.44,24.04]],"ltp":1.3,"tv":0.14,"id":40096582}]}]}
{"op":"mcm","clk":"11837610344","pt":1723483863739,"mc":[{"id":"1.231730206","rc":[{"batb":[[2,1.44,6.73]],"ltp":1.3,"tv":0.14,"id":40096582}]}]}
{"op":"mcm","clk":"11837618204","pt":1723483960462,"mc":[{"id":"1.231730206","rc":[{"batb":[[0,1.78,444],[1,1.74,5],[2,1.73,23.33]],"ltp":1.3,"tv":4.93,"id":40096580}]}]}
{"op":"mcm","clk":"11837618361","pt":1723483962194,"mc":[{"id":"1.231730206","rc":[{"batb":[[2,1.73,6]],"ltp":1.3,"tv":4.93,"id":40096580}]}]}
{"op":"mcm","clk":"11837628887","pt":1723484093051,"mc":[{"id":"1.231730206","rc":[{"batb":[[0,3.1,1.57],[1,1.78,444],[2,1.74,5]],"ltp":1.3,"tv":4.93,"id":40096580}]}]}
{"op":"mcm","clk":"11837630057","pt":1723484106669,"mc":[{"id":"1.231730206","rc":[{"batb":[[0,1.78,444],[1,1.74,5],[2,1.73,6]],"ltp":1.3,"tv":4.93,"id":40096580}]}]}
{"op":"mcm","clk":"11837636226","pt":1723484181661,"mc":[{"id":"1.231730206","rc":[{"batb":[[0,3,1.57],[1,1.78,444],[2,1.74,5]],"ltp":1.3,"tv":4.93,"id":40096580}]}]}
{"op":"mcm","clk":"11837637279","pt":1723484195384,"mc":[{"id":"1.231730206","rc":[{"batb":[[0,1.78,444],[1,1.74,5],[2,1.73,6]],"ltp":1.3,"tv":4.93,"id":40096580}]}]}
{"op":"mcm","clk":"11837653858","pt":1723484395195,"mc":[{"id":"1.231730206","rc":[{"batl":[[0,2.1,1.57]],"ltp":1.3,"tv":4.93,"id":40096580}]}]}
{"op":"mcm","clk":"11837656789","pt":1723484429170,"mc":[{"id":"1.231730206","rc":[{"batl":[[1,2.2,1.57]],"ltp":1.3,"tv":4.93,"id":40096580}]}]}
{"op":"mcm","clk":"11837658156","pt":1723484445395,"mc":[{"id":"1.231730206","rc":[{"batl":[[2,2.3,1.72]],"ltp":1.3,"tv":4.93,"id":40096580}]}]}
{"op":"mcm","clk":"11837661600","pt":1723484488224,"mc":[{"id":"1.231730206","rc":[{"batb":[[0,1.91,666],[1,1.47,18.31],[2,1.46,4.93]],"ltp":1.3,"tv":0.14,"id":40096582}]}]}
{"op":"mcm","clk":"11837662383","pt":1723484498063,"mc":[{"id":"1.231730206","rc":[{"batl":[[1,2.2,0],[2,2.3,0]],"ltp":1.3,"tv":4.93,"id":40096580}]}]}
{"op":"mcm","clk":"11837679581","pt":1723484695800,"mc":[{"id":"1.231730206","rc":[{"batb":[[0,1.79,17.47],[1,1.78,444],[2,1.74,5]],"ltp":1.3,"tv":4.93,"id":40096580},{"batl":[[0,2.28,16.88]],"ltp":1.3,"tv":0.14,"id":40096582}]}]}
{"op":"mcm","clk":"11837715995","pt":1723485220154,"mc":[{"id":"1.231730206","rc":[{"batb":[[0,1.92,16.97],[1,1.91,666],[2,1.47,18.31]],"ltp":1.3,"tv":0.14,"id":40096582}]}]}
{"op":"mcm","clk":"11837717129","pt":1723485240240,"mc":[{"id":"1.231730206","rc":[{"batb":[[0,1.79,23.46]],"ltp":1.3,"tv":4.93,"id":40096580},{"batb":[[0,1.92,23.7]],"ltp":1.3,"tv":0.14,"id":40096582}]}]}
{"op":"mcm","clk":"11837717148","pt":1723485240649,"mc":[{"id":"1.231730206","rc":[{"batl":[[0,2.08,16.83]],"ltp":1.3,"tv":4.93,"id":40096580}]}]}
{"op":"mcm","clk":"11837741801","pt":1723485609763,"mc":[{"id":"1.231730206","rc":[{"batb":[[0,1.8,112.15],[1,1.79,23.46],[2,1.78,444]],"batl":[[0,2.08,16.84]],"ltp":1.3,"tv":4.93,"id":40096580},{"batb":[[0,1.92,23.7],[2,1.47,18.31]],"batl":[[0,2.28,16.88]],"ltp":1.3,"tv":0.14,"id":40096582}]}]}
{"op":"mcm","clk":"11837741903","pt":1723485611278,"mc":[{"id":"1.231730206","rc":[{"batb":[[1,1.79,5.99]],"ltp":1.3,"tv":4.93,"id":40096580}]}]}
{"op":"mcm","clk":"11837745917","pt":1723485663306,"mc":[{"id":"1.231730206","rc":[{"batb":[[2,1.46,4.93]],"ltp":1.3,"tv":0.14,"id":40096582}]}]}
{"op":"mcm","clk":"11837758274","pt":1723485812483,"mc":[{"id":"1.231730206","rc":[{"batb":[[2,1.79,49.04]],"ltp":1.3,"tv":0.14,"id":40096582}]}]}
{"op":"mcm","clk":"11837802963","pt":1723486332589,"mc":[{"id":"1.231730206","rc":[{"batb":[[0,1.81,5.51],[1,1.8,112.15],[2,1.79,5.99]],"ltp":1.3,"tv":4.93,"id":40096580},{"batl":[[0,2.24,4.39]],"ltp":1.3,"tv":0.14,"id":40096582}]}]}
{"op":"mcm","clk":"11837816517","pt":1723486405199,"mc":[{"id":"1.231730206","rc":[{"batb":[[0,1.9,84.79],[1,1.81,5.51],[2,1.8,112.15]],"ltp":1.3,"tv":4.93,"id":40096580}]}]}
{"op":"mcm","clk":"11837816547","pt":1723486405494,"mc":[{"id":"1.231730206","rc":[{"batb":[[0,1.9,173.31],[1,1.79,5.99],[2,1.78,444]],"ltp":1.3,"tv":4.93,"id":40096580}]}]}
{"op":"mcm","clk":"11837817931","pt":1723486420014,"mc":[{"id":"1.231730206","rc":[{"batb":[[0,1.91,84.79],[1,1.9,173.31],[2,1.79,5.99]],"ltp":1.3,"tv":4.93,"id":40096580}]}]}
{"op":"mcm","clk":"11837828387","pt":1723486529638,"mc":[{"id":"1.231730206","rc":[{"batb":[[0,1.92,64.49],[1,1.91,84.79],[2,1.9,84.79]],"ltp":1.3,"tv":4.93,"id":40096580}]}]}
{"op":"mcm","clk":"11837830076","pt":1723486546061,"mc":[{"id":"1.231730206","rc":[{"batb":[[1,1.79,5.99],[2,1.78,444]],"ltp":1.3,"tv":4.93,"id":40096580}]}]}
{"op":"mcm","clk":"11837830787","pt":1723486553077,"mc":[{"id":"1.231730206","rc":[{"batb":[[0,1.95,84.79],[1,1.92,64.49],[2,1.79,5.99]],"ltp":1.3,"tv":4.93,"id":40096580}]}]}
{"op":"mcm","clk":"11837835939","pt":1723486604155,"mc":[{"id":"1.231730206","rc":[{"trd":[[2.08,0.08]],"batb":[[1,1.79,5.99],[2,1.78,444]],"batl":[[0,2.08,16.8]],"ltp":2.08,"tv":5.02,"id":40096580}],"tv":5.16}]}
{"op":"mcm","clk":"11837835950","pt":1723486604262,"mc":[{"id":"1.231730206","rc":[{"batb":[[0,1.95,108.71]],"ltp":2.08,"tv":5.02,"id":40096580}]}]}
{"op":"mcm","clk":"11837836564","pt":1723486611130,"mc":[{"id":"1.231730206","rc":[{"batl":[[0,2.06,84.79]],"ltp":2.08,"tv":5.02,"id":40096580},{"batb":[[0,1.92,6.73]],"ltp":1.3,"tv":0.14,"id":40096582}]}]}
{"op":"mcm","clk":"11837837320","pt":1723486619310,"mc":[{"id":"1.231730206","rc":[{"batb":[[0,1.95,23.92]],"ltp":2.08,"tv":5.02,"id":40096580}]}]}
{"op":"mcm","clk":"11837847022","pt":1723486714386,"mc":[{"id":"1.231730206","rc":[{"batl":[[0,2.06,341.73]],"ltp":2.08,"tv":5.02,"id":40096580}]}]}
{"op":"mcm","clk":"11837850813","pt":1723486750728,"mc":[{"id":"1.231730206","rc":[{"trd":[[2.1,33.4]],"ltp":2.1,"tv":38.42,"id":40096580},{"trd":[[1.91,29.96],[1.92,6.73]],"batb":[[0,1.91,636.04],[1,1.79,49.04],[2,1.43,975.08]],"ltp":1.91,"tv":36.82,"id":40096582}],"tv":75.24}]}
{"op":"mcm","clk":"11837851298","pt":1723486755710,"mc":[{"id":"1.231730206","rc":[{"trd":[[2.1,66.8]],"ltp":2.1,"tv":71.82,"id":40096580},{"trd":[[1.91,66.68]],"batb":[[0,1.91,599.32]],"ltp":1.91,"tv":73.54,"id":40096582}],"tv":145.36}]}
{"op":"mcm","clk":"11837856371","pt":1723486808711,"mc":[{"id":"1.231730206","rc":[{"trd":[[1.91,1265.32]],"batb":[[0,1.79,49.04],[1,1.43,975.08],[2,1.25,100]],"batl":[[0,1.91,0.2]],"ltp":1.91,"tv":1272.19,"id":40096582}],"tv":1344.01}]}
{"op":"mcm","clk":"11837858202","pt":1723486827208,"mc":[{"id":"1.231730206","rc":[{"batb":[[1,1.78,444],[2,1.72,975.08]],"ltp":2.1,"tv":71.82,"id":40096580}]}]}
{"op":"mcm","clk":"11837858215","pt":1723486827309,"mc":[{"id":"1.231730206","rc":[{"batb":[[0,1.96,5.99],[1,1.95,23.92],[2,1.78,444]],"ltp":2.1,"tv":71.82,"id":40096580}]}]}
{"op":"mcm","clk":"11837862816","pt":1723486872775,"mc":[{"id":"1.231730206","rc":[{"batb":[[1,1.78,444],[2,1.72,975.08]],"ltp":2.1,"tv":71.82,"id":40096580},{"batb":[[0,1.85,555],[1,1.79,49.04],[2,1.43,975.08]],"ltp":1.91,"tv":1272.19,"id":40096582}]}]}
{"op":"mcm","clk":"11837869005","pt":1723486936931,"mc":[{"id":"1.231730206","rc":[{"batb":[[0,1.8,555]],"ltp":1.91,"tv":1272.19,"id":40096582}]}]}
{"op":"mcm","clk":"11837870198","pt":1723486948975,"mc":[{"id":"1.231730206","rc":[{"batb":[[1,1.79,493.04]],"ltp":1.91,"tv":1272.19,"id":40096582}]}]}
{"op":"mcm","clk":"11837872433","pt":1723486972872,"mc":[{"id":"1.231730206","rc":[{"batb":[[0,2,560.98],[1,1.96,5.99],[2,1.78,444]],"ltp":2.1,"tv":71.82,"id":40096580}]}]}
{"op":"mcm","clk":"11837875455","pt":1723487003364,"mc":[{"id":"1.231730206","rc":[{"batl":[[0,1.99,500]],"ltp":1.91,"tv":1272.19,"id":40096582}]}]}
{"op":"mcm","clk":"11837880483","pt":1723487051561,"mc":[{"id":"1.231730206","rc":[{"batb":[[2,1.85,444]],"ltp":2.1,"tv":71.82,"id":40096580}]}]}
{"op":"mcm","clk":"11837887070","pt":1723487124104,"mc":[{"id":"1.231730206","rc":[{"batb":[[2,1.95,606]],"ltp":2.1,"tv":71.82,"id":40096580}]}]}
{"op":"mcm","clk":"11837894155","pt":1723487199008,"mc":[{"id":"1.231730206","rc":[{"batb":[[0,1.81,17.45],[1,1.8,555],[2,1.79,493.04]],"ltp":1.91,"tv":1272.19,"id":40096582}]}]}
{"op":"mcm","clk":"11837905713","pt":1723487316925,"mc":[{"id":"1.231730206","rc":[{"batl":[[0,1.99,16.83]],"ltp":1.91,"tv":1272.19,"id":40096582}]}]}
{"op":"mcm","clk":"11837939228","pt":1723487668312,"mc":[{"id":"1.231730206","rc":[{"batl":[[0,2.24,16.84]],"ltp":2.1,"tv":71.82,"id":40096580}]}]}
{"op":"mcm","clk":"11837940846","pt":1723487686314,"mc":[{"id":"1.231730206","rc":[{"batb":[[0,2.02,10],[1,2,560.98],[2,1.96,5.99]],"ltp":2.1,"tv":71.82,"id":40096580}]}]}
{"op":"mcm","clk":"11837941800","pt":1723487697546,"mc":[{"id":"1.231730206","rc":[{"batb":[[0,2.02,26.88]],"ltp":2.1,"tv":71.82,"id":40096580}]}]}
{"op":"mcm","clk":"11837943313","pt":1723487713584,"mc":[{"id":"1.231730206","rc":[{"batb":[[0,2.02,16.88]],"ltp":2.1,"tv":71.82,"id":40096580}]}]}
{"op":"mcm","clk":"11837943889","pt":1723487719793,"mc":[{"id":"1.231730206","rc":[{"batb":[[0,2.04,10],[1,2.02,16.88],[2,2,560.98]],"ltp":2.1,"tv":71.82,"id":40096580}]}]}
{"op":"mcm","clk":"11837944026","pt":1723487721262,"mc":[{"id":"1.231730206","rc":[{"batb":[[1,2,560.98],[2,1.96,5.99]],"ltp":2.1,"tv":71.82,"id":40096580}]}]}
{"op":"mcm","clk":"11837945826","pt":1723487739718,"mc":[{"id":"1.231730206","rc":[{"batb":[[0,2.1,560.98],[1,2.04,10]],"ltp":2.1,"tv":71.82,"id":40096580}]}]}
{"op":"mcm","clk":"11837945940","pt":1723487740834,"mc":[{"id":"1.231730206","rc":[{"batb":[[1,1.96,5.99],[2,1.95,606]],"ltp":2.1,"tv":71.82,"id":40096580}]}]}
{"op":"mcm","clk":"11837947643","pt":1723487757511,"mc":[{"id":"1.231730206","rc":[{"batb":[[1,2.06,10],[2,1.96,5.99]],"ltp":2.1,"tv":71.82,"id":40096580}]}]}
{"op":"mcm","clk":"11837949810","pt":1723487778849,"mc":[{"id":"1.231730206","rc":[{"batb":[[1,1.96,5.99],[2,1.95,606]],"ltp":2.1,"tv":71.82,"id":40096580}]}]}
{"op":"mcm","clk":"11837951464","pt":1723487796068,"mc":[{"id":"1.231730206","rc":[{"batb":[[0,2.12,10],[1,2.1,560.98],[2,1.96,5.99]],"ltp":2.1,"tv":71.82,"id":40096580}]}]}
{"op":"mcm","clk":"11837952056","pt":1723487801965,"mc":[{"id":"1.231730206","rc":[{"batl":[[0,1.9,17.13]],"ltp":1.91,"tv":1272.19,"id":40096582}]}]}
{"op":"mcm","clk":"11837953505","pt":1723487816593,"mc":[{"id":"1.231730206","rc":[{"batb":[[0,2.1,560.98],[1,1.96,5.99],[2,1.95,606]],"ltp":2.1,"tv":71.82,"id":40096580}]}]}
{"op":"mcm","clk":"11837953770","pt":1723487819061,"mc":[{"id":"1.231730206","rc":[{"batb":[[0,2.14,10],[1,2.1,560.98],[2,1.96,5.99]],"ltp":2.1,"tv":71.82,"id":40096580}]}]}
{"op":"mcm","clk":"11837955925","pt":1723487839707,"mc":[{"id":"1.231730206","rc":[{"batb":[[0,2.1,560.98],[1,1.96,5.99],[2,1.95,606]],"ltp":2.1,"tv":71.82,"id":40096580}]}]}
{"op":"mcm","clk":"11837956860","pt":1723487848907,"mc":[{"id":"1.231730206","rc":[{"batl":[[0,1.9,17.13]],"ltp":1.91,"tv":1272.19,"id":40096582}]}]}
{"op":"mcm","clk":"11837957672","pt":1723487857198,"mc":[{"id":"1.231730206","rc":[{"batb":[[0,2.12,10],[1,2.1,560.98],[2,1.96,5.99]],"ltp":2.1,"tv":71.82,"id":40096580}]}]}
{"op":"mcm","clk":"11837959778","pt":1723487877929,"mc":[{"id":"1.231730206","rc":[{"batb":[[0,2.1,560.98],[1,1.96,5.99],[2,1.95,606]],"ltp":2.1,"tv":71.82,"id":40096580}]}]}
{"op":"mcm","clk":"11837988839","pt":1723488163607,"mc":[{"id":"1.231730206","rc":[{"batb":[[0,2.12,15.57],[1,2.1,560.98],[2,1.96,5.99]],"ltp":2.1,"tv":71.82,"id":40096580}]}]}
{"op":"mcm","clk":"11838009739","pt":1723488372022,"mc":[{"id":"1.231730206","rc":[{"batb":[[0,1.82,95.07],[1,1.81,17.45],[2,1.8,555]],"ltp":1.91,"tv":1272.19,"id":40096582}]}]}
{"op":"mcm","clk":"11838009910","pt":1723488373916,"mc":[{"id":"1.231730206","rc":[{"batb":[[1,1.8,555],[2,1.79,493.04]],"ltp":1.91,"tv":1272.19,"id":40096582}]}]}
{"op":"mcm","clk":"11838011299","pt":1723488389136,"mc":[{"id":"1.231730206","rc":[{"batb":[[2,1.95,606]],"ltp":2.1,"tv":71.82,"id":40096580}]}]}
{"op":"mcm","clk":"11838012632","pt":1723488403728,"mc":[{"id":"1.231730206","rc":[{"batb":[[0,1.83,7.14],[1,1.82,95.07],[2,1.8,555]],"ltp":1.91,"tv":1272.19,"id":40096582}]}]}
{"op":"mcm","clk":"11838014152","pt":1723488420523,"mc":[{"id":"1.231730206","rc":[{"batb":[[0,1.84,95.07],[1,1.83,7.14]],"ltp":1.91,"tv":1272.19,"id":40096582}]}]}
{"op":"mcm","clk":"11838014341","pt":1723488422324,"mc":[{"id":"1.231730206","rc":[{"batb":[[1,1.8,555],[2,1.79,493.04]],"ltp":1.91,"tv":1272.19,"id":40096582}]}]}
{"op":"mcm","clk":"11838017216","pt":1723488454172,"mc":[{"id":"1.231730206","rc":[{"batb":[[0,1.85,7.14],[1,1.84,95.07],[2,1.8,555]],"ltp":1.91,"tv":1272.19,"id":40096582}]}]}
{"op":"mcm","clk":"11838018430","pt":1723488468100,"mc":[{"id":"1.231730206","rc":[{"batb":[[0,2.12,31.06]],"ltp":2.1,"tv":71.82,"id":40096580}]}]}
{"op":"mcm","clk":"11838024058","pt":1723488528169,"mc":[{"id":"1.231730206","rc":[{"batb":[[0,1.86,95.07],[1,1.85,7.14]],"ltp":1.91,"tv":1272.19,"id":40096582}]}]}
{"op":"mcm","clk":"11838024244","pt":1723488530181,"mc":[{"id":"1.231730206","rc":[{"batb":[[1,1.8,555],[2,1.79,493.04]],"ltp":1.91,"tv":1272.19,"id":40096582}]}]}
{"op":"mcm","clk":"11838024385","pt":1723488531878,"mc":[{"id":"1.231730206","rc":[{"batb":[[2,1.79,444]],"ltp":1.91,"tv":1272.19,"id":40096582}]}]}
{"op":"mcm","clk":"11838026875","pt":1723488561693,"mc":[{"id":"1.231730206","rc":[{"batb":[[0,1.87,7.14],[1,1.86,95.07],[2,1.8,555]],"ltp":1.91,"tv":1272.19,"id":40096582}]}]}
{"op":"mcm","clk":"11838027961","pt":1723488573988,"mc":[{"id":"1.231730206","rc":[{"trd":[[1.87,14.29]],"batb":[[0,1.86,95.07],[1,1.8,555],[2,1.79,444]],"batl":[[0,1.9,17.69]],"ltp":1.87,"tv":1286.47,"id":40096582}],"tv":1358.29}]}
{"op":"mcm","clk":"11838028385","pt":1723488578692,"mc":[{"id":"1.231730206","rc":[{"batl":[[0,1.9,17.13]],"ltp":1.87,"tv":1286.47,"id":40096582}]}]}
{"op":"mcm","clk":"11838028813","pt":1723488583521,"mc":[{"id":"1.231730206","rc":[{"batb":[[0,1.8,555],[1,1.79,444],[2,1.74,17.32]],"ltp":1.87,"tv":1286.47,"id":40096582}]}]}
{"op":"mcm","clk":"11838029149","pt":1723488587032,"mc":[{"id":"1.231730206","rc":[{"batb":[[1,1.79,493.04]],"ltp":1.87,"tv":1286.47,"id":40096582}]}]}
{"op":"mcm","clk":"11838047743","pt":1723488826315,"mc":[{"id":"1.231730206","rc":[{"batb":[[0,1.81,16.86],[1,1.8,555],[2,1.79,493.04]],"ltp":1.87,"tv":1286.47,"id":40096582}]}]}
{"op":"mcm","clk":"11838049594","pt":1723488854918,"mc":[{"id":"1.231730206","rc":[{"batb":[[0,1.82,65.95]],"ltp":1.87,"tv":1286.47,"id":40096582}]}]}
{"op":"mcm","clk":"11838074609","pt":1723489243449,"mc":[{"id":"1.231730206","rc":[{"batb":[[0,2.12,31.05],[1,2.1,560.64]],"ltp":2.1,"tv":71.82,"id":40096580},{"trd":[[1.87,14.28],[1.91,1264.96],[1.92,6.73]],"batb":[[0,1.8,555],[1,1.79,493.04],[2,1.74,17.32]],"batl":[[0,1.9,17.12]],"ltp":1.87,"tv":1286.1,"id":40096582}],"tv":1357.92}]}
{"op":"mcm","clk":"11838074687","pt":1723489244953,"mc":[{"id":"1.231730206","rc":[{"batl":[[0,2.24,17.12]],"ltp":2.1,"tv":71.82,"id":40096580},{"batb":[[0,1.81,17.46],[1,1.8,555],[2,1.79,493.04]],"ltp":1.87,"tv":1286.1,"id":40096582}]}]}
{"op":"mcm","clk":"11838074781","pt":1723489246518,"mc":[{"id":"1.231730206","rc":[{"batb":[[0,2.14,10],[1,2.12,31.05],[2,2.1,560.64]],"ltp":2.1,"tv":71.82,"id":40096580}]}]}
{"op":"mcm","clk":"11838075099","pt":1723489252446,"mc":[{"id":"1.231730206","rc":[{"batb":[[0,2.12,31.05],[1,2.1,560.64],[2,1.95,606]],"ltp":2.1,"tv":71.82,"id":40096580}]}]}
{"op":"mcm","clk":"11838075220","pt":1723489254831,"mc":[{"id":"1.231730206","rc":[{"batb":[[0,2.14,10],[1,2.12,31.05],[2,2.1,560.64]],"ltp":2.1,"tv":71.82,"id":40096580},{"batb":[[0,1.82,95.01],[1,1.81,17.46],[2,1.8,555]],"ltp":1.87,"tv":1286.1,"id":40096582}]}]}
{"op":"mcm","clk":"11838075296","pt":1723489255864,"mc":[{"id":"1.231730206","rc":[{"batb":[[1,1.8,555],[2,1.79,493.04]],"ltp":1.87,"tv":1286.1,"id":40096582}]}]}
{"op":"mcm","clk":"11838075519","pt":1723489259658,"mc":[{"id":"1.231730206","rc":[{"batb":[[0,2.12,31.05],[1,2.1,560.64],[2,1.95,606]],"ltp":2.1,"tv":71.82,"id":40096580}]}]}
{"op":"mcm","clk":"11838089891","pt":1723489495404,"mc":[{"id":"1.231730206","rc":[{"batb":[[0,1.83,4.66],[1,1.82,95.01],[2,1.8,555]],"ltp":1.87,"tv":1286.1,"id":40096582}]}]}
{"op":"mcm","clk":"11838098696","pt":1723489645763,"mc":[{"id":"1.231730206","rc":[{"batl":[[0,2.2,6.14]],"ltp":2.1,"tv":71.82,"id":40096580}]}]}
{"op":"mcm","clk":"11838146724","pt":1723490315068,"mc":[{"id":"1.231730206","rc":[{"batb":[[0,1.86,95.01],[1,1.83,4.66]],"ltp":1.87,"tv":1286.1,"id":40096582}]}]}
{"op":"mcm","clk":"11838146811","pt":1723490316072,"mc":[{"id":"1.231730206","rc":[{"batb":[[1,1.8,555],[2,1.79,493.04]],"ltp":1.87,"tv":1286.1,"id":40096582}]}]}
{"op":"mcm","clk":"11838146935","pt":1723490317847,"mc":[{"id":"1.231730206","rc":[{"batb":[[2,1.79,444]],"ltp":1.87,"tv":1286.1,"id":40096582}]}]}
{"op":"mcm","clk":"11838166127","pt":1723490556662,"mc":[{"id":"1.231730206","rc":[{"batb":[[0,1.87,4.66],[1,1.86,95.01],[2,1.8,555]],"ltp":1.87,"tv":1286.1,"id":40096582}]}]}
{"op":"mcm","clk":"11838171630","pt":1723490621210,"mc":[{"id":"1.231730206","rc":[{"trd":[[1.87,23.61]],"batb":[[0,1.86,95.01],[1,1.8,555],[2,1.79,444]],"batl":[[0,1.9,17.59]],"ltp":1.87,"tv":1295.43,"id":40096582}],"tv":1367.25}]}
{"op":"mcm","clk":"11838171651","pt":1723490621420,"mc":[{"id":"1.231730206","rc":[{"batl":[[0,1.89,5.08],[1,1.9,17.12]],"ltp":1.87,"tv":1295.43,"id":40096582}]}]}
{"op":"mcm","clk":"11838173465","pt":1723490643850,"mc":[{"id":"1.231730206","rc":[{"batb":[[0,1.8,555],[1,1.79,493.04],[2,1.74,17.32]],"batl":[[0,1.89,4.61]],"ltp":1.87,"tv":1295.43,"id":40096582}]}]}
{"op":"mcm","clk":"11838203534","pt":1723491035340,"mc":[{"id":"1.231730206","rc":[{"batl":[[0,2.24,17.12]],"ltp":2.1,"tv":71.82,"id":40096580}]}]}
{"op":"mcm","clk":"11838204835","pt":1723491050644,"mc":[{"id":"1.231730206","rc":[{"batb":[[0,2.14,10],[1,2.12,31.05],[2,2.1,560.64]],"ltp":2.1,"tv":71.82,"id":40096580}]}]}
{"op":"mcm","clk":"11838206644","pt":1723491073420,"mc":[{"id":"1.231730206","rc":[{"batb":[[0,2.12,31.05],[1,2.1,560.64],[2,1.95,606]],"ltp":2.1,"tv":71.82,"id":40096580}]}]}
{"op":"mcm","clk":"11838207410","pt":1723491082422,"mc":[{"id":"1.231730206","rc":[{"batb":[[0,2.16,10],[1,2.12,31.05],[2,2.1,560.64]],"ltp":2.1,"tv":71.82,"id":40096580}]}]}
{"op":"mcm","clk":"11838208889","pt":1723491100141,"mc":[{"id":"1.231730206","rc":[{"batb":[[0,2.12,31.05],[1,2.1,560.64],[2,1.95,606]],"ltp":2.1,"tv":71.82,"id":40096580}]}]}
{"op":"mcm","clk":"11838210018","pt":1723491114937,"mc":[{"id":"1.231730206","rc":[{"batb":[[0,2.14,10],[1,2.12,31.05],[2,2.1,560.64]],"ltp":2.1,"tv":71.82,"id":40096580}]}]}
{"op":"mcm","clk":"11838211551","pt":1723491133478,"mc":[{"id":"1.231730206","rc":[{"batb":[[0,2.12,31.05],[1,2.1,560.64],[2,1.95,606]],"ltp":2.1,"tv":71.82,"id":40096580}]}]}
{"op":"mcm","clk":"11838212841","pt":1723491148880,"mc":[{"id":"1.231730206","rc":[{"batb":[[0,2.14,10],[1,2.12,31.05],[2,2.1,560.64]],"ltp":2.1,"tv":71.82,"id":40096580}]}]}
{"op":"mcm","clk":"11838214373","pt":1723491167114,"mc":[{"id":"1.231730206","rc":[{"batb":[[0,2.12,31.05],[1,2.1,560.64],[2,1.95,606]],"ltp":2.1,"tv":71.82,"id":40096580}]}]}
{"op":"mcm","clk":"11838215575","pt":1723491182494,"mc":[{"id":"1.231730206","rc":[{"batb":[[0,2.14,10],[1,2.12,31.05],[2,2.1,560.64]],"ltp":2.1,"tv":71.82,"id":40096580}]}]}
{"op":"mcm","clk":"11838217130","pt":1723491201408,"mc":[{"id":"1.231730206","rc":[{"batb":[[0,2.12,31.05],[1,2.1,560.64],[2,1.95,606]],"ltp":2.1,"tv":71.82,"id":40096580}]}]}
{"op":"mcm","clk":"11838218448","pt":1723491216640,"mc":[{"id":"1.231730206","rc":[{"batb":[[0,2.14,10],[1,2.12,31.05],[2,2.1,560.64]],"ltp":2.1,"tv":71.82,"id":40096580}]}]}
{"op":"mcm","clk":"11838219818","pt":1723491234754,"mc":[{"id":"1.231730206","rc":[{"batb":[[0,2.12,31.05],[1,2.1,560.64],[2,1.95,606]],"ltp":2.1,"tv":71.82,"id":40096580}]}]}
{"op":"mcm","clk":"11838220156","pt":1723491239475,"mc":[{"id":"1.231730206","rc":[{"batb":[[0,2.16,10],[1,2.12,31.05],[2,2.1,560.64]],"ltp":2.1,"tv":71.82,"id":40096580}]}]}
{"op":"mcm","clk":"11838221459","pt":1723491257686,"mc":[{"id":"1.231730206","rc":[{"batb":[[0,2.12,31.05],[1,2.1,560.64],[2,1.95,606]],"ltp":2.1,"tv":71.82,"id":40096580}]}]}
{"op":"mcm","clk":"11838222571","pt":1723491273098,"mc":[{"id":"1.231730206","rc":[{"batb":[[0,2.14,10],[1,2.12,31.05],[2,2.1,560.64]],"ltp":2.1,"tv":71.82,"id":40096580}]}]}
{"op":"mcm","clk":"11838223810","pt":1723491291026,"mc":[{"id":"1.231730206","rc":[{"batb":[[0,2.12,31.05],[1,2.1,560.64],[2,1.95,606]],"ltp":2.1,"tv":71.82,"id":40096580}]}]}
{"op":"mcm","clk":"11838224966","pt":1723491305560,"mc":[{"id":"1.231730206","rc":[{"batb":[[0,2.14,10],[1,2.12,31.05],[2,2.1,560.64]],"ltp":2.1,"tv":71.82,"id":40096580}]}]}
{"op":"mcm","clk":"11838226332","pt":1723491323551,"mc":[{"id":"1.231730206","rc":[{"batb":[[0,2.12,31.05],[1,2.1,560.64],[2,1.95,606]],"ltp":2.1,"tv":71.82,"id":40096580}]}]}
{"op":"mcm","clk":"11838227544","pt":1723491339279,"mc":[{"id":"1.231730206","rc":[{"batb":[[0,2.14,10],[1,2.12,31.05],[2,2.1,560.64]],"ltp":2.1,"tv":71.82,"id":40096580}]}]}
{"op":"mcm","clk":"11838228873","pt":1723491357080,"mc":[{"id":"1.231730206","rc":[{"batb":[[0,2.12,31.05],[1,2.1,560.64],[2,1.95,606]],"ltp":2.1,"tv":71.82,"id":40096580}]}]}
{"op":"mcm","clk":"11838229986","pt":1723491372123,"mc":[{"id":"1.231730206","rc":[{"batb":[[0,2.14,10],[1,2.12,31.05],[2,2.1,560.64]],"ltp":2.1,"tv":71.82,"id":40096580}]}]}
{"op":"mcm","clk":"11838231295","pt":1723491390467,"mc":[{"id":"1.231730206","rc":[{"batb":[[0,2.12,31.05],[1,2.1,560.64],[2,1.95,606]],"ltp":2.1,"tv":71.82,"id":40096580}]}]}
{"op":"mcm","clk":"11838232323","pt":1723491404871,"mc":[{"id":"1.231730206","rc":[{"batb":[[0,2.14,10],[1,2.12,31.05],[2,2.1,560.64]],"ltp":2.1,"tv":71.82,"id":40096580}]}]}
{"op":"mcm","clk":"11838233670","pt":1723491423361,"mc":[{"id":"1.231730206","rc":[{"batb":[[0,2.12,31.05],[1,2.1,560.64],[2,1.95,606]],"ltp":2.1,"tv":71.82,"id":40096580}]}]}
{"op":"mcm","clk":"11838234766","pt":1723491437375,"mc":[{"id":"1.231730206","rc":[{"batb":[[0,2.14,10],[1,2.12,31.05],[2,2.1,560.64]],"ltp":2.1,"tv":71.82,"id":40096580}]}]}
{"op":"mcm","clk":"11838236069","pt":1723491454917,"mc":[{"id":"1.231730206","rc":[{"batb":[[0,2.12,31.05],[1,2.1,560.64],[2,1.95,606]],"ltp":2.1,"tv":71.82,"id":40096580}]}]}
{"op":"mcm","clk":"11838237147","pt":1723491469321,"mc":[{"id":"1.231730206","rc":[{"batb":[[0,2.14,10],[1,2.12,31.05],[2,2.1,560.64]],"ltp":2.1,"tv":71.82,"id":40096580}]}]}
{"op":"mcm","clk":"11838238456","pt":1723491487928,"mc":[{"id":"1.231730206","rc":[{"batb":[[0,2.12,31.05],[1,2.1,560.64],[2,1.95,606]],"ltp":2.1,"tv":71.82,"id":40096580}]}]}
{"op":"mcm","clk":"11838239600","pt":1723491503453,"mc":[{"id":"1.231730206","rc":[{"batb":[[0,2.14,10],[1,2.12,31.05],[2,2.1,560.64]],"ltp":2.1,"tv":71.82,"id":40096580}]}]}
{"op":"mcm","clk":"11838241025","pt":1723491521871,"mc":[{"id":"1.231730206","rc":[{"batb":[[0,2.12,31.05],[1,2.1,560.64],[2,1.95,606]],"ltp":2.1,"tv":71.82,"id":40096580}]}]}
{"op":"mcm","clk":"11838242055","pt":1723491536582,"mc":[{"id":"1.231730206","rc":[{"batb":[[0,2.14,10],[1,2.12,31.05],[2,2.1,560.64]],"ltp":2.1,"tv":71.82,"id":40096580}]}]}
{"op":"mcm","clk":"11838243603","pt":1723491560223,"mc":[{"id":"1.231730206","rc":[{"batb":[[0,2.12,31.05],[1,2.1,560.64],[2,1.95,606]],"ltp":2.1,"tv":71.82,"id":40096580}]}]}
{"op":"mcm","clk":"11838244143","pt":1723491568643,"mc":[{"id":"1.231730206","rc":[{"batb":[[0,2.16,10],[1,2.12,31.05],[2,2.1,560.64]],"ltp":2.1,"tv":71.82,"id":40096580}]}]}
{"op":"mcm","clk":"11838245375","pt":1723491587843,"mc":[{"id":"1.231730206","rc":[{"batb":[[0,2.12,31.05],[1,2.1,560.64],[2,1.95,606]],"ltp":2.1,"tv":71.82,"id":40096580}]}]}
{"op":"mcm","clk":"11838246364","pt":1723491603293,"mc":[{"id":"1.231730206","rc":[{"batb":[[0,2.14,10],[1,2.12,31.05],[2,2.1,560.64]],"ltp":2.1,"tv":71.82,"id":40096580}]}]}
{"op":"mcm","clk":"11838247740","pt":1723491621992,"mc":[{"id":"1.231730206","rc":[{"batb":[[0,2.12,31.05],[1,2.1,560.64],[2,1.95,606]],"ltp":2.1,"tv":71.82,"id":40096580}]}]}
{"op":"mcm","clk":"11838249036","pt":1723491639011,"mc":[{"id":"1.231730206","rc":[{"batb":[[0,2.14,10],[1,2.12,31.05],[2,2.1,560.64]],"ltp":2.1,"tv":71.82,"id":40096580}]}]}
{"op":"mcm","clk":"11838250465","pt":1723491657913,"mc":[{"id":"1.231730206","rc":[{"batb":[[0,2.12,31.05],[1,2.1,560.64],[2,1.95,606]],"ltp":2.1,"tv":71.82,"id":40096580}]}]}
{"op":"mcm","clk":"11838251675","pt":1723491673528,"mc":[{"id":"1.231730206","rc":[{"batb":[[0,2.14,10],[1,2.12,31.05],[2,2.1,560.64]],"ltp":2.1,"tv":71.82,"id":40096580}]}]}
{"op":"mcm","clk":"11838253027","pt":1723491692462,"mc":[{"id":"1.231730206","rc":[{"batb":[[0,2.12,31.05],[1,2.1,560.64],[2,1.95,606]],"ltp":2.1,"tv":71.82,"id":40096580}]}]}
{"op":"mcm","clk":"11838254169","pt":1723491708591,"mc":[{"id":"1.231730206","rc":[{"batb":[[0,2.14,10],[1,2.12,31.05],[2,2.1,560.64]],"ltp":2.1,"tv":71.82,"id":40096580}]}]}
{"op":"mcm","clk":"11838255395","pt":1723491726704,"mc":[{"id":"1.231730206","rc":[{"batb":[[0,2.12,31.05],[1,2.1,560.64],[2,1.95,606]],"ltp":2.1,"tv":71.82,"id":40096580}]}]}
{"op":"mcm","clk":"11838256389","pt":1723491741146,"mc":[{"id":"1.231730206","rc":[{"batb":[[0,2.14,10],[1,2.12,31.05],[2,2.1,560.64]],"ltp":2.1,"tv":71.82,"id":40096580}]}]}
{"op":"mcm","clk":"11838257562","pt":1723491759628,"mc":[{"id":"1.231730206","rc":[{"batb":[[0,2.12,31.05],[1,2.1,560.64],[2,1.95,606]],"ltp":2.1,"tv":71.82,"id":40096580}]}]}
{"op":"mcm","clk":"11838328338","pt":1723492806491,"mc":[{"id":"1.231730206","rc":[{"batb":[[0,2.12,31.05],[1,2.1,560.79]],"batl":[[0,2.24,34.49]],"ltp":2.1,"tv":71.82,"id":40096580},{"trd":[[1.87,23.61],[1.91,1265.12],[1.92,6.73]],"batl":[[0,1.89,4.61],[1,1.9,17.12]],"ltp":1.87,"tv":1295.59,"id":40096582}],"tv":1367.41}]}
{"op":"mcm","clk":"11838328533","pt":1723492810003,"mc":[{"id":"1.231730206","rc":[{"batb":[[0,2.14,10],[1,2.12,31.05],[2,2.1,560.79]],"ltp":2.1,"tv":71.82,"id":40096580}]}]}
{"op":"mcm","clk":"11838328835","pt":1723492815946,"mc":[{"id":"1.231730206","rc":[{"batb":[[0,2.12,31.05],[1,2.1,560.79],[2,1.95,606]],"ltp":2.1,"tv":71.82,"id":40096580}]}]}
{"op":"mcm","clk":"11838348543","pt":1723493277902,"mc":[{"id":"1.231730206","rc":[{"batb":[[0,2.14,10],[1,2.12,31.05],[2,2.1,560.79]],"ltp":2.1,"tv":71.82,"id":40096580}]}]}
{"op":"mcm","clk":"11838348676","pt":1723493281402,"mc":[{"id":"1.231730206","rc":[{"batb":[[0,2.12,31.05],[1,2.1,560.79],[2,1.95,606]],"ltp":2.1,"tv":71.82,"id":40096580}]}]}
{"op":"mcm","clk":"11838359444","pt":1723493609955,"mc":[{"id":"1.231730206","rc":[{"batb":[[0,2.14,10],[1,2.12,31.05],[2,2.1,560.79]],"ltp":2.1,"tv":71.82,"id":40096580}]}]}
{"op":"mcm","clk":"11838359580","pt":1723493614036,"mc":[{"id":"1.231730206","rc":[{"batb":[[0,2.12,31.05],[1,2.1,560.79],[2,1.95,606]],"ltp":2.1,"tv":71.82,"id":40096580}]}]}
{"op":"mcm","clk":"11838360263","pt":1723493636601,"mc":[{"id":"1.231730206","rc":[{"batb":[[0,2.14,10],[1,2.12,31.05],[2,2.1,560.79]],"ltp":2.1,"tv":71.82,"id":40096580}]}]}
{"op":"mcm","clk":"11838360350","pt":1723493640205,"mc":[{"id":"1.231730206","rc":[{"batb":[[0,2.12,31.05],[1,2.1,560.79],[2,1.95,606]],"ltp":2.1,"tv":71.82,"id":40096580}]}]}
{"op":"mcm","clk":"11838360635","pt":1723493649580,"mc":[{"id":"1.231730206","rc":[{"batb":[[0,2.14,10],[1,2.12,31.05],[2,2.1,560.79]],"ltp":2.1,"tv":71.82,"id":40096580}]}]}
{"op":"mcm","clk":"11838360783","pt":1723493653542,"mc":[{"id":"1.231730206","rc":[{"batb":[[0,2.12,31.05],[1,2.1,560.79],[2,1.95,606]],"ltp":2.1,"tv":71.82,"id":40096580}]}]}
{"op":"mcm","clk":"11838360970","pt":1723493659613,"mc":[{"id":"1.231730206","rc":[{"batb":[[0,2.14,10],[1,2.12,31.05],[2,2.1,560.79]],"ltp":2.1,"tv":71.82,"id":40096580}]}]}
{"op":"mcm","clk":"11838361081","pt":1723493663831,"mc":[{"id":"1.231730206","rc":[{"batb":[[0,2.12,31.05],[1,2.1,560.79],[2,1.95,606]],"ltp":2.1,"tv":71.82,"id":40096580}]}]}
{"op":"mcm","clk":"11838361181","pt":1723493667287,"mc":[{"id":"1.231730206","rc":[{"batb":[[0,2.14,10],[1,2.12,31.05],[2,2.1,560.79]],"ltp":2.1,"tv":71.82,"id":40096580}]}]}
{"op":"mcm","clk":"11838361281","pt":1723493670534,"mc":[{"id":"1.231730206","rc":[{"batb":[[0,2.12,31.05],[1,2.1,560.79],[2,1.95,606]],"ltp":2.1,"tv":71.82,"id":40096580}]}]}
{"op":"mcm","clk":"11838361424","pt":1723493675042,"mc":[{"id":"1.231730206","rc":[{"batb":[[0,2.14,10],[1,2.12,31.05],[2,2.1,560.79]],"ltp":2.1,"tv":71.82,"id":40096580}]}]}
{"op":"mcm","clk":"11838361529","pt":1723493678541,"mc":[{"id":"1.231730206","rc":[{"batb":[[0,2.12,31.05],[1,2.1,560.79],[2,1.95,606]],"ltp":2.1,"tv":71.82,"id":40096580}]}]}
{"op":"mcm","clk":"11838361685","pt":1723493683234,"mc":[{"id":"1.231730206","rc":[{"batb":[[0,2.14,10],[1,2.12,31.05],[2,2.1,560.79]],"ltp":2.1,"tv":71.82,"id":40096580}]}]}
{"op":"mcm","clk":"11838361792","pt":1723493686640,"mc":[{"id":"1.231730206","rc":[{"batb":[[0,2.12,31.05],[1,2.1,560.79],[2,1.95,606]],"ltp":2.1,"tv":71.82,"id":40096580}]}]}
{"op":"mcm","clk":"11838361898","pt":1723493689829,"mc":[{"id":"1.231730206","rc":[{"batb":[[0,2.14,10],[1,2.12,31.05],[2,2.1,560.79]],"ltp":2.1,"tv":71.82,"id":40096580}]}]}
{"op":"mcm","clk":"11838362026","pt":1723493693443,"mc":[{"id":"1.231730206","rc":[{"batb":[[0,2.12,31.05],[1,2.1,560.79],[2,1.95,606]],"ltp":2.1,"tv":71.82,"id":40096580}]}]}
{"op":"mcm","clk":"11838362165","pt":1723493697064,"mc":[{"id":"1.231730206","rc":[{"batb":[[0,2.14,10],[1,2.12,31.05],[2,2.1,560.79]],"ltp":2.1,"tv":71.82,"id":40096580}]}]}
{"op":"mcm","clk":"11838362276","pt":1723493700461,"mc":[{"id":"1.231730206","rc":[{"batb":[[0,2.12,31.05],[1,2.1,560.79],[2,1.95,606]],"ltp":2.1,"tv":71.82,"id":40096580}]}]}
{"op":"mcm","clk":"11838362404","pt":1723493704145,"mc":[{"id":"1.231730206","rc":[{"batb":[[0,2.14,10],[1,2.12,31.05],[2,2.1,560.79]],"ltp":2.1,"tv":71.82,"id":40096580}]}]}
{"op":"mcm","clk":"11838362509","pt":1723493707659,"mc":[{"id":"1.231730206","rc":[{"batb":[[0,2.12,31.05],[1,2.1,560.79],[2,1.95,606]],"ltp":2.1,"tv":71.82,"id":40096580}]}]}
{"op":"mcm","clk":"11838362672","pt":1723493711430,"mc":[{"id":"1.231730206","rc":[{"batb":[[0,2.14,10],[1,2.12,31.05],[2,2.1,560.79]],"ltp":2.1,"tv":71.82,"id":40096580}]}]}
{"op":"mcm","clk":"11838362777","pt":1723493714845,"mc":[{"id":"1.231730206","rc":[{"batb":[[0,2.12,31.05],[1,2.1,560.79],[2,1.95,606]],"ltp":2.1,"tv":71.82,"id":40096580}]}]}
{"op":"mcm","clk":"11838362891","pt":1723493718149,"mc":[{"id":"1.231730206","rc":[{"batb":[[0,2.14,10],[1,2.12,31.05],[2,2.1,560.79]],"ltp":2.1,"tv":71.82,"id":40096580}]}]}
{"op":"mcm","clk":"11838362998","pt":1723493721775,"mc":[{"id":"1.231730206","rc":[{"batb":[[0,2.12,31.05],[1,2.1,560.79],[2,1.95,606]],"ltp":2.1,"tv":71.82,"id":40096580}]}]}
{"op":"mcm","clk":"11838363090","pt":1723493724060,"mc":[{"id":"1.231730206","rc":[{"batb":[[0,2.14,10],[1,2.12,31.05],[2,2.1,560.79]],"ltp":2.1,"tv":71.82,"id":40096580}]}]}
{"op":"mcm","clk":"11838363227","pt":1723493727681,"mc":[{"id":"1.231730206","rc":[{"batb":[[0,2.12,31.05],[1,2.1,560.79],[2,1.95,606]],"ltp":2.1,"tv":71.82,"id":40096580}]}]}
{"op":"mcm","clk":"11838363347","pt":1723493731258,"mc":[{"id":"1.231730206","rc":[{"batb":[[0,2.14,10],[1,2.12,31.05],[2,2.1,560.79]],"ltp":2.1,"tv":71.82,"id":40096580}]}]}
{"op":"mcm","clk":"11838363498","pt":1723493735298,"mc":[{"id":"1.231730206","rc":[{"batb":[[0,2.12,31.05],[1,2.1,560.79],[2,1.95,606]],"ltp":2.1,"tv":71.82,"id":40096580}]}]}
{"op":"mcm","clk":"11838363609","pt":1723493738368,"mc":[{"id":"1.231730206","rc":[{"batb":[[0,2.14,10],[1,2.12,31.05],[2,2.1,560.79]],"ltp":2.1,"tv":71.82,"id":40096580}]}]}
{"op":"mcm","clk":"11838363776","pt":1723493742497,"mc":[{"id":"1.231730206","rc":[{"batb":[[0,2.12,31.05],[1,2.1,560.79],[2,1.95,606]],"ltp":2.1,"tv":71.82,"id":40096580}]}]}
{"op":"mcm","clk":"11838363873","pt":1723493745287,"mc":[{"id":"1.231730206","rc":[{"batb":[[0,2.14,10],[1,2.12,31.05],[2,2.1,560.79]],"ltp":2.1,"tv":71.82,"id":40096580}]}]}
{"op":"mcm","clk":"11838363993","pt":1723493749207,"mc":[{"id":"1.231730206","rc":[{"batb":[[0,2.12,31.05],[1,2.1,560.79],[2,1.95,606]],"ltp":2.1,"tv":71.82,"id":40096580}]}]}
{"op":"mcm","clk":"11838364096","pt":1723493752303,"mc":[{"id":"1.231730206","rc":[{"batb":[[0,2.14,10],[1,2.12,31.05],[2,2.1,560.79]],"ltp":2.1,"tv":71.82,"id":40096580}]}]}
{"op":"mcm","clk":"11838364231","pt":1723493756220,"mc":[{"id":"1.231730206","rc":[{"batb":[[0,2.12,31.05],[1,2.1,560.79],[2,1.95,606]],"ltp":2.1,"tv":71.82,"id":40096580}]}]}
{"op":"mcm","clk":"11838364358","pt":1723493759332,"mc":[{"id":"1.231730206","rc":[{"batb":[[0,2.14,10],[1,2.12,31.05],[2,2.1,560.79]],"ltp":2.1,"tv":71.82,"id":40096580}]}]}
{"op":"mcm","clk":"11838364461","pt":1723493762907,"mc":[{"id":"1.231730206","rc":[{"batb":[[0,2.12,31.05],[1,2.1,560.79],[2,1.95,606]],"ltp":2.1,"tv":71.82,"id":40096580}]}]}
{"op":"mcm","clk":"11838364768","pt":1723493770537,"mc":[{"id":"1.231730206","rc":[{"batb":[[0,2.14,10],[1,2.12,31.05],[2,2.1,560.79]],"ltp":2.1,"tv":71.82,"id":40096580}]}]}
{"op":"mcm","clk":"11838364905","pt":1723493774246,"mc":[{"id":"1.231730206","rc":[{"batb":[[0,2.12,31.05],[1,2.1,560.79],[2,1.95,606]],"ltp":2.1,"tv":71.82,"id":40096580}]}]}
{"op":"mcm","clk":"11838364995","pt":1723493776624,"mc":[{"id":"1.231730206","rc":[{"batb":[[0,2.14,10],[1,2.12,31.05],[2,2.1,560.79]],"ltp":2.1,"tv":71.82,"id":40096580}]}]}
{"op":"mcm","clk":"11838365113","pt":1723493780130,"mc":[{"id":"1.231730206","rc":[{"batb":[[0,2.12,31.05],[1,2.1,560.79],[2,1.95,606]],"ltp":2.1,"tv":71.82,"id":40096580}]}]}
{"op":"mcm","clk":"11838365204","pt":1723493782747,"mc":[{"id":"1.231730206","rc":[{"batb":[[0,2.14,10],[1,2.12,31.05],[2,2.1,560.79]],"ltp":2.1,"tv":71.82,"id":40096580}]}]}
{"op":"mcm","clk":"11838365353","pt":1723493786251,"mc":[{"id":"1.231730206","rc":[{"batb":[[0,2.12,31.05],[1,2.1,560.79],[2,1.95,606]],"ltp":2.1,"tv":71.82,"id":40096580}]}]}
{"op":"mcm","clk":"11838365492","pt":1723493790224,"mc":[{"id":"1.231730206","rc":[{"batb":[[0,2.14,10],[1,2.12,31.05],[2,2.1,560.79]],"ltp":2.1,"tv":71.82,"id":40096580}]}]}
{"op":"mcm","clk":"11838365627","pt":1723493793933,"mc":[{"id":"1.231730206","rc":[{"batb":[[0,2.12,31.05],[1,2.1,560.79],[2,1.95,606]],"ltp":2.1,"tv":71.82,"id":40096580}]}]}
{"op":"mcm","clk":"11838365756","pt":1723493798468,"mc":[{"id":"1.231730206","rc":[{"batb":[[0,2.14,10],[1,2.12,31.05],[2,2.1,560.79]],"ltp":2.1,"tv":71.82,"id":40096580}]}]}
{"op":"mcm","clk":"11838365891","pt":1723493802234,"mc":[{"id":"1.231730206","rc":[{"batb":[[0,2.12,31.05],[1,2.1,560.79],[2,1.95,606]],"ltp":2.1,"tv":71.82,"id":40096580}]}]}
{"op":"mcm","clk":"11838366014","pt":1723493805437,"mc":[{"id":"1.231730206","rc":[{"batb":[[0,2.14,10],[1,2.12,31.05],[2,2.1,560.79]],"ltp":2.1,"tv":71.82,"id":40096580}]}]}
{"op":"mcm","clk":"11838366132","pt":1723493809244,"mc":[{"id":"1.231730206","rc":[{"batb":[[0,2.12,31.05],[1,2.1,560.79],[2,1.95,606]],"ltp":2.1,"tv":71.82,"id":40096580}]}]}
{"op":"mcm","clk":"11838366283","pt":1723493813582,"mc":[{"id":"1.231730206","rc":[{"batb":[[0,2.14,10],[1,2.12,31.05],[2,2.1,560.79]],"ltp":2.1,"tv":71.82,"id":40096580}]}]}
{"op":"mcm","clk":"11838366442","pt":1723493817141,"mc":[{"id":"1.231730206","rc":[{"batb":[[0,2.12,31.05],[1,2.1,560.79],[2,1.95,606]],"ltp":2.1,"tv":71.82,"id":40096580}]}]}
{"op":"mcm","clk":"11838366613","pt":1723493821368,"mc":[{"id":"1.231730206","rc":[{"batb":[[0,2.14,10],[1,2.12,31.05],[2,2.1,560.79]],"ltp":2.1,"tv":71.82,"id":40096580}]}]}
{"op":"mcm","clk":"11838366777","pt":1723493825175,"mc":[{"id":"1.231730206","rc":[{"batb":[[0,2.12,31.05],[1,2.1,560.79],[2,1.95,606]],"ltp":2.1,"tv":71.82,"id":40096580}]}]}
{"op":"mcm","clk":"11838366964","pt":1723493829089,"mc":[{"id":"1.231730206","rc":[{"batb":[[0,2.14,10],[1,2.12,31.05],[2,2.1,560.79]],"ltp":2.1,"tv":71.82,"id":40096580}]}]}
{"op":"mcm","clk":"11838367118","pt":1723493832793,"mc":[{"id":"1.231730206","rc":[{"batb":[[0,2.12,31.05],[1,2.1,560.79],[2,1.95,606]],"ltp":2.1,"tv":71.82,"id":40096580}]}]}
{"op":"mcm","clk":"11838367268","pt":1723493836195,"mc":[{"id":"1.231730206","rc":[{"batb":[[0,2.14,10],[1,2.12,31.05],[2,2.1,560.79]],"ltp":2.1,"tv":71.82,"id":40096580}]}]}
{"op":"mcm","clk":"11838367410","pt":1723493839800,"mc":[{"id":"1.231730206","rc":[{"batb":[[0,2.12,31.05],[1,2.1,560.79],[2,1.95,606]],"ltp":2.1,"tv":71.82,"id":40096580}]}]}
{"op":"mcm","clk":"11838367515","pt":1723493842682,"mc":[{"id":"1.231730206","rc":[{"batb":[[0,2.14,10],[1,2.12,31.05],[2,2.1,560.79]],"ltp":2.1,"tv":71.82,"id":40096580}]}]}
{"op":"mcm","clk":"11838367676","pt":1723493846495,"mc":[{"id":"1.231730206","rc":[{"batb":[[0,2.12,31.05],[1,2.1,560.79],[2,1.95,606]],"ltp":2.1,"tv":71.82,"id":40096580}]}]}
{"op":"mcm","clk":"11838367809","pt":1723493849386,"mc":[{"id":"1.231730206","rc":[{"batb":[[0,2.14,10],[1,2.12,31.05],[2,2.1,560.79]],"ltp":2.1,"tv":71.82,"id":40096580}]}]}
{"op":"mcm","clk":"11838367950","pt":1723493853085,"mc":[{"id":"1.231730206","rc":[{"batb":[[0,2.12,31.05],[1,2.1,560.79],[2,1.95,606]],"ltp":2.1,"tv":71.82,"id":40096580}]}]}
{"op":"mcm","clk":"11838368038","pt":1723493855688,"mc":[{"id":"1.231730206","rc":[{"batb":[[0,2.14,10],[1,2.12,31.05],[2,2.1,560.79]],"ltp":2.1,"tv":71.82,"id":40096580}]}]}
{"op":"mcm","clk":"11838368173","pt":1723493859505,"mc":[{"id":"1.231730206","rc":[{"batb":[[0,2.12,31.05],[1,2.1,560.79],[2,1.95,606]],"ltp":2.1,"tv":71.82,"id":40096580}]}]}
{"op":"mcm","clk":"11838368291","pt":1723493862696,"mc":[{"id":"1.231730206","rc":[{"batb":[[0,2.14,10],[1,2.12,31.05],[2,2.1,560.79]],"ltp":2.1,"tv":71.82,"id":40096580}]}]}
{"op":"mcm","clk":"11838368421","pt":1723493866717,"mc":[{"id":"1.231730206","rc":[{"batb":[[0,2.12,31.05],[1,2.1,560.79],[2,1.95,606]],"ltp":2.1,"tv":71.82,"id":40096580}]}]}
{"op":"mcm","clk":"11838368537","pt":1723493869706,"mc":[{"id":"1.231730206","rc":[{"batb":[[0,2.14,10],[1,2.12,31.05],[2,2.1,560.79]],"ltp":2.1,"tv":71.82,"id":40096580}]}]}
{"op":"mcm","clk":"11838368660","pt":1723493873205,"mc":[{"id":"1.231730206","rc":[{"batb":[[0,2.12,31.05],[1,2.1,560.79],[2,1.95,606]],"ltp":2.1,"tv":71.82,"id":40096580}]}]}
{"op":"mcm","clk":"11838368752","pt":1723493875626,"mc":[{"id":"1.231730206","rc":[{"batb":[[0,2.14,10],[1,2.12,31.05],[2,2.1,560.79]],"ltp":2.1,"tv":71.82,"id":40096580}]}]}
{"op":"mcm","clk":"11838368890","pt":1723493879234,"mc":[{"id":"1.231730206","rc":[{"batb":[[0,2.12,31.05],[1,2.1,560.79],[2,1.95,606]],"ltp":2.1,"tv":71.82,"id":40096580}]}]}
{"op":"mcm","clk":"11838369020","pt":1723493883320,"mc":[{"id":"1.231730206","rc":[{"batb":[[0,2.14,10],[1,2.12,31.05],[2,2.1,560.79]],"ltp":2.1,"tv":71.82,"id":40096580}]}]}
{"op":"mcm","clk":"11838369136","pt":1723493886920,"mc":[{"id":"1.231730206","rc":[{"batb":[[0,2.12,31.05],[1,2.1,560.79],[2,1.95,606]],"ltp":2.1,"tv":71.82,"id":40096580}]}]}
{"op":"mcm","clk":"11838369231","pt":1723493889550,"mc":[{"id":"1.231730206","rc":[{"batb":[[0,2.14,10],[1,2.12,31.05],[2,2.1,560.79]],"ltp":2.1,"tv":71.82,"id":40096580}]}]}
{"op":"mcm","clk":"11838369396","pt":1723493893329,"mc":[{"id":"1.231730206","rc":[{"batb":[[0,2.12,31.05],[1,2.1,560.79],[2,1.95,606]],"ltp":2.1,"tv":71.82,"id":40096580}]}]}
{"op":"mcm","clk":"11838369499","pt":1723493895962,"mc":[{"id":"1.231730206","rc":[{"batb":[[0,2.14,10],[1,2.12,31.05],[2,2.1,560.79]],"ltp":2.1,"tv":71.82,"id":40096580}]}]}
{"op":"mcm","clk":"11838369613","pt":1723493899670,"mc":[{"id":"1.231730206","rc":[{"batb":[[0,2.12,31.05],[1,2.1,560.79],[2,1.95,606]],"ltp":2.1,"tv":71.82,"id":40096580}]}]}
{"op":"mcm","clk":"11838369748","pt":1723493902253,"mc":[{"id":"1.231730206","rc":[{"batb":[[0,2.14,10],[1,2.12,31.05],[2,2.1,560.79]],"ltp":2.1,"tv":71.82,"id":40096580}]}]}
{"op":"mcm","clk":"11838369868","pt":1723493905658,"mc":[{"id":"1.231730206","rc":[{"batb":[[0,2.12,31.05],[1,2.1,560.79],[2,1.95,606]],"ltp":2.1,"tv":71.82,"id":40096580}]}]}
{"op":"mcm","clk":"11838369985","pt":1723493908456,"mc":[{"id":"1.231730206","rc":[{"batb":[[0,2.14,10],[1,2.12,31.05],[2,2.1,560.79]],"ltp":2.1,"tv":71.82,"id":40096580}]}]}
{"op":"mcm","clk":"11838370103","pt":1723493912166,"mc":[{"id":"1.231730206","rc":[{"batb":[[0,2.12,31.05],[1,2.1,560.79],[2,1.95,606]],"ltp":2.1,"tv":71.82,"id":40096580}]}]}
{"op":"mcm","clk":"11838370222","pt":1723493914851,"mc":[{"id":"1.231730206","rc":[{"batb":[[0,2.14,10],[1,2.12,31.05],[2,2.1,560.79]],"ltp":2.1,"tv":71.82,"id":40096580}]}]}
{"op":"mcm","clk":"11838370347","pt":1723493918570,"mc":[{"id":"1.231730206","rc":[{"batb":[[0,2.12,31.05],[1,2.1,560.79],[2,1.95,606]],"ltp":2.1,"tv":71.82,"id":40096580}]}]}
{"op":"mcm","clk":"11838370445","pt":1723493921258,"mc":[{"id":"1.231730206","rc":[{"batb":[[0,2.14,10],[1,2.12,31.05],[2,2.1,560.79]],"ltp":2.1,"tv":71.82,"id":40096580}]}]}
{"op":"mcm","clk":"11838370576","pt":1723493924802,"mc":[{"id":"1.231730206","rc":[{"batb":[[0,2.12,31.05],[1,2.1,560.79],[2,1.95,606]],"ltp":2.1,"tv":71.82,"id":40096580}]}]}
{"op":"mcm","clk":"11838370662","pt":1723493927385,"mc":[{"id":"1.231730206","rc":[{"batb":[[0,2.14,10],[1,2.12,31.05],[2,2.1,560.79]],"ltp":2.1,"tv":71.82,"id":40096580}]}]}
{"op":"mcm","clk":"11838370782","pt":1723493930784,"mc":[{"id":"1.231730206","rc":[{"batb":[[0,2.12,31.05],[1,2.1,560.79],[2,1.95,606]],"ltp":2.1,"tv":71.82,"id":40096580}]}]}
{"op":"mcm","clk":"11838370898","pt":1723493933406,"mc":[{"id":"1.231730206","rc":[{"batb":[[0,2.14,10],[1,2.12,31.05],[2,2.1,560.79]],"ltp":2.1,"tv":71.82,"id":40096580}]}]}
{"op":"mcm","clk":"11838371047","pt":1723493936808,"mc":[{"id":"1.231730206","rc":[{"batb":[[0,2.12,31.05],[1,2.1,560.79],[2,1.95,606]],"ltp":2.1,"tv":71.82,"id":40096580}]}]}
{"op":"mcm","clk":"11838371153","pt":1723493939279,"mc":[{"id":"1.231730206","rc":[{"batb":[[0,2.14,10],[1,2.12,31.05],[2,2.1,560.79]],"ltp":2.1,"tv":71.82,"id":40096580}]}]}
{"op":"mcm","clk":"11838371299","pt":1723493942891,"mc":[{"id":"1.231730206","rc":[{"batb":[[0,2.12,31.05],[1,2.1,560.79],[2,1.95,606]],"ltp":2.1,"tv":71.82,"id":40096580}]}]}
{"op":"mcm","clk":"11838371408","pt":1723493945618,"mc":[{"id":"1.231730206","rc":[{"batb":[[0,2.14,10],[1,2.12,31.05],[2,2.1,560.79]],"ltp":2.1,"tv":71.82,"id":40096580}]}]}
{"op":"mcm","clk":"11838371528","pt":1723493949117,"mc":[{"id":"1.231730206","rc":[{"batb":[[0,2.12,31.05],[1,2.1,560.79],[2,1.95,606]],"ltp":2.1,"tv":71.82,"id":40096580}]}]}
{"op":"mcm","clk":"11838371605","pt":1723493951400,"mc":[{"id":"1.231730206","rc":[{"batb":[[0,2.14,10],[1,2.12,31.05],[2,2.1,560.79]],"ltp":2.1,"tv":71.82,"id":40096580}]}]}
{"op":"mcm","clk":"11838371722","pt":1723493954830,"mc":[{"id":"1.231730206","rc":[{"batb":[[0,2.12,31.05],[1,2.1,560.79],[2,1.95,606]],"ltp":2.1,"tv":71.82,"id":40096580}]}]}
{"op":"mcm","clk":"11838371855","pt":1723493958706,"mc":[{"id":"1.231730206","rc":[{"batb":[[0,2.14,10],[1,2.12,31.05],[2,2.1,560.79]],"ltp":2.1,"tv":71.82,"id":40096580}]}]}
{"op":"mcm","clk":"11838371995","pt":1723493962637,"mc":[{"id":"1.231730206","rc":[{"batb":[[0,2.12,31.05],[1,2.1,560.79],[2,1.95,606]],"ltp":2.1,"tv":71.82,"id":40096580}]}]}
{"op":"mcm","clk":"11838372094","pt":1723493965137,"mc":[{"id":"1.231730206","rc":[{"batb":[[0,2.14,10],[1,2.12,31.05],[2,2.1,560.79]],"ltp":2.1,"tv":71.82,"id":40096580}]}]}
{"op":"mcm","clk":"11838372254","pt":1723493968811,"mc":[{"id":"1.231730206","rc":[{"batb":[[0,2.12,31.05],[1,2.1,560.79],[2,1.95,606]],"ltp":2.1,"tv":71.82,"id":40096580}]}]}
{"op":"mcm","clk":"11838372377","pt":1723493971649,"mc":[{"id":"1.231730206","rc":[{"batb":[[0,2.14,10],[1,2.12,31.05],[2,2.1,560.79]],"ltp":2.1,"tv":71.82,"id":40096580}]}]}
{"op":"mcm","clk":"11838372539","pt":1723493975327,"mc":[{"id":"1.231730206","rc":[{"batb":[[0,2.12,31.05],[1,2.1,560.79],[2,1.95,606]],"ltp":2.1,"tv":71.82,"id":40096580}]}]}
{"op":"mcm","clk":"11838372648","pt":1723493978625,"mc":[{"id":"1.231730206","rc":[{"batb":[[0,2.14,10],[1,2.12,31.05],[2,2.1,560.79]],"ltp":2.1,"tv":71.82,"id":40096580}]}]}
{"op":"mcm","clk":"11838372828","pt":1723493982545,"mc":[{"id":"1.231730206","rc":[{"batb":[[0,2.12,31.05],[1,2.1,560.79],[2,1.95,606]],"ltp":2.1,"tv":71.82,"id":40096580}]}]}
{"op":"mcm","clk":"11838373023","pt":1723493986938,"mc":[{"id":"1.231730206","rc":[{"batb":[[0,2.14,10],[1,2.12,31.05],[2,2.1,560.79]],"ltp":2.1,"tv":71.82,"id":40096580}]}]}
{"op":"mcm","clk":"11838373329","pt":1723493994347,"mc":[{"id":"1.231730206","rc":[{"batb":[[0,2.12,31.05],[1,2.1,560.79],[2,1.95,606]],"ltp":2.1,"tv":71.82,"id":40096580}]}]}
{"op":"mcm","clk":"11838373542","pt":1723493999868,"mc":[{"id":"1.231730206","rc":[{"batb":[[0,2.16,10],[1,2.12,31.05],[2,2.1,560.79]],"ltp":2.1,"tv":71.82,"id":40096580}]}]}
{"op":"mcm","clk":"11838373916","pt":1723494009866,"mc":[{"id":"1.231730206","rc":[{"batb":[[0,2.12,31.05],[1,2.1,560.79],[2,1.95,606]],"ltp":2.1,"tv":71.82,"id":40096580}]}]}
{"op":"mcm","clk":"11838374177","pt":1723494016981,"mc":[{"id":"1.231730206","rc":[{"batb":[[0,2.14,10],[1,2.12,31.05],[2,2.1,560.79]],"ltp":2.1,"tv":71.82,"id":40096580}]}]}
{"op":"mcm","clk":"11838374597","pt":1723494027497,"mc":[{"id":"1.231730206","rc":[{"batb":[[0,2.12,31.05],[1,2.1,560.79],[2,1.95,606]],"ltp":2.1,"tv":71.82,"id":40096580}]}]}
{"op":"mcm","clk":"11838374760","pt":1723494032092,"mc":[{"id":"1.231730206","rc":[{"batb":[[0,2.14,10],[1,2.12,31.05],[2,2.1,560.79]],"ltp":2.1,"tv":71.82,"id":40096580}]}]}
{"op":"mcm","clk":"11838374959","pt":1723494038175,"mc":[{"id":"1.231730206","rc":[{"batb":[[0,2.12,31.05],[1,2.1,560.79],[2,1.95,606]],"ltp":2.1,"tv":71.82,"id":40096580}]}]}
{"op":"mcm","clk":"11838375067","pt":1723494041210,"mc":[{"id":"1.231730206","rc":[{"batb":[[0,2.14,10],[1,2.12,31.05],[2,2.1,560.79]],"ltp":2.1,"tv":71.82,"id":40096580}]}]}
{"op":"mcm","clk":"11838375204","pt":1723494045423,"mc":[{"id":"1.231730206","rc":[{"batb":[[0,2.12,31.05],[1,2.1,560.79],[2,1.95,606]],"ltp":2.1,"tv":71.82,"id":40096580}]}]}
{"op":"mcm","clk":"11838375283","pt":1723494047902,"mc":[{"id":"1.231730206","rc":[{"batb":[[0,2.14,10],[1,2.12,31.05],[2,2.1,560.79]],"ltp":2.1,"tv":71.82,"id":40096580}]}]}
{"op":"mcm","clk":"11838375427","pt":1723494051309,"mc":[{"id":"1.231730206","rc":[{"batb":[[0,2.12,31.05],[1,2.1,560.79],[2,1.95,606]],"ltp":2.1,"tv":71.82,"id":40096580}]}]}
{"op":"mcm","clk":"11838375512","pt":1723494053632,"mc":[{"id":"1.231730206","rc":[{"batb":[[0,2.14,10],[1,2.12,31.05],[2,2.1,560.79]],"ltp":2.1,"tv":71.82,"id":40096580}]}]}
{"op":"mcm","clk":"11838375634","pt":1723494057135,"mc":[{"id":"1.231730206","rc":[{"batb":[[0,2.12,31.05],[1,2.1,560.79],[2,1.95,606]],"ltp":2.1,"tv":71.82,"id":40096580}]}]}
{"op":"mcm","clk":"11838375722","pt":1723494059515,"mc":[{"id":"1.231730206","rc":[{"batb":[[0,2.14,10],[1,2.12,31.05],[2,2.1,560.79]],"ltp":2.1,"tv":71.82,"id":40096580}]}]}
{"op":"mcm","clk":"11838375844","pt":1723494063136,"mc":[{"id":"1.231730206","rc":[{"batb":[[0,2.12,31.05],[1,2.1,560.79],[2,1.95,606]],"ltp":2.1,"tv":71.82,"id":40096580}]}]}
{"op":"mcm","clk":"11838375951","pt":1723494065723,"mc":[{"id":"1.231730206","rc":[{"batb":[[0,2.14,10],[1,2.12,31.05],[2,2.1,560.79]],"ltp":2.1,"tv":71.82,"id":40096580}]}]}
{"op":"mcm","clk":"11838376091","pt":1723494069166,"mc":[{"id":"1.231730206","rc":[{"batb":[[0,2.12,31.05],[1,2.1,560.79],[2,1.95,606]],"ltp":2.1,"tv":71.82,"id":40096580}]}]}
{"op":"mcm","clk":"11838376240","pt":1723494072634,"mc":[{"id":"1.231730206","rc":[{"batb":[[0,2.14,10],[1,2.12,31.05],[2,2.1,560.79]],"ltp":2.1,"tv":71.82,"id":40096580}]}]}
{"op":"mcm","clk":"11838376374","pt":1723494076455,"mc":[{"id":"1.231730206","rc":[{"batb":[[0,2.12,31.05],[1,2.1,560.79],[2,1.95,606]],"ltp":2.1,"tv":71.82,"id":40096580}]}]}
{"op":"mcm","clk":"11838376442","pt":1723494078764,"mc":[{"id":"1.231730206","rc":[{"batb":[[0,2.14,10],[1,2.12,31.05],[2,2.1,560.79]],"ltp":2.1,"tv":71.82,"id":40096580}]}]}
{"op":"mcm","clk":"11838376566","pt":1723494082369,"mc":[{"id":"1.231730206","rc":[{"batb":[[0,2.12,31.05],[1,2.1,560.79],[2,1.95,606]],"ltp":2.1,"tv":71.82,"id":40096580}]}]}
{"op":"mcm","clk":"11838376648","pt":1723494084637,"mc":[{"id":"1.231730206","rc":[{"batb":[[0,2.14,10],[1,2.12,31.05],[2,2.1,560.79]],"ltp":2.1,"tv":71.82,"id":40096580}]}]}
{"op":"mcm","clk":"11838376778","pt":1723494088179,"mc":[{"id":"1.231730206","rc":[{"batb":[[0,2.12,31.05],[1,2.1,560.79],[2,1.95,606]],"ltp":2.1,"tv":71.82,"id":40096580}]}]}
{"op":"mcm","clk":"11838376881","pt":1723494090350,"mc":[{"id":"1.231730206","rc":[{"batb":[[0,2.14,10],[1,2.12,31.05],[2,2.1,560.79]],"ltp":2.1,"tv":71.82,"id":40096580}]}]}
{"op":"mcm","clk":"11838376991","pt":1723494093959,"mc":[{"id":"1.231730206","rc":[{"batb":[[0,2.12,31.05],[1,2.1,560.79],[2,1.95,606]],"ltp":2.1,"tv":71.82,"id":40096580}]}]}
{"op":"mcm","clk":"11838377065","pt":1723494096283,"mc":[{"id":"1.231730206","rc":[{"batb":[[0,2.14,10],[1,2.12,31.05],[2,2.1,560.79]],"ltp":2.1,"tv":71.82,"id":40096580}]}]}
{"op":"mcm","clk":"11838377185","pt":1723494099785,"mc":[{"id":"1.231730206","rc":[{"batb":[[0,2.12,31.05],[1,2.1,560.79],[2,1.95,606]],"ltp":2.1,"tv":71.82,"id":40096580}]}]}
{"op":"mcm","clk":"11838377277","pt":1723494102280,"mc":[{"id":"1.231730206","rc":[{"batb":[[0,2.14,10],[1,2.12,31.05],[2,2.1,560.79]],"ltp":2.1,"tv":71.82,"id":40096580}]}]}
{"op":"mcm","clk":"11838377384","pt":1723494105582,"mc":[{"id":"1.231730206","rc":[{"batb":[[0,2.12,31.05],[1,2.1,560.79],[2,1.95,606]],"ltp":2.1,"tv":71.82,"id":40096580}]}]}
{"op":"mcm","clk":"11838377446","pt":1723494108108,"mc":[{"id":"1.231730206","rc":[{"batb":[[0,2.14,10],[1,2.12,31.05],[2,2.1,560.79]],"ltp":2.1,"tv":71.82,"id":40096580}]}]}
{"op":"mcm","clk":"11838377536","pt":1723494111469,"mc":[{"id":"1.231730206","rc":[{"batb":[[0,2.12,31.05],[1,2.1,560.79],[2,1.95,606]],"ltp":2.1,"tv":71.82,"id":40096580}]}]}
{"op":"mcm","clk":"11838377631","pt":1723494114205,"mc":[{"id":"1.231730206","rc":[{"batb":[[0,2.14,10],[1,2.12,31.05],[2,2.1,560.79]],"ltp":2.1,"tv":71.82,"id":40096580}]}]}
{"op":"mcm","clk":"11838377776","pt":1723494117821,"mc":[{"id":"1.231730206","rc":[{"batb":[[0,2.12,31.05],[1,2.1,560.79],[2,1.95,606]],"ltp":2.1,"tv":71.82,"id":40096580}]}]}
{"op":"mcm","clk":"11838377857","pt":1723494120505,"mc":[{"id":"1.231730206","rc":[{"batb":[[0,2.14,10],[1,2.12,31.05],[2,2.1,560.79]],"ltp":2.1,"tv":71.82,"id":40096580}]}]}
{"op":"mcm","clk":"11838377960","pt":1723494123926,"mc":[{"id":"1.231730206","rc":[{"batb":[[0,2.12,31.05],[1,2.1,560.79],[2,1.95,606]],"ltp":2.1,"tv":71.82,"id":40096580}]}]}
{"op":"mcm","clk":"11838378051","pt":1723494126620,"mc":[{"id":"1.231730206","rc":[{"batb":[[0,2.14,10],[1,2.12,31.05],[2,2.1,560.79]],"ltp":2.1,"tv":71.82,"id":40096580}]}]}
{"op":"mcm","clk":"11838378164","pt":1723494130442,"mc":[{"id":"1.231730206","rc":[{"batb":[[0,2.12,31.05],[1,2.1,560.79],[2,1.95,606]],"ltp":2.1,"tv":71.82,"id":40096580}]}]}
{"op":"mcm","clk":"11838378223","pt":1723494132712,"mc":[{"id":"1.231730206","rc":[{"batb":[[0,2.14,10],[1,2.12,31.05],[2,2.1,560.79]],"ltp":2.1,"tv":71.82,"id":40096580}]}]}
{"op":"mcm","clk":"11838378334","pt":1723494136223,"mc":[{"id":"1.231730206","rc":[{"batb":[[0,2.12,31.05],[1,2.1,560.79],[2,1.95,606]],"ltp":2.1,"tv":71.82,"id":40096580}]}]}
{"op":"mcm","clk":"11838378405","pt":1723494138847,"mc":[{"id":"1.231730206","rc":[{"batb":[[0,2.14,10],[1,2.12,31.05],[2,2.1,560.79]],"ltp":2.1,"tv":71.82,"id":40096580}]}]}
{"op":"mcm","clk":"11838378496","pt":1723494142608,"mc":[{"id":"1.231730206","rc":[{"batb":[[0,2.12,31.05],[1,2.1,560.79],[2,1.95,606]],"ltp":2.1,"tv":71.82,"id":40096580}]}]}
{"op":"mcm","clk":"11838378569","pt":1723494144929,"mc":[{"id":"1.231730206","rc":[{"batb":[[0,2.14,10],[1,2.12,31.05],[2,2.1,560.79]],"ltp":2.1,"tv":71.82,"id":40096580}]}]}
{"op":"mcm","clk":"11838378700","pt":1723494148638,"mc":[{"id":"1.231730206","rc":[{"batb":[[0,2.12,31.05],[1,2.1,560.79],[2,1.95,606]],"ltp":2.1,"tv":71.82,"id":40096580}]}]}
{"op":"mcm","clk":"11838378789","pt":1723494151229,"mc":[{"id":"1.231730206","rc":[{"batb":[[0,2.14,10],[1,2.12,31.05],[2,2.1,560.79]],"ltp":2.1,"tv":71.82,"id":40096580}]}]}
{"op":"mcm","clk":"11838378907","pt":1723494154836,"mc":[{"id":"1.231730206","rc":[{"batb":[[0,2.12,31.05],[1,2.1,560.79],[2,1.95,606]],"ltp":2.1,"tv":71.82,"id":40096580}]}]}
{"op":"mcm","clk":"11838378994","pt":1723494157370,"mc":[{"id":"1.231730206","rc":[{"batb":[[0,2.14,10],[1,2.12,31.05],[2,2.1,560.79]],"ltp":2.1,"tv":71.82,"id":40096580}]}]}
{"op":"mcm","clk":"11838379134","pt":1723494160944,"mc":[{"id":"1.231730206","rc":[{"batb":[[0,2.12,31.05],[1,2.1,560.79],[2,1.95,606]],"ltp":2.1,"tv":71.82,"id":40096580}]}]}
{"op":"mcm","clk":"11838379207","pt":1723494163577,"mc":[{"id":"1.231730206","rc":[{"batb":[[0,2.14,10],[1,2.12,31.05],[2,2.1,560.79]],"ltp":2.1,"tv":71.82,"id":40096580}]}]}
{"op":"mcm","clk":"11838379326","pt":1723494167347,"mc":[{"id":"1.231730206","rc":[{"batb":[[0,2.12,31.05],[1,2.1,560.79],[2,1.95,606]],"ltp":2.1,"tv":71.82,"id":40096580}]}]}
{"op":"mcm","clk":"11838379399","pt":1723494169563,"mc":[{"id":"1.231730206","rc":[{"batb":[[0,2.14,10],[1,2.12,31.05],[2,2.1,560.79]],"ltp":2.1,"tv":71.82,"id":40096580}]}]}
{"op":"mcm","clk":"11838379559","pt":1723494173384,"mc":[{"id":"1.231730206","rc":[{"batb":[[0,2.12,31.05],[1,2.1,560.79],[2,1.95,606]],"ltp":2.1,"tv":71.82,"id":40096580}]}]}
{"op":"mcm","clk":"11838379686","pt":1723494175870,"mc":[{"id":"1.231730206","rc":[{"batb":[[0,2.14,10],[1,2.12,31.05],[2,2.1,560.79]],"ltp":2.1,"tv":71.82,"id":40096580}]}]}
{"op":"mcm","clk":"11838379801","pt":1723494179685,"mc":[{"id":"1.231730206","rc":[{"batb":[[0,2.12,31.05],[1,2.1,560.79],[2,1.95,606]],"ltp":2.1,"tv":71.82,"id":40096580}]}]}
{"op":"mcm","clk":"11838379897","pt":1723494182573,"mc":[{"id":"1.231730206","rc":[{"batb":[[0,2.14,10],[1,2.12,31.05],[2,2.1,560.79]],"ltp":2.1,"tv":71.82,"id":40096580}]}]}
{"op":"mcm","clk":"11838380016","pt":1723494186192,"mc":[{"id":"1.231730206","rc":[{"batb":[[0,2.12,31.05],[1,2.1,560.79],[2,1.95,606]],"ltp":2.1,"tv":71.82,"id":40096580}]}]}
{"op":"mcm","clk":"11838380085","pt":1723494188868,"mc":[{"id":"1.231730206","rc":[{"batb":[[0,2.14,10],[1,2.12,31.05],[2,2.1,560.79]],"ltp":2.1,"tv":71.82,"id":40096580}]}]}
{"op":"mcm","clk":"11838380222","pt":1723494192793,"mc":[{"id":"1.231730206","rc":[{"batb":[[0,2.12,31.05],[1,2.1,560.79],[2,1.95,606]],"ltp":2.1,"tv":71.82,"id":40096580}]}]}
{"op":"mcm","clk":"11838380533","pt":1723494200074,"mc":[{"id":"1.231730206","rc":[{"batb":[[0,2.14,10],[1,2.12,31.05],[2,2.1,560.79]],"ltp":2.1,"tv":71.82,"id":40096580}]}]}
{"op":"mcm","clk":"11838380846","pt":1723494207610,"mc":[{"id":"1.231730206","rc":[{"batb":[[0,2.12,31.05],[1,2.1,560.79],[2,1.95,606]],"ltp":2.1,"tv":71.82,"id":40096580}]}]}
{"op":"mcm","clk":"11838380948","pt":1723494209975,"mc":[{"id":"1.231730206","rc":[{"batb":[[0,2.16,10],[1,2.12,31.05],[2,2.1,560.79]],"ltp":2.1,"tv":71.82,"id":40096580}]}]}
{"op":"mcm","clk":"11838381113","pt":1723494215684,"mc":[{"id":"1.231730206","rc":[{"batb":[[0,2.12,31.05],[1,2.1,560.79],[2,1.95,606]],"ltp":2.1,"tv":71.82,"id":40096580}]}]}
{"op":"mcm","clk":"11838381207","pt":1723494218311,"mc":[{"id":"1.231730206","rc":[{"batb":[[0,2.14,10],[1,2.12,31.05],[2,2.1,560.79]],"ltp":2.1,"tv":71.82,"id":40096580}]}]}
{"op":"mcm","clk":"11838381353","pt":1723494221611,"mc":[{"id":"1.231730206","rc":[{"batb":[[0,2.12,31.05],[1,2.1,560.79],[2,1.95,606]],"ltp":2.1,"tv":71.82,"id":40096580}]}]}
{"op":"mcm","clk":"11838381492","pt":1723494224590,"mc":[{"id":"1.231730206","rc":[{"batb":[[0,2.14,10],[1,2.12,31.05],[2,2.1,560.79]],"ltp":2.1,"tv":71.82,"id":40096580}]}]}
{"op":"mcm","clk":"11838381636","pt":1723494228406,"mc":[{"id":"1.231730206","rc":[{"batb":[[0,2.12,31.05],[1,2.1,560.79],[2,1.95,606]],"ltp":2.1,"tv":71.82,"id":40096580}]}]}
{"op":"mcm","clk":"11838381728","pt":1723494230722,"mc":[{"id":"1.231730206","rc":[{"batb":[[0,2.14,10],[1,2.12,31.05],[2,2.1,560.79]],"ltp":2.1,"tv":71.82,"id":40096580}]}]}
{"op":"mcm","clk":"11838381892","pt":1723494234218,"mc":[{"id":"1.231730206","rc":[{"batb":[[0,2.12,31.05],[1,2.1,560.79],[2,1.95,606]],"ltp":2.1,"tv":71.82,"id":40096580}]}]}
{"op":"mcm","clk":"11838381987","pt":1723494236535,"mc":[{"id":"1.231730206","rc":[{"batb":[[0,2.16,10],[1,2.12,31.05],[2,2.1,560.79]],"ltp":2.1,"tv":71.82,"id":40096580}]}]}
{"op":"mcm","clk":"11838382291","pt":1723494243640,"mc":[{"id":"1.231730206","rc":[{"batb":[[0,2.12,31.05],[1,2.1,560.79],[2,1.95,606]],"ltp":2.1,"tv":71.82,"id":40096580}]}]}
{"op":"mcm","clk":"11838382434","pt":1723494247652,"mc":[{"id":"1.231730206","rc":[{"batb":[[0,2.14,10],[1,2.12,31.05],[2,2.1,560.79]],"ltp":2.1,"tv":71.82,"id":40096580}]}]}
{"op":"mcm","clk":"11838382641","pt":1723494253616,"mc":[{"id":"1.231730206","rc":[{"batb":[[0,2.12,31.05],[1,2.1,560.79],[2,1.95,606]],"ltp":2.1,"tv":71.82,"id":40096580}]}]}
{"op":"mcm","clk":"11838382871","pt":1723494259233,"mc":[{"id":"1.231730206","rc":[{"batb":[[0,2.14,10],[1,2.12,31.05],[2,2.1,560.79]],"ltp":2.1,"tv":71.82,"id":40096580}]}]}
{"op":"mcm","clk":"11838383126","pt":1723494265860,"mc":[{"id":"1.231730206","rc":[{"batb":[[0,2.12,31.05],[1,2.1,560.79],[2,1.95,606]],"ltp":2.1,"tv":71.82,"id":40096580}]}]}
{"op":"mcm","clk":"11838383225","pt":1723494268272,"mc":[{"id":"1.231730206","rc":[{"batb":[[0,2.16,10],[1,2.12,31.05],[2,2.1,560.79]],"ltp":2.1,"tv":71.82,"id":40096580}]}]}
{"op":"mcm","clk":"11838383498","pt":1723494274469,"mc":[{"id":"1.231730206","rc":[{"batb":[[0,2.12,31.05],[1,2.1,560.79],[2,1.95,606]],"ltp":2.1,"tv":71.82,"id":40096580}]}]}
{"op":"mcm","clk":"11838383587","pt":1723494276681,"mc":[{"id":"1.231730206","rc":[{"batb":[[0,2.14,10],[1,2.12,31.05],[2,2.1,560.79]],"ltp":2.1,"tv":71.82,"id":40096580}]}]}
{"op":"mcm","clk":"11838383769","pt":1723494281883,"mc":[{"id":"1.231730206","rc":[{"batb":[[0,2.12,31.05],[1,2.1,560.79],[2,1.95,606]],"ltp":2.1,"tv":71.82,"id":40096580}]}]}
{"op":"mcm","clk":"11838383877","pt":1723494284256,"mc":[{"id":"1.231730206","rc":[{"batb":[[0,2.14,10],[1,2.12,31.05],[2,2.1,560.79]],"ltp":2.1,"tv":71.82,"id":40096580}]}]}
{"op":"mcm","clk":"11838384017","pt":1723494287766,"mc":[{"id":"1.231730206","rc":[{"batb":[[0,2.12,31.05],[1,2.1,560.79],[2,1.95,606]],"ltp":2.1,"tv":71.82,"id":40096580}]}]}
{"op":"mcm","clk":"11838384206","pt":1723494291890,"mc":[{"id":"1.231730206","rc":[{"batb":[[0,2.14,10],[1,2.12,31.05],[2,2.1,560.79]],"ltp":2.1,"tv":71.82,"id":40096580}]}]}
{"op":"mcm","clk":"11838384356","pt":1723494295291,"mc":[{"id":"1.231730206","rc":[{"batb":[[0,2.12,31.05],[1,2.1,560.79],[2,1.95,606]],"ltp":2.1,"tv":71.82,"id":40096580}]}]}
{"op":"mcm","clk":"11838384445","pt":1723494297802,"mc":[{"id":"1.231730206","rc":[{"batb":[[0,2.14,10],[1,2.12,31.05],[2,2.1,560.79]],"ltp":2.1,"tv":71.82,"id":40096580}]}]}
{"op":"mcm","clk":"11838384600","pt":1723494301314,"mc":[{"id":"1.231730206","rc":[{"batb":[[0,2.12,31.05],[1,2.1,560.79],[2,1.95,606]],"ltp":2.1,"tv":71.82,"id":40096580}]}]}
{"op":"mcm","clk":"11838384786","pt":1723494304778,"mc":[{"id":"1.231730206","rc":[{"batb":[[0,2.14,10],[1,2.12,31.05],[2,2.1,560.79]],"ltp":2.1,"tv":71.82,"id":40096580}]}]}
{"op":"mcm","clk":"11838384939","pt":1723494308590,"mc":[{"id":"1.231730206","rc":[{"batb":[[0,2.12,31.05],[1,2.1,560.79],[2,1.95,606]],"ltp":2.1,"tv":71.82,"id":40096580}]}]}
{"op":"mcm","clk":"11838385119","pt":1723494311691,"mc":[{"id":"1.231730206","rc":[{"batb":[[0,2.14,10],[1,2.12,31.05],[2,2.1,560.79]],"ltp":2.1,"tv":71.82,"id":40096580}]}]}
{"op":"mcm","clk":"11838385256","pt":1723494315204,"mc":[{"id":"1.231730206","rc":[{"batb":[[0,2.12,31.05],[1,2.1,560.79],[2,1.95,606]],"ltp":2.1,"tv":71.82,"id":40096580}]}]}
{"op":"mcm","clk":"11838385396","pt":1723494318336,"mc":[{"id":"1.231730206","rc":[{"batb":[[0,2.14,10],[1,2.12,31.05],[2,2.1,560.79]],"ltp":2.1,"tv":71.82,"id":40096580}]}]}
{"op":"mcm","clk":"11838385570","pt":1723494322209,"mc":[{"id":"1.231730206","rc":[{"batb":[[0,2.12,31.05],[1,2.1,560.79],[2,1.95,606]],"ltp":2.1,"tv":71.82,"id":40096580}]}]}
{"op":"mcm","clk":"11838385805","pt":1723494328129,"mc":[{"id":"1.231730206","rc":[{"batb":[[0,2.14,10],[1,2.12,31.05],[2,2.1,560.79]],"ltp":2.1,"tv":71.82,"id":40096580}]}]}
{"op":"mcm","clk":"11838386137","pt":1723494334838,"mc":[{"id":"1.231730206","rc":[{"batb":[[0,2.12,31.05],[1,2.1,560.79],[2,1.95,606]],"ltp":2.1,"tv":71.82,"id":40096580}]}]}
{"op":"mcm","clk":"11838386260","pt":1723494337732,"mc":[{"id":"1.231730206","rc":[{"batb":[[0,2.14,10],[1,2.12,31.05],[2,2.1,560.79]],"ltp":2.1,"tv":71.82,"id":40096580}]}]}
{"op":"mcm","clk":"11838386478","pt":1723494343144,"mc":[{"id":"1.231730206","rc":[{"batb":[[0,2.12,31.05],[1,2.1,560.79],[2,1.95,606]],"ltp":2.1,"tv":71.82,"id":40096580}]}]}
{"op":"mcm","clk":"11838386586","pt":1723494346141,"mc":[{"id":"1.231730206","rc":[{"batb":[[0,2.14,10],[1,2.12,31.05],[2,2.1,560.79]],"ltp":2.1,"tv":71.82,"id":40096580}]}]}
{"op":"mcm","clk":"11838386705","pt":1723494349642,"mc":[{"id":"1.231730206","rc":[{"batb":[[0,2.12,31.05],[1,2.1,560.79],[2,1.95,606]],"ltp":2.1,"tv":71.82,"id":40096580}]}]}
{"op":"mcm","clk":"11838386829","pt":1723494353052,"mc":[{"id":"1.231730206","rc":[{"batb":[[0,2.14,10],[1,2.12,31.05],[2,2.1,560.79]],"ltp":2.1,"tv":71.82,"id":40096580}]}]}
{"op":"mcm","clk":"11838386962","pt":1723494356560,"mc":[{"id":"1.231730206","rc":[{"batb":[[0,2.12,31.05],[1,2.1,560.79],[2,1.95,606]],"ltp":2.1,"tv":71.82,"id":40096580}]}]}
{"op":"mcm","clk":"11838387053","pt":1723494359249,"mc":[{"id":"1.231730206","rc":[{"batb":[[0,2.14,10],[1,2.12,31.05],[2,2.1,560.79]],"ltp":2.1,"tv":71.82,"id":40096580}]}]}
{"op":"mcm","clk":"11838387178","pt":1723494362650,"mc":[{"id":"1.231730206","rc":[{"batb":[[0,2.12,31.05],[1,2.1,560.79],[2,1.95,606]],"ltp":2.1,"tv":71.82,"id":40096580}]}]}
{"op":"mcm","clk":"11838387280","pt":1723494365375,"mc":[{"id":"1.231730206","rc":[{"batb":[[0,2.14,10],[1,2.12,31.05],[2,2.1,560.79]],"ltp":2.1,"tv":71.82,"id":40096580}]}]}
{"op":"mcm","clk":"11838387411","pt":1723494368777,"mc":[{"id":"1.231730206","rc":[{"batb":[[0,2.12,31.05],[1,2.1,560.79],[2,1.95,606]],"ltp":2.1,"tv":71.82,"id":40096580}]}]}
{"op":"mcm","clk":"11838387521","pt":1723494371361,"mc":[{"id":"1.231730206","rc":[{"batb":[[0,2.14,10],[1,2.12,31.05],[2,2.1,560.79]],"ltp":2.1,"tv":71.82,"id":40096580}]}]}
{"op":"mcm","clk":"11838387628","pt":1723494374796,"mc":[{"id":"1.231730206","rc":[{"batb":[[0,2.12,31.05],[1,2.1,560.79],[2,1.95,606]],"ltp":2.1,"tv":71.82,"id":40096580}]}]}
{"op":"mcm","clk":"11838387717","pt":1723494377483,"mc":[{"id":"1.231730206","rc":[{"batb":[[0,2.14,10],[1,2.12,31.05],[2,2.1,560.79]],"ltp":2.1,"tv":71.82,"id":40096580}]}]}
{"op":"mcm","clk":"11838387856","pt":1723494380777,"mc":[{"id":"1.231730206","rc":[{"batb":[[0,2.12,31.05],[1,2.1,560.79],[2,1.95,606]],"ltp":2.1,"tv":71.82,"id":40096580}]}]}
{"op":"mcm","clk":"11838387952","pt":1723494383605,"mc":[{"id":"1.231730206","rc":[{"batb":[[0,2.14,10],[1,2.12,31.05],[2,2.1,560.79]],"ltp":2.1,"tv":71.82,"id":40096580}]}]}
{"op":"mcm","clk":"11838388089","pt":1723494387105,"mc":[{"id":"1.231730206","rc":[{"batb":[[0,2.12,31.05],[1,2.1,560.79],[2,1.95,606]],"ltp":2.1,"tv":71.82,"id":40096580}]}]}
{"op":"mcm","clk":"11838388196","pt":1723494389689,"mc":[{"id":"1.231730206","rc":[{"batb":[[0,2.14,10],[1,2.12,31.05],[2,2.1,560.79]],"ltp":2.1,"tv":71.82,"id":40096580}]}]}
{"op":"mcm","clk":"11838388315","pt":1723494393000,"mc":[{"id":"1.231730206","rc":[{"batb":[[0,2.12,31.05],[1,2.1,560.79],[2,1.95,606]],"ltp":2.1,"tv":71.82,"id":40096580}]}]}
{"op":"mcm","clk":"11838388414","pt":1723494395581,"mc":[{"id":"1.231730206","rc":[{"batb":[[0,2.14,10],[1,2.12,31.05],[2,2.1,560.79]],"ltp":2.1,"tv":71.82,"id":40096580}]}]}
{"op":"mcm","clk":"11838388527","pt":1723494399023,"mc":[{"id":"1.231730206","rc":[{"batb":[[0,2.12,31.05],[1,2.1,560.79],[2,1.95,606]],"ltp":2.1,"tv":71.82,"id":40096580}]}]}
{"op":"mcm","clk":"11838388632","pt":1723494401909,"mc":[{"id":"1.231730206","rc":[{"batb":[[0,2.14,10],[1,2.12,31.05],[2,2.1,560.79]],"ltp":2.1,"tv":71.82,"id":40096580}]}]}
{"op":"mcm","clk":"11838388766","pt":1723494405210,"mc":[{"id":"1.231730206","rc":[{"batb":[[0,2.12,31.05],[1,2.1,560.79],[2,1.95,606]],"ltp":2.1,"tv":71.82,"id":40096580}]}]}
{"op":"mcm","clk":"11838388871","pt":1723494407831,"mc":[{"id":"1.231730206","rc":[{"batb":[[0,2.14,10],[1,2.12,31.05],[2,2.1,560.79]],"ltp":2.1,"tv":71.82,"id":40096580}]}]}
{"op":"mcm","clk":"11838388980","pt":1723494411125,"mc":[{"id":"1.231730206","rc":[{"batb":[[0,2.12,31.05],[1,2.1,560.79],[2,1.95,606]],"ltp":2.1,"tv":71.82,"id":40096580}]}]}
{"op":"mcm","clk":"11838389059","pt":1723494413846,"mc":[{"id":"1.231730206","rc":[{"batb":[[0,2.14,10],[1,2.12,31.05],[2,2.1,560.79]],"ltp":2.1,"tv":71.82,"id":40096580}]}]}
{"op":"mcm","clk":"11838389166","pt":1723494417313,"mc":[{"id":"1.231730206","rc":[{"batb":[[0,2.12,31.05],[1,2.1,560.79],[2,1.95,606]],"ltp":2.1,"tv":71.82,"id":40096580}]}]}
{"op":"mcm","clk":"11838389287","pt":1723494419950,"mc":[{"id":"1.231730206","rc":[{"batb":[[0,2.14,10],[1,2.12,31.05],[2,2.1,560.79]],"ltp":2.1,"tv":71.82,"id":40096580}]}]}
{"op":"mcm","clk":"11838389475","pt":1723494423748,"mc":[{"id":"1.231730206","rc":[{"batb":[[0,2.12,31.05],[1,2.1,560.79],[2,1.95,606]],"ltp":2.1,"tv":71.82,"id":40096580}]}]}
{"op":"mcm","clk":"11838389570","pt":1723494426133,"mc":[{"id":"1.231730206","rc":[{"batb":[[0,2.14,10],[1,2.12,31.05],[2,2.1,560.79]],"ltp":2.1,"tv":71.82,"id":40096580}]}]}
{"op":"mcm","clk":"11838389715","pt":1723494430147,"mc":[{"id":"1.231730206","rc":[{"batb":[[0,2.12,31.05],[1,2.1,560.79],[2,1.95,606]],"ltp":2.1,"tv":71.82,"id":40096580}]}]}
{"op":"mcm","clk":"11838389787","pt":1723494432362,"mc":[{"id":"1.231730206","rc":[{"batb":[[0,2.14,10],[1,2.12,31.05],[2,2.1,560.79]],"ltp":2.1,"tv":71.82,"id":40096580}]}]}
{"op":"mcm","clk":"11838389899","pt":1723494435965,"mc":[{"id":"1.231730206","rc":[{"batb":[[0,2.12,31.05],[1,2.1,560.79],[2,1.95,606]],"ltp":2.1,"tv":71.82,"id":40096580}]}]}
{"op":"mcm","clk":"11838390000","pt":1723494438542,"mc":[{"id":"1.231730206","rc":[{"batb":[[0,2.14,10],[1,2.12,31.05],[2,2.1,560.79]],"ltp":2.1,"tv":71.82,"id":40096580}]}]}
{"op":"mcm","clk":"11838390146","pt":1723494442351,"mc":[{"id":"1.231730206","rc":[{"batb":[[0,2.12,31.05],[1,2.1,560.79],[2,1.95,606]],"ltp":2.1,"tv":71.82,"id":40096580}]}]}
{"op":"mcm","clk":"11838390259","pt":1723494445445,"mc":[{"id":"1.231730206","rc":[{"batb":[[0,2.14,10],[1,2.12,31.05],[2,2.1,560.79]],"ltp":2.1,"tv":71.82,"id":40096580}]}]}
{"op":"mcm","clk":"11838390427","pt":1723494449254,"mc":[{"id":"1.231730206","rc":[{"batb":[[0,2.12,31.05],[1,2.1,560.79],[2,1.95,606]],"ltp":2.1,"tv":71.82,"id":40096580}]}]}
{"op":"mcm","clk":"11838390573","pt":1723494452961,"mc":[{"id":"1.231730206","rc":[{"batb":[[0,2.14,10],[1,2.12,31.05],[2,2.1,560.79]],"ltp":2.1,"tv":71.82,"id":40096580}]}]}
{"op":"mcm","clk":"11838390710","pt":1723494456667,"mc":[{"id":"1.231730206","rc":[{"batb":[[0,2.12,31.05],[1,2.1,560.79],[2,1.95,606]],"ltp":2.1,"tv":71.82,"id":40096580}]}]}
{"op":"mcm","clk":"11838390795","pt":1723494459081,"mc":[{"id":"1.231730206","rc":[{"batb":[[0,2.14,10],[1,2.12,31.05],[2,2.1,560.79]],"ltp":2.1,"tv":71.82,"id":40096580}]}]}
{"op":"mcm","clk":"11838390907","pt":1723494462573,"mc":[{"id":"1.231730206","rc":[{"batb":[[0,2.12,31.05],[1,2.1,560.79],[2,1.95,606]],"ltp":2.1,"tv":71.82,"id":40096580}]}]}
{"op":"mcm","clk":"11838391019","pt":1723494465463,"mc":[{"id":"1.231730206","rc":[{"batb":[[0,2.14,10],[1,2.12,31.05],[2,2.1,560.79]],"ltp":2.1,"tv":71.82,"id":40096580}]}]}
{"op":"mcm","clk":"11838391137","pt":1723494468966,"mc":[{"id":"1.231730206","rc":[{"batb":[[0,2.12,31.05],[1,2.1,560.79],[2,1.95,606]],"ltp":2.1,"tv":71.82,"id":40096580}]}]}
{"op":"mcm","clk":"11838391214","pt":1723494471566,"mc":[{"id":"1.231730206","rc":[{"batb":[[0,2.14,10],[1,2.12,31.05],[2,2.1,560.79]],"ltp":2.1,"tv":71.82,"id":40096580}]}]}
{"op":"mcm","clk":"11838391324","pt":1723494474965,"mc":[{"id":"1.231730206","rc":[{"batb":[[0,2.12,31.05],[1,2.1,560.79],[2,1.95,606]],"ltp":2.1,"tv":71.82,"id":40096580}]}]}
{"op":"mcm","clk":"11838391414","pt":1723494477796,"mc":[{"id":"1.231730206","rc":[{"batb":[[0,2.14,10],[1,2.12,31.05],[2,2.1,560.79]],"ltp":2.1,"tv":71.82,"id":40096580}]}]}
{"op":"mcm","clk":"11838391535","pt":1723494481315,"mc":[{"id":"1.231730206","rc":[{"batb":[[0,2.12,31.05],[1,2.1,560.79],[2,1.95,606]],"ltp":2.1,"tv":71.82,"id":40096580}]}]}
{"op":"mcm","clk":"11838391633","pt":1723494483885,"mc":[{"id":"1.231730206","rc":[{"batb":[[0,2.14,10],[1,2.12,31.05],[2,2.1,560.79]],"ltp":2.1,"tv":71.82,"id":40096580}]}]}
{"op":"mcm","clk":"11838391780","pt":1723494487382,"mc":[{"id":"1.231730206","rc":[{"batb":[[0,2.12,31.05],[1,2.1,560.79],[2,1.95,606]],"ltp":2.1,"tv":71.82,"id":40096580}]}]}
{"op":"mcm","clk":"11838391929","pt":1723494490419,"mc":[{"id":"1.231730206","rc":[{"batb":[[0,2.14,10],[1,2.12,31.05],[2,2.1,560.79]],"ltp":2.1,"tv":71.82,"id":40096580}]}]}
{"op":"mcm","clk":"11838392178","pt":1723494498404,"mc":[{"id":"1.231730206","rc":[{"batb":[[0,2.12,31.05],[1,2.1,560.79],[2,1.95,606]],"ltp":2.1,"tv":71.82,"id":40096580}]}]}
{"op":"mcm","clk":"11838392266","pt":1723494500928,"mc":[{"id":"1.231730206","rc":[{"batb":[[0,2.14,10],[1,2.12,31.05],[2,2.1,560.79]],"ltp":2.1,"tv":71.82,"id":40096580}]}]}
{"op":"mcm","clk":"11838392436","pt":1723494506438,"mc":[{"id":"1.231730206","rc":[{"batb":[[0,2.12,31.05],[1,2.1,560.79],[2,1.95,606]],"ltp":2.1,"tv":71.82,"id":40096580}]}]}
{"op":"mcm","clk":"11838392533","pt":1723494509515,"mc":[{"id":"1.231730206","rc":[{"batb":[[0,2.14,10],[1,2.12,31.05],[2,2.1,560.79]],"ltp":2.1,"tv":71.82,"id":40096580}]}]}
{"op":"mcm","clk":"11838392655","pt":1723494513015,"mc":[{"id":"1.231730206","rc":[{"batb":[[0,2.12,31.05],[1,2.1,560.79],[2,1.95,606]],"ltp":2.1,"tv":71.82,"id":40096580}]}]}
{"op":"mcm","clk":"11838392810","pt":1723494516617,"mc":[{"id":"1.231730206","rc":[{"batb":[[0,2.14,10],[1,2.12,31.05],[2,2.1,560.79]],"ltp":2.1,"tv":71.82,"id":40096580}]}]}
{"op":"mcm","clk":"11838392920","pt":1723494519816,"mc":[{"id":"1.231730206","rc":[{"batb":[[0,2.12,31.05],[1,2.1,560.79],[2,1.95,606]],"ltp":2.1,"tv":71.82,"id":40096580}]}]}
{"op":"mcm","clk":"11838392983","pt":1723494522024,"mc":[{"id":"1.231730206","rc":[{"batb":[[0,2.14,10],[1,2.12,31.05],[2,2.1,560.79]],"ltp":2.1,"tv":71.82,"id":40096580}]}]}
{"op":"mcm","clk":"11838393118","pt":1723494525424,"mc":[{"id":"1.231730206","rc":[{"batb":[[0,2.12,31.05],[1,2.1,560.79],[2,1.95,606]],"ltp":2.1,"tv":71.82,"id":40096580}]}]}
{"op":"mcm","clk":"11838393234","pt":1723494528445,"mc":[{"id":"1.231730206","rc":[{"batb":[[0,2.14,10],[1,2.12,31.05],[2,2.1,560.79]],"ltp":2.1,"tv":71.82,"id":40096580}]}]}
{"op":"mcm","clk":"11838393369","pt":1723494532039,"mc":[{"id":"1.231730206","rc":[{"batb":[[0,2.12,31.05],[1,2.1,560.79],[2,1.95,606]],"ltp":2.1,"tv":71.82,"id":40096580}]}]}
{"op":"mcm","clk":"11838393497","pt":1723494535642,"mc":[{"id":"1.231730206","rc":[{"batb":[[0,2.14,10],[1,2.12,31.05],[2,2.1,560.79]],"ltp":2.1,"tv":71.82,"id":40096580}]}]}
{"op":"mcm","clk":"11838393614","pt":1723494539447,"mc":[{"id":"1.231730206","rc":[{"batb":[[0,2.12,31.05],[1,2.1,560.79],[2,1.95,606]],"ltp":2.1,"tv":71.82,"id":40096580}]}]}
{"op":"mcm","clk":"11838393727","pt":1723494542745,"mc":[{"id":"1.231730206","rc":[{"batb":[[0,2.14,10],[1,2.12,31.05],[2,2.1,560.79]],"ltp":2.1,"tv":71.82,"id":40096580}]}]}
{"op":"mcm","clk":"11838393866","pt":1723494546349,"mc":[{"id":"1.231730206","rc":[{"batb":[[0,2.12,31.05],[1,2.1,560.79],[2,1.95,606]],"ltp":2.1,"tv":71.82,"id":40096580}]}]}
{"op":"mcm","clk":"11838393980","pt":1723494549361,"mc":[{"id":"1.231730206","rc":[{"batb":[[0,2.14,10],[1,2.12,31.05],[2,2.1,560.79]],"ltp":2.1,"tv":71.82,"id":40096580}]}]}
{"op":"mcm","clk":"11838394119","pt":1723494553266,"mc":[{"id":"1.231730206","rc":[{"batb":[[0,2.12,31.05],[1,2.1,560.79],[2,1.95,606]],"ltp":2.1,"tv":71.82,"id":40096580}]}]}
{"op":"mcm","clk":"11838394214","pt":1723494556048,"mc":[{"id":"1.231730206","rc":[{"batb":[[0,2.14,10],[1,2.12,31.05],[2,2.1,560.79]],"ltp":2.1,"tv":71.82,"id":40096580}]}]}
{"op":"mcm","clk":"11838394324","pt":1723494559652,"mc":[{"id":"1.231730206","rc":[{"batb":[[0,2.12,31.05],[1,2.1,560.79],[2,1.95,606]],"ltp":2.1,"tv":71.82,"id":40096580}]}]}
{"op":"mcm","clk":"11838394406","pt":1723494561961,"mc":[{"id":"1.231730206","rc":[{"batb":[[0,2.14,10],[1,2.12,31.05],[2,2.1,560.79]],"ltp":2.1,"tv":71.82,"id":40096580}]}]}
{"op":"mcm","clk":"11838394531","pt":1723494565460,"mc":[{"id":"1.231730206","rc":[{"batb":[[0,2.12,31.05],[1,2.1,560.79],[2,1.95,606]],"ltp":2.1,"tv":71.82,"id":40096580}]}]}
{"op":"mcm","clk":"11838394635","pt":1723494568559,"mc":[{"id":"1.231730206","rc":[{"batb":[[0,2.14,10],[1,2.12,31.05],[2,2.1,560.79]],"ltp":2.1,"tv":71.82,"id":40096580}]}]}
{"op":"mcm","clk":"11838394762","pt":1723494572062,"mc":[{"id":"1.231730206","rc":[{"batb":[[0,2.12,31.05],[1,2.1,560.79],[2,1.95,606]],"ltp":2.1,"tv":71.82,"id":40096580}]}]}
{"op":"mcm","clk":"11838394865","pt":1723494574783,"mc":[{"id":"1.231730206","rc":[{"batb":[[0,2.14,10],[1,2.12,31.05],[2,2.1,560.79]],"ltp":2.1,"tv":71.82,"id":40096580}]}]}
{"op":"mcm","clk":"11838394986","pt":1723494578178,"mc":[{"id":"1.231730206","rc":[{"batb":[[0,2.12,31.05],[1,2.1,560.79],[2,1.95,606]],"ltp":2.1,"tv":71.82,"id":40096580}]}]}
{"op":"mcm","clk":"11838395078","pt":1723494580862,"mc":[{"id":"1.231730206","rc":[{"batb":[[0,2.14,10],[1,2.12,31.05],[2,2.1,560.79]],"ltp":2.1,"tv":71.82,"id":40096580}]}]}
{"op":"mcm","clk":"11838395202","pt":1723494584398,"mc":[{"id":"1.231730206","rc":[{"batb":[[0,2.12,31.05],[1,2.1,560.79],[2,1.95,606]],"ltp":2.1,"tv":71.82,"id":40096580}]}]}
{"op":"mcm","clk":"11838395335","pt":1723494587813,"mc":[{"id":"1.231730206","rc":[{"batb":[[0,2.14,10],[1,2.12,31.05],[2,2.1,560.79]],"ltp":2.1,"tv":71.82,"id":40096580}]}]}
{"op":"mcm","clk":"11838395460","pt":1723494590475,"mc":[{"id":"1.231730206","rc":[{"batb":[[0,2.14,570.79],[2,1.95,606]],"ltp":2.1,"tv":71.82,"id":40096580}]}]}
{"op":"mcm","clk":"11838395534","pt":1723494592073,"mc":[{"id":"1.231730206","rc":[{"batb":[[0,2.14,560.79],[1,1.95,606],[2,1.85,444]],"ltp":2.1,"tv":71.82,"id":40096580},{"batl":[[0,1.87,4.67],[1,1.9,0]],"ltp":1.87,"tv":1295.59,"id":40096582}]}]}
{"op":"mcm","clk":"11838395546","pt":1723494592281,"mc":[{"id":"1.231730206","rc":[{"batl":[[0,1.87,11.81]],"ltp":1.87,"tv":1295.59,"id":40096582}]}]}
{"op":"mcm","clk":"11838395654","pt":1723494594712,"mc":[{"id":"1.231730206","rc":[{"batb":[[0,2.16,10],[1,2.14,560.79],[2,1.95,606]],"ltp":2.1,"tv":71.82,"id":40096580}]}]}
{"op":"mcm","clk":"11838395839","pt":1723494598480,"mc":[{"id":"1.231730206","rc":[{"batb":[[0,2.14,560.79],[1,1.95,606],[2,1.85,444]],"ltp":2.1,"tv":71.82,"id":40096580}]}]}
{"op":"mcm","clk":"11838396035","pt":1723494602216,"mc":[{"id":"1.231730206","rc":[{"batb":[[0,2.16,10],[1,2.14,560.79],[2,1.95,606]],"ltp":2.1,"tv":71.82,"id":40096580}]}]}
{"op":"mcm","clk":"11838396427","pt":1723494609707,"mc":[{"id":"1.231730206","rc":[{"batb":[[0,2.14,560.79],[1,1.95,606],[2,1.85,444]],"ltp":2.1,"tv":71.82,"id":40096580}]}]}
{"op":"mcm","clk":"11838396600","pt":1723494613102,"mc":[{"id":"1.231730206","rc":[{"batb":[[0,2.16,10],[1,2.14,560.79],[2,1.95,606]],"ltp":2.1,"tv":71.82,"id":40096580}]}]}
{"op":"mcm","clk":"11838396812","pt":1723494618499,"mc":[{"id":"1.231730206","rc":[{"batb":[[0,2.14,560.79],[1,1.95,606],[2,1.85,444]],"ltp":2.1,"tv":71.82,"id":40096580}]}]}
{"op":"mcm","clk":"11838396963","pt":1723494622206,"mc":[{"id":"1.231730206","rc":[{"batb":[[0,2.16,10],[1,2.14,560.79],[2,1.95,606]],"ltp":2.1,"tv":71.82,"id":40096580},{"batl":[[0,1.87,28.93]],"ltp":1.87,"tv":1295.59,"id":40096582}]}]}
{"op":"mcm","clk":"11838397080","pt":1723494624835,"mc":[{"id":"1.231730206","rc":[{"batb":[[0,2.14,560.79],[1,1.95,606],[2,1.85,444]],"ltp":2.1,"tv":71.82,"id":40096580}]}]}
{"op":"mcm","clk":"11838397239","pt":1723494628423,"mc":[{"id":"1.231730206","rc":[{"batb":[[0,2.16,10],[1,2.14,560.79],[2,1.95,606]],"ltp":2.1,"tv":71.82,"id":40096580}]}]}
{"op":"mcm","clk":"11838397380","pt":1723494632125,"mc":[{"id":"1.231730206","rc":[{"batb":[[0,2.14,560.79],[1,1.95,606],[2,1.85,444]],"ltp":2.1,"tv":71.82,"id":40096580}]}]}
{"op":"mcm","clk":"11838397480","pt":1723494634438,"mc":[{"id":"1.231730206","rc":[{"batb":[[0,2.16,10],[1,2.14,560.79],[2,1.95,606]],"ltp":2.1,"tv":71.82,"id":40096580}]}]}
{"op":"mcm","clk":"11838397627","pt":1723494638039,"mc":[{"id":"1.231730206","rc":[{"batb":[[0,2.14,560.79],[1,1.95,606],[2,1.85,444]],"ltp":2.1,"tv":71.82,"id":40096580}]}]}
{"op":"mcm","clk":"11838397742","pt":1723494640511,"mc":[{"id":"1.231730206","rc":[{"batb":[[0,2.16,10],[1,2.14,560.79],[2,1.95,606]],"ltp":2.1,"tv":71.82,"id":40096580}]}]}
{"op":"mcm","clk":"11838397874","pt":1723494644152,"mc":[{"id":"1.231730206","rc":[{"batb":[[0,2.14,560.79],[1,1.95,606],[2,1.85,444]],"ltp":2.1,"tv":71.82,"id":40096580}]}]}
{"op":"mcm","clk":"11838397978","pt":1723494646938,"mc":[{"id":"1.231730206","rc":[{"batb":[[0,2.16,10],[1,2.14,560.79],[2,1.95,606]],"ltp":2.1,"tv":71.82,"id":40096580}]}]}
{"op":"mcm","clk":"11838398127","pt":1723494650737,"mc":[{"id":"1.231730206","rc":[{"batb":[[0,2.14,560.79],[1,1.95,606],[2,1.85,444]],"ltp":2.1,"tv":71.82,"id":40096580}]}]}
{"op":"mcm","clk":"11838398252","pt":1723494654124,"mc":[{"id":"1.231730206","rc":[{"batb":[[0,2.16,10],[1,2.14,560.79],[2,1.95,606]],"ltp":2.1,"tv":71.82,"id":40096580}]}]}
{"op":"mcm","clk":"11838398380","pt":1723494657738,"mc":[{"id":"1.231730206","rc":[{"batb":[[0,2.14,560.79],[1,1.95,606],[2,1.85,444]],"ltp":2.1,"tv":71.82,"id":40096580}]}]}
{"op":"mcm","clk":"11838398469","pt":1723494660048,"mc":[{"id":"1.231730206","rc":[{"batb":[[0,2.16,10],[1,2.14,560.79],[2,1.95,606]],"ltp":2.1,"tv":71.82,"id":40096580}]}]}
{"op":"mcm","clk":"11838398619","pt":1723494663656,"mc":[{"id":"1.231730206","rc":[{"batb":[[0,2.14,560.79],[1,1.95,606],[2,1.85,444]],"ltp":2.1,"tv":71.82,"id":40096580}]}]}
{"op":"mcm","clk":"11838398743","pt":1723494666172,"mc":[{"id":"1.231730206","rc":[{"batb":[[0,2.16,10],[1,2.14,560.79],[2,1.95,606]],"ltp":2.1,"tv":71.82,"id":40096580}]}]}
{"op":"mcm","clk":"11838398906","pt":1723494669834,"mc":[{"id":"1.231730206","rc":[{"batb":[[0,2.14,560.79],[1,1.95,606],[2,1.85,444]],"ltp":2.1,"tv":71.82,"id":40096580}]}]}
{"op":"mcm","clk":"11838399005","pt":1723494672067,"mc":[{"id":"1.231730206","rc":[{"batb":[[0,2.16,10],[1,2.14,560.79],[2,1.95,606]],"ltp":2.1,"tv":71.82,"id":40096580}]}]}
{"op":"mcm","clk":"11838399163","pt":1723494675681,"mc":[{"id":"1.231730206","rc":[{"batb":[[0,2.14,560.79],[1,1.95,606],[2,1.85,444]],"ltp":2.1,"tv":71.82,"id":40096580}]}]}
{"op":"mcm","clk":"11838399262","pt":1723494678157,"mc":[{"id":"1.231730206","rc":[{"batb":[[0,2.16,10],[1,2.14,560.79],[2,1.95,606]],"ltp":2.1,"tv":71.82,"id":40096580}]}]}
{"op":"mcm","clk":"11838399415","pt":1723494681983,"mc":[{"id":"1.231730206","rc":[{"batb":[[0,2.14,560.79],[1,1.95,606],[2,1.85,444]],"ltp":2.1,"tv":71.82,"id":40096580}]}]}
{"op":"mcm","clk":"11838399512","pt":1723494684352,"mc":[{"id":"1.231730206","rc":[{"batb":[[0,2.16,10],[1,2.14,560.79],[2,1.95,606]],"ltp":2.1,"tv":71.82,"id":40096580}]}]}
{"op":"mcm","clk":"11838399668","pt":1723494688056,"mc":[{"id":"1.231730206","rc":[{"batb":[[0,2.14,560.79],[1,1.95,606],[2,1.85,444]],"ltp":2.1,"tv":71.82,"id":40096580}]}]}
{"op":"mcm","clk":"11838399770","pt":1723494690480,"mc":[{"id":"1.231730206","rc":[{"batb":[[0,2.16,10],[1,2.14,560.79],[2,1.95,606]],"ltp":2.1,"tv":71.82,"id":40096580}]}]}
{"op":"mcm","clk":"11838399884","pt":1723494693886,"mc":[{"id":"1.231730206","rc":[{"batb":[[0,2.14,560.79],[1,1.95,606],[2,1.85,444]],"ltp":2.1,"tv":71.82,"id":40096580}]}]}
{"op":"mcm","clk":"11838400006","pt":1723494696504,"mc":[{"id":"1.231730206","rc":[{"batb":[[0,2.16,10],[1,2.14,560.79],[2,1.95,606]],"ltp":2.1,"tv":71.82,"id":40096580}]}]}
{"op":"mcm","clk":"11838400165","pt":1723494700005,"mc":[{"id":"1.231730206","rc":[{"batb":[[0,2.14,560.79],[1,1.95,606],[2,1.85,444]],"ltp":2.1,"tv":71.82,"id":40096580}]}]}
{"op":"mcm","clk":"11838400289","pt":1723494702530,"mc":[{"id":"1.231730206","rc":[{"batb":[[0,2.16,10],[1,2.14,560.79],[2,1.95,606]],"ltp":2.1,"tv":71.82,"id":40096580}]}]}
{"op":"mcm","clk":"11838400454","pt":1723494706085,"mc":[{"id":"1.231730206","rc":[{"batb":[[0,2.14,560.79],[1,1.95,606],[2,1.85,444]],"ltp":2.1,"tv":71.82,"id":40096580}]}]}
{"op":"mcm","clk":"11838400756","pt":1723494713903,"mc":[{"id":"1.231730206","rc":[{"batb":[[0,2.16,10],[1,2.14,560.79],[2,1.95,606]],"ltp":2.1,"tv":71.82,"id":40096580}]}]}
{"op":"mcm","clk":"11838401010","pt":1723494718198,"mc":[{"id":"1.231730206","rc":[{"batb":[[0,2.14,560.79],[1,1.95,606],[2,1.85,444]],"ltp":2.1,"tv":71.82,"id":40096580}]}]}
{"op":"mcm","clk":"11838401352","pt":1723494725709,"mc":[{"id":"1.231730206","rc":[{"batb":[[0,2.16,10],[1,2.14,560.79],[2,1.95,606]],"ltp":2.1,"tv":71.82,"id":40096580}]}]}
{"op":"mcm","clk":"11838401911","pt":1723494738633,"mc":[{"id":"1.231730206","rc":[{"batb":[[0,2.14,560.79],[1,1.95,606],[2,1.85,444]],"ltp":2.1,"tv":71.82,"id":40096580}]}]}
{"op":"mcm","clk":"11838402088","pt":1723494743628,"mc":[{"id":"1.231730206","rc":[{"batb":[[0,2.16,10],[1,2.14,560.79],[2,1.95,606]],"ltp":2.1,"tv":71.82,"id":40096580}]}]}
{"op":"mcm","clk":"11838402375","pt":1723494750539,"mc":[{"id":"1.231730206","rc":[{"batb":[[0,2.14,560.79],[1,1.95,606],[2,1.85,444]],"ltp":2.1,"tv":71.82,"id":40096580}]}]}
{"op":"mcm","clk":"11838402528","pt":1723494753749,"mc":[{"id":"1.231730206","rc":[{"batb":[[0,2.16,10],[1,2.14,560.79],[2,1.95,606]],"ltp":2.1,"tv":71.82,"id":40096580}]}]}
{"op":"mcm","clk":"11838402746","pt":1723494758037,"mc":[{"id":"1.231730206","rc":[{"batb":[[0,2.14,560.79],[1,1.95,606],[2,1.85,444]],"ltp":2.1,"tv":71.82,"id":40096580}]}]}
{"op":"mcm","clk":"11838402855","pt":1723494760759,"mc":[{"id":"1.231730206","rc":[{"batb":[[0,2.16,10],[1,2.14,560.79],[2,1.95,606]],"ltp":2.1,"tv":71.82,"id":40096580}]}]}
{"op":"mcm","clk":"11838402993","pt":1723494764367,"mc":[{"id":"1.231730206","rc":[{"batb":[[0,2.14,560.79],[1,1.95,606],[2,1.85,444]],"ltp":2.1,"tv":71.82,"id":40096580}]}]}
{"op":"mcm","clk":"11838403211","pt":1723494769986,"mc":[{"id":"1.231730206","rc":[{"batb":[[0,2.16,10],[1,2.14,560.79],[2,1.95,606]],"ltp":2.1,"tv":71.82,"id":40096580}]}]}
{"op":"mcm","clk":"11838403472","pt":1723494775901,"mc":[{"id":"1.231730206","rc":[{"batb":[[0,2.14,560.79],[1,1.95,606],[2,1.85,444]],"ltp":2.1,"tv":71.82,"id":40096580}]}]}
{"op":"mcm","clk":"11838403584","pt":1723494778482,"mc":[{"id":"1.231730206","rc":[{"batb":[[0,2.16,10],[1,2.14,560.79],[2,1.95,606]],"ltp":2.1,"tv":71.82,"id":40096580}]}]}
{"op":"mcm","clk":"11838403814","pt":1723494783882,"mc":[{"id":"1.231730206","rc":[{"batb":[[0,2.14,560.79],[1,1.95,606],[2,1.85,444]],"ltp":2.1,"tv":71.82,"id":40096580}]}]}
{"op":"mcm","clk":"11838403961","pt":1723494787503,"mc":[{"id":"1.231730206","rc":[{"batb":[[0,2.16,10],[1,2.14,560.79],[2,1.95,606]],"ltp":2.1,"tv":71.82,"id":40096580}]}]}
{"op":"mcm","clk":"11838404106","pt":1723494791304,"mc":[{"id":"1.231730206","rc":[{"batb":[[0,2.14,560.79],[1,1.95,606],[2,1.85,444]],"ltp":2.1,"tv":71.82,"id":40096580}]}]}
{"op":"mcm","clk":"11838404278","pt":1723494795585,"mc":[{"id":"1.231730206","rc":[{"batb":[[0,2.16,10],[1,2.14,560.79],[2,1.95,606]],"ltp":2.1,"tv":71.82,"id":40096580}]}]}
{"op":"mcm","clk":"11838404427","pt":1723494798884,"mc":[{"id":"1.231730206","rc":[{"batb":[[0,2.14,560.79],[1,1.95,606],[2,1.85,444]],"ltp":2.1,"tv":71.82,"id":40096580}]}]}
{"op":"mcm","clk":"11838404568","pt":1723494801918,"mc":[{"id":"1.231730206","rc":[{"batb":[[0,2.16,10],[1,2.14,560.79],[2,1.95,606]],"ltp":2.1,"tv":71.82,"id":40096580}]}]}
{"op":"mcm","clk":"11838404770","pt":1723494805687,"mc":[{"id":"1.231730206","rc":[{"batb":[[0,2.14,560.79],[1,1.95,606],[2,1.85,444]],"ltp":2.1,"tv":71.82,"id":40096580}]}]}
{"op":"mcm","clk":"11838405000","pt":1723494809017,"mc":[{"id":"1.231730206","rc":[{"batb":[[0,2.16,10],[1,2.14,560.79],[2,1.95,606]],"ltp":2.1,"tv":71.82,"id":40096580}]}]}
{"op":"mcm","clk":"11838405265","pt":1723494812620,"mc":[{"id":"1.231730206","rc":[{"batb":[[0,2.14,560.79],[1,1.95,606],[2,1.85,444]],"ltp":2.1,"tv":71.82,"id":40096580}]}]}
{"op":"mcm","clk":"11838405367","pt":1723494814897,"mc":[{"id":"1.231730206","rc":[{"batb":[[0,2.16,10],[1,2.14,560.79],[2,1.95,606]],"ltp":2.1,"tv":71.82,"id":40096580}]}]}
{"op":"mcm","clk":"11838405518","pt":1723494818294,"mc":[{"id":"1.231730206","rc":[{"batb":[[0,2.14,560.79],[1,1.95,606],[2,1.85,444]],"ltp":2.1,"tv":71.82,"id":40096580}]}]}
{"op":"mcm","clk":"11838405646","pt":1723494821015,"mc":[{"id":"1.231730206","rc":[{"batb":[[0,2.16,10],[1,2.14,560.79],[2,1.95,606]],"ltp":2.1,"tv":71.82,"id":40096580}]}]}
{"op":"mcm","clk":"11838405806","pt":1723494824602,"mc":[{"id":"1.231730206","rc":[{"batb":[[0,2.14,560.79],[1,1.95,606],[2,1.85,444]],"ltp":2.1,"tv":71.82,"id":40096580}]}]}
{"op":"mcm","clk":"11838405899","pt":1723494827016,"mc":[{"id":"1.231730206","rc":[{"batb":[[0,2.16,10],[1,2.14,560.79],[2,1.95,606]],"ltp":2.1,"tv":71.82,"id":40096580}]}]}
{"op":"mcm","clk":"11838406035","pt":1723494830637,"mc":[{"id":"1.231730206","rc":[{"batb":[[0,2.14,560.79],[1,1.95,606],[2,1.85,444]],"ltp":2.1,"tv":71.82,"id":40096580}]}]}
{"op":"mcm","clk":"11838406239","pt":1723494834706,"mc":[{"id":"1.231730206","rc":[{"batb":[[0,2.16,10],[1,2.14,560.79],[2,1.95,606]],"ltp":2.1,"tv":71.82,"id":40096580}]}]}
{"op":"mcm","clk":"11838406554","pt":1723494841235,"mc":[{"id":"1.231730206","rc":[{"batb":[[0,2.14,560.79],[1,1.95,606],[2,1.85,444]],"ltp":2.1,"tv":71.82,"id":40096580}]}]}
{"op":"mcm","clk":"11838406746","pt":1723494845717,"mc":[{"id":"1.231730206","rc":[{"batb":[[0,2.16,10],[1,2.14,560.79],[2,1.95,606]],"ltp":2.1,"tv":71.82,"id":40096580}]}]}
{"op":"mcm","clk":"11838407007","pt":1723494851946,"mc":[{"id":"1.231730206","rc":[{"batb":[[0,2.14,560.79],[1,1.95,606],[2,1.85,444]],"ltp":2.1,"tv":71.82,"id":40096580}]}]}
{"op":"mcm","clk":"11838407113","pt":1723494854269,"mc":[{"id":"1.231730206","rc":[{"batb":[[0,2.16,10],[1,2.14,560.79],[2,1.95,606]],"ltp":2.1,"tv":71.82,"id":40096580}]}]}
{"op":"mcm","clk":"11838407275","pt":1723494857954,"mc":[{"id":"1.231730206","rc":[{"batb":[[0,2.14,560.79],[1,1.95,606],[2,1.85,444]],"ltp":2.1,"tv":71.82,"id":40096580}]}]}
{"op":"mcm","clk":"11838407429","pt":1723494860641,"mc":[{"id":"1.231730206","rc":[{"batb":[[0,2.16,10],[1,2.14,560.79],[2,1.95,606]],"ltp":2.1,"tv":71.82,"id":40096580}]}]}
{"op":"mcm","clk":"11838407575","pt":1723494864238,"mc":[{"id":"1.231730206","rc":[{"batb":[[0,2.14,560.79],[1,1.95,606],[2,1.85,444]],"ltp":2.1,"tv":71.82,"id":40096580}]}]}
{"op":"mcm","clk":"11838407674","pt":1723494866856,"mc":[{"id":"1.231730206","rc":[{"batb":[[0,2.16,10],[1,2.14,560.79],[2,1.95,606]],"ltp":2.1,"tv":71.82,"id":40096580}]}]}
{"op":"mcm","clk":"11838407804","pt":1723494870562,"mc":[{"id":"1.231730206","rc":[{"batb":[[0,2.14,560.79],[1,1.95,606],[2,1.85,444]],"ltp":2.1,"tv":71.82,"id":40096580}]}]}
{"op":"mcm","clk":"11838407879","pt":1723494872876,"mc":[{"id":"1.231730206","rc":[{"batb":[[0,2.16,10],[1,2.14,560.79],[2,1.95,606]],"ltp":2.1,"tv":71.82,"id":40096580}]}]}
{"op":"mcm","clk":"11838408020","pt":1723494876389,"mc":[{"id":"1.231730206","rc":[{"batb":[[0,2.14,560.79],[1,1.95,606],[2,1.85,444]],"ltp":2.1,"tv":71.82,"id":40096580}]}]}
{"op":"mcm","clk":"11838408157","pt":1723494879156,"mc":[{"id":"1.231730206","rc":[{"batb":[[0,2.16,10],[1,2.14,560.79],[2,1.95,606]],"ltp":2.1,"tv":71.82,"id":40096580}]}]}
{"op":"mcm","clk":"11838408331","pt":1723494882961,"mc":[{"id":"1.231730206","rc":[{"batb":[[0,2.14,560.79],[1,1.95,606],[2,1.85,444]],"ltp":2.1,"tv":71.82,"id":40096580}]}]}
{"op":"mcm","clk":"11838408457","pt":1723494885487,"mc":[{"id":"1.231730206","rc":[{"batb":[[0,2.16,10],[1,2.14,560.79],[2,1.95,606]],"ltp":2.1,"tv":71.82,"id":40096580}]}]}
{"op":"mcm","clk":"11838408646","pt":1723494889556,"mc":[{"id":"1.231730206","rc":[{"batb":[[0,2.14,560.79],[1,1.95,606],[2,1.85,444]],"ltp":2.1,"tv":71.82,"id":40096580}]}]}
{"op":"mcm","clk":"11838408720","pt":1723494891869,"mc":[{"id":"1.231730206","rc":[{"batb":[[0,2.16,10],[1,2.14,560.79],[2,1.95,606]],"ltp":2.1,"tv":71.82,"id":40096580}]}]}
{"op":"mcm","clk":"11838408896","pt":1723494895780,"mc":[{"id":"1.231730206","rc":[{"batb":[[0,2.14,560.79],[1,1.95,606],[2,1.85,444]],"ltp":2.1,"tv":71.82,"id":40096580}]}]}
{"op":"mcm","clk":"11838409006","pt":1723494898403,"mc":[{"id":"1.231730206","rc":[{"batb":[[0,2.16,10],[1,2.14,560.79],[2,1.95,606]],"ltp":2.1,"tv":71.82,"id":40096580}]}]}
{"op":"mcm","clk":"11838409155","pt":1723494902070,"mc":[{"id":"1.231730206","rc":[{"batb":[[0,2.14,560.79],[1,1.95,606],[2,1.85,444]],"ltp":2.1,"tv":71.82,"id":40096580}]}]}
{"op":"mcm","clk":"11838409258","pt":1723494904685,"mc":[{"id":"1.231730206","rc":[{"batb":[[0,2.16,10],[1,2.14,560.79],[2,1.95,606]],"ltp":2.1,"tv":71.82,"id":40096580}]}]}
{"op":"mcm","clk":"11838409372","pt":1723494908486,"mc":[{"id":"1.231730206","rc":[{"batb":[[0,2.14,560.79],[1,1.95,606],[2,1.85,444]],"ltp":2.1,"tv":71.82,"id":40096580}]}]}
{"op":"mcm","clk":"11838409473","pt":1723494911276,"mc":[{"id":"1.231730206","rc":[{"batb":[[0,2.16,10],[1,2.14,560.79],[2,1.95,606]],"ltp":2.1,"tv":71.82,"id":40096580}]}]}
{"op":"mcm","clk":"11838409610","pt":1723494915091,"mc":[{"id":"1.231730206","rc":[{"batb":[[0,2.14,560.79],[1,1.95,606],[2,1.85,444]],"ltp":2.1,"tv":71.82,"id":40096580}]}]}
{"op":"mcm","clk":"11838409728","pt":1723494918292,"mc":[{"id":"1.231730206","rc":[{"batb":[[0,2.16,10],[1,2.14,560.79],[2,1.95,606]],"ltp":2.1,"tv":71.82,"id":40096580}]}]}
{"op":"mcm","clk":"11838409862","pt":1723494922095,"mc":[{"id":"1.231730206","rc":[{"batb":[[0,2.14,560.79],[1,1.95,606],[2,1.85,444]],"ltp":2.1,"tv":71.82,"id":40096580}]}]}
{"op":"mcm","clk":"11838409992","pt":1723494925600,"mc":[{"id":"1.231730206","rc":[{"batb":[[0,2.16,10],[1,2.14,560.79],[2,1.95,606]],"ltp":2.1,"tv":71.82,"id":40096580}]}]}
{"op":"mcm","clk":"11838410137","pt":1723494929204,"mc":[{"id":"1.231730206","rc":[{"batb":[[0,2.14,560.79],[1,1.95,606],[2,1.85,444]],"ltp":2.1,"tv":71.82,"id":40096580}]}]}
{"op":"mcm","clk":"11838410266","pt":1723494932639,"mc":[{"id":"1.231730206","rc":[{"batb":[[0,2.16,10],[1,2.14,560.79],[2,1.95,606]],"ltp":2.1,"tv":71.82,"id":40096580}]}]}
{"op":"mcm","clk":"11838410394","pt":1723494936032,"mc":[{"id":"1.231730206","rc":[{"batb":[[0,2.14,560.79],[1,1.95,606],[2,1.85,444]],"ltp":2.1,"tv":71.82,"id":40096580}]}]}
{"op":"mcm","clk":"11838410495","pt":1723494938650,"mc":[{"id":"1.231730206","rc":[{"batb":[[0,2.16,10],[1,2.14,560.79],[2,1.95,606]],"ltp":2.1,"tv":71.82,"id":40096580}]}]}
{"op":"mcm","clk":"11838410612","pt":1723494942354,"mc":[{"id":"1.231730206","rc":[{"batb":[[0,2.14,560.79],[1,1.95,606],[2,1.85,444]],"ltp":2.1,"tv":71.82,"id":40096580}]}]}
{"op":"mcm","clk":"11838410692","pt":1723494944825,"mc":[{"id":"1.231730206","rc":[{"batb":[[0,2.16,10],[1,2.14,560.79],[2,1.95,606]],"ltp":2.1,"tv":71.82,"id":40096580}]}]}
{"op":"mcm","clk":"11838410791","pt":1723494948159,"mc":[{"id":"1.231730206","rc":[{"batb":[[0,2.14,560.79],[1,1.95,606],[2,1.85,444]],"ltp":2.1,"tv":71.82,"id":40096580}]}]}
{"op":"mcm","clk":"11838410892","pt":1723494950842,"mc":[{"id":"1.231730206","rc":[{"batb":[[0,2.16,10],[1,2.14,560.79],[2,1.95,606]],"ltp":2.1,"tv":71.82,"id":40096580}]}]}
{"op":"mcm","clk":"11838411025","pt":1723494954333,"mc":[{"id":"1.231730206","rc":[{"batb":[[0,2.14,560.79],[1,1.95,606],[2,1.85,444]],"ltp":2.1,"tv":71.82,"id":40096580}]}]}
{"op":"mcm","clk":"11838411151","pt":1723494957665,"mc":[{"id":"1.231730206","rc":[{"batb":[[0,2.16,10],[1,2.14,560.79],[2,1.95,606]],"ltp":2.1,"tv":71.82,"id":40096580}]}]}
{"op":"mcm","clk":"11838411291","pt":1723494961469,"mc":[{"id":"1.231730206","rc":[{"batb":[[0,2.14,560.79],[1,1.95,606],[2,1.85,444]],"ltp":2.1,"tv":71.82,"id":40096580}]}]}
{"op":"mcm","clk":"11838411412","pt":1723494964865,"mc":[{"id":"1.231730206","rc":[{"batb":[[0,2.16,10],[1,2.14,560.79],[2,1.95,606]],"ltp":2.1,"tv":71.82,"id":40096580}]}]}
{"op":"mcm","clk":"11838411669","pt":1723494971863,"mc":[{"id":"1.231730206","rc":[{"batb":[[0,2.14,560.79],[1,1.95,606],[2,1.85,444]],"ltp":2.1,"tv":71.82,"id":40096580}]}]}
{"op":"mcm","clk":"11838411788","pt":1723494974751,"mc":[{"id":"1.231730206","rc":[{"batb":[[0,2.16,10],[1,2.14,560.79],[2,1.95,606]],"ltp":2.1,"tv":71.82,"id":40096580}]}]}
{"op":"mcm","clk":"11838412067","pt":1723494982164,"mc":[{"id":"1.231730206","rc":[{"batb":[[0,2.14,560.79],[1,1.95,606],[2,1.85,444]],"ltp":2.1,"tv":71.82,"id":40096580}]}]}
{"op":"mcm","clk":"11838412078","pt":1723494982371,"mc":[{"id":"1.231730206","rc":[{"batb":[[0,2.16,15.02],[1,2.14,560.79],[2,1.95,606]],"ltp":2.1,"tv":71.82,"id":40096580}]}]}
{"op":"mcm","clk":"11838412260","pt":1723494987568,"mc":[{"id":"1.231730206","rc":[{"batb":[[0,2.16,25.02]],"ltp":2.1,"tv":71.82,"id":40096580}]}]}
{"op":"mcm","clk":"11838412546","pt":1723494995486,"mc":[{"id":"1.231730206","rc":[{"batb":[[0,2.16,15.02]],"ltp":2.1,"tv":71.82,"id":40096580}]}]}
{"op":"mcm","clk":"11838414286","pt":1723495050248,"mc":[{"id":"1.231730206","rc":[{"batb":[[1,1.95,606],[2,1.85,444]],"ltp":2.1,"tv":71.82,"id":40096580}]}]}
{"op":"mcm","clk":"11838414332","pt":1723495051231,"mc":[{"id":"1.231730206","rc":[{"batb":[[0,2.2,560.79]],"ltp":2.1,"tv":71.82,"id":40096580},{"batl":[[0,1.83,7.29],[1,1.87,4.67]],"ltp":1.87,"tv":1295.59,"id":40096582}]}]}
{"op":"mcm","clk":"11838414335","pt":1723495051334,"mc":[{"id":"1.231730206","rc":[{"batl":[[0,2.24,17.12]],"ltp":2.1,"tv":71.82,"id":40096580}]}]}
{"op":"mcm","clk":"11838415236","pt":1723495081382,"mc":[{"id":"1.231730206","rc":[{"batl":[[0,1.83,24.42]],"ltp":1.87,"tv":1295.59,"id":40096582}]}]}
{"op":"mcm","clk":"11838416649","pt":1723495128035,"mc":[{"id":"1.231730206","rc":[{"batb":[[0,1.95,606],[1,1.85,444],[2,1.74,17.32]],"ltp":2.1,"tv":71.82,"id":40096580}]}]}
{"op":"mcm","clk":"11838416710","pt":1723495129998,"mc":[{"id":"1.231730206","rc":[{"batl":[[0,2.04,10.82],[1,1.87,0]],"ltp":1.87,"tv":1295.59,"id":40096582}]}]}
{"op":"mcm","clk":"11838416804","pt":1723495133600,"mc":[{"id":"1.231730206","rc":[{"batb":[[0,1.96,10],[1,1.95,606],[2,1.85,444]],"ltp":2.1,"tv":71.82,"id":40096580}]}]}
{"op":"mcm","clk":"11838416868","pt":1723495135342,"mc":[{"id":"1.231730206","rc":[{"batb":[[0,1.81,10],[1,1.8,555],[2,1.79,493.04]],"ltp":1.87,"tv":1295.59,"id":40096582}]}]}
{"op":"mcm","clk":"11838417058","pt":1723495141832,"mc":[{"id":"1.231730206","rc":[{"batb":[[0,1.95,606],[1,1.85,444],[2,1.74,17.32]],"ltp":2.1,"tv":71.82,"id":40096580}]}]}
{"op":"mcm","clk":"11838417129","pt":1723495144246,"mc":[{"id":"1.231730206","rc":[{"batb":[[0,1.97,10],[1,1.95,606],[2,1.85,444]],"ltp":2.1,"tv":71.82,"id":40096580}]}]}
{"op":"mcm","clk":"11838417179","pt":1723495146149,"mc":[{"id":"1.231730206","rc":[{"batb":[[0,1.8,555],[1,1.79,493.04],[2,1.74,17.32]],"ltp":1.87,"tv":1295.59,"id":40096582}]}]}
{"op":"mcm","clk":"11838417218","pt":1723495147538,"mc":[{"id":"1.231730206","rc":[{"batb":[[0,1.82,95.03],[1,1.8,555],[2,1.79,493.04]],"ltp":1.87,"tv":1295.59,"id":40096582}]}]}
{"op":"mcm","clk":"11838417303","pt":1723495149747,"mc":[{"id":"1.231730206","rc":[{"batb":[[0,1.82,105.03]],"ltp":1.87,"tv":1295.59,"id":40096582}]}]}
{"op":"mcm","clk":"11838417430","pt":1723495154124,"mc":[{"id":"1.231730206","rc":[{"batb":[[0,1.95,606],[1,1.85,444],[2,1.74,17.32]],"ltp":2.1,"tv":71.82,"id":40096580}]}]}
{"op":"mcm","clk":"11838417584","pt":1723495159237,"mc":[{"id":"1.231730206","rc":[{"batb":[[0,1.82,95.03]],"ltp":1.87,"tv":1295.59,"id":40096582}]}]}
{"op":"mcm","clk":"11838417601","pt":1723495159849,"mc":[{"id":"1.231730206","rc":[{"batl":[[0,2.04,27.95]],"ltp":1.87,"tv":1295.59,"id":40096582}]}]}
{"op":"mcm","clk":"11838417675","pt":1723495162478,"mc":[{"id":"1.231730206","rc":[{"batb":[[0,1.83,10],[1,1.82,95.03],[2,1.8,555]],"ltp":1.87,"tv":1295.59,"id":40096582}]}]}
{"op":"mcm","clk":"11838418036","pt":1723495172684,"mc":[{"id":"1.231730206","rc":[{"batb":[[0,1.82,95.03],[1,1.8,555],[2,1.79,493.04]],"ltp":1.87,"tv":1295.59,"id":40096582}]}]}
{"op":"mcm","clk":"11838418102","pt":1723495175056,"mc":[{"id":"1.231730206","rc":[{"batb":[[0,1.84,10],[1,1.82,95.03],[2,1.8,555]],"ltp":1.87,"tv":1295.59,"id":40096582}]}]}
{"op":"mcm","clk":"11838418410","pt":1723495184773,"mc":[{"id":"1.231730206","rc":[{"batb":[[0,1.82,95.03],[1,1.8,555],[2,1.79,493.04]],"ltp":1.87,"tv":1295.59,"id":40096582}]}]}
{"op":"mcm","clk":"11838418613","pt":1723495189878,"mc":[{"id":"1.231730206","rc":[{"batb":[[0,1.85,10],[1,1.82,95.03],[2,1.8,555]],"ltp":1.87,"tv":1295.59,"id":40096582}]}]}
{"op":"mcm","clk":"11838418972","pt":1723495200585,"mc":[{"id":"1.231730206","rc":[{"batb":[[0,1.82,95.03],[1,1.8,555],[2,1.79,493.04]],"ltp":1.87,"tv":1295.59,"id":40096582}]}]}
{"op":"mcm","clk":"11838419059","pt":1723495203469,"mc":[{"id":"1.231730206","rc":[{"batb":[[0,1.86,10],[1,1.82,95.03],[2,1.8,555]],"ltp":1.87,"tv":1295.59,"id":40096582}]}]}
{"op":"mcm","clk":"11838419441","pt":1723495214991,"mc":[{"id":"1.231730206","rc":[{"batb":[[0,1.82,95.03],[1,1.8,555],[2,1.79,493.04]],"ltp":1.87,"tv":1295.59,"id":40096582}]}]}
{"op":"mcm","clk":"11838419597","pt":1723495219684,"mc":[{"id":"1.231730206","rc":[{"batb":[[0,1.87,10],[1,1.82,95.03],[2,1.8,555]],"ltp":1.87,"tv":1295.59,"id":40096582}]}]}
{"op":"mcm","clk":"11838419904","pt":1723495229295,"mc":[{"id":"1.231730206","rc":[{"batb":[[0,1.82,95.03],[1,1.8,555],[2,1.79,493.04]],"ltp":1.87,"tv":1295.59,"id":40096582}]}]}
{"op":"mcm","clk":"11838420071","pt":1723495234705,"mc":[{"id":"1.231730206","rc":[{"batb":[[0,1.88,10],[1,1.82,95.03],[2,1.8,555]],"ltp":1.87,"tv":1295.59,"id":40096582}]}]}
{"op":"mcm","clk":"11838420375","pt":1723495244221,"mc":[{"id":"1.231730206","rc":[{"batb":[[0,1.82,95.03],[1,1.8,555],[2,1.79,493.04]],"ltp":1.87,"tv":1295.59,"id":40096582}]}]}
{"op":"mcm","clk":"11838420455","pt":1723495246637,"mc":[{"id":"1.231730206","rc":[{"batb":[[0,1.89,10],[1,1.82,95.03],[2,1.8,555]],"ltp":1.87,"tv":1295.59,"id":40096582}]}]}
{"op":"mcm","clk":"11838420823","pt":1723495256006,"mc":[{"id":"1.231730206","rc":[{"batb":[[0,1.82,95.03],[1,1.8,555],[2,1.79,493.04]],"ltp":1.87,"tv":1295.59,"id":40096582}]}]}
{"op":"mcm","clk":"11838420930","pt":1723495258435,"mc":[{"id":"1.231730206","rc":[{"batb":[[0,1.9,10],[1,1.82,95.03],[2,1.8,555]],"ltp":1.87,"tv":1295.59,"id":40096582}]}]}
{"op":"mcm","clk":"11838421348","pt":1723495269524,"mc":[{"id":"1.231730206","rc":[{"batb":[[0,1.82,95.03],[1,1.8,555],[2,1.79,493.04]],"ltp":1.87,"tv":1295.59,"id":40096582}]}]}
{"op":"mcm","clk":"11838421445","pt":1723495272556,"mc":[{"id":"1.231730206","rc":[{"batb":[[0,1.91,10],[1,1.82,95.03],[2,1.8,555]],"ltp":1.87,"tv":1295.59,"id":40096582}]}]}
{"op":"mcm","clk":"11838421933","pt":1723495284969,"mc":[{"id":"1.231730206","rc":[{"batb":[[0,1.82,95.03],[1,1.8,555],[2,1.79,493.04]],"ltp":1.87,"tv":1295.59,"id":40096582}]}]}
{"op":"mcm","clk":"11838422000","pt":1723495287082,"mc":[{"id":"1.231730206","rc":[{"batb":[[0,1.92,10],[1,1.82,95.03],[2,1.8,555]],"ltp":1.87,"tv":1295.59,"id":40096582}]}]}
{"op":"mcm","clk":"11838422423","pt":1723495298767,"mc":[{"id":"1.231730206","rc":[{"batb":[[0,1.82,95.03],[1,1.8,555],[2,1.79,493.04]],"ltp":1.87,"tv":1295.59,"id":40096582}]}]}
{"op":"mcm","clk":"11838422596","pt":1723495304560,"mc":[{"id":"1.231730206","rc":[{"batb":[[0,1.93,10],[1,1.82,95.03],[2,1.8,555]],"ltp":1.87,"tv":1295.59,"id":40096582}]}]}
{"op":"mcm","clk":"11838422936","pt":1723495315207,"mc":[{"id":"1.231730206","rc":[{"batb":[[0,1.82,95.03],[1,1.8,555],[2,1.79,493.04]],"ltp":1.87,"tv":1295.59,"id":40096582}]}]}
{"op":"mcm","clk":"11838423017","pt":1723495317681,"mc":[{"id":"1.231730206","rc":[{"batb":[[0,1.94,10],[1,1.82,95.03],[2,1.8,555]],"ltp":1.87,"tv":1295.59,"id":40096582}]}]}
{"op":"mcm","clk":"11838423390","pt":1723495328382,"mc":[{"id":"1.231730206","rc":[{"batb":[[0,1.82,95.03],[1,1.8,555],[2,1.79,493.04]],"ltp":1.87,"tv":1295.59,"id":40096582}]}]}
{"op":"mcm","clk":"11838423493","pt":1723495330694,"mc":[{"id":"1.231730206","rc":[{"batb":[[0,1.95,10],[1,1.82,95.03],[2,1.8,555]],"ltp":1.87,"tv":1295.59,"id":40096582}]}]}
{"op":"mcm","clk":"11838423854","pt":1723495341329,"mc":[{"id":"1.231730206","rc":[{"batb":[[0,1.82,95.03],[1,1.8,555],[2,1.79,493.04]],"ltp":1.87,"tv":1295.59,"id":40096582}]}]}
{"op":"mcm","clk":"11838423938","pt":1723495344619,"mc":[{"id":"1.231730206","rc":[{"batb":[[0,1.96,10],[1,1.82,95.03],[2,1.8,555]],"ltp":1.87,"tv":1295.59,"id":40096582}]}]}
{"op":"mcm","clk":"11838424390","pt":1723495357838,"mc":[{"id":"1.231730206","rc":[{"batb":[[0,1.82,95.03],[1,1.8,555],[2,1.79,493.04]],"ltp":1.87,"tv":1295.59,"id":40096582}]}]}
{"op":"mcm","clk":"11838424537","pt":1723495362724,"mc":[{"id":"1.231730206","rc":[{"batb":[[0,1.97,10],[1,1.82,95.03],[2,1.8,555]],"ltp":1.87,"tv":1295.59,"id":40096582}]}]}
{"op":"mcm","clk":"11838424953","pt":1723495375953,"mc":[{"id":"1.231730206","rc":[{"batb":[[0,1.82,95.03],[1,1.8,555],[2,1.79,493.04]],"ltp":1.87,"tv":1295.59,"id":40096582}]}]}
{"op":"mcm","clk":"11838425009","pt":1723495378668,"mc":[{"id":"1.231730206","rc":[{"batb":[[0,1.98,10],[1,1.82,95.03],[2,1.8,555]],"ltp":1.87,"tv":1295.59,"id":40096582}]}]}
{"op":"mcm","clk":"11838425411","pt":1723495391263,"mc":[{"id":"1.231730206","rc":[{"batb":[[0,1.82,95.03],[1,1.8,555],[2,1.79,493.04]],"ltp":1.87,"tv":1295.59,"id":40096582}]}]}
{"op":"mcm","clk":"11838425731","pt":1723495401151,"mc":[{"id":"1.231730206","rc":[{"batb":[[0,1.83,10],[1,1.82,95.03],[2,1.8,555]],"ltp":1.87,"tv":1295.59,"id":40096582}]}]}
{"op":"mcm","clk":"11838426279","pt":1723495415381,"mc":[{"id":"1.231730206","rc":[{"batb":[[0,1.82,95.03],[1,1.8,555],[2,1.79,493.04]],"ltp":1.87,"tv":1295.59,"id":40096582}]}]}
{"op":"mcm","clk":"11838426473","pt":1723495421906,"mc":[{"id":"1.231730206","rc":[{"batb":[[0,1.84,10],[1,1.82,95.03],[2,1.8,555]],"ltp":1.87,"tv":1295.59,"id":40096582}]}]}
{"op":"mcm","clk":"11838426932","pt":1723495436498,"mc":[{"id":"1.231730206","rc":[{"batb":[[0,1.82,95.03],[1,1.8,555],[2,1.79,493.04]],"ltp":1.87,"tv":1295.59,"id":40096582}]}]}
{"op":"mcm","clk":"11838427005","pt":1723495439018,"mc":[{"id":"1.231730206","rc":[{"batb":[[0,1.85,10],[1,1.82,95.03],[2,1.8,555]],"ltp":1.87,"tv":1295.59,"id":40096582}]}]}
{"op":"mcm","clk":"11838427523","pt":1723495458656,"mc":[{"id":"1.231730206","rc":[{"batb":[[0,1.82,95.03],[1,1.8,555],[2,1.79,493.04]],"ltp":1.87,"tv":1295.59,"id":40096582}]}]}
{"op":"mcm","clk":"11838427608","pt":1723495461034,"mc":[{"id":"1.231730206","rc":[{"batb":[[0,1.86,10],[1,1.82,95.03],[2,1.8,555]],"ltp":1.87,"tv":1295.59,"id":40096582}]}]}
{"op":"mcm","clk":"11838428054","pt":1723495476471,"mc":[{"id":"1.231730206","rc":[{"batb":[[0,1.82,95.03],[1,1.8,555],[2,1.79,493.04]],"ltp":1.87,"tv":1295.59,"id":40096582}]}]}
{"op":"mcm","clk":"11838428204","pt":1723495480340,"mc":[{"id":"1.231730206","rc":[{"batb":[[0,1.87,10],[1,1.82,95.03],[2,1.8,555]],"ltp":1.87,"tv":1295.59,"id":40096582}]}]}
{"op":"mcm","clk":"11838428804","pt":1723495500046,"mc":[{"id":"1.231730206","rc":[{"batb":[[0,1.82,95.03],[1,1.8,555],[2,1.79,493.04]],"ltp":1.87,"tv":1295.59,"id":40096582}]}]}
{"op":"mcm","clk":"11838428915","pt":1723495502993,"mc":[{"id":"1.231730206","rc":[{"batb":[[0,1.88,10],[1,1.82,95.03],[2,1.8,555]],"ltp":1.87,"tv":1295.59,"id":40096582}]}]}
{"op":"mcm","clk":"11838429656","pt":1723495522494,"mc":[{"id":"1.231730206","rc":[{"batb":[[0,1.82,95.03],[1,1.8,555],[2,1.79,493.04]],"ltp":1.87,"tv":1295.59,"id":40096582}]}]}
{"op":"mcm","clk":"11838429736","pt":1723495525116,"mc":[{"id":"1.231730206","rc":[{"batb":[[0,1.89,10],[1,1.82,95.03],[2,1.8,555]],"ltp":1.87,"tv":1295.59,"id":40096582}]}]}
{"op":"mcm","clk":"11838430425","pt":1723495546617,"mc":[{"id":"1.231730206","rc":[{"batb":[[0,1.82,95.03],[1,1.8,555],[2,1.79,493.04]],"ltp":1.87,"tv":1295.59,"id":40096582}]}]}
{"op":"mcm","clk":"11838430456","pt":1723495547496,"mc":[{"id":"1.231730206","rc":[{"batl":[[0,2.2,5.85]],"ltp":2.1,"tv":71.82,"id":40096580}]}]}
{"op":"mcm","clk":"11838430503","pt":1723495548831,"mc":[{"id":"1.231730206","rc":[{"batb":[[0,1.9,10],[1,1.82,95.03],[2,1.8,555]],"ltp":1.87,"tv":1295.59,"id":40096582}]}]}
{"op":"mcm","clk":"11838431219","pt":1723495567540,"mc":[{"id":"1.231730206","rc":[{"batb":[[0,1.96,10],[1,1.95,606],[2,1.85,444]],"ltp":2.1,"tv":71.82,"id":40096580}]}]}
{"op":"mcm","clk":"11838431325","pt":1723495571239,"mc":[{"id":"1.231730206","rc":[{"batb":[[0,1.82,95.03],[1,1.8,555],[2,1.79,493.04]],"ltp":1.87,"tv":1295.59,"id":40096582}]}]}
{"op":"mcm","clk":"11838431401","pt":1723495573651,"mc":[{"id":"1.231730206","rc":[{"batb":[[0,1.91,10],[1,1.82,95.03],[2,1.8,555]],"ltp":1.87,"tv":1295.59,"id":40096582}]}]}
{"op":"mcm","clk":"11838431974","pt":1723495589152,"mc":[{"id":"1.231730206","rc":[{"batb":[[0,1.95,606],[1,1.85,444],[2,1.74,17.32]],"ltp":2.1,"tv":71.82,"id":40096580}]}]}
{"op":"mcm","clk":"11838432212","pt":1723495594795,"mc":[{"id":"1.231730206","rc":[{"batb":[[0,1.82,95.03],[1,1.8,555],[2,1.79,493.04]],"ltp":1.87,"tv":1295.59,"id":40096582}]}]}
{"op":"mcm","clk":"11838432303","pt":1723495597161,"mc":[{"id":"1.231730206","rc":[{"batb":[[0,1.92,10],[1,1.82,95.03],[2,1.8,555]],"ltp":1.87,"tv":1295.59,"id":40096582}]}]}
{"op":"mcm","clk":"11838433075","pt":1723495616598,"mc":[{"id":"1.231730206","rc":[{"trd":[[2.1,66.87]],"ltp":2.1,"tv":71.89,"id":40096580},{"trd":[[1.92,6.81]],"batb":[[0,1.92,9.92]],"ltp":1.92,"tv":1295.67,"id":40096582}],"tv":1367.56}]}
{"op":"mcm","clk":"11838433149","pt":1723495619215,"mc":[{"id":"1.231730206","rc":[{"batb":[[0,1.82,95.03],[1,1.8,555],[2,1.79,493.04]],"ltp":1.92,"tv":1295.67,"id":40096582}]}]}
{"op":"mcm","clk":"11838433205","pt":1723495620811,"mc":[{"id":"1.231730206","rc":[{"batl":[[0,2.2,5.85]],"ltp":2.1,"tv":71.89,"id":40096580}]}]}
{"op":"mcm","clk":"11838433250","pt":1723495621994,"mc":[{"id":"1.231730206","rc":[{"batb":[[0,1.93,10],[1,1.82,95.03],[2,1.8,555]],"ltp":1.92,"tv":1295.67,"id":40096582}]}]}
{"op":"mcm","clk":"11838433905","pt":1723495640258,"mc":[{"id":"1.231730206","rc":[{"batb":[[0,1.96,10],[1,1.95,606],[2,1.85,444]],"ltp":2.1,"tv":71.89,"id":40096580}]}]}
{"op":"mcm","clk":"11838434099","pt":1723495645042,"mc":[{"id":"1.231730206","rc":[{"batb":[[0,1.82,95.03],[1,1.8,555],[2,1.79,493.04]],"ltp":1.92,"tv":1295.67,"id":40096582}]}]}
{"op":"mcm","clk":"11838434242","pt":1723495648632,"mc":[{"id":"1.231730206","rc":[{"batb":[[0,1.94,10],[1,1.82,95.03],[2,1.8,555]],"ltp":1.92,"tv":1295.67,"id":40096582}]}]}
{"op":"mcm","clk":"11838434739","pt":1723495661744,"mc":[{"id":"1.231730206","rc":[{"batb":[[0,1.95,606],[1,1.85,444],[2,1.74,17.32]],"ltp":2.1,"tv":71.89,"id":40096580}]}]}
{"op":"mcm","clk":"11838435063","pt":1723495670771,"mc":[{"id":"1.231730206","rc":[{"batb":[[0,1.82,95.03],[1,1.8,555],[2,1.79,493.04]],"ltp":1.92,"tv":1295.67,"id":40096582}]}]}
{"op":"mcm","clk":"11838435141","pt":1723495673076,"mc":[{"id":"1.231730206","rc":[{"batb":[[0,1.95,10],[1,1.82,95.03],[2,1.8,555]],"ltp":1.92,"tv":1295.67,"id":40096582}]}]}
{"op":"mcm","clk":"11838435932","pt":1723495697086,"mc":[{"id":"1.231730206","rc":[{"batl":[[0,2.2,5.85]],"ltp":2.1,"tv":71.89,"id":40096580},{"batb":[[0,1.82,95.03],[1,1.8,555],[2,1.79,493.04]],"ltp":1.92,"tv":1295.67,"id":40096582}]}]}
{"op":"mcm","clk":"11838435980","pt":1723495698777,"mc":[{"id":"1.231730206","rc":[{"batb":[[0,1.96,10],[1,1.82,95.03],[2,1.8,555]],"ltp":1.92,"tv":1295.67,"id":40096582}]}]}
{"op":"mcm","clk":"11838436679","pt":1723495717982,"mc":[{"id":"1.231730206","rc":[{"batb":[[0,1.96,10],[1,1.95,606],[2,1.85,444]],"ltp":2.1,"tv":71.89,"id":40096580}]}]}
{"op":"mcm","clk":"11838436822","pt":1723495722506,"mc":[{"id":"1.231730206","rc":[{"batb":[[0,1.82,95.03],[1,1.8,555],[2,1.79,493.04]],"ltp":1.92,"tv":1295.67,"id":40096582}]}]}
{"op":"mcm","clk":"11838436898","pt":1723495725184,"mc":[{"id":"1.231730206","rc":[{"batb":[[0,1.97,10],[1,1.82,95.03],[2,1.8,555]],"ltp":1.92,"tv":1295.67,"id":40096582}]}]}
{"op":"mcm","clk":"11838436983","pt":1723495728219,"mc":[{"id":"1.231730206","rc":[{"trd":[[2.04,9.66]],"batb":[[0,2.04,75.1],[1,1.96,10],[2,1.95,606]],"ltp":2.04,"tv":81.54,"id":40096580},{"trd":[[1.97,10]],"batb":[[0,1.82,95.03],[1,1.8,555],[2,1.79,493.04]],"batl":[[0,1.97,84.76],[1,2.04,27.95]],"ltp":1.97,"tv":1305.67,"id":40096582}],"tv":1387.22}]}
{"op":"mcm","clk":"11838437009","pt":1723495729089,"mc":[{"id":"1.231730206","rc":[{"batl":[[0,1.96,4.45],[1,1.97,84.76],[2,2.04,23.66]],"ltp":1.97,"tv":1305.67,"id":40096582}]}]}
{"op":"mcm","clk":"11838437024","pt":1723495729505,"mc":[{"id":"1.231730206","rc":[{"batl":[[0,1.96,11.27],[2,2.04,0]],"ltp":1.97,"tv":1305.67,"id":40096582}]}]}
{"op":"mcm","clk":"11838437411","pt":1723495739940,"mc":[{"id":"1.231730206","rc":[{"batb":[[1,1.95,606],[2,1.85,444]],"ltp":2.04,"tv":81.54,"id":40096580}]}]}
{"op":"mcm","clk":"11838437743","pt":1723495749032,"mc":[{"id":"1.231730206","rc":[{"batb":[[0,1.95,606],[1,1.85,444],[2,1.74,17.32]],"ltp":2.04,"tv":81.54,"id":40096580},{"batl":[[0,1.96,6.82],[1,2.04,4.28]],"ltp":1.97,"tv":1305.67,"id":40096582}]}]}
{"op":"mcm","clk":"11838437781","pt":1723495750112,"mc":[{"id":"1.231730206","rc":[{"batl":[[0,2.04,10.82],[1,2.04,0]],"ltp":1.97,"tv":1305.67,"id":40096582}]}]}
{"op":"mcm","clk":"11838437913","pt":1723495754830,"mc":[{"id":"1.231730206","rc":[{"batl":[[0,2.2,5.85]],"ltp":2.04,"tv":81.54,"id":40096580}]}]}
{"op":"mcm","clk":"11838438350","pt":1723495768649,"mc":[{"id":"1.231730206","rc":[{"batb":[[0,1.83,10],[1,1.82,95.03],[2,1.8,555]],"ltp":1.97,"tv":1305.67,"id":40096582}]}]}
{"op":"mcm","clk":"11838438539","pt":1723495773534,"mc":[{"id":"1.231730206","rc":[{"batb":[[0,1.96,10],[1,1.95,606],[2,1.85,444]],"ltp":2.04,"tv":81.54,"id":40096580}]}]}
{"op":"mcm","clk":"11838438692","pt":1723495776976,"mc":[{"id":"1.231730206","rc":[{"batb":[[0,1.84,95.03],[1,1.83,10]],"ltp":1.97,"tv":1305.67,"id":40096582}]}]}
{"op":"mcm","clk":"11838438830","pt":1723495780877,"mc":[{"id":"1.231730206","rc":[{"batl":[[0,2.04,27.95]],"ltp":1.97,"tv":1305.67,"id":40096582}]}]}
{"op":"mcm","clk":"11838439153","pt":1723495789965,"mc":[{"id":"1.231730206","rc":[{"batb":[[1,1.8,555],[2,1.79,493.04]],"ltp":1.97,"tv":1305.67,"id":40096582}]}]}
{"op":"mcm","clk":"11838439248","pt":1723495793294,"mc":[{"id":"1.231730206","rc":[{"batb":[[0,1.84,105.03]],"ltp":1.97,"tv":1305.67,"id":40096582}]}]}
{"op":"mcm","clk":"11838439302","pt":1723495794680,"mc":[{"id":"1.231730206","rc":[{"batb":[[0,1.95,606],[1,1.85,444],[2,1.74,17.32]],"ltp":2.04,"tv":81.54,"id":40096580}]}]}
{"op":"mcm","clk":"11838439405","pt":1723495797089,"mc":[{"id":"1.231730206","rc":[{"batb":[[0,1.97,10],[1,1.95,606],[2,1.85,444]],"ltp":2.04,"tv":81.54,"id":40096580}]}]}
{"op":"mcm","clk":"11838440095","pt":1723495815885,"mc":[{"id":"1.231730206","rc":[{"batb":[[0,1.84,95.03]],"ltp":1.97,"tv":1305.67,"id":40096582}]}]}
{"op":"mcm","clk":"11838440192","pt":1723495818598,"mc":[{"id":"1.231730206","rc":[{"batb":[[0,1.85,10],[1,1.84,95.03],[2,1.8,555]],"ltp":1.97,"tv":1305.67,"id":40096582}]}]}
{"op":"mcm","clk":"11838440262","pt":1723495820496,"mc":[{"id":"1.231730206","rc":[{"batb":[[0,1.95,606],[1,1.85,444],[2,1.74,17.32]],"ltp":2.04,"tv":81.54,"id":40096580}]}]}
{"op":"mcm","clk":"11838440329","pt":1723495822712,"mc":[{"id":"1.231730206","rc":[{"batb":[[0,1.98,10],[1,1.95,606],[2,1.85,444]],"ltp":2.04,"tv":81.54,"id":40096580}]}]}
{"op":"mcm","clk":"11838441024","pt":1723495841016,"mc":[{"id":"1.231730206","rc":[{"batb":[[0,1.84,95.03],[1,1.8,555],[2,1.79,493.04]],"ltp":1.97,"tv":1305.67,"id":40096582}]}]}
{"op":"mcm","clk":"11838441146","pt":1723495844412,"mc":[{"id":"1.231730206","rc":[{"batb":[[0,1.86,10],[1,1.84,95.03],[2,1.8,555]],"ltp":1.97,"tv":1305.67,"id":40096582}]}]}
{"op":"mcm","clk":"11838441194","pt":1723495845946,"mc":[{"id":"1.231730206","rc":[{"batb":[[0,1.95,606],[1,1.85,444],[2,1.74,17.32]],"ltp":2.04,"tv":81.54,"id":40096580}]}]}
{"op":"mcm","clk":"11838441287","pt":1723495848925,"mc":[{"id":"1.231730206","rc":[{"batb":[[0,1.99,10],[1,1.95,606],[2,1.85,444]],"ltp":2.04,"tv":81.54,"id":40096580}]}]}
{"op":"mcm","clk":"11838442046","pt":1723495867569,"mc":[{"id":"1.231730206","rc":[{"batb":[[0,1.84,95.03],[1,1.8,555],[2,1.79,493.04]],"ltp":1.97,"tv":1305.67,"id":40096582}]}]}
{"op":"mcm","clk":"11838442121","pt":1723495870142,"mc":[{"id":"1.231730206","rc":[{"batb":[[0,1.87,10],[1,1.84,95.03],[2,1.8,555]],"ltp":1.97,"tv":1305.67,"id":40096582}]}]}
{"op":"mcm","clk":"11838442171","pt":1723495872146,"mc":[{"id":"1.231730206","rc":[{"batb":[[0,1.95,606],[1,1.85,444],[2,1.74,17.32]],"ltp":2.04,"tv":81.54,"id":40096580}]}]}
{"op":"mcm","clk":"11838442317","pt":1723495876265,"mc":[{"id":"1.231730206","rc":[{"batb":[[0,2,10],[1,1.95,606],[2,1.85,444]],"ltp":2.04,"tv":81.54,"id":40096580}]}]}
{"op":"mcm","clk":"11838442929","pt":1723495893496,"mc":[{"id":"1.231730206","rc":[{"batb":[[0,1.84,95.03],[1,1.8,555],[2,1.79,493.04]],"ltp":1.97,"tv":1305.67,"id":40096582}]}]}
{"op":"mcm","clk":"11838443033","pt":1723495896116,"mc":[{"id":"1.231730206","rc":[{"batb":[[0,1.88,10],[1,1.84,95.03],[2,1.8,555]],"ltp":1.97,"tv":1305.67,"id":40096582}]}]}
{"op":"mcm","clk":"11838443182","pt":1723495899299,"mc":[{"id":"1.231730206","rc":[{"batb":[[0,1.95,606],[1,1.85,444],[2,1.74,17.32]],"ltp":2.04,"tv":81.54,"id":40096580}]}]}
{"op":"mcm","clk":"11838443278","pt":1723495902579,"mc":[{"id":"1.231730206","rc":[{"batb":[[0,2.02,10],[1,1.95,606],[2,1.85,444]],"ltp":2.04,"tv":81.54,"id":40096580}]}]}
{"op":"mcm","clk":"11838443302","pt":1723495903501,"mc":[{"id":"1.231730206","rc":[{"batl":[[0,2.04,10.82]],"ltp":1.97,"tv":1305.67,"id":40096582}]}]}
{"op":"mcm","clk":"11838444069","pt":1723495924823,"mc":[{"id":"1.231730206","rc":[{"batb":[[0,1.84,95.03],[1,1.8,555],[2,1.79,493.04]],"ltp":1.97,"tv":1305.67,"id":40096582}]}]}
{"op":"mcm","clk":"11838444262","pt":1723495927314,"mc":[{"id":"1.231730206","rc":[{"batb":[[0,1.89,10],[1,1.84,95.03],[2,1.8,555]],"ltp":1.97,"tv":1305.67,"id":40096582}]}]}
{"op":"mcm","clk":"11838444450","pt":1723495931122,"mc":[{"id":"1.231730206","rc":[{"batb":[[0,1.96,17.07]],"ltp":2.04,"tv":81.54,"id":40096580}]}]}
{"op":"mcm","clk":"11838444483","pt":1723495931839,"mc":[{"id":"1.231730206","rc":[{"batl":[[0,2.04,27.95]],"ltp":1.97,"tv":1305.67,"id":40096582}]}]}
{"op":"mcm","clk":"11838445258","pt":1723495950728,"mc":[{"id":"1.231730206","rc":[{"batb":[[0,1.84,95.03],[1,1.8,555],[2,1.79,493.04]],"ltp":1.97,"tv":1305.67,"id":40096582}]}]}
{"op":"mcm","clk":"11838447600","pt":1723496024008,"mc":[{"id":"1.231730206","rc":[{"batb":[[0,1.8,555],[1,1.79,493.04],[2,1.74,17.32]],"ltp":1.97,"tv":1305.67,"id":40096582}]}]}
{"op":"mcm","clk":"11838448002","pt":1723496036658,"mc":[{"id":"1.231730206","rc":[{"batb":[[0,2,218.32],[1,1.96,17.07],[2,1.95,606]],"ltp":2.04,"tv":81.54,"id":40096580}]}]}
{"op":"mcm","clk":"11838448057","pt":1723496038248,"mc":[{"id":"1.231730206","rc":[{"batb":[[1,1.95,606],[2,1.85,444]],"ltp":2.04,"tv":81.54,"id":40096580},{"batl":[[0,1.99,11.1]],"ltp":1.97,"tv":1305.67,"id":40096582}]}]}
{"op":"mcm","clk":"11838448312","pt":1723496045845,"mc":[{"id":"1.231730206","rc":[{"batb":[[0,2.1,218.32]],"ltp":2.04,"tv":81.54,"id":40096580}]}]}
{"op":"mcm","clk":"11838448343","pt":1723496046664,"mc":[{"id":"1.231730206","rc":[{"batl":[[0,1.99,6.71]],"ltp":1.97,"tv":1305.67,"id":40096582}]}]}
{"op":"mcm","clk":"11838448446","pt":1723496049230,"mc":[{"id":"1.231730206","rc":[{"batl":[[0,1.9,7.03]],"ltp":1.97,"tv":1305.67,"id":40096582}]}]}
{"op":"mcm","clk":"11838448744","pt":1723496056984,"mc":[{"id":"1.231730206","rc":[{"batb":[[0,2.16,218.32]],"ltp":2.04,"tv":81.54,"id":40096580},{"batl":[[0,1.87,4.67],[1,1.9,7.03]],"ltp":1.97,"tv":1305.67,"id":40096582}]}]}
{"op":"mcm","clk":"11838448792","pt":1723496058162,"mc":[{"id":"1.231730206","rc":[{"batl":[[1,1.9,0]],"ltp":1.97,"tv":1305.67,"id":40096582}]}]}
{"op":"mcm","clk":"11838448951","pt":1723496062582,"mc":[{"id":"1.231730206","rc":[{"batl":[[0,1.86,7.17],[1,1.87,4.67]],"ltp":1.97,"tv":1305.67,"id":40096582}]}]}
{"op":"mcm","clk":"11838449181","pt":1723496069254,"mc":[{"id":"1.231730206","rc":[{"batb":[[0,2.2,218.32]],"ltp":2.04,"tv":81.54,"id":40096580}]}]}
{"op":"mcm","clk":"11838449243","pt":1723496070589,"mc":[{"id":"1.231730206","rc":[{"batl":[[0,1.83,7.29]],"ltp":1.97,"tv":1305.67,"id":40096582}]}]}
{"op":"mcm","clk":"11838450157","pt":1723496092175,"mc":[{"id":"1.231730206","rc":[{"batb":[[0,1.95,606],[1,1.85,444],[2,1.74,17.32]],"ltp":2.04,"tv":81.54,"id":40096580},{"batl":[[1,1.87,0]],"ltp":1.97,"tv":1305.67,"id":40096582}]}]}
{"op":"mcm","clk":"11838450170","pt":1723496092383,"mc":[{"id":"1.231730206","rc":[{"batl":[[0,2.04,4.28]],"ltp":1.97,"tv":1305.67,"id":40096582}]}]}
{"op":"mcm","clk":"11838450251","pt":1723496094082,"mc":[{"id":"1.231730206","rc":[{"batl":[[0,2.04,10.82]],"ltp":1.97,"tv":1305.67,"id":40096582}]}]}
{"op":"mcm","clk":"11838450872","pt":1723496108814,"mc":[{"id":"1.231730206","rc":[{"batb":[[0,1.82,218.32],[1,1.8,555],[2,1.79,493.04]],"ltp":1.97,"tv":1305.67,"id":40096582}]}]}
{"op":"mcm","clk":"11838451451","pt":1723496123233,"mc":[{"id":"1.231730206","rc":[{"batb":[[0,1.8,555],[1,1.79,493.04],[2,1.74,17.32]],"ltp":1.97,"tv":1305.67,"id":40096582}]}]}
{"op":"mcm","clk":"11838451527","pt":1723496125027,"mc":[{"id":"1.231730206","rc":[{"batl":[[0,2.04,27.95]],"ltp":1.97,"tv":1305.67,"id":40096582}]}]}
{"op":"mcm","clk":"11838458678","pt":1723496319817,"mc":[{"id":"1.231730206","rc":[{"batb":[[0,2.2,218.32],[1,1.95,606],[2,1.85,444]],"ltp":2.04,"tv":81.54,"id":40096580}]}]}
{"op":"mcm","clk":"11838458708","pt":1723496320994,"mc":[{"id":"1.231730206","rc":[{"batl":[[0,1.83,12.06]],"ltp":1.97,"tv":1305.67,"id":40096582}]}]}
{"op":"mcm","clk":"11838458746","pt":1723496322225,"mc":[{"id":"1.231730206","rc":[{"batl":[[1,1.87,4.67]],"ltp":1.97,"tv":1305.67,"id":40096582}]}]}
{"op":"mcm","clk":"11838459641","pt":1723496352008,"mc":[{"id":"1.231730206","rc":[{"batl":[[0,1.83,29.19]],"ltp":1.97,"tv":1305.67,"id":40096582}]}]}
{"op":"mcm","clk":"11838463310","pt":1723496446123,"mc":[{"id":"1.231730206","rc":[{"trd":[[2.04,9.66]],"batb":[[0,1.95,606],[1,1.85,444],[2,1.74,17.32]],"ltp":2.04,"tv":81.55,"id":40096580},{"trd":[[1.87,23.62],[1.91,1265.27]],"batl":[[0,1.83,29.19],[1,1.87,4.67]],"ltp":1.97,"tv":1305.83,"id":40096582}],"tv":1387.39}]}
{"op":"mcm","clk":"11838463410","pt":1723496448027,"mc":[{"id":"1.231730206","rc":[{"batl":[[0,1.83,24.42]],"ltp":1.97,"tv":1305.83,"id":40096582}]}]}
{"op":"mcm","clk":"11838463451","pt":1723496449204,"mc":[{"id":"1.231730206","rc":[{"batl":[[0,1.87,4.67],[1,1.87,0]],"ltp":1.97,"tv":1305.83,"id":40096582}]}]}
{"op":"mcm","clk":"11838463455","pt":1723496449306,"mc":[{"id":"1.231730206","rc":[{"batl":[[1,2.04,6.54]],"ltp":1.97,"tv":1305.83,"id":40096582}]}]}
{"op":"mcm","clk":"11838463500","pt":1723496450693,"mc":[{"id":"1.231730206","rc":[{"batl":[[0,2.04,10.82],[1,2.04,0]],"ltp":1.97,"tv":1305.83,"id":40096582}]}]}
{"op":"mcm","clk":"11838463727","pt":1723496457907,"mc":[{"id":"1.231730206","rc":[{"batb":[[0,1.81,10],[1,1.8,555],[2,1.79,493.04]],"ltp":1.97,"tv":1305.83,"id":40096582}]}]}
{"op":"mcm","clk":"11838464042","pt":1723496467545,"mc":[{"id":"1.231730206","rc":[{"batb":[[0,1.8,555],[1,1.79,493.04],[2,1.74,17.32]],"ltp":1.97,"tv":1305.83,"id":40096582}]}]}
{"op":"mcm","clk":"11838464256","pt":1723496470943,"mc":[{"id":"1.231730206","rc":[{"batb":[[0,1.82,10],[1,1.8,555],[2,1.79,493.04]],"ltp":1.97,"tv":1305.83,"id":40096582}]}]}
{"op":"mcm","clk":"11838464621","pt":1723496480055,"mc":[{"id":"1.231730206","rc":[{"batl":[[0,2.04,27.95]],"ltp":1.97,"tv":1305.83,"id":40096582}]}]}
{"op":"mcm","clk":"11838464765","pt":1723496482737,"mc":[{"id":"1.231730206","rc":[{"batb":[[0,1.8,555],[1,1.79,493.04],[2,1.74,17.32]],"ltp":1.97,"tv":1305.83,"id":40096582}]}]}
{"op":"mcm","clk":"11838464937","pt":1723496485764,"mc":[{"id":"1.231730206","rc":[{"batb":[[0,1.83,10],[1,1.8,555],[2,1.79,493.04]],"ltp":1.97,"tv":1305.83,"id":40096582}]}]}
{"op":"mcm","clk":"11838465429","pt":1723496498757,"mc":[{"id":"1.231730206","rc":[{"batb":[[0,1.8,555],[1,1.79,493.04],[2,1.74,17.32]],"ltp":1.97,"tv":1305.83,"id":40096582}]}]}
{"op":"mcm","clk":"11838465566","pt":1723496502553,"mc":[{"id":"1.231730206","rc":[{"batb":[[0,1.84,10],[1,1.8,555],[2,1.79,493.04]],"ltp":1.97,"tv":1305.83,"id":40096582}]}]}
{"op":"mcm","clk":"11838465990","pt":1723496513382,"mc":[{"id":"1.231730206","rc":[{"batb":[[0,1.8,555],[1,1.79,493.04],[2,1.74,17.32]],"ltp":1.97,"tv":1305.83,"id":40096582}]}]}
{"op":"mcm","clk":"11838466045","pt":1723496515273,"mc":[{"id":"1.231730206","rc":[{"batl":[[0,2.24,17.13]],"ltp":2.04,"tv":81.55,"id":40096580}]}]}
{"op":"mcm","clk":"11838466185","pt":1723496520398,"mc":[{"id":"1.231730206","rc":[{"batb":[[0,1.85,10],[1,1.8,555],[2,1.79,493.04]],"ltp":1.97,"tv":1305.83,"id":40096582}]}]}
{"op":"mcm","clk":"11838466286","pt":1723496523378,"mc":[{"id":"1.231730206","rc":[{"batb":[[0,1.96,10],[1,1.95,606],[2,1.85,444]],"ltp":2.04,"tv":81.55,"id":40096580}]}]}
{"op":"mcm","clk":"11838466539","pt":1723496531312,"mc":[{"id":"1.231730206","rc":[{"batb":[[0,1.8,555],[1,1.79,493.04],[2,1.74,17.32]],"ltp":1.97,"tv":1305.83,"id":40096582}]}]}
{"op":"mcm","clk":"11838466688","pt":1723496535012,"mc":[{"id":"1.231730206","rc":[{"batb":[[0,1.95,606],[1,1.85,444],[2,1.74,17.32]],"ltp":2.04,"tv":81.55,"id":40096580},{"batb":[[0,1.86,10],[1,1.8,555],[2,1.79,493.04]],"ltp":1.97,"tv":1305.83,"id":40096582}]}]}
{"op":"mcm","clk":"11838466778","pt":1723496537488,"mc":[{"id":"1.231730206","rc":[{"batb":[[0,1.97,10],[1,1.95,606],[2,1.85,444]],"ltp":2.04,"tv":81.55,"id":40096580}]}]}
{"op":"mcm","clk":"11838467329","pt":1723496553308,"mc":[{"id":"1.231730206","rc":[{"batb":[[0,1.8,555],[1,1.79,493.04],[2,1.74,17.32]],"ltp":1.97,"tv":1305.83,"id":40096582}]}]}
{"op":"mcm","clk":"11838467390","pt":1723496556126,"mc":[{"id":"1.231730206","rc":[{"batb":[[0,1.95,606],[1,1.85,444],[2,1.74,17.32]],"ltp":2.04,"tv":81.55,"id":40096580}]}]}
{"op":"mcm","clk":"11838467411","pt":1723496557003,"mc":[{"id":"1.231730206","rc":[{"batb":[[0,1.87,10],[1,1.8,555],[2,1.79,493.04]],"ltp":1.97,"tv":1305.83,"id":40096582}]}]}
{"op":"mcm","clk":"11838467486","pt":1723496559053,"mc":[{"id":"1.231730206","rc":[{"batb":[[0,1.98,10],[1,1.95,606],[2,1.85,444]],"ltp":2.04,"tv":81.55,"id":40096580}]}]}
{"op":"mcm","clk":"11838467899","pt":1723496570047,"mc":[{"id":"1.231730206","rc":[{"batb":[[0,1.8,555],[1,1.79,493.04],[2,1.74,17.32]],"ltp":1.97,"tv":1305.83,"id":40096582}]}]}
{"op":"mcm","clk":"11838468006","pt":1723496572261,"mc":[{"id":"1.231730206","rc":[{"batb":[[0,1.95,606],[1,1.85,444],[2,1.74,17.32]],"batl":[[0,2.24,17.13]],"ltp":2.04,"tv":81.55,"id":40096580}]}]}
{"op":"mcm","clk":"11838468017","pt":1723496572422,"mc":[{"id":"1.231730206","rc":[{"batb":[[0,1.88,10],[1,1.8,555],[2,1.79,493.04]],"ltp":1.97,"tv":1305.83,"id":40096582}]}]}
{"op":"mcm","clk":"11838468388","pt":1723496582026,"mc":[{"id":"1.231730206","rc":[{"batb":[[0,1.99,10],[1,1.95,606],[2,1.85,444]],"ltp":2.04,"tv":81.55,"id":40096580}]}]}
{"op":"mcm","clk":"11838468506","pt":1723496585733,"mc":[{"id":"1.231730206","rc":[{"batb":[[0,1.8,555],[1,1.79,493.04],[2,1.74,17.32]],"ltp":1.97,"tv":1305.83,"id":40096582}]}]}
{"op":"mcm","clk":"11838468633","pt":1723496588864,"mc":[{"id":"1.231730206","rc":[{"batb":[[0,1.89,10],[1,1.8,555],[2,1.79,493.04]],"ltp":1.97,"tv":1305.83,"id":40096582}]}]}
{"op":"mcm","clk":"11838468864","pt":1723496595751,"mc":[{"id":"1.231730206","rc":[{"batb":[[0,1.95,606],[1,1.85,444],[2,1.74,17.32]],"ltp":2.04,"tv":81.55,"id":40096580}]}]}
{"op":"mcm","clk":"11838469132","pt":1723496602371,"mc":[{"id":"1.231730206","rc":[{"batb":[[0,1.8,555],[1,1.79,493.04],[2,1.74,17.32]],"ltp":1.97,"tv":1305.83,"id":40096582}]}]}
{"op":"mcm","clk":"11838469217","pt":1723496604780,"mc":[{"id":"1.231730206","rc":[{"batb":[[0,1.9,10],[1,1.8,555],[2,1.79,493.04]],"ltp":1.97,"tv":1305.83,"id":40096582}]}]}
{"op":"mcm","clk":"11838469841","pt":1723496620172,"mc":[{"id":"1.231730206","rc":[{"batb":[[0,1.8,555],[1,1.79,493.04],[2,1.74,17.32]],"ltp":1.97,"tv":1305.83,"id":40096582}]}]}
{"op":"mcm","clk":"11838469946","pt":1723496623299,"mc":[{"id":"1.231730206","rc":[{"batb":[[0,1.91,10],[1,1.8,555],[2,1.79,493.04]],"ltp":1.97,"tv":1305.83,"id":40096582}]}]}
{"op":"mcm","clk":"11838470568","pt":1723496638721,"mc":[{"id":"1.231730206","rc":[{"batb":[[0,1.8,555],[1,1.79,493.04],[2,1.74,17.32]],"ltp":1.97,"tv":1305.83,"id":40096582}]}]}
{"op":"mcm","clk":"11838470588","pt":1723496639285,"mc":[{"id":"1.231730206","rc":[{"batl":[[0,2.24,17.13]],"ltp":2.04,"tv":81.55,"id":40096580}]}]}
{"op":"mcm","clk":"11838470641","pt":1723496641187,"mc":[{"id":"1.231730206","rc":[{"batb":[[0,1.92,10],[1,1.8,555],[2,1.79,493.04]],"ltp":1.97,"tv":1305.83,"id":40096582}]}]}
{"op":"mcm","clk":"11838470998","pt":1723496652316,"mc":[{"id":"1.231730206","rc":[{"batb":[[0,1.96,10],[1,1.95,606],[2,1.85,444]],"ltp":2.04,"tv":81.55,"id":40096580}]}]}
{"op":"mcm","clk":"11838471163","pt":1723496657556,"mc":[{"id":"1.231730206","rc":[{"batb":[[0,1.8,555],[1,1.79,493.04],[2,1.74,17.32]],"ltp":1.97,"tv":1305.83,"id":40096582}]}]}
{"op":"mcm","clk":"11838471328","pt":1723496660740,"mc":[{"id":"1.231730206","rc":[{"batb":[[0,1.93,10],[1,1.8,555],[2,1.79,493.04]],"ltp":1.97,"tv":1305.83,"id":40096582}]}]}
{"op":"mcm","clk":"11838471640","pt":1723496669880,"mc":[{"id":"1.231730206","rc":[{"batb":[[0,1.95,606],[1,1.85,444],[2,1.74,17.32]],"ltp":2.04,"tv":81.55,"id":40096580}]}]}
{"op":"mcm","clk":"11838471922","pt":1723496678562,"mc":[{"id":"1.231730206","rc":[{"batb":[[0,1.8,555],[1,1.79,493.04],[2,1.74,17.32]],"ltp":1.97,"tv":1305.83,"id":40096582}]}]}
{"op":"mcm","clk":"11838471991","pt":1723496680867,"mc":[{"id":"1.231730206","rc":[{"batb":[[0,1.94,10],[1,1.8,555],[2,1.79,493.04]],"ltp":1.97,"tv":1305.83,"id":40096582}]}]}
{"op":"mcm","clk":"11838472710","pt":1723496698781,"mc":[{"id":"1.231730206","rc":[{"batb":[[0,1.8,555],[1,1.79,493.04],[2,1.74,17.32]],"ltp":1.97,"tv":1305.83,"id":40096582}]}]}
{"op":"mcm","clk":"11838472780","pt":1723496700588,"mc":[{"id":"1.231730206","rc":[{"batl":[[0,2.24,17.13]],"ltp":2.04,"tv":81.55,"id":40096580}]}]}
{"op":"mcm","clk":"11838472908","pt":1723496703175,"mc":[{"id":"1.231730206","rc":[{"batb":[[0,1.95,10],[1,1.8,555],[2,1.79,493.04]],"ltp":1.97,"tv":1305.83,"id":40096582}]}]}
{"op":"mcm","clk":"11838473394","pt":1723496716221,"mc":[{"id":"1.231730206","rc":[{"batb":[[0,1.96,10],[1,1.95,606],[2,1.85,444]],"ltp":2.04,"tv":81.55,"id":40096580}]}]}
{"op":"mcm","clk":"11838473603","pt":1723496720989,"mc":[{"id":"1.231730206","rc":[{"batb":[[0,1.8,555],[1,1.79,493.04],[2,1.74,17.32]],"ltp":1.97,"tv":1305.83,"id":40096582}]}]}
{"op":"mcm","clk":"11838473736","pt":1723496723407,"mc":[{"id":"1.231730206","rc":[{"batb":[[0,1.96,10],[1,1.8,555],[2,1.79,493.04]],"ltp":1.97,"tv":1305.83,"id":40096582}]}]}
{"op":"mcm","clk":"11838474141","pt":1723496735306,"mc":[{"id":"1.231730206","rc":[{"batb":[[0,1.95,606],[1,1.85,444],[2,1.74,17.32]],"ltp":2.04,"tv":81.55,"id":40096580}]}]}
{"op":"mcm","clk":"11838474432","pt":1723496743816,"mc":[{"id":"1.231730206","rc":[{"batb":[[0,1.8,555],[1,1.79,493.04],[2,1.74,17.32]],"ltp":1.97,"tv":1305.83,"id":40096582}]}]}
{"op":"mcm","clk":"11838474617","pt":1723496748638,"mc":[{"id":"1.231730206","rc":[{"batl":[[0,2.24,17.13]],"ltp":2.04,"tv":81.55,"id":40096580},{"batb":[[0,1.97,10],[1,1.8,555],[2,1.79,493.04]],"ltp":1.97,"tv":1305.83,"id":40096582}]}]}
{"op":"mcm","clk":"11838474699","pt":1723496751251,"mc":[{"id":"1.231730206","rc":[{"trd":[[1.97,30]],"batb":[[0,1.8,555],[1,1.79,493.04],[2,1.74,17.32]],"batl":[[0,1.97,2.84],[1,2.04,27.95]],"ltp":1.97,"tv":1325.84,"id":40096582}],"tv":1407.39}]}
{"op":"mcm","clk":"11838474980","pt":1723496758937,"mc":[{"id":"1.231730206","rc":[{"batl":[[0,2.04,27.95],[1,2.04,0]],"ltp":1.97,"tv":1325.84,"id":40096582}]}]}
{"op":"mcm","clk":"11838475261","pt":1723496765866,"mc":[{"id":"1.231730206","rc":[{"batb":[[0,1.96,10],[1,1.95,606],[2,1.85,444]],"ltp":2.04,"tv":81.55,"id":40096580}]}]}
{"op":"mcm","clk":"11838475798","pt":1723496777135,"mc":[{"id":"1.231730206","rc":[{"batb":[[0,1.81,10],[1,1.8,555],[2,1.79,493.04]],"ltp":1.97,"tv":1325.84,"id":40096582}]}]}
{"op":"mcm","clk":"11838476299","pt":1723496788280,"mc":[{"id":"1.231730206","rc":[{"batb":[[0,1.95,606],[1,1.85,444],[2,1.74,17.32]],"ltp":2.04,"tv":81.55,"id":40096580}]}]}
{"op":"mcm","clk":"11838476621","pt":1723496799581,"mc":[{"id":"1.231730206","rc":[{"batb":[[0,1.8,555],[1,1.79,493.04],[2,1.74,17.32]],"ltp":1.97,"tv":1325.84,"id":40096582}]}]}
{"op":"mcm","clk":"11838476688","pt":1723496801781,"mc":[{"id":"1.231730206","rc":[{"batb":[[0,1.82,10],[1,1.8,555],[2,1.79,493.04]],"ltp":1.97,"tv":1325.84,"id":40096582}]}]}
{"op":"mcm","clk":"11838476820","pt":1723496806079,"mc":[{"id":"1.231730206","rc":[{"batl":[[0,2.24,17.13]],"ltp":2.04,"tv":81.55,"id":40096580}]}]}
{"op":"mcm","clk":"11838477426","pt":1723496826392,"mc":[{"id":"1.231730206","rc":[{"batb":[[0,1.8,555],[1,1.79,493.04],[2,1.74,17.32]],"ltp":1.97,"tv":1325.84,"id":40096582}]}]}
{"op":"mcm","clk":"11838477482","pt":1723496828187,"mc":[{"id":"1.231730206","rc":[{"batb":[[0,1.96,10],[1,1.95,606],[2,1.85,444]],"ltp":2.04,"tv":81.55,"id":40096580}]}]}
{"op":"mcm","clk":"11838477534","pt":1723496829727,"mc":[{"id":"1.231730206","rc":[{"batb":[[0,1.83,10],[1,1.8,555],[2,1.79,493.04]],"ltp":1.97,"tv":1325.84,"id":40096582}]}]}
{"op":"mcm","clk":"11838478508","pt":1723496861528,"mc":[{"id":"1.231730206","rc":[{"batb":[[0,1.95,606],[1,1.85,444],[2,1.74,17.32]],"ltp":2.04,"tv":81.55,"id":40096580}]}]}
{"op":"mcm","clk":"11838478564","pt":1723496862961,"mc":[{"id":"1.231730206","rc":[{"batb":[[0,1.8,555],[1,1.79,493.04],[2,1.74,17.32]],"ltp":1.97,"tv":1325.84,"id":40096582}]}]}
{"op":"mcm","clk":"11838478590","pt":1723496863730,"mc":[{"id":"1.231730206","rc":[{"batb":[[0,1.97,10],[1,1.95,606],[2,1.85,444]],"ltp":2.04,"tv":81.55,"id":40096580}]}]}
{"op":"mcm","clk":"11838478624","pt":1723496865322,"mc":[{"id":"1.231730206","rc":[{"batb":[[0,1.84,10],[1,1.8,555],[2,1.79,493.04]],"ltp":1.97,"tv":1325.84,"id":40096582}]}]}
{"op":"mcm","clk":"11838479359","pt":1723496890360,"mc":[{"id":"1.231730206","rc":[{"batb":[[0,1.95,606],[1,1.85,444],[2,1.74,17.32]],"ltp":2.04,"tv":81.55,"id":40096580}]}]}
{"op":"mcm","clk":"11838479403","pt":1723496892047,"mc":[{"id":"1.231730206","rc":[{"batb":[[0,1.8,555],[1,1.79,493.04],[2,1.74,17.32]],"ltp":1.97,"tv":1325.84,"id":40096582}]}]}
{"op":"mcm","clk":"11838479459","pt":1723496894550,"mc":[{"id":"1.231730206","rc":[{"batb":[[0,1.98,10],[1,1.95,606],[2,1.85,444]],"ltp":2.04,"tv":81.55,"id":40096580},{"batb":[[0,1.85,10],[1,1.8,555],[2,1.79,493.04]],"ltp":1.97,"tv":1325.84,"id":40096582}]}]}
{"op":"mcm","clk":"11838480549","pt":1723496925407,"mc":[{"id":"1.231730206","rc":[{"batb":[[0,1.95,606],[1,1.85,444],[2,1.74,17.32]],"ltp":2.04,"tv":81.55,"id":40096580},{"batb":[[0,1.8,555],[1,1.79,493.04],[2,1.74,17.32]],"ltp":1.97,"tv":1325.84,"id":40096582}]}]}
{"op":"mcm","clk":"11838480599","pt":1723496927712,"mc":[{"id":"1.231730206","rc":[{"batb":[[0,1.99,10],[1,1.95,606],[2,1.85,444]],"ltp":2.04,"tv":81.55,"id":40096580},{"batb":[[0,1.86,10],[1,1.8,555],[2,1.79,493.04]],"ltp":1.97,"tv":1325.84,"id":40096582}]}]}
{"op":"mcm","clk":"11838481331","pt":1723496960331,"mc":[{"id":"1.231730206","rc":[{"batb":[[0,1.95,606],[1,1.85,444],[2,1.74,17.32]],"ltp":2.04,"tv":81.55,"id":40096580},{"batb":[[0,1.8,555],[1,1.79,493.04],[2,1.74,17.32]],"ltp":1.97,"tv":1325.84,"id":40096582}]}]}
{"op":"mcm","clk":"11838481417","pt":1723496963456,"mc":[{"id":"1.231730206","rc":[{"batb":[[0,2,10],[1,1.95,606],[2,1.85,444]],"ltp":2.04,"tv":81.55,"id":40096580},{"batb":[[0,1.87,10],[1,1.8,555],[2,1.79,493.04]],"ltp":1.97,"tv":1325.84,"id":40096582}]}]}
{"op":"mcm","clk":"11838482340","pt":1723496997953,"mc":[{"id":"1.231730206","rc":[{"batb":[[0,1.95,606],[1,1.85,444],[2,1.74,17.32]],"ltp":2.04,"tv":81.55,"id":40096580},{"batb":[[0,1.8,555],[1,1.79,493.04],[2,1.74,17.32]],"ltp":1.97,"tv":1325.84,"id":40096582}]}]}
{"op":"mcm","clk":"11838482367","pt":1723496998885,"mc":[{"id":"1.231730206","rc":[{"batl":[[0,2.24,17.27]],"ltp":2.04,"tv":81.55,"id":40096580}]}]}
{"op":"mcm","clk":"11838482438","pt":1723497001287,"mc":[{"id":"1.231730206","rc":[{"batb":[[0,1.88,10],[1,1.8,555],[2,1.79,493.04]],"ltp":1.97,"tv":1325.84,"id":40096582}]}]}
{"op":"mcm","clk":"11838483280","pt":1723497034689,"mc":[{"id":"1.231730206","rc":[{"batb":[[0,1.96,10],[1,1.95,606],[2,1.85,444]],"ltp":2.04,"tv":81.55,"id":40096580}]}]}
{"op":"mcm","clk":"11838483371","pt":1723497039815,"mc":[{"id":"1.231730206","rc":[{"batb":[[0,1.8,555],[1,1.79,493.04],[2,1.74,17.32]],"ltp":1.97,"tv":1325.84,"id":40096582}]}]}
{"op":"mcm","clk":"11838483443","pt":1723497042029,"mc":[{"id":"1.231730206","rc":[{"batl":[[0,2.24,17.13]],"ltp":2.04,"tv":81.55,"id":40096580},{"batb":[[0,1.89,10],[1,1.8,555],[2,1.79,493.04]],"ltp":1.97,"tv":1325.84,"id":40096582}]}]}
{"op":"mcm","clk":"11838484200","pt":1723497073173,"mc":[{"id":"1.231730206","rc":[{"batb":[[0,1.95,606],[1,1.85,444],[2,1.74,17.32]],"ltp":2.04,"tv":81.55,"id":40096580}]}]}
{"op":"mcm","clk":"11838484265","pt":1723497076859,"mc":[{"id":"1.231730206","rc":[{"batb":[[0,1.97,10],[1,1.95,606],[2,1.85,444]],"ltp":2.04,"tv":81.55,"id":40096580}]}]}
{"op":"mcm","clk":"11838484352","pt":1723497080346,"mc":[{"id":"1.231730206","rc":[{"batb":[[0,1.8,555],[1,1.79,493.04],[2,1.74,17.32]],"ltp":1.97,"tv":1325.84,"id":40096582}]}]}
{"op":"mcm","clk":"11838484415","pt":1723497082853,"mc":[{"id":"1.231730206","rc":[{"batb":[[0,1.9,10],[1,1.8,555],[2,1.79,493.04]],"ltp":1.97,"tv":1325.84,"id":40096582}]}]}
{"op":"mcm","clk":"11838485364","pt":1723497112875,"mc":[{"id":"1.231730206","rc":[{"batb":[[0,1.95,606],[1,1.85,444],[2,1.74,17.32]],"ltp":2.04,"tv":81.55,"id":40096580}]}]}
{"op":"mcm","clk":"11838485508","pt":1723497119176,"mc":[{"id":"1.231730206","rc":[{"batb":[[0,1.8,555],[1,1.79,493.04],[2,1.74,17.32]],"ltp":1.97,"tv":1325.84,"id":40096582}]}]}
{"op":"mcm","clk":"11838485555","pt":1723497121072,"mc":[{"id":"1.231730206","rc":[{"batl":[[0,2.24,33.9]],"ltp":2.04,"tv":81.55,"id":40096580}]}]}
{"op":"mcm","clk":"11838485564","pt":1723497121789,"mc":[{"id":"1.231730206","rc":[{"batb":[[0,1.91,10],[1,1.8,555],[2,1.79,493.04]],"ltp":1.97,"tv":1325.84,"id":40096582}]}]}
{"op":"mcm","clk":"11838486293","pt":1723497152745,"mc":[{"id":"1.231730206","rc":[{"batb":[[0,1.96,10],[1,1.95,606],[2,1.85,444]],"ltp":2.04,"tv":81.55,"id":40096580}]}]}
{"op":"mcm","clk":"11838486385","pt":1723497156948,"mc":[{"id":"1.231730206","rc":[{"batb":[[0,1.8,555],[1,1.79,493.04],[2,1.74,17.32]],"ltp":1.97,"tv":1325.84,"id":40096582}]}]}
{"op":"mcm","clk":"11838486456","pt":1723497159614,"mc":[{"id":"1.231730206","rc":[{"batb":[[0,1.92,10],[1,1.8,555],[2,1.79,493.04]],"ltp":1.97,"tv":1325.84,"id":40096582}]}]}
{"op":"mcm","clk":"11838494254","pt":1723497193083,"mc":[{"id":"1.231730206","rc":[{"batb":[[0,1.95,606],[1,1.85,444],[2,1.74,17.32]],"ltp":2.04,"tv":81.55,"id":40096580}]}]}
{"op":"mcm","clk":"11838494343","pt":1723497198653,"mc":[{"id":"1.231730206","rc":[{"batb":[[0,1.8,555],[1,1.79,493.04],[2,1.74,17.32]],"ltp":1.97,"tv":1325.84,"id":40096582}]}]}
{"op":"mcm","clk":"11838494381","pt":1723497200292,"mc":[{"id":"1.231730206","rc":[{"batl":[[0,2.24,17.13]],"ltp":2.04,"tv":81.55,"id":40096580}]}]}
{"op":"mcm","clk":"11838494420","pt":1723497201985,"mc":[{"id":"1.231730206","rc":[{"batb":[[0,1.93,10],[1,1.8,555],[2,1.79,493.04]],"ltp":1.97,"tv":1325.84,"id":40096582}]}]}
{"op":"mcm","clk":"11838495129","pt":1723497231845,"mc":[{"id":"1.231730206","rc":[{"batb":[[0,1.96,10],[1,1.95,606],[2,1.85,444]],"ltp":2.04,"tv":81.55,"id":40096580}]}]}
{"op":"mcm","clk":"11838495253","pt":1723497237204,"mc":[{"id":"1.231730206","rc":[{"batl":[[0,2.24,17.16]],"ltp":2.04,"tv":81.55,"id":40096580},{"batb":[[0,1.8,555],[1,1.79,493.04],[2,1.74,17.32]],"ltp":1.97,"tv":1325.84,"id":40096582}]}]}
{"op":"mcm","clk":"11838495290","pt":1723497238899,"mc":[{"id":"1.231730206","rc":[{"batb":[[0,1.94,10],[1,1.8,555],[2,1.79,493.04]],"ltp":1.97,"tv":1325.84,"id":40096582}]}]}
{"op":"mcm","clk":"11838495991","pt":1723497266531,"mc":[{"id":"1.231730206","rc":[{"batb":[[0,1.95,606],[1,1.85,444],[2,1.74,17.32]],"ltp":2.04,"tv":81.55,"id":40096580}]}]}
{"op":"mcm","clk":"11838496142","pt":1723497269556,"mc":[{"id":"1.231730206","rc":[{"batb":[[0,1.97,10],[1,1.95,606],[2,1.85,444]],"ltp":2.04,"tv":81.55,"id":40096580}]}]}
{"op":"mcm","clk":"11838496320","pt":1723497273833,"mc":[{"id":"1.231730206","rc":[{"batb":[[0,1.8,555],[1,1.79,493.04],[2,1.74,17.32]],"ltp":1.97,"tv":1325.84,"id":40096582}]}]}
{"op":"mcm","clk":"11838496348","pt":1723497274760,"mc":[{"id":"1.231730206","rc":[{"batl":[[0,2.24,17.13]],"ltp":2.04,"tv":81.55,"id":40096580}]}]}
{"op":"mcm","clk":"11838496391","pt":1723497276554,"mc":[{"id":"1.231730206","rc":[{"batb":[[0,1.95,10],[1,1.8,555],[2,1.79,493.04]],"ltp":1.97,"tv":1325.84,"id":40096582}]}]}
{"op":"mcm","clk":"11838497084","pt":1723497303275,"mc":[{"id":"1.231730206","rc":[{"batb":[[0,1.95,606],[1,1.85,444],[2,1.74,17.32]],"ltp":2.04,"tv":81.55,"id":40096580}]}]}
{"op":"mcm","clk":"11838497164","pt":1723497306090,"mc":[{"id":"1.231730206","rc":[{"batb":[[0,1.98,10],[1,1.95,606],[2,1.85,444]],"ltp":2.04,"tv":81.55,"id":40096580}]}]}
{"op":"mcm","clk":"11838497256","pt":1723497310084,"mc":[{"id":"1.231730206","rc":[{"batb":[[0,1.8,555],[1,1.79,493.04],[2,1.74,17.32]],"ltp":1.97,"tv":1325.84,"id":40096582}]}]}
{"op":"mcm","clk":"11838497333","pt":1723497312904,"mc":[{"id":"1.231730206","rc":[{"batb":[[0,1.96,10],[1,1.8,555],[2,1.79,493.04]],"ltp":1.97,"tv":1325.84,"id":40096582}]}]}
{"op":"mcm","clk":"11838498150","pt":1723497340044,"mc":[{"id":"1.231730206","rc":[{"batb":[[0,1.95,606],[1,1.85,444],[2,1.74,17.32]],"ltp":2.04,"tv":81.55,"id":40096580}]}]}
{"op":"mcm","clk":"11838498409","pt":1723497348223,"mc":[{"id":"1.231730206","rc":[{"batl":[[0,2.24,16.85]],"ltp":2.04,"tv":81.55,"id":40096580},{"batb":[[0,1.8,555],[1,1.79,493.04],[2,1.74,17.32]],"ltp":1.97,"tv":1325.84,"id":40096582}]}]}
{"op":"mcm","clk":"11838498447","pt":1723497349044,"mc":[{"id":"1.231730206","rc":[{"batl":[[0,2.24,33.97]],"ltp":2.04,"tv":81.55,"id":40096580}]}]}
{"op":"mcm","clk":"11838498477","pt":1723497349864,"mc":[{"id":"1.231730206","rc":[{"batl":[[0,2.24,17.13]],"ltp":2.04,"tv":81.55,"id":40096580},{"batb":[[0,1.97,10],[1,1.8,555],[2,1.79,493.04]],"ltp":1.97,"tv":1325.84,"id":40096582}]}]}
{"op":"mcm","clk":"11838498667","pt":1723497354941,"mc":[{"id":"1.231730206","rc":[{"trd":[[1.97,50.01]],"batb":[[0,1.8,555],[1,1.79,493.04],[2,1.74,17.32]],"batl":[[0,1.97,8.84],[1,2.04,27.95]],"ltp":1.97,"tv":1345.84,"id":40096582}],"tv":1427.39}]}
{"op":"mcm","clk":"11838498702","pt":1723497355965,"mc":[{"id":"1.231730206","rc":[{"batl":[[1,2.04,21.41]],"ltp":1.97,"tv":1345.84,"id":40096582}]}]}
{"op":"mcm","clk":"11838499033","pt":1723497368575,"mc":[{"id":"1.231730206","rc":[{"batl":[[0,2.04,21.41],[1,2.04,0]],"ltp":1.97,"tv":1345.84,"id":40096582}]}]}
{"op":"mcm","clk":"11838499058","pt":1723497369556,"mc":[{"id":"1.231730206","rc":[{"batl":[[0,2.04,38.54]],"ltp":1.97,"tv":1345.84,"id":40096582}]}]}
{"op":"mcm","clk":"11838499484","pt":1723497382477,"mc":[{"id":"1.231730206","rc":[{"batb":[[0,1.96,10],[1,1.95,606],[2,1.85,444]],"ltp":2.04,"tv":81.55,"id":40096580}]}]}
{"op":"mcm","clk":"11838499698","pt":1723497390491,"mc":[{"id":"1.231730206","rc":[{"batb":[[0,1.98,10],[1,1.8,555],[2,1.79,493.04]],"ltp":1.97,"tv":1345.84,"id":40096582}]}]}
{"op":"mcm","clk":"11838500618","pt":1723497423318,"mc":[{"id":"1.231730206","rc":[{"batb":[[0,1.95,606],[1,1.85,444],[2,1.74,17.32]],"ltp":2.04,"tv":81.55,"id":40096580}]}]}
{"op":"mcm","clk":"11838500839","pt":1723497429824,"mc":[{"id":"1.231730206","rc":[{"batb":[[0,1.8,555],[1,1.79,493.04],[2,1.74,17.32]],"ltp":1.97,"tv":1345.84,"id":40096582}]}]}
{"op":"mcm","clk":"11838500915","pt":1723497432127,"mc":[{"id":"1.231730206","rc":[{"batl":[[0,2.24,17.13]],"ltp":2.04,"tv":81.55,"id":40096580},{"batl":[[0,1.98,18.84],[1,2.04,38.54]],"ltp":1.97,"tv":1345.84,"id":40096582}]}]}
{"op":"mcm","clk":"11838500974","pt":1723497434019,"mc":[{"id":"1.231730206","rc":[{"batl":[[0,1.97,11.21],[1,1.98,18.84]],"ltp":1.97,"tv":1345.84,"id":40096582}]}]}
{"op":"mcm","clk":"11838501113","pt":1723497438625,"mc":[{"id":"1.231730206","rc":[{"batl":[[1,1.98,0]],"ltp":1.97,"tv":1345.84,"id":40096582}]}]}
{"op":"mcm","clk":"11838501162","pt":1723497439906,"mc":[{"id":"1.231730206","rc":[{"batl":[[0,1.97,6.78],[1,2.04,21.71]],"ltp":1.97,"tv":1345.84,"id":40096582}]}]}
{"op":"mcm","clk":"11838501181","pt":1723497441036,"mc":[{"id":"1.231730206","rc":[{"batl":[[0,2.04,21.71],[1,2.04,0]],"ltp":1.97,"tv":1345.84,"id":40096582}]}]}
{"op":"mcm","clk":"11838501286","pt":1723497444934,"mc":[{"id":"1.231730206","rc":[{"batl":[[0,2.02,6.61],[1,2.04,21.71]],"ltp":1.97,"tv":1345.84,"id":40096582}]}]}
{"op":"mcm","clk":"11838501831","pt":1723497464354,"mc":[{"id":"1.231730206","rc":[{"batb":[[0,1.81,10],[1,1.8,555],[2,1.79,493.04]],"ltp":1.97,"tv":1345.84,"id":40096582}]}]}
{"op":"mcm","clk":"11838501885","pt":1723497466352,"mc":[{"id":"1.231730206","rc":[{"batb":[[0,1.96,10],[1,1.95,606],[2,1.85,444]],"ltp":2.04,"tv":81.55,"id":40096580}]}]}
{"op":"mcm","clk":"11838502256","pt":1723497480893,"mc":[{"id":"1.231730206","rc":[{"batb":[[0,1.9,10.28],[1,1.81,10],[2,1.8,555]],"ltp":1.97,"tv":1345.84,"id":40096582}]}]}
{"op":"mcm","clk":"11838502698","pt":1723497497693,"mc":[{"id":"1.231730206","rc":[{"batb":[[1,1.8,555],[2,1.79,493.04]],"ltp":1.97,"tv":1345.84,"id":40096582}]}]}
{"op":"mcm","clk":"11838502752","pt":1723497499386,"mc":[{"id":"1.231730206","rc":[{"batb":[[0,1.95,606],[1,1.85,444],[2,1.74,17.32]],"ltp":2.04,"tv":81.55,"id":40096580}]}]}
{"op":"mcm","clk":"11838502789","pt":1723497500715,"mc":[{"id":"1.231730206","rc":[{"batb":[[1,1.82,10],[2,1.8,555]],"ltp":1.97,"tv":1345.84,"id":40096582}]}]}
{"op":"mcm","clk":"11838502828","pt":1723497502303,"mc":[{"id":"1.231730206","rc":[{"batb":[[0,1.97,10],[1,1.95,606],[2,1.85,444]],"ltp":2.04,"tv":81.55,"id":40096580}]}]}
{"op":"mcm","clk":"11838503135","pt":1723497510088,"mc":[{"id":"1.231730206","rc":[{"batb":[[0,1.9,95.92]],"ltp":1.97,"tv":1345.84,"id":40096582}]}]}
{"op":"mcm","clk":"11838503894","pt":1723497532621,"mc":[{"id":"1.231730206","rc":[{"batb":[[1,1.8,555],[2,1.79,493.04]],"ltp":1.97,"tv":1345.84,"id":40096582}]}]}
{"op":"mcm","clk":"11838503957","pt":1723497534717,"mc":[{"id":"1.231730206","rc":[{"batb":[[0,1.95,606],[1,1.85,444],[2,1.74,17.32]],"ltp":2.04,"tv":81.55,"id":40096580}]}]}
{"op":"mcm","clk":"11838503969","pt":1723497535432,"mc":[{"id":"1.231730206","rc":[{"batb":[[0,1.91,10],[1,1.9,95.92],[2,1.8,555]],"ltp":1.97,"tv":1345.84,"id":40096582}]}]}
{"op":"mcm","clk":"11838504437","pt":1723497550948,"mc":[{"id":"1.231730206","rc":[{"batb":[[0,1.94,85.64],[1,1.91,10]],"ltp":1.97,"tv":1345.84,"id":40096582}]}]}
{"op":"mcm","clk":"11838504876","pt":1723497567667,"mc":[{"id":"1.231730206","rc":[{"batb":[[1,1.8,555],[2,1.79,493.04]],"ltp":1.97,"tv":1345.84,"id":40096582}]}]}
{"op":"mcm","clk":"11838504962","pt":1723497570790,"mc":[{"id":"1.231730206","rc":[{"batb":[[1,1.92,10],[2,1.8,555]],"ltp":1.97,"tv":1345.84,"id":40096582}]}]}
{"op":"mcm","clk":"11838505091","pt":1723497575187,"mc":[{"id":"1.231730206","rc":[{"batb":[[0,1.92,10],[1,1.8,555],[2,1.79,493.04]],"ltp":1.97,"tv":1345.84,"id":40096582}]}]}
{"op":"mcm","clk":"11838506307","pt":1723497614732,"mc":[{"id":"1.231730206","rc":[{"batl":[[0,2.24,16.93]],"ltp":2.04,"tv":81.55,"id":40096580},{"batb":[[0,1.8,555],[1,1.79,493.04],[2,1.74,17.32]],"ltp":1.97,"tv":1345.84,"id":40096582}]}]}
{"op":"mcm","clk":"11838506346","pt":1723497616829,"mc":[{"id":"1.231730206","rc":[{"batb":[[0,1.93,10],[1,1.8,555],[2,1.79,493.04]],"ltp":1.97,"tv":1345.84,"id":40096582}]}]}
{"op":"mcm","clk":"11838507082","pt":1723497646865,"mc":[{"id":"1.231730206","rc":[{"batb":[[0,1.96,10],[1,1.95,606],[2,1.85,444]],"ltp":2.04,"tv":81.55,"id":40096580}]}]}
{"op":"mcm","clk":"11838507230","pt":1723497651996,"mc":[{"id":"1.231730206","rc":[{"batb":[[0,1.8,555],[1,1.79,493.04],[2,1.74,17.32]],"ltp":1.97,"tv":1345.84,"id":40096582}]}]}
{"op":"mcm","clk":"11838507318","pt":1723497654402,"mc":[{"id":"1.231730206","rc":[{"batb":[[0,1.94,10],[1,1.8,555],[2,1.79,493.04]],"ltp":1.97,"tv":1345.84,"id":40096582}]}]}
{"op":"mcm","clk":"11838507969","pt":1723497679523,"mc":[{"id":"1.231730206","rc":[{"batb":[[0,1.95,606],[1,1.85,444],[2,1.74,17.32]],"ltp":2.04,"tv":81.55,"id":40096580}]}]}
{"op":"mcm","clk":"11838508128","pt":1723497686024,"mc":[{"id":"1.231730206","rc":[{"batb":[[0,1.8,555],[1,1.79,493.04],[2,1.74,17.32]],"ltp":1.97,"tv":1345.84,"id":40096582}]}]}
{"op":"mcm","clk":"11838508190","pt":1723497688328,"mc":[{"id":"1.231730206","rc":[{"batb":[[0,1.95,10],[1,1.8,555],[2,1.79,493.04]],"ltp":1.97,"tv":1345.84,"id":40096582}]}]}
{"op":"mcm","clk":"11838509011","pt":1723497718891,"mc":[{"id":"1.231730206","rc":[{"batb":[[0,1.8,555],[1,1.79,493.04],[2,1.74,17.32]],"ltp":1.97,"tv":1345.84,"id":40096582}]}]}
{"op":"mcm","clk":"11838509032","pt":1723497719762,"mc":[{"id":"1.231730206","rc":[{"batl":[[0,2.24,16.67]],"ltp":2.04,"tv":81.55,"id":40096580}]}]}
{"op":"mcm","clk":"11838509079","pt":1723497721659,"mc":[{"id":"1.231730206","rc":[{"batb":[[0,1.96,10],[1,1.8,555],[2,1.79,493.04]],"ltp":1.97,"tv":1345.84,"id":40096582}]}]}
{"op":"mcm","clk":"11838509651","pt":1723497747098,"mc":[{"id":"1.231730206","rc":[{"batb":[[0,1.96,10],[1,1.95,606],[2,1.85,444]],"ltp":2.04,"tv":81.55,"id":40096580}]}]}
{"op":"mcm","clk":"11838509788","pt":1723497752015,"mc":[{"id":"1.231730206","rc":[{"batb":[[0,1.8,555],[1,1.79,493.04],[2,1.74,17.32]],"ltp":1.97,"tv":1345.84,"id":40096582}]}]}
{"op":"mcm","clk":"11838509848","pt":1723497754724,"mc":[{"id":"1.231730206","rc":[{"batb":[[0,1.97,10],[1,1.8,555],[2,1.79,493.04]],"ltp":1.97,"tv":1345.84,"id":40096582}]}]}
{"op":"mcm","clk":"11838510372","pt":1723497776151,"mc":[{"id":"1.231730206","rc":[{"batb":[[0,1.95,606],[1,1.85,444],[2,1.74,17.32]],"ltp":2.04,"tv":81.55,"id":40096580}]}]}
{"op":"mcm","clk":"11838510562","pt":1723497783431,"mc":[{"id":"1.231730206","rc":[{"batb":[[0,1.8,555],[1,1.79,493.04],[2,1.74,17.32]],"ltp":1.97,"tv":1345.84,"id":40096582}]}]}
{"op":"mcm","clk":"11838511184","pt":1723497808571,"mc":[{"id":"1.231730206","rc":[{"batb":[[0,1.81,10],[1,1.8,555],[2,1.79,493.04]],"ltp":1.97,"tv":1345.84,"id":40096582}]}]}
{"op":"mcm","clk":"11838511345","pt":1723497817165,"mc":[{"id":"1.231730206","rc":[{"batl":[[0,2.24,16.91]],"ltp":2.04,"tv":81.55,"id":40096580}]}]}
{"op":"mcm","clk":"11838511631","pt":1723497829697,"mc":[{"id":"1.231730206","rc":[{"batb":[[0,1.95,95.06],[1,1.81,10],[2,1.8,555]],"ltp":1.97,"tv":1345.84,"id":40096582}]}]}
{"op":"mcm","clk":"11838511781","pt":1723497836088,"mc":[{"id":"1.231730206","rc":[{"batb":[[1,1.8,555],[2,1.79,493.04]],"ltp":1.97,"tv":1345.84,"id":40096582}]}]}
{"op":"mcm","clk":"11838511848","pt":1723497838897,"mc":[{"id":"1.231730206","rc":[{"batb":[[1,1.82,10],[2,1.8,555]],"ltp":1.97,"tv":1345.84,"id":40096582}]}]}
{"op":"mcm","clk":"11838511911","pt":1723497841605,"mc":[{"id":"1.231730206","rc":[{"batb":[[0,1.96,10],[1,1.95,606],[2,1.85,444]],"ltp":2.04,"tv":81.55,"id":40096580}]}]}
{"op":"mcm","clk":"11838512581","pt":1723497867357,"mc":[{"id":"1.231730206","rc":[{"batb":[[1,1.8,555],[2,1.79,493.04]],"ltp":1.97,"tv":1345.84,"id":40096582}]}]}
{"op":"mcm","clk":"11838512687","pt":1723497870820,"mc":[{"id":"1.231730206","rc":[{"batb":[[0,1.95,606],[1,1.85,444],[2,1.74,17.32]],"ltp":2.04,"tv":81.55,"id":40096580},{"batb":[[0,1.96,10],[1,1.95,95.06],[2,1.8,555]],"ltp":1.97,"tv":1345.84,"id":40096582}]}]}
{"op":"mcm","clk":"11838513504","pt":1723497899080,"mc":[{"id":"1.231730206","rc":[{"batb":[[0,1.95,95.06],[1,1.8,555],[2,1.79,493.04]],"ltp":1.97,"tv":1345.84,"id":40096582}]}]}
{"op":"mcm","clk":"11838513633","pt":1723497902264,"mc":[{"id":"1.231730206","rc":[{"batb":[[0,1.97,10],[1,1.95,95.06],[2,1.8,555]],"ltp":1.97,"tv":1345.84,"id":40096582}]}]}
{"op":"mcm","clk":"11838513703","pt":1723497904675,"mc":[{"id":"1.231730206","rc":[{"trd":[[1.97,70.01]],"batb":[[0,1.95,95.06],[1,1.8,555],[2,1.79,493.04]],"batl":[[0,1.97,8.84],[1,2.02,6.61],[2,2.04,21.71]],"ltp":1.97,"tv":1365.84,"id":40096582}],"tv":1447.39}]}
{"op":"mcm","clk":"11838513747","pt":1723497906003,"mc":[{"id":"1.231730206","rc":[{"batl":[[2,2.04,4.28]],"ltp":1.97,"tv":1365.84,"id":40096582}]}]}
{"op":"mcm","clk":"11838515100","pt":1723497958134,"mc":[{"id":"1.231730206","rc":[{"batl":[[0,2.02,6.61],[1,2.04,4.28],[2,2.04,0]],"ltp":1.97,"tv":1365.84,"id":40096582}]}]}
{"op":"mcm","clk":"11838515119","pt":1723497958953,"mc":[{"id":"1.231730206","rc":[{"batb":[[0,1.96,34.07],[1,1.95,606],[2,1.85,444]],"ltp":2.04,"tv":81.55,"id":40096580},{"batl":[[0,2.04,44.89],[1,2.04,0]],"ltp":1.97,"tv":1365.84,"id":40096582}]}]}
{"op":"mcm","clk":"11838515698","pt":1723497982766,"mc":[{"id":"1.231730206","rc":[{"batb":[[0,1.96,10],[1,1.95,95.06],[2,1.8,555]],"ltp":1.97,"tv":1365.84,"id":40096582}]}]}
{"op":"mcm","clk":"11838516467","pt":1723498010905,"mc":[{"id":"1.231730206","rc":[{"batb":[[0,1.95,95.06],[1,1.8,555],[2,1.79,493.04]],"ltp":1.97,"tv":1365.84,"id":40096582}]}]}
{"op":"mcm","clk":"11838516526","pt":1723498013618,"mc":[{"id":"1.231730206","rc":[{"batb":[[0,1.97,10],[1,1.95,95.06],[2,1.8,555]],"ltp":1.97,"tv":1365.84,"id":40096582}]}]}
{"op":"mcm","clk":"11838516606","pt":1723498016128,"mc":[{"id":"1.231730206","rc":[{"trd":[[1.97,90.01]],"batb":[[0,1.95,95.06],[1,1.8,555],[2,1.79,493.04]],"batl":[[0,1.97,8.84],[1,2.04,44.89]],"ltp":1.97,"tv":1385.85,"id":40096582}],"tv":1467.4}]}
{"op":"mcm","clk":"11838516639","pt":1723498016846,"mc":[{"id":"1.231730206","rc":[{"batb":[[0,1.95,606],[1,1.85,444],[2,1.74,17.32]],"ltp":2.04,"tv":81.55,"id":40096580},{"batl":[[1,2.04,10.82]],"ltp":1.97,"tv":1385.85,"id":40096582}]}]}
{"op":"mcm","clk":"11838516746","pt":1723498020331,"mc":[{"id":"1.231730206","rc":[{"batl":[[0,2.04,10.82],[1,2.04,0]],"ltp":1.97,"tv":1385.85,"id":40096582}]}]}
{"op":"mcm","clk":"11838516773","pt":1723498021406,"mc":[{"id":"1.231730206","rc":[{"batl":[[0,2.04,27.95]],"ltp":1.97,"tv":1385.85,"id":40096582}]}]}
{"op":"mcm","clk":"11838516992","pt":1723498028955,"mc":[{"id":"1.231730206","rc":[{"batb":[[0,1.97,95.06]],"ltp":1.97,"tv":1385.85,"id":40096582}]}]}
{"op":"mcm","clk":"11838517439","pt":1723498045655,"mc":[{"id":"1.231730206","rc":[{"batb":[[1,1.96,10],[2,1.8,555]],"ltp":1.97,"tv":1385.85,"id":40096582}]}]}
{"op":"mcm","clk":"11838518120","pt":1723498071070,"mc":[{"id":"1.231730206","rc":[{"batb":[[0,1.96,105.06],[1,1.8,555],[2,1.79,493.04]],"ltp":1.97,"tv":1385.85,"id":40096582}]}]}
{"op":"mcm","clk":"11838518338","pt":1723498080493,"mc":[{"id":"1.231730206","rc":[{"batb":[[0,1.96,95.06]],"ltp":1.97,"tv":1385.85,"id":40096582}]}]}
{"op":"mcm","clk":"11838518431","pt":1723498084085,"mc":[{"id":"1.231730206","rc":[{"batb":[[0,1.98,10],[1,1.96,95.06],[2,1.8,555]],"ltp":1.97,"tv":1385.85,"id":40096582}]}]}
{"op":"mcm","clk":"11838518575","pt":1723498089670,"mc":[{"id":"1.231730206","rc":[{"trd":[[1.98,20]],"batb":[[0,1.96,95.06],[1,1.8,555],[2,1.79,493.04]],"batl":[[0,2.04,28.23]],"ltp":1.98,"tv":1405.85,"id":40096582}],"tv":1487.4}]}
{"op":"mcm","clk":"11838518689","pt":1723498094477,"mc":[{"id":"1.231730206","rc":[{"batl":[[0,2.04,27.95]],"ltp":1.98,"tv":1405.85,"id":40096582}]}]}
{"op":"mcm","clk":"11838518820","pt":1723498099190,"mc":[{"id":"1.231730206","rc":[{"batb":[[0,1.97,95.06]],"ltp":1.98,"tv":1405.85,"id":40096582}]}]}
{"op":"mcm","clk":"11838519310","pt":1723498116651,"mc":[{"id":"1.231730206","rc":[{"batb":[[0,1.97,105.06]],"ltp":1.98,"tv":1405.85,"id":40096582}]}]}
{"op":"mcm","clk":"11838520210","pt":1723498148216,"mc":[{"id":"1.231730206","rc":[{"batb":[[0,1.97,95.06]],"ltp":1.98,"tv":1405.85,"id":40096582}]}]}
{"op":"mcm","clk":"11838520286","pt":1723498150925,"mc":[{"id":"1.231730206","rc":[{"batb":[[0,1.98,10],[1,1.97,95.06],[2,1.8,555]],"ltp":1.98,"tv":1405.85,"id":40096582}]}]}
{"op":"mcm","clk":"11838520459","pt":1723498157413,"mc":[{"id":"1.231730206","rc":[{"trd":[[1.98,40.01]],"batb":[[0,1.97,95.06],[1,1.8,555],[2,1.79,493.04]],"batl":[[0,2.04,28.23]],"ltp":1.98,"tv":1425.85,"id":40096582}],"tv":1507.4}]}
{"op":"mcm","clk":"11838520525","pt":1723498159209,"mc":[{"id":"1.231730206","rc":[{"batb":[[0,1.97,39.94],[1,1.95,606],[2,1.85,444]],"ltp":2.04,"tv":81.55,"id":40096580},{"batb":[[0,1.97,135]],"ltp":1.98,"tv":1425.85,"id":40096582}]}]}
{"op":"mcm","clk":"11838520527","pt":1723498159311,"mc":[{"id":"1.231730206","rc":[{"batb":[[2,1.79,444]],"ltp":1.98,"tv":1425.85,"id":40096582}]}]}
{"op":"mcm","clk":"11838520597","pt":1723498161718,"mc":[{"id":"1.231730206","rc":[{"batl":[[0,2.04,27.95]],"ltp":1.98,"tv":1425.85,"id":40096582}]}]}
{"op":"mcm","clk":"11838520936","pt":1723498175924,"mc":[{"id":"1.231730206","rc":[{"trd":[[1.97,169.89]],"batb":[[0,1.8,555],[1,1.79,444],[2,1.74,17.32]],"batl":[[0,2.04,28.26]],"ltp":1.97,"tv":1505.73,"id":40096582}],"tv":1587.28}]}
{"op":"mcm","clk":"11838521019","pt":1723498179347,"mc":[{"id":"1.231730206","rc":[{"batb":[[0,1.93,41.66],[1,1.8,555],[2,1.79,444]],"ltp":1.97,"tv":1505.73,"id":40096582}]}]}
{"op":"mcm","clk":"11838521041","pt":1723498180266,"mc":[{"id":"1.231730206","rc":[{"batl":[[0,2.04,27.95]],"ltp":1.97,"tv":1505.73,"id":40096582}]}]}
{"op":"mcm","clk":"11838521118","pt":1723498184622,"mc":[{"id":"1.231730206","rc":[{"batb":[[0,1.98,10],[1,1.93,41.66],[2,1.8,555]],"ltp":1.97,"tv":1505.73,"id":40096582}]}]}
{"op":"mcm","clk":"11838521302","pt":1723498192652,"mc":[{"id":"1.231730206","rc":[{"trd":[[1.98,60.01]],"batb":[[0,1.93,41.66],[1,1.8,555],[2,1.79,444]],"batl":[[0,2.04,28.23]],"ltp":1.98,"tv":1525.73,"id":40096582}],"tv":1607.29}]}
{"op":"mcm","clk":"11838521414","pt":1723498196849,"mc":[{"id":"1.231730206","rc":[{"batl":[[0,2.04,27.95]],"ltp":1.98,"tv":1525.73,"id":40096582}]}]}
{"op":"mcm","clk":"11838521708","pt":1723498206589,"mc":[{"id":"1.231730206","rc":[{"batb":[[0,1.97,95.06],[1,1.93,41.66],[2,1.8,555]],"ltp":1.98,"tv":1525.73,"id":40096582}]}]}
{"op":"mcm","clk":"11838522269","pt":1723498219960,"mc":[{"id":"1.231730206","rc":[{"batb":[[1,1.94,10],[2,1.93,41.66]],"ltp":1.98,"tv":1525.73,"id":40096582}]}]}
{"op":"mcm","clk":"11838523348","pt":1723498250200,"mc":[{"id":"1.231730206","rc":[{"batb":[[1,1.93,41.66],[2,1.8,555]],"ltp":1.98,"tv":1525.73,"id":40096582}]}]}
{"op":"mcm","clk":"11838523432","pt":1723498252813,"mc":[{"id":"1.231730206","rc":[{"batb":[[0,1.98,10],[1,1.97,95.06],[2,1.93,41.66]],"ltp":1.98,"tv":1525.73,"id":40096582}]}]}
{"op":"mcm","clk":"11838523929","pt":1723498267499,"mc":[{"id":"1.231730206","rc":[{"trd":[[1.98,80.01]],"batb":[[0,1.97,95.06],[1,1.93,41.66],[2,1.8,555]],"batl":[[0,2.04,28.23]],"ltp":1.98,"tv":1545.74,"id":40096582}],"tv":1627.29}]}
{"op":"mcm","clk":"11838524105","pt":1723498271910,"mc":[{"id":"1.231730206","rc":[{"batl":[[0,2.04,27.95]],"ltp":1.98,"tv":1545.74,"id":40096582}]}]}
{"op":"mcm","clk":"11838525003","pt":1723498296062,"mc":[{"id":"1.231730206","rc":[{"batb":[[0,1.98,10],[1,1.97,95.06],[2,1.93,41.66]],"ltp":1.98,"tv":1545.74,"id":40096582}]}]}
{"op":"mcm","clk":"11838525177","pt":1723498300826,"mc":[{"id":"1.231730206","rc":[{"trd":[[1.98,100.01]],"batb":[[0,1.97,95.06],[1,1.93,41.66],[2,1.8,555]],"batl":[[0,2.04,28.23]],"ltp":1.98,"tv":1565.74,"id":40096582}],"tv":1647.29}]}
{"op":"mcm","clk":"11838525324","pt":1723498305146,"mc":[{"id":"1.231730206","rc":[{"batl":[[0,2.04,27.95]],"ltp":1.98,"tv":1565.74,"id":40096582}]}]}
{"op":"mcm","clk":"11838526121","pt":1723498331852,"mc":[{"id":"1.231730206","rc":[{"batb":[[0,1.98,10],[1,1.97,95.06],[2,1.93,41.66]],"ltp":1.98,"tv":1565.74,"id":40096582}]}]}
{"op":"mcm","clk":"11838526282","pt":1723498337087,"mc":[{"id":"1.231730206","rc":[{"trd":[[1.98,120.02]],"batb":[[0,1.97,95.06],[1,1.93,41.66],[2,1.8,555]],"batl":[[0,2.04,28.23]],"ltp":1.98,"tv":1585.74,"id":40096582}],"tv":1667.29}]}
{"op":"mcm","clk":"11838526440","pt":1723498341903,"mc":[{"id":"1.231730206","rc":[{"batl":[[0,2.04,27.95]],"ltp":1.98,"tv":1585.74,"id":40096582}]}]}
{"op":"mcm","clk":"11838527455","pt":1723498370995,"mc":[{"id":"1.231730206","rc":[{"batb":[[0,1.98,10],[1,1.97,95.06],[2,1.93,41.66]],"ltp":1.98,"tv":1585.74,"id":40096582}]}]}
{"op":"mcm","clk":"11838527556","pt":1723498374015,"mc":[{"id":"1.231730206","rc":[{"trd":[[1.98,140.02]],"batb":[[0,1.97,95.06],[1,1.93,41.66],[2,1.8,555]],"batl":[[0,2.04,28.23]],"ltp":1.98,"tv":1605.74,"id":40096582}],"tv":1687.3}]}
{"op":"mcm","clk":"11838527718","pt":1723498378939,"mc":[{"id":"1.231730206","rc":[{"batl":[[0,2.04,27.95]],"ltp":1.98,"tv":1605.74,"id":40096582}]}]}
{"op":"mcm","clk":"11838530814","pt":1723498465899,"mc":[{"id":"1.231730206","rc":[{"batb":[[0,1.93,41.66],[1,1.8,555],[2,1.79,444]],"ltp":1.98,"tv":1605.74,"id":40096582}]}]}
{"op":"mcm","clk":"11838532714","pt":1723498534083,"mc":[{"id":"1.231730206","rc":[{"trd":[[1.93,83.32]],"batb":[[0,1.8,555],[1,1.79,444],[2,1.74,17.32]],"batl":[[0,1.93,5.44],[1,2.04,27.95]],"ltp":1.93,"tv":1689.07,"id":40096582}],"tv":1770.62}]}
{"op":"mcm","clk":"11838532749","pt":1723498535466,"mc":[{"id":"1.231730206","rc":[{"batb":[[0,1.89,43.53],[1,1.8,555],[2,1.79,444]],"ltp":1.93,"tv":1689.07,"id":40096582}]}]}
{"op":"mcm","clk":"11838532868","pt":1723498538897,"mc":[{"id":"1.231730206","rc":[{"batl":[[0,2.04,27.95],[1,2.04,0]],"ltp":1.93,"tv":1689.07,"id":40096582}]}]}
{"op":"mcm","clk":"11838533401","pt":1723498556758,"mc":[{"id":"1.231730206","rc":[{"batb":[[0,2.02,304.02],[1,1.97,39.94],[2,1.95,606]],"ltp":2.04,"tv":81.55,"id":40096580}]}]}
{"op":"mcm","clk":"11838533420","pt":1723498557782,"mc":[{"id":"1.231730206","rc":[{"batl":[[0,1.98,4.41],[1,2.04,23.67]],"ltp":1.93,"tv":1689.07,"id":40096582}]}]}
{"op":"mcm","clk":"11838533455","pt":1723498559112,"mc":[{"id":"1.231730206","rc":[{"batl":[[0,1.98,11.16],[1,2.04,0]],"ltp":1.93,"tv":1689.07,"id":40096582}]}]}
{"op":"mcm","clk":"11838533491","pt":1723498560598,"mc":[{"id":"1.231730206","rc":[{"batb":[[0,2.02,342],[1,1.95,606],[2,1.85,444]],"ltp":2.04,"tv":81.55,"id":40096580},{"batb":[[0,1.9,43.05]],"ltp":1.93,"tv":1689.07,"id":40096582}]}]}
{"op":"mcm","clk":"11838533768","pt":1723498572015,"mc":[{"id":"1.231730206","rc":[{"batb":[[0,2.04,304.02],[1,2.02,37.98],[2,1.95,606]],"ltp":2.04,"tv":81.55,"id":40096580}]}]}
{"op":"mcm","clk":"11838533795","pt":1723498573193,"mc":[{"id":"1.231730206","rc":[{"batl":[[0,1.96,4.45]],"ltp":1.93,"tv":1689.07,"id":40096582}]}]}
{"op":"mcm","clk":"11838533800","pt":1723498573296,"mc":[{"id":"1.231730206","rc":[{"batl":[[0,1.96,11.27]],"ltp":1.93,"tv":1689.07,"id":40096582}]}]}
{"op":"mcm","clk":"11838534072","pt":1723498584821,"mc":[{"id":"1.231730206","rc":[{"batb":[[0,2.1,304.02]],"ltp":2.04,"tv":81.55,"id":40096580},{"batl":[[0,1.96,6.82]],"ltp":1.93,"tv":1689.07,"id":40096582}]}]}
{"op":"mcm","clk":"11838534114","pt":1723498585781,"mc":[{"id":"1.231730206","rc":[{"batl":[[0,1.91,7]],"ltp":1.93,"tv":1689.07,"id":40096582}]}]}
{"op":"mcm","clk":"11838534266","pt":1723498591926,"mc":[{"id":"1.231730206","rc":[{"batl":[[0,1.91,11.57]],"ltp":1.93,"tv":1689.07,"id":40096582}]}]}
{"op":"mcm","clk":"11838534323","pt":1723498594531,"mc":[{"id":"1.231730206","rc":[{"batb":[[0,2.02,37.98],[1,1.95,606],[2,1.85,444]],"ltp":2.04,"tv":81.55,"id":40096580}]}]}
{"op":"mcm","clk":"11838534682","pt":1723498607954,"mc":[{"id":"1.231730206","rc":[{"batl":[[0,1.98,6.75]],"ltp":1.93,"tv":1689.07,"id":40096582}]}]}
{"op":"mcm","clk":"11838535800","pt":1723498654168,"mc":[{"id":"1.231730206","rc":[{"batl":[[0,1.98,11.16]],"ltp":1.93,"tv":1689.07,"id":40096582}]}]}
{"op":"mcm","clk":"11838544075","pt":1723498933374,"mc":[{"id":"1.231730206","rc":[{"batb":[[0,1.91,95.06],[1,1.9,43.05],[2,1.8,555]],"ltp":1.93,"tv":1689.07,"id":40096582}]}]}
{"op":"mcm","clk":"11838547529","pt":1723499038740,"mc":[{"id":"1.231730206","rc":[{"batb":[[0,1.9,43.05],[1,1.8,555],[2,1.79,444]],"ltp":1.93,"tv":1689.07,"id":40096582}]}]}
{"op":"mcm","clk":"11838550558","pt":1723499136540,"mc":[{"id":"1.231730206","rc":[{"batb":[[0,2.04,304.02],[1,2.02,37.98],[2,1.95,606]],"ltp":2.04,"tv":81.55,"id":40096580}]}]}
{"op":"mcm","clk":"11838550616","pt":1723499138130,"mc":[{"id":"1.231730206","rc":[{"batl":[[0,1.96,19.91]],"ltp":1.93,"tv":1689.07,"id":40096582}]}]}
{"op":"mcm","clk":"11838550627","pt":1723499138334,"mc":[{"id":"1.231730206","rc":[{"batb":[[0,2.06,16.47],[1,2.04,304.02],[2,2.02,37.98]],"ltp":2.04,"tv":81.55,"id":40096580},{"batl":[[0,1.96,43.86]],"ltp":1.93,"tv":1689.07,"id":40096582}]}]}
{"op":"mcm","clk":"11838550973","pt":1723499147546,"mc":[{"id":"1.231730206","rc":[{"batl":[[0,1.94,6.89]],"ltp":1.93,"tv":1689.07,"id":40096582}]}]}
{"op":"mcm","clk":"11838551079","pt":1723499150666,"mc":[{"id":"1.231730206","rc":[{"batb":[[0,2.08,304.02],[1,2.06,16.47]],"ltp":2.04,"tv":81.55,"id":40096580}]}]}
{"op":"mcm","clk":"11838551112","pt":1723499151537,"mc":[{"id":"1.231730206","rc":[{"batb":[[1,2.02,37.98],[2,1.95,606]],"ltp":2.04,"tv":81.55,"id":40096580}]}]}
{"op":"mcm","clk":"11838551278","pt":1723499156646,"mc":[{"id":"1.231730206","rc":[{"batl":[[0,1.92,6.95]],"ltp":1.93,"tv":1689.07,"id":40096582}]}]}
{"op":"mcm","clk":"11838551311","pt":1723499157668,"mc":[{"id":"1.231730206","rc":[{"batl":[[0,1.92,11.5]],"ltp":1.93,"tv":1689.07,"id":40096582}]}]}
{"op":"mcm","clk":"11838552118","pt":1723499181671,"mc":[{"id":"1.231730206","rc":[{"batl":[[0,1.92,28.63]],"ltp":1.93,"tv":1689.07,"id":40096582}]}]}
{"op":"mcm","clk":"11838553048","pt":1723499208020,"mc":[{"id":"1.231730206","rc":[{"batb":[[0,2.02,37.98],[1,1.95,606],[2,1.85,444]],"ltp":2.04,"tv":81.55,"id":40096580}]}]}
{"op":"mcm","clk":"11838553072","pt":1723499208637,"mc":[{"id":"1.231730206","rc":[{"batl":[[0,1.92,4.55]],"ltp":1.93,"tv":1689.07,"id":40096582}]}]}
{"op":"mcm","clk":"11838553155","pt":1723499209819,"mc":[{"id":"1.231730206","rc":[{"batl":[[0,1.98,4.41]],"ltp":1.93,"tv":1689.07,"id":40096582}]}]}
{"op":"mcm","clk":"11838553198","pt":1723499210810,"mc":[{"id":"1.231730206","rc":[{"batl":[[0,1.98,11.16]],"ltp":1.93,"tv":1689.07,"id":40096582}]}]}
{"op":"mcm","clk":"11838553367","pt":1723499214702,"mc":[{"id":"1.231730206","rc":[{"trd":[[1.9,11.22]],"batb":[[0,1.9,31.83]],"ltp":1.9,"tv":1700.29,"id":40096582}],"tv":1781.84}]}
{"op":"mcm","clk":"11838553478","pt":1723499217727,"mc":[{"id":"1.231730206","rc":[{"batb":[[0,1.9,43.05]],"ltp":1.9,"tv":1700.29,"id":40096582}]}]}
{"op":"mcm","clk":"11838730537","pt":1723502574876,"mc":[{"id":"1.231730206","rc":[{"trd":[[2.04,9.66]],"ltp":2.04,"tv":81.54,"id":40096580},{"trd":[[1.87,23.62],[1.91,1265.17],[1.92,6.81],[1.93,83.32],[1.97,169.88],[1.98,140.01]],"batl":[[0,1.98,11.16]],"ltp":1.9,"tv":1700.15,"id":40096582}],"tv":1781.7}]}
{"op":"mcm","clk":"11838821449","pt":1723504031328,"mc":[{"id":"1.231730206","rc":[{"trd":[[1.87,23.62],[1.91,1265.22],[1.93,83.32],[1.97,169.89],[1.98,140.01]],"batb":[[1,1.81,89.98],[2,1.8,555]],"ltp":1.9,"tv":1700.22,"id":40096582}],"tv":1781.77}]}
{"op":"mcm","clk":"11838825797","pt":1723504083893,"mc":[{"id":"1.231730206","rc":[{"trd":[[1.9,92.36]],"batb":[[0,1.9,2.48]],"ltp":1.9,"tv":1781.36,"id":40096582}],"tv":1862.91}]}
{"op":"mcm","clk":"11838825883","pt":1723504084923,"mc":[{"id":"1.231730206","rc":[{"batb":[[0,1.86,45.05]],"ltp":1.9,"tv":1781.36,"id":40096582}]}]}
{"op":"mcm","clk":"11838828237","pt":1723504113874,"mc":[{"id":"1.231730206","rc":[{"batb":[[1,1.8,555],[2,1.79,444]],"ltp":1.9,"tv":1781.36,"id":40096582}]}]}
{"op":"mcm","clk":"11838828875","pt":1723504121349,"mc":[{"id":"1.231730206","rc":[{"batb":[[0,2.1,303.99],[1,2.02,37.98],[2,1.95,606]],"ltp":2.04,"tv":81.54,"id":40096580}]}]}
{"op":"mcm","clk":"11838829027","pt":1723504123254,"mc":[{"id":"1.231730206","rc":[{"batl":[[0,1.98,6.75]],"ltp":1.9,"tv":1781.36,"id":40096582}]}]}
{"op":"mcm","clk":"11838829058","pt":1723504123769,"mc":[{"id":"1.231730206","rc":[{"batl":[[0,1.9,11.62]],"ltp":1.9,"tv":1781.36,"id":40096582}]}]}
{"op":"mcm","clk":"11838829157","pt":1723504125056,"mc":[{"id":"1.231730206","rc":[{"batb":[[1,2.08,35.87]],"ltp":2.04,"tv":81.54,"id":40096580},{"batb":[[0,1.85,45.58]],"ltp":1.9,"tv":1781.36,"id":40096582}]}]}
{"op":"mcm","clk":"11838831198","pt":1723504151100,"mc":[{"id":"1.231730206","rc":[{"batb":[[0,2.08,35.87],[1,1.95,606],[2,1.85,444]],"ltp":2.04,"tv":81.54,"id":40096580}]}]}
{"op":"mcm","clk":"11838831357","pt":1723504152901,"mc":[{"id":"1.231730206","rc":[{"batl":[[0,1.92,11.5]],"ltp":1.9,"tv":1781.36,"id":40096582}]}]}
{"op":"mcm","clk":"11838832249","pt":1723504164088,"mc":[{"id":"1.231730206","rc":[{"batb":[[0,1.88,190.1],[1,1.85,45.58],[2,1.8,555]],"ltp":1.9,"tv":1781.36,"id":40096582}]}]}
{"op":"mcm","clk":"11838833773","pt":1723504182010,"mc":[{"id":"1.231730206","rc":[{"batb":[[0,1.85,45.58],[1,1.8,555],[2,1.79,444]],"ltp":1.9,"tv":1781.36,"id":40096582}]}]}
{"op":"mcm","clk":"11838857145","pt":1723504490533,"mc":[{"id":"1.231730206","rc":[{"batb":[[1,2,589.14],[2,1.95,606]],"ltp":2.04,"tv":81.54,"id":40096580}]}]}
{"op":"mcm","clk":"11839066925","pt":1723507974948,"mc":[{"id":"1.231730206","rc":[{"batb":[[1,2,589.19]],"ltp":2.04,"tv":81.54,"id":40096580},{"trd":[[1.87,23.62],[1.91,1265.27],[1.92,6.81],[1.93,83.32],[1.97,169.89],[1.98,140.02]],"ltp":1.9,"tv":1781.43,"id":40096582}],"tv":1862.98}]}
{"op":"mcm","clk":"11839271464","pt":1723513374936,"mc":[{"id":"1.231730206","rc":[{"trd":[[2.04,9.66]],"batb":[[1,2,589.04]],"ltp":2.04,"tv":81.54,"id":40096580},{"trd":[[1.87,23.61],[1.91,1265.12],[1.92,6.81],[1.93,83.31],[1.97,169.87],[1.98,140]],"batl":[[0,1.92,11.5]],"ltp":1.9,"tv":1781.22,"id":40096582}],"tv":1862.77}]}
{"op":"mcm","clk":"11839366825","pt":1723516134970,"mc":[{"id":"1.231730206","rc":[{"batb":[[1,2,588.99]],"ltp":2.04,"tv":81.54,"id":40096580},{"trd":[[1.87,23.61],[1.91,1265.07],[1.92,6.81],[1.93,83.31],[1.97,169.86],[1.98,139.99]],"batl":[[1,1.96,40.57]],"ltp":1.9,"tv":1781.15,"id":40096582}],"tv":1862.69}]}
{"op":"mcm","clk":"11839367327","pt":1723516149157,"mc":[{"id":"1.231730206","rc":[{"batb":[[1,1.81,31.55],[2,1.8,555]],"ltp":1.9,"tv":1781.15,"id":40096582}]}]}
{"op":"mcm","clk":"11839448118","pt":1723518774961,"mc":[{"id":"1.231730206","rc":[{"trd":[[2.04,9.66]],"batb":[[1,2,589.09]],"ltp":2.04,"tv":81.54,"id":40096580},{"trd":[[1.87,23.62],[1.91,1265.17],[1.93,83.32],[1.97,169.88],[1.98,140.01]],"batl":[[0,1.92,11.5]],"ltp":1.9,"tv":1781.29,"id":40096582}],"tv":1862.83}]}
{"op":"mcm","clk":"11839593068","pt":1723524174955,"mc":[{"id":"1.231730206","rc":[{"batb":[[1,2,589.04]],"ltp":2.04,"tv":81.54,"id":40096580},{"trd":[[1.87,23.61],[1.91,1265.12],[1.92,6.8],[1.93,83.31],[1.97,169.87],[1.98,140]],"ltp":1.9,"tv":1781.21,"id":40096582}],"tv":1862.76}]}
{"op":"mcm","clk":"11839601754","pt":1723524335077,"mc":[{"id":"1.231730206","rc":[{"batl":[[1,1.95,36.06],[2,1.96,40.57]],"ltp":1.9,"tv":1781.21,"id":40096582}]}]}
{"op":"mcm","clk":"11839721364","pt":1723527937544,"mc":[{"id":"1.231730206","rc":[{"batb":[[1,2,588.99]],"ltp":2.04,"tv":81.54,"id":40096580},{"trd":[[1.87,23.61],[1.91,1265.07],[1.92,6.8],[1.93,83.31],[1.97,169.86],[1.98,139.99]],"batb":[[0,1.86,222],[1,1.85,45.58],[2,1.81,31.55]],"ltp":1.9,"tv":1781.14,"id":40096582}],"tv":1862.69}]}
{"op":"mcm","clk":"11839722009","pt":1723527958384,"mc":[{"id":"1.231730206","rc":[{"batb":[[0,1.9,33],[1,1.86,222],[2,1.85,45.58]],"ltp":1.9,"tv":1781.14,"id":40096582}]}]}
{"op":"mcm","clk":"11839722381","pt":1723527969692,"mc":[{"id":"1.231730206","rc":[{"batb":[[0,1.9,33.9]],"ltp":1.9,"tv":1781.14,"id":40096582}]}]}
{"op":"mcm","clk":"11839785186","pt":1723529574945,"mc":[{"id":"1.231730206","rc":[{"batb":[[1,2,588.94]],"ltp":2.04,"tv":81.54,"id":40096580},{"trd":[[1.87,23.61],[1.91,1265.02],[1.93,83.31],[1.97,169.86],[1.98,139.99]],"ltp":1.9,"tv":1781.07,"id":40096582}],"tv":1862.62}]}
{"op":"mcm","clk":"11839951882","pt":1723534974910,"mc":[{"id":"1.231730206","rc":[{"trd":[[1.03,1.22],[1.07,1.79],[2.04,9.63]],"batb":[[1,2,587.48]],"ltp":2.04,"tv":81.51,"id":40096580},{"trd":[[1.87,23.55],[1.91,1263.53],[1.92,6.79],[1.93,83.2],[1.97,169.66],[1.98,139.81]],"batl":[[0,1.92,11.47]],"ltp":1.9,"tv":1779.04,"id":40096582}],"tv":1860.56}]}
{"op":"mcm","clk":"11840024384","pt":1723537223115,"mc":[{"id":"1.231730206","rc":[{"trd":[[2.04,9.63]],"batb":[[1,2,587.08]],"ltp":2.04,"tv":81.5,"id":40096580},{"trd":[[1.87,23.53],[1.91,1263.12],[1.92,6.79],[1.93,83.17],[1.97,169.61],[1.98,139.77]],"batl":[[0,1.92,11.46]],"ltp":1.9,"tv":1778.49,"id":40096582}],"tv":1860.0}]}
{"op":"mcm","clk":"11840024413","pt":1723537223833,"mc":[{"id":"1.231730206","rc":[{"trd":[[1.92,7.57]],"batl":[[0,1.92,11.07]],"ltp":1.92,"tv":1779.27,"id":40096582}],"tv":1860.78}]}
{"op":"mcm","clk":"11840127526","pt":1723540374895,"mc":[{"id":"1.231730206","rc":[{"trd":[[2.04,9.63]],"batb":[[1,2,587.18]],"ltp":2.04,"tv":81.51,"id":40096580},{"trd":[[1.87,23.54],[1.91,1263.23],[1.92,7.57],[1.93,83.18],[1.97,169.62],[1.98,139.78]],"batl":[[0,1.92,11.07]],"ltp":1.92,"tv":1779.41,"id":40096582}],"tv":1860.93}]}
{"op":"mcm","clk":"11840299863","pt":1723543990641,"mc":[{"id":"1.231730206","rc":[{"trd":[[2.04,9.63]],"batb":[[1,2,587.28]],"ltp":2.04,"tv":81.51,"id":40096580},{"trd":[[1.87,23.54],[1.91,1263.33],[1.92,7.58],[1.93,83.19],[1.97,169.63],[1.98,139.79]],"batl":[[0,1.92,11.07],[1,1.96,40.57],[2,1.97,36.06]],"ltp":1.92,"tv":1779.55,"id":40096582}],"tv":1861.07}]}
{"op":"mcm","clk":"11840375864","pt":1723545379419,"mc":[{"id":"1.231730206","rc":[{"batl":[[2,1.97,0]],"ltp":1.92,"tv":1779.55,"id":40096582}]}]}
{"op":"mcm","clk":"11840441024","pt":1723546554649,"mc":[{"id":"1.231730206","rc":[{"batl":[[0,2.24,1]],"ltp":2.04,"tv":81.51,"id":40096580}]}]}
{"op":"mcm","clk":"11840453366","pt":1723546802517,"mc":[{"id":"1.231730206","rc":[{"batb":[[0,2.1,10],[1,2.08,35.87],[2,2,587.28]],"ltp":2.04,"tv":81.51,"id":40096580}]}]}
{"op":"mcm","clk":"11840453640","pt":1723546806425,"mc":[{"id":"1.231730206","rc":[{"trd":[[2.04,9.64]],"batb":[[0,2.08,35.87],[1,2,587.83],[2,1.95,606]],"ltp":2.04,"tv":81.52,"id":40096580},{"trd":[[1.87,23.56],[1.91,1263.89],[1.92,7.58],[1.93,83.23],[1.97,169.71],[1.98,139.86]],"batl":[[0,1.92,11.08]],"ltp":1.92,"tv":1780.32,"id":40096582}],"tv":1861.85}]}
{"op":"mcm","clk":"11840453903","pt":1723546810349,"mc":[{"id":"1.231730206","rc":[{"batb":[[0,2.1,10],[1,2.08,35.87],[2,2,587.83]],"ltp":2.04,"tv":81.52,"id":40096580}]}]}
{"op":"mcm","clk":"11840454046","pt":1723546812635,"mc":[{"id":"1.231730206","rc":[{"batb":[[1,2,587.83],[2,1.95,606]],"ltp":2.04,"tv":81.52,"id":40096580},{"batb":[[2,1.81,31.55]],"ltp":1.92,"tv":1780.32,"id":40096582}]}]}
{"op":"mcm","clk":"11840454127","pt":1723546814037,"mc":[{"id":"1.231730206","rc":[{"batb":[[0,2,587.83],[1,1.95,606],[2,1.85,444]],"ltp":2.04,"tv":81.52,"id":40096580},{"batl":[[0,1.92,4.14]],"ltp":1.92,"tv":1780.32,"id":40096582}]}]}
{"op":"mcm","clk":"11840454208","pt":1723546815229,"mc":[{"id":"1.231730206","rc":[{"batl":[[0,1.95,4.08]],"ltp":1.92,"tv":1780.32,"id":40096582}]}]}
{"op":"mcm","clk":"11840454257","pt":1723546816047,"mc":[{"id":"1.231730206","rc":[{"batl":[[0,1.95,10.91]],"ltp":1.92,"tv":1780.32,"id":40096582}]}]}
{"op":"mcm","clk":"11840454373","pt":1723546817643,"mc":[{"id":"1.231730206","rc":[{"batb":[[0,2.02,47.98],[1,2,587.83],[2,1.95,606]],"ltp":2.04,"tv":81.52,"id":40096580},{"batb":[[0,1.9,76.95]],"ltp":1.92,"tv":1780.32,"id":40096582}]}]}
{"op":"mcm","clk":"11840454604","pt":1723546821052,"mc":[{"id":"1.231730206","rc":[{"batb":[[0,2.02,37.98]],"ltp":2.04,"tv":81.52,"id":40096580}]}]}
{"op":"mcm","clk":"11840454816","pt":1723546824625,"mc":[{"id":"1.231730206","rc":[{"batb":[[0,2.04,10],[1,2.02,37.98],[2,2,587.83]],"ltp":2.04,"tv":81.52,"id":40096580}]}]}
{"op":"mcm","clk":"11840455016","pt":1723546827938,"mc":[{"id":"1.231730206","rc":[{"batb":[[0,2.02,37.98],[1,2,587.83],[2,1.95,606]],"ltp":2.04,"tv":81.52,"id":40096580}]}]}
{"op":"mcm","clk":"11840455363","pt":1723546833160,"mc":[{"id":"1.231730206","rc":[{"batb":[[0,2.04,10],[1,2.02,37.98],[2,2,587.83]],"ltp":2.04,"tv":81.52,"id":40096580}]}]}
{"op":"mcm","clk":"11840455660","pt":1723546836832,"mc":[{"id":"1.231730206","rc":[{"batb":[[0,2.02,37.98],[1,2,587.83],[2,1.95,606]],"ltp":2.04,"tv":81.52,"id":40096580}]}]}
{"op":"mcm","clk":"11840456019","pt":1723546842269,"mc":[{"id":"1.231730206","rc":[{"batb":[[0,2.04,10],[1,2.02,37.98],[2,2,587.83]],"ltp":2.04,"tv":81.52,"id":40096580}]}]}
{"op":"mcm","clk":"11840456201","pt":1723546845529,"mc":[{"id":"1.231730206","rc":[{"batb":[[0,2.02,37.98],[1,2,587.83],[2,1.95,606]],"ltp":2.04,"tv":81.52,"id":40096580}]}]}
{"op":"mcm","clk":"11840456496","pt":1723546849461,"mc":[{"id":"1.231730206","rc":[{"batb":[[0,2.04,10],[1,2.02,37.98],[2,2,587.83]],"ltp":2.04,"tv":81.52,"id":40096580}]}]}
{"op":"mcm","clk":"11840456684","pt":1723546852868,"mc":[{"id":"1.231730206","rc":[{"batb":[[0,2.02,37.98],[1,2,587.83],[2,1.95,606]],"ltp":2.04,"tv":81.52,"id":40096580}]}]}
{"op":"mcm","clk":"11840456895","pt":1723546856545,"mc":[{"id":"1.231730206","rc":[{"batb":[[0,2.04,10],[1,2.02,37.98],[2,2,587.83]],"ltp":2.04,"tv":81.52,"id":40096580}]}]}
{"op":"mcm","clk":"11840457089","pt":1723546859964,"mc":[{"id":"1.231730206","rc":[{"batb":[[0,2.02,37.98],[1,2,587.83],[2,1.95,606]],"ltp":2.04,"tv":81.52,"id":40096580}]}]}
{"op":"mcm","clk":"11840457400","pt":1723546865285,"mc":[{"id":"1.231730206","rc":[{"batb":[[0,2.04,10],[1,2.02,37.98],[2,2,587.83]],"ltp":2.04,"tv":81.52,"id":40096580}]}]}
{"op":"mcm","clk":"11840457589","pt":1723546868687,"mc":[{"id":"1.231730206","rc":[{"batb":[[0,2.02,37.98],[1,2,587.83],[2,1.95,606]],"ltp":2.04,"tv":81.52,"id":40096580}]}]}
{"op":"mcm","clk":"11840457807","pt":1723546872978,"mc":[{"id":"1.231730206","rc":[{"batb":[[0,2.04,10],[1,2.02,37.98],[2,2,587.83]],"ltp":2.04,"tv":81.52,"id":40096580}]}]}
{"op":"mcm","clk":"11840457967","pt":1723546876477,"mc":[{"id":"1.231730206","rc":[{"batb":[[0,2.02,37.98],[1,2,587.83],[2,1.95,606]],"ltp":2.04,"tv":81.52,"id":40096580}]}]}
{"op":"mcm","clk":"11840458385","pt":1723546884596,"mc":[{"id":"1.231730206","rc":[{"batb":[[0,2.04,10],[1,2.02,37.98],[2,2,587.83]],"ltp":2.04,"tv":81.52,"id":40096580}]}]}
{"op":"mcm","clk":"11840458556","pt":1723546888298,"mc":[{"id":"1.231730206","rc":[{"batb":[[0,2.02,37.98],[1,2,587.83],[2,1.95,606]],"ltp":2.04,"tv":81.52,"id":40096580}]}]}
{"op":"mcm","clk":"11840458861","pt":1723546894633,"mc":[{"id":"1.231730206","rc":[{"batb":[[0,2.04,10],[1,2.02,37.98],[2,2,587.83]],"ltp":2.04,"tv":81.52,"id":40096580}]}]}
{"op":"mcm","clk":"11840459020","pt":1723546898127,"mc":[{"id":"1.231730206","rc":[{"batb":[[0,2.02,37.98],[1,2,587.83],[2,1.95,606]],"ltp":2.04,"tv":81.52,"id":40096580}]}]}
{"op":"mcm","clk":"11840459304","pt":1723546905541,"mc":[{"id":"1.231730206","rc":[{"batb":[[0,2.04,10],[1,2.02,37.98],[2,2,587.83]],"ltp":2.04,"tv":81.52,"id":40096580}]}]}
{"op":"mcm","clk":"11840459431","pt":1723546908821,"mc":[{"id":"1.231730206","rc":[{"batb":[[0,2.02,37.98],[1,2,587.83],[2,1.95,606]],"ltp":2.04,"tv":81.52,"id":40096580}]}]}
{"op":"mcm","clk":"11840459637","pt":1723546913945,"mc":[{"id":"1.231730206","rc":[{"batb":[[0,2.04,10],[1,2.02,37.98],[2,2,587.83]],"ltp":2.04,"tv":81.52,"id":40096580}]}]}
{"op":"mcm","clk":"11840459798","pt":1723546917351,"mc":[{"id":"1.231730206","rc":[{"batb":[[0,2.02,37.98],[1,2,587.83],[2,1.95,606]],"ltp":2.04,"tv":81.52,"id":40096580}]}]}
{"op":"mcm","clk":"11840459974","pt":1723546921871,"mc":[{"id":"1.231730206","rc":[{"batb":[[0,2.04,10],[1,2.02,37.98],[2,2,587.83]],"ltp":2.04,"tv":81.52,"id":40096580}]}]}
{"op":"mcm","clk":"11840460174","pt":1723546926652,"mc":[{"id":"1.231730206","rc":[{"batb":[[0,2.02,37.98],[1,2,587.83],[2,1.95,606]],"ltp":2.04,"tv":81.52,"id":40096580}]}]}
{"op":"mcm","clk":"11840460365","pt":1723546931736,"mc":[{"id":"1.231730206","rc":[{"batb":[[0,2.04,10],[1,2.02,37.98],[2,2,587.83]],"ltp":2.04,"tv":81.52,"id":40096580}]}]}
{"op":"mcm","clk":"11840460497","pt":1723546935278,"mc":[{"id":"1.231730206","rc":[{"batb":[[0,2.02,37.98],[1,2,587.83],[2,1.95,606]],"ltp":2.04,"tv":81.52,"id":40096580}]}]}
{"op":"mcm","clk":"11840460774","pt":1723546942980,"mc":[{"id":"1.231730206","rc":[{"batb":[[0,2.04,10],[1,2.02,37.98],[2,2,587.83]],"ltp":2.04,"tv":81.52,"id":40096580}]}]}
{"op":"mcm","clk":"11840460937","pt":1723546946679,"mc":[{"id":"1.231730206","rc":[{"batb":[[0,2.02,37.98],[1,2,587.83],[2,1.95,606]],"ltp":2.04,"tv":81.52,"id":40096580}]}]}
{"op":"mcm","clk":"11840461380","pt":1723546957174,"mc":[{"id":"1.231730206","rc":[{"batb":[[0,2.04,10],[1,2.02,37.98],[2,2,587.83]],"ltp":2.04,"tv":81.52,"id":40096580}]}]}
{"op":"mcm","clk":"11840461526","pt":1723546960817,"mc":[{"id":"1.231730206","rc":[{"batb":[[0,2.02,37.98],[1,2,587.83],[2,1.95,606]],"ltp":2.04,"tv":81.52,"id":40096580}]}]}
{"op":"mcm","clk":"11840461771","pt":1723546966800,"mc":[{"id":"1.231730206","rc":[{"batb":[[0,2.04,10],[1,2.02,37.98],[2,2,587.83]],"ltp":2.04,"tv":81.52,"id":40096580}]}]}
{"op":"mcm","clk":"11840461906","pt":1723546970199,"mc":[{"id":"1.231730206","rc":[{"batb":[[0,2.02,37.98],[1,2,587.83],[2,1.95,606]],"ltp":2.04,"tv":81.52,"id":40096580}]}]}
{"op":"mcm","clk":"11840462146","pt":1723546976210,"mc":[{"id":"1.231730206","rc":[{"batb":[[0,2.04,10],[1,2.02,37.98],[2,2,587.83]],"ltp":2.04,"tv":81.52,"id":40096580}]}]}
{"op":"mcm","clk":"11840462302","pt":1723546979739,"mc":[{"id":"1.231730206","rc":[{"batb":[[0,2.02,37.98],[1,2,587.83],[2,1.95,606]],"ltp":2.04,"tv":81.52,"id":40096580}]}]}
{"op":"mcm","clk":"11840462442","pt":1723546982110,"mc":[{"id":"1.231730206","rc":[{"batb":[[0,2.04,10],[1,2.02,37.98],[2,2,587.83]],"ltp":2.04,"tv":81.52,"id":40096580}]}]}
{"op":"mcm","clk":"11840462638","pt":1723546985803,"mc":[{"id":"1.231730206","rc":[{"batb":[[0,2.02,37.98],[1,2,587.83],[2,1.95,606]],"ltp":2.04,"tv":81.52,"id":40096580}]}]}
{"op":"mcm","clk":"11840462767","pt":1723546988730,"mc":[{"id":"1.231730206","rc":[{"batb":[[0,2.04,10],[1,2.02,37.98],[2,2,587.83]],"ltp":2.04,"tv":81.52,"id":40096580}]}]}
{"op":"mcm","clk":"11840462894","pt":1723546992327,"mc":[{"id":"1.231730206","rc":[{"batb":[[0,2.02,37.98],[1,2,587.83],[2,1.95,606]],"ltp":2.04,"tv":81.52,"id":40096580}]}]}
{"op":"mcm","clk":"11840463444","pt":1723547000540,"mc":[{"id":"1.231730206","rc":[{"batb":[[0,2.04,10],[1,2.02,37.98],[2,2,587.83]],"ltp":2.04,"tv":81.52,"id":40096580}]}]}
{"op":"mcm","clk":"11840463587","pt":1723547003826,"mc":[{"id":"1.231730206","rc":[{"batb":[[0,2.02,37.98],[1,2,587.83],[2,1.95,606]],"ltp":2.04,"tv":81.52,"id":40096580}]}]}
{"op":"mcm","clk":"11840463752","pt":1723547007129,"mc":[{"id":"1.231730206","rc":[{"batb":[[0,2.04,10],[1,2.02,37.98],[2,2,587.83]],"ltp":2.04,"tv":81.52,"id":40096580}]}]}
{"op":"mcm","clk":"11840463922","pt":1723547010530,"mc":[{"id":"1.231730206","rc":[{"batb":[[0,2.02,37.98],[1,2,587.83],[2,1.95,606]],"ltp":2.04,"tv":81.52,"id":40096580}]}]}
{"op":"mcm","clk":"11840464163","pt":1723547016132,"mc":[{"id":"1.231730206","rc":[{"batb":[[0,2.04,10],[1,2.02,37.98],[2,2,587.83]],"ltp":2.04,"tv":81.52,"id":40096580}]}]}
{"op":"mcm","clk":"11840464282","pt":1723547019732,"mc":[{"id":"1.231730206","rc":[{"batb":[[0,2.02,37.98],[1,2,587.83],[2,1.95,606]],"ltp":2.04,"tv":81.52,"id":40096580}]}]}
{"op":"mcm","clk":"11840464620","pt":1723547026387,"mc":[{"id":"1.231730206","rc":[{"batb":[[0,2.04,10],[1,2.02,37.98],[2,2,587.83]],"ltp":2.04,"tv":81.52,"id":40096580}]}]}
{"op":"mcm","clk":"11840464770","pt":1723547030042,"mc":[{"id":"1.231730206","rc":[{"batb":[[0,2.02,37.98],[1,2,587.83],[2,1.95,606]],"ltp":2.04,"tv":81.52,"id":40096580}]}]}
{"op":"mcm","clk":"11840465013","pt":1723547036370,"mc":[{"id":"1.231730206","rc":[{"batb":[[0,2.04,10],[1,2.02,37.98],[2,2,587.83]],"ltp":2.04,"tv":81.52,"id":40096580}]}]}
{"op":"mcm","clk":"11840465170","pt":1723547039874,"mc":[{"id":"1.231730206","rc":[{"batb":[[0,2.02,37.98],[1,2,587.83],[2,1.95,606]],"ltp":2.04,"tv":81.52,"id":40096580}]}]}
{"op":"mcm","clk":"11840465305","pt":1723547042867,"mc":[{"id":"1.231730206","rc":[{"batb":[[0,2.04,10],[1,2.02,37.98],[2,2,587.83]],"ltp":2.04,"tv":81.52,"id":40096580}]}]}
{"op":"mcm","clk":"11840465452","pt":1723547046172,"mc":[{"id":"1.231730206","rc":[{"batb":[[0,2.02,37.98],[1,2,587.83],[2,1.95,606]],"ltp":2.04,"tv":81.52,"id":40096580}]}]}
{"op":"mcm","clk":"11840465575","pt":1723547049269,"mc":[{"id":"1.231730206","rc":[{"batb":[[0,2.04,10],[1,2.02,37.98],[2,2,587.83]],"ltp":2.04,"tv":81.52,"id":40096580}]}]}
{"op":"mcm","clk":"11840465706","pt":1723547052562,"mc":[{"id":"1.231730206","rc":[{"batb":[[0,2.02,37.98],[1,2,587.83],[2,1.95,606]],"ltp":2.04,"tv":81.52,"id":40096580}]}]}
{"op":"mcm","clk":"11840465879","pt":1723547056383,"mc":[{"id":"1.231730206","rc":[{"batb":[[0,2.04,10],[1,2.02,37.98],[2,2,587.83]],"ltp":2.04,"tv":81.52,"id":40096580}]}]}
{"op":"mcm","clk":"11840466016","pt":1723547059681,"mc":[{"id":"1.231730206","rc":[{"batb":[[0,2.02,37.98],[1,2,587.83],[2,1.95,606]],"ltp":2.04,"tv":81.52,"id":40096580}]}]}
{"op":"mcm","clk":"11840466156","pt":1723547062368,"mc":[{"id":"1.231730206","rc":[{"batb":[[0,2.04,10],[1,2.02,37.98],[2,2,587.83]],"ltp":2.04,"tv":81.52,"id":40096580}]}]}
{"op":"mcm","clk":"11840466344","pt":1723547065980,"mc":[{"id":"1.231730206","rc":[{"batb":[[0,2.02,37.98],[1,2,587.83],[2,1.95,606]],"ltp":2.04,"tv":81.52,"id":40096580}]}]}
{"op":"mcm","clk":"11840466483","pt":1723547068802,"mc":[{"id":"1.231730206","rc":[{"batb":[[0,2.04,10],[1,2.02,37.98],[2,2,587.83]],"ltp":2.04,"tv":81.52,"id":40096580}]}]}
{"op":"mcm","clk":"11840466643","pt":1723547072412,"mc":[{"id":"1.231730206","rc":[{"batb":[[0,2.02,37.98],[1,2,587.83],[2,1.95,606]],"ltp":2.04,"tv":81.52,"id":40096580}]}]}
{"op":"mcm","clk":"11840466788","pt":1723547075406,"mc":[{"id":"1.231730206","rc":[{"batb":[[0,2.04,10],[1,2.02,37.98],[2,2,587.83]],"ltp":2.04,"tv":81.52,"id":40096580}]}]}
{"op":"mcm","clk":"11840466932","pt":1723547078704,"mc":[{"id":"1.231730206","rc":[{"batb":[[0,2.02,37.98],[1,2,587.83],[2,1.95,606]],"ltp":2.04,"tv":81.52,"id":40096580}]}]}
{"op":"mcm","clk":"11840467131","pt":1723547083414,"mc":[{"id":"1.231730206","rc":[{"batb":[[0,2.04,10],[1,2.02,37.98],[2,2,587.83]],"ltp":2.04,"tv":81.52,"id":40096580}]}]}
{"op":"mcm","clk":"11840467296","pt":1723547086929,"mc":[{"id":"1.231730206","rc":[{"batb":[[0,2.02,37.98],[1,2,587.83],[2,1.95,606]],"ltp":2.04,"tv":81.52,"id":40096580}]}]}
{"op":"mcm","clk":"11840467597","pt":1723547093337,"mc":[{"id":"1.231730206","rc":[{"batb":[[0,2.04,10],[1,2.02,37.98],[2,2,587.83]],"ltp":2.04,"tv":81.52,"id":40096580}]}]}
{"op":"mcm","clk":"11840467765","pt":1723547096743,"mc":[{"id":"1.231730206","rc":[{"batb":[[0,2.02,37.98],[1,2,587.83],[2,1.95,606]],"ltp":2.04,"tv":81.52,"id":40096580}]}]}
{"op":"mcm","clk":"11840468033","pt":1723547102945,"mc":[{"id":"1.231730206","rc":[{"batb":[[0,2.04,10],[1,2.02,37.98],[2,2,587.83]],"ltp":2.04,"tv":81.52,"id":40096580}]}]}
{"op":"mcm","clk":"11840468211","pt":1723547106452,"mc":[{"id":"1.231730206","rc":[{"batb":[[0,2.02,37.98],[1,2,587.83],[2,1.95,606]],"ltp":2.04,"tv":81.52,"id":40096580}]}]}
{"op":"mcm","clk":"11840468460","pt":1723547111841,"mc":[{"id":"1.231730206","rc":[{"batb":[[0,2.04,10],[1,2.02,37.98],[2,2,587.83]],"ltp":2.04,"tv":81.52,"id":40096580}]}]}
{"op":"mcm","clk":"11840468645","pt":1723547115347,"mc":[{"id":"1.231730206","rc":[{"batb":[[0,2.02,37.98],[1,2,587.83],[2,1.95,606]],"ltp":2.04,"tv":81.52,"id":40096580}]}]}
{"op":"mcm","clk":"11840468782","pt":1723547117761,"mc":[{"id":"1.231730206","rc":[{"batb":[[0,2.04,10],[1,2.02,37.98],[2,2,587.83]],"ltp":2.04,"tv":81.52,"id":40096580}]}]}
{"op":"mcm","clk":"11840468985","pt":1723547121266,"mc":[{"id":"1.231730206","rc":[{"batb":[[0,2.02,37.98],[1,2,587.83],[2,1.95,606]],"ltp":2.04,"tv":81.52,"id":40096580}]}]}
{"op":"mcm","clk":"11840469105","pt":1723547123469,"mc":[{"id":"1.231730206","rc":[{"batb":[[0,2.04,10],[1,2.02,37.98],[2,2,587.83]],"ltp":2.04,"tv":81.52,"id":40096580}]}]}
{"op":"mcm","clk":"11840469283","pt":1723547127073,"mc":[{"id":"1.231730206","rc":[{"batb":[[0,2.02,37.98],[1,2,587.83],[2,1.95,606]],"ltp":2.04,"tv":81.52,"id":40096580}]}]}
{"op":"mcm","clk":"11840469398","pt":1723547129669,"mc":[{"id":"1.231730206","rc":[{"batb":[[0,2.04,10],[1,2.02,37.98],[2,2,587.83]],"ltp":2.04,"tv":81.52,"id":40096580}]}]}
{"op":"mcm","clk":"11840469557","pt":1723547133283,"mc":[{"id":"1.231730206","rc":[{"batb":[[0,2.02,37.98],[1,2,587.83],[2,1.95,606]],"ltp":2.04,"tv":81.52,"id":40096580}]}]}
{"op":"mcm","clk":"11840469770","pt":1723547136681,"mc":[{"id":"1.231730206","rc":[{"batb":[[0,2.04,10],[1,2.02,37.98],[2,2,587.83]],"ltp":2.04,"tv":81.52,"id":40096580}]}]}
{"op":"mcm","clk":"11840469943","pt":1723547140073,"mc":[{"id":"1.231730206","rc":[{"batb":[[0,2.02,37.98],[1,2,587.83],[2,1.95,606]],"ltp":2.04,"tv":81.52,"id":40096580}]}]}
{"op":"mcm","clk":"11840470066","pt":1723547142273,"mc":[{"id":"1.231730206","rc":[{"batb":[[0,2.04,10],[1,2.02,37.98],[2,2,587.83]],"ltp":2.04,"tv":81.52,"id":40096580}]}]}
{"op":"mcm","clk":"11840470213","pt":1723547145670,"mc":[{"id":"1.231730206","rc":[{"batb":[[0,2.02,37.98],[1,2,587.83],[2,1.95,606]],"ltp":2.04,"tv":81.52,"id":40096580}]}]}
