{"op":"mcm","clk":"11847777756","pt":1723653244502,"mc":[{"id":"1.231815703","marketDefinition":{"bspMarket":false,"turnInPlayEnabled":true,"persistenceEnabled":true,"marketBaseRate":5.0,"eventId":"33495145","eventTypeId":"4","numberOfWinners":1,"bettingType":"ODDS","marketType":"MATCH_ODDS","marketTime":"2024-08-15T12:00:00.000Z","suspendTime":"2024-08-15T12:00:00.000Z","bspReconciled":false,"complete":true,"inPlay":false,"crossMatching":false,"runnersVoidable":false,"numberOfActiveRunners":2,"betDelay":0,"status":"OPEN","runners":[{"status":"ACTIVE","sortPriority":1,"id":12474498,"name":"Papua New Guinea Women"},{"status":"ACTIVE","sortPriority":2,"id":12482925,"name":"Scotland Women"}],"regulators":["MR_INT"],"countryCode":"GB","discountAllowed":false,"timezone":"GMT","openDate":"2024-08-15T12:00:00.000Z","version":6074572427,"name":"Match Odds","eventName":"Papua New Guinea Women v Scotland Women"},"rc":[{"batb":[[0,1.03,200],[1,1.02,200],[2,1.01,220]],"ltp":0.0,"tv":0.0,"id":12474498},{"batb":[[0,1.03,200],[1,1.02,200],[2,1.01,220]],"ltp":0.0,"tv":0.0,"id":12482925}]}]}
{"op":"mcm","clk":"11847777959","pt":1723653246018,"mc":[{"id":"1.231815703","marketDefinition":{"bspMarket":false,"turnInPlayEnabled":true,"persistenceEnabled":true,"marketBaseRate":5.0,"eventId":"33495145","eventTypeId":"4","numberOfWinners":1,"bettingType":"ODDS","marketType":"MATCH_ODDS","marketTime":"2024-08-15T12:00:00.000Z","suspendTime":"2024-08-15T12:00:00.000Z","bspReconciled":false,"complete":true,"inPlay":false,"crossMatching":false,"runnersVoidable":false,"numberOfActiveRunners":2,"betDelay":0,"status":"OPEN","runners":[{"status":"ACTIVE","sortPriority":1,"id":12474498,"name":"Papua New Guinea Women"},{"status":"ACTIVE","sortPriority":2,"id":12482925,"name":"Scotland Women"}],"regulators":["MR_INT"],"countryCode":"GB","discountAllowed":true,"timezone":"GMT","openDate":"2024-08-15T12:00:00.000Z","version":6074572427,"name":"Match Odds","eventName":"Papua New Guinea Women v Scotland Women"}}]}
{"op":"mcm","clk":"11847783826","pt":1723653290961,"mc":[{"id":"1.231815703","rc":[{"batb":[[0,1.04,1636.21],[1,1.03,2365.59],[2,1.02,3397.77]],"ltp":0.0,"tv":0.0,"id":12474498}]}]}
{"op":"mcm","clk":"11847783911","pt":1723653291686,"mc":[{"id":"1.231815703","rc":[{"batb":[[0,1.04,1636.21],[1,1.03,2365.59],[2,1.02,3397.77]],"ltp":0.0,"tv":0.0,"id":12482925}]}]}
{"op":"mcm","clk":"11848244012","pt":1723656668928,"mc":[{"id":"1.231815703","rc":[{"batb":[[0,1.04,1636.77],[1,1.03,2366.34],[2,1.02,3398.87]],"ltp":0.0,"tv":0.0,"id":12474498},{"batb":[[0,1.04,1636.77],[1,1.03,2366.34],[2,1.02,3398.87]],"ltp":0.0,"tv":0.0,"id":12482925}]}]}
{"op":"mcm","clk":"11848247374","pt":1723656696355,"mc":[{"id":"1.231815703","marketDefinition":{"bspMarket":false,"turnInPlayEnabled":true,"persistenceEnabled":true,"marketBaseRate":5.0,"eventId":"33495145","eventTypeId":"4","numberOfWinners":1,"bettingType":"ODDS","marketType":"MATCH_ODDS","marketTime":"2024-08-15T12:00:00.000Z","suspendTime":"2024-08-15T12:00:00.000Z","bspReconciled":false,"complete":true,"inPlay":false,"crossMatching":true,"runnersVoidable":false,"numberOfActiveRunners":2,"betDelay":0,"status":"OPEN","runners":[{"status":"ACTIVE","sortPriority":1,"id":12474498,"name":"Papua New Guinea Women"},{"status":"ACTIVE","sortPriority":2,"id":12482925,"name":"Scotland Women"}],"regulators":["MR_INT"],"countryCode":"GB","discountAllowed":true,"timezone":"GMT","openDate":"2024-08-15T12:00:00.000Z","version":6074572427,"name":"Match Odds","eventName":"Papua New Guinea Women v Scotland Women"}}]}
{"op":"mcm","clk":"11848350123","pt":1723657384583,"mc":[{"id":"1.231815703","rc":[{"batb":[[0,1.1,10000],[1,1.04,1636.77],[2,1.03,2366.34]],"ltp":0.0,"tv":0.0,"id":12474498}]}]}
{"op":"mcm","clk":"11848350726","pt":1723657388202,"mc":[{"id":"1.231815703","rc":[{"batl":[[0,2,1000]],"ltp":0.0,"tv":0.0,"id":12474498}]}]}
{"op":"mcm","clk":"11848358825","pt":1723657435648,"mc":[{"id":"1.231815703","rc":[{"trd":[[2,100]],"batb":[[0,1.11,10],[1,1.1,10000],[2,1.04,1636.77]],"batl":[[0,2,900]],"ltp":2.0,"tv":100.0,"id":12474498},{"trd":[[2,100]],"ltp":2.0,"tv":100.0,"id":12482925}],"tv":200.0}]}
{"op":"mcm","clk":"11848359350","pt":1723657438931,"mc":[{"id":"1.231815703","rc":[{"batb":[[0,1.1,10000],[1,1.04,1636.77],[2,1.03,2366.34]],"ltp":2.0,"tv":100.0,"id":12474498}]}]}
{"op":"mcm","clk":"11848360291","pt":1723657444446,"mc":[{"id":"1.231815703","rc":[{"trd":[[2,200]],"batb":[[0,1.11,10],[1,1.1,10000],[2,1.04,1636.77]],"batl":[[0,2,800]],"ltp":2.0,"tv":200.0,"id":12474498},{"trd":[[2,200]],"ltp":2.0,"tv":200.0,"id":12482925}],"tv":400.0}]}
{"op":"mcm","clk":"11848360812","pt":1723657447784,"mc":[{"id":"1.231815703","rc":[{"batb":[[0,1.1,10000],[1,1.04,1636.77],[2,1.03,2366.34]],"ltp":2.0,"tv":200.0,"id":12474498}]}]}
{"op":"mcm","clk":"11848363272","pt":1723657462567,"mc":[{"id":"1.231815703","rc":[{"batb":[[0,2,200],[1,1.1,10000],[2,1.04,1636.77]],"ltp":2.0,"tv":200.0,"id":12474498}]}]}
{"op":"mcm","clk":"11848367615","pt":1723657489905,"mc":[{"id":"1.231815703","rc":[{"batb":[[1,1.04,1636.77],[2,1.03,2366.34]],"ltp":2.0,"tv":200.0,"id":12474498}]}]}
{"op":"mcm","clk":"11848369754","pt":1723657501903,"mc":[{"id":"1.231815703","rc":[{"batb":[[0,1.05,10],[1,1.04,1636.77],[2,1.03,2366.34]],"batl":[[0,2,1000]],"ltp":2.0,"tv":200.0,"id":12482925}]}]}
{"op":"mcm","clk":"11848370332","pt":1723657505117,"mc":[{"id":"1.231815703","rc":[{"batb":[[0,1.04,1636.77],[1,1.03,2366.34],[2,1.02,3398.87]],"ltp":2.0,"tv":200.0,"id":12482925}]}]}
{"op":"mcm","clk":"11848374467","pt":1723657528934,"mc":[{"id":"1.231815703","rc":[{"batb":[[0,1.1,7000],[1,1.04,1636.77],[2,1.03,2366.34]],"ltp":2.0,"tv":200.0,"id":12482925}]}]}
{"op":"mcm","clk":"11848374500","pt":1723657529141,"mc":[{"id":"1.231815703","rc":[{"batb":[[0,1.11,10],[1,1.1,7000],[2,1.04,1636.77]],"ltp":2.0,"tv":200.0,"id":12482925}]}]}
{"op":"mcm","clk":"11848375053","pt":1723657532455,"mc":[{"id":"1.231815703","rc":[{"batb":[[0,1.1,7000],[1,1.04,1636.77],[2,1.03,2366.34]],"ltp":2.0,"tv":200.0,"id":12482925}]}]}
{"op":"mcm","clk":"11848377486","pt":1723657547177,"mc":[{"id":"1.231815703","rc":[{"batb":[[0,1.05,10]],"ltp":2.0,"tv":200.0,"id":12482925}]}]}
{"op":"mcm","clk":"11848377653","pt":1723657548175,"mc":[{"id":"1.231815703","rc":[{"batb":[[0,1.1,8000],[1,1.05,10],[2,1.04,1636.77]],"ltp":2.0,"tv":200.0,"id":12482925}]}]}
{"op":"mcm","clk":"11848378063","pt":1723657550590,"mc":[{"id":"1.231815703","rc":[{"batb":[[1,1.04,1636.77],[2,1.03,2366.34]],"ltp":2.0,"tv":200.0,"id":12482925}]}]}
{"op":"mcm","clk":"11848389611","pt":1723657622951,"mc":[{"id":"1.231815703","rc":[{"batb":[[0,2.02,85.83],[1,2,200],[2,1.04,1636.77]],"ltp":2.0,"tv":200.0,"id":12474498},{"batb":[[0,1.11,10],[1,1.1,8000],[2,1.04,1636.77]],"ltp":2.0,"tv":200.0,"id":12482925}]}]}
{"op":"mcm","clk":"11848389858","pt":1723657624471,"mc":[{"id":"1.231815703","rc":[{"batb":[[0,2.02,171.66]],"ltp":2.0,"tv":200.0,"id":12474498}]}]}
{"op":"mcm","clk":"11848390260","pt":1723657626773,"mc":[{"id":"1.231815703","rc":[{"batb":[[0,1.12,257.49]],"ltp":2.0,"tv":200.0,"id":12482925}]}]}
{"op":"mcm","clk":"11848390747","pt":1723657629555,"mc":[{"id":"1.231815703","rc":[{"batb":[[0,1.13,10],[1,1.12,686.64],[2,1.1,8000]],"ltp":2.0,"tv":200.0,"id":12482925}]}]}
{"op":"mcm","clk":"11848391087","pt":1723657631495,"mc":[{"id":"1.231815703","rc":[{"batb":[[0,1.16,686.64],[1,1.13,10]],"ltp":2.0,"tv":200.0,"id":12482925}]}]}
{"op":"mcm","clk":"11848391289","pt":1723657632760,"mc":[{"id":"1.231815703","rc":[{"batb":[[1,1.1,8000],[2,1.04,1636.77]],"ltp":2.0,"tv":200.0,"id":12482925}]}]}
{"op":"mcm","clk":"11848393998","pt":1723657648989,"mc":[{"id":"1.231815703","rc":[{"batb":[[0,1.3,100],[1,1.16,686.64],[2,1.1,8000]],"ltp":2.0,"tv":200.0,"id":12482925}]}]}
{"op":"mcm","clk":"11848394017","pt":1723657649095,"mc":[{"id":"1.231815703","rc":[{"batb":[[0,1.31,10],[1,1.3,100],[2,1.16,686.64]],"ltp":2.0,"tv":200.0,"id":12482925}]}]}
{"op":"mcm","clk":"11848394703","pt":1723657652880,"mc":[{"id":"1.231815703","rc":[{"batb":[[0,1.32,686.64],[2,1.1,8000]],"ltp":2.0,"tv":200.0,"id":12482925}]}]}
{"op":"mcm","clk":"11848398226","pt":1723657675003,"mc":[{"id":"1.231815703","rc":[{"batb":[[1,1.04,1636.77],[2,1.03,2366.34]],"ltp":2.0,"tv":200.0,"id":12474498},{"batb":[[0,1.33,10],[1,1.32,686.64],[2,1.3,100]],"ltp":2.0,"tv":200.0,"id":12482925}]}]}
{"op":"mcm","clk":"11848398709","pt":1723657678305,"mc":[{"id":"1.231815703","rc":[{"batb":[[0,1.32,686.64],[1,1.3,100],[2,1.1,8000]],"ltp":2.0,"tv":200.0,"id":12482925}]}]}
{"op":"mcm","clk":"11848399115","pt":1723657680909,"mc":[{"id":"1.231815703","rc":[{"batb":[[0,1.32,52.91],[1,1.31,42.91],[2,1.3,100]],"ltp":2.0,"tv":200.0,"id":12482925}]}]}
{"op":"mcm","clk":"11848399208","pt":1723657681398,"mc":[{"id":"1.231815703","rc":[{"batb":[[0,1.35,42.91],[1,1.34,42.91],[2,1.32,52.91]],"ltp":2.0,"tv":200.0,"id":12482925}]}]}
{"op":"mcm","clk":"11848399387","pt":1723657682507,"mc":[{"id":"1.231815703","rc":[{"batb":[[0,1.37,42.91],[1,1.35,42.91],[2,1.34,42.91]],"batl":[[0,1.9,100],[1,2,1000]],"ltp":2.0,"tv":200.0,"id":12482925}]}]}
{"op":"mcm","clk":"11848399589","pt":1723657683819,"mc":[{"id":"1.231815703","rc":[{"batb":[[1,1.08,1.72],[2,1.04,1636.77]],"ltp":2.0,"tv":200.0,"id":12474498},{"batl":[[0,1.8,100],[1,1.9,100],[2,2,1000]],"ltp":2.0,"tv":200.0,"id":12482925}]}]}
{"op":"mcm","clk":"11848399705","pt":1723657684508,"mc":[{"id":"1.231815703","rc":[{"batb":[[0,2.02,171.74],[1,1.04,1636.77],[2,1.03,2366.34]],"ltp":2.0,"tv":200.0,"id":12474498}]}]}
{"op":"mcm","clk":"11848400246","pt":1723657687809,"mc":[{"id":"1.231815703","rc":[{"batb":[[0,2.26,42.91],[1,2.02,171.74],[2,1.04,1636.77]],"ltp":2.0,"tv":200.0,"id":12474498}]}]}
{"op":"mcm","clk":"11848400315","pt":1723657688227,"mc":[{"id":"1.231815703","rc":[{"batb":[[0,2.26,85.83]],"ltp":2.0,"tv":200.0,"id":12474498}]}]}
{"op":"mcm","clk":"11848400899","pt":1723657691828,"mc":[{"id":"1.231815703","rc":[{"batb":[[0,1.34,42.91],[1,1.32,42.91],[2,1.31,42.91]],"ltp":2.0,"tv":200.0,"id":12482925}]}]}
{"op":"mcm","clk":"11848400945","pt":1723657692142,"mc":[{"id":"1.231815703","rc":[{"batb":[[0,1.32,42.91],[1,1.31,42.91],[2,1.3,100]],"ltp":2.0,"tv":200.0,"id":12482925}]}]}
{"op":"mcm","clk":"11848401880","pt":1723657697509,"mc":[{"id":"1.231815703","rc":[{"batb":[[0,2.26,85.92],[1,2.02,171.66]],"ltp":2.0,"tv":200.0,"id":12474498}]}]}
{"op":"mcm","clk":"11848403195","pt":1723657706228,"mc":[{"id":"1.231815703","rc":[{"batl":[[0,1.9,100],[1,2,1000],[2,2,0]],"ltp":2.0,"tv":200.0,"id":12482925}]}]}
{"op":"mcm","clk":"11848403450","pt":1723657707948,"mc":[{"id":"1.231815703","rc":[{"batb":[[0,1.33,10],[1,1.32,42.91],[2,1.31,42.91]],"batl":[[0,2,1000],[1,2,0]],"ltp":2.0,"tv":200.0,"id":12482925}]}]}
{"op":"mcm","clk":"11848403797","pt":1723657710651,"mc":[{"id":"1.231815703","rc":[{"batl":[[0,1.6,250],[1,2,1000]],"ltp":2.0,"tv":200.0,"id":12482925}]}]}
{"op":"mcm","clk":"11848403890","pt":1723657711235,"mc":[{"id":"1.231815703","rc":[{"batb":[[0,1.32,42.91],[1,1.31,42.91],[2,1.3,100]],"ltp":2.0,"tv":200.0,"id":12482925}]}]}
{"op":"mcm","clk":"11848406496","pt":1723657728559,"mc":[{"id":"1.231815703","rc":[{"batb":[[2,1.1,200]],"ltp":2.0,"tv":200.0,"id":12474498}]}]}
{"op":"mcm","clk":"11848406649","pt":1723657729651,"mc":[{"id":"1.231815703","rc":[{"batb":[[2,1.2,100]],"ltp":2.0,"tv":200.0,"id":12474498}]}]}
{"op":"mcm","clk":"11848406829","pt":1723657731057,"mc":[{"id":"1.231815703","rc":[{"batb":[[2,1.3,66.67]],"ltp":2.0,"tv":200.0,"id":12474498}]}]}
{"op":"mcm","clk":"11848407050","pt":1723657732572,"mc":[{"id":"1.231815703","rc":[{"batb":[[2,1.4,50]],"ltp":2.0,"tv":200.0,"id":12474498}]}]}
{"op":"mcm","clk":"11848415305","pt":1723657791033,"mc":[{"id":"1.231815703","rc":[{"trd":[[1.6,200]],"batl":[[0,1.6,150]],"ltp":1.6,"tv":400.0,"id":12482925}],"tv":600.0}]}
{"op":"mcm","clk":"11848416610","pt":1723657799997,"mc":[{"id":"1.231815703","rc":[{"batb":[[0,2.04,85.92]],"ltp":2.0,"tv":200.0,"id":12474498}]}]}
{"op":"mcm","clk":"11848416709","pt":1723657800586,"mc":[{"id":"1.231815703","rc":[{"batb":[[0,2.04,85.83]],"ltp":2.0,"tv":200.0,"id":12474498}]}]}
{"op":"mcm","clk":"11848416875","pt":1723657801650,"mc":[{"id":"1.231815703","rc":[{"trd":[[1.6,500]],"batb":[[0,1.33,10],[1,1.32,42.91],[2,1.31,42.91]],"batl":[[0,2,1000],[1,2,0]],"ltp":1.6,"tv":700.0,"id":12482925}],"tv":900.0}]}
{"op":"mcm","clk":"11848417078","pt":1723657802959,"mc":[{"id":"1.231815703","rc":[{"batb":[[1,1.2,1000],[2,1.18,42.91]],"ltp":1.6,"tv":700.0,"id":12482925}]}]}
{"op":"mcm","clk":"11848417357","pt":1723657804965,"mc":[{"id":"1.231815703","rc":[{"batb":[[0,1.2,1000],[1,1.18,42.91],[2,1.17,42.91]],"ltp":1.6,"tv":700.0,"id":12482925}]}]}
{"op":"mcm","clk":"11848417488","pt":1723657805743,"mc":[{"id":"1.231815703","rc":[{"batb":[[0,1.23,85.83],[1,1.21,42.91],[2,1.2,1000]],"ltp":1.6,"tv":700.0,"id":12482925}]}]}
{"op":"mcm","clk":"11848417778","pt":1723657807870,"mc":[{"id":"1.231815703","rc":[{"batb":[[0,1.24,10],[1,1.23,85.83],[2,1.22,42.91]],"ltp":1.6,"tv":700.0,"id":12482925}]}]}
{"op":"mcm","clk":"11848417988","pt":1723657809492,"mc":[{"id":"1.231815703","rc":[{"batb":[[0,1.24,52.91]],"ltp":1.6,"tv":700.0,"id":12482925}]}]}
{"op":"mcm","clk":"11848418193","pt":1723657811069,"mc":[{"id":"1.231815703","rc":[{"batb":[[0,1.24,42.91]],"ltp":1.6,"tv":700.0,"id":12482925}]}]}
{"op":"mcm","clk":"11848428742","pt":1723657892169,"mc":[{"id":"1.231815703","rc":[{"batl":[[0,1.9,50],[1,2,1000]],"ltp":1.6,"tv":700.0,"id":12482925}]}]}
{"op":"mcm","clk":"11848438586","pt":1723657970044,"mc":[{"id":"1.231815703","rc":[{"batb":[[0,3,45],[1,2.04,85.83],[2,2.02,171.66]],"ltp":2.0,"tv":200.0,"id":12474498}]}]}
{"op":"mcm","clk":"11848441579","pt":1723657993401,"mc":[{"id":"1.231815703","rc":[{"batl":[[0,1.45,225],[1,1.9,50],[2,2,1000]],"ltp":1.6,"tv":700.0,"id":12482925}]}]}
{"op":"mcm","clk":"11848442290","pt":1723657999482,"mc":[{"id":"1.231815703","rc":[{"batb":[[0,2.04,85.83],[1,2.02,171.66],[2,1.4,50]],"ltp":2.0,"tv":200.0,"id":12474498}]}]}
{"op":"mcm","clk":"11848445423","pt":1723658023299,"mc":[{"id":"1.231815703","rc":[{"batb":[[0,1.43,2.34],[1,1.24,42.91],[2,1.23,85.83]],"ltp":1.6,"tv":700.0,"id":12482925}]}]}
{"op":"mcm","clk":"11848446629","pt":1723658033313,"mc":[{"id":"1.231815703","rc":[{"trd":[[1.43,4]],"batb":[[0,1.24,43.25],[1,1.23,85.83],[2,1.22,42.91]],"ltp":1.43,"tv":704.0,"id":12482925}],"tv":904.0}]}
{"op":"mcm","clk":"11848449409","pt":1723658053973,"mc":[{"id":"1.231815703","rc":[{"batl":[[0,3.3,1.56]],"ltp":2.0,"tv":200.0,"id":12474498}]}]}
{"op":"mcm","clk":"11848449436","pt":1723658054127,"mc":[{"id":"1.231815703","rc":[{"batb":[[0,2.06,14],[1,2.04,85.83],[2,2.02,171.66]],"ltp":2.0,"tv":200.0,"id":12474498}]}]}
{"op":"mcm","clk":"11848449733","pt":1723658056366,"mc":[{"id":"1.231815703","rc":[{"batb":[[0,2.06,10]],"ltp":2.0,"tv":200.0,"id":12474498}]}]}
{"op":"mcm","clk":"11848449898","pt":1723658057564,"mc":[{"id":"1.231815703","rc":[{"batb":[[0,2.04,85.83],[1,2.02,171.66],[2,1.4,50]],"ltp":2.0,"tv":200.0,"id":12474498}]}]}
{"op":"mcm","clk":"11848450572","pt":1723658063145,"mc":[{"id":"1.231815703","rc":[{"trd":[[3.3,3.12]],"batb":[[0,3.3,34.63],[1,2.04,85.83],[2,2.02,171.66]],"ltp":3.3,"tv":203.11,"id":12474498}],"tv":907.11}]}
{"op":"mcm","clk":"11848451946","pt":1723658074252,"mc":[{"id":"1.231815703","rc":[{"batl":[[1,1.54,225],[2,1.9,50]],"ltp":1.43,"tv":704.0,"id":12482925}]}]}
{"op":"mcm","clk":"11848453920","pt":1723658089899,"mc":[{"id":"1.231815703","rc":[{"trd":[[1.43,4.67]],"batb":[[0,1.24,42.91]],"batl":[[0,1.4,224.67],[1,1.45,225],[2,1.54,225]],"ltp":1.43,"tv":704.66,"id":12482925}],"tv":907.78}]}
{"op":"mcm","clk":"11848456119","pt":1723658106924,"mc":[{"id":"1.231815703","rc":[{"trd":[[3.5,10]],"ltp":3.5,"tv":213.11,"id":12474498},{"trd":[[1.4,25]],"batl":[[0,1.4,199.67]],"ltp":1.4,"tv":729.66,"id":12482925}],"tv":942.78}]}
{"op":"mcm","clk":"11848456931","pt":1723658112803,"mc":[{"id":"1.231815703","rc":[{"batl":[[0,1.25,2.34],[1,1.4,199.67],[2,1.45,225]],"ltp":1.4,"tv":729.66,"id":12482925}]}]}
{"op":"mcm","clk":"11848457077","pt":1723658113931,"mc":[{"id":"1.231815703","rc":[{"batl":[[1,1.38,6],[2,1.4,199.67]],"ltp":1.4,"tv":729.66,"id":12482925}]}]}
{"op":"mcm","clk":"11848457778","pt":1723658119504,"mc":[{"id":"1.231815703","rc":[{"batl":[[1,1.4,199.67],[2,1.45,225]],"ltp":1.4,"tv":729.66,"id":12482925}]}]}
{"op":"mcm","clk":"11848458124","pt":1723658122521,"mc":[{"id":"1.231815703","rc":[{"trd":[[1.25,4]],"batl":[[0,1.4,200],[1,1.45,225],[2,1.54,225]],"ltp":1.25,"tv":733.66,"id":12482925}],"tv":946.78}]}
{"op":"mcm","clk":"11848458472","pt":1723658125444,"mc":[{"id":"1.231815703","rc":[{"batl":[[0,1.4,199.67]],"ltp":1.25,"tv":733.66,"id":12482925}]}]}
{"op":"mcm","clk":"11848461417","pt":1723658150132,"mc":[{"id":"1.231815703","rc":[{"batb":[[0,3.6,182.14],[1,3.3,34.63],[2,2.04,85.83]],"ltp":3.5,"tv":213.11,"id":12474498}]}]}
{"op":"mcm","clk":"11848461576","pt":1723658151435,"mc":[{"id":"1.231815703","rc":[{"batl":[[0,1.39,30],[1,1.4,199.67],[2,1.45,225]],"ltp":1.25,"tv":733.66,"id":12482925}]}]}
{"op":"mcm","clk":"11848462605","pt":1723658160442,"mc":[{"id":"1.231815703","rc":[{"batb":[[0,3.65,10],[1,3.6,182.14],[2,3.3,34.63]],"batl":[[0,4.9,10]],"ltp":3.5,"tv":213.11,"id":12474498}]}]}
{"op":"mcm","clk":"11848463009","pt":1723658163778,"mc":[{"id":"1.231815703","rc":[{"batb":[[0,3.6,182.14],[1,3.3,34.63],[2,2.04,85.83]],"ltp":3.5,"tv":213.11,"id":12474498}]}]}
{"op":"mcm","clk":"11848464192","pt":1723658174783,"mc":[{"id":"1.231815703","rc":[{"batb":[[0,3.65,10],[1,3.6,182.14],[2,3.3,34.63]],"ltp":3.5,"tv":213.11,"id":12474498},{"batl":[[0,1.35,10],[1,1.39,30],[2,1.4,199.67]],"ltp":1.25,"tv":733.66,"id":12482925}]}]}
{"op":"mcm","clk":"11848464511","pt":1723658178016,"mc":[{"id":"1.231815703","rc":[{"batb":[[0,3.6,182.14],[1,3.3,34.63],[2,2.04,85.83]],"ltp":3.5,"tv":213.11,"id":12474498}]}]}
{"op":"mcm","clk":"11848465081","pt":1723658183162,"mc":[{"id":"1.231815703","rc":[{"trd":[[3.85,0.9]],"batb":[[0,3.65,10],[1,3.6,182.14],[2,3.3,34.63]],"ltp":3.85,"tv":214.02,"id":12474498},{"trd":[[1.35,2.58]],"batl":[[0,1.35,7.42]],"ltp":1.35,"tv":736.24,"id":12482925}],"tv":950.26}]}
{"op":"mcm","clk":"11848465467","pt":1723658186582,"mc":[{"id":"1.231815703","rc":[{"batb":[[0,3.6,182.14],[1,3.3,34.63],[2,2.04,85.83]],"ltp":3.85,"tv":214.02,"id":12474498}]}]}
{"op":"mcm","clk":"11848465854","pt":1723658190519,"mc":[{"id":"1.231815703","rc":[{"batb":[[0,3.65,10],[1,3.6,182.14],[2,3.3,34.63]],"ltp":3.85,"tv":214.02,"id":12474498},{"batl":[[0,1.39,30],[1,1.4,199.67],[2,1.45,225]],"ltp":1.35,"tv":736.24,"id":12482925}]}]}
{"op":"mcm","clk":"11848466202","pt":1723658193815,"mc":[{"id":"1.231815703","rc":[{"batb":[[0,3.6,182.14],[1,3.3,34.63],[2,2.04,85.83]],"ltp":3.85,"tv":214.02,"id":12474498}]}]}
{"op":"mcm","clk":"11848472420","pt":1723658248949,"mc":[{"id":"1.231815703","rc":[{"batl":[[0,1.38,22],[1,1.39,30],[2,1.4,199.67]],"ltp":1.35,"tv":736.24,"id":12482925}]}]}
{"op":"mcm","clk":"11848472433","pt":1723658249050,"mc":[{"id":"1.231815703","rc":[{"batb":[[0,3.65,10],[1,3.6,182.14],[2,3.3,34.63]],"ltp":3.85,"tv":214.02,"id":12474498}]}]}
{"op":"mcm","clk":"11848472781","pt":1723658252225,"mc":[{"id":"1.231815703","rc":[{"batb":[[0,3.6,182.14],[1,3.3,34.63],[2,2.04,85.83]],"ltp":3.85,"tv":214.02,"id":12474498}]}]}
{"op":"mcm","clk":"11848473883","pt":1723658261986,"mc":[{"id":"1.231815703","rc":[{"batb":[[0,3.65,10],[1,3.6,182.14],[2,3.3,34.63]],"ltp":3.85,"tv":214.02,"id":12474498},{"batl":[[0,1.35,5],[1,1.38,22],[2,1.39,30]],"ltp":1.35,"tv":736.24,"id":12482925}]}]}
{"op":"mcm","clk":"11848474248","pt":1723658265278,"mc":[{"id":"1.231815703","rc":[{"batb":[[0,3.6,182.14],[1,3.3,34.63],[2,2.04,85.83]],"ltp":3.85,"tv":214.02,"id":12474498}]}]}
{"op":"mcm","clk":"11848476353","pt":1723658282292,"mc":[{"id":"1.231815703","rc":[{"trd":[[3.85,1.27]],"batb":[[0,3.65,10],[1,3.6,182.14],[2,3.3,34.63]],"ltp":3.85,"tv":214.38,"id":12474498},{"trd":[[1.35,3.61]],"batl":[[0,1.35,3.97]],"ltp":1.35,"tv":737.27,"id":12482925}],"tv":951.66}]}
{"op":"mcm","clk":"11848476800","pt":1723658285627,"mc":[{"id":"1.231815703","rc":[{"batb":[[0,3.6,182.14],[1,3.3,34.63],[2,2.04,85.83]],"ltp":3.85,"tv":214.38,"id":12474498}]}]}
{"op":"mcm","clk":"11848479756","pt":1723658312437,"mc":[{"id":"1.231815703","rc":[{"batb":[[0,3.65,10],[1,3.6,182.14]],"ltp":3.85,"tv":214.38,"id":12474498}]}]}
{"op":"mcm","clk":"11848480114","pt":1723658315623,"mc":[{"id":"1.231815703","rc":[{"batb":[[0,3.6,182.14],[1,2.04,85.83],[2,2.02,171.66]],"ltp":3.85,"tv":214.38,"id":12474498}]}]}
{"op":"mcm","clk":"11848481586","pt":1723658327486,"mc":[{"id":"1.231815703","rc":[{"batb":[[0,2.06,10]],"ltp":3.85,"tv":214.38,"id":12474498}]}]}
{"op":"mcm","clk":"11848481990","pt":1723658330770,"mc":[{"id":"1.231815703","rc":[{"batb":[[0,2.04,85.83],[1,2.02,171.66],[2,1.4,50]],"ltp":3.85,"tv":214.38,"id":12474498}]}]}
{"op":"mcm","clk":"11848488002","pt":1723658385629,"mc":[{"id":"1.231815703","rc":[{"batb":[[0,2.06,10],[1,2.04,85.83],[2,2.02,171.66]],"ltp":3.85,"tv":214.38,"id":12474498}]}]}
{"op":"mcm","clk":"11848488424","pt":1723658388934,"mc":[{"id":"1.231815703","rc":[{"batb":[[0,2.04,85.83],[1,2.02,171.66],[2,1.4,50]],"ltp":3.85,"tv":214.38,"id":12474498}]}]}
{"op":"mcm","clk":"11848494534","pt":1723658437285,"mc":[{"id":"1.231815703","rc":[{"trd":[[3.3,3.12]],"batb":[[0,2.06,14],[1,2.04,85.85],[2,2.02,171.7]],"batl":[[0,3.9,2.34],[1,4.9,10]],"ltp":3.85,"tv":214.38,"id":12474498},{"trd":[[1.25,4],[1.43,4.67]],"batb":[[0,1.24,42.93],[1,1.23,85.85],[2,1.22,42.93]],"ltp":1.35,"tv":737.28,"id":12482925}],"tv":951.66}]}
{"op":"mcm","clk":"11848494857","pt":1723658439588,"mc":[{"id":"1.231815703","rc":[{"batb":[[0,2.06,10]],"ltp":3.85,"tv":214.38,"id":12474498}]}]}
{"op":"mcm","clk":"11848494990","pt":1723658440573,"mc":[{"id":"1.231815703","rc":[{"batb":[[0,2.04,85.85],[1,2.02,171.7],[2,1.4,50]],"ltp":3.85,"tv":214.38,"id":12474498}]}]}
{"op":"mcm","clk":"11848495704","pt":1723658445903,"mc":[{"id":"1.231815703","rc":[{"batl":[[0,4.9,10],[1,4.9,0]],"ltp":3.85,"tv":214.38,"id":12474498}]}]}
{"op":"mcm","clk":"11848495732","pt":1723658446112,"mc":[{"id":"1.231815703","rc":[{"batb":[[0,2.06,10],[1,2.04,85.85],[2,2.02,171.7]],"ltp":3.85,"tv":214.38,"id":12474498}]}]}
{"op":"mcm","clk":"11848496142","pt":1723658449400,"mc":[{"id":"1.231815703","rc":[{"batb":[[0,2.04,85.85],[1,2.02,171.7],[2,1.4,50]],"ltp":3.85,"tv":214.38,"id":12474498}]}]}
{"op":"mcm","clk":"11848497168","pt":1723658457391,"mc":[{"id":"1.231815703","rc":[{"batb":[[0,2.06,14],[1,2.04,85.85],[2,2.02,171.7]],"batl":[[0,3.9,2.34],[1,4.9,10]],"ltp":3.85,"tv":214.38,"id":12474498}]}]}
{"op":"mcm","clk":"11848497436","pt":1723658459734,"mc":[{"id":"1.231815703","rc":[{"batb":[[0,2.06,10]],"ltp":3.85,"tv":214.38,"id":12474498}]}]}
{"op":"mcm","clk":"11848497541","pt":1723658460625,"mc":[{"id":"1.231815703","rc":[{"batb":[[0,2.04,85.85],[1,2.02,171.7],[2,1.4,50]],"ltp":3.85,"tv":214.38,"id":12474498}]}]}
{"op":"mcm","clk":"11848498898","pt":1723658470717,"mc":[{"id":"1.231815703","rc":[{"batb":[[0,2.06,10],[1,2.04,85.85],[2,2.02,171.7]],"batl":[[0,4.9,10],[1,4.9,0]],"ltp":3.85,"tv":214.38,"id":12474498}]}]}
{"op":"mcm","clk":"11848499307","pt":1723658474055,"mc":[{"id":"1.231815703","rc":[{"batb":[[0,2.04,85.85],[1,2.02,171.7],[2,1.4,50]],"ltp":3.85,"tv":214.38,"id":12474498}]}]}
{"op":"mcm","clk":"11848501412","pt":1723658491573,"mc":[{"id":"1.231815703","rc":[{"batb":[[0,2.06,10],[1,2.04,85.85],[2,2.02,171.7]],"ltp":3.85,"tv":214.38,"id":12474498},{"batb":[[0,1.25,45.08],[1,1.24,42.93],[2,1.23,85.85]],"ltp":1.35,"tv":737.28,"id":12482925}]}]}
{"op":"mcm","clk":"11848501843","pt":1723658494980,"mc":[{"id":"1.231815703","rc":[{"batb":[[0,2.04,85.85],[1,2.02,171.7],[2,1.4,50]],"ltp":3.85,"tv":214.38,"id":12474498}]}]}
{"op":"mcm","clk":"11848504811","pt":1723658520375,"mc":[{"id":"1.231815703","rc":[{"batb":[[0,2.06,10],[1,2.04,85.85],[2,2.02,171.7]],"ltp":3.85,"tv":214.38,"id":12474498},{"batl":[[0,1.26,2.34],[1,1.35,3.97],[2,1.38,22]],"ltp":1.35,"tv":737.28,"id":12482925}]}]}
{"op":"mcm","clk":"11848505198","pt":1723658523617,"mc":[{"id":"1.231815703","rc":[{"batb":[[0,2.04,85.85],[1,2.02,171.7],[2,1.4,50]],"ltp":3.85,"tv":214.38,"id":12474498}]}]}
{"op":"mcm","clk":"11848506830","pt":1723658536921,"mc":[{"id":"1.231815703","rc":[{"batl":[[0,1.35,3.97],[1,1.38,22],[2,1.39,30]],"ltp":1.35,"tv":737.28,"id":12482925}]}]}
{"op":"mcm","clk":"11848506846","pt":1723658537129,"mc":[{"id":"1.231815703","rc":[{"batb":[[0,2.06,10],[1,2.04,85.85],[2,2.02,171.7]],"ltp":3.85,"tv":214.38,"id":12474498}]}]}
{"op":"mcm","clk":"11848507266","pt":1723658540326,"mc":[{"id":"1.231815703","rc":[{"batb":[[0,2.04,85.85],[1,2.02,171.7],[2,1.4,50]],"ltp":3.85,"tv":214.38,"id":12474498}]}]}
{"op":"mcm","clk":"11848508623","pt":1723658551148,"mc":[{"id":"1.231815703","rc":[{"batb":[[0,2.06,10],[1,2.04,85.85],[2,2.02,171.7]],"ltp":3.85,"tv":214.38,"id":12474498},{"batl":[[0,1.26,3.12],[1,1.35,3.97],[2,1.38,22]],"ltp":1.35,"tv":737.28,"id":12482925}]}]}
{"op":"mcm","clk":"11848509014","pt":1723658554864,"mc":[{"id":"1.231815703","rc":[{"batb":[[0,3.55,3.48]],"ltp":3.85,"tv":214.38,"id":12474498},{"trd":[[1.26,6.24]],"batb":[[0,1.26,4.65],[1,1.25,45.08],[2,1.24,42.93]],"batl":[[0,1.35,3.97],[1,1.38,22],[2,1.39,30]],"ltp":1.26,"tv":743.51,"id":12482925}],"tv":957.9}]}
{"op":"mcm","clk":"11848509859","pt":1723658561834,"mc":[{"id":"1.231815703","rc":[{"batl":[[0,1.34,45],[1,1.35,3.97],[2,1.38,22]],"ltp":1.26,"tv":743.51,"id":12482925}]}]}
{"op":"mcm","clk":"11848511267","pt":1723658572156,"mc":[{"id":"1.231815703","rc":[{"batl":[[0,1.34,90.08]],"ltp":1.26,"tv":743.51,"id":12482925}]}]}
{"op":"mcm","clk":"11848512365","pt":1723658580166,"mc":[{"id":"1.231815703","rc":[{"batl":[[0,1.28,2.34],[1,1.34,90.08],[2,1.35,3.97]],"ltp":1.26,"tv":743.51,"id":12482925}]}]}
{"op":"mcm","clk":"11848514204","pt":1723658592568,"mc":[{"id":"1.231815703","rc":[{"batl":[[0,1.34,90.08],[1,1.35,3.97],[2,1.38,22]],"ltp":1.26,"tv":743.51,"id":12482925}]}]}
{"op":"mcm","clk":"11848519342","pt":1723658627609,"mc":[{"id":"1.231815703","rc":[{"batb":[[0,3.95,10],[1,3.9,14.16],[2,3.55,3.48]],"ltp":3.85,"tv":214.38,"id":12474498},{"batb":[[0,1.29,141.63],[1,1.26,4.65],[2,1.25,45.08]],"ltp":1.26,"tv":743.51,"id":12482925}]}]}
{"op":"mcm","clk":"11848519804","pt":1723658630928,"mc":[{"id":"1.231815703","rc":[{"batb":[[0,3.9,14.16],[1,3.55,3.48],[2,2.04,85.85]],"ltp":3.85,"tv":214.38,"id":12474498}]}]}
{"op":"mcm","clk":"11848520556","pt":1723658635923,"mc":[{"id":"1.231815703","rc":[{"trd":[[3.95,4.68]],"batb":[[0,3.95,1.66],[1,3.9,14.16],[2,3.55,3.48]],"ltp":3.95,"tv":219.06,"id":12474498}],"tv":962.58}]}
{"op":"mcm","clk":"11848520888","pt":1723658638318,"mc":[{"id":"1.231815703","rc":[{"batb":[[0,3.95,10]],"ltp":3.95,"tv":219.06,"id":12474498}]}]}
{"op":"mcm","clk":"11848521354","pt":1723658641737,"mc":[{"id":"1.231815703","rc":[{"batb":[[0,3.9,14.16],[1,3.55,3.48],[2,2.04,85.85]],"ltp":3.95,"tv":219.06,"id":12474498}]}]}
{"op":"mcm","clk":"11848524121","pt":1723658661988,"mc":[{"id":"1.231815703","rc":[{"trd":[[3.95,12.68]],"batl":[[0,3.95,3.02],[1,4.9,10]],"ltp":3.95,"tv":227.06,"id":12474498}],"tv":970.58}]}
{"op":"mcm","clk":"11848524193","pt":1723658662663,"mc":[{"id":"1.231815703","rc":[{"batl":[[0,1.34,45]],"ltp":1.26,"tv":743.51,"id":12482925}]}]}
{"op":"mcm","clk":"11848524347","pt":1723658663654,"mc":[{"id":"1.231815703","rc":[{"batb":[[2,1.24,42.93]],"ltp":1.26,"tv":743.51,"id":12482925}]}]}
{"op":"mcm","clk":"11848524686","pt":1723658666180,"mc":[{"id":"1.231815703","rc":[{"batb":[[0,3.95,10],[1,3.9,14.16],[2,3.55,3.48]],"batl":[[0,4.9,10],[1,4.9,0]],"ltp":3.95,"tv":227.06,"id":12474498}]}]}
{"op":"mcm","clk":"11848525215","pt":1723658669677,"mc":[{"id":"1.231815703","rc":[{"batb":[[0,3.9,14.16],[1,3.55,3.48],[2,2.04,85.85]],"ltp":3.95,"tv":227.06,"id":12474498},{"batl":[[0,1.33,45.08],[1,1.34,45],[2,1.35,3.97]],"ltp":1.26,"tv":743.51,"id":12482925}]}]}
{"op":"mcm","clk":"11848525763","pt":1723658673901,"mc":[{"id":"1.231815703","rc":[{"batb":[[0,3.95,10],[1,3.9,14.16],[2,3.55,3.48]],"ltp":3.95,"tv":227.06,"id":12474498},{"batl":[[0,1.34,45],[1,1.35,3.97],[2,1.38,22]],"ltp":1.26,"tv":743.51,"id":12482925}]}]}
{"op":"mcm","clk":"11848526098","pt":1723658676108,"mc":[{"id":"1.231815703","rc":[{"batb":[[0,1.3,45],[1,1.29,141.63],[2,1.26,4.65]],"ltp":1.26,"tv":743.51,"id":12482925}]}]}
{"op":"mcm","clk":"11848526242","pt":1723658677303,"mc":[{"id":"1.231815703","rc":[{"batb":[[0,3.9,14.16],[1,3.55,3.48],[2,2.04,85.85]],"ltp":3.95,"tv":227.06,"id":12474498}]}]}
{"op":"mcm","clk":"11848526720","pt":1723658680716,"mc":[{"id":"1.231815703","rc":[{"batb":[[0,3.95,4],[1,3.9,14.16],[2,3.55,3.48]],"batl":[[0,4,2.34],[1,4.9,10]],"ltp":3.95,"tv":227.06,"id":12474498}]}]}
{"op":"mcm","clk":"11848527039","pt":1723658683007,"mc":[{"id":"1.231815703","rc":[{"batb":[[0,3.9,14.16],[1,3.55,3.48],[2,2.04,85.85]],"ltp":3.95,"tv":227.06,"id":12474498}]}]}
{"op":"mcm","clk":"11848527703","pt":1723658687812,"mc":[{"id":"1.231815703","rc":[{"trd":[[4,1.33]],"batb":[[0,3.95,4],[1,3.9,14.16],[2,3.55,3.48]],"batl":[[0,4,1.01]],"ltp":4.0,"tv":228.39,"id":12474498},{"trd":[[1.33,4]],"ltp":1.33,"tv":747.51,"id":12482925}],"tv":975.91}]}
{"op":"mcm","clk":"11848528012","pt":1723658690098,"mc":[{"id":"1.231815703","rc":[{"batb":[[0,3.9,14.16],[1,3.55,3.48],[2,2.04,85.85]],"ltp":4.0,"tv":228.39,"id":12474498}]}]}
{"op":"mcm","clk":"11848528629","pt":1723658695001,"mc":[{"id":"1.231815703","rc":[{"batl":[[0,4.9,10],[1,4.9,0]],"ltp":4.0,"tv":228.39,"id":12474498}]}]}
{"op":"mcm","clk":"11848528638","pt":1723658695099,"mc":[{"id":"1.231815703","rc":[{"batb":[[0,3.95,10],[1,3.9,14.16],[2,3.55,3.48]],"ltp":4.0,"tv":228.39,"id":12474498}]}]}
{"op":"mcm","clk":"11848529093","pt":1723658698596,"mc":[{"id":"1.231815703","rc":[{"batb":[[0,3.9,14.16],[1,3.55,3.48],[2,2.04,85.85]],"ltp":4.0,"tv":228.39,"id":12474498}]}]}
{"op":"mcm","clk":"11848530440","pt":1723658708255,"mc":[{"id":"1.231815703","rc":[{"batb":[[0,3.95,10],[1,3.9,14.16],[2,3.55,3.48]],"ltp":4.0,"tv":228.39,"id":12474498},{"batb":[[0,1.3,49]],"ltp":1.33,"tv":747.51,"id":12482925}]}]}
{"op":"mcm","clk":"11848530888","pt":1723658711439,"mc":[{"id":"1.231815703","rc":[{"batb":[[0,3.9,14.16],[1,3.55,3.48],[2,2.04,85.85]],"ltp":4.0,"tv":228.39,"id":12474498}]}]}
{"op":"mcm","clk":"11848535688","pt":1723658744479,"mc":[{"id":"1.231815703","rc":[{"batb":[[0,3.95,10],[1,3.9,14.16],[2,3.55,3.48]],"ltp":4.0,"tv":228.39,"id":12474498},{"trd":[[1.3,49.88]],"batb":[[0,1.3,24.06]],"ltp":1.3,"tv":797.39,"id":12482925}],"tv":1025.78}]}
{"op":"mcm","clk":"11848536168","pt":1723658747777,"mc":[{"id":"1.231815703","rc":[{"batb":[[0,3.9,14.16],[1,3.55,3.48],[2,2.04,85.85]],"ltp":4.0,"tv":228.39,"id":12474498}]}]}
{"op":"mcm","clk":"11848552971","pt":1723658864826,"mc":[{"id":"1.231815703","rc":[{"batb":[[0,3.95,10],[1,3.9,14.16],[2,3.55,3.48]],"ltp":4.0,"tv":228.39,"id":12474498},{"batl":[[0,1.35,3.97],[1,1.38,22],[2,1.39,30]],"ltp":1.3,"tv":797.39,"id":12482925}]}]}
{"op":"mcm","clk":"11848553408","pt":1723658868200,"mc":[{"id":"1.231815703","rc":[{"batb":[[0,3.9,14.16],[1,3.55,3.48],[2,2.04,85.85]],"ltp":4.0,"tv":228.39,"id":12474498}]}]}
{"op":"mcm","clk":"11848555491","pt":1723658883616,"mc":[{"id":"1.231815703","rc":[{"batb":[[0,3.95,10],[1,3.9,14.16],[2,3.55,3.48]],"ltp":4.0,"tv":228.39,"id":12474498}]}]}
{"op":"mcm","clk":"11848555962","pt":1723658886910,"mc":[{"id":"1.231815703","rc":[{"batb":[[0,3.9,14.16],[1,3.55,3.48],[2,1.4,50]],"ltp":4.0,"tv":228.39,"id":12474498}]}]}
{"op":"mcm","clk":"11848563018","pt":1723658937384,"mc":[{"id":"1.231815703","rc":[{"batb":[[0,3.95,10],[1,3.9,14.16],[2,3.55,3.48]],"ltp":4.0,"tv":228.39,"id":12474498},{"batl":[[0,1.34,22.5],[1,1.35,3.97],[2,1.38,22]],"ltp":1.3,"tv":797.39,"id":12482925}]}]}
{"op":"mcm","clk":"11848563458","pt":1723658940585,"mc":[{"id":"1.231815703","rc":[{"batb":[[0,3.9,14.16],[1,3.55,3.48],[2,1.4,50]],"ltp":4.0,"tv":228.39,"id":12474498}]}]}
{"op":"mcm","clk":"11848585169","pt":1723659087973,"mc":[{"id":"1.231815703","rc":[{"batb":[[0,3.95,10],[1,3.9,14.16],[2,3.55,3.48]],"ltp":4.0,"tv":228.39,"id":12474498},{"batb":[[0,1.3,4]],"ltp":1.3,"tv":797.39,"id":12482925}]}]}
{"op":"mcm","clk":"11848585618","pt":1723659091320,"mc":[{"id":"1.231815703","rc":[{"batb":[[0,3.9,14.16],[1,3.55,3.48],[2,1.4,50]],"ltp":4.0,"tv":228.39,"id":12474498}]}]}
{"op":"mcm","clk":"11848594695","pt":1723659160460,"mc":[{"id":"1.231815703","rc":[{"batb":[[0,3.95,10],[1,3.9,14.16],[2,3.55,3.48]],"ltp":4.0,"tv":228.39,"id":12474498},{"batl":[[0,1.35,3.97],[1,1.38,22],[2,1.39,30]],"ltp":1.3,"tv":797.39,"id":12482925}]}]}
{"op":"mcm","clk":"11848595204","pt":1723659163989,"mc":[{"id":"1.231815703","rc":[{"batb":[[0,3.9,14.16],[1,3.55,3.48],[2,1.4,50]],"ltp":4.0,"tv":228.39,"id":12474498}]}]}
{"op":"mcm","clk":"11848619807","pt":1723659281640,"mc":[{"id":"1.231815703","rc":[{"trd":[[3.9,2.9]],"batb":[[0,3.95,10],[1,3.9,12.71],[2,3.55,3.48]],"ltp":3.9,"tv":231.29,"id":12474498},{"batb":[[0,1.29,141.63],[1,1.26,4.65],[2,1.2,1000]],"ltp":1.3,"tv":797.39,"id":12482925}],"tv":1028.68}]}
{"op":"mcm","clk":"11848620154","pt":1723659283717,"mc":[{"id":"1.231815703","rc":[{"batb":[[1,3.9,14.16]],"ltp":3.9,"tv":231.29,"id":12474498}]}]}
{"op":"mcm","clk":"11848620349","pt":1723659284917,"mc":[{"id":"1.231815703","rc":[{"batb":[[0,3.9,14.16],[1,3.55,3.48],[2,1.4,50]],"ltp":3.9,"tv":231.29,"id":12474498}]}]}
{"op":"mcm","clk":"11848635387","pt":1723659387472,"mc":[{"id":"1.231815703","rc":[{"batb":[[0,3.95,10],[1,3.9,14.16],[2,3.55,3.48]],"ltp":3.9,"tv":231.29,"id":12474498},{"batb":[[0,1.3,20.25],[1,1.29,141.63],[2,1.26,4.65]],"ltp":1.3,"tv":797.39,"id":12482925}]}]}
{"op":"mcm","clk":"11848635818","pt":1723659390661,"mc":[{"id":"1.231815703","rc":[{"batb":[[0,3.9,14.16],[1,3.55,3.48],[2,1.4,50]],"ltp":3.9,"tv":231.29,"id":12474498}]}]}
{"op":"mcm","clk":"11848639470","pt":1723659414875,"mc":[{"id":"1.231815703","rc":[{"trd":[[1.35,5.61]],"batl":[[0,1.35,2.97]],"ltp":1.35,"tv":799.39,"id":12482925}],"tv":1030.68}]}
{"op":"mcm","clk":"11848639500","pt":1723659415098,"mc":[{"id":"1.231815703","rc":[{"batb":[[0,3.95,10],[1,3.9,14.16],[2,3.55,3.48]],"ltp":3.9,"tv":231.29,"id":12474498}]}]}
{"op":"mcm","clk":"11848640048","pt":1723659418914,"mc":[{"id":"1.231815703","rc":[{"batb":[[0,3.9,14.16],[1,3.55,3.48],[2,1.4,50]],"ltp":3.9,"tv":231.29,"id":12474498}]}]}
{"op":"mcm","clk":"11848687978","pt":1723659763574,"mc":[{"id":"1.231815703","rc":[{"batb":[[0,3.95,10],[1,3.9,14.16],[2,3.55,3.48]],"ltp":3.9,"tv":231.29,"id":12474498}]}]}
{"op":"mcm","clk":"11848688420","pt":1723659766995,"mc":[{"id":"1.231815703","rc":[{"batb":[[0,3.9,14.16],[1,3.55,3.48],[2,1.4,50]],"ltp":3.9,"tv":231.29,"id":12474498}]}]}
{"op":"mcm","clk":"11848742074","pt":1723660201376,"mc":[{"id":"1.231815703","rc":[{"batb":[[0,3.95,10],[1,3.9,14.16],[2,3.55,3.48]],"ltp":3.9,"tv":231.29,"id":12474498}]}]}
{"op":"mcm","clk":"11848742615","pt":1723660204887,"mc":[{"id":"1.231815703","rc":[{"batb":[[0,3.9,14.16],[1,3.55,3.48],[2,1.4,50]],"ltp":3.9,"tv":231.29,"id":12474498}]}]}
{"op":"mcm","clk":"11848776939","pt":1723660492956,"mc":[{"id":"1.231815703","rc":[{"batb":[[0,3.95,10],[1,3.9,14.16]],"ltp":3.9,"tv":231.29,"id":12474498},{"batb":[[2,1.2,1000]],"ltp":1.35,"tv":799.39,"id":12482925}]}]}
{"op":"mcm","clk":"11848777338","pt":1723660495991,"mc":[{"id":"1.231815703","rc":[{"batb":[[0,3.9,14.16],[1,1.4,50],[2,1.3,66.67]],"ltp":3.9,"tv":231.29,"id":12474498}]}]}
{"op":"mcm","clk":"11848854903","pt":1723661091880,"mc":[{"id":"1.231815703","rc":[{"batb":[[0,3.95,10],[1,3.9,14.16],[2,1.4,50]],"ltp":3.9,"tv":231.29,"id":12474498}]}]}
{"op":"mcm","clk":"11848855350","pt":1723661095266,"mc":[{"id":"1.231815703","rc":[{"batb":[[0,3.9,14.16],[1,1.4,50],[2,1.3,66.67]],"ltp":3.9,"tv":231.29,"id":12474498}]}]}
{"op":"mcm","clk":"11848864567","pt":1723661165648,"mc":[{"id":"1.231815703","rc":[{"batb":[[0,3.95,10],[1,3.9,14.16],[2,1.4,50]],"ltp":3.9,"tv":231.29,"id":12474498}]}]}
{"op":"mcm","clk":"11848864993","pt":1723661169028,"mc":[{"id":"1.231815703","rc":[{"batb":[[0,3.9,14.16],[1,1.4,50],[2,1.3,66.67]],"ltp":3.9,"tv":231.29,"id":12474498}]}]}
{"op":"mcm","clk":"11848865377","pt":1723661171942,"mc":[{"id":"1.231815703","rc":[{"trd":[[3.9,5.33]],"ltp":3.9,"tv":233.72,"id":12474498},{"trd":[[1.35,18.58]],"batl":[[0,1.38,22],[1,1.39,30],[2,1.4,199.67]],"ltp":1.35,"tv":812.36,"id":12482925}],"tv":1046.08}]}
{"op":"mcm","clk":"11848865395","pt":1723661172040,"mc":[{"id":"1.231815703","rc":[{"batb":[[0,3.95,10],[1,3.9,14.16],[2,1.4,50]],"ltp":3.9,"tv":233.72,"id":12474498}]}]}
{"op":"mcm","clk":"11848865807","pt":1723661175347,"mc":[{"id":"1.231815703","rc":[{"batb":[[0,3.9,14.16],[1,1.4,50],[2,1.3,66.67]],"ltp":3.9,"tv":233.72,"id":12474498}]}]}
{"op":"mcm","clk":"11848867199","pt":1723661186869,"mc":[{"id":"1.231815703","rc":[{"batb":[[0,1.33,11],[1,1.3,20.25],[2,1.29,141.63]],"ltp":1.35,"tv":812.36,"id":12482925}]}]}
{"op":"mcm","clk":"11848867221","pt":1723661187076,"mc":[{"id":"1.231815703","rc":[{"batb":[[0,3.95,10],[1,3.9,14.16],[2,1.4,50]],"ltp":3.9,"tv":233.72,"id":12474498}]}]}
{"op":"mcm","clk":"11848867612","pt":1723661190370,"mc":[{"id":"1.231815703","rc":[{"batb":[[0,3.9,14.16],[1,1.4,50],[2,1.3,66.67]],"ltp":3.9,"tv":233.72,"id":12474498}]}]}
{"op":"mcm","clk":"11848880923","pt":1723661308138,"mc":[{"id":"1.231815703","rc":[{"batb":[[0,3.95,10],[1,3.9,14.16],[2,1.4,50]],"ltp":3.9,"tv":233.72,"id":12474498}]}]}
{"op":"mcm","clk":"11848881396","pt":1723661311561,"mc":[{"id":"1.231815703","rc":[{"batb":[[0,3.9,14.16],[1,1.4,50],[2,1.3,66.67]],"ltp":3.9,"tv":233.72,"id":12474498}]}]}
{"op":"mcm","clk":"11848883630","pt":1723661331807,"mc":[{"id":"1.231815703","rc":[{"batb":[[0,3.95,10],[1,3.9,14.16],[2,1.4,50]],"ltp":3.9,"tv":233.72,"id":12474498}]}]}
{"op":"mcm","clk":"11848883681","pt":1723661332275,"mc":[{"id":"1.231815703","rc":[{"batb":[[1,1.4,50],[2,1.3,66.67]],"ltp":3.9,"tv":233.72,"id":12474498},{"batb":[[2,1.2,1000]],"ltp":1.35,"tv":812.36,"id":12482925}]}]}
{"op":"mcm","clk":"11848883991","pt":1723661335199,"mc":[{"id":"1.231815703","rc":[{"batb":[[0,1.4,50],[1,1.3,66.67],[2,1.2,100]],"ltp":3.9,"tv":233.72,"id":12474498}]}]}
{"op":"mcm","clk":"11848884221","pt":1723661337395,"mc":[{"id":"1.231815703","rc":[{"batb":[[0,3.95,10],[1,3.9,14.16],[2,1.4,50]],"ltp":3.9,"tv":233.72,"id":12474498},{"batb":[[2,1.29,141.63]],"ltp":1.35,"tv":812.36,"id":12482925}]}]}
{"op":"mcm","clk":"11848884589","pt":1723661340693,"mc":[{"id":"1.231815703","rc":[{"batb":[[0,3.9,14.16],[1,1.4,50],[2,1.3,66.67]],"ltp":3.9,"tv":233.72,"id":12474498}]}]}
{"op":"mcm","clk":"11848890551","pt":1723661393078,"mc":[{"id":"1.231815703","rc":[{"batb":[[0,3.95,10],[1,3.9,14.16],[2,1.4,50]],"ltp":3.9,"tv":233.72,"id":12474498}]}]}
{"op":"mcm","clk":"11848890983","pt":1723661396578,"mc":[{"id":"1.231815703","rc":[{"batb":[[0,3.9,14.16],[1,1.4,50],[2,1.3,66.67]],"ltp":3.9,"tv":233.72,"id":12474498}]}]}
{"op":"mcm","clk":"11848895390","pt":1723661432000,"mc":[{"id":"1.231815703","rc":[{"batb":[[0,3.95,10],[1,3.9,14.16],[2,1.4,50]],"ltp":3.9,"tv":233.72,"id":12474498}]}]}
{"op":"mcm","clk":"11848895437","pt":1723661432422,"mc":[{"id":"1.231815703","rc":[{"batb":[[1,1.4,50],[2,1.3,66.67]],"ltp":3.9,"tv":233.72,"id":12474498},{"batb":[[2,1.2,1000]],"ltp":1.35,"tv":812.36,"id":12482925}]}]}
{"op":"mcm","clk":"11848895805","pt":1723661435413,"mc":[{"id":"1.231815703","rc":[{"batb":[[0,1.4,50],[1,1.3,66.67],[2,1.2,100]],"ltp":3.9,"tv":233.72,"id":12474498}]}]}
{"op":"mcm","clk":"11848896079","pt":1723661437588,"mc":[{"id":"1.231815703","rc":[{"batb":[[0,3.95,10],[1,3.9,14.16],[2,1.4,50]],"ltp":3.9,"tv":233.72,"id":12474498},{"batb":[[2,1.29,141.63]],"ltp":1.35,"tv":812.36,"id":12482925}]}]}
{"op":"mcm","clk":"11848896495","pt":1723661441038,"mc":[{"id":"1.231815703","rc":[{"batb":[[0,3.9,14.16],[1,1.4,50],[2,1.3,66.67]],"ltp":3.9,"tv":233.72,"id":12474498}]}]}
{"op":"mcm","clk":"11848897889","pt":1723661452429,"mc":[{"id":"1.231815703","rc":[{"batb":[[0,3.95,10],[1,3.9,14.16],[2,1.4,50]],"ltp":3.9,"tv":233.72,"id":12474498}]}]}
{"op":"mcm","clk":"11848898359","pt":1723661456119,"mc":[{"id":"1.231815703","rc":[{"batb":[[0,3.9,14.16],[1,1.4,50],[2,1.3,66.67]],"ltp":3.9,"tv":233.72,"id":12474498}]}]}
{"op":"mcm","clk":"11848898722","pt":1723661458924,"mc":[{"id":"1.231815703","rc":[{"batb":[[0,3.95,10],[1,3.9,14.16],[2,1.4,50]],"ltp":3.9,"tv":233.72,"id":12474498}]}]}
{"op":"mcm","clk":"11848899127","pt":1723661462210,"mc":[{"id":"1.231815703","rc":[{"batb":[[0,3.9,14.16],[1,1.4,50],[2,1.3,66.67]],"ltp":3.9,"tv":233.72,"id":12474498}]}]}
{"op":"mcm","clk":"11848899433","pt":1723661464939,"mc":[{"id":"1.231815703","rc":[{"batb":[[0,3.95,10],[1,3.9,14.16],[2,1.4,50]],"ltp":3.9,"tv":233.72,"id":12474498}]}]}
{"op":"mcm","clk":"11848899715","pt":1723661467535,"mc":[{"id":"1.231815703","rc":[{"batb":[[1,1.4,50],[2,1.3,66.67]],"ltp":3.9,"tv":233.72,"id":12474498},{"batb":[[2,1.2,1000]],"ltp":1.35,"tv":812.36,"id":12482925}]}]}
{"op":"mcm","clk":"11848899826","pt":1723661468371,"mc":[{"id":"1.231815703","rc":[{"batb":[[0,1.4,50],[1,1.3,66.67],[2,1.2,100]],"ltp":3.9,"tv":233.72,"id":12474498}]}]}
{"op":"mcm","clk":"11848900340","pt":1723661472550,"mc":[{"id":"1.231815703","rc":[{"batb":[[0,3.95,10],[1,3.9,14.16],[2,1.4,50]],"ltp":3.9,"tv":233.72,"id":12474498},{"batb":[[2,1.29,141.63]],"ltp":1.35,"tv":812.36,"id":12482925}]}]}
{"op":"mcm","clk":"11848900746","pt":1723661475837,"mc":[{"id":"1.231815703","rc":[{"batb":[[0,3.9,14.16],[1,1.4,50],[2,1.3,66.67]],"ltp":3.9,"tv":233.72,"id":12474498}]}]}
{"op":"mcm","clk":"11848904015","pt":1723661502881,"mc":[{"id":"1.231815703","rc":[{"batb":[[0,3.95,10],[1,3.9,14.16],[2,1.4,50]],"ltp":3.9,"tv":233.72,"id":12474498}]}]}
{"op":"mcm","clk":"11848904401","pt":1723661506212,"mc":[{"id":"1.231815703","rc":[{"batb":[[0,3.9,14.16],[1,1.4,50],[2,1.3,66.67]],"ltp":3.9,"tv":233.72,"id":12474498}]}]}
{"op":"mcm","clk":"11848904998","pt":1723661511825,"mc":[{"id":"1.231815703","rc":[{"batb":[[0,3.95,10],[1,3.9,14.16],[2,1.4,50]],"ltp":3.9,"tv":233.72,"id":12474498}]}]}
{"op":"mcm","clk":"11848905098","pt":1723661512606,"mc":[{"id":"1.231815703","rc":[{"batb":[[1,1.4,50],[2,1.3,66.67]],"ltp":3.9,"tv":233.72,"id":12474498},{"batb":[[2,1.2,1000]],"ltp":1.35,"tv":812.36,"id":12482925}]}]}
{"op":"mcm","clk":"11848905401","pt":1723661515321,"mc":[{"id":"1.231815703","rc":[{"batb":[[0,1.4,50],[1,1.3,66.67],[2,1.2,100]],"ltp":3.9,"tv":233.72,"id":12474498}]}]}
{"op":"mcm","clk":"11848905628","pt":1723661517595,"mc":[{"id":"1.231815703","rc":[{"batb":[[0,3.95,10],[1,3.9,14.16],[2,1.4,50]],"ltp":3.9,"tv":233.72,"id":12474498},{"batb":[[2,1.29,141.63]],"ltp":1.35,"tv":812.36,"id":12482925}]}]}
{"op":"mcm","clk":"11848906030","pt":1723661520831,"mc":[{"id":"1.231815703","rc":[{"batb":[[0,3.9,14.16],[1,1.4,50],[2,1.3,66.67]],"ltp":3.9,"tv":233.72,"id":12474498}]}]}
{"op":"mcm","clk":"11848909729","pt":1723661552900,"mc":[{"id":"1.231815703","rc":[{"batb":[[0,3.95,10],[1,3.9,14.16],[2,1.4,50]],"ltp":3.9,"tv":233.72,"id":12474498}]}]}
{"op":"mcm","clk":"11848910118","pt":1723661556275,"mc":[{"id":"1.231815703","rc":[{"batb":[[0,3.9,14.16],[1,1.4,50],[2,1.3,66.67]],"ltp":3.9,"tv":233.72,"id":12474498}]}]}
{"op":"mcm","clk":"11848988328","pt":1723662374266,"mc":[{"id":"1.231815703","rc":[{"trd":[[4.1,3.57]],"batb":[[0,3.95,10.05],[1,3.9,14.16],[2,1.4,50]],"ltp":4.1,"tv":237.29,"id":12474498},{"trd":[[1.3,49.87],[1.33,15]],"batb":[[0,1.3,20.25],[1,1.29,141.63],[2,1.2,1000]],"ltp":1.33,"tv":823.35,"id":12482925}],"tv":1060.64}]}
{"op":"mcm","clk":"11848988648","pt":1723662377471,"mc":[{"id":"1.231815703","rc":[{"batb":[[0,3.9,14.21],[1,1.4,50],[2,1.3,66.67]],"ltp":4.1,"tv":237.29,"id":12474498}]}]}
{"op":"mcm","clk":"11849046304","pt":1723662854245,"mc":[{"id":"1.231815703","rc":[{"batb":[[0,3.95,10.05],[1,3.9,14.16],[2,1.4,50]],"ltp":4.1,"tv":237.29,"id":12474498},{"batb":[[0,1.3,45.68]],"ltp":1.33,"tv":823.35,"id":12482925}]}]}
{"op":"mcm","clk":"11849046662","pt":1723662857435,"mc":[{"id":"1.231815703","rc":[{"batb":[[0,3.9,14.21],[1,1.4,50],[2,1.3,66.67]],"ltp":4.1,"tv":237.29,"id":12474498}]}]}
{"op":"mcm","clk":"11849136340","pt":1723663694241,"mc":[{"id":"1.231815703","rc":[{"batb":[[0,3.95,10.05],[1,3.9,14.16],[2,1.4,50]],"ltp":4.1,"tv":237.29,"id":12474498},{"batb":[[0,1.3,25.43]],"ltp":1.33,"tv":823.35,"id":12482925}]}]}
{"op":"mcm","clk":"11849136688","pt":1723663697442,"mc":[{"id":"1.231815703","rc":[{"batb":[[0,3.9,14.21],[1,1.4,50],[2,1.3,66.67]],"ltp":4.1,"tv":237.29,"id":12474498}]}]}
{"op":"mcm","clk":"11849173243","pt":1723664025951,"mc":[{"id":"1.231815703","rc":[{"batb":[[0,3.95,10.05],[1,3.9,14.16],[2,1.4,50]],"ltp":4.1,"tv":237.29,"id":12474498},{"batb":[[0,1.29,141.63],[1,1.2,1000],[2,1.16,1250]],"batl":[[0,1.3,19.65],[1,1.38,22],[2,1.39,30]],"ltp":1.33,"tv":823.35,"id":12482925}]}]}
{"op":"mcm","clk":"11849173640","pt":1723664029357,"mc":[{"id":"1.231815703","rc":[{"batb":[[0,3.9,14.21],[1,1.4,50],[2,1.3,66.67]],"ltp":4.1,"tv":237.29,"id":12474498}]}]}
{"op":"mcm","clk":"11849177760","pt":1723664068592,"mc":[{"id":"1.231815703","rc":[{"batb":[[0,3.95,10.05],[1,3.9,14.16],[2,1.4,50]],"ltp":4.1,"tv":237.29,"id":12474498},{"batb":[[1,1.22,9.02],[2,1.2,1000]],"ltp":1.33,"tv":823.35,"id":12482925}]}]}
{"op":"mcm","clk":"11849178077","pt":1723664071772,"mc":[{"id":"1.231815703","rc":[{"batb":[[0,3.9,14.21],[1,1.4,50],[2,1.3,66.67]],"ltp":4.1,"tv":237.29,"id":12474498}]}]}
{"op":"mcm","clk":"11849294118","pt":1723665258393,"mc":[{"id":"1.231815703","rc":[{"batb":[[0,3.95,10.05],[1,3.9,14.16],[2,1.4,50]],"ltp":4.1,"tv":237.29,"id":12474498},{"batb":[[0,1.3,25.35],[1,1.29,141.63],[2,1.22,9.02]],"batl":[[0,1.38,22],[1,1.39,30],[2,1.4,199.67]],"ltp":1.33,"tv":823.35,"id":12482925}]}]}
{"op":"mcm","clk":"11849294345","pt":1723665261807,"mc":[{"id":"1.231815703","rc":[{"batb":[[0,3.9,14.21],[1,1.4,50],[2,1.3,66.67]],"ltp":4.1,"tv":237.29,"id":12474498}]}]}
{"op":"mcm","clk":"11849296851","pt":1723665297526,"mc":[{"id":"1.231815703","rc":[{"batb":[[0,3.95,10.05],[1,3.9,14.16],[2,1.4,50]],"ltp":4.1,"tv":237.29,"id":12474498}]}]}
{"op":"mcm","clk":"11849297089","pt":1723665300984,"mc":[{"id":"1.231815703","rc":[{"batb":[[0,3.9,14.21],[1,1.4,50],[2,1.3,66.67]],"ltp":4.1,"tv":237.29,"id":12474498}]}]}
{"op":"mcm","clk":"11849340085","pt":1723665983253,"mc":[{"id":"1.231815703","rc":[{"trd":[[3.95,12.68]],"batb":[[0,3.95,10.05],[1,3.9,14.16],[2,1.4,50]],"ltp":4.1,"tv":237.29,"id":12474498},{"trd":[[1.26,6.24],[1.3,49.88]],"batl":[[0,1.36,225],[1,1.38,22],[2,1.39,30]],"ltp":1.33,"tv":823.36,"id":12482925}],"tv":1060.66}]}
{"op":"mcm","clk":"11849340253","pt":1723665986454,"mc":[{"id":"1.231815703","rc":[{"batb":[[0,3.9,14.21],[1,1.4,50],[2,1.3,66.67]],"ltp":4.1,"tv":237.29,"id":12474498}]}]}
{"op":"mcm","clk":"11849340661","pt":1723665993833,"mc":[{"id":"1.231815703","rc":[{"batb":[[0,3.95,10.05],[1,3.9,14.16],[2,1.4,50]],"ltp":4.1,"tv":237.29,"id":12474498},{"batl":[[1,1.37,225],[2,1.38,22]],"ltp":1.33,"tv":823.36,"id":12482925}]}]}
{"op":"mcm","clk":"11849340857","pt":1723665997350,"mc":[{"id":"1.231815703","rc":[{"batb":[[0,3.9,14.21],[1,1.4,50],[2,1.3,66.67]],"ltp":4.1,"tv":237.29,"id":12474498}]}]}
{"op":"mcm","clk":"11849341338","pt":1723666004958,"mc":[{"id":"1.231815703","rc":[{"batb":[[0,3.95,10.05],[1,3.9,14.16],[2,1.4,50]],"ltp":4.1,"tv":237.29,"id":12474498},{"batl":[[2,1.38,247]],"ltp":1.33,"tv":823.36,"id":12482925}]}]}
{"op":"mcm","clk":"11849341571","pt":1723666008360,"mc":[{"id":"1.231815703","rc":[{"batb":[[0,3.9,14.21],[1,1.4,50],[2,1.3,66.67]],"ltp":4.1,"tv":237.29,"id":12474498}]}]}
{"op":"mcm","clk":"11849342276","pt":1723666019699,"mc":[{"id":"1.231815703","rc":[{"batb":[[0,3.95,10.05],[1,3.9,14.16],[2,1.4,50]],"ltp":4.1,"tv":237.29,"id":12474498}]}]}
{"op":"mcm","clk":"11849342476","pt":1723666023096,"mc":[{"id":"1.231815703","rc":[{"batb":[[0,3.9,14.21],[1,1.4,50],[2,1.3,66.67]],"ltp":4.1,"tv":237.29,"id":12474498}]}]}
{"op":"mcm","clk":"11849343053","pt":1723666032206,"mc":[{"id":"1.231815703","rc":[{"batb":[[0,3.95,10.05],[1,3.9,14.16],[2,1.4,50]],"ltp":4.1,"tv":237.29,"id":12474498}]}]}
{"op":"mcm","clk":"11849343269","pt":1723666035716,"mc":[{"id":"1.231815703","rc":[{"batb":[[0,3.9,14.21],[1,1.4,50],[2,1.3,66.67]],"ltp":4.1,"tv":237.29,"id":12474498}]}]}
{"op":"mcm","clk":"11849344846","pt":1723666060931,"mc":[{"id":"1.231815703","rc":[{"batb":[[0,3.95,10.05],[1,3.9,14.16],[2,1.4,50]],"ltp":4.1,"tv":237.29,"id":12474498}]}]}
{"op":"mcm","clk":"11849345033","pt":1723666064235,"mc":[{"id":"1.231815703","rc":[{"batb":[[0,3.9,14.21],[1,1.4,50],[2,1.3,66.67]],"ltp":4.1,"tv":237.29,"id":12474498}]}]}
{"op":"mcm","clk":"11849357410","pt":1723666262024,"mc":[{"id":"1.231815703","rc":[{"batb":[[0,3.95,10.05],[1,3.9,14.16],[2,1.4,50]],"ltp":4.1,"tv":237.29,"id":12474498}]}]}
{"op":"mcm","clk":"11849357616","pt":1723666265431,"mc":[{"id":"1.231815703","rc":[{"batb":[[0,3.9,14.21],[1,1.4,50],[2,1.3,66.67]],"ltp":4.1,"tv":237.29,"id":12474498}]}]}
{"op":"mcm","clk":"11849358013","pt":1723666272446,"mc":[{"id":"1.231815703","rc":[{"batb":[[0,3.95,10.05],[1,3.9,14.16],[2,1.4,50]],"ltp":4.1,"tv":237.29,"id":12474498}]}]}
{"op":"mcm","clk":"11849358196","pt":1723666275739,"mc":[{"id":"1.231815703","rc":[{"batb":[[0,3.9,14.21],[1,1.4,50],[2,1.3,66.67]],"ltp":4.1,"tv":237.29,"id":12474498}]}]}
{"op":"mcm","clk":"11849358338","pt":1723666278366,"mc":[{"id":"1.231815703","rc":[{"batb":[[0,3.95,10.05],[1,3.9,14.16],[2,1.4,50]],"ltp":4.1,"tv":237.29,"id":12474498}]}]}
{"op":"mcm","clk":"11849358507","pt":1723666281564,"mc":[{"id":"1.231815703","rc":[{"batb":[[0,3.9,14.21],[1,1.4,50],[2,1.3,66.67]],"ltp":4.1,"tv":237.29,"id":12474498}]}]}
{"op":"mcm","clk":"11849358627","pt":1723666283852,"mc":[{"id":"1.231815703","rc":[{"batb":[[0,3.95,10.05],[1,3.9,14.16],[2,1.4,50]],"ltp":4.1,"tv":237.29,"id":12474498}]}]}
{"op":"mcm","clk":"11849358797","pt":1723666287371,"mc":[{"id":"1.231815703","rc":[{"batb":[[0,3.9,14.21],[1,1.4,50],[2,1.3,66.67]],"ltp":4.1,"tv":237.29,"id":12474498}]}]}
{"op":"mcm","clk":"11849358987","pt":1723666290564,"mc":[{"id":"1.231815703","rc":[{"batb":[[0,3.95,10.05],[1,3.9,14.16],[2,1.4,50]],"ltp":4.1,"tv":237.29,"id":12474498}]}]}
{"op":"mcm","clk":"11849359159","pt":1723666293872,"mc":[{"id":"1.231815703","rc":[{"batb":[[0,3.9,14.21],[1,1.4,50],[2,1.3,66.67]],"ltp":4.1,"tv":237.29,"id":12474498}]}]}
{"op":"mcm","clk":"11849359380","pt":1723666296966,"mc":[{"id":"1.231815703","rc":[{"batb":[[0,3.95,10.05],[1,3.9,14.16],[2,1.4,50]],"ltp":4.1,"tv":237.29,"id":12474498}]}]}
{"op":"mcm","clk":"11849359550","pt":1723666300268,"mc":[{"id":"1.231815703","rc":[{"batb":[[0,3.9,14.21],[1,1.4,50],[2,1.3,66.67]],"ltp":4.1,"tv":237.29,"id":12474498}]}]}
{"op":"mcm","clk":"11849359669","pt":1723666302581,"mc":[{"id":"1.231815703","rc":[{"batb":[[0,3.95,10.05],[1,3.9,14.16],[2,1.4,50]],"ltp":4.1,"tv":237.29,"id":12474498}]}]}
{"op":"mcm","clk":"11849359831","pt":1723666306084,"mc":[{"id":"1.231815703","rc":[{"batb":[[0,3.9,14.21],[1,1.4,50],[2,1.3,66.67]],"ltp":4.1,"tv":237.29,"id":12474498}]}]}
{"op":"mcm","clk":"11849360013","pt":1723666309386,"mc":[{"id":"1.231815703","rc":[{"batb":[[0,3.95,10.05],[1,3.9,14.16],[2,1.4,50]],"ltp":4.1,"tv":237.29,"id":12474498}]}]}
{"op":"mcm","clk":"11849360217","pt":1723666312780,"mc":[{"id":"1.231815703","rc":[{"batb":[[0,3.9,14.21],[1,1.4,50],[2,1.3,66.67]],"ltp":4.1,"tv":237.29,"id":12474498}]}]}
{"op":"mcm","clk":"11849360344","pt":1723666314985,"mc":[{"id":"1.231815703","rc":[{"batb":[[0,3.95,10.05],[1,3.9,14.16],[2,1.4,50]],"ltp":4.1,"tv":237.29,"id":12474498}]}]}
{"op":"mcm","clk":"11849360558","pt":1723666318493,"mc":[{"id":"1.231815703","rc":[{"batb":[[0,3.9,14.21],[1,1.4,50],[2,1.3,66.67]],"ltp":4.1,"tv":237.29,"id":12474498}]}]}
{"op":"mcm","clk":"11849360689","pt":1723666320808,"mc":[{"id":"1.231815703","rc":[{"batb":[[0,3.95,10.05],[1,3.9,14.16],[2,1.4,50]],"ltp":4.1,"tv":237.29,"id":12474498}]}]}
{"op":"mcm","clk":"11849360899","pt":1723666324371,"mc":[{"id":"1.231815703","rc":[{"batb":[[0,3.9,14.21],[1,1.4,50],[2,1.3,66.67]],"ltp":4.1,"tv":237.29,"id":12474498}]}]}
{"op":"mcm","clk":"11849361029","pt":1723666326701,"mc":[{"id":"1.231815703","rc":[{"batb":[[0,3.95,10.05],[1,3.9,14.16],[2,1.4,50]],"ltp":4.1,"tv":237.29,"id":12474498}]}]}
{"op":"mcm","clk":"11849361250","pt":1723666329993,"mc":[{"id":"1.231815703","rc":[{"batb":[[0,3.9,14.21],[1,1.4,50],[2,1.3,66.67]],"ltp":4.1,"tv":237.29,"id":12474498}]}]}
{"op":"mcm","clk":"11849361377","pt":1723666332308,"mc":[{"id":"1.231815703","rc":[{"batb":[[0,3.95,10.05],[1,3.9,14.16],[2,1.4,50]],"ltp":4.1,"tv":237.29,"id":12474498}]}]}
{"op":"mcm","clk":"11849361614","pt":1723666335719,"mc":[{"id":"1.231815703","rc":[{"batb":[[0,3.9,14.21],[1,1.4,50],[2,1.3,66.67]],"ltp":4.1,"tv":237.29,"id":12474498}]}]}
{"op":"mcm","clk":"11849361758","pt":1723666337993,"mc":[{"id":"1.231815703","rc":[{"batb":[[0,3.95,10.05],[1,3.9,14.16],[2,1.4,50]],"ltp":4.1,"tv":237.29,"id":12474498}]}]}
{"op":"mcm","clk":"11849361991","pt":1723666341412,"mc":[{"id":"1.231815703","rc":[{"batb":[[0,3.9,14.21],[1,1.4,50],[2,1.3,66.67]],"ltp":4.1,"tv":237.29,"id":12474498}]}]}
{"op":"mcm","clk":"11849362101","pt":1723666343627,"mc":[{"id":"1.231815703","rc":[{"batb":[[0,3.95,10.05],[1,3.9,14.16],[2,1.4,50]],"ltp":4.1,"tv":237.29,"id":12474498}]}]}
{"op":"mcm","clk":"11849362295","pt":1723666347005,"mc":[{"id":"1.231815703","rc":[{"batb":[[0,3.9,14.21],[1,1.4,50],[2,1.3,66.67]],"ltp":4.1,"tv":237.29,"id":12474498}]}]}
{"op":"mcm","clk":"11849362468","pt":1723666350330,"mc":[{"id":"1.231815703","rc":[{"batb":[[0,3.95,10.05],[1,3.9,14.16],[2,1.4,50]],"ltp":4.1,"tv":237.29,"id":12474498}]}]}
{"op":"mcm","clk":"11849362687","pt":1723666353320,"mc":[{"id":"1.231815703","rc":[{"batb":[[0,3.9,14.21],[1,1.4,50],[2,1.3,66.67]],"ltp":4.1,"tv":237.29,"id":12474498}]}]}
{"op":"mcm","clk":"11849362815","pt":1723666355640,"mc":[{"id":"1.231815703","rc":[{"batb":[[0,3.95,10.05],[1,3.9,14.16],[2,1.4,50]],"ltp":4.1,"tv":237.29,"id":12474498}]}]}
{"op":"mcm","clk":"11849363027","pt":1723666358947,"mc":[{"id":"1.231815703","rc":[{"batb":[[0,3.9,14.21],[1,1.4,50],[2,1.3,66.67]],"ltp":4.1,"tv":237.29,"id":12474498}]}]}
{"op":"mcm","clk":"11849363178","pt":1723666361439,"mc":[{"id":"1.231815703","rc":[{"batb":[[0,3.95,10.05],[1,3.9,14.16],[2,1.4,50]],"ltp":4.1,"tv":237.29,"id":12474498}]}]}
{"op":"mcm","clk":"11849363340","pt":1723666364634,"mc":[{"id":"1.231815703","rc":[{"batb":[[0,3.9,14.21],[1,1.4,50],[2,1.3,66.67]],"ltp":4.1,"tv":237.29,"id":12474498}]}]}
{"op":"mcm","clk":"11849363459","pt":1723666367048,"mc":[{"id":"1.231815703","rc":[{"batb":[[0,3.95,10.05],[1,3.9,14.16],[2,1.4,50]],"ltp":4.1,"tv":237.29,"id":12474498}]}]}
{"op":"mcm","clk":"11849363679","pt":1723666370356,"mc":[{"id":"1.231815703","rc":[{"batb":[[0,3.9,14.21],[1,1.4,50],[2,1.3,66.67]],"ltp":4.1,"tv":237.29,"id":12474498}]}]}
{"op":"mcm","clk":"11849363785","pt":1723666372636,"mc":[{"id":"1.231815703","rc":[{"batb":[[0,3.95,10.05],[1,3.9,14.16],[2,1.4,50]],"ltp":4.1,"tv":237.29,"id":12474498}]}]}
{"op":"mcm","clk":"11849363957","pt":1723666375944,"mc":[{"id":"1.231815703","rc":[{"batb":[[0,3.9,14.21],[1,1.4,50],[2,1.3,66.67]],"ltp":4.1,"tv":237.29,"id":12474498}]}]}
{"op":"mcm","clk":"11849364091","pt":1723666378258,"mc":[{"id":"1.231815703","rc":[{"batb":[[0,3.95,10.05],[1,3.9,14.16],[2,1.4,50]],"ltp":4.1,"tv":237.29,"id":12474498}]}]}
{"op":"mcm","clk":"11849364294","pt":1723666381770,"mc":[{"id":"1.231815703","rc":[{"batb":[[0,3.9,14.21],[1,1.4,50],[2,1.3,66.67]],"ltp":4.1,"tv":237.29,"id":12474498}]}]}
{"op":"mcm","clk":"11849364431","pt":1723666384047,"mc":[{"id":"1.231815703","rc":[{"batb":[[0,3.95,10.05],[1,3.9,14.16],[2,1.4,50]],"ltp":4.1,"tv":237.29,"id":12474498}]}]}
{"op":"mcm","clk":"11849364624","pt":1723666387450,"mc":[{"id":"1.231815703","rc":[{"batb":[[0,3.9,14.21],[1,1.4,50],[2,1.3,66.67]],"ltp":4.1,"tv":237.29,"id":12474498}]}]}
{"op":"mcm","clk":"11849364751","pt":1723666389781,"mc":[{"id":"1.231815703","rc":[{"batb":[[0,3.95,10.05],[1,3.9,14.16],[2,1.4,50]],"ltp":4.1,"tv":237.29,"id":12474498}]}]}
{"op":"mcm","clk":"11849364894","pt":1723666393079,"mc":[{"id":"1.231815703","rc":[{"batb":[[0,3.9,14.21],[1,1.4,50],[2,1.3,66.67]],"ltp":4.1,"tv":237.29,"id":12474498}]}]}
{"op":"mcm","clk":"11849365029","pt":1723666395558,"mc":[{"id":"1.231815703","rc":[{"batb":[[0,3.95,10.05],[1,3.9,14.16],[2,1.4,50]],"ltp":4.1,"tv":237.29,"id":12474498}]}]}
{"op":"mcm","clk":"11849365234","pt":1723666398968,"mc":[{"id":"1.231815703","rc":[{"batb":[[0,3.9,14.21],[1,1.4,50],[2,1.3,66.67]],"ltp":4.1,"tv":237.29,"id":12474498}]}]}
{"op":"mcm","clk":"11849365345","pt":1723666401384,"mc":[{"id":"1.231815703","rc":[{"batb":[[0,3.95,10.05],[1,3.9,14.16],[2,1.4,50]],"ltp":4.1,"tv":237.29,"id":12474498}]}]}
{"op":"mcm","clk":"11849365574","pt":1723666405367,"mc":[{"id":"1.231815703","rc":[{"batb":[[0,3.9,14.21],[1,1.4,50],[2,1.3,66.67]],"ltp":4.1,"tv":237.29,"id":12474498}]}]}
{"op":"mcm","clk":"11849365729","pt":1723666407693,"mc":[{"id":"1.231815703","rc":[{"batb":[[0,3.95,10.05],[1,3.9,14.16],[2,1.4,50]],"ltp":4.1,"tv":237.29,"id":12474498}]}]}
{"op":"mcm","clk":"11849365955","pt":1723666411099,"mc":[{"id":"1.231815703","rc":[{"batb":[[0,3.9,14.21],[1,1.4,50],[2,1.3,66.67]],"ltp":4.1,"tv":237.29,"id":12474498}]}]}
{"op":"mcm","clk":"11849366150","pt":1723666413175,"mc":[{"id":"1.231815703","rc":[{"batb":[[0,3.95,10.05],[1,3.9,14.16],[2,1.4,50]],"ltp":4.1,"tv":237.29,"id":12474498}]}]}
{"op":"mcm","clk":"11849366378","pt":1723666416689,"mc":[{"id":"1.231815703","rc":[{"batb":[[0,3.9,14.21],[1,1.4,50],[2,1.3,66.67]],"ltp":4.1,"tv":237.29,"id":12474498}]}]}
{"op":"mcm","clk":"11849366624","pt":1723666420186,"mc":[{"id":"1.231815703","rc":[{"batb":[[0,3.95,10.05],[1,3.9,14.16],[2,1.4,50]],"ltp":4.1,"tv":237.29,"id":12474498}]}]}
{"op":"mcm","clk":"11849366872","pt":1723666423593,"mc":[{"id":"1.231815703","rc":[{"batb":[[0,3.9,14.21],[1,1.4,50],[2,1.3,66.67]],"ltp":4.1,"tv":237.29,"id":12474498}]}]}
{"op":"mcm","clk":"11849367029","pt":1723666425924,"mc":[{"id":"1.231815703","rc":[{"batb":[[0,3.95,10.05],[1,3.9,14.16],[2,1.4,50]],"ltp":4.1,"tv":237.29,"id":12474498}]}]}
{"op":"mcm","clk":"11849367249","pt":1723666429314,"mc":[{"id":"1.231815703","rc":[{"batb":[[0,3.9,14.21],[1,1.4,50],[2,1.3,66.67]],"ltp":4.1,"tv":237.29,"id":12474498}]}]}
{"op":"mcm","clk":"11849367402","pt":1723666431811,"mc":[{"id":"1.231815703","rc":[{"batb":[[0,3.95,10.05],[1,3.9,14.16],[2,1.4,50]],"ltp":4.1,"tv":237.29,"id":12474498}]}]}
{"op":"mcm","clk":"11849367625","pt":1723666435330,"mc":[{"id":"1.231815703","rc":[{"batb":[[0,3.9,14.21],[1,1.4,50],[2,1.3,66.67]],"ltp":4.1,"tv":237.29,"id":12474498}]}]}
{"op":"mcm","clk":"11849367787","pt":1723666437619,"mc":[{"id":"1.231815703","rc":[{"batb":[[0,3.95,10.05],[1,3.9,14.16],[2,1.4,50]],"ltp":4.1,"tv":237.29,"id":12474498}]}]}
{"op":"mcm","clk":"11849368018","pt":1723666440935,"mc":[{"id":"1.231815703","rc":[{"batb":[[0,3.9,14.21],[1,1.4,50],[2,1.3,66.67]],"ltp":4.1,"tv":237.29,"id":12474498}]}]}
{"op":"mcm","clk":"11849368206","pt":1723666443434,"mc":[{"id":"1.231815703","rc":[{"batb":[[0,3.95,10.05],[1,3.9,14.16],[2,1.4,50]],"ltp":4.1,"tv":237.29,"id":12474498}]}]}
{"op":"mcm","clk":"11849368415","pt":1723666446638,"mc":[{"id":"1.231815703","rc":[{"batb":[[0,3.9,14.21],[1,1.4,50],[2,1.3,66.67]],"ltp":4.1,"tv":237.29,"id":12474498}]}]}
{"op":"mcm","clk":"11849368566","pt":1723666449117,"mc":[{"id":"1.231815703","rc":[{"batb":[[0,3.95,10.05],[1,3.9,14.16],[2,1.4,50]],"ltp":4.1,"tv":237.29,"id":12474498}]}]}
{"op":"mcm","clk":"11849368785","pt":1723666452526,"mc":[{"id":"1.231815703","rc":[{"batb":[[0,3.9,14.21],[1,1.4,50],[2,1.3,66.67]],"ltp":4.1,"tv":237.29,"id":12474498}]}]}
{"op":"mcm","clk":"11849368980","pt":1723666455969,"mc":[{"id":"1.231815703","rc":[{"batb":[[0,3.95,10.05],[1,3.9,14.16],[2,1.4,50]],"ltp":4.1,"tv":237.29,"id":12474498}]}]}
{"op":"mcm","clk":"11849369182","pt":1723666459378,"mc":[{"id":"1.231815703","rc":[{"batb":[[0,3.9,14.21],[1,1.4,50],[2,1.3,66.67]],"ltp":4.1,"tv":237.29,"id":12474498}]}]}
{"op":"mcm","clk":"11849369600","pt":1723666465574,"mc":[{"id":"1.231815703","rc":[{"batb":[[0,3.95,10.05],[1,3.9,14.16],[2,1.4,50]],"ltp":4.1,"tv":237.29,"id":12474498}]}]}
{"op":"mcm","clk":"11849369826","pt":1723666468875,"mc":[{"id":"1.231815703","rc":[{"batb":[[0,3.9,14.21],[1,1.4,50],[2,1.3,66.67]],"ltp":4.1,"tv":237.29,"id":12474498}]}]}
{"op":"mcm","clk":"11849369962","pt":1723666471157,"mc":[{"id":"1.231815703","rc":[{"batb":[[0,3.95,10.05],[1,3.9,14.16],[2,1.4,50]],"ltp":4.1,"tv":237.29,"id":12474498}]}]}
{"op":"mcm","clk":"11849370171","pt":1723666474565,"mc":[{"id":"1.231815703","rc":[{"batb":[[0,3.9,14.21],[1,1.4,50],[2,1.3,66.67]],"ltp":4.1,"tv":237.29,"id":12474498}]}]}
{"op":"mcm","clk":"11849370383","pt":1723666477687,"mc":[{"id":"1.231815703","rc":[{"batb":[[0,3.95,10.05],[1,3.9,14.16],[2,1.4,50]],"ltp":4.1,"tv":237.29,"id":12474498}]}]}
{"op":"mcm","clk":"11849370624","pt":1723666481090,"mc":[{"id":"1.231815703","rc":[{"batb":[[0,3.9,14.21],[1,1.4,50],[2,1.3,66.67]],"ltp":4.1,"tv":237.29,"id":12474498}]}]}
{"op":"mcm","clk":"11849370767","pt":1723666483364,"mc":[{"id":"1.231815703","rc":[{"batb":[[0,3.95,10.05],[1,3.9,14.16],[2,1.4,50]],"ltp":4.1,"tv":237.29,"id":12474498}]}]}
{"op":"mcm","clk":"11849371014","pt":1723666486666,"mc":[{"id":"1.231815703","rc":[{"batb":[[0,3.9,14.21],[1,1.4,50],[2,1.3,66.67]],"ltp":4.1,"tv":237.29,"id":12474498}]}]}
{"op":"mcm","clk":"11849371243","pt":1723666490486,"mc":[{"id":"1.231815703","rc":[{"batb":[[0,3.95,10.05],[1,3.9,14.16],[2,1.4,50]],"ltp":4.1,"tv":237.29,"id":12474498}]}]}
{"op":"mcm","clk":"11849371466","pt":1723666493790,"mc":[{"id":"1.231815703","rc":[{"batb":[[0,3.9,14.21],[1,1.4,50],[2,1.3,66.67]],"ltp":4.1,"tv":237.29,"id":12474498}]}]}
{"op":"mcm","clk":"11849371628","pt":1723666496180,"mc":[{"id":"1.231815703","rc":[{"batb":[[0,3.95,10.05],[1,3.9,14.16],[2,1.4,50]],"ltp":4.1,"tv":237.29,"id":12474498}]}]}
{"op":"mcm","clk":"11849371826","pt":1723666499590,"mc":[{"id":"1.231815703","rc":[{"batb":[[0,3.9,14.21],[1,1.4,50],[2,1.3,66.67]],"ltp":4.1,"tv":237.29,"id":12474498}]}]}
{"op":"mcm","clk":"11849372078","pt":1723666503014,"mc":[{"id":"1.231815703","rc":[{"batb":[[0,3.95,10.05],[1,3.9,14.16],[2,1.4,50]],"ltp":4.1,"tv":237.29,"id":12474498}]}]}
{"op":"mcm","clk":"11849372340","pt":1723666506329,"mc":[{"id":"1.231815703","rc":[{"batb":[[0,3.9,14.21],[1,1.4,50],[2,1.3,66.67]],"ltp":4.1,"tv":237.29,"id":12474498}]}]}
{"op":"mcm","clk":"11849372519","pt":1723666508818,"mc":[{"id":"1.231815703","rc":[{"batb":[[0,3.95,10.05],[1,3.9,14.16],[2,1.4,50]],"ltp":4.1,"tv":237.29,"id":12474498}]}]}
{"op":"mcm","clk":"11849372744","pt":1723666512127,"mc":[{"id":"1.231815703","rc":[{"batb":[[0,3.9,14.21],[1,1.4,50],[2,1.3,66.67]],"ltp":4.1,"tv":237.29,"id":12474498}]}]}
{"op":"mcm","clk":"11849373011","pt":1723666515631,"mc":[{"id":"1.231815703","rc":[{"batb":[[0,3.95,10.05],[1,3.9,14.16],[2,1.4,50]],"ltp":4.1,"tv":237.29,"id":12474498}]}]}
{"op":"mcm","clk":"11849373226","pt":1723666518839,"mc":[{"id":"1.231815703","rc":[{"batb":[[0,3.9,14.21],[1,1.4,50],[2,1.3,66.67]],"ltp":4.1,"tv":237.29,"id":12474498}]}]}
{"op":"mcm","clk":"11849373408","pt":1723666521429,"mc":[{"id":"1.231815703","rc":[{"batb":[[0,3.95,10.05],[1,3.9,14.16],[2,1.4,50]],"ltp":4.1,"tv":237.29,"id":12474498}]}]}
{"op":"mcm","clk":"11849373627","pt":1723666524731,"mc":[{"id":"1.231815703","rc":[{"batb":[[0,3.9,14.21],[1,1.4,50],[2,1.3,66.67]],"ltp":4.1,"tv":237.29,"id":12474498}]}]}
{"op":"mcm","clk":"11849373764","pt":1723666527012,"mc":[{"id":"1.231815703","rc":[{"batb":[[0,3.95,10.05],[1,3.9,14.16],[2,1.4,50]],"ltp":4.1,"tv":237.29,"id":12474498}]}]}
{"op":"mcm","clk":"11849373979","pt":1723666530258,"mc":[{"id":"1.231815703","rc":[{"batb":[[0,3.9,14.21],[1,1.4,50],[2,1.3,66.67]],"ltp":4.1,"tv":237.29,"id":12474498}]}]}
{"op":"mcm","clk":"11849374122","pt":1723666532630,"mc":[{"id":"1.231815703","rc":[{"batb":[[0,3.95,10.05],[1,3.9,14.16],[2,1.4,50]],"ltp":4.1,"tv":237.29,"id":12474498}]}]}
{"op":"mcm","clk":"11849374333","pt":1723666536052,"mc":[{"id":"1.231815703","rc":[{"batb":[[0,3.9,14.21],[1,1.4,50],[2,1.3,66.67]],"ltp":4.1,"tv":237.29,"id":12474498}]}]}
{"op":"mcm","clk":"11849374459","pt":1723666538471,"mc":[{"id":"1.231815703","rc":[{"batb":[[0,3.95,10.05],[1,3.9,14.16],[2,1.4,50]],"ltp":4.1,"tv":237.29,"id":12474498}]}]}
{"op":"mcm","clk":"11849374672","pt":1723666541726,"mc":[{"id":"1.231815703","rc":[{"batb":[[0,3.9,14.21],[1,1.4,50],[2,1.3,66.67]],"ltp":4.1,"tv":237.29,"id":12474498}]}]}
{"op":"mcm","clk":"11849374895","pt":1723666545366,"mc":[{"id":"1.231815703","rc":[{"batb":[[0,3.95,10.05],[1,3.9,14.16],[2,1.4,50]],"ltp":4.1,"tv":237.29,"id":12474498}]}]}
{"op":"mcm","clk":"11849375130","pt":1723666548762,"mc":[{"id":"1.231815703","rc":[{"batb":[[0,3.9,14.21],[1,1.4,50],[2,1.3,66.67]],"ltp":4.1,"tv":237.29,"id":12474498}]}]}
{"op":"mcm","clk":"11849375293","pt":1723666551057,"mc":[{"id":"1.231815703","rc":[{"batb":[[0,3.95,10.05],[1,3.9,14.16],[2,1.4,50]],"ltp":4.1,"tv":237.29,"id":12474498}]}]}
{"op":"mcm","clk":"11849375539","pt":1723666554482,"mc":[{"id":"1.231815703","rc":[{"batb":[[0,3.9,14.21],[1,1.4,50],[2,1.3,66.67]],"ltp":4.1,"tv":237.29,"id":12474498}]}]}
{"op":"mcm","clk":"11849375655","pt":1723666556753,"mc":[{"id":"1.231815703","rc":[{"batb":[[0,3.95,10.05],[1,3.9,14.16],[2,1.4,50]],"ltp":4.1,"tv":237.29,"id":12474498}]}]}
{"op":"mcm","clk":"11849375825","pt":1723666559972,"mc":[{"id":"1.231815703","rc":[{"batb":[[0,3.9,14.21],[1,1.4,50],[2,1.3,66.67]],"ltp":4.1,"tv":237.29,"id":12474498}]}]}
{"op":"mcm","clk":"11849376066","pt":1723666563441,"mc":[{"id":"1.231815703","rc":[{"batb":[[0,3.95,10.05],[1,3.9,14.16],[2,1.4,50]],"ltp":4.1,"tv":237.29,"id":12474498}]}]}
{"op":"mcm","clk":"11849376279","pt":1723666566915,"mc":[{"id":"1.231815703","rc":[{"batb":[[0,3.9,14.21],[1,1.4,50],[2,1.3,66.67]],"ltp":4.1,"tv":237.29,"id":12474498}]}]}
{"op":"mcm","clk":"11849376459","pt":1723666569980,"mc":[{"id":"1.231815703","rc":[{"batb":[[0,3.95,10.05],[1,3.9,14.16],[2,1.4,50]],"ltp":4.1,"tv":237.29,"id":12474498}]}]}
{"op":"mcm","clk":"11849376682","pt":1723666573282,"mc":[{"id":"1.231815703","rc":[{"batb":[[0,3.9,14.21],[1,1.4,50],[2,1.3,66.67]],"ltp":4.1,"tv":237.29,"id":12474498}]}]}
{"op":"mcm","clk":"11849376854","pt":1723666575564,"mc":[{"id":"1.231815703","rc":[{"batb":[[0,3.95,10.05],[1,3.9,14.16],[2,1.4,50]],"ltp":4.1,"tv":237.29,"id":12474498}]}]}
{"op":"mcm","clk":"11849377068","pt":1723666579084,"mc":[{"id":"1.231815703","rc":[{"batb":[[0,3.9,14.21],[1,1.4,50],[2,1.3,66.67]],"ltp":4.1,"tv":237.29,"id":12474498}]}]}
{"op":"mcm","clk":"11849377227","pt":1723666581394,"mc":[{"id":"1.231815703","rc":[{"batb":[[0,3.95,10.05],[1,3.9,14.16],[2,1.4,50]],"ltp":4.1,"tv":237.29,"id":12474498}]}]}
{"op":"mcm","clk":"11849377415","pt":1723666584694,"mc":[{"id":"1.231815703","rc":[{"batb":[[0,3.9,14.21],[1,1.4,50],[2,1.3,66.67]],"ltp":4.1,"tv":237.29,"id":12474498}]}]}
{"op":"mcm","clk":"11849377580","pt":1723666587277,"mc":[{"id":"1.231815703","rc":[{"batb":[[0,3.95,10.05],[1,3.9,14.16],[2,1.4,50]],"ltp":4.1,"tv":237.29,"id":12474498}]}]}
{"op":"mcm","clk":"11849377774","pt":1723666590691,"mc":[{"id":"1.231815703","rc":[{"batb":[[0,3.9,14.21],[1,1.4,50],[2,1.3,66.67]],"ltp":4.1,"tv":237.29,"id":12474498}]}]}
{"op":"mcm","clk":"11849377894","pt":1723666592997,"mc":[{"id":"1.231815703","rc":[{"batb":[[0,3.95,10.05],[1,3.9,14.16],[2,1.4,50]],"ltp":4.1,"tv":237.29,"id":12474498}]}]}
{"op":"mcm","clk":"11849378125","pt":1723666596498,"mc":[{"id":"1.231815703","rc":[{"batb":[[0,3.9,14.21],[1,1.4,50],[2,1.3,66.67]],"ltp":4.1,"tv":237.29,"id":12474498}]}]}
{"op":"mcm","clk":"11849378337","pt":1723666599217,"mc":[{"id":"1.231815703","rc":[{"batb":[[0,3.95,10.05],[1,3.9,14.16],[2,1.4,50]],"ltp":4.1,"tv":237.29,"id":12474498}]}]}
{"op":"mcm","clk":"11849378555","pt":1723666602522,"mc":[{"id":"1.231815703","rc":[{"batb":[[0,3.9,14.21],[1,1.4,50],[2,1.3,66.67]],"ltp":4.1,"tv":237.29,"id":12474498}]}]}
{"op":"mcm","clk":"11849378830","pt":1723666605730,"mc":[{"id":"1.231815703","rc":[{"batb":[[0,3.95,10.05],[1,3.9,14.16],[2,1.4,50]],"ltp":4.1,"tv":237.29,"id":12474498}]}]}
{"op":"mcm","clk":"11849379101","pt":1723666608947,"mc":[{"id":"1.231815703","rc":[{"batb":[[0,3.9,14.21],[1,1.4,50],[2,1.3,66.67]],"ltp":4.1,"tv":237.29,"id":12474498}]}]}
{"op":"mcm","clk":"11849379261","pt":1723666611502,"mc":[{"id":"1.231815703","rc":[{"batb":[[0,3.95,10.05],[1,3.9,14.16],[2,1.4,50]],"ltp":4.1,"tv":237.29,"id":12474498}]}]}
{"op":"mcm","clk":"11849379482","pt":1723666614819,"mc":[{"id":"1.231815703","rc":[{"batb":[[0,3.9,14.21],[1,1.4,50],[2,1.3,66.67]],"ltp":4.1,"tv":237.29,"id":12474498}]}]}
{"op":"mcm","clk":"11849379641","pt":1723666617235,"mc":[{"id":"1.231815703","rc":[{"batb":[[0,3.95,10.05],[1,3.9,14.16],[2,1.4,50]],"ltp":4.1,"tv":237.29,"id":12474498}]}]}
{"op":"mcm","clk":"11849379888","pt":1723666620635,"mc":[{"id":"1.231815703","rc":[{"batb":[[0,3.9,14.21],[1,1.4,50],[2,1.3,66.67]],"ltp":4.1,"tv":237.29,"id":12474498}]}]}
{"op":"mcm","clk":"11849380028","pt":1723666622723,"mc":[{"id":"1.231815703","rc":[{"batb":[[0,3.95,10.05],[1,3.9,14.16],[2,1.4,50]],"ltp":4.1,"tv":237.29,"id":12474498}]}]}
{"op":"mcm","clk":"11849380280","pt":1723666626014,"mc":[{"id":"1.231815703","rc":[{"batb":[[0,3.9,14.21],[1,1.4,50],[2,1.3,66.67]],"ltp":4.1,"tv":237.29,"id":12474498}]}]}
{"op":"mcm","clk":"11849380482","pt":1723666628533,"mc":[{"id":"1.231815703","rc":[{"batb":[[0,3.95,10.05],[1,3.9,14.16],[2,1.4,50]],"ltp":4.1,"tv":237.29,"id":12474498}]}]}
{"op":"mcm","clk":"11849380762","pt":1723666631830,"mc":[{"id":"1.231815703","rc":[{"batb":[[0,3.9,14.21],[1,1.4,50],[2,1.3,66.67]],"ltp":4.1,"tv":237.29,"id":12474498}]}]}
{"op":"mcm","clk":"11849380970","pt":1723666634347,"mc":[{"id":"1.231815703","rc":[{"batb":[[0,3.95,10.05],[1,3.9,14.16],[2,1.4,50]],"ltp":4.1,"tv":237.29,"id":12474498}]}]}
{"op":"mcm","clk":"11849381209","pt":1723666637746,"mc":[{"id":"1.231815703","rc":[{"batb":[[0,3.9,14.21],[1,1.4,50],[2,1.3,66.67]],"ltp":4.1,"tv":237.29,"id":12474498}]}]}
{"op":"mcm","clk":"11849381380","pt":1723666640059,"mc":[{"id":"1.231815703","rc":[{"batb":[[0,3.95,10.05],[1,3.9,14.16],[2,1.4,50]],"ltp":4.1,"tv":237.29,"id":12474498}]}]}
{"op":"mcm","clk":"11849381663","pt":1723666643258,"mc":[{"id":"1.231815703","rc":[{"batb":[[0,3.9,14.21],[1,1.4,50],[2,1.3,66.67]],"ltp":4.1,"tv":237.29,"id":12474498}]}]}
{"op":"mcm","clk":"11849381904","pt":1723666646736,"mc":[{"id":"1.231815703","rc":[{"batb":[[0,3.95,10.05],[1,3.9,14.16],[2,1.4,50]],"ltp":4.1,"tv":237.29,"id":12474498}]}]}
{"op":"mcm","clk":"11849382142","pt":1723666650038,"mc":[{"id":"1.231815703","rc":[{"batb":[[0,3.9,14.21],[1,1.4,50],[2,1.3,66.67]],"ltp":4.1,"tv":237.29,"id":12474498}]}]}
{"op":"mcm","clk":"11849382327","pt":1723666652456,"mc":[{"id":"1.231815703","rc":[{"batb":[[0,3.95,10.05],[1,3.9,14.16],[2,1.4,50]],"ltp":4.1,"tv":237.29,"id":12474498}]}]}
{"op":"mcm","clk":"11849382565","pt":1723666655782,"mc":[{"id":"1.231815703","rc":[{"batb":[[0,3.9,14.21],[1,1.4,50],[2,1.3,66.67]],"ltp":4.1,"tv":237.29,"id":12474498}]}]}
{"op":"mcm","clk":"11849382741","pt":1723666658264,"mc":[{"id":"1.231815703","rc":[{"batb":[[0,3.95,10.05],[1,3.9,14.16],[2,1.4,50]],"ltp":4.1,"tv":237.29,"id":12474498}]}]}
{"op":"mcm","clk":"11849382992","pt":1723666661659,"mc":[{"id":"1.231815703","rc":[{"batb":[[0,3.9,14.21],[1,1.4,50],[2,1.3,66.67]],"ltp":4.1,"tv":237.29,"id":12474498}]}]}
{"op":"mcm","clk":"11849383139","pt":1723666663886,"mc":[{"id":"1.231815703","rc":[{"batb":[[0,3.95,10.05],[1,3.9,14.16],[2,1.4,50]],"ltp":4.1,"tv":237.29,"id":12474498}]}]}
{"op":"mcm","clk":"11849383379","pt":1723666667187,"mc":[{"id":"1.231815703","rc":[{"batb":[[0,3.9,14.21],[1,1.4,50],[2,1.3,66.67]],"ltp":4.1,"tv":237.29,"id":12474498}]}]}
{"op":"mcm","clk":"11849383571","pt":1723666669769,"mc":[{"id":"1.231815703","rc":[{"batb":[[0,3.95,10.05],[1,3.9,14.16],[2,1.4,50]],"ltp":4.1,"tv":237.29,"id":12474498}]}]}
{"op":"mcm","clk":"11849383771","pt":1723666673077,"mc":[{"id":"1.231815703","rc":[{"batb":[[0,3.9,14.21],[1,1.4,50],[2,1.3,66.67]],"ltp":4.1,"tv":237.29,"id":12474498}]}]}
{"op":"mcm","clk":"11849383998","pt":1723666676802,"mc":[{"id":"1.231815703","rc":[{"batb":[[0,3.95,10.05],[1,3.9,14.16],[2,1.4,50]],"ltp":4.1,"tv":237.29,"id":12474498}]}]}
{"op":"mcm","clk":"11849384219","pt":1723666680101,"mc":[{"id":"1.231815703","rc":[{"batb":[[0,3.9,14.21],[1,1.4,50],[2,1.3,66.67]],"ltp":4.1,"tv":237.29,"id":12474498}]}]}
{"op":"mcm","clk":"11849384499","pt":1723666683473,"mc":[{"id":"1.231815703","rc":[{"batb":[[0,3.95,10.05],[1,3.9,14.16],[2,1.4,50]],"ltp":4.1,"tv":237.29,"id":12474498}]}]}
{"op":"mcm","clk":"11849384782","pt":1723666686996,"mc":[{"id":"1.231815703","rc":[{"batb":[[0,3.9,14.21],[1,1.4,50],[2,1.3,66.67]],"ltp":4.1,"tv":237.29,"id":12474498}]}]}
{"op":"mcm","clk":"11849385021","pt":1723666690095,"mc":[{"id":"1.231815703","rc":[{"batb":[[0,3.95,10.05],[1,3.9,14.16],[2,1.4,50]],"ltp":4.1,"tv":237.29,"id":12474498}]}]}
{"op":"mcm","clk":"11849385232","pt":1723666693299,"mc":[{"id":"1.231815703","rc":[{"batb":[[0,3.9,14.21],[1,1.4,50],[2,1.3,66.67]],"ltp":4.1,"tv":237.29,"id":12474498}]}]}
{"op":"mcm","clk":"11849385452","pt":1723666696611,"mc":[{"id":"1.231815703","rc":[{"batb":[[0,3.95,10.05],[1,3.9,14.16],[2,1.4,50]],"ltp":4.1,"tv":237.29,"id":12474498}]}]}
{"op":"mcm","clk":"11849385710","pt":1723666699908,"mc":[{"id":"1.231815703","rc":[{"batb":[[0,3.9,14.21],[1,1.4,50],[2,1.3,66.67]],"ltp":4.1,"tv":237.29,"id":12474498}]}]}
{"op":"mcm","clk":"11849385917","pt":1723666703412,"mc":[{"id":"1.231815703","rc":[{"batb":[[0,3.95,10.05],[1,3.9,14.16],[2,1.4,50]],"ltp":4.1,"tv":237.29,"id":12474498}]}]}
{"op":"mcm","clk":"11849386154","pt":1723666706826,"mc":[{"id":"1.231815703","rc":[{"batb":[[0,3.9,14.21],[1,1.4,50],[2,1.3,66.67]],"ltp":4.1,"tv":237.29,"id":12474498}]}]}
{"op":"mcm","clk":"11849386427","pt":1723666710129,"mc":[{"id":"1.231815703","rc":[{"batb":[[0,3.95,10.05],[1,3.9,14.16],[2,1.4,50]],"ltp":4.1,"tv":237.29,"id":12474498}]}]}
{"op":"mcm","clk":"11849386751","pt":1723666713637,"mc":[{"id":"1.231815703","rc":[{"batb":[[0,3.9,14.21],[1,1.4,50],[2,1.3,66.67]],"ltp":4.1,"tv":237.29,"id":12474498}]}]}
{"op":"mcm","clk":"11849386936","pt":1723666716118,"mc":[{"id":"1.231815703","rc":[{"batb":[[0,3.95,10.05],[1,3.9,14.16],[2,1.4,50]],"ltp":4.1,"tv":237.29,"id":12474498}]}]}
{"op":"mcm","clk":"11849387215","pt":1723666719447,"mc":[{"id":"1.231815703","rc":[{"batb":[[0,3.9,14.21],[1,1.4,50],[2,1.3,66.67]],"ltp":4.1,"tv":237.29,"id":12474498}]}]}
{"op":"mcm","clk":"11849387385","pt":1723666721617,"mc":[{"id":"1.231815703","rc":[{"batb":[[0,3.95,10.05],[1,3.9,14.16],[2,1.4,50]],"ltp":4.1,"tv":237.29,"id":12474498}]}]}
{"op":"mcm","clk":"11849387625","pt":1723666724948,"mc":[{"id":"1.231815703","rc":[{"batb":[[0,3.9,14.21],[1,1.4,50],[2,1.3,66.67]],"ltp":4.1,"tv":237.29,"id":12474498}]}]}
{"op":"mcm","clk":"11849387791","pt":1723666727534,"mc":[{"id":"1.231815703","rc":[{"batb":[[0,3.95,10.05],[1,3.9,14.16],[2,1.4,50]],"ltp":4.1,"tv":237.29,"id":12474498}]}]}
{"op":"mcm","clk":"11849388028","pt":1723666730843,"mc":[{"id":"1.231815703","rc":[{"batb":[[0,3.9,14.21],[1,1.4,50],[2,1.3,66.67]],"ltp":4.1,"tv":237.29,"id":12474498}]}]}
{"op":"mcm","clk":"11849388258","pt":1723666733368,"mc":[{"id":"1.231815703","rc":[{"batb":[[0,3.95,10.05],[1,3.9,14.16],[2,1.4,50]],"ltp":4.1,"tv":237.29,"id":12474498}]}]}
{"op":"mcm","clk":"11849388491","pt":1723666736730,"mc":[{"id":"1.231815703","rc":[{"batb":[[0,3.9,14.21],[1,1.4,50],[2,1.3,66.67]],"ltp":4.1,"tv":237.29,"id":12474498}]}]}
{"op":"mcm","clk":"11849388717","pt":1723666740037,"mc":[{"id":"1.231815703","rc":[{"batb":[[0,3.95,10.05],[1,3.9,14.16],[2,1.4,50]],"ltp":4.1,"tv":237.29,"id":12474498}]}]}
{"op":"mcm","clk":"11849388995","pt":1723666743455,"mc":[{"id":"1.231815703","rc":[{"batb":[[0,3.9,14.21],[1,1.4,50],[2,1.3,66.67]],"ltp":4.1,"tv":237.29,"id":12474498}]}]}
{"op":"mcm","clk":"11849389154","pt":1723666745741,"mc":[{"id":"1.231815703","rc":[{"batb":[[0,3.95,10.05],[1,3.9,14.16],[2,1.4,50]],"ltp":4.1,"tv":237.29,"id":12474498}]}]}
{"op":"mcm","clk":"11849389359","pt":1723666749066,"mc":[{"id":"1.231815703","rc":[{"batb":[[0,3.9,14.21],[1,1.4,50],[2,1.3,66.67]],"ltp":4.1,"tv":237.29,"id":12474498}]}]}
{"op":"mcm","clk":"11849389549","pt":1723666751444,"mc":[{"id":"1.231815703","rc":[{"batb":[[0,3.95,10.05],[1,3.9,14.16],[2,1.4,50]],"ltp":4.1,"tv":237.29,"id":12474498}]}]}
{"op":"mcm","clk":"11849389820","pt":1723666754966,"mc":[{"id":"1.231815703","rc":[{"batb":[[0,3.9,14.21],[1,1.4,50],[2,1.3,66.67]],"ltp":4.1,"tv":237.29,"id":12474498}]}]}
{"op":"mcm","clk":"11849390051","pt":1723666758256,"mc":[{"id":"1.231815703","rc":[{"batb":[[0,3.95,10.05],[1,3.9,14.16],[2,1.4,50]],"ltp":4.1,"tv":237.29,"id":12474498}]}]}
{"op":"mcm","clk":"11849390279","pt":1723666761571,"mc":[{"id":"1.231815703","rc":[{"batb":[[0,3.9,14.21],[1,1.4,50],[2,1.3,66.67]],"ltp":4.1,"tv":237.29,"id":12474498}]}]}
{"op":"mcm","clk":"11849390511","pt":1723666764575,"mc":[{"id":"1.231815703","rc":[{"batb":[[0,3.95,10.05],[1,3.9,14.16],[2,1.4,50]],"ltp":4.1,"tv":237.29,"id":12474498}]}]}
{"op":"mcm","clk":"11849390731","pt":1723666767982,"mc":[{"id":"1.231815703","rc":[{"batb":[[0,3.9,14.21],[1,1.4,50],[2,1.3,66.67]],"ltp":4.1,"tv":237.29,"id":12474498}]}]}
{"op":"mcm","clk":"11849390903","pt":1723666770302,"mc":[{"id":"1.231815703","rc":[{"batb":[[0,3.95,10.05],[1,3.9,14.16],[2,1.4,50]],"ltp":4.1,"tv":237.29,"id":12474498}]}]}
{"op":"mcm","clk":"11849391132","pt":1723666773605,"mc":[{"id":"1.231815703","rc":[{"batb":[[0,3.9,14.21],[1,1.4,50],[2,1.3,66.67]],"ltp":4.1,"tv":237.29,"id":12474498}]}]}
{"op":"mcm","clk":"11849391396","pt":1723666777278,"mc":[{"id":"1.231815703","rc":[{"batb":[[0,3.95,10.05],[1,3.9,14.16],[2,1.4,50]],"ltp":4.1,"tv":237.29,"id":12474498}]}]}
{"op":"mcm","clk":"11849391657","pt":1723666780696,"mc":[{"id":"1.231815703","rc":[{"batb":[[0,3.9,14.21],[1,1.4,50],[2,1.3,66.67]],"ltp":4.1,"tv":237.29,"id":12474498}]}]}
{"op":"mcm","clk":"11849391836","pt":1723666783020,"mc":[{"id":"1.231815703","rc":[{"batb":[[0,3.95,10.05],[1,3.9,14.16],[2,1.4,50]],"ltp":4.1,"tv":237.29,"id":12474498}]}]}
{"op":"mcm","clk":"11849392117","pt":1723666786289,"mc":[{"id":"1.231815703","rc":[{"batb":[[0,3.9,14.21],[1,1.4,50],[2,1.3,66.67]],"ltp":4.1,"tv":237.29,"id":12474498}]}]}
{"op":"mcm","clk":"11849392311","pt":1723666788802,"mc":[{"id":"1.231815703","rc":[{"batb":[[0,3.95,10.05],[1,3.9,14.16],[2,1.4,50]],"ltp":4.1,"tv":237.29,"id":12474498}]}]}
{"op":"mcm","clk":"11849392585","pt":1723666792010,"mc":[{"id":"1.231815703","rc":[{"batb":[[0,3.9,14.21],[1,1.4,50],[2,1.3,66.67]],"ltp":4.1,"tv":237.29,"id":12474498}]}]}
{"op":"mcm","clk":"11849392754","pt":1723666794330,"mc":[{"id":"1.231815703","rc":[{"batb":[[0,3.95,10.05],[1,3.9,14.16],[2,1.4,50]],"ltp":4.1,"tv":237.29,"id":12474498}]}]}
{"op":"mcm","clk":"11849393033","pt":1723666797645,"mc":[{"id":"1.231815703","rc":[{"batb":[[0,3.9,14.21],[1,1.4,50],[2,1.3,66.67]],"ltp":4.1,"tv":237.29,"id":12474498}]}]}
{"op":"mcm","clk":"11849393197","pt":1723666799918,"mc":[{"id":"1.231815703","rc":[{"batb":[[0,3.95,10.05],[1,3.9,14.16],[2,1.4,50]],"ltp":4.1,"tv":237.29,"id":12474498}]}]}
{"op":"mcm","clk":"11849393454","pt":1723666803204,"mc":[{"id":"1.231815703","rc":[{"batb":[[0,3.9,14.21],[1,1.4,50],[2,1.3,66.67]],"ltp":4.1,"tv":237.29,"id":12474498}]}]}
{"op":"mcm","clk":"11849393639","pt":1723666805837,"mc":[{"id":"1.231815703","rc":[{"batb":[[0,3.95,10.05],[1,3.9,14.16],[2,1.4,50]],"ltp":4.1,"tv":237.29,"id":12474498}]}]}
{"op":"mcm","clk":"11849393892","pt":1723666809251,"mc":[{"id":"1.231815703","rc":[{"batb":[[0,3.9,14.21],[1,1.4,50],[2,1.3,66.67]],"ltp":4.1,"tv":237.29,"id":12474498}]}]}
{"op":"mcm","clk":"11849394078","pt":1723666811530,"mc":[{"id":"1.231815703","rc":[{"batb":[[0,3.95,10.05],[1,3.9,14.16],[2,1.4,50]],"ltp":4.1,"tv":237.29,"id":12474498}]}]}
{"op":"mcm","clk":"11849394373","pt":1723666814853,"mc":[{"id":"1.231815703","rc":[{"batb":[[0,3.9,14.21],[1,1.4,50],[2,1.3,66.67]],"ltp":4.1,"tv":237.29,"id":12474498}]}]}
{"op":"mcm","clk":"11849394555","pt":1723666817231,"mc":[{"id":"1.231815703","rc":[{"batb":[[0,3.95,10.05],[1,3.9,14.16],[2,1.4,50]],"ltp":4.1,"tv":237.29,"id":12474498}]}]}
{"op":"mcm","clk":"11849394769","pt":1723666820472,"mc":[{"id":"1.231815703","rc":[{"batb":[[0,3.9,14.21],[1,1.4,50],[2,1.3,66.67]],"ltp":4.1,"tv":237.29,"id":12474498}]}]}
{"op":"mcm","clk":"11849394963","pt":1723666822955,"mc":[{"id":"1.231815703","rc":[{"batb":[[0,3.95,10.05],[1,3.9,14.16],[2,1.4,50]],"ltp":4.1,"tv":237.29,"id":12474498}]}]}
{"op":"mcm","clk":"11849395207","pt":1723666826262,"mc":[{"id":"1.231815703","rc":[{"batb":[[0,3.9,14.21],[1,1.4,50],[2,1.3,66.67]],"ltp":4.1,"tv":237.29,"id":12474498}]}]}
{"op":"mcm","clk":"11849395455","pt":1723666829565,"mc":[{"id":"1.231815703","rc":[{"batb":[[0,3.95,10.05],[1,3.9,14.16],[2,1.4,50]],"ltp":4.1,"tv":237.29,"id":12474498}]}]}
{"op":"mcm","clk":"11849395726","pt":1723666832867,"mc":[{"id":"1.231815703","rc":[{"batb":[[0,3.9,14.21],[1,1.4,50],[2,1.3,66.67]],"ltp":4.1,"tv":237.29,"id":12474498}]}]}
{"op":"mcm","clk":"11849395900","pt":1723666835140,"mc":[{"id":"1.231815703","rc":[{"batb":[[0,3.95,10.05],[1,3.9,14.16],[2,1.4,50]],"ltp":4.1,"tv":237.29,"id":12474498}]}]}
{"op":"mcm","clk":"11849396142","pt":1723666838484,"mc":[{"id":"1.231815703","rc":[{"batb":[[0,3.9,14.21],[1,1.4,50],[2,1.3,66.67]],"ltp":4.1,"tv":237.29,"id":12474498}]}]}
{"op":"mcm","clk":"11849396336","pt":1723666841071,"mc":[{"id":"1.231815703","rc":[{"batb":[[0,3.95,10.05],[1,3.9,14.16],[2,1.4,50]],"ltp":4.1,"tv":237.29,"id":12474498}]}]}
{"op":"mcm","clk":"11849396584","pt":1723666844380,"mc":[{"id":"1.231815703","rc":[{"batb":[[0,3.9,14.21],[1,1.4,50],[2,1.3,66.67]],"ltp":4.1,"tv":237.29,"id":12474498}]}]}
{"op":"mcm","clk":"11849396781","pt":1723666846654,"mc":[{"id":"1.231815703","rc":[{"batb":[[0,3.95,10.05],[1,3.9,14.16],[2,1.4,50]],"ltp":4.1,"tv":237.29,"id":12474498}]}]}
{"op":"mcm","clk":"11849397061","pt":1723666850070,"mc":[{"id":"1.231815703","rc":[{"batb":[[0,3.9,14.21],[1,1.4,50],[2,1.3,66.67]],"ltp":4.1,"tv":237.29,"id":12474498}]}]}
{"op":"mcm","clk":"11849397236","pt":1723666852197,"mc":[{"id":"1.231815703","rc":[{"batb":[[0,3.95,10.05],[1,3.9,14.16],[2,1.4,50]],"ltp":4.1,"tv":237.29,"id":12474498}]}]}
{"op":"mcm","clk":"11849397537","pt":1723666855668,"mc":[{"id":"1.231815703","rc":[{"batb":[[0,3.9,14.21],[1,1.4,50],[2,1.3,66.67]],"ltp":4.1,"tv":237.29,"id":12474498}]}]}
{"op":"mcm","clk":"11849397732","pt":1723666858193,"mc":[{"id":"1.231815703","rc":[{"batb":[[0,3.95,10.05],[1,3.9,14.16],[2,1.4,50]],"ltp":4.1,"tv":237.29,"id":12474498}]}]}
{"op":"mcm","clk":"11849397975","pt":1723666861404,"mc":[{"id":"1.231815703","rc":[{"batb":[[0,3.9,14.21],[1,1.4,50],[2,1.3,66.67]],"ltp":4.1,"tv":237.29,"id":12474498}]}]}
{"op":"mcm","clk":"11849398207","pt":1723666864399,"mc":[{"id":"1.231815703","rc":[{"batb":[[0,3.95,10.05],[1,3.9,14.16],[2,1.4,50]],"ltp":4.1,"tv":237.29,"id":12474498}]}]}
{"op":"mcm","clk":"11849398434","pt":1723666867697,"mc":[{"id":"1.231815703","rc":[{"batb":[[0,3.9,14.21],[1,1.4,50],[2,1.3,66.67]],"ltp":4.1,"tv":237.29,"id":12474498}]}]}
{"op":"mcm","clk":"11849398601","pt":1723666870200,"mc":[{"id":"1.231815703","rc":[{"batb":[[0,3.95,10.05],[1,3.9,14.16],[2,1.4,50]],"ltp":4.1,"tv":237.29,"id":12474498}]}]}
{"op":"mcm","clk":"11849398848","pt":1723666873497,"mc":[{"id":"1.231815703","rc":[{"batb":[[0,3.9,14.21],[1,1.4,50],[2,1.3,66.67]],"ltp":4.1,"tv":237.29,"id":12474498}]}]}
{"op":"mcm","clk":"11849399018","pt":1723666875814,"mc":[{"id":"1.231815703","rc":[{"batb":[[0,3.95,10.05],[1,3.9,14.16],[2,1.4,50]],"ltp":4.1,"tv":237.29,"id":12474498}]}]}
{"op":"mcm","clk":"11849399255","pt":1723666879010,"mc":[{"id":"1.231815703","rc":[{"batb":[[0,3.9,14.21],[1,1.4,50],[2,1.3,66.67]],"ltp":4.1,"tv":237.29,"id":12474498}]}]}
{"op":"mcm","clk":"11849399427","pt":1723666881427,"mc":[{"id":"1.231815703","rc":[{"batb":[[0,3.95,10.05],[1,3.9,14.16],[2,1.4,50]],"ltp":4.1,"tv":237.29,"id":12474498}]}]}
{"op":"mcm","clk":"11849399692","pt":1723666884825,"mc":[{"id":"1.231815703","rc":[{"batb":[[0,3.9,14.21],[1,1.4,50],[2,1.3,66.67]],"ltp":4.1,"tv":237.29,"id":12474498}]}]}
{"op":"mcm","clk":"11849399882","pt":1723666887139,"mc":[{"id":"1.231815703","rc":[{"batb":[[0,3.95,10.05],[1,3.9,14.16],[2,1.4,50]],"ltp":4.1,"tv":237.29,"id":12474498}]}]}
{"op":"mcm","clk":"11849400130","pt":1723666890439,"mc":[{"id":"1.231815703","rc":[{"batb":[[0,3.9,14.21],[1,1.4,50],[2,1.3,66.67]],"ltp":4.1,"tv":237.29,"id":12474498}]}]}
{"op":"mcm","clk":"11849400305","pt":1723666892708,"mc":[{"id":"1.231815703","rc":[{"batb":[[0,3.95,10.05],[1,3.9,14.16],[2,1.4,50]],"ltp":4.1,"tv":237.29,"id":12474498}]}]}
{"op":"mcm","clk":"11849400541","pt":1723666895954,"mc":[{"id":"1.231815703","rc":[{"batb":[[0,3.9,14.21],[1,1.4,50],[2,1.3,66.67]],"ltp":4.1,"tv":237.29,"id":12474498}]}]}
{"op":"mcm","clk":"11849400714","pt":1723666898472,"mc":[{"id":"1.231815703","rc":[{"batb":[[0,3.95,10.05],[1,3.9,14.16],[2,1.4,50]],"ltp":4.1,"tv":237.29,"id":12474498}]}]}
{"op":"mcm","clk":"11849400975","pt":1723666901820,"mc":[{"id":"1.231815703","rc":[{"batb":[[0,3.9,14.21],[1,1.4,50],[2,1.3,66.67]],"ltp":4.1,"tv":237.29,"id":12474498}]}]}
{"op":"mcm","clk":"11849401130","pt":1723666904135,"mc":[{"id":"1.231815703","rc":[{"batb":[[0,3.95,10.05],[1,3.9,14.16],[2,1.4,50]],"ltp":4.1,"tv":237.29,"id":12474498}]}]}
{"op":"mcm","clk":"11849401407","pt":1723666907442,"mc":[{"id":"1.231815703","rc":[{"batb":[[0,3.9,14.21],[1,1.4,50],[2,1.3,66.67]],"ltp":4.1,"tv":237.29,"id":12474498}]}]}
{"op":"mcm","clk":"11849401597","pt":1723666909861,"mc":[{"id":"1.231815703","rc":[{"batb":[[0,3.95,10.05],[1,3.9,14.16],[2,1.4,50]],"ltp":4.1,"tv":237.29,"id":12474498}]}]}
{"op":"mcm","clk":"11849401828","pt":1723666913331,"mc":[{"id":"1.231815703","rc":[{"batb":[[0,3.9,14.21],[1,1.4,50],[2,1.3,66.67]],"ltp":4.1,"tv":237.29,"id":12474498}]}]}
{"op":"mcm","clk":"11849401993","pt":1723666915649,"mc":[{"id":"1.231815703","rc":[{"batb":[[0,3.95,10.05],[1,3.9,14.16],[2,1.4,50]],"ltp":4.1,"tv":237.29,"id":12474498}]}]}
{"op":"mcm","clk":"11849402178","pt":1723666918879,"mc":[{"id":"1.231815703","rc":[{"batb":[[0,3.9,14.21],[1,1.4,50],[2,1.3,66.67]],"ltp":4.1,"tv":237.29,"id":12474498}]}]}
{"op":"mcm","clk":"11849402347","pt":1723666921465,"mc":[{"id":"1.231815703","rc":[{"batb":[[0,3.95,10.05],[1,3.9,14.16],[2,1.4,50]],"ltp":4.1,"tv":237.29,"id":12474498}]}]}
{"op":"mcm","clk":"11849402580","pt":1723666924872,"mc":[{"id":"1.231815703","rc":[{"batb":[[0,3.9,14.21],[1,1.4,50],[2,1.3,66.67]],"ltp":4.1,"tv":237.29,"id":12474498}]}]}
{"op":"mcm","clk":"11849402765","pt":1723666927352,"mc":[{"id":"1.231815703","rc":[{"batb":[[0,3.95,10.05],[1,3.9,14.16],[2,1.4,50]],"ltp":4.1,"tv":237.29,"id":12474498}]}]}
{"op":"mcm","clk":"11849402995","pt":1723666930790,"mc":[{"id":"1.231815703","rc":[{"batb":[[0,3.9,14.21],[1,1.4,50],[2,1.3,66.67]],"ltp":4.1,"tv":237.29,"id":12474498}]}]}
{"op":"mcm","clk":"11849403175","pt":1723666933062,"mc":[{"id":"1.231815703","rc":[{"batb":[[0,3.95,10.05],[1,3.9,14.16],[2,1.4,50]],"ltp":4.1,"tv":237.29,"id":12474498}]}]}
{"op":"mcm","clk":"11849403375","pt":1723666936400,"mc":[{"id":"1.231815703","rc":[{"batb":[[0,3.9,14.21],[1,1.4,50],[2,1.3,66.67]],"ltp":4.1,"tv":237.29,"id":12474498}]}]}
{"op":"mcm","clk":"11849403558","pt":1723666938988,"mc":[{"id":"1.231815703","rc":[{"batb":[[0,3.95,10.05],[1,3.9,14.16],[2,1.4,50]],"ltp":4.1,"tv":237.29,"id":12474498}]}]}
{"op":"mcm","clk":"11849403795","pt":1723666942392,"mc":[{"id":"1.231815703","rc":[{"batb":[[0,3.9,14.21],[1,1.4,50],[2,1.3,66.67]],"ltp":4.1,"tv":237.29,"id":12474498}]}]}
{"op":"mcm","clk":"11849403956","pt":1723666944808,"mc":[{"id":"1.231815703","rc":[{"batb":[[0,3.95,10.05],[1,3.9,14.16],[2,1.4,50]],"ltp":4.1,"tv":237.29,"id":12474498}]}]}
{"op":"mcm","clk":"11849404213","pt":1723666948118,"mc":[{"id":"1.231815703","rc":[{"batb":[[0,3.9,14.21],[1,1.4,50],[2,1.3,66.67]],"ltp":4.1,"tv":237.29,"id":12474498}]}]}
{"op":"mcm","clk":"11849404384","pt":1723666950600,"mc":[{"id":"1.231815703","rc":[{"batb":[[0,3.95,10.05],[1,3.9,14.16],[2,1.4,50]],"ltp":4.1,"tv":237.29,"id":12474498}]}]}
{"op":"mcm","clk":"11849404625","pt":1723666954004,"mc":[{"id":"1.231815703","rc":[{"batb":[[0,3.9,14.21],[1,1.4,50],[2,1.3,66.67]],"ltp":4.1,"tv":237.29,"id":12474498}]}]}
{"op":"mcm","clk":"11849404796","pt":1723666956326,"mc":[{"id":"1.231815703","rc":[{"batb":[[0,3.95,10.05],[1,3.9,14.16],[2,1.4,50]],"ltp":4.1,"tv":237.29,"id":12474498}]}]}
{"op":"mcm","clk":"11849405027","pt":1723666959626,"mc":[{"id":"1.231815703","rc":[{"batb":[[0,3.9,14.21],[1,1.4,50],[2,1.3,66.67]],"ltp":4.1,"tv":237.29,"id":12474498}]}]}
{"op":"mcm","clk":"11849405210","pt":1723666962109,"mc":[{"id":"1.231815703","rc":[{"batb":[[0,3.95,10.05],[1,3.9,14.16],[2,1.4,50]],"ltp":4.1,"tv":237.29,"id":12474498}]}]}
{"op":"mcm","clk":"11849405441","pt":1723666965443,"mc":[{"id":"1.231815703","rc":[{"batb":[[0,3.9,14.21],[1,1.4,50],[2,1.3,66.67]],"ltp":4.1,"tv":237.29,"id":12474498}]}]}
{"op":"mcm","clk":"11849405618","pt":1723666967615,"mc":[{"id":"1.231815703","rc":[{"batb":[[0,3.95,10.05],[1,3.9,14.16],[2,1.4,50]],"ltp":4.1,"tv":237.29,"id":12474498}]}]}
{"op":"mcm","clk":"11849405881","pt":1723666970921,"mc":[{"id":"1.231815703","rc":[{"batb":[[0,3.9,14.21],[1,1.4,50],[2,1.3,66.67]],"ltp":4.1,"tv":237.29,"id":12474498}]}]}
{"op":"mcm","clk":"11849406030","pt":1723666973131,"mc":[{"id":"1.231815703","rc":[{"batb":[[0,3.95,10.05],[1,3.9,14.16],[2,1.4,50]],"ltp":4.1,"tv":237.29,"id":12474498}]}]}
{"op":"mcm","clk":"11849406268","pt":1723666976450,"mc":[{"id":"1.231815703","rc":[{"batb":[[0,3.9,14.21],[1,1.4,50],[2,1.3,66.67]],"ltp":4.1,"tv":237.29,"id":12474498}]}]}
{"op":"mcm","clk":"11849406440","pt":1723666978636,"mc":[{"id":"1.231815703","rc":[{"batb":[[0,3.95,10.05],[1,3.9,14.16],[2,1.4,50]],"ltp":4.1,"tv":237.29,"id":12474498}]}]}
{"op":"mcm","clk":"11849406678","pt":1723666981951,"mc":[{"id":"1.231815703","rc":[{"batb":[[0,3.9,14.21],[1,1.4,50],[2,1.3,66.67]],"ltp":4.1,"tv":237.29,"id":12474498}]}]}
{"op":"mcm","clk":"11849406876","pt":1723666984342,"mc":[{"id":"1.231815703","rc":[{"batb":[[0,3.95,10.05],[1,3.9,14.16],[2,1.4,50]],"ltp":4.1,"tv":237.29,"id":12474498}]}]}
{"op":"mcm","clk":"11849407107","pt":1723666987654,"mc":[{"id":"1.231815703","rc":[{"batb":[[0,3.9,14.21],[1,1.4,50],[2,1.3,66.67]],"ltp":4.1,"tv":237.29,"id":12474498}]}]}
{"op":"mcm","clk":"11849407266","pt":1723666989935,"mc":[{"id":"1.231815703","rc":[{"batb":[[0,3.95,10.05],[1,3.9,14.16],[2,1.4,50]],"ltp":4.1,"tv":237.29,"id":12474498}]}]}
{"op":"mcm","clk":"11849407514","pt":1723666993336,"mc":[{"id":"1.231815703","rc":[{"batb":[[0,3.9,14.21],[1,1.4,50],[2,1.3,66.67]],"ltp":4.1,"tv":237.29,"id":12474498}]}]}
{"op":"mcm","clk":"11849407644","pt":1723666995451,"mc":[{"id":"1.231815703","rc":[{"batb":[[0,3.95,10.05],[1,3.9,14.16],[2,1.4,50]],"ltp":4.1,"tv":237.29,"id":12474498}]}]}
{"op":"mcm","clk":"11849407884","pt":1723666998755,"mc":[{"id":"1.231815703","rc":[{"batb":[[0,3.9,14.21],[1,1.4,50],[2,1.3,66.67]],"ltp":4.1,"tv":237.29,"id":12474498}]}]}
{"op":"mcm","clk":"11849408084","pt":1723667000981,"mc":[{"id":"1.231815703","rc":[{"batb":[[0,3.95,10.05],[1,3.9,14.16],[2,1.4,50]],"ltp":4.1,"tv":237.29,"id":12474498}]}]}
{"op":"mcm","clk":"11849408334","pt":1723667004448,"mc":[{"id":"1.231815703","rc":[{"batb":[[0,3.9,14.21],[1,1.4,50],[2,1.3,66.67]],"ltp":4.1,"tv":237.29,"id":12474498}]}]}
{"op":"mcm","clk":"11849408488","pt":1723667006559,"mc":[{"id":"1.231815703","rc":[{"batb":[[0,3.95,10.05],[1,3.9,14.16],[2,1.4,50]],"ltp":4.1,"tv":237.29,"id":12474498}]}]}
{"op":"mcm","clk":"11849408926","pt":1723667009968,"mc":[{"id":"1.231815703","rc":[{"batb":[[0,3.9,14.21],[1,1.4,50],[2,1.3,66.67]],"ltp":4.1,"tv":237.29,"id":12474498}]}]}
{"op":"mcm","clk":"11849409068","pt":1723667012182,"mc":[{"id":"1.231815703","rc":[{"batb":[[0,3.95,10.05],[1,3.9,14.16],[2,1.4,50]],"ltp":4.1,"tv":237.29,"id":12474498}]}]}
{"op":"mcm","clk":"11849409264","pt":1723667015484,"mc":[{"id":"1.231815703","rc":[{"batb":[[0,3.9,14.21],[1,1.4,50],[2,1.3,66.67]],"ltp":4.1,"tv":237.29,"id":12474498}]}]}
{"op":"mcm","clk":"11849409392","pt":1723667017764,"mc":[{"id":"1.231815703","rc":[{"batb":[[0,3.95,10.05],[1,3.9,14.16],[2,1.4,50]],"ltp":4.1,"tv":237.29,"id":12474498}]}]}
{"op":"mcm","clk":"11849409613","pt":1723667021064,"mc":[{"id":"1.231815703","rc":[{"batb":[[0,3.9,14.21],[1,1.4,50],[2,1.3,66.67]],"ltp":4.1,"tv":237.29,"id":12474498}]}]}
{"op":"mcm","clk":"11849409733","pt":1723667023175,"mc":[{"id":"1.231815703","rc":[{"batb":[[0,3.95,10.05],[1,3.9,14.16],[2,1.4,50]],"ltp":4.1,"tv":237.29,"id":12474498}]}]}
{"op":"mcm","clk":"11849409943","pt":1723667026475,"mc":[{"id":"1.231815703","rc":[{"batb":[[0,3.9,14.21],[1,1.4,50],[2,1.3,66.67]],"ltp":4.1,"tv":237.29,"id":12474498}]}]}
{"op":"mcm","clk":"11849410082","pt":1723667028788,"mc":[{"id":"1.231815703","rc":[{"batb":[[0,3.95,10.05],[1,3.9,14.16],[2,1.4,50]],"ltp":4.1,"tv":237.29,"id":12474498}]}]}
{"op":"mcm","clk":"11849410276","pt":1723667032198,"mc":[{"id":"1.231815703","rc":[{"batb":[[0,3.9,14.21],[1,1.4,50],[2,1.3,66.67]],"ltp":4.1,"tv":237.29,"id":12474498}]}]}
{"op":"mcm","clk":"11849410411","pt":1723667034414,"mc":[{"id":"1.231815703","rc":[{"batb":[[0,3.95,10.05],[1,3.9,14.16],[2,1.4,50]],"ltp":4.1,"tv":237.29,"id":12474498}]}]}
{"op":"mcm","clk":"11849410598","pt":1723667037811,"mc":[{"id":"1.231815703","rc":[{"batb":[[0,3.9,14.21],[1,1.4,50],[2,1.3,66.67]],"ltp":4.1,"tv":237.29,"id":12474498}]}]}
{"op":"mcm","clk":"11849410699","pt":1723667039988,"mc":[{"id":"1.231815703","rc":[{"batb":[[0,3.95,10.05],[1,3.9,14.16],[2,1.4,50]],"ltp":4.1,"tv":237.29,"id":12474498}]}]}
{"op":"mcm","clk":"11849410908","pt":1723667043387,"mc":[{"id":"1.231815703","rc":[{"batb":[[0,3.9,14.21],[1,1.4,50],[2,1.3,66.67]],"ltp":4.1,"tv":237.29,"id":12474498}]}]}
{"op":"mcm","clk":"11849411049","pt":1723667045798,"mc":[{"id":"1.231815703","rc":[{"batb":[[0,3.95,10.05],[1,3.9,14.16],[2,1.4,50]],"ltp":4.1,"tv":237.29,"id":12474498}]}]}
{"op":"mcm","clk":"11849411265","pt":1723667049198,"mc":[{"id":"1.231815703","rc":[{"batb":[[0,3.9,14.21],[1,1.4,50],[2,1.3,66.67]],"ltp":4.1,"tv":237.29,"id":12474498}]}]}
{"op":"mcm","clk":"11849411394","pt":1723667051331,"mc":[{"id":"1.231815703","rc":[{"batb":[[0,3.95,10.05],[1,3.9,14.16],[2,1.4,50]],"ltp":4.1,"tv":237.29,"id":12474498}]}]}
{"op":"mcm","clk":"11849411613","pt":1723667054529,"mc":[{"id":"1.231815703","rc":[{"batb":[[0,3.9,14.21],[1,1.4,50],[2,1.3,66.67]],"ltp":4.1,"tv":237.29,"id":12474498}]}]}
{"op":"mcm","clk":"11849411782","pt":1723667057029,"mc":[{"id":"1.231815703","rc":[{"batb":[[0,3.95,10.05],[1,3.9,14.16],[2,1.4,50]],"ltp":4.1,"tv":237.29,"id":12474498}]}]}
{"op":"mcm","clk":"11849411971","pt":1723667060435,"mc":[{"id":"1.231815703","rc":[{"batb":[[0,3.9,14.21],[1,1.4,50],[2,1.3,66.67]],"ltp":4.1,"tv":237.29,"id":12474498}]}]}
{"op":"mcm","clk":"11849412137","pt":1723667062806,"mc":[{"id":"1.231815703","rc":[{"batb":[[0,3.95,10.05],[1,3.9,14.16],[2,1.4,50]],"ltp":4.1,"tv":237.29,"id":12474498}]}]}
{"op":"mcm","clk":"11849412359","pt":1723667066311,"mc":[{"id":"1.231815703","rc":[{"batb":[[0,3.9,14.21],[1,1.4,50],[2,1.3,66.67]],"ltp":4.1,"tv":237.29,"id":12474498}]}]}
{"op":"mcm","clk":"11849412494","pt":1723667068527,"mc":[{"id":"1.231815703","rc":[{"batb":[[0,3.95,10.05],[1,3.9,14.16],[2,1.4,50]],"ltp":4.1,"tv":237.29,"id":12474498}]}]}
{"op":"mcm","clk":"11849412694","pt":1723667071871,"mc":[{"id":"1.231815703","rc":[{"batb":[[0,3.9,14.21],[1,1.4,50],[2,1.3,66.67]],"ltp":4.1,"tv":237.29,"id":12474498}]}]}
{"op":"mcm","clk":"11849412858","pt":1723667074139,"mc":[{"id":"1.231815703","rc":[{"batb":[[0,3.95,10.05],[1,3.9,14.16],[2,1.4,50]],"ltp":4.1,"tv":237.29,"id":12474498}]}]}
{"op":"mcm","clk":"11849413071","pt":1723667077540,"mc":[{"id":"1.231815703","rc":[{"batb":[[0,3.9,14.21],[1,1.4,50],[2,1.3,66.67]],"ltp":4.1,"tv":237.29,"id":12474498}]}]}
{"op":"mcm","clk":"11849413186","pt":1723667079751,"mc":[{"id":"1.231815703","rc":[{"batb":[[0,3.95,10.05],[1,3.9,14.16],[2,1.4,50]],"ltp":4.1,"tv":237.29,"id":12474498}]}]}
{"op":"mcm","clk":"11849413426","pt":1723667083151,"mc":[{"id":"1.231815703","rc":[{"batb":[[0,3.9,14.21],[1,1.4,50],[2,1.3,66.67]],"ltp":4.1,"tv":237.29,"id":12474498}]}]}
{"op":"mcm","clk":"11849413573","pt":1723667085373,"mc":[{"id":"1.231815703","rc":[{"batb":[[0,3.95,10.05],[1,3.9,14.16],[2,1.4,50]],"ltp":4.1,"tv":237.29,"id":12474498}]}]}
{"op":"mcm","clk":"11849413828","pt":1723667088675,"mc":[{"id":"1.231815703","rc":[{"batb":[[0,3.9,14.21],[1,1.4,50],[2,1.3,66.67]],"ltp":4.1,"tv":237.29,"id":12474498}]}]}
{"op":"mcm","clk":"11849413974","pt":1723667090890,"mc":[{"id":"1.231815703","rc":[{"batb":[[0,3.95,10.05],[1,3.9,14.16],[2,1.4,50]],"ltp":4.1,"tv":237.29,"id":12474498}]}]}
{"op":"mcm","clk":"11849414180","pt":1723667094189,"mc":[{"id":"1.231815703","rc":[{"batb":[[0,3.9,14.21],[1,1.4,50],[2,1.3,66.67]],"ltp":4.1,"tv":237.29,"id":12474498}]}]}
{"op":"mcm","clk":"11849414314","pt":1723667096351,"mc":[{"id":"1.231815703","rc":[{"batb":[[0,3.95,10.05],[1,3.9,14.16],[2,1.4,50]],"ltp":4.1,"tv":237.29,"id":12474498}]}]}
{"op":"mcm","clk":"11849414537","pt":1723667099654,"mc":[{"id":"1.231815703","rc":[{"batb":[[0,3.9,14.21],[1,1.4,50],[2,1.3,66.67]],"ltp":4.1,"tv":237.29,"id":12474498}]}]}
{"op":"mcm","clk":"11849414652","pt":1723667101873,"mc":[{"id":"1.231815703","rc":[{"batb":[[0,3.95,10.05],[1,3.9,14.16],[2,1.4,50]],"ltp":4.1,"tv":237.29,"id":12474498}]}]}
{"op":"mcm","clk":"11849414845","pt":1723667105172,"mc":[{"id":"1.231815703","rc":[{"batb":[[0,3.9,14.21],[1,1.4,50],[2,1.3,66.67]],"ltp":4.1,"tv":237.29,"id":12474498}]}]}
{"op":"mcm","clk":"11849414957","pt":1723667107487,"mc":[{"id":"1.231815703","rc":[{"batb":[[0,3.95,10.05],[1,3.9,14.16],[2,1.4,50]],"ltp":4.1,"tv":237.29,"id":12474498}]}]}
{"op":"mcm","clk":"11849415161","pt":1723667110685,"mc":[{"id":"1.231815703","rc":[{"batb":[[0,3.9,14.21],[1,1.4,50],[2,1.3,66.67]],"ltp":4.1,"tv":237.29,"id":12474498}]}]}
{"op":"mcm","clk":"11849415320","pt":1723667113470,"mc":[{"id":"1.231815703","rc":[{"batb":[[0,3.95,10.05],[1,3.9,14.16],[2,1.4,50]],"ltp":4.1,"tv":237.29,"id":12474498}]}]}
{"op":"mcm","clk":"11849415540","pt":1723667116775,"mc":[{"id":"1.231815703","rc":[{"batb":[[0,3.9,14.21],[1,1.4,50],[2,1.3,66.67]],"ltp":4.1,"tv":237.29,"id":12474498}]}]}
{"op":"mcm","clk":"11849415697","pt":1723667119298,"mc":[{"id":"1.231815703","rc":[{"batb":[[0,3.95,10.05],[1,3.9,14.16],[2,1.4,50]],"ltp":4.1,"tv":237.29,"id":12474498}]}]}
{"op":"mcm","clk":"11849415885","pt":1723667122599,"mc":[{"id":"1.231815703","rc":[{"batb":[[0,3.9,14.21],[1,1.4,50],[2,1.3,66.67]],"ltp":4.1,"tv":237.29,"id":12474498}]}]}
{"op":"mcm","clk":"11849416042","pt":1723667125124,"mc":[{"id":"1.231815703","rc":[{"batb":[[0,3.95,10.05],[1,3.9,14.16],[2,1.4,50]],"ltp":4.1,"tv":237.29,"id":12474498}]}]}
{"op":"mcm","clk":"11849416233","pt":1723667128536,"mc":[{"id":"1.231815703","rc":[{"batb":[[0,3.9,14.21],[1,1.4,50],[2,1.3,66.67]],"ltp":4.1,"tv":237.29,"id":12474498}]}]}
{"op":"mcm","clk":"11849416429","pt":1723667131825,"mc":[{"id":"1.231815703","rc":[{"batb":[[0,3.95,10.05],[1,3.9,14.16],[2,1.4,50]],"ltp":4.1,"tv":237.29,"id":12474498}]}]}
{"op":"mcm","clk":"11849416661","pt":1723667135220,"mc":[{"id":"1.231815703","rc":[{"batb":[[0,3.9,14.21],[1,1.4,50],[2,1.3,66.67]],"ltp":4.1,"tv":237.29,"id":12474498}]}]}
{"op":"mcm","clk":"11849416795","pt":1723667137540,"mc":[{"id":"1.231815703","rc":[{"batb":[[0,3.95,10.05],[1,3.9,14.16],[2,1.4,50]],"ltp":4.1,"tv":237.29,"id":12474498}]}]}
{"op":"mcm","clk":"11849416976","pt":1723667140829,"mc":[{"id":"1.231815703","rc":[{"batb":[[0,3.9,14.21],[1,1.4,50],[2,1.3,66.67]],"ltp":4.1,"tv":237.29,"id":12474498}]}]}
{"op":"mcm","clk":"11849417126","pt":1723667143449,"mc":[{"id":"1.231815703","rc":[{"batb":[[0,3.95,10.05],[1,3.9,14.16],[2,1.4,50]],"ltp":4.1,"tv":237.29,"id":12474498}]}]}
{"op":"mcm","clk":"11849417307","pt":1723667146841,"mc":[{"id":"1.231815703","rc":[{"batb":[[0,3.9,14.21],[1,1.4,50],[2,1.3,66.67]],"ltp":4.1,"tv":237.29,"id":12474498}]}]}
{"op":"mcm","clk":"11849417495","pt":1723667150645,"mc":[{"id":"1.231815703","rc":[{"batb":[[0,3.95,10.05],[1,3.9,14.16],[2,1.4,50]],"ltp":4.1,"tv":237.29,"id":12474498}]}]}
{"op":"mcm","clk":"11849417680","pt":1723667153831,"mc":[{"id":"1.231815703","rc":[{"batb":[[0,3.9,14.21],[1,1.4,50],[2,1.3,66.67]],"ltp":4.1,"tv":237.29,"id":12474498}]}]}
{"op":"mcm","clk":"11849417840","pt":1723667156360,"mc":[{"id":"1.231815703","rc":[{"batb":[[0,3.95,10.05],[1,3.9,14.16],[2,1.4,50]],"ltp":4.1,"tv":237.29,"id":12474498}]}]}
{"op":"mcm","clk":"11849418028","pt":1723667159647,"mc":[{"id":"1.231815703","rc":[{"batb":[[0,3.9,14.21],[1,1.4,50],[2,1.3,66.67]],"ltp":4.1,"tv":237.29,"id":12474498}]}]}
{"op":"mcm","clk":"11849418167","pt":1723667162075,"mc":[{"id":"1.231815703","rc":[{"batb":[[0,3.95,10.05],[1,3.9,14.16],[2,1.4,50]],"ltp":4.1,"tv":237.29,"id":12474498}]}]}
{"op":"mcm","clk":"11849418389","pt":1723667165465,"mc":[{"id":"1.231815703","rc":[{"batb":[[0,3.9,14.21],[1,1.4,50],[2,1.3,66.67]],"ltp":4.1,"tv":237.29,"id":12474498}]}]}
{"op":"mcm","clk":"11849418523","pt":1723667167877,"mc":[{"id":"1.231815703","rc":[{"batb":[[0,3.95,10.05],[1,3.9,14.16],[2,1.4,50]],"ltp":4.1,"tv":237.29,"id":12474498}]}]}
{"op":"mcm","clk":"11849418750","pt":1723667171278,"mc":[{"id":"1.231815703","rc":[{"batb":[[0,3.9,14.21],[1,1.4,50],[2,1.3,66.67]],"ltp":4.1,"tv":237.29,"id":12474498}]}]}
{"op":"mcm","clk":"11849418906","pt":1723667173551,"mc":[{"id":"1.231815703","rc":[{"batb":[[0,3.95,10.05],[1,3.9,14.16],[2,1.4,50]],"ltp":4.1,"tv":237.29,"id":12474498}]}]}
{"op":"mcm","clk":"11849419123","pt":1723667176950,"mc":[{"id":"1.231815703","rc":[{"batb":[[0,3.9,14.21],[1,1.4,50],[2,1.3,66.67]],"ltp":4.1,"tv":237.29,"id":12474498}]}]}
{"op":"mcm","clk":"11849419277","pt":1723667179268,"mc":[{"id":"1.231815703","rc":[{"batb":[[0,3.95,10.05],[1,3.9,14.16],[2,1.4,50]],"ltp":4.1,"tv":237.29,"id":12474498}]}]}
{"op":"mcm","clk":"11849419508","pt":1723667182675,"mc":[{"id":"1.231815703","rc":[{"batb":[[0,3.9,14.21],[1,1.4,50],[2,1.3,66.67]],"ltp":4.1,"tv":237.29,"id":12474498}]}]}
{"op":"mcm","clk":"11849419662","pt":1723667184994,"mc":[{"id":"1.231815703","rc":[{"batb":[[0,3.95,10.05],[1,3.9,14.16],[2,1.4,50]],"ltp":4.1,"tv":237.29,"id":12474498}]}]}
{"op":"mcm","clk":"11849419895","pt":1723667188392,"mc":[{"id":"1.231815703","rc":[{"batb":[[0,3.9,14.21],[1,1.4,50],[2,1.3,66.67]],"ltp":4.1,"tv":237.29,"id":12474498}]}]}
{"op":"mcm","clk":"11849420077","pt":1723667190670,"mc":[{"id":"1.231815703","rc":[{"batb":[[0,3.95,10.05],[1,3.9,14.16],[2,1.4,50]],"ltp":4.1,"tv":237.29,"id":12474498}]}]}
{"op":"mcm","clk":"11849420315","pt":1723667194115,"mc":[{"id":"1.231815703","rc":[{"batb":[[0,3.9,14.21],[1,1.4,50],[2,1.3,66.67]],"ltp":4.1,"tv":237.29,"id":12474498}]}]}
{"op":"mcm","clk":"11849420464","pt":1723667196390,"mc":[{"id":"1.231815703","rc":[{"batb":[[0,3.95,10.05],[1,3.9,14.16],[2,1.4,50]],"ltp":4.1,"tv":237.29,"id":12474498}]}]}
{"op":"mcm","clk":"11849420677","pt":1723667199795,"mc":[{"id":"1.231815703","rc":[{"batb":[[0,3.9,14.21],[1,1.4,50],[2,1.3,66.67]],"ltp":4.1,"tv":237.29,"id":12474498}]}]}
{"op":"mcm","clk":"11849420855","pt":1723667202183,"mc":[{"id":"1.231815703","rc":[{"batb":[[0,3.95,10.05],[1,3.9,14.16],[2,1.4,50]],"ltp":4.1,"tv":237.29,"id":12474498}]}]}
{"op":"mcm","clk":"11849421066","pt":1723667205487,"mc":[{"id":"1.231815703","rc":[{"batb":[[0,3.9,14.21],[1,1.4,50],[2,1.3,66.67]],"ltp":4.1,"tv":237.29,"id":12474498}]}]}
{"op":"mcm","clk":"11849421232","pt":1723667207805,"mc":[{"id":"1.231815703","rc":[{"batb":[[0,3.95,10.05],[1,3.9,14.16],[2,1.4,50]],"ltp":4.1,"tv":237.29,"id":12474498}]}]}
{"op":"mcm","clk":"11849421458","pt":1723667211110,"mc":[{"id":"1.231815703","rc":[{"batb":[[0,3.9,14.21],[1,1.4,50],[2,1.3,66.67]],"ltp":4.1,"tv":237.29,"id":12474498}]}]}
{"op":"mcm","clk":"11849421608","pt":1723667213435,"mc":[{"id":"1.231815703","rc":[{"batb":[[0,3.95,10.05],[1,3.9,14.16],[2,1.4,50]],"ltp":4.1,"tv":237.29,"id":12474498}]}]}
{"op":"mcm","clk":"11849421820","pt":1723667216938,"mc":[{"id":"1.231815703","rc":[{"batb":[[0,3.9,14.21],[1,1.4,50],[2,1.3,66.67]],"ltp":4.1,"tv":237.29,"id":12474498}]}]}
{"op":"mcm","clk":"11849422036","pt":1723667220242,"mc":[{"id":"1.231815703","rc":[{"batb":[[0,3.95,10.05],[1,3.9,14.16],[2,1.4,50]],"ltp":4.1,"tv":237.29,"id":12474498}]}]}
{"op":"mcm","clk":"11849422264","pt":1723667223425,"mc":[{"id":"1.231815703","rc":[{"batb":[[0,3.9,14.21],[1,1.4,50],[2,1.3,66.67]],"ltp":4.1,"tv":237.29,"id":12474498}]}]}
{"op":"mcm","clk":"11849422420","pt":1723667225949,"mc":[{"id":"1.231815703","rc":[{"batb":[[0,3.95,10.05],[1,3.9,14.16],[2,1.4,50]],"ltp":4.1,"tv":237.29,"id":12474498}]}]}
{"op":"mcm","clk":"11849422657","pt":1723667229137,"mc":[{"id":"1.231815703","rc":[{"batb":[[0,3.9,14.21],[1,1.4,50],[2,1.3,66.67]],"ltp":4.1,"tv":237.29,"id":12474498}]}]}
{"op":"mcm","clk":"11849422843","pt":1723667231628,"mc":[{"id":"1.231815703","rc":[{"batb":[[0,3.95,10.05],[1,3.9,14.16],[2,1.4,50]],"ltp":4.1,"tv":237.29,"id":12474498}]}]}
{"op":"mcm","clk":"11849423046","pt":1723667234957,"mc":[{"id":"1.231815703","rc":[{"batb":[[0,3.9,14.21],[1,1.4,50],[2,1.3,66.67]],"ltp":4.1,"tv":237.29,"id":12474498}]}]}
{"op":"mcm","clk":"11849423213","pt":1723667237335,"mc":[{"id":"1.231815703","rc":[{"batb":[[0,3.95,10.05],[1,3.9,14.16],[2,1.4,50]],"ltp":4.1,"tv":237.29,"id":12474498}]}]}
{"op":"mcm","clk":"11849423416","pt":1723667240680,"mc":[{"id":"1.231815703","rc":[{"batb":[[0,3.9,14.21],[1,1.4,50],[2,1.3,66.67]],"ltp":4.1,"tv":237.29,"id":12474498}]}]}
{"op":"mcm","clk":"11849423574","pt":1723667242942,"mc":[{"id":"1.231815703","rc":[{"batb":[[0,3.95,10.05],[1,3.9,14.16],[2,1.4,50]],"ltp":4.1,"tv":237.29,"id":12474498}]}]}
{"op":"mcm","clk":"11849423773","pt":1723667246244,"mc":[{"id":"1.231815703","rc":[{"batb":[[0,3.9,14.21],[1,1.4,50],[2,1.3,66.67]],"ltp":4.1,"tv":237.29,"id":12474498}]}]}
{"op":"mcm","clk":"11849423911","pt":1723667248563,"mc":[{"id":"1.231815703","rc":[{"batb":[[0,3.95,10.05],[1,3.9,14.16],[2,1.4,50]],"ltp":4.1,"tv":237.29,"id":12474498}]}]}
{"op":"mcm","clk":"11849424105","pt":1723667251757,"mc":[{"id":"1.231815703","rc":[{"batb":[[0,3.9,14.21],[1,1.4,50],[2,1.3,66.67]],"ltp":4.1,"tv":237.29,"id":12474498}]}]}
{"op":"mcm","clk":"11849424250","pt":1723667254179,"mc":[{"id":"1.231815703","rc":[{"batb":[[0,3.95,10.05],[1,3.9,14.16],[2,1.4,50]],"ltp":4.1,"tv":237.29,"id":12474498}]}]}
{"op":"mcm","clk":"11849424495","pt":1723667257481,"mc":[{"id":"1.231815703","rc":[{"batb":[[0,3.9,14.21],[1,1.4,50],[2,1.3,66.67]],"ltp":4.1,"tv":237.29,"id":12474498}]}]}
{"op":"mcm","clk":"11849424660","pt":1723667259762,"mc":[{"id":"1.231815703","rc":[{"batb":[[0,3.95,10.05],[1,3.9,14.16],[2,1.4,50]],"ltp":4.1,"tv":237.29,"id":12474498}]}]}
{"op":"mcm","clk":"11849424893","pt":1723667263059,"mc":[{"id":"1.231815703","rc":[{"batb":[[0,3.9,14.21],[1,1.4,50],[2,1.3,66.67]],"ltp":4.1,"tv":237.29,"id":12474498}]}]}
{"op":"mcm","clk":"11849425063","pt":1723667265480,"mc":[{"id":"1.231815703","rc":[{"batb":[[0,3.95,10.05],[1,3.9,14.16],[2,1.4,50]],"ltp":4.1,"tv":237.29,"id":12474498}]}]}
{"op":"mcm","clk":"11849425339","pt":1723667268996,"mc":[{"id":"1.231815703","rc":[{"batb":[[0,3.9,14.21],[1,1.4,50],[2,1.3,66.67]],"ltp":4.1,"tv":237.29,"id":12474498}]}]}
{"op":"mcm","clk":"11849425508","pt":1723667271273,"mc":[{"id":"1.231815703","rc":[{"batb":[[0,3.95,10.05],[1,3.9,14.16],[2,1.4,50]],"ltp":4.1,"tv":237.29,"id":12474498}]}]}
{"op":"mcm","clk":"11849425742","pt":1723667274779,"mc":[{"id":"1.231815703","rc":[{"batb":[[0,3.9,14.21],[1,1.4,50],[2,1.3,66.67]],"ltp":4.1,"tv":237.29,"id":12474498}]}]}
{"op":"mcm","clk":"11849425913","pt":1723667277101,"mc":[{"id":"1.231815703","rc":[{"batb":[[0,3.95,10.05],[1,3.9,14.16],[2,1.4,50]],"ltp":4.1,"tv":237.29,"id":12474498}]}]}
{"op":"mcm","clk":"11849426144","pt":1723667280513,"mc":[{"id":"1.231815703","rc":[{"batb":[[0,3.9,14.21],[1,1.4,50],[2,1.3,66.67]],"ltp":4.1,"tv":237.29,"id":12474498}]}]}
{"op":"mcm","clk":"11849426317","pt":1723667282791,"mc":[{"id":"1.231815703","rc":[{"batb":[[0,3.95,10.05],[1,3.9,14.16],[2,1.4,50]],"ltp":4.1,"tv":237.29,"id":12474498}]}]}
{"op":"mcm","clk":"11849426556","pt":1723667286094,"mc":[{"id":"1.231815703","rc":[{"batb":[[0,3.9,14.21],[1,1.4,50],[2,1.3,66.67]],"ltp":4.1,"tv":237.29,"id":12474498}]}]}
{"op":"mcm","clk":"11849426691","pt":1723667288415,"mc":[{"id":"1.231815703","rc":[{"batb":[[0,3.95,10.05],[1,3.9,14.16],[2,1.4,50]],"ltp":4.1,"tv":237.29,"id":12474498}]}]}
{"op":"mcm","clk":"11849426901","pt":1723667292019,"mc":[{"id":"1.231815703","rc":[{"batb":[[0,3.9,14.21],[1,1.4,50],[2,1.3,66.67]],"ltp":4.1,"tv":237.29,"id":12474498}]}]}
{"op":"mcm","clk":"11849427043","pt":1723667294337,"mc":[{"id":"1.231815703","rc":[{"batb":[[0,3.95,10.05],[1,3.9,14.16],[2,1.4,50]],"ltp":4.1,"tv":237.29,"id":12474498}]}]}
{"op":"mcm","clk":"11849427243","pt":1723667297725,"mc":[{"id":"1.231815703","rc":[{"batb":[[0,3.9,14.21],[1,1.4,50],[2,1.3,66.67]],"ltp":4.1,"tv":237.29,"id":12474498}]}]}
{"op":"mcm","clk":"11849427469","pt":1723667301540,"mc":[{"id":"1.231815703","rc":[{"batb":[[0,3.95,10.05],[1,3.9,14.16],[2,1.4,50]],"ltp":4.1,"tv":237.29,"id":12474498}]}]}
{"op":"mcm","clk":"11849427669","pt":1723667304942,"mc":[{"id":"1.231815703","rc":[{"batb":[[0,3.9,14.21],[1,1.4,50],[2,1.3,66.67]],"ltp":4.1,"tv":237.29,"id":12474498}]}]}
{"op":"mcm","clk":"11849427845","pt":1723667307314,"mc":[{"id":"1.231815703","rc":[{"batb":[[0,3.95,10.05],[1,3.9,14.16],[2,1.4,50]],"ltp":4.1,"tv":237.29,"id":12474498}]}]}
{"op":"mcm","clk":"11849428066","pt":1723667310620,"mc":[{"id":"1.231815703","rc":[{"batb":[[0,3.9,14.21],[1,1.4,50],[2,1.3,66.67]],"ltp":4.1,"tv":237.29,"id":12474498}]}]}
{"op":"mcm","clk":"11849428234","pt":1723667312930,"mc":[{"id":"1.231815703","rc":[{"batb":[[0,3.95,10.05],[1,3.9,14.16],[2,1.4,50]],"ltp":4.1,"tv":237.29,"id":12474498}]}]}
{"op":"mcm","clk":"11849428441","pt":1723667316229,"mc":[{"id":"1.231815703","rc":[{"batb":[[0,3.9,14.21],[1,1.4,50],[2,1.3,66.67]],"ltp":4.1,"tv":237.29,"id":12474498}]}]}
{"op":"mcm","clk":"11849428565","pt":1723667318545,"mc":[{"id":"1.231815703","rc":[{"batb":[[0,3.95,10.05],[1,3.9,14.16],[2,1.4,50]],"ltp":4.1,"tv":237.29,"id":12474498}]}]}
{"op":"mcm","clk":"11849428757","pt":1723667322046,"mc":[{"id":"1.231815703","rc":[{"batb":[[0,3.9,14.21],[1,1.4,50],[2,1.3,66.67]],"ltp":4.1,"tv":237.29,"id":12474498}]}]}
{"op":"mcm","clk":"11849428891","pt":1723667324368,"mc":[{"id":"1.231815703","rc":[{"batb":[[0,3.95,10.05],[1,3.9,14.16],[2,1.4,50]],"ltp":4.1,"tv":237.29,"id":12474498}]}]}
{"op":"mcm","clk":"11849429066","pt":1723667327658,"mc":[{"id":"1.231815703","rc":[{"batb":[[0,3.9,14.21],[1,1.4,50],[2,1.3,66.67]],"ltp":4.1,"tv":237.29,"id":12474498}]}]}
{"op":"mcm","clk":"11849429212","pt":1723667330039,"mc":[{"id":"1.231815703","rc":[{"batb":[[0,3.95,10.05],[1,3.9,14.16],[2,1.4,50]],"ltp":4.1,"tv":237.29,"id":12474498}]}]}
{"op":"mcm","clk":"11849429449","pt":1723667333386,"mc":[{"id":"1.231815703","rc":[{"batb":[[0,3.9,14.21],[1,1.4,50],[2,1.3,66.67]],"ltp":4.1,"tv":237.29,"id":12474498}]}]}
{"op":"mcm","clk":"11849429612","pt":1723667335758,"mc":[{"id":"1.231815703","rc":[{"batb":[[0,3.95,10.05],[1,3.9,14.16],[2,1.4,50]],"ltp":4.1,"tv":237.29,"id":12474498}]}]}
{"op":"mcm","clk":"11849429814","pt":1723667339061,"mc":[{"id":"1.231815703","rc":[{"batb":[[0,3.9,14.21],[1,1.4,50],[2,1.3,66.67]],"ltp":4.1,"tv":237.29,"id":12474498}]}]}
{"op":"mcm","clk":"11849429953","pt":1723667341701,"mc":[{"id":"1.231815703","rc":[{"batb":[[0,3.95,10.05],[1,3.9,14.16],[2,1.4,50]],"ltp":4.1,"tv":237.29,"id":12474498}]}]}
{"op":"mcm","clk":"11849430186","pt":1723667344960,"mc":[{"id":"1.231815703","rc":[{"batb":[[0,3.9,14.21],[1,1.4,50],[2,1.3,66.67]],"ltp":4.1,"tv":237.29,"id":12474498}]}]}
{"op":"mcm","clk":"11849430424","pt":1723667348265,"mc":[{"id":"1.231815703","rc":[{"batb":[[0,3.95,10.05],[1,3.9,14.16],[2,1.4,50]],"ltp":4.1,"tv":237.29,"id":12474498}]}]}
{"op":"mcm","clk":"11849430647","pt":1723667351667,"mc":[{"id":"1.231815703","rc":[{"batb":[[0,3.9,14.21],[1,1.4,50],[2,1.3,66.67]],"ltp":4.1,"tv":237.29,"id":12474498}]}]}
{"op":"mcm","clk":"11849430850","pt":1723667354815,"mc":[{"id":"1.231815703","rc":[{"batb":[[0,3.95,10.05],[1,3.9,14.16],[2,1.4,50]],"ltp":4.1,"tv":237.29,"id":12474498}]}]}
{"op":"mcm","clk":"11849431082","pt":1723667358221,"mc":[{"id":"1.231815703","rc":[{"batb":[[0,3.9,14.21],[1,1.4,50],[2,1.3,66.67]],"ltp":4.1,"tv":237.29,"id":12474498}]}]}
{"op":"mcm","clk":"11849431228","pt":1723667360591,"mc":[{"id":"1.231815703","rc":[{"batb":[[0,3.95,10.05],[1,3.9,14.16],[2,1.4,50]],"ltp":4.1,"tv":237.29,"id":12474498}]}]}
{"op":"mcm","clk":"11849431468","pt":1723667363902,"mc":[{"id":"1.231815703","rc":[{"batb":[[0,3.9,14.21],[1,1.4,50],[2,1.3,66.67]],"ltp":4.1,"tv":237.29,"id":12474498}]}]}
{"op":"mcm","clk":"11849431625","pt":1723667366386,"mc":[{"id":"1.231815703","rc":[{"batb":[[0,3.95,10.05],[1,3.9,14.16],[2,1.4,50]],"ltp":4.1,"tv":237.29,"id":12474498}]}]}
{"op":"mcm","clk":"11849431857","pt":1723667369797,"mc":[{"id":"1.231815703","rc":[{"batb":[[0,3.9,14.21],[1,1.4,50],[2,1.3,66.67]],"ltp":4.1,"tv":237.29,"id":12474498}]}]}
{"op":"mcm","clk":"11849432019","pt":1723667372122,"mc":[{"id":"1.231815703","rc":[{"batb":[[0,3.95,10.05],[1,3.9,14.16],[2,1.4,50]],"ltp":4.1,"tv":237.29,"id":12474498}]}]}
{"op":"mcm","clk":"11849432222","pt":1723667375520,"mc":[{"id":"1.231815703","rc":[{"batb":[[0,3.9,14.21],[1,1.4,50],[2,1.3,66.67]],"ltp":4.1,"tv":237.29,"id":12474498}]}]}
{"op":"mcm","clk":"11849432388","pt":1723667377795,"mc":[{"id":"1.231815703","rc":[{"batb":[[0,3.95,10.05],[1,3.9,14.16],[2,1.4,50]],"ltp":4.1,"tv":237.29,"id":12474498}]}]}
{"op":"mcm","clk":"11849432642","pt":1723667381104,"mc":[{"id":"1.231815703","rc":[{"batb":[[0,3.9,14.21],[1,1.4,50],[2,1.3,66.67]],"ltp":4.1,"tv":237.29,"id":12474498}]}]}
{"op":"mcm","clk":"11849432779","pt":1723667383523,"mc":[{"id":"1.231815703","rc":[{"batb":[[0,3.95,10.05],[1,3.9,14.16],[2,1.4,50]],"ltp":4.1,"tv":237.29,"id":12474498}]}]}
{"op":"mcm","clk":"11849432986","pt":1723667386924,"mc":[{"id":"1.231815703","rc":[{"batb":[[0,3.9,14.21],[1,1.4,50],[2,1.3,66.67]],"ltp":4.1,"tv":237.29,"id":12474498}]}]}
{"op":"mcm","clk":"11849433123","pt":1723667389246,"mc":[{"id":"1.231815703","rc":[{"batb":[[0,3.95,10.05],[1,3.9,14.16],[2,1.4,50]],"ltp":4.1,"tv":237.29,"id":12474498}]}]}
{"op":"mcm","clk":"11849433355","pt":1723667392549,"mc":[{"id":"1.231815703","rc":[{"batb":[[0,3.9,14.21],[1,1.4,50],[2,1.3,66.67]],"ltp":4.1,"tv":237.29,"id":12474498}]}]}
{"op":"mcm","clk":"11849433500","pt":1723667395024,"mc":[{"id":"1.231815703","rc":[{"batb":[[0,3.95,10.05],[1,3.9,14.16],[2,1.4,50]],"ltp":4.1,"tv":237.29,"id":12474498}]}]}
{"op":"mcm","clk":"11849433696","pt":1723667398321,"mc":[{"id":"1.231815703","rc":[{"batb":[[0,3.9,14.21],[1,1.4,50],[2,1.3,66.67]],"ltp":4.1,"tv":237.29,"id":12474498}]}]}
{"op":"mcm","clk":"11849433858","pt":1723667400751,"mc":[{"id":"1.231815703","rc":[{"batb":[[0,3.95,10.05],[1,3.9,14.16],[2,1.4,50]],"ltp":4.1,"tv":237.29,"id":12474498}]}]}
{"op":"mcm","clk":"11849434108","pt":1723667404167,"mc":[{"id":"1.231815703","rc":[{"batb":[[0,3.9,14.21],[1,1.4,50],[2,1.3,66.67]],"ltp":4.1,"tv":237.29,"id":12474498}]}]}
{"op":"mcm","clk":"11849434281","pt":1723667406431,"mc":[{"id":"1.231815703","rc":[{"batb":[[0,3.95,10.05],[1,3.9,14.16],[2,1.4,50]],"ltp":4.1,"tv":237.29,"id":12474498}]}]}
{"op":"mcm","clk":"11849434504","pt":1723667409738,"mc":[{"id":"1.231815703","rc":[{"batb":[[0,3.9,14.21],[1,1.4,50],[2,1.3,66.67]],"ltp":4.1,"tv":237.29,"id":12474498}]}]}
{"op":"mcm","clk":"11849434714","pt":1723667412949,"mc":[{"id":"1.231815703","rc":[{"batb":[[0,3.95,10.05],[1,3.9,14.16],[2,1.4,50]],"ltp":4.1,"tv":237.29,"id":12474498}]}]}
{"op":"mcm","clk":"11849434955","pt":1723667416263,"mc":[{"id":"1.231815703","rc":[{"batb":[[0,3.9,14.21],[1,1.4,50],[2,1.3,66.67]],"ltp":4.1,"tv":237.29,"id":12474498}]}]}
{"op":"mcm","clk":"11849435121","pt":1723667418542,"mc":[{"id":"1.231815703","rc":[{"batb":[[0,3.95,10.05],[1,3.9,14.16],[2,1.4,50]],"ltp":4.1,"tv":237.29,"id":12474498}]}]}
{"op":"mcm","clk":"11849435351","pt":1723667421846,"mc":[{"id":"1.231815703","rc":[{"batb":[[0,3.9,14.21],[1,1.4,50],[2,1.3,66.67]],"ltp":4.1,"tv":237.29,"id":12474498}]}]}
{"op":"mcm","clk":"11849435601","pt":1723667425673,"mc":[{"id":"1.231815703","rc":[{"batb":[[0,3.95,10.05],[1,3.9,14.16],[2,1.4,50]],"ltp":4.1,"tv":237.29,"id":12474498}]}]}
{"op":"mcm","clk":"11849435851","pt":1723667429089,"mc":[{"id":"1.231815703","rc":[{"batb":[[0,3.9,14.21],[1,1.4,50],[2,1.3,66.67]],"ltp":4.1,"tv":237.29,"id":12474498}]}]}
{"op":"mcm","clk":"11849435997","pt":1723667431264,"mc":[{"id":"1.231815703","rc":[{"batb":[[0,3.95,10.05],[1,3.9,14.16],[2,1.4,50]],"ltp":4.1,"tv":237.29,"id":12474498}]}]}
{"op":"mcm","clk":"11849436233","pt":1723667434569,"mc":[{"id":"1.231815703","rc":[{"batb":[[0,3.9,14.21],[1,1.4,50],[2,1.3,66.67]],"ltp":4.1,"tv":237.29,"id":12474498}]}]}
{"op":"mcm","clk":"11849436401","pt":1723667436889,"mc":[{"id":"1.231815703","rc":[{"batb":[[0,3.95,10.05],[1,3.9,14.16],[2,1.4,50]],"ltp":4.1,"tv":237.29,"id":12474498}]}]}
{"op":"mcm","clk":"11849436632","pt":1723667440272,"mc":[{"id":"1.231815703","rc":[{"batb":[[0,3.9,14.21],[1,1.4,50],[2,1.3,66.67]],"ltp":4.1,"tv":237.29,"id":12474498}]}]}
{"op":"mcm","clk":"11849436881","pt":1723667443575,"mc":[{"id":"1.231815703","rc":[{"batb":[[0,3.95,10.05],[1,3.9,14.16],[2,1.04,1637.19]],"ltp":4.1,"tv":237.29,"id":12474498}]}]}
{"op":"mcm","clk":"11849437101","pt":1723667446494,"mc":[{"id":"1.231815703","rc":[{"batb":[[0,3.9,14.21],[1,1.04,1637.19],[2,1.03,2366.9]],"ltp":4.1,"tv":237.29,"id":12474498}]}]}
{"op":"mcm","clk":"11849437256","pt":1723667448974,"mc":[{"id":"1.231815703","rc":[{"batb":[[0,3.95,10.05],[1,3.9,14.16],[2,1.04,1637.19]],"ltp":4.1,"tv":237.29,"id":12474498}]}]}
{"op":"mcm","clk":"11849437476","pt":1723667452170,"mc":[{"id":"1.231815703","rc":[{"batb":[[0,3.9,14.21],[1,1.04,1637.19],[2,1.03,2366.9]],"ltp":4.1,"tv":237.29,"id":12474498}]}]}
{"op":"mcm","clk":"11849437638","pt":1723667454488,"mc":[{"id":"1.231815703","rc":[{"batb":[[0,3.95,10.05],[1,3.9,14.16],[2,1.04,1637.19]],"ltp":4.1,"tv":237.29,"id":12474498}]}]}
{"op":"mcm","clk":"11849437872","pt":1723667457896,"mc":[{"id":"1.231815703","rc":[{"batb":[[0,3.9,14.21],[1,1.04,1637.19],[2,1.03,2366.9]],"ltp":4.1,"tv":237.29,"id":12474498}]}]}
{"op":"mcm","clk":"11849438037","pt":1723667460217,"mc":[{"id":"1.231815703","rc":[{"batb":[[0,3.95,10.05],[1,3.9,14.16],[2,1.04,1637.19]],"ltp":4.1,"tv":237.29,"id":12474498}]}]}
{"op":"mcm","clk":"11849438270","pt":1723667463577,"mc":[{"id":"1.231815703","rc":[{"batb":[[0,3.9,14.21],[1,1.04,1637.19],[2,1.03,2366.9]],"ltp":4.1,"tv":237.29,"id":12474498}]}]}
{"op":"mcm","clk":"11849438444","pt":1723667465896,"mc":[{"id":"1.231815703","rc":[{"batb":[[0,3.95,10.05],[1,3.9,14.16],[2,1.04,1637.19]],"ltp":4.1,"tv":237.29,"id":12474498}]}]}
{"op":"mcm","clk":"11849438726","pt":1723667469298,"mc":[{"id":"1.231815703","rc":[{"batb":[[0,3.9,14.21],[1,1.04,1637.19],[2,1.03,2366.9]],"ltp":4.1,"tv":237.29,"id":12474498}]}]}
{"op":"mcm","clk":"11849438867","pt":1723667471620,"mc":[{"id":"1.231815703","rc":[{"batb":[[0,3.95,10.05],[1,3.9,14.16],[2,1.04,1637.19]],"ltp":4.1,"tv":237.29,"id":12474498}]}]}
{"op":"mcm","clk":"11849439052","pt":1723667474817,"mc":[{"id":"1.231815703","rc":[{"batb":[[0,3.9,14.21],[1,1.04,1637.19],[2,1.03,2366.9]],"ltp":4.1,"tv":237.29,"id":12474498}]}]}
{"op":"mcm","clk":"11849439224","pt":1723667477599,"mc":[{"id":"1.231815703","rc":[{"batb":[[0,3.95,10.05],[1,3.9,14.16],[2,1.04,1637.19]],"ltp":4.1,"tv":237.29,"id":12474498}]}]}
{"op":"mcm","clk":"11849439429","pt":1723667481012,"mc":[{"id":"1.231815703","rc":[{"batb":[[0,3.9,14.21],[1,1.04,1637.19],[2,1.03,2366.9]],"ltp":4.1,"tv":237.29,"id":12474498}]}]}
{"op":"mcm","clk":"11849439583","pt":1723667483327,"mc":[{"id":"1.231815703","rc":[{"batb":[[0,3.95,10.05],[1,3.9,14.16],[2,1.04,1637.19]],"ltp":4.1,"tv":237.29,"id":12474498}]}]}
{"op":"mcm","clk":"11849439803","pt":1723667486543,"mc":[{"id":"1.231815703","rc":[{"batb":[[0,3.9,14.21],[1,1.04,1637.19],[2,1.03,2366.9]],"ltp":4.1,"tv":237.29,"id":12474498}]}]}
{"op":"mcm","clk":"11849439996","pt":1723667489839,"mc":[{"id":"1.231815703","rc":[{"batb":[[0,3.95,10.05],[1,3.9,14.16],[2,1.04,1637.19]],"ltp":4.1,"tv":237.29,"id":12474498}]}]}
{"op":"mcm","clk":"11849440213","pt":1723667493036,"mc":[{"id":"1.231815703","rc":[{"batb":[[0,3.9,14.21],[1,1.04,1637.19],[2,1.03,2366.9]],"ltp":4.1,"tv":237.29,"id":12474498}]}]}
{"op":"mcm","clk":"11849440374","pt":1723667495319,"mc":[{"id":"1.231815703","rc":[{"batb":[[0,3.95,10.05],[1,3.9,14.16],[2,1.04,1637.19]],"ltp":4.1,"tv":237.29,"id":12474498}]}]}
{"op":"mcm","clk":"11849440673","pt":1723667498761,"mc":[{"id":"1.231815703","rc":[{"batb":[[0,3.9,14.21],[1,1.04,1637.19],[2,1.03,2366.9]],"ltp":4.1,"tv":237.29,"id":12474498}]}]}
{"op":"mcm","clk":"11849440868","pt":1723667500929,"mc":[{"id":"1.231815703","rc":[{"batb":[[0,3.95,10.05],[1,3.9,14.16],[2,1.04,1637.19]],"ltp":4.1,"tv":237.29,"id":12474498}]}]}
{"op":"mcm","clk":"11849441126","pt":1723667504331,"mc":[{"id":"1.231815703","rc":[{"batb":[[0,3.9,14.21],[1,1.04,1637.19],[2,1.03,2366.9]],"ltp":4.1,"tv":237.29,"id":12474498}]}]}
{"op":"mcm","clk":"11849441293","pt":1723667506665,"mc":[{"id":"1.231815703","rc":[{"batb":[[0,3.95,10.05],[1,3.9,14.16],[2,1.04,1637.19]],"ltp":4.1,"tv":237.29,"id":12474498}]}]}
{"op":"mcm","clk":"11849441535","pt":1723667509824,"mc":[{"id":"1.231815703","rc":[{"batb":[[0,3.9,14.21],[1,1.04,1637.19],[2,1.03,2366.9]],"ltp":4.1,"tv":237.29,"id":12474498}]}]}
{"op":"mcm","clk":"11849441776","pt":1723667513175,"mc":[{"id":"1.231815703","rc":[{"batb":[[0,3.95,10.05],[1,3.9,14.16],[2,1.04,1637.19]],"ltp":4.1,"tv":237.29,"id":12474498}]}]}
{"op":"mcm","clk":"11849442008","pt":1723667516574,"mc":[{"id":"1.231815703","rc":[{"batb":[[0,3.9,14.21],[1,1.04,1637.19],[2,1.03,2366.9]],"ltp":4.1,"tv":237.29,"id":12474498}]}]}
{"op":"mcm","clk":"11849442173","pt":1723667518898,"mc":[{"id":"1.231815703","rc":[{"batb":[[0,3.95,10.05],[1,3.9,14.16],[2,1.04,1637.19]],"ltp":4.1,"tv":237.29,"id":12474498}]}]}
{"op":"mcm","clk":"11849442409","pt":1723667522099,"mc":[{"id":"1.231815703","rc":[{"batb":[[0,3.9,14.21],[1,1.04,1637.19],[2,1.03,2366.9]],"ltp":4.1,"tv":237.29,"id":12474498}]}]}
{"op":"mcm","clk":"11849442556","pt":1723667524274,"mc":[{"id":"1.231815703","rc":[{"batb":[[0,3.95,10.05],[1,3.9,14.16],[2,1.04,1637.19]],"ltp":4.1,"tv":237.29,"id":12474498}]}]}
{"op":"mcm","clk":"11849442802","pt":1723667527583,"mc":[{"id":"1.231815703","rc":[{"batb":[[0,3.9,14.21],[1,1.04,1637.19],[2,1.03,2366.9]],"ltp":4.1,"tv":237.29,"id":12474498}]}]}
{"op":"mcm","clk":"11849442960","pt":1723667529904,"mc":[{"id":"1.231815703","rc":[{"batb":[[0,3.95,10.05],[1,3.9,14.16],[2,1.04,1637.19]],"ltp":4.1,"tv":237.29,"id":12474498}]}]}
{"op":"mcm","clk":"11849443203","pt":1723667533154,"mc":[{"id":"1.231815703","rc":[{"batb":[[0,3.9,14.21],[1,1.04,1637.19],[2,1.03,2366.9]],"ltp":4.1,"tv":237.29,"id":12474498}]}]}
{"op":"mcm","clk":"11849443369","pt":1723667535376,"mc":[{"id":"1.231815703","rc":[{"batb":[[0,3.95,10.05],[1,3.9,14.16],[2,1.04,1637.19]],"ltp":4.1,"tv":237.29,"id":12474498}]}]}
{"op":"mcm","clk":"11849443572","pt":1723667538669,"mc":[{"id":"1.231815703","rc":[{"batb":[[0,3.9,14.21],[1,1.04,1637.19],[2,1.03,2366.9]],"ltp":4.1,"tv":237.29,"id":12474498}]}]}
{"op":"mcm","clk":"11849443731","pt":1723667541096,"mc":[{"id":"1.231815703","rc":[{"batb":[[0,3.95,10.05],[1,3.9,14.16],[2,1.04,1637.19]],"ltp":4.1,"tv":237.29,"id":12474498}]}]}
{"op":"mcm","clk":"11849443949","pt":1723667544391,"mc":[{"id":"1.231815703","rc":[{"batb":[[0,3.9,14.21],[1,1.04,1637.19],[2,1.03,2366.9]],"ltp":4.1,"tv":237.29,"id":12474498}]}]}
{"op":"mcm","clk":"11849444117","pt":1723667546609,"mc":[{"id":"1.231815703","rc":[{"batb":[[0,3.95,10.05],[1,3.9,14.16],[2,1.04,1637.19]],"ltp":4.1,"tv":237.29,"id":12474498}]}]}
{"op":"mcm","clk":"11849444362","pt":1723667549909,"mc":[{"id":"1.231815703","rc":[{"batb":[[0,3.9,14.21],[1,1.04,1637.19],[2,1.03,2366.9]],"ltp":4.1,"tv":237.29,"id":12474498}]}]}
{"op":"mcm","clk":"11849444541","pt":1723667552327,"mc":[{"id":"1.231815703","rc":[{"batb":[[0,3.95,10.05],[1,3.9,14.16],[2,1.04,1637.19]],"ltp":4.1,"tv":237.29,"id":12474498}]}]}
{"op":"mcm","clk":"11849444771","pt":1723667555726,"mc":[{"id":"1.231815703","rc":[{"batb":[[0,3.9,14.21],[1,1.04,1637.19],[2,1.03,2366.9]],"ltp":4.1,"tv":237.29,"id":12474498}]}]}
{"op":"mcm","clk":"11849444939","pt":1723667558102,"mc":[{"id":"1.231815703","rc":[{"batb":[[0,3.95,10.05],[1,3.9,14.16],[2,1.04,1637.19]],"ltp":4.1,"tv":237.29,"id":12474498}]}]}
{"op":"mcm","clk":"11849445144","pt":1723667561558,"mc":[{"id":"1.231815703","rc":[{"batb":[[0,3.9,14.21],[1,1.04,1637.19],[2,1.03,2366.9]],"ltp":4.1,"tv":237.29,"id":12474498}]}]}
{"op":"mcm","clk":"11849445396","pt":1723667564703,"mc":[{"id":"1.231815703","rc":[{"batb":[[0,3.95,10.05],[1,3.9,14.16],[2,1.04,1637.19]],"ltp":4.1,"tv":237.29,"id":12474498}]}]}
{"op":"mcm","clk":"11849445635","pt":1723667568217,"mc":[{"id":"1.231815703","rc":[{"batb":[[0,3.9,14.21],[1,1.04,1637.19],[2,1.03,2366.9]],"ltp":4.1,"tv":237.29,"id":12474498}]}]}
{"op":"mcm","clk":"11849445772","pt":1723667570535,"mc":[{"id":"1.231815703","rc":[{"batb":[[0,3.95,10.05],[1,3.9,14.16],[2,1.04,1637.19]],"ltp":4.1,"tv":237.29,"id":12474498}]}]}
{"op":"mcm","clk":"11849445997","pt":1723667573831,"mc":[{"id":"1.231815703","rc":[{"batb":[[0,3.9,14.21],[1,1.04,1637.19],[2,1.03,2366.9]],"ltp":4.1,"tv":237.29,"id":12474498}]}]}
{"op":"mcm","clk":"11849446152","pt":1723667576145,"mc":[{"id":"1.231815703","rc":[{"batb":[[0,3.95,10.05],[1,3.9,14.16],[2,1.04,1637.19]],"ltp":4.1,"tv":237.29,"id":12474498}]}]}
{"op":"mcm","clk":"11849446367","pt":1723667579436,"mc":[{"id":"1.231815703","rc":[{"batb":[[0,3.9,14.21],[1,1.04,1637.19],[2,1.03,2366.9]],"ltp":4.1,"tv":237.29,"id":12474498}]}]}
{"op":"mcm","clk":"11849446665","pt":1723667583822,"mc":[{"id":"1.231815703","rc":[{"batb":[[0,3.95,10.05],[1,3.9,14.16],[2,1.04,1637.19]],"ltp":4.1,"tv":237.29,"id":12474498}]}]}
{"op":"mcm","clk":"11849446877","pt":1723667587170,"mc":[{"id":"1.231815703","rc":[{"batb":[[0,3.9,14.21],[1,1.04,1637.19],[2,1.03,2366.9]],"ltp":4.1,"tv":237.29,"id":12474498}]}]}
{"op":"mcm","clk":"11849447040","pt":1723667589438,"mc":[{"id":"1.231815703","rc":[{"batb":[[0,3.95,10.05],[1,3.9,14.16],[2,1.04,1637.19]],"ltp":4.1,"tv":237.29,"id":12474498}]}]}
{"op":"mcm","clk":"11849447288","pt":1723667592950,"mc":[{"id":"1.231815703","rc":[{"batb":[[0,3.9,14.21],[1,1.04,1637.19],[2,1.03,2366.9]],"ltp":4.1,"tv":237.29,"id":12474498}]}]}
{"op":"mcm","clk":"11849447539","pt":1723667596888,"mc":[{"id":"1.231815703","rc":[{"batb":[[0,3.95,10.05],[1,3.9,14.16],[2,1.04,1637.19]],"ltp":4.1,"tv":237.29,"id":12474498}]}]}
{"op":"mcm","clk":"11849447789","pt":1723667600150,"mc":[{"id":"1.231815703","rc":[{"batb":[[0,3.9,14.21],[1,1.04,1637.19],[2,1.03,2366.9]],"ltp":4.1,"tv":237.29,"id":12474498}]}]}
{"op":"mcm","clk":"11849447929","pt":1723667602471,"mc":[{"id":"1.231815703","rc":[{"batb":[[0,3.95,10.05],[1,3.9,14.16],[2,1.04,1637.19]],"ltp":4.1,"tv":237.29,"id":12474498}]}]}
{"op":"mcm","clk":"11849448159","pt":1723667605674,"mc":[{"id":"1.231815703","rc":[{"batb":[[0,3.9,14.21],[1,1.04,1637.19],[2,1.03,2366.9]],"ltp":4.1,"tv":237.29,"id":12474498}]}]}
{"op":"mcm","clk":"11849448372","pt":1723667608298,"mc":[{"id":"1.231815703","rc":[{"batb":[[0,3.95,10.05],[1,3.9,14.16],[2,1.04,1637.19]],"ltp":4.1,"tv":237.29,"id":12474498}]}]}
{"op":"mcm","clk":"11849448573","pt":1723667611594,"mc":[{"id":"1.231815703","rc":[{"batb":[[0,3.9,14.21],[1,1.04,1637.19],[2,1.03,2366.9]],"ltp":4.1,"tv":237.29,"id":12474498}]}]}
{"op":"mcm","clk":"11849448717","pt":1723667613960,"mc":[{"id":"1.231815703","rc":[{"batb":[[0,3.95,10.05],[1,3.9,14.16],[2,1.04,1637.19]],"ltp":4.1,"tv":237.29,"id":12474498}]}]}
{"op":"mcm","clk":"11849448938","pt":1723667617308,"mc":[{"id":"1.231815703","rc":[{"batb":[[0,3.9,14.21],[1,1.04,1637.19],[2,1.03,2366.9]],"ltp":4.1,"tv":237.29,"id":12474498}]}]}
{"op":"mcm","clk":"11849449078","pt":1723667619580,"mc":[{"id":"1.231815703","rc":[{"batb":[[0,3.95,10.05],[1,3.9,14.16],[2,1.04,1637.19]],"ltp":4.1,"tv":237.29,"id":12474498}]}]}
{"op":"mcm","clk":"11849449271","pt":1723667622879,"mc":[{"id":"1.231815703","rc":[{"batb":[[0,3.9,14.21],[1,1.04,1637.19],[2,1.03,2366.9]],"ltp":4.1,"tv":237.29,"id":12474498}]}]}
{"op":"mcm","clk":"11849449423","pt":1723667625092,"mc":[{"id":"1.231815703","rc":[{"batb":[[0,3.95,10.05],[1,3.9,14.16],[2,1.04,1637.19]],"ltp":4.1,"tv":237.29,"id":12474498}]}]}
{"op":"mcm","clk":"11849449666","pt":1723667628504,"mc":[{"id":"1.231815703","rc":[{"batb":[[0,3.9,14.21],[1,1.04,1637.19],[2,1.03,2366.9]],"ltp":4.1,"tv":237.29,"id":12474498}]}]}
{"op":"mcm","clk":"11849449828","pt":1723667630823,"mc":[{"id":"1.231815703","rc":[{"batb":[[0,3.95,10.05],[1,3.9,14.16],[2,1.04,1637.19]],"ltp":4.1,"tv":237.29,"id":12474498}]}]}
{"op":"mcm","clk":"11849450057","pt":1723667634198,"mc":[{"id":"1.231815703","rc":[{"batb":[[0,3.9,14.21],[1,1.04,1637.19],[2,1.03,2366.9]],"ltp":4.1,"tv":237.29,"id":12474498}]}]}
{"op":"mcm","clk":"11849450217","pt":1723667636616,"mc":[{"id":"1.231815703","rc":[{"batb":[[0,3.95,10.05],[1,3.9,14.16],[2,1.04,1637.19]],"ltp":4.1,"tv":237.29,"id":12474498}]}]}
{"op":"mcm","clk":"11849450447","pt":1723667640026,"mc":[{"id":"1.231815703","rc":[{"batb":[[0,3.9,14.21],[1,1.04,1637.19],[2,1.03,2366.9]],"ltp":4.1,"tv":237.29,"id":12474498}]}]}
{"op":"mcm","clk":"11849450659","pt":1723667642305,"mc":[{"id":"1.231815703","rc":[{"batb":[[0,3.95,10.05],[1,3.9,14.16],[2,1.04,1637.19]],"ltp":4.1,"tv":237.29,"id":12474498}]}]}
{"op":"mcm","clk":"11849450897","pt":1723667645609,"mc":[{"id":"1.231815703","rc":[{"batb":[[0,3.9,14.21],[1,1.04,1637.19],[2,1.03,2366.9]],"ltp":4.1,"tv":237.29,"id":12474498}]}]}
{"op":"mcm","clk":"11849451022","pt":1723667648026,"mc":[{"id":"1.231815703","rc":[{"batb":[[0,3.95,10.05],[1,3.9,14.16],[2,1.04,1637.19]],"ltp":4.1,"tv":237.29,"id":12474498}]}]}
{"op":"mcm","clk":"11849451237","pt":1723667651431,"mc":[{"id":"1.231815703","rc":[{"batb":[[0,3.9,14.21],[1,1.04,1637.19],[2,1.03,2366.9]],"ltp":4.1,"tv":237.29,"id":12474498}]}]}
{"op":"mcm","clk":"11849451401","pt":1723667653845,"mc":[{"id":"1.231815703","rc":[{"batb":[[0,3.95,10.05],[1,3.9,14.16],[2,1.04,1637.19]],"ltp":4.1,"tv":237.29,"id":12474498}]}]}
{"op":"mcm","clk":"11849451641","pt":1723667657047,"mc":[{"id":"1.231815703","rc":[{"batb":[[0,3.9,14.21],[1,1.04,1637.19],[2,1.03,2366.9]],"ltp":4.1,"tv":237.29,"id":12474498}]}]}
{"op":"mcm","clk":"11849451790","pt":1723667659320,"mc":[{"id":"1.231815703","rc":[{"batb":[[0,3.95,10.05],[1,3.9,14.16],[2,1.04,1637.19]],"ltp":4.1,"tv":237.29,"id":12474498}]}]}
{"op":"mcm","clk":"11849452031","pt":1723667662614,"mc":[{"id":"1.231815703","rc":[{"batb":[[0,3.9,14.21],[1,1.04,1637.19],[2,1.03,2366.9]],"ltp":4.1,"tv":237.29,"id":12474498}]}]}
{"op":"mcm","clk":"11849452185","pt":1723667664927,"mc":[{"id":"1.231815703","rc":[{"batb":[[0,3.95,10.05],[1,3.9,14.16],[2,1.04,1637.19]],"ltp":4.1,"tv":237.29,"id":12474498}]}]}
{"op":"mcm","clk":"11849452425","pt":1723667668244,"mc":[{"id":"1.231815703","rc":[{"batb":[[0,3.9,14.21],[1,1.04,1637.19],[2,1.03,2366.9]],"ltp":4.1,"tv":237.29,"id":12474498}]}]}
{"op":"mcm","clk":"11849452601","pt":1723667670526,"mc":[{"id":"1.231815703","rc":[{"batb":[[0,3.95,10.05],[1,3.9,14.16],[2,1.04,1637.19]],"ltp":4.1,"tv":237.29,"id":12474498}]}]}
{"op":"mcm","clk":"11849452820","pt":1723667673862,"mc":[{"id":"1.231815703","rc":[{"batb":[[0,3.9,14.21],[1,1.04,1637.19],[2,1.03,2366.9]],"ltp":4.1,"tv":237.29,"id":12474498}]}]}
{"op":"mcm","clk":"11849453008","pt":1723667676342,"mc":[{"id":"1.231815703","rc":[{"batb":[[0,3.95,10.05],[1,3.9,14.16],[2,1.04,1637.19]],"ltp":4.1,"tv":237.29,"id":12474498}]}]}
{"op":"mcm","clk":"11849453232","pt":1723667679740,"mc":[{"id":"1.231815703","rc":[{"batb":[[0,3.9,14.21],[1,1.04,1637.19],[2,1.03,2366.9]],"ltp":4.1,"tv":237.29,"id":12474498}]}]}
{"op":"mcm","clk":"11849453400","pt":1723667682054,"mc":[{"id":"1.231815703","rc":[{"batb":[[0,3.95,10.05],[1,3.9,14.16],[2,1.04,1637.19]],"ltp":4.1,"tv":237.29,"id":12474498}]}]}
{"op":"mcm","clk":"11849453660","pt":1723667685347,"mc":[{"id":"1.231815703","rc":[{"batb":[[0,3.9,14.21],[1,1.04,1637.19],[2,1.03,2366.9]],"ltp":4.1,"tv":237.29,"id":12474498}]}]}
{"op":"mcm","clk":"11849453821","pt":1723667687662,"mc":[{"id":"1.231815703","rc":[{"batb":[[0,3.95,10.05],[1,3.9,14.16],[2,1.04,1637.19]],"ltp":4.1,"tv":237.29,"id":12474498}]}]}
{"op":"mcm","clk":"11849454034","pt":1723667690961,"mc":[{"id":"1.231815703","rc":[{"batb":[[0,3.9,14.21],[1,1.04,1637.19],[2,1.03,2366.9]],"ltp":4.1,"tv":237.29,"id":12474498}]}]}
{"op":"mcm","clk":"11849454229","pt":1723667693851,"mc":[{"id":"1.231815703","rc":[{"batb":[[0,3.95,10.05],[1,3.9,14.16],[2,1.04,1637.19]],"ltp":4.1,"tv":237.29,"id":12474498}]}]}
{"op":"mcm","clk":"11849454441","pt":1723667697349,"mc":[{"id":"1.231815703","rc":[{"batb":[[0,3.9,14.21],[1,1.04,1637.19],[2,1.03,2366.9]],"ltp":4.1,"tv":237.29,"id":12474498}]}]}
{"op":"mcm","clk":"11849454555","pt":1723667699448,"mc":[{"id":"1.231815703","rc":[{"batb":[[0,3.95,10.05],[1,3.9,14.16],[2,1.04,1637.19]],"ltp":4.1,"tv":237.29,"id":12474498}]}]}
{"op":"mcm","clk":"11849454771","pt":1723667702756,"mc":[{"id":"1.231815703","rc":[{"batb":[[0,3.9,14.21],[1,1.04,1637.19],[2,1.03,2366.9]],"ltp":4.1,"tv":237.29,"id":12474498}]}]}
{"op":"mcm","clk":"11849454929","pt":1723667705170,"mc":[{"id":"1.231815703","rc":[{"batb":[[0,3.95,10.05],[1,3.9,14.16],[2,1.04,1637.19]],"ltp":4.1,"tv":237.29,"id":12474498}]}]}
{"op":"mcm","clk":"11849455142","pt":1723667708616,"mc":[{"id":"1.231815703","rc":[{"batb":[[0,3.9,14.21],[1,1.04,1637.19],[2,1.03,2366.9]],"ltp":4.1,"tv":237.29,"id":12474498}]}]}
{"op":"mcm","clk":"11849455281","pt":1723667710886,"mc":[{"id":"1.231815703","rc":[{"batb":[[0,3.95,10.05],[1,3.9,14.16],[2,1.04,1637.19]],"ltp":4.1,"tv":237.29,"id":12474498}]}]}
{"op":"mcm","clk":"11849455498","pt":1723667714402,"mc":[{"id":"1.231815703","rc":[{"batb":[[0,3.9,14.21],[1,1.04,1637.19],[2,1.03,2366.9]],"ltp":4.1,"tv":237.29,"id":12474498}]}]}
{"op":"mcm","clk":"11849455668","pt":1723667716769,"mc":[{"id":"1.231815703","rc":[{"batb":[[0,3.95,10.05],[1,3.9,14.16],[2,1.04,1637.19]],"ltp":4.1,"tv":237.29,"id":12474498}]}]}
{"op":"mcm","clk":"11849455882","pt":1723667720184,"mc":[{"id":"1.231815703","rc":[{"batb":[[0,3.9,14.21],[1,1.04,1637.19],[2,1.03,2366.9]],"ltp":4.1,"tv":237.29,"id":12474498}]}]}
{"op":"mcm","clk":"11849456033","pt":1723667722395,"mc":[{"id":"1.231815703","rc":[{"batb":[[0,3.95,10.05],[1,3.9,14.16],[2,1.04,1637.19]],"ltp":4.1,"tv":237.29,"id":12474498}]}]}
{"op":"mcm","clk":"11849456253","pt":1723667725693,"mc":[{"id":"1.231815703","rc":[{"batb":[[0,3.9,14.21],[1,1.04,1637.19],[2,1.03,2366.9]],"ltp":4.1,"tv":237.29,"id":12474498}]}]}
{"op":"mcm","clk":"11849456389","pt":1723667728074,"mc":[{"id":"1.231815703","rc":[{"batb":[[0,3.95,10.05],[1,3.9,14.16],[2,1.04,1637.19]],"ltp":4.1,"tv":237.29,"id":12474498}]}]}
{"op":"mcm","clk":"11849456608","pt":1723667731412,"mc":[{"id":"1.231815703","rc":[{"batb":[[0,3.9,14.21],[1,1.04,1637.19],[2,1.03,2366.9]],"ltp":4.1,"tv":237.29,"id":12474498}]}]}
{"op":"mcm","clk":"11849456828","pt":1723667734501,"mc":[{"id":"1.231815703","rc":[{"batb":[[0,3.95,10.05],[1,3.9,14.16],[2,1.04,1637.19]],"ltp":4.1,"tv":237.29,"id":12474498}]}]}
{"op":"mcm","clk":"11849457041","pt":1723667737693,"mc":[{"id":"1.231815703","rc":[{"batb":[[0,3.9,14.21],[1,1.04,1637.19],[2,1.03,2366.9]],"ltp":4.1,"tv":237.29,"id":12474498}]}]}
{"op":"mcm","clk":"11849457171","pt":1723667740008,"mc":[{"id":"1.231815703","rc":[{"batb":[[0,3.95,10.05],[1,3.9,14.16],[2,1.04,1637.19]],"ltp":4.1,"tv":237.29,"id":12474498}]}]}
{"op":"mcm","clk":"11849457404","pt":1723667743300,"mc":[{"id":"1.231815703","rc":[{"batb":[[0,3.9,14.21],[1,1.04,1637.19],[2,1.03,2366.9]],"ltp":4.1,"tv":237.29,"id":12474498}]}]}
{"op":"mcm","clk":"11849457562","pt":1723667745722,"mc":[{"id":"1.231815703","rc":[{"batb":[[0,3.95,10.05],[1,3.9,14.16],[2,1.04,1637.19]],"ltp":4.1,"tv":237.29,"id":12474498}]}]}
{"op":"mcm","clk":"11849457798","pt":1723667749117,"mc":[{"id":"1.231815703","rc":[{"batb":[[0,3.9,14.21],[1,1.04,1637.19],[2,1.03,2366.9]],"ltp":4.1,"tv":237.29,"id":12474498}]}]}
{"op":"mcm","clk":"11849457940","pt":1723667751324,"mc":[{"id":"1.231815703","rc":[{"batb":[[0,3.95,10.05],[1,3.9,14.16],[2,1.04,1637.19]],"ltp":4.1,"tv":237.29,"id":12474498}]}]}
{"op":"mcm","clk":"11849458182","pt":1723667754833,"mc":[{"id":"1.231815703","rc":[{"batb":[[0,3.9,14.21],[1,1.04,1637.19],[2,1.03,2366.9]],"ltp":4.1,"tv":237.29,"id":12474498}]}]}
{"op":"mcm","clk":"11849458322","pt":1723667757107,"mc":[{"id":"1.231815703","rc":[{"batb":[[0,3.95,10.05],[1,3.9,14.16],[2,1.04,1637.19]],"ltp":4.1,"tv":237.29,"id":12474498}]}]}
{"op":"mcm","clk":"11849458532","pt":1723667760505,"mc":[{"id":"1.231815703","rc":[{"batb":[[0,3.9,14.21],[1,1.04,1637.19],[2,1.03,2366.9]],"ltp":4.1,"tv":237.29,"id":12474498}]}]}
{"op":"mcm","clk":"11849458706","pt":1723667763047,"mc":[{"id":"1.231815703","rc":[{"batb":[[0,3.95,10.05],[1,3.9,14.16],[2,1.04,1637.19]],"ltp":4.1,"tv":237.29,"id":12474498}]}]}
{"op":"mcm","clk":"11849458959","pt":1723667766516,"mc":[{"id":"1.231815703","rc":[{"batb":[[0,3.9,14.21],[1,1.04,1637.19],[2,1.03,2366.9]],"ltp":4.1,"tv":237.29,"id":12474498}]}]}
{"op":"mcm","clk":"11849459095","pt":1723667768625,"mc":[{"id":"1.231815703","rc":[{"batb":[[0,3.95,10.05],[1,3.9,14.16],[2,1.04,1637.19]],"ltp":4.1,"tv":237.29,"id":12474498}]}]}
{"op":"mcm","clk":"11849459311","pt":1723667772132,"mc":[{"id":"1.231815703","rc":[{"batb":[[0,3.9,14.21],[1,1.04,1637.19],[2,1.03,2366.9]],"ltp":4.1,"tv":237.29,"id":12474498}]}]}
{"op":"mcm","clk":"11849459451","pt":1723667774245,"mc":[{"id":"1.231815703","rc":[{"batb":[[0,3.95,10.05],[1,3.9,14.16],[2,1.04,1637.19]],"ltp":4.1,"tv":237.29,"id":12474498}]}]}
{"op":"mcm","clk":"11849459635","pt":1723667777742,"mc":[{"id":"1.231815703","rc":[{"batb":[[0,3.9,14.21],[1,1.04,1637.19],[2,1.03,2366.9]],"ltp":4.1,"tv":237.29,"id":12474498}]}]}
{"op":"mcm","clk":"11849459772","pt":1723667779960,"mc":[{"id":"1.231815703","rc":[{"batb":[[0,3.95,10.05],[1,3.9,14.16],[2,1.04,1637.19]],"ltp":4.1,"tv":237.29,"id":12474498}]}]}
{"op":"mcm","clk":"11849460010","pt":1723667783421,"mc":[{"id":"1.231815703","rc":[{"batb":[[0,3.9,14.21],[1,1.04,1637.19],[2,1.03,2366.9]],"ltp":4.1,"tv":237.29,"id":12474498}]}]}
{"op":"mcm","clk":"11849460108","pt":1723667785633,"mc":[{"id":"1.231815703","rc":[{"batb":[[0,3.95,10.05],[1,3.9,14.16],[2,1.04,1637.19]],"ltp":4.1,"tv":237.29,"id":12474498}]}]}
{"op":"mcm","clk":"11849460296","pt":1723667789070,"mc":[{"id":"1.231815703","rc":[{"batb":[[0,3.9,14.21],[1,1.04,1637.19],[2,1.03,2366.9]],"ltp":4.1,"tv":237.29,"id":12474498}]}]}
{"op":"mcm","clk":"11849460462","pt":1723667791952,"mc":[{"id":"1.231815703","rc":[{"batb":[[0,3.95,10.05],[1,3.9,14.16],[2,1.04,1637.19]],"ltp":4.1,"tv":237.29,"id":12474498}]}]}
{"op":"mcm","clk":"11849460685","pt":1723667795251,"mc":[{"id":"1.231815703","rc":[{"batb":[[0,3.9,14.21],[1,1.04,1637.19],[2,1.03,2366.9]],"ltp":4.1,"tv":237.29,"id":12474498}]}]}
{"op":"mcm","clk":"11849460857","pt":1723667797567,"mc":[{"id":"1.231815703","rc":[{"batb":[[0,3.95,10.05],[1,3.9,14.16],[2,1.04,1637.19]],"ltp":4.1,"tv":237.29,"id":12474498}]}]}
{"op":"mcm","clk":"11849461069","pt":1723667800838,"mc":[{"id":"1.231815703","rc":[{"batb":[[0,3.9,14.21],[1,1.04,1637.19],[2,1.03,2366.9]],"ltp":4.1,"tv":237.29,"id":12474498}]}]}
{"op":"mcm","clk":"11849461243","pt":1723667803664,"mc":[{"id":"1.231815703","rc":[{"batb":[[0,3.95,10.05],[1,3.9,14.16],[2,1.04,1637.19]],"ltp":4.1,"tv":237.29,"id":12474498}]}]}
{"op":"mcm","clk":"11849461451","pt":1723667806953,"mc":[{"id":"1.231815703","rc":[{"batb":[[0,3.9,14.21],[1,1.04,1637.19],[2,1.03,2366.9]],"ltp":4.1,"tv":237.29,"id":12474498}]}]}
{"op":"mcm","clk":"11849461577","pt":1723667809158,"mc":[{"id":"1.231815703","rc":[{"batb":[[0,3.95,10.05],[1,3.9,14.16],[2,1.04,1637.19]],"ltp":4.1,"tv":237.29,"id":12474498}]}]}
{"op":"mcm","clk":"11849461767","pt":1723667812491,"mc":[{"id":"1.231815703","rc":[{"batb":[[0,3.9,14.21],[1,1.04,1637.19],[2,1.03,2366.9]],"ltp":4.1,"tv":237.29,"id":12474498}]}]}
{"op":"mcm","clk":"11849461888","pt":1723667814593,"mc":[{"id":"1.231815703","rc":[{"batb":[[0,3.95,10.05],[1,3.9,14.16],[2,1.04,1637.19]],"ltp":4.1,"tv":237.29,"id":12474498}]}]}
{"op":"mcm","clk":"11849462071","pt":1723667817789,"mc":[{"id":"1.231815703","rc":[{"batb":[[0,3.9,14.21],[1,1.04,1637.19],[2,1.03,2366.9]],"ltp":4.1,"tv":237.29,"id":12474498}]}]}
{"op":"mcm","clk":"11849462212","pt":1723667819902,"mc":[{"id":"1.231815703","rc":[{"batb":[[0,3.95,10.05],[1,3.9,14.16],[2,1.04,1637.19]],"ltp":4.1,"tv":237.29,"id":12474498}]}]}
{"op":"mcm","clk":"11849462437","pt":1723667823206,"mc":[{"id":"1.231815703","rc":[{"batb":[[0,3.9,14.21],[1,1.04,1637.19],[2,1.03,2366.9]],"ltp":4.1,"tv":237.29,"id":12474498}]}]}
{"op":"mcm","clk":"11849462601","pt":1723667825886,"mc":[{"id":"1.231815703","rc":[{"batb":[[0,3.95,10.05],[1,3.9,14.16],[2,1.04,1637.19]],"ltp":4.1,"tv":237.29,"id":12474498}]}]}
{"op":"mcm","clk":"11849462820","pt":1723667829190,"mc":[{"id":"1.231815703","rc":[{"batb":[[0,3.9,14.21],[1,1.04,1637.19],[2,1.03,2366.9]],"ltp":4.1,"tv":237.29,"id":12474498}]}]}
{"op":"mcm","clk":"11849462955","pt":1723667831507,"mc":[{"id":"1.231815703","rc":[{"batb":[[0,3.95,10.05],[1,3.9,14.16],[2,1.04,1637.19]],"ltp":4.1,"tv":237.29,"id":12474498}]}]}
{"op":"mcm","clk":"11849463160","pt":1723667834923,"mc":[{"id":"1.231815703","rc":[{"batb":[[0,3.9,14.21],[1,1.04,1637.19],[2,1.03,2366.9]],"ltp":4.1,"tv":237.29,"id":12474498}]}]}
{"op":"mcm","clk":"11849463271","pt":1723667837297,"mc":[{"id":"1.231815703","rc":[{"batb":[[0,3.95,10.05],[1,3.9,14.16],[2,1.04,1637.19]],"ltp":4.1,"tv":237.29,"id":12474498}]}]}
{"op":"mcm","clk":"11849463462","pt":1723667840808,"mc":[{"id":"1.231815703","rc":[{"batb":[[0,3.9,14.21],[1,1.04,1637.19],[2,1.03,2366.9]],"ltp":4.1,"tv":237.29,"id":12474498}]}]}
{"op":"mcm","clk":"11849463629","pt":1723667844108,"mc":[{"id":"1.231815703","rc":[{"batb":[[0,3.95,10.05],[1,3.9,14.16],[2,1.04,1637.19]],"ltp":4.1,"tv":237.29,"id":12474498}]}]}
{"op":"mcm","clk":"11849463856","pt":1723667847525,"mc":[{"id":"1.231815703","rc":[{"batb":[[0,3.9,14.21],[1,1.04,1637.19],[2,1.03,2366.9]],"ltp":4.1,"tv":237.29,"id":12474498}]}]}
{"op":"mcm","clk":"11849463985","pt":1723667849802,"mc":[{"id":"1.231815703","rc":[{"batb":[[0,3.95,10.05],[1,3.9,14.16],[2,1.04,1637.19]],"ltp":4.1,"tv":237.29,"id":12474498}]}]}
{"op":"mcm","clk":"11849464191","pt":1723667853145,"mc":[{"id":"1.231815703","rc":[{"batb":[[0,3.9,14.21],[1,1.04,1637.19],[2,1.03,2366.9]],"ltp":4.1,"tv":237.29,"id":12474498}]}]}
{"op":"mcm","clk":"11849464352","pt":1723667855519,"mc":[{"id":"1.231815703","rc":[{"batb":[[0,3.95,10.05],[1,3.9,14.16],[2,1.04,1637.19]],"ltp":4.1,"tv":237.29,"id":12474498}]}]}
{"op":"mcm","clk":"11849464538","pt":1723667858811,"mc":[{"id":"1.231815703","rc":[{"batb":[[0,3.9,14.21],[1,1.04,1637.19],[2,1.03,2366.9]],"ltp":4.1,"tv":237.29,"id":12474498}]}]}
{"op":"mcm","clk":"11849464686","pt":1723667861122,"mc":[{"id":"1.231815703","rc":[{"batb":[[0,3.95,10.05],[1,3.9,14.16],[2,1.04,1637.19]],"ltp":4.1,"tv":237.29,"id":12474498}]}]}
{"op":"mcm","clk":"11849464864","pt":1723667864521,"mc":[{"id":"1.231815703","rc":[{"batb":[[0,3.9,14.21],[1,1.04,1637.19],[2,1.03,2366.9]],"ltp":4.1,"tv":237.29,"id":12474498}]}]}
{"op":"mcm","clk":"11849464964","pt":1723667866938,"mc":[{"id":"1.231815703","rc":[{"batb":[[0,3.95,10.05],[1,3.9,14.16],[2,1.04,1637.19]],"ltp":4.1,"tv":237.29,"id":12474498}]}]}
{"op":"mcm","clk":"11849465121","pt":1723667870271,"mc":[{"id":"1.231815703","rc":[{"batb":[[0,3.9,14.21],[1,1.04,1637.19],[2,1.03,2366.9]],"ltp":4.1,"tv":237.29,"id":12474498}]}]}
{"op":"mcm","clk":"11849465271","pt":1723667873048,"mc":[{"id":"1.231815703","rc":[{"batb":[[0,3.95,10.05],[1,3.9,14.16],[2,1.04,1637.19]],"ltp":4.1,"tv":237.29,"id":12474498}]}]}
{"op":"mcm","clk":"11849465520","pt":1723667876254,"mc":[{"id":"1.231815703","rc":[{"batb":[[0,3.9,14.21],[1,1.04,1637.19],[2,1.03,2366.9]],"ltp":4.1,"tv":237.29,"id":12474498}]}]}
{"op":"mcm","clk":"11849465727","pt":1723667878674,"mc":[{"id":"1.231815703","rc":[{"batb":[[0,3.95,10.05],[1,3.9,14.16],[2,1.04,1637.19]],"ltp":4.1,"tv":237.29,"id":12474498}]}]}
{"op":"mcm","clk":"11849465943","pt":1723667881970,"mc":[{"id":"1.231815703","rc":[{"batb":[[0,3.9,14.21],[1,1.04,1637.19],[2,1.03,2366.9]],"ltp":4.1,"tv":237.29,"id":12474498}]}]}
{"op":"mcm","clk":"11849466160","pt":1723667884750,"mc":[{"id":"1.231815703","rc":[{"batb":[[0,3.95,10.05],[1,3.9,14.16],[2,1.04,1637.19]],"ltp":4.1,"tv":237.29,"id":12474498}]}]}
{"op":"mcm","clk":"11849466478","pt":1723667888050,"mc":[{"id":"1.231815703","rc":[{"batb":[[0,3.9,14.21],[1,1.04,1637.19],[2,1.03,2366.9]],"ltp":4.1,"tv":237.29,"id":12474498}]}]}
{"op":"mcm","clk":"11849466728","pt":1723667891192,"mc":[{"id":"1.231815703","rc":[{"batb":[[0,3.95,10.05],[1,3.9,14.16],[2,1.04,1637.19]],"ltp":4.1,"tv":237.29,"id":12474498}]}]}
{"op":"mcm","clk":"11849466981","pt":1723667894491,"mc":[{"id":"1.231815703","rc":[{"batb":[[0,3.9,14.21],[1,1.04,1637.19],[2,1.03,2366.9]],"ltp":4.1,"tv":237.29,"id":12474498}]}]}
{"op":"mcm","clk":"11849467163","pt":1723667896800,"mc":[{"id":"1.231815703","rc":[{"batb":[[0,3.95,10.05],[1,3.9,14.16],[2,1.04,1637.19]],"ltp":4.1,"tv":237.29,"id":12474498}]}]}
{"op":"mcm","clk":"11849467501","pt":1723667900873,"mc":[{"id":"1.231815703","rc":[{"batb":[[0,3.9,14.21],[1,1.04,1637.19],[2,1.03,2366.9]],"ltp":4.1,"tv":237.29,"id":12474498}]}]}
{"op":"mcm","clk":"11849467706","pt":1723667903900,"mc":[{"id":"1.231815703","rc":[{"batb":[[0,3.95,10.05],[1,3.9,14.16],[2,1.04,1637.19]],"ltp":4.1,"tv":237.29,"id":12474498}]}]}
{"op":"mcm","clk":"11849467955","pt":1723667907204,"mc":[{"id":"1.231815703","rc":[{"batb":[[0,3.9,14.21],[1,1.04,1637.19],[2,1.03,2366.9]],"ltp":4.1,"tv":237.29,"id":12474498}]}]}
{"op":"mcm","clk":"11849468112","pt":1723667909610,"mc":[{"id":"1.231815703","rc":[{"batb":[[0,3.95,10.05],[1,3.9,14.16],[2,1.04,1637.19]],"ltp":4.1,"tv":237.29,"id":12474498}]}]}
{"op":"mcm","clk":"11849468348","pt":1723667912910,"mc":[{"id":"1.231815703","rc":[{"batb":[[0,3.9,14.21],[1,1.04,1637.19],[2,1.03,2366.9]],"ltp":4.1,"tv":237.29,"id":12474498}]}]}
{"op":"mcm","clk":"11849468513","pt":1723667914975,"mc":[{"id":"1.231815703","rc":[{"batb":[[0,3.95,10.05],[1,3.9,14.16],[2,1.04,1637.19]],"ltp":4.1,"tv":237.29,"id":12474498}]}]}
{"op":"mcm","clk":"11849468733","pt":1723667918304,"mc":[{"id":"1.231815703","rc":[{"batb":[[0,3.9,14.21],[1,1.04,1637.19],[2,1.03,2366.9]],"ltp":4.1,"tv":237.29,"id":12474498}]}]}
{"op":"mcm","clk":"11849468871","pt":1723667920622,"mc":[{"id":"1.231815703","rc":[{"batb":[[0,3.95,10.05],[1,3.9,14.16],[2,1.04,1637.19]],"ltp":4.1,"tv":237.29,"id":12474498}]}]}
{"op":"mcm","clk":"11849469121","pt":1723667923928,"mc":[{"id":"1.231815703","rc":[{"batb":[[0,3.9,14.21],[1,1.04,1637.19],[2,1.03,2366.9]],"ltp":4.1,"tv":237.29,"id":12474498}]}]}
{"op":"mcm","clk":"11849469272","pt":1723667926103,"mc":[{"id":"1.231815703","rc":[{"batb":[[0,3.95,10.05],[1,3.9,14.16],[2,1.04,1637.19]],"ltp":4.1,"tv":237.29,"id":12474498}]}]}
{"op":"mcm","clk":"11849469466","pt":1723667929398,"mc":[{"id":"1.231815703","rc":[{"batb":[[0,3.9,14.21],[1,1.04,1637.19],[2,1.03,2366.9]],"ltp":4.1,"tv":237.29,"id":12474498}]}]}
{"op":"mcm","clk":"11849469609","pt":1723667931610,"mc":[{"id":"1.231815703","rc":[{"batb":[[0,3.95,10.05],[1,3.9,14.16],[2,1.04,1637.19]],"ltp":4.1,"tv":237.29,"id":12474498}]}]}
{"op":"mcm","clk":"11849469816","pt":1723667934805,"mc":[{"id":"1.231815703","rc":[{"batb":[[0,3.9,14.21],[1,1.04,1637.19],[2,1.03,2366.9]],"ltp":4.1,"tv":237.29,"id":12474498}]}]}
{"op":"mcm","clk":"11849469975","pt":1723667937324,"mc":[{"id":"1.231815703","rc":[{"batb":[[0,3.95,10.05],[1,3.9,14.16],[2,1.04,1637.19]],"ltp":4.1,"tv":237.29,"id":12474498}]}]}
{"op":"mcm","clk":"11849470178","pt":1723667940721,"mc":[{"id":"1.231815703","rc":[{"batb":[[0,3.9,14.21],[1,1.04,1637.19],[2,1.03,2366.9]],"ltp":4.1,"tv":237.29,"id":12474498}]}]}
{"op":"mcm","clk":"11849470331","pt":1723667942938,"mc":[{"id":"1.231815703","rc":[{"batb":[[0,3.95,10.05],[1,3.9,14.16],[2,1.04,1637.19]],"ltp":4.1,"tv":237.29,"id":12474498}]}]}
{"op":"mcm","clk":"11849470429","pt":1723667944325,"mc":[{"id":"1.231815703","rc":[{"batb":[[2,1.1,1000]],"ltp":4.1,"tv":237.29,"id":12474498}]}]}
{"op":"mcm","clk":"11849470515","pt":1723667945514,"mc":[{"id":"1.231815703","rc":[{"batb":[[2,1.2,500]],"ltp":4.1,"tv":237.29,"id":12474498}]}]}
{"op":"mcm","clk":"11849470615","pt":1723667946857,"mc":[{"id":"1.231815703","rc":[{"batb":[[0,3.9,14.21],[1,1.2,500],[2,1.1,1000]],"ltp":4.1,"tv":237.29,"id":12474498},{"batb":[[2,1.26,14]],"ltp":1.33,"tv":823.36,"id":12482925}]}]}
{"op":"mcm","clk":"11849470635","pt":1723667947111,"mc":[{"id":"1.231815703","rc":[{"batb":[[1,1.33,303.03],[2,1.2,500]],"ltp":4.1,"tv":237.29,"id":12474498}]}]}
{"op":"mcm","clk":"11849470790","pt":1723667949630,"mc":[{"id":"1.231815703","rc":[{"batb":[[0,3.95,10.05],[1,3.9,14.16],[2,1.5,200]],"ltp":4.1,"tv":237.29,"id":12474498}]}]}
{"op":"mcm","clk":"11849471005","pt":1723667952831,"mc":[{"id":"1.231815703","rc":[{"batb":[[0,3.9,14.21],[1,1.5,200],[2,1.33,303.03]],"ltp":4.1,"tv":237.29,"id":12474498}]}]}
{"op":"mcm","clk":"11849471017","pt":1723667953035,"mc":[{"id":"1.231815703","rc":[{"batb":[[1,2,100],[2,1.5,200]],"ltp":4.1,"tv":237.29,"id":12474498}]}]}
{"op":"mcm","clk":"11849471171","pt":1723667955349,"mc":[{"id":"1.231815703","rc":[{"batb":[[0,3.95,10.05],[1,3.9,14.16],[2,2,100]],"ltp":4.1,"tv":237.29,"id":12474498}]}]}
{"op":"mcm","clk":"11849471408","pt":1723667958638,"mc":[{"id":"1.231815703","rc":[{"batb":[[0,3.9,14.21],[1,2,100],[2,1.5,200]],"ltp":4.1,"tv":237.29,"id":12474498}]}]}
{"op":"mcm","clk":"11849471586","pt":1723667961260,"mc":[{"id":"1.231815703","rc":[{"batb":[[0,3.95,10.05],[1,3.9,14.16],[2,2,100]],"ltp":4.1,"tv":237.29,"id":12474498}]}]}
{"op":"mcm","clk":"11849471803","pt":1723667964447,"mc":[{"id":"1.231815703","rc":[{"batb":[[0,3.9,14.21],[1,2,100],[2,1.5,200]],"ltp":4.1,"tv":237.29,"id":12474498}]}]}
{"op":"mcm","clk":"11849471955","pt":1723667966873,"mc":[{"id":"1.231815703","rc":[{"batb":[[0,3.95,10.05],[1,3.9,14.16],[2,2,100]],"ltp":4.1,"tv":237.29,"id":12474498}]}]}
{"op":"mcm","clk":"11849472184","pt":1723667970174,"mc":[{"id":"1.231815703","rc":[{"batb":[[0,3.9,14.21],[1,2,100],[2,1.5,200]],"ltp":4.1,"tv":237.29,"id":12474498}]}]}
{"op":"mcm","clk":"11849472355","pt":1723667972950,"mc":[{"id":"1.231815703","rc":[{"batb":[[0,3.95,10.05],[1,3.9,14.16],[2,2,100]],"ltp":4.1,"tv":237.29,"id":12474498}]}]}
{"op":"mcm","clk":"11849472591","pt":1723667976351,"mc":[{"id":"1.231815703","rc":[{"batb":[[0,3.9,14.21],[1,2,100],[2,1.5,200]],"ltp":4.1,"tv":237.29,"id":12474498}]}]}
{"op":"mcm","clk":"11849472738","pt":1723667978665,"mc":[{"id":"1.231815703","rc":[{"batb":[[0,3.95,10.05],[1,3.9,14.16],[2,2,100]],"ltp":4.1,"tv":237.29,"id":12474498}]}]}
{"op":"mcm","clk":"11849472950","pt":1723667981855,"mc":[{"id":"1.231815703","rc":[{"batb":[[0,3.9,14.21],[1,2,100],[2,1.5,200]],"ltp":4.1,"tv":237.29,"id":12474498}]}]}
{"op":"mcm","clk":"11849473099","pt":1723667984271,"mc":[{"id":"1.231815703","rc":[{"batb":[[0,3.95,10.05],[1,3.9,14.16],[2,2,100]],"ltp":4.1,"tv":237.29,"id":12474498}]}]}
{"op":"mcm","clk":"11849473307","pt":1723667987567,"mc":[{"id":"1.231815703","rc":[{"batb":[[0,3.9,14.21],[1,2,100],[2,1.5,200]],"ltp":4.1,"tv":237.29,"id":12474498}]}]}
{"op":"mcm","clk":"11849473483","pt":1723667990145,"mc":[{"id":"1.231815703","rc":[{"batb":[[0,3.95,10.05],[1,3.9,14.16],[2,2,100]],"ltp":4.1,"tv":237.29,"id":12474498}]}]}
{"op":"mcm","clk":"11849473678","pt":1723667993586,"mc":[{"id":"1.231815703","rc":[{"batb":[[0,3.9,14.21],[1,2,100],[2,1.5,200]],"ltp":4.1,"tv":237.29,"id":12474498}]}]}
{"op":"mcm","clk":"11849473801","pt":1723667995798,"mc":[{"id":"1.231815703","rc":[{"batb":[[0,3.95,10.05],[1,3.9,14.16],[2,2,100]],"ltp":4.1,"tv":237.29,"id":12474498}]}]}
{"op":"mcm","clk":"11849474021","pt":1723667999083,"mc":[{"id":"1.231815703","rc":[{"batb":[[0,3.9,14.21],[1,2,100],[2,1.5,200]],"ltp":4.1,"tv":237.29,"id":12474498}]}]}
{"op":"mcm","clk":"11849474204","pt":1723668001403,"mc":[{"id":"1.231815703","rc":[{"batb":[[0,3.95,10.05],[1,3.9,14.16],[2,2,100]],"ltp":4.1,"tv":237.29,"id":12474498}]}]}
{"op":"mcm","clk":"11849474436","pt":1723668004802,"mc":[{"id":"1.231815703","rc":[{"batb":[[0,3.9,14.21],[1,2,100],[2,1.5,200]],"ltp":4.1,"tv":237.29,"id":12474498}]}]}
{"op":"mcm","clk":"11849474580","pt":1723668007173,"mc":[{"id":"1.231815703","rc":[{"batb":[[0,3.95,10.05],[1,3.9,14.16],[2,2,100]],"ltp":4.1,"tv":237.29,"id":12474498}]}]}
{"op":"mcm","clk":"11849474809","pt":1723668010474,"mc":[{"id":"1.231815703","rc":[{"batb":[[0,3.9,14.21],[1,2,100],[2,1.5,200]],"ltp":4.1,"tv":237.29,"id":12474498}]}]}
{"op":"mcm","clk":"11849474968","pt":1723668012689,"mc":[{"id":"1.231815703","rc":[{"batb":[[0,3.95,10.05],[1,3.9,14.16],[2,2,100]],"ltp":4.1,"tv":237.29,"id":12474498}]}]}
{"op":"mcm","clk":"11849475166","pt":1723668015877,"mc":[{"id":"1.231815703","rc":[{"batb":[[0,3.9,14.21],[1,2,100],[2,1.5,200]],"ltp":4.1,"tv":237.29,"id":12474498}]}]}
{"op":"mcm","clk":"11849475327","pt":1723668018472,"mc":[{"id":"1.231815703","rc":[{"batb":[[0,3.95,10.05],[1,3.9,14.16],[2,2,100]],"ltp":4.1,"tv":237.29,"id":12474498}]}]}
{"op":"mcm","clk":"11849475538","pt":1723668021812,"mc":[{"id":"1.231815703","rc":[{"batb":[[0,3.9,14.21],[1,2,100],[2,1.5,200]],"ltp":4.1,"tv":237.29,"id":12474498}]}]}
{"op":"mcm","clk":"11849475762","pt":1723668024997,"mc":[{"id":"1.231815703","rc":[{"batb":[[0,3.95,10.05],[1,3.9,14.16],[2,2,100]],"ltp":4.1,"tv":237.29,"id":12474498}]}]}
{"op":"mcm","clk":"11849475988","pt":1723668028490,"mc":[{"id":"1.231815703","rc":[{"batb":[[0,3.9,14.21],[1,2,100],[2,1.5,200]],"ltp":4.1,"tv":237.29,"id":12474498}]}]}
{"op":"mcm","clk":"11849476148","pt":1723668030804,"mc":[{"id":"1.231815703","rc":[{"batb":[[0,3.95,10.05],[1,3.9,14.16],[2,2,100]],"ltp":4.1,"tv":237.29,"id":12474498}]}]}
{"op":"mcm","clk":"11849476340","pt":1723668033987,"mc":[{"id":"1.231815703","rc":[{"batb":[[0,3.9,14.21],[1,2,100],[2,1.5,200]],"ltp":4.1,"tv":237.29,"id":12474498}]}]}
{"op":"mcm","clk":"11849476501","pt":1723668036910,"mc":[{"id":"1.231815703","rc":[{"batb":[[0,3.95,10.05],[1,3.9,14.16],[2,2,100]],"ltp":4.1,"tv":237.29,"id":12474498}]}]}
{"op":"mcm","clk":"11849476711","pt":1723668040307,"mc":[{"id":"1.231815703","rc":[{"batb":[[0,3.9,14.21],[1,2,100],[2,1.5,200]],"ltp":4.1,"tv":237.29,"id":12474498}]}]}
{"op":"mcm","clk":"11849477041","pt":1723668045192,"mc":[{"id":"1.231815703","rc":[{"batb":[[0,3.95,10.05],[1,3.9,14.16],[2,2,100]],"ltp":4.1,"tv":237.29,"id":12474498}]}]}
{"op":"mcm","clk":"11849477288","pt":1723668048637,"mc":[{"id":"1.231815703","rc":[{"batb":[[0,3.9,14.21],[1,2,100],[2,1.5,200]],"ltp":4.1,"tv":237.29,"id":12474498}]}]}
{"op":"mcm","clk":"11849477433","pt":1723668050901,"mc":[{"id":"1.231815703","rc":[{"batb":[[0,3.95,10.05],[1,3.9,14.16],[2,2,100]],"ltp":4.1,"tv":237.29,"id":12474498}]}]}
{"op":"mcm","clk":"11849477616","pt":1723668054132,"mc":[{"id":"1.231815703","rc":[{"batb":[[0,3.9,14.21],[1,2,100],[2,1.5,200]],"ltp":4.1,"tv":237.29,"id":12474498}]}]}
{"op":"mcm","clk":"11849477754","pt":1723668056239,"mc":[{"id":"1.231815703","rc":[{"batb":[[0,3.95,10.05],[1,3.9,14.16],[2,2,100]],"ltp":4.1,"tv":237.29,"id":12474498}]}]}
{"op":"mcm","clk":"11849477987","pt":1723668059528,"mc":[{"id":"1.231815703","rc":[{"batb":[[0,3.9,14.21],[1,2,100],[2,1.5,200]],"ltp":4.1,"tv":237.29,"id":12474498}]}]}
{"op":"mcm","clk":"11849478148","pt":1723668061745,"mc":[{"id":"1.231815703","rc":[{"batb":[[0,3.95,10.05],[1,3.9,14.16],[2,2,100]],"ltp":4.1,"tv":237.29,"id":12474498}]}]}
{"op":"mcm","clk":"11849478392","pt":1723668065038,"mc":[{"id":"1.231815703","rc":[{"batb":[[0,3.9,14.21],[1,2,100],[2,1.5,200]],"ltp":4.1,"tv":237.29,"id":12474498}]}]}
{"op":"mcm","clk":"11849478522","pt":1723668067244,"mc":[{"id":"1.231815703","rc":[{"batb":[[0,3.95,10.05],[1,3.9,14.16],[2,2,100]],"ltp":4.1,"tv":237.29,"id":12474498}]}]}
{"op":"mcm","clk":"11849478751","pt":1723668070540,"mc":[{"id":"1.231815703","rc":[{"batb":[[0,3.9,14.21],[1,2,100],[2,1.5,200]],"ltp":4.1,"tv":237.29,"id":12474498}]}]}
{"op":"mcm","clk":"11849478921","pt":1723668072706,"mc":[{"id":"1.231815703","rc":[{"batb":[[0,3.95,10.05],[1,3.9,14.16],[2,2,100]],"ltp":4.1,"tv":237.29,"id":12474498}]}]}
{"op":"mcm","clk":"11849479153","pt":1723668075944,"mc":[{"id":"1.231815703","rc":[{"batb":[[0,3.9,14.21],[1,2,100],[2,1.5,200]],"ltp":4.1,"tv":237.29,"id":12474498}]}]}
{"op":"mcm","clk":"11849479338","pt":1723668078936,"mc":[{"id":"1.231815703","rc":[{"batb":[[0,3.95,10.05],[1,3.9,14.16],[2,2,100]],"ltp":4.1,"tv":237.29,"id":12474498}]}]}
{"op":"mcm","clk":"11849479563","pt":1723668082231,"mc":[{"id":"1.231815703","rc":[{"batb":[[0,3.9,14.21],[1,2,100],[2,1.5,200]],"ltp":4.1,"tv":237.29,"id":12474498}]}]}
{"op":"mcm","clk":"11849479733","pt":1723668084646,"mc":[{"id":"1.231815703","rc":[{"batb":[[0,3.95,10.05],[1,3.9,14.16],[2,2,100]],"ltp":4.1,"tv":237.29,"id":12474498}]}]}
{"op":"mcm","clk":"11849479950","pt":1723668088036,"mc":[{"id":"1.231815703","rc":[{"batb":[[0,3.9,14.21],[1,2,100],[2,1.5,200]],"ltp":4.1,"tv":237.29,"id":12474498}]}]}
{"op":"mcm","clk":"11849480178","pt":1723668091274,"mc":[{"id":"1.231815703","rc":[{"batb":[[0,3.95,10.05],[1,3.9,14.16],[2,2,100]],"ltp":4.1,"tv":237.29,"id":12474498}]}]}
{"op":"mcm","clk":"11849480381","pt":1723668094570,"mc":[{"id":"1.231815703","rc":[{"batb":[[0,3.9,14.21],[1,2,100],[2,1.5,200]],"ltp":4.1,"tv":237.29,"id":12474498}]}]}
{"op":"mcm","clk":"11849480509","pt":1723668096883,"mc":[{"id":"1.231815703","rc":[{"batb":[[0,3.95,10.05],[1,3.9,14.16],[2,2,100]],"ltp":4.1,"tv":237.29,"id":12474498}]}]}
{"op":"mcm","clk":"11849480708","pt":1723668100070,"mc":[{"id":"1.231815703","rc":[{"batb":[[0,3.9,14.21],[1,2,100],[2,1.5,200]],"ltp":4.1,"tv":237.29,"id":12474498}]}]}
{"op":"mcm","clk":"11849480844","pt":1723668102556,"mc":[{"id":"1.231815703","rc":[{"batb":[[0,3.95,10.05],[1,3.9,14.16],[2,2,100]],"ltp":4.1,"tv":237.29,"id":12474498}]}]}
{"op":"mcm","clk":"11849481066","pt":1723668105993,"mc":[{"id":"1.231815703","rc":[{"batb":[[0,3.9,14.21],[1,2,100],[2,1.5,200]],"ltp":4.1,"tv":237.29,"id":12474498}]}]}
{"op":"mcm","clk":"11849481226","pt":1723668108259,"mc":[{"id":"1.231815703","rc":[{"batb":[[0,3.95,10.05],[1,3.9,14.16],[2,2,100]],"ltp":4.1,"tv":237.29,"id":12474498}]}]}
{"op":"mcm","clk":"11849481386","pt":1723668111387,"mc":[{"id":"1.231815703","rc":[{"batb":[[0,3.9,14.21],[1,2,100],[2,1.5,200]],"ltp":4.1,"tv":237.29,"id":12474498}]}]}
{"op":"mcm","clk":"11849481544","pt":1723668114064,"mc":[{"id":"1.231815703","rc":[{"batb":[[0,3.95,10.05],[1,3.9,14.16],[2,2,100]],"ltp":4.1,"tv":237.29,"id":12474498}]}]}
{"op":"mcm","clk":"11849481748","pt":1723668117391,"mc":[{"id":"1.231815703","rc":[{"batb":[[0,3.9,14.21],[1,2,100],[2,1.5,200]],"ltp":4.1,"tv":237.29,"id":12474498}]}]}
{"op":"mcm","clk":"11849481900","pt":1723668119704,"mc":[{"id":"1.231815703","rc":[{"batb":[[0,3.95,10.05],[1,3.9,14.16],[2,2,100]],"ltp":4.1,"tv":237.29,"id":12474498}]}]}
{"op":"mcm","clk":"11849482188","pt":1723668123113,"mc":[{"id":"1.231815703","rc":[{"batb":[[0,3.9,14.21],[1,2,100],[2,1.5,200]],"ltp":4.1,"tv":237.29,"id":12474498}]}]}
{"op":"mcm","clk":"11849482334","pt":1723668125476,"mc":[{"id":"1.231815703","rc":[{"batb":[[0,3.95,10.05],[1,3.9,14.16],[2,2,100]],"ltp":4.1,"tv":237.29,"id":12474498}]}]}
{"op":"mcm","clk":"11849482554","pt":1723668128807,"mc":[{"id":"1.231815703","rc":[{"batb":[[0,3.9,14.21],[1,2,100],[2,1.5,200]],"ltp":4.1,"tv":237.29,"id":12474498}]}]}
{"op":"mcm","clk":"11849482725","pt":1723668131123,"mc":[{"id":"1.231815703","rc":[{"batb":[[0,3.95,10.05],[1,3.9,14.16],[2,2,100]],"ltp":4.1,"tv":237.29,"id":12474498}]}]}
{"op":"mcm","clk":"11849482944","pt":1723668134519,"mc":[{"id":"1.231815703","rc":[{"batb":[[0,3.9,14.21],[1,2,100],[2,1.5,200]],"ltp":4.1,"tv":237.29,"id":12474498}]}]}
{"op":"mcm","clk":"11849483089","pt":1723668136790,"mc":[{"id":"1.231815703","rc":[{"batb":[[0,3.95,10.05],[1,3.9,14.16],[2,2,100]],"ltp":4.1,"tv":237.29,"id":12474498}]}]}
{"op":"mcm","clk":"11849483315","pt":1723668140100,"mc":[{"id":"1.231815703","rc":[{"batb":[[0,3.9,14.21],[1,2,100],[2,1.5,200]],"ltp":4.1,"tv":237.29,"id":12474498}]}]}
{"op":"mcm","clk":"11849483464","pt":1723668142409,"mc":[{"id":"1.231815703","rc":[{"batb":[[0,3.95,10.05],[1,3.9,14.16],[2,2,100]],"ltp":4.1,"tv":237.29,"id":12474498}]}]}
{"op":"mcm","clk":"11849483667","pt":1723668145700,"mc":[{"id":"1.231815703","rc":[{"batb":[[0,3.9,14.21],[1,2,100],[2,1.5,200]],"ltp":4.1,"tv":237.29,"id":12474498}]}]}
{"op":"mcm","clk":"11849483859","pt":1723668149035,"mc":[{"id":"1.231815703","rc":[{"batb":[[0,3.95,10.05],[1,3.9,14.16],[2,2,100]],"ltp":4.1,"tv":237.29,"id":12474498}]}]}
{"op":"mcm","clk":"11849484077","pt":1723668152425,"mc":[{"id":"1.231815703","rc":[{"batb":[[0,3.9,14.21],[1,2,100],[2,1.5,200]],"ltp":4.1,"tv":237.29,"id":12474498}]}]}
{"op":"mcm","clk":"11849484310","pt":1723668156432,"mc":[{"id":"1.231815703","rc":[{"batb":[[0,3.95,10.05],[1,3.9,14.16],[2,2,100]],"ltp":4.1,"tv":237.29,"id":12474498}]}]}
{"op":"mcm","clk":"11849484513","pt":1723668159809,"mc":[{"id":"1.231815703","rc":[{"batb":[[0,3.9,14.21],[1,2,100],[2,1.5,200]],"ltp":4.1,"tv":237.29,"id":12474498}]}]}
{"op":"mcm","clk":"11849484644","pt":1723668162118,"mc":[{"id":"1.231815703","rc":[{"batb":[[0,3.95,10.05],[1,3.9,14.16],[2,2,100]],"ltp":4.1,"tv":237.29,"id":12474498}]}]}
{"op":"mcm","clk":"11849484853","pt":1723668165456,"mc":[{"id":"1.231815703","rc":[{"batb":[[0,3.9,14.21],[1,2,100],[2,1.5,200]],"ltp":4.1,"tv":237.29,"id":12474498}]}]}
{"op":"mcm","clk":"11849485018","pt":1723668167721,"mc":[{"id":"1.231815703","rc":[{"batb":[[0,3.95,10.05],[1,3.9,14.16],[2,2,100]],"ltp":4.1,"tv":237.29,"id":12474498}]}]}
{"op":"mcm","clk":"11849485225","pt":1723668171051,"mc":[{"id":"1.231815703","rc":[{"batb":[[0,3.9,14.21],[1,2,100],[2,1.5,200]],"ltp":4.1,"tv":237.29,"id":12474498}]}]}
{"op":"mcm","clk":"11849485390","pt":1723668173858,"mc":[{"id":"1.231815703","rc":[{"batb":[[0,3.95,10.05],[1,3.9,14.16],[2,2,100]],"ltp":4.1,"tv":237.29,"id":12474498}]}]}
{"op":"mcm","clk":"11849485619","pt":1723668177356,"mc":[{"id":"1.231815703","rc":[{"batb":[[0,3.9,14.21],[1,2,100],[2,1.5,200]],"ltp":4.1,"tv":237.29,"id":12474498}]}]}
{"op":"mcm","clk":"11849485766","pt":1723668179669,"mc":[{"id":"1.231815703","rc":[{"batb":[[0,3.95,10.05],[1,3.9,14.16],[2,2,100]],"ltp":4.1,"tv":237.29,"id":12474498}]}]}
{"op":"mcm","clk":"11849485973","pt":1723668183068,"mc":[{"id":"1.231815703","rc":[{"batb":[[0,3.9,14.21],[1,2,100],[2,1.5,200]],"ltp":4.1,"tv":237.29,"id":12474498}]}]}
{"op":"mcm","clk":"11849486143","pt":1723668185448,"mc":[{"id":"1.231815703","rc":[{"batb":[[0,3.95,10.05],[1,3.9,14.16],[2,2,100]],"ltp":4.1,"tv":237.29,"id":12474498}]}]}
{"op":"mcm","clk":"11849486330","pt":1723668188874,"mc":[{"id":"1.231815703","rc":[{"batb":[[0,3.9,14.21],[1,2,100],[2,1.5,200]],"ltp":4.1,"tv":237.29,"id":12474498}]}]}
{"op":"mcm","clk":"11849486503","pt":1723668191144,"mc":[{"id":"1.231815703","rc":[{"batb":[[0,3.95,10.05],[1,3.9,14.16],[2,2,100]],"ltp":4.1,"tv":237.29,"id":12474498}]}]}
{"op":"mcm","clk":"11849486732","pt":1723668194586,"mc":[{"id":"1.231815703","rc":[{"batb":[[0,3.9,14.21],[1,2,100],[2,1.5,200]],"ltp":4.1,"tv":237.29,"id":12474498}]}]}
{"op":"mcm","clk":"11849486859","pt":1723668196849,"mc":[{"id":"1.231815703","rc":[{"batb":[[0,3.95,10.05],[1,3.9,14.16],[2,2,100]],"ltp":4.1,"tv":237.29,"id":12474498}]}]}
{"op":"mcm","clk":"11849487050","pt":1723668200181,"mc":[{"id":"1.231815703","rc":[{"batb":[[0,3.9,14.21],[1,2,100],[2,1.5,200]],"ltp":4.1,"tv":237.29,"id":12474498}]}]}
{"op":"mcm","clk":"11849487194","pt":1723668202566,"mc":[{"id":"1.231815703","rc":[{"batb":[[0,3.95,10.05],[1,3.9,14.16],[2,2,100]],"ltp":4.1,"tv":237.29,"id":12474498}]}]}
{"op":"mcm","clk":"11849487384","pt":1723668205961,"mc":[{"id":"1.231815703","rc":[{"batb":[[0,3.9,14.21],[1,2,100],[2,1.5,200]],"ltp":4.1,"tv":237.29,"id":12474498}]}]}
{"op":"mcm","clk":"11849487532","pt":1723668208280,"mc":[{"id":"1.231815703","rc":[{"batb":[[0,3.95,10.05],[1,3.9,14.16],[2,2,100]],"ltp":4.1,"tv":237.29,"id":12474498}]}]}
{"op":"mcm","clk":"11849487742","pt":1723668211589,"mc":[{"id":"1.231815703","rc":[{"batb":[[0,3.9,14.21],[1,2,100],[2,1.5,200]],"ltp":4.1,"tv":237.29,"id":12474498}]}]}
{"op":"mcm","clk":"11849487888","pt":1723668214000,"mc":[{"id":"1.231815703","rc":[{"batb":[[0,3.95,10.05],[1,3.9,14.16],[2,2,100]],"ltp":4.1,"tv":237.29,"id":12474498}]}]}
{"op":"mcm","clk":"11849488085","pt":1723668217392,"mc":[{"id":"1.231815703","rc":[{"batb":[[0,3.9,14.21],[1,2,100],[2,1.5,200]],"ltp":4.1,"tv":237.29,"id":12474498}]}]}
{"op":"mcm","clk":"11849488217","pt":1723668219707,"mc":[{"id":"1.231815703","rc":[{"batb":[[0,3.95,10.05],[1,3.9,14.16],[2,2,100]],"ltp":4.1,"tv":237.29,"id":12474498}]}]}
{"op":"mcm","clk":"11849488435","pt":1723668223198,"mc":[{"id":"1.231815703","rc":[{"batb":[[0,3.9,14.21],[1,2,100],[2,1.5,200]],"ltp":4.1,"tv":237.29,"id":12474498}]}]}
{"op":"mcm","clk":"11849488568","pt":1723668225508,"mc":[{"id":"1.231815703","rc":[{"batb":[[0,3.95,10.05],[1,3.9,14.16],[2,2,100]],"ltp":4.1,"tv":237.29,"id":12474498}]}]}
{"op":"mcm","clk":"11849488792","pt":1723668228913,"mc":[{"id":"1.231815703","rc":[{"batb":[[0,3.9,14.21],[1,2,100],[2,1.5,200]],"ltp":4.1,"tv":237.29,"id":12474498}]}]}
{"op":"mcm","clk":"11849488920","pt":1723668231224,"mc":[{"id":"1.231815703","rc":[{"batb":[[0,3.95,10.05],[1,3.9,14.16],[2,2,100]],"ltp":4.1,"tv":237.29,"id":12474498}]}]}
{"op":"mcm","clk":"11849489107","pt":1723668234520,"mc":[{"id":"1.231815703","rc":[{"batb":[[0,3.9,14.21],[1,2,100],[2,1.5,200]],"ltp":4.1,"tv":237.29,"id":12474498}]}]}
{"op":"mcm","clk":"11849489238","pt":1723668236788,"mc":[{"id":"1.231815703","rc":[{"batb":[[0,3.95,10.05],[1,3.9,14.16],[2,2,100]],"ltp":4.1,"tv":237.29,"id":12474498}]}]}
{"op":"mcm","clk":"11849489427","pt":1723668240125,"mc":[{"id":"1.231815703","rc":[{"batb":[[0,3.9,14.21],[1,2,100],[2,1.5,200]],"ltp":4.1,"tv":237.29,"id":12474498}]}]}
{"op":"mcm","clk":"11849489594","pt":1723668242498,"mc":[{"id":"1.231815703","rc":[{"batb":[[0,3.95,10.05],[1,3.9,14.16],[2,2,100]],"ltp":4.1,"tv":237.29,"id":12474498}]}]}
{"op":"mcm","clk":"11849489804","pt":1723668245831,"mc":[{"id":"1.231815703","rc":[{"batb":[[0,3.9,14.21],[1,2,100],[2,1.5,200]],"ltp":4.1,"tv":237.29,"id":12474498}]}]}
{"op":"mcm","clk":"11849489988","pt":1723668248717,"mc":[{"id":"1.231815703","rc":[{"batb":[[0,3.95,10.05],[1,3.9,14.16],[2,2,100]],"ltp":4.1,"tv":237.29,"id":12474498}]}]}
{"op":"mcm","clk":"11849490239","pt":1723668252359,"mc":[{"id":"1.231815703","rc":[{"batb":[[0,3.9,14.21],[1,2,100],[2,1.5,200]],"ltp":4.1,"tv":237.29,"id":12474498}]}]}
{"op":"mcm","clk":"11849490396","pt":1723668254525,"mc":[{"id":"1.231815703","rc":[{"batb":[[0,3.95,10.05],[1,3.9,14.16],[2,2,100]],"ltp":4.1,"tv":237.29,"id":12474498}]}]}
{"op":"mcm","clk":"11849490645","pt":1723668257963,"mc":[{"id":"1.231815703","rc":[{"batb":[[0,3.9,14.21],[1,2,100],[2,1.5,200]],"ltp":4.1,"tv":237.29,"id":12474498}]}]}
{"op":"mcm","clk":"11849490793","pt":1723668260275,"mc":[{"id":"1.231815703","rc":[{"batb":[[0,3.95,10.05],[1,3.9,14.16],[2,2,100]],"ltp":4.1,"tv":237.29,"id":12474498}]}]}
{"op":"mcm","clk":"11849490997","pt":1723668263669,"mc":[{"id":"1.231815703","rc":[{"batb":[[0,3.9,14.21],[1,2,100],[2,1.5,200]],"ltp":4.1,"tv":237.29,"id":12474498}]}]}
{"op":"mcm","clk":"11849491118","pt":1723668265870,"mc":[{"id":"1.231815703","rc":[{"batb":[[0,3.95,10.05],[1,3.9,14.16],[2,2,100]],"ltp":4.1,"tv":237.29,"id":12474498}]}]}
{"op":"mcm","clk":"11849491381","pt":1723668269266,"mc":[{"id":"1.231815703","rc":[{"batb":[[0,3.9,14.21],[1,2,100],[2,1.5,200]],"ltp":4.1,"tv":237.29,"id":12474498}]}]}
{"op":"mcm","clk":"11849491546","pt":1723668271556,"mc":[{"id":"1.231815703","rc":[{"batb":[[0,3.95,10.05],[1,3.9,14.16],[2,2,100]],"ltp":4.1,"tv":237.29,"id":12474498}]}]}
{"op":"mcm","clk":"11849491819","pt":1723668274999,"mc":[{"id":"1.231815703","rc":[{"batb":[[0,3.9,14.21],[1,2,100],[2,1.5,200]],"ltp":4.1,"tv":237.29,"id":12474498}]}]}
{"op":"mcm","clk":"11849491969","pt":1723668277262,"mc":[{"id":"1.231815703","rc":[{"batb":[[0,3.95,10.05],[1,3.9,14.16],[2,2,100]],"ltp":4.1,"tv":237.29,"id":12474498}]}]}
{"op":"mcm","clk":"11849492208","pt":1723668280561,"mc":[{"id":"1.231815703","rc":[{"batb":[[0,3.9,14.21],[1,2,100],[2,1.5,200]],"ltp":4.1,"tv":237.29,"id":12474498}]}]}
{"op":"mcm","clk":"11849492354","pt":1723668282866,"mc":[{"id":"1.231815703","rc":[{"batb":[[0,3.95,10.05],[1,3.9,14.16],[2,2,100]],"ltp":4.1,"tv":237.29,"id":12474498}]}]}
{"op":"mcm","clk":"11849492576","pt":1723668286369,"mc":[{"id":"1.231815703","rc":[{"batb":[[0,3.9,14.21],[1,2,100],[2,1.5,200]],"ltp":4.1,"tv":237.29,"id":12474498}]}]}
{"op":"mcm","clk":"11849492786","pt":1723668289407,"mc":[{"id":"1.231815703","rc":[{"batb":[[0,3.95,10.05],[1,3.9,14.16],[2,2,100]],"ltp":4.1,"tv":237.29,"id":12474498}]}]}
{"op":"mcm","clk":"11849493036","pt":1723668292810,"mc":[{"id":"1.231815703","rc":[{"batb":[[0,3.9,14.21],[1,2,100],[2,1.5,200]],"ltp":4.1,"tv":237.29,"id":12474498}]}]}
{"op":"mcm","clk":"11849493205","pt":1723668295112,"mc":[{"id":"1.231815703","rc":[{"batb":[[0,3.95,10.05],[1,3.9,14.16],[2,2,100]],"ltp":4.1,"tv":237.29,"id":12474498}]}]}
{"op":"mcm","clk":"11849493437","pt":1723668298410,"mc":[{"id":"1.231815703","rc":[{"batb":[[0,3.9,14.21],[1,2,100],[2,1.5,200]],"ltp":4.1,"tv":237.29,"id":12474498}]}]}
{"op":"mcm","clk":"11849493606","pt":1723668300894,"mc":[{"id":"1.231815703","rc":[{"batb":[[0,3.95,10.05],[1,3.9,14.16],[2,2,100]],"ltp":4.1,"tv":237.29,"id":12474498}]}]}
{"op":"mcm","clk":"11849493834","pt":1723668304318,"mc":[{"id":"1.231815703","rc":[{"batb":[[0,3.9,14.21],[1,2,100],[2,1.5,200]],"ltp":4.1,"tv":237.29,"id":12474498}]}]}
{"op":"mcm","clk":"11849494046","pt":1723668307619,"mc":[{"id":"1.231815703","rc":[{"batb":[[0,3.95,10.05],[1,3.9,14.16],[2,2,100]],"ltp":4.1,"tv":237.29,"id":12474498}]}]}
{"op":"mcm","clk":"11849494271","pt":1723668311017,"mc":[{"id":"1.231815703","rc":[{"batb":[[0,3.9,14.21],[1,2,100],[2,1.5,200]],"ltp":4.1,"tv":237.29,"id":12474498}]}]}
{"op":"mcm","clk":"11849494446","pt":1723668313611,"mc":[{"id":"1.231815703","rc":[{"batb":[[0,3.95,10.05],[1,3.9,14.16],[2,2,100]],"ltp":4.1,"tv":237.29,"id":12474498}]}]}
{"op":"mcm","clk":"11849494673","pt":1723668316911,"mc":[{"id":"1.231815703","rc":[{"batb":[[0,3.9,14.21],[1,2,100],[2,1.5,200]],"ltp":4.1,"tv":237.29,"id":12474498}]}]}
{"op":"mcm","clk":"11849494814","pt":1723668319324,"mc":[{"id":"1.231815703","rc":[{"batb":[[0,3.95,10.05],[1,3.9,14.16],[2,2,100]],"ltp":4.1,"tv":237.29,"id":12474498}]}]}
{"op":"mcm","clk":"11849495035","pt":1723668322749,"mc":[{"id":"1.231815703","rc":[{"batb":[[0,3.9,14.21],[1,2,100],[2,1.5,200]],"ltp":4.1,"tv":237.29,"id":12474498}]}]}
{"op":"mcm","clk":"11849495199","pt":1723668325015,"mc":[{"id":"1.231815703","rc":[{"batb":[[0,3.95,10.05],[1,3.9,14.16],[2,2,100]],"ltp":4.1,"tv":237.29,"id":12474498}]}]}
{"op":"mcm","clk":"11849495393","pt":1723668328459,"mc":[{"id":"1.231815703","rc":[{"batb":[[0,3.9,14.21],[1,2,100],[2,1.5,200]],"ltp":4.1,"tv":237.29,"id":12474498}]}]}
{"op":"mcm","clk":"11849495554","pt":1723668330628,"mc":[{"id":"1.231815703","rc":[{"batb":[[0,3.95,10.05],[1,3.9,14.16],[2,2,100]],"ltp":4.1,"tv":237.29,"id":12474498}]}]}
{"op":"mcm","clk":"11849495763","pt":1723668334077,"mc":[{"id":"1.231815703","rc":[{"batb":[[0,3.9,14.21],[1,2,100],[2,1.5,200]],"ltp":4.1,"tv":237.29,"id":12474498}]}]}
{"op":"mcm","clk":"11849495935","pt":1723668336317,"mc":[{"id":"1.231815703","rc":[{"batb":[[0,3.95,10.05],[1,3.9,14.16],[2,2,100]],"ltp":4.1,"tv":237.29,"id":12474498}]}]}
{"op":"mcm","clk":"11849496211","pt":1723668339703,"mc":[{"id":"1.231815703","rc":[{"batb":[[0,3.9,14.21],[1,2,100],[2,1.5,200]],"ltp":4.1,"tv":237.29,"id":12474498}]}]}
{"op":"mcm","clk":"11849496411","pt":1723668342105,"mc":[{"id":"1.231815703","rc":[{"batb":[[0,3.95,10.05],[1,3.9,14.16],[2,2,100]],"ltp":4.1,"tv":237.29,"id":12474498}]}]}
{"op":"mcm","clk":"11849496613","pt":1723668345289,"mc":[{"id":"1.231815703","rc":[{"batb":[[0,3.9,14.21],[1,2,100],[2,1.5,200]],"ltp":4.1,"tv":237.29,"id":12474498}]}]}
{"op":"mcm","clk":"11849496812","pt":1723668347914,"mc":[{"id":"1.231815703","rc":[{"batb":[[0,3.95,10.05],[1,3.9,14.16],[2,2,100]],"ltp":4.1,"tv":237.29,"id":12474498}]}]}
{"op":"mcm","clk":"11849497039","pt":1723668351301,"mc":[{"id":"1.231815703","rc":[{"batb":[[0,3.9,14.21],[1,2,100],[2,1.5,200]],"ltp":4.1,"tv":237.29,"id":12474498}]}]}
{"op":"mcm","clk":"11849497196","pt":1723668353821,"mc":[{"id":"1.231815703","rc":[{"batb":[[0,3.95,10.05],[1,3.9,14.16],[2,2,100]],"ltp":4.1,"tv":237.29,"id":12474498}]}]}
{"op":"mcm","clk":"11849497421","pt":1723668357121,"mc":[{"id":"1.231815703","rc":[{"batb":[[0,3.9,14.21],[1,2,100],[2,1.5,200]],"ltp":4.1,"tv":237.29,"id":12474498}]}]}
{"op":"mcm","clk":"11849497631","pt":1723668360614,"mc":[{"id":"1.231815703","rc":[{"batb":[[0,3.95,10.05],[1,3.9,14.16],[2,2,100]],"ltp":4.1,"tv":237.29,"id":12474498}]}]}
{"op":"mcm","clk":"11849497849","pt":1723668364108,"mc":[{"id":"1.231815703","rc":[{"batb":[[0,3.9,14.21],[1,2,100],[2,1.5,200]],"ltp":4.1,"tv":237.29,"id":12474498}]}]}
{"op":"mcm","clk":"11849498016","pt":1723668367095,"mc":[{"id":"1.231815703","rc":[{"batb":[[0,3.95,10.05],[1,3.9,14.16],[2,2,100]],"ltp":4.1,"tv":237.29,"id":12474498}]}]}
{"op":"mcm","clk":"11849498223","pt":1723668370649,"mc":[{"id":"1.231815703","rc":[{"batb":[[0,3.9,14.21],[1,2,100],[2,1.5,200]],"ltp":4.1,"tv":237.29,"id":12474498}]}]}
{"op":"mcm","clk":"11849498392","pt":1723668372969,"mc":[{"id":"1.231815703","rc":[{"batb":[[0,3.95,10.05],[1,3.9,14.16],[2,2,100]],"ltp":4.1,"tv":237.29,"id":12474498}]}]}
{"op":"mcm","clk":"11849498610","pt":1723668376350,"mc":[{"id":"1.231815703","rc":[{"batb":[[0,3.9,14.21],[1,2,100],[2,1.5,200]],"ltp":4.1,"tv":237.29,"id":12474498}]}]}
{"op":"mcm","clk":"11849498755","pt":1723668378615,"mc":[{"id":"1.231815703","rc":[{"batb":[[0,3.95,10.05],[1,3.9,14.16],[2,2,100]],"ltp":4.1,"tv":237.29,"id":12474498}]}]}
{"op":"mcm","clk":"11849498954","pt":1723668381846,"mc":[{"id":"1.231815703","rc":[{"batb":[[0,3.9,14.21],[1,2,100],[2,1.5,200]],"ltp":4.1,"tv":237.29,"id":12474498}]}]}
{"op":"mcm","clk":"11849499112","pt":1723668384463,"mc":[{"id":"1.231815703","rc":[{"batb":[[0,3.95,10.05],[1,3.9,14.16],[2,2,100]],"ltp":4.1,"tv":237.29,"id":12474498}]}]}
{"op":"mcm","clk":"11849499302","pt":1723668387747,"mc":[{"id":"1.231815703","rc":[{"batb":[[0,3.9,14.21],[1,2,100],[2,1.5,200]],"ltp":4.1,"tv":237.29,"id":12474498}]}]}
{"op":"mcm","clk":"11849499449","pt":1723668390158,"mc":[{"id":"1.231815703","rc":[{"batb":[[0,3.95,10.05],[1,3.9,14.16],[2,2,100]],"ltp":4.1,"tv":237.29,"id":12474498}]}]}
{"op":"mcm","clk":"11849499663","pt":1723668393546,"mc":[{"id":"1.231815703","rc":[{"batb":[[0,3.9,14.21],[1,2,100],[2,1.5,200]],"ltp":4.1,"tv":237.29,"id":12474498}]}]}
{"op":"mcm","clk":"11849499801","pt":1723668396059,"mc":[{"id":"1.231815703","rc":[{"batb":[[0,3.95,10.05],[1,3.9,14.16],[2,2,100]],"ltp":4.1,"tv":237.29,"id":12474498}]}]}
{"op":"mcm","clk":"11849499992","pt":1723668399344,"mc":[{"id":"1.231815703","rc":[{"batb":[[0,3.9,14.21],[1,2,100],[2,1.5,200]],"ltp":4.1,"tv":237.29,"id":12474498}]}]}
{"op":"mcm","clk":"11849500156","pt":1723668401764,"mc":[{"id":"1.231815703","rc":[{"batb":[[0,3.95,10.05],[1,3.9,14.16],[2,2,100]],"ltp":4.1,"tv":237.29,"id":12474498}]}]}
{"op":"mcm","clk":"11849500336","pt":1723668405157,"mc":[{"id":"1.231815703","rc":[{"batb":[[0,3.9,14.21],[1,2,100],[2,1.5,200]],"ltp":4.1,"tv":237.29,"id":12474498}]}]}
{"op":"mcm","clk":"11849500457","pt":1723668407358,"mc":[{"id":"1.231815703","rc":[{"batb":[[0,3.95,10.05],[1,3.9,14.16],[2,2,100]],"ltp":4.1,"tv":237.29,"id":12474498}]}]}
{"op":"mcm","clk":"11849500660","pt":1723668410592,"mc":[{"id":"1.231815703","rc":[{"batb":[[0,3.9,14.21],[1,2,100],[2,1.5,200]],"ltp":4.1,"tv":237.29,"id":12474498}]}]}
{"op":"mcm","clk":"11849500795","pt":1723668412952,"mc":[{"id":"1.231815703","rc":[{"batb":[[0,3.95,10.05],[1,3.9,14.16],[2,2,100]],"ltp":4.1,"tv":237.29,"id":12474498}]}]}
{"op":"mcm","clk":"11849501012","pt":1723668416392,"mc":[{"id":"1.231815703","rc":[{"batb":[[0,3.9,14.21],[1,2,100],[2,1.5,200]],"ltp":4.1,"tv":237.29,"id":12474498}]}]}
{"op":"mcm","clk":"11849501163","pt":1723668418804,"mc":[{"id":"1.231815703","rc":[{"batb":[[0,3.95,10.05],[1,3.9,14.16],[2,2,100]],"ltp":4.1,"tv":237.29,"id":12474498}]}]}
{"op":"mcm","clk":"11849501385","pt":1723668422302,"mc":[{"id":"1.231815703","rc":[{"batb":[[0,3.9,14.21],[1,2,100],[2,1.5,200]],"ltp":4.1,"tv":237.29,"id":12474498}]}]}
{"op":"mcm","clk":"11849501510","pt":1723668424712,"mc":[{"id":"1.231815703","rc":[{"batb":[[0,3.95,10.05],[1,3.9,14.16],[2,2,100]],"ltp":4.1,"tv":237.29,"id":12474498}]}]}
{"op":"mcm","clk":"11849501697","pt":1723668428093,"mc":[{"id":"1.231815703","rc":[{"batb":[[0,3.9,14.21],[1,2,100],[2,1.5,200]],"ltp":4.1,"tv":237.29,"id":12474498}]}]}
{"op":"mcm","clk":"11849501856","pt":1723668430406,"mc":[{"id":"1.231815703","rc":[{"batb":[[0,3.95,10.05],[1,3.9,14.16],[2,2,100]],"ltp":4.1,"tv":237.29,"id":12474498}]}]}
{"op":"mcm","clk":"11849502066","pt":1723668433589,"mc":[{"id":"1.231815703","rc":[{"batb":[[0,3.9,14.21],[1,2,100],[2,1.5,200]],"ltp":4.1,"tv":237.29,"id":12474498}]}]}
{"op":"mcm","clk":"11849502265","pt":1723668437182,"mc":[{"id":"1.231815703","rc":[{"batb":[[0,3.95,10.05],[1,3.9,14.16],[2,2,100]],"ltp":4.1,"tv":237.29,"id":12474498}]}]}
{"op":"mcm","clk":"11849502448","pt":1723668440619,"mc":[{"id":"1.231815703","rc":[{"batb":[[0,3.9,14.21],[1,2,100],[2,1.5,200]],"ltp":4.1,"tv":237.29,"id":12474498}]}]}
{"op":"mcm","clk":"11849502669","pt":1723668444519,"mc":[{"id":"1.231815703","rc":[{"batb":[[0,3.95,10.05],[1,3.9,14.16],[2,2,100]],"ltp":4.1,"tv":237.29,"id":12474498}]}]}
{"op":"mcm","clk":"11849502861","pt":1723668447715,"mc":[{"id":"1.231815703","rc":[{"batb":[[0,3.9,14.21],[1,2,100],[2,1.5,200]],"ltp":4.1,"tv":237.29,"id":12474498}]}]}
{"op":"mcm","clk":"11849502983","pt":1723668450223,"mc":[{"id":"1.231815703","rc":[{"batb":[[0,3.95,10.05],[1,3.9,14.16],[2,2,100]],"ltp":4.1,"tv":237.29,"id":12474498}]}]}
{"op":"mcm","clk":"11849503174","pt":1723668453513,"mc":[{"id":"1.231815703","rc":[{"batb":[[0,3.9,14.21],[1,2,100],[2,1.5,200]],"ltp":4.1,"tv":237.29,"id":12474498}]}]}
{"op":"mcm","clk":"11849503356","pt":1723668456899,"mc":[{"id":"1.231815703","rc":[{"batb":[[0,3.95,10.05],[1,3.9,14.16],[2,2,100]],"ltp":4.1,"tv":237.29,"id":12474498}]}]}
{"op":"mcm","clk":"11849503539","pt":1723668460134,"mc":[{"id":"1.231815703","rc":[{"batb":[[0,3.9,14.21],[1,2,100],[2,1.5,200]],"ltp":4.1,"tv":237.29,"id":12474498}]}]}
{"op":"mcm","clk":"11849503668","pt":1723668462649,"mc":[{"id":"1.231815703","rc":[{"batb":[[0,3.95,10.05],[1,3.9,14.16],[2,2,100]],"ltp":4.1,"tv":237.29,"id":12474498}]}]}
{"op":"mcm","clk":"11849503847","pt":1723668465991,"mc":[{"id":"1.231815703","rc":[{"batb":[[0,3.9,14.21],[1,2,100],[2,1.5,200]],"ltp":4.1,"tv":237.29,"id":12474498}]}]}
{"op":"mcm","clk":"11849503971","pt":1723668468302,"mc":[{"id":"1.231815703","rc":[{"batb":[[0,3.95,10.05],[1,3.9,14.16],[2,2,100]],"ltp":4.1,"tv":237.29,"id":12474498}]}]}
{"op":"mcm","clk":"11849504118","pt":1723668471546,"mc":[{"id":"1.231815703","rc":[{"batb":[[0,3.9,14.21],[1,2,100],[2,1.5,200]],"ltp":4.1,"tv":237.29,"id":12474498}]}]}
{"op":"mcm","clk":"11849504256","pt":1723668474320,"mc":[{"id":"1.231815703","rc":[{"batb":[[0,3.95,10.05],[1,3.9,14.16],[2,2,100]],"ltp":4.1,"tv":237.29,"id":12474498}]}]}
{"op":"mcm","clk":"11849504437","pt":1723668477757,"mc":[{"id":"1.231815703","rc":[{"batb":[[0,3.9,14.21],[1,2,100],[2,1.5,200]],"ltp":4.1,"tv":237.29,"id":12474498}]}]}
{"op":"mcm","clk":"11849504581","pt":1723668480119,"mc":[{"id":"1.231815703","rc":[{"batb":[[0,3.95,10.05],[1,3.9,14.16],[2,2,100]],"ltp":4.1,"tv":237.29,"id":12474498}]}]}
{"op":"mcm","clk":"11849504754","pt":1723668483558,"mc":[{"id":"1.231815703","rc":[{"batb":[[0,3.9,14.21],[1,2,100],[2,1.5,200]],"ltp":4.1,"tv":237.29,"id":12474498}]}]}
{"op":"mcm","clk":"11849504858","pt":1723668486171,"mc":[{"id":"1.231815703","rc":[{"batb":[[0,3.95,10.05],[1,3.9,14.16],[2,2,100]],"ltp":4.1,"tv":237.29,"id":12474498}]}]}
{"op":"mcm","clk":"11849504998","pt":1723668489455,"mc":[{"id":"1.231815703","rc":[{"batb":[[0,3.9,14.21],[1,2,100],[2,1.5,200]],"ltp":4.1,"tv":237.29,"id":12474498}]}]}
{"op":"mcm","clk":"11849505170","pt":1723668492636,"mc":[{"id":"1.231815703","rc":[{"batb":[[0,3.95,10.05],[1,3.9,14.16],[2,2,100]],"ltp":4.1,"tv":237.29,"id":12474498}]}]}
{"op":"mcm","clk":"11849505332","pt":1723668496073,"mc":[{"id":"1.231815703","rc":[{"batb":[[0,3.9,14.21],[1,2,100],[2,1.5,200]],"ltp":4.1,"tv":237.29,"id":12474498}]}]}
{"op":"mcm","clk":"11849505452","pt":1723668498282,"mc":[{"id":"1.231815703","rc":[{"batb":[[0,3.95,10.05],[1,3.9,14.16],[2,2,100]],"ltp":4.1,"tv":237.29,"id":12474498}]}]}
{"op":"mcm","clk":"11849505643","pt":1723668501568,"mc":[{"id":"1.231815703","rc":[{"batb":[[0,3.9,14.21],[1,2,100],[2,1.5,200]],"ltp":4.1,"tv":237.29,"id":12474498}]}]}
{"op":"mcm","clk":"11849505773","pt":1723668503977,"mc":[{"id":"1.231815703","rc":[{"batb":[[0,3.95,10.05],[1,3.9,14.16],[2,2,100]],"ltp":4.1,"tv":237.29,"id":12474498}]}]}
{"op":"mcm","clk":"11849505951","pt":1723668507259,"mc":[{"id":"1.231815703","rc":[{"batb":[[0,3.9,14.21],[1,2,100],[2,1.5,200]],"ltp":4.1,"tv":237.29,"id":12474498}]}]}
{"op":"mcm","clk":"11849506121","pt":1723668509772,"mc":[{"id":"1.231815703","rc":[{"batb":[[0,3.95,10.05],[1,3.9,14.16],[2,2,100]],"ltp":4.1,"tv":237.29,"id":12474498}]}]}
{"op":"mcm","clk":"11849506310","pt":1723668513056,"mc":[{"id":"1.231815703","rc":[{"batb":[[0,3.9,14.21],[1,2,100],[2,1.5,200]],"ltp":4.1,"tv":237.29,"id":12474498}]}]}
{"op":"mcm","clk":"11849506473","pt":1723668515370,"mc":[{"id":"1.231815703","rc":[{"batb":[[0,3.95,10.05],[1,3.9,14.16],[2,2,100]],"ltp":4.1,"tv":237.29,"id":12474498}]}]}
{"op":"mcm","clk":"11849506664","pt":1723668518808,"mc":[{"id":"1.231815703","rc":[{"batb":[[0,3.9,14.21],[1,2,100],[2,1.5,200]],"ltp":4.1,"tv":237.29,"id":12474498}]}]}
{"op":"mcm","clk":"11849506813","pt":1723668521069,"mc":[{"id":"1.231815703","rc":[{"batb":[[0,3.95,10.05],[1,3.9,14.16],[2,2,100]],"ltp":4.1,"tv":237.29,"id":12474498}]}]}
{"op":"mcm","clk":"11849507006","pt":1723668524369,"mc":[{"id":"1.231815703","rc":[{"batb":[[0,3.9,14.21],[1,2,100],[2,1.5,200]],"ltp":4.1,"tv":237.29,"id":12474498}]}]}
{"op":"mcm","clk":"11849507196","pt":1723668527599,"mc":[{"id":"1.231815703","rc":[{"batb":[[0,3.95,10.05],[1,3.9,14.16],[2,2,100]],"ltp":4.1,"tv":237.29,"id":12474498}]}]}
{"op":"mcm","clk":"11849507339","pt":1723668530876,"mc":[{"id":"1.231815703","rc":[{"batb":[[0,3.9,14.21],[1,2,100],[2,1.5,200]],"ltp":4.1,"tv":237.29,"id":12474498}]}]}
{"op":"mcm","clk":"11849507529","pt":1723668534307,"mc":[{"id":"1.231815703","rc":[{"batb":[[0,3.95,10.05],[1,3.9,14.16],[2,2,100]],"ltp":4.1,"tv":237.29,"id":12474498}]}]}
{"op":"mcm","clk":"11849507721","pt":1723668537686,"mc":[{"id":"1.231815703","rc":[{"batb":[[0,3.9,14.21],[1,2,100],[2,1.5,200]],"ltp":4.1,"tv":237.29,"id":12474498}]}]}
{"op":"mcm","clk":"11849507816","pt":1723668540041,"mc":[{"id":"1.231815703","rc":[{"batb":[[0,3.95,10.05],[1,3.9,14.16],[2,2,100]],"ltp":4.1,"tv":237.29,"id":12474498}]}]}
{"op":"mcm","clk":"11849507987","pt":1723668543226,"mc":[{"id":"1.231815703","rc":[{"batb":[[0,3.9,14.21],[1,2,100],[2,1.5,200]],"ltp":4.1,"tv":237.29,"id":12474498}]}]}
{"op":"mcm","clk":"11849508121","pt":1723668545845,"mc":[{"id":"1.231815703","rc":[{"batb":[[0,3.95,10.05],[1,3.9,14.16],[2,2,100]],"ltp":4.1,"tv":237.29,"id":12474498}]}]}
{"op":"mcm","clk":"11849508288","pt":1723668549129,"mc":[{"id":"1.231815703","rc":[{"batb":[[0,3.9,14.21],[1,2,100],[2,1.5,200]],"ltp":4.1,"tv":237.29,"id":12474498}]}]}
{"op":"mcm","clk":"11849508426","pt":1723668551539,"mc":[{"id":"1.231815703","rc":[{"batb":[[0,3.95,10.05],[1,3.9,14.16],[2,2,100]],"ltp":4.1,"tv":237.29,"id":12474498}]}]}
{"op":"mcm","clk":"11849508589","pt":1723668554728,"mc":[{"id":"1.231815703","rc":[{"batb":[[0,3.9,14.21],[1,2,100],[2,1.5,200]],"ltp":4.1,"tv":237.29,"id":12474498}]}]}
{"op":"mcm","clk":"11849508702","pt":1723668557341,"mc":[{"id":"1.231815703","rc":[{"batb":[[0,3.95,10.05],[1,3.9,14.16],[2,2,100]],"ltp":4.1,"tv":237.29,"id":12474498}]}]}
{"op":"mcm","clk":"11849508847","pt":1723668560519,"mc":[{"id":"1.231815703","rc":[{"batb":[[0,3.9,14.21],[1,2,100],[2,1.5,200]],"ltp":4.1,"tv":237.29,"id":12474498}]}]}
{"op":"mcm","clk":"11849508970","pt":1723668562931,"mc":[{"id":"1.231815703","rc":[{"batb":[[0,3.95,10.05],[1,3.9,14.16],[2,2,100]],"ltp":4.1,"tv":237.29,"id":12474498}]}]}
{"op":"mcm","clk":"11849509136","pt":1723668566116,"mc":[{"id":"1.231815703","rc":[{"batb":[[0,3.9,14.21],[1,2,100],[2,1.5,200]],"ltp":4.1,"tv":237.29,"id":12474498}]}]}
{"op":"mcm","clk":"11849509265","pt":1723668568627,"mc":[{"id":"1.231815703","rc":[{"batb":[[0,3.95,10.05],[1,3.9,14.16],[2,2,100]],"ltp":4.1,"tv":237.29,"id":12474498}]}]}
{"op":"mcm","clk":"11849509444","pt":1723668571861,"mc":[{"id":"1.231815703","rc":[{"batb":[[0,3.9,14.21],[1,2,100],[2,1.5,200]],"ltp":4.1,"tv":237.29,"id":12474498}]}]}
{"op":"mcm","clk":"11849509551","pt":1723668574368,"mc":[{"id":"1.231815703","rc":[{"batb":[[0,3.95,10.05],[1,3.9,14.16],[2,2,100]],"ltp":4.1,"tv":237.29,"id":12474498}]}]}
{"op":"mcm","clk":"11849509680","pt":1723668577639,"mc":[{"id":"1.231815703","rc":[{"batb":[[0,3.9,14.21],[1,2,100],[2,1.5,200]],"ltp":4.1,"tv":237.29,"id":12474498}]}]}
{"op":"mcm","clk":"11849509799","pt":1723668579944,"mc":[{"id":"1.231815703","rc":[{"batb":[[0,3.95,10.05],[1,3.9,14.16],[2,2,100]],"ltp":4.1,"tv":237.29,"id":12474498}]}]}
{"op":"mcm","clk":"11849509934","pt":1723668583168,"mc":[{"id":"1.231815703","rc":[{"batb":[[0,3.9,14.21],[1,2,100],[2,1.5,200]],"ltp":4.1,"tv":237.29,"id":12474498}]}]}
{"op":"mcm","clk":"11849509982","pt":1723668584144,"mc":[{"id":"1.231815703","rc":[{"batb":[[0,3.95,8.4],[1,3.9,14.16],[2,2,100]],"ltp":4.1,"tv":237.29,"id":12474498},{"batb":[[0,1.3,50.4]],"ltp":1.33,"tv":823.36,"id":12482925}]}]}
{"op":"mcm","clk":"11849510043","pt":1723668585269,"mc":[{"id":"1.231815703","rc":[{"batb":[[0,4,10.05],[1,3.95,8.35],[2,3.9,14.16]],"ltp":4.1,"tv":237.29,"id":12474498}]}]}
{"op":"mcm","clk":"11849510182","pt":1723668588495,"mc":[{"id":"1.231815703","rc":[{"batb":[[0,3.95,8.4],[1,3.9,14.16],[2,2,100]],"ltp":4.1,"tv":237.29,"id":12474498}]}]}
{"op":"mcm","clk":"11849510318","pt":1723668591084,"mc":[{"id":"1.231815703","rc":[{"batb":[[0,4,10.05],[1,3.95,8.35],[2,3.9,14.16]],"ltp":4.1,"tv":237.29,"id":12474498}]}]}
{"op":"mcm","clk":"11849510511","pt":1723668594472,"mc":[{"id":"1.231815703","rc":[{"batb":[[0,3.95,8.4],[1,3.9,14.16],[2,2,100]],"ltp":4.1,"tv":237.29,"id":12474498}]}]}
{"op":"mcm","clk":"11849510636","pt":1723668596978,"mc":[{"id":"1.231815703","rc":[{"batb":[[0,4,10.05],[1,3.95,8.35],[2,3.9,14.16]],"ltp":4.1,"tv":237.29,"id":12474498}]}]}
{"op":"mcm","clk":"11849510779","pt":1723668600208,"mc":[{"id":"1.231815703","rc":[{"batb":[[0,3.95,8.4],[1,3.9,14.16],[2,2,100]],"ltp":4.1,"tv":237.29,"id":12474498}]}]}
{"op":"mcm","clk":"11849510949","pt":1723668603698,"mc":[{"id":"1.231815703","rc":[{"batb":[[0,4,10.05],[1,3.95,8.35],[2,3.9,14.16]],"ltp":4.1,"tv":237.29,"id":12474498}]}]}
{"op":"mcm","clk":"11849510973","pt":1723668604111,"mc":[{"id":"1.231815703","rc":[{"batb":[[2,1.26,51.57]],"ltp":1.33,"tv":823.36,"id":12482925}]}]}
{"op":"mcm","clk":"11849511138","pt":1723668607190,"mc":[{"id":"1.231815703","rc":[{"batb":[[0,3.95,8.4],[1,3.9,14.16],[2,3.35,16.7]],"ltp":4.1,"tv":237.29,"id":12474498}]}]}
{"op":"mcm","clk":"11849511266","pt":1723668610012,"mc":[{"id":"1.231815703","rc":[{"batb":[[0,4,10.05],[1,3.95,8.35],[2,3.9,14.16]],"ltp":4.1,"tv":237.29,"id":12474498}]}]}
{"op":"mcm","clk":"11849511457","pt":1723668613397,"mc":[{"id":"1.231815703","rc":[{"batb":[[0,3.95,8.4],[1,3.9,14.16],[2,3.35,16.7]],"ltp":4.1,"tv":237.29,"id":12474498}]}]}
{"op":"mcm","clk":"11849511618","pt":1723668616545,"mc":[{"id":"1.231815703","rc":[{"batb":[[0,4,10.05],[1,3.95,8.35],[2,3.9,14.16]],"ltp":4.1,"tv":237.29,"id":12474498}]}]}
{"op":"mcm","clk":"11849511736","pt":1723668619831,"mc":[{"id":"1.231815703","rc":[{"batb":[[0,3.95,8.4],[1,3.9,14.16],[2,3.35,16.7]],"ltp":4.1,"tv":237.29,"id":12474498}]}]}
{"op":"mcm","clk":"11849511821","pt":1723668622136,"mc":[{"id":"1.231815703","rc":[{"batb":[[0,4,10.05],[1,3.95,8.35],[2,3.9,14.16]],"ltp":4.1,"tv":237.29,"id":12474498}]}]}
{"op":"mcm","clk":"11849511997","pt":1723668625520,"mc":[{"id":"1.231815703","rc":[{"batb":[[0,3.95,8.4],[1,3.9,14.16],[2,3.35,16.7]],"ltp":4.1,"tv":237.29,"id":12474498}]}]}
{"op":"mcm","clk":"11849512145","pt":1723668628041,"mc":[{"id":"1.231815703","rc":[{"batb":[[0,4,10.05],[1,3.95,8.35],[2,3.9,14.16]],"ltp":4.1,"tv":237.29,"id":12474498}]}]}
{"op":"mcm","clk":"11849512290","pt":1723668631332,"mc":[{"id":"1.231815703","rc":[{"batb":[[0,3.95,8.4],[1,3.9,14.16],[2,3.35,16.7]],"ltp":4.1,"tv":237.29,"id":12474498}]}]}
{"op":"mcm","clk":"11849512440","pt":1723668633749,"mc":[{"id":"1.231815703","rc":[{"batb":[[0,4,10.05],[1,3.95,8.35],[2,3.9,14.16]],"ltp":4.1,"tv":237.29,"id":12474498}]}]}
{"op":"mcm","clk":"11849512707","pt":1723668637288,"mc":[{"id":"1.231815703","rc":[{"batb":[[0,3.95,8.4],[1,3.9,14.16],[2,3.35,16.7]],"ltp":4.1,"tv":237.29,"id":12474498}]}]}
{"op":"mcm","clk":"11849512811","pt":1723668639552,"mc":[{"id":"1.231815703","rc":[{"batb":[[0,4,10.05],[1,3.95,8.35],[2,3.9,14.16]],"ltp":4.1,"tv":237.29,"id":12474498}]}]}
{"op":"mcm","clk":"11849512995","pt":1723668642985,"mc":[{"id":"1.231815703","rc":[{"batb":[[0,3.95,8.4],[1,3.9,14.16],[2,3.35,16.7]],"ltp":4.1,"tv":237.29,"id":12474498}]}]}
{"op":"mcm","clk":"11849513122","pt":1723668645520,"mc":[{"id":"1.231815703","rc":[{"batb":[[0,4,10.05],[1,3.95,8.35],[2,3.9,14.16]],"ltp":4.1,"tv":237.29,"id":12474498}]}]}
{"op":"mcm","clk":"11849513259","pt":1723668648790,"mc":[{"id":"1.231815703","rc":[{"batb":[[0,3.95,8.4],[1,3.9,14.16],[2,3.35,16.7]],"ltp":4.1,"tv":237.29,"id":12474498}]}]}
{"op":"mcm","clk":"11849513380","pt":1723668651181,"mc":[{"id":"1.231815703","rc":[{"batb":[[0,4,10.05],[1,3.95,8.35],[2,3.9,14.16]],"ltp":4.1,"tv":237.29,"id":12474498}]}]}
{"op":"mcm","clk":"11849513510","pt":1723668654501,"mc":[{"id":"1.231815703","rc":[{"batb":[[0,3.95,8.4],[1,3.9,14.16],[2,3.35,16.7]],"ltp":4.1,"tv":237.29,"id":12474498}]}]}
{"op":"mcm","clk":"11849513613","pt":1723668656702,"mc":[{"id":"1.231815703","rc":[{"batb":[[0,4,10.05],[1,3.95,8.35],[2,3.9,14.16]],"ltp":4.1,"tv":237.29,"id":12474498}]}]}
{"op":"mcm","clk":"11849513738","pt":1723668659885,"mc":[{"id":"1.231815703","rc":[{"batb":[[0,3.95,8.4],[1,3.9,14.16],[2,3.35,16.7]],"ltp":4.1,"tv":237.29,"id":12474498}]}]}
{"op":"mcm","clk":"11849513810","pt":1723668662297,"mc":[{"id":"1.231815703","rc":[{"batb":[[0,4,10.05],[1,3.95,8.35],[2,3.9,14.16]],"ltp":4.1,"tv":237.29,"id":12474498}]}]}
{"op":"mcm","clk":"11849513958","pt":1723668665618,"mc":[{"id":"1.231815703","rc":[{"batb":[[0,3.95,8.4],[1,3.9,14.16],[2,3.35,16.7]],"ltp":4.1,"tv":237.29,"id":12474498}]}]}
{"op":"mcm","clk":"11849514108","pt":1723668668800,"mc":[{"id":"1.231815703","rc":[{"batb":[[0,4,10.05],[1,3.95,8.35],[2,3.9,14.16]],"ltp":4.1,"tv":237.29,"id":12474498}]}]}
{"op":"mcm","clk":"11849514235","pt":1723668672224,"mc":[{"id":"1.231815703","rc":[{"batb":[[0,3.95,8.4],[1,3.9,14.16],[2,3.35,16.7]],"ltp":4.1,"tv":237.29,"id":12474498}]}]}
{"op":"mcm","clk":"11849514349","pt":1723668674629,"mc":[{"id":"1.231815703","rc":[{"batb":[[0,4,10.05],[1,3.95,8.35],[2,3.9,14.16]],"ltp":4.1,"tv":237.29,"id":12474498}]}]}
{"op":"mcm","clk":"11849514514","pt":1723668678114,"mc":[{"id":"1.231815703","rc":[{"batb":[[0,3.95,8.4],[1,3.9,14.16],[2,3.35,16.7]],"ltp":4.1,"tv":237.29,"id":12474498}]}]}
{"op":"mcm","clk":"11849514609","pt":1723668680623,"mc":[{"id":"1.231815703","rc":[{"batb":[[0,4,10.05],[1,3.95,8.35],[2,3.9,14.16]],"ltp":4.1,"tv":237.29,"id":12474498}]}]}
{"op":"mcm","clk":"11849514755","pt":1723668684047,"mc":[{"id":"1.231815703","rc":[{"batb":[[0,3.95,8.4],[1,3.9,14.16],[2,3.35,16.7]],"ltp":4.1,"tv":237.29,"id":12474498}]}]}
{"op":"mcm","clk":"11849514859","pt":1723668686401,"mc":[{"id":"1.231815703","rc":[{"batb":[[0,4,10.05],[1,3.95,8.35],[2,3.9,14.16]],"ltp":4.1,"tv":237.29,"id":12474498}]}]}
{"op":"mcm","clk":"11849515015","pt":1723668689829,"mc":[{"id":"1.231815703","rc":[{"batb":[[0,3.95,8.4],[1,3.9,14.16],[2,3.35,16.7]],"ltp":4.1,"tv":237.29,"id":12474498}]}]}
{"op":"mcm","clk":"11849515134","pt":1723668692338,"mc":[{"id":"1.231815703","rc":[{"batb":[[0,4,10.05],[1,3.95,8.35],[2,3.9,14.16]],"ltp":4.1,"tv":237.29,"id":12474498}]}]}
{"op":"mcm","clk":"11849515323","pt":1723668695718,"mc":[{"id":"1.231815703","rc":[{"batb":[[0,3.95,8.4],[1,3.9,14.16],[2,3.35,16.7]],"ltp":4.1,"tv":237.29,"id":12474498}]}]}
{"op":"mcm","clk":"11849515459","pt":1723668698127,"mc":[{"id":"1.231815703","rc":[{"batb":[[0,4,10.05],[1,3.95,8.35],[2,3.9,14.16]],"ltp":4.1,"tv":237.29,"id":12474498}]}]}
{"op":"mcm","clk":"11849515644","pt":1723668701565,"mc":[{"id":"1.231815703","rc":[{"batb":[[0,3.95,8.4],[1,3.9,14.16],[2,3.35,16.7]],"ltp":4.1,"tv":237.29,"id":12474498}]}]}
{"op":"mcm","clk":"11849515774","pt":1723668703771,"mc":[{"id":"1.231815703","rc":[{"batb":[[0,4,10.05],[1,3.95,8.35],[2,3.9,14.16]],"ltp":4.1,"tv":237.29,"id":12474498}]}]}
{"op":"mcm","clk":"11849515931","pt":1723668707258,"mc":[{"id":"1.231815703","rc":[{"batb":[[0,3.95,8.4],[1,3.9,14.16],[2,3.35,16.7]],"ltp":4.1,"tv":237.29,"id":12474498}]}]}
{"op":"mcm","clk":"11849516103","pt":1723668710342,"mc":[{"id":"1.231815703","rc":[{"batb":[[0,4,10.05],[1,3.95,8.35],[2,3.9,14.16]],"ltp":4.1,"tv":237.29,"id":12474498}]}]}
{"op":"mcm","clk":"11849516285","pt":1723668713680,"mc":[{"id":"1.231815703","rc":[{"batb":[[0,3.95,8.4],[1,3.9,14.16],[2,3.35,16.7]],"ltp":4.1,"tv":237.29,"id":12474498}]}]}
{"op":"mcm","clk":"11849516394","pt":1723668716042,"mc":[{"id":"1.231815703","rc":[{"batb":[[0,4,10.05],[1,3.95,8.35],[2,3.9,14.16]],"ltp":4.1,"tv":237.29,"id":12474498}]}]}
{"op":"mcm","clk":"11849516558","pt":1723668719475,"mc":[{"id":"1.231815703","rc":[{"batb":[[0,3.95,8.4],[1,3.9,14.16],[2,3.35,16.7]],"ltp":4.1,"tv":237.29,"id":12474498}]}]}
{"op":"mcm","clk":"11849516649","pt":1723668721884,"mc":[{"id":"1.231815703","rc":[{"batb":[[0,4,10.05],[1,3.95,8.35],[2,3.9,14.16]],"ltp":4.1,"tv":237.29,"id":12474498}]}]}
{"op":"mcm","clk":"11849516792","pt":1723668725371,"mc":[{"id":"1.231815703","rc":[{"batb":[[0,3.95,8.4],[1,3.9,14.16],[2,3.35,16.7]],"ltp":4.1,"tv":237.29,"id":12474498}]}]}
{"op":"mcm","clk":"11849516892","pt":1723668727573,"mc":[{"id":"1.231815703","rc":[{"batb":[[0,4,10.05],[1,3.95,8.35],[2,3.9,14.16]],"ltp":4.1,"tv":237.29,"id":12474498}]}]}
{"op":"mcm","clk":"11849517040","pt":1723668730864,"mc":[{"id":"1.231815703","rc":[{"batb":[[0,3.95,8.4],[1,3.9,14.16],[2,3.35,16.7]],"ltp":4.1,"tv":237.29,"id":12474498}]}]}
{"op":"mcm","clk":"11849517142","pt":1723668733928,"mc":[{"id":"1.231815703","rc":[{"batb":[[0,4,10.05],[1,3.95,8.35],[2,3.9,14.16]],"ltp":4.1,"tv":237.29,"id":12474498}]}]}
{"op":"mcm","clk":"11849517270","pt":1723668736807,"mc":[{"id":"1.231815703","rc":[{"batb":[[0,3.95,8.4],[1,3.9,14.16],[2,3.35,16.7]],"ltp":4.1,"tv":237.29,"id":12474498}]}]}
{"op":"mcm","clk":"11849517368","pt":1723668739378,"mc":[{"id":"1.231815703","rc":[{"batb":[[0,4,10.05],[1,3.95,8.35],[2,3.9,14.16]],"ltp":4.1,"tv":237.29,"id":12474498}]}]}
{"op":"mcm","clk":"11849517510","pt":1723668742604,"mc":[{"id":"1.231815703","rc":[{"batb":[[0,3.95,8.4],[1,3.9,14.16],[2,3.35,16.7]],"ltp":4.1,"tv":237.29,"id":12474498}]}]}
{"op":"mcm","clk":"11849517633","pt":1723668745213,"mc":[{"id":"1.231815703","rc":[{"batb":[[0,4,10.05],[1,3.95,8.35],[2,3.9,14.16]],"ltp":4.1,"tv":237.29,"id":12474498}]}]}
{"op":"mcm","clk":"11849517795","pt":1723668748598,"mc":[{"id":"1.231815703","rc":[{"batb":[[0,3.95,8.4],[1,3.9,14.16],[2,3.35,16.7]],"ltp":4.1,"tv":237.29,"id":12474498}]}]}
{"op":"mcm","clk":"11849517865","pt":1723668750796,"mc":[{"id":"1.231815703","rc":[{"batb":[[0,4,10.05],[1,3.95,8.35],[2,3.9,14.16]],"ltp":4.1,"tv":237.29,"id":12474498}]}]}
{"op":"mcm","clk":"11849518027","pt":1723668754120,"mc":[{"id":"1.231815703","rc":[{"batb":[[0,3.95,8.4],[1,3.9,14.16],[2,3.35,16.7]],"ltp":4.1,"tv":237.29,"id":12474498}]}]}
{"op":"mcm","clk":"11849518129","pt":1723668757505,"mc":[{"id":"1.231815703","rc":[{"batb":[[0,4,10.05],[1,3.95,8.35],[2,3.9,14.16]],"ltp":4.1,"tv":237.29,"id":12474498}]}]}
{"op":"mcm","clk":"11849518264","pt":1723668760939,"mc":[{"id":"1.231815703","rc":[{"batb":[[0,3.95,8.4],[1,3.9,14.16],[2,3.35,16.7]],"ltp":4.1,"tv":237.29,"id":12474498}]}]}
{"op":"mcm","clk":"11849518368","pt":1723668763345,"mc":[{"id":"1.231815703","rc":[{"batb":[[0,4,10.05],[1,3.95,8.35],[2,3.9,14.16]],"ltp":4.1,"tv":237.29,"id":12474498}]}]}
{"op":"mcm","clk":"11849518505","pt":1723668766757,"mc":[{"id":"1.231815703","rc":[{"batb":[[0,3.95,8.4],[1,3.9,14.16],[2,3.35,16.7]],"ltp":4.1,"tv":237.29,"id":12474498}]}]}
{"op":"mcm","clk":"11849518590","pt":1723668768839,"mc":[{"id":"1.231815703","rc":[{"batb":[[0,4,10.05],[1,3.95,8.35],[2,3.9,14.16]],"ltp":4.1,"tv":237.29,"id":12474498}]}]}
{"op":"mcm","clk":"11849518713","pt":1723668772125,"mc":[{"id":"1.231815703","rc":[{"batb":[[0,3.95,8.4],[1,3.9,14.16],[2,3.35,16.7]],"ltp":4.1,"tv":237.29,"id":12474498}]}]}
{"op":"mcm","clk":"11849518839","pt":1723668774630,"mc":[{"id":"1.231815703","rc":[{"batb":[[0,4,10.05],[1,3.95,8.35],[2,3.9,14.16]],"ltp":4.1,"tv":237.29,"id":12474498}]}]}
{"op":"mcm","clk":"11849518976","pt":1723668777955,"mc":[{"id":"1.231815703","rc":[{"batb":[[0,3.95,8.4],[1,3.9,14.16],[2,3.35,16.7]],"ltp":4.1,"tv":237.29,"id":12474498}]}]}
{"op":"mcm","clk":"11849519099","pt":1723668780258,"mc":[{"id":"1.231815703","rc":[{"batb":[[0,4,10.05],[1,3.95,8.35],[2,3.9,14.16]],"ltp":4.1,"tv":237.29,"id":12474498}]}]}
{"op":"mcm","clk":"11849519284","pt":1723668783639,"mc":[{"id":"1.231815703","rc":[{"batb":[[0,3.95,8.4],[1,3.9,14.16],[2,3.35,16.7]],"ltp":4.1,"tv":237.29,"id":12474498}]}]}
{"op":"mcm","clk":"11849519389","pt":1723668786042,"mc":[{"id":"1.231815703","rc":[{"batb":[[0,4,10.05],[1,3.95,8.35],[2,3.9,14.16]],"ltp":4.1,"tv":237.29,"id":12474498}]}]}
{"op":"mcm","clk":"11849519541","pt":1723668789364,"mc":[{"id":"1.231815703","rc":[{"batb":[[0,3.95,8.4],[1,3.9,14.16],[2,3.35,16.7]],"ltp":4.1,"tv":237.29,"id":12474498}]}]}
{"op":"mcm","clk":"11849519726","pt":1723668793365,"mc":[{"id":"1.231815703","rc":[{"batb":[[0,4,10.05],[1,3.95,8.35],[2,3.9,14.16]],"ltp":4.1,"tv":237.29,"id":12474498}]}]}
{"op":"mcm","clk":"11849519864","pt":1723668796696,"mc":[{"id":"1.231815703","rc":[{"batb":[[0,3.95,8.4],[1,3.9,14.16],[2,3.35,16.7]],"ltp":4.1,"tv":237.29,"id":12474498}]}]}
{"op":"mcm","clk":"11849519954","pt":1723668799198,"mc":[{"id":"1.231815703","rc":[{"batb":[[0,4,10.05],[1,3.95,8.35],[2,3.9,14.16]],"ltp":4.1,"tv":237.29,"id":12474498}]}]}
