{"op":"mcm","clk":"11953422615","pt":1724523367280,"mc":[{"id":"1.232239000","marketDefinition":{"bspMarket":false,"turnInPlayEnabled":true,"persistenceEnabled":true,"marketBaseRate":5.0,"eventId":"33524183","eventTypeId":"4","numberOfWinners":1,"bettingType":"ODDS","marketType":"MATCH_ODDS","marketTime":"2024-08-25T14:30:00.000Z","suspendTime":"2024-08-25T14:30:00.000Z","bspReconciled":false,"complete":true,"inPlay":false,"crossMatching":false,"runnersVoidable":false,"numberOfActiveRunners":2,"betDelay":0,"status":"OPEN","runners":[{"status":"ACTIVE","sortPriority":1,"id":60971786,"name":"Greece"},{"status":"ACTIVE","sortPriority":2,"id":24640635,"name":"Spain"}],"regulators":["MR_INT"],"countryCode":"GB","discountAllowed":false,"timezone":"GMT","openDate":"2024-08-25T14:30:00.000Z","version":6096631961,"name":"Match Odds","eventName":"Greece v Spain"},"rc":[{"batb":[[0,1.03,200],[1,1.02,200],[2,1.01,220]],"ltp":0.0,"tv":0.0,"id":24640635},{"batb":[[0,1.03,200],[1,1.02,200],[2,1.01,220]],"ltp":0.0,"tv":0.0,"id":60971786}]}]}
{"op":"mcm","clk":"11953422836","pt":1724523368507,"mc":[{"id":"1.232239000","marketDefinition":{"bspMarket":false,"turnInPlayEnabled":true,"persistenceEnabled":true,"marketBaseRate":5.0,"eventId":"33524183","eventTypeId":"4","numberOfWinners":1,"bettingType":"ODDS","marketType":"MATCH_ODDS","marketTime":"2024-08-25T14:30:00.000Z","suspendTime":"2024-08-25T14:30:00.000Z","bspReconciled":false,"complete":true,"inPlay":false,"crossMatching":false,"runnersVoidable":false,"numberOfActiveRunners":2,"betDelay":0,"status":"OPEN","runners":[{"status":"ACTIVE","sortPriority":1,"id":60971786,"name":"Greece"},{"status":"ACTIVE","sortPriority":2,"id":24640635,"name":"Spain"}],"regulators":["MR_INT"],"countryCode":"GB","discountAllowed":true,"timezone":"GMT","openDate":"2024-08-25T14:30:00.000Z","version":6096631961,"name":"Match Odds","eventName":"Greece v Spain"}}]}
{"op":"mcm","clk":"11953855548","pt":1724525369864,"mc":[{"id":"1.232239000","rc":[{"batb":[[0,1.05,500],[1,1.03,200],[2,1.02,200]],"ltp":0.0,"tv":0.0,"id":24640635},{"batb":[[0,12.5,5],[1,1.03,200],[2,1.02,200]],"ltp":0.0,"tv":0.0,"id":60971786}]}]}
{"op":"mcm","clk":"11953858182","pt":1724525382252,"mc":[{"id":"1.232239000","marketDefinition":{"bspMarket":false,"turnInPlayEnabled":true,"persistenceEnabled":true,"marketBaseRate":5.0,"eventId":"33524183","eventTypeId":"4","numberOfWinners":1,"bettingType":"ODDS","marketType":"MATCH_ODDS","marketTime":"2024-08-25T14:30:00.000Z","suspendTime":"2024-08-25T14:30:00.000Z","bspReconciled":false,"complete":true,"inPlay":false,"crossMatching":true,"runnersVoidable":false,"numberOfActiveRunners":2,"betDelay":0,"status":"OPEN","runners":[{"status":"ACTIVE","sortPriority":1,"id":60971786,"name":"Greece"},{"status":"ACTIVE","sortPriority":2,"id":24640635,"name":"Spain"}],"regulators":["MR_INT"],"countryCode":"GB","discountAllowed":true,"timezone":"GMT","openDate":"2024-08-25T14:30:00.000Z","version":6096631961,"name":"Match Odds","eventName":"Greece v Spain"}}]}
{"op":"mcm","clk":"11954093168","pt":1724526482303,"mc":[{"id":"1.232239000","rc":[{"batb":[[1,1.04,1.05],[2,1.03,200]],"ltp":0.0,"tv":0.0,"id":24640635},{"batb":[[1,1.04,1.05],[2,1.03,200]],"ltp":0.0,"tv":0.0,"id":60971786}]}]}
{"op":"mcm","clk":"11955039421","pt":1724530544928,"mc":[{"id":"1.232239000","rc":[{"trd":[[1.09,1.18]],"ltp":1.09,"tv":1.18,"id":24640635},{"trd":[[12.5,0.1]],"batb":[[0,12.5,4.9]],"ltp":12.5,"tv":0.1,"id":60971786}],"tv":1.28}]}
{"op":"mcm","clk":"11955039835","pt":1724530547175,"mc":[{"id":"1.232239000","rc":[{"batb":[[0,12.5,5]],"ltp":12.5,"tv":0.1,"id":60971786}]}]}
{"op":"mcm","clk":"11955466463","pt":1724533479671,"mc":[{"id":"1.232239000","rc":[{"batl":[[0,1.08,30]],"ltp":1.09,"tv":1.18,"id":24640635}]}]}
{"op":"mcm","clk":"11955516002","pt":1724533889777,"mc":[{"id":"1.232239000","rc":[{"trd":[[1.08,6.43]],"batl":[[0,1.08,23.57]],"ltp":1.08,"tv":7.6,"id":24640635},{"trd":[[13.5,0.51]],"ltp":13.5,"tv":0.61,"id":60971786}],"tv":8.22}]}
{"op":"mcm","clk":"11955569767","pt":1724534363165,"mc":[{"id":"1.232239000","rc":[{"batl":[[0,21,0.51]],"ltp":13.5,"tv":0.61,"id":60971786}]}]}
{"op":"mcm","clk":"11956612712","pt":1724547168660,"mc":[{"id":"1.232239000","rc":[{"trd":[[1.08,30]],"ltp":1.08,"tv":31.18,"id":24640635},{"trd":[[13.5,2.4]],"batl":[[0,13.5,3.11],[1,21,0.51]],"ltp":13.5,"tv":2.5,"id":60971786}],"tv":33.68}]}
{"op":"mcm","clk":"11956614326","pt":1724547190664,"mc":[{"id":"1.232239000","rc":[{"batl":[[0,21,0.51],[1,21,0]],"ltp":13.5,"tv":2.5,"id":60971786}]}]}
{"op":"mcm","clk":"11956616548","pt":1724547223721,"mc":[{"id":"1.232239000","rc":[{"trd":[[12.5,6.32]],"batb":[[0,12.5,1.89]],"ltp":12.5,"tv":8.72,"id":60971786}],"tv":39.9}]}
{"op":"mcm","clk":"11956616859","pt":1724547228735,"mc":[{"id":"1.232239000","rc":[{"batb":[[0,12.5,5]],"ltp":12.5,"tv":8.72,"id":60971786}]}]}
{"op":"mcm","clk":"11957651817","pt":1724561920607,"mc":[{"id":"1.232239000","rc":[{"batl":[[0,14,0.76]],"ltp":1.08,"tv":31.18,"id":24640635},{"batl":[[0,21,1.27]],"ltp":12.5,"tv":8.72,"id":60971786}]}]}
{"op":"mcm","clk":"11957652895","pt":1724561938242,"mc":[{"id":"1.232239000","rc":[{"batl":[[0,21,0.51]],"ltp":12.5,"tv":8.72,"id":60971786}]}]}
{"op":"mcm","clk":"11957655507","pt":1724561978193,"mc":[{"id":"1.232239000","rc":[{"batb":[[2,1.03,200.76]],"ltp":1.08,"tv":31.18,"id":24640635},{"batb":[[2,1.03,200.76]],"ltp":12.5,"tv":8.72,"id":60971786}]}]}
{"op":"mcm","clk":"11957656223","pt":1724561989670,"mc":[{"id":"1.232239000","rc":[{"batb":[[1,1.04,1.81]],"ltp":1.08,"tv":31.18,"id":24640635},{"batb":[[1,1.04,1.81]],"ltp":12.5,"tv":8.72,"id":60971786}]}]}
{"op":"mcm","clk":"11957657100","pt":1724562003224,"mc":[{"id":"1.232239000","rc":[{"batb":[[0,1.05,500.76]],"ltp":1.08,"tv":31.18,"id":24640635},{"batb":[[1,1.04,2.56]],"ltp":12.5,"tv":8.72,"id":60971786}]}]}
{"op":"mcm","clk":"11957696411","pt":1724562624409,"mc":[{"id":"1.232239000","rc":[{"batb":[[0,1.05,700.76],[1,1.04,251.81],[2,1.03,534.09]],"ltp":1.08,"tv":31.18,"id":24640635},{"batb":[[1,1.05,200.76],[2,1.04,251.81]],"ltp":12.5,"tv":8.72,"id":60971786}]}]}
{"op":"mcm","clk":"11957698087","pt":1724562658040,"mc":[{"id":"1.232239000","rc":[{"batl":[[0,2,150]],"ltp":1.08,"tv":31.18,"id":24640635}]}]}
{"op":"mcm","clk":"11957698362","pt":1724562662522,"mc":[{"id":"1.232239000","rc":[{"batl":[[0,1.8,150]],"ltp":1.08,"tv":31.18,"id":24640635}]}]}
{"op":"mcm","clk":"11957754643","pt":1724563499524,"mc":[{"id":"1.232239000","rc":[{"batb":[[1,2.1,4.09],[2,1.05,200.76]],"ltp":12.5,"tv":8.72,"id":60971786}]}]}
{"op":"mcm","clk":"11957759430","pt":1724563594707,"mc":[{"id":"1.232239000","rc":[{"trd":[[12.5,7.38]],"batb":[[0,12.5,4.47]],"ltp":12.5,"tv":9.78,"id":60971786}],"tv":40.96}]}
{"op":"mcm","clk":"11957759511","pt":1724563596238,"mc":[{"id":"1.232239000","rc":[{"batb":[[0,12.5,5]],"ltp":12.5,"tv":9.78,"id":60971786}]}]}
{"op":"mcm","clk":"11957798215","pt":1724564359688,"mc":[{"id":"1.232239000","rc":[{"batb":[[1,2.26,6.17],[2,2.1,4.09]],"ltp":12.5,"tv":9.78,"id":60971786}]}]}
{"op":"mcm","clk":"11957845919","pt":1724565235689,"mc":[{"id":"1.232239000","rc":[{"batb":[[0,1.06,2.64],[1,1.05,700.76],[2,1.04,251.81]],"ltp":1.08,"tv":31.18,"id":24640635}]}]}
{"op":"mcm","clk":"11957903812","pt":1724566271108,"mc":[{"id":"1.232239000","rc":[{"trd":[[1.06,4]],"batb":[[0,1.05,701.4],[1,1.04,251.81],[2,1.03,534.09]],"ltp":1.06,"tv":35.17,"id":24640635}],"tv":44.96}]}
{"op":"mcm","clk":"11957919501","pt":1724566533824,"mc":[{"id":"1.232239000","rc":[{"batb":[[0,1.05,700.76]],"ltp":1.06,"tv":35.17,"id":24640635}]}]}
{"op":"mcm","clk":"11957967047","pt":1724567164907,"mc":[{"id":"1.232239000","rc":[{"batl":[[0,1.8,328]],"ltp":1.06,"tv":35.17,"id":24640635}]}]}
{"op":"mcm","clk":"11957968800","pt":1724567191064,"mc":[{"id":"1.232239000","rc":[{"batl":[[0,1.8,178]],"ltp":1.06,"tv":35.17,"id":24640635}]}]}
{"op":"mcm","clk":"11958094937","pt":1724569057708,"mc":[{"id":"1.232239000","rc":[{"batl":[[0,1.09,50],[1,1.8,178]],"ltp":1.06,"tv":35.17,"id":24640635}]}]}
{"op":"mcm","clk":"11958095030","pt":1724569058945,"mc":[{"id":"1.232239000","rc":[{"batb":[[1,2.1,4.09],[2,1.05,200.76]],"ltp":12.5,"tv":9.78,"id":60971786}]}]}
{"op":"mcm","clk":"11958130064","pt":1724569569049,"mc":[{"id":"1.232239000","rc":[{"batb":[[0,12.5,34.85]],"ltp":12.5,"tv":9.78,"id":60971786}]}]}
{"op":"mcm","clk":"11958218866","pt":1724570899959,"mc":[{"id":"1.232239000","rc":[{"trd":[[12.5,7.94]],"ltp":12.5,"tv":10.34,"id":60971786}],"tv":45.52}]}
{"op":"mcm","clk":"11958888200","pt":1724577638731,"mc":[{"id":"1.232239000","rc":[{"trd":[[12.5,9.7]],"batb":[[0,12.5,33.97]],"ltp":12.5,"tv":12.1,"id":60971786}],"tv":47.28}]}
{"op":"mcm","clk":"11959034472","pt":1724578841649,"mc":[{"id":"1.232239000","rc":[{"batb":[[2,1.03,2733.66]],"ltp":1.06,"tv":35.17,"id":24640635}]}]}
{"op":"mcm","clk":"11959087197","pt":1724579175354,"mc":[{"id":"1.232239000","rc":[{"trd":[[1.09,135.99]],"batl":[[0,1.8,178],[1,1.8,0]],"ltp":1.09,"tv":169.99,"id":24640635},{"trd":[[12.5,12.74]],"batb":[[0,12.5,30.93]],"ltp":12.5,"tv":15.14,"id":60971786}],"tv":185.13}]}
{"op":"mcm","clk":"11959087221","pt":1724579175566,"mc":[{"id":"1.232239000","rc":[{"batb":[[0,13,5],[1,12.5,30.93],[2,2.1,4.09]],"ltp":12.5,"tv":15.14,"id":60971786}]}]}
{"op":"mcm","clk":"11959087616","pt":1724579178787,"mc":[{"id":"1.232239000","rc":[{"batl":[[1,5.6,16.5]],"ltp":1.09,"tv":169.99,"id":24640635},{"batb":[[0,12.5,30.93],[1,2.1,4.09],[2,1.05,200.76]],"ltp":12.5,"tv":15.14,"id":60971786}]}]}
{"op":"mcm","clk":"11959088021","pt":1724579182054,"mc":[{"id":"1.232239000","rc":[{"batb":[[0,13,5],[1,12.5,30.93],[2,2.1,4.09]],"ltp":12.5,"tv":15.14,"id":60971786}]}]}
{"op":"mcm","clk":"11959088447","pt":1724579185323,"mc":[{"id":"1.232239000","rc":[{"batb":[[0,12.5,30.93],[1,2.1,4.09],[2,1.05,200.76]],"ltp":12.5,"tv":15.14,"id":60971786}]}]}
{"op":"mcm","clk":"11959089232","pt":1724579191780,"mc":[{"id":"1.232239000","rc":[{"batb":[[0,13,5],[1,12.5,30.93],[2,2.1,4.09]],"ltp":12.5,"tv":15.14,"id":60971786}]}]}
{"op":"mcm","clk":"11959089630","pt":1724579195000,"mc":[{"id":"1.232239000","rc":[{"batb":[[0,12.5,30.93],[1,2.1,4.09],[2,1.05,200.76]],"ltp":12.5,"tv":15.14,"id":60971786}]}]}
{"op":"mcm","clk":"11959090820","pt":1724579205495,"mc":[{"id":"1.232239000","rc":[{"batb":[[0,13,5],[1,12.5,30.93],[2,2.1,4.09]],"ltp":12.5,"tv":15.14,"id":60971786}]}]}
{"op":"mcm","clk":"11959091238","pt":1724579208920,"mc":[{"id":"1.232239000","rc":[{"batb":[[0,12.5,30.93],[1,2.1,4.09],[2,1.05,200.76]],"ltp":12.5,"tv":15.14,"id":60971786}]}]}
{"op":"mcm","clk":"11959091634","pt":1724579212399,"mc":[{"id":"1.232239000","rc":[{"batb":[[0,13,5],[1,12.5,30.93],[2,2.1,4.09]],"ltp":12.5,"tv":15.14,"id":60971786}]}]}
{"op":"mcm","clk":"11959092087","pt":1724579215730,"mc":[{"id":"1.232239000","rc":[{"batb":[[0,12.5,30.93],[1,2.1,4.09],[2,1.05,200.76]],"ltp":12.5,"tv":15.14,"id":60971786}]}]}
{"op":"mcm","clk":"11959092704","pt":1724579220211,"mc":[{"id":"1.232239000","rc":[{"batb":[[0,13,5],[1,12.5,30.93],[2,2.1,4.09]],"ltp":12.5,"tv":15.14,"id":60971786}]}]}
{"op":"mcm","clk":"11959093231","pt":1724579223720,"mc":[{"id":"1.232239000","rc":[{"batb":[[0,12.5,30.93],[1,2.1,4.09],[2,1.05,200.76]],"ltp":12.5,"tv":15.14,"id":60971786}]}]}
{"op":"mcm","clk":"11959093798","pt":1724579227730,"mc":[{"id":"1.232239000","rc":[{"batb":[[0,13,5],[1,12.5,30.93],[2,2.1,4.09]],"ltp":12.5,"tv":15.14,"id":60971786}]}]}
{"op":"mcm","clk":"11959094224","pt":1724579231046,"mc":[{"id":"1.232239000","rc":[{"batb":[[0,12.5,30.93],[1,2.1,4.09],[2,1.05,200.76]],"ltp":12.5,"tv":15.14,"id":60971786}]}]}
{"op":"mcm","clk":"11959094583","pt":1724579234117,"mc":[{"id":"1.232239000","rc":[{"batb":[[0,13,5],[1,12.5,30.93],[2,2.1,4.09]],"ltp":12.5,"tv":15.14,"id":60971786}]}]}
{"op":"mcm","clk":"11959094971","pt":1724579237357,"mc":[{"id":"1.232239000","rc":[{"batb":[[0,12.5,30.93],[1,2.1,4.09],[2,1.05,200.76]],"ltp":12.5,"tv":15.14,"id":60971786}]}]}
{"op":"mcm","clk":"11959095360","pt":1724579240949,"mc":[{"id":"1.232239000","rc":[{"batb":[[0,13,5],[1,12.5,30.93],[2,2.1,4.09]],"ltp":12.5,"tv":15.14,"id":60971786}]}]}
{"op":"mcm","clk":"11959095735","pt":1724579244443,"mc":[{"id":"1.232239000","rc":[{"batb":[[0,12.5,30.93],[1,2.1,4.09],[2,1.05,200.76]],"ltp":12.5,"tv":15.14,"id":60971786}]}]}
{"op":"mcm","clk":"11959096447","pt":1724579250543,"mc":[{"id":"1.232239000","rc":[{"batb":[[0,13,5],[1,12.5,30.93],[2,2.1,4.09]],"ltp":12.5,"tv":15.14,"id":60971786}]}]}
{"op":"mcm","clk":"11959096888","pt":1724579253769,"mc":[{"id":"1.232239000","rc":[{"batb":[[0,12.5,30.93],[1,2.1,4.09],[2,1.05,200.76]],"ltp":12.5,"tv":15.14,"id":60971786}]}]}
{"op":"mcm","clk":"11959097807","pt":1724579262551,"mc":[{"id":"1.232239000","rc":[{"batb":[[0,13,5],[1,12.5,30.93],[2,2.1,4.09]],"ltp":12.5,"tv":15.14,"id":60971786}]}]}
{"op":"mcm","clk":"11959098168","pt":1724579265969,"mc":[{"id":"1.232239000","rc":[{"batb":[[0,12.5,30.93],[1,2.1,4.09],[2,1.05,200.76]],"ltp":12.5,"tv":15.14,"id":60971786}]}]}
{"op":"mcm","clk":"11959098986","pt":1724579273440,"mc":[{"id":"1.232239000","rc":[{"batb":[[0,13,5],[1,12.5,30.93],[2,2.1,4.09]],"ltp":12.5,"tv":15.14,"id":60971786}]}]}
{"op":"mcm","clk":"11959099341","pt":1724579276671,"mc":[{"id":"1.232239000","rc":[{"batb":[[0,12.5,30.93],[1,2.1,4.09],[2,1.05,200.76]],"ltp":12.5,"tv":15.14,"id":60971786}]}]}
{"op":"mcm","clk":"11959099689","pt":1724579279891,"mc":[{"id":"1.232239000","rc":[{"batb":[[0,13,5],[1,12.5,30.93],[2,2.1,4.09]],"ltp":12.5,"tv":15.14,"id":60971786}]}]}
{"op":"mcm","clk":"11959100126","pt":1724579283388,"mc":[{"id":"1.232239000","rc":[{"batb":[[0,12.5,30.93],[1,2.1,4.09],[2,1.05,200.76]],"ltp":12.5,"tv":15.14,"id":60971786}]}]}
{"op":"mcm","clk":"11959100574","pt":1724579287394,"mc":[{"id":"1.232239000","rc":[{"batb":[[0,13,5],[1,12.5,30.93],[2,2.1,4.09]],"ltp":12.5,"tv":15.14,"id":60971786}]}]}
{"op":"mcm","clk":"11959100962","pt":1724579290780,"mc":[{"id":"1.232239000","rc":[{"batb":[[0,12.5,30.93],[1,2.1,4.09],[2,1.05,200.76]],"ltp":12.5,"tv":15.14,"id":60971786}]}]}
{"op":"mcm","clk":"11959101616","pt":1724579296273,"mc":[{"id":"1.232239000","rc":[{"batb":[[0,13,5],[1,12.5,30.93],[2,2.1,4.09]],"ltp":12.5,"tv":15.14,"id":60971786}]}]}
{"op":"mcm","clk":"11959102060","pt":1724579299602,"mc":[{"id":"1.232239000","rc":[{"batb":[[0,12.5,30.93],[1,2.1,4.09],[2,1.05,200.76]],"ltp":12.5,"tv":15.14,"id":60971786}]}]}
{"op":"mcm","clk":"11959103614","pt":1724579310701,"mc":[{"id":"1.232239000","rc":[{"batb":[[0,13,5],[1,12.5,30.93],[2,2.1,4.09]],"ltp":12.5,"tv":15.14,"id":60971786}]}]}
{"op":"mcm","clk":"11959104026","pt":1724579313920,"mc":[{"id":"1.232239000","rc":[{"batb":[[0,12.5,30.93],[1,2.1,4.09],[2,1.05,200.76]],"ltp":12.5,"tv":15.14,"id":60971786}]}]}
{"op":"mcm","clk":"11959104529","pt":1724579317520,"mc":[{"id":"1.232239000","rc":[{"batb":[[0,13,5],[1,12.5,30.93],[2,2.1,4.09]],"ltp":12.5,"tv":15.14,"id":60971786}]}]}
{"op":"mcm","clk":"11959104908","pt":1724579320905,"mc":[{"id":"1.232239000","rc":[{"batb":[[0,12.5,30.93],[1,2.1,4.09],[2,1.05,200.76]],"ltp":12.5,"tv":15.14,"id":60971786}]}]}
{"op":"mcm","clk":"11959105470","pt":1724579325520,"mc":[{"id":"1.232239000","rc":[{"batb":[[0,13,5],[1,12.5,30.93],[2,2.1,4.09]],"ltp":12.5,"tv":15.14,"id":60971786}]}]}
{"op":"mcm","clk":"11959105867","pt":1724579328929,"mc":[{"id":"1.232239000","rc":[{"batb":[[0,12.5,30.93],[1,2.1,4.09],[2,1.05,200.76]],"ltp":12.5,"tv":15.14,"id":60971786}]}]}
{"op":"mcm","clk":"11959106710","pt":1724579336231,"mc":[{"id":"1.232239000","rc":[{"batb":[[0,13,5],[1,12.5,30.93],[2,2.1,4.09]],"ltp":12.5,"tv":15.14,"id":60971786}]}]}
{"op":"mcm","clk":"11959107077","pt":1724579339535,"mc":[{"id":"1.232239000","rc":[{"batb":[[0,12.5,30.93],[1,2.1,4.09],[2,1.05,200.76]],"ltp":12.5,"tv":15.14,"id":60971786}]}]}
{"op":"mcm","clk":"11959108787","pt":1724579353166,"mc":[{"id":"1.232239000","rc":[{"batb":[[0,13,5],[1,12.5,30.93],[2,2.1,4.09]],"ltp":12.5,"tv":15.14,"id":60971786}]}]}
{"op":"mcm","clk":"11959109162","pt":1724579356423,"mc":[{"id":"1.232239000","rc":[{"batb":[[0,12.5,30.93],[1,2.1,4.09],[2,1.05,200.76]],"ltp":12.5,"tv":15.14,"id":60971786}]}]}
{"op":"mcm","clk":"11959109953","pt":1724579363261,"mc":[{"id":"1.232239000","rc":[{"batb":[[0,13,5],[1,12.5,30.93],[2,2.1,4.09]],"ltp":12.5,"tv":15.14,"id":60971786}]}]}
{"op":"mcm","clk":"11959110387","pt":1724579366595,"mc":[{"id":"1.232239000","rc":[{"batb":[[0,12.5,30.93],[1,2.1,4.09],[2,1.05,200.76]],"ltp":12.5,"tv":15.14,"id":60971786}]}]}
{"op":"mcm","clk":"11959111355","pt":1724579372896,"mc":[{"id":"1.232239000","rc":[{"batb":[[0,13,5],[1,12.5,30.93],[2,2.1,4.09]],"ltp":12.5,"tv":15.14,"id":60971786}]}]}
{"op":"mcm","clk":"11959111846","pt":1724579376196,"mc":[{"id":"1.232239000","rc":[{"batb":[[0,12.5,30.93],[1,2.1,4.09],[2,1.05,200.76]],"ltp":12.5,"tv":15.14,"id":60971786}]}]}
{"op":"mcm","clk":"11959112809","pt":1724579383701,"mc":[{"id":"1.232239000","rc":[{"batb":[[0,13,5],[1,12.5,30.93],[2,2.1,4.09]],"ltp":12.5,"tv":15.14,"id":60971786}]}]}
{"op":"mcm","clk":"11959113238","pt":1724579386988,"mc":[{"id":"1.232239000","rc":[{"batb":[[0,12.5,30.93],[1,2.1,4.09],[2,1.05,200.76]],"ltp":12.5,"tv":15.14,"id":60971786}]}]}
{"op":"mcm","clk":"11959113647","pt":1724579389909,"mc":[{"id":"1.232239000","rc":[{"batb":[[0,13,5],[1,12.5,30.93],[2,2.1,4.09]],"ltp":12.5,"tv":15.14,"id":60971786}]}]}
{"op":"mcm","clk":"11959114110","pt":1724579393093,"mc":[{"id":"1.232239000","rc":[{"batb":[[0,12.5,30.93],[1,2.1,4.09],[2,1.05,200.76]],"ltp":12.5,"tv":15.14,"id":60971786}]}]}
{"op":"mcm","clk":"11959114636","pt":1724579397015,"mc":[{"id":"1.232239000","rc":[{"batb":[[0,13,5],[1,12.5,30.93],[2,2.1,4.09]],"ltp":12.5,"tv":15.14,"id":60971786}]}]}
{"op":"mcm","clk":"11959115012","pt":1724579400189,"mc":[{"id":"1.232239000","rc":[{"batb":[[0,12.5,30.93],[1,2.1,4.09],[2,1.05,200.76]],"ltp":12.5,"tv":15.14,"id":60971786}]}]}
{"op":"mcm","clk":"11959116149","pt":1724579407828,"mc":[{"id":"1.232239000","rc":[{"batb":[[0,13,5],[1,12.5,30.93],[2,2.1,4.09]],"ltp":12.5,"tv":15.14,"id":60971786}]}]}
{"op":"mcm","clk":"11959116628","pt":1724579411216,"mc":[{"id":"1.232239000","rc":[{"batb":[[0,12.5,30.93],[1,2.1,4.09],[2,1.05,200.76]],"ltp":12.5,"tv":15.14,"id":60971786}]}]}
{"op":"mcm","clk":"11959117320","pt":1724579416739,"mc":[{"id":"1.232239000","rc":[{"batb":[[0,13,5],[1,12.5,30.93],[2,2.1,4.09]],"ltp":12.5,"tv":15.14,"id":60971786}]}]}
{"op":"mcm","clk":"11959117732","pt":1724579420006,"mc":[{"id":"1.232239000","rc":[{"batb":[[0,12.5,30.93],[1,2.1,4.09],[2,1.05,200.76]],"ltp":12.5,"tv":15.14,"id":60971786}]}]}
{"op":"mcm","clk":"11959119020","pt":1724579430339,"mc":[{"id":"1.232239000","rc":[{"batb":[[0,13,5],[1,12.5,30.93],[2,2.1,4.09]],"ltp":12.5,"tv":15.14,"id":60971786}]}]}
{"op":"mcm","clk":"11959119451","pt":1724579433555,"mc":[{"id":"1.232239000","rc":[{"batb":[[0,12.5,30.93],[1,2.1,4.09],[2,1.05,200.76]],"ltp":12.5,"tv":15.14,"id":60971786}]}]}
{"op":"mcm","clk":"11959120371","pt":1724579440966,"mc":[{"id":"1.232239000","rc":[{"batb":[[0,13,5],[1,12.5,30.93],[2,2.1,4.09]],"ltp":12.5,"tv":15.14,"id":60971786}]}]}
{"op":"mcm","clk":"11959120809","pt":1724579444174,"mc":[{"id":"1.232239000","rc":[{"batb":[[0,12.5,30.93],[1,2.1,4.09],[2,1.05,200.76]],"ltp":12.5,"tv":15.14,"id":60971786}]}]}
{"op":"mcm","clk":"11959121219","pt":1724579447049,"mc":[{"id":"1.232239000","rc":[{"batb":[[0,13,5],[1,12.5,30.93],[2,2.1,4.09]],"ltp":12.5,"tv":15.14,"id":60971786}]}]}
{"op":"mcm","clk":"11959121610","pt":1724579450366,"mc":[{"id":"1.232239000","rc":[{"batb":[[0,12.5,30.93],[1,2.1,4.09],[2,1.05,200.76]],"ltp":12.5,"tv":15.14,"id":60971786}]}]}
{"op":"mcm","clk":"11959122006","pt":1724579452980,"mc":[{"id":"1.232239000","rc":[{"batb":[[0,13,5],[1,12.5,30.93],[2,2.1,4.09]],"ltp":12.5,"tv":15.14,"id":60971786}]}]}
{"op":"mcm","clk":"11959122409","pt":1724579456282,"mc":[{"id":"1.232239000","rc":[{"batb":[[0,12.5,30.93],[1,2.1,4.09],[2,1.05,200.76]],"ltp":12.5,"tv":15.14,"id":60971786}]}]}
{"op":"mcm","clk":"11959123337","pt":1724579462761,"mc":[{"id":"1.232239000","rc":[{"batb":[[0,13,5],[1,12.5,30.93],[2,2.1,4.09]],"ltp":12.5,"tv":15.14,"id":60971786}]}]}
{"op":"mcm","clk":"11959123813","pt":1724579466151,"mc":[{"id":"1.232239000","rc":[{"batb":[[0,12.5,30.93],[1,2.1,4.09],[2,1.05,200.76]],"ltp":12.5,"tv":15.14,"id":60971786}]}]}
{"op":"mcm","clk":"11959124275","pt":1724579469585,"mc":[{"id":"1.232239000","rc":[{"batb":[[0,13,5],[1,12.5,30.93],[2,2.1,4.09]],"ltp":12.5,"tv":15.14,"id":60971786}]}]}
{"op":"mcm","clk":"11959124656","pt":1724579472779,"mc":[{"id":"1.232239000","rc":[{"batb":[[0,12.5,30.93],[1,2.1,4.09],[2,1.05,200.76]],"ltp":12.5,"tv":15.14,"id":60971786}]}]}
{"op":"mcm","clk":"11959125281","pt":1724579477308,"mc":[{"id":"1.232239000","rc":[{"batb":[[0,13,5],[1,12.5,30.93],[2,2.1,4.09]],"ltp":12.5,"tv":15.14,"id":60971786}]}]}
{"op":"mcm","clk":"11959125726","pt":1724579480480,"mc":[{"id":"1.232239000","rc":[{"batb":[[0,12.5,30.93],[1,2.1,4.09],[2,1.05,200.76]],"ltp":12.5,"tv":15.14,"id":60971786}]}]}
{"op":"mcm","clk":"11959126702","pt":1724579487515,"mc":[{"id":"1.232239000","rc":[{"batb":[[0,13,5],[1,12.5,30.93],[2,2.1,4.09]],"ltp":12.5,"tv":15.14,"id":60971786}]}]}
{"op":"mcm","clk":"11959127103","pt":1724579490682,"mc":[{"id":"1.232239000","rc":[{"batb":[[0,12.5,30.93],[1,2.1,4.09],[2,1.05,200.76]],"ltp":12.5,"tv":15.14,"id":60971786}]}]}
{"op":"mcm","clk":"11959127712","pt":1724579494386,"mc":[{"id":"1.232239000","rc":[{"batb":[[0,13,5],[1,12.5,30.93],[2,2.1,4.09]],"ltp":12.5,"tv":15.14,"id":60971786}]}]}
{"op":"mcm","clk":"11959128172","pt":1724579497707,"mc":[{"id":"1.232239000","rc":[{"batb":[[0,12.5,30.93],[1,2.1,4.09],[2,1.05,200.76]],"ltp":12.5,"tv":15.14,"id":60971786}]}]}
{"op":"mcm","clk":"11959129138","pt":1724579504713,"mc":[{"id":"1.232239000","rc":[{"batb":[[0,13,5],[1,12.5,30.93],[2,2.1,4.09]],"ltp":12.5,"tv":15.14,"id":60971786}]}]}
{"op":"mcm","clk":"11959129583","pt":1724579507929,"mc":[{"id":"1.232239000","rc":[{"batb":[[0,12.5,30.93],[1,2.1,4.09],[2,1.05,200.76]],"ltp":12.5,"tv":15.14,"id":60971786}]}]}
{"op":"mcm","clk":"11959130340","pt":1724579513606,"mc":[{"id":"1.232239000","rc":[{"batb":[[0,13,5],[1,12.5,30.93],[2,2.1,4.09]],"ltp":12.5,"tv":15.14,"id":60971786}]}]}
{"op":"mcm","clk":"11959130824","pt":1724579517031,"mc":[{"id":"1.232239000","rc":[{"batb":[[0,12.5,30.93],[1,2.1,4.09],[2,1.05,200.76]],"ltp":12.5,"tv":15.14,"id":60971786}]}]}
{"op":"mcm","clk":"11959131404","pt":1724579521255,"mc":[{"id":"1.232239000","rc":[{"batb":[[0,13,5],[1,12.5,30.93],[2,2.1,4.09]],"ltp":12.5,"tv":15.14,"id":60971786}]}]}
{"op":"mcm","clk":"11959131943","pt":1724579524646,"mc":[{"id":"1.232239000","rc":[{"batb":[[0,12.5,30.93],[1,2.1,4.09],[2,1.05,200.76]],"ltp":12.5,"tv":15.14,"id":60971786}]}]}
{"op":"mcm","clk":"11959132619","pt":1724579528868,"mc":[{"id":"1.232239000","rc":[{"batb":[[0,13,5],[1,12.5,30.93],[2,2.1,4.09]],"ltp":12.5,"tv":15.14,"id":60971786}]}]}
{"op":"mcm","clk":"11959133140","pt":1724579532055,"mc":[{"id":"1.232239000","rc":[{"batb":[[0,12.5,30.93],[1,2.1,4.09],[2,1.05,200.76]],"ltp":12.5,"tv":15.14,"id":60971786}]}]}
{"op":"mcm","clk":"11959133632","pt":1724579535533,"mc":[{"id":"1.232239000","rc":[{"batb":[[0,13,5],[1,12.5,30.93],[2,2.1,4.09]],"ltp":12.5,"tv":15.14,"id":60971786}]}]}
{"op":"mcm","clk":"11959134069","pt":1724579538739,"mc":[{"id":"1.232239000","rc":[{"batb":[[0,12.5,30.93],[1,2.1,4.09],[2,1.05,200.76]],"ltp":12.5,"tv":15.14,"id":60971786}]}]}
{"op":"mcm","clk":"11959134946","pt":1724579544467,"mc":[{"id":"1.232239000","rc":[{"batb":[[0,13,5],[1,12.5,30.93],[2,2.1,4.09]],"ltp":12.5,"tv":15.14,"id":60971786}]}]}
{"op":"mcm","clk":"11959135538","pt":1724579547751,"mc":[{"id":"1.232239000","rc":[{"batb":[[0,12.5,30.93],[1,2.1,4.09],[2,1.05,200.76]],"ltp":12.5,"tv":15.14,"id":60971786}]}]}
{"op":"mcm","clk":"11959135908","pt":1724579550565,"mc":[{"id":"1.232239000","rc":[{"batb":[[0,13,5],[1,12.5,30.93],[2,2.1,4.09]],"ltp":12.5,"tv":15.14,"id":60971786}]}]}
{"op":"mcm","clk":"11959136381","pt":1724579553878,"mc":[{"id":"1.232239000","rc":[{"batb":[[0,12.5,30.93],[1,2.1,4.09],[2,1.05,200.76]],"ltp":12.5,"tv":15.14,"id":60971786}]}]}
{"op":"mcm","clk":"11959137189","pt":1724579560057,"mc":[{"id":"1.232239000","rc":[{"batb":[[0,13,5],[1,12.5,30.93],[2,2.1,4.09]],"ltp":12.5,"tv":15.14,"id":60971786}]}]}
{"op":"mcm","clk":"11959137634","pt":1724579563485,"mc":[{"id":"1.232239000","rc":[{"batb":[[0,12.5,30.93],[1,2.1,4.09],[2,1.05,200.76]],"ltp":12.5,"tv":15.14,"id":60971786}]}]}
{"op":"mcm","clk":"11959138133","pt":1724579567264,"mc":[{"id":"1.232239000","rc":[{"batb":[[0,13,5],[1,12.5,30.93],[2,2.1,4.09]],"ltp":12.5,"tv":15.14,"id":60971786}]}]}
{"op":"mcm","clk":"11959138558","pt":1724579570485,"mc":[{"id":"1.232239000","rc":[{"batb":[[0,12.5,30.93],[1,2.1,4.09],[2,1.05,200.76]],"ltp":12.5,"tv":15.14,"id":60971786}]}]}
{"op":"mcm","clk":"11959139801","pt":1724579579698,"mc":[{"id":"1.232239000","rc":[{"batb":[[0,13,5],[1,12.5,30.93],[2,2.1,4.09]],"ltp":12.5,"tv":15.14,"id":60971786}]}]}
{"op":"mcm","clk":"11959140265","pt":1724579582918,"mc":[{"id":"1.232239000","rc":[{"batb":[[0,12.5,30.93],[1,2.1,4.09],[2,1.05,200.76]],"ltp":12.5,"tv":15.14,"id":60971786}]}]}
{"op":"mcm","clk":"11959140677","pt":1724579585781,"mc":[{"id":"1.232239000","rc":[{"batb":[[0,13,5],[1,12.5,30.93],[2,2.1,4.09]],"ltp":12.5,"tv":15.14,"id":60971786}]}]}
{"op":"mcm","clk":"11959141115","pt":1724579589017,"mc":[{"id":"1.232239000","rc":[{"batb":[[0,12.5,30.93],[1,2.1,4.09],[2,1.05,200.76]],"ltp":12.5,"tv":15.14,"id":60971786}]}]}
{"op":"mcm","clk":"11959141576","pt":1724579593313,"mc":[{"id":"1.232239000","rc":[{"batb":[[0,13,5],[1,12.5,30.93],[2,2.1,4.09]],"ltp":12.5,"tv":15.14,"id":60971786}]}]}
{"op":"mcm","clk":"11959141994","pt":1724579596393,"mc":[{"id":"1.232239000","rc":[{"batb":[[0,12.5,30.93],[1,2.1,4.09],[2,1.05,200.76]],"ltp":12.5,"tv":15.14,"id":60971786}]}]}
{"op":"mcm","clk":"11959142539","pt":1724579600597,"mc":[{"id":"1.232239000","rc":[{"batb":[[0,13,5],[1,12.5,30.93],[2,2.1,4.09]],"ltp":12.5,"tv":15.14,"id":60971786}]}]}
{"op":"mcm","clk":"11959143043","pt":1724579603836,"mc":[{"id":"1.232239000","rc":[{"batb":[[0,12.5,30.93],[1,2.1,4.09],[2,1.05,200.76]],"ltp":12.5,"tv":15.14,"id":60971786}]}]}
{"op":"mcm","clk":"11959143927","pt":1724579610343,"mc":[{"id":"1.232239000","rc":[{"batb":[[0,13,5],[1,12.5,30.93],[2,2.1,4.09]],"ltp":12.5,"tv":15.14,"id":60971786}]}]}
{"op":"mcm","clk":"11959144393","pt":1724579613718,"mc":[{"id":"1.232239000","rc":[{"batb":[[0,12.5,30.93],[1,2.1,4.09],[2,1.05,200.76]],"ltp":12.5,"tv":15.14,"id":60971786}]}]}
{"op":"mcm","clk":"11959145126","pt":1724579619929,"mc":[{"id":"1.232239000","rc":[{"batb":[[0,13,5],[1,12.5,30.93],[2,2.1,4.09]],"ltp":12.5,"tv":15.14,"id":60971786}]}]}
{"op":"mcm","clk":"11959145535","pt":1724579623250,"mc":[{"id":"1.232239000","rc":[{"batb":[[0,12.5,30.93],[1,2.1,4.09],[2,1.05,200.76]],"ltp":12.5,"tv":15.14,"id":60971786}]}]}
{"op":"mcm","clk":"11959146452","pt":1724579630719,"mc":[{"id":"1.232239000","rc":[{"batb":[[0,13,5],[1,12.5,30.93],[2,2.1,4.09]],"ltp":12.5,"tv":15.14,"id":60971786}]}]}
{"op":"mcm","clk":"11959146845","pt":1724579633966,"mc":[{"id":"1.232239000","rc":[{"batb":[[0,12.5,30.93],[1,2.1,4.09],[2,1.05,200.76]],"ltp":12.5,"tv":15.14,"id":60971786}]}]}
{"op":"mcm","clk":"11959147318","pt":1724579637646,"mc":[{"id":"1.232239000","rc":[{"batb":[[0,13,5],[1,12.5,30.93],[2,2.1,4.09]],"ltp":12.5,"tv":15.14,"id":60971786}]}]}
{"op":"mcm","clk":"11959147720","pt":1724579640968,"mc":[{"id":"1.232239000","rc":[{"batb":[[0,12.5,30.93],[1,2.1,4.09],[2,1.05,200.76]],"ltp":12.5,"tv":15.14,"id":60971786}]}]}
{"op":"mcm","clk":"11959148805","pt":1724579649363,"mc":[{"id":"1.232239000","rc":[{"batb":[[0,13,5],[1,12.5,30.93],[2,2.1,4.09]],"ltp":12.5,"tv":15.14,"id":60971786}]}]}
{"op":"mcm","clk":"11959149254","pt":1724579652585,"mc":[{"id":"1.232239000","rc":[{"batb":[[0,12.5,30.93],[1,2.1,4.09],[2,1.05,200.76]],"ltp":12.5,"tv":15.14,"id":60971786}]}]}
{"op":"mcm","clk":"11959149822","pt":1724579656372,"mc":[{"id":"1.232239000","rc":[{"batb":[[0,13,5],[1,12.5,30.93],[2,2.1,4.09]],"ltp":12.5,"tv":15.14,"id":60971786}]}]}
{"op":"mcm","clk":"11959150305","pt":1724579659690,"mc":[{"id":"1.232239000","rc":[{"batb":[[0,12.5,30.93],[1,2.1,4.09],[2,1.05,200.76]],"ltp":12.5,"tv":15.14,"id":60971786}]}]}
{"op":"mcm","clk":"11959150749","pt":1724579662860,"mc":[{"id":"1.232239000","rc":[{"batb":[[0,13,5],[1,12.5,30.93],[2,2.1,4.09]],"ltp":12.5,"tv":15.14,"id":60971786}]}]}
{"op":"mcm","clk":"11959151304","pt":1724579666296,"mc":[{"id":"1.232239000","rc":[{"batb":[[0,12.5,30.93],[1,2.1,4.09],[2,1.05,200.76]],"ltp":12.5,"tv":15.14,"id":60971786}]}]}
{"op":"mcm","clk":"11959152142","pt":1724579672618,"mc":[{"id":"1.232239000","rc":[{"batb":[[0,13,5],[1,12.5,30.93],[2,2.1,4.09]],"ltp":12.5,"tv":15.14,"id":60971786}]}]}
{"op":"mcm","clk":"11959152696","pt":1724579675874,"mc":[{"id":"1.232239000","rc":[{"batb":[[0,12.5,30.93],[1,2.1,4.09],[2,1.05,200.76]],"ltp":12.5,"tv":15.14,"id":60971786}]}]}
{"op":"mcm","clk":"11959153907","pt":1724579684308,"mc":[{"id":"1.232239000","rc":[{"batb":[[0,13,5],[1,12.5,30.93],[2,2.1,4.09]],"ltp":12.5,"tv":15.14,"id":60971786}]}]}
{"op":"mcm","clk":"11959154380","pt":1724579687618,"mc":[{"id":"1.232239000","rc":[{"batb":[[0,12.5,30.93],[1,2.1,4.09],[2,1.05,200.76]],"ltp":12.5,"tv":15.14,"id":60971786}]}]}
{"op":"mcm","clk":"11959154994","pt":1724579691838,"mc":[{"id":"1.232239000","rc":[{"batb":[[0,13,5],[1,12.5,30.93],[2,2.1,4.09]],"ltp":12.5,"tv":15.14,"id":60971786}]}]}
{"op":"mcm","clk":"11959155494","pt":1724579695110,"mc":[{"id":"1.232239000","rc":[{"batb":[[0,12.5,30.93],[1,2.1,4.09],[2,1.05,200.76]],"ltp":12.5,"tv":15.14,"id":60971786}]}]}
{"op":"mcm","clk":"11959156402","pt":1724579701341,"mc":[{"id":"1.232239000","rc":[{"batb":[[0,13,5],[1,12.5,30.93],[2,2.1,4.09]],"ltp":12.5,"tv":15.14,"id":60971786}]}]}
{"op":"mcm","clk":"11959156938","pt":1724579704622,"mc":[{"id":"1.232239000","rc":[{"batb":[[0,12.5,30.93],[1,2.1,4.09],[2,1.05,200.76]],"ltp":12.5,"tv":15.14,"id":60971786}]}]}
{"op":"mcm","clk":"11959158180","pt":1724579712947,"mc":[{"id":"1.232239000","rc":[{"batb":[[0,13,5],[1,12.5,30.93],[2,2.1,4.09]],"ltp":12.5,"tv":15.14,"id":60971786}]}]}
{"op":"mcm","clk":"11959158582","pt":1724579716227,"mc":[{"id":"1.232239000","rc":[{"batb":[[0,12.5,30.93],[1,2.1,4.09],[2,1.05,200.76]],"ltp":12.5,"tv":15.14,"id":60971786}]}]}
{"op":"mcm","clk":"11959159380","pt":1724579721881,"mc":[{"id":"1.232239000","rc":[{"batb":[[0,13,5],[1,12.5,30.93],[2,2.1,4.09]],"ltp":12.5,"tv":15.14,"id":60971786}]}]}
{"op":"mcm","clk":"11959159859","pt":1724579725154,"mc":[{"id":"1.232239000","rc":[{"batb":[[0,12.5,30.93],[1,2.1,4.09],[2,1.05,200.76]],"ltp":12.5,"tv":15.14,"id":60971786}]}]}
{"op":"mcm","clk":"11959160943","pt":1724579733065,"mc":[{"id":"1.232239000","rc":[{"batb":[[0,13,5],[1,12.5,30.93],[2,2.1,4.09]],"ltp":12.5,"tv":15.14,"id":60971786}]}]}
{"op":"mcm","clk":"11959161313","pt":1724579736274,"mc":[{"id":"1.232239000","rc":[{"batb":[[0,12.5,30.93],[1,2.1,4.09],[2,1.05,200.76]],"ltp":12.5,"tv":15.14,"id":60971786}]}]}
{"op":"mcm","clk":"11959161679","pt":1724579739284,"mc":[{"id":"1.232239000","rc":[{"batb":[[0,13,5],[1,12.5,30.93],[2,2.1,4.09]],"ltp":12.5,"tv":15.14,"id":60971786}]}]}
{"op":"mcm","clk":"11959162083","pt":1724579742498,"mc":[{"id":"1.232239000","rc":[{"batb":[[0,12.5,30.93],[1,2.1,4.09],[2,1.05,200.76]],"ltp":12.5,"tv":15.14,"id":60971786}]}]}
{"op":"mcm","clk":"11959162568","pt":1724579746199,"mc":[{"id":"1.232239000","rc":[{"batb":[[0,13,5],[1,12.5,30.93],[2,2.1,4.09]],"ltp":12.5,"tv":15.14,"id":60971786}]}]}
{"op":"mcm","clk":"11959162996","pt":1724579749576,"mc":[{"id":"1.232239000","rc":[{"batb":[[0,12.5,30.93],[1,2.1,4.09],[2,1.05,200.76]],"ltp":12.5,"tv":15.14,"id":60971786}]}]}
{"op":"mcm","clk":"11959163739","pt":1724579755289,"mc":[{"id":"1.232239000","rc":[{"batb":[[0,13,5],[1,12.5,30.93],[2,2.1,4.09]],"ltp":12.5,"tv":15.14,"id":60971786}]}]}
{"op":"mcm","clk":"11959164143","pt":1724579758500,"mc":[{"id":"1.232239000","rc":[{"batb":[[0,12.5,30.93],[1,2.1,4.09],[2,1.05,200.76]],"ltp":12.5,"tv":15.14,"id":60971786}]}]}
{"op":"mcm","clk":"11959164670","pt":1724579762494,"mc":[{"id":"1.232239000","rc":[{"batb":[[0,13,5],[1,12.5,30.93],[2,2.1,4.09]],"ltp":12.5,"tv":15.14,"id":60971786}]}]}
{"op":"mcm","clk":"11959165084","pt":1724579765708,"mc":[{"id":"1.232239000","rc":[{"batb":[[0,12.5,30.93],[1,2.1,4.09],[2,1.05,200.76]],"ltp":12.5,"tv":15.14,"id":60971786}]}]}
{"op":"mcm","clk":"11959165734","pt":1724579770890,"mc":[{"id":"1.232239000","rc":[{"batb":[[0,13,5],[1,12.5,30.93],[2,2.1,4.09]],"ltp":12.5,"tv":15.14,"id":60971786}]}]}
{"op":"mcm","clk":"11959166138","pt":1724579774217,"mc":[{"id":"1.232239000","rc":[{"batb":[[0,12.5,30.93],[1,2.1,4.09],[2,1.05,200.76]],"ltp":12.5,"tv":15.14,"id":60971786}]}]}
{"op":"mcm","clk":"11959166415","pt":1724579776403,"mc":[{"id":"1.232239000","rc":[{"batb":[[0,13,5],[1,12.5,30.93],[2,2.1,4.09]],"ltp":12.5,"tv":15.14,"id":60971786}]}]}
{"op":"mcm","clk":"11959166826","pt":1724579779819,"mc":[{"id":"1.232239000","rc":[{"batb":[[0,12.5,30.93],[1,2.1,4.09],[2,1.05,200.76]],"ltp":12.5,"tv":15.14,"id":60971786}]}]}
{"op":"mcm","clk":"11959167244","pt":1724579783192,"mc":[{"id":"1.232239000","rc":[{"batb":[[0,13,5],[1,12.5,30.93],[2,2.1,4.09]],"ltp":12.5,"tv":15.14,"id":60971786}]}]}
{"op":"mcm","clk":"11959167641","pt":1724579786417,"mc":[{"id":"1.232239000","rc":[{"batb":[[0,12.5,30.93],[1,2.1,4.09],[2,1.05,200.76]],"ltp":12.5,"tv":15.14,"id":60971786}]}]}
{"op":"mcm","clk":"11959168936","pt":1724579797028,"mc":[{"id":"1.232239000","rc":[{"batb":[[0,13,5],[1,12.5,30.93],[2,2.1,4.09]],"ltp":12.5,"tv":15.14,"id":60971786}]}]}
{"op":"mcm","clk":"11959169264","pt":1724579800314,"mc":[{"id":"1.232239000","rc":[{"batb":[[0,12.5,30.93],[1,2.1,4.09],[2,1.05,200.76]],"ltp":12.5,"tv":15.14,"id":60971786}]}]}
{"op":"mcm","clk":"11959169633","pt":1724579803726,"mc":[{"id":"1.232239000","rc":[{"batb":[[0,13,5],[1,12.5,30.93],[2,2.1,4.09]],"ltp":12.5,"tv":15.14,"id":60971786}]}]}
{"op":"mcm","clk":"11959169985","pt":1724579807033,"mc":[{"id":"1.232239000","rc":[{"batb":[[0,12.5,30.93],[1,2.1,4.09],[2,1.05,200.76]],"ltp":12.5,"tv":15.14,"id":60971786}]}]}
{"op":"mcm","clk":"11959170551","pt":1724579812227,"mc":[{"id":"1.232239000","rc":[{"batb":[[0,13,5],[1,12.5,30.93],[2,2.1,4.09]],"ltp":12.5,"tv":15.14,"id":60971786}]}]}
{"op":"mcm","clk":"11959170937","pt":1724579815632,"mc":[{"id":"1.232239000","rc":[{"batb":[[0,12.5,30.93],[1,2.1,4.09],[2,1.05,200.76]],"batl":[[0,21,0.96]],"ltp":12.5,"tv":15.14,"id":60971786}]}]}
{"op":"mcm","clk":"11959171253","pt":1724579818430,"mc":[{"id":"1.232239000","rc":[{"trd":[[13,0.88]],"batb":[[0,13,4.56],[1,12.5,30.93],[2,2.1,4.09]],"batl":[[0,21,0.51]],"ltp":13.0,"tv":16.02,"id":60971786}],"tv":186.01}]}
{"op":"mcm","clk":"11959171656","pt":1724579821633,"mc":[{"id":"1.232239000","rc":[{"batb":[[0,12.5,30.93],[1,2.1,4.09],[2,1.05,200.76]],"ltp":13.0,"tv":16.02,"id":60971786}]}]}
{"op":"mcm","clk":"11959171972","pt":1724579824228,"mc":[{"id":"1.232239000","rc":[{"batb":[[0,13,5],[1,12.5,30.93],[2,2.1,4.09]],"ltp":13.0,"tv":16.02,"id":60971786}]}]}
{"op":"mcm","clk":"11959172389","pt":1724579827546,"mc":[{"id":"1.232239000","rc":[{"batb":[[0,12.5,30.93],[1,2.1,4.09],[2,1.05,200.76]],"ltp":13.0,"tv":16.02,"id":60971786}]}]}
{"op":"mcm","clk":"11959173477","pt":1724579837736,"mc":[{"id":"1.232239000","rc":[{"batb":[[0,13,5],[1,12.5,30.93],[2,2.1,4.09]],"ltp":13.0,"tv":16.02,"id":60971786}]}]}
{"op":"mcm","clk":"11959173799","pt":1724579841053,"mc":[{"id":"1.232239000","rc":[{"batb":[[0,12.5,30.93],[1,2.1,4.09],[2,1.05,200.76]],"ltp":13.0,"tv":16.02,"id":60971786}]}]}
{"op":"mcm","clk":"11959178311","pt":1724579884516,"mc":[{"id":"1.232239000","rc":[{"batb":[[0,13,5],[1,12.5,30.93],[2,2.1,4.09]],"ltp":13.0,"tv":16.02,"id":60971786}]}]}
{"op":"mcm","clk":"11959178686","pt":1724579887825,"mc":[{"id":"1.232239000","rc":[{"batb":[[0,12.5,30.93],[1,2.1,4.09],[2,1.05,200.76]],"ltp":13.0,"tv":16.02,"id":60971786}]}]}
{"op":"mcm","clk":"11959178994","pt":1724579891027,"mc":[{"id":"1.232239000","rc":[{"batb":[[0,13,5],[1,12.5,30.93],[2,2.1,4.09]],"ltp":13.0,"tv":16.02,"id":60971786}]}]}
{"op":"mcm","clk":"11959179383","pt":1724579894398,"mc":[{"id":"1.232239000","rc":[{"batb":[[0,12.5,30.93],[1,2.1,4.09],[2,1.05,200.76]],"ltp":13.0,"tv":16.02,"id":60971786}]}]}
{"op":"mcm","clk":"11959179784","pt":1724579897920,"mc":[{"id":"1.232239000","rc":[{"batb":[[0,13,5],[1,12.5,30.93],[2,2.1,4.09]],"ltp":13.0,"tv":16.02,"id":60971786}]}]}
{"op":"mcm","clk":"11959180175","pt":1724579901125,"mc":[{"id":"1.232239000","rc":[{"batb":[[0,12.5,30.93],[1,2.1,4.09],[2,1.05,200.76]],"ltp":13.0,"tv":16.02,"id":60971786}]}]}
{"op":"mcm","clk":"11959181631","pt":1724579915252,"mc":[{"id":"1.232239000","rc":[{"batb":[[0,13,5],[1,12.5,30.93],[2,2.1,4.09]],"ltp":13.0,"tv":16.02,"id":60971786}]}]}
{"op":"mcm","clk":"11959181969","pt":1724579918344,"mc":[{"id":"1.232239000","rc":[{"batb":[[0,12.5,30.93],[1,2.1,4.09],[2,1.05,200.76]],"ltp":13.0,"tv":16.02,"id":60971786}]}]}
{"op":"mcm","clk":"11959182225","pt":1724579921462,"mc":[{"id":"1.232239000","rc":[{"batb":[[0,13,5],[1,12.5,30.93],[2,2.1,4.09]],"ltp":13.0,"tv":16.02,"id":60971786}]}]}
{"op":"mcm","clk":"11959182579","pt":1724579924876,"mc":[{"id":"1.232239000","rc":[{"batb":[[0,12.5,30.93],[1,2.1,4.09],[2,1.05,200.76]],"ltp":13.0,"tv":16.02,"id":60971786}]}]}
{"op":"mcm","clk":"11959183050","pt":1724579929987,"mc":[{"id":"1.232239000","rc":[{"batb":[[0,13,5],[1,12.5,30.93],[2,2.1,4.09]],"ltp":13.0,"tv":16.02,"id":60971786}]}]}
{"op":"mcm","clk":"11959183383","pt":1724579933267,"mc":[{"id":"1.232239000","rc":[{"batb":[[0,12.5,30.93],[1,2.1,4.09],[2,1.05,200.76]],"ltp":13.0,"tv":16.02,"id":60971786}]}]}
{"op":"mcm","clk":"11959183750","pt":1724579936977,"mc":[{"id":"1.232239000","rc":[{"batb":[[0,13,5],[1,12.5,30.93],[2,2.1,4.09]],"ltp":13.0,"tv":16.02,"id":60971786}]}]}
{"op":"mcm","clk":"11959184069","pt":1724579940294,"mc":[{"id":"1.232239000","rc":[{"batb":[[0,12.5,30.93],[1,2.1,4.09],[2,1.05,200.76]],"ltp":13.0,"tv":16.02,"id":60971786}]}]}
{"op":"mcm","clk":"11959184953","pt":1724579946567,"mc":[{"id":"1.232239000","rc":[{"batb":[[0,13,5],[1,12.5,30.93],[2,2.1,4.09]],"ltp":13.0,"tv":16.02,"id":60971786}]}]}
{"op":"mcm","clk":"11959185348","pt":1724579949887,"mc":[{"id":"1.232239000","rc":[{"batb":[[0,12.5,30.93],[1,2.1,4.09],[2,1.05,200.76]],"ltp":13.0,"tv":16.02,"id":60971786}]}]}
{"op":"mcm","clk":"11959185779","pt":1724579953212,"mc":[{"id":"1.232239000","rc":[{"batb":[[0,13,5],[1,12.5,30.93],[2,2.1,4.09]],"ltp":13.0,"tv":16.02,"id":60971786}]}]}
{"op":"mcm","clk":"11959186132","pt":1724579956607,"mc":[{"id":"1.232239000","rc":[{"batb":[[0,12.5,30.93],[1,2.1,4.09],[2,1.05,200.76]],"ltp":13.0,"tv":16.02,"id":60971786}]}]}
{"op":"mcm","clk":"11959186779","pt":1724579961834,"mc":[{"id":"1.232239000","rc":[{"batb":[[0,13,5],[1,12.5,30.93],[2,2.1,4.09]],"ltp":13.0,"tv":16.02,"id":60971786}]}]}
{"op":"mcm","clk":"11959187148","pt":1724579965207,"mc":[{"id":"1.232239000","rc":[{"batb":[[0,12.5,30.93],[1,2.1,4.09],[2,1.05,200.76]],"ltp":13.0,"tv":16.02,"id":60971786}]}]}
{"op":"mcm","clk":"11959188183","pt":1724579973438,"mc":[{"id":"1.232239000","rc":[{"batb":[[0,13,5],[1,12.5,30.93],[2,2.1,4.09]],"ltp":13.0,"tv":16.02,"id":60971786}]}]}
{"op":"mcm","clk":"11959188562","pt":1724579976848,"mc":[{"id":"1.232239000","rc":[{"batb":[[0,12.5,30.93],[1,2.1,4.09],[2,1.05,200.76]],"ltp":13.0,"tv":16.02,"id":60971786}]}]}
{"op":"mcm","clk":"11959190105","pt":1724579991647,"mc":[{"id":"1.232239000","rc":[{"batb":[[0,13,5],[1,12.5,30.93],[2,2.1,4.09]],"ltp":13.0,"tv":16.02,"id":60971786}]}]}
{"op":"mcm","clk":"11959190465","pt":1724579994856,"mc":[{"id":"1.232239000","rc":[{"batb":[[0,12.5,30.93],[1,2.1,4.09],[2,1.05,200.76]],"ltp":13.0,"tv":16.02,"id":60971786}]}]}
{"op":"mcm","clk":"11959192181","pt":1724580006329,"mc":[{"id":"1.232239000","rc":[{"batb":[[0,13,5],[1,12.5,30.93],[2,2.1,4.09]],"ltp":13.0,"tv":16.02,"id":60971786}]}]}
{"op":"mcm","clk":"11959192707","pt":1724580008590,"mc":[{"id":"1.232239000","rc":[{"batb":[[0,12.5,30.93],[1,2.1,4.09],[2,1.05,200.76]],"ltp":13.0,"tv":16.02,"id":60971786}]}]}
{"op":"mcm","clk":"11959193396","pt":1724580012767,"mc":[{"id":"1.232239000","rc":[{"batb":[[0,13,5],[1,12.5,30.93],[2,2.1,4.09]],"ltp":13.0,"tv":16.02,"id":60971786}]}]}
{"op":"mcm","clk":"11959193864","pt":1724580016146,"mc":[{"id":"1.232239000","rc":[{"batb":[[0,12.5,30.93],[1,2.1,4.09],[2,1.05,200.76]],"ltp":13.0,"tv":16.02,"id":60971786}]}]}
{"op":"mcm","clk":"11959194184","pt":1724580018748,"mc":[{"id":"1.232239000","rc":[{"batb":[[0,13,5],[1,12.5,30.93],[2,2.1,4.09]],"ltp":13.0,"tv":16.02,"id":60971786}]}]}
{"op":"mcm","clk":"11959194571","pt":1724580022078,"mc":[{"id":"1.232239000","rc":[{"batb":[[0,12.5,30.93],[1,2.1,4.09],[2,1.05,200.76]],"ltp":13.0,"tv":16.02,"id":60971786}]}]}
{"op":"mcm","clk":"11959195542","pt":1724580029491,"mc":[{"id":"1.232239000","rc":[{"batb":[[0,13,5],[1,12.5,30.93],[2,2.1,4.09]],"ltp":13.0,"tv":16.02,"id":60971786}]}]}
{"op":"mcm","clk":"11959195959","pt":1724580032858,"mc":[{"id":"1.232239000","rc":[{"batb":[[0,12.5,30.93],[1,2.1,4.09],[2,1.05,200.76]],"ltp":13.0,"tv":16.02,"id":60971786}]}]}
{"op":"mcm","clk":"11959197531","pt":1724580044777,"mc":[{"id":"1.232239000","rc":[{"batb":[[0,13,5],[1,12.5,30.93],[2,2.1,4.09]],"ltp":13.0,"tv":16.02,"id":60971786}]}]}
{"op":"mcm","clk":"11959197924","pt":1724580047892,"mc":[{"id":"1.232239000","rc":[{"batb":[[0,12.5,30.93],[1,2.1,4.09],[2,1.05,200.76]],"ltp":13.0,"tv":16.02,"id":60971786}]}]}
{"op":"mcm","clk":"11959198314","pt":1724580051195,"mc":[{"id":"1.232239000","rc":[{"batb":[[0,13,5],[1,12.5,30.93],[2,2.1,4.09]],"ltp":13.0,"tv":16.02,"id":60971786}]}]}
{"op":"mcm","clk":"11959198817","pt":1724580054504,"mc":[{"id":"1.232239000","rc":[{"batb":[[0,12.5,30.93],[1,2.1,4.09],[2,1.05,200.76]],"ltp":13.0,"tv":16.02,"id":60971786}]}]}
{"op":"mcm","clk":"11959199403","pt":1724580059800,"mc":[{"id":"1.232239000","rc":[{"batb":[[0,13,5],[1,12.5,30.93],[2,2.1,4.09]],"ltp":13.0,"tv":16.02,"id":60971786}]}]}
{"op":"mcm","clk":"11959199821","pt":1724580063099,"mc":[{"id":"1.232239000","rc":[{"batb":[[0,12.5,30.93],[1,2.1,4.09],[2,1.05,200.76]],"ltp":13.0,"tv":16.02,"id":60971786}]}]}
{"op":"mcm","clk":"11959201320","pt":1724580074927,"mc":[{"id":"1.232239000","rc":[{"batb":[[0,13,5],[1,12.5,30.93],[2,2.1,4.09]],"ltp":13.0,"tv":16.02,"id":60971786}]}]}
{"op":"mcm","clk":"11959201772","pt":1724580078307,"mc":[{"id":"1.232239000","rc":[{"batb":[[0,12.5,30.93],[1,2.1,4.09],[2,1.05,200.76]],"ltp":13.0,"tv":16.02,"id":60971786}]}]}
{"op":"mcm","clk":"11959204080","pt":1724580095618,"mc":[{"id":"1.232239000","rc":[{"batb":[[0,13,5],[1,12.5,30.93],[2,2.1,4.09]],"ltp":13.0,"tv":16.02,"id":60971786}]}]}
{"op":"mcm","clk":"11959204528","pt":1724580098931,"mc":[{"id":"1.232239000","rc":[{"batb":[[0,12.5,30.93],[1,2.1,4.09],[2,1.05,200.76]],"ltp":13.0,"tv":16.02,"id":60971786}]}]}
{"op":"mcm","clk":"11959205892","pt":1724580109664,"mc":[{"id":"1.232239000","rc":[{"batb":[[0,13,5],[1,12.5,30.93],[2,2.1,4.09]],"ltp":13.0,"tv":16.02,"id":60971786}]}]}
{"op":"mcm","clk":"11959206335","pt":1724580113084,"mc":[{"id":"1.232239000","rc":[{"batb":[[0,12.5,30.93],[1,2.1,4.09],[2,1.05,200.76]],"ltp":13.0,"tv":16.02,"id":60971786}]}]}
{"op":"mcm","clk":"11959207248","pt":1724580121087,"mc":[{"id":"1.232239000","rc":[{"batb":[[0,13,5],[1,12.5,30.93],[2,2.1,4.09]],"ltp":13.0,"tv":16.02,"id":60971786}]}]}
{"op":"mcm","clk":"11959207670","pt":1724580124376,"mc":[{"id":"1.232239000","rc":[{"batb":[[0,12.5,30.93],[1,2.1,4.09],[2,1.05,200.76]],"ltp":13.0,"tv":16.02,"id":60971786}]}]}
{"op":"mcm","clk":"11959208439","pt":1724580130464,"mc":[{"id":"1.232239000","rc":[{"batb":[[0,13,5],[1,12.5,30.93],[2,2.1,4.09]],"ltp":13.0,"tv":16.02,"id":60971786}]}]}
{"op":"mcm","clk":"11959208886","pt":1724580133880,"mc":[{"id":"1.232239000","rc":[{"batb":[[0,12.5,30.93],[1,2.1,4.09],[2,1.05,200.76]],"ltp":13.0,"tv":16.02,"id":60971786}]}]}
{"op":"mcm","clk":"11959209310","pt":1724580137203,"mc":[{"id":"1.232239000","rc":[{"batb":[[0,13,5],[1,12.5,30.93],[2,2.1,4.09]],"ltp":13.0,"tv":16.02,"id":60971786}]}]}
{"op":"mcm","clk":"11959209716","pt":1724580140384,"mc":[{"id":"1.232239000","rc":[{"batb":[[0,12.5,30.93],[1,2.1,4.09],[2,1.05,200.76]],"ltp":13.0,"tv":16.02,"id":60971786}]}]}
{"op":"mcm","clk":"11959210934","pt":1724580149901,"mc":[{"id":"1.232239000","rc":[{"batb":[[0,13,5],[1,12.5,30.93],[2,2.1,4.09]],"ltp":13.0,"tv":16.02,"id":60971786}]}]}
{"op":"mcm","clk":"11959211371","pt":1724580153083,"mc":[{"id":"1.232239000","rc":[{"batb":[[0,12.5,30.93],[1,2.1,4.09],[2,1.05,200.76]],"ltp":13.0,"tv":16.02,"id":60971786}]}]}
{"op":"mcm","clk":"11959212075","pt":1724580159001,"mc":[{"id":"1.232239000","rc":[{"batb":[[0,13,5],[1,12.5,30.93],[2,2.1,4.09]],"ltp":13.0,"tv":16.02,"id":60971786}]}]}
{"op":"mcm","clk":"11959212456","pt":1724580162187,"mc":[{"id":"1.232239000","rc":[{"batb":[[0,12.5,30.93],[1,2.1,4.09],[2,1.05,200.76]],"ltp":13.0,"tv":16.02,"id":60971786}]}]}
{"op":"mcm","clk":"11959212656","pt":1724580163692,"mc":[{"id":"1.232239000","rc":[{"batb":[[1,3.2,2],[2,2.1,4.09]],"ltp":13.0,"tv":16.02,"id":60971786}]}]}
{"op":"mcm","clk":"11959213728","pt":1724580172491,"mc":[{"id":"1.232239000","rc":[{"batb":[[0,13,5],[1,12.5,30.93],[2,3.2,2]],"ltp":13.0,"tv":16.02,"id":60971786}]}]}
{"op":"mcm","clk":"11959214133","pt":1724580175800,"mc":[{"id":"1.232239000","rc":[{"batb":[[0,12.5,30.93],[1,3.2,2],[2,2.1,4.09]],"ltp":13.0,"tv":16.02,"id":60971786}]}]}
{"op":"mcm","clk":"11959215916","pt":1724580189797,"mc":[{"id":"1.232239000","rc":[{"batb":[[0,13,5],[1,12.5,30.93],[2,3.2,2]],"ltp":13.0,"tv":16.02,"id":60971786}]}]}
{"op":"mcm","clk":"11959216321","pt":1724580193200,"mc":[{"id":"1.232239000","rc":[{"batb":[[0,12.5,30.93],[1,3.2,2],[2,2.1,4.09]],"ltp":13.0,"tv":16.02,"id":60971786}]}]}
{"op":"mcm","clk":"11959216913","pt":1724580198004,"mc":[{"id":"1.232239000","rc":[{"batb":[[0,13,5],[1,12.5,30.93],[2,3.2,2]],"ltp":13.0,"tv":16.02,"id":60971786}]}]}
{"op":"mcm","clk":"11959217314","pt":1724580201312,"mc":[{"id":"1.232239000","rc":[{"batb":[[0,12.5,30.93],[1,3.2,2],[2,2.1,4.09]],"ltp":13.0,"tv":16.02,"id":60971786}]}]}
{"op":"mcm","clk":"11959218414","pt":1724580210249,"mc":[{"id":"1.232239000","rc":[{"batb":[[0,13,5],[1,12.5,30.93],[2,3.2,2]],"ltp":13.0,"tv":16.02,"id":60971786}]}]}
{"op":"mcm","clk":"11959218834","pt":1724580213461,"mc":[{"id":"1.232239000","rc":[{"batb":[[0,12.5,30.93],[1,3.2,2],[2,2.1,4.09]],"ltp":13.0,"tv":16.02,"id":60971786}]}]}
{"op":"mcm","clk":"11959219171","pt":1724580216343,"mc":[{"id":"1.232239000","rc":[{"batb":[[0,13,5],[1,12.5,30.93],[2,3.2,2]],"ltp":13.0,"tv":16.02,"id":60971786}]}]}
{"op":"mcm","clk":"11959219628","pt":1724580219654,"mc":[{"id":"1.232239000","rc":[{"batb":[[0,12.5,30.93],[1,3.2,2],[2,2.1,4.09]],"ltp":13.0,"tv":16.02,"id":60971786}]}]}
{"op":"mcm","clk":"11959220597","pt":1724580226983,"mc":[{"id":"1.232239000","rc":[{"batb":[[0,13,5],[1,12.5,30.93],[2,3.2,2]],"ltp":13.0,"tv":16.02,"id":60971786}]}]}
{"op":"mcm","clk":"11959221009","pt":1724580230145,"mc":[{"id":"1.232239000","rc":[{"batb":[[0,12.5,30.93],[1,3.2,2],[2,2.1,4.09]],"ltp":13.0,"tv":16.02,"id":60971786}]}]}
{"op":"mcm","clk":"11959221422","pt":1724580233186,"mc":[{"id":"1.232239000","rc":[{"batb":[[0,13,5],[1,12.5,30.93],[2,3.2,2]],"ltp":13.0,"tv":16.02,"id":60971786}]}]}
{"op":"mcm","clk":"11959221828","pt":1724580236474,"mc":[{"id":"1.232239000","rc":[{"batb":[[0,12.5,30.93],[1,3.2,2],[2,2.1,4.09]],"ltp":13.0,"tv":16.02,"id":60971786}]}]}
{"op":"mcm","clk":"11959222088","pt":1724580238569,"mc":[{"id":"1.232239000","rc":[{"batb":[[0,13,5],[1,12.5,30.93],[2,3.2,2]],"ltp":13.0,"tv":16.02,"id":60971786}]}]}
{"op":"mcm","clk":"11959222586","pt":1724580241997,"mc":[{"id":"1.232239000","rc":[{"batb":[[0,12.5,30.93],[1,3.2,2],[2,2.1,4.09]],"ltp":13.0,"tv":16.02,"id":60971786}]}]}
{"op":"mcm","clk":"11959223680","pt":1724580249396,"mc":[{"id":"1.232239000","rc":[{"batb":[[0,13,5],[1,12.5,30.93],[2,3.2,2]],"ltp":13.0,"tv":16.02,"id":60971786}]}]}
{"op":"mcm","clk":"11959224189","pt":1724580252819,"mc":[{"id":"1.232239000","rc":[{"batb":[[0,12.5,30.93],[1,3.2,2],[2,2.1,4.09]],"ltp":13.0,"tv":16.02,"id":60971786}]}]}
{"op":"mcm","clk":"11959224873","pt":1724580258119,"mc":[{"id":"1.232239000","rc":[{"batb":[[0,13,5],[1,12.5,30.93],[2,3.2,2]],"ltp":13.0,"tv":16.02,"id":60971786}]}]}
{"op":"mcm","clk":"11959225299","pt":1724580261311,"mc":[{"id":"1.232239000","rc":[{"batb":[[0,12.5,30.93],[1,3.2,2],[2,2.1,4.09]],"ltp":13.0,"tv":16.02,"id":60971786}]}]}
{"op":"mcm","clk":"11959225754","pt":1724580264308,"mc":[{"id":"1.232239000","rc":[{"batb":[[0,13,5],[1,12.5,30.93],[2,3.2,2]],"ltp":13.0,"tv":16.02,"id":60971786}]}]}
{"op":"mcm","clk":"11959226247","pt":1724580267624,"mc":[{"id":"1.232239000","rc":[{"batb":[[0,12.5,30.93],[1,3.2,2],[2,2.1,4.09]],"ltp":13.0,"tv":16.02,"id":60971786}]}]}
{"op":"mcm","clk":"11959227513","pt":1724580276233,"mc":[{"id":"1.232239000","rc":[{"batb":[[0,13,5],[1,12.5,30.93],[2,3.2,2]],"ltp":13.0,"tv":16.02,"id":60971786}]}]}
{"op":"mcm","clk":"11959228007","pt":1724580279426,"mc":[{"id":"1.232239000","rc":[{"batb":[[0,12.5,30.93],[1,3.2,2],[2,2.1,4.09]],"ltp":13.0,"tv":16.02,"id":60971786}]}]}
{"op":"mcm","clk":"11959230454","pt":1724580297131,"mc":[{"id":"1.232239000","rc":[{"batb":[[0,13,5],[1,12.5,30.93],[2,3.2,2]],"ltp":13.0,"tv":16.02,"id":60971786}]}]}
{"op":"mcm","clk":"11959230893","pt":1724580300432,"mc":[{"id":"1.232239000","rc":[{"batb":[[0,12.5,30.93],[1,3.2,2],[2,2.1,4.09]],"ltp":13.0,"tv":16.02,"id":60971786}]}]}
{"op":"mcm","clk":"11959231393","pt":1724580304130,"mc":[{"id":"1.232239000","rc":[{"batb":[[0,13,5],[1,12.5,30.93],[2,3.2,2]],"ltp":13.0,"tv":16.02,"id":60971786}]}]}
{"op":"mcm","clk":"11959231892","pt":1724580307551,"mc":[{"id":"1.232239000","rc":[{"batb":[[0,12.5,30.93],[1,3.2,2],[2,2.1,4.09]],"ltp":13.0,"tv":16.02,"id":60971786}]}]}
{"op":"mcm","clk":"11959234227","pt":1724580324636,"mc":[{"id":"1.232239000","rc":[{"batb":[[0,13,5],[1,12.5,30.93],[2,3.2,2]],"ltp":13.0,"tv":16.02,"id":60971786}]}]}
{"op":"mcm","clk":"11959234709","pt":1724580327945,"mc":[{"id":"1.232239000","rc":[{"batb":[[0,12.5,30.93],[1,3.2,2],[2,2.1,4.09]],"ltp":13.0,"tv":16.02,"id":60971786}]}]}
{"op":"mcm","clk":"11959237060","pt":1724580346688,"mc":[{"id":"1.232239000","rc":[{"batb":[[0,13,5],[1,12.5,30.93],[2,3.2,2]],"ltp":13.0,"tv":16.02,"id":60971786}]}]}
{"op":"mcm","clk":"11959237461","pt":1724580350097,"mc":[{"id":"1.232239000","rc":[{"batb":[[0,12.5,30.93],[1,3.2,2],[2,2.1,4.09]],"ltp":13.0,"tv":16.02,"id":60971786}]}]}
{"op":"mcm","clk":"11959238897","pt":1724580361607,"mc":[{"id":"1.232239000","rc":[{"batb":[[0,13,5],[1,12.5,30.93],[2,3.2,2]],"ltp":13.0,"tv":16.02,"id":60971786}]}]}
{"op":"mcm","clk":"11959239299","pt":1724580364789,"mc":[{"id":"1.232239000","rc":[{"batb":[[0,12.5,30.93],[1,3.2,2],[2,2.1,4.09]],"ltp":13.0,"tv":16.02,"id":60971786}]}]}
{"op":"mcm","clk":"11959240173","pt":1724580371698,"mc":[{"id":"1.232239000","rc":[{"batb":[[0,13,5],[1,12.5,30.93],[2,3.2,2]],"ltp":13.0,"tv":16.02,"id":60971786}]}]}
{"op":"mcm","clk":"11959240629","pt":1724580375006,"mc":[{"id":"1.232239000","rc":[{"batb":[[0,12.5,30.93],[1,3.2,2],[2,2.1,4.09]],"ltp":13.0,"tv":16.02,"id":60971786}]}]}
{"op":"mcm","clk":"11959241381","pt":1724580381108,"mc":[{"id":"1.232239000","rc":[{"batb":[[0,13,5],[1,12.5,30.93],[2,3.2,2]],"ltp":13.0,"tv":16.02,"id":60971786}]}]}
{"op":"mcm","clk":"11959241854","pt":1724580384395,"mc":[{"id":"1.232239000","rc":[{"batb":[[0,12.5,30.93],[1,3.2,2],[2,2.1,4.09]],"ltp":13.0,"tv":16.02,"id":60971786}]}]}
{"op":"mcm","clk":"11959243656","pt":1724580397814,"mc":[{"id":"1.232239000","rc":[{"batb":[[0,13,5],[1,12.5,30.93],[2,3.2,2]],"ltp":13.0,"tv":16.02,"id":60971786}]}]}
{"op":"mcm","clk":"11959244103","pt":1724580401256,"mc":[{"id":"1.232239000","rc":[{"batb":[[0,12.5,30.93],[1,3.2,2],[2,2.1,4.09]],"ltp":13.0,"tv":16.02,"id":60971786}]}]}
{"op":"mcm","clk":"11959244977","pt":1724580408217,"mc":[{"id":"1.232239000","rc":[{"batb":[[0,13,5],[1,12.5,30.93],[2,3.2,2]],"ltp":13.0,"tv":16.02,"id":60971786}]}]}
{"op":"mcm","clk":"11959245383","pt":1724580411655,"mc":[{"id":"1.232239000","rc":[{"batb":[[0,12.5,30.93],[1,3.2,2],[2,2.1,4.09]],"ltp":13.0,"tv":16.02,"id":60971786}]}]}
{"op":"mcm","clk":"11959247036","pt":1724580424616,"mc":[{"id":"1.232239000","rc":[{"batb":[[0,13,5],[1,12.5,30.93],[2,3.2,2]],"ltp":13.0,"tv":16.02,"id":60971786}]}]}
{"op":"mcm","clk":"11959247435","pt":1724580427757,"mc":[{"id":"1.232239000","rc":[{"batb":[[0,12.5,30.93],[1,3.2,2],[2,2.1,4.09]],"ltp":13.0,"tv":16.02,"id":60971786}]}]}
{"op":"mcm","clk":"11959248339","pt":1724580434163,"mc":[{"id":"1.232239000","rc":[{"batb":[[0,13,5],[1,12.5,30.93],[2,3.2,2]],"ltp":13.0,"tv":16.02,"id":60971786}]}]}
{"op":"mcm","clk":"11959248864","pt":1724580437475,"mc":[{"id":"1.232239000","rc":[{"batb":[[0,12.5,30.93],[1,3.2,2],[2,2.1,4.09]],"ltp":13.0,"tv":16.02,"id":60971786}]}]}
{"op":"mcm","clk":"11959249456","pt":1724580441089,"mc":[{"id":"1.232239000","rc":[{"batb":[[0,13,5],[1,12.5,30.93],[2,3.2,2]],"ltp":13.0,"tv":16.02,"id":60971786}]}]}
{"op":"mcm","clk":"11959249978","pt":1724580444370,"mc":[{"id":"1.232239000","rc":[{"batb":[[0,12.5,30.93],[1,3.2,2],[2,2.1,4.09]],"ltp":13.0,"tv":16.02,"id":60971786}]}]}
{"op":"mcm","clk":"11959250683","pt":1724580449572,"mc":[{"id":"1.232239000","rc":[{"batb":[[0,13,5],[1,12.5,30.93],[2,3.2,2]],"ltp":13.0,"tv":16.02,"id":60971786}]}]}
{"op":"mcm","clk":"11959251178","pt":1724580452890,"mc":[{"id":"1.232239000","rc":[{"batb":[[0,12.5,30.93],[1,3.2,2],[2,2.1,4.09]],"ltp":13.0,"tv":16.02,"id":60971786}]}]}
{"op":"mcm","clk":"11959251636","pt":1724580456203,"mc":[{"id":"1.232239000","rc":[{"batb":[[0,13,5],[1,12.5,30.93],[2,3.2,2]],"ltp":13.0,"tv":16.02,"id":60971786}]}]}
{"op":"mcm","clk":"11959252064","pt":1724580459480,"mc":[{"id":"1.232239000","rc":[{"batb":[[0,12.5,30.93],[1,3.2,2],[2,2.1,4.09]],"ltp":13.0,"tv":16.02,"id":60971786}]}]}
{"op":"mcm","clk":"11959252571","pt":1724580463100,"mc":[{"id":"1.232239000","rc":[{"batb":[[0,13,5],[1,12.5,30.93],[2,3.2,2]],"ltp":13.0,"tv":16.02,"id":60971786}]}]}
{"op":"mcm","clk":"11959253003","pt":1724580466408,"mc":[{"id":"1.232239000","rc":[{"batb":[[0,12.5,30.93],[1,3.2,2],[2,2.1,4.09]],"ltp":13.0,"tv":16.02,"id":60971786}]}]}
{"op":"mcm","clk":"11959253779","pt":1724580471613,"mc":[{"id":"1.232239000","rc":[{"batb":[[0,13,5],[1,12.5,30.93],[2,3.2,2]],"ltp":13.0,"tv":16.02,"id":60971786}]}]}
{"op":"mcm","clk":"11959254241","pt":1724580475211,"mc":[{"id":"1.232239000","rc":[{"batb":[[0,12.5,30.93],[1,3.2,2],[2,2.1,4.09]],"ltp":13.0,"tv":16.02,"id":60971786}]}]}
{"op":"mcm","clk":"11959254582","pt":1724580477821,"mc":[{"id":"1.232239000","rc":[{"batb":[[0,13,5],[1,12.5,30.93],[2,3.2,2]],"ltp":13.0,"tv":16.02,"id":60971786}]}]}
{"op":"mcm","clk":"11959255066","pt":1724580481104,"mc":[{"id":"1.232239000","rc":[{"batb":[[0,12.5,30.93],[1,3.2,2],[2,2.1,4.09]],"ltp":13.0,"tv":16.02,"id":60971786}]}]}
{"op":"mcm","clk":"11959259425","pt":1724580507337,"mc":[{"id":"1.232239000","rc":[{"batb":[[0,13,5],[1,12.5,30.93],[2,3.2,2]],"ltp":13.0,"tv":16.02,"id":60971786}]}]}
{"op":"mcm","clk":"11959259873","pt":1724580510524,"mc":[{"id":"1.232239000","rc":[{"batb":[[0,12.5,30.93],[1,3.2,2],[2,2.1,4.09]],"ltp":13.0,"tv":16.02,"id":60971786}]}]}
{"op":"mcm","clk":"11959261136","pt":1724580519333,"mc":[{"id":"1.232239000","rc":[{"batb":[[0,13,5],[1,12.5,30.93],[2,3.2,2]],"ltp":13.0,"tv":16.02,"id":60971786}]}]}
{"op":"mcm","clk":"11959261558","pt":1724580522549,"mc":[{"id":"1.232239000","rc":[{"batb":[[0,12.5,30.93],[1,3.2,2],[2,2.1,4.09]],"ltp":13.0,"tv":16.02,"id":60971786}]}]}
{"op":"mcm","clk":"11959264901","pt":1724580544377,"mc":[{"id":"1.232239000","rc":[{"batb":[[0,13,5],[1,12.5,30.93],[2,3.2,2]],"ltp":13.0,"tv":16.02,"id":60971786}]}]}
{"op":"mcm","clk":"11959265402","pt":1724580547483,"mc":[{"id":"1.232239000","rc":[{"batb":[[0,12.5,30.93],[1,3.2,2],[2,2.1,4.09]],"ltp":13.0,"tv":16.02,"id":60971786}]}]}
{"op":"mcm","clk":"11959266718","pt":1724580556604,"mc":[{"id":"1.232239000","rc":[{"batb":[[0,13,5],[1,12.5,30.93],[2,3.2,2]],"ltp":13.0,"tv":16.02,"id":60971786}]}]}
{"op":"mcm","clk":"11959267218","pt":1724580559973,"mc":[{"id":"1.232239000","rc":[{"batb":[[0,12.5,30.93],[1,3.2,2],[2,2.1,4.09]],"ltp":13.0,"tv":16.02,"id":60971786}]}]}
{"op":"mcm","clk":"11959269474","pt":1724580574602,"mc":[{"id":"1.232239000","rc":[{"batb":[[0,13,5],[1,12.5,30.93],[2,3.2,2]],"ltp":13.0,"tv":16.02,"id":60971786}]}]}
{"op":"mcm","clk":"11959269967","pt":1724580577783,"mc":[{"id":"1.232239000","rc":[{"batb":[[0,12.5,30.93],[1,3.2,2],[2,2.1,4.09]],"ltp":13.0,"tv":16.02,"id":60971786}]}]}
{"op":"mcm","clk":"11959270542","pt":1724580581609,"mc":[{"id":"1.232239000","rc":[{"batb":[[0,13,5],[1,12.5,30.93],[2,3.2,2]],"ltp":13.0,"tv":16.02,"id":60971786}]}]}
{"op":"mcm","clk":"11959271046","pt":1724580584898,"mc":[{"id":"1.232239000","rc":[{"batb":[[0,12.5,30.93],[1,3.2,2],[2,2.1,4.09]],"ltp":13.0,"tv":16.02,"id":60971786}]}]}
{"op":"mcm","clk":"11959275621","pt":1724580612615,"mc":[{"id":"1.232239000","rc":[{"batb":[[0,13,5],[1,12.5,30.93],[2,3.2,2]],"ltp":13.0,"tv":16.02,"id":60971786}]}]}
{"op":"mcm","clk":"11959276193","pt":1724580616049,"mc":[{"id":"1.232239000","rc":[{"batb":[[0,12.5,30.93],[1,3.2,2],[2,2.1,4.09]],"ltp":13.0,"tv":16.02,"id":60971786}]}]}
{"op":"mcm","clk":"11959279204","pt":1724580634453,"mc":[{"id":"1.232239000","rc":[{"batb":[[0,13,5],[1,12.5,30.93],[2,3.2,2]],"ltp":13.0,"tv":16.02,"id":60971786}]}]}
{"op":"mcm","clk":"11959279651","pt":1724580637649,"mc":[{"id":"1.232239000","rc":[{"batb":[[0,12.5,30.93],[1,3.2,2],[2,2.1,4.09]],"ltp":13.0,"tv":16.02,"id":60971786}]}]}
{"op":"mcm","clk":"11959281834","pt":1724580652482,"mc":[{"id":"1.232239000","rc":[{"batb":[[0,13,5],[1,12.5,30.93],[2,3.2,2]],"ltp":13.0,"tv":16.02,"id":60971786}]}]}
{"op":"mcm","clk":"11959282356","pt":1724580655894,"mc":[{"id":"1.232239000","rc":[{"batb":[[0,12.5,30.93],[1,3.2,2],[2,2.1,4.09]],"ltp":13.0,"tv":16.02,"id":60971786}]}]}
{"op":"mcm","clk":"11959285469","pt":1724580675670,"mc":[{"id":"1.232239000","rc":[{"batb":[[0,13,5],[1,12.5,30.93],[2,3.2,2]],"ltp":13.0,"tv":16.02,"id":60971786}]}]}
{"op":"mcm","clk":"11959286023","pt":1724580678982,"mc":[{"id":"1.232239000","rc":[{"batb":[[0,12.5,30.93],[1,3.2,2],[2,2.1,4.09]],"ltp":13.0,"tv":16.02,"id":60971786}]}]}
{"op":"mcm","clk":"11959287233","pt":1724580687136,"mc":[{"id":"1.232239000","rc":[{"batb":[[0,13,5],[1,12.5,30.93],[2,3.2,2]],"ltp":13.0,"tv":16.02,"id":60971786}]}]}
{"op":"mcm","clk":"11959287746","pt":1724580690441,"mc":[{"id":"1.232239000","rc":[{"batb":[[0,12.5,30.93],[1,3.2,2],[2,2.1,4.09]],"ltp":13.0,"tv":16.02,"id":60971786}]}]}
{"op":"mcm","clk":"11959289272","pt":1724580700230,"mc":[{"id":"1.232239000","rc":[{"batb":[[0,13,5],[1,12.5,30.93],[2,3.2,2]],"ltp":13.0,"tv":16.02,"id":60971786}]}]}
{"op":"mcm","clk":"11959289847","pt":1724580703628,"mc":[{"id":"1.232239000","rc":[{"batb":[[0,12.5,30.93],[1,3.2,2],[2,2.1,4.09]],"ltp":13.0,"tv":16.02,"id":60971786}]}]}
{"op":"mcm","clk":"11959290634","pt":1724580708741,"mc":[{"id":"1.232239000","rc":[{"batb":[[0,13,5],[1,12.5,30.93],[2,3.2,2]],"ltp":13.0,"tv":16.02,"id":60971786}]}]}
{"op":"mcm","clk":"11959291061","pt":1724580712030,"mc":[{"id":"1.232239000","rc":[{"batb":[[0,12.5,30.93],[1,3.2,2],[2,2.1,4.09]],"ltp":13.0,"tv":16.02,"id":60971786}]}]}
{"op":"mcm","clk":"11959291415","pt":1724580714530,"mc":[{"id":"1.232239000","rc":[{"batb":[[0,13,5],[1,12.5,30.93],[2,3.2,2]],"ltp":13.0,"tv":16.02,"id":60971786}]}]}
{"op":"mcm","clk":"11959291835","pt":1724580717755,"mc":[{"id":"1.232239000","rc":[{"batb":[[0,12.5,30.93],[1,3.2,2],[2,2.1,4.09]],"ltp":13.0,"tv":16.02,"id":60971786}]}]}
{"op":"mcm","clk":"11959293298","pt":1724580727038,"mc":[{"id":"1.232239000","rc":[{"batb":[[0,13,5],[1,12.5,30.93],[2,3.2,2]],"ltp":13.0,"tv":16.02,"id":60971786}]}]}
{"op":"mcm","clk":"11959293837","pt":1724580730540,"mc":[{"id":"1.232239000","rc":[{"batb":[[0,12.5,30.93],[1,3.2,2],[2,2.1,4.09]],"ltp":13.0,"tv":16.02,"id":60971786}]}]}
{"op":"mcm","clk":"11959295041","pt":1724580739080,"mc":[{"id":"1.232239000","rc":[{"batb":[[0,13,5],[1,12.5,30.93],[2,3.2,2]],"ltp":13.0,"tv":16.02,"id":60971786}]}]}
{"op":"mcm","clk":"11959295522","pt":1724580742378,"mc":[{"id":"1.232239000","rc":[{"batb":[[0,12.5,30.93],[1,3.2,2],[2,2.1,4.09]],"ltp":13.0,"tv":16.02,"id":60971786}]}]}
{"op":"mcm","clk":"11959296454","pt":1724580748780,"mc":[{"id":"1.232239000","rc":[{"batb":[[0,13,5],[1,12.5,30.93],[2,3.2,2]],"ltp":13.0,"tv":16.02,"id":60971786}]}]}
{"op":"mcm","clk":"11959296976","pt":1724580752197,"mc":[{"id":"1.232239000","rc":[{"batb":[[0,12.5,30.93],[1,3.2,2],[2,2.1,4.09]],"ltp":13.0,"tv":16.02,"id":60971786}]}]}
{"op":"mcm","clk":"11959299010","pt":1724580766213,"mc":[{"id":"1.232239000","rc":[{"batb":[[0,13,5],[1,12.5,30.93],[2,3.2,2]],"ltp":13.0,"tv":16.02,"id":60971786}]}]}
{"op":"mcm","clk":"11959299519","pt":1724580769632,"mc":[{"id":"1.232239000","rc":[{"batb":[[0,12.5,30.93],[1,3.2,2],[2,2.1,4.09]],"ltp":13.0,"tv":16.02,"id":60971786}]}]}
{"op":"mcm","clk":"11959301713","pt":1724580783940,"mc":[{"id":"1.232239000","rc":[{"batb":[[0,13,5],[1,12.5,30.93],[2,3.2,2]],"ltp":13.0,"tv":16.02,"id":60971786}]}]}
{"op":"mcm","clk":"11959302248","pt":1724580787151,"mc":[{"id":"1.232239000","rc":[{"batb":[[0,12.5,30.93],[1,3.2,2],[2,2.1,4.09]],"ltp":13.0,"tv":16.02,"id":60971786}]}]}
{"op":"mcm","clk":"11959305712","pt":1724580811091,"mc":[{"id":"1.232239000","rc":[{"batb":[[0,13,5],[1,12.5,30.93],[2,3.2,2]],"ltp":13.0,"tv":16.02,"id":60971786}]}]}
{"op":"mcm","clk":"11959306224","pt":1724580814361,"mc":[{"id":"1.232239000","rc":[{"batb":[[0,12.5,30.93],[1,3.2,2],[2,2.1,4.09]],"ltp":13.0,"tv":16.02,"id":60971786}]}]}
{"op":"mcm","clk":"11959307749","pt":1724580825089,"mc":[{"id":"1.232239000","rc":[{"batb":[[0,13,5],[1,12.5,30.93],[2,3.2,2]],"ltp":13.0,"tv":16.02,"id":60971786}]}]}
{"op":"mcm","clk":"11959308164","pt":1724580828424,"mc":[{"id":"1.232239000","rc":[{"batb":[[0,12.5,30.93],[1,3.2,2],[2,2.1,4.09]],"ltp":13.0,"tv":16.02,"id":60971786}]}]}
{"op":"mcm","clk":"11959308669","pt":1724580831676,"mc":[{"id":"1.232239000","rc":[{"batb":[[0,13,5],[1,12.5,30.93],[2,3.2,2]],"ltp":13.0,"tv":16.02,"id":60971786}]}]}
{"op":"mcm","clk":"11959309237","pt":1724580835304,"mc":[{"id":"1.232239000","rc":[{"batb":[[0,12.5,30.93],[1,3.2,2],[2,2.1,4.09]],"ltp":13.0,"tv":16.02,"id":60971786}]}]}
{"op":"mcm","clk":"11959312640","pt":1724580858539,"mc":[{"id":"1.232239000","rc":[{"batb":[[0,13,5],[1,12.5,30.93],[2,3.2,2]],"ltp":13.0,"tv":16.02,"id":60971786}]}]}
{"op":"mcm","clk":"11959313155","pt":1724580861724,"mc":[{"id":"1.232239000","rc":[{"batb":[[0,12.5,30.93],[1,3.2,2],[2,2.1,4.09]],"ltp":13.0,"tv":16.02,"id":60971786}]}]}
{"op":"mcm","clk":"11959321154","pt":1724580915314,"mc":[{"id":"1.232239000","rc":[{"batb":[[0,13,5],[1,12.5,30.93],[2,3.2,2]],"ltp":13.0,"tv":16.02,"id":60971786}]}]}
{"op":"mcm","clk":"11959321663","pt":1724580918624,"mc":[{"id":"1.232239000","rc":[{"batb":[[0,12.5,30.93],[1,3.2,2],[2,2.1,4.09]],"ltp":13.0,"tv":16.02,"id":60971786}]}]}
{"op":"mcm","clk":"11959324097","pt":1724580935148,"mc":[{"id":"1.232239000","rc":[{"batb":[[0,13,5],[1,12.5,30.93],[2,3.2,2]],"ltp":13.0,"tv":16.02,"id":60971786}]}]}
{"op":"mcm","clk":"11959324591","pt":1724580938450,"mc":[{"id":"1.232239000","rc":[{"batb":[[0,12.5,30.93],[1,3.2,2],[2,2.1,4.09]],"ltp":13.0,"tv":16.02,"id":60971786}]}]}
{"op":"mcm","clk":"11959331708","pt":1724580985813,"mc":[{"id":"1.232239000","rc":[{"batb":[[0,13,5],[1,12.5,30.93],[2,3.2,2]],"ltp":13.0,"tv":16.02,"id":60971786}]}]}
{"op":"mcm","clk":"11959332259","pt":1724580989222,"mc":[{"id":"1.232239000","rc":[{"batb":[[0,12.5,30.93],[1,3.2,2],[2,2.1,4.09]],"ltp":13.0,"tv":16.02,"id":60971786}]}]}
{"op":"mcm","clk":"11959334273","pt":1724581002526,"mc":[{"id":"1.232239000","rc":[{"batb":[[0,13,5],[1,12.5,30.93],[2,3.2,2]],"ltp":13.0,"tv":16.02,"id":60971786}]}]}
{"op":"mcm","clk":"11959334742","pt":1724581005730,"mc":[{"id":"1.232239000","rc":[{"batb":[[0,12.5,30.93],[1,3.2,2],[2,2.1,4.09]],"ltp":13.0,"tv":16.02,"id":60971786}]}]}
{"op":"mcm","clk":"11959335317","pt":1724581009614,"mc":[{"id":"1.232239000","rc":[{"batb":[[0,13,5],[1,12.5,30.93],[2,3.2,2]],"ltp":13.0,"tv":16.02,"id":60971786}]}]}
{"op":"mcm","clk":"11959335831","pt":1724581013021,"mc":[{"id":"1.232239000","rc":[{"batb":[[0,12.5,30.93],[1,3.2,2],[2,2.1,4.09]],"ltp":13.0,"tv":16.02,"id":60971786}]}]}
{"op":"mcm","clk":"11959337703","pt":1724581024859,"mc":[{"id":"1.232239000","rc":[{"batb":[[0,13,5],[1,12.5,30.93],[2,3.2,2]],"ltp":13.0,"tv":16.02,"id":60971786}]}]}
{"op":"mcm","clk":"11959338200","pt":1724581028078,"mc":[{"id":"1.232239000","rc":[{"batb":[[0,12.5,30.93],[1,3.2,2],[2,2.1,4.09]],"ltp":13.0,"tv":16.02,"id":60971786}]}]}
{"op":"mcm","clk":"11959343716","pt":1724581062614,"mc":[{"id":"1.232239000","rc":[{"batb":[[0,13,5],[1,12.5,30.93],[2,3.2,2]],"ltp":13.0,"tv":16.02,"id":60971786}]}]}
{"op":"mcm","clk":"11959344243","pt":1724581065904,"mc":[{"id":"1.232239000","rc":[{"batb":[[0,12.5,30.93],[1,3.2,2],[2,2.1,4.09]],"ltp":13.0,"tv":16.02,"id":60971786}]}]}
{"op":"mcm","clk":"11959346039","pt":1724581076939,"mc":[{"id":"1.232239000","rc":[{"batb":[[0,13,5],[1,12.5,30.93],[2,3.2,2]],"ltp":13.0,"tv":16.02,"id":60971786}]}]}
{"op":"mcm","clk":"11959346557","pt":1724581080221,"mc":[{"id":"1.232239000","rc":[{"batb":[[0,12.5,30.93],[1,3.2,2],[2,2.1,4.09]],"ltp":13.0,"tv":16.02,"id":60971786}]}]}
{"op":"mcm","clk":"11959348575","pt":1724581092311,"mc":[{"id":"1.232239000","rc":[{"batb":[[0,13,5],[1,12.5,30.93],[2,3.2,2]],"ltp":13.0,"tv":16.02,"id":60971786}]}]}
{"op":"mcm","clk":"11959349078","pt":1724581095528,"mc":[{"id":"1.232239000","rc":[{"batb":[[0,12.5,30.93],[1,3.2,2],[2,2.1,4.09]],"ltp":13.0,"tv":16.02,"id":60971786}]}]}
{"op":"mcm","clk":"11959349583","pt":1724581098632,"mc":[{"id":"1.232239000","rc":[{"batb":[[0,13,5],[1,12.5,30.93],[2,3.2,2]],"ltp":13.0,"tv":16.02,"id":60971786}]}]}
{"op":"mcm","clk":"11959350085","pt":1724581101946,"mc":[{"id":"1.232239000","rc":[{"batb":[[0,12.5,30.93],[1,3.2,2],[2,2.1,4.09]],"ltp":13.0,"tv":16.02,"id":60971786}]}]}
{"op":"mcm","clk":"11959352868","pt":1724581119441,"mc":[{"id":"1.232239000","rc":[{"batb":[[0,13,5],[1,12.5,30.93],[2,3.2,2]],"ltp":13.0,"tv":16.02,"id":60971786}]}]}
{"op":"mcm","clk":"11959353365","pt":1724581122785,"mc":[{"id":"1.232239000","rc":[{"batb":[[0,12.5,30.93],[1,3.2,2],[2,2.1,4.09]],"ltp":13.0,"tv":16.02,"id":60971786}]}]}
{"op":"mcm","clk":"11959355294","pt":1724581134782,"mc":[{"id":"1.232239000","rc":[{"batb":[[0,13,5],[1,12.5,30.93],[2,3.2,2]],"ltp":13.0,"tv":16.02,"id":60971786}]}]}
{"op":"mcm","clk":"11959355776","pt":1724581138078,"mc":[{"id":"1.232239000","rc":[{"batb":[[0,12.5,30.93],[1,3.2,2],[2,2.1,4.09]],"ltp":13.0,"tv":16.02,"id":60971786}]}]}
{"op":"mcm","clk":"11959363712","pt":1724581187827,"mc":[{"id":"1.232239000","rc":[{"batb":[[0,13,5],[1,12.5,30.93],[2,3.2,2]],"ltp":13.0,"tv":16.02,"id":60971786}]}]}
{"op":"mcm","clk":"11959364259","pt":1724581191147,"mc":[{"id":"1.232239000","rc":[{"batb":[[0,12.5,30.93],[1,3.2,2],[2,2.1,4.09]],"ltp":13.0,"tv":16.02,"id":60971786}]}]}
{"op":"mcm","clk":"11959366222","pt":1724581203485,"mc":[{"id":"1.232239000","rc":[{"batb":[[0,13,5],[1,12.5,30.93],[2,3.2,2]],"ltp":13.0,"tv":16.02,"id":60971786}]}]}
{"op":"mcm","clk":"11959366743","pt":1724581206776,"mc":[{"id":"1.232239000","rc":[{"batb":[[0,12.5,30.93],[1,3.2,2],[2,2.1,4.09]],"ltp":13.0,"tv":16.02,"id":60971786}]}]}
{"op":"mcm","clk":"11959376487","pt":1724581270964,"mc":[{"id":"1.232239000","rc":[{"batb":[[0,13,5],[1,12.5,30.93],[2,3.2,2]],"ltp":13.0,"tv":16.02,"id":60971786}]}]}
{"op":"mcm","clk":"11959377030","pt":1724581274335,"mc":[{"id":"1.232239000","rc":[{"batb":[[0,12.5,30.93],[1,3.2,2],[2,2.1,4.09]],"ltp":13.0,"tv":16.02,"id":60971786}]}]}
{"op":"mcm","clk":"11959378001","pt":1724581280855,"mc":[{"id":"1.232239000","rc":[{"batb":[[0,13,5],[1,12.5,30.93],[2,3.2,2]],"ltp":13.0,"tv":16.02,"id":60971786}]}]}
{"op":"mcm","clk":"11959378550","pt":1724581284259,"mc":[{"id":"1.232239000","rc":[{"batb":[[0,12.5,30.93],[1,3.2,2],[2,2.1,4.09]],"ltp":13.0,"tv":16.02,"id":60971786}]}]}
{"op":"mcm","clk":"11959379777","pt":1724581292390,"mc":[{"id":"1.232239000","rc":[{"batb":[[0,13,5],[1,12.5,30.93],[2,3.2,2]],"ltp":13.0,"tv":16.02,"id":60971786}]}]}
{"op":"mcm","clk":"11959380249","pt":1724581295592,"mc":[{"id":"1.232239000","rc":[{"batb":[[0,12.5,30.93],[1,3.2,2],[2,2.1,4.09]],"ltp":13.0,"tv":16.02,"id":60971786}]}]}
{"op":"mcm","clk":"11959381806","pt":1724581306196,"mc":[{"id":"1.232239000","rc":[{"batb":[[0,13,5],[1,12.5,30.93],[2,3.2,2]],"ltp":13.0,"tv":16.02,"id":60971786}]}]}
{"op":"mcm","clk":"11959382317","pt":1724581309495,"mc":[{"id":"1.232239000","rc":[{"batb":[[0,12.5,30.93],[1,3.2,2],[2,2.1,4.09]],"ltp":13.0,"tv":16.02,"id":60971786}]}]}
{"op":"mcm","clk":"11959382755","pt":1724581312214,"mc":[{"id":"1.232239000","rc":[{"batb":[[0,13,5],[1,12.5,30.93],[2,3.2,2]],"ltp":13.0,"tv":16.02,"id":60971786}]}]}
{"op":"mcm","clk":"11959383310","pt":1724581315615,"mc":[{"id":"1.232239000","rc":[{"batb":[[0,12.5,30.93],[1,3.2,2],[2,2.1,4.09]],"ltp":13.0,"tv":16.02,"id":60971786}]}]}
{"op":"mcm","clk":"11959384271","pt":1724581321498,"mc":[{"id":"1.232239000","rc":[{"batb":[[0,13,5],[1,12.5,30.93],[2,3.2,2]],"ltp":13.0,"tv":16.02,"id":60971786}]}]}
{"op":"mcm","clk":"11959384788","pt":1724581324715,"mc":[{"id":"1.232239000","rc":[{"batb":[[0,12.5,30.93],[1,3.2,2],[2,2.1,4.09]],"ltp":13.0,"tv":16.02,"id":60971786}]}]}
{"op":"mcm","clk":"11959387415","pt":1724581341546,"mc":[{"id":"1.232239000","rc":[{"batb":[[0,13,5],[1,12.5,30.93],[2,3.2,2]],"ltp":13.0,"tv":16.02,"id":60971786}]}]}
{"op":"mcm","clk":"11959387931","pt":1724581344731,"mc":[{"id":"1.232239000","rc":[{"batb":[[0,12.5,30.93],[1,3.2,2],[2,2.1,4.09]],"ltp":13.0,"tv":16.02,"id":60971786}]}]}
{"op":"mcm","clk":"11959389440","pt":1724581354371,"mc":[{"id":"1.232239000","rc":[{"batb":[[0,13,5],[1,12.5,30.93],[2,3.2,2]],"ltp":13.0,"tv":16.02,"id":60971786}]}]}
{"op":"mcm","clk":"11959389926","pt":1724581357545,"mc":[{"id":"1.232239000","rc":[{"batb":[[0,12.5,30.93],[1,3.2,2],[2,2.1,4.09]],"ltp":13.0,"tv":16.02,"id":60971786}]}]}
{"op":"mcm","clk":"11959401549","pt":1724581431593,"mc":[{"id":"1.232239000","rc":[{"batb":[[0,13,5],[1,12.5,30.93],[2,3.2,2]],"ltp":13.0,"tv":16.02,"id":60971786}]}]}
{"op":"mcm","clk":"11959402045","pt":1724581435224,"mc":[{"id":"1.232239000","rc":[{"batb":[[0,12.5,30.93],[1,3.2,2],[2,2.1,4.09]],"ltp":13.0,"tv":16.02,"id":60971786}]}]}
{"op":"mcm","clk":"11959404237","pt":1724581449810,"mc":[{"id":"1.232239000","rc":[{"batb":[[0,13,5],[1,12.5,30.93],[2,3.2,2]],"ltp":13.0,"tv":16.02,"id":60971786}]}]}
{"op":"mcm","clk":"11959404764","pt":1724581453144,"mc":[{"id":"1.232239000","rc":[{"batb":[[0,12.5,30.93],[1,3.2,2],[2,2.1,4.09]],"ltp":13.0,"tv":16.02,"id":60971786}]}]}
{"op":"mcm","clk":"11959405238","pt":1724581456224,"mc":[{"id":"1.232239000","rc":[{"batb":[[0,13,5],[1,12.5,30.93],[2,3.2,2]],"ltp":13.0,"tv":16.02,"id":60971786}]}]}
{"op":"mcm","clk":"11959405724","pt":1724581459548,"mc":[{"id":"1.232239000","rc":[{"batb":[[0,12.5,30.93],[1,3.2,2],[2,2.1,4.09]],"ltp":13.0,"tv":16.02,"id":60971786}]}]}
{"op":"mcm","clk":"11959406870","pt":1724581466927,"mc":[{"id":"1.232239000","rc":[{"batb":[[0,13,5],[1,12.5,30.93],[2,3.2,2]],"ltp":13.0,"tv":16.02,"id":60971786}]}]}
{"op":"mcm","clk":"11959407397","pt":1724581470436,"mc":[{"id":"1.232239000","rc":[{"batb":[[0,12.5,30.93],[1,3.2,2],[2,2.1,4.09]],"ltp":13.0,"tv":16.02,"id":60971786}]}]}
{"op":"mcm","clk":"11959408215","pt":1724581475936,"mc":[{"id":"1.232239000","rc":[{"batb":[[0,13,5],[1,12.5,30.93],[2,3.2,2]],"ltp":13.0,"tv":16.02,"id":60971786}]}]}
{"op":"mcm","clk":"11959408724","pt":1724581479365,"mc":[{"id":"1.232239000","rc":[{"batb":[[0,12.5,30.93],[1,3.2,2],[2,2.1,4.09]],"ltp":13.0,"tv":16.02,"id":60971786}]}]}
{"op":"mcm","clk":"11959409455","pt":1724581484473,"mc":[{"id":"1.232239000","rc":[{"batb":[[0,13,5],[1,12.5,30.93],[2,3.2,2]],"ltp":13.0,"tv":16.02,"id":60971786}]}]}
{"op":"mcm","clk":"11959409892","pt":1724581487676,"mc":[{"id":"1.232239000","rc":[{"batb":[[0,12.5,30.93],[1,3.2,2],[2,2.1,4.09]],"ltp":13.0,"tv":16.02,"id":60971786}]}]}
{"op":"mcm","clk":"11959411690","pt":1724581499588,"mc":[{"id":"1.232239000","rc":[{"batb":[[0,13,5],[1,12.5,30.93],[2,3.2,2]],"ltp":13.0,"tv":16.02,"id":60971786}]}]}
{"op":"mcm","clk":"11959412254","pt":1724581502906,"mc":[{"id":"1.232239000","rc":[{"batb":[[0,12.5,30.93],[1,3.2,2],[2,2.1,4.09]],"ltp":13.0,"tv":16.02,"id":60971786}]}]}
{"op":"mcm","clk":"11959412665","pt":1724581505309,"mc":[{"id":"1.232239000","rc":[{"batb":[[0,13,5],[1,12.5,30.93],[2,3.2,2]],"ltp":13.0,"tv":16.02,"id":60971786}]}]}
{"op":"mcm","clk":"11959413199","pt":1724581508664,"mc":[{"id":"1.232239000","rc":[{"batb":[[0,12.5,30.93],[1,3.2,2],[2,2.1,4.09]],"ltp":13.0,"tv":16.02,"id":60971786}]}]}
{"op":"mcm","clk":"11959413786","pt":1724581512291,"mc":[{"id":"1.232239000","rc":[{"batb":[[0,13,5],[1,12.5,30.93],[2,3.2,2]],"ltp":13.0,"tv":16.02,"id":60971786}]}]}
{"op":"mcm","clk":"11959414274","pt":1724581515595,"mc":[{"id":"1.232239000","rc":[{"batb":[[0,12.5,30.93],[1,3.2,2],[2,2.1,4.09]],"ltp":13.0,"tv":16.02,"id":60971786}]}]}
{"op":"mcm","clk":"11959415457","pt":1724581522999,"mc":[{"id":"1.232239000","rc":[{"batb":[[0,13,5],[1,12.5,30.93],[2,3.2,2]],"ltp":13.0,"tv":16.02,"id":60971786}]}]}
{"op":"mcm","clk":"11959415971","pt":1724581526298,"mc":[{"id":"1.232239000","rc":[{"batb":[[0,12.5,30.93],[1,3.2,2],[2,2.1,4.09]],"ltp":13.0,"tv":16.02,"id":60971786}]}]}
{"op":"mcm","clk":"11959416982","pt":1724581532506,"mc":[{"id":"1.232239000","rc":[{"batb":[[0,13,5],[1,12.5,30.93],[2,3.2,2]],"ltp":13.0,"tv":16.02,"id":60971786}]}]}
{"op":"mcm","clk":"11959417501","pt":1724581535841,"mc":[{"id":"1.232239000","rc":[{"batb":[[0,12.5,30.93],[1,3.2,2],[2,2.1,4.09]],"ltp":13.0,"tv":16.02,"id":60971786}]}]}
{"op":"mcm","clk":"11959417969","pt":1724581538715,"mc":[{"id":"1.232239000","rc":[{"batb":[[0,13,5],[1,12.5,30.93],[2,3.2,2]],"ltp":13.0,"tv":16.02,"id":60971786}]}]}
{"op":"mcm","clk":"11959418469","pt":1724581542023,"mc":[{"id":"1.232239000","rc":[{"batb":[[0,12.5,30.93],[1,3.2,2],[2,2.1,4.09]],"ltp":13.0,"tv":16.02,"id":60971786}]}]}
{"op":"mcm","clk":"11959418857","pt":1724581544543,"mc":[{"id":"1.232239000","rc":[{"batb":[[0,13,5],[1,12.5,30.93],[2,3.2,2]],"ltp":13.0,"tv":16.02,"id":60971786}]}]}
{"op":"mcm","clk":"11959419350","pt":1724581547736,"mc":[{"id":"1.232239000","rc":[{"batb":[[0,12.5,30.93],[1,3.2,2],[2,2.1,4.09]],"ltp":13.0,"tv":16.02,"id":60971786}]}]}
{"op":"mcm","clk":"11959420026","pt":1724581552025,"mc":[{"id":"1.232239000","rc":[{"batb":[[0,13,5],[1,12.5,30.93],[2,3.2,2]],"ltp":13.0,"tv":16.02,"id":60971786}]}]}
{"op":"mcm","clk":"11959420533","pt":1724581555436,"mc":[{"id":"1.232239000","rc":[{"trd":[[1.05,1400]],"batb":[[0,1.04,252.57],[1,1.03,2733.66],[2,1.02,700]],"ltp":1.05,"tv":1569.98,"id":24640635},{"batb":[[0,12.5,30.93],[1,3.2,2],[2,2.1,4.09]],"ltp":13.0,"tv":16.02,"id":60971786}],"tv":1586.01}]}
{"op":"mcm","clk":"11959420871","pt":1724581557838,"mc":[{"id":"1.232239000","rc":[{"batb":[[0,13,5],[1,12.5,30.93],[2,3.2,2]],"ltp":13.0,"tv":16.02,"id":60971786}]}]}
{"op":"mcm","clk":"11959421091","pt":1724581559411,"mc":[{"id":"1.232239000","rc":[{"batb":[[0,1.05,170.38],[1,1.04,251.81],[2,1.03,2733.66]],"ltp":1.05,"tv":1569.98,"id":24640635}]}]}
{"op":"mcm","clk":"11959421236","pt":1724581560508,"mc":[{"id":"1.232239000","rc":[{"batb":[[0,1.05,848.86]],"ltp":1.05,"tv":1569.98,"id":24640635}]}]}
{"op":"mcm","clk":"11959421339","pt":1724581561217,"mc":[{"id":"1.232239000","rc":[{"batb":[[0,1.05,1357.73]],"ltp":1.05,"tv":1569.98,"id":24640635},{"batb":[[0,12.5,30.93],[1,3.2,2],[2,2.1,4.09]],"ltp":13.0,"tv":16.02,"id":60971786}]}]}
{"op":"mcm","clk":"11959421420","pt":1724581561744,"mc":[{"id":"1.232239000","rc":[{"batb":[[0,1.05,1527.35],[1,1.04,421.43]],"ltp":1.05,"tv":1569.98,"id":24640635}]}]}
{"op":"mcm","clk":"11959422350","pt":1724581567630,"mc":[{"id":"1.232239000","rc":[{"batb":[[0,13,5],[1,12.5,30.93],[2,3.2,2]],"ltp":13.0,"tv":16.02,"id":60971786}]}]}
{"op":"mcm","clk":"11959422851","pt":1724581571039,"mc":[{"id":"1.232239000","rc":[{"batb":[[0,12.5,30.93],[1,3.2,2],[2,2.1,4.09]],"ltp":13.0,"tv":16.02,"id":60971786}]}]}
{"op":"mcm","clk":"11959423457","pt":1724581575219,"mc":[{"id":"1.232239000","rc":[{"batb":[[0,13,5],[1,12.5,30.93],[2,3.2,2]],"ltp":13.0,"tv":16.02,"id":60971786}]}]}
{"op":"mcm","clk":"11959423977","pt":1724581578631,"mc":[{"id":"1.232239000","rc":[{"batb":[[0,12.5,30.93],[1,3.2,2],[2,2.1,4.09]],"ltp":13.0,"tv":16.02,"id":60971786}]}]}
{"op":"mcm","clk":"11959424784","pt":1724581583774,"mc":[{"id":"1.232239000","rc":[{"batb":[[0,13,5],[1,12.5,30.93],[2,3.2,2]],"ltp":13.0,"tv":16.02,"id":60971786}]}]}
{"op":"mcm","clk":"11959425315","pt":1724581587293,"mc":[{"id":"1.232239000","rc":[{"batb":[[0,12.5,30.93],[1,3.2,2],[2,2.1,4.09]],"ltp":13.0,"tv":16.02,"id":60971786}]}]}
{"op":"mcm","clk":"11959425820","pt":1724581590681,"mc":[{"id":"1.232239000","rc":[{"batb":[[0,13,5],[1,12.5,30.93],[2,3.2,2]],"ltp":13.0,"tv":16.02,"id":60971786}]}]}
{"op":"mcm","clk":"11959426303","pt":1724581593992,"mc":[{"id":"1.232239000","rc":[{"batb":[[0,12.5,30.93],[1,3.2,2],[2,2.1,4.09]],"ltp":13.0,"tv":16.02,"id":60971786}]}]}
{"op":"mcm","clk":"11959427874","pt":1724581604303,"mc":[{"id":"1.232239000","rc":[{"batb":[[0,13,5],[1,12.5,30.93],[2,3.2,2]],"ltp":13.0,"tv":16.02,"id":60971786}]}]}
{"op":"mcm","clk":"11959428344","pt":1724581607697,"mc":[{"id":"1.232239000","rc":[{"batb":[[0,12.5,30.93],[1,3.2,2],[2,2.1,4.09]],"ltp":13.0,"tv":16.02,"id":60971786}]}]}
{"op":"mcm","clk":"11959429369","pt":1724581614492,"mc":[{"id":"1.232239000","rc":[{"batb":[[0,13,5],[1,12.5,30.93],[2,3.2,2]],"ltp":13.0,"tv":16.02,"id":60971786}]}]}
{"op":"mcm","clk":"11959429864","pt":1724581617902,"mc":[{"id":"1.232239000","rc":[{"batb":[[0,12.5,30.93],[1,3.2,2],[2,2.1,4.09]],"ltp":13.0,"tv":16.02,"id":60971786}]}]}
{"op":"mcm","clk":"11959430205","pt":1724581620200,"mc":[{"id":"1.232239000","rc":[{"batb":[[0,13,5],[1,12.5,30.93],[2,3.2,2]],"ltp":13.0,"tv":16.02,"id":60971786}]}]}
{"op":"mcm","clk":"11959430740","pt":1724581623519,"mc":[{"id":"1.232239000","rc":[{"batb":[[0,12.5,30.93],[1,3.2,2],[2,2.1,4.09]],"ltp":13.0,"tv":16.02,"id":60971786}]}]}
{"op":"mcm","clk":"11959430907","pt":1724581624620,"mc":[{"id":"1.232239000","rc":[{"batb":[[0,1.06,16.76],[1,1.05,1527.35],[2,1.04,421.43]],"ltp":1.05,"tv":1569.98,"id":24640635}]}]}
{"op":"mcm","clk":"11959431468","pt":1724581627993,"mc":[{"id":"1.232239000","rc":[{"batb":[[0,13,5],[1,12.5,30.93],[2,3.2,2]],"ltp":13.0,"tv":16.02,"id":60971786}]}]}
{"op":"mcm","clk":"11959431966","pt":1724581631293,"mc":[{"id":"1.232239000","rc":[{"batb":[[0,12.5,30.93],[1,3.2,2],[2,2.1,4.09]],"ltp":13.0,"tv":16.02,"id":60971786}]}]}
{"op":"mcm","clk":"11959433251","pt":1724581639244,"mc":[{"id":"1.232239000","rc":[{"batb":[[0,13,5],[1,12.5,30.93],[2,3.2,2]],"ltp":13.0,"tv":16.02,"id":60971786}]}]}
{"op":"mcm","clk":"11959433788","pt":1724581642647,"mc":[{"id":"1.232239000","rc":[{"batb":[[0,12.5,30.93],[1,3.2,2],[2,2.1,4.09]],"ltp":13.0,"tv":16.02,"id":60971786}]}]}
{"op":"mcm","clk":"11959434792","pt":1724581648726,"mc":[{"id":"1.232239000","rc":[{"batb":[[0,13,5],[1,12.5,30.93],[2,3.2,2]],"ltp":13.0,"tv":16.02,"id":60971786}]}]}
{"op":"mcm","clk":"11959435307","pt":1724581652024,"mc":[{"id":"1.232239000","rc":[{"batb":[[0,12.5,30.93],[1,3.2,2],[2,2.1,4.09]],"ltp":13.0,"tv":16.02,"id":60971786}]}]}
{"op":"mcm","clk":"11959436408","pt":1724581658458,"mc":[{"id":"1.232239000","rc":[{"batb":[[0,13,5],[1,12.5,30.93],[2,3.2,2]],"ltp":13.0,"tv":16.02,"id":60971786}]}]}
{"op":"mcm","clk":"11959436981","pt":1724581661783,"mc":[{"id":"1.232239000","rc":[{"batb":[[0,12.5,30.93],[1,3.2,2],[2,2.1,4.09]],"ltp":13.0,"tv":16.02,"id":60971786}]}]}
{"op":"mcm","clk":"11959437622","pt":1724581665639,"mc":[{"id":"1.232239000","rc":[{"batb":[[0,13,5],[1,12.5,30.93],[2,3.2,2]],"ltp":13.0,"tv":16.02,"id":60971786}]}]}
{"op":"mcm","clk":"11959438170","pt":1724581668856,"mc":[{"id":"1.232239000","rc":[{"batb":[[0,12.5,30.93],[1,3.2,2],[2,2.1,4.09]],"ltp":13.0,"tv":16.02,"id":60971786}]}]}
{"op":"mcm","clk":"11959438728","pt":1724581672373,"mc":[{"id":"1.232239000","rc":[{"batb":[[0,13,5],[1,12.5,30.93],[2,3.2,2]],"ltp":13.0,"tv":16.02,"id":60971786}]}]}
{"op":"mcm","clk":"11959439284","pt":1724581675662,"mc":[{"id":"1.232239000","rc":[{"batb":[[0,12.5,30.93],[1,3.2,2],[2,2.1,4.09]],"ltp":13.0,"tv":16.02,"id":60971786}]}]}
{"op":"mcm","clk":"11959439851","pt":1724581679155,"mc":[{"id":"1.232239000","rc":[{"batb":[[0,13,5],[1,12.5,30.93],[2,3.2,2]],"ltp":13.0,"tv":16.02,"id":60971786}]}]}
{"op":"mcm","clk":"11959440386","pt":1724581682357,"mc":[{"id":"1.232239000","rc":[{"batb":[[0,12.5,30.93],[1,3.2,2],[2,2.1,4.09]],"ltp":13.0,"tv":16.02,"id":60971786}]}]}
{"op":"mcm","clk":"11959441922","pt":1724581691787,"mc":[{"id":"1.232239000","rc":[{"batb":[[0,13,5],[1,12.5,30.93],[2,3.2,2]],"ltp":13.0,"tv":16.02,"id":60971786}]}]}
{"op":"mcm","clk":"11959442462","pt":1724581694984,"mc":[{"id":"1.232239000","rc":[{"batb":[[0,12.5,30.93],[1,3.2,2],[2,2.1,4.09]],"ltp":13.0,"tv":16.02,"id":60971786}]}]}
{"op":"mcm","clk":"11959443509","pt":1724581701308,"mc":[{"id":"1.232239000","rc":[{"batb":[[0,13,5],[1,12.5,30.93],[2,3.2,2]],"ltp":13.0,"tv":16.02,"id":60971786}]}]}
{"op":"mcm","clk":"11959444072","pt":1724581704784,"mc":[{"id":"1.232239000","rc":[{"batb":[[0,12.5,30.93],[1,3.2,2],[2,2.1,4.09]],"ltp":13.0,"tv":16.02,"id":60971786}]}]}
{"op":"mcm","clk":"11959445432","pt":1724581713407,"mc":[{"id":"1.232239000","rc":[{"batb":[[0,13,5],[1,12.5,30.93],[2,3.2,2]],"ltp":13.0,"tv":16.02,"id":60971786}]}]}
{"op":"mcm","clk":"11959445942","pt":1724581716705,"mc":[{"id":"1.232239000","rc":[{"batb":[[0,12.5,30.93],[1,3.2,2],[2,2.1,4.09]],"ltp":13.0,"tv":16.02,"id":60971786}]}]}
{"op":"mcm","clk":"11959447464","pt":1724581725988,"mc":[{"id":"1.232239000","rc":[{"batb":[[0,13,5],[1,12.5,30.93],[2,3.2,2]],"ltp":13.0,"tv":16.02,"id":60971786}]}]}
{"op":"mcm","clk":"11959447974","pt":1724581729326,"mc":[{"id":"1.232239000","rc":[{"batb":[[0,12.5,30.93],[1,3.2,2],[2,2.1,4.09]],"ltp":13.0,"tv":16.02,"id":60971786}]}]}
{"op":"mcm","clk":"11959449056","pt":1724581736032,"mc":[{"id":"1.232239000","rc":[{"batb":[[0,13,5],[1,12.5,30.93],[2,3.2,2]],"ltp":13.0,"tv":16.02,"id":60971786}]}]}
{"op":"mcm","clk":"11959449593","pt":1724581739452,"mc":[{"id":"1.232239000","rc":[{"batb":[[0,12.5,30.93],[1,3.2,2],[2,2.1,4.09]],"ltp":13.0,"tv":16.02,"id":60971786}]}]}
{"op":"mcm","clk":"11959450621","pt":1724581745250,"mc":[{"id":"1.232239000","rc":[{"batb":[[0,13,5],[1,12.5,30.93],[2,3.2,2]],"ltp":13.0,"tv":16.02,"id":60971786}]}]}
{"op":"mcm","clk":"11959451230","pt":1724581748676,"mc":[{"id":"1.232239000","rc":[{"batb":[[0,12.5,30.93],[1,3.2,2],[2,2.1,4.09]],"ltp":13.0,"tv":16.02,"id":60971786}]}]}
{"op":"mcm","clk":"11959454855","pt":1724581772355,"mc":[{"id":"1.232239000","rc":[{"batb":[[0,13,5],[1,12.5,30.93],[2,3.2,2]],"ltp":13.0,"tv":16.02,"id":60971786}]}]}
{"op":"mcm","clk":"11959455350","pt":1724581775637,"mc":[{"id":"1.232239000","rc":[{"batb":[[0,12.5,30.93],[1,3.2,2],[2,2.1,4.09]],"ltp":13.0,"tv":16.02,"id":60971786}]}]}
{"op":"mcm","clk":"11959456413","pt":1724581782946,"mc":[{"id":"1.232239000","rc":[{"batb":[[0,13,5],[1,12.5,30.93],[2,3.2,2]],"ltp":13.0,"tv":16.02,"id":60971786}]}]}
{"op":"mcm","clk":"11959456880","pt":1724581786246,"mc":[{"id":"1.232239000","rc":[{"batb":[[0,12.5,30.93],[1,3.2,2],[2,2.1,4.09]],"ltp":13.0,"tv":16.02,"id":60971786}]}]}
{"op":"mcm","clk":"11959458068","pt":1724581793580,"mc":[{"id":"1.232239000","rc":[{"batb":[[0,13,5],[1,12.5,30.93],[2,3.2,2]],"ltp":13.0,"tv":16.02,"id":60971786}]}]}
{"op":"mcm","clk":"11959458540","pt":1724581796987,"mc":[{"id":"1.232239000","rc":[{"batb":[[0,12.5,30.93],[1,3.2,2],[2,2.1,4.09]],"ltp":13.0,"tv":16.02,"id":60971786}]}]}
{"op":"mcm","clk":"11959460027","pt":1724581805380,"mc":[{"id":"1.232239000","rc":[{"batb":[[0,13,5],[1,12.5,30.93],[2,3.2,2]],"ltp":13.0,"tv":16.02,"id":60971786}]}]}
{"op":"mcm","clk":"11959460558","pt":1724581808897,"mc":[{"id":"1.232239000","rc":[{"batb":[[0,12.5,30.93],[1,3.2,2],[2,2.1,4.09]],"ltp":13.0,"tv":16.02,"id":60971786}]}]}
{"op":"mcm","clk":"11959461413","pt":1724581813808,"mc":[{"id":"1.232239000","rc":[{"batb":[[0,13,5],[1,12.5,30.93],[2,3.2,2]],"ltp":13.0,"tv":16.02,"id":60971786}]}]}
{"op":"mcm","clk":"11959461946","pt":1724581817177,"mc":[{"id":"1.232239000","rc":[{"batb":[[0,12.5,30.93],[1,3.2,2],[2,2.1,4.09]],"ltp":13.0,"tv":16.02,"id":60971786}]}]}
{"op":"mcm","clk":"11959462424","pt":1724581820796,"mc":[{"id":"1.232239000","rc":[{"batb":[[0,13,5],[1,12.5,30.93],[2,3.2,2]],"ltp":13.0,"tv":16.02,"id":60971786}]}]}
{"op":"mcm","clk":"11959462914","pt":1724581824095,"mc":[{"id":"1.232239000","rc":[{"batb":[[0,12.5,30.93],[1,3.2,2],[2,2.1,4.09]],"ltp":13.0,"tv":16.02,"id":60971786}]}]}
{"op":"mcm","clk":"11959463883","pt":1724581830417,"mc":[{"id":"1.232239000","rc":[{"batb":[[0,13,5],[1,12.5,30.93],[2,3.2,2]],"ltp":13.0,"tv":16.02,"id":60971786}]}]}
{"op":"mcm","clk":"11959464330","pt":1724581833690,"mc":[{"id":"1.232239000","rc":[{"batb":[[0,12.5,30.93],[1,3.2,2],[2,2.1,4.09]],"ltp":13.0,"tv":16.02,"id":60971786}]}]}
{"op":"mcm","clk":"11959466289","pt":1724581847507,"mc":[{"id":"1.232239000","rc":[{"batb":[[0,13,5],[1,12.5,30.93],[2,3.2,2]],"ltp":13.0,"tv":16.02,"id":60971786}]}]}
{"op":"mcm","clk":"11959466805","pt":1724581850928,"mc":[{"id":"1.232239000","rc":[{"batb":[[0,12.5,30.93],[1,3.2,2],[2,2.1,4.09]],"ltp":13.0,"tv":16.02,"id":60971786}]}]}
{"op":"mcm","clk":"11959467338","pt":1724581854519,"mc":[{"id":"1.232239000","rc":[{"batb":[[0,13,5],[1,12.5,30.93],[2,3.2,2]],"ltp":13.0,"tv":16.02,"id":60971786}]}]}
{"op":"mcm","clk":"11959467866","pt":1724581857828,"mc":[{"id":"1.232239000","rc":[{"batb":[[0,12.5,30.93],[1,3.2,2],[2,2.1,4.09]],"ltp":13.0,"tv":16.02,"id":60971786}]}]}
{"op":"mcm","clk":"11959468448","pt":1724581861841,"mc":[{"id":"1.232239000","rc":[{"batb":[[0,13,5],[1,12.5,30.93],[2,3.2,2]],"ltp":13.0,"tv":16.02,"id":60971786}]}]}
{"op":"mcm","clk":"11959468895","pt":1724581865141,"mc":[{"id":"1.232239000","rc":[{"batb":[[0,12.5,30.93],[1,3.2,2],[2,2.1,4.09]],"ltp":13.0,"tv":16.02,"id":60971786}]}]}
{"op":"mcm","clk":"11959471716","pt":1724581884394,"mc":[{"id":"1.232239000","rc":[{"batb":[[0,13,5],[1,12.5,30.93],[2,3.2,2]],"ltp":13.0,"tv":16.02,"id":60971786}]}]}
{"op":"mcm","clk":"11959472262","pt":1724581887882,"mc":[{"id":"1.232239000","rc":[{"batb":[[0,12.5,30.93],[1,3.2,2],[2,2.1,4.09]],"ltp":13.0,"tv":16.02,"id":60971786}]}]}
{"op":"mcm","clk":"11959472766","pt":1724581890979,"mc":[{"id":"1.232239000","rc":[{"batb":[[0,13,5],[1,12.5,30.93],[2,3.2,2]],"ltp":13.0,"tv":16.02,"id":60971786}]}]}
{"op":"mcm","clk":"11959473259","pt":1724581894288,"mc":[{"id":"1.232239000","rc":[{"batb":[[0,12.5,30.93],[1,3.2,2],[2,2.1,4.09]],"ltp":13.0,"tv":16.02,"id":60971786}]}]}
{"op":"mcm","clk":"11959474812","pt":1724581904405,"mc":[{"id":"1.232239000","rc":[{"batb":[[0,13,5],[1,12.5,30.93],[2,3.2,2]],"ltp":13.0,"tv":16.02,"id":60971786}]}]}
{"op":"mcm","clk":"11959475377","pt":1724581907943,"mc":[{"id":"1.232239000","rc":[{"batb":[[0,12.5,30.93],[1,3.2,2],[2,2.1,4.09]],"ltp":13.0,"tv":16.02,"id":60971786}]}]}
{"op":"mcm","clk":"11959476050","pt":1724581912104,"mc":[{"id":"1.232239000","rc":[{"batb":[[0,13,5],[1,12.5,30.93],[2,3.2,2]],"ltp":13.0,"tv":16.02,"id":60971786}]}]}
{"op":"mcm","clk":"11959476408","pt":1724581914511,"mc":[{"id":"1.232239000","rc":[{"batb":[[1,1.04,422.19],[2,1.03,2733.66]],"ltp":1.05,"tv":1569.98,"id":24640635}]}]}
{"op":"mcm","clk":"11959476539","pt":1724581915437,"mc":[{"id":"1.232239000","rc":[{"batb":[[1,1.04,252.57]],"ltp":1.05,"tv":1569.98,"id":24640635},{"batb":[[0,12.5,30.93],[1,3.2,2],[2,2.1,4.09]],"ltp":13.0,"tv":16.02,"id":60971786}]}]}
{"op":"mcm","clk":"11959477564","pt":1724581921541,"mc":[{"id":"1.232239000","rc":[{"batb":[[0,13,5],[1,12.5,30.93],[2,3.2,2]],"ltp":13.0,"tv":16.02,"id":60971786}]}]}
{"op":"mcm","clk":"11959478119","pt":1724581925059,"mc":[{"id":"1.232239000","rc":[{"batb":[[0,12.5,30.93],[1,3.2,2],[2,2.1,4.09]],"ltp":13.0,"tv":16.02,"id":60971786}]}]}
{"op":"mcm","clk":"11959478400","pt":1724581926737,"mc":[{"id":"1.232239000","rc":[{"batl":[[0,21,0.96]],"ltp":13.0,"tv":16.02,"id":60971786}]}]}
{"op":"mcm","clk":"11959478654","pt":1724581927944,"mc":[{"id":"1.232239000","rc":[{"trd":[[13,1.76]],"batb":[[0,13,4.56],[1,12.5,30.93],[2,3.2,2]],"batl":[[0,21,0.51]],"ltp":13.0,"tv":16.9,"id":60971786}],"tv":1586.89}]}
{"op":"mcm","clk":"11959479221","pt":1724581931353,"mc":[{"id":"1.232239000","rc":[{"batb":[[0,12.5,30.93],[1,3.2,2],[2,2.1,4.09]],"ltp":13.0,"tv":16.9,"id":60971786}]}]}
{"op":"mcm","clk":"11959480097","pt":1724581937059,"mc":[{"id":"1.232239000","rc":[{"batb":[[0,13,5],[1,12.5,30.93],[2,3.2,2]],"ltp":13.0,"tv":16.9,"id":60971786}]}]}
{"op":"mcm","clk":"11959480661","pt":1724581940436,"mc":[{"id":"1.232239000","rc":[{"batb":[[0,12.5,30.93],[1,3.2,2],[2,2.1,4.09]],"ltp":13.0,"tv":16.9,"id":60971786}]}]}
{"op":"mcm","clk":"11959481125","pt":1724581943553,"mc":[{"id":"1.232239000","rc":[{"batb":[[0,13,5],[1,12.5,30.93],[2,3.2,2]],"ltp":13.0,"tv":16.9,"id":60971786}]}]}
{"op":"mcm","clk":"11959481629","pt":1724581946942,"mc":[{"id":"1.232239000","rc":[{"batb":[[0,12.5,30.93],[1,3.2,2],[2,2.1,4.09]],"ltp":13.0,"tv":16.9,"id":60971786}]}]}
{"op":"mcm","clk":"11959481965","pt":1724581949363,"mc":[{"id":"1.232239000","rc":[{"batb":[[0,13,5],[1,12.5,30.93],[2,3.2,2]],"ltp":13.0,"tv":16.9,"id":60971786}]}]}
{"op":"mcm","clk":"11959482613","pt":1724581953267,"mc":[{"id":"1.232239000","rc":[{"batb":[[0,12.5,30.93],[1,3.2,2],[2,2.1,4.09]],"ltp":13.0,"tv":16.9,"id":60971786}]}]}
{"op":"mcm","clk":"11959483772","pt":1724581961253,"mc":[{"id":"1.232239000","rc":[{"batb":[[0,13,5],[1,12.5,30.93],[2,3.2,2]],"ltp":13.0,"tv":16.9,"id":60971786}]}]}
{"op":"mcm","clk":"11959484220","pt":1724581964571,"mc":[{"id":"1.232239000","rc":[{"batb":[[0,12.5,30.93],[1,3.2,2],[2,2.1,4.09]],"ltp":13.0,"tv":16.9,"id":60971786}]}]}
{"op":"mcm","clk":"11959484655","pt":1724581967468,"mc":[{"id":"1.232239000","rc":[{"batb":[[0,13,5],[1,12.5,30.93],[2,3.2,2]],"ltp":13.0,"tv":16.9,"id":60971786}]}]}
{"op":"mcm","clk":"11959485115","pt":1724581970676,"mc":[{"id":"1.232239000","rc":[{"batb":[[0,12.5,30.93],[1,3.2,2],[2,2.1,4.09]],"ltp":13.0,"tv":16.9,"id":60971786}]}]}
{"op":"mcm","clk":"11959486068","pt":1724581976968,"mc":[{"id":"1.232239000","rc":[{"batb":[[0,13,5],[1,12.5,30.93],[2,3.2,2]],"ltp":13.0,"tv":16.9,"id":60971786}]}]}
{"op":"mcm","clk":"11959486610","pt":1724581980397,"mc":[{"id":"1.232239000","rc":[{"batb":[[0,12.5,30.93],[1,3.2,2],[2,2.1,4.09]],"ltp":13.0,"tv":16.9,"id":60971786}]}]}
{"op":"mcm","clk":"11959486962","pt":1724581982709,"mc":[{"id":"1.232239000","rc":[{"batb":[[0,13,5],[1,12.5,30.93],[2,3.2,2]],"ltp":13.0,"tv":16.9,"id":60971786}]}]}
{"op":"mcm","clk":"11959487436","pt":1724581986016,"mc":[{"id":"1.232239000","rc":[{"batb":[[0,12.5,30.93],[1,3.2,2],[2,2.1,4.09]],"ltp":13.0,"tv":16.9,"id":60971786}]}]}
{"op":"mcm","clk":"11959488978","pt":1724581995978,"mc":[{"id":"1.232239000","rc":[{"batb":[[0,13,5],[1,12.5,30.93],[2,3.2,2]],"ltp":13.0,"tv":16.9,"id":60971786}]}]}
{"op":"mcm","clk":"11959489439","pt":1724581999329,"mc":[{"id":"1.232239000","rc":[{"batb":[[0,12.5,30.93],[1,3.2,2],[2,2.1,4.09]],"ltp":13.0,"tv":16.9,"id":60971786}]}]}
{"op":"mcm","clk":"11959489925","pt":1724582002313,"mc":[{"id":"1.232239000","rc":[{"batb":[[0,13,5],[1,12.5,30.93],[2,3.2,2]],"ltp":13.0,"tv":16.9,"id":60971786}]}]}
{"op":"mcm","clk":"11959490426","pt":1724582005721,"mc":[{"id":"1.232239000","rc":[{"batb":[[0,12.5,30.93],[1,3.2,2],[2,2.1,4.09]],"ltp":13.0,"tv":16.9,"id":60971786}]}]}
{"op":"mcm","clk":"11959491189","pt":1724582011121,"mc":[{"id":"1.232239000","rc":[{"batb":[[0,13,5],[1,12.5,30.93],[2,3.2,2]],"ltp":13.0,"tv":16.9,"id":60971786}]}]}
{"op":"mcm","clk":"11959491710","pt":1724582014394,"mc":[{"id":"1.232239000","rc":[{"batb":[[0,12.5,30.93],[1,3.2,2],[2,2.1,4.09]],"ltp":13.0,"tv":16.9,"id":60971786}]}]}
{"op":"mcm","clk":"11959492190","pt":1724582017321,"mc":[{"id":"1.232239000","rc":[{"batb":[[0,13,5],[1,12.5,30.93],[2,3.2,2]],"ltp":13.0,"tv":16.9,"id":60971786}]}]}
{"op":"mcm","clk":"11959492754","pt":1724582020705,"mc":[{"id":"1.232239000","rc":[{"batb":[[0,12.5,30.93],[1,3.2,2],[2,2.1,4.09]],"ltp":13.0,"tv":16.9,"id":60971786}]}]}
{"op":"mcm","clk":"11959493382","pt":1724582024735,"mc":[{"id":"1.232239000","rc":[{"batb":[[0,13,5],[1,12.5,30.93],[2,3.2,2]],"ltp":13.0,"tv":16.9,"id":60971786}]}]}
{"op":"mcm","clk":"11959493875","pt":1724582028008,"mc":[{"id":"1.232239000","rc":[{"batb":[[0,12.5,30.93],[1,3.2,2],[2,2.1,4.09]],"ltp":13.0,"tv":16.9,"id":60971786}]}]}
{"op":"mcm","clk":"11959494406","pt":1724582031310,"mc":[{"id":"1.232239000","rc":[{"batb":[[0,13,5],[1,12.5,30.93],[2,3.2,2]],"ltp":13.0,"tv":16.9,"id":60971786}]}]}
{"op":"mcm","clk":"11959494895","pt":1724582034614,"mc":[{"id":"1.232239000","rc":[{"batb":[[0,12.5,30.93],[1,3.2,2],[2,2.1,4.09]],"ltp":13.0,"tv":16.9,"id":60971786}]}]}
{"op":"mcm","clk":"11959495345","pt":1724582037609,"mc":[{"id":"1.232239000","rc":[{"batb":[[0,13,5],[1,12.5,30.93],[2,3.2,2]],"ltp":13.0,"tv":16.9,"id":60971786}]}]}
{"op":"mcm","clk":"11959495876","pt":1724582041038,"mc":[{"id":"1.232239000","rc":[{"batb":[[0,12.5,30.93],[1,3.2,2],[2,2.1,4.09]],"ltp":13.0,"tv":16.9,"id":60971786}]}]}
{"op":"mcm","clk":"11959496837","pt":1724582046756,"mc":[{"id":"1.232239000","rc":[{"batb":[[0,13,5],[1,12.5,30.93],[2,3.2,2]],"ltp":13.0,"tv":16.9,"id":60971786}]}]}
{"op":"mcm","clk":"11959497377","pt":1724582049959,"mc":[{"id":"1.232239000","rc":[{"batb":[[0,12.5,30.93],[1,3.2,2],[2,2.1,4.09]],"ltp":13.0,"tv":16.9,"id":60971786}]}]}
{"op":"mcm","clk":"11959497885","pt":1724582053060,"mc":[{"id":"1.232239000","rc":[{"batb":[[0,13,5],[1,12.5,30.93],[2,3.2,2]],"ltp":13.0,"tv":16.9,"id":60971786}]}]}
{"op":"mcm","clk":"11959498426","pt":1724582056268,"mc":[{"id":"1.232239000","rc":[{"batb":[[0,12.5,30.93],[1,3.2,2],[2,2.1,4.09]],"ltp":13.0,"tv":16.9,"id":60971786}]}]}
{"op":"mcm","clk":"11959499209","pt":1724582061100,"mc":[{"id":"1.232239000","rc":[{"batb":[[0,13,5],[1,12.5,30.93],[2,3.2,2]],"ltp":13.0,"tv":16.9,"id":60971786}]}]}
{"op":"mcm","clk":"11959499791","pt":1724582064265,"mc":[{"id":"1.232239000","rc":[{"batb":[[0,12.5,30.93],[1,3.2,2],[2,2.1,4.09]],"ltp":13.0,"tv":16.9,"id":60971786}]}]}
{"op":"mcm","clk":"11959501045","pt":1724582071764,"mc":[{"id":"1.232239000","rc":[{"batb":[[0,13,5],[1,12.5,30.93],[2,3.2,2]],"ltp":13.0,"tv":16.9,"id":60971786}]}]}
{"op":"mcm","clk":"11959501590","pt":1724582075163,"mc":[{"id":"1.232239000","rc":[{"batb":[[0,12.5,30.93],[1,3.2,2],[2,2.1,4.09]],"ltp":13.0,"tv":16.9,"id":60971786}]}]}
{"op":"mcm","clk":"11959502875","pt":1724582083599,"mc":[{"id":"1.232239000","rc":[{"batb":[[0,13,5],[1,12.5,30.93],[2,3.2,2]],"ltp":13.0,"tv":16.9,"id":60971786}]}]}
{"op":"mcm","clk":"11959503427","pt":1724582087028,"mc":[{"id":"1.232239000","rc":[{"batb":[[0,12.5,30.93],[1,3.2,2],[2,2.1,4.09]],"ltp":13.0,"tv":16.9,"id":60971786}]}]}
{"op":"mcm","clk":"11959503892","pt":1724582089730,"mc":[{"id":"1.232239000","rc":[{"batb":[[0,13,5],[1,12.5,30.93],[2,3.2,2]],"ltp":13.0,"tv":16.9,"id":60971786}]}]}
{"op":"mcm","clk":"11959504417","pt":1724582092915,"mc":[{"id":"1.232239000","rc":[{"batb":[[0,12.5,30.93],[1,3.2,2],[2,2.1,4.09]],"ltp":13.0,"tv":16.9,"id":60971786}]}]}
{"op":"mcm","clk":"11959504968","pt":1724582096084,"mc":[{"id":"1.232239000","rc":[{"batb":[[0,13,5],[1,12.5,30.93],[2,3.2,2]],"ltp":13.0,"tv":16.9,"id":60971786}]}]}
{"op":"mcm","clk":"11959505534","pt":1724582099300,"mc":[{"id":"1.232239000","rc":[{"batb":[[0,12.5,30.93],[1,3.2,2],[2,2.1,4.09]],"ltp":13.0,"tv":16.9,"id":60971786}]}]}
{"op":"mcm","clk":"11959506352","pt":1724582104043,"mc":[{"id":"1.232239000","rc":[{"batb":[[0,13,5],[1,12.5,30.93],[2,3.2,2]],"ltp":13.0,"tv":16.9,"id":60971786}]}]}
{"op":"mcm","clk":"11959506933","pt":1724582107320,"mc":[{"id":"1.232239000","rc":[{"batb":[[0,12.5,30.93],[1,3.2,2],[2,2.1,4.09]],"ltp":13.0,"tv":16.9,"id":60971786}]}]}
{"op":"mcm","clk":"11959508046","pt":1724582113832,"mc":[{"id":"1.232239000","rc":[{"batb":[[0,13,5],[1,12.5,30.93],[2,3.2,2]],"ltp":13.0,"tv":16.9,"id":60971786}]}]}
{"op":"mcm","clk":"11959508661","pt":1724582117300,"mc":[{"id":"1.232239000","rc":[{"batb":[[0,12.5,30.93],[1,3.2,2],[2,2.1,4.09]],"ltp":13.0,"tv":16.9,"id":60971786}]}]}
{"op":"mcm","clk":"11959509132","pt":1724582120128,"mc":[{"id":"1.232239000","rc":[{"batb":[[0,13,5],[1,12.5,30.93],[2,3.2,2]],"ltp":13.0,"tv":16.9,"id":60971786}]}]}
{"op":"mcm","clk":"11959509704","pt":1724582123460,"mc":[{"id":"1.232239000","rc":[{"batb":[[0,12.5,30.93],[1,3.2,2],[2,2.1,4.09]],"ltp":13.0,"tv":16.9,"id":60971786}]}]}
{"op":"mcm","clk":"11959510301","pt":1724582126963,"mc":[{"id":"1.232239000","rc":[{"batb":[[0,13,5],[1,12.5,30.93],[2,3.2,2]],"ltp":13.0,"tv":16.9,"id":60971786}]}]}
{"op":"mcm","clk":"11959510838","pt":1724582130263,"mc":[{"id":"1.232239000","rc":[{"batb":[[0,12.5,30.93],[1,3.2,2],[2,2.1,4.09]],"ltp":13.0,"tv":16.9,"id":60971786}]}]}
{"op":"mcm","clk":"11959511854","pt":1724582136282,"mc":[{"id":"1.232239000","rc":[{"batb":[[0,13,5],[1,12.5,30.93],[2,3.2,2]],"ltp":13.0,"tv":16.9,"id":60971786}]}]}
{"op":"mcm","clk":"11959512418","pt":1724582139688,"mc":[{"id":"1.232239000","rc":[{"batb":[[0,12.5,30.93],[1,3.2,2],[2,2.1,4.09]],"ltp":13.0,"tv":16.9,"id":60971786}]}]}
{"op":"mcm","clk":"11959513087","pt":1724582143781,"mc":[{"id":"1.232239000","rc":[{"batb":[[0,13,5],[1,12.5,30.93],[2,3.2,2]],"ltp":13.0,"tv":16.9,"id":60971786}]}]}
{"op":"mcm","clk":"11959513634","pt":1724582147088,"mc":[{"id":"1.232239000","rc":[{"batb":[[0,12.5,30.93],[1,3.2,2],[2,2.1,4.09]],"ltp":13.0,"tv":16.9,"id":60971786}]}]}
{"op":"mcm","clk":"11959515405","pt":1724582158814,"mc":[{"id":"1.232239000","rc":[{"batb":[[0,13,5],[1,12.5,30.93],[2,3.2,2]],"ltp":13.0,"tv":16.9,"id":60971786}]}]}
{"op":"mcm","clk":"11959515921","pt":1724582162019,"mc":[{"id":"1.232239000","rc":[{"batb":[[0,12.5,30.93],[1,3.2,2],[2,2.1,4.09]],"ltp":13.0,"tv":16.9,"id":60971786}]}]}
{"op":"mcm","clk":"11959516905","pt":1724582168091,"mc":[{"id":"1.232239000","rc":[{"batb":[[0,13,5],[1,12.5,30.93],[2,3.2,2]],"ltp":13.0,"tv":16.9,"id":60971786}]}]}
{"op":"mcm","clk":"11959517432","pt":1724582171517,"mc":[{"id":"1.232239000","rc":[{"batb":[[0,12.5,30.93],[1,3.2,2],[2,2.1,4.09]],"ltp":13.0,"tv":16.9,"id":60971786}]}]}
{"op":"mcm","clk":"11959517783","pt":1724582173610,"mc":[{"id":"1.232239000","rc":[{"batb":[[0,13,5],[1,12.5,30.93],[2,3.2,2]],"ltp":13.0,"tv":16.9,"id":60971786}]}]}
{"op":"mcm","clk":"11959518337","pt":1724582177018,"mc":[{"id":"1.232239000","rc":[{"batb":[[0,12.5,30.93],[1,3.2,2],[2,2.1,4.09]],"ltp":13.0,"tv":16.9,"id":60971786}]}]}
{"op":"mcm","clk":"11959519155","pt":1724582182467,"mc":[{"id":"1.232239000","rc":[{"batb":[[0,13,5],[1,12.5,30.93],[2,3.2,2]],"ltp":13.0,"tv":16.9,"id":60971786}]}]}
{"op":"mcm","clk":"11959519672","pt":1724582185629,"mc":[{"id":"1.232239000","rc":[{"batb":[[0,12.5,30.93],[1,3.2,2],[2,2.1,4.09]],"ltp":13.0,"tv":16.9,"id":60971786}]}]}
{"op":"mcm","clk":"11959521329","pt":1724582196464,"mc":[{"id":"1.232239000","rc":[{"batb":[[0,13,5],[1,12.5,30.93],[2,3.2,2]],"ltp":13.0,"tv":16.9,"id":60971786}]}]}
{"op":"mcm","clk":"11959521910","pt":1724582200052,"mc":[{"id":"1.232239000","rc":[{"batb":[[0,12.5,30.93],[1,3.2,2],[2,2.1,4.09]],"ltp":13.0,"tv":16.9,"id":60971786}]}]}
{"op":"mcm","clk":"11959522549","pt":1724582204131,"mc":[{"id":"1.232239000","rc":[{"batb":[[0,13,5],[1,12.5,30.93],[2,3.2,2]],"ltp":13.0,"tv":16.9,"id":60971786}]}]}
{"op":"mcm","clk":"11959523032","pt":1724582207471,"mc":[{"id":"1.232239000","rc":[{"batb":[[0,12.5,30.93],[1,3.2,2],[2,2.1,4.09]],"ltp":13.0,"tv":16.9,"id":60971786}]}]}
{"op":"mcm","clk":"11959524484","pt":1724582216710,"mc":[{"id":"1.232239000","rc":[{"batb":[[0,13,5],[1,12.5,30.93],[2,3.2,2]],"ltp":13.0,"tv":16.9,"id":60971786}]}]}
{"op":"mcm","clk":"11959525112","pt":1724582220486,"mc":[{"id":"1.232239000","rc":[{"batb":[[0,12.5,30.93],[1,3.2,2],[2,2.1,4.09]],"ltp":13.0,"tv":16.9,"id":60971786}]}]}
{"op":"mcm","clk":"11959525571","pt":1724582223482,"mc":[{"id":"1.232239000","rc":[{"batb":[[0,13,5],[1,12.5,30.93],[2,3.2,2]],"ltp":13.0,"tv":16.9,"id":60971786}]}]}
{"op":"mcm","clk":"11959526039","pt":1724582226720,"mc":[{"id":"1.232239000","rc":[{"batb":[[0,12.5,30.93],[1,3.2,2],[2,2.1,4.09]],"ltp":13.0,"tv":16.9,"id":60971786}]}]}
{"op":"mcm","clk":"11959526595","pt":1724582230308,"mc":[{"id":"1.232239000","rc":[{"batb":[[0,13,5],[1,12.5,30.93],[2,3.2,2]],"ltp":13.0,"tv":16.9,"id":60971786}]}]}
{"op":"mcm","clk":"11959527184","pt":1724582233672,"mc":[{"id":"1.232239000","rc":[{"batb":[[0,12.5,30.93],[1,3.2,2],[2,2.1,4.09]],"ltp":13.0,"tv":16.9,"id":60971786}]}]}
{"op":"mcm","clk":"11959528296","pt":1724582240605,"mc":[{"id":"1.232239000","rc":[{"batb":[[0,13,5],[1,12.5,30.93],[2,3.2,2]],"ltp":13.0,"tv":16.9,"id":60971786}]}]}
{"op":"mcm","clk":"11959528823","pt":1724582243795,"mc":[{"id":"1.232239000","rc":[{"batb":[[0,12.5,30.93],[1,3.2,2],[2,2.1,4.09]],"ltp":13.0,"tv":16.9,"id":60971786}]}]}
{"op":"mcm","clk":"11959529297","pt":1724582246736,"mc":[{"id":"1.232239000","rc":[{"batb":[[0,13,5],[1,12.5,30.93],[2,3.2,2]],"ltp":13.0,"tv":16.9,"id":60971786}]}]}
{"op":"mcm","clk":"11959529809","pt":1724582249926,"mc":[{"id":"1.232239000","rc":[{"batb":[[0,12.5,30.93],[1,3.2,2],[2,2.1,4.09]],"ltp":13.0,"tv":16.9,"id":60971786}]}]}
{"op":"mcm","clk":"11959530213","pt":1724582252338,"mc":[{"id":"1.232239000","rc":[{"batb":[[0,13,5],[1,12.5,30.93],[2,3.2,2]],"ltp":13.0,"tv":16.9,"id":60971786}]}]}
{"op":"mcm","clk":"11959530780","pt":1724582255533,"mc":[{"id":"1.232239000","rc":[{"batb":[[0,12.5,30.93],[1,3.2,2],[2,2.1,4.09]],"ltp":13.0,"tv":16.9,"id":60971786}]}]}
{"op":"mcm","clk":"11959531843","pt":1724582262540,"mc":[{"id":"1.232239000","rc":[{"batb":[[0,13,5],[1,12.5,30.93],[2,3.2,2]],"ltp":13.0,"tv":16.9,"id":60971786}]}]}
{"op":"mcm","clk":"11959532297","pt":1724582265728,"mc":[{"id":"1.232239000","rc":[{"batb":[[0,12.5,30.93],[1,3.2,2],[2,2.1,4.09]],"ltp":13.0,"tv":16.9,"id":60971786}]}]}
{"op":"mcm","clk":"11959534020","pt":1724582277262,"mc":[{"id":"1.232239000","rc":[{"batb":[[0,13,5],[1,12.5,30.93],[2,3.2,2]],"ltp":13.0,"tv":16.9,"id":60971786}]}]}
{"op":"mcm","clk":"11959534591","pt":1724582280655,"mc":[{"id":"1.232239000","rc":[{"batb":[[0,12.5,30.93],[1,3.2,2],[2,2.1,4.09]],"ltp":13.0,"tv":16.9,"id":60971786}]}]}
{"op":"mcm","clk":"11959536594","pt":1724582294653,"mc":[{"id":"1.232239000","rc":[{"batb":[[0,13,5],[1,12.5,30.93],[2,3.2,2]],"ltp":13.0,"tv":16.9,"id":60971786}]}]}
{"op":"mcm","clk":"11959537081","pt":1724582297997,"mc":[{"id":"1.232239000","rc":[{"batb":[[0,12.5,30.93],[1,3.2,2],[2,2.1,4.09]],"ltp":13.0,"tv":16.9,"id":60971786}]}]}
{"op":"mcm","clk":"11959537748","pt":1724582301857,"mc":[{"id":"1.232239000","rc":[{"batb":[[0,13,5],[1,12.5,30.93],[2,3.2,2]],"ltp":13.0,"tv":16.9,"id":60971786}]}]}
{"op":"mcm","clk":"11959538281","pt":1724582305186,"mc":[{"id":"1.232239000","rc":[{"batb":[[0,12.5,30.93],[1,3.2,2],[2,2.1,4.09]],"ltp":13.0,"tv":16.9,"id":60971786}]}]}
{"op":"mcm","clk":"11959538756","pt":1724582308466,"mc":[{"id":"1.232239000","rc":[{"batb":[[0,13,5],[1,12.5,30.93],[2,3.2,2]],"ltp":13.0,"tv":16.9,"id":60971786}]}]}
{"op":"mcm","clk":"11959539261","pt":1724582311861,"mc":[{"id":"1.232239000","rc":[{"batb":[[0,12.5,30.93],[1,3.2,2],[2,2.1,4.09]],"ltp":13.0,"tv":16.9,"id":60971786}]}]}
{"op":"mcm","clk":"11959541563","pt":1724582327300,"mc":[{"id":"1.232239000","rc":[{"batb":[[0,13,5],[1,12.5,30.93],[2,3.2,2]],"ltp":13.0,"tv":16.9,"id":60971786}]}]}
{"op":"mcm","clk":"11959542019","pt":1724582330594,"mc":[{"id":"1.232239000","rc":[{"batb":[[0,12.5,30.93],[1,3.2,2],[2,2.1,4.09]],"ltp":13.0,"tv":16.9,"id":60971786}]}]}
{"op":"mcm","clk":"11959542508","pt":1724582333818,"mc":[{"id":"1.232239000","rc":[{"batb":[[0,13,5],[1,12.5,30.93],[2,3.2,2]],"ltp":13.0,"tv":16.9,"id":60971786}]}]}
{"op":"mcm","clk":"11959542960","pt":1724582337003,"mc":[{"id":"1.232239000","rc":[{"batb":[[0,12.5,30.93],[1,3.2,2],[2,2.1,4.09]],"ltp":13.0,"tv":16.9,"id":60971786}]}]}
{"op":"mcm","clk":"11959543497","pt":1724582340914,"mc":[{"id":"1.232239000","rc":[{"batb":[[0,13,5],[1,12.5,30.93],[2,3.2,2]],"ltp":13.0,"tv":16.9,"id":60971786}]}]}
{"op":"mcm","clk":"11959543947","pt":1724582344231,"mc":[{"id":"1.232239000","rc":[{"batb":[[0,12.5,30.93],[1,3.2,2],[2,2.1,4.09]],"ltp":13.0,"tv":16.9,"id":60971786}]}]}
{"op":"mcm","clk":"11959544432","pt":1724582347299,"mc":[{"id":"1.232239000","rc":[{"batb":[[0,13,5],[1,12.5,30.93],[2,3.2,2]],"ltp":13.0,"tv":16.9,"id":60971786}]}]}
{"op":"mcm","clk":"11959544927","pt":1724582350825,"mc":[{"id":"1.232239000","rc":[{"batb":[[0,12.5,30.93],[1,3.2,2],[2,2.1,4.09]],"ltp":13.0,"tv":16.9,"id":60971786}]}]}
{"op":"mcm","clk":"11959545437","pt":1724582354137,"mc":[{"id":"1.232239000","rc":[{"batb":[[0,13,5],[1,12.5,30.93],[2,3.2,2]],"ltp":13.0,"tv":16.9,"id":60971786}]}]}
{"op":"mcm","clk":"11959545913","pt":1724582357538,"mc":[{"id":"1.232239000","rc":[{"batb":[[0,12.5,30.93],[1,3.2,2],[2,2.1,4.09]],"ltp":13.0,"tv":16.9,"id":60971786}]}]}
{"op":"mcm","clk":"11959546350","pt":1724582360318,"mc":[{"id":"1.232239000","rc":[{"batb":[[0,13,5],[1,12.5,30.93],[2,3.2,2]],"ltp":13.0,"tv":16.9,"id":60971786}]}]}
{"op":"mcm","clk":"11959546871","pt":1724582363619,"mc":[{"id":"1.232239000","rc":[{"batb":[[0,12.5,30.93],[1,3.2,2],[2,2.1,4.09]],"ltp":13.0,"tv":16.9,"id":60971786}]}]}
{"op":"mcm","clk":"11959547696","pt":1724582369224,"mc":[{"id":"1.232239000","rc":[{"batb":[[0,13,5],[1,12.5,30.93],[2,3.2,2]],"ltp":13.0,"tv":16.9,"id":60971786}]}]}
{"op":"mcm","clk":"11959548159","pt":1724582372465,"mc":[{"id":"1.232239000","rc":[{"batb":[[0,12.5,30.93],[1,3.2,2],[2,2.1,4.09]],"ltp":13.0,"tv":16.9,"id":60971786}]}]}
{"op":"mcm","clk":"11959548746","pt":1724582376130,"mc":[{"id":"1.232239000","rc":[{"batb":[[0,13,5],[1,12.5,30.93],[2,3.2,2]],"ltp":13.0,"tv":16.9,"id":60971786}]}]}
{"op":"mcm","clk":"11959549183","pt":1724582379367,"mc":[{"id":"1.232239000","rc":[{"batb":[[0,12.5,30.93],[1,3.2,2],[2,2.1,4.09]],"ltp":13.0,"tv":16.9,"id":60971786}]}]}
{"op":"mcm","clk":"11959549961","pt":1724582384278,"mc":[{"id":"1.232239000","rc":[{"batb":[[0,13,5],[1,12.5,30.93],[2,3.2,2]],"ltp":13.0,"tv":16.9,"id":60971786}]}]}
{"op":"mcm","clk":"11959550432","pt":1724582387578,"mc":[{"id":"1.232239000","rc":[{"batb":[[0,12.5,30.93],[1,3.2,2],[2,2.1,4.09]],"ltp":13.0,"tv":16.9,"id":60971786}]}]}
{"op":"mcm","clk":"11959550930","pt":1724582391166,"mc":[{"id":"1.232239000","rc":[{"batb":[[0,13,5],[1,12.5,30.93],[2,3.2,2]],"ltp":13.0,"tv":16.9,"id":60971786}]}]}
{"op":"mcm","clk":"11959551407","pt":1724582394553,"mc":[{"id":"1.232239000","rc":[{"batb":[[0,12.5,30.93],[1,3.2,2],[2,2.1,4.09]],"ltp":13.0,"tv":16.9,"id":60971786}]}]}
{"op":"mcm","clk":"11959551813","pt":1724582397295,"mc":[{"id":"1.232239000","rc":[{"batb":[[0,13,5],[1,12.5,30.93],[2,3.2,2]],"ltp":13.0,"tv":16.9,"id":60971786}]}]}
{"op":"mcm","clk":"11959552341","pt":1724582400652,"mc":[{"id":"1.232239000","rc":[{"batb":[[0,12.5,30.93],[1,3.2,2],[2,2.1,4.09]],"ltp":13.0,"tv":16.9,"id":60971786}]}]}
{"op":"mcm","clk":"11959553993","pt":1724582411857,"mc":[{"id":"1.232239000","rc":[{"batb":[[0,13,5],[1,12.5,30.93],[2,3.2,2]],"ltp":13.0,"tv":16.9,"id":60971786}]}]}
{"op":"mcm","clk":"11959554512","pt":1724582415176,"mc":[{"id":"1.232239000","rc":[{"batb":[[0,12.5,30.93],[1,3.2,2],[2,2.1,4.09]],"ltp":13.0,"tv":16.9,"id":60971786}]}]}
{"op":"mcm","clk":"11959555015","pt":1724582418402,"mc":[{"id":"1.232239000","rc":[{"batb":[[0,13,5],[1,12.5,30.93],[2,3.2,2]],"ltp":13.0,"tv":16.9,"id":60971786}]}]}
{"op":"mcm","clk":"11959555535","pt":1724582421823,"mc":[{"id":"1.232239000","rc":[{"batb":[[0,12.5,30.93],[1,3.2,2],[2,2.1,4.09]],"ltp":13.0,"tv":16.9,"id":60971786}]}]}
{"op":"mcm","clk":"11959556339","pt":1724582426884,"mc":[{"id":"1.232239000","rc":[{"batb":[[0,13,5],[1,12.5,30.93],[2,3.2,2]],"ltp":13.0,"tv":16.9,"id":60971786}]}]}
{"op":"mcm","clk":"11959556841","pt":1724582430194,"mc":[{"id":"1.232239000","rc":[{"batb":[[0,12.5,30.93],[1,3.2,2],[2,2.1,4.09]],"ltp":13.0,"tv":16.9,"id":60971786}]}]}
{"op":"mcm","clk":"11959557346","pt":1724582433602,"mc":[{"id":"1.232239000","rc":[{"batb":[[0,13,5],[1,12.5,30.93],[2,3.2,2]],"ltp":13.0,"tv":16.9,"id":60971786}]}]}
{"op":"mcm","clk":"11959557810","pt":1724582436997,"mc":[{"id":"1.232239000","rc":[{"batb":[[0,12.5,30.93],[1,3.2,2],[2,2.1,4.09]],"ltp":13.0,"tv":16.9,"id":60971786}]}]}
{"op":"mcm","clk":"11959558423","pt":1724582441625,"mc":[{"id":"1.232239000","rc":[{"batb":[[0,13,5],[1,12.5,30.93],[2,3.2,2]],"ltp":13.0,"tv":16.9,"id":60971786}]}]}
{"op":"mcm","clk":"11959558865","pt":1724582444924,"mc":[{"id":"1.232239000","rc":[{"batb":[[0,12.5,30.93],[1,3.2,2],[2,2.1,4.09]],"ltp":13.0,"tv":16.9,"id":60971786}]}]}
{"op":"mcm","clk":"11959559315","pt":1724582448321,"mc":[{"id":"1.232239000","rc":[{"batb":[[0,13,5],[1,12.5,30.93],[2,3.2,2]],"ltp":13.0,"tv":16.9,"id":60971786}]}]}
{"op":"mcm","clk":"11959559780","pt":1724582451607,"mc":[{"id":"1.232239000","rc":[{"batb":[[0,12.5,30.93],[1,3.2,2],[2,2.1,4.09]],"ltp":13.0,"tv":16.9,"id":60971786}]}]}
{"op":"mcm","clk":"11959560115","pt":1724582454221,"mc":[{"id":"1.232239000","rc":[{"batb":[[0,13,5],[1,12.5,30.93],[2,3.2,2]],"ltp":13.0,"tv":16.9,"id":60971786}]}]}
{"op":"mcm","clk":"11959560604","pt":1724582457628,"mc":[{"id":"1.232239000","rc":[{"batb":[[0,12.5,30.93],[1,3.2,2],[2,2.1,4.09]],"ltp":13.0,"tv":16.9,"id":60971786}]}]}
{"op":"mcm","clk":"11959561400","pt":1724582463226,"mc":[{"id":"1.232239000","rc":[{"batb":[[0,13,5],[1,12.5,30.93],[2,3.2,2]],"ltp":13.0,"tv":16.9,"id":60971786}]}]}
{"op":"mcm","clk":"11959561860","pt":1724582466536,"mc":[{"id":"1.232239000","rc":[{"batb":[[0,12.5,30.93],[1,3.2,2],[2,2.1,4.09]],"ltp":13.0,"tv":16.9,"id":60971786}]}]}
{"op":"mcm","clk":"11959562464","pt":1724582470738,"mc":[{"id":"1.232239000","rc":[{"batb":[[0,13,5],[1,12.5,30.93],[2,3.2,2]],"ltp":13.0,"tv":16.9,"id":60971786}]}]}
{"op":"mcm","clk":"11959562954","pt":1724582473980,"mc":[{"id":"1.232239000","rc":[{"batb":[[0,12.5,30.93],[1,3.2,2],[2,2.1,4.09]],"ltp":13.0,"tv":16.9,"id":60971786}]}]}
{"op":"mcm","clk":"11959563955","pt":1724582480961,"mc":[{"id":"1.232239000","rc":[{"batb":[[0,13,5],[1,12.5,30.93],[2,3.2,2]],"ltp":13.0,"tv":16.9,"id":60971786}]}]}
{"op":"mcm","clk":"11959564489","pt":1724582484272,"mc":[{"id":"1.232239000","rc":[{"batb":[[0,12.5,30.93],[1,3.2,2],[2,2.1,4.09]],"ltp":13.0,"tv":16.9,"id":60971786}]}]}
{"op":"mcm","clk":"11959564849","pt":1724582486693,"mc":[{"id":"1.232239000","rc":[{"batb":[[0,13,5],[1,12.5,30.93],[2,3.2,2]],"ltp":13.0,"tv":16.9,"id":60971786}]}]}
{"op":"mcm","clk":"11959565385","pt":1724582490054,"mc":[{"id":"1.232239000","rc":[{"batb":[[0,12.5,30.93],[1,3.2,2],[2,2.1,4.09]],"ltp":13.0,"tv":16.9,"id":60971786}]}]}
{"op":"mcm","clk":"11959566090","pt":1724582494896,"mc":[{"id":"1.232239000","rc":[{"batb":[[0,13,5],[1,12.5,30.93],[2,3.2,2]],"ltp":13.0,"tv":16.9,"id":60971786}]}]}
{"op":"mcm","clk":"11959566559","pt":1724582498292,"mc":[{"id":"1.232239000","rc":[{"batb":[[0,12.5,30.93],[1,3.2,2],[2,2.1,4.09]],"ltp":13.0,"tv":16.9,"id":60971786}]}]}
{"op":"mcm","clk":"11959566897","pt":1724582500690,"mc":[{"id":"1.232239000","rc":[{"batb":[[0,13,5],[1,12.5,30.93],[2,3.2,2]],"ltp":13.0,"tv":16.9,"id":60971786}]}]}
{"op":"mcm","clk":"11959567371","pt":1724582503980,"mc":[{"id":"1.232239000","rc":[{"batb":[[0,12.5,30.93],[1,3.2,2],[2,2.1,4.09]],"ltp":13.0,"tv":16.9,"id":60971786}]}]}
{"op":"mcm","clk":"11959567847","pt":1724582507084,"mc":[{"id":"1.232239000","rc":[{"batb":[[0,13,5],[1,12.5,30.93],[2,3.2,2]],"ltp":13.0,"tv":16.9,"id":60971786}]}]}
{"op":"mcm","clk":"11959568235","pt":1724582510184,"mc":[{"id":"1.232239000","rc":[{"batb":[[0,12.5,30.93],[1,3.2,2],[2,2.1,4.09]],"ltp":13.0,"tv":16.9,"id":60971786}]}]}
{"op":"mcm","clk":"11959568765","pt":1724582513892,"mc":[{"id":"1.232239000","rc":[{"batb":[[0,13,5],[1,12.5,30.93],[2,3.2,2]],"ltp":13.0,"tv":16.9,"id":60971786}]}]}
{"op":"mcm","clk":"11959569227","pt":1724582517091,"mc":[{"id":"1.232239000","rc":[{"batb":[[0,12.5,30.93],[1,3.2,2],[2,2.1,4.09]],"ltp":13.0,"tv":16.9,"id":60971786}]}]}
{"op":"mcm","clk":"11959569569","pt":1724582519917,"mc":[{"id":"1.232239000","rc":[{"batb":[[0,13,5],[1,12.5,30.93],[2,3.2,2]],"ltp":13.0,"tv":16.9,"id":60971786}]}]}
{"op":"mcm","clk":"11959570064","pt":1724582523214,"mc":[{"id":"1.232239000","rc":[{"batb":[[0,12.5,30.93],[1,3.2,2],[2,2.1,4.09]],"ltp":13.0,"tv":16.9,"id":60971786}]}]}
{"op":"mcm","clk":"11959571379","pt":1724582531094,"mc":[{"id":"1.232239000","rc":[{"batb":[[0,13,5],[1,12.5,30.93],[2,3.2,2]],"ltp":13.0,"tv":16.9,"id":60971786}]}]}
{"op":"mcm","clk":"11959571862","pt":1724582534422,"mc":[{"id":"1.232239000","rc":[{"batb":[[0,12.5,30.93],[1,3.2,2],[2,2.1,4.09]],"ltp":13.0,"tv":16.9,"id":60971786}]}]}
{"op":"mcm","clk":"11959573683","pt":1724582546852,"mc":[{"id":"1.232239000","rc":[{"batb":[[0,13,5],[1,12.5,30.93],[2,3.2,2]],"ltp":13.0,"tv":16.9,"id":60971786}]}]}
{"op":"mcm","clk":"11959574181","pt":1724582550041,"mc":[{"id":"1.232239000","rc":[{"batb":[[0,12.5,30.93],[1,3.2,2],[2,2.1,4.09]],"ltp":13.0,"tv":16.9,"id":60971786}]}]}
{"op":"mcm","clk":"11959574820","pt":1724582554446,"mc":[{"id":"1.232239000","rc":[{"batb":[[0,13,5],[1,12.5,30.93],[2,3.2,2]],"ltp":13.0,"tv":16.9,"id":60971786}]}]}
{"op":"mcm","clk":"11959575335","pt":1724582557742,"mc":[{"id":"1.232239000","rc":[{"batb":[[0,12.5,30.93],[1,3.2,2],[2,2.1,4.09]],"ltp":13.0,"tv":16.9,"id":60971786}]}]}
{"op":"mcm","clk":"11959576274","pt":1724582564461,"mc":[{"id":"1.232239000","rc":[{"batb":[[0,13,5],[1,12.5,30.93],[2,3.2,2]],"ltp":13.0,"tv":16.9,"id":60971786}]}]}
{"op":"mcm","clk":"11959576783","pt":1724582567870,"mc":[{"id":"1.232239000","rc":[{"batb":[[0,12.5,30.93],[1,3.2,2],[2,2.1,4.09]],"ltp":13.0,"tv":16.9,"id":60971786}]}]}
{"op":"mcm","clk":"11959577888","pt":1724582575192,"mc":[{"id":"1.232239000","rc":[{"batb":[[0,13,5],[1,12.5,30.93],[2,3.2,2]],"ltp":13.0,"tv":16.9,"id":60971786}]}]}
{"op":"mcm","clk":"11959578346","pt":1724582578293,"mc":[{"id":"1.232239000","rc":[{"batb":[[0,12.5,30.93],[1,3.2,2],[2,2.1,4.09]],"ltp":13.0,"tv":16.9,"id":60971786}]}]}
{"op":"mcm","clk":"11959579410","pt":1724582585083,"mc":[{"id":"1.232239000","rc":[{"batb":[[0,13,5],[1,12.5,30.93],[2,3.2,2]],"ltp":13.0,"tv":16.9,"id":60971786}]}]}
{"op":"mcm","clk":"11959579960","pt":1724582588592,"mc":[{"id":"1.232239000","rc":[{"batb":[[0,12.5,30.93],[1,3.2,2],[2,2.1,4.09]],"ltp":13.0,"tv":16.9,"id":60971786}]}]}
{"op":"mcm","clk":"11959580849","pt":1724582594264,"mc":[{"id":"1.232239000","rc":[{"batb":[[0,13,5],[1,12.5,30.93],[2,3.2,2]],"ltp":13.0,"tv":16.9,"id":60971786}]}]}
{"op":"mcm","clk":"11959581361","pt":1724582597683,"mc":[{"id":"1.232239000","rc":[{"batb":[[0,12.5,30.93],[1,3.2,2],[2,2.1,4.09]],"ltp":13.0,"tv":16.9,"id":60971786}]}]}
{"op":"mcm","clk":"11959582060","pt":1724582602607,"mc":[{"id":"1.232239000","rc":[{"batb":[[0,13,5],[1,12.5,30.93],[2,3.2,2]],"ltp":13.0,"tv":16.9,"id":60971786}]}]}
{"op":"mcm","clk":"11959582553","pt":1724582605883,"mc":[{"id":"1.232239000","rc":[{"batb":[[0,12.5,30.93],[1,3.2,2],[2,2.1,4.09]],"ltp":13.0,"tv":16.9,"id":60971786}]}]}
{"op":"mcm","clk":"11959583128","pt":1724582609922,"mc":[{"id":"1.232239000","rc":[{"batb":[[0,13,5],[1,12.5,30.93],[2,3.2,2]],"ltp":13.0,"tv":16.9,"id":60971786}]}]}
{"op":"mcm","clk":"11959583588","pt":1724582613215,"mc":[{"id":"1.232239000","rc":[{"batb":[[0,12.5,30.93],[1,3.2,2],[2,2.1,4.09]],"ltp":13.0,"tv":16.9,"id":60971786}]}]}
{"op":"mcm","clk":"11959584608","pt":1724582619810,"mc":[{"id":"1.232239000","rc":[{"batb":[[0,13,5],[1,12.5,30.93],[2,3.2,2]],"ltp":13.0,"tv":16.9,"id":60971786}]}]}
{"op":"mcm","clk":"11959585090","pt":1724582623113,"mc":[{"id":"1.232239000","rc":[{"batb":[[0,12.5,30.93],[1,3.2,2],[2,2.1,4.09]],"ltp":13.0,"tv":16.9,"id":60971786}]}]}
{"op":"mcm","clk":"11959586167","pt":1724582630402,"mc":[{"id":"1.232239000","rc":[{"batb":[[0,13,5],[1,12.5,30.93],[2,3.2,2]],"ltp":13.0,"tv":16.9,"id":60971786}]}]}
{"op":"mcm","clk":"11959586670","pt":1724582633710,"mc":[{"id":"1.232239000","rc":[{"batb":[[0,12.5,30.93],[1,3.2,2],[2,2.1,4.09]],"ltp":13.0,"tv":16.9,"id":60971786}]}]}
{"op":"mcm","clk":"11959587501","pt":1724582639540,"mc":[{"id":"1.232239000","rc":[{"batb":[[0,13,5],[1,12.5,30.93],[2,3.2,2]],"ltp":13.0,"tv":16.9,"id":60971786}]}]}
{"op":"mcm","clk":"11959588059","pt":1724582642958,"mc":[{"id":"1.232239000","rc":[{"batb":[[0,12.5,30.93],[1,3.2,2],[2,2.1,4.09]],"ltp":13.0,"tv":16.9,"id":60971786}]}]}
{"op":"mcm","clk":"11959588424","pt":1724582645258,"mc":[{"id":"1.232239000","rc":[{"batb":[[0,13,5],[1,12.5,30.93],[2,3.2,2]],"ltp":13.0,"tv":16.9,"id":60971786}]}]}
{"op":"mcm","clk":"11959588946","pt":1724582648444,"mc":[{"id":"1.232239000","rc":[{"batb":[[0,12.5,30.93],[1,3.2,2],[2,2.1,4.09]],"ltp":13.0,"tv":16.9,"id":60971786}]}]}
{"op":"mcm","clk":"11959589328","pt":1724582650942,"mc":[{"id":"1.232239000","rc":[{"batb":[[0,13,5],[1,12.5,30.93],[2,3.2,2]],"ltp":13.0,"tv":16.9,"id":60971786}]}]}
{"op":"mcm","clk":"11959589875","pt":1724582654259,"mc":[{"id":"1.232239000","rc":[{"batb":[[0,12.5,30.93],[1,3.2,2],[2,2.1,4.09]],"ltp":13.0,"tv":16.9,"id":60971786}]}]}
{"op":"mcm","clk":"11959590293","pt":1724582656842,"mc":[{"id":"1.232239000","rc":[{"batb":[[0,13,5],[1,12.5,30.93],[2,3.2,2]],"ltp":13.0,"tv":16.9,"id":60971786}]}]}
{"op":"mcm","clk":"11959590810","pt":1724582660241,"mc":[{"id":"1.232239000","rc":[{"batb":[[0,12.5,30.93],[1,3.2,2],[2,2.1,4.09]],"ltp":13.0,"tv":16.9,"id":60971786}]}]}
{"op":"mcm","clk":"11959591761","pt":1724582665960,"mc":[{"id":"1.232239000","rc":[{"batb":[[0,13,5],[1,12.5,30.93],[2,3.2,2]],"ltp":13.0,"tv":16.9,"id":60971786}]}]}
{"op":"mcm","clk":"11959592385","pt":1724582669370,"mc":[{"id":"1.232239000","rc":[{"batb":[[0,12.5,30.93],[1,3.2,2],[2,2.1,4.09]],"ltp":13.0,"tv":16.9,"id":60971786}]}]}
{"op":"mcm","clk":"11959593416","pt":1724582675673,"mc":[{"id":"1.232239000","rc":[{"batb":[[0,13,5],[1,12.5,30.93],[2,3.2,2]],"ltp":13.0,"tv":16.9,"id":60971786}]}]}
{"op":"mcm","clk":"11959593979","pt":1724582678960,"mc":[{"id":"1.232239000","rc":[{"batb":[[0,12.5,30.93],[1,3.2,2],[2,2.1,4.09]],"ltp":13.0,"tv":16.9,"id":60971786}]}]}
{"op":"mcm","clk":"11959596492","pt":1724582694181,"mc":[{"id":"1.232239000","rc":[{"batb":[[0,13,5],[1,12.5,30.93],[2,3.2,2]],"ltp":13.0,"tv":16.9,"id":60971786}]}]}
{"op":"mcm","clk":"11959597042","pt":1724582697384,"mc":[{"id":"1.232239000","rc":[{"batb":[[0,12.5,30.93],[1,3.2,2],[2,2.1,4.09]],"ltp":13.0,"tv":16.9,"id":60971786}]}]}
{"op":"mcm","clk":"11959597436","pt":1724582699797,"mc":[{"id":"1.232239000","rc":[{"batb":[[0,13,5],[1,12.5,30.93],[2,3.2,2]],"ltp":13.0,"tv":16.9,"id":60971786}]}]}
{"op":"mcm","clk":"11959598068","pt":1724582703084,"mc":[{"id":"1.232239000","rc":[{"batb":[[0,12.5,30.93],[1,3.2,2],[2,2.1,4.09]],"ltp":13.0,"tv":16.9,"id":60971786}]}]}
{"op":"mcm","clk":"11959600068","pt":1724582713594,"mc":[{"id":"1.232239000","rc":[{"batb":[[0,13,5],[1,12.5,30.93],[2,3.2,2]],"ltp":13.0,"tv":16.9,"id":60971786}]}]}
{"op":"mcm","clk":"11959600647","pt":1724582717008,"mc":[{"id":"1.232239000","rc":[{"batb":[[0,12.5,30.93],[1,3.2,2],[2,2.1,4.09]],"ltp":13.0,"tv":16.9,"id":60971786}]}]}
{"op":"mcm","clk":"11959601112","pt":1724582719597,"mc":[{"id":"1.232239000","rc":[{"batb":[[0,13,5],[1,12.5,30.93],[2,3.2,2]],"ltp":13.0,"tv":16.9,"id":60971786}]}]}
{"op":"mcm","clk":"11959601647","pt":1724582722962,"mc":[{"id":"1.232239000","rc":[{"batb":[[0,12.5,30.93],[1,3.2,2],[2,2.1,4.09]],"ltp":13.0,"tv":16.9,"id":60971786}]}]}
{"op":"mcm","clk":"11959602096","pt":1724582725434,"mc":[{"id":"1.232239000","rc":[{"batb":[[0,13,5],[1,12.5,30.93],[2,3.2,2]],"ltp":13.0,"tv":16.9,"id":60971786}]}]}
{"op":"mcm","clk":"11959602649","pt":1724582728716,"mc":[{"id":"1.232239000","rc":[{"batb":[[0,12.5,30.93],[1,3.2,2],[2,2.1,4.09]],"ltp":13.0,"tv":16.9,"id":60971786}]}]}
{"op":"mcm","clk":"11959604279","pt":1724582738612,"mc":[{"id":"1.232239000","rc":[{"batb":[[0,13,5],[1,12.5,30.93],[2,3.2,2]],"ltp":13.0,"tv":16.9,"id":60971786}]}]}
{"op":"mcm","clk":"11959604775","pt":1724582741920,"mc":[{"id":"1.232239000","rc":[{"batb":[[0,12.5,30.93],[1,3.2,2],[2,2.1,4.09]],"ltp":13.0,"tv":16.9,"id":60971786}]}]}
{"op":"mcm","clk":"11959605863","pt":1724582748436,"mc":[{"id":"1.232239000","rc":[{"batb":[[0,13,5],[1,12.5,30.93],[2,3.2,2]],"ltp":13.0,"tv":16.9,"id":60971786}]}]}
{"op":"mcm","clk":"11959606396","pt":1724582751725,"mc":[{"id":"1.232239000","rc":[{"batb":[[0,12.5,30.93],[1,3.2,2],[2,2.1,4.09]],"ltp":13.0,"tv":16.9,"id":60971786}]}]}
{"op":"mcm","clk":"11959606913","pt":1724582754750,"mc":[{"id":"1.232239000","rc":[{"batb":[[0,13,5],[1,12.5,30.93],[2,3.2,2]],"ltp":13.0,"tv":16.9,"id":60971786}]}]}
{"op":"mcm","clk":"11959607465","pt":1724582760058,"mc":[{"id":"1.232239000","rc":[{"batb":[[0,12.5,30.93],[1,3.2,2],[2,2.1,4.09]],"ltp":13.0,"tv":16.9,"id":60971786}]}]}
{"op":"mcm","clk":"11959607773","pt":1724582760579,"mc":[{"id":"1.232239000","rc":[{"batb":[[0,13,5],[1,12.5,30.93],[2,3.2,2]],"ltp":13.0,"tv":16.9,"id":60971786}]}]}
{"op":"mcm","clk":"11959608369","pt":1724582763548,"mc":[{"id":"1.232239000","rc":[{"batb":[[0,12.5,30.93],[1,3.2,2],[2,2.1,4.09]],"ltp":13.0,"tv":16.9,"id":60971786}]}]}
{"op":"mcm","clk":"11959609808","pt":1724582771779,"mc":[{"id":"1.232239000","rc":[{"batb":[[0,13,5],[1,12.5,30.93],[2,3.2,2]],"ltp":13.0,"tv":16.9,"id":60971786}]}]}
{"op":"mcm","clk":"11959610383","pt":1724582774987,"mc":[{"id":"1.232239000","rc":[{"batb":[[0,12.5,30.93],[1,3.2,2],[2,2.1,4.09]],"ltp":13.0,"tv":16.9,"id":60971786}]}]}
{"op":"mcm","clk":"11959611562","pt":1724582781567,"mc":[{"id":"1.232239000","rc":[{"batb":[[0,13,5],[1,12.5,30.93],[2,3.2,2]],"ltp":13.0,"tv":16.9,"id":60971786}]}]}
{"op":"mcm","clk":"11959612135","pt":1724582784880,"mc":[{"id":"1.232239000","rc":[{"batb":[[0,12.5,30.93],[1,3.2,2],[2,2.1,4.09]],"ltp":13.0,"tv":16.9,"id":60971786}]}]}
{"op":"mcm","clk":"11959612653","pt":1724582787763,"mc":[{"id":"1.232239000","rc":[{"batb":[[0,13,5],[1,12.5,30.93],[2,3.2,2]],"ltp":13.0,"tv":16.9,"id":60971786}]}]}
{"op":"mcm","clk":"11959613158","pt":1724582790967,"mc":[{"id":"1.232239000","rc":[{"batb":[[0,12.5,30.93],[1,3.2,2],[2,2.1,4.09]],"ltp":13.0,"tv":16.9,"id":60971786}]}]}
{"op":"mcm","clk":"11959614137","pt":1724582796509,"mc":[{"id":"1.232239000","rc":[{"batb":[[0,13,5],[1,12.5,30.93],[2,3.2,2]],"ltp":13.0,"tv":16.9,"id":60971786}]}]}
{"op":"mcm","clk":"11959614704","pt":1724582799902,"mc":[{"id":"1.232239000","rc":[{"batb":[[0,12.5,30.93],[1,3.2,2],[2,2.1,4.09]],"ltp":13.0,"tv":16.9,"id":60971786}]}]}
{"op":"mcm","clk":"11959615489","pt":1724582804290,"mc":[{"id":"1.232239000","rc":[{"batb":[[0,13,5],[1,12.5,30.93],[2,3.2,2]],"ltp":13.0,"tv":16.9,"id":60971786}]}]}
{"op":"mcm","clk":"11959616080","pt":1724582807598,"mc":[{"id":"1.232239000","rc":[{"batb":[[0,12.5,30.93],[1,3.2,2],[2,2.1,4.09]],"ltp":13.0,"tv":16.9,"id":60971786}]}]}
{"op":"mcm","clk":"11959617612","pt":1724582817209,"mc":[{"id":"1.232239000","rc":[{"batb":[[0,13,5],[1,12.5,30.93],[2,3.2,2]],"ltp":13.0,"tv":16.9,"id":60971786}]}]}
{"op":"mcm","clk":"11959618168","pt":1724582820507,"mc":[{"id":"1.232239000","rc":[{"batb":[[0,12.5,30.93],[1,3.2,2],[2,2.1,4.09]],"ltp":13.0,"tv":16.9,"id":60971786}]}]}
{"op":"mcm","clk":"11959618613","pt":1724582822821,"mc":[{"id":"1.232239000","rc":[{"batb":[[0,13,5],[1,12.5,30.93],[2,3.2,2]],"ltp":13.0,"tv":16.9,"id":60971786}]}]}
{"op":"mcm","clk":"11959619187","pt":1724582826034,"mc":[{"id":"1.232239000","rc":[{"batb":[[0,12.5,30.93],[1,3.2,2],[2,2.1,4.09]],"ltp":13.0,"tv":16.9,"id":60971786}]}]}
{"op":"mcm","clk":"11959619872","pt":1724582830025,"mc":[{"id":"1.232239000","rc":[{"batb":[[0,13,5],[1,12.5,30.93],[2,3.2,2]],"ltp":13.0,"tv":16.9,"id":60971786}]}]}
{"op":"mcm","clk":"11959620454","pt":1724582833226,"mc":[{"id":"1.232239000","rc":[{"batb":[[0,12.5,30.93],[1,3.2,2],[2,2.1,4.09]],"ltp":13.0,"tv":16.9,"id":60971786}]}]}
{"op":"mcm","clk":"11959623096","pt":1724582851232,"mc":[{"id":"1.232239000","rc":[{"batb":[[0,13,5],[1,12.5,30.93],[2,3.2,2]],"ltp":13.0,"tv":16.9,"id":60971786}]}]}
{"op":"mcm","clk":"11959623572","pt":1724582854471,"mc":[{"id":"1.232239000","rc":[{"batb":[[0,12.5,30.93],[1,3.2,2],[2,2.1,4.09]],"ltp":13.0,"tv":16.9,"id":60971786}]}]}
{"op":"mcm","clk":"11959624233","pt":1724582859066,"mc":[{"id":"1.232239000","rc":[{"batb":[[0,13,5],[1,12.5,30.93],[2,3.85,3.6]],"batl":[[0,110,2.06]],"ltp":13.0,"tv":16.9,"id":60971786}]}]}
{"op":"mcm","clk":"11959624704","pt":1724582862364,"mc":[{"id":"1.232239000","rc":[{"batb":[[0,12.5,30.93],[1,3.85,3.6],[2,3.2,2]],"ltp":13.0,"tv":16.9,"id":60971786}]}]}
{"op":"mcm","clk":"11959625696","pt":1724582868856,"mc":[{"id":"1.232239000","rc":[{"batb":[[0,13,5],[1,12.5,30.93],[2,3.85,3.6]],"ltp":13.0,"tv":16.9,"id":60971786}]}]}
{"op":"mcm","clk":"11959626171","pt":1724582872054,"mc":[{"id":"1.232239000","rc":[{"batb":[[0,12.5,30.93],[1,3.85,3.6],[2,3.2,2]],"ltp":13.0,"tv":16.9,"id":60971786}]}]}
{"op":"mcm","clk":"11959627663","pt":1724582882195,"mc":[{"id":"1.232239000","rc":[{"batb":[[0,13,5],[1,12.5,30.93],[2,3.85,3.6]],"ltp":13.0,"tv":16.9,"id":60971786}]}]}
{"op":"mcm","clk":"11959628202","pt":1724582885470,"mc":[{"id":"1.232239000","rc":[{"batb":[[0,12.5,30.93],[1,3.85,3.6],[2,3.2,2]],"ltp":13.0,"tv":16.9,"id":60971786}]}]}
{"op":"mcm","clk":"11959628662","pt":1724582888400,"mc":[{"id":"1.232239000","rc":[{"batb":[[0,13,5],[1,12.5,30.93],[2,3.85,3.6]],"ltp":13.0,"tv":16.9,"id":60971786}]}]}
{"op":"mcm","clk":"11959629168","pt":1724582891807,"mc":[{"id":"1.232239000","rc":[{"batb":[[0,12.5,30.93],[1,3.85,3.6],[2,3.2,2]],"ltp":13.0,"tv":16.9,"id":60971786}]}]}
{"op":"mcm","clk":"11959629538","pt":1724582894113,"mc":[{"id":"1.232239000","rc":[{"batb":[[0,13,5],[1,12.5,30.93],[2,3.85,3.6]],"ltp":13.0,"tv":16.9,"id":60971786}]}]}
{"op":"mcm","clk":"11959630067","pt":1724582897387,"mc":[{"id":"1.232239000","rc":[{"batb":[[0,12.5,30.93],[1,3.85,3.6],[2,3.2,2]],"ltp":13.0,"tv":16.9,"id":60971786}]}]}
{"op":"mcm","clk":"11959630598","pt":1724582900690,"mc":[{"id":"1.232239000","rc":[{"batb":[[0,13,5],[1,12.5,30.93],[2,3.85,3.6]],"ltp":13.0,"tv":16.9,"id":60971786}]}]}
{"op":"mcm","clk":"11959631031","pt":1724582904102,"mc":[{"id":"1.232239000","rc":[{"batb":[[0,12.5,30.93],[1,3.85,3.6],[2,3.2,2]],"ltp":13.0,"tv":16.9,"id":60971786}]}]}
{"op":"mcm","clk":"11959632206","pt":1724582912103,"mc":[{"id":"1.232239000","rc":[{"batb":[[0,13,5],[1,12.5,30.93],[2,3.85,3.6]],"ltp":13.0,"tv":16.9,"id":60971786}]}]}
{"op":"mcm","clk":"11959632703","pt":1724582915428,"mc":[{"id":"1.232239000","rc":[{"batb":[[0,12.5,30.93],[1,3.85,3.6],[2,3.2,2]],"ltp":13.0,"tv":16.9,"id":60971786}]}]}
{"op":"mcm","clk":"11959633103","pt":1724582918196,"mc":[{"id":"1.232239000","rc":[{"batb":[[0,13,5],[1,12.5,30.93],[2,3.85,3.6]],"ltp":13.0,"tv":16.9,"id":60971786}]}]}
{"op":"mcm","clk":"11959633607","pt":1724582921462,"mc":[{"id":"1.232239000","rc":[{"batb":[[0,12.5,30.93],[1,3.85,3.6],[2,3.2,2]],"ltp":13.0,"tv":16.9,"id":60971786}]}]}
{"op":"mcm","clk":"11959634371","pt":1724582926826,"mc":[{"id":"1.232239000","rc":[{"batb":[[0,13,5],[1,12.5,30.93],[2,3.85,3.6]],"ltp":13.0,"tv":16.9,"id":60971786}]}]}
{"op":"mcm","clk":"11959634834","pt":1724582930018,"mc":[{"id":"1.232239000","rc":[{"batb":[[0,12.5,30.93],[1,3.85,3.6],[2,3.2,2]],"ltp":13.0,"tv":16.9,"id":60971786}]}]}
{"op":"mcm","clk":"11959635332","pt":1724582933329,"mc":[{"id":"1.232239000","rc":[{"batb":[[0,13,5],[1,12.5,30.93],[2,3.85,3.6]],"ltp":13.0,"tv":16.9,"id":60971786}]}]}
{"op":"mcm","clk":"11959635798","pt":1724582936648,"mc":[{"id":"1.232239000","rc":[{"batb":[[0,12.5,30.93],[1,3.85,3.6],[2,3.2,2]],"ltp":13.0,"tv":16.9,"id":60971786}]}]}
{"op":"mcm","clk":"11959636212","pt":1724582939435,"mc":[{"id":"1.232239000","rc":[{"batb":[[0,13,5],[1,12.5,30.93],[2,3.85,3.6]],"ltp":13.0,"tv":16.9,"id":60971786}]}]}
{"op":"mcm","clk":"11959636655","pt":1724582942792,"mc":[{"id":"1.232239000","rc":[{"batb":[[0,12.5,30.93],[1,3.85,3.6],[2,3.2,2]],"ltp":13.0,"tv":16.9,"id":60971786}]}]}
{"op":"mcm","clk":"11959638691","pt":1724582955561,"mc":[{"id":"1.232239000","rc":[{"batb":[[0,13,5],[1,12.5,30.93],[2,3.85,3.6]],"ltp":13.0,"tv":16.9,"id":60971786}]}]}
{"op":"mcm","clk":"11959639184","pt":1724582958851,"mc":[{"id":"1.232239000","rc":[{"batb":[[0,12.5,30.93],[1,3.85,3.6],[2,3.2,2]],"ltp":13.0,"tv":16.9,"id":60971786}]}]}
{"op":"mcm","clk":"11959639546","pt":1724582961379,"mc":[{"id":"1.232239000","rc":[{"batb":[[0,13,5],[1,12.5,30.93],[2,3.85,3.6]],"ltp":13.0,"tv":16.9,"id":60971786}]}]}
{"op":"mcm","clk":"11959640005","pt":1724582964751,"mc":[{"id":"1.232239000","rc":[{"batb":[[0,12.5,30.93],[1,3.85,3.6],[2,3.2,2]],"ltp":13.0,"tv":16.9,"id":60971786}]}]}
{"op":"mcm","clk":"11959641567","pt":1724582975989,"mc":[{"id":"1.232239000","rc":[{"batb":[[0,13,5],[1,12.5,30.93],[2,3.85,3.6]],"ltp":13.0,"tv":16.9,"id":60971786}]}]}
{"op":"mcm","clk":"11959642055","pt":1724582979489,"mc":[{"id":"1.232239000","rc":[{"batb":[[0,12.5,30.93],[1,3.85,3.6],[2,3.2,2]],"ltp":13.0,"tv":16.9,"id":60971786}]}]}
{"op":"mcm","clk":"11959643156","pt":1724582987180,"mc":[{"id":"1.232239000","rc":[{"batb":[[0,13,5],[1,12.5,30.93],[2,3.85,3.6]],"ltp":13.0,"tv":16.9,"id":60971786}]}]}
{"op":"mcm","clk":"11959643593","pt":1724582990514,"mc":[{"id":"1.232239000","rc":[{"batb":[[0,12.5,30.93],[1,3.85,3.6],[2,3.2,2]],"ltp":13.0,"tv":16.9,"id":60971786}]}]}
{"op":"mcm","clk":"11959643980","pt":1724582993389,"mc":[{"id":"1.232239000","rc":[{"batb":[[0,13,5],[1,12.5,30.93],[2,3.85,3.6]],"ltp":13.0,"tv":16.9,"id":60971786}]}]}
{"op":"mcm","clk":"11959644396","pt":1724582996724,"mc":[{"id":"1.232239000","rc":[{"batb":[[0,12.5,30.93],[1,3.85,3.6],[2,3.2,2]],"ltp":13.0,"tv":16.9,"id":60971786}]}]}
{"op":"mcm","clk":"11959645744","pt":1724583005503,"mc":[{"id":"1.232239000","rc":[{"batb":[[0,13,5],[1,12.5,30.93],[2,3.85,3.6]],"ltp":13.0,"tv":16.9,"id":60971786}]}]}
{"op":"mcm","clk":"11959646228","pt":1724583008800,"mc":[{"id":"1.232239000","rc":[{"batb":[[0,12.5,30.93],[1,3.85,3.6],[2,3.2,2]],"ltp":13.0,"tv":16.9,"id":60971786}]}]}
{"op":"mcm","clk":"11959646603","pt":1724583011341,"mc":[{"id":"1.232239000","rc":[{"batb":[[0,13,5],[1,12.5,30.93],[2,3.85,3.6]],"ltp":13.0,"tv":16.9,"id":60971786}]}]}
{"op":"mcm","clk":"11959647101","pt":1724583014732,"mc":[{"id":"1.232239000","rc":[{"batb":[[0,12.5,30.93],[1,3.85,3.6],[2,3.2,2]],"ltp":13.0,"tv":16.9,"id":60971786}]}]}
{"op":"mcm","clk":"11959648669","pt":1724583025240,"mc":[{"id":"1.232239000","rc":[{"batb":[[0,13,5],[1,12.5,30.93],[2,3.85,3.6]],"ltp":13.0,"tv":16.9,"id":60971786}]}]}
{"op":"mcm","clk":"11959649168","pt":1724583028425,"mc":[{"id":"1.232239000","rc":[{"batb":[[0,12.5,30.93],[1,3.85,3.6],[2,3.2,2]],"ltp":13.0,"tv":16.9,"id":60971786}]}]}
{"op":"mcm","clk":"11959649780","pt":1724583032750,"mc":[{"id":"1.232239000","rc":[{"batb":[[0,13,5],[1,12.5,30.93],[2,3.85,3.6]],"ltp":13.0,"tv":16.9,"id":60971786}]}]}
{"op":"mcm","clk":"11959650242","pt":1724583035959,"mc":[{"id":"1.232239000","rc":[{"batb":[[0,12.5,30.93],[1,3.85,3.6],[2,3.2,2]],"ltp":13.0,"tv":16.9,"id":60971786}]}]}
{"op":"mcm","clk":"11959651402","pt":1724583043459,"mc":[{"id":"1.232239000","rc":[{"batb":[[0,1.07,41.89],[1,1.06,16.76],[2,1.04,252.57]],"ltp":1.05,"tv":1569.98,"id":24640635}]}]}
{"op":"mcm","clk":"11959651431","pt":1724583043660,"mc":[{"id":"1.232239000","rc":[{"batb":[[0,13,5],[1,12.5,30.93],[2,3.85,3.6]],"ltp":13.0,"tv":16.9,"id":60971786}]}]}
{"op":"mcm","clk":"11959651920","pt":1724583046962,"mc":[{"id":"1.232239000","rc":[{"batb":[[0,12.5,30.93],[1,3.85,3.6],[2,3.2,2]],"ltp":13.0,"tv":16.9,"id":60971786}]}]}
{"op":"mcm","clk":"11959652466","pt":1724583050773,"mc":[{"id":"1.232239000","rc":[{"batb":[[0,13,5],[1,12.5,30.93],[2,3.85,3.6]],"ltp":13.0,"tv":16.9,"id":60971786}]}]}
{"op":"mcm","clk":"11959652959","pt":1724583053974,"mc":[{"id":"1.232239000","rc":[{"batb":[[0,12.5,30.93],[1,3.85,3.6],[2,3.2,2]],"ltp":13.0,"tv":16.9,"id":60971786}]}]}
{"op":"mcm","clk":"11959653717","pt":1724583058992,"mc":[{"id":"1.232239000","rc":[{"batb":[[0,13,5],[1,12.5,30.93],[2,3.85,3.6]],"ltp":13.0,"tv":16.9,"id":60971786}]}]}
{"op":"mcm","clk":"11959654193","pt":1724583062299,"mc":[{"id":"1.232239000","rc":[{"batb":[[0,12.5,30.93],[1,3.85,3.6],[2,3.2,2]],"ltp":13.0,"tv":16.9,"id":60971786}]}]}
{"op":"mcm","clk":"11959654800","pt":1724583066003,"mc":[{"id":"1.232239000","rc":[{"batb":[[0,13,5],[1,12.5,30.93],[2,3.85,3.6]],"ltp":13.0,"tv":16.9,"id":60971786}]}]}
{"op":"mcm","clk":"11959655339","pt":1724583069432,"mc":[{"id":"1.232239000","rc":[{"batb":[[0,12.5,30.93],[1,3.85,3.6],[2,3.2,2]],"ltp":13.0,"tv":16.9,"id":60971786}]}]}
{"op":"mcm","clk":"11959656213","pt":1724583075128,"mc":[{"id":"1.232239000","rc":[{"batb":[[0,13,5],[1,12.5,30.93],[2,3.85,3.6]],"ltp":13.0,"tv":16.9,"id":60971786}]}]}
{"op":"mcm","clk":"11959656702","pt":1724583078439,"mc":[{"id":"1.232239000","rc":[{"batb":[[0,12.5,30.93],[1,3.85,3.6],[2,3.2,2]],"ltp":13.0,"tv":16.9,"id":60971786}]}]}
{"op":"mcm","clk":"11959657698","pt":1724583085345,"mc":[{"id":"1.232239000","rc":[{"batb":[[0,13,5],[1,12.5,30.93],[2,3.85,3.6]],"ltp":13.0,"tv":16.9,"id":60971786}]}]}
{"op":"mcm","clk":"11959658178","pt":1724583088424,"mc":[{"id":"1.232239000","rc":[{"batb":[[0,12.5,30.93],[1,3.85,3.6],[2,3.2,2]],"ltp":13.0,"tv":16.9,"id":60971786}]}]}
{"op":"mcm","clk":"11959659126","pt":1724583094920,"mc":[{"id":"1.232239000","rc":[{"batb":[[0,13,5],[1,12.5,30.93],[2,3.85,3.6]],"ltp":13.0,"tv":16.9,"id":60971786}]}]}
{"op":"mcm","clk":"11959659642","pt":1724583098235,"mc":[{"id":"1.232239000","rc":[{"batb":[[0,12.5,30.93],[1,3.85,3.6],[2,3.2,2]],"ltp":13.0,"tv":16.9,"id":60971786}]}]}
{"op":"mcm","clk":"11959660463","pt":1724583103764,"mc":[{"id":"1.232239000","rc":[{"batb":[[0,13,5],[1,12.5,30.93],[2,3.85,3.6]],"ltp":13.0,"tv":16.9,"id":60971786}]}]}
{"op":"mcm","clk":"11959660909","pt":1724583107069,"mc":[{"id":"1.232239000","rc":[{"batb":[[0,12.5,30.93],[1,3.85,3.6],[2,3.2,2]],"ltp":13.0,"tv":16.9,"id":60971786}]}]}
{"op":"mcm","clk":"11959661421","pt":1724583110576,"mc":[{"id":"1.232239000","rc":[{"batb":[[0,13,5],[1,12.5,30.93],[2,3.85,3.6]],"ltp":13.0,"tv":16.9,"id":60971786}]}]}
{"op":"mcm","clk":"11959661908","pt":1724583113850,"mc":[{"id":"1.232239000","rc":[{"batb":[[0,12.5,30.93],[1,3.85,3.6],[2,3.2,2]],"ltp":13.0,"tv":16.9,"id":60971786}]}]}
{"op":"mcm","clk":"11959662820","pt":1724583120083,"mc":[{"id":"1.232239000","rc":[{"batb":[[0,13,5],[1,12.5,30.93],[2,3.85,3.6]],"ltp":13.0,"tv":16.9,"id":60971786}]}]}
{"op":"mcm","clk":"11959663361","pt":1724583123389,"mc":[{"id":"1.232239000","rc":[{"batb":[[0,12.5,30.93],[1,3.85,3.6],[2,3.2,2]],"ltp":13.0,"tv":16.9,"id":60971786}]}]}
{"op":"mcm","clk":"11959664427","pt":1724583129496,"mc":[{"id":"1.232239000","rc":[{"batb":[[0,13,5],[1,12.5,30.93],[2,3.85,3.6]],"ltp":13.0,"tv":16.9,"id":60971786}]}]}
{"op":"mcm","clk":"11959664981","pt":1724583132780,"mc":[{"id":"1.232239000","rc":[{"batb":[[0,12.5,30.93],[1,3.85,3.6],[2,3.2,2]],"ltp":13.0,"tv":16.9,"id":60971786}]}]}
{"op":"mcm","clk":"11959665395","pt":1724583135655,"mc":[{"id":"1.232239000","rc":[{"batb":[[0,13,5],[1,12.5,30.93],[2,3.85,3.6]],"ltp":13.0,"tv":16.9,"id":60971786}]}]}
{"op":"mcm","clk":"11959665902","pt":1724583139156,"mc":[{"id":"1.232239000","rc":[{"batb":[[0,12.5,30.93],[1,3.85,3.6],[2,3.2,2]],"ltp":13.0,"tv":16.9,"id":60971786}]}]}
{"op":"mcm","clk":"11959666317","pt":1724583142280,"mc":[{"id":"1.232239000","rc":[{"batb":[[0,13,5],[1,12.5,30.93],[2,3.85,3.6]],"ltp":13.0,"tv":16.9,"id":60971786}]}]}
{"op":"mcm","clk":"11959666804","pt":1724583145484,"mc":[{"id":"1.232239000","rc":[{"batb":[[0,12.5,30.93],[1,3.85,3.6],[2,3.2,2]],"ltp":13.0,"tv":16.9,"id":60971786}]}]}
{"op":"mcm","clk":"11959667264","pt":1724583148818,"mc":[{"id":"1.232239000","rc":[{"batb":[[0,13,5],[1,12.5,30.93],[2,3.85,3.6]],"ltp":13.0,"tv":16.9,"id":60971786}]}]}
{"op":"mcm","clk":"11959667744","pt":1724583152192,"mc":[{"id":"1.232239000","rc":[{"batb":[[0,12.5,30.93],[1,3.85,3.6],[2,3.2,2]],"ltp":13.0,"tv":16.9,"id":60971786}]}]}
{"op":"mcm","clk":"11959669008","pt":1724583161598,"mc":[{"id":"1.232239000","rc":[{"batb":[[0,13,5],[1,12.5,30.93],[2,3.85,3.6]],"ltp":13.0,"tv":16.9,"id":60971786}]}]}
{"op":"mcm","clk":"11959669452","pt":1724583165020,"mc":[{"id":"1.232239000","rc":[{"batb":[[0,12.5,30.93],[1,3.85,3.6],[2,3.2,2]],"ltp":13.0,"tv":16.9,"id":60971786}]}]}
{"op":"mcm","clk":"11959670219","pt":1724583170010,"mc":[{"id":"1.232239000","rc":[{"batb":[[0,13,5],[1,12.5,30.93],[2,3.85,3.6]],"ltp":13.0,"tv":16.9,"id":60971786}]}]}
{"op":"mcm","clk":"11959670699","pt":1724583173336,"mc":[{"id":"1.232239000","rc":[{"batb":[[0,12.5,30.93],[1,3.85,3.6],[2,3.2,2]],"ltp":13.0,"tv":16.9,"id":60971786}]}]}
{"op":"mcm","clk":"11959671032","pt":1724583175830,"mc":[{"id":"1.232239000","rc":[{"batb":[[0,13,5],[1,12.5,30.93],[2,3.85,3.6]],"ltp":13.0,"tv":16.9,"id":60971786}]}]}
{"op":"mcm","clk":"11959671438","pt":1724583179135,"mc":[{"id":"1.232239000","rc":[{"batb":[[0,12.5,30.93],[1,3.85,3.6],[2,3.2,2]],"ltp":13.0,"tv":16.9,"id":60971786}]}]}
{"op":"mcm","clk":"11959671739","pt":1724583181632,"mc":[{"id":"1.232239000","rc":[{"batb":[[0,13,5],[1,12.5,30.93],[2,3.85,3.6]],"ltp":13.0,"tv":16.9,"id":60971786}]}]}
{"op":"mcm","clk":"11959672209","pt":1724583185010,"mc":[{"id":"1.232239000","rc":[{"batb":[[0,12.5,30.93],[1,3.85,3.6],[2,3.2,2]],"ltp":13.0,"tv":16.9,"id":60971786}]}]}
{"op":"mcm","clk":"11959672528","pt":1724583187246,"mc":[{"id":"1.232239000","rc":[{"batb":[[0,13,5],[1,12.5,30.93],[2,3.85,3.6]],"ltp":13.0,"tv":16.9,"id":60971786}]}]}
{"op":"mcm","clk":"11959672997","pt":1724583190609,"mc":[{"id":"1.232239000","rc":[{"batb":[[0,12.5,30.93],[1,3.85,3.6],[2,3.2,2]],"ltp":13.0,"tv":16.9,"id":60971786}]}]}
{"op":"mcm","clk":"11959673904","pt":1724583197032,"mc":[{"id":"1.232239000","rc":[{"batb":[[0,13,5],[1,12.5,30.93],[2,3.85,3.6]],"ltp":13.0,"tv":16.9,"id":60971786}]}]}
{"op":"mcm","clk":"11959674377","pt":1724583200255,"mc":[{"id":"1.232239000","rc":[{"batb":[[0,12.5,30.93],[1,3.85,3.6],[2,3.2,2]],"ltp":13.0,"tv":16.9,"id":60971786}]}]}
{"op":"mcm","clk":"11959674991","pt":1724583204971,"mc":[{"id":"1.232239000","rc":[{"batb":[[0,13,5],[1,12.5,30.93],[2,3.85,3.6]],"ltp":13.0,"tv":16.9,"id":60971786}]}]}
{"op":"mcm","clk":"11959675481","pt":1724583208357,"mc":[{"id":"1.232239000","rc":[{"batb":[[0,12.5,30.93],[1,3.85,3.6],[2,3.2,2]],"ltp":13.0,"tv":16.9,"id":60971786}]}]}
{"op":"mcm","clk":"11959676300","pt":1724583214371,"mc":[{"id":"1.232239000","rc":[{"batb":[[0,13,5],[1,12.5,30.93],[2,3.85,3.6]],"ltp":13.0,"tv":16.9,"id":60971786}]}]}
{"op":"mcm","clk":"11959676793","pt":1724583217608,"mc":[{"id":"1.232239000","rc":[{"batb":[[0,12.5,30.93],[1,3.85,3.6],[2,3.2,2]],"ltp":13.0,"tv":16.9,"id":60971786}]}]}
{"op":"mcm","clk":"11959678436","pt":1724583229521,"mc":[{"id":"1.232239000","rc":[{"batb":[[0,13,5],[1,12.5,30.93],[2,3.85,3.6]],"ltp":13.0,"tv":16.9,"id":60971786}]}]}
{"op":"mcm","clk":"11959678893","pt":1724583232830,"mc":[{"id":"1.232239000","rc":[{"batb":[[0,12.5,30.93],[1,3.85,3.6],[2,3.2,2]],"ltp":13.0,"tv":16.9,"id":60971786}]}]}
{"op":"mcm","clk":"11959679356","pt":1724583236117,"mc":[{"id":"1.232239000","rc":[{"batb":[[0,13,5],[1,12.5,30.93],[2,3.85,3.6]],"ltp":13.0,"tv":16.9,"id":60971786}]}]}
{"op":"mcm","clk":"11959679836","pt":1724583239538,"mc":[{"id":"1.232239000","rc":[{"batb":[[0,12.5,30.93],[1,3.85,3.6],[2,3.2,2]],"ltp":13.0,"tv":16.9,"id":60971786}]}]}
{"op":"mcm","clk":"11959680529","pt":1724583244440,"mc":[{"id":"1.232239000","rc":[{"batb":[[0,13,5],[1,12.5,30.93],[2,3.85,3.6]],"ltp":13.0,"tv":16.9,"id":60971786}]}]}
{"op":"mcm","clk":"11959680981","pt":1724583247735,"mc":[{"id":"1.232239000","rc":[{"batb":[[0,12.5,30.93],[1,3.85,3.6],[2,3.2,2]],"ltp":13.0,"tv":16.9,"id":60971786}]}]}
{"op":"mcm","clk":"11959681882","pt":1724583254556,"mc":[{"id":"1.232239000","rc":[{"batb":[[0,13,5],[1,12.5,30.93],[2,3.85,3.6]],"ltp":13.0,"tv":16.9,"id":60971786}]}]}
{"op":"mcm","clk":"11959682327","pt":1724583257933,"mc":[{"id":"1.232239000","rc":[{"batb":[[0,12.5,30.93],[1,3.85,3.6],[2,3.2,2]],"ltp":13.0,"tv":16.9,"id":60971786}]}]}
{"op":"mcm","clk":"11959682721","pt":1724583260629,"mc":[{"id":"1.232239000","rc":[{"batb":[[0,13,5],[1,12.5,30.93],[2,3.85,3.6]],"ltp":13.0,"tv":16.9,"id":60971786}]}]}
{"op":"mcm","clk":"11959683262","pt":1724583264054,"mc":[{"id":"1.232239000","rc":[{"batb":[[0,12.5,30.93],[1,3.85,3.6],[2,3.2,2]],"ltp":13.0,"tv":16.9,"id":60971786}]}]}
{"op":"mcm","clk":"11959683976","pt":1724583269178,"mc":[{"id":"1.232239000","rc":[{"batb":[[0,13,5],[1,12.5,30.93],[2,3.85,3.6]],"ltp":13.0,"tv":16.9,"id":60971786}]}]}
{"op":"mcm","clk":"11959684418","pt":1724583272381,"mc":[{"id":"1.232239000","rc":[{"batb":[[0,12.5,30.93],[1,3.85,3.6],[2,3.2,2]],"ltp":13.0,"tv":16.9,"id":60971786}]}]}
{"op":"mcm","clk":"11959684952","pt":1724583276186,"mc":[{"id":"1.232239000","rc":[{"batb":[[0,13,5],[1,12.5,30.93],[2,3.85,3.6]],"ltp":13.0,"tv":16.9,"id":60971786}]}]}
{"op":"mcm","clk":"11959685399","pt":1724583279563,"mc":[{"id":"1.232239000","rc":[{"batb":[[0,12.5,30.93],[1,3.85,3.6],[2,3.2,2]],"ltp":13.0,"tv":16.9,"id":60971786}]}]}
{"op":"mcm","clk":"11959685772","pt":1724583282368,"mc":[{"id":"1.232239000","rc":[{"batb":[[0,13,5],[1,12.5,30.93],[2,3.85,3.6]],"ltp":13.0,"tv":16.9,"id":60971786}]}]}
{"op":"mcm","clk":"11959686255","pt":1724583285685,"mc":[{"id":"1.232239000","rc":[{"batb":[[0,12.5,30.93],[1,3.85,3.6],[2,3.2,2]],"ltp":13.0,"tv":16.9,"id":60971786}]}]}
{"op":"mcm","clk":"11959686745","pt":1724583289175,"mc":[{"id":"1.232239000","rc":[{"batb":[[0,13,5],[1,12.5,30.93],[2,3.85,3.6]],"ltp":13.0,"tv":16.9,"id":60971786}]}]}
{"op":"mcm","clk":"11959687238","pt":1724583292562,"mc":[{"id":"1.232239000","rc":[{"batb":[[0,12.5,30.93],[1,3.85,3.6],[2,3.2,2]],"ltp":13.0,"tv":16.9,"id":60971786}]}]}
{"op":"mcm","clk":"11959688494","pt":1724583301286,"mc":[{"id":"1.232239000","rc":[{"batb":[[0,13,5],[1,12.5,30.93],[2,3.85,3.6]],"ltp":13.0,"tv":16.9,"id":60971786}]}]}
{"op":"mcm","clk":"11959689087","pt":1724583304585,"mc":[{"id":"1.232239000","rc":[{"batb":[[0,12.5,30.93],[1,3.85,3.6],[2,3.2,2]],"ltp":13.0,"tv":16.9,"id":60971786}]}]}
{"op":"mcm","clk":"11959690505","pt":1724583313097,"mc":[{"id":"1.232239000","rc":[{"batb":[[0,13,5],[1,12.5,30.93],[2,3.85,3.6]],"ltp":13.0,"tv":16.9,"id":60971786}]}]}
{"op":"mcm","clk":"11959691066","pt":1724583316492,"mc":[{"id":"1.232239000","rc":[{"batb":[[0,12.5,30.93],[1,3.85,3.6],[2,3.2,2]],"ltp":13.0,"tv":16.9,"id":60971786}]}]}
{"op":"mcm","clk":"11959691751","pt":1724583320203,"mc":[{"id":"1.232239000","rc":[{"batb":[[0,13,5],[1,12.5,30.93],[2,3.85,3.6]],"ltp":13.0,"tv":16.9,"id":60971786}]}]}
{"op":"mcm","clk":"11959692234","pt":1724583323531,"mc":[{"id":"1.232239000","rc":[{"batb":[[0,12.5,30.93],[1,3.85,3.6],[2,3.2,2]],"ltp":13.0,"tv":16.9,"id":60971786}]}]}
{"op":"mcm","clk":"11959693654","pt":1724583332141,"mc":[{"id":"1.232239000","rc":[{"batb":[[0,13,5],[1,12.5,30.93],[2,3.85,3.6]],"ltp":13.0,"tv":16.9,"id":60971786}]}]}
{"op":"mcm","clk":"11959694139","pt":1724583335514,"mc":[{"id":"1.232239000","rc":[{"batb":[[0,12.5,30.93],[1,3.85,3.6],[2,3.2,2]],"ltp":13.0,"tv":16.9,"id":60971786}]}]}
{"op":"mcm","clk":"11959694673","pt":1724583338795,"mc":[{"id":"1.232239000","rc":[{"batb":[[0,13,5],[1,12.5,30.93],[2,3.85,3.6]],"ltp":13.0,"tv":16.9,"id":60971786}]}]}
{"op":"mcm","clk":"11959695178","pt":1724583342021,"mc":[{"id":"1.232239000","rc":[{"batb":[[0,12.5,30.93],[1,3.85,3.6],[2,3.2,2]],"ltp":13.0,"tv":16.9,"id":60971786}]}]}
{"op":"mcm","clk":"11959695904","pt":1724583347114,"mc":[{"id":"1.232239000","rc":[{"batb":[[0,13,5],[1,12.5,30.93],[2,3.85,3.6]],"ltp":13.0,"tv":16.9,"id":60971786}]}]}
{"op":"mcm","clk":"11959696348","pt":1724583350326,"mc":[{"id":"1.232239000","rc":[{"batb":[[0,12.5,30.93],[1,3.85,3.6],[2,3.2,2]],"ltp":13.0,"tv":16.9,"id":60971786}]}]}
{"op":"mcm","clk":"11959696932","pt":1724583354312,"mc":[{"id":"1.232239000","rc":[{"batb":[[0,13,5],[1,12.5,30.93],[2,3.85,3.6]],"ltp":13.0,"tv":16.9,"id":60971786}]}]}
{"op":"mcm","clk":"11959697435","pt":1724583357545,"mc":[{"id":"1.232239000","rc":[{"batb":[[0,12.5,30.93],[1,3.85,3.6],[2,3.2,2]],"ltp":13.0,"tv":16.9,"id":60971786}]}]}
{"op":"mcm","clk":"11959698210","pt":1724583362834,"mc":[{"id":"1.232239000","rc":[{"batb":[[0,13,5],[1,12.5,30.93],[2,3.85,3.6]],"ltp":13.0,"tv":16.9,"id":60971786}]}]}
{"op":"mcm","clk":"11959698699","pt":1724583366255,"mc":[{"id":"1.232239000","rc":[{"batb":[[0,12.5,30.93],[1,3.85,3.6],[2,3.2,2]],"ltp":13.0,"tv":16.9,"id":60971786}]}]}
{"op":"mcm","clk":"11959699684","pt":1724583372949,"mc":[{"id":"1.232239000","rc":[{"batb":[[0,13,5],[1,12.5,30.93],[2,3.85,3.6]],"ltp":13.0,"tv":16.9,"id":60971786}]}]}
{"op":"mcm","clk":"11959700163","pt":1724583376269,"mc":[{"id":"1.232239000","rc":[{"batb":[[0,12.5,30.93],[1,3.85,3.6],[2,3.2,2]],"ltp":13.0,"tv":16.9,"id":60971786}]}]}
{"op":"mcm","clk":"11959700599","pt":1724583379138,"mc":[{"id":"1.232239000","rc":[{"batb":[[0,13,5],[1,12.5,30.93],[2,3.85,3.6]],"ltp":13.0,"tv":16.9,"id":60971786}]}]}
{"op":"mcm","clk":"11959700930","pt":1724583381472,"mc":[{"id":"1.232239000","rc":[{"batb":[[1,12.5,5]],"ltp":13.0,"tv":16.9,"id":60971786}]}]}
{"op":"mcm","clk":"11959701071","pt":1724583382452,"mc":[{"id":"1.232239000","rc":[{"trd":[[13,9.28]],"batb":[[0,12.5,5],[1,3.85,3.6],[2,3.2,2]],"ltp":13.0,"tv":24.42,"id":60971786}],"tv":1594.41}]}
{"op":"mcm","clk":"11959702260","pt":1724583390265,"mc":[{"id":"1.232239000","rc":[{"batb":[[0,13,5],[1,12.5,5],[2,3.85,3.6]],"ltp":13.0,"tv":24.42,"id":60971786}]}]}
{"op":"mcm","clk":"11959702742","pt":1724583393586,"mc":[{"id":"1.232239000","rc":[{"batb":[[0,12.5,5],[1,3.85,3.6],[2,3.2,2]],"ltp":13.0,"tv":24.42,"id":60971786}]}]}
{"op":"mcm","clk":"11959703322","pt":1724583398365,"mc":[{"id":"1.232239000","rc":[{"batb":[[0,13,5],[1,12.5,5],[2,3.85,3.6]],"ltp":13.0,"tv":24.42,"id":60971786}]}]}
{"op":"mcm","clk":"11959703759","pt":1724583401571,"mc":[{"id":"1.232239000","rc":[{"batb":[[0,12.5,5],[1,3.85,3.6],[2,3.2,2]],"ltp":13.0,"tv":24.42,"id":60971786}]}]}
{"op":"mcm","clk":"11959704135","pt":1724583404478,"mc":[{"id":"1.232239000","rc":[{"batb":[[0,13,5],[1,12.5,5],[2,3.85,3.6]],"ltp":13.0,"tv":24.42,"id":60971786}]}]}
{"op":"mcm","clk":"11959704550","pt":1724583407782,"mc":[{"id":"1.232239000","rc":[{"batb":[[0,12.5,5],[1,3.85,3.6],[2,3.2,2]],"ltp":13.0,"tv":24.42,"id":60971786}]}]}
{"op":"mcm","clk":"11959705896","pt":1724583418313,"mc":[{"id":"1.232239000","rc":[{"batb":[[0,13,5],[1,12.5,5],[2,3.85,3.6]],"ltp":13.0,"tv":24.42,"id":60971786}]}]}
{"op":"mcm","clk":"11959706339","pt":1724583421528,"mc":[{"id":"1.232239000","rc":[{"batb":[[0,12.5,5],[1,3.85,3.6],[2,3.2,2]],"ltp":13.0,"tv":24.42,"id":60971786}]}]}
{"op":"mcm","clk":"11959706775","pt":1724583424511,"mc":[{"id":"1.232239000","rc":[{"batb":[[0,13,5],[1,12.5,5],[2,3.85,3.6]],"ltp":13.0,"tv":24.42,"id":60971786}]}]}
{"op":"mcm","clk":"11959707237","pt":1724583427840,"mc":[{"id":"1.232239000","rc":[{"batb":[[0,12.5,5],[1,3.85,3.6],[2,3.2,2]],"ltp":13.0,"tv":24.42,"id":60971786}]}]}
{"op":"mcm","clk":"11959707756","pt":1724583431722,"mc":[{"id":"1.232239000","rc":[{"batb":[[0,13,5],[1,12.5,5],[2,3.85,3.6]],"ltp":13.0,"tv":24.42,"id":60971786}]}]}
{"op":"mcm","clk":"11959708159","pt":1724583435032,"mc":[{"id":"1.232239000","rc":[{"batb":[[0,12.5,5],[1,3.85,3.6],[2,3.2,2]],"ltp":13.0,"tv":24.42,"id":60971786}]}]}
{"op":"mcm","clk":"11959708571","pt":1724583437944,"mc":[{"id":"1.232239000","rc":[{"batb":[[0,13,5],[1,12.5,5],[2,3.85,3.6]],"ltp":13.0,"tv":24.42,"id":60971786}]}]}
{"op":"mcm","clk":"11959709045","pt":1724583441235,"mc":[{"id":"1.232239000","rc":[{"batb":[[0,12.5,5],[1,3.85,3.6],[2,3.2,2]],"ltp":13.0,"tv":24.42,"id":60971786}]}]}
{"op":"mcm","clk":"11959710246","pt":1724583449658,"mc":[{"id":"1.232239000","rc":[{"batb":[[0,13,5],[1,12.5,5],[2,3.85,3.6]],"ltp":13.0,"tv":24.42,"id":60971786}]}]}
{"op":"mcm","clk":"11959710728","pt":1724583452956,"mc":[{"id":"1.232239000","rc":[{"batb":[[0,12.5,5],[1,3.85,3.6],[2,3.2,2]],"ltp":13.0,"tv":24.42,"id":60971786}]}]}
{"op":"mcm","clk":"11959711112","pt":1724583455770,"mc":[{"id":"1.232239000","rc":[{"batb":[[0,13,5],[1,12.5,5],[2,3.85,3.6]],"ltp":13.0,"tv":24.42,"id":60971786}]}]}
{"op":"mcm","clk":"11959711584","pt":1724583459048,"mc":[{"id":"1.232239000","rc":[{"batb":[[0,12.5,5],[1,3.85,3.6],[2,3.2,2]],"ltp":13.0,"tv":24.42,"id":60971786}]}]}
{"op":"mcm","clk":"11959713429","pt":1724583472167,"mc":[{"id":"1.232239000","rc":[{"batb":[[0,13,5],[1,12.5,5],[2,3.85,3.6]],"ltp":13.0,"tv":24.42,"id":60971786}]}]}
{"op":"mcm","clk":"11959713945","pt":1724583475449,"mc":[{"id":"1.232239000","rc":[{"batb":[[0,12.5,5],[1,3.85,3.6],[2,3.2,2]],"ltp":13.0,"tv":24.42,"id":60971786}]}]}
{"op":"mcm","clk":"11959714624","pt":1724583480758,"mc":[{"id":"1.232239000","rc":[{"batb":[[0,13,5],[1,12.5,5],[2,3.85,3.6]],"ltp":13.0,"tv":24.42,"id":60971786}]}]}
{"op":"mcm","clk":"11959715073","pt":1724583483995,"mc":[{"id":"1.232239000","rc":[{"batb":[[0,12.5,5],[1,3.85,3.6],[2,3.2,2]],"ltp":13.0,"tv":24.42,"id":60971786}]}]}
{"op":"mcm","clk":"11959715633","pt":1724583488303,"mc":[{"id":"1.232239000","rc":[{"batb":[[0,13,5],[1,12.5,5],[2,3.85,3.6]],"ltp":13.0,"tv":24.42,"id":60971786}]}]}
{"op":"mcm","clk":"11959716086","pt":1724583491498,"mc":[{"id":"1.232239000","rc":[{"batb":[[0,12.5,5],[1,3.85,3.6],[2,3.2,2]],"ltp":13.0,"tv":24.42,"id":60971786}]}]}
{"op":"mcm","clk":"11959718827","pt":1724583510106,"mc":[{"id":"1.232239000","rc":[{"batb":[[0,13,5],[1,12.5,5],[2,3.85,3.6]],"ltp":13.0,"tv":24.42,"id":60971786}]}]}
{"op":"mcm","clk":"11959719238","pt":1724583513400,"mc":[{"id":"1.232239000","rc":[{"batb":[[0,12.5,5],[1,3.85,3.6],[2,3.2,2]],"ltp":13.0,"tv":24.42,"id":60971786}]}]}
{"op":"mcm","clk":"11959719562","pt":1724583515822,"mc":[{"id":"1.232239000","rc":[{"batb":[[0,13,5],[1,12.5,5],[2,3.85,3.6]],"ltp":13.0,"tv":24.42,"id":60971786}]}]}
{"op":"mcm","clk":"11959719999","pt":1724583519038,"mc":[{"id":"1.232239000","rc":[{"batb":[[0,12.5,5],[1,3.85,3.6],[2,3.2,2]],"ltp":13.0,"tv":24.42,"id":60971786}]}]}
{"op":"mcm","clk":"11959720784","pt":1724583524441,"mc":[{"id":"1.232239000","rc":[{"batb":[[0,13,5],[1,12.5,5],[2,3.85,3.6]],"ltp":13.0,"tv":24.42,"id":60971786}]}]}
{"op":"mcm","clk":"11959721289","pt":1724583527827,"mc":[{"id":"1.232239000","rc":[{"batb":[[0,12.5,5],[1,3.85,3.6],[2,3.2,2]],"ltp":13.0,"tv":24.42,"id":60971786}]}]}
{"op":"mcm","clk":"11959722837","pt":1724583539035,"mc":[{"id":"1.232239000","rc":[{"batb":[[0,13,5],[1,12.5,5],[2,3.85,3.6]],"ltp":13.0,"tv":24.42,"id":60971786}]}]}
{"op":"mcm","clk":"11959723382","pt":1724583542440,"mc":[{"id":"1.232239000","rc":[{"batb":[[0,12.5,5],[1,3.85,3.6],[2,3.2,2]],"ltp":13.0,"tv":24.42,"id":60971786}]}]}
{"op":"mcm","clk":"11959724987","pt":1724583552157,"mc":[{"id":"1.232239000","rc":[{"batb":[[0,13,5],[1,12.5,5],[2,3.85,3.6]],"ltp":13.0,"tv":24.42,"id":60971786}]}]}
{"op":"mcm","clk":"11959725496","pt":1724583555547,"mc":[{"id":"1.232239000","rc":[{"batb":[[0,12.5,5],[1,3.85,3.6],[2,3.2,2]],"ltp":13.0,"tv":24.42,"id":60971786}]}]}
{"op":"mcm","clk":"11959726272","pt":1724583560548,"mc":[{"id":"1.232239000","rc":[{"batb":[[0,13,5],[1,12.5,5],[2,3.85,3.6]],"ltp":13.0,"tv":24.42,"id":60971786}]}]}
{"op":"mcm","clk":"11959726790","pt":1724583563868,"mc":[{"id":"1.232239000","rc":[{"batb":[[0,12.5,5],[1,3.85,3.6],[2,3.2,2]],"ltp":13.0,"tv":24.42,"id":60971786}]}]}
{"op":"mcm","clk":"11959728435","pt":1724583575475,"mc":[{"id":"1.232239000","rc":[{"batb":[[0,13,5],[1,12.5,5],[2,3.85,3.6]],"ltp":13.0,"tv":24.42,"id":60971786}]}]}
{"op":"mcm","clk":"11959728958","pt":1724583578803,"mc":[{"id":"1.232239000","rc":[{"batb":[[0,12.5,5],[1,3.85,3.6],[2,3.2,2]],"ltp":13.0,"tv":24.42,"id":60971786}]}]}
{"op":"mcm","clk":"11959729327","pt":1724583581098,"mc":[{"id":"1.232239000","rc":[{"batb":[[0,13,5],[1,12.5,5],[2,3.85,3.6]],"ltp":13.0,"tv":24.42,"id":60971786}]}]}
{"op":"mcm","clk":"11959729774","pt":1724583584281,"mc":[{"id":"1.232239000","rc":[{"batb":[[0,12.5,5],[1,3.85,3.6],[2,3.2,2]],"ltp":13.0,"tv":24.42,"id":60971786}]}]}
{"op":"mcm","clk":"11959730162","pt":1724583586989,"mc":[{"id":"1.232239000","rc":[{"batb":[[0,13,5],[1,12.5,5],[2,3.85,3.6]],"ltp":13.0,"tv":24.42,"id":60971786}]}]}
{"op":"mcm","clk":"11959730605","pt":1724583590280,"mc":[{"id":"1.232239000","rc":[{"batb":[[0,12.5,5],[1,3.85,3.6],[2,3.2,2]],"ltp":13.0,"tv":24.42,"id":60971786}]}]}
{"op":"mcm","clk":"11959733230","pt":1724583606811,"mc":[{"id":"1.232239000","rc":[{"batb":[[0,13,5],[1,12.5,5],[2,3.85,3.6]],"ltp":13.0,"tv":24.42,"id":60971786}]}]}
{"op":"mcm","clk":"11959733839","pt":1724583610022,"mc":[{"id":"1.232239000","rc":[{"batb":[[0,12.5,5],[1,3.85,3.6],[2,3.2,2]],"ltp":13.0,"tv":24.42,"id":60971786}]}]}
{"op":"mcm","clk":"11959734824","pt":1724583615753,"mc":[{"id":"1.232239000","rc":[{"batb":[[0,13,5],[1,12.5,5],[2,3.85,3.6]],"ltp":13.0,"tv":24.42,"id":60971786}]}]}
{"op":"mcm","clk":"11959735417","pt":1724583619013,"mc":[{"id":"1.232239000","rc":[{"batb":[[0,12.5,5],[1,3.85,3.6],[2,3.2,2]],"ltp":13.0,"tv":24.42,"id":60971786}]}]}
{"op":"mcm","clk":"11959736189","pt":1724583623711,"mc":[{"id":"1.232239000","rc":[{"batb":[[0,13,5],[1,12.5,5],[2,3.85,3.6]],"ltp":13.0,"tv":24.42,"id":60971786}]}]}
{"op":"mcm","clk":"11959736733","pt":1724583627004,"mc":[{"id":"1.232239000","rc":[{"batb":[[0,12.5,5],[1,3.85,3.6],[2,3.2,2]],"ltp":13.0,"tv":24.42,"id":60971786}]}]}
{"op":"mcm","clk":"11959737335","pt":1724583630732,"mc":[{"id":"1.232239000","rc":[{"batb":[[0,13,5],[1,12.5,5],[2,3.85,3.6]],"ltp":13.0,"tv":24.42,"id":60971786}]}]}
{"op":"mcm","clk":"11959737916","pt":1724583633914,"mc":[{"id":"1.232239000","rc":[{"batb":[[0,12.5,5],[1,3.85,3.6],[2,3.2,2]],"ltp":13.0,"tv":24.42,"id":60971786}]}]}
{"op":"mcm","clk":"11959739013","pt":1724583639412,"mc":[{"id":"1.232239000","rc":[{"batb":[[0,13,5],[1,12.5,5],[2,3.85,3.6]],"ltp":13.0,"tv":24.42,"id":60971786}]}]}
{"op":"mcm","clk":"11959739689","pt":1724583643339,"mc":[{"id":"1.232239000","rc":[{"batb":[[0,12.5,5],[1,3.85,3.6],[2,3.2,2]],"ltp":13.0,"tv":24.42,"id":60971786}]}]}
{"op":"mcm","clk":"11959741399","pt":1724583652625,"mc":[{"id":"1.232239000","rc":[{"batb":[[0,13,5],[1,12.5,5],[2,3.85,3.6]],"ltp":13.0,"tv":24.42,"id":60971786}]}]}
{"op":"mcm","clk":"11959741979","pt":1724583655954,"mc":[{"id":"1.232239000","rc":[{"batb":[[0,12.5,5],[1,3.85,3.6],[2,3.2,2]],"ltp":13.0,"tv":24.42,"id":60971786}]}]}
{"op":"mcm","clk":"11959742410","pt":1724583658564,"mc":[{"id":"1.232239000","rc":[{"batb":[[0,13,5],[1,12.5,5],[2,3.85,3.6]],"ltp":13.0,"tv":24.42,"id":60971786}]}]}
{"op":"mcm","clk":"11959743008","pt":1724583661939,"mc":[{"id":"1.232239000","rc":[{"batb":[[0,12.5,5],[1,3.85,3.6],[2,3.2,2]],"ltp":13.0,"tv":24.42,"id":60971786}]}]}
{"op":"mcm","clk":"11959745114","pt":1724583673456,"mc":[{"id":"1.232239000","rc":[{"batb":[[0,13,5],[1,12.5,5],[2,3.85,3.6]],"ltp":13.0,"tv":24.42,"id":60971786}]}]}
{"op":"mcm","clk":"11959745775","pt":1724583676839,"mc":[{"id":"1.232239000","rc":[{"batb":[[0,12.5,5],[1,3.85,3.6],[2,3.2,2]],"ltp":13.0,"tv":24.42,"id":60971786}]}]}
{"op":"mcm","clk":"11959748937","pt":1724583694876,"mc":[{"id":"1.232239000","rc":[{"batb":[[0,13,5],[1,12.5,5],[2,3.85,3.6]],"ltp":13.0,"tv":24.42,"id":60971786}]}]}
{"op":"mcm","clk":"11959749503","pt":1724583698284,"mc":[{"id":"1.232239000","rc":[{"batb":[[0,12.5,5],[1,3.85,3.6],[2,3.2,2]],"ltp":13.0,"tv":24.42,"id":60971786}]}]}
{"op":"mcm","clk":"11959751525","pt":1724583709425,"mc":[{"id":"1.232239000","rc":[{"batb":[[0,13,5],[1,12.5,5],[2,3.85,3.6]],"ltp":13.0,"tv":24.42,"id":60971786}]}]}
{"op":"mcm","clk":"11959752173","pt":1724583712813,"mc":[{"id":"1.232239000","rc":[{"batb":[[0,12.5,5],[1,3.85,3.6],[2,3.2,2]],"ltp":13.0,"tv":24.42,"id":60971786}]}]}
{"op":"mcm","clk":"11959756260","pt":1724583734159,"mc":[{"id":"1.232239000","rc":[{"batb":[[0,13,5],[1,12.5,5],[2,3.85,3.6]],"ltp":13.0,"tv":24.42,"id":60971786}]}]}
{"op":"mcm","clk":"11959756958","pt":1724583737667,"mc":[{"id":"1.232239000","rc":[{"batb":[[0,12.5,5],[1,3.85,3.6],[2,3.2,2]],"ltp":13.0,"tv":24.42,"id":60971786}]}]}
{"op":"mcm","clk":"11959757528","pt":1724583740746,"mc":[{"id":"1.232239000","rc":[{"batb":[[0,13,5],[1,12.5,5],[2,3.85,3.6]],"ltp":13.0,"tv":24.42,"id":60971786}]}]}
{"op":"mcm","clk":"11959758128","pt":1724583743922,"mc":[{"id":"1.232239000","rc":[{"batb":[[0,12.5,5],[1,3.85,3.6],[2,3.2,2]],"ltp":13.0,"tv":24.42,"id":60971786}]}]}
{"op":"mcm","clk":"11959759417","pt":1724583751160,"mc":[{"id":"1.232239000","rc":[{"batb":[[0,13,5],[1,12.5,5],[2,3.85,3.6]],"ltp":13.0,"tv":24.42,"id":60971786}]}]}
{"op":"mcm","clk":"11959759968","pt":1724583754473,"mc":[{"id":"1.232239000","rc":[{"batb":[[0,12.5,5],[1,3.85,3.6],[2,3.2,2]],"ltp":13.0,"tv":24.42,"id":60971786}]}]}
{"op":"mcm","clk":"11959761398","pt":1724583762642,"mc":[{"id":"1.232239000","rc":[{"batb":[[0,13,5],[1,12.5,5],[2,3.85,3.6]],"ltp":13.0,"tv":24.42,"id":60971786}]}]}
{"op":"mcm","clk":"11959762004","pt":1724583765880,"mc":[{"id":"1.232239000","rc":[{"batb":[[0,12.5,5],[1,3.85,3.6],[2,3.2,2]],"ltp":13.0,"tv":24.42,"id":60971786}]}]}
{"op":"mcm","clk":"11959765748","pt":1724583786980,"mc":[{"id":"1.232239000","rc":[{"batb":[[0,13,5],[1,12.5,5],[2,3.85,3.6]],"ltp":13.0,"tv":24.42,"id":60971786}]}]}
{"op":"mcm","clk":"11959766336","pt":1724583790380,"mc":[{"id":"1.232239000","rc":[{"batb":[[0,12.5,5],[1,3.85,3.6],[2,3.2,2]],"ltp":13.0,"tv":24.42,"id":60971786}]}]}
{"op":"mcm","clk":"11959768120","pt":1724583800087,"mc":[{"id":"1.232239000","rc":[{"batb":[[0,13,5],[1,12.5,5],[2,3.85,3.6]],"ltp":13.0,"tv":24.42,"id":60971786}]}]}
{"op":"mcm","clk":"11959768716","pt":1724583803412,"mc":[{"id":"1.232239000","rc":[{"batb":[[0,12.5,5],[1,3.85,3.6],[2,3.2,2]],"ltp":13.0,"tv":24.42,"id":60971786}]}]}
{"op":"mcm","clk":"11959769372","pt":1724583806927,"mc":[{"id":"1.232239000","rc":[{"batb":[[0,13,5],[1,12.5,5],[2,3.85,3.6]],"ltp":13.0,"tv":24.42,"id":60971786}]}]}
{"op":"mcm","clk":"11959770026","pt":1724583810444,"mc":[{"id":"1.232239000","rc":[{"batb":[[0,12.5,5],[1,3.85,3.6],[2,3.2,2]],"ltp":13.0,"tv":24.42,"id":60971786}]}]}
{"op":"mcm","clk":"11959770707","pt":1724583813926,"mc":[{"id":"1.232239000","rc":[{"batb":[[0,13,5],[1,12.5,5],[2,3.85,3.6]],"ltp":13.0,"tv":24.42,"id":60971786}]}]}
{"op":"mcm","clk":"11959771284","pt":1724583817222,"mc":[{"id":"1.232239000","rc":[{"batb":[[0,12.5,5],[1,3.85,3.6],[2,3.2,2]],"ltp":13.0,"tv":24.42,"id":60971786}]}]}
{"op":"mcm","clk":"11959772691","pt":1724583825270,"mc":[{"id":"1.232239000","rc":[{"batb":[[0,13,5],[1,12.5,5],[2,3.85,3.6]],"ltp":13.0,"tv":24.42,"id":60971786}]}]}
{"op":"mcm","clk":"11959773221","pt":1724583828558,"mc":[{"id":"1.232239000","rc":[{"batb":[[0,12.5,5],[1,3.85,3.6],[2,3.2,2]],"ltp":13.0,"tv":24.42,"id":60971786}]}]}
{"op":"mcm","clk":"11959774674","pt":1724583836734,"mc":[{"id":"1.232239000","rc":[{"batb":[[0,13,5],[1,12.5,5],[2,3.85,3.6]],"ltp":13.0,"tv":24.42,"id":60971786}]}]}
{"op":"mcm","clk":"11959775277","pt":1724583840079,"mc":[{"id":"1.232239000","rc":[{"batb":[[0,12.5,5],[1,3.85,3.6],[2,3.2,2]],"ltp":13.0,"tv":24.42,"id":60971786}]}]}
{"op":"mcm","clk":"11959775949","pt":1724583843639,"mc":[{"id":"1.232239000","rc":[{"batb":[[0,13,5],[1,12.5,5],[2,3.85,3.6]],"ltp":13.0,"tv":24.42,"id":60971786}]}]}
{"op":"mcm","clk":"11959776583","pt":1724583846981,"mc":[{"id":"1.232239000","rc":[{"batb":[[0,12.5,5],[1,3.85,3.6],[2,3.2,2]],"ltp":13.0,"tv":24.42,"id":60971786}]}]}
{"op":"mcm","clk":"11959777272","pt":1724583850777,"mc":[{"id":"1.232239000","rc":[{"batb":[[0,13,5],[1,12.5,5],[2,3.85,3.6]],"ltp":13.0,"tv":24.42,"id":60971786}]}]}
{"op":"mcm","clk":"11959777837","pt":1724583853951,"mc":[{"id":"1.232239000","rc":[{"batb":[[0,12.5,5],[1,3.85,3.6],[2,3.2,2]],"ltp":13.0,"tv":24.42,"id":60971786}]}]}
{"op":"mcm","clk":"11959778275","pt":1724583856564,"mc":[{"id":"1.232239000","rc":[{"batb":[[0,13,5],[1,12.5,5],[2,3.85,3.6]],"ltp":13.0,"tv":24.42,"id":60971786}]}]}
{"op":"mcm","clk":"11959778734","pt":1724583859757,"mc":[{"id":"1.232239000","rc":[{"batb":[[0,12.5,5],[1,3.85,3.6],[2,3.2,2]],"ltp":13.0,"tv":24.42,"id":60971786}]}]}
{"op":"mcm","clk":"11959779243","pt":1724583862980,"mc":[{"id":"1.232239000","rc":[{"batb":[[0,13,5],[1,12.5,5],[2,3.85,3.6]],"ltp":13.0,"tv":24.42,"id":60971786}]}]}
{"op":"mcm","clk":"11959779720","pt":1724583866263,"mc":[{"id":"1.232239000","rc":[{"batb":[[0,12.5,5],[1,3.85,3.6],[2,3.2,2]],"ltp":13.0,"tv":24.42,"id":60971786}]}]}
{"op":"mcm","clk":"11959780115","pt":1724583868668,"mc":[{"id":"1.232239000","rc":[{"batb":[[0,13,5],[1,12.5,5],[2,3.85,3.6]],"ltp":13.0,"tv":24.42,"id":60971786}]}]}
{"op":"mcm","clk":"11959780683","pt":1724583872006,"mc":[{"id":"1.232239000","rc":[{"batb":[[0,12.5,5],[1,3.85,3.6],[2,3.2,2]],"ltp":13.0,"tv":24.42,"id":60971786}]}]}
{"op":"mcm","clk":"11959781204","pt":1724583875185,"mc":[{"id":"1.232239000","rc":[{"batb":[[0,13,5],[1,12.5,5],[2,3.85,3.6]],"ltp":13.0,"tv":24.42,"id":60971786}]}]}
{"op":"mcm","clk":"11959781766","pt":1724583878484,"mc":[{"id":"1.232239000","rc":[{"batb":[[0,12.5,5],[1,3.85,3.6],[2,3.2,2]],"ltp":13.0,"tv":24.42,"id":60971786}]}]}
{"op":"mcm","clk":"11959782111","pt":1724583880719,"mc":[{"id":"1.232239000","rc":[{"batb":[[0,13,5],[1,12.5,5],[2,3.85,3.6]],"ltp":13.0,"tv":24.42,"id":60971786}]}]}
{"op":"mcm","clk":"11959782656","pt":1724583883902,"mc":[{"id":"1.232239000","rc":[{"batb":[[0,12.5,5],[1,3.85,3.6],[2,3.2,2]],"ltp":13.0,"tv":24.42,"id":60971786}]}]}
{"op":"mcm","clk":"11959783597","pt":1724583889338,"mc":[{"id":"1.232239000","rc":[{"batb":[[0,13,5],[1,12.5,5],[2,3.85,3.6]],"ltp":13.0,"tv":24.42,"id":60971786}]}]}
{"op":"mcm","clk":"11959784220","pt":1724583892754,"mc":[{"id":"1.232239000","rc":[{"batb":[[0,12.5,5],[1,3.85,3.6],[2,3.2,2]],"ltp":13.0,"tv":24.42,"id":60971786}]}]}
{"op":"mcm","clk":"11959785258","pt":1724583898332,"mc":[{"id":"1.232239000","rc":[{"batb":[[0,13,5],[1,12.5,5],[2,3.85,3.6]],"ltp":13.0,"tv":24.42,"id":60971786}]}]}
{"op":"mcm","clk":"11959785860","pt":1724583901648,"mc":[{"id":"1.232239000","rc":[{"batb":[[0,12.5,5],[1,3.85,3.6],[2,3.2,2]],"ltp":13.0,"tv":24.42,"id":60971786}]}]}
{"op":"mcm","clk":"11959786838","pt":1724583906727,"mc":[{"id":"1.232239000","rc":[{"batb":[[0,13,5],[1,12.5,5],[2,3.85,3.6]],"ltp":13.0,"tv":24.42,"id":60971786}]}]}
{"op":"mcm","clk":"11959787418","pt":1724583910120,"mc":[{"id":"1.232239000","rc":[{"batb":[[0,12.5,5],[1,3.85,3.6],[2,3.2,2]],"ltp":13.0,"tv":24.42,"id":60971786}]}]}
{"op":"mcm","clk":"11959787857","pt":1724583912458,"mc":[{"id":"1.232239000","rc":[{"batb":[[0,13,5],[1,12.5,5],[2,3.85,3.6]],"ltp":13.0,"tv":24.42,"id":60971786}]}]}
{"op":"mcm","clk":"11959788419","pt":1724583915736,"mc":[{"id":"1.232239000","rc":[{"batb":[[0,12.5,5],[1,3.85,3.6],[2,3.2,2]],"ltp":13.0,"tv":24.42,"id":60971786}]}]}
{"op":"mcm","clk":"11959790004","pt":1724583924860,"mc":[{"id":"1.232239000","rc":[{"batb":[[0,13,5],[1,12.5,5],[2,3.85,3.6]],"ltp":13.0,"tv":24.42,"id":60971786}]}]}
{"op":"mcm","clk":"11959790553","pt":1724583928273,"mc":[{"id":"1.232239000","rc":[{"batb":[[0,12.5,5],[1,3.85,3.6],[2,3.2,2]],"ltp":13.0,"tv":24.42,"id":60971786}]}]}
{"op":"mcm","clk":"11959791622","pt":1724583934719,"mc":[{"id":"1.232239000","rc":[{"batb":[[0,13,5],[1,12.5,5],[2,3.85,3.6]],"ltp":13.0,"tv":24.42,"id":60971786}]}]}
{"op":"mcm","clk":"11959792227","pt":1724583938051,"mc":[{"id":"1.232239000","rc":[{"batb":[[0,12.5,5],[1,3.85,3.6],[2,3.2,2]],"ltp":13.0,"tv":24.42,"id":60971786}]}]}
{"op":"mcm","clk":"11959792744","pt":1724583940838,"mc":[{"id":"1.232239000","rc":[{"batb":[[0,13,5],[1,12.5,5],[2,3.85,3.6]],"ltp":13.0,"tv":24.42,"id":60971786}]}]}
{"op":"mcm","clk":"11959793279","pt":1724583944167,"mc":[{"id":"1.232239000","rc":[{"batb":[[0,12.5,5],[1,3.85,3.6],[2,3.2,2]],"ltp":13.0,"tv":24.42,"id":60971786}]}]}
{"op":"mcm","clk":"11959793924","pt":1724583947883,"mc":[{"id":"1.232239000","rc":[{"batb":[[0,13,5],[1,12.5,5],[2,3.85,3.6]],"ltp":13.0,"tv":24.42,"id":60971786}]}]}
{"op":"mcm","clk":"11959794494","pt":1724583951302,"mc":[{"id":"1.232239000","rc":[{"batb":[[0,12.5,5],[1,3.85,3.6],[2,3.2,2]],"ltp":13.0,"tv":24.42,"id":60971786}]}]}
{"op":"mcm","clk":"11959795126","pt":1724583954920,"mc":[{"id":"1.232239000","rc":[{"batb":[[0,13,5],[1,12.5,5],[2,3.85,3.6]],"ltp":13.0,"tv":24.42,"id":60971786}]}]}
{"op":"mcm","clk":"11959795702","pt":1724583958120,"mc":[{"id":"1.232239000","rc":[{"batb":[[0,12.5,5],[1,3.85,3.6],[2,3.2,2]],"ltp":13.0,"tv":24.42,"id":60971786}]}]}
{"op":"mcm","clk":"11959796429","pt":1724583961945,"mc":[{"id":"1.232239000","rc":[{"batb":[[0,13,5],[1,12.5,5],[2,3.85,3.6]],"ltp":13.0,"tv":24.42,"id":60971786}]}]}
{"op":"mcm","clk":"11959797094","pt":1724583965317,"mc":[{"id":"1.232239000","rc":[{"batb":[[0,12.5,5],[1,3.85,3.6],[2,3.2,2]],"ltp":13.0,"tv":24.42,"id":60971786}]}]}
{"op":"mcm","clk":"11959799455","pt":1724583977559,"mc":[{"id":"1.232239000","rc":[{"batb":[[0,13,5],[1,12.5,5],[2,3.85,3.6]],"ltp":13.0,"tv":24.42,"id":60971786}]}]}
{"op":"mcm","clk":"11959800106","pt":1724583981077,"mc":[{"id":"1.232239000","rc":[{"batb":[[0,12.5,5],[1,3.85,3.6],[2,3.2,2]],"ltp":13.0,"tv":24.42,"id":60971786}]}]}
{"op":"mcm","clk":"11959800614","pt":1724583983629,"mc":[{"id":"1.232239000","rc":[{"batb":[[0,13,5],[1,12.5,5],[2,3.85,3.6]],"ltp":13.0,"tv":24.42,"id":60971786}]}]}
{"op":"mcm","clk":"11959801235","pt":1724583986852,"mc":[{"id":"1.232239000","rc":[{"batb":[[0,12.5,5],[1,3.85,3.6],[2,3.2,2]],"ltp":13.0,"tv":24.42,"id":60971786}]}]}
{"op":"mcm","clk":"11959801977","pt":1724583990842,"mc":[{"id":"1.232239000","rc":[{"batb":[[0,13,5],[1,12.5,5],[2,3.85,3.6]],"ltp":13.0,"tv":24.42,"id":60971786}]}]}
{"op":"mcm","clk":"11959802648","pt":1724583994288,"mc":[{"id":"1.232239000","rc":[{"batb":[[0,12.5,5],[1,3.85,3.6],[2,3.2,2]],"ltp":13.0,"tv":24.42,"id":60971786}]}]}
{"op":"mcm","clk":"11959803142","pt":1724583997163,"mc":[{"id":"1.232239000","rc":[{"batb":[[0,13,5],[1,12.5,5],[2,3.85,3.6]],"ltp":13.0,"tv":24.42,"id":60971786}]}]}
{"op":"mcm","clk":"11959803755","pt":1724584000371,"mc":[{"id":"1.232239000","rc":[{"batb":[[0,12.5,5],[1,3.85,3.6],[2,3.2,2]],"ltp":13.0,"tv":24.42,"id":60971786}]}]}
{"op":"mcm","clk":"11959805172","pt":1724584007858,"mc":[{"id":"1.232239000","rc":[{"batb":[[0,13,5],[1,12.5,5],[2,3.85,3.6]],"ltp":13.0,"tv":24.42,"id":60971786}]}]}
{"op":"mcm","clk":"11959805763","pt":1724584011191,"mc":[{"id":"1.232239000","rc":[{"batb":[[0,12.5,5],[1,3.85,3.6],[2,3.2,2]],"ltp":13.0,"tv":24.42,"id":60971786}]}]}
{"op":"mcm","clk":"11959806355","pt":1724584014694,"mc":[{"id":"1.232239000","rc":[{"batb":[[0,13,5],[1,12.5,5],[2,3.85,3.6]],"ltp":13.0,"tv":24.42,"id":60971786}]}]}
{"op":"mcm","clk":"11959806936","pt":1724584018101,"mc":[{"id":"1.232239000","rc":[{"batb":[[0,12.5,5],[1,3.85,3.6],[2,3.2,2]],"ltp":13.0,"tv":24.42,"id":60971786}]}]}
{"op":"mcm","clk":"11959808566","pt":1724584026866,"mc":[{"id":"1.232239000","rc":[{"batb":[[0,13,5],[1,12.5,5],[2,3.85,3.6]],"ltp":13.0,"tv":24.42,"id":60971786}]}]}
{"op":"mcm","clk":"11959809267","pt":1724584030098,"mc":[{"id":"1.232239000","rc":[{"batb":[[0,12.5,5],[1,3.85,3.6],[2,3.2,2]],"ltp":13.0,"tv":24.42,"id":60971786}]}]}
{"op":"mcm","clk":"11959810380","pt":1724584035692,"mc":[{"id":"1.232239000","rc":[{"batb":[[0,13,5],[1,12.5,5],[2,3.85,3.6]],"ltp":13.0,"tv":24.42,"id":60971786}]}]}
{"op":"mcm","clk":"11959810958","pt":1724584038930,"mc":[{"id":"1.232239000","rc":[{"batb":[[0,12.5,5],[1,3.85,3.6],[2,3.2,2]],"ltp":13.0,"tv":24.42,"id":60971786}]}]}
{"op":"mcm","clk":"11959812479","pt":1724584047018,"mc":[{"id":"1.232239000","rc":[{"batb":[[0,13,5],[1,12.5,5],[2,3.85,3.6]],"ltp":13.0,"tv":24.42,"id":60971786}]}]}
{"op":"mcm","clk":"11959813140","pt":1724584050416,"mc":[{"id":"1.232239000","rc":[{"batb":[[0,12.5,5],[1,3.85,3.6],[2,3.2,2]],"ltp":13.0,"tv":24.42,"id":60971786}]}]}
{"op":"mcm","clk":"11959814896","pt":1724584059844,"mc":[{"id":"1.232239000","rc":[{"batb":[[0,13,5],[1,12.5,5],[2,3.85,3.6]],"ltp":13.0,"tv":24.42,"id":60971786}]}]}
{"op":"mcm","clk":"11959815487","pt":1724584063039,"mc":[{"id":"1.232239000","rc":[{"batb":[[0,12.5,5],[1,3.85,3.6],[2,3.2,2]],"ltp":13.0,"tv":24.42,"id":60971786}]}]}
{"op":"mcm","clk":"11959816373","pt":1724584068222,"mc":[{"id":"1.232239000","rc":[{"batb":[[0,13,5],[1,12.5,5],[2,3.85,3.6]],"ltp":13.0,"tv":24.42,"id":60971786}]}]}
{"op":"mcm","clk":"11959816970","pt":1724584071539,"mc":[{"id":"1.232239000","rc":[{"batb":[[0,12.5,5],[1,3.85,3.6],[2,3.2,2]],"ltp":13.0,"tv":24.42,"id":60971786}]}]}
{"op":"mcm","clk":"11959818044","pt":1724584077330,"mc":[{"id":"1.232239000","rc":[{"batb":[[0,13,5],[1,12.5,5],[2,3.85,3.6]],"ltp":13.0,"tv":24.42,"id":60971786}]}]}
{"op":"mcm","clk":"11959818637","pt":1724584080538,"mc":[{"id":"1.232239000","rc":[{"batb":[[0,12.5,5],[1,3.85,3.6],[2,3.2,2]],"ltp":13.0,"tv":24.42,"id":60971786}]}]}
{"op":"mcm","clk":"11959819133","pt":1724584083133,"mc":[{"id":"1.232239000","rc":[{"batb":[[0,13,5],[1,12.5,5],[2,3.85,3.6]],"ltp":13.0,"tv":24.42,"id":60971786}]}]}
{"op":"mcm","clk":"11959819744","pt":1724584086565,"mc":[{"id":"1.232239000","rc":[{"batb":[[0,12.5,5],[1,3.85,3.6],[2,3.2,2]],"ltp":13.0,"tv":24.42,"id":60971786}]}]}
{"op":"mcm","clk":"11959820710","pt":1724584091568,"mc":[{"id":"1.232239000","rc":[{"batb":[[0,13,5],[1,12.5,5],[2,3.85,3.6]],"ltp":13.0,"tv":24.42,"id":60971786}]}]}
{"op":"mcm","clk":"11959821317","pt":1724584094839,"mc":[{"id":"1.232239000","rc":[{"batb":[[0,12.5,5],[1,3.85,3.6],[2,3.2,2]],"ltp":13.0,"tv":24.42,"id":60971786}]}]}
{"op":"mcm","clk":"11959822051","pt":1724584098670,"mc":[{"id":"1.232239000","rc":[{"batb":[[0,13,5],[1,12.5,5],[2,3.85,3.6]],"ltp":13.0,"tv":24.42,"id":60971786}]}]}
{"op":"mcm","clk":"11959822687","pt":1724584101948,"mc":[{"id":"1.232239000","rc":[{"batb":[[0,12.5,5],[1,3.85,3.6],[2,3.2,2]],"ltp":13.0,"tv":24.42,"id":60971786}]}]}
{"op":"mcm","clk":"11959823406","pt":1724584105979,"mc":[{"id":"1.232239000","rc":[{"batb":[[0,13,5],[1,12.5,5],[2,3.85,3.6]],"ltp":13.0,"tv":24.42,"id":60971786}]}]}
{"op":"mcm","clk":"11959824009","pt":1724584109365,"mc":[{"id":"1.232239000","rc":[{"batb":[[0,12.5,5],[1,3.85,3.6],[2,3.2,2]],"ltp":13.0,"tv":24.42,"id":60971786}]}]}
{"op":"mcm","clk":"11959824563","pt":1724584112405,"mc":[{"id":"1.232239000","rc":[{"batb":[[0,13,5],[1,12.5,5],[2,3.85,3.6]],"ltp":13.0,"tv":24.42,"id":60971786}]}]}
{"op":"mcm","clk":"11959825199","pt":1724584115784,"mc":[{"id":"1.232239000","rc":[{"batb":[[0,12.5,5],[1,3.85,3.6],[2,3.2,2]],"ltp":13.0,"tv":24.42,"id":60971786}]}]}
{"op":"mcm","clk":"11959826279","pt":1724584121295,"mc":[{"id":"1.232239000","rc":[{"batb":[[0,13,5],[1,12.5,5],[2,3.85,3.6]],"ltp":13.0,"tv":24.42,"id":60971786}]}]}
{"op":"mcm","clk":"11959826896","pt":1724584124606,"mc":[{"id":"1.232239000","rc":[{"batb":[[0,12.5,5],[1,3.85,3.6],[2,3.2,2]],"ltp":13.0,"tv":24.42,"id":60971786}]}]}
{"op":"mcm","clk":"11959827607","pt":1724584128111,"mc":[{"id":"1.232239000","rc":[{"batb":[[0,13,5],[1,12.5,5],[2,3.85,3.6]],"ltp":13.0,"tv":24.42,"id":60971786}]}]}
{"op":"mcm","clk":"11959828220","pt":1724584131504,"mc":[{"id":"1.232239000","rc":[{"batb":[[0,12.5,5],[1,3.85,3.6],[2,3.2,2]],"ltp":13.0,"tv":24.42,"id":60971786}]}]}
{"op":"mcm","clk":"11959828822","pt":1724584134513,"mc":[{"id":"1.232239000","rc":[{"batb":[[0,13,5],[1,12.5,5],[2,3.85,3.6]],"ltp":13.0,"tv":24.42,"id":60971786}]}]}
{"op":"mcm","clk":"11959829464","pt":1724584137817,"mc":[{"id":"1.232239000","rc":[{"batb":[[0,12.5,5],[1,3.85,3.6],[2,3.2,2]],"ltp":13.0,"tv":24.42,"id":60971786}]}]}
{"op":"mcm","clk":"11959829886","pt":1724584140009,"mc":[{"id":"1.232239000","rc":[{"batb":[[0,13,5],[1,12.5,5],[2,3.85,3.6]],"ltp":13.0,"tv":24.42,"id":60971786}]}]}
{"op":"mcm","clk":"11959830544","pt":1724584143438,"mc":[{"id":"1.232239000","rc":[{"batb":[[0,12.5,5],[1,3.85,3.6],[2,3.2,2]],"ltp":13.0,"tv":24.42,"id":60971786}]}]}
{"op":"mcm","clk":"11959831664","pt":1724584149387,"mc":[{"id":"1.232239000","rc":[{"batb":[[0,13,5],[1,12.5,5],[2,3.85,3.6]],"ltp":13.0,"tv":24.42,"id":60971786}]}]}
{"op":"mcm","clk":"11959832275","pt":1724584152633,"mc":[{"id":"1.232239000","rc":[{"batb":[[0,12.5,5],[1,3.85,3.6],[2,3.2,2]],"ltp":13.0,"tv":24.42,"id":60971786}]}]}
{"op":"mcm","clk":"11959833175","pt":1724584157439,"mc":[{"id":"1.232239000","rc":[{"batb":[[0,13,5],[1,12.5,5],[2,3.85,3.6]],"ltp":13.0,"tv":24.42,"id":60971786}]}]}
{"op":"mcm","clk":"11959833766","pt":1724584160746,"mc":[{"id":"1.232239000","rc":[{"batb":[[0,12.5,5],[1,3.85,3.6],[2,3.2,2]],"ltp":13.0,"tv":24.42,"id":60971786}]}]}
{"op":"mcm","clk":"11959834313","pt":1724584163537,"mc":[{"id":"1.232239000","rc":[{"batb":[[0,13,5],[1,12.5,5],[2,3.85,3.6]],"ltp":13.0,"tv":24.42,"id":60971786}]}]}
{"op":"mcm","clk":"11959834990","pt":1724584166946,"mc":[{"id":"1.232239000","rc":[{"batb":[[0,12.5,5],[1,3.85,3.6],[2,3.2,2]],"ltp":13.0,"tv":24.42,"id":60971786}]}]}
{"op":"mcm","clk":"11959835518","pt":1724584169734,"mc":[{"id":"1.232239000","rc":[{"batb":[[0,13,5],[1,12.5,5],[2,3.85,3.6]],"ltp":13.0,"tv":24.42,"id":60971786}]}]}
{"op":"mcm","clk":"11959836166","pt":1724584173070,"mc":[{"id":"1.232239000","rc":[{"batb":[[0,12.5,5],[1,3.85,3.6],[2,3.2,2]],"ltp":13.0,"tv":24.42,"id":60971786}]}]}
{"op":"mcm","clk":"11959837304","pt":1724584179044,"mc":[{"id":"1.232239000","rc":[{"batb":[[0,13,5],[1,12.5,5],[2,3.85,3.6]],"ltp":13.0,"tv":24.42,"id":60971786}]}]}
{"op":"mcm","clk":"11959837906","pt":1724584182345,"mc":[{"id":"1.232239000","rc":[{"batb":[[0,12.5,5],[1,3.85,3.6],[2,3.2,2]],"ltp":13.0,"tv":24.42,"id":60971786}]}]}
{"op":"mcm","clk":"11959838972","pt":1724584188562,"mc":[{"id":"1.232239000","rc":[{"batb":[[0,13,5],[1,12.5,5],[2,3.85,3.6]],"ltp":13.0,"tv":24.42,"id":60971786}]}]}
{"op":"mcm","clk":"11959839543","pt":1724584191902,"mc":[{"id":"1.232239000","rc":[{"batb":[[0,12.5,5],[1,3.85,3.6],[2,3.2,2]],"ltp":13.0,"tv":24.42,"id":60971786}]}]}
{"op":"mcm","clk":"11959840998","pt":1724584199366,"mc":[{"id":"1.232239000","rc":[{"batb":[[0,13,5],[1,12.5,5],[2,3.85,3.6]],"ltp":13.0,"tv":24.42,"id":60971786}]}]}
{"op":"mcm","clk":"11959841641","pt":1724584202792,"mc":[{"id":"1.232239000","rc":[{"batb":[[0,12.5,5],[1,3.85,3.6],[2,3.2,2]],"ltp":13.0,"tv":24.42,"id":60971786}]}]}
{"op":"mcm","clk":"11959842108","pt":1724584205195,"mc":[{"id":"1.232239000","rc":[{"batb":[[0,13,5],[1,12.5,5],[2,3.85,3.6]],"ltp":13.0,"tv":24.42,"id":60971786}]}]}
{"op":"mcm","clk":"11959842759","pt":1724584208591,"mc":[{"id":"1.232239000","rc":[{"batb":[[0,12.5,5],[1,3.85,3.6],[2,3.2,2]],"ltp":13.0,"tv":24.42,"id":60971786}]}]}
{"op":"mcm","clk":"11959843544","pt":1724584212692,"mc":[{"id":"1.232239000","rc":[{"batb":[[0,13,5],[1,12.5,5],[2,3.85,3.6]],"ltp":13.0,"tv":24.42,"id":60971786}]}]}
{"op":"mcm","clk":"11959844123","pt":1724584215990,"mc":[{"id":"1.232239000","rc":[{"batb":[[0,12.5,5],[1,3.85,3.6],[2,3.2,2]],"ltp":13.0,"tv":24.42,"id":60971786}]}]}
{"op":"mcm","clk":"11959844607","pt":1724584218811,"mc":[{"id":"1.232239000","rc":[{"batb":[[0,13,5],[1,12.5,5],[2,3.85,3.6]],"ltp":13.0,"tv":24.42,"id":60971786}]}]}
{"op":"mcm","clk":"11959845223","pt":1724584222123,"mc":[{"id":"1.232239000","rc":[{"batb":[[0,12.5,5],[1,3.85,3.6],[2,3.2,2]],"ltp":13.0,"tv":24.42,"id":60971786}]}]}
{"op":"mcm","clk":"11959845670","pt":1724584224526,"mc":[{"id":"1.232239000","rc":[{"batb":[[0,13,5],[1,12.5,5],[2,3.85,3.6]],"ltp":13.0,"tv":24.42,"id":60971786}]}]}
{"op":"mcm","clk":"11959846342","pt":1724584227888,"mc":[{"id":"1.232239000","rc":[{"batb":[[0,12.5,5],[1,3.85,3.6],[2,3.2,2]],"ltp":13.0,"tv":24.42,"id":60971786}]}]}
{"op":"mcm","clk":"11959847044","pt":1724584231813,"mc":[{"id":"1.232239000","rc":[{"batb":[[0,13,5],[1,12.5,5],[2,3.85,3.6]],"ltp":13.0,"tv":24.42,"id":60971786}]}]}
{"op":"mcm","clk":"11959847669","pt":1724584235011,"mc":[{"id":"1.232239000","rc":[{"batb":[[0,12.5,5],[1,3.85,3.6],[2,3.2,2]],"ltp":13.0,"tv":24.42,"id":60971786}]}]}
{"op":"mcm","clk":"11959848758","pt":1724584240222,"mc":[{"id":"1.232239000","rc":[{"batb":[[0,13,5],[1,12.5,5],[2,3.85,3.6]],"ltp":13.0,"tv":24.42,"id":60971786}]}]}
{"op":"mcm","clk":"11959849353","pt":1724584243424,"mc":[{"id":"1.232239000","rc":[{"batb":[[0,12.5,5],[1,3.85,3.6],[2,3.2,2]],"ltp":13.0,"tv":24.42,"id":60971786}]}]}
{"op":"mcm","clk":"11959849943","pt":1724584246728,"mc":[{"id":"1.232239000","rc":[{"batb":[[0,13,5],[1,12.5,5],[2,3.85,3.6]],"ltp":13.0,"tv":24.42,"id":60971786}]}]}
{"op":"mcm","clk":"11959850583","pt":1724584250123,"mc":[{"id":"1.232239000","rc":[{"batb":[[0,12.5,5],[1,3.85,3.6],[2,3.2,2]],"ltp":13.0,"tv":24.42,"id":60971786}]}]}
{"op":"mcm","clk":"11959851120","pt":1724584252860,"mc":[{"id":"1.232239000","rc":[{"batb":[[0,13,5],[1,12.5,5],[2,3.85,3.6]],"ltp":13.0,"tv":24.42,"id":60971786}]}]}
{"op":"mcm","clk":"11959851671","pt":1724584256173,"mc":[{"id":"1.232239000","rc":[{"batb":[[0,12.5,5],[1,3.85,3.6],[2,3.2,2]],"ltp":13.0,"tv":24.42,"id":60971786}]}]}
{"op":"mcm","clk":"11959852379","pt":1724584259966,"mc":[{"id":"1.232239000","rc":[{"batb":[[0,13,5],[1,12.5,5],[2,3.85,3.6]],"ltp":13.0,"tv":24.42,"id":60971786}]}]}
{"op":"mcm","clk":"11959853052","pt":1724584263378,"mc":[{"id":"1.232239000","rc":[{"batb":[[0,12.5,5],[1,3.85,3.6],[2,3.2,2]],"ltp":13.0,"tv":24.42,"id":60971786}]}]}
{"op":"mcm","clk":"11959853739","pt":1724584267082,"mc":[{"id":"1.232239000","rc":[{"batb":[[0,13,5],[1,12.5,5],[2,3.85,3.6]],"ltp":13.0,"tv":24.42,"id":60971786}]}]}
{"op":"mcm","clk":"11959854373","pt":1724584270499,"mc":[{"id":"1.232239000","rc":[{"batb":[[0,12.5,5],[1,3.85,3.6],[2,3.2,2]],"ltp":13.0,"tv":24.42,"id":60971786}]}]}
{"op":"mcm","clk":"11959855065","pt":1724584274190,"mc":[{"id":"1.232239000","rc":[{"batb":[[0,13,5],[1,12.5,5],[2,3.85,3.6]],"ltp":13.0,"tv":24.42,"id":60971786}]}]}
{"op":"mcm","clk":"11959855708","pt":1724584277584,"mc":[{"id":"1.232239000","rc":[{"batb":[[0,12.5,5],[1,3.85,3.6],[2,3.2,2]],"ltp":13.0,"tv":24.42,"id":60971786}]}]}
{"op":"mcm","clk":"11959856403","pt":1724584281488,"mc":[{"id":"1.232239000","rc":[{"batb":[[0,13,5],[1,12.5,5],[2,3.85,3.6]],"ltp":13.0,"tv":24.42,"id":60971786}]}]}
{"op":"mcm","clk":"11959857035","pt":1724584284799,"mc":[{"id":"1.232239000","rc":[{"batb":[[0,12.5,5],[1,3.85,3.6],[2,3.2,2]],"ltp":13.0,"tv":24.42,"id":60971786}]}]}
{"op":"mcm","clk":"11959857598","pt":1724584287853,"mc":[{"id":"1.232239000","rc":[{"batb":[[0,13,5],[1,12.5,5],[2,3.85,3.6]],"ltp":13.0,"tv":24.42,"id":60971786}]}]}
{"op":"mcm","clk":"11959858268","pt":1724584291495,"mc":[{"id":"1.232239000","rc":[{"batb":[[0,12.5,5],[1,3.85,3.6],[2,3.2,2]],"ltp":13.0,"tv":24.42,"id":60971786}]}]}
{"op":"mcm","clk":"11959858890","pt":1724584294926,"mc":[{"id":"1.232239000","rc":[{"batb":[[0,13,5],[1,12.5,5],[2,3.85,3.6]],"ltp":13.0,"tv":24.42,"id":60971786}]}]}
{"op":"mcm","clk":"11959859483","pt":1724584298229,"mc":[{"id":"1.232239000","rc":[{"batb":[[0,12.5,5],[1,3.85,3.6],[2,3.2,2]],"ltp":13.0,"tv":24.42,"id":60971786}]}]}
{"op":"mcm","clk":"11959860676","pt":1724584304126,"mc":[{"id":"1.232239000","rc":[{"batb":[[0,13,5],[1,12.5,5],[2,3.85,3.6]],"ltp":13.0,"tv":24.42,"id":60971786}]}]}
{"op":"mcm","clk":"11959861287","pt":1724584307424,"mc":[{"id":"1.232239000","rc":[{"batb":[[0,12.5,5],[1,3.85,3.6],[2,3.2,2]],"ltp":13.0,"tv":24.42,"id":60971786}]}]}
{"op":"mcm","clk":"11959862253","pt":1724584312827,"mc":[{"id":"1.232239000","rc":[{"batb":[[0,13,5],[1,12.5,5],[2,3.85,3.6]],"ltp":13.0,"tv":24.42,"id":60971786}]}]}
{"op":"mcm","clk":"11959862801","pt":1724584316038,"mc":[{"id":"1.232239000","rc":[{"batb":[[0,12.5,5],[1,3.85,3.6],[2,3.2,2]],"ltp":13.0,"tv":24.42,"id":60971786}]}]}
{"op":"mcm","clk":"11959863302","pt":1724584318932,"mc":[{"id":"1.232239000","rc":[{"batb":[[0,13,5],[1,12.5,5],[2,3.85,3.6]],"ltp":13.0,"tv":24.42,"id":60971786}]}]}
{"op":"mcm","clk":"11959863944","pt":1724584322223,"mc":[{"id":"1.232239000","rc":[{"batb":[[0,12.5,5],[1,3.85,3.6],[2,3.2,2]],"ltp":13.0,"tv":24.42,"id":60971786}]}]}
{"op":"mcm","clk":"11959865191","pt":1724584328444,"mc":[{"id":"1.232239000","rc":[{"batb":[[0,13,5],[1,12.5,5],[2,3.85,3.6]],"ltp":13.0,"tv":24.42,"id":60971786}]}]}
{"op":"mcm","clk":"11959865886","pt":1724584331756,"mc":[{"id":"1.232239000","rc":[{"batb":[[0,12.5,5],[1,3.85,3.6],[2,3.2,2]],"ltp":13.0,"tv":24.42,"id":60971786}]}]}
{"op":"mcm","clk":"11959867670","pt":1724584339793,"mc":[{"id":"1.232239000","rc":[{"batb":[[0,13,5],[1,12.5,5],[2,3.85,3.6]],"ltp":13.0,"tv":24.42,"id":60971786}]}]}
{"op":"mcm","clk":"11959868364","pt":1724584343214,"mc":[{"id":"1.232239000","rc":[{"batb":[[0,12.5,5],[1,3.85,3.6],[2,3.2,2]],"ltp":13.0,"tv":24.42,"id":60971786}]}]}
{"op":"mcm","clk":"11959869850","pt":1724584350314,"mc":[{"id":"1.232239000","rc":[{"batb":[[0,13,5],[1,12.5,5],[2,3.85,3.6]],"ltp":13.0,"tv":24.42,"id":60971786}]}]}
{"op":"mcm","clk":"11959870540","pt":1724584353619,"mc":[{"id":"1.232239000","rc":[{"batb":[[0,12.5,5],[1,3.85,3.6],[2,3.2,2]],"ltp":13.0,"tv":24.42,"id":60971786}]}]}
{"op":"mcm","clk":"11959871299","pt":1724584357196,"mc":[{"id":"1.232239000","rc":[{"batb":[[0,13,5],[1,12.5,5],[2,3.85,3.6]],"ltp":13.0,"tv":24.42,"id":60971786}]}]}
{"op":"mcm","clk":"11959872010","pt":1724584360526,"mc":[{"id":"1.232239000","rc":[{"batb":[[0,12.5,5],[1,3.85,3.6],[2,3.2,2]],"ltp":13.0,"tv":24.42,"id":60971786}]}]}
{"op":"mcm","clk":"11959872681","pt":1724584364132,"mc":[{"id":"1.232239000","rc":[{"batb":[[0,13,5],[1,12.5,5],[2,3.85,3.6]],"ltp":13.0,"tv":24.42,"id":60971786}]}]}
{"op":"mcm","clk":"11959873332","pt":1724584367537,"mc":[{"id":"1.232239000","rc":[{"batb":[[0,12.5,5],[1,3.85,3.6],[2,3.2,2]],"ltp":13.0,"tv":24.42,"id":60971786}]}]}
{"op":"mcm","clk":"11959874038","pt":1724584371148,"mc":[{"id":"1.232239000","rc":[{"batb":[[0,13,5],[1,12.5,5],[2,3.85,3.6]],"ltp":13.0,"tv":24.42,"id":60971786}]}]}
{"op":"mcm","clk":"11959874649","pt":1724584374422,"mc":[{"id":"1.232239000","rc":[{"batb":[[0,12.5,5],[1,3.85,3.6],[2,3.2,2]],"ltp":13.0,"tv":24.42,"id":60971786}]}]}
{"op":"mcm","clk":"11959890455","pt":1724584381537,"mc":[{"id":"1.232239000","rc":[{"batb":[[0,13,5],[1,12.5,5],[2,3.85,3.6]],"ltp":13.0,"tv":24.42,"id":60971786}]}]}
{"op":"mcm","clk":"11959891160","pt":1724584384939,"mc":[{"id":"1.232239000","rc":[{"batb":[[0,12.5,5],[1,3.85,3.6],[2,3.2,2]],"ltp":13.0,"tv":24.42,"id":60971786}]}]}
{"op":"mcm","clk":"11959892627","pt":1724584392159,"mc":[{"id":"1.232239000","rc":[{"batb":[[0,13,5],[1,12.5,5],[2,3.85,3.6]],"ltp":13.0,"tv":24.42,"id":60971786}]}]}
{"op":"mcm","clk":"11959893367","pt":1724584395476,"mc":[{"id":"1.232239000","rc":[{"batb":[[0,12.5,5],[1,3.85,3.6],[2,3.2,2]],"ltp":13.0,"tv":24.42,"id":60971786}]}]}
{"op":"mcm","clk":"11959894609","pt":1724584401675,"mc":[{"id":"1.232239000","rc":[{"batb":[[0,13,5],[1,12.5,5],[2,3.85,3.6]],"ltp":13.0,"tv":24.42,"id":60971786}]}]}
{"op":"mcm","clk":"11959895318","pt":1724584405182,"mc":[{"id":"1.232239000","rc":[{"batb":[[0,12.5,5],[1,3.85,3.6],[2,3.2,2]],"ltp":13.0,"tv":24.42,"id":60971786}]}]}
{"op":"mcm","clk":"11959895818","pt":1724584407863,"mc":[{"id":"1.232239000","rc":[{"batb":[[0,13,5],[1,12.5,5],[2,3.85,3.6]],"ltp":13.0,"tv":24.42,"id":60971786}]}]}
{"op":"mcm","clk":"11959896395","pt":1724584411261,"mc":[{"id":"1.232239000","rc":[{"batb":[[0,12.5,5],[1,3.85,3.6],[2,3.2,2]],"ltp":13.0,"tv":24.42,"id":60971786}]}]}
{"op":"mcm","clk":"11959897111","pt":1724584414882,"mc":[{"id":"1.232239000","rc":[{"batb":[[0,13,5],[1,12.5,5],[2,3.85,3.6]],"ltp":13.0,"tv":24.42,"id":60971786}]}]}
{"op":"mcm","clk":"11959897752","pt":1724584418289,"mc":[{"id":"1.232239000","rc":[{"batb":[[0,12.5,5],[1,3.85,3.6],[2,3.2,2]],"ltp":13.0,"tv":24.42,"id":60971786}]}]}
{"op":"mcm","clk":"11959898754","pt":1724584423481,"mc":[{"id":"1.232239000","rc":[{"batb":[[0,13,5],[1,12.5,5],[2,3.85,3.6]],"ltp":13.0,"tv":24.42,"id":60971786}]}]}
{"op":"mcm","clk":"11959899412","pt":1724584426997,"mc":[{"id":"1.232239000","rc":[{"batb":[[0,12.5,5],[1,3.85,3.6],[2,3.2,2]],"ltp":13.0,"tv":24.42,"id":60971786}]}]}
{"op":"mcm","clk":"11959900918","pt":1724584434311,"mc":[{"id":"1.232239000","rc":[{"batb":[[0,13,5],[1,12.5,5],[2,3.85,3.6]],"ltp":13.0,"tv":24.42,"id":60971786}]}]}
{"op":"mcm","clk":"11959901539","pt":1724584437709,"mc":[{"id":"1.232239000","rc":[{"batb":[[0,12.5,5],[1,3.85,3.6],[2,3.2,2]],"ltp":13.0,"tv":24.42,"id":60971786}]}]}
{"op":"mcm","clk":"11959903260","pt":1724584446627,"mc":[{"id":"1.232239000","rc":[{"batb":[[0,13,5],[1,12.5,5],[2,3.85,3.6]],"ltp":13.0,"tv":24.42,"id":60971786}]}]}
{"op":"mcm","clk":"11959903975","pt":1724584449934,"mc":[{"id":"1.232239000","rc":[{"batb":[[0,12.5,5],[1,3.85,3.6],[2,3.2,2]],"ltp":13.0,"tv":24.42,"id":60971786}]}]}
{"op":"mcm","clk":"11959904758","pt":1724584453629,"mc":[{"id":"1.232239000","rc":[{"batb":[[0,13,5],[1,12.5,5],[2,3.85,3.6]],"ltp":13.0,"tv":24.42,"id":60971786}]}]}
{"op":"mcm","clk":"11959905350","pt":1724584456836,"mc":[{"id":"1.232239000","rc":[{"batb":[[0,12.5,5],[1,3.85,3.6],[2,3.2,2]],"ltp":13.0,"tv":24.42,"id":60971786}]}]}
{"op":"mcm","clk":"11959905877","pt":1724584459226,"mc":[{"id":"1.232239000","rc":[{"batb":[[0,13,5],[1,12.5,5],[2,3.85,3.6]],"ltp":13.0,"tv":24.42,"id":60971786}]}]}
{"op":"mcm","clk":"11959906484","pt":1724584462460,"mc":[{"id":"1.232239000","rc":[{"batb":[[0,12.5,5],[1,3.85,3.6],[2,3.2,2]],"ltp":13.0,"tv":24.42,"id":60971786}]}]}
{"op":"mcm","clk":"11959909181","pt":1724584475899,"mc":[{"id":"1.232239000","rc":[{"batb":[[0,13,5],[1,12.5,5],[2,3.85,3.6]],"ltp":13.0,"tv":24.42,"id":60971786}]}]}
{"op":"mcm","clk":"11959909926","pt":1724584479277,"mc":[{"id":"1.232239000","rc":[{"batb":[[0,12.5,5],[1,3.85,3.6],[2,3.2,2]],"ltp":13.0,"tv":24.42,"id":60971786}]}]}
{"op":"mcm","clk":"11959910440","pt":1724584481957,"mc":[{"id":"1.232239000","rc":[{"batb":[[0,13,5],[1,12.5,5],[2,3.85,3.6]],"ltp":13.0,"tv":24.42,"id":60971786}]}]}
{"op":"mcm","clk":"11959911108","pt":1724584485255,"mc":[{"id":"1.232239000","rc":[{"batb":[[0,12.5,5],[1,3.85,3.6],[2,3.2,2]],"ltp":13.0,"tv":24.42,"id":60971786}]}]}
{"op":"mcm","clk":"11959914030","pt":1724584500077,"mc":[{"id":"1.232239000","rc":[{"batb":[[0,13,5],[1,12.5,5],[2,3.85,3.6]],"ltp":13.0,"tv":24.42,"id":60971786}]}]}
{"op":"mcm","clk":"11959914763","pt":1724584503377,"mc":[{"id":"1.232239000","rc":[{"batb":[[0,12.5,5],[1,3.85,3.6],[2,3.2,2]],"ltp":13.0,"tv":24.42,"id":60971786}]}]}
{"op":"mcm","clk":"11959916327","pt":1724584510486,"mc":[{"id":"1.232239000","rc":[{"batb":[[0,13,5],[1,12.5,5],[2,3.85,3.6]],"ltp":13.0,"tv":24.42,"id":60971786}]}]}
{"op":"mcm","clk":"11959917062","pt":1724584513669,"mc":[{"id":"1.232239000","rc":[{"batb":[[0,12.5,5],[1,3.85,3.6],[2,3.2,2]],"ltp":13.0,"tv":24.42,"id":60971786}]}]}
{"op":"mcm","clk":"11959917737","pt":1724584516787,"mc":[{"id":"1.232239000","rc":[{"batb":[[0,13,5],[1,12.5,5],[2,3.85,3.6]],"ltp":13.0,"tv":24.42,"id":60971786}]}]}
{"op":"mcm","clk":"11959918475","pt":1724584520089,"mc":[{"id":"1.232239000","rc":[{"batb":[[0,12.5,5],[1,3.85,3.6],[2,3.2,2]],"ltp":13.0,"tv":24.42,"id":60971786}]}]}
{"op":"mcm","clk":"11959919514","pt":1724584524711,"mc":[{"id":"1.232239000","rc":[{"batb":[[0,13,5],[1,12.5,5],[2,3.85,3.6]],"ltp":13.0,"tv":24.42,"id":60971786}]}]}
{"op":"mcm","clk":"11959920154","pt":1724584527907,"mc":[{"id":"1.232239000","rc":[{"batb":[[0,12.5,5],[1,3.85,3.6],[2,3.2,2]],"ltp":13.0,"tv":24.42,"id":60971786}]}]}
{"op":"mcm","clk":"11959920820","pt":1724584531111,"mc":[{"id":"1.232239000","rc":[{"batb":[[0,13,5],[1,12.5,5],[2,3.85,3.6]],"ltp":13.0,"tv":24.42,"id":60971786}]}]}
{"op":"mcm","clk":"11959921442","pt":1724584534518,"mc":[{"id":"1.232239000","rc":[{"batb":[[0,12.5,5],[1,3.85,3.6],[2,3.2,2]],"ltp":13.0,"tv":24.42,"id":60971786}]}]}
{"op":"mcm","clk":"11959922135","pt":1724584538191,"mc":[{"id":"1.232239000","rc":[{"batb":[[0,13,5],[1,12.5,5],[2,3.85,3.6]],"ltp":13.0,"tv":24.42,"id":60971786}]}]}
{"op":"mcm","clk":"11959922808","pt":1724584541491,"mc":[{"id":"1.232239000","rc":[{"batb":[[0,12.5,5],[1,3.85,3.6],[2,3.2,2]],"ltp":13.0,"tv":24.42,"id":60971786}]}]}
{"op":"mcm","clk":"11959925053","pt":1724584553306,"mc":[{"id":"1.232239000","rc":[{"batb":[[0,13,5],[1,12.5,5],[2,3.85,3.6]],"ltp":13.0,"tv":24.42,"id":60971786}]}]}
{"op":"mcm","clk":"11959925689","pt":1724584556648,"mc":[{"id":"1.232239000","rc":[{"batb":[[0,12.5,5],[1,3.85,3.6],[2,3.2,2]],"ltp":13.0,"tv":24.42,"id":60971786}]}]}
{"op":"mcm","clk":"11959926482","pt":1724584560724,"mc":[{"id":"1.232239000","rc":[{"batb":[[0,13,5],[1,12.5,5],[2,3.85,3.6]],"ltp":13.0,"tv":24.42,"id":60971786}]}]}
{"op":"mcm","clk":"11959927216","pt":1724584564154,"mc":[{"id":"1.232239000","rc":[{"batb":[[0,12.5,5],[1,3.85,3.6],[2,3.2,2]],"ltp":13.0,"tv":24.42,"id":60971786}]}]}
{"op":"mcm","clk":"11959928109","pt":1724584568349,"mc":[{"id":"1.232239000","rc":[{"batb":[[0,13,5],[1,12.5,5],[2,3.85,3.6]],"ltp":13.0,"tv":24.42,"id":60971786}]}]}
{"op":"mcm","clk":"11959928748","pt":1724584571754,"mc":[{"id":"1.232239000","rc":[{"batb":[[0,12.5,5],[1,3.85,3.6],[2,3.2,2]],"ltp":13.0,"tv":24.42,"id":60971786}]}]}
{"op":"mcm","clk":"11959929336","pt":1724584575144,"mc":[{"id":"1.232239000","rc":[{"batb":[[0,13,5],[1,12.5,5],[2,3.85,3.6]],"ltp":13.0,"tv":24.42,"id":60971786}]}]}
{"op":"mcm","clk":"11959930015","pt":1724584578463,"mc":[{"id":"1.232239000","rc":[{"batb":[[0,12.5,5],[1,3.85,3.6],[2,3.2,2]],"ltp":13.0,"tv":24.42,"id":60971786}]}]}
{"op":"mcm","clk":"11959930056","pt":1724584578661,"mc":[{"id":"1.232239000","rc":[{"trd":[[1.07,10.7]],"batb":[[0,1.07,36.54]],"ltp":1.07,"tv":1580.68,"id":24640635}],"tv":1605.11}]}
{"op":"mcm","clk":"11959930489","pt":1724584580868,"mc":[{"id":"1.232239000","rc":[{"batb":[[0,13,5],[1,12.5,5],[2,3.85,3.6]],"ltp":13.0,"tv":24.42,"id":60971786}]}]}
{"op":"mcm","clk":"11959931171","pt":1724584584172,"mc":[{"id":"1.232239000","rc":[{"batb":[[0,12.5,5],[1,3.85,3.6],[2,3.2,2]],"ltp":13.0,"tv":24.42,"id":60971786}]}]}
{"op":"mcm","clk":"11959931881","pt":1724584587891,"mc":[{"id":"1.232239000","rc":[{"batb":[[0,13,5],[1,12.5,5],[2,3.85,3.6]],"ltp":13.0,"tv":24.42,"id":60971786}]}]}
{"op":"mcm","clk":"11959932564","pt":1724584591182,"mc":[{"id":"1.232239000","rc":[{"batb":[[0,12.5,5],[1,3.85,3.6],[2,3.2,2]],"ltp":13.0,"tv":24.42,"id":60971786}]}]}
{"op":"mcm","clk":"11959933457","pt":1724584595879,"mc":[{"id":"1.232239000","rc":[{"batb":[[0,13,5],[1,12.5,5],[2,3.85,3.6]],"ltp":13.0,"tv":24.42,"id":60971786}]}]}
{"op":"mcm","clk":"11959934105","pt":1724584599217,"mc":[{"id":"1.232239000","rc":[{"batb":[[0,12.5,5],[1,3.85,3.6],[2,3.2,2]],"ltp":13.0,"tv":24.42,"id":60971786}]}]}
{"op":"mcm","clk":"11959935079","pt":1724584604183,"mc":[{"id":"1.232239000","rc":[{"batb":[[0,13,5],[1,12.5,5],[2,3.85,3.6]],"ltp":13.0,"tv":24.42,"id":60971786}]}]}
{"op":"mcm","clk":"11959935764","pt":1724584607579,"mc":[{"id":"1.232239000","rc":[{"batb":[[0,12.5,5],[1,3.85,3.6],[2,3.2,2]],"ltp":13.0,"tv":24.42,"id":60971786}]}]}
{"op":"mcm","clk":"11959936526","pt":1724584611412,"mc":[{"id":"1.232239000","rc":[{"batb":[[0,13,5],[1,12.5,5],[2,3.85,3.6]],"ltp":13.0,"tv":24.42,"id":60971786}]}]}
{"op":"mcm","clk":"11959937149","pt":1724584614811,"mc":[{"id":"1.232239000","rc":[{"batb":[[0,12.5,5],[1,3.85,3.6],[2,3.2,2]],"ltp":13.0,"tv":24.42,"id":60971786}]}]}
{"op":"mcm","clk":"11959938233","pt":1724584620228,"mc":[{"id":"1.232239000","rc":[{"batb":[[0,13,5],[1,12.5,5],[2,3.85,3.6]],"ltp":13.0,"tv":24.42,"id":60971786}]}]}
{"op":"mcm","clk":"11959938950","pt":1724584623625,"mc":[{"id":"1.232239000","rc":[{"batb":[[0,12.5,5],[1,3.85,3.6],[2,3.2,2]],"ltp":13.0,"tv":24.42,"id":60971786}]}]}
{"op":"mcm","clk":"11959940301","pt":1724584630156,"mc":[{"id":"1.232239000","rc":[{"batb":[[0,13,5],[1,12.5,5],[2,3.85,3.6]],"ltp":13.0,"tv":24.42,"id":60971786}]}]}
{"op":"mcm","clk":"11959941062","pt":1724584633417,"mc":[{"id":"1.232239000","rc":[{"batb":[[0,12.5,5],[1,3.85,3.6],[2,3.2,2]],"ltp":13.0,"tv":24.42,"id":60971786}]}]}
{"op":"mcm","clk":"11959941757","pt":1724584637058,"mc":[{"id":"1.232239000","rc":[{"batb":[[0,13,5],[1,12.5,5],[2,3.85,3.6]],"ltp":13.0,"tv":24.42,"id":60971786}]}]}
{"op":"mcm","clk":"11959942441","pt":1724584640434,"mc":[{"id":"1.232239000","rc":[{"batb":[[0,12.5,5],[1,3.85,3.6],[2,3.2,2]],"ltp":13.0,"tv":24.42,"id":60971786}]}]}
{"op":"mcm","clk":"11959943201","pt":1724584644029,"mc":[{"id":"1.232239000","rc":[{"batb":[[0,13,5],[1,12.5,5],[2,3.85,3.6]],"ltp":13.0,"tv":24.42,"id":60971786}]}]}
{"op":"mcm","clk":"11959943902","pt":1724584647334,"mc":[{"id":"1.232239000","rc":[{"batb":[[0,12.5,5],[1,3.85,3.6],[2,3.2,2]],"ltp":13.0,"tv":24.42,"id":60971786}]}]}
{"op":"mcm","clk":"11959944574","pt":1724584650836,"mc":[{"id":"1.232239000","rc":[{"batb":[[0,13,5],[1,12.5,5],[2,3.85,3.6]],"ltp":13.0,"tv":24.42,"id":60971786}]}]}
{"op":"mcm","clk":"11959945237","pt":1724584654257,"mc":[{"id":"1.232239000","rc":[{"batb":[[0,12.5,5],[1,3.85,3.6],[2,3.2,2]],"ltp":13.0,"tv":24.42,"id":60971786}]}]}
{"op":"mcm","clk":"11959945774","pt":1724584657049,"mc":[{"id":"1.232239000","rc":[{"batb":[[0,13,5],[1,12.5,5],[2,3.85,3.6]],"ltp":13.0,"tv":24.42,"id":60971786}]}]}
{"op":"mcm","clk":"11959946335","pt":1724584660381,"mc":[{"id":"1.232239000","rc":[{"batb":[[0,12.5,5],[1,3.85,3.6],[2,3.2,2]],"ltp":13.0,"tv":24.42,"id":60971786}]}]}
{"op":"mcm","clk":"11959947764","pt":1724584667583,"mc":[{"id":"1.232239000","rc":[{"batb":[[0,13,5],[1,12.5,5],[2,3.85,3.6]],"ltp":13.0,"tv":24.42,"id":60971786}]}]}
{"op":"mcm","clk":"11959948357","pt":1724584670887,"mc":[{"id":"1.232239000","rc":[{"batb":[[0,12.5,5],[1,3.85,3.6],[2,3.2,2]],"ltp":13.0,"tv":24.42,"id":60971786}]}]}
{"op":"mcm","clk":"11959948909","pt":1724584673792,"mc":[{"id":"1.232239000","rc":[{"batb":[[0,13,5],[1,12.5,5],[2,3.85,3.6]],"ltp":13.0,"tv":24.42,"id":60971786}]}]}
{"op":"mcm","clk":"11959949493","pt":1724584676994,"mc":[{"id":"1.232239000","rc":[{"batb":[[0,12.5,5],[1,3.85,3.6],[2,3.2,2]],"ltp":13.0,"tv":24.42,"id":60971786}]}]}
{"op":"mcm","clk":"11959950056","pt":1724584680069,"mc":[{"id":"1.232239000","rc":[{"batb":[[0,13,5],[1,12.5,5],[2,3.85,3.6]],"ltp":13.0,"tv":24.42,"id":60971786}]}]}
{"op":"mcm","clk":"11959950720","pt":1724584683488,"mc":[{"id":"1.232239000","rc":[{"batb":[[0,12.5,5],[1,3.85,3.6],[2,3.2,2]],"ltp":13.0,"tv":24.42,"id":60971786}]}]}
{"op":"mcm","clk":"11959951168","pt":1724584686118,"mc":[{"id":"1.232239000","rc":[{"batb":[[0,13,5],[1,12.5,5],[2,3.85,3.6]],"ltp":13.0,"tv":24.42,"id":60971786}]}]}
{"op":"mcm","clk":"11959951833","pt":1724584689488,"mc":[{"id":"1.232239000","rc":[{"batb":[[0,12.5,5],[1,3.85,3.6],[2,3.2,2]],"ltp":13.0,"tv":24.42,"id":60971786}]}]}
{"op":"mcm","clk":"11959954111","pt":1724584701295,"mc":[{"id":"1.232239000","rc":[{"batb":[[0,13,5],[1,12.5,5],[2,3.85,3.6]],"ltp":13.0,"tv":24.42,"id":60971786}]}]}
{"op":"mcm","clk":"11959954834","pt":1724584704590,"mc":[{"id":"1.232239000","rc":[{"batb":[[0,12.5,5],[1,3.85,3.6],[2,3.2,2]],"ltp":13.0,"tv":24.42,"id":60971786}]}]}
{"op":"mcm","clk":"11959955289","pt":1724584706798,"mc":[{"id":"1.232239000","rc":[{"batb":[[0,13,5],[1,12.5,5],[2,3.85,3.6]],"ltp":13.0,"tv":24.42,"id":60971786}]}]}
{"op":"mcm","clk":"11959955922","pt":1724584710112,"mc":[{"id":"1.232239000","rc":[{"batb":[[0,12.5,5],[1,3.85,3.6],[2,3.2,2]],"ltp":13.0,"tv":24.42,"id":60971786}]}]}
{"op":"mcm","clk":"11959958171","pt":1724584722317,"mc":[{"id":"1.232239000","rc":[{"batb":[[0,13,5],[1,12.5,5],[2,3.85,3.6]],"ltp":13.0,"tv":24.42,"id":60971786}]}]}
{"op":"mcm","clk":"11959958758","pt":1724584725638,"mc":[{"id":"1.232239000","rc":[{"batb":[[0,12.5,5],[1,3.85,3.6],[2,3.2,2]],"ltp":13.0,"tv":24.42,"id":60971786}]}]}
{"op":"mcm","clk":"11959959353","pt":1724584728728,"mc":[{"id":"1.232239000","rc":[{"batb":[[0,13,5],[1,12.5,5],[2,3.85,3.6]],"ltp":13.0,"tv":24.42,"id":60971786}]}]}
{"op":"mcm","clk":"11959960023","pt":1724584732038,"mc":[{"id":"1.232239000","rc":[{"batb":[[0,12.5,5],[1,3.85,3.6],[2,3.2,2]],"ltp":13.0,"tv":24.42,"id":60971786}]}]}
{"op":"mcm","clk":"11959960937","pt":1724584736735,"mc":[{"id":"1.232239000","rc":[{"batb":[[0,13,5],[1,12.5,5],[2,3.85,3.6]],"ltp":13.0,"tv":24.42,"id":60971786}]}]}
{"op":"mcm","clk":"11959961612","pt":1724584740132,"mc":[{"id":"1.232239000","rc":[{"batb":[[0,12.5,5],[1,3.85,3.6],[2,3.2,2]],"ltp":13.0,"tv":24.42,"id":60971786}]}]}
{"op":"mcm","clk":"11959964129","pt":1724584751965,"mc":[{"id":"1.232239000","rc":[{"batb":[[0,13,5],[1,12.5,5],[2,3.85,3.6]],"ltp":13.0,"tv":24.42,"id":60971786}]}]}
{"op":"mcm","clk":"11959964851","pt":1724584755260,"mc":[{"id":"1.232239000","rc":[{"batb":[[0,12.5,5],[1,3.85,3.6],[2,3.2,2]],"ltp":13.0,"tv":24.42,"id":60971786}]}]}
{"op":"mcm","clk":"11959967470","pt":1724584768271,"mc":[{"id":"1.232239000","rc":[{"batb":[[0,13,5],[1,12.5,5],[2,3.85,3.6]],"ltp":13.0,"tv":24.42,"id":60971786}]}]}
{"op":"mcm","clk":"11959968188","pt":1724584771588,"mc":[{"id":"1.232239000","rc":[{"batb":[[0,12.5,5],[1,3.85,3.6],[2,3.2,2]],"ltp":13.0,"tv":24.42,"id":60971786}]}]}
{"op":"mcm","clk":"11959969475","pt":1724584777876,"mc":[{"id":"1.232239000","rc":[{"batb":[[0,13,5],[1,12.5,5],[2,3.85,3.6]],"ltp":13.0,"tv":24.42,"id":60971786}]}]}
{"op":"mcm","clk":"11959970092","pt":1724584781275,"mc":[{"id":"1.232239000","rc":[{"batb":[[0,12.5,5],[1,3.85,3.6],[2,3.2,2]],"ltp":13.0,"tv":24.42,"id":60971786}]}]}
{"op":"mcm","clk":"11959971530","pt":1724584788709,"mc":[{"id":"1.232239000","rc":[{"batb":[[0,13,5],[1,12.5,5],[2,3.85,3.6]],"ltp":13.0,"tv":24.42,"id":60971786}]}]}
{"op":"mcm","clk":"11959972195","pt":1724584792014,"mc":[{"id":"1.232239000","rc":[{"batb":[[0,12.5,5],[1,3.85,3.6],[2,3.2,2]],"ltp":13.0,"tv":24.42,"id":60971786}]}]}
{"op":"mcm","clk":"11959974770","pt":1724584803919,"mc":[{"id":"1.232239000","rc":[{"batb":[[0,13,5],[1,12.5,5],[2,3.85,3.6]],"ltp":13.0,"tv":24.42,"id":60971786}]}]}
{"op":"mcm","clk":"11959975461","pt":1724584807241,"mc":[{"id":"1.232239000","rc":[{"batb":[[0,12.5,5],[1,3.85,3.6],[2,3.2,2]],"ltp":13.0,"tv":24.42,"id":60971786}]}]}
{"op":"mcm","clk":"11959975972","pt":1724584809642,"mc":[{"id":"1.232239000","rc":[{"batb":[[0,13,5],[1,12.5,5],[2,3.85,3.6]],"ltp":13.0,"tv":24.42,"id":60971786}]}]}
{"op":"mcm","clk":"11959976654","pt":1724584812912,"mc":[{"id":"1.232239000","rc":[{"batb":[[0,12.5,5],[1,3.85,3.6],[2,3.2,2]],"ltp":13.0,"tv":24.42,"id":60971786}]}]}
{"op":"mcm","clk":"11959977458","pt":1724584816940,"mc":[{"id":"1.232239000","rc":[{"batb":[[0,13,5],[1,12.5,5],[2,3.85,3.6]],"ltp":13.0,"tv":24.42,"id":60971786}]}]}
{"op":"mcm","clk":"11959978088","pt":1724584820231,"mc":[{"id":"1.232239000","rc":[{"batb":[[0,12.5,5],[1,3.85,3.6],[2,3.2,2]],"ltp":13.0,"tv":24.42,"id":60971786}]}]}
{"op":"mcm","clk":"11959978696","pt":1724584823227,"mc":[{"id":"1.232239000","rc":[{"batb":[[0,13,5],[1,12.5,5],[2,3.85,3.6]],"ltp":13.0,"tv":24.42,"id":60971786}]}]}
{"op":"mcm","clk":"11959979362","pt":1724584826431,"mc":[{"id":"1.232239000","rc":[{"batb":[[0,12.5,5],[1,3.85,3.6],[2,3.2,2]],"ltp":13.0,"tv":24.42,"id":60971786}]}]}
{"op":"mcm","clk":"11959981348","pt":1724584835874,"mc":[{"id":"1.232239000","rc":[{"batb":[[0,13,5],[1,12.5,5],[2,3.85,3.6]],"ltp":13.0,"tv":24.42,"id":60971786}]}]}
{"op":"mcm","clk":"11959982075","pt":1724584839143,"mc":[{"id":"1.232239000","rc":[{"batb":[[0,12.5,5],[1,3.85,3.6],[2,3.2,2]],"ltp":13.0,"tv":24.42,"id":60971786}]}]}
