{"op":"mcm","clk":"11829528549","pt":1723378504259,"mc":[{"id":"1.231702167","marketDefinition":{"bspMarket":false,"turnInPlayEnabled":true,"persistenceEnabled":true,"marketBaseRate":5.0,"eventId":"33486139","eventTypeId":"4","numberOfWinners":1,"bettingType":"ODDS","marketType":"MATCH_ODDS","marketTime":"2024-08-14T10:00:00.000Z","suspendTime":"2024-08-14T10:00:00.000Z","bspReconciled":false,"complete":true,"inPlay":false,"crossMatching":false,"runnersVoidable":false,"numberOfActiveRunners":2,"betDelay":0,"status":"OPEN","runners":[{"status":"ACTIVE","sortPriority":1,"id":5901,"name":"Kent"},{"status":"ACTIVE","sortPriority":2,"id":475559,"name":"Northamptonshire"}],"regulators":["MR_INT"],"countryCode":"GB","discountAllowed":false,"timezone":"GMT","openDate":"2024-08-14T10:00:00.000Z","version":6069313034,"name":"Match Odds","eventName":"Kent v Northamptonshire"},"rc":[{"batb":[[0,1.03,200],[1,1.02,200],[2,1.01,220]],"ltp":0.0,"tv":0.0,"id":5901},{"batb":[[0,1.03,200],[1,1.02,200],[2,1.01,220]],"ltp":0.0,"tv":0.0,"id":475559}]}]}
{"op":"mcm","clk":"11829528664","pt":1723378504794,"mc":[{"id":"1.231702167","marketDefinition":{"bspMarket":false,"turnInPlayEnabled":true,"persistenceEnabled":true,"marketBaseRate":5.0,"eventId":"33486139","eventTypeId":"4","numberOfWinners":1,"bettingType":"ODDS","marketType":"MATCH_ODDS","marketTime":"2024-08-14T10:00:00.000Z","suspendTime":"2024-08-14T10:00:00.000Z","bspReconciled":false,"complete":true,"inPlay":false,"crossMatching":false,"runnersVoidable":false,"numberOfActiveRunners":2,"betDelay":0,"status":"OPEN","runners":[{"status":"ACTIVE","sortPriority":1,"id":5901,"name":"Kent"},{"status":"ACTIVE","sortPriority":2,"id":475559,"name":"Northamptonshire"}],"regulators":["MR_INT"],"countryCode":"GB","discountAllowed":true,"timezone":"GMT","openDate":"2024-08-14T10:00:00.000Z","version":6069313034,"name":"Match Odds","eventName":"Kent v Northamptonshire"}}]}
{"op":"mcm","clk":"11830663877","pt":1723384894552,"mc":[{"id":"1.231702167","rc":[{"batb":[[2,1.01,480.71]],"ltp":0.0,"tv":0.0,"id":5901},{"batb":[[2,1.01,480.71]],"ltp":0.0,"tv":0.0,"id":475559}]}]}
{"op":"mcm","clk":"11831089727","pt":1723387213868,"mc":[{"id":"1.231702167","rc":[{"batb":[[2,1.01,488.56]],"ltp":0.0,"tv":0.0,"id":5901},{"batb":[[2,1.01,488.56]],"ltp":0.0,"tv":0.0,"id":475559}]}]}
{"op":"mcm","clk":"11831093085","pt":1723387234266,"mc":[{"id":"1.231702167","marketDefinition":{"bspMarket":false,"turnInPlayEnabled":true,"persistenceEnabled":true,"marketBaseRate":5.0,"eventId":"33486139","eventTypeId":"4","numberOfWinners":1,"bettingType":"ODDS","marketType":"MATCH_ODDS","marketTime":"2024-08-14T10:00:00.000Z","suspendTime":"2024-08-14T10:00:00.000Z","bspReconciled":false,"complete":true,"inPlay":false,"crossMatching":true,"runnersVoidable":false,"numberOfActiveRunners":2,"betDelay":0,"status":"OPEN","runners":[{"status":"ACTIVE","sortPriority":1,"id":5901,"name":"Kent"},{"status":"ACTIVE","sortPriority":2,"id":475559,"name":"Northamptonshire"}],"regulators":["MR_INT"],"countryCode":"GB","discountAllowed":true,"timezone":"GMT","openDate":"2024-08-14T10:00:00.000Z","version":6069313034,"name":"Match Odds","eventName":"Kent v Northamptonshire"}}]}
{"op":"mcm","clk":"11831095248","pt":1723387247593,"mc":[{"id":"1.231702167","rc":[{"batb":[[1,1.02,207.85]],"ltp":0.0,"tv":0.0,"id":5901},{"batb":[[1,1.02,207.85]],"ltp":0.0,"tv":0.0,"id":475559}]}]}
{"op":"mcm","clk":"11831097291","pt":1723387259277,"mc":[{"id":"1.231702167","rc":[{"batb":[[1,1.02,247.13]],"ltp":0.0,"tv":0.0,"id":5901},{"batb":[[1,1.02,247.13]],"ltp":0.0,"tv":0.0,"id":475559}]}]}
{"op":"mcm","clk":"11831100330","pt":1723387276497,"mc":[{"id":"1.231702167","rc":[{"batb":[[0,1.03,207.85]],"ltp":0.0,"tv":0.0,"id":5901},{"batb":[[0,1.03,207.85]],"ltp":0.0,"tv":0.0,"id":475559}]}]}
{"op":"mcm","clk":"11831103025","pt":1723387290898,"mc":[{"id":"1.231702167","rc":[{"batb":[[0,1.04,7.85],[1,1.03,207.85],[2,1.02,247.13]],"ltp":0.0,"tv":0.0,"id":5901},{"batb":[[0,1.04,7.85],[1,1.03,207.85],[2,1.02,247.13]],"ltp":0.0,"tv":0.0,"id":475559}]}]}
{"op":"mcm","clk":"11831105222","pt":1723387303418,"mc":[{"id":"1.231702167","rc":[{"batb":[[0,1.05,7.85],[1,1.04,7.85],[2,1.03,207.85]],"ltp":0.0,"tv":0.0,"id":5901},{"batb":[[0,1.05,7.85],[1,1.04,7.85],[2,1.03,207.85]],"ltp":0.0,"tv":0.0,"id":475559}]}]}
{"op":"mcm","clk":"11831107851","pt":1723387318413,"mc":[{"id":"1.231702167","rc":[{"batb":[[0,1.06,7.85],[1,1.05,7.85],[2,1.04,7.85]],"ltp":0.0,"tv":0.0,"id":5901},{"batb":[[0,1.06,7.85],[1,1.05,7.85],[2,1.04,7.85]],"ltp":0.0,"tv":0.0,"id":475559}]}]}
{"op":"mcm","clk":"11831109914","pt":1723387331225,"mc":[{"id":"1.231702167","rc":[{"batb":[[0,1.07,7.85],[1,1.06,7.85],[2,1.05,7.85]],"ltp":0.0,"tv":0.0,"id":5901},{"batb":[[0,1.07,7.85],[1,1.06,7.85],[2,1.05,7.85]],"ltp":0.0,"tv":0.0,"id":475559}]}]}
{"op":"mcm","clk":"11831112211","pt":1723387345359,"mc":[{"id":"1.231702167","rc":[{"batb":[[0,1.08,7.85],[1,1.07,7.85],[2,1.06,7.85]],"ltp":0.0,"tv":0.0,"id":5901},{"batb":[[0,1.08,7.85],[1,1.07,7.85],[2,1.06,7.85]],"ltp":0.0,"tv":0.0,"id":475559}]}]}
{"op":"mcm","clk":"11832013529","pt":1723392490150,"mc":[{"id":"1.231702167","rc":[{"batb":[[0,1.09,95.53],[1,1.08,7.85],[2,1.07,7.85]],"ltp":0.0,"tv":0.0,"id":5901},{"batb":[[0,1.09,95.53],[1,1.08,7.85],[2,1.07,7.85]],"ltp":0.0,"tv":0.0,"id":475559}]}]}
{"op":"mcm","clk":"11832317278","pt":1723394291685,"mc":[{"id":"1.231702167","rc":[{"batb":[[0,1.08,7.85],[1,1.07,7.85],[2,1.06,7.85]],"ltp":0.0,"tv":0.0,"id":5901},{"batb":[[0,1.08,7.85],[1,1.07,7.85],[2,1.06,7.85]],"ltp":0.0,"tv":0.0,"id":475559}]}]}
{"op":"mcm","clk":"11832326437","pt":1723394343179,"mc":[{"id":"1.231702167","rc":[{"batb":[[0,1.09,95.53],[1,1.08,7.85],[2,1.07,7.85]],"ltp":0.0,"tv":0.0,"id":5901},{"batb":[[0,1.09,95.53],[1,1.08,7.85],[2,1.07,7.85]],"ltp":0.0,"tv":0.0,"id":475559}]}]}
{"op":"mcm","clk":"11832607621","pt":1723396144506,"mc":[{"id":"1.231702167","rc":[{"batb":[[0,1.08,7.85],[1,1.07,7.85],[2,1.06,7.85]],"ltp":0.0,"tv":0.0,"id":475559}]}]}
{"op":"mcm","clk":"11832607664","pt":1723396144820,"mc":[{"id":"1.231702167","rc":[{"batb":[[0,1.08,7.85],[1,1.07,7.85],[2,1.06,7.85]],"ltp":0.0,"tv":0.0,"id":5901}]}]}
{"op":"mcm","clk":"11832612578","pt":1723396177759,"mc":[{"id":"1.231702167","rc":[{"batb":[[0,1.09,95.53],[1,1.08,7.85],[2,1.07,7.85]],"ltp":0.0,"tv":0.0,"id":5901},{"batb":[[0,1.09,95.53],[1,1.08,7.85],[2,1.07,7.85]],"ltp":0.0,"tv":0.0,"id":475559}]}]}
{"op":"mcm","clk":"11832834709","pt":1723397761763,"mc":[{"id":"1.231702167","rc":[{"batb":[[0,1.25,100],[1,1.09,95.53],[2,1.08,7.85]],"ltp":0.0,"tv":0.0,"id":5901},{"batb":[[0,1.25,100],[1,1.09,95.53],[2,1.08,7.85]],"ltp":0.0,"tv":0.0,"id":475559}]}]}
{"op":"mcm","clk":"11832863976","pt":1723397979080,"mc":[{"id":"1.231702167","rc":[{"batb":[[1,1.08,7.85],[2,1.07,7.85]],"ltp":0.0,"tv":0.0,"id":5901},{"batb":[[1,1.08,7.85],[2,1.07,7.85]],"ltp":0.0,"tv":0.0,"id":475559}]}]}
{"op":"mcm","clk":"11832875266","pt":1723398056155,"mc":[{"id":"1.231702167","rc":[{"batb":[[0,1.26,33.07],[1,1.25,100],[2,1.08,7.85]],"ltp":0.0,"tv":0.0,"id":5901},{"batb":[[0,1.26,33.07],[1,1.25,100],[2,1.08,7.85]],"ltp":0.0,"tv":0.0,"id":475559}]}]}
{"op":"mcm","clk":"11832920395","pt":1723398368317,"mc":[{"id":"1.231702167","rc":[{"batb":[[0,1.27,6.65],[1,1.26,33.07],[2,1.25,100]],"ltp":0.0,"tv":0.0,"id":5901},{"batb":[[0,1.27,6.99],[1,1.26,33.07],[2,1.25,100]],"ltp":0.0,"tv":0.0,"id":475559}]}]}
{"op":"mcm","clk":"11833098224","pt":1723399596863,"mc":[{"id":"1.231702167","rc":[{"batb":[[0,1.72,5.59],[1,1.27,6.65],[2,1.26,33.07]],"ltp":0.0,"tv":0.0,"id":5901},{"batb":[[0,2.26,3.19],[1,1.27,6.99],[2,1.26,33.07]],"ltp":0.0,"tv":0.0,"id":475559}]}]}
{"op":"mcm","clk":"11833141184","pt":1723399856707,"mc":[{"id":"1.231702167","rc":[{"batb":[[2,1.25,100]],"ltp":0.0,"tv":0.0,"id":5901},{"batb":[[2,1.25,100]],"ltp":0.0,"tv":0.0,"id":475559}]}]}
{"op":"mcm","clk":"11833276610","pt":1723400619600,"mc":[{"id":"1.231702167","rc":[{"batb":[[1,1.25,100],[2,1.08,7.85]],"ltp":0.0,"tv":0.0,"id":5901}]}]}
{"op":"mcm","clk":"11833276681","pt":1723400620013,"mc":[{"id":"1.231702167","rc":[{"batb":[[1,1.25,100],[2,1.08,7.85]],"ltp":0.0,"tv":0.0,"id":475559}]}]}
{"op":"mcm","clk":"11834742066","pt":1723410774918,"mc":[{"id":"1.231702167","rc":[{"batb":[[2,1.08,7.83]],"ltp":0.0,"tv":0.0,"id":5901},{"batb":[[2,1.08,7.83]],"ltp":0.0,"tv":0.0,"id":475559}]}]}
{"op":"mcm","clk":"11835085111","pt":1723416174928,"mc":[{"id":"1.231702167","rc":[{"batb":[[2,1.08,7.84]],"ltp":0.0,"tv":0.0,"id":5901},{"batb":[[2,1.08,7.84]],"ltp":0.0,"tv":0.0,"id":475559}]}]}
{"op":"mcm","clk":"11835386917","pt":1723421574928,"mc":[{"id":"1.231702167","rc":[{"batb":[[2,1.08,7.84]],"ltp":0.0,"tv":0.0,"id":5901},{"batb":[[2,1.08,7.84]],"ltp":0.0,"tv":0.0,"id":475559}]}]}
{"op":"mcm","clk":"11835498814","pt":1723423550109,"mc":[{"id":"1.231702167","rc":[{"trd":[[1.8,0.07]],"ltp":1.8,"tv":0.07,"id":5901},{"trd":[[2.26,0.06]],"batb":[[0,2.26,3.13]],"ltp":2.26,"tv":0.06,"id":475559}],"tv":0.13}]}
{"op":"mcm","clk":"11835498846","pt":1723423550934,"mc":[{"id":"1.231702167","rc":[{"batb":[[0,2.26,3.19]],"ltp":2.26,"tv":0.06,"id":475559}]}]}
{"op":"mcm","clk":"11835594439","pt":1723426974961,"mc":[{"id":"1.231702167","rc":[{"batb":[[2,1.08,7.84]],"ltp":1.8,"tv":0.07,"id":5901},{"batb":[[2,1.08,7.84]],"ltp":2.26,"tv":0.06,"id":475559}]}]}
{"op":"mcm","clk":"11835768913","pt":1723432374961,"mc":[{"id":"1.231702167","rc":[{"batb":[[2,1.08,7.84]],"ltp":1.8,"tv":0.07,"id":5901},{"batb":[[2,1.08,7.84]],"ltp":2.26,"tv":0.06,"id":475559}]}]}
{"op":"mcm","clk":"11835947344","pt":1723437774923,"mc":[{"id":"1.231702167","rc":[{"batb":[[2,1.08,7.84]],"ltp":1.8,"tv":0.07,"id":5901},{"batb":[[2,1.08,7.84]],"ltp":2.26,"tv":0.06,"id":475559}]}]}
{"op":"mcm","clk":"11836108045","pt":1723443174921,"mc":[{"id":"1.231702167","rc":[{"batb":[[2,1.08,7.83]],"ltp":1.8,"tv":0.07,"id":5901},{"batb":[[2,1.08,7.83]],"ltp":2.26,"tv":0.06,"id":475559}]}]}
{"op":"mcm","clk":"11836282634","pt":1723448574942,"mc":[{"id":"1.231702167","rc":[{"batb":[[2,1.08,7.83]],"ltp":1.8,"tv":0.07,"id":5901},{"batb":[[2,1.08,7.83]],"ltp":2.26,"tv":0.06,"id":475559}]}]}
{"op":"mcm","clk":"11836436583","pt":1723453974933,"mc":[{"id":"1.231702167","rc":[{"batb":[[2,1.08,7.83]],"ltp":1.8,"tv":0.07,"id":5901},{"batb":[[2,1.08,7.83]],"ltp":2.26,"tv":0.06,"id":475559}]}]}
{"op":"mcm","clk":"11836494313","pt":1723456102625,"mc":[{"id":"1.231702167","rc":[{"batb":[[0,1.27,188.03]],"ltp":1.8,"tv":0.07,"id":5901},{"batb":[[0,1.53,155.56]],"ltp":2.26,"tv":0.06,"id":475559}]}]}
{"op":"mcm","clk":"11836496428","pt":1723456172579,"mc":[{"id":"1.231702167","rc":[{"batb":[[0,1.28,30.71],[1,1.27,188.03],[2,1.25,100]],"ltp":1.8,"tv":0.07,"id":5901},{"batb":[[0,1.54,15.92],[1,1.53,155.56],[2,1.25,100]],"ltp":2.26,"tv":0.06,"id":475559}]}]}
{"op":"mcm","clk":"11836502521","pt":1723456356019,"mc":[{"id":"1.231702167","rc":[{"batb":[[1,1.25,100],[2,1.08,7.83]],"ltp":1.8,"tv":0.07,"id":5901},{"batb":[[1,1.25,100],[2,1.08,7.83]],"ltp":2.26,"tv":0.06,"id":475559}]}]}
{"op":"mcm","clk":"11836506597","pt":1723456462802,"mc":[{"id":"1.231702167","rc":[{"batb":[[0,1.31,182.2],[1,1.28,30.71],[2,1.25,100]],"ltp":1.8,"tv":0.07,"id":5901},{"batb":[[0,1.55,153.52],[1,1.54,15.92],[2,1.25,100]],"ltp":2.26,"tv":0.06,"id":475559}]}]}
{"op":"mcm","clk":"11836521889","pt":1723456878422,"mc":[{"id":"1.231702167","rc":[{"batb":[[0,1.32,6.55],[1,1.31,182.2],[2,1.28,30.74]],"ltp":1.8,"tv":0.07,"id":5901},{"batb":[[0,1.56,7.55],[1,1.55,153.52],[2,1.54,15.94]],"ltp":2.26,"tv":0.06,"id":475559}]}]}
{"op":"mcm","clk":"11836534039","pt":1723457199506,"mc":[{"id":"1.231702167","rc":[{"batb":[[1,1.28,30.74],[2,1.25,100]],"ltp":1.8,"tv":0.07,"id":5901},{"batb":[[1,1.54,15.94],[2,1.25,100]],"ltp":2.26,"tv":0.06,"id":475559}]}]}
{"op":"mcm","clk":"11836537882","pt":1723457306327,"mc":[{"id":"1.231702167","rc":[{"batb":[[0,1.35,176.72],[1,1.32,6.55],[2,1.28,30.74]],"ltp":1.8,"tv":0.07,"id":5901},{"batb":[[0,1.58,150.57],[1,1.56,7.55],[2,1.54,15.94]],"ltp":2.26,"tv":0.06,"id":475559}]}]}
{"op":"mcm","clk":"11836544320","pt":1723457464761,"mc":[{"id":"1.231702167","rc":[{"batb":[[0,1.72,56.42],[1,1.35,176.72],[2,1.32,6.55]],"ltp":1.8,"tv":0.07,"id":5901},{"batb":[[0,2.26,32.24],[1,1.58,150.57],[2,1.56,7.55]],"ltp":2.26,"tv":0.06,"id":475559}]}]}
{"op":"mcm","clk":"11836547251","pt":1723457511014,"mc":[{"id":"1.231702167","rc":[{"batb":[[1,1.32,6.55],[2,1.28,30.74]],"ltp":1.8,"tv":0.07,"id":5901},{"batb":[[1,1.56,7.55],[2,1.54,15.94]],"ltp":2.26,"tv":0.06,"id":475559}]}]}
{"op":"mcm","clk":"11836563482","pt":1723457973128,"mc":[{"id":"1.231702167","rc":[{"batb":[[2,1.25,100]],"ltp":1.8,"tv":0.07,"id":5901},{"batb":[[2,1.25,100]],"ltp":2.26,"tv":0.06,"id":475559}]}]}
{"op":"mcm","clk":"11836580173","pt":1723458531484,"mc":[{"id":"1.231702167","rc":[{"batb":[[1,1.25,100],[2,1.08,7.84]],"ltp":1.8,"tv":0.07,"id":5901},{"batb":[[1,1.25,100],[2,1.08,7.84]],"ltp":2.26,"tv":0.06,"id":475559}]}]}
{"op":"mcm","clk":"11836779871","pt":1723464367785,"mc":[{"id":"1.231702167","rc":[{"trd":[[1.8,0.14]],"batb":[[2,1.08,7.83]],"ltp":1.8,"tv":0.14,"id":5901},{"trd":[[2.26,0.12]],"batb":[[0,2.26,32.18],[2,1.08,7.83]],"ltp":2.26,"tv":0.12,"id":475559}],"tv":0.26}]}
{"op":"mcm","clk":"11836780035","pt":1723464372149,"mc":[{"id":"1.231702167","rc":[{"batb":[[0,2.26,32.24]],"ltp":2.26,"tv":0.12,"id":475559}]}]}
{"op":"mcm","clk":"11836826463","pt":1723465567377,"mc":[{"id":"1.231702167","rc":[{"trd":[[1.8,0.21]],"ltp":1.8,"tv":0.21,"id":5901},{"trd":[[2.26,0.18]],"batb":[[0,2.26,32.18]],"ltp":2.26,"tv":0.18,"id":475559}],"tv":0.39}]}
{"op":"mcm","clk":"11836826568","pt":1723465570869,"mc":[{"id":"1.231702167","rc":[{"batb":[[0,2.26,32.24]],"ltp":2.26,"tv":0.18,"id":475559}]}]}
{"op":"mcm","clk":"11836857089","pt":1723466734951,"mc":[{"id":"1.231702167","rc":[{"batb":[[0,1.73,55.65]],"ltp":1.8,"tv":0.21,"id":5901}]}]}
{"op":"mcm","clk":"11836866437","pt":1723467044572,"mc":[{"id":"1.231702167","rc":[{"batb":[[1,1.08,7.83],[2,1.07,7.83]],"ltp":1.8,"tv":0.21,"id":5901},{"batb":[[1,1.08,7.83],[2,1.07,7.83]],"ltp":2.26,"tv":0.18,"id":475559}]}]}
{"op":"mcm","clk":"11836876251","pt":1723467389185,"mc":[{"id":"1.231702167","rc":[{"batb":[[1,1.3,1166.67],[2,1.08,7.83]],"ltp":1.8,"tv":0.21,"id":5901},{"batb":[[1,1.3,1166.67],[2,1.08,7.83]],"ltp":2.26,"tv":0.18,"id":475559}]}]}
{"op":"mcm","clk":"11836878095","pt":1723467458380,"mc":[{"id":"1.231702167","rc":[{"batb":[[1,1.08,7.83],[2,1.07,7.83]],"ltp":1.8,"tv":0.21,"id":5901},{"batb":[[1,1.08,7.83],[2,1.07,7.83]],"ltp":2.26,"tv":0.18,"id":475559}]}]}
{"op":"mcm","clk":"11836878830","pt":1723467486332,"mc":[{"id":"1.231702167","rc":[{"batb":[[1,1.25,100],[2,1.08,7.83]],"ltp":1.8,"tv":0.21,"id":5901},{"batb":[[1,1.25,100],[2,1.08,7.83]],"ltp":2.26,"tv":0.18,"id":475559}]}]}
{"op":"mcm","clk":"11836890863","pt":1723467951013,"mc":[{"id":"1.231702167","rc":[{"trd":[[1.8,0.28]],"batb":[[2,1.08,7.83]],"ltp":1.8,"tv":0.28,"id":5901},{"trd":[[2.26,0.24]],"batb":[[0,2.26,32.18],[2,1.08,7.83]],"ltp":2.26,"tv":0.24,"id":475559}],"tv":0.52}]}
{"op":"mcm","clk":"11836890913","pt":1723467954090,"mc":[{"id":"1.231702167","rc":[{"batb":[[0,2.26,32.24]],"ltp":2.26,"tv":0.24,"id":475559}]}]}
{"op":"mcm","clk":"11836946130","pt":1723469715305,"mc":[{"id":"1.231702167","rc":[{"batb":[[0,1.73,53.07]],"ltp":1.8,"tv":0.28,"id":5901},{"batb":[[0,2.26,30.75]],"ltp":2.26,"tv":0.24,"id":475559}]}]}
{"op":"mcm","clk":"11837164309","pt":1723475574946,"mc":[{"id":"1.231702167","rc":[{"batb":[[2,1.08,7.82]],"ltp":1.8,"tv":0.28,"id":5901},{"batb":[[2,1.08,7.82]],"ltp":2.26,"tv":0.24,"id":475559}]}]}
{"op":"mcm","clk":"11837213847","pt":1723476687093,"mc":[{"id":"1.231702167","rc":[{"trd":[[2.26,8.06]],"batb":[[0,2.26,26.84]],"ltp":2.26,"tv":8.06,"id":475559}],"tv":8.34}]}
{"op":"mcm","clk":"11837213953","pt":1723476689424,"mc":[{"id":"1.231702167","rc":[{"batb":[[0,2.26,30.75]],"ltp":2.26,"tv":8.06,"id":475559}]}]}
{"op":"mcm","clk":"11837215045","pt":1723476718033,"mc":[{"id":"1.231702167","rc":[{"trd":[[1.73,10.22]],"batb":[[0,1.73,47.96]],"ltp":1.73,"tv":10.49,"id":5901}],"tv":18.55}]}
{"op":"mcm","clk":"11837215121","pt":1723476719551,"mc":[{"id":"1.231702167","rc":[{"batb":[[0,1.73,53.07]],"ltp":1.73,"tv":10.49,"id":5901}]}]}
{"op":"mcm","clk":"11837428547","pt":1723480974931,"mc":[{"id":"1.231702167","rc":[{"trd":[[1.73,10.22]],"batb":[[2,1.08,7.83]],"ltp":1.73,"tv":10.5,"id":5901},{"trd":[[2.26,8.06]],"batb":[[2,1.08,7.83]],"ltp":2.26,"tv":8.06,"id":475559}],"tv":18.56}]}
{"op":"mcm","clk":"11837762526","pt":1723485861562,"mc":[{"id":"1.231702167","rc":[{"trd":[[1.73,26.22]],"batb":[[0,1.73,45.07],[2,1.08,7.83]],"ltp":1.73,"tv":26.5,"id":5901},{"trd":[[2.26,8.07]],"batb":[[2,1.08,7.83]],"ltp":2.26,"tv":8.06,"id":475559}],"tv":34.57}]}
{"op":"mcm","clk":"11837762636","pt":1723485862758,"mc":[{"id":"1.231702167","rc":[{"batb":[[0,1.73,53.07]],"ltp":1.73,"tv":26.5,"id":5901}]}]}
{"op":"mcm","clk":"11838263561","pt":1723491774923,"mc":[{"id":"1.231702167","rc":[{"trd":[[1.73,26.22]],"batb":[[2,1.08,7.83]],"ltp":1.73,"tv":26.5,"id":5901},{"batb":[[2,1.08,7.83]],"ltp":2.26,"tv":8.06,"id":475559}],"tv":34.56}]}
{"op":"mcm","clk":"11838491821","pt":1723497174929,"mc":[{"id":"1.231702167","rc":[{"trd":[[1.73,26.23]],"batb":[[2,1.08,7.83]],"ltp":1.73,"tv":26.5,"id":5901},{"trd":[[2.26,8.07]],"batb":[[2,1.08,7.83]],"ltp":2.26,"tv":8.06,"id":475559}],"tv":34.57}]}
{"op":"mcm","clk":"11838732311","pt":1723502574947,"mc":[{"id":"1.231702167","rc":[{"batb":[[2,1.08,7.83]],"ltp":1.73,"tv":26.5,"id":5901},{"batb":[[2,1.08,7.83]],"ltp":2.26,"tv":8.06,"id":475559}],"tv":34.57}]}
{"op":"mcm","clk":"11839068657","pt":1723507975000,"mc":[{"id":"1.231702167","rc":[{"batb":[[2,1.08,7.83]],"ltp":1.73,"tv":26.5,"id":5901},{"batb":[[2,1.08,7.83]],"ltp":2.26,"tv":8.06,"id":475559}],"tv":34.56}]}
{"op":"mcm","clk":"11839273090","pt":1723513375002,"mc":[{"id":"1.231702167","rc":[{"batb":[[2,1.08,7.83]],"ltp":1.73,"tv":26.5,"id":5901},{"batb":[[2,1.08,7.83]],"ltp":2.26,"tv":8.06,"id":475559}],"tv":34.57}]}
{"op":"mcm","clk":"11839361275","pt":1723515960495,"mc":[{"id":"1.231702167","rc":[{"trd":[[1.73,26.22],[1.8,0.35]],"batb":[[2,1.08,7.83]],"ltp":1.8,"tv":26.57,"id":5901},{"trd":[[2.26,8.12]],"batb":[[0,2.26,30.69],[2,1.08,7.83]],"ltp":2.26,"tv":8.12,"id":475559}],"tv":34.69}]}
{"op":"mcm","clk":"11839361318","pt":1723515961680,"mc":[{"id":"1.231702167","rc":[{"batb":[[0,2.26,61.44]],"ltp":2.26,"tv":8.12,"id":475559}]}]}
{"op":"mcm","clk":"11839361320","pt":1723515961785,"mc":[{"id":"1.231702167","rc":[{"batb":[[0,2.26,30.75]],"ltp":2.26,"tv":8.12,"id":475559}]}]}
{"op":"mcm","clk":"11839594614","pt":1723524175019,"mc":[{"id":"1.231702167","rc":[{"batb":[[2,1.08,7.83]],"ltp":1.8,"tv":26.57,"id":5901},{"batb":[[2,1.08,7.83]],"ltp":2.26,"tv":8.12,"id":475559}],"tv":34.69}]}
{"op":"mcm","clk":"11839786751","pt":1723529574994,"mc":[{"id":"1.231702167","rc":[{"trd":[[1.73,26.22]],"batb":[[2,1.08,7.83]],"ltp":1.8,"tv":26.56,"id":5901},{"trd":[[2.26,8.12]],"batb":[[2,1.08,7.83]],"ltp":2.26,"tv":8.12,"id":475559}],"tv":34.69}]}
{"op":"mcm","clk":"11839953457","pt":1723534974977,"mc":[{"id":"1.231702167","rc":[{"trd":[[1.73,26.21]],"batb":[[2,1.08,7.81]],"ltp":1.8,"tv":26.56,"id":5901},{"trd":[[2.26,8.12]],"batb":[[2,1.08,7.81]],"ltp":2.26,"tv":8.11,"id":475559}],"tv":34.67}]}
{"op":"mcm","clk":"11840129093","pt":1723540374958,"mc":[{"id":"1.231702167","rc":[{"trd":[[1.73,26.21]],"batb":[[2,1.08,7.81]],"ltp":1.8,"tv":26.56,"id":5901},{"trd":[[2.26,8.12]],"batb":[[2,1.08,7.81]],"ltp":2.26,"tv":8.11,"id":475559}],"tv":34.67}]}
{"op":"mcm","clk":"11840252063","pt":1723543141638,"mc":[{"id":"1.231702167","rc":[{"trd":[[2.26,64.12]],"batb":[[0,2.26,2.75]],"ltp":2.26,"tv":64.11,"id":475559}],"tv":90.67}]}
{"op":"mcm","clk":"11840252155","pt":1723543143336,"mc":[{"id":"1.231702167","rc":[{"batb":[[0,2.18,32.83]],"ltp":2.26,"tv":64.11,"id":475559}]}]}
{"op":"mcm","clk":"11840399308","pt":1723545774990,"mc":[{"id":"1.231702167","rc":[{"trd":[[1.73,26.21]],"batb":[[2,1.08,7.82]],"ltp":1.8,"tv":26.56,"id":5901},{"trd":[[2.26,64.12]],"batb":[[2,1.08,7.82]],"ltp":2.26,"tv":64.11,"id":475559}],"tv":90.68}]}
{"op":"mcm","clk":"11840432476","pt":1723546384875,"mc":[{"id":"1.231702167","rc":[{"batl":[[0,2.38,1]],"ltp":2.26,"tv":64.11,"id":475559}]}]}
{"op":"mcm","clk":"11840433068","pt":1723546394688,"mc":[{"id":"1.231702167","rc":[{"batb":[[0,1.79,1.42],[1,1.73,53.07],[2,1.25,100]],"ltp":1.8,"tv":26.56,"id":5901}]}]}
{"op":"mcm","clk":"11840433654","pt":1723546404106,"mc":[{"id":"1.231702167","rc":[{"batb":[[0,1.73,53.07],[1,1.25,100],[2,1.08,7.82]],"ltp":1.8,"tv":26.56,"id":5901}]}]}
{"op":"mcm","clk":"11840453365","pt":1723546802517,"mc":[{"id":"1.231702167","rc":[{"batb":[[0,2.2,10],[1,2.18,32.83],[2,1.25,100]],"ltp":2.26,"tv":64.11,"id":475559}]}]}
{"op":"mcm","clk":"11840453639","pt":1723546806425,"mc":[{"id":"1.231702167","rc":[{"trd":[[1.73,26.22]],"batb":[[2,1.08,7.82]],"ltp":1.8,"tv":26.56,"id":5901},{"trd":[[2.26,64.12]],"batb":[[0,2.18,32.83],[1,1.25,100],[2,1.08,7.82]],"ltp":2.26,"tv":64.12,"id":475559}],"tv":90.68}]}
{"op":"mcm","clk":"11840453901","pt":1723546810349,"mc":[{"id":"1.231702167","rc":[{"batb":[[0,2.2,10],[1,2.18,32.83],[2,1.25,100]],"ltp":2.26,"tv":64.12,"id":475559}]}]}
{"op":"mcm","clk":"11840454112","pt":1723546813731,"mc":[{"id":"1.231702167","rc":[{"batb":[[0,2.18,32.83],[1,1.25,100],[2,1.08,7.82]],"ltp":2.26,"tv":64.12,"id":475559}]}]}
{"op":"mcm","clk":"11840454530","pt":1723546819927,"mc":[{"id":"1.231702167","rc":[{"batb":[[0,2.2,10],[1,2.18,32.83],[2,1.25,100]],"ltp":2.26,"tv":64.12,"id":475559}]}]}
{"op":"mcm","clk":"11840454754","pt":1723546823538,"mc":[{"id":"1.231702167","rc":[{"batb":[[0,2.18,32.83],[1,1.25,100],[2,1.08,7.82]],"ltp":2.26,"tv":64.12,"id":475559}]}]}
{"op":"mcm","clk":"11840455102","pt":1723546829336,"mc":[{"id":"1.231702167","rc":[{"batb":[[0,2.2,10],[1,2.18,32.83],[2,1.25,100]],"ltp":2.26,"tv":64.12,"id":475559}]}]}
{"op":"mcm","clk":"11840455314","pt":1723546832583,"mc":[{"id":"1.231702167","rc":[{"batb":[[0,2.18,32.83],[1,1.25,100],[2,1.08,7.82]],"ltp":2.26,"tv":64.12,"id":475559}]}]}
{"op":"mcm","clk":"11840455569","pt":1723546835641,"mc":[{"id":"1.231702167","rc":[{"batb":[[0,2.2,10],[1,2.18,32.83],[2,1.25,100]],"ltp":2.26,"tv":64.12,"id":475559}]}]}
{"op":"mcm","clk":"11840455815","pt":1723546839149,"mc":[{"id":"1.231702167","rc":[{"batb":[[0,2.18,32.83],[1,1.25,100],[2,1.08,7.82]],"ltp":2.26,"tv":64.12,"id":475559}]}]}
{"op":"mcm","clk":"11840456024","pt":1723546842372,"mc":[{"id":"1.231702167","rc":[{"batb":[[0,2.2,10],[1,2.18,32.83],[2,1.25,100]],"ltp":2.26,"tv":64.12,"id":475559}]}]}
{"op":"mcm","clk":"11840456217","pt":1723546845736,"mc":[{"id":"1.231702167","rc":[{"batb":[[0,2.18,32.83],[1,1.25,100],[2,1.08,7.82]],"ltp":2.26,"tv":64.12,"id":475559}]}]}
{"op":"mcm","clk":"11840456495","pt":1723546849461,"mc":[{"id":"1.231702167","rc":[{"batb":[[0,2.2,10],[1,2.18,32.83],[2,1.25,100]],"ltp":2.26,"tv":64.12,"id":475559}]}]}
{"op":"mcm","clk":"11840456683","pt":1723546852868,"mc":[{"id":"1.231702167","rc":[{"batb":[[0,2.18,32.83],[1,1.25,100],[2,1.08,7.82]],"ltp":2.26,"tv":64.12,"id":475559}]}]}
{"op":"mcm","clk":"11840456894","pt":1723546856545,"mc":[{"id":"1.231702167","rc":[{"batb":[[0,2.2,10],[1,2.18,32.83],[2,1.25,100]],"ltp":2.26,"tv":64.12,"id":475559}]}]}
{"op":"mcm","clk":"11840457088","pt":1723546859964,"mc":[{"id":"1.231702167","rc":[{"batb":[[0,2.18,32.83],[1,1.25,100],[2,1.08,7.82]],"ltp":2.26,"tv":64.12,"id":475559}]}]}
{"op":"mcm","clk":"11840457399","pt":1723546865285,"mc":[{"id":"1.231702167","rc":[{"batb":[[0,2.2,10],[1,2.18,32.83],[2,1.25,100]],"ltp":2.26,"tv":64.12,"id":475559}]}]}
{"op":"mcm","clk":"11840457588","pt":1723546868687,"mc":[{"id":"1.231702167","rc":[{"batb":[[0,2.18,32.83],[1,1.25,100],[2,1.08,7.82]],"ltp":2.26,"tv":64.12,"id":475559}]}]}
{"op":"mcm","clk":"11840457806","pt":1723546872978,"mc":[{"id":"1.231702167","rc":[{"batb":[[0,2.2,10],[1,2.18,32.83],[2,1.25,100]],"ltp":2.26,"tv":64.12,"id":475559}]}]}
{"op":"mcm","clk":"11840457965","pt":1723546876477,"mc":[{"id":"1.231702167","rc":[{"batb":[[0,2.18,32.83],[1,1.25,100],[2,1.08,7.82]],"ltp":2.26,"tv":64.12,"id":475559}]}]}
{"op":"mcm","clk":"11840458384","pt":1723546884596,"mc":[{"id":"1.231702167","rc":[{"batb":[[0,2.2,10],[1,2.18,32.83],[2,1.25,100]],"ltp":2.26,"tv":64.12,"id":475559}]}]}
{"op":"mcm","clk":"11840458555","pt":1723546888298,"mc":[{"id":"1.231702167","rc":[{"batb":[[0,2.18,32.83],[1,1.25,100],[2,1.08,7.82]],"ltp":2.26,"tv":64.12,"id":475559}]}]}
{"op":"mcm","clk":"11840458860","pt":1723546894633,"mc":[{"id":"1.231702167","rc":[{"batb":[[0,2.2,10],[1,2.18,32.83],[2,1.25,100]],"ltp":2.26,"tv":64.12,"id":475559}]}]}
{"op":"mcm","clk":"11840459018","pt":1723546898127,"mc":[{"id":"1.231702167","rc":[{"batb":[[0,2.18,32.83],[1,1.25,100],[2,1.08,7.82]],"ltp":2.26,"tv":64.12,"id":475559}]}]}
{"op":"mcm","clk":"11840459309","pt":1723546905640,"mc":[{"id":"1.231702167","rc":[{"batb":[[0,2.2,10],[1,2.18,32.83],[2,1.25,100]],"ltp":2.26,"tv":64.12,"id":475559}]}]}
{"op":"mcm","clk":"11840459438","pt":1723546909021,"mc":[{"id":"1.231702167","rc":[{"batb":[[0,2.18,32.83],[1,1.25,100],[2,1.08,7.82]],"ltp":2.26,"tv":64.12,"id":475559}]}]}
{"op":"mcm","clk":"11840459636","pt":1723546913945,"mc":[{"id":"1.231702167","rc":[{"batb":[[0,2.2,10],[1,2.18,32.83],[2,1.25,100]],"ltp":2.26,"tv":64.12,"id":475559}]}]}
{"op":"mcm","clk":"11840459797","pt":1723546917350,"mc":[{"id":"1.231702167","rc":[{"batb":[[0,2.18,32.83],[1,1.25,100],[2,1.08,7.82]],"ltp":2.26,"tv":64.12,"id":475559}]}]}
{"op":"mcm","clk":"11840459972","pt":1723546921871,"mc":[{"id":"1.231702167","rc":[{"batb":[[0,2.2,10],[1,2.18,32.83],[2,1.25,100]],"ltp":2.26,"tv":64.12,"id":475559}]}]}
{"op":"mcm","clk":"11840460173","pt":1723546926652,"mc":[{"id":"1.231702167","rc":[{"batb":[[0,2.18,32.83],[1,1.25,100],[2,1.08,7.82]],"ltp":2.26,"tv":64.12,"id":475559}]}]}
{"op":"mcm","clk":"11840460364","pt":1723546931736,"mc":[{"id":"1.231702167","rc":[{"batb":[[0,2.2,10],[1,2.18,32.83],[2,1.25,100]],"ltp":2.26,"tv":64.12,"id":475559}]}]}
{"op":"mcm","clk":"11840460496","pt":1723546935278,"mc":[{"id":"1.231702167","rc":[{"batb":[[0,2.18,32.83],[1,1.25,100],[2,1.08,7.82]],"ltp":2.26,"tv":64.12,"id":475559}]}]}
{"op":"mcm","clk":"11840460773","pt":1723546942980,"mc":[{"id":"1.231702167","rc":[{"batb":[[0,2.2,10],[1,2.18,32.83],[2,1.25,100]],"ltp":2.26,"tv":64.12,"id":475559}]}]}
{"op":"mcm","clk":"11840460936","pt":1723546946679,"mc":[{"id":"1.231702167","rc":[{"batb":[[0,2.18,32.83],[1,1.25,100],[2,1.08,7.82]],"ltp":2.26,"tv":64.12,"id":475559}]}]}
{"op":"mcm","clk":"11840461379","pt":1723546957174,"mc":[{"id":"1.231702167","rc":[{"batb":[[0,2.2,10],[1,2.18,32.83],[2,1.25,100]],"ltp":2.26,"tv":64.12,"id":475559}]}]}
{"op":"mcm","clk":"11840461525","pt":1723546960817,"mc":[{"id":"1.231702167","rc":[{"batb":[[0,2.18,32.83],[1,1.25,100],[2,1.08,7.82]],"ltp":2.26,"tv":64.12,"id":475559}]}]}
{"op":"mcm","clk":"11840461769","pt":1723546966800,"mc":[{"id":"1.231702167","rc":[{"batb":[[0,2.2,10],[1,2.18,32.83],[2,1.25,100]],"ltp":2.26,"tv":64.12,"id":475559}]}]}
{"op":"mcm","clk":"11840461905","pt":1723546970199,"mc":[{"id":"1.231702167","rc":[{"batb":[[0,2.18,32.83],[1,1.25,100],[2,1.08,7.82]],"ltp":2.26,"tv":64.12,"id":475559}]}]}
{"op":"mcm","clk":"11840462145","pt":1723546976210,"mc":[{"id":"1.231702167","rc":[{"batb":[[0,2.2,10],[1,2.18,32.83],[2,1.25,100]],"ltp":2.26,"tv":64.12,"id":475559}]}]}
{"op":"mcm","clk":"11840462301","pt":1723546979739,"mc":[{"id":"1.231702167","rc":[{"batb":[[0,2.18,32.83],[1,1.25,100],[2,1.08,7.82]],"ltp":2.26,"tv":64.12,"id":475559}]}]}
{"op":"mcm","clk":"11840462441","pt":1723546982110,"mc":[{"id":"1.231702167","rc":[{"batb":[[0,2.2,10],[1,2.18,32.83],[2,1.25,100]],"ltp":2.26,"tv":64.12,"id":475559}]}]}
{"op":"mcm","clk":"11840462636","pt":1723546985803,"mc":[{"id":"1.231702167","rc":[{"batb":[[0,2.18,32.83],[1,1.25,100],[2,1.08,7.82]],"ltp":2.26,"tv":64.12,"id":475559}]}]}
{"op":"mcm","clk":"11840462766","pt":1723546988730,"mc":[{"id":"1.231702167","rc":[{"batb":[[0,2.2,10],[1,2.18,32.83],[2,1.25,100]],"ltp":2.26,"tv":64.12,"id":475559}]}]}
{"op":"mcm","clk":"11840462893","pt":1723546992327,"mc":[{"id":"1.231702167","rc":[{"batb":[[0,2.18,32.83],[1,1.25,100],[2,1.08,7.82]],"ltp":2.26,"tv":64.12,"id":475559}]}]}
{"op":"mcm","clk":"11840463441","pt":1723547000540,"mc":[{"id":"1.231702167","rc":[{"batb":[[0,2.2,10],[1,2.18,32.83],[2,1.25,100]],"ltp":2.26,"tv":64.12,"id":475559}]}]}
{"op":"mcm","clk":"11840463586","pt":1723547003826,"mc":[{"id":"1.231702167","rc":[{"batb":[[0,2.18,32.83],[1,1.25,100],[2,1.08,7.82]],"ltp":2.26,"tv":64.12,"id":475559}]}]}
{"op":"mcm","clk":"11840463751","pt":1723547007129,"mc":[{"id":"1.231702167","rc":[{"batb":[[0,2.2,10],[1,2.18,32.83],[2,1.25,100]],"ltp":2.26,"tv":64.12,"id":475559}]}]}
{"op":"mcm","clk":"11840463921","pt":1723547010530,"mc":[{"id":"1.231702167","rc":[{"batb":[[0,2.18,32.83],[1,1.25,100],[2,1.08,7.82]],"ltp":2.26,"tv":64.12,"id":475559}]}]}
{"op":"mcm","clk":"11840464162","pt":1723547016132,"mc":[{"id":"1.231702167","rc":[{"batb":[[0,2.2,10],[1,2.18,32.83],[2,1.25,100]],"ltp":2.26,"tv":64.12,"id":475559}]}]}
{"op":"mcm","clk":"11840464281","pt":1723547019731,"mc":[{"id":"1.231702167","rc":[{"batb":[[0,2.18,32.83],[1,1.25,100],[2,1.08,7.82]],"ltp":2.26,"tv":64.12,"id":475559}]}]}
{"op":"mcm","clk":"11840464610","pt":1723547026231,"mc":[{"id":"1.231702167","rc":[{"batb":[[0,2.2,10],[1,2.18,32.83],[2,1.25,100]],"ltp":2.26,"tv":64.12,"id":475559}]}]}
{"op":"mcm","clk":"11840464750","pt":1723547029673,"mc":[{"id":"1.231702167","rc":[{"batb":[[0,2.18,32.83],[1,1.25,100],[2,1.08,7.82]],"ltp":2.26,"tv":64.12,"id":475559}]}]}
{"op":"mcm","clk":"11840465012","pt":1723547036370,"mc":[{"id":"1.231702167","rc":[{"batb":[[0,2.2,10],[1,2.18,32.83],[2,1.25,100]],"ltp":2.26,"tv":64.12,"id":475559}]}]}
{"op":"mcm","clk":"11840465169","pt":1723547039874,"mc":[{"id":"1.231702167","rc":[{"batb":[[0,2.18,32.83],[1,1.25,100],[2,1.08,7.82]],"ltp":2.26,"tv":64.12,"id":475559}]}]}
{"op":"mcm","clk":"11840465304","pt":1723547042867,"mc":[{"id":"1.231702167","rc":[{"batb":[[0,2.2,10],[1,2.18,32.83],[2,1.25,100]],"ltp":2.26,"tv":64.12,"id":475559}]}]}
{"op":"mcm","clk":"11840465451","pt":1723547046172,"mc":[{"id":"1.231702167","rc":[{"batb":[[0,2.18,32.83],[1,1.25,100],[2,1.08,7.82]],"ltp":2.26,"tv":64.12,"id":475559}]}]}
{"op":"mcm","clk":"11840465583","pt":1723547049374,"mc":[{"id":"1.231702167","rc":[{"batb":[[0,2.2,10],[1,2.18,32.83],[2,1.25,100]],"ltp":2.26,"tv":64.12,"id":475559}]}]}
{"op":"mcm","clk":"11840465723","pt":1723547052978,"mc":[{"id":"1.231702167","rc":[{"batb":[[0,2.18,32.83],[1,1.25,100],[2,1.08,7.82]],"ltp":2.26,"tv":64.12,"id":475559}]}]}
{"op":"mcm","clk":"11840465878","pt":1723547056383,"mc":[{"id":"1.231702167","rc":[{"batb":[[0,2.2,10],[1,2.18,32.83],[2,1.25,100]],"ltp":2.26,"tv":64.12,"id":475559}]}]}
{"op":"mcm","clk":"11840466015","pt":1723547059681,"mc":[{"id":"1.231702167","rc":[{"batb":[[0,2.18,32.83],[1,1.25,100],[2,1.08,7.82]],"ltp":2.26,"tv":64.12,"id":475559}]}]}
{"op":"mcm","clk":"11840466148","pt":1723547062310,"mc":[{"id":"1.231702167","rc":[{"batb":[[0,2.2,10],[1,2.18,32.83],[2,1.25,100]],"ltp":2.26,"tv":64.12,"id":475559}]}]}
{"op":"mcm","clk":"11840466332","pt":1723547065815,"mc":[{"id":"1.231702167","rc":[{"batb":[[0,2.18,32.83],[1,1.25,100],[2,1.08,7.82]],"ltp":2.26,"tv":64.12,"id":475559}]}]}
{"op":"mcm","clk":"11840466482","pt":1723547068802,"mc":[{"id":"1.231702167","rc":[{"batb":[[0,2.2,10],[1,2.18,32.83],[2,1.25,100]],"ltp":2.26,"tv":64.12,"id":475559}]}]}
{"op":"mcm","clk":"11840466641","pt":1723547072412,"mc":[{"id":"1.231702167","rc":[{"batb":[[0,2.18,32.83],[1,1.25,100],[2,1.08,7.82]],"ltp":2.26,"tv":64.12,"id":475559}]}]}
{"op":"mcm","clk":"11840466787","pt":1723547075406,"mc":[{"id":"1.231702167","rc":[{"batb":[[0,2.2,10],[1,2.18,32.83],[2,1.25,100]],"ltp":2.26,"tv":64.12,"id":475559}]}]}
{"op":"mcm","clk":"11840466931","pt":1723547078704,"mc":[{"id":"1.231702167","rc":[{"batb":[[0,2.18,32.83],[1,1.25,100],[2,1.08,7.82]],"ltp":2.26,"tv":64.12,"id":475559}]}]}
{"op":"mcm","clk":"11840467127","pt":1723547083315,"mc":[{"id":"1.231702167","rc":[{"batb":[[0,2.2,10],[1,2.18,32.83],[2,1.25,100]],"ltp":2.26,"tv":64.12,"id":475559}]}]}
{"op":"mcm","clk":"11840467273","pt":1723547086518,"mc":[{"id":"1.231702167","rc":[{"batb":[[0,2.18,32.83],[1,1.25,100],[2,1.08,7.82]],"ltp":2.26,"tv":64.12,"id":475559}]}]}
{"op":"mcm","clk":"11840467596","pt":1723547093337,"mc":[{"id":"1.231702167","rc":[{"batb":[[0,2.2,10],[1,2.18,32.83],[2,1.25,100]],"ltp":2.26,"tv":64.12,"id":475559}]}]}
{"op":"mcm","clk":"11840467764","pt":1723547096743,"mc":[{"id":"1.231702167","rc":[{"batb":[[0,2.18,32.83],[1,1.25,100],[2,1.08,7.82]],"ltp":2.26,"tv":64.12,"id":475559}]}]}
{"op":"mcm","clk":"11840468032","pt":1723547102945,"mc":[{"id":"1.231702167","rc":[{"batb":[[0,2.2,10],[1,2.18,32.83],[2,1.25,100]],"ltp":2.26,"tv":64.12,"id":475559}]}]}
{"op":"mcm","clk":"11840468216","pt":1723547106452,"mc":[{"id":"1.231702167","rc":[{"batb":[[0,2.18,32.83],[1,1.25,100],[2,1.08,7.82]],"ltp":2.26,"tv":64.12,"id":475559}]}]}
{"op":"mcm","clk":"11840468459","pt":1723547111841,"mc":[{"id":"1.231702167","rc":[{"batb":[[0,2.2,10],[1,2.18,32.83],[2,1.25,100]],"ltp":2.26,"tv":64.12,"id":475559}]}]}
{"op":"mcm","clk":"11840468644","pt":1723547115347,"mc":[{"id":"1.231702167","rc":[{"batb":[[0,2.18,32.83],[1,1.25,100],[2,1.08,7.82]],"ltp":2.26,"tv":64.12,"id":475559}]}]}
{"op":"mcm","clk":"11840468781","pt":1723547117761,"mc":[{"id":"1.231702167","rc":[{"batb":[[0,2.2,10],[1,2.18,32.83],[2,1.25,100]],"ltp":2.26,"tv":64.12,"id":475559}]}]}
{"op":"mcm","clk":"11840468983","pt":1723547121266,"mc":[{"id":"1.231702167","rc":[{"batb":[[0,2.18,32.83],[1,1.25,100],[2,1.08,7.82]],"ltp":2.26,"tv":64.12,"id":475559}]}]}
{"op":"mcm","clk":"11840469104","pt":1723547123469,"mc":[{"id":"1.231702167","rc":[{"batb":[[0,2.2,10],[1,2.18,32.83],[2,1.25,100]],"ltp":2.26,"tv":64.12,"id":475559}]}]}
{"op":"mcm","clk":"11840469282","pt":1723547127073,"mc":[{"id":"1.231702167","rc":[{"batb":[[0,2.18,32.83],[1,1.25,100],[2,1.08,7.82]],"ltp":2.26,"tv":64.12,"id":475559}]}]}
{"op":"mcm","clk":"11840469397","pt":1723547129669,"mc":[{"id":"1.231702167","rc":[{"batb":[[0,2.2,10],[1,2.18,32.83],[2,1.25,100]],"ltp":2.26,"tv":64.12,"id":475559}]}]}
{"op":"mcm","clk":"11840469556","pt":1723547133283,"mc":[{"id":"1.231702167","rc":[{"batb":[[0,2.18,32.83],[1,1.25,100],[2,1.08,7.82]],"ltp":2.26,"tv":64.12,"id":475559}]}]}
{"op":"mcm","clk":"11840469769","pt":1723547136680,"mc":[{"id":"1.231702167","rc":[{"batb":[[0,2.2,10],[1,2.18,32.83],[2,1.25,100]],"ltp":2.26,"tv":64.12,"id":475559}]}]}
{"op":"mcm","clk":"11840469942","pt":1723547140073,"mc":[{"id":"1.231702167","rc":[{"batb":[[0,2.18,32.83],[1,1.25,100],[2,1.08,7.82]],"ltp":2.26,"tv":64.12,"id":475559}]}]}
{"op":"mcm","clk":"11840470065","pt":1723547142273,"mc":[{"id":"1.231702167","rc":[{"batb":[[0,2.2,10],[1,2.18,32.83],[2,1.25,100]],"ltp":2.26,"tv":64.12,"id":475559}]}]}
{"op":"mcm","clk":"11840470221","pt":1723547145773,"mc":[{"id":"1.231702167","rc":[{"batb":[[0,2.18,32.83],[1,1.25,100],[2,1.08,7.82]],"ltp":2.26,"tv":64.12,"id":475559}]}]}
{"op":"mcm","clk":"11840470388","pt":1723547149366,"mc":[{"id":"1.231702167","rc":[{"batb":[[0,2.2,10],[1,2.18,32.83],[2,1.25,100]],"ltp":2.26,"tv":64.12,"id":475559}]}]}
{"op":"mcm","clk":"11840470540","pt":1723547153005,"mc":[{"id":"1.231702167","rc":[{"batb":[[0,2.18,32.83],[1,1.25,100],[2,1.08,7.82]],"ltp":2.26,"tv":64.12,"id":475559}]}]}
{"op":"mcm","clk":"11840470637","pt":1723547155487,"mc":[{"id":"1.231702167","rc":[{"batb":[[0,2.2,10],[1,2.18,32.83],[2,1.25,100]],"ltp":2.26,"tv":64.12,"id":475559}]}]}
{"op":"mcm","clk":"11840470809","pt":1723547159098,"mc":[{"id":"1.231702167","rc":[{"batb":[[0,2.18,32.83],[1,1.25,100],[2,1.08,7.82]],"ltp":2.26,"tv":64.12,"id":475559}]}]}
{"op":"mcm","clk":"11840470997","pt":1723547162910,"mc":[{"id":"1.231702167","rc":[{"batb":[[0,2.2,10],[1,2.18,32.83],[2,1.25,100]],"ltp":2.26,"tv":64.12,"id":475559}]}]}
{"op":"mcm","clk":"11840471141","pt":1723547166201,"mc":[{"id":"1.231702167","rc":[{"batb":[[0,2.18,32.83],[1,1.25,100],[2,1.08,7.82]],"ltp":2.26,"tv":64.12,"id":475559}]}]}
{"op":"mcm","clk":"11840471289","pt":1723547168714,"mc":[{"id":"1.231702167","rc":[{"batb":[[0,2.2,10],[1,2.18,32.83],[2,1.25,100]],"ltp":2.26,"tv":64.12,"id":475559}]}]}
{"op":"mcm","clk":"11840471433","pt":1723547172110,"mc":[{"id":"1.231702167","rc":[{"batb":[[0,2.18,32.83],[1,1.25,100],[2,1.08,7.82]],"ltp":2.26,"tv":64.12,"id":475559}]}]}
{"op":"mcm","clk":"11840471532","pt":1723547174416,"mc":[{"id":"1.231702167","rc":[{"batb":[[0,2.2,10],[1,2.18,32.83],[2,1.25,100]],"ltp":2.26,"tv":64.12,"id":475559}]}]}
{"op":"mcm","clk":"11840471698","pt":1723547178113,"mc":[{"id":"1.231702167","rc":[{"batb":[[0,2.18,32.83],[1,1.25,100],[2,1.08,7.82]],"ltp":2.26,"tv":64.12,"id":475559}]}]}
{"op":"mcm","clk":"11840471827","pt":1723547181314,"mc":[{"id":"1.231702167","rc":[{"batb":[[0,2.2,10],[1,2.18,32.83],[2,1.25,100]],"ltp":2.26,"tv":64.12,"id":475559}]}]}
{"op":"mcm","clk":"11840471962","pt":1723547184894,"mc":[{"id":"1.231702167","rc":[{"batb":[[0,2.18,32.83],[1,1.25,100],[2,1.08,7.82]],"ltp":2.26,"tv":64.12,"id":475559}]}]}
{"op":"mcm","clk":"11840472075","pt":1723547187716,"mc":[{"id":"1.231702167","rc":[{"batb":[[0,2.2,10],[1,2.18,32.83],[2,1.25,100]],"ltp":2.26,"tv":64.12,"id":475559}]}]}
{"op":"mcm","clk":"11840472251","pt":1723547191218,"mc":[{"id":"1.231702167","rc":[{"batb":[[0,2.18,32.83],[1,1.25,100],[2,1.08,7.82]],"ltp":2.26,"tv":64.12,"id":475559}]}]}
{"op":"mcm","clk":"11840472423","pt":1723547194404,"mc":[{"id":"1.231702167","rc":[{"batb":[[0,2.2,10],[1,2.18,32.83],[2,1.25,100]],"ltp":2.26,"tv":64.12,"id":475559}]}]}
{"op":"mcm","clk":"11840472596","pt":1723547198053,"mc":[{"id":"1.231702167","rc":[{"batb":[[0,2.18,32.83],[1,1.25,100],[2,1.08,7.82]],"ltp":2.26,"tv":64.12,"id":475559}]}]}
{"op":"mcm","clk":"11840472803","pt":1723547202353,"mc":[{"id":"1.231702167","rc":[{"batb":[[0,2.2,10],[1,2.18,32.83],[2,1.25,100]],"ltp":2.26,"tv":64.12,"id":475559}]}]}
{"op":"mcm","clk":"11840472986","pt":1723547205936,"mc":[{"id":"1.231702167","rc":[{"batb":[[0,2.18,32.83],[1,1.25,100],[2,1.08,7.82]],"ltp":2.26,"tv":64.12,"id":475559}]}]}
{"op":"mcm","clk":"11840473109","pt":1723547208662,"mc":[{"id":"1.231702167","rc":[{"batb":[[0,2.2,10],[1,2.18,32.83],[2,1.25,100]],"ltp":2.26,"tv":64.12,"id":475559}]}]}
{"op":"mcm","clk":"11840473249","pt":1723547212161,"mc":[{"id":"1.231702167","rc":[{"batb":[[0,2.18,32.83],[1,1.25,100],[2,1.08,7.82]],"ltp":2.26,"tv":64.12,"id":475559}]}]}
{"op":"mcm","clk":"11840473342","pt":1723547214669,"mc":[{"id":"1.231702167","rc":[{"batb":[[0,2.2,10],[1,2.18,32.83],[2,1.25,100]],"ltp":2.26,"tv":64.12,"id":475559}]}]}
{"op":"mcm","clk":"11840473505","pt":1723547217973,"mc":[{"id":"1.231702167","rc":[{"batb":[[0,2.18,32.83],[1,1.25,100],[2,1.08,7.82]],"ltp":2.26,"tv":64.12,"id":475559}]}]}
{"op":"mcm","clk":"11840473619","pt":1723547220086,"mc":[{"id":"1.231702167","rc":[{"batb":[[0,2.2,10],[1,2.18,32.83],[2,1.25,100]],"ltp":2.26,"tv":64.12,"id":475559}]}]}
{"op":"mcm","clk":"11840473827","pt":1723547223298,"mc":[{"id":"1.231702167","rc":[{"batb":[[0,2.18,32.83],[1,1.25,100],[2,1.08,7.82]],"ltp":2.26,"tv":64.12,"id":475559}]}]}
{"op":"mcm","clk":"11840473992","pt":1723547225884,"mc":[{"id":"1.231702167","rc":[{"batb":[[0,2.2,10],[1,2.18,32.83],[2,1.25,100]],"ltp":2.26,"tv":64.12,"id":475559}]}]}
{"op":"mcm","clk":"11840474179","pt":1723547229088,"mc":[{"id":"1.231702167","rc":[{"batb":[[0,2.18,32.83],[1,1.25,100],[2,1.08,7.82]],"ltp":2.26,"tv":64.12,"id":475559}]}]}
{"op":"mcm","clk":"11840474469","pt":1723547234643,"mc":[{"id":"1.231702167","rc":[{"batb":[[0,2.2,10],[1,2.18,32.83],[2,1.25,100]],"ltp":2.26,"tv":64.12,"id":475559}]}]}
{"op":"mcm","clk":"11840474658","pt":1723547238043,"mc":[{"id":"1.231702167","rc":[{"batb":[[0,2.18,32.83],[1,1.25,100],[2,1.08,7.82]],"ltp":2.26,"tv":64.12,"id":475559}]}]}
{"op":"mcm","clk":"11840474823","pt":1723547241136,"mc":[{"id":"1.231702167","rc":[{"batb":[[0,2.2,10],[1,2.18,32.83],[2,1.25,100]],"ltp":2.26,"tv":64.12,"id":475559}]}]}
{"op":"mcm","clk":"11840475015","pt":1723547244746,"mc":[{"id":"1.231702167","rc":[{"batb":[[0,2.18,32.83],[1,1.25,100],[2,1.08,7.82]],"ltp":2.26,"tv":64.12,"id":475559}]}]}
{"op":"mcm","clk":"11840475190","pt":1723547247532,"mc":[{"id":"1.231702167","rc":[{"batb":[[0,2.2,10],[1,2.18,32.83],[2,1.25,100]],"ltp":2.26,"tv":64.12,"id":475559}]}]}
{"op":"mcm","clk":"11840475396","pt":1723547251142,"mc":[{"id":"1.231702167","rc":[{"batb":[[0,2.18,32.83],[1,1.25,100],[2,1.08,7.82]],"ltp":2.26,"tv":64.12,"id":475559}]}]}
{"op":"mcm","clk":"11840475531","pt":1723547253322,"mc":[{"id":"1.231702167","rc":[{"batb":[[0,2.2,10],[1,2.18,32.83],[2,1.25,100]],"ltp":2.26,"tv":64.12,"id":475559}]}]}
{"op":"mcm","clk":"11840475716","pt":1723547256664,"mc":[{"id":"1.231702167","rc":[{"batb":[[0,2.18,32.83],[1,1.25,100],[2,1.08,7.82]],"ltp":2.26,"tv":64.12,"id":475559}]}]}
{"op":"mcm","clk":"11840476061","pt":1723547263059,"mc":[{"id":"1.231702167","rc":[{"batb":[[0,2.2,10],[1,2.18,32.83],[2,1.25,100]],"ltp":2.26,"tv":64.12,"id":475559}]}]}
{"op":"mcm","clk":"11840476255","pt":1723547266350,"mc":[{"id":"1.231702167","rc":[{"batb":[[0,2.18,32.83],[1,1.25,100],[2,1.08,7.82]],"ltp":2.26,"tv":64.12,"id":475559}]}]}
{"op":"mcm","clk":"11840476409","pt":1723547268828,"mc":[{"id":"1.231702167","rc":[{"batb":[[0,2.2,10],[1,2.18,32.83],[2,1.25,100]],"ltp":2.26,"tv":64.12,"id":475559}]}]}
{"op":"mcm","clk":"11840476620","pt":1723547272342,"mc":[{"id":"1.231702167","rc":[{"batb":[[0,2.18,32.83],[1,1.25,100],[2,1.08,7.82]],"ltp":2.26,"tv":64.12,"id":475559}]}]}
{"op":"mcm","clk":"11840477169","pt":1723547282145,"mc":[{"id":"1.231702167","rc":[{"batb":[[0,2.2,10],[1,2.18,32.83],[2,1.25,100]],"ltp":2.26,"tv":64.12,"id":475559}]}]}
{"op":"mcm","clk":"11840477388","pt":1723547285467,"mc":[{"id":"1.231702167","rc":[{"batb":[[0,2.18,32.83],[1,1.25,100],[2,1.08,7.82]],"ltp":2.26,"tv":64.12,"id":475559}]}]}
{"op":"mcm","clk":"11840477514","pt":1723547287683,"mc":[{"id":"1.231702167","rc":[{"batb":[[0,2.2,10],[1,2.18,32.83],[2,1.25,100]],"ltp":2.26,"tv":64.12,"id":475559}]}]}
{"op":"mcm","clk":"11840477713","pt":1723547290982,"mc":[{"id":"1.231702167","rc":[{"batb":[[0,2.18,32.83],[1,1.25,100],[2,1.08,7.82]],"ltp":2.26,"tv":64.12,"id":475559}]}]}
{"op":"mcm","clk":"11840478118","pt":1723547297700,"mc":[{"id":"1.231702167","rc":[{"batb":[[0,2.2,10],[1,2.18,32.83],[2,1.25,100]],"ltp":2.26,"tv":64.12,"id":475559}]}]}
{"op":"mcm","clk":"11840478324","pt":1723547301200,"mc":[{"id":"1.231702167","rc":[{"batb":[[0,2.18,32.83],[1,1.25,100],[2,1.08,7.82]],"ltp":2.26,"tv":64.12,"id":475559}]}]}
{"op":"mcm","clk":"11840478458","pt":1723547303495,"mc":[{"id":"1.231702167","rc":[{"batb":[[0,2.2,10],[1,2.18,32.83],[2,1.25,100]],"ltp":2.26,"tv":64.12,"id":475559}]}]}
{"op":"mcm","clk":"11840478663","pt":1723547306895,"mc":[{"id":"1.231702167","rc":[{"batb":[[0,2.18,32.83],[1,1.25,100],[2,1.08,7.82]],"ltp":2.26,"tv":64.12,"id":475559}]}]}
{"op":"mcm","clk":"11840478832","pt":1723547309494,"mc":[{"id":"1.231702167","rc":[{"batb":[[0,2.2,10],[1,2.18,32.83],[2,1.25,100]],"ltp":2.26,"tv":64.12,"id":475559}]}]}
{"op":"mcm","clk":"11840479058","pt":1723547312912,"mc":[{"id":"1.231702167","rc":[{"batb":[[0,2.18,32.83],[1,1.25,100],[2,1.08,7.82]],"ltp":2.26,"tv":64.12,"id":475559}]}]}
{"op":"mcm","clk":"11840479380","pt":1723547317110,"mc":[{"id":"1.231702167","rc":[{"batb":[[0,2.2,10],[1,2.18,32.83],[2,1.25,100]],"ltp":2.26,"tv":64.12,"id":475559}]}]}
{"op":"mcm","clk":"11840479570","pt":1723547320677,"mc":[{"id":"1.231702167","rc":[{"batb":[[0,2.18,32.83],[1,1.25,100],[2,1.08,7.82]],"ltp":2.26,"tv":64.12,"id":475559}]}]}
{"op":"mcm","clk":"11840479761","pt":1723547324385,"mc":[{"id":"1.231702167","rc":[{"batb":[[0,2.2,10],[1,2.18,32.83],[2,1.25,100]],"ltp":2.26,"tv":64.12,"id":475559}]}]}
{"op":"mcm","clk":"11840479963","pt":1723547327781,"mc":[{"id":"1.231702167","rc":[{"batb":[[0,2.18,32.83],[1,1.25,100],[2,1.08,7.82]],"ltp":2.26,"tv":64.12,"id":475559}]}]}
{"op":"mcm","clk":"11840480127","pt":1723547330609,"mc":[{"id":"1.231702167","rc":[{"batb":[[0,2.2,10],[1,2.18,32.83],[2,1.25,100]],"ltp":2.26,"tv":64.12,"id":475559}]}]}
{"op":"mcm","clk":"11840480326","pt":1723547334115,"mc":[{"id":"1.231702167","rc":[{"batb":[[0,2.18,32.83],[1,1.25,100],[2,1.08,7.82]],"ltp":2.26,"tv":64.12,"id":475559}]}]}
{"op":"mcm","clk":"11840480490","pt":1723547337422,"mc":[{"id":"1.231702167","rc":[{"batb":[[0,2.2,10],[1,2.18,32.83],[2,1.25,100]],"ltp":2.26,"tv":64.12,"id":475559}]}]}
{"op":"mcm","clk":"11840480682","pt":1723547340726,"mc":[{"id":"1.231702167","rc":[{"batb":[[0,2.18,32.83],[1,1.25,100],[2,1.08,7.82]],"ltp":2.26,"tv":64.12,"id":475559}]}]}
{"op":"mcm","clk":"11840481090","pt":1723547347137,"mc":[{"id":"1.231702167","rc":[{"batb":[[0,2.2,10],[1,2.18,32.83],[2,1.25,100]],"ltp":2.26,"tv":64.12,"id":475559}]}]}
{"op":"mcm","clk":"11840481325","pt":1723547350536,"mc":[{"id":"1.231702167","rc":[{"batb":[[0,2.18,32.83],[1,1.25,100],[2,1.08,7.82]],"ltp":2.26,"tv":64.12,"id":475559}]}]}
{"op":"mcm","clk":"11840481535","pt":1723547354244,"mc":[{"id":"1.231702167","rc":[{"batb":[[0,2.2,10],[1,2.18,32.83],[2,1.25,100]],"ltp":2.26,"tv":64.12,"id":475559}]}]}
{"op":"mcm","clk":"11840481729","pt":1723547357847,"mc":[{"id":"1.231702167","rc":[{"batb":[[0,2.18,32.83],[1,1.25,100],[2,1.08,7.82]],"ltp":2.26,"tv":64.12,"id":475559}]}]}
{"op":"mcm","clk":"11840481951","pt":1723547362227,"mc":[{"id":"1.231702167","rc":[{"batb":[[0,2.2,10],[1,2.18,32.83],[2,1.25,100]],"ltp":2.26,"tv":64.12,"id":475559}]}]}
{"op":"mcm","clk":"11840482139","pt":1723547365737,"mc":[{"id":"1.231702167","rc":[{"batb":[[0,2.18,32.83],[1,1.25,100],[2,1.08,7.82]],"ltp":2.26,"tv":64.12,"id":475559}]}]}
{"op":"mcm","clk":"11840482297","pt":1723547368355,"mc":[{"id":"1.231702167","rc":[{"batb":[[0,2.2,10],[1,2.18,32.83],[2,1.25,100]],"ltp":2.26,"tv":64.12,"id":475559}]}]}
{"op":"mcm","clk":"11840482487","pt":1723547372064,"mc":[{"id":"1.231702167","rc":[{"batb":[[0,2.18,32.83],[1,1.25,100],[2,1.08,7.82]],"ltp":2.26,"tv":64.12,"id":475559}]}]}
{"op":"mcm","clk":"11840482652","pt":1723547374542,"mc":[{"id":"1.231702167","rc":[{"batb":[[0,2.2,10],[1,2.18,32.83],[2,1.25,100]],"ltp":2.26,"tv":64.12,"id":475559}]}]}
{"op":"mcm","clk":"11840482880","pt":1723547377963,"mc":[{"id":"1.231702167","rc":[{"batb":[[0,2.18,32.83],[1,1.25,100],[2,1.08,7.82]],"ltp":2.26,"tv":64.12,"id":475559}]}]}
{"op":"mcm","clk":"11840483046","pt":1723547380541,"mc":[{"id":"1.231702167","rc":[{"batb":[[0,2.2,10],[1,2.18,32.83],[2,1.25,100]],"ltp":2.26,"tv":64.12,"id":475559}]}]}
{"op":"mcm","clk":"11840483253","pt":1723547384043,"mc":[{"id":"1.231702167","rc":[{"batb":[[0,2.18,32.83],[1,1.25,100],[2,1.08,7.82]],"ltp":2.26,"tv":64.12,"id":475559}]}]}
{"op":"mcm","clk":"11840483531","pt":1723547388774,"mc":[{"id":"1.231702167","rc":[{"batb":[[0,2.2,10],[1,2.18,32.83],[2,1.25,100]],"ltp":2.26,"tv":64.12,"id":475559}]}]}
{"op":"mcm","clk":"11840483737","pt":1723547392173,"mc":[{"id":"1.231702167","rc":[{"batb":[[0,2.18,32.83],[1,1.25,100],[2,1.08,7.82]],"ltp":2.26,"tv":64.12,"id":475559}]}]}
{"op":"mcm","clk":"11840484033","pt":1723547397891,"mc":[{"id":"1.231702167","rc":[{"batb":[[0,2.2,10],[1,2.18,32.83],[2,1.25,100]],"ltp":2.26,"tv":64.12,"id":475559}]}]}
{"op":"mcm","clk":"11840484247","pt":1723547401289,"mc":[{"id":"1.231702167","rc":[{"batb":[[0,2.18,32.83],[1,1.25,100],[2,1.08,7.82]],"ltp":2.26,"tv":64.12,"id":475559}]}]}
{"op":"mcm","clk":"11840484459","pt":1723547404590,"mc":[{"id":"1.231702167","rc":[{"batb":[[0,2.2,10],[1,2.18,32.83],[2,1.25,100]],"ltp":2.26,"tv":64.12,"id":475559}]}]}
{"op":"mcm","clk":"11840484697","pt":1723547408203,"mc":[{"id":"1.231702167","rc":[{"batb":[[0,2.18,32.83],[1,1.25,100],[2,1.08,7.82]],"ltp":2.26,"tv":64.12,"id":475559}]}]}
{"op":"mcm","clk":"11840485057","pt":1723547414309,"mc":[{"id":"1.231702167","rc":[{"batb":[[0,2.2,10],[1,2.18,32.83],[2,1.25,100]],"ltp":2.26,"tv":64.12,"id":475559}]}]}
{"op":"mcm","clk":"11840485266","pt":1723547417707,"mc":[{"id":"1.231702167","rc":[{"batb":[[0,2.18,32.83],[1,1.25,100],[2,1.08,7.82]],"ltp":2.26,"tv":64.12,"id":475559}]}]}
{"op":"mcm","clk":"11840485434","pt":1723547420379,"mc":[{"id":"1.231702167","rc":[{"batb":[[0,2.2,10],[1,2.18,32.83],[2,1.25,100]],"ltp":2.26,"tv":64.12,"id":475559}]}]}
{"op":"mcm","clk":"11840485617","pt":1723547423612,"mc":[{"id":"1.231702167","rc":[{"batb":[[0,2.18,32.83],[1,1.25,100],[2,1.08,7.82]],"ltp":2.26,"tv":64.12,"id":475559}]}]}
{"op":"mcm","clk":"11840485991","pt":1723547430710,"mc":[{"id":"1.231702167","rc":[{"batb":[[0,2.2,10],[1,2.18,32.83],[2,1.25,100]],"ltp":2.26,"tv":64.12,"id":475559}]}]}
{"op":"mcm","clk":"11840486188","pt":1723547434208,"mc":[{"id":"1.231702167","rc":[{"batb":[[0,2.18,32.83],[1,1.25,100],[2,1.08,7.82]],"ltp":2.26,"tv":64.12,"id":475559}]}]}
{"op":"mcm","clk":"11840486391","pt":1723547437711,"mc":[{"id":"1.231702167","rc":[{"batb":[[0,2.2,10],[1,2.18,32.83],[2,1.25,100]],"ltp":2.26,"tv":64.12,"id":475559}]}]}
{"op":"mcm","clk":"11840486595","pt":1723547441219,"mc":[{"id":"1.231702167","rc":[{"batb":[[0,2.18,32.83],[1,1.25,100],[2,1.08,7.82]],"ltp":2.26,"tv":64.12,"id":475559}]}]}
{"op":"mcm","clk":"11840486840","pt":1723547445811,"mc":[{"id":"1.231702167","rc":[{"batb":[[0,2.2,10],[1,2.18,32.83],[2,1.25,100]],"ltp":2.26,"tv":64.12,"id":475559}]}]}
{"op":"mcm","clk":"11840487028","pt":1723547449317,"mc":[{"id":"1.231702167","rc":[{"batb":[[0,2.18,32.83],[1,1.25,100],[2,1.08,7.82]],"ltp":2.26,"tv":64.12,"id":475559}]}]}
{"op":"mcm","clk":"11840487236","pt":1723547452823,"mc":[{"id":"1.231702167","rc":[{"batb":[[0,2.2,10],[1,2.18,32.83],[2,1.25,100]],"ltp":2.26,"tv":64.12,"id":475559}]}]}
{"op":"mcm","clk":"11840487419","pt":1723547456327,"mc":[{"id":"1.231702167","rc":[{"batb":[[0,2.18,32.83],[1,1.25,100],[2,1.08,7.82]],"ltp":2.26,"tv":64.12,"id":475559}]}]}
{"op":"mcm","clk":"11840487591","pt":1723547459225,"mc":[{"id":"1.231702167","rc":[{"batb":[[0,2.2,10],[1,2.18,32.83],[2,1.25,100]],"ltp":2.26,"tv":64.12,"id":475559}]}]}
{"op":"mcm","clk":"11840487825","pt":1723547462743,"mc":[{"id":"1.231702167","rc":[{"batb":[[0,2.18,32.83],[1,1.25,100],[2,1.08,7.82]],"ltp":2.26,"tv":64.12,"id":475559}]}]}
{"op":"mcm","clk":"11840488008","pt":1723547465640,"mc":[{"id":"1.231702167","rc":[{"batb":[[0,2.2,10],[1,2.18,32.83],[2,1.25,100]],"ltp":2.26,"tv":64.12,"id":475559}]}]}
{"op":"mcm","clk":"11840488231","pt":1723547469145,"mc":[{"id":"1.231702167","rc":[{"batb":[[0,2.18,32.83],[1,1.25,100],[2,1.08,7.82]],"ltp":2.26,"tv":64.12,"id":475559}]}]}
{"op":"mcm","clk":"11840488395","pt":1723547472343,"mc":[{"id":"1.231702167","rc":[{"batb":[[0,2.2,10],[1,2.18,32.83],[2,1.25,100]],"ltp":2.26,"tv":64.12,"id":475559}]}]}
{"op":"mcm","clk":"11840488586","pt":1723547475837,"mc":[{"id":"1.231702167","rc":[{"batb":[[0,2.18,32.83],[1,1.25,100],[2,1.08,7.82]],"ltp":2.26,"tv":64.12,"id":475559}]}]}
{"op":"mcm","clk":"11840488781","pt":1723547479349,"mc":[{"id":"1.231702167","rc":[{"batb":[[0,2.2,10],[1,2.18,32.83],[2,1.25,100]],"ltp":2.26,"tv":64.12,"id":475559}]}]}
{"op":"mcm","clk":"11840488950","pt":1723547482691,"mc":[{"id":"1.231702167","rc":[{"batb":[[0,2.18,32.83],[1,1.25,100],[2,1.08,7.82]],"ltp":2.26,"tv":64.12,"id":475559}]}]}
{"op":"mcm","clk":"11840489123","pt":1723547485276,"mc":[{"id":"1.231702167","rc":[{"batb":[[0,2.2,10],[1,2.18,32.83],[2,1.25,100]],"ltp":2.26,"tv":64.12,"id":475559}]}]}
{"op":"mcm","clk":"11840489323","pt":1723547488771,"mc":[{"id":"1.231702167","rc":[{"batb":[[0,2.18,32.83],[1,1.25,100],[2,1.08,7.82]],"ltp":2.26,"tv":64.12,"id":475559}]}]}
{"op":"mcm","clk":"11840489461","pt":1723547491095,"mc":[{"id":"1.231702167","rc":[{"batb":[[0,2.2,10],[1,2.18,32.83],[2,1.25,100]],"ltp":2.26,"tv":64.12,"id":475559}]}]}
{"op":"mcm","clk":"11840489666","pt":1723547494560,"mc":[{"id":"1.231702167","rc":[{"batb":[[0,2.18,32.83],[1,1.25,100],[2,1.08,7.82]],"ltp":2.26,"tv":64.12,"id":475559}]}]}
{"op":"mcm","clk":"11840489825","pt":1723547497295,"mc":[{"id":"1.231702167","rc":[{"batb":[[0,2.2,10],[1,2.18,32.83],[2,1.25,100]],"ltp":2.26,"tv":64.12,"id":475559}]}]}
{"op":"mcm","clk":"11840490012","pt":1723547500605,"mc":[{"id":"1.231702167","rc":[{"batb":[[0,2.18,32.83],[1,1.25,100],[2,1.08,7.82]],"ltp":2.26,"tv":64.12,"id":475559}]}]}
{"op":"mcm","clk":"11840490144","pt":1723547502913,"mc":[{"id":"1.231702167","rc":[{"batb":[[0,2.2,10],[1,2.18,32.83],[2,1.25,100]],"ltp":2.26,"tv":64.12,"id":475559}]}]}
{"op":"mcm","clk":"11840490336","pt":1723547506403,"mc":[{"id":"1.231702167","rc":[{"batb":[[0,2.18,32.83],[1,1.25,100],[2,1.08,7.82]],"ltp":2.26,"tv":64.12,"id":475559}]}]}
{"op":"mcm","clk":"11840490511","pt":1723547509492,"mc":[{"id":"1.231702167","rc":[{"batb":[[0,2.2,10],[1,2.18,32.83],[2,1.25,100]],"ltp":2.26,"tv":64.12,"id":475559}]}]}
{"op":"mcm","clk":"11840490749","pt":1723547512893,"mc":[{"id":"1.231702167","rc":[{"batb":[[0,2.18,32.83],[1,1.25,100],[2,1.08,7.82]],"ltp":2.26,"tv":64.12,"id":475559}]}]}
{"op":"mcm","clk":"11840490991","pt":1723547516312,"mc":[{"id":"1.231702167","rc":[{"batb":[[0,2.2,10],[1,2.18,32.83],[2,1.25,100]],"ltp":2.26,"tv":64.12,"id":475559}]}]}
{"op":"mcm","clk":"11840491208","pt":1723547519810,"mc":[{"id":"1.231702167","rc":[{"batb":[[0,2.18,32.83],[1,1.25,100],[2,1.08,7.82]],"ltp":2.26,"tv":64.12,"id":475559}]}]}
{"op":"mcm","clk":"11840491460","pt":1723547524541,"mc":[{"id":"1.231702167","rc":[{"batb":[[0,2.2,10],[1,2.18,32.83],[2,1.25,100]],"ltp":2.26,"tv":64.12,"id":475559}]}]}
{"op":"mcm","clk":"11840491650","pt":1723547527838,"mc":[{"id":"1.231702167","rc":[{"batb":[[0,2.18,32.83],[1,1.25,100],[2,1.08,7.82]],"ltp":2.26,"tv":64.12,"id":475559}]}]}
{"op":"mcm","clk":"11840491867","pt":1723547531031,"mc":[{"id":"1.231702167","rc":[{"batb":[[0,2.2,10],[1,2.18,32.83],[2,1.25,100]],"ltp":2.26,"tv":64.12,"id":475559}]}]}
{"op":"mcm","clk":"11840492081","pt":1723547534532,"mc":[{"id":"1.231702167","rc":[{"batb":[[0,2.18,32.83],[1,1.25,100],[2,1.08,7.82]],"ltp":2.26,"tv":64.12,"id":475559}]}]}
{"op":"mcm","clk":"11840492234","pt":1723547537121,"mc":[{"id":"1.231702167","rc":[{"batb":[[0,2.2,10],[1,2.18,32.83],[2,1.25,100]],"ltp":2.26,"tv":64.12,"id":475559}]}]}
{"op":"mcm","clk":"11840492456","pt":1723547540524,"mc":[{"id":"1.231702167","rc":[{"batb":[[0,2.18,32.83],[1,1.25,100],[2,1.08,7.82]],"ltp":2.26,"tv":64.12,"id":475559}]}]}
{"op":"mcm","clk":"11840492651","pt":1723547544630,"mc":[{"id":"1.231702167","rc":[{"batb":[[0,2.2,10],[1,2.18,32.83],[2,1.25,100]],"ltp":2.26,"tv":64.12,"id":475559}]}]}
{"op":"mcm","clk":"11840492822","pt":1723547548028,"mc":[{"id":"1.231702167","rc":[{"batb":[[0,2.18,32.83],[1,1.25,100],[2,1.08,7.82]],"ltp":2.26,"tv":64.12,"id":475559}]}]}
{"op":"mcm","clk":"11840493037","pt":1723547551627,"mc":[{"id":"1.231702167","rc":[{"batb":[[0,2.2,10],[1,2.18,32.83],[2,1.25,100]],"ltp":2.26,"tv":64.12,"id":475559}]}]}
{"op":"mcm","clk":"11840493289","pt":1723547556452,"mc":[{"id":"1.231702167","rc":[{"batb":[[0,2.18,32.83],[1,1.25,100],[2,1.08,7.82]],"ltp":2.26,"tv":64.12,"id":475559}]}]}
{"op":"mcm","clk":"11840493403","pt":1723547558657,"mc":[{"id":"1.231702167","rc":[{"batb":[[0,2.2,10],[1,2.18,32.83],[2,1.25,100]],"ltp":2.26,"tv":64.12,"id":475559}]}]}
{"op":"mcm","clk":"11840493588","pt":1723547562161,"mc":[{"id":"1.231702167","rc":[{"batb":[[0,2.18,32.83],[1,1.25,100],[2,1.08,7.82]],"ltp":2.26,"tv":64.12,"id":475559}]}]}
{"op":"mcm","clk":"11840493714","pt":1723547564875,"mc":[{"id":"1.231702167","rc":[{"batb":[[0,2.2,10],[1,2.18,32.83],[2,1.25,100]],"ltp":2.26,"tv":64.12,"id":475559}]}]}
{"op":"mcm","clk":"11840493894","pt":1723547568378,"mc":[{"id":"1.231702167","rc":[{"batb":[[0,2.18,32.83],[1,1.25,100],[2,1.08,7.82]],"ltp":2.26,"tv":64.12,"id":475559}]}]}
{"op":"mcm","clk":"11840494215","pt":1723547574080,"mc":[{"id":"1.231702167","rc":[{"batb":[[0,2.2,10],[1,2.18,32.83],[2,1.25,100]],"ltp":2.26,"tv":64.12,"id":475559}]}]}
{"op":"mcm","clk":"11840494372","pt":1723547577552,"mc":[{"id":"1.231702167","rc":[{"batb":[[0,2.18,32.83],[1,1.25,100],[2,1.08,7.82]],"ltp":2.26,"tv":64.12,"id":475559}]}]}
{"op":"mcm","clk":"11840494537","pt":1723547580893,"mc":[{"id":"1.231702167","rc":[{"batb":[[0,2.2,10],[1,2.18,32.83],[2,1.25,100]],"ltp":2.26,"tv":64.12,"id":475559}]}]}
{"op":"mcm","clk":"11840494750","pt":1723547584354,"mc":[{"id":"1.231702167","rc":[{"batb":[[0,2.18,32.83],[1,1.25,100],[2,1.08,7.82]],"ltp":2.26,"tv":64.12,"id":475559}]}]}
{"op":"mcm","clk":"11840495019","pt":1723547589190,"mc":[{"id":"1.231702167","rc":[{"batb":[[0,2.2,10],[1,2.18,32.83],[2,1.25,100]],"ltp":2.26,"tv":64.12,"id":475559}]}]}
{"op":"mcm","clk":"11840495212","pt":1723547593035,"mc":[{"id":"1.231702167","rc":[{"batb":[[0,2.18,32.83],[1,1.25,100],[2,1.08,7.82]],"ltp":2.26,"tv":64.12,"id":475559}]}]}
{"op":"mcm","clk":"11840495315","pt":1723547595349,"mc":[{"id":"1.231702167","rc":[{"batb":[[0,2.2,10],[1,2.18,32.83],[2,1.25,100]],"ltp":2.26,"tv":64.12,"id":475559}]}]}
{"op":"mcm","clk":"11840495524","pt":1723547598857,"mc":[{"id":"1.231702167","rc":[{"batb":[[0,2.18,32.83],[1,1.25,100],[2,1.08,7.82]],"ltp":2.26,"tv":64.12,"id":475559}]}]}
{"op":"mcm","clk":"11840495783","pt":1723547602867,"mc":[{"id":"1.231702167","rc":[{"batb":[[0,2.2,10],[1,2.18,32.83],[2,1.25,100]],"ltp":2.26,"tv":64.12,"id":475559}]}]}
{"op":"mcm","clk":"11840496007","pt":1723547606480,"mc":[{"id":"1.231702167","rc":[{"batb":[[0,2.18,32.83],[1,1.25,100],[2,1.08,7.82]],"ltp":2.26,"tv":64.12,"id":475559}]}]}
{"op":"mcm","clk":"11840496169","pt":1723547609461,"mc":[{"id":"1.231702167","rc":[{"batb":[[0,2.2,10],[1,2.18,32.83],[2,1.25,100]],"ltp":2.26,"tv":64.12,"id":475559}]}]}
{"op":"mcm","clk":"11840496383","pt":1723547613056,"mc":[{"id":"1.231702167","rc":[{"batb":[[0,2.18,32.83],[1,1.25,100],[2,1.08,7.82]],"ltp":2.26,"tv":64.12,"id":475559}]}]}
{"op":"mcm","clk":"11840496517","pt":1723547615278,"mc":[{"id":"1.231702167","rc":[{"batb":[[0,2.2,10],[1,2.18,32.83],[2,1.25,100]],"ltp":2.26,"tv":64.12,"id":475559}]}]}
{"op":"mcm","clk":"11840496720","pt":1723547618779,"mc":[{"id":"1.231702167","rc":[{"batb":[[0,2.18,32.83],[1,1.25,100],[2,1.08,7.82]],"ltp":2.26,"tv":64.12,"id":475559}]}]}
{"op":"mcm","clk":"11840496923","pt":1723547622384,"mc":[{"id":"1.231702167","rc":[{"batb":[[0,2.2,10],[1,2.18,32.83],[2,1.25,100]],"ltp":2.26,"tv":64.12,"id":475559}]}]}
{"op":"mcm","clk":"11840497087","pt":1723547625677,"mc":[{"id":"1.231702167","rc":[{"batb":[[0,2.18,32.83],[1,1.25,100],[2,1.08,7.82]],"ltp":2.26,"tv":64.12,"id":475559}]}]}
{"op":"mcm","clk":"11840497244","pt":1723547628564,"mc":[{"id":"1.231702167","rc":[{"batb":[[0,2.2,10],[1,2.18,32.83],[2,1.25,100]],"ltp":2.26,"tv":64.12,"id":475559}]}]}
{"op":"mcm","clk":"11840497468","pt":1723547632390,"mc":[{"id":"1.231702167","rc":[{"batb":[[0,2.18,32.83],[1,1.25,100],[2,1.08,7.82]],"ltp":2.26,"tv":64.12,"id":475559}]}]}
{"op":"mcm","clk":"11840497687","pt":1723547636203,"mc":[{"id":"1.231702167","rc":[{"batb":[[0,2.2,10],[1,2.18,32.83],[2,1.25,100]],"ltp":2.26,"tv":64.12,"id":475559}]}]}
{"op":"mcm","clk":"11840497922","pt":1723547639823,"mc":[{"id":"1.231702167","rc":[{"batb":[[0,2.18,32.83],[1,1.25,100],[2,1.08,7.82]],"ltp":2.26,"tv":64.12,"id":475559}]}]}
{"op":"mcm","clk":"11840498170","pt":1723547644122,"mc":[{"id":"1.231702167","rc":[{"batb":[[0,2.2,10],[1,2.18,32.83],[2,1.25,100]],"ltp":2.26,"tv":64.12,"id":475559}]}]}
{"op":"mcm","clk":"11840498384","pt":1723547647725,"mc":[{"id":"1.231702167","rc":[{"batb":[[0,2.18,32.83],[1,1.25,100],[2,1.08,7.82]],"ltp":2.26,"tv":64.12,"id":475559}]}]}
{"op":"mcm","clk":"11840498553","pt":1723547650417,"mc":[{"id":"1.231702167","rc":[{"batb":[[0,2.2,10],[1,2.18,32.83],[2,1.25,100]],"ltp":2.26,"tv":64.12,"id":475559}]}]}
{"op":"mcm","clk":"11840498772","pt":1723547654024,"mc":[{"id":"1.231702167","rc":[{"batb":[[0,2.18,32.83],[1,1.25,100],[2,1.08,7.82]],"ltp":2.26,"tv":64.12,"id":475559}]}]}
{"op":"mcm","clk":"11840498971","pt":1723547657536,"mc":[{"id":"1.231702167","rc":[{"batb":[[0,2.2,10],[1,2.18,32.83],[2,1.25,100]],"ltp":2.26,"tv":64.12,"id":475559}]}]}
{"op":"mcm","clk":"11840499175","pt":1723547661144,"mc":[{"id":"1.231702167","rc":[{"batb":[[0,2.18,32.83],[1,1.25,100],[2,1.08,7.82]],"ltp":2.26,"tv":64.12,"id":475559}]}]}
{"op":"mcm","clk":"11840499444","pt":1723547665322,"mc":[{"id":"1.231702167","rc":[{"batb":[[0,2.2,10],[1,2.18,32.83],[2,1.25,100]],"ltp":2.26,"tv":64.12,"id":475559}]}]}
{"op":"mcm","clk":"11840499682","pt":1723547668824,"mc":[{"id":"1.231702167","rc":[{"batb":[[0,2.18,32.83],[1,1.25,100],[2,1.08,7.82]],"ltp":2.26,"tv":64.12,"id":475559}]}]}
{"op":"mcm","clk":"11840499864","pt":1723547671818,"mc":[{"id":"1.231702167","rc":[{"batb":[[0,2.2,10],[1,2.18,32.83],[2,1.25,100]],"ltp":2.26,"tv":64.12,"id":475559}]}]}
{"op":"mcm","clk":"11840500114","pt":1723547675448,"mc":[{"id":"1.231702167","rc":[{"batb":[[0,2.18,32.83],[1,1.25,100],[2,1.08,7.82]],"ltp":2.26,"tv":64.12,"id":475559}]}]}
{"op":"mcm","clk":"11840500571","pt":1723547682441,"mc":[{"id":"1.231702167","rc":[{"batb":[[0,2.2,10],[1,2.18,32.83],[2,1.25,100]],"ltp":2.26,"tv":64.12,"id":475559}]}]}
{"op":"mcm","clk":"11840500792","pt":1723547686041,"mc":[{"id":"1.231702167","rc":[{"batb":[[0,2.18,32.83],[1,1.25,100],[2,1.08,7.82]],"ltp":2.26,"tv":64.12,"id":475559}]}]}
{"op":"mcm","clk":"11840501003","pt":1723547689536,"mc":[{"id":"1.231702167","rc":[{"batb":[[0,2.2,10],[1,2.18,32.83],[2,1.25,100]],"ltp":2.26,"tv":64.12,"id":475559}]}]}
{"op":"mcm","clk":"11840501227","pt":1723547693036,"mc":[{"id":"1.231702167","rc":[{"batb":[[0,2.18,32.83],[1,1.25,100],[2,1.08,7.82]],"ltp":2.26,"tv":64.12,"id":475559}]}]}
{"op":"mcm","clk":"11840501369","pt":1723547695244,"mc":[{"id":"1.231702167","rc":[{"batb":[[0,2.2,10],[1,2.18,32.83],[2,1.25,100]],"ltp":2.26,"tv":64.12,"id":475559}]}]}
{"op":"mcm","clk":"11840501553","pt":1723547698529,"mc":[{"id":"1.231702167","rc":[{"batb":[[0,2.18,32.83],[1,1.25,100],[2,1.08,7.82]],"ltp":2.26,"tv":64.12,"id":475559}]}]}
{"op":"mcm","clk":"11840501779","pt":1723547702185,"mc":[{"id":"1.231702167","rc":[{"batb":[[0,2.2,10],[1,2.18,32.83],[2,1.25,100]],"ltp":2.26,"tv":64.12,"id":475559}]}]}
{"op":"mcm","clk":"11840502016","pt":1723547705887,"mc":[{"id":"1.231702167","rc":[{"batb":[[0,2.18,32.83],[1,1.25,100],[2,1.08,7.82]],"ltp":2.26,"tv":64.12,"id":475559}]}]}
{"op":"mcm","clk":"11840502239","pt":1723547709490,"mc":[{"id":"1.231702167","rc":[{"batb":[[0,2.2,10],[1,2.18,32.83],[2,1.25,100]],"ltp":2.26,"tv":64.12,"id":475559}]}]}
{"op":"mcm","clk":"11840502434","pt":1723547713046,"mc":[{"id":"1.231702167","rc":[{"batb":[[0,2.18,32.83],[1,1.25,100],[2,1.08,7.82]],"ltp":2.26,"tv":64.12,"id":475559}]}]}
{"op":"mcm","clk":"11840502572","pt":1723547715871,"mc":[{"id":"1.231702167","rc":[{"batb":[[0,2.2,10],[1,2.18,32.83],[2,1.25,100]],"ltp":2.26,"tv":64.12,"id":475559}]}]}
{"op":"mcm","clk":"11840502765","pt":1723547719469,"mc":[{"id":"1.231702167","rc":[{"batb":[[0,2.18,32.83],[1,1.25,100],[2,1.08,7.82]],"ltp":2.26,"tv":64.12,"id":475559}]}]}
{"op":"mcm","clk":"11840502980","pt":1723547722702,"mc":[{"id":"1.231702167","rc":[{"batb":[[0,2.2,10],[1,2.18,32.83],[2,1.25,100]],"ltp":2.26,"tv":64.12,"id":475559}]}]}
{"op":"mcm","clk":"11840503182","pt":1723547726295,"mc":[{"id":"1.231702167","rc":[{"batb":[[0,2.18,32.83],[1,1.25,100],[2,1.08,7.82]],"ltp":2.26,"tv":64.12,"id":475559}]}]}
{"op":"mcm","clk":"11840503453","pt":1723547731316,"mc":[{"id":"1.231702167","rc":[{"batb":[[0,2.2,10],[1,2.18,32.83],[2,1.25,100]],"ltp":2.26,"tv":64.12,"id":475559}]}]}
{"op":"mcm","clk":"11840503727","pt":1723547736008,"mc":[{"id":"1.231702167","rc":[{"batb":[[0,2.18,32.83],[1,1.25,100],[2,1.08,7.82]],"ltp":2.26,"tv":64.12,"id":475559}]}]}
{"op":"mcm","clk":"11840504004","pt":1723547740742,"mc":[{"id":"1.231702167","rc":[{"batb":[[0,2.2,10],[1,2.18,32.83],[2,1.25,100]],"ltp":2.26,"tv":64.12,"id":475559}]}]}
{"op":"mcm","clk":"11840504196","pt":1723547744316,"mc":[{"id":"1.231702167","rc":[{"batb":[[0,2.18,32.83],[1,1.25,100],[2,1.08,7.82]],"ltp":2.26,"tv":64.12,"id":475559}]}]}
{"op":"mcm","clk":"11840504458","pt":1723547749502,"mc":[{"id":"1.231702167","rc":[{"batb":[[0,2.2,10],[1,2.18,32.83],[2,1.25,100]],"ltp":2.26,"tv":64.12,"id":475559}]}]}
{"op":"mcm","clk":"11840504628","pt":1723547752836,"mc":[{"id":"1.231702167","rc":[{"batb":[[0,2.18,32.83],[1,1.25,100],[2,1.08,7.82]],"ltp":2.26,"tv":64.12,"id":475559}]}]}
{"op":"mcm","clk":"11840504771","pt":1723547755405,"mc":[{"id":"1.231702167","rc":[{"batb":[[0,2.2,10],[1,2.18,32.83],[2,1.25,100]],"ltp":2.26,"tv":64.12,"id":475559}]}]}
{"op":"mcm","clk":"11840504952","pt":1723547758942,"mc":[{"id":"1.231702167","rc":[{"batb":[[0,2.18,32.83],[1,1.25,100],[2,1.08,7.82]],"ltp":2.26,"tv":64.12,"id":475559}]}]}
{"op":"mcm","clk":"11840505169","pt":1723547762311,"mc":[{"id":"1.231702167","rc":[{"batb":[[0,2.2,10],[1,2.18,32.83],[2,1.25,100]],"ltp":2.26,"tv":64.12,"id":475559}]}]}
{"op":"mcm","clk":"11840505346","pt":1723547765926,"mc":[{"id":"1.231702167","rc":[{"batb":[[0,2.18,32.83],[1,1.25,100],[2,1.08,7.82]],"ltp":2.26,"tv":64.12,"id":475559}]}]}
{"op":"mcm","clk":"11840505508","pt":1723547769017,"mc":[{"id":"1.231702167","rc":[{"batb":[[0,2.2,10],[1,2.18,32.83],[2,1.25,100]],"ltp":2.26,"tv":64.12,"id":475559}]}]}
{"op":"mcm","clk":"11840505755","pt":1723547773649,"mc":[{"id":"1.231702167","rc":[{"batb":[[0,2.18,32.83],[1,1.25,100],[2,1.08,7.82]],"ltp":2.26,"tv":64.12,"id":475559}]}]}
{"op":"mcm","clk":"11840505917","pt":1723547776734,"mc":[{"id":"1.231702167","rc":[{"batb":[[0,2.2,10],[1,2.18,32.83],[2,1.25,100]],"ltp":2.26,"tv":64.12,"id":475559}]}]}
{"op":"mcm","clk":"11840506128","pt":1723547780032,"mc":[{"id":"1.231702167","rc":[{"batb":[[0,2.18,32.83],[1,1.25,100],[2,1.08,7.82]],"ltp":2.26,"tv":64.12,"id":475559}]}]}
{"op":"mcm","clk":"11840506254","pt":1723547782858,"mc":[{"id":"1.231702167","rc":[{"batb":[[0,2.2,10],[1,2.18,32.83],[2,1.25,100]],"ltp":2.26,"tv":64.12,"id":475559}]}]}
{"op":"mcm","clk":"11840506453","pt":1723547786627,"mc":[{"id":"1.231702167","rc":[{"batb":[[0,2.18,32.83],[1,1.25,100],[2,1.08,7.82]],"ltp":2.26,"tv":64.12,"id":475559}]}]}
{"op":"mcm","clk":"11840506621","pt":1723547790271,"mc":[{"id":"1.231702167","rc":[{"batb":[[0,2.2,10],[1,2.18,32.83],[2,1.25,100]],"ltp":2.26,"tv":64.12,"id":475559}]}]}
{"op":"mcm","clk":"11840506795","pt":1723547793776,"mc":[{"id":"1.231702167","rc":[{"batb":[[0,2.18,32.83],[1,1.25,100],[2,1.08,7.82]],"ltp":2.26,"tv":64.12,"id":475559}]}]}
{"op":"mcm","clk":"11840506946","pt":1723547796760,"mc":[{"id":"1.231702167","rc":[{"batb":[[0,2.2,10],[1,2.18,32.83],[2,1.25,100]],"ltp":2.26,"tv":64.12,"id":475559}]}]}
{"op":"mcm","clk":"11840507151","pt":1723547800388,"mc":[{"id":"1.231702167","rc":[{"batb":[[0,2.18,32.83],[1,1.25,100],[2,1.08,7.82]],"ltp":2.26,"tv":64.12,"id":475559}]}]}
{"op":"mcm","clk":"11840507290","pt":1723547802653,"mc":[{"id":"1.231702167","rc":[{"batb":[[0,2.2,10],[1,2.18,32.83],[2,1.25,100]],"ltp":2.26,"tv":64.12,"id":475559}]}]}
{"op":"mcm","clk":"11840507496","pt":1723547806255,"mc":[{"id":"1.231702167","rc":[{"batb":[[0,2.18,32.83],[1,1.25,100],[2,1.08,7.82]],"ltp":2.26,"tv":64.12,"id":475559}]}]}
{"op":"mcm","clk":"11840507714","pt":1723547810264,"mc":[{"id":"1.231702167","rc":[{"batb":[[0,2.2,10],[1,2.18,32.83],[2,1.25,100]],"ltp":2.26,"tv":64.12,"id":475559}]}]}
{"op":"mcm","clk":"11840507910","pt":1723547813774,"mc":[{"id":"1.231702167","rc":[{"batb":[[0,2.18,32.83],[1,1.25,100],[2,1.08,7.82]],"ltp":2.26,"tv":64.12,"id":475559}]}]}
{"op":"mcm","clk":"11840508117","pt":1723547818104,"mc":[{"id":"1.231702167","rc":[{"batb":[[0,2.2,10],[1,2.18,32.83],[2,1.25,100]],"ltp":2.26,"tv":64.12,"id":475559}]}]}
{"op":"mcm","clk":"11840508320","pt":1723547821406,"mc":[{"id":"1.231702167","rc":[{"batb":[[0,2.18,32.83],[1,1.25,100],[2,1.08,7.82]],"ltp":2.26,"tv":64.12,"id":475559}]}]}
{"op":"mcm","clk":"11840508468","pt":1723547824299,"mc":[{"id":"1.231702167","rc":[{"batb":[[0,2.2,10],[1,2.18,32.83],[2,1.25,100]],"ltp":2.26,"tv":64.12,"id":475559}]}]}
{"op":"mcm","clk":"11840508671","pt":1723547827804,"mc":[{"id":"1.231702167","rc":[{"batb":[[0,2.18,32.83],[1,1.25,100],[2,1.08,7.82]],"ltp":2.26,"tv":64.12,"id":475559}]}]}
{"op":"mcm","clk":"11840508834","pt":1723547830681,"mc":[{"id":"1.231702167","rc":[{"batb":[[0,2.2,10],[1,2.18,32.83],[2,1.25,100]],"ltp":2.26,"tv":64.12,"id":475559}]}]}
{"op":"mcm","clk":"11840509028","pt":1723547834182,"mc":[{"id":"1.231702167","rc":[{"batb":[[0,2.18,32.83],[1,1.25,100],[2,1.08,7.82]],"ltp":2.26,"tv":64.12,"id":475559}]}]}
{"op":"mcm","clk":"11840509690","pt":1723547845999,"mc":[{"id":"1.231702167","rc":[{"batb":[[0,2.2,10],[1,2.18,32.83],[2,1.25,100]],"ltp":2.26,"tv":64.12,"id":475559}]}]}
{"op":"mcm","clk":"11840509887","pt":1723547849397,"mc":[{"id":"1.231702167","rc":[{"batb":[[0,2.18,32.83],[1,1.25,100],[2,1.08,7.82]],"ltp":2.26,"tv":64.12,"id":475559}]}]}
{"op":"mcm","clk":"11840509998","pt":1723547851721,"mc":[{"id":"1.231702167","rc":[{"batb":[[0,2.2,10],[1,2.18,32.83],[2,1.25,100]],"ltp":2.26,"tv":64.12,"id":475559}]}]}
{"op":"mcm","clk":"11840510182","pt":1723547855034,"mc":[{"id":"1.231702167","rc":[{"batb":[[0,2.18,32.83],[1,1.25,100],[2,1.08,7.82]],"ltp":2.26,"tv":64.12,"id":475559}]}]}
{"op":"mcm","clk":"11840510488","pt":1723547860103,"mc":[{"id":"1.231702167","rc":[{"batb":[[0,2.2,10],[1,2.18,32.83],[2,1.25,100]],"ltp":2.26,"tv":64.12,"id":475559}]}]}
{"op":"mcm","clk":"11840510703","pt":1723547863810,"mc":[{"id":"1.231702167","rc":[{"batb":[[0,2.18,32.83],[1,1.25,100],[2,1.08,7.82]],"ltp":2.26,"tv":64.12,"id":475559}]}]}
{"op":"mcm","clk":"11840510880","pt":1723547866953,"mc":[{"id":"1.231702167","rc":[{"batb":[[0,2.2,10],[1,2.18,32.83],[2,1.25,100]],"ltp":2.26,"tv":64.12,"id":475559}]}]}
{"op":"mcm","clk":"11840511056","pt":1723547870244,"mc":[{"id":"1.231702167","rc":[{"batb":[[0,2.18,32.83],[1,1.25,100],[2,1.08,7.82]],"ltp":2.26,"tv":64.12,"id":475559}]}]}
{"op":"mcm","clk":"11840511372","pt":1723547876151,"mc":[{"id":"1.231702167","rc":[{"batb":[[0,2.2,10],[1,2.18,32.83],[2,1.25,100]],"ltp":2.26,"tv":64.12,"id":475559}]}]}
{"op":"mcm","clk":"11840511552","pt":1723547879448,"mc":[{"id":"1.231702167","rc":[{"batb":[[0,2.18,32.83],[1,1.25,100],[2,1.08,7.82]],"ltp":2.26,"tv":64.12,"id":475559}]}]}
{"op":"mcm","clk":"11840511749","pt":1723547882341,"mc":[{"id":"1.231702167","rc":[{"batb":[[0,2.2,10],[1,2.18,32.83],[2,1.25,100]],"ltp":2.26,"tv":64.12,"id":475559}]}]}
{"op":"mcm","clk":"11840511947","pt":1723547885585,"mc":[{"id":"1.231702167","rc":[{"batb":[[0,2.18,32.83],[1,1.25,100],[2,1.08,7.82]],"ltp":2.26,"tv":64.12,"id":475559}]}]}
{"op":"mcm","clk":"11840512125","pt":1723547888773,"mc":[{"id":"1.231702167","rc":[{"batb":[[0,2.2,10],[1,2.18,32.83],[2,1.25,100]],"ltp":2.26,"tv":64.12,"id":475559}]}]}
{"op":"mcm","clk":"11840512313","pt":1723547892066,"mc":[{"id":"1.231702167","rc":[{"batb":[[0,2.18,32.83],[1,1.25,100],[2,1.08,7.82]],"ltp":2.26,"tv":64.12,"id":475559}]}]}
{"op":"mcm","clk":"11840512437","pt":1723547894586,"mc":[{"id":"1.231702167","rc":[{"batb":[[0,2.2,10],[1,2.18,32.83],[2,1.25,100]],"ltp":2.26,"tv":64.12,"id":475559}]}]}
{"op":"mcm","clk":"11840512650","pt":1723547898245,"mc":[{"id":"1.231702167","rc":[{"batb":[[0,2.18,32.83],[1,1.25,100],[2,1.08,7.82]],"ltp":2.26,"tv":64.12,"id":475559}]}]}
{"op":"mcm","clk":"11840512899","pt":1723547902154,"mc":[{"id":"1.231702167","rc":[{"batb":[[0,2.2,10],[1,2.18,32.83],[2,1.25,100]],"ltp":2.26,"tv":64.12,"id":475559}]}]}
{"op":"mcm","clk":"11840513119","pt":1723547905760,"mc":[{"id":"1.231702167","rc":[{"batb":[[0,2.18,32.83],[1,1.25,100],[2,1.08,7.82]],"ltp":2.26,"tv":64.12,"id":475559}]}]}
{"op":"mcm","clk":"11840513502","pt":1723547912079,"mc":[{"id":"1.231702167","rc":[{"batb":[[0,2.2,10],[1,2.18,32.83],[2,1.25,100]],"ltp":2.26,"tv":64.12,"id":475559}]}]}
{"op":"mcm","clk":"11840513696","pt":1723547915707,"mc":[{"id":"1.231702167","rc":[{"batb":[[0,2.18,32.83],[1,1.25,100],[2,1.08,7.82]],"ltp":2.26,"tv":64.12,"id":475559}]}]}
{"op":"mcm","clk":"11840513910","pt":1723547919878,"mc":[{"id":"1.231702167","rc":[{"batb":[[0,2.2,10],[1,2.18,32.83],[2,1.25,100]],"ltp":2.26,"tv":64.12,"id":475559}]}]}
{"op":"mcm","clk":"11840514112","pt":1723547923183,"mc":[{"id":"1.231702167","rc":[{"batb":[[0,2.18,32.83],[1,1.25,100],[2,1.08,7.82]],"ltp":2.26,"tv":64.12,"id":475559}]}]}
{"op":"mcm","clk":"11840514375","pt":1723547928363,"mc":[{"id":"1.231702167","rc":[{"batb":[[0,2.2,10],[1,2.18,32.83],[2,1.25,100]],"ltp":2.26,"tv":64.12,"id":475559}]}]}
{"op":"mcm","clk":"11840514545","pt":1723547931757,"mc":[{"id":"1.231702167","rc":[{"batb":[[0,2.18,32.83],[1,1.25,100],[2,1.08,7.82]],"ltp":2.26,"tv":64.12,"id":475559}]}]}
{"op":"mcm","clk":"11840514736","pt":1723547934596,"mc":[{"id":"1.231702167","rc":[{"batb":[[0,2.2,10],[1,2.18,32.83],[2,1.25,100]],"ltp":2.26,"tv":64.12,"id":475559}]}]}
{"op":"mcm","clk":"11840514917","pt":1723547938291,"mc":[{"id":"1.231702167","rc":[{"batb":[[0,2.18,32.83],[1,1.25,100],[2,1.08,7.82]],"ltp":2.26,"tv":64.12,"id":475559}]}]}
{"op":"mcm","clk":"11840515083","pt":1723547941178,"mc":[{"id":"1.231702167","rc":[{"batb":[[0,2.2,10],[1,2.18,32.83],[2,1.25,100]],"ltp":2.26,"tv":64.12,"id":475559}]}]}
{"op":"mcm","clk":"11840515308","pt":1723547944884,"mc":[{"id":"1.231702167","rc":[{"batb":[[0,2.18,32.83],[1,1.25,100],[2,1.08,7.82]],"ltp":2.26,"tv":64.12,"id":475559}]}]}
{"op":"mcm","clk":"11840515640","pt":1723547950803,"mc":[{"id":"1.231702167","rc":[{"batb":[[0,2.2,10],[1,2.18,32.83],[2,1.25,100]],"ltp":2.26,"tv":64.12,"id":475559}]}]}
{"op":"mcm","clk":"11840515841","pt":1723547954301,"mc":[{"id":"1.231702167","rc":[{"batb":[[0,2.18,32.83],[1,1.25,100],[2,1.08,7.82]],"ltp":2.26,"tv":64.12,"id":475559}]}]}
{"op":"mcm","clk":"11840515942","pt":1723547956715,"mc":[{"id":"1.231702167","rc":[{"batb":[[0,2.2,10],[1,2.18,32.83],[2,1.25,100]],"ltp":2.26,"tv":64.12,"id":475559}]}]}
{"op":"mcm","clk":"11840516160","pt":1723547960719,"mc":[{"id":"1.231702167","rc":[{"batb":[[0,2.18,32.83],[1,1.25,100],[2,1.08,7.82]],"ltp":2.26,"tv":64.12,"id":475559}]}]}
{"op":"mcm","clk":"11840516306","pt":1723547963506,"mc":[{"id":"1.231702167","rc":[{"batb":[[0,2.2,10],[1,2.18,32.83],[2,1.25,100]],"ltp":2.26,"tv":64.12,"id":475559}]}]}
{"op":"mcm","clk":"11840516477","pt":1723547966788,"mc":[{"id":"1.231702167","rc":[{"batb":[[0,2.18,32.83],[1,1.25,100],[2,1.08,7.82]],"ltp":2.26,"tv":64.12,"id":475559}]}]}
{"op":"mcm","clk":"11840516623","pt":1723547969818,"mc":[{"id":"1.231702167","rc":[{"batb":[[0,2.2,10],[1,2.18,32.83],[2,1.25,100]],"ltp":2.26,"tv":64.12,"id":475559}]}]}
{"op":"mcm","clk":"11840516782","pt":1723547973104,"mc":[{"id":"1.231702167","rc":[{"batb":[[0,2.18,32.83],[1,1.25,100],[2,1.08,7.82]],"ltp":2.26,"tv":64.12,"id":475559}]}]}
{"op":"mcm","clk":"11840516891","pt":1723547975324,"mc":[{"id":"1.231702167","rc":[{"batb":[[0,2.2,10],[1,2.18,32.83],[2,1.25,100]],"ltp":2.26,"tv":64.12,"id":475559}]}]}
{"op":"mcm","clk":"11840517092","pt":1723547978631,"mc":[{"id":"1.231702167","rc":[{"batb":[[0,2.18,32.83],[1,1.25,100],[2,1.08,7.82]],"ltp":2.26,"tv":64.12,"id":475559}]}]}
{"op":"mcm","clk":"11840517235","pt":1723547981008,"mc":[{"id":"1.231702167","rc":[{"batb":[[0,2.2,10],[1,2.18,32.83],[2,1.25,100]],"ltp":2.26,"tv":64.12,"id":475559}]}]}
{"op":"mcm","clk":"11840517405","pt":1723547984508,"mc":[{"id":"1.231702167","rc":[{"batb":[[0,2.18,32.83],[1,1.25,100],[2,1.08,7.82]],"ltp":2.26,"tv":64.12,"id":475559}]}]}
{"op":"mcm","clk":"11840517550","pt":1723547987233,"mc":[{"id":"1.231702167","rc":[{"batb":[[0,2.2,10],[1,2.18,32.83],[2,1.25,100]],"ltp":2.26,"tv":64.12,"id":475559}]}]}
{"op":"mcm","clk":"11840517717","pt":1723547990520,"mc":[{"id":"1.231702167","rc":[{"batb":[[0,2.18,32.83],[1,1.25,100],[2,1.08,7.82]],"ltp":2.26,"tv":64.12,"id":475559}]}]}
{"op":"mcm","clk":"11840517865","pt":1723547993248,"mc":[{"id":"1.231702167","rc":[{"batb":[[0,2.2,10],[1,2.18,32.83],[2,1.25,100]],"ltp":2.26,"tv":64.12,"id":475559}]}]}
{"op":"mcm","clk":"11840518022","pt":1723547996535,"mc":[{"id":"1.231702167","rc":[{"batb":[[0,2.18,32.83],[1,1.25,100],[2,1.08,7.82]],"ltp":2.26,"tv":64.12,"id":475559}]}]}
{"op":"mcm","clk":"11840518221","pt":1723548000345,"mc":[{"id":"1.231702167","rc":[{"batb":[[0,2.2,10],[1,2.18,32.83],[2,1.25,100]],"ltp":2.26,"tv":64.12,"id":475559}]}]}
{"op":"mcm","clk":"11840518403","pt":1723548003552,"mc":[{"id":"1.231702167","rc":[{"batb":[[0,2.18,32.83],[1,1.25,100],[2,1.08,7.82]],"ltp":2.26,"tv":64.12,"id":475559}]}]}
{"op":"mcm","clk":"11840518571","pt":1723548006443,"mc":[{"id":"1.231702167","rc":[{"batb":[[0,2.2,10],[1,2.18,32.83],[2,1.25,100]],"ltp":2.26,"tv":64.12,"id":475559}]}]}
{"op":"mcm","clk":"11840518793","pt":1723548010261,"mc":[{"id":"1.231702167","rc":[{"batb":[[0,2.18,32.83],[1,1.25,100],[2,1.08,7.82]],"ltp":2.26,"tv":64.12,"id":475559}]}]}
{"op":"mcm","clk":"11840519005","pt":1723548014070,"mc":[{"id":"1.231702167","rc":[{"batb":[[0,2.2,10],[1,2.18,32.83],[2,1.25,100]],"ltp":2.26,"tv":64.12,"id":475559}]}]}
{"op":"mcm","clk":"11840519192","pt":1723548017565,"mc":[{"id":"1.231702167","rc":[{"batb":[[0,2.18,32.83],[1,1.25,100],[2,1.08,7.82]],"ltp":2.26,"tv":64.12,"id":475559}]}]}
{"op":"mcm","clk":"11840519288","pt":1723548019778,"mc":[{"id":"1.231702167","rc":[{"batb":[[0,2.2,10],[1,2.18,32.83],[2,1.25,100]],"ltp":2.26,"tv":64.12,"id":475559}]}]}
{"op":"mcm","clk":"11840519470","pt":1723548023171,"mc":[{"id":"1.231702167","rc":[{"batb":[[0,2.18,32.83],[1,1.25,100],[2,1.08,7.82]],"ltp":2.26,"tv":64.12,"id":475559}]}]}
{"op":"mcm","clk":"11840520004","pt":1723548032911,"mc":[{"id":"1.231702167","rc":[{"batb":[[0,2.2,10],[1,2.18,32.83],[2,1.25,100]],"ltp":2.26,"tv":64.12,"id":475559}]}]}
{"op":"mcm","clk":"11840520191","pt":1723548036206,"mc":[{"id":"1.231702167","rc":[{"batb":[[0,2.18,32.83],[1,1.25,100],[2,1.08,7.82]],"ltp":2.26,"tv":64.12,"id":475559}]}]}
{"op":"mcm","clk":"11840520496","pt":1723548041606,"mc":[{"id":"1.231702167","rc":[{"batb":[[0,2.2,10],[1,2.18,32.83],[2,1.25,100]],"ltp":2.26,"tv":64.12,"id":475559}]}]}
{"op":"mcm","clk":"11840520729","pt":1723548045823,"mc":[{"id":"1.231702167","rc":[{"batb":[[0,2.18,32.83],[1,1.25,100],[2,1.08,7.82]],"ltp":2.26,"tv":64.12,"id":475559}]}]}
{"op":"mcm","clk":"11840521064","pt":1723548051696,"mc":[{"id":"1.231702167","rc":[{"batb":[[0,2.2,10],[1,2.18,32.83],[2,1.25,100]],"ltp":2.26,"tv":64.12,"id":475559}]}]}
{"op":"mcm","clk":"11840521290","pt":1723548055203,"mc":[{"id":"1.231702167","rc":[{"batb":[[0,2.18,32.83],[1,1.25,100],[2,1.08,7.82]],"ltp":2.26,"tv":64.12,"id":475559}]}]}
{"op":"mcm","clk":"11840521444","pt":1723548057632,"mc":[{"id":"1.231702167","rc":[{"batb":[[0,2.2,10],[1,2.18,32.83],[2,1.25,100]],"ltp":2.26,"tv":64.12,"id":475559}]}]}
{"op":"mcm","clk":"11840521652","pt":1723548061042,"mc":[{"id":"1.231702167","rc":[{"batb":[[0,2.18,32.83],[1,1.25,100],[2,1.08,7.82]],"ltp":2.26,"tv":64.12,"id":475559}]}]}
{"op":"mcm","clk":"11840521898","pt":1723548065018,"mc":[{"id":"1.231702167","rc":[{"batb":[[0,2.2,10],[1,2.18,32.83],[2,1.25,100]],"ltp":2.26,"tv":64.12,"id":475559}]}]}
{"op":"mcm","clk":"11840522111","pt":1723548068527,"mc":[{"id":"1.231702167","rc":[{"batb":[[0,2.18,32.83],[1,1.25,100],[2,1.08,7.82]],"ltp":2.26,"tv":64.12,"id":475559}]}]}
{"op":"mcm","clk":"11840522284","pt":1723548071224,"mc":[{"id":"1.231702167","rc":[{"batb":[[0,2.2,10],[1,2.18,32.83],[2,1.25,100]],"ltp":2.26,"tv":64.12,"id":475559}]}]}
{"op":"mcm","clk":"11840522491","pt":1723548074743,"mc":[{"id":"1.231702167","rc":[{"batb":[[0,2.18,32.83],[1,1.25,100],[2,1.08,7.82]],"ltp":2.26,"tv":64.12,"id":475559}]}]}
{"op":"mcm","clk":"11840522735","pt":1723548078971,"mc":[{"id":"1.231702167","rc":[{"batb":[[0,2.2,10],[1,2.18,32.83],[2,1.25,100]],"ltp":2.26,"tv":64.12,"id":475559}]}]}
{"op":"mcm","clk":"11840522929","pt":1723548082358,"mc":[{"id":"1.231702167","rc":[{"batb":[[0,2.18,32.83],[1,1.25,100],[2,1.08,7.82]],"ltp":2.26,"tv":64.12,"id":475559}]}]}
{"op":"mcm","clk":"11840523183","pt":1723548087368,"mc":[{"id":"1.231702167","rc":[{"batb":[[0,2.2,10],[1,2.18,32.83],[2,1.25,100]],"ltp":2.26,"tv":64.12,"id":475559}]}]}
{"op":"mcm","clk":"11840523386","pt":1723548090660,"mc":[{"id":"1.231702167","rc":[{"batb":[[0,2.18,32.83],[1,1.25,100],[2,1.08,7.82]],"ltp":2.26,"tv":64.12,"id":475559}]}]}
{"op":"mcm","clk":"11840523528","pt":1723548093050,"mc":[{"id":"1.231702167","rc":[{"batb":[[0,2.2,10],[1,2.18,32.83],[2,1.25,100]],"ltp":2.26,"tv":64.12,"id":475559}]}]}
{"op":"mcm","clk":"11840523721","pt":1723548096557,"mc":[{"id":"1.231702167","rc":[{"batb":[[0,2.18,32.83],[1,1.25,100],[2,1.08,7.82]],"ltp":2.26,"tv":64.12,"id":475559}]}]}
{"op":"mcm","clk":"11840523985","pt":1723548100474,"mc":[{"id":"1.231702167","rc":[{"batb":[[0,2.2,10],[1,2.18,32.83],[2,1.25,100]],"ltp":2.26,"tv":64.12,"id":475559}]}]}
{"op":"mcm","clk":"11840524177","pt":1723548103986,"mc":[{"id":"1.231702167","rc":[{"batb":[[0,2.18,32.83],[1,1.25,100],[2,1.08,7.82]],"ltp":2.26,"tv":64.12,"id":475559}]}]}
{"op":"mcm","clk":"11840524319","pt":1723548106670,"mc":[{"id":"1.231702167","rc":[{"batb":[[0,2.2,10],[1,2.18,32.83],[2,1.25,100]],"ltp":2.26,"tv":64.12,"id":475559}]}]}
{"op":"mcm","clk":"11840524510","pt":1723548110076,"mc":[{"id":"1.231702167","rc":[{"batb":[[0,2.18,32.83],[1,1.25,100],[2,1.08,7.82]],"ltp":2.26,"tv":64.12,"id":475559}]}]}
{"op":"mcm","clk":"11840524711","pt":1723548113882,"mc":[{"id":"1.231702167","rc":[{"batb":[[0,2.2,10],[1,2.18,32.83],[2,1.25,100]],"ltp":2.26,"tv":64.12,"id":475559}]}]}
{"op":"mcm","clk":"11840524891","pt":1723548117283,"mc":[{"id":"1.231702167","rc":[{"batb":[[0,2.18,32.83],[1,1.25,100],[2,1.08,7.82]],"ltp":2.26,"tv":64.12,"id":475559}]}]}
{"op":"mcm","clk":"11840525036","pt":1723548119809,"mc":[{"id":"1.231702167","rc":[{"batb":[[0,2.2,10],[1,2.18,32.83],[2,1.25,100]],"ltp":2.26,"tv":64.12,"id":475559}]}]}
{"op":"mcm","clk":"11840525244","pt":1723548123215,"mc":[{"id":"1.231702167","rc":[{"batb":[[0,2.18,32.83],[1,1.25,100],[2,1.08,7.82]],"ltp":2.26,"tv":64.12,"id":475559}]}]}
{"op":"mcm","clk":"11840525387","pt":1723548125798,"mc":[{"id":"1.231702167","rc":[{"batb":[[0,2.2,10],[1,2.18,32.83],[2,1.25,100]],"ltp":2.26,"tv":64.12,"id":475559}]}]}
{"op":"mcm","clk":"11840525577","pt":1723548129091,"mc":[{"id":"1.231702167","rc":[{"batb":[[0,2.18,32.83],[1,1.25,100],[2,1.08,7.82]],"ltp":2.26,"tv":64.12,"id":475559}]}]}
{"op":"mcm","clk":"11840525730","pt":1723548131921,"mc":[{"id":"1.231702167","rc":[{"batb":[[0,2.2,10],[1,2.18,32.83],[2,1.25,100]],"ltp":2.26,"tv":64.12,"id":475559}]}]}
{"op":"mcm","clk":"11840525977","pt":1723548135634,"mc":[{"id":"1.231702167","rc":[{"batb":[[0,2.18,32.83],[1,1.25,100],[2,1.08,7.82]],"ltp":2.26,"tv":64.12,"id":475559}]}]}
{"op":"mcm","clk":"11840526302","pt":1723548141497,"mc":[{"id":"1.231702167","rc":[{"batb":[[0,2.2,10],[1,2.18,32.83],[2,1.25,100]],"ltp":2.26,"tv":64.12,"id":475559}]}]}
{"op":"mcm","clk":"11840526583","pt":1723548146806,"mc":[{"id":"1.231702167","rc":[{"batb":[[0,2.18,32.83],[1,1.25,100],[2,1.08,7.82]],"ltp":2.26,"tv":64.12,"id":475559}]}]}
{"op":"mcm","clk":"11840526745","pt":1723548149427,"mc":[{"id":"1.231702167","rc":[{"batb":[[0,2.2,10],[1,2.18,32.83],[2,1.25,100]],"ltp":2.26,"tv":64.12,"id":475559}]}]}
{"op":"mcm","clk":"11840526935","pt":1723548152820,"mc":[{"id":"1.231702167","rc":[{"batb":[[0,2.18,32.83],[1,1.25,100],[2,1.08,7.82]],"ltp":2.26,"tv":64.12,"id":475559}]}]}
{"op":"mcm","clk":"11840527086","pt":1723548155553,"mc":[{"id":"1.231702167","rc":[{"batb":[[0,2.2,10],[1,2.18,32.83],[2,1.25,100]],"ltp":2.26,"tv":64.12,"id":475559}]}]}
{"op":"mcm","clk":"11840527270","pt":1723548158867,"mc":[{"id":"1.231702167","rc":[{"batb":[[0,2.18,32.83],[1,1.25,100],[2,1.08,7.82]],"ltp":2.26,"tv":64.12,"id":475559}]}]}
{"op":"mcm","clk":"11840527426","pt":1723548161545,"mc":[{"id":"1.231702167","rc":[{"batb":[[0,2.2,10],[1,2.18,32.83],[2,1.25,100]],"ltp":2.26,"tv":64.12,"id":475559}]}]}
{"op":"mcm","clk":"11840527605","pt":1723548165140,"mc":[{"id":"1.231702167","rc":[{"batb":[[0,2.18,32.83],[1,1.25,100],[2,1.08,7.82]],"ltp":2.26,"tv":64.12,"id":475559}]}]}
{"op":"mcm","clk":"11840527740","pt":1723548167554,"mc":[{"id":"1.231702167","rc":[{"batb":[[0,2.2,10],[1,2.18,32.83],[2,1.25,100]],"ltp":2.26,"tv":64.12,"id":475559}]}]}
{"op":"mcm","clk":"11840527912","pt":1723548171246,"mc":[{"id":"1.231702167","rc":[{"batb":[[0,2.18,32.83],[1,1.25,100],[2,1.08,7.82]],"ltp":2.26,"tv":64.12,"id":475559}]}]}
{"op":"mcm","clk":"11840528004","pt":1723548173564,"mc":[{"id":"1.231702167","rc":[{"batb":[[0,2.2,10],[1,2.18,32.83],[2,1.25,100]],"ltp":2.26,"tv":64.12,"id":475559}]}]}
{"op":"mcm","clk":"11840528173","pt":1723548176947,"mc":[{"id":"1.231702167","rc":[{"batb":[[0,2.18,32.83],[1,1.25,100],[2,1.08,7.82]],"ltp":2.26,"tv":64.12,"id":475559}]}]}
{"op":"mcm","clk":"11840528303","pt":1723548179263,"mc":[{"id":"1.231702167","rc":[{"batb":[[0,2.2,10],[1,2.18,32.83],[2,1.25,100]],"ltp":2.26,"tv":64.12,"id":475559}]}]}
{"op":"mcm","clk":"11840528527","pt":1723548182759,"mc":[{"id":"1.231702167","rc":[{"batb":[[0,2.18,32.83],[1,1.25,100],[2,1.08,7.82]],"ltp":2.26,"tv":64.12,"id":475559}]}]}
{"op":"mcm","clk":"11840528708","pt":1723548186766,"mc":[{"id":"1.231702167","rc":[{"batb":[[0,2.2,10],[1,2.18,32.83],[2,1.25,100]],"ltp":2.26,"tv":64.12,"id":475559}]}]}
{"op":"mcm","clk":"11840528878","pt":1723548190259,"mc":[{"id":"1.231702167","rc":[{"batb":[[0,2.18,32.83],[1,1.25,100],[2,1.08,7.82]],"ltp":2.26,"tv":64.12,"id":475559}]}]}
{"op":"mcm","clk":"11840529048","pt":1723548193394,"mc":[{"id":"1.231702167","rc":[{"batb":[[0,2.2,10],[1,2.18,32.83],[2,1.25,100]],"ltp":2.26,"tv":64.12,"id":475559}]}]}
{"op":"mcm","clk":"11840529222","pt":1723548196995,"mc":[{"id":"1.231702167","rc":[{"batb":[[0,2.18,32.83],[1,1.25,100],[2,1.08,7.82]],"ltp":2.26,"tv":64.12,"id":475559}]}]}
{"op":"mcm","clk":"11840529402","pt":1723548200695,"mc":[{"id":"1.231702167","rc":[{"batb":[[0,2.2,10],[1,2.18,32.83],[2,1.25,100]],"ltp":2.26,"tv":64.12,"id":475559}]}]}
{"op":"mcm","clk":"11840529552","pt":1723548204190,"mc":[{"id":"1.231702167","rc":[{"batb":[[0,2.18,32.83],[1,1.25,100],[2,1.08,7.82]],"ltp":2.26,"tv":64.12,"id":475559}]}]}
{"op":"mcm","clk":"11840529687","pt":1723548207105,"mc":[{"id":"1.231702167","rc":[{"batb":[[0,2.2,10],[1,2.18,32.83],[2,1.25,100]],"ltp":2.26,"tv":64.12,"id":475559}]}]}
{"op":"mcm","clk":"11840529885","pt":1723548210396,"mc":[{"id":"1.231702167","rc":[{"batb":[[0,2.18,32.83],[1,1.25,100],[2,1.08,7.82]],"ltp":2.26,"tv":64.12,"id":475559}]}]}
{"op":"mcm","clk":"11840530005","pt":1723548213017,"mc":[{"id":"1.231702167","rc":[{"batb":[[0,2.2,10],[1,2.18,32.83],[2,1.25,100]],"ltp":2.26,"tv":64.12,"id":475559}]}]}
{"op":"mcm","clk":"11840530170","pt":1723548216515,"mc":[{"id":"1.231702167","rc":[{"batb":[[0,2.18,32.83],[1,1.25,100],[2,1.08,7.82]],"ltp":2.26,"tv":64.12,"id":475559}]}]}
{"op":"mcm","clk":"11840530288","pt":1723548218836,"mc":[{"id":"1.231702167","rc":[{"batb":[[0,2.2,10],[1,2.18,32.83],[2,1.25,100]],"ltp":2.26,"tv":64.12,"id":475559}]}]}
{"op":"mcm","clk":"11840530455","pt":1723548222435,"mc":[{"id":"1.231702167","rc":[{"batb":[[0,2.18,32.83],[1,1.25,100],[2,1.08,7.82]],"ltp":2.26,"tv":64.12,"id":475559}]}]}
{"op":"mcm","clk":"11840530561","pt":1723548224696,"mc":[{"id":"1.231702167","rc":[{"batb":[[0,2.2,10],[1,2.18,32.83],[2,1.25,100]],"ltp":2.26,"tv":64.12,"id":475559}]}]}
{"op":"mcm","clk":"11840530749","pt":1723548228203,"mc":[{"id":"1.231702167","rc":[{"batb":[[0,2.18,32.83],[1,1.25,100],[2,1.08,7.82]],"ltp":2.26,"tv":64.12,"id":475559}]}]}
{"op":"mcm","clk":"11840530935","pt":1723548232326,"mc":[{"id":"1.231702167","rc":[{"batb":[[0,2.2,10],[1,2.18,32.83],[2,1.25,100]],"ltp":2.26,"tv":64.12,"id":475559}]}]}
{"op":"mcm","clk":"11840531107","pt":1723548236020,"mc":[{"id":"1.231702167","rc":[{"batb":[[0,2.18,32.83],[1,1.25,100],[2,1.08,7.82]],"ltp":2.26,"tv":64.12,"id":475559}]}]}
{"op":"mcm","clk":"11840531275","pt":1723548239614,"mc":[{"id":"1.231702167","rc":[{"batb":[[0,2.2,10],[1,2.18,32.83],[2,1.25,100]],"ltp":2.26,"tv":64.12,"id":475559}]}]}
{"op":"mcm","clk":"11840531498","pt":1723548243138,"mc":[{"id":"1.231702167","rc":[{"batb":[[0,2.18,32.83],[1,1.25,100],[2,1.08,7.82]],"ltp":2.26,"tv":64.12,"id":475559}]}]}
{"op":"mcm","clk":"11840531698","pt":1723548246350,"mc":[{"id":"1.231702167","rc":[{"batb":[[0,2.2,10],[1,2.18,32.83],[2,1.25,100]],"ltp":2.26,"tv":64.12,"id":475559}]}]}
{"op":"mcm","clk":"11840531909","pt":1723548249852,"mc":[{"id":"1.231702167","rc":[{"batb":[[0,2.18,32.83],[1,1.25,100],[2,1.08,7.82]],"ltp":2.26,"tv":64.12,"id":475559}]}]}
{"op":"mcm","clk":"11840532022","pt":1723548252063,"mc":[{"id":"1.231702167","rc":[{"batb":[[0,2.2,10],[1,2.18,32.83],[2,1.25,100]],"ltp":2.26,"tv":64.12,"id":475559}]}]}
{"op":"mcm","clk":"11840532236","pt":1723548255836,"mc":[{"id":"1.231702167","rc":[{"batb":[[0,2.18,32.83],[1,1.25,100],[2,1.08,7.82]],"ltp":2.26,"tv":64.12,"id":475559}]}]}
{"op":"mcm","clk":"11840532380","pt":1723548258361,"mc":[{"id":"1.231702167","rc":[{"batb":[[0,2.2,10],[1,2.18,32.83],[2,1.25,100]],"ltp":2.26,"tv":64.12,"id":475559}]}]}
{"op":"mcm","clk":"11840532560","pt":1723548261659,"mc":[{"id":"1.231702167","rc":[{"batb":[[0,2.18,32.83],[1,1.25,100],[2,1.08,7.82]],"ltp":2.26,"tv":64.12,"id":475559}]}]}
{"op":"mcm","clk":"11840532697","pt":1723548264141,"mc":[{"id":"1.231702167","rc":[{"batb":[[0,2.2,10],[1,2.18,32.83],[2,1.25,100]],"ltp":2.26,"tv":64.12,"id":475559}]}]}
{"op":"mcm","clk":"11840532884","pt":1723548267622,"mc":[{"id":"1.231702167","rc":[{"batb":[[0,2.18,32.83],[1,1.25,100],[2,1.08,7.82]],"ltp":2.26,"tv":64.12,"id":475559}]}]}
{"op":"mcm","clk":"11840533120","pt":1723548271934,"mc":[{"id":"1.231702167","rc":[{"batb":[[0,2.2,10],[1,2.18,32.83],[2,1.25,100]],"ltp":2.26,"tv":64.12,"id":475559}]}]}
{"op":"mcm","clk":"11840533326","pt":1723548275438,"mc":[{"id":"1.231702167","rc":[{"batb":[[0,2.18,32.83],[1,1.25,100],[2,1.08,7.82]],"ltp":2.26,"tv":64.12,"id":475559}]}]}
{"op":"mcm","clk":"11840533459","pt":1723548277758,"mc":[{"id":"1.231702167","rc":[{"batb":[[0,2.2,10],[1,2.18,32.83],[2,1.25,100]],"ltp":2.26,"tv":64.12,"id":475559}]}]}
{"op":"mcm","clk":"11840533661","pt":1723548281159,"mc":[{"id":"1.231702167","rc":[{"batb":[[0,2.18,32.83],[1,1.25,100],[2,1.08,7.82]],"ltp":2.26,"tv":64.12,"id":475559}]}]}
{"op":"mcm","clk":"11840533849","pt":1723548284456,"mc":[{"id":"1.231702167","rc":[{"batb":[[0,2.2,10],[1,2.18,32.83],[2,1.25,100]],"ltp":2.26,"tv":64.12,"id":475559}]}]}
{"op":"mcm","clk":"11840534015","pt":1723548287751,"mc":[{"id":"1.231702167","rc":[{"batb":[[0,2.18,32.83],[1,1.25,100],[2,1.08,7.82]],"ltp":2.26,"tv":64.12,"id":475559}]}]}
{"op":"mcm","clk":"11840534242","pt":1723548291458,"mc":[{"id":"1.231702167","rc":[{"batb":[[0,2.2,10],[1,2.18,32.83],[2,1.25,100]],"ltp":2.26,"tv":64.12,"id":475559}]}]}
{"op":"mcm","clk":"11840534428","pt":1723548294976,"mc":[{"id":"1.231702167","rc":[{"batb":[[0,2.18,32.83],[1,1.25,100],[2,1.08,7.82]],"ltp":2.26,"tv":64.12,"id":475559}]}]}
{"op":"mcm","clk":"11840534629","pt":1723548298902,"mc":[{"id":"1.231702167","rc":[{"batb":[[0,2.2,10],[1,2.18,32.83],[2,1.25,100]],"ltp":2.26,"tv":64.12,"id":475559}]}]}
{"op":"mcm","clk":"11840534842","pt":1723548302288,"mc":[{"id":"1.231702167","rc":[{"batb":[[0,2.18,32.83],[1,1.25,100],[2,1.08,7.82]],"ltp":2.26,"tv":64.12,"id":475559}]}]}
{"op":"mcm","clk":"11840535132","pt":1723548307091,"mc":[{"id":"1.231702167","rc":[{"batb":[[0,2.2,10],[1,2.18,32.83],[2,1.25,100]],"ltp":2.26,"tv":64.12,"id":475559}]}]}
{"op":"mcm","clk":"11840535301","pt":1723548310712,"mc":[{"id":"1.231702167","rc":[{"batb":[[0,2.18,32.83],[1,1.25,100],[2,1.08,7.82]],"ltp":2.26,"tv":64.12,"id":475559}]}]}
{"op":"mcm","clk":"11840535490","pt":1723548314186,"mc":[{"id":"1.231702167","rc":[{"batb":[[0,2.2,10],[1,2.18,32.83],[2,1.25,100]],"ltp":2.26,"tv":64.12,"id":475559}]}]}
{"op":"mcm","clk":"11840535688","pt":1723548317801,"mc":[{"id":"1.231702167","rc":[{"batb":[[0,2.18,32.83],[1,1.25,100],[2,1.08,7.82]],"ltp":2.26,"tv":64.12,"id":475559}]}]}
{"op":"mcm","clk":"11840535950","pt":1723548322817,"mc":[{"id":"1.231702167","rc":[{"batb":[[0,2.2,10],[1,2.18,32.83],[2,1.25,100]],"ltp":2.26,"tv":64.12,"id":475559}]}]}
{"op":"mcm","clk":"11840536136","pt":1723548326230,"mc":[{"id":"1.231702167","rc":[{"batb":[[0,2.18,32.83],[1,1.25,100],[2,1.08,7.82]],"ltp":2.26,"tv":64.12,"id":475559}]}]}
{"op":"mcm","clk":"11840536756","pt":1723548335831,"mc":[{"id":"1.231702167","rc":[{"batb":[[0,2.2,10],[1,2.18,32.83],[2,1.25,100]],"ltp":2.26,"tv":64.12,"id":475559}]}]}
{"op":"mcm","clk":"11840536945","pt":1723548339141,"mc":[{"id":"1.231702167","rc":[{"batb":[[0,2.18,32.83],[1,1.25,100],[2,1.08,7.82]],"ltp":2.26,"tv":64.12,"id":475559}]}]}
{"op":"mcm","clk":"11840537149","pt":1723548342640,"mc":[{"id":"1.231702167","rc":[{"batb":[[0,2.2,10],[1,2.18,32.83],[2,1.25,100]],"ltp":2.26,"tv":64.12,"id":475559}]}]}
{"op":"mcm","clk":"11840537317","pt":1723548346236,"mc":[{"id":"1.231702167","rc":[{"batb":[[0,2.18,32.83],[1,1.25,100],[2,1.08,7.82]],"ltp":2.26,"tv":64.12,"id":475559}]}]}
{"op":"mcm","clk":"11840537556","pt":1723548349851,"mc":[{"id":"1.231702167","rc":[{"batb":[[0,2.2,10],[1,2.18,32.83],[2,1.25,100]],"ltp":2.26,"tv":64.12,"id":475559}]}]}
{"op":"mcm","clk":"11840537735","pt":1723548353141,"mc":[{"id":"1.231702167","rc":[{"batb":[[0,2.18,32.83],[1,1.25,100],[2,1.08,7.82]],"ltp":2.26,"tv":64.12,"id":475559}]}]}
{"op":"mcm","clk":"11840537875","pt":1723548355565,"mc":[{"id":"1.231702167","rc":[{"batb":[[0,2.2,10],[1,2.18,32.83],[2,1.25,100]],"ltp":2.26,"tv":64.12,"id":475559}]}]}
{"op":"mcm","clk":"11840538049","pt":1723548358960,"mc":[{"id":"1.231702167","rc":[{"batb":[[0,2.18,32.83],[1,1.25,100],[2,1.08,7.82]],"ltp":2.26,"tv":64.12,"id":475559}]}]}
{"op":"mcm","clk":"11840538314","pt":1723548363653,"mc":[{"id":"1.231702167","rc":[{"batb":[[0,2.2,10],[1,2.18,32.83],[2,1.25,100]],"ltp":2.26,"tv":64.12,"id":475559}]}]}
{"op":"mcm","clk":"11840538485","pt":1723548367352,"mc":[{"id":"1.231702167","rc":[{"batb":[[0,2.18,32.83],[1,1.25,100],[2,1.08,7.82]],"ltp":2.26,"tv":64.12,"id":475559}]}]}
{"op":"mcm","clk":"11840538811","pt":1723548373269,"mc":[{"id":"1.231702167","rc":[{"batb":[[0,2.2,10],[1,2.18,32.83],[2,1.25,100]],"ltp":2.26,"tv":64.12,"id":475559}]}]}
{"op":"mcm","clk":"11840538986","pt":1723548376611,"mc":[{"id":"1.231702167","rc":[{"batb":[[0,2.18,32.83],[1,1.25,100],[2,1.08,7.82]],"ltp":2.26,"tv":64.12,"id":475559}]}]}
{"op":"mcm","clk":"11840539202","pt":1723548380773,"mc":[{"id":"1.231702167","rc":[{"batb":[[0,2.2,10],[1,2.18,32.83],[2,1.25,100]],"ltp":2.26,"tv":64.12,"id":475559}]}]}
{"op":"mcm","clk":"11840539378","pt":1723548384417,"mc":[{"id":"1.231702167","rc":[{"batb":[[0,2.18,32.83],[1,1.25,100],[2,1.08,7.82]],"ltp":2.26,"tv":64.12,"id":475559}]}]}
{"op":"mcm","clk":"11840539540","pt":1723548387197,"mc":[{"id":"1.231702167","rc":[{"batb":[[0,2.2,10],[1,2.18,32.83],[2,1.25,100]],"ltp":2.26,"tv":64.12,"id":475559}]}]}
{"op":"mcm","clk":"11840539701","pt":1723548390700,"mc":[{"id":"1.231702167","rc":[{"batb":[[0,2.18,32.83],[1,1.25,100],[2,1.08,7.82]],"ltp":2.26,"tv":64.12,"id":475559}]}]}
{"op":"mcm","clk":"11840540038","pt":1723548398190,"mc":[{"id":"1.231702167","rc":[{"batb":[[0,2.2,10],[1,2.18,32.83],[2,1.25,100]],"ltp":2.26,"tv":64.12,"id":475559}]}]}
{"op":"mcm","clk":"11840540185","pt":1723548401523,"mc":[{"id":"1.231702167","rc":[{"batb":[[0,2.18,32.83],[1,1.25,100],[2,1.08,7.82]],"ltp":2.26,"tv":64.12,"id":475559}]}]}
{"op":"mcm","clk":"11840540361","pt":1723548405745,"mc":[{"id":"1.231702167","rc":[{"batb":[[0,2.2,10],[1,2.18,32.83],[2,1.25,100]],"ltp":2.26,"tv":64.12,"id":475559}]}]}
{"op":"mcm","clk":"11840540516","pt":1723548409343,"mc":[{"id":"1.231702167","rc":[{"batb":[[0,2.18,32.83],[1,1.25,100],[2,1.08,7.82]],"ltp":2.26,"tv":64.12,"id":475559}]}]}
{"op":"mcm","clk":"11840540664","pt":1723548412722,"mc":[{"id":"1.231702167","rc":[{"batb":[[0,2.2,10],[1,2.18,32.83],[2,1.25,100]],"ltp":2.26,"tv":64.12,"id":475559}]}]}
{"op":"mcm","clk":"11840540831","pt":1723548416320,"mc":[{"id":"1.231702167","rc":[{"batb":[[0,2.18,32.83],[1,1.25,100],[2,1.08,7.82]],"ltp":2.26,"tv":64.12,"id":475559}]}]}
{"op":"mcm","clk":"11840541208","pt":1723548423424,"mc":[{"id":"1.231702167","rc":[{"batb":[[0,2.2,10],[1,2.18,32.83],[2,1.25,100]],"ltp":2.26,"tv":64.12,"id":475559}]}]}
{"op":"mcm","clk":"11840541373","pt":1723548426868,"mc":[{"id":"1.231702167","rc":[{"batb":[[0,2.18,32.83],[1,1.25,100],[2,1.08,7.82]],"ltp":2.26,"tv":64.12,"id":475559}]}]}
{"op":"mcm","clk":"11840541569","pt":1723548431040,"mc":[{"id":"1.231702167","rc":[{"batb":[[0,2.2,10],[1,2.18,32.83],[2,1.25,100]],"ltp":2.26,"tv":64.12,"id":475559}]}]}
{"op":"mcm","clk":"11840541743","pt":1723548434430,"mc":[{"id":"1.231702167","rc":[{"batb":[[0,2.18,32.83],[1,1.25,100],[2,1.08,7.82]],"ltp":2.26,"tv":64.12,"id":475559}]}]}
{"op":"mcm","clk":"11840541936","pt":1723548438858,"mc":[{"id":"1.231702167","rc":[{"batb":[[0,2.2,10],[1,2.18,32.83],[2,1.25,100]],"ltp":2.26,"tv":64.12,"id":475559}]}]}
{"op":"mcm","clk":"11840542100","pt":1723548442658,"mc":[{"id":"1.231702167","rc":[{"batb":[[0,2.18,32.83],[1,1.25,100],[2,1.08,7.82]],"ltp":2.26,"tv":64.12,"id":475559}]}]}
{"op":"mcm","clk":"11840542336","pt":1723548448160,"mc":[{"id":"1.231702167","rc":[{"batb":[[0,2.2,10],[1,2.18,32.83],[2,1.25,100]],"ltp":2.26,"tv":64.12,"id":475559}]}]}
{"op":"mcm","clk":"11840542498","pt":1723548451449,"mc":[{"id":"1.231702167","rc":[{"batb":[[0,2.18,32.83],[1,1.25,100],[2,1.08,7.82]],"ltp":2.26,"tv":64.12,"id":475559}]}]}
{"op":"mcm","clk":"11840542748","pt":1723548458072,"mc":[{"id":"1.231702167","rc":[{"batb":[[0,2.2,10],[1,2.18,32.83],[2,1.25,100]],"ltp":2.26,"tv":64.12,"id":475559}]}]}
{"op":"mcm","clk":"11840542924","pt":1723548461670,"mc":[{"id":"1.231702167","rc":[{"batb":[[0,2.18,32.83],[1,1.25,100],[2,1.08,7.82]],"ltp":2.26,"tv":64.12,"id":475559}]}]}
{"op":"mcm","clk":"11840543071","pt":1723548465165,"mc":[{"id":"1.231702167","rc":[{"batb":[[0,2.2,10],[1,2.18,32.83],[2,1.25,100]],"ltp":2.26,"tv":64.12,"id":475559}]}]}
{"op":"mcm","clk":"11840543251","pt":1723548468977,"mc":[{"id":"1.231702167","rc":[{"batb":[[0,2.18,32.83],[1,1.25,100],[2,1.08,7.82]],"ltp":2.26,"tv":64.12,"id":475559}]}]}
{"op":"mcm","clk":"11840543516","pt":1723548474679,"mc":[{"id":"1.231702167","rc":[{"batb":[[0,2.2,10],[1,2.18,32.83],[2,1.25,100]],"ltp":2.26,"tv":64.12,"id":475559}]}]}
{"op":"mcm","clk":"11840543681","pt":1723548478021,"mc":[{"id":"1.231702167","rc":[{"batb":[[0,2.18,32.83],[1,1.25,100],[2,1.08,7.82]],"ltp":2.26,"tv":64.12,"id":475559}]}]}
{"op":"mcm","clk":"11840543796","pt":1723548480186,"mc":[{"id":"1.231702167","rc":[{"batb":[[0,2.2,10],[1,2.18,32.83],[2,1.25,100]],"ltp":2.26,"tv":64.12,"id":475559}]}]}
{"op":"mcm","clk":"11840544020","pt":1723548483812,"mc":[{"id":"1.231702167","rc":[{"batb":[[0,2.18,32.83],[1,1.25,100],[2,1.08,7.82]],"ltp":2.26,"tv":64.12,"id":475559}]}]}
{"op":"mcm","clk":"11840544211","pt":1723548487736,"mc":[{"id":"1.231702167","rc":[{"batb":[[0,2.2,10],[1,2.18,32.83],[2,1.25,100]],"ltp":2.26,"tv":64.12,"id":475559}]}]}
{"op":"mcm","clk":"11840544423","pt":1723548491310,"mc":[{"id":"1.231702167","rc":[{"batb":[[0,2.18,32.83],[1,1.25,100],[2,1.08,7.82]],"ltp":2.26,"tv":64.12,"id":475559}]}]}
{"op":"mcm","clk":"11840544531","pt":1723548493840,"mc":[{"id":"1.231702167","rc":[{"batb":[[0,2.2,10],[1,2.18,32.83],[2,1.25,100]],"ltp":2.26,"tv":64.12,"id":475559}]}]}
{"op":"mcm","clk":"11840544731","pt":1723548497548,"mc":[{"id":"1.231702167","rc":[{"batb":[[0,2.18,32.83],[1,1.25,100],[2,1.08,7.82]],"ltp":2.26,"tv":64.12,"id":475559}]}]}
{"op":"mcm","clk":"11840544840","pt":1723548499718,"mc":[{"id":"1.231702167","rc":[{"batb":[[0,2.2,10],[1,2.18,32.83],[2,1.25,100]],"ltp":2.26,"tv":64.12,"id":475559}]}]}
{"op":"mcm","clk":"11840545003","pt":1723548503422,"mc":[{"id":"1.231702167","rc":[{"batb":[[0,2.18,32.83],[1,1.25,100],[2,1.08,7.82]],"ltp":2.26,"tv":64.12,"id":475559}]}]}
{"op":"mcm","clk":"11840545310","pt":1723548509541,"mc":[{"id":"1.231702167","rc":[{"batb":[[0,2.2,10],[1,2.18,32.83],[2,1.25,100]],"ltp":2.26,"tv":64.12,"id":475559}]}]}
{"op":"mcm","clk":"11840545503","pt":1723548513353,"mc":[{"id":"1.231702167","rc":[{"batb":[[0,2.18,32.83],[1,1.25,100],[2,1.08,7.82]],"ltp":2.26,"tv":64.12,"id":475559}]}]}
{"op":"mcm","clk":"11840545625","pt":1723548515824,"mc":[{"id":"1.231702167","rc":[{"batb":[[0,2.2,10],[1,2.18,32.83],[2,1.25,100]],"ltp":2.26,"tv":64.12,"id":475559}]}]}
{"op":"mcm","clk":"11840545811","pt":1723548519351,"mc":[{"id":"1.231702167","rc":[{"batb":[[0,2.18,32.83],[1,1.25,100],[2,1.08,7.82]],"ltp":2.26,"tv":64.12,"id":475559}]}]}
{"op":"mcm","clk":"11840546064","pt":1723548523769,"mc":[{"id":"1.231702167","rc":[{"batb":[[0,2.2,10],[1,2.18,32.83],[2,1.25,100]],"ltp":2.26,"tv":64.12,"id":475559}]}]}
{"op":"mcm","clk":"11840546244","pt":1723548527257,"mc":[{"id":"1.231702167","rc":[{"batb":[[0,2.18,32.83],[1,1.25,100],[2,1.08,7.82]],"ltp":2.26,"tv":64.12,"id":475559}]}]}
{"op":"mcm","clk":"11840546405","pt":1723548530237,"mc":[{"id":"1.231702167","rc":[{"batb":[[0,2.2,10],[1,2.18,32.83],[2,1.25,100]],"ltp":2.26,"tv":64.12,"id":475559}]}]}
{"op":"mcm","clk":"11840546601","pt":1723548534042,"mc":[{"id":"1.231702167","rc":[{"batb":[[0,2.18,32.83],[1,1.25,100],[2,1.08,7.82]],"ltp":2.26,"tv":64.12,"id":475559}]}]}
{"op":"mcm","clk":"11840546891","pt":1723548539372,"mc":[{"id":"1.231702167","rc":[{"batb":[[0,2.2,10],[1,2.18,32.83],[2,1.25,100]],"ltp":2.26,"tv":64.12,"id":475559}]}]}
{"op":"mcm","clk":"11840547069","pt":1723548542769,"mc":[{"id":"1.231702167","rc":[{"batb":[[0,2.18,32.83],[1,1.25,100],[2,1.08,7.82]],"ltp":2.26,"tv":64.12,"id":475559}]}]}
{"op":"mcm","clk":"11840547345","pt":1723548547705,"mc":[{"id":"1.231702167","rc":[{"batb":[[0,2.2,10],[1,2.18,32.83],[2,1.25,100]],"ltp":2.26,"tv":64.12,"id":475559}]}]}
{"op":"mcm","clk":"11840547529","pt":1723548550899,"mc":[{"id":"1.231702167","rc":[{"batb":[[0,2.18,32.83],[1,1.25,100],[2,1.08,7.82]],"ltp":2.26,"tv":64.12,"id":475559}]}]}
{"op":"mcm","clk":"11840547706","pt":1723548553779,"mc":[{"id":"1.231702167","rc":[{"batb":[[0,2.2,10],[1,2.18,32.83],[2,1.25,100]],"ltp":2.26,"tv":64.12,"id":475559}]}]}
{"op":"mcm","clk":"11840547914","pt":1723548557068,"mc":[{"id":"1.231702167","rc":[{"batb":[[0,2.18,32.83],[1,1.25,100],[2,1.08,7.82]],"ltp":2.26,"tv":64.12,"id":475559}]}]}
{"op":"mcm","clk":"11840548131","pt":1723548561481,"mc":[{"id":"1.231702167","rc":[{"batb":[[0,2.2,10],[1,2.18,32.83],[2,1.25,100]],"ltp":2.26,"tv":64.12,"id":475559}]}]}
{"op":"mcm","clk":"11840548280","pt":1723548564911,"mc":[{"id":"1.231702167","rc":[{"batb":[[0,2.18,32.83],[1,1.25,100],[2,1.08,7.82]],"ltp":2.26,"tv":64.12,"id":475559}]}]}
{"op":"mcm","clk":"11840548420","pt":1723548568093,"mc":[{"id":"1.231702167","rc":[{"batb":[[0,2.2,10],[1,2.18,32.83],[2,1.25,100]],"ltp":2.26,"tv":64.12,"id":475559}]}]}
{"op":"mcm","clk":"11840548603","pt":1723548571593,"mc":[{"id":"1.231702167","rc":[{"batb":[[0,2.18,32.83],[1,1.25,100],[2,1.08,7.82]],"ltp":2.26,"tv":64.12,"id":475559}]}]}
{"op":"mcm","clk":"11840548947","pt":1723548578212,"mc":[{"id":"1.231702167","rc":[{"batb":[[0,2.2,10],[1,2.18,32.83],[2,1.25,100]],"ltp":2.26,"tv":64.12,"id":475559}]}]}
{"op":"mcm","clk":"11840549134","pt":1723548581613,"mc":[{"id":"1.231702167","rc":[{"batb":[[0,2.18,32.83],[1,1.25,100],[2,1.08,7.82]],"ltp":2.26,"tv":64.12,"id":475559}]}]}
{"op":"mcm","clk":"11840549629","pt":1723548592340,"mc":[{"id":"1.231702167","rc":[{"batb":[[0,2.2,10],[1,2.18,32.83],[2,1.25,100]],"ltp":2.26,"tv":64.12,"id":475559}]}]}
{"op":"mcm","clk":"11840549803","pt":1723548595836,"mc":[{"id":"1.231702167","rc":[{"batb":[[0,2.18,32.83],[1,1.25,100],[2,1.08,7.82]],"ltp":2.26,"tv":64.12,"id":475559}]}]}
{"op":"mcm","clk":"11840549957","pt":1723548599525,"mc":[{"id":"1.231702167","rc":[{"batb":[[0,2.2,10],[1,2.18,32.83],[2,1.25,100]],"ltp":2.26,"tv":64.12,"id":475559}]}]}
{"op":"mcm","clk":"11840550198","pt":1723548603149,"mc":[{"id":"1.231702167","rc":[{"batb":[[0,2.18,32.83],[1,1.25,100],[2,1.08,7.82]],"ltp":2.26,"tv":64.12,"id":475559}]}]}
{"op":"mcm","clk":"11840550357","pt":1723548605569,"mc":[{"id":"1.231702167","rc":[{"batb":[[0,2.2,10],[1,2.18,32.83],[2,1.25,100]],"ltp":2.26,"tv":64.12,"id":475559}]}]}
{"op":"mcm","clk":"11840550605","pt":1723548609270,"mc":[{"id":"1.231702167","rc":[{"batb":[[0,2.18,32.83],[1,1.25,100],[2,1.08,7.82]],"ltp":2.26,"tv":64.12,"id":475559}]}]}
{"op":"mcm","clk":"11840550710","pt":1723548611433,"mc":[{"id":"1.231702167","rc":[{"batb":[[0,2.2,10],[1,2.18,32.83],[2,1.25,100]],"ltp":2.26,"tv":64.12,"id":475559}]}]}
{"op":"mcm","clk":"11840550976","pt":1723548614946,"mc":[{"id":"1.231702167","rc":[{"batb":[[0,2.18,32.83],[1,1.25,100],[2,1.08,7.82]],"ltp":2.26,"tv":64.12,"id":475559}]}]}
{"op":"mcm","clk":"11840551708","pt":1723548627284,"mc":[{"id":"1.231702167","rc":[{"batb":[[0,2.2,10],[1,2.18,32.83],[2,1.25,100]],"ltp":2.26,"tv":64.12,"id":475559}]}]}
{"op":"mcm","clk":"11840551910","pt":1723548631174,"mc":[{"id":"1.231702167","rc":[{"batb":[[0,2.18,32.83],[1,1.25,100],[2,1.08,7.82]],"ltp":2.26,"tv":64.12,"id":475559}]}]}
{"op":"mcm","clk":"11840552223","pt":1723548636076,"mc":[{"id":"1.231702167","rc":[{"batb":[[0,2.2,10],[1,2.18,32.83],[2,1.25,100]],"ltp":2.26,"tv":64.12,"id":475559}]}]}
{"op":"mcm","clk":"11840552417","pt":1723548639417,"mc":[{"id":"1.231702167","rc":[{"batb":[[0,2.18,32.83],[1,1.25,100],[2,1.08,7.82]],"ltp":2.26,"tv":64.12,"id":475559}]}]}
{"op":"mcm","clk":"11840553124","pt":1723548651306,"mc":[{"id":"1.231702167","rc":[{"batb":[[0,2.2,10],[1,2.18,32.83],[2,1.25,100]],"ltp":2.26,"tv":64.12,"id":475559}]}]}
{"op":"mcm","clk":"11840553294","pt":1723548654695,"mc":[{"id":"1.231702167","rc":[{"batb":[[0,2.18,32.83],[1,1.25,100],[2,1.08,7.82]],"ltp":2.26,"tv":64.12,"id":475559}]}]}
{"op":"mcm","clk":"11840553580","pt":1723548659527,"mc":[{"id":"1.231702167","rc":[{"batb":[[0,2.2,10],[1,2.18,32.83],[2,1.25,100]],"ltp":2.26,"tv":64.12,"id":475559}]}]}
{"op":"mcm","clk":"11840553787","pt":1723548662929,"mc":[{"id":"1.231702167","rc":[{"batb":[[0,2.18,32.83],[1,1.25,100],[2,1.08,7.82]],"ltp":2.26,"tv":64.12,"id":475559}]}]}
{"op":"mcm","clk":"11840553919","pt":1723548665301,"mc":[{"id":"1.231702167","rc":[{"batb":[[0,2.2,10],[1,2.18,32.83],[2,1.25,100]],"ltp":2.26,"tv":64.12,"id":475559}]}]}
{"op":"mcm","clk":"11840554147","pt":1723548668898,"mc":[{"id":"1.231702167","rc":[{"batb":[[0,2.18,32.83],[1,1.25,100],[2,1.08,7.82]],"ltp":2.26,"tv":64.12,"id":475559}]}]}
{"op":"mcm","clk":"11840554449","pt":1723548673871,"mc":[{"id":"1.231702167","rc":[{"batb":[[0,2.2,10],[1,2.18,32.83],[2,1.25,100]],"ltp":2.26,"tv":64.12,"id":475559}]}]}
{"op":"mcm","clk":"11840554674","pt":1723548677724,"mc":[{"id":"1.231702167","rc":[{"batb":[[0,2.18,32.83],[1,1.25,100],[2,1.08,7.82]],"ltp":2.26,"tv":64.12,"id":475559}]}]}
{"op":"mcm","clk":"11840555001","pt":1723548682918,"mc":[{"id":"1.231702167","rc":[{"batb":[[0,2.2,10],[1,2.18,32.83],[2,1.25,100]],"ltp":2.26,"tv":64.12,"id":475559}]}]}
{"op":"mcm","clk":"11840555198","pt":1723548686558,"mc":[{"id":"1.231702167","rc":[{"batb":[[0,2.18,32.83],[1,1.25,100],[2,1.08,7.82]],"ltp":2.26,"tv":64.12,"id":475559}]}]}
{"op":"mcm","clk":"11840555409","pt":1723548689859,"mc":[{"id":"1.231702167","rc":[{"batb":[[0,2.2,10],[1,2.18,32.83],[2,1.25,100]],"ltp":2.26,"tv":64.12,"id":475559}]}]}
{"op":"mcm","clk":"11840555642","pt":1723548693760,"mc":[{"id":"1.231702167","rc":[{"batb":[[0,2.18,32.83],[1,1.25,100],[2,1.08,7.82]],"ltp":2.26,"tv":64.12,"id":475559}]}]}
{"op":"mcm","clk":"11840556202","pt":1723548702355,"mc":[{"id":"1.231702167","rc":[{"batb":[[0,2.2,10],[1,2.18,32.83],[2,1.25,100]],"ltp":2.26,"tv":64.12,"id":475559}]}]}
{"op":"mcm","clk":"11840556422","pt":1723548705843,"mc":[{"id":"1.231702167","rc":[{"batb":[[0,2.18,32.83],[1,1.25,100],[2,1.08,7.82]],"ltp":2.26,"tv":64.12,"id":475559}]}]}
{"op":"mcm","clk":"11840557398","pt":1723548722181,"mc":[{"id":"1.231702167","rc":[{"batb":[[0,2.2,10],[1,2.18,32.83],[2,1.25,100]],"ltp":2.26,"tv":64.12,"id":475559}]}]}
{"op":"mcm","clk":"11840557601","pt":1723548725684,"mc":[{"id":"1.231702167","rc":[{"batb":[[0,2.18,32.83],[1,1.25,100],[2,1.08,7.82]],"ltp":2.26,"tv":64.12,"id":475559}]}]}
{"op":"mcm","clk":"11840557759","pt":1723548728563,"mc":[{"id":"1.231702167","rc":[{"batb":[[0,2.2,10],[1,2.18,32.83],[2,1.25,100]],"ltp":2.26,"tv":64.12,"id":475559}]}]}
{"op":"mcm","clk":"11840557929","pt":1723548731896,"mc":[{"id":"1.231702167","rc":[{"batb":[[0,2.18,32.83],[1,1.25,100],[2,1.08,7.82]],"ltp":2.26,"tv":64.12,"id":475559}]}]}
{"op":"mcm","clk":"11840558380","pt":1723548740670,"mc":[{"id":"1.231702167","rc":[{"batb":[[0,2.2,10],[1,2.18,32.83],[2,1.25,100]],"ltp":2.26,"tv":64.12,"id":475559}]}]}
{"op":"mcm","clk":"11840558563","pt":1723548744209,"mc":[{"id":"1.231702167","rc":[{"batb":[[0,2.18,32.83],[1,1.25,100],[2,1.08,7.82]],"ltp":2.26,"tv":64.12,"id":475559}]}]}
{"op":"mcm","clk":"11840558803","pt":1723548748584,"mc":[{"id":"1.231702167","rc":[{"batb":[[0,2.2,10],[1,2.18,32.83],[2,1.25,100]],"ltp":2.26,"tv":64.12,"id":475559}]}]}
{"op":"mcm","clk":"11840559010","pt":1723548752085,"mc":[{"id":"1.231702167","rc":[{"batb":[[0,2.18,32.83],[1,1.25,100],[2,1.08,7.82]],"ltp":2.26,"tv":64.12,"id":475559}]}]}
{"op":"mcm","clk":"11840559157","pt":1723548754709,"mc":[{"id":"1.231702167","rc":[{"batb":[[0,2.2,10],[1,2.18,32.83],[2,1.25,100]],"ltp":2.26,"tv":64.12,"id":475559}]}]}
{"op":"mcm","clk":"11840559359","pt":1723548758216,"mc":[{"id":"1.231702167","rc":[{"batb":[[0,2.18,32.83],[1,1.25,100],[2,1.08,7.82]],"ltp":2.26,"tv":64.12,"id":475559}]}]}
{"op":"mcm","clk":"11840559546","pt":1723548761615,"mc":[{"id":"1.231702167","rc":[{"batb":[[0,2.2,10],[1,2.18,32.83],[2,1.25,100]],"ltp":2.26,"tv":64.12,"id":475559}]}]}
{"op":"mcm","clk":"11840559726","pt":1723548764838,"mc":[{"id":"1.231702167","rc":[{"batb":[[0,2.18,32.83],[1,1.25,100],[2,1.08,7.82]],"ltp":2.26,"tv":64.12,"id":475559}]}]}
{"op":"mcm","clk":"11840559855","pt":1723548767102,"mc":[{"id":"1.231702167","rc":[{"batb":[[0,2.2,10],[1,2.18,32.83],[2,1.25,100]],"ltp":2.26,"tv":64.12,"id":475559}]}]}
{"op":"mcm","clk":"11840560066","pt":1723548770342,"mc":[{"id":"1.231702167","rc":[{"batb":[[0,2.18,32.83],[1,1.25,100],[2,1.08,7.82]],"ltp":2.26,"tv":64.12,"id":475559}]}]}
{"op":"mcm","clk":"11840560641","pt":1723548778548,"mc":[{"id":"1.231702167","rc":[{"batb":[[0,2.2,10],[1,2.18,32.83],[2,1.25,100]],"ltp":2.26,"tv":64.12,"id":475559}]}]}
{"op":"mcm","clk":"11840560826","pt":1723548781849,"mc":[{"id":"1.231702167","rc":[{"batb":[[0,2.18,32.83],[1,1.25,100],[2,1.08,7.82]],"ltp":2.26,"tv":64.12,"id":475559}]}]}
{"op":"mcm","clk":"11840561591","pt":1723548794242,"mc":[{"id":"1.231702167","rc":[{"batb":[[0,2.2,10],[1,2.18,32.83],[2,1.25,100]],"ltp":2.26,"tv":64.12,"id":475559}]}]}
{"op":"mcm","clk":"11840561774","pt":1723548797436,"mc":[{"id":"1.231702167","rc":[{"batb":[[0,2.18,32.83],[1,1.25,100],[2,1.08,7.82]],"ltp":2.26,"tv":64.12,"id":475559}]}]}
{"op":"mcm","clk":"11840561980","pt":1723548801144,"mc":[{"id":"1.231702167","rc":[{"batb":[[0,2.2,10],[1,2.18,32.83],[2,1.25,100]],"ltp":2.26,"tv":64.12,"id":475559}]}]}
{"op":"mcm","clk":"11840562134","pt":1723548804651,"mc":[{"id":"1.231702167","rc":[{"batb":[[0,2.18,32.83],[1,1.25,100],[2,1.08,7.82]],"ltp":2.26,"tv":64.12,"id":475559}]}]}
{"op":"mcm","clk":"11840562244","pt":1723548806961,"mc":[{"id":"1.231702167","rc":[{"batb":[[0,2.2,10],[1,2.18,32.83],[2,1.25,100]],"ltp":2.26,"tv":64.12,"id":475559}]}]}
{"op":"mcm","clk":"11840562421","pt":1723548810254,"mc":[{"id":"1.231702167","rc":[{"batb":[[0,2.18,32.83],[1,1.25,100],[2,1.08,7.82]],"ltp":2.26,"tv":64.12,"id":475559}]}]}
{"op":"mcm","clk":"11840562677","pt":1723548814542,"mc":[{"id":"1.231702167","rc":[{"batb":[[0,2.2,10],[1,2.18,32.83],[2,1.25,100]],"ltp":2.26,"tv":64.12,"id":475559}]}]}
{"op":"mcm","clk":"11840562885","pt":1723548817903,"mc":[{"id":"1.231702167","rc":[{"batb":[[0,2.18,32.83],[1,1.25,100],[2,1.08,7.82]],"ltp":2.26,"tv":64.12,"id":475559}]}]}
{"op":"mcm","clk":"11840563314","pt":1723548824350,"mc":[{"id":"1.231702167","rc":[{"batb":[[0,2.2,10],[1,2.18,32.83],[2,1.25,100]],"ltp":2.26,"tv":64.12,"id":475559}]}]}
{"op":"mcm","clk":"11840563539","pt":1723548827761,"mc":[{"id":"1.231702167","rc":[{"batb":[[0,2.18,32.83],[1,1.25,100],[2,1.08,7.82]],"ltp":2.26,"tv":64.12,"id":475559}]}]}
{"op":"mcm","clk":"11840563848","pt":1723548832780,"mc":[{"id":"1.231702167","rc":[{"batb":[[0,2.2,10],[1,2.18,32.83],[2,1.25,100]],"ltp":2.26,"tv":64.12,"id":475559}]}]}
{"op":"mcm","clk":"11840564058","pt":1723548836384,"mc":[{"id":"1.231702167","rc":[{"batb":[[0,2.18,32.83],[1,1.25,100],[2,1.08,7.82]],"ltp":2.26,"tv":64.12,"id":475559}]}]}
{"op":"mcm","clk":"11840564300","pt":1723548839801,"mc":[{"id":"1.231702167","rc":[{"batb":[[0,2.2,10],[1,2.18,32.83],[2,1.25,100]],"ltp":2.26,"tv":64.12,"id":475559}]}]}
{"op":"mcm","clk":"11840564555","pt":1723548843377,"mc":[{"id":"1.231702167","rc":[{"batb":[[0,2.18,32.83],[1,1.25,100],[2,1.08,7.82]],"ltp":2.26,"tv":64.12,"id":475559}]}]}
{"op":"mcm","clk":"11840564748","pt":1723548847190,"mc":[{"id":"1.231702167","rc":[{"batb":[[0,2.2,10],[1,2.18,32.83],[2,1.25,100]],"ltp":2.26,"tv":64.12,"id":475559}]}]}
{"op":"mcm","clk":"11840564903","pt":1723548850626,"mc":[{"id":"1.231702167","rc":[{"batb":[[0,2.18,32.83],[1,1.25,100],[2,1.08,7.82]],"ltp":2.26,"tv":64.12,"id":475559}]}]}
{"op":"mcm","clk":"11840565126","pt":1723548854195,"mc":[{"id":"1.231702167","rc":[{"batb":[[0,2.2,10],[1,2.18,32.83],[2,1.25,100]],"ltp":2.26,"tv":64.12,"id":475559}]}]}
{"op":"mcm","clk":"11840565296","pt":1723548857432,"mc":[{"id":"1.231702167","rc":[{"batb":[[0,2.18,32.83],[1,1.25,100],[2,1.08,7.82]],"ltp":2.26,"tv":64.12,"id":475559}]}]}
{"op":"mcm","clk":"11840565500","pt":1723548861035,"mc":[{"id":"1.231702167","rc":[{"batb":[[0,2.2,10],[1,2.18,32.83],[2,1.25,100]],"ltp":2.26,"tv":64.12,"id":475559}]}]}
{"op":"mcm","clk":"11840565689","pt":1723548864429,"mc":[{"id":"1.231702167","rc":[{"batb":[[0,2.18,32.83],[1,1.25,100],[2,1.08,7.82]],"ltp":2.26,"tv":64.12,"id":475559}]}]}
{"op":"mcm","clk":"11840565857","pt":1723548867812,"mc":[{"id":"1.231702167","rc":[{"batb":[[0,2.2,10],[1,2.18,32.83],[2,1.25,100]],"ltp":2.26,"tv":64.12,"id":475559}]}]}
{"op":"mcm","clk":"11840566050","pt":1723548871263,"mc":[{"id":"1.231702167","rc":[{"batb":[[0,2.18,32.83],[1,1.25,100],[2,1.08,7.82]],"ltp":2.26,"tv":64.12,"id":475559}]}]}
{"op":"mcm","clk":"11840566222","pt":1723548873530,"mc":[{"id":"1.231702167","rc":[{"batb":[[0,2.2,10],[1,2.18,32.83],[2,1.25,100]],"ltp":2.26,"tv":64.12,"id":475559}]}]}
{"op":"mcm","clk":"11840566383","pt":1723548876931,"mc":[{"id":"1.231702167","rc":[{"batb":[[0,2.18,32.83],[1,1.25,100],[2,1.08,7.82]],"ltp":2.26,"tv":64.12,"id":475559}]}]}
{"op":"mcm","clk":"11840566625","pt":1723548880847,"mc":[{"id":"1.231702167","rc":[{"batb":[[0,2.2,10],[1,2.18,32.83],[2,1.25,100]],"ltp":2.26,"tv":64.12,"id":475559}]}]}
{"op":"mcm","clk":"11840566841","pt":1723548884561,"mc":[{"id":"1.231702167","rc":[{"batb":[[0,2.18,32.83],[1,1.25,100],[2,1.08,7.82]],"ltp":2.26,"tv":64.12,"id":475559}]}]}
{"op":"mcm","clk":"11840566980","pt":1723548886978,"mc":[{"id":"1.231702167","rc":[{"batb":[[0,2.2,10],[1,2.18,32.83],[2,1.25,100]],"ltp":2.26,"tv":64.12,"id":475559}]}]}
{"op":"mcm","clk":"11840567181","pt":1723548890486,"mc":[{"id":"1.231702167","rc":[{"batb":[[0,2.18,32.83],[1,1.25,100],[2,1.08,7.82]],"ltp":2.26,"tv":64.12,"id":475559}]}]}
{"op":"mcm","clk":"11840567508","pt":1723548896272,"mc":[{"id":"1.231702167","rc":[{"batb":[[0,2.2,10],[1,2.18,32.83],[2,1.25,100]],"ltp":2.26,"tv":64.12,"id":475559}]}]}
{"op":"mcm","clk":"11840567681","pt":1723548899477,"mc":[{"id":"1.231702167","rc":[{"batb":[[0,2.18,32.83],[1,1.25,100],[2,1.08,7.82]],"ltp":2.26,"tv":64.12,"id":475559}]}]}
{"op":"mcm","clk":"11840567881","pt":1723548902781,"mc":[{"id":"1.231702167","rc":[{"batb":[[0,2.2,10],[1,2.18,32.83],[2,1.25,100]],"ltp":2.26,"tv":64.12,"id":475559}]}]}
{"op":"mcm","clk":"11840568086","pt":1723548906296,"mc":[{"id":"1.231702167","rc":[{"batb":[[0,2.18,32.83],[1,1.25,100],[2,1.08,7.82]],"ltp":2.26,"tv":64.12,"id":475559}]}]}
{"op":"mcm","clk":"11840568380","pt":1723548911204,"mc":[{"id":"1.231702167","rc":[{"batb":[[0,2.2,10],[1,2.18,32.83],[2,1.25,100]],"ltp":2.26,"tv":64.12,"id":475559}]}]}
{"op":"mcm","clk":"11840568573","pt":1723548914522,"mc":[{"id":"1.231702167","rc":[{"batb":[[0,2.18,32.83],[1,1.25,100],[2,1.08,7.82]],"ltp":2.26,"tv":64.12,"id":475559}]}]}
{"op":"mcm","clk":"11840568774","pt":1723548917720,"mc":[{"id":"1.231702167","rc":[{"batb":[[0,2.2,10],[1,2.18,32.83],[2,1.25,100]],"ltp":2.26,"tv":64.12,"id":475559}]}]}
{"op":"mcm","clk":"11840568909","pt":1723548921112,"mc":[{"id":"1.231702167","rc":[{"batb":[[0,2.18,32.83],[1,1.25,100],[2,1.08,7.82]],"ltp":2.26,"tv":64.12,"id":475559}]}]}
{"op":"mcm","clk":"11840569156","pt":1723548925433,"mc":[{"id":"1.231702167","rc":[{"batb":[[0,2.2,10],[1,2.18,32.83],[2,1.25,100]],"ltp":2.26,"tv":64.12,"id":475559}]}]}
{"op":"mcm","clk":"11840569360","pt":1723548928939,"mc":[{"id":"1.231702167","rc":[{"batb":[[0,2.18,32.83],[1,1.25,100],[2,1.08,7.82]],"ltp":2.26,"tv":64.12,"id":475559}]}]}
{"op":"mcm","clk":"11840569671","pt":1723548934826,"mc":[{"id":"1.231702167","rc":[{"batb":[[0,2.2,10],[1,2.18,32.83],[2,1.25,100]],"ltp":2.26,"tv":64.12,"id":475559}]}]}
{"op":"mcm","clk":"11840569866","pt":1723548938026,"mc":[{"id":"1.231702167","rc":[{"batb":[[0,2.18,32.83],[1,1.25,100],[2,1.08,7.82]],"ltp":2.26,"tv":64.12,"id":475559}]}]}
{"op":"mcm","clk":"11840570054","pt":1723548941423,"mc":[{"id":"1.231702167","rc":[{"batb":[[0,2.2,10],[1,2.18,32.83],[2,1.25,100]],"ltp":2.26,"tv":64.12,"id":475559}]}]}
{"op":"mcm","clk":"11840570266","pt":1723548945231,"mc":[{"id":"1.231702167","rc":[{"batb":[[0,2.18,32.83],[1,1.25,100],[2,1.08,7.82]],"ltp":2.26,"tv":64.12,"id":475559}]}]}
{"op":"mcm","clk":"11840570466","pt":1723548948622,"mc":[{"id":"1.231702167","rc":[{"batb":[[0,2.2,10],[1,2.18,32.83],[2,1.25,100]],"ltp":2.26,"tv":64.12,"id":475559}]}]}
{"op":"mcm","clk":"11840570639","pt":1723548952264,"mc":[{"id":"1.231702167","rc":[{"batb":[[0,2.18,32.83],[1,1.25,100],[2,1.08,7.82]],"ltp":2.26,"tv":64.12,"id":475559}]}]}
{"op":"mcm","clk":"11840570812","pt":1723548955242,"mc":[{"id":"1.231702167","rc":[{"batb":[[0,2.2,10],[1,2.18,32.83],[2,1.25,100]],"ltp":2.26,"tv":64.12,"id":475559}]}]}
{"op":"mcm","clk":"11840571017","pt":1723548958780,"mc":[{"id":"1.231702167","rc":[{"batb":[[0,2.18,32.83],[1,1.25,100],[2,1.08,7.82]],"ltp":2.26,"tv":64.12,"id":475559}]}]}
{"op":"mcm","clk":"11840571285","pt":1723548961653,"mc":[{"id":"1.231702167","rc":[{"batb":[[0,2.2,10],[1,2.18,32.83],[2,1.25,100]],"ltp":2.26,"tv":64.12,"id":475559}]}]}
{"op":"mcm","clk":"11840571535","pt":1723548965051,"mc":[{"id":"1.231702167","rc":[{"batb":[[0,2.18,32.83],[1,1.25,100],[2,1.08,7.82]],"ltp":2.26,"tv":64.12,"id":475559}]}]}
{"op":"mcm","clk":"11840571724","pt":1723548967727,"mc":[{"id":"1.231702167","rc":[{"batb":[[0,2.2,10],[1,2.18,32.83],[2,1.25,100]],"ltp":2.26,"tv":64.12,"id":475559}]}]}
{"op":"mcm","clk":"11840571957","pt":1723548971339,"mc":[{"id":"1.231702167","rc":[{"batb":[[0,2.18,32.83],[1,1.25,100],[2,1.08,7.82]],"ltp":2.26,"tv":64.12,"id":475559}]}]}
{"op":"mcm","clk":"11840572132","pt":1723548974432,"mc":[{"id":"1.231702167","rc":[{"batb":[[0,2.2,10],[1,2.18,32.83],[2,1.25,100]],"ltp":2.26,"tv":64.12,"id":475559}]}]}
{"op":"mcm","clk":"11840572334","pt":1723548978035,"mc":[{"id":"1.231702167","rc":[{"batb":[[0,2.18,32.83],[1,1.25,100],[2,1.08,7.82]],"ltp":2.26,"tv":64.12,"id":475559}]}]}
{"op":"mcm","clk":"11840572532","pt":1723548981879,"mc":[{"id":"1.231702167","rc":[{"batb":[[0,2.2,10],[1,2.18,32.83],[2,1.25,100]],"ltp":2.26,"tv":64.12,"id":475559}]}]}
{"op":"mcm","clk":"11840572705","pt":1723548985165,"mc":[{"id":"1.231702167","rc":[{"batb":[[0,2.18,32.83],[1,1.25,100],[2,1.08,7.82]],"ltp":2.26,"tv":64.12,"id":475559}]}]}
{"op":"mcm","clk":"11840572831","pt":1723548987588,"mc":[{"id":"1.231702167","rc":[{"batb":[[0,2.2,10],[1,2.18,32.83],[2,1.25,100]],"ltp":2.26,"tv":64.12,"id":475559}]}]}
{"op":"mcm","clk":"11840572990","pt":1723548990984,"mc":[{"id":"1.231702167","rc":[{"batb":[[0,2.18,32.83],[1,1.25,100],[2,1.08,7.82]],"ltp":2.26,"tv":64.12,"id":475559}]}]}
{"op":"mcm","clk":"11840573179","pt":1723548993978,"mc":[{"id":"1.231702167","rc":[{"batb":[[0,2.2,10],[1,2.18,32.83],[2,1.25,100]],"ltp":2.26,"tv":64.12,"id":475559}]}]}
{"op":"mcm","clk":"11840573352","pt":1723548997487,"mc":[{"id":"1.231702167","rc":[{"batb":[[0,2.18,32.83],[1,1.25,100],[2,1.08,7.82]],"ltp":2.26,"tv":64.12,"id":475559}]}]}
{"op":"mcm","clk":"11840573527","pt":1723548999960,"mc":[{"id":"1.231702167","rc":[{"batb":[[0,2.2,10],[1,2.18,32.83],[2,1.25,100]],"ltp":2.26,"tv":64.12,"id":475559}]}]}
{"op":"mcm","clk":"11840573715","pt":1723549003773,"mc":[{"id":"1.231702167","rc":[{"batb":[[0,2.18,32.83],[1,1.25,100],[2,1.08,7.82]],"ltp":2.26,"tv":64.12,"id":475559}]}]}
{"op":"mcm","clk":"11840573874","pt":1723549006712,"mc":[{"id":"1.231702167","rc":[{"batb":[[0,2.2,10],[1,2.18,32.83],[2,1.25,100]],"ltp":2.26,"tv":64.12,"id":475559}]}]}
{"op":"mcm","clk":"11840574078","pt":1723549010094,"mc":[{"id":"1.231702167","rc":[{"batb":[[0,2.18,32.83],[1,1.25,100],[2,1.08,7.82]],"ltp":2.26,"tv":64.12,"id":475559}]}]}
{"op":"mcm","clk":"11840574220","pt":1723549012666,"mc":[{"id":"1.231702167","rc":[{"batb":[[0,2.2,10],[1,2.18,32.83],[2,1.25,100]],"ltp":2.26,"tv":64.12,"id":475559}]}]}
{"op":"mcm","clk":"11840574456","pt":1723549016321,"mc":[{"id":"1.231702167","rc":[{"batb":[[0,2.18,32.83],[1,1.25,100],[2,1.08,7.82]],"ltp":2.26,"tv":64.12,"id":475559}]}]}
{"op":"mcm","clk":"11840574681","pt":1723549020187,"mc":[{"id":"1.231702167","rc":[{"batb":[[0,2.2,10],[1,2.18,32.83],[2,1.25,100]],"ltp":2.26,"tv":64.12,"id":475559}]}]}
{"op":"mcm","clk":"11840574892","pt":1723549023704,"mc":[{"id":"1.231702167","rc":[{"batb":[[0,2.18,32.83],[1,1.25,100],[2,1.08,7.82]],"ltp":2.26,"tv":64.12,"id":475559}]}]}
{"op":"mcm","clk":"11840575021","pt":1723549026117,"mc":[{"id":"1.231702167","rc":[{"batb":[[0,2.2,10],[1,2.18,32.83],[2,1.25,100]],"ltp":2.26,"tv":64.12,"id":475559}]}]}
{"op":"mcm","clk":"11840575229","pt":1723549029527,"mc":[{"id":"1.231702167","rc":[{"batb":[[0,2.18,32.83],[1,1.25,100],[2,1.08,7.82]],"ltp":2.26,"tv":64.12,"id":475559}]}]}
{"op":"mcm","clk":"11840575388","pt":1723549032204,"mc":[{"id":"1.231702167","rc":[{"batb":[[0,2.2,10],[1,2.18,32.83],[2,1.25,100]],"ltp":2.26,"tv":64.12,"id":475559}]}]}
{"op":"mcm","clk":"11840575610","pt":1723549035915,"mc":[{"id":"1.231702167","rc":[{"batb":[[0,2.18,32.83],[1,1.25,100],[2,1.08,7.82]],"ltp":2.26,"tv":64.12,"id":475559}]}]}
{"op":"mcm","clk":"11840575751","pt":1723549038325,"mc":[{"id":"1.231702167","rc":[{"batb":[[0,2.2,10],[1,2.18,32.83],[2,1.25,100]],"ltp":2.26,"tv":64.12,"id":475559}]}]}
{"op":"mcm","clk":"11840575931","pt":1723549041510,"mc":[{"id":"1.231702167","rc":[{"batb":[[0,2.18,32.83],[1,1.25,100],[2,1.08,7.82]],"ltp":2.26,"tv":64.12,"id":475559}]}]}
{"op":"mcm","clk":"11840576145","pt":1723549044924,"mc":[{"id":"1.231702167","rc":[{"batb":[[0,2.2,10],[1,2.18,32.83],[2,1.25,100]],"ltp":2.26,"tv":64.12,"id":475559}]}]}
{"op":"mcm","clk":"11840576341","pt":1723549048415,"mc":[{"id":"1.231702167","rc":[{"batb":[[0,2.18,32.83],[1,1.25,100],[2,1.08,7.82]],"ltp":2.26,"tv":64.12,"id":475559}]}]}
{"op":"mcm","clk":"11840576553","pt":1723549051924,"mc":[{"id":"1.231702167","rc":[{"batb":[[0,2.2,10],[1,2.18,32.83],[2,1.25,100]],"ltp":2.26,"tv":64.12,"id":475559}]}]}
{"op":"mcm","clk":"11840576776","pt":1723549055223,"mc":[{"id":"1.231702167","rc":[{"batb":[[0,2.18,32.83],[1,1.25,100],[2,1.08,7.82]],"ltp":2.26,"tv":64.12,"id":475559}]}]}
{"op":"mcm","clk":"11840577031","pt":1723549058941,"mc":[{"id":"1.231702167","rc":[{"batb":[[0,2.2,10],[1,2.18,32.83],[2,1.25,100]],"ltp":2.26,"tv":64.12,"id":475559}]}]}
{"op":"mcm","clk":"11840577277","pt":1723549062358,"mc":[{"id":"1.231702167","rc":[{"batb":[[0,2.18,32.83],[1,1.25,100],[2,1.08,7.82]],"ltp":2.26,"tv":64.12,"id":475559}]}]}
{"op":"mcm","clk":"11840577415","pt":1723549064878,"mc":[{"id":"1.231702167","rc":[{"batb":[[0,2.2,10],[1,2.18,32.83],[2,1.25,100]],"ltp":2.26,"tv":64.12,"id":475559}]}]}
{"op":"mcm","clk":"11840577654","pt":1723549068488,"mc":[{"id":"1.231702167","rc":[{"batb":[[0,2.18,32.83],[1,1.25,100],[2,1.08,7.82]],"ltp":2.26,"tv":64.12,"id":475559}]}]}
{"op":"mcm","clk":"11840577869","pt":1723549071954,"mc":[{"id":"1.231702167","rc":[{"batb":[[0,2.2,10],[1,2.18,32.83],[2,1.25,100]],"ltp":2.26,"tv":64.12,"id":475559}]}]}
{"op":"mcm","clk":"11840578090","pt":1723549075468,"mc":[{"id":"1.231702167","rc":[{"batb":[[0,2.18,32.83],[1,1.25,100],[2,1.08,7.82]],"ltp":2.26,"tv":64.12,"id":475559}]}]}
{"op":"mcm","clk":"11840578313","pt":1723549078879,"mc":[{"id":"1.231702167","rc":[{"batb":[[0,2.2,10],[1,2.18,32.83],[2,1.25,100]],"ltp":2.26,"tv":64.12,"id":475559}]}]}
{"op":"mcm","clk":"11840578515","pt":1723549082091,"mc":[{"id":"1.231702167","rc":[{"batb":[[0,2.18,32.83],[1,1.25,100],[2,1.08,7.82]],"ltp":2.26,"tv":64.12,"id":475559}]}]}
{"op":"mcm","clk":"11840578667","pt":1723549084365,"mc":[{"id":"1.231702167","rc":[{"batb":[[0,2.2,10],[1,2.18,32.83],[2,1.25,100]],"ltp":2.26,"tv":64.12,"id":475559}]}]}
{"op":"mcm","clk":"11840578880","pt":1723549087787,"mc":[{"id":"1.231702167","rc":[{"batb":[[0,2.18,32.83],[1,1.25,100],[2,1.08,7.82]],"ltp":2.26,"tv":64.12,"id":475559}]}]}
{"op":"mcm","clk":"11840579155","pt":1723549092491,"mc":[{"id":"1.231702167","rc":[{"batb":[[0,2.2,10],[1,2.18,32.83],[2,1.25,100]],"ltp":2.26,"tv":64.12,"id":475559}]}]}
{"op":"mcm","clk":"11840579361","pt":1723549095790,"mc":[{"id":"1.231702167","rc":[{"batb":[[0,2.18,32.83],[1,1.25,100],[2,1.08,7.82]],"ltp":2.26,"tv":64.12,"id":475559}]}]}
{"op":"mcm","clk":"11840579588","pt":1723549099189,"mc":[{"id":"1.231702167","rc":[{"batb":[[0,2.2,10],[1,2.18,32.83],[2,1.25,100]],"ltp":2.26,"tv":64.12,"id":475559}]}]}
{"op":"mcm","clk":"11840579774","pt":1723549102538,"mc":[{"id":"1.231702167","rc":[{"batb":[[0,2.18,32.83],[1,1.25,100],[2,1.08,7.82]],"ltp":2.26,"tv":64.12,"id":475559}]}]}
{"op":"mcm","clk":"11840580067","pt":1723549107595,"mc":[{"id":"1.231702167","rc":[{"batb":[[0,2.2,10],[1,2.18,32.83],[2,1.25,100]],"ltp":2.26,"tv":64.12,"id":475559}]}]}
{"op":"mcm","clk":"11840580301","pt":1723549111086,"mc":[{"id":"1.231702167","rc":[{"batb":[[0,2.18,32.83],[1,1.25,100],[2,1.08,7.82]],"ltp":2.26,"tv":64.12,"id":475559}]}]}
{"op":"mcm","clk":"11840580533","pt":1723549114430,"mc":[{"id":"1.231702167","rc":[{"batb":[[0,2.2,10],[1,2.18,32.83],[2,1.25,100]],"ltp":2.26,"tv":64.12,"id":475559}]}]}
{"op":"mcm","clk":"11840580825","pt":1723549118835,"mc":[{"id":"1.231702167","rc":[{"batb":[[0,2.18,32.83],[1,1.25,100],[2,1.08,7.82]],"ltp":2.26,"tv":64.12,"id":475559}]}]}
{"op":"mcm","clk":"11840580947","pt":1723549120902,"mc":[{"id":"1.231702167","rc":[{"batb":[[0,2.2,10],[1,2.18,32.83],[2,1.25,100]],"ltp":2.26,"tv":64.12,"id":475559}]}]}
{"op":"mcm","clk":"11840581153","pt":1723549124111,"mc":[{"id":"1.231702167","rc":[{"batb":[[0,2.18,32.83],[1,1.25,100],[2,1.08,7.82]],"ltp":2.26,"tv":64.12,"id":475559}]}]}
{"op":"mcm","clk":"11840581570","pt":1723549130940,"mc":[{"id":"1.231702167","rc":[{"batb":[[0,2.2,10],[1,2.18,32.83],[2,1.25,100]],"ltp":2.26,"tv":64.12,"id":475559}]}]}
{"op":"mcm","clk":"11840581793","pt":1723549134545,"mc":[{"id":"1.231702167","rc":[{"batb":[[0,2.18,32.83],[1,1.25,100],[2,1.08,7.82]],"ltp":2.26,"tv":64.12,"id":475559}]}]}
{"op":"mcm","clk":"11840582094","pt":1723549139220,"mc":[{"id":"1.231702167","rc":[{"batb":[[0,2.2,10],[1,2.18,32.83],[2,1.25,100]],"ltp":2.26,"tv":64.12,"id":475559}]}]}
{"op":"mcm","clk":"11840582295","pt":1723549142666,"mc":[{"id":"1.231702167","rc":[{"batb":[[0,2.18,32.83],[1,1.25,100],[2,1.08,7.82]],"ltp":2.26,"tv":64.12,"id":475559}]}]}
{"op":"mcm","clk":"11840582571","pt":1723549147140,"mc":[{"id":"1.231702167","rc":[{"batb":[[0,2.2,10],[1,2.18,32.83],[2,1.25,100]],"ltp":2.26,"tv":64.12,"id":475559}]}]}
{"op":"mcm","clk":"11840582763","pt":1723549150575,"mc":[{"id":"1.231702167","rc":[{"batb":[[0,2.18,32.83],[1,1.25,100],[2,1.08,7.82]],"ltp":2.26,"tv":64.12,"id":475559}]}]}
{"op":"mcm","clk":"11840582904","pt":1723549152950,"mc":[{"id":"1.231702167","rc":[{"batb":[[0,2.2,10],[1,2.18,32.83],[2,1.25,100]],"ltp":2.26,"tv":64.12,"id":475559}]}]}
{"op":"mcm","clk":"11840583101","pt":1723549156442,"mc":[{"id":"1.231702167","rc":[{"batb":[[0,2.18,32.83],[1,1.25,100],[2,1.08,7.82]],"ltp":2.26,"tv":64.12,"id":475559}]}]}
{"op":"mcm","clk":"11840658660","pt":1723550401716,"mc":[{"id":"1.231702167","rc":[{"batb":[[0,2.2,10],[1,2.18,32.83],[2,1.25,100]],"ltp":2.26,"tv":64.12,"id":475559}]}]}
{"op":"mcm","clk":"11840658931","pt":1723550405083,"mc":[{"id":"1.231702167","rc":[{"trd":[[1.73,26.22]],"batb":[[2,1.08,7.82]],"ltp":1.8,"tv":26.56,"id":5901},{"trd":[[2.26,64.12]],"batb":[[0,2.18,32.83],[1,1.25,100],[2,1.08,7.82]],"ltp":2.26,"tv":64.11,"id":475559}],"tv":90.68}]}
{"op":"mcm","clk":"11840659134","pt":1723550407916,"mc":[{"id":"1.231702167","rc":[{"batb":[[0,2.2,10],[1,2.18,32.83],[2,1.25,100]],"ltp":2.26,"tv":64.11,"id":475559}]}]}
{"op":"mcm","clk":"11840659369","pt":1723550411325,"mc":[{"id":"1.231702167","rc":[{"batb":[[0,2.18,32.83],[1,1.25,100],[2,1.08,7.82]],"ltp":2.26,"tv":64.11,"id":475559}]}]}
{"op":"mcm","clk":"11840659830","pt":1723550419530,"mc":[{"id":"1.231702167","rc":[{"batb":[[0,2.2,10],[1,2.18,32.83],[2,1.25,100]],"ltp":2.26,"tv":64.11,"id":475559}]}]}
{"op":"mcm","clk":"11840660034","pt":1723550422931,"mc":[{"id":"1.231702167","rc":[{"batb":[[0,2.18,32.83],[1,1.25,100],[2,1.08,7.82]],"ltp":2.26,"tv":64.11,"id":475559}]}]}
{"op":"mcm","clk":"11840660230","pt":1723550425835,"mc":[{"id":"1.231702167","rc":[{"batb":[[0,2.2,10],[1,2.18,32.83],[2,1.25,100]],"ltp":2.26,"tv":64.11,"id":475559}]}]}
{"op":"mcm","clk":"11840660455","pt":1723550429103,"mc":[{"id":"1.231702167","rc":[{"batb":[[0,2.18,32.83],[1,1.25,100],[2,1.08,7.82]],"ltp":2.26,"tv":64.11,"id":475559}]}]}
{"op":"mcm","clk":"11840660773","pt":1723550433733,"mc":[{"id":"1.231702167","rc":[{"batb":[[0,2.2,10],[1,2.18,32.83],[2,1.25,100]],"ltp":2.26,"tv":64.11,"id":475559}]}]}
{"op":"mcm","clk":"11840661032","pt":1723550437356,"mc":[{"id":"1.231702167","rc":[{"batb":[[0,2.18,32.83],[1,1.25,100],[2,1.08,7.82]],"ltp":2.26,"tv":64.11,"id":475559}]}]}
{"op":"mcm","clk":"11840661231","pt":1723550440051,"mc":[{"id":"1.231702167","rc":[{"batb":[[0,2.2,10],[1,2.18,32.83],[2,1.25,100]],"ltp":2.26,"tv":64.11,"id":475559}]}]}
{"op":"mcm","clk":"11840661430","pt":1723550443436,"mc":[{"id":"1.231702167","rc":[{"batb":[[0,2.18,32.83],[1,1.25,100],[2,1.08,7.82]],"ltp":2.26,"tv":64.11,"id":475559}]}]}
{"op":"mcm","clk":"11840661631","pt":1723550446435,"mc":[{"id":"1.231702167","rc":[{"batb":[[0,2.2,10],[1,2.18,32.83],[2,1.25,100]],"ltp":2.26,"tv":64.11,"id":475559}]}]}
{"op":"mcm","clk":"11840661908","pt":1723550450029,"mc":[{"id":"1.231702167","rc":[{"batb":[[0,2.18,32.83],[1,1.25,100],[2,1.08,7.82]],"ltp":2.26,"tv":64.11,"id":475559}]}]}
{"op":"mcm","clk":"11840662044","pt":1723550452255,"mc":[{"id":"1.231702167","rc":[{"batb":[[0,2.2,10],[1,2.18,32.83],[2,1.25,100]],"ltp":2.26,"tv":64.11,"id":475559}]}]}
{"op":"mcm","clk":"11840662239","pt":1723550455638,"mc":[{"id":"1.231702167","rc":[{"batb":[[0,2.18,32.83],[1,1.25,100],[2,1.08,7.82]],"ltp":2.26,"tv":64.11,"id":475559}]}]}
{"op":"mcm","clk":"11840662575","pt":1723550460777,"mc":[{"id":"1.231702167","rc":[{"batb":[[0,2.2,10],[1,2.18,32.83],[2,1.25,100]],"ltp":2.26,"tv":64.11,"id":475559}]}]}
{"op":"mcm","clk":"11840662824","pt":1723550464174,"mc":[{"id":"1.231702167","rc":[{"batb":[[0,2.18,32.83],[1,1.25,100],[2,1.08,7.82]],"ltp":2.26,"tv":64.11,"id":475559}]}]}
{"op":"mcm","clk":"11840663018","pt":1723550466642,"mc":[{"id":"1.231702167","rc":[{"batb":[[0,2.2,10],[1,2.18,32.83],[2,1.25,100]],"ltp":2.26,"tv":64.11,"id":475559}]}]}
{"op":"mcm","clk":"11840663272","pt":1723550470181,"mc":[{"id":"1.231702167","rc":[{"batb":[[0,2.18,32.83],[1,1.25,100],[2,1.08,7.82]],"ltp":2.26,"tv":64.11,"id":475559}]}]}
{"op":"mcm","clk":"11840663431","pt":1723550472658,"mc":[{"id":"1.231702167","rc":[{"batb":[[0,2.2,10],[1,2.18,32.83],[2,1.25,100]],"ltp":2.26,"tv":64.11,"id":475559}]}]}
{"op":"mcm","clk":"11840663687","pt":1723550476000,"mc":[{"id":"1.231702167","rc":[{"batb":[[0,2.18,32.83],[1,1.25,100],[2,1.08,7.82]],"ltp":2.26,"tv":64.11,"id":475559}]}]}
{"op":"mcm","clk":"11840663911","pt":1723550479489,"mc":[{"id":"1.231702167","rc":[{"batb":[[0,2.2,10],[1,2.18,32.83],[2,1.25,100]],"ltp":2.26,"tv":64.11,"id":475559}]}]}
{"op":"mcm","clk":"11840664156","pt":1723550482984,"mc":[{"id":"1.231702167","rc":[{"batb":[[0,2.18,32.83],[1,1.25,100],[2,1.08,7.82]],"ltp":2.26,"tv":64.11,"id":475559}]}]}
{"op":"mcm","clk":"11840664389","pt":1723550486165,"mc":[{"id":"1.231702167","rc":[{"batb":[[0,2.2,10],[1,2.18,32.83],[2,1.25,100]],"ltp":2.26,"tv":64.11,"id":475559}]}]}
{"op":"mcm","clk":"11840664654","pt":1723550489762,"mc":[{"id":"1.231702167","rc":[{"batb":[[0,2.18,32.83],[1,1.25,100],[2,1.08,7.82]],"ltp":2.26,"tv":64.11,"id":475559}]}]}
{"op":"mcm","clk":"11840665009","pt":1723550494286,"mc":[{"id":"1.231702167","rc":[{"batb":[[0,2.2,10],[1,2.18,32.83],[2,1.25,100]],"ltp":2.26,"tv":64.11,"id":475559}]}]}
{"op":"mcm","clk":"11840665300","pt":1723550497787,"mc":[{"id":"1.231702167","rc":[{"batb":[[0,2.18,32.83],[1,1.25,100],[2,1.08,7.82]],"ltp":2.26,"tv":64.11,"id":475559}]}]}
{"op":"mcm","clk":"11840665523","pt":1723550500785,"mc":[{"id":"1.231702167","rc":[{"batb":[[0,2.2,10],[1,2.18,32.83],[2,1.25,100]],"ltp":2.26,"tv":64.11,"id":475559}]}]}
{"op":"mcm","clk":"11840665765","pt":1723550504077,"mc":[{"id":"1.231702167","rc":[{"batb":[[0,2.18,32.83],[1,1.25,100],[2,1.08,7.82]],"ltp":2.26,"tv":64.11,"id":475559}]}]}
{"op":"mcm","clk":"11840665983","pt":1723550506586,"mc":[{"id":"1.231702167","rc":[{"batb":[[0,2.2,10],[1,2.18,32.83],[2,1.25,100]],"ltp":2.26,"tv":64.11,"id":475559}]}]}
{"op":"mcm","clk":"11840666219","pt":1723550509924,"mc":[{"id":"1.231702167","rc":[{"batb":[[0,2.18,32.83],[1,1.25,100],[2,1.08,7.82]],"ltp":2.26,"tv":64.11,"id":475559}]}]}
{"op":"mcm","clk":"11840666428","pt":1723550512601,"mc":[{"id":"1.231702167","rc":[{"batb":[[0,2.2,10],[1,2.18,32.83],[2,1.25,100]],"ltp":2.26,"tv":64.11,"id":475559}]}]}
{"op":"mcm","clk":"11840666669","pt":1723550515893,"mc":[{"id":"1.231702167","rc":[{"batb":[[0,2.18,32.83],[1,1.25,100],[2,1.08,7.82]],"ltp":2.26,"tv":64.11,"id":475559}]}]}
{"op":"mcm","clk":"11840667039","pt":1723550520745,"mc":[{"id":"1.231702167","rc":[{"batb":[[0,2.2,10],[1,2.18,32.83],[2,1.25,100]],"ltp":2.26,"tv":64.11,"id":475559}]}]}
{"op":"mcm","clk":"11840667298","pt":1723550524009,"mc":[{"id":"1.231702167","rc":[{"batb":[[0,2.18,32.83],[1,1.25,100],[2,1.08,7.82]],"ltp":2.26,"tv":64.11,"id":475559}]}]}
{"op":"mcm","clk":"11840667934","pt":1723550531443,"mc":[{"id":"1.231702167","rc":[{"batb":[[0,2.2,10],[1,2.18,32.83],[2,1.25,100]],"ltp":2.26,"tv":64.11,"id":475559}]}]}
{"op":"mcm","clk":"11840668217","pt":1723550534749,"mc":[{"id":"1.231702167","rc":[{"batb":[[0,2.18,32.83],[1,1.25,100],[2,1.08,7.82]],"ltp":2.26,"tv":64.11,"id":475559}]}]}
{"op":"mcm","clk":"11840668742","pt":1723550541962,"mc":[{"id":"1.231702167","rc":[{"batb":[[0,2.2,10],[1,2.18,32.83],[2,1.25,100]],"ltp":2.26,"tv":64.11,"id":475559}]}]}
{"op":"mcm","clk":"11840668985","pt":1723550545368,"mc":[{"id":"1.231702167","rc":[{"batb":[[0,2.18,32.83],[1,1.25,100],[2,1.08,7.82]],"ltp":2.26,"tv":64.11,"id":475559}]}]}
{"op":"mcm","clk":"11840670295","pt":1723550562298,"mc":[{"id":"1.231702167","rc":[{"batb":[[0,2.2,10],[1,2.18,32.83],[2,1.25,100]],"ltp":2.26,"tv":64.11,"id":475559}]}]}
{"op":"mcm","clk":"11840670559","pt":1723550565662,"mc":[{"id":"1.231702167","rc":[{"batb":[[0,2.18,32.83],[1,1.25,100],[2,1.08,7.82]],"ltp":2.26,"tv":64.11,"id":475559}]}]}
{"op":"mcm","clk":"11840670774","pt":1723550568797,"mc":[{"id":"1.231702167","rc":[{"batb":[[0,2.2,10],[1,2.18,32.83],[2,1.25,100]],"ltp":2.26,"tv":64.11,"id":475559}]}]}
{"op":"mcm","clk":"11840671033","pt":1723550572058,"mc":[{"id":"1.231702167","rc":[{"batb":[[0,2.18,32.83],[1,1.25,100],[2,1.08,7.82]],"ltp":2.26,"tv":64.11,"id":475559}]}]}
{"op":"mcm","clk":"11840671337","pt":1723550575885,"mc":[{"id":"1.231702167","rc":[{"batb":[[0,2.2,10],[1,2.18,32.83],[2,1.25,100]],"ltp":2.26,"tv":64.11,"id":475559}]}]}
{"op":"mcm","clk":"11840671647","pt":1723550579424,"mc":[{"id":"1.231702167","rc":[{"batb":[[0,2.18,32.83],[1,1.25,100],[2,1.08,7.82]],"ltp":2.26,"tv":64.11,"id":475559}]}]}
{"op":"mcm","clk":"11840671989","pt":1723550583319,"mc":[{"id":"1.231702167","rc":[{"batb":[[0,2.2,10],[1,2.18,32.83],[2,1.25,100]],"ltp":2.26,"tv":64.11,"id":475559}]}]}
{"op":"mcm","clk":"11840672313","pt":1723550586892,"mc":[{"id":"1.231702167","rc":[{"batb":[[0,2.18,32.83],[1,1.25,100],[2,1.08,7.82]],"ltp":2.26,"tv":64.11,"id":475559}]}]}
{"op":"mcm","clk":"11840672780","pt":1723550593016,"mc":[{"id":"1.231702167","rc":[{"batb":[[0,2.2,10],[1,2.18,32.83],[2,1.25,100]],"ltp":2.26,"tv":64.11,"id":475559}]}]}
{"op":"mcm","clk":"11840673052","pt":1723550596566,"mc":[{"id":"1.231702167","rc":[{"batb":[[0,2.18,32.83],[1,1.25,100],[2,1.08,7.82]],"ltp":2.26,"tv":64.11,"id":475559}]}]}
{"op":"mcm","clk":"11840673398","pt":1723550600635,"mc":[{"id":"1.231702167","rc":[{"batb":[[0,2.2,10],[1,2.18,32.83],[2,1.25,100]],"ltp":2.26,"tv":64.11,"id":475559}]}]}
{"op":"mcm","clk":"11840673647","pt":1723550604068,"mc":[{"id":"1.231702167","rc":[{"batb":[[0,2.18,32.83],[1,1.25,100],[2,1.08,7.82]],"ltp":2.26,"tv":64.11,"id":475559}]}]}
{"op":"mcm","clk":"11840673883","pt":1723550607252,"mc":[{"id":"1.231702167","rc":[{"batb":[[0,2.2,10],[1,2.18,32.83],[2,1.25,100]],"ltp":2.26,"tv":64.11,"id":475559}]}]}
{"op":"mcm","clk":"11840674182","pt":1723550610954,"mc":[{"id":"1.231702167","rc":[{"batb":[[0,2.18,32.83],[1,1.25,100],[2,1.08,7.82]],"ltp":2.26,"tv":64.11,"id":475559}]}]}
{"op":"mcm","clk":"11840674414","pt":1723550614437,"mc":[{"id":"1.231702167","rc":[{"batb":[[0,2.2,10],[1,2.18,32.83],[2,1.25,100]],"ltp":2.26,"tv":64.11,"id":475559}]}]}
{"op":"mcm","clk":"11840674630","pt":1723550617724,"mc":[{"id":"1.231702167","rc":[{"batb":[[0,2.18,32.83],[1,1.25,100],[2,1.08,7.82]],"ltp":2.26,"tv":64.11,"id":475559}]}]}
{"op":"mcm","clk":"11840675007","pt":1723550623128,"mc":[{"id":"1.231702167","rc":[{"batb":[[0,2.2,10],[1,2.18,32.83],[2,1.25,100]],"ltp":2.26,"tv":64.11,"id":475559}]}]}
{"op":"mcm","clk":"11840675218","pt":1723550626466,"mc":[{"id":"1.231702167","rc":[{"batb":[[0,2.18,32.83],[1,1.25,100],[2,1.08,7.82]],"ltp":2.26,"tv":64.11,"id":475559}]}]}
{"op":"mcm","clk":"11840675682","pt":1723550633034,"mc":[{"id":"1.231702167","rc":[{"batb":[[0,2.2,10],[1,2.18,32.83],[2,1.25,100]],"ltp":2.26,"tv":64.11,"id":475559}]}]}
{"op":"mcm","clk":"11840675910","pt":1723550636454,"mc":[{"id":"1.231702167","rc":[{"batb":[[0,2.18,32.83],[1,1.25,100],[2,1.08,7.82]],"ltp":2.26,"tv":64.11,"id":475559}]}]}
{"op":"mcm","clk":"11840676138","pt":1723550639839,"mc":[{"id":"1.231702167","rc":[{"batb":[[0,2.2,10],[1,2.18,32.83],[2,1.25,100]],"ltp":2.26,"tv":64.11,"id":475559}]}]}
{"op":"mcm","clk":"11840676357","pt":1723550643085,"mc":[{"id":"1.231702167","rc":[{"batb":[[0,2.18,32.83],[1,1.25,100],[2,1.08,7.82]],"ltp":2.26,"tv":64.11,"id":475559}]}]}
{"op":"mcm","clk":"11840676625","pt":1723550646787,"mc":[{"id":"1.231702167","rc":[{"batb":[[0,2.2,10],[1,2.18,32.83],[2,1.25,100]],"ltp":2.26,"tv":64.11,"id":475559}]}]}
{"op":"mcm","clk":"11840676867","pt":1723550650290,"mc":[{"id":"1.231702167","rc":[{"batb":[[0,2.18,32.83],[1,1.25,100],[2,1.08,7.82]],"ltp":2.26,"tv":64.11,"id":475559}]}]}
{"op":"mcm","clk":"11840677107","pt":1723550653377,"mc":[{"id":"1.231702167","rc":[{"batb":[[0,2.2,10],[1,2.18,32.83],[2,1.25,100]],"ltp":2.26,"tv":64.11,"id":475559}]}]}
{"op":"mcm","clk":"11840677359","pt":1723550656982,"mc":[{"id":"1.231702167","rc":[{"batb":[[0,2.18,32.83],[1,1.25,100],[2,1.08,7.82]],"ltp":2.26,"tv":64.11,"id":475559}]}]}
{"op":"mcm","clk":"11840677644","pt":1723550661596,"mc":[{"id":"1.231702167","rc":[{"batb":[[0,2.2,10],[1,2.18,32.83],[2,1.25,100]],"ltp":2.26,"tv":64.11,"id":475559}]}]}
{"op":"mcm","clk":"11840677842","pt":1723550664890,"mc":[{"id":"1.231702167","rc":[{"batb":[[0,2.18,32.83],[1,1.25,100],[2,1.08,7.82]],"ltp":2.26,"tv":64.11,"id":475559}]}]}
{"op":"mcm","clk":"11840678625","pt":1723550675596,"mc":[{"id":"1.231702167","rc":[{"batb":[[0,2.2,10],[1,2.18,32.83],[2,1.25,100]],"ltp":2.26,"tv":64.11,"id":475559}]}]}
{"op":"mcm","clk":"11840678891","pt":1723550678888,"mc":[{"id":"1.231702167","rc":[{"batb":[[0,2.18,32.83],[1,1.25,100],[2,1.08,7.82]],"ltp":2.26,"tv":64.11,"id":475559}]}]}
{"op":"mcm","clk":"11840679375","pt":1723550685427,"mc":[{"id":"1.231702167","rc":[{"batb":[[0,2.2,10],[1,2.18,32.83],[2,1.25,100]],"ltp":2.26,"tv":64.11,"id":475559}]}]}
{"op":"mcm","clk":"11840679624","pt":1723550688824,"mc":[{"id":"1.231702167","rc":[{"batb":[[0,2.18,32.83],[1,1.25,100],[2,1.08,7.82]],"ltp":2.26,"tv":64.11,"id":475559}]}]}
{"op":"mcm","clk":"11840679904","pt":1723550692526,"mc":[{"id":"1.231702167","rc":[{"batb":[[0,2.2,10],[1,2.18,32.83],[2,1.25,100]],"ltp":2.26,"tv":64.11,"id":475559}]}]}
{"op":"mcm","clk":"11840680174","pt":1723550696126,"mc":[{"id":"1.231702167","rc":[{"batb":[[0,2.18,32.83],[1,1.25,100],[2,1.08,7.82]],"ltp":2.26,"tv":64.11,"id":475559}]}]}
{"op":"mcm","clk":"11840680335","pt":1723550698541,"mc":[{"id":"1.231702167","rc":[{"batb":[[0,2.2,10],[1,2.18,32.83],[2,1.25,100]],"ltp":2.26,"tv":64.11,"id":475559}]}]}
{"op":"mcm","clk":"11840680686","pt":1723550701867,"mc":[{"id":"1.231702167","rc":[{"batb":[[0,2.18,32.83],[1,1.25,100],[2,1.08,7.82]],"ltp":2.26,"tv":64.11,"id":475559}]}]}
{"op":"mcm","clk":"11840680916","pt":1723550704758,"mc":[{"id":"1.231702167","rc":[{"batb":[[0,2.2,10],[1,2.18,32.83],[2,1.25,100]],"ltp":2.26,"tv":64.11,"id":475559}]}]}
{"op":"mcm","clk":"11840681169","pt":1723550708177,"mc":[{"id":"1.231702167","rc":[{"batb":[[0,2.18,32.83],[1,1.25,100],[2,1.08,7.82]],"ltp":2.26,"tv":64.11,"id":475559}]}]}
{"op":"mcm","clk":"11840681511","pt":1723550712982,"mc":[{"id":"1.231702167","rc":[{"batb":[[0,2.2,10],[1,2.18,32.83],[2,1.25,100]],"ltp":2.26,"tv":64.11,"id":475559}]}]}
{"op":"mcm","clk":"11840681829","pt":1723550717059,"mc":[{"id":"1.231702167","rc":[{"batb":[[0,2.18,32.83],[1,1.25,100],[2,1.08,7.82]],"ltp":2.26,"tv":64.11,"id":475559}]}]}
{"op":"mcm","clk":"11840682407","pt":1723550725813,"mc":[{"id":"1.231702167","rc":[{"batb":[[0,2.2,10],[1,2.18,32.83],[2,1.25,100]],"ltp":2.26,"tv":64.11,"id":475559}]}]}
{"op":"mcm","clk":"11840682664","pt":1723550729212,"mc":[{"id":"1.231702167","rc":[{"batb":[[0,2.18,32.83],[1,1.25,100],[2,1.08,7.82]],"ltp":2.26,"tv":64.11,"id":475559}]}]}
{"op":"mcm","clk":"11840682900","pt":1723550732401,"mc":[{"id":"1.231702167","rc":[{"batb":[[0,2.2,10],[1,2.18,32.83],[2,1.25,100]],"ltp":2.26,"tv":64.11,"id":475559}]}]}
{"op":"mcm","clk":"11840683142","pt":1723550735801,"mc":[{"id":"1.231702167","rc":[{"batb":[[0,2.18,32.83],[1,1.25,100],[2,1.08,7.82]],"ltp":2.26,"tv":64.11,"id":475559}]}]}
{"op":"mcm","clk":"11840683349","pt":1723550738430,"mc":[{"id":"1.231702167","rc":[{"batb":[[0,2.2,10],[1,2.18,32.83],[2,1.25,100]],"ltp":2.26,"tv":64.11,"id":475559}]}]}
{"op":"mcm","clk":"11840683563","pt":1723550741838,"mc":[{"id":"1.231702167","rc":[{"batb":[[0,2.18,32.83],[1,1.25,100],[2,1.08,7.82]],"ltp":2.26,"tv":64.11,"id":475559}]}]}
{"op":"mcm","clk":"11840684184","pt":1723550751120,"mc":[{"id":"1.231702167","rc":[{"batb":[[0,2.2,10],[1,2.18,32.83],[2,1.25,100]],"ltp":2.26,"tv":64.11,"id":475559}]}]}
{"op":"mcm","clk":"11840684411","pt":1723550754824,"mc":[{"id":"1.231702167","rc":[{"batb":[[0,2.18,32.83],[1,1.25,100],[2,1.08,7.82]],"ltp":2.26,"tv":64.11,"id":475559}]}]}
{"op":"mcm","clk":"11840684935","pt":1723550761317,"mc":[{"id":"1.231702167","rc":[{"batb":[[0,2.2,10],[1,2.18,32.83],[2,1.25,100]],"ltp":2.26,"tv":64.11,"id":475559}]}]}
{"op":"mcm","clk":"11840685211","pt":1723550764830,"mc":[{"id":"1.231702167","rc":[{"batb":[[0,2.18,32.83],[1,1.25,100],[2,1.08,7.82]],"ltp":2.26,"tv":64.11,"id":475559}]}]}
{"op":"mcm","clk":"11840685709","pt":1723550770651,"mc":[{"id":"1.231702167","rc":[{"batb":[[0,2.2,10],[1,2.18,32.83],[2,1.25,100]],"ltp":2.26,"tv":64.11,"id":475559}]}]}
{"op":"mcm","clk":"11840685993","pt":1723550774057,"mc":[{"id":"1.231702167","rc":[{"batb":[[0,2.18,32.83],[1,1.25,100],[2,1.08,7.82]],"ltp":2.26,"tv":64.11,"id":475559}]}]}
{"op":"mcm","clk":"11840686216","pt":1723550777257,"mc":[{"id":"1.231702167","rc":[{"batb":[[0,2.2,10],[1,2.18,32.83],[2,1.25,100]],"ltp":2.26,"tv":64.11,"id":475559}]}]}
{"op":"mcm","clk":"11840686459","pt":1723550780569,"mc":[{"id":"1.231702167","rc":[{"batb":[[0,2.18,32.83],[1,1.25,100],[2,1.08,7.82]],"ltp":2.26,"tv":64.11,"id":475559}]}]}
{"op":"mcm","clk":"11840686632","pt":1723550782838,"mc":[{"id":"1.231702167","rc":[{"batb":[[0,2.2,10],[1,2.18,32.83],[2,1.25,100]],"ltp":2.26,"tv":64.11,"id":475559}]}]}
{"op":"mcm","clk":"11840686862","pt":1723550786350,"mc":[{"id":"1.231702167","rc":[{"batb":[[0,2.18,32.83],[1,1.25,100],[2,1.08,7.82]],"ltp":2.26,"tv":64.11,"id":475559}]}]}
{"op":"mcm","clk":"11840687019","pt":1723550788768,"mc":[{"id":"1.231702167","rc":[{"batb":[[0,2.2,10],[1,2.18,32.83],[2,1.25,100]],"ltp":2.26,"tv":64.11,"id":475559}]}]}
{"op":"mcm","clk":"11840687270","pt":1723550792168,"mc":[{"id":"1.231702167","rc":[{"batb":[[0,2.18,32.83],[1,1.25,100],[2,1.08,7.82]],"ltp":2.26,"tv":64.11,"id":475559}]}]}
{"op":"mcm","clk":"11840687557","pt":1723550795786,"mc":[{"id":"1.231702167","rc":[{"batb":[[0,2.2,10],[1,2.18,32.83],[2,1.25,100]],"ltp":2.26,"tv":64.11,"id":475559}]}]}
{"op":"mcm","clk":"11840687813","pt":1723550799096,"mc":[{"id":"1.231702167","rc":[{"batb":[[0,2.18,32.83],[1,1.25,100],[2,1.08,7.82]],"ltp":2.26,"tv":64.11,"id":475559}]}]}
{"op":"mcm","clk":"11840688224","pt":1723550804565,"mc":[{"id":"1.231702167","rc":[{"batb":[[0,2.2,10],[1,2.18,32.83],[2,1.25,100]],"ltp":2.26,"tv":64.11,"id":475559}]}]}
{"op":"mcm","clk":"11840688516","pt":1723550808287,"mc":[{"id":"1.231702167","rc":[{"batb":[[0,2.18,32.83],[1,1.25,100],[2,1.08,7.82]],"ltp":2.26,"tv":64.11,"id":475559}]}]}
{"op":"mcm","clk":"11840688719","pt":1723550811192,"mc":[{"id":"1.231702167","rc":[{"batb":[[0,2.2,10],[1,2.18,32.83],[2,1.25,100]],"ltp":2.26,"tv":64.11,"id":475559}]}]}
{"op":"mcm","clk":"11840689070","pt":1723550815780,"mc":[{"id":"1.231702167","rc":[{"batb":[[0,2.18,32.83],[1,1.25,100],[2,1.08,7.82]],"ltp":2.26,"tv":64.11,"id":475559}]}]}
{"op":"mcm","clk":"11840689245","pt":1723550818205,"mc":[{"id":"1.231702167","rc":[{"batb":[[0,2.2,10],[1,2.18,32.83],[2,1.25,100]],"ltp":2.26,"tv":64.11,"id":475559}]}]}
{"op":"mcm","clk":"11840689554","pt":1723550821618,"mc":[{"id":"1.231702167","rc":[{"batb":[[0,2.18,32.83],[1,1.25,100],[2,1.08,7.82]],"ltp":2.26,"tv":64.11,"id":475559}]}]}
{"op":"mcm","clk":"11840690187","pt":1723550829184,"mc":[{"id":"1.231702167","rc":[{"batb":[[0,2.2,10],[1,2.18,32.83],[2,1.25,100]],"ltp":2.26,"tv":64.11,"id":475559}]}]}
{"op":"mcm","clk":"11840690461","pt":1723550832609,"mc":[{"id":"1.231702167","rc":[{"batb":[[0,2.18,32.83],[1,1.25,100],[2,1.08,7.82]],"ltp":2.26,"tv":64.11,"id":475559}]}]}
{"op":"mcm","clk":"11840690750","pt":1723550836235,"mc":[{"id":"1.231702167","rc":[{"batb":[[0,2.2,10],[1,2.18,32.83],[2,1.25,100]],"ltp":2.26,"tv":64.11,"id":475559}]}]}
{"op":"mcm","clk":"11840691022","pt":1723550839704,"mc":[{"id":"1.231702167","rc":[{"batb":[[0,2.18,32.83],[1,1.25,100],[2,1.08,7.82]],"ltp":2.26,"tv":64.11,"id":475559}]}]}
{"op":"mcm","clk":"11840691353","pt":1723550844205,"mc":[{"id":"1.231702167","rc":[{"batb":[[0,2.2,10],[1,2.18,32.83],[2,1.25,100]],"ltp":2.26,"tv":64.11,"id":475559}]}]}
{"op":"mcm","clk":"11840691635","pt":1723550847432,"mc":[{"id":"1.231702167","rc":[{"batb":[[0,2.18,32.83],[1,1.25,100],[2,1.08,7.82]],"ltp":2.26,"tv":64.11,"id":475559}]}]}
{"op":"mcm","clk":"11840692186","pt":1723550854011,"mc":[{"id":"1.231702167","rc":[{"batb":[[0,2.2,10],[1,2.18,32.83],[2,1.25,100]],"ltp":2.26,"tv":64.11,"id":475559}]}]}
{"op":"mcm","clk":"11840692467","pt":1723550857521,"mc":[{"id":"1.231702167","rc":[{"batb":[[0,2.18,32.83],[1,1.25,100],[2,1.08,7.82]],"ltp":2.26,"tv":64.11,"id":475559}]}]}
{"op":"mcm","clk":"11840693063","pt":1723550865343,"mc":[{"id":"1.231702167","rc":[{"batb":[[0,2.2,10],[1,2.18,32.83],[2,1.25,100]],"ltp":2.26,"tv":64.11,"id":475559}]}]}
{"op":"mcm","clk":"11840693310","pt":1723550868848,"mc":[{"id":"1.231702167","rc":[{"batb":[[0,2.18,32.83],[1,1.25,100],[2,1.08,7.82]],"ltp":2.26,"tv":64.11,"id":475559}]}]}
{"op":"mcm","clk":"11840693588","pt":1723550872821,"mc":[{"id":"1.231702167","rc":[{"batb":[[0,2.2,10],[1,2.18,32.83],[2,1.25,100]],"ltp":2.26,"tv":64.11,"id":475559}]}]}
{"op":"mcm","clk":"11840693795","pt":1723550876333,"mc":[{"id":"1.231702167","rc":[{"batb":[[0,2.18,32.83],[1,1.25,100],[2,1.08,7.82]],"ltp":2.26,"tv":64.11,"id":475559}]}]}
{"op":"mcm","clk":"11840694015","pt":1723550879645,"mc":[{"id":"1.231702167","rc":[{"batb":[[0,2.2,10],[1,2.18,32.83],[2,1.25,100]],"ltp":2.26,"tv":64.11,"id":475559}]}]}
{"op":"mcm","clk":"11840694262","pt":1723550883224,"mc":[{"id":"1.231702167","rc":[{"batb":[[0,2.18,32.83],[1,1.25,100],[2,1.08,7.82]],"ltp":2.26,"tv":64.11,"id":475559}]}]}
{"op":"mcm","clk":"11840694426","pt":1723550885542,"mc":[{"id":"1.231702167","rc":[{"batb":[[0,2.2,10],[1,2.18,32.83],[2,1.25,100]],"ltp":2.26,"tv":64.11,"id":475559}]}]}
{"op":"mcm","clk":"11840694670","pt":1723550889259,"mc":[{"id":"1.231702167","rc":[{"batb":[[0,2.18,32.83],[1,1.25,100],[2,1.08,7.82]],"ltp":2.26,"tv":64.11,"id":475559}]}]}
{"op":"mcm","clk":"11840695032","pt":1723550894968,"mc":[{"id":"1.231702167","rc":[{"batb":[[0,2.2,10],[1,2.18,32.83],[2,1.25,100]],"ltp":2.26,"tv":64.11,"id":475559}]}]}
{"op":"mcm","clk":"11840695261","pt":1723550898359,"mc":[{"id":"1.231702167","rc":[{"batb":[[0,2.18,32.83],[1,1.25,100],[2,1.08,7.82]],"ltp":2.26,"tv":64.11,"id":475559}]}]}
{"op":"mcm","clk":"11840695851","pt":1723550909050,"mc":[{"id":"1.231702167","rc":[{"batb":[[0,2.2,10],[1,2.18,32.83],[2,1.25,100]],"ltp":2.26,"tv":64.11,"id":475559}]}]}
{"op":"mcm","clk":"11840696042","pt":1723550912390,"mc":[{"id":"1.231702167","rc":[{"batb":[[0,2.18,32.83],[1,1.25,100],[2,1.08,7.82]],"ltp":2.26,"tv":64.11,"id":475559}]}]}
{"op":"mcm","clk":"11840696459","pt":1723550918977,"mc":[{"id":"1.231702167","rc":[{"batb":[[0,2.2,10],[1,2.18,32.83],[2,1.25,100]],"ltp":2.26,"tv":64.11,"id":475559}]}]}
{"op":"mcm","clk":"11840696671","pt":1723550922484,"mc":[{"id":"1.231702167","rc":[{"batb":[[0,2.18,32.83],[1,1.25,100],[2,1.08,7.82]],"ltp":2.26,"tv":64.11,"id":475559}]}]}
{"op":"mcm","clk":"11840697067","pt":1723550929211,"mc":[{"id":"1.231702167","rc":[{"batb":[[0,2.2,10],[1,2.18,32.83],[2,1.25,100]],"ltp":2.26,"tv":64.11,"id":475559}]}]}
{"op":"mcm","clk":"11840697270","pt":1723550932763,"mc":[{"id":"1.231702167","rc":[{"batb":[[0,2.18,32.83],[1,1.25,100],[2,1.08,7.82]],"ltp":2.26,"tv":64.11,"id":475559}]}]}
{"op":"mcm","clk":"11840697384","pt":1723550935083,"mc":[{"id":"1.231702167","rc":[{"batb":[[0,2.2,10],[1,2.18,32.83],[2,1.25,100]],"ltp":2.26,"tv":64.11,"id":475559}]}]}
{"op":"mcm","clk":"11840697564","pt":1723550938375,"mc":[{"id":"1.231702167","rc":[{"batb":[[0,2.18,32.83],[1,1.25,100],[2,1.08,7.82]],"ltp":2.26,"tv":64.11,"id":475559}]}]}
{"op":"mcm","clk":"11840698075","pt":1723550945901,"mc":[{"id":"1.231702167","rc":[{"batb":[[0,2.2,10],[1,2.18,32.83],[2,1.25,100]],"ltp":2.26,"tv":64.11,"id":475559}]}]}
{"op":"mcm","clk":"11840698319","pt":1723550949297,"mc":[{"id":"1.231702167","rc":[{"batb":[[0,2.18,32.83],[1,1.25,100],[2,1.08,7.82]],"ltp":2.26,"tv":64.11,"id":475559}]}]}
{"op":"mcm","clk":"11840699501","pt":1723550966919,"mc":[{"id":"1.231702167","rc":[{"batb":[[0,2.2,10],[1,2.18,32.83],[2,1.25,100]],"ltp":2.26,"tv":64.11,"id":475559}]}]}
{"op":"mcm","clk":"11840699720","pt":1723550970420,"mc":[{"id":"1.231702167","rc":[{"batb":[[0,2.18,32.83],[1,1.25,100],[2,1.08,7.82]],"ltp":2.26,"tv":64.11,"id":475559}]}]}
{"op":"mcm","clk":"11840699902","pt":1723550973619,"mc":[{"id":"1.231702167","rc":[{"batb":[[0,2.2,10],[1,2.18,32.83],[2,1.25,100]],"ltp":2.26,"tv":64.11,"id":475559}]}]}
{"op":"mcm","clk":"11840700119","pt":1723550977237,"mc":[{"id":"1.231702167","rc":[{"batb":[[0,2.18,32.83],[1,1.25,100],[2,1.08,7.82]],"ltp":2.26,"tv":64.11,"id":475559}]}]}
{"op":"mcm","clk":"11840700615","pt":1723550985962,"mc":[{"id":"1.231702167","rc":[{"batb":[[0,2.2,10],[1,2.18,32.83],[2,1.25,100]],"ltp":2.26,"tv":64.11,"id":475559}]}]}
{"op":"mcm","clk":"11840700825","pt":1723550989534,"mc":[{"id":"1.231702167","rc":[{"batb":[[0,2.18,32.83],[1,1.25,100],[2,1.08,7.82]],"ltp":2.26,"tv":64.11,"id":475559}]}]}
{"op":"mcm","clk":"11840701342","pt":1723550998776,"mc":[{"id":"1.231702167","rc":[{"batb":[[0,2.2,10],[1,2.18,32.83],[2,1.25,100]],"ltp":2.26,"tv":64.11,"id":475559}]}]}
{"op":"mcm","clk":"11840701530","pt":1723551002090,"mc":[{"id":"1.231702167","rc":[{"batb":[[0,2.18,32.83],[1,1.25,100],[2,1.08,7.82]],"ltp":2.26,"tv":64.11,"id":475559}]}]}
{"op":"mcm","clk":"11840702254","pt":1723551012604,"mc":[{"id":"1.231702167","rc":[{"batb":[[0,2.2,10],[1,2.18,32.83],[2,1.25,100]],"ltp":2.26,"tv":64.11,"id":475559}]}]}
{"op":"mcm","clk":"11840702473","pt":1723551016073,"mc":[{"id":"1.231702167","rc":[{"batb":[[0,2.18,32.83],[1,1.25,100],[2,1.08,7.82]],"ltp":2.26,"tv":64.11,"id":475559}]}]}
{"op":"mcm","clk":"11840703588","pt":1723551033518,"mc":[{"id":"1.231702167","rc":[{"batb":[[0,2.2,10],[1,2.18,32.83],[2,1.25,100]],"ltp":2.26,"tv":64.11,"id":475559}]}]}
{"op":"mcm","clk":"11840703837","pt":1723551037117,"mc":[{"id":"1.231702167","rc":[{"batb":[[0,2.18,32.83],[1,1.25,100],[2,1.08,7.82]],"ltp":2.26,"tv":64.11,"id":475559}]}]}
{"op":"mcm","clk":"11840704120","pt":1723551041044,"mc":[{"id":"1.231702167","rc":[{"batb":[[0,2.2,10],[1,2.18,32.83],[2,1.25,100]],"ltp":2.26,"tv":64.11,"id":475559}]}]}
{"op":"mcm","clk":"11840704395","pt":1723551044752,"mc":[{"id":"1.231702167","rc":[{"batb":[[0,2.18,32.83],[1,1.25,100],[2,1.08,7.82]],"ltp":2.26,"tv":64.11,"id":475559}]}]}
{"op":"mcm","clk":"11840705037","pt":1723551054128,"mc":[{"id":"1.231702167","rc":[{"batb":[[0,2.2,10],[1,2.18,32.83],[2,1.25,100]],"ltp":2.26,"tv":64.11,"id":475559}]}]}
{"op":"mcm","clk":"11840705226","pt":1723551057665,"mc":[{"id":"1.231702167","rc":[{"batb":[[0,2.18,32.83],[1,1.25,100],[2,1.08,7.82]],"ltp":2.26,"tv":64.11,"id":475559}]}]}
{"op":"mcm","clk":"11840705438","pt":1723551060854,"mc":[{"id":"1.231702167","rc":[{"batb":[[0,2.2,10],[1,2.18,32.83],[2,1.25,100]],"ltp":2.26,"tv":64.11,"id":475559}]}]}
{"op":"mcm","clk":"11840705733","pt":1723551064560,"mc":[{"id":"1.231702167","rc":[{"batb":[[0,2.18,32.83],[1,1.25,100],[2,1.08,7.82]],"ltp":2.26,"tv":64.11,"id":475559}]}]}
{"op":"mcm","clk":"11840706092","pt":1723551069083,"mc":[{"id":"1.231702167","rc":[{"batb":[[0,2.2,10],[1,2.18,32.83],[2,1.25,100]],"ltp":2.26,"tv":64.11,"id":475559}]}]}
{"op":"mcm","clk":"11840706363","pt":1723551072476,"mc":[{"id":"1.231702167","rc":[{"batb":[[0,2.18,32.83],[1,1.25,100],[2,1.08,7.82]],"ltp":2.26,"tv":64.11,"id":475559}]}]}
{"op":"mcm","clk":"11840706949","pt":1723551080983,"mc":[{"id":"1.231702167","rc":[{"batb":[[0,2.2,10],[1,2.18,32.83],[2,1.25,100]],"ltp":2.26,"tv":64.11,"id":475559}]}]}
{"op":"mcm","clk":"11840707146","pt":1723551084272,"mc":[{"id":"1.231702167","rc":[{"batb":[[0,2.18,32.83],[1,1.25,100],[2,1.08,7.82]],"ltp":2.26,"tv":64.11,"id":475559}]}]}
{"op":"mcm","clk":"11840707624","pt":1723551093169,"mc":[{"id":"1.231702167","rc":[{"batb":[[0,2.2,10],[1,2.18,32.83],[2,1.25,100]],"ltp":2.26,"tv":64.11,"id":475559}]}]}
{"op":"mcm","clk":"11840707858","pt":1723551096672,"mc":[{"id":"1.231702167","rc":[{"batb":[[0,2.18,32.83],[1,1.25,100],[2,1.08,7.82]],"ltp":2.26,"tv":64.11,"id":475559}]}]}
{"op":"mcm","clk":"11840708046","pt":1723551099294,"mc":[{"id":"1.231702167","rc":[{"batb":[[0,2.2,10],[1,2.18,32.83],[2,1.25,100]],"ltp":2.26,"tv":64.11,"id":475559}]}]}
{"op":"mcm","clk":"11840708270","pt":1723551102687,"mc":[{"id":"1.231702167","rc":[{"batb":[[0,2.18,32.83],[1,1.25,100],[2,1.08,7.82]],"ltp":2.26,"tv":64.11,"id":475559}]}]}
{"op":"mcm","clk":"11840708459","pt":1723551105305,"mc":[{"id":"1.231702167","rc":[{"batb":[[0,2.2,10],[1,2.18,32.83],[2,1.25,100]],"ltp":2.26,"tv":64.11,"id":475559}]}]}
{"op":"mcm","clk":"11840708671","pt":1723551108602,"mc":[{"id":"1.231702167","rc":[{"batb":[[0,2.18,32.83],[1,1.25,100],[2,1.08,7.82]],"ltp":2.26,"tv":64.11,"id":475559}]}]}
{"op":"mcm","clk":"11840709065","pt":1723551114990,"mc":[{"id":"1.231702167","rc":[{"batb":[[0,2.2,10],[1,2.18,32.83],[2,1.25,100]],"ltp":2.26,"tv":64.11,"id":475559}]}]}
{"op":"mcm","clk":"11840709273","pt":1723551118488,"mc":[{"id":"1.231702167","rc":[{"batb":[[0,2.18,32.83],[1,1.25,100],[2,1.08,7.82]],"ltp":2.26,"tv":64.11,"id":475559}]}]}
{"op":"mcm","clk":"11840709445","pt":1723551121009,"mc":[{"id":"1.231702167","rc":[{"batb":[[0,2.2,10],[1,2.18,32.83],[2,1.25,100]],"ltp":2.26,"tv":64.11,"id":475559}]}]}
{"op":"mcm","clk":"11840709691","pt":1723551124524,"mc":[{"id":"1.231702167","rc":[{"batb":[[0,2.18,32.83],[1,1.25,100],[2,1.08,7.82]],"ltp":2.26,"tv":64.11,"id":475559}]}]}
{"op":"mcm","clk":"11840710104","pt":1723551130406,"mc":[{"id":"1.231702167","rc":[{"batb":[[0,2.2,10],[1,2.18,32.83],[2,1.25,100]],"ltp":2.26,"tv":64.11,"id":475559}]}]}
{"op":"mcm","clk":"11840710346","pt":1723551133905,"mc":[{"id":"1.231702167","rc":[{"batb":[[0,2.18,32.83],[1,1.25,100],[2,1.08,7.82]],"ltp":2.26,"tv":64.11,"id":475559}]}]}
{"op":"mcm","clk":"11840710540","pt":1723551137247,"mc":[{"id":"1.231702167","rc":[{"batb":[[0,2.2,10],[1,2.18,32.83],[2,1.25,100]],"ltp":2.26,"tv":64.11,"id":475559}]}]}
{"op":"mcm","clk":"11840710778","pt":1723551140542,"mc":[{"id":"1.231702167","rc":[{"batb":[[0,2.18,32.83],[1,1.25,100],[2,1.08,7.82]],"ltp":2.26,"tv":64.11,"id":475559}]}]}
{"op":"mcm","clk":"11840711021","pt":1723551143947,"mc":[{"id":"1.231702167","rc":[{"batb":[[0,2.2,10],[1,2.18,32.83],[2,1.25,100]],"ltp":2.26,"tv":64.11,"id":475559}]}]}
{"op":"mcm","clk":"11840711241","pt":1723551147655,"mc":[{"id":"1.231702167","rc":[{"batb":[[0,2.18,32.83],[1,1.25,100],[2,1.08,7.82]],"ltp":2.26,"tv":64.11,"id":475559}]}]}
{"op":"mcm","clk":"11840711568","pt":1723551152653,"mc":[{"id":"1.231702167","rc":[{"batb":[[0,2.2,10],[1,2.18,32.83],[2,1.25,100]],"ltp":2.26,"tv":64.11,"id":475559}]}]}
{"op":"mcm","clk":"11840711785","pt":1723551156051,"mc":[{"id":"1.231702167","rc":[{"batb":[[0,2.18,32.83],[1,1.25,100],[2,1.08,7.82]],"ltp":2.26,"tv":64.11,"id":475559}]}]}
{"op":"mcm","clk":"11840712030","pt":1723551159346,"mc":[{"id":"1.231702167","rc":[{"batb":[[0,2.2,10],[1,2.18,32.83],[2,1.25,100]],"ltp":2.26,"tv":64.11,"id":475559}]}]}
{"op":"mcm","clk":"11840712250","pt":1723551162752,"mc":[{"id":"1.231702167","rc":[{"batb":[[0,2.18,32.83],[1,1.25,100],[2,1.08,7.82]],"ltp":2.26,"tv":64.11,"id":475559}]}]}
{"op":"mcm","clk":"11840712467","pt":1723551165873,"mc":[{"id":"1.231702167","rc":[{"batb":[[0,2.2,10],[1,2.18,32.83],[2,1.25,100]],"ltp":2.26,"tv":64.11,"id":475559}]}]}
{"op":"mcm","clk":"11840712707","pt":1723551169276,"mc":[{"id":"1.231702167","rc":[{"batb":[[0,2.18,32.83],[1,1.25,100],[2,1.08,7.82]],"ltp":2.26,"tv":64.11,"id":475559}]}]}
{"op":"mcm","clk":"11840712922","pt":1723551172566,"mc":[{"id":"1.231702167","rc":[{"batb":[[0,2.2,10],[1,2.18,32.83],[2,1.25,100]],"ltp":2.26,"tv":64.11,"id":475559}]}]}
{"op":"mcm","clk":"11840720289","pt":1723551176082,"mc":[{"id":"1.231702167","rc":[{"batb":[[0,2.18,32.83],[1,1.25,100],[2,1.08,7.82]],"ltp":2.26,"tv":64.11,"id":475559}]}]}
{"op":"mcm","clk":"11840720597","pt":1723551180302,"mc":[{"id":"1.231702167","rc":[{"batb":[[0,2.2,10],[1,2.18,32.83],[2,1.25,100]],"ltp":2.26,"tv":64.11,"id":475559}]}]}
{"op":"mcm","clk":"11840720838","pt":1723551183678,"mc":[{"id":"1.231702167","rc":[{"batb":[[0,2.18,32.83],[1,1.25,100],[2,1.08,7.82]],"ltp":2.26,"tv":64.11,"id":475559}]}]}
{"op":"mcm","clk":"11840721045","pt":1723551186666,"mc":[{"id":"1.231702167","rc":[{"batb":[[0,2.2,10],[1,2.18,32.83],[2,1.25,100]],"ltp":2.26,"tv":64.11,"id":475559}]}]}
{"op":"mcm","clk":"11840721274","pt":1723551190222,"mc":[{"id":"1.231702167","rc":[{"batb":[[0,2.18,32.83],[1,1.25,100],[2,1.08,7.82]],"ltp":2.26,"tv":64.11,"id":475559}]}]}
{"op":"mcm","clk":"11840721658","pt":1723551195293,"mc":[{"id":"1.231702167","rc":[{"batb":[[0,2.2,10],[1,2.18,32.83],[2,1.25,100]],"ltp":2.26,"tv":64.11,"id":475559}]}]}
{"op":"mcm","clk":"11840721877","pt":1723551198691,"mc":[{"id":"1.231702167","rc":[{"batb":[[0,2.18,32.83],[1,1.25,100],[2,1.08,7.82]],"ltp":2.26,"tv":64.11,"id":475559}]}]}
{"op":"mcm","clk":"11840722136","pt":1723551202513,"mc":[{"id":"1.231702167","rc":[{"batb":[[0,2.2,10],[1,2.18,32.83],[2,1.25,100]],"ltp":2.26,"tv":64.11,"id":475559}]}]}
{"op":"mcm","clk":"11840722363","pt":1723551205924,"mc":[{"id":"1.231702167","rc":[{"batb":[[0,2.18,32.83],[1,1.25,100],[2,1.08,7.82]],"ltp":2.26,"tv":64.11,"id":475559}]}]}
{"op":"mcm","clk":"11840723047","pt":1723551216037,"mc":[{"id":"1.231702167","rc":[{"batb":[[0,2.2,10],[1,2.18,32.83],[2,1.25,100]],"ltp":2.26,"tv":64.11,"id":475559}]}]}
{"op":"mcm","clk":"11840723298","pt":1723551219214,"mc":[{"id":"1.231702167","rc":[{"batb":[[0,2.18,32.83],[1,1.25,100],[2,1.08,7.82]],"ltp":2.26,"tv":64.11,"id":475559}]}]}
{"op":"mcm","clk":"11840723549","pt":1723551222517,"mc":[{"id":"1.231702167","rc":[{"batb":[[0,2.2,10],[1,2.18,32.83],[2,1.25,100]],"ltp":2.26,"tv":64.11,"id":475559}]}]}
{"op":"mcm","clk":"11840723820","pt":1723551226141,"mc":[{"id":"1.231702167","rc":[{"batb":[[0,2.18,32.83],[1,1.25,100],[2,1.08,7.82]],"ltp":2.26,"tv":64.11,"id":475559}]}]}
{"op":"mcm","clk":"11840724129","pt":1723551230412,"mc":[{"id":"1.231702167","rc":[{"batb":[[0,2.2,10],[1,2.18,32.83],[2,1.25,100]],"ltp":2.26,"tv":64.11,"id":475559}]}]}
{"op":"mcm","clk":"11840724377","pt":1723551233913,"mc":[{"id":"1.231702167","rc":[{"batb":[[0,2.18,32.83],[1,1.25,100],[2,1.08,7.82]],"ltp":2.26,"tv":64.11,"id":475559}]}]}
{"op":"mcm","clk":"11840724594","pt":1723551237353,"mc":[{"id":"1.231702167","rc":[{"batb":[[0,2.2,10],[1,2.18,32.83],[2,1.25,100]],"ltp":2.26,"tv":64.11,"id":475559}]}]}
{"op":"mcm","clk":"11840724861","pt":1723551240655,"mc":[{"id":"1.231702167","rc":[{"batb":[[0,2.18,32.83],[1,1.25,100],[2,1.08,7.82]],"ltp":2.26,"tv":64.11,"id":475559}]}]}
{"op":"mcm","clk":"11840725053","pt":1723551243036,"mc":[{"id":"1.231702167","rc":[{"batb":[[0,2.2,10],[1,2.18,32.83],[2,1.25,100]],"ltp":2.26,"tv":64.11,"id":475559}]}]}
{"op":"mcm","clk":"11840725306","pt":1723551246446,"mc":[{"id":"1.231702167","rc":[{"batb":[[0,2.18,32.83],[1,1.25,100],[2,1.08,7.82]],"ltp":2.26,"tv":64.11,"id":475559}]}]}
{"op":"mcm","clk":"11840725666","pt":1723551251043,"mc":[{"id":"1.231702167","rc":[{"batb":[[0,2.2,10],[1,2.18,32.83],[2,1.25,100]],"ltp":2.26,"tv":64.11,"id":475559}]}]}
{"op":"mcm","clk":"11840725940","pt":1723551254572,"mc":[{"id":"1.231702167","rc":[{"batb":[[0,2.18,32.83],[1,1.25,100],[2,1.08,7.82]],"ltp":2.26,"tv":64.11,"id":475559}]}]}
{"op":"mcm","clk":"11840726901","pt":1723551267362,"mc":[{"id":"1.231702167","rc":[{"batb":[[0,2.2,10],[1,2.18,32.83],[2,1.25,100]],"ltp":2.26,"tv":64.11,"id":475559}]}]}
{"op":"mcm","clk":"11840727170","pt":1723551270872,"mc":[{"id":"1.231702167","rc":[{"batb":[[0,2.18,32.83],[1,1.25,100],[2,1.08,7.82]],"ltp":2.26,"tv":64.11,"id":475559}]}]}
{"op":"mcm","clk":"11840728563","pt":1723551288693,"mc":[{"id":"1.231702167","rc":[{"batb":[[0,2.2,10],[1,2.18,32.83],[2,1.25,100]],"ltp":2.26,"tv":64.11,"id":475559}]}]}
{"op":"mcm","clk":"11840728855","pt":1723551292104,"mc":[{"id":"1.231702167","rc":[{"batb":[[0,2.18,32.83],[1,1.25,100],[2,1.08,7.82]],"ltp":2.26,"tv":64.11,"id":475559}]}]}
{"op":"mcm","clk":"11840729496","pt":1723551300509,"mc":[{"id":"1.231702167","rc":[{"batb":[[0,2.2,10],[1,2.18,32.83],[2,1.25,100]],"ltp":2.26,"tv":64.11,"id":475559}]}]}
{"op":"mcm","clk":"11840729785","pt":1723551303995,"mc":[{"id":"1.231702167","rc":[{"batb":[[0,2.18,32.83],[1,1.25,100],[2,1.08,7.82]],"ltp":2.26,"tv":64.11,"id":475559}]}]}
{"op":"mcm","clk":"11840730751","pt":1723551314897,"mc":[{"id":"1.231702167","rc":[{"batb":[[0,2.2,10],[1,2.18,32.83],[2,1.25,100]],"ltp":2.26,"tv":64.11,"id":475559}]}]}
{"op":"mcm","clk":"11840731023","pt":1723551318306,"mc":[{"id":"1.231702167","rc":[{"batb":[[0,2.18,32.83],[1,1.25,100],[2,1.08,7.82]],"ltp":2.26,"tv":64.11,"id":475559}]}]}
{"op":"mcm","clk":"11840731279","pt":1723551321809,"mc":[{"id":"1.231702167","rc":[{"batb":[[0,2.2,10],[1,2.18,32.83],[2,1.25,100]],"ltp":2.26,"tv":64.11,"id":475559}]}]}
{"op":"mcm","clk":"11840731524","pt":1723551325255,"mc":[{"id":"1.231702167","rc":[{"batb":[[0,2.18,32.83],[1,1.25,100],[2,1.08,7.82]],"ltp":2.26,"tv":64.11,"id":475559}]}]}
{"op":"mcm","clk":"11840731757","pt":1723551328245,"mc":[{"id":"1.231702167","rc":[{"batb":[[0,2.2,10],[1,2.18,32.83],[2,1.25,100]],"ltp":2.26,"tv":64.11,"id":475559}]}]}
{"op":"mcm","clk":"11840732053","pt":1723551331744,"mc":[{"id":"1.231702167","rc":[{"batb":[[0,2.18,32.83],[1,1.25,100],[2,1.08,7.82]],"ltp":2.26,"tv":64.11,"id":475559}]}]}
{"op":"mcm","clk":"11840733308","pt":1723551348877,"mc":[{"id":"1.231702167","rc":[{"batb":[[0,2.2,10],[1,2.18,32.83],[2,1.25,100]],"ltp":2.26,"tv":64.11,"id":475559}]}]}
{"op":"mcm","clk":"11840733601","pt":1723551352173,"mc":[{"id":"1.231702167","rc":[{"batb":[[0,2.18,32.83],[1,1.25,100],[2,1.08,7.82]],"ltp":2.26,"tv":64.11,"id":475559}]}]}
{"op":"mcm","clk":"11840733975","pt":1723551356854,"mc":[{"id":"1.231702167","rc":[{"batb":[[0,2.2,10],[1,2.18,32.83],[2,1.25,100]],"ltp":2.26,"tv":64.11,"id":475559}]}]}
{"op":"mcm","clk":"11840734243","pt":1723551360270,"mc":[{"id":"1.231702167","rc":[{"batb":[[0,2.18,32.83],[1,1.25,100],[2,1.08,7.82]],"ltp":2.26,"tv":64.11,"id":475559}]}]}
{"op":"mcm","clk":"11840734483","pt":1723551363169,"mc":[{"id":"1.231702167","rc":[{"batb":[[0,2.2,10],[1,2.18,32.83],[2,1.25,100]],"ltp":2.26,"tv":64.11,"id":475559}]}]}
{"op":"mcm","clk":"11840734742","pt":1723551366463,"mc":[{"id":"1.231702167","rc":[{"batb":[[0,2.18,32.83],[1,1.25,100],[2,1.08,7.82]],"ltp":2.26,"tv":64.11,"id":475559}]}]}
{"op":"mcm","clk":"11840734985","pt":1723551369357,"mc":[{"id":"1.231702167","rc":[{"batb":[[0,2.2,10],[1,2.18,32.83],[2,1.25,100]],"ltp":2.26,"tv":64.11,"id":475559}]}]}
{"op":"mcm","clk":"11840735295","pt":1723551372770,"mc":[{"id":"1.231702167","rc":[{"batb":[[0,2.18,32.83],[1,1.25,100],[2,1.08,7.82]],"ltp":2.26,"tv":64.11,"id":475559}]}]}
{"op":"mcm","clk":"11840735581","pt":1723551375796,"mc":[{"id":"1.231702167","rc":[{"batb":[[0,2.2,10],[1,2.18,32.83],[2,1.25,100]],"ltp":2.26,"tv":64.11,"id":475559}]}]}
{"op":"mcm","clk":"11840735827","pt":1723551378978,"mc":[{"id":"1.231702167","rc":[{"batb":[[0,2.18,32.83],[1,1.25,100],[2,1.08,7.82]],"ltp":2.26,"tv":64.11,"id":475559}]}]}
{"op":"mcm","clk":"11840736027","pt":1723551381405,"mc":[{"id":"1.231702167","rc":[{"batb":[[0,2.2,10],[1,2.18,32.83],[2,1.25,100]],"ltp":2.26,"tv":64.11,"id":475559}]}]}
{"op":"mcm","clk":"11840736311","pt":1723551384904,"mc":[{"id":"1.231702167","rc":[{"batb":[[0,2.18,32.83],[1,1.25,100],[2,1.08,7.82]],"ltp":2.26,"tv":64.11,"id":475559}]}]}
{"op":"mcm","clk":"11840736622","pt":1723551388613,"mc":[{"id":"1.231702167","rc":[{"batb":[[0,2.2,10],[1,2.18,32.83],[2,1.25,100]],"ltp":2.26,"tv":64.11,"id":475559}]}]}
{"op":"mcm","clk":"11840736953","pt":1723551392011,"mc":[{"id":"1.231702167","rc":[{"batb":[[0,2.18,32.83],[1,1.25,100],[2,1.08,7.82]],"ltp":2.26,"tv":64.11,"id":475559}]}]}
{"op":"mcm","clk":"11840737169","pt":1723551394719,"mc":[{"id":"1.231702167","rc":[{"batb":[[0,2.2,10],[1,2.18,32.83],[2,1.25,100]],"ltp":2.26,"tv":64.11,"id":475559}]}]}
{"op":"mcm","clk":"11840737487","pt":1723551398286,"mc":[{"id":"1.231702167","rc":[{"batb":[[0,2.18,32.83],[1,1.25,100],[2,1.08,7.82]],"ltp":2.26,"tv":64.11,"id":475559}]}]}
{"op":"mcm","clk":"11840738302","pt":1723551408032,"mc":[{"id":"1.231702167","rc":[{"batb":[[0,2.2,10],[1,2.18,32.83],[2,1.25,100]],"ltp":2.26,"tv":64.11,"id":475559}]}]}
{"op":"mcm","clk":"11840738593","pt":1723551411604,"mc":[{"id":"1.231702167","rc":[{"batb":[[0,2.18,32.83],[1,1.25,100],[2,1.08,7.82]],"ltp":2.26,"tv":64.11,"id":475559}]}]}
{"op":"mcm","clk":"11840738932","pt":1723551415942,"mc":[{"id":"1.231702167","rc":[{"batb":[[0,2.2,10],[1,2.18,32.83],[2,1.25,100]],"ltp":2.26,"tv":64.11,"id":475559}]}]}
{"op":"mcm","clk":"11840739251","pt":1723551419318,"mc":[{"id":"1.231702167","rc":[{"batb":[[0,2.18,32.83],[1,1.25,100],[2,1.08,7.82]],"ltp":2.26,"tv":64.11,"id":475559}]}]}
{"op":"mcm","clk":"11840739795","pt":1723551426342,"mc":[{"id":"1.231702167","rc":[{"batb":[[0,2.2,10],[1,2.18,32.83],[2,1.25,100]],"ltp":2.26,"tv":64.11,"id":475559}]}]}
{"op":"mcm","clk":"11840740028","pt":1723551429647,"mc":[{"id":"1.231702167","rc":[{"batb":[[0,2.18,32.83],[1,1.25,100],[2,1.08,7.82]],"ltp":2.26,"tv":64.11,"id":475559}]}]}
{"op":"mcm","clk":"11840740305","pt":1723551432924,"mc":[{"id":"1.231702167","rc":[{"batb":[[0,2.2,10],[1,2.18,32.83],[2,1.25,100]],"ltp":2.26,"tv":64.11,"id":475559}]}]}
{"op":"mcm","clk":"11840740586","pt":1723551436237,"mc":[{"id":"1.231702167","rc":[{"batb":[[0,2.18,32.83],[1,1.25,100],[2,1.08,7.82]],"ltp":2.26,"tv":64.11,"id":475559}]}]}
{"op":"mcm","clk":"11840740897","pt":1723551440321,"mc":[{"id":"1.231702167","rc":[{"batb":[[0,2.2,10],[1,2.18,32.83],[2,1.25,100]],"ltp":2.26,"tv":64.11,"id":475559}]}]}
{"op":"mcm","clk":"11840741093","pt":1723551443665,"mc":[{"id":"1.231702167","rc":[{"batb":[[0,2.18,32.83],[1,1.25,100],[2,1.08,7.82]],"ltp":2.26,"tv":64.11,"id":475559}]}]}
{"op":"mcm","clk":"11840741336","pt":1723551447170,"mc":[{"id":"1.231702167","rc":[{"batb":[[0,2.2,10],[1,2.18,32.83],[2,1.25,100]],"ltp":2.26,"tv":64.11,"id":475559}]}]}
{"op":"mcm","clk":"11840741549","pt":1723551450876,"mc":[{"id":"1.231702167","rc":[{"batb":[[0,2.18,32.83],[1,1.25,100],[2,1.08,7.82]],"ltp":2.26,"tv":64.11,"id":475559}]}]}
{"op":"mcm","clk":"11840741932","pt":1723551457569,"mc":[{"id":"1.231702167","rc":[{"batb":[[0,2.2,10],[1,2.18,32.83],[2,1.25,100]],"ltp":2.26,"tv":64.11,"id":475559}]}]}
{"op":"mcm","clk":"11840742145","pt":1723551460857,"mc":[{"id":"1.231702167","rc":[{"batb":[[0,2.18,32.83],[1,1.25,100],[2,1.08,7.82]],"ltp":2.26,"tv":64.11,"id":475559}]}]}
{"op":"mcm","clk":"11840742300","pt":1723551463580,"mc":[{"id":"1.231702167","rc":[{"batb":[[0,2.2,10],[1,2.18,32.83],[2,1.25,100]],"ltp":2.26,"tv":64.11,"id":475559}]}]}
{"op":"mcm","clk":"11840742505","pt":1723551466951,"mc":[{"id":"1.231702167","rc":[{"batb":[[0,2.18,32.83],[1,1.25,100],[2,1.08,7.82]],"ltp":2.26,"tv":64.11,"id":475559}]}]}
{"op":"mcm","clk":"11840742987","pt":1723551474097,"mc":[{"id":"1.231702167","rc":[{"batb":[[0,2.2,10],[1,2.18,32.83],[2,1.25,100]],"ltp":2.26,"tv":64.11,"id":475559}]}]}
{"op":"mcm","clk":"11840743196","pt":1723551477494,"mc":[{"id":"1.231702167","rc":[{"batb":[[0,2.18,32.83],[1,1.25,100],[2,1.08,7.82]],"ltp":2.26,"tv":64.11,"id":475559}]}]}
{"op":"mcm","clk":"11840743458","pt":1723551481206,"mc":[{"id":"1.231702167","rc":[{"batb":[[0,2.2,10],[1,2.18,32.83],[2,1.25,100]],"ltp":2.26,"tv":64.11,"id":475559}]}]}
{"op":"mcm","clk":"11840743698","pt":1723551484474,"mc":[{"id":"1.231702167","rc":[{"batb":[[0,2.18,32.83],[1,1.25,100],[2,1.08,7.82]],"ltp":2.26,"tv":64.11,"id":475559}]}]}
{"op":"mcm","clk":"11840743935","pt":1723551488190,"mc":[{"id":"1.231702167","rc":[{"batb":[[0,2.2,10],[1,2.18,32.83],[2,1.25,100]],"ltp":2.26,"tv":64.11,"id":475559}]}]}
{"op":"mcm","clk":"11840744172","pt":1723551491587,"mc":[{"id":"1.231702167","rc":[{"batb":[[0,2.18,32.83],[1,1.25,100],[2,1.08,7.82]],"ltp":2.26,"tv":64.11,"id":475559}]}]}
{"op":"mcm","clk":"11840744526","pt":1723551496300,"mc":[{"id":"1.231702167","rc":[{"batb":[[0,2.2,10],[1,2.18,32.83],[2,1.25,100]],"ltp":2.26,"tv":64.11,"id":475559}]}]}
{"op":"mcm","clk":"11840744798","pt":1723551499810,"mc":[{"id":"1.231702167","rc":[{"batb":[[0,2.18,32.83],[1,1.25,100],[2,1.08,7.82]],"ltp":2.26,"tv":64.11,"id":475559}]}]}
{"op":"mcm","clk":"11840745338","pt":1723551507190,"mc":[{"id":"1.231702167","rc":[{"batb":[[0,2.2,10],[1,2.18,32.83],[2,1.25,100]],"ltp":2.26,"tv":64.11,"id":475559}]}]}
{"op":"mcm","clk":"11840745593","pt":1723551510509,"mc":[{"id":"1.231702167","rc":[{"batb":[[0,2.18,32.83],[1,1.25,100],[2,1.08,7.82]],"ltp":2.26,"tv":64.11,"id":475559}]}]}
{"op":"mcm","clk":"11840745857","pt":1723551513821,"mc":[{"id":"1.231702167","rc":[{"batb":[[0,2.2,10],[1,2.18,32.83],[2,1.25,100]],"ltp":2.26,"tv":64.11,"id":475559}]}]}
{"op":"mcm","clk":"11840746120","pt":1723551517337,"mc":[{"id":"1.231702167","rc":[{"batb":[[0,2.18,32.83],[1,1.25,100],[2,1.08,7.82]],"ltp":2.26,"tv":64.11,"id":475559}]}]}
{"op":"mcm","clk":"11840746411","pt":1723551521529,"mc":[{"id":"1.231702167","rc":[{"batb":[[0,2.2,10],[1,2.18,32.83],[2,1.25,100]],"ltp":2.26,"tv":64.11,"id":475559}]}]}
{"op":"mcm","clk":"11840746644","pt":1723551525033,"mc":[{"id":"1.231702167","rc":[{"batb":[[0,2.18,32.83],[1,1.25,100],[2,1.08,7.82]],"ltp":2.26,"tv":64.11,"id":475559}]}]}
{"op":"mcm","clk":"11840746840","pt":1723551528124,"mc":[{"id":"1.231702167","rc":[{"batb":[[0,2.2,10],[1,2.18,32.83],[2,1.25,100]],"ltp":2.26,"tv":64.11,"id":475559}]}]}
{"op":"mcm","clk":"11840747057","pt":1723551531428,"mc":[{"id":"1.231702167","rc":[{"batb":[[0,2.18,32.83],[1,1.25,100],[2,1.08,7.82]],"ltp":2.26,"tv":64.11,"id":475559}]}]}
{"op":"mcm","clk":"11840747606","pt":1723551539132,"mc":[{"id":"1.231702167","rc":[{"batb":[[0,2.2,10],[1,2.18,32.83],[2,1.25,100]],"ltp":2.26,"tv":64.11,"id":475559}]}]}
{"op":"mcm","clk":"11840747829","pt":1723551542657,"mc":[{"id":"1.231702167","rc":[{"batb":[[0,2.18,32.83],[1,1.25,100],[2,1.08,7.82]],"ltp":2.26,"tv":64.11,"id":475559}]}]}
{"op":"mcm","clk":"11840748106","pt":1723551547248,"mc":[{"id":"1.231702167","rc":[{"batb":[[0,2.2,10],[1,2.18,32.83],[2,1.25,100]],"ltp":2.26,"tv":64.11,"id":475559}]}]}
{"op":"mcm","clk":"11840748337","pt":1723551550652,"mc":[{"id":"1.231702167","rc":[{"batb":[[0,2.18,32.83],[1,1.25,100],[2,1.08,7.82]],"ltp":2.26,"tv":64.11,"id":475559}]}]}
{"op":"mcm","clk":"11840748521","pt":1723551553247,"mc":[{"id":"1.231702167","rc":[{"batb":[[0,2.2,10],[1,2.18,32.83],[2,1.25,100]],"ltp":2.26,"tv":64.11,"id":475559}]}]}
{"op":"mcm","clk":"11840748714","pt":1723551556755,"mc":[{"id":"1.231702167","rc":[{"batb":[[0,2.18,32.83],[1,1.25,100],[2,1.08,7.82]],"ltp":2.26,"tv":64.11,"id":475559}]}]}
{"op":"mcm","clk":"11840748915","pt":1723551561294,"mc":[{"id":"1.231702167","rc":[{"batb":[[0,2.2,10],[1,2.18,32.83],[2,1.25,100]],"ltp":2.26,"tv":64.11,"id":475559}]}]}
{"op":"mcm","clk":"11840749065","pt":1723551564585,"mc":[{"id":"1.231702167","rc":[{"batb":[[0,2.18,32.83],[1,1.25,100],[2,1.08,7.82]],"ltp":2.26,"tv":64.11,"id":475559}]}]}
{"op":"mcm","clk":"11840749193","pt":1723551567163,"mc":[{"id":"1.231702167","rc":[{"batb":[[0,2.2,10],[1,2.18,32.83],[2,1.25,100]],"ltp":2.26,"tv":64.11,"id":475559}]}]}
{"op":"mcm","clk":"11840749413","pt":1723551570871,"mc":[{"id":"1.231702167","rc":[{"batb":[[0,2.18,32.83],[1,1.25,100],[2,1.08,7.82]],"ltp":2.26,"tv":64.11,"id":475559}]}]}
{"op":"mcm","clk":"11840749604","pt":1723551573915,"mc":[{"id":"1.231702167","rc":[{"batb":[[0,2.2,10],[1,2.18,32.83],[2,1.25,100]],"ltp":2.26,"tv":64.11,"id":475559}]}]}
{"op":"mcm","clk":"11840749808","pt":1723551577368,"mc":[{"id":"1.231702167","rc":[{"batb":[[0,2.18,32.83],[1,1.25,100],[2,1.08,7.82]],"ltp":2.26,"tv":64.11,"id":475559}]}]}
{"op":"mcm","clk":"11840750032","pt":1723551581695,"mc":[{"id":"1.231702167","rc":[{"batb":[[0,2.2,10],[1,2.18,32.83],[2,1.25,100]],"ltp":2.26,"tv":64.11,"id":475559}]}]}
{"op":"mcm","clk":"11840750247","pt":1723551585104,"mc":[{"id":"1.231702167","rc":[{"batb":[[0,2.18,32.83],[1,1.25,100],[2,1.08,7.82]],"ltp":2.26,"tv":64.11,"id":475559}]}]}
{"op":"mcm","clk":"11840750500","pt":1723551589706,"mc":[{"id":"1.231702167","rc":[{"batb":[[0,2.2,10],[1,2.18,32.83],[2,1.25,100]],"ltp":2.26,"tv":64.11,"id":475559}]}]}
{"op":"mcm","clk":"11840750700","pt":1723551593118,"mc":[{"id":"1.231702167","rc":[{"batb":[[0,2.18,32.83],[1,1.25,100],[2,1.08,7.82]],"ltp":2.26,"tv":64.11,"id":475559}]}]}
{"op":"mcm","clk":"11840750871","pt":1723551595898,"mc":[{"id":"1.231702167","rc":[{"batb":[[0,2.2,10],[1,2.18,32.83],[2,1.25,100]],"ltp":2.26,"tv":64.11,"id":475559}]}]}
{"op":"mcm","clk":"11840751076","pt":1723551599302,"mc":[{"id":"1.231702167","rc":[{"batb":[[0,2.18,32.83],[1,1.25,100],[2,1.08,7.82]],"ltp":2.26,"tv":64.11,"id":475559}]}]}
{"op":"mcm","clk":"11840751408","pt":1723551605403,"mc":[{"id":"1.231702167","rc":[{"batb":[[0,2.2,10],[1,2.18,32.83],[2,1.25,100]],"ltp":2.26,"tv":64.11,"id":475559}]}]}
{"op":"mcm","clk":"11840751609","pt":1723551608910,"mc":[{"id":"1.231702167","rc":[{"batb":[[0,2.18,32.83],[1,1.25,100],[2,1.08,7.82]],"ltp":2.26,"tv":64.11,"id":475559}]}]}
{"op":"mcm","clk":"11840752277","pt":1723551620756,"mc":[{"id":"1.231702167","rc":[{"batb":[[0,2.2,10],[1,2.18,32.83],[2,1.25,100]],"ltp":2.26,"tv":64.11,"id":475559}]}]}
{"op":"mcm","clk":"11840752447","pt":1723551624268,"mc":[{"id":"1.231702167","rc":[{"batb":[[0,2.18,32.83],[1,1.25,100],[2,1.08,7.82]],"ltp":2.26,"tv":64.11,"id":475559}]}]}
{"op":"mcm","clk":"11840752596","pt":1723551627475,"mc":[{"id":"1.231702167","rc":[{"batb":[[0,2.2,10],[1,2.18,32.83],[2,1.25,100]],"ltp":2.26,"tv":64.11,"id":475559}]}]}
{"op":"mcm","clk":"11840752820","pt":1723551631102,"mc":[{"id":"1.231702167","rc":[{"batb":[[0,2.18,32.83],[1,1.25,100],[2,1.08,7.82]],"ltp":2.26,"tv":64.11,"id":475559}]}]}
{"op":"mcm","clk":"11840753004","pt":1723551633893,"mc":[{"id":"1.231702167","rc":[{"batb":[[0,2.2,10],[1,2.18,32.83],[2,1.25,100]],"ltp":2.26,"tv":64.11,"id":475559}]}]}
{"op":"mcm","clk":"11840753182","pt":1723551637303,"mc":[{"id":"1.231702167","rc":[{"batb":[[0,2.18,32.83],[1,1.25,100],[2,1.08,7.82]],"ltp":2.26,"tv":64.11,"id":475559}]}]}
{"op":"mcm","clk":"11840753478","pt":1723551642785,"mc":[{"id":"1.231702167","rc":[{"batb":[[0,2.2,10],[1,2.18,32.83],[2,1.25,100]],"ltp":2.26,"tv":64.11,"id":475559}]}]}
{"op":"mcm","clk":"11840753688","pt":1723551646392,"mc":[{"id":"1.231702167","rc":[{"batb":[[0,2.18,32.83],[1,1.25,100],[2,1.08,7.82]],"ltp":2.26,"tv":64.11,"id":475559}]}]}
{"op":"mcm","clk":"11840754275","pt":1723551658151,"mc":[{"id":"1.231702167","rc":[{"batb":[[0,2.2,10],[1,2.18,32.83],[2,1.25,100]],"ltp":2.26,"tv":64.11,"id":475559}]}]}
{"op":"mcm","clk":"11840754483","pt":1723551661760,"mc":[{"id":"1.231702167","rc":[{"batb":[[0,2.18,32.83],[1,1.25,100],[2,1.08,7.82]],"ltp":2.26,"tv":64.11,"id":475559}]}]}
{"op":"mcm","clk":"11840754799","pt":1723551667004,"mc":[{"id":"1.231702167","rc":[{"batb":[[0,2.2,10],[1,2.18,32.83],[2,1.25,100]],"ltp":2.26,"tv":64.11,"id":475559}]}]}
{"op":"mcm","clk":"11840754962","pt":1723551670348,"mc":[{"id":"1.231702167","rc":[{"batb":[[0,2.18,32.83],[1,1.25,100],[2,1.08,7.82]],"ltp":2.26,"tv":64.11,"id":475559}]}]}
{"op":"mcm","clk":"11840755130","pt":1723551673783,"mc":[{"id":"1.231702167","rc":[{"batb":[[0,2.2,10],[1,2.18,32.83],[2,1.25,100]],"ltp":2.26,"tv":64.11,"id":475559}]}]}
{"op":"mcm","clk":"11840755355","pt":1723551677181,"mc":[{"id":"1.231702167","rc":[{"batb":[[0,2.18,32.83],[1,1.25,100],[2,1.08,7.82]],"ltp":2.26,"tv":64.11,"id":475559}]}]}
{"op":"mcm","clk":"11840756008","pt":1723551689365,"mc":[{"id":"1.231702167","rc":[{"batb":[[0,2.2,10],[1,2.18,32.83],[2,1.25,100]],"ltp":2.26,"tv":64.11,"id":475559}]}]}
{"op":"mcm","clk":"11840756195","pt":1723551692822,"mc":[{"id":"1.231702167","rc":[{"batb":[[0,2.18,32.83],[1,1.25,100],[2,1.08,7.82]],"ltp":2.26,"tv":64.11,"id":475559}]}]}
{"op":"mcm","clk":"11840756409","pt":1723551696780,"mc":[{"id":"1.231702167","rc":[{"batb":[[0,2.2,10],[1,2.18,32.83],[2,1.25,100]],"ltp":2.26,"tv":64.11,"id":475559}]}]}
{"op":"mcm","clk":"11840756615","pt":1723551700618,"mc":[{"id":"1.231702167","rc":[{"batb":[[0,2.18,32.83],[1,1.25,100],[2,1.08,7.82]],"ltp":2.26,"tv":64.11,"id":475559}]}]}
{"op":"mcm","clk":"11840756831","pt":1723551704689,"mc":[{"id":"1.231702167","rc":[{"batb":[[0,2.2,10],[1,2.18,32.83],[2,1.25,100]],"ltp":2.26,"tv":64.11,"id":475559}]}]}
{"op":"mcm","clk":"11840756996","pt":1723551708182,"mc":[{"id":"1.231702167","rc":[{"batb":[[0,2.18,32.83],[1,1.25,100],[2,1.08,7.82]],"ltp":2.26,"tv":64.11,"id":475559}]}]}
{"op":"mcm","clk":"11840757524","pt":1723551719143,"mc":[{"id":"1.231702167","rc":[{"batb":[[0,2.2,10],[1,2.18,32.83],[2,1.25,100]],"ltp":2.26,"tv":64.11,"id":475559}]}]}
{"op":"mcm","clk":"11840757754","pt":1723551722687,"mc":[{"id":"1.231702167","rc":[{"batb":[[0,2.18,32.83],[1,1.25,100],[2,1.08,7.82]],"ltp":2.26,"tv":64.11,"id":475559}]}]}
{"op":"mcm","clk":"11840758377","pt":1723551727998,"mc":[{"id":"1.231702167","rc":[{"batb":[[0,2.2,10],[1,2.18,32.83],[2,1.25,100]],"ltp":2.26,"tv":64.11,"id":475559}]}]}
{"op":"mcm","clk":"11840758735","pt":1723551731306,"mc":[{"id":"1.231702167","rc":[{"batb":[[0,2.18,32.83],[1,1.25,100],[2,1.08,7.82]],"ltp":2.26,"tv":64.11,"id":475559}]}]}
{"op":"mcm","clk":"11840759397","pt":1723551737183,"mc":[{"id":"1.231702167","rc":[{"batb":[[0,2.2,10],[1,2.18,32.83],[2,1.25,100]],"ltp":2.26,"tv":64.11,"id":475559}]}]}
{"op":"mcm","clk":"11840759746","pt":1723551740704,"mc":[{"id":"1.231702167","rc":[{"batb":[[0,2.18,32.83],[1,1.25,100],[2,1.08,7.82]],"ltp":2.26,"tv":64.11,"id":475559}]}]}
{"op":"mcm","clk":"11840760232","pt":1723551746188,"mc":[{"id":"1.231702167","rc":[{"batb":[[0,2.2,10],[1,2.18,32.83],[2,1.25,100]],"ltp":2.26,"tv":64.11,"id":475559}]}]}
{"op":"mcm","clk":"11840760499","pt":1723551749692,"mc":[{"id":"1.231702167","rc":[{"batb":[[0,2.18,32.83],[1,1.25,100],[2,1.08,7.82]],"ltp":2.26,"tv":64.11,"id":475559}]}]}
{"op":"mcm","clk":"11840761003","pt":1723551754213,"mc":[{"id":"1.231702167","rc":[{"batb":[[0,2.2,10],[1,2.18,32.83],[2,1.25,100]],"ltp":2.26,"tv":64.11,"id":475559}]}]}
{"op":"mcm","clk":"11840761406","pt":1723551757833,"mc":[{"id":"1.231702167","rc":[{"batb":[[0,2.18,32.83],[1,1.25,100],[2,1.08,7.82]],"ltp":2.26,"tv":64.11,"id":475559}]}]}
{"op":"mcm","clk":"11840761655","pt":1723551760425,"mc":[{"id":"1.231702167","rc":[{"batb":[[0,2.2,10],[1,2.18,32.83],[2,1.25,100]],"ltp":2.26,"tv":64.11,"id":475559}]}]}
{"op":"mcm","clk":"11840761983","pt":1723551763637,"mc":[{"id":"1.231702167","rc":[{"batb":[[0,2.18,32.83],[1,1.25,100],[2,1.08,7.82]],"ltp":2.26,"tv":64.11,"id":475559}]}]}
{"op":"mcm","clk":"11840762751","pt":1723551772031,"mc":[{"id":"1.231702167","rc":[{"batb":[[0,2.2,10],[1,2.18,32.83],[2,1.25,100]],"ltp":2.26,"tv":64.11,"id":475559}]}]}
{"op":"mcm","clk":"11840762983","pt":1723551775536,"mc":[{"id":"1.231702167","rc":[{"batb":[[0,2.18,32.83],[1,1.25,100],[2,1.08,7.82]],"ltp":2.26,"tv":64.11,"id":475559}]}]}
{"op":"mcm","clk":"11840763209","pt":1723551779146,"mc":[{"id":"1.231702167","rc":[{"batb":[[0,2.2,10],[1,2.18,32.83],[2,1.25,100]],"ltp":2.26,"tv":64.11,"id":475559}]}]}
{"op":"mcm","clk":"11840763503","pt":1723551783143,"mc":[{"id":"1.231702167","rc":[{"batb":[[0,2.18,32.83],[1,1.25,100],[2,1.08,7.82]],"ltp":2.26,"tv":64.11,"id":475559}]}]}
{"op":"mcm","clk":"11840763873","pt":1723551788463,"mc":[{"id":"1.231702167","rc":[{"batb":[[0,2.2,10],[1,2.18,32.83],[2,1.25,100]],"ltp":2.26,"tv":64.11,"id":475559}]}]}
{"op":"mcm","clk":"11840764130","pt":1723551791976,"mc":[{"id":"1.231702167","rc":[{"batb":[[0,2.18,32.83],[1,1.25,100],[2,1.08,7.82]],"ltp":2.26,"tv":64.11,"id":475559}]}]}
{"op":"mcm","clk":"11840764397","pt":1723551796060,"mc":[{"id":"1.231702167","rc":[{"batb":[[0,2.2,10],[1,2.18,32.83],[2,1.25,100]],"ltp":2.26,"tv":64.11,"id":475559}]}]}
{"op":"mcm","clk":"11840764620","pt":1723551799571,"mc":[{"id":"1.231702167","rc":[{"batb":[[0,2.18,32.83],[1,1.25,100],[2,1.08,7.82]],"ltp":2.26,"tv":64.11,"id":475559}]}]}
{"op":"mcm","clk":"11840765303","pt":1723551810144,"mc":[{"id":"1.231702167","rc":[{"batb":[[0,2.2,10],[1,2.18,32.83],[2,1.25,100]],"ltp":2.26,"tv":64.11,"id":475559}]}]}
{"op":"mcm","clk":"11840765485","pt":1723551813471,"mc":[{"id":"1.231702167","rc":[{"batb":[[0,2.18,32.83],[1,1.25,100],[2,1.08,7.82]],"ltp":2.26,"tv":64.11,"id":475559}]}]}
{"op":"mcm","clk":"11840765882","pt":1723551819395,"mc":[{"id":"1.231702167","rc":[{"batb":[[0,2.2,10],[1,2.18,32.83],[2,1.25,100]],"ltp":2.26,"tv":64.11,"id":475559}]}]}
{"op":"mcm","clk":"11840766079","pt":1723551822680,"mc":[{"id":"1.231702167","rc":[{"batb":[[0,2.18,32.83],[1,1.25,100],[2,1.08,7.82]],"ltp":2.26,"tv":64.11,"id":475559}]}]}
{"op":"mcm","clk":"11840766301","pt":1723551825777,"mc":[{"id":"1.231702167","rc":[{"batb":[[0,2.2,10],[1,2.18,32.83],[2,1.25,100]],"ltp":2.26,"tv":64.11,"id":475559}]}]}
{"op":"mcm","clk":"11840766512","pt":1723551829107,"mc":[{"id":"1.231702167","rc":[{"batb":[[0,2.18,32.83],[1,1.25,100],[2,1.08,7.82]],"ltp":2.26,"tv":64.11,"id":475559}]}]}
{"op":"mcm","clk":"11840766761","pt":1723551833216,"mc":[{"id":"1.231702167","rc":[{"batb":[[0,2.2,10],[1,2.18,32.83],[2,1.25,100]],"ltp":2.26,"tv":64.11,"id":475559}]}]}
{"op":"mcm","clk":"11840766967","pt":1723551836723,"mc":[{"id":"1.231702167","rc":[{"batb":[[0,2.18,32.83],[1,1.25,100],[2,1.08,7.82]],"ltp":2.26,"tv":64.11,"id":475559}]}]}
{"op":"mcm","clk":"11840767116","pt":1723551839030,"mc":[{"id":"1.231702167","rc":[{"batb":[[0,2.2,10],[1,2.18,32.83],[2,1.25,100]],"ltp":2.26,"tv":64.11,"id":475559}]}]}
{"op":"mcm","clk":"11840767357","pt":1723551842444,"mc":[{"id":"1.231702167","rc":[{"batb":[[0,2.18,32.83],[1,1.25,100],[2,1.08,7.82]],"ltp":2.26,"tv":64.11,"id":475559}]}]}
{"op":"mcm","clk":"11840768419","pt":1723551859248,"mc":[{"id":"1.231702167","rc":[{"batb":[[0,2.2,10],[1,2.18,32.83],[2,1.25,100]],"ltp":2.26,"tv":64.11,"id":475559}]}]}
{"op":"mcm","clk":"11840768647","pt":1723551862665,"mc":[{"id":"1.231702167","rc":[{"batb":[[0,2.18,32.83],[1,1.25,100],[2,1.08,7.82]],"ltp":2.26,"tv":64.11,"id":475559}]}]}
{"op":"mcm","clk":"11840769048","pt":1723551868259,"mc":[{"id":"1.231702167","rc":[{"batb":[[0,2.2,10],[1,2.18,32.83],[2,1.25,100]],"ltp":2.26,"tv":64.11,"id":475559}]}]}
{"op":"mcm","clk":"11840769303","pt":1723551872542,"mc":[{"id":"1.231702167","rc":[{"batb":[[0,2.18,32.83],[1,1.25,100],[2,1.08,7.82]],"ltp":2.26,"tv":64.11,"id":475559}]}]}
{"op":"mcm","clk":"11840769502","pt":1723551875837,"mc":[{"id":"1.231702167","rc":[{"batb":[[0,2.2,10],[1,2.18,32.83],[2,1.25,100]],"ltp":2.26,"tv":64.11,"id":475559}]}]}
{"op":"mcm","clk":"11840769731","pt":1723551879125,"mc":[{"id":"1.231702167","rc":[{"batb":[[0,2.18,32.83],[1,1.25,100],[2,1.08,7.82]],"ltp":2.26,"tv":64.11,"id":475559}]}]}
{"op":"mcm","clk":"11840769859","pt":1723551881331,"mc":[{"id":"1.231702167","rc":[{"batb":[[0,2.2,10],[1,2.18,32.83],[2,1.25,100]],"ltp":2.26,"tv":64.11,"id":475559}]}]}
{"op":"mcm","clk":"11840770066","pt":1723551884675,"mc":[{"id":"1.231702167","rc":[{"batb":[[0,2.18,32.83],[1,1.25,100],[2,1.08,7.82]],"ltp":2.26,"tv":64.11,"id":475559}]}]}
{"op":"mcm","clk":"11840770320","pt":1723551889145,"mc":[{"id":"1.231702167","rc":[{"batb":[[0,2.2,10],[1,2.18,32.83],[2,1.25,100]],"ltp":2.26,"tv":64.11,"id":475559}]}]}
{"op":"mcm","clk":"11840770530","pt":1723551892641,"mc":[{"id":"1.231702167","rc":[{"batb":[[0,2.18,32.83],[1,1.25,100],[2,1.08,7.82]],"ltp":2.26,"tv":64.11,"id":475559}]}]}
{"op":"mcm","clk":"11840770749","pt":1723551896347,"mc":[{"id":"1.231702167","rc":[{"batb":[[0,2.2,10],[1,2.18,32.83],[2,1.25,100]],"ltp":2.26,"tv":64.11,"id":475559}]}]}
{"op":"mcm","clk":"11840770969","pt":1723551899848,"mc":[{"id":"1.231702167","rc":[{"batb":[[0,2.18,32.83],[1,1.25,100],[2,1.08,7.82]],"ltp":2.26,"tv":64.11,"id":475559}]}]}
{"op":"mcm","clk":"11840771382","pt":1723551905771,"mc":[{"id":"1.231702167","rc":[{"batb":[[0,2.2,10],[1,2.18,32.83],[2,1.25,100]],"ltp":2.26,"tv":64.11,"id":475559}]}]}
{"op":"mcm","clk":"11840771624","pt":1723551909378,"mc":[{"id":"1.231702167","rc":[{"batb":[[0,2.18,32.83],[1,1.25,100],[2,1.08,7.82]],"ltp":2.26,"tv":64.11,"id":475559}]}]}
{"op":"mcm","clk":"11840772275","pt":1723551921058,"mc":[{"id":"1.231702167","rc":[{"batb":[[0,2.2,10],[1,2.18,32.83],[2,1.25,100]],"ltp":2.26,"tv":64.11,"id":475559}]}]}
{"op":"mcm","clk":"11840772488","pt":1723551924501,"mc":[{"id":"1.231702167","rc":[{"batb":[[0,2.18,32.83],[1,1.25,100],[2,1.08,7.82]],"ltp":2.26,"tv":64.11,"id":475559}]}]}
{"op":"mcm","clk":"11840772812","pt":1723551929590,"mc":[{"id":"1.231702167","rc":[{"batb":[[0,2.2,10],[1,2.18,32.83],[2,1.25,100]],"ltp":2.26,"tv":64.11,"id":475559}]}]}
{"op":"mcm","clk":"11840773020","pt":1723551933089,"mc":[{"id":"1.231702167","rc":[{"batb":[[0,2.18,32.83],[1,1.25,100],[2,1.08,7.82]],"ltp":2.26,"tv":64.11,"id":475559}]}]}
{"op":"mcm","clk":"11840773210","pt":1723551936174,"mc":[{"id":"1.231702167","rc":[{"batb":[[0,2.2,10],[1,2.18,32.83],[2,1.25,100]],"ltp":2.26,"tv":64.11,"id":475559}]}]}
{"op":"mcm","clk":"11840773423","pt":1723551939577,"mc":[{"id":"1.231702167","rc":[{"batb":[[0,2.18,32.83],[1,1.25,100],[2,1.08,7.82]],"ltp":2.26,"tv":64.11,"id":475559}]}]}
{"op":"mcm","clk":"11840773685","pt":1723551943905,"mc":[{"id":"1.231702167","rc":[{"batb":[[0,2.2,10],[1,2.18,32.83],[2,1.25,100]],"ltp":2.26,"tv":64.11,"id":475559}]}]}
{"op":"mcm","clk":"11840773905","pt":1723551947202,"mc":[{"id":"1.231702167","rc":[{"batb":[[0,2.18,32.83],[1,1.25,100],[2,1.08,7.82]],"ltp":2.26,"tv":64.11,"id":475559}]}]}
{"op":"mcm","clk":"11840774093","pt":1723551950084,"mc":[{"id":"1.231702167","rc":[{"batb":[[0,2.2,10],[1,2.18,32.83],[2,1.25,100]],"ltp":2.26,"tv":64.11,"id":475559}]}]}
{"op":"mcm","clk":"11840774294","pt":1723551953725,"mc":[{"id":"1.231702167","rc":[{"batb":[[0,2.18,32.83],[1,1.25,100],[2,1.08,7.82]],"ltp":2.26,"tv":64.11,"id":475559}]}]}
{"op":"mcm","clk":"11840774582","pt":1723551958923,"mc":[{"id":"1.231702167","rc":[{"batb":[[0,2.2,10],[1,2.18,32.83],[2,1.25,100]],"ltp":2.26,"tv":64.11,"id":475559}]}]}
{"op":"mcm","clk":"11840774775","pt":1723551962535,"mc":[{"id":"1.231702167","rc":[{"batb":[[0,2.18,32.83],[1,1.25,100],[2,1.08,7.82]],"ltp":2.26,"tv":64.11,"id":475559}]}]}
{"op":"mcm","clk":"11840774940","pt":1723551965011,"mc":[{"id":"1.231702167","rc":[{"batb":[[0,2.2,10],[1,2.18,32.83],[2,1.25,100]],"ltp":2.26,"tv":64.11,"id":475559}]}]}
{"op":"mcm","clk":"11840775176","pt":1723551968515,"mc":[{"id":"1.231702167","rc":[{"batb":[[0,2.18,32.83],[1,1.25,100],[2,1.08,7.82]],"ltp":2.26,"tv":64.11,"id":475559}]}]}
{"op":"mcm","clk":"11840775486","pt":1723551974024,"mc":[{"id":"1.231702167","rc":[{"batb":[[0,2.2,10],[1,2.18,32.83],[2,1.25,100]],"ltp":2.26,"tv":64.11,"id":475559}]}]}
{"op":"mcm","clk":"11840775641","pt":1723551977358,"mc":[{"id":"1.231702167","rc":[{"batb":[[0,2.18,32.83],[1,1.25,100],[2,1.08,7.82]],"ltp":2.26,"tv":64.11,"id":475559}]}]}
{"op":"mcm","clk":"11840776035","pt":1723551984232,"mc":[{"id":"1.231702167","rc":[{"batb":[[0,2.2,10],[1,2.18,32.83],[2,1.25,100]],"ltp":2.26,"tv":64.11,"id":475559}]}]}
{"op":"mcm","clk":"11840776243","pt":1723551987744,"mc":[{"id":"1.231702167","rc":[{"batb":[[0,2.18,32.83],[1,1.25,100],[2,1.08,7.82]],"ltp":2.26,"tv":64.11,"id":475559}]}]}
{"op":"mcm","clk":"11840776402","pt":1723551990165,"mc":[{"id":"1.231702167","rc":[{"batb":[[0,2.2,10],[1,2.18,32.83],[2,1.25,100]],"ltp":2.26,"tv":64.11,"id":475559}]}]}
{"op":"mcm","clk":"11840776614","pt":1723551994165,"mc":[{"id":"1.231702167","rc":[{"batb":[[0,2.18,32.83],[1,1.25,100],[2,1.08,7.82]],"ltp":2.26,"tv":64.11,"id":475559}]}]}
{"op":"mcm","clk":"11840777033","pt":1723552001561,"mc":[{"id":"1.231702167","rc":[{"batb":[[0,2.2,10],[1,2.18,32.83],[2,1.25,100]],"ltp":2.26,"tv":64.11,"id":475559}]}]}
{"op":"mcm","clk":"11840777216","pt":1723552005064,"mc":[{"id":"1.231702167","rc":[{"batb":[[0,2.18,32.83],[1,1.25,100],[2,1.08,7.82]],"ltp":2.26,"tv":64.11,"id":475559}]}]}
{"op":"mcm","clk":"11840777412","pt":1723552008494,"mc":[{"id":"1.231702167","rc":[{"batb":[[0,2.2,10],[1,2.18,32.83],[2,1.25,100]],"ltp":2.26,"tv":64.11,"id":475559}]}]}
{"op":"mcm","clk":"11840777594","pt":1723552011983,"mc":[{"id":"1.231702167","rc":[{"batb":[[0,2.18,32.83],[1,1.25,100],[2,1.08,7.82]],"ltp":2.26,"tv":64.11,"id":475559}]}]}
{"op":"mcm","clk":"11840777776","pt":1723552015567,"mc":[{"id":"1.231702167","rc":[{"batb":[[0,2.2,10],[1,2.18,32.83],[2,1.25,100]],"ltp":2.26,"tv":64.11,"id":475559}]}]}
{"op":"mcm","clk":"11840777941","pt":1723552018895,"mc":[{"id":"1.231702167","rc":[{"batb":[[0,2.18,32.83],[1,1.25,100],[2,1.08,7.82]],"ltp":2.26,"tv":64.11,"id":475559}]}]}
{"op":"mcm","clk":"11840778063","pt":1723552021407,"mc":[{"id":"1.231702167","rc":[{"batb":[[0,2.2,10],[1,2.18,32.83],[2,1.25,100]],"ltp":2.26,"tv":64.11,"id":475559}]}]}
{"op":"mcm","clk":"11840778260","pt":1723552024907,"mc":[{"id":"1.231702167","rc":[{"batb":[[0,2.18,32.83],[1,1.25,100],[2,1.08,7.82]],"ltp":2.26,"tv":64.11,"id":475559}]}]}
{"op":"mcm","clk":"11840778597","pt":1723552031014,"mc":[{"id":"1.231702167","rc":[{"batb":[[0,2.2,10],[1,2.18,32.83],[2,1.25,100]],"ltp":2.26,"tv":64.11,"id":475559}]}]}
{"op":"mcm","clk":"11840778829","pt":1723552034705,"mc":[{"id":"1.231702167","rc":[{"batb":[[0,2.18,32.83],[1,1.25,100],[2,1.08,7.82]],"ltp":2.26,"tv":64.11,"id":475559}]}]}
{"op":"mcm","clk":"11840779246","pt":1723552043190,"mc":[{"id":"1.231702167","rc":[{"batb":[[0,2.2,10],[1,2.18,32.83],[2,1.25,100]],"ltp":2.26,"tv":64.11,"id":475559}]}]}
{"op":"mcm","clk":"11840779482","pt":1723552046787,"mc":[{"id":"1.231702167","rc":[{"batb":[[0,2.18,32.83],[1,1.25,100],[2,1.08,7.82]],"ltp":2.26,"tv":64.11,"id":475559}]}]}
{"op":"mcm","clk":"11840780141","pt":1723552058304,"mc":[{"id":"1.231702167","rc":[{"batb":[[0,2.2,10],[1,2.18,32.83],[2,1.25,100]],"ltp":2.26,"tv":64.11,"id":475559}]}]}
{"op":"mcm","clk":"11840780335","pt":1723552061857,"mc":[{"id":"1.231702167","rc":[{"batb":[[0,2.18,32.83],[1,1.25,100],[2,1.08,7.82]],"ltp":2.26,"tv":64.11,"id":475559}]}]}
{"op":"mcm","clk":"11840780475","pt":1723552064425,"mc":[{"id":"1.231702167","rc":[{"batb":[[0,2.2,10],[1,2.18,32.83],[2,1.25,100]],"ltp":2.26,"tv":64.11,"id":475559}]}]}
{"op":"mcm","clk":"11840780648","pt":1723552067829,"mc":[{"id":"1.231702167","rc":[{"batb":[[0,2.18,32.83],[1,1.25,100],[2,1.08,7.82]],"ltp":2.26,"tv":64.11,"id":475559}]}]}
{"op":"mcm","clk":"11840781051","pt":1723552075231,"mc":[{"id":"1.231702167","rc":[{"batb":[[0,2.2,10],[1,2.18,32.83],[2,1.25,100]],"ltp":2.26,"tv":64.11,"id":475559}]}]}
{"op":"mcm","clk":"11840781271","pt":1723552078879,"mc":[{"id":"1.231702167","rc":[{"batb":[[0,2.18,32.83],[1,1.25,100],[2,1.08,7.82]],"ltp":2.26,"tv":64.11,"id":475559}]}]}
{"op":"mcm","clk":"11840781645","pt":1723552084579,"mc":[{"id":"1.231702167","rc":[{"batb":[[0,2.2,10],[1,2.18,32.83],[2,1.25,100]],"ltp":2.26,"tv":64.11,"id":475559}]}]}
{"op":"mcm","clk":"11840781889","pt":1723552088184,"mc":[{"id":"1.231702167","rc":[{"batb":[[0,2.18,32.83],[1,1.25,100],[2,1.08,7.82]],"ltp":2.26,"tv":64.11,"id":475559}]}]}
{"op":"mcm","clk":"11840782059","pt":1723552090557,"mc":[{"id":"1.231702167","rc":[{"batb":[[0,2.2,10],[1,2.18,32.83],[2,1.25,100]],"ltp":2.26,"tv":64.11,"id":475559}]}]}
{"op":"mcm","clk":"11840782262","pt":1723552094061,"mc":[{"id":"1.231702167","rc":[{"batb":[[0,2.18,32.83],[1,1.25,100],[2,1.08,7.82]],"ltp":2.26,"tv":64.11,"id":475559}]}]}
{"op":"mcm","clk":"11840782443","pt":1723552097264,"mc":[{"id":"1.231702167","rc":[{"batb":[[0,2.2,10],[1,2.18,32.83],[2,1.25,100]],"ltp":2.26,"tv":64.11,"id":475559}]}]}
{"op":"mcm","clk":"11840782638","pt":1723552100591,"mc":[{"id":"1.231702167","rc":[{"batb":[[0,2.18,32.83],[1,1.25,100],[2,1.08,7.82]],"ltp":2.26,"tv":64.11,"id":475559}]}]}
{"op":"mcm","clk":"11840783052","pt":1723552107277,"mc":[{"id":"1.231702167","rc":[{"batb":[[0,2.2,10],[1,2.18,32.83],[2,1.25,100]],"ltp":2.26,"tv":64.11,"id":475559}]}]}
{"op":"mcm","clk":"11840783268","pt":1723552110671,"mc":[{"id":"1.231702167","rc":[{"batb":[[0,2.18,32.83],[1,1.25,100],[2,1.08,7.82]],"ltp":2.26,"tv":64.11,"id":475559}]}]}
{"op":"mcm","clk":"11840783499","pt":1723552114280,"mc":[{"id":"1.231702167","rc":[{"batb":[[0,2.2,10],[1,2.18,32.83],[2,1.25,100]],"ltp":2.26,"tv":64.11,"id":475559}]}]}
{"op":"mcm","clk":"11840783723","pt":1723552117681,"mc":[{"id":"1.231702167","rc":[{"batb":[[0,2.18,32.83],[1,1.25,100],[2,1.08,7.82]],"ltp":2.26,"tv":64.11,"id":475559}]}]}
{"op":"mcm","clk":"11840783854","pt":1723552120105,"mc":[{"id":"1.231702167","rc":[{"batb":[[0,2.2,10],[1,2.18,32.83],[2,1.25,100]],"ltp":2.26,"tv":64.11,"id":475559}]}]}
{"op":"mcm","clk":"11840784129","pt":1723552123417,"mc":[{"id":"1.231702167","rc":[{"batb":[[0,2.18,32.83],[1,1.25,100],[2,1.08,7.82]],"ltp":2.26,"tv":64.11,"id":475559}]}]}
{"op":"mcm","clk":"11840784306","pt":1723552125889,"mc":[{"id":"1.231702167","rc":[{"batb":[[0,2.2,10],[1,2.18,32.83],[2,1.25,100]],"ltp":2.26,"tv":64.11,"id":475559}]}]}
{"op":"mcm","clk":"11840784533","pt":1723552129437,"mc":[{"id":"1.231702167","rc":[{"batb":[[0,2.18,32.83],[1,1.25,100],[2,1.08,7.82]],"ltp":2.26,"tv":64.11,"id":475559}]}]}
{"op":"mcm","clk":"11840784744","pt":1723552132738,"mc":[{"id":"1.231702167","rc":[{"batb":[[0,2.2,10],[1,2.18,32.83],[2,1.25,100]],"ltp":2.26,"tv":64.11,"id":475559}]}]}
{"op":"mcm","clk":"11840784918","pt":1723552135937,"mc":[{"id":"1.231702167","rc":[{"batb":[[0,2.18,32.83],[1,1.25,100],[2,1.08,7.82]],"ltp":2.26,"tv":64.11,"id":475559}]}]}
{"op":"mcm","clk":"11840785089","pt":1723552139121,"mc":[{"id":"1.231702167","rc":[{"batb":[[0,2.2,10],[1,2.18,32.83],[2,1.25,100]],"ltp":2.26,"tv":64.11,"id":475559}]}]}
{"op":"mcm","clk":"11840785282","pt":1723552142323,"mc":[{"id":"1.231702167","rc":[{"batb":[[0,2.18,32.83],[1,1.25,100],[2,1.08,7.82]],"ltp":2.26,"tv":64.11,"id":475559}]}]}
{"op":"mcm","clk":"11840785988","pt":1723552152445,"mc":[{"id":"1.231702167","rc":[{"batb":[[0,2.2,10],[1,2.18,32.83],[2,1.25,100]],"ltp":2.26,"tv":64.11,"id":475559}]}]}
{"op":"mcm","clk":"11840786193","pt":1723552155949,"mc":[{"id":"1.231702167","rc":[{"batb":[[0,2.18,32.83],[1,1.25,100],[2,1.08,7.82]],"ltp":2.26,"tv":64.11,"id":475559}]}]}
{"op":"mcm","clk":"11840786512","pt":1723552161572,"mc":[{"id":"1.231702167","rc":[{"batb":[[0,2.2,10],[1,2.18,32.83],[2,1.25,100]],"ltp":2.26,"tv":64.11,"id":475559}]}]}
{"op":"mcm","clk":"11840786723","pt":1723552164873,"mc":[{"id":"1.231702167","rc":[{"batb":[[0,2.18,32.83],[1,1.25,100],[2,1.08,7.82]],"ltp":2.26,"tv":64.11,"id":475559}]}]}
{"op":"mcm","clk":"11840786914","pt":1723552167764,"mc":[{"id":"1.231702167","rc":[{"batb":[[0,2.2,10],[1,2.18,32.83],[2,1.25,100]],"ltp":2.26,"tv":64.11,"id":475559}]}]}
{"op":"mcm","clk":"11840787154","pt":1723552171271,"mc":[{"id":"1.231702167","rc":[{"batb":[[0,2.18,32.83],[1,1.25,100],[2,1.08,7.82]],"ltp":2.26,"tv":64.11,"id":475559}]}]}
{"op":"mcm","clk":"11840787547","pt":1723552176845,"mc":[{"id":"1.231702167","rc":[{"batb":[[0,2.2,10],[1,2.18,32.83],[2,1.25,100]],"ltp":2.26,"tv":64.11,"id":475559}]}]}
{"op":"mcm","clk":"11840787821","pt":1723552180553,"mc":[{"id":"1.231702167","rc":[{"batb":[[0,2.18,32.83],[1,1.25,100],[2,1.08,7.82]],"ltp":2.26,"tv":64.11,"id":475559}]}]}
{"op":"mcm","clk":"11840787984","pt":1723552182879,"mc":[{"id":"1.231702167","rc":[{"batb":[[0,2.2,10],[1,2.18,32.83],[2,1.25,100]],"ltp":2.26,"tv":64.11,"id":475559}]}]}
{"op":"mcm","clk":"11840788217","pt":1723552186370,"mc":[{"id":"1.231702167","rc":[{"batb":[[0,2.18,32.83],[1,1.25,100],[2,1.08,7.82]],"ltp":2.26,"tv":64.11,"id":475559}]}]}
{"op":"mcm","clk":"11840788394","pt":1723552190165,"mc":[{"id":"1.231702167","rc":[{"batb":[[0,2.2,10],[1,2.18,32.83],[2,1.25,100]],"ltp":2.26,"tv":64.11,"id":475559}]}]}
{"op":"mcm","clk":"11840788582","pt":1723552193708,"mc":[{"id":"1.231702167","rc":[{"batb":[[0,2.18,32.83],[1,1.25,100],[2,1.08,7.82]],"ltp":2.26,"tv":64.11,"id":475559}]}]}
