{"op":"mcm","clk":"11915858108","pt":1724068189376,"mc":[{"id":"1.232011680","marketDefinition":{"bspMarket":false,"turnInPlayEnabled":true,"persistenceEnabled":true,"marketBaseRate":5.0,"eventId":"33507998","eventTypeId":"4","numberOfWinners":1,"bettingType":"ODDS","marketType":"MATCH_ODDS","marketTime":"2024-08-19T18:30:00.000Z","suspendTime":"2024-08-19T18:30:00.000Z","bspReconciled":false,"complete":true,"inPlay":false,"crossMatching":true,"runnersVoidable":false,"numberOfActiveRunners":2,"betDelay":0,"status":"OPEN","runners":[{"status":"ACTIVE","sortPriority":1,"id":72857114,"name":"Boca Raton Trailblazers"},{"status":"ACTIVE","sortPriority":2,"id":72857116,"name":"Grand Cayman Stingrays"}],"regulators":["MR_INT"],"countryCode":"GB","discountAllowed":false,"timezone":"GMT","openDate":"2024-08-19T18:30:00.000Z","version":6086344306,"name":"Match Odds","eventName":"Boca Raton Trailblazers v Grand Cayman Stingrays"},"rc":[{"batb":[[0,1.01,20]],"ltp":0.0,"tv":0.0,"id":72857114},{"batb":[[0,1.01,20]],"ltp":0.0,"tv":0.0,"id":72857116}]}]}
{"op":"mcm","clk":"11915858161","pt":1724068190710,"mc":[{"id":"1.232011680","rc":[{"batb":[[0,1.03,200],[1,1.02,200],[2,1.01,220]],"ltp":0.0,"tv":0.0,"id":72857114},{"batb":[[0,1.03,200],[1,1.02,200],[2,1.01,220]],"ltp":0.0,"tv":0.0,"id":72857116}]}]}
{"op":"mcm","clk":"11915858286","pt":1724068194958,"mc":[{"id":"1.232011680","marketDefinition":{"bspMarket":false,"turnInPlayEnabled":true,"persistenceEnabled":true,"marketBaseRate":5.0,"eventId":"33507998","eventTypeId":"4","numberOfWinners":1,"bettingType":"ODDS","marketType":"MATCH_ODDS","marketTime":"2024-08-19T18:30:00.000Z","suspendTime":"2024-08-19T18:30:00.000Z","bspReconciled":false,"complete":true,"inPlay":false,"crossMatching":true,"runnersVoidable":false,"numberOfActiveRunners":2,"betDelay":0,"status":"OPEN","runners":[{"status":"ACTIVE","sortPriority":1,"id":72857114,"name":"Boca Raton Trailblazers"},{"status":"ACTIVE","sortPriority":2,"id":72857116,"name":"Grand Cayman Stingrays"}],"regulators":["MR_INT"],"countryCode":"GB","discountAllowed":true,"timezone":"GMT","openDate":"2024-08-19T18:30:00.000Z","version":6086344306,"name":"Match Odds","eventName":"Boca Raton Trailblazers v Grand Cayman Stingrays"}}]}
{"op":"mcm","clk":"11915865542","pt":1724068402516,"mc":[{"id":"1.232011680","rc":[{"batl":[[0,13,0.94]],"ltp":0.0,"tv":0.0,"id":72857116}]}]}
{"op":"mcm","clk":"11915865836","pt":1724068411800,"mc":[{"id":"1.232011680","rc":[{"batl":[[0,13,0.94]],"ltp":0.0,"tv":0.0,"id":72857114}]}]}
{"op":"mcm","clk":"11915918192","pt":1724069555089,"mc":[{"id":"1.232011680","rc":[{"batb":[[0,1.71,52.08],[1,1.03,200],[2,1.02,200]],"ltp":0.0,"tv":0.0,"id":72857114},{"batb":[[0,2.28,28.89],[1,1.03,200],[2,1.02,200]],"ltp":0.0,"tv":0.0,"id":72857116}]}]}
{"op":"mcm","clk":"11915939187","pt":1724069932155,"mc":[{"id":"1.232011680","rc":[{"batb":[[1,1.41,8.79],[2,1.03,200]],"batl":[[0,2.2,5.17],[1,13,0.94]],"ltp":0.0,"tv":0.0,"id":72857114}]}]}
{"op":"mcm","clk":"11916053349","pt":1724071823252,"mc":[{"id":"1.232011680","rc":[{"trd":[[1.79,10]],"ltp":1.79,"tv":10.0,"id":72857114},{"trd":[[2.28,7.85]],"batb":[[0,2.28,21.04]],"ltp":2.28,"tv":7.85,"id":72857116}],"tv":17.85}]}
{"op":"mcm","clk":"11916053439","pt":1724071825143,"mc":[{"id":"1.232011680","rc":[{"batb":[[0,2.28,28.89]],"ltp":2.28,"tv":7.85,"id":72857116}]}]}
{"op":"mcm","clk":"11916106389","pt":1724072903284,"mc":[{"id":"1.232011680","rc":[{"batb":[[2,1.02,294.97]],"ltp":2.28,"tv":7.85,"id":72857116}]}]}
{"op":"mcm","clk":"11916107991","pt":1724072929441,"mc":[{"id":"1.232011680","rc":[{"batb":[[2,1.1,1000]],"ltp":1.79,"tv":10.0,"id":72857114}]}]}
{"op":"mcm","clk":"11916108166","pt":1724072932419,"mc":[{"id":"1.232011680","rc":[{"batb":[[1,1.1,1000],[2,1.03,200]],"ltp":2.28,"tv":7.85,"id":72857116}]}]}
{"op":"mcm","clk":"11916178335","pt":1724073961102,"mc":[{"id":"1.232011680","rc":[{"batl":[[1,3,1.98],[2,13,0.94]],"ltp":1.79,"tv":10.0,"id":72857114}]}]}
{"op":"mcm","clk":"11916178597","pt":1724073964520,"mc":[{"id":"1.232011680","rc":[{"batl":[[1,13,0.94],[2,13,0]],"ltp":1.79,"tv":10.0,"id":72857114}]}]}
{"op":"mcm","clk":"11916180083","pt":1724073985438,"mc":[{"id":"1.232011680","rc":[{"batb":[[2,1.03,200]],"ltp":1.79,"tv":10.0,"id":72857114},{"batb":[[1,1.03,200],[2,1.02,294.97]],"ltp":2.28,"tv":7.85,"id":72857116}]}]}
{"op":"mcm","clk":"11916180574","pt":1724073992843,"mc":[{"id":"1.232011680","rc":[{"batb":[[2,1.07,357.14]],"ltp":1.79,"tv":10.0,"id":72857114},{"batb":[[1,1.07,357.14],[2,1.05,500]],"ltp":2.28,"tv":7.85,"id":72857116}]}]}
{"op":"mcm","clk":"11916180629","pt":1724073993616,"mc":[{"id":"1.232011680","rc":[{"batb":[[1,1.43,116.28],[2,1.41,8.79]],"ltp":1.79,"tv":10.0,"id":72857114},{"batb":[[1,1.43,116.28],[2,1.38,131.58]],"ltp":2.28,"tv":7.85,"id":72857116}]}]}
{"op":"mcm","clk":"11916180746","pt":1724073995152,"mc":[{"id":"1.232011680","rc":[{"batb":[[1,1.43,125.07],[2,1.38,131.58]],"ltp":1.79,"tv":10.0,"id":72857114}]}]}
{"op":"mcm","clk":"11916217553","pt":1724074515419,"mc":[{"id":"1.232011680","rc":[{"batb":[[0,1.71,61.52]],"ltp":1.79,"tv":10.0,"id":72857114},{"batb":[[0,2.28,34.12]],"ltp":2.28,"tv":7.85,"id":72857116}]}]}
{"op":"mcm","clk":"11916257612","pt":1724075124541,"mc":[{"id":"1.232011680","rc":[{"batl":[[1,13,0]],"ltp":1.79,"tv":10.0,"id":72857114}]}]}
{"op":"mcm","clk":"11916282095","pt":1724075498180,"mc":[{"id":"1.232011680","rc":[{"trd":[[1.71,0.16]],"batb":[[0,1.71,61.44]],"ltp":1.71,"tv":10.15,"id":72857114}],"tv":18.0}]}
{"op":"mcm","clk":"11916282469","pt":1724075502713,"mc":[{"id":"1.232011680","rc":[{"batb":[[0,1.71,61.52]],"ltp":1.71,"tv":10.15,"id":72857114}]}]}
{"op":"mcm","clk":"11916296282","pt":1724075729744,"mc":[{"id":"1.232011680","rc":[{"batl":[[0,2.2,5.25]],"ltp":1.71,"tv":10.15,"id":72857114}]}]}
{"op":"mcm","clk":"11916297756","pt":1724075757560,"mc":[{"id":"1.232011680","rc":[{"batl":[[0,2.2,5.17]],"ltp":1.71,"tv":10.15,"id":72857114}]}]}
{"op":"mcm","clk":"11916353843","pt":1724076745937,"mc":[{"id":"1.232011680","rc":[{"trd":[[1.71,0.48]],"batb":[[0,1.71,61.36]],"ltp":1.71,"tv":10.47,"id":72857114}],"tv":18.32}]}
{"op":"mcm","clk":"11916354090","pt":1724076750332,"mc":[{"id":"1.232011680","rc":[{"batb":[[0,1.71,61.52]],"ltp":1.71,"tv":10.47,"id":72857114}]}]}
{"op":"mcm","clk":"11916354374","pt":1724076756528,"mc":[{"id":"1.232011680","rc":[{"batl":[[0,2.2,5.29]],"ltp":1.71,"tv":10.47,"id":72857114}]}]}
{"op":"mcm","clk":"11916354833","pt":1724076764164,"mc":[{"id":"1.232011680","rc":[{"batl":[[0,2.2,5.45]],"ltp":1.71,"tv":10.47,"id":72857114}]}]}
{"op":"mcm","clk":"11916365683","pt":1724076786608,"mc":[{"id":"1.232011680","rc":[{"batl":[[0,2.2,5.17]],"ltp":1.71,"tv":10.47,"id":72857114}]}]}
{"op":"mcm","clk":"11916410663","pt":1724077506458,"mc":[{"id":"1.232011680","rc":[{"batb":[[0,1.72,3.59],[1,1.71,61.52],[2,1.43,125.07]],"ltp":1.71,"tv":10.47,"id":72857114}]}]}
{"op":"mcm","clk":"11916461494","pt":1724078314540,"mc":[{"id":"1.232011680","rc":[{"trd":[[2.28,11.27]],"batb":[[0,2.28,32.41]],"ltp":2.28,"tv":11.27,"id":72857116}],"tv":21.75}]}
{"op":"mcm","clk":"11916461714","pt":1724078318843,"mc":[{"id":"1.232011680","rc":[{"batb":[[0,2.28,34.12]],"ltp":2.28,"tv":11.27,"id":72857116}]}]}
{"op":"mcm","clk":"11916485392","pt":1724078718524,"mc":[{"id":"1.232011680","rc":[{"batb":[[0,1.71,61.52],[1,1.43,125.07],[2,1.38,131.58]],"ltp":1.71,"tv":10.47,"id":72857114}]}]}
{"op":"mcm","clk":"11916757614","pt":1724081711711,"mc":[{"id":"1.232011680","rc":[{"trd":[[1.71,2.48]],"batb":[[0,1.71,60.52],[1,1.43,125.07]],"batl":[[0,2.2,5.17]],"ltp":1.71,"tv":12.47,"id":72857114}],"tv":23.74}]}
{"op":"mcm","clk":"11916758146","pt":1724081716243,"mc":[{"id":"1.232011680","rc":[{"batb":[[0,1.71,61.52]],"ltp":1.71,"tv":12.47,"id":72857114}]}]}
{"op":"mcm","clk":"11916889901","pt":1724083017869,"mc":[{"id":"1.232011680","rc":[{"batb":[[1,1.43,8.79],[2,1.03,200]],"ltp":1.71,"tv":12.47,"id":72857114},{"batb":[[1,1.03,200],[2,1.02,294.72]],"ltp":2.28,"tv":11.27,"id":72857116}]}]}
{"op":"mcm","clk":"11916890429","pt":1724083022885,"mc":[{"id":"1.232011680","rc":[{"batb":[[2,1.14,714.29]],"ltp":1.71,"tv":12.47,"id":72857114},{"batb":[[1,1.09,1111.11],[2,1.04,1250]],"ltp":2.28,"tv":11.27,"id":72857116}]}]}
{"op":"mcm","clk":"11916890472","pt":1724083023296,"mc":[{"id":"1.232011680","rc":[{"batb":[[2,1.33,151.52]],"ltp":1.71,"tv":12.47,"id":72857114},{"batb":[[1,1.33,151.52],[2,1.23,434.78]],"ltp":2.28,"tv":11.27,"id":72857116}]}]}
{"op":"mcm","clk":"11916937100","pt":1724083439841,"mc":[{"id":"1.232011680","rc":[{"batb":[[0,1.73,5.73],[1,1.71,61.52],[2,1.43,8.79]],"ltp":1.71,"tv":12.47,"id":72857114},{"trd":[[2.28,11.27]],"ltp":2.28,"tv":11.27,"id":72857116}],"tv":23.75}]}
{"op":"mcm","clk":"11916945088","pt":1724083502966,"mc":[{"id":"1.232011680","rc":[{"batl":[[0,1.75,385.15],[1,2.2,5.17]],"ltp":1.71,"tv":12.47,"id":72857114}]}]}
{"op":"mcm","clk":"11916945553","pt":1724083506257,"mc":[{"id":"1.232011680","rc":[{"trd":[[1.75,770.3]],"batb":[[0,1.74,10],[1,1.73,5.73],[2,1.71,61.52]],"batl":[[0,2.2,5.17],[1,2.2,0]],"ltp":1.75,"tv":782.77,"id":72857114}],"tv":794.04}]}
{"op":"mcm","clk":"11916945967","pt":1724083509555,"mc":[{"id":"1.232011680","rc":[{"batb":[[0,1.73,5.73],[1,1.71,61.52],[2,1.43,8.79]],"ltp":1.75,"tv":782.77,"id":72857114}]}]}
{"op":"mcm","clk":"11916946733","pt":1724083515549,"mc":[{"id":"1.232011680","rc":[{"batl":[[0,1.75,385.15],[1,2.2,5.17]],"ltp":1.75,"tv":782.77,"id":72857114}]}]}
{"op":"mcm","clk":"11916947467","pt":1724083521757,"mc":[{"id":"1.232011680","rc":[{"trd":[[1.75,1540.59]],"batb":[[0,1.74,10],[1,1.73,5.73],[2,1.71,61.52]],"batl":[[0,2.2,5.17],[1,2.2,0]],"ltp":1.75,"tv":1553.07,"id":72857114}],"tv":1564.34}]}
{"op":"mcm","clk":"11916947853","pt":1724083525087,"mc":[{"id":"1.232011680","rc":[{"batb":[[0,1.73,5.73],[1,1.71,61.52],[2,1.43,8.79]],"ltp":1.75,"tv":1553.07,"id":72857114}]}]}
{"op":"mcm","clk":"11916948352","pt":1724083528993,"mc":[{"id":"1.232011680","rc":[{"batl":[[0,1.75,385.15],[1,2.2,5.17]],"ltp":1.75,"tv":1553.07,"id":72857114}]}]}
{"op":"mcm","clk":"11916948563","pt":1724083530808,"mc":[{"id":"1.232011680","rc":[{"trd":[[1.75,2310.89]],"batl":[[0,2.2,5.17],[1,2.2,0]],"ltp":1.75,"tv":2323.36,"id":72857114}],"tv":2334.64}]}
{"op":"mcm","clk":"11916948584","pt":1724083530967,"mc":[{"id":"1.232011680","rc":[{"batb":[[0,1.74,10],[1,1.73,5.73],[2,1.71,61.52]],"ltp":1.75,"tv":2323.36,"id":72857114}]}]}
{"op":"mcm","clk":"11916948969","pt":1724083533898,"mc":[{"id":"1.232011680","rc":[{"batb":[[0,1.75,20],[1,1.74,10],[2,1.73,5.73]],"ltp":1.75,"tv":2323.36,"id":72857114}]}]}
{"op":"mcm","clk":"11916949014","pt":1724083534316,"mc":[{"id":"1.232011680","rc":[{"batb":[[1,1.73,5.73],[2,1.71,61.52]],"ltp":1.75,"tv":2323.36,"id":72857114}]}]}
{"op":"mcm","clk":"11916949210","pt":1724083535776,"mc":[{"id":"1.232011680","rc":[{"trd":[[1.75,2350.89]],"batb":[[0,1.73,5.73],[1,1.71,61.52],[2,1.43,8.79]],"batl":[[0,1.75,365.15],[1,2.2,5.17]],"ltp":1.75,"tv":2363.36,"id":72857114}],"tv":2374.64}]}
{"op":"mcm","clk":"11916950371","pt":1724083545779,"mc":[{"id":"1.232011680","rc":[{"trd":[[1.75,3081.19]],"batb":[[0,1.75,20],[1,1.73,5.73],[2,1.71,61.52]],"batl":[[0,2.2,5.17],[1,2.2,0]],"ltp":1.75,"tv":3093.66,"id":72857114}],"tv":3104.94}]}
{"op":"mcm","clk":"11916950396","pt":1724083546088,"mc":[{"id":"1.232011680","rc":[{"batb":[[0,1.76,10],[1,1.75,20],[2,1.73,5.73]],"ltp":1.75,"tv":3093.66,"id":72857114}]}]}
{"op":"mcm","clk":"11916950816","pt":1724083549379,"mc":[{"id":"1.232011680","rc":[{"batb":[[0,1.75,20],[1,1.73,5.73],[2,1.71,61.52]],"ltp":1.75,"tv":3093.66,"id":72857114}]}]}
{"op":"mcm","clk":"11916951479","pt":1724083554509,"mc":[{"id":"1.232011680","rc":[{"trd":[[1.75,3121.19]],"batb":[[0,1.74,10]],"ltp":1.75,"tv":3133.66,"id":72857114}],"tv":3144.94}]}
{"op":"mcm","clk":"11916951925","pt":1724083557888,"mc":[{"id":"1.232011680","rc":[{"batb":[[0,1.73,5.73],[1,1.71,61.52],[2,1.43,8.79]],"ltp":1.75,"tv":3133.66,"id":72857114}]}]}
{"op":"mcm","clk":"11916954351","pt":1724083577341,"mc":[{"id":"1.232011680","rc":[{"batl":[[0,1.79,4],[1,2.2,5.17]],"ltp":1.75,"tv":3133.66,"id":72857114},{"batb":[[0,2.3,4],[1,2.28,38.12],[2,1.33,151.52]],"ltp":2.28,"tv":11.27,"id":72857116}]}]}
{"op":"mcm","clk":"11916959128","pt":1724083612651,"mc":[{"id":"1.232011680","rc":[{"batl":[[0,1.75,385.15],[1,1.79,4],[2,2.2,5.17]],"ltp":1.75,"tv":3133.66,"id":72857114}]}]}
{"op":"mcm","clk":"11916959484","pt":1724083615345,"mc":[{"id":"1.232011680","rc":[{"trd":[[1.75,3891.49]],"batl":[[0,1.79,4],[1,2.2,5.17],[2,2.2,0]],"ltp":1.75,"tv":3903.96,"id":72857114}],"tv":3915.23}]}
{"op":"mcm","clk":"11916960288","pt":1724083621260,"mc":[{"id":"1.232011680","rc":[{"batl":[[0,1.75,385.15],[1,1.79,4],[2,2.2,5.17]],"ltp":1.75,"tv":3903.96,"id":72857114}]}]}
{"op":"mcm","clk":"11916960506","pt":1724083622871,"mc":[{"id":"1.232011680","rc":[{"batl":[[0,1.75,389.15]],"ltp":1.75,"tv":3903.96,"id":72857114},{"batb":[[0,2.34,4],[1,2.32,4],[2,2.3,4]],"ltp":2.28,"tv":11.27,"id":72857116}]}]}
{"op":"mcm","clk":"11916960911","pt":1724083625676,"mc":[{"id":"1.232011680","rc":[{"batb":[[1,1.43,8.79],[2,1.33,151.52]],"ltp":1.75,"tv":3903.96,"id":72857114}]}]}
{"op":"mcm","clk":"11916961351","pt":1724083628856,"mc":[{"id":"1.232011680","rc":[{"trd":[[1.75,4661.78]],"batl":[[0,2.2,5.17],[1,1.79,0],[2,2.2,0]],"ltp":1.75,"tv":4674.26,"id":72857114},{"batb":[[0,1.33,151.52],[1,1.23,434.78],[2,1.19,526.32]],"ltp":2.28,"tv":11.27,"id":72857116}],"tv":4685.53}]}
{"op":"mcm","clk":"11916961382","pt":1724083629067,"mc":[{"id":"1.232011680","rc":[{"batb":[[0,1.74,10],[1,1.73,5.73],[2,1.43,8.79]],"ltp":1.75,"tv":4674.26,"id":72857114}]}]}
{"op":"mcm","clk":"11916961587","pt":1724083630569,"mc":[{"id":"1.232011680","rc":[{"batb":[[2,1.71,61.52]],"ltp":1.75,"tv":4674.26,"id":72857114},{"batb":[[0,2.28,34.12],[1,1.33,151.52],[2,1.23,434.78]],"ltp":2.28,"tv":11.27,"id":72857116}]}]}
{"op":"mcm","clk":"11916961867","pt":1724083632384,"mc":[{"id":"1.232011680","rc":[{"batb":[[0,1.73,5.73],[1,1.71,61.52],[2,1.43,8.79]],"ltp":1.75,"tv":4674.26,"id":72857114}]}]}
{"op":"mcm","clk":"11916962637","pt":1724083637964,"mc":[{"id":"1.232011680","rc":[{"batl":[[0,1.79,4],[1,2.2,5.17]],"ltp":1.75,"tv":4674.26,"id":72857114},{"batb":[[0,2.3,4],[1,2.28,38.12],[2,1.33,151.52]],"ltp":2.28,"tv":11.27,"id":72857116}]}]}
{"op":"mcm","clk":"11916962954","pt":1724083640396,"mc":[{"id":"1.232011680","rc":[{"batl":[[0,1.75,385.15],[1,1.79,4],[2,2.2,5.17]],"ltp":1.75,"tv":4674.26,"id":72857114}]}]}
{"op":"mcm","clk":"11916963635","pt":1724083645492,"mc":[{"id":"1.232011680","rc":[{"trd":[[1.75,5432.08]],"batl":[[0,1.79,4],[1,2.2,5.17],[2,2.2,0]],"ltp":1.75,"tv":5444.55,"id":72857114}],"tv":5455.83}]}
{"op":"mcm","clk":"11916964572","pt":1724083651883,"mc":[{"id":"1.232011680","rc":[{"batl":[[0,1.75,385.15],[1,1.79,4],[2,2.2,5.17]],"ltp":1.75,"tv":5444.55,"id":72857114}]}]}
{"op":"mcm","clk":"11916964738","pt":1724083653084,"mc":[{"id":"1.232011680","rc":[{"batl":[[0,1.75,389.15]],"ltp":1.75,"tv":5444.55,"id":72857114},{"batb":[[0,2.34,4],[1,2.32,4],[2,2.3,4]],"ltp":2.28,"tv":11.27,"id":72857116}]}]}
{"op":"mcm","clk":"11916965084","pt":1724083655638,"mc":[{"id":"1.232011680","rc":[{"batb":[[1,1.43,8.79],[2,1.33,151.52]],"ltp":1.75,"tv":5444.55,"id":72857114}]}]}
{"op":"mcm","clk":"11916965395","pt":1724083657885,"mc":[{"id":"1.232011680","rc":[{"trd":[[1.75,6202.38]],"batl":[[0,1.75,4]],"ltp":1.75,"tv":6214.85,"id":72857114},{"batb":[[0,1.33,151.52],[1,1.23,434.78],[2,1.19,526.32]],"ltp":2.28,"tv":11.27,"id":72857116}],"tv":6226.12}]}
{"op":"mcm","clk":"11916965425","pt":1724083658103,"mc":[{"id":"1.232011680","rc":[{"batb":[[0,1.74,10],[1,1.73,5.73],[2,1.43,8.79]],"batl":[[0,2.2,5.17],[1,1.79,0],[2,2.2,0]],"ltp":1.75,"tv":6214.85,"id":72857114}]}]}
{"op":"mcm","clk":"11916965771","pt":1724083660606,"mc":[{"id":"1.232011680","rc":[{"batb":[[2,1.71,61.52]],"ltp":1.75,"tv":6214.85,"id":72857114},{"batb":[[0,2.28,34.12],[1,1.33,151.52],[2,1.23,434.78]],"ltp":2.28,"tv":11.27,"id":72857116}]}]}
{"op":"mcm","clk":"11916965863","pt":1724083661387,"mc":[{"id":"1.232011680","rc":[{"batb":[[0,1.73,5.73],[1,1.71,61.52],[2,1.43,8.79]],"ltp":1.75,"tv":6214.85,"id":72857114}]}]}
{"op":"mcm","clk":"11916966708","pt":1724083666897,"mc":[{"id":"1.232011680","rc":[{"batl":[[0,1.75,385.15],[1,2.2,5.17]],"ltp":1.75,"tv":6214.85,"id":72857114}]}]}
{"op":"mcm","clk":"11916966904","pt":1724083668315,"mc":[{"id":"1.232011680","rc":[{"batl":[[0,1.75,389.15]],"ltp":1.75,"tv":6214.85,"id":72857114},{"batb":[[0,2.34,4],[1,2.32,4],[2,2.28,34.12]],"ltp":2.28,"tv":11.27,"id":72857116}]}]}
{"op":"mcm","clk":"11916967263","pt":1724083670677,"mc":[{"id":"1.232011680","rc":[{"batb":[[1,1.43,8.79],[2,1.33,151.52]],"ltp":1.75,"tv":6214.85,"id":72857114},{"batb":[[2,1.33,151.52]],"ltp":2.28,"tv":11.27,"id":72857116}]}]}
{"op":"mcm","clk":"11916967707","pt":1724083673932,"mc":[{"id":"1.232011680","rc":[{"trd":[[1.75,6972.68]],"batb":[[0,1.74,10],[1,1.73,5.73],[2,1.43,8.79]],"batl":[[0,2.2,5.17],[1,2.2,0]],"ltp":1.75,"tv":6985.15,"id":72857114},{"batb":[[0,1.33,151.52],[1,1.23,434.78],[2,1.19,526.32]],"ltp":2.28,"tv":11.27,"id":72857116}],"tv":6996.42}]}
{"op":"mcm","clk":"11916967907","pt":1724083675604,"mc":[{"id":"1.232011680","rc":[{"batb":[[2,1.71,61.52]],"ltp":1.75,"tv":6985.15,"id":72857114},{"batb":[[0,2.28,34.12],[1,1.33,151.52],[2,1.23,434.78]],"ltp":2.28,"tv":11.27,"id":72857116}]}]}
{"op":"mcm","clk":"11916968175","pt":1724083677314,"mc":[{"id":"1.232011680","rc":[{"batb":[[0,1.73,5.73],[1,1.71,61.52],[2,1.43,8.79]],"ltp":1.75,"tv":6985.15,"id":72857114}]}]}
{"op":"mcm","clk":"11916968418","pt":1724083679127,"mc":[{"id":"1.232011680","rc":[{"batl":[[0,1.75,385.15],[1,2.2,5.17]],"ltp":1.75,"tv":6985.15,"id":72857114}]}]}
{"op":"mcm","clk":"11916968752","pt":1724083681808,"mc":[{"id":"1.232011680","rc":[{"trd":[[1.75,7742.97]],"batl":[[0,2.2,5.17],[1,2.2,0]],"ltp":1.75,"tv":7755.45,"id":72857114}],"tv":7766.72}]}
{"op":"mcm","clk":"11916968780","pt":1724083682021,"mc":[{"id":"1.232011680","rc":[{"batb":[[0,1.74,10],[1,1.73,5.73],[2,1.71,61.52]],"ltp":1.75,"tv":7755.45,"id":72857114}]}]}
{"op":"mcm","clk":"11916969012","pt":1724083683639,"mc":[{"id":"1.232011680","rc":[{"batb":[[0,1.74,14]],"batl":[[0,1.79,4],[1,2.2,5.17]],"ltp":1.75,"tv":7755.45,"id":72857114},{"batb":[[0,2.3,4],[1,2.28,38.12],[2,1.33,151.52]],"ltp":2.28,"tv":11.27,"id":72857116}]}]}
{"op":"mcm","clk":"11916969297","pt":1724083685720,"mc":[{"id":"1.232011680","rc":[{"batb":[[0,1.73,5.73],[1,1.71,61.52],[2,1.43,8.79]],"ltp":1.75,"tv":7755.45,"id":72857114}]}]}
{"op":"mcm","clk":"11916988896","pt":1724083823042,"mc":[{"id":"1.232011680","rc":[{"batl":[[0,1.75,385.15],[1,1.79,4],[2,2.2,5.17]],"ltp":1.75,"tv":7755.45,"id":72857114}]}]}
{"op":"mcm","clk":"11916989241","pt":1724083825544,"mc":[{"id":"1.232011680","rc":[{"trd":[[1.75,8513.27]],"batl":[[0,1.79,4],[1,2.2,5.17],[2,2.2,0]],"ltp":1.75,"tv":8525.74,"id":72857114}],"tv":8537.02}]}
{"op":"mcm","clk":"11916989942","pt":1724083830380,"mc":[{"id":"1.232011680","rc":[{"batl":[[0,1.75,385.15],[1,1.79,4],[2,2.2,5.17]],"ltp":1.75,"tv":8525.74,"id":72857114}]}]}
{"op":"mcm","clk":"11916990238","pt":1724083832465,"mc":[{"id":"1.232011680","rc":[{"trd":[[1.75,9283.57]],"batl":[[0,1.79,4],[1,2.2,5.17],[2,2.2,0]],"ltp":1.75,"tv":9296.04,"id":72857114}],"tv":9307.31}]}
{"op":"mcm","clk":"11916991039","pt":1724083838067,"mc":[{"id":"1.232011680","rc":[{"batl":[[0,1.75,385.15],[1,1.79,4],[2,2.2,5.17]],"ltp":1.75,"tv":9296.04,"id":72857114}]}]}
{"op":"mcm","clk":"11916991494","pt":1724083841306,"mc":[{"id":"1.232011680","rc":[{"trd":[[1.75,10053.87]],"batl":[[0,1.79,4],[1,2.2,5.17],[2,2.2,0]],"ltp":1.75,"tv":10066.34,"id":72857114}],"tv":10077.61}]}
{"op":"mcm","clk":"11916992162","pt":1724083845951,"mc":[{"id":"1.232011680","rc":[{"batl":[[0,1.75,385.15],[1,1.79,4],[2,2.2,5.17]],"ltp":1.75,"tv":10066.34,"id":72857114}]}]}
{"op":"mcm","clk":"11916992726","pt":1724083850274,"mc":[{"id":"1.232011680","rc":[{"batl":[[0,1.75,389.15]],"ltp":1.75,"tv":10066.34,"id":72857114},{"batb":[[0,2.34,4],[1,2.32,4],[2,2.3,4]],"ltp":2.28,"tv":11.27,"id":72857116}]}]}
{"op":"mcm","clk":"11916992843","pt":1724083851063,"mc":[{"id":"1.232011680","rc":[{"batb":[[1,1.43,8.79],[2,1.33,151.52]],"ltp":1.75,"tv":10066.34,"id":72857114}]}]}
{"op":"mcm","clk":"11916993196","pt":1724083853574,"mc":[{"id":"1.232011680","rc":[{"trd":[[1.75,10824.16]],"batb":[[0,1.74,10],[1,1.73,5.73],[2,1.43,8.79]],"batl":[[0,2.2,5.17],[1,1.79,0],[2,2.2,0]],"ltp":1.75,"tv":10836.63,"id":72857114},{"batb":[[0,1.33,151.52],[1,1.23,434.78],[2,1.19,526.32]],"ltp":2.28,"tv":11.27,"id":72857116}],"tv":10847.91}]}
{"op":"mcm","clk":"11916993696","pt":1724083856884,"mc":[{"id":"1.232011680","rc":[{"batb":[[0,1.73,5.73],[1,1.71,61.52]],"ltp":1.75,"tv":10836.63,"id":72857114},{"batb":[[0,2.28,34.12],[1,1.33,151.52],[2,1.23,434.78]],"ltp":2.28,"tv":11.27,"id":72857116}]}]}
{"op":"mcm","clk":"11916994639","pt":1724083863401,"mc":[{"id":"1.232011680","rc":[{"batl":[[0,1.75,385.15],[1,2.2,5.17]],"ltp":1.75,"tv":10836.63,"id":72857114}]}]}
{"op":"mcm","clk":"11916994973","pt":1724083865507,"mc":[{"id":"1.232011680","rc":[{"batl":[[0,1.75,389.15]],"ltp":1.75,"tv":10836.63,"id":72857114},{"batb":[[0,2.34,4],[1,2.32,4],[2,2.28,34.12]],"ltp":2.28,"tv":11.27,"id":72857116}]}]}
{"op":"mcm","clk":"11916995055","pt":1724083866087,"mc":[{"id":"1.232011680","rc":[{"batb":[[1,1.43,8.79],[2,1.33,151.52]],"ltp":1.75,"tv":10836.63,"id":72857114},{"batb":[[2,1.33,151.52]],"ltp":2.28,"tv":11.27,"id":72857116}]}]}
{"op":"mcm","clk":"11916995284","pt":1724083867717,"mc":[{"id":"1.232011680","rc":[{"trd":[[1.75,11594.46]],"batb":[[0,1.74,10],[1,1.73,5.73],[2,1.43,8.79]],"batl":[[0,2.2,5.17],[1,2.2,0]],"ltp":1.75,"tv":11606.93,"id":72857114},{"batb":[[0,1.33,151.52],[1,1.23,434.78],[2,1.19,526.32]],"ltp":2.28,"tv":11.27,"id":72857116}],"tv":11618.21}]}
{"op":"mcm","clk":"11916995835","pt":1724083871114,"mc":[{"id":"1.232011680","rc":[{"batb":[[0,1.73,5.73],[1,1.71,61.52]],"ltp":1.75,"tv":11606.93,"id":72857114},{"batb":[[0,2.28,34.12],[1,1.33,151.52],[2,1.23,434.78]],"ltp":2.28,"tv":11.27,"id":72857116}]}]}
{"op":"mcm","clk":"11916996115","pt":1724083872897,"mc":[{"id":"1.232011680","rc":[{"batl":[[0,1.75,385.15],[1,2.2,5.17]],"ltp":1.75,"tv":11606.93,"id":72857114}]}]}
{"op":"mcm","clk":"11916996343","pt":1724083874384,"mc":[{"id":"1.232011680","rc":[{"batb":[[0,1.74,10],[1,1.73,5.73],[2,1.71,61.52]],"ltp":1.75,"tv":11606.93,"id":72857114}]}]}
{"op":"mcm","clk":"11916996815","pt":1724083877421,"mc":[{"id":"1.232011680","rc":[{"trd":[[1.75,12364.76]],"batl":[[0,2.2,5.17],[1,2.2,0]],"ltp":1.75,"tv":12377.23,"id":72857114}],"tv":12388.5}]}
{"op":"mcm","clk":"11916997088","pt":1724083879380,"mc":[{"id":"1.232011680","rc":[{"batb":[[0,1.73,5.73],[1,1.71,61.52],[2,1.43,8.79]],"ltp":1.75,"tv":12377.23,"id":72857114}]}]}
{"op":"mcm","clk":"11916997252","pt":1724083880680,"mc":[{"id":"1.232011680","rc":[{"batl":[[0,1.79,4],[1,2.2,5.17]],"ltp":1.75,"tv":12377.23,"id":72857114},{"batb":[[0,2.3,4],[1,2.28,38.12],[2,1.33,151.52]],"ltp":2.28,"tv":11.27,"id":72857116}]}]}
{"op":"mcm","clk":"11916997765","pt":1724083884483,"mc":[{"id":"1.232011680","rc":[{"batl":[[0,1.75,385.15],[1,1.79,4],[2,2.2,5.17]],"ltp":1.75,"tv":12377.23,"id":72857114}]}]}
{"op":"mcm","clk":"11916998523","pt":1724083890330,"mc":[{"id":"1.232011680","rc":[{"trd":[[1.75,13135.05]],"batl":[[0,1.79,4],[1,2.2,5.17],[2,2.2,0]],"ltp":1.75,"tv":13147.53,"id":72857114}],"tv":13158.8}]}
{"op":"mcm","clk":"11916999675","pt":1724083898546,"mc":[{"id":"1.232011680","rc":[{"batl":[[0,1.75,385.15],[1,1.79,4],[2,2.2,5.17]],"ltp":1.75,"tv":13147.53,"id":72857114}]}]}
{"op":"mcm","clk":"11917000204","pt":1724083902432,"mc":[{"id":"1.232011680","rc":[{"trd":[[1.75,13905.35]],"batl":[[0,1.79,4],[1,2.2,5.17],[2,2.2,0]],"ltp":1.75,"tv":13917.82,"id":72857114}],"tv":13929.1}]}
{"op":"mcm","clk":"11917001217","pt":1724083909268,"mc":[{"id":"1.232011680","rc":[{"batl":[[0,1.75,385.15],[1,1.79,4],[2,2.2,5.17]],"ltp":1.75,"tv":13917.82,"id":72857114}]}]}
{"op":"mcm","clk":"11917001504","pt":1724083911248,"mc":[{"id":"1.232011680","rc":[{"batb":[[1,1.43,8.79],[2,1.33,151.52]],"batl":[[0,1.75,389.15]],"ltp":1.75,"tv":13917.82,"id":72857114},{"batb":[[0,2.34,4],[1,2.32,4],[2,2.3,4]],"ltp":2.28,"tv":11.27,"id":72857116}]}]}
{"op":"mcm","clk":"11917002178","pt":1724083915868,"mc":[{"id":"1.232011680","rc":[{"trd":[[1.75,14675.65]],"batb":[[0,1.74,10],[1,1.73,5.73],[2,1.43,8.79]],"batl":[[0,2.2,5.17],[1,1.79,0],[2,2.2,0]],"ltp":1.75,"tv":14688.12,"id":72857114},{"batb":[[0,1.33,151.52],[1,1.23,434.78],[2,1.19,526.32]],"ltp":2.28,"tv":11.27,"id":72857116}],"tv":14699.4}]}
{"op":"mcm","clk":"11917002224","pt":1724083916175,"mc":[{"id":"1.232011680","rc":[{"batb":[[2,1.71,61.52]],"ltp":1.75,"tv":14688.12,"id":72857114},{"batb":[[0,2.28,34.12],[1,1.33,151.52],[2,1.23,434.78]],"ltp":2.28,"tv":11.27,"id":72857116}]}]}
{"op":"mcm","clk":"11917002699","pt":1724083919252,"mc":[{"id":"1.232011680","rc":[{"batb":[[0,1.73,5.73],[1,1.71,61.52],[2,1.43,8.79]],"ltp":1.75,"tv":14688.12,"id":72857114}]}]}
{"op":"mcm","clk":"11917003219","pt":1724083922393,"mc":[{"id":"1.232011680","rc":[{"batl":[[0,1.75,385.15],[1,2.2,5.17]],"ltp":1.75,"tv":14688.12,"id":72857114}]}]}
{"op":"mcm","clk":"11917003894","pt":1724083926263,"mc":[{"id":"1.232011680","rc":[{"batl":[[0,1.75,389.15]],"ltp":1.75,"tv":14688.12,"id":72857114},{"batb":[[0,2.34,4],[1,2.32,4],[2,2.28,34.12]],"ltp":2.28,"tv":11.27,"id":72857116}]}]}
{"op":"mcm","clk":"11917004141","pt":1724083927885,"mc":[{"id":"1.232011680","rc":[{"trd":[[1.75,15445.95]],"batl":[[0,2.2,5.17],[1,2.2,0]],"ltp":1.75,"tv":15458.42,"id":72857114},{"batb":[[0,2.28,34.12],[1,1.33,151.52],[2,1.23,434.78]],"ltp":2.28,"tv":11.27,"id":72857116}],"tv":15469.69}]}
{"op":"mcm","clk":"11917004171","pt":1724083928090,"mc":[{"id":"1.232011680","rc":[{"batb":[[0,1.74,10],[1,1.73,5.73],[2,1.71,61.52]],"ltp":1.75,"tv":15458.42,"id":72857114}]}]}
{"op":"mcm","clk":"11917004718","pt":1724083931277,"mc":[{"id":"1.232011680","rc":[{"batb":[[0,1.73,5.73],[1,1.71,61.52],[2,1.43,8.79]],"ltp":1.75,"tv":15458.42,"id":72857114}]}]}
{"op":"mcm","clk":"11917005109","pt":1724083933760,"mc":[{"id":"1.232011680","rc":[{"batl":[[0,1.75,385.15],[1,2.2,5.17]],"ltp":1.75,"tv":15458.42,"id":72857114}]}]}
{"op":"mcm","clk":"11917005385","pt":1724083935673,"mc":[{"id":"1.232011680","rc":[{"trd":[[1.75,16216.24]],"batb":[[0,1.74,10],[1,1.73,5.73],[2,1.71,61.52]],"batl":[[0,2.2,5.17],[1,2.2,0]],"ltp":1.75,"tv":16228.72,"id":72857114}],"tv":16239.99}]}
{"op":"mcm","clk":"11917005936","pt":1724083938887,"mc":[{"id":"1.232011680","rc":[{"batb":[[0,1.73,5.73],[1,1.71,61.52],[2,1.43,8.79]],"ltp":1.75,"tv":16228.72,"id":72857114}]}]}
{"op":"mcm","clk":"11917006322","pt":1724083941394,"mc":[{"id":"1.232011680","rc":[{"batl":[[0,1.79,4],[1,2.2,5.17]],"ltp":1.75,"tv":16228.72,"id":72857114},{"batb":[[0,2.3,4],[1,2.28,38.12],[2,1.33,151.52]],"ltp":2.28,"tv":11.27,"id":72857116}]}]}
{"op":"mcm","clk":"11917007247","pt":1724083947670,"mc":[{"id":"1.232011680","rc":[{"batl":[[0,1.75,385.15],[1,1.79,4],[2,2.2,5.17]],"ltp":1.75,"tv":16228.72,"id":72857114}]}]}
{"op":"mcm","clk":"11917007843","pt":1724083952171,"mc":[{"id":"1.232011680","rc":[{"trd":[[1.75,16986.54]],"batl":[[0,1.79,4],[1,2.2,5.17],[2,2.2,0]],"ltp":1.75,"tv":16999.01,"id":72857114}],"tv":17010.29}]}
{"op":"mcm","clk":"11917008722","pt":1724083958495,"mc":[{"id":"1.232011680","rc":[{"batl":[[0,1.75,385.15],[1,1.79,4],[2,2.2,5.17]],"ltp":1.75,"tv":16999.01,"id":72857114}]}]}
{"op":"mcm","clk":"11917008998","pt":1724083960723,"mc":[{"id":"1.232011680","rc":[{"trd":[[1.75,17756.84]],"batl":[[0,1.79,4],[1,2.2,5.17],[2,2.2,0]],"ltp":1.75,"tv":17769.31,"id":72857114}],"tv":17780.59}]}
{"op":"mcm","clk":"11917009549","pt":1724083965010,"mc":[{"id":"1.232011680","rc":[{"batl":[[0,1.75,385.15],[1,1.79,4],[2,2.2,5.17]],"ltp":1.75,"tv":17769.31,"id":72857114}]}]}
{"op":"mcm","clk":"11917009857","pt":1724083967390,"mc":[{"id":"1.232011680","rc":[{"trd":[[1.75,18527.14]],"batl":[[0,1.79,4],[1,2.2,5.17],[2,2.2,0]],"ltp":1.75,"tv":18539.61,"id":72857114}],"tv":18550.88}]}
{"op":"mcm","clk":"11917010821","pt":1724083975043,"mc":[{"id":"1.232011680","rc":[{"batl":[[0,1.75,385.15],[1,1.79,4],[2,2.2,5.17]],"ltp":1.75,"tv":18539.61,"id":72857114}]}]}
{"op":"mcm","clk":"11917011490","pt":1724083980227,"mc":[{"id":"1.232011680","rc":[{"trd":[[1.75,19297.43]],"batl":[[0,1.79,4],[1,2.2,5.17],[2,2.2,0]],"ltp":1.75,"tv":19309.91,"id":72857114}],"tv":19321.18}]}
{"op":"mcm","clk":"11917012036","pt":1724083984146,"mc":[{"id":"1.232011680","rc":[{"batl":[[0,1.75,385.15],[1,1.79,4],[2,2.2,5.17]],"ltp":1.75,"tv":19309.91,"id":72857114}]}]}
{"op":"mcm","clk":"11917012404","pt":1724083986845,"mc":[{"id":"1.232011680","rc":[{"batb":[[0,2.32,4],[1,2.3,4],[2,2.28,38.12]],"ltp":2.28,"tv":11.27,"id":72857116}]}]}
{"op":"mcm","clk":"11917012519","pt":1724083987782,"mc":[{"id":"1.232011680","rc":[{"trd":[[1.75,20067.73]],"batl":[[0,2.2,5.17],[1,1.79,0],[2,2.2,0]],"ltp":1.75,"tv":20080.2,"id":72857114},{"batb":[[0,2.28,34.12],[1,1.33,151.52],[2,1.23,434.78]],"ltp":2.28,"tv":11.27,"id":72857116}],"tv":20091.48}]}
{"op":"mcm","clk":"11917012544","pt":1724083987943,"mc":[{"id":"1.232011680","rc":[{"batb":[[0,1.74,10],[1,1.73,5.73],[2,1.71,61.52]],"ltp":1.75,"tv":20080.2,"id":72857114}]}]}
{"op":"mcm","clk":"11917012929","pt":1724083991123,"mc":[{"id":"1.232011680","rc":[{"batb":[[0,1.73,5.73],[1,1.71,61.52],[2,1.43,8.79]],"ltp":1.75,"tv":20080.2,"id":72857114}]}]}
{"op":"mcm","clk":"11917013848","pt":1724083997885,"mc":[{"id":"1.232011680","rc":[{"batl":[[0,1.75,385.15],[1,2.2,5.17]],"ltp":1.75,"tv":20080.2,"id":72857114}]}]}
{"op":"mcm","clk":"11917014222","pt":1724084000483,"mc":[{"id":"1.232011680","rc":[{"trd":[[1.75,20838.03]],"batb":[[0,1.74,10],[1,1.73,5.73],[2,1.71,61.52]],"batl":[[0,2.2,5.17],[1,2.2,0]],"ltp":1.75,"tv":20850.5,"id":72857114}],"tv":20861.77}]}
{"op":"mcm","clk":"11917014452","pt":1724084001956,"mc":[{"id":"1.232011680","rc":[{"batb":[[0,1.74,14]],"batl":[[0,1.79,4],[1,2.2,5.17]],"ltp":1.75,"tv":20850.5,"id":72857114},{"batb":[[0,2.3,4],[1,2.28,38.12],[2,1.33,151.52]],"ltp":2.28,"tv":11.27,"id":72857116}]}]}
{"op":"mcm","clk":"11917014685","pt":1724084003676,"mc":[{"id":"1.232011680","rc":[{"batb":[[0,1.74,4]],"ltp":1.75,"tv":20850.5,"id":72857114}]}]}
{"op":"mcm","clk":"11917014823","pt":1724084004864,"mc":[{"id":"1.232011680","rc":[{"batb":[[0,1.73,5.73],[1,1.71,61.52],[2,1.43,8.79]],"batl":[[0,1.75,385.15],[1,1.79,4],[2,2.2,5.17]],"ltp":1.75,"tv":20850.5,"id":72857114}]}]}
{"op":"mcm","clk":"11917015238","pt":1724084008385,"mc":[{"id":"1.232011680","rc":[{"trd":[[1.75,21608.33]],"batl":[[0,1.79,4],[1,2.2,5.17],[2,2.2,0]],"ltp":1.75,"tv":21620.8,"id":72857114}],"tv":21632.07}]}
{"op":"mcm","clk":"11917016628","pt":1724084018767,"mc":[{"id":"1.232011680","rc":[{"batl":[[0,1.75,385.15],[1,1.79,4],[2,2.2,5.17]],"ltp":1.75,"tv":21620.8,"id":72857114}]}]}
{"op":"mcm","clk":"11917017072","pt":1724084022298,"mc":[{"id":"1.232011680","rc":[{"trd":[[1.75,22378.62]],"batl":[[0,1.79,4],[1,2.2,5.17],[2,2.2,0]],"ltp":1.75,"tv":22391.09,"id":72857114}],"tv":22402.37}]}
{"op":"mcm","clk":"11917017723","pt":1724084027463,"mc":[{"id":"1.232011680","rc":[{"batl":[[0,1.75,385.15],[1,1.79,4],[2,2.2,5.17]],"ltp":1.75,"tv":22391.09,"id":72857114}]}]}
{"op":"mcm","clk":"11917018471","pt":1724084032582,"mc":[{"id":"1.232011680","rc":[{"trd":[[1.75,23148.92]],"batl":[[0,1.75,4]],"ltp":1.75,"tv":23161.39,"id":72857114},{"batb":[[0,2.34,4],[1,2.32,4],[2,2.28,34.12]],"ltp":2.28,"tv":11.27,"id":72857116}],"tv":23172.67}]}
{"op":"mcm","clk":"11917018623","pt":1724084033649,"mc":[{"id":"1.232011680","rc":[{"batl":[[0,1.79,4],[1,2.2,5.17],[2,2.2,0]],"ltp":1.75,"tv":23161.39,"id":72857114},{"batb":[[0,2.28,34.12],[1,1.33,151.52],[2,1.23,434.78]],"ltp":2.28,"tv":11.27,"id":72857116}]}]}
{"op":"mcm","clk":"11917019298","pt":1724084038969,"mc":[{"id":"1.232011680","rc":[{"batl":[[0,1.75,385.15],[1,1.79,4],[2,2.2,5.17]],"ltp":1.75,"tv":23161.39,"id":72857114}]}]}
{"op":"mcm","clk":"11917019465","pt":1724084040270,"mc":[{"id":"1.232011680","rc":[{"trd":[[1.75,23919.22]],"batl":[[0,1.79,4],[1,2.2,5.17],[2,2.2,0]],"ltp":1.75,"tv":23931.69,"id":72857114}],"tv":23942.96}]}
{"op":"mcm","clk":"11917019877","pt":1724084043468,"mc":[{"id":"1.232011680","rc":[{"batb":[[0,1.75,1.99],[1,1.73,5.73],[2,1.71,61.52]],"ltp":1.75,"tv":23931.69,"id":72857114}]}]}
{"op":"mcm","clk":"11917020384","pt":1724084047571,"mc":[{"id":"1.232011680","rc":[{"batb":[[0,2.3,4],[1,2.28,38.12],[2,1.33,151.52]],"ltp":2.28,"tv":11.27,"id":72857116}]}]}
{"op":"mcm","clk":"11917021078","pt":1724084052605,"mc":[{"id":"1.232011680","rc":[{"batb":[[0,1.73,6.67],[1,1.71,61.52],[2,1.43,8.79]],"ltp":1.75,"tv":23931.69,"id":72857114}]}]}
{"op":"mcm","clk":"11917021782","pt":1724084057889,"mc":[{"id":"1.232011680","rc":[{"batl":[[0,1.76,385.15],[1,1.79,4],[2,2.2,5.17]],"ltp":1.75,"tv":23931.69,"id":72857114}]}]}
{"op":"mcm","clk":"11917022331","pt":1724084062714,"mc":[{"id":"1.232011680","rc":[{"trd":[[1.76,770.3]],"batl":[[0,1.76,4]],"ltp":1.76,"tv":24701.99,"id":72857114}],"tv":24713.26}]}
{"op":"mcm","clk":"11917022675","pt":1724084065495,"mc":[{"id":"1.232011680","rc":[{"batl":[[1,1.79,4.94]],"ltp":1.76,"tv":24701.99,"id":72857114}]}]}
{"op":"mcm","clk":"11917022745","pt":1724084066005,"mc":[{"id":"1.232011680","rc":[{"batl":[[0,1.79,4.94],[1,2.2,5.17],[2,2.2,0]],"ltp":1.76,"tv":24701.99,"id":72857114}]}]}
{"op":"mcm","clk":"11917024160","pt":1724084076811,"mc":[{"id":"1.232011680","rc":[{"trd":[[1.77,3.11]],"batl":[[0,1.79,4]],"ltp":1.77,"tv":24705.1,"id":72857114},{"trd":[[2.3,0.95]],"batb":[[0,2.3,3.05]],"ltp":2.3,"tv":12.22,"id":72857116}],"tv":24717.33}]}
{"op":"mcm","clk":"11917026192","pt":1724084092842,"mc":[{"id":"1.232011680","rc":[{"batl":[[0,1.79,4.94]],"ltp":1.77,"tv":24705.1,"id":72857114}]}]}
{"op":"mcm","clk":"11917026202","pt":1724084092945,"mc":[{"id":"1.232011680","rc":[{"trd":[[1.73,2.54],[1.75,23921.1]],"batb":[[0,1.73,4.46]],"ltp":1.73,"tv":24709.53,"id":72857114}],"tv":24721.75}]}
{"op":"mcm","clk":"11917027627","pt":1724084103413,"mc":[{"id":"1.232011680","rc":[{"batb":[[0,1.73,5.4]],"ltp":1.73,"tv":24709.53,"id":72857114}]}]}
{"op":"mcm","clk":"11917030980","pt":1724084128066,"mc":[{"id":"1.232011680","rc":[{"batl":[[0,1.76,382.84],[1,1.79,4.94],[2,2.2,5.17]],"ltp":1.73,"tv":24709.53,"id":72857114}]}]}
{"op":"mcm","clk":"11917031500","pt":1724084131961,"mc":[{"id":"1.232011680","rc":[{"trd":[[1.76,1535.97]],"batl":[[0,1.79,4.94],[1,2.2,5.17],[2,2.2,0]],"ltp":1.76,"tv":25475.2,"id":72857114}],"tv":25487.43}]}
{"op":"mcm","clk":"11917032619","pt":1724084139852,"mc":[{"id":"1.232011680","rc":[{"batl":[[0,1.76,382.84],[1,1.79,4.94],[2,2.2,5.17]],"ltp":1.76,"tv":25475.2,"id":72857114}]}]}
{"op":"mcm","clk":"11917033890","pt":1724084149285,"mc":[{"id":"1.232011680","rc":[{"trd":[[1.76,2301.65]],"batl":[[0,1.79,4.94],[1,2.2,5.17],[2,2.2,0]],"ltp":1.76,"tv":26240.88,"id":72857114}],"tv":26253.1}]}
{"op":"mcm","clk":"11917035525","pt":1724084160690,"mc":[{"id":"1.232011680","rc":[{"batl":[[0,1.76,385.15],[1,1.79,4.94],[2,2.2,5.17]],"ltp":1.76,"tv":26240.88,"id":72857114}]}]}
{"op":"mcm","clk":"11917035935","pt":1724084163092,"mc":[{"id":"1.232011680","rc":[{"trd":[[1.76,3071.95]],"batl":[[0,1.79,4.94],[1,2.2,5.17],[2,2.2,0]],"ltp":1.76,"tv":27011.17,"id":72857114}],"tv":27023.4}]}
{"op":"mcm","clk":"11917037175","pt":1724084171608,"mc":[{"id":"1.232011680","rc":[{"batl":[[0,1.76,385.15],[1,1.79,4.94],[2,2.2,5.17]],"ltp":1.76,"tv":27011.17,"id":72857114}]}]}
{"op":"mcm","clk":"11917038985","pt":1724084184180,"mc":[{"id":"1.232011680","rc":[{"batl":[[0,1.76,389.15]],"ltp":1.76,"tv":27011.17,"id":72857114}]}]}
{"op":"mcm","clk":"11917043757","pt":1724084218582,"mc":[{"id":"1.232011680","rc":[{"trd":[[1.76,3842.24]],"batl":[[0,1.79,4.94],[1,2.2,5.17],[2,2.2,0]],"ltp":1.76,"tv":27781.47,"id":72857114}],"tv":27793.7}]}
{"op":"mcm","clk":"11917046193","pt":1724084237837,"mc":[{"id":"1.232011680","rc":[{"trd":[[1.77,3.13]],"batb":[[0,1.73,4.46]],"batl":[[0,1.79,4]],"ltp":1.77,"tv":27781.48,"id":72857114},{"trd":[[2.3,0.96]],"batb":[[0,2.3,3.04]],"ltp":2.3,"tv":12.23,"id":72857116}],"tv":27793.72}]}
{"op":"mcm","clk":"11917046515","pt":1724084240035,"mc":[{"id":"1.232011680","rc":[{"batb":[[1,1.72,4.95],[2,1.71,61.52]],"ltp":1.77,"tv":27781.48,"id":72857114}]}]}
{"op":"mcm","clk":"11917071440","pt":1724084428830,"mc":[{"id":"1.232011680","rc":[{"batl":[[0,1.75,462.18],[1,1.79,4],[2,2.2,5.17]],"ltp":1.77,"tv":27781.48,"id":72857114}]}]}
{"op":"mcm","clk":"11917071966","pt":1724084432845,"mc":[{"id":"1.232011680","rc":[{"trd":[[1.75,24845.46]],"batl":[[0,1.79,4],[1,2.2,5.17],[2,2.2,0]],"ltp":1.75,"tv":28705.84,"id":72857114}],"tv":28718.07}]}
{"op":"mcm","clk":"11917072338","pt":1724084435556,"mc":[{"id":"1.232011680","rc":[{"batb":[[0,1.72,4.95],[1,1.71,61.52],[2,1.43,8.79]],"ltp":1.75,"tv":28705.84,"id":72857114}]}]}
{"op":"mcm","clk":"11917073141","pt":1724084441344,"mc":[{"id":"1.232011680","rc":[{"batl":[[0,1.75,462.18],[1,1.79,4],[2,2.2,5.17]],"ltp":1.75,"tv":28705.84,"id":72857114}]}]}
{"op":"mcm","clk":"11917073245","pt":1724084442132,"mc":[{"id":"1.232011680","rc":[{"batl":[[0,1.75,466.18]],"ltp":1.75,"tv":28705.84,"id":72857114},{"batb":[[0,2.32,4],[1,2.3,3.04],[2,2.28,38.12]],"ltp":2.3,"tv":12.23,"id":72857116}]}]}
{"op":"mcm","clk":"11917073890","pt":1724084446835,"mc":[{"id":"1.232011680","rc":[{"trd":[[1.75,25769.81]],"batl":[[0,1.75,4]],"ltp":1.75,"tv":29630.2,"id":72857114}],"tv":29642.43}]}
{"op":"mcm","clk":"11917073994","pt":1724084447554,"mc":[{"id":"1.232011680","rc":[{"batb":[[0,1.73,10],[1,1.72,4.95],[2,1.71,61.52]],"batl":[[0,2.2,5.17],[1,1.79,0],[2,2.2,0]],"ltp":1.75,"tv":29630.2,"id":72857114},{"batb":[[0,2.3,3.04],[1,2.28,38.12],[2,1.33,151.52]],"ltp":2.3,"tv":12.23,"id":72857116}]}]}
{"op":"mcm","clk":"11917074062","pt":1724084448026,"mc":[{"id":"1.232011680","rc":[{"batb":[[1,1.71,61.52],[2,1.43,8.79]],"ltp":1.75,"tv":29630.2,"id":72857114}]}]}
{"op":"mcm","clk":"11917074450","pt":1724084450833,"mc":[{"id":"1.232011680","rc":[{"batb":[[0,1.71,61.52],[1,1.43,8.79],[2,1.33,151.52]],"ltp":1.75,"tv":29630.2,"id":72857114}]}]}
{"op":"mcm","clk":"11917074617","pt":1724084452029,"mc":[{"id":"1.232011680","rc":[{"batb":[[0,1.72,4.62],[1,1.71,61.52],[2,1.43,8.79]],"ltp":1.75,"tv":29630.2,"id":72857114}]}]}
{"op":"mcm","clk":"11917075063","pt":1724084455067,"mc":[{"id":"1.232011680","rc":[{"batl":[[0,1.75,462.18],[1,2.2,5.17]],"ltp":1.75,"tv":29630.2,"id":72857114}]}]}
{"op":"mcm","clk":"11917075372","pt":1724084457461,"mc":[{"id":"1.232011680","rc":[{"batl":[[0,1.75,466.18]],"ltp":1.75,"tv":29630.2,"id":72857114},{"batb":[[0,2.32,4],[1,2.3,3.04],[2,2.28,38.12]],"ltp":2.3,"tv":12.23,"id":72857116}]}]}
{"op":"mcm","clk":"11917075488","pt":1724084458336,"mc":[{"id":"1.232011680","rc":[{"trd":[[1.75,26694.17]],"batl":[[0,1.75,4]],"ltp":1.75,"tv":30554.55,"id":72857114}],"tv":30566.79}]}
{"op":"mcm","clk":"11917075590","pt":1724084459167,"mc":[{"id":"1.232011680","rc":[{"batb":[[0,1.73,10],[1,1.72,4.62],[2,1.71,61.52]],"batl":[[0,2.2,5.17],[1,2.2,0]],"ltp":1.75,"tv":30554.55,"id":72857114},{"batb":[[0,2.3,3.04],[1,2.28,38.12],[2,1.33,151.52]],"ltp":2.3,"tv":12.23,"id":72857116}]}]}
{"op":"mcm","clk":"11917075859","pt":1724084461056,"mc":[{"id":"1.232011680","rc":[{"batb":[[1,1.71,61.52],[2,1.43,8.79]],"ltp":1.75,"tv":30554.55,"id":72857114}]}]}
{"op":"mcm","clk":"11917076043","pt":1724084462358,"mc":[{"id":"1.232011680","rc":[{"batb":[[0,1.71,61.52],[1,1.43,8.79],[2,1.33,151.52]],"ltp":1.75,"tv":30554.55,"id":72857114}]}]}
{"op":"mcm","clk":"11917076181","pt":1724084463448,"mc":[{"id":"1.232011680","rc":[{"batl":[[0,1.74,1.26],[1,2.2,5.17]],"ltp":1.75,"tv":30554.55,"id":72857114}]}]}
{"op":"mcm","clk":"11917076658","pt":1724084466567,"mc":[{"id":"1.232011680","rc":[{"batl":[[1,1.75,462.18],[2,2.2,5.17]],"ltp":1.75,"tv":30554.55,"id":72857114}]}]}
{"op":"mcm","clk":"11917076848","pt":1724084467863,"mc":[{"id":"1.232011680","rc":[{"batl":[[0,1.74,18.32]],"ltp":1.75,"tv":30554.55,"id":72857114}]}]}
{"op":"mcm","clk":"11917077187","pt":1724084470579,"mc":[{"id":"1.232011680","rc":[{"batl":[[1,2.2,5.17],[2,2.2,0]],"ltp":1.75,"tv":30554.55,"id":72857114}]}]}
{"op":"mcm","clk":"11917077269","pt":1724084471257,"mc":[{"id":"1.232011680","rc":[{"batl":[[0,1.74,1.26]],"ltp":1.75,"tv":30554.55,"id":72857114}]}]}
{"op":"mcm","clk":"11917077489","pt":1724084472760,"mc":[{"id":"1.232011680","rc":[{"batb":[[0,1.72,4],[1,1.71,65.52],[2,1.43,8.79]],"ltp":1.75,"tv":30554.55,"id":72857114},{"batl":[[0,2.4,4],[1,2.42,4]],"ltp":2.3,"tv":12.23,"id":72857116}]}]}
{"op":"mcm","clk":"11917079634","pt":1724084489380,"mc":[{"id":"1.232011680","rc":[{"batl":[[1,1.8,517.2],[2,2.2,5.17]],"ltp":1.75,"tv":30554.55,"id":72857114}]}]}
{"op":"mcm","clk":"11917082685","pt":1724084513613,"mc":[{"id":"1.232011680","rc":[{"batb":[[0,1.72,9.22]],"ltp":1.75,"tv":30554.55,"id":72857114}]}]}
{"op":"mcm","clk":"11917084927","pt":1724084528702,"mc":[{"id":"1.232011680","rc":[{"batl":[[1,1.75,462.18],[2,1.8,517.2]],"ltp":1.75,"tv":30554.55,"id":72857114}]}]}
{"op":"mcm","clk":"11917084989","pt":1724084529113,"mc":[{"id":"1.232011680","rc":[{"batb":[[0,1.72,5.22],[1,1.71,61.52]],"ltp":1.75,"tv":30554.55,"id":72857114}]}]}
{"op":"mcm","clk":"11917085162","pt":1724084530105,"mc":[{"id":"1.232011680","rc":[{"batl":[[0,1.74,18.32]],"ltp":1.75,"tv":30554.55,"id":72857114}]}]}
{"op":"mcm","clk":"11917085699","pt":1724084533601,"mc":[{"id":"1.232011680","rc":[{"batl":[[0,1.74,22.32],[1,1.8,517.2],[2,2.2,5.17]],"ltp":1.75,"tv":30554.55,"id":72857114},{"batb":[[0,2.34,4],[1,2.3,3.04],[2,2.28,38.12]],"ltp":2.3,"tv":12.23,"id":72857116}]}]}
{"op":"mcm","clk":"11917085938","pt":1724084535426,"mc":[{"id":"1.232011680","rc":[{"batl":[[0,1.74,1.26]],"ltp":1.75,"tv":30554.55,"id":72857114},{"batb":[[0,2.3,3.04],[1,2.28,38.12],[2,1.33,151.52]],"ltp":2.3,"tv":12.23,"id":72857116}]}]}
{"op":"mcm","clk":"11917087814","pt":1724084548866,"mc":[{"id":"1.232011680","rc":[{"batb":[[0,1.72,9.22]],"ltp":1.75,"tv":30554.55,"id":72857114}]}]}
{"op":"mcm","clk":"11917089812","pt":1724084564504,"mc":[{"id":"1.232011680","rc":[{"batb":[[0,1.72,9.94]],"batl":[[0,1.8,517.2],[1,2.2,5.17],[2,2.2,0]],"ltp":1.75,"tv":30554.55,"id":72857114}]}]}
{"op":"mcm","clk":"11917089926","pt":1724084565283,"mc":[{"id":"1.232011680","rc":[{"trd":[[1.74,1.45]],"batb":[[0,1.72,5.22]],"batl":[[0,1.73,461.45],[1,1.8,517.2],[2,2.2,5.17]],"ltp":1.74,"tv":30556.0,"id":72857114}],"tv":30568.23}]}
{"op":"mcm","clk":"11917090145","pt":1724084566995,"mc":[{"id":"1.232011680","rc":[{"trd":[[1.73,925.45]],"batb":[[0,1.71,62.24],[1,1.43,8.79],[2,1.33,151.52]],"batl":[[0,1.8,517.2],[1,2.2,5.17],[2,2.2,0]],"ltp":1.73,"tv":31478.91,"id":72857114}],"tv":31491.14}]}
{"op":"mcm","clk":"11917091263","pt":1724084575503,"mc":[{"id":"1.232011680","rc":[{"batl":[[0,1.8,518.14]],"ltp":1.73,"tv":31478.91,"id":72857114}]}]}
{"op":"mcm","clk":"11917091388","pt":1724084576485,"mc":[{"id":"1.232011680","rc":[{"trd":[[1.75,26696.05],[1.77,7.08],[1.79,11.03]],"batb":[[0,1.72,4.62],[1,1.71,61.52],[2,1.43,8.79]],"batl":[[0,1.8,517.2]],"ltp":1.79,"tv":31485.78,"id":72857114},{"trd":[[2.28,12.08],[2.3,4]],"batb":[[0,2.28,37.31],[1,1.33,151.52],[2,1.23,434.78]],"ltp":2.28,"tv":16.08,"id":72857116}],"tv":31501.86}]}
{"op":"mcm","clk":"11917091525","pt":1724084577567,"mc":[{"id":"1.232011680","rc":[{"batb":[[0,2.28,38.12]],"ltp":2.28,"tv":16.08,"id":72857116}]}]}
{"op":"mcm","clk":"11917091672","pt":1724084578511,"mc":[{"id":"1.232011680","rc":[{"trd":[[1.71,3.98],[1.72,9.24]],"batb":[[0,1.71,60.77],[1,1.43,8.79],[2,1.33,151.52]],"ltp":1.71,"tv":31496.52,"id":72857114}],"tv":31512.61}]}
{"op":"mcm","clk":"11917091804","pt":1724084579598,"mc":[{"id":"1.232011680","rc":[{"batl":[[0,1.78,4.47],[1,1.8,517.2],[2,2.2,5.17]],"ltp":1.71,"tv":31496.52,"id":72857114}]}]}
{"op":"mcm","clk":"11917092221","pt":1724084582577,"mc":[{"id":"1.232011680","rc":[{"batb":[[0,1.71,61.52]],"ltp":1.71,"tv":31496.52,"id":72857114}]}]}
{"op":"mcm","clk":"11917092616","pt":1724084585501,"mc":[{"id":"1.232011680","rc":[{"batl":[[0,1.78,5.41]],"ltp":1.71,"tv":31496.52,"id":72857114}]}]}
{"op":"mcm","clk":"11917094243","pt":1724084597011,"mc":[{"id":"1.232011680","rc":[{"batl":[[0,1.74,462.18],[1,1.78,5.41],[2,1.8,517.2]],"ltp":1.71,"tv":31496.52,"id":72857114}]}]}
{"op":"mcm","clk":"11917094511","pt":1724084598839,"mc":[{"id":"1.232011680","rc":[{"batl":[[1,1.8,518.14],[2,2.2,5.17]],"ltp":1.71,"tv":31496.52,"id":72857114}]}]}
{"op":"mcm","clk":"11917094592","pt":1724084599314,"mc":[{"id":"1.232011680","rc":[{"batl":[[0,1.73,521.79],[1,1.74,462.18],[2,2.2,6.11]],"ltp":1.71,"tv":31496.52,"id":72857114}]}]}
{"op":"mcm","clk":"11917095353","pt":1724084604638,"mc":[{"id":"1.232011680","rc":[{"batl":[[2,1.75,1.03]],"ltp":1.71,"tv":31496.52,"id":72857114}]}]}
{"op":"mcm","clk":"11917095498","pt":1724084605728,"mc":[{"id":"1.232011680","rc":[{"batl":[[0,1.72,517.2],[1,1.73,4.6],[2,1.74,462.18]],"ltp":1.71,"tv":31496.52,"id":72857114}]}]}
{"op":"mcm","clk":"11917096154","pt":1724084609633,"mc":[{"id":"1.232011680","rc":[{"batl":[[0,1.72,521.2]],"ltp":1.71,"tv":31496.52,"id":72857114},{"batb":[[0,2.38,4],[1,2.28,38.12],[2,1.33,151.52]],"ltp":2.28,"tv":16.08,"id":72857116}]}]}
{"op":"mcm","clk":"11917096827","pt":1724084613245,"mc":[{"id":"1.232011680","rc":[{"trd":[[1.71,127.02]],"batb":[[0,1.43,8.79],[1,1.33,151.52],[2,1.23,434.78]],"batl":[[0,1.71,455.68],[1,1.72,4],[2,1.73,4.6]],"ltp":1.71,"tv":31619.56,"id":72857114}],"tv":31635.65}]}
{"op":"mcm","clk":"11917097051","pt":1724084614645,"mc":[{"id":"1.232011680","rc":[{"batl":[[0,1.7,4.67],[1,1.71,455.68],[2,1.72,4]],"ltp":1.71,"tv":31619.56,"id":72857114}]}]}
{"op":"mcm","clk":"11917097460","pt":1724084617711,"mc":[{"id":"1.232011680","rc":[{"batb":[[0,1.67,65.19],[1,1.43,8.79],[2,1.33,151.52]],"ltp":1.71,"tv":31619.56,"id":72857114}]}]}
{"op":"mcm","clk":"11917098424","pt":1724084624846,"mc":[{"id":"1.232011680","rc":[{"batb":[[0,1.68,4],[1,1.67,69.19],[2,1.48,3.18]],"batl":[[1,1.72,4],[2,1.75,1.03]],"ltp":1.71,"tv":31619.56,"id":72857114}]}]}
{"op":"mcm","clk":"11917098542","pt":1724084625628,"mc":[{"id":"1.232011680","rc":[{"batl":[[0,1.75,1.03],[1,2.2,5.17],[2,1.75,0]],"ltp":1.71,"tv":31619.56,"id":72857114},{"batb":[[0,2.3,10]],"batl":[[0,2.48,4],[1,2.5,4]],"ltp":2.28,"tv":16.08,"id":72857116}]}]}
{"op":"mcm","clk":"11917098635","pt":1724084626255,"mc":[{"id":"1.232011680","rc":[{"batb":[[2,1.48,11.97]],"ltp":1.71,"tv":31619.56,"id":72857114}]}]}
{"op":"mcm","clk":"11917099024","pt":1724084628764,"mc":[{"id":"1.232011680","rc":[{"batb":[[0,2.28,38.12],[1,1.33,151.52],[2,1.23,434.78]],"ltp":2.28,"tv":16.08,"id":72857116}]}]}
{"op":"mcm","clk":"11917100816","pt":1724084640670,"mc":[{"id":"1.232011680","rc":[{"trd":[[1.48,23.95],[1.66,6.03],[1.67,144.32],[1.68,8]],"batb":[[0,1.33,151.52],[1,1.23,434.78],[2,1.19,526.32]],"ltp":1.48,"tv":31801.85,"id":72857114},{"trd":[[2.48,4],[2.5,4]],"ltp":2.5,"tv":24.08,"id":72857116}],"tv":31825.93}]}
{"op":"mcm","clk":"11917100931","pt":1724084641354,"mc":[{"id":"1.232011680","rc":[{"batl":[[0,1.68,358.53],[1,1.75,1.03],[2,2.2,5.17]],"ltp":1.48,"tv":31801.85,"id":72857114}]}]}
{"op":"mcm","clk":"11917101343","pt":1724084644150,"mc":[{"id":"1.232011680","rc":[{"batl":[[0,1.67,4.76],[1,1.68,358.53],[2,1.75,1.03]],"ltp":1.48,"tv":31801.85,"id":72857114}]}]}
{"op":"mcm","clk":"11917102003","pt":1724084648199,"mc":[{"id":"1.232011680","rc":[{"batb":[[0,1.48,10.65],[1,1.33,151.52],[2,1.23,434.78]],"ltp":1.48,"tv":31801.85,"id":72857114},{"batb":[[0,2.46,6.4],[1,2.28,38.12],[2,1.33,151.52]],"ltp":2.5,"tv":24.08,"id":72857116}]}]}
{"op":"mcm","clk":"11917102887","pt":1724084654482,"mc":[{"id":"1.232011680","rc":[{"batl":[[0,1.58,3.18],[1,1.67,4.76],[2,1.68,358.53]],"ltp":1.48,"tv":31801.85,"id":72857114}]}]}
{"op":"mcm","clk":"11917103958","pt":1724084662174,"mc":[{"id":"1.232011680","rc":[{"batb":[[0,1.52,10.33]],"ltp":1.48,"tv":31801.85,"id":72857114},{"batb":[[0,2.34,6.72]],"ltp":2.5,"tv":24.08,"id":72857116}]}]}
{"op":"mcm","clk":"11917105007","pt":1724084670611,"mc":[{"id":"1.232011680","rc":[{"batb":[[0,1.52,14.33]],"ltp":1.48,"tv":31801.85,"id":72857114}]}]}
{"op":"mcm","clk":"11917105274","pt":1724084672531,"mc":[{"id":"1.232011680","rc":[{"trd":[[1.58,6.36]],"batb":[[0,1.52,14.74]],"batl":[[0,1.67,4.76],[1,1.68,358.53],[2,1.75,1.03]],"ltp":1.58,"tv":31808.21,"id":72857114}],"tv":31832.3}]}
{"op":"mcm","clk":"11917105791","pt":1724084675437,"mc":[{"id":"1.232011680","rc":[{"batl":[[0,1.67,21.81]],"ltp":1.58,"tv":31808.21,"id":72857114}]}]}
{"op":"mcm","clk":"11917106503","pt":1724084680539,"mc":[{"id":"1.232011680","rc":[{"batb":[[0,1.52,14.33]],"ltp":1.58,"tv":31808.21,"id":72857114}]}]}
{"op":"mcm","clk":"11917106830","pt":1724084683115,"mc":[{"id":"1.232011680","rc":[{"batb":[[0,1.54,10.25],[1,1.52,4],[2,1.33,151.52]],"ltp":1.58,"tv":31808.21,"id":72857114}]}]}
{"op":"mcm","clk":"11917107088","pt":1724084685143,"mc":[{"id":"1.232011680","rc":[{"batl":[[1,1.75,1.03],[2,1.8,358.53]],"ltp":1.58,"tv":31808.21,"id":72857114}]}]}
{"op":"mcm","clk":"11917107203","pt":1724084686024,"mc":[{"id":"1.232011680","rc":[{"batl":[[0,1.75,1.03],[1,1.8,358.53],[2,2.2,5.17]],"ltp":1.58,"tv":31808.21,"id":72857114}]}]}
{"op":"mcm","clk":"11917107797","pt":1724084690533,"mc":[{"id":"1.232011680","rc":[{"batb":[[0,1.55,1.99],[1,1.54,10.25]],"ltp":1.58,"tv":31808.21,"id":72857114}]}]}
{"op":"mcm","clk":"11917109369","pt":1724084702472,"mc":[{"id":"1.232011680","rc":[{"batl":[[0,1.75,1.97]],"ltp":1.58,"tv":31808.21,"id":72857114}]}]}
{"op":"mcm","clk":"11917109443","pt":1724084703155,"mc":[{"id":"1.232011680","rc":[{"batb":[[0,1.56,10.09],[1,1.55,1.99]],"ltp":1.58,"tv":31808.21,"id":72857114},{"batb":[[0,2.28,38.12],[1,2.26,6.97]],"ltp":2.5,"tv":24.08,"id":72857116}]}]}
{"op":"mcm","clk":"11917109802","pt":1724084705762,"mc":[{"id":"1.232011680","rc":[{"batl":[[0,1.69,4.71],[1,1.7,463.12],[2,1.75,1.03]],"ltp":1.58,"tv":31808.21,"id":72857114}]}]}
{"op":"mcm","clk":"11917110796","pt":1724084713341,"mc":[{"id":"1.232011680","rc":[{"batl":[[1,1.75,1.97],[2,1.8,358.53]],"ltp":1.58,"tv":31808.21,"id":72857114}]}]}
{"op":"mcm","clk":"11917111015","pt":1724084714881,"mc":[{"id":"1.232011680","rc":[{"batl":[[0,1.75,1.97],[1,1.8,358.53],[2,2.2,5.17]],"ltp":1.58,"tv":31808.21,"id":72857114}]}]}
{"op":"mcm","clk":"11917111037","pt":1724084715063,"mc":[{"id":"1.232011680","rc":[{"batl":[[1,1.78,4.47],[2,1.8,358.53]],"ltp":1.58,"tv":31808.21,"id":72857114}]}]}
{"op":"mcm","clk":"11917112054","pt":1724084723463,"mc":[{"id":"1.232011680","rc":[{"batb":[[0,1.55,1.99],[1,1.33,151.52],[2,1.23,434.78]],"ltp":1.58,"tv":31808.21,"id":72857114},{"batb":[[1,1.33,151.52],[2,1.23,434.78]],"ltp":2.5,"tv":24.08,"id":72857116}]}]}
{"op":"mcm","clk":"11917112795","pt":1724084729159,"mc":[{"id":"1.232011680","rc":[{"batl":[[0,1.68,462.18],[1,1.75,1.97],[2,1.78,4.47]],"ltp":1.58,"tv":31808.21,"id":72857114}]}]}
{"op":"mcm","clk":"11917113063","pt":1724084731192,"mc":[{"id":"1.232011680","rc":[{"batl":[[0,1.67,4.76],[1,1.68,462.18],[2,1.75,1.97]],"ltp":1.58,"tv":31808.21,"id":72857114}]}]}
{"op":"mcm","clk":"11917114145","pt":1724084740392,"mc":[{"id":"1.232011680","rc":[{"trd":[[1.67,152.32]],"batl":[[0,1.68,462.94],[1,1.75,1.97],[2,1.8,358.53]],"ltp":1.67,"tv":31816.21,"id":72857114}],"tv":31840.29}]}
{"op":"mcm","clk":"11917116171","pt":1724084756898,"mc":[{"id":"1.232011680","rc":[{"batb":[[0,1.33,151.52],[1,1.23,434.78],[2,1.19,526.32]],"ltp":1.67,"tv":31816.21,"id":72857114}]}]}
{"op":"mcm","clk":"11917116182","pt":1724084757003,"mc":[{"id":"1.232011680","rc":[{"batb":[[0,1.52,2.6],[1,1.33,151.52],[2,1.23,434.78]],"ltp":1.67,"tv":31816.21,"id":72857114}]}]}
{"op":"mcm","clk":"11917116338","pt":1724084758495,"mc":[{"id":"1.232011680","rc":[{"trd":[[1.67,153.84],[1.68,930.83]],"batl":[[0,1.7,1.7],[1,1.75,1.03]],"ltp":1.68,"tv":32740.56,"id":72857114}],"tv":32764.65}]}
{"op":"mcm","clk":"11917117540","pt":1724084768638,"mc":[{"id":"1.232011680","rc":[{"batb":[[0,1.55,20],[1,1.52,2.6],[2,1.33,151.52]],"ltp":1.68,"tv":32740.56,"id":72857114}]}]}
{"op":"mcm","clk":"11917118294","pt":1724084774406,"mc":[{"id":"1.232011680","rc":[{"batl":[[0,1.68,462.94],[1,1.75,1.97]],"ltp":1.68,"tv":32740.56,"id":72857114}]}]}
{"op":"mcm","clk":"11917118375","pt":1724084775028,"mc":[{"id":"1.232011680","rc":[{"batl":[[0,1.67,16.92],[1,1.68,462.94],[2,1.75,1.97]],"ltp":1.68,"tv":32740.56,"id":72857114}]}]}
{"op":"mcm","clk":"11917119515","pt":1724084783819,"mc":[{"id":"1.232011680","rc":[{"batb":[[0,1.55,20.94]],"ltp":1.68,"tv":32740.56,"id":72857114}]}]}
{"op":"mcm","clk":"11917119698","pt":1724084785234,"mc":[{"id":"1.232011680","rc":[{"batl":[[1,1.7,1.7],[2,1.75,1.03]],"ltp":1.68,"tv":32740.56,"id":72857114}]}]}
{"op":"mcm","clk":"11917119910","pt":1724084786939,"mc":[{"id":"1.232011680","rc":[{"batl":[[0,1.7,1.7],[1,1.75,1.03],[2,1.8,358.53]],"ltp":1.68,"tv":32740.56,"id":72857114}]}]}
{"op":"mcm","clk":"11917121653","pt":1724084800669,"mc":[{"id":"1.232011680","rc":[{"batl":[[0,1.68,462.94],[1,1.75,1.97]],"ltp":1.68,"tv":32740.56,"id":72857114}]}]}
{"op":"mcm","clk":"11917122068","pt":1724084803890,"mc":[{"id":"1.232011680","rc":[{"batl":[[1,1.7,4.94],[2,1.75,1.03]],"ltp":1.68,"tv":32740.56,"id":72857114}]}]}
{"op":"mcm","clk":"11917122284","pt":1724084805345,"mc":[{"id":"1.232011680","rc":[{"trd":[[1.68,1853.66]],"batl":[[0,1.7,5.7],[1,1.75,1.03],[2,1.8,358.53]],"ltp":1.68,"tv":33663.4,"id":72857114}],"tv":33687.48}]}
{"op":"mcm","clk":"11917123233","pt":1724084812158,"mc":[{"id":"1.232011680","rc":[{"batb":[[1,1.54,10.21],[2,1.52,2.6]],"ltp":1.68,"tv":33663.4,"id":72857114},{"batb":[[0,2.3,6.84],[1,2.28,38.12],[2,1.33,151.52]],"ltp":2.5,"tv":24.08,"id":72857116}]}]}
{"op":"mcm","clk":"11917123485","pt":1724084814185,"mc":[{"id":"1.232011680","rc":[{"batl":[[0,1.68,462.94],[1,1.7,4.94],[2,1.75,1.03]],"ltp":1.68,"tv":33663.4,"id":72857114}]}]}
{"op":"mcm","clk":"11917123946","pt":1724084817763,"mc":[{"id":"1.232011680","rc":[{"trd":[[1.68,2776.49]],"batl":[[0,1.7,5.7],[1,1.75,1.03],[2,1.8,358.53]],"ltp":1.68,"tv":34586.23,"id":72857114}],"tv":34610.31}]}
{"op":"mcm","clk":"11917124473","pt":1724084821892,"mc":[{"id":"1.232011680","rc":[{"batl":[[0,1.67,3.04],[1,1.7,5.7],[2,1.75,1.03]],"ltp":1.68,"tv":34586.23,"id":72857114}]}]}
{"op":"mcm","clk":"11917124538","pt":1724084822301,"mc":[{"id":"1.232011680","rc":[{"batb":[[1,2.28,34.12]],"ltp":2.5,"tv":24.08,"id":72857116}]}]}
{"op":"mcm","clk":"11917125737","pt":1724084830909,"mc":[{"id":"1.232011680","rc":[{"trd":[[1.67,159.93]],"batb":[[0,1.57,1.48],[1,1.55,20],[2,1.54,10.21]],"batl":[[0,1.7,5.7],[1,1.75,1.03],[2,1.8,358.53]],"ltp":1.67,"tv":34592.32,"id":72857114}],"tv":34616.4}]}
{"op":"mcm","clk":"11917126735","pt":1724084838113,"mc":[{"id":"1.232011680","rc":[{"batl":[[0,1.68,462.94],[1,1.7,4.94],[2,1.75,1.03]],"ltp":1.67,"tv":34592.32,"id":72857114}]}]}
{"op":"mcm","clk":"11917126869","pt":1724084839108,"mc":[{"id":"1.232011680","rc":[{"trd":[[1.67,161]],"batb":[[0,1.55,20.94],[1,1.54,10.21],[2,1.52,2.6]],"batl":[[0,1.67,16.38],[1,1.68,462.94],[2,1.7,4.94]],"ltp":1.67,"tv":34593.39,"id":72857114}],"tv":34617.47}]}
{"op":"mcm","clk":"11917127039","pt":1724084840409,"mc":[{"id":"1.232011680","rc":[{"trd":[[1.67,193.76],[1.68,3666.57]],"batl":[[0,1.68,17.14],[1,1.7,4.94],[2,1.75,1.03]],"ltp":1.68,"tv":35516.23,"id":72857114}],"tv":35540.31}]}
{"op":"mcm","clk":"11917127108","pt":1724084841029,"mc":[{"id":"1.232011680","rc":[{"batb":[[0,1.56,19.05],[1,1.55,20],[2,1.54,10.21]],"ltp":1.68,"tv":35516.23,"id":72857114}]}]}
{"op":"mcm","clk":"11917128120","pt":1724084848321,"mc":[{"id":"1.232011680","rc":[{"trd":[[1.68,3666.77]],"batl":[[0,1.68,17.04]],"ltp":1.68,"tv":35516.43,"id":72857114}],"tv":35540.51}]}
{"op":"mcm","clk":"11917128535","pt":1724084851540,"mc":[{"id":"1.232011680","rc":[{"batb":[[0,1.58,3.58],[1,1.56,19.05],[2,1.55,20]],"ltp":1.68,"tv":35516.43,"id":72857114}]}]}
{"op":"mcm","clk":"11917129558","pt":1724084858939,"mc":[{"id":"1.232011680","rc":[{"trd":[[1.56,27.54],[1.57,1.88],[1.58,13.52]],"batb":[[0,1.56,4.34],[1,1.55,20],[2,1.54,10.21]],"batl":[[0,1.7,4.94],[1,1.75,1.03],[2,1.8,358.53]],"ltp":1.56,"tv":35553.01,"id":72857114}],"tv":35577.1}]}
{"op":"mcm","clk":"11917131142","pt":1724084870436,"mc":[{"id":"1.232011680","rc":[{"batl":[[0,1.69,3.58],[1,1.7,4.94],[2,1.75,1.03]],"ltp":1.56,"tv":35553.01,"id":72857114}]}]}
{"op":"mcm","clk":"11917131306","pt":1724084871928,"mc":[{"id":"1.232011680","rc":[{"batl":[[1,1.7,4]],"ltp":1.56,"tv":35553.01,"id":72857114}]}]}
{"op":"mcm","clk":"11917131318","pt":1724084872035,"mc":[{"id":"1.232011680","rc":[{"batl":[[0,1.69,4.52]],"ltp":1.56,"tv":35553.01,"id":72857114}]}]}
{"op":"mcm","clk":"11917132741","pt":1724084883039,"mc":[{"id":"1.232011680","rc":[{"batl":[[0,1.64,462.18],[1,1.69,4.52],[2,1.7,4]],"ltp":1.56,"tv":35553.01,"id":72857114}]}]}
{"op":"mcm","clk":"11917133352","pt":1724084887446,"mc":[{"id":"1.232011680","rc":[{"trd":[[1.64,924.36]],"batb":[[2,1.52,2.6]],"batl":[[0,1.69,4.52],[1,1.7,4],[2,1.75,1.03]],"ltp":1.64,"tv":36477.37,"id":72857114},{"batb":[[0,2.28,34.12],[1,1.33,151.52],[2,1.23,434.78]],"ltp":2.5,"tv":24.08,"id":72857116}],"tv":36501.46}]}
{"op":"mcm","clk":"11917135074","pt":1724084901863,"mc":[{"id":"1.232011680","rc":[{"batb":[[2,1.33,151.52]],"ltp":1.64,"tv":36477.37,"id":72857114}]}]}
{"op":"mcm","clk":"11917135098","pt":1724084902075,"mc":[{"id":"1.232011680","rc":[{"batb":[[2,1.48,2.6]],"ltp":1.64,"tv":36477.37,"id":72857114}]}]}
{"op":"mcm","clk":"11917135397","pt":1724084904370,"mc":[{"id":"1.232011680","rc":[{"batl":[[0,1.65,462.18],[1,1.69,4.52],[2,1.7,4]],"ltp":1.64,"tv":36477.37,"id":72857114}]}]}
{"op":"mcm","clk":"11917136309","pt":1724084909895,"mc":[{"id":"1.232011680","rc":[{"batb":[[0,1.58,3.58],[1,1.56,4.34],[2,1.55,20]],"ltp":1.64,"tv":36477.37,"id":72857114}]}]}
{"op":"mcm","clk":"11917136363","pt":1724084910308,"mc":[{"id":"1.232011680","rc":[{"trd":[[1.65,924.36]],"batl":[[0,1.69,4.52],[1,1.7,4],[2,1.75,1.03]],"ltp":1.65,"tv":37401.73,"id":72857114}],"tv":37425.81}]}
{"op":"mcm","clk":"11917136619","pt":1724084911608,"mc":[{"id":"1.232011680","rc":[{"batb":[[2,1.55,30.16]],"ltp":1.65,"tv":37401.73,"id":72857114},{"batb":[[0,2.28,41.02]],"ltp":2.5,"tv":24.08,"id":72857116}]}]}
{"op":"mcm","clk":"11917137167","pt":1724084915283,"mc":[{"id":"1.232011680","rc":[{"trd":[[1.58,19.35]],"batb":[[0,1.56,5.01],[1,1.55,30.16],[2,1.48,2.6]],"ltp":1.58,"tv":37407.55,"id":72857114}],"tv":37431.64}]}
{"op":"mcm","clk":"11917137424","pt":1724084917009,"mc":[{"id":"1.232011680","rc":[{"trd":[[1.66,7.91],[1.69,3.62]],"batl":[[0,1.69,1.77]],"ltp":1.69,"tv":37413.05,"id":72857114}],"tv":37437.14}]}
{"op":"mcm","clk":"11917139343","pt":1724084931721,"mc":[{"id":"1.232011680","rc":[{"batb":[[1,1.55,20]],"ltp":1.69,"tv":37413.05,"id":72857114},{"batb":[[0,2.28,34.12]],"ltp":2.5,"tv":24.08,"id":72857116}]}]}
{"op":"mcm","clk":"11917139464","pt":1724084932607,"mc":[{"id":"1.232011680","rc":[{"batl":[[0,1.65,462.18],[1,1.69,1.77],[2,1.7,4]],"ltp":1.69,"tv":37413.05,"id":72857114}]}]}
{"op":"mcm","clk":"11917139719","pt":1724084934419,"mc":[{"id":"1.232011680","rc":[{"batl":[[1,1.69,2.71]],"ltp":1.69,"tv":37413.05,"id":72857114}]}]}
{"op":"mcm","clk":"11917140129","pt":1724084937712,"mc":[{"id":"1.232011680","rc":[{"trd":[[1.65,1848.71]],"batl":[[0,1.69,2.71],[1,1.7,4],[2,1.75,1.03]],"ltp":1.65,"tv":38337.41,"id":72857114}],"tv":38361.49}]}
{"op":"mcm","clk":"11917141422","pt":1724084946455,"mc":[{"id":"1.232011680","rc":[{"batb":[[0,1.58,1.61],[1,1.56,4.34],[2,1.55,20]],"ltp":1.65,"tv":38337.41,"id":72857114}]}]}
{"op":"mcm","clk":"11917142025","pt":1724084950621,"mc":[{"id":"1.232011680","rc":[{"batl":[[0,1.66,462.18],[1,1.69,2.71],[2,1.7,4]],"ltp":1.65,"tv":38337.41,"id":72857114}]}]}
{"op":"mcm","clk":"11917142646","pt":1724084954925,"mc":[{"id":"1.232011680","rc":[{"trd":[[1.66,932.26]],"batl":[[0,1.69,2.71],[1,1.7,4],[2,1.75,1.03]],"ltp":1.66,"tv":39261.77,"id":72857114}],"tv":39285.85}]}
{"op":"mcm","clk":"11917143620","pt":1724084961743,"mc":[{"id":"1.232011680","rc":[{"batb":[[0,1.58,4.09]],"ltp":1.66,"tv":39261.77,"id":72857114}]}]}
{"op":"mcm","clk":"11917143703","pt":1724084962366,"mc":[{"id":"1.232011680","rc":[{"trd":[[1.58,23.31],[1.59,1.88]],"batb":[[0,1.58,1.17]],"ltp":1.58,"tv":39267.61,"id":72857114}],"tv":39291.69}]}
{"op":"mcm","clk":"11917145354","pt":1724084974487,"mc":[{"id":"1.232011680","rc":[{"trd":[[1.67,195.64],[1.69,7.16],[1.7,0.06]],"batl":[[0,1.7,3.97],[1,1.75,1.03],[2,1.8,358.53]],"ltp":1.7,"tv":39273.09,"id":72857114}],"tv":39297.18}]}
{"op":"mcm","clk":"11917147253","pt":1724084987999,"mc":[{"id":"1.232011680","rc":[{"batl":[[0,1.65,462.18],[1,1.7,3.97],[2,1.75,1.03]],"ltp":1.7,"tv":39273.09,"id":72857114}]}]}
{"op":"mcm","clk":"11917147501","pt":1724084989507,"mc":[{"id":"1.232011680","rc":[{"batl":[[1,1.69,3.51],[2,1.7,3.97]],"ltp":1.7,"tv":39273.09,"id":72857114}]}]}
{"op":"mcm","clk":"11917147921","pt":1724084992683,"mc":[{"id":"1.232011680","rc":[{"trd":[[1.65,2773.07]],"batl":[[0,1.69,3.51],[1,1.7,3.97],[2,1.75,1.03]],"ltp":1.65,"tv":40197.45,"id":72857114}],"tv":40221.54}]}
{"op":"mcm","clk":"11917148030","pt":1724084993488,"mc":[{"id":"1.232011680","rc":[{"batb":[[0,1.58,2.11]],"ltp":1.65,"tv":40197.45,"id":72857114}]}]}
{"op":"mcm","clk":"11917148449","pt":1724084996898,"mc":[{"id":"1.232011680","rc":[{"batb":[[0,1.56,5.28],[1,1.55,20],[2,1.48,2.6]],"ltp":1.65,"tv":40197.45,"id":72857114}]}]}
{"op":"mcm","clk":"11917148460","pt":1724084996999,"mc":[{"id":"1.232011680","rc":[{"batb":[[0,1.58,4.52],[1,1.56,4.34],[2,1.55,20]],"ltp":1.65,"tv":40197.45,"id":72857114}]}]}
{"op":"mcm","clk":"11917149116","pt":1724085001527,"mc":[{"id":"1.232011680","rc":[{"batb":[[0,2.28,48.11]],"ltp":2.5,"tv":24.08,"id":72857116}]}]}
{"op":"mcm","clk":"11917149603","pt":1724085004512,"mc":[{"id":"1.232011680","rc":[{"batl":[[0,1.69,4.45]],"ltp":1.65,"tv":40197.45,"id":72857114}]}]}
{"op":"mcm","clk":"11917149841","pt":1724085006094,"mc":[{"id":"1.232011680","rc":[{"batl":[[0,1.66,462.18],[1,1.69,4.45],[2,1.7,3.97]],"ltp":1.65,"tv":40197.45,"id":72857114}]}]}
{"op":"mcm","clk":"11917150228","pt":1724085008523,"mc":[{"id":"1.232011680","rc":[{"batb":[[0,2.48,12.1],[1,2.28,48.11],[2,1.33,151.52]],"ltp":2.5,"tv":24.08,"id":72857116}]}]}
{"op":"mcm","clk":"11917150544","pt":1724085010514,"mc":[{"id":"1.232011680","rc":[{"trd":[[1.66,1856.62]],"batl":[[0,1.69,4.45],[1,1.7,3.97],[2,1.75,1.03]],"ltp":1.66,"tv":41121.81,"id":72857114},{"batb":[[0,2.28,48.11],[1,1.33,151.52],[2,1.23,434.78]],"ltp":2.5,"tv":24.08,"id":72857116}],"tv":41145.89}]}
{"op":"mcm","clk":"11917151455","pt":1724085016727,"mc":[{"id":"1.232011680","rc":[{"trd":[[1.58,27.25],[1.6,1.88]],"batb":[[0,1.58,1.61]],"ltp":1.58,"tv":41127.63,"id":72857114}],"tv":41151.72}]}
{"op":"mcm","clk":"11917151807","pt":1724085019045,"mc":[{"id":"1.232011680","rc":[{"trd":[[1.67,197.52],[1.69,10.78]],"batl":[[0,1.69,1.7]],"ltp":1.69,"tv":41133.14,"id":72857114}],"tv":41157.22}]}
{"op":"mcm","clk":"11917154221","pt":1724085035429,"mc":[{"id":"1.232011680","rc":[{"batb":[[0,1.58,2.55]],"ltp":1.69,"tv":41133.14,"id":72857114}]}]}
{"op":"mcm","clk":"11917155521","pt":1724085044860,"mc":[{"id":"1.232011680","rc":[{"batl":[[0,1.69,2.64]],"ltp":1.69,"tv":41133.14,"id":72857114}]}]}
{"op":"mcm","clk":"11917156246","pt":1724085049926,"mc":[{"id":"1.232011680","rc":[{"batl":[[0,1.69,4.7]],"ltp":1.69,"tv":41133.14,"id":72857114}]}]}
{"op":"mcm","clk":"11917156762","pt":1724085053565,"mc":[{"id":"1.232011680","rc":[{"batl":[[0,1.65,454.48],[1,1.69,4.7],[2,1.7,3.97]],"ltp":1.69,"tv":41133.14,"id":72857114}]}]}
{"op":"mcm","clk":"11917157028","pt":1724085055544,"mc":[{"id":"1.232011680","rc":[{"batb":[[0,2.5,11.94],[1,2.28,48.11],[2,1.33,151.52]],"ltp":2.5,"tv":24.08,"id":72857116}]}]}
{"op":"mcm","clk":"11917157285","pt":1724085057472,"mc":[{"id":"1.232011680","rc":[{"trd":[[1.65,3682.02]],"batl":[[0,1.69,4.7],[1,1.7,3.97],[2,1.75,1.03]],"ltp":1.65,"tv":42042.09,"id":72857114}],"tv":42066.17}]}
{"op":"mcm","clk":"11917157492","pt":1724085058739,"mc":[{"id":"1.232011680","rc":[{"batb":[[0,1.58,4.52]],"ltp":1.65,"tv":42042.09,"id":72857114},{"batb":[[0,2.28,48.11],[1,1.33,151.52],[2,1.23,434.78]],"ltp":2.5,"tv":24.08,"id":72857116}]}]}
{"op":"mcm","clk":"11917159008","pt":1724085069340,"mc":[{"id":"1.232011680","rc":[{"batl":[[0,1.65,454.48],[1,1.69,4.7],[2,1.7,3.97]],"ltp":1.65,"tv":42042.09,"id":72857114}]}]}
{"op":"mcm","clk":"11917159319","pt":1724085071583,"mc":[{"id":"1.232011680","rc":[{"batb":[[0,2.5,11.94],[1,2.28,48.11],[2,1.33,151.52]],"ltp":2.5,"tv":24.08,"id":72857116}]}]}
{"op":"mcm","clk":"11917159893","pt":1724085075588,"mc":[{"id":"1.232011680","rc":[{"trd":[[1.65,4590.97]],"batl":[[0,1.69,4.7],[1,1.7,3.97],[2,1.75,1.03]],"ltp":1.65,"tv":42951.04,"id":72857114},{"batb":[[0,2.28,48.11],[1,1.33,151.52],[2,1.23,434.78]],"ltp":2.5,"tv":24.08,"id":72857116}],"tv":42975.12}]}
{"op":"mcm","clk":"11917160630","pt":1724085080648,"mc":[{"id":"1.232011680","rc":[{"batl":[[0,1.65,454.48],[1,1.69,4.7],[2,1.7,3.97]],"ltp":1.65,"tv":42951.04,"id":72857114}]}]}
{"op":"mcm","clk":"11917160949","pt":1724085082782,"mc":[{"id":"1.232011680","rc":[{"trd":[[1.65,5499.92]],"batl":[[0,1.69,4.7],[1,1.7,3.97],[2,1.75,1.03]],"ltp":1.65,"tv":43859.99,"id":72857114},{"batb":[[0,2.5,11.94],[1,2.28,48.11],[2,1.33,151.52]],"ltp":2.5,"tv":24.08,"id":72857116}],"tv":43884.07}]}
{"op":"mcm","clk":"11917160991","pt":1724085083092,"mc":[{"id":"1.232011680","rc":[{"batb":[[0,2.28,48.11],[1,1.33,151.52],[2,1.23,434.78]],"ltp":2.5,"tv":24.08,"id":72857116}]}]}
{"op":"mcm","clk":"11917162380","pt":1724085093646,"mc":[{"id":"1.232011680","rc":[{"batl":[[0,1.65,454.48],[1,1.69,4.7],[2,1.7,3.97]],"ltp":1.65,"tv":43859.99,"id":72857114}]}]}
{"op":"mcm","clk":"11917162553","pt":1724085095309,"mc":[{"id":"1.232011680","rc":[{"trd":[[1.65,6408.87]],"batl":[[0,1.69,4.7],[1,1.7,3.97],[2,1.75,1.03]],"ltp":1.65,"tv":44768.94,"id":72857114}],"tv":44793.02}]}
{"op":"mcm","clk":"11917163595","pt":1724085104516,"mc":[{"id":"1.232011680","rc":[{"batl":[[0,1.65,454.48],[1,1.69,4.7],[2,1.7,3.97]],"ltp":1.65,"tv":44768.94,"id":72857114}]}]}
{"op":"mcm","clk":"11917163823","pt":1724085106610,"mc":[{"id":"1.232011680","rc":[{"batb":[[0,2.5,11.94],[1,2.28,48.11],[2,1.33,151.52]],"ltp":2.5,"tv":24.08,"id":72857116}]}]}
{"op":"mcm","clk":"11917163938","pt":1724085107499,"mc":[{"id":"1.232011680","rc":[{"trd":[[1.65,7317.82]],"batl":[[0,1.69,4.7],[1,1.7,3.97],[2,1.75,1.03]],"ltp":1.65,"tv":45677.89,"id":72857114}],"tv":45701.98}]}
{"op":"mcm","clk":"11917164018","pt":1724085108207,"mc":[{"id":"1.232011680","rc":[{"batb":[[0,2.28,48.11],[1,1.33,151.52],[2,1.23,434.78]],"ltp":2.5,"tv":24.08,"id":72857116}]}]}
{"op":"mcm","clk":"11917164424","pt":1724085111520,"mc":[{"id":"1.232011680","rc":[{"batb":[[0,1.6,36.76],[1,1.58,3.58],[2,1.56,4.34]],"ltp":1.65,"tv":45677.89,"id":72857114}]}]}
{"op":"mcm","clk":"11917164713","pt":1724085113915,"mc":[{"id":"1.232011680","rc":[{"batb":[[1,1.59,30.35],[2,1.58,3.58]],"ltp":1.65,"tv":45677.89,"id":72857114}]}]}
{"op":"mcm","clk":"11917164826","pt":1724085114606,"mc":[{"id":"1.232011680","rc":[{"batb":[[0,1.61,4.2],[1,1.6,66.6],[2,1.59,30.35]],"ltp":1.65,"tv":45677.89,"id":72857114},{"batb":[[1,2.26,6.97],[2,1.33,151.52]],"ltp":2.5,"tv":24.08,"id":72857116}]}]}
{"op":"mcm","clk":"11917165281","pt":1724085118910,"mc":[{"id":"1.232011680","rc":[{"batl":[[0,1.65,454.48],[1,1.69,4.7],[2,1.7,3.97]],"ltp":1.65,"tv":45677.89,"id":72857114}]}]}
{"op":"mcm","clk":"11917165648","pt":1724085121584,"mc":[{"id":"1.232011680","rc":[{"batb":[[0,2.5,11.94],[1,2.28,48.11],[2,2.26,6.97]],"ltp":2.5,"tv":24.08,"id":72857116}]}]}
{"op":"mcm","clk":"11917166128","pt":1724085125583,"mc":[{"id":"1.232011680","rc":[{"trd":[[1.65,8226.78]],"batl":[[0,1.69,4.7],[1,1.7,3.97],[2,1.75,1.03]],"ltp":1.65,"tv":46586.84,"id":72857114},{"batb":[[0,2.28,48.11],[1,2.26,6.97],[2,1.33,151.52]],"ltp":2.5,"tv":24.08,"id":72857116}],"tv":46610.93}]}
{"op":"mcm","clk":"11917166220","pt":1724085126470,"mc":[{"id":"1.232011680","rc":[{"batb":[[0,1.65,17.91],[1,1.61,4.2],[2,1.6,66.6]],"ltp":1.65,"tv":46586.84,"id":72857114}]}]}
{"op":"mcm","clk":"11917166441","pt":1724085128179,"mc":[{"id":"1.232011680","rc":[{"batb":[[0,1.66,4.08],[1,1.65,17.91]],"ltp":1.65,"tv":46586.84,"id":72857114}]}]}
{"op":"mcm","clk":"11917166970","pt":1724085132494,"mc":[{"id":"1.232011680","rc":[{"batl":[[0,1.69,3.76]],"ltp":1.65,"tv":46586.84,"id":72857114}]}]}
{"op":"mcm","clk":"11917167215","pt":1724085134480,"mc":[{"id":"1.232011680","rc":[{"batb":[[1,1.6,66.6],[2,1.59,30.35]],"ltp":1.65,"tv":46586.84,"id":72857114}]}]}
{"op":"mcm","clk":"11917167380","pt":1724085135887,"mc":[{"id":"1.232011680","rc":[{"batb":[[0,1.6,66.6],[1,1.59,30.35],[2,1.58,3.58]],"ltp":1.65,"tv":46586.84,"id":72857114}]}]}
{"op":"mcm","clk":"11917167581","pt":1724085137487,"mc":[{"id":"1.232011680","rc":[{"batb":[[1,1.33,151.52],[2,1.23,434.78]],"ltp":2.5,"tv":24.08,"id":72857116}]}]}
{"op":"mcm","clk":"11917168152","pt":1724085141898,"mc":[{"id":"1.232011680","rc":[{"batb":[[0,1.6,65.66]],"ltp":1.65,"tv":46586.84,"id":72857114}]}]}
{"op":"mcm","clk":"11917168171","pt":1724085142108,"mc":[{"id":"1.232011680","rc":[{"batb":[[0,1.6,66.6]],"ltp":1.65,"tv":46586.84,"id":72857114}]}]}
{"op":"mcm","clk":"11917169265","pt":1724085151594,"mc":[{"id":"1.232011680","rc":[{"batl":[[0,1.65,454.48],[1,1.69,3.76],[2,1.7,3.97]],"ltp":1.65,"tv":46586.84,"id":72857114}]}]}
{"op":"mcm","clk":"11917169336","pt":1724085152225,"mc":[{"id":"1.232011680","rc":[{"batb":[[0,1.6,36.76]],"ltp":1.65,"tv":46586.84,"id":72857114}]}]}
{"op":"mcm","clk":"11917169492","pt":1724085153624,"mc":[{"id":"1.232011680","rc":[{"batb":[[0,2.5,11.94],[1,2.28,48.11],[2,1.33,151.52]],"ltp":2.5,"tv":24.08,"id":72857116}]}]}
{"op":"mcm","clk":"11917169899","pt":1724085156812,"mc":[{"id":"1.232011680","rc":[{"trd":[[1.64,932.36],[1.65,8254.6]],"batl":[[0,1.65,444.56]],"ltp":1.65,"tv":46622.66,"id":72857114},{"batb":[[0,2.52,11.78],[1,2.5,11.94],[2,2.28,48.11]],"ltp":2.5,"tv":24.08,"id":72857116}],"tv":46646.75}]}
{"op":"mcm","clk":"11917169999","pt":1724085157726,"mc":[{"id":"1.232011680","rc":[{"trd":[[1.65,9143.72]],"batb":[[0,1.65,9.91],[1,1.6,36.76],[2,1.59,30.35]],"batl":[[0,1.69,3.76],[1,1.7,3.97],[2,1.75,1.03]],"ltp":1.65,"tv":47511.79,"id":72857114}],"tv":47535.87}]}
{"op":"mcm","clk":"11917170094","pt":1724085158613,"mc":[{"id":"1.232011680","rc":[{"batb":[[1,1.6,66.6]],"ltp":1.65,"tv":47511.79,"id":72857114},{"batb":[[0,2.28,48.11],[1,1.33,151.52],[2,1.23,434.78]],"ltp":2.5,"tv":24.08,"id":72857116}]}]}
{"op":"mcm","clk":"11917171412","pt":1724085167812,"mc":[{"id":"1.232011680","rc":[{"batl":[[0,1.69,4.7]],"ltp":1.65,"tv":47511.79,"id":72857114}]}]}
{"op":"mcm","clk":"11917171889","pt":1724085171509,"mc":[{"id":"1.232011680","rc":[{"batb":[[0,1.66,4],[1,1.65,13.91],[2,1.6,66.6]],"ltp":1.65,"tv":47511.79,"id":72857114}]}]}
{"op":"mcm","clk":"11917172999","pt":1724085179813,"mc":[{"id":"1.232011680","rc":[{"batl":[[0,1.68,17.06],[1,1.69,3.76],[2,1.7,3.97]],"ltp":1.65,"tv":47511.79,"id":72857114}]}]}
{"op":"mcm","clk":"11917173222","pt":1724085181632,"mc":[{"id":"1.232011680","rc":[{"trd":[[1.65,9151.72],[1.66,1864.62]],"batb":[[0,1.6,36.76],[1,1.59,30.35],[2,1.58,3.58]],"batl":[[0,1.65,436.57],[1,1.68,17.06],[2,1.69,3.76]],"ltp":1.65,"tv":47527.78,"id":72857114},{"batb":[[0,2.42,12.61],[1,2.28,48.11],[2,1.33,151.52]],"ltp":2.5,"tv":24.08,"id":72857116}],"tv":47551.87}]}
{"op":"mcm","clk":"11917173367","pt":1724085182623,"mc":[{"id":"1.232011680","rc":[{"batb":[[0,1.61,5.15],[1,1.6,65.66],[2,1.59,30.35]],"ltp":1.65,"tv":47527.78,"id":72857114}]}]}
{"op":"mcm","clk":"11917173503","pt":1724085183625,"mc":[{"id":"1.232011680","rc":[{"batb":[[0,2.5,11.94],[1,2.42,12.61],[2,2.28,48.11]],"ltp":2.5,"tv":24.08,"id":72857116}]}]}
{"op":"mcm","clk":"11917173751","pt":1724085185552,"mc":[{"id":"1.232011680","rc":[{"trd":[[1.65,10024.85]],"batb":[[0,1.65,17.91],[1,1.61,5.15],[2,1.6,65.66]],"batl":[[0,1.68,17.06],[1,1.69,3.76],[2,1.7,3.97]],"ltp":1.65,"tv":48400.92,"id":72857114}],"tv":48425.0}]}
{"op":"mcm","clk":"11917173919","pt":1724085186848,"mc":[{"id":"1.232011680","rc":[{"batb":[[0,1.65,21.91]],"batl":[[0,1.68,21.06]],"ltp":1.65,"tv":48400.92,"id":72857114},{"batb":[[0,2.48,4],[1,2.46,4],[2,2.42,12.61]],"batl":[[0,2.54,4],[1,2.56,1.29]],"ltp":2.5,"tv":24.08,"id":72857116}]}]}
{"op":"mcm","clk":"11917174055","pt":1724085187827,"mc":[{"id":"1.232011680","rc":[{"batb":[[1,1.6,66.6],[2,1.59,30.35]],"ltp":1.65,"tv":48400.92,"id":72857114}]}]}
{"op":"mcm","clk":"11917174151","pt":1724085188649,"mc":[{"id":"1.232011680","rc":[{"batb":[[1,2.46,16.26]],"ltp":2.5,"tv":24.08,"id":72857116}]}]}
{"op":"mcm","clk":"11917174669","pt":1724085192851,"mc":[{"id":"1.232011680","rc":[{"batb":[[0,1.66,4.08],[1,1.65,21.91],[2,1.6,66.6]],"ltp":1.65,"tv":48400.92,"id":72857114}]}]}
{"op":"mcm","clk":"11917174898","pt":1724085194776,"mc":[{"id":"1.232011680","rc":[{"batb":[[1,1.65,4],[2,1.64,27.98]],"ltp":1.65,"tv":48400.92,"id":72857114},{"trd":[[2.48,4.04]],"batb":[[0,2.48,3.98]],"ltp":2.48,"tv":24.11,"id":72857116}],"tv":48425.03}]}
{"op":"mcm","clk":"11917175014","pt":1724085195760,"mc":[{"id":"1.232011680","rc":[{"trd":[[1.67,199.4],[1.68,3700.07]],"batb":[[1,1.6,66.6],[2,1.59,30.35]],"batl":[[0,1.68,3.47]],"ltp":1.68,"tv":48436.09,"id":72857114},{"batb":[[1,2.46,4]],"ltp":2.48,"tv":24.11,"id":72857116}],"tv":48460.21}]}
{"op":"mcm","clk":"11917175152","pt":1724085196749,"mc":[{"id":"1.232011680","rc":[{"batb":[[0,1.6,66.6],[1,1.59,30.35],[2,1.58,3.58]],"batl":[[0,1.69,3.76],[1,1.7,3.97],[2,1.75,1.03]],"ltp":1.68,"tv":48436.09,"id":72857114},{"batb":[[0,2.28,48.11],[1,1.33,151.52],[2,1.23,434.78]],"ltp":2.48,"tv":24.11,"id":72857116}]}]}
{"op":"mcm","clk":"11917177901","pt":1724085215465,"mc":[{"id":"1.232011680","rc":[{"batl":[[0,1.69,4.7]],"ltp":1.68,"tv":48436.09,"id":72857114}]}]}
{"op":"mcm","clk":"11917179475","pt":1724085226763,"mc":[{"id":"1.232011680","rc":[{"batb":[[0,1.6,36.76]],"batl":[[0,1.65,454.48],[1,1.69,4.7],[2,1.7,3.97]],"ltp":1.68,"tv":48436.09,"id":72857114}]}]}
{"op":"mcm","clk":"11917179756","pt":1724085228697,"mc":[{"id":"1.232011680","rc":[{"batb":[[0,2.5,11.94],[1,2.28,48.11],[2,1.33,151.52]],"ltp":2.48,"tv":24.11,"id":72857116}]}]}
{"op":"mcm","clk":"11917180267","pt":1724085232785,"mc":[{"id":"1.232011680","rc":[{"trd":[[1.64,940.35],[1.65,10925.81]],"batl":[[0,1.65,8]],"ltp":1.65,"tv":49345.04,"id":72857114},{"batb":[[0,2.52,11.78],[1,2.5,11.94],[2,2.28,48.11]],"ltp":2.48,"tv":24.11,"id":72857116}],"tv":49369.16}]}
{"op":"mcm","clk":"11917180379","pt":1724085233674,"mc":[{"id":"1.232011680","rc":[{"batb":[[0,2.28,48.11],[1,1.33,151.52],[2,1.23,434.78]],"ltp":2.48,"tv":24.11,"id":72857116}]}]}
{"op":"mcm","clk":"11917180458","pt":1724085234187,"mc":[{"id":"1.232011680","rc":[{"batl":[[0,1.65,4]],"ltp":1.65,"tv":49345.04,"id":72857114}]}]}
{"op":"mcm","clk":"11917181499","pt":1724085241901,"mc":[{"id":"1.232011680","rc":[{"trd":[[1.65,10933.8]],"batb":[[0,1.65,13.91],[1,1.6,36.76],[2,1.59,30.35]],"batl":[[0,1.69,4.7],[1,1.7,3.97],[2,1.75,1.03]],"ltp":1.65,"tv":49353.04,"id":72857114}],"tv":49377.16}]}
{"op":"mcm","clk":"11917181632","pt":1724085242697,"mc":[{"id":"1.232011680","rc":[{"batb":[[1,1.6,66.6]],"ltp":1.65,"tv":49353.04,"id":72857114}]}]}
{"op":"mcm","clk":"11917182212","pt":1724085246900,"mc":[{"id":"1.232011680","rc":[{"batb":[[0,1.6,66.6],[1,1.59,30.35],[2,1.58,3.58]],"ltp":1.65,"tv":49353.04,"id":72857114}]}]}
{"op":"mcm","clk":"11917182340","pt":1724085247784,"mc":[{"id":"1.232011680","rc":[{"batb":[[0,2.3,10],[1,2.28,48.11],[2,1.33,151.52]],"ltp":2.48,"tv":24.11,"id":72857116}]}]}
{"op":"mcm","clk":"11917182613","pt":1724085249701,"mc":[{"id":"1.232011680","rc":[{"batb":[[0,1.61,5.15],[1,1.6,65.66],[2,1.59,30.35]],"ltp":1.65,"tv":49353.04,"id":72857114},{"batb":[[0,2.3,23.77]],"ltp":2.48,"tv":24.11,"id":72857116}]}]}
{"op":"mcm","clk":"11917182742","pt":1724085250594,"mc":[{"id":"1.232011680","rc":[{"batb":[[0,2.3,13.77]],"ltp":2.48,"tv":24.11,"id":72857116}]}]}
{"op":"mcm","clk":"11917182824","pt":1724085251315,"mc":[{"id":"1.232011680","rc":[{"batb":[[0,2.28,48.11],[1,1.33,151.52],[2,1.23,434.78]],"ltp":2.48,"tv":24.11,"id":72857116}]}]}
{"op":"mcm","clk":"11917183111","pt":1724085253496,"mc":[{"id":"1.232011680","rc":[{"batl":[[0,1.65,454.48],[1,1.69,4.7],[2,1.7,3.97]],"ltp":1.65,"tv":49353.04,"id":72857114}]}]}
{"op":"mcm","clk":"11917183320","pt":1724085255206,"mc":[{"id":"1.232011680","rc":[{"trd":[[1.65,11842.75]],"batl":[[0,1.69,4.7],[1,1.7,3.97],[2,1.75,1.03]],"ltp":1.65,"tv":50261.99,"id":72857114}],"tv":50286.11}]}
{"op":"mcm","clk":"11917185033","pt":1724085267533,"mc":[{"id":"1.232011680","rc":[{"batl":[[0,1.68,9.9],[1,1.69,3.76],[2,1.7,3.97]],"ltp":1.65,"tv":50261.99,"id":72857114}]}]}
{"op":"mcm","clk":"11917186384","pt":1724085277930,"mc":[{"id":"1.232011680","rc":[{"trd":[[1.67,199.43]],"batl":[[0,1.68,9.87]],"ltp":1.67,"tv":50262.01,"id":72857114},{"trd":[[2.48,4.05]],"ltp":2.48,"tv":24.13,"id":72857116}],"tv":50286.15}]}
{"op":"mcm","clk":"11917187016","pt":1724085281912,"mc":[{"id":"1.232011680","rc":[{"batl":[[2,1.75,1.03]],"ltp":1.67,"tv":50262.01,"id":72857114}]}]}
{"op":"mcm","clk":"11917187640","pt":1724085286602,"mc":[{"id":"1.232011680","rc":[{"batl":[[0,1.67,4.68],[1,1.68,8.95]],"ltp":1.67,"tv":50262.01,"id":72857114}]}]}
{"op":"mcm","clk":"11917188201","pt":1724085290433,"mc":[{"id":"1.232011680","rc":[{"batl":[[0,1.65,454.48],[1,1.67,4.68],[2,1.68,8.95]],"ltp":1.67,"tv":50262.01,"id":72857114}]}]}
{"op":"mcm","clk":"11917188567","pt":1724085292909,"mc":[{"id":"1.232011680","rc":[{"trd":[[1.64,948.35],[1.65,12743.71]],"batl":[[0,1.65,8]],"ltp":1.65,"tv":51170.97,"id":72857114},{"batb":[[0,2.54,4],[1,2.52,4],[2,2.5,11.94]],"ltp":2.48,"tv":24.13,"id":72857116}],"tv":51195.1}]}
{"op":"mcm","clk":"11917188679","pt":1724085293630,"mc":[{"id":"1.232011680","rc":[{"trd":[[1.65,12765.86]],"batb":[[0,1.65,3.75],[1,1.61,5.15],[2,1.6,65.66]],"batl":[[0,1.67,4.68],[1,1.68,8.95],[2,1.75,1.03]],"ltp":1.65,"tv":51193.12,"id":72857114},{"trd":[[2.54,4]],"batb":[[0,2.28,48.11],[1,1.33,151.52],[2,1.23,434.78]],"ltp":2.54,"tv":28.13,"id":72857116}],"tv":51221.26}]}
{"op":"mcm","clk":"11917189528","pt":1724085299915,"mc":[{"id":"1.232011680","rc":[{"trd":[[1.65,12773.03]],"batb":[[0,1.62,1.11],[1,1.61,4.2]],"ltp":1.65,"tv":51200.28,"id":72857114}],"tv":51228.42}]}
{"op":"mcm","clk":"11917190903","pt":1724085308537,"mc":[{"id":"1.232011680","rc":[{"batb":[[0,1.62,4.7]],"ltp":1.65,"tv":51200.28,"id":72857114}]}]}
{"op":"mcm","clk":"11917191316","pt":1724085311622,"mc":[{"id":"1.232011680","rc":[{"trd":[[1.65,12773.37]],"batb":[[0,1.62,4.52]],"batl":[[0,1.65,454.31],[1,1.67,4.68],[2,1.68,8.95]],"ltp":1.65,"tv":51200.62,"id":72857114}],"tv":51228.76}]}
{"op":"mcm","clk":"11917191608","pt":1724085313745,"mc":[{"id":"1.232011680","rc":[{"batb":[[0,2.5,11.94],[1,2.28,48.11],[2,1.33,151.52]],"ltp":2.54,"tv":28.13,"id":72857116}]}]}
{"op":"mcm","clk":"11917191816","pt":1724085315252,"mc":[{"id":"1.232011680","rc":[{"trd":[[1.65,13681.98]],"batb":[[0,1.62,4.69]],"batl":[[0,1.67,4.68],[1,1.68,8.95],[2,1.75,1.03]],"ltp":1.65,"tv":52109.24,"id":72857114},{"batb":[[0,2.28,48.11],[1,1.33,151.52],[2,1.23,434.78]],"ltp":2.54,"tv":28.13,"id":72857116}],"tv":52137.37}]}
{"op":"mcm","clk":"11917192531","pt":1724085320561,"mc":[{"id":"1.232011680","rc":[{"trd":[[1.67,199.76]],"batb":[[0,1.62,4.52]],"batl":[[0,1.67,4.51]],"ltp":1.67,"tv":52109.58,"id":72857114}],"tv":52137.71}]}
{"op":"mcm","clk":"11917192780","pt":1724085322336,"mc":[{"id":"1.232011680","rc":[{"trd":[[1.67,199.81]],"batl":[[0,1.67,4.49]],"ltp":1.67,"tv":52109.62,"id":72857114}],"tv":52137.76}]}
{"op":"mcm","clk":"11917193765","pt":1724085329825,"mc":[{"id":"1.232011680","rc":[{"batl":[[1,1.75,1.03],[2,1.8,358.53]],"ltp":1.67,"tv":52109.62,"id":72857114}]}]}
{"op":"mcm","clk":"11917199072","pt":1724085367480,"mc":[{"id":"1.232011680","rc":[{"batl":[[1,1.72,22.39],[2,1.75,1.03]],"ltp":1.67,"tv":52109.62,"id":72857114}]}]}
{"op":"mcm","clk":"11917199364","pt":1724085369715,"mc":[{"id":"1.232011680","rc":[{"batb":[[0,2.38,12.98],[1,2.28,48.11],[2,1.33,151.52]],"ltp":2.54,"tv":28.13,"id":72857116}]}]}
{"op":"mcm","clk":"11917199552","pt":1724085370916,"mc":[{"id":"1.232011680","rc":[{"batb":[[0,2.4,10],[1,2.38,12.98],[2,2.28,48.11]],"batl":[[0,2.52,300.42]],"ltp":2.54,"tv":28.13,"id":72857116}]}]}
{"op":"mcm","clk":"11917199583","pt":1724085371081,"mc":[{"id":"1.232011680","rc":[{"batl":[[1,2.54,1.36]],"ltp":2.54,"tv":28.13,"id":72857116}]}]}
{"op":"mcm","clk":"11917199798","pt":1724085372701,"mc":[{"id":"1.232011680","rc":[{"batb":[[0,1.66,4.08],[1,1.65,27.55],[2,1.62,4.52]],"ltp":1.67,"tv":52109.62,"id":72857114}]}]}
{"op":"mcm","clk":"11917199977","pt":1724085374098,"mc":[{"id":"1.232011680","rc":[{"batb":[[0,2.38,12.98],[1,2.28,48.11],[2,1.33,151.52]],"ltp":2.54,"tv":28.13,"id":72857116}]}]}
{"op":"mcm","clk":"11917200272","pt":1724085376290,"mc":[{"id":"1.232011680","rc":[{"batb":[[1,1.62,4.52],[2,1.6,65.66]],"ltp":1.67,"tv":52109.62,"id":72857114},{"trd":[[2.52,600.83]],"ltp":2.52,"tv":628.96,"id":72857116}],"tv":52738.59}]}
{"op":"mcm","clk":"11917200518","pt":1724085378212,"mc":[{"id":"1.232011680","rc":[{"batb":[[0,1.62,4.52],[1,1.61,4.2]],"ltp":1.67,"tv":52109.62,"id":72857114}]}]}
{"op":"mcm","clk":"11917208042","pt":1724085430267,"mc":[{"id":"1.232011680","rc":[{"batb":[[2,2.22,7.06]],"ltp":2.52,"tv":628.96,"id":72857116}]}]}
{"op":"mcm","clk":"11917209322","pt":1724085438861,"mc":[{"id":"1.232011680","rc":[{"batb":[[0,2.4,10],[1,2.38,12.98],[2,2.28,48.11]],"batl":[[0,2.52,300.42],[1,2.54,1.36]],"ltp":2.52,"tv":628.96,"id":72857116}]}]}
{"op":"mcm","clk":"11917209606","pt":1724085440901,"mc":[{"id":"1.232011680","rc":[{"batb":[[0,1.66,4.08],[1,1.64,27.98],[2,1.62,4.52]],"ltp":1.67,"tv":52109.62,"id":72857114}]}]}
{"op":"mcm","clk":"11917209719","pt":1724085441772,"mc":[{"id":"1.232011680","rc":[{"batb":[[1,1.65,27.55],[2,1.64,27.98]],"ltp":1.67,"tv":52109.62,"id":72857114}]}]}
{"op":"mcm","clk":"11917209752","pt":1724085442091,"mc":[{"id":"1.232011680","rc":[{"batb":[[0,2.38,12.98],[1,2.28,48.11],[2,2.22,7.06]],"ltp":2.52,"tv":628.96,"id":72857116}]}]}
{"op":"mcm","clk":"11917209947","pt":1724085443664,"mc":[{"id":"1.232011680","rc":[{"batl":[[0,2.5,4],[1,2.52,304.42],[2,2.54,1.36]],"ltp":2.52,"tv":628.96,"id":72857116}]}]}
{"op":"mcm","clk":"11917210222","pt":1724085445808,"mc":[{"id":"1.232011680","rc":[{"batb":[[1,1.62,4.52],[2,1.6,65.66]],"ltp":1.67,"tv":52109.62,"id":72857114},{"trd":[[2.5,12],[2.52,1193.67]],"batb":[[0,2.4,10],[1,2.38,12.98],[2,2.28,48.11]],"batl":[[0,2.52,8],[1,2.54,1.36],[2,2.54,0]],"ltp":2.52,"tv":1229.8,"id":72857116}],"tv":53339.42}]}
{"op":"mcm","clk":"11917210267","pt":1724085446175,"mc":[{"id":"1.232011680","rc":[{"batl":[[0,2.52,4]],"ltp":2.52,"tv":1229.8,"id":72857116}]}]}
{"op":"mcm","clk":"11917210522","pt":1724085447317,"mc":[{"id":"1.232011680","rc":[{"batb":[[0,1.62,4.52],[1,1.6,65.66],[2,1.59,30.35]],"ltp":1.67,"tv":52109.62,"id":72857114}]}]}
{"op":"mcm","clk":"11917210779","pt":1724085448841,"mc":[{"id":"1.232011680","rc":[{"batb":[[0,2.38,12.98],[1,2.28,48.11],[2,1.33,151.52]],"ltp":2.52,"tv":1229.8,"id":72857116}]}]}
{"op":"mcm","clk":"11917210969","pt":1724085449856,"mc":[{"id":"1.232011680","rc":[{"batl":[[0,1.66,3.58],[1,1.67,4.49],[2,1.72,22.39]],"ltp":1.67,"tv":52109.62,"id":72857114}]}]}
{"op":"mcm","clk":"11917211636","pt":1724085453741,"mc":[{"id":"1.232011680","rc":[{"batb":[[1,1.61,4.2],[2,1.6,65.66]],"ltp":1.67,"tv":52109.62,"id":72857114}]}]}
{"op":"mcm","clk":"11917211760","pt":1724085454580,"mc":[{"id":"1.232011680","rc":[{"batl":[[0,1.67,4.49],[1,1.72,22.39],[2,1.75,1.03]],"ltp":1.67,"tv":52109.62,"id":72857114},{"batb":[[0,2.4,10],[1,2.38,12.98],[2,2.28,48.11]],"ltp":2.52,"tv":1229.8,"id":72857116}]}]}
{"op":"mcm","clk":"11917212180","pt":1724085457250,"mc":[{"id":"1.232011680","rc":[{"batb":[[0,2.38,12.98],[1,2.28,48.11],[2,1.33,151.52]],"ltp":2.52,"tv":1229.8,"id":72857116}]}]}
{"op":"mcm","clk":"11917212819","pt":1724085461176,"mc":[{"id":"1.232011680","rc":[{"batb":[[0,2.4,10],[1,2.38,12.98],[2,2.28,48.11]],"ltp":2.52,"tv":1229.8,"id":72857116}]}]}
{"op":"mcm","clk":"11917213037","pt":1724085462165,"mc":[{"id":"1.232011680","rc":[{"trd":[[2.52,1193.71]],"batl":[[0,2.52,3.97]],"ltp":2.52,"tv":1229.84,"id":72857116}],"tv":53339.47}]}
{"op":"mcm","clk":"11917213562","pt":1724085464612,"mc":[{"id":"1.232011680","rc":[{"batb":[[0,2.38,12.98],[1,2.28,48.11],[2,1.33,151.52]],"ltp":2.52,"tv":1229.84,"id":72857116}]}]}
{"op":"mcm","clk":"11917214023","pt":1724085467935,"mc":[{"id":"1.232011680","rc":[{"batb":[[0,1.61,5.15],[1,1.6,65.66],[2,1.59,30.35]],"batl":[[0,1.72,23.11],[1,1.75,1.03],[2,1.8,358.53]],"ltp":1.67,"tv":52109.62,"id":72857114}]}]}
{"op":"mcm","clk":"11917214056","pt":1724085468151,"mc":[{"id":"1.232011680","rc":[{"trd":[[2.52,1199.63]],"batb":[[0,2.4,10],[1,2.38,12.98],[2,2.28,48.11]],"batl":[[0,2.52,1.02]],"ltp":2.52,"tv":1235.76,"id":72857116}],"tv":53345.39}]}
{"op":"mcm","clk":"11917214494","pt":1724085471347,"mc":[{"id":"1.232011680","rc":[{"batb":[[0,2.38,12.98],[1,2.28,48.11],[2,1.33,151.52]],"ltp":2.52,"tv":1235.76,"id":72857116}]}]}
{"op":"mcm","clk":"11917215945","pt":1724085480856,"mc":[{"id":"1.232011680","rc":[{"batb":[[0,1.61,12.31]],"ltp":1.67,"tv":52109.62,"id":72857114}]}]}
{"op":"mcm","clk":"11917215964","pt":1724085480967,"mc":[{"id":"1.232011680","rc":[{"batb":[[0,2.4,10],[1,2.38,12.98],[2,2.28,48.11]],"ltp":2.52,"tv":1235.76,"id":72857116}]}]}
{"op":"mcm","clk":"11917216516","pt":1724085484193,"mc":[{"id":"1.232011680","rc":[{"batb":[[0,2.38,12.98],[1,2.28,48.11],[2,1.33,151.52]],"ltp":2.52,"tv":1235.76,"id":72857116}]}]}
{"op":"mcm","clk":"11917217027","pt":1724085487583,"mc":[{"id":"1.232011680","rc":[{"batb":[[0,2.4,10],[1,2.38,12.98],[2,2.28,48.11]],"ltp":2.52,"tv":1235.76,"id":72857116}]}]}
{"op":"mcm","clk":"11917217239","pt":1724085489033,"mc":[{"id":"1.232011680","rc":[{"batb":[[0,2.42,4],[1,2.4,14],[2,2.38,12.98]],"ltp":2.52,"tv":1235.76,"id":72857116}]}]}
{"op":"mcm","clk":"11917217530","pt":1724085490804,"mc":[{"id":"1.232011680","rc":[{"batb":[[1,2.4,26.79]],"ltp":2.52,"tv":1235.76,"id":72857116}]}]}
{"op":"mcm","clk":"11917217600","pt":1724085491321,"mc":[{"id":"1.232011680","rc":[{"batb":[[1,2.4,4]],"ltp":2.52,"tv":1235.76,"id":72857116}]}]}
{"op":"mcm","clk":"11917217677","pt":1724085492009,"mc":[{"id":"1.232011680","rc":[{"batb":[[0,2.4,4],[1,2.38,12.98],[2,2.28,48.11]],"ltp":2.52,"tv":1235.76,"id":72857116}]}]}
{"op":"mcm","clk":"11917217819","pt":1724085493221,"mc":[{"id":"1.232011680","rc":[{"trd":[[1.67,200.54]],"batl":[[0,1.72,22.39]],"ltp":1.67,"tv":52110.35,"id":72857114},{"trd":[[2.48,4.54]],"batl":[[0,2.46,307.63],[1,2.52,1.02],[2,2.54,1.36]],"ltp":2.48,"tv":1236.25,"id":72857116}],"tv":53346.61}]}
{"op":"mcm","clk":"11917218139","pt":1724085495807,"mc":[{"id":"1.232011680","rc":[{"batb":[[0,1.69,4.01],[1,1.67,26.72],[2,1.61,8.11]],"ltp":1.67,"tv":52110.35,"id":72857114}]}]}
{"op":"mcm","clk":"11917218283","pt":1724085496802,"mc":[{"id":"1.232011680","rc":[{"batb":[[1,1.68,26.33],[2,1.67,26.72]],"ltp":1.67,"tv":52110.35,"id":72857114},{"batb":[[0,2.38,12.98],[1,2.28,48.11],[2,1.33,151.52]],"ltp":2.48,"tv":1236.25,"id":72857116}]}]}
{"op":"mcm","clk":"11917218425","pt":1724085497843,"mc":[{"id":"1.232011680","rc":[{"trd":[[1.69,11.5]],"batb":[[0,1.69,3.29],[1,1.61,8.11],[2,1.6,65.66]],"ltp":1.69,"tv":52111.07,"id":72857114},{"trd":[[2.46,615.74]],"batb":[[0,2.4,10],[1,2.38,12.98],[2,2.28,48.11]],"batl":[[0,2.52,1.02],[1,2.54,1.36],[2,2.54,0]],"ltp":2.46,"tv":1852.0,"id":72857116}],"tv":53963.07}]}
{"op":"mcm","clk":"11917218834","pt":1724085500729,"mc":[{"id":"1.232011680","rc":[{"batb":[[0,1.61,8.11],[1,1.6,65.66],[2,1.59,30.35]],"ltp":1.69,"tv":52111.07,"id":72857114},{"batb":[[0,2.38,12.98],[1,2.28,48.11],[2,1.33,151.52]],"ltp":2.46,"tv":1852.0,"id":72857116}]}]}
{"op":"mcm","clk":"11917219204","pt":1724085503443,"mc":[{"id":"1.232011680","rc":[{"batb":[[0,2.4,10],[1,2.38,12.98],[2,2.28,48.11]],"ltp":2.46,"tv":1852.0,"id":72857116}]}]}
{"op":"mcm","clk":"11917219319","pt":1724085504231,"mc":[{"id":"1.232011680","rc":[{"batb":[[0,2.42,4],[1,2.4,14],[2,2.38,12.98]],"ltp":2.46,"tv":1852.0,"id":72857116}]}]}
{"op":"mcm","clk":"11917219713","pt":1724085506903,"mc":[{"id":"1.232011680","rc":[{"batl":[[0,1.72,23.33]],"ltp":1.69,"tv":52111.07,"id":72857114},{"batb":[[1,2.4,16.79]],"batl":[[0,2.46,308.12],[1,2.52,1.02],[2,2.54,1.36]],"ltp":2.46,"tv":1852.0,"id":72857116}]}]}
{"op":"mcm","clk":"11917219880","pt":1724085507840,"mc":[{"id":"1.232011680","rc":[{"batb":[[0,2.36,13.17],[1,2.28,48.11],[2,1.33,151.52]],"ltp":2.46,"tv":1852.0,"id":72857116}]}]}
{"op":"mcm","clk":"11917220077","pt":1724085508938,"mc":[{"id":"1.232011680","rc":[{"batb":[[0,1.67,26.72],[1,1.61,8.11],[2,1.6,65.66]],"ltp":1.69,"tv":52111.07,"id":72857114},{"batb":[[0,2.38,10],[1,2.36,13.17],[2,2.28,48.11]],"ltp":2.46,"tv":1852.0,"id":72857116}]}]}
{"op":"mcm","clk":"11917220225","pt":1724085509823,"mc":[{"id":"1.232011680","rc":[{"batb":[[0,1.61,8.11],[1,1.6,65.66],[2,1.59,30.35]],"ltp":1.69,"tv":52111.07,"id":72857114},{"trd":[[2.46,1231.98]],"batl":[[0,2.52,1.02],[1,2.54,1.36],[2,2.54,0]],"ltp":2.46,"tv":2468.24,"id":72857116}],"tv":54579.31}]}
{"op":"mcm","clk":"11917220594","pt":1724085512125,"mc":[{"id":"1.232011680","rc":[{"batb":[[0,2.36,13.17],[1,2.28,48.11],[2,1.33,151.52]],"ltp":2.46,"tv":2468.24,"id":72857116}]}]}
{"op":"mcm","clk":"11917221359","pt":1724085517626,"mc":[{"id":"1.232011680","rc":[{"trd":[[1.69,13.38],[1.72,10.37]],"batb":[[0,1.61,11.56]],"batl":[[0,1.72,21.82]],"ltp":1.72,"tv":52114.07,"id":72857114},{"batb":[[0,2.38,10],[1,2.36,13.17],[2,2.28,48.11]],"ltp":2.46,"tv":2468.24,"id":72857116}],"tv":54582.31}]}
{"op":"mcm","clk":"11917221756","pt":1724085520655,"mc":[{"id":"1.232011680","rc":[{"batb":[[0,2.36,13.17],[1,2.28,48.11],[2,1.33,151.52]],"ltp":2.46,"tv":2468.24,"id":72857116}]}]}
{"op":"mcm","clk":"11917222073","pt":1724085522837,"mc":[{"id":"1.232011680","rc":[{"batl":[[0,1.69,2],[1,1.72,21.82],[2,1.75,1.03]],"ltp":1.72,"tv":52114.07,"id":72857114},{"batb":[[0,2.38,12.98],[1,2.36,13.17],[2,2.28,48.11]],"ltp":2.46,"tv":2468.24,"id":72857116}]}]}
{"op":"mcm","clk":"11917223074","pt":1724085530456,"mc":[{"id":"1.232011680","rc":[{"batl":[[0,2.46,308.12],[1,2.48,1.36]],"ltp":2.46,"tv":2468.24,"id":72857116}]}]}
{"op":"mcm","clk":"11917223402","pt":1724085532863,"mc":[{"id":"1.232011680","rc":[{"trd":[[1.68,3717.97]],"batb":[[0,1.67,26.72],[1,1.63,1.88],[2,1.61,7.16]],"ltp":1.68,"tv":52131.98,"id":72857114},{"trd":[[2.46,1244.22]],"batl":[[0,2.46,295.89]],"ltp":2.46,"tv":2480.47,"id":72857116}],"tv":54612.45}]}
{"op":"mcm","clk":"11917223607","pt":1724085534381,"mc":[{"id":"1.232011680","rc":[{"batb":[[0,1.68,4],[1,1.67,26.72],[2,1.63,1.88]],"ltp":1.68,"tv":52131.98,"id":72857114},{"batl":[[0,2.46,299.89]],"ltp":2.46,"tv":2480.47,"id":72857116}]}]}
{"op":"mcm","clk":"11917224413","pt":1724085540760,"mc":[{"id":"1.232011680","rc":[{"trd":[[1.68,3719.97]],"batb":[[0,1.68,3]],"ltp":1.68,"tv":52133.98,"id":72857114}],"tv":54614.45}]}
{"op":"mcm","clk":"11917224544","pt":1724085541854,"mc":[{"id":"1.232011680","rc":[{"batl":[[1,1.75,1.03],[2,1.8,358.53]],"ltp":1.68,"tv":52133.98,"id":72857114},{"trd":[[2.46,1250.28]],"batb":[[0,2.28,48.11],[1,2.24,7.03],[2,1.33,151.52]],"batl":[[0,2.46,296.85]],"ltp":2.46,"tv":2486.54,"id":72857116}],"tv":54620.52}]}
{"op":"mcm","clk":"11917224556","pt":1724085541958,"mc":[{"id":"1.232011680","rc":[{"batb":[[0,2.3,10],[1,2.28,48.11],[2,2.24,7.03]],"ltp":2.46,"tv":2486.54,"id":72857116}]}]}
{"op":"mcm","clk":"11917224792","pt":1724085543846,"mc":[{"id":"1.232011680","rc":[{"batl":[[1,1.8,358.53],[2,2.2,5.17]],"ltp":1.68,"tv":52133.98,"id":72857114}]}]}
{"op":"mcm","clk":"11917224954","pt":1724085545250,"mc":[{"id":"1.232011680","rc":[{"batb":[[0,2.28,48.11],[1,2.18,7.22],[2,1.33,151.52]],"ltp":2.46,"tv":2486.54,"id":72857116}]}]}
{"op":"mcm","clk":"11917225132","pt":1724085546758,"mc":[{"id":"1.232011680","rc":[{"batl":[[0,1.8,358.53],[1,2.2,5.17],[2,2.2,0]],"ltp":1.68,"tv":52133.98,"id":72857114},{"trd":[[2.46,1254.3]],"batl":[[0,2.46,294.84]],"ltp":2.46,"tv":2490.56,"id":72857116}],"tv":54624.54}]}
{"op":"mcm","clk":"11917225281","pt":1724085547906,"mc":[{"id":"1.232011680","rc":[{"batb":[[0,1.63,1.88],[1,1.61,7.16],[2,1.6,9.83]],"ltp":1.68,"tv":52133.98,"id":72857114},{"trd":[[2.46,1843.98]],"batb":[[0,2.46,13.28],[1,2.28,48.11],[2,2.18,7.22]],"ltp":2.46,"tv":3080.24,"id":72857116}],"tv":55214.22}]}
{"op":"mcm","clk":"11917225503","pt":1724085549582,"mc":[{"id":"1.232011680","rc":[{"batl":[[0,1.69,4],[1,1.8,358.53],[2,2.2,5.17]],"ltp":1.68,"tv":52133.98,"id":72857114}]}]}
{"op":"mcm","clk":"11917225806","pt":1724085551882,"mc":[{"id":"1.232011680","rc":[{"batb":[[1,2.44,12.43],[2,2.28,48.11]],"ltp":2.46,"tv":3080.24,"id":72857116}]}]}
{"op":"mcm","clk":"11917226052","pt":1724085553907,"mc":[{"id":"1.232011680","rc":[{"batb":[[0,1.61,8.11],[1,1.6,9.83],[2,1.33,205.78]],"ltp":1.68,"tv":52133.98,"id":72857114}]}]}
{"op":"mcm","clk":"11917226078","pt":1724085554069,"mc":[{"id":"1.232011680","rc":[{"batb":[[0,1.63,1.88],[1,1.61,7.16],[2,1.6,9.83]],"ltp":1.68,"tv":52133.98,"id":72857114}]}]}
{"op":"mcm","clk":"11917227049","pt":1724085561887,"mc":[{"id":"1.232011680","rc":[{"batl":[[0,1.8,358.53],[1,2.2,5.17],[2,2.2,0]],"ltp":1.68,"tv":52133.98,"id":72857114},{"batb":[[1,2.28,48.11],[2,2.18,7.22]],"batl":[[0,2.48,308.12],[1,2.5,1.36]],"ltp":2.46,"tv":3080.24,"id":72857116}]}]}
{"op":"mcm","clk":"11917227307","pt":1724085563814,"mc":[{"id":"1.232011680","rc":[{"batb":[[0,1.68,3.31],[1,1.67,26.72],[2,1.63,1.88]],"ltp":1.68,"tv":52133.98,"id":72857114}]}]}
{"op":"mcm","clk":"11917227432","pt":1724085564802,"mc":[{"id":"1.232011680","rc":[{"batb":[[1,1.63,1.88],[2,1.61,7.16]],"batl":[[0,1.69,4],[1,1.8,358.53],[2,2.2,5.17]],"ltp":1.68,"tv":52133.98,"id":72857114},{"trd":[[2.48,620.78]],"batl":[[0,2.48,4],[1,2.5,1.43]],"ltp":2.48,"tv":3696.48,"id":72857116}],"tv":55830.46}]}
{"op":"mcm","clk":"11917227563","pt":1724085565790,"mc":[{"id":"1.232011680","rc":[{"batb":[[0,1.63,1.88],[1,1.61,7.16],[2,1.33,205.78]],"ltp":1.68,"tv":52133.98,"id":72857114},{"batb":[[2,1.33,151.52]],"ltp":2.48,"tv":3696.48,"id":72857116}]}]}
{"op":"mcm","clk":"11917227685","pt":1724085566787,"mc":[{"id":"1.232011680","rc":[{"batb":[[0,1.66,1.88]],"ltp":1.68,"tv":52133.98,"id":72857114},{"batb":[[1,2.44,12.43],[2,2.28,48.11]],"ltp":2.48,"tv":3696.48,"id":72857116}]}]}
{"op":"mcm","clk":"11917227887","pt":1724085568599,"mc":[{"id":"1.232011680","rc":[{"batl":[[0,2.5,5.06],[1,2.52,1.36]],"ltp":2.48,"tv":3696.48,"id":72857116}]}]}
{"op":"mcm","clk":"11917228145","pt":1724085570686,"mc":[{"id":"1.232011680","rc":[{"trd":[[1.33,6.06],[1.61,7.16],[1.66,1866.5]],"batb":[[0,1.33,199.72],[1,1.23,434.78],[2,1.19,526.32]],"batl":[[0,1.8,358.53],[1,2.2,5.17],[2,2.2,0]],"ltp":1.33,"tv":52149.09,"id":72857114},{"trd":[[2.46,1848.96],[2.5,22.13],[2.52,1203.6],[2.64,4.37],[4.1,1.96]],"batb":[[0,2.28,48.11],[1,1.33,151.52],[2,1.23,434.78]],"ltp":4.1,"tv":3721.89,"id":72857116}],"tv":55870.98}]}
{"op":"mcm","clk":"11917228831","pt":1724085576566,"mc":[{"id":"1.232011680","rc":[{"batb":[[0,1.34,4.14],[1,1.33,199.72],[2,1.23,434.78]],"ltp":1.33,"tv":52149.09,"id":72857114},{"trd":[[2.28,17.43]],"batb":[[0,2.28,45.44]],"ltp":2.28,"tv":3727.23,"id":72857116}],"tv":55876.32}]}
{"op":"mcm","clk":"11917229247","pt":1724085579761,"mc":[{"id":"1.232011680","rc":[{"batb":[[0,2.28,48.11]],"ltp":2.28,"tv":3727.23,"id":72857116}]}]}
{"op":"mcm","clk":"11917229345","pt":1724085580586,"mc":[{"id":"1.232011680","rc":[{"batb":[[0,1.39,3.58],[1,1.34,4.14],[2,1.33,199.72]],"ltp":1.33,"tv":52149.09,"id":72857114}]}]}
{"op":"mcm","clk":"11917229670","pt":1724085582875,"mc":[{"id":"1.232011680","rc":[{"batb":[[0,1.44,600],[1,1.39,3.58],[2,1.34,4.14]],"ltp":1.33,"tv":52149.09,"id":72857114}]}]}
{"op":"mcm","clk":"11917229918","pt":1724085584850,"mc":[{"id":"1.232011680","rc":[{"batb":[[1,1.43,41.64],[2,1.39,3.58]],"ltp":1.33,"tv":52149.09,"id":72857114}]}]}
{"op":"mcm","clk":"11917230726","pt":1724085590852,"mc":[{"id":"1.232011680","rc":[{"batb":[[0,1.48,35.82],[1,1.45,3.83],[2,1.44,640.7]],"ltp":1.33,"tv":52149.09,"id":72857114}]}]}
{"op":"mcm","clk":"11917230955","pt":1724085592572,"mc":[{"id":"1.232011680","rc":[{"batb":[[1,1.44,640.7],[2,1.43,41.64]],"ltp":1.33,"tv":52149.09,"id":72857114}]}]}
{"op":"mcm","clk":"11917231083","pt":1724085593453,"mc":[{"id":"1.232011680","rc":[{"batb":[[0,1.48,39.75],[1,1.44,40.7]],"ltp":1.33,"tv":52149.09,"id":72857114}]}]}
{"op":"mcm","clk":"11917231153","pt":1724085593972,"mc":[{"id":"1.232011680","rc":[{"batb":[[1,1.39,3.58],[2,1.33,145.46]],"ltp":1.33,"tv":52149.09,"id":72857114}]}]}
{"op":"mcm","clk":"11917232299","pt":1724085602894,"mc":[{"id":"1.232011680","rc":[{"batb":[[0,1.48,35.82]],"ltp":1.33,"tv":52149.09,"id":72857114}]}]}
{"op":"mcm","clk":"11917232425","pt":1724085603885,"mc":[{"id":"1.232011680","rc":[{"batb":[[0,1.5,9.94],[1,1.48,35.82],[2,1.39,3.58]],"ltp":1.33,"tv":52149.09,"id":72857114}]}]}
{"op":"mcm","clk":"11917232469","pt":1724085604270,"mc":[{"id":"1.232011680","rc":[{"batb":[[1,1.49,3.73],[2,1.48,35.82]],"ltp":1.33,"tv":52149.09,"id":72857114}]}]}
{"op":"mcm","clk":"11917232658","pt":1724085605864,"mc":[{"id":"1.232011680","rc":[{"batb":[[2,1.48,73.12]],"ltp":1.33,"tv":52149.09,"id":72857114}]}]}
{"op":"mcm","clk":"11917233971","pt":1724085616900,"mc":[{"id":"1.232011680","rc":[{"batl":[[0,1.75,3.06],[1,1.8,358.53],[2,2.2,5.17]],"ltp":1.33,"tv":52149.09,"id":72857114}]}]}
{"op":"mcm","clk":"11917234019","pt":1724085617466,"mc":[{"id":"1.232011680","rc":[{"batb":[[0,1.55,3.58],[1,1.5,9.94],[2,1.49,3.73]],"ltp":1.33,"tv":52149.09,"id":72857114}]}]}
{"op":"mcm","clk":"11917234125","pt":1724085618500,"mc":[{"id":"1.232011680","rc":[{"batb":[[0,2.3,10],[1,2.28,48.11],[2,1.33,151.52]],"batl":[[0,2.48,308.12]],"ltp":2.28,"tv":3727.23,"id":72857116}]}]}
{"op":"mcm","clk":"11917234219","pt":1724085619277,"mc":[{"id":"1.232011680","rc":[{"batb":[[2,1.48,73.12]],"ltp":1.33,"tv":52149.09,"id":72857114}]}]}
{"op":"mcm","clk":"11917234343","pt":1724085620270,"mc":[{"id":"1.232011680","rc":[{"trd":[[2.48,1237.02]],"ltp":2.48,"tv":4343.47,"id":72857116}],"tv":56492.56}]}
{"op":"mcm","clk":"11917234514","pt":1724085621780,"mc":[{"id":"1.232011680","rc":[{"batb":[[0,2.28,48.11],[1,1.33,151.52],[2,1.23,434.78]],"ltp":2.48,"tv":4343.47,"id":72857116}]}]}
{"op":"mcm","clk":"11917235133","pt":1724085627419,"mc":[{"id":"1.232011680","rc":[{"batb":[[0,2.3,10],[1,2.28,48.11],[2,1.33,151.52]],"batl":[[0,2.48,308.12]],"ltp":2.48,"tv":4343.47,"id":72857116}]}]}
{"op":"mcm","clk":"11917235352","pt":1724085629229,"mc":[{"id":"1.232011680","rc":[{"trd":[[2.48,1853.26]],"ltp":2.48,"tv":4959.7,"id":72857116}],"tv":57108.8}]}
{"op":"mcm","clk":"11917235515","pt":1724085630687,"mc":[{"id":"1.232011680","rc":[{"batb":[[0,2.28,48.11],[1,1.33,151.52],[2,1.23,434.78]],"ltp":2.48,"tv":4959.7,"id":72857116}]}]}
{"op":"mcm","clk":"11917236326","pt":1724085637621,"mc":[{"id":"1.232011680","rc":[{"batb":[[0,1.68,3.31],[1,1.55,3.58],[2,1.5,9.94]],"ltp":1.33,"tv":52149.09,"id":72857114},{"batb":[[0,2.3,10],[1,2.28,48.11],[2,1.33,151.52]],"batl":[[0,2.48,308.12]],"ltp":2.48,"tv":4959.7,"id":72857116}]}]}
{"op":"mcm","clk":"11917236471","pt":1724085638919,"mc":[{"id":"1.232011680","rc":[{"batb":[[1,1.67,26.72],[2,1.55,3.58]],"ltp":1.33,"tv":52149.09,"id":72857114}]}]}
{"op":"mcm","clk":"11917236655","pt":1724085640527,"mc":[{"id":"1.232011680","rc":[{"batb":[[1,1.55,3.58],[2,1.5,9.94]],"ltp":1.33,"tv":52149.09,"id":72857114},{"trd":[[2.48,2469.5]],"batb":[[0,2.28,48.11],[1,1.33,151.52],[2,1.23,434.78]],"ltp":2.48,"tv":5575.94,"id":72857116}],"tv":57725.04}]}
{"op":"mcm","clk":"11917236825","pt":1724085641930,"mc":[{"id":"1.232011680","rc":[{"batb":[[2,1.5,6]],"batl":[[0,1.71,6.74],[1,1.75,3.06],[2,1.8,358.53]],"ltp":1.33,"tv":52149.09,"id":72857114}]}]}
{"op":"mcm","clk":"11917236916","pt":1724085642707,"mc":[{"id":"1.232011680","rc":[{"batb":[[0,1.55,3.58],[1,1.5,6],[2,1.48,73.12]],"ltp":1.33,"tv":52149.09,"id":72857114}]}]}
{"op":"mcm","clk":"11917237482","pt":1724085647329,"mc":[{"id":"1.232011680","rc":[{"batb":[[0,2.3,10],[1,2.28,48.11],[2,1.33,151.52]],"batl":[[0,2.48,308.12]],"ltp":2.48,"tv":5575.94,"id":72857116}]}]}
{"op":"mcm","clk":"11917237841","pt":1724085649930,"mc":[{"id":"1.232011680","rc":[{"trd":[[2.48,3085.73]],"batb":[[0,2.3,23.77]],"ltp":2.48,"tv":6192.18,"id":72857116}],"tv":58341.27}]}
{"op":"mcm","clk":"11917237982","pt":1724085650915,"mc":[{"id":"1.232011680","rc":[{"batb":[[0,2.28,48.11],[1,1.33,151.52],[2,1.23,434.78]],"ltp":2.48,"tv":6192.18,"id":72857116}]}]}
{"op":"mcm","clk":"11917238842","pt":1724085657837,"mc":[{"id":"1.232011680","rc":[{"batb":[[0,2.3,10],[1,2.28,48.11],[2,1.33,151.52]],"batl":[[0,2.48,308.12]],"ltp":2.48,"tv":6192.18,"id":72857116}]}]}
{"op":"mcm","clk":"11917239150","pt":1724085659918,"mc":[{"id":"1.232011680","rc":[{"batb":[[0,1.66,27.13],[1,1.55,3.58],[2,1.5,6]],"ltp":1.33,"tv":52149.09,"id":72857114},{"batb":[[0,2.3,23.77]],"ltp":2.48,"tv":6192.18,"id":72857116}]}]}
{"op":"mcm","clk":"11917239228","pt":1724085660438,"mc":[{"id":"1.232011680","rc":[{"batb":[[0,1.55,4.52],[1,1.5,6],[2,1.48,73.12]],"ltp":1.33,"tv":52149.09,"id":72857114},{"trd":[[2.48,3701.97]],"ltp":2.48,"tv":6808.42,"id":72857116}],"tv":58957.51}]}
{"op":"mcm","clk":"11917239439","pt":1724085661845,"mc":[{"id":"1.232011680","rc":[{"batl":[[0,1.75,3.06],[1,1.8,358.53],[2,2.2,5.17]],"ltp":1.33,"tv":52149.09,"id":72857114},{"batb":[[0,2.28,48.11],[1,1.33,151.52],[2,1.23,434.78]],"ltp":2.48,"tv":6808.42,"id":72857116}]}]}
{"op":"mcm","clk":"11917239466","pt":1724085662051,"mc":[{"id":"1.232011680","rc":[{"batl":[[0,1.67,6.74],[1,1.75,3.06],[2,1.8,358.53]],"ltp":1.33,"tv":52149.09,"id":72857114}]}]}
{"op":"mcm","clk":"11917239879","pt":1724085665591,"mc":[{"id":"1.232011680","rc":[{"batl":[[0,1.75,3.06],[1,1.8,358.53],[2,2.2,5.17]],"ltp":1.33,"tv":52149.09,"id":72857114}]}]}
{"op":"mcm","clk":"11917240475","pt":1724085669758,"mc":[{"id":"1.232011680","rc":[{"batb":[[2,1.49,3.73]],"ltp":1.33,"tv":52149.09,"id":72857114}]}]}
{"op":"mcm","clk":"11917240802","pt":1724085672357,"mc":[{"id":"1.232011680","rc":[{"batb":[[0,2.3,10],[1,2.28,48.11],[2,1.33,151.52]],"batl":[[0,2.48,308.12]],"ltp":2.48,"tv":6808.42,"id":72857116}]}]}
{"op":"mcm","clk":"11917241155","pt":1724085674786,"mc":[{"id":"1.232011680","rc":[{"batb":[[2,1.48,73.12]],"ltp":1.33,"tv":52149.09,"id":72857114},{"trd":[[2.48,4318.21]],"ltp":2.48,"tv":7424.66,"id":72857116}],"tv":59573.75}]}
{"op":"mcm","clk":"11917241295","pt":1724085675673,"mc":[{"id":"1.232011680","rc":[{"batb":[[0,2.28,48.11],[1,1.33,151.52],[2,1.23,434.78]],"ltp":2.48,"tv":7424.66,"id":72857116}]}]}
{"op":"mcm","clk":"11917241476","pt":1724085676875,"mc":[{"id":"1.232011680","rc":[{"batl":[[0,1.75,4]],"ltp":1.33,"tv":52149.09,"id":72857114}]}]}
{"op":"mcm","clk":"11917242292","pt":1724085683669,"mc":[{"id":"1.232011680","rc":[{"batb":[[0,2.3,10],[1,2.28,48.11],[2,1.33,151.52]],"batl":[[0,2.48,308.12]],"ltp":2.48,"tv":7424.66,"id":72857116}]}]}
{"op":"mcm","clk":"11917242607","pt":1724085685884,"mc":[{"id":"1.232011680","rc":[{"batl":[[0,1.65,6.98],[1,1.75,4],[2,1.8,358.53]],"ltp":1.33,"tv":52149.09,"id":72857114},{"trd":[[2.48,4934.45]],"ltp":2.48,"tv":8040.89,"id":72857116}],"tv":60189.99}]}
{"op":"mcm","clk":"11917242728","pt":1724085686890,"mc":[{"id":"1.232011680","rc":[{"batb":[[0,2.28,48.11],[1,1.33,151.52],[2,1.23,434.78]],"ltp":2.48,"tv":8040.89,"id":72857116}]}]}
{"op":"mcm","clk":"11917243198","pt":1724085690499,"mc":[{"id":"1.232011680","rc":[{"batl":[[0,1.75,4],[1,1.8,358.53],[2,2.2,5.17]],"ltp":1.33,"tv":52149.09,"id":72857114}]}]}
{"op":"mcm","clk":"11917244079","pt":1724085696806,"mc":[{"id":"1.232011680","rc":[{"batb":[[0,2.3,10],[1,2.28,48.11],[2,1.33,151.52]],"batl":[[0,2.48,308.12]],"ltp":2.48,"tv":8040.89,"id":72857116}]}]}
{"op":"mcm","clk":"11917244361","pt":1724085698902,"mc":[{"id":"1.232011680","rc":[{"batb":[[0,1.66,27.13],[1,1.55,4.52],[2,1.5,6]],"ltp":1.33,"tv":52149.09,"id":72857114}]}]}
{"op":"mcm","clk":"11917244438","pt":1724085699479,"mc":[{"id":"1.232011680","rc":[{"batb":[[0,1.55,4.52],[1,1.5,6],[2,1.48,73.12]],"ltp":1.33,"tv":52149.09,"id":72857114},{"trd":[[2.48,5550.68]],"ltp":2.48,"tv":8657.13,"id":72857116}],"tv":60806.22}]}
{"op":"mcm","clk":"11917244588","pt":1724085700523,"mc":[{"id":"1.232011680","rc":[{"batl":[[0,1.72,4.52],[1,1.75,3.06],[2,1.8,358.53]],"ltp":1.33,"tv":52149.09,"id":72857114},{"batb":[[0,2.28,48.11],[1,1.33,151.52],[2,1.23,434.78]],"ltp":2.48,"tv":8657.13,"id":72857116}]}]}
{"op":"mcm","clk":"11917244903","pt":1724085702927,"mc":[{"id":"1.232011680","rc":[{"batb":[[1,1.48,73.12],[2,1.46,3.22]],"ltp":1.33,"tv":52149.09,"id":72857114}]}]}
{"op":"mcm","clk":"11917245036","pt":1724085703914,"mc":[{"id":"1.232011680","rc":[{"batb":[[1,1.48,35.82]],"ltp":1.33,"tv":52149.09,"id":72857114}]}]}
{"op":"mcm","clk":"11917245536","pt":1724085707808,"mc":[{"id":"1.232011680","rc":[{"batb":[[0,2.3,10],[1,2.28,48.11],[2,1.33,151.52]],"batl":[[0,2.48,308.12]],"ltp":2.48,"tv":8657.13,"id":72857116}]}]}
{"op":"mcm","clk":"11917245675","pt":1724085708808,"mc":[{"id":"1.232011680","rc":[{"batb":[[0,1.68,3.31],[1,1.55,4.52],[2,1.48,35.82]],"ltp":1.33,"tv":52149.09,"id":72857114}]}]}
{"op":"mcm","clk":"11917245813","pt":1724085709934,"mc":[{"id":"1.232011680","rc":[{"batb":[[1,1.67,26.72],[2,1.55,4.52]],"ltp":1.33,"tv":52149.09,"id":72857114},{"trd":[[2.48,6166.92]],"ltp":2.48,"tv":9273.37,"id":72857116}],"tv":61422.46}]}
{"op":"mcm","clk":"11917245930","pt":1724085710924,"mc":[{"id":"1.232011680","rc":[{"batb":[[1,1.55,4.52],[2,1.48,73.12]],"ltp":1.33,"tv":52149.09,"id":72857114}]}]}
{"op":"mcm","clk":"11917246077","pt":1724085711918,"mc":[{"id":"1.232011680","rc":[{"batb":[[0,1.55,4.52],[1,1.46,3.22],[2,1.39,49.49]],"batl":[[0,1.66,3.58],[1,1.72,4.52],[2,1.75,3.06]],"ltp":1.33,"tv":52149.09,"id":72857114},{"batb":[[0,2.28,48.11],[1,1.33,151.52],[2,1.23,434.78]],"ltp":2.48,"tv":9273.37,"id":72857116}]}]}
{"op":"mcm","clk":"11917246091","pt":1724085712021,"mc":[{"id":"1.232011680","rc":[{"batb":[[0,1.57,36.76],[1,1.55,3.58],[2,1.46,3.22]],"ltp":1.33,"tv":52149.09,"id":72857114}]}]}
{"op":"mcm","clk":"11917246343","pt":1724085714263,"mc":[{"id":"1.232011680","rc":[{"batb":[[1,1.55,36.14]],"ltp":1.33,"tv":52149.09,"id":72857114}]}]}
{"op":"mcm","clk":"11917246636","pt":1724085715906,"mc":[{"id":"1.232011680","rc":[{"batb":[[1,1.56,10.09],[2,1.55,36.14]],"batl":[[0,1.72,4.52],[1,1.75,3.06],[2,1.8,358.53]],"ltp":1.33,"tv":52149.09,"id":72857114},{"batb":[[1,2.26,6.97],[2,1.33,151.52]],"ltp":2.48,"tv":9273.37,"id":72857116}]}]}
{"op":"mcm","clk":"11917246906","pt":1724085717939,"mc":[{"id":"1.232011680","rc":[{"batb":[[1,1.56,42.06]],"ltp":1.33,"tv":52149.09,"id":72857114}]}]}
{"op":"mcm","clk":"11917247160","pt":1724085719804,"mc":[{"id":"1.232011680","rc":[{"batl":[[0,1.72,5.47]],"ltp":1.33,"tv":52149.09,"id":72857114}]}]}
{"op":"mcm","clk":"11917247335","pt":1724085721244,"mc":[{"id":"1.232011680","rc":[{"batb":[[0,2.3,10],[1,2.28,48.11],[2,2.26,6.97]],"batl":[[0,2.48,308.12]],"ltp":2.48,"tv":9273.37,"id":72857116}]}]}
{"op":"mcm","clk":"11917247532","pt":1724085722909,"mc":[{"id":"1.232011680","rc":[{"batb":[[0,1.66,27.13],[1,1.57,36.76],[2,1.56,42.06]],"ltp":1.33,"tv":52149.09,"id":72857114},{"batb":[[0,2.3,23.77]],"ltp":2.48,"tv":9273.37,"id":72857116}]}]}
{"op":"mcm","clk":"11917247598","pt":1724085723432,"mc":[{"id":"1.232011680","rc":[{"trd":[[1.67,204.12]],"batb":[[2,1.56,31.97]],"ltp":1.67,"tv":52152.67,"id":72857114},{"trd":[[2.48,6169.33]],"batb":[[2,1.33,151.52]],"batl":[[0,2.48,305.71]],"ltp":2.48,"tv":9275.78,"id":72857116}],"tv":61428.46}]}
{"op":"mcm","clk":"11917247756","pt":1724085724623,"mc":[{"id":"1.232011680","rc":[{"batb":[[0,1.67,3.33],[2,1.55,36.14]],"ltp":1.67,"tv":52152.67,"id":72857114},{"trd":[[2.48,6780.75]],"batb":[[0,2.48,2.41],[1,2.3,13.77],[2,2.28,48.11]],"ltp":2.48,"tv":9887.2,"id":72857116}],"tv":62039.87}]}
{"op":"mcm","clk":"11917247797","pt":1724085725042,"mc":[{"id":"1.232011680","rc":[{"batb":[[1,2.28,48.11],[2,1.33,151.52]],"ltp":2.48,"tv":9887.2,"id":72857116}]}]}
{"op":"mcm","clk":"11917248005","pt":1724085726850,"mc":[{"id":"1.232011680","rc":[{"batb":[[0,1.57,36.76],[1,1.55,36.14],[2,1.46,3.22]],"ltp":1.67,"tv":52152.67,"id":72857114}]}]}
{"op":"mcm","clk":"11917249283","pt":1724085737737,"mc":[{"id":"1.232011680","rc":[{"batb":[[0,1.58,4.46],[1,1.57,35.82],[2,1.55,36.14]],"ltp":1.67,"tv":52152.67,"id":72857114}]}]}
{"op":"mcm","clk":"11917249568","pt":1724085740070,"mc":[{"id":"1.232011680","rc":[{"batb":[[1,1.57,67.23]],"batl":[[0,1.67,3.58],[1,1.72,1.88],[2,1.75,3.06]],"ltp":1.67,"tv":52152.67,"id":72857114}]}]}
{"op":"mcm","clk":"11917249895","pt":1724085742773,"mc":[{"id":"1.232011680","rc":[{"trd":[[1.58,34.79]],"batb":[[0,1.57,67.91],[1,1.55,36.14],[2,1.46,3.22]],"ltp":1.58,"tv":52160.21,"id":72857114},{"batb":[[0,2.28,48.11],[1,1.33,151.52],[2,1.23,434.78]],"ltp":2.48,"tv":9887.2,"id":72857116}],"tv":62047.41}]}
{"op":"mcm","clk":"11917249928","pt":1724085742978,"mc":[{"id":"1.232011680","rc":[{"batb":[[0,1.57,36.5]],"ltp":1.58,"tv":52160.21,"id":72857114}]}]}
{"op":"mcm","clk":"11917250210","pt":1724085745161,"mc":[{"id":"1.232011680","rc":[{"batb":[[0,1.57,35.82]],"ltp":1.58,"tv":52160.21,"id":72857114}]}]}
{"op":"mcm","clk":"11917250391","pt":1724085746560,"mc":[{"id":"1.232011680","rc":[{"batl":[[0,1.72,1.88],[1,1.75,3.06],[2,1.8,358.53]],"ltp":1.58,"tv":52160.21,"id":72857114}]}]}
{"op":"mcm","clk":"11917251522","pt":1724085755577,"mc":[{"id":"1.232011680","rc":[{"batb":[[1,1.55,46.29]],"ltp":1.58,"tv":52160.21,"id":72857114},{"batb":[[0,2.28,55.01]],"ltp":2.48,"tv":9887.2,"id":72857116}]}]}
{"op":"mcm","clk":"11917252444","pt":1724085763166,"mc":[{"id":"1.232011680","rc":[{"batb":[[0,1.57,45.81],[1,1.55,36.14]],"ltp":1.58,"tv":52160.21,"id":72857114},{"batb":[[0,2.28,48.11],[1,2.22,7.06],[2,1.33,151.52]],"ltp":2.48,"tv":9887.2,"id":72857116}]}]}
{"op":"mcm","clk":"11917252644","pt":1724085764978,"mc":[{"id":"1.232011680","rc":[{"batb":[[1,1.56,31.97],[2,1.55,36.14]],"ltp":1.58,"tv":52160.21,"id":72857114}]}]}
{"op":"mcm","clk":"11917253849","pt":1724085775062,"mc":[{"id":"1.232011680","rc":[{"batl":[[0,1.67,4.52],[1,1.75,4]],"ltp":1.58,"tv":52160.21,"id":72857114}]}]}
{"op":"mcm","clk":"11917254241","pt":1724085778002,"mc":[{"id":"1.232011680","rc":[{"batb":[[0,1.57,46.75]],"ltp":1.58,"tv":52160.21,"id":72857114}]}]}
{"op":"mcm","clk":"11917255138","pt":1724085784614,"mc":[{"id":"1.232011680","rc":[{"batb":[[0,1.58,5.6],[1,1.57,45.81],[2,1.56,31.97]],"ltp":1.58,"tv":52160.21,"id":72857114}]}]}
{"op":"mcm","clk":"11917255195","pt":1724085785026,"mc":[{"id":"1.232011680","rc":[{"batb":[[1,1.57,77.22]],"ltp":1.58,"tv":52160.21,"id":72857114}]}]}
{"op":"mcm","clk":"11917256541","pt":1724085795303,"mc":[{"id":"1.232011680","rc":[{"batb":[[0,2.3,10],[1,2.28,48.11],[2,2.22,7.06]],"batl":[[0,2.5,304.27]],"ltp":2.48,"tv":9887.2,"id":72857116}]}]}
{"op":"mcm","clk":"11917256737","pt":1724085797007,"mc":[{"id":"1.232011680","rc":[{"batb":[[0,1.65,27.55],[1,1.58,5.6],[2,1.57,77.22]],"ltp":1.58,"tv":52160.21,"id":72857114},{"batb":[[0,2.3,23.77]],"ltp":2.48,"tv":9887.2,"id":72857116}]}]}
{"op":"mcm","clk":"11917256935","pt":1724085798621,"mc":[{"id":"1.232011680","rc":[{"batb":[[0,2.3,13.77]],"ltp":2.48,"tv":9887.2,"id":72857116}]}]}
{"op":"mcm","clk":"11917256985","pt":1724085799031,"mc":[{"id":"1.232011680","rc":[{"batb":[[0,2.28,48.11],[1,2.22,7.06],[2,1.33,151.52]],"ltp":2.48,"tv":9887.2,"id":72857116}]}]}
{"op":"mcm","clk":"11917257133","pt":1724085800333,"mc":[{"id":"1.232011680","rc":[{"trd":[[2.5,630.67]],"ltp":2.5,"tv":10495.73,"id":72857116}],"tv":62655.95}]}
{"op":"mcm","clk":"11917257304","pt":1724085801836,"mc":[{"id":"1.232011680","rc":[{"batb":[[0,1.58,5.6],[1,1.57,77.22],[2,1.56,31.97]],"ltp":1.58,"tv":52160.21,"id":72857114}]}]}
{"op":"mcm","clk":"11917257561","pt":1724085804113,"mc":[{"id":"1.232011680","rc":[{"batl":[[0,1.67,4.27]],"ltp":1.58,"tv":52160.21,"id":72857114}]}]}
{"op":"mcm","clk":"11917258061","pt":1724085807729,"mc":[{"id":"1.232011680","rc":[{"trd":[[1.66,1867.45]],"batl":[[0,1.67,3.33]],"ltp":1.66,"tv":52161.15,"id":72857114},{"trd":[[2.5,631.29]],"batb":[[0,2.3,10],[1,2.28,48.11],[2,2.22,7.06]],"batl":[[0,2.5,303.64]],"ltp":2.5,"tv":10496.35,"id":72857116}],"tv":62657.51}]}
{"op":"mcm","clk":"11917258394","pt":1724085810022,"mc":[{"id":"1.232011680","rc":[{"batb":[[0,1.65,27.55],[1,1.58,5.6],[2,1.57,77.22]],"ltp":1.66,"tv":52161.15,"id":72857114}]}]}
{"op":"mcm","clk":"11917258506","pt":1724085810949,"mc":[{"id":"1.232011680","rc":[{"batb":[[0,2.28,48.11],[1,2.22,7.06],[2,1.33,151.52]],"ltp":2.5,"tv":10496.35,"id":72857116}]}]}
{"op":"mcm","clk":"11917258969","pt":1724085813749,"mc":[{"id":"1.232011680","rc":[{"trd":[[2.5,1238.58]],"batb":[[0,2.28,48.74]],"ltp":2.5,"tv":11103.64,"id":72857116}],"tv":63264.8}]}
{"op":"mcm","clk":"11917259097","pt":1724085814629,"mc":[{"id":"1.232011680","rc":[{"batb":[[0,1.58,5.6],[1,1.57,77.22],[2,1.56,31.97]],"batl":[[0,1.66,3.33]],"ltp":1.66,"tv":52161.15,"id":72857114}]}]}
{"op":"mcm","clk":"11917260106","pt":1724085822726,"mc":[{"id":"1.232011680","rc":[{"batl":[[0,1.67,3.33]],"ltp":1.66,"tv":52161.15,"id":72857114}]}]}
{"op":"mcm","clk":"11917260679","pt":1724085827239,"mc":[{"id":"1.232011680","rc":[{"trd":[[1.58,34.88],[1.59,3.76]],"batb":[[0,1.58,4.61]],"ltp":1.58,"tv":52163.13,"id":72857114},{"batb":[[0,2.28,48.11]],"ltp":2.5,"tv":11103.64,"id":72857116}],"tv":63266.77}]}
{"op":"mcm","clk":"11917260844","pt":1724085828736,"mc":[{"id":"1.232011680","rc":[{"batl":[[2,1.78,7.7]],"ltp":1.58,"tv":52163.13,"id":72857114}]}]}
{"op":"mcm","clk":"11917261112","pt":1724085830873,"mc":[{"id":"1.232011680","rc":[{"batb":[[1,1.57,67.23]],"ltp":1.58,"tv":52163.13,"id":72857114},{"batb":[[1,1.33,151.52],[2,1.23,434.78]],"ltp":2.5,"tv":11103.64,"id":72857116}]}]}
{"op":"mcm","clk":"11917261179","pt":1724085831441,"mc":[{"id":"1.232011680","rc":[{"batl":[[0,1.67,4.27]],"ltp":1.58,"tv":52163.13,"id":72857114}]}]}
{"op":"mcm","clk":"11917261845","pt":1724085836883,"mc":[{"id":"1.232011680","rc":[{"trd":[[1.66,1868.39]],"batl":[[0,1.67,3.33]],"ltp":1.66,"tv":52164.07,"id":72857114},{"trd":[[2.5,1239.2]],"batb":[[0,2.3,10],[1,2.28,48.11],[2,1.33,151.52]],"batl":[[0,2.5,303.64]],"ltp":2.5,"tv":11104.27,"id":72857116}],"tv":63268.34}]}
{"op":"mcm","clk":"11917262064","pt":1724085838653,"mc":[{"id":"1.232011680","rc":[{"trd":[[1.66,1871.72]],"batl":[[0,1.75,4],[1,1.78,7.7],[2,1.8,358.53]],"ltp":1.66,"tv":52167.4,"id":72857114},{"trd":[[2.5,1241.41]],"batl":[[0,2.5,301.43]],"ltp":2.5,"tv":11106.48,"id":72857116}],"tv":63273.88}]}
{"op":"mcm","clk":"11917262100","pt":1724085838962,"mc":[{"id":"1.232011680","rc":[{"batb":[[0,1.65,27.55],[1,1.58,4.61],[2,1.57,67.23]],"ltp":1.66,"tv":52167.4,"id":72857114}]}]}
{"op":"mcm","clk":"11917262309","pt":1724085840367,"mc":[{"id":"1.232011680","rc":[{"trd":[[2.5,1844.28]],"batb":[[0,2.5,2.83],[1,2.3,10],[2,2.28,48.11]],"ltp":2.5,"tv":11709.34,"id":72857116}],"tv":63876.75}]}
{"op":"mcm","clk":"11917262419","pt":1724085841042,"mc":[{"id":"1.232011680","rc":[{"batb":[[0,1.58,4.61],[1,1.57,67.23],[2,1.56,31.97]],"ltp":1.66,"tv":52167.4,"id":72857114}]}]}
{"op":"mcm","clk":"11917262650","pt":1724085842669,"mc":[{"id":"1.232011680","rc":[{"batb":[[1,2.28,48.11],[2,1.33,151.52]],"ltp":2.5,"tv":11709.34,"id":72857116}]}]}
{"op":"mcm","clk":"11917263609","pt":1724085849682,"mc":[{"id":"1.232011680","rc":[{"batl":[[0,1.73,8.65],[1,1.75,3.06],[2,1.78,7.7]],"ltp":1.66,"tv":52167.4,"id":72857114}]}]}
{"op":"mcm","clk":"11917263861","pt":1724085851461,"mc":[{"id":"1.232011680","rc":[{"batb":[[0,1.58,5.55]],"ltp":1.66,"tv":52167.4,"id":72857114}]}]}
{"op":"mcm","clk":"11917264168","pt":1724085853701,"mc":[{"id":"1.232011680","rc":[{"batb":[[0,2.28,48.11],[1,1.33,151.52],[2,1.23,434.78]],"batl":[[0,2.5,301.43]],"ltp":2.5,"tv":11709.34,"id":72857116}]}]}
{"op":"mcm","clk":"11917264233","pt":1724085854168,"mc":[{"id":"1.232011680","rc":[{"batb":[[0,2.3,10],[1,2.28,48.11],[2,1.33,151.52]],"ltp":2.5,"tv":11709.34,"id":72857116}]}]}
{"op":"mcm","clk":"11917264475","pt":1724085855984,"mc":[{"id":"1.232011680","rc":[{"batb":[[0,1.65,27.55],[1,1.58,5.55],[2,1.57,67.23]],"ltp":1.66,"tv":52167.4,"id":72857114},{"batb":[[0,2.3,23.77]],"ltp":2.5,"tv":11709.34,"id":72857116}]}]}
{"op":"mcm","clk":"11917264679","pt":1724085857391,"mc":[{"id":"1.232011680","rc":[{"batb":[[0,2.3,13.77]],"ltp":2.5,"tv":11709.34,"id":72857116}]}]}
{"op":"mcm","clk":"11917264767","pt":1724085858073,"mc":[{"id":"1.232011680","rc":[{"batb":[[0,2.28,48.11],[1,1.33,151.52],[2,1.23,434.78]],"ltp":2.5,"tv":11709.34,"id":72857116}]}]}
{"op":"mcm","clk":"11917264950","pt":1724085859686,"mc":[{"id":"1.232011680","rc":[{"batb":[[0,1.58,5.55],[1,1.57,77.22],[2,1.56,31.97]],"ltp":1.66,"tv":52167.4,"id":72857114},{"trd":[[2.5,2447.14]],"batb":[[0,2.5,2.83],[1,2.28,48.11],[2,2.22,7.06]],"ltp":2.5,"tv":12312.21,"id":72857116}],"tv":64479.61}]}
{"op":"mcm","clk":"11917265560","pt":1724085864472,"mc":[{"id":"1.232011680","rc":[{"batb":[[0,1.6,17.67],[1,1.58,4.61],[2,1.57,77.22]],"ltp":1.66,"tv":52167.4,"id":72857114}]}]}
{"op":"mcm","clk":"11917266020","pt":1724085867791,"mc":[{"id":"1.232011680","rc":[{"trd":[[1.6,10.73]],"batb":[[0,1.6,13.25]],"ltp":1.6,"tv":52176.24,"id":72857114},{"batb":[[0,2.28,48.11],[1,2.22,7.06],[2,1.33,151.52]],"ltp":2.5,"tv":12312.21,"id":72857116}],"tv":64488.46}]}
{"op":"mcm","clk":"11917268130","pt":1724085883906,"mc":[{"id":"1.232011680","rc":[{"batl":[[2,1.8,358.53]],"ltp":1.6,"tv":52176.24,"id":72857114}]}]}
{"op":"mcm","clk":"11917268336","pt":1724085885613,"mc":[{"id":"1.232011680","rc":[{"batb":[[0,1.61,4.61],[1,1.6,13.25]],"ltp":1.6,"tv":52176.24,"id":72857114}]}]}
{"op":"mcm","clk":"11917269003","pt":1724085890808,"mc":[{"id":"1.232011680","rc":[{"batb":[[0,1.61,5.55]],"ltp":1.6,"tv":52176.24,"id":72857114}]}]}
{"op":"mcm","clk":"11917269064","pt":1724085891224,"mc":[{"id":"1.232011680","rc":[{"batb":[[0,2.3,10],[1,2.28,48.11],[2,2.22,7.06]],"batl":[[0,2.48,308.12]],"ltp":2.5,"tv":12312.21,"id":72857116}]}]}
{"op":"mcm","clk":"11917269263","pt":1724085892989,"mc":[{"id":"1.232011680","rc":[{"batb":[[0,1.66,27.13],[1,1.61,5.55],[2,1.6,13.25]],"ltp":1.6,"tv":52176.24,"id":72857114},{"batb":[[0,2.3,23.77]],"ltp":2.5,"tv":12312.21,"id":72857116}]}]}
{"op":"mcm","clk":"11917269499","pt":1724085894598,"mc":[{"id":"1.232011680","rc":[{"batb":[[0,2.28,48.11],[1,2.22,7.06],[2,1.33,151.52]],"ltp":2.5,"tv":12312.21,"id":72857116}]}]}
{"op":"mcm","clk":"11917269627","pt":1724085895487,"mc":[{"id":"1.232011680","rc":[{"batb":[[0,1.61,5.55],[1,1.6,13.25],[2,1.57,77.22]],"ltp":1.6,"tv":52176.24,"id":72857114},{"trd":[[2.48,7396.99]],"ltp":2.48,"tv":12928.45,"id":72857116}],"tv":65104.69}]}
{"op":"mcm","clk":"11917269983","pt":1724085898197,"mc":[{"id":"1.232011680","rc":[{"batb":[[2,1.57,67.23]],"ltp":1.6,"tv":52176.24,"id":72857114},{"batb":[[1,1.33,151.52],[2,1.23,434.78]],"ltp":2.48,"tv":12928.45,"id":72857116}]}]}
{"op":"mcm","clk":"11917270451","pt":1724085901934,"mc":[{"id":"1.232011680","rc":[{"batb":[[0,2.3,10],[1,2.28,48.11],[2,1.33,151.52]],"batl":[[0,2.48,308.12]],"ltp":2.48,"tv":12928.45,"id":72857116}]}]}
{"op":"mcm","clk":"11917270878","pt":1724085904516,"mc":[{"id":"1.232011680","rc":[{"trd":[[2.48,8013.23]],"batb":[[0,2.3,23.77]],"ltp":2.48,"tv":13544.68,"id":72857116}],"tv":65720.93}]}
{"op":"mcm","clk":"11917271029","pt":1724085905504,"mc":[{"id":"1.232011680","rc":[{"batb":[[0,2.28,48.11],[1,1.33,151.52],[2,1.23,434.78]],"ltp":2.48,"tv":13544.68,"id":72857116}]}]}
{"op":"mcm","clk":"11917272560","pt":1724085916710,"mc":[{"id":"1.232011680","rc":[{"trd":[[1.67,205.06]],"batl":[[0,1.73,7.7]],"ltp":1.67,"tv":52177.19,"id":72857114},{"trd":[[2.48,8013.86]],"batb":[[0,2.3,10],[1,2.28,48.11],[2,1.33,151.52]],"batl":[[0,2.48,307.49]],"ltp":2.48,"tv":13545.31,"id":72857116}],"tv":65722.51}]}
{"op":"mcm","clk":"11917272843","pt":1724085919045,"mc":[{"id":"1.232011680","rc":[{"batb":[[0,1.66,27.13],[1,1.61,5.55],[2,1.6,13.25]],"ltp":1.67,"tv":52177.19,"id":72857114},{"batb":[[0,2.3,23.77]],"ltp":2.48,"tv":13545.31,"id":72857116}]}]}
{"op":"mcm","clk":"11917273045","pt":1724085920549,"mc":[{"id":"1.232011680","rc":[{"batb":[[0,2.28,48.11],[1,1.33,151.52],[2,1.23,434.78]],"ltp":2.48,"tv":13545.31,"id":72857116}]}]}
{"op":"mcm","clk":"11917273318","pt":1724085922530,"mc":[{"id":"1.232011680","rc":[{"batb":[[0,1.61,5.55],[1,1.6,13.25],[2,1.57,67.23]],"ltp":1.67,"tv":52177.19,"id":72857114},{"trd":[[2.48,8628.83]],"batb":[[0,2.28,48.74]],"ltp":2.48,"tv":14160.29,"id":72857116}],"tv":66337.48}]}
{"op":"mcm","clk":"11917274485","pt":1724085930864,"mc":[{"id":"1.232011680","rc":[{"batb":[[0,2.28,48.11]],"batl":[[0,2.48,307.49]],"ltp":2.48,"tv":14160.29,"id":72857116}]}]}
{"op":"mcm","clk":"11917274517","pt":1724085931023,"mc":[{"id":"1.232011680","rc":[{"batb":[[1,1.57,67.23],[2,1.56,31.97]],"ltp":1.67,"tv":52177.19,"id":72857114},{"batb":[[0,2.3,10],[1,2.28,48.11],[2,1.33,151.52]],"ltp":2.48,"tv":14160.29,"id":72857116}]}]}
{"op":"mcm","clk":"11917274787","pt":1724085933047,"mc":[{"id":"1.232011680","rc":[{"batb":[[0,1.66,27.13],[1,1.61,5.55],[2,1.57,67.23]],"ltp":1.67,"tv":52177.19,"id":72857114},{"batb":[[0,2.3,23.77]],"ltp":2.48,"tv":14160.29,"id":72857116}]}]}
{"op":"mcm","clk":"11917275003","pt":1724085934558,"mc":[{"id":"1.232011680","rc":[{"batb":[[0,1.61,5.55],[1,1.57,67.23],[2,1.56,31.97]],"ltp":1.67,"tv":52177.19,"id":72857114},{"trd":[[2.48,9243.81]],"batb":[[0,2.3,14.4]],"ltp":2.48,"tv":14775.26,"id":72857116}],"tv":66952.46}]}
{"op":"mcm","clk":"11917275082","pt":1724085935181,"mc":[{"id":"1.232011680","rc":[{"batb":[[0,2.28,48.74],[1,1.33,151.52],[2,1.23,434.78]],"ltp":2.48,"tv":14775.26,"id":72857116}]}]}
{"op":"mcm","clk":"11917275937","pt":1724085942380,"mc":[{"id":"1.232011680","rc":[{"trd":[[1.61,7.23],[1.63,1.88]],"batb":[[0,1.61,4.58]],"ltp":1.61,"tv":52179.13,"id":72857114},{"batb":[[0,2.28,48.11]],"ltp":2.48,"tv":14775.26,"id":72857116}],"tv":66954.4}]}
{"op":"mcm","clk":"11917277522","pt":1724085953697,"mc":[{"id":"1.232011680","rc":[{"batl":[[0,1.71,3.48],[1,1.73,7.7],[2,1.75,3.06]],"ltp":1.61,"tv":52179.13,"id":72857114}]}]}
{"op":"mcm","clk":"11917277863","pt":1724085955888,"mc":[{"id":"1.232011680","rc":[{"batl":[[0,1.71,4.42]],"ltp":1.61,"tv":52179.13,"id":72857114}]}]}
{"op":"mcm","clk":"11917279383","pt":1724085966875,"mc":[{"id":"1.232011680","rc":[{"batb":[[0,1.61,5.52]],"ltp":1.61,"tv":52179.13,"id":72857114}]}]}
{"op":"mcm","clk":"11917282944","pt":1724085994221,"mc":[{"id":"1.232011680","rc":[{"batb":[[0,2.3,10],[1,2.28,48.11],[2,1.33,151.52]],"batl":[[0,2.48,308.12]],"ltp":2.48,"tv":14775.26,"id":72857116}]}]}
{"op":"mcm","clk":"11917283175","pt":1724085996081,"mc":[{"id":"1.232011680","rc":[{"batb":[[0,1.66,27.13],[1,1.61,5.52],[2,1.57,67.23]],"ltp":1.61,"tv":52179.13,"id":72857114},{"batb":[[0,2.3,23.77]],"ltp":2.48,"tv":14775.26,"id":72857116}]}]}
{"op":"mcm","clk":"11917283347","pt":1724085997535,"mc":[{"id":"1.232011680","rc":[{"batb":[[0,2.3,13.77]],"ltp":2.48,"tv":14775.26,"id":72857116}]}]}
{"op":"mcm","clk":"11917283427","pt":1724085998106,"mc":[{"id":"1.232011680","rc":[{"batb":[[0,2.28,48.11],[1,1.33,151.52],[2,1.23,434.78]],"ltp":2.48,"tv":14775.26,"id":72857116}]}]}
{"op":"mcm","clk":"11917283746","pt":1724086000631,"mc":[{"id":"1.232011680","rc":[{"batb":[[0,1.61,5.52],[1,1.57,67.23],[2,1.56,31.97]],"ltp":1.61,"tv":52179.13,"id":72857114},{"trd":[[2.48,9860.04]],"ltp":2.48,"tv":15391.5,"id":72857116}],"tv":67570.64}]}
{"op":"mcm","clk":"11917284407","pt":1724086005917,"mc":[{"id":"1.232011680","rc":[{"batl":[[0,1.71,3.48]],"ltp":1.61,"tv":52179.13,"id":72857114}]}]}
{"op":"mcm","clk":"11917284422","pt":1724086006020,"mc":[{"id":"1.232011680","rc":[{"batl":[[0,1.71,4.42]],"ltp":1.61,"tv":52179.13,"id":72857114}]}]}
{"op":"mcm","clk":"11917285022","pt":1724086010324,"mc":[{"id":"1.232011680","rc":[{"trd":[[1.67,206]],"batl":[[0,1.71,3.48]],"ltp":1.67,"tv":52180.07,"id":72857114},{"trd":[[2.48,9860.68]],"batb":[[0,2.3,10],[1,2.28,48.11],[2,1.33,151.52]],"batl":[[0,2.48,307.49]],"ltp":2.48,"tv":15392.13,"id":72857116}],"tv":67572.21}]}
{"op":"mcm","clk":"11917285262","pt":1724086012129,"mc":[{"id":"1.232011680","rc":[{"batb":[[0,1.66,27.13],[1,1.61,5.52],[2,1.57,67.23]],"ltp":1.67,"tv":52180.07,"id":72857114},{"batb":[[0,2.3,23.77]],"ltp":2.48,"tv":15392.13,"id":72857116}]}]}
{"op":"mcm","clk":"11917285465","pt":1724086013630,"mc":[{"id":"1.232011680","rc":[{"batb":[[0,2.3,13.77]],"ltp":2.48,"tv":15392.13,"id":72857116}]}]}
{"op":"mcm","clk":"11917285632","pt":1724086014824,"mc":[{"id":"1.232011680","rc":[{"batb":[[1,1.61,4.58]],"ltp":1.67,"tv":52180.07,"id":72857114},{"trd":[[2.48,10475.65]],"batb":[[0,2.28,48.74],[1,1.33,151.52],[2,1.23,434.78]],"ltp":2.48,"tv":16007.11,"id":72857116}],"tv":68187.18}]}
{"op":"mcm","clk":"11917285676","pt":1724086015136,"mc":[{"id":"1.232011680","rc":[{"batb":[[0,1.61,5.52],[1,1.57,67.23],[2,1.56,31.97]],"ltp":1.67,"tv":52180.07,"id":72857114}]}]}
{"op":"mcm","clk":"11917288110","pt":1724086032367,"mc":[{"id":"1.232011680","rc":[{"trd":[[1.61,7.26],[1.64,950.23]],"batb":[[0,1.61,4.56]],"ltp":1.61,"tv":52181.98,"id":72857114},{"batb":[[0,2.28,48.11]],"ltp":2.48,"tv":16007.11,"id":72857116}],"tv":68189.1}]}
{"op":"mcm","clk":"11917289263","pt":1724086041452,"mc":[{"id":"1.232011680","rc":[{"batl":[[0,1.71,4.42]],"ltp":1.61,"tv":52181.98,"id":72857114}]}]}
{"op":"mcm","clk":"11917289965","pt":1724086047354,"mc":[{"id":"1.232011680","rc":[{"trd":[[1.67,206.95]],"batl":[[0,1.71,3.48]],"ltp":1.67,"tv":52182.93,"id":72857114},{"trd":[[2.48,10476.28]],"batb":[[0,2.3,10],[1,2.28,48.11],[2,1.33,151.52]],"batl":[[0,2.48,307.49]],"ltp":2.48,"tv":16007.74,"id":72857116}],"tv":68190.67}]}
{"op":"mcm","clk":"11917290155","pt":1724086048769,"mc":[{"id":"1.232011680","rc":[{"batb":[[0,1.68,4],[1,1.67,4],[2,1.61,4.56]],"ltp":1.67,"tv":52182.93,"id":72857114},{"batb":[[2,2.24,7.03]],"batl":[[0,2.48,311.49]],"ltp":2.48,"tv":16007.74,"id":72857116}]}]}
{"op":"mcm","clk":"11917290200","pt":1724086049183,"mc":[{"id":"1.232011680","rc":[{"batb":[[1,1.67,30.72]],"ltp":1.67,"tv":52182.93,"id":72857114},{"batb":[[0,2.3,23.77]],"ltp":2.48,"tv":16007.74,"id":72857116}]}]}
{"op":"mcm","clk":"11917290395","pt":1724086050787,"mc":[{"id":"1.232011680","rc":[{"batb":[[1,1.67,4]],"ltp":1.67,"tv":52182.93,"id":72857114},{"trd":[[2.48,11092.52]],"batb":[[0,2.3,13.77]],"batl":[[0,2.48,3.37]],"ltp":2.48,"tv":16623.98,"id":72857116}],"tv":68806.91}]}
{"op":"mcm","clk":"11917290449","pt":1724086051154,"mc":[{"id":"1.232011680","rc":[{"batb":[[0,1.61,4.56],[1,1.57,77.26],[2,1.56,31.97]],"ltp":1.67,"tv":52182.93,"id":72857114},{"batb":[[0,2.28,48.11],[1,2.24,7.03],[2,1.33,151.52]],"ltp":2.48,"tv":16623.98,"id":72857116}]}]}
{"op":"mcm","clk":"11917291260","pt":1724086057876,"mc":[{"id":"1.232011680","rc":[{"batb":[[0,2.3,10],[1,2.28,48.11],[2,2.24,7.03]],"batl":[[0,2.48,308.12]],"ltp":2.48,"tv":16623.98,"id":72857116}]}]}
{"op":"mcm","clk":"11917291457","pt":1724086059483,"mc":[{"id":"1.232011680","rc":[{"batb":[[0,1.61,5.51]],"ltp":1.67,"tv":52182.93,"id":72857114}]}]}
{"op":"mcm","clk":"11917291538","pt":1724086060101,"mc":[{"id":"1.232011680","rc":[{"batb":[[0,1.66,27.13],[1,1.61,5.51],[2,1.57,77.26]],"ltp":1.67,"tv":52182.93,"id":72857114},{"batb":[[0,2.3,23.77]],"ltp":2.48,"tv":16623.98,"id":72857116}]}]}
{"op":"mcm","clk":"11917291732","pt":1724086061715,"mc":[{"id":"1.232011680","rc":[{"batb":[[0,2.28,48.11],[1,2.24,7.03],[2,1.33,151.52]],"ltp":2.48,"tv":16623.98,"id":72857116}]}]}
{"op":"mcm","clk":"11917292012","pt":1724086063694,"mc":[{"id":"1.232011680","rc":[{"batb":[[0,1.68,4],[1,1.67,4],[2,1.66,27.13]],"ltp":1.67,"tv":52182.93,"id":72857114},{"batb":[[0,2.3,10],[1,2.28,48.11]],"batl":[[0,2.48,312.12]],"ltp":2.48,"tv":16623.98,"id":72857116}]}]}
{"op":"mcm","clk":"11917292157","pt":1724086064892,"mc":[{"id":"1.232011680","rc":[{"batb":[[0,1.61,5.51],[1,1.57,67.23],[2,1.56,31.97]],"ltp":1.67,"tv":52182.93,"id":72857114},{"trd":[[2.48,11708.76]],"ltp":2.48,"tv":17240.21,"id":72857116}],"tv":69423.15}]}
{"op":"mcm","clk":"11917292375","pt":1724086066700,"mc":[{"id":"1.232011680","rc":[{"batb":[[0,2.3,13.77]],"ltp":2.48,"tv":17240.21,"id":72857116}]}]}
{"op":"mcm","clk":"11917292425","pt":1724086067159,"mc":[{"id":"1.232011680","rc":[{"batb":[[0,2.28,48.11],[1,1.33,151.52],[2,1.23,434.78]],"ltp":2.48,"tv":17240.21,"id":72857116}]}]}
{"op":"mcm","clk":"11917299487","pt":1724086115847,"mc":[{"id":"1.232011680","rc":[{"batb":[[0,2.3,10],[1,2.28,48.11],[2,1.33,151.52]],"batl":[[0,2.48,308.12]],"ltp":2.48,"tv":17240.21,"id":72857116}]}]}
{"op":"mcm","clk":"11917299776","pt":1724086118177,"mc":[{"id":"1.232011680","rc":[{"batb":[[0,1.66,27.13],[1,1.61,5.51],[2,1.57,67.23]],"ltp":1.67,"tv":52182.93,"id":72857114},{"batb":[[0,2.3,23.77]],"ltp":2.48,"tv":17240.21,"id":72857116}]}]}
{"op":"mcm","clk":"11917299968","pt":1724086119661,"mc":[{"id":"1.232011680","rc":[{"batb":[[0,2.28,48.11],[1,1.33,151.52],[2,1.23,434.78]],"ltp":2.48,"tv":17240.21,"id":72857116}]}]}
{"op":"mcm","clk":"11917300041","pt":1724086120182,"mc":[{"id":"1.232011680","rc":[{"batb":[[0,1.61,5.51],[1,1.57,67.23],[2,1.56,31.97]],"ltp":1.67,"tv":52182.93,"id":72857114},{"trd":[[2.48,12324.99]],"ltp":2.48,"tv":17856.45,"id":72857116}],"tv":70039.38}]}
{"op":"mcm","clk":"11917300767","pt":1724086125680,"mc":[{"id":"1.232011680","rc":[{"batb":[[0,2.3,10],[1,2.28,48.11],[2,1.33,151.52]],"batl":[[0,2.48,308.12]],"ltp":2.48,"tv":17856.45,"id":72857116}]}]}
{"op":"mcm","clk":"11917300972","pt":1724086127274,"mc":[{"id":"1.232011680","rc":[{"batl":[[0,1.73,7.7],[1,1.75,3.06],[2,1.8,358.53]],"ltp":1.67,"tv":52182.93,"id":72857114}]}]}
{"op":"mcm","clk":"11917301103","pt":1724086128166,"mc":[{"id":"1.232011680","rc":[{"batb":[[0,1.66,27.13],[1,1.61,5.51],[2,1.57,67.23]],"ltp":1.67,"tv":52182.93,"id":72857114},{"batb":[[0,2.3,23.77]],"ltp":2.48,"tv":17856.45,"id":72857116}]}]}
{"op":"mcm","clk":"11917301305","pt":1724086129674,"mc":[{"id":"1.232011680","rc":[{"batb":[[0,1.61,5.51],[1,1.57,67.23],[2,1.56,31.97]],"ltp":1.67,"tv":52182.93,"id":72857114},{"trd":[[2.48,12941.23]],"batb":[[0,2.28,48.11],[1,1.33,151.52],[2,1.23,434.78]],"ltp":2.48,"tv":18472.69,"id":72857116}],"tv":70655.62}]}
{"op":"mcm","clk":"11917302703","pt":1724086140385,"mc":[{"id":"1.232011680","rc":[{"batl":[[0,1.67,3.48],[1,1.73,7.7],[2,1.75,3.06]],"ltp":1.67,"tv":52182.93,"id":72857114}]}]}
{"op":"mcm","clk":"11917304935","pt":1724086158194,"mc":[{"id":"1.232011680","rc":[{"trd":[[1.61,15.4],[1.64,952.12]],"batb":[[0,1.57,36.31],[1,1.39,3.58],[2,1.33,145.46]],"ltp":1.61,"tv":52192.95,"id":72857114}],"tv":70665.64}]}
{"op":"mcm","clk":"11917305194","pt":1724086160175,"mc":[{"id":"1.232011680","rc":[{"batb":[[0,2.3,10],[1,2.28,48.11],[2,1.33,151.52]],"batl":[[0,2.5,304.27]],"ltp":2.48,"tv":18472.69,"id":72857116}]}]}
{"op":"mcm","clk":"11917305450","pt":1724086162189,"mc":[{"id":"1.232011680","rc":[{"batb":[[0,1.65,27.55],[1,1.57,36.31],[2,1.39,3.58]],"ltp":1.61,"tv":52192.95,"id":72857114},{"batb":[[0,2.3,23.77]],"ltp":2.48,"tv":18472.69,"id":72857116}]}]}
{"op":"mcm","clk":"11917305596","pt":1724086163589,"mc":[{"id":"1.232011680","rc":[{"batb":[[0,2.3,13.77]],"ltp":2.48,"tv":18472.69,"id":72857116}]}]}
{"op":"mcm","clk":"11917305684","pt":1724086164266,"mc":[{"id":"1.232011680","rc":[{"batb":[[0,2.28,48.11],[1,1.33,151.52],[2,1.23,434.78]],"ltp":2.48,"tv":18472.69,"id":72857116}]}]}
{"op":"mcm","clk":"11917305861","pt":1724086165765,"mc":[{"id":"1.232011680","rc":[{"batb":[[0,1.57,36.31],[1,1.39,3.58],[2,1.33,145.46]],"ltp":1.61,"tv":52192.95,"id":72857114},{"trd":[[2.5,3055.68]],"ltp":2.5,"tv":19081.22,"id":72857116}],"tv":71274.18}]}
{"op":"mcm","clk":"11917306410","pt":1724086171379,"mc":[{"id":"1.232011680","rc":[{"batb":[[0,2.3,10],[1,2.28,48.11],[2,1.33,151.52]],"batl":[[0,2.5,304.27]],"ltp":2.5,"tv":19081.22,"id":72857116}]}]}
{"op":"mcm","clk":"11917306574","pt":1724086173182,"mc":[{"id":"1.232011680","rc":[{"batb":[[0,1.65,27.55],[1,1.57,36.31],[2,1.39,3.58]],"ltp":1.61,"tv":52192.95,"id":72857114},{"batb":[[0,2.3,23.77]],"ltp":2.5,"tv":19081.22,"id":72857116}]}]}
{"op":"mcm","clk":"11917306770","pt":1724086174887,"mc":[{"id":"1.232011680","rc":[{"batb":[[0,1.57,36.31],[1,1.39,3.58],[2,1.33,145.46]],"ltp":1.61,"tv":52192.95,"id":72857114},{"trd":[[2.5,3664.21]],"batb":[[0,2.3,13.77]],"ltp":2.5,"tv":19689.76,"id":72857116}],"tv":71882.71}]}
{"op":"mcm","clk":"11917306801","pt":1724086175198,"mc":[{"id":"1.232011680","rc":[{"batb":[[0,2.28,48.11],[1,1.33,151.52],[2,1.23,434.78]],"ltp":2.5,"tv":19689.76,"id":72857116}]}]}
{"op":"mcm","clk":"11917307589","pt":1724086182493,"mc":[{"id":"1.232011680","rc":[{"batb":[[0,1.58,6.58],[1,1.57,35.82],[2,1.39,3.58]],"ltp":1.61,"tv":52192.95,"id":72857114}]}]}
{"op":"mcm","clk":"11917307824","pt":1724086184829,"mc":[{"id":"1.232011680","rc":[{"batb":[[1,1.57,67.23]],"ltp":1.61,"tv":52192.95,"id":72857114},{"batb":[[0,2.3,10],[1,2.28,48.11],[2,1.33,151.52]],"batl":[[0,2.5,304.27]],"ltp":2.5,"tv":19689.76,"id":72857116}]}]}
{"op":"mcm","clk":"11917307927","pt":1724086185808,"mc":[{"id":"1.232011680","rc":[{"trd":[[2.5,4272.75]],"ltp":2.5,"tv":20298.29,"id":72857116}],"tv":72491.25}]}
{"op":"mcm","clk":"11917308047","pt":1724086187215,"mc":[{"id":"1.232011680","rc":[{"batb":[[0,2.3,23.77]],"ltp":2.5,"tv":20298.29,"id":72857116}]}]}
{"op":"mcm","clk":"11917308233","pt":1724086188806,"mc":[{"id":"1.232011680","rc":[{"batb":[[0,2.28,48.11],[1,1.33,151.52],[2,1.23,434.78]],"ltp":2.5,"tv":20298.29,"id":72857116}]}]}
{"op":"mcm","clk":"11917308812","pt":1724086194536,"mc":[{"id":"1.232011680","rc":[{"batl":[[0,1.73,7.7],[1,1.75,3.06],[2,1.8,358.53]],"ltp":1.61,"tv":52192.95,"id":72857114}]}]}
{"op":"mcm","clk":"11917309341","pt":1724086199446,"mc":[{"id":"1.232011680","rc":[{"batb":[[0,1.6,1.44],[1,1.58,6.09],[2,1.57,67.23]],"ltp":1.61,"tv":52192.95,"id":72857114}]}]}
{"op":"mcm","clk":"11917310110","pt":1724086206526,"mc":[{"id":"1.232011680","rc":[{"batb":[[0,2.3,10],[1,2.28,48.11],[2,1.33,151.52]],"batl":[[0,2.5,304.27]],"ltp":2.5,"tv":20298.29,"id":72857116}]}]}
{"op":"mcm","clk":"11917310319","pt":1724086208239,"mc":[{"id":"1.232011680","rc":[{"batb":[[0,1.65,27.55],[1,1.6,1.44],[2,1.58,6.09]],"ltp":1.61,"tv":52192.95,"id":72857114},{"batb":[[0,2.3,23.77]],"ltp":2.5,"tv":20298.29,"id":72857116}]}]}
{"op":"mcm","clk":"11917310483","pt":1724086209841,"mc":[{"id":"1.232011680","rc":[{"trd":[[1.66,1875.66]],"ltp":1.66,"tv":52196.89,"id":72857114},{"trd":[[2.5,4275.37]],"batb":[[0,2.3,13.77]],"batl":[[0,2.5,301.65]],"ltp":2.5,"tv":20300.91,"id":72857116}],"tv":72497.81}]}
{"op":"mcm","clk":"11917310577","pt":1724086210619,"mc":[{"id":"1.232011680","rc":[{"batb":[[0,1.6,1.44],[1,1.58,6.09],[2,1.57,67.23]],"batl":[[0,1.65,3.48],[1,1.73,7.7],[2,1.75,3.06]],"ltp":1.66,"tv":52196.89,"id":72857114},{"trd":[[2.5,4878.66]],"batb":[[0,2.5,2.62]],"ltp":2.5,"tv":20904.21,"id":72857116}],"tv":73101.1}]}
{"op":"mcm","clk":"11917310716","pt":1724086211850,"mc":[{"id":"1.232011680","rc":[{"batl":[[1,1.73,8.65]],"ltp":1.66,"tv":52196.89,"id":72857114}]}]}
{"op":"mcm","clk":"11917311888","pt":1724086222722,"mc":[{"id":"1.232011680","rc":[{"trd":[[1.6,18],[1.61,16.38]],"batb":[[0,1.6,3.75],[1,1.57,35.82],[2,1.39,3.58]],"ltp":1.6,"tv":52205.15,"id":72857114},{"batb":[[0,2.28,48.11],[1,1.33,151.52],[2,1.23,434.78]],"ltp":2.5,"tv":20904.21,"id":72857116}],"tv":73109.36}]}
{"op":"mcm","clk":"11917312175","pt":1724086225255,"mc":[{"id":"1.232011680","rc":[{"batb":[[1,1.57,67.23]],"ltp":1.6,"tv":52205.15,"id":72857114}]}]}
{"op":"mcm","clk":"11917312556","pt":1724086228561,"mc":[{"id":"1.232011680","rc":[{"trd":[[1.65,13682.02]],"batl":[[0,1.65,3.44]],"ltp":1.65,"tv":52205.19,"id":72857114},{"trd":[[2.52,1203.62]],"ltp":2.52,"tv":20904.23,"id":72857116}],"tv":73109.43}]}
{"op":"mcm","clk":"11917315509","pt":1724086255864,"mc":[{"id":"1.232011680","rc":[{"batl":[[1,1.73,7.7]],"ltp":1.65,"tv":52205.19,"id":72857114}]}]}
{"op":"mcm","clk":"11917317831","pt":1724086278466,"mc":[{"id":"1.232011680","rc":[{"batl":[[0,1.64,1.49],[1,1.65,3.44],[2,1.73,7.7]],"ltp":1.65,"tv":52205.19,"id":72857114}]}]}
{"op":"mcm","clk":"11917318511","pt":1724086284614,"mc":[{"id":"1.232011680","rc":[{"batb":[[2,1.4,170.53]],"ltp":1.65,"tv":52205.19,"id":72857114},{"batb":[[0,2.3,14],[1,2.28,48.11],[2,1.33,151.52]],"batl":[[0,3,74.65]],"ltp":2.52,"tv":20904.23,"id":72857116}]}]}
{"op":"mcm","clk":"11917318766","pt":1724086286788,"mc":[{"id":"1.232011680","rc":[{"batb":[[0,2.3,23.77]],"ltp":2.52,"tv":20904.23,"id":72857116}]}]}
{"op":"mcm","clk":"11917318921","pt":1724086288281,"mc":[{"id":"1.232011680","rc":[{"batb":[[0,2.28,48.11],[1,1.33,151.52],[2,1.23,434.78]],"ltp":2.52,"tv":20904.23,"id":72857116}]}]}
{"op":"mcm","clk":"11917319139","pt":1724086290191,"mc":[{"id":"1.232011680","rc":[{"batl":[[0,1.65,4.92],[1,1.73,7.7],[2,1.75,3.06]],"ltp":1.65,"tv":52205.19,"id":72857114},{"batb":[[0,2.3,14],[1,2.28,48.11],[2,1.33,151.52]],"ltp":2.52,"tv":20904.23,"id":72857116}]}]}
{"op":"mcm","clk":"11917319351","pt":1724086292304,"mc":[{"id":"1.232011680","rc":[{"batb":[[0,2.3,27.77]],"ltp":2.52,"tv":20904.23,"id":72857116}]}]}
{"op":"mcm","clk":"11917319584","pt":1724086294264,"mc":[{"id":"1.232011680","rc":[{"batb":[[0,2.3,23.77]],"ltp":2.52,"tv":20904.23,"id":72857116}]}]}
{"op":"mcm","clk":"11917319769","pt":1724086295865,"mc":[{"id":"1.232011680","rc":[{"batb":[[0,2.28,48.11],[1,1.33,151.52],[2,1.23,434.78]],"ltp":2.52,"tv":20904.23,"id":72857116}]}]}
{"op":"mcm","clk":"11917320070","pt":1724086298553,"mc":[{"id":"1.232011680","rc":[{"batl":[[0,1.65,4.92]],"ltp":1.65,"tv":52205.19,"id":72857114},{"batb":[[0,2.3,14],[1,2.28,48.11],[2,1.33,151.52]],"ltp":2.52,"tv":20904.23,"id":72857116}]}]}
{"op":"mcm","clk":"11917320235","pt":1724086300268,"mc":[{"id":"1.232011680","rc":[{"batb":[[0,2.3,27.77]],"ltp":2.52,"tv":20904.23,"id":72857116}]}]}
{"op":"mcm","clk":"11917320307","pt":1724086300943,"mc":[{"id":"1.232011680","rc":[{"batb":[[0,2.3,23.77]],"ltp":2.52,"tv":20904.23,"id":72857116}]}]}
{"op":"mcm","clk":"11917320445","pt":1724086302286,"mc":[{"id":"1.232011680","rc":[{"batb":[[0,2.28,48.11],[1,1.33,151.52],[2,1.23,434.78]],"ltp":2.52,"tv":20904.23,"id":72857116}]}]}
{"op":"mcm","clk":"11917320625","pt":1724086304247,"mc":[{"id":"1.232011680","rc":[{"batb":[[0,2.3,14],[1,2.28,48.11],[2,1.33,151.52]],"ltp":2.52,"tv":20904.23,"id":72857116}]}]}
{"op":"mcm","clk":"11917320812","pt":1724086306259,"mc":[{"id":"1.232011680","rc":[{"batb":[[0,2.3,27.77]],"ltp":2.52,"tv":20904.23,"id":72857116}]}]}
{"op":"mcm","clk":"11917320945","pt":1724086307656,"mc":[{"id":"1.232011680","rc":[{"batb":[[0,2.3,13.77]],"ltp":2.52,"tv":20904.23,"id":72857116}]}]}
{"op":"mcm","clk":"11917321006","pt":1724086308375,"mc":[{"id":"1.232011680","rc":[{"batb":[[0,2.28,48.11],[1,1.33,151.52],[2,1.23,434.78]],"ltp":2.52,"tv":20904.23,"id":72857116}]}]}
{"op":"mcm","clk":"11917321124","pt":1724086309561,"mc":[{"id":"1.232011680","rc":[{"batb":[[0,2.3,4],[1,2.28,48.11],[2,1.33,151.52]],"ltp":2.52,"tv":20904.23,"id":72857116}]}]}
{"op":"mcm","clk":"11917321316","pt":1724086311753,"mc":[{"id":"1.232011680","rc":[{"batb":[[0,2.28,48.11],[1,1.33,151.52],[2,1.23,434.78]],"ltp":2.52,"tv":20904.23,"id":72857116}]}]}
{"op":"mcm","clk":"11917321337","pt":1724086311959,"mc":[{"id":"1.232011680","rc":[{"batb":[[0,2.3,10],[1,2.28,48.11],[2,1.33,151.52]],"ltp":2.52,"tv":20904.23,"id":72857116}]}]}
{"op":"mcm","clk":"11917321616","pt":1724086314388,"mc":[{"id":"1.232011680","rc":[{"batb":[[0,2.32,4],[1,2.3,23.77],[2,2.28,48.11]],"ltp":2.52,"tv":20904.23,"id":72857116}]}]}
{"op":"mcm","clk":"11917321759","pt":1724086315890,"mc":[{"id":"1.232011680","rc":[{"batb":[[1,2.28,48.11],[2,1.33,151.52]],"ltp":2.52,"tv":20904.23,"id":72857116}]}]}
{"op":"mcm","clk":"11917321833","pt":1724086316661,"mc":[{"id":"1.232011680","rc":[{"batb":[[0,2.28,48.11],[1,1.33,151.52],[2,1.23,434.78]],"ltp":2.52,"tv":20904.23,"id":72857116}]}]}
{"op":"mcm","clk":"11917322086","pt":1724086319183,"mc":[{"id":"1.232011680","rc":[{"batl":[[0,1.65,1.48]],"ltp":1.65,"tv":52205.19,"id":72857114},{"batb":[[0,2.3,14],[1,2.28,48.11],[2,1.33,151.52]],"ltp":2.52,"tv":20904.23,"id":72857116}]}]}
{"op":"mcm","clk":"11917322329","pt":1724086321457,"mc":[{"id":"1.232011680","rc":[{"batb":[[0,2.3,23.77]],"ltp":2.52,"tv":20904.23,"id":72857116}]}]}
{"op":"mcm","clk":"11917322466","pt":1724086322798,"mc":[{"id":"1.232011680","rc":[{"batb":[[0,2.28,48.11],[1,1.33,151.52],[2,1.23,434.78]],"ltp":2.52,"tv":20904.23,"id":72857116}]}]}
{"op":"mcm","clk":"11917323177","pt":1724086329887,"mc":[{"id":"1.232011680","rc":[{"trd":[[1.6,24.88]],"batb":[[0,1.57,36.13],[1,1.4,170.53],[2,1.39,3.58]],"ltp":1.6,"tv":52212.07,"id":72857114},{"batb":[[0,2.3,14],[1,2.28,48.11],[2,1.33,151.52]],"ltp":2.52,"tv":20904.23,"id":72857116}],"tv":73116.31}]}
{"op":"mcm","clk":"11917323219","pt":1724086330299,"mc":[{"id":"1.232011680","rc":[{"batb":[[1,1.5,35.81],[2,1.4,170.53]],"ltp":1.6,"tv":52212.07,"id":72857114}]}]}
{"op":"mcm","clk":"11917323376","pt":1724086331801,"mc":[{"id":"1.232011680","rc":[{"batb":[[0,2.3,23.77]],"ltp":2.52,"tv":20904.23,"id":72857116}]}]}
{"op":"mcm","clk":"11917323472","pt":1724086332893,"mc":[{"id":"1.232011680","rc":[{"batb":[[0,2.3,13.77]],"ltp":2.52,"tv":20904.23,"id":72857116}]}]}
{"op":"mcm","clk":"11917323520","pt":1724086333371,"mc":[{"id":"1.232011680","rc":[{"batb":[[0,2.28,48.11],[1,1.33,151.52],[2,1.23,434.78]],"ltp":2.52,"tv":20904.23,"id":72857116}]}]}
{"op":"mcm","clk":"11917324729","pt":1724086345924,"mc":[{"id":"1.232011680","rc":[{"batb":[[1,1.56,10.09],[2,1.5,35.81]],"ltp":1.6,"tv":52212.07,"id":72857114},{"batb":[[0,2.3,14],[1,2.28,48.11],[2,2.26,6.97]],"ltp":2.52,"tv":20904.23,"id":72857116}]}]}
{"op":"mcm","clk":"11917324963","pt":1724086348309,"mc":[{"id":"1.232011680","rc":[{"batb":[[1,1.56,42.06]],"ltp":1.6,"tv":52212.07,"id":72857114},{"batb":[[0,2.3,23.77]],"ltp":2.52,"tv":20904.23,"id":72857116}]}]}
{"op":"mcm","clk":"11917325118","pt":1724086349905,"mc":[{"id":"1.232011680","rc":[{"batb":[[0,2.28,48.11],[1,2.26,6.97],[2,1.33,151.52]],"ltp":2.52,"tv":20904.23,"id":72857116}]}]}
{"op":"mcm","clk":"11917325290","pt":1724086351712,"mc":[{"id":"1.232011680","rc":[{"batb":[[0,2.32,10],[1,2.3,4],[2,2.28,48.11]],"ltp":2.52,"tv":20904.23,"id":72857116}]}]}
{"op":"mcm","clk":"11917325510","pt":1724086353927,"mc":[{"id":"1.232011680","rc":[{"batb":[[1,2.28,48.11],[2,2.26,6.97]],"ltp":2.52,"tv":20904.23,"id":72857116}]}]}
{"op":"mcm","clk":"11917325538","pt":1724086354338,"mc":[{"id":"1.232011680","rc":[{"batb":[[0,2.32,23.57]],"ltp":2.52,"tv":20904.23,"id":72857116}]}]}
{"op":"mcm","clk":"11917325679","pt":1724086355435,"mc":[{"id":"1.232011680","rc":[{"batb":[[0,2.28,48.11],[1,2.26,6.97],[2,1.33,151.52]],"batl":[[0,2.54,296.56],[1,3,74.65]],"ltp":2.52,"tv":20904.23,"id":72857116}]}]}
{"op":"mcm","clk":"11917325868","pt":1724086357412,"mc":[{"id":"1.232011680","rc":[{"batb":[[0,1.63,28.42],[1,1.57,36.13],[2,1.56,42.06]],"ltp":1.6,"tv":52212.07,"id":72857114},{"batb":[[0,2.3,10],[1,2.28,48.11],[2,2.26,6.97]],"ltp":2.52,"tv":20904.23,"id":72857116}]}]}
{"op":"mcm","clk":"11917326071","pt":1724086359521,"mc":[{"id":"1.232011680","rc":[{"trd":[[1.64,958.74]],"ltp":1.64,"tv":52218.7,"id":72857114},{"trd":[[2.54,8.28]],"batb":[[0,2.3,23.77]],"batl":[[0,2.54,292.29]],"ltp":2.54,"tv":20908.51,"id":72857116}],"tv":73127.21}]}
{"op":"mcm","clk":"11917326204","pt":1724086360817,"mc":[{"id":"1.232011680","rc":[{"batb":[[0,2.3,13.77]],"ltp":2.54,"tv":20908.51,"id":72857116}]}]}
{"op":"mcm","clk":"11917326271","pt":1724086361432,"mc":[{"id":"1.232011680","rc":[{"batb":[[0,2.28,48.11],[1,2.26,6.97],[2,1.33,151.52]],"ltp":2.54,"tv":20908.51,"id":72857116}]}]}
{"op":"mcm","clk":"11917326404","pt":1724086362831,"mc":[{"id":"1.232011680","rc":[{"trd":[[2.54,592.85]],"batb":[[0,2.56,4],[1,2.54,4.28],[2,2.28,48.11]],"batl":[[0,3,74.65],[1,3,0]],"ltp":2.54,"tv":21493.09,"id":72857116}],"tv":73711.79}]}
{"op":"mcm","clk":"11917326480","pt":1724086363507,"mc":[{"id":"1.232011680","rc":[{"batb":[[0,1.57,36.13],[1,1.56,42.06],[2,1.5,35.81]],"ltp":1.64,"tv":52218.7,"id":72857114},{"batb":[[0,2.58,10],[1,2.56,4],[2,2.54,4.28]],"ltp":2.54,"tv":21493.09,"id":72857116}]}]}
{"op":"mcm","clk":"11917326699","pt":1724086365835,"mc":[{"id":"1.232011680","rc":[{"batb":[[1,2.54,4.28],[2,2.28,48.11]],"ltp":2.54,"tv":21493.09,"id":72857116}]}]}
{"op":"mcm","clk":"11917326806","pt":1724086366821,"mc":[{"id":"1.232011680","rc":[{"batb":[[0,2.54,15.91],[1,2.28,48.11],[2,2.26,6.97]],"ltp":2.54,"tv":21493.09,"id":72857116}]}]}
{"op":"mcm","clk":"11917326882","pt":1724086367539,"mc":[{"id":"1.232011680","rc":[{"batb":[[0,2.56,4],[1,2.54,4.28],[2,2.28,48.11]],"ltp":2.54,"tv":21493.09,"id":72857116}]}]}
{"op":"mcm","clk":"11917327122","pt":1724086369919,"mc":[{"id":"1.232011680","rc":[{"batb":[[1,1.56,31.97]],"ltp":1.64,"tv":52218.7,"id":72857114},{"batb":[[0,2.58,10],[2,2.36,13.17]],"ltp":2.54,"tv":21493.09,"id":72857116}]}]}
{"op":"mcm","clk":"11917327184","pt":1724086370436,"mc":[{"id":"1.232011680","rc":[{"batb":[[0,1.59,7.48],[1,1.57,35.82]],"ltp":1.64,"tv":52218.7,"id":72857114}]}]}
{"op":"mcm","clk":"11917327285","pt":1724086371317,"mc":[{"id":"1.232011680","rc":[{"batb":[[1,2.54,15.91]],"ltp":2.54,"tv":21493.09,"id":72857116}]}]}
{"op":"mcm","clk":"11917327408","pt":1724086372753,"mc":[{"id":"1.232011680","rc":[{"batb":[[1,1.57,67.23]],"ltp":1.64,"tv":52218.7,"id":72857114},{"batb":[[0,2.6,4]],"ltp":2.54,"tv":21493.09,"id":72857116}]}]}
{"op":"mcm","clk":"11917327470","pt":1724086373326,"mc":[{"id":"1.232011680","rc":[{"batb":[[1,2.54,4.28]],"ltp":2.54,"tv":21493.09,"id":72857116}]}]}
{"op":"mcm","clk":"11917327647","pt":1724086374934,"mc":[{"id":"1.232011680","rc":[{"batb":[[0,1.59,7.16]],"ltp":1.64,"tv":52218.7,"id":72857114},{"batb":[[0,2.54,4.28],[1,2.28,48.11],[2,1.03,200]],"ltp":2.54,"tv":21493.09,"id":72857116}]}]}
{"op":"mcm","clk":"11917327668","pt":1724086375140,"mc":[{"id":"1.232011680","rc":[{"batb":[[0,2.56,10],[1,2.54,4.28],[2,2.28,48.11]],"ltp":2.54,"tv":21493.09,"id":72857116}]}]}
{"op":"mcm","clk":"11917327905","pt":1724086377461,"mc":[{"id":"1.232011680","rc":[{"batb":[[0,2.58,4],[1,2.56,10],[2,2.54,15.91]],"ltp":2.54,"tv":21493.09,"id":72857116}]}]}
{"op":"mcm","clk":"11917328079","pt":1724086378859,"mc":[{"id":"1.232011680","rc":[{"batb":[[1,2.54,4.28],[2,2.28,48.11]],"ltp":2.54,"tv":21493.09,"id":72857116}]}]}
{"op":"mcm","clk":"11917328190","pt":1724086379841,"mc":[{"id":"1.232011680","rc":[{"batb":[[0,2.54,4.28],[1,2.36,13.17]],"ltp":2.54,"tv":21493.09,"id":72857116}]}]}
{"op":"mcm","clk":"11917328285","pt":1724086380830,"mc":[{"id":"1.232011680","rc":[{"batb":[[1,2.28,48.11],[2,1.03,200]],"batl":[[0,2.56,7.16],[1,3,74.65]],"ltp":2.54,"tv":21493.09,"id":72857116}]}]}
{"op":"mcm","clk":"11917329617","pt":1724086392471,"mc":[{"id":"1.232011680","rc":[{"trd":[[1.65,13691.55]],"batb":[[0,1.65,135.79],[1,1.59,7.16],[2,1.57,67.23]],"batl":[[0,1.73,7.7],[1,1.75,3.06],[2,1.8,358.53]],"ltp":1.65,"tv":52228.23,"id":72857114},{"trd":[[2.54,597.13]],"batb":[[0,2.3,10]],"ltp":2.54,"tv":21497.36,"id":72857116}],"tv":73725.6}]}
{"op":"mcm","clk":"11917329844","pt":1724086394331,"mc":[{"id":"1.232011680","rc":[{"batb":[[1,1.64,27.98],[2,1.59,7.16]],"ltp":1.65,"tv":52228.23,"id":72857114},{"batb":[[0,2.3,23.77]],"ltp":2.54,"tv":21497.36,"id":72857116}]}]}
{"op":"mcm","clk":"11917330020","pt":1724086395836,"mc":[{"id":"1.232011680","rc":[{"batb":[[0,2.3,13.77]],"ltp":2.54,"tv":21497.36,"id":72857116}]}]}
{"op":"mcm","clk":"11917330096","pt":1724086396460,"mc":[{"id":"1.232011680","rc":[{"batb":[[0,2.28,48.11],[1,1.03,200],[2,1.02,294.75]],"ltp":2.54,"tv":21497.36,"id":72857116}]}]}
{"op":"mcm","clk":"11917330397","pt":1724086398949,"mc":[{"id":"1.232011680","rc":[{"batb":[[0,2.3,10],[1,2.28,48.11],[2,1.03,200]],"ltp":2.54,"tv":21497.36,"id":72857116}]}]}
{"op":"mcm","clk":"11917330674","pt":1724086401386,"mc":[{"id":"1.232011680","rc":[{"batb":[[0,2.3,23.77]],"ltp":2.54,"tv":21497.36,"id":72857116}]}]}
{"op":"mcm","clk":"11917330848","pt":1724086402889,"mc":[{"id":"1.232011680","rc":[{"batb":[[0,2.28,48.11],[1,1.03,200],[2,1.02,294.75]],"ltp":2.54,"tv":21497.36,"id":72857116}]}]}
{"op":"mcm","clk":"11917330951","pt":1724086403871,"mc":[{"id":"1.232011680","rc":[{"batl":[[0,2.56,7.34]],"ltp":2.54,"tv":21497.36,"id":72857116}]}]}
{"op":"mcm","clk":"11917330988","pt":1724086404182,"mc":[{"id":"1.232011680","rc":[{"batb":[[1,1.49,85.27],[2,1.03,200]],"ltp":2.54,"tv":21497.36,"id":72857116}]}]}
{"op":"mcm","clk":"11917331131","pt":1724086405371,"mc":[{"id":"1.232011680","rc":[{"batb":[[0,2.3,10],[1,2.28,48.11],[2,1.56,85.27]],"ltp":2.54,"tv":21497.36,"id":72857116}]}]}
{"op":"mcm","clk":"11917331402","pt":1724086407339,"mc":[{"id":"1.232011680","rc":[{"batb":[[0,2.3,23.77],[2,1.6,85.27]],"ltp":2.54,"tv":21497.36,"id":72857116}]}]}
{"op":"mcm","clk":"11917331623","pt":1724086408661,"mc":[{"id":"1.232011680","rc":[{"batb":[[0,2.3,13.77],[2,1.67,85.27]],"ltp":2.54,"tv":21497.36,"id":72857116}]}]}
{"op":"mcm","clk":"11917331778","pt":1724086409854,"mc":[{"id":"1.232011680","rc":[{"batb":[[0,2.28,48.11],[1,1.77,85.27],[2,1.71,85.27]],"ltp":2.54,"tv":21497.36,"id":72857116}]}]}
{"op":"mcm","clk":"11917332305","pt":1724086414879,"mc":[{"id":"1.232011680","rc":[{"batb":[[0,1.64,27.98],[1,1.59,7.16],[2,1.57,67.23]],"ltp":1.65,"tv":52228.23,"id":72857114}]}]}
{"op":"mcm","clk":"11917332375","pt":1724086415453,"mc":[{"id":"1.232011680","rc":[{"batb":[[0,1.59,7.16],[1,1.57,67.23],[2,1.5,35.81]],"ltp":1.65,"tv":52228.23,"id":72857114},{"batb":[[0,2.3,10],[1,2.28,48.11],[2,1.77,85.27]],"ltp":2.54,"tv":21497.36,"id":72857116}]}]}
{"op":"mcm","clk":"11917332570","pt":1724086417368,"mc":[{"id":"1.232011680","rc":[{"batb":[[0,2.3,23.77]],"ltp":2.54,"tv":21497.36,"id":72857116}]}]}
{"op":"mcm","clk":"11917332722","pt":1724086418871,"mc":[{"id":"1.232011680","rc":[{"batb":[[0,2.28,48.11],[1,1.77,85.27],[2,1.71,85.27]],"ltp":2.54,"tv":21497.36,"id":72857116}]}]}
{"op":"mcm","clk":"11917332759","pt":1724086419184,"mc":[{"id":"1.232011680","rc":[{"batl":[[0,2.52,296.56],[1,2.56,7.34],[2,3,74.65]],"ltp":2.54,"tv":21497.36,"id":72857116}]}]}
{"op":"mcm","clk":"11917333006","pt":1724086421469,"mc":[{"id":"1.232011680","rc":[{"batb":[[0,1.64,27.98],[1,1.59,7.16],[2,1.57,67.23]],"ltp":1.65,"tv":52228.23,"id":72857114},{"batb":[[0,2.3,10],[1,2.28,48.11],[2,1.77,85.27]],"ltp":2.54,"tv":21497.36,"id":72857116}]}]}
{"op":"mcm","clk":"11917333278","pt":1724086423795,"mc":[{"id":"1.232011680","rc":[{"batb":[[0,2.3,23.77]],"ltp":2.54,"tv":21497.36,"id":72857116}]}]}
{"op":"mcm","clk":"11917333390","pt":1724086424877,"mc":[{"id":"1.232011680","rc":[{"batb":[[0,1.59,7.16],[1,1.57,67.23],[2,1.5,35.81]],"ltp":1.65,"tv":52228.23,"id":72857114},{"trd":[[2.52,1796.75]],"batb":[[0,2.28,48.11],[1,1.77,85.27],[2,1.71,85.27]],"batl":[[0,2.56,7.34],[1,3,74.65],[2,3,0]],"ltp":2.52,"tv":22090.49,"id":72857116}],"tv":74318.73}]}
{"op":"mcm","clk":"11917333824","pt":1724086429221,"mc":[{"id":"1.232011680","rc":[{"batb":[[0,2.3,10],[1,2.28,48.11],[2,1.77,85.27]],"ltp":2.52,"tv":22090.49,"id":72857116}]}]}
{"op":"mcm","clk":"11917334069","pt":1724086431382,"mc":[{"id":"1.232011680","rc":[{"batb":[[0,2.3,23.77]],"ltp":2.52,"tv":22090.49,"id":72857116}]}]}
{"op":"mcm","clk":"11917334241","pt":1724086432875,"mc":[{"id":"1.232011680","rc":[{"batb":[[0,2.3,13.77]],"ltp":2.52,"tv":22090.49,"id":72857116}]}]}
{"op":"mcm","clk":"11917334319","pt":1724086433495,"mc":[{"id":"1.232011680","rc":[{"batb":[[0,2.28,48.11],[1,1.77,85.27],[2,1.71,85.27]],"ltp":2.52,"tv":22090.49,"id":72857116}]}]}
{"op":"mcm","clk":"11917334447","pt":1724086434782,"mc":[{"id":"1.232011680","rc":[{"batb":[[0,1.67,143.27],[1,1.59,7.16],[2,1.57,67.23]],"ltp":1.65,"tv":52228.23,"id":72857114}]}]}
{"op":"mcm","clk":"11917334690","pt":1724086436905,"mc":[{"id":"1.232011680","rc":[{"trd":[[1.67,214.05]],"batb":[[0,1.67,139.72]],"ltp":1.67,"tv":52235.33,"id":72857114}],"tv":74325.83}]}
{"op":"mcm","clk":"11917334768","pt":1724086437579,"mc":[{"id":"1.232011680","rc":[{"trd":[[1.73,932.32]],"batb":[[1,1.66,27.13],[2,1.59,7.16]],"batl":[[0,1.73,4.27]],"ltp":1.73,"tv":52242.2,"id":72857114},{"batb":[[0,2.3,10],[1,2.28,48.11],[2,1.77,85.27]],"ltp":2.52,"tv":22090.49,"id":72857116}],"tv":74332.7}]}
{"op":"mcm","clk":"11917335002","pt":1724086440212,"mc":[{"id":"1.232011680","rc":[{"batb":[[0,2.28,48.11],[1,1.77,85.27],[2,1.71,85.27]],"ltp":2.52,"tv":22090.49,"id":72857116}]}]}
{"op":"mcm","clk":"11917335197","pt":1724086441727,"mc":[{"id":"1.232011680","rc":[{"batb":[[0,1.68,4],[1,1.67,143.72],[2,1.66,27.13]],"ltp":1.73,"tv":52242.2,"id":72857114}]}]}
{"op":"mcm","clk":"11917335304","pt":1724086442509,"mc":[{"id":"1.232011680","rc":[{"batb":[[1,1.67,170.44]],"ltp":1.73,"tv":52242.2,"id":72857114},{"batb":[[0,2.3,10],[1,2.28,48.11],[2,1.77,85.27]],"ltp":2.52,"tv":22090.49,"id":72857116}]}]}
{"op":"mcm","clk":"11917335707","pt":1724086445891,"mc":[{"id":"1.232011680","rc":[{"batb":[[0,2.28,48.11],[1,1.77,85.27],[2,1.71,85.27]],"ltp":2.52,"tv":22090.49,"id":72857116}]}]}
{"op":"mcm","clk":"11917336104","pt":1724086449918,"mc":[{"id":"1.232011680","rc":[{"batb":[[0,2.3,10],[1,2.28,48.11],[2,1.77,85.27]],"ltp":2.52,"tv":22090.49,"id":72857116}]}]}
{"op":"mcm","clk":"11917336452","pt":1724086453317,"mc":[{"id":"1.232011680","rc":[{"batb":[[0,2.28,48.11],[1,1.77,85.27],[2,1.71,85.27]],"ltp":2.52,"tv":22090.49,"id":72857116}]}]}
{"op":"mcm","clk":"11917336841","pt":1724086456942,"mc":[{"id":"1.232011680","rc":[{"batl":[[0,2.48,4],[1,2.56,7.34],[2,3,74.65]],"ltp":2.52,"tv":22090.49,"id":72857116}]}]}
{"op":"mcm","clk":"11917336935","pt":1724086457719,"mc":[{"id":"1.232011680","rc":[{"batb":[[0,2.3,10],[1,2.28,48.11],[2,1.77,85.27]],"batl":[[0,2.42,308.12],[1,2.48,4],[2,2.56,7.34]],"ltp":2.52,"tv":22090.49,"id":72857116}]}]}
{"op":"mcm","clk":"11917337257","pt":1724086460415,"mc":[{"id":"1.232011680","rc":[{"batb":[[0,1.69,25.95],[1,1.68,4],[2,1.67,170.44]],"ltp":1.73,"tv":52242.2,"id":72857114},{"batb":[[0,2.28,48.11],[1,1.77,85.27],[2,1.71,85.27]],"ltp":2.52,"tv":22090.49,"id":72857116}]}]}
{"op":"mcm","clk":"11917337392","pt":1724086461653,"mc":[{"id":"1.232011680","rc":[{"batb":[[0,1.68,4],[1,1.67,170.44],[2,1.66,27.13]],"ltp":1.73,"tv":52242.2,"id":72857114},{"trd":[[2.42,616.24]],"batl":[[0,2.48,4],[1,2.56,7.34],[2,3,74.65]],"ltp":2.42,"tv":22706.73,"id":72857116}],"tv":74948.94}]}
{"op":"mcm","clk":"11917337765","pt":1724086464918,"mc":[{"id":"1.232011680","rc":[{"batl":[[1,3,74.83],[2,3,0]],"ltp":2.42,"tv":22706.73,"id":72857116}]}]}
{"op":"mcm","clk":"11917337779","pt":1724086465023,"mc":[{"id":"1.232011680","rc":[{"trd":[[1.73,936.59]],"batl":[[0,1.75,3.06],[1,1.8,358.53],[2,1.83,7.7]],"ltp":1.73,"tv":52246.47,"id":72857114},{"trd":[[2.36,3.13]],"batb":[[0,2.3,10],[1,2.28,48.11],[2,1.77,85.27]],"batl":[[0,2.36,4.04],[1,2.48,4],[2,3,74.83]],"ltp":2.36,"tv":22709.86,"id":72857116}],"tv":74956.33}]}
{"op":"mcm","clk":"11917338097","pt":1724086468425,"mc":[{"id":"1.232011680","rc":[{"batb":[[0,2.28,48.11],[1,1.77,85.27],[2,1.71,85.27]],"batl":[[1,2.42,308.12],[2,2.48,4]],"ltp":2.36,"tv":22709.86,"id":72857116}]}]}
{"op":"mcm","clk":"11917338305","pt":1724086470442,"mc":[{"id":"1.232011680","rc":[{"batb":[[0,1.7,25.58],[1,1.68,4],[2,1.67,170.44]],"ltp":1.73,"tv":52246.47,"id":72857114}]}]}
{"op":"mcm","clk":"11917339276","pt":1724086479919,"mc":[{"id":"1.232011680","rc":[{"batb":[[0,1.68,4],[1,1.67,170.44],[2,1.66,27.13]],"ltp":1.73,"tv":52246.47,"id":72857114},{"trd":[[2.42,1232.48]],"batb":[[0,2.3,10],[1,2.28,48.11],[2,1.77,85.27]],"batl":[[0,2.48,4],[1,3,74.83],[2,2.48,0]],"ltp":2.42,"tv":23326.09,"id":72857116}],"tv":75572.57}]}
{"op":"mcm","clk":"11917339326","pt":1724086480436,"mc":[{"id":"1.232011680","rc":[{"batl":[[0,2.36,1.82],[1,2.48,4],[2,3,74.83]],"ltp":2.42,"tv":23326.09,"id":72857116}]}]}
{"op":"mcm","clk":"11917339599","pt":1724086482962,"mc":[{"id":"1.232011680","rc":[{"batb":[[0,2.28,48.11],[1,1.77,85.27],[2,1.71,85.27]],"ltp":2.42,"tv":23326.09,"id":72857116}]}]}
{"op":"mcm","clk":"11917340196","pt":1724086488880,"mc":[{"id":"1.232011680","rc":[{"batb":[[1,1.67,30.72]],"ltp":1.73,"tv":52246.47,"id":72857114}]}]}
{"op":"mcm","clk":"11917340254","pt":1724086489453,"mc":[{"id":"1.232011680","rc":[{"batb":[[0,1.59,7.16],[1,1.57,67.23],[2,1.42,170.53]],"ltp":1.73,"tv":52246.47,"id":72857114},{"batl":[[1,3,74.83],[2,3,0]],"ltp":2.42,"tv":23326.09,"id":72857116}]}]}
{"op":"mcm","clk":"11917340827","pt":1724086494674,"mc":[{"id":"1.232011680","rc":[{"trd":[[1.73,939.07]],"batl":[[0,1.75,3.08]],"ltp":1.73,"tv":52248.95,"id":72857114},{"trd":[[2.36,4.95]],"batb":[[0,2.3,14],[1,2.28,48.11],[2,1.77,85.27]],"batl":[[0,3,74.83],[1,3,0]],"ltp":2.36,"tv":23327.91,"id":72857116}],"tv":75576.87}]}
{"op":"mcm","clk":"11917341046","pt":1724086496850,"mc":[{"id":"1.232011680","rc":[{"batb":[[0,2.3,10]],"ltp":2.36,"tv":23327.91,"id":72857116}]}]}
{"op":"mcm","clk":"11917341153","pt":1724086497873,"mc":[{"id":"1.232011680","rc":[{"batb":[[0,2.28,48.11],[1,1.77,85.27],[2,1.71,85.27]],"ltp":2.36,"tv":23327.91,"id":72857116}]}]}
{"op":"mcm","clk":"11917341455","pt":1724086500690,"mc":[{"id":"1.232011680","rc":[{"batb":[[0,1.69,125.36],[1,1.59,7.16],[2,1.57,67.23]],"ltp":1.73,"tv":52248.95,"id":72857114},{"batb":[[0,2.3,14],[1,2.28,48.11],[2,1.77,85.27]],"ltp":2.36,"tv":23327.91,"id":72857116}]}]}
{"op":"mcm","clk":"11917341708","pt":1724086502594,"mc":[{"id":"1.232011680","rc":[{"batb":[[0,1.7,4],[1,1.69,129.36],[2,1.68,26.33]],"ltp":1.73,"tv":52248.95,"id":72857114}]}]}
{"op":"mcm","clk":"11917341881","pt":1724086503895,"mc":[{"id":"1.232011680","rc":[{"batb":[[1,1.69,155.31]],"ltp":1.73,"tv":52248.95,"id":72857114},{"batb":[[0,2.28,48.11],[1,1.77,85.27],[2,1.71,85.27]],"ltp":2.36,"tv":23327.91,"id":72857116}]}]}
{"op":"mcm","clk":"11917342269","pt":1724086506864,"mc":[{"id":"1.232011680","rc":[{"batb":[[0,1.71,125.36],[1,1.7,4],[2,1.69,29.95]],"ltp":1.73,"tv":52248.95,"id":72857114},{"batb":[[0,2.3,14],[1,2.28,48.11],[2,1.77,85.27]],"ltp":2.36,"tv":23327.91,"id":72857116}]}]}
{"op":"mcm","clk":"11917342339","pt":1724086507489,"mc":[{"id":"1.232011680","rc":[{"batb":[[2,1.69,4]],"ltp":1.73,"tv":52248.95,"id":72857114}]}]}
{"op":"mcm","clk":"11917342525","pt":1724086508897,"mc":[{"id":"1.232011680","rc":[{"batb":[[0,2.3,10]],"ltp":2.36,"tv":23327.91,"id":72857116}]}]}
{"op":"mcm","clk":"11917342588","pt":1724086509365,"mc":[{"id":"1.232011680","rc":[{"batb":[[1,1.7,29.58]],"ltp":1.73,"tv":52248.95,"id":72857114}]}]}
{"op":"mcm","clk":"11917342659","pt":1724086510089,"mc":[{"id":"1.232011680","rc":[{"batb":[[0,2.28,48.11],[1,1.77,85.27],[2,1.71,85.27]],"ltp":2.36,"tv":23327.91,"id":72857116}]}]}
{"op":"mcm","clk":"11917343190","pt":1724086514766,"mc":[{"id":"1.232011680","rc":[{"batb":[[0,2.3,14],[1,2.28,48.11],[2,1.77,85.27]],"ltp":2.36,"tv":23327.91,"id":72857116}]}]}
{"op":"mcm","clk":"11917343356","pt":1724086515922,"mc":[{"id":"1.232011680","rc":[{"batl":[[0,1.8,358.55],[1,1.83,7.7],[2,2.2,5.17]],"ltp":1.73,"tv":52248.95,"id":72857114}]}]}
{"op":"mcm","clk":"11917343569","pt":1724086517676,"mc":[{"id":"1.232011680","rc":[{"batb":[[0,1.72,4],[1,1.71,129.36],[2,1.7,29.58]],"batl":[[0,1.77,4.02],[1,1.8,358.53],[2,1.83,7.7]],"ltp":1.73,"tv":52248.95,"id":72857114},{"batl":[[0,2.42,4],[1,3,74.83]],"ltp":2.36,"tv":23327.91,"id":72857116}]}]}
{"op":"mcm","clk":"11917343724","pt":1724086518717,"mc":[{"id":"1.232011680","rc":[{"batb":[[1,1.71,154.58]],"batl":[[0,1.8,358.55],[1,1.83,7.7],[2,2.2,5.17]],"ltp":1.73,"tv":52248.95,"id":72857114},{"batb":[[0,2.3,4]],"ltp":2.36,"tv":23327.91,"id":72857116}]}]}
{"op":"mcm","clk":"11917344011","pt":1724086520579,"mc":[{"id":"1.232011680","rc":[{"batl":[[0,1.8,358.53]],"ltp":1.73,"tv":52248.95,"id":72857114},{"batb":[[0,2.32,10],[1,2.3,4],[2,2.28,48.11]],"ltp":2.36,"tv":23327.91,"id":72857116}]}]}
{"op":"mcm","clk":"11917344579","pt":1724086524897,"mc":[{"id":"1.232011680","rc":[{"trd":[[1.72,18.37]],"batb":[[0,1.71,154.58],[1,1.7,29.58],[2,1.69,4]],"batl":[[0,1.8,358.77]],"ltp":1.72,"tv":52256.95,"id":72857114},{"batb":[[0,2.3,4],[1,2.28,48.11],[2,1.77,85.27]],"ltp":2.36,"tv":23327.91,"id":72857116}],"tv":75584.87}]}
{"op":"mcm","clk":"11917344662","pt":1724086525578,"mc":[{"id":"1.232011680","rc":[{"trd":[[1.72,18.86]],"batb":[[0,1.74,125.12],[1,1.71,29.22],[2,1.7,29.58]],"batl":[[0,1.8,358.53]],"ltp":1.72,"tv":52257.44,"id":72857114}],"tv":75585.36}]}
{"op":"mcm","clk":"11917344904","pt":1724086527595,"mc":[{"id":"1.232011680","rc":[{"batb":[[1,1.73,24.53],[2,1.71,29.22]],"ltp":1.72,"tv":52257.44,"id":72857114},{"batb":[[0,2.32,10],[1,2.3,4],[2,2.28,48.11]],"ltp":2.36,"tv":23327.91,"id":72857116}]}]}
{"op":"mcm","clk":"11917345244","pt":1724086530814,"mc":[{"id":"1.232011680","rc":[{"batb":[[0,2.3,4],[1,2.28,48.11],[2,1.77,85.27]],"ltp":2.36,"tv":23327.91,"id":72857116}]}]}
{"op":"mcm","clk":"11917345374","pt":1724086531789,"mc":[{"id":"1.232011680","rc":[{"trd":[[1.74,17.36]],"batb":[[0,1.74,117.16]],"ltp":1.74,"tv":52273.35,"id":72857114}],"tv":75601.27}]}
{"op":"mcm","clk":"11917345497","pt":1724086532777,"mc":[{"id":"1.232011680","rc":[{"batb":[[0,1.74,121.16]],"ltp":1.74,"tv":52273.35,"id":72857114},{"batl":[[0,2.36,4],[1,2.42,4],[2,3,74.83]],"ltp":2.36,"tv":23327.91,"id":72857116}]}]}
{"op":"mcm","clk":"11917346572","pt":1724086541908,"mc":[{"id":"1.232011680","rc":[{"batl":[[0,2.34,308.12],[1,2.36,4],[2,2.42,4]],"ltp":2.36,"tv":23327.91,"id":72857116}]}]}
{"op":"mcm","clk":"11917346828","pt":1724086544130,"mc":[{"id":"1.232011680","rc":[{"batb":[[0,1.74,123.64]],"ltp":1.74,"tv":52273.35,"id":72857114}]}]}
{"op":"mcm","clk":"11917347041","pt":1724086545734,"mc":[{"id":"1.232011680","rc":[{"trd":[[2.34,616.24]],"batl":[[0,2.36,4],[1,2.42,4],[2,3,74.83]],"ltp":2.34,"tv":23944.15,"id":72857116}],"tv":76217.51}]}
{"op":"mcm","clk":"11917347776","pt":1724086552222,"mc":[{"id":"1.232011680","rc":[{"batl":[[0,2.34,308.12],[1,2.36,4],[2,2.42,4]],"ltp":2.34,"tv":23944.15,"id":72857116}]}]}
{"op":"mcm","clk":"11917347867","pt":1724086553048,"mc":[{"id":"1.232011680","rc":[{"batb":[[0,1.74,6.48]],"ltp":1.74,"tv":52273.35,"id":72857114}]}]}
{"op":"mcm","clk":"11917348100","pt":1724086554816,"mc":[{"id":"1.232011680","rc":[{"batb":[[0,1.74,2.48],[2,1.71,25.22]],"ltp":1.74,"tv":52273.35,"id":72857114},{"trd":[[2.34,1232.48]],"batb":[[0,2.32,14],[1,2.3,4],[2,2.28,48.11]],"batl":[[0,3,74.83],[1,2.36,0],[2,2.42,0]],"ltp":2.34,"tv":24560.39,"id":72857116}],"tv":76833.75}]}
{"op":"mcm","clk":"11917348121","pt":1724086555023,"mc":[{"id":"1.232011680","rc":[{"batb":[[1,1.59,7.16],[2,1.57,67.23]],"ltp":1.74,"tv":52273.35,"id":72857114}]}]}
{"op":"mcm","clk":"11917348358","pt":1724086557256,"mc":[{"id":"1.232011680","rc":[{"batb":[[0,2.32,10]],"ltp":2.34,"tv":24560.39,"id":72857116}]}]}
{"op":"mcm","clk":"11917348466","pt":1724086558240,"mc":[{"id":"1.232011680","rc":[{"batb":[[0,2.3,4],[1,2.28,48.11],[2,1.77,85.27]],"ltp":2.34,"tv":24560.39,"id":72857116}]}]}
{"op":"mcm","clk":"11917348711","pt":1724086560455,"mc":[{"id":"1.232011680","rc":[{"batb":[[0,2.32,14],[1,2.3,4],[2,2.28,48.11]],"ltp":2.34,"tv":24560.39,"id":72857116}]}]}
{"op":"mcm","clk":"11917349030","pt":1724086562864,"mc":[{"id":"1.232011680","rc":[{"batb":[[0,2.32,10],[1,2.3,17.77]],"ltp":2.34,"tv":24560.39,"id":72857116}]}]}
{"op":"mcm","clk":"11917349190","pt":1724086563774,"mc":[{"id":"1.232011680","rc":[{"batl":[[0,1.75,4],[1,1.76,4],[2,1.8,358.53]],"ltp":1.74,"tv":52273.35,"id":72857114},{"batb":[[0,2.34,4],[1,2.32,4],[2,2.3,17.77]],"ltp":2.34,"tv":24560.39,"id":72857116}]}]}
{"op":"mcm","clk":"11917349277","pt":1724086564474,"mc":[{"id":"1.232011680","rc":[{"batl":[[0,1.76,4],[1,1.8,358.53],[2,1.83,7.7]],"ltp":1.74,"tv":52273.35,"id":72857114},{"batb":[[0,2.32,4],[1,2.3,4],[2,2.28,48.11]],"ltp":2.34,"tv":24560.39,"id":72857116}]}]}
{"op":"mcm","clk":"11917349380","pt":1724086565252,"mc":[{"id":"1.232011680","rc":[{"batl":[[0,1.8,358.53],[1,1.83,7.7],[2,2.2,5.17]],"ltp":1.74,"tv":52273.35,"id":72857114}]}]}
{"op":"mcm","clk":"11917349558","pt":1724086566555,"mc":[{"id":"1.232011680","rc":[{"batb":[[0,2.34,10],[1,2.32,4],[2,2.3,4]],"ltp":2.34,"tv":24560.39,"id":72857116}]}]}
{"op":"mcm","clk":"11917349713","pt":1724086567847,"mc":[{"id":"1.232011680","rc":[{"batb":[[0,1.59,7.16],[1,1.57,67.23],[2,1.42,170.96]],"ltp":1.74,"tv":52273.35,"id":72857114},{"batb":[[1,2.3,4],[2,2.28,48.11]],"ltp":2.34,"tv":24560.39,"id":72857116}]}]}
{"op":"mcm","clk":"11917349725","pt":1724086567955,"mc":[{"id":"1.232011680","rc":[{"trd":[[2.34,1236.14]],"batb":[[0,2.34,8.17]],"ltp":2.34,"tv":24564.05,"id":72857116}],"tv":76837.41}]}
{"op":"mcm","clk":"11917349948","pt":1724086569864,"mc":[{"id":"1.232011680","rc":[{"batb":[[0,2.3,4],[1,2.28,48.11],[2,1.77,85.27]],"ltp":2.34,"tv":24564.05,"id":72857116}]}]}
{"op":"mcm","clk":"11917350039","pt":1724086570578,"mc":[{"id":"1.232011680","rc":[{"batb":[[0,2.32,4]],"batl":[[0,2.34,308.12],[1,3,74.83]],"ltp":2.34,"tv":24564.05,"id":72857116}]}]}
{"op":"mcm","clk":"11917350268","pt":1724086572454,"mc":[{"id":"1.232011680","rc":[{"batb":[[0,1.73,24.53],[1,1.59,7.16],[2,1.57,67.23]],"ltp":1.74,"tv":52273.35,"id":72857114},{"batb":[[0,2.28,48.11],[1,1.77,85.27],[2,1.71,85.27]],"ltp":2.34,"tv":24564.05,"id":72857116}]}]}
{"op":"mcm","clk":"11917350580","pt":1724086575591,"mc":[{"id":"1.232011680","rc":[{"batb":[[0,1.59,7.16],[1,1.57,67.23],[2,1.42,170.96]],"ltp":1.74,"tv":52273.35,"id":72857114},{"batb":[[0,2.3,14],[1,2.28,48.11],[2,1.77,85.27]],"batl":[[0,3,74.83],[1,3,0]],"ltp":2.34,"tv":24564.05,"id":72857116}]}]}
{"op":"mcm","clk":"11917350678","pt":1724086576478,"mc":[{"id":"1.232011680","rc":[{"batl":[[0,1.74,11.46],[1,1.8,358.53],[2,1.83,7.7]],"ltp":1.74,"tv":52273.35,"id":72857114}]}]}
{"op":"mcm","clk":"11917350785","pt":1724086577458,"mc":[{"id":"1.232011680","rc":[{"batb":[[0,2.3,10]],"ltp":2.34,"tv":24564.05,"id":72857116}]}]}
{"op":"mcm","clk":"11917350899","pt":1724086578491,"mc":[{"id":"1.232011680","rc":[{"batb":[[0,2.3,13.77]],"ltp":2.34,"tv":24564.05,"id":72857116}]}]}
{"op":"mcm","clk":"11917350962","pt":1724086579014,"mc":[{"id":"1.232011680","rc":[{"batb":[[0,2.28,48.11],[1,1.77,85.27],[2,1.71,85.27]],"ltp":2.34,"tv":24564.05,"id":72857116}]}]}
{"op":"mcm","clk":"11917351116","pt":1724086580195,"mc":[{"id":"1.232011680","rc":[{"batb":[[0,2.3,4],[1,2.28,48.11],[2,1.77,85.27]],"ltp":2.34,"tv":24564.05,"id":72857116}]}]}
{"op":"mcm","clk":"11917351266","pt":1724086581388,"mc":[{"id":"1.232011680","rc":[{"batb":[[0,2.32,10],[1,2.3,4],[2,2.28,48.11]],"ltp":2.34,"tv":24564.05,"id":72857116}]}]}
{"op":"mcm","clk":"11917351402","pt":1724086582579,"mc":[{"id":"1.232011680","rc":[{"batb":[[1,2.28,48.11],[2,1.71,85.27]],"ltp":2.34,"tv":24564.05,"id":72857116}]}]}
{"op":"mcm","clk":"11917351500","pt":1724086583599,"mc":[{"id":"1.232011680","rc":[{"batb":[[0,2.32,23.57],[2,1.67,85.27]],"ltp":2.34,"tv":24564.05,"id":72857116}]}]}
{"op":"mcm","clk":"11917351614","pt":1724086584793,"mc":[{"id":"1.232011680","rc":[{"batb":[[0,2.34,4],[1,2.32,13.57],[2,2.28,48.11]],"ltp":2.34,"tv":24564.05,"id":72857116}]}]}
{"op":"mcm","clk":"11917351746","pt":1724086585881,"mc":[{"id":"1.232011680","rc":[{"batb":[[0,1.62,3.06],[1,1.59,7.16],[2,1.57,67.23]],"ltp":1.74,"tv":52273.35,"id":72857114},{"batb":[[1,2.28,48.11],[2,1.67,85.27]],"ltp":2.34,"tv":24564.05,"id":72857116}]}]}
{"op":"mcm","clk":"11917351901","pt":1724086587279,"mc":[{"id":"1.232011680","rc":[{"batb":[[0,2.3,10]],"ltp":2.34,"tv":24564.05,"id":72857116}]}]}
{"op":"mcm","clk":"11917352126","pt":1724086589599,"mc":[{"id":"1.232011680","rc":[{"batb":[[0,2.32,4],[1,2.3,23.77],[2,2.28,48.11]],"ltp":2.34,"tv":24564.05,"id":72857116}]}]}
{"op":"mcm","clk":"11917352235","pt":1724086590681,"mc":[{"id":"1.232011680","rc":[{"batb":[[1,2.3,13.77]],"ltp":2.34,"tv":24564.05,"id":72857116}]}]}
{"op":"mcm","clk":"11917352269","pt":1724086591002,"mc":[{"id":"1.232011680","rc":[{"batb":[[1,2.28,48.11],[2,1.67,85.27]],"ltp":2.34,"tv":24564.05,"id":72857116}]}]}
{"op":"mcm","clk":"11917352368","pt":1724086591973,"mc":[{"id":"1.232011680","rc":[{"batb":[[0,2.28,48.11],[1,1.67,85.27],[2,1.6,85.27]],"ltp":2.34,"tv":24564.05,"id":72857116}]}]}
{"op":"mcm","clk":"11917352614","pt":1724086594596,"mc":[{"id":"1.232011680","rc":[{"batb":[[0,2.3,14],[1,2.28,48.11],[2,1.67,85.27]],"batl":[[0,2.4,308.12],[1,3,74.83]],"ltp":2.34,"tv":24564.05,"id":72857116}]}]}
{"op":"mcm","clk":"11917352799","pt":1724086596603,"mc":[{"id":"1.232011680","rc":[{"batb":[[0,1.7,25.58],[1,1.59,8.11]],"ltp":1.74,"tv":52273.35,"id":72857114},{"batb":[[0,2.3,27.77]],"ltp":2.34,"tv":24564.05,"id":72857116}]}]}
{"op":"mcm","clk":"11917352869","pt":1724086597213,"mc":[{"id":"1.232011680","rc":[{"batb":[[0,2.3,23.77]],"ltp":2.34,"tv":24564.05,"id":72857116}]}]}
{"op":"mcm","clk":"11917352999","pt":1724086598509,"mc":[{"id":"1.232011680","rc":[{"batb":[[0,2.28,48.11],[1,1.67,85.27],[2,1.6,85.27]],"ltp":2.34,"tv":24564.05,"id":72857116}]}]}
{"op":"mcm","clk":"11917353222","pt":1724086600921,"mc":[{"id":"1.232011680","rc":[{"batb":[[1,1.57,68.17],[2,1.42,170.96]],"batl":[[0,1.74,11.42]],"ltp":1.74,"tv":52273.35,"id":72857114},{"trd":[[2.4,616.24]],"batb":[[0,2.3,10],[1,2.28,48.11],[2,1.67,85.27]],"batl":[[0,3,74.83],[1,3,0]],"ltp":2.4,"tv":25180.29,"id":72857116}],"tv":77453.65}]}
{"op":"mcm","clk":"11917353285","pt":1724086601498,"mc":[{"id":"1.232011680","rc":[{"batb":[[0,1.57,36.76],[1,1.5,36.24],[2,1.42,170.53]],"ltp":1.74,"tv":52273.35,"id":72857114},{"batb":[[0,2.32,4],[1,2.3,10],[2,2.28,48.11]],"ltp":2.4,"tv":25180.29,"id":72857116}]}]}
{"op":"mcm","clk":"11917353393","pt":1724086602780,"mc":[{"id":"1.232011680","rc":[{"batb":[[0,1.63,72.19],[1,1.57,36.76],[2,1.5,36.24]],"ltp":1.74,"tv":52273.35,"id":72857114},{"batb":[[1,2.3,23.77]],"ltp":2.4,"tv":25180.29,"id":72857116}]}]}
{"op":"mcm","clk":"11917353443","pt":1724086603296,"mc":[{"id":"1.232011680","rc":[{"batb":[[0,2.3,23.77],[1,2.28,48.11],[2,1.67,85.27]],"ltp":2.4,"tv":25180.29,"id":72857116}]}]}
{"op":"mcm","clk":"11917353573","pt":1724086604483,"mc":[{"id":"1.232011680","rc":[{"batb":[[1,1.62,29.82],[2,1.57,35.82]],"ltp":1.74,"tv":52273.35,"id":72857114},{"batb":[[0,2.28,48.11],[1,1.67,85.27],[2,1.6,85.27]],"ltp":2.4,"tv":25180.29,"id":72857116}]}]}
{"op":"mcm","clk":"11917353643","pt":1724086605405,"mc":[{"id":"1.232011680","rc":[{"batl":[[0,2.4,308.12],[1,3,74.83]],"ltp":2.4,"tv":25180.29,"id":72857116}]}]}
{"op":"mcm","clk":"11917353727","pt":1724086606594,"mc":[{"id":"1.232011680","rc":[{"batb":[[0,1.63,100.61]],"ltp":1.74,"tv":52273.35,"id":72857114},{"batb":[[0,2.3,10],[1,2.28,48.11],[2,1.67,85.27]],"ltp":2.4,"tv":25180.29,"id":72857116}]}]}
{"op":"mcm","clk":"11917353829","pt":1724086607520,"mc":[{"id":"1.232011680","rc":[{"batb":[[0,1.7,25.58],[1,1.63,100.61],[2,1.62,29.82]],"ltp":1.74,"tv":52273.35,"id":72857114}]}]}
{"op":"mcm","clk":"11917353951","pt":1724086608510,"mc":[{"id":"1.232011680","rc":[{"batb":[[0,1.71,4],[1,1.7,25.58],[2,1.63,100.61]],"ltp":1.74,"tv":52273.35,"id":72857114},{"batb":[[0,2.3,23.77]],"batl":[[0,2.4,312.12]],"ltp":2.4,"tv":25180.29,"id":72857116}]}]}
{"op":"mcm","clk":"11917354030","pt":1724086609395,"mc":[{"id":"1.232011680","rc":[{"trd":[[2.4,1232.48]],"batl":[[0,2.4,4]],"ltp":2.4,"tv":25796.53,"id":72857116}],"tv":78069.89}]}
{"op":"mcm","clk":"11917354146","pt":1724086610518,"mc":[{"id":"1.232011680","rc":[{"batb":[[0,1.63,100.61],[1,1.62,29.82],[2,1.57,35.82]],"ltp":1.74,"tv":52273.35,"id":72857114},{"batb":[[0,2.32,4]],"batl":[[0,3,74.83],[1,3,0]],"ltp":2.4,"tv":25796.53,"id":72857116}]}]}
{"op":"mcm","clk":"11917354272","pt":1724086611914,"mc":[{"id":"1.232011680","rc":[{"batl":[[0,1.74,12.36]],"ltp":1.74,"tv":52273.35,"id":72857114}]}]}
{"op":"mcm","clk":"11917354330","pt":1724086612426,"mc":[{"id":"1.232011680","rc":[{"batb":[[0,2.34,10]],"ltp":2.4,"tv":25796.53,"id":72857116}]}]}
{"op":"mcm","clk":"11917354462","pt":1724086613519,"mc":[{"id":"1.232011680","rc":[{"batb":[[0,1.57,36.76],[1,1.5,36.24],[2,1.42,170.53]],"ltp":1.74,"tv":52273.35,"id":72857114}]}]}
{"op":"mcm","clk":"11917354588","pt":1724086614606,"mc":[{"id":"1.232011680","rc":[{"batb":[[0,2.36,4],[1,2.34,10],[2,2.32,13.57]],"ltp":2.4,"tv":25796.53,"id":72857116}]}]}
{"op":"mcm","clk":"11917354704","pt":1724086615634,"mc":[{"id":"1.232011680","rc":[{"batb":[[1,2.34,13.36]],"ltp":2.4,"tv":25796.53,"id":72857116}]}]}
{"op":"mcm","clk":"11917354831","pt":1724086616928,"mc":[{"id":"1.232011680","rc":[{"batb":[[0,2.28,48.11],[1,1.67,85.27],[2,1.6,85.27]],"ltp":2.4,"tv":25796.53,"id":72857116}]}]}
{"op":"mcm","clk":"11917355005","pt":1724086618524,"mc":[{"id":"1.232011680","rc":[{"batb":[[0,1.62,8.11],[1,1.57,35.82],[2,1.5,36.24]],"ltp":1.74,"tv":52273.35,"id":72857114},{"batb":[[0,2.3,10],[1,2.28,48.11],[2,1.67,85.27]],"ltp":2.4,"tv":25796.53,"id":72857116}]}]}
{"op":"mcm","clk":"11917355189","pt":1724086620532,"mc":[{"id":"1.232011680","rc":[{"batb":[[1,1.57,67.23]],"ltp":1.74,"tv":52273.35,"id":72857114},{"batb":[[0,2.32,4],[1,2.3,23.77],[2,2.28,48.11]],"ltp":2.4,"tv":25796.53,"id":72857116}]}]}
{"op":"mcm","clk":"11917355336","pt":1724086621939,"mc":[{"id":"1.232011680","rc":[{"batb":[[1,2.3,13.77]],"ltp":2.4,"tv":25796.53,"id":72857116}]}]}
{"op":"mcm","clk":"11917355410","pt":1724086622553,"mc":[{"id":"1.232011680","rc":[{"batb":[[0,2.28,48.11],[1,1.67,85.27],[2,1.6,85.27]],"ltp":2.4,"tv":25796.53,"id":72857116}]}]}
{"op":"mcm","clk":"11917355699","pt":1724086624853,"mc":[{"id":"1.232011680","rc":[{"batb":[[0,1.62,7.16]],"ltp":1.74,"tv":52273.35,"id":72857114}]}]}
{"op":"mcm","clk":"11917355802","pt":1724086625733,"mc":[{"id":"1.232011680","rc":[{"trd":[[1.71,127.96]],"batb":[[0,1.62,8.11]],"batl":[[0,1.74,11.42]],"ltp":1.71,"tv":52274.29,"id":72857114},{"trd":[[2.4,1233.15]],"batb":[[0,2.3,14],[1,2.28,48.11],[2,1.67,85.27]],"batl":[[0,2.4,307.45],[1,3,74.83]],"ltp":2.4,"tv":25797.2,"id":72857116}],"tv":78071.5}]}
{"op":"mcm","clk":"11917355962","pt":1724086627538,"mc":[{"id":"1.232011680","rc":[{"batb":[[0,1.7,25.58],[1,1.62,8.11],[2,1.57,67.23]],"ltp":1.71,"tv":52274.29,"id":72857114},{"batb":[[0,2.3,23.77]],"ltp":2.4,"tv":25797.2,"id":72857116}]}]}
{"op":"mcm","clk":"11917356038","pt":1724086628324,"mc":[{"id":"1.232011680","rc":[{"batb":[[0,2.3,13.77]],"ltp":2.4,"tv":25797.2,"id":72857116}]}]}
{"op":"mcm","clk":"11917356120","pt":1724086629045,"mc":[{"id":"1.232011680","rc":[{"batb":[[0,2.28,48.11],[1,1.67,85.27],[2,1.6,85.27]],"ltp":2.4,"tv":25797.2,"id":72857116}]}]}
{"op":"mcm","clk":"11917356369","pt":1724086631530,"mc":[{"id":"1.232011680","rc":[{"batb":[[0,1.62,8.11],[1,1.57,67.23],[2,1.5,36.24]],"ltp":1.71,"tv":52274.29,"id":72857114},{"trd":[[2.4,1848.04]],"batb":[[0,2.3,14.67],[1,2.28,48.11],[2,1.67,85.27]],"batl":[[0,3,74.83],[1,3,0]],"ltp":2.4,"tv":26412.1,"id":72857116}],"tv":78686.4}]}
{"op":"mcm","clk":"11917356531","pt":1724086633844,"mc":[{"id":"1.232011680","rc":[{"batb":[[1,1.58,9.96],[2,1.57,67.23]],"ltp":1.71,"tv":52274.29,"id":72857114},{"batb":[[0,2.3,24.44],[2,2.22,7.09]],"ltp":2.4,"tv":26412.1,"id":72857116}]}]}
{"op":"mcm","clk":"11917356627","pt":1724086634731,"mc":[{"id":"1.232011680","rc":[{"batb":[[0,2.3,14.44]],"ltp":2.4,"tv":26412.1,"id":72857116}]}]}
{"op":"mcm","clk":"11917356658","pt":1724086635043,"mc":[{"id":"1.232011680","rc":[{"batb":[[0,2.28,48.78],[1,2.22,7.09],[2,1.67,85.27]],"ltp":2.4,"tv":26412.1,"id":72857116}]}]}
{"op":"mcm","clk":"11917356983","pt":1724086637939,"mc":[{"id":"1.232011680","rc":[{"batb":[[0,2.3,10],[1,2.28,48.11],[2,2.22,7.09]],"batl":[[0,2.4,307.45],[1,3,74.83]],"ltp":2.4,"tv":26412.1,"id":72857116}]}]}
{"op":"mcm","clk":"11917357070","pt":1724086638860,"mc":[{"id":"1.232011680","rc":[{"batb":[[0,1.71,4],[1,1.62,8.11],[2,1.58,9.96]],"ltp":1.71,"tv":52274.29,"id":72857114},{"batl":[[0,2.4,311.45]],"ltp":2.4,"tv":26412.1,"id":72857116}]}]}
{"op":"mcm","clk":"11917357134","pt":1724086639436,"mc":[{"id":"1.232011680","rc":[{"batb":[[1,1.7,25.58],[2,1.62,8.11]],"ltp":1.71,"tv":52274.29,"id":72857114}]}]}
{"op":"mcm","clk":"11917357246","pt":1724086640455,"mc":[{"id":"1.232011680","rc":[{"batb":[[0,2.3,23.77]],"ltp":2.4,"tv":26412.1,"id":72857116}]}]}
{"op":"mcm","clk":"11917357379","pt":1724086641551,"mc":[{"id":"1.232011680","rc":[{"batb":[[0,2.28,48.11],[1,2.22,7.09],[2,1.67,85.27]],"ltp":2.4,"tv":26412.1,"id":72857116}]}]}
{"op":"mcm","clk":"11917357608","pt":1724086643865,"mc":[{"id":"1.232011680","rc":[{"trd":[[2.4,2464.28]],"batl":[[0,2.4,3.33]],"ltp":2.4,"tv":27028.34,"id":72857116}],"tv":79302.64}]}
{"op":"mcm","clk":"11917357729","pt":1724086644854,"mc":[{"id":"1.232011680","rc":[{"batb":[[0,1.62,8.11],[1,1.58,9.96],[2,1.57,67.23]],"ltp":1.71,"tv":52274.29,"id":72857114},{"batb":[[0,2.32,4],[1,2.3,10],[2,2.28,48.11]],"batl":[[0,3,74.83],[1,3,0]],"ltp":2.4,"tv":27028.34,"id":72857116}]}]}
{"op":"mcm","clk":"11917357899","pt":1724086646460,"mc":[{"id":"1.232011680","rc":[{"batb":[[1,2.3,23.77]],"ltp":2.4,"tv":27028.34,"id":72857116}]}]}
{"op":"mcm","clk":"11917357992","pt":1724086647448,"mc":[{"id":"1.232011680","rc":[{"batb":[[0,2.28,48.11],[1,2.22,7.09],[2,1.67,85.27]],"ltp":2.4,"tv":27028.34,"id":72857116}]}]}
{"op":"mcm","clk":"11917358112","pt":1724086648741,"mc":[{"id":"1.232011680","rc":[{"batb":[[1,1.57,67.23],[2,1.5,36.24]],"ltp":1.71,"tv":52274.29,"id":72857114},{"batb":[[1,1.67,85.27],[2,1.6,85.27]],"ltp":2.4,"tv":27028.34,"id":72857116}]}]}
{"op":"mcm","clk":"11917358184","pt":1724086649569,"mc":[{"id":"1.232011680","rc":[{"batb":[[0,2.32,10],[1,2.3,4],[2,2.28,48.11]],"ltp":2.4,"tv":27028.34,"id":72857116}]}]}
{"op":"mcm","clk":"11917358364","pt":1724086651572,"mc":[{"id":"1.232011680","rc":[{"batb":[[0,2.32,23.57],[1,2.28,48.11],[2,1.67,85.27]],"ltp":2.4,"tv":27028.34,"id":72857116}]}]}
{"op":"mcm","clk":"11917358504","pt":1724086652854,"mc":[{"id":"1.232011680","rc":[{"batb":[[0,2.32,13.57]],"ltp":2.4,"tv":27028.34,"id":72857116}]}]}
{"op":"mcm","clk":"11917358530","pt":1724086653068,"mc":[{"id":"1.232011680","rc":[{"batb":[[0,2.28,48.11],[1,1.67,85.27],[2,1.6,85.27]],"ltp":2.4,"tv":27028.34,"id":72857116}]}]}
{"op":"mcm","clk":"11917359357","pt":1724086660747,"mc":[{"id":"1.232011680","rc":[{"batb":[[0,1.62,8.14]],"ltp":1.71,"tv":52274.29,"id":72857114},{"batb":[[0,2.3,14],[1,2.28,48.11],[2,1.67,85.27]],"ltp":2.4,"tv":27028.34,"id":72857116}]}]}
{"op":"mcm","clk":"11917359533","pt":1724086662918,"mc":[{"id":"1.232011680","rc":[{"batb":[[0,2.3,23.77]],"ltp":2.4,"tv":27028.34,"id":72857116}]}]}
{"op":"mcm","clk":"11917359620","pt":1724086663893,"mc":[{"id":"1.232011680","rc":[{"batb":[[0,2.3,13.77]],"ltp":2.4,"tv":27028.34,"id":72857116}]}]}
{"op":"mcm","clk":"11917359671","pt":1724086664569,"mc":[{"id":"1.232011680","rc":[{"batb":[[0,2.28,48.11],[1,1.67,85.27],[2,1.6,85.27]],"ltp":2.4,"tv":27028.34,"id":72857116}]}]}
{"op":"mcm","clk":"11917359820","pt":1724086666272,"mc":[{"id":"1.232011680","rc":[{"batb":[[1,1.58,9.96],[2,1.57,67.23]],"ltp":1.71,"tv":52274.29,"id":72857114},{"batb":[[0,2.3,14],[1,2.28,48.11],[2,2.22,7.09]],"ltp":2.4,"tv":27028.34,"id":72857116}]}]}
{"op":"mcm","clk":"11917360027","pt":1724086668497,"mc":[{"id":"1.232011680","rc":[{"batb":[[0,2.3,23.77]],"ltp":2.4,"tv":27028.34,"id":72857116}]}]}
{"op":"mcm","clk":"11917360131","pt":1724086669485,"mc":[{"id":"1.232011680","rc":[{"batb":[[0,2.3,13.77]],"ltp":2.4,"tv":27028.34,"id":72857116}]}]}
{"op":"mcm","clk":"11917360199","pt":1724086670098,"mc":[{"id":"1.232011680","rc":[{"batb":[[0,2.28,48.11],[1,2.22,7.09],[2,1.67,85.27]],"ltp":2.4,"tv":27028.34,"id":72857116}]}]}
{"op":"mcm","clk":"11917360490","pt":1724086672899,"mc":[{"id":"1.232011680","rc":[{"batl":[[0,2.4,308.12],[1,3,74.83]],"ltp":2.4,"tv":27028.34,"id":72857116}]}]}
{"op":"mcm","clk":"11917360505","pt":1724086673109,"mc":[{"id":"1.232011680","rc":[{"batb":[[0,2.3,10],[1,2.28,48.11],[2,2.22,7.09]],"ltp":2.4,"tv":27028.34,"id":72857116}]}]}
{"op":"mcm","clk":"11917360719","pt":1724086675496,"mc":[{"id":"1.232011680","rc":[{"batb":[[0,1.7,25.58],[1,1.62,8.14],[2,1.58,9.96]],"ltp":1.71,"tv":52274.29,"id":72857114},{"batb":[[0,2.3,23.77]],"ltp":2.4,"tv":27028.34,"id":72857116}]}]}
{"op":"mcm","clk":"11917360807","pt":1724086676587,"mc":[{"id":"1.232011680","rc":[{"batb":[[0,1.62,8.14],[1,1.58,9.96],[2,1.57,67.23]],"ltp":1.71,"tv":52274.29,"id":72857114},{"trd":[[2.4,3080.52]],"batb":[[0,2.32,4]],"batl":[[0,3,74.83],[1,3,0]],"ltp":2.4,"tv":27644.57,"id":72857116}],"tv":79918.87}]}
{"op":"mcm","clk":"11917360999","pt":1724086678903,"mc":[{"id":"1.232011680","rc":[{"batb":[[0,1.62,7.16]],"ltp":1.71,"tv":52274.29,"id":72857114},{"batb":[[0,2.3,10]],"ltp":2.4,"tv":27644.57,"id":72857116}]}]}
{"op":"mcm","clk":"11917361016","pt":1724086679009,"mc":[{"id":"1.232011680","rc":[{"batb":[[0,1.62,8.13]],"ltp":1.71,"tv":52274.29,"id":72857114}]}]}
{"op":"mcm","clk":"11917361152","pt":1724086680711,"mc":[{"id":"1.232011680","rc":[{"batb":[[0,2.32,4],[1,2.3,23.77],[2,2.28,48.11]],"ltp":2.4,"tv":27644.57,"id":72857116}]}]}
{"op":"mcm","clk":"11917361276","pt":1724086681904,"mc":[{"id":"1.232011680","rc":[{"batb":[[1,2.3,13.77]],"ltp":2.4,"tv":27644.57,"id":72857116}]}]}
{"op":"mcm","clk":"11917361389","pt":1724086682893,"mc":[{"id":"1.232011680","rc":[{"batb":[[0,2.28,48.11],[1,2.22,7.09],[2,1.67,85.27]],"batl":[[0,2.4,308.12],[1,3,74.83]],"ltp":2.4,"tv":27644.57,"id":72857116}]}]}
{"op":"mcm","clk":"11917361527","pt":1724086684492,"mc":[{"id":"1.232011680","rc":[{"batb":[[0,1.71,4],[1,1.7,25.58],[2,1.62,8.13]],"ltp":1.71,"tv":52274.29,"id":72857114},{"batb":[[0,2.3,10],[1,2.28,48.11],[2,2.22,7.09]],"batl":[[0,2.4,312.12]],"ltp":2.4,"tv":27644.57,"id":72857116}]}]}
{"op":"mcm","clk":"11917361766","pt":1724086686718,"mc":[{"id":"1.232011680","rc":[{"batb":[[0,1.71,39.13]],"ltp":1.71,"tv":52274.29,"id":72857114},{"batb":[[0,2.3,49.89]],"batl":[[0,2.38,25.24],[1,2.4,312.12],[2,3,74.83]],"ltp":2.4,"tv":27644.57,"id":72857116}]}]}
{"op":"mcm","clk":"11917361850","pt":1724086687593,"mc":[{"id":"1.232011680","rc":[{"batb":[[0,1.71,29.22]],"ltp":1.71,"tv":52274.29,"id":72857114},{"trd":[[2.38,50.48],[2.4,3646.27]],"batb":[[0,2.3,39.89]],"batl":[[0,2.4,29.24],[1,3,74.83],[2,3,0]],"ltp":2.4,"tv":28260.81,"id":72857116}],"tv":80535.11}]}
{"op":"mcm","clk":"11917361897","pt":1724086688110,"mc":[{"id":"1.232011680","rc":[{"batb":[[0,1.71,4]],"ltp":1.71,"tv":52274.29,"id":72857114}]}]}
{"op":"mcm","clk":"11917362273","pt":1724086691726,"mc":[{"id":"1.232011680","rc":[{"trd":[[1.71,129.85]],"batb":[[0,1.71,3.06]],"ltp":1.71,"tv":52276.18,"id":72857114},{"batb":[[0,2.32,10],[1,2.3,39.89],[2,2.28,48.11]],"ltp":2.4,"tv":28260.81,"id":72857116}],"tv":80536.99}]}
{"op":"mcm","clk":"11917362436","pt":1724086693577,"mc":[{"id":"1.232011680","rc":[{"batb":[[0,2.32,23.57]],"ltp":2.4,"tv":28260.81,"id":72857116}]}]}
{"op":"mcm","clk":"11917362632","pt":1724086695600,"mc":[{"id":"1.232011680","rc":[{"batb":[[0,2.3,39.89],[1,2.28,48.11],[2,2.22,7.09]],"ltp":2.4,"tv":28260.81,"id":72857116}]}]}
{"op":"mcm","clk":"11917362911","pt":1724086698204,"mc":[{"id":"1.232011680","rc":[{"trd":[[2.4,3646.69]],"batb":[[0,2.32,10],[1,2.3,39.89],[2,2.28,48.11]],"batl":[[0,2.4,29.03]],"ltp":2.4,"tv":28261.22,"id":72857116}],"tv":80537.41}]}
{"op":"mcm","clk":"11917362995","pt":1724086699235,"mc":[{"id":"1.232011680","rc":[{"batl":[[0,1.74,15.42]],"ltp":1.71,"tv":52276.18,"id":72857114},{"batb":[[0,2.34,4],[1,2.32,10],[2,2.3,39.89]],"ltp":2.4,"tv":28261.22,"id":72857116}]}]}
{"op":"mcm","clk":"11917363139","pt":1724086700531,"mc":[{"id":"1.232011680","rc":[{"batb":[[1,2.32,23.57]],"ltp":2.4,"tv":28261.22,"id":72857116}]}]}
{"op":"mcm","clk":"11917363260","pt":1724086701832,"mc":[{"id":"1.232011680","rc":[{"trd":[[1.74,48.2],[1.75,26701.4],[1.76,3855.82]],"batb":[[1,1.62,8.13],[2,1.58,9.96]],"batl":[[0,1.8,358.53],[1,1.83,7.7],[2,2.2,5.17]],"ltp":1.76,"tv":52325.94,"id":72857114},{"trd":[[2.32,10.3],[2.34,1240.14]],"batb":[[0,2.3,39.89],[1,2.28,48.11],[2,2.22,7.09]],"batl":[[0,3,74.83],[1,3,0]],"ltp":2.32,"tv":28275.52,"id":72857116}],"tv":80601.47}]}
{"op":"mcm","clk":"11917363335","pt":1724086702518,"mc":[{"id":"1.232011680","rc":[{"batb":[[0,1.62,8.13],[1,1.58,9.96],[2,1.57,67.23]],"ltp":1.76,"tv":52325.94,"id":72857114},{"batb":[[0,2.32,4],[1,2.3,39.89],[2,2.28,48.11]],"ltp":2.32,"tv":28275.52,"id":72857116}]}]}
{"op":"mcm","clk":"11917363559","pt":1724086704645,"mc":[{"id":"1.232011680","rc":[{"batb":[[0,2.32,10]],"ltp":2.32,"tv":28275.52,"id":72857116}]}]}
{"op":"mcm","clk":"11917363775","pt":1724086706715,"mc":[{"id":"1.232011680","rc":[{"batb":[[0,2.34,4],[1,2.32,10],[2,2.3,39.89]],"ltp":2.32,"tv":28275.52,"id":72857116}]}]}
{"op":"mcm","clk":"11917363868","pt":1724086707916,"mc":[{"id":"1.232011680","rc":[{"batb":[[1,2.3,39.89],[2,2.28,48.11]],"ltp":2.32,"tv":28275.52,"id":72857116}]}]}
{"op":"mcm","clk":"11917363994","pt":1724086709313,"mc":[{"id":"1.232011680","rc":[{"batb":[[0,2.3,39.89],[1,2.28,48.11],[2,2.22,7.09]],"ltp":2.32,"tv":28275.52,"id":72857116}]}]}
{"op":"mcm","clk":"11917364565","pt":1724086714856,"mc":[{"id":"1.232011680","rc":[{"batb":[[0,1.66,1.91],[1,1.64,5.71],[2,1.62,7.16]],"ltp":1.76,"tv":52325.94,"id":72857114},{"batb":[[0,2.32,14],[1,2.3,39.89],[2,2.28,48.11]],"ltp":2.32,"tv":28275.52,"id":72857116}]}]}
{"op":"mcm","clk":"11917364774","pt":1724086716936,"mc":[{"id":"1.232011680","rc":[{"batb":[[0,2.32,10]],"ltp":2.32,"tv":28275.52,"id":72857116}]}]}
{"op":"mcm","clk":"11917364935","pt":1724086718545,"mc":[{"id":"1.232011680","rc":[{"batb":[[0,2.3,26.12],[1,2.28,48.11],[2,2.22,7.09]],"batl":[[0,2.4,308.12],[1,3,74.83]],"ltp":2.32,"tv":28275.52,"id":72857116}]}]}
{"op":"mcm","clk":"11917365145","pt":1724086720862,"mc":[{"id":"1.232011680","rc":[{"batb":[[0,1.7,25.58],[1,1.66,1.91],[2,1.64,5.71]],"ltp":1.76,"tv":52325.94,"id":72857114},{"trd":[[2.4,4262.93]],"batb":[[0,2.32,10],[1,2.3,26.12],[2,2.28,48.11]],"batl":[[0,3,74.83],[1,3,0]],"ltp":2.4,"tv":28891.76,"id":72857116}],"tv":81217.71}]}
{"op":"mcm","clk":"11917365202","pt":1724086721538,"mc":[{"id":"1.232011680","rc":[{"batb":[[0,1.66,1.91],[1,1.64,5.71],[2,1.62,7.16]],"batl":[[0,1.75,6.71],[1,1.8,358.53],[2,1.83,7.7]],"ltp":1.76,"tv":52325.94,"id":72857114},{"batb":[[0,2.34,4],[1,2.32,10],[2,2.3,39.89]],"ltp":2.4,"tv":28891.76,"id":72857116}]}]}
{"op":"mcm","clk":"11917365322","pt":1724086723240,"mc":[{"id":"1.232011680","rc":[{"batb":[[0,2.32,10],[1,2.3,39.89],[2,2.28,48.11]],"ltp":2.4,"tv":28891.76,"id":72857116}]}]}
{"op":"mcm","clk":"11917365413","pt":1724086723960,"mc":[{"id":"1.232011680","rc":[{"batb":[[0,2.3,39.89],[1,2.28,48.11],[2,2.22,7.09]],"ltp":2.4,"tv":28891.76,"id":72857116}]}]}
{"op":"mcm","clk":"11917365762","pt":1724086727570,"mc":[{"id":"1.232011680","rc":[{"batb":[[0,2.32,10],[1,2.3,39.89],[2,2.28,48.11]],"batl":[[0,2.4,308.12],[1,3,74.83]],"ltp":2.4,"tv":28891.76,"id":72857116}]}]}
{"op":"mcm","clk":"11917365960","pt":1724086729547,"mc":[{"id":"1.232011680","rc":[{"batb":[[0,1.72,4],[1,1.71,4],[2,1.7,25.58]],"ltp":1.76,"tv":52325.94,"id":72857114},{"trd":[[2.4,4879.16]],"batb":[[0,2.32,14]],"batl":[[0,2.4,4]],"ltp":2.4,"tv":29508.0,"id":72857116}],"tv":81833.95}]}
{"op":"mcm","clk":"11917366073","pt":1724086730770,"mc":[{"id":"1.232011680","rc":[{"batb":[[0,1.66,1.91],[1,1.64,5.71],[2,1.62,7.16]],"ltp":1.76,"tv":52325.94,"id":72857114},{"batb":[[0,2.34,4],[1,2.32,4],[2,2.3,39.89]],"batl":[[0,3,74.83],[1,3,0]],"ltp":2.4,"tv":29508.0,"id":72857116}]}]}
{"op":"mcm","clk":"11917366252","pt":1724086732684,"mc":[{"id":"1.232011680","rc":[{"batb":[[0,2.32,4],[1,2.3,39.89],[2,2.28,48.11]],"ltp":2.4,"tv":29508.0,"id":72857116}]}]}
{"op":"mcm","clk":"11917366374","pt":1724086733875,"mc":[{"id":"1.232011680","rc":[{"batl":[[0,2.54,0.18]],"ltp":2.4,"tv":29508.0,"id":72857116}]}]}
{"op":"mcm","clk":"11917366393","pt":1724086734088,"mc":[{"id":"1.232011680","rc":[{"batb":[[0,2.34,10],[1,2.32,4],[2,2.3,39.89]],"ltp":2.4,"tv":29508.0,"id":72857116}]}]}
{"op":"mcm","clk":"11917366620","pt":1724086736546,"mc":[{"id":"1.232011680","rc":[{"batb":[[1,2.32,17.57]],"ltp":2.4,"tv":29508.0,"id":72857116}]}]}
{"op":"mcm","clk":"11917366703","pt":1724086737582,"mc":[{"id":"1.232011680","rc":[{"batb":[[0,2.32,4],[1,2.3,39.89],[2,2.28,48.11]],"ltp":2.4,"tv":29508.0,"id":72857116}]}]}
{"op":"mcm","clk":"11917366899","pt":1724086739892,"mc":[{"id":"1.232011680","rc":[{"batb":[[1,1.62,7.16],[2,1.58,9.96]],"ltp":1.76,"tv":52325.94,"id":72857114}]}]}
{"op":"mcm","clk":"11917366914","pt":1724086740092,"mc":[{"id":"1.232011680","rc":[{"batb":[[0,2.34,10],[1,2.32,4],[2,2.3,39.89]],"ltp":2.4,"tv":29508.0,"id":72857116}]}]}
{"op":"mcm","clk":"11917367209","pt":1724086742583,"mc":[{"id":"1.232011680","rc":[{"batb":[[1,2.32,17.57]],"ltp":2.4,"tv":29508.0,"id":72857116}]}]}
{"op":"mcm","clk":"11917367325","pt":1724086743575,"mc":[{"id":"1.232011680","rc":[{"batb":[[0,2.32,4],[1,2.3,39.89],[2,2.28,48.11]],"batl":[[0,2.4,308.12],[1,2.54,0.18]],"ltp":2.4,"tv":29508.0,"id":72857116}]}]}
{"op":"mcm","clk":"11917367418","pt":1724086744569,"mc":[{"id":"1.232011680","rc":[{"batb":[[0,1.72,4],[1,1.71,4],[2,1.66,1.91]],"ltp":1.76,"tv":52325.94,"id":72857114},{"batl":[[0,2.4,312.12]],"ltp":2.4,"tv":29508.0,"id":72857116}]}]}
{"op":"mcm","clk":"11917367560","pt":1724086745870,"mc":[{"id":"1.232011680","rc":[{"batb":[[1,1.71,29.22]],"ltp":1.76,"tv":52325.94,"id":72857114},{"trd":[[2.38,101.26],[2.4,5444.62]],"batl":[[0,2.38,25.39],[1,2.4,29.39],[2,2.54,0.18]],"ltp":2.4,"tv":30124.24,"id":72857116}],"tv":82450.19}]}
{"op":"mcm","clk":"11917367570","pt":1724086745966,"mc":[{"id":"1.232011680","rc":[{"batl":[[0,2.4,29.39],[1,2.54,0.18],[2,2.54,0]],"ltp":2.4,"tv":30124.24,"id":72857116}]}]}
{"op":"mcm","clk":"11917368223","pt":1724086752680,"mc":[{"id":"1.232011680","rc":[{"batl":[[0,1.8,358.53],[1,1.83,7.7],[2,2.2,5.17]],"ltp":1.76,"tv":52325.94,"id":72857114},{"batl":[[0,2.4,337.51]],"ltp":2.4,"tv":30124.24,"id":72857116}]}]}
{"op":"mcm","clk":"11917370501","pt":1724086775156,"mc":[{"id":"1.232011680","rc":[{"batl":[[0,2.38,308.12],[1,2.4,29.39],[2,2.54,0.18]],"ltp":2.4,"tv":30124.24,"id":72857116}]}]}
{"op":"mcm","clk":"11917370970","pt":1724086779463,"mc":[{"id":"1.232011680","rc":[{"trd":[[2.38,111.9]],"batl":[[0,2.38,302.8]],"ltp":2.38,"tv":30134.88,"id":72857116}],"tv":82460.83}]}
{"op":"mcm","clk":"11917371039","pt":1724086780081,"mc":[{"id":"1.232011680","rc":[{"trd":[[2.38,717.5]],"batb":[[0,2.38,5.32],[1,2.32,4],[2,2.3,39.89]],"batl":[[0,2.4,29.39],[1,2.54,0.18],[2,2.54,0]],"ltp":2.38,"tv":30740.47,"id":72857116}],"tv":83066.42}]}
{"op":"mcm","clk":"11917372011","pt":1724086789563,"mc":[{"id":"1.232011680","rc":[{"batb":[[1,1.71,4]],"ltp":1.76,"tv":52325.94,"id":72857114},{"batb":[[0,2.32,4],[1,2.3,39.89],[2,2.28,13.99]],"batl":[[0,2.4,4]],"ltp":2.38,"tv":30740.47,"id":72857116}]}]}
{"op":"mcm","clk":"11917372083","pt":1724086790376,"mc":[{"id":"1.232011680","rc":[{"batb":[[0,1.66,1.91],[1,1.62,7.16],[2,1.57,67.23]],"batl":[[0,1.76,4],[1,1.8,358.53],[2,1.83,7.7]],"ltp":1.76,"tv":52325.94,"id":72857114},{"batb":[[0,2.34,10],[1,2.32,4],[2,2.3,39.89]],"batl":[[0,2.54,0.18],[1,2.54,0]],"ltp":2.38,"tv":30740.47,"id":72857116}]}]}
{"op":"mcm","clk":"11917372171","pt":1724086791160,"mc":[{"id":"1.232011680","rc":[{"batl":[[0,1.72,2.59],[1,1.76,4],[2,1.8,358.53]],"ltp":1.76,"tv":52325.94,"id":72857114}]}]}
{"op":"mcm","clk":"11917372356","pt":1724086792759,"mc":[{"id":"1.232011680","rc":[{"trd":[[1.72,24.03],[1.75,26702.08]],"batl":[[0,1.76,4],[1,1.8,358.53],[2,1.83,7.7]],"ltp":1.75,"tv":52331.8,"id":72857114},{"trd":[[2.34,1240.65]],"batb":[[0,2.34,9.49]],"ltp":2.34,"tv":30740.98,"id":72857116}],"tv":83072.79}]}
{"op":"mcm","clk":"11917372396","pt":1724086793277,"mc":[{"id":"1.232011680","rc":[{"trd":[[2.3,13.22],[2.32,18.3],[2.34,1259.63]],"batb":[[0,2.3,35.28],[1,2.28,48.11],[2,1.67,85.27]],"ltp":2.3,"tv":30777.19,"id":72857116}],"tv":83108.99}]}
{"op":"mcm","clk":"11917373032","pt":1724086800114,"mc":[{"id":"1.232011680","rc":[{"batb":[[0,2.32,10],[1,2.3,35.28],[2,2.28,48.11]],"ltp":2.3,"tv":30777.19,"id":72857116}]}]}
{"op":"mcm","clk":"11917373532","pt":1724086803392,"mc":[{"id":"1.232011680","rc":[{"batb":[[0,2.3,35.28],[1,2.28,48.11],[2,1.67,85.27]],"ltp":2.3,"tv":30777.19,"id":72857116}]}]}
{"op":"mcm","clk":"11917374376","pt":1724086810112,"mc":[{"id":"1.232011680","rc":[{"trd":[[1.48,23.96],[1.56,27.55],[1.58,34.89],[1.61,16.38],[1.64,958.74],[1.65,13691.56],[1.66,1875.66],[1.67,214.13],[1.68,3719.98],[1.71,129.9],[1.72,24.04],[1.74,48.2]],"batb":[[2,1.57,67.25]],"batl":[[1,1.8,358.84]],"ltp":1.75,"tv":52331.99,"id":72857114},{"batb":[[0,2.32,10],[1,2.3,35.29],[2,2.28,48.12]],"ltp":2.3,"tv":30777.19,"id":72857116}],"tv":83109.19}]}
{"op":"mcm","clk":"11917374815","pt":1724086813916,"mc":[{"id":"1.232011680","rc":[{"batb":[[0,2.3,35.29],[1,2.28,48.12],[2,1.67,85.3]],"ltp":2.3,"tv":30777.19,"id":72857116}]}]}
{"op":"mcm","clk":"11917376267","pt":1724086826636,"mc":[{"id":"1.232011680","rc":[{"batb":[[0,2.32,10],[1,2.3,35.29],[2,2.28,48.12]],"ltp":2.3,"tv":30777.19,"id":72857116}]}]}
{"op":"mcm","clk":"11917376627","pt":1724086829907,"mc":[{"id":"1.232011680","rc":[{"batb":[[0,2.3,35.29],[1,2.28,48.12],[2,1.67,85.3]],"ltp":2.3,"tv":30777.19,"id":72857116}]}]}
{"op":"mcm","clk":"11917376936","pt":1724086832436,"mc":[{"id":"1.232011680","rc":[{"batb":[[0,2.32,10],[1,2.3,35.29],[2,2.28,48.12]],"ltp":2.3,"tv":30777.19,"id":72857116}]}]}
{"op":"mcm","clk":"11917377350","pt":1724086835938,"mc":[{"id":"1.232011680","rc":[{"batb":[[0,2.3,35.29],[1,2.28,48.12],[2,1.67,85.3]],"ltp":2.3,"tv":30777.19,"id":72857116}]}]}
{"op":"mcm","clk":"11917378535","pt":1724086846247,"mc":[{"id":"1.232011680","rc":[{"batb":[[0,2.32,10],[1,2.3,35.29],[2,2.28,48.12]],"ltp":2.3,"tv":30777.19,"id":72857116}]}]}
{"op":"mcm","clk":"11917378950","pt":1724086849639,"mc":[{"id":"1.232011680","rc":[{"batb":[[0,2.3,35.29],[1,2.28,48.12],[2,1.67,85.3]],"ltp":2.3,"tv":30777.19,"id":72857116}]}]}
{"op":"mcm","clk":"11917379259","pt":1724086852643,"mc":[{"id":"1.232011680","rc":[{"trd":[[2.3,13.37]],"batb":[[0,2.32,10],[1,2.3,35.22],[2,2.28,48.12]],"ltp":2.3,"tv":30777.33,"id":72857116}],"tv":83109.33}]}
{"op":"mcm","clk":"11917379617","pt":1724086855871,"mc":[{"id":"1.232011680","rc":[{"batb":[[0,2.3,35.22],[1,2.28,48.12],[2,1.67,85.3]],"batl":[[0,2.4,308.12],[1,2.54,0.18]],"ltp":2.3,"tv":30777.33,"id":72857116}]}]}
{"op":"mcm","clk":"11917379703","pt":1724086856661,"mc":[{"id":"1.232011680","rc":[{"batl":[[0,1.8,358.84],[1,1.83,7.7],[2,2.2,5.18]],"ltp":1.75,"tv":52331.99,"id":72857114},{"batb":[[0,2.3,21.44]],"ltp":2.3,"tv":30777.33,"id":72857116}]}]}
{"op":"mcm","clk":"11917379824","pt":1724086857652,"mc":[{"id":"1.232011680","rc":[{"batb":[[0,1.7,25.59],[1,1.66,1.91],[2,1.62,7.16]],"ltp":1.75,"tv":52331.99,"id":72857114}]}]}
{"op":"mcm","clk":"11917380297","pt":1724086861667,"mc":[{"id":"1.232011680","rc":[{"batb":[[0,1.66,1.91],[1,1.62,7.16],[2,1.57,67.25]],"ltp":1.75,"tv":52331.99,"id":72857114},{"trd":[[2.4,6060.86]],"batb":[[0,2.32,10],[1,2.3,35.22],[2,2.28,48.12]],"batl":[[0,2.54,0.18],[1,2.54,0]],"ltp":2.4,"tv":31393.57,"id":72857116}],"tv":83725.57}]}
{"op":"mcm","clk":"11917380636","pt":1724086864572,"mc":[{"id":"1.232011680","rc":[{"batb":[[0,2.3,35.22],[1,2.28,48.12],[2,1.67,85.3]],"ltp":2.4,"tv":31393.57,"id":72857116}]}]}
{"op":"mcm","clk":"11917380914","pt":1724086866885,"mc":[{"id":"1.232011680","rc":[{"batb":[[0,1.72,4],[1,1.71,4],[2,1.66,1.91]],"batl":[[0,1.77,4],[1,1.8,358.84],[2,1.83,7.7]],"ltp":1.75,"tv":52331.99,"id":72857114},{"batb":[[0,2.3,25.44]],"batl":[[0,2.4,312.12],[1,2.54,0.18]],"ltp":2.4,"tv":31393.57,"id":72857116}]}]}
{"op":"mcm","clk":"11917381061","pt":1724086867878,"mc":[{"id":"1.232011680","rc":[{"batb":[[0,1.72,39.14],[1,1.71,29.23]],"ltp":1.75,"tv":52331.99,"id":72857114},{"batb":[[0,2.32,10],[1,2.3,39.22],[2,2.28,48.12]],"batl":[[0,2.38,25.39],[1,2.4,312.12],[2,2.54,0.18]],"ltp":2.4,"tv":31393.57,"id":72857116}]}]}
{"op":"mcm","clk":"11917381142","pt":1724086868678,"mc":[{"id":"1.232011680","rc":[{"batl":[[0,1.79,33.76]],"ltp":1.75,"tv":52331.99,"id":72857114}]}]}
{"op":"mcm","clk":"11917381248","pt":1724086869681,"mc":[{"id":"1.232011680","rc":[{"batb":[[0,1.72,4]],"ltp":1.75,"tv":52331.99,"id":72857114},{"trd":[[2.38,768.28],[2.4,6626.32]],"batl":[[0,2.4,29.39],[1,2.54,0.18],[2,2.54,0]],"ltp":2.4,"tv":32009.81,"id":72857116}],"tv":84341.81}]}
{"op":"mcm","clk":"11917381319","pt":1724086870362,"mc":[{"id":"1.232011680","rc":[{"batb":[[0,2.3,39.22],[1,2.28,48.12],[2,1.67,85.3]],"ltp":2.4,"tv":32009.81,"id":72857116}]}]}
{"op":"mcm","clk":"11917381841","pt":1724086874895,"mc":[{"id":"1.232011680","rc":[{"batb":[[0,2.32,10],[1,2.3,39.22],[2,2.28,48.12]],"batl":[[0,2.4,4]],"ltp":2.4,"tv":32009.81,"id":72857116}]}]}
{"op":"mcm","clk":"11917381932","pt":1724086875583,"mc":[{"id":"1.232011680","rc":[{"batb":[[0,1.66,1.91],[1,1.62,7.16],[2,1.57,67.25]],"ltp":1.75,"tv":52331.99,"id":72857114},{"batl":[[0,2.54,0.18],[1,2.54,0]],"ltp":2.4,"tv":32009.81,"id":72857116}]}]}
{"op":"mcm","clk":"11917382249","pt":1724086878083,"mc":[{"id":"1.232011680","rc":[{"batb":[[0,2.3,39.22],[1,2.28,48.12],[2,1.67,85.3]],"ltp":2.4,"tv":32009.81,"id":72857116}]}]}
{"op":"mcm","clk":"11917383023","pt":1724086884692,"mc":[{"id":"1.232011680","rc":[{"trd":[[1.66,1876.27]],"batb":[[0,1.66,1.61]],"ltp":1.66,"tv":52332.6,"id":72857114},{"trd":[[2.3,66.35]],"batb":[[0,2.32,10]],"ltp":2.3,"tv":32062.8,"id":72857116}],"tv":84395.4}]}
{"op":"mcm","clk":"11917383390","pt":1724086887794,"mc":[{"id":"1.232011680","rc":[{"batb":[[0,2.28,48.12],[1,1.67,85.3],[2,1.6,85.3]],"ltp":2.3,"tv":32062.8,"id":72857116}]}]}
{"op":"mcm","clk":"11917384665","pt":1724086898411,"mc":[{"id":"1.232011680","rc":[{"batb":[[0,2.3,10],[1,2.28,48.12],[2,1.67,85.3]],"ltp":2.3,"tv":32062.8,"id":72857116}]}]}
{"op":"mcm","clk":"11917384890","pt":1724086900225,"mc":[{"id":"1.232011680","rc":[{"batl":[[0,2.42,308.12],[1,2.54,0.18]],"ltp":2.3,"tv":32062.8,"id":72857116}]}]}
{"op":"mcm","clk":"11917385102","pt":1724086901911,"mc":[{"id":"1.232011680","rc":[{"batb":[[0,2.28,48.12],[1,1.67,85.3],[2,1.6,85.3]],"ltp":2.3,"tv":32062.8,"id":72857116}]}]}
{"op":"mcm","clk":"11917385202","pt":1724086902594,"mc":[{"id":"1.232011680","rc":[{"batb":[[0,1.69,25.96],[1,1.66,1.61],[2,1.62,7.16]],"ltp":1.66,"tv":52332.6,"id":72857114}]}]}
{"op":"mcm","clk":"11917385645","pt":1724086906693,"mc":[{"id":"1.232011680","rc":[{"batb":[[0,1.66,1.61],[1,1.62,7.16],[2,1.57,67.25]],"ltp":1.66,"tv":52332.6,"id":72857114},{"trd":[[2.42,1848.71]],"batb":[[0,2.3,10],[1,2.28,48.12],[2,1.67,85.3]],"batl":[[0,2.54,0.18],[1,2.54,0]],"ltp":2.42,"tv":32679.03,"id":72857116}],"tv":85011.63}]}
{"op":"mcm","clk":"11917385947","pt":1724086909389,"mc":[{"id":"1.232011680","rc":[{"batb":[[0,2.28,48.12],[1,1.67,85.3],[2,1.6,85.3]],"ltp":2.42,"tv":32679.03,"id":72857116}]}]}
{"op":"mcm","clk":"11917386238","pt":1724086911822,"mc":[{"id":"1.232011680","rc":[{"batb":[[0,2.3,10],[1,2.28,48.12],[2,1.67,85.3]],"batl":[[0,2.42,308.12],[1,2.54,0.18]],"ltp":2.42,"tv":32679.03,"id":72857116}]}]}
{"op":"mcm","clk":"11917386292","pt":1724086912301,"mc":[{"id":"1.232011680","rc":[{"batb":[[0,2.3,14]],"batl":[[0,2.4,4],[1,2.42,312.12],[2,2.54,0.18]],"ltp":2.42,"tv":32679.03,"id":72857116}]}]}
{"op":"mcm","clk":"11917386446","pt":1724086913605,"mc":[{"id":"1.232011680","rc":[{"batb":[[0,1.7,25.59],[1,1.66,1.61],[2,1.62,7.16]],"ltp":1.66,"tv":52332.6,"id":72857114}]}]}
