{"op":"mcm","clk":"11908131699","pt":1724494827805,"mc":[{"id":"1.232220323","marketDefinition":{"bspMarket":false,"turnInPlayEnabled":true,"persistenceEnabled":true,"marketBaseRate":5.0,"eventId":"33523191","eventTypeId":"4","numberOfWinners":1,"bettingType":"ODDS","marketType":"MATCH_ODDS","marketTime":"2024-08-25T14:00:00.000Z","suspendTime":"2024-08-25T14:00:00.000Z","bspReconciled":false,"complete":true,"inPlay":false,"crossMatching":false,"runnersVoidable":false,"numberOfActiveRunners":2,"betDelay":0,"status":"OPEN","runners":[{"status":"ACTIVE","sortPriority":1,"id":228749,"name":"Netherlands"},{"status":"ACTIVE","sortPriority":2,"id":891555,"name":"USA"}],"regulators":["MR_INT"],"countryCode":"GB","discountAllowed":false,"timezone":"GMT","openDate":"2024-08-25T14:00:00.000Z","version":6094283549,"name":"Match Odds","eventName":"Netherlands v USA"},"rc":[{"batb":[[0,1.03,200],[1,1.02,200],[2,1.01,220]],"ltp":0.0,"tv":0.0,"id":228749},{"batb":[[0,1.03,200],[1,1.02,200],[2,1.01,220]],"ltp":0.0,"tv":0.0,"id":891555}]}]}
{"op":"mcm","clk":"11908131905","pt":1724494829161,"mc":[{"id":"1.232220323","marketDefinition":{"bspMarket":false,"turnInPlayEnabled":true,"persistenceEnabled":true,"marketBaseRate":5.0,"eventId":"33523191","eventTypeId":"4","numberOfWinners":1,"bettingType":"ODDS","marketType":"MATCH_ODDS","marketTime":"2024-08-25T14:00:00.000Z","suspendTime":"2024-08-25T14:00:00.000Z","bspReconciled":false,"complete":true,"inPlay":false,"crossMatching":false,"runnersVoidable":false,"numberOfActiveRunners":2,"betDelay":0,"status":"OPEN","runners":[{"status":"ACTIVE","sortPriority":1,"id":228749,"name":"Netherlands"},{"status":"ACTIVE","sortPriority":2,"id":891555,"name":"USA"}],"regulators":["MR_INT"],"countryCode":"GB","discountAllowed":true,"timezone":"GMT","openDate":"2024-08-25T14:00:00.000Z","version":6094283549,"name":"Match Odds","eventName":"Netherlands v USA"}}]}
{"op":"mcm","clk":"11908146164","pt":1724494915988,"mc":[{"id":"1.232220323","rc":[{"batb":[[0,1.03,2340.62],[1,1.02,3360.89],[2,1.01,6356.04]],"ltp":0.0,"tv":0.0,"id":228749}]}]}
{"op":"mcm","clk":"11908146302","pt":1724494916877,"mc":[{"id":"1.232220323","rc":[{"batb":[[0,1.04,1617.34],[1,1.03,2340.62],[2,1.02,3360.89]],"ltp":0.0,"tv":0.0,"id":228749},{"batb":[[0,1.04,1617.34],[1,1.03,2340.62],[2,1.02,3360.89]],"ltp":0.0,"tv":0.0,"id":891555}]}]}
{"op":"mcm","clk":"11908217732","pt":1724495347598,"mc":[{"id":"1.232220323","rc":[{"batb":[[0,1.1,100],[1,1.04,1617.34],[2,1.03,2340.62]],"ltp":0.0,"tv":0.0,"id":228749},{"batb":[[0,1.1,100],[1,1.04,1617.34],[2,1.03,2340.62]],"ltp":0.0,"tv":0.0,"id":891555}]}]}
{"op":"mcm","clk":"11908219515","pt":1724495357322,"mc":[{"id":"1.232220323","rc":[{"batl":[[0,11,5]],"ltp":0.0,"tv":0.0,"id":228749},{"batl":[[0,11,5]],"ltp":0.0,"tv":0.0,"id":891555}]}]}
{"op":"mcm","clk":"11908223568","pt":1724495381157,"mc":[{"id":"1.232220323","marketDefinition":{"bspMarket":false,"turnInPlayEnabled":true,"persistenceEnabled":true,"marketBaseRate":5.0,"eventId":"33523191","eventTypeId":"4","numberOfWinners":1,"bettingType":"ODDS","marketType":"MATCH_ODDS","marketTime":"2024-08-25T14:00:00.000Z","suspendTime":"2024-08-25T14:00:00.000Z","bspReconciled":false,"complete":true,"inPlay":false,"crossMatching":true,"runnersVoidable":false,"numberOfActiveRunners":2,"betDelay":0,"status":"OPEN","runners":[{"status":"ACTIVE","sortPriority":1,"id":228749,"name":"Netherlands"},{"status":"ACTIVE","sortPriority":2,"id":891555,"name":"USA"}],"regulators":["MR_INT"],"countryCode":"GB","discountAllowed":true,"timezone":"GMT","openDate":"2024-08-25T14:00:00.000Z","version":6094283549,"name":"Match Odds","eventName":"Netherlands v USA"}}]}
{"op":"mcm","clk":"11908423980","pt":1724496428930,"mc":[{"id":"1.232220323","rc":[{"batb":[[0,1.4,276.92],[1,1.1,100],[2,1.04,1617.34]],"ltp":0.0,"tv":0.0,"id":228749}]}]}
{"op":"mcm","clk":"11908425187","pt":1724496435550,"mc":[{"id":"1.232220323","rc":[{"batb":[[0,1.6,276.92],[1,1.1,100],[2,1.04,1617.34]],"ltp":0.0,"tv":0.0,"id":891555}]}]}
{"op":"mcm","clk":"11908426766","pt":1724496444967,"mc":[{"id":"1.232220323","rc":[{"batb":[[1,1.04,1617.34],[2,1.03,2340.62]],"batl":[[0,1.95,276.92]],"ltp":0.0,"tv":0.0,"id":228749},{"batb":[[1,1.04,1617.34],[2,1.03,2340.62]],"ltp":0.0,"tv":0.0,"id":891555}]}]}
{"op":"mcm","clk":"11908452046","pt":1724496589751,"mc":[{"id":"1.232220323","rc":[{"batb":[[0,1.45,738.46],[1,1.4,276.92],[2,1.04,1617.34]],"ltp":0.0,"tv":0.0,"id":228749}]}]}
{"op":"mcm","clk":"11908453123","pt":1724496595736,"mc":[{"id":"1.232220323","rc":[{"batb":[[0,1.5,738.46],[1,1.45,738.46],[2,1.4,276.92]],"ltp":0.0,"tv":0.0,"id":228749}]}]}
{"op":"mcm","clk":"11908457018","pt":1724496616677,"mc":[{"id":"1.232220323","rc":[{"batl":[[0,1.95,276.99]],"ltp":0.0,"tv":0.0,"id":228749}]}]}
{"op":"mcm","clk":"11908457775","pt":1724496620886,"mc":[{"id":"1.232220323","rc":[{"batb":[[0,1.9,738.46],[1,1.6,276.92],[2,1.04,1617.34]],"ltp":0.0,"tv":0.0,"id":891555}]}]}
{"op":"mcm","clk":"11908458572","pt":1724496625386,"mc":[{"id":"1.232220323","rc":[{"batb":[[1,1.85,738.46],[2,1.6,276.92]],"ltp":0.0,"tv":0.0,"id":891555}]}]}
{"op":"mcm","clk":"11908458800","pt":1724496626704,"mc":[{"id":"1.232220323","rc":[{"batl":[[0,2.8,0.07]],"ltp":0.0,"tv":0.0,"id":891555}]}]}
{"op":"mcm","clk":"11908459012","pt":1724496627910,"mc":[{"id":"1.232220323","rc":[{"batb":[[2,1.8,276.92]],"ltp":0.0,"tv":0.0,"id":891555}]}]}
{"op":"mcm","clk":"11908459424","pt":1724496630374,"mc":[{"id":"1.232220323","rc":[{"batb":[[2,1.8,1015.38]],"ltp":0.0,"tv":0.0,"id":891555}]}]}
{"op":"mcm","clk":"11908471608","pt":1724496701378,"mc":[{"id":"1.232220323","rc":[{"batb":[[0,1.52,492.31],[1,1.5,738.46],[2,1.45,738.46]],"ltp":0.0,"tv":0.0,"id":228749}]}]}
{"op":"mcm","clk":"11908480181","pt":1724496750728,"mc":[{"id":"1.232220323","rc":[{"batl":[[0,1.95,276.92]],"ltp":0.0,"tv":0.0,"id":228749}]}]}
{"op":"mcm","clk":"11908671383","pt":1724497875116,"mc":[{"id":"1.232220323","rc":[{"batl":[[0,1.94,13.6],[1,1.95,276.92]],"ltp":0.0,"tv":0.0,"id":228749},{"batb":[[0,2.06,12.99],[1,1.9,738.46],[2,1.85,738.46]],"ltp":0.0,"tv":0.0,"id":891555}]}]}
{"op":"mcm","clk":"11908707777","pt":1724498053807,"mc":[{"id":"1.232220323","rc":[{"batb":[[0,1.53,16.9],[1,1.52,492.31],[2,1.5,738.46]],"ltp":0.0,"tv":0.0,"id":228749},{"batl":[[0,2.92,12.5]],"ltp":0.0,"tv":0.0,"id":891555}]}]}
{"op":"mcm","clk":"11909198378","pt":1724500537209,"mc":[{"id":"1.232220323","rc":[{"batb":[[0,1.53,22.94]],"ltp":0.0,"tv":0.0,"id":228749}]}]}
{"op":"mcm","clk":"11909737835","pt":1724503346898,"mc":[{"id":"1.232220323","rc":[{"batl":[[0,1.75,55.68]],"ltp":0.0,"tv":0.0,"id":228749},{"batb":[[0,1.9,738.46],[1,1.85,738.46],[2,1.8,1015.38]],"ltp":0.0,"tv":0.0,"id":891555}]}]}
{"op":"mcm","clk":"11909759880","pt":1724503457329,"mc":[{"id":"1.232220323","rc":[{"batl":[[0,1.95,276.92],[1,1.95,0]],"ltp":0.0,"tv":0.0,"id":228749}]}]}
{"op":"mcm","clk":"11909765139","pt":1724503483065,"mc":[{"id":"1.232220323","rc":[{"batl":[[0,1.55,8],[1,1.95,276.92]],"ltp":0.0,"tv":0.0,"id":228749}]}]}
{"op":"mcm","clk":"11909766010","pt":1724503487397,"mc":[{"id":"1.232220323","rc":[{"batl":[[0,1.95,276.92],[1,1.95,0]],"ltp":0.0,"tv":0.0,"id":228749}]}]}
{"op":"mcm","clk":"11909772846","pt":1724503518468,"mc":[{"id":"1.232220323","rc":[{"batl":[[0,1.94,13.6],[1,1.95,276.92]],"ltp":0.0,"tv":0.0,"id":228749},{"batb":[[0,2.06,12.99],[1,1.9,738.46],[2,1.85,738.46]],"ltp":0.0,"tv":0.0,"id":891555}]}]}
{"op":"mcm","clk":"11910130832","pt":1724505289317,"mc":[{"id":"1.232220323","rc":[{"batb":[[0,1.56,138.46],[1,1.53,22.94],[2,1.52,492.31]],"ltp":0.0,"tv":0.0,"id":228749}]}]}
{"op":"mcm","clk":"11910131180","pt":1724505291233,"mc":[{"id":"1.232220323","rc":[{"batb":[[1,1.53,6.03]],"ltp":0.0,"tv":0.0,"id":228749}]}]}
{"op":"mcm","clk":"11910367789","pt":1724506626959,"mc":[{"id":"1.232220323","rc":[{"batb":[[0,1.57,6.03],[1,1.56,138.46]],"ltp":0.0,"tv":0.0,"id":228749}]}]}
{"op":"mcm","clk":"11910367836","pt":1724506627234,"mc":[{"id":"1.232220323","rc":[{"batb":[[0,2.06,18.94]],"ltp":0.0,"tv":0.0,"id":891555}]}]}
{"op":"mcm","clk":"11910369231","pt":1724506635162,"mc":[{"id":"1.232220323","rc":[{"batb":[[0,1.57,13.13]],"ltp":0.0,"tv":0.0,"id":228749}]}]}
{"op":"mcm","clk":"11910604354","pt":1724508034412,"mc":[{"id":"1.232220323","rc":[{"batl":[[0,1.65,44.31],[1,1.94,13.6],[2,1.95,276.92]],"ltp":0.0,"tv":0.0,"id":228749}]}]}
{"op":"mcm","clk":"11910605563","pt":1724508038747,"mc":[{"id":"1.232220323","rc":[{"batl":[[0,1.95,276.92],[1,1.94,0],[2,1.95,0]],"ltp":0.0,"tv":0.0,"id":228749},{"batb":[[0,2.06,5.95]],"ltp":0.0,"tv":0.0,"id":891555}]}]}
{"op":"mcm","clk":"11910614864","pt":1724508075040,"mc":[{"id":"1.232220323","rc":[{"batl":[[0,1.94,13.91],[1,1.95,276.92]],"ltp":0.0,"tv":0.0,"id":228749},{"batb":[[0,2.06,19.24]],"ltp":0.0,"tv":0.0,"id":891555}]}]}
{"op":"mcm","clk":"11911781072","pt":1724512215454,"mc":[{"id":"1.232220323","rc":[{"trd":[[2.06,0.04]],"batb":[[0,2.06,19.22]],"ltp":2.06,"tv":0.04,"id":891555}],"tv":0.04}]}
{"op":"mcm","clk":"11911786825","pt":1724512233867,"mc":[{"id":"1.232220323","rc":[{"trd":[[2.06,0.06]],"batb":[[0,2.06,19.21]],"ltp":2.06,"tv":0.05,"id":891555}],"tv":0.05}]}
{"op":"mcm","clk":"11912384511","pt":1724518185867,"mc":[{"id":"1.232220323","rc":[{"batl":[[0,1.9,12.47],[1,1.94,13.91],[2,1.95,276.92]],"ltp":0.0,"tv":0.0,"id":228749}]}]}
{"op":"mcm","clk":"11912384972","pt":1724518189244,"mc":[{"id":"1.232220323","rc":[{"batl":[[1,1.95,276.92],[2,1.95,0]],"ltp":0.0,"tv":0.0,"id":228749}]}]}
{"op":"mcm","clk":"11912408256","pt":1724518371625,"mc":[{"id":"1.232220323","rc":[{"batl":[[0,1.88,69.23],[1,1.9,12.47],[2,1.95,276.92]],"ltp":0.0,"tv":0.0,"id":228749}]}]}
{"op":"mcm","clk":"11912408392","pt":1724518372883,"mc":[{"id":"1.232220323","rc":[{"batb":[[0,2.06,5.92]],"ltp":2.06,"tv":0.05,"id":891555}]}]}
{"op":"mcm","clk":"11912468052","pt":1724518876718,"mc":[{"id":"1.232220323","rc":[{"batb":[[0,1.6,58.68],[1,1.57,13.13],[2,1.56,138.46]],"batl":[[0,1.86,46],[1,1.88,69.23],[2,1.9,12.47]],"ltp":0.0,"tv":0.0,"id":228749}]}]}
{"op":"mcm","clk":"11912468140","pt":1724518877524,"mc":[{"id":"1.232220323","rc":[{"batb":[[1,1.57,6.03]],"ltp":0.0,"tv":0.0,"id":228749}]}]}
{"op":"mcm","clk":"11912650584","pt":1724520314427,"mc":[{"id":"1.232220323","rc":[{"batb":[[0,1.69,62.24],[1,1.6,58.68],[2,1.57,6.03]],"ltp":0.0,"tv":0.0,"id":228749},{"batb":[[0,2.32,32.53],[1,2.06,5.92],[2,1.9,738.46]],"ltp":2.06,"tv":0.05,"id":891555}]}]}
{"op":"mcm","clk":"11912658836","pt":1724520376868,"mc":[{"id":"1.232220323","rc":[{"batb":[[1,1.57,6.03],[2,1.56,138.46]],"batl":[[0,1.88,69.23],[1,1.9,12.47],[2,1.95,276.92]],"ltp":0.0,"tv":0.0,"id":228749}]}]}
{"op":"mcm","clk":"11912689984","pt":1724520637103,"mc":[{"id":"1.232220323","rc":[{"trd":[[1.76,0.22]],"ltp":1.76,"tv":0.22,"id":228749},{"trd":[[2.32,0.17]],"batb":[[0,2.32,32.36]],"ltp":2.32,"tv":0.22,"id":891555}],"tv":0.44}]}
{"op":"mcm","clk":"11912690459","pt":1724520640301,"mc":[{"id":"1.232220323","rc":[{"batb":[[0,2.32,32.53]],"ltp":2.32,"tv":0.22,"id":891555}]}]}
{"op":"mcm","clk":"11912717986","pt":1724520840076,"mc":[{"id":"1.232220323","rc":[{"batb":[[1,1.56,138.46],[2,1.52,492.31]],"ltp":1.76,"tv":0.22,"id":228749},{"batb":[[1,1.9,738.46],[2,1.85,738.46]],"ltp":2.32,"tv":0.22,"id":891555}]}]}
{"op":"mcm","clk":"11913131862","pt":1724523433016,"mc":[{"id":"1.232220323","rc":[{"batl":[[1,1.89,749.38],[2,1.9,12.47]],"ltp":1.76,"tv":0.22,"id":228749}]}]}
{"op":"mcm","clk":"11913159404","pt":1724523590461,"mc":[{"id":"1.232220323","rc":[{"batl":[[0,1.72,103.87],[1,1.88,69.23],[2,1.89,749.38]],"ltp":1.76,"tv":0.22,"id":228749}]}]}
{"op":"mcm","clk":"11913302447","pt":1724524339506,"mc":[{"id":"1.232220323","rc":[{"batl":[[0,1.71,5.1],[1,1.72,103.87],[2,1.88,69.23]],"ltp":1.76,"tv":0.22,"id":228749}]}]}
{"op":"mcm","clk":"11913445103","pt":1724524973599,"mc":[{"id":"1.232220323","rc":[{"batl":[[1,1.88,69.23],[2,1.89,749.38]],"ltp":1.76,"tv":0.22,"id":228749}]}]}
{"op":"mcm","clk":"11913445462","pt":1724524975359,"mc":[{"id":"1.232220323","rc":[{"batl":[[0,1.88,69.23],[1,1.89,749.38],[2,1.9,12.47]],"ltp":1.76,"tv":0.22,"id":228749}]}]}
{"op":"mcm","clk":"11913594165","pt":1724525728139,"mc":[{"id":"1.232220323","rc":[{"batl":[[0,2.36,20]],"ltp":2.32,"tv":0.22,"id":891555}]}]}
{"op":"mcm","clk":"11913800447","pt":1724526774769,"mc":[{"id":"1.232220323","rc":[{"batl":[[1,1.89,748.98]],"ltp":1.76,"tv":0.22,"id":228749}]}]}
{"op":"mcm","clk":"11913993195","pt":1724527662096,"mc":[{"id":"1.232220323","rc":[{"batl":[[1,2.44,4]],"ltp":2.32,"tv":0.22,"id":891555}]}]}
{"op":"mcm","clk":"11914794919","pt":1724532691872,"mc":[{"id":"1.232220323","rc":[{"batl":[[0,1.87,748.98],[1,1.88,69.23]],"ltp":1.76,"tv":0.22,"id":228749}]}]}
{"op":"mcm","clk":"11914814616","pt":1724532926292,"mc":[{"id":"1.232220323","rc":[{"batb":[[1,1.9,998.13]],"ltp":2.32,"tv":0.22,"id":891555}]}]}
{"op":"mcm","clk":"11914816479","pt":1724532951555,"mc":[{"id":"1.232220323","rc":[{"batb":[[2,1.52,751.98]],"ltp":1.76,"tv":0.22,"id":228749}]}]}
{"op":"mcm","clk":"11914817302","pt":1724532962223,"mc":[{"id":"1.232220323","rc":[{"batb":[[1,1.56,398.13]],"ltp":1.76,"tv":0.22,"id":228749}]}]}
{"op":"mcm","clk":"11914818039","pt":1724532971758,"mc":[{"id":"1.232220323","rc":[{"batb":[[1,1.6,259.67],[2,1.56,398.13]],"ltp":1.76,"tv":0.22,"id":228749}]}]}
{"op":"mcm","clk":"11914905094","pt":1724534130739,"mc":[{"id":"1.232220323","rc":[{"batb":[[0,1.75,514.67],[1,1.69,62.24],[2,1.6,259.67]],"ltp":1.76,"tv":0.22,"id":228749}]}]}
{"op":"mcm","clk":"11915163500","pt":1724537829287,"mc":[{"id":"1.232220323","rc":[{"trd":[[1.75,1028.9]],"batb":[[0,1.69,62.46],[1,1.6,259.67],[2,1.56,398.13]],"ltp":1.75,"tv":1029.12,"id":228749}],"tv":1029.35}]}
{"op":"mcm","clk":"11915222201","pt":1724538802081,"mc":[{"id":"1.232220323","rc":[{"trd":[[1.69,27],[1.73,27.28],[1.75,1029.34]],"batb":[[0,1.69,62.24]],"ltp":1.69,"tv":1083.83,"id":228749},{"trd":[[2.36,20]],"batb":[[0,2.34,5],[1,2.32,32.53],[2,1.9,998.13]],"batl":[[0,2.44,4],[1,2.44,0]],"ltp":2.36,"tv":20.22,"id":891555}],"tv":1104.06}]}
{"op":"mcm","clk":"11915222401","pt":1724538804873,"mc":[{"id":"1.232220323","rc":[{"batb":[[0,2.32,32.53],[1,1.9,998.13],[2,1.85,738.46]],"ltp":2.36,"tv":20.22,"id":891555}]}]}
{"op":"mcm","clk":"11915223947","pt":1724538833329,"mc":[{"id":"1.232220323","rc":[{"batb":[[0,1.7,5.11],[1,1.69,62.24],[2,1.6,259.67]],"ltp":1.69,"tv":1083.83,"id":228749},{"batb":[[0,2.34,5],[1,2.32,32.53],[2,1.9,998.13]],"ltp":2.36,"tv":20.22,"id":891555}]}]}
{"op":"mcm","clk":"11915224145","pt":1724538836732,"mc":[{"id":"1.232220323","rc":[{"batb":[[0,2.32,32.53],[1,1.9,998.13],[2,1.85,738.46]],"ltp":2.36,"tv":20.22,"id":891555}]}]}
{"op":"mcm","clk":"11915224575","pt":1724538844448,"mc":[{"id":"1.232220323","rc":[{"batb":[[0,2.34,5],[1,2.32,32.53],[2,1.9,998.13]],"ltp":2.36,"tv":20.22,"id":891555}]}]}
{"op":"mcm","clk":"11915224785","pt":1724538848043,"mc":[{"id":"1.232220323","rc":[{"batb":[[0,2.32,32.53],[1,1.9,998.13],[2,1.85,738.46]],"ltp":2.36,"tv":20.22,"id":891555}]}]}
{"op":"mcm","clk":"11915227059","pt":1724538890673,"mc":[{"id":"1.232220323","rc":[{"batb":[[0,2.34,5],[1,2.32,32.53],[2,1.9,998.13]],"ltp":2.36,"tv":20.22,"id":891555}]}]}
{"op":"mcm","clk":"11915227227","pt":1724538893961,"mc":[{"id":"1.232220323","rc":[{"batb":[[0,2.32,32.53],[1,1.9,998.13],[2,1.85,738.46]],"ltp":2.36,"tv":20.22,"id":891555}]}]}
{"op":"mcm","clk":"11915228245","pt":1724538912183,"mc":[{"id":"1.232220323","rc":[{"batb":[[0,2.34,5],[1,2.32,32.53],[2,1.9,998.13]],"ltp":2.36,"tv":20.22,"id":891555}]}]}
{"op":"mcm","clk":"11915228435","pt":1724538915776,"mc":[{"id":"1.232220323","rc":[{"batb":[[0,2.32,32.53],[1,1.9,998.13],[2,1.85,738.46]],"ltp":2.36,"tv":20.22,"id":891555}]}]}
{"op":"mcm","clk":"11915229253","pt":1724538929800,"mc":[{"id":"1.232220323","rc":[{"batb":[[0,2.34,5],[1,2.32,32.53],[2,1.9,998.13]],"ltp":2.36,"tv":20.22,"id":891555}]}]}
{"op":"mcm","clk":"11915229426","pt":1724538933321,"mc":[{"id":"1.232220323","rc":[{"batb":[[0,2.32,32.53],[1,1.9,998.13],[2,1.85,738.46]],"ltp":2.36,"tv":20.22,"id":891555}]}]}
{"op":"mcm","clk":"11915230198","pt":1724538949624,"mc":[{"id":"1.232220323","rc":[{"batb":[[0,2.34,5],[1,2.32,32.53],[2,1.9,998.13]],"ltp":2.36,"tv":20.22,"id":891555}]}]}
{"op":"mcm","clk":"11915230355","pt":1724538953056,"mc":[{"id":"1.232220323","rc":[{"batb":[[0,2.32,32.53],[1,1.9,998.13],[2,1.85,738.46]],"ltp":2.36,"tv":20.22,"id":891555}]}]}
{"op":"mcm","clk":"11915230863","pt":1724538963655,"mc":[{"id":"1.232220323","rc":[{"batb":[[0,2.34,5],[1,2.32,32.53],[2,1.9,998.13]],"ltp":2.36,"tv":20.22,"id":891555}]}]}
{"op":"mcm","clk":"11915231055","pt":1724538967043,"mc":[{"id":"1.232220323","rc":[{"batb":[[0,2.32,32.53],[1,1.9,998.13],[2,1.85,738.46]],"ltp":2.36,"tv":20.22,"id":891555}]}]}
{"op":"mcm","clk":"11915231377","pt":1724538973882,"mc":[{"id":"1.232220323","rc":[{"batb":[[0,2.34,5],[1,2.32,32.53],[2,1.9,998.13]],"ltp":2.36,"tv":20.22,"id":891555}]}]}
{"op":"mcm","clk":"11915231552","pt":1724538977289,"mc":[{"id":"1.232220323","rc":[{"batb":[[0,2.32,32.53],[1,1.9,998.13],[2,1.85,738.46]],"ltp":2.36,"tv":20.22,"id":891555}]}]}
{"op":"mcm","clk":"11915233722","pt":1724539025402,"mc":[{"id":"1.232220323","rc":[{"batb":[[0,2.34,5],[1,2.32,32.53],[2,1.9,998.13]],"ltp":2.36,"tv":20.22,"id":891555}]}]}
{"op":"mcm","clk":"11915233864","pt":1724539028890,"mc":[{"id":"1.232220323","rc":[{"batb":[[0,2.32,32.53],[1,1.9,998.13],[2,1.85,738.46]],"ltp":2.36,"tv":20.22,"id":891555}]}]}
{"op":"mcm","clk":"11915238594","pt":1724539121431,"mc":[{"id":"1.232220323","rc":[{"batb":[[0,2.34,5],[1,2.32,32.53],[2,1.9,998.13]],"ltp":2.36,"tv":20.22,"id":891555}]}]}
{"op":"mcm","clk":"11915238749","pt":1724539124735,"mc":[{"id":"1.232220323","rc":[{"batb":[[0,2.32,32.53],[1,1.9,998.13],[2,1.85,738.46]],"ltp":2.36,"tv":20.22,"id":891555}]}]}
{"op":"mcm","clk":"11915241196","pt":1724539171113,"mc":[{"id":"1.232220323","rc":[{"batb":[[0,2.34,5],[1,2.32,32.53],[2,1.9,998.13]],"ltp":2.36,"tv":20.22,"id":891555}]}]}
{"op":"mcm","clk":"11915241408","pt":1724539174714,"mc":[{"id":"1.232220323","rc":[{"batb":[[0,2.32,32.53],[1,1.9,998.13],[2,1.85,738.46]],"ltp":2.36,"tv":20.22,"id":891555}]}]}
{"op":"mcm","clk":"11915243460","pt":1724539218058,"mc":[{"id":"1.232220323","rc":[{"batb":[[0,2.34,5],[1,2.32,32.53],[2,1.9,998.13]],"ltp":2.36,"tv":20.22,"id":891555}]}]}
{"op":"mcm","clk":"11915243607","pt":1724539221554,"mc":[{"id":"1.232220323","rc":[{"batb":[[0,2.32,32.53],[1,1.9,998.13],[2,1.85,738.46]],"ltp":2.36,"tv":20.22,"id":891555}]}]}
{"op":"mcm","clk":"11915244141","pt":1724539234377,"mc":[{"id":"1.232220323","rc":[{"batb":[[0,2.34,5],[1,2.32,32.53],[2,1.9,998.13]],"ltp":2.36,"tv":20.22,"id":891555}]}]}
{"op":"mcm","clk":"11915244289","pt":1724539237862,"mc":[{"id":"1.232220323","rc":[{"batb":[[0,2.32,32.53],[1,1.9,998.13],[2,1.85,738.46]],"ltp":2.36,"tv":20.22,"id":891555}]}]}
{"op":"mcm","clk":"11915244939","pt":1724539253211,"mc":[{"id":"1.232220323","rc":[{"batb":[[0,2.34,5],[1,2.32,32.53],[2,1.9,998.13]],"ltp":2.36,"tv":20.22,"id":891555}]}]}
{"op":"mcm","clk":"11915245088","pt":1724539256713,"mc":[{"id":"1.232220323","rc":[{"batb":[[0,2.32,32.53],[1,1.9,998.13],[2,1.85,738.46]],"ltp":2.36,"tv":20.22,"id":891555}]}]}
{"op":"mcm","clk":"11915245358","pt":1724539262292,"mc":[{"id":"1.232220323","rc":[{"batb":[[0,2.34,5],[1,2.32,32.53],[2,1.9,998.13]],"ltp":2.36,"tv":20.22,"id":891555}]}]}
{"op":"mcm","clk":"11915245482","pt":1724539265629,"mc":[{"id":"1.232220323","rc":[{"batb":[[0,2.32,32.53],[1,1.9,998.13],[2,1.85,738.46]],"ltp":2.36,"tv":20.22,"id":891555}]}]}
{"op":"mcm","clk":"11915245981","pt":1724539277140,"mc":[{"id":"1.232220323","rc":[{"batb":[[0,2.34,5],[1,2.32,32.53],[2,1.9,998.13]],"ltp":2.36,"tv":20.22,"id":891555}]}]}
{"op":"mcm","clk":"11915246161","pt":1724539280531,"mc":[{"id":"1.232220323","rc":[{"batb":[[0,2.32,32.53],[1,1.9,998.13],[2,1.85,738.46]],"ltp":2.36,"tv":20.22,"id":891555}]}]}
{"op":"mcm","clk":"11915246477","pt":1724539287827,"mc":[{"id":"1.232220323","rc":[{"batb":[[0,2.34,5],[1,2.32,32.53],[2,1.9,998.13]],"ltp":2.36,"tv":20.22,"id":891555}]}]}
{"op":"mcm","clk":"11915246629","pt":1724539291468,"mc":[{"id":"1.232220323","rc":[{"batb":[[0,2.32,32.53],[1,1.9,998.13],[2,1.85,738.46]],"ltp":2.36,"tv":20.22,"id":891555}]}]}
{"op":"mcm","clk":"11915247190","pt":1724539306343,"mc":[{"id":"1.232220323","rc":[{"batb":[[0,2.34,5],[1,2.32,32.53],[2,1.9,998.13]],"ltp":2.36,"tv":20.22,"id":891555}]}]}
{"op":"mcm","clk":"11915247320","pt":1724539309848,"mc":[{"id":"1.232220323","rc":[{"batb":[[0,2.32,32.53],[1,1.9,998.13],[2,1.85,738.46]],"ltp":2.36,"tv":20.22,"id":891555}]}]}
{"op":"mcm","clk":"11915247615","pt":1724539316363,"mc":[{"id":"1.232220323","rc":[{"batb":[[0,2.34,5],[1,2.32,32.53],[2,1.9,998.13]],"ltp":2.36,"tv":20.22,"id":891555}]}]}
{"op":"mcm","clk":"11915247770","pt":1724539319755,"mc":[{"id":"1.232220323","rc":[{"batb":[[0,2.32,32.53],[1,1.9,998.13],[2,1.85,738.46]],"ltp":2.36,"tv":20.22,"id":891555}]}]}
{"op":"mcm","clk":"11915248000","pt":1724539324691,"mc":[{"id":"1.232220323","rc":[{"batb":[[0,2.34,5],[1,2.32,32.53],[2,1.9,998.13]],"ltp":2.36,"tv":20.22,"id":891555}]}]}
{"op":"mcm","clk":"11915248151","pt":1724539327984,"mc":[{"id":"1.232220323","rc":[{"batb":[[0,2.32,32.53],[1,1.9,998.13],[2,1.85,738.46]],"ltp":2.36,"tv":20.22,"id":891555}]}]}
{"op":"mcm","clk":"11915248359","pt":1724539331788,"mc":[{"id":"1.232220323","rc":[{"batb":[[0,2.34,5],[1,2.32,32.53],[2,1.9,998.13]],"ltp":2.36,"tv":20.22,"id":891555}]}]}
{"op":"mcm","clk":"11915248499","pt":1724539335080,"mc":[{"id":"1.232220323","rc":[{"batb":[[0,2.32,32.53],[1,1.9,998.13],[2,1.85,738.46]],"ltp":2.36,"tv":20.22,"id":891555}]}]}
{"op":"mcm","clk":"11915248793","pt":1724539340985,"mc":[{"id":"1.232220323","rc":[{"batb":[[0,2.34,5],[1,2.32,32.53],[2,1.9,998.13]],"ltp":2.36,"tv":20.22,"id":891555}]}]}
{"op":"mcm","clk":"11915248938","pt":1724539344475,"mc":[{"id":"1.232220323","rc":[{"batb":[[0,2.32,32.53],[1,1.9,998.13],[2,1.85,738.46]],"ltp":2.36,"tv":20.22,"id":891555}]}]}
{"op":"mcm","clk":"11915249098","pt":1724539347810,"mc":[{"id":"1.232220323","rc":[{"batb":[[0,2.34,5],[1,2.32,32.53],[2,1.9,998.13]],"ltp":2.36,"tv":20.22,"id":891555}]}]}
{"op":"mcm","clk":"11915249238","pt":1724539351200,"mc":[{"id":"1.232220323","rc":[{"batb":[[0,2.32,32.53],[1,1.9,998.13],[2,1.85,738.46]],"ltp":2.36,"tv":20.22,"id":891555}]}]}
{"op":"mcm","clk":"11915249400","pt":1724539354798,"mc":[{"id":"1.232220323","rc":[{"batb":[[0,2.34,5],[1,2.32,32.53],[2,1.9,998.13]],"ltp":2.36,"tv":20.22,"id":891555}]}]}
{"op":"mcm","clk":"11915249532","pt":1724539358293,"mc":[{"id":"1.232220323","rc":[{"batb":[[0,2.32,32.53],[1,1.9,998.13],[2,1.85,738.46]],"ltp":2.36,"tv":20.22,"id":891555}]}]}
{"op":"mcm","clk":"11915249752","pt":1724539362806,"mc":[{"id":"1.232220323","rc":[{"batb":[[0,2.34,5],[1,2.32,32.53],[2,1.9,998.13]],"ltp":2.36,"tv":20.22,"id":891555}]}]}
{"op":"mcm","clk":"11915249906","pt":1724539366202,"mc":[{"id":"1.232220323","rc":[{"batb":[[0,2.32,32.53],[1,1.9,998.13],[2,1.85,738.46]],"ltp":2.36,"tv":20.22,"id":891555}]}]}
{"op":"mcm","clk":"11915250131","pt":1724539369831,"mc":[{"id":"1.232220323","rc":[{"batb":[[0,2.34,5],[1,2.32,32.53],[2,1.9,998.13]],"ltp":2.36,"tv":20.22,"id":891555}]}]}
{"op":"mcm","clk":"11915250285","pt":1724539373121,"mc":[{"id":"1.232220323","rc":[{"batb":[[0,2.32,32.53],[1,1.9,998.13],[2,1.85,738.46]],"ltp":2.36,"tv":20.22,"id":891555}]}]}
{"op":"mcm","clk":"11915250594","pt":1724539379437,"mc":[{"id":"1.232220323","rc":[{"batb":[[0,2.34,5],[1,2.32,32.53],[2,1.9,998.13]],"ltp":2.36,"tv":20.22,"id":891555}]}]}
{"op":"mcm","clk":"11915250814","pt":1724539383039,"mc":[{"id":"1.232220323","rc":[{"batb":[[0,2.32,32.53],[1,1.9,998.13],[2,1.85,738.46]],"ltp":2.36,"tv":20.22,"id":891555}]}]}
{"op":"mcm","clk":"11915250942","pt":1724539385767,"mc":[{"id":"1.232220323","rc":[{"batb":[[0,2.34,5],[1,2.32,32.53],[2,1.9,998.13]],"ltp":2.36,"tv":20.22,"id":891555}]}]}
{"op":"mcm","clk":"11915251101","pt":1724539389264,"mc":[{"id":"1.232220323","rc":[{"batb":[[0,2.32,32.53],[1,1.9,998.13],[2,1.85,738.46]],"ltp":2.36,"tv":20.22,"id":891555}]}]}
{"op":"mcm","clk":"11915251261","pt":1724539392658,"mc":[{"id":"1.232220323","rc":[{"batb":[[0,2.34,5],[1,2.32,32.53],[2,1.9,998.13]],"ltp":2.36,"tv":20.22,"id":891555}]}]}
{"op":"mcm","clk":"11915251400","pt":1724539395952,"mc":[{"id":"1.232220323","rc":[{"batb":[[0,2.32,32.53],[1,1.9,998.13],[2,1.85,738.46]],"ltp":2.36,"tv":20.22,"id":891555}]}]}
{"op":"mcm","clk":"11915251525","pt":1724539398241,"mc":[{"id":"1.232220323","rc":[{"batb":[[0,2.34,5],[1,2.32,32.53],[2,1.9,998.13]],"ltp":2.36,"tv":20.22,"id":891555}]}]}
{"op":"mcm","clk":"11915251680","pt":1724539401781,"mc":[{"id":"1.232220323","rc":[{"batb":[[0,2.32,32.53],[1,1.9,998.13],[2,1.85,738.46]],"ltp":2.36,"tv":20.22,"id":891555}]}]}
{"op":"mcm","clk":"11915251913","pt":1724539406471,"mc":[{"id":"1.232220323","rc":[{"batb":[[0,2.34,5],[1,2.32,32.53],[2,1.9,998.13]],"ltp":2.36,"tv":20.22,"id":891555}]}]}
{"op":"mcm","clk":"11915252082","pt":1724539409658,"mc":[{"id":"1.232220323","rc":[{"batb":[[0,2.32,32.53],[1,1.9,998.13],[2,1.85,738.46]],"ltp":2.36,"tv":20.22,"id":891555}]}]}
{"op":"mcm","clk":"11915252327","pt":1724539415256,"mc":[{"id":"1.232220323","rc":[{"batb":[[0,2.34,5],[1,2.32,32.53],[2,1.9,998.13]],"ltp":2.36,"tv":20.22,"id":891555}]}]}
{"op":"mcm","clk":"11915252478","pt":1724539418697,"mc":[{"id":"1.232220323","rc":[{"batb":[[0,2.32,32.53],[1,1.9,998.13],[2,1.85,738.46]],"ltp":2.36,"tv":20.22,"id":891555}]}]}
{"op":"mcm","clk":"11915252718","pt":1724539424513,"mc":[{"id":"1.232220323","rc":[{"batb":[[0,2.34,5],[1,2.32,32.53],[2,1.9,998.13]],"ltp":2.36,"tv":20.22,"id":891555}]}]}
{"op":"mcm","clk":"11915252895","pt":1724539427798,"mc":[{"id":"1.232220323","rc":[{"batb":[[0,2.32,32.53],[1,1.9,998.13],[2,1.85,738.46]],"ltp":2.36,"tv":20.22,"id":891555}]}]}
{"op":"mcm","clk":"11915253010","pt":1724539430305,"mc":[{"id":"1.232220323","rc":[{"batb":[[0,2.34,5],[1,2.32,32.53],[2,1.9,998.13]],"ltp":2.36,"tv":20.22,"id":891555}]}]}
{"op":"mcm","clk":"11915253136","pt":1724539433534,"mc":[{"id":"1.232220323","rc":[{"batb":[[0,2.32,32.53],[1,1.9,998.13],[2,1.85,738.46]],"ltp":2.36,"tv":20.22,"id":891555}]}]}
{"op":"mcm","clk":"11915253413","pt":1724539439239,"mc":[{"id":"1.232220323","rc":[{"batb":[[0,2.34,5],[1,2.32,32.53],[2,1.9,998.13]],"ltp":2.36,"tv":20.22,"id":891555}]}]}
{"op":"mcm","clk":"11915253567","pt":1724539442430,"mc":[{"id":"1.232220323","rc":[{"batb":[[0,2.32,32.53],[1,1.9,998.13],[2,1.85,738.46]],"ltp":2.36,"tv":20.22,"id":891555}]}]}
{"op":"mcm","clk":"11915253878","pt":1724539449832,"mc":[{"id":"1.232220323","rc":[{"batb":[[0,2.34,5],[1,2.32,32.53],[2,1.9,998.13]],"ltp":2.36,"tv":20.22,"id":891555}]}]}
{"op":"mcm","clk":"11915254056","pt":1724539453226,"mc":[{"id":"1.232220323","rc":[{"batb":[[0,2.32,32.53],[1,1.9,998.13],[2,1.85,738.46]],"ltp":2.36,"tv":20.22,"id":891555}]}]}
{"op":"mcm","clk":"11915254381","pt":1724539460361,"mc":[{"id":"1.232220323","rc":[{"batb":[[0,2.34,5],[1,2.32,32.53],[2,1.9,998.13]],"ltp":2.36,"tv":20.22,"id":891555}]}]}
{"op":"mcm","clk":"11915254537","pt":1724539463964,"mc":[{"id":"1.232220323","rc":[{"batb":[[0,2.32,32.53],[1,1.9,998.13],[2,1.85,738.46]],"ltp":2.36,"tv":20.22,"id":891555}]}]}
{"op":"mcm","clk":"11915254657","pt":1724539466423,"mc":[{"id":"1.232220323","rc":[{"batb":[[0,2.34,5],[1,2.32,32.53],[2,1.9,998.13]],"ltp":2.36,"tv":20.22,"id":891555}]}]}
{"op":"mcm","clk":"11915254792","pt":1724539469629,"mc":[{"id":"1.232220323","rc":[{"batb":[[0,2.32,32.53],[1,1.9,998.13],[2,1.85,738.46]],"ltp":2.36,"tv":20.22,"id":891555}]}]}
{"op":"mcm","clk":"11915254924","pt":1724539472350,"mc":[{"id":"1.232220323","rc":[{"batb":[[0,2.34,5],[1,2.32,32.53],[2,1.9,998.13]],"ltp":2.36,"tv":20.22,"id":891555}]}]}
{"op":"mcm","clk":"11915255037","pt":1724539475742,"mc":[{"id":"1.232220323","rc":[{"batb":[[0,2.32,32.53],[1,1.9,998.13],[2,1.85,738.46]],"ltp":2.36,"tv":20.22,"id":891555}]}]}
{"op":"mcm","clk":"11915255203","pt":1724539479345,"mc":[{"id":"1.232220323","rc":[{"batb":[[0,2.34,5],[1,2.32,32.53],[2,1.9,998.13]],"ltp":2.36,"tv":20.22,"id":891555}]}]}
{"op":"mcm","clk":"11915255362","pt":1724539482880,"mc":[{"id":"1.232220323","rc":[{"batb":[[0,2.32,32.53],[1,1.9,998.13],[2,1.85,738.46]],"ltp":2.36,"tv":20.22,"id":891555}]}]}
{"op":"mcm","clk":"11915255484","pt":1724539485352,"mc":[{"id":"1.232220323","rc":[{"batb":[[0,2.34,5],[1,2.32,32.53],[2,1.9,998.13]],"ltp":2.36,"tv":20.22,"id":891555}]}]}
{"op":"mcm","clk":"11915255668","pt":1724539488943,"mc":[{"id":"1.232220323","rc":[{"batb":[[0,2.32,32.53],[1,1.9,998.13],[2,1.85,738.46]],"ltp":2.36,"tv":20.22,"id":891555}]}]}
{"op":"mcm","clk":"11915255836","pt":1724539492379,"mc":[{"id":"1.232220323","rc":[{"batb":[[0,2.34,5],[1,2.32,32.53],[2,1.9,998.13]],"ltp":2.36,"tv":20.22,"id":891555}]}]}
{"op":"mcm","clk":"11915256010","pt":1724539495871,"mc":[{"id":"1.232220323","rc":[{"batb":[[0,2.32,32.53],[1,1.9,998.13],[2,1.85,738.46]],"ltp":2.36,"tv":20.22,"id":891555}]}]}
{"op":"mcm","clk":"11915256152","pt":1724539499007,"mc":[{"id":"1.232220323","rc":[{"batb":[[0,2.34,5],[1,2.32,32.53],[2,1.9,998.13]],"ltp":2.36,"tv":20.22,"id":891555}]}]}
{"op":"mcm","clk":"11915256311","pt":1724539502273,"mc":[{"id":"1.232220323","rc":[{"batb":[[0,2.32,32.53],[1,1.9,998.13],[2,1.85,738.46]],"ltp":2.36,"tv":20.22,"id":891555}]}]}
{"op":"mcm","clk":"11915256487","pt":1724539506002,"mc":[{"id":"1.232220323","rc":[{"batb":[[0,2.34,5],[1,2.32,32.53],[2,1.9,998.13]],"ltp":2.36,"tv":20.22,"id":891555}]}]}
{"op":"mcm","clk":"11915256612","pt":1724539509393,"mc":[{"id":"1.232220323","rc":[{"batb":[[0,2.32,32.53],[1,1.9,998.13],[2,1.85,738.46]],"ltp":2.36,"tv":20.22,"id":891555}]}]}
{"op":"mcm","clk":"11915256755","pt":1724539512481,"mc":[{"id":"1.232220323","rc":[{"batb":[[0,2.34,5],[1,2.32,32.53],[2,1.9,998.13]],"ltp":2.36,"tv":20.22,"id":891555}]}]}
{"op":"mcm","clk":"11915256900","pt":1724539515769,"mc":[{"id":"1.232220323","rc":[{"batb":[[0,2.32,32.53],[1,1.9,998.13],[2,1.85,738.46]],"ltp":2.36,"tv":20.22,"id":891555}]}]}
{"op":"mcm","clk":"11915257062","pt":1724539519216,"mc":[{"id":"1.232220323","rc":[{"batb":[[0,2.34,5],[1,2.32,32.53],[2,1.9,998.13]],"ltp":2.36,"tv":20.22,"id":891555}]}]}
{"op":"mcm","clk":"11915257201","pt":1724539522410,"mc":[{"id":"1.232220323","rc":[{"batb":[[0,2.32,32.53],[1,1.9,998.13],[2,1.85,738.46]],"ltp":2.36,"tv":20.22,"id":891555}]}]}
{"op":"mcm","clk":"11915257449","pt":1724539528512,"mc":[{"id":"1.232220323","rc":[{"batb":[[0,2.34,5],[1,2.32,32.53],[2,1.9,998.13]],"ltp":2.36,"tv":20.22,"id":891555}]}]}
{"op":"mcm","clk":"11915257600","pt":1724539531905,"mc":[{"id":"1.232220323","rc":[{"batb":[[0,2.32,32.53],[1,1.9,998.13],[2,1.85,738.46]],"ltp":2.36,"tv":20.22,"id":891555}]}]}
{"op":"mcm","clk":"11915257690","pt":1724539534319,"mc":[{"id":"1.232220323","rc":[{"batb":[[0,2.34,5],[1,2.32,32.53],[2,1.9,998.13]],"ltp":2.36,"tv":20.22,"id":891555}]}]}
{"op":"mcm","clk":"11915257822","pt":1724539537611,"mc":[{"id":"1.232220323","rc":[{"batb":[[0,2.32,32.53],[1,1.9,998.13],[2,1.85,738.46]],"ltp":2.36,"tv":20.22,"id":891555}]}]}
{"op":"mcm","clk":"11915257948","pt":1724539541401,"mc":[{"id":"1.232220323","rc":[{"batb":[[0,2.34,5],[1,2.32,32.53],[2,1.9,998.13]],"ltp":2.36,"tv":20.22,"id":891555}]}]}
{"op":"mcm","clk":"11915258088","pt":1724539544736,"mc":[{"id":"1.232220323","rc":[{"batb":[[0,2.32,32.53],[1,1.9,998.13],[2,1.85,738.46]],"ltp":2.36,"tv":20.22,"id":891555}]}]}
{"op":"mcm","clk":"11915258229","pt":1724539547717,"mc":[{"id":"1.232220323","rc":[{"batb":[[0,2.34,5],[1,2.32,32.53],[2,1.9,998.13]],"ltp":2.36,"tv":20.22,"id":891555}]}]}
{"op":"mcm","clk":"11915258407","pt":1724539551164,"mc":[{"id":"1.232220323","rc":[{"batb":[[0,2.32,32.53],[1,1.9,998.13],[2,1.85,738.46]],"ltp":2.36,"tv":20.22,"id":891555}]}]}
{"op":"mcm","clk":"11915258520","pt":1724539554250,"mc":[{"id":"1.232220323","rc":[{"batb":[[0,2.34,5],[1,2.32,32.53],[2,1.9,998.13]],"ltp":2.36,"tv":20.22,"id":891555}]}]}
{"op":"mcm","clk":"11915258648","pt":1724539557539,"mc":[{"id":"1.232220323","rc":[{"batb":[[0,2.32,32.53],[1,1.9,998.13],[2,1.85,738.46]],"ltp":2.36,"tv":20.22,"id":891555}]}]}
{"op":"mcm","clk":"11915258758","pt":1724539559748,"mc":[{"id":"1.232220323","rc":[{"batb":[[0,2.34,5],[1,2.32,32.53],[2,1.9,998.13]],"ltp":2.36,"tv":20.22,"id":891555}]}]}
{"op":"mcm","clk":"11915258891","pt":1724539563046,"mc":[{"id":"1.232220323","rc":[{"batb":[[0,2.32,32.53],[1,1.9,998.13],[2,1.85,738.46]],"ltp":2.36,"tv":20.22,"id":891555}]}]}
{"op":"mcm","clk":"11915259011","pt":1724539566745,"mc":[{"id":"1.232220323","rc":[{"batb":[[0,2.34,5],[1,2.32,32.53],[2,1.9,998.13]],"ltp":2.36,"tv":20.22,"id":891555}]}]}
{"op":"mcm","clk":"11915259170","pt":1724539570256,"mc":[{"id":"1.232220323","rc":[{"batb":[[0,2.32,32.53],[1,1.9,998.13],[2,1.85,738.46]],"ltp":2.36,"tv":20.22,"id":891555}]}]}
{"op":"mcm","clk":"11915259342","pt":1724539574572,"mc":[{"id":"1.232220323","rc":[{"batb":[[0,2.34,5],[1,2.32,32.53],[2,1.9,998.13]],"ltp":2.36,"tv":20.22,"id":891555}]}]}
{"op":"mcm","clk":"11915259492","pt":1724539578072,"mc":[{"id":"1.232220323","rc":[{"batb":[[0,2.32,32.53],[1,1.9,998.13],[2,1.85,738.46]],"ltp":2.36,"tv":20.22,"id":891555}]}]}
{"op":"mcm","clk":"11915259601","pt":1724539580485,"mc":[{"id":"1.232220323","rc":[{"batb":[[0,2.34,5],[1,2.32,32.53],[2,1.9,998.13]],"ltp":2.36,"tv":20.22,"id":891555}]}]}
{"op":"mcm","clk":"11915259730","pt":1724539583979,"mc":[{"id":"1.232220323","rc":[{"batb":[[0,2.32,32.53],[1,1.9,998.13],[2,1.85,738.46]],"ltp":2.36,"tv":20.22,"id":891555}]}]}
{"op":"mcm","clk":"11915259938","pt":1724539589269,"mc":[{"id":"1.232220323","rc":[{"batb":[[0,2.34,5],[1,2.32,32.53],[2,1.9,998.13]],"ltp":2.36,"tv":20.22,"id":891555}]}]}
{"op":"mcm","clk":"11915260097","pt":1724539592466,"mc":[{"id":"1.232220323","rc":[{"batb":[[0,2.32,32.53],[1,1.9,998.13],[2,1.85,738.46]],"ltp":2.36,"tv":20.22,"id":891555}]}]}
{"op":"mcm","clk":"11915260402","pt":1724539599407,"mc":[{"id":"1.232220323","rc":[{"batb":[[0,2.34,5],[1,2.32,32.53],[2,1.9,998.13]],"ltp":2.36,"tv":20.22,"id":891555}]}]}
{"op":"mcm","clk":"11915260570","pt":1724539602903,"mc":[{"id":"1.232220323","rc":[{"batb":[[0,2.32,32.53],[1,1.9,998.13],[2,1.85,738.46]],"ltp":2.36,"tv":20.22,"id":891555}]}]}
{"op":"mcm","clk":"11915260693","pt":1724539605113,"mc":[{"id":"1.232220323","rc":[{"batb":[[0,2.34,5],[1,2.32,32.53],[2,1.9,998.13]],"ltp":2.36,"tv":20.22,"id":891555}]}]}
{"op":"mcm","clk":"11915260832","pt":1724539608404,"mc":[{"id":"1.232220323","rc":[{"batb":[[0,2.32,32.53],[1,1.9,998.13],[2,1.85,738.46]],"ltp":2.36,"tv":20.22,"id":891555}]}]}
{"op":"mcm","clk":"11915260919","pt":1724539610616,"mc":[{"id":"1.232220323","rc":[{"batb":[[0,2.34,5],[1,2.32,32.53],[2,1.9,998.13]],"ltp":2.36,"tv":20.22,"id":891555}]}]}
{"op":"mcm","clk":"11915261075","pt":1724539613911,"mc":[{"id":"1.232220323","rc":[{"batb":[[0,2.32,32.53],[1,1.9,998.13],[2,1.85,738.46]],"ltp":2.36,"tv":20.22,"id":891555}]}]}
{"op":"mcm","clk":"11915261186","pt":1724539616529,"mc":[{"id":"1.232220323","rc":[{"batb":[[0,2.34,5],[1,2.32,32.53],[2,1.9,998.13]],"ltp":2.36,"tv":20.22,"id":891555}]}]}
{"op":"mcm","clk":"11915261345","pt":1724539619811,"mc":[{"id":"1.232220323","rc":[{"batb":[[0,2.32,32.53],[1,1.9,998.13],[2,1.85,738.46]],"ltp":2.36,"tv":20.22,"id":891555}]}]}
{"op":"mcm","clk":"11915261467","pt":1724539622230,"mc":[{"id":"1.232220323","rc":[{"batb":[[0,2.34,5],[1,2.32,32.53],[2,1.9,998.13]],"ltp":2.36,"tv":20.22,"id":891555}]}]}
{"op":"mcm","clk":"11915261613","pt":1724539625526,"mc":[{"id":"1.232220323","rc":[{"batb":[[0,2.32,32.53],[1,1.9,998.13],[2,1.85,738.46]],"ltp":2.36,"tv":20.22,"id":891555}]}]}
{"op":"mcm","clk":"11915261762","pt":1724539628008,"mc":[{"id":"1.232220323","rc":[{"batb":[[0,2.34,5],[1,2.32,32.53],[2,1.9,998.13]],"ltp":2.36,"tv":20.22,"id":891555}]}]}
{"op":"mcm","clk":"11915261931","pt":1724539631538,"mc":[{"id":"1.232220323","rc":[{"batb":[[0,2.32,32.53],[1,1.9,998.13],[2,1.85,738.46]],"ltp":2.36,"tv":20.22,"id":891555}]}]}
{"op":"mcm","clk":"11915262085","pt":1724539634155,"mc":[{"id":"1.232220323","rc":[{"batb":[[0,2.34,5],[1,2.32,32.53],[2,1.9,998.13]],"ltp":2.36,"tv":20.22,"id":891555}]}]}
{"op":"mcm","clk":"11915262227","pt":1724539637437,"mc":[{"id":"1.232220323","rc":[{"batb":[[0,2.32,32.53],[1,1.9,998.13],[2,1.85,738.46]],"ltp":2.36,"tv":20.22,"id":891555}]}]}
{"op":"mcm","clk":"11915262446","pt":1724539642410,"mc":[{"id":"1.232220323","rc":[{"batb":[[0,2.34,5],[1,2.32,32.53],[2,1.9,998.13]],"ltp":2.36,"tv":20.22,"id":891555}]}]}
{"op":"mcm","clk":"11915262600","pt":1724539645753,"mc":[{"id":"1.232220323","rc":[{"batb":[[0,2.32,32.53],[1,1.9,998.13],[2,1.85,738.46]],"ltp":2.36,"tv":20.22,"id":891555}]}]}
{"op":"mcm","clk":"11915262944","pt":1724539651622,"mc":[{"id":"1.232220323","rc":[{"batb":[[0,2.34,5],[1,2.32,32.53],[2,1.9,998.13]],"ltp":2.36,"tv":20.22,"id":891555}]}]}
{"op":"mcm","clk":"11915263107","pt":1724539655038,"mc":[{"id":"1.232220323","rc":[{"batb":[[0,2.32,32.53],[1,1.9,998.13],[2,1.85,738.46]],"ltp":2.36,"tv":20.22,"id":891555}]}]}
{"op":"mcm","clk":"11915263207","pt":1724539657448,"mc":[{"id":"1.232220323","rc":[{"batb":[[0,2.34,5],[1,2.32,32.53],[2,1.9,998.13]],"ltp":2.36,"tv":20.22,"id":891555}]}]}
{"op":"mcm","clk":"11915263361","pt":1724539660679,"mc":[{"id":"1.232220323","rc":[{"batb":[[0,2.32,32.53],[1,1.9,998.13],[2,1.85,738.46]],"ltp":2.36,"tv":20.22,"id":891555}]}]}
{"op":"mcm","clk":"11915263482","pt":1724539663455,"mc":[{"id":"1.232220323","rc":[{"batb":[[0,2.34,5],[1,2.32,32.53],[2,1.9,998.13]],"ltp":2.36,"tv":20.22,"id":891555}]}]}
{"op":"mcm","clk":"11915263614","pt":1724539666678,"mc":[{"id":"1.232220323","rc":[{"batb":[[0,2.32,32.53],[1,1.9,998.13],[2,1.85,738.46]],"ltp":2.36,"tv":20.22,"id":891555}]}]}
{"op":"mcm","clk":"11915263813","pt":1724539671185,"mc":[{"id":"1.232220323","rc":[{"batb":[[0,2.34,5],[1,2.32,32.53],[2,1.9,998.13]],"ltp":2.36,"tv":20.22,"id":891555}]}]}
{"op":"mcm","clk":"11915263980","pt":1724539674786,"mc":[{"id":"1.232220323","rc":[{"batb":[[0,2.32,32.53],[1,1.9,998.13],[2,1.85,738.46]],"ltp":2.36,"tv":20.22,"id":891555}]}]}
{"op":"mcm","clk":"11915264103","pt":1724539677868,"mc":[{"id":"1.232220323","rc":[{"batb":[[0,2.34,5],[1,2.32,32.53],[2,1.9,998.13]],"ltp":2.36,"tv":20.22,"id":891555}]}]}
{"op":"mcm","clk":"11915264278","pt":1724539681068,"mc":[{"id":"1.232220323","rc":[{"batb":[[0,2.32,32.53],[1,1.9,998.13],[2,1.85,738.46]],"ltp":2.36,"tv":20.22,"id":891555}]}]}
{"op":"mcm","clk":"11915264396","pt":1724539683483,"mc":[{"id":"1.232220323","rc":[{"batb":[[0,2.34,5],[1,2.32,32.53],[2,1.9,998.13]],"ltp":2.36,"tv":20.22,"id":891555}]}]}
{"op":"mcm","clk":"11915264555","pt":1724539686773,"mc":[{"id":"1.232220323","rc":[{"batb":[[0,2.32,32.53],[1,1.9,998.13],[2,1.85,738.46]],"ltp":2.36,"tv":20.22,"id":891555}]}]}
{"op":"mcm","clk":"11915264813","pt":1724539692491,"mc":[{"id":"1.232220323","rc":[{"batb":[[0,2.34,5],[1,2.32,32.53],[2,1.9,998.13]],"ltp":2.36,"tv":20.22,"id":891555}]}]}
{"op":"mcm","clk":"11915265023","pt":1724539695794,"mc":[{"id":"1.232220323","rc":[{"batb":[[0,2.32,32.53],[1,1.9,998.13],[2,1.85,738.46]],"ltp":2.36,"tv":20.22,"id":891555}]}]}
{"op":"mcm","clk":"11915265139","pt":1724539698314,"mc":[{"id":"1.232220323","rc":[{"batb":[[0,2.34,5],[1,2.32,32.53],[2,1.9,998.13]],"ltp":2.36,"tv":20.22,"id":891555}]}]}
{"op":"mcm","clk":"11915265292","pt":1724539701512,"mc":[{"id":"1.232220323","rc":[{"batb":[[0,2.32,32.53],[1,1.9,998.13],[2,1.85,738.46]],"ltp":2.36,"tv":20.22,"id":891555}]}]}
{"op":"mcm","clk":"11915265447","pt":1724539704483,"mc":[{"id":"1.232220323","rc":[{"batb":[[0,2.34,5],[1,2.32,32.53],[2,1.9,998.13]],"ltp":2.36,"tv":20.22,"id":891555}]}]}
{"op":"mcm","clk":"11915265601","pt":1724539707916,"mc":[{"id":"1.232220323","rc":[{"batb":[[0,2.32,32.53],[1,1.9,998.13],[2,1.85,738.46]],"ltp":2.36,"tv":20.22,"id":891555}]}]}
{"op":"mcm","clk":"11915265790","pt":1724539712014,"mc":[{"id":"1.232220323","rc":[{"batb":[[0,2.34,5],[1,2.32,32.53],[2,1.9,998.13]],"ltp":2.36,"tv":20.22,"id":891555}]}]}
{"op":"mcm","clk":"11915265945","pt":1724539715503,"mc":[{"id":"1.232220323","rc":[{"batb":[[0,2.32,32.53],[1,1.9,998.13],[2,1.85,738.46]],"ltp":2.36,"tv":20.22,"id":891555}]}]}
{"op":"mcm","clk":"11915266143","pt":1724539720136,"mc":[{"id":"1.232220323","rc":[{"batb":[[0,2.34,5],[1,2.32,32.53],[2,1.9,998.13]],"ltp":2.36,"tv":20.22,"id":891555}]}]}
{"op":"mcm","clk":"11915266291","pt":1724539723428,"mc":[{"id":"1.232220323","rc":[{"batb":[[0,2.32,32.53],[1,1.9,998.13],[2,1.85,738.46]],"ltp":2.36,"tv":20.22,"id":891555}]}]}
{"op":"mcm","clk":"11915266416","pt":1724539725842,"mc":[{"id":"1.232220323","rc":[{"batb":[[0,2.34,5],[1,2.32,32.53],[2,1.9,998.13]],"ltp":2.36,"tv":20.22,"id":891555}]}]}
{"op":"mcm","clk":"11915266572","pt":1724539729029,"mc":[{"id":"1.232220323","rc":[{"batb":[[0,2.32,32.53],[1,1.9,998.13],[2,1.85,738.46]],"ltp":2.36,"tv":20.22,"id":891555}]}]}
{"op":"mcm","clk":"11915266727","pt":1724539732016,"mc":[{"id":"1.232220323","rc":[{"batb":[[0,2.34,5],[1,2.32,32.53],[2,1.9,998.13]],"ltp":2.36,"tv":20.22,"id":891555}]}]}
{"op":"mcm","clk":"11915266894","pt":1724539735449,"mc":[{"id":"1.232220323","rc":[{"batb":[[0,2.32,32.53],[1,1.9,998.13],[2,1.85,738.46]],"ltp":2.36,"tv":20.22,"id":891555}]}]}
{"op":"mcm","clk":"11915267241","pt":1724539741353,"mc":[{"id":"1.232220323","rc":[{"batb":[[0,2.34,5],[1,2.32,32.53],[2,1.9,998.13]],"ltp":2.36,"tv":20.22,"id":891555}]}]}
{"op":"mcm","clk":"11915267385","pt":1724539744744,"mc":[{"id":"1.232220323","rc":[{"batb":[[0,2.32,32.53],[1,1.9,998.13],[2,1.85,738.46]],"ltp":2.36,"tv":20.22,"id":891555}]}]}
{"op":"mcm","clk":"11915267513","pt":1724539747523,"mc":[{"id":"1.232220323","rc":[{"batb":[[0,2.34,5],[1,2.32,32.53],[2,1.9,998.13]],"ltp":2.36,"tv":20.22,"id":891555}]}]}
{"op":"mcm","clk":"11915267674","pt":1724539750955,"mc":[{"id":"1.232220323","rc":[{"batb":[[0,2.32,32.53],[1,1.9,998.13],[2,1.85,738.46]],"ltp":2.36,"tv":20.22,"id":891555}]}]}
{"op":"mcm","clk":"11915267830","pt":1724539754242,"mc":[{"id":"1.232220323","rc":[{"batb":[[0,2.34,5],[1,2.32,32.53],[2,1.9,998.13]],"ltp":2.36,"tv":20.22,"id":891555}]}]}
{"op":"mcm","clk":"11915267981","pt":1724539757372,"mc":[{"id":"1.232220323","rc":[{"batb":[[0,2.32,32.53],[1,1.9,998.13],[2,1.85,738.46]],"ltp":2.36,"tv":20.22,"id":891555}]}]}
{"op":"mcm","clk":"11915268112","pt":1724539760354,"mc":[{"id":"1.232220323","rc":[{"batb":[[0,2.34,5],[1,2.32,32.53],[2,1.9,998.13]],"ltp":2.36,"tv":20.22,"id":891555}]}]}
{"op":"mcm","clk":"11915268276","pt":1724539763746,"mc":[{"id":"1.232220323","rc":[{"batb":[[0,2.32,32.53],[1,1.9,998.13],[2,1.85,738.46]],"ltp":2.36,"tv":20.22,"id":891555}]}]}
{"op":"mcm","clk":"11915268383","pt":1724539765952,"mc":[{"id":"1.232220323","rc":[{"batb":[[0,2.34,5],[1,2.32,32.53],[2,1.9,998.13]],"ltp":2.36,"tv":20.22,"id":891555}]}]}
{"op":"mcm","clk":"11915268543","pt":1724539769495,"mc":[{"id":"1.232220323","rc":[{"batb":[[0,2.32,32.53],[1,1.9,998.13],[2,1.85,738.46]],"ltp":2.36,"tv":20.22,"id":891555}]}]}
{"op":"mcm","clk":"11915268674","pt":1724539772579,"mc":[{"id":"1.232220323","rc":[{"batb":[[0,2.34,5],[1,2.32,32.53],[2,1.9,998.13]],"ltp":2.36,"tv":20.22,"id":891555}]}]}
{"op":"mcm","clk":"11915268804","pt":1724539775773,"mc":[{"id":"1.232220323","rc":[{"batb":[[0,2.32,32.53],[1,1.9,998.13],[2,1.85,738.46]],"ltp":2.36,"tv":20.22,"id":891555}]}]}
{"op":"mcm","clk":"11915268911","pt":1724539777975,"mc":[{"id":"1.232220323","rc":[{"batb":[[0,2.34,5],[1,2.32,32.53],[2,1.9,998.13]],"ltp":2.36,"tv":20.22,"id":891555}]}]}
{"op":"mcm","clk":"11915269041","pt":1724539781212,"mc":[{"id":"1.232220323","rc":[{"batb":[[0,2.32,32.53],[1,1.9,998.13],[2,1.85,738.46]],"ltp":2.36,"tv":20.22,"id":891555}]}]}
{"op":"mcm","clk":"11915269208","pt":1724539784810,"mc":[{"id":"1.232220323","rc":[{"batb":[[0,2.34,5],[1,2.32,32.53],[2,1.9,998.13]],"ltp":2.36,"tv":20.22,"id":891555}]}]}
{"op":"mcm","clk":"11915269366","pt":1724539788101,"mc":[{"id":"1.232220323","rc":[{"batb":[[0,2.32,32.53],[1,1.9,998.13],[2,1.85,738.46]],"ltp":2.36,"tv":20.22,"id":891555}]}]}
{"op":"mcm","clk":"11915269499","pt":1724539790614,"mc":[{"id":"1.232220323","rc":[{"batb":[[0,2.34,5],[1,2.32,32.53],[2,1.9,998.13]],"ltp":2.36,"tv":20.22,"id":891555}]}]}
{"op":"mcm","clk":"11915269636","pt":1724539793895,"mc":[{"id":"1.232220323","rc":[{"batb":[[0,2.32,32.53],[1,1.9,998.13],[2,1.85,738.46]],"ltp":2.36,"tv":20.22,"id":891555}]}]}
{"op":"mcm","clk":"11915269770","pt":1724539796308,"mc":[{"id":"1.232220323","rc":[{"batb":[[0,2.34,5],[1,2.32,32.53],[2,1.9,998.13]],"ltp":2.36,"tv":20.22,"id":891555}]}]}
{"op":"mcm","clk":"11915269938","pt":1724539799696,"mc":[{"id":"1.232220323","rc":[{"batb":[[0,2.32,32.53],[1,1.9,998.13],[2,1.85,738.46]],"ltp":2.36,"tv":20.22,"id":891555}]}]}
{"op":"mcm","clk":"11915270041","pt":1724539802109,"mc":[{"id":"1.232220323","rc":[{"batb":[[0,2.34,5],[1,2.32,32.53],[2,1.9,998.13]],"ltp":2.36,"tv":20.22,"id":891555}]}]}
{"op":"mcm","clk":"11915270211","pt":1724539805406,"mc":[{"id":"1.232220323","rc":[{"batb":[[0,2.32,32.53],[1,1.9,998.13],[2,1.85,738.46]],"ltp":2.36,"tv":20.22,"id":891555}]}]}
{"op":"mcm","clk":"11915270399","pt":1724539809024,"mc":[{"id":"1.232220323","rc":[{"batb":[[0,2.34,5],[1,2.32,32.53],[2,1.9,998.13]],"ltp":2.36,"tv":20.22,"id":891555}]}]}
{"op":"mcm","clk":"11915270566","pt":1724539812357,"mc":[{"id":"1.232220323","rc":[{"batb":[[0,2.32,32.53],[1,1.9,998.13],[2,1.85,738.46]],"ltp":2.36,"tv":20.22,"id":891555}]}]}
{"op":"mcm","clk":"11915270679","pt":1724539814820,"mc":[{"id":"1.232220323","rc":[{"batb":[[0,2.34,5],[1,2.32,32.53],[2,1.9,998.13]],"ltp":2.36,"tv":20.22,"id":891555}]}]}
{"op":"mcm","clk":"11915270841","pt":1724539818354,"mc":[{"id":"1.232220323","rc":[{"batb":[[0,2.32,32.53],[1,1.9,998.13],[2,1.85,738.46]],"ltp":2.36,"tv":20.22,"id":891555}]}]}
{"op":"mcm","clk":"11915270932","pt":1724539820557,"mc":[{"id":"1.232220323","rc":[{"batb":[[0,2.34,5],[1,2.32,32.53],[2,1.9,998.13]],"ltp":2.36,"tv":20.22,"id":891555}]}]}
{"op":"mcm","clk":"11915271092","pt":1724539823946,"mc":[{"id":"1.232220323","rc":[{"batb":[[0,2.32,32.53],[1,1.9,998.13],[2,1.85,738.46]],"ltp":2.36,"tv":20.22,"id":891555}]}]}
{"op":"mcm","clk":"11915271261","pt":1724539827440,"mc":[{"id":"1.232220323","rc":[{"batb":[[0,2.34,5],[1,2.32,32.53],[2,1.9,998.13]],"ltp":2.36,"tv":20.22,"id":891555}]}]}
{"op":"mcm","clk":"11915271404","pt":1724539830779,"mc":[{"id":"1.232220323","rc":[{"batb":[[0,2.32,32.53],[1,1.9,998.13],[2,1.85,738.46]],"ltp":2.36,"tv":20.22,"id":891555}]}]}
{"op":"mcm","clk":"11915271538","pt":1724539833045,"mc":[{"id":"1.232220323","rc":[{"batb":[[0,2.34,5],[1,2.32,32.53],[2,1.9,998.13]],"ltp":2.36,"tv":20.22,"id":891555}]}]}
{"op":"mcm","clk":"11915271719","pt":1724539836543,"mc":[{"id":"1.232220323","rc":[{"batb":[[0,2.32,32.53],[1,1.9,998.13],[2,1.85,738.46]],"ltp":2.36,"tv":20.22,"id":891555}]}]}
{"op":"mcm","clk":"11915271860","pt":1724539839783,"mc":[{"id":"1.232220323","rc":[{"batb":[[0,2.34,5],[1,2.32,32.53],[2,1.9,998.13]],"ltp":2.36,"tv":20.22,"id":891555}]}]}
{"op":"mcm","clk":"11915272025","pt":1724539843175,"mc":[{"id":"1.232220323","rc":[{"batb":[[0,2.32,32.53],[1,1.9,998.13],[2,1.85,738.46]],"ltp":2.36,"tv":20.22,"id":891555}]}]}
{"op":"mcm","clk":"11915272144","pt":1724539845691,"mc":[{"id":"1.232220323","rc":[{"batb":[[0,2.34,5],[1,2.32,32.53],[2,1.9,998.13]],"ltp":2.36,"tv":20.22,"id":891555}]}]}
{"op":"mcm","clk":"11915272288","pt":1724539848983,"mc":[{"id":"1.232220323","rc":[{"batb":[[0,2.32,32.53],[1,1.9,998.13],[2,1.85,738.46]],"ltp":2.36,"tv":20.22,"id":891555}]}]}
{"op":"mcm","clk":"11915272425","pt":1724539851397,"mc":[{"id":"1.232220323","rc":[{"batb":[[0,2.34,5],[1,2.32,32.53],[2,1.9,998.13]],"ltp":2.36,"tv":20.22,"id":891555}]}]}
{"op":"mcm","clk":"11915272584","pt":1724539854587,"mc":[{"id":"1.232220323","rc":[{"batb":[[0,2.32,32.53],[1,1.9,998.13],[2,1.85,738.46]],"ltp":2.36,"tv":20.22,"id":891555}]}]}
{"op":"mcm","clk":"11915272717","pt":1724539857308,"mc":[{"id":"1.232220323","rc":[{"batb":[[0,2.34,5],[1,2.32,32.53],[2,1.9,998.13]],"ltp":2.36,"tv":20.22,"id":891555}]}]}
{"op":"mcm","clk":"11915272872","pt":1724539860809,"mc":[{"id":"1.232220323","rc":[{"batb":[[0,2.32,32.53],[1,1.9,998.13],[2,1.85,738.46]],"ltp":2.36,"tv":20.22,"id":891555}]}]}
{"op":"mcm","clk":"11915272963","pt":1724539863069,"mc":[{"id":"1.232220323","rc":[{"batb":[[0,2.34,5],[1,2.32,32.53],[2,1.9,998.13]],"ltp":2.36,"tv":20.22,"id":891555}]}]}
{"op":"mcm","clk":"11915273083","pt":1724539866508,"mc":[{"id":"1.232220323","rc":[{"batb":[[0,2.32,32.53],[1,1.9,998.13],[2,1.85,738.46]],"ltp":2.36,"tv":20.22,"id":891555}]}]}
{"op":"mcm","clk":"11915273211","pt":1724539870115,"mc":[{"id":"1.232220323","rc":[{"batb":[[0,2.34,5],[1,2.32,32.53],[2,1.9,998.13]],"ltp":2.36,"tv":20.22,"id":891555}]}]}
{"op":"mcm","clk":"11915273349","pt":1724539873310,"mc":[{"id":"1.232220323","rc":[{"batb":[[0,2.32,32.53],[1,1.9,998.13],[2,1.85,738.46]],"ltp":2.36,"tv":20.22,"id":891555}]}]}
{"op":"mcm","clk":"11915273618","pt":1724539879013,"mc":[{"id":"1.232220323","rc":[{"batb":[[0,2.34,5],[1,2.32,32.53],[2,1.9,998.13]],"ltp":2.36,"tv":20.22,"id":891555}]}]}
{"op":"mcm","clk":"11915273770","pt":1724539882617,"mc":[{"id":"1.232220323","rc":[{"batb":[[0,2.32,32.53],[1,1.9,998.13],[2,1.85,738.46]],"ltp":2.36,"tv":20.22,"id":891555}]}]}
{"op":"mcm","clk":"11915273855","pt":1724539884825,"mc":[{"id":"1.232220323","rc":[{"batb":[[0,2.34,5],[1,2.32,32.53],[2,1.9,998.13]],"ltp":2.36,"tv":20.22,"id":891555}]}]}
{"op":"mcm","clk":"11915274023","pt":1724539888116,"mc":[{"id":"1.232220323","rc":[{"batb":[[0,2.32,32.53],[1,1.9,998.13],[2,1.85,738.46]],"ltp":2.36,"tv":20.22,"id":891555}]}]}
{"op":"mcm","clk":"11915274150","pt":1724539890528,"mc":[{"id":"1.232220323","rc":[{"batb":[[0,2.34,5],[1,2.32,32.53],[2,1.9,998.13]],"ltp":2.36,"tv":20.22,"id":891555}]}]}
{"op":"mcm","clk":"11915274312","pt":1724539894015,"mc":[{"id":"1.232220323","rc":[{"batb":[[0,2.32,32.53],[1,1.9,998.13],[2,1.85,738.46]],"ltp":2.36,"tv":20.22,"id":891555}]}]}
{"op":"mcm","clk":"11915274416","pt":1724539896329,"mc":[{"id":"1.232220323","rc":[{"batb":[[0,2.34,5],[1,2.32,32.53],[2,1.9,998.13]],"ltp":2.36,"tv":20.22,"id":891555}]}]}
{"op":"mcm","clk":"11915274558","pt":1724539899819,"mc":[{"id":"1.232220323","rc":[{"batb":[[0,2.32,32.53],[1,1.9,998.13],[2,1.85,738.46]],"ltp":2.36,"tv":20.22,"id":891555}]}]}
{"op":"mcm","clk":"11915274641","pt":1724539901922,"mc":[{"id":"1.232220323","rc":[{"batb":[[0,2.34,5],[1,2.32,32.53],[2,1.9,998.13]],"ltp":2.36,"tv":20.22,"id":891555}]}]}
{"op":"mcm","clk":"11915274789","pt":1724539905217,"mc":[{"id":"1.232220323","rc":[{"batb":[[0,2.32,32.53],[1,1.9,998.13],[2,1.85,738.46]],"ltp":2.36,"tv":20.22,"id":891555}]}]}
{"op":"mcm","clk":"11915274895","pt":1724539907835,"mc":[{"id":"1.232220323","rc":[{"batb":[[0,2.34,5],[1,2.32,32.53],[2,1.9,998.13]],"ltp":2.36,"tv":20.22,"id":891555}]}]}
{"op":"mcm","clk":"11915275059","pt":1724539911227,"mc":[{"id":"1.232220323","rc":[{"batb":[[0,2.32,32.53],[1,1.9,998.13],[2,1.85,738.46]],"ltp":2.36,"tv":20.22,"id":891555}]}]}
{"op":"mcm","clk":"11915275185","pt":1724539913621,"mc":[{"id":"1.232220323","rc":[{"batb":[[0,2.34,5],[1,2.32,32.53],[2,1.9,998.13]],"ltp":2.36,"tv":20.22,"id":891555}]}]}
{"op":"mcm","clk":"11915275379","pt":1724539917220,"mc":[{"id":"1.232220323","rc":[{"batb":[[0,2.32,32.53],[1,1.9,998.13],[2,1.85,738.46]],"ltp":2.36,"tv":20.22,"id":891555}]}]}
{"op":"mcm","clk":"11915275537","pt":1724539920454,"mc":[{"id":"1.232220323","rc":[{"batb":[[0,2.34,5],[1,2.32,32.53],[2,1.9,998.13]],"ltp":2.36,"tv":20.22,"id":891555}]}]}
{"op":"mcm","clk":"11915275706","pt":1724539923747,"mc":[{"id":"1.232220323","rc":[{"batb":[[0,2.32,32.53],[1,1.9,998.13],[2,1.85,738.46]],"ltp":2.36,"tv":20.22,"id":891555}]}]}
{"op":"mcm","clk":"11915275865","pt":1724539926265,"mc":[{"id":"1.232220323","rc":[{"batb":[[0,2.34,5],[1,2.32,32.53],[2,1.9,998.13]],"ltp":2.36,"tv":20.22,"id":891555}]}]}
{"op":"mcm","clk":"11915276042","pt":1724539929443,"mc":[{"id":"1.232220323","rc":[{"batb":[[0,2.32,32.53],[1,1.9,998.13],[2,1.85,738.46]],"ltp":2.36,"tv":20.22,"id":891555}]}]}
{"op":"mcm","clk":"11915276178","pt":1724539931863,"mc":[{"id":"1.232220323","rc":[{"batb":[[0,2.34,5],[1,2.32,32.53],[2,1.9,998.13]],"ltp":2.36,"tv":20.22,"id":891555}]}]}
{"op":"mcm","clk":"11915276360","pt":1724539935150,"mc":[{"id":"1.232220323","rc":[{"batb":[[0,2.32,32.53],[1,1.9,998.13],[2,1.85,738.46]],"ltp":2.36,"tv":20.22,"id":891555}]}]}
{"op":"mcm","clk":"11915276520","pt":1724539937569,"mc":[{"id":"1.232220323","rc":[{"batb":[[0,2.34,5],[1,2.32,32.53],[2,1.9,998.13]],"ltp":2.36,"tv":20.22,"id":891555}]}]}
{"op":"mcm","clk":"11915276690","pt":1724539940960,"mc":[{"id":"1.232220323","rc":[{"batb":[[0,2.32,32.53],[1,1.9,998.13],[2,1.85,738.46]],"ltp":2.36,"tv":20.22,"id":891555}]}]}
{"op":"mcm","clk":"11915276825","pt":1724539943380,"mc":[{"id":"1.232220323","rc":[{"batb":[[0,2.34,5],[1,2.32,32.53],[2,1.9,998.13]],"ltp":2.36,"tv":20.22,"id":891555}]}]}
{"op":"mcm","clk":"11915277017","pt":1724539946551,"mc":[{"id":"1.232220323","rc":[{"batb":[[0,2.32,32.53],[1,1.9,998.13],[2,1.85,738.46]],"ltp":2.36,"tv":20.22,"id":891555}]}]}
{"op":"mcm","clk":"11915277223","pt":1724539951279,"mc":[{"id":"1.232220323","rc":[{"batb":[[0,2.34,5],[1,2.32,32.53],[2,1.9,998.13]],"ltp":2.36,"tv":20.22,"id":891555}]}]}
{"op":"mcm","clk":"11915277426","pt":1724539954882,"mc":[{"id":"1.232220323","rc":[{"batb":[[0,2.32,32.53],[1,1.9,998.13],[2,1.85,738.46]],"ltp":2.36,"tv":20.22,"id":891555}]}]}
{"op":"mcm","clk":"11915277571","pt":1724539958074,"mc":[{"id":"1.232220323","rc":[{"batb":[[0,2.34,5],[1,2.32,32.53],[2,1.9,998.13]],"ltp":2.36,"tv":20.22,"id":891555}]}]}
{"op":"mcm","clk":"11915277732","pt":1724539961563,"mc":[{"id":"1.232220323","rc":[{"batb":[[0,2.32,32.53],[1,1.9,998.13],[2,1.85,738.46]],"ltp":2.36,"tv":20.22,"id":891555}]}]}
{"op":"mcm","clk":"11915277880","pt":1724539964491,"mc":[{"id":"1.232220323","rc":[{"batb":[[0,2.34,5],[1,2.32,32.53],[2,1.9,998.13]],"ltp":2.36,"tv":20.22,"id":891555}]}]}
{"op":"mcm","clk":"11915278044","pt":1724539967890,"mc":[{"id":"1.232220323","rc":[{"batb":[[0,2.32,32.53],[1,1.9,998.13],[2,1.85,738.46]],"ltp":2.36,"tv":20.22,"id":891555}]}]}
{"op":"mcm","clk":"11915278172","pt":1724539970197,"mc":[{"id":"1.232220323","rc":[{"batb":[[0,2.34,5],[1,2.32,32.53],[2,1.9,998.13]],"ltp":2.36,"tv":20.22,"id":891555}]}]}
{"op":"mcm","clk":"11915278375","pt":1724539973698,"mc":[{"id":"1.232220323","rc":[{"batb":[[0,2.32,32.53],[1,1.9,998.13],[2,1.85,738.46]],"ltp":2.36,"tv":20.22,"id":891555}]}]}
{"op":"mcm","clk":"11915278541","pt":1724539976783,"mc":[{"id":"1.232220323","rc":[{"batb":[[0,2.34,5],[1,2.32,32.53],[2,1.9,998.13]],"ltp":2.36,"tv":20.22,"id":891555}]}]}
{"op":"mcm","clk":"11915278739","pt":1724539980117,"mc":[{"id":"1.232220323","rc":[{"batb":[[0,2.32,32.53],[1,1.9,998.13],[2,1.85,738.46]],"ltp":2.36,"tv":20.22,"id":891555}]}]}
{"op":"mcm","clk":"11915278888","pt":1724539982584,"mc":[{"id":"1.232220323","rc":[{"batb":[[0,2.34,5],[1,2.32,32.53],[2,1.9,998.13]],"ltp":2.36,"tv":20.22,"id":891555}]}]}
{"op":"mcm","clk":"11915279072","pt":1724539986120,"mc":[{"id":"1.232220323","rc":[{"batb":[[0,2.32,32.53],[1,1.9,998.13],[2,1.85,738.46]],"ltp":2.36,"tv":20.22,"id":891555}]}]}
{"op":"mcm","clk":"11915279193","pt":1724539988323,"mc":[{"id":"1.232220323","rc":[{"batb":[[0,2.34,5],[1,2.32,32.53],[2,1.9,998.13]],"ltp":2.36,"tv":20.22,"id":891555}]}]}
{"op":"mcm","clk":"11915279373","pt":1724539991614,"mc":[{"id":"1.232220323","rc":[{"batb":[[0,2.32,32.53],[1,1.9,998.13],[2,1.85,738.46]],"ltp":2.36,"tv":20.22,"id":891555}]}]}
{"op":"mcm","clk":"11915279540","pt":1724539994291,"mc":[{"id":"1.232220323","rc":[{"batb":[[0,2.34,5],[1,2.32,32.53],[2,1.9,998.13]],"ltp":2.36,"tv":20.22,"id":891555}]}]}
{"op":"mcm","clk":"11915279755","pt":1724539997630,"mc":[{"id":"1.232220323","rc":[{"batb":[[0,2.32,32.53],[1,1.9,998.13],[2,1.85,738.46]],"ltp":2.36,"tv":20.22,"id":891555}]}]}
{"op":"mcm","clk":"11915279893","pt":1724540000044,"mc":[{"id":"1.232220323","rc":[{"batb":[[0,2.34,5],[1,2.32,32.53],[2,1.9,998.13]],"ltp":2.36,"tv":20.22,"id":891555}]}]}
{"op":"mcm","clk":"11915280070","pt":1724540003736,"mc":[{"id":"1.232220323","rc":[{"batb":[[0,2.32,32.53],[1,1.9,998.13],[2,1.85,738.46]],"ltp":2.36,"tv":20.22,"id":891555}]}]}
{"op":"mcm","clk":"11915280244","pt":1724540006513,"mc":[{"id":"1.232220323","rc":[{"batb":[[0,2.34,5],[1,2.32,32.53],[2,1.9,998.13]],"ltp":2.36,"tv":20.22,"id":891555}]}]}
{"op":"mcm","clk":"11915280440","pt":1724540010012,"mc":[{"id":"1.232220323","rc":[{"batb":[[0,2.32,32.53],[1,1.9,998.13],[2,1.85,738.46]],"ltp":2.36,"tv":20.22,"id":891555}]}]}
{"op":"mcm","clk":"11915280560","pt":1724540012225,"mc":[{"id":"1.232220323","rc":[{"batb":[[0,2.34,5],[1,2.32,32.53],[2,1.9,998.13]],"ltp":2.36,"tv":20.22,"id":891555}]}]}
{"op":"mcm","clk":"11915280757","pt":1724540015555,"mc":[{"id":"1.232220323","rc":[{"batb":[[0,2.32,32.53],[1,1.9,998.13],[2,1.85,738.46]],"ltp":2.36,"tv":20.22,"id":891555}]}]}
{"op":"mcm","clk":"11915280911","pt":1724540017816,"mc":[{"id":"1.232220323","rc":[{"batb":[[0,2.34,5],[1,2.32,32.53],[2,1.9,998.13]],"ltp":2.36,"tv":20.22,"id":891555}]}]}
{"op":"mcm","clk":"11915281074","pt":1724540021155,"mc":[{"id":"1.232220323","rc":[{"batb":[[0,2.32,32.53],[1,1.9,998.13],[2,1.85,738.46]],"ltp":2.36,"tv":20.22,"id":891555}]}]}
{"op":"mcm","clk":"11915281209","pt":1724540023416,"mc":[{"id":"1.232220323","rc":[{"batb":[[0,2.34,5],[1,2.32,32.53],[2,1.9,998.13]],"ltp":2.36,"tv":20.22,"id":891555}]}]}
{"op":"mcm","clk":"11915281399","pt":1724540026857,"mc":[{"id":"1.232220323","rc":[{"batb":[[0,2.32,32.53],[1,1.9,998.13],[2,1.85,738.46]],"ltp":2.36,"tv":20.22,"id":891555}]}]}
{"op":"mcm","clk":"11915281571","pt":1724540029018,"mc":[{"id":"1.232220323","rc":[{"batb":[[0,2.34,5],[1,2.32,32.53],[2,1.9,998.13]],"ltp":2.36,"tv":20.22,"id":891555}]}]}
{"op":"mcm","clk":"11915281730","pt":1724540032462,"mc":[{"id":"1.232220323","rc":[{"batb":[[0,2.32,32.53],[1,1.9,998.13],[2,1.85,738.46]],"ltp":2.36,"tv":20.22,"id":891555}]}]}
{"op":"mcm","clk":"11915281852","pt":1724540034669,"mc":[{"id":"1.232220323","rc":[{"batb":[[0,2.34,5],[1,2.32,32.53],[2,1.9,998.13]],"ltp":2.36,"tv":20.22,"id":891555}]}]}
{"op":"mcm","clk":"11915282000","pt":1724540038056,"mc":[{"id":"1.232220323","rc":[{"batb":[[0,2.32,32.53],[1,1.9,998.13],[2,1.85,738.46]],"ltp":2.36,"tv":20.22,"id":891555}]}]}
{"op":"mcm","clk":"11915282145","pt":1724540041086,"mc":[{"id":"1.232220323","rc":[{"batb":[[0,2.34,5],[1,2.32,32.53],[2,1.9,998.13]],"ltp":2.36,"tv":20.22,"id":891555}]}]}
{"op":"mcm","clk":"11915282323","pt":1724540044377,"mc":[{"id":"1.232220323","rc":[{"batb":[[0,2.32,32.53],[1,1.9,998.13],[2,1.85,738.46]],"ltp":2.36,"tv":20.22,"id":891555}]}]}
{"op":"mcm","clk":"11915282485","pt":1724540047057,"mc":[{"id":"1.232220323","rc":[{"batb":[[0,2.34,5],[1,2.32,32.53],[2,1.9,998.13]],"ltp":2.36,"tv":20.22,"id":891555}]}]}
{"op":"mcm","clk":"11915282652","pt":1724540050446,"mc":[{"id":"1.232220323","rc":[{"batb":[[0,2.32,32.53],[1,1.9,998.13],[2,1.85,738.46]],"ltp":2.36,"tv":20.22,"id":891555}]}]}
{"op":"mcm","clk":"11915282786","pt":1724540052956,"mc":[{"id":"1.232220323","rc":[{"batb":[[0,2.34,5],[1,2.32,32.53],[2,1.9,998.13]],"ltp":2.36,"tv":20.22,"id":891555}]}]}
{"op":"mcm","clk":"11915282987","pt":1724540056458,"mc":[{"id":"1.232220323","rc":[{"batb":[[0,2.32,32.53],[1,1.9,998.13],[2,1.85,738.46]],"ltp":2.36,"tv":20.22,"id":891555}]}]}
{"op":"mcm","clk":"11915283099","pt":1724540058769,"mc":[{"id":"1.232220323","rc":[{"batb":[[0,2.34,5],[1,2.32,32.53],[2,1.9,998.13]],"ltp":2.36,"tv":20.22,"id":891555}]}]}
{"op":"mcm","clk":"11915283333","pt":1724540062106,"mc":[{"id":"1.232220323","rc":[{"batb":[[0,2.32,32.53],[1,1.9,998.13],[2,1.85,738.46]],"ltp":2.36,"tv":20.22,"id":891555}]}]}
{"op":"mcm","clk":"11915283483","pt":1724540064880,"mc":[{"id":"1.232220323","rc":[{"batb":[[0,2.34,5],[1,2.32,32.53],[2,1.9,998.13]],"ltp":2.36,"tv":20.22,"id":891555}]}]}
{"op":"mcm","clk":"11915283665","pt":1724540068269,"mc":[{"id":"1.232220323","rc":[{"batb":[[0,2.32,32.53],[1,1.9,998.13],[2,1.85,738.46]],"ltp":2.36,"tv":20.22,"id":891555}]}]}
{"op":"mcm","clk":"11915283779","pt":1724540070578,"mc":[{"id":"1.232220323","rc":[{"batb":[[0,2.34,5],[1,2.32,32.53],[2,1.9,998.13]],"ltp":2.36,"tv":20.22,"id":891555}]}]}
{"op":"mcm","clk":"11915283960","pt":1724540074095,"mc":[{"id":"1.232220323","rc":[{"batb":[[0,2.32,32.53],[1,1.9,998.13],[2,1.85,738.46]],"ltp":2.36,"tv":20.22,"id":891555}]}]}
{"op":"mcm","clk":"11915284109","pt":1724540076406,"mc":[{"id":"1.232220323","rc":[{"batb":[[0,2.34,5],[1,2.32,32.53],[2,1.9,998.13]],"ltp":2.36,"tv":20.22,"id":891555}]}]}
{"op":"mcm","clk":"11915284314","pt":1724540079690,"mc":[{"id":"1.232220323","rc":[{"batb":[[0,2.32,32.53],[1,1.9,998.13],[2,1.85,738.46]],"ltp":2.36,"tv":20.22,"id":891555}]}]}
{"op":"mcm","clk":"11915284445","pt":1724540082203,"mc":[{"id":"1.232220323","rc":[{"batb":[[0,2.34,5],[1,2.32,32.53],[2,1.9,998.13]],"ltp":2.36,"tv":20.22,"id":891555}]}]}
{"op":"mcm","clk":"11915284592","pt":1724540085536,"mc":[{"id":"1.232220323","rc":[{"batb":[[0,2.32,32.53],[1,1.9,998.13],[2,1.85,738.46]],"ltp":2.36,"tv":20.22,"id":891555}]}]}
{"op":"mcm","clk":"11915284775","pt":1724540088619,"mc":[{"id":"1.232220323","rc":[{"batb":[[0,2.34,5],[1,2.32,32.53],[2,1.9,998.13]],"ltp":2.36,"tv":20.22,"id":891555}]}]}
{"op":"mcm","clk":"11915284955","pt":1724540092160,"mc":[{"id":"1.232220323","rc":[{"batb":[[0,2.32,32.53],[1,1.9,998.13],[2,1.85,738.46]],"ltp":2.36,"tv":20.22,"id":891555}]}]}
{"op":"mcm","clk":"11915285073","pt":1724540094420,"mc":[{"id":"1.232220323","rc":[{"batb":[[0,2.34,5],[1,2.32,32.53],[2,1.9,998.13]],"ltp":2.36,"tv":20.22,"id":891555}]}]}
{"op":"mcm","clk":"11915285274","pt":1724540097913,"mc":[{"id":"1.232220323","rc":[{"batb":[[0,2.32,32.53],[1,1.9,998.13],[2,1.85,738.46]],"ltp":2.36,"tv":20.22,"id":891555}]}]}
{"op":"mcm","clk":"11915285375","pt":1724540100216,"mc":[{"id":"1.232220323","rc":[{"batb":[[0,2.34,5],[1,2.32,32.53],[2,1.9,998.13]],"ltp":2.36,"tv":20.22,"id":891555}]}]}
{"op":"mcm","clk":"11915285555","pt":1724540103513,"mc":[{"id":"1.232220323","rc":[{"batb":[[0,2.32,32.53],[1,1.9,998.13],[2,1.85,738.46]],"ltp":2.36,"tv":20.22,"id":891555}]}]}
{"op":"mcm","clk":"11915285696","pt":1724540106341,"mc":[{"id":"1.232220323","rc":[{"batb":[[0,2.34,5],[1,2.32,32.53],[2,1.9,998.13]],"ltp":2.36,"tv":20.22,"id":891555}]}]}
{"op":"mcm","clk":"11915285848","pt":1724540109520,"mc":[{"id":"1.232220323","rc":[{"batb":[[0,2.32,32.53],[1,1.9,998.13],[2,1.85,738.46]],"ltp":2.36,"tv":20.22,"id":891555}]}]}
{"op":"mcm","clk":"11915285978","pt":1724540112142,"mc":[{"id":"1.232220323","rc":[{"batb":[[0,2.34,5],[1,2.32,32.53],[2,1.9,998.13]],"ltp":2.36,"tv":20.22,"id":891555}]}]}
{"op":"mcm","clk":"11915286121","pt":1724540115426,"mc":[{"id":"1.232220323","rc":[{"batb":[[0,2.32,32.53],[1,1.9,998.13],[2,1.85,738.46]],"ltp":2.36,"tv":20.22,"id":891555}]}]}
{"op":"mcm","clk":"11915286253","pt":1724540117953,"mc":[{"id":"1.232220323","rc":[{"batb":[[0,2.34,5],[1,2.32,32.53],[2,1.9,998.13]],"ltp":2.36,"tv":20.22,"id":891555}]}]}
{"op":"mcm","clk":"11915286428","pt":1724540121341,"mc":[{"id":"1.232220323","rc":[{"batb":[[0,2.32,32.53],[1,1.9,998.13],[2,1.85,738.46]],"ltp":2.36,"tv":20.22,"id":891555}]}]}
{"op":"mcm","clk":"11915286544","pt":1724540123552,"mc":[{"id":"1.232220323","rc":[{"batb":[[0,2.34,5],[1,2.32,32.53],[2,1.9,998.13]],"ltp":2.36,"tv":20.22,"id":891555}]}]}
{"op":"mcm","clk":"11915286701","pt":1724540126952,"mc":[{"id":"1.232220323","rc":[{"batb":[[0,2.32,32.53],[1,1.9,998.13],[2,1.85,738.46]],"ltp":2.36,"tv":20.22,"id":891555}]}]}
{"op":"mcm","clk":"11915286821","pt":1724540129364,"mc":[{"id":"1.232220323","rc":[{"batb":[[0,2.34,5],[1,2.32,32.53],[2,1.9,998.13]],"ltp":2.36,"tv":20.22,"id":891555}]}]}
{"op":"mcm","clk":"11915286960","pt":1724540132652,"mc":[{"id":"1.232220323","rc":[{"batb":[[0,2.32,32.53],[1,1.9,998.13],[2,1.85,738.46]],"ltp":2.36,"tv":20.22,"id":891555}]}]}
{"op":"mcm","clk":"11915287075","pt":1724540134868,"mc":[{"id":"1.232220323","rc":[{"batb":[[0,2.34,5],[1,2.32,32.53],[2,1.9,998.13]],"ltp":2.36,"tv":20.22,"id":891555}]}]}
{"op":"mcm","clk":"11915287230","pt":1724540138354,"mc":[{"id":"1.232220323","rc":[{"batb":[[0,2.32,32.53],[1,1.9,998.13],[2,1.85,738.46]],"ltp":2.36,"tv":20.22,"id":891555}]}]}
{"op":"mcm","clk":"11915287372","pt":1724540140768,"mc":[{"id":"1.232220323","rc":[{"batb":[[0,2.34,5],[1,2.32,32.53],[2,1.9,998.13]],"ltp":2.36,"tv":20.22,"id":891555}]}]}
{"op":"mcm","clk":"11915287554","pt":1724540144058,"mc":[{"id":"1.232220323","rc":[{"batb":[[0,2.32,32.53],[1,1.9,998.13],[2,1.85,738.46]],"ltp":2.36,"tv":20.22,"id":891555}]}]}
{"op":"mcm","clk":"11915287803","pt":1724540149289,"mc":[{"id":"1.232220323","rc":[{"batb":[[0,2.34,5],[1,2.32,32.53],[2,1.9,998.13]],"ltp":2.36,"tv":20.22,"id":891555}]}]}
{"op":"mcm","clk":"11915287956","pt":1724540152471,"mc":[{"id":"1.232220323","rc":[{"batb":[[0,2.32,32.53],[1,1.9,998.13],[2,1.85,738.46]],"ltp":2.36,"tv":20.22,"id":891555}]}]}
{"op":"mcm","clk":"11915288056","pt":1724540155009,"mc":[{"id":"1.232220323","rc":[{"batb":[[0,2.34,5],[1,2.32,32.53],[2,1.9,998.13]],"ltp":2.36,"tv":20.22,"id":891555}]}]}
{"op":"mcm","clk":"11915288210","pt":1724540158300,"mc":[{"id":"1.232220323","rc":[{"batb":[[0,2.32,32.53],[1,1.9,998.13],[2,1.85,738.46]],"ltp":2.36,"tv":20.22,"id":891555}]}]}
{"op":"mcm","clk":"11915288336","pt":1724540161015,"mc":[{"id":"1.232220323","rc":[{"batb":[[0,2.34,5],[1,2.32,32.53],[2,1.9,998.13]],"ltp":2.36,"tv":20.22,"id":891555}]}]}
{"op":"mcm","clk":"11915288483","pt":1724540164313,"mc":[{"id":"1.232220323","rc":[{"batb":[[0,2.32,32.53],[1,1.9,998.13],[2,1.85,738.46]],"ltp":2.36,"tv":20.22,"id":891555}]}]}
{"op":"mcm","clk":"11915288590","pt":1724540166634,"mc":[{"id":"1.232220323","rc":[{"batb":[[0,2.34,5],[1,2.32,32.53],[2,1.9,998.13]],"ltp":2.36,"tv":20.22,"id":891555}]}]}
{"op":"mcm","clk":"11915288769","pt":1724540170023,"mc":[{"id":"1.232220323","rc":[{"batb":[[0,2.32,32.53],[1,1.9,998.13],[2,1.85,738.46]],"ltp":2.36,"tv":20.22,"id":891555}]}]}
{"op":"mcm","clk":"11915288852","pt":1724540172225,"mc":[{"id":"1.232220323","rc":[{"batb":[[0,2.34,5],[1,2.32,32.53],[2,1.9,998.13]],"ltp":2.36,"tv":20.22,"id":891555}]}]}
{"op":"mcm","clk":"11915289010","pt":1724540175611,"mc":[{"id":"1.232220323","rc":[{"batb":[[0,2.32,32.53],[1,1.9,998.13],[2,1.85,738.46]],"ltp":2.36,"tv":20.22,"id":891555}]}]}
{"op":"mcm","clk":"11915289130","pt":1724540177915,"mc":[{"id":"1.232220323","rc":[{"batb":[[0,2.34,5],[1,2.32,32.53],[2,1.9,998.13]],"ltp":2.36,"tv":20.22,"id":891555}]}]}
{"op":"mcm","clk":"11915289290","pt":1724540181242,"mc":[{"id":"1.232220323","rc":[{"batb":[[0,2.32,32.53],[1,1.9,998.13],[2,1.85,738.46]],"ltp":2.36,"tv":20.22,"id":891555}]}]}
{"op":"mcm","clk":"11915289416","pt":1724540183914,"mc":[{"id":"1.232220323","rc":[{"batb":[[0,2.34,5],[1,2.32,32.53],[2,1.9,998.13]],"ltp":2.36,"tv":20.22,"id":891555}]}]}
{"op":"mcm","clk":"11915289580","pt":1724540187343,"mc":[{"id":"1.232220323","rc":[{"batb":[[0,2.32,32.53],[1,1.9,998.13],[2,1.85,738.46]],"ltp":2.36,"tv":20.22,"id":891555}]}]}
{"op":"mcm","clk":"11915289667","pt":1724540189646,"mc":[{"id":"1.232220323","rc":[{"batb":[[0,2.34,5],[1,2.32,32.53],[2,1.9,998.13]],"ltp":2.36,"tv":20.22,"id":891555}]}]}
{"op":"mcm","clk":"11915289814","pt":1724540192831,"mc":[{"id":"1.232220323","rc":[{"batb":[[0,2.32,32.53],[1,1.9,998.13],[2,1.85,738.46]],"ltp":2.36,"tv":20.22,"id":891555}]}]}
{"op":"mcm","clk":"11915289959","pt":1724540195444,"mc":[{"id":"1.232220323","rc":[{"batb":[[0,2.34,5],[1,2.32,32.53],[2,1.9,998.13]],"ltp":2.36,"tv":20.22,"id":891555}]}]}
{"op":"mcm","clk":"11915290113","pt":1724540198626,"mc":[{"id":"1.232220323","rc":[{"batb":[[0,2.32,32.53],[1,1.9,998.13],[2,1.85,738.46]],"ltp":2.36,"tv":20.22,"id":891555}]}]}
{"op":"mcm","clk":"11915290220","pt":1724540201141,"mc":[{"id":"1.232220323","rc":[{"batb":[[0,2.34,5],[1,2.32,32.53],[2,1.9,998.13]],"ltp":2.36,"tv":20.22,"id":891555}]}]}
{"op":"mcm","clk":"11915290396","pt":1724540204525,"mc":[{"id":"1.232220323","rc":[{"batb":[[0,2.32,32.53],[1,1.9,998.13],[2,1.85,738.46]],"ltp":2.36,"tv":20.22,"id":891555}]}]}
{"op":"mcm","clk":"11915290500","pt":1724540206831,"mc":[{"id":"1.232220323","rc":[{"batb":[[0,2.34,5],[1,2.32,32.53],[2,1.9,998.13]],"ltp":2.36,"tv":20.22,"id":891555}]}]}
{"op":"mcm","clk":"11915290665","pt":1724540210168,"mc":[{"id":"1.232220323","rc":[{"batb":[[0,2.32,32.53],[1,1.9,998.13],[2,1.85,738.46]],"ltp":2.36,"tv":20.22,"id":891555}]}]}
{"op":"mcm","clk":"11915290848","pt":1724540213546,"mc":[{"id":"1.232220323","rc":[{"batb":[[0,2.34,5],[1,2.32,32.53],[2,1.9,998.13]],"ltp":2.36,"tv":20.22,"id":891555}]}]}
{"op":"mcm","clk":"11915291048","pt":1724540217047,"mc":[{"id":"1.232220323","rc":[{"batb":[[0,2.32,32.53],[1,1.9,998.13],[2,1.85,738.46]],"ltp":2.36,"tv":20.22,"id":891555}]}]}
{"op":"mcm","clk":"11915291135","pt":1724540219248,"mc":[{"id":"1.232220323","rc":[{"batb":[[0,2.34,5],[1,2.32,32.53],[2,1.9,998.13]],"ltp":2.36,"tv":20.22,"id":891555}]}]}
{"op":"mcm","clk":"11915291296","pt":1724540222692,"mc":[{"id":"1.232220323","rc":[{"batb":[[0,2.32,32.53],[1,1.9,998.13],[2,1.85,738.46]],"ltp":2.36,"tv":20.22,"id":891555}]}]}
{"op":"mcm","clk":"11915291418","pt":1724540225155,"mc":[{"id":"1.232220323","rc":[{"batb":[[0,2.34,5],[1,2.32,32.53],[2,1.9,998.13]],"ltp":2.36,"tv":20.22,"id":891555}]}]}
{"op":"mcm","clk":"11915291586","pt":1724540228592,"mc":[{"id":"1.232220323","rc":[{"batb":[[0,2.32,32.53],[1,1.9,998.13],[2,1.85,738.46]],"ltp":2.36,"tv":20.22,"id":891555}]}]}
{"op":"mcm","clk":"11915291696","pt":1724540230693,"mc":[{"id":"1.232220323","rc":[{"batb":[[0,2.34,5],[1,2.32,32.53],[2,1.9,998.13]],"ltp":2.36,"tv":20.22,"id":891555}]}]}
{"op":"mcm","clk":"11915291880","pt":1724540233971,"mc":[{"id":"1.232220323","rc":[{"batb":[[0,2.32,32.53],[1,1.9,998.13],[2,1.85,738.46]],"ltp":2.36,"tv":20.22,"id":891555}]}]}
{"op":"mcm","clk":"11915292006","pt":1724540236487,"mc":[{"id":"1.232220323","rc":[{"batb":[[0,2.34,5],[1,2.32,32.53],[2,1.9,998.13]],"ltp":2.36,"tv":20.22,"id":891555}]}]}
{"op":"mcm","clk":"11915292195","pt":1724540239993,"mc":[{"id":"1.232220323","rc":[{"batb":[[0,2.32,32.53],[1,1.9,998.13],[2,1.85,738.46]],"ltp":2.36,"tv":20.22,"id":891555}]}]}
{"op":"mcm","clk":"11915292294","pt":1724540242303,"mc":[{"id":"1.232220323","rc":[{"batb":[[0,2.34,5],[1,2.32,32.53],[2,1.9,998.13]],"ltp":2.36,"tv":20.22,"id":891555}]}]}
{"op":"mcm","clk":"11915292425","pt":1724540245587,"mc":[{"id":"1.232220323","rc":[{"batb":[[0,2.32,32.53],[1,1.9,998.13],[2,1.85,738.46]],"ltp":2.36,"tv":20.22,"id":891555}]}]}
{"op":"mcm","clk":"11915292540","pt":1724540248107,"mc":[{"id":"1.232220323","rc":[{"batb":[[0,2.34,5],[1,2.32,32.53],[2,1.9,998.13]],"ltp":2.36,"tv":20.22,"id":891555}]}]}
{"op":"mcm","clk":"11915292689","pt":1724540251393,"mc":[{"id":"1.232220323","rc":[{"batb":[[0,2.32,32.53],[1,1.9,998.13],[2,1.85,738.46]],"ltp":2.36,"tv":20.22,"id":891555}]}]}
{"op":"mcm","clk":"11915292791","pt":1724540253808,"mc":[{"id":"1.232220323","rc":[{"batb":[[0,2.34,5],[1,2.32,32.53],[2,1.9,998.13]],"ltp":2.36,"tv":20.22,"id":891555}]}]}
{"op":"mcm","clk":"11915292950","pt":1724540257097,"mc":[{"id":"1.232220323","rc":[{"batb":[[0,2.32,32.53],[1,1.9,998.13],[2,1.85,738.46]],"ltp":2.36,"tv":20.22,"id":891555}]}]}
{"op":"mcm","clk":"11915293088","pt":1724540260434,"mc":[{"id":"1.232220323","rc":[{"batb":[[0,2.34,5],[1,2.32,32.53],[2,1.9,998.13]],"ltp":2.36,"tv":20.22,"id":891555}]}]}
{"op":"mcm","clk":"11915293255","pt":1724540263928,"mc":[{"id":"1.232220323","rc":[{"batb":[[0,2.32,32.53],[1,1.9,998.13],[2,1.85,738.46]],"ltp":2.36,"tv":20.22,"id":891555}]}]}
{"op":"mcm","clk":"11915293369","pt":1724540266137,"mc":[{"id":"1.232220323","rc":[{"batb":[[0,2.34,5],[1,2.32,32.53],[2,1.9,998.13]],"ltp":2.36,"tv":20.22,"id":891555}]}]}
{"op":"mcm","clk":"11915293561","pt":1724540269596,"mc":[{"id":"1.232220323","rc":[{"batb":[[0,2.32,32.53],[1,1.9,998.13],[2,1.85,738.46]],"ltp":2.36,"tv":20.22,"id":891555}]}]}
{"op":"mcm","clk":"11915293649","pt":1724540271903,"mc":[{"id":"1.232220323","rc":[{"batb":[[0,2.34,5],[1,2.32,32.53],[2,1.9,998.13]],"ltp":2.36,"tv":20.22,"id":891555}]}]}
{"op":"mcm","clk":"11915293795","pt":1724540275196,"mc":[{"id":"1.232220323","rc":[{"batb":[[0,2.32,32.53],[1,1.9,998.13],[2,1.85,738.46]],"ltp":2.36,"tv":20.22,"id":891555}]}]}
{"op":"mcm","clk":"11915293928","pt":1724540278120,"mc":[{"id":"1.232220323","rc":[{"batb":[[0,2.34,5],[1,2.32,32.53],[2,1.9,998.13]],"ltp":2.36,"tv":20.22,"id":891555}]}]}
{"op":"mcm","clk":"11915294082","pt":1724540281452,"mc":[{"id":"1.232220323","rc":[{"batb":[[0,2.32,32.53],[1,1.9,998.13],[2,1.85,738.46]],"ltp":2.36,"tv":20.22,"id":891555}]}]}
{"op":"mcm","clk":"11915294283","pt":1724540284952,"mc":[{"id":"1.232220323","rc":[{"batb":[[0,2.34,5],[1,2.32,32.53],[2,1.9,998.13]],"ltp":2.36,"tv":20.22,"id":891555}]}]}
{"op":"mcm","clk":"11915294433","pt":1724540288343,"mc":[{"id":"1.232220323","rc":[{"batb":[[0,2.32,32.53],[1,1.9,998.13],[2,1.85,738.46]],"ltp":2.36,"tv":20.22,"id":891555}]}]}
{"op":"mcm","clk":"11915294557","pt":1724540290661,"mc":[{"id":"1.232220323","rc":[{"batb":[[0,2.34,5],[1,2.32,32.53],[2,1.9,998.13]],"ltp":2.36,"tv":20.22,"id":891555}]}]}
{"op":"mcm","clk":"11915294722","pt":1724540293954,"mc":[{"id":"1.232220323","rc":[{"batb":[[0,2.32,32.53],[1,1.9,998.13],[2,1.85,738.46]],"ltp":2.36,"tv":20.22,"id":891555}]}]}
{"op":"mcm","clk":"11915294868","pt":1724540296523,"mc":[{"id":"1.232220323","rc":[{"batb":[[0,2.34,5],[1,2.32,32.53],[2,1.9,998.13]],"ltp":2.36,"tv":20.22,"id":891555}]}]}
{"op":"mcm","clk":"11915294989","pt":1724540299756,"mc":[{"id":"1.232220323","rc":[{"batb":[[0,2.32,32.53],[1,1.9,998.13],[2,1.85,738.46]],"ltp":2.36,"tv":20.22,"id":891555}]}]}
{"op":"mcm","clk":"11915295092","pt":1724540302267,"mc":[{"id":"1.232220323","rc":[{"batb":[[0,2.34,5],[1,2.32,32.53],[2,1.9,998.13]],"ltp":2.36,"tv":20.22,"id":891555}]}]}
{"op":"mcm","clk":"11915295254","pt":1724540305550,"mc":[{"id":"1.232220323","rc":[{"batb":[[0,2.32,32.53],[1,1.9,998.13],[2,1.85,738.46]],"ltp":2.36,"tv":20.22,"id":891555}]}]}
{"op":"mcm","clk":"11915295345","pt":1724540307957,"mc":[{"id":"1.232220323","rc":[{"batb":[[0,2.34,5],[1,2.32,32.53],[2,1.9,998.13]],"ltp":2.36,"tv":20.22,"id":891555}]}]}
{"op":"mcm","clk":"11915295502","pt":1724540311343,"mc":[{"id":"1.232220323","rc":[{"batb":[[0,2.32,32.53],[1,1.9,998.13],[2,1.85,738.46]],"ltp":2.36,"tv":20.22,"id":891555}]}]}
{"op":"mcm","clk":"11915295617","pt":1724540313659,"mc":[{"id":"1.232220323","rc":[{"batb":[[0,2.34,5],[1,2.32,32.53],[2,1.9,998.13]],"ltp":2.36,"tv":20.22,"id":891555}]}]}
{"op":"mcm","clk":"11915295780","pt":1724540316883,"mc":[{"id":"1.232220323","rc":[{"batb":[[0,2.32,32.53],[1,1.9,998.13],[2,1.85,738.46]],"ltp":2.36,"tv":20.22,"id":891555}]}]}
{"op":"mcm","clk":"11915295893","pt":1724540319448,"mc":[{"id":"1.232220323","rc":[{"batb":[[0,2.34,5],[1,2.32,32.53],[2,1.9,998.13]],"ltp":2.36,"tv":20.22,"id":891555}]}]}
{"op":"mcm","clk":"11915296062","pt":1724540322791,"mc":[{"id":"1.232220323","rc":[{"batb":[[0,2.32,32.53],[1,1.9,998.13],[2,1.85,738.46]],"ltp":2.36,"tv":20.22,"id":891555}]}]}
{"op":"mcm","clk":"11915296186","pt":1724540325103,"mc":[{"id":"1.232220323","rc":[{"batb":[[0,2.34,5],[1,2.32,32.53],[2,1.9,998.13]],"ltp":2.36,"tv":20.22,"id":891555}]}]}
{"op":"mcm","clk":"11915296344","pt":1724540328492,"mc":[{"id":"1.232220323","rc":[{"batb":[[0,2.32,32.53],[1,1.9,998.13],[2,1.85,738.46]],"ltp":2.36,"tv":20.22,"id":891555}]}]}
{"op":"mcm","clk":"11915296443","pt":1724540330900,"mc":[{"id":"1.232220323","rc":[{"batb":[[0,2.34,5],[1,2.32,32.53],[2,1.9,998.13]],"ltp":2.36,"tv":20.22,"id":891555}]}]}
{"op":"mcm","clk":"11915296589","pt":1724540334088,"mc":[{"id":"1.232220323","rc":[{"batb":[[0,2.32,32.53],[1,1.9,998.13],[2,1.85,738.46]],"ltp":2.36,"tv":20.22,"id":891555}]}]}
{"op":"mcm","clk":"11915296740","pt":1724540336708,"mc":[{"id":"1.232220323","rc":[{"batb":[[0,2.34,5],[1,2.32,32.53],[2,1.9,998.13]],"ltp":2.36,"tv":20.22,"id":891555}]}]}
{"op":"mcm","clk":"11915296875","pt":1724540340101,"mc":[{"id":"1.232220323","rc":[{"batb":[[0,2.32,32.53],[1,1.9,998.13],[2,1.85,738.46]],"ltp":2.36,"tv":20.22,"id":891555}]}]}
{"op":"mcm","clk":"11915296983","pt":1724540342420,"mc":[{"id":"1.232220323","rc":[{"batb":[[0,2.34,5],[1,2.32,32.53],[2,1.9,998.13]],"ltp":2.36,"tv":20.22,"id":891555}]}]}
{"op":"mcm","clk":"11915297148","pt":1724540345829,"mc":[{"id":"1.232220323","rc":[{"batb":[[0,2.32,32.53],[1,1.9,998.13],[2,1.85,738.46]],"ltp":2.36,"tv":20.22,"id":891555}]}]}
{"op":"mcm","clk":"11915297323","pt":1724540349502,"mc":[{"id":"1.232220323","rc":[{"batb":[[0,2.34,5],[1,2.32,32.53],[2,1.9,998.13]],"ltp":2.36,"tv":20.22,"id":891555}]}]}
{"op":"mcm","clk":"11915297502","pt":1724540352842,"mc":[{"id":"1.232220323","rc":[{"batb":[[0,2.32,32.53],[1,1.9,998.13],[2,1.85,738.46]],"ltp":2.36,"tv":20.22,"id":891555}]}]}
{"op":"mcm","clk":"11915297643","pt":1724540355212,"mc":[{"id":"1.232220323","rc":[{"batb":[[0,2.34,5],[1,2.32,32.53],[2,1.9,998.13]],"ltp":2.36,"tv":20.22,"id":891555}]}]}
{"op":"mcm","clk":"11915297843","pt":1724540358617,"mc":[{"id":"1.232220323","rc":[{"batb":[[0,2.32,32.53],[1,1.9,998.13],[2,1.85,738.46]],"ltp":2.36,"tv":20.22,"id":891555}]}]}
{"op":"mcm","clk":"11915298004","pt":1724540361438,"mc":[{"id":"1.232220323","rc":[{"batb":[[0,2.34,5],[1,2.32,32.53],[2,1.9,998.13]],"ltp":2.36,"tv":20.22,"id":891555}]}]}
{"op":"mcm","clk":"11915298150","pt":1724540364624,"mc":[{"id":"1.232220323","rc":[{"batb":[[0,2.32,32.53],[1,1.9,998.13],[2,1.85,738.46]],"ltp":2.36,"tv":20.22,"id":891555}]}]}
{"op":"mcm","clk":"11915298277","pt":1724540367347,"mc":[{"id":"1.232220323","rc":[{"batb":[[0,2.34,5],[1,2.32,32.53],[2,1.9,998.13]],"ltp":2.36,"tv":20.22,"id":891555}]}]}
{"op":"mcm","clk":"11915298425","pt":1724540370663,"mc":[{"id":"1.232220323","rc":[{"batb":[[0,2.32,32.53],[1,1.9,998.13],[2,1.85,738.46]],"ltp":2.36,"tv":20.22,"id":891555}]}]}
{"op":"mcm","clk":"11915298548","pt":1724540373031,"mc":[{"id":"1.232220323","rc":[{"batb":[[0,2.34,5],[1,2.32,32.53],[2,1.9,998.13]],"ltp":2.36,"tv":20.22,"id":891555}]}]}
{"op":"mcm","clk":"11915298721","pt":1724540376535,"mc":[{"id":"1.232220323","rc":[{"batb":[[0,2.32,32.53],[1,1.9,998.13],[2,1.85,738.46]],"ltp":2.36,"tv":20.22,"id":891555}]}]}
{"op":"mcm","clk":"11915298820","pt":1724540378852,"mc":[{"id":"1.232220323","rc":[{"batb":[[0,2.34,5],[1,2.32,32.53],[2,1.9,998.13]],"ltp":2.36,"tv":20.22,"id":891555}]}]}
{"op":"mcm","clk":"11915298976","pt":1724540382348,"mc":[{"id":"1.232220323","rc":[{"batb":[[0,2.32,32.53],[1,1.9,998.13],[2,1.85,738.46]],"ltp":2.36,"tv":20.22,"id":891555}]}]}
{"op":"mcm","clk":"11915299072","pt":1724540384558,"mc":[{"id":"1.232220323","rc":[{"batb":[[0,2.34,5],[1,2.32,32.53],[2,1.9,998.13]],"ltp":2.36,"tv":20.22,"id":891555}]}]}
{"op":"mcm","clk":"11915299231","pt":1724540387855,"mc":[{"id":"1.232220323","rc":[{"batb":[[0,2.32,32.53],[1,1.9,998.13],[2,1.85,738.46]],"ltp":2.36,"tv":20.22,"id":891555}]}]}
{"op":"mcm","clk":"11915299347","pt":1724540390378,"mc":[{"id":"1.232220323","rc":[{"batb":[[0,2.34,5],[1,2.32,32.53],[2,1.9,998.13]],"ltp":2.36,"tv":20.22,"id":891555}]}]}
{"op":"mcm","clk":"11915299525","pt":1724540393670,"mc":[{"id":"1.232220323","rc":[{"batb":[[0,2.32,32.53],[1,1.9,998.13],[2,1.85,738.46]],"ltp":2.36,"tv":20.22,"id":891555}]}]}
{"op":"mcm","clk":"11915299709","pt":1724540397267,"mc":[{"id":"1.232220323","rc":[{"batb":[[0,2.34,5],[1,2.32,32.53],[2,1.9,998.13]],"ltp":2.36,"tv":20.22,"id":891555}]}]}
{"op":"mcm","clk":"11915299901","pt":1724540400577,"mc":[{"id":"1.232220323","rc":[{"batb":[[0,2.32,32.53],[1,1.9,998.13],[2,1.85,738.46]],"ltp":2.36,"tv":20.22,"id":891555}]}]}
{"op":"mcm","clk":"11915300184","pt":1724540403265,"mc":[{"id":"1.232220323","rc":[{"batb":[[0,2.34,5],[1,2.32,32.53],[2,1.9,998.13]],"ltp":2.36,"tv":20.22,"id":891555}]}]}
{"op":"mcm","clk":"11915300428","pt":1724540406707,"mc":[{"id":"1.232220323","rc":[{"batb":[[0,2.32,32.53],[1,1.9,998.13],[2,1.85,738.46]],"ltp":2.36,"tv":20.22,"id":891555}]}]}
{"op":"mcm","clk":"11915300573","pt":1724540408890,"mc":[{"id":"1.232220323","rc":[{"batb":[[0,2.34,5],[1,2.32,32.53],[2,1.9,998.13]],"ltp":2.36,"tv":20.22,"id":891555}]}]}
{"op":"mcm","clk":"11915300838","pt":1724540412104,"mc":[{"id":"1.232220323","rc":[{"batb":[[0,2.32,32.53],[1,1.9,998.13],[2,1.85,738.46]],"ltp":2.36,"tv":20.22,"id":891555}]}]}
{"op":"mcm","clk":"11915301028","pt":1724540414588,"mc":[{"id":"1.232220323","rc":[{"batb":[[0,2.34,5],[1,2.32,32.53],[2,1.9,998.13]],"ltp":2.36,"tv":20.22,"id":891555}]}]}
{"op":"mcm","clk":"11915301223","pt":1724540417881,"mc":[{"id":"1.232220323","rc":[{"batb":[[0,2.32,32.53],[1,1.9,998.13],[2,1.85,738.46]],"ltp":2.36,"tv":20.22,"id":891555}]}]}
{"op":"mcm","clk":"11915301362","pt":1724540420192,"mc":[{"id":"1.232220323","rc":[{"batb":[[0,2.34,5],[1,2.32,32.53],[2,1.9,998.13]],"ltp":2.36,"tv":20.22,"id":891555}]}]}
{"op":"mcm","clk":"11915301569","pt":1724540423389,"mc":[{"id":"1.232220323","rc":[{"batb":[[0,2.32,32.53],[1,1.9,998.13],[2,1.85,738.46]],"ltp":2.36,"tv":20.22,"id":891555}]}]}
{"op":"mcm","clk":"11915301761","pt":1724540425810,"mc":[{"id":"1.232220323","rc":[{"batb":[[0,2.34,5],[1,2.32,32.53],[2,1.9,998.13]],"ltp":2.36,"tv":20.22,"id":891555}]}]}
{"op":"mcm","clk":"11915301979","pt":1724540429106,"mc":[{"id":"1.232220323","rc":[{"batb":[[0,2.32,32.53],[1,1.9,998.13],[2,1.85,738.46]],"ltp":2.36,"tv":20.22,"id":891555}]}]}
{"op":"mcm","clk":"11915302129","pt":1724540431625,"mc":[{"id":"1.232220323","rc":[{"batb":[[0,2.34,5],[1,2.32,32.53],[2,1.9,998.13]],"ltp":2.36,"tv":20.22,"id":891555}]}]}
{"op":"mcm","clk":"11915302320","pt":1724540435008,"mc":[{"id":"1.232220323","rc":[{"batb":[[0,2.32,32.53],[1,1.9,998.13],[2,1.85,738.46]],"ltp":2.36,"tv":20.22,"id":891555}]}]}
{"op":"mcm","clk":"11915302452","pt":1724540437242,"mc":[{"id":"1.232220323","rc":[{"batb":[[0,2.34,5],[1,2.32,32.53],[2,1.9,998.13]],"ltp":2.36,"tv":20.22,"id":891555}]}]}
{"op":"mcm","clk":"11915302630","pt":1724540440549,"mc":[{"id":"1.232220323","rc":[{"batb":[[0,2.32,32.53],[1,1.9,998.13],[2,1.85,738.46]],"ltp":2.36,"tv":20.22,"id":891555}]}]}
{"op":"mcm","clk":"11915302781","pt":1724540442822,"mc":[{"id":"1.232220323","rc":[{"batb":[[0,2.34,5],[1,2.32,32.53],[2,1.9,998.13]],"ltp":2.36,"tv":20.22,"id":891555}]}]}
{"op":"mcm","clk":"11915302946","pt":1724540446228,"mc":[{"id":"1.232220323","rc":[{"batb":[[0,2.32,32.53],[1,1.9,998.13],[2,1.85,738.46]],"ltp":2.36,"tv":20.22,"id":891555}]}]}
{"op":"mcm","clk":"11915303108","pt":1724540448747,"mc":[{"id":"1.232220323","rc":[{"batb":[[0,2.34,5],[1,2.32,32.53],[2,1.9,998.13]],"ltp":2.36,"tv":20.22,"id":891555}]}]}
{"op":"mcm","clk":"11915303282","pt":1724540452159,"mc":[{"id":"1.232220323","rc":[{"batb":[[0,2.32,32.53],[1,1.9,998.13],[2,1.85,738.46]],"ltp":2.36,"tv":20.22,"id":891555}]}]}
{"op":"mcm","clk":"11915303424","pt":1724540454535,"mc":[{"id":"1.232220323","rc":[{"batb":[[0,2.34,5],[1,2.32,32.53],[2,1.9,998.13]],"ltp":2.36,"tv":20.22,"id":891555}]}]}
{"op":"mcm","clk":"11915303616","pt":1724540457840,"mc":[{"id":"1.232220323","rc":[{"batb":[[0,2.32,32.53],[1,1.9,998.13],[2,1.85,738.46]],"ltp":2.36,"tv":20.22,"id":891555}]}]}
{"op":"mcm","clk":"11915303762","pt":1724540460672,"mc":[{"id":"1.232220323","rc":[{"batb":[[0,2.34,5],[1,2.32,32.53],[2,1.9,998.13]],"ltp":2.36,"tv":20.22,"id":891555}]}]}
{"op":"mcm","clk":"11915303994","pt":1724540464049,"mc":[{"id":"1.232220323","rc":[{"batb":[[0,2.32,32.53],[1,1.9,998.13],[2,1.85,738.46]],"ltp":2.36,"tv":20.22,"id":891555}]}]}
{"op":"mcm","clk":"11915304126","pt":1724540466472,"mc":[{"id":"1.232220323","rc":[{"batb":[[0,2.34,5],[1,2.32,32.53],[2,1.9,998.13]],"ltp":2.36,"tv":20.22,"id":891555}]}]}
{"op":"mcm","clk":"11915304304","pt":1724540469768,"mc":[{"id":"1.232220323","rc":[{"batb":[[0,2.32,32.53],[1,1.9,998.13],[2,1.85,738.46]],"ltp":2.36,"tv":20.22,"id":891555}]}]}
{"op":"mcm","clk":"11915304443","pt":1724540472153,"mc":[{"id":"1.232220323","rc":[{"batb":[[0,2.34,5],[1,2.32,32.53],[2,1.9,998.13]],"ltp":2.36,"tv":20.22,"id":891555}]}]}
{"op":"mcm","clk":"11915304624","pt":1724540475654,"mc":[{"id":"1.232220323","rc":[{"batb":[[0,2.32,32.53],[1,1.9,998.13],[2,1.85,738.46]],"ltp":2.36,"tv":20.22,"id":891555}]}]}
{"op":"mcm","clk":"11915304820","pt":1724540478760,"mc":[{"id":"1.232220323","rc":[{"batb":[[0,2.34,5],[1,2.32,32.53],[2,1.9,998.13]],"ltp":2.36,"tv":20.22,"id":891555}]}]}
{"op":"mcm","clk":"11915305049","pt":1724540482169,"mc":[{"id":"1.232220323","rc":[{"batb":[[0,2.32,32.53],[1,1.9,998.13],[2,1.85,738.46]],"ltp":2.36,"tv":20.22,"id":891555}]}]}
{"op":"mcm","clk":"11915305201","pt":1724540484457,"mc":[{"id":"1.232220323","rc":[{"batb":[[0,2.34,5],[1,2.32,32.53],[2,1.9,998.13]],"ltp":2.36,"tv":20.22,"id":891555}]}]}
{"op":"mcm","clk":"11915305417","pt":1724540487758,"mc":[{"id":"1.232220323","rc":[{"batb":[[0,2.32,32.53],[1,1.9,998.13],[2,1.85,738.46]],"ltp":2.36,"tv":20.22,"id":891555}]}]}
{"op":"mcm","clk":"11915305557","pt":1724540490187,"mc":[{"id":"1.232220323","rc":[{"batb":[[0,2.34,5],[1,2.32,32.53],[2,1.9,998.13]],"ltp":2.36,"tv":20.22,"id":891555}]}]}
{"op":"mcm","clk":"11915305763","pt":1724540493563,"mc":[{"id":"1.232220323","rc":[{"batb":[[0,2.32,32.53],[1,1.9,998.13],[2,1.85,738.46]],"ltp":2.36,"tv":20.22,"id":891555}]}]}
{"op":"mcm","clk":"11915305957","pt":1724540496250,"mc":[{"id":"1.232220323","rc":[{"batb":[[0,2.34,5],[1,2.32,32.53],[2,1.9,998.13]],"ltp":2.36,"tv":20.22,"id":891555}]}]}
{"op":"mcm","clk":"11915306193","pt":1724540499666,"mc":[{"id":"1.232220323","rc":[{"batb":[[0,2.32,32.53],[1,1.9,998.13],[2,1.85,738.46]],"ltp":2.36,"tv":20.22,"id":891555}]}]}
{"op":"mcm","clk":"11915306316","pt":1724540501937,"mc":[{"id":"1.232220323","rc":[{"batb":[[0,2.34,5],[1,2.32,32.53],[2,1.9,998.13]],"ltp":2.36,"tv":20.22,"id":891555}]}]}
{"op":"mcm","clk":"11915306510","pt":1724540505137,"mc":[{"id":"1.232220323","rc":[{"batb":[[0,2.32,32.53],[1,1.9,998.13],[2,1.85,738.46]],"ltp":2.36,"tv":20.22,"id":891555}]}]}
{"op":"mcm","clk":"11915306649","pt":1724540507558,"mc":[{"id":"1.232220323","rc":[{"batb":[[0,2.34,5],[1,2.32,32.53],[2,1.9,998.13]],"ltp":2.36,"tv":20.22,"id":891555}]}]}
{"op":"mcm","clk":"11915306853","pt":1724540510861,"mc":[{"id":"1.232220323","rc":[{"batb":[[0,2.32,32.53],[1,1.9,998.13],[2,1.85,738.46]],"ltp":2.36,"tv":20.22,"id":891555}]}]}
{"op":"mcm","clk":"11915307006","pt":1724540513280,"mc":[{"id":"1.232220323","rc":[{"batb":[[0,2.34,5],[1,2.32,32.53],[2,1.9,998.13]],"ltp":2.36,"tv":20.22,"id":891555}]}]}
{"op":"mcm","clk":"11915307222","pt":1724540516580,"mc":[{"id":"1.232220323","rc":[{"batb":[[0,2.32,32.53],[1,1.9,998.13],[2,1.85,738.46]],"ltp":2.36,"tv":20.22,"id":891555}]}]}
{"op":"mcm","clk":"11915307378","pt":1724540518851,"mc":[{"id":"1.232220323","rc":[{"batb":[[0,2.34,5],[1,2.32,32.53],[2,1.9,998.13]],"ltp":2.36,"tv":20.22,"id":891555}]}]}
{"op":"mcm","clk":"11915307576","pt":1724540522057,"mc":[{"id":"1.232220323","rc":[{"batb":[[0,2.32,32.53],[1,1.9,998.13],[2,1.85,738.46]],"ltp":2.36,"tv":20.22,"id":891555}]}]}
{"op":"mcm","clk":"11915307759","pt":1724540525058,"mc":[{"id":"1.232220323","rc":[{"batb":[[0,2.34,5],[1,2.32,32.53],[2,1.9,998.13]],"ltp":2.36,"tv":20.22,"id":891555}]}]}
{"op":"mcm","clk":"11915307934","pt":1724540528460,"mc":[{"id":"1.232220323","rc":[{"batb":[[0,2.32,32.53],[1,1.9,998.13],[2,1.85,738.46]],"ltp":2.36,"tv":20.22,"id":891555}]}]}
{"op":"mcm","clk":"11915308071","pt":1724540530675,"mc":[{"id":"1.232220323","rc":[{"batb":[[0,2.34,5],[1,2.32,32.53],[2,1.9,998.13]],"ltp":2.36,"tv":20.22,"id":891555}]}]}
{"op":"mcm","clk":"11915308288","pt":1724540533975,"mc":[{"id":"1.232220323","rc":[{"batb":[[0,2.32,32.53],[1,1.9,998.13],[2,1.85,738.46]],"ltp":2.36,"tv":20.22,"id":891555}]}]}
{"op":"mcm","clk":"11915308419","pt":1724540536467,"mc":[{"id":"1.232220323","rc":[{"batb":[[0,2.34,5],[1,2.32,32.53],[2,1.9,998.13]],"ltp":2.36,"tv":20.22,"id":891555}]}]}
{"op":"mcm","clk":"11915308648","pt":1724540539765,"mc":[{"id":"1.232220323","rc":[{"batb":[[0,2.32,32.53],[1,1.9,998.13],[2,1.85,738.46]],"ltp":2.36,"tv":20.22,"id":891555}]}]}
{"op":"mcm","clk":"11915308793","pt":1724540542190,"mc":[{"id":"1.232220323","rc":[{"batb":[[0,2.34,5],[1,2.32,32.53],[2,1.9,998.13]],"ltp":2.36,"tv":20.22,"id":891555}]}]}
{"op":"mcm","clk":"11915308970","pt":1724540545696,"mc":[{"id":"1.232220323","rc":[{"batb":[[0,2.32,32.53],[1,1.9,998.13],[2,1.85,738.46]],"ltp":2.36,"tv":20.22,"id":891555}]}]}
{"op":"mcm","clk":"11915309165","pt":1724540548788,"mc":[{"id":"1.232220323","rc":[{"batb":[[0,2.34,5],[1,2.32,32.53],[2,1.9,998.13]],"ltp":2.36,"tv":20.22,"id":891555}]}]}
{"op":"mcm","clk":"11915309360","pt":1724540552090,"mc":[{"id":"1.232220323","rc":[{"batb":[[0,2.32,32.53],[1,1.9,998.13],[2,1.85,738.46]],"ltp":2.36,"tv":20.22,"id":891555}]}]}
{"op":"mcm","clk":"11915309581","pt":1724540556419,"mc":[{"id":"1.232220323","rc":[{"batb":[[0,2.34,5],[1,2.32,32.53],[2,1.9,998.13]],"ltp":2.36,"tv":20.22,"id":891555}]}]}
{"op":"mcm","clk":"11915309709","pt":1724540559710,"mc":[{"id":"1.232220323","rc":[{"batb":[[0,2.32,32.53],[1,1.9,998.13],[2,1.85,738.46]],"ltp":2.36,"tv":20.22,"id":891555}]}]}
{"op":"mcm","clk":"11915309845","pt":1724540562081,"mc":[{"id":"1.232220323","rc":[{"batb":[[0,2.34,5],[1,2.32,32.53],[2,1.9,998.13]],"ltp":2.36,"tv":20.22,"id":891555}]}]}
{"op":"mcm","clk":"11915309978","pt":1724540565430,"mc":[{"id":"1.232220323","rc":[{"batb":[[0,2.32,32.53],[1,1.9,998.13],[2,1.85,738.46]],"ltp":2.36,"tv":20.22,"id":891555}]}]}
{"op":"mcm","clk":"11915310122","pt":1724540568011,"mc":[{"id":"1.232220323","rc":[{"batb":[[0,2.34,5],[1,2.32,32.53],[2,1.9,998.13]],"ltp":2.36,"tv":20.22,"id":891555}]}]}
{"op":"mcm","clk":"11915310300","pt":1724540571413,"mc":[{"id":"1.232220323","rc":[{"batb":[[0,2.32,32.53],[1,1.9,998.13],[2,1.85,738.46]],"ltp":2.36,"tv":20.22,"id":891555}]}]}
{"op":"mcm","clk":"11915310408","pt":1724540573735,"mc":[{"id":"1.232220323","rc":[{"batb":[[0,2.34,5],[1,2.32,32.53],[2,1.9,998.13]],"ltp":2.36,"tv":20.22,"id":891555}]}]}
{"op":"mcm","clk":"11915310590","pt":1724540577242,"mc":[{"id":"1.232220323","rc":[{"batb":[[0,2.32,32.53],[1,1.9,998.13],[2,1.85,738.46]],"ltp":2.36,"tv":20.22,"id":891555}]}]}
{"op":"mcm","clk":"11915310737","pt":1724540579617,"mc":[{"id":"1.232220323","rc":[{"batb":[[0,2.34,5],[1,2.32,32.53],[2,1.9,998.13]],"ltp":2.36,"tv":20.22,"id":891555}]}]}
{"op":"mcm","clk":"11915310929","pt":1724540582831,"mc":[{"id":"1.232220323","rc":[{"batb":[[0,2.32,32.53],[1,1.9,998.13],[2,1.85,738.46]],"ltp":2.36,"tv":20.22,"id":891555}]}]}
{"op":"mcm","clk":"11915311089","pt":1724540585416,"mc":[{"id":"1.232220323","rc":[{"batb":[[0,2.34,5],[1,2.32,32.53],[2,1.9,998.13]],"ltp":2.36,"tv":20.22,"id":891555}]}]}
{"op":"mcm","clk":"11915311238","pt":1724540588660,"mc":[{"id":"1.232220323","rc":[{"batb":[[0,2.32,32.53],[1,1.9,998.13],[2,1.85,738.46]],"ltp":2.36,"tv":20.22,"id":891555}]}]}
{"op":"mcm","clk":"11915311372","pt":1724540591036,"mc":[{"id":"1.232220323","rc":[{"batb":[[0,2.34,5],[1,2.32,32.53],[2,1.9,998.13]],"ltp":2.36,"tv":20.22,"id":891555}]}]}
{"op":"mcm","clk":"11915311564","pt":1724540594436,"mc":[{"id":"1.232220323","rc":[{"batb":[[0,2.32,32.53],[1,1.9,998.13],[2,1.85,738.46]],"ltp":2.36,"tv":20.22,"id":891555}]}]}
{"op":"mcm","clk":"11915311692","pt":1724540596753,"mc":[{"id":"1.232220323","rc":[{"batb":[[0,2.34,5],[1,2.32,32.53],[2,1.9,998.13]],"ltp":2.36,"tv":20.22,"id":891555}]}]}
{"op":"mcm","clk":"11915311874","pt":1724540599948,"mc":[{"id":"1.232220323","rc":[{"batb":[[0,2.32,32.53],[1,1.9,998.13],[2,1.85,738.46]],"ltp":2.36,"tv":20.22,"id":891555}]}]}
{"op":"mcm","clk":"11915312005","pt":1724540602475,"mc":[{"id":"1.232220323","rc":[{"batb":[[0,2.34,5],[1,2.32,32.53],[2,1.9,998.13]],"ltp":2.36,"tv":20.22,"id":891555}]}]}
{"op":"mcm","clk":"11915312217","pt":1724540605939,"mc":[{"id":"1.232220323","rc":[{"batb":[[0,2.32,32.53],[1,1.9,998.13],[2,1.85,738.46]],"ltp":2.36,"tv":20.22,"id":891555}]}]}
{"op":"mcm","clk":"11915312378","pt":1724540608367,"mc":[{"id":"1.232220323","rc":[{"batb":[[0,2.34,5],[1,2.32,32.53],[2,1.9,998.13]],"ltp":2.36,"tv":20.22,"id":891555}]}]}
{"op":"mcm","clk":"11915312561","pt":1724540611773,"mc":[{"id":"1.232220323","rc":[{"batb":[[0,2.32,32.53],[1,1.9,998.13],[2,1.85,738.46]],"ltp":2.36,"tv":20.22,"id":891555}]}]}
{"op":"mcm","clk":"11915312811","pt":1724540615384,"mc":[{"id":"1.232220323","rc":[{"batb":[[0,2.34,5],[1,2.32,32.53],[2,1.9,998.13]],"ltp":2.36,"tv":20.22,"id":891555}]}]}
{"op":"mcm","clk":"11915312992","pt":1724540618641,"mc":[{"id":"1.232220323","rc":[{"batb":[[0,2.32,32.53],[1,1.9,998.13],[2,1.85,738.46]],"ltp":2.36,"tv":20.22,"id":891555}]}]}
{"op":"mcm","clk":"11915313140","pt":1724540621071,"mc":[{"id":"1.232220323","rc":[{"batb":[[0,2.34,5],[1,2.32,32.53],[2,1.9,998.13]],"ltp":2.36,"tv":20.22,"id":891555}]}]}
{"op":"mcm","clk":"11915313366","pt":1724540624289,"mc":[{"id":"1.232220323","rc":[{"batb":[[0,2.32,32.53],[1,1.9,998.13],[2,1.85,738.46]],"ltp":2.36,"tv":20.22,"id":891555}]}]}
{"op":"mcm","clk":"11915313530","pt":1724540626897,"mc":[{"id":"1.232220323","rc":[{"batb":[[0,2.34,5],[1,2.32,32.53],[2,1.9,998.13]],"ltp":2.36,"tv":20.22,"id":891555}]}]}
{"op":"mcm","clk":"11915313746","pt":1724540630166,"mc":[{"id":"1.232220323","rc":[{"batb":[[0,2.32,32.53],[1,1.9,998.13],[2,1.85,738.46]],"ltp":2.36,"tv":20.22,"id":891555}]}]}
{"op":"mcm","clk":"11915313847","pt":1724540632586,"mc":[{"id":"1.232220323","rc":[{"batb":[[0,2.34,5],[1,2.32,32.53],[2,1.9,998.13]],"ltp":2.36,"tv":20.22,"id":891555}]}]}
{"op":"mcm","clk":"11915314037","pt":1724540635895,"mc":[{"id":"1.232220323","rc":[{"batb":[[0,2.32,32.53],[1,1.9,998.13],[2,1.85,738.46]],"ltp":2.36,"tv":20.22,"id":891555}]}]}
{"op":"mcm","clk":"11915314212","pt":1724540638265,"mc":[{"id":"1.232220323","rc":[{"batb":[[0,2.34,5],[1,2.32,32.53],[2,1.9,998.13]],"ltp":2.36,"tv":20.22,"id":891555}]}]}
{"op":"mcm","clk":"11915314388","pt":1724540641676,"mc":[{"id":"1.232220323","rc":[{"batb":[[0,2.32,32.53],[1,1.9,998.13],[2,1.85,738.46]],"ltp":2.36,"tv":20.22,"id":891555}]}]}
{"op":"mcm","clk":"11915314549","pt":1724540644205,"mc":[{"id":"1.232220323","rc":[{"batb":[[0,2.34,5],[1,2.32,32.53],[2,1.9,998.13]],"ltp":2.36,"tv":20.22,"id":891555}]}]}
{"op":"mcm","clk":"11915314738","pt":1724540647601,"mc":[{"id":"1.232220323","rc":[{"batb":[[0,2.32,32.53],[1,1.9,998.13],[2,1.85,738.46]],"ltp":2.36,"tv":20.22,"id":891555}]}]}
{"op":"mcm","clk":"11915314872","pt":1724540649977,"mc":[{"id":"1.232220323","rc":[{"batb":[[0,2.34,5],[1,2.32,32.53],[2,1.9,998.13]],"ltp":2.36,"tv":20.22,"id":891555}]}]}
{"op":"mcm","clk":"11915315104","pt":1724540653190,"mc":[{"id":"1.232220323","rc":[{"batb":[[0,2.32,32.53],[1,1.9,998.13],[2,1.85,738.46]],"ltp":2.36,"tv":20.22,"id":891555}]}]}
{"op":"mcm","clk":"11915315245","pt":1724540655601,"mc":[{"id":"1.232220323","rc":[{"batb":[[0,2.34,5],[1,2.32,32.53],[2,1.9,998.13]],"ltp":2.36,"tv":20.22,"id":891555}]}]}
{"op":"mcm","clk":"11915315426","pt":1724540658907,"mc":[{"id":"1.232220323","rc":[{"batb":[[0,2.32,32.53],[1,1.9,998.13],[2,1.85,738.46]],"ltp":2.36,"tv":20.22,"id":891555}]}]}
{"op":"mcm","clk":"11915315594","pt":1724540661520,"mc":[{"id":"1.232220323","rc":[{"batb":[[0,2.34,5],[1,2.32,32.53],[2,1.9,998.13]],"ltp":2.36,"tv":20.22,"id":891555}]}]}
{"op":"mcm","clk":"11915315754","pt":1724540664824,"mc":[{"id":"1.232220323","rc":[{"batb":[[0,2.32,32.53],[1,1.9,998.13],[2,1.85,738.46]],"ltp":2.36,"tv":20.22,"id":891555}]}]}
{"op":"mcm","clk":"11915315891","pt":1724540667147,"mc":[{"id":"1.232220323","rc":[{"batb":[[0,2.34,5],[1,2.32,32.53],[2,1.9,998.13]],"ltp":2.36,"tv":20.22,"id":891555}]}]}
{"op":"mcm","clk":"11915316115","pt":1724540670539,"mc":[{"id":"1.232220323","rc":[{"batb":[[0,2.32,32.53],[1,1.9,998.13],[2,1.85,738.46]],"ltp":2.36,"tv":20.22,"id":891555}]}]}
{"op":"mcm","clk":"11915316228","pt":1724540672850,"mc":[{"id":"1.232220323","rc":[{"batb":[[0,2.34,5],[1,2.32,32.53],[2,1.9,998.13]],"ltp":2.36,"tv":20.22,"id":891555}]}]}
{"op":"mcm","clk":"11915316429","pt":1724540676143,"mc":[{"id":"1.232220323","rc":[{"batb":[[0,2.32,32.53],[1,1.9,998.13],[2,1.85,738.46]],"ltp":2.36,"tv":20.22,"id":891555}]}]}
{"op":"mcm","clk":"11915316598","pt":1724540678535,"mc":[{"id":"1.232220323","rc":[{"batb":[[0,2.34,5],[1,2.32,32.53],[2,1.9,998.13]],"ltp":2.36,"tv":20.22,"id":891555}]}]}
{"op":"mcm","clk":"11915316788","pt":1724540681953,"mc":[{"id":"1.232220323","rc":[{"batb":[[0,2.32,32.53],[1,1.9,998.13],[2,1.85,738.46]],"ltp":2.36,"tv":20.22,"id":891555}]}]}
{"op":"mcm","clk":"11915316920","pt":1724540684335,"mc":[{"id":"1.232220323","rc":[{"batb":[[0,2.34,5],[1,2.32,32.53],[2,1.9,998.13]],"ltp":2.36,"tv":20.22,"id":891555}]}]}
{"op":"mcm","clk":"11915317094","pt":1724540687599,"mc":[{"id":"1.232220323","rc":[{"batb":[[0,2.32,32.53],[1,1.9,998.13],[2,1.85,738.46]],"ltp":2.36,"tv":20.22,"id":891555}]}]}
{"op":"mcm","clk":"11915317287","pt":1724540691274,"mc":[{"id":"1.232220323","rc":[{"batb":[[0,2.34,5],[1,2.32,32.53],[2,1.9,998.13]],"ltp":2.36,"tv":20.22,"id":891555}]}]}
{"op":"mcm","clk":"11915317497","pt":1724540694471,"mc":[{"id":"1.232220323","rc":[{"batb":[[0,2.32,32.53],[1,1.9,998.13],[2,1.85,738.46]],"ltp":2.36,"tv":20.22,"id":891555}]}]}
{"op":"mcm","clk":"11915317633","pt":1724540696844,"mc":[{"id":"1.232220323","rc":[{"batb":[[0,2.34,5],[1,2.32,32.53],[2,1.9,998.13]],"ltp":2.36,"tv":20.22,"id":891555}]}]}
{"op":"mcm","clk":"11915317807","pt":1724540700292,"mc":[{"id":"1.232220323","rc":[{"batb":[[0,2.32,32.53],[1,1.9,998.13],[2,1.85,738.46]],"ltp":2.36,"tv":20.22,"id":891555}]}]}
{"op":"mcm","clk":"11915317913","pt":1724540702456,"mc":[{"id":"1.232220323","rc":[{"batb":[[0,2.34,5],[1,2.32,32.53],[2,1.9,998.13]],"ltp":2.36,"tv":20.22,"id":891555}]}]}
{"op":"mcm","clk":"11915318088","pt":1724540705867,"mc":[{"id":"1.232220323","rc":[{"batb":[[0,2.32,32.53],[1,1.9,998.13],[2,1.85,738.46]],"ltp":2.36,"tv":20.22,"id":891555}]}]}
{"op":"mcm","clk":"11915318199","pt":1724540708698,"mc":[{"id":"1.232220323","rc":[{"batb":[[0,2.34,5],[1,2.32,32.53],[2,1.9,998.13]],"ltp":2.36,"tv":20.22,"id":891555}]}]}
{"op":"mcm","clk":"11915318383","pt":1724540711964,"mc":[{"id":"1.232220323","rc":[{"batb":[[0,2.32,32.53],[1,1.9,998.13],[2,1.85,738.46]],"ltp":2.36,"tv":20.22,"id":891555}]}]}
{"op":"mcm","clk":"11915318516","pt":1724540714295,"mc":[{"id":"1.232220323","rc":[{"batb":[[0,2.34,5],[1,2.32,32.53],[2,1.9,998.13]],"ltp":2.36,"tv":20.22,"id":891555}]}]}
{"op":"mcm","clk":"11915318767","pt":1724540718013,"mc":[{"id":"1.232220323","rc":[{"batb":[[0,2.32,32.53],[1,1.9,998.13],[2,1.85,738.46]],"ltp":2.36,"tv":20.22,"id":891555}]}]}
{"op":"mcm","clk":"11915318905","pt":1724540720381,"mc":[{"id":"1.232220323","rc":[{"batb":[[0,2.34,5],[1,2.32,32.53],[2,1.9,998.13]],"ltp":2.36,"tv":20.22,"id":891555}]}]}
{"op":"mcm","clk":"11915319113","pt":1724540723887,"mc":[{"id":"1.232220323","rc":[{"batb":[[0,2.32,32.53],[1,1.9,998.13],[2,1.85,738.46]],"ltp":2.36,"tv":20.22,"id":891555}]}]}
{"op":"mcm","clk":"11915319290","pt":1724540727290,"mc":[{"id":"1.232220323","rc":[{"batb":[[0,2.34,5],[1,2.32,32.53],[2,1.9,998.13]],"ltp":2.36,"tv":20.22,"id":891555}]}]}
{"op":"mcm","clk":"11915319466","pt":1724540730487,"mc":[{"id":"1.232220323","rc":[{"batb":[[0,2.32,32.53],[1,1.9,998.13],[2,1.85,738.46]],"ltp":2.36,"tv":20.22,"id":891555}]}]}
{"op":"mcm","clk":"11915319615","pt":1724540733328,"mc":[{"id":"1.232220323","rc":[{"batb":[[0,2.34,5],[1,2.32,32.53],[2,1.9,998.13]],"ltp":2.36,"tv":20.22,"id":891555}]}]}
{"op":"mcm","clk":"11915319802","pt":1724540736728,"mc":[{"id":"1.232220323","rc":[{"batb":[[0,2.32,32.53],[1,1.9,998.13],[2,1.85,738.46]],"ltp":2.36,"tv":20.22,"id":891555}]}]}
{"op":"mcm","clk":"11915319973","pt":1724540740128,"mc":[{"id":"1.232220323","rc":[{"batb":[[0,2.34,5],[1,2.32,32.53],[2,1.9,998.13]],"ltp":2.36,"tv":20.22,"id":891555}]}]}
{"op":"mcm","clk":"11915320155","pt":1724540743331,"mc":[{"id":"1.232220323","rc":[{"batb":[[0,2.32,32.53],[1,1.9,998.13],[2,1.85,738.46]],"ltp":2.36,"tv":20.22,"id":891555}]}]}
{"op":"mcm","clk":"11915320278","pt":1724540745605,"mc":[{"id":"1.232220323","rc":[{"batb":[[0,2.34,5],[1,2.32,32.53],[2,1.9,998.13]],"ltp":2.36,"tv":20.22,"id":891555}]}]}
{"op":"mcm","clk":"11915320443","pt":1724540748947,"mc":[{"id":"1.232220323","rc":[{"batb":[[0,2.32,32.53],[1,1.9,998.13],[2,1.85,738.46]],"ltp":2.36,"tv":20.22,"id":891555}]}]}
{"op":"mcm","clk":"11915320557","pt":1724540751331,"mc":[{"id":"1.232220323","rc":[{"batb":[[0,2.34,5],[1,2.32,32.53],[2,1.9,998.13]],"ltp":2.36,"tv":20.22,"id":891555}]}]}
{"op":"mcm","clk":"11915320756","pt":1724540754535,"mc":[{"id":"1.232220323","rc":[{"batb":[[0,2.32,32.53],[1,1.9,998.13],[2,1.85,738.46]],"ltp":2.36,"tv":20.22,"id":891555}]}]}
{"op":"mcm","clk":"11915321020","pt":1724540759837,"mc":[{"id":"1.232220323","rc":[{"batb":[[0,2.34,5],[1,2.32,32.53],[2,1.9,998.13]],"ltp":2.36,"tv":20.22,"id":891555}]}]}
{"op":"mcm","clk":"11915321176","pt":1724540763238,"mc":[{"id":"1.232220323","rc":[{"batb":[[0,2.32,32.53],[1,1.9,998.13],[2,1.85,738.46]],"ltp":2.36,"tv":20.22,"id":891555}]}]}
{"op":"mcm","clk":"11915321314","pt":1724540765658,"mc":[{"id":"1.232220323","rc":[{"batb":[[0,2.34,5],[1,2.32,32.53],[2,1.9,998.13]],"ltp":2.36,"tv":20.22,"id":891555}]}]}
{"op":"mcm","clk":"11915321486","pt":1724540768940,"mc":[{"id":"1.232220323","rc":[{"batb":[[0,2.32,32.53],[1,1.9,998.13],[2,1.85,738.46]],"ltp":2.36,"tv":20.22,"id":891555}]}]}
{"op":"mcm","clk":"11915321591","pt":1724540771255,"mc":[{"id":"1.232220323","rc":[{"batb":[[0,2.34,5],[1,2.32,32.53],[2,1.9,998.13]],"ltp":2.36,"tv":20.22,"id":891555}]}]}
{"op":"mcm","clk":"11915321738","pt":1724540774541,"mc":[{"id":"1.232220323","rc":[{"batb":[[0,2.32,32.53],[1,1.9,998.13],[2,1.85,738.46]],"ltp":2.36,"tv":20.22,"id":891555}]}]}
{"op":"mcm","clk":"11915321848","pt":1724540776960,"mc":[{"id":"1.232220323","rc":[{"batb":[[0,2.34,5],[1,2.32,32.53],[2,1.9,998.13]],"ltp":2.36,"tv":20.22,"id":891555}]}]}
{"op":"mcm","clk":"11915322003","pt":1724540780150,"mc":[{"id":"1.232220323","rc":[{"batb":[[0,2.32,32.53],[1,1.9,998.13],[2,1.85,738.46]],"ltp":2.36,"tv":20.22,"id":891555}]}]}
{"op":"mcm","clk":"11915322122","pt":1724540782975,"mc":[{"id":"1.232220323","rc":[{"batb":[[0,2.34,5],[1,2.32,32.53],[2,1.9,998.13]],"ltp":2.36,"tv":20.22,"id":891555}]}]}
{"op":"mcm","clk":"11915322268","pt":1724540786264,"mc":[{"id":"1.232220323","rc":[{"batb":[[0,2.32,32.53],[1,1.9,998.13],[2,1.85,738.46]],"ltp":2.36,"tv":20.22,"id":891555}]}]}
{"op":"mcm","clk":"11915322402","pt":1724540788788,"mc":[{"id":"1.232220323","rc":[{"batb":[[0,2.34,5],[1,2.32,32.53],[2,1.9,998.13]],"ltp":2.36,"tv":20.22,"id":891555}]}]}
{"op":"mcm","clk":"11915322555","pt":1724540792073,"mc":[{"id":"1.232220323","rc":[{"batb":[[0,2.32,32.53],[1,1.9,998.13],[2,1.85,738.46]],"ltp":2.36,"tv":20.22,"id":891555}]}]}
{"op":"mcm","clk":"11915322686","pt":1724540794961,"mc":[{"id":"1.232220323","rc":[{"batb":[[0,2.34,5],[1,2.32,32.53],[2,1.9,998.13]],"ltp":2.36,"tv":20.22,"id":891555}]}]}
{"op":"mcm","clk":"11915322863","pt":1724540798398,"mc":[{"id":"1.232220323","rc":[{"batb":[[0,2.32,32.53],[1,1.9,998.13],[2,1.85,738.46]],"ltp":2.36,"tv":20.22,"id":891555}]}]}
{"op":"mcm","clk":"11915322999","pt":1724540801378,"mc":[{"id":"1.232220323","rc":[{"batb":[[0,2.34,5],[1,2.32,32.53],[2,1.9,998.13]],"ltp":2.36,"tv":20.22,"id":891555}]}]}
{"op":"mcm","clk":"11915323159","pt":1724540804876,"mc":[{"id":"1.232220323","rc":[{"batb":[[0,2.32,32.53],[1,1.9,998.13],[2,1.85,738.46]],"ltp":2.36,"tv":20.22,"id":891555}]}]}
{"op":"mcm","clk":"11915323406","pt":1724540809614,"mc":[{"id":"1.232220323","rc":[{"batb":[[0,2.34,5],[1,2.32,32.53],[2,1.9,998.13]],"ltp":2.36,"tv":20.22,"id":891555}]}]}
{"op":"mcm","clk":"11915323551","pt":1724540813118,"mc":[{"id":"1.232220323","rc":[{"batb":[[0,2.32,32.53],[1,1.9,998.13],[2,1.85,738.46]],"ltp":2.36,"tv":20.22,"id":891555}]}]}
{"op":"mcm","clk":"11915323681","pt":1724540815283,"mc":[{"id":"1.232220323","rc":[{"batb":[[0,2.34,5],[1,2.32,32.53],[2,1.9,998.13]],"ltp":2.36,"tv":20.22,"id":891555}]}]}
{"op":"mcm","clk":"11915323893","pt":1724540818626,"mc":[{"id":"1.232220323","rc":[{"batb":[[0,2.32,32.53],[1,1.9,998.13],[2,1.85,738.46]],"ltp":2.36,"tv":20.22,"id":891555}]}]}
{"op":"mcm","clk":"11915323998","pt":1724540820858,"mc":[{"id":"1.232220323","rc":[{"batb":[[0,2.34,5],[1,2.32,32.53],[2,1.9,998.13]],"ltp":2.36,"tv":20.22,"id":891555}]}]}
{"op":"mcm","clk":"11915324239","pt":1724540824310,"mc":[{"id":"1.232220323","rc":[{"batb":[[0,2.32,32.53],[1,1.9,998.13],[2,1.85,738.46]],"ltp":2.36,"tv":20.22,"id":891555}]}]}
{"op":"mcm","clk":"11915324405","pt":1724540827686,"mc":[{"id":"1.232220323","rc":[{"batb":[[0,2.34,5],[1,2.32,32.53],[2,1.9,998.13]],"ltp":2.36,"tv":20.22,"id":891555}]}]}
{"op":"mcm","clk":"11915324599","pt":1724540831180,"mc":[{"id":"1.232220323","rc":[{"batb":[[0,2.32,32.53],[1,1.9,998.13],[2,1.85,738.46]],"ltp":2.36,"tv":20.22,"id":891555}]}]}
{"op":"mcm","clk":"11915324701","pt":1724540833695,"mc":[{"id":"1.232220323","rc":[{"batb":[[0,2.34,5],[1,2.32,32.53],[2,1.9,998.13]],"ltp":2.36,"tv":20.22,"id":891555}]}]}
{"op":"mcm","clk":"11915324883","pt":1724540836899,"mc":[{"id":"1.232220323","rc":[{"batb":[[0,2.32,32.53],[1,1.9,998.13],[2,1.85,738.46]],"ltp":2.36,"tv":20.22,"id":891555}]}]}
{"op":"mcm","clk":"11915325021","pt":1724540839214,"mc":[{"id":"1.232220323","rc":[{"batb":[[0,2.34,5],[1,2.32,32.53],[2,1.9,998.13]],"ltp":2.36,"tv":20.22,"id":891555}]}]}
{"op":"mcm","clk":"11915325182","pt":1724540842509,"mc":[{"id":"1.232220323","rc":[{"batb":[[0,2.32,32.53],[1,1.9,998.13],[2,1.85,738.46]],"ltp":2.36,"tv":20.22,"id":891555}]}]}
{"op":"mcm","clk":"11915325327","pt":1724540845022,"mc":[{"id":"1.232220323","rc":[{"batb":[[0,2.34,5],[1,2.32,32.53],[2,1.9,998.13]],"ltp":2.36,"tv":20.22,"id":891555}]}]}
{"op":"mcm","clk":"11915325485","pt":1724540848115,"mc":[{"id":"1.232220323","rc":[{"batb":[[0,2.32,32.53],[1,1.9,998.13],[2,1.85,738.46]],"ltp":2.36,"tv":20.22,"id":891555}]}]}
{"op":"mcm","clk":"11915325636","pt":1724540850851,"mc":[{"id":"1.232220323","rc":[{"batb":[[0,2.34,5],[1,2.32,32.53],[2,1.9,998.13]],"ltp":2.36,"tv":20.22,"id":891555}]}]}
{"op":"mcm","clk":"11915325828","pt":1724540854155,"mc":[{"id":"1.232220323","rc":[{"batb":[[0,2.32,32.53],[1,1.9,998.13],[2,1.85,738.46]],"ltp":2.36,"tv":20.22,"id":891555}]}]}
{"op":"mcm","clk":"11915325980","pt":1724540856530,"mc":[{"id":"1.232220323","rc":[{"batb":[[0,2.34,5],[1,2.32,32.53],[2,1.9,998.13]],"ltp":2.36,"tv":20.22,"id":891555}]}]}
{"op":"mcm","clk":"11915326159","pt":1724540859722,"mc":[{"id":"1.232220323","rc":[{"batb":[[0,2.32,32.53],[1,1.9,998.13],[2,1.85,738.46]],"ltp":2.36,"tv":20.22,"id":891555}]}]}
{"op":"mcm","clk":"11915326323","pt":1724540862653,"mc":[{"id":"1.232220323","rc":[{"batb":[[0,2.34,5],[1,2.32,32.53],[2,1.9,998.13]],"ltp":2.36,"tv":20.22,"id":891555}]}]}
{"op":"mcm","clk":"11915326461","pt":1724540865949,"mc":[{"id":"1.232220323","rc":[{"batb":[[0,2.32,32.53],[1,1.9,998.13],[2,1.85,738.46]],"ltp":2.36,"tv":20.22,"id":891555}]}]}
{"op":"mcm","clk":"11915326619","pt":1724540868450,"mc":[{"id":"1.232220323","rc":[{"batb":[[0,2.34,5],[1,2.32,32.53],[2,1.9,998.13]],"ltp":2.36,"tv":20.22,"id":891555}]}]}
{"op":"mcm","clk":"11915326771","pt":1724540871751,"mc":[{"id":"1.232220323","rc":[{"batb":[[0,2.32,32.53],[1,1.9,998.13],[2,1.85,738.46]],"ltp":2.36,"tv":20.22,"id":891555}]}]}
{"op":"mcm","clk":"11915326889","pt":1724540874258,"mc":[{"id":"1.232220323","rc":[{"batb":[[0,2.34,5],[1,2.32,32.53],[2,1.9,998.13]],"ltp":2.36,"tv":20.22,"id":891555}]}]}
{"op":"mcm","clk":"11915327096","pt":1724540877773,"mc":[{"id":"1.232220323","rc":[{"batb":[[0,2.32,32.53],[1,1.9,998.13],[2,1.85,738.46]],"ltp":2.36,"tv":20.22,"id":891555}]}]}
{"op":"mcm","clk":"11915327244","pt":1724540880247,"mc":[{"id":"1.232220323","rc":[{"batb":[[0,2.34,5],[1,2.32,32.53],[2,1.9,998.13]],"ltp":2.36,"tv":20.22,"id":891555}]}]}
{"op":"mcm","clk":"11915327410","pt":1724540883565,"mc":[{"id":"1.232220323","rc":[{"batb":[[0,2.32,32.53],[1,1.9,998.13],[2,1.85,738.46]],"ltp":2.36,"tv":20.22,"id":891555}]}]}
{"op":"mcm","clk":"11915327531","pt":1724540885774,"mc":[{"id":"1.232220323","rc":[{"batb":[[0,2.34,5],[1,2.32,32.53],[2,1.9,998.13]],"ltp":2.36,"tv":20.22,"id":891555}]}]}
{"op":"mcm","clk":"11915327692","pt":1724540889183,"mc":[{"id":"1.232220323","rc":[{"batb":[[0,2.32,32.53],[1,1.9,998.13],[2,1.85,738.46]],"ltp":2.36,"tv":20.22,"id":891555}]}]}
{"op":"mcm","clk":"11915327900","pt":1724540893360,"mc":[{"id":"1.232220323","rc":[{"batb":[[0,2.34,5],[1,2.32,32.53],[2,1.9,998.13]],"ltp":2.36,"tv":20.22,"id":891555}]}]}
{"op":"mcm","clk":"11915328058","pt":1724540896871,"mc":[{"id":"1.232220323","rc":[{"batb":[[0,2.32,32.53],[1,1.9,998.13],[2,1.85,738.46]],"ltp":2.36,"tv":20.22,"id":891555}]}]}
{"op":"mcm","clk":"11915328177","pt":1724540899089,"mc":[{"id":"1.232220323","rc":[{"batb":[[0,2.34,5],[1,2.32,32.53],[2,1.9,998.13]],"ltp":2.36,"tv":20.22,"id":891555}]}]}
{"op":"mcm","clk":"11915328337","pt":1724540902583,"mc":[{"id":"1.232220323","rc":[{"batb":[[0,2.32,32.53],[1,1.9,998.13],[2,1.85,738.46]],"ltp":2.36,"tv":20.22,"id":891555}]}]}
{"op":"mcm","clk":"11915328436","pt":1724540904802,"mc":[{"id":"1.232220323","rc":[{"batb":[[0,2.34,5],[1,2.32,32.53],[2,1.9,998.13]],"ltp":2.36,"tv":20.22,"id":891555}]}]}
{"op":"mcm","clk":"11915328614","pt":1724540908104,"mc":[{"id":"1.232220323","rc":[{"batb":[[0,2.32,32.53],[1,1.9,998.13],[2,1.85,738.46]],"ltp":2.36,"tv":20.22,"id":891555}]}]}
{"op":"mcm","clk":"11915328719","pt":1724540910583,"mc":[{"id":"1.232220323","rc":[{"batb":[[0,2.34,5],[1,2.32,32.53],[2,1.9,998.13]],"ltp":2.36,"tv":20.22,"id":891555}]}]}
{"op":"mcm","clk":"11915328881","pt":1724540913929,"mc":[{"id":"1.232220323","rc":[{"batb":[[0,2.32,32.53],[1,1.9,998.13],[2,1.85,738.46]],"ltp":2.36,"tv":20.22,"id":891555}]}]}
{"op":"mcm","clk":"11915328992","pt":1724540916103,"mc":[{"id":"1.232220323","rc":[{"batb":[[0,2.34,5],[1,2.32,32.53],[2,1.9,998.13]],"ltp":2.36,"tv":20.22,"id":891555}]}]}
{"op":"mcm","clk":"11915329124","pt":1724540919405,"mc":[{"id":"1.232220323","rc":[{"batb":[[0,2.32,32.53],[1,1.9,998.13],[2,1.85,738.46]],"ltp":2.36,"tv":20.22,"id":891555}]}]}
{"op":"mcm","clk":"11915329315","pt":1724540922909,"mc":[{"id":"1.232220323","rc":[{"batb":[[0,2.34,5],[1,2.32,32.53],[2,1.9,998.13]],"ltp":2.36,"tv":20.22,"id":891555}]}]}
{"op":"mcm","clk":"11915329496","pt":1724540926222,"mc":[{"id":"1.232220323","rc":[{"batb":[[0,2.32,32.53],[1,1.9,998.13],[2,1.85,738.46]],"ltp":2.36,"tv":20.22,"id":891555}]}]}
{"op":"mcm","clk":"11915329622","pt":1724540928636,"mc":[{"id":"1.232220323","rc":[{"batb":[[0,2.34,5],[1,2.32,32.53],[2,1.9,998.13]],"ltp":2.36,"tv":20.22,"id":891555}]}]}
{"op":"mcm","clk":"11915329759","pt":1724540931930,"mc":[{"id":"1.232220323","rc":[{"batb":[[0,2.32,32.53],[1,1.9,998.13],[2,1.85,738.46]],"ltp":2.36,"tv":20.22,"id":891555}]}]}
{"op":"mcm","clk":"11915329911","pt":1724540934956,"mc":[{"id":"1.232220323","rc":[{"batb":[[0,2.34,5],[1,2.32,32.53],[2,1.9,998.13]],"ltp":2.36,"tv":20.22,"id":891555}]}]}
{"op":"mcm","clk":"11915330122","pt":1724540938354,"mc":[{"id":"1.232220323","rc":[{"batb":[[0,2.32,32.53],[1,1.9,998.13],[2,1.85,738.46]],"ltp":2.36,"tv":20.22,"id":891555}]}]}
{"op":"mcm","clk":"11915330273","pt":1724540940522,"mc":[{"id":"1.232220323","rc":[{"batb":[[0,2.34,5],[1,2.32,32.53],[2,1.9,998.13]],"ltp":2.36,"tv":20.22,"id":891555}]}]}
{"op":"mcm","clk":"11915330580","pt":1724540945616,"mc":[{"id":"1.232220323","rc":[{"batb":[[0,2.32,32.53],[1,1.9,998.13],[2,1.85,738.46]],"ltp":2.36,"tv":20.22,"id":891555}]}]}
{"op":"mcm","clk":"11915330696","pt":1724540947835,"mc":[{"id":"1.232220323","rc":[{"batb":[[0,2.34,5],[1,2.32,32.53],[2,1.9,998.13]],"ltp":2.36,"tv":20.22,"id":891555}]}]}
{"op":"mcm","clk":"11915330925","pt":1724540951237,"mc":[{"id":"1.232220323","rc":[{"batb":[[0,2.32,32.53],[1,1.9,998.13],[2,1.85,738.46]],"ltp":2.36,"tv":20.22,"id":891555}]}]}
{"op":"mcm","clk":"11915331065","pt":1724540953557,"mc":[{"id":"1.232220323","rc":[{"batb":[[0,2.34,5],[1,2.32,32.53],[2,1.9,998.13]],"ltp":2.36,"tv":20.22,"id":891555}]}]}
{"op":"mcm","clk":"11915331197","pt":1724540956861,"mc":[{"id":"1.232220323","rc":[{"batb":[[0,2.32,32.53],[1,1.9,998.13],[2,1.85,738.46]],"ltp":2.36,"tv":20.22,"id":891555}]}]}
{"op":"mcm","clk":"11915331317","pt":1724540959172,"mc":[{"id":"1.232220323","rc":[{"batb":[[0,2.34,5],[1,2.32,32.53],[2,1.9,998.13]],"ltp":2.36,"tv":20.22,"id":891555}]}]}
{"op":"mcm","clk":"11915331486","pt":1724540962373,"mc":[{"id":"1.232220323","rc":[{"batb":[[0,2.32,32.53],[1,1.9,998.13],[2,1.85,738.46]],"ltp":2.36,"tv":20.22,"id":891555}]}]}
{"op":"mcm","clk":"11915331605","pt":1724540964941,"mc":[{"id":"1.232220323","rc":[{"batb":[[0,2.34,5],[1,2.32,32.53],[2,1.9,998.13]],"ltp":2.36,"tv":20.22,"id":891555}]}]}
{"op":"mcm","clk":"11915331796","pt":1724540968591,"mc":[{"id":"1.232220323","rc":[{"batb":[[0,2.32,32.53],[1,1.9,998.13],[2,1.85,738.46]],"ltp":2.36,"tv":20.22,"id":891555}]}]}
{"op":"mcm","clk":"11915331900","pt":1724540970751,"mc":[{"id":"1.232220323","rc":[{"batb":[[0,2.34,5],[1,2.32,32.53],[2,1.9,998.13]],"ltp":2.36,"tv":20.22,"id":891555}]}]}
{"op":"mcm","clk":"11915332089","pt":1724540974098,"mc":[{"id":"1.232220323","rc":[{"batb":[[0,2.32,32.53],[1,1.9,998.13],[2,1.85,738.46]],"ltp":2.36,"tv":20.22,"id":891555}]}]}
{"op":"mcm","clk":"11915332201","pt":1724540976569,"mc":[{"id":"1.232220323","rc":[{"batb":[[0,2.34,5],[1,2.32,32.53],[2,1.9,998.13]],"ltp":2.36,"tv":20.22,"id":891555}]}]}
{"op":"mcm","clk":"11915332377","pt":1724540979802,"mc":[{"id":"1.232220323","rc":[{"batb":[[0,2.32,32.53],[1,1.9,998.13],[2,1.85,738.46]],"ltp":2.36,"tv":20.22,"id":891555}]}]}
{"op":"mcm","clk":"11915332514","pt":1724540982379,"mc":[{"id":"1.232220323","rc":[{"batb":[[0,2.34,5],[1,2.32,32.53],[2,1.9,998.13]],"ltp":2.36,"tv":20.22,"id":891555}]}]}
{"op":"mcm","clk":"11915332681","pt":1724540985777,"mc":[{"id":"1.232220323","rc":[{"batb":[[0,2.32,32.53],[1,1.9,998.13],[2,1.85,738.46]],"ltp":2.36,"tv":20.22,"id":891555}]}]}
{"op":"mcm","clk":"11915332794","pt":1724540988088,"mc":[{"id":"1.232220323","rc":[{"batb":[[0,2.34,5],[1,2.32,32.53],[2,1.9,998.13]],"ltp":2.36,"tv":20.22,"id":891555}]}]}
{"op":"mcm","clk":"11915332945","pt":1724540991590,"mc":[{"id":"1.232220323","rc":[{"batb":[[0,2.32,32.53],[1,1.9,998.13],[2,1.85,738.46]],"ltp":2.36,"tv":20.22,"id":891555}]}]}
{"op":"mcm","clk":"11915333128","pt":1724540994621,"mc":[{"id":"1.232220323","rc":[{"batb":[[0,2.34,5],[1,2.32,32.53],[2,1.9,998.13]],"ltp":2.36,"tv":20.22,"id":891555}]}]}
{"op":"mcm","clk":"11915333290","pt":1724540998118,"mc":[{"id":"1.232220323","rc":[{"batb":[[0,2.32,32.53],[1,1.9,998.13],[2,1.85,738.46]],"ltp":2.36,"tv":20.22,"id":891555}]}]}
{"op":"mcm","clk":"11915333405","pt":1724541000634,"mc":[{"id":"1.232220323","rc":[{"batb":[[0,2.34,5],[1,2.32,32.53],[2,1.9,998.13]],"ltp":2.36,"tv":20.22,"id":891555}]}]}
{"op":"mcm","clk":"11915333605","pt":1724541004136,"mc":[{"id":"1.232220323","rc":[{"batb":[[0,2.32,32.53],[1,1.9,998.13],[2,1.85,738.46]],"ltp":2.36,"tv":20.22,"id":891555}]}]}
{"op":"mcm","clk":"11915333729","pt":1724541006609,"mc":[{"id":"1.232220323","rc":[{"batb":[[0,2.34,5],[1,2.32,32.53],[2,1.9,998.13]],"ltp":2.36,"tv":20.22,"id":891555}]}]}
{"op":"mcm","clk":"11915333858","pt":1724541009946,"mc":[{"id":"1.232220323","rc":[{"batb":[[0,2.32,32.53],[1,1.9,998.13],[2,1.85,738.46]],"ltp":2.36,"tv":20.22,"id":891555}]}]}
{"op":"mcm","clk":"11915334022","pt":1724541013541,"mc":[{"id":"1.232220323","rc":[{"batb":[[0,2.34,5],[1,2.32,32.53],[2,1.9,998.13]],"ltp":2.36,"tv":20.22,"id":891555}]}]}
{"op":"mcm","clk":"11915334204","pt":1724541016840,"mc":[{"id":"1.232220323","rc":[{"batb":[[0,2.32,32.53],[1,1.9,998.13],[2,1.85,738.46]],"ltp":2.36,"tv":20.22,"id":891555}]}]}
{"op":"mcm","clk":"11915334310","pt":1724541019111,"mc":[{"id":"1.232220323","rc":[{"batb":[[0,2.34,5],[1,2.32,32.53],[2,1.9,998.13]],"ltp":2.36,"tv":20.22,"id":891555}]}]}
{"op":"mcm","clk":"11915334488","pt":1724541022657,"mc":[{"id":"1.232220323","rc":[{"batb":[[0,2.32,32.53],[1,1.9,998.13],[2,1.85,738.46]],"ltp":2.36,"tv":20.22,"id":891555}]}]}
{"op":"mcm","clk":"11915334631","pt":1724541025234,"mc":[{"id":"1.232220323","rc":[{"batb":[[0,2.34,5],[1,2.32,32.53],[2,1.9,998.13]],"ltp":2.36,"tv":20.22,"id":891555}]}]}
{"op":"mcm","clk":"11915334780","pt":1724541028654,"mc":[{"id":"1.232220323","rc":[{"batb":[[0,2.32,32.53],[1,1.9,998.13],[2,1.85,738.46]],"ltp":2.36,"tv":20.22,"id":891555}]}]}
{"op":"mcm","clk":"11915334911","pt":1724541030927,"mc":[{"id":"1.232220323","rc":[{"batb":[[0,2.34,5],[1,2.32,32.53],[2,1.9,998.13]],"ltp":2.36,"tv":20.22,"id":891555}]}]}
{"op":"mcm","clk":"11915335061","pt":1724541034231,"mc":[{"id":"1.232220323","rc":[{"batb":[[0,2.32,32.53],[1,1.9,998.13],[2,1.85,738.46]],"ltp":2.36,"tv":20.22,"id":891555}]}]}
{"op":"mcm","clk":"11915335161","pt":1724541036651,"mc":[{"id":"1.232220323","rc":[{"batb":[[0,2.34,5],[1,2.32,32.53],[2,1.9,998.13]],"ltp":2.36,"tv":20.22,"id":891555}]}]}
{"op":"mcm","clk":"11915335310","pt":1724541040252,"mc":[{"id":"1.232220323","rc":[{"batb":[[0,2.32,32.53],[1,1.9,998.13],[2,1.85,738.46]],"ltp":2.36,"tv":20.22,"id":891555}]}]}
{"op":"mcm","clk":"11915335450","pt":1724541042974,"mc":[{"id":"1.232220323","rc":[{"batb":[[0,2.34,5],[1,2.32,32.53],[2,1.9,998.13]],"ltp":2.36,"tv":20.22,"id":891555}]}]}
{"op":"mcm","clk":"11915335601","pt":1724541046367,"mc":[{"id":"1.232220323","rc":[{"batb":[[0,2.32,32.53],[1,1.9,998.13],[2,1.85,738.46]],"ltp":2.36,"tv":20.22,"id":891555}]}]}
{"op":"mcm","clk":"11915335732","pt":1724541049453,"mc":[{"id":"1.232220323","rc":[{"batb":[[0,2.34,5],[1,2.32,32.53],[2,1.9,998.13]],"ltp":2.36,"tv":20.22,"id":891555}]}]}
{"op":"mcm","clk":"11915335866","pt":1724541052860,"mc":[{"id":"1.232220323","rc":[{"batb":[[0,2.32,32.53],[1,1.9,998.13],[2,1.85,738.46]],"ltp":2.36,"tv":20.22,"id":891555}]}]}
{"op":"mcm","clk":"11915335989","pt":1724541055381,"mc":[{"id":"1.232220323","rc":[{"batb":[[0,2.34,5],[1,2.32,32.53],[2,1.9,998.13]],"ltp":2.36,"tv":20.22,"id":891555}]}]}
{"op":"mcm","clk":"11915336167","pt":1724541058782,"mc":[{"id":"1.232220323","rc":[{"batb":[[0,2.32,32.53],[1,1.9,998.13],[2,1.85,738.46]],"ltp":2.36,"tv":20.22,"id":891555}]}]}
{"op":"mcm","clk":"11915336298","pt":1724541061304,"mc":[{"id":"1.232220323","rc":[{"batb":[[0,2.34,5],[1,2.32,32.53],[2,1.9,998.13]],"ltp":2.36,"tv":20.22,"id":891555}]}]}
{"op":"mcm","clk":"11915336517","pt":1724541064765,"mc":[{"id":"1.232220323","rc":[{"batb":[[0,2.32,32.53],[1,1.9,998.13],[2,1.85,738.46]],"ltp":2.36,"tv":20.22,"id":891555}]}]}
{"op":"mcm","clk":"11915336656","pt":1724541067902,"mc":[{"id":"1.232220323","rc":[{"batb":[[0,2.34,5],[1,2.32,32.53],[2,1.9,998.13]],"ltp":2.36,"tv":20.22,"id":891555}]}]}
{"op":"mcm","clk":"11915336873","pt":1724541071206,"mc":[{"id":"1.232220323","rc":[{"batb":[[0,2.32,32.53],[1,1.9,998.13],[2,1.85,738.46]],"ltp":2.36,"tv":20.22,"id":891555}]}]}
{"op":"mcm","clk":"11915336977","pt":1724541073584,"mc":[{"id":"1.232220323","rc":[{"batb":[[0,2.34,5],[1,2.32,32.53],[2,1.9,998.13]],"ltp":2.36,"tv":20.22,"id":891555}]}]}
{"op":"mcm","clk":"11915337198","pt":1724541076782,"mc":[{"id":"1.232220323","rc":[{"batb":[[0,2.32,32.53],[1,1.9,998.13],[2,1.85,738.46]],"ltp":2.36,"tv":20.22,"id":891555}]}]}
{"op":"mcm","clk":"11915337386","pt":1724541080278,"mc":[{"id":"1.232220323","rc":[{"batb":[[0,2.34,5],[1,2.32,32.53],[2,1.9,998.13]],"ltp":2.36,"tv":20.22,"id":891555}]}]}
{"op":"mcm","clk":"11915337590","pt":1724541083733,"mc":[{"id":"1.232220323","rc":[{"batb":[[0,2.32,32.53],[1,1.9,998.13],[2,1.85,738.46]],"ltp":2.36,"tv":20.22,"id":891555}]}]}
{"op":"mcm","clk":"11915337755","pt":1724541086722,"mc":[{"id":"1.232220323","rc":[{"batb":[[0,2.34,5],[1,2.32,32.53],[2,1.9,998.13]],"ltp":2.36,"tv":20.22,"id":891555}]}]}
{"op":"mcm","clk":"11915337934","pt":1724541090123,"mc":[{"id":"1.232220323","rc":[{"batb":[[0,2.32,32.53],[1,1.9,998.13],[2,1.85,738.46]],"ltp":2.36,"tv":20.22,"id":891555}]}]}
{"op":"mcm","clk":"11915338090","pt":1724541092504,"mc":[{"id":"1.232220323","rc":[{"batb":[[0,2.34,5],[1,2.32,32.53],[2,1.9,998.13]],"ltp":2.36,"tv":20.22,"id":891555}]}]}
{"op":"mcm","clk":"11915338304","pt":1724541095906,"mc":[{"id":"1.232220323","rc":[{"batb":[[0,2.32,32.53],[1,1.9,998.13],[2,1.85,738.46]],"ltp":2.36,"tv":20.22,"id":891555}]}]}
{"op":"mcm","clk":"11915338452","pt":1724541098322,"mc":[{"id":"1.232220323","rc":[{"batb":[[0,2.34,5],[1,2.32,32.53],[2,1.9,998.13]],"ltp":2.36,"tv":20.22,"id":891555}]}]}
{"op":"mcm","clk":"11915338669","pt":1724541101661,"mc":[{"id":"1.232220323","rc":[{"batb":[[0,2.32,32.53],[1,1.9,998.13],[2,1.85,738.46]],"ltp":2.36,"tv":20.22,"id":891555}]}]}
{"op":"mcm","clk":"11915338815","pt":1724541103925,"mc":[{"id":"1.232220323","rc":[{"batb":[[0,2.34,5],[1,2.32,32.53],[2,1.9,998.13]],"ltp":2.36,"tv":20.22,"id":891555}]}]}
{"op":"mcm","clk":"11915339002","pt":1724541107341,"mc":[{"id":"1.232220323","rc":[{"batb":[[0,2.32,32.53],[1,1.9,998.13],[2,1.85,738.46]],"ltp":2.36,"tv":20.22,"id":891555}]}]}
{"op":"mcm","clk":"11915339157","pt":1724541109863,"mc":[{"id":"1.232220323","rc":[{"batb":[[0,2.34,5],[1,2.32,32.53],[2,1.9,998.13]],"ltp":2.36,"tv":20.22,"id":891555}]}]}
{"op":"mcm","clk":"11915339371","pt":1724541113364,"mc":[{"id":"1.232220323","rc":[{"batb":[[0,2.32,32.53],[1,1.9,998.13],[2,1.85,738.46]],"ltp":2.36,"tv":20.22,"id":891555}]}]}
{"op":"mcm","clk":"11915339496","pt":1724541115639,"mc":[{"id":"1.232220323","rc":[{"batb":[[0,2.34,5],[1,2.32,32.53],[2,1.9,998.13]],"ltp":2.36,"tv":20.22,"id":891555}]}]}
{"op":"mcm","clk":"11915339692","pt":1724541119044,"mc":[{"id":"1.232220323","rc":[{"batb":[[0,2.32,32.53],[1,1.9,998.13],[2,1.85,738.46]],"ltp":2.36,"tv":20.22,"id":891555}]}]}
{"op":"mcm","clk":"11915339829","pt":1724541121470,"mc":[{"id":"1.232220323","rc":[{"batb":[[0,2.34,5],[1,2.32,32.53],[2,1.9,998.13]],"ltp":2.36,"tv":20.22,"id":891555}]}]}
{"op":"mcm","clk":"11915340022","pt":1724541124782,"mc":[{"id":"1.232220323","rc":[{"batb":[[0,2.32,32.53],[1,1.9,998.13],[2,1.85,738.46]],"ltp":2.36,"tv":20.22,"id":891555}]}]}
{"op":"mcm","clk":"11915340134","pt":1724541127055,"mc":[{"id":"1.232220323","rc":[{"batb":[[0,2.34,5],[1,2.32,32.53],[2,1.9,998.13]],"ltp":2.36,"tv":20.22,"id":891555}]}]}
{"op":"mcm","clk":"11915340428","pt":1724541133358,"mc":[{"id":"1.232220323","rc":[{"batb":[[0,2.32,32.53],[1,1.9,998.13],[2,1.85,738.46]],"ltp":2.36,"tv":20.22,"id":891555}]}]}
{"op":"mcm","clk":"11915340561","pt":1724541136054,"mc":[{"id":"1.232220323","rc":[{"batb":[[0,2.34,5],[1,2.32,32.53],[2,1.9,998.13]],"ltp":2.36,"tv":20.22,"id":891555}]}]}
{"op":"mcm","clk":"11915340725","pt":1724541139462,"mc":[{"id":"1.232220323","rc":[{"batb":[[0,2.32,32.53],[1,1.9,998.13],[2,1.85,738.46]],"ltp":2.36,"tv":20.22,"id":891555}]}]}
{"op":"mcm","clk":"11915340833","pt":1724541141775,"mc":[{"id":"1.232220323","rc":[{"batb":[[0,2.34,5],[1,2.32,32.53],[2,1.9,998.13]],"ltp":2.36,"tv":20.22,"id":891555}]}]}
{"op":"mcm","clk":"11915340975","pt":1724541145175,"mc":[{"id":"1.232220323","rc":[{"batb":[[0,2.32,32.53],[1,1.9,998.13],[2,1.85,738.46]],"ltp":2.36,"tv":20.22,"id":891555}]}]}
{"op":"mcm","clk":"11915341103","pt":1724541147807,"mc":[{"id":"1.232220323","rc":[{"batb":[[0,2.34,5],[1,2.32,32.53],[2,1.9,998.13]],"ltp":2.36,"tv":20.22,"id":891555}]}]}
{"op":"mcm","clk":"11915341358","pt":1724541151307,"mc":[{"id":"1.232220323","rc":[{"batb":[[0,2.32,32.53],[1,1.9,998.13],[2,1.85,738.46]],"ltp":2.36,"tv":20.22,"id":891555}]}]}
{"op":"mcm","clk":"11915341558","pt":1724541154611,"mc":[{"id":"1.232220323","rc":[{"batb":[[0,2.34,5],[1,2.32,32.53],[2,1.9,998.13]],"ltp":2.36,"tv":20.22,"id":891555}]}]}
{"op":"mcm","clk":"11915341698","pt":1724541157981,"mc":[{"id":"1.232220323","rc":[{"batb":[[0,2.32,32.53],[1,1.9,998.13],[2,1.85,738.46]],"ltp":2.36,"tv":20.22,"id":891555}]}]}
{"op":"mcm","clk":"11915341796","pt":1724541160497,"mc":[{"id":"1.232220323","rc":[{"batb":[[0,2.34,5],[1,2.32,32.53],[2,1.9,998.13]],"ltp":2.36,"tv":20.22,"id":891555}]}]}
{"op":"mcm","clk":"11915341925","pt":1724541164101,"mc":[{"id":"1.232220323","rc":[{"batb":[[0,2.32,32.53],[1,1.9,998.13],[2,1.85,738.46]],"ltp":2.36,"tv":20.22,"id":891555}]}]}
{"op":"mcm","clk":"11915341997","pt":1724541166614,"mc":[{"id":"1.232220323","rc":[{"batb":[[0,2.34,5],[1,2.32,32.53],[2,1.9,998.13]],"ltp":2.36,"tv":20.22,"id":891555}]}]}
{"op":"mcm","clk":"11915342133","pt":1724541169826,"mc":[{"id":"1.232220323","rc":[{"batb":[[0,2.32,32.53],[1,1.9,998.13],[2,1.85,738.46]],"ltp":2.36,"tv":20.22,"id":891555}]}]}
{"op":"mcm","clk":"11915342266","pt":1724541173325,"mc":[{"id":"1.232220323","rc":[{"batb":[[0,2.34,5],[1,2.32,32.53],[2,1.9,998.13]],"ltp":2.36,"tv":20.22,"id":891555}]}]}
{"op":"mcm","clk":"11915342420","pt":1724541176515,"mc":[{"id":"1.232220323","rc":[{"batb":[[0,2.32,32.53],[1,1.9,998.13],[2,1.85,738.46]],"ltp":2.36,"tv":20.22,"id":891555}]}]}
{"op":"mcm","clk":"11915342560","pt":1724541179038,"mc":[{"id":"1.232220323","rc":[{"batb":[[0,2.34,5],[1,2.32,32.53],[2,1.9,998.13]],"ltp":2.36,"tv":20.22,"id":891555}]}]}
{"op":"mcm","clk":"11915342720","pt":1724541182438,"mc":[{"id":"1.232220323","rc":[{"batb":[[0,2.32,32.53],[1,1.9,998.13],[2,1.85,738.46]],"ltp":2.36,"tv":20.22,"id":891555}]}]}
{"op":"mcm","clk":"11915342823","pt":1724541184806,"mc":[{"id":"1.232220323","rc":[{"batb":[[0,2.34,5],[1,2.32,32.53],[2,1.9,998.13]],"ltp":2.36,"tv":20.22,"id":891555}]}]}
{"op":"mcm","clk":"11915342992","pt":1724541188005,"mc":[{"id":"1.232220323","rc":[{"batb":[[0,2.32,32.53],[1,1.9,998.13],[2,1.85,738.46]],"ltp":2.36,"tv":20.22,"id":891555}]}]}
{"op":"mcm","clk":"11915343108","pt":1724541190528,"mc":[{"id":"1.232220323","rc":[{"batb":[[0,2.34,5],[1,2.32,32.53],[2,1.9,998.13]],"ltp":2.36,"tv":20.22,"id":891555}]}]}
{"op":"mcm","clk":"11915343272","pt":1724541193927,"mc":[{"id":"1.232220323","rc":[{"batb":[[0,2.32,32.53],[1,1.9,998.13],[2,1.85,738.46]],"ltp":2.36,"tv":20.22,"id":891555}]}]}
{"op":"mcm","clk":"11915343388","pt":1724541196343,"mc":[{"id":"1.232220323","rc":[{"batb":[[0,2.34,5],[1,2.32,32.53],[2,1.9,998.13]],"ltp":2.36,"tv":20.22,"id":891555}]}]}
{"op":"mcm","clk":"11915343556","pt":1724541199743,"mc":[{"id":"1.232220323","rc":[{"batb":[[0,2.32,32.53],[1,1.9,998.13],[2,1.85,738.46]],"ltp":2.36,"tv":20.22,"id":891555}]}]}
{"op":"mcm","clk":"11915343709","pt":1724541202124,"mc":[{"id":"1.232220323","rc":[{"batb":[[0,2.34,5],[1,2.32,32.53],[2,1.9,998.13]],"ltp":2.36,"tv":20.22,"id":891555}]}]}
{"op":"mcm","clk":"11915343901","pt":1724541205528,"mc":[{"id":"1.232220323","rc":[{"batb":[[0,2.32,32.53],[1,1.9,998.13],[2,1.85,738.46]],"ltp":2.36,"tv":20.22,"id":891555}]}]}
{"op":"mcm","clk":"11915344030","pt":1724541208163,"mc":[{"id":"1.232220323","rc":[{"batb":[[0,2.34,5],[1,2.32,32.53],[2,1.9,998.13]],"ltp":2.36,"tv":20.22,"id":891555}]}]}
{"op":"mcm","clk":"11915344167","pt":1724541211366,"mc":[{"id":"1.232220323","rc":[{"batb":[[0,2.32,32.53],[1,1.9,998.13],[2,1.85,738.46]],"ltp":2.36,"tv":20.22,"id":891555}]}]}
{"op":"mcm","clk":"11915344299","pt":1724541213946,"mc":[{"id":"1.232220323","rc":[{"batb":[[0,2.34,5],[1,2.32,32.53],[2,1.9,998.13]],"ltp":2.36,"tv":20.22,"id":891555}]}]}
{"op":"mcm","clk":"11915344447","pt":1724541217172,"mc":[{"id":"1.232220323","rc":[{"batb":[[0,2.32,32.53],[1,1.9,998.13],[2,1.85,738.46]],"ltp":2.36,"tv":20.22,"id":891555}]}]}
{"op":"mcm","clk":"11915344561","pt":1724541219544,"mc":[{"id":"1.232220323","rc":[{"batb":[[0,2.34,5],[1,2.32,32.53],[2,1.9,998.13]],"ltp":2.36,"tv":20.22,"id":891555}]}]}
{"op":"mcm","clk":"11915344726","pt":1724541222843,"mc":[{"id":"1.232220323","rc":[{"batb":[[0,2.32,32.53],[1,1.9,998.13],[2,1.85,738.46]],"ltp":2.36,"tv":20.22,"id":891555}]}]}
{"op":"mcm","clk":"11915344838","pt":1724541225262,"mc":[{"id":"1.232220323","rc":[{"batb":[[0,2.34,5],[1,2.32,32.53],[2,1.9,998.13]],"ltp":2.36,"tv":20.22,"id":891555}]}]}
{"op":"mcm","clk":"11915345033","pt":1724541228660,"mc":[{"id":"1.232220323","rc":[{"batb":[[0,2.32,32.53],[1,1.9,998.13],[2,1.85,738.46]],"ltp":2.36,"tv":20.22,"id":891555}]}]}
{"op":"mcm","clk":"11915345153","pt":1724541231085,"mc":[{"id":"1.232220323","rc":[{"batb":[[0,2.34,5],[1,2.32,32.53],[2,1.9,998.13]],"ltp":2.36,"tv":20.22,"id":891555}]}]}
{"op":"mcm","clk":"11915345295","pt":1724541234481,"mc":[{"id":"1.232220323","rc":[{"batb":[[0,2.32,32.53],[1,1.9,998.13],[2,1.85,738.46]],"ltp":2.36,"tv":20.22,"id":891555}]}]}
{"op":"mcm","clk":"11915345455","pt":1724541237877,"mc":[{"id":"1.232220323","rc":[{"batb":[[0,2.34,5],[1,2.32,32.53],[2,1.9,998.13]],"ltp":2.36,"tv":20.22,"id":891555}]}]}
{"op":"mcm","clk":"11915345623","pt":1724541241182,"mc":[{"id":"1.232220323","rc":[{"batb":[[0,2.32,32.53],[1,1.9,998.13],[2,1.85,738.46]],"ltp":2.36,"tv":20.22,"id":891555}]}]}
{"op":"mcm","clk":"11915345736","pt":1724541243605,"mc":[{"id":"1.232220323","rc":[{"batb":[[0,2.34,5],[1,2.32,32.53],[2,1.9,998.13]],"ltp":2.36,"tv":20.22,"id":891555}]}]}
{"op":"mcm","clk":"11915345891","pt":1724541246901,"mc":[{"id":"1.232220323","rc":[{"batb":[[0,2.32,32.53],[1,1.9,998.13],[2,1.85,738.46]],"ltp":2.36,"tv":20.22,"id":891555}]}]}
{"op":"mcm","clk":"11915345992","pt":1724541249385,"mc":[{"id":"1.232220323","rc":[{"batb":[[0,2.34,5],[1,2.32,32.53],[2,1.9,998.13]],"ltp":2.36,"tv":20.22,"id":891555}]}]}
{"op":"mcm","clk":"11915346147","pt":1724541252988,"mc":[{"id":"1.232220323","rc":[{"batb":[[0,2.32,32.53],[1,1.9,998.13],[2,1.85,738.46]],"ltp":2.36,"tv":20.22,"id":891555}]}]}
{"op":"mcm","clk":"11915346254","pt":1724541255407,"mc":[{"id":"1.232220323","rc":[{"batb":[[0,2.34,5],[1,2.32,32.53],[2,1.9,998.13]],"ltp":2.36,"tv":20.22,"id":891555}]}]}
{"op":"mcm","clk":"11915346416","pt":1724541258785,"mc":[{"id":"1.232220323","rc":[{"batb":[[0,2.32,32.53],[1,1.9,998.13],[2,1.85,738.46]],"ltp":2.36,"tv":20.22,"id":891555}]}]}
{"op":"mcm","clk":"11915346538","pt":1724541261099,"mc":[{"id":"1.232220323","rc":[{"batb":[[0,2.34,5],[1,2.32,32.53],[2,1.9,998.13]],"ltp":2.36,"tv":20.22,"id":891555}]}]}
{"op":"mcm","clk":"11915346682","pt":1724541264496,"mc":[{"id":"1.232220323","rc":[{"batb":[[0,2.32,32.53],[1,1.9,998.13],[2,1.85,738.46]],"ltp":2.36,"tv":20.22,"id":891555}]}]}
{"op":"mcm","clk":"11915346786","pt":1724541267082,"mc":[{"id":"1.232220323","rc":[{"batb":[[0,2.34,5],[1,2.32,32.53],[2,1.9,998.13]],"ltp":2.36,"tv":20.22,"id":891555}]}]}
{"op":"mcm","clk":"11915346953","pt":1724541270489,"mc":[{"id":"1.232220323","rc":[{"batb":[[0,2.32,32.53],[1,1.9,998.13],[2,1.85,738.46]],"ltp":2.36,"tv":20.22,"id":891555}]}]}
{"op":"mcm","clk":"11915347059","pt":1724541272911,"mc":[{"id":"1.232220323","rc":[{"batb":[[0,2.34,5],[1,2.32,32.53],[2,1.9,998.13]],"ltp":2.36,"tv":20.22,"id":891555}]}]}
{"op":"mcm","clk":"11915347224","pt":1724541276212,"mc":[{"id":"1.232220323","rc":[{"batb":[[0,2.32,32.53],[1,1.9,998.13],[2,1.85,738.46]],"ltp":2.36,"tv":20.22,"id":891555}]}]}
{"op":"mcm","clk":"11915347315","pt":1724541278416,"mc":[{"id":"1.232220323","rc":[{"batb":[[0,2.34,5],[1,2.32,32.53],[2,1.9,998.13]],"ltp":2.36,"tv":20.22,"id":891555}]}]}
{"op":"mcm","clk":"11915347474","pt":1724541281813,"mc":[{"id":"1.232220323","rc":[{"batb":[[0,2.32,32.53],[1,1.9,998.13],[2,1.85,738.46]],"ltp":2.36,"tv":20.22,"id":891555}]}]}
{"op":"mcm","clk":"11915347604","pt":1724541284389,"mc":[{"id":"1.232220323","rc":[{"batb":[[0,2.34,5],[1,2.32,32.53],[2,1.9,998.13]],"ltp":2.36,"tv":20.22,"id":891555}]}]}
{"op":"mcm","clk":"11915347749","pt":1724541287701,"mc":[{"id":"1.232220323","rc":[{"batb":[[0,2.32,32.53],[1,1.9,998.13],[2,1.85,738.46]],"ltp":2.36,"tv":20.22,"id":891555}]}]}
{"op":"mcm","clk":"11915347875","pt":1724541290719,"mc":[{"id":"1.232220323","rc":[{"batb":[[0,2.34,5],[1,2.32,32.53],[2,1.9,998.13]],"ltp":2.36,"tv":20.22,"id":891555}]}]}
{"op":"mcm","clk":"11915348022","pt":1724541294018,"mc":[{"id":"1.232220323","rc":[{"batb":[[0,2.32,32.53],[1,1.9,998.13],[2,1.85,738.46]],"ltp":2.36,"tv":20.22,"id":891555}]}]}
{"op":"mcm","clk":"11915348183","pt":1724541297119,"mc":[{"id":"1.232220323","rc":[{"batb":[[0,2.34,5],[1,2.32,32.53],[2,1.9,998.13]],"ltp":2.36,"tv":20.22,"id":891555}]}]}
{"op":"mcm","clk":"11915348325","pt":1724541300312,"mc":[{"id":"1.232220323","rc":[{"batb":[[0,2.32,32.53],[1,1.9,998.13],[2,1.85,738.46]],"ltp":2.36,"tv":20.22,"id":891555}]}]}
{"op":"mcm","clk":"11915348460","pt":1724541302947,"mc":[{"id":"1.232220323","rc":[{"batb":[[0,2.34,5],[1,2.32,32.53],[2,1.9,998.13]],"ltp":2.36,"tv":20.22,"id":891555}]}]}
{"op":"mcm","clk":"11915348616","pt":1724541306214,"mc":[{"id":"1.232220323","rc":[{"batb":[[0,2.32,32.53],[1,1.9,998.13],[2,1.85,738.46]],"ltp":2.36,"tv":20.22,"id":891555}]}]}
{"op":"mcm","clk":"11915348756","pt":1724541308657,"mc":[{"id":"1.232220323","rc":[{"batb":[[0,2.34,5],[1,2.32,32.53],[2,1.9,998.13]],"ltp":2.36,"tv":20.22,"id":891555}]}]}
{"op":"mcm","clk":"11915348951","pt":1724541311955,"mc":[{"id":"1.232220323","rc":[{"batb":[[0,2.32,32.53],[1,1.9,998.13],[2,1.85,738.46]],"ltp":2.36,"tv":20.22,"id":891555}]}]}
{"op":"mcm","clk":"11915349107","pt":1724541314450,"mc":[{"id":"1.232220323","rc":[{"batb":[[0,2.34,5],[1,2.32,32.53],[2,1.9,998.13]],"ltp":2.36,"tv":20.22,"id":891555}]}]}
{"op":"mcm","clk":"11915349312","pt":1724541317839,"mc":[{"id":"1.232220323","rc":[{"batb":[[0,2.32,32.53],[1,1.9,998.13],[2,1.85,738.46]],"ltp":2.36,"tv":20.22,"id":891555}]}]}
{"op":"mcm","clk":"11915349449","pt":1724541320676,"mc":[{"id":"1.232220323","rc":[{"batb":[[0,2.34,5],[1,2.32,32.53],[2,1.9,998.13]],"ltp":2.36,"tv":20.22,"id":891555}]}]}
{"op":"mcm","clk":"11915349589","pt":1724541323872,"mc":[{"id":"1.232220323","rc":[{"batb":[[0,2.32,32.53],[1,1.9,998.13],[2,1.85,738.46]],"ltp":2.36,"tv":20.22,"id":891555}]}]}
{"op":"mcm","clk":"11915349695","pt":1724541326266,"mc":[{"id":"1.232220323","rc":[{"batb":[[0,2.34,5],[1,2.32,32.53],[2,1.9,998.13]],"ltp":2.36,"tv":20.22,"id":891555}]}]}
{"op":"mcm","clk":"11915349857","pt":1724541329562,"mc":[{"id":"1.232220323","rc":[{"batb":[[0,2.32,32.53],[1,1.9,998.13],[2,1.85,738.46]],"ltp":2.36,"tv":20.22,"id":891555}]}]}
{"op":"mcm","clk":"11915349967","pt":1724541332183,"mc":[{"id":"1.232220323","rc":[{"batb":[[0,2.34,5],[1,2.32,32.53],[2,1.9,998.13]],"ltp":2.36,"tv":20.22,"id":891555}]}]}
{"op":"mcm","clk":"11915350121","pt":1724541335377,"mc":[{"id":"1.232220323","rc":[{"batb":[[0,2.32,32.53],[1,1.9,998.13],[2,1.85,738.46]],"ltp":2.36,"tv":20.22,"id":891555}]}]}
{"op":"mcm","clk":"11915350264","pt":1724541337955,"mc":[{"id":"1.232220323","rc":[{"batb":[[0,2.34,5],[1,2.32,32.53],[2,1.9,998.13]],"ltp":2.36,"tv":20.22,"id":891555}]}]}
{"op":"mcm","clk":"11915350383","pt":1724541341397,"mc":[{"id":"1.232220323","rc":[{"batb":[[0,2.32,32.53],[1,1.9,998.13],[2,1.85,738.46]],"ltp":2.36,"tv":20.22,"id":891555}]}]}
{"op":"mcm","clk":"11915350560","pt":1724541344485,"mc":[{"id":"1.232220323","rc":[{"batb":[[0,2.34,5],[1,2.32,32.53],[2,1.9,998.13]],"ltp":2.36,"tv":20.22,"id":891555}]}]}
{"op":"mcm","clk":"11915350766","pt":1724541348006,"mc":[{"id":"1.232220323","rc":[{"batb":[[0,2.32,32.53],[1,1.9,998.13],[2,1.85,738.46]],"ltp":2.36,"tv":20.22,"id":891555}]}]}
{"op":"mcm","clk":"11915350897","pt":1724541350276,"mc":[{"id":"1.232220323","rc":[{"batb":[[0,2.34,5],[1,2.32,32.53],[2,1.9,998.13]],"ltp":2.36,"tv":20.22,"id":891555}]}]}
{"op":"mcm","clk":"11915351095","pt":1724541353586,"mc":[{"id":"1.232220323","rc":[{"batb":[[0,2.32,32.53],[1,1.9,998.13],[2,1.85,738.46]],"ltp":2.36,"tv":20.22,"id":891555}]}]}
{"op":"mcm","clk":"11915351219","pt":1724541356111,"mc":[{"id":"1.232220323","rc":[{"batb":[[0,2.34,5],[1,2.32,32.53],[2,1.9,998.13]],"ltp":2.36,"tv":20.22,"id":891555}]}]}
{"op":"mcm","clk":"11915351395","pt":1724541359523,"mc":[{"id":"1.232220323","rc":[{"batb":[[0,2.32,32.53],[1,1.9,998.13],[2,1.85,738.46]],"ltp":2.36,"tv":20.22,"id":891555}]}]}
{"op":"mcm","clk":"11915351507","pt":1724541361902,"mc":[{"id":"1.232220323","rc":[{"batb":[[0,2.34,5],[1,2.32,32.53],[2,1.9,998.13]],"ltp":2.36,"tv":20.22,"id":891555}]}]}
{"op":"mcm","clk":"11915351755","pt":1724541365417,"mc":[{"id":"1.232220323","rc":[{"batb":[[0,2.32,32.53],[1,1.9,998.13],[2,1.85,738.46]],"ltp":2.36,"tv":20.22,"id":891555}]}]}
{"op":"mcm","clk":"11915351879","pt":1724541367584,"mc":[{"id":"1.232220323","rc":[{"batb":[[0,2.34,5],[1,2.32,32.53],[2,1.9,998.13]],"ltp":2.36,"tv":20.22,"id":891555}]}]}
{"op":"mcm","clk":"11915352033","pt":1724541370929,"mc":[{"id":"1.232220323","rc":[{"batb":[[0,2.32,32.53],[1,1.9,998.13],[2,1.85,738.46]],"ltp":2.36,"tv":20.22,"id":891555}]}]}
{"op":"mcm","clk":"11915352153","pt":1724541373499,"mc":[{"id":"1.232220323","rc":[{"batb":[[0,2.34,5],[1,2.32,32.53],[2,1.9,998.13]],"ltp":2.36,"tv":20.22,"id":891555}]}]}
{"op":"mcm","clk":"11915352356","pt":1724541376907,"mc":[{"id":"1.232220323","rc":[{"batb":[[0,2.32,32.53],[1,1.9,998.13],[2,1.85,738.46]],"ltp":2.36,"tv":20.22,"id":891555}]}]}
{"op":"mcm","clk":"11915352527","pt":1724541380118,"mc":[{"id":"1.232220323","rc":[{"batb":[[0,2.34,5],[1,2.32,32.53],[2,1.9,998.13]],"ltp":2.36,"tv":20.22,"id":891555}]}]}
{"op":"mcm","clk":"11915352676","pt":1724541383526,"mc":[{"id":"1.232220323","rc":[{"batb":[[0,2.32,32.53],[1,1.9,998.13],[2,1.85,738.46]],"ltp":2.36,"tv":20.22,"id":891555}]}]}
{"op":"mcm","clk":"11915352789","pt":1724541385737,"mc":[{"id":"1.232220323","rc":[{"batb":[[0,2.34,5],[1,2.32,32.53],[2,1.9,998.13]],"ltp":2.36,"tv":20.22,"id":891555}]}]}
{"op":"mcm","clk":"11915352942","pt":1724541389248,"mc":[{"id":"1.232220323","rc":[{"batb":[[0,2.32,32.53],[1,1.9,998.13],[2,1.85,738.46]],"ltp":2.36,"tv":20.22,"id":891555}]}]}
{"op":"mcm","clk":"11915353058","pt":1724541391412,"mc":[{"id":"1.232220323","rc":[{"batb":[[0,2.34,5],[1,2.32,32.53],[2,1.9,998.13]],"ltp":2.36,"tv":20.22,"id":891555}]}]}
{"op":"mcm","clk":"11915353183","pt":1724541394752,"mc":[{"id":"1.232220323","rc":[{"batb":[[0,2.32,32.53],[1,1.9,998.13],[2,1.85,738.46]],"ltp":2.36,"tv":20.22,"id":891555}]}]}
{"op":"mcm","clk":"11915353301","pt":1724541397129,"mc":[{"id":"1.232220323","rc":[{"batb":[[0,2.34,5],[1,2.32,32.53],[2,1.9,998.13]],"ltp":2.36,"tv":20.22,"id":891555}]}]}
{"op":"mcm","clk":"11915353464","pt":1724541400475,"mc":[{"id":"1.232220323","rc":[{"batb":[[0,2.32,32.53],[1,1.9,998.13],[2,1.85,738.46]],"ltp":2.36,"tv":20.22,"id":891555}]}]}
{"op":"mcm","clk":"11915353576","pt":1724541403049,"mc":[{"id":"1.232220323","rc":[{"batb":[[0,2.34,5],[1,2.32,32.53],[2,1.9,998.13]],"ltp":2.36,"tv":20.22,"id":891555}]}]}
{"op":"mcm","clk":"11915353720","pt":1724541406542,"mc":[{"id":"1.232220323","rc":[{"batb":[[0,2.32,32.53],[1,1.9,998.13],[2,1.85,738.46]],"ltp":2.36,"tv":20.22,"id":891555}]}]}
{"op":"mcm","clk":"11915353836","pt":1724541408750,"mc":[{"id":"1.232220323","rc":[{"batb":[[0,2.34,5],[1,2.32,32.53],[2,1.9,998.13]],"ltp":2.36,"tv":20.22,"id":891555}]}]}
{"op":"mcm","clk":"11915353984","pt":1724541412255,"mc":[{"id":"1.232220323","rc":[{"batb":[[0,2.32,32.53],[1,1.9,998.13],[2,1.85,738.46]],"ltp":2.36,"tv":20.22,"id":891555}]}]}
{"op":"mcm","clk":"11915354117","pt":1724541414937,"mc":[{"id":"1.232220323","rc":[{"batb":[[0,2.34,5],[1,2.32,32.53],[2,1.9,998.13]],"ltp":2.36,"tv":20.22,"id":891555}]}]}
{"op":"mcm","clk":"11915354273","pt":1724541418464,"mc":[{"id":"1.232220323","rc":[{"batb":[[0,2.32,32.53],[1,1.9,998.13],[2,1.85,738.46]],"ltp":2.36,"tv":20.22,"id":891555}]}]}
{"op":"mcm","clk":"11915354451","pt":1724541421352,"mc":[{"id":"1.232220323","rc":[{"batb":[[0,2.34,5],[1,2.32,32.53],[2,1.9,998.13]],"ltp":2.36,"tv":20.22,"id":891555}]}]}
{"op":"mcm","clk":"11915354666","pt":1724541424869,"mc":[{"id":"1.232220323","rc":[{"batb":[[0,2.32,32.53],[1,1.9,998.13],[2,1.85,738.46]],"ltp":2.36,"tv":20.22,"id":891555}]}]}
{"op":"mcm","clk":"11915354770","pt":1724541427082,"mc":[{"id":"1.232220323","rc":[{"batb":[[0,2.34,5],[1,2.32,32.53],[2,1.9,998.13]],"ltp":2.36,"tv":20.22,"id":891555}]}]}
{"op":"mcm","clk":"11915354931","pt":1724541430484,"mc":[{"id":"1.232220323","rc":[{"batb":[[0,2.32,32.53],[1,1.9,998.13],[2,1.85,738.46]],"ltp":2.36,"tv":20.22,"id":891555}]}]}
{"op":"mcm","clk":"11915355052","pt":1724541432908,"mc":[{"id":"1.232220323","rc":[{"batb":[[0,2.34,5],[1,2.32,32.53],[2,1.9,998.13]],"ltp":2.36,"tv":20.22,"id":891555}]}]}
{"op":"mcm","clk":"11915355226","pt":1724541436500,"mc":[{"id":"1.232220323","rc":[{"batb":[[0,2.32,32.53],[1,1.9,998.13],[2,1.85,738.46]],"ltp":2.36,"tv":20.22,"id":891555}]}]}
{"op":"mcm","clk":"11915355345","pt":1724541438878,"mc":[{"id":"1.232220323","rc":[{"batb":[[0,2.34,5],[1,2.32,32.53],[2,1.9,998.13]],"ltp":2.36,"tv":20.22,"id":891555}]}]}
{"op":"mcm","clk":"11915355510","pt":1724541442296,"mc":[{"id":"1.232220323","rc":[{"batb":[[0,2.32,32.53],[1,1.9,998.13],[2,1.85,738.46]],"ltp":2.36,"tv":20.22,"id":891555}]}]}
{"op":"mcm","clk":"11915355609","pt":1724541444614,"mc":[{"id":"1.232220323","rc":[{"batb":[[0,2.34,5],[1,2.32,32.53],[2,1.9,998.13]],"ltp":2.36,"tv":20.22,"id":891555}]}]}
{"op":"mcm","clk":"11915355772","pt":1724541448120,"mc":[{"id":"1.232220323","rc":[{"batb":[[0,2.32,32.53],[1,1.9,998.13],[2,1.85,738.46]],"ltp":2.36,"tv":20.22,"id":891555}]}]}
{"op":"mcm","clk":"11915355878","pt":1724541450796,"mc":[{"id":"1.232220323","rc":[{"batb":[[0,2.34,5],[1,2.32,32.53],[2,1.9,998.13]],"ltp":2.36,"tv":20.22,"id":891555}]}]}
{"op":"mcm","clk":"11915356042","pt":1724541454199,"mc":[{"id":"1.232220323","rc":[{"batb":[[0,2.32,32.53],[1,1.9,998.13],[2,1.85,738.46]],"ltp":2.36,"tv":20.22,"id":891555}]}]}
{"op":"mcm","clk":"11915356198","pt":1724541457531,"mc":[{"id":"1.232220323","rc":[{"batb":[[0,2.34,5],[1,2.32,32.53],[2,1.9,998.13]],"ltp":2.36,"tv":20.22,"id":891555}]}]}
{"op":"mcm","clk":"11915356344","pt":1724541460829,"mc":[{"id":"1.232220323","rc":[{"batb":[[0,2.32,32.53],[1,1.9,998.13],[2,1.85,738.46]],"ltp":2.36,"tv":20.22,"id":891555}]}]}
{"op":"mcm","clk":"11915356432","pt":1724541463239,"mc":[{"id":"1.232220323","rc":[{"batb":[[0,2.34,5],[1,2.32,32.53],[2,1.9,998.13]],"ltp":2.36,"tv":20.22,"id":891555}]}]}
{"op":"mcm","clk":"11915356557","pt":1724541466525,"mc":[{"id":"1.232220323","rc":[{"batb":[[0,2.32,32.53],[1,1.9,998.13],[2,1.85,738.46]],"ltp":2.36,"tv":20.22,"id":891555}]}]}
{"op":"mcm","clk":"11915356713","pt":1724541468947,"mc":[{"id":"1.232220323","rc":[{"batb":[[0,2.34,5],[1,2.32,32.53],[2,1.9,998.13]],"ltp":2.36,"tv":20.22,"id":891555}]}]}
{"op":"mcm","clk":"11915356828","pt":1724541472132,"mc":[{"id":"1.232220323","rc":[{"batb":[[0,2.32,32.53],[1,1.9,998.13],[2,1.85,738.46]],"ltp":2.36,"tv":20.22,"id":891555}]}]}
{"op":"mcm","clk":"11915356941","pt":1724541474752,"mc":[{"id":"1.232220323","rc":[{"batb":[[0,2.34,5],[1,2.32,32.53],[2,1.9,998.13]],"ltp":2.36,"tv":20.22,"id":891555}]}]}
{"op":"mcm","clk":"11915357055","pt":1724541477947,"mc":[{"id":"1.232220323","rc":[{"batb":[[0,2.32,32.53],[1,1.9,998.13],[2,1.85,738.46]],"ltp":2.36,"tv":20.22,"id":891555}]}]}
{"op":"mcm","clk":"11915357188","pt":1724541481037,"mc":[{"id":"1.232220323","rc":[{"batb":[[0,2.34,5],[1,2.32,32.53],[2,1.9,998.13]],"ltp":2.36,"tv":20.22,"id":891555}]}]}
{"op":"mcm","clk":"11915357367","pt":1724541484636,"mc":[{"id":"1.232220323","rc":[{"batb":[[0,2.32,32.53],[1,1.9,998.13],[2,1.85,738.46]],"ltp":2.36,"tv":20.22,"id":891555}]}]}
{"op":"mcm","clk":"11915357465","pt":1724541486935,"mc":[{"id":"1.232220323","rc":[{"batb":[[0,2.34,5],[1,2.32,32.53],[2,1.9,998.13]],"ltp":2.36,"tv":20.22,"id":891555}]}]}
{"op":"mcm","clk":"11915357626","pt":1724541490378,"mc":[{"id":"1.232220323","rc":[{"batb":[[0,2.32,32.53],[1,1.9,998.13],[2,1.85,738.46]],"ltp":2.36,"tv":20.22,"id":891555}]}]}
{"op":"mcm","clk":"11915357740","pt":1724541492639,"mc":[{"id":"1.232220323","rc":[{"batb":[[0,2.34,5],[1,2.32,32.53],[2,1.9,998.13]],"ltp":2.36,"tv":20.22,"id":891555}]}]}
{"op":"mcm","clk":"11915357902","pt":1724541496081,"mc":[{"id":"1.232220323","rc":[{"batb":[[0,2.32,32.53],[1,1.9,998.13],[2,1.85,738.46]],"ltp":2.36,"tv":20.22,"id":891555}]}]}
{"op":"mcm","clk":"11915358062","pt":1724541498650,"mc":[{"id":"1.232220323","rc":[{"batb":[[0,2.34,5],[1,2.32,32.53],[2,1.9,998.13]],"ltp":2.36,"tv":20.22,"id":891555}]}]}
{"op":"mcm","clk":"11915358238","pt":1724541502155,"mc":[{"id":"1.232220323","rc":[{"batb":[[0,2.32,32.53],[1,1.9,998.13],[2,1.85,738.46]],"ltp":2.36,"tv":20.22,"id":891555}]}]}
{"op":"mcm","clk":"11915358356","pt":1724541504364,"mc":[{"id":"1.232220323","rc":[{"batb":[[0,2.34,5],[1,2.32,32.53],[2,1.9,998.13]],"ltp":2.36,"tv":20.22,"id":891555}]}]}
{"op":"mcm","clk":"11915358513","pt":1724541507770,"mc":[{"id":"1.232220323","rc":[{"batb":[[0,2.32,32.53],[1,1.9,998.13],[2,1.85,738.46]],"ltp":2.36,"tv":20.22,"id":891555}]}]}
{"op":"mcm","clk":"11915358598","pt":1724541509977,"mc":[{"id":"1.232220323","rc":[{"batb":[[0,2.34,5],[1,2.32,32.53],[2,1.9,998.13]],"ltp":2.36,"tv":20.22,"id":891555}]}]}
{"op":"mcm","clk":"11915358713","pt":1724541513163,"mc":[{"id":"1.232220323","rc":[{"batb":[[0,2.32,32.53],[1,1.9,998.13],[2,1.85,738.46]],"ltp":2.36,"tv":20.22,"id":891555}]}]}
{"op":"mcm","clk":"11915358811","pt":1724541515370,"mc":[{"id":"1.232220323","rc":[{"batb":[[0,2.34,5],[1,2.32,32.53],[2,1.9,998.13]],"ltp":2.36,"tv":20.22,"id":891555}]}]}
{"op":"mcm","clk":"11915358948","pt":1724541518808,"mc":[{"id":"1.232220323","rc":[{"batb":[[0,2.32,32.53],[1,1.9,998.13],[2,1.85,738.46]],"ltp":2.36,"tv":20.22,"id":891555}]}]}
{"op":"mcm","clk":"11915359033","pt":1724541521074,"mc":[{"id":"1.232220323","rc":[{"batb":[[0,2.34,5],[1,2.32,32.53],[2,1.9,998.13]],"ltp":2.36,"tv":20.22,"id":891555}]}]}
{"op":"mcm","clk":"11915359168","pt":1724541524619,"mc":[{"id":"1.232220323","rc":[{"batb":[[0,2.32,32.53],[1,1.9,998.13],[2,1.85,738.46]],"ltp":2.36,"tv":20.22,"id":891555}]}]}
{"op":"mcm","clk":"11915359256","pt":1724541526989,"mc":[{"id":"1.232220323","rc":[{"batb":[[0,2.34,5],[1,2.32,32.53],[2,1.9,998.13]],"ltp":2.36,"tv":20.22,"id":891555}]}]}
{"op":"mcm","clk":"11915359421","pt":1724541530527,"mc":[{"id":"1.232220323","rc":[{"batb":[[0,2.32,32.53],[1,1.9,998.13],[2,1.85,738.46]],"ltp":2.36,"tv":20.22,"id":891555}]}]}
{"op":"mcm","clk":"11915359502","pt":1724541532887,"mc":[{"id":"1.232220323","rc":[{"batb":[[0,2.34,5],[1,2.32,32.53],[2,1.9,998.13]],"ltp":2.36,"tv":20.22,"id":891555}]}]}
{"op":"mcm","clk":"11915359631","pt":1724541536131,"mc":[{"id":"1.232220323","rc":[{"batb":[[0,2.32,32.53],[1,1.9,998.13],[2,1.85,738.46]],"ltp":2.36,"tv":20.22,"id":891555}]}]}
{"op":"mcm","clk":"11915359733","pt":1724541538599,"mc":[{"id":"1.232220323","rc":[{"batb":[[0,2.34,5],[1,2.32,32.53],[2,1.9,998.13]],"ltp":2.36,"tv":20.22,"id":891555}]}]}
{"op":"mcm","clk":"11915359938","pt":1724541542108,"mc":[{"id":"1.232220323","rc":[{"batb":[[0,2.32,32.53],[1,1.9,998.13],[2,1.85,738.46]],"ltp":2.36,"tv":20.22,"id":891555}]}]}
{"op":"mcm","clk":"11915360081","pt":1724541544836,"mc":[{"id":"1.232220323","rc":[{"batb":[[0,2.34,5],[1,2.32,32.53],[2,1.9,998.13]],"ltp":2.36,"tv":20.22,"id":891555}]}]}
{"op":"mcm","clk":"11915360257","pt":1724541548716,"mc":[{"id":"1.232220323","rc":[{"batb":[[0,2.32,32.53],[1,1.9,998.13],[2,1.85,738.46]],"ltp":2.36,"tv":20.22,"id":891555}]}]}
{"op":"mcm","clk":"11915360379","pt":1724541551233,"mc":[{"id":"1.232220323","rc":[{"batb":[[0,2.34,5],[1,2.32,32.53],[2,1.9,998.13]],"ltp":2.36,"tv":20.22,"id":891555}]}]}
{"op":"mcm","clk":"11915360550","pt":1724541554464,"mc":[{"id":"1.232220323","rc":[{"batb":[[0,2.32,32.53],[1,1.9,998.13],[2,1.85,738.46]],"ltp":2.36,"tv":20.22,"id":891555}]}]}
{"op":"mcm","clk":"11915360674","pt":1724541556837,"mc":[{"id":"1.232220323","rc":[{"batb":[[0,2.34,5],[1,2.32,32.53],[2,1.9,998.13]],"ltp":2.36,"tv":20.22,"id":891555}]}]}
{"op":"mcm","clk":"11915360879","pt":1724541560334,"mc":[{"id":"1.232220323","rc":[{"batb":[[0,2.32,32.53],[1,1.9,998.13],[2,1.85,738.46]],"ltp":2.36,"tv":20.22,"id":891555}]}]}
{"op":"mcm","clk":"11915360988","pt":1724541562849,"mc":[{"id":"1.232220323","rc":[{"batb":[[0,2.34,5],[1,2.32,32.53],[2,1.9,998.13]],"ltp":2.36,"tv":20.22,"id":891555}]}]}
{"op":"mcm","clk":"11915361145","pt":1724541566238,"mc":[{"id":"1.232220323","rc":[{"batb":[[0,2.32,32.53],[1,1.9,998.13],[2,1.85,738.46]],"ltp":2.36,"tv":20.22,"id":891555}]}]}
{"op":"mcm","clk":"11915361235","pt":1724541568453,"mc":[{"id":"1.232220323","rc":[{"batb":[[0,2.34,5],[1,2.32,32.53],[2,1.9,998.13]],"ltp":2.36,"tv":20.22,"id":891555}]}]}
{"op":"mcm","clk":"11915361391","pt":1724541571684,"mc":[{"id":"1.232220323","rc":[{"batb":[[0,2.32,32.53],[1,1.9,998.13],[2,1.85,738.46]],"ltp":2.36,"tv":20.22,"id":891555}]}]}
{"op":"mcm","clk":"11915361560","pt":1724541575078,"mc":[{"id":"1.232220323","rc":[{"batb":[[0,2.34,5],[1,2.32,32.53],[2,1.9,998.13]],"ltp":2.36,"tv":20.22,"id":891555}]}]}
{"op":"mcm","clk":"11915361725","pt":1724541578379,"mc":[{"id":"1.232220323","rc":[{"batb":[[0,2.32,32.53],[1,1.9,998.13],[2,1.85,738.46]],"ltp":2.36,"tv":20.22,"id":891555}]}]}
{"op":"mcm","clk":"11915361838","pt":1724541580797,"mc":[{"id":"1.232220323","rc":[{"batb":[[0,2.34,5],[1,2.32,32.53],[2,1.9,998.13]],"ltp":2.36,"tv":20.22,"id":891555}]}]}
{"op":"mcm","clk":"11915361986","pt":1724541584095,"mc":[{"id":"1.232220323","rc":[{"batb":[[0,2.32,32.53],[1,1.9,998.13],[2,1.85,738.46]],"ltp":2.36,"tv":20.22,"id":891555}]}]}
{"op":"mcm","clk":"11915362076","pt":1724541586510,"mc":[{"id":"1.232220323","rc":[{"batb":[[0,2.34,5],[1,2.32,32.53],[2,1.9,998.13]],"ltp":2.36,"tv":20.22,"id":891555}]}]}
{"op":"mcm","clk":"11915362259","pt":1724541589813,"mc":[{"id":"1.232220323","rc":[{"batb":[[0,2.32,32.53],[1,1.9,998.13],[2,1.85,738.46]],"ltp":2.36,"tv":20.22,"id":891555}]}]}
{"op":"mcm","clk":"11915362403","pt":1724541592290,"mc":[{"id":"1.232220323","rc":[{"batb":[[0,2.34,5],[1,2.32,32.53],[2,1.9,998.13]],"ltp":2.36,"tv":20.22,"id":891555}]}]}
{"op":"mcm","clk":"11915362574","pt":1724541595587,"mc":[{"id":"1.232220323","rc":[{"batb":[[0,2.32,32.53],[1,1.9,998.13],[2,1.85,738.46]],"ltp":2.36,"tv":20.22,"id":891555}]}]}
{"op":"mcm","clk":"11915362699","pt":1724541597803,"mc":[{"id":"1.232220323","rc":[{"batb":[[0,2.34,5],[1,2.32,32.53],[2,1.9,998.13]],"ltp":2.36,"tv":20.22,"id":891555}]}]}
{"op":"mcm","clk":"11915362841","pt":1724541601102,"mc":[{"id":"1.232220323","rc":[{"batb":[[0,2.32,32.53],[1,1.9,998.13],[2,1.85,738.46]],"ltp":2.36,"tv":20.22,"id":891555}]}]}
{"op":"mcm","clk":"11915362974","pt":1724541603518,"mc":[{"id":"1.232220323","rc":[{"batb":[[0,2.34,5],[1,2.32,32.53],[2,1.9,998.13]],"ltp":2.36,"tv":20.22,"id":891555}]}]}
{"op":"mcm","clk":"11915363155","pt":1724541606929,"mc":[{"id":"1.232220323","rc":[{"batb":[[0,2.32,32.53],[1,1.9,998.13],[2,1.85,738.46]],"ltp":2.36,"tv":20.22,"id":891555}]}]}
{"op":"mcm","clk":"11915363276","pt":1724541609094,"mc":[{"id":"1.232220323","rc":[{"batb":[[0,2.34,5],[1,2.32,32.53],[2,1.9,998.13]],"ltp":2.36,"tv":20.22,"id":891555}]}]}
{"op":"mcm","clk":"11915363410","pt":1724541612421,"mc":[{"id":"1.232220323","rc":[{"batb":[[0,2.32,32.53],[1,1.9,998.13],[2,1.85,738.46]],"ltp":2.36,"tv":20.22,"id":891555}]}]}
{"op":"mcm","clk":"11915363528","pt":1724541614835,"mc":[{"id":"1.232220323","rc":[{"batb":[[0,2.34,5],[1,2.32,32.53],[2,1.9,998.13]],"ltp":2.36,"tv":20.22,"id":891555}]}]}
{"op":"mcm","clk":"11915363670","pt":1724541618126,"mc":[{"id":"1.232220323","rc":[{"batb":[[0,2.32,32.53],[1,1.9,998.13],[2,1.85,738.46]],"ltp":2.36,"tv":20.22,"id":891555}]}]}
{"op":"mcm","clk":"11915363773","pt":1724541620335,"mc":[{"id":"1.232220323","rc":[{"batb":[[0,2.34,5],[1,2.32,32.53],[2,1.9,998.13]],"ltp":2.36,"tv":20.22,"id":891555}]}]}
{"op":"mcm","clk":"11915363955","pt":1724541623823,"mc":[{"id":"1.232220323","rc":[{"batb":[[0,2.32,32.53],[1,1.9,998.13],[2,1.85,738.46]],"ltp":2.36,"tv":20.22,"id":891555}]}]}
{"op":"mcm","clk":"11915364117","pt":1724541627121,"mc":[{"id":"1.232220323","rc":[{"batb":[[0,2.34,5],[1,2.32,32.53],[2,1.9,998.13]],"ltp":2.36,"tv":20.22,"id":891555}]}]}
{"op":"mcm","clk":"11915364266","pt":1724541630419,"mc":[{"id":"1.232220323","rc":[{"batb":[[0,2.32,32.53],[1,1.9,998.13],[2,1.85,738.46]],"ltp":2.36,"tv":20.22,"id":891555}]}]}
{"op":"mcm","clk":"11915364413","pt":1724541633038,"mc":[{"id":"1.232220323","rc":[{"batb":[[0,2.34,5],[1,2.32,32.53],[2,1.9,998.13]],"ltp":2.36,"tv":20.22,"id":891555}]}]}
{"op":"mcm","clk":"11915364567","pt":1724541636340,"mc":[{"id":"1.232220323","rc":[{"batb":[[0,2.32,32.53],[1,1.9,998.13],[2,1.85,738.46]],"ltp":2.36,"tv":20.22,"id":891555}]}]}
{"op":"mcm","clk":"11915364684","pt":1724541638706,"mc":[{"id":"1.232220323","rc":[{"batb":[[0,2.34,5],[1,2.32,32.53],[2,1.9,998.13]],"ltp":2.36,"tv":20.22,"id":891555}]}]}
{"op":"mcm","clk":"11915364817","pt":1724541641946,"mc":[{"id":"1.232220323","rc":[{"batb":[[0,2.32,32.53],[1,1.9,998.13],[2,1.85,738.46]],"ltp":2.36,"tv":20.22,"id":891555}]}]}
{"op":"mcm","clk":"11915364946","pt":1724541644417,"mc":[{"id":"1.232220323","rc":[{"batb":[[0,2.34,5],[1,2.32,32.53],[2,1.9,998.13]],"ltp":2.36,"tv":20.22,"id":891555}]}]}
{"op":"mcm","clk":"11915365100","pt":1724541647666,"mc":[{"id":"1.232220323","rc":[{"batb":[[0,2.32,32.53],[1,1.9,998.13],[2,1.85,738.46]],"ltp":2.36,"tv":20.22,"id":891555}]}]}
{"op":"mcm","clk":"11915365234","pt":1724541650038,"mc":[{"id":"1.232220323","rc":[{"batb":[[0,2.34,5],[1,2.32,32.53],[2,1.9,998.13]],"ltp":2.36,"tv":20.22,"id":891555}]}]}
{"op":"mcm","clk":"11915365410","pt":1724541653335,"mc":[{"id":"1.232220323","rc":[{"batb":[[0,2.32,32.53],[1,1.9,998.13],[2,1.85,738.46]],"ltp":2.36,"tv":20.22,"id":891555}]}]}
{"op":"mcm","clk":"11915365536","pt":1724541655751,"mc":[{"id":"1.232220323","rc":[{"batb":[[0,2.34,5],[1,2.32,32.53],[2,1.9,998.13]],"ltp":2.36,"tv":20.22,"id":891555}]}]}
{"op":"mcm","clk":"11915365701","pt":1724541659047,"mc":[{"id":"1.232220323","rc":[{"batb":[[0,2.32,32.53],[1,1.9,998.13],[2,1.85,738.46]],"ltp":2.36,"tv":20.22,"id":891555}]}]}
{"op":"mcm","clk":"11915365836","pt":1724541661465,"mc":[{"id":"1.232220323","rc":[{"batb":[[0,2.34,5],[1,2.32,32.53],[2,1.9,998.13]],"ltp":2.36,"tv":20.22,"id":891555}]}]}
{"op":"mcm","clk":"11915366014","pt":1724541664760,"mc":[{"id":"1.232220323","rc":[{"batb":[[0,2.32,32.53],[1,1.9,998.13],[2,1.85,738.46]],"ltp":2.36,"tv":20.22,"id":891555}]}]}
{"op":"mcm","clk":"11915366171","pt":1724541667641,"mc":[{"id":"1.232220323","rc":[{"batb":[[0,2.34,5],[1,2.32,32.53],[2,1.9,998.13]],"ltp":2.36,"tv":20.22,"id":891555}]}]}
{"op":"mcm","clk":"11915366358","pt":1724541670980,"mc":[{"id":"1.232220323","rc":[{"batb":[[0,2.32,32.53],[1,1.9,998.13],[2,1.85,738.46]],"ltp":2.36,"tv":20.22,"id":891555}]}]}
{"op":"mcm","clk":"11915366463","pt":1724541673349,"mc":[{"id":"1.232220323","rc":[{"batb":[[0,2.34,5],[1,2.32,32.53],[2,1.9,998.13]],"ltp":2.36,"tv":20.22,"id":891555}]}]}
{"op":"mcm","clk":"11915366635","pt":1724541676695,"mc":[{"id":"1.232220323","rc":[{"batb":[[0,2.32,32.53],[1,1.9,998.13],[2,1.85,738.46]],"ltp":2.36,"tv":20.22,"id":891555}]}]}
{"op":"mcm","clk":"11915366767","pt":1724541679584,"mc":[{"id":"1.232220323","rc":[{"batb":[[0,2.34,5],[1,2.32,32.53],[2,1.9,998.13]],"ltp":2.36,"tv":20.22,"id":891555}]}]}
{"op":"mcm","clk":"11915366957","pt":1724541683087,"mc":[{"id":"1.232220323","rc":[{"batb":[[0,2.32,32.53],[1,1.9,998.13],[2,1.85,738.46]],"ltp":2.36,"tv":20.22,"id":891555}]}]}
{"op":"mcm","clk":"11915367083","pt":1724541685456,"mc":[{"id":"1.232220323","rc":[{"batb":[[0,2.34,5],[1,2.32,32.53],[2,1.9,998.13]],"ltp":2.36,"tv":20.22,"id":891555}]}]}
{"op":"mcm","clk":"11915367230","pt":1724541688961,"mc":[{"id":"1.232220323","rc":[{"batb":[[0,2.32,32.53],[1,1.9,998.13],[2,1.85,738.46]],"ltp":2.36,"tv":20.22,"id":891555}]}]}
{"op":"mcm","clk":"11915367322","pt":1724541691270,"mc":[{"id":"1.232220323","rc":[{"batb":[[0,2.34,5],[1,2.32,32.53],[2,1.9,998.13]],"ltp":2.36,"tv":20.22,"id":891555}]}]}
{"op":"mcm","clk":"11915367503","pt":1724541694562,"mc":[{"id":"1.232220323","rc":[{"batb":[[0,2.32,32.53],[1,1.9,998.13],[2,1.85,738.46]],"ltp":2.36,"tv":20.22,"id":891555}]}]}
{"op":"mcm","clk":"11915367666","pt":1724541697784,"mc":[{"id":"1.232220323","rc":[{"batb":[[0,2.34,5],[1,2.32,32.53],[2,1.9,998.13]],"ltp":2.36,"tv":20.22,"id":891555}]}]}
{"op":"mcm","clk":"11915367812","pt":1724541701177,"mc":[{"id":"1.232220323","rc":[{"batb":[[0,2.32,32.53],[1,1.9,998.13],[2,1.85,738.46]],"ltp":2.36,"tv":20.22,"id":891555}]}]}
{"op":"mcm","clk":"11915367904","pt":1724541703484,"mc":[{"id":"1.232220323","rc":[{"batb":[[0,2.34,5],[1,2.32,32.53],[2,1.9,998.13]],"ltp":2.36,"tv":20.22,"id":891555}]}]}
{"op":"mcm","clk":"11915368053","pt":1724541707080,"mc":[{"id":"1.232220323","rc":[{"batb":[[0,2.32,32.53],[1,1.9,998.13],[2,1.85,738.46]],"ltp":2.36,"tv":20.22,"id":891555}]}]}
{"op":"mcm","clk":"11915368209","pt":1724541709603,"mc":[{"id":"1.232220323","rc":[{"batb":[[0,2.34,5],[1,2.32,32.53],[2,1.9,998.13]],"ltp":2.36,"tv":20.22,"id":891555}]}]}
{"op":"mcm","clk":"11915368344","pt":1724541712997,"mc":[{"id":"1.232220323","rc":[{"batb":[[0,2.32,32.53],[1,1.9,998.13],[2,1.85,738.46]],"ltp":2.36,"tv":20.22,"id":891555}]}]}
{"op":"mcm","clk":"11915368469","pt":1724541715519,"mc":[{"id":"1.232220323","rc":[{"batb":[[0,2.34,5],[1,2.32,32.53],[2,1.9,998.13]],"ltp":2.36,"tv":20.22,"id":891555}]}]}
{"op":"mcm","clk":"11915368590","pt":1724541718808,"mc":[{"id":"1.232220323","rc":[{"batb":[[0,2.32,32.53],[1,1.9,998.13],[2,1.85,738.46]],"ltp":2.36,"tv":20.22,"id":891555}]}]}
{"op":"mcm","clk":"11915368698","pt":1724541721230,"mc":[{"id":"1.232220323","rc":[{"batb":[[0,2.34,5],[1,2.32,32.53],[2,1.9,998.13]],"ltp":2.36,"tv":20.22,"id":891555}]}]}
{"op":"mcm","clk":"11915368928","pt":1724541725606,"mc":[{"id":"1.232220323","rc":[{"batb":[[0,2.32,32.53],[1,1.9,998.13],[2,1.85,738.46]],"ltp":2.36,"tv":20.22,"id":891555}]}]}
{"op":"mcm","clk":"11915369031","pt":1724541727817,"mc":[{"id":"1.232220323","rc":[{"batb":[[0,2.34,5],[1,2.32,32.53],[2,1.9,998.13]],"ltp":2.36,"tv":20.22,"id":891555}]}]}
{"op":"mcm","clk":"11915369179","pt":1724541731320,"mc":[{"id":"1.232220323","rc":[{"batb":[[0,2.32,32.53],[1,1.9,998.13],[2,1.85,738.46]],"ltp":2.36,"tv":20.22,"id":891555}]}]}
{"op":"mcm","clk":"11915369334","pt":1724541734816,"mc":[{"id":"1.232220323","rc":[{"batb":[[0,2.34,5],[1,2.32,32.53],[2,1.9,998.13]],"ltp":2.36,"tv":20.22,"id":891555}]}]}
{"op":"mcm","clk":"11915369545","pt":1724541738435,"mc":[{"id":"1.232220323","rc":[{"batb":[[0,2.32,32.53],[1,1.9,998.13],[2,1.85,738.46]],"ltp":2.36,"tv":20.22,"id":891555}]}]}
{"op":"mcm","clk":"11915369653","pt":1724541740648,"mc":[{"id":"1.232220323","rc":[{"batb":[[0,2.34,5],[1,2.32,32.53],[2,1.9,998.13]],"ltp":2.36,"tv":20.22,"id":891555}]}]}
{"op":"mcm","clk":"11915369849","pt":1724541743950,"mc":[{"id":"1.232220323","rc":[{"batb":[[0,2.32,32.53],[1,1.9,998.13],[2,1.85,738.46]],"ltp":2.36,"tv":20.22,"id":891555}]}]}
{"op":"mcm","clk":"11915369976","pt":1724541746265,"mc":[{"id":"1.232220323","rc":[{"batb":[[0,2.34,5],[1,2.32,32.53],[2,1.9,998.13]],"ltp":2.36,"tv":20.22,"id":891555}]}]}
{"op":"mcm","clk":"11915370171","pt":1724541749864,"mc":[{"id":"1.232220323","rc":[{"batb":[[0,2.32,32.53],[1,1.9,998.13],[2,1.85,738.46]],"ltp":2.36,"tv":20.22,"id":891555}]}]}
{"op":"mcm","clk":"11915370303","pt":1724541752038,"mc":[{"id":"1.232220323","rc":[{"batb":[[0,2.34,5],[1,2.32,32.53],[2,1.9,998.13]],"ltp":2.36,"tv":20.22,"id":891555}]}]}
{"op":"mcm","clk":"11915370502","pt":1724541755578,"mc":[{"id":"1.232220323","rc":[{"batb":[[0,2.32,32.53],[1,1.9,998.13],[2,1.85,738.46]],"ltp":2.36,"tv":20.22,"id":891555}]}]}
{"op":"mcm","clk":"11915370616","pt":1724541757743,"mc":[{"id":"1.232220323","rc":[{"batb":[[0,2.34,5],[1,2.32,32.53],[2,1.9,998.13]],"ltp":2.36,"tv":20.22,"id":891555}]}]}
{"op":"mcm","clk":"11915370802","pt":1724541761356,"mc":[{"id":"1.232220323","rc":[{"batb":[[0,2.32,32.53],[1,1.9,998.13],[2,1.85,738.46]],"ltp":2.36,"tv":20.22,"id":891555}]}]}
{"op":"mcm","clk":"11915370927","pt":1724541763570,"mc":[{"id":"1.232220323","rc":[{"batb":[[0,2.34,5],[1,2.32,32.53],[2,1.9,998.13]],"ltp":2.36,"tv":20.22,"id":891555}]}]}
{"op":"mcm","clk":"11915371111","pt":1724541767083,"mc":[{"id":"1.232220323","rc":[{"batb":[[0,2.32,32.53],[1,1.9,998.13],[2,1.85,738.46]],"ltp":2.36,"tv":20.22,"id":891555}]}]}
{"op":"mcm","clk":"11915371234","pt":1724541769302,"mc":[{"id":"1.232220323","rc":[{"batb":[[0,2.34,5],[1,2.32,32.53],[2,1.9,998.13]],"ltp":2.36,"tv":20.22,"id":891555}]}]}
{"op":"mcm","clk":"11915371383","pt":1724541772754,"mc":[{"id":"1.232220323","rc":[{"batb":[[0,2.32,32.53],[1,1.9,998.13],[2,1.85,738.46]],"ltp":2.36,"tv":20.22,"id":891555}]}]}
{"op":"mcm","clk":"11915371494","pt":1724541774966,"mc":[{"id":"1.232220323","rc":[{"batb":[[0,2.34,5],[1,2.32,32.53],[2,1.9,998.13]],"ltp":2.36,"tv":20.22,"id":891555}]}]}
{"op":"mcm","clk":"11915371673","pt":1724541778484,"mc":[{"id":"1.232220323","rc":[{"batb":[[0,2.32,32.53],[1,1.9,998.13],[2,1.85,738.46]],"ltp":2.36,"tv":20.22,"id":891555}]}]}
{"op":"mcm","clk":"11915371779","pt":1724541780693,"mc":[{"id":"1.232220323","rc":[{"batb":[[0,2.34,5],[1,2.32,32.53],[2,1.9,998.13]],"ltp":2.36,"tv":20.22,"id":891555}]}]}
{"op":"mcm","clk":"11915371980","pt":1724541784097,"mc":[{"id":"1.232220323","rc":[{"batb":[[0,2.32,32.53],[1,1.9,998.13],[2,1.85,738.46]],"ltp":2.36,"tv":20.22,"id":891555}]}]}
{"op":"mcm","clk":"11915372092","pt":1724541786209,"mc":[{"id":"1.232220323","rc":[{"batb":[[0,2.34,5],[1,2.32,32.53],[2,1.9,998.13]],"ltp":2.36,"tv":20.22,"id":891555}]}]}
{"op":"mcm","clk":"11915372280","pt":1724541789606,"mc":[{"id":"1.232220323","rc":[{"batb":[[0,2.32,32.53],[1,1.9,998.13],[2,1.85,738.46]],"ltp":2.36,"tv":20.22,"id":891555}]}]}
{"op":"mcm","clk":"11915372424","pt":1724541792090,"mc":[{"id":"1.232220323","rc":[{"batb":[[0,2.34,5],[1,2.32,32.53],[2,1.9,998.13]],"ltp":2.36,"tv":20.22,"id":891555}]}]}
{"op":"mcm","clk":"11915372608","pt":1724541795417,"mc":[{"id":"1.232220323","rc":[{"batb":[[0,2.32,32.53],[1,1.9,998.13],[2,1.85,738.46]],"ltp":2.36,"tv":20.22,"id":891555}]}]}
{"op":"mcm","clk":"11915372841","pt":1724541799101,"mc":[{"id":"1.232220323","rc":[{"batb":[[0,2.34,5],[1,2.32,32.53],[2,1.9,998.13]],"ltp":2.36,"tv":20.22,"id":891555}]}]}
{"op":"mcm","clk":"11915373057","pt":1724541802526,"mc":[{"id":"1.232220323","rc":[{"batb":[[0,2.32,32.53],[1,1.9,998.13],[2,1.85,738.46]],"ltp":2.36,"tv":20.22,"id":891555}]}]}
{"op":"mcm","clk":"11915373165","pt":1724541804708,"mc":[{"id":"1.232220323","rc":[{"batb":[[0,2.34,5],[1,2.32,32.53],[2,1.9,998.13]],"ltp":2.36,"tv":20.22,"id":891555}]}]}
{"op":"mcm","clk":"11915373326","pt":1724541808031,"mc":[{"id":"1.232220323","rc":[{"batb":[[0,2.32,32.53],[1,1.9,998.13],[2,1.85,738.46]],"ltp":2.36,"tv":20.22,"id":891555}]}]}
{"op":"mcm","clk":"11915373451","pt":1724541810298,"mc":[{"id":"1.232220323","rc":[{"batb":[[0,2.34,5],[1,2.32,32.53],[2,1.9,998.13]],"ltp":2.36,"tv":20.22,"id":891555}]}]}
{"op":"mcm","clk":"11915373671","pt":1724541813910,"mc":[{"id":"1.232220323","rc":[{"batb":[[0,2.32,32.53],[1,1.9,998.13],[2,1.85,738.46]],"ltp":2.36,"tv":20.22,"id":891555}]}]}
{"op":"mcm","clk":"11915373815","pt":1724541816228,"mc":[{"id":"1.232220323","rc":[{"batb":[[0,2.34,5],[1,2.32,32.53],[2,1.9,998.13]],"ltp":2.36,"tv":20.22,"id":891555}]}]}
{"op":"mcm","clk":"11915373978","pt":1724541819518,"mc":[{"id":"1.232220323","rc":[{"batb":[[0,2.32,32.53],[1,1.9,998.13],[2,1.85,738.46]],"ltp":2.36,"tv":20.22,"id":891555}]}]}
{"op":"mcm","clk":"11915374094","pt":1724541821829,"mc":[{"id":"1.232220323","rc":[{"batb":[[0,2.34,5],[1,2.32,32.53],[2,1.9,998.13]],"ltp":2.36,"tv":20.22,"id":891555}]}]}
{"op":"mcm","clk":"11915374278","pt":1724541825328,"mc":[{"id":"1.232220323","rc":[{"batb":[[0,2.32,32.53],[1,1.9,998.13],[2,1.85,738.46]],"ltp":2.36,"tv":20.22,"id":891555}]}]}
{"op":"mcm","clk":"11915374417","pt":1724541827548,"mc":[{"id":"1.232220323","rc":[{"batb":[[0,2.34,5],[1,2.32,32.53],[2,1.9,998.13]],"ltp":2.36,"tv":20.22,"id":891555}]}]}
{"op":"mcm","clk":"11915374594","pt":1724541830852,"mc":[{"id":"1.232220323","rc":[{"batb":[[0,2.32,32.53],[1,1.9,998.13],[2,1.85,738.46]],"ltp":2.36,"tv":20.22,"id":891555}]}]}
{"op":"mcm","clk":"11915374742","pt":1724541833130,"mc":[{"id":"1.232220323","rc":[{"batb":[[0,2.34,5],[1,2.32,32.53],[2,1.9,998.13]],"ltp":2.36,"tv":20.22,"id":891555}]}]}
{"op":"mcm","clk":"11915374895","pt":1724541836446,"mc":[{"id":"1.232220323","rc":[{"batb":[[0,2.32,32.53],[1,1.9,998.13],[2,1.85,738.46]],"ltp":2.36,"tv":20.22,"id":891555}]}]}
{"op":"mcm","clk":"11915375000","pt":1724541838663,"mc":[{"id":"1.232220323","rc":[{"batb":[[0,2.34,5],[1,2.32,32.53],[2,1.9,998.13]],"ltp":2.36,"tv":20.22,"id":891555}]}]}
{"op":"mcm","clk":"11915375202","pt":1724541842169,"mc":[{"id":"1.232220323","rc":[{"batb":[[0,2.32,32.53],[1,1.9,998.13],[2,1.85,738.46]],"ltp":2.36,"tv":20.22,"id":891555}]}]}
{"op":"mcm","clk":"11915375323","pt":1724541844235,"mc":[{"id":"1.232220323","rc":[{"batb":[[0,2.34,5],[1,2.32,32.53],[2,1.9,998.13]],"ltp":2.36,"tv":20.22,"id":891555}]}]}
{"op":"mcm","clk":"11915375466","pt":1724541847539,"mc":[{"id":"1.232220323","rc":[{"batb":[[0,2.32,32.53],[1,1.9,998.13],[2,1.85,738.46]],"ltp":2.36,"tv":20.22,"id":891555}]}]}
{"op":"mcm","clk":"11915375584","pt":1724541849752,"mc":[{"id":"1.232220323","rc":[{"batb":[[0,2.34,5],[1,2.32,32.53],[2,1.9,998.13]],"ltp":2.36,"tv":20.22,"id":891555}]}]}
{"op":"mcm","clk":"11915375739","pt":1724541853158,"mc":[{"id":"1.232220323","rc":[{"batb":[[0,2.32,32.53],[1,1.9,998.13],[2,1.85,738.46]],"ltp":2.36,"tv":20.22,"id":891555}]}]}
{"op":"mcm","clk":"11915375901","pt":1724541856263,"mc":[{"id":"1.232220323","rc":[{"batb":[[0,2.34,5],[1,2.32,32.53],[2,1.9,998.13]],"ltp":2.36,"tv":20.22,"id":891555}]}]}
{"op":"mcm","clk":"11915376086","pt":1724541859856,"mc":[{"id":"1.232220323","rc":[{"batb":[[0,2.32,32.53],[1,1.9,998.13],[2,1.85,738.46]],"ltp":2.36,"tv":20.22,"id":891555}]}]}
{"op":"mcm","clk":"11915376169","pt":1724541862591,"mc":[{"id":"1.232220323","rc":[{"batb":[[0,2.34,5],[1,2.32,32.53],[2,1.9,998.13]],"ltp":2.36,"tv":20.22,"id":891555}]}]}
{"op":"mcm","clk":"11915376299","pt":1724541866085,"mc":[{"id":"1.232220323","rc":[{"batb":[[0,2.32,32.53],[1,1.9,998.13],[2,1.85,738.46]],"ltp":2.36,"tv":20.22,"id":891555}]}]}
{"op":"mcm","clk":"11915376389","pt":1724541868292,"mc":[{"id":"1.232220323","rc":[{"batb":[[0,2.34,5],[1,2.32,32.53],[2,1.9,998.13]],"ltp":2.36,"tv":20.22,"id":891555}]}]}
{"op":"mcm","clk":"11915376523","pt":1724541871687,"mc":[{"id":"1.232220323","rc":[{"batb":[[0,2.32,32.53],[1,1.9,998.13],[2,1.85,738.46]],"ltp":2.36,"tv":20.22,"id":891555}]}]}
{"op":"mcm","clk":"11915376598","pt":1724541873900,"mc":[{"id":"1.232220323","rc":[{"batb":[[0,2.34,5],[1,2.32,32.53],[2,1.9,998.13]],"ltp":2.36,"tv":20.22,"id":891555}]}]}
{"op":"mcm","clk":"11915376765","pt":1724541877270,"mc":[{"id":"1.232220323","rc":[{"batb":[[0,2.32,32.53],[1,1.9,998.13],[2,1.85,738.46]],"ltp":2.36,"tv":20.22,"id":891555}]}]}
{"op":"mcm","clk":"11915376884","pt":1724541879890,"mc":[{"id":"1.232220323","rc":[{"batb":[[0,2.34,5],[1,2.32,32.53],[2,1.9,998.13]],"ltp":2.36,"tv":20.22,"id":891555}]}]}
{"op":"mcm","clk":"11915377032","pt":1724541883383,"mc":[{"id":"1.232220323","rc":[{"batb":[[0,2.32,32.53],[1,1.9,998.13],[2,1.85,738.46]],"ltp":2.36,"tv":20.22,"id":891555}]}]}
{"op":"mcm","clk":"11915377137","pt":1724541885590,"mc":[{"id":"1.232220323","rc":[{"batb":[[0,2.34,5],[1,2.32,32.53],[2,1.9,998.13]],"ltp":2.36,"tv":20.22,"id":891555}]}]}
{"op":"mcm","clk":"11915377276","pt":1724541888935,"mc":[{"id":"1.232220323","rc":[{"batb":[[0,2.32,32.53],[1,1.9,998.13],[2,1.85,738.46]],"ltp":2.36,"tv":20.22,"id":891555}]}]}
{"op":"mcm","clk":"11915377367","pt":1724541891095,"mc":[{"id":"1.232220323","rc":[{"batb":[[0,2.34,5],[1,2.32,32.53],[2,1.9,998.13]],"ltp":2.36,"tv":20.22,"id":891555}]}]}
{"op":"mcm","clk":"11915377535","pt":1724541894281,"mc":[{"id":"1.232220323","rc":[{"batb":[[0,2.32,32.53],[1,1.9,998.13],[2,1.85,738.46]],"ltp":2.36,"tv":20.22,"id":891555}]}]}
{"op":"mcm","clk":"11915377654","pt":1724541896711,"mc":[{"id":"1.232220323","rc":[{"batb":[[0,2.34,5],[1,2.32,32.53],[2,1.9,998.13]],"ltp":2.36,"tv":20.22,"id":891555}]}]}
{"op":"mcm","clk":"11915377817","pt":1724541900312,"mc":[{"id":"1.232220323","rc":[{"batb":[[0,2.32,32.53],[1,1.9,998.13],[2,1.85,738.46]],"ltp":2.36,"tv":20.22,"id":891555}]}]}
{"op":"mcm","clk":"11915377937","pt":1724541902437,"mc":[{"id":"1.232220323","rc":[{"batb":[[0,2.34,5],[1,2.32,32.53],[2,1.9,998.13]],"ltp":2.36,"tv":20.22,"id":891555}]}]}
{"op":"mcm","clk":"11915378154","pt":1724541905698,"mc":[{"id":"1.232220323","rc":[{"batb":[[0,2.32,32.53],[1,1.9,998.13],[2,1.85,738.46]],"ltp":2.36,"tv":20.22,"id":891555}]}]}
{"op":"mcm","clk":"11915378291","pt":1724541908108,"mc":[{"id":"1.232220323","rc":[{"batb":[[0,2.34,5],[1,2.32,32.53],[2,1.9,998.13]],"ltp":2.36,"tv":20.22,"id":891555}]}]}
{"op":"mcm","clk":"11915378481","pt":1724541911518,"mc":[{"id":"1.232220323","rc":[{"batb":[[0,2.32,32.53],[1,1.9,998.13],[2,1.85,738.46]],"ltp":2.36,"tv":20.22,"id":891555}]}]}
{"op":"mcm","clk":"11915378600","pt":1724541913827,"mc":[{"id":"1.232220323","rc":[{"batb":[[0,2.34,5],[1,2.32,32.53],[2,1.9,998.13]],"ltp":2.36,"tv":20.22,"id":891555}]}]}
{"op":"mcm","clk":"11915378813","pt":1724541917217,"mc":[{"id":"1.232220323","rc":[{"batb":[[0,2.32,32.53],[1,1.9,998.13],[2,1.85,738.46]],"ltp":2.36,"tv":20.22,"id":891555}]}]}
{"op":"mcm","clk":"11915378996","pt":1724541920223,"mc":[{"id":"1.232220323","rc":[{"batb":[[0,2.34,5],[1,2.32,32.53],[2,1.9,998.13]],"ltp":2.36,"tv":20.22,"id":891555}]}]}
{"op":"mcm","clk":"11915379174","pt":1724541923518,"mc":[{"id":"1.232220323","rc":[{"batb":[[0,2.32,32.53],[1,1.9,998.13],[2,1.85,738.46]],"ltp":2.36,"tv":20.22,"id":891555}]}]}
{"op":"mcm","clk":"11915379290","pt":1724541925733,"mc":[{"id":"1.232220323","rc":[{"batb":[[0,2.34,5],[1,2.32,32.53],[2,1.9,998.13]],"ltp":2.36,"tv":20.22,"id":891555}]}]}
{"op":"mcm","clk":"11915379465","pt":1724541929227,"mc":[{"id":"1.232220323","rc":[{"batb":[[0,2.32,32.53],[1,1.9,998.13],[2,1.85,738.46]],"ltp":2.36,"tv":20.22,"id":891555}]}]}
{"op":"mcm","clk":"11915379572","pt":1724541931440,"mc":[{"id":"1.232220323","rc":[{"batb":[[0,2.34,5],[1,2.32,32.53],[2,1.9,998.13]],"ltp":2.36,"tv":20.22,"id":891555}]}]}
{"op":"mcm","clk":"11915379758","pt":1724541934841,"mc":[{"id":"1.232220323","rc":[{"batb":[[0,2.32,32.53],[1,1.9,998.13],[2,1.85,738.46]],"ltp":2.36,"tv":20.22,"id":891555}]}]}
{"op":"mcm","clk":"11915379879","pt":1724541937063,"mc":[{"id":"1.232220323","rc":[{"batb":[[0,2.34,5],[1,2.32,32.53],[2,1.9,998.13]],"ltp":2.36,"tv":20.22,"id":891555}]}]}
{"op":"mcm","clk":"11915380076","pt":1724541940567,"mc":[{"id":"1.232220323","rc":[{"batb":[[0,2.32,32.53],[1,1.9,998.13],[2,1.85,738.46]],"ltp":2.36,"tv":20.22,"id":891555}]}]}
{"op":"mcm","clk":"11915380207","pt":1724541942740,"mc":[{"id":"1.232220323","rc":[{"batb":[[0,2.34,5],[1,2.32,32.53],[2,1.9,998.13]],"ltp":2.36,"tv":20.22,"id":891555}]}]}
{"op":"mcm","clk":"11915380365","pt":1724541946240,"mc":[{"id":"1.232220323","rc":[{"batb":[[0,2.32,32.53],[1,1.9,998.13],[2,1.85,738.46]],"ltp":2.36,"tv":20.22,"id":891555}]}]}
{"op":"mcm","clk":"11915380490","pt":1724541948768,"mc":[{"id":"1.232220323","rc":[{"batb":[[0,2.34,5],[1,2.32,32.53],[2,1.9,998.13]],"ltp":2.36,"tv":20.22,"id":891555}]}]}
{"op":"mcm","clk":"11915380653","pt":1724541952273,"mc":[{"id":"1.232220323","rc":[{"batb":[[0,2.32,32.53],[1,1.9,998.13],[2,1.85,738.46]],"ltp":2.36,"tv":20.22,"id":891555}]}]}
{"op":"mcm","clk":"11915380774","pt":1724541954456,"mc":[{"id":"1.232220323","rc":[{"batb":[[0,2.34,5],[1,2.32,32.53],[2,1.9,998.13]],"ltp":2.36,"tv":20.22,"id":891555}]}]}
{"op":"mcm","clk":"11915380921","pt":1724541958055,"mc":[{"id":"1.232220323","rc":[{"batb":[[0,2.32,32.53],[1,1.9,998.13],[2,1.85,738.46]],"ltp":2.36,"tv":20.22,"id":891555}]}]}
{"op":"mcm","clk":"11915381048","pt":1724541960266,"mc":[{"id":"1.232220323","rc":[{"batb":[[0,2.34,5],[1,2.32,32.53],[2,1.9,998.13]],"ltp":2.36,"tv":20.22,"id":891555}]}]}
{"op":"mcm","clk":"11915381262","pt":1724541963882,"mc":[{"id":"1.232220323","rc":[{"batb":[[0,2.32,32.53],[1,1.9,998.13],[2,1.85,738.46]],"ltp":2.36,"tv":20.22,"id":891555}]}]}
{"op":"mcm","clk":"11915381377","pt":1724541966094,"mc":[{"id":"1.232220323","rc":[{"batb":[[0,2.34,5],[1,2.32,32.53],[2,1.9,998.13]],"ltp":2.36,"tv":20.22,"id":891555}]}]}
{"op":"mcm","clk":"11915381570","pt":1724541969696,"mc":[{"id":"1.232220323","rc":[{"batb":[[0,2.32,32.53],[1,1.9,998.13],[2,1.85,738.46]],"ltp":2.36,"tv":20.22,"id":891555}]}]}
{"op":"mcm","clk":"11915381700","pt":1724541971909,"mc":[{"id":"1.232220323","rc":[{"batb":[[0,2.34,5],[1,2.32,32.53],[2,1.9,998.13]],"ltp":2.36,"tv":20.22,"id":891555}]}]}
{"op":"mcm","clk":"11915381846","pt":1724541975393,"mc":[{"id":"1.232220323","rc":[{"batb":[[0,2.32,32.53],[1,1.9,998.13],[2,1.85,738.46]],"ltp":2.36,"tv":20.22,"id":891555}]}]}
{"op":"mcm","clk":"11915381952","pt":1724541977609,"mc":[{"id":"1.232220323","rc":[{"batb":[[0,2.34,5],[1,2.32,32.53],[2,1.9,998.13]],"ltp":2.36,"tv":20.22,"id":891555}]}]}
{"op":"mcm","clk":"11915382125","pt":1724541981117,"mc":[{"id":"1.232220323","rc":[{"batb":[[0,2.32,32.53],[1,1.9,998.13],[2,1.85,738.46]],"ltp":2.36,"tv":20.22,"id":891555}]}]}
{"op":"mcm","clk":"11915382228","pt":1724541983347,"mc":[{"id":"1.232220323","rc":[{"batb":[[0,2.34,5],[1,2.32,32.53],[2,1.9,998.13]],"ltp":2.36,"tv":20.22,"id":891555}]}]}
{"op":"mcm","clk":"11915382424","pt":1724541986800,"mc":[{"id":"1.232220323","rc":[{"batb":[[0,2.32,32.53],[1,1.9,998.13],[2,1.85,738.46]],"ltp":2.36,"tv":20.22,"id":891555}]}]}
{"op":"mcm","clk":"11915382549","pt":1724541988978,"mc":[{"id":"1.232220323","rc":[{"batb":[[0,2.34,5],[1,2.32,32.53],[2,1.9,998.13]],"ltp":2.36,"tv":20.22,"id":891555}]}]}
{"op":"mcm","clk":"11915382731","pt":1724541992178,"mc":[{"id":"1.232220323","rc":[{"batb":[[0,2.32,32.53],[1,1.9,998.13],[2,1.85,738.46]],"ltp":2.36,"tv":20.22,"id":891555}]}]}
{"op":"mcm","clk":"11915382899","pt":1724541994817,"mc":[{"id":"1.232220323","rc":[{"batb":[[0,2.34,5],[1,2.32,32.53],[2,1.9,998.13]],"ltp":2.36,"tv":20.22,"id":891555}]}]}
{"op":"mcm","clk":"11915383074","pt":1724541998119,"mc":[{"id":"1.232220323","rc":[{"batb":[[0,2.32,32.53],[1,1.9,998.13],[2,1.85,738.46]],"ltp":2.36,"tv":20.22,"id":891555}]}]}
{"op":"mcm","clk":"11915383191","pt":1724542000520,"mc":[{"id":"1.232220323","rc":[{"batb":[[0,2.34,5],[1,2.32,32.53],[2,1.9,998.13]],"ltp":2.36,"tv":20.22,"id":891555}]}]}
{"op":"mcm","clk":"11915383389","pt":1724542004098,"mc":[{"id":"1.232220323","rc":[{"batb":[[0,2.32,32.53],[1,1.9,998.13],[2,1.85,738.46]],"ltp":2.36,"tv":20.22,"id":891555}]}]}
{"op":"mcm","clk":"11915383484","pt":1724542006313,"mc":[{"id":"1.232220323","rc":[{"batb":[[0,2.34,5],[1,2.32,32.53],[2,1.9,998.13]],"ltp":2.36,"tv":20.22,"id":891555}]}]}
{"op":"mcm","clk":"11915383644","pt":1724542009631,"mc":[{"id":"1.232220323","rc":[{"batb":[[0,2.32,32.53],[1,1.9,998.13],[2,1.85,738.46]],"ltp":2.36,"tv":20.22,"id":891555}]}]}
{"op":"mcm","clk":"11915383761","pt":1724542012002,"mc":[{"id":"1.232220323","rc":[{"batb":[[0,2.34,5],[1,2.32,32.53],[2,1.9,998.13]],"ltp":2.36,"tv":20.22,"id":891555}]}]}
{"op":"mcm","clk":"11915383924","pt":1724542015309,"mc":[{"id":"1.232220323","rc":[{"batb":[[0,2.32,32.53],[1,1.9,998.13],[2,1.85,738.46]],"ltp":2.36,"tv":20.22,"id":891555}]}]}
{"op":"mcm","clk":"11915384034","pt":1724542017524,"mc":[{"id":"1.232220323","rc":[{"batb":[[0,2.34,5],[1,2.32,32.53],[2,1.9,998.13]],"ltp":2.36,"tv":20.22,"id":891555}]}]}
{"op":"mcm","clk":"11915384203","pt":1724542021022,"mc":[{"id":"1.232220323","rc":[{"batb":[[0,2.32,32.53],[1,1.9,998.13],[2,1.85,738.46]],"ltp":2.36,"tv":20.22,"id":891555}]}]}
{"op":"mcm","clk":"11915384326","pt":1724542023245,"mc":[{"id":"1.232220323","rc":[{"batb":[[0,2.34,5],[1,2.32,32.53],[2,1.9,998.13]],"ltp":2.36,"tv":20.22,"id":891555}]}]}
{"op":"mcm","clk":"11915384585","pt":1724542026753,"mc":[{"id":"1.232220323","rc":[{"batb":[[0,2.32,32.53],[1,1.9,998.13],[2,1.85,738.46]],"ltp":2.36,"tv":20.22,"id":891555}]}]}
{"op":"mcm","clk":"11915384757","pt":1724542030057,"mc":[{"id":"1.232220323","rc":[{"batb":[[0,2.34,5],[1,2.32,32.53],[2,1.9,998.13]],"ltp":2.36,"tv":20.22,"id":891555}]}]}
{"op":"mcm","clk":"11915384927","pt":1724542033564,"mc":[{"id":"1.232220323","rc":[{"batb":[[0,2.32,32.53],[1,1.9,998.13],[2,1.85,738.46]],"ltp":2.36,"tv":20.22,"id":891555}]}]}
{"op":"mcm","clk":"11915385032","pt":1724542035838,"mc":[{"id":"1.232220323","rc":[{"batb":[[0,2.34,5],[1,2.32,32.53],[2,1.9,998.13]],"ltp":2.36,"tv":20.22,"id":891555}]}]}
{"op":"mcm","clk":"11915385229","pt":1724542039354,"mc":[{"id":"1.232220323","rc":[{"batb":[[0,2.32,32.53],[1,1.9,998.13],[2,1.85,738.46]],"ltp":2.36,"tv":20.22,"id":891555}]}]}
{"op":"mcm","clk":"11915385344","pt":1724542041773,"mc":[{"id":"1.232220323","rc":[{"batb":[[0,2.34,5],[1,2.32,32.53],[2,1.9,998.13]],"ltp":2.36,"tv":20.22,"id":891555}]}]}
{"op":"mcm","clk":"11915385498","pt":1724542045073,"mc":[{"id":"1.232220323","rc":[{"batb":[[0,2.32,32.53],[1,1.9,998.13],[2,1.85,738.46]],"ltp":2.36,"tv":20.22,"id":891555}]}]}
{"op":"mcm","clk":"11915385608","pt":1724542047347,"mc":[{"id":"1.232220323","rc":[{"batb":[[0,2.34,5],[1,2.32,32.53],[2,1.9,998.13]],"ltp":2.36,"tv":20.22,"id":891555}]}]}
{"op":"mcm","clk":"11915385803","pt":1724542050590,"mc":[{"id":"1.232220323","rc":[{"batb":[[0,2.32,32.53],[1,1.9,998.13],[2,1.85,738.46]],"ltp":2.36,"tv":20.22,"id":891555}]}]}
{"op":"mcm","clk":"11915385920","pt":1724542052965,"mc":[{"id":"1.232220323","rc":[{"batb":[[0,2.34,5],[1,2.32,32.53],[2,1.9,998.13]],"ltp":2.36,"tv":20.22,"id":891555}]}]}
{"op":"mcm","clk":"11915386098","pt":1724542056372,"mc":[{"id":"1.232220323","rc":[{"batb":[[0,2.32,32.53],[1,1.9,998.13],[2,1.85,738.46]],"ltp":2.36,"tv":20.22,"id":891555}]}]}
{"op":"mcm","clk":"11915386239","pt":1724542059190,"mc":[{"id":"1.232220323","rc":[{"batb":[[0,2.34,5],[1,2.32,32.53],[2,1.9,998.13]],"ltp":2.36,"tv":20.22,"id":891555}]}]}
{"op":"mcm","clk":"11915386410","pt":1724542062484,"mc":[{"id":"1.232220323","rc":[{"batb":[[0,2.32,32.53],[1,1.9,998.13],[2,1.85,738.46]],"ltp":2.36,"tv":20.22,"id":891555}]}]}
{"op":"mcm","clk":"11915386524","pt":1724542064877,"mc":[{"id":"1.232220323","rc":[{"batb":[[0,2.34,5],[1,2.32,32.53],[2,1.9,998.13]],"ltp":2.36,"tv":20.22,"id":891555}]}]}
{"op":"mcm","clk":"11915386683","pt":1724542068070,"mc":[{"id":"1.232220323","rc":[{"batb":[[0,2.32,32.53],[1,1.9,998.13],[2,1.85,738.46]],"ltp":2.36,"tv":20.22,"id":891555}]}]}
{"op":"mcm","clk":"11915386812","pt":1724542070490,"mc":[{"id":"1.232220323","rc":[{"batb":[[0,2.34,5],[1,2.32,32.53],[2,1.9,998.13]],"ltp":2.36,"tv":20.22,"id":891555}]}]}
{"op":"mcm","clk":"11915386966","pt":1724542074001,"mc":[{"id":"1.232220323","rc":[{"batb":[[0,2.32,32.53],[1,1.9,998.13],[2,1.85,738.46]],"ltp":2.36,"tv":20.22,"id":891555}]}]}
{"op":"mcm","clk":"11915387115","pt":1724542076402,"mc":[{"id":"1.232220323","rc":[{"batb":[[0,2.34,5],[1,2.32,32.53],[2,1.9,998.13]],"ltp":2.36,"tv":20.22,"id":891555}]}]}
{"op":"mcm","clk":"11915387271","pt":1724542079590,"mc":[{"id":"1.232220323","rc":[{"batb":[[0,2.32,32.53],[1,1.9,998.13],[2,1.85,738.46]],"ltp":2.36,"tv":20.22,"id":891555}]}]}
{"op":"mcm","clk":"11915387393","pt":1724542082117,"mc":[{"id":"1.232220323","rc":[{"batb":[[0,2.34,5],[1,2.32,32.53],[2,1.9,998.13]],"ltp":2.36,"tv":20.22,"id":891555}]}]}
{"op":"mcm","clk":"11915387596","pt":1724542085401,"mc":[{"id":"1.232220323","rc":[{"batb":[[0,2.32,32.53],[1,1.9,998.13],[2,1.85,738.46]],"ltp":2.36,"tv":20.22,"id":891555}]}]}
{"op":"mcm","clk":"11915387725","pt":1724542087711,"mc":[{"id":"1.232220323","rc":[{"batb":[[0,2.34,5],[1,2.32,32.53],[2,1.9,998.13]],"ltp":2.36,"tv":20.22,"id":891555}]}]}
{"op":"mcm","clk":"11915387960","pt":1724542091620,"mc":[{"id":"1.232220323","rc":[{"batb":[[0,2.32,32.53],[1,1.9,998.13],[2,1.85,738.46]],"ltp":2.36,"tv":20.22,"id":891555}]}]}
{"op":"mcm","clk":"11915388101","pt":1724542093798,"mc":[{"id":"1.232220323","rc":[{"batb":[[0,2.34,5],[1,2.32,32.53],[2,1.9,998.13]],"ltp":2.36,"tv":20.22,"id":891555}]}]}
{"op":"mcm","clk":"11915388310","pt":1724542097336,"mc":[{"id":"1.232220323","rc":[{"batb":[[0,2.32,32.53],[1,1.9,998.13],[2,1.85,738.46]],"ltp":2.36,"tv":20.22,"id":891555}]}]}
{"op":"mcm","clk":"11915388436","pt":1724542099401,"mc":[{"id":"1.232220323","rc":[{"batb":[[0,2.34,5],[1,2.32,32.53],[2,1.9,998.13]],"ltp":2.36,"tv":20.22,"id":891555}]}]}
{"op":"mcm","clk":"11915388613","pt":1724542102703,"mc":[{"id":"1.232220323","rc":[{"batb":[[0,2.32,32.53],[1,1.9,998.13],[2,1.85,738.46]],"ltp":2.36,"tv":20.22,"id":891555}]}]}
{"op":"mcm","clk":"11915388795","pt":1724542105935,"mc":[{"id":"1.232220323","rc":[{"batb":[[0,2.34,5],[1,2.32,32.53],[2,1.9,998.13]],"ltp":2.36,"tv":20.22,"id":891555}]}]}
{"op":"mcm","clk":"11915388973","pt":1724542109419,"mc":[{"id":"1.232220323","rc":[{"batb":[[0,2.32,32.53],[1,1.9,998.13],[2,1.85,738.46]],"ltp":2.36,"tv":20.22,"id":891555}]}]}
{"op":"mcm","clk":"11915389104","pt":1724542111529,"mc":[{"id":"1.232220323","rc":[{"batb":[[0,2.34,5],[1,2.32,32.53],[2,1.9,998.13]],"ltp":2.36,"tv":20.22,"id":891555}]}]}
{"op":"mcm","clk":"11915389268","pt":1724542114819,"mc":[{"id":"1.232220323","rc":[{"batb":[[0,2.32,32.53],[1,1.9,998.13],[2,1.85,738.46]],"ltp":2.36,"tv":20.22,"id":891555}]}]}
{"op":"mcm","clk":"11915389382","pt":1724542117134,"mc":[{"id":"1.232220323","rc":[{"batb":[[0,2.34,5],[1,2.32,32.53],[2,1.9,998.13]],"ltp":2.36,"tv":20.22,"id":891555}]}]}
{"op":"mcm","clk":"11915389551","pt":1724542120564,"mc":[{"id":"1.232220323","rc":[{"batb":[[0,2.32,32.53],[1,1.9,998.13],[2,1.85,738.46]],"ltp":2.36,"tv":20.22,"id":891555}]}]}
{"op":"mcm","clk":"11915389677","pt":1724542122775,"mc":[{"id":"1.232220323","rc":[{"batb":[[0,2.34,5],[1,2.32,32.53],[2,1.9,998.13]],"ltp":2.36,"tv":20.22,"id":891555}]}]}
{"op":"mcm","clk":"11915389863","pt":1724542126278,"mc":[{"id":"1.232220323","rc":[{"batb":[[0,2.32,32.53],[1,1.9,998.13],[2,1.85,738.46]],"ltp":2.36,"tv":20.22,"id":891555}]}]}
{"op":"mcm","clk":"11915389983","pt":1724542128440,"mc":[{"id":"1.232220323","rc":[{"batb":[[0,2.34,5],[1,2.32,32.53],[2,1.9,998.13]],"ltp":2.36,"tv":20.22,"id":891555}]}]}
{"op":"mcm","clk":"11915390159","pt":1724542131983,"mc":[{"id":"1.232220323","rc":[{"batb":[[0,2.32,32.53],[1,1.9,998.13],[2,1.85,738.46]],"ltp":2.36,"tv":20.22,"id":891555}]}]}
{"op":"mcm","clk":"11915390334","pt":1724542135273,"mc":[{"id":"1.232220323","rc":[{"batb":[[0,2.34,5],[1,2.32,32.53],[2,1.9,998.13]],"ltp":2.36,"tv":20.22,"id":891555}]}]}
{"op":"mcm","clk":"11915390501","pt":1724542138568,"mc":[{"id":"1.232220323","rc":[{"batb":[[0,2.32,32.53],[1,1.9,998.13],[2,1.85,738.46]],"ltp":2.36,"tv":20.22,"id":891555}]}]}
{"op":"mcm","clk":"11915390604","pt":1724542140684,"mc":[{"id":"1.232220323","rc":[{"batb":[[0,2.34,5],[1,2.32,32.53],[2,1.9,998.13]],"ltp":2.36,"tv":20.22,"id":891555}]}]}
{"op":"mcm","clk":"11915390835","pt":1724542144158,"mc":[{"id":"1.232220323","rc":[{"batb":[[0,2.32,32.53],[1,1.9,998.13],[2,1.85,738.46]],"ltp":2.36,"tv":20.22,"id":891555}]}]}
{"op":"mcm","clk":"11915390962","pt":1724542146295,"mc":[{"id":"1.232220323","rc":[{"batb":[[0,2.34,5],[1,2.32,32.53],[2,1.9,998.13]],"ltp":2.36,"tv":20.22,"id":891555}]}]}
{"op":"mcm","clk":"11915391178","pt":1724542149600,"mc":[{"id":"1.232220323","rc":[{"batb":[[0,2.32,32.53],[1,1.9,998.13],[2,1.85,738.46]],"ltp":2.36,"tv":20.22,"id":891555}]}]}
{"op":"mcm","clk":"11915391346","pt":1724542152073,"mc":[{"id":"1.232220323","rc":[{"batb":[[0,2.34,5],[1,2.32,32.53],[2,1.9,998.13]],"ltp":2.36,"tv":20.22,"id":891555}]}]}
{"op":"mcm","clk":"11915391558","pt":1724542155607,"mc":[{"id":"1.232220323","rc":[{"batb":[[0,2.32,32.53],[1,1.9,998.13],[2,1.85,738.46]],"ltp":2.36,"tv":20.22,"id":891555}]}]}
{"op":"mcm","clk":"11915391720","pt":1724542158088,"mc":[{"id":"1.232220323","rc":[{"batb":[[0,2.34,5],[1,2.32,32.53],[2,1.9,998.13]],"ltp":2.36,"tv":20.22,"id":891555}]}]}
{"op":"mcm","clk":"11915391903","pt":1724542161631,"mc":[{"id":"1.232220323","rc":[{"batb":[[0,2.32,32.53],[1,1.9,998.13],[2,1.85,738.46]],"ltp":2.36,"tv":20.22,"id":891555}]}]}
{"op":"mcm","clk":"11915392064","pt":1724542165031,"mc":[{"id":"1.232220323","rc":[{"batb":[[0,2.34,5],[1,2.32,32.53],[2,1.9,998.13]],"ltp":2.36,"tv":20.22,"id":891555}]}]}
{"op":"mcm","clk":"11915392247","pt":1724542168321,"mc":[{"id":"1.232220323","rc":[{"batb":[[0,2.32,32.53],[1,1.9,998.13],[2,1.85,738.46]],"ltp":2.36,"tv":20.22,"id":891555}]}]}
{"op":"mcm","clk":"11915392381","pt":1724542170631,"mc":[{"id":"1.232220323","rc":[{"batb":[[0,2.34,5],[1,2.32,32.53],[2,1.9,998.13]],"ltp":2.36,"tv":20.22,"id":891555}]}]}
{"op":"mcm","clk":"11915392587","pt":1724542174131,"mc":[{"id":"1.232220323","rc":[{"batb":[[0,2.32,32.53],[1,1.9,998.13],[2,1.85,738.46]],"ltp":2.36,"tv":20.22,"id":891555}]}]}
{"op":"mcm","clk":"11915392712","pt":1724542176651,"mc":[{"id":"1.232220323","rc":[{"batb":[[0,2.34,5],[1,2.32,32.53],[2,1.9,998.13]],"ltp":2.36,"tv":20.22,"id":891555}]}]}
{"op":"mcm","clk":"11915392867","pt":1724542179939,"mc":[{"id":"1.232220323","rc":[{"batb":[[0,2.32,32.53],[1,1.9,998.13],[2,1.85,738.46]],"ltp":2.36,"tv":20.22,"id":891555}]}]}
{"op":"mcm","clk":"11915392993","pt":1724542182349,"mc":[{"id":"1.232220323","rc":[{"batb":[[0,2.34,5],[1,2.32,32.53],[2,1.9,998.13]],"ltp":2.36,"tv":20.22,"id":891555}]}]}
{"op":"mcm","clk":"11915393157","pt":1724542185848,"mc":[{"id":"1.232220323","rc":[{"batb":[[0,2.32,32.53],[1,1.9,998.13],[2,1.85,738.46]],"ltp":2.36,"tv":20.22,"id":891555}]}]}
{"op":"mcm","clk":"11915393272","pt":1724542188257,"mc":[{"id":"1.232220323","rc":[{"batb":[[0,2.34,5],[1,2.32,32.53],[2,1.9,998.13]],"ltp":2.36,"tv":20.22,"id":891555}]}]}
{"op":"mcm","clk":"11915393443","pt":1724542191548,"mc":[{"id":"1.232220323","rc":[{"batb":[[0,2.32,32.53],[1,1.9,998.13],[2,1.85,738.46]],"ltp":2.36,"tv":20.22,"id":891555}]}]}
{"op":"mcm","clk":"11915393559","pt":1724542194142,"mc":[{"id":"1.232220323","rc":[{"batb":[[0,2.34,5],[1,2.32,32.53],[2,1.9,998.13]],"ltp":2.36,"tv":20.22,"id":891555}]}]}
{"op":"mcm","clk":"11915393692","pt":1724542197560,"mc":[{"id":"1.232220323","rc":[{"batb":[[0,2.32,32.53],[1,1.9,998.13],[2,1.85,738.46]],"ltp":2.36,"tv":20.22,"id":891555}]}]}
{"op":"mcm","clk":"11915393797","pt":1724542199936,"mc":[{"id":"1.232220323","rc":[{"batb":[[0,2.34,5],[1,2.32,32.53],[2,1.9,998.13]],"ltp":2.36,"tv":20.22,"id":891555}]}]}
{"op":"mcm","clk":"11915394014","pt":1724542203259,"mc":[{"id":"1.232220323","rc":[{"batb":[[0,2.32,32.53],[1,1.9,998.13],[2,1.85,738.46]],"ltp":2.36,"tv":20.22,"id":891555}]}]}
{"op":"mcm","clk":"11915394195","pt":1724542205660,"mc":[{"id":"1.232220323","rc":[{"batb":[[0,2.34,5],[1,2.32,32.53],[2,1.9,998.13]],"ltp":2.36,"tv":20.22,"id":891555}]}]}
{"op":"mcm","clk":"11915394412","pt":1724542209046,"mc":[{"id":"1.232220323","rc":[{"batb":[[0,2.32,32.53],[1,1.9,998.13],[2,1.85,738.46]],"ltp":2.36,"tv":20.22,"id":891555}]}]}
{"op":"mcm","clk":"11915394593","pt":1724542211749,"mc":[{"id":"1.232220323","rc":[{"batb":[[0,2.34,5],[1,2.32,32.53],[2,1.9,998.13]],"ltp":2.36,"tv":20.22,"id":891555}]}]}
{"op":"mcm","clk":"11915394848","pt":1724542215193,"mc":[{"id":"1.232220323","rc":[{"batb":[[0,2.32,32.53],[1,1.9,998.13],[2,1.85,738.46]],"ltp":2.36,"tv":20.22,"id":891555}]}]}
{"op":"mcm","clk":"11915395048","pt":1724542217476,"mc":[{"id":"1.232220323","rc":[{"batb":[[0,2.34,5],[1,2.32,32.53],[2,1.9,998.13]],"ltp":2.36,"tv":20.22,"id":891555}]}]}
{"op":"mcm","clk":"11915395341","pt":1724542220701,"mc":[{"id":"1.232220323","rc":[{"batb":[[0,2.32,32.53],[1,1.9,998.13],[2,1.85,738.46]],"ltp":2.36,"tv":20.22,"id":891555}]}]}
{"op":"mcm","clk":"11915395527","pt":1724542223098,"mc":[{"id":"1.232220323","rc":[{"batb":[[0,2.34,5],[1,2.32,32.53],[2,1.9,998.13]],"ltp":2.36,"tv":20.22,"id":891555}]}]}
{"op":"mcm","clk":"11915395790","pt":1724542226566,"mc":[{"id":"1.232220323","rc":[{"batb":[[0,2.32,32.53],[1,1.9,998.13],[2,1.85,738.46]],"ltp":2.36,"tv":20.22,"id":891555}]}]}
{"op":"mcm","clk":"11915395931","pt":1724542228886,"mc":[{"id":"1.232220323","rc":[{"batb":[[0,2.34,5],[1,2.32,32.53],[2,1.9,998.13]],"ltp":2.36,"tv":20.22,"id":891555}]}]}
{"op":"mcm","clk":"11915396137","pt":1724542232366,"mc":[{"id":"1.232220323","rc":[{"batb":[[0,2.32,32.53],[1,1.9,998.13],[2,1.85,738.46]],"ltp":2.36,"tv":20.22,"id":891555}]}]}
{"op":"mcm","clk":"11915396322","pt":1724542235310,"mc":[{"id":"1.232220323","rc":[{"batb":[[0,2.34,5],[1,2.32,32.53],[2,1.9,998.13]],"ltp":2.36,"tv":20.22,"id":891555}]}]}
{"op":"mcm","clk":"11915396498","pt":1724542238710,"mc":[{"id":"1.232220323","rc":[{"batb":[[0,2.32,32.53],[1,1.9,998.13],[2,1.85,738.46]],"ltp":2.36,"tv":20.22,"id":891555}]}]}
{"op":"mcm","clk":"11915396598","pt":1724542240974,"mc":[{"id":"1.232220323","rc":[{"batb":[[0,2.34,5],[1,2.32,32.53],[2,1.9,998.13]],"ltp":2.36,"tv":20.22,"id":891555}]}]}
{"op":"mcm","clk":"11915396759","pt":1724542244186,"mc":[{"id":"1.232220323","rc":[{"batb":[[0,2.32,32.53],[1,1.9,998.13],[2,1.85,738.46]],"ltp":2.36,"tv":20.22,"id":891555}]}]}
{"op":"mcm","clk":"11915396884","pt":1724542246902,"mc":[{"id":"1.232220323","rc":[{"batb":[[0,2.34,5],[1,2.32,32.53],[2,1.9,998.13]],"ltp":2.36,"tv":20.22,"id":891555}]}]}
{"op":"mcm","clk":"11915397076","pt":1724542250400,"mc":[{"id":"1.232220323","rc":[{"batb":[[0,2.32,32.53],[1,1.9,998.13],[2,1.85,738.46]],"ltp":2.36,"tv":20.22,"id":891555}]}]}
{"op":"mcm","clk":"11915397215","pt":1724542253331,"mc":[{"id":"1.232220323","rc":[{"batb":[[0,2.34,5],[1,2.32,32.53],[2,1.9,998.13]],"ltp":2.36,"tv":20.22,"id":891555}]}]}
{"op":"mcm","clk":"11915397399","pt":1724542256736,"mc":[{"id":"1.232220323","rc":[{"batb":[[0,2.32,32.53],[1,1.9,998.13],[2,1.85,738.46]],"ltp":2.36,"tv":20.22,"id":891555}]}]}
{"op":"mcm","clk":"11915397551","pt":1724542259418,"mc":[{"id":"1.232220323","rc":[{"batb":[[0,2.34,5],[1,2.32,32.53],[2,1.9,998.13]],"ltp":2.36,"tv":20.22,"id":891555}]}]}
{"op":"mcm","clk":"11915397738","pt":1724542262715,"mc":[{"id":"1.232220323","rc":[{"batb":[[0,2.32,32.53],[1,1.9,998.13],[2,1.85,738.46]],"ltp":2.36,"tv":20.22,"id":891555}]}]}
{"op":"mcm","clk":"11915397971","pt":1724542265612,"mc":[{"id":"1.232220323","rc":[{"batb":[[0,2.34,5],[1,2.32,32.53],[2,1.9,998.13]],"ltp":2.36,"tv":20.22,"id":891555}]}]}
{"op":"mcm","clk":"11915398292","pt":1724542269105,"mc":[{"id":"1.232220323","rc":[{"batb":[[0,2.32,32.53],[1,1.9,998.13],[2,1.85,738.46]],"ltp":2.36,"tv":20.22,"id":891555}]}]}
{"op":"mcm","clk":"11915398509","pt":1724542272452,"mc":[{"id":"1.232220323","rc":[{"batb":[[0,2.34,5],[1,2.32,32.53],[2,1.9,998.13]],"ltp":2.36,"tv":20.22,"id":891555}]}]}
{"op":"mcm","clk":"11915398700","pt":1724542275741,"mc":[{"id":"1.232220323","rc":[{"batb":[[0,2.32,32.53],[1,1.9,998.13],[2,1.85,738.46]],"ltp":2.36,"tv":20.22,"id":891555}]}]}
{"op":"mcm","clk":"11915398816","pt":1724542278157,"mc":[{"id":"1.232220323","rc":[{"batb":[[0,2.34,5],[1,2.32,32.53],[2,1.9,998.13]],"ltp":2.36,"tv":20.22,"id":891555}]}]}
{"op":"mcm","clk":"11915398958","pt":1724542281449,"mc":[{"id":"1.232220323","rc":[{"batb":[[0,2.32,32.53],[1,1.9,998.13],[2,1.85,738.46]],"ltp":2.36,"tv":20.22,"id":891555}]}]}
{"op":"mcm","clk":"11915399065","pt":1724542283716,"mc":[{"id":"1.232220323","rc":[{"batb":[[0,2.34,5],[1,2.32,32.53],[2,1.9,998.13]],"ltp":2.36,"tv":20.22,"id":891555}]}]}
{"op":"mcm","clk":"11915399196","pt":1724542287058,"mc":[{"id":"1.232220323","rc":[{"batb":[[0,2.32,32.53],[1,1.9,998.13],[2,1.85,738.46]],"ltp":2.36,"tv":20.22,"id":891555}]}]}
{"op":"mcm","clk":"11915399344","pt":1724542289467,"mc":[{"id":"1.232220323","rc":[{"batb":[[0,2.34,5],[1,2.32,32.53],[2,1.9,998.13]],"ltp":2.36,"tv":20.22,"id":891555}]}]}
{"op":"mcm","clk":"11915399499","pt":1724542292756,"mc":[{"id":"1.232220323","rc":[{"batb":[[0,2.32,32.53],[1,1.9,998.13],[2,1.85,738.46]],"ltp":2.36,"tv":20.22,"id":891555}]}]}
{"op":"mcm","clk":"11915399626","pt":1724542295034,"mc":[{"id":"1.232220323","rc":[{"batb":[[0,2.34,5],[1,2.32,32.53],[2,1.9,998.13]],"ltp":2.36,"tv":20.22,"id":891555}]}]}
{"op":"mcm","clk":"11915399824","pt":1724542298342,"mc":[{"id":"1.232220323","rc":[{"batb":[[0,2.32,32.53],[1,1.9,998.13],[2,1.85,738.46]],"ltp":2.36,"tv":20.22,"id":891555}]}]}
{"op":"mcm","clk":"11915399939","pt":1724542300754,"mc":[{"id":"1.232220323","rc":[{"batb":[[0,2.34,5],[1,2.32,32.53],[2,1.9,998.13]],"ltp":2.36,"tv":20.22,"id":891555}]}]}
{"op":"mcm","clk":"11915400067","pt":1724542304082,"mc":[{"id":"1.232220323","rc":[{"batb":[[0,2.32,32.53],[1,1.9,998.13],[2,1.85,738.46]],"ltp":2.36,"tv":20.22,"id":891555}]}]}
{"op":"mcm","clk":"11915400170","pt":1724542306447,"mc":[{"id":"1.232220323","rc":[{"batb":[[0,2.34,5],[1,2.32,32.53],[2,1.9,998.13]],"ltp":2.36,"tv":20.22,"id":891555}]}]}
{"op":"mcm","clk":"11915400351","pt":1724542310062,"mc":[{"id":"1.232220323","rc":[{"batb":[[0,2.32,32.53],[1,1.9,998.13],[2,1.85,738.46]],"ltp":2.36,"tv":20.22,"id":891555}]}]}
{"op":"mcm","clk":"11915400497","pt":1724542312587,"mc":[{"id":"1.232220323","rc":[{"batb":[[0,2.34,5],[1,2.32,32.53],[2,1.9,998.13]],"ltp":2.36,"tv":20.22,"id":891555}]}]}
{"op":"mcm","clk":"11915400664","pt":1724542315892,"mc":[{"id":"1.232220323","rc":[{"batb":[[0,2.32,32.53],[1,1.9,998.13],[2,1.85,738.46]],"ltp":2.36,"tv":20.22,"id":891555}]}]}
{"op":"mcm","clk":"11915400833","pt":1724542318484,"mc":[{"id":"1.232220323","rc":[{"batb":[[0,2.34,5],[1,2.32,32.53],[2,1.9,998.13]],"ltp":2.36,"tv":20.22,"id":891555}]}]}
{"op":"mcm","clk":"11915401012","pt":1724542321796,"mc":[{"id":"1.232220323","rc":[{"batb":[[0,2.32,32.53],[1,1.9,998.13],[2,1.85,738.46]],"ltp":2.36,"tv":20.22,"id":891555}]}]}
{"op":"mcm","clk":"11915401130","pt":1724542324173,"mc":[{"id":"1.232220323","rc":[{"batb":[[0,2.34,5],[1,2.32,32.53],[2,1.9,998.13]],"ltp":2.36,"tv":20.22,"id":891555}]}]}
{"op":"mcm","clk":"11915401303","pt":1724542327371,"mc":[{"id":"1.232220323","rc":[{"batb":[[0,2.32,32.53],[1,1.9,998.13],[2,1.85,738.46]],"ltp":2.36,"tv":20.22,"id":891555}]}]}
{"op":"mcm","clk":"11915401438","pt":1724542330007,"mc":[{"id":"1.232220323","rc":[{"batb":[[0,2.34,5],[1,2.32,32.53],[2,1.9,998.13]],"ltp":2.36,"tv":20.22,"id":891555}]}]}
{"op":"mcm","clk":"11915401596","pt":1724542333309,"mc":[{"id":"1.232220323","rc":[{"batb":[[0,2.32,32.53],[1,1.9,998.13],[2,1.85,738.46]],"ltp":2.36,"tv":20.22,"id":891555}]}]}
{"op":"mcm","clk":"11915401689","pt":1724542335578,"mc":[{"id":"1.232220323","rc":[{"batb":[[0,2.34,5],[1,2.32,32.53],[2,1.9,998.13]],"ltp":2.36,"tv":20.22,"id":891555}]}]}
{"op":"mcm","clk":"11915401835","pt":1724542338774,"mc":[{"id":"1.232220323","rc":[{"batb":[[0,2.32,32.53],[1,1.9,998.13],[2,1.85,738.46]],"ltp":2.36,"tv":20.22,"id":891555}]}]}
{"op":"mcm","clk":"11915401939","pt":1724542341392,"mc":[{"id":"1.232220323","rc":[{"batb":[[0,2.34,5],[1,2.32,32.53],[2,1.9,998.13]],"ltp":2.36,"tv":20.22,"id":891555}]}]}
{"op":"mcm","clk":"11915402063","pt":1724542344683,"mc":[{"id":"1.232220323","rc":[{"batb":[[0,2.32,32.53],[1,1.9,998.13],[2,1.85,738.46]],"ltp":2.36,"tv":20.22,"id":891555}]}]}
{"op":"mcm","clk":"11915402129","pt":1724542346999,"mc":[{"id":"1.232220323","rc":[{"batb":[[0,2.34,5],[1,2.32,32.53],[2,1.9,998.13]],"ltp":2.36,"tv":20.22,"id":891555}]}]}
{"op":"mcm","clk":"11915402271","pt":1724542350216,"mc":[{"id":"1.232220323","rc":[{"batb":[[0,2.32,32.53],[1,1.9,998.13],[2,1.85,738.46]],"ltp":2.36,"tv":20.22,"id":891555}]}]}
{"op":"mcm","clk":"11915402383","pt":1724542352607,"mc":[{"id":"1.232220323","rc":[{"batb":[[0,2.34,5],[1,2.32,32.53],[2,1.9,998.13]],"ltp":2.36,"tv":20.22,"id":891555}]}]}
{"op":"mcm","clk":"11915402544","pt":1724542355801,"mc":[{"id":"1.232220323","rc":[{"batb":[[0,2.32,32.53],[1,1.9,998.13],[2,1.85,738.46]],"ltp":2.36,"tv":20.22,"id":891555}]}]}
{"op":"mcm","clk":"11915402677","pt":1724542358429,"mc":[{"id":"1.232220323","rc":[{"batb":[[0,2.34,5],[1,2.32,32.53],[2,1.9,998.13]],"ltp":2.36,"tv":20.22,"id":891555}]}]}
{"op":"mcm","clk":"11915402828","pt":1724542361808,"mc":[{"id":"1.232220323","rc":[{"batb":[[0,2.32,32.53],[1,1.9,998.13],[2,1.85,738.46]],"ltp":2.36,"tv":20.22,"id":891555}]}]}
{"op":"mcm","clk":"11915402928","pt":1724542364103,"mc":[{"id":"1.232220323","rc":[{"batb":[[0,2.34,5],[1,2.32,32.53],[2,1.9,998.13]],"ltp":2.36,"tv":20.22,"id":891555}]}]}
{"op":"mcm","clk":"11915403061","pt":1724542367341,"mc":[{"id":"1.232220323","rc":[{"batb":[[0,2.32,32.53],[1,1.9,998.13],[2,1.85,738.46]],"ltp":2.36,"tv":20.22,"id":891555}]}]}
{"op":"mcm","clk":"11915403168","pt":1724542369807,"mc":[{"id":"1.232220323","rc":[{"batb":[[0,2.34,5],[1,2.32,32.53],[2,1.9,998.13]],"ltp":2.36,"tv":20.22,"id":891555}]}]}
{"op":"mcm","clk":"11915403324","pt":1724542373210,"mc":[{"id":"1.232220323","rc":[{"batb":[[0,2.32,32.53],[1,1.9,998.13],[2,1.85,738.46]],"ltp":2.36,"tv":20.22,"id":891555}]}]}
{"op":"mcm","clk":"11915403410","pt":1724542375547,"mc":[{"id":"1.232220323","rc":[{"batb":[[0,2.34,5],[1,2.32,32.53],[2,1.9,998.13]],"ltp":2.36,"tv":20.22,"id":891555}]}]}
{"op":"mcm","clk":"11915403536","pt":1724542378942,"mc":[{"id":"1.232220323","rc":[{"batb":[[0,2.32,32.53],[1,1.9,998.13],[2,1.85,738.46]],"ltp":2.36,"tv":20.22,"id":891555}]}]}
{"op":"mcm","clk":"11915403665","pt":1724542381432,"mc":[{"id":"1.232220323","rc":[{"batb":[[0,2.34,5],[1,2.32,32.53],[2,1.9,998.13]],"ltp":2.36,"tv":20.22,"id":891555}]}]}
{"op":"mcm","clk":"11915403833","pt":1724542384834,"mc":[{"id":"1.232220323","rc":[{"batb":[[0,2.32,32.53],[1,1.9,998.13],[2,1.85,738.46]],"ltp":2.36,"tv":20.22,"id":891555}]}]}
{"op":"mcm","clk":"11915403931","pt":1724542387147,"mc":[{"id":"1.232220323","rc":[{"batb":[[0,2.34,5],[1,2.32,32.53],[2,1.9,998.13]],"ltp":2.36,"tv":20.22,"id":891555}]}]}
{"op":"mcm","clk":"11915404089","pt":1724542390433,"mc":[{"id":"1.232220323","rc":[{"batb":[[0,2.32,32.53],[1,1.9,998.13],[2,1.85,738.46]],"ltp":2.36,"tv":20.22,"id":891555}]}]}
{"op":"mcm","clk":"11915404213","pt":1724542392744,"mc":[{"id":"1.232220323","rc":[{"batb":[[0,2.34,5],[1,2.32,32.53],[2,1.9,998.13]],"ltp":2.36,"tv":20.22,"id":891555}]}]}
{"op":"mcm","clk":"11915404387","pt":1724542396048,"mc":[{"id":"1.232220323","rc":[{"batb":[[0,2.32,32.53],[1,1.9,998.13],[2,1.85,738.46]],"ltp":2.36,"tv":20.22,"id":891555}]}]}
{"op":"mcm","clk":"11915404487","pt":1724542398371,"mc":[{"id":"1.232220323","rc":[{"batb":[[0,2.34,5],[1,2.32,32.53],[2,1.9,998.13]],"ltp":2.36,"tv":20.22,"id":891555}]}]}
{"op":"mcm","clk":"11915404611","pt":1724542401660,"mc":[{"id":"1.232220323","rc":[{"batb":[[0,2.32,32.53],[1,1.9,998.13],[2,1.85,738.46]],"ltp":2.36,"tv":20.22,"id":891555}]}]}
{"op":"mcm","clk":"11915404689","pt":1724542404038,"mc":[{"id":"1.232220323","rc":[{"batb":[[0,2.34,5],[1,2.32,32.53],[2,1.9,998.13]],"ltp":2.36,"tv":20.22,"id":891555}]}]}
{"op":"mcm","clk":"11915404839","pt":1724542407457,"mc":[{"id":"1.232220323","rc":[{"batb":[[0,2.32,32.53],[1,1.9,998.13],[2,1.85,738.46]],"ltp":2.36,"tv":20.22,"id":891555}]}]}
{"op":"mcm","clk":"11915404951","pt":1724542409771,"mc":[{"id":"1.232220323","rc":[{"batb":[[0,2.34,5],[1,2.32,32.53],[2,1.9,998.13]],"ltp":2.36,"tv":20.22,"id":891555}]}]}
{"op":"mcm","clk":"11915405081","pt":1724542413056,"mc":[{"id":"1.232220323","rc":[{"batb":[[0,2.32,32.53],[1,1.9,998.13],[2,1.85,738.46]],"ltp":2.36,"tv":20.22,"id":891555}]}]}
{"op":"mcm","clk":"11915405171","pt":1724542415369,"mc":[{"id":"1.232220323","rc":[{"batb":[[0,2.34,5],[1,2.32,32.53],[2,1.9,998.13]],"ltp":2.36,"tv":20.22,"id":891555}]}]}
{"op":"mcm","clk":"11915405316","pt":1724542418651,"mc":[{"id":"1.232220323","rc":[{"batb":[[0,2.32,32.53],[1,1.9,998.13],[2,1.85,738.46]],"ltp":2.36,"tv":20.22,"id":891555}]}]}
{"op":"mcm","clk":"11915405433","pt":1724542421168,"mc":[{"id":"1.232220323","rc":[{"batb":[[0,2.34,5],[1,2.32,32.53],[2,1.9,998.13]],"ltp":2.36,"tv":20.22,"id":891555}]}]}
