{"op":"mcm","clk":"11882181845","pt":1724157623126,"mc":[{"id":"1.232050243","marketDefinition":{"bspMarket":false,"turnInPlayEnabled":true,"persistenceEnabled":true,"marketBaseRate":5.0,"eventId":"33511212","eventTypeId":"4","numberOfWinners":1,"bettingType":"ODDS","marketType":"MATCH_ODDS","marketTime":"2024-08-21T19:00:00.000Z","suspendTime":"2024-08-21T19:00:00.000Z","bspReconciled":false,"complete":true,"inPlay":false,"crossMatching":true,"runnersVoidable":false,"numberOfActiveRunners":2,"betDelay":0,"status":"OPEN","runners":[{"status":"ACTIVE","sortPriority":1,"id":72857117,"name":"Caribbean Giants"},{"status":"ACTIVE","sortPriority":2,"id":72857116,"name":"Grand Cayman Stingrays"}],"regulators":["MR_INT"],"countryCode":"GB","discountAllowed":false,"timezone":"GMT","openDate":"2024-08-21T19:00:00.000Z","version":6087507540,"name":"Match Odds","eventName":"Caribbean Giants v Grand Cayman Stingrays"},"rc":[{"batb":[[0,1.03,200],[1,1.02,200],[2,1.01,220]],"ltp":0.0,"tv":0.0,"id":72857116},{"batb":[[0,1.03,200],[1,1.02,200],[2,1.01,220]],"ltp":0.0,"tv":0.0,"id":72857117}]}]}
{"op":"mcm","clk":"11882181928","pt":1724157624196,"mc":[{"id":"1.232050243","marketDefinition":{"bspMarket":false,"turnInPlayEnabled":true,"persistenceEnabled":true,"marketBaseRate":5.0,"eventId":"33511212","eventTypeId":"4","numberOfWinners":1,"bettingType":"ODDS","marketType":"MATCH_ODDS","marketTime":"2024-08-21T19:00:00.000Z","suspendTime":"2024-08-21T19:00:00.000Z","bspReconciled":false,"complete":true,"inPlay":false,"crossMatching":true,"runnersVoidable":false,"numberOfActiveRunners":2,"betDelay":0,"status":"OPEN","runners":[{"status":"ACTIVE","sortPriority":1,"id":72857117,"name":"Caribbean Giants"},{"status":"ACTIVE","sortPriority":2,"id":72857116,"name":"Grand Cayman Stingrays"}],"regulators":["MR_INT"],"countryCode":"GB","discountAllowed":true,"timezone":"GMT","openDate":"2024-08-21T19:00:00.000Z","version":6087507540,"name":"Match Odds","eventName":"Caribbean Giants v Grand Cayman Stingrays"}}]}
{"op":"mcm","clk":"11882254435","pt":1724158549470,"mc":[{"id":"1.232050243","rc":[{"batb":[[0,1.03,200.54]],"ltp":0.0,"tv":0.0,"id":72857117}]}]}
{"op":"mcm","clk":"11882255131","pt":1724158559518,"mc":[{"id":"1.232050243","rc":[{"batb":[[0,1.03,200.54]],"ltp":0.0,"tv":0.0,"id":72857116}]}]}
{"op":"mcm","clk":"11882457660","pt":1724160663038,"mc":[{"id":"1.232050243","rc":[{"batb":[[2,1.01,481.95]],"ltp":0.0,"tv":0.0,"id":72857117}]}]}
{"op":"mcm","clk":"11882457683","pt":1724160663247,"mc":[{"id":"1.232050243","rc":[{"batb":[[2,1.01,481.95]],"ltp":0.0,"tv":0.0,"id":72857116}]}]}
{"op":"mcm","clk":"11882563904","pt":1724161630508,"mc":[{"id":"1.232050243","rc":[{"batb":[[0,1.03,200]],"ltp":0.0,"tv":0.0,"id":72857116},{"batb":[[0,1.03,200]],"ltp":0.0,"tv":0.0,"id":72857117}]}]}
{"op":"mcm","clk":"11882892049","pt":1724164975095,"mc":[{"id":"1.232050243","rc":[{"batb":[[2,1.01,482.04]],"ltp":0.0,"tv":0.0,"id":72857116},{"batb":[[2,1.01,482.04]],"ltp":0.0,"tv":0.0,"id":72857117}]}]}
{"op":"mcm","clk":"11883223229","pt":1724167952112,"mc":[{"id":"1.232050243","rc":[{"batb":[[0,1.13,384.62],[1,1.07,357.14],[2,1.03,200]],"ltp":0.0,"tv":0.0,"id":72857116},{"batb":[[0,1.18,277.78],[1,1.13,384.62],[2,1.07,357.14]],"ltp":0.0,"tv":0.0,"id":72857117}]}]}
{"op":"mcm","clk":"11883223283","pt":1724167952480,"mc":[{"id":"1.232050243","rc":[{"batb":[[0,1.43,116.28],[1,1.33,151.52],[2,1.28,178.57]],"ltp":0.0,"tv":0.0,"id":72857116},{"batb":[[0,1.43,116.28],[1,1.33,151.52],[2,1.28,178.57]],"ltp":0.0,"tv":0.0,"id":72857117}]}]}
{"op":"mcm","clk":"11883373377","pt":1724168989671,"mc":[{"id":"1.232050243","rc":[{"batb":[[0,1.44,7.1],[1,1.43,116.28],[2,1.33,151.52]],"ltp":0.0,"tv":0.0,"id":72857116},{"batb":[[0,1.44,7.06],[1,1.43,116.28],[2,1.33,151.52]],"ltp":0.0,"tv":0.0,"id":72857117}]}]}
{"op":"mcm","clk":"11883414275","pt":1724169304188,"mc":[{"id":"1.232050243","rc":[{"batb":[[0,1.44,13.15]],"ltp":0.0,"tv":0.0,"id":72857116},{"batb":[[0,1.44,13.11]],"ltp":0.0,"tv":0.0,"id":72857117}]}]}
{"op":"mcm","clk":"11883572397","pt":1724170375118,"mc":[{"id":"1.232050243","rc":[{"batb":[[0,1.44,13.16]],"ltp":0.0,"tv":0.0,"id":72857116},{"batb":[[0,1.44,13.12]],"ltp":0.0,"tv":0.0,"id":72857117}]}]}
{"op":"mcm","clk":"11884409075","pt":1724175775072,"mc":[{"id":"1.232050243","rc":[{"batb":[[0,1.44,13.16]],"ltp":0.0,"tv":0.0,"id":72857116},{"batb":[[0,1.44,13.12]],"ltp":0.0,"tv":0.0,"id":72857117}]}]}
{"op":"mcm","clk":"11886029048","pt":1724186575119,"mc":[{"id":"1.232050243","rc":[{"batb":[[0,1.44,13.16]],"ltp":0.0,"tv":0.0,"id":72857116},{"batb":[[0,1.44,13.12]],"ltp":0.0,"tv":0.0,"id":72857117}]}]}
{"op":"mcm","clk":"11886183228","pt":1724188959113,"mc":[{"id":"1.232050243","rc":[{"batb":[[0,1.44,13.16]],"ltp":0.0,"tv":0.0,"id":72857116},{"batb":[[0,1.44,13.12]],"ltp":0.0,"tv":0.0,"id":72857117}]}]}
{"op":"mcm","clk":"11886357204","pt":1724191975106,"mc":[{"id":"1.232050243","rc":[{"batb":[[0,1.44,13.16]],"ltp":0.0,"tv":0.0,"id":72857116},{"batb":[[0,1.44,13.12]],"ltp":0.0,"tv":0.0,"id":72857117}]}]}
{"op":"mcm","clk":"11886737677","pt":1724197375096,"mc":[{"id":"1.232050243","rc":[{"batb":[[0,1.44,13.16]],"ltp":0.0,"tv":0.0,"id":72857116},{"batb":[[0,1.44,13.12]],"ltp":0.0,"tv":0.0,"id":72857117}]}]}
{"op":"mcm","clk":"11886888934","pt":1724199877418,"mc":[{"id":"1.232050243","rc":[{"batb":[[0,1.44,13.16]],"ltp":0.0,"tv":0.0,"id":72857116},{"batb":[[0,1.5,8.28],[1,1.44,13.12],[2,1.43,116.28]],"ltp":0.0,"tv":0.0,"id":72857117}]}]}
{"op":"mcm","clk":"11886890057","pt":1724199899570,"mc":[{"id":"1.232050243","rc":[{"batb":[[0,1.44,13.12],[1,1.43,116.28],[2,1.33,151.52]],"ltp":0.0,"tv":0.0,"id":72857117}]}]}
{"op":"mcm","clk":"11887024835","pt":1724202775090,"mc":[{"id":"1.232050243","rc":[{"batb":[[0,1.44,13.16]],"ltp":0.0,"tv":0.0,"id":72857116},{"batb":[[0,1.44,13.12]],"ltp":0.0,"tv":0.0,"id":72857117}]}]}
{"op":"mcm","clk":"11887238462","pt":1724208175090,"mc":[{"id":"1.232050243","rc":[{"batb":[[0,1.44,13.16]],"ltp":0.0,"tv":0.0,"id":72857116},{"batb":[[0,1.44,13.12]],"ltp":0.0,"tv":0.0,"id":72857117}]}]}
{"op":"mcm","clk":"11887420192","pt":1724213575078,"mc":[{"id":"1.232050243","rc":[{"batb":[[0,1.44,13.16]],"ltp":0.0,"tv":0.0,"id":72857116},{"batb":[[0,1.44,13.12]],"ltp":0.0,"tv":0.0,"id":72857117}]}]}
{"op":"mcm","clk":"11887458768","pt":1724215190451,"mc":[{"id":"1.232050243","rc":[{"batb":[[0,1.44,14.06]],"ltp":0.0,"tv":0.0,"id":72857117}]}]}
{"op":"mcm","clk":"11887458964","pt":1724215199448,"mc":[{"id":"1.232050243","rc":[{"batb":[[0,1.44,14.1]],"ltp":0.0,"tv":0.0,"id":72857116}]}]}
{"op":"mcm","clk":"11887503045","pt":1724216910536,"mc":[{"id":"1.232050243","rc":[{"batb":[[0,1.45,1.83],[1,1.44,13.12],[2,1.43,116.28]],"ltp":0.0,"tv":0.0,"id":72857117}]}]}
{"op":"mcm","clk":"11887503221","pt":1724216919799,"mc":[{"id":"1.232050243","rc":[{"batb":[[0,1.45,1.83],[1,1.44,13.16],[2,1.43,116.28]],"ltp":0.0,"tv":0.0,"id":72857116}]}]}
{"op":"mcm","clk":"11887577384","pt":1724219773865,"mc":[{"id":"1.232050243","rc":[{"batb":[[0,1.54,1.47],[1,1.44,14.02]],"ltp":0.0,"tv":0.0,"id":72857117}]}]}
{"op":"mcm","clk":"11887577624","pt":1724219784499,"mc":[{"id":"1.232050243","rc":[{"batb":[[0,1.54,1.47],[1,1.44,14.05]],"ltp":0.0,"tv":0.0,"id":72857116}]}]}
{"op":"mcm","clk":"11887587272","pt":1724220158629,"mc":[{"id":"1.232050243","rc":[{"batb":[[1,1.44,14.06]],"ltp":0.0,"tv":0.0,"id":72857116},{"batb":[[0,1.55,1.83],[1,1.44,13.66]],"ltp":0.0,"tv":0.0,"id":72857117}]}]}
{"op":"mcm","clk":"11887587338","pt":1724220163555,"mc":[{"id":"1.232050243","rc":[{"batb":[[0,1.54,1.48],[1,1.44,13.13]],"ltp":0.0,"tv":0.0,"id":72857117}]}]}
{"op":"mcm","clk":"11887587418","pt":1724220167570,"mc":[{"id":"1.232050243","rc":[{"batb":[[1,1.44,13.17]],"ltp":0.0,"tv":0.0,"id":72857116}]}]}
{"op":"mcm","clk":"11887680129","pt":1724224052679,"mc":[{"id":"1.232050243","rc":[{"batb":[[1,1.44,13.17]],"ltp":0.0,"tv":0.0,"id":72857116},{"batb":[[1,1.44,13.13]],"ltp":0.0,"tv":0.0,"id":72857117}]}]}
{"op":"mcm","clk":"11887897483","pt":1724229779648,"mc":[{"id":"1.232050243","rc":[{"batb":[[1,1.45,19.07],[2,1.44,13.17]],"ltp":0.0,"tv":0.0,"id":72857116},{"batb":[[1,1.45,19.07],[2,1.44,13.13]],"ltp":0.0,"tv":0.0,"id":72857117}]}]}
{"op":"mcm","clk":"11887897503","pt":1724229780365,"mc":[{"id":"1.232050243","rc":[{"batb":[[2,1.44,7.11]],"ltp":0.0,"tv":0.0,"id":72857116},{"batb":[[2,1.44,7.07]],"ltp":0.0,"tv":0.0,"id":72857117}]}]}
{"op":"mcm","clk":"11887983817","pt":1724231580160,"mc":[{"id":"1.232050243","rc":[{"batb":[[1,1.44,7.11],[2,1.43,116.28]],"ltp":0.0,"tv":0.0,"id":72857116},{"batb":[[1,1.44,7.07],[2,1.43,116.28]],"ltp":0.0,"tv":0.0,"id":72857117}]}]}
{"op":"mcm","clk":"11887984675","pt":1724231593965,"mc":[{"id":"1.232050243","rc":[{"batb":[[1,1.44,12.81]],"ltp":0.0,"tv":0.0,"id":72857116},{"batb":[[1,1.44,12.78]],"ltp":0.0,"tv":0.0,"id":72857117}]}]}
{"op":"mcm","clk":"11887986545","pt":1724231630026,"mc":[{"id":"1.232050243","rc":[{"batb":[[1,1.45,19.08],[2,1.44,12.81]],"ltp":0.0,"tv":0.0,"id":72857116},{"batb":[[1,1.45,19.08],[2,1.44,12.78]],"ltp":0.0,"tv":0.0,"id":72857117}]}]}
{"op":"mcm","clk":"11887986602","pt":1724231631320,"mc":[{"id":"1.232050243","rc":[{"batb":[[2,1.44,7.11]],"ltp":0.0,"tv":0.0,"id":72857116},{"batb":[[2,1.44,7.07]],"ltp":0.0,"tv":0.0,"id":72857117}]}]}
{"op":"mcm","clk":"11888045643","pt":1724232648851,"mc":[{"id":"1.232050243","rc":[{"batb":[[0,1.45,20.02],[1,1.44,7.07],[2,1.04,1.53]],"ltp":0.0,"tv":0.0,"id":72857117}]}]}
{"op":"mcm","clk":"11888045926","pt":1724232652461,"mc":[{"id":"1.232050243","rc":[{"batb":[[0,1.45,20.02],[1,1.44,7.11],[2,1.04,1.53]],"ltp":0.0,"tv":0.0,"id":72857116}]}]}
{"op":"mcm","clk":"11888094284","pt":1724233430549,"mc":[{"id":"1.232050243","rc":[{"batb":[[0,1.44,8.05],[1,1.04,1.53],[2,1.03,200]],"ltp":0.0,"tv":0.0,"id":72857116},{"batb":[[0,1.44,8.01],[1,1.04,1.53],[2,1.03,200]],"ltp":0.0,"tv":0.0,"id":72857117}]}]}
{"op":"mcm","clk":"11888096986","pt":1724233472993,"mc":[{"id":"1.232050243","rc":[{"batb":[[0,1.45,20.02],[1,1.44,7.11],[2,1.04,1.53]],"ltp":0.0,"tv":0.0,"id":72857116},{"batb":[[0,1.45,20.02],[1,1.44,7.07],[2,1.04,1.53]],"ltp":0.0,"tv":0.0,"id":72857117}]}]}
{"op":"mcm","clk":"11888163445","pt":1724234515608,"mc":[{"id":"1.232050243","rc":[{"batb":[[0,1.45,20],[1,1.44,7.1]],"ltp":0.0,"tv":0.0,"id":72857116},{"batb":[[0,1.45,20],[1,1.44,7.06]],"batl":[[0,1.65,1.15]],"ltp":0.0,"tv":0.0,"id":72857117}]}]}
{"op":"mcm","clk":"11888164275","pt":1724234525026,"mc":[{"id":"1.232050243","rc":[{"batl":[[0,1.65,1.15]],"ltp":0.0,"tv":0.0,"id":72857116}]}]}
{"op":"mcm","clk":"11888167343","pt":1724234562002,"mc":[{"id":"1.232050243","rc":[{"batl":[[0,1.65,1.15]],"ltp":0.0,"tv":0.0,"id":72857117}]}]}
{"op":"mcm","clk":"11888172244","pt":1724234615955,"mc":[{"id":"1.232050243","rc":[{"batl":[[0,1.64,1.15]],"ltp":0.0,"tv":0.0,"id":72857117}]}]}
{"op":"mcm","clk":"11888173351","pt":1724234625956,"mc":[{"id":"1.232050243","rc":[{"batb":[[1,1.04,1.53],[2,1.03,200]],"ltp":0.0,"tv":0.0,"id":72857116},{"batb":[[1,1.04,1.53],[2,1.03,200]],"ltp":0.0,"tv":0.0,"id":72857117}]}]}
{"op":"mcm","clk":"11888174618","pt":1724234638493,"mc":[{"id":"1.232050243","rc":[{"batl":[[0,1.64,1.15]],"ltp":0.0,"tv":0.0,"id":72857116}]}]}
{"op":"mcm","clk":"11888179073","pt":1724234688547,"mc":[{"id":"1.232050243","rc":[{"batl":[[0,1.64,1.15]],"ltp":0.0,"tv":0.0,"id":72857117}]}]}
{"op":"mcm","clk":"11888180656","pt":1724234708295,"mc":[{"id":"1.232050243","rc":[{"batl":[[0,1.66,1.54]],"ltp":0.0,"tv":0.0,"id":72857117}]}]}
{"op":"mcm","clk":"11888185236","pt":1724234763649,"mc":[{"id":"1.232050243","rc":[{"batl":[[0,2.54,1.15]],"ltp":0.0,"tv":0.0,"id":72857116}]}]}
{"op":"mcm","clk":"11888187363","pt":1724234791405,"mc":[{"id":"1.232050243","rc":[{"trd":[[2.62,0.58]],"batb":[[0,1.62,1.51],[1,1.45,19.06],[2,1.04,1.53]],"ltp":2.62,"tv":0.58,"id":72857116},{"trd":[[1.62,0.94]],"batb":[[0,1.45,19.06]],"ltp":1.62,"tv":0.93,"id":72857117}],"tv":1.52}]}
{"op":"mcm","clk":"11888187637","pt":1724234794522,"mc":[{"id":"1.232050243","rc":[{"batb":[[0,1.45,20],[1,1.04,1.53],[2,1.03,200]],"ltp":2.62,"tv":0.58,"id":72857116}]}]}
{"op":"mcm","clk":"11888188305","pt":1724234802704,"mc":[{"id":"1.232050243","rc":[{"trd":[[1.62,1.88]],"batb":[[0,1.45,19.06]],"ltp":1.62,"tv":2.45,"id":72857116}],"tv":3.39}]}
{"op":"mcm","clk":"11888191727","pt":1724234832541,"mc":[{"id":"1.232050243","rc":[{"trd":[[1.55,1.54]],"ltp":1.55,"tv":3.99,"id":72857116},{"trd":[[2.8,0.85]],"batl":[[0,1.5,0.3]],"ltp":2.8,"tv":1.79,"id":72857117}],"tv":5.78}]}
{"op":"mcm","clk":"11888192664","pt":1724234842645,"mc":[{"id":"1.232050243","rc":[{"batl":[[0,1.62,1.54]],"ltp":1.55,"tv":3.99,"id":72857116}]}]}
{"op":"mcm","clk":"11888195244","pt":1724234873274,"mc":[{"id":"1.232050243","rc":[{"batb":[[0,1.61,1.15],[1,1.45,19.06],[2,1.04,1.53]],"ltp":1.55,"tv":3.99,"id":72857116}]}]}
{"op":"mcm","clk":"11888195398","pt":1724234875504,"mc":[{"id":"1.232050243","rc":[{"batb":[[0,1.45,19.06],[1,1.04,1.53],[2,1.03,200]],"ltp":1.55,"tv":3.99,"id":72857116}]}]}
{"op":"mcm","clk":"11888197491","pt":1724234902340,"mc":[{"id":"1.232050243","rc":[{"batl":[[0,1.47,1.15]],"ltp":1.55,"tv":3.99,"id":72857116}]}]}
{"op":"mcm","clk":"11888199687","pt":1724234928672,"mc":[{"id":"1.232050243","rc":[{"batl":[[0,1.66,1.54]],"ltp":2.8,"tv":1.79,"id":72857117}]}]}
{"op":"mcm","clk":"11888200116","pt":1724234933783,"mc":[{"id":"1.232050243","rc":[{"batl":[[0,1.52,1.15],[1,1.66,1.54]],"ltp":2.8,"tv":1.79,"id":72857117}]}]}
{"op":"mcm","clk":"11888200328","pt":1724234936477,"mc":[{"id":"1.232050243","rc":[{"trd":[[1.66,3.07]],"batb":[[0,1.66,1.63],[1,1.45,19.06],[2,1.04,1.53]],"ltp":1.66,"tv":4.86,"id":72857117}],"tv":8.85}]}
{"op":"mcm","clk":"11888201217","pt":1724234948208,"mc":[{"id":"1.232050243","rc":[{"batl":[[0,1.68,1.54]],"ltp":1.66,"tv":4.86,"id":72857117}]}]}
{"op":"mcm","clk":"11888201711","pt":1724234954813,"mc":[{"id":"1.232050243","rc":[{"trd":[[1.68,3.07]],"batb":[[0,1.66,2.08]],"ltp":1.68,"tv":7.93,"id":72857117}],"tv":11.92}]}
{"op":"mcm","clk":"11888202691","pt":1724234967800,"mc":[{"id":"1.232050243","rc":[{"batl":[[0,1.7,1.54],[1,2.5,0.94]],"ltp":1.68,"tv":7.93,"id":72857117}]}]}
{"op":"mcm","clk":"11888203201","pt":1724234973840,"mc":[{"id":"1.232050243","rc":[{"trd":[[1.7,3.07]],"batb":[[0,1.66,2.52]],"batl":[[0,2.5,0.94],[1,2.5,0]],"ltp":1.7,"tv":11.0,"id":72857117}],"tv":14.99}]}
{"op":"mcm","clk":"11888203583","pt":1724234978644,"mc":[{"id":"1.232050243","rc":[{"batb":[[0,1.66,2.08]],"ltp":1.7,"tv":11.0,"id":72857117}]}]}
{"op":"mcm","clk":"11888203902","pt":1724234982527,"mc":[{"id":"1.232050243","rc":[{"batb":[[0,1.66,1.63]],"ltp":1.7,"tv":11.0,"id":72857117}]}]}
{"op":"mcm","clk":"11888204162","pt":1724234985843,"mc":[{"id":"1.232050243","rc":[{"batb":[[0,1.45,19.06],[1,1.04,1.53],[2,1.03,200]],"ltp":1.7,"tv":11.0,"id":72857117}]}]}
{"op":"mcm","clk":"11888205124","pt":1724235000581,"mc":[{"id":"1.232050243","rc":[{"batl":[[0,1.7,1.54],[1,2.5,0.94]],"ltp":1.7,"tv":11.0,"id":72857117}]}]}
{"op":"mcm","clk":"11888205530","pt":1724235005768,"mc":[{"id":"1.232050243","rc":[{"batl":[[1,2.5,3.03]],"ltp":1.7,"tv":11.0,"id":72857117}]}]}
{"op":"mcm","clk":"11888206067","pt":1724235012772,"mc":[{"id":"1.232050243","rc":[{"batl":[[1,2.5,3.1]],"ltp":1.7,"tv":11.0,"id":72857117}]}]}
{"op":"mcm","clk":"11888206416","pt":1724235017270,"mc":[{"id":"1.232050243","rc":[{"trd":[[1.7,5.88]],"batl":[[0,2.5,3.23],[1,2.5,0]],"ltp":1.7,"tv":13.81,"id":72857117}],"tv":17.8}]}
{"op":"mcm","clk":"11888207062","pt":1724235026495,"mc":[{"id":"1.232050243","rc":[{"batl":[[0,2.5,3.1]],"ltp":1.7,"tv":13.81,"id":72857117}]}]}
{"op":"mcm","clk":"11888207238","pt":1724235028775,"mc":[{"id":"1.232050243","rc":[{"batl":[[0,2.5,4.04]],"ltp":1.7,"tv":13.81,"id":72857117}]}]}
{"op":"mcm","clk":"11888207957","pt":1724235038002,"mc":[{"id":"1.232050243","rc":[{"batl":[[0,2.5,3.1]],"ltp":1.7,"tv":13.81,"id":72857117}]}]}
{"op":"mcm","clk":"11888207973","pt":1724235038210,"mc":[{"id":"1.232050243","rc":[{"batl":[[0,2.5,4.04]],"ltp":1.7,"tv":13.81,"id":72857117}]}]}
{"op":"mcm","clk":"11888210045","pt":1724235069206,"mc":[{"id":"1.232050243","rc":[{"batl":[[0,1.85,1.15]],"ltp":1.55,"tv":3.99,"id":72857116}]}]}
{"op":"mcm","clk":"11888210122","pt":1724235070243,"mc":[{"id":"1.232050243","rc":[{"trd":[[1.83,1.13]],"batl":[[0,1.7,1.94],[1,1.85,1.15]],"ltp":1.83,"tv":5.12,"id":72857116},{"trd":[[2.2,0.94]],"batl":[[0,2.5,3.1]],"ltp":2.2,"tv":14.75,"id":72857117}],"tv":19.87}]}
{"op":"mcm","clk":"11888210217","pt":1724235071642,"mc":[{"id":"1.232050243","rc":[{"batl":[[1,1.85,0]],"ltp":1.83,"tv":5.12,"id":72857116}]}]}
{"op":"mcm","clk":"11888210639","pt":1724235078431,"mc":[{"id":"1.232050243","rc":[{"trd":[[1.7,3.88]],"batb":[[0,1.7,1.63],[1,1.45,19.06],[2,1.04,1.53]],"ltp":1.7,"tv":9.0,"id":72857116}],"tv":23.75}]}
{"op":"mcm","clk":"11888210887","pt":1724235082725,"mc":[{"id":"1.232050243","rc":[{"batb":[[0,1.45,19.06],[1,1.04,1.53],[2,1.03,200]],"ltp":1.7,"tv":9.0,"id":72857116}]}]}
{"op":"mcm","clk":"11888211523","pt":1724235091834,"mc":[{"id":"1.232050243","rc":[{"batl":[[0,1.72,1.54]],"ltp":1.7,"tv":9.0,"id":72857116}]}]}
{"op":"mcm","clk":"11888211732","pt":1724235094475,"mc":[{"id":"1.232050243","rc":[{"trd":[[1.72,1.3]],"batl":[[0,1.72,0.24]],"ltp":1.72,"tv":10.3,"id":72857116},{"trd":[[2.38,0.94]],"ltp":2.38,"tv":15.68,"id":72857117}],"tv":25.99}]}
{"op":"mcm","clk":"11888211844","pt":1724235095879,"mc":[{"id":"1.232050243","rc":[{"trd":[[1.72,1.77]],"batb":[[0,1.72,3.33],[1,1.45,19.06],[2,1.04,1.53]],"ltp":1.72,"tv":10.78,"id":72857116}],"tv":26.46}]}
{"op":"mcm","clk":"11888212185","pt":1724235100583,"mc":[{"id":"1.232050243","rc":[{"batb":[[0,1.45,19.06],[1,1.04,1.53],[2,1.03,200]],"ltp":1.72,"tv":10.78,"id":72857116}]}]}
{"op":"mcm","clk":"11888212395","pt":1724235103964,"mc":[{"id":"1.232050243","rc":[{"batl":[[0,1.48,1.15],[1,2.5,3.1]],"ltp":2.38,"tv":15.68,"id":72857117}]}]}
{"op":"mcm","clk":"11888212429","pt":1724235104488,"mc":[{"id":"1.232050243","rc":[{"batl":[[1,2.5,4.04]],"ltp":2.38,"tv":15.68,"id":72857117}]}]}
{"op":"mcm","clk":"11888212586","pt":1724235106567,"mc":[{"id":"1.232050243","rc":[{"batl":[[0,2.5,4.04],[1,2.5,0]],"ltp":2.38,"tv":15.68,"id":72857117}]}]}
{"op":"mcm","clk":"11888212641","pt":1724235107456,"mc":[{"id":"1.232050243","rc":[{"batb":[[0,1.48,3.57],[1,1.45,19.06],[2,1.04,1.53]],"ltp":2.38,"tv":15.68,"id":72857117}]}]}
{"op":"mcm","clk":"11888212895","pt":1724235111669,"mc":[{"id":"1.232050243","rc":[{"batb":[[0,1.45,19.06],[1,1.04,1.53],[2,1.03,200]],"ltp":2.38,"tv":15.68,"id":72857117}]}]}
{"op":"mcm","clk":"11888213010","pt":1724235113494,"mc":[{"id":"1.232050243","rc":[{"batb":[[0,1.45,20]],"ltp":2.38,"tv":15.68,"id":72857117}]}]}
{"op":"mcm","clk":"11888214220","pt":1724235130810,"mc":[{"id":"1.232050243","rc":[{"batl":[[0,1.79,1.15]],"ltp":1.72,"tv":10.78,"id":72857116}]}]}
{"op":"mcm","clk":"11888214686","pt":1724235137428,"mc":[{"id":"1.232050243","rc":[{"batl":[[0,1.8,1.54]],"ltp":1.72,"tv":10.78,"id":72857116}]}]}
{"op":"mcm","clk":"11888214846","pt":1724235139401,"mc":[{"id":"1.232050243","rc":[{"trd":[[1.8,3.07]],"batb":[[0,1.8,2.03],[1,1.45,19.06],[2,1.04,1.53]],"ltp":1.8,"tv":13.85,"id":72857116}],"tv":29.54}]}
{"op":"mcm","clk":"11888215109","pt":1724235142930,"mc":[{"id":"1.232050243","rc":[{"batb":[[0,1.45,19.06],[1,1.04,1.53],[2,1.03,200]],"ltp":1.8,"tv":13.85,"id":72857116}]}]}
{"op":"mcm","clk":"11888216224","pt":1724235156034,"mc":[{"id":"1.232050243","rc":[{"trd":[[1.89,1.05],[2.8,0.64]],"batl":[[0,1.82,0.61]],"ltp":1.89,"tv":15.53,"id":72857116},{"trd":[[1.55,1.15],[2.12,0.94]],"batl":[[0,2.5,3.1]],"ltp":2.12,"tv":17.77,"id":72857117}],"tv":33.31}]}
{"op":"mcm","clk":"11888216319","pt":1724235157434,"mc":[{"id":"1.232050243","rc":[{"batb":[[0,1.59,3.21],[1,1.45,20],[2,1.04,1.53]],"ltp":2.12,"tv":17.77,"id":72857117}]}]}
{"op":"mcm","clk":"11888217370","pt":1724235172341,"mc":[{"id":"1.232050243","rc":[{"batl":[[0,1.83,1.54]],"ltp":1.89,"tv":15.53,"id":72857116}]}]}
{"op":"mcm","clk":"11888226058","pt":1724235175071,"mc":[{"id":"1.232050243","rc":[{"batb":[[0,1.45,20],[1,1.04,1.53],[2,1.03,200]],"ltp":2.12,"tv":17.77,"id":72857117}]}]}
{"op":"mcm","clk":"11888226236","pt":1724235175456,"mc":[{"id":"1.232050243","rc":[{"trd":[[1.83,4.2]],"batb":[[0,1.83,2.03],[1,1.45,19.06],[2,1.04,1.53]],"ltp":1.83,"tv":18.61,"id":72857116}],"tv":36.39}]}
{"op":"mcm","clk":"11888226572","pt":1724235179666,"mc":[{"id":"1.232050243","rc":[{"batb":[[0,1.45,19.06],[1,1.04,1.53],[2,1.03,200]],"ltp":1.83,"tv":18.61,"id":72857116}]}]}
{"op":"mcm","clk":"11888226651","pt":1724235180968,"mc":[{"id":"1.232050243","rc":[{"batl":[[0,1.63,1.15],[1,2.5,3.1]],"ltp":2.12,"tv":17.77,"id":72857117}]}]}
{"op":"mcm","clk":"11888226816","pt":1724235183143,"mc":[{"id":"1.232050243","rc":[{"batl":[[0,2.5,3.1],[1,2.5,0]],"ltp":2.12,"tv":17.77,"id":72857117}]}]}
{"op":"mcm","clk":"11888227031","pt":1724235186461,"mc":[{"id":"1.232050243","rc":[{"batl":[[0,1.88,1.54]],"ltp":1.83,"tv":18.61,"id":72857116}]}]}
{"op":"mcm","clk":"11888227111","pt":1724235187454,"mc":[{"id":"1.232050243","rc":[{"batl":[[0,2.5,4.04]],"ltp":2.12,"tv":17.77,"id":72857117}]}]}
{"op":"mcm","clk":"11888227213","pt":1724235188849,"mc":[{"id":"1.232050243","rc":[{"trd":[[1.88,3.07]],"batb":[[0,1.88,2.03],[1,1.45,19.06],[2,1.04,1.53]],"ltp":1.88,"tv":21.68,"id":72857116}],"tv":39.46}]}
{"op":"mcm","clk":"11888227472","pt":1724235192549,"mc":[{"id":"1.232050243","rc":[{"batb":[[0,1.45,19.06],[1,1.04,1.53],[2,1.03,200]],"ltp":1.88,"tv":21.68,"id":72857116}]}]}
{"op":"mcm","clk":"11888227937","pt":1724235199083,"mc":[{"id":"1.232050243","rc":[{"batl":[[0,1.93,1.54]],"ltp":1.88,"tv":21.68,"id":72857116}]}]}
{"op":"mcm","clk":"11888228158","pt":1724235201785,"mc":[{"id":"1.232050243","rc":[{"trd":[[1.93,3.07]],"batb":[[0,1.93,2.03],[1,1.45,19.06],[2,1.04,1.53]],"ltp":1.93,"tv":24.75,"id":72857116}],"tv":42.53}]}
{"op":"mcm","clk":"11888228444","pt":1724235205561,"mc":[{"id":"1.232050243","rc":[{"batb":[[0,1.45,19.06],[1,1.04,1.53],[2,1.03,200]],"ltp":1.93,"tv":24.75,"id":72857116}]}]}
{"op":"mcm","clk":"11888231535","pt":1724235249797,"mc":[{"id":"1.232050243","rc":[{"trd":[[2.04,1.75]],"batl":[[0,2.5,3.16]],"ltp":2.04,"tv":19.53,"id":72857117}],"tv":44.28}]}
{"op":"mcm","clk":"11888232820","pt":1724235266999,"mc":[{"id":"1.232050243","rc":[{"batl":[[0,1.66,2.3],[1,2.5,3.16]],"ltp":2.04,"tv":19.53,"id":72857117}]}]}
{"op":"mcm","clk":"11888233038","pt":1724235270418,"mc":[{"id":"1.232050243","rc":[{"trd":[[2.5,1.53]],"batl":[[0,2.5,2.04]],"ltp":2.5,"tv":26.28,"id":72857116},{"trd":[[1.66,5.37]],"batl":[[0,2.5,3.16],[1,2.5,0]],"ltp":1.66,"tv":21.83,"id":72857117}],"tv":48.11}]}
{"op":"mcm","clk":"11888233326","pt":1724235273835,"mc":[{"id":"1.232050243","rc":[{"batb":[[0,1.04,1.53],[1,1.03,200],[2,1.02,200]],"ltp":2.5,"tv":26.28,"id":72857116},{"batb":[[0,1.04,2.47],[1,1.03,200],[2,1.02,200]],"ltp":1.66,"tv":21.83,"id":72857117}]}]}
{"op":"mcm","clk":"11888233815","pt":1724235280766,"mc":[{"id":"1.232050243","rc":[{"trd":[[2.42,1.15]],"ltp":2.42,"tv":27.43,"id":72857116},{"trd":[[1.7,7.52]],"batl":[[0,2.5,3.82]],"ltp":1.7,"tv":23.47,"id":72857117}],"tv":50.9}]}
{"op":"mcm","clk":"11888234459","pt":1724235289054,"mc":[{"id":"1.232050243","rc":[{"batb":[[0,1.56,10.94],[1,1.55,3.17],[2,1.04,1.53]],"ltp":1.7,"tv":23.47,"id":72857117}]}]}
{"op":"mcm","clk":"11888234544","pt":1724235290253,"mc":[{"id":"1.232050243","rc":[{"batl":[[0,2.5,3.16]],"ltp":1.7,"tv":23.47,"id":72857117}]}]}
{"op":"mcm","clk":"11888234682","pt":1724235292225,"mc":[{"id":"1.232050243","rc":[{"batb":[[0,1.55,4.11],[1,1.04,1.53],[2,1.03,200]],"ltp":1.7,"tv":23.47,"id":72857117}]}]}
{"op":"mcm","clk":"11888235191","pt":1724235298456,"mc":[{"id":"1.232050243","rc":[{"batl":[[0,1.7,2.3],[1,2.5,3.16]],"ltp":1.7,"tv":23.47,"id":72857117}]}]}
{"op":"mcm","clk":"11888235348","pt":1724235300579,"mc":[{"id":"1.232050243","rc":[{"batl":[[1,2.5,3.1]],"ltp":1.7,"tv":23.47,"id":72857117}]}]}
{"op":"mcm","clk":"11888235599","pt":1724235303464,"mc":[{"id":"1.232050243","rc":[{"trd":[[1.7,12.13]],"batb":[[0,1.7,1.27],[1,1.55,4.11],[2,1.04,1.53]],"batl":[[0,2.5,3.1],[1,2.5,0]],"ltp":1.7,"tv":28.08,"id":72857117}],"tv":55.51}]}
{"op":"mcm","clk":"11888235971","pt":1724235307760,"mc":[{"id":"1.232050243","rc":[{"batb":[[0,1.56,10.94],[1,1.55,3.17]],"ltp":1.7,"tv":28.08,"id":72857117}]}]}
{"op":"mcm","clk":"11888236216","pt":1724235311081,"mc":[{"id":"1.232050243","rc":[{"batb":[[0,1.55,4.11],[1,1.04,1.53],[2,1.03,200]],"ltp":1.7,"tv":28.08,"id":72857117}]}]}
{"op":"mcm","clk":"11888236232","pt":1724235311290,"mc":[{"id":"1.232050243","rc":[{"batb":[[0,1.67,12.8],[1,1.04,1.53],[2,1.03,200]],"ltp":2.42,"tv":27.43,"id":72857116},{"batb":[[0,1.57,15.99],[1,1.55,3.17],[2,1.04,1.53]],"ltp":1.7,"tv":28.08,"id":72857117}]}]}
{"op":"mcm","clk":"11888237127","pt":1724235322295,"mc":[{"id":"1.232050243","rc":[{"batl":[[0,1.72,1.54],[1,2.5,3.1]],"ltp":1.7,"tv":28.08,"id":72857117}]}]}
{"op":"mcm","clk":"11888237414","pt":1724235325717,"mc":[{"id":"1.232050243","rc":[{"trd":[[1.72,3.07]],"batb":[[0,1.73,10],[1,1.72,5.09],[2,1.57,15.99]],"batl":[[0,2.5,3.1],[1,2.5,0]],"ltp":1.72,"tv":31.15,"id":72857117}],"tv":58.58}]}
{"op":"mcm","clk":"11888237511","pt":1724235326696,"mc":[{"id":"1.232050243","rc":[{"batb":[[1,1.05,5.19],[2,1.04,1.53]],"ltp":2.42,"tv":27.43,"id":72857116}]}]}
{"op":"mcm","clk":"11888237685","pt":1724235329099,"mc":[{"id":"1.232050243","rc":[{"batb":[[0,1.72,5.09],[1,1.57,15.99],[2,1.55,3.17]],"ltp":1.72,"tv":31.15,"id":72857117}]}]}
{"op":"mcm","clk":"11888237722","pt":1724235329621,"mc":[{"id":"1.232050243","rc":[{"batb":[[0,1.72,1.52]],"ltp":1.72,"tv":31.15,"id":72857117}]}]}
{"op":"mcm","clk":"11888237895","pt":1724235331816,"mc":[{"id":"1.232050243","rc":[{"batb":[[0,1.58,10.94],[1,1.57,15.05]],"ltp":1.72,"tv":31.15,"id":72857117}]}]}
{"op":"mcm","clk":"11888238186","pt":1724235335194,"mc":[{"id":"1.232050243","rc":[{"batb":[[0,1.57,15.99],[1,1.55,3.17],[2,1.04,1.53]],"ltp":1.72,"tv":31.15,"id":72857117}]}]}
{"op":"mcm","clk":"11888238866","pt":1724235343127,"mc":[{"id":"1.232050243","rc":[{"batl":[[0,1.75,1.54],[1,2.5,3.1]],"ltp":1.72,"tv":31.15,"id":72857117}]}]}
{"op":"mcm","clk":"11888239153","pt":1724235346432,"mc":[{"id":"1.232050243","rc":[{"trd":[[1.75,3.07]],"batb":[[0,1.75,2.03],[1,1.57,15.99],[2,1.55,3.17]],"batl":[[0,2.5,3.1],[1,2.5,0]],"ltp":1.75,"tv":34.22,"id":72857117}],"tv":61.65}]}
{"op":"mcm","clk":"11888239226","pt":1724235347427,"mc":[{"id":"1.232050243","rc":[{"batl":[[0,2.04,1.12],[1,2.5,3.1]],"ltp":1.75,"tv":34.22,"id":72857117}]}]}
{"op":"mcm","clk":"11888239475","pt":1724235350629,"mc":[{"id":"1.232050243","rc":[{"batb":[[0,1.58,10.94],[1,1.57,15.05]],"ltp":1.75,"tv":34.22,"id":72857117}]}]}
{"op":"mcm","clk":"11888239742","pt":1724235353937,"mc":[{"id":"1.232050243","rc":[{"batb":[[0,1.57,15.99],[1,1.55,3.17],[2,1.04,1.53]],"ltp":1.75,"tv":34.22,"id":72857117}]}]}
{"op":"mcm","clk":"11888240265","pt":1724235360760,"mc":[{"id":"1.232050243","rc":[{"batb":[[0,1.58,10.94],[1,1.57,15.05]],"ltp":1.75,"tv":34.22,"id":72857117}]}]}
{"op":"mcm","clk":"11888240402","pt":1724235362446,"mc":[{"id":"1.232050243","rc":[{"batl":[[0,1.8,1.54],[1,2.04,1.12],[2,2.5,3.1]],"ltp":1.75,"tv":34.22,"id":72857117}]}]}
{"op":"mcm","clk":"11888240553","pt":1724235363973,"mc":[{"id":"1.232050243","rc":[{"batb":[[0,1.57,15.99],[1,1.04,1.53],[2,1.03,200]],"ltp":1.75,"tv":34.22,"id":72857117}]}]}
{"op":"mcm","clk":"11888240731","pt":1724235365856,"mc":[{"id":"1.232050243","rc":[{"trd":[[1.8,3.07]],"batb":[[0,1.8,2.03],[1,1.57,15.99],[2,1.04,1.53]],"batl":[[0,2.04,1.12],[1,2.5,3.1],[2,2.5,0]],"ltp":1.8,"tv":37.29,"id":72857117}],"tv":64.72}]}
{"op":"mcm","clk":"11888241066","pt":1724235369703,"mc":[{"id":"1.232050243","rc":[{"batb":[[0,1.58,10.94],[1,1.57,15.05]],"ltp":1.8,"tv":37.29,"id":72857117}]}]}
{"op":"mcm","clk":"11888241223","pt":1724235371371,"mc":[{"id":"1.232050243","rc":[{"trd":[[1.67,1.07],[1.96,1.16]],"batb":[[0,1.67,12.26]],"ltp":1.67,"tv":29.66,"id":72857116},{"trd":[[2.04,2.87]],"batl":[[0,2.5,3.1],[1,2.5,0]],"ltp":2.04,"tv":38.41,"id":72857117}],"tv":68.07}]}
{"op":"mcm","clk":"11888241379","pt":1724235373090,"mc":[{"id":"1.232050243","rc":[{"batb":[[0,1.57,15.99],[1,1.04,1.53],[2,1.03,200]],"ltp":2.04,"tv":38.41,"id":72857117}]}]}
{"op":"mcm","clk":"11888242274","pt":1724235384018,"mc":[{"id":"1.232050243","rc":[{"batb":[[0,1.58,10.94],[1,1.57,15.05],[2,1.04,1.53]],"ltp":2.04,"tv":38.41,"id":72857117}]}]}
{"op":"mcm","clk":"11888242405","pt":1724235385311,"mc":[{"id":"1.232050243","rc":[{"trd":[[1.58,1.52],[1.68,4.95]],"batb":[[0,1.58,9.24]],"ltp":1.58,"tv":41.8,"id":72857117}],"tv":71.47}]}
{"op":"mcm","clk":"11888242579","pt":1724235387326,"mc":[{"id":"1.232050243","rc":[{"batb":[[0,1.57,15.05],[1,1.04,1.53],[2,1.03,200]],"ltp":1.58,"tv":41.8,"id":72857117}]}]}
{"op":"mcm","clk":"11888243517","pt":1724235397601,"mc":[{"id":"1.232050243","rc":[{"batb":[[0,1.58,10],[1,1.57,15.05],[2,1.04,1.53]],"batl":[[0,2.5,4.04]],"ltp":1.58,"tv":41.8,"id":72857117}]}]}
{"op":"mcm","clk":"11888243883","pt":1724235401453,"mc":[{"id":"1.232050243","rc":[{"batb":[[0,1.57,15.05],[1,1.04,1.53],[2,1.03,200]],"ltp":1.58,"tv":41.8,"id":72857117}]}]}
{"op":"mcm","clk":"11888244837","pt":1724235413559,"mc":[{"id":"1.232050243","rc":[{"batb":[[0,1.58,10.94],[1,1.57,15.05],[2,1.04,1.53]],"ltp":1.58,"tv":41.8,"id":72857117}]}]}
{"op":"mcm","clk":"11888245136","pt":1724235416878,"mc":[{"id":"1.232050243","rc":[{"batb":[[0,1.57,15.99],[1,1.04,1.53],[2,1.03,200]],"ltp":1.58,"tv":41.8,"id":72857117}]}]}
{"op":"mcm","clk":"11888245549","pt":1724235421583,"mc":[{"id":"1.232050243","rc":[{"batb":[[0,1.95,1.15],[1,1.57,15.99],[2,1.04,1.53]],"ltp":1.58,"tv":41.8,"id":72857117}]}]}
{"op":"mcm","clk":"11888245651","pt":1724235422994,"mc":[{"id":"1.232050243","rc":[{"batb":[[0,1.57,15.99],[1,1.04,1.53],[2,1.03,200]],"ltp":1.58,"tv":41.8,"id":72857117}]}]}
{"op":"mcm","clk":"11888245686","pt":1724235423295,"mc":[{"id":"1.232050243","rc":[{"batb":[[0,1.58,10.94],[1,1.57,15.05],[2,1.04,1.53]],"ltp":1.58,"tv":41.8,"id":72857117}]}]}
{"op":"mcm","clk":"11888246020","pt":1724235426576,"mc":[{"id":"1.232050243","rc":[{"batb":[[0,1.57,15.99],[1,1.04,1.53],[2,1.03,200]],"ltp":1.58,"tv":41.8,"id":72857117}]}]}
{"op":"mcm","clk":"11888246874","pt":1724235437591,"mc":[{"id":"1.232050243","rc":[{"batb":[[0,1.97,1.15],[1,1.57,15.99],[2,1.04,1.53]],"ltp":1.58,"tv":41.8,"id":72857117}]}]}
{"op":"mcm","clk":"11888246998","pt":1724235439105,"mc":[{"id":"1.232050243","rc":[{"batb":[[0,1.57,15.99],[1,1.04,1.53],[2,1.03,200]],"ltp":1.58,"tv":41.8,"id":72857117}]}]}
{"op":"mcm","clk":"11888247005","pt":1724235439203,"mc":[{"id":"1.232050243","rc":[{"batb":[[0,1.58,10.94],[1,1.57,15.05],[2,1.04,1.53]],"ltp":1.58,"tv":41.8,"id":72857117}]}]}
{"op":"mcm","clk":"11888247306","pt":1724235442586,"mc":[{"id":"1.232050243","rc":[{"batl":[[0,1.94,1.54]],"ltp":1.67,"tv":29.66,"id":72857116},{"batb":[[0,1.57,15.99],[1,1.04,1.53],[2,1.03,200]],"ltp":1.58,"tv":41.8,"id":72857117}]}]}
{"op":"mcm","clk":"11888247674","pt":1724235446707,"mc":[{"id":"1.232050243","rc":[{"trd":[[1.94,1.54]],"ltp":1.94,"tv":31.2,"id":72857116},{"trd":[[2.06,1.45]],"batb":[[0,1.58,10.94],[1,1.57,15.05],[2,1.04,1.53]],"batl":[[0,2.06,2.12],[1,2.5,4.04]],"ltp":2.06,"tv":43.25,"id":72857117}],"tv":74.45}]}
{"op":"mcm","clk":"11888247956","pt":1724235449934,"mc":[{"id":"1.232050243","rc":[{"batb":[[0,1.57,15.99],[1,1.04,1.53],[2,1.03,200]],"ltp":2.06,"tv":43.25,"id":72857117}]}]}
{"op":"mcm","clk":"11888248006","pt":1724235450518,"mc":[{"id":"1.232050243","rc":[{"batl":[[0,2.5,4.04],[1,2.5,0]],"ltp":2.06,"tv":43.25,"id":72857117}]}]}
{"op":"mcm","clk":"11888248156","pt":1724235452128,"mc":[{"id":"1.232050243","rc":[{"batb":[[0,1.58,10.94],[1,1.57,15.05],[2,1.04,1.53]],"ltp":2.06,"tv":43.25,"id":72857117}]}]}
{"op":"mcm","clk":"11888248409","pt":1724235455411,"mc":[{"id":"1.232050243","rc":[{"batb":[[0,1.57,15.99],[1,1.04,1.53],[2,1.03,200]],"ltp":2.06,"tv":43.25,"id":72857117}]}]}
{"op":"mcm","clk":"11888248544","pt":1724235457125,"mc":[{"id":"1.232050243","rc":[{"trd":[[1.98,0.96]],"batl":[[0,1.95,0.58]],"ltp":1.98,"tv":32.16,"id":72857116},{"trd":[[2.02,0.94]],"batl":[[0,2.5,3.1]],"ltp":2.02,"tv":44.19,"id":72857117}],"tv":76.35}]}
{"op":"mcm","clk":"11888248618","pt":1724235458015,"mc":[{"id":"1.232050243","rc":[{"batb":[[0,1.58,10.94],[1,1.57,15.05],[2,1.04,1.53]],"ltp":2.02,"tv":44.19,"id":72857117}]}]}
{"op":"mcm","clk":"11888248914","pt":1724235461403,"mc":[{"id":"1.232050243","rc":[{"batb":[[0,1.57,15.99],[1,1.04,1.53],[2,1.03,200]],"ltp":2.02,"tv":44.19,"id":72857117}]}]}
{"op":"mcm","clk":"11888249770","pt":1724235471553,"mc":[{"id":"1.232050243","rc":[{"batl":[[0,1.95,1.54]],"ltp":1.98,"tv":32.16,"id":72857116},{"batb":[[0,1.58,10.94],[1,1.57,15.05],[2,1.04,1.53]],"ltp":2.02,"tv":44.19,"id":72857117}]}]}
{"op":"mcm","clk":"11888249852","pt":1724235472852,"mc":[{"id":"1.232050243","rc":[{"trd":[[1.95,0.98]],"batl":[[0,1.95,0.55]],"ltp":1.95,"tv":33.14,"id":72857116},{"trd":[[2.04,3.81]],"ltp":2.04,"tv":45.12,"id":72857117}],"tv":78.27}]}
{"op":"mcm","clk":"11888250031","pt":1724235474836,"mc":[{"id":"1.232050243","rc":[{"trd":[[1.95,2.09]],"batb":[[0,1.95,3.02],[1,1.67,12.26],[2,1.05,5.19]],"ltp":1.95,"tv":34.24,"id":72857116},{"batb":[[0,1.57,15.99],[1,1.04,1.53],[2,1.03,200]],"ltp":2.04,"tv":45.12,"id":72857117}],"tv":79.37}]}
{"op":"mcm","clk":"11888251498","pt":1724235492050,"mc":[{"id":"1.232050243","rc":[{"batb":[[0,1.72,1.26],[1,1.57,15.05],[2,1.04,1.53]],"ltp":2.04,"tv":45.12,"id":72857117}]}]}
{"op":"mcm","clk":"11888251518","pt":1724235492361,"mc":[{"id":"1.232050243","rc":[{"batb":[[1,1.58,10],[2,1.57,15.05]],"ltp":2.04,"tv":45.12,"id":72857117}]}]}
{"op":"mcm","clk":"11888251805","pt":1724235496066,"mc":[{"id":"1.232050243","rc":[{"batb":[[1,1.57,15.05],[2,1.04,1.53]],"ltp":2.04,"tv":45.12,"id":72857117}]}]}
{"op":"mcm","clk":"11888252979","pt":1724235510971,"mc":[{"id":"1.232050243","rc":[{"batl":[[0,1.97,1.54]],"ltp":1.95,"tv":34.24,"id":72857116}]}]}
{"op":"mcm","clk":"11888255842","pt":1724235546502,"mc":[{"id":"1.232050243","rc":[{"trd":[[1.97,3.07]],"batb":[[0,1.97,2.03],[1,1.95,3.02],[2,1.67,12.26]],"ltp":1.97,"tv":37.32,"id":72857116}],"tv":82.44}]}
{"op":"mcm","clk":"11888256152","pt":1724235549921,"mc":[{"id":"1.232050243","rc":[{"batb":[[1,1.67,12.26],[2,1.05,5.19]],"ltp":1.97,"tv":37.32,"id":72857116}]}]}
{"op":"mcm","clk":"11888256833","pt":1724235558843,"mc":[{"id":"1.232050243","rc":[{"batb":[[0,1.67,12.26],[1,1.05,5.19],[2,1.04,1.53]],"ltp":1.97,"tv":37.32,"id":72857116}]}]}
{"op":"mcm","clk":"11888257674","pt":1724235569637,"mc":[{"id":"1.232050243","rc":[{"trd":[[1.57,11.12],[1.72,5.59]],"batb":[[0,1.57,9.49],[1,1.04,1.53],[2,1.03,200]],"ltp":1.57,"tv":58.76,"id":72857117}],"tv":96.08}]}
{"op":"mcm","clk":"11888269635","pt":1724235719811,"mc":[{"id":"1.232050243","rc":[{"batb":[[0,1.57,10.43]],"ltp":1.57,"tv":58.76,"id":72857117}]}]}
{"op":"mcm","clk":"11888270468","pt":1724235730936,"mc":[{"id":"1.232050243","rc":[{"batb":[[0,1.58,10.94],[1,1.57,9.49],[2,1.04,1.53]],"batl":[[0,2.06,0.94]],"ltp":1.57,"tv":58.76,"id":72857117}]}]}
{"op":"mcm","clk":"11888270710","pt":1724235734215,"mc":[{"id":"1.232050243","rc":[{"batb":[[0,1.57,10.43],[1,1.04,1.53],[2,1.03,200]],"ltp":1.57,"tv":58.76,"id":72857117}]}]}
{"op":"mcm","clk":"11888272428","pt":1724235757023,"mc":[{"id":"1.232050243","rc":[{"batb":[[0,1.58,10.94],[1,1.57,9.49],[2,1.04,1.53]],"ltp":1.57,"tv":58.76,"id":72857117}]}]}
{"op":"mcm","clk":"11888272703","pt":1724235760873,"mc":[{"id":"1.232050243","rc":[{"batb":[[0,1.57,10.43],[1,1.04,1.53],[2,1.03,200]],"ltp":1.57,"tv":58.76,"id":72857117}]}]}
{"op":"mcm","clk":"11888273197","pt":1724235767780,"mc":[{"id":"1.232050243","rc":[{"batb":[[0,1.58,10.94],[1,1.57,9.49],[2,1.04,1.53]],"ltp":1.57,"tv":58.76,"id":72857117}]}]}
{"op":"mcm","clk":"11888273450","pt":1724235771351,"mc":[{"id":"1.232050243","rc":[{"batb":[[0,1.57,10.43],[1,1.04,1.53],[2,1.03,200]],"ltp":1.57,"tv":58.76,"id":72857117}]}]}
{"op":"mcm","clk":"11888275284","pt":1724235794988,"mc":[{"id":"1.232050243","rc":[{"batb":[[0,1.58,10.94],[1,1.57,9.49],[2,1.04,1.53]],"batl":[[0,2.18,0.94]],"ltp":1.57,"tv":58.76,"id":72857117}]}]}
{"op":"mcm","clk":"11888275541","pt":1724235798311,"mc":[{"id":"1.232050243","rc":[{"batb":[[0,1.57,10.43],[1,1.04,1.53],[2,1.03,200]],"ltp":1.57,"tv":58.76,"id":72857117}]}]}
{"op":"mcm","clk":"11888275731","pt":1724235800720,"mc":[{"id":"1.232050243","rc":[{"batb":[[0,1.58,10.94],[1,1.57,9.49],[2,1.04,1.53]],"batl":[[0,2.14,0.94]],"ltp":1.57,"tv":58.76,"id":72857117}]}]}
{"op":"mcm","clk":"11888275991","pt":1724235804116,"mc":[{"id":"1.232050243","rc":[{"batb":[[0,1.57,10.43],[1,1.04,1.53],[2,1.03,200]],"ltp":1.57,"tv":58.76,"id":72857117}]}]}
{"op":"mcm","clk":"11888278479","pt":1724235837462,"mc":[{"id":"1.232050243","rc":[{"batb":[[0,1.58,10.94],[1,1.57,9.49],[2,1.04,1.53]],"ltp":1.57,"tv":58.76,"id":72857117}]}]}
{"op":"mcm","clk":"11888278769","pt":1724235841476,"mc":[{"id":"1.232050243","rc":[{"batb":[[0,1.57,10.43],[1,1.04,1.53],[2,1.03,200]],"ltp":1.57,"tv":58.76,"id":72857117}]}]}
{"op":"mcm","clk":"11888287984","pt":1724235962809,"mc":[{"id":"1.232050243","rc":[{"batb":[[0,1.58,10.94],[1,1.57,9.49],[2,1.04,1.53]],"ltp":1.57,"tv":58.76,"id":72857117}]}]}
{"op":"mcm","clk":"11888288256","pt":1724235966444,"mc":[{"id":"1.232050243","rc":[{"batb":[[0,1.57,10.43],[1,1.04,1.53],[2,1.03,200]],"ltp":1.57,"tv":58.76,"id":72857117}]}]}
{"op":"mcm","clk":"11888291709","pt":1724236015700,"mc":[{"id":"1.232050243","rc":[{"batb":[[0,1.58,10.94],[1,1.57,9.49],[2,1.04,1.53]],"ltp":1.57,"tv":58.76,"id":72857117}]}]}
{"op":"mcm","clk":"11888291927","pt":1724236019077,"mc":[{"id":"1.232050243","rc":[{"batb":[[0,1.57,10.43],[1,1.04,1.53],[2,1.03,200]],"ltp":1.57,"tv":58.76,"id":72857117}]}]}
{"op":"mcm","clk":"11888311450","pt":1724236260610,"mc":[{"id":"1.232050243","rc":[{"batb":[[0,1.58,10.94],[1,1.57,9.49],[2,1.04,1.53]],"ltp":1.57,"tv":58.76,"id":72857117}]}]}
{"op":"mcm","clk":"11888311828","pt":1724236264609,"mc":[{"id":"1.232050243","rc":[{"batb":[[0,1.57,10.43],[1,1.04,1.53],[2,1.03,200]],"ltp":1.57,"tv":58.76,"id":72857117}]}]}
{"op":"mcm","clk":"11888314220","pt":1724236291938,"mc":[{"id":"1.232050243","rc":[{"batb":[[0,1.58,10.94],[1,1.57,9.49],[2,1.04,1.53]],"ltp":1.57,"tv":58.76,"id":72857117}]}]}
{"op":"mcm","clk":"11888314599","pt":1724236295650,"mc":[{"id":"1.232050243","rc":[{"batb":[[0,1.57,10.43],[1,1.04,1.53],[2,1.03,200]],"ltp":1.57,"tv":58.76,"id":72857117}]}]}
{"op":"mcm","clk":"11888316340","pt":1724236313652,"mc":[{"id":"1.232050243","rc":[{"batb":[[0,1.58,10.94],[1,1.57,9.49],[2,1.04,1.53]],"ltp":1.57,"tv":58.76,"id":72857117}]}]}
{"op":"mcm","clk":"11888316722","pt":1724236317801,"mc":[{"id":"1.232050243","rc":[{"batb":[[0,1.57,10.43],[1,1.04,1.53],[2,1.03,200]],"ltp":1.57,"tv":58.76,"id":72857117}]}]}
{"op":"mcm","clk":"11888323676","pt":1724236389597,"mc":[{"id":"1.232050243","rc":[{"batb":[[0,1.58,10.94],[1,1.57,9.49],[2,1.04,1.53]],"ltp":1.57,"tv":58.76,"id":72857117}]}]}
{"op":"mcm","clk":"11888324034","pt":1724236393323,"mc":[{"id":"1.232050243","rc":[{"batb":[[0,1.57,10.43],[1,1.04,1.53],[2,1.03,200]],"ltp":1.57,"tv":58.76,"id":72857117}]}]}
{"op":"mcm","clk":"11888327422","pt":1724236425531,"mc":[{"id":"1.232050243","rc":[{"batb":[[0,1.58,10.94],[1,1.57,9.49],[2,1.04,1.53]],"ltp":1.57,"tv":58.76,"id":72857117}]}]}
{"op":"mcm","clk":"11888327829","pt":1724236429430,"mc":[{"id":"1.232050243","rc":[{"batb":[[0,1.57,10.43],[1,1.04,1.53],[2,1.03,200]],"ltp":1.57,"tv":58.76,"id":72857117}]}]}
{"op":"mcm","clk":"11888331269","pt":1724236465462,"mc":[{"id":"1.232050243","rc":[{"batb":[[0,1.58,10.94],[1,1.57,9.49],[2,1.04,1.53]],"ltp":1.57,"tv":58.76,"id":72857117}]}]}
{"op":"mcm","clk":"11888331602","pt":1724236469277,"mc":[{"id":"1.232050243","rc":[{"batb":[[0,1.57,10.43],[1,1.04,1.53],[2,1.03,200]],"ltp":1.57,"tv":58.76,"id":72857117}]}]}
{"op":"mcm","clk":"11888333107","pt":1724236487718,"mc":[{"id":"1.232050243","rc":[{"batb":[[0,1.58,10.94],[1,1.57,9.49],[2,1.04,1.53]],"ltp":1.57,"tv":58.76,"id":72857117}]}]}
{"op":"mcm","clk":"11888333442","pt":1724236491713,"mc":[{"id":"1.232050243","rc":[{"batb":[[0,1.57,10.43],[1,1.04,1.53],[2,1.03,200]],"ltp":1.57,"tv":58.76,"id":72857117}]}]}
{"op":"mcm","clk":"11888336958","pt":1724236532248,"mc":[{"id":"1.232050243","rc":[{"batb":[[0,1.58,10.94],[1,1.57,9.49],[2,1.04,1.53]],"ltp":1.57,"tv":58.76,"id":72857117}]}]}
{"op":"mcm","clk":"11888337262","pt":1724236535763,"mc":[{"id":"1.232050243","rc":[{"batb":[[0,1.57,10.43],[1,1.04,1.53],[2,1.03,200]],"ltp":1.57,"tv":58.76,"id":72857117}]}]}
{"op":"mcm","clk":"11888340359","pt":1724236569294,"mc":[{"id":"1.232050243","rc":[{"batb":[[0,1.58,10.94],[1,1.57,9.49],[2,1.04,1.53]],"ltp":1.57,"tv":58.76,"id":72857117}]}]}
{"op":"mcm","clk":"11888340732","pt":1724236573122,"mc":[{"id":"1.232050243","rc":[{"batb":[[0,1.57,10.43],[1,1.04,1.53],[2,1.03,200]],"ltp":1.57,"tv":58.76,"id":72857117}]}]}
{"op":"mcm","clk":"11888345522","pt":1724236624867,"mc":[{"id":"1.232050243","rc":[{"batb":[[0,1.58,10.94],[1,1.57,9.49],[2,1.04,1.53]],"ltp":1.57,"tv":58.76,"id":72857117}]}]}
{"op":"mcm","clk":"11888345879","pt":1724236628568,"mc":[{"id":"1.232050243","rc":[{"batb":[[0,1.57,10.43],[1,1.04,1.53],[2,1.03,200]],"ltp":1.57,"tv":58.76,"id":72857117}]}]}
{"op":"mcm","clk":"11888346430","pt":1724236634800,"mc":[{"id":"1.232050243","rc":[{"batb":[[0,1.58,10.94],[1,1.57,9.49],[2,1.04,1.53]],"ltp":1.57,"tv":58.76,"id":72857117}]}]}
{"op":"mcm","clk":"11888346761","pt":1724236638385,"mc":[{"id":"1.232050243","rc":[{"batb":[[0,1.57,10.43],[1,1.04,1.53],[2,1.03,200]],"ltp":1.57,"tv":58.76,"id":72857117}]}]}
{"op":"mcm","clk":"11888347707","pt":1724236648220,"mc":[{"id":"1.232050243","rc":[{"batb":[[0,1.58,10.94],[1,1.57,9.49],[2,1.04,1.53]],"ltp":1.57,"tv":58.76,"id":72857117}]}]}
{"op":"mcm","clk":"11888348045","pt":1724236651768,"mc":[{"id":"1.232050243","rc":[{"batb":[[0,1.57,10.43],[1,1.04,1.53],[2,1.03,200]],"ltp":1.57,"tv":58.76,"id":72857117}]}]}
{"op":"mcm","clk":"11888349883","pt":1724236670284,"mc":[{"id":"1.232050243","rc":[{"batb":[[0,1.58,10.94],[1,1.57,9.49],[2,1.04,1.53]],"ltp":1.57,"tv":58.76,"id":72857117}]}]}
{"op":"mcm","clk":"11888350280","pt":1724236674444,"mc":[{"id":"1.232050243","rc":[{"batb":[[0,1.57,10.43],[1,1.04,1.53],[2,1.03,200]],"ltp":1.57,"tv":58.76,"id":72857117}]}]}
{"op":"mcm","clk":"11888350722","pt":1724236679025,"mc":[{"id":"1.232050243","rc":[{"batb":[[0,1.58,10.94],[1,1.57,9.49],[2,1.04,1.53]],"ltp":1.57,"tv":58.76,"id":72857117}]}]}
{"op":"mcm","clk":"11888351134","pt":1724236682840,"mc":[{"id":"1.232050243","rc":[{"batb":[[0,1.57,10.43],[1,1.04,1.53],[2,1.03,200]],"ltp":1.57,"tv":58.76,"id":72857117}]}]}
{"op":"mcm","clk":"11888353202","pt":1724236705947,"mc":[{"id":"1.232050243","rc":[{"batb":[[0,1.58,10.94],[1,1.57,9.49],[2,1.04,1.53]],"ltp":1.57,"tv":58.76,"id":72857117}]}]}
{"op":"mcm","clk":"11888353513","pt":1724236709731,"mc":[{"id":"1.232050243","rc":[{"batb":[[0,1.57,10.43],[1,1.04,1.53],[2,1.03,200]],"ltp":1.57,"tv":58.76,"id":72857117}]}]}
{"op":"mcm","clk":"11888359433","pt":1724236782624,"mc":[{"id":"1.232050243","rc":[{"batb":[[0,1.58,10.94],[1,1.57,9.49],[2,1.04,1.53]],"ltp":1.57,"tv":58.76,"id":72857117}]}]}
{"op":"mcm","clk":"11888359703","pt":1724236785955,"mc":[{"id":"1.232050243","rc":[{"batb":[[0,1.57,10.43],[1,1.04,1.53],[2,1.03,200]],"ltp":1.57,"tv":58.76,"id":72857117}]}]}
{"op":"mcm","clk":"11888363555","pt":1724236831391,"mc":[{"id":"1.232050243","rc":[{"batb":[[0,1.58,10.94],[1,1.57,9.49],[2,1.04,1.53]],"ltp":1.57,"tv":58.76,"id":72857117}]}]}
{"op":"mcm","clk":"11888363866","pt":1724236835398,"mc":[{"id":"1.232050243","rc":[{"batb":[[0,1.57,10.43],[1,1.04,1.53],[2,1.03,200]],"ltp":1.57,"tv":58.76,"id":72857117}]}]}
{"op":"mcm","clk":"11888366124","pt":1724236862441,"mc":[{"id":"1.232050243","rc":[{"batb":[[0,1.58,10.94],[1,1.57,9.49],[2,1.04,1.53]],"ltp":1.57,"tv":58.76,"id":72857117}]}]}
{"op":"mcm","clk":"11888366430","pt":1724236865923,"mc":[{"id":"1.232050243","rc":[{"batb":[[0,1.57,10.43],[1,1.04,1.53],[2,1.03,200]],"ltp":1.57,"tv":58.76,"id":72857117}]}]}
{"op":"mcm","clk":"11888368188","pt":1724236888365,"mc":[{"id":"1.232050243","rc":[{"batb":[[0,1.58,10.94],[1,1.57,9.49],[2,1.04,1.53]],"ltp":1.57,"tv":58.76,"id":72857117}]}]}
{"op":"mcm","clk":"11888368456","pt":1724236891574,"mc":[{"id":"1.232050243","rc":[{"batb":[[0,1.57,10.43],[1,1.04,1.53],[2,1.03,200]],"ltp":1.57,"tv":58.76,"id":72857117}]}]}
{"op":"mcm","clk":"11888368826","pt":1724236895855,"mc":[{"id":"1.232050243","rc":[{"batb":[[0,1.58,10.94],[1,1.57,9.49],[2,1.04,1.53]],"ltp":1.57,"tv":58.76,"id":72857117}]}]}
{"op":"mcm","clk":"11888369144","pt":1724236899790,"mc":[{"id":"1.232050243","rc":[{"batb":[[0,1.57,10.43],[1,1.04,1.53],[2,1.03,200]],"ltp":1.57,"tv":58.76,"id":72857117}]}]}
{"op":"mcm","clk":"11888369488","pt":1724236904358,"mc":[{"id":"1.232050243","rc":[{"batb":[[0,1.58,10.94],[1,1.57,9.49],[2,1.04,1.53]],"ltp":1.57,"tv":58.76,"id":72857117}]}]}
{"op":"mcm","clk":"11888369782","pt":1724236908396,"mc":[{"id":"1.232050243","rc":[{"batb":[[0,1.57,10.43],[1,1.04,1.53],[2,1.03,200]],"ltp":1.57,"tv":58.76,"id":72857117}]}]}
{"op":"mcm","clk":"11888371029","pt":1724236923871,"mc":[{"id":"1.232050243","rc":[{"batb":[[0,1.58,10.94],[1,1.57,9.49],[2,1.04,1.53]],"ltp":1.57,"tv":58.76,"id":72857117}]}]}
{"op":"mcm","clk":"11888371335","pt":1724236927612,"mc":[{"id":"1.232050243","rc":[{"batb":[[0,1.57,10.43],[1,1.04,1.53],[2,1.03,200]],"ltp":1.57,"tv":58.76,"id":72857117}]}]}
{"op":"mcm","clk":"11888372470","pt":1724236942209,"mc":[{"id":"1.232050243","rc":[{"batb":[[0,1.58,10.94],[1,1.57,9.49],[2,1.04,1.53]],"ltp":1.57,"tv":58.76,"id":72857117}]}]}
{"op":"mcm","clk":"11888372774","pt":1724236945933,"mc":[{"id":"1.232050243","rc":[{"batb":[[0,1.57,10.43],[1,1.04,1.53],[2,1.03,200]],"ltp":1.57,"tv":58.76,"id":72857117}]}]}
{"op":"mcm","clk":"11888373939","pt":1724236959343,"mc":[{"id":"1.232050243","rc":[{"batb":[[0,1.58,10.94],[1,1.57,9.49],[2,1.04,1.53]],"ltp":1.57,"tv":58.76,"id":72857117}]}]}
{"op":"mcm","clk":"11888374278","pt":1724236963458,"mc":[{"id":"1.232050243","rc":[{"batb":[[0,1.57,10.43],[1,1.04,1.53],[2,1.03,200]],"ltp":1.57,"tv":58.76,"id":72857117}]}]}
{"op":"mcm","clk":"11888377603","pt":1724237003792,"mc":[{"id":"1.232050243","rc":[{"batb":[[0,1.58,10.94],[1,1.57,9.49],[2,1.04,1.53]],"ltp":1.57,"tv":58.76,"id":72857117}]}]}
{"op":"mcm","clk":"11888377907","pt":1724237007733,"mc":[{"id":"1.232050243","rc":[{"batb":[[0,1.57,10.43],[1,1.04,1.53],[2,1.03,200]],"ltp":1.57,"tv":58.76,"id":72857117}]}]}
{"op":"mcm","clk":"11888379205","pt":1724237022543,"mc":[{"id":"1.232050243","rc":[{"batb":[[0,1.58,10.94],[1,1.57,9.49],[2,1.04,1.53]],"ltp":1.57,"tv":58.76,"id":72857117}]}]}
{"op":"mcm","clk":"11888379537","pt":1724237026244,"mc":[{"id":"1.232050243","rc":[{"batb":[[0,1.57,10.43],[1,1.04,1.53],[2,1.03,200]],"ltp":1.57,"tv":58.76,"id":72857117}]}]}
{"op":"mcm","clk":"11888379730","pt":1724237028733,"mc":[{"id":"1.232050243","rc":[{"batb":[[0,1.58,10.94],[1,1.57,9.49],[2,1.04,1.53]],"ltp":1.57,"tv":58.76,"id":72857117}]}]}
{"op":"mcm","clk":"11888380036","pt":1724237032569,"mc":[{"id":"1.232050243","rc":[{"batb":[[0,1.57,10.43],[1,1.04,1.53],[2,1.03,200]],"ltp":1.57,"tv":58.76,"id":72857117}]}]}
{"op":"mcm","clk":"11888380668","pt":1724237039530,"mc":[{"id":"1.232050243","rc":[{"batb":[[0,1.58,10.94],[1,1.57,9.49],[2,1.04,1.53]],"ltp":1.57,"tv":58.76,"id":72857117}]}]}
{"op":"mcm","clk":"11888380950","pt":1724237043161,"mc":[{"id":"1.232050243","rc":[{"batb":[[0,1.57,10.43],[1,1.04,1.53],[2,1.03,200]],"ltp":1.57,"tv":58.76,"id":72857117}]}]}
{"op":"mcm","clk":"11888382154","pt":1724237056371,"mc":[{"id":"1.232050243","rc":[{"batb":[[0,1.58,10.94],[1,1.57,9.49],[2,1.04,1.53]],"ltp":1.57,"tv":58.76,"id":72857117}]}]}
{"op":"mcm","clk":"11888382481","pt":1724237060272,"mc":[{"id":"1.232050243","rc":[{"batb":[[0,1.57,10.43],[1,1.04,1.53],[2,1.03,200]],"ltp":1.57,"tv":58.76,"id":72857117}]}]}
{"op":"mcm","clk":"11888383403","pt":1724237071807,"mc":[{"id":"1.232050243","rc":[{"batb":[[0,1.58,10.94],[1,1.57,9.49],[2,1.04,1.53]],"ltp":1.57,"tv":58.76,"id":72857117}]}]}
{"op":"mcm","clk":"11888383700","pt":1724237075382,"mc":[{"id":"1.232050243","rc":[{"batb":[[0,1.57,10.43],[1,1.04,1.53],[2,1.03,200]],"ltp":1.57,"tv":58.76,"id":72857117}]}]}
{"op":"mcm","clk":"11888386915","pt":1724237111895,"mc":[{"id":"1.232050243","rc":[{"batb":[[0,1.05,5.19],[1,1.04,1.53],[2,1.03,200]],"ltp":1.97,"tv":37.32,"id":72857116},{"batb":[[0,1.58,10.94]],"ltp":1.57,"tv":58.76,"id":72857117}]}]}
{"op":"mcm","clk":"11888387355","pt":1724237115505,"mc":[{"id":"1.232050243","rc":[{"batb":[[0,1.04,2.47],[1,1.03,200],[2,1.02,200]],"ltp":1.57,"tv":58.76,"id":72857117}]}]}
{"op":"mcm","clk":"11888424039","pt":1724237533104,"mc":[{"id":"1.232050243","rc":[{"batb":[[0,1.21,84.21],[1,1.04,1.53],[2,1.03,200]],"ltp":1.57,"tv":58.76,"id":72857117}]}]}
{"op":"mcm","clk":"11888424062","pt":1724237533337,"mc":[{"id":"1.232050243","rc":[{"batb":[[0,1.22,10.94],[1,1.21,83.27],[2,1.04,1.53]],"ltp":1.57,"tv":58.76,"id":72857117}]}]}
{"op":"mcm","clk":"11888424362","pt":1724237536633,"mc":[{"id":"1.232050243","rc":[{"batb":[[0,1.21,84.21],[1,1.04,1.53],[2,1.03,200]],"ltp":1.57,"tv":58.76,"id":72857117}]}]}
{"op":"mcm","clk":"11888425224","pt":1724237546110,"mc":[{"id":"1.232050243","rc":[{"batb":[[0,1.21,83.27],[1,1.05,5.19],[2,1.04,1.53]],"ltp":1.97,"tv":37.32,"id":72857116},{"batb":[[0,1.22,10.94],[1,1.21,83.27],[2,1.04,1.53]],"ltp":1.57,"tv":58.76,"id":72857117}]}]}
{"op":"mcm","clk":"11888425459","pt":1724237549421,"mc":[{"id":"1.232050243","rc":[{"batb":[[0,1.21,84.21],[1,1.04,1.53],[2,1.03,200]],"ltp":1.57,"tv":58.76,"id":72857117}]}]}
{"op":"mcm","clk":"11888432261","pt":1724237631823,"mc":[{"id":"1.232050243","rc":[{"batb":[[0,1.22,10.94],[1,1.21,83.27],[2,1.04,1.53]],"ltp":1.57,"tv":58.76,"id":72857117}]}]}
{"op":"mcm","clk":"11888432528","pt":1724237635447,"mc":[{"id":"1.232050243","rc":[{"batb":[[0,1.21,84.21],[1,1.04,1.53],[2,1.03,200]],"ltp":1.57,"tv":58.76,"id":72857117}]}]}
{"op":"mcm","clk":"11888437273","pt":1724237705044,"mc":[{"id":"1.232050243","rc":[{"batb":[[0,1.22,10.94],[1,1.21,83.27],[2,1.04,1.53]],"ltp":1.57,"tv":58.76,"id":72857117}]}]}
{"op":"mcm","clk":"11888437509","pt":1724237708405,"mc":[{"id":"1.232050243","rc":[{"batb":[[0,1.21,84.21],[1,1.04,1.53],[2,1.03,200]],"ltp":1.57,"tv":58.76,"id":72857117}]}]}
{"op":"mcm","clk":"11888438345","pt":1724237721419,"mc":[{"id":"1.232050243","rc":[{"batb":[[0,1.22,10.94],[1,1.21,83.27],[2,1.04,1.53]],"ltp":1.57,"tv":58.76,"id":72857117}]}]}
{"op":"mcm","clk":"11888438568","pt":1724237724825,"mc":[{"id":"1.232050243","rc":[{"batb":[[0,1.21,84.21],[1,1.04,1.53],[2,1.03,200]],"ltp":1.57,"tv":58.76,"id":72857117}]}]}
{"op":"mcm","clk":"11888440709","pt":1724237760667,"mc":[{"id":"1.232050243","rc":[{"batb":[[0,1.22,10.94],[1,1.21,83.27],[2,1.04,1.53]],"ltp":1.57,"tv":58.76,"id":72857117}]}]}
{"op":"mcm","clk":"11888440953","pt":1724237764489,"mc":[{"id":"1.232050243","rc":[{"batb":[[0,1.21,84.21],[1,1.04,1.53],[2,1.03,200]],"ltp":1.57,"tv":58.76,"id":72857117}]}]}
{"op":"mcm","clk":"11888441967","pt":1724237779137,"mc":[{"id":"1.232050243","rc":[{"batb":[[0,1.22,10.94],[1,1.21,83.27],[2,1.04,1.53]],"ltp":1.57,"tv":58.76,"id":72857117}]}]}
{"op":"mcm","clk":"11888442240","pt":1724237782945,"mc":[{"id":"1.232050243","rc":[{"batb":[[0,1.21,84.21],[1,1.04,1.53],[2,1.03,200]],"ltp":1.57,"tv":58.76,"id":72857117}]}]}
{"op":"mcm","clk":"11888442719","pt":1724237790420,"mc":[{"id":"1.232050243","rc":[{"batb":[[0,1.22,10.94],[1,1.21,83.27],[2,1.04,1.53]],"ltp":1.57,"tv":58.76,"id":72857117}]}]}
{"op":"mcm","clk":"11888442991","pt":1724237794246,"mc":[{"id":"1.232050243","rc":[{"batb":[[0,1.21,84.21],[1,1.04,1.53],[2,1.03,200]],"ltp":1.57,"tv":58.76,"id":72857117}]}]}
{"op":"mcm","clk":"11888443412","pt":1724237800465,"mc":[{"id":"1.232050243","rc":[{"batb":[[0,1.22,10.94],[1,1.21,83.27],[2,1.04,1.53]],"ltp":1.57,"tv":58.76,"id":72857117}]}]}
{"op":"mcm","clk":"11888443646","pt":1724237804478,"mc":[{"id":"1.232050243","rc":[{"batb":[[0,1.21,84.21],[1,1.04,1.53],[2,1.03,200]],"ltp":1.57,"tv":58.76,"id":72857117}]}]}
{"op":"mcm","clk":"11888444059","pt":1724237810776,"mc":[{"id":"1.232050243","rc":[{"batb":[[0,1.22,10.94],[1,1.21,83.27],[2,1.04,1.53]],"ltp":1.57,"tv":58.76,"id":72857117}]}]}
{"op":"mcm","clk":"11888444286","pt":1724237814451,"mc":[{"id":"1.232050243","rc":[{"batb":[[0,1.21,84.21],[1,1.04,1.53],[2,1.03,200]],"ltp":1.57,"tv":58.76,"id":72857117}]}]}
{"op":"mcm","clk":"11888445171","pt":1724237826965,"mc":[{"id":"1.232050243","rc":[{"batb":[[0,1.22,10.94],[1,1.21,83.27],[2,1.04,1.53]],"ltp":1.57,"tv":58.76,"id":72857117}]}]}
{"op":"mcm","clk":"11888445441","pt":1724237830572,"mc":[{"id":"1.232050243","rc":[{"batb":[[0,1.21,84.21],[1,1.04,1.53],[2,1.03,200]],"ltp":1.57,"tv":58.76,"id":72857117}]}]}
{"op":"mcm","clk":"11888446138","pt":1724237840994,"mc":[{"id":"1.232050243","rc":[{"batb":[[0,1.22,10.94],[1,1.21,83.27],[2,1.04,1.53]],"ltp":1.57,"tv":58.76,"id":72857117}]}]}
{"op":"mcm","clk":"11888446441","pt":1724237844581,"mc":[{"id":"1.232050243","rc":[{"batb":[[0,1.21,84.21],[1,1.04,1.53],[2,1.03,200]],"ltp":1.57,"tv":58.76,"id":72857117}]}]}
{"op":"mcm","clk":"11888448937","pt":1724237881567,"mc":[{"id":"1.232050243","rc":[{"batb":[[0,1.22,10.94],[1,1.21,83.27],[2,1.04,1.53]],"ltp":1.57,"tv":58.76,"id":72857117}]}]}
{"op":"mcm","clk":"11888449217","pt":1724237885166,"mc":[{"id":"1.232050243","rc":[{"batb":[[0,1.21,84.21],[1,1.04,1.53],[2,1.03,200]],"ltp":1.57,"tv":58.76,"id":72857117}]}]}
{"op":"mcm","clk":"11888449731","pt":1724237892978,"mc":[{"id":"1.232050243","rc":[{"batb":[[0,1.22,10.94],[1,1.21,83.27],[2,1.04,1.53]],"ltp":1.57,"tv":58.76,"id":72857117}]}]}
{"op":"mcm","clk":"11888449971","pt":1724237896844,"mc":[{"id":"1.232050243","rc":[{"batb":[[0,1.21,84.21],[1,1.04,1.53],[2,1.03,200]],"ltp":1.57,"tv":58.76,"id":72857117}]}]}
{"op":"mcm","clk":"11888450489","pt":1724237905103,"mc":[{"id":"1.232050243","rc":[{"batb":[[0,1.22,10.94],[1,1.21,83.27],[2,1.04,1.53]],"ltp":1.57,"tv":58.76,"id":72857117}]}]}
{"op":"mcm","clk":"11888450730","pt":1724237908796,"mc":[{"id":"1.232050243","rc":[{"batb":[[0,1.21,84.21],[1,1.04,1.53],[2,1.03,200]],"ltp":1.57,"tv":58.76,"id":72857117}]}]}
{"op":"mcm","clk":"11888453443","pt":1724237947028,"mc":[{"id":"1.232050243","rc":[{"batb":[[0,1.22,10.94],[1,1.21,83.27],[2,1.04,1.53]],"ltp":1.57,"tv":58.76,"id":72857117}]}]}
{"op":"mcm","clk":"11888453704","pt":1724237950549,"mc":[{"id":"1.232050243","rc":[{"batb":[[0,1.21,84.21],[1,1.04,1.53],[2,1.03,200]],"ltp":1.57,"tv":58.76,"id":72857117}]}]}
{"op":"mcm","clk":"11888456478","pt":1724237987985,"mc":[{"id":"1.232050243","rc":[{"batb":[[0,1.22,10.94],[1,1.21,83.27],[2,1.04,1.53]],"ltp":1.57,"tv":58.76,"id":72857117}]}]}
{"op":"mcm","clk":"11888457009","pt":1724237994384,"mc":[{"id":"1.232050243","rc":[{"batb":[[0,1.21,84.21],[1,1.04,1.53],[2,1.03,200]],"ltp":1.57,"tv":58.76,"id":72857117}]}]}
{"op":"mcm","clk":"11888457369","pt":1724237999191,"mc":[{"id":"1.232050243","rc":[{"batb":[[0,1.22,10.94],[1,1.21,83.27],[2,1.04,1.53]],"ltp":1.57,"tv":58.76,"id":72857117}]}]}
{"op":"mcm","clk":"11888457678","pt":1724238002700,"mc":[{"id":"1.232050243","rc":[{"batb":[[0,1.21,84.21],[1,1.04,1.53],[2,1.03,200]],"ltp":1.57,"tv":58.76,"id":72857117}]}]}
{"op":"mcm","clk":"11888458076","pt":1724238007328,"mc":[{"id":"1.232050243","rc":[{"trd":[[1.55,1.53],[1.62,1.87],[1.7,3.88],[1.72,1.77],[1.8,3.07],[1.83,4.19],[1.88,3.07],[1.89,1.05],[1.93,3.07],[1.94,1.53],[1.95,2.09],[1.96,1.16],[1.97,3.07],[1.98,0.96],[2.42,1.15],[2.5,1.53]],"batb":[[0,1.21,83.24]],"ltp":1.97,"tv":37.27,"id":72857116},{"trd":[[1.55,1.15],[1.57,11.11],[1.62,0.94],[1.66,5.37],[1.68,4.94],[1.7,12.11],[1.72,5.58],[1.75,3.07],[1.8,3.07],[2.02,0.94],[2.04,3.8],[2.06,1.44],[2.12,0.94],[2.2,0.94],[2.38,0.94],[2.8,0.85]],"batb":[[0,1.22,10.94],[1,1.21,83.24],[2,1.04,1.53]],"batl":[[0,2.14,0.94]],"ltp":1.57,"tv":58.69,"id":72857117}],"tv":95.97}]}
{"op":"mcm","clk":"11888458326","pt":1724238011429,"mc":[{"id":"1.232050243","rc":[{"batb":[[0,1.21,84.18],[1,1.04,1.53],[2,1.03,200]],"ltp":1.57,"tv":58.69,"id":72857117}]}]}
{"op":"mcm","clk":"11888458875","pt":1724238017936,"mc":[{"id":"1.232050243","rc":[{"batb":[[0,1.22,10],[1,1.21,83.24],[2,1.04,1.53]],"ltp":1.57,"tv":58.69,"id":72857117}]}]}
{"op":"mcm","clk":"11888459126","pt":1724238021240,"mc":[{"id":"1.232050243","rc":[{"batb":[[0,1.21,83.24],[1,1.04,1.53],[2,1.03,200]],"ltp":1.57,"tv":58.69,"id":72857117}]}]}
{"op":"mcm","clk":"11888460314","pt":1724238036871,"mc":[{"id":"1.232050243","rc":[{"batb":[[0,1.3,3.91],[1,1.21,83.24],[2,1.04,1.53]],"ltp":1.57,"tv":58.69,"id":72857117}]}]}
{"op":"mcm","clk":"11888461192","pt":1724238048652,"mc":[{"id":"1.232050243","rc":[{"batb":[[0,1.31,14],[1,1.3,3.91],[2,1.21,83.24]],"batl":[[0,4,3.05]],"ltp":1.57,"tv":58.69,"id":72857117}]}]}
{"op":"mcm","clk":"11888461394","pt":1724238051183,"mc":[{"id":"1.232050243","rc":[{"batb":[[0,1.31,10]],"ltp":1.57,"tv":58.69,"id":72857117}]}]}
{"op":"mcm","clk":"11888461464","pt":1724238051963,"mc":[{"id":"1.232050243","rc":[{"batb":[[0,1.3,3.91],[1,1.21,83.24],[2,1.04,1.53]],"ltp":1.57,"tv":58.69,"id":72857117}]}]}
{"op":"mcm","clk":"11888461681","pt":1724238054693,"mc":[{"id":"1.232050243","rc":[{"batb":[[0,1.34,3.91],[1,1.22,14],[2,1.21,83.24]],"ltp":1.57,"tv":58.69,"id":72857117}]}]}
{"op":"mcm","clk":"11888461839","pt":1724238056875,"mc":[{"id":"1.232050243","rc":[{"batb":[[1,1.22,10]],"ltp":1.57,"tv":58.69,"id":72857117}]}]}
{"op":"mcm","clk":"11888461926","pt":1724238057970,"mc":[{"id":"1.232050243","rc":[{"batb":[[1,1.21,83.24],[2,1.04,1.53]],"ltp":1.57,"tv":58.69,"id":72857117}]}]}
{"op":"mcm","clk":"11888463808","pt":1724238080922,"mc":[{"id":"1.232050243","rc":[{"batb":[[0,1.35,14],[1,1.34,3.91],[2,1.21,83.24]],"batl":[[0,4,3.98]],"ltp":1.57,"tv":58.69,"id":72857117}]}]}
{"op":"mcm","clk":"11888464013","pt":1724238083213,"mc":[{"id":"1.232050243","rc":[{"batb":[[0,1.35,10]],"ltp":1.57,"tv":58.69,"id":72857117}]}]}
{"op":"mcm","clk":"11888464118","pt":1724238084406,"mc":[{"id":"1.232050243","rc":[{"batb":[[0,1.34,3.91],[1,1.21,83.24],[2,1.04,1.53]],"ltp":1.57,"tv":58.69,"id":72857117}]}]}
{"op":"mcm","clk":"11888465041","pt":1724238095034,"mc":[{"id":"1.232050243","rc":[{"batb":[[0,1.35,14],[1,1.34,3.91],[2,1.21,83.24]],"ltp":1.57,"tv":58.69,"id":72857117}]}]}
{"op":"mcm","clk":"11888465249","pt":1724238097352,"mc":[{"id":"1.232050243","rc":[{"batb":[[0,1.35,10]],"ltp":1.57,"tv":58.69,"id":72857117}]}]}
{"op":"mcm","clk":"11888465385","pt":1724238098851,"mc":[{"id":"1.232050243","rc":[{"batb":[[0,1.34,3.91],[1,1.21,83.24],[2,1.04,1.53]],"ltp":1.57,"tv":58.69,"id":72857117}]}]}
{"op":"mcm","clk":"11888466506","pt":1724238112962,"mc":[{"id":"1.232050243","rc":[{"batb":[[0,1.35,14],[1,1.34,3.91],[2,1.21,83.24]],"ltp":1.57,"tv":58.69,"id":72857117}]}]}
{"op":"mcm","clk":"11888466932","pt":1724238117147,"mc":[{"id":"1.232050243","rc":[{"batb":[[0,1.34,3.91],[1,1.21,83.24],[2,1.04,1.53]],"ltp":1.57,"tv":58.69,"id":72857117}]}]}
{"op":"mcm","clk":"11888467956","pt":1724238128788,"mc":[{"id":"1.232050243","rc":[{"batb":[[0,1.35,14],[1,1.34,3.91],[2,1.21,83.24]],"ltp":1.57,"tv":58.69,"id":72857117}]}]}
{"op":"mcm","clk":"11888468203","pt":1724238131571,"mc":[{"id":"1.232050243","rc":[{"batb":[[0,1.35,10]],"ltp":1.57,"tv":58.69,"id":72857117}]}]}
{"op":"mcm","clk":"11888468281","pt":1724238132557,"mc":[{"id":"1.232050243","rc":[{"batb":[[0,1.34,3.91],[1,1.21,83.24],[2,1.04,1.53]],"ltp":1.57,"tv":58.69,"id":72857117}]}]}
{"op":"mcm","clk":"11888468666","pt":1724238137197,"mc":[{"id":"1.232050243","rc":[{"batb":[[0,1.35,14],[1,1.34,3.91],[2,1.21,83.24]],"ltp":1.57,"tv":58.69,"id":72857117}]}]}
{"op":"mcm","clk":"11888468906","pt":1724238139995,"mc":[{"id":"1.232050243","rc":[{"batb":[[0,1.35,10]],"ltp":1.57,"tv":58.69,"id":72857117}]}]}
{"op":"mcm","clk":"11888468984","pt":1724238140978,"mc":[{"id":"1.232050243","rc":[{"batb":[[0,1.34,3.91],[1,1.21,83.24],[2,1.04,1.53]],"ltp":1.57,"tv":58.69,"id":72857117}]}]}
{"op":"mcm","clk":"11888469190","pt":1724238143496,"mc":[{"id":"1.232050243","rc":[{"batb":[[0,1.35,14],[1,1.34,3.91],[2,1.21,83.24]],"ltp":1.57,"tv":58.69,"id":72857117}]}]}
{"op":"mcm","clk":"11888469420","pt":1724238146183,"mc":[{"id":"1.232050243","rc":[{"batb":[[0,1.35,10]],"ltp":1.57,"tv":58.69,"id":72857117}]}]}
{"op":"mcm","clk":"11888469514","pt":1724238147315,"mc":[{"id":"1.232050243","rc":[{"batb":[[0,1.34,3.91],[1,1.21,83.24],[2,1.04,1.53]],"ltp":1.57,"tv":58.69,"id":72857117}]}]}
{"op":"mcm","clk":"11888471029","pt":1724238164830,"mc":[{"id":"1.232050243","rc":[{"batb":[[0,1.35,14],[1,1.34,3.91],[2,1.21,83.24]],"ltp":1.57,"tv":58.69,"id":72857117}]}]}
{"op":"mcm","clk":"11888471259","pt":1724238167519,"mc":[{"id":"1.232050243","rc":[{"batb":[[0,1.35,10]],"ltp":1.57,"tv":58.69,"id":72857117}]}]}
{"op":"mcm","clk":"11888471392","pt":1724238168548,"mc":[{"id":"1.232050243","rc":[{"batb":[[0,1.34,3.91],[1,1.21,83.24],[2,1.04,1.53]],"ltp":1.57,"tv":58.69,"id":72857117}]}]}
{"op":"mcm","clk":"11888472483","pt":1724238180262,"mc":[{"id":"1.232050243","rc":[{"batb":[[0,1.35,14],[1,1.34,3.91],[2,1.21,83.24]],"ltp":1.57,"tv":58.69,"id":72857117}]}]}
{"op":"mcm","clk":"11888473535","pt":1724238191564,"mc":[{"id":"1.232050243","rc":[{"batb":[[0,1.35,10]],"ltp":1.57,"tv":58.69,"id":72857117}]}]}
{"op":"mcm","clk":"11888473612","pt":1724238192390,"mc":[{"id":"1.232050243","rc":[{"batb":[[0,1.34,3.91],[1,1.21,83.24],[2,1.04,1.53]],"ltp":1.57,"tv":58.69,"id":72857117}]}]}
{"op":"mcm","clk":"11888473805","pt":1724238194355,"mc":[{"id":"1.232050243","rc":[{"batb":[[0,1.36,4],[1,1.34,3.91],[2,1.21,83.24]],"ltp":1.57,"tv":58.69,"id":72857117}]}]}
{"op":"mcm","clk":"11888474001","pt":1724238196780,"mc":[{"id":"1.232050243","rc":[{"batb":[[0,1.36,14]],"ltp":1.57,"tv":58.69,"id":72857117}]}]}
{"op":"mcm","clk":"11888474804","pt":1724238204582,"mc":[{"id":"1.232050243","rc":[{"batb":[[0,1.36,10]],"ltp":1.57,"tv":58.69,"id":72857117}]}]}
{"op":"mcm","clk":"11888475123","pt":1724238207564,"mc":[{"id":"1.232050243","rc":[{"batb":[[0,1.37,4],[1,1.36,10],[2,1.34,3.91]],"ltp":1.57,"tv":58.69,"id":72857117}]}]}
{"op":"mcm","clk":"11888475207","pt":1724238208490,"mc":[{"id":"1.232050243","rc":[{"batb":[[1,1.34,3.91],[2,1.21,83.24]],"ltp":1.57,"tv":58.69,"id":72857117}]}]}
{"op":"mcm","clk":"11888475554","pt":1724238212415,"mc":[{"id":"1.232050243","rc":[{"batb":[[0,1.38,10],[1,1.37,4],[2,1.34,3.91]],"ltp":1.57,"tv":58.69,"id":72857117}]}]}
{"op":"mcm","clk":"11888475792","pt":1724238214584,"mc":[{"id":"1.232050243","rc":[{"batb":[[1,1.34,3.91],[2,1.21,83.24]],"ltp":1.57,"tv":58.69,"id":72857117}]}]}
{"op":"mcm","clk":"11888476096","pt":1724238217224,"mc":[{"id":"1.232050243","rc":[{"batb":[[0,1.39,4],[1,1.38,10],[2,1.34,3.91]],"ltp":1.57,"tv":58.69,"id":72857117}]}]}
{"op":"mcm","clk":"11888476255","pt":1724238218986,"mc":[{"id":"1.232050243","rc":[{"batb":[[1,1.34,3.91],[2,1.21,83.24]],"ltp":1.57,"tv":58.69,"id":72857117}]}]}
{"op":"mcm","clk":"11888476474","pt":1724238221727,"mc":[{"id":"1.232050243","rc":[{"batb":[[0,1.4,10],[1,1.39,4],[2,1.34,3.91]],"ltp":1.57,"tv":58.69,"id":72857117}]}]}
{"op":"mcm","clk":"11888476545","pt":1724238222500,"mc":[{"id":"1.232050243","rc":[{"batb":[[1,1.34,3.91],[2,1.21,83.24]],"ltp":1.57,"tv":58.69,"id":72857117}]}]}
{"op":"mcm","clk":"11888476905","pt":1724238226624,"mc":[{"id":"1.232050243","rc":[{"batb":[[0,1.34,3.91],[1,1.21,83.24],[2,1.04,1.53]],"ltp":1.57,"tv":58.69,"id":72857117}]}]}
{"op":"mcm","clk":"11888476962","pt":1724238227313,"mc":[{"id":"1.232050243","rc":[{"batb":[[0,1.35,4],[1,1.34,3.91],[2,1.21,83.24]],"ltp":1.57,"tv":58.69,"id":72857117}]}]}
{"op":"mcm","clk":"11888477190","pt":1724238229835,"mc":[{"id":"1.232050243","rc":[{"batb":[[0,1.35,10]],"ltp":1.57,"tv":58.69,"id":72857117}]}]}
{"op":"mcm","clk":"11888477470","pt":1724238233038,"mc":[{"id":"1.232050243","rc":[{"batb":[[0,1.34,3.91],[1,1.21,83.24],[2,1.04,1.53]],"ltp":1.57,"tv":58.69,"id":72857117}]}]}
{"op":"mcm","clk":"11888477504","pt":1724238233448,"mc":[{"id":"1.232050243","rc":[{"batb":[[0,1.35,4],[1,1.34,3.91],[2,1.21,83.24]],"ltp":1.57,"tv":58.69,"id":72857117}]}]}
{"op":"mcm","clk":"11888477693","pt":1724238235821,"mc":[{"id":"1.232050243","rc":[{"batb":[[0,1.34,3.91],[1,1.21,83.24],[2,1.04,1.53]],"ltp":1.57,"tv":58.69,"id":72857117}]}]}
{"op":"mcm","clk":"11888477727","pt":1724238236232,"mc":[{"id":"1.232050243","rc":[{"batb":[[0,1.35,10],[1,1.34,3.91],[2,1.21,83.24]],"ltp":1.57,"tv":58.69,"id":72857117}]}]}
{"op":"mcm","clk":"11888478028","pt":1724238239633,"mc":[{"id":"1.232050243","rc":[{"batb":[[0,1.34,3.91],[1,1.21,83.24],[2,1.04,1.53]],"ltp":1.57,"tv":58.69,"id":72857117}]}]}
{"op":"mcm","clk":"11888478677","pt":1724238246425,"mc":[{"id":"1.232050243","rc":[{"batb":[[0,1.35,14],[1,1.34,3.91],[2,1.21,83.24]],"ltp":1.57,"tv":58.69,"id":72857117}]}]}
{"op":"mcm","clk":"11888479589","pt":1724238255957,"mc":[{"id":"1.232050243","rc":[{"batb":[[0,1.35,10]],"ltp":1.57,"tv":58.69,"id":72857117}]}]}
{"op":"mcm","clk":"11888479693","pt":1724238256894,"mc":[{"id":"1.232050243","rc":[{"batb":[[0,1.34,3.91],[1,1.21,83.24],[2,1.04,1.53]],"ltp":1.57,"tv":58.69,"id":72857117}]}]}
{"op":"mcm","clk":"11888479983","pt":1724238259555,"mc":[{"id":"1.232050243","rc":[{"batb":[[0,1.36,14],[1,1.34,3.91],[2,1.21,83.24]],"ltp":1.57,"tv":58.69,"id":72857117}]}]}
{"op":"mcm","clk":"11888480491","pt":1724238264472,"mc":[{"id":"1.232050243","rc":[{"batb":[[0,1.36,10]],"ltp":1.57,"tv":58.69,"id":72857117}]}]}
{"op":"mcm","clk":"11888480615","pt":1724238265566,"mc":[{"id":"1.232050243","rc":[{"batb":[[0,1.34,3.91],[1,1.21,83.24],[2,1.04,1.53]],"ltp":1.57,"tv":58.69,"id":72857117}]}]}
{"op":"mcm","clk":"11888480724","pt":1724238266702,"mc":[{"id":"1.232050243","rc":[{"batb":[[0,1.35,4],[1,1.34,3.91],[2,1.21,83.24]],"ltp":1.57,"tv":58.69,"id":72857117}]}]}
{"op":"mcm","clk":"11888480840","pt":1724238267991,"mc":[{"id":"1.232050243","rc":[{"batb":[[0,1.36,10],[1,1.35,4],[2,1.34,3.91]],"ltp":1.57,"tv":58.69,"id":72857117}]}]}
{"op":"mcm","clk":"11888481055","pt":1724238269907,"mc":[{"id":"1.232050243","rc":[{"batb":[[1,1.34,3.91],[2,1.21,83.24]],"ltp":1.57,"tv":58.69,"id":72857117}]}]}
{"op":"mcm","clk":"11888481347","pt":1724238272566,"mc":[{"id":"1.232050243","rc":[{"batb":[[0,1.35,4]],"ltp":1.57,"tv":58.69,"id":72857117}]}]}
{"op":"mcm","clk":"11888481582","pt":1724238274894,"mc":[{"id":"1.232050243","rc":[{"batb":[[0,1.34,3.91],[1,1.21,83.24],[2,1.04,1.53]],"ltp":1.57,"tv":58.69,"id":72857117}]}]}
{"op":"mcm","clk":"11888481628","pt":1724238275421,"mc":[{"id":"1.232050243","rc":[{"batb":[[0,1.35,10],[1,1.34,3.91],[2,1.21,83.24]],"ltp":1.57,"tv":58.69,"id":72857117}]}]}
{"op":"mcm","clk":"11888481855","pt":1724238277908,"mc":[{"id":"1.232050243","rc":[{"batb":[[0,1.36,4],[1,1.35,10],[2,1.34,3.91]],"ltp":1.57,"tv":58.69,"id":72857117}]}]}
{"op":"mcm","clk":"11888481944","pt":1724238278797,"mc":[{"id":"1.232050243","rc":[{"batb":[[1,1.34,3.91],[2,1.21,83.24]],"ltp":1.57,"tv":58.69,"id":72857117}]}]}
{"op":"mcm","clk":"11888482109","pt":1724238280305,"mc":[{"id":"1.232050243","rc":[{"batb":[[0,1.34,3.91],[1,1.21,83.24],[2,1.04,1.53]],"ltp":1.57,"tv":58.69,"id":72857117}]}]}
{"op":"mcm","clk":"11888482789","pt":1724238287086,"mc":[{"id":"1.232050243","rc":[{"batb":[[0,1.35,14],[1,1.34,3.91],[2,1.21,83.24]],"ltp":1.57,"tv":58.69,"id":72857117}]}]}
{"op":"mcm","clk":"11888483720","pt":1724238296900,"mc":[{"id":"1.232050243","rc":[{"batb":[[0,1.35,10]],"ltp":1.57,"tv":58.69,"id":72857117}]}]}
{"op":"mcm","clk":"11888483802","pt":1724238297829,"mc":[{"id":"1.232050243","rc":[{"batb":[[0,1.34,3.91],[1,1.21,83.24],[2,1.04,1.53]],"ltp":1.57,"tv":58.69,"id":72857117}]}]}
{"op":"mcm","clk":"11888484528","pt":1724238305038,"mc":[{"id":"1.232050243","rc":[{"batb":[[0,1.36,14],[1,1.34,3.91],[2,1.21,83.24]],"ltp":1.57,"tv":58.69,"id":72857117}]}]}
{"op":"mcm","clk":"11888485182","pt":1724238312045,"mc":[{"id":"1.232050243","rc":[{"batb":[[0,1.36,10]],"ltp":1.57,"tv":58.69,"id":72857117}]}]}
{"op":"mcm","clk":"11888485257","pt":1724238312932,"mc":[{"id":"1.232050243","rc":[{"batb":[[0,1.34,3.91],[1,1.21,83.24],[2,1.04,1.53]],"ltp":1.57,"tv":58.69,"id":72857117}]}]}
{"op":"mcm","clk":"11888485568","pt":1724238316156,"mc":[{"id":"1.232050243","rc":[{"batb":[[0,1.37,14],[1,1.34,3.91],[2,1.21,83.24]],"ltp":1.57,"tv":58.69,"id":72857117}]}]}
{"op":"mcm","clk":"11888486096","pt":1724238321563,"mc":[{"id":"1.232050243","rc":[{"batb":[[0,1.37,10]],"ltp":1.57,"tv":58.69,"id":72857117}]}]}
{"op":"mcm","clk":"11888486211","pt":1724238322755,"mc":[{"id":"1.232050243","rc":[{"batb":[[0,1.34,3.91],[1,1.21,83.24],[2,1.04,1.53]],"ltp":1.57,"tv":58.69,"id":72857117}]}]}
{"op":"mcm","clk":"11888488035","pt":1724238341869,"mc":[{"id":"1.232050243","rc":[{"batb":[[0,1.35,14],[1,1.34,3.91],[2,1.21,83.24]],"ltp":1.57,"tv":58.69,"id":72857117}]}]}
{"op":"mcm","clk":"11888488304","pt":1724238344567,"mc":[{"id":"1.232050243","rc":[{"batb":[[0,1.35,10]],"ltp":1.57,"tv":58.69,"id":72857117}]}]}
{"op":"mcm","clk":"11888488405","pt":1724238345674,"mc":[{"id":"1.232050243","rc":[{"batb":[[0,1.34,3.91],[1,1.21,83.24],[2,1.04,1.53]],"ltp":1.57,"tv":58.69,"id":72857117}]}]}
{"op":"mcm","clk":"11888490977","pt":1724238373499,"mc":[{"id":"1.232050243","rc":[{"batb":[[0,1.35,14],[1,1.34,3.91],[2,1.21,83.24]],"ltp":1.57,"tv":58.69,"id":72857117}]}]}
{"op":"mcm","clk":"11888491264","pt":1724238376299,"mc":[{"id":"1.232050243","rc":[{"batb":[[0,1.35,10]],"ltp":1.57,"tv":58.69,"id":72857117}]}]}
{"op":"mcm","clk":"11888491361","pt":1724238377329,"mc":[{"id":"1.232050243","rc":[{"batb":[[0,1.34,3.91],[1,1.21,83.24],[2,1.04,1.53]],"ltp":1.57,"tv":58.69,"id":72857117}]}]}
{"op":"mcm","clk":"11888492876","pt":1724238392225,"mc":[{"id":"1.232050243","rc":[{"batb":[[0,1.35,14],[1,1.34,3.91],[2,1.21,83.24]],"ltp":1.57,"tv":58.69,"id":72857117}]}]}
{"op":"mcm","clk":"11888493147","pt":1724238395025,"mc":[{"id":"1.232050243","rc":[{"batb":[[0,1.35,10]],"ltp":1.57,"tv":58.69,"id":72857117}]}]}
{"op":"mcm","clk":"11888493270","pt":1724238396109,"mc":[{"id":"1.232050243","rc":[{"batb":[[0,1.34,3.91],[1,1.21,83.24],[2,1.04,1.53]],"ltp":1.57,"tv":58.69,"id":72857117}]}]}
{"op":"mcm","clk":"11888494398","pt":1724238408438,"mc":[{"id":"1.232050243","rc":[{"batb":[[0,1.35,14],[1,1.34,3.91],[2,1.21,83.24]],"ltp":1.57,"tv":58.69,"id":72857117}]}]}
{"op":"mcm","clk":"11888494642","pt":1724238411405,"mc":[{"id":"1.232050243","rc":[{"batb":[[0,1.35,10]],"ltp":1.57,"tv":58.69,"id":72857117}]}]}
{"op":"mcm","clk":"11888494715","pt":1724238412228,"mc":[{"id":"1.232050243","rc":[{"batb":[[0,1.34,3.91],[1,1.21,83.24],[2,1.04,1.53]],"ltp":1.57,"tv":58.69,"id":72857117}]}]}
{"op":"mcm","clk":"11888495471","pt":1724238419967,"mc":[{"id":"1.232050243","rc":[{"batb":[[0,1.35,14],[1,1.34,3.91],[2,1.21,83.24]],"ltp":1.57,"tv":58.69,"id":72857117}]}]}
{"op":"mcm","clk":"11888495739","pt":1724238422749,"mc":[{"id":"1.232050243","rc":[{"batb":[[0,1.35,10]],"ltp":1.57,"tv":58.69,"id":72857117}]}]}
{"op":"mcm","clk":"11888495847","pt":1724238423845,"mc":[{"id":"1.232050243","rc":[{"batb":[[0,1.34,3.91],[1,1.21,83.24],[2,1.04,1.53]],"ltp":1.57,"tv":58.69,"id":72857117}]}]}
{"op":"mcm","clk":"11888496443","pt":1724238429646,"mc":[{"id":"1.232050243","rc":[{"batb":[[0,1.35,14],[1,1.34,3.91],[2,1.21,83.24]],"ltp":1.57,"tv":58.69,"id":72857117}]}]}
{"op":"mcm","clk":"11888496739","pt":1724238432459,"mc":[{"id":"1.232050243","rc":[{"batb":[[0,1.35,10]],"ltp":1.57,"tv":58.69,"id":72857117}]}]}
{"op":"mcm","clk":"11888496854","pt":1724238433492,"mc":[{"id":"1.232050243","rc":[{"batb":[[0,1.34,3.91],[1,1.21,83.24],[2,1.04,1.53]],"ltp":1.57,"tv":58.69,"id":72857117}]}]}
{"op":"mcm","clk":"11888497537","pt":1724238440383,"mc":[{"id":"1.232050243","rc":[{"batb":[[0,1.35,14],[1,1.34,3.91],[2,1.21,83.24]],"ltp":1.57,"tv":58.69,"id":72857117}]}]}
{"op":"mcm","clk":"11888497830","pt":1724238443589,"mc":[{"id":"1.232050243","rc":[{"batb":[[0,1.35,10]],"ltp":1.57,"tv":58.69,"id":72857117}]}]}
{"op":"mcm","clk":"11888497897","pt":1724238444373,"mc":[{"id":"1.232050243","rc":[{"batb":[[0,1.34,3.91],[1,1.21,83.24],[2,1.04,1.53]],"ltp":1.57,"tv":58.69,"id":72857117}]}]}
{"op":"mcm","clk":"11888498664","pt":1724238452576,"mc":[{"id":"1.232050243","rc":[{"batb":[[0,1.35,14],[1,1.34,3.91],[2,1.21,83.24]],"ltp":1.57,"tv":58.69,"id":72857117}]}]}
{"op":"mcm","clk":"11888498884","pt":1724238455276,"mc":[{"id":"1.232050243","rc":[{"batb":[[0,1.35,10]],"ltp":1.57,"tv":58.69,"id":72857117}]}]}
{"op":"mcm","clk":"11888498986","pt":1724238456411,"mc":[{"id":"1.232050243","rc":[{"batb":[[0,1.34,3.91],[1,1.21,83.24],[2,1.04,1.53]],"ltp":1.57,"tv":58.69,"id":72857117}]}]}
{"op":"mcm","clk":"11888499380","pt":1724238460107,"mc":[{"id":"1.232050243","rc":[{"batb":[[0,1.35,14],[1,1.34,3.91],[2,1.21,83.24]],"ltp":1.57,"tv":58.69,"id":72857117}]}]}
{"op":"mcm","clk":"11888499613","pt":1724238462699,"mc":[{"id":"1.232050243","rc":[{"batb":[[0,1.35,10]],"ltp":1.57,"tv":58.69,"id":72857117}]}]}
{"op":"mcm","clk":"11888499722","pt":1724238463787,"mc":[{"id":"1.232050243","rc":[{"batb":[[0,1.34,3.91],[1,1.21,83.24],[2,1.04,1.53]],"ltp":1.57,"tv":58.69,"id":72857117}]}]}
{"op":"mcm","clk":"11888499978","pt":1724238466432,"mc":[{"id":"1.232050243","rc":[{"batb":[[0,1.35,14],[1,1.34,3.91],[2,1.21,83.24]],"ltp":1.57,"tv":58.69,"id":72857117}]}]}
{"op":"mcm","clk":"11888500322","pt":1724238469507,"mc":[{"id":"1.232050243","rc":[{"batb":[[0,1.35,10]],"ltp":1.57,"tv":58.69,"id":72857117}]}]}
{"op":"mcm","clk":"11888500434","pt":1724238470496,"mc":[{"id":"1.232050243","rc":[{"batb":[[0,1.34,3.91],[1,1.21,83.24],[2,1.04,1.53]],"ltp":1.57,"tv":58.69,"id":72857117}]}]}
{"op":"mcm","clk":"11888500693","pt":1724238472918,"mc":[{"id":"1.232050243","rc":[{"batb":[[0,1.35,14],[1,1.34,3.91],[2,1.21,83.24]],"ltp":1.57,"tv":58.69,"id":72857117}]}]}
{"op":"mcm","clk":"11888500945","pt":1724238475419,"mc":[{"id":"1.232050243","rc":[{"batb":[[0,1.35,10]],"ltp":1.57,"tv":58.69,"id":72857117}]}]}
{"op":"mcm","clk":"11888501037","pt":1724238476404,"mc":[{"id":"1.232050243","rc":[{"batb":[[0,1.34,3.91],[1,1.21,83.24],[2,1.04,1.53]],"ltp":1.57,"tv":58.69,"id":72857117}]}]}
{"op":"mcm","clk":"11888501678","pt":1724238482012,"mc":[{"id":"1.232050243","rc":[{"batb":[[0,1.35,14],[1,1.34,3.91],[2,1.21,83.24]],"ltp":1.57,"tv":58.69,"id":72857117}]}]}
{"op":"mcm","clk":"11888501948","pt":1724238484825,"mc":[{"id":"1.232050243","rc":[{"batb":[[0,1.35,10]],"ltp":1.57,"tv":58.69,"id":72857117}]}]}
{"op":"mcm","clk":"11888502025","pt":1724238485613,"mc":[{"id":"1.232050243","rc":[{"batb":[[0,1.34,3.91],[1,1.21,83.24],[2,1.04,1.53]],"ltp":1.57,"tv":58.69,"id":72857117}]}]}
{"op":"mcm","clk":"11888502491","pt":1724238489951,"mc":[{"id":"1.232050243","rc":[{"batb":[[0,1.35,14],[1,1.34,3.91],[2,1.21,83.24]],"ltp":1.57,"tv":58.69,"id":72857117}]}]}
{"op":"mcm","clk":"11888502763","pt":1724238492632,"mc":[{"id":"1.232050243","rc":[{"batb":[[0,1.35,10]],"ltp":1.57,"tv":58.69,"id":72857117}]}]}
{"op":"mcm","clk":"11888502860","pt":1724238493624,"mc":[{"id":"1.232050243","rc":[{"batb":[[0,1.34,3.91],[1,1.21,83.24],[2,1.04,1.53]],"ltp":1.57,"tv":58.69,"id":72857117}]}]}
{"op":"mcm","clk":"11888503084","pt":1724238495964,"mc":[{"id":"1.232050243","rc":[{"batb":[[0,1.35,14],[1,1.34,3.91],[2,1.21,83.24]],"ltp":1.57,"tv":58.69,"id":72857117}]}]}
{"op":"mcm","clk":"11888503350","pt":1724238498460,"mc":[{"id":"1.232050243","rc":[{"batb":[[0,1.35,10]],"ltp":1.57,"tv":58.69,"id":72857117}]}]}
{"op":"mcm","clk":"11888503450","pt":1724238499355,"mc":[{"id":"1.232050243","rc":[{"batb":[[0,1.34,3.91],[1,1.21,83.24],[2,1.04,1.53]],"ltp":1.57,"tv":58.69,"id":72857117}]}]}
{"op":"mcm","clk":"11888505612","pt":1724238519087,"mc":[{"id":"1.232050243","rc":[{"batb":[[0,1.35,14],[1,1.34,3.91],[2,1.21,83.24]],"ltp":1.57,"tv":58.69,"id":72857117}]}]}
{"op":"mcm","clk":"11888506101","pt":1724238523955,"mc":[{"id":"1.232050243","rc":[{"batb":[[0,1.35,10]],"ltp":1.57,"tv":58.69,"id":72857117}]}]}
{"op":"mcm","clk":"11888506194","pt":1724238524886,"mc":[{"id":"1.232050243","rc":[{"batb":[[0,1.34,3.91],[1,1.21,83.24],[2,1.04,1.53]],"ltp":1.57,"tv":58.69,"id":72857117}]}]}
{"op":"mcm","clk":"11888506324","pt":1724238526187,"mc":[{"id":"1.232050243","rc":[{"batb":[[0,1.35,4],[1,1.34,3.91],[2,1.21,83.24]],"ltp":1.57,"tv":58.69,"id":72857117}]}]}
{"op":"mcm","clk":"11888506467","pt":1724238527483,"mc":[{"id":"1.232050243","rc":[{"batb":[[0,1.36,10],[1,1.35,4],[2,1.34,3.91]],"ltp":1.57,"tv":58.69,"id":72857117}]}]}
{"op":"mcm","clk":"11888506670","pt":1724238529360,"mc":[{"id":"1.232050243","rc":[{"batb":[[1,1.34,3.91],[2,1.21,83.24]],"ltp":1.57,"tv":58.69,"id":72857117}]}]}
{"op":"mcm","clk":"11888506863","pt":1724238531599,"mc":[{"id":"1.232050243","rc":[{"batb":[[0,1.35,4]],"ltp":1.57,"tv":58.69,"id":72857117}]}]}
{"op":"mcm","clk":"11888507066","pt":1724238533987,"mc":[{"id":"1.232050243","rc":[{"batb":[[0,1.34,3.91],[1,1.21,83.24],[2,1.04,1.53]],"ltp":1.57,"tv":58.69,"id":72857117}]}]}
{"op":"mcm","clk":"11888507090","pt":1724238534298,"mc":[{"id":"1.232050243","rc":[{"batb":[[0,1.35,10],[1,1.34,3.91],[2,1.21,83.24]],"ltp":1.57,"tv":58.69,"id":72857117}]}]}
{"op":"mcm","clk":"11888507412","pt":1724238538093,"mc":[{"id":"1.232050243","rc":[{"batb":[[0,1.35,4]],"ltp":1.57,"tv":58.69,"id":72857117}]}]}
{"op":"mcm","clk":"11888507659","pt":1724238540704,"mc":[{"id":"1.232050243","rc":[{"batb":[[0,1.35,10]],"ltp":1.57,"tv":58.69,"id":72857117}]}]}
{"op":"mcm","clk":"11888507966","pt":1724238544018,"mc":[{"id":"1.232050243","rc":[{"batb":[[0,1.34,3.91],[1,1.21,83.24],[2,1.04,1.53]],"ltp":1.57,"tv":58.69,"id":72857117}]}]}
{"op":"mcm","clk":"11888507996","pt":1724238544331,"mc":[{"id":"1.232050243","rc":[{"batb":[[0,1.35,4],[1,1.34,3.91],[2,1.21,83.24]],"ltp":1.57,"tv":58.69,"id":72857117}]}]}
{"op":"mcm","clk":"11888508231","pt":1724238546717,"mc":[{"id":"1.232050243","rc":[{"batb":[[0,1.35,10]],"ltp":1.57,"tv":58.69,"id":72857117}]}]}
{"op":"mcm","clk":"11888508559","pt":1724238549914,"mc":[{"id":"1.232050243","rc":[{"batb":[[0,1.34,3.91],[1,1.21,83.24],[2,1.04,1.53]],"ltp":1.57,"tv":58.69,"id":72857117}]}]}
{"op":"mcm","clk":"11888508584","pt":1724238550229,"mc":[{"id":"1.232050243","rc":[{"batb":[[0,1.35,4],[1,1.34,3.91],[2,1.21,83.24]],"ltp":1.57,"tv":58.69,"id":72857117}]}]}
{"op":"mcm","clk":"11888508841","pt":1724238552828,"mc":[{"id":"1.232050243","rc":[{"batb":[[0,1.35,10]],"ltp":1.57,"tv":58.69,"id":72857117}]}]}
{"op":"mcm","clk":"11888509144","pt":1724238556144,"mc":[{"id":"1.232050243","rc":[{"batb":[[0,1.34,3.91],[1,1.21,83.24],[2,1.04,1.53]],"ltp":1.57,"tv":58.69,"id":72857117}]}]}
{"op":"mcm","clk":"11888509163","pt":1724238556349,"mc":[{"id":"1.232050243","rc":[{"batb":[[0,1.35,4],[1,1.34,3.91],[2,1.21,83.24]],"ltp":1.57,"tv":58.69,"id":72857117}]}]}
{"op":"mcm","clk":"11888509387","pt":1724238558948,"mc":[{"id":"1.232050243","rc":[{"batb":[[0,1.35,10]],"ltp":1.57,"tv":58.69,"id":72857117}]}]}
{"op":"mcm","clk":"11888509714","pt":1724238562416,"mc":[{"id":"1.232050243","rc":[{"batb":[[0,1.35,4]],"ltp":1.57,"tv":58.69,"id":72857117}]}]}
{"op":"mcm","clk":"11888509963","pt":1724238565151,"mc":[{"id":"1.232050243","rc":[{"batb":[[0,1.35,10]],"ltp":1.57,"tv":58.69,"id":72857117}]}]}
{"op":"mcm","clk":"11888510294","pt":1724238568824,"mc":[{"id":"1.232050243","rc":[{"batb":[[0,1.35,4]],"ltp":1.57,"tv":58.69,"id":72857117}]}]}
{"op":"mcm","clk":"11888510518","pt":1724238571164,"mc":[{"id":"1.232050243","rc":[{"batb":[[0,1.34,3.91],[1,1.21,83.24],[2,1.04,1.53]],"ltp":1.57,"tv":58.69,"id":72857117}]}]}
{"op":"mcm","clk":"11888510533","pt":1724238571327,"mc":[{"id":"1.232050243","rc":[{"batb":[[0,1.35,10],[1,1.34,3.91],[2,1.21,83.24]],"ltp":1.57,"tv":58.69,"id":72857117}]}]}
{"op":"mcm","clk":"11888510914","pt":1724238575061,"mc":[{"id":"1.232050243","rc":[{"batb":[[0,1.35,4]],"ltp":1.57,"tv":58.69,"id":72857117}]}]}
{"op":"mcm","clk":"11888511216","pt":1724238578064,"mc":[{"id":"1.232050243","rc":[{"batb":[[0,1.35,10]],"ltp":1.57,"tv":58.69,"id":72857117}]}]}
{"op":"mcm","clk":"11888511562","pt":1724238581632,"mc":[{"id":"1.232050243","rc":[{"batb":[[0,1.35,4]],"ltp":1.57,"tv":58.69,"id":72857117}]}]}
{"op":"mcm","clk":"11888511781","pt":1724238584059,"mc":[{"id":"1.232050243","rc":[{"batb":[[0,1.34,3.91],[1,1.21,83.24],[2,1.04,1.53]],"ltp":1.57,"tv":58.69,"id":72857117}]}]}
{"op":"mcm","clk":"11888511838","pt":1724238584681,"mc":[{"id":"1.232050243","rc":[{"batb":[[0,1.35,10],[1,1.34,3.91],[2,1.21,83.24]],"ltp":1.57,"tv":58.69,"id":72857117}]}]}
{"op":"mcm","clk":"11888512144","pt":1724238588163,"mc":[{"id":"1.232050243","rc":[{"batb":[[0,1.35,4]],"ltp":1.57,"tv":58.69,"id":72857117}]}]}
{"op":"mcm","clk":"11888512384","pt":1724238590967,"mc":[{"id":"1.232050243","rc":[{"batb":[[0,1.35,10]],"ltp":1.57,"tv":58.69,"id":72857117}]}]}
{"op":"mcm","clk":"11888512649","pt":1724238594182,"mc":[{"id":"1.232050243","rc":[{"batb":[[0,1.34,3.91],[1,1.21,83.24],[2,1.04,1.53]],"ltp":1.57,"tv":58.69,"id":72857117}]}]}
{"op":"mcm","clk":"11888512682","pt":1724238594448,"mc":[{"id":"1.232050243","rc":[{"batb":[[0,1.35,4],[1,1.34,3.91],[2,1.21,83.24]],"ltp":1.57,"tv":58.69,"id":72857117}]}]}
{"op":"mcm","clk":"11888512903","pt":1724238597069,"mc":[{"id":"1.232050243","rc":[{"batb":[[0,1.34,3.91],[1,1.21,83.24],[2,1.04,1.53]],"ltp":1.57,"tv":58.69,"id":72857117}]}]}
{"op":"mcm","clk":"11888512919","pt":1724238597278,"mc":[{"id":"1.232050243","rc":[{"batb":[[0,1.35,10],[1,1.34,3.91],[2,1.21,83.24]],"ltp":1.57,"tv":58.69,"id":72857117}]}]}
{"op":"mcm","clk":"11888513211","pt":1724238600885,"mc":[{"id":"1.232050243","rc":[{"batb":[[0,1.35,4]],"ltp":1.57,"tv":58.69,"id":72857117}]}]}
{"op":"mcm","clk":"11888513494","pt":1724238603794,"mc":[{"id":"1.232050243","rc":[{"batb":[[0,1.35,10]],"ltp":1.57,"tv":58.69,"id":72857117}]}]}
{"op":"mcm","clk":"11888513816","pt":1724238607368,"mc":[{"id":"1.232050243","rc":[{"batb":[[0,1.35,4]],"ltp":1.57,"tv":58.69,"id":72857117}]}]}
{"op":"mcm","clk":"11888514039","pt":1724238610171,"mc":[{"id":"1.232050243","rc":[{"batb":[[0,1.35,10]],"ltp":1.57,"tv":58.69,"id":72857117}]}]}
{"op":"mcm","clk":"11888514339","pt":1724238613798,"mc":[{"id":"1.232050243","rc":[{"batb":[[0,1.35,4]],"ltp":1.57,"tv":58.69,"id":72857117}]}]}
{"op":"mcm","clk":"11888514536","pt":1724238616075,"mc":[{"id":"1.232050243","rc":[{"batb":[[0,1.34,3.91],[1,1.21,83.24],[2,1.04,1.53]],"ltp":1.57,"tv":58.69,"id":72857117}]}]}
{"op":"mcm","clk":"11888514559","pt":1724238616385,"mc":[{"id":"1.232050243","rc":[{"batb":[[0,1.35,10],[1,1.34,3.91],[2,1.21,83.24]],"ltp":1.57,"tv":58.69,"id":72857117}]}]}
{"op":"mcm","clk":"11888514880","pt":1724238619814,"mc":[{"id":"1.232050243","rc":[{"batb":[[0,1.35,4]],"ltp":1.57,"tv":58.69,"id":72857117}]}]}
{"op":"mcm","clk":"11888515103","pt":1724238622091,"mc":[{"id":"1.232050243","rc":[{"batb":[[0,1.34,3.91],[1,1.21,83.24],[2,1.04,1.53]],"ltp":1.57,"tv":58.69,"id":72857117}]}]}
{"op":"mcm","clk":"11888515135","pt":1724238622405,"mc":[{"id":"1.232050243","rc":[{"batb":[[0,1.35,10],[1,1.34,3.91],[2,1.21,83.24]],"ltp":1.57,"tv":58.69,"id":72857117}]}]}
{"op":"mcm","clk":"11888515422","pt":1724238625913,"mc":[{"id":"1.232050243","rc":[{"batb":[[0,1.35,4]],"ltp":1.57,"tv":58.69,"id":72857117}]}]}
{"op":"mcm","clk":"11888515609","pt":1724238628301,"mc":[{"id":"1.232050243","rc":[{"batb":[[0,1.35,10]],"ltp":1.57,"tv":58.69,"id":72857117}]}]}
{"op":"mcm","clk":"11888515914","pt":1724238631920,"mc":[{"id":"1.232050243","rc":[{"batb":[[0,1.35,4]],"ltp":1.57,"tv":58.69,"id":72857117}]}]}
{"op":"mcm","clk":"11888516142","pt":1724238634603,"mc":[{"id":"1.232050243","rc":[{"batb":[[0,1.35,10]],"ltp":1.57,"tv":58.69,"id":72857117}]}]}
{"op":"mcm","clk":"11888516410","pt":1724238637910,"mc":[{"id":"1.232050243","rc":[{"batb":[[0,1.34,3.91],[1,1.21,83.24],[2,1.04,1.53]],"ltp":1.57,"tv":58.69,"id":72857117}]}]}
{"op":"mcm","clk":"11888516443","pt":1724238638215,"mc":[{"id":"1.232050243","rc":[{"batb":[[0,1.35,4],[1,1.34,3.91],[2,1.21,83.24]],"ltp":1.57,"tv":58.69,"id":72857117}]}]}
{"op":"mcm","clk":"11888516654","pt":1724238640600,"mc":[{"id":"1.232050243","rc":[{"batb":[[0,1.36,10]],"ltp":1.57,"tv":58.69,"id":72857117}]}]}
{"op":"mcm","clk":"11888516974","pt":1724238644534,"mc":[{"id":"1.232050243","rc":[{"batb":[[0,1.35,4]],"ltp":1.57,"tv":58.69,"id":72857117}]}]}
{"op":"mcm","clk":"11888517189","pt":1724238647037,"mc":[{"id":"1.232050243","rc":[{"batb":[[0,1.35,10]],"ltp":1.57,"tv":58.69,"id":72857117}]}]}
{"op":"mcm","clk":"11888517535","pt":1724238650839,"mc":[{"id":"1.232050243","rc":[{"batb":[[0,1.35,4]],"ltp":1.57,"tv":58.69,"id":72857117}]}]}
{"op":"mcm","clk":"11888517735","pt":1724238653047,"mc":[{"id":"1.232050243","rc":[{"batb":[[0,1.34,3.91],[1,1.21,83.24],[2,1.04,1.53]],"ltp":1.57,"tv":58.69,"id":72857117}]}]}
{"op":"mcm","clk":"11888517749","pt":1724238653253,"mc":[{"id":"1.232050243","rc":[{"batb":[[0,1.35,10],[1,1.34,3.91],[2,1.21,83.24]],"ltp":1.57,"tv":58.69,"id":72857117}]}]}
{"op":"mcm","clk":"11888518056","pt":1724238656833,"mc":[{"id":"1.232050243","rc":[{"batb":[[0,1.35,4]],"ltp":1.57,"tv":58.69,"id":72857117}]}]}
{"op":"mcm","clk":"11888518267","pt":1724238659415,"mc":[{"id":"1.232050243","rc":[{"batb":[[0,1.35,10]],"ltp":1.57,"tv":58.69,"id":72857117}]}]}
{"op":"mcm","clk":"11888518542","pt":1724238662851,"mc":[{"id":"1.232050243","rc":[{"batb":[[0,1.35,4]],"ltp":1.57,"tv":58.69,"id":72857117}]}]}
{"op":"mcm","clk":"11888518771","pt":1724238665464,"mc":[{"id":"1.232050243","rc":[{"batb":[[0,1.35,10]],"ltp":1.57,"tv":58.69,"id":72857117}]}]}
{"op":"mcm","clk":"11888519053","pt":1724238668952,"mc":[{"id":"1.232050243","rc":[{"batb":[[0,1.35,4]],"ltp":1.57,"tv":58.69,"id":72857117}]}]}
{"op":"mcm","clk":"11888519279","pt":1724238671853,"mc":[{"id":"1.232050243","rc":[{"batb":[[0,1.35,10]],"ltp":1.57,"tv":58.69,"id":72857117}]}]}
{"op":"mcm","clk":"11888519591","pt":1724238675544,"mc":[{"id":"1.232050243","rc":[{"batb":[[0,1.35,4]],"ltp":1.57,"tv":58.69,"id":72857117}]}]}
{"op":"mcm","clk":"11888519805","pt":1724238678043,"mc":[{"id":"1.232050243","rc":[{"batb":[[0,1.34,3.91],[1,1.21,83.24],[2,1.04,1.53]],"ltp":1.57,"tv":58.69,"id":72857117}]}]}
{"op":"mcm","clk":"11888519832","pt":1724238678348,"mc":[{"id":"1.232050243","rc":[{"batb":[[0,1.35,10],[1,1.34,3.91],[2,1.21,83.24]],"ltp":1.57,"tv":58.69,"id":72857117}]}]}
{"op":"mcm","clk":"11888520141","pt":1724238682062,"mc":[{"id":"1.232050243","rc":[{"batb":[[0,1.35,4]],"ltp":1.57,"tv":58.69,"id":72857117}]}]}
{"op":"mcm","clk":"11888520407","pt":1724238684960,"mc":[{"id":"1.232050243","rc":[{"batb":[[0,1.35,10]],"ltp":1.57,"tv":58.69,"id":72857117}]}]}
{"op":"mcm","clk":"11888520609","pt":1724238687057,"mc":[{"id":"1.232050243","rc":[{"batb":[[0,1.36,4],[1,1.35,10],[2,1.34,3.91]],"ltp":1.57,"tv":58.69,"id":72857117}]}]}
{"op":"mcm","clk":"11888520693","pt":1724238688188,"mc":[{"id":"1.232050243","rc":[{"batb":[[1,1.34,3.91],[2,1.21,83.24]],"ltp":1.57,"tv":58.69,"id":72857117}]}]}
{"op":"mcm","clk":"11888520817","pt":1724238689588,"mc":[{"id":"1.232050243","rc":[{"batb":[[0,1.34,3.91],[1,1.21,83.24],[2,1.04,1.53]],"ltp":1.57,"tv":58.69,"id":72857117}]}]}
{"op":"mcm","clk":"11888521525","pt":1724238697991,"mc":[{"id":"1.232050243","rc":[{"batb":[[0,1.35,14],[1,1.34,3.91],[2,1.21,83.24]],"ltp":1.57,"tv":58.69,"id":72857117}]}]}
{"op":"mcm","clk":"11888521793","pt":1724238700979,"mc":[{"id":"1.232050243","rc":[{"batb":[[0,1.35,10]],"ltp":1.57,"tv":58.69,"id":72857117}]}]}
{"op":"mcm","clk":"11888521873","pt":1724238701975,"mc":[{"id":"1.232050243","rc":[{"batb":[[0,1.34,3.91],[1,1.21,83.24],[2,1.04,1.53]],"ltp":1.57,"tv":58.69,"id":72857117}]}]}
{"op":"mcm","clk":"11888522443","pt":1724238708984,"mc":[{"id":"1.232050243","rc":[{"batb":[[0,1.35,14],[1,1.34,3.91],[2,1.21,83.24]],"ltp":1.57,"tv":58.69,"id":72857117}]}]}
{"op":"mcm","clk":"11888522680","pt":1724238711709,"mc":[{"id":"1.232050243","rc":[{"batb":[[0,1.35,10]],"ltp":1.57,"tv":58.69,"id":72857117}]}]}
{"op":"mcm","clk":"11888522757","pt":1724238712706,"mc":[{"id":"1.232050243","rc":[{"batb":[[0,1.34,3.91],[1,1.21,83.24],[2,1.04,1.53]],"ltp":1.57,"tv":58.69,"id":72857117}]}]}
{"op":"mcm","clk":"11888523266","pt":1724238718432,"mc":[{"id":"1.232050243","rc":[{"batb":[[0,1.35,14],[1,1.34,3.91],[2,1.21,83.24]],"ltp":1.57,"tv":58.69,"id":72857117}]}]}
{"op":"mcm","clk":"11888523508","pt":1724238721098,"mc":[{"id":"1.232050243","rc":[{"batb":[[0,1.35,10]],"ltp":1.57,"tv":58.69,"id":72857117}]}]}
{"op":"mcm","clk":"11888523602","pt":1724238722207,"mc":[{"id":"1.232050243","rc":[{"batb":[[0,1.34,3.91],[1,1.21,83.24],[2,1.04,1.53]],"ltp":1.57,"tv":58.69,"id":72857117}]}]}
{"op":"mcm","clk":"11888523967","pt":1724238726237,"mc":[{"id":"1.232050243","rc":[{"batb":[[0,1.35,14],[1,1.34,3.91],[2,1.21,83.24]],"ltp":1.57,"tv":58.69,"id":72857117}]}]}
{"op":"mcm","clk":"11888524209","pt":1724238728729,"mc":[{"id":"1.232050243","rc":[{"batb":[[0,1.35,10]],"ltp":1.57,"tv":58.69,"id":72857117}]}]}
{"op":"mcm","clk":"11888524309","pt":1724238729965,"mc":[{"id":"1.232050243","rc":[{"batb":[[0,1.34,3.91],[1,1.21,83.24],[2,1.04,1.53]],"ltp":1.57,"tv":58.69,"id":72857117}]}]}
{"op":"mcm","clk":"11888525862","pt":1724238751749,"mc":[{"id":"1.232050243","rc":[{"batb":[[0,1.35,14],[1,1.34,3.91],[2,1.21,83.24]],"ltp":1.57,"tv":58.69,"id":72857117}]}]}
{"op":"mcm","clk":"11888526052","pt":1724238754352,"mc":[{"id":"1.232050243","rc":[{"batb":[[0,1.35,10]],"ltp":1.57,"tv":58.69,"id":72857117}]}]}
{"op":"mcm","clk":"11888526120","pt":1724238755345,"mc":[{"id":"1.232050243","rc":[{"batb":[[0,1.34,3.91],[1,1.21,83.24],[2,1.04,1.53]],"ltp":1.57,"tv":58.69,"id":72857117}]}]}
{"op":"mcm","clk":"11888526540","pt":1724238761370,"mc":[{"id":"1.232050243","rc":[{"batb":[[0,1.35,14],[1,1.34,3.91],[2,1.21,83.24]],"ltp":1.57,"tv":58.69,"id":72857117}]}]}
{"op":"mcm","clk":"11888526699","pt":1724238763653,"mc":[{"id":"1.232050243","rc":[{"batb":[[0,1.35,10]],"ltp":1.57,"tv":58.69,"id":72857117}]}]}
{"op":"mcm","clk":"11888526779","pt":1724238764854,"mc":[{"id":"1.232050243","rc":[{"batb":[[0,1.34,3.91],[1,1.21,83.24],[2,1.04,1.53]],"ltp":1.57,"tv":58.69,"id":72857117}]}]}
{"op":"mcm","clk":"11888527953","pt":1724238780602,"mc":[{"id":"1.232050243","rc":[{"batb":[[0,1.35,14],[1,1.34,3.91],[2,1.21,83.24]],"ltp":1.57,"tv":58.69,"id":72857117}]}]}
{"op":"mcm","clk":"11888528182","pt":1724238784012,"mc":[{"id":"1.232050243","rc":[{"batb":[[0,1.34,3.91],[1,1.21,83.24],[2,1.04,1.53]],"ltp":1.57,"tv":58.69,"id":72857117}]}]}
{"op":"mcm","clk":"11888528826","pt":1724238792796,"mc":[{"id":"1.232050243","rc":[{"batb":[[0,1.35,14],[1,1.34,3.91],[2,1.21,83.24]],"ltp":1.57,"tv":58.69,"id":72857117}]}]}
{"op":"mcm","clk":"11888529030","pt":1724238795578,"mc":[{"id":"1.232050243","rc":[{"batb":[[0,1.35,10]],"ltp":1.57,"tv":58.69,"id":72857117}]}]}
{"op":"mcm","clk":"11888529110","pt":1724238796710,"mc":[{"id":"1.232050243","rc":[{"batb":[[0,1.34,3.91],[1,1.21,83.24],[2,1.04,1.53]],"ltp":1.57,"tv":58.69,"id":72857117}]}]}
{"op":"mcm","clk":"11888529888","pt":1724238807939,"mc":[{"id":"1.232050243","rc":[{"batb":[[0,1.35,14],[1,1.34,3.91],[2,1.21,83.24]],"ltp":1.57,"tv":58.69,"id":72857117}]}]}
{"op":"mcm","clk":"11888530069","pt":1724238810591,"mc":[{"id":"1.232050243","rc":[{"batb":[[0,1.35,10]],"ltp":1.57,"tv":58.69,"id":72857117}]}]}
{"op":"mcm","clk":"11888530141","pt":1724238811567,"mc":[{"id":"1.232050243","rc":[{"batb":[[0,1.34,3.91],[1,1.21,83.24],[2,1.04,1.53]],"ltp":1.57,"tv":58.69,"id":72857117}]}]}
{"op":"mcm","clk":"11888530971","pt":1724238824056,"mc":[{"id":"1.232050243","rc":[{"batb":[[0,1.35,14],[1,1.34,3.91],[2,1.21,83.24]],"ltp":1.57,"tv":58.69,"id":72857117}]}]}
{"op":"mcm","clk":"11888531125","pt":1724238826733,"mc":[{"id":"1.232050243","rc":[{"batb":[[0,1.35,10]],"ltp":1.57,"tv":58.69,"id":72857117}]}]}
{"op":"mcm","clk":"11888531193","pt":1724238827769,"mc":[{"id":"1.232050243","rc":[{"batb":[[0,1.34,3.91],[1,1.21,83.24],[2,1.04,1.53]],"ltp":1.57,"tv":58.69,"id":72857117}]}]}
{"op":"mcm","clk":"11888533604","pt":1724238861907,"mc":[{"id":"1.232050243","rc":[{"batb":[[0,1.35,14],[1,1.34,3.91],[2,1.21,83.24]],"ltp":1.57,"tv":58.69,"id":72857117}]}]}
{"op":"mcm","clk":"11888533820","pt":1724238864905,"mc":[{"id":"1.232050243","rc":[{"batb":[[0,1.35,10]],"ltp":1.57,"tv":58.69,"id":72857117}]}]}
{"op":"mcm","clk":"11888533845","pt":1724238865215,"mc":[{"id":"1.232050243","rc":[{"batb":[[0,1.34,3.91],[1,1.21,83.24],[2,1.04,1.53]],"ltp":1.57,"tv":58.69,"id":72857117}]}]}
{"op":"mcm","clk":"11888534590","pt":1724238874920,"mc":[{"id":"1.232050243","rc":[{"batb":[[0,1.35,14],[1,1.34,3.91],[2,1.21,83.24]],"ltp":1.57,"tv":58.69,"id":72857117}]}]}
{"op":"mcm","clk":"11888534797","pt":1724238877691,"mc":[{"id":"1.232050243","rc":[{"batb":[[0,1.35,10]],"ltp":1.57,"tv":58.69,"id":72857117}]}]}
{"op":"mcm","clk":"11888534860","pt":1724238878519,"mc":[{"id":"1.232050243","rc":[{"batb":[[0,1.34,3.91],[1,1.21,83.24],[2,1.04,1.53]],"ltp":1.57,"tv":58.69,"id":72857117}]}]}
{"op":"mcm","clk":"11888536208","pt":1724238897328,"mc":[{"id":"1.232050243","rc":[{"batb":[[0,1.35,14],[1,1.34,3.91],[2,1.21,83.24]],"ltp":1.57,"tv":58.69,"id":72857117}]}]}
{"op":"mcm","clk":"11888536399","pt":1724238899822,"mc":[{"id":"1.232050243","rc":[{"batb":[[0,1.35,10]],"ltp":1.57,"tv":58.69,"id":72857117}]}]}
{"op":"mcm","clk":"11888536484","pt":1724238900749,"mc":[{"id":"1.232050243","rc":[{"batb":[[0,1.34,3.91],[1,1.21,83.24],[2,1.04,1.53]],"ltp":1.57,"tv":58.69,"id":72857117}]}]}
{"op":"mcm","clk":"11888536784","pt":1724238904433,"mc":[{"id":"1.232050243","rc":[{"batb":[[0,1.35,14],[1,1.34,3.91],[2,1.21,83.24]],"ltp":1.57,"tv":58.69,"id":72857117}]}]}
{"op":"mcm","clk":"11888537074","pt":1724238907546,"mc":[{"id":"1.232050243","rc":[{"batb":[[0,1.35,10]],"ltp":1.57,"tv":58.69,"id":72857117}]}]}
{"op":"mcm","clk":"11888537153","pt":1724238908643,"mc":[{"id":"1.232050243","rc":[{"batb":[[0,1.34,3.91],[1,1.21,83.24],[2,1.04,1.53]],"ltp":1.57,"tv":58.69,"id":72857117}]}]}
{"op":"mcm","clk":"11888537732","pt":1724238915962,"mc":[{"id":"1.232050243","rc":[{"batb":[[0,1.35,14],[1,1.34,3.91],[2,1.21,83.24]],"ltp":1.57,"tv":58.69,"id":72857117}]}]}
{"op":"mcm","clk":"11888537943","pt":1724238918465,"mc":[{"id":"1.232050243","rc":[{"batb":[[0,1.35,10]],"ltp":1.57,"tv":58.69,"id":72857117}]}]}
{"op":"mcm","clk":"11888538028","pt":1724238919553,"mc":[{"id":"1.232050243","rc":[{"batb":[[0,1.34,3.91],[1,1.21,83.24],[2,1.04,1.53]],"ltp":1.57,"tv":58.69,"id":72857117}]}]}
{"op":"mcm","clk":"11888539160","pt":1724238933065,"mc":[{"id":"1.232050243","rc":[{"batb":[[0,1.35,14],[1,1.34,3.91],[2,1.21,83.24]],"ltp":1.57,"tv":58.69,"id":72857117}]}]}
{"op":"mcm","clk":"11888539347","pt":1724238935789,"mc":[{"id":"1.232050243","rc":[{"batb":[[0,1.35,10]],"ltp":1.57,"tv":58.69,"id":72857117}]}]}
{"op":"mcm","clk":"11888539435","pt":1724238936886,"mc":[{"id":"1.232050243","rc":[{"batb":[[0,1.34,3.91],[1,1.21,83.24],[2,1.04,1.53]],"ltp":1.57,"tv":58.69,"id":72857117}]}]}
{"op":"mcm","clk":"11888540294","pt":1724238947685,"mc":[{"id":"1.232050243","rc":[{"batb":[[0,1.35,14],[1,1.34,3.91],[2,1.21,83.24]],"ltp":1.57,"tv":58.69,"id":72857117}]}]}
{"op":"mcm","clk":"11888540576","pt":1724238951166,"mc":[{"id":"1.232050243","rc":[{"batb":[[0,1.34,3.91],[1,1.21,83.24],[2,1.04,1.53]],"ltp":1.57,"tv":58.69,"id":72857117}]}]}
{"op":"mcm","clk":"11888542462","pt":1724238977899,"mc":[{"id":"1.232050243","rc":[{"batb":[[0,1.35,14],[1,1.34,3.91],[2,1.21,83.24]],"ltp":1.57,"tv":58.69,"id":72857117}]}]}
{"op":"mcm","clk":"11888542705","pt":1724238980714,"mc":[{"id":"1.232050243","rc":[{"batb":[[0,1.35,10]],"ltp":1.57,"tv":58.69,"id":72857117}]}]}
{"op":"mcm","clk":"11888542787","pt":1724238981703,"mc":[{"id":"1.232050243","rc":[{"batb":[[0,1.34,3.91],[1,1.21,83.24],[2,1.04,1.53]],"ltp":1.57,"tv":58.69,"id":72857117}]}]}
{"op":"mcm","clk":"11888543642","pt":1724238992548,"mc":[{"id":"1.232050243","rc":[{"batb":[[0,1.35,14],[1,1.34,3.91],[2,1.21,83.24]],"ltp":1.57,"tv":58.69,"id":72857117}]}]}
{"op":"mcm","clk":"11888543909","pt":1724238995161,"mc":[{"id":"1.232050243","rc":[{"batb":[[0,1.35,10]],"ltp":1.57,"tv":58.69,"id":72857117}]}]}
{"op":"mcm","clk":"11888544005","pt":1724238996147,"mc":[{"id":"1.232050243","rc":[{"batb":[[0,1.34,3.91],[1,1.21,83.24],[2,1.04,1.53]],"ltp":1.57,"tv":58.69,"id":72857117}]}]}
{"op":"mcm","clk":"11888544537","pt":1724239002346,"mc":[{"id":"1.232050243","rc":[{"batb":[[0,1.35,14],[1,1.34,3.91],[2,1.21,83.24]],"ltp":1.57,"tv":58.69,"id":72857117}]}]}
{"op":"mcm","clk":"11888544745","pt":1724239004947,"mc":[{"id":"1.232050243","rc":[{"batb":[[0,1.35,10]],"ltp":1.57,"tv":58.69,"id":72857117}]}]}
{"op":"mcm","clk":"11888544819","pt":1724239006033,"mc":[{"id":"1.232050243","rc":[{"batb":[[0,1.34,3.91],[1,1.21,83.24],[2,1.04,1.53]],"ltp":1.57,"tv":58.69,"id":72857117}]}]}
{"op":"mcm","clk":"11888545738","pt":1724239017985,"mc":[{"id":"1.232050243","rc":[{"batb":[[0,1.35,14],[1,1.34,3.91],[2,1.21,83.24]],"ltp":1.57,"tv":58.69,"id":72857117}]}]}
{"op":"mcm","clk":"11888545952","pt":1724239020797,"mc":[{"id":"1.232050243","rc":[{"batb":[[0,1.35,10]],"ltp":1.57,"tv":58.69,"id":72857117}]}]}
{"op":"mcm","clk":"11888546006","pt":1724239021578,"mc":[{"id":"1.232050243","rc":[{"batb":[[0,1.34,3.91],[1,1.21,83.24],[2,1.04,1.53]],"ltp":1.57,"tv":58.69,"id":72857117}]}]}
{"op":"mcm","clk":"11888546100","pt":1724239022989,"mc":[{"id":"1.232050243","rc":[{"batb":[[0,1.35,4],[1,1.34,3.91],[2,1.21,83.24]],"ltp":1.57,"tv":58.69,"id":72857117}]}]}
{"op":"mcm","clk":"11888546346","pt":1724239025678,"mc":[{"id":"1.232050243","rc":[{"batb":[[0,1.35,10]],"ltp":1.57,"tv":58.69,"id":72857117}]}]}
{"op":"mcm","clk":"11888546501","pt":1724239028065,"mc":[{"id":"1.232050243","rc":[{"batb":[[0,1.36,4],[1,1.35,10],[2,1.34,3.91]],"ltp":1.57,"tv":58.69,"id":72857117}]}]}
{"op":"mcm","clk":"11888546566","pt":1724239029097,"mc":[{"id":"1.232050243","rc":[{"batb":[[1,1.34,3.91],[2,1.21,83.24]],"ltp":1.57,"tv":58.69,"id":72857117}]}]}
{"op":"mcm","clk":"11888546665","pt":1724239030396,"mc":[{"id":"1.232050243","rc":[{"batb":[[0,1.34,3.91],[1,1.21,83.24],[2,1.04,1.53]],"ltp":1.57,"tv":58.69,"id":72857117}]}]}
{"op":"mcm","clk":"11888546838","pt":1724239032594,"mc":[{"id":"1.232050243","rc":[{"batb":[[0,1.36,4],[1,1.35,10],[2,1.34,3.91]],"ltp":1.57,"tv":58.69,"id":72857117}]}]}
{"op":"mcm","clk":"11888547047","pt":1724239035188,"mc":[{"id":"1.232050243","rc":[{"batb":[[0,1.35,10],[1,1.34,3.91],[2,1.21,83.24]],"ltp":1.57,"tv":58.69,"id":72857117}]}]}
{"op":"mcm","clk":"11888547098","pt":1724239035808,"mc":[{"id":"1.232050243","rc":[{"batb":[[0,1.34,3.91],[1,1.21,83.24],[2,1.04,1.53]],"ltp":1.57,"tv":58.69,"id":72857117}]}]}
{"op":"mcm","clk":"11888547267","pt":1724239038088,"mc":[{"id":"1.232050243","rc":[{"batb":[[0,1.36,10],[1,1.35,4],[2,1.34,3.91]],"ltp":1.57,"tv":58.69,"id":72857117}]}]}
{"op":"mcm","clk":"11888547402","pt":1724239039760,"mc":[{"id":"1.232050243","rc":[{"batb":[[1,1.34,3.91],[2,1.21,83.24]],"ltp":1.57,"tv":58.69,"id":72857117}]}]}
{"op":"mcm","clk":"11888547538","pt":1724239041571,"mc":[{"id":"1.232050243","rc":[{"batb":[[0,1.34,3.91],[1,1.21,83.24],[2,1.04,1.53]],"ltp":1.57,"tv":58.69,"id":72857117}]}]}
{"op":"mcm","clk":"11888547915","pt":1724239046553,"mc":[{"id":"1.232050243","rc":[{"batb":[[0,1.35,14],[1,1.34,3.91],[2,1.21,83.24]],"ltp":1.57,"tv":58.69,"id":72857117}]}]}
{"op":"mcm","clk":"11888548153","pt":1724239049509,"mc":[{"id":"1.232050243","rc":[{"batb":[[0,1.35,10]],"ltp":1.57,"tv":58.69,"id":72857117}]}]}
{"op":"mcm","clk":"11888548224","pt":1724239050399,"mc":[{"id":"1.232050243","rc":[{"batb":[[0,1.34,3.91],[1,1.21,83.24],[2,1.04,1.53]],"ltp":1.57,"tv":58.69,"id":72857117}]}]}
{"op":"mcm","clk":"11888549206","pt":1724239061995,"mc":[{"id":"1.232050243","rc":[{"batb":[[0,1.35,14],[1,1.34,3.91],[2,1.21,83.24]],"ltp":1.57,"tv":58.69,"id":72857117}]}]}
{"op":"mcm","clk":"11888549395","pt":1724239064304,"mc":[{"id":"1.232050243","rc":[{"batb":[[0,1.35,10]],"ltp":1.57,"tv":58.69,"id":72857117}]}]}
{"op":"mcm","clk":"11888549471","pt":1724239065343,"mc":[{"id":"1.232050243","rc":[{"batb":[[0,1.34,3.91],[1,1.21,83.24],[2,1.04,1.53]],"ltp":1.57,"tv":58.69,"id":72857117}]}]}
{"op":"mcm","clk":"11888551267","pt":1724239087243,"mc":[{"id":"1.232050243","rc":[{"batb":[[0,1.35,14],[1,1.34,3.91],[2,1.21,83.24]],"ltp":1.57,"tv":58.69,"id":72857117}]}]}
{"op":"mcm","clk":"11888551469","pt":1724239089853,"mc":[{"id":"1.232050243","rc":[{"batb":[[0,1.35,10]],"ltp":1.57,"tv":58.69,"id":72857117}]}]}
{"op":"mcm","clk":"11888551582","pt":1724239090956,"mc":[{"id":"1.232050243","rc":[{"batb":[[0,1.34,3.91],[1,1.21,83.24],[2,1.04,1.53]],"ltp":1.57,"tv":58.69,"id":72857117}]}]}
{"op":"mcm","clk":"11888552363","pt":1724239099274,"mc":[{"id":"1.232050243","rc":[{"batb":[[0,1.35,14],[1,1.34,3.91],[2,1.21,83.24]],"ltp":1.57,"tv":58.69,"id":72857117}]}]}
{"op":"mcm","clk":"11888552606","pt":1724239102063,"mc":[{"id":"1.232050243","rc":[{"batb":[[0,1.35,10]],"ltp":1.57,"tv":58.69,"id":72857117}]}]}
{"op":"mcm","clk":"11888552675","pt":1724239103063,"mc":[{"id":"1.232050243","rc":[{"batb":[[0,1.34,3.91],[1,1.21,83.24],[2,1.04,1.53]],"ltp":1.57,"tv":58.69,"id":72857117}]}]}
{"op":"mcm","clk":"11888554740","pt":1724239127083,"mc":[{"id":"1.232050243","rc":[{"batb":[[0,1.35,14],[1,1.34,3.91],[2,1.21,83.24]],"ltp":1.57,"tv":58.69,"id":72857117}]}]}
{"op":"mcm","clk":"11888554981","pt":1724239129821,"mc":[{"id":"1.232050243","rc":[{"batb":[[0,1.35,10]],"ltp":1.57,"tv":58.69,"id":72857117}]}]}
{"op":"mcm","clk":"11888555074","pt":1724239131014,"mc":[{"id":"1.232050243","rc":[{"batb":[[0,1.34,3.91],[1,1.21,83.24],[2,1.04,1.53]],"ltp":1.57,"tv":58.69,"id":72857117}]}]}
{"op":"mcm","clk":"11888555209","pt":1724239132820,"mc":[{"id":"1.232050243","rc":[{"batb":[[0,1.35,4],[1,1.34,3.91],[2,1.21,83.24]],"ltp":1.57,"tv":58.69,"id":72857117}]}]}
{"op":"mcm","clk":"11888555259","pt":1724239133607,"mc":[{"id":"1.232050243","rc":[{"batb":[[0,1.36,10],[1,1.35,4],[2,1.34,3.91]],"ltp":1.57,"tv":58.69,"id":72857117}]}]}
{"op":"mcm","clk":"11888555402","pt":1724239135625,"mc":[{"id":"1.232050243","rc":[{"batb":[[1,1.34,3.91],[2,1.21,83.24]],"ltp":1.57,"tv":58.69,"id":72857117}]}]}
{"op":"mcm","clk":"11888555512","pt":1724239137317,"mc":[{"id":"1.232050243","rc":[{"batb":[[0,1.34,3.91],[1,1.21,83.24],[2,1.04,1.53]],"ltp":1.57,"tv":58.69,"id":72857117}]}]}
{"op":"mcm","clk":"11888556003","pt":1724239144124,"mc":[{"id":"1.232050243","rc":[{"batb":[[0,1.35,14],[1,1.34,3.91],[2,1.21,83.24]],"ltp":1.57,"tv":58.69,"id":72857117}]}]}
{"op":"mcm","clk":"11888556191","pt":1724239146647,"mc":[{"id":"1.232050243","rc":[{"batb":[[0,1.35,10]],"ltp":1.57,"tv":58.69,"id":72857117}]}]}
{"op":"mcm","clk":"11888556258","pt":1724239147532,"mc":[{"id":"1.232050243","rc":[{"batb":[[0,1.34,3.91],[1,1.21,83.24],[2,1.04,1.53]],"ltp":1.57,"tv":58.69,"id":72857117}]}]}
{"op":"mcm","clk":"11888556576","pt":1724239151827,"mc":[{"id":"1.232050243","rc":[{"batb":[[0,1.35,14],[1,1.34,3.91],[2,1.21,83.24]],"ltp":1.57,"tv":58.69,"id":72857117}]}]}
{"op":"mcm","clk":"11888556819","pt":1724239154421,"mc":[{"id":"1.232050243","rc":[{"batb":[[0,1.35,10]],"ltp":1.57,"tv":58.69,"id":72857117}]}]}
{"op":"mcm","clk":"11888556899","pt":1724239155463,"mc":[{"id":"1.232050243","rc":[{"batb":[[0,1.34,3.91],[1,1.21,83.24],[2,1.04,1.53]],"ltp":1.57,"tv":58.69,"id":72857117}]}]}
{"op":"mcm","clk":"11888557650","pt":1724239164835,"mc":[{"id":"1.232050243","rc":[{"batb":[[0,1.35,14],[1,1.34,3.91],[2,1.21,83.24]],"ltp":1.57,"tv":58.69,"id":72857117}]}]}
{"op":"mcm","clk":"11888557866","pt":1724239167638,"mc":[{"id":"1.232050243","rc":[{"batb":[[0,1.35,10]],"ltp":1.57,"tv":58.69,"id":72857117}]}]}
{"op":"mcm","clk":"11888557907","pt":1724239168258,"mc":[{"id":"1.232050243","rc":[{"batb":[[0,1.34,3.91],[1,1.21,83.24],[2,1.04,1.53]],"ltp":1.57,"tv":58.69,"id":72857117}]}]}
{"op":"mcm","clk":"11888559533","pt":1724239189893,"mc":[{"id":"1.232050243","rc":[{"batb":[[0,1.35,14],[1,1.34,3.91],[2,1.21,83.24]],"ltp":1.57,"tv":58.69,"id":72857117}]}]}
{"op":"mcm","clk":"11888559752","pt":1724239192592,"mc":[{"id":"1.232050243","rc":[{"batb":[[0,1.35,10]],"ltp":1.57,"tv":58.69,"id":72857117}]}]}
{"op":"mcm","clk":"11888559810","pt":1724239193469,"mc":[{"id":"1.232050243","rc":[{"batb":[[0,1.34,3.91],[1,1.21,83.24],[2,1.04,1.53]],"ltp":1.57,"tv":58.69,"id":72857117}]}]}
{"op":"mcm","clk":"11888562536","pt":1724239222924,"mc":[{"id":"1.232050243","rc":[{"batb":[[0,1.35,14],[1,1.34,3.91],[2,1.21,83.24]],"ltp":1.57,"tv":58.69,"id":72857117}]}]}
{"op":"mcm","clk":"11888562733","pt":1724239225222,"mc":[{"id":"1.232050243","rc":[{"batb":[[0,1.35,10]],"ltp":1.57,"tv":58.69,"id":72857117}]}]}
{"op":"mcm","clk":"11888562831","pt":1724239226245,"mc":[{"id":"1.232050243","rc":[{"batb":[[0,1.34,3.91],[1,1.21,83.24],[2,1.04,1.53]],"ltp":1.57,"tv":58.69,"id":72857117}]}]}
{"op":"mcm","clk":"11888564876","pt":1724239249044,"mc":[{"id":"1.232050243","rc":[{"batb":[[0,1.35,14],[1,1.34,3.91],[2,1.21,83.24]],"ltp":1.57,"tv":58.69,"id":72857117}]}]}
{"op":"mcm","clk":"11888565111","pt":1724239251875,"mc":[{"id":"1.232050243","rc":[{"batb":[[0,1.35,10]],"ltp":1.57,"tv":58.69,"id":72857117}]}]}
{"op":"mcm","clk":"11888565177","pt":1724239252645,"mc":[{"id":"1.232050243","rc":[{"batb":[[0,1.34,3.91],[1,1.21,83.24],[2,1.04,1.53]],"ltp":1.57,"tv":58.69,"id":72857117}]}]}
{"op":"mcm","clk":"11888565301","pt":1724239254161,"mc":[{"id":"1.232050243","rc":[{"batb":[[0,1.35,4],[1,1.34,3.91],[2,1.21,83.24]],"ltp":1.57,"tv":58.69,"id":72857117}]}]}
{"op":"mcm","clk":"11888565438","pt":1724239255755,"mc":[{"id":"1.232050243","rc":[{"batb":[[0,1.36,10],[1,1.35,4],[2,1.34,3.91]],"ltp":1.57,"tv":58.69,"id":72857117}]}]}
{"op":"mcm","clk":"11888565508","pt":1724239256652,"mc":[{"id":"1.232050243","rc":[{"batb":[[1,1.34,3.91],[2,1.21,83.24]],"ltp":1.57,"tv":58.69,"id":72857117}]}]}
{"op":"mcm","clk":"11888565766","pt":1724239259439,"mc":[{"id":"1.232050243","rc":[{"batb":[[0,1.35,4]],"ltp":1.57,"tv":58.69,"id":72857117}]}]}
{"op":"mcm","clk":"11888566029","pt":1724239262164,"mc":[{"id":"1.232050243","rc":[{"batb":[[0,1.35,10]],"ltp":1.57,"tv":58.69,"id":72857117}]}]}
{"op":"mcm","clk":"11888566372","pt":1724239266064,"mc":[{"id":"1.232050243","rc":[{"batb":[[0,1.35,4]],"ltp":1.57,"tv":58.69,"id":72857117}]}]}
{"op":"mcm","clk":"11888566633","pt":1724239269072,"mc":[{"id":"1.232050243","rc":[{"batb":[[0,1.35,10]],"ltp":1.57,"tv":58.69,"id":72857117}]}]}
{"op":"mcm","clk":"11888566935","pt":1724239272793,"mc":[{"id":"1.232050243","rc":[{"batb":[[0,1.35,4]],"ltp":1.57,"tv":58.69,"id":72857117}]}]}
{"op":"mcm","clk":"11888567225","pt":1724239275704,"mc":[{"id":"1.232050243","rc":[{"batb":[[0,1.35,10]],"ltp":1.57,"tv":58.69,"id":72857117}]}]}
{"op":"mcm","clk":"11888567557","pt":1724239279097,"mc":[{"id":"1.232050243","rc":[{"batb":[[0,1.35,4]],"ltp":1.57,"tv":58.69,"id":72857117}]}]}
{"op":"mcm","clk":"11888567803","pt":1724239281793,"mc":[{"id":"1.232050243","rc":[{"batb":[[0,1.35,10]],"ltp":1.57,"tv":58.69,"id":72857117}]}]}
{"op":"mcm","clk":"11888568099","pt":1724239285079,"mc":[{"id":"1.232050243","rc":[{"batb":[[0,1.34,3.91],[1,1.21,83.24],[2,1.04,1.53]],"ltp":1.57,"tv":58.69,"id":72857117}]}]}
{"op":"mcm","clk":"11888568123","pt":1724239285381,"mc":[{"id":"1.232050243","rc":[{"batb":[[0,1.35,4],[1,1.34,3.91],[2,1.21,83.24]],"ltp":1.57,"tv":58.69,"id":72857117}]}]}
{"op":"mcm","clk":"11888568337","pt":1724239287706,"mc":[{"id":"1.232050243","rc":[{"batb":[[0,1.35,10]],"ltp":1.57,"tv":58.69,"id":72857117}]}]}
{"op":"mcm","clk":"11888568742","pt":1724239291801,"mc":[{"id":"1.232050243","rc":[{"batb":[[0,1.35,4]],"ltp":1.57,"tv":58.69,"id":72857117}]}]}
{"op":"mcm","clk":"11888569007","pt":1724239294398,"mc":[{"id":"1.232050243","rc":[{"batb":[[0,1.35,10]],"ltp":1.57,"tv":58.69,"id":72857117}]}]}
{"op":"mcm","clk":"11888569368","pt":1724239297797,"mc":[{"id":"1.232050243","rc":[{"batb":[[0,1.34,3.91],[1,1.21,83.24],[2,1.04,1.53]],"ltp":1.57,"tv":58.69,"id":72857117}]}]}
{"op":"mcm","clk":"11888569429","pt":1724239298406,"mc":[{"id":"1.232050243","rc":[{"batb":[[0,1.35,4],[1,1.34,3.91],[2,1.21,83.24]],"ltp":1.57,"tv":58.69,"id":72857117}]}]}
{"op":"mcm","clk":"11888569691","pt":1724239301106,"mc":[{"id":"1.232050243","rc":[{"batb":[[0,1.35,10]],"ltp":1.57,"tv":58.69,"id":72857117}]}]}
{"op":"mcm","clk":"11888570030","pt":1724239304919,"mc":[{"id":"1.232050243","rc":[{"batb":[[0,1.35,4]],"ltp":1.57,"tv":58.69,"id":72857117}]}]}
{"op":"mcm","clk":"11888570291","pt":1724239307623,"mc":[{"id":"1.232050243","rc":[{"batb":[[0,1.35,10]],"ltp":1.57,"tv":58.69,"id":72857117}]}]}
{"op":"mcm","clk":"11888570636","pt":1724239311117,"mc":[{"id":"1.232050243","rc":[{"batb":[[0,1.34,3.91],[1,1.21,83.24],[2,1.04,1.53]],"ltp":1.57,"tv":58.69,"id":72857117}]}]}
{"op":"mcm","clk":"11888570656","pt":1724239311330,"mc":[{"id":"1.232050243","rc":[{"batb":[[0,1.35,4],[1,1.34,3.91],[2,1.21,83.24]],"ltp":1.57,"tv":58.69,"id":72857117}]}]}
{"op":"mcm","clk":"11888570885","pt":1724239313823,"mc":[{"id":"1.232050243","rc":[{"batb":[[0,1.35,10]],"ltp":1.57,"tv":58.69,"id":72857117}]}]}
{"op":"mcm","clk":"11888571195","pt":1724239317430,"mc":[{"id":"1.232050243","rc":[{"batb":[[0,1.35,4]],"ltp":1.57,"tv":58.69,"id":72857117}]}]}
{"op":"mcm","clk":"11888571427","pt":1724239320033,"mc":[{"id":"1.232050243","rc":[{"batb":[[0,1.35,10]],"ltp":1.57,"tv":58.69,"id":72857117}]}]}
{"op":"mcm","clk":"11888571747","pt":1724239323115,"mc":[{"id":"1.232050243","rc":[{"batb":[[0,1.36,4],[1,1.35,10],[2,1.34,3.91]],"ltp":1.57,"tv":58.69,"id":72857117}]}]}
{"op":"mcm","clk":"11888571768","pt":1724239323431,"mc":[{"id":"1.232050243","rc":[{"batb":[[1,1.34,3.91],[2,1.21,83.24]],"ltp":1.57,"tv":58.69,"id":72857117}]}]}
{"op":"mcm","clk":"11888572021","pt":1724239325917,"mc":[{"id":"1.232050243","rc":[{"batb":[[0,1.37,10]],"ltp":1.57,"tv":58.69,"id":72857117}]}]}
{"op":"mcm","clk":"11888572311","pt":1724239329029,"mc":[{"id":"1.232050243","rc":[{"batb":[[0,1.35,4]],"ltp":1.57,"tv":58.69,"id":72857117}]}]}
{"op":"mcm","clk":"11888572621","pt":1724239331942,"mc":[{"id":"1.232050243","rc":[{"batb":[[0,1.35,10]],"ltp":1.57,"tv":58.69,"id":72857117}]}]}
{"op":"mcm","clk":"11888572918","pt":1724239335149,"mc":[{"id":"1.232050243","rc":[{"batb":[[0,1.36,4]],"ltp":1.57,"tv":58.69,"id":72857117}]}]}
{"op":"mcm","clk":"11888573135","pt":1724239337544,"mc":[{"id":"1.232050243","rc":[{"batb":[[0,1.35,10]],"ltp":1.57,"tv":58.69,"id":72857117}]}]}
{"op":"mcm","clk":"11888573448","pt":1724239340858,"mc":[{"id":"1.232050243","rc":[{"batb":[[0,1.36,4]],"ltp":1.57,"tv":58.69,"id":72857117}]}]}
{"op":"mcm","clk":"11888573650","pt":1724239343045,"mc":[{"id":"1.232050243","rc":[{"batb":[[0,1.34,3.91],[1,1.21,83.24],[2,1.04,1.53]],"ltp":1.57,"tv":58.69,"id":72857117}]}]}
{"op":"mcm","clk":"11888573687","pt":1724239343353,"mc":[{"id":"1.232050243","rc":[{"batb":[[0,1.35,10],[1,1.34,3.91],[2,1.21,83.24]],"ltp":1.57,"tv":58.69,"id":72857117}]}]}
{"op":"mcm","clk":"11888573997","pt":1724239346881,"mc":[{"id":"1.232050243","rc":[{"batb":[[0,1.35,4]],"ltp":1.57,"tv":58.69,"id":72857117}]}]}
{"op":"mcm","clk":"11888574253","pt":1724239349578,"mc":[{"id":"1.232050243","rc":[{"batb":[[0,1.35,10]],"ltp":1.57,"tv":58.69,"id":72857117}]}]}
{"op":"mcm","clk":"11888574556","pt":1724239352893,"mc":[{"id":"1.232050243","rc":[{"batb":[[0,1.34,3.91],[1,1.21,83.24],[2,1.04,1.53]],"ltp":1.57,"tv":58.69,"id":72857117}]}]}
{"op":"mcm","clk":"11888574589","pt":1724239353201,"mc":[{"id":"1.232050243","rc":[{"batb":[[0,1.35,4],[1,1.34,3.91],[2,1.21,83.24]],"ltp":1.57,"tv":58.69,"id":72857117}]}]}
{"op":"mcm","clk":"11888574845","pt":1724239355902,"mc":[{"id":"1.232050243","rc":[{"batb":[[0,1.35,10]],"ltp":1.57,"tv":58.69,"id":72857117}]}]}
{"op":"mcm","clk":"11888575129","pt":1724239359180,"mc":[{"id":"1.232050243","rc":[{"batb":[[0,1.34,3.91],[1,1.21,83.24],[2,1.04,1.53]],"ltp":1.57,"tv":58.69,"id":72857117}]}]}
{"op":"mcm","clk":"11888575145","pt":1724239359381,"mc":[{"id":"1.232050243","rc":[{"batb":[[0,1.35,4],[1,1.34,3.91],[2,1.21,83.24]],"ltp":1.57,"tv":58.69,"id":72857117}]}]}
{"op":"mcm","clk":"11888575397","pt":1724239361995,"mc":[{"id":"1.232050243","rc":[{"batb":[[0,1.35,10]],"ltp":1.57,"tv":58.69,"id":72857117}]}]}
{"op":"mcm","clk":"11888575653","pt":1724239364798,"mc":[{"id":"1.232050243","rc":[{"batb":[[0,1.36,4],[1,1.35,10],[2,1.34,3.91]],"ltp":1.57,"tv":58.69,"id":72857117}]}]}
{"op":"mcm","clk":"11888575719","pt":1724239365384,"mc":[{"id":"1.232050243","rc":[{"batb":[[1,1.34,3.91],[2,1.21,83.24]],"ltp":1.57,"tv":58.69,"id":72857117}]}]}
{"op":"mcm","clk":"11888575980","pt":1724239367876,"mc":[{"id":"1.232050243","rc":[{"batb":[[0,1.35,10]],"ltp":1.57,"tv":58.69,"id":72857117}]}]}
{"op":"mcm","clk":"11888576306","pt":1724239371600,"mc":[{"id":"1.232050243","rc":[{"batb":[[0,1.35,4]],"ltp":1.57,"tv":58.69,"id":72857117}]}]}
{"op":"mcm","clk":"11888576480","pt":1724239373980,"mc":[{"id":"1.232050243","rc":[{"batb":[[0,1.34,3.91],[1,1.21,83.24],[2,1.04,1.53]],"ltp":1.57,"tv":58.69,"id":72857117}]}]}
{"op":"mcm","clk":"11888576504","pt":1724239374284,"mc":[{"id":"1.232050243","rc":[{"batb":[[0,1.35,10],[1,1.34,3.91],[2,1.21,83.24]],"ltp":1.57,"tv":58.69,"id":72857117}]}]}
{"op":"mcm","clk":"11888576856","pt":1724239378097,"mc":[{"id":"1.232050243","rc":[{"batb":[[0,1.35,4]],"ltp":1.57,"tv":58.69,"id":72857117}]}]}
{"op":"mcm","clk":"11888577128","pt":1724239380899,"mc":[{"id":"1.232050243","rc":[{"batb":[[0,1.35,10]],"ltp":1.57,"tv":58.69,"id":72857117}]}]}
{"op":"mcm","clk":"11888577486","pt":1724239384427,"mc":[{"id":"1.232050243","rc":[{"batb":[[0,1.36,4]],"ltp":1.57,"tv":58.69,"id":72857117}]}]}
{"op":"mcm","clk":"11888577729","pt":1724239387118,"mc":[{"id":"1.232050243","rc":[{"batb":[[0,1.34,3.91],[1,1.21,83.24],[2,1.04,1.53]],"ltp":1.57,"tv":58.69,"id":72857117}]}]}
{"op":"mcm","clk":"11888577759","pt":1724239387384,"mc":[{"id":"1.232050243","rc":[{"batb":[[0,1.35,10],[1,1.34,3.91],[2,1.21,83.24]],"ltp":1.57,"tv":58.69,"id":72857117}]}]}
{"op":"mcm","clk":"11888577975","pt":1724239389704,"mc":[{"id":"1.232050243","rc":[{"batb":[[0,1.36,4],[1,1.35,10],[2,1.34,3.91]],"ltp":1.57,"tv":58.69,"id":72857117}]}]}
{"op":"mcm","clk":"11888578077","pt":1724239390901,"mc":[{"id":"1.232050243","rc":[{"batb":[[1,1.34,3.91],[2,1.21,83.24]],"ltp":1.57,"tv":58.69,"id":72857117}]}]}
{"op":"mcm","clk":"11888578176","pt":1724239392186,"mc":[{"id":"1.232050243","rc":[{"batb":[[0,1.34,3.91],[1,1.21,83.24],[2,1.04,1.53]],"ltp":1.57,"tv":58.69,"id":72857117}]}]}
{"op":"mcm","clk":"11888580031","pt":1724239411852,"mc":[{"id":"1.232050243","rc":[{"batb":[[0,1.35,14],[1,1.34,3.91],[2,1.21,83.24]],"ltp":1.57,"tv":58.69,"id":72857117}]}]}
{"op":"mcm","clk":"11888580236","pt":1724239414330,"mc":[{"id":"1.232050243","rc":[{"batb":[[0,1.35,10]],"ltp":1.57,"tv":58.69,"id":72857117}]}]}
{"op":"mcm","clk":"11888580340","pt":1724239415463,"mc":[{"id":"1.232050243","rc":[{"batb":[[0,1.34,3.91],[1,1.21,83.24],[2,1.04,1.53]],"ltp":1.57,"tv":58.69,"id":72857117}]}]}
{"op":"mcm","clk":"11888581202","pt":1724239424543,"mc":[{"id":"1.232050243","rc":[{"batb":[[0,1.35,14],[1,1.34,3.91],[2,1.21,83.24]],"ltp":1.57,"tv":58.69,"id":72857117}]}]}
{"op":"mcm","clk":"11888581460","pt":1724239427143,"mc":[{"id":"1.232050243","rc":[{"batb":[[0,1.35,10]],"ltp":1.57,"tv":58.69,"id":72857117}]}]}
{"op":"mcm","clk":"11888581556","pt":1724239428131,"mc":[{"id":"1.232050243","rc":[{"batb":[[0,1.34,3.91],[1,1.21,83.24],[2,1.04,1.53]],"ltp":1.57,"tv":58.69,"id":72857117}]}]}
{"op":"mcm","clk":"11888582320","pt":1724239436478,"mc":[{"id":"1.232050243","rc":[{"batb":[[0,1.35,14],[1,1.34,3.91],[2,1.21,83.24]],"ltp":1.57,"tv":58.69,"id":72857117}]}]}
{"op":"mcm","clk":"11888582678","pt":1724239439955,"mc":[{"id":"1.232050243","rc":[{"batb":[[0,1.34,3.91],[1,1.21,83.24],[2,1.04,1.53]],"ltp":1.57,"tv":58.69,"id":72857117}]}]}
{"op":"mcm","clk":"11888583195","pt":1724239444984,"mc":[{"id":"1.232050243","rc":[{"batb":[[0,1.35,14],[1,1.34,3.91],[2,1.21,83.24]],"ltp":1.57,"tv":58.69,"id":72857117}]}]}
{"op":"mcm","clk":"11888583487","pt":1724239447480,"mc":[{"id":"1.232050243","rc":[{"batb":[[0,1.35,10]],"ltp":1.57,"tv":58.69,"id":72857117}]}]}
{"op":"mcm","clk":"11888583585","pt":1724239448476,"mc":[{"id":"1.232050243","rc":[{"batb":[[0,1.34,3.91],[1,1.21,83.24],[2,1.04,1.53]],"ltp":1.57,"tv":58.69,"id":72857117}]}]}
{"op":"mcm","clk":"11888584151","pt":1724239453673,"mc":[{"id":"1.232050243","rc":[{"batb":[[0,1.35,14],[1,1.34,3.91],[2,1.21,83.24]],"ltp":1.57,"tv":58.69,"id":72857117}]}]}
{"op":"mcm","clk":"11888584445","pt":1724239456388,"mc":[{"id":"1.232050243","rc":[{"batb":[[0,1.35,10]],"ltp":1.57,"tv":58.69,"id":72857117}]}]}
{"op":"mcm","clk":"11888584565","pt":1724239457484,"mc":[{"id":"1.232050243","rc":[{"batb":[[0,1.34,3.91],[1,1.21,83.24],[2,1.04,1.53]],"ltp":1.57,"tv":58.69,"id":72857117}]}]}
{"op":"mcm","clk":"11888585022","pt":1724239462089,"mc":[{"id":"1.232050243","rc":[{"batb":[[0,1.35,14],[1,1.34,3.91],[2,1.21,83.24]],"ltp":1.57,"tv":58.69,"id":72857117}]}]}
{"op":"mcm","clk":"11888585294","pt":1724239464694,"mc":[{"id":"1.232050243","rc":[{"batb":[[0,1.35,10]],"ltp":1.57,"tv":58.69,"id":72857117}]}]}
{"op":"mcm","clk":"11888585383","pt":1724239465685,"mc":[{"id":"1.232050243","rc":[{"batb":[[0,1.34,3.91],[1,1.21,83.24],[2,1.04,1.53]],"ltp":1.57,"tv":58.69,"id":72857117}]}]}
{"op":"mcm","clk":"11888585520","pt":1724239467093,"mc":[{"id":"1.232050243","rc":[{"batb":[[0,1.35,4],[1,1.34,3.91],[2,1.21,83.24]],"ltp":1.57,"tv":58.69,"id":72857117}]}]}
{"op":"mcm","clk":"11888585776","pt":1724239469889,"mc":[{"id":"1.232050243","rc":[{"batb":[[0,1.35,10]],"ltp":1.57,"tv":58.69,"id":72857117}]}]}
{"op":"mcm","clk":"11888586154","pt":1724239473728,"mc":[{"id":"1.232050243","rc":[{"batb":[[0,1.35,4]],"ltp":1.57,"tv":58.69,"id":72857117}]}]}
{"op":"mcm","clk":"11888586441","pt":1724239476502,"mc":[{"id":"1.232050243","rc":[{"batb":[[0,1.35,10]],"ltp":1.57,"tv":58.69,"id":72857117}]}]}
{"op":"mcm","clk":"11888586787","pt":1724239479935,"mc":[{"id":"1.232050243","rc":[{"batb":[[0,1.35,4]],"ltp":1.57,"tv":58.69,"id":72857117}]}]}
{"op":"mcm","clk":"11888587058","pt":1724239482739,"mc":[{"id":"1.232050243","rc":[{"batb":[[0,1.35,10]],"ltp":1.57,"tv":58.69,"id":72857117}]}]}
{"op":"mcm","clk":"11888587276","pt":1724239484933,"mc":[{"id":"1.232050243","rc":[{"batb":[[0,1.36,4],[1,1.35,10],[2,1.34,3.91]],"ltp":1.57,"tv":58.69,"id":72857117}]}]}
{"op":"mcm","clk":"11888587410","pt":1724239486435,"mc":[{"id":"1.232050243","rc":[{"batb":[[1,1.34,3.91],[2,1.21,83.24]],"ltp":1.57,"tv":58.69,"id":72857117}]}]}
{"op":"mcm","clk":"11888587505","pt":1724239487210,"mc":[{"id":"1.232050243","rc":[{"batb":[[0,1.34,3.91],[1,1.21,83.24],[2,1.04,1.53]],"ltp":1.57,"tv":58.69,"id":72857117}]}]}
{"op":"mcm","clk":"11888587695","pt":1724239489126,"mc":[{"id":"1.232050243","rc":[{"batb":[[0,1.35,10],[1,1.34,3.91],[2,1.21,83.24]],"ltp":1.57,"tv":58.69,"id":72857117}]}]}
{"op":"mcm","clk":"11888588083","pt":1724239492927,"mc":[{"id":"1.232050243","rc":[{"batb":[[0,1.35,4]],"ltp":1.57,"tv":58.69,"id":72857117}]}]}
{"op":"mcm","clk":"11888588287","pt":1724239495125,"mc":[{"id":"1.232050243","rc":[{"batb":[[0,1.34,3.91],[1,1.21,83.24],[2,1.04,1.53]],"ltp":1.57,"tv":58.69,"id":72857117}]}]}
{"op":"mcm","clk":"11888588329","pt":1724239495545,"mc":[{"id":"1.232050243","rc":[{"batb":[[0,1.35,10],[1,1.34,3.91],[2,1.21,83.24]],"ltp":1.57,"tv":58.69,"id":72857117}]}]}
{"op":"mcm","clk":"11888588662","pt":1724239499037,"mc":[{"id":"1.232050243","rc":[{"batb":[[0,1.35,4]],"ltp":1.57,"tv":58.69,"id":72857117}]}]}
{"op":"mcm","clk":"11888588931","pt":1724239501864,"mc":[{"id":"1.232050243","rc":[{"batb":[[0,1.35,10]],"ltp":1.57,"tv":58.69,"id":72857117}]}]}
{"op":"mcm","clk":"11888589309","pt":1724239505582,"mc":[{"id":"1.232050243","rc":[{"batb":[[0,1.35,4]],"ltp":1.57,"tv":58.69,"id":72857117}]}]}
{"op":"mcm","clk":"11888589588","pt":1724239508180,"mc":[{"id":"1.232050243","rc":[{"batb":[[0,1.35,10]],"ltp":1.57,"tv":58.69,"id":72857117}]}]}
{"op":"mcm","clk":"11888589949","pt":1724239511683,"mc":[{"id":"1.232050243","rc":[{"batb":[[0,1.35,4]],"ltp":1.57,"tv":58.69,"id":72857117}]}]}
{"op":"mcm","clk":"11888590212","pt":1724239514179,"mc":[{"id":"1.232050243","rc":[{"batb":[[0,1.36,10]],"ltp":1.57,"tv":58.69,"id":72857117}]}]}
{"op":"mcm","clk":"11888590609","pt":1724239517992,"mc":[{"id":"1.232050243","rc":[{"batb":[[0,1.35,4]],"ltp":1.57,"tv":58.69,"id":72857117}]}]}
{"op":"mcm","clk":"11888590858","pt":1724239520483,"mc":[{"id":"1.232050243","rc":[{"batb":[[0,1.35,10]],"ltp":1.57,"tv":58.69,"id":72857117}]}]}
{"op":"mcm","clk":"11888591220","pt":1724239524056,"mc":[{"id":"1.232050243","rc":[{"batb":[[0,1.35,4]],"ltp":1.57,"tv":58.69,"id":72857117}]}]}
{"op":"mcm","clk":"11888591518","pt":1724239526671,"mc":[{"id":"1.232050243","rc":[{"batb":[[0,1.35,10]],"ltp":1.57,"tv":58.69,"id":72857117}]}]}
{"op":"mcm","clk":"11888591860","pt":1724239529988,"mc":[{"id":"1.232050243","rc":[{"batb":[[0,1.34,3.91],[1,1.21,83.24],[2,1.04,1.53]],"ltp":1.57,"tv":58.69,"id":72857117}]}]}
{"op":"mcm","clk":"11888591908","pt":1724239530510,"mc":[{"id":"1.232050243","rc":[{"batb":[[0,1.35,4],[1,1.34,3.91],[2,1.21,83.24]],"ltp":1.57,"tv":58.69,"id":72857117}]}]}
{"op":"mcm","clk":"11888592178","pt":1724239533075,"mc":[{"id":"1.232050243","rc":[{"batb":[[0,1.35,10]],"ltp":1.57,"tv":58.69,"id":72857117}]}]}
{"op":"mcm","clk":"11888592459","pt":1724239535790,"mc":[{"id":"1.232050243","rc":[{"batb":[[0,1.36,4],[1,1.35,10],[2,1.34,3.91]],"ltp":1.57,"tv":58.69,"id":72857117}]}]}
{"op":"mcm","clk":"11888592517","pt":1724239536413,"mc":[{"id":"1.232050243","rc":[{"batb":[[1,1.34,3.91],[2,1.21,83.24]],"ltp":1.57,"tv":58.69,"id":72857117}]}]}
{"op":"mcm","clk":"11888592734","pt":1724239538623,"mc":[{"id":"1.232050243","rc":[{"batb":[[0,1.35,10]],"ltp":1.57,"tv":58.69,"id":72857117}]}]}
{"op":"mcm","clk":"11888592980","pt":1724239540813,"mc":[{"id":"1.232050243","rc":[{"batb":[[0,1.36,4],[1,1.35,10],[2,1.34,3.91]],"ltp":1.57,"tv":58.69,"id":72857117}]}]}
{"op":"mcm","clk":"11888593145","pt":1724239542317,"mc":[{"id":"1.232050243","rc":[{"batb":[[1,1.34,3.91],[2,1.21,83.24]],"ltp":1.57,"tv":58.69,"id":72857117}]}]}
{"op":"mcm","clk":"11888593246","pt":1724239543416,"mc":[{"id":"1.232050243","rc":[{"batb":[[0,1.34,3.91],[1,1.21,83.24],[2,1.04,1.53]],"ltp":1.57,"tv":58.69,"id":72857117}]}]}
{"op":"mcm","clk":"11888593373","pt":1724239544708,"mc":[{"id":"1.232050243","rc":[{"batb":[[0,1.35,10],[1,1.34,3.91],[2,1.21,83.24]],"ltp":1.57,"tv":58.69,"id":72857117}]}]}
{"op":"mcm","clk":"11888593707","pt":1724239548132,"mc":[{"id":"1.232050243","rc":[{"batb":[[0,1.34,3.91],[1,1.21,83.24],[2,1.04,1.53]],"ltp":1.57,"tv":58.69,"id":72857117}]}]}
{"op":"mcm","clk":"11888593731","pt":1724239548301,"mc":[{"id":"1.232050243","rc":[{"batb":[[0,1.35,4],[1,1.34,3.91],[2,1.21,83.24]],"ltp":1.57,"tv":58.69,"id":72857117}]}]}
{"op":"mcm","clk":"11888593983","pt":1724239550939,"mc":[{"id":"1.232050243","rc":[{"batb":[[0,1.35,10]],"ltp":1.57,"tv":58.69,"id":72857117}]}]}
{"op":"mcm","clk":"11888594268","pt":1724239554143,"mc":[{"id":"1.232050243","rc":[{"batb":[[0,1.36,4]],"ltp":1.57,"tv":58.69,"id":72857117}]}]}
{"op":"mcm","clk":"11888594394","pt":1724239555713,"mc":[{"id":"1.232050243","rc":[{"batb":[[0,1.34,3.91],[1,1.21,83.24],[2,1.04,1.53]],"ltp":1.57,"tv":58.69,"id":72857117}]}]}
{"op":"mcm","clk":"11888594710","pt":1724239559357,"mc":[{"id":"1.232050243","rc":[{"batb":[[0,1.35,14],[1,1.34,3.91],[2,1.21,83.24]],"ltp":1.57,"tv":58.69,"id":72857117}]}]}
{"op":"mcm","clk":"11888594982","pt":1724239562120,"mc":[{"id":"1.232050243","rc":[{"batb":[[0,1.35,10]],"ltp":1.57,"tv":58.69,"id":72857117}]}]}
{"op":"mcm","clk":"11888595062","pt":1724239562954,"mc":[{"id":"1.232050243","rc":[{"batb":[[0,1.34,3.91],[1,1.21,83.24],[2,1.04,1.53]],"ltp":1.57,"tv":58.69,"id":72857117}]}]}
{"op":"mcm","clk":"11888595287","pt":1724239565143,"mc":[{"id":"1.232050243","rc":[{"batb":[[0,1.35,14],[1,1.34,3.91],[2,1.21,83.24]],"ltp":1.57,"tv":58.69,"id":72857117}]}]}
{"op":"mcm","clk":"11888595545","pt":1724239567532,"mc":[{"id":"1.232050243","rc":[{"batb":[[0,1.35,10]],"ltp":1.57,"tv":58.69,"id":72857117}]}]}
{"op":"mcm","clk":"11888595625","pt":1724239568421,"mc":[{"id":"1.232050243","rc":[{"batb":[[0,1.34,3.91],[1,1.21,83.24],[2,1.04,1.53]],"ltp":1.57,"tv":58.69,"id":72857117}]}]}
{"op":"mcm","clk":"11888595843","pt":1724239570756,"mc":[{"id":"1.232050243","rc":[{"batb":[[0,1.36,10],[1,1.35,4],[2,1.34,3.91]],"ltp":1.57,"tv":58.69,"id":72857117}]}]}
{"op":"mcm","clk":"11888596019","pt":1724239572776,"mc":[{"id":"1.232050243","rc":[{"batb":[[1,1.34,3.91],[2,1.21,83.24]],"ltp":1.57,"tv":58.69,"id":72857117}]}]}
{"op":"mcm","clk":"11888596161","pt":1724239574381,"mc":[{"id":"1.232050243","rc":[{"batb":[[0,1.34,3.91],[1,1.21,83.24],[2,1.04,1.53]],"ltp":1.57,"tv":58.69,"id":72857117}]}]}
{"op":"mcm","clk":"11888596322","pt":1724239576076,"mc":[{"id":"1.232050243","rc":[{"batb":[[0,1.35,4],[1,1.34,3.91],[2,1.21,83.24]],"ltp":1.57,"tv":58.69,"id":72857117}]}]}
{"op":"mcm","clk":"11888596515","pt":1724239577879,"mc":[{"id":"1.232050243","rc":[{"batb":[[0,1.36,10],[1,1.35,4],[2,1.34,3.91]],"ltp":1.57,"tv":58.69,"id":72857117}]}]}
{"op":"mcm","clk":"11888596589","pt":1724239578662,"mc":[{"id":"1.232050243","rc":[{"batb":[[1,1.34,3.91],[2,1.21,83.24]],"ltp":1.57,"tv":58.69,"id":72857117}]}]}
{"op":"mcm","clk":"11888596847","pt":1724239581555,"mc":[{"id":"1.232050243","rc":[{"batb":[[0,1.35,4]],"ltp":1.57,"tv":58.69,"id":72857117}]}]}
{"op":"mcm","clk":"11888597053","pt":1724239583989,"mc":[{"id":"1.232050243","rc":[{"batb":[[0,1.36,10]],"ltp":1.57,"tv":58.69,"id":72857117}]}]}
{"op":"mcm","clk":"11888597410","pt":1724239587775,"mc":[{"id":"1.232050243","rc":[{"batb":[[0,1.35,4]],"ltp":1.57,"tv":58.69,"id":72857117}]}]}
{"op":"mcm","clk":"11888597619","pt":1724239590098,"mc":[{"id":"1.232050243","rc":[{"batb":[[0,1.34,3.91],[1,1.21,83.24],[2,1.04,1.53]],"ltp":1.57,"tv":58.69,"id":72857117}]}]}
{"op":"mcm","clk":"11888597635","pt":1724239590334,"mc":[{"id":"1.232050243","rc":[{"batb":[[0,1.35,10],[1,1.34,3.91],[2,1.21,83.24]],"ltp":1.57,"tv":58.69,"id":72857117}]}]}
{"op":"mcm","clk":"11888597960","pt":1724239593883,"mc":[{"id":"1.232050243","rc":[{"batb":[[0,1.35,4]],"ltp":1.57,"tv":58.69,"id":72857117}]}]}
{"op":"mcm","clk":"11888598148","pt":1724239596517,"mc":[{"id":"1.232050243","rc":[{"batb":[[0,1.36,10]],"ltp":1.57,"tv":58.69,"id":72857117}]}]}
{"op":"mcm","clk":"11888598486","pt":1724239600595,"mc":[{"id":"1.232050243","rc":[{"batb":[[0,1.37,4]],"ltp":1.57,"tv":58.69,"id":72857117}]}]}
{"op":"mcm","clk":"11888598683","pt":1724239603029,"mc":[{"id":"1.232050243","rc":[{"batb":[[0,1.35,10]],"ltp":1.57,"tv":58.69,"id":72857117}]}]}
{"op":"mcm","clk":"11888598990","pt":1724239606591,"mc":[{"id":"1.232050243","rc":[{"batb":[[0,1.35,4]],"ltp":1.57,"tv":58.69,"id":72857117}]}]}
{"op":"mcm","clk":"11888599172","pt":1724239608943,"mc":[{"id":"1.232050243","rc":[{"batb":[[0,1.34,3.91],[1,1.21,83.24],[2,1.04,1.53]],"ltp":1.57,"tv":58.69,"id":72857117}]}]}
{"op":"mcm","clk":"11888599217","pt":1724239609324,"mc":[{"id":"1.232050243","rc":[{"batb":[[0,1.35,10],[1,1.34,3.91],[2,1.21,83.24]],"ltp":1.57,"tv":58.69,"id":72857117}]}]}
{"op":"mcm","clk":"11888599545","pt":1724239612908,"mc":[{"id":"1.232050243","rc":[{"batb":[[0,1.35,4]],"ltp":1.57,"tv":58.69,"id":72857117}]}]}
{"op":"mcm","clk":"11888599755","pt":1724239615543,"mc":[{"id":"1.232050243","rc":[{"batb":[[0,1.35,10]],"ltp":1.57,"tv":58.69,"id":72857117}]}]}
{"op":"mcm","clk":"11888600042","pt":1724239619125,"mc":[{"id":"1.232050243","rc":[{"batb":[[0,1.35,4]],"ltp":1.57,"tv":58.69,"id":72857117}]}]}
{"op":"mcm","clk":"11888600309","pt":1724239621934,"mc":[{"id":"1.232050243","rc":[{"batb":[[0,1.35,10]],"ltp":1.57,"tv":58.69,"id":72857117}]}]}
{"op":"mcm","clk":"11888600647","pt":1724239625526,"mc":[{"id":"1.232050243","rc":[{"batb":[[0,1.35,4]],"ltp":1.57,"tv":58.69,"id":72857117}]}]}
{"op":"mcm","clk":"11888600908","pt":1724239628122,"mc":[{"id":"1.232050243","rc":[{"batb":[[0,1.36,10]],"ltp":1.57,"tv":58.69,"id":72857117}]}]}
{"op":"mcm","clk":"11888601283","pt":1724239631545,"mc":[{"id":"1.232050243","rc":[{"batb":[[0,1.34,3.91],[1,1.21,83.24],[2,1.04,1.53]],"ltp":1.57,"tv":58.69,"id":72857117}]}]}
{"op":"mcm","clk":"11888601840","pt":1724239636860,"mc":[{"id":"1.232050243","rc":[{"batb":[[0,1.35,14],[1,1.34,3.91],[2,1.21,83.24]],"ltp":1.57,"tv":58.69,"id":72857117}]}]}
{"op":"mcm","clk":"11888602615","pt":1724239645366,"mc":[{"id":"1.232050243","rc":[{"batb":[[0,1.35,10]],"ltp":1.57,"tv":58.69,"id":72857117}]}]}
{"op":"mcm","clk":"11888602705","pt":1724239646363,"mc":[{"id":"1.232050243","rc":[{"batb":[[0,1.34,3.91],[1,1.21,83.24],[2,1.04,1.53]],"ltp":1.57,"tv":58.69,"id":72857117}]}]}
{"op":"mcm","clk":"11888602922","pt":1724239648173,"mc":[{"id":"1.232050243","rc":[{"batb":[[0,1.36,4],[1,1.34,3.91],[2,1.21,83.24]],"ltp":1.57,"tv":58.69,"id":72857117}]}]}
{"op":"mcm","clk":"11888603000","pt":1724239648953,"mc":[{"id":"1.232050243","rc":[{"batb":[[1,1.35,10],[2,1.34,3.91]],"ltp":1.57,"tv":58.69,"id":72857117}]}]}
{"op":"mcm","clk":"11888603317","pt":1724239652182,"mc":[{"id":"1.232050243","rc":[{"batb":[[0,1.35,10],[1,1.34,3.91],[2,1.21,83.24]],"ltp":1.57,"tv":58.69,"id":72857117}]}]}
{"op":"mcm","clk":"11888603447","pt":1724239653588,"mc":[{"id":"1.232050243","rc":[{"batb":[[0,1.34,3.91],[1,1.21,83.24],[2,1.04,1.53]],"ltp":1.57,"tv":58.69,"id":72857117}]}]}
{"op":"mcm","clk":"11888603656","pt":1724239655752,"mc":[{"id":"1.232050243","rc":[{"batb":[[0,1.35,14],[1,1.34,3.91],[2,1.21,83.24]],"ltp":1.57,"tv":58.69,"id":72857117}]}]}
{"op":"mcm","clk":"11888603921","pt":1724239658353,"mc":[{"id":"1.232050243","rc":[{"batb":[[0,1.35,10]],"ltp":1.57,"tv":58.69,"id":72857117}]}]}
{"op":"mcm","clk":"11888604003","pt":1724239659386,"mc":[{"id":"1.232050243","rc":[{"batb":[[0,1.34,3.91],[1,1.21,83.24],[2,1.04,1.53]],"ltp":1.57,"tv":58.69,"id":72857117}]}]}
{"op":"mcm","clk":"11888604392","pt":1724239663666,"mc":[{"id":"1.232050243","rc":[{"batb":[[0,1.35,14],[1,1.34,3.91],[2,1.21,83.24]],"ltp":1.57,"tv":58.69,"id":72857117}]}]}
{"op":"mcm","clk":"11888604629","pt":1724239666258,"mc":[{"id":"1.232050243","rc":[{"batb":[[0,1.35,10]],"ltp":1.57,"tv":58.69,"id":72857117}]}]}
{"op":"mcm","clk":"11888604709","pt":1724239667192,"mc":[{"id":"1.232050243","rc":[{"batb":[[0,1.34,3.91],[1,1.21,83.24],[2,1.04,1.53]],"ltp":1.57,"tv":58.69,"id":72857117}]}]}
{"op":"mcm","clk":"11888604947","pt":1724239670088,"mc":[{"id":"1.232050243","rc":[{"batb":[[0,1.35,14],[1,1.34,3.91],[2,1.21,83.24]],"ltp":1.57,"tv":58.69,"id":72857117}]}]}
{"op":"mcm","clk":"11888605159","pt":1724239672576,"mc":[{"id":"1.232050243","rc":[{"batb":[[0,1.35,10]],"ltp":1.57,"tv":58.69,"id":72857117}]}]}
{"op":"mcm","clk":"11888605238","pt":1724239673507,"mc":[{"id":"1.232050243","rc":[{"batb":[[0,1.34,3.91],[1,1.21,83.24],[2,1.04,1.53]],"ltp":1.57,"tv":58.69,"id":72857117}]}]}
{"op":"mcm","clk":"11888605459","pt":1724239675699,"mc":[{"id":"1.232050243","rc":[{"batb":[[0,1.35,14],[1,1.34,3.91],[2,1.21,83.24]],"ltp":1.57,"tv":58.69,"id":72857117}]}]}
{"op":"mcm","clk":"11888605701","pt":1724239678635,"mc":[{"id":"1.232050243","rc":[{"batb":[[0,1.35,10]],"ltp":1.57,"tv":58.69,"id":72857117}]}]}
{"op":"mcm","clk":"11888605782","pt":1724239679384,"mc":[{"id":"1.232050243","rc":[{"batb":[[0,1.34,3.91],[1,1.21,83.24],[2,1.04,1.53]],"ltp":1.57,"tv":58.69,"id":72857117}]}]}
{"op":"mcm","clk":"11888606180","pt":1724239683503,"mc":[{"id":"1.232050243","rc":[{"batb":[[0,1.35,14],[1,1.34,3.91],[2,1.21,83.24]],"ltp":1.57,"tv":58.69,"id":72857117}]}]}
{"op":"mcm","clk":"11888606376","pt":1724239685894,"mc":[{"id":"1.232050243","rc":[{"batb":[[0,1.35,10]],"ltp":1.57,"tv":58.69,"id":72857117}]}]}
{"op":"mcm","clk":"11888606515","pt":1724239687301,"mc":[{"id":"1.232050243","rc":[{"batb":[[0,1.34,3.91],[1,1.21,83.24],[2,1.04,1.53]],"ltp":1.57,"tv":58.69,"id":72857117}]}]}
{"op":"mcm","clk":"11888607216","pt":1724239694544,"mc":[{"id":"1.232050243","rc":[{"batb":[[0,1.35,14],[1,1.34,3.91],[2,1.21,83.24]],"ltp":1.57,"tv":58.69,"id":72857117}]}]}
{"op":"mcm","clk":"11888607543","pt":1724239698139,"mc":[{"id":"1.232050243","rc":[{"batb":[[0,1.34,3.91],[1,1.21,83.24],[2,1.04,1.53]],"ltp":1.57,"tv":58.69,"id":72857117}]}]}
{"op":"mcm","clk":"11888608228","pt":1724239705941,"mc":[{"id":"1.232050243","rc":[{"batb":[[0,1.35,14],[1,1.34,3.91],[2,1.21,83.24]],"ltp":1.57,"tv":58.69,"id":72857117}]}]}
{"op":"mcm","clk":"11888608475","pt":1724239708635,"mc":[{"id":"1.232050243","rc":[{"batb":[[0,1.35,10]],"ltp":1.57,"tv":58.69,"id":72857117}]}]}
{"op":"mcm","clk":"11888608556","pt":1724239709620,"mc":[{"id":"1.232050243","rc":[{"batb":[[0,1.34,3.91],[1,1.21,83.24],[2,1.04,1.53]],"ltp":1.57,"tv":58.69,"id":72857117}]}]}
{"op":"mcm","clk":"11888608744","pt":1724239711847,"mc":[{"id":"1.232050243","rc":[{"batb":[[0,1.36,10],[1,1.35,4],[2,1.34,3.91]],"ltp":1.57,"tv":58.69,"id":72857117}]}]}
{"op":"mcm","clk":"11888608929","pt":1724239714124,"mc":[{"id":"1.232050243","rc":[{"batb":[[1,1.34,3.91],[2,1.21,83.24]],"ltp":1.57,"tv":58.69,"id":72857117}]}]}
{"op":"mcm","clk":"11888609043","pt":1724239715421,"mc":[{"id":"1.232050243","rc":[{"batb":[[0,1.34,3.91],[1,1.21,83.24],[2,1.04,1.53]],"ltp":1.57,"tv":58.69,"id":72857117}]}]}
{"op":"mcm","clk":"11888609256","pt":1724239718163,"mc":[{"id":"1.232050243","rc":[{"batb":[[0,1.35,14],[1,1.34,3.91],[2,1.21,83.24]],"ltp":1.57,"tv":58.69,"id":72857117}]}]}
{"op":"mcm","clk":"11888609456","pt":1724239720451,"mc":[{"id":"1.232050243","rc":[{"batb":[[0,1.35,10]],"ltp":1.57,"tv":58.69,"id":72857117}]}]}
{"op":"mcm","clk":"11888609540","pt":1724239721436,"mc":[{"id":"1.232050243","rc":[{"batb":[[0,1.34,3.91],[1,1.21,83.24],[2,1.04,1.53]],"ltp":1.57,"tv":58.69,"id":72857117}]}]}
{"op":"mcm","clk":"11888610145","pt":1724239728484,"mc":[{"id":"1.232050243","rc":[{"batb":[[0,1.35,14],[1,1.34,3.91],[2,1.21,83.24]],"ltp":1.57,"tv":58.69,"id":72857117}]}]}
{"op":"mcm","clk":"11888610329","pt":1724239730844,"mc":[{"id":"1.232050243","rc":[{"batb":[[0,1.35,10]],"ltp":1.57,"tv":58.69,"id":72857117}]}]}
{"op":"mcm","clk":"11888610431","pt":1724239732085,"mc":[{"id":"1.232050243","rc":[{"batb":[[0,1.34,3.91],[1,1.21,83.24],[2,1.04,1.53]],"ltp":1.57,"tv":58.69,"id":72857117}]}]}
{"op":"mcm","clk":"11888610917","pt":1724239738561,"mc":[{"id":"1.232050243","rc":[{"batb":[[0,1.35,14],[1,1.34,3.91],[2,1.21,83.24]],"ltp":1.57,"tv":58.69,"id":72857117}]}]}
{"op":"mcm","clk":"11888611122","pt":1724239741085,"mc":[{"id":"1.232050243","rc":[{"batb":[[0,1.35,10]],"ltp":1.57,"tv":58.69,"id":72857117}]}]}
{"op":"mcm","clk":"11888611184","pt":1724239741872,"mc":[{"id":"1.232050243","rc":[{"batb":[[0,1.34,3.91],[1,1.21,83.24],[2,1.04,1.53]],"ltp":1.57,"tv":58.69,"id":72857117}]}]}
{"op":"mcm","clk":"11888611441","pt":1724239744886,"mc":[{"id":"1.232050243","rc":[{"batb":[[0,1.35,14],[1,1.34,3.91],[2,1.21,83.24]],"ltp":1.57,"tv":58.69,"id":72857117}]}]}
{"op":"mcm","clk":"11888611628","pt":1724239747258,"mc":[{"id":"1.232050243","rc":[{"batb":[[0,1.35,10]],"ltp":1.57,"tv":58.69,"id":72857117}]}]}
{"op":"mcm","clk":"11888611705","pt":1724239748386,"mc":[{"id":"1.232050243","rc":[{"batb":[[0,1.34,3.91],[1,1.21,83.24],[2,1.04,1.53]],"ltp":1.57,"tv":58.69,"id":72857117}]}]}
{"op":"mcm","clk":"11888612160","pt":1724239754996,"mc":[{"id":"1.232050243","rc":[{"batb":[[0,1.35,14],[1,1.34,3.91],[2,1.21,83.24]],"ltp":1.57,"tv":58.69,"id":72857117}]}]}
{"op":"mcm","clk":"11888612319","pt":1724239757692,"mc":[{"id":"1.232050243","rc":[{"batb":[[0,1.35,10]],"ltp":1.57,"tv":58.69,"id":72857117}]}]}
{"op":"mcm","clk":"11888612365","pt":1724239758567,"mc":[{"id":"1.232050243","rc":[{"batb":[[0,1.34,3.91],[1,1.21,83.24],[2,1.04,1.53]],"ltp":1.57,"tv":58.69,"id":72857117}]}]}
{"op":"mcm","clk":"11888612555","pt":1724239761975,"mc":[{"id":"1.232050243","rc":[{"batb":[[0,1.35,14],[1,1.34,3.91],[2,1.21,83.24]],"ltp":1.57,"tv":58.69,"id":72857117}]}]}
{"op":"mcm","clk":"11888612743","pt":1724239764677,"mc":[{"id":"1.232050243","rc":[{"batb":[[0,1.35,10]],"ltp":1.57,"tv":58.69,"id":72857117}]}]}
{"op":"mcm","clk":"11888612822","pt":1724239765717,"mc":[{"id":"1.232050243","rc":[{"batb":[[0,1.34,3.91],[1,1.21,83.24],[2,1.04,1.53]],"ltp":1.57,"tv":58.69,"id":72857117}]}]}
{"op":"mcm","clk":"11888613391","pt":1724239774819,"mc":[{"id":"1.232050243","rc":[{"batb":[[0,1.35,14],[1,1.34,3.91],[2,1.21,83.24]],"ltp":1.57,"tv":58.69,"id":72857117}]}]}
{"op":"mcm","clk":"11888613552","pt":1724239777614,"mc":[{"id":"1.232050243","rc":[{"batb":[[0,1.35,10]],"ltp":1.57,"tv":58.69,"id":72857117}]}]}
{"op":"mcm","clk":"11888613634","pt":1724239778496,"mc":[{"id":"1.232050243","rc":[{"batb":[[0,1.34,3.91],[1,1.21,83.24],[2,1.04,1.53]],"ltp":1.57,"tv":58.69,"id":72857117}]}]}
{"op":"mcm","clk":"11888613786","pt":1724239781030,"mc":[{"id":"1.232050243","rc":[{"batb":[[0,1.35,14],[1,1.34,3.91],[2,1.21,83.24]],"ltp":1.57,"tv":58.69,"id":72857117}]}]}
{"op":"mcm","clk":"11888613961","pt":1724239783874,"mc":[{"id":"1.232050243","rc":[{"batb":[[0,1.35,10]],"ltp":1.57,"tv":58.69,"id":72857117}]}]}
{"op":"mcm","clk":"11888614020","pt":1724239784765,"mc":[{"id":"1.232050243","rc":[{"batb":[[0,1.34,3.91],[1,1.21,83.24],[2,1.04,1.53]],"ltp":1.57,"tv":58.69,"id":72857117}]}]}
{"op":"mcm","clk":"11888614396","pt":1724239790688,"mc":[{"id":"1.232050243","rc":[{"batb":[[0,1.35,14],[1,1.34,3.91],[2,1.21,83.24]],"ltp":1.57,"tv":58.69,"id":72857117}]}]}
{"op":"mcm","clk":"11888614561","pt":1724239793286,"mc":[{"id":"1.232050243","rc":[{"batb":[[0,1.35,10]],"ltp":1.57,"tv":58.69,"id":72857117}]}]}
{"op":"mcm","clk":"11888614625","pt":1724239794369,"mc":[{"id":"1.232050243","rc":[{"batb":[[0,1.34,3.91],[1,1.21,83.24],[2,1.04,1.53]],"ltp":1.57,"tv":58.69,"id":72857117}]}]}
{"op":"mcm","clk":"11888614800","pt":1724239797166,"mc":[{"id":"1.232050243","rc":[{"batb":[[0,1.35,14],[1,1.34,3.91],[2,1.21,83.24]],"ltp":1.57,"tv":58.69,"id":72857117}]}]}
{"op":"mcm","clk":"11888615009","pt":1724239799860,"mc":[{"id":"1.232050243","rc":[{"batb":[[0,1.35,10]],"ltp":1.57,"tv":58.69,"id":72857117}]}]}
{"op":"mcm","clk":"11888615093","pt":1724239800761,"mc":[{"id":"1.232050243","rc":[{"batb":[[0,1.34,3.91],[1,1.21,83.24],[2,1.04,1.53]],"ltp":1.57,"tv":58.69,"id":72857117}]}]}
{"op":"mcm","clk":"11888615350","pt":1724239803583,"mc":[{"id":"1.232050243","rc":[{"batb":[[0,1.35,14],[1,1.34,3.91],[2,1.21,83.24]],"ltp":1.57,"tv":58.69,"id":72857117}]}]}
{"op":"mcm","clk":"11888615615","pt":1724239806389,"mc":[{"id":"1.232050243","rc":[{"batb":[[0,1.35,10]],"ltp":1.57,"tv":58.69,"id":72857117}]}]}
{"op":"mcm","clk":"11888615722","pt":1724239807389,"mc":[{"id":"1.232050243","rc":[{"batb":[[0,1.34,3.91],[1,1.21,83.24],[2,1.04,1.53]],"ltp":1.57,"tv":58.69,"id":72857117}]}]}
{"op":"mcm","clk":"11888616078","pt":1724239811407,"mc":[{"id":"1.232050243","rc":[{"batb":[[0,1.35,14],[1,1.34,3.91],[2,1.21,83.24]],"ltp":1.57,"tv":58.69,"id":72857117}]}]}
{"op":"mcm","clk":"11888616306","pt":1724239814500,"mc":[{"id":"1.232050243","rc":[{"batb":[[0,1.35,10]],"ltp":1.57,"tv":58.69,"id":72857117}]}]}
{"op":"mcm","clk":"11888616382","pt":1724239815487,"mc":[{"id":"1.232050243","rc":[{"batb":[[0,1.34,3.91],[1,1.21,83.24],[2,1.04,1.53]],"ltp":1.57,"tv":58.69,"id":72857117}]}]}
{"op":"mcm","clk":"11888616498","pt":1724239816772,"mc":[{"id":"1.232050243","rc":[{"batb":[[0,1.35,4],[1,1.34,3.91],[2,1.21,83.24]],"ltp":1.57,"tv":58.69,"id":72857117}]}]}
{"op":"mcm","clk":"11888616601","pt":1724239818090,"mc":[{"id":"1.232050243","rc":[{"batb":[[0,1.36,10],[1,1.35,4],[2,1.34,3.91]],"ltp":1.57,"tv":58.69,"id":72857117}]}]}
{"op":"mcm","clk":"11888616675","pt":1724239819385,"mc":[{"id":"1.232050243","rc":[{"batb":[[1,1.34,3.91],[2,1.21,83.24]],"ltp":1.57,"tv":58.69,"id":72857117}]}]}
{"op":"mcm","clk":"11888616847","pt":1724239821711,"mc":[{"id":"1.232050243","rc":[{"batb":[[0,1.35,4]],"ltp":1.57,"tv":58.69,"id":72857117}]}]}
{"op":"mcm","clk":"11888617026","pt":1724239824116,"mc":[{"id":"1.232050243","rc":[{"batb":[[0,1.34,3.91],[1,1.21,83.24],[2,1.04,1.53]],"ltp":1.57,"tv":58.69,"id":72857117}]}]}
{"op":"mcm","clk":"11888617031","pt":1724239824220,"mc":[{"id":"1.232050243","rc":[{"batb":[[0,1.35,10],[1,1.34,3.91],[2,1.21,83.24]],"ltp":1.57,"tv":58.69,"id":72857117}]}]}
{"op":"mcm","clk":"11888617285","pt":1724239827935,"mc":[{"id":"1.232050243","rc":[{"batb":[[0,1.35,4]],"ltp":1.57,"tv":58.69,"id":72857117}]}]}
{"op":"mcm","clk":"11888617468","pt":1724239830688,"mc":[{"id":"1.232050243","rc":[{"batb":[[0,1.35,10]],"ltp":1.57,"tv":58.69,"id":72857117}]}]}
{"op":"mcm","clk":"11888617742","pt":1724239834629,"mc":[{"id":"1.232050243","rc":[{"batb":[[0,1.35,4]],"ltp":1.57,"tv":58.69,"id":72857117}]}]}
{"op":"mcm","clk":"11888617924","pt":1724239836931,"mc":[{"id":"1.232050243","rc":[{"batb":[[0,1.34,3.91],[1,1.21,83.24],[2,1.04,1.53]],"ltp":1.57,"tv":58.69,"id":72857117}]}]}
{"op":"mcm","clk":"11888617952","pt":1724239837332,"mc":[{"id":"1.232050243","rc":[{"batb":[[0,1.35,10],[1,1.34,3.91],[2,1.21,83.24]],"ltp":1.57,"tv":58.69,"id":72857117}]}]}
{"op":"mcm","clk":"11888618164","pt":1724239840812,"mc":[{"id":"1.232050243","rc":[{"batb":[[0,1.36,4]],"ltp":1.57,"tv":58.69,"id":72857117}]}]}
{"op":"mcm","clk":"11888618378","pt":1724239843799,"mc":[{"id":"1.232050243","rc":[{"batb":[[0,1.35,10]],"ltp":1.57,"tv":58.69,"id":72857117}]}]}
{"op":"mcm","clk":"11888618639","pt":1724239847623,"mc":[{"id":"1.232050243","rc":[{"batb":[[0,1.35,4]],"ltp":1.57,"tv":58.69,"id":72857117}]}]}
{"op":"mcm","clk":"11888618794","pt":1724239850052,"mc":[{"id":"1.232050243","rc":[{"batb":[[0,1.34,3.91],[1,1.21,83.24],[2,1.04,1.53]],"ltp":1.57,"tv":58.69,"id":72857117}]}]}
{"op":"mcm","clk":"11888618805","pt":1724239850211,"mc":[{"id":"1.232050243","rc":[{"batb":[[0,1.35,10],[1,1.34,3.91],[2,1.21,83.24]],"ltp":1.57,"tv":58.69,"id":72857117}]}]}
{"op":"mcm","clk":"11888619047","pt":1724239854057,"mc":[{"id":"1.232050243","rc":[{"batb":[[0,1.35,4]],"ltp":1.57,"tv":58.69,"id":72857117}]}]}
{"op":"mcm","clk":"11888619249","pt":1724239856652,"mc":[{"id":"1.232050243","rc":[{"batb":[[0,1.35,10]],"ltp":1.57,"tv":58.69,"id":72857117}]}]}
{"op":"mcm","clk":"11888619472","pt":1724239860154,"mc":[{"id":"1.232050243","rc":[{"batb":[[0,1.34,3.91],[1,1.21,83.24],[2,1.04,1.53]],"ltp":1.57,"tv":58.69,"id":72857117}]}]}
{"op":"mcm","clk":"11888619488","pt":1724239860364,"mc":[{"id":"1.232050243","rc":[{"batb":[[0,1.35,4],[1,1.34,3.91],[2,1.21,83.24]],"ltp":1.57,"tv":58.69,"id":72857117}]}]}
{"op":"mcm","clk":"11888619714","pt":1724239863047,"mc":[{"id":"1.232050243","rc":[{"batb":[[0,1.35,10]],"ltp":1.57,"tv":58.69,"id":72857117}]}]}
{"op":"mcm","clk":"11888619973","pt":1724239866566,"mc":[{"id":"1.232050243","rc":[{"batb":[[0,1.35,4]],"ltp":1.57,"tv":58.69,"id":72857117}]}]}
{"op":"mcm","clk":"11888620158","pt":1724239869057,"mc":[{"id":"1.232050243","rc":[{"batb":[[0,1.34,3.91],[1,1.21,83.24],[2,1.04,1.53]],"ltp":1.57,"tv":58.69,"id":72857117}]}]}
{"op":"mcm","clk":"11888620196","pt":1724239869572,"mc":[{"id":"1.232050243","rc":[{"batb":[[0,1.35,10],[1,1.34,3.91],[2,1.21,83.24]],"ltp":1.57,"tv":58.69,"id":72857117}]}]}
{"op":"mcm","clk":"11888620439","pt":1724239872991,"mc":[{"id":"1.232050243","rc":[{"batb":[[0,1.34,3.91],[1,1.21,83.24],[2,1.04,1.53]],"ltp":1.57,"tv":58.69,"id":72857117}]}]}
{"op":"mcm","clk":"11888620468","pt":1724239873250,"mc":[{"id":"1.232050243","rc":[{"batb":[[0,1.35,4],[1,1.34,3.91],[2,1.21,83.24]],"ltp":1.57,"tv":58.69,"id":72857117}]}]}
{"op":"mcm","clk":"11888620689","pt":1724239875882,"mc":[{"id":"1.232050243","rc":[{"batb":[[0,1.35,10]],"ltp":1.57,"tv":58.69,"id":72857117}]}]}
{"op":"mcm","clk":"11888620969","pt":1724239879465,"mc":[{"id":"1.232050243","rc":[{"batb":[[0,1.35,4]],"ltp":1.57,"tv":58.69,"id":72857117}]}]}
{"op":"mcm","clk":"11888621149","pt":1724239881901,"mc":[{"id":"1.232050243","rc":[{"batb":[[0,1.36,10]],"ltp":1.57,"tv":58.69,"id":72857117}]}]}
{"op":"mcm","clk":"11888621439","pt":1724239885382,"mc":[{"id":"1.232050243","rc":[{"batb":[[0,1.35,4]],"ltp":1.57,"tv":58.69,"id":72857117}]}]}
{"op":"mcm","clk":"11888621651","pt":1724239888184,"mc":[{"id":"1.232050243","rc":[{"batb":[[0,1.36,10]],"ltp":1.57,"tv":58.69,"id":72857117}]}]}
{"op":"mcm","clk":"11888621946","pt":1724239891917,"mc":[{"id":"1.232050243","rc":[{"batb":[[0,1.34,3.91],[1,1.21,83.24],[2,1.04,1.53]],"ltp":1.57,"tv":58.69,"id":72857117}]}]}
{"op":"mcm","clk":"11888622009","pt":1724239892912,"mc":[{"id":"1.232050243","rc":[{"batb":[[0,1.35,4],[1,1.34,3.91],[2,1.21,83.24]],"ltp":1.57,"tv":58.69,"id":72857117}]}]}
{"op":"mcm","clk":"11888622110","pt":1724239894420,"mc":[{"id":"1.232050243","rc":[{"batb":[[0,1.36,10],[1,1.35,4],[2,1.34,3.91]],"ltp":1.57,"tv":58.69,"id":72857117}]}]}
{"op":"mcm","clk":"11888622207","pt":1724239895507,"mc":[{"id":"1.232050243","rc":[{"batb":[[1,1.34,3.91],[2,1.21,83.24]],"ltp":1.57,"tv":58.69,"id":72857117}]}]}
{"op":"mcm","clk":"11888622423","pt":1724239898092,"mc":[{"id":"1.232050243","rc":[{"batb":[[0,1.35,4]],"ltp":1.57,"tv":58.69,"id":72857117}]}]}
{"op":"mcm","clk":"11888622650","pt":1724239900718,"mc":[{"id":"1.232050243","rc":[{"batb":[[0,1.35,10]],"ltp":1.57,"tv":58.69,"id":72857117}]}]}
{"op":"mcm","clk":"11888622935","pt":1724239903889,"mc":[{"id":"1.232050243","rc":[{"batb":[[0,1.36,4],[1,1.35,10],[2,1.34,3.91]],"ltp":1.57,"tv":58.69,"id":72857117}]}]}
{"op":"mcm","clk":"11888622961","pt":1724239904204,"mc":[{"id":"1.232050243","rc":[{"batb":[[1,1.34,3.91],[2,1.21,83.24]],"ltp":1.57,"tv":58.69,"id":72857117}]}]}
{"op":"mcm","clk":"11888623145","pt":1724239906428,"mc":[{"id":"1.232050243","rc":[{"batb":[[0,1.37,10]],"ltp":1.57,"tv":58.69,"id":72857117}]}]}
{"op":"mcm","clk":"11888623413","pt":1724239909905,"mc":[{"id":"1.232050243","rc":[{"batb":[[0,1.35,4]],"ltp":1.57,"tv":58.69,"id":72857117}]}]}
{"op":"mcm","clk":"11888623635","pt":1724239913117,"mc":[{"id":"1.232050243","rc":[{"batb":[[0,1.35,10]],"ltp":1.57,"tv":58.69,"id":72857117}]}]}
{"op":"mcm","clk":"11888623847","pt":1724239915723,"mc":[{"id":"1.232050243","rc":[{"batb":[[0,1.36,4],[1,1.35,10],[2,1.34,3.91]],"ltp":1.57,"tv":58.69,"id":72857117}]}]}
{"op":"mcm","clk":"11888623941","pt":1724239916828,"mc":[{"id":"1.232050243","rc":[{"batb":[[1,1.34,3.91],[2,1.21,83.24]],"ltp":1.57,"tv":58.69,"id":72857117}]}]}
{"op":"mcm","clk":"11888624053","pt":1724239918243,"mc":[{"id":"1.232050243","rc":[{"batb":[[0,1.34,3.91],[1,1.21,83.24],[2,1.04,1.53]],"ltp":1.57,"tv":58.69,"id":72857117}]}]}
{"op":"mcm","clk":"11888624359","pt":1724239922418,"mc":[{"id":"1.232050243","rc":[{"batb":[[0,1.35,14],[1,1.34,3.91],[2,1.21,83.24]],"ltp":1.57,"tv":58.69,"id":72857117}]}]}
{"op":"mcm","clk":"11888624559","pt":1724239925062,"mc":[{"id":"1.232050243","rc":[{"batb":[[0,1.35,10]],"ltp":1.57,"tv":58.69,"id":72857117}]}]}
{"op":"mcm","clk":"11888624630","pt":1724239925925,"mc":[{"id":"1.232050243","rc":[{"batb":[[0,1.34,3.91],[1,1.21,83.24],[2,1.04,1.53]],"ltp":1.57,"tv":58.69,"id":72857117}]}]}
{"op":"mcm","clk":"11888625267","pt":1724239934460,"mc":[{"id":"1.232050243","rc":[{"batb":[[0,1.35,14],[1,1.34,3.91],[2,1.21,83.24]],"ltp":1.57,"tv":58.69,"id":72857117}]}]}
{"op":"mcm","clk":"11888625455","pt":1724239937056,"mc":[{"id":"1.232050243","rc":[{"batb":[[0,1.35,10]],"ltp":1.57,"tv":58.69,"id":72857117}]}]}
{"op":"mcm","clk":"11888625533","pt":1724239938041,"mc":[{"id":"1.232050243","rc":[{"batb":[[0,1.34,3.91],[1,1.21,83.24],[2,1.04,1.53]],"ltp":1.57,"tv":58.69,"id":72857117}]}]}
{"op":"mcm","clk":"11888625977","pt":1724239944473,"mc":[{"id":"1.232050243","rc":[{"batb":[[0,1.35,14],[1,1.34,3.91],[2,1.21,83.24]],"ltp":1.57,"tv":58.69,"id":72857117}]}]}
{"op":"mcm","clk":"11888626138","pt":1724239946861,"mc":[{"id":"1.232050243","rc":[{"batb":[[0,1.35,10]],"ltp":1.57,"tv":58.69,"id":72857117}]}]}
{"op":"mcm","clk":"11888626222","pt":1724239947862,"mc":[{"id":"1.232050243","rc":[{"batb":[[0,1.34,3.91],[1,1.21,83.24],[2,1.04,1.53]],"ltp":1.57,"tv":58.69,"id":72857117}]}]}
{"op":"mcm","clk":"11888626527","pt":1724239951873,"mc":[{"id":"1.232050243","rc":[{"batb":[[0,1.35,14],[1,1.34,3.91],[2,1.21,83.24]],"ltp":1.57,"tv":58.69,"id":72857117}]}]}
{"op":"mcm","clk":"11888626771","pt":1724239955174,"mc":[{"id":"1.232050243","rc":[{"batb":[[0,1.34,3.91],[1,1.21,83.24],[2,1.04,1.53]],"ltp":1.57,"tv":58.69,"id":72857117}]}]}
{"op":"mcm","clk":"11888626858","pt":1724239956478,"mc":[{"id":"1.232050243","rc":[{"batb":[[0,1.35,4],[1,1.34,3.91],[2,1.21,83.24]],"ltp":1.57,"tv":58.69,"id":72857117}]}]}
{"op":"mcm","clk":"11888627027","pt":1724239959004,"mc":[{"id":"1.232050243","rc":[{"batb":[[0,1.35,10]],"ltp":1.57,"tv":58.69,"id":72857117}]}]}
{"op":"mcm","clk":"11888627348","pt":1724239962677,"mc":[{"id":"1.232050243","rc":[{"batb":[[0,1.35,4]],"ltp":1.57,"tv":58.69,"id":72857117}]}]}
{"op":"mcm","clk":"11888627550","pt":1724239965058,"mc":[{"id":"1.232050243","rc":[{"batb":[[0,1.34,3.91],[1,1.21,83.24],[2,1.04,1.53]],"ltp":1.57,"tv":58.69,"id":72857117}]}]}
{"op":"mcm","clk":"11888627565","pt":1724239965270,"mc":[{"id":"1.232050243","rc":[{"batb":[[0,1.35,10],[1,1.34,3.91],[2,1.21,83.24]],"ltp":1.57,"tv":58.69,"id":72857117}]}]}
{"op":"mcm","clk":"11888627833","pt":1724239968780,"mc":[{"id":"1.232050243","rc":[{"batb":[[0,1.35,4]],"ltp":1.57,"tv":58.69,"id":72857117}]}]}
{"op":"mcm","clk":"11888628000","pt":1724239971469,"mc":[{"id":"1.232050243","rc":[{"batb":[[0,1.35,10]],"ltp":1.57,"tv":58.69,"id":72857117}]}]}
{"op":"mcm","clk":"11888628136","pt":1724239973685,"mc":[{"id":"1.232050243","rc":[{"batb":[[0,1.36,4],[1,1.35,10],[2,1.34,3.91]],"ltp":1.57,"tv":58.69,"id":72857117}]}]}
{"op":"mcm","clk":"11888628211","pt":1724239974669,"mc":[{"id":"1.232050243","rc":[{"batb":[[1,1.34,3.91],[2,1.21,83.24]],"ltp":1.57,"tv":58.69,"id":72857117}]}]}
{"op":"mcm","clk":"11888628297","pt":1724239976058,"mc":[{"id":"1.232050243","rc":[{"batb":[[0,1.34,3.91],[1,1.21,83.24],[2,1.04,1.53]],"ltp":1.57,"tv":58.69,"id":72857117}]}]}
{"op":"mcm","clk":"11888628683","pt":1724239982087,"mc":[{"id":"1.232050243","rc":[{"batb":[[0,1.35,14],[1,1.34,3.91],[2,1.21,83.24]],"ltp":1.57,"tv":58.69,"id":72857117}]}]}
{"op":"mcm","clk":"11888628901","pt":1724239984984,"mc":[{"id":"1.232050243","rc":[{"batb":[[0,1.35,10]],"ltp":1.57,"tv":58.69,"id":72857117}]}]}
{"op":"mcm","clk":"11888628950","pt":1724239985663,"mc":[{"id":"1.232050243","rc":[{"batb":[[0,1.34,3.91],[1,1.21,83.24],[2,1.04,1.53]],"ltp":1.57,"tv":58.69,"id":72857117}]}]}
{"op":"mcm","clk":"11888629372","pt":1724239992105,"mc":[{"id":"1.232050243","rc":[{"batb":[[0,1.35,14],[1,1.34,3.91],[2,1.21,83.24]],"ltp":1.57,"tv":58.69,"id":72857117}]}]}
{"op":"mcm","clk":"11888629553","pt":1724239994578,"mc":[{"id":"1.232050243","rc":[{"batb":[[0,1.35,10]],"ltp":1.57,"tv":58.69,"id":72857117}]}]}
{"op":"mcm","clk":"11888629631","pt":1724239995715,"mc":[{"id":"1.232050243","rc":[{"batb":[[0,1.34,3.91],[1,1.21,83.24],[2,1.04,1.53]],"ltp":1.57,"tv":58.69,"id":72857117}]}]}
{"op":"mcm","clk":"11888629853","pt":1724239999192,"mc":[{"id":"1.232050243","rc":[{"batb":[[0,1.35,14],[1,1.34,3.91],[2,1.21,83.24]],"ltp":1.57,"tv":58.69,"id":72857117}]}]}
{"op":"mcm","clk":"11888630051","pt":1724240002092,"mc":[{"id":"1.232050243","rc":[{"batb":[[0,1.35,10]],"ltp":1.57,"tv":58.69,"id":72857117}]}]}
{"op":"mcm","clk":"11888630127","pt":1724240003081,"mc":[{"id":"1.232050243","rc":[{"batb":[[0,1.34,3.91],[1,1.21,83.24],[2,1.04,1.53]],"ltp":1.57,"tv":58.69,"id":72857117}]}]}
{"op":"mcm","clk":"11888630234","pt":1724240004525,"mc":[{"id":"1.232050243","rc":[{"batb":[[0,1.35,4],[1,1.34,3.91],[2,1.21,83.24]],"ltp":1.57,"tv":58.69,"id":72857117}]}]}
{"op":"mcm","clk":"11888630391","pt":1724240007008,"mc":[{"id":"1.232050243","rc":[{"batb":[[0,1.34,3.91],[1,1.21,83.24],[2,1.04,1.53]],"ltp":1.57,"tv":58.69,"id":72857117}]}]}
{"op":"mcm","clk":"11888630408","pt":1724240007310,"mc":[{"id":"1.232050243","rc":[{"batb":[[0,1.35,10],[1,1.34,3.91],[2,1.21,83.24]],"ltp":1.57,"tv":58.69,"id":72857117}]}]}
{"op":"mcm","clk":"11888630580","pt":1724240009594,"mc":[{"id":"1.232050243","rc":[{"batb":[[0,1.36,4],[1,1.35,10],[2,1.34,3.91]],"ltp":1.57,"tv":58.69,"id":72857117}]}]}
{"op":"mcm","clk":"11888630659","pt":1724240010678,"mc":[{"id":"1.232050243","rc":[{"batb":[[1,1.34,3.91],[2,1.21,83.24]],"ltp":1.57,"tv":58.69,"id":72857117}]}]}
{"op":"mcm","clk":"11888630768","pt":1724240012297,"mc":[{"id":"1.232050243","rc":[{"batb":[[0,1.34,3.91],[1,1.21,83.24],[2,1.04,1.53]],"ltp":1.57,"tv":58.69,"id":72857117}]}]}
{"op":"mcm","clk":"11888631038","pt":1724240015609,"mc":[{"id":"1.232050243","rc":[{"batb":[[0,1.35,14],[1,1.34,3.91],[2,1.21,83.24]],"ltp":1.57,"tv":58.69,"id":72857117}]}]}
{"op":"mcm","clk":"11888631194","pt":1724240017993,"mc":[{"id":"1.232050243","rc":[{"batb":[[0,1.35,10]],"ltp":1.57,"tv":58.69,"id":72857117}]}]}
{"op":"mcm","clk":"11888631266","pt":1724240019026,"mc":[{"id":"1.232050243","rc":[{"batb":[[0,1.34,3.91],[1,1.21,83.24],[2,1.04,1.53]],"ltp":1.57,"tv":58.69,"id":72857117}]}]}
{"op":"mcm","clk":"11888631835","pt":1724240026829,"mc":[{"id":"1.232050243","rc":[{"batb":[[0,1.35,14],[1,1.34,3.91],[2,1.21,83.24]],"ltp":1.57,"tv":58.69,"id":72857117}]}]}
{"op":"mcm","clk":"11888632022","pt":1724240029629,"mc":[{"id":"1.232050243","rc":[{"batb":[[0,1.35,10]],"ltp":1.57,"tv":58.69,"id":72857117}]}]}
{"op":"mcm","clk":"11888632100","pt":1724240030620,"mc":[{"id":"1.232050243","rc":[{"batb":[[0,1.34,3.91],[1,1.21,83.24],[2,1.04,1.53]],"ltp":1.57,"tv":58.69,"id":72857117}]}]}
{"op":"mcm","clk":"11888633061","pt":1724240042849,"mc":[{"id":"1.232050243","rc":[{"batb":[[0,1.35,14],[1,1.34,3.91],[2,1.21,83.24]],"ltp":1.57,"tv":58.69,"id":72857117}]}]}
{"op":"mcm","clk":"11888633240","pt":1724240045277,"mc":[{"id":"1.232050243","rc":[{"batb":[[0,1.35,10]],"ltp":1.57,"tv":58.69,"id":72857117}]}]}
{"op":"mcm","clk":"11888633303","pt":1724240046316,"mc":[{"id":"1.232050243","rc":[{"batb":[[0,1.34,3.91],[1,1.21,83.24],[2,1.04,1.53]],"ltp":1.57,"tv":58.69,"id":72857117}]}]}
{"op":"mcm","clk":"11888633487","pt":1724240049130,"mc":[{"id":"1.232050243","rc":[{"batb":[[0,1.35,14],[1,1.34,3.91],[2,1.21,83.24]],"ltp":1.57,"tv":58.69,"id":72857117}]}]}
{"op":"mcm","clk":"11888633638","pt":1724240051460,"mc":[{"id":"1.232050243","rc":[{"batb":[[0,1.35,10]],"ltp":1.57,"tv":58.69,"id":72857117}]}]}
{"op":"mcm","clk":"11888633723","pt":1724240052515,"mc":[{"id":"1.232050243","rc":[{"batb":[[0,1.34,3.91],[1,1.21,83.24],[2,1.04,1.53]],"ltp":1.57,"tv":58.69,"id":72857117}]}]}
{"op":"mcm","clk":"11888633955","pt":1724240055826,"mc":[{"id":"1.232050243","rc":[{"batb":[[0,1.35,14],[1,1.34,3.91],[2,1.21,83.24]],"ltp":1.57,"tv":58.69,"id":72857117}]}]}
{"op":"mcm","clk":"11888634136","pt":1724240058722,"mc":[{"id":"1.232050243","rc":[{"batb":[[0,1.35,10]],"ltp":1.57,"tv":58.69,"id":72857117}]}]}
{"op":"mcm","clk":"11888634190","pt":1724240059759,"mc":[{"id":"1.232050243","rc":[{"batb":[[0,1.34,3.91],[1,1.21,83.24],[2,1.04,1.53]],"ltp":1.57,"tv":58.69,"id":72857117}]}]}
{"op":"mcm","clk":"11888634269","pt":1724240061047,"mc":[{"id":"1.232050243","rc":[{"batb":[[0,1.35,4],[1,1.34,3.91],[2,1.21,83.24]],"ltp":1.57,"tv":58.69,"id":72857117}]}]}
{"op":"mcm","clk":"11888634509","pt":1724240064157,"mc":[{"id":"1.232050243","rc":[{"batb":[[0,1.35,10]],"ltp":1.57,"tv":58.69,"id":72857117}]}]}
{"op":"mcm","clk":"11888634676","pt":1724240066776,"mc":[{"id":"1.232050243","rc":[{"batb":[[0,1.36,4],[1,1.35,10],[2,1.34,3.91]],"ltp":1.57,"tv":58.69,"id":72857117}]}]}
{"op":"mcm","clk":"11888634727","pt":1724240067553,"mc":[{"id":"1.232050243","rc":[{"batb":[[1,1.34,3.91],[2,1.21,83.24]],"ltp":1.57,"tv":58.69,"id":72857117}]}]}
{"op":"mcm","clk":"11888634831","pt":1724240069061,"mc":[{"id":"1.232050243","rc":[{"batb":[[0,1.34,3.91],[1,1.21,83.24],[2,1.04,1.53]],"ltp":1.57,"tv":58.69,"id":72857117}]}]}
{"op":"mcm","clk":"11888635612","pt":1724240080096,"mc":[{"id":"1.232050243","rc":[{"batb":[[0,1.35,14],[1,1.34,3.91],[2,1.21,83.24]],"ltp":1.57,"tv":58.69,"id":72857117}]}]}
{"op":"mcm","clk":"11888635805","pt":1724240082684,"mc":[{"id":"1.232050243","rc":[{"batb":[[0,1.35,10]],"ltp":1.57,"tv":58.69,"id":72857117}]}]}
{"op":"mcm","clk":"11888635869","pt":1724240083876,"mc":[{"id":"1.232050243","rc":[{"batb":[[0,1.34,3.91],[1,1.21,83.24],[2,1.04,1.53]],"ltp":1.57,"tv":58.69,"id":72857117}]}]}
{"op":"mcm","clk":"11888636490","pt":1724240092799,"mc":[{"id":"1.232050243","rc":[{"batb":[[0,1.35,14],[1,1.34,3.91],[2,1.21,83.24]],"ltp":1.57,"tv":58.69,"id":72857117}]}]}
{"op":"mcm","clk":"11888636674","pt":1724240095593,"mc":[{"id":"1.232050243","rc":[{"batb":[[0,1.35,10]],"ltp":1.57,"tv":58.69,"id":72857117}]}]}
{"op":"mcm","clk":"11888636741","pt":1724240096589,"mc":[{"id":"1.232050243","rc":[{"batb":[[0,1.34,3.91],[1,1.21,83.24],[2,1.04,1.53]],"ltp":1.57,"tv":58.69,"id":72857117}]}]}
{"op":"mcm","clk":"11888637223","pt":1724240102804,"mc":[{"id":"1.232050243","rc":[{"batb":[[0,1.35,14],[1,1.34,3.91],[2,1.21,83.24]],"ltp":1.57,"tv":58.69,"id":72857117}]}]}
{"op":"mcm","clk":"11888637438","pt":1724240105304,"mc":[{"id":"1.232050243","rc":[{"batb":[[0,1.35,10]],"ltp":1.57,"tv":58.69,"id":72857117}]}]}
{"op":"mcm","clk":"11888637499","pt":1724240106192,"mc":[{"id":"1.232050243","rc":[{"batb":[[0,1.34,3.91],[1,1.21,83.24],[2,1.04,1.53]],"ltp":1.57,"tv":58.69,"id":72857117}]}]}
{"op":"mcm","clk":"11888638840","pt":1724240122934,"mc":[{"id":"1.232050243","rc":[{"batb":[[0,1.35,14],[1,1.34,3.91],[2,1.21,83.24]],"ltp":1.57,"tv":58.69,"id":72857117}]}]}
{"op":"mcm","clk":"11888639054","pt":1724240125638,"mc":[{"id":"1.232050243","rc":[{"batb":[[0,1.35,10]],"ltp":1.57,"tv":58.69,"id":72857117}]}]}
{"op":"mcm","clk":"11888639134","pt":1724240126721,"mc":[{"id":"1.232050243","rc":[{"batb":[[0,1.34,3.91],[1,1.21,83.24],[2,1.04,1.53]],"ltp":1.57,"tv":58.69,"id":72857117}]}]}
{"op":"mcm","clk":"11888641006","pt":1724240149576,"mc":[{"id":"1.232050243","rc":[{"batb":[[0,1.35,14],[1,1.34,3.91],[2,1.21,83.24]],"ltp":1.57,"tv":58.69,"id":72857117}]}]}
{"op":"mcm","clk":"11888641374","pt":1724240154177,"mc":[{"id":"1.232050243","rc":[{"batb":[[0,1.34,3.91],[1,1.21,83.24],[2,1.04,1.53]],"ltp":1.57,"tv":58.69,"id":72857117}]}]}
{"op":"mcm","clk":"11888641940","pt":1724240161361,"mc":[{"id":"1.232050243","rc":[{"batb":[[0,1.35,14],[1,1.34,3.91],[2,1.21,83.24]],"ltp":1.57,"tv":58.69,"id":72857117}]}]}
{"op":"mcm","clk":"11888642117","pt":1724240163893,"mc":[{"id":"1.232050243","rc":[{"batb":[[0,1.35,10]],"ltp":1.57,"tv":58.69,"id":72857117}]}]}
{"op":"mcm","clk":"11888642185","pt":1724240164877,"mc":[{"id":"1.232050243","rc":[{"batb":[[0,1.34,3.91],[1,1.21,83.24],[2,1.04,1.53]],"ltp":1.57,"tv":58.69,"id":72857117}]}]}
{"op":"mcm","clk":"11888643983","pt":1724240185514,"mc":[{"id":"1.232050243","rc":[{"batb":[[0,1.35,14],[1,1.34,3.91],[2,1.21,83.24]],"ltp":1.57,"tv":58.69,"id":72857117}]}]}
{"op":"mcm","clk":"11888644189","pt":1724240188096,"mc":[{"id":"1.232050243","rc":[{"batb":[[0,1.35,10]],"ltp":1.57,"tv":58.69,"id":72857117}]}]}
{"op":"mcm","clk":"11888644241","pt":1724240188717,"mc":[{"id":"1.232050243","rc":[{"batb":[[0,1.34,3.91],[1,1.21,83.24],[2,1.04,1.53]],"ltp":1.57,"tv":58.69,"id":72857117}]}]}
{"op":"mcm","clk":"11888644752","pt":1724240194841,"mc":[{"id":"1.232050243","rc":[{"batb":[[0,1.35,14],[1,1.34,3.91],[2,1.21,83.24]],"ltp":1.57,"tv":58.69,"id":72857117}]}]}
{"op":"mcm","clk":"11888645055","pt":1724240198114,"mc":[{"id":"1.232050243","rc":[{"batb":[[0,1.34,3.91],[1,1.21,83.24],[2,1.04,1.53]],"ltp":1.57,"tv":58.69,"id":72857117}]}]}
{"op":"mcm","clk":"11888645925","pt":1724240207146,"mc":[{"id":"1.232050243","rc":[{"batb":[[0,1.35,14],[1,1.34,3.91],[2,1.21,83.24]],"ltp":1.57,"tv":58.69,"id":72857117}]}]}
{"op":"mcm","clk":"11888646624","pt":1724240215368,"mc":[{"id":"1.232050243","rc":[{"batb":[[0,1.35,10]],"ltp":1.57,"tv":58.69,"id":72857117}]}]}
{"op":"mcm","clk":"11888646699","pt":1724240216243,"mc":[{"id":"1.232050243","rc":[{"batb":[[0,1.34,3.91],[1,1.21,83.24],[2,1.04,1.53]],"ltp":1.57,"tv":58.69,"id":72857117}]}]}
{"op":"mcm","clk":"11888646925","pt":1724240218931,"mc":[{"id":"1.232050243","rc":[{"batb":[[0,1.36,4],[1,1.35,10],[2,1.34,3.91]],"ltp":1.57,"tv":58.69,"id":72857117}]}]}
{"op":"mcm","clk":"11888647289","pt":1724240222967,"mc":[{"id":"1.232050243","rc":[{"batb":[[0,1.35,10],[1,1.34,3.91],[2,1.21,83.24]],"ltp":1.57,"tv":58.69,"id":72857117}]}]}
{"op":"mcm","clk":"11888647459","pt":1724240225174,"mc":[{"id":"1.232050243","rc":[{"batb":[[0,1.36,4]],"ltp":1.57,"tv":58.69,"id":72857117}]}]}
{"op":"mcm","clk":"11888647604","pt":1724240226574,"mc":[{"id":"1.232050243","rc":[{"batb":[[0,1.37,10],[1,1.36,4],[2,1.34,3.91]],"ltp":1.57,"tv":58.69,"id":72857117}]}]}
{"op":"mcm","clk":"11888647795","pt":1724240228556,"mc":[{"id":"1.232050243","rc":[{"batb":[[1,1.34,3.91],[2,1.21,83.24]],"ltp":1.57,"tv":58.69,"id":72857117}]}]}
{"op":"mcm","clk":"11888648059","pt":1724240231069,"mc":[{"id":"1.232050243","rc":[{"batb":[[0,1.35,4]],"ltp":1.57,"tv":58.69,"id":72857117}]}]}
{"op":"mcm","clk":"11888648306","pt":1724240233681,"mc":[{"id":"1.232050243","rc":[{"batb":[[0,1.35,10]],"ltp":1.57,"tv":58.69,"id":72857117}]}]}
{"op":"mcm","clk":"11888648612","pt":1724240237055,"mc":[{"id":"1.232050243","rc":[{"batb":[[0,1.34,3.91],[1,1.21,83.24],[2,1.04,1.53]],"ltp":1.57,"tv":58.69,"id":72857117}]}]}
{"op":"mcm","clk":"11888648656","pt":1724240237468,"mc":[{"id":"1.232050243","rc":[{"batb":[[0,1.35,4],[1,1.34,3.91],[2,1.21,83.24]],"ltp":1.57,"tv":58.69,"id":72857117}]}]}
{"op":"mcm","clk":"11888648840","pt":1724240239901,"mc":[{"id":"1.232050243","rc":[{"batb":[[0,1.36,10]],"ltp":1.57,"tv":58.69,"id":72857117}]}]}
{"op":"mcm","clk":"11888649124","pt":1724240243489,"mc":[{"id":"1.232050243","rc":[{"batb":[[0,1.35,4]],"ltp":1.57,"tv":58.69,"id":72857117}]}]}
{"op":"mcm","clk":"11888649339","pt":1724240246064,"mc":[{"id":"1.232050243","rc":[{"batb":[[0,1.35,10]],"ltp":1.57,"tv":58.69,"id":72857117}]}]}
{"op":"mcm","clk":"11888649648","pt":1724240249594,"mc":[{"id":"1.232050243","rc":[{"batb":[[0,1.35,4]],"ltp":1.57,"tv":58.69,"id":72857117}]}]}
{"op":"mcm","clk":"11888649872","pt":1724240252069,"mc":[{"id":"1.232050243","rc":[{"batb":[[0,1.34,3.91],[1,1.21,83.24],[2,1.04,1.53]],"ltp":1.57,"tv":58.69,"id":72857117}]}]}
{"op":"mcm","clk":"11888649916","pt":1724240252490,"mc":[{"id":"1.232050243","rc":[{"batb":[[0,1.35,10],[1,1.34,3.91],[2,1.21,83.24]],"ltp":1.57,"tv":58.69,"id":72857117}]}]}
{"op":"mcm","clk":"11888650232","pt":1724240256104,"mc":[{"id":"1.232050243","rc":[{"batb":[[0,1.35,4]],"ltp":1.57,"tv":58.69,"id":72857117}]}]}
{"op":"mcm","clk":"11888650447","pt":1724240258802,"mc":[{"id":"1.232050243","rc":[{"batb":[[0,1.35,10]],"ltp":1.57,"tv":58.69,"id":72857117}]}]}
{"op":"mcm","clk":"11888650711","pt":1724240261897,"mc":[{"id":"1.232050243","rc":[{"batb":[[0,1.36,4],[1,1.35,10],[2,1.34,3.91]],"ltp":1.57,"tv":58.69,"id":72857117}]}]}
{"op":"mcm","clk":"11888650742","pt":1724240262213,"mc":[{"id":"1.232050243","rc":[{"batb":[[1,1.34,3.91],[2,1.21,83.24]],"ltp":1.57,"tv":58.69,"id":72857117}]}]}
{"op":"mcm","clk":"11888650962","pt":1724240264589,"mc":[{"id":"1.232050243","rc":[{"batb":[[0,1.35,10]],"ltp":1.57,"tv":58.69,"id":72857117}]}]}
{"op":"mcm","clk":"11888651269","pt":1724240267912,"mc":[{"id":"1.232050243","rc":[{"batb":[[0,1.36,4]],"ltp":1.57,"tv":58.69,"id":72857117}]}]}
{"op":"mcm","clk":"11888651421","pt":1724240269732,"mc":[{"id":"1.232050243","rc":[{"batb":[[0,1.34,3.91],[1,1.21,83.24],[2,1.04,1.53]],"ltp":1.57,"tv":58.69,"id":72857117}]}]}
{"op":"mcm","clk":"11888651550","pt":1724240271286,"mc":[{"id":"1.232050243","rc":[{"batb":[[0,1.35,10],[1,1.34,3.91],[2,1.21,83.24]],"ltp":1.57,"tv":58.69,"id":72857117}]}]}
{"op":"mcm","clk":"11888651654","pt":1724240272530,"mc":[{"id":"1.232050243","rc":[{"batb":[[0,1.36,4],[1,1.35,10],[2,1.34,3.91]],"ltp":1.57,"tv":58.69,"id":72857117}]}]}
{"op":"mcm","clk":"11888651874","pt":1724240275007,"mc":[{"id":"1.232050243","rc":[{"batb":[[0,1.34,3.91],[1,1.21,83.24],[2,1.04,1.53]],"ltp":1.57,"tv":58.69,"id":72857117}]}]}
{"op":"mcm","clk":"11888652337","pt":1724240279930,"mc":[{"id":"1.232050243","rc":[{"batb":[[0,1.35,14],[1,1.34,3.91],[2,1.21,83.24]],"ltp":1.57,"tv":58.69,"id":72857117}]}]}
{"op":"mcm","clk":"11888652621","pt":1724240282635,"mc":[{"id":"1.232050243","rc":[{"batb":[[0,1.35,10]],"ltp":1.57,"tv":58.69,"id":72857117}]}]}
{"op":"mcm","clk":"11888652713","pt":1724240283634,"mc":[{"id":"1.232050243","rc":[{"batb":[[0,1.34,3.91],[1,1.21,83.24],[2,1.04,1.53]],"ltp":1.57,"tv":58.69,"id":72857117}]}]}
{"op":"mcm","clk":"11888652944","pt":1724240286108,"mc":[{"id":"1.232050243","rc":[{"batb":[[0,1.35,10],[1,1.34,3.91],[2,1.21,83.24]],"ltp":1.57,"tv":58.69,"id":72857117}]}]}
{"op":"mcm","clk":"11888652956","pt":1724240286210,"mc":[{"id":"1.232050243","rc":[{"batb":[[0,1.35,14]],"ltp":1.57,"tv":58.69,"id":72857117}]}]}
{"op":"mcm","clk":"11888653191","pt":1724240288815,"mc":[{"id":"1.232050243","rc":[{"batb":[[0,1.35,10]],"ltp":1.57,"tv":58.69,"id":72857117}]}]}
{"op":"mcm","clk":"11888653242","pt":1724240289437,"mc":[{"id":"1.232050243","rc":[{"batb":[[0,1.34,3.91],[1,1.21,83.24],[2,1.04,1.53]],"ltp":1.57,"tv":58.69,"id":72857117}]}]}
{"op":"mcm","clk":"11888653643","pt":1724240293544,"mc":[{"id":"1.232050243","rc":[{"batb":[[0,1.35,14],[1,1.34,3.91],[2,1.21,83.24]],"ltp":1.57,"tv":58.69,"id":72857117}]}]}
{"op":"mcm","clk":"11888653859","pt":1724240295831,"mc":[{"id":"1.232050243","rc":[{"batb":[[0,1.35,10]],"ltp":1.57,"tv":58.69,"id":72857117}]}]}
{"op":"mcm","clk":"11888653973","pt":1724240296965,"mc":[{"id":"1.232050243","rc":[{"batb":[[0,1.34,3.91],[1,1.21,83.24],[2,1.04,1.53]],"ltp":1.57,"tv":58.69,"id":72857117}]}]}
{"op":"mcm","clk":"11888654218","pt":1724240300129,"mc":[{"id":"1.232050243","rc":[{"batb":[[0,1.35,14],[1,1.34,3.91],[2,1.21,83.24]],"ltp":1.57,"tv":58.69,"id":72857117}]}]}
{"op":"mcm","clk":"11888654435","pt":1724240302567,"mc":[{"id":"1.232050243","rc":[{"batb":[[0,1.35,10]],"ltp":1.57,"tv":58.69,"id":72857117}]}]}
{"op":"mcm","clk":"11888654531","pt":1724240303659,"mc":[{"id":"1.232050243","rc":[{"batb":[[0,1.34,3.91],[1,1.21,83.24],[2,1.04,1.53]],"ltp":1.57,"tv":58.69,"id":72857117}]}]}
{"op":"mcm","clk":"11888654749","pt":1724240306344,"mc":[{"id":"1.232050243","rc":[{"batb":[[0,1.35,14],[1,1.34,3.91],[2,1.21,83.24]],"ltp":1.57,"tv":58.69,"id":72857117}]}]}
{"op":"mcm","clk":"11888654993","pt":1724240309139,"mc":[{"id":"1.232050243","rc":[{"batb":[[0,1.35,10]],"ltp":1.57,"tv":58.69,"id":72857117}]}]}
{"op":"mcm","clk":"11888655092","pt":1724240310182,"mc":[{"id":"1.232050243","rc":[{"batb":[[0,1.34,3.91],[1,1.21,83.24],[2,1.04,1.53]],"ltp":1.57,"tv":58.69,"id":72857117}]}]}
{"op":"mcm","clk":"11888655229","pt":1724240311848,"mc":[{"id":"1.232050243","rc":[{"batb":[[0,1.35,4],[1,1.34,3.91],[2,1.21,83.24]],"ltp":1.57,"tv":58.69,"id":72857117}]}]}
{"op":"mcm","clk":"11888655292","pt":1724240312574,"mc":[{"id":"1.232050243","rc":[{"batb":[[0,1.36,10],[1,1.35,4],[2,1.34,3.91]],"ltp":1.57,"tv":58.69,"id":72857117}]}]}
{"op":"mcm","clk":"11888655485","pt":1724240314688,"mc":[{"id":"1.232050243","rc":[{"batb":[[1,1.34,3.91],[2,1.21,83.24]],"ltp":1.57,"tv":58.69,"id":72857117}]}]}
{"op":"mcm","clk":"11888655610","pt":1724240315981,"mc":[{"id":"1.232050243","rc":[{"batb":[[0,1.34,3.91],[1,1.21,83.24],[2,1.04,1.53]],"ltp":1.57,"tv":58.69,"id":72857117}]}]}
{"op":"mcm","clk":"11888655986","pt":1724240319862,"mc":[{"id":"1.232050243","rc":[{"batb":[[0,1.35,14],[1,1.34,3.91],[2,1.21,83.24]],"ltp":1.57,"tv":58.69,"id":72857117}]}]}
{"op":"mcm","clk":"11888656227","pt":1724240322266,"mc":[{"id":"1.232050243","rc":[{"batb":[[0,1.35,10]],"ltp":1.57,"tv":58.69,"id":72857117}]}]}
{"op":"mcm","clk":"11888656342","pt":1724240323384,"mc":[{"id":"1.232050243","rc":[{"batb":[[0,1.34,3.91],[1,1.21,83.24],[2,1.04,1.53]],"ltp":1.57,"tv":58.69,"id":72857117}]}]}
{"op":"mcm","clk":"11888656717","pt":1724240327062,"mc":[{"id":"1.232050243","rc":[{"batb":[[0,1.35,14],[1,1.34,3.91],[2,1.21,83.24]],"ltp":1.57,"tv":58.69,"id":72857117}]}]}
{"op":"mcm","clk":"11888656960","pt":1724240329495,"mc":[{"id":"1.232050243","rc":[{"batb":[[0,1.35,10]],"ltp":1.57,"tv":58.69,"id":72857117}]}]}
{"op":"mcm","clk":"11888657058","pt":1724240330574,"mc":[{"id":"1.232050243","rc":[{"batb":[[0,1.34,3.91],[1,1.21,83.24],[2,1.04,1.53]],"ltp":1.57,"tv":58.69,"id":72857117}]}]}
{"op":"mcm","clk":"11888657321","pt":1724240333373,"mc":[{"id":"1.232050243","rc":[{"batb":[[0,1.35,14],[1,1.34,3.91],[2,1.21,83.24]],"ltp":1.57,"tv":58.69,"id":72857117}]}]}
{"op":"mcm","clk":"11888657518","pt":1724240335687,"mc":[{"id":"1.232050243","rc":[{"batb":[[0,1.35,10]],"ltp":1.57,"tv":58.69,"id":72857117}]}]}
{"op":"mcm","clk":"11888657611","pt":1724240336874,"mc":[{"id":"1.232050243","rc":[{"batb":[[0,1.34,3.91],[1,1.21,83.24],[2,1.04,1.53]],"ltp":1.57,"tv":58.69,"id":72857117}]}]}
{"op":"mcm","clk":"11888658205","pt":1724240342786,"mc":[{"id":"1.232050243","rc":[{"batb":[[0,1.35,14],[1,1.34,3.91],[2,1.21,83.24]],"ltp":1.57,"tv":58.69,"id":72857117}]}]}
{"op":"mcm","clk":"11888658465","pt":1724240345479,"mc":[{"id":"1.232050243","rc":[{"batb":[[0,1.35,10]],"ltp":1.57,"tv":58.69,"id":72857117}]}]}
{"op":"mcm","clk":"11888658567","pt":1724240346513,"mc":[{"id":"1.232050243","rc":[{"batb":[[0,1.34,3.91],[1,1.21,83.24],[2,1.04,1.53]],"ltp":1.57,"tv":58.69,"id":72857117}]}]}
{"op":"mcm","clk":"11888658832","pt":1724240349118,"mc":[{"id":"1.232050243","rc":[{"batb":[[0,1.35,14],[1,1.34,3.91],[2,1.21,83.24]],"ltp":1.57,"tv":58.69,"id":72857117}]}]}
{"op":"mcm","clk":"11888659055","pt":1724240351412,"mc":[{"id":"1.232050243","rc":[{"batb":[[0,1.35,10]],"ltp":1.57,"tv":58.69,"id":72857117}]}]}
{"op":"mcm","clk":"11888659131","pt":1724240352289,"mc":[{"id":"1.232050243","rc":[{"batb":[[0,1.34,3.91],[1,1.21,83.24],[2,1.04,1.53]],"ltp":1.57,"tv":58.69,"id":72857117}]}]}
{"op":"mcm","clk":"11888659441","pt":1724240355403,"mc":[{"id":"1.232050243","rc":[{"batb":[[0,1.35,14],[1,1.34,3.91],[2,1.21,83.24]],"ltp":1.57,"tv":58.69,"id":72857117}]}]}
{"op":"mcm","clk":"11888659680","pt":1724240357941,"mc":[{"id":"1.232050243","rc":[{"batb":[[0,1.35,10]],"ltp":1.57,"tv":58.69,"id":72857117}]}]}
{"op":"mcm","clk":"11888659760","pt":1724240358819,"mc":[{"id":"1.232050243","rc":[{"batb":[[0,1.34,3.91],[1,1.21,83.24],[2,1.04,1.53]],"ltp":1.57,"tv":58.69,"id":72857117}]}]}
{"op":"mcm","clk":"11888659914","pt":1724240360333,"mc":[{"id":"1.232050243","rc":[{"batb":[[0,1.35,4],[1,1.34,3.91],[2,1.21,83.24]],"ltp":1.57,"tv":58.69,"id":72857117}]}]}
{"op":"mcm","clk":"11888660188","pt":1724240363127,"mc":[{"id":"1.232050243","rc":[{"batb":[[0,1.35,10]],"ltp":1.57,"tv":58.69,"id":72857117}]}]}
{"op":"mcm","clk":"11888660495","pt":1724240366735,"mc":[{"id":"1.232050243","rc":[{"batb":[[0,1.35,4]],"ltp":1.57,"tv":58.69,"id":72857117}]}]}
{"op":"mcm","clk":"11888660705","pt":1724240369112,"mc":[{"id":"1.232050243","rc":[{"batb":[[0,1.34,3.91],[1,1.21,83.24],[2,1.04,1.53]],"ltp":1.57,"tv":58.69,"id":72857117}]}]}
{"op":"mcm","clk":"11888660738","pt":1724240369423,"mc":[{"id":"1.232050243","rc":[{"batb":[[0,1.35,10],[1,1.34,3.91],[2,1.21,83.24]],"ltp":1.57,"tv":58.69,"id":72857117}]}]}
{"op":"mcm","clk":"11888661066","pt":1724240373045,"mc":[{"id":"1.232050243","rc":[{"batb":[[0,1.35,4]],"ltp":1.57,"tv":58.69,"id":72857117}]}]}
{"op":"mcm","clk":"11888661315","pt":1724240375741,"mc":[{"id":"1.232050243","rc":[{"batb":[[0,1.35,10]],"ltp":1.57,"tv":58.69,"id":72857117}]}]}
{"op":"mcm","clk":"11888661572","pt":1724240378134,"mc":[{"id":"1.232050243","rc":[{"batb":[[0,1.36,4],[1,1.35,10],[2,1.34,3.91]],"ltp":1.57,"tv":58.69,"id":72857117}]}]}
{"op":"mcm","clk":"11888661667","pt":1724240379264,"mc":[{"id":"1.232050243","rc":[{"batb":[[1,1.34,3.91],[2,1.21,83.24]],"ltp":1.57,"tv":58.69,"id":72857117}]}]}
{"op":"mcm","clk":"11888661831","pt":1724240380949,"mc":[{"id":"1.232050243","rc":[{"batb":[[0,1.34,3.91],[1,1.21,83.24],[2,1.04,1.53]],"ltp":1.57,"tv":58.69,"id":72857117}]}]}
{"op":"mcm","clk":"11888661867","pt":1724240381459,"mc":[{"id":"1.232050243","rc":[{"batb":[[0,1.35,10],[1,1.34,3.91],[2,1.21,83.24]],"ltp":1.57,"tv":58.69,"id":72857117}]}]}
{"op":"mcm","clk":"11888662195","pt":1724240384872,"mc":[{"id":"1.232050243","rc":[{"batb":[[0,1.35,4]],"ltp":1.57,"tv":58.69,"id":72857117}]}]}
{"op":"mcm","clk":"11888662373","pt":1724240387048,"mc":[{"id":"1.232050243","rc":[{"batb":[[0,1.34,3.91],[1,1.21,83.24],[2,1.04,1.53]],"ltp":1.57,"tv":58.69,"id":72857117}]}]}
{"op":"mcm","clk":"11888662393","pt":1724240387261,"mc":[{"id":"1.232050243","rc":[{"batb":[[0,1.35,10],[1,1.34,3.91],[2,1.21,83.24]],"ltp":1.57,"tv":58.69,"id":72857117}]}]}
{"op":"mcm","clk":"11888662742","pt":1724240391076,"mc":[{"id":"1.232050243","rc":[{"batb":[[0,1.35,4]],"ltp":1.57,"tv":58.69,"id":72857117}]}]}
{"op":"mcm","clk":"11888663003","pt":1724240393884,"mc":[{"id":"1.232050243","rc":[{"batb":[[0,1.35,10]],"ltp":1.57,"tv":58.69,"id":72857117}]}]}
{"op":"mcm","clk":"11888663252","pt":1724240396440,"mc":[{"id":"1.232050243","rc":[{"batb":[[0,1.36,4],[1,1.35,10],[2,1.34,3.91]],"ltp":1.57,"tv":58.69,"id":72857117}]}]}
{"op":"mcm","clk":"11888663322","pt":1724240397262,"mc":[{"id":"1.232050243","rc":[{"batb":[[1,1.34,3.91],[2,1.21,83.24]],"ltp":1.57,"tv":58.69,"id":72857117}]}]}
{"op":"mcm","clk":"11888663462","pt":1724240398874,"mc":[{"id":"1.232050243","rc":[{"batb":[[0,1.34,3.91],[1,1.21,83.24],[2,1.04,1.53]],"ltp":1.57,"tv":58.69,"id":72857117}]}]}
{"op":"mcm","clk":"11888663784","pt":1724240402242,"mc":[{"id":"1.232050243","rc":[{"batb":[[0,1.35,14],[1,1.34,3.91],[2,1.21,83.24]],"ltp":1.57,"tv":58.69,"id":72857117}]}]}
{"op":"mcm","clk":"11888664016","pt":1724240404585,"mc":[{"id":"1.232050243","rc":[{"batb":[[0,1.35,10]],"ltp":1.57,"tv":58.69,"id":72857117}]}]}
{"op":"mcm","clk":"11888664125","pt":1724240405683,"mc":[{"id":"1.232050243","rc":[{"batb":[[0,1.34,3.91],[1,1.21,83.24],[2,1.04,1.53]],"ltp":1.57,"tv":58.69,"id":72857117}]}]}
{"op":"mcm","clk":"11888664255","pt":1724240407093,"mc":[{"id":"1.232050243","rc":[{"batb":[[0,1.35,4],[1,1.34,3.91],[2,1.21,83.24]],"ltp":1.57,"tv":58.69,"id":72857117}]}]}
{"op":"mcm","clk":"11888664380","pt":1724240408396,"mc":[{"id":"1.232050243","rc":[{"batb":[[0,1.36,10],[1,1.35,4],[2,1.34,3.91]],"ltp":1.57,"tv":58.69,"id":72857117}]}]}
{"op":"mcm","clk":"11888664512","pt":1724240409798,"mc":[{"id":"1.232050243","rc":[{"batb":[[1,1.34,3.91],[2,1.21,83.24]],"ltp":1.57,"tv":58.69,"id":72857117}]}]}
{"op":"mcm","clk":"11888664731","pt":1724240412092,"mc":[{"id":"1.232050243","rc":[{"batb":[[0,1.35,4]],"ltp":1.57,"tv":58.69,"id":72857117}]}]}
{"op":"mcm","clk":"11888664975","pt":1724240414683,"mc":[{"id":"1.232050243","rc":[{"batb":[[0,1.35,10]],"ltp":1.57,"tv":58.69,"id":72857117}]}]}
{"op":"mcm","clk":"11888665290","pt":1724240418106,"mc":[{"id":"1.232050243","rc":[{"batb":[[0,1.34,3.91],[1,1.21,83.24],[2,1.04,1.53]],"ltp":1.57,"tv":58.69,"id":72857117}]}]}
{"op":"mcm","clk":"11888665301","pt":1724240418209,"mc":[{"id":"1.232050243","rc":[{"batb":[[0,1.35,4],[1,1.34,3.91],[2,1.21,83.24]],"ltp":1.57,"tv":58.69,"id":72857117}]}]}
{"op":"mcm","clk":"11888665543","pt":1724240420817,"mc":[{"id":"1.232050243","rc":[{"batb":[[0,1.35,10]],"ltp":1.57,"tv":58.69,"id":72857117}]}]}
{"op":"mcm","clk":"11888665849","pt":1724240424091,"mc":[{"id":"1.232050243","rc":[{"batb":[[0,1.34,3.91],[1,1.21,83.24],[2,1.04,1.53]],"ltp":1.57,"tv":58.69,"id":72857117}]}]}
{"op":"mcm","clk":"11888665864","pt":1724240424295,"mc":[{"id":"1.232050243","rc":[{"batb":[[0,1.35,4],[1,1.34,3.91],[2,1.21,83.24]],"ltp":1.57,"tv":58.69,"id":72857117}]}]}
{"op":"mcm","clk":"11888666119","pt":1724240426807,"mc":[{"id":"1.232050243","rc":[{"batb":[[0,1.36,10]],"ltp":1.57,"tv":58.69,"id":72857117}]}]}
{"op":"mcm","clk":"11888666403","pt":1724240429807,"mc":[{"id":"1.232050243","rc":[{"batb":[[0,1.35,4]],"ltp":1.57,"tv":58.69,"id":72857117}]}]}
{"op":"mcm","clk":"11888666624","pt":1724240432103,"mc":[{"id":"1.232050243","rc":[{"batb":[[0,1.34,3.91],[1,1.21,83.24],[2,1.04,1.53]],"ltp":1.57,"tv":58.69,"id":72857117}]}]}
{"op":"mcm","clk":"11888666667","pt":1724240432516,"mc":[{"id":"1.232050243","rc":[{"batb":[[0,1.36,10],[1,1.34,3.91],[2,1.21,83.24]],"ltp":1.57,"tv":58.69,"id":72857117}]}]}
{"op":"mcm","clk":"11888666995","pt":1724240436010,"mc":[{"id":"1.232050243","rc":[{"batb":[[0,1.35,4]],"ltp":1.57,"tv":58.69,"id":72857117}]}]}
{"op":"mcm","clk":"11888667171","pt":1724240438139,"mc":[{"id":"1.232050243","rc":[{"batb":[[0,1.36,10],[1,1.35,4],[2,1.34,3.91]],"ltp":1.57,"tv":58.69,"id":72857117}]}]}
{"op":"mcm","clk":"11888667190","pt":1724240438300,"mc":[{"id":"1.232050243","rc":[{"batb":[[1,1.34,3.91],[2,1.21,83.24]],"ltp":1.57,"tv":58.69,"id":72857117}]}]}
{"op":"mcm","clk":"11888667514","pt":1724240442036,"mc":[{"id":"1.232050243","rc":[{"batb":[[0,1.37,4]],"ltp":1.57,"tv":58.69,"id":72857117}]}]}
{"op":"mcm","clk":"11888667750","pt":1724240444630,"mc":[{"id":"1.232050243","rc":[{"batb":[[0,1.35,10]],"ltp":1.57,"tv":58.69,"id":72857117}]}]}
{"op":"mcm","clk":"11888668024","pt":1724240447816,"mc":[{"id":"1.232050243","rc":[{"batb":[[0,1.36,4]],"ltp":1.57,"tv":58.69,"id":72857117}]}]}
{"op":"mcm","clk":"11888668293","pt":1724240450846,"mc":[{"id":"1.232050243","rc":[{"batb":[[0,1.34,3.91],[1,1.21,83.24],[2,1.04,1.53]],"ltp":1.57,"tv":58.69,"id":72857117}]}]}
{"op":"mcm","clk":"11888668334","pt":1724240451315,"mc":[{"id":"1.232050243","rc":[{"batb":[[0,1.35,10],[1,1.34,3.91],[2,1.21,83.24]],"ltp":1.57,"tv":58.69,"id":72857117}]}]}
{"op":"mcm","clk":"11888668595","pt":1724240453927,"mc":[{"id":"1.232050243","rc":[{"batb":[[0,1.36,4],[1,1.35,10],[2,1.34,3.91]],"ltp":1.57,"tv":58.69,"id":72857117}]}]}
{"op":"mcm","clk":"11888668677","pt":1724240454807,"mc":[{"id":"1.232050243","rc":[{"batb":[[1,1.34,3.91],[2,1.21,83.24]],"ltp":1.57,"tv":58.69,"id":72857117}]}]}
{"op":"mcm","clk":"11888668902","pt":1724240456962,"mc":[{"id":"1.232050243","rc":[{"batb":[[0,1.34,3.91],[1,1.21,83.24],[2,1.04,1.53]],"ltp":1.57,"tv":58.69,"id":72857117}]}]}
{"op":"mcm","clk":"11888668941","pt":1724240457328,"mc":[{"id":"1.232050243","rc":[{"batb":[[0,1.35,10],[1,1.34,3.91],[2,1.21,83.24]],"ltp":1.57,"tv":58.69,"id":72857117}]}]}
{"op":"mcm","clk":"11888669274","pt":1724240460722,"mc":[{"id":"1.232050243","rc":[{"batb":[[0,1.35,4]],"ltp":1.57,"tv":58.69,"id":72857117}]}]}
{"op":"mcm","clk":"11888669513","pt":1724240463013,"mc":[{"id":"1.232050243","rc":[{"batb":[[0,1.34,3.91],[1,1.21,83.24],[2,1.04,1.53]],"ltp":1.57,"tv":58.69,"id":72857117}]}]}
{"op":"mcm","clk":"11888669537","pt":1724240463225,"mc":[{"id":"1.232050243","rc":[{"batb":[[0,1.35,10],[1,1.34,3.91],[2,1.21,83.24]],"ltp":1.57,"tv":58.69,"id":72857117}]}]}
{"op":"mcm","clk":"11888669804","pt":1724240466031,"mc":[{"id":"1.232050243","rc":[{"batb":[[0,1.36,4],[1,1.35,10],[2,1.34,3.91]],"ltp":1.57,"tv":58.69,"id":72857117}]}]}
{"op":"mcm","clk":"11888669866","pt":1724240466650,"mc":[{"id":"1.232050243","rc":[{"batb":[[1,1.34,3.91],[2,1.21,83.24]],"ltp":1.57,"tv":58.69,"id":72857117}]}]}
{"op":"mcm","clk":"11888670109","pt":1724240468926,"mc":[{"id":"1.232050243","rc":[{"batb":[[0,1.34,3.91],[1,1.21,83.24],[2,1.04,1.53]],"ltp":1.57,"tv":58.69,"id":72857117}]}]}
{"op":"mcm","clk":"11888670132","pt":1724240469240,"mc":[{"id":"1.232050243","rc":[{"batb":[[0,1.35,10],[1,1.34,3.91],[2,1.21,83.24]],"ltp":1.57,"tv":58.69,"id":72857117}]}]}
{"op":"mcm","clk":"11888670416","pt":1724240472135,"mc":[{"id":"1.232050243","rc":[{"batb":[[0,1.36,4],[1,1.35,10],[2,1.34,3.91]],"ltp":1.57,"tv":58.69,"id":72857117}]}]}
{"op":"mcm","clk":"11888670454","pt":1724240472552,"mc":[{"id":"1.232050243","rc":[{"batb":[[1,1.34,3.91],[2,1.21,83.24]],"ltp":1.57,"tv":58.69,"id":72857117}]}]}
{"op":"mcm","clk":"11888670681","pt":1724240474933,"mc":[{"id":"1.232050243","rc":[{"batb":[[0,1.35,10]],"ltp":1.57,"tv":58.69,"id":72857117}]}]}
{"op":"mcm","clk":"11888670945","pt":1724240478046,"mc":[{"id":"1.232050243","rc":[{"batb":[[0,1.36,4],[1,1.35,10],[2,1.34,3.91]],"ltp":1.57,"tv":58.69,"id":72857117}]}]}
{"op":"mcm","clk":"11888670966","pt":1724240478248,"mc":[{"id":"1.232050243","rc":[{"batb":[[1,1.34,3.91],[2,1.21,83.24]],"ltp":1.57,"tv":58.69,"id":72857117}]}]}
{"op":"mcm","clk":"11888671152","pt":1724240480477,"mc":[{"id":"1.232050243","rc":[{"batb":[[0,1.35,10]],"ltp":1.57,"tv":58.69,"id":72857117}]}]}
{"op":"mcm","clk":"11888671504","pt":1724240484068,"mc":[{"id":"1.232050243","rc":[{"batb":[[0,1.35,4]],"ltp":1.57,"tv":58.69,"id":72857117}]}]}
{"op":"mcm","clk":"11888671744","pt":1724240486777,"mc":[{"id":"1.232050243","rc":[{"batb":[[0,1.35,10]],"ltp":1.57,"tv":58.69,"id":72857117}]}]}
{"op":"mcm","clk":"11888672010","pt":1724240489439,"mc":[{"id":"1.232050243","rc":[{"batb":[[0,1.36,4],[1,1.35,10],[2,1.34,3.91]],"ltp":1.57,"tv":58.69,"id":72857117}]}]}
{"op":"mcm","clk":"11888672084","pt":1724240490264,"mc":[{"id":"1.232050243","rc":[{"batb":[[1,1.34,3.91],[2,1.21,83.24]],"ltp":1.57,"tv":58.69,"id":72857117}]}]}
{"op":"mcm","clk":"11888672223","pt":1724240491842,"mc":[{"id":"1.232050243","rc":[{"batb":[[0,1.34,3.91],[1,1.21,83.24],[2,1.04,1.53]],"ltp":1.57,"tv":58.69,"id":72857117}]}]}
{"op":"mcm","clk":"11888672611","pt":1724240496089,"mc":[{"id":"1.232050243","rc":[{"batb":[[0,1.35,14],[1,1.34,3.91],[2,1.21,83.24]],"ltp":1.57,"tv":58.69,"id":72857117}]}]}
{"op":"mcm","clk":"11888672855","pt":1724240498686,"mc":[{"id":"1.232050243","rc":[{"batb":[[0,1.35,10]],"ltp":1.57,"tv":58.69,"id":72857117}]}]}
{"op":"mcm","clk":"11888672929","pt":1724240499571,"mc":[{"id":"1.232050243","rc":[{"batb":[[0,1.34,3.91],[1,1.21,83.24],[2,1.04,1.53]],"ltp":1.57,"tv":58.69,"id":72857117}]}]}
{"op":"mcm","clk":"11888673109","pt":1724240501866,"mc":[{"id":"1.232050243","rc":[{"batb":[[0,1.35,14],[1,1.34,3.91],[2,1.21,83.24]],"ltp":1.57,"tv":58.69,"id":72857117}]}]}
{"op":"mcm","clk":"11888673379","pt":1724240504671,"mc":[{"id":"1.232050243","rc":[{"batb":[[0,1.35,10]],"ltp":1.57,"tv":58.69,"id":72857117}]}]}
{"op":"mcm","clk":"11888673468","pt":1724240505705,"mc":[{"id":"1.232050243","rc":[{"batb":[[0,1.34,3.91],[1,1.21,83.24],[2,1.04,1.53]],"ltp":1.57,"tv":58.69,"id":72857117}]}]}
{"op":"mcm","clk":"11888673766","pt":1724240508775,"mc":[{"id":"1.232050243","rc":[{"batb":[[0,1.35,14],[1,1.34,3.91],[2,1.21,83.24]],"ltp":1.57,"tv":58.69,"id":72857117}]}]}
{"op":"mcm","clk":"11888674014","pt":1724240511379,"mc":[{"id":"1.232050243","rc":[{"batb":[[0,1.35,10]],"ltp":1.57,"tv":58.69,"id":72857117}]}]}
{"op":"mcm","clk":"11888674121","pt":1724240512573,"mc":[{"id":"1.232050243","rc":[{"batb":[[0,1.34,3.91],[1,1.21,83.24],[2,1.04,1.53]],"ltp":1.57,"tv":58.69,"id":72857117}]}]}
{"op":"mcm","clk":"11888674269","pt":1724240513875,"mc":[{"id":"1.232050243","rc":[{"batb":[[0,1.35,4],[1,1.34,3.91],[2,1.21,83.24]],"ltp":1.57,"tv":58.69,"id":72857117}]}]}
{"op":"mcm","clk":"11888674545","pt":1724240516591,"mc":[{"id":"1.232050243","rc":[{"batb":[[0,1.34,3.91],[1,1.21,83.24],[2,1.04,1.53]],"ltp":1.57,"tv":58.69,"id":72857117}]}]}
{"op":"mcm","clk":"11888674599","pt":1724240517213,"mc":[{"id":"1.232050243","rc":[{"batb":[[0,1.35,10],[1,1.34,3.91],[2,1.21,83.24]],"ltp":1.57,"tv":58.69,"id":72857117}]}]}
{"op":"mcm","clk":"11888674998","pt":1724240520815,"mc":[{"id":"1.232050243","rc":[{"batb":[[0,1.36,4]],"ltp":1.57,"tv":58.69,"id":72857117}]}]}
{"op":"mcm","clk":"11888675343","pt":1724240523830,"mc":[{"id":"1.232050243","rc":[{"batb":[[0,1.34,3.91],[1,1.21,83.24],[2,1.04,1.53]],"ltp":1.57,"tv":58.69,"id":72857117}]}]}
{"op":"mcm","clk":"11888675443","pt":1724240524712,"mc":[{"id":"1.232050243","rc":[{"batb":[[0,1.35,10],[1,1.34,3.91],[2,1.21,83.24]],"ltp":1.57,"tv":58.69,"id":72857117}]}]}
{"op":"mcm","clk":"11888675749","pt":1724240527116,"mc":[{"id":"1.232050243","rc":[{"batb":[[0,1.36,4],[1,1.35,10],[2,1.34,3.91]],"ltp":1.57,"tv":58.69,"id":72857117}]}]}
{"op":"mcm","clk":"11888675921","pt":1724240528718,"mc":[{"id":"1.232050243","rc":[{"batb":[[1,1.34,3.91],[2,1.21,83.24]],"ltp":1.57,"tv":58.69,"id":72857117}]}]}
{"op":"mcm","clk":"11888676031","pt":1724240529848,"mc":[{"id":"1.232050243","rc":[{"batb":[[0,1.34,3.91],[1,1.21,83.24],[2,1.04,1.53]],"ltp":1.57,"tv":58.69,"id":72857117}]}]}
{"op":"mcm","clk":"11888676353","pt":1724240532935,"mc":[{"id":"1.232050243","rc":[{"batb":[[0,1.35,14],[1,1.34,3.91],[2,1.21,83.24]],"ltp":1.57,"tv":58.69,"id":72857117}]}]}
{"op":"mcm","clk":"11888676621","pt":1724240535724,"mc":[{"id":"1.232050243","rc":[{"batb":[[0,1.35,10]],"ltp":1.57,"tv":58.69,"id":72857117}]}]}
{"op":"mcm","clk":"11888676768","pt":1724240537120,"mc":[{"id":"1.232050243","rc":[{"batb":[[0,1.34,3.91],[1,1.21,83.24],[2,1.04,1.53]],"ltp":1.57,"tv":58.69,"id":72857117}]}]}
{"op":"mcm","clk":"11888676969","pt":1724240539037,"mc":[{"id":"1.232050243","rc":[{"batb":[[0,1.35,4],[1,1.34,3.91],[2,1.21,83.24]],"ltp":1.57,"tv":58.69,"id":72857117}]}]}
{"op":"mcm","clk":"11888677022","pt":1724240539556,"mc":[{"id":"1.232050243","rc":[{"batb":[[0,1.36,10],[1,1.35,4],[2,1.34,3.91]],"ltp":1.57,"tv":58.69,"id":72857117}]}]}
{"op":"mcm","clk":"11888677236","pt":1724240541734,"mc":[{"id":"1.232050243","rc":[{"batb":[[1,1.34,3.91],[2,1.21,83.24]],"ltp":1.57,"tv":58.69,"id":72857117}]}]}
{"op":"mcm","clk":"11888677404","pt":1724240543442,"mc":[{"id":"1.232050243","rc":[{"batb":[[0,1.34,3.91],[1,1.21,83.24],[2,1.04,1.53]],"ltp":1.57,"tv":58.69,"id":72857117}]}]}
{"op":"mcm","clk":"11888677535","pt":1724240545135,"mc":[{"id":"1.232050243","rc":[{"batb":[[0,1.35,4],[1,1.34,3.91],[2,1.21,83.24]],"ltp":1.57,"tv":58.69,"id":72857117}]}]}
{"op":"mcm","clk":"11888677588","pt":1724240545753,"mc":[{"id":"1.232050243","rc":[{"batb":[[0,1.36,10],[1,1.35,4],[2,1.34,3.91]],"ltp":1.57,"tv":58.69,"id":72857117}]}]}
{"op":"mcm","clk":"11888677783","pt":1724240547970,"mc":[{"id":"1.232050243","rc":[{"batb":[[1,1.34,3.91],[2,1.21,83.24]],"ltp":1.57,"tv":58.69,"id":72857117}]}]}
{"op":"mcm","clk":"11888677922","pt":1724240549570,"mc":[{"id":"1.232050243","rc":[{"batb":[[0,1.34,3.91],[1,1.21,83.24],[2,1.04,1.53]],"ltp":1.57,"tv":58.69,"id":72857117}]}]}
{"op":"mcm","clk":"11888678261","pt":1724240553272,"mc":[{"id":"1.232050243","rc":[{"batb":[[0,1.35,14],[1,1.34,3.91],[2,1.21,83.24]],"ltp":1.57,"tv":58.69,"id":72857117}]}]}
{"op":"mcm","clk":"11888678524","pt":1724240556181,"mc":[{"id":"1.232050243","rc":[{"batb":[[0,1.35,10]],"ltp":1.57,"tv":58.69,"id":72857117}]}]}
{"op":"mcm","clk":"11888678624","pt":1724240557276,"mc":[{"id":"1.232050243","rc":[{"batb":[[0,1.34,3.91],[1,1.21,83.24],[2,1.04,1.53]],"ltp":1.57,"tv":58.69,"id":72857117}]}]}
{"op":"mcm","clk":"11888679080","pt":1724240561987,"mc":[{"id":"1.232050243","rc":[{"batb":[[0,1.35,14],[1,1.34,3.91],[2,1.21,83.24]],"ltp":1.57,"tv":58.69,"id":72857117}]}]}
{"op":"mcm","clk":"11888679356","pt":1724240565088,"mc":[{"id":"1.232050243","rc":[{"batb":[[0,1.35,10]],"ltp":1.57,"tv":58.69,"id":72857117}]}]}
{"op":"mcm","clk":"11888679449","pt":1724240566074,"mc":[{"id":"1.232050243","rc":[{"batb":[[0,1.34,3.91],[1,1.21,83.24],[2,1.04,1.53]],"ltp":1.57,"tv":58.69,"id":72857117}]}]}
{"op":"mcm","clk":"11888679652","pt":1724240568070,"mc":[{"id":"1.232050243","rc":[{"batb":[[0,1.35,4],[1,1.34,3.91],[2,1.21,83.24]],"ltp":1.57,"tv":58.69,"id":72857117}]}]}
{"op":"mcm","clk":"11888679735","pt":1724240568997,"mc":[{"id":"1.232050243","rc":[{"batb":[[0,1.36,10],[1,1.35,4],[2,1.34,3.91]],"ltp":1.57,"tv":58.69,"id":72857117}]}]}
{"op":"mcm","clk":"11888679934","pt":1724240570964,"mc":[{"id":"1.232050243","rc":[{"batb":[[1,1.34,3.91],[2,1.21,83.24]],"ltp":1.57,"tv":58.69,"id":72857117}]}]}
{"op":"mcm","clk":"11888680057","pt":1724240572305,"mc":[{"id":"1.232050243","rc":[{"batb":[[0,1.34,3.91],[1,1.21,83.24],[2,1.04,1.53]],"ltp":1.57,"tv":58.69,"id":72857117}]}]}
{"op":"mcm","clk":"11888688974","pt":1724240575195,"mc":[{"id":"1.232050243","rc":[{"batb":[[0,1.35,14],[1,1.34,3.91],[2,1.21,83.24]],"ltp":1.57,"tv":58.69,"id":72857117}]}]}
{"op":"mcm","clk":"11888689257","pt":1724240577883,"mc":[{"id":"1.232050243","rc":[{"batb":[[0,1.35,10]],"ltp":1.57,"tv":58.69,"id":72857117}]}]}
{"op":"mcm","clk":"11888689345","pt":1724240579011,"mc":[{"id":"1.232050243","rc":[{"batb":[[0,1.34,3.91],[1,1.21,83.24],[2,1.04,1.53]],"ltp":1.57,"tv":58.69,"id":72857117}]}]}
{"op":"mcm","clk":"11888689473","pt":1724240580309,"mc":[{"id":"1.232050243","rc":[{"batb":[[0,1.35,4],[1,1.34,3.91],[2,1.21,83.24]],"ltp":1.57,"tv":58.69,"id":72857117}]}]}
{"op":"mcm","clk":"11888689727","pt":1724240582928,"mc":[{"id":"1.232050243","rc":[{"batb":[[0,1.34,3.91],[1,1.21,83.24],[2,1.04,1.53]],"ltp":1.57,"tv":58.69,"id":72857117}]}]}
{"op":"mcm","clk":"11888689766","pt":1724240583296,"mc":[{"id":"1.232050243","rc":[{"batb":[[0,1.35,10],[1,1.34,3.91],[2,1.21,83.24]],"ltp":1.57,"tv":58.69,"id":72857117}]}]}
{"op":"mcm","clk":"11888690109","pt":1724240586980,"mc":[{"id":"1.232050243","rc":[{"batb":[[0,1.35,4]],"ltp":1.57,"tv":58.69,"id":72857117}]}]}
{"op":"mcm","clk":"11888690364","pt":1724240589722,"mc":[{"id":"1.232050243","rc":[{"batb":[[0,1.35,10]],"ltp":1.57,"tv":58.69,"id":72857117}]}]}
{"op":"mcm","clk":"11888690686","pt":1724240593089,"mc":[{"id":"1.232050243","rc":[{"batb":[[0,1.36,4]],"ltp":1.57,"tv":58.69,"id":72857117}]}]}
{"op":"mcm","clk":"11888691037","pt":1724240596135,"mc":[{"id":"1.232050243","rc":[{"batb":[[0,1.35,10]],"ltp":1.57,"tv":58.69,"id":72857117}]}]}
{"op":"mcm","clk":"11888691219","pt":1724240597809,"mc":[{"id":"1.232050243","rc":[{"batb":[[0,1.36,4],[1,1.35,10],[2,1.34,3.91]],"ltp":1.57,"tv":58.69,"id":72857117}]}]}
{"op":"mcm","clk":"11888691416","pt":1724240599746,"mc":[{"id":"1.232050243","rc":[{"batb":[[1,1.34,3.91],[2,1.21,83.24]],"ltp":1.57,"tv":58.69,"id":72857117}]}]}
{"op":"mcm","clk":"11888691507","pt":1724240600625,"mc":[{"id":"1.232050243","rc":[{"batb":[[0,1.34,3.91],[1,1.21,83.24],[2,1.04,1.53]],"ltp":1.57,"tv":58.69,"id":72857117}]}]}
{"op":"mcm","clk":"11888691728","pt":1724240602951,"mc":[{"id":"1.232050243","rc":[{"batb":[[0,1.36,4],[1,1.35,10],[2,1.34,3.91]],"ltp":1.57,"tv":58.69,"id":72857117}]}]}
{"op":"mcm","clk":"11888691993","pt":1724240605711,"mc":[{"id":"1.232050243","rc":[{"batb":[[0,1.34,3.91],[1,1.21,83.24],[2,1.04,1.53]],"ltp":1.57,"tv":58.69,"id":72857117}]}]}
{"op":"mcm","clk":"11888692311","pt":1724240608810,"mc":[{"id":"1.232050243","rc":[{"batb":[[0,1.35,14],[1,1.34,3.91],[2,1.21,83.24]],"ltp":1.57,"tv":58.69,"id":72857117}]}]}
{"op":"mcm","clk":"11888692533","pt":1724240611063,"mc":[{"id":"1.232050243","rc":[{"batb":[[0,1.35,10]],"ltp":1.57,"tv":58.69,"id":72857117}]}]}
{"op":"mcm","clk":"11888692641","pt":1724240612051,"mc":[{"id":"1.232050243","rc":[{"batb":[[0,1.34,3.91],[1,1.21,83.24],[2,1.04,1.53]],"ltp":1.57,"tv":58.69,"id":72857117}]}]}
{"op":"mcm","clk":"11888692827","pt":1724240614120,"mc":[{"id":"1.232050243","rc":[{"batb":[[0,1.35,4],[1,1.34,3.91],[2,1.21,83.24]],"ltp":1.57,"tv":58.69,"id":72857117}]}]}
{"op":"mcm","clk":"11888692866","pt":1724240614635,"mc":[{"id":"1.232050243","rc":[{"batb":[[0,1.36,10],[1,1.35,4],[2,1.34,3.91]],"ltp":1.57,"tv":58.69,"id":72857117}]}]}
{"op":"mcm","clk":"11888693042","pt":1724240616645,"mc":[{"id":"1.232050243","rc":[{"batb":[[1,1.34,3.91],[2,1.21,83.24]],"ltp":1.57,"tv":58.69,"id":72857117}]}]}
{"op":"mcm","clk":"11888693188","pt":1724240618257,"mc":[{"id":"1.232050243","rc":[{"batb":[[0,1.34,3.91],[1,1.21,83.24],[2,1.04,1.53]],"ltp":1.57,"tv":58.69,"id":72857117}]}]}
{"op":"mcm","clk":"11888693568","pt":1724240622152,"mc":[{"id":"1.232050243","rc":[{"batb":[[0,1.35,14],[1,1.34,3.91],[2,1.21,83.24]],"ltp":1.57,"tv":58.69,"id":72857117}]}]}
{"op":"mcm","clk":"11888693872","pt":1724240624952,"mc":[{"id":"1.232050243","rc":[{"batb":[[0,1.35,10]],"ltp":1.57,"tv":58.69,"id":72857117}]}]}
{"op":"mcm","clk":"11888693960","pt":1724240625835,"mc":[{"id":"1.232050243","rc":[{"batb":[[0,1.34,3.91],[1,1.21,83.24],[2,1.04,1.53]],"ltp":1.57,"tv":58.69,"id":72857117}]}]}
{"op":"mcm","clk":"11888694181","pt":1724240628068,"mc":[{"id":"1.232050243","rc":[{"batb":[[0,1.36,10],[1,1.35,4],[2,1.34,3.91]],"ltp":1.57,"tv":58.69,"id":72857117}]}]}
{"op":"mcm","clk":"11888694397","pt":1724240630342,"mc":[{"id":"1.232050243","rc":[{"batb":[[1,1.34,3.91],[2,1.21,83.24]],"ltp":1.57,"tv":58.69,"id":72857117}]}]}
{"op":"mcm","clk":"11888694554","pt":1724240631845,"mc":[{"id":"1.232050243","rc":[{"batb":[[0,1.34,3.91],[1,1.21,83.24],[2,1.04,1.53]],"ltp":1.57,"tv":58.69,"id":72857117}]}]}
{"op":"mcm","clk":"11888695058","pt":1724240636870,"mc":[{"id":"1.232050243","rc":[{"batb":[[0,1.35,14],[1,1.34,3.91],[2,1.21,83.24]],"ltp":1.57,"tv":58.69,"id":72857117}]}]}
{"op":"mcm","clk":"11888695381","pt":1724240639674,"mc":[{"id":"1.232050243","rc":[{"batb":[[0,1.35,10]],"ltp":1.57,"tv":58.69,"id":72857117}]}]}
{"op":"mcm","clk":"11888695485","pt":1724240640565,"mc":[{"id":"1.232050243","rc":[{"batb":[[0,1.34,3.91],[1,1.21,83.24],[2,1.04,1.53]],"ltp":1.57,"tv":58.69,"id":72857117}]}]}
{"op":"mcm","clk":"11888696009","pt":1724240645105,"mc":[{"id":"1.232050243","rc":[{"batb":[[0,1.36,14],[1,1.34,3.91],[2,1.21,83.24]],"ltp":1.57,"tv":58.69,"id":72857117}]}]}
{"op":"mcm","clk":"11888696827","pt":1724240652880,"mc":[{"id":"1.232050243","rc":[{"batb":[[0,1.36,10]],"ltp":1.57,"tv":58.69,"id":72857117}]}]}
{"op":"mcm","clk":"11888696919","pt":1724240653803,"mc":[{"id":"1.232050243","rc":[{"batb":[[0,1.34,3.91],[1,1.21,83.24],[2,1.04,1.53]],"ltp":1.57,"tv":58.69,"id":72857117}]}]}
{"op":"mcm","clk":"11888697193","pt":1724240656482,"mc":[{"id":"1.232050243","rc":[{"batb":[[0,1.37,14],[1,1.34,3.91],[2,1.21,83.24]],"ltp":1.57,"tv":58.69,"id":72857117}]}]}
{"op":"mcm","clk":"11888697632","pt":1724240660989,"mc":[{"id":"1.232050243","rc":[{"batb":[[0,1.37,10]],"ltp":1.57,"tv":58.69,"id":72857117}]}]}
{"op":"mcm","clk":"11888697755","pt":1724240662229,"mc":[{"id":"1.232050243","rc":[{"batb":[[0,1.34,3.91],[1,1.21,83.24],[2,1.04,1.53]],"ltp":1.57,"tv":58.69,"id":72857117}]}]}
{"op":"mcm","clk":"11888697866","pt":1724240663216,"mc":[{"id":"1.232050243","rc":[{"batb":[[0,1.35,4],[1,1.34,3.91],[2,1.21,83.24]],"ltp":1.57,"tv":58.69,"id":72857117}]}]}
{"op":"mcm","clk":"11888698170","pt":1724240666124,"mc":[{"id":"1.232050243","rc":[{"batb":[[0,1.35,10]],"ltp":1.57,"tv":58.69,"id":72857117}]}]}
{"op":"mcm","clk":"11888698556","pt":1724240669750,"mc":[{"id":"1.232050243","rc":[{"batb":[[0,1.35,4]],"ltp":1.57,"tv":58.69,"id":72857117}]}]}
{"op":"mcm","clk":"11888698797","pt":1724240672045,"mc":[{"id":"1.232050243","rc":[{"batb":[[0,1.34,3.91],[1,1.21,83.24],[2,1.04,1.53]],"ltp":1.57,"tv":58.69,"id":72857117}]}]}
{"op":"mcm","clk":"11888698847","pt":1724240672428,"mc":[{"id":"1.232050243","rc":[{"batb":[[0,1.35,10],[1,1.34,3.91],[2,1.21,83.24]],"ltp":1.57,"tv":58.69,"id":72857117}]}]}
{"op":"mcm","clk":"11888699204","pt":1724240676122,"mc":[{"id":"1.232050243","rc":[{"batb":[[0,1.35,4]],"ltp":1.57,"tv":58.69,"id":72857117}]}]}
{"op":"mcm","clk":"11888699464","pt":1724240678727,"mc":[{"id":"1.232050243","rc":[{"batb":[[0,1.35,10]],"ltp":1.57,"tv":58.69,"id":72857117}]}]}
{"op":"mcm","clk":"11888699802","pt":1724240682060,"mc":[{"id":"1.232050243","rc":[{"batb":[[0,1.36,4]],"ltp":1.57,"tv":58.69,"id":72857117}]}]}
{"op":"mcm","clk":"11888700062","pt":1724240684746,"mc":[{"id":"1.232050243","rc":[{"batb":[[0,1.34,3.91],[1,1.21,83.24],[2,1.04,1.53]],"ltp":1.57,"tv":58.69,"id":72857117}]}]}
{"op":"mcm","clk":"11888700123","pt":1724240685463,"mc":[{"id":"1.232050243","rc":[{"batb":[[0,1.35,10],[1,1.34,3.91],[2,1.21,83.24]],"ltp":1.57,"tv":58.69,"id":72857117}]}]}
{"op":"mcm","clk":"11888700508","pt":1724240689059,"mc":[{"id":"1.232050243","rc":[{"batb":[[0,1.35,4]],"ltp":1.57,"tv":58.69,"id":72857117}]}]}
{"op":"mcm","clk":"11888700780","pt":1724240691654,"mc":[{"id":"1.232050243","rc":[{"batb":[[0,1.35,10]],"ltp":1.57,"tv":58.69,"id":72857117}]}]}
{"op":"mcm","clk":"11888701153","pt":1724240695073,"mc":[{"id":"1.232050243","rc":[{"batb":[[0,1.34,3.91],[1,1.21,83.24],[2,1.04,1.53]],"ltp":1.57,"tv":58.69,"id":72857117}]}]}
{"op":"mcm","clk":"11888701184","pt":1724240695332,"mc":[{"id":"1.232050243","rc":[{"batb":[[0,1.35,4],[1,1.34,3.91],[2,1.21,83.24]],"ltp":1.57,"tv":58.69,"id":72857117}]}]}
{"op":"mcm","clk":"11888701450","pt":1724240697957,"mc":[{"id":"1.232050243","rc":[{"batb":[[0,1.35,10]],"ltp":1.57,"tv":58.69,"id":72857117}]}]}
{"op":"mcm","clk":"11888701797","pt":1724240701639,"mc":[{"id":"1.232050243","rc":[{"batb":[[0,1.35,4]],"ltp":1.57,"tv":58.69,"id":72857117}]}]}
{"op":"mcm","clk":"11888702085","pt":1724240704181,"mc":[{"id":"1.232050243","rc":[{"batb":[[0,1.35,10]],"ltp":1.57,"tv":58.69,"id":72857117}]}]}
{"op":"mcm","clk":"11888702278","pt":1724240706297,"mc":[{"id":"1.232050243","rc":[{"batb":[[0,1.36,4],[1,1.35,10],[2,1.34,3.91]],"ltp":1.57,"tv":58.69,"id":72857117}]}]}
{"op":"mcm","clk":"11888702427","pt":1724240707753,"mc":[{"id":"1.232050243","rc":[{"batb":[[1,1.34,3.91],[2,1.21,83.24]],"ltp":1.57,"tv":58.69,"id":72857117}]}]}
{"op":"mcm","clk":"11888702567","pt":1724240709051,"mc":[{"id":"1.232050243","rc":[{"batb":[[0,1.34,3.91],[1,1.21,83.24],[2,1.04,1.53]],"ltp":1.57,"tv":58.69,"id":72857117}]}]}
{"op":"mcm","clk":"11888703019","pt":1724240714153,"mc":[{"id":"1.232050243","rc":[{"batb":[[0,1.35,14],[1,1.34,3.91],[2,1.21,83.24]],"ltp":1.57,"tv":58.69,"id":72857117}]}]}
{"op":"mcm","clk":"11888703275","pt":1724240717002,"mc":[{"id":"1.232050243","rc":[{"batb":[[0,1.35,10]],"ltp":1.57,"tv":58.69,"id":72857117}]}]}
{"op":"mcm","clk":"11888703380","pt":1724240718091,"mc":[{"id":"1.232050243","rc":[{"batb":[[0,1.34,3.91],[1,1.21,83.24],[2,1.04,1.53]],"ltp":1.57,"tv":58.69,"id":72857117}]}]}
{"op":"mcm","clk":"11888703626","pt":1724240720662,"mc":[{"id":"1.232050243","rc":[{"batb":[[0,1.35,14],[1,1.34,3.91],[2,1.21,83.24]],"ltp":1.57,"tv":58.69,"id":72857117}]}]}
{"op":"mcm","clk":"11888703887","pt":1724240723605,"mc":[{"id":"1.232050243","rc":[{"batb":[[0,1.35,10]],"ltp":1.57,"tv":58.69,"id":72857117}]}]}
{"op":"mcm","clk":"11888703971","pt":1724240724592,"mc":[{"id":"1.232050243","rc":[{"batb":[[0,1.34,3.91],[1,1.21,83.24],[2,1.04,1.53]],"ltp":1.57,"tv":58.69,"id":72857117}]}]}
{"op":"mcm","clk":"11888704106","pt":1724240725994,"mc":[{"id":"1.232050243","rc":[{"batb":[[0,1.35,4],[1,1.34,3.91],[2,1.21,83.24]],"ltp":1.57,"tv":58.69,"id":72857117}]}]}
{"op":"mcm","clk":"11888704346","pt":1724240728785,"mc":[{"id":"1.232050243","rc":[{"batb":[[0,1.34,3.91],[1,1.21,83.24],[2,1.04,1.53]],"ltp":1.57,"tv":58.69,"id":72857117}]}]}
{"op":"mcm","clk":"11888704408","pt":1724240729503,"mc":[{"id":"1.232050243","rc":[{"batb":[[0,1.35,10],[1,1.34,3.91],[2,1.21,83.24]],"ltp":1.57,"tv":58.69,"id":72857117}]}]}
{"op":"mcm","clk":"11888704730","pt":1724240733014,"mc":[{"id":"1.232050243","rc":[{"batb":[[0,1.34,3.91],[1,1.21,83.24],[2,1.04,1.53]],"ltp":1.57,"tv":58.69,"id":72857117}]}]}
{"op":"mcm","clk":"11888704752","pt":1724240733316,"mc":[{"id":"1.232050243","rc":[{"batb":[[0,1.35,4],[1,1.34,3.91],[2,1.21,83.24]],"ltp":1.57,"tv":58.69,"id":72857117}]}]}
{"op":"mcm","clk":"11888704954","pt":1724240735627,"mc":[{"id":"1.232050243","rc":[{"batb":[[0,1.35,10]],"ltp":1.57,"tv":58.69,"id":72857117}]}]}
{"op":"mcm","clk":"11888705266","pt":1724240739039,"mc":[{"id":"1.232050243","rc":[{"batb":[[0,1.36,4]],"ltp":1.57,"tv":58.69,"id":72857117}]}]}
{"op":"mcm","clk":"11888705532","pt":1724240741942,"mc":[{"id":"1.232050243","rc":[{"batb":[[0,1.35,10]],"ltp":1.57,"tv":58.69,"id":72857117}]}]}
{"op":"mcm","clk":"11888705861","pt":1724240745449,"mc":[{"id":"1.232050243","rc":[{"batb":[[0,1.36,4]],"ltp":1.57,"tv":58.69,"id":72857117}]}]}
{"op":"mcm","clk":"11888706087","pt":1724240748032,"mc":[{"id":"1.232050243","rc":[{"batb":[[0,1.34,3.91],[1,1.21,83.24],[2,1.04,1.53]],"ltp":1.57,"tv":58.69,"id":72857117}]}]}
