{"op":"mcm","clk":"11915977409","pt":1724070649733,"mc":[{"id":"1.232013794","marketDefinition":{"bspMarket":false,"turnInPlayEnabled":true,"persistenceEnabled":true,"marketBaseRate":5.0,"eventId":"33508163","eventTypeId":"4","numberOfWinners":1,"bettingType":"ODDS","marketType":"MATCH_ODDS","marketTime":"2024-08-21T09:30:00.000Z","suspendTime":"2024-08-21T09:30:00.000Z","bspReconciled":false,"complete":true,"inPlay":false,"crossMatching":false,"runnersVoidable":false,"numberOfActiveRunners":2,"betDelay":0,"status":"OPEN","runners":[{"status":"ACTIVE","sortPriority":1,"id":61077257,"name":"Guernsey"},{"status":"ACTIVE","sortPriority":2,"id":61077258,"name":"Bulgaria"}],"regulators":["MR_INT"],"countryCode":"GB","discountAllowed":false,"timezone":"GMT","openDate":"2024-08-21T09:30:00.000Z","version":6086377739,"name":"Match Odds","eventName":"Guernsey v Bulgaria"},"rc":[{"batb":[[0,1.03,200],[1,1.02,200],[2,1.01,220]],"ltp":0.0,"tv":0.0,"id":61077257},{"batb":[[0,1.03,200],[1,1.02,200],[2,1.01,220]],"ltp":0.0,"tv":0.0,"id":61077258}]}]}
{"op":"mcm","clk":"11915977500","pt":1724070651241,"mc":[{"id":"1.232013794","marketDefinition":{"bspMarket":false,"turnInPlayEnabled":true,"persistenceEnabled":true,"marketBaseRate":5.0,"eventId":"33508163","eventTypeId":"4","numberOfWinners":1,"bettingType":"ODDS","marketType":"MATCH_ODDS","marketTime":"2024-08-21T09:30:00.000Z","suspendTime":"2024-08-21T09:30:00.000Z","bspReconciled":false,"complete":true,"inPlay":false,"crossMatching":false,"runnersVoidable":false,"numberOfActiveRunners":2,"betDelay":0,"status":"OPEN","runners":[{"status":"ACTIVE","sortPriority":1,"id":61077257,"name":"Guernsey"},{"status":"ACTIVE","sortPriority":2,"id":61077258,"name":"Bulgaria"}],"regulators":["MR_INT"],"countryCode":"GB","discountAllowed":true,"timezone":"GMT","openDate":"2024-08-21T09:30:00.000Z","version":6086377739,"name":"Match Odds","eventName":"Guernsey v Bulgaria"}}]}
{"op":"mcm","clk":"11916116463","pt":1724073076211,"mc":[{"id":"1.232013794","rc":[{"batb":[[0,1.05,200],[1,1.04,250],[2,1.03,533.33]],"ltp":0.0,"tv":0.0,"id":61077257},{"batb":[[0,1.05,200],[1,1.04,250],[2,1.03,533.33]],"ltp":0.0,"tv":0.0,"id":61077258}]}]}
{"op":"mcm","clk":"11916116467","pt":1724073076314,"mc":[{"id":"1.232013794","rc":[{"batb":[[0,1.06,166.67],[1,1.05,200],[2,1.04,250]],"ltp":0.0,"tv":0.0,"id":61077257},{"batb":[[0,1.06,166.67],[1,1.05,200],[2,1.04,250]],"ltp":0.0,"tv":0.0,"id":61077258}]}]}
{"op":"mcm","clk":"11916171640","pt":1724073868484,"mc":[{"id":"1.232013794","rc":[{"batb":[[0,1.1,4.49],[1,1.06,166.67],[2,1.05,200]],"ltp":0.0,"tv":0.0,"id":61077258}]}]}
{"op":"mcm","clk":"11916172329","pt":1724073877440,"mc":[{"id":"1.232013794","marketDefinition":{"bspMarket":false,"turnInPlayEnabled":true,"persistenceEnabled":true,"marketBaseRate":5.0,"eventId":"33508163","eventTypeId":"4","numberOfWinners":1,"bettingType":"ODDS","marketType":"MATCH_ODDS","marketTime":"2024-08-21T09:30:00.000Z","suspendTime":"2024-08-21T09:30:00.000Z","bspReconciled":false,"complete":true,"inPlay":false,"crossMatching":true,"runnersVoidable":false,"numberOfActiveRunners":2,"betDelay":0,"status":"OPEN","runners":[{"status":"ACTIVE","sortPriority":1,"id":61077257,"name":"Guernsey"},{"status":"ACTIVE","sortPriority":2,"id":61077258,"name":"Bulgaria"}],"regulators":["MR_INT"],"countryCode":"GB","discountAllowed":true,"timezone":"GMT","openDate":"2024-08-21T09:30:00.000Z","version":6086377739,"name":"Match Odds","eventName":"Guernsey v Bulgaria"}}]}
{"op":"mcm","clk":"11916172967","pt":1724073886839,"mc":[{"id":"1.232013794","rc":[{"batb":[[0,1.06,166.67],[1,1.05,200],[2,1.04,250]],"ltp":0.0,"tv":0.0,"id":61077258}]}]}
{"op":"mcm","clk":"11916196963","pt":1724074217696,"mc":[{"id":"1.232013794","rc":[{"trd":[[1.06,2]],"batb":[[0,1.06,165.67]],"ltp":1.06,"tv":2.0,"id":61077257}],"tv":2.0}]}
{"op":"mcm","clk":"11916209589","pt":1724074394664,"mc":[{"id":"1.232013794","rc":[{"trd":[[18,1]],"ltp":18.0,"tv":3.0,"id":61077257},{"trd":[[1.06,16.98]],"batb":[[0,1.06,149.69]],"ltp":1.06,"tv":16.98,"id":61077258}],"tv":19.98}]}
{"op":"mcm","clk":"11916214387","pt":1724074467487,"mc":[{"id":"1.232013794","rc":[{"batb":[[0,1.07,165.75],[1,1.06,149.69],[2,1.05,200]],"ltp":1.06,"tv":16.98,"id":61077258}]}]}
{"op":"mcm","clk":"11916234275","pt":1724074763605,"mc":[{"id":"1.232013794","rc":[{"trd":[[1.06,4]],"batb":[[0,1.06,164.67]],"ltp":1.06,"tv":5.0,"id":61077257}],"tv":21.98}]}
{"op":"mcm","clk":"11916235974","pt":1724074786451,"mc":[{"id":"1.232013794","rc":[{"batb":[[0,1.07,40.04],[1,1.06,164.67],[2,1.05,200]],"ltp":1.06,"tv":5.0,"id":61077257}]}]}
{"op":"mcm","clk":"11916274112","pt":1724075381475,"mc":[{"id":"1.232013794","rc":[{"batb":[[0,1.22,10.77],[1,1.07,40.04],[2,1.06,164.67]],"ltp":1.06,"tv":5.0,"id":61077257}]}]}
{"op":"mcm","clk":"11916363276","pt":1724076775046,"mc":[{"id":"1.232013794","rc":[{"batb":[[0,1.22,10.76],[1,1.07,40.01]],"ltp":1.06,"tv":5.0,"id":61077257},{"batb":[[0,1.07,165.63]],"ltp":1.06,"tv":16.98,"id":61077258}]}]}
{"op":"mcm","clk":"11916376219","pt":1724076966994,"mc":[{"id":"1.232013794","rc":[{"batl":[[0,2.5,30]],"ltp":1.06,"tv":5.0,"id":61077257}]}]}
{"op":"mcm","clk":"11916587158","pt":1724080066435,"mc":[{"id":"1.232013794","rc":[{"batb":[[0,1.22,10.74],[1,1.08,14.7],[2,1.07,39.93]],"ltp":1.06,"tv":5.0,"id":61077257},{"batb":[[0,1.07,165.31]],"ltp":1.06,"tv":16.98,"id":61077258}]}]}
{"op":"mcm","clk":"11916587389","pt":1724080068714,"mc":[{"id":"1.232013794","rc":[{"batb":[[1,1.07,39.93],[2,1.06,164.67]],"ltp":1.06,"tv":5.0,"id":61077257}]}]}
{"op":"mcm","clk":"11916587952","pt":1724080074127,"mc":[{"id":"1.232013794","rc":[{"batb":[[0,1.23,12.91],[1,1.22,10.74],[2,1.07,39.93]],"ltp":1.06,"tv":5.0,"id":61077257}]}]}
{"op":"mcm","clk":"11916696730","pt":1724081140551,"mc":[{"id":"1.232013794","rc":[{"batb":[[0,1.06,149.69],[1,1.05,200],[2,1.04,250]],"ltp":1.06,"tv":16.98,"id":61077258}]}]}
{"op":"mcm","clk":"11916697287","pt":1724081145470,"mc":[{"id":"1.232013794","rc":[{"batb":[[2,1.06,164.67]],"ltp":1.06,"tv":5.0,"id":61077257}]}]}
{"op":"mcm","clk":"11916792132","pt":1724082074265,"mc":[{"id":"1.232013794","rc":[{"batb":[[0,1.24,35.68],[1,1.23,12.91],[2,1.22,10.74]],"ltp":1.06,"tv":5.0,"id":61077257},{"batb":[[0,1.67,12.78],[1,1.06,149.69],[2,1.05,200]],"ltp":1.06,"tv":16.98,"id":61077258}]}]}
{"op":"mcm","clk":"11916877530","pt":1724082884822,"mc":[{"id":"1.232013794","rc":[{"batb":[[1,1.22,10.74],[2,1.06,164.67]],"ltp":1.06,"tv":5.0,"id":61077257}]}]}
{"op":"mcm","clk":"11916877670","pt":1724082886320,"mc":[{"id":"1.232013794","rc":[{"batb":[[0,1.25,12.7],[1,1.24,35.68],[2,1.22,10.74]],"ltp":1.06,"tv":5.0,"id":61077257}]}]}
{"op":"mcm","clk":"11916996408","pt":1724083874903,"mc":[{"id":"1.232013794","rc":[{"batb":[[1,1.22,10.74],[2,1.06,164.67]],"ltp":1.06,"tv":5.0,"id":61077257},{"batb":[[0,1.7,30]],"ltp":1.06,"tv":16.98,"id":61077258}]}]}
{"op":"mcm","clk":"11917001739","pt":1724083913072,"mc":[{"id":"1.232013794","rc":[{"batb":[[0,1.26,32.96],[1,1.25,12.7],[2,1.22,10.74]],"ltp":1.06,"tv":5.0,"id":61077257},{"batb":[[0,1.71,12.07],[1,1.7,30],[2,1.06,149.69]],"ltp":1.06,"tv":16.98,"id":61077258}]}]}
{"op":"mcm","clk":"11917042421","pt":1724084208985,"mc":[{"id":"1.232013794","rc":[{"batb":[[0,1.71,19]],"ltp":1.06,"tv":16.98,"id":61077258}]}]}
{"op":"mcm","clk":"11917246327","pt":1724085713836,"mc":[{"id":"1.232013794","rc":[{"batb":[[0,1.25,12.7],[1,1.22,10.74],[2,1.06,164.67]],"ltp":1.06,"tv":5.0,"id":61077257},{"batb":[[0,1.71,6.92]],"ltp":1.06,"tv":16.98,"id":61077258}]}]}
{"op":"mcm","clk":"11917251428","pt":1724085755011,"mc":[{"id":"1.232013794","rc":[{"batb":[[0,1.26,32.96],[1,1.25,12.7],[2,1.22,10.74]],"ltp":1.06,"tv":5.0,"id":61077257},{"batb":[[0,1.72,11.9],[1,1.71,6.92],[2,1.7,30]],"ltp":1.06,"tv":16.98,"id":61077258}]}]}
{"op":"mcm","clk":"11917308097","pt":1724086187831,"mc":[{"id":"1.232013794","rc":[{"batb":[[1,1.22,10.74],[2,1.06,164.67]],"ltp":1.06,"tv":5.0,"id":61077257}]}]}
{"op":"mcm","clk":"11917308269","pt":1724086189231,"mc":[{"id":"1.232013794","rc":[{"batb":[[0,1.27,12.5],[1,1.26,32.96],[2,1.22,10.74]],"ltp":1.06,"tv":5.0,"id":61077257}]}]}
{"op":"mcm","clk":"11917482437","pt":1724087555566,"mc":[{"id":"1.232013794","rc":[{"batb":[[1,1.22,10.75],[2,1.06,164.67]],"ltp":1.06,"tv":5.0,"id":61077257},{"batb":[[0,1.71,6.92],[1,1.7,30],[2,1.06,149.69]],"ltp":1.06,"tv":16.98,"id":61077258}]}]}
{"op":"mcm","clk":"11917495364","pt":1724087575200,"mc":[{"id":"1.232013794","rc":[{"batb":[[0,1.28,30.62],[1,1.27,12.5],[2,1.22,10.75]],"ltp":1.06,"tv":5.0,"id":61077257}]}]}
{"op":"mcm","clk":"11917495375","pt":1724087575293,"mc":[{"id":"1.232013794","rc":[{"batb":[[0,1.72,11.91],[1,1.71,6.92],[2,1.7,30]],"ltp":1.06,"tv":16.98,"id":61077258}]}]}
{"op":"mcm","clk":"11917666681","pt":1724088753873,"mc":[{"id":"1.232013794","rc":[{"batb":[[1,1.22,10.75],[2,1.06,164.67]],"ltp":1.06,"tv":5.0,"id":61077257}]}]}
{"op":"mcm","clk":"11917666828","pt":1724088754965,"mc":[{"id":"1.232013794","rc":[{"batb":[[0,1.29,12.31],[1,1.28,30.62],[2,1.22,10.75]],"ltp":1.06,"tv":5.0,"id":61077257}]}]}
{"op":"mcm","clk":"11917759350","pt":1724089375826,"mc":[{"id":"1.232013794","rc":[{"batb":[[1,1.22,10.75],[2,1.06,164.67]],"ltp":1.06,"tv":5.0,"id":61077257},{"batb":[[0,1.71,6.92],[1,1.7,30],[2,1.06,149.69]],"ltp":1.06,"tv":16.98,"id":61077258}]}]}
{"op":"mcm","clk":"11917773481","pt":1724089463705,"mc":[{"id":"1.232013794","rc":[{"batb":[[0,1.7,30],[1,1.06,149.69],[2,1.05,200]],"ltp":1.06,"tv":16.98,"id":61077258}]}]}
{"op":"mcm","clk":"11917784884","pt":1724089536443,"mc":[{"id":"1.232013794","rc":[{"batb":[[0,1.3,28.58],[1,1.29,12.31],[2,1.22,10.75]],"ltp":1.06,"tv":5.0,"id":61077257},{"batb":[[0,1.71,12.07],[1,1.7,30],[2,1.06,149.69]],"ltp":1.06,"tv":16.98,"id":61077258}]}]}
{"op":"mcm","clk":"11917807126","pt":1724089679569,"mc":[{"id":"1.232013794","rc":[{"batb":[[1,1.22,10.75],[2,1.06,164.67]],"ltp":1.06,"tv":5.0,"id":61077257}]}]}
{"op":"mcm","clk":"11917808289","pt":1724089686538,"mc":[{"id":"1.232013794","rc":[{"batb":[[0,1.31,12.12],[1,1.3,28.58],[2,1.22,10.75]],"ltp":1.06,"tv":5.0,"id":61077257}]}]}
{"op":"mcm","clk":"11917977279","pt":1724090948812,"mc":[{"id":"1.232013794","rc":[{"batb":[[0,1.4,9.31],[1,1.31,12.12],[2,1.3,28.56]],"ltp":1.06,"tv":5.0,"id":61077257},{"batb":[[0,1.71,12.07]],"ltp":1.06,"tv":16.98,"id":61077258}]}]}
{"op":"mcm","clk":"11918034021","pt":1724091337071,"mc":[{"id":"1.232013794","rc":[{"batb":[[2,1.06,164.67]],"ltp":1.06,"tv":5.0,"id":61077257},{"batb":[[0,1.7,30],[1,1.06,149.69],[2,1.05,200]],"ltp":1.06,"tv":16.98,"id":61077258}]}]}
{"op":"mcm","clk":"11918054136","pt":1724091468072,"mc":[{"id":"1.232013794","rc":[{"batb":[[0,1.41,20.9],[1,1.4,9.31],[2,1.31,12.12]],"ltp":1.06,"tv":5.0,"id":61077257},{"batb":[[0,1.71,12.07],[1,1.7,30],[2,1.06,149.69]],"ltp":1.06,"tv":16.98,"id":61077258}]}]}
{"op":"mcm","clk":"11918152146","pt":1724092085556,"mc":[{"id":"1.232013794","rc":[{"batb":[[0,1.71,18.67]],"ltp":1.06,"tv":16.98,"id":61077258}]}]}
{"op":"mcm","clk":"11918193492","pt":1724092329472,"mc":[{"id":"1.232013794","rc":[{"batb":[[2,1.06,164.67]],"ltp":1.06,"tv":5.0,"id":61077257}]}]}
{"op":"mcm","clk":"11918193831","pt":1724092331475,"mc":[{"id":"1.232013794","rc":[{"batb":[[0,1.42,11.18],[1,1.41,20.9],[2,1.4,9.31]],"ltp":1.06,"tv":5.0,"id":61077257}]}]}
{"op":"mcm","clk":"11918360839","pt":1724093268684,"mc":[{"id":"1.232013794","rc":[{"batb":[[1,1.4,9.31],[2,1.06,164.67]],"ltp":1.06,"tv":5.0,"id":61077257},{"batb":[[0,1.71,6.61]],"ltp":1.06,"tv":16.98,"id":61077258}]}]}
{"op":"mcm","clk":"11918375563","pt":1724093362379,"mc":[{"id":"1.232013794","rc":[{"batb":[[0,1.43,19.93],[1,1.42,11.18],[2,1.4,9.31]],"ltp":1.06,"tv":5.0,"id":61077257},{"batb":[[0,1.72,11.9],[1,1.71,6.61],[2,1.7,30]],"ltp":1.06,"tv":16.98,"id":61077258}]}]}
{"op":"mcm","clk":"11918618571","pt":1724095162968,"mc":[{"id":"1.232013794","rc":[{"batb":[[0,1.42,11.18],[1,1.4,9.31],[2,1.06,164.67]],"ltp":1.06,"tv":5.0,"id":61077257},{"batb":[[0,1.71,6.6],[1,1.7,30],[2,1.06,149.69]],"ltp":1.06,"tv":16.98,"id":61077258}]}]}
{"op":"mcm","clk":"11918621604","pt":1724095184694,"mc":[{"id":"1.232013794","rc":[{"batl":[[0,1.8,30],[1,2.5,30]],"ltp":1.06,"tv":5.0,"id":61077257}]}]}
{"op":"mcm","clk":"11918730422","pt":1724095941644,"mc":[{"id":"1.232013794","rc":[{"batb":[[0,1.43,6.98],[1,1.42,11.18]],"ltp":1.06,"tv":5.0,"id":61077257}]}]}
{"op":"mcm","clk":"11918732605","pt":1724095955552,"mc":[{"id":"1.232013794","rc":[{"batb":[[0,1.42,11.18],[1,1.06,164.67],[2,1.05,200]],"ltp":1.06,"tv":5.0,"id":61077257}]}]}
{"op":"mcm","clk":"11918740718","pt":1724096009867,"mc":[{"id":"1.232013794","rc":[{"batl":[[0,1.75,7.16],[1,1.8,30],[2,2.5,30]],"ltp":1.06,"tv":5.0,"id":61077257}]}]}
{"op":"mcm","clk":"11918742859","pt":1724096023520,"mc":[{"id":"1.232013794","rc":[{"trd":[[1.42,22.36]],"batb":[[0,1.06,164.67],[1,1.05,200],[2,1.04,251.53]],"batl":[[0,1.75,7.98]],"ltp":1.42,"tv":27.36,"id":61077257}],"tv":44.34}]}
{"op":"mcm","clk":"11918744002","pt":1724096030719,"mc":[{"id":"1.232013794","rc":[{"batl":[[0,1.75,7.16]],"ltp":1.42,"tv":27.36,"id":61077257}]}]}
{"op":"mcm","clk":"11918745975","pt":1724096043335,"mc":[{"id":"1.232013794","rc":[{"batl":[[2,2.5,0]],"ltp":1.42,"tv":27.36,"id":61077257}]}]}
{"op":"mcm","clk":"11918746253","pt":1724096045329,"mc":[{"id":"1.232013794","rc":[{"batl":[[1,1.8,0]],"ltp":1.42,"tv":27.36,"id":61077257}]}]}
{"op":"mcm","clk":"11918750826","pt":1724096080258,"mc":[{"id":"1.232013794","rc":[{"batb":[[0,1.1,12],[1,1.06,164.67],[2,1.05,200]],"ltp":1.42,"tv":27.36,"id":61077257}]}]}
{"op":"mcm","clk":"11918753779","pt":1724096103752,"mc":[{"id":"1.232013794","rc":[{"batb":[[1,1.06,149.69],[2,1.05,200]],"ltp":1.06,"tv":16.98,"id":61077258}]}]}
{"op":"mcm","clk":"11918757299","pt":1724096131112,"mc":[{"id":"1.232013794","rc":[{"batl":[[1,1.8,30]],"ltp":1.42,"tv":27.36,"id":61077257}]}]}
{"op":"mcm","clk":"11918759472","pt":1724096147215,"mc":[{"id":"1.232013794","rc":[{"batb":[[0,1.11,77.93],[1,1.1,12],[2,1.06,164.67]],"ltp":1.42,"tv":27.36,"id":61077257},{"batb":[[0,2.34,6.4],[1,1.71,6.6],[2,1.06,149.69]],"ltp":1.06,"tv":16.98,"id":61077258}]}]}
{"op":"mcm","clk":"11918804013","pt":1724096475138,"mc":[{"id":"1.232013794","rc":[{"batl":[[1,1.8,0]],"ltp":1.42,"tv":27.36,"id":61077257}]}]}
{"op":"mcm","clk":"11918804028","pt":1724096475241,"mc":[{"id":"1.232013794","rc":[{"batl":[[0,1.7,30],[1,1.75,7.16]],"ltp":1.42,"tv":27.36,"id":61077257}]}]}
{"op":"mcm","clk":"11918882670","pt":1724097026328,"mc":[{"id":"1.232013794","rc":[{"batl":[[0,1.69,15],[1,1.7,30],[2,1.75,7.16]],"ltp":1.42,"tv":27.36,"id":61077257}]}]}
{"op":"mcm","clk":"11918885364","pt":1724097048454,"mc":[{"id":"1.232013794","rc":[{"batb":[[1,1.06,149.69],[2,1.05,200]],"ltp":1.06,"tv":16.98,"id":61077258}]}]}
{"op":"mcm","clk":"11918984801","pt":1724097947605,"mc":[{"id":"1.232013794","rc":[{"batb":[[0,1.1,12],[1,1.06,164.67],[2,1.05,200]],"batl":[[2,1.75,7.16]],"ltp":1.42,"tv":27.36,"id":61077257},{"batb":[[0,1.06,149.69],[1,1.05,200],[2,1.04,251.53]],"ltp":1.06,"tv":16.98,"id":61077258}]}]}
{"op":"mcm","clk":"11918992260","pt":1724098042848,"mc":[{"id":"1.232013794","rc":[{"batb":[[0,1.11,77.96],[1,1.1,12],[2,1.06,164.67]],"ltp":1.42,"tv":27.36,"id":61077257},{"batb":[[0,2.46,5.87],[1,1.06,149.69],[2,1.05,200]],"ltp":1.06,"tv":16.98,"id":61077258}]}]}
{"op":"mcm","clk":"11919159914","pt":1724099843117,"mc":[{"id":"1.232013794","rc":[{"batb":[[0,1.1,12],[1,1.06,164.67],[2,1.05,200]],"ltp":1.42,"tv":27.36,"id":61077257}]}]}
{"op":"mcm","clk":"11919159936","pt":1724099843323,"mc":[{"id":"1.232013794","rc":[{"batb":[[0,1.06,149.69],[1,1.05,200],[2,1.04,251.53]],"ltp":1.06,"tv":16.98,"id":61077258}]}]}
{"op":"mcm","clk":"11919163171","pt":1724099882861,"mc":[{"id":"1.232013794","rc":[{"batb":[[0,1.11,77.96],[1,1.1,12],[2,1.06,164.67]],"ltp":1.42,"tv":27.36,"id":61077257},{"batb":[[0,2.46,5.87],[1,1.06,149.69],[2,1.05,200]],"ltp":1.06,"tv":16.98,"id":61077258}]}]}
{"op":"mcm","clk":"11919211625","pt":1724100534811,"mc":[{"id":"1.232013794","rc":[{"batl":[[0,1.69,20]],"ltp":1.42,"tv":27.36,"id":61077257}]}]}
{"op":"mcm","clk":"11919279110","pt":1724101683212,"mc":[{"id":"1.232013794","rc":[{"batb":[[0,1.1,12],[1,1.06,164.67],[2,1.05,200]],"batl":[[2,1.75,7.16]],"ltp":1.42,"tv":27.36,"id":61077257}]}]}
{"op":"mcm","clk":"11919279122","pt":1724101683417,"mc":[{"id":"1.232013794","rc":[{"batb":[[0,1.06,149.69],[1,1.05,200],[2,1.04,251.53]],"ltp":1.06,"tv":16.98,"id":61077258}]}]}
{"op":"mcm","clk":"11919279399","pt":1724101688494,"mc":[{"id":"1.232013794","rc":[{"batb":[[0,1.11,77.96],[1,1.1,12],[2,1.06,164.67]],"ltp":1.42,"tv":27.36,"id":61077257},{"batb":[[0,2.46,5.87],[1,1.06,149.69],[2,1.05,200]],"ltp":1.06,"tv":16.98,"id":61077258}]}]}
{"op":"mcm","clk":"11919351512","pt":1724103488840,"mc":[{"id":"1.232013794","rc":[{"batb":[[0,1.1,12],[1,1.06,164.67],[2,1.05,200]],"ltp":1.42,"tv":27.36,"id":61077257},{"batb":[[0,1.06,149.69],[1,1.05,200],[2,1.04,251.53]],"ltp":1.06,"tv":16.98,"id":61077258}]}]}
{"op":"mcm","clk":"11919356184","pt":1724103616185,"mc":[{"id":"1.232013794","rc":[{"batb":[[0,1.11,77.96],[1,1.1,12],[2,1.06,164.67]],"ltp":1.42,"tv":27.36,"id":61077257},{"batb":[[0,2.46,5.87],[1,1.06,149.69],[2,1.05,200]],"ltp":1.06,"tv":16.98,"id":61077258}]}]}
{"op":"mcm","clk":"11919435848","pt":1724105416600,"mc":[{"id":"1.232013794","rc":[{"batb":[[0,1.1,12],[1,1.06,164.67],[2,1.05,200]],"ltp":1.42,"tv":27.36,"id":61077257},{"batb":[[0,1.06,149.69],[1,1.05,200],[2,1.04,251.53]],"ltp":1.06,"tv":16.98,"id":61077258}]}]}
{"op":"mcm","clk":"11919440636","pt":1724105519342,"mc":[{"id":"1.232013794","rc":[{"batb":[[0,1.11,77.97],[1,1.1,12],[2,1.06,164.67]],"ltp":1.42,"tv":27.36,"id":61077257},{"batb":[[0,2.46,5.87],[1,1.06,149.69],[2,1.05,200]],"ltp":1.06,"tv":16.98,"id":61077258}]}]}
{"op":"mcm","clk":"11919532019","pt":1724107319789,"mc":[{"id":"1.232013794","rc":[{"batb":[[0,1.1,12],[1,1.06,164.67],[2,1.05,200]],"ltp":1.42,"tv":27.36,"id":61077257},{"batb":[[0,1.06,149.69],[1,1.05,200],[2,1.04,251.53]],"ltp":1.06,"tv":16.98,"id":61077258}]}]}
{"op":"mcm","clk":"11919537276","pt":1724107406275,"mc":[{"id":"1.232013794","rc":[{"batb":[[0,1.11,77.97],[1,1.1,12],[2,1.06,164.67]],"ltp":1.42,"tv":27.36,"id":61077257},{"batb":[[0,2.46,5.87],[1,1.06,149.69],[2,1.05,200]],"ltp":1.06,"tv":16.98,"id":61077258}]}]}
{"op":"mcm","clk":"11919634797","pt":1724109175014,"mc":[{"id":"1.232013794","rc":[{"batb":[[0,1.11,77.97]],"ltp":1.42,"tv":27.36,"id":61077257}]}]}
{"op":"mcm","clk":"11919638128","pt":1724109206738,"mc":[{"id":"1.232013794","rc":[{"batb":[[0,1.1,12],[1,1.06,164.67],[2,1.05,200]],"ltp":1.42,"tv":27.36,"id":61077257},{"batb":[[0,1.06,149.69],[1,1.05,200],[2,1.04,251.53]],"ltp":1.06,"tv":16.98,"id":61077258}]}]}
{"op":"mcm","clk":"11919642276","pt":1724109281766,"mc":[{"id":"1.232013794","rc":[{"batb":[[0,1.11,77.97],[1,1.1,12],[2,1.06,164.67]],"ltp":1.42,"tv":27.36,"id":61077257},{"batb":[[0,2.46,5.87],[1,1.06,149.69],[2,1.05,200]],"ltp":1.06,"tv":16.98,"id":61077258}]}]}
{"op":"mcm","clk":"11919735007","pt":1724111082179,"mc":[{"id":"1.232013794","rc":[{"batb":[[0,1.1,12],[1,1.06,164.67],[2,1.05,200]],"ltp":1.42,"tv":27.36,"id":61077257},{"batb":[[0,1.06,149.69],[1,1.05,200],[2,1.04,251.53]],"ltp":1.06,"tv":16.98,"id":61077258}]}]}
{"op":"mcm","clk":"11919738245","pt":1724111143549,"mc":[{"id":"1.232013794","rc":[{"batb":[[0,1.11,77.97],[1,1.1,12],[2,1.06,164.67]],"ltp":1.42,"tv":27.36,"id":61077257},{"batb":[[0,2.46,5.87],[1,1.06,149.69],[2,1.05,200]],"ltp":1.06,"tv":16.98,"id":61077258}]}]}
{"op":"mcm","clk":"11919839978","pt":1724112944062,"mc":[{"id":"1.232013794","rc":[{"batb":[[0,1.1,12],[1,1.06,164.67],[2,1.05,200]],"batl":[[2,1.75,7.16]],"ltp":1.42,"tv":27.36,"id":61077257},{"batb":[[0,1.06,149.69],[1,1.05,200],[2,1.04,251.53]],"ltp":1.06,"tv":16.98,"id":61077258}]}]}
{"op":"mcm","clk":"11919841974","pt":1724112980187,"mc":[{"id":"1.232013794","rc":[{"batb":[[0,1.11,77.98],[1,1.1,12],[2,1.06,164.67]],"ltp":1.42,"tv":27.36,"id":61077257},{"batb":[[0,2.46,5.88],[1,1.06,149.69],[2,1.05,200]],"ltp":1.06,"tv":16.98,"id":61077258}]}]}
{"op":"mcm","clk":"11919937731","pt":1724114780614,"mc":[{"id":"1.232013794","rc":[{"batb":[[0,1.1,12],[1,1.06,164.67],[2,1.05,200]],"ltp":1.42,"tv":27.36,"id":61077257},{"batb":[[0,1.06,149.69],[1,1.05,200],[2,1.04,251.53]],"ltp":1.06,"tv":16.98,"id":61077258}]}]}
{"op":"mcm","clk":"11919938318","pt":1724114793887,"mc":[{"id":"1.232013794","rc":[{"batb":[[0,1.11,77.98],[1,1.1,12],[2,1.06,164.67]],"ltp":1.42,"tv":27.36,"id":61077257},{"batb":[[0,2.46,5.88],[1,1.06,149.69],[2,1.05,200]],"ltp":1.06,"tv":16.98,"id":61077258}]}]}
{"op":"mcm","clk":"11920023090","pt":1724116594107,"mc":[{"id":"1.232013794","rc":[{"batb":[[0,1.1,12],[1,1.06,164.67],[2,1.05,200]],"ltp":1.42,"tv":27.36,"id":61077257}]}]}
{"op":"mcm","clk":"11920023097","pt":1724116594310,"mc":[{"id":"1.232013794","rc":[{"batb":[[0,1.06,149.69],[1,1.05,200],[2,1.04,251.53]],"ltp":1.06,"tv":16.98,"id":61077258}]}]}
{"op":"mcm","clk":"11920029351","pt":1724116728589,"mc":[{"id":"1.232013794","rc":[{"batb":[[0,1.11,77.98],[1,1.1,12],[2,1.06,164.67]],"ltp":1.42,"tv":27.36,"id":61077257},{"batb":[[0,2.46,5.88],[1,1.06,149.69],[2,1.05,200]],"ltp":1.06,"tv":16.98,"id":61077258}]}]}
{"op":"mcm","clk":"11920118903","pt":1724118528964,"mc":[{"id":"1.232013794","rc":[{"batb":[[0,1.1,12],[1,1.06,164.67],[2,1.05,200]],"ltp":1.42,"tv":27.36,"id":61077257},{"batb":[[0,1.06,149.69],[1,1.05,200],[2,1.04,251.53]],"ltp":1.06,"tv":16.98,"id":61077258}]}]}
{"op":"mcm","clk":"11920123488","pt":1724118619346,"mc":[{"id":"1.232013794","rc":[{"batb":[[0,1.11,77.98],[1,1.1,12],[2,1.06,164.67]],"ltp":1.42,"tv":27.36,"id":61077257},{"batb":[[0,2.46,5.88],[1,1.06,149.69],[2,1.05,200]],"ltp":1.06,"tv":16.98,"id":61077258}]}]}
{"op":"mcm","clk":"11920196004","pt":1724119975078,"mc":[{"id":"1.232013794","rc":[{"batb":[[0,1.11,78]],"batl":[[2,1.75,7.17]],"ltp":1.42,"tv":27.36,"id":61077257},{"batb":[[0,2.46,5.88]],"ltp":1.06,"tv":16.98,"id":61077258}]}]}
{"op":"mcm","clk":"11920215651","pt":1724120419778,"mc":[{"id":"1.232013794","rc":[{"batb":[[0,1.1,12],[1,1.06,164.67],[2,1.05,200]],"ltp":1.42,"tv":27.36,"id":61077257},{"batb":[[0,1.06,149.69],[1,1.05,200],[2,1.04,251.53]],"ltp":1.06,"tv":16.98,"id":61077258}]}]}
{"op":"mcm","clk":"11920218509","pt":1724120484260,"mc":[{"id":"1.232013794","rc":[{"batb":[[0,1.11,78],[1,1.1,12],[2,1.06,164.67]],"ltp":1.42,"tv":27.36,"id":61077257},{"batb":[[0,2.46,5.88],[1,1.06,149.69],[2,1.05,200]],"ltp":1.06,"tv":16.98,"id":61077258}]}]}
{"op":"mcm","clk":"11920331018","pt":1724123622520,"mc":[{"id":"1.232013794","rc":[{"batb":[[0,1.1,12],[1,1.06,164.67],[2,1.05,200]],"ltp":1.42,"tv":27.36,"id":61077257},{"batb":[[0,1.06,149.69],[1,1.05,200],[2,1.04,251.53]],"ltp":1.06,"tv":16.98,"id":61077258}]}]}
{"op":"mcm","clk":"11920333620","pt":1724123709949,"mc":[{"id":"1.232013794","rc":[{"batb":[[0,1.11,77.97],[1,1.1,12],[2,1.06,164.67]],"ltp":1.42,"tv":27.36,"id":61077257},{"batb":[[0,2.46,5.87],[1,1.06,149.69],[2,1.05,200]],"ltp":1.06,"tv":16.98,"id":61077258}]}]}
{"op":"mcm","clk":"11920338368","pt":1724123864398,"mc":[{"id":"1.232013794","rc":[{"batl":[[0,9.8,0.31]],"ltp":1.06,"tv":16.98,"id":61077258}]}]}
{"op":"mcm","clk":"11920393767","pt":1724125510573,"mc":[{"id":"1.232013794","rc":[{"batb":[[0,1.1,12],[1,1.06,164.67],[2,1.05,200]],"ltp":1.42,"tv":27.36,"id":61077257},{"batb":[[0,1.06,149.69],[1,1.05,200],[2,1.04,251.53]],"ltp":1.06,"tv":16.98,"id":61077258}]}]}
{"op":"mcm","clk":"11920394195","pt":1724125527285,"mc":[{"id":"1.232013794","rc":[{"batb":[[0,1.12,71.47],[1,1.1,12],[2,1.06,164.67]],"ltp":1.42,"tv":27.36,"id":61077257},{"batb":[[0,2.46,5.87],[1,1.06,149.69],[2,1.05,200]],"ltp":1.06,"tv":16.98,"id":61077258}]}]}
{"op":"mcm","clk":"11920450547","pt":1724127327984,"mc":[{"id":"1.232013794","rc":[{"batb":[[0,1.1,12],[1,1.06,164.67],[2,1.05,200]],"ltp":1.42,"tv":27.36,"id":61077257},{"batb":[[0,1.06,149.69],[1,1.05,200],[2,1.04,251.53]],"ltp":1.06,"tv":16.98,"id":61077258}]}]}
{"op":"mcm","clk":"11920450726","pt":1724127333608,"mc":[{"id":"1.232013794","rc":[{"batb":[[0,1.12,71.48],[1,1.1,12],[2,1.06,164.67]],"ltp":1.42,"tv":27.36,"id":61077257},{"batb":[[0,2.46,5.87],[1,1.06,149.69],[2,1.05,200]],"ltp":1.06,"tv":16.98,"id":61077258}]}]}
{"op":"mcm","clk":"11920510269","pt":1724129134223,"mc":[{"id":"1.232013794","rc":[{"batb":[[0,1.1,12],[1,1.06,164.67],[2,1.05,200]],"ltp":1.42,"tv":27.36,"id":61077257},{"batb":[[0,1.06,149.69],[1,1.05,200],[2,1.04,251.53]],"ltp":1.06,"tv":16.98,"id":61077258}]}]}
{"op":"mcm","clk":"11920514026","pt":1724129256736,"mc":[{"id":"1.232013794","rc":[{"batb":[[0,1.12,71.48],[1,1.1,12],[2,1.06,164.67]],"ltp":1.42,"tv":27.36,"id":61077257},{"batb":[[0,2.46,5.87],[1,1.06,149.69],[2,1.05,200]],"ltp":1.06,"tv":16.98,"id":61077258}]}]}
{"op":"mcm","clk":"11920579521","pt":1724130775030,"mc":[{"id":"1.232013794","rc":[{"batl":[[2,1.75,7.17]],"ltp":1.42,"tv":27.36,"id":61077257}]}]}
{"op":"mcm","clk":"11920592425","pt":1724131057218,"mc":[{"id":"1.232013794","rc":[{"batb":[[0,1.1,12],[1,1.06,164.67],[2,1.05,200]],"ltp":1.42,"tv":27.36,"id":61077257}]}]}
{"op":"mcm","clk":"11920592434","pt":1724131057428,"mc":[{"id":"1.232013794","rc":[{"batb":[[0,1.06,149.69],[1,1.05,200],[2,1.04,251.53]],"ltp":1.06,"tv":16.98,"id":61077258}]}]}
{"op":"mcm","clk":"11920594244","pt":1724131123602,"mc":[{"id":"1.232013794","rc":[{"batb":[[0,1.12,71.48],[1,1.1,12],[2,1.06,164.67]],"ltp":1.42,"tv":27.36,"id":61077257},{"batb":[[0,2.46,5.87],[1,1.06,149.69],[2,1.05,200]],"ltp":1.06,"tv":16.98,"id":61077258}]}]}
{"op":"mcm","clk":"11920594309","pt":1724131125874,"mc":[{"id":"1.232013794","rc":[{"batb":[[0,1.12,74.94]],"ltp":1.42,"tv":27.36,"id":61077257}]}]}
{"op":"mcm","clk":"11920657379","pt":1724132924227,"mc":[{"id":"1.232013794","rc":[{"batb":[[0,1.12,3.46]],"ltp":1.42,"tv":27.36,"id":61077257},{"batb":[[0,1.06,149.69],[1,1.05,200],[2,1.04,251.53]],"ltp":1.06,"tv":16.98,"id":61077258}]}]}
{"op":"mcm","clk":"11920660408","pt":1724132990571,"mc":[{"id":"1.232013794","rc":[{"batb":[[0,1.13,65.98],[1,1.12,3.46],[2,1.1,12]],"ltp":1.42,"tv":27.36,"id":61077257},{"batb":[[0,2.46,5.87],[1,1.06,149.69],[2,1.05,200]],"ltp":1.06,"tv":16.98,"id":61077258}]}]}
{"op":"mcm","clk":"11920715761","pt":1724134791078,"mc":[{"id":"1.232013794","rc":[{"batb":[[0,1.13,65.97]],"ltp":1.42,"tv":27.36,"id":61077257},{"batb":[[0,1.06,149.69],[1,1.05,200],[2,1.04,251.53]],"ltp":1.06,"tv":16.98,"id":61077258}]}]}
{"op":"mcm","clk":"11920715764","pt":1724134791282,"mc":[{"id":"1.232013794","rc":[{"batb":[[0,1.12,3.46],[1,1.1,12],[2,1.06,164.67]],"ltp":1.42,"tv":27.36,"id":61077257}]}]}
{"op":"mcm","clk":"11920717244","pt":1724134856145,"mc":[{"id":"1.232013794","rc":[{"batb":[[0,1.13,65.97],[1,1.12,3.46],[2,1.1,12]],"ltp":1.42,"tv":27.36,"id":61077257},{"batb":[[0,2.46,5.87],[1,1.06,149.69],[2,1.05,200]],"ltp":1.06,"tv":16.98,"id":61077258}]}]}
{"op":"mcm","clk":"11920781673","pt":1724136656672,"mc":[{"id":"1.232013794","rc":[{"batb":[[0,1.12,3.46],[1,1.1,12],[2,1.06,164.67]],"ltp":1.42,"tv":27.36,"id":61077257},{"batb":[[0,1.06,149.69],[1,1.05,200],[2,1.04,251.53]],"ltp":1.06,"tv":16.98,"id":61077258}]}]}
{"op":"mcm","clk":"11920783716","pt":1724136720343,"mc":[{"id":"1.232013794","rc":[{"batb":[[0,1.13,65.97],[1,1.12,3.46],[2,1.1,12]],"ltp":1.42,"tv":27.36,"id":61077257},{"batb":[[0,2.46,5.87],[1,1.06,149.69],[2,1.05,200]],"ltp":1.06,"tv":16.98,"id":61077258}]}]}
{"op":"mcm","clk":"11920844762","pt":1724138521058,"mc":[{"id":"1.232013794","rc":[{"batb":[[0,1.12,3.46],[1,1.1,12],[2,1.06,164.67]],"batl":[[2,1.75,7.16]],"ltp":1.42,"tv":27.36,"id":61077257},{"batb":[[0,1.06,149.69],[1,1.05,200],[2,1.04,251.53]],"ltp":1.06,"tv":16.98,"id":61077258}]}]}
{"op":"mcm","clk":"11920846561","pt":1724138583844,"mc":[{"id":"1.232013794","rc":[{"batb":[[0,1.13,65.93],[1,1.12,3.46],[2,1.1,12]],"ltp":1.42,"tv":27.36,"id":61077257},{"batb":[[0,2.46,5.87],[1,1.06,149.69],[2,1.05,200]],"ltp":1.06,"tv":16.98,"id":61077258}]}]}
{"op":"mcm","clk":"11920879120","pt":1724139669921,"mc":[{"id":"1.232013794","rc":[{"batl":[[0,1.68,30],[1,1.69,20]],"ltp":1.42,"tv":27.36,"id":61077257}]}]}
{"op":"mcm","clk":"11920879760","pt":1724139693932,"mc":[{"id":"1.232013794","rc":[{"batb":[[0,1.14,12],[1,1.13,65.93],[2,1.12,3.46]],"ltp":1.42,"tv":27.36,"id":61077257}]}]}
{"op":"mcm","clk":"11920900659","pt":1724140384147,"mc":[{"id":"1.232013794","rc":[{"batb":[[1,1.12,3.46],[2,1.06,164.67]],"ltp":1.42,"tv":27.36,"id":61077257},{"batb":[[0,1.06,149.69],[1,1.05,200],[2,1.04,251.53]],"ltp":1.06,"tv":16.98,"id":61077258}]}]}
{"op":"mcm","clk":"11920902824","pt":1724140446110,"mc":[{"id":"1.232013794","rc":[{"batb":[[0,1.15,57.14],[1,1.14,12],[2,1.12,3.46]],"ltp":1.42,"tv":27.36,"id":61077257},{"batb":[[0,2.48,5.79],[1,1.06,149.69],[2,1.05,200]],"ltp":1.06,"tv":16.98,"id":61077258}]}]}
{"op":"mcm","clk":"11920943243","pt":1724141575074,"mc":[{"id":"1.232013794","rc":[{"batb":[[0,1.15,57.13],[2,1.12,3.46]],"batl":[[2,1.75,7.15]],"ltp":1.42,"tv":27.36,"id":61077257}]}]}
{"op":"mcm","clk":"11920964130","pt":1724142246791,"mc":[{"id":"1.232013794","rc":[{"batb":[[0,1.14,12],[1,1.12,3.46],[2,1.06,164.67]],"ltp":1.42,"tv":27.36,"id":61077257},{"batb":[[0,1.06,149.69],[1,1.05,200],[2,1.04,251.53]],"ltp":1.06,"tv":16.98,"id":61077258}]}]}
{"op":"mcm","clk":"11920968016","pt":1724142371212,"mc":[{"id":"1.232013794","rc":[{"batb":[[0,1.15,57.13],[1,1.14,12],[2,1.12,3.46]],"ltp":1.42,"tv":27.36,"id":61077257},{"batb":[[0,2.48,5.79],[1,1.06,149.69],[2,1.05,200]],"ltp":1.06,"tv":16.98,"id":61077258}]}]}
{"op":"mcm","clk":"11921031005","pt":1724144171815,"mc":[{"id":"1.232013794","rc":[{"batb":[[0,1.14,12],[1,1.12,3.46],[2,1.06,164.67]],"ltp":1.42,"tv":27.36,"id":61077257},{"batb":[[0,1.06,149.69],[1,1.05,200],[2,1.04,251.53]],"ltp":1.06,"tv":16.98,"id":61077258}]}]}
{"op":"mcm","clk":"11921032602","pt":1724144214862,"mc":[{"id":"1.232013794","rc":[{"batb":[[0,1.15,57.13],[1,1.14,12],[2,1.12,3.46]],"ltp":1.42,"tv":27.36,"id":61077257},{"batb":[[0,2.48,5.79],[1,1.06,149.69],[2,1.05,200]],"ltp":1.06,"tv":16.98,"id":61077258}]}]}
{"op":"mcm","clk":"11921034304","pt":1724144263008,"mc":[{"id":"1.232013794","rc":[{"batb":[[2,1.06,164.67]],"ltp":1.42,"tv":27.36,"id":61077257}]}]}
{"op":"mcm","clk":"11921036456","pt":1724144346181,"mc":[{"id":"1.232013794","rc":[{"batl":[[0,1.67,20],[1,1.68,30]],"ltp":1.42,"tv":27.36,"id":61077257}]}]}
{"op":"mcm","clk":"11921095903","pt":1724146015445,"mc":[{"id":"1.232013794","rc":[{"batb":[[0,1.14,12],[1,1.06,164.67],[2,1.05,200]],"batl":[[2,1.75,7.16]],"ltp":1.42,"tv":27.36,"id":61077257},{"batb":[[0,1.06,149.69],[1,1.05,200],[2,1.04,251.53]],"ltp":1.06,"tv":16.98,"id":61077258}]}]}
{"op":"mcm","clk":"11921097491","pt":1724146052082,"mc":[{"id":"1.232013794","rc":[{"batb":[[0,1.15,57.11],[1,1.14,12],[2,1.06,164.67]],"ltp":1.42,"tv":27.36,"id":61077257},{"batb":[[0,2.5,5.71],[1,1.06,149.69],[2,1.05,200]],"ltp":1.06,"tv":16.98,"id":61077258}]}]}
{"op":"mcm","clk":"11921179402","pt":1724147776974,"mc":[{"id":"1.232013794","rc":[{"batl":[[0,1.66,30],[1,1.67,20]],"ltp":1.42,"tv":27.36,"id":61077257}]}]}
{"op":"mcm","clk":"11921180194","pt":1724147795613,"mc":[{"id":"1.232013794","rc":[{"batb":[[0,1.16,12],[1,1.15,57.11]],"ltp":1.42,"tv":27.36,"id":61077257}]}]}
{"op":"mcm","clk":"11921182770","pt":1724147852972,"mc":[{"id":"1.232013794","rc":[{"batb":[[1,1.06,164.67],[2,1.05,200]],"ltp":1.42,"tv":27.36,"id":61077257},{"batb":[[0,1.06,149.69],[1,1.05,200],[2,1.04,251.53]],"ltp":1.06,"tv":16.98,"id":61077258}]}]}
{"op":"mcm","clk":"11921184149","pt":1724147885105,"mc":[{"id":"1.232013794","rc":[{"batb":[[0,1.17,50.39],[1,1.16,12],[2,1.06,164.67]],"ltp":1.42,"tv":27.36,"id":61077257},{"batb":[[0,2.52,5.64],[1,1.06,149.69],[2,1.05,200]],"ltp":1.06,"tv":16.98,"id":61077258}]}]}
{"op":"mcm","clk":"11921191742","pt":1724148080912,"mc":[{"id":"1.232013794","rc":[{"batb":[[0,1.17,50.36]],"batl":[[2,1.75,7.15]],"ltp":1.42,"tv":27.36,"id":61077257},{"batb":[[0,2.52,5.63]],"ltp":1.06,"tv":16.98,"id":61077258}]}]}
{"op":"mcm","clk":"11921220494","pt":1724148685504,"mc":[{"id":"1.232013794","rc":[{"batb":[[0,1.18,4.47],[1,1.17,50.36],[2,1.16,12]],"ltp":1.42,"tv":27.36,"id":61077257}]}]}
{"op":"mcm","clk":"11921251860","pt":1724149312877,"mc":[{"id":"1.232013794","rc":[{"batb":[[0,1.17,50.36],[1,1.16,12],[2,1.06,164.67]],"ltp":1.42,"tv":27.36,"id":61077257}]}]}
{"op":"mcm","clk":"11921268323","pt":1724149685608,"mc":[{"id":"1.232013794","rc":[{"batb":[[0,1.16,12],[1,1.06,164.67],[2,1.05,200]],"ltp":1.42,"tv":27.36,"id":61077257},{"batb":[[0,1.06,149.69],[1,1.05,200],[2,1.04,251.53]],"ltp":1.06,"tv":16.98,"id":61077258}]}]}
{"op":"mcm","clk":"11921269582","pt":1724149717133,"mc":[{"id":"1.232013794","rc":[{"batb":[[0,1.17,50.36],[1,1.16,12],[2,1.06,164.67]],"ltp":1.42,"tv":27.36,"id":61077257},{"batb":[[0,2.52,5.63],[1,1.06,149.69],[2,1.05,200]],"ltp":1.06,"tv":16.98,"id":61077258}]}]}
{"op":"mcm","clk":"11921346419","pt":1724151517730,"mc":[{"id":"1.232013794","rc":[{"batb":[[0,1.16,12],[1,1.06,164.67],[2,1.05,200]],"ltp":1.42,"tv":27.36,"id":61077257},{"batb":[[0,1.06,149.69],[1,1.05,200],[2,1.04,251.53]],"ltp":1.06,"tv":16.98,"id":61077258}]}]}
{"op":"mcm","clk":"11921347122","pt":1724151533754,"mc":[{"id":"1.232013794","rc":[{"batb":[[0,1.17,50.36],[1,1.16,12],[2,1.06,164.67]],"ltp":1.42,"tv":27.36,"id":61077257},{"batb":[[0,2.52,5.63],[1,1.06,149.69],[2,1.05,200]],"ltp":1.06,"tv":16.98,"id":61077258}]}]}
{"op":"mcm","clk":"11921391120","pt":1724152375014,"mc":[{"id":"1.232013794","rc":[{"batb":[[0,1.17,50.38]],"batl":[[2,1.75,7.15]],"ltp":1.42,"tv":27.36,"id":61077257},{"batb":[[0,2.52,5.63]],"ltp":1.06,"tv":16.98,"id":61077258}]}]}
{"op":"mcm","clk":"11921435203","pt":1724153334068,"mc":[{"id":"1.232013794","rc":[{"batb":[[0,1.06,149.69],[1,1.05,200],[2,1.04,251.53]],"ltp":1.06,"tv":16.98,"id":61077258}]}]}
{"op":"mcm","clk":"11921435218","pt":1724153334379,"mc":[{"id":"1.232013794","rc":[{"batb":[[0,1.16,12],[1,1.06,164.67],[2,1.05,200]],"ltp":1.42,"tv":27.36,"id":61077257}]}]}
{"op":"mcm","clk":"11921435414","pt":1724153337663,"mc":[{"id":"1.232013794","rc":[{"batb":[[0,1.17,50.38],[1,1.16,12],[2,1.06,164.67]],"ltp":1.42,"tv":27.36,"id":61077257},{"batb":[[0,2.52,5.63],[1,1.06,149.69],[2,1.05,200]],"ltp":1.06,"tv":16.98,"id":61077258}]}]}
{"op":"mcm","clk":"11921450499","pt":1724153650380,"mc":[{"id":"1.232013794","rc":[{"batl":[[0,1.4,1],[1,1.66,30],[2,1.67,20]],"ltp":1.42,"tv":27.36,"id":61077257}]}]}
{"op":"mcm","clk":"11921501661","pt":1724154871571,"mc":[{"id":"1.232013794","rc":[{"batl":[[0,1.4,6],[2,1.67,15]],"ltp":1.42,"tv":27.36,"id":61077257}]}]}
{"op":"mcm","clk":"11921502058","pt":1724154878866,"mc":[{"id":"1.232013794","rc":[{"batl":[[0,1.39,5],[1,1.4,1],[2,1.66,30]],"ltp":1.42,"tv":27.36,"id":61077257}]}]}
{"op":"mcm","clk":"11921514349","pt":1724155138129,"mc":[{"id":"1.232013794","rc":[{"batb":[[0,1.16,12],[1,1.06,164.67],[2,1.05,200]],"ltp":1.42,"tv":27.36,"id":61077257},{"batb":[[0,1.06,149.69],[1,1.05,200],[2,1.04,251.53]],"ltp":1.06,"tv":16.98,"id":61077258}]}]}
{"op":"mcm","clk":"11921517373","pt":1724155209304,"mc":[{"id":"1.232013794","rc":[{"trd":[[1.16,24]],"batb":[[0,1.06,164.67],[1,1.05,200],[2,1.04,251.53]],"ltp":1.16,"tv":51.36,"id":61077257}],"tv":68.34}]}
{"op":"mcm","clk":"11921518933","pt":1724155240313,"mc":[{"id":"1.232013794","rc":[{"batl":[[0,1.35,20],[1,1.39,5],[2,1.4,1]],"ltp":1.16,"tv":51.36,"id":61077257}]}]}
{"op":"mcm","clk":"11921519323","pt":1724155248340,"mc":[{"id":"1.232013794","rc":[{"batl":[[1,1.4,1],[2,1.66,30]],"ltp":1.16,"tv":51.36,"id":61077257}]}]}
{"op":"mcm","clk":"11921614106","pt":1724157192799,"mc":[{"id":"1.232013794","rc":[{"batb":[[0,1.07,23.23],[1,1.06,164.67],[2,1.05,200]],"ltp":1.16,"tv":51.36,"id":61077257}]}]}
{"op":"mcm","clk":"11921661888","pt":1724157925735,"mc":[{"id":"1.232013794","rc":[{"batb":[[0,1.08,276.92],[1,1.07,23.23],[2,1.06,164.67]],"ltp":1.16,"tv":51.36,"id":61077257}]}]}
{"op":"mcm","clk":"11921661920","pt":1724157926248,"mc":[{"id":"1.232013794","rc":[{"batb":[[0,1.16,273],[1,1.08,276.92],[2,1.07,23.23]],"ltp":1.16,"tv":51.36,"id":61077257},{"batb":[[0,5.9,8.91],[1,1.06,149.69],[2,1.05,200]],"ltp":1.06,"tv":16.98,"id":61077258}]}]}
{"op":"mcm","clk":"11921677300","pt":1724158237527,"mc":[{"id":"1.232013794","rc":[{"batb":[[2,1.06,164.67]],"ltp":1.16,"tv":51.36,"id":61077257}]}]}
{"op":"mcm","clk":"11921722976","pt":1724159152699,"mc":[{"id":"1.232013794","rc":[{"batb":[[1,1.08,276.81]],"batl":[[2,1.66,0]],"ltp":1.16,"tv":51.36,"id":61077257},{"trd":[[5.9,0.66]],"batb":[[0,5.9,8.58]],"ltp":5.9,"tv":17.64,"id":61077258}],"tv":69.0}]}
{"op":"mcm","clk":"11921723091","pt":1724159154703,"mc":[{"id":"1.232013794","rc":[{"batb":[[0,5.9,8.91]],"ltp":5.9,"tv":17.64,"id":61077258}]}]}
{"op":"mcm","clk":"11921784906","pt":1724160276802,"mc":[{"id":"1.232013794","rc":[{"batl":[[0,1.34,32.44],[1,1.35,20],[2,1.4,1]],"ltp":1.16,"tv":51.36,"id":61077257}]}]}
{"op":"mcm","clk":"11921801456","pt":1724160582674,"mc":[{"id":"1.232013794","rc":[{"trd":[[1.21,0.86]],"ltp":1.21,"tv":52.21,"id":61077257},{"trd":[[5.9,0.84]],"batb":[[0,5.9,8.73]],"ltp":5.9,"tv":17.82,"id":61077258}],"tv":70.03}]}
{"op":"mcm","clk":"11921801485","pt":1724160583547,"mc":[{"id":"1.232013794","rc":[{"batb":[[0,5.9,8.91]],"ltp":5.9,"tv":17.82,"id":61077258}]}]}
{"op":"mcm","clk":"11921821318","pt":1724160914478,"mc":[{"id":"1.232013794","rc":[{"batb":[[0,1.16,235.67]],"ltp":1.21,"tv":52.21,"id":61077257},{"batb":[[0,5.9,7.69]],"ltp":5.9,"tv":17.82,"id":61077258}]}]}
{"op":"mcm","clk":"11921825485","pt":1724161006033,"mc":[{"id":"1.232013794","rc":[{"batl":[[0,1.19,20],[1,1.34,32.44]],"ltp":1.21,"tv":52.21,"id":61077257}]}]}
{"op":"mcm","clk":"11921835509","pt":1724161194130,"mc":[{"id":"1.232013794","rc":[{"trd":[[1.16,34]],"batb":[[0,1.16,230.67]],"ltp":1.16,"tv":62.21,"id":61077257}],"tv":80.03}]}
{"op":"mcm","clk":"11921835582","pt":1724161195426,"mc":[{"id":"1.232013794","rc":[{"batb":[[0,1.16,235.67]],"ltp":1.16,"tv":62.21,"id":61077257}]}]}
{"op":"mcm","clk":"11921908955","pt":1724162564108,"mc":[{"id":"1.232013794","rc":[{"batb":[[1,1.08,276.84]],"batl":[[0,1.2,20]],"ltp":1.16,"tv":62.21,"id":61077257}]}]}
{"op":"mcm","clk":"11921917610","pt":1724162709960,"mc":[{"id":"1.232013794","rc":[{"batb":[[0,1.12,314.23]],"ltp":1.16,"tv":62.21,"id":61077257},{"batb":[[0,7.2,6.08]],"ltp":5.9,"tv":17.82,"id":61077258}]}]}
{"op":"mcm","clk":"11922012148","pt":1724164214978,"mc":[{"id":"1.232013794","rc":[{"batl":[[0,1.16,20]],"ltp":1.16,"tv":62.21,"id":61077257}]}]}
{"op":"mcm","clk":"11922313858","pt":1724168575003,"mc":[{"id":"1.232013794","rc":[{"batb":[[1,1.08,276.89]],"ltp":1.16,"tv":62.21,"id":61077257}]}]}
{"op":"mcm","clk":"11922635109","pt":1724171751638,"mc":[{"id":"1.232013794","rc":[{"batb":[[1,1.08,276.81]],"ltp":1.16,"tv":62.21,"id":61077257},{"batb":[[1,2,58.24],[2,1.06,149.69]],"ltp":5.9,"tv":17.82,"id":61077258}]}]}
{"op":"mcm","clk":"11922881123","pt":1724173975018,"mc":[{"id":"1.232013794","rc":[{"batb":[[1,1.08,276.67]],"ltp":1.16,"tv":62.21,"id":61077257},{"batb":[[1,2,58.4]],"ltp":5.9,"tv":17.82,"id":61077258}]}]}
{"op":"mcm","clk":"11923545534","pt":1724179375103,"mc":[{"id":"1.232013794","rc":[{"batb":[[1,1.08,276.81]],"ltp":1.16,"tv":62.21,"id":61077257},{"batb":[[1,2,58.43]],"ltp":5.9,"tv":17.82,"id":61077258}]}]}
{"op":"mcm","clk":"11924352994","pt":1724184775025,"mc":[{"id":"1.232013794","rc":[{"batb":[[1,1.08,276.96]],"ltp":1.16,"tv":62.21,"id":61077257},{"batb":[[1,2,58.41]],"ltp":5.9,"tv":17.82,"id":61077258}]}]}
{"op":"mcm","clk":"11924696151","pt":1724190175021,"mc":[{"id":"1.232013794","rc":[{"batb":[[1,1.08,276.93]],"ltp":1.16,"tv":62.21,"id":61077257},{"batb":[[1,2,58.44]],"ltp":5.9,"tv":17.82,"id":61077258}]}]}
{"op":"mcm","clk":"11924757382","pt":1724191409078,"mc":[{"id":"1.232013794","rc":[{"batb":[[1,1.08,276.83]],"ltp":1.16,"tv":62.21,"id":61077257},{"batb":[[0,7.4,10],[1,7.2,6.08],[2,2,58.4]],"batl":[[0,9.8,0.52]],"ltp":5.9,"tv":17.82,"id":61077258}]}]}
{"op":"mcm","clk":"11924757624","pt":1724191412395,"mc":[{"id":"1.232013794","rc":[{"batb":[[0,7.2,6.08],[1,2,58.4],[2,1.06,149.69]],"ltp":5.9,"tv":17.82,"id":61077258}]}]}
{"op":"mcm","clk":"11924758312","pt":1724191423299,"mc":[{"id":"1.232013794","rc":[{"batb":[[0,7.4,10],[1,7.2,6.08],[2,2,58.4]],"ltp":5.9,"tv":17.82,"id":61077258}]}]}
{"op":"mcm","clk":"11924758569","pt":1724191426799,"mc":[{"id":"1.232013794","rc":[{"batb":[[0,7.2,6.08],[1,2,58.4],[2,1.06,149.69]],"ltp":5.9,"tv":17.82,"id":61077258}]}]}
{"op":"mcm","clk":"11924759513","pt":1724191441446,"mc":[{"id":"1.232013794","rc":[{"batb":[[0,7.4,10],[1,7.2,6.08],[2,2,58.4]],"ltp":5.9,"tv":17.82,"id":61077258}]}]}
{"op":"mcm","clk":"11924759739","pt":1724191444743,"mc":[{"id":"1.232013794","rc":[{"batb":[[0,7.2,6.08],[1,2,58.4],[2,1.06,149.69]],"ltp":5.9,"tv":17.82,"id":61077258}]}]}
{"op":"mcm","clk":"11924763290","pt":1724191501659,"mc":[{"id":"1.232013794","rc":[{"batb":[[0,7.4,10],[1,7.2,6.08],[2,2,58.4]],"ltp":5.9,"tv":17.82,"id":61077258}]}]}
{"op":"mcm","clk":"11924763475","pt":1724191504953,"mc":[{"id":"1.232013794","rc":[{"batb":[[0,7.2,6.08],[1,2,58.4],[2,1.06,149.69]],"ltp":5.9,"tv":17.82,"id":61077258}]}]}
{"op":"mcm","clk":"11924764753","pt":1724191527081,"mc":[{"id":"1.232013794","rc":[{"batb":[[0,7.4,10],[1,7.2,6.08],[2,2,58.4]],"ltp":5.9,"tv":17.82,"id":61077258}]}]}
{"op":"mcm","clk":"11924764957","pt":1724191530778,"mc":[{"id":"1.232013794","rc":[{"batb":[[0,7.2,6.08],[1,2,58.4],[2,1.06,149.69]],"ltp":5.9,"tv":17.82,"id":61077258}]}]}
{"op":"mcm","clk":"11924765242","pt":1724191536072,"mc":[{"id":"1.232013794","rc":[{"batb":[[0,7.4,10],[1,7.2,6.08],[2,2,58.4]],"ltp":5.9,"tv":17.82,"id":61077258}]}]}
{"op":"mcm","clk":"11924765440","pt":1724191539677,"mc":[{"id":"1.232013794","rc":[{"batb":[[0,7.2,6.08],[1,2,58.4],[2,1.06,149.69]],"ltp":5.9,"tv":17.82,"id":61077258}]}]}
{"op":"mcm","clk":"11924765638","pt":1724191543275,"mc":[{"id":"1.232013794","rc":[{"batb":[[0,7.4,10],[1,7.2,6.08],[2,2,58.4]],"ltp":5.9,"tv":17.82,"id":61077258}]}]}
{"op":"mcm","clk":"11924765855","pt":1724191546889,"mc":[{"id":"1.232013794","rc":[{"batb":[[0,7.2,6.08],[1,2,58.4],[2,1.06,149.69]],"ltp":5.9,"tv":17.82,"id":61077258}]}]}
{"op":"mcm","clk":"11924767009","pt":1724191567707,"mc":[{"id":"1.232013794","rc":[{"batb":[[0,7.4,10],[1,7.2,6.08],[2,2,58.4]],"ltp":5.9,"tv":17.82,"id":61077258}]}]}
{"op":"mcm","clk":"11924767222","pt":1724191571101,"mc":[{"id":"1.232013794","rc":[{"batb":[[0,7.2,6.08],[1,2,58.4],[2,1.06,149.69]],"ltp":5.9,"tv":17.82,"id":61077258}]}]}
{"op":"mcm","clk":"11924767892","pt":1724191584147,"mc":[{"id":"1.232013794","rc":[{"batb":[[0,7.4,10],[1,7.2,6.08],[2,2,58.4]],"ltp":5.9,"tv":17.82,"id":61077258}]}]}
{"op":"mcm","clk":"11924768072","pt":1724191587332,"mc":[{"id":"1.232013794","rc":[{"batb":[[0,7.2,6.08],[1,2,58.4],[2,1.06,149.69]],"ltp":5.9,"tv":17.82,"id":61077258}]}]}
{"op":"mcm","clk":"11924768357","pt":1724191591241,"mc":[{"id":"1.232013794","rc":[{"batb":[[0,7.4,10],[1,7.2,6.08],[2,2,58.4]],"ltp":5.9,"tv":17.82,"id":61077258}]}]}
{"op":"mcm","clk":"11924768541","pt":1724191594931,"mc":[{"id":"1.232013794","rc":[{"batb":[[0,7.2,6.08],[1,2,58.4],[2,1.06,149.69]],"ltp":5.9,"tv":17.82,"id":61077258}]}]}
{"op":"mcm","clk":"11924768812","pt":1724191599853,"mc":[{"id":"1.232013794","rc":[{"batb":[[0,7.4,10],[1,7.2,6.08],[2,2,58.4]],"ltp":5.9,"tv":17.82,"id":61077258}]}]}
{"op":"mcm","clk":"11924769101","pt":1724191603551,"mc":[{"id":"1.232013794","rc":[{"batb":[[0,7.2,6.08],[1,2,58.4],[2,1.06,149.69]],"ltp":5.9,"tv":17.82,"id":61077258}]}]}
{"op":"mcm","clk":"11924771377","pt":1724191641786,"mc":[{"id":"1.232013794","rc":[{"batb":[[0,7.4,10],[1,7.2,6.08],[2,2,58.4]],"ltp":5.9,"tv":17.82,"id":61077258}]}]}
{"op":"mcm","clk":"11924771586","pt":1724191645368,"mc":[{"id":"1.232013794","rc":[{"batb":[[0,7.2,6.08],[1,2,58.4],[2,1.06,149.69]],"ltp":5.9,"tv":17.82,"id":61077258}]}]}
{"op":"mcm","clk":"11924771864","pt":1724191650764,"mc":[{"id":"1.232013794","rc":[{"batb":[[0,7.4,10],[1,7.2,6.08],[2,2,58.4]],"ltp":5.9,"tv":17.82,"id":61077258}]}]}
{"op":"mcm","clk":"11924772080","pt":1724191654163,"mc":[{"id":"1.232013794","rc":[{"batb":[[0,7.2,6.08],[1,2,58.4],[2,1.06,149.69]],"ltp":5.9,"tv":17.82,"id":61077258}]}]}
{"op":"mcm","clk":"11924773774","pt":1724191681926,"mc":[{"id":"1.232013794","rc":[{"batb":[[0,7.4,10],[1,7.2,6.08],[2,2,58.4]],"ltp":5.9,"tv":17.82,"id":61077258}]}]}
{"op":"mcm","clk":"11924773976","pt":1724191685427,"mc":[{"id":"1.232013794","rc":[{"batb":[[0,7.2,6.08],[1,2,58.4],[2,1.06,149.69]],"ltp":5.9,"tv":17.82,"id":61077258}]}]}
{"op":"mcm","clk":"11924776190","pt":1724191720242,"mc":[{"id":"1.232013794","rc":[{"batb":[[0,7.4,10],[1,7.2,6.08],[2,2,58.4]],"ltp":5.9,"tv":17.82,"id":61077258}]}]}
{"op":"mcm","clk":"11924776459","pt":1724191724042,"mc":[{"id":"1.232013794","rc":[{"batb":[[0,7.2,6.08],[1,2,58.4],[2,1.06,149.69]],"ltp":5.9,"tv":17.82,"id":61077258}]}]}
{"op":"mcm","clk":"11924776835","pt":1724191729658,"mc":[{"id":"1.232013794","rc":[{"batb":[[0,7.4,10],[1,7.2,6.08],[2,2,58.4]],"ltp":5.9,"tv":17.82,"id":61077258}]}]}
{"op":"mcm","clk":"11924777094","pt":1724191733061,"mc":[{"id":"1.232013794","rc":[{"batb":[[0,7.2,6.08],[1,2,58.4],[2,1.06,149.69]],"ltp":5.9,"tv":17.82,"id":61077258}]}]}
{"op":"mcm","clk":"11924778210","pt":1724191751700,"mc":[{"id":"1.232013794","rc":[{"batb":[[0,7.4,10],[1,7.2,6.08],[2,2,58.4]],"ltp":5.9,"tv":17.82,"id":61077258}]}]}
{"op":"mcm","clk":"11924778450","pt":1724191755503,"mc":[{"id":"1.232013794","rc":[{"batb":[[0,7.2,6.08],[1,2,58.4],[2,1.06,149.69]],"ltp":5.9,"tv":17.82,"id":61077258}]}]}
{"op":"mcm","clk":"11924778705","pt":1724191760595,"mc":[{"id":"1.232013794","rc":[{"batb":[[0,7.4,10],[1,7.2,6.08],[2,2,58.4]],"ltp":5.9,"tv":17.82,"id":61077258}]}]}
{"op":"mcm","clk":"11924778917","pt":1724191764497,"mc":[{"id":"1.232013794","rc":[{"batb":[[0,7.2,6.08],[1,2,58.4],[2,1.06,149.69]],"ltp":5.9,"tv":17.82,"id":61077258}]}]}
{"op":"mcm","clk":"11924779103","pt":1724191767589,"mc":[{"id":"1.232013794","rc":[{"batb":[[0,7.4,10],[1,7.2,6.08],[2,2,58.4]],"ltp":5.9,"tv":17.82,"id":61077258}]}]}
{"op":"mcm","clk":"11924779302","pt":1724191770985,"mc":[{"id":"1.232013794","rc":[{"batb":[[0,7.2,6.08],[1,2,58.4],[2,1.06,149.69]],"ltp":5.9,"tv":17.82,"id":61077258}]}]}
{"op":"mcm","clk":"11924779606","pt":1724191776301,"mc":[{"id":"1.232013794","rc":[{"batb":[[0,7.4,10],[1,7.2,6.08],[2,2,58.4]],"ltp":5.9,"tv":17.82,"id":61077258}]}]}
{"op":"mcm","clk":"11924779797","pt":1724191779597,"mc":[{"id":"1.232013794","rc":[{"batb":[[0,7.2,6.08],[1,2,58.4],[2,1.06,149.69]],"ltp":5.9,"tv":17.82,"id":61077258}]}]}
{"op":"mcm","clk":"11924779967","pt":1724191782726,"mc":[{"id":"1.232013794","rc":[{"batb":[[0,7.4,10],[1,7.2,6.08],[2,2,58.4]],"ltp":5.9,"tv":17.82,"id":61077258}]}]}
{"op":"mcm","clk":"11924780144","pt":1724191785929,"mc":[{"id":"1.232013794","rc":[{"batb":[[0,7.2,6.08],[1,2,58.4],[2,1.06,149.69]],"ltp":5.9,"tv":17.82,"id":61077258}]}]}
{"op":"mcm","clk":"11924781055","pt":1724191800324,"mc":[{"id":"1.232013794","rc":[{"batb":[[0,7.4,10],[1,7.2,6.08],[2,2,58.4]],"ltp":5.9,"tv":17.82,"id":61077258}]}]}
{"op":"mcm","clk":"11924781324","pt":1724191803930,"mc":[{"id":"1.232013794","rc":[{"batb":[[0,7.2,6.08],[1,2,58.4],[2,1.06,149.69]],"ltp":5.9,"tv":17.82,"id":61077258}]}]}
{"op":"mcm","clk":"11924781970","pt":1724191815031,"mc":[{"id":"1.232013794","rc":[{"batb":[[0,7.4,10],[1,7.2,6.08],[2,2,58.4]],"ltp":5.9,"tv":17.82,"id":61077258}]}]}
{"op":"mcm","clk":"11924782164","pt":1724191818465,"mc":[{"id":"1.232013794","rc":[{"batb":[[0,7.2,6.08],[1,2,58.4],[2,1.06,149.69]],"ltp":5.9,"tv":17.82,"id":61077258}]}]}
{"op":"mcm","clk":"11924785461","pt":1724191870197,"mc":[{"id":"1.232013794","rc":[{"batb":[[0,7.4,10],[1,7.2,6.08],[2,2,58.4]],"ltp":5.9,"tv":17.82,"id":61077258}]}]}
{"op":"mcm","clk":"11924785689","pt":1724191873901,"mc":[{"id":"1.232013794","rc":[{"batb":[[0,7.2,6.08],[1,2,58.4],[2,1.06,149.69]],"ltp":5.9,"tv":17.82,"id":61077258}]}]}
{"op":"mcm","clk":"11924786992","pt":1724191895038,"mc":[{"id":"1.232013794","rc":[{"batb":[[0,7.4,10],[1,7.2,6.08],[2,2,58.4]],"ltp":5.9,"tv":17.82,"id":61077258}]}]}
{"op":"mcm","clk":"11924787187","pt":1724191898438,"mc":[{"id":"1.232013794","rc":[{"batb":[[0,7.2,6.08],[1,2,58.4],[2,1.06,149.69]],"ltp":5.9,"tv":17.82,"id":61077258}]}]}
{"op":"mcm","clk":"11924788407","pt":1724191917656,"mc":[{"id":"1.232013794","rc":[{"batb":[[0,7.4,10],[1,7.2,6.08],[2,2,58.4]],"ltp":5.9,"tv":17.82,"id":61077258}]}]}
{"op":"mcm","clk":"11924788625","pt":1724191921207,"mc":[{"id":"1.232013794","rc":[{"batb":[[0,7.2,6.08],[1,2,58.4],[2,1.06,149.69]],"ltp":5.9,"tv":17.82,"id":61077258}]}]}
{"op":"mcm","clk":"11924788832","pt":1724191924188,"mc":[{"id":"1.232013794","rc":[{"batb":[[0,7.4,10],[1,7.2,6.08],[2,2,58.4]],"ltp":5.9,"tv":17.82,"id":61077258}]}]}
{"op":"mcm","clk":"11924789063","pt":1724191927985,"mc":[{"id":"1.232013794","rc":[{"batb":[[0,7.2,6.08],[1,2,58.4],[2,1.06,149.69]],"ltp":5.9,"tv":17.82,"id":61077258}]}]}
{"op":"mcm","clk":"11924789222","pt":1724191930806,"mc":[{"id":"1.232013794","rc":[{"batb":[[0,7.4,10],[1,7.2,6.08],[2,2,58.4]],"ltp":5.9,"tv":17.82,"id":61077258}]}]}
{"op":"mcm","clk":"11924789475","pt":1724191934400,"mc":[{"id":"1.232013794","rc":[{"batb":[[0,7.2,6.08],[1,2,58.4],[2,1.06,149.69]],"ltp":5.9,"tv":17.82,"id":61077258}]}]}
{"op":"mcm","clk":"11924789845","pt":1724191939584,"mc":[{"id":"1.232013794","rc":[{"batb":[[0,7.4,10],[1,7.2,6.08],[2,2,58.4]],"ltp":5.9,"tv":17.82,"id":61077258}]}]}
{"op":"mcm","clk":"11924790035","pt":1724191943425,"mc":[{"id":"1.232013794","rc":[{"batb":[[0,7.2,6.08],[1,2,58.4],[2,1.06,149.69]],"ltp":5.9,"tv":17.82,"id":61077258}]}]}
{"op":"mcm","clk":"11924790295","pt":1724191948617,"mc":[{"id":"1.232013794","rc":[{"batb":[[0,7.4,10],[1,7.2,6.08],[2,2,58.4]],"ltp":5.9,"tv":17.82,"id":61077258}]}]}
{"op":"mcm","clk":"11924790530","pt":1724191952112,"mc":[{"id":"1.232013794","rc":[{"batb":[[0,7.2,6.08],[1,2,58.4],[2,1.06,149.69]],"ltp":5.9,"tv":17.82,"id":61077258}]}]}
{"op":"mcm","clk":"11924790673","pt":1724191954323,"mc":[{"id":"1.232013794","rc":[{"batb":[[0,7.4,10],[1,7.2,6.08],[2,2,58.4]],"ltp":5.9,"tv":17.82,"id":61077258}]}]}
{"op":"mcm","clk":"11924790871","pt":1724191957714,"mc":[{"id":"1.232013794","rc":[{"batb":[[0,7.2,6.08],[1,2,58.4],[2,1.06,149.69]],"ltp":5.9,"tv":17.82,"id":61077258}]}]}
{"op":"mcm","clk":"11924791032","pt":1724191960338,"mc":[{"id":"1.232013794","rc":[{"batb":[[0,7.4,10],[1,7.2,6.08],[2,2,58.4]],"ltp":5.9,"tv":17.82,"id":61077258}]}]}
{"op":"mcm","clk":"11924791252","pt":1724191963829,"mc":[{"id":"1.232013794","rc":[{"batb":[[0,7.2,6.08],[1,2,58.4],[2,1.06,149.69]],"ltp":5.9,"tv":17.82,"id":61077258}]}]}
{"op":"mcm","clk":"11924791414","pt":1724191966607,"mc":[{"id":"1.232013794","rc":[{"batb":[[0,7.4,10],[1,7.2,6.08],[2,2,58.4]],"ltp":5.9,"tv":17.82,"id":61077258}]}]}
{"op":"mcm","clk":"11924791618","pt":1724191970505,"mc":[{"id":"1.232013794","rc":[{"batb":[[0,7.2,6.08],[1,2,58.4],[2,1.06,149.69]],"ltp":5.9,"tv":17.82,"id":61077258}]}]}
{"op":"mcm","clk":"11924792247","pt":1724191982037,"mc":[{"id":"1.232013794","rc":[{"batb":[[0,7.4,10],[1,7.2,6.08],[2,2,58.4]],"ltp":5.9,"tv":17.82,"id":61077258}]}]}
{"op":"mcm","clk":"11924792480","pt":1724191985541,"mc":[{"id":"1.232013794","rc":[{"batb":[[0,7.2,6.08],[1,2,58.4],[2,1.06,149.69]],"ltp":5.9,"tv":17.82,"id":61077258}]}]}
{"op":"mcm","clk":"11924792929","pt":1724191993060,"mc":[{"id":"1.232013794","rc":[{"batb":[[0,7.4,10],[1,7.2,6.08],[2,2,58.4]],"ltp":5.9,"tv":17.82,"id":61077258}]}]}
{"op":"mcm","clk":"11924793122","pt":1724191996657,"mc":[{"id":"1.232013794","rc":[{"batb":[[0,7.2,6.08],[1,2,58.4],[2,1.06,149.69]],"ltp":5.9,"tv":17.82,"id":61077258}]}]}
{"op":"mcm","clk":"11924794664","pt":1724192017496,"mc":[{"id":"1.232013794","rc":[{"batb":[[0,7.4,10],[1,7.2,6.08],[2,2,58.4]],"ltp":5.9,"tv":17.82,"id":61077258}]}]}
{"op":"mcm","clk":"11924795068","pt":1724192021061,"mc":[{"id":"1.232013794","rc":[{"batb":[[0,7.2,6.08],[1,2,58.4],[2,1.06,149.69]],"ltp":5.9,"tv":17.82,"id":61077258}]}]}
{"op":"mcm","clk":"11924795379","pt":1724192025865,"mc":[{"id":"1.232013794","rc":[{"batb":[[0,7.4,10],[1,7.2,6.08],[2,2,58.4]],"ltp":5.9,"tv":17.82,"id":61077258}]}]}
{"op":"mcm","clk":"11924795545","pt":1724192029260,"mc":[{"id":"1.232013794","rc":[{"batb":[[0,7.2,6.08],[1,2,58.4],[2,1.06,149.69]],"ltp":5.9,"tv":17.82,"id":61077258}]}]}
{"op":"mcm","clk":"11924795776","pt":1724192032762,"mc":[{"id":"1.232013794","rc":[{"batb":[[0,7.4,10],[1,7.2,6.08],[2,2,58.4]],"ltp":5.9,"tv":17.82,"id":61077258}]}]}
{"op":"mcm","clk":"11924795977","pt":1724192036274,"mc":[{"id":"1.232013794","rc":[{"batb":[[0,7.2,6.08],[1,2,58.4],[2,1.06,149.69]],"ltp":5.9,"tv":17.82,"id":61077258}]}]}
{"op":"mcm","clk":"11924796161","pt":1724192039372,"mc":[{"id":"1.232013794","rc":[{"batb":[[0,7.4,10],[1,7.2,6.08],[2,2,58.4]],"ltp":5.9,"tv":17.82,"id":61077258}]}]}
{"op":"mcm","clk":"11924796380","pt":1724192043181,"mc":[{"id":"1.232013794","rc":[{"batb":[[0,7.2,6.08],[1,2,58.4],[2,1.06,149.69]],"ltp":5.9,"tv":17.82,"id":61077258}]}]}
{"op":"mcm","clk":"11924796644","pt":1724192048112,"mc":[{"id":"1.232013794","rc":[{"batb":[[0,7.4,10],[1,7.2,6.08],[2,2,58.4]],"ltp":5.9,"tv":17.82,"id":61077258}]}]}
{"op":"mcm","clk":"11924796815","pt":1724192051682,"mc":[{"id":"1.232013794","rc":[{"batb":[[0,7.2,6.08],[1,2,58.4],[2,1.06,149.69]],"ltp":5.9,"tv":17.82,"id":61077258}]}]}
{"op":"mcm","clk":"11924796986","pt":1724192055216,"mc":[{"id":"1.232013794","rc":[{"batb":[[0,7.4,10],[1,7.2,6.08],[2,2,58.4]],"ltp":5.9,"tv":17.82,"id":61077258}]}]}
{"op":"mcm","clk":"11924797168","pt":1724192058592,"mc":[{"id":"1.232013794","rc":[{"batb":[[0,7.2,6.08],[1,2,58.4],[2,1.06,149.69]],"ltp":5.9,"tv":17.82,"id":61077258}]}]}
{"op":"mcm","clk":"11924797330","pt":1724192061821,"mc":[{"id":"1.232013794","rc":[{"batb":[[0,7.4,10],[1,7.2,6.08],[2,2,58.4]],"ltp":5.9,"tv":17.82,"id":61077258}]}]}
{"op":"mcm","clk":"11924797485","pt":1724192065101,"mc":[{"id":"1.232013794","rc":[{"batb":[[0,7.2,6.08],[1,2,58.4],[2,1.06,149.69]],"ltp":5.9,"tv":17.82,"id":61077258}]}]}
{"op":"mcm","clk":"11924797645","pt":1724192068283,"mc":[{"id":"1.232013794","rc":[{"batb":[[0,7.4,10],[1,7.2,6.08],[2,2,58.4]],"ltp":5.9,"tv":17.82,"id":61077258}]}]}
{"op":"mcm","clk":"11924797830","pt":1724192071829,"mc":[{"id":"1.232013794","rc":[{"batb":[[0,7.2,6.08],[1,2,58.4],[2,1.06,149.69]],"ltp":5.9,"tv":17.82,"id":61077258}]}]}
{"op":"mcm","clk":"11924797984","pt":1724192074815,"mc":[{"id":"1.232013794","rc":[{"batb":[[0,7.4,10],[1,7.2,6.08],[2,2,58.4]],"ltp":5.9,"tv":17.82,"id":61077258}]}]}
{"op":"mcm","clk":"11924798178","pt":1724192078231,"mc":[{"id":"1.232013794","rc":[{"batb":[[0,7.2,6.08],[1,2,58.4],[2,1.06,149.69]],"ltp":5.9,"tv":17.82,"id":61077258}]}]}
{"op":"mcm","clk":"11924798322","pt":1724192081210,"mc":[{"id":"1.232013794","rc":[{"batb":[[0,7.4,10],[1,7.2,6.08],[2,2,58.4]],"ltp":5.9,"tv":17.82,"id":61077258}]}]}
{"op":"mcm","clk":"11924798470","pt":1724192084652,"mc":[{"id":"1.232013794","rc":[{"batb":[[0,7.2,6.08],[1,2,58.4],[2,1.06,149.69]],"ltp":5.9,"tv":17.82,"id":61077258}]}]}
{"op":"mcm","clk":"11924798570","pt":1724192087054,"mc":[{"id":"1.232013794","rc":[{"batb":[[0,7.4,10],[1,7.2,6.08],[2,2,58.4]],"ltp":5.9,"tv":17.82,"id":61077258}]}]}
{"op":"mcm","clk":"11924798686","pt":1724192090436,"mc":[{"id":"1.232013794","rc":[{"batb":[[0,7.2,6.08],[1,2,58.4],[2,1.06,149.69]],"ltp":5.9,"tv":17.82,"id":61077258}]}]}
{"op":"mcm","clk":"11924798834","pt":1724192094644,"mc":[{"id":"1.232013794","rc":[{"batb":[[0,7.4,10],[1,7.2,6.08],[2,2,58.4]],"ltp":5.9,"tv":17.82,"id":61077258}]}]}
{"op":"mcm","clk":"11924798963","pt":1724192098136,"mc":[{"id":"1.232013794","rc":[{"batb":[[0,7.2,6.08],[1,2,58.4],[2,1.06,149.69]],"ltp":5.9,"tv":17.82,"id":61077258}]}]}
{"op":"mcm","clk":"11924799090","pt":1724192100563,"mc":[{"id":"1.232013794","rc":[{"batb":[[0,7.4,10],[1,7.2,6.08],[2,2,58.4]],"ltp":5.9,"tv":17.82,"id":61077258}]}]}
{"op":"mcm","clk":"11924799252","pt":1724192104177,"mc":[{"id":"1.232013794","rc":[{"batb":[[0,7.2,6.08],[1,2,58.4],[2,1.06,149.69]],"ltp":5.9,"tv":17.82,"id":61077258}]}]}
{"op":"mcm","clk":"11924799538","pt":1724192109457,"mc":[{"id":"1.232013794","rc":[{"batb":[[0,7.4,10],[1,7.2,6.08],[2,2,58.4]],"ltp":5.9,"tv":17.82,"id":61077258}]}]}
{"op":"mcm","clk":"11924799714","pt":1724192112984,"mc":[{"id":"1.232013794","rc":[{"batb":[[0,7.2,6.08],[1,2,58.4],[2,1.06,149.69]],"ltp":5.9,"tv":17.82,"id":61077258}]}]}
{"op":"mcm","clk":"11924799896","pt":1724192116552,"mc":[{"id":"1.232013794","rc":[{"batb":[[0,7.4,10],[1,7.2,6.08],[2,2,58.4]],"ltp":5.9,"tv":17.82,"id":61077258}]}]}
{"op":"mcm","clk":"11924800060","pt":1724192120299,"mc":[{"id":"1.232013794","rc":[{"batb":[[0,7.2,6.08],[1,2,58.4],[2,1.06,149.69]],"ltp":5.9,"tv":17.82,"id":61077258}]}]}
{"op":"mcm","clk":"11924800185","pt":1724192122968,"mc":[{"id":"1.232013794","rc":[{"batb":[[0,7.4,10],[1,7.2,6.08],[2,2,58.4]],"ltp":5.9,"tv":17.82,"id":61077258}]}]}
{"op":"mcm","clk":"11924800368","pt":1724192126266,"mc":[{"id":"1.232013794","rc":[{"batb":[[0,7.2,6.08],[1,2,58.4],[2,1.06,149.69]],"ltp":5.9,"tv":17.82,"id":61077258}]}]}
{"op":"mcm","clk":"11924800466","pt":1724192128681,"mc":[{"id":"1.232013794","rc":[{"batb":[[0,7.4,10],[1,7.2,6.08],[2,2,58.4]],"ltp":5.9,"tv":17.82,"id":61077258}]}]}
{"op":"mcm","clk":"11924800662","pt":1724192132104,"mc":[{"id":"1.232013794","rc":[{"batb":[[0,7.2,6.08],[1,2,58.4],[2,1.06,149.69]],"ltp":5.9,"tv":17.82,"id":61077258}]}]}
{"op":"mcm","clk":"11924800806","pt":1724192134312,"mc":[{"id":"1.232013794","rc":[{"batb":[[0,7.4,10],[1,7.2,6.08],[2,2,58.4]],"ltp":5.9,"tv":17.82,"id":61077258}]}]}
{"op":"mcm","clk":"11924801034","pt":1724192138081,"mc":[{"id":"1.232013794","rc":[{"batb":[[0,7.2,6.08],[1,2,58.4],[2,1.06,149.69]],"ltp":5.9,"tv":17.82,"id":61077258}]}]}
{"op":"mcm","clk":"11924801283","pt":1724192141683,"mc":[{"id":"1.232013794","rc":[{"batb":[[0,7.4,10],[1,7.2,6.08],[2,2,58.4]],"ltp":5.9,"tv":17.82,"id":61077258}]}]}
{"op":"mcm","clk":"11924801486","pt":1724192145430,"mc":[{"id":"1.232013794","rc":[{"batb":[[0,7.2,6.08],[1,2,58.4],[2,1.06,149.69]],"ltp":5.9,"tv":17.82,"id":61077258}]}]}
{"op":"mcm","clk":"11924801687","pt":1724192148522,"mc":[{"id":"1.232013794","rc":[{"batb":[[0,7.4,10],[1,7.2,6.08],[2,2,58.4]],"ltp":5.9,"tv":17.82,"id":61077258}]}]}
{"op":"mcm","clk":"11924801896","pt":1724192151707,"mc":[{"id":"1.232013794","rc":[{"batb":[[0,7.2,6.08],[1,2,58.4],[2,1.06,149.69]],"ltp":5.9,"tv":17.82,"id":61077258}]}]}
{"op":"mcm","clk":"11924802044","pt":1724192154227,"mc":[{"id":"1.232013794","rc":[{"batb":[[0,7.4,10],[1,7.2,6.08],[2,2,58.4]],"ltp":5.9,"tv":17.82,"id":61077258}]}]}
{"op":"mcm","clk":"11924802233","pt":1724192157561,"mc":[{"id":"1.232013794","rc":[{"batb":[[0,7.2,6.08],[1,2,58.4],[2,1.06,149.69]],"ltp":5.9,"tv":17.82,"id":61077258}]}]}
{"op":"mcm","clk":"11924802343","pt":1724192160477,"mc":[{"id":"1.232013794","rc":[{"batb":[[0,7.4,10],[1,7.2,6.08],[2,2,58.4]],"ltp":5.9,"tv":17.82,"id":61077258}]}]}
{"op":"mcm","clk":"11924802574","pt":1724192164292,"mc":[{"id":"1.232013794","rc":[{"batb":[[0,7.2,6.08],[1,2,58.4],[2,1.06,149.69]],"ltp":5.9,"tv":17.82,"id":61077258}]}]}
{"op":"mcm","clk":"11924802770","pt":1724192167744,"mc":[{"id":"1.232013794","rc":[{"batb":[[0,7.4,10],[1,7.2,6.08],[2,2,58.4]],"ltp":5.9,"tv":17.82,"id":61077258}]}]}
{"op":"mcm","clk":"11924802969","pt":1724192171036,"mc":[{"id":"1.232013794","rc":[{"batb":[[0,7.2,6.08],[1,2,58.4],[2,1.06,149.69]],"ltp":5.9,"tv":17.82,"id":61077258}]}]}
{"op":"mcm","clk":"11924803125","pt":1724192173558,"mc":[{"id":"1.232013794","rc":[{"batb":[[0,7.4,10],[1,7.2,6.08],[2,2,58.4]],"ltp":5.9,"tv":17.82,"id":61077258}]}]}
{"op":"mcm","clk":"11924803327","pt":1724192177016,"mc":[{"id":"1.232013794","rc":[{"batb":[[0,7.2,6.08],[1,2,58.4],[2,1.06,149.69]],"ltp":5.9,"tv":17.82,"id":61077258}]}]}
{"op":"mcm","clk":"11924803541","pt":1724192180261,"mc":[{"id":"1.232013794","rc":[{"batb":[[0,7.4,10],[1,7.2,6.08],[2,2,58.4]],"ltp":5.9,"tv":17.82,"id":61077258}]}]}
{"op":"mcm","clk":"11924803730","pt":1724192183646,"mc":[{"id":"1.232013794","rc":[{"batb":[[0,7.2,6.08],[1,2,58.4],[2,1.06,149.69]],"ltp":5.9,"tv":17.82,"id":61077258}]}]}
{"op":"mcm","clk":"11924803895","pt":1724192186729,"mc":[{"id":"1.232013794","rc":[{"batb":[[0,7.4,10],[1,7.2,6.08],[2,2,58.4]],"ltp":5.9,"tv":17.82,"id":61077258}]}]}
{"op":"mcm","clk":"11924804147","pt":1724192190135,"mc":[{"id":"1.232013794","rc":[{"batb":[[0,7.2,6.08],[1,2,58.4],[2,1.06,149.69]],"ltp":5.9,"tv":17.82,"id":61077258}]}]}
{"op":"mcm","clk":"11924804779","pt":1724192200268,"mc":[{"id":"1.232013794","rc":[{"batb":[[0,7.4,10],[1,7.2,6.08],[2,2,58.4]],"ltp":5.9,"tv":17.82,"id":61077258}]}]}
{"op":"mcm","clk":"11924804984","pt":1724192203868,"mc":[{"id":"1.232013794","rc":[{"batb":[[0,7.2,6.08],[1,2,58.4],[2,1.06,149.69]],"ltp":5.9,"tv":17.82,"id":61077258}]}]}
{"op":"mcm","clk":"11924805248","pt":1724192207772,"mc":[{"id":"1.232013794","rc":[{"batb":[[0,7.4,10],[1,7.2,6.08],[2,2,58.4]],"ltp":5.9,"tv":17.82,"id":61077258}]}]}
{"op":"mcm","clk":"11924805417","pt":1724192211370,"mc":[{"id":"1.232013794","rc":[{"batb":[[0,7.2,6.08],[1,2,58.4],[2,1.06,149.69]],"ltp":5.9,"tv":17.82,"id":61077258}]}]}
{"op":"mcm","clk":"11924805586","pt":1724192214673,"mc":[{"id":"1.232013794","rc":[{"batb":[[0,7.4,10],[1,7.2,6.08],[2,2,58.4]],"ltp":5.9,"tv":17.82,"id":61077258}]}]}
{"op":"mcm","clk":"11924805762","pt":1724192218471,"mc":[{"id":"1.232013794","rc":[{"batb":[[0,7.2,6.08],[1,2,58.4],[2,1.06,149.69]],"ltp":5.9,"tv":17.82,"id":61077258}]}]}
{"op":"mcm","clk":"11924805978","pt":1724192222478,"mc":[{"id":"1.232013794","rc":[{"batb":[[0,7.4,10],[1,7.2,6.08],[2,2,58.4]],"ltp":5.9,"tv":17.82,"id":61077258}]}]}
{"op":"mcm","clk":"11924806180","pt":1724192225561,"mc":[{"id":"1.232013794","rc":[{"batb":[[0,7.2,6.08],[1,2,58.4],[2,1.06,149.69]],"ltp":5.9,"tv":17.82,"id":61077258}]}]}
{"op":"mcm","clk":"11924806384","pt":1724192229063,"mc":[{"id":"1.232013794","rc":[{"batb":[[0,7.4,10],[1,7.2,6.08],[2,2,58.4]],"ltp":5.9,"tv":17.82,"id":61077258}]}]}
{"op":"mcm","clk":"11924806580","pt":1724192232294,"mc":[{"id":"1.232013794","rc":[{"batb":[[0,7.2,6.08],[1,2,58.4],[2,1.06,149.69]],"ltp":5.9,"tv":17.82,"id":61077258}]}]}
{"op":"mcm","clk":"11924806972","pt":1724192238416,"mc":[{"id":"1.232013794","rc":[{"batb":[[0,7.4,10],[1,7.2,6.08],[2,2,58.4]],"ltp":5.9,"tv":17.82,"id":61077258}]}]}
{"op":"mcm","clk":"11924807204","pt":1724192242012,"mc":[{"id":"1.232013794","rc":[{"batb":[[0,7.2,6.08],[1,2,58.4],[2,1.06,149.69]],"ltp":5.9,"tv":17.82,"id":61077258}]}]}
{"op":"mcm","clk":"11924807371","pt":1724192245191,"mc":[{"id":"1.232013794","rc":[{"batb":[[0,7.4,10],[1,7.2,6.08],[2,2,58.4]],"ltp":5.9,"tv":17.82,"id":61077258}]}]}
{"op":"mcm","clk":"11924807591","pt":1724192248580,"mc":[{"id":"1.232013794","rc":[{"batb":[[0,7.2,6.08],[1,2,58.4],[2,1.06,149.69]],"ltp":5.9,"tv":17.82,"id":61077258}]}]}
{"op":"mcm","clk":"11924807984","pt":1724192254700,"mc":[{"id":"1.232013794","rc":[{"batb":[[0,7.4,10],[1,7.2,6.08],[2,2,58.4]],"ltp":5.9,"tv":17.82,"id":61077258}]}]}
{"op":"mcm","clk":"11924808200","pt":1724192258396,"mc":[{"id":"1.232013794","rc":[{"batb":[[0,7.2,6.08],[1,2,58.4],[2,1.06,149.69]],"ltp":5.9,"tv":17.82,"id":61077258}]}]}
{"op":"mcm","clk":"11924808512","pt":1724192263331,"mc":[{"id":"1.232013794","rc":[{"batb":[[0,7.4,10],[1,7.2,6.08],[2,2,58.4]],"ltp":5.9,"tv":17.82,"id":61077258}]}]}
{"op":"mcm","clk":"11924808732","pt":1724192266830,"mc":[{"id":"1.232013794","rc":[{"batb":[[0,7.2,6.08],[1,2,58.4],[2,1.06,149.69]],"ltp":5.9,"tv":17.82,"id":61077258}]}]}
{"op":"mcm","clk":"11924808882","pt":1724192269613,"mc":[{"id":"1.232013794","rc":[{"batb":[[0,7.4,10],[1,7.2,6.08],[2,2,58.4]],"ltp":5.9,"tv":17.82,"id":61077258}]}]}
{"op":"mcm","clk":"11924809160","pt":1724192273315,"mc":[{"id":"1.232013794","rc":[{"batb":[[0,7.2,6.08],[1,2,58.4],[2,1.06,149.69]],"ltp":5.9,"tv":17.82,"id":61077258}]}]}
{"op":"mcm","clk":"11924809388","pt":1724192276353,"mc":[{"id":"1.232013794","rc":[{"batb":[[0,7.4,10],[1,7.2,6.08],[2,2,58.4]],"ltp":5.9,"tv":17.82,"id":61077258}]}]}
{"op":"mcm","clk":"11924809575","pt":1724192279645,"mc":[{"id":"1.232013794","rc":[{"batb":[[0,7.2,6.08],[1,2,58.4],[2,1.06,149.69]],"ltp":5.9,"tv":17.82,"id":61077258}]}]}
{"op":"mcm","clk":"11924809740","pt":1724192282063,"mc":[{"id":"1.232013794","rc":[{"batb":[[0,7.4,10],[1,7.2,6.08],[2,2,58.4]],"ltp":5.9,"tv":17.82,"id":61077258}]}]}
{"op":"mcm","clk":"11924809968","pt":1724192285478,"mc":[{"id":"1.232013794","rc":[{"batb":[[0,7.2,6.08],[1,2,58.4],[2,1.06,149.69]],"ltp":5.9,"tv":17.82,"id":61077258}]}]}
{"op":"mcm","clk":"11924810171","pt":1724192288563,"mc":[{"id":"1.232013794","rc":[{"batb":[[0,7.4,10],[1,7.2,6.08],[2,2,58.4]],"ltp":5.9,"tv":17.82,"id":61077258}]}]}
{"op":"mcm","clk":"11924810351","pt":1724192291756,"mc":[{"id":"1.232013794","rc":[{"batb":[[0,7.2,6.08],[1,2,58.4],[2,1.06,149.69]],"ltp":5.9,"tv":17.82,"id":61077258}]}]}
{"op":"mcm","clk":"11924810492","pt":1724192294177,"mc":[{"id":"1.232013794","rc":[{"batb":[[0,7.4,10],[1,7.2,6.08],[2,2,58.4]],"ltp":5.9,"tv":17.82,"id":61077258}]}]}
{"op":"mcm","clk":"11924810667","pt":1724192297366,"mc":[{"id":"1.232013794","rc":[{"batb":[[0,7.2,6.08],[1,2,58.4],[2,1.06,149.69]],"ltp":5.9,"tv":17.82,"id":61077258}]}]}
{"op":"mcm","clk":"11924810848","pt":1724192299787,"mc":[{"id":"1.232013794","rc":[{"batb":[[0,7.4,10],[1,7.2,6.08],[2,2,58.4]],"ltp":5.9,"tv":17.82,"id":61077258}]}]}
{"op":"mcm","clk":"11924811062","pt":1724192303091,"mc":[{"id":"1.232013794","rc":[{"batb":[[0,7.2,6.08],[1,2,58.4],[2,1.06,149.69]],"ltp":5.9,"tv":17.82,"id":61077258}]}]}
{"op":"mcm","clk":"11924811314","pt":1724192306604,"mc":[{"id":"1.232013794","rc":[{"batb":[[0,7.4,10],[1,7.2,6.08],[2,2,58.4]],"ltp":5.9,"tv":17.82,"id":61077258}]}]}
{"op":"mcm","clk":"11924811563","pt":1724192309803,"mc":[{"id":"1.232013794","rc":[{"batb":[[0,7.2,6.08],[1,2,58.4],[2,1.06,149.69]],"ltp":5.9,"tv":17.82,"id":61077258}]}]}
{"op":"mcm","clk":"11924811712","pt":1724192312070,"mc":[{"id":"1.232013794","rc":[{"batb":[[0,7.4,10],[1,7.2,6.08],[2,2,58.4]],"ltp":5.9,"tv":17.82,"id":61077258}]}]}
{"op":"mcm","clk":"11924811934","pt":1724192315670,"mc":[{"id":"1.232013794","rc":[{"batb":[[0,7.2,6.08],[1,2,58.4],[2,1.06,149.69]],"ltp":5.9,"tv":17.82,"id":61077258}]}]}
{"op":"mcm","clk":"11924812088","pt":1724192318388,"mc":[{"id":"1.232013794","rc":[{"batb":[[0,7.4,10],[1,7.2,6.08],[2,2,58.4]],"ltp":5.9,"tv":17.82,"id":61077258}]}]}
{"op":"mcm","clk":"11924812278","pt":1724192321678,"mc":[{"id":"1.232013794","rc":[{"batb":[[0,7.2,6.08],[1,2,58.4],[2,1.06,149.69]],"ltp":5.9,"tv":17.82,"id":61077258}]}]}
{"op":"mcm","clk":"11924812421","pt":1724192324199,"mc":[{"id":"1.232013794","rc":[{"batb":[[0,7.4,10],[1,7.2,6.08],[2,2,58.4]],"ltp":5.9,"tv":17.82,"id":61077258}]}]}
{"op":"mcm","clk":"11924812582","pt":1724192327496,"mc":[{"id":"1.232013794","rc":[{"batb":[[0,7.2,6.08],[1,2,58.4],[2,1.06,149.69]],"ltp":5.9,"tv":17.82,"id":61077258}]}]}
{"op":"mcm","clk":"11924812766","pt":1724192330987,"mc":[{"id":"1.232013794","rc":[{"batb":[[0,7.4,10],[1,7.2,6.08],[2,2,58.4]],"ltp":5.9,"tv":17.82,"id":61077258}]}]}
{"op":"mcm","clk":"11924812971","pt":1724192334483,"mc":[{"id":"1.232013794","rc":[{"batb":[[0,7.2,6.08],[1,2,58.4],[2,1.06,149.69]],"ltp":5.9,"tv":17.82,"id":61077258}]}]}
{"op":"mcm","clk":"11924813145","pt":1724192337308,"mc":[{"id":"1.232013794","rc":[{"batb":[[0,7.4,10],[1,7.2,6.08],[2,2,58.4]],"ltp":5.9,"tv":17.82,"id":61077258}]}]}
{"op":"mcm","clk":"11924813344","pt":1724192340808,"mc":[{"id":"1.232013794","rc":[{"batb":[[0,7.2,6.08],[1,2,58.4],[2,1.06,149.69]],"ltp":5.9,"tv":17.82,"id":61077258}]}]}
{"op":"mcm","clk":"11924813727","pt":1724192347509,"mc":[{"id":"1.232013794","rc":[{"batb":[[0,7.4,10],[1,7.2,6.08],[2,2,58.4]],"ltp":5.9,"tv":17.82,"id":61077258}]}]}
{"op":"mcm","clk":"11924813921","pt":1724192351018,"mc":[{"id":"1.232013794","rc":[{"batb":[[0,7.2,6.08],[1,2,58.4],[2,1.06,149.69]],"ltp":5.9,"tv":17.82,"id":61077258}]}]}
{"op":"mcm","clk":"11924814072","pt":1724192353491,"mc":[{"id":"1.232013794","rc":[{"batb":[[0,7.4,10],[1,7.2,6.08],[2,2,58.4]],"ltp":5.9,"tv":17.82,"id":61077258}]}]}
{"op":"mcm","clk":"11924814312","pt":1724192357148,"mc":[{"id":"1.232013794","rc":[{"batb":[[0,7.2,6.08],[1,2,58.4],[2,1.06,149.69]],"ltp":5.9,"tv":17.82,"id":61077258}]}]}
{"op":"mcm","clk":"11924814523","pt":1724192360448,"mc":[{"id":"1.232013794","rc":[{"batb":[[0,7.4,10],[1,7.2,6.08],[2,2,58.4]],"ltp":5.9,"tv":17.82,"id":61077258}]}]}
{"op":"mcm","clk":"11924814704","pt":1724192363738,"mc":[{"id":"1.232013794","rc":[{"batb":[[0,7.2,6.08],[1,2,58.4],[2,1.06,149.69]],"ltp":5.9,"tv":17.82,"id":61077258}]}]}
{"op":"mcm","clk":"11924814831","pt":1724192366359,"mc":[{"id":"1.232013794","rc":[{"batb":[[0,7.4,10],[1,7.2,6.08],[2,2,58.4]],"ltp":5.9,"tv":17.82,"id":61077258}]}]}
{"op":"mcm","clk":"11924815009","pt":1724192369646,"mc":[{"id":"1.232013794","rc":[{"batb":[[0,7.2,6.08],[1,2,58.4],[2,1.06,149.69]],"ltp":5.9,"tv":17.82,"id":61077258}]}]}
{"op":"mcm","clk":"11924815128","pt":1724192371963,"mc":[{"id":"1.232013794","rc":[{"batb":[[0,7.4,10],[1,7.2,6.08],[2,2,58.4]],"ltp":5.9,"tv":17.82,"id":61077258}]}]}
{"op":"mcm","clk":"11924815289","pt":1724192375265,"mc":[{"id":"1.232013794","rc":[{"batb":[[0,7.2,6.08],[1,2,58.4],[2,1.06,149.69]],"ltp":5.9,"tv":17.82,"id":61077258}]}]}
{"op":"mcm","clk":"11924815517","pt":1724192378769,"mc":[{"id":"1.232013794","rc":[{"batb":[[0,7.4,10],[1,7.2,6.08],[2,2,58.4]],"ltp":5.9,"tv":17.82,"id":61077258}]}]}
{"op":"mcm","clk":"11924815715","pt":1724192382168,"mc":[{"id":"1.232013794","rc":[{"batb":[[0,7.2,6.08],[1,2,58.4],[2,1.06,149.69]],"ltp":5.9,"tv":17.82,"id":61077258}]}]}
{"op":"mcm","clk":"11924815894","pt":1724192385467,"mc":[{"id":"1.232013794","rc":[{"batb":[[0,7.4,10],[1,7.2,6.08],[2,2,58.4]],"ltp":5.9,"tv":17.82,"id":61077258}]}]}
{"op":"mcm","clk":"11924816117","pt":1724192388867,"mc":[{"id":"1.232013794","rc":[{"batb":[[0,7.2,6.08],[1,2,58.4],[2,1.06,149.69]],"ltp":5.9,"tv":17.82,"id":61077258}]}]}
{"op":"mcm","clk":"11924816271","pt":1724192391394,"mc":[{"id":"1.232013794","rc":[{"batb":[[0,7.4,10],[1,7.2,6.08],[2,2,58.4]],"ltp":5.9,"tv":17.82,"id":61077258}]}]}
{"op":"mcm","clk":"11924816451","pt":1724192394790,"mc":[{"id":"1.232013794","rc":[{"batb":[[0,7.2,6.08],[1,2,58.4],[2,1.06,149.69]],"ltp":5.9,"tv":17.82,"id":61077258}]}]}
{"op":"mcm","clk":"11924816576","pt":1724192397366,"mc":[{"id":"1.232013794","rc":[{"batb":[[0,7.4,10],[1,7.2,6.08],[2,2,58.4]],"ltp":5.9,"tv":17.82,"id":61077258}]}]}
{"op":"mcm","clk":"11924816738","pt":1724192400713,"mc":[{"id":"1.232013794","rc":[{"batb":[[0,7.2,6.08],[1,2,58.4],[2,1.06,149.69]],"ltp":5.9,"tv":17.82,"id":61077258}]}]}
{"op":"mcm","clk":"11924816971","pt":1724192404582,"mc":[{"id":"1.232013794","rc":[{"batb":[[0,7.4,10],[1,7.2,6.08],[2,2,58.4]],"ltp":5.9,"tv":17.82,"id":61077258}]}]}
{"op":"mcm","clk":"11924817210","pt":1724192408390,"mc":[{"id":"1.232013794","rc":[{"batb":[[0,7.2,6.08],[1,2,58.4],[2,1.06,149.69]],"ltp":5.9,"tv":17.82,"id":61077258}]}]}
{"op":"mcm","clk":"11924817346","pt":1724192411122,"mc":[{"id":"1.232013794","rc":[{"batb":[[0,7.4,10],[1,7.2,6.08],[2,2,58.4]],"ltp":5.9,"tv":17.82,"id":61077258}]}]}
{"op":"mcm","clk":"11924817521","pt":1724192414615,"mc":[{"id":"1.232013794","rc":[{"batb":[[0,7.2,6.08],[1,2,58.4],[2,1.06,149.69]],"ltp":5.9,"tv":17.82,"id":61077258}]}]}
{"op":"mcm","clk":"11924817633","pt":1724192417300,"mc":[{"id":"1.232013794","rc":[{"batb":[[0,7.4,10],[1,7.2,6.08],[2,2,58.4]],"ltp":5.9,"tv":17.82,"id":61077258}]}]}
{"op":"mcm","clk":"11924817820","pt":1724192421012,"mc":[{"id":"1.232013794","rc":[{"batb":[[0,7.2,6.08],[1,2,58.4],[2,1.06,149.69]],"ltp":5.9,"tv":17.82,"id":61077258}]}]}
{"op":"mcm","clk":"11924817957","pt":1724192423436,"mc":[{"id":"1.232013794","rc":[{"batb":[[0,7.4,10],[1,7.2,6.08],[2,2,58.4]],"ltp":5.9,"tv":17.82,"id":61077258}]}]}
{"op":"mcm","clk":"11924818149","pt":1724192426836,"mc":[{"id":"1.232013794","rc":[{"batb":[[0,7.2,6.08],[1,2,58.4],[2,1.06,149.69]],"ltp":5.9,"tv":17.82,"id":61077258}]}]}
{"op":"mcm","clk":"11924818314","pt":1724192429822,"mc":[{"id":"1.232013794","rc":[{"batb":[[0,7.4,10],[1,7.2,6.08],[2,2,58.4]],"ltp":5.9,"tv":17.82,"id":61077258}]}]}
{"op":"mcm","clk":"11924818478","pt":1724192433159,"mc":[{"id":"1.232013794","rc":[{"batb":[[0,7.2,6.08],[1,2,58.4],[2,1.06,149.69]],"ltp":5.9,"tv":17.82,"id":61077258}]}]}
{"op":"mcm","clk":"11924818604","pt":1724192435422,"mc":[{"id":"1.232013794","rc":[{"batb":[[0,7.4,10],[1,7.2,6.08],[2,2,58.4]],"ltp":5.9,"tv":17.82,"id":61077258}]}]}
{"op":"mcm","clk":"11924818795","pt":1724192438756,"mc":[{"id":"1.232013794","rc":[{"batb":[[0,7.2,6.08],[1,2,58.4],[2,1.06,149.69]],"ltp":5.9,"tv":17.82,"id":61077258}]}]}
{"op":"mcm","clk":"11924819002","pt":1724192442563,"mc":[{"id":"1.232013794","rc":[{"batb":[[0,7.4,10],[1,7.2,6.08],[2,2,58.4]],"ltp":5.9,"tv":17.82,"id":61077258}]}]}
{"op":"mcm","clk":"11924819175","pt":1724192445862,"mc":[{"id":"1.232013794","rc":[{"batb":[[0,7.2,6.08],[1,2,58.4],[2,1.06,149.69]],"ltp":5.9,"tv":17.82,"id":61077258}]}]}
{"op":"mcm","clk":"11924819340","pt":1724192448938,"mc":[{"id":"1.232013794","rc":[{"batb":[[0,7.4,10],[1,7.2,6.08],[2,2,58.4]],"ltp":5.9,"tv":17.82,"id":61077258}]}]}
{"op":"mcm","clk":"11924819568","pt":1724192452586,"mc":[{"id":"1.232013794","rc":[{"batb":[[0,7.2,6.08],[1,2,58.4],[2,1.06,149.69]],"ltp":5.9,"tv":17.82,"id":61077258}]}]}
{"op":"mcm","clk":"11924819713","pt":1724192455061,"mc":[{"id":"1.232013794","rc":[{"batb":[[0,7.4,10],[1,7.2,6.08],[2,2,58.4]],"ltp":5.9,"tv":17.82,"id":61077258}]}]}
{"op":"mcm","clk":"11924819868","pt":1724192458591,"mc":[{"id":"1.232013794","rc":[{"batb":[[0,7.2,6.08],[1,2,58.4],[2,1.06,149.69]],"ltp":5.9,"tv":17.82,"id":61077258}]}]}
{"op":"mcm","clk":"11924820022","pt":1724192461879,"mc":[{"id":"1.232013794","rc":[{"batb":[[0,7.4,10],[1,7.2,6.08],[2,2,58.4]],"ltp":5.9,"tv":17.82,"id":61077258}]}]}
{"op":"mcm","clk":"11924820269","pt":1724192465283,"mc":[{"id":"1.232013794","rc":[{"batb":[[0,7.2,6.08],[1,2,58.4],[2,1.06,149.69]],"ltp":5.9,"tv":17.82,"id":61077258}]}]}
{"op":"mcm","clk":"11924820467","pt":1724192468573,"mc":[{"id":"1.232013794","rc":[{"batb":[[0,7.4,10],[1,7.2,6.08],[2,2,58.4]],"ltp":5.9,"tv":17.82,"id":61077258}]}]}
{"op":"mcm","clk":"11924820657","pt":1724192472013,"mc":[{"id":"1.232013794","rc":[{"batb":[[0,7.2,6.08],[1,2,58.4],[2,1.06,149.69]],"ltp":5.9,"tv":17.82,"id":61077258}]}]}
{"op":"mcm","clk":"11924820849","pt":1724192476082,"mc":[{"id":"1.232013794","rc":[{"batb":[[0,7.4,10],[1,7.2,6.08],[2,2,58.4]],"ltp":5.9,"tv":17.82,"id":61077258}]}]}
{"op":"mcm","clk":"11924820985","pt":1724192479677,"mc":[{"id":"1.232013794","rc":[{"batb":[[0,7.2,6.08],[1,2,58.4],[2,1.06,149.69]],"ltp":5.9,"tv":17.82,"id":61077258}]}]}
{"op":"mcm","clk":"11924821139","pt":1724192482508,"mc":[{"id":"1.232013794","rc":[{"batb":[[0,7.4,10],[1,7.2,6.08],[2,2,58.4]],"ltp":5.9,"tv":17.82,"id":61077258}]}]}
{"op":"mcm","clk":"11924821336","pt":1724192485799,"mc":[{"id":"1.232013794","rc":[{"batb":[[0,7.2,6.08],[1,2,58.4],[2,1.06,149.69]],"ltp":5.9,"tv":17.82,"id":61077258}]}]}
{"op":"mcm","clk":"11924821515","pt":1724192489195,"mc":[{"id":"1.232013794","rc":[{"batb":[[0,7.4,10],[1,7.2,6.08],[2,2,58.4]],"ltp":5.9,"tv":17.82,"id":61077258}]}]}
{"op":"mcm","clk":"11924821683","pt":1724192492541,"mc":[{"id":"1.232013794","rc":[{"batb":[[0,7.2,6.08],[1,2,58.4],[2,1.06,149.69]],"ltp":5.9,"tv":17.82,"id":61077258}]}]}
{"op":"mcm","clk":"11924821816","pt":1724192494903,"mc":[{"id":"1.232013794","rc":[{"batb":[[0,7.4,10],[1,7.2,6.08],[2,2,58.4]],"ltp":5.9,"tv":17.82,"id":61077258}]}]}
{"op":"mcm","clk":"11924821986","pt":1724192498196,"mc":[{"id":"1.232013794","rc":[{"batb":[[0,7.2,6.08],[1,2,58.4],[2,1.06,149.69]],"ltp":5.9,"tv":17.82,"id":61077258}]}]}
{"op":"mcm","clk":"11924822141","pt":1724192501430,"mc":[{"id":"1.232013794","rc":[{"batb":[[0,7.4,10],[1,7.2,6.08],[2,2,58.4]],"ltp":5.9,"tv":17.82,"id":61077258}]}]}
{"op":"mcm","clk":"11924822330","pt":1724192504930,"mc":[{"id":"1.232013794","rc":[{"batb":[[0,7.2,6.08],[1,2,58.4],[2,1.06,149.69]],"ltp":5.9,"tv":17.82,"id":61077258}]}]}
{"op":"mcm","clk":"11924822440","pt":1724192507410,"mc":[{"id":"1.232013794","rc":[{"batb":[[0,7.4,10],[1,7.2,6.08],[2,2,58.4]],"ltp":5.9,"tv":17.82,"id":61077258}]}]}
{"op":"mcm","clk":"11924822626","pt":1724192510924,"mc":[{"id":"1.232013794","rc":[{"batb":[[0,7.2,6.08],[1,2,58.4],[2,1.06,149.69]],"ltp":5.9,"tv":17.82,"id":61077258}]}]}
{"op":"mcm","clk":"11924822754","pt":1724192513348,"mc":[{"id":"1.232013794","rc":[{"batb":[[0,7.4,10],[1,7.2,6.08],[2,2,58.4]],"ltp":5.9,"tv":17.82,"id":61077258}]}]}
{"op":"mcm","clk":"11924822925","pt":1724192516746,"mc":[{"id":"1.232013794","rc":[{"batb":[[0,7.2,6.08],[1,2,58.4],[2,1.06,149.69]],"ltp":5.9,"tv":17.82,"id":61077258}]}]}
{"op":"mcm","clk":"11924823052","pt":1724192519116,"mc":[{"id":"1.232013794","rc":[{"batb":[[0,7.4,10],[1,7.2,6.08],[2,2,58.4]],"ltp":5.9,"tv":17.82,"id":61077258}]}]}
{"op":"mcm","clk":"11924823243","pt":1724192522421,"mc":[{"id":"1.232013794","rc":[{"batb":[[0,7.2,6.08],[1,2,58.4],[2,1.06,149.69]],"ltp":5.9,"tv":17.82,"id":61077258}]}]}
{"op":"mcm","clk":"11924823371","pt":1724192524840,"mc":[{"id":"1.232013794","rc":[{"batb":[[0,7.4,10],[1,7.2,6.08],[2,2,58.4]],"ltp":5.9,"tv":17.82,"id":61077258}]}]}
{"op":"mcm","clk":"11924823534","pt":1724192528240,"mc":[{"id":"1.232013794","rc":[{"batb":[[0,7.2,6.08],[1,2,58.4],[2,1.06,149.69]],"ltp":5.9,"tv":17.82,"id":61077258}]}]}
{"op":"mcm","clk":"11924823640","pt":1724192530666,"mc":[{"id":"1.232013794","rc":[{"batb":[[0,7.4,10],[1,7.2,6.08],[2,2,58.4]],"ltp":5.9,"tv":17.82,"id":61077258}]}]}
{"op":"mcm","clk":"11924823801","pt":1724192534162,"mc":[{"id":"1.232013794","rc":[{"batb":[[0,7.2,6.08],[1,2,58.4],[2,1.06,149.69]],"ltp":5.9,"tv":17.82,"id":61077258}]}]}
{"op":"mcm","clk":"11924823966","pt":1724192537251,"mc":[{"id":"1.232013794","rc":[{"batb":[[0,7.4,10],[1,7.2,6.08],[2,2,58.4]],"ltp":5.9,"tv":17.82,"id":61077258}]}]}
{"op":"mcm","clk":"11924824138","pt":1724192540546,"mc":[{"id":"1.232013794","rc":[{"batb":[[0,7.2,6.08],[1,2,58.4],[2,1.06,149.69]],"ltp":5.9,"tv":17.82,"id":61077258}]}]}
{"op":"mcm","clk":"11924824298","pt":1724192543993,"mc":[{"id":"1.232013794","rc":[{"batb":[[0,7.4,10],[1,7.2,6.08],[2,2,58.4]],"ltp":5.9,"tv":17.82,"id":61077258}]}]}
{"op":"mcm","clk":"11924824473","pt":1724192547181,"mc":[{"id":"1.232013794","rc":[{"batb":[[0,7.2,6.08],[1,2,58.4],[2,1.06,149.69]],"ltp":5.9,"tv":17.82,"id":61077258}]}]}
{"op":"mcm","clk":"11924824618","pt":1724192550586,"mc":[{"id":"1.232013794","rc":[{"batb":[[0,7.4,10],[1,7.2,6.08],[2,2,58.4]],"ltp":5.9,"tv":17.82,"id":61077258}]}]}
{"op":"mcm","clk":"11924824819","pt":1724192553991,"mc":[{"id":"1.232013794","rc":[{"batb":[[0,7.2,6.08],[1,2,58.4],[2,1.06,149.69]],"ltp":5.9,"tv":17.82,"id":61077258}]}]}
{"op":"mcm","clk":"11924824986","pt":1724192556714,"mc":[{"id":"1.232013794","rc":[{"batb":[[0,7.4,10],[1,7.2,6.08],[2,2,58.4]],"ltp":5.9,"tv":17.82,"id":61077258}]}]}
{"op":"mcm","clk":"11924825205","pt":1724192560319,"mc":[{"id":"1.232013794","rc":[{"batb":[[0,7.2,6.08],[1,2,58.4],[2,1.06,149.69]],"ltp":5.9,"tv":17.82,"id":61077258}]}]}
{"op":"mcm","clk":"11924825373","pt":1724192562888,"mc":[{"id":"1.232013794","rc":[{"batb":[[0,7.4,10],[1,7.2,6.08],[2,2,58.4]],"ltp":5.9,"tv":17.82,"id":61077258}]}]}
{"op":"mcm","clk":"11924825524","pt":1724192566077,"mc":[{"id":"1.232013794","rc":[{"batb":[[0,7.2,6.08],[1,2,58.4],[2,1.06,149.69]],"ltp":5.9,"tv":17.82,"id":61077258}]}]}
{"op":"mcm","clk":"11924825637","pt":1724192568497,"mc":[{"id":"1.232013794","rc":[{"batb":[[0,7.4,10],[1,7.2,6.08],[2,2,58.4]],"ltp":5.9,"tv":17.82,"id":61077258}]}]}
{"op":"mcm","clk":"11924825791","pt":1724192571882,"mc":[{"id":"1.232013794","rc":[{"batb":[[0,7.2,6.08],[1,2,58.4],[2,1.06,149.69]],"ltp":5.9,"tv":17.82,"id":61077258}]}]}
{"op":"mcm","clk":"11924825889","pt":1724192574196,"mc":[{"id":"1.232013794","rc":[{"batb":[[0,7.4,10],[1,7.2,6.08],[2,2,58.4]],"ltp":5.9,"tv":17.82,"id":61077258}]}]}
{"op":"mcm","clk":"11924826064","pt":1724192577634,"mc":[{"id":"1.232013794","rc":[{"batb":[[0,7.2,6.08],[1,2,58.4],[2,1.06,149.69]],"ltp":5.9,"tv":17.82,"id":61077258}]}]}
{"op":"mcm","clk":"11924826181","pt":1724192580045,"mc":[{"id":"1.232013794","rc":[{"batb":[[0,7.4,10],[1,7.2,6.08],[2,2,58.4]],"ltp":5.9,"tv":17.82,"id":61077258}]}]}
{"op":"mcm","clk":"11924826320","pt":1724192583226,"mc":[{"id":"1.232013794","rc":[{"batb":[[0,7.2,6.08],[1,2,58.4],[2,1.06,149.69]],"ltp":5.9,"tv":17.82,"id":61077258}]}]}
{"op":"mcm","clk":"11924826436","pt":1724192585740,"mc":[{"id":"1.232013794","rc":[{"batb":[[0,7.4,10],[1,7.2,6.08],[2,2,58.4]],"ltp":5.9,"tv":17.82,"id":61077258}]}]}
{"op":"mcm","clk":"11924826626","pt":1724192589231,"mc":[{"id":"1.232013794","rc":[{"batb":[[0,7.2,6.08],[1,2,58.4],[2,1.06,149.69]],"ltp":5.9,"tv":17.82,"id":61077258}]}]}
{"op":"mcm","clk":"11924826806","pt":1724192592460,"mc":[{"id":"1.232013794","rc":[{"batb":[[0,7.4,10],[1,7.2,6.08],[2,2,58.4]],"ltp":5.9,"tv":17.82,"id":61077258}]}]}
{"op":"mcm","clk":"11924826968","pt":1724192595837,"mc":[{"id":"1.232013794","rc":[{"batb":[[0,7.2,6.08],[1,2,58.4],[2,1.06,149.69]],"ltp":5.9,"tv":17.82,"id":61077258}]}]}
{"op":"mcm","clk":"11924827150","pt":1724192599129,"mc":[{"id":"1.232013794","rc":[{"batb":[[0,7.4,10],[1,7.2,6.08],[2,2,58.4]],"ltp":5.9,"tv":17.82,"id":61077258}]}]}
{"op":"mcm","clk":"11924827304","pt":1724192602471,"mc":[{"id":"1.232013794","rc":[{"batb":[[0,7.2,6.08],[1,2,58.4],[2,1.06,149.69]],"ltp":5.9,"tv":17.82,"id":61077258}]}]}
{"op":"mcm","clk":"11924827442","pt":1724192605051,"mc":[{"id":"1.232013794","rc":[{"batb":[[0,7.4,10],[1,7.2,6.08],[2,2,58.4]],"ltp":5.9,"tv":17.82,"id":61077258}]}]}
{"op":"mcm","clk":"11924827709","pt":1724192608436,"mc":[{"id":"1.232013794","rc":[{"batb":[[0,7.2,6.08],[1,2,58.4],[2,1.06,149.69]],"ltp":5.9,"tv":17.82,"id":61077258}]}]}
{"op":"mcm","clk":"11924827870","pt":1724192610747,"mc":[{"id":"1.232013794","rc":[{"batb":[[0,7.4,10],[1,7.2,6.08],[2,2,58.4]],"ltp":5.9,"tv":17.82,"id":61077258}]}]}
{"op":"mcm","clk":"11924828214","pt":1724192613966,"mc":[{"id":"1.232013794","rc":[{"batb":[[0,7.2,6.08],[1,2,58.4],[2,1.06,149.69]],"ltp":5.9,"tv":17.82,"id":61077258}]}]}
{"op":"mcm","clk":"11924828334","pt":1724192616270,"mc":[{"id":"1.232013794","rc":[{"batb":[[0,7.4,10],[1,7.2,6.08],[2,2,58.4]],"ltp":5.9,"tv":17.82,"id":61077258}]}]}
{"op":"mcm","clk":"11924828535","pt":1724192619853,"mc":[{"id":"1.232013794","rc":[{"batb":[[0,7.2,6.08],[1,2,58.4],[2,1.06,149.69]],"ltp":5.9,"tv":17.82,"id":61077258}]}]}
{"op":"mcm","clk":"11924828666","pt":1724192622362,"mc":[{"id":"1.232013794","rc":[{"batb":[[0,7.4,10],[1,7.2,6.08],[2,2,58.4]],"ltp":5.9,"tv":17.82,"id":61077258}]}]}
{"op":"mcm","clk":"11924828871","pt":1724192626198,"mc":[{"id":"1.232013794","rc":[{"batb":[[0,7.2,6.08],[1,2,58.4],[2,1.06,149.69]],"ltp":5.9,"tv":17.82,"id":61077258}]}]}
{"op":"mcm","clk":"11924829008","pt":1724192628508,"mc":[{"id":"1.232013794","rc":[{"batb":[[0,7.4,10],[1,7.2,6.08],[2,2,58.4]],"ltp":5.9,"tv":17.82,"id":61077258}]}]}
{"op":"mcm","clk":"11924829192","pt":1724192631896,"mc":[{"id":"1.232013794","rc":[{"batb":[[0,7.2,6.08],[1,2,58.4],[2,1.06,149.69]],"ltp":5.9,"tv":17.82,"id":61077258}]}]}
{"op":"mcm","clk":"11924829310","pt":1724192634303,"mc":[{"id":"1.232013794","rc":[{"batb":[[0,7.4,10],[1,7.2,6.08],[2,2,58.4]],"ltp":5.9,"tv":17.82,"id":61077258}]}]}
{"op":"mcm","clk":"11924829502","pt":1724192637690,"mc":[{"id":"1.232013794","rc":[{"batb":[[0,7.2,6.08],[1,2,58.4],[2,1.06,149.69]],"ltp":5.9,"tv":17.82,"id":61077258}]}]}
{"op":"mcm","clk":"11924829614","pt":1724192639988,"mc":[{"id":"1.232013794","rc":[{"batb":[[0,7.4,10],[1,7.2,6.08],[2,2,58.4]],"ltp":5.9,"tv":17.82,"id":61077258}]}]}
{"op":"mcm","clk":"11924829783","pt":1724192643320,"mc":[{"id":"1.232013794","rc":[{"batb":[[0,7.2,6.08],[1,2,58.4],[2,1.06,149.69]],"ltp":5.9,"tv":17.82,"id":61077258}]}]}
{"op":"mcm","clk":"11924829953","pt":1724192646188,"mc":[{"id":"1.232013794","rc":[{"batb":[[0,7.4,10],[1,7.2,6.08],[2,2,58.4]],"ltp":5.9,"tv":17.82,"id":61077258}]}]}
{"op":"mcm","clk":"11924830113","pt":1724192649513,"mc":[{"id":"1.232013794","rc":[{"batb":[[0,7.2,6.08],[1,2,58.4],[2,1.06,149.69]],"ltp":5.9,"tv":17.82,"id":61077258}]}]}
{"op":"mcm","clk":"11924830268","pt":1724192652026,"mc":[{"id":"1.232013794","rc":[{"batb":[[0,7.4,10],[1,7.2,6.08],[2,2,58.4]],"ltp":5.9,"tv":17.82,"id":61077258}]}]}
{"op":"mcm","clk":"11924830467","pt":1724192655450,"mc":[{"id":"1.232013794","rc":[{"batb":[[0,7.2,6.08],[1,2,58.4],[2,1.06,149.69]],"ltp":5.9,"tv":17.82,"id":61077258}]}]}
{"op":"mcm","clk":"11924830650","pt":1724192658311,"mc":[{"id":"1.232013794","rc":[{"batb":[[0,7.4,10],[1,7.2,6.08],[2,2,58.4]],"ltp":5.9,"tv":17.82,"id":61077258}]}]}
{"op":"mcm","clk":"11924830842","pt":1724192661748,"mc":[{"id":"1.232013794","rc":[{"batb":[[0,7.2,6.08],[1,2,58.4],[2,1.06,149.69]],"ltp":5.9,"tv":17.82,"id":61077258}]}]}
{"op":"mcm","clk":"11924830982","pt":1724192664166,"mc":[{"id":"1.232013794","rc":[{"batb":[[0,7.4,10],[1,7.2,6.08],[2,2,58.4]],"ltp":5.9,"tv":17.82,"id":61077258}]}]}
{"op":"mcm","clk":"11924831194","pt":1724192667556,"mc":[{"id":"1.232013794","rc":[{"batb":[[0,7.2,6.08],[1,2,58.4],[2,1.06,149.69]],"ltp":5.9,"tv":17.82,"id":61077258}]}]}
{"op":"mcm","clk":"11924831336","pt":1724192670640,"mc":[{"id":"1.232013794","rc":[{"batb":[[0,7.4,10],[1,7.2,6.08],[2,2,58.4]],"ltp":5.9,"tv":17.82,"id":61077258}]}]}
{"op":"mcm","clk":"11924831500","pt":1724192673922,"mc":[{"id":"1.232013794","rc":[{"batb":[[0,7.2,6.08],[1,2,58.4],[2,1.06,149.69]],"ltp":5.9,"tv":17.82,"id":61077258}]}]}
{"op":"mcm","clk":"11924831722","pt":1724192677772,"mc":[{"id":"1.232013794","rc":[{"batb":[[0,7.4,10],[1,7.2,6.08],[2,2,58.4]],"ltp":5.9,"tv":17.82,"id":61077258}]}]}
{"op":"mcm","clk":"11924831906","pt":1724192681358,"mc":[{"id":"1.232013794","rc":[{"batb":[[0,7.2,6.08],[1,2,58.4],[2,1.06,149.69]],"ltp":5.9,"tv":17.82,"id":61077258}]}]}
{"op":"mcm","clk":"11924832047","pt":1724192683770,"mc":[{"id":"1.232013794","rc":[{"batb":[[0,7.4,10],[1,7.2,6.08],[2,2,58.4]],"ltp":5.9,"tv":17.82,"id":61077258}]}]}
{"op":"mcm","clk":"11924832244","pt":1724192687171,"mc":[{"id":"1.232013794","rc":[{"batb":[[0,7.2,6.08],[1,2,58.4],[2,1.06,149.69]],"ltp":5.9,"tv":17.82,"id":61077258}]}]}
{"op":"mcm","clk":"11924832368","pt":1724192689478,"mc":[{"id":"1.232013794","rc":[{"batb":[[0,7.4,10],[1,7.2,6.08],[2,2,58.4]],"ltp":5.9,"tv":17.82,"id":61077258}]}]}
{"op":"mcm","clk":"11924832521","pt":1724192692807,"mc":[{"id":"1.232013794","rc":[{"batb":[[0,7.2,6.08],[1,2,58.4],[2,1.06,149.69]],"ltp":5.9,"tv":17.82,"id":61077258}]}]}
{"op":"mcm","clk":"11924832608","pt":1724192695066,"mc":[{"id":"1.232013794","rc":[{"batb":[[0,7.4,10],[1,7.2,6.08],[2,2,58.4]],"ltp":5.9,"tv":17.82,"id":61077258}]}]}
{"op":"mcm","clk":"11924832784","pt":1724192698455,"mc":[{"id":"1.232013794","rc":[{"batb":[[0,7.2,6.08],[1,2,58.4],[2,1.06,149.69]],"ltp":5.9,"tv":17.82,"id":61077258}]}]}
{"op":"mcm","clk":"11924832900","pt":1724192700889,"mc":[{"id":"1.232013794","rc":[{"batb":[[0,7.4,10],[1,7.2,6.08],[2,2,58.4]],"ltp":5.9,"tv":17.82,"id":61077258}]}]}
{"op":"mcm","clk":"11924833079","pt":1724192704377,"mc":[{"id":"1.232013794","rc":[{"batb":[[0,7.2,6.08],[1,2,58.4],[2,1.06,149.69]],"ltp":5.9,"tv":17.82,"id":61077258}]}]}
{"op":"mcm","clk":"11924833194","pt":1724192706890,"mc":[{"id":"1.232013794","rc":[{"batb":[[0,7.4,10],[1,7.2,6.08],[2,2,58.4]],"ltp":5.9,"tv":17.82,"id":61077258}]}]}
{"op":"mcm","clk":"11924833384","pt":1724192710281,"mc":[{"id":"1.232013794","rc":[{"batb":[[0,7.2,6.08],[1,2,58.4],[2,1.06,149.69]],"ltp":5.9,"tv":17.82,"id":61077258}]}]}
{"op":"mcm","clk":"11924833691","pt":1724192716189,"mc":[{"id":"1.232013794","rc":[{"batb":[[0,7.4,10],[1,7.2,6.08],[2,2,58.4]],"ltp":5.9,"tv":17.82,"id":61077258}]}]}
{"op":"mcm","clk":"11924833851","pt":1724192719986,"mc":[{"id":"1.232013794","rc":[{"batb":[[0,7.2,6.08],[1,2,58.4],[2,1.06,149.69]],"ltp":5.9,"tv":17.82,"id":61077258}]}]}
{"op":"mcm","clk":"11924833966","pt":1724192722504,"mc":[{"id":"1.232013794","rc":[{"batb":[[0,7.4,10],[1,7.2,6.08],[2,2,58.4]],"ltp":5.9,"tv":17.82,"id":61077258}]}]}
{"op":"mcm","clk":"11924834125","pt":1724192725793,"mc":[{"id":"1.232013794","rc":[{"batb":[[0,7.2,6.08],[1,2,58.4],[2,1.06,149.69]],"ltp":5.9,"tv":17.82,"id":61077258}]}]}
{"op":"mcm","clk":"11924834241","pt":1724192728196,"mc":[{"id":"1.232013794","rc":[{"batb":[[0,7.4,10],[1,7.2,6.08],[2,2,58.4]],"ltp":5.9,"tv":17.82,"id":61077258}]}]}
{"op":"mcm","clk":"11924834393","pt":1724192731735,"mc":[{"id":"1.232013794","rc":[{"batb":[[0,7.2,6.08],[1,2,58.4],[2,1.06,149.69]],"ltp":5.9,"tv":17.82,"id":61077258}]}]}
{"op":"mcm","clk":"11924834507","pt":1724192734000,"mc":[{"id":"1.232013794","rc":[{"batb":[[0,7.4,10],[1,7.2,6.08],[2,2,58.4]],"ltp":5.9,"tv":17.82,"id":61077258}]}]}
{"op":"mcm","clk":"11924834697","pt":1724192737342,"mc":[{"id":"1.232013794","rc":[{"batb":[[0,7.2,6.08],[1,2,58.4],[2,1.06,149.69]],"ltp":5.9,"tv":17.82,"id":61077258}]}]}
{"op":"mcm","clk":"11924834822","pt":1724192739797,"mc":[{"id":"1.232013794","rc":[{"batb":[[0,7.4,10],[1,7.2,6.08],[2,2,58.4]],"ltp":5.9,"tv":17.82,"id":61077258}]}]}
{"op":"mcm","clk":"11924835012","pt":1724192743299,"mc":[{"id":"1.232013794","rc":[{"batb":[[0,7.2,6.08],[1,2,58.4],[2,1.06,149.69]],"ltp":5.9,"tv":17.82,"id":61077258}]}]}
{"op":"mcm","clk":"11924835119","pt":1724192745725,"mc":[{"id":"1.232013794","rc":[{"batb":[[0,7.4,10],[1,7.2,6.08],[2,2,58.4]],"ltp":5.9,"tv":17.82,"id":61077258}]}]}
{"op":"mcm","clk":"11924835286","pt":1724192749121,"mc":[{"id":"1.232013794","rc":[{"batb":[[0,7.2,6.08],[1,2,58.4],[2,1.06,149.69]],"ltp":5.9,"tv":17.82,"id":61077258}]}]}
{"op":"mcm","clk":"11924835395","pt":1724192751941,"mc":[{"id":"1.232013794","rc":[{"batb":[[0,7.4,10],[1,7.2,6.08],[2,2,58.4]],"ltp":5.9,"tv":17.82,"id":61077258}]}]}
{"op":"mcm","clk":"11924835513","pt":1724192755318,"mc":[{"id":"1.232013794","rc":[{"batb":[[0,7.2,6.08],[1,2,58.4],[2,1.06,149.69]],"ltp":5.9,"tv":17.82,"id":61077258}]}]}
{"op":"mcm","clk":"11924835614","pt":1724192757721,"mc":[{"id":"1.232013794","rc":[{"batb":[[0,7.4,10],[1,7.2,6.08],[2,2,58.4]],"ltp":5.9,"tv":17.82,"id":61077258}]}]}
{"op":"mcm","clk":"11924835769","pt":1724192761064,"mc":[{"id":"1.232013794","rc":[{"batb":[[0,7.2,6.08],[1,2,58.4],[2,1.06,149.69]],"ltp":5.9,"tv":17.82,"id":61077258}]}]}
{"op":"mcm","clk":"11924835905","pt":1724192763435,"mc":[{"id":"1.232013794","rc":[{"batb":[[0,7.4,10],[1,7.2,6.08],[2,2,58.4]],"ltp":5.9,"tv":17.82,"id":61077258}]}]}
{"op":"mcm","clk":"11924836111","pt":1724192766963,"mc":[{"id":"1.232013794","rc":[{"batb":[[0,7.2,6.08],[1,2,58.4],[2,1.06,149.69]],"ltp":5.9,"tv":17.82,"id":61077258}]}]}
{"op":"mcm","clk":"11924836223","pt":1724192769368,"mc":[{"id":"1.232013794","rc":[{"batb":[[0,7.4,10],[1,7.2,6.08],[2,2,58.4]],"ltp":5.9,"tv":17.82,"id":61077258}]}]}
{"op":"mcm","clk":"11924836392","pt":1724192772755,"mc":[{"id":"1.232013794","rc":[{"batb":[[0,7.2,6.08],[1,2,58.4],[2,1.06,149.69]],"ltp":5.9,"tv":17.82,"id":61077258}]}]}
{"op":"mcm","clk":"11924836508","pt":1724192775272,"mc":[{"id":"1.232013794","rc":[{"batb":[[0,7.4,10],[1,7.2,6.08],[2,2,58.4]],"ltp":5.9,"tv":17.82,"id":61077258}]}]}
{"op":"mcm","clk":"11924836670","pt":1724192778666,"mc":[{"id":"1.232013794","rc":[{"batb":[[0,7.2,6.08],[1,2,58.4],[2,1.06,149.69]],"ltp":5.9,"tv":17.82,"id":61077258}]}]}
{"op":"mcm","clk":"11924836799","pt":1724192781182,"mc":[{"id":"1.232013794","rc":[{"batb":[[0,7.4,10],[1,7.2,6.08],[2,2,58.4]],"ltp":5.9,"tv":17.82,"id":61077258}]}]}
{"op":"mcm","clk":"11924836972","pt":1724192784461,"mc":[{"id":"1.232013794","rc":[{"batb":[[0,7.2,6.08],[1,2,58.4],[2,1.06,149.69]],"ltp":5.9,"tv":17.82,"id":61077258}]}]}
{"op":"mcm","clk":"11924837137","pt":1724192787685,"mc":[{"id":"1.232013794","rc":[{"batb":[[0,7.4,10],[1,7.2,6.08],[2,2,58.4]],"ltp":5.9,"tv":17.82,"id":61077258}]}]}
{"op":"mcm","clk":"11924837294","pt":1724192791072,"mc":[{"id":"1.232013794","rc":[{"batb":[[0,7.2,6.08],[1,2,58.4],[2,1.06,149.69]],"ltp":5.9,"tv":17.82,"id":61077258}]}]}
{"op":"mcm","clk":"11924837434","pt":1724192793789,"mc":[{"id":"1.232013794","rc":[{"batb":[[0,7.4,10],[1,7.2,6.08],[2,2,58.4]],"ltp":5.9,"tv":17.82,"id":61077258}]}]}
{"op":"mcm","clk":"11924837594","pt":1724192797279,"mc":[{"id":"1.232013794","rc":[{"batb":[[0,7.2,6.08],[1,2,58.4],[2,1.06,149.69]],"ltp":5.9,"tv":17.82,"id":61077258}]}]}
{"op":"mcm","clk":"11924837726","pt":1724192799686,"mc":[{"id":"1.232013794","rc":[{"batb":[[0,7.4,10],[1,7.2,6.08],[2,2,58.4]],"ltp":5.9,"tv":17.82,"id":61077258}]}]}
{"op":"mcm","clk":"11924837926","pt":1724192802963,"mc":[{"id":"1.232013794","rc":[{"batb":[[0,7.2,6.08],[1,2,58.4],[2,1.06,149.69]],"ltp":5.9,"tv":17.82,"id":61077258}]}]}
{"op":"mcm","clk":"11924838059","pt":1724192805366,"mc":[{"id":"1.232013794","rc":[{"batb":[[0,7.4,10],[1,7.2,6.08],[2,2,58.4]],"ltp":5.9,"tv":17.82,"id":61077258}]}]}
{"op":"mcm","clk":"11924838224","pt":1724192808908,"mc":[{"id":"1.232013794","rc":[{"batb":[[0,7.2,6.08],[1,2,58.4],[2,1.06,149.69]],"ltp":5.9,"tv":17.82,"id":61077258}]}]}
{"op":"mcm","clk":"11924838329","pt":1724192811314,"mc":[{"id":"1.232013794","rc":[{"batb":[[0,7.4,10],[1,7.2,6.08],[2,2,58.4]],"ltp":5.9,"tv":17.82,"id":61077258}]}]}
{"op":"mcm","clk":"11924838475","pt":1724192814600,"mc":[{"id":"1.232013794","rc":[{"batb":[[0,7.2,6.08],[1,2,58.4],[2,1.06,149.69]],"ltp":5.9,"tv":17.82,"id":61077258}]}]}
{"op":"mcm","clk":"11924838610","pt":1724192817019,"mc":[{"id":"1.232013794","rc":[{"batb":[[0,7.4,10],[1,7.2,6.08],[2,2,58.4]],"ltp":5.9,"tv":17.82,"id":61077258}]}]}
{"op":"mcm","clk":"11924838786","pt":1724192820415,"mc":[{"id":"1.232013794","rc":[{"batb":[[0,7.2,6.08],[1,2,58.4],[2,1.06,149.69]],"ltp":5.9,"tv":17.82,"id":61077258}]}]}
{"op":"mcm","clk":"11924838928","pt":1724192822941,"mc":[{"id":"1.232013794","rc":[{"batb":[[0,7.4,10],[1,7.2,6.08],[2,2,58.4]],"ltp":5.9,"tv":17.82,"id":61077258}]}]}
{"op":"mcm","clk":"11924839116","pt":1724192826326,"mc":[{"id":"1.232013794","rc":[{"batb":[[0,7.2,6.08],[1,2,58.4],[2,1.06,149.69]],"ltp":5.9,"tv":17.82,"id":61077258}]}]}
{"op":"mcm","clk":"11924839295","pt":1724192829516,"mc":[{"id":"1.232013794","rc":[{"batb":[[0,7.4,10],[1,7.2,6.08],[2,2,58.4]],"ltp":5.9,"tv":17.82,"id":61077258}]}]}
{"op":"mcm","clk":"11924839461","pt":1724192832846,"mc":[{"id":"1.232013794","rc":[{"batb":[[0,7.2,6.08],[1,2,58.4],[2,1.06,149.69]],"ltp":5.9,"tv":17.82,"id":61077258}]}]}
{"op":"mcm","clk":"11924839642","pt":1724192836652,"mc":[{"id":"1.232013794","rc":[{"batb":[[0,7.4,10],[1,7.2,6.08],[2,2,58.4]],"ltp":5.9,"tv":17.82,"id":61077258}]}]}
{"op":"mcm","clk":"11924839830","pt":1724192839946,"mc":[{"id":"1.232013794","rc":[{"batb":[[0,7.2,6.08],[1,2,58.4],[2,1.06,149.69]],"ltp":5.9,"tv":17.82,"id":61077258}]}]}
{"op":"mcm","clk":"11924839989","pt":1724192843444,"mc":[{"id":"1.232013794","rc":[{"batb":[[0,7.4,10],[1,7.2,6.08],[2,2,58.4]],"ltp":5.9,"tv":17.82,"id":61077258}]}]}
{"op":"mcm","clk":"11924840161","pt":1724192846942,"mc":[{"id":"1.232013794","rc":[{"batb":[[0,7.2,6.08],[1,2,58.4],[2,1.06,149.69]],"ltp":5.9,"tv":17.82,"id":61077258}]}]}
{"op":"mcm","clk":"11924840307","pt":1724192849670,"mc":[{"id":"1.232013794","rc":[{"batb":[[0,7.4,10],[1,7.2,6.08],[2,2,58.4]],"ltp":5.9,"tv":17.82,"id":61077258}]}]}
{"op":"mcm","clk":"11924840493","pt":1724192853034,"mc":[{"id":"1.232013794","rc":[{"batb":[[0,7.2,6.08],[1,2,58.4],[2,1.06,149.69]],"ltp":5.9,"tv":17.82,"id":61077258}]}]}
{"op":"mcm","clk":"11924840636","pt":1724192855553,"mc":[{"id":"1.232013794","rc":[{"batb":[[0,7.4,10],[1,7.2,6.08],[2,2,58.4]],"ltp":5.9,"tv":17.82,"id":61077258}]}]}
{"op":"mcm","clk":"11924840800","pt":1724192858945,"mc":[{"id":"1.232013794","rc":[{"batb":[[0,7.2,6.08],[1,2,58.4],[2,1.06,149.69]],"ltp":5.9,"tv":17.82,"id":61077258}]}]}
{"op":"mcm","clk":"11924840936","pt":1724192861354,"mc":[{"id":"1.232013794","rc":[{"batb":[[0,7.4,10],[1,7.2,6.08],[2,2,58.4]],"ltp":5.9,"tv":17.82,"id":61077258}]}]}
{"op":"mcm","clk":"11924841122","pt":1724192864650,"mc":[{"id":"1.232013794","rc":[{"batb":[[0,7.2,6.08],[1,2,58.4],[2,1.06,149.69]],"ltp":5.9,"tv":17.82,"id":61077258}]}]}
{"op":"mcm","clk":"11924841248","pt":1724192867066,"mc":[{"id":"1.232013794","rc":[{"batb":[[0,7.4,10],[1,7.2,6.08],[2,2,58.4]],"ltp":5.9,"tv":17.82,"id":61077258}]}]}
{"op":"mcm","clk":"11924841420","pt":1724192870455,"mc":[{"id":"1.232013794","rc":[{"batb":[[0,7.2,6.08],[1,2,58.4],[2,1.06,149.69]],"ltp":5.9,"tv":17.82,"id":61077258}]}]}
{"op":"mcm","clk":"11924841589","pt":1724192873680,"mc":[{"id":"1.232013794","rc":[{"batb":[[0,7.4,10],[1,7.2,6.08],[2,2,58.4]],"ltp":5.9,"tv":17.82,"id":61077258}]}]}
{"op":"mcm","clk":"11924841748","pt":1724192876866,"mc":[{"id":"1.232013794","rc":[{"batb":[[0,7.2,6.08],[1,2,58.4],[2,1.06,149.69]],"ltp":5.9,"tv":17.82,"id":61077258}]}]}
{"op":"mcm","clk":"11924841932","pt":1724192880147,"mc":[{"id":"1.232013794","rc":[{"batb":[[0,7.4,10],[1,7.2,6.08],[2,2,58.4]],"ltp":5.9,"tv":17.82,"id":61077258}]}]}
{"op":"mcm","clk":"11924842130","pt":1724192883687,"mc":[{"id":"1.232013794","rc":[{"batb":[[0,7.2,6.08],[1,2,58.4],[2,1.06,149.69]],"ltp":5.9,"tv":17.82,"id":61077258}]}]}
{"op":"mcm","clk":"11924842259","pt":1724192886194,"mc":[{"id":"1.232013794","rc":[{"batb":[[0,7.4,10],[1,7.2,6.08],[2,2,58.4]],"ltp":5.9,"tv":17.82,"id":61077258}]}]}
{"op":"mcm","clk":"11924842427","pt":1724192889587,"mc":[{"id":"1.232013794","rc":[{"batb":[[0,7.2,6.08],[1,2,58.4],[2,1.06,149.69]],"ltp":5.9,"tv":17.82,"id":61077258}]}]}
{"op":"mcm","clk":"11924842546","pt":1724192891990,"mc":[{"id":"1.232013794","rc":[{"batb":[[0,7.4,10],[1,7.2,6.08],[2,2,58.4]],"ltp":5.9,"tv":17.82,"id":61077258}]}]}
{"op":"mcm","clk":"11924842697","pt":1724192895280,"mc":[{"id":"1.232013794","rc":[{"batb":[[0,7.2,6.08],[1,2,58.4],[2,1.06,149.69]],"ltp":5.9,"tv":17.82,"id":61077258}]}]}
{"op":"mcm","clk":"11924842850","pt":1724192898310,"mc":[{"id":"1.232013794","rc":[{"batb":[[0,7.4,10],[1,7.2,6.08],[2,2,58.4]],"ltp":5.9,"tv":17.82,"id":61077258}]}]}
{"op":"mcm","clk":"11924843051","pt":1724192901694,"mc":[{"id":"1.232013794","rc":[{"batb":[[0,7.2,6.08],[1,2,58.4],[2,1.06,149.69]],"ltp":5.9,"tv":17.82,"id":61077258}]}]}
{"op":"mcm","clk":"11924843182","pt":1724192904309,"mc":[{"id":"1.232013794","rc":[{"batb":[[0,7.4,10],[1,7.2,6.08],[2,2,58.4]],"ltp":5.9,"tv":17.82,"id":61077258}]}]}
{"op":"mcm","clk":"11924843457","pt":1724192907591,"mc":[{"id":"1.232013794","rc":[{"batb":[[0,7.2,6.08],[1,2,58.4],[2,1.06,149.69]],"ltp":5.9,"tv":17.82,"id":61077258}]}]}
{"op":"mcm","clk":"11924843590","pt":1724192909812,"mc":[{"id":"1.232013794","rc":[{"batb":[[0,7.4,10],[1,7.2,6.08],[2,2,58.4]],"ltp":5.9,"tv":17.82,"id":61077258}]}]}
{"op":"mcm","clk":"11924843850","pt":1724192913413,"mc":[{"id":"1.232013794","rc":[{"batb":[[0,7.2,6.08],[1,2,58.4],[2,1.06,149.69]],"ltp":5.9,"tv":17.82,"id":61077258}]}]}
{"op":"mcm","clk":"11924843995","pt":1724192916499,"mc":[{"id":"1.232013794","rc":[{"batb":[[0,7.4,10],[1,7.2,6.08],[2,2,58.4]],"ltp":5.9,"tv":17.82,"id":61077258}]}]}
{"op":"mcm","clk":"11924844141","pt":1724192920054,"mc":[{"id":"1.232013794","rc":[{"batb":[[0,7.2,6.08],[1,2,58.4],[2,1.06,149.69]],"ltp":5.9,"tv":17.82,"id":61077258}]}]}
{"op":"mcm","clk":"11924844276","pt":1724192923234,"mc":[{"id":"1.232013794","rc":[{"batb":[[0,7.4,10],[1,7.2,6.08],[2,2,58.4]],"ltp":5.9,"tv":17.82,"id":61077258}]}]}
{"op":"mcm","clk":"11924844449","pt":1724192926621,"mc":[{"id":"1.232013794","rc":[{"batb":[[0,7.2,6.08],[1,2,58.4],[2,1.06,149.69]],"ltp":5.9,"tv":17.82,"id":61077258}]}]}
{"op":"mcm","clk":"11924844576","pt":1724192929244,"mc":[{"id":"1.232013794","rc":[{"batb":[[0,7.4,10],[1,7.2,6.08],[2,2,58.4]],"ltp":5.9,"tv":17.82,"id":61077258}]}]}
{"op":"mcm","clk":"11924844704","pt":1724192932530,"mc":[{"id":"1.232013794","rc":[{"batb":[[0,7.2,6.08],[1,2,58.4],[2,1.06,149.69]],"ltp":5.9,"tv":17.82,"id":61077258}]}]}
{"op":"mcm","clk":"11924844823","pt":1724192935259,"mc":[{"id":"1.232013794","rc":[{"batb":[[0,7.4,10],[1,7.2,6.08],[2,2,58.4]],"ltp":5.9,"tv":17.82,"id":61077258}]}]}
{"op":"mcm","clk":"11924844953","pt":1724192938551,"mc":[{"id":"1.232013794","rc":[{"batb":[[0,7.2,6.08],[1,2,58.4],[2,1.06,149.69]],"ltp":5.9,"tv":17.82,"id":61077258}]}]}
{"op":"mcm","clk":"11924845086","pt":1724192941287,"mc":[{"id":"1.232013794","rc":[{"batb":[[0,7.4,10],[1,7.2,6.08],[2,2,58.4]],"ltp":5.9,"tv":17.82,"id":61077258}]}]}
{"op":"mcm","clk":"11924845294","pt":1724192944880,"mc":[{"id":"1.232013794","rc":[{"batb":[[0,7.2,6.08],[1,2,58.4],[2,1.06,149.69]],"ltp":5.9,"tv":17.82,"id":61077258}]}]}
{"op":"mcm","clk":"11924845471","pt":1724192948477,"mc":[{"id":"1.232013794","rc":[{"batb":[[0,7.4,10],[1,7.2,6.08],[2,2,58.4]],"ltp":5.9,"tv":17.82,"id":61077258}]}]}
{"op":"mcm","clk":"11924845642","pt":1724192951773,"mc":[{"id":"1.232013794","rc":[{"batb":[[0,7.2,6.08],[1,2,58.4],[2,1.06,149.69]],"ltp":5.9,"tv":17.82,"id":61077258}]}]}
{"op":"mcm","clk":"11924845807","pt":1724192954801,"mc":[{"id":"1.232013794","rc":[{"batb":[[0,7.4,10],[1,7.2,6.08],[2,2,58.4]],"ltp":5.9,"tv":17.82,"id":61077258}]}]}
{"op":"mcm","clk":"11924845978","pt":1724192958399,"mc":[{"id":"1.232013794","rc":[{"batb":[[0,7.2,6.08],[1,2,58.4],[2,1.06,149.69]],"ltp":5.9,"tv":17.82,"id":61077258}]}]}
{"op":"mcm","clk":"11924846100","pt":1724192960974,"mc":[{"id":"1.232013794","rc":[{"batb":[[0,7.4,10],[1,7.2,6.08],[2,2,58.4]],"ltp":5.9,"tv":17.82,"id":61077258}]}]}
{"op":"mcm","clk":"11924846267","pt":1724192964287,"mc":[{"id":"1.232013794","rc":[{"batb":[[0,7.2,6.08],[1,2,58.4],[2,1.06,149.69]],"ltp":5.9,"tv":17.82,"id":61077258}]}]}
{"op":"mcm","clk":"11924846380","pt":1724192966705,"mc":[{"id":"1.232013794","rc":[{"batb":[[0,7.4,10],[1,7.2,6.08],[2,2,58.4]],"ltp":5.9,"tv":17.82,"id":61077258}]}]}
{"op":"mcm","clk":"11924846539","pt":1724192970199,"mc":[{"id":"1.232013794","rc":[{"batb":[[0,7.2,6.08],[1,2,58.4],[2,1.06,149.69]],"ltp":5.9,"tv":17.82,"id":61077258}]}]}
{"op":"mcm","clk":"11924846660","pt":1724192972624,"mc":[{"id":"1.232013794","rc":[{"batb":[[0,7.4,10],[1,7.2,6.08],[2,2,58.4]],"ltp":5.9,"tv":17.82,"id":61077258}]}]}
{"op":"mcm","clk":"11924846829","pt":1724192975916,"mc":[{"id":"1.232013794","rc":[{"batb":[[0,7.2,6.08],[1,2,58.4],[2,1.06,149.69]],"ltp":5.9,"tv":17.82,"id":61077258}]}]}
{"op":"mcm","clk":"11924846942","pt":1724192978283,"mc":[{"id":"1.232013794","rc":[{"batb":[[0,7.4,10],[1,7.2,6.08],[2,2,58.4]],"ltp":5.9,"tv":17.82,"id":61077258}]}]}
{"op":"mcm","clk":"11924847109","pt":1724192981619,"mc":[{"id":"1.232013794","rc":[{"batb":[[0,7.2,6.08],[1,2,58.4],[2,1.06,149.69]],"ltp":5.9,"tv":17.82,"id":61077258}]}]}
{"op":"mcm","clk":"11924847235","pt":1724192984028,"mc":[{"id":"1.232013794","rc":[{"batb":[[0,7.4,10],[1,7.2,6.08],[2,2,58.4]],"ltp":5.9,"tv":17.82,"id":61077258}]}]}
{"op":"mcm","clk":"11924847387","pt":1724192987335,"mc":[{"id":"1.232013794","rc":[{"batb":[[0,7.2,6.08],[1,2,58.4],[2,1.06,149.69]],"ltp":5.9,"tv":17.82,"id":61077258}]}]}
{"op":"mcm","clk":"11924847525","pt":1724192989705,"mc":[{"id":"1.232013794","rc":[{"batb":[[0,7.4,10],[1,7.2,6.08],[2,2,58.4]],"ltp":5.9,"tv":17.82,"id":61077258}]}]}
{"op":"mcm","clk":"11924847699","pt":1724192993138,"mc":[{"id":"1.232013794","rc":[{"batb":[[0,7.2,6.08],[1,2,58.4],[2,1.06,149.69]],"ltp":5.9,"tv":17.82,"id":61077258}]}]}
{"op":"mcm","clk":"11924847819","pt":1724192995505,"mc":[{"id":"1.232013794","rc":[{"batb":[[0,7.4,10],[1,7.2,6.08],[2,2,58.4]],"ltp":5.9,"tv":17.82,"id":61077258}]}]}
{"op":"mcm","clk":"11924847983","pt":1724192998837,"mc":[{"id":"1.232013794","rc":[{"batb":[[0,7.2,6.08],[1,2,58.4],[2,1.06,149.69]],"ltp":5.9,"tv":17.82,"id":61077258}]}]}
{"op":"mcm","clk":"11924848100","pt":1724193001212,"mc":[{"id":"1.232013794","rc":[{"batb":[[0,7.4,10],[1,7.2,6.08],[2,2,58.4]],"ltp":5.9,"tv":17.82,"id":61077258}]}]}
{"op":"mcm","clk":"11924848309","pt":1724193004726,"mc":[{"id":"1.232013794","rc":[{"batb":[[0,7.2,6.08],[1,2,58.4],[2,1.06,149.69]],"ltp":5.9,"tv":17.82,"id":61077258}]}]}
{"op":"mcm","clk":"11924848474","pt":1724193007254,"mc":[{"id":"1.232013794","rc":[{"batb":[[0,7.4,10],[1,7.2,6.08],[2,2,58.4]],"ltp":5.9,"tv":17.82,"id":61077258}]}]}
{"op":"mcm","clk":"11924848669","pt":1724193010657,"mc":[{"id":"1.232013794","rc":[{"batb":[[0,7.2,6.08],[1,2,58.4],[2,1.06,149.69]],"ltp":5.9,"tv":17.82,"id":61077258}]}]}
{"op":"mcm","clk":"11924848838","pt":1724193013856,"mc":[{"id":"1.232013794","rc":[{"batb":[[0,7.4,10],[1,7.2,6.08],[2,2,58.4]],"ltp":5.9,"tv":17.82,"id":61077258}]}]}
{"op":"mcm","clk":"11924849003","pt":1724193017259,"mc":[{"id":"1.232013794","rc":[{"batb":[[0,7.2,6.08],[1,2,58.4],[2,1.06,149.69]],"ltp":5.9,"tv":17.82,"id":61077258}]}]}
{"op":"mcm","clk":"11924849143","pt":1724193019943,"mc":[{"id":"1.232013794","rc":[{"batb":[[0,7.4,10],[1,7.2,6.08],[2,2,58.4]],"ltp":5.9,"tv":17.82,"id":61077258}]}]}
{"op":"mcm","clk":"11924849321","pt":1724193023489,"mc":[{"id":"1.232013794","rc":[{"batb":[[0,7.2,6.08],[1,2,58.4],[2,1.06,149.69]],"ltp":5.9,"tv":17.82,"id":61077258}]}]}
{"op":"mcm","clk":"11924849481","pt":1724193026668,"mc":[{"id":"1.232013794","rc":[{"batb":[[0,7.4,10],[1,7.2,6.08],[2,2,58.4]],"ltp":5.9,"tv":17.82,"id":61077258}]}]}
{"op":"mcm","clk":"11924849639","pt":1724193029967,"mc":[{"id":"1.232013794","rc":[{"batb":[[0,7.2,6.08],[1,2,58.4],[2,1.06,149.69]],"ltp":5.9,"tv":17.82,"id":61077258}]}]}
{"op":"mcm","clk":"11924849752","pt":1724193032291,"mc":[{"id":"1.232013794","rc":[{"batb":[[0,7.4,10],[1,7.2,6.08],[2,2,58.4]],"ltp":5.9,"tv":17.82,"id":61077258}]}]}
{"op":"mcm","clk":"11924849946","pt":1724193035669,"mc":[{"id":"1.232013794","rc":[{"batb":[[0,7.2,6.08],[1,2,58.4],[2,1.06,149.69]],"ltp":5.9,"tv":17.82,"id":61077258}]}]}
{"op":"mcm","clk":"11924850064","pt":1724193037777,"mc":[{"id":"1.232013794","rc":[{"batb":[[0,7.4,10],[1,7.2,6.08],[2,2,58.4]],"ltp":5.9,"tv":17.82,"id":61077258}]}]}
{"op":"mcm","clk":"11924850273","pt":1724193041371,"mc":[{"id":"1.232013794","rc":[{"batb":[[0,7.2,6.08],[1,2,58.4],[2,1.06,149.69]],"ltp":5.9,"tv":17.82,"id":61077258}]}]}
{"op":"mcm","clk":"11924850426","pt":1724193043795,"mc":[{"id":"1.232013794","rc":[{"batb":[[0,7.4,10],[1,7.2,6.08],[2,2,58.4]],"ltp":5.9,"tv":17.82,"id":61077258}]}]}
{"op":"mcm","clk":"11924850625","pt":1724193047088,"mc":[{"id":"1.232013794","rc":[{"batb":[[0,7.2,6.08],[1,2,58.4],[2,1.06,149.69]],"ltp":5.9,"tv":17.82,"id":61077258}]}]}
{"op":"mcm","clk":"11924850786","pt":1724193049599,"mc":[{"id":"1.232013794","rc":[{"batb":[[0,7.4,10],[1,7.2,6.08],[2,2,58.4]],"ltp":5.9,"tv":17.82,"id":61077258}]}]}
{"op":"mcm","clk":"11924850976","pt":1724193052885,"mc":[{"id":"1.232013794","rc":[{"batb":[[0,7.2,6.08],[1,2,58.4],[2,1.06,149.69]],"ltp":5.9,"tv":17.82,"id":61077258}]}]}
{"op":"mcm","clk":"11924851117","pt":1724193055714,"mc":[{"id":"1.232013794","rc":[{"batb":[[0,7.4,10],[1,7.2,6.08],[2,2,58.4]],"ltp":5.9,"tv":17.82,"id":61077258}]}]}
{"op":"mcm","clk":"11924851289","pt":1724193059108,"mc":[{"id":"1.232013794","rc":[{"batb":[[0,7.2,6.08],[1,2,58.4],[2,1.06,149.69]],"ltp":5.9,"tv":17.82,"id":61077258}]}]}
{"op":"mcm","clk":"11924851500","pt":1724193062818,"mc":[{"id":"1.232013794","rc":[{"batb":[[0,7.4,10],[1,7.2,6.08],[2,2,58.4]],"ltp":5.9,"tv":17.82,"id":61077258}]}]}
{"op":"mcm","clk":"11924851667","pt":1724193066108,"mc":[{"id":"1.232013794","rc":[{"batb":[[0,7.2,6.08],[1,2,58.4],[2,1.06,149.69]],"ltp":5.9,"tv":17.82,"id":61077258}]}]}
{"op":"mcm","clk":"11924851834","pt":1724193069136,"mc":[{"id":"1.232013794","rc":[{"batb":[[0,7.4,10],[1,7.2,6.08],[2,2,58.4]],"ltp":5.9,"tv":17.82,"id":61077258}]}]}
{"op":"mcm","clk":"11924852017","pt":1724193072733,"mc":[{"id":"1.232013794","rc":[{"batb":[[0,7.2,6.08],[1,2,58.4],[2,1.06,149.69]],"ltp":5.9,"tv":17.82,"id":61077258}]}]}
{"op":"mcm","clk":"11924852176","pt":1724193075108,"mc":[{"id":"1.232013794","rc":[{"batb":[[0,7.4,10],[1,7.2,6.08],[2,2,58.4]],"ltp":5.9,"tv":17.82,"id":61077258}]}]}
{"op":"mcm","clk":"11924852365","pt":1724193078553,"mc":[{"id":"1.232013794","rc":[{"batb":[[0,7.2,6.08],[1,2,58.4],[2,1.06,149.69]],"ltp":5.9,"tv":17.82,"id":61077258}]}]}
{"op":"mcm","clk":"11924852500","pt":1724193080913,"mc":[{"id":"1.232013794","rc":[{"batb":[[0,7.4,10],[1,7.2,6.08],[2,2,58.4]],"ltp":5.9,"tv":17.82,"id":61077258}]}]}
{"op":"mcm","clk":"11924852692","pt":1724193084448,"mc":[{"id":"1.232013794","rc":[{"batb":[[0,7.2,6.08],[1,2,58.4],[2,1.06,149.69]],"ltp":5.9,"tv":17.82,"id":61077258}]}]}
{"op":"mcm","clk":"11924852817","pt":1724193086859,"mc":[{"id":"1.232013794","rc":[{"batb":[[0,7.4,10],[1,7.2,6.08],[2,2,58.4]],"ltp":5.9,"tv":17.82,"id":61077258}]}]}
{"op":"mcm","clk":"11924853028","pt":1724193090049,"mc":[{"id":"1.232013794","rc":[{"batb":[[0,7.2,6.08],[1,2,58.4],[2,1.06,149.69]],"ltp":5.9,"tv":17.82,"id":61077258}]}]}
{"op":"mcm","clk":"11924853236","pt":1724193093037,"mc":[{"id":"1.232013794","rc":[{"batb":[[0,7.4,10],[1,7.2,6.08],[2,2,58.4]],"ltp":5.9,"tv":17.82,"id":61077258}]}]}
{"op":"mcm","clk":"11924853468","pt":1724193096440,"mc":[{"id":"1.232013794","rc":[{"batb":[[0,7.2,6.08],[1,2,58.4],[2,1.06,149.69]],"ltp":5.9,"tv":17.82,"id":61077258}]}]}
{"op":"mcm","clk":"11924853668","pt":1724193099669,"mc":[{"id":"1.232013794","rc":[{"batb":[[0,7.4,10],[1,7.2,6.08],[2,2,58.4]],"ltp":5.9,"tv":17.82,"id":61077258}]}]}
{"op":"mcm","clk":"11924853904","pt":1724193103369,"mc":[{"id":"1.232013794","rc":[{"batb":[[0,7.2,6.08],[1,2,58.4],[2,1.06,149.69]],"ltp":5.9,"tv":17.82,"id":61077258}]}]}
{"op":"mcm","clk":"11924854133","pt":1724193107181,"mc":[{"id":"1.232013794","rc":[{"batb":[[0,7.4,10],[1,7.2,6.08],[2,2,58.4]],"ltp":5.9,"tv":17.82,"id":61077258}]}]}
{"op":"mcm","clk":"11924854346","pt":1724193110584,"mc":[{"id":"1.232013794","rc":[{"batb":[[0,7.2,6.08],[1,2,58.4],[2,1.06,149.69]],"ltp":5.9,"tv":17.82,"id":61077258}]}]}
{"op":"mcm","clk":"11924854470","pt":1724193112957,"mc":[{"id":"1.232013794","rc":[{"batb":[[0,7.4,10],[1,7.2,6.08],[2,2,58.4]],"ltp":5.9,"tv":17.82,"id":61077258}]}]}
{"op":"mcm","clk":"11924854649","pt":1724193116291,"mc":[{"id":"1.232013794","rc":[{"batb":[[0,7.2,6.08],[1,2,58.4],[2,1.06,149.69]],"ltp":5.9,"tv":17.82,"id":61077258}]}]}
{"op":"mcm","clk":"11924854802","pt":1724193119282,"mc":[{"id":"1.232013794","rc":[{"batb":[[0,7.4,10],[1,7.2,6.08],[2,2,58.4]],"ltp":5.9,"tv":17.82,"id":61077258}]}]}
{"op":"mcm","clk":"11924854992","pt":1724193122583,"mc":[{"id":"1.232013794","rc":[{"batb":[[0,7.2,6.08],[1,2,58.4],[2,1.06,149.69]],"ltp":5.9,"tv":17.82,"id":61077258}]}]}
{"op":"mcm","clk":"11924855200","pt":1724193126080,"mc":[{"id":"1.232013794","rc":[{"batb":[[0,7.4,10],[1,7.2,6.08],[2,2,58.4]],"ltp":5.9,"tv":17.82,"id":61077258}]}]}
{"op":"mcm","clk":"11924855400","pt":1724193129473,"mc":[{"id":"1.232013794","rc":[{"batb":[[0,7.2,6.08],[1,2,58.4],[2,1.06,149.69]],"ltp":5.9,"tv":17.82,"id":61077258}]}]}
{"op":"mcm","clk":"11924855583","pt":1724193132297,"mc":[{"id":"1.232013794","rc":[{"batb":[[0,7.4,10],[1,7.2,6.08],[2,2,58.4]],"ltp":5.9,"tv":17.82,"id":61077258}]}]}
{"op":"mcm","clk":"11924855808","pt":1724193136000,"mc":[{"id":"1.232013794","rc":[{"batb":[[0,7.2,6.08],[1,2,58.4],[2,1.06,149.69]],"ltp":5.9,"tv":17.82,"id":61077258}]}]}
{"op":"mcm","clk":"11924855969","pt":1724193138474,"mc":[{"id":"1.232013794","rc":[{"batb":[[0,7.4,10],[1,7.2,6.08],[2,2,58.4]],"ltp":5.9,"tv":17.82,"id":61077258}]}]}
{"op":"mcm","clk":"11924856186","pt":1724193141924,"mc":[{"id":"1.232013794","rc":[{"batb":[[0,7.2,6.08],[1,2,58.4],[2,1.06,149.69]],"ltp":5.9,"tv":17.82,"id":61077258}]}]}
{"op":"mcm","clk":"11924856304","pt":1724193144291,"mc":[{"id":"1.232013794","rc":[{"batb":[[0,7.4,10],[1,7.2,6.08],[2,2,58.4]],"ltp":5.9,"tv":17.82,"id":61077258}]}]}
{"op":"mcm","clk":"11924856486","pt":1724193147582,"mc":[{"id":"1.232013794","rc":[{"batb":[[0,7.2,6.08],[1,2,58.4],[2,1.06,149.69]],"ltp":5.9,"tv":17.82,"id":61077258}]}]}
{"op":"mcm","clk":"11924856624","pt":1724193149997,"mc":[{"id":"1.232013794","rc":[{"batb":[[0,7.4,10],[1,7.2,6.08],[2,2,58.4]],"ltp":5.9,"tv":17.82,"id":61077258}]}]}
{"op":"mcm","clk":"11924856990","pt":1724193156418,"mc":[{"id":"1.232013794","rc":[{"batb":[[0,7.2,6.08],[1,2,58.4],[2,1.06,149.69]],"ltp":5.9,"tv":17.82,"id":61077258}]}]}
{"op":"mcm","clk":"11924857108","pt":1724193158725,"mc":[{"id":"1.232013794","rc":[{"batb":[[0,7.4,10],[1,7.2,6.08],[2,2,58.4]],"ltp":5.9,"tv":17.82,"id":61077258}]}]}
{"op":"mcm","clk":"11924857282","pt":1724193162136,"mc":[{"id":"1.232013794","rc":[{"batb":[[0,7.2,6.08],[1,2,58.4],[2,1.06,149.69]],"ltp":5.9,"tv":17.82,"id":61077258}]}]}
{"op":"mcm","clk":"11924857422","pt":1724193164543,"mc":[{"id":"1.232013794","rc":[{"batb":[[0,7.4,10],[1,7.2,6.08],[2,2,58.4]],"ltp":5.9,"tv":17.82,"id":61077258}]}]}
{"op":"mcm","clk":"11924857630","pt":1724193167932,"mc":[{"id":"1.232013794","rc":[{"batb":[[0,7.2,6.08],[1,2,58.4],[2,1.06,149.69]],"ltp":5.9,"tv":17.82,"id":61077258}]}]}
{"op":"mcm","clk":"11924857759","pt":1724193170345,"mc":[{"id":"1.232013794","rc":[{"batb":[[0,7.4,10],[1,7.2,6.08],[2,2,58.4]],"ltp":5.9,"tv":17.82,"id":61077258}]}]}
{"op":"mcm","clk":"11924857915","pt":1724193173739,"mc":[{"id":"1.232013794","rc":[{"batb":[[0,7.2,6.08],[1,2,58.4],[2,1.06,149.69]],"ltp":5.9,"tv":17.82,"id":61077258}]}]}
{"op":"mcm","clk":"11924858009","pt":1724193176146,"mc":[{"id":"1.232013794","rc":[{"batb":[[0,7.4,10],[1,7.2,6.08],[2,2,58.4]],"ltp":5.9,"tv":17.82,"id":61077258}]}]}
{"op":"mcm","clk":"11924858158","pt":1724193179423,"mc":[{"id":"1.232013794","rc":[{"batb":[[0,7.2,6.08],[1,2,58.4],[2,1.06,149.69]],"ltp":5.9,"tv":17.82,"id":61077258}]}]}
{"op":"mcm","clk":"11924858269","pt":1724193181837,"mc":[{"id":"1.232013794","rc":[{"batb":[[0,7.4,10],[1,7.2,6.08],[2,2,58.4]],"ltp":5.9,"tv":17.82,"id":61077258}]}]}
{"op":"mcm","clk":"11924858442","pt":1724193185228,"mc":[{"id":"1.232013794","rc":[{"batb":[[0,7.2,6.08],[1,2,58.4],[2,1.06,149.69]],"ltp":5.9,"tv":17.82,"id":61077258}]}]}
{"op":"mcm","clk":"11924858562","pt":1724193187849,"mc":[{"id":"1.232013794","rc":[{"batb":[[0,7.4,10],[1,7.2,6.08],[2,2,58.4]],"ltp":5.9,"tv":17.82,"id":61077258}]}]}
{"op":"mcm","clk":"11924858766","pt":1724193191250,"mc":[{"id":"1.232013794","rc":[{"batb":[[0,7.2,6.08],[1,2,58.4],[2,1.06,149.69]],"ltp":5.9,"tv":17.82,"id":61077258}]}]}
{"op":"mcm","clk":"11924858886","pt":1724193193665,"mc":[{"id":"1.232013794","rc":[{"batb":[[0,7.4,10],[1,7.2,6.08],[2,2,58.4]],"ltp":5.9,"tv":17.82,"id":61077258}]}]}
{"op":"mcm","clk":"11924859100","pt":1724193196961,"mc":[{"id":"1.232013794","rc":[{"batb":[[0,7.2,6.08],[1,2,58.4],[2,1.06,149.69]],"ltp":5.9,"tv":17.82,"id":61077258}]}]}
{"op":"mcm","clk":"11924859272","pt":1724193199482,"mc":[{"id":"1.232013794","rc":[{"batb":[[0,7.4,10],[1,7.2,6.08],[2,2,58.4]],"ltp":5.9,"tv":17.82,"id":61077258}]}]}
{"op":"mcm","clk":"11924859479","pt":1724193202874,"mc":[{"id":"1.232013794","rc":[{"batb":[[0,7.2,6.08],[1,2,58.4],[2,1.06,149.69]],"ltp":5.9,"tv":17.82,"id":61077258}]}]}
{"op":"mcm","clk":"11924859584","pt":1724193205184,"mc":[{"id":"1.232013794","rc":[{"batb":[[0,7.4,10],[1,7.2,6.08],[2,2,58.4]],"ltp":5.9,"tv":17.82,"id":61077258}]}]}
{"op":"mcm","clk":"11924859743","pt":1724193208476,"mc":[{"id":"1.232013794","rc":[{"batb":[[0,7.2,6.08],[1,2,58.4],[2,1.06,149.69]],"ltp":5.9,"tv":17.82,"id":61077258}]}]}
{"op":"mcm","clk":"11924859929","pt":1724193211774,"mc":[{"id":"1.232013794","rc":[{"batb":[[0,7.4,10],[1,7.2,6.08],[2,2,58.4]],"ltp":5.9,"tv":17.82,"id":61077258}]}]}
{"op":"mcm","clk":"11924860125","pt":1724193215175,"mc":[{"id":"1.232013794","rc":[{"batb":[[0,7.2,6.08],[1,2,58.4],[2,1.06,149.69]],"ltp":5.9,"tv":17.82,"id":61077258}]}]}
{"op":"mcm","clk":"11924860271","pt":1724193217893,"mc":[{"id":"1.232013794","rc":[{"batb":[[0,7.4,10],[1,7.2,6.08],[2,2,58.4]],"ltp":5.9,"tv":17.82,"id":61077258}]}]}
{"op":"mcm","clk":"11924860510","pt":1724193221489,"mc":[{"id":"1.232013794","rc":[{"batb":[[0,7.2,6.08],[1,2,58.4],[2,1.06,149.69]],"ltp":5.9,"tv":17.82,"id":61077258}]}]}
{"op":"mcm","clk":"11924860645","pt":1724193223916,"mc":[{"id":"1.232013794","rc":[{"batb":[[0,7.4,10],[1,7.2,6.08],[2,2,58.4]],"ltp":5.9,"tv":17.82,"id":61077258}]}]}
{"op":"mcm","clk":"11924860844","pt":1724193227201,"mc":[{"id":"1.232013794","rc":[{"batb":[[0,7.2,6.08],[1,2,58.4],[2,1.06,149.69]],"ltp":5.9,"tv":17.82,"id":61077258}]}]}
{"op":"mcm","clk":"11924860987","pt":1724193229571,"mc":[{"id":"1.232013794","rc":[{"batb":[[0,7.4,10],[1,7.2,6.08],[2,2,58.4]],"ltp":5.9,"tv":17.82,"id":61077258}]}]}
{"op":"mcm","clk":"11924861192","pt":1724193232907,"mc":[{"id":"1.232013794","rc":[{"batb":[[0,7.2,6.08],[1,2,58.4],[2,1.06,149.69]],"ltp":5.9,"tv":17.82,"id":61077258}]}]}
{"op":"mcm","clk":"11924861367","pt":1724193235179,"mc":[{"id":"1.232013794","rc":[{"batb":[[0,7.4,10],[1,7.2,6.08],[2,2,58.4]],"ltp":5.9,"tv":17.82,"id":61077258}]}]}
{"op":"mcm","clk":"11924861584","pt":1724193238488,"mc":[{"id":"1.232013794","rc":[{"batb":[[0,7.2,6.08],[1,2,58.4],[2,1.06,149.69]],"ltp":5.9,"tv":17.82,"id":61077258}]}]}
{"op":"mcm","clk":"11924861731","pt":1724193240905,"mc":[{"id":"1.232013794","rc":[{"batb":[[0,7.4,10],[1,7.2,6.08],[2,2,58.4]],"ltp":5.9,"tv":17.82,"id":61077258}]}]}
{"op":"mcm","clk":"11924861923","pt":1724193244188,"mc":[{"id":"1.232013794","rc":[{"batb":[[0,7.2,6.08],[1,2,58.4],[2,1.06,149.69]],"ltp":5.9,"tv":17.82,"id":61077258}]}]}
{"op":"mcm","clk":"11924862051","pt":1724193246602,"mc":[{"id":"1.232013794","rc":[{"batb":[[0,7.4,10],[1,7.2,6.08],[2,2,58.4]],"ltp":5.9,"tv":17.82,"id":61077258}]}]}
{"op":"mcm","clk":"11924862263","pt":1724193250212,"mc":[{"id":"1.232013794","rc":[{"batb":[[0,7.2,6.08],[1,2,58.4],[2,1.06,149.69]],"ltp":5.9,"tv":17.82,"id":61077258}]}]}
{"op":"mcm","clk":"11924862477","pt":1724193252891,"mc":[{"id":"1.232013794","rc":[{"batb":[[0,7.4,10],[1,7.2,6.08],[2,2,58.4]],"ltp":5.9,"tv":17.82,"id":61077258}]}]}
{"op":"mcm","clk":"11924862701","pt":1724193256394,"mc":[{"id":"1.232013794","rc":[{"batb":[[0,7.2,6.08],[1,2,58.4],[2,1.06,149.69]],"ltp":5.9,"tv":17.82,"id":61077258}]}]}
{"op":"mcm","clk":"11924862935","pt":1724193260105,"mc":[{"id":"1.232013794","rc":[{"batb":[[0,7.4,10],[1,7.2,6.08],[2,2,58.4]],"ltp":5.9,"tv":17.82,"id":61077258}]}]}
{"op":"mcm","clk":"11924863134","pt":1724193263600,"mc":[{"id":"1.232013794","rc":[{"batb":[[0,7.2,6.08],[1,2,58.4],[2,1.06,149.69]],"ltp":5.9,"tv":17.82,"id":61077258}]}]}
{"op":"mcm","clk":"11924863306","pt":1724193266332,"mc":[{"id":"1.232013794","rc":[{"batb":[[0,7.4,10],[1,7.2,6.08],[2,2,58.4]],"ltp":5.9,"tv":17.82,"id":61077258}]}]}
{"op":"mcm","clk":"11924863505","pt":1724193269737,"mc":[{"id":"1.232013794","rc":[{"batb":[[0,7.2,6.08],[1,2,58.4],[2,1.06,149.69]],"ltp":5.9,"tv":17.82,"id":61077258}]}]}
{"op":"mcm","clk":"11924863681","pt":1724193272324,"mc":[{"id":"1.232013794","rc":[{"batb":[[0,7.4,10],[1,7.2,6.08],[2,2,58.4]],"ltp":5.9,"tv":17.82,"id":61077258}]}]}
{"op":"mcm","clk":"11924863878","pt":1724193275738,"mc":[{"id":"1.232013794","rc":[{"batb":[[0,7.2,6.08],[1,2,58.4],[2,1.06,149.69]],"ltp":5.9,"tv":17.82,"id":61077258}]}]}
{"op":"mcm","clk":"11924864007","pt":1724193278154,"mc":[{"id":"1.232013794","rc":[{"batb":[[0,7.4,10],[1,7.2,6.08],[2,2,58.4]],"ltp":5.9,"tv":17.82,"id":61077258}]}]}
{"op":"mcm","clk":"11924864199","pt":1724193281355,"mc":[{"id":"1.232013794","rc":[{"batb":[[0,7.2,6.08],[1,2,58.4],[2,1.06,149.69]],"ltp":5.9,"tv":17.82,"id":61077258}]}]}
{"op":"mcm","clk":"11924864364","pt":1724193284447,"mc":[{"id":"1.232013794","rc":[{"batb":[[0,7.4,10],[1,7.2,6.08],[2,2,58.4]],"ltp":5.9,"tv":17.82,"id":61077258}]}]}
{"op":"mcm","clk":"11924864565","pt":1724193288355,"mc":[{"id":"1.232013794","rc":[{"batb":[[0,7.2,6.08],[1,2,58.4],[2,1.06,149.69]],"ltp":5.9,"tv":17.82,"id":61077258}]}]}
{"op":"mcm","clk":"11924864666","pt":1724193290871,"mc":[{"id":"1.232013794","rc":[{"batb":[[0,7.4,10],[1,7.2,6.08],[2,2,58.4]],"ltp":5.9,"tv":17.82,"id":61077258}]}]}
{"op":"mcm","clk":"11924864835","pt":1724193294369,"mc":[{"id":"1.232013794","rc":[{"batb":[[0,7.2,6.08],[1,2,58.4],[2,1.06,149.69]],"ltp":5.9,"tv":17.82,"id":61077258}]}]}
{"op":"mcm","clk":"11924864946","pt":1724193296779,"mc":[{"id":"1.232013794","rc":[{"batb":[[0,7.4,10],[1,7.2,6.08],[2,2,58.4]],"ltp":5.9,"tv":17.82,"id":61077258}]}]}
{"op":"mcm","clk":"11924865081","pt":1724193300168,"mc":[{"id":"1.232013794","rc":[{"batb":[[0,7.2,6.08],[1,2,58.4],[2,1.06,149.69]],"ltp":5.9,"tv":17.82,"id":61077258}]}]}
{"op":"mcm","clk":"11924865240","pt":1724193302901,"mc":[{"id":"1.232013794","rc":[{"batb":[[0,7.4,10],[1,7.2,6.08],[2,2,58.4]],"ltp":5.9,"tv":17.82,"id":61077258}]}]}
{"op":"mcm","clk":"11924865460","pt":1724193306317,"mc":[{"id":"1.232013794","rc":[{"batb":[[0,7.2,6.08],[1,2,58.4],[2,1.06,149.69]],"ltp":5.9,"tv":17.82,"id":61077258}]}]}
{"op":"mcm","clk":"11924865591","pt":1724193308680,"mc":[{"id":"1.232013794","rc":[{"batb":[[0,7.4,10],[1,7.2,6.08],[2,2,58.4]],"ltp":5.9,"tv":17.82,"id":61077258}]}]}
{"op":"mcm","clk":"11924865768","pt":1724193312072,"mc":[{"id":"1.232013794","rc":[{"batb":[[0,7.2,6.08],[1,2,58.4],[2,1.06,149.69]],"ltp":5.9,"tv":17.82,"id":61077258}]}]}
{"op":"mcm","clk":"11924865898","pt":1724193314694,"mc":[{"id":"1.232013794","rc":[{"batb":[[0,7.4,10],[1,7.2,6.08],[2,2,58.4]],"ltp":5.9,"tv":17.82,"id":61077258}]}]}
{"op":"mcm","clk":"11924866073","pt":1724193318286,"mc":[{"id":"1.232013794","rc":[{"batb":[[0,7.2,6.08],[1,2,58.4],[2,1.06,149.69]],"ltp":5.9,"tv":17.82,"id":61077258}]}]}
{"op":"mcm","clk":"11924866168","pt":1724193320489,"mc":[{"id":"1.232013794","rc":[{"batb":[[0,7.4,10],[1,7.2,6.08],[2,2,58.4]],"ltp":5.9,"tv":17.82,"id":61077258}]}]}
{"op":"mcm","clk":"11924866347","pt":1724193323772,"mc":[{"id":"1.232013794","rc":[{"batb":[[0,7.2,6.08],[1,2,58.4],[2,1.06,149.69]],"ltp":5.9,"tv":17.82,"id":61077258}]}]}
{"op":"mcm","clk":"11924866530","pt":1724193326912,"mc":[{"id":"1.232013794","rc":[{"batb":[[0,7.4,10],[1,7.2,6.08],[2,2,58.4]],"ltp":5.9,"tv":17.82,"id":61077258}]}]}
{"op":"mcm","clk":"11924866716","pt":1724193330306,"mc":[{"id":"1.232013794","rc":[{"batb":[[0,7.2,6.08],[1,2,58.4],[2,1.06,149.69]],"ltp":5.9,"tv":17.82,"id":61077258}]}]}
{"op":"mcm","clk":"11924866885","pt":1724193333129,"mc":[{"id":"1.232013794","rc":[{"batb":[[0,7.4,10],[1,7.2,6.08],[2,2,58.4]],"ltp":5.9,"tv":17.82,"id":61077258}]}]}
{"op":"mcm","clk":"11924867040","pt":1724193336523,"mc":[{"id":"1.232013794","rc":[{"batb":[[0,7.2,6.08],[1,2,58.4],[2,1.06,149.69]],"ltp":5.9,"tv":17.82,"id":61077258}]}]}
{"op":"mcm","clk":"11924867175","pt":1724193338924,"mc":[{"id":"1.232013794","rc":[{"batb":[[0,7.4,10],[1,7.2,6.08],[2,2,58.4]],"ltp":5.9,"tv":17.82,"id":61077258}]}]}
{"op":"mcm","clk":"11924867312","pt":1724193342115,"mc":[{"id":"1.232013794","rc":[{"batb":[[0,7.2,6.08],[1,2,58.4],[2,1.06,149.69]],"ltp":5.9,"tv":17.82,"id":61077258}]}]}
{"op":"mcm","clk":"11924867437","pt":1724193344635,"mc":[{"id":"1.232013794","rc":[{"batb":[[0,7.4,10],[1,7.2,6.08],[2,2,58.4]],"ltp":5.9,"tv":17.82,"id":61077258}]}]}
{"op":"mcm","clk":"11924867635","pt":1724193348336,"mc":[{"id":"1.232013794","rc":[{"batb":[[0,7.2,6.08],[1,2,58.4],[2,1.06,149.69]],"ltp":5.9,"tv":17.82,"id":61077258}]}]}
{"op":"mcm","clk":"11924867750","pt":1724193350810,"mc":[{"id":"1.232013794","rc":[{"batb":[[0,7.4,10],[1,7.2,6.08],[2,2,58.4]],"ltp":5.9,"tv":17.82,"id":61077258}]}]}
{"op":"mcm","clk":"11924867938","pt":1724193354248,"mc":[{"id":"1.232013794","rc":[{"batb":[[0,7.2,6.08],[1,2,58.4],[2,1.06,149.69]],"ltp":5.9,"tv":17.82,"id":61077258}]}]}
{"op":"mcm","clk":"11924868067","pt":1724193356512,"mc":[{"id":"1.232013794","rc":[{"batb":[[0,7.4,10],[1,7.2,6.08],[2,2,58.4]],"ltp":5.9,"tv":17.82,"id":61077258}]}]}
{"op":"mcm","clk":"11924868213","pt":1724193360052,"mc":[{"id":"1.232013794","rc":[{"batb":[[0,7.2,6.08],[1,2,58.4],[2,1.06,149.69]],"ltp":5.9,"tv":17.82,"id":61077258}]}]}
{"op":"mcm","clk":"11924868322","pt":1724193362318,"mc":[{"id":"1.232013794","rc":[{"batb":[[0,7.4,10],[1,7.2,6.08],[2,2,58.4]],"ltp":5.9,"tv":17.82,"id":61077258}]}]}
{"op":"mcm","clk":"11924868450","pt":1724193365754,"mc":[{"id":"1.232013794","rc":[{"batb":[[0,7.2,6.08],[1,2,58.4],[2,1.06,149.69]],"ltp":5.9,"tv":17.82,"id":61077258}]}]}
{"op":"mcm","clk":"11924868603","pt":1724193369038,"mc":[{"id":"1.232013794","rc":[{"batb":[[0,7.4,10],[1,7.2,6.08],[2,2,58.4]],"ltp":5.9,"tv":17.82,"id":61077258}]}]}
{"op":"mcm","clk":"11924868769","pt":1724193372468,"mc":[{"id":"1.232013794","rc":[{"batb":[[0,7.2,6.08],[1,2,58.4],[2,1.06,149.69]],"ltp":5.9,"tv":17.82,"id":61077258}]}]}
{"op":"mcm","clk":"11924868920","pt":1724193375357,"mc":[{"id":"1.232013794","rc":[{"batb":[[0,7.4,10],[1,7.2,6.08],[2,2,58.4]],"ltp":5.9,"tv":17.82,"id":61077258}]}]}
{"op":"mcm","clk":"11924869093","pt":1724193378946,"mc":[{"id":"1.232013794","rc":[{"batb":[[0,7.2,6.08],[1,2,58.4],[2,1.06,149.69]],"ltp":5.9,"tv":17.82,"id":61077258}]}]}
{"op":"mcm","clk":"11924869186","pt":1724193381364,"mc":[{"id":"1.232013794","rc":[{"batb":[[0,7.4,10],[1,7.2,6.08],[2,2,58.4]],"ltp":5.9,"tv":17.82,"id":61077258}]}]}
{"op":"mcm","clk":"11924869347","pt":1724193384755,"mc":[{"id":"1.232013794","rc":[{"batb":[[0,7.2,6.08],[1,2,58.4],[2,1.06,149.69]],"ltp":5.9,"tv":17.82,"id":61077258}]}]}
{"op":"mcm","clk":"11924869451","pt":1724193387169,"mc":[{"id":"1.232013794","rc":[{"batb":[[0,7.4,10],[1,7.2,6.08],[2,2,58.4]],"ltp":5.9,"tv":17.82,"id":61077258}]}]}
{"op":"mcm","clk":"11924869597","pt":1724193390460,"mc":[{"id":"1.232013794","rc":[{"batb":[[0,7.2,6.08],[1,2,58.4],[2,1.06,149.69]],"ltp":5.9,"tv":17.82,"id":61077258}]}]}
{"op":"mcm","clk":"11924869715","pt":1724193393078,"mc":[{"id":"1.232013794","rc":[{"batb":[[0,7.4,10],[1,7.2,6.08],[2,2,58.4]],"ltp":5.9,"tv":17.82,"id":61077258}]}]}
{"op":"mcm","clk":"11924869871","pt":1724193396365,"mc":[{"id":"1.232013794","rc":[{"batb":[[0,7.2,6.08],[1,2,58.4],[2,1.06,149.69]],"ltp":5.9,"tv":17.82,"id":61077258}]}]}
{"op":"mcm","clk":"11924870003","pt":1724193398987,"mc":[{"id":"1.232013794","rc":[{"batb":[[0,7.4,10],[1,7.2,6.08],[2,2,58.4]],"ltp":5.9,"tv":17.82,"id":61077258}]}]}
{"op":"mcm","clk":"11924870148","pt":1724193402280,"mc":[{"id":"1.232013794","rc":[{"batb":[[0,7.2,6.08],[1,2,58.4],[2,1.06,149.69]],"ltp":5.9,"tv":17.82,"id":61077258}]}]}
{"op":"mcm","clk":"11924870288","pt":1724193405364,"mc":[{"id":"1.232013794","rc":[{"batb":[[0,7.4,10],[1,7.2,6.08],[2,2,58.4]],"ltp":5.9,"tv":17.82,"id":61077258}]}]}
{"op":"mcm","clk":"11924870479","pt":1724193408960,"mc":[{"id":"1.232013794","rc":[{"batb":[[0,7.2,6.08],[1,2,58.4],[2,1.06,149.69]],"ltp":5.9,"tv":17.82,"id":61077258}]}]}
{"op":"mcm","clk":"11924870590","pt":1724193411676,"mc":[{"id":"1.232013794","rc":[{"batb":[[0,7.4,10],[1,7.2,6.08],[2,2,58.4]],"ltp":5.9,"tv":17.82,"id":61077258}]}]}
{"op":"mcm","clk":"11924870726","pt":1724193415162,"mc":[{"id":"1.232013794","rc":[{"batb":[[0,7.2,6.08],[1,2,58.4],[2,1.06,149.69]],"ltp":5.9,"tv":17.82,"id":61077258}]}]}
{"op":"mcm","clk":"11924870827","pt":1724193417704,"mc":[{"id":"1.232013794","rc":[{"batb":[[0,7.4,10],[1,7.2,6.08],[2,2,58.4]],"ltp":5.9,"tv":17.82,"id":61077258}]}]}
{"op":"mcm","clk":"11924870981","pt":1724193421192,"mc":[{"id":"1.232013794","rc":[{"batb":[[0,7.2,6.08],[1,2,58.4],[2,1.06,149.69]],"ltp":5.9,"tv":17.82,"id":61077258}]}]}
{"op":"mcm","clk":"11924871114","pt":1724193423708,"mc":[{"id":"1.232013794","rc":[{"batb":[[0,7.4,10],[1,7.2,6.08],[2,2,58.4]],"ltp":5.9,"tv":17.82,"id":61077258}]}]}
{"op":"mcm","clk":"11924871253","pt":1724193426987,"mc":[{"id":"1.232013794","rc":[{"batb":[[0,7.2,6.08],[1,2,58.4],[2,1.06,149.69]],"ltp":5.9,"tv":17.82,"id":61077258}]}]}
{"op":"mcm","clk":"11924871395","pt":1724193430122,"mc":[{"id":"1.232013794","rc":[{"batb":[[0,7.4,10],[1,7.2,6.08],[2,2,58.4]],"ltp":5.9,"tv":17.82,"id":61077258}]}]}
{"op":"mcm","clk":"11924871532","pt":1724193433614,"mc":[{"id":"1.232013794","rc":[{"batb":[[0,7.2,6.08],[1,2,58.4],[2,1.06,149.69]],"ltp":5.9,"tv":17.82,"id":61077258}]}]}
{"op":"mcm","clk":"11924871659","pt":1724193436538,"mc":[{"id":"1.232013794","rc":[{"batb":[[0,7.4,10],[1,7.2,6.08],[2,2,58.4]],"ltp":5.9,"tv":17.82,"id":61077258}]}]}
{"op":"mcm","clk":"11924871812","pt":1724193440240,"mc":[{"id":"1.232013794","rc":[{"batb":[[0,7.2,6.08],[1,2,58.4],[2,1.06,149.69]],"ltp":5.9,"tv":17.82,"id":61077258}]}]}
{"op":"mcm","clk":"11924871935","pt":1724193442711,"mc":[{"id":"1.232013794","rc":[{"batb":[[0,7.4,10],[1,7.2,6.08],[2,2,58.4]],"ltp":5.9,"tv":17.82,"id":61077258}]}]}
{"op":"mcm","clk":"11924872105","pt":1724193446008,"mc":[{"id":"1.232013794","rc":[{"batb":[[0,7.2,6.08],[1,2,58.4],[2,1.06,149.69]],"ltp":5.9,"tv":17.82,"id":61077258}]}]}
{"op":"mcm","clk":"11924872243","pt":1724193448730,"mc":[{"id":"1.232013794","rc":[{"batb":[[0,7.4,10],[1,7.2,6.08],[2,2,58.4]],"ltp":5.9,"tv":17.82,"id":61077258}]}]}
{"op":"mcm","clk":"11924872409","pt":1724193452127,"mc":[{"id":"1.232013794","rc":[{"batb":[[0,7.2,6.08],[1,2,58.4],[2,1.06,149.69]],"ltp":5.9,"tv":17.82,"id":61077258}]}]}
{"op":"mcm","clk":"11924872544","pt":1724193454440,"mc":[{"id":"1.232013794","rc":[{"batb":[[0,7.4,10],[1,7.2,6.08],[2,2,58.4]],"ltp":5.9,"tv":17.82,"id":61077258}]}]}
{"op":"mcm","clk":"11924872724","pt":1724193457734,"mc":[{"id":"1.232013794","rc":[{"batb":[[0,7.2,6.08],[1,2,58.4],[2,1.06,149.69]],"ltp":5.9,"tv":17.82,"id":61077258}]}]}
{"op":"mcm","clk":"11924872876","pt":1724193460447,"mc":[{"id":"1.232013794","rc":[{"batb":[[0,7.4,10],[1,7.2,6.08],[2,2,58.4]],"ltp":5.9,"tv":17.82,"id":61077258}]}]}
{"op":"mcm","clk":"11924873058","pt":1724193464042,"mc":[{"id":"1.232013794","rc":[{"batb":[[0,7.2,6.08],[1,2,58.4],[2,1.06,149.69]],"ltp":5.9,"tv":17.82,"id":61077258}]}]}
{"op":"mcm","clk":"11924873250","pt":1724193466460,"mc":[{"id":"1.232013794","rc":[{"batb":[[0,7.4,10],[1,7.2,6.08],[2,2,58.4]],"ltp":5.9,"tv":17.82,"id":61077258}]}]}
{"op":"mcm","clk":"11924873451","pt":1724193469748,"mc":[{"id":"1.232013794","rc":[{"batb":[[0,7.2,6.08],[1,2,58.4],[2,1.06,149.69]],"ltp":5.9,"tv":17.82,"id":61077258}]}]}
{"op":"mcm","clk":"11924873630","pt":1724193472830,"mc":[{"id":"1.232013794","rc":[{"batb":[[0,7.4,10],[1,7.2,6.08],[2,2,58.4]],"ltp":5.9,"tv":17.82,"id":61077258}]}]}
{"op":"mcm","clk":"11924873822","pt":1724193476271,"mc":[{"id":"1.232013794","rc":[{"batb":[[0,7.2,6.08],[1,2,58.4],[2,1.06,149.69]],"ltp":5.9,"tv":17.82,"id":61077258}]}]}
{"op":"mcm","clk":"11924873983","pt":1724193479243,"mc":[{"id":"1.232013794","rc":[{"batb":[[0,7.4,10],[1,7.2,6.08],[2,2,58.4]],"ltp":5.9,"tv":17.82,"id":61077258}]}]}
{"op":"mcm","clk":"11924874165","pt":1724193482839,"mc":[{"id":"1.232013794","rc":[{"batb":[[0,7.2,6.08],[1,2,58.4],[2,1.06,149.69]],"ltp":5.9,"tv":17.82,"id":61077258}]}]}
{"op":"mcm","clk":"11924874286","pt":1724193485457,"mc":[{"id":"1.232013794","rc":[{"batb":[[0,7.4,10],[1,7.2,6.08],[2,2,58.4]],"ltp":5.9,"tv":17.82,"id":61077258}]}]}
{"op":"mcm","clk":"11924874442","pt":1724193488853,"mc":[{"id":"1.232013794","rc":[{"batb":[[0,7.2,6.08],[1,2,58.4],[2,1.06,149.69]],"ltp":5.9,"tv":17.82,"id":61077258}]}]}
{"op":"mcm","clk":"11924874563","pt":1724193491273,"mc":[{"id":"1.232013794","rc":[{"batb":[[0,7.4,10],[1,7.2,6.08],[2,2,58.4]],"ltp":5.9,"tv":17.82,"id":61077258}]}]}
{"op":"mcm","clk":"11924874758","pt":1724193494769,"mc":[{"id":"1.232013794","rc":[{"batb":[[0,7.2,6.08],[1,2,58.4],[2,1.06,149.69]],"ltp":5.9,"tv":17.82,"id":61077258}]}]}
{"op":"mcm","clk":"11924874885","pt":1724193497079,"mc":[{"id":"1.232013794","rc":[{"batb":[[0,7.4,10],[1,7.2,6.08],[2,2,58.4]],"ltp":5.9,"tv":17.82,"id":61077258}]}]}
{"op":"mcm","clk":"11924875054","pt":1724193500367,"mc":[{"id":"1.232013794","rc":[{"batb":[[0,7.2,6.08],[1,2,58.4],[2,1.06,149.69]],"ltp":5.9,"tv":17.82,"id":61077258}]}]}
{"op":"mcm","clk":"11924875194","pt":1724193502883,"mc":[{"id":"1.232013794","rc":[{"batb":[[0,7.4,10],[1,7.2,6.08],[2,2,58.4]],"ltp":5.9,"tv":17.82,"id":61077258}]}]}
{"op":"mcm","clk":"11924875364","pt":1724193506320,"mc":[{"id":"1.232013794","rc":[{"batb":[[0,7.2,6.08],[1,2,58.4],[2,1.06,149.69]],"ltp":5.9,"tv":17.82,"id":61077258}]}]}
{"op":"mcm","clk":"11924875534","pt":1724193508778,"mc":[{"id":"1.232013794","rc":[{"batb":[[0,7.4,10],[1,7.2,6.08],[2,2,58.4]],"ltp":5.9,"tv":17.82,"id":61077258}]}]}
{"op":"mcm","clk":"11924875786","pt":1724193512121,"mc":[{"id":"1.232013794","rc":[{"batb":[[0,7.2,6.08],[1,2,58.4],[2,1.06,149.69]],"ltp":5.9,"tv":17.82,"id":61077258}]}]}
{"op":"mcm","clk":"11924875912","pt":1724193514591,"mc":[{"id":"1.232013794","rc":[{"batb":[[0,7.4,10],[1,7.2,6.08],[2,2,58.4]],"ltp":5.9,"tv":17.82,"id":61077258}]}]}
{"op":"mcm","clk":"11924876116","pt":1724193518130,"mc":[{"id":"1.232013794","rc":[{"batb":[[0,7.2,6.08],[1,2,58.4],[2,1.06,149.69]],"ltp":5.9,"tv":17.82,"id":61077258}]}]}
{"op":"mcm","clk":"11924876225","pt":1724193520408,"mc":[{"id":"1.232013794","rc":[{"batb":[[0,7.4,10],[1,7.2,6.08],[2,2,58.4]],"ltp":5.9,"tv":17.82,"id":61077258}]}]}
{"op":"mcm","clk":"11924876401","pt":1724193523693,"mc":[{"id":"1.232013794","rc":[{"batb":[[0,7.2,6.08],[1,2,58.4],[2,1.06,149.69]],"ltp":5.9,"tv":17.82,"id":61077258}]}]}
{"op":"mcm","clk":"11924876586","pt":1724193527028,"mc":[{"id":"1.232013794","rc":[{"batb":[[0,7.4,10],[1,7.2,6.08],[2,2,58.4]],"ltp":5.9,"tv":17.82,"id":61077258}]}]}
{"op":"mcm","clk":"11924876779","pt":1724193530215,"mc":[{"id":"1.232013794","rc":[{"batb":[[0,7.2,6.08],[1,2,58.4],[2,1.06,149.69]],"ltp":5.9,"tv":17.82,"id":61077258}]}]}
{"op":"mcm","clk":"11924876951","pt":1724193533196,"mc":[{"id":"1.232013794","rc":[{"batb":[[0,7.4,10],[1,7.2,6.08],[2,2,58.4]],"ltp":5.9,"tv":17.82,"id":61077258}]}]}
{"op":"mcm","clk":"11924877164","pt":1724193536798,"mc":[{"id":"1.232013794","rc":[{"batb":[[0,7.2,6.08],[1,2,58.4],[2,1.06,149.69]],"ltp":5.9,"tv":17.82,"id":61077258}]}]}
{"op":"mcm","clk":"11924877289","pt":1724193539311,"mc":[{"id":"1.232013794","rc":[{"batb":[[0,7.4,10],[1,7.2,6.08],[2,2,58.4]],"ltp":5.9,"tv":17.82,"id":61077258}]}]}
{"op":"mcm","clk":"11924877465","pt":1724193542851,"mc":[{"id":"1.232013794","rc":[{"batb":[[0,7.2,6.08],[1,2,58.4],[2,1.06,149.69]],"ltp":5.9,"tv":17.82,"id":61077258}]}]}
{"op":"mcm","clk":"11924877685","pt":1724193547620,"mc":[{"id":"1.232013794","rc":[{"batb":[[0,7.4,10],[1,7.2,6.08],[2,2,58.4]],"ltp":5.9,"tv":17.82,"id":61077258}]}]}
{"op":"mcm","clk":"11924877894","pt":1724193551159,"mc":[{"id":"1.232013794","rc":[{"batb":[[0,7.2,6.08],[1,2,58.4],[2,1.06,149.69]],"ltp":5.9,"tv":17.82,"id":61077258}]}]}
{"op":"mcm","clk":"11924878027","pt":1724193553733,"mc":[{"id":"1.232013794","rc":[{"batb":[[0,7.4,10],[1,7.2,6.08],[2,2,58.4]],"ltp":5.9,"tv":17.82,"id":61077258}]}]}
{"op":"mcm","clk":"11924878240","pt":1724193557440,"mc":[{"id":"1.232013794","rc":[{"batb":[[0,7.2,6.08],[1,2,58.4],[2,1.06,149.69]],"ltp":5.9,"tv":17.82,"id":61077258}]}]}
{"op":"mcm","clk":"11924878377","pt":1724193559952,"mc":[{"id":"1.232013794","rc":[{"batb":[[0,7.4,10],[1,7.2,6.08],[2,2,58.4]],"ltp":5.9,"tv":17.82,"id":61077258}]}]}
{"op":"mcm","clk":"11924878568","pt":1724193563246,"mc":[{"id":"1.232013794","rc":[{"batb":[[0,7.2,6.08],[1,2,58.4],[2,1.06,149.69]],"ltp":5.9,"tv":17.82,"id":61077258}]}]}
{"op":"mcm","clk":"11924878715","pt":1724193565972,"mc":[{"id":"1.232013794","rc":[{"batb":[[0,7.4,10],[1,7.2,6.08],[2,2,58.4]],"ltp":5.9,"tv":17.82,"id":61077258}]}]}
{"op":"mcm","clk":"11924878910","pt":1724193569156,"mc":[{"id":"1.232013794","rc":[{"batb":[[0,7.2,6.08],[1,2,58.4],[2,1.06,149.69]],"ltp":5.9,"tv":17.82,"id":61077258}]}]}
{"op":"mcm","clk":"11924879043","pt":1724193571679,"mc":[{"id":"1.232013794","rc":[{"batb":[[0,7.4,10],[1,7.2,6.08],[2,2,58.4]],"ltp":5.9,"tv":17.82,"id":61077258}]}]}
{"op":"mcm","clk":"11924879212","pt":1724193574983,"mc":[{"id":"1.232013794","rc":[{"batb":[[0,7.2,6.08],[1,2,58.4],[2,1.06,149.69]],"ltp":5.9,"tv":17.82,"id":61077258}]}]}
{"op":"mcm","clk":"11924879388","pt":1724193578270,"mc":[{"id":"1.232013794","rc":[{"batb":[[0,7.4,10],[1,7.2,6.08],[2,2,58.4]],"ltp":5.9,"tv":17.82,"id":61077258}]}]}
{"op":"mcm","clk":"11924879625","pt":1724193581880,"mc":[{"id":"1.232013794","rc":[{"batb":[[0,7.2,6.08],[1,2,58.4],[2,1.06,149.69]],"ltp":5.9,"tv":17.82,"id":61077258}]}]}
{"op":"mcm","clk":"11924879744","pt":1724193584396,"mc":[{"id":"1.232013794","rc":[{"batb":[[0,7.4,10],[1,7.2,6.08],[2,2,58.4]],"ltp":5.9,"tv":17.82,"id":61077258}]}]}
{"op":"mcm","clk":"11924879980","pt":1724193588154,"mc":[{"id":"1.232013794","rc":[{"batb":[[0,7.2,6.08],[1,2,58.4],[2,1.06,149.69]],"ltp":5.9,"tv":17.82,"id":61077258}]}]}
{"op":"mcm","clk":"11924880143","pt":1724193590574,"mc":[{"id":"1.232013794","rc":[{"batb":[[0,7.4,10],[1,7.2,6.08],[2,2,58.4]],"ltp":5.9,"tv":17.82,"id":61077258}]}]}
{"op":"mcm","clk":"11924880339","pt":1724193594069,"mc":[{"id":"1.232013794","rc":[{"batb":[[0,7.2,6.08],[1,2,58.4],[2,1.06,149.69]],"ltp":5.9,"tv":17.82,"id":61077258}]}]}
{"op":"mcm","clk":"11924880512","pt":1724193596893,"mc":[{"id":"1.232013794","rc":[{"batb":[[0,7.4,10],[1,7.2,6.08],[2,2,58.4]],"ltp":5.9,"tv":17.82,"id":61077258}]}]}
{"op":"mcm","clk":"11924880664","pt":1724193600076,"mc":[{"id":"1.232013794","rc":[{"batb":[[0,7.2,6.08],[1,2,58.4],[2,1.06,149.69]],"ltp":5.9,"tv":17.82,"id":61077258}]}]}
{"op":"mcm","clk":"11924880858","pt":1724193603575,"mc":[{"id":"1.232013794","rc":[{"batb":[[0,7.4,10],[1,7.2,6.08],[2,2,58.4]],"ltp":5.9,"tv":17.82,"id":61077258}]}]}
{"op":"mcm","clk":"11924881045","pt":1724193606916,"mc":[{"id":"1.232013794","rc":[{"batb":[[0,7.2,6.08],[1,2,58.4],[2,1.06,149.69]],"ltp":5.9,"tv":17.82,"id":61077258}]}]}
{"op":"mcm","clk":"11924881153","pt":1724193609216,"mc":[{"id":"1.232013794","rc":[{"batb":[[0,7.4,10],[1,7.2,6.08],[2,2,58.4]],"ltp":5.9,"tv":17.82,"id":61077258}]}]}
{"op":"mcm","clk":"11924881360","pt":1724193612604,"mc":[{"id":"1.232013794","rc":[{"batb":[[0,7.2,6.08],[1,2,58.4],[2,1.06,149.69]],"ltp":5.9,"tv":17.82,"id":61077258}]}]}
{"op":"mcm","clk":"11924881529","pt":1724193615127,"mc":[{"id":"1.232013794","rc":[{"batb":[[0,7.4,10],[1,7.2,6.08],[2,2,58.4]],"ltp":5.9,"tv":17.82,"id":61077258}]}]}
{"op":"mcm","clk":"11924881722","pt":1724193618520,"mc":[{"id":"1.232013794","rc":[{"batb":[[0,7.2,6.08],[1,2,58.4],[2,1.06,149.69]],"ltp":5.9,"tv":17.82,"id":61077258}]}]}
{"op":"mcm","clk":"11924881885","pt":1724193621405,"mc":[{"id":"1.232013794","rc":[{"batb":[[0,7.4,10],[1,7.2,6.08],[2,2,58.4]],"ltp":5.9,"tv":17.82,"id":61077258}]}]}
{"op":"mcm","clk":"11924882082","pt":1724193624800,"mc":[{"id":"1.232013794","rc":[{"batb":[[0,7.2,6.08],[1,2,58.4],[2,1.06,149.69]],"ltp":5.9,"tv":17.82,"id":61077258}]}]}
{"op":"mcm","clk":"11924882233","pt":1724193627427,"mc":[{"id":"1.232013794","rc":[{"batb":[[0,7.4,10],[1,7.2,6.08],[2,2,58.4]],"ltp":5.9,"tv":17.82,"id":61077258}]}]}
{"op":"mcm","clk":"11924882374","pt":1724193630720,"mc":[{"id":"1.232013794","rc":[{"batb":[[0,7.2,6.08],[1,2,58.4],[2,1.06,149.69]],"ltp":5.9,"tv":17.82,"id":61077258}]}]}
{"op":"mcm","clk":"11924882489","pt":1724193633133,"mc":[{"id":"1.232013794","rc":[{"batb":[[0,7.4,10],[1,7.2,6.08],[2,2,58.4]],"ltp":5.9,"tv":17.82,"id":61077258}]}]}
{"op":"mcm","clk":"11924882661","pt":1724193636946,"mc":[{"id":"1.232013794","rc":[{"batb":[[0,7.2,6.08],[1,2,58.4],[2,1.06,149.69]],"ltp":5.9,"tv":17.82,"id":61077258}]}]}
{"op":"mcm","clk":"11924882814","pt":1724193640436,"mc":[{"id":"1.232013794","rc":[{"batb":[[0,7.4,10],[1,7.2,6.08],[2,2,58.4]],"ltp":5.9,"tv":17.82,"id":61077258}]}]}
{"op":"mcm","clk":"11924882960","pt":1724193643820,"mc":[{"id":"1.232013794","rc":[{"batb":[[0,7.2,6.08],[1,2,58.4],[2,1.06,149.69]],"ltp":5.9,"tv":17.82,"id":61077258}]}]}
{"op":"mcm","clk":"11924883114","pt":1724193647163,"mc":[{"id":"1.232013794","rc":[{"batb":[[0,7.4,10],[1,7.2,6.08],[2,2,58.4]],"ltp":5.9,"tv":17.82,"id":61077258}]}]}
{"op":"mcm","clk":"11924883302","pt":1724193650559,"mc":[{"id":"1.232013794","rc":[{"batb":[[0,7.2,6.08],[1,2,58.4],[2,1.06,149.69]],"ltp":5.9,"tv":17.82,"id":61077258}]}]}
{"op":"mcm","clk":"11924883476","pt":1724193653258,"mc":[{"id":"1.232013794","rc":[{"batb":[[0,7.4,10],[1,7.2,6.08],[2,2,58.4]],"ltp":5.9,"tv":17.82,"id":61077258}]}]}
{"op":"mcm","clk":"11924883680","pt":1724193656663,"mc":[{"id":"1.232013794","rc":[{"batb":[[0,7.2,6.08],[1,2,58.4],[2,1.06,149.69]],"ltp":5.9,"tv":17.82,"id":61077258}]}]}
{"op":"mcm","clk":"11924883813","pt":1724193659181,"mc":[{"id":"1.232013794","rc":[{"batb":[[0,7.4,10],[1,7.2,6.08],[2,2,58.4]],"ltp":5.9,"tv":17.82,"id":61077258}]}]}
{"op":"mcm","clk":"11924884055","pt":1724193662572,"mc":[{"id":"1.232013794","rc":[{"batb":[[0,7.2,6.08],[1,2,58.4],[2,1.06,149.69]],"ltp":5.9,"tv":17.82,"id":61077258}]}]}
{"op":"mcm","clk":"11924884216","pt":1724193664982,"mc":[{"id":"1.232013794","rc":[{"batb":[[0,7.4,10],[1,7.2,6.08],[2,2,58.4]],"ltp":5.9,"tv":17.82,"id":61077258}]}]}
{"op":"mcm","clk":"11924884371","pt":1724193668280,"mc":[{"id":"1.232013794","rc":[{"batb":[[0,7.2,6.08],[1,2,58.4],[2,1.06,149.69]],"ltp":5.9,"tv":17.82,"id":61077258}]}]}
{"op":"mcm","clk":"11924884507","pt":1724193671478,"mc":[{"id":"1.232013794","rc":[{"batb":[[0,7.4,10],[1,7.2,6.08],[2,2,58.4]],"ltp":5.9,"tv":17.82,"id":61077258}]}]}
{"op":"mcm","clk":"11924884681","pt":1724193674872,"mc":[{"id":"1.232013794","rc":[{"batb":[[0,7.2,6.08],[1,2,58.4],[2,1.06,149.69]],"ltp":5.9,"tv":17.82,"id":61077258}]}]}
{"op":"mcm","clk":"11924884832","pt":1724193678205,"mc":[{"id":"1.232013794","rc":[{"batb":[[0,7.4,10],[1,7.2,6.08],[2,2,58.4]],"ltp":5.9,"tv":17.82,"id":61077258}]}]}
{"op":"mcm","clk":"11924885003","pt":1724193681589,"mc":[{"id":"1.232013794","rc":[{"batb":[[0,7.2,6.08],[1,2,58.4],[2,1.06,149.69]],"ltp":5.9,"tv":17.82,"id":61077258}]}]}
{"op":"mcm","clk":"11924885141","pt":1724193684265,"mc":[{"id":"1.232013794","rc":[{"batb":[[0,7.4,10],[1,7.2,6.08],[2,2,58.4]],"ltp":5.9,"tv":17.82,"id":61077258}]}]}
{"op":"mcm","clk":"11924885310","pt":1724193687705,"mc":[{"id":"1.232013794","rc":[{"batb":[[0,7.2,6.08],[1,2,58.4],[2,1.06,149.69]],"ltp":5.9,"tv":17.82,"id":61077258}]}]}
{"op":"mcm","clk":"11924885449","pt":1724193690381,"mc":[{"id":"1.232013794","rc":[{"batb":[[0,7.4,10],[1,7.2,6.08],[2,2,58.4]],"ltp":5.9,"tv":17.82,"id":61077258}]}]}
{"op":"mcm","clk":"11924885665","pt":1724193693921,"mc":[{"id":"1.232013794","rc":[{"batb":[[0,7.2,6.08],[1,2,58.4],[2,1.06,149.69]],"ltp":5.9,"tv":17.82,"id":61077258}]}]}
{"op":"mcm","clk":"11924885836","pt":1724193696489,"mc":[{"id":"1.232013794","rc":[{"batb":[[0,7.4,10],[1,7.2,6.08],[2,2,58.4]],"ltp":5.9,"tv":17.82,"id":61077258}]}]}
{"op":"mcm","clk":"11924886004","pt":1724193699828,"mc":[{"id":"1.232013794","rc":[{"batb":[[0,7.2,6.08],[1,2,58.4],[2,1.06,149.69]],"ltp":5.9,"tv":17.82,"id":61077258}]}]}
{"op":"mcm","clk":"11924886179","pt":1724193702812,"mc":[{"id":"1.232013794","rc":[{"batb":[[0,7.4,10],[1,7.2,6.08],[2,2,58.4]],"ltp":5.9,"tv":17.82,"id":61077258}]}]}
{"op":"mcm","clk":"11924886369","pt":1724193706212,"mc":[{"id":"1.232013794","rc":[{"batb":[[0,7.2,6.08],[1,2,58.4],[2,1.06,149.69]],"ltp":5.9,"tv":17.82,"id":61077258}]}]}
{"op":"mcm","clk":"11924886485","pt":1724193708426,"mc":[{"id":"1.232013794","rc":[{"batb":[[0,7.4,10],[1,7.2,6.08],[2,2,58.4]],"ltp":5.9,"tv":17.82,"id":61077258}]}]}
{"op":"mcm","clk":"11924886688","pt":1724193711924,"mc":[{"id":"1.232013794","rc":[{"batb":[[0,7.2,6.08],[1,2,58.4],[2,1.06,149.69]],"ltp":5.9,"tv":17.82,"id":61077258}]}]}
{"op":"mcm","clk":"11924886816","pt":1724193714342,"mc":[{"id":"1.232013794","rc":[{"batb":[[0,7.4,10],[1,7.2,6.08],[2,2,58.4]],"ltp":5.9,"tv":17.82,"id":61077258}]}]}
{"op":"mcm","clk":"11924886979","pt":1724193717933,"mc":[{"id":"1.232013794","rc":[{"batb":[[0,7.2,6.08],[1,2,58.4],[2,1.06,149.69]],"ltp":5.9,"tv":17.82,"id":61077258}]}]}
{"op":"mcm","clk":"11924887085","pt":1724193720241,"mc":[{"id":"1.232013794","rc":[{"batb":[[0,7.4,10],[1,7.2,6.08],[2,2,58.4]],"ltp":5.9,"tv":17.82,"id":61077258}]}]}
{"op":"mcm","clk":"11924887245","pt":1724193723627,"mc":[{"id":"1.232013794","rc":[{"batb":[[0,7.2,6.08],[1,2,58.4],[2,1.06,149.69]],"ltp":5.9,"tv":17.82,"id":61077258}]}]}
{"op":"mcm","clk":"11924887381","pt":1724193726043,"mc":[{"id":"1.232013794","rc":[{"batb":[[0,7.4,10],[1,7.2,6.08],[2,2,58.4]],"ltp":5.9,"tv":17.82,"id":61077258}]}]}
{"op":"mcm","clk":"11924887553","pt":1724193729636,"mc":[{"id":"1.232013794","rc":[{"batb":[[0,7.2,6.08],[1,2,58.4],[2,1.06,149.69]],"ltp":5.9,"tv":17.82,"id":61077258}]}]}
{"op":"mcm","clk":"11924887745","pt":1724193733637,"mc":[{"id":"1.232013794","rc":[{"batb":[[0,7.4,10],[1,7.2,6.08],[2,2,58.4]],"ltp":5.9,"tv":17.82,"id":61077258}]}]}
{"op":"mcm","clk":"11924887913","pt":1724193737028,"mc":[{"id":"1.232013794","rc":[{"batb":[[0,7.2,6.08],[1,2,58.4],[2,1.06,149.69]],"ltp":5.9,"tv":17.82,"id":61077258}]}]}
{"op":"mcm","clk":"11924888073","pt":1724193740167,"mc":[{"id":"1.232013794","rc":[{"batb":[[0,7.4,10],[1,7.2,6.08],[2,2,58.4]],"ltp":5.9,"tv":17.82,"id":61077258}]}]}
{"op":"mcm","clk":"11924888280","pt":1724193743452,"mc":[{"id":"1.232013794","rc":[{"batb":[[0,7.2,6.08],[1,2,58.4],[2,1.06,149.69]],"ltp":5.9,"tv":17.82,"id":61077258}]}]}
{"op":"mcm","clk":"11924888416","pt":1724193746169,"mc":[{"id":"1.232013794","rc":[{"batb":[[0,7.4,10],[1,7.2,6.08],[2,2,58.4]],"ltp":5.9,"tv":17.82,"id":61077258}]}]}
{"op":"mcm","clk":"11924888618","pt":1724193749461,"mc":[{"id":"1.232013794","rc":[{"batb":[[0,7.2,6.08],[1,2,58.4],[2,1.06,149.69]],"ltp":5.9,"tv":17.82,"id":61077258}]}]}
{"op":"mcm","clk":"11924888756","pt":1724193752081,"mc":[{"id":"1.232013794","rc":[{"batb":[[0,7.4,10],[1,7.2,6.08],[2,2,58.4]],"ltp":5.9,"tv":17.82,"id":61077258}]}]}
{"op":"mcm","clk":"11924888958","pt":1724193755482,"mc":[{"id":"1.232013794","rc":[{"batb":[[0,7.2,6.08],[1,2,58.4],[2,1.06,149.69]],"ltp":5.9,"tv":17.82,"id":61077258}]}]}
{"op":"mcm","clk":"11924889095","pt":1724193757795,"mc":[{"id":"1.232013794","rc":[{"batb":[[0,7.4,10],[1,7.2,6.08],[2,2,58.4]],"ltp":5.9,"tv":17.82,"id":61077258}]}]}
{"op":"mcm","clk":"11924889270","pt":1724193760983,"mc":[{"id":"1.232013794","rc":[{"batb":[[0,7.2,6.08],[1,2,58.4],[2,1.06,149.69]],"ltp":5.9,"tv":17.82,"id":61077258}]}]}
{"op":"mcm","clk":"11924889472","pt":1724193764771,"mc":[{"id":"1.232013794","rc":[{"batb":[[0,7.4,10],[1,7.2,6.08],[2,2,58.4]],"ltp":5.9,"tv":17.82,"id":61077258}]}]}
{"op":"mcm","clk":"11924889628","pt":1724193768013,"mc":[{"id":"1.232013794","rc":[{"batb":[[0,7.2,6.08],[1,2,58.4],[2,1.06,149.69]],"ltp":5.9,"tv":17.82,"id":61077258}]}]}
{"op":"mcm","clk":"11924889795","pt":1724193770899,"mc":[{"id":"1.232013794","rc":[{"batb":[[0,7.4,10],[1,7.2,6.08],[2,2,58.4]],"ltp":5.9,"tv":17.82,"id":61077258}]}]}
{"op":"mcm","clk":"11924889962","pt":1724193774125,"mc":[{"id":"1.232013794","rc":[{"batb":[[0,7.2,6.08],[1,2,58.4],[2,1.06,149.69]],"ltp":5.9,"tv":17.82,"id":61077258}]}]}
{"op":"mcm","clk":"11924890131","pt":1724193777202,"mc":[{"id":"1.232013794","rc":[{"batb":[[0,7.4,10],[1,7.2,6.08],[2,2,58.4]],"ltp":5.9,"tv":17.82,"id":61077258}]}]}
{"op":"mcm","clk":"11924890313","pt":1724193780800,"mc":[{"id":"1.232013794","rc":[{"batb":[[0,7.2,6.08],[1,2,58.4],[2,1.06,149.69]],"ltp":5.9,"tv":17.82,"id":61077258}]}]}
{"op":"mcm","clk":"11924890444","pt":1724193783212,"mc":[{"id":"1.232013794","rc":[{"batb":[[0,7.4,10],[1,7.2,6.08],[2,2,58.4]],"ltp":5.9,"tv":17.82,"id":61077258}]}]}
{"op":"mcm","clk":"11924890600","pt":1724193786641,"mc":[{"id":"1.232013794","rc":[{"batb":[[0,7.2,6.08],[1,2,58.4],[2,1.06,149.69]],"ltp":5.9,"tv":17.82,"id":61077258}]}]}
{"op":"mcm","clk":"11924890731","pt":1724193789005,"mc":[{"id":"1.232013794","rc":[{"batb":[[0,7.4,10],[1,7.2,6.08],[2,2,58.4]],"ltp":5.9,"tv":17.82,"id":61077258}]}]}
{"op":"mcm","clk":"11924890898","pt":1724193792432,"mc":[{"id":"1.232013794","rc":[{"batb":[[0,7.2,6.08],[1,2,58.4],[2,1.06,149.69]],"ltp":5.9,"tv":17.82,"id":61077258}]}]}
{"op":"mcm","clk":"11924891030","pt":1724193794638,"mc":[{"id":"1.232013794","rc":[{"batb":[[0,7.4,10],[1,7.2,6.08],[2,2,58.4]],"ltp":5.9,"tv":17.82,"id":61077258}]}]}
{"op":"mcm","clk":"11924891213","pt":1724193798399,"mc":[{"id":"1.232013794","rc":[{"batb":[[0,7.2,6.08],[1,2,58.4],[2,1.06,149.69]],"ltp":5.9,"tv":17.82,"id":61077258}]}]}
{"op":"mcm","clk":"11924891359","pt":1724193801328,"mc":[{"id":"1.232013794","rc":[{"batb":[[0,7.4,10],[1,7.2,6.08],[2,2,58.4]],"ltp":5.9,"tv":17.82,"id":61077258}]}]}
{"op":"mcm","clk":"11924891525","pt":1724193804759,"mc":[{"id":"1.232013794","rc":[{"batb":[[0,7.2,6.08],[1,2,58.4],[2,1.06,149.69]],"ltp":5.9,"tv":17.82,"id":61077258}]}]}
{"op":"mcm","clk":"11924891641","pt":1724193807274,"mc":[{"id":"1.232013794","rc":[{"batb":[[0,7.4,10],[1,7.2,6.08],[2,2,58.4]],"ltp":5.9,"tv":17.82,"id":61077258}]}]}
{"op":"mcm","clk":"11924891968","pt":1724193810660,"mc":[{"id":"1.232013794","rc":[{"batb":[[0,7.2,6.08],[1,2,58.4],[2,1.06,149.69]],"ltp":5.9,"tv":17.82,"id":61077258}]}]}
{"op":"mcm","clk":"11924892411","pt":1724193813965,"mc":[{"id":"1.232013794","rc":[{"batb":[[0,7.4,10],[1,7.2,6.08],[2,2,58.4]],"ltp":5.9,"tv":17.82,"id":61077258}]}]}
{"op":"mcm","clk":"11924892840","pt":1724193817357,"mc":[{"id":"1.232013794","rc":[{"batb":[[0,7.2,6.08],[1,2,58.4],[2,1.06,149.69]],"ltp":5.9,"tv":17.82,"id":61077258}]}]}
{"op":"mcm","clk":"11924893118","pt":1724193820079,"mc":[{"id":"1.232013794","rc":[{"batb":[[0,7.4,10],[1,7.2,6.08],[2,2,58.4]],"ltp":5.9,"tv":17.82,"id":61077258}]}]}
{"op":"mcm","clk":"11924893502","pt":1724193823257,"mc":[{"id":"1.232013794","rc":[{"batb":[[0,7.2,6.08],[1,2,58.4],[2,1.06,149.69]],"ltp":5.9,"tv":17.82,"id":61077258}]}]}
{"op":"mcm","clk":"11924893869","pt":1724193825675,"mc":[{"id":"1.232013794","rc":[{"batb":[[0,7.4,10],[1,7.2,6.08],[2,2,58.4]],"ltp":5.9,"tv":17.82,"id":61077258}]}]}
{"op":"mcm","clk":"11924894227","pt":1724193829056,"mc":[{"id":"1.232013794","rc":[{"batb":[[0,7.2,6.08],[1,2,58.4],[2,1.06,149.69]],"ltp":5.9,"tv":17.82,"id":61077258}]}]}
{"op":"mcm","clk":"11924894411","pt":1724193832488,"mc":[{"id":"1.232013794","rc":[{"batb":[[0,7.4,10],[1,7.2,6.08],[2,2,58.4]],"ltp":5.9,"tv":17.82,"id":61077258}]}]}
{"op":"mcm","clk":"11924894560","pt":1724193835766,"mc":[{"id":"1.232013794","rc":[{"batb":[[0,7.2,6.08],[1,2,58.4],[2,1.06,149.69]],"ltp":5.9,"tv":17.82,"id":61077258}]}]}
{"op":"mcm","clk":"11924894661","pt":1724193837978,"mc":[{"id":"1.232013794","rc":[{"batb":[[0,7.4,10],[1,7.2,6.08],[2,2,58.4]],"ltp":5.9,"tv":17.82,"id":61077258}]}]}
{"op":"mcm","clk":"11924894775","pt":1724193841309,"mc":[{"id":"1.232013794","rc":[{"batb":[[0,7.2,6.08],[1,2,58.4],[2,1.06,149.69]],"ltp":5.9,"tv":17.82,"id":61077258}]}]}
{"op":"mcm","clk":"11924894916","pt":1724193844497,"mc":[{"id":"1.232013794","rc":[{"batb":[[0,7.4,10],[1,7.2,6.08],[2,2,58.4]],"ltp":5.9,"tv":17.82,"id":61077258}]}]}
{"op":"mcm","clk":"11924895057","pt":1724193847686,"mc":[{"id":"1.232013794","rc":[{"batb":[[0,7.2,6.08],[1,2,58.4],[2,1.06,149.69]],"ltp":5.9,"tv":17.82,"id":61077258}]}]}
{"op":"mcm","clk":"11924895190","pt":1724193850714,"mc":[{"id":"1.232013794","rc":[{"batb":[[0,7.4,10],[1,7.2,6.08],[2,2,58.4]],"ltp":5.9,"tv":17.82,"id":61077258}]}]}
{"op":"mcm","clk":"11924895329","pt":1724193853899,"mc":[{"id":"1.232013794","rc":[{"batb":[[0,7.2,6.08],[1,2,58.4],[2,1.06,149.69]],"ltp":5.9,"tv":17.82,"id":61077258}]}]}
{"op":"mcm","clk":"11924895468","pt":1724193856926,"mc":[{"id":"1.232013794","rc":[{"batb":[[0,7.4,10],[1,7.2,6.08],[2,2,58.4]],"ltp":5.9,"tv":17.82,"id":61077258}]}]}
{"op":"mcm","clk":"11924895629","pt":1724193860515,"mc":[{"id":"1.232013794","rc":[{"batb":[[0,7.2,6.08],[1,2,58.4],[2,1.06,149.69]],"ltp":5.9,"tv":17.82,"id":61077258}]}]}
{"op":"mcm","clk":"11924895747","pt":1724193863028,"mc":[{"id":"1.232013794","rc":[{"batb":[[0,7.4,10],[1,7.2,6.08],[2,2,58.4]],"ltp":5.9,"tv":17.82,"id":61077258}]}]}
{"op":"mcm","clk":"11924896211","pt":1724193866251,"mc":[{"id":"1.232013794","rc":[{"batb":[[0,7.2,6.08],[1,2,58.4],[2,1.06,149.69]],"ltp":5.9,"tv":17.82,"id":61077258}]}]}
{"op":"mcm","clk":"11924896740","pt":1724193869185,"mc":[{"id":"1.232013794","rc":[{"batb":[[0,7.4,10],[1,7.2,6.08],[2,2,58.4]],"ltp":5.9,"tv":17.82,"id":61077258}]}]}
{"op":"mcm","clk":"11924897624","pt":1724193873703,"mc":[{"id":"1.232013794","rc":[{"batb":[[0,7.2,6.08],[1,2,58.4],[2,1.06,149.69]],"ltp":5.9,"tv":17.82,"id":61077258}]}]}
{"op":"mcm","clk":"11924898072","pt":1724193877194,"mc":[{"id":"1.232013794","rc":[{"batb":[[0,7.4,10],[1,7.2,6.08],[2,2,58.4]],"ltp":5.9,"tv":17.82,"id":61077258}]}]}
{"op":"mcm","clk":"11924898355","pt":1724193880463,"mc":[{"id":"1.232013794","rc":[{"batb":[[0,7.2,6.08],[1,2,58.4],[2,1.06,149.69]],"ltp":5.9,"tv":17.82,"id":61077258}]}]}
{"op":"mcm","clk":"11924898576","pt":1724193883607,"mc":[{"id":"1.232013794","rc":[{"batb":[[0,7.4,10],[1,7.2,6.08],[2,2,58.4]],"ltp":5.9,"tv":17.82,"id":61077258}]}]}
{"op":"mcm","clk":"11924898826","pt":1724193887013,"mc":[{"id":"1.232013794","rc":[{"batb":[[0,7.2,6.08],[1,2,58.4],[2,1.06,149.69]],"ltp":5.9,"tv":17.82,"id":61077258}]}]}
{"op":"mcm","clk":"11924899033","pt":1724193889801,"mc":[{"id":"1.232013794","rc":[{"batb":[[0,7.4,10],[1,7.2,6.08],[2,2,58.4]],"ltp":5.9,"tv":17.82,"id":61077258}]}]}
{"op":"mcm","clk":"11924899326","pt":1724193893515,"mc":[{"id":"1.232013794","rc":[{"batb":[[0,7.2,6.08],[1,2,58.4],[2,1.06,149.69]],"ltp":5.9,"tv":17.82,"id":61077258}]}]}
{"op":"mcm","clk":"11924899886","pt":1724193900436,"mc":[{"id":"1.232013794","rc":[{"batb":[[0,7.4,10],[1,7.2,6.08],[2,2,58.4]],"ltp":5.9,"tv":17.82,"id":61077258}]}]}
{"op":"mcm","clk":"11924900225","pt":1724193904225,"mc":[{"id":"1.232013794","rc":[{"batb":[[0,7.2,6.08],[1,2,58.4],[2,1.06,149.69]],"ltp":5.9,"tv":17.82,"id":61077258}]}]}
{"op":"mcm","clk":"11924900571","pt":1724193908243,"mc":[{"id":"1.232013794","rc":[{"batb":[[0,7.4,10],[1,7.2,6.08],[2,2,58.4]],"ltp":5.9,"tv":17.82,"id":61077258}]}]}
{"op":"mcm","clk":"11924900885","pt":1724193911667,"mc":[{"id":"1.232013794","rc":[{"batb":[[0,7.2,6.08],[1,2,58.4],[2,1.06,149.69]],"ltp":5.9,"tv":17.82,"id":61077258}]}]}
{"op":"mcm","clk":"11924901148","pt":1724193914559,"mc":[{"id":"1.232013794","rc":[{"batb":[[0,7.4,10],[1,7.2,6.08],[2,2,58.4]],"ltp":5.9,"tv":17.82,"id":61077258}]}]}
{"op":"mcm","clk":"11924901412","pt":1724193917868,"mc":[{"id":"1.232013794","rc":[{"batb":[[0,7.2,6.08],[1,2,58.4],[2,1.06,149.69]],"ltp":5.9,"tv":17.82,"id":61077258}]}]}
{"op":"mcm","clk":"11924901782","pt":1724193921679,"mc":[{"id":"1.232013794","rc":[{"batb":[[0,7.4,10],[1,7.2,6.08],[2,2,58.4]],"ltp":5.9,"tv":17.82,"id":61077258}]}]}
{"op":"mcm","clk":"11924902130","pt":1724193925340,"mc":[{"id":"1.232013794","rc":[{"batb":[[0,7.2,6.08],[1,2,58.4],[2,1.06,149.69]],"ltp":5.9,"tv":17.82,"id":61077258}]}]}
{"op":"mcm","clk":"11924902452","pt":1724193928844,"mc":[{"id":"1.232013794","rc":[{"batb":[[0,7.4,10],[1,7.2,6.08],[2,2,58.4]],"ltp":5.9,"tv":17.82,"id":61077258}]}]}
{"op":"mcm","clk":"11924902778","pt":1724193932354,"mc":[{"id":"1.232013794","rc":[{"batb":[[0,7.2,6.08],[1,2,58.4],[2,1.06,149.69]],"ltp":5.9,"tv":17.82,"id":61077258}]}]}
{"op":"mcm","clk":"11924903049","pt":1724193935870,"mc":[{"id":"1.232013794","rc":[{"batb":[[0,7.4,10],[1,7.2,6.08],[2,2,58.4]],"ltp":5.9,"tv":17.82,"id":61077258}]}]}
{"op":"mcm","clk":"11924903329","pt":1724193939385,"mc":[{"id":"1.232013794","rc":[{"batb":[[0,7.2,6.08],[1,2,58.4],[2,1.06,149.69]],"ltp":5.9,"tv":17.82,"id":61077258}]}]}
{"op":"mcm","clk":"11924903514","pt":1724193941966,"mc":[{"id":"1.232013794","rc":[{"batb":[[0,7.4,10],[1,7.2,6.08],[2,2,58.4]],"ltp":5.9,"tv":17.82,"id":61077258}]}]}
{"op":"mcm","clk":"11924903779","pt":1724193945586,"mc":[{"id":"1.232013794","rc":[{"batb":[[0,7.2,6.08],[1,2,58.4],[2,1.06,149.69]],"ltp":5.9,"tv":17.82,"id":61077258}]}]}
{"op":"mcm","clk":"11924904051","pt":1724193948864,"mc":[{"id":"1.232013794","rc":[{"batb":[[0,7.4,10],[1,7.2,6.08],[2,2,58.4]],"ltp":5.9,"tv":17.82,"id":61077258}]}]}
{"op":"mcm","clk":"11924904345","pt":1724193952262,"mc":[{"id":"1.232013794","rc":[{"batb":[[0,7.2,6.08],[1,2,58.4],[2,1.06,149.69]],"ltp":5.9,"tv":17.82,"id":61077258}]}]}
{"op":"mcm","clk":"11924904560","pt":1724193954779,"mc":[{"id":"1.232013794","rc":[{"batb":[[0,7.4,10],[1,7.2,6.08],[2,2,58.4]],"ltp":5.9,"tv":17.82,"id":61077258}]}]}
{"op":"mcm","clk":"11924905151","pt":1724193958081,"mc":[{"id":"1.232013794","rc":[{"batb":[[0,7.2,6.08],[1,2,58.4],[2,1.06,149.69]],"ltp":5.9,"tv":17.82,"id":61077258}]}]}
{"op":"mcm","clk":"11924905393","pt":1724193960408,"mc":[{"id":"1.232013794","rc":[{"batb":[[0,7.4,10],[1,7.2,6.08],[2,2,58.4]],"ltp":5.9,"tv":17.82,"id":61077258}]}]}
{"op":"mcm","clk":"11924905737","pt":1724193963723,"mc":[{"id":"1.232013794","rc":[{"batb":[[0,7.2,6.08],[1,2,58.4],[2,1.06,149.69]],"ltp":5.9,"tv":17.82,"id":61077258}]}]}
{"op":"mcm","clk":"11924905973","pt":1724193966111,"mc":[{"id":"1.232013794","rc":[{"batb":[[0,7.4,10],[1,7.2,6.08],[2,2,58.4]],"ltp":5.9,"tv":17.82,"id":61077258}]}]}
{"op":"mcm","clk":"11924906368","pt":1724193969385,"mc":[{"id":"1.232013794","rc":[{"batb":[[0,7.2,6.08],[1,2,58.4],[2,1.06,149.69]],"ltp":5.9,"tv":17.82,"id":61077258}]}]}
{"op":"mcm","clk":"11924906685","pt":1724193972682,"mc":[{"id":"1.232013794","rc":[{"batb":[[0,7.4,10],[1,7.2,6.08],[2,2,58.4]],"ltp":5.9,"tv":17.82,"id":61077258}]}]}
{"op":"mcm","clk":"11924906971","pt":1724193975982,"mc":[{"id":"1.232013794","rc":[{"batb":[[0,7.2,6.08],[1,2,58.4],[2,1.06,149.69]],"ltp":5.9,"tv":17.82,"id":61077258}]}]}
{"op":"mcm","clk":"11924907290","pt":1724193980094,"mc":[{"id":"1.232013794","rc":[{"batb":[[0,7.4,10],[1,7.2,6.08],[2,2,58.4]],"ltp":5.9,"tv":17.82,"id":61077258}]}]}
{"op":"mcm","clk":"11924907582","pt":1724193983409,"mc":[{"id":"1.232013794","rc":[{"batb":[[0,7.2,6.08],[1,2,58.4],[2,1.06,149.69]],"ltp":5.9,"tv":17.82,"id":61077258}]}]}
{"op":"mcm","clk":"11924907807","pt":1724193986098,"mc":[{"id":"1.232013794","rc":[{"batb":[[0,7.4,10],[1,7.2,6.08],[2,2,58.4]],"ltp":5.9,"tv":17.82,"id":61077258}]}]}
{"op":"mcm","clk":"11924908065","pt":1724193989513,"mc":[{"id":"1.232013794","rc":[{"batb":[[0,7.2,6.08],[1,2,58.4],[2,1.06,149.69]],"ltp":5.9,"tv":17.82,"id":61077258}]}]}
{"op":"mcm","clk":"11924908265","pt":1724193991890,"mc":[{"id":"1.232013794","rc":[{"batb":[[0,7.4,10],[1,7.2,6.08],[2,2,58.4]],"ltp":5.9,"tv":17.82,"id":61077258}]}]}
{"op":"mcm","clk":"11924908556","pt":1724193995522,"mc":[{"id":"1.232013794","rc":[{"batb":[[0,7.2,6.08],[1,2,58.4],[2,1.06,149.69]],"ltp":5.9,"tv":17.82,"id":61077258}]}]}
{"op":"mcm","clk":"11924908815","pt":1724193998622,"mc":[{"id":"1.232013794","rc":[{"batb":[[0,7.4,10],[1,7.2,6.08],[2,2,58.4]],"ltp":5.9,"tv":17.82,"id":61077258}]}]}
{"op":"mcm","clk":"11924909052","pt":1724194001947,"mc":[{"id":"1.232013794","rc":[{"batb":[[0,7.2,6.08],[1,2,58.4],[2,1.06,149.69]],"ltp":5.9,"tv":17.82,"id":61077258}]}]}
{"op":"mcm","clk":"11924909289","pt":1724194005158,"mc":[{"id":"1.232013794","rc":[{"batb":[[0,7.4,10],[1,7.2,6.08],[2,2,58.4]],"ltp":5.9,"tv":17.82,"id":61077258}]}]}
{"op":"mcm","clk":"11924909536","pt":1724194008562,"mc":[{"id":"1.232013794","rc":[{"batb":[[0,7.2,6.08],[1,2,58.4],[2,1.06,149.69]],"ltp":5.9,"tv":17.82,"id":61077258}]}]}
{"op":"mcm","clk":"11924909753","pt":1724194011763,"mc":[{"id":"1.232013794","rc":[{"batb":[[0,7.4,10],[1,7.2,6.08],[2,2,58.4]],"ltp":5.9,"tv":17.82,"id":61077258}]}]}
{"op":"mcm","clk":"11924909988","pt":1724194015056,"mc":[{"id":"1.232013794","rc":[{"batb":[[0,7.2,6.08],[1,2,58.4],[2,1.06,149.69]],"ltp":5.9,"tv":17.82,"id":61077258}]}]}
{"op":"mcm","clk":"11924910168","pt":1724194017730,"mc":[{"id":"1.232013794","rc":[{"batb":[[0,7.4,10],[1,7.2,6.08],[2,2,58.4]],"ltp":5.9,"tv":17.82,"id":61077258}]}]}
{"op":"mcm","clk":"11924910382","pt":1724194020969,"mc":[{"id":"1.232013794","rc":[{"batb":[[0,7.2,6.08],[1,2,58.4],[2,1.06,149.69]],"ltp":5.9,"tv":17.82,"id":61077258}]}]}
{"op":"mcm","clk":"11924910585","pt":1724194023655,"mc":[{"id":"1.232013794","rc":[{"batb":[[0,7.4,10],[1,7.2,6.08],[2,2,58.4]],"ltp":5.9,"tv":17.82,"id":61077258}]}]}
{"op":"mcm","clk":"11924910848","pt":1724194027162,"mc":[{"id":"1.232013794","rc":[{"batb":[[0,7.2,6.08],[1,2,58.4],[2,1.06,149.69]],"ltp":5.9,"tv":17.82,"id":61077258}]}]}
{"op":"mcm","clk":"11924911035","pt":1724194030557,"mc":[{"id":"1.232013794","rc":[{"batb":[[0,7.4,10],[1,7.2,6.08],[2,2,58.4]],"ltp":5.9,"tv":17.82,"id":61077258}]}]}
{"op":"mcm","clk":"11924911261","pt":1724194033745,"mc":[{"id":"1.232013794","rc":[{"batb":[[0,7.2,6.08],[1,2,58.4],[2,1.06,149.69]],"ltp":5.9,"tv":17.82,"id":61077258}]}]}
{"op":"mcm","clk":"11924911433","pt":1724194035956,"mc":[{"id":"1.232013794","rc":[{"batb":[[0,7.4,10],[1,7.2,6.08],[2,2,58.4]],"ltp":5.9,"tv":17.82,"id":61077258}]}]}
{"op":"mcm","clk":"11924911648","pt":1724194039502,"mc":[{"id":"1.232013794","rc":[{"batb":[[0,7.2,6.08],[1,2,58.4],[2,1.06,149.69]],"ltp":5.9,"tv":17.82,"id":61077258}]}]}
{"op":"mcm","clk":"11924911838","pt":1724194041949,"mc":[{"id":"1.232013794","rc":[{"batb":[[0,7.4,10],[1,7.2,6.08],[2,2,58.4]],"ltp":5.9,"tv":17.82,"id":61077258}]}]}
{"op":"mcm","clk":"11924912083","pt":1724194045257,"mc":[{"id":"1.232013794","rc":[{"batb":[[0,7.2,6.08],[1,2,58.4],[2,1.06,149.69]],"ltp":5.9,"tv":17.82,"id":61077258}]}]}
{"op":"mcm","clk":"11924912327","pt":1724194049079,"mc":[{"id":"1.232013794","rc":[{"batb":[[0,7.4,10],[1,7.2,6.08],[2,2,58.4]],"ltp":5.9,"tv":17.82,"id":61077258}]}]}
{"op":"mcm","clk":"11924912545","pt":1724194052489,"mc":[{"id":"1.232013794","rc":[{"batb":[[0,7.2,6.08],[1,2,58.4],[2,1.06,149.69]],"ltp":5.9,"tv":17.82,"id":61077258}]}]}
{"op":"mcm","clk":"11924912735","pt":1724194055371,"mc":[{"id":"1.232013794","rc":[{"batb":[[0,7.4,10],[1,7.2,6.08],[2,2,58.4]],"ltp":5.9,"tv":17.82,"id":61077258}]}]}
{"op":"mcm","clk":"11924912969","pt":1724194058992,"mc":[{"id":"1.232013794","rc":[{"batb":[[0,7.2,6.08],[1,2,58.4],[2,1.06,149.69]],"ltp":5.9,"tv":17.82,"id":61077258}]}]}
{"op":"mcm","clk":"11924913363","pt":1724194065496,"mc":[{"id":"1.232013794","rc":[{"batb":[[0,7.4,10],[1,7.2,6.08],[2,2,58.4]],"ltp":5.9,"tv":17.82,"id":61077258}]}]}
{"op":"mcm","clk":"11924913565","pt":1724194068900,"mc":[{"id":"1.232013794","rc":[{"batb":[[0,7.2,6.08],[1,2,58.4],[2,1.06,149.69]],"ltp":5.9,"tv":17.82,"id":61077258}]}]}
{"op":"mcm","clk":"11924913733","pt":1724194071415,"mc":[{"id":"1.232013794","rc":[{"batb":[[0,7.4,10],[1,7.2,6.08],[2,2,58.4]],"ltp":5.9,"tv":17.82,"id":61077258}]}]}
{"op":"mcm","clk":"11924913931","pt":1724194074607,"mc":[{"id":"1.232013794","rc":[{"batb":[[0,7.2,6.08],[1,2,58.4],[2,1.06,149.69]],"ltp":5.9,"tv":17.82,"id":61077258}]}]}
{"op":"mcm","clk":"11924914056","pt":1724194076812,"mc":[{"id":"1.232013794","rc":[{"batb":[[0,7.4,10],[1,7.2,6.08],[2,2,58.4]],"ltp":5.9,"tv":17.82,"id":61077258}]}]}
{"op":"mcm","clk":"11924914264","pt":1724194080514,"mc":[{"id":"1.232013794","rc":[{"batb":[[0,7.2,6.08],[1,2,58.4],[2,1.06,149.69]],"ltp":5.9,"tv":17.82,"id":61077258}]}]}
{"op":"mcm","clk":"11924914397","pt":1724194082793,"mc":[{"id":"1.232013794","rc":[{"batb":[[0,7.4,10],[1,7.2,6.08],[2,2,58.4]],"ltp":5.9,"tv":17.82,"id":61077258}]}]}
{"op":"mcm","clk":"11924914638","pt":1724194086306,"mc":[{"id":"1.232013794","rc":[{"batb":[[0,7.2,6.08],[1,2,58.4],[2,1.06,149.69]],"ltp":5.9,"tv":17.82,"id":61077258}]}]}
{"op":"mcm","clk":"11924914836","pt":1724194089122,"mc":[{"id":"1.232013794","rc":[{"batb":[[0,7.4,10],[1,7.2,6.08],[2,2,58.4]],"ltp":5.9,"tv":17.82,"id":61077258}]}]}
{"op":"mcm","clk":"11924915089","pt":1724194092726,"mc":[{"id":"1.232013794","rc":[{"batb":[[0,7.2,6.08],[1,2,58.4],[2,1.06,149.69]],"ltp":5.9,"tv":17.82,"id":61077258}]}]}
{"op":"mcm","clk":"11924915276","pt":1724194095508,"mc":[{"id":"1.232013794","rc":[{"batb":[[0,7.4,10],[1,7.2,6.08],[2,2,58.4]],"ltp":5.9,"tv":17.82,"id":61077258}]}]}
{"op":"mcm","clk":"11924915530","pt":1724194099016,"mc":[{"id":"1.232013794","rc":[{"batb":[[0,7.2,6.08],[1,2,58.4],[2,1.06,149.69]],"ltp":5.9,"tv":17.82,"id":61077258}]}]}
{"op":"mcm","clk":"11924915736","pt":1724194102314,"mc":[{"id":"1.232013794","rc":[{"batb":[[0,7.4,10],[1,7.2,6.08],[2,2,58.4]],"ltp":5.9,"tv":17.82,"id":61077258}]}]}
{"op":"mcm","clk":"11924915927","pt":1724194105708,"mc":[{"id":"1.232013794","rc":[{"batb":[[0,7.2,6.08],[1,2,58.4],[2,1.06,149.69]],"ltp":5.9,"tv":17.82,"id":61077258}]}]}
{"op":"mcm","clk":"11924916102","pt":1724194108531,"mc":[{"id":"1.232013794","rc":[{"batb":[[0,7.4,10],[1,7.2,6.08],[2,2,58.4]],"ltp":5.9,"tv":17.82,"id":61077258}]}]}
{"op":"mcm","clk":"11924916342","pt":1724194112035,"mc":[{"id":"1.232013794","rc":[{"batb":[[0,7.2,6.08],[1,2,58.4],[2,1.06,149.69]],"ltp":5.9,"tv":17.82,"id":61077258}]}]}
{"op":"mcm","clk":"11924916491","pt":1724194114523,"mc":[{"id":"1.232013794","rc":[{"batb":[[0,7.4,10],[1,7.2,6.08],[2,2,58.4]],"ltp":5.9,"tv":17.82,"id":61077258}]}]}
{"op":"mcm","clk":"11924916710","pt":1724194117838,"mc":[{"id":"1.232013794","rc":[{"batb":[[0,7.2,6.08],[1,2,58.4],[2,1.06,149.69]],"ltp":5.9,"tv":17.82,"id":61077258}]}]}
{"op":"mcm","clk":"11924916860","pt":1724194120566,"mc":[{"id":"1.232013794","rc":[{"batb":[[0,7.4,10],[1,7.2,6.08],[2,2,58.4]],"ltp":5.9,"tv":17.82,"id":61077258}]}]}
{"op":"mcm","clk":"11924917121","pt":1724194123974,"mc":[{"id":"1.232013794","rc":[{"batb":[[0,7.2,6.08],[1,2,58.4],[2,1.06,149.69]],"ltp":5.9,"tv":17.82,"id":61077258}]}]}
{"op":"mcm","clk":"11924917301","pt":1724194126537,"mc":[{"id":"1.232013794","rc":[{"batb":[[0,7.4,10],[1,7.2,6.08],[2,2,58.4]],"ltp":5.9,"tv":17.82,"id":61077258}]}]}
{"op":"mcm","clk":"11924917497","pt":1724194129831,"mc":[{"id":"1.232013794","rc":[{"batb":[[0,7.2,6.08],[1,2,58.4],[2,1.06,149.69]],"ltp":5.9,"tv":17.82,"id":61077258}]}]}
{"op":"mcm","clk":"11924917619","pt":1724194132555,"mc":[{"id":"1.232013794","rc":[{"batb":[[0,7.4,10],[1,7.2,6.08],[2,2,58.4]],"ltp":5.9,"tv":17.82,"id":61077258}]}]}
{"op":"mcm","clk":"11924917817","pt":1724194135847,"mc":[{"id":"1.232013794","rc":[{"batb":[[0,7.2,6.08],[1,2,58.4],[2,1.06,149.69]],"ltp":5.9,"tv":17.82,"id":61077258}]}]}
{"op":"mcm","clk":"11924917970","pt":1724194138063,"mc":[{"id":"1.232013794","rc":[{"batb":[[0,7.4,10],[1,7.2,6.08],[2,2,58.4]],"ltp":5.9,"tv":17.82,"id":61077258}]}]}
{"op":"mcm","clk":"11924918140","pt":1724194141352,"mc":[{"id":"1.232013794","rc":[{"batb":[[0,7.2,6.08],[1,2,58.4],[2,1.06,149.69]],"ltp":5.9,"tv":17.82,"id":61077258}]}]}
{"op":"mcm","clk":"11924918307","pt":1724194143677,"mc":[{"id":"1.232013794","rc":[{"batb":[[0,7.4,10],[1,7.2,6.08],[2,2,58.4]],"ltp":5.9,"tv":17.82,"id":61077258}]}]}
{"op":"mcm","clk":"11924918512","pt":1724194146964,"mc":[{"id":"1.232013794","rc":[{"batb":[[0,7.2,6.08],[1,2,58.4],[2,1.06,149.69]],"ltp":5.9,"tv":17.82,"id":61077258}]}]}
{"op":"mcm","clk":"11924918689","pt":1724194149600,"mc":[{"id":"1.232013794","rc":[{"batb":[[0,7.4,10],[1,7.2,6.08],[2,2,58.4]],"ltp":5.9,"tv":17.82,"id":61077258}]}]}
{"op":"mcm","clk":"11924918918","pt":1724194153204,"mc":[{"id":"1.232013794","rc":[{"batb":[[0,7.2,6.08],[1,2,58.4],[2,1.06,149.69]],"ltp":5.9,"tv":17.82,"id":61077258}]}]}
{"op":"mcm","clk":"11924919111","pt":1724194156605,"mc":[{"id":"1.232013794","rc":[{"batb":[[0,7.4,10],[1,7.2,6.08],[2,2,58.4]],"ltp":5.9,"tv":17.82,"id":61077258}]}]}
{"op":"mcm","clk":"11924919293","pt":1724194159900,"mc":[{"id":"1.232013794","rc":[{"batb":[[0,7.2,6.08],[1,2,58.4],[2,1.06,149.69]],"ltp":5.9,"tv":17.82,"id":61077258}]}]}
{"op":"mcm","clk":"11924919448","pt":1724194162581,"mc":[{"id":"1.232013794","rc":[{"batb":[[0,7.4,10],[1,7.2,6.08],[2,2,58.4]],"ltp":5.9,"tv":17.82,"id":61077258}]}]}
{"op":"mcm","clk":"11924919647","pt":1724194166198,"mc":[{"id":"1.232013794","rc":[{"batb":[[0,7.2,6.08],[1,2,58.4],[2,1.06,149.69]],"ltp":5.9,"tv":17.82,"id":61077258}]}]}
{"op":"mcm","clk":"11924919765","pt":1724194168621,"mc":[{"id":"1.232013794","rc":[{"batb":[[0,7.4,10],[1,7.2,6.08],[2,2,58.4]],"ltp":5.9,"tv":17.82,"id":61077258}]}]}
{"op":"mcm","clk":"11924920003","pt":1724194172295,"mc":[{"id":"1.232013794","rc":[{"batb":[[0,7.2,6.08],[1,2,58.4],[2,1.06,149.69]],"ltp":5.9,"tv":17.82,"id":61077258}]}]}
{"op":"mcm","clk":"11924920191","pt":1724194175594,"mc":[{"id":"1.232013794","rc":[{"batb":[[0,7.4,10],[1,7.2,6.08],[2,2,58.4]],"ltp":5.9,"tv":17.82,"id":61077258}]}]}
{"op":"mcm","clk":"11924920363","pt":1724194178826,"mc":[{"id":"1.232013794","rc":[{"batb":[[0,7.2,6.08],[1,2,58.4],[2,1.06,149.69]],"ltp":5.9,"tv":17.82,"id":61077258}]}]}
{"op":"mcm","clk":"11924920562","pt":1724194182330,"mc":[{"id":"1.232013794","rc":[{"batb":[[0,7.4,10],[1,7.2,6.08],[2,2,58.4]],"ltp":5.9,"tv":17.82,"id":61077258}]}]}
{"op":"mcm","clk":"11924920761","pt":1724194185628,"mc":[{"id":"1.232013794","rc":[{"batb":[[0,7.2,6.08],[1,2,58.4],[2,1.06,149.69]],"ltp":5.9,"tv":17.82,"id":61077258}]}]}
{"op":"mcm","clk":"11924920906","pt":1724194188318,"mc":[{"id":"1.232013794","rc":[{"batb":[[0,7.4,10],[1,7.2,6.08],[2,2,58.4]],"ltp":5.9,"tv":17.82,"id":61077258}]}]}
{"op":"mcm","clk":"11924921081","pt":1724194191706,"mc":[{"id":"1.232013794","rc":[{"batb":[[0,7.2,6.08],[1,2,58.4],[2,1.06,149.69]],"ltp":5.9,"tv":17.82,"id":61077258}]}]}
{"op":"mcm","clk":"11924921322","pt":1724194195308,"mc":[{"id":"1.232013794","rc":[{"batb":[[0,7.4,10],[1,7.2,6.08],[2,2,58.4]],"ltp":5.9,"tv":17.82,"id":61077258}]}]}
{"op":"mcm","clk":"11924921524","pt":1724194198838,"mc":[{"id":"1.232013794","rc":[{"batb":[[0,7.2,6.08],[1,2,58.4],[2,1.06,149.69]],"ltp":5.9,"tv":17.82,"id":61077258}]}]}
{"op":"mcm","clk":"11924921679","pt":1724194201223,"mc":[{"id":"1.232013794","rc":[{"batb":[[0,7.4,10],[1,7.2,6.08],[2,2,58.4]],"ltp":5.9,"tv":17.82,"id":61077258}]}]}
{"op":"mcm","clk":"11924921913","pt":1724194204519,"mc":[{"id":"1.232013794","rc":[{"batb":[[0,7.2,6.08],[1,2,58.4],[2,1.06,149.69]],"ltp":5.9,"tv":17.82,"id":61077258}]}]}
{"op":"mcm","clk":"11924922091","pt":1724194208132,"mc":[{"id":"1.232013794","rc":[{"batb":[[0,7.4,10],[1,7.2,6.08],[2,2,58.4]],"ltp":5.9,"tv":17.82,"id":61077258}]}]}
{"op":"mcm","clk":"11924922269","pt":1724194211456,"mc":[{"id":"1.232013794","rc":[{"batb":[[0,7.2,6.08],[1,2,58.4],[2,1.06,149.69]],"ltp":5.9,"tv":17.82,"id":61077258}]}]}
{"op":"mcm","clk":"11924922424","pt":1724194214442,"mc":[{"id":"1.232013794","rc":[{"batb":[[0,7.4,10],[1,7.2,6.08],[2,2,58.4]],"ltp":5.9,"tv":17.82,"id":61077258}]}]}
{"op":"mcm","clk":"11924922581","pt":1724194217878,"mc":[{"id":"1.232013794","rc":[{"batb":[[0,7.2,6.08],[1,2,58.4],[2,1.06,149.69]],"ltp":5.9,"tv":17.82,"id":61077258}]}]}
{"op":"mcm","clk":"11924922709","pt":1724194220139,"mc":[{"id":"1.232013794","rc":[{"batb":[[0,7.4,10],[1,7.2,6.08],[2,2,58.4]],"ltp":5.9,"tv":17.82,"id":61077258}]}]}
{"op":"mcm","clk":"11924922910","pt":1724194223679,"mc":[{"id":"1.232013794","rc":[{"batb":[[0,7.2,6.08],[1,2,58.4],[2,1.06,149.69]],"ltp":5.9,"tv":17.82,"id":61077258}]}]}
{"op":"mcm","clk":"11924923058","pt":1724194226052,"mc":[{"id":"1.232013794","rc":[{"batb":[[0,7.4,10],[1,7.2,6.08],[2,2,58.4]],"ltp":5.9,"tv":17.82,"id":61077258}]}]}
{"op":"mcm","clk":"11924923266","pt":1724194229390,"mc":[{"id":"1.232013794","rc":[{"batb":[[0,7.2,6.08],[1,2,58.4],[2,1.06,149.69]],"ltp":5.9,"tv":17.82,"id":61077258}]}]}
{"op":"mcm","clk":"11924923452","pt":1724194231665,"mc":[{"id":"1.232013794","rc":[{"batb":[[0,7.4,10],[1,7.2,6.08],[2,2,58.4]],"ltp":5.9,"tv":17.82,"id":61077258}]}]}
{"op":"mcm","clk":"11924923725","pt":1724194235273,"mc":[{"id":"1.232013794","rc":[{"batb":[[0,7.2,6.08],[1,2,58.4],[2,1.06,149.69]],"ltp":5.9,"tv":17.82,"id":61077258}]}]}
{"op":"mcm","clk":"11924923861","pt":1724194237852,"mc":[{"id":"1.232013794","rc":[{"batb":[[0,7.4,10],[1,7.2,6.08],[2,2,58.4]],"ltp":5.9,"tv":17.82,"id":61077258}]}]}
{"op":"mcm","clk":"11924924019","pt":1724194241159,"mc":[{"id":"1.232013794","rc":[{"batb":[[0,7.2,6.08],[1,2,58.4],[2,1.06,149.69]],"ltp":5.9,"tv":17.82,"id":61077258}]}]}
{"op":"mcm","clk":"11924924181","pt":1724194244862,"mc":[{"id":"1.232013794","rc":[{"batb":[[0,7.4,10],[1,7.2,6.08],[2,2,58.4]],"ltp":5.9,"tv":17.82,"id":61077258}]}]}
{"op":"mcm","clk":"11924924352","pt":1724194248205,"mc":[{"id":"1.232013794","rc":[{"batb":[[0,7.2,6.08],[1,2,58.4],[2,1.06,149.69]],"ltp":5.9,"tv":17.82,"id":61077258}]}]}
{"op":"mcm","clk":"11924924493","pt":1724194250878,"mc":[{"id":"1.232013794","rc":[{"batb":[[0,7.4,10],[1,7.2,6.08],[2,2,58.4]],"ltp":5.9,"tv":17.82,"id":61077258}]}]}
{"op":"mcm","clk":"11924924677","pt":1724194254469,"mc":[{"id":"1.232013794","rc":[{"batb":[[0,7.2,6.08],[1,2,58.4],[2,1.06,149.69]],"ltp":5.9,"tv":17.82,"id":61077258}]}]}
{"op":"mcm","clk":"11924924809","pt":1724194256880,"mc":[{"id":"1.232013794","rc":[{"batb":[[0,7.4,10],[1,7.2,6.08],[2,2,58.4]],"ltp":5.9,"tv":17.82,"id":61077258}]}]}
{"op":"mcm","clk":"11924925000","pt":1724194260284,"mc":[{"id":"1.232013794","rc":[{"batb":[[0,7.2,6.08],[1,2,58.4],[2,1.06,149.69]],"ltp":5.9,"tv":17.82,"id":61077258}]}]}
{"op":"mcm","clk":"11924925144","pt":1724194262603,"mc":[{"id":"1.232013794","rc":[{"batb":[[0,7.4,10],[1,7.2,6.08],[2,2,58.4]],"ltp":5.9,"tv":17.82,"id":61077258}]}]}
{"op":"mcm","clk":"11924925376","pt":1724194266102,"mc":[{"id":"1.232013794","rc":[{"batb":[[0,7.2,6.08],[1,2,58.4],[2,1.06,149.69]],"ltp":5.9,"tv":17.82,"id":61077258}]}]}
{"op":"mcm","clk":"11924925497","pt":1724194268409,"mc":[{"id":"1.232013794","rc":[{"batb":[[0,7.4,10],[1,7.2,6.08],[2,2,58.4]],"ltp":5.9,"tv":17.82,"id":61077258}]}]}
{"op":"mcm","clk":"11924925710","pt":1724194271607,"mc":[{"id":"1.232013794","rc":[{"batb":[[0,7.2,6.08],[1,2,58.4],[2,1.06,149.69]],"ltp":5.9,"tv":17.82,"id":61077258}]}]}
{"op":"mcm","clk":"11924925860","pt":1724194274021,"mc":[{"id":"1.232013794","rc":[{"batb":[[0,7.4,10],[1,7.2,6.08],[2,2,58.4]],"ltp":5.9,"tv":17.82,"id":61077258}]}]}
{"op":"mcm","clk":"11924926066","pt":1724194277414,"mc":[{"id":"1.232013794","rc":[{"batb":[[0,7.2,6.08],[1,2,58.4],[2,1.06,149.69]],"ltp":5.9,"tv":17.82,"id":61077258}]}]}
{"op":"mcm","clk":"11924926209","pt":1724194280126,"mc":[{"id":"1.232013794","rc":[{"batb":[[0,7.4,10],[1,7.2,6.08],[2,2,58.4]],"ltp":5.9,"tv":17.82,"id":61077258}]}]}
{"op":"mcm","clk":"11924926369","pt":1724194283321,"mc":[{"id":"1.232013794","rc":[{"batb":[[0,7.2,6.08],[1,2,58.4],[2,1.06,149.69]],"ltp":5.9,"tv":17.82,"id":61077258}]}]}
{"op":"mcm","clk":"11924926491","pt":1724194285730,"mc":[{"id":"1.232013794","rc":[{"batb":[[0,7.4,10],[1,7.2,6.08],[2,2,58.4]],"ltp":5.9,"tv":17.82,"id":61077258}]}]}
{"op":"mcm","clk":"11924926690","pt":1724194289163,"mc":[{"id":"1.232013794","rc":[{"batb":[[0,7.2,6.08],[1,2,58.4],[2,1.06,149.69]],"ltp":5.9,"tv":17.82,"id":61077258}]}]}
{"op":"mcm","clk":"11924926826","pt":1724194291842,"mc":[{"id":"1.232013794","rc":[{"batb":[[0,7.4,10],[1,7.2,6.08],[2,2,58.4]],"ltp":5.9,"tv":17.82,"id":61077258}]}]}
{"op":"mcm","clk":"11924927036","pt":1724194295240,"mc":[{"id":"1.232013794","rc":[{"batb":[[0,7.2,6.08],[1,2,58.4],[2,1.06,149.69]],"ltp":5.9,"tv":17.82,"id":61077258}]}]}
{"op":"mcm","clk":"11924927146","pt":1724194297549,"mc":[{"id":"1.232013794","rc":[{"batb":[[0,7.4,10],[1,7.2,6.08],[2,2,58.4]],"ltp":5.9,"tv":17.82,"id":61077258}]}]}
{"op":"mcm","clk":"11924927306","pt":1724194300750,"mc":[{"id":"1.232013794","rc":[{"batb":[[0,7.2,6.08],[1,2,58.4],[2,1.06,149.69]],"ltp":5.9,"tv":17.82,"id":61077258}]}]}
{"op":"mcm","clk":"11924927384","pt":1724194302845,"mc":[{"id":"1.232013794","rc":[{"batb":[[0,7.4,10],[1,7.2,6.08],[2,2,58.4]],"ltp":5.9,"tv":17.82,"id":61077258}]}]}
{"op":"mcm","clk":"11924927550","pt":1724194306337,"mc":[{"id":"1.232013794","rc":[{"batb":[[0,7.2,6.08],[1,2,58.4],[2,1.06,149.69]],"ltp":5.9,"tv":17.82,"id":61077258}]}]}
{"op":"mcm","clk":"11924927661","pt":1724194308483,"mc":[{"id":"1.232013794","rc":[{"batb":[[0,7.4,10],[1,7.2,6.08],[2,2,58.4]],"ltp":5.9,"tv":17.82,"id":61077258}]}]}
{"op":"mcm","clk":"11924927797","pt":1724194311668,"mc":[{"id":"1.232013794","rc":[{"batb":[[0,7.2,6.08],[1,2,58.4],[2,1.06,149.69]],"ltp":5.9,"tv":17.82,"id":61077258}]}]}
{"op":"mcm","clk":"11924927917","pt":1724194313879,"mc":[{"id":"1.232013794","rc":[{"batb":[[0,7.4,10],[1,7.2,6.08],[2,2,58.4]],"ltp":5.9,"tv":17.82,"id":61077258}]}]}
{"op":"mcm","clk":"11924928083","pt":1724194317475,"mc":[{"id":"1.232013794","rc":[{"batb":[[0,7.2,6.08],[1,2,58.4],[2,1.06,149.69]],"ltp":5.9,"tv":17.82,"id":61077258}]}]}
{"op":"mcm","clk":"11924928223","pt":1724194319780,"mc":[{"id":"1.232013794","rc":[{"batb":[[0,7.4,10],[1,7.2,6.08],[2,2,58.4]],"ltp":5.9,"tv":17.82,"id":61077258}]}]}
{"op":"mcm","clk":"11924928411","pt":1724194323078,"mc":[{"id":"1.232013794","rc":[{"batb":[[0,7.2,6.08],[1,2,58.4],[2,1.06,149.69]],"ltp":5.9,"tv":17.82,"id":61077258}]}]}
{"op":"mcm","clk":"11924928561","pt":1724194325483,"mc":[{"id":"1.232013794","rc":[{"batb":[[0,7.4,10],[1,7.2,6.08],[2,2,58.4]],"ltp":5.9,"tv":17.82,"id":61077258}]}]}
{"op":"mcm","clk":"11924928761","pt":1724194328774,"mc":[{"id":"1.232013794","rc":[{"batb":[[0,7.2,6.08],[1,2,58.4],[2,1.06,149.69]],"ltp":5.9,"tv":17.82,"id":61077258}]}]}
{"op":"mcm","clk":"11924928874","pt":1724194331111,"mc":[{"id":"1.232013794","rc":[{"batb":[[0,7.4,10],[1,7.2,6.08],[2,2,58.4]],"ltp":5.9,"tv":17.82,"id":61077258}]}]}
{"op":"mcm","clk":"11924929047","pt":1724194334397,"mc":[{"id":"1.232013794","rc":[{"batb":[[0,7.2,6.08],[1,2,58.4],[2,1.06,149.69]],"ltp":5.9,"tv":17.82,"id":61077258}]}]}
{"op":"mcm","clk":"11924929161","pt":1724194337273,"mc":[{"id":"1.232013794","rc":[{"batb":[[0,7.4,10],[1,7.2,6.08],[2,2,58.4]],"ltp":5.9,"tv":17.82,"id":61077258}]}]}
{"op":"mcm","clk":"11924929297","pt":1724194340697,"mc":[{"id":"1.232013794","rc":[{"batb":[[0,7.2,6.08],[1,2,58.4],[2,1.06,149.69]],"ltp":5.9,"tv":17.82,"id":61077258}]}]}
{"op":"mcm","clk":"11924929420","pt":1724194343413,"mc":[{"id":"1.232013794","rc":[{"batb":[[0,7.4,10],[1,7.2,6.08],[2,2,58.4]],"ltp":5.9,"tv":17.82,"id":61077258}]}]}
{"op":"mcm","clk":"11924929608","pt":1724194346914,"mc":[{"id":"1.232013794","rc":[{"batb":[[0,7.2,6.08],[1,2,58.4],[2,1.06,149.69]],"ltp":5.9,"tv":17.82,"id":61077258}]}]}
{"op":"mcm","clk":"11924929724","pt":1724194349318,"mc":[{"id":"1.232013794","rc":[{"batb":[[0,7.4,10],[1,7.2,6.08],[2,2,58.4]],"ltp":5.9,"tv":17.82,"id":61077258}]}]}
{"op":"mcm","clk":"11924929902","pt":1724194352706,"mc":[{"id":"1.232013794","rc":[{"batb":[[0,7.2,6.08],[1,2,58.4],[2,1.06,149.69]],"ltp":5.9,"tv":17.82,"id":61077258}]}]}
{"op":"mcm","clk":"11924930063","pt":1724194355225,"mc":[{"id":"1.232013794","rc":[{"batb":[[0,7.4,10],[1,7.2,6.08],[2,2,58.4]],"ltp":5.9,"tv":17.82,"id":61077258}]}]}
{"op":"mcm","clk":"11924930256","pt":1724194358516,"mc":[{"id":"1.232013794","rc":[{"batb":[[0,7.2,6.08],[1,2,58.4],[2,1.06,149.69]],"ltp":5.9,"tv":17.82,"id":61077258}]}]}
{"op":"mcm","clk":"11924930402","pt":1724194361230,"mc":[{"id":"1.232013794","rc":[{"batb":[[0,7.4,10],[1,7.2,6.08],[2,2,58.4]],"ltp":5.9,"tv":17.82,"id":61077258}]}]}
{"op":"mcm","clk":"11924930589","pt":1724194364727,"mc":[{"id":"1.232013794","rc":[{"batb":[[0,7.2,6.08],[1,2,58.4],[2,1.06,149.69]],"ltp":5.9,"tv":17.82,"id":61077258}]}]}
{"op":"mcm","clk":"11924930765","pt":1724194367913,"mc":[{"id":"1.232013794","rc":[{"batb":[[0,7.4,10],[1,7.2,6.08],[2,2,58.4]],"ltp":5.9,"tv":17.82,"id":61077258}]}]}
{"op":"mcm","clk":"11924930914","pt":1724194371221,"mc":[{"id":"1.232013794","rc":[{"batb":[[0,7.2,6.08],[1,2,58.4],[2,1.06,149.69]],"ltp":5.9,"tv":17.82,"id":61077258}]}]}
{"op":"mcm","clk":"11924931050","pt":1724194374038,"mc":[{"id":"1.232013794","rc":[{"batb":[[0,7.4,10],[1,7.2,6.08],[2,2,58.4]],"ltp":5.9,"tv":17.82,"id":61077258}]}]}
{"op":"mcm","clk":"11924931206","pt":1724194377634,"mc":[{"id":"1.232013794","rc":[{"batb":[[0,7.2,6.08],[1,2,58.4],[2,1.06,149.69]],"ltp":5.9,"tv":17.82,"id":61077258}]}]}
{"op":"mcm","clk":"11924931325","pt":1724194380040,"mc":[{"id":"1.232013794","rc":[{"batb":[[0,7.4,10],[1,7.2,6.08],[2,2,58.4]],"ltp":5.9,"tv":17.82,"id":61077258}]}]}
{"op":"mcm","clk":"11924931516","pt":1724194383434,"mc":[{"id":"1.232013794","rc":[{"batb":[[0,7.2,6.08],[1,2,58.4],[2,1.06,149.69]],"ltp":5.9,"tv":17.82,"id":61077258}]}]}
{"op":"mcm","clk":"11924931647","pt":1724194385847,"mc":[{"id":"1.232013794","rc":[{"batb":[[0,7.4,10],[1,7.2,6.08],[2,2,58.4]],"ltp":5.9,"tv":17.82,"id":61077258}]}]}
{"op":"mcm","clk":"11924931842","pt":1724194389335,"mc":[{"id":"1.232013794","rc":[{"batb":[[0,7.2,6.08],[1,2,58.4],[2,1.06,149.69]],"ltp":5.9,"tv":17.82,"id":61077258}]}]}
{"op":"mcm","clk":"11924931953","pt":1724194391650,"mc":[{"id":"1.232013794","rc":[{"batb":[[0,7.4,10],[1,7.2,6.08],[2,2,58.4]],"ltp":5.9,"tv":17.82,"id":61077258}]}]}
{"op":"mcm","clk":"11924932123","pt":1724194394940,"mc":[{"id":"1.232013794","rc":[{"batb":[[0,7.2,6.08],[1,2,58.4],[2,1.06,149.69]],"ltp":5.9,"tv":17.82,"id":61077258}]}]}
{"op":"mcm","clk":"11924932237","pt":1724194397350,"mc":[{"id":"1.232013794","rc":[{"batb":[[0,7.4,10],[1,7.2,6.08],[2,2,58.4]],"ltp":5.9,"tv":17.82,"id":61077258}]}]}
{"op":"mcm","clk":"11924932403","pt":1724194400646,"mc":[{"id":"1.232013794","rc":[{"batb":[[0,7.2,6.08],[1,2,58.4],[2,1.06,149.69]],"ltp":5.9,"tv":17.82,"id":61077258}]}]}
{"op":"mcm","clk":"11924932556","pt":1724194402965,"mc":[{"id":"1.232013794","rc":[{"batb":[[0,7.4,10],[1,7.2,6.08],[2,2,58.4]],"ltp":5.9,"tv":17.82,"id":61077258}]}]}
{"op":"mcm","clk":"11924932747","pt":1724194406250,"mc":[{"id":"1.232013794","rc":[{"batb":[[0,7.2,6.08],[1,2,58.4],[2,1.06,149.69]],"ltp":5.9,"tv":17.82,"id":61077258}]}]}
{"op":"mcm","clk":"11924932916","pt":1724194409381,"mc":[{"id":"1.232013794","rc":[{"batb":[[0,7.4,10],[1,7.2,6.08],[2,2,58.4]],"ltp":5.9,"tv":17.82,"id":61077258}]}]}
{"op":"mcm","clk":"11924933128","pt":1724194412777,"mc":[{"id":"1.232013794","rc":[{"batb":[[0,7.2,6.08],[1,2,58.4],[2,1.06,149.69]],"ltp":5.9,"tv":17.82,"id":61077258}]}]}
{"op":"mcm","clk":"11924933284","pt":1724194415257,"mc":[{"id":"1.232013794","rc":[{"batb":[[0,7.4,10],[1,7.2,6.08],[2,2,58.4]],"ltp":5.9,"tv":17.82,"id":61077258}]}]}
{"op":"mcm","clk":"11924933451","pt":1724194418752,"mc":[{"id":"1.232013794","rc":[{"batb":[[0,7.2,6.08],[1,2,58.4],[2,1.06,149.69]],"ltp":5.9,"tv":17.82,"id":61077258}]}]}
{"op":"mcm","clk":"11924933600","pt":1724194421372,"mc":[{"id":"1.232013794","rc":[{"batb":[[0,7.4,10],[1,7.2,6.08],[2,2,58.4]],"ltp":5.9,"tv":17.82,"id":61077258}]}]}
{"op":"mcm","clk":"11924933788","pt":1724194424978,"mc":[{"id":"1.232013794","rc":[{"batb":[[0,7.2,6.08],[1,2,58.4],[2,1.06,149.69]],"ltp":5.9,"tv":17.82,"id":61077258}]}]}
{"op":"mcm","clk":"11924933915","pt":1724194427392,"mc":[{"id":"1.232013794","rc":[{"batb":[[0,7.4,10],[1,7.2,6.08],[2,2,58.4]],"ltp":5.9,"tv":17.82,"id":61077258}]}]}
{"op":"mcm","clk":"11924934052","pt":1724194430687,"mc":[{"id":"1.232013794","rc":[{"batb":[[0,7.2,6.08],[1,2,58.4],[2,1.06,149.69]],"ltp":5.9,"tv":17.82,"id":61077258}]}]}
{"op":"mcm","clk":"11924934183","pt":1724194433098,"mc":[{"id":"1.232013794","rc":[{"batb":[[0,7.4,10],[1,7.2,6.08],[2,2,58.4]],"ltp":5.9,"tv":17.82,"id":61077258}]}]}
{"op":"mcm","clk":"11924934336","pt":1724194436484,"mc":[{"id":"1.232013794","rc":[{"batb":[[0,7.2,6.08],[1,2,58.4],[2,1.06,149.69]],"ltp":5.9,"tv":17.82,"id":61077258}]}]}
{"op":"mcm","clk":"11924934411","pt":1724194438798,"mc":[{"id":"1.232013794","rc":[{"batb":[[0,7.4,10],[1,7.2,6.08],[2,2,58.4]],"ltp":5.9,"tv":17.82,"id":61077258}]}]}
{"op":"mcm","clk":"11924934583","pt":1724194441991,"mc":[{"id":"1.232013794","rc":[{"batb":[[0,7.2,6.08],[1,2,58.4],[2,1.06,149.69]],"ltp":5.9,"tv":17.82,"id":61077258}]}]}
{"op":"mcm","clk":"11924934704","pt":1724194444400,"mc":[{"id":"1.232013794","rc":[{"batb":[[0,7.4,10],[1,7.2,6.08],[2,2,58.4]],"ltp":5.9,"tv":17.82,"id":61077258}]}]}
{"op":"mcm","clk":"11924934886","pt":1724194447737,"mc":[{"id":"1.232013794","rc":[{"batb":[[0,7.2,6.08],[1,2,58.4],[2,1.06,149.69]],"ltp":5.9,"tv":17.82,"id":61077258}]}]}
{"op":"mcm","clk":"11924935046","pt":1724194451022,"mc":[{"id":"1.232013794","rc":[{"batb":[[0,7.4,10],[1,7.2,6.08],[2,2,58.4]],"ltp":5.9,"tv":17.82,"id":61077258}]}]}
{"op":"mcm","clk":"11924935214","pt":1724194454393,"mc":[{"id":"1.232013794","rc":[{"batb":[[0,7.2,6.08],[1,2,58.4],[2,1.06,149.69]],"ltp":5.9,"tv":17.82,"id":61077258}]}]}
{"op":"mcm","clk":"11924935405","pt":1724194458133,"mc":[{"id":"1.232013794","rc":[{"batb":[[0,7.4,10],[1,7.2,6.08],[2,2,58.4]],"ltp":5.9,"tv":17.82,"id":61077258}]}]}
{"op":"mcm","clk":"11924935596","pt":1724194461427,"mc":[{"id":"1.232013794","rc":[{"batb":[[0,7.2,6.08],[1,2,58.4],[2,1.06,149.69]],"ltp":5.9,"tv":17.82,"id":61077258}]}]}
{"op":"mcm","clk":"11924935774","pt":1724194464046,"mc":[{"id":"1.232013794","rc":[{"batb":[[0,7.4,10],[1,7.2,6.08],[2,2,58.4]],"ltp":5.9,"tv":17.82,"id":61077258}]}]}
{"op":"mcm","clk":"11924935960","pt":1724194467633,"mc":[{"id":"1.232013794","rc":[{"batb":[[0,7.2,6.08],[1,2,58.4],[2,1.06,149.69]],"ltp":5.9,"tv":17.82,"id":61077258}]}]}
{"op":"mcm","clk":"11924936102","pt":1724194470140,"mc":[{"id":"1.232013794","rc":[{"batb":[[0,7.4,10],[1,7.2,6.08],[2,2,58.4]],"ltp":5.9,"tv":17.82,"id":61077258}]}]}
{"op":"mcm","clk":"11924936302","pt":1724194473637,"mc":[{"id":"1.232013794","rc":[{"batb":[[0,7.2,6.08],[1,2,58.4],[2,1.06,149.69]],"ltp":5.9,"tv":17.82,"id":61077258}]}]}
{"op":"mcm","clk":"11924936439","pt":1724194476049,"mc":[{"id":"1.232013794","rc":[{"batb":[[0,7.4,10],[1,7.2,6.08],[2,2,58.4]],"ltp":5.9,"tv":17.82,"id":61077258}]}]}
{"op":"mcm","clk":"11924936595","pt":1724194479540,"mc":[{"id":"1.232013794","rc":[{"batb":[[0,7.2,6.08],[1,2,58.4],[2,1.06,149.69]],"ltp":5.9,"tv":17.82,"id":61077258}]}]}
{"op":"mcm","clk":"11924936745","pt":1724194481956,"mc":[{"id":"1.232013794","rc":[{"batb":[[0,7.4,10],[1,7.2,6.08],[2,2,58.4]],"ltp":5.9,"tv":17.82,"id":61077258}]}]}
{"op":"mcm","clk":"11924936926","pt":1724194485453,"mc":[{"id":"1.232013794","rc":[{"batb":[[0,7.2,6.08],[1,2,58.4],[2,1.06,149.69]],"ltp":5.9,"tv":17.82,"id":61077258}]}]}
{"op":"mcm","clk":"11924937074","pt":1724194488070,"mc":[{"id":"1.232013794","rc":[{"batb":[[0,7.4,10],[1,7.2,6.08],[2,2,58.4]],"ltp":5.9,"tv":17.82,"id":61077258}]}]}
{"op":"mcm","clk":"11924937219","pt":1724194491460,"mc":[{"id":"1.232013794","rc":[{"batb":[[0,7.2,6.08],[1,2,58.4],[2,1.06,149.69]],"ltp":5.9,"tv":17.82,"id":61077258}]}]}
{"op":"mcm","clk":"11924937336","pt":1724194493871,"mc":[{"id":"1.232013794","rc":[{"batb":[[0,7.4,10],[1,7.2,6.08],[2,2,58.4]],"ltp":5.9,"tv":17.82,"id":61077258}]}]}
{"op":"mcm","clk":"11924937473","pt":1724194497357,"mc":[{"id":"1.232013794","rc":[{"batb":[[0,7.2,6.08],[1,2,58.4],[2,1.06,149.69]],"ltp":5.9,"tv":17.82,"id":61077258}]}]}
{"op":"mcm","clk":"11924937582","pt":1724194499761,"mc":[{"id":"1.232013794","rc":[{"batb":[[0,7.4,10],[1,7.2,6.08],[2,2,58.4]],"ltp":5.9,"tv":17.82,"id":61077258}]}]}
{"op":"mcm","clk":"11924937802","pt":1724194503060,"mc":[{"id":"1.232013794","rc":[{"batb":[[0,7.2,6.08],[1,2,58.4],[2,1.06,149.69]],"ltp":5.9,"tv":17.82,"id":61077258}]}]}
{"op":"mcm","clk":"11924937921","pt":1724194505375,"mc":[{"id":"1.232013794","rc":[{"batb":[[0,7.4,10],[1,7.2,6.08],[2,2,58.4]],"ltp":5.9,"tv":17.82,"id":61077258}]}]}
{"op":"mcm","clk":"11924938065","pt":1724194508666,"mc":[{"id":"1.232013794","rc":[{"batb":[[0,7.2,6.08],[1,2,58.4],[2,1.06,149.69]],"ltp":5.9,"tv":17.82,"id":61077258}]}]}
{"op":"mcm","clk":"11924938206","pt":1724194511082,"mc":[{"id":"1.232013794","rc":[{"batb":[[0,7.4,10],[1,7.2,6.08],[2,2,58.4]],"ltp":5.9,"tv":17.82,"id":61077258}]}]}
{"op":"mcm","clk":"11924938361","pt":1724194514377,"mc":[{"id":"1.232013794","rc":[{"batb":[[0,7.2,6.08],[1,2,58.4],[2,1.06,149.69]],"ltp":5.9,"tv":17.82,"id":61077258}]}]}
{"op":"mcm","clk":"11924938494","pt":1724194517466,"mc":[{"id":"1.232013794","rc":[{"batb":[[0,7.4,10],[1,7.2,6.08],[2,2,58.4]],"ltp":5.9,"tv":17.82,"id":61077258}]}]}
{"op":"mcm","clk":"11924938681","pt":1724194520800,"mc":[{"id":"1.232013794","rc":[{"batb":[[0,7.2,6.08],[1,2,58.4],[2,1.06,149.69]],"ltp":5.9,"tv":17.82,"id":61077258}]}]}
{"op":"mcm","clk":"11924938812","pt":1724194523110,"mc":[{"id":"1.232013794","rc":[{"batb":[[0,7.4,10],[1,7.2,6.08],[2,2,58.4]],"ltp":5.9,"tv":17.82,"id":61077258}]}]}
{"op":"mcm","clk":"11924938986","pt":1724194526504,"mc":[{"id":"1.232013794","rc":[{"batb":[[0,7.2,6.08],[1,2,58.4],[2,1.06,149.69]],"ltp":5.9,"tv":17.82,"id":61077258}]}]}
{"op":"mcm","clk":"11924939182","pt":1724194528920,"mc":[{"id":"1.232013794","rc":[{"batb":[[0,7.4,10],[1,7.2,6.08],[2,2,58.4]],"ltp":5.9,"tv":17.82,"id":61077258}]}]}
{"op":"mcm","clk":"11924939374","pt":1724194532208,"mc":[{"id":"1.232013794","rc":[{"batb":[[0,7.2,6.08],[1,2,58.4],[2,1.06,149.69]],"ltp":5.9,"tv":17.82,"id":61077258}]}]}
{"op":"mcm","clk":"11924939496","pt":1724194534422,"mc":[{"id":"1.232013794","rc":[{"batb":[[0,7.4,10],[1,7.2,6.08],[2,2,58.4]],"ltp":5.9,"tv":17.82,"id":61077258}]}]}
{"op":"mcm","clk":"11924939675","pt":1724194537814,"mc":[{"id":"1.232013794","rc":[{"batb":[[0,7.2,6.08],[1,2,58.4],[2,1.06,149.69]],"ltp":5.9,"tv":17.82,"id":61077258}]}]}
{"op":"mcm","clk":"11924939859","pt":1724194541200,"mc":[{"id":"1.232013794","rc":[{"batb":[[0,7.4,10],[1,7.2,6.08],[2,2,58.4]],"ltp":5.9,"tv":17.82,"id":61077258}]}]}
{"op":"mcm","clk":"11924940027","pt":1724194544591,"mc":[{"id":"1.232013794","rc":[{"batb":[[0,7.2,6.08],[1,2,58.4],[2,1.06,149.69]],"ltp":5.9,"tv":17.82,"id":61077258}]}]}
{"op":"mcm","clk":"11924940455","pt":1724194552820,"mc":[{"id":"1.232013794","rc":[{"batb":[[0,7.4,10],[1,7.2,6.08],[2,2,58.4]],"ltp":5.9,"tv":17.82,"id":61077258}]}]}
{"op":"mcm","clk":"11924940604","pt":1724194556147,"mc":[{"id":"1.232013794","rc":[{"batb":[[0,7.2,6.08],[1,2,58.4],[2,1.06,149.69]],"ltp":5.9,"tv":17.82,"id":61077258}]}]}
{"op":"mcm","clk":"11924940714","pt":1724194558351,"mc":[{"id":"1.232013794","rc":[{"batb":[[0,7.4,10],[1,7.2,6.08],[2,2,58.4]],"ltp":5.9,"tv":17.82,"id":61077258}]}]}
{"op":"mcm","clk":"11924940864","pt":1724194561748,"mc":[{"id":"1.232013794","rc":[{"batb":[[0,7.2,6.08],[1,2,58.4],[2,1.06,149.69]],"ltp":5.9,"tv":17.82,"id":61077258}]}]}
{"op":"mcm","clk":"11924940983","pt":1724194563950,"mc":[{"id":"1.232013794","rc":[{"batb":[[0,7.4,10],[1,7.2,6.08],[2,2,58.4]],"ltp":5.9,"tv":17.82,"id":61077258}]}]}
{"op":"mcm","clk":"11924941154","pt":1724194567142,"mc":[{"id":"1.232013794","rc":[{"batb":[[0,7.2,6.08],[1,2,58.4],[2,1.06,149.69]],"ltp":5.9,"tv":17.82,"id":61077258}]}]}
{"op":"mcm","clk":"11924941258","pt":1724194569345,"mc":[{"id":"1.232013794","rc":[{"batb":[[0,7.4,10],[1,7.2,6.08],[2,2,58.4]],"ltp":5.9,"tv":17.82,"id":61077258}]}]}
{"op":"mcm","clk":"11924941450","pt":1724194572469,"mc":[{"id":"1.232013794","rc":[{"batb":[[0,7.2,6.08],[1,2,58.4],[2,1.06,149.69]],"ltp":5.9,"tv":17.82,"id":61077258}]}]}
{"op":"mcm","clk":"11924941628","pt":1724194575602,"mc":[{"id":"1.232013794","rc":[{"batb":[[0,7.4,10],[1,7.2,6.08],[2,2,58.4]],"ltp":5.9,"tv":17.82,"id":61077258}]}]}
{"op":"mcm","clk":"11924941816","pt":1724194579096,"mc":[{"id":"1.232013794","rc":[{"batb":[[0,7.2,6.08],[1,2,58.4],[2,1.06,149.69]],"ltp":5.9,"tv":17.82,"id":61077258}]}]}
{"op":"mcm","clk":"11924941974","pt":1724194582382,"mc":[{"id":"1.232013794","rc":[{"batb":[[0,7.4,10],[1,7.2,6.08],[2,2,58.4]],"ltp":5.9,"tv":17.82,"id":61077258}]}]}
{"op":"mcm","clk":"11924942143","pt":1724194585882,"mc":[{"id":"1.232013794","rc":[{"batb":[[0,7.2,6.08],[1,2,58.4],[2,1.06,149.69]],"ltp":5.9,"tv":17.82,"id":61077258}]}]}
{"op":"mcm","clk":"11924942252","pt":1724194588091,"mc":[{"id":"1.232013794","rc":[{"batb":[[0,7.4,10],[1,7.2,6.08],[2,2,58.4]],"ltp":5.9,"tv":17.82,"id":61077258}]}]}
{"op":"mcm","clk":"11924942422","pt":1724194591388,"mc":[{"id":"1.232013794","rc":[{"batb":[[0,7.2,6.08],[1,2,58.4],[2,1.06,149.69]],"ltp":5.9,"tv":17.82,"id":61077258}]}]}
{"op":"mcm","clk":"11924942605","pt":1724194594379,"mc":[{"id":"1.232013794","rc":[{"batb":[[0,7.4,10],[1,7.2,6.08],[2,2,58.4]],"ltp":5.9,"tv":17.82,"id":61077258}]}]}
{"op":"mcm","clk":"11924942785","pt":1724194597719,"mc":[{"id":"1.232013794","rc":[{"batb":[[0,7.2,6.08],[1,2,58.4],[2,1.06,149.69]],"ltp":5.9,"tv":17.82,"id":61077258}]}]}
{"op":"mcm","clk":"11924942921","pt":1724194600395,"mc":[{"id":"1.232013794","rc":[{"batb":[[0,7.4,10],[1,7.2,6.08],[2,2,58.4]],"ltp":5.9,"tv":17.82,"id":61077258}]}]}
{"op":"mcm","clk":"11924943080","pt":1724194603785,"mc":[{"id":"1.232013794","rc":[{"batb":[[0,7.2,6.08],[1,2,58.4],[2,1.06,149.69]],"ltp":5.9,"tv":17.82,"id":61077258}]}]}
{"op":"mcm","clk":"11924943172","pt":1724194605992,"mc":[{"id":"1.232013794","rc":[{"batb":[[0,7.4,10],[1,7.2,6.08],[2,2,58.4]],"ltp":5.9,"tv":17.82,"id":61077258}]}]}
{"op":"mcm","clk":"11924943325","pt":1724194609388,"mc":[{"id":"1.232013794","rc":[{"batb":[[0,7.2,6.08],[1,2,58.4],[2,1.06,149.69]],"ltp":5.9,"tv":17.82,"id":61077258}]}]}
{"op":"mcm","clk":"11924943426","pt":1724194611897,"mc":[{"id":"1.232013794","rc":[{"batb":[[0,7.4,10],[1,7.2,6.08],[2,2,58.4]],"ltp":5.9,"tv":17.82,"id":61077258}]}]}
{"op":"mcm","clk":"11924943571","pt":1724194615334,"mc":[{"id":"1.232013794","rc":[{"batb":[[0,7.2,6.08],[1,2,58.4],[2,1.06,149.69]],"ltp":5.9,"tv":17.82,"id":61077258}]}]}
{"op":"mcm","clk":"11924943662","pt":1724194617699,"mc":[{"id":"1.232013794","rc":[{"batb":[[0,7.4,10],[1,7.2,6.08],[2,2,58.4]],"ltp":5.9,"tv":17.82,"id":61077258}]}]}
{"op":"mcm","clk":"11924943785","pt":1724194621236,"mc":[{"id":"1.232013794","rc":[{"batb":[[0,7.2,6.08],[1,2,58.4],[2,1.06,149.69]],"ltp":5.9,"tv":17.82,"id":61077258}]}]}
{"op":"mcm","clk":"11924943896","pt":1724194624008,"mc":[{"id":"1.232013794","rc":[{"batb":[[0,7.4,10],[1,7.2,6.08],[2,2,58.4]],"ltp":5.9,"tv":17.82,"id":61077258}]}]}
{"op":"mcm","clk":"11924944070","pt":1724194627502,"mc":[{"id":"1.232013794","rc":[{"batb":[[0,7.2,6.08],[1,2,58.4],[2,1.06,149.69]],"ltp":5.9,"tv":17.82,"id":61077258}]}]}
{"op":"mcm","clk":"11924944168","pt":1724194629712,"mc":[{"id":"1.232013794","rc":[{"batb":[[0,7.4,10],[1,7.2,6.08],[2,2,58.4]],"ltp":5.9,"tv":17.82,"id":61077258}]}]}
{"op":"mcm","clk":"11924944330","pt":1724194633247,"mc":[{"id":"1.232013794","rc":[{"batb":[[0,7.2,6.08],[1,2,58.4],[2,1.06,149.69]],"ltp":5.9,"tv":17.82,"id":61077258}]}]}
{"op":"mcm","clk":"11924944447","pt":1724194635715,"mc":[{"id":"1.232013794","rc":[{"batb":[[0,7.4,10],[1,7.2,6.08],[2,2,58.4]],"ltp":5.9,"tv":17.82,"id":61077258}]}]}
{"op":"mcm","clk":"11924944587","pt":1724194639158,"mc":[{"id":"1.232013794","rc":[{"batb":[[0,7.2,6.08],[1,2,58.4],[2,1.06,149.69]],"ltp":5.9,"tv":17.82,"id":61077258}]}]}
{"op":"mcm","clk":"11924944690","pt":1724194641728,"mc":[{"id":"1.232013794","rc":[{"batb":[[0,7.4,10],[1,7.2,6.08],[2,2,58.4]],"ltp":5.9,"tv":17.82,"id":61077258}]}]}
{"op":"mcm","clk":"11924944825","pt":1724194644968,"mc":[{"id":"1.232013794","rc":[{"batb":[[0,7.2,6.08],[1,2,58.4],[2,1.06,149.69]],"ltp":5.9,"tv":17.82,"id":61077258}]}]}
{"op":"mcm","clk":"11924944973","pt":1724194647330,"mc":[{"id":"1.232013794","rc":[{"batb":[[0,7.4,10],[1,7.2,6.08],[2,2,58.4]],"ltp":5.9,"tv":17.82,"id":61077258}]}]}
{"op":"mcm","clk":"11924945127","pt":1724194650952,"mc":[{"id":"1.232013794","rc":[{"batb":[[0,7.2,6.08],[1,2,58.4],[2,1.06,149.69]],"ltp":5.9,"tv":17.82,"id":61077258}]}]}
{"op":"mcm","clk":"11924945223","pt":1724194653278,"mc":[{"id":"1.232013794","rc":[{"batb":[[0,7.4,10],[1,7.2,6.08],[2,2,58.4]],"ltp":5.9,"tv":17.82,"id":61077258}]}]}
{"op":"mcm","clk":"11924945352","pt":1724194656649,"mc":[{"id":"1.232013794","rc":[{"batb":[[0,7.2,6.08],[1,2,58.4],[2,1.06,149.69]],"ltp":5.9,"tv":17.82,"id":61077258}]}]}
{"op":"mcm","clk":"11924945484","pt":1724194659476,"mc":[{"id":"1.232013794","rc":[{"batb":[[0,7.4,10],[1,7.2,6.08],[2,2,58.4]],"ltp":5.9,"tv":17.82,"id":61077258}]}]}
{"op":"mcm","clk":"11924945635","pt":1724194662863,"mc":[{"id":"1.232013794","rc":[{"batb":[[0,7.2,6.08],[1,2,58.4],[2,1.06,149.69]],"ltp":5.9,"tv":17.82,"id":61077258}]}]}
{"op":"mcm","clk":"11924945792","pt":1724194665989,"mc":[{"id":"1.232013794","rc":[{"batb":[[0,7.4,10],[1,7.2,6.08],[2,2,58.4]],"ltp":5.9,"tv":17.82,"id":61077258}]}]}
{"op":"mcm","clk":"11924945934","pt":1724194669377,"mc":[{"id":"1.232013794","rc":[{"batb":[[0,7.2,6.08],[1,2,58.4],[2,1.06,149.69]],"ltp":5.9,"tv":17.82,"id":61077258}]}]}
{"op":"mcm","clk":"11924946065","pt":1724194672962,"mc":[{"id":"1.232013794","rc":[{"batb":[[0,7.4,10],[1,7.2,6.08],[2,2,58.4]],"ltp":5.9,"tv":17.82,"id":61077258}]}]}
{"op":"mcm","clk":"11924946192","pt":1724194676294,"mc":[{"id":"1.232013794","rc":[{"batb":[[0,7.2,6.08],[1,2,58.4],[2,1.06,149.69]],"ltp":5.9,"tv":17.82,"id":61077258}]}]}
{"op":"mcm","clk":"11924946321","pt":1724194678811,"mc":[{"id":"1.232013794","rc":[{"batb":[[0,7.4,10],[1,7.2,6.08],[2,2,58.4]],"ltp":5.9,"tv":17.82,"id":61077258}]}]}
{"op":"mcm","clk":"11924946449","pt":1724194681991,"mc":[{"id":"1.232013794","rc":[{"batb":[[0,7.2,6.08],[1,2,58.4],[2,1.06,149.69]],"ltp":5.9,"tv":17.82,"id":61077258}]}]}
{"op":"mcm","clk":"11924946546","pt":1724194684711,"mc":[{"id":"1.232013794","rc":[{"batb":[[0,7.4,10],[1,7.2,6.08],[2,2,58.4]],"ltp":5.9,"tv":17.82,"id":61077258}]}]}
{"op":"mcm","clk":"11924946747","pt":1724194688010,"mc":[{"id":"1.232013794","rc":[{"batb":[[0,7.2,6.08],[1,2,58.4],[2,1.06,149.69]],"ltp":5.9,"tv":17.82,"id":61077258}]}]}
{"op":"mcm","clk":"11924946855","pt":1724194690325,"mc":[{"id":"1.232013794","rc":[{"batb":[[0,7.4,10],[1,7.2,6.08],[2,2,58.4]],"ltp":5.9,"tv":17.82,"id":61077258}]}]}
{"op":"mcm","clk":"11924947019","pt":1724194693612,"mc":[{"id":"1.232013794","rc":[{"batb":[[0,7.2,6.08],[1,2,58.4],[2,1.06,149.69]],"ltp":5.9,"tv":17.82,"id":61077258}]}]}
{"op":"mcm","clk":"11924947173","pt":1724194696526,"mc":[{"id":"1.232013794","rc":[{"batb":[[0,7.4,10],[1,7.2,6.08],[2,2,58.4]],"ltp":5.9,"tv":17.82,"id":61077258}]}]}
{"op":"mcm","clk":"11924947317","pt":1724194699833,"mc":[{"id":"1.232013794","rc":[{"batb":[[0,7.2,6.08],[1,2,58.4],[2,1.06,149.69]],"ltp":5.9,"tv":17.82,"id":61077258}]}]}
{"op":"mcm","clk":"11924947423","pt":1724194702104,"mc":[{"id":"1.232013794","rc":[{"batb":[[0,7.4,10],[1,7.2,6.08],[2,2,58.4]],"ltp":5.9,"tv":17.82,"id":61077258}]}]}
{"op":"mcm","clk":"11924947563","pt":1724194705434,"mc":[{"id":"1.232013794","rc":[{"batb":[[0,7.2,6.08],[1,2,58.4],[2,1.06,149.69]],"ltp":5.9,"tv":17.82,"id":61077258}]}]}
{"op":"mcm","clk":"11924947655","pt":1724194707845,"mc":[{"id":"1.232013794","rc":[{"batb":[[0,7.4,10],[1,7.2,6.08],[2,2,58.4]],"ltp":5.9,"tv":17.82,"id":61077258}]}]}
{"op":"mcm","clk":"11924947877","pt":1724194711243,"mc":[{"id":"1.232013794","rc":[{"batb":[[0,7.2,6.08],[1,2,58.4],[2,1.06,149.69]],"ltp":5.9,"tv":17.82,"id":61077258}]}]}
{"op":"mcm","clk":"11924947999","pt":1724194713764,"mc":[{"id":"1.232013794","rc":[{"batb":[[0,7.4,10],[1,7.2,6.08],[2,2,58.4]],"ltp":5.9,"tv":17.82,"id":61077258}]}]}
{"op":"mcm","clk":"11924948229","pt":1724194717217,"mc":[{"id":"1.232013794","rc":[{"batb":[[0,7.2,6.08],[1,2,58.4],[2,1.06,149.69]],"ltp":5.9,"tv":17.82,"id":61077258}]}]}
{"op":"mcm","clk":"11924948337","pt":1724194719624,"mc":[{"id":"1.232013794","rc":[{"batb":[[0,7.4,10],[1,7.2,6.08],[2,2,58.4]],"ltp":5.9,"tv":17.82,"id":61077258}]}]}
{"op":"mcm","clk":"11924948475","pt":1724194722960,"mc":[{"id":"1.232013794","rc":[{"batb":[[0,7.2,6.08],[1,2,58.4],[2,1.06,149.69]],"ltp":5.9,"tv":17.82,"id":61077258}]}]}
{"op":"mcm","clk":"11924948636","pt":1724194725533,"mc":[{"id":"1.232013794","rc":[{"batb":[[0,7.4,10],[1,7.2,6.08],[2,2,58.4]],"ltp":5.9,"tv":17.82,"id":61077258}]}]}
{"op":"mcm","clk":"11924948755","pt":1724194729024,"mc":[{"id":"1.232013794","rc":[{"batb":[[0,7.2,6.08],[1,2,58.4],[2,1.06,149.69]],"ltp":5.9,"tv":17.82,"id":61077258}]}]}
{"op":"mcm","clk":"11924948856","pt":1724194731532,"mc":[{"id":"1.232013794","rc":[{"batb":[[0,7.4,10],[1,7.2,6.08],[2,2,58.4]],"ltp":5.9,"tv":17.82,"id":61077258}]}]}
{"op":"mcm","clk":"11924948989","pt":1724194734967,"mc":[{"id":"1.232013794","rc":[{"batb":[[0,7.2,6.08],[1,2,58.4],[2,1.06,149.69]],"ltp":5.9,"tv":17.82,"id":61077258}]}]}
{"op":"mcm","clk":"11924949078","pt":1724194737529,"mc":[{"id":"1.232013794","rc":[{"batb":[[0,7.4,10],[1,7.2,6.08],[2,2,58.4]],"ltp":5.9,"tv":17.82,"id":61077258}]}]}
