{"op":"mcm","clk":"11837271164","pt":1723646191199,"mc":[{"id":"1.231812842","marketDefinition":{"bspMarket":false,"turnInPlayEnabled":true,"persistenceEnabled":true,"marketBaseRate":5.0,"eventId":"33494847","eventTypeId":"4","numberOfWinners":1,"bettingType":"ODDS","marketType":"MATCH_ODDS","marketTime":"2024-08-22T10:00:00.000Z","suspendTime":"2024-08-22T10:00:00.000Z","bspReconciled":false,"complete":true,"inPlay":false,"crossMatching":false,"runnersVoidable":false,"numberOfActiveRunners":3,"betDelay":0,"status":"OPEN","runners":[{"status":"ACTIVE","sortPriority":1,"id":424676,"name":"Surrey"},{"status":"ACTIVE","sortPriority":2,"id":424679,"name":"Lancashire"},{"status":"ACTIVE","sortPriority":3,"id":60443,"name":"The Draw"}],"regulators":["MR_INT"],"countryCode":"GB","discountAllowed":false,"timezone":"GMT","openDate":"2024-08-22T10:00:00.000Z","version":6074361937,"name":"Match Odds","eventName":"Surrey v Lancashire"},"rc":[{"batb":[[0,1.01,20]],"ltp":0.0,"tv":0.0,"id":424679},{"batb":[[0,1.01,20]],"ltp":0.0,"tv":0.0,"id":424676},{"batb":[[0,1.01,20]],"ltp":0.0,"tv":0.0,"id":60443}]}]}
{"op":"mcm","clk":"11837271246","pt":1723646192016,"mc":[{"id":"1.231812842","rc":[{"batb":[[0,1.03,200],[1,1.02,200],[2,1.01,220]],"ltp":0.0,"tv":0.0,"id":424679},{"batb":[[0,1.03,200],[1,1.02,200],[2,1.01,220]],"ltp":0.0,"tv":0.0,"id":424676},{"batb":[[0,1.03,200],[1,1.02,200],[2,1.01,220]],"ltp":0.0,"tv":0.0,"id":60443}]}]}
{"op":"mcm","clk":"11837271432","pt":1723646193769,"mc":[{"id":"1.231812842","marketDefinition":{"bspMarket":false,"turnInPlayEnabled":true,"persistenceEnabled":true,"marketBaseRate":5.0,"eventId":"33494847","eventTypeId":"4","numberOfWinners":1,"bettingType":"ODDS","marketType":"MATCH_ODDS","marketTime":"2024-08-22T10:00:00.000Z","suspendTime":"2024-08-22T10:00:00.000Z","bspReconciled":false,"complete":true,"inPlay":false,"crossMatching":false,"runnersVoidable":false,"numberOfActiveRunners":3,"betDelay":0,"status":"OPEN","runners":[{"status":"ACTIVE","sortPriority":1,"id":424676,"name":"Surrey"},{"status":"ACTIVE","sortPriority":2,"id":424679,"name":"Lancashire"},{"status":"ACTIVE","sortPriority":3,"id":60443,"name":"The Draw"}],"regulators":["MR_INT"],"countryCode":"GB","discountAllowed":true,"timezone":"GMT","openDate":"2024-08-22T10:00:00.000Z","version":6074361937,"name":"Match Odds","eventName":"Surrey v Lancashire"}}]}
{"op":"mcm","clk":"11837611408","pt":1723649466705,"mc":[{"id":"1.231812842","rc":[{"batb":[[2,1.01,481.27]],"ltp":0.0,"tv":0.0,"id":424679},{"batb":[[2,1.01,481.27]],"ltp":0.0,"tv":0.0,"id":424676},{"batb":[[2,1.01,481.27]],"ltp":0.0,"tv":0.0,"id":60443}]}]}
{"op":"mcm","clk":"11837889535","pt":1723651975069,"mc":[{"id":"1.231812842","rc":[{"batb":[[2,1.01,480.83]],"ltp":0.0,"tv":0.0,"id":424679},{"batb":[[2,1.01,480.83]],"ltp":0.0,"tv":0.0,"id":424676},{"batb":[[2,1.01,480.83]],"ltp":0.0,"tv":0.0,"id":60443}]}]}
{"op":"mcm","clk":"11838563130","pt":1723657007989,"mc":[{"id":"1.231812842","rc":[{"batb":[[2,1.01,480.82]],"batl":[[0,990,5]],"ltp":0.0,"tv":0.0,"id":424679},{"batb":[[2,1.01,480.82]],"batl":[[0,990,5]],"ltp":0.0,"tv":0.0,"id":424676},{"batb":[[2,1.01,480.82]],"batl":[[0,990,5]],"ltp":0.0,"tv":0.0,"id":60443}]}]}
{"op":"mcm","clk":"11838566054","pt":1723657027196,"mc":[{"id":"1.231812842","marketDefinition":{"bspMarket":false,"turnInPlayEnabled":true,"persistenceEnabled":true,"marketBaseRate":5.0,"eventId":"33494847","eventTypeId":"4","numberOfWinners":1,"bettingType":"ODDS","marketType":"MATCH_ODDS","marketTime":"2024-08-22T10:00:00.000Z","suspendTime":"2024-08-22T10:00:00.000Z","bspReconciled":false,"complete":true,"inPlay":false,"crossMatching":true,"runnersVoidable":false,"numberOfActiveRunners":3,"betDelay":0,"status":"OPEN","runners":[{"status":"ACTIVE","sortPriority":1,"id":424676,"name":"Surrey"},{"status":"ACTIVE","sortPriority":2,"id":424679,"name":"Lancashire"},{"status":"ACTIVE","sortPriority":3,"id":60443,"name":"The Draw"}],"regulators":["MR_INT"],"countryCode":"GB","discountAllowed":true,"timezone":"GMT","openDate":"2024-08-22T10:00:00.000Z","version":6074361937,"name":"Match Odds","eventName":"Surrey v Lancashire"}}]}
{"op":"mcm","clk":"11838577136","pt":1723657094699,"mc":[{"id":"1.231812842","rc":[{"batb":[[0,1.04,250],[1,1.03,200],[2,1.02,200]],"batl":[[0,95,5],[1,990,5]],"ltp":0.0,"tv":0.0,"id":424679},{"batb":[[0,1.04,250],[1,1.03,200],[2,1.02,200]],"batl":[[0,95,5],[1,990,5]],"ltp":0.0,"tv":0.0,"id":424676},{"batl":[[0,95,5],[1,990,5]],"ltp":0.0,"tv":0.0,"id":60443}]}]}
{"op":"mcm","clk":"11838577152","pt":1723657094795,"mc":[{"id":"1.231812842","rc":[{"batb":[[0,1.04,250],[1,1.03,200],[2,1.02,200]],"ltp":0.0,"tv":0.0,"id":60443}]}]}
{"op":"mcm","clk":"11841458744","pt":1723701425494,"mc":[{"id":"1.231812842","marketDefinition":{"bspMarket":false,"turnInPlayEnabled":true,"persistenceEnabled":true,"marketBaseRate":5.0,"eventId":"33494847","eventTypeId":"4","numberOfWinners":1,"bettingType":"ODDS","marketType":"MATCH_ODDS","marketTime":"2024-08-22T10:00:00.000Z","suspendTime":"2024-08-22T10:00:00.000Z","bspReconciled":false,"complete":true,"inPlay":false,"crossMatching":true,"runnersVoidable":false,"numberOfActiveRunners":3,"betDelay":0,"status":"OPEN","runners":[{"status":"ACTIVE","sortPriority":1,"id":424676,"name":"Surrey"},{"status":"ACTIVE","sortPriority":2,"id":424679,"name":"Lancashire"},{"status":"ACTIVE","sortPriority":3,"id":60443,"name":"The Draw"}],"regulators":["MR_INT"],"countryCode":"GB","discountAllowed":true,"timezone":"GMT","openDate":"2024-08-22T10:00:00.000Z","version":6075395168,"name":"Match Odds","eventName":"Surrey v Lancashire"}}]}
{"op":"mcm","clk":"11842986964","pt":1723735144088,"mc":[{"id":"1.231812842","rc":[{"batl":[[0,95,5.95]],"ltp":0.0,"tv":0.0,"id":424676}]}]}
{"op":"mcm","clk":"11842987764","pt":1723735154109,"mc":[{"id":"1.231812842","rc":[{"batl":[[0,95,5.95]],"ltp":0.0,"tv":0.0,"id":424679}]}]}
{"op":"mcm","clk":"11842988452","pt":1723735163106,"mc":[{"id":"1.231812842","rc":[{"batl":[[0,95,5.95]],"ltp":0.0,"tv":0.0,"id":60443}]}]}
{"op":"mcm","clk":"11843053493","pt":1723736091983,"mc":[{"id":"1.231812842","rc":[{"batb":[[0,1.03,200],[1,1.02,200],[2,1.01,479.35]],"ltp":0.0,"tv":0.0,"id":60443}]}]}
{"op":"mcm","clk":"11843053556","pt":1723736093177,"mc":[{"id":"1.231812842","rc":[{"batb":[[0,1.03,200],[1,1.02,200],[2,1.01,479.35]],"ltp":0.0,"tv":0.0,"id":424679}]}]}
{"op":"mcm","clk":"11843053661","pt":1723736095094,"mc":[{"id":"1.231812842","rc":[{"batb":[[0,1.03,200],[1,1.02,200],[2,1.01,479.35]],"ltp":0.0,"tv":0.0,"id":424676}]}]}
{"op":"mcm","clk":"11843063086","pt":1723736244257,"mc":[{"id":"1.231812842","rc":[{"batb":[[0,1.13,138.46],[1,1.03,200],[2,1.02,200]],"ltp":0.0,"tv":0.0,"id":424679},{"batb":[[0,1.13,138.46],[1,1.03,200],[2,1.02,200]],"ltp":0.0,"tv":0.0,"id":424676},{"batb":[[0,1.13,138.46],[1,1.03,200],[2,1.02,200]],"ltp":0.0,"tv":0.0,"id":60443}]}]}
{"op":"mcm","clk":"11843246572","pt":1723738375147,"mc":[{"id":"1.231812842","rc":[{"batl":[[0,95,5.95]],"ltp":0.0,"tv":0.0,"id":424679},{"batl":[[0,95,5.95]],"ltp":0.0,"tv":0.0,"id":424676},{"batl":[[0,95,5.95]],"ltp":0.0,"tv":0.0,"id":60443}]}]}
{"op":"mcm","clk":"11846043061","pt":1723785684986,"mc":[{"id":"1.231812842","rc":[{"batb":[[0,1.14,61.26],[1,1.13,138.46],[2,1.03,200]],"ltp":0.0,"tv":0.0,"id":424679},{"batb":[[0,1.14,61.26],[1,1.13,138.46],[2,1.03,200]],"ltp":0.0,"tv":0.0,"id":424676},{"batb":[[0,1.14,61.26],[1,1.13,138.46],[2,1.03,200]],"ltp":0.0,"tv":0.0,"id":60443}]}]}
{"op":"mcm","clk":"11846141480","pt":1723787486707,"mc":[{"id":"1.231812842","rc":[{"batb":[[0,1.13,138.46],[1,1.03,200],[2,1.02,200]],"ltp":0.0,"tv":0.0,"id":424679}]}]}
{"op":"mcm","clk":"11846141500","pt":1723787487014,"mc":[{"id":"1.231812842","rc":[{"batb":[[0,1.13,138.46],[1,1.03,200],[2,1.02,200]],"ltp":0.0,"tv":0.0,"id":424676},{"batb":[[0,1.13,138.46],[1,1.03,200],[2,1.02,200]],"ltp":0.0,"tv":0.0,"id":60443}]}]}
{"op":"mcm","clk":"11846145738","pt":1723787576171,"mc":[{"id":"1.231812842","rc":[{"batb":[[0,1.14,61.26],[1,1.13,138.46],[2,1.03,200]],"ltp":0.0,"tv":0.0,"id":424679},{"batb":[[0,1.14,61.26],[1,1.13,138.46],[2,1.03,200]],"ltp":0.0,"tv":0.0,"id":424676},{"batb":[[0,1.14,61.26],[1,1.13,138.46],[2,1.03,200]],"ltp":0.0,"tv":0.0,"id":60443}]}]}
{"op":"mcm","clk":"11846220999","pt":1723789377588,"mc":[{"id":"1.231812842","rc":[{"batb":[[0,1.13,138.46],[1,1.03,200],[2,1.02,200]],"ltp":0.0,"tv":0.0,"id":424679},{"batb":[[0,1.13,138.46],[1,1.03,200],[2,1.02,200]],"ltp":0.0,"tv":0.0,"id":424676},{"batb":[[0,1.14,61.25]],"ltp":0.0,"tv":0.0,"id":60443}]}]}
{"op":"mcm","clk":"11846221008","pt":1723789377791,"mc":[{"id":"1.231812842","rc":[{"batb":[[0,1.13,138.46],[1,1.03,200],[2,1.02,200]],"ltp":0.0,"tv":0.0,"id":60443}]}]}
{"op":"mcm","clk":"11846223933","pt":1723789467814,"mc":[{"id":"1.231812842","rc":[{"batb":[[0,1.14,61.25],[1,1.13,138.46],[2,1.03,200]],"ltp":0.0,"tv":0.0,"id":424679},{"batb":[[0,1.14,61.25],[1,1.13,138.46],[2,1.03,200]],"ltp":0.0,"tv":0.0,"id":424676},{"batb":[[0,1.14,61.25],[1,1.13,138.46],[2,1.03,200]],"ltp":0.0,"tv":0.0,"id":60443}]}]}
{"op":"mcm","clk":"11846304221","pt":1723791269179,"mc":[{"id":"1.231812842","rc":[{"batb":[[0,1.13,138.46],[1,1.03,200],[2,1.02,200]],"ltp":0.0,"tv":0.0,"id":424679},{"batb":[[0,1.13,138.46],[1,1.03,200],[2,1.02,200]],"ltp":0.0,"tv":0.0,"id":424676},{"batb":[[0,1.13,138.46],[1,1.03,200],[2,1.02,200]],"ltp":0.0,"tv":0.0,"id":60443}]}]}
{"op":"mcm","clk":"11846307561","pt":1723791364035,"mc":[{"id":"1.231812842","rc":[{"batb":[[0,1.14,61.25],[1,1.13,138.46],[2,1.03,200]],"ltp":0.0,"tv":0.0,"id":424679},{"batb":[[0,1.14,61.25],[1,1.13,138.46],[2,1.03,200]],"ltp":0.0,"tv":0.0,"id":424676},{"batb":[[0,1.14,61.25],[1,1.13,138.46],[2,1.03,200]],"ltp":0.0,"tv":0.0,"id":60443}]}]}
{"op":"mcm","clk":"11846368622","pt":1723792375298,"mc":[{"id":"1.231812842","rc":[{"batb":[[0,1.14,61.24]],"ltp":0.0,"tv":0.0,"id":424679},{"batb":[[0,1.14,61.24]],"ltp":0.0,"tv":0.0,"id":424676},{"batb":[[0,1.14,61.24]],"ltp":0.0,"tv":0.0,"id":60443}]}]}
{"op":"mcm","clk":"11846412430","pt":1723793164588,"mc":[{"id":"1.231812842","rc":[{"batb":[[0,1.13,138.46],[1,1.03,200],[2,1.02,200]],"ltp":0.0,"tv":0.0,"id":424679},{"batb":[[0,1.13,138.46],[1,1.03,200],[2,1.02,200]],"ltp":0.0,"tv":0.0,"id":60443}]}]}
{"op":"mcm","clk":"11846412450","pt":1723793164892,"mc":[{"id":"1.231812842","rc":[{"batb":[[0,1.13,138.46],[1,1.03,200],[2,1.02,200]],"ltp":0.0,"tv":0.0,"id":424676}]}]}
{"op":"mcm","clk":"11846417491","pt":1723793257113,"mc":[{"id":"1.231812842","rc":[{"batb":[[0,1.14,61.24],[1,1.13,138.46],[2,1.03,200]],"ltp":0.0,"tv":0.0,"id":424679},{"batb":[[0,1.14,61.24],[1,1.13,138.46],[2,1.03,200]],"ltp":0.0,"tv":0.0,"id":424676},{"batb":[[0,1.14,61.24],[1,1.13,138.46],[2,1.03,200]],"ltp":0.0,"tv":0.0,"id":60443}]}]}
{"op":"mcm","clk":"11846521518","pt":1723795058668,"mc":[{"id":"1.231812842","rc":[{"batb":[[0,1.13,138.46],[1,1.03,200],[2,1.02,200]],"ltp":0.0,"tv":0.0,"id":424679},{"batb":[[0,1.13,138.46],[1,1.03,200],[2,1.02,200]],"ltp":0.0,"tv":0.0,"id":424676},{"batb":[[0,1.13,138.46],[1,1.03,200],[2,1.02,200]],"ltp":0.0,"tv":0.0,"id":60443}]}]}
{"op":"mcm","clk":"11846526933","pt":1723795147491,"mc":[{"id":"1.231812842","rc":[{"batb":[[0,1.14,61.24],[1,1.13,138.46],[2,1.03,200]],"ltp":0.0,"tv":0.0,"id":424679},{"batb":[[0,1.14,61.24],[1,1.13,138.46],[2,1.03,200]],"ltp":0.0,"tv":0.0,"id":424676},{"batb":[[0,1.14,61.24],[1,1.13,138.46],[2,1.03,200]],"ltp":0.0,"tv":0.0,"id":60443}]}]}
{"op":"mcm","clk":"11846643298","pt":1723796948719,"mc":[{"id":"1.231812842","rc":[{"batb":[[0,1.14,61.23]],"ltp":0.0,"tv":0.0,"id":424679},{"batb":[[0,1.13,138.46],[1,1.03,200],[2,1.02,200]],"ltp":0.0,"tv":0.0,"id":424676},{"batb":[[0,1.14,61.23]],"ltp":0.0,"tv":0.0,"id":60443}]}]}
{"op":"mcm","clk":"11846643324","pt":1723796949021,"mc":[{"id":"1.231812842","rc":[{"batb":[[0,1.13,138.46],[1,1.03,200],[2,1.02,200]],"ltp":0.0,"tv":0.0,"id":424679},{"batb":[[0,1.13,138.46],[1,1.03,200],[2,1.02,200]],"ltp":0.0,"tv":0.0,"id":60443}]}]}
{"op":"mcm","clk":"11846649353","pt":1723797036950,"mc":[{"id":"1.231812842","rc":[{"batb":[[0,1.14,61.23],[1,1.13,138.46],[2,1.03,200]],"ltp":0.0,"tv":0.0,"id":424679},{"batb":[[0,1.14,61.23],[1,1.13,138.46],[2,1.03,200]],"ltp":0.0,"tv":0.0,"id":424676},{"batb":[[0,1.14,61.23],[1,1.13,138.46],[2,1.03,200]],"ltp":0.0,"tv":0.0,"id":60443}]}]}
{"op":"mcm","clk":"11846766467","pt":1723798838266,"mc":[{"id":"1.231812842","rc":[{"batb":[[0,1.13,138.46],[1,1.03,200],[2,1.02,200]],"ltp":0.0,"tv":0.0,"id":424679},{"batb":[[0,1.13,138.46],[1,1.03,200],[2,1.02,200]],"ltp":0.0,"tv":0.0,"id":424676},{"batb":[[0,1.13,138.46],[1,1.03,200],[2,1.02,200]],"ltp":0.0,"tv":0.0,"id":60443}]}]}
{"op":"mcm","clk":"11846772822","pt":1723798924583,"mc":[{"id":"1.231812842","rc":[{"batb":[[0,1.14,61.19],[1,1.13,138.46],[2,1.03,200]],"ltp":0.0,"tv":0.0,"id":424679},{"batb":[[0,1.14,61.19],[1,1.13,138.46],[2,1.03,200]],"ltp":0.0,"tv":0.0,"id":424676},{"batb":[[0,1.14,61.19],[1,1.13,138.46],[2,1.03,200]],"ltp":0.0,"tv":0.0,"id":60443}]}]}
{"op":"mcm","clk":"11846875713","pt":1723800423760,"mc":[{"id":"1.231812842","rc":[{"batb":[[1,1.03,200],[2,1.02,200]],"ltp":0.0,"tv":0.0,"id":424679},{"batb":[[1,1.03,200],[2,1.02,200]],"ltp":0.0,"tv":0.0,"id":424676},{"batb":[[1,1.03,200],[2,1.02,200]],"ltp":0.0,"tv":0.0,"id":60443}]}]}
{"op":"mcm","clk":"11846878165","pt":1723800461120,"mc":[{"id":"1.231812842","rc":[{"batb":[[0,1.15,133.33],[1,1.14,61.19],[2,1.03,200]],"ltp":0.0,"tv":0.0,"id":424676}]}]}
{"op":"mcm","clk":"11846878389","pt":1723800465095,"mc":[{"id":"1.231812842","rc":[{"batb":[[0,1.15,133.33],[1,1.14,61.19],[2,1.03,200]],"ltp":0.0,"tv":0.0,"id":424679}]}]}
{"op":"mcm","clk":"11846878761","pt":1723800471019,"mc":[{"id":"1.231812842","rc":[{"batb":[[0,1.15,133.33],[1,1.14,61.19],[2,1.03,200]],"ltp":0.0,"tv":0.0,"id":60443}]}]}
{"op":"mcm","clk":"11846894347","pt":1723800725124,"mc":[{"id":"1.231812842","rc":[{"batb":[[1,1.03,200],[2,1.02,200]],"ltp":0.0,"tv":0.0,"id":424679},{"batb":[[1,1.03,200],[2,1.02,200]],"ltp":0.0,"tv":0.0,"id":424676},{"batb":[[1,1.03,200],[2,1.02,200]],"ltp":0.0,"tv":0.0,"id":60443}]}]}
{"op":"mcm","clk":"11846900337","pt":1723800811950,"mc":[{"id":"1.231812842","rc":[{"batb":[[0,1.16,53.54],[1,1.15,133.33],[2,1.03,200]],"ltp":0.0,"tv":0.0,"id":424679},{"batb":[[0,1.16,53.54],[1,1.15,133.33],[2,1.03,200]],"ltp":0.0,"tv":0.0,"id":424676},{"batb":[[0,1.16,53.54],[1,1.15,133.33],[2,1.03,200]],"ltp":0.0,"tv":0.0,"id":60443}]}]}
{"op":"mcm","clk":"11847022125","pt":1723802612764,"mc":[{"id":"1.231812842","rc":[{"batb":[[0,1.16,53.5]],"batl":[[0,95,5.95]],"ltp":0.0,"tv":0.0,"id":424679},{"batb":[[0,1.15,133.33],[1,1.03,200],[2,1.02,200]],"batl":[[0,95,5.95]],"ltp":0.0,"tv":0.0,"id":424676},{"batb":[[0,1.16,53.5]],"batl":[[0,95,5.95]],"ltp":0.0,"tv":0.0,"id":60443}]}]}
{"op":"mcm","clk":"11847022152","pt":1723802613171,"mc":[{"id":"1.231812842","rc":[{"batb":[[0,1.15,133.33],[1,1.03,200],[2,1.02,200]],"ltp":0.0,"tv":0.0,"id":424679},{"batb":[[0,1.15,133.33],[1,1.03,200],[2,1.02,200]],"ltp":0.0,"tv":0.0,"id":60443}]}]}
{"op":"mcm","clk":"11847027251","pt":1723802696060,"mc":[{"id":"1.231812842","rc":[{"batb":[[0,1.16,53.5],[1,1.15,133.33],[2,1.03,200]],"ltp":0.0,"tv":0.0,"id":424679},{"batb":[[0,1.16,53.5],[1,1.15,133.33],[2,1.03,200]],"ltp":0.0,"tv":0.0,"id":424676},{"batb":[[0,1.16,53.5],[1,1.15,133.33],[2,1.03,200]],"ltp":0.0,"tv":0.0,"id":60443}]}]}
{"op":"mcm","clk":"11847047330","pt":1723802982176,"mc":[{"id":"1.231812842","rc":[{"trd":[[1.16,2]],"batb":[[0,1.16,52.5]],"ltp":1.16,"tv":1.99,"id":424676}],"tv":1.99}]}
{"op":"mcm","clk":"11847051998","pt":1723803044509,"mc":[{"id":"1.231812842","rc":[{"trd":[[1.16,2]],"batb":[[0,1.16,52.5]],"ltp":1.16,"tv":1.99,"id":424679}],"tv":3.99}]}
{"op":"mcm","clk":"11847053320","pt":1723803063520,"mc":[{"id":"1.231812842","rc":[{"trd":[[1.16,2]],"batb":[[0,1.16,52.5]],"ltp":1.16,"tv":1.99,"id":60443}],"tv":5.99}]}
{"op":"mcm","clk":"11847054028","pt":1723803071831,"mc":[{"id":"1.231812842","rc":[{"trd":[[1.16,4]],"batb":[[0,1.16,51.5]],"ltp":1.16,"tv":3.99,"id":424676}],"tv":7.99}]}
{"op":"mcm","clk":"11847179173","pt":1723804497685,"mc":[{"id":"1.231812842","rc":[{"batb":[[0,1.15,133.33],[1,1.03,200],[2,1.02,200]],"ltp":1.16,"tv":1.99,"id":424679},{"batb":[[0,1.15,133.33],[1,1.03,200],[2,1.02,200]],"ltp":1.16,"tv":3.99,"id":424676},{"batb":[[0,1.15,133.33],[1,1.03,200],[2,1.02,200]],"ltp":1.16,"tv":1.99,"id":60443}]}]}
{"op":"mcm","clk":"11847798614","pt":1723811469278,"mc":[{"id":"1.231812842","rc":[{"batb":[[0,1.03,200],[1,1.02,200],[2,1.01,478.17]],"ltp":1.16,"tv":3.99,"id":424676}]}]}
{"op":"mcm","clk":"11847798737","pt":1723811470583,"mc":[{"id":"1.231812842","rc":[{"batb":[[0,1.13,153.85],[1,1.03,200],[2,1.02,200]],"ltp":1.16,"tv":3.99,"id":424676}]}]}
{"op":"mcm","clk":"11847799158","pt":1723811475455,"mc":[{"id":"1.231812842","rc":[{"batb":[[0,1.03,200],[1,1.02,200],[2,1.01,478.17]],"ltp":1.16,"tv":1.99,"id":424679}]}]}
{"op":"mcm","clk":"11847799257","pt":1723811476592,"mc":[{"id":"1.231812842","rc":[{"batb":[[0,1.13,153.85],[1,1.03,200],[2,1.02,200]],"ltp":1.16,"tv":1.99,"id":424679}]}]}
{"op":"mcm","clk":"11847799635","pt":1723811481053,"mc":[{"id":"1.231812842","rc":[{"batb":[[0,1.03,200],[1,1.02,200],[2,1.01,478.17]],"ltp":1.16,"tv":1.99,"id":60443}]}]}
{"op":"mcm","clk":"11847799736","pt":1723811482394,"mc":[{"id":"1.231812842","rc":[{"batb":[[0,1.13,153.85],[1,1.03,200],[2,1.02,200]],"ltp":1.16,"tv":1.99,"id":60443}]}]}
{"op":"mcm","clk":"11848029343","pt":1723813975220,"mc":[{"id":"1.231812842","rc":[{"trd":[[1.16,2]],"ltp":1.16,"tv":2.0,"id":424679},{"trd":[[1.16,4]],"ltp":1.16,"tv":4.0,"id":424676},{"trd":[[1.16,2]],"ltp":1.16,"tv":2.0,"id":60443}],"tv":8.0}]}
{"op":"mcm","clk":"11848426718","pt":1723818607224,"mc":[{"id":"1.231812842","rc":[{"batl":[[0,95,5]],"ltp":1.16,"tv":2.0,"id":424679},{"batl":[[0,95,5]],"ltp":1.16,"tv":4.0,"id":424676},{"batl":[[0,95,5]],"ltp":1.16,"tv":2.0,"id":60443}]}]}
{"op":"mcm","clk":"11849003467","pt":1723824775329,"mc":[{"id":"1.231812842","tv":8.0}]}
{"op":"mcm","clk":"11849519296","pt":1723827550175,"mc":[{"id":"1.231812842","rc":[{"batl":[[0,95,5.95]],"ltp":1.16,"tv":2.0,"id":60443}]}]}
{"op":"mcm","clk":"11849520907","pt":1723827561179,"mc":[{"id":"1.231812842","rc":[{"batl":[[0,95,5.95]],"ltp":1.16,"tv":2.0,"id":424679}]}]}
{"op":"mcm","clk":"11849522399","pt":1723827572222,"mc":[{"id":"1.231812842","rc":[{"batl":[[0,95,5.95]],"ltp":1.16,"tv":4.0,"id":424676}]}]}
{"op":"mcm","clk":"11849651501","pt":1723828164173,"mc":[{"id":"1.231812842","rc":[{"batl":[[0,95,5.95]],"ltp":1.16,"tv":1.99,"id":424679},{"trd":[[1.16,4]],"batl":[[0,95,5.95]],"ltp":1.16,"tv":3.99,"id":424676},{"batl":[[0,95,5.95]],"ltp":1.16,"tv":1.99,"id":60443}],"tv":7.99}]}
{"op":"mcm","clk":"11851170213","pt":1723835575264,"mc":[{"id":"1.231812842","rc":[{"batl":[[0,95,5.94]],"ltp":1.16,"tv":1.99,"id":424679},{"batl":[[0,95,5.94]],"ltp":1.16,"tv":3.99,"id":424676},{"batl":[[0,95,5.94]],"ltp":1.16,"tv":1.99,"id":60443}]}]}
{"op":"mcm","clk":"11857541174","pt":1723900267764,"mc":[{"id":"1.231812842","rc":[{"batb":[[0,1.14,35.78],[1,1.13,153.85],[2,1.03,200]],"batl":[[0,90,1.79],[1,95,5],[2,990,5]],"ltp":1.16,"tv":1.99,"id":424679},{"batb":[[0,1.14,35.78],[1,1.13,153.85],[2,1.03,200]],"batl":[[0,90,1.79],[1,95,5],[2,990,5]],"ltp":1.16,"tv":3.99,"id":424676},{"batb":[[0,1.14,55.37],[1,1.13,153.85],[2,1.03,200]],"batl":[[0,90,1.79],[1,95,5],[2,990,5]],"ltp":1.16,"tv":1.99,"id":60443}]}]}
{"op":"mcm","clk":"11857547824","pt":1723900300743,"mc":[{"id":"1.231812842","rc":[{"batl":[[0,95,5.94],[1,990,5],[2,990,0]],"ltp":1.16,"tv":1.99,"id":424679},{"batl":[[0,95,5.94],[1,990,5],[2,990,0]],"ltp":1.16,"tv":3.99,"id":424676},{"batl":[[0,95,5.94],[1,990,5],[2,990,0]],"ltp":1.16,"tv":1.99,"id":60443}]}]}
{"op":"mcm","clk":"11857547846","pt":1723900300865,"mc":[{"id":"1.231812842","rc":[{"batl":[[0,18,1.79],[1,95,5],[2,990,5]],"ltp":1.16,"tv":1.99,"id":424679},{"batl":[[0,18,1.79],[1,95,5],[2,990,5]],"ltp":1.16,"tv":3.99,"id":424676},{"batl":[[0,16,1.79],[1,95,5],[2,990,5]],"ltp":1.16,"tv":1.99,"id":60443}]}]}
{"op":"mcm","clk":"11859943024","pt":1723909161030,"mc":[{"id":"1.231812842","rc":[{"batl":[[0,95,5.85],[1,990,5],[2,990,0]],"ltp":1.16,"tv":1.99,"id":424679},{"batl":[[0,95,5.85],[1,990,5],[2,990,0]],"ltp":1.16,"tv":3.99,"id":424676},{"batl":[[0,95,5.85],[1,990,5],[2,990,0]],"ltp":1.16,"tv":1.99,"id":60443}]}]}
{"op":"mcm","clk":"11860043215","pt":1723909491015,"mc":[{"id":"1.231812842","rc":[{"batb":[[0,1.15,35.78]],"ltp":1.16,"tv":1.99,"id":424679},{"batb":[[0,1.15,35.78]],"ltp":1.16,"tv":3.99,"id":424676}]}]}
{"op":"mcm","clk":"11862225855","pt":1723921184120,"mc":[{"id":"1.231812842","rc":[{"batb":[[1,1.03,200],[2,1.02,200]],"ltp":1.16,"tv":3.99,"id":424676}]}]}
{"op":"mcm","clk":"11862226073","pt":1723921185556,"mc":[{"id":"1.231812842","rc":[{"batb":[[1,1.03,200],[2,1.02,200]],"ltp":1.16,"tv":1.99,"id":424679}]}]}
{"op":"mcm","clk":"11862226282","pt":1723921187021,"mc":[{"id":"1.231812842","rc":[{"batb":[[1,1.03,200],[2,1.02,200]],"ltp":1.16,"tv":1.99,"id":60443}]}]}
{"op":"mcm","clk":"11862226421","pt":1723921187923,"mc":[{"id":"1.231812842","rc":[{"batb":[[0,1.15,133.33],[1,1.14,55.37],[2,1.03,200]],"ltp":1.16,"tv":1.99,"id":60443}]}]}
{"op":"mcm","clk":"11862226669","pt":1723921189665,"mc":[{"id":"1.231812842","rc":[{"batb":[[0,1.16,125],[1,1.15,35.78],[2,1.03,200]],"ltp":1.16,"tv":1.99,"id":424679}]}]}
{"op":"mcm","clk":"11862227085","pt":1723921192281,"mc":[{"id":"1.231812842","rc":[{"batb":[[0,1.16,125],[1,1.15,35.78],[2,1.03,200]],"ltp":1.16,"tv":3.99,"id":424676}]}]}
{"op":"mcm","clk":"11865471328","pt":1723957585218,"mc":[{"id":"1.231812842","rc":[{"batb":[[0,1.17,35.78],[1,1.16,125]],"ltp":1.16,"tv":1.99,"id":424679},{"batb":[[0,1.17,35.78],[1,1.16,125]],"ltp":1.16,"tv":3.99,"id":424676},{"batb":[[0,1.16,55.37],[1,1.15,133.33]],"ltp":1.16,"tv":1.99,"id":60443}]}]}
{"op":"mcm","clk":"11865666966","pt":1723962814891,"mc":[{"id":"1.231812842","rc":[{"batb":[[0,1.18,19],[1,1.17,35.78],[2,1.16,125]],"ltp":1.16,"tv":1.99,"id":424679},{"batb":[[0,1.18,23],[1,1.17,35.78],[2,1.16,125]],"ltp":1.16,"tv":3.99,"id":424676}]}]}
{"op":"mcm","clk":"11866024976","pt":1723969632174,"mc":[{"id":"1.231812842","rc":[{"batb":[[0,2,25],[1,1.16,55.37],[2,1.15,133.33]],"ltp":1.16,"tv":1.99,"id":60443}]}]}
{"op":"mcm","clk":"11866037612","pt":1723969810887,"mc":[{"id":"1.231812842","rc":[{"batb":[[0,1.19,35.78],[1,1.18,19]],"ltp":1.16,"tv":1.99,"id":424679},{"batb":[[0,1.19,35.78],[1,1.18,23]],"ltp":1.16,"tv":3.99,"id":424676},{"batb":[[1,1.17,55.37]],"ltp":1.16,"tv":1.99,"id":60443}]}]}
{"op":"mcm","clk":"11866047175","pt":1723969956948,"mc":[{"id":"1.231812842","rc":[{"batl":[[0,3.45,15],[1,95,5.85],[2,990,5]],"ltp":1.16,"tv":3.99,"id":424676}]}]}
{"op":"mcm","clk":"11866306207","pt":1723972582604,"mc":[{"id":"1.231812842","rc":[{"batb":[[0,1.2,7.3],[1,1.19,35.78],[2,1.18,23]],"ltp":1.16,"tv":3.99,"id":424676}]}]}
{"op":"mcm","clk":"11866306240","pt":1723972582873,"mc":[{"id":"1.231812842","rc":[{"batb":[[0,1.2,7.5],[1,1.19,35.78],[2,1.18,19]],"ltp":1.16,"tv":1.99,"id":424679}]}]}
{"op":"mcm","clk":"11866407025","pt":1723973562048,"mc":[{"id":"1.231812842","rc":[{"batb":[[0,1.4,20],[1,1.2,7.3],[2,1.19,35.78]],"ltp":1.16,"tv":3.99,"id":424676}]}]}
{"op":"mcm","clk":"11866408035","pt":1723973570968,"mc":[{"id":"1.231812842","rc":[{"batb":[[0,1.5,20],[1,1.2,7.5],[2,1.19,35.78]],"ltp":1.16,"tv":1.99,"id":424679}]}]}
{"op":"mcm","clk":"11866409027","pt":1723973580603,"mc":[{"id":"1.231812842","rc":[{"batb":[[1,1.3,20],[2,1.17,55.37]],"ltp":1.16,"tv":1.99,"id":60443}]}]}
{"op":"mcm","clk":"11866549519","pt":1723974862837,"mc":[{"id":"1.231812842","rc":[{"batb":[[0,1.5,3.94],[1,1.4,20],[2,1.2,7.3]],"ltp":1.16,"tv":3.99,"id":424676}]}]}
{"op":"mcm","clk":"11866610470","pt":1723975423493,"mc":[{"id":"1.231812842","rc":[{"batb":[[1,1.19,35.78],[2,1.18,19]],"ltp":1.16,"tv":1.99,"id":424679},{"batb":[[2,1.19,35.78]],"ltp":1.16,"tv":3.99,"id":424676}]}]}
{"op":"mcm","clk":"11866682663","pt":1723975962716,"mc":[{"id":"1.231812842","rc":[{"batb":[[2,1.16,125]],"ltp":1.16,"tv":1.99,"id":424679}]}]}
{"op":"mcm","clk":"11866682673","pt":1723975962820,"mc":[{"id":"1.231812842","rc":[{"batb":[[0,1.52,19],[1,1.5,20],[2,1.19,35.78]],"ltp":1.16,"tv":1.99,"id":424679},{"batb":[[0,1.51,23],[1,1.5,3.94],[2,1.4,20]],"ltp":1.16,"tv":3.99,"id":424676}]}]}
{"op":"mcm","clk":"11867012168","pt":1723978332949,"mc":[{"id":"1.231812842","rc":[{"batb":[[2,1.2,6.94]],"ltp":1.16,"tv":1.99,"id":424679}]}]}
{"op":"mcm","clk":"11867438800","pt":1723981247997,"mc":[{"id":"1.231812842","rc":[{"batb":[[2,1.19,35.78]],"ltp":1.16,"tv":1.99,"id":424679}]}]}
{"op":"mcm","clk":"11867842472","pt":1723983921668,"mc":[{"id":"1.231812842","rc":[{"batb":[[2,1.2,6.84]],"ltp":1.16,"tv":1.99,"id":424679}]}]}
{"op":"mcm","clk":"11868281959","pt":1723986721027,"mc":[{"id":"1.231812842","rc":[{"batb":[[2,1.19,35.78]],"ltp":1.16,"tv":1.99,"id":424679}]}]}
{"op":"mcm","clk":"11868577052","pt":1723988492656,"mc":[{"id":"1.231812842","rc":[{"batb":[[2,1.16,125]],"ltp":1.16,"tv":1.99,"id":424679},{"batb":[[2,1.15,133.33]],"ltp":1.16,"tv":1.99,"id":60443}]}]}
{"op":"mcm","clk":"11871030640","pt":1724000899051,"mc":[{"id":"1.231812842","rc":[{"batb":[[1,1.4,20],[2,1.16,125]],"ltp":1.16,"tv":3.99,"id":424676}]}]}
{"op":"mcm","clk":"11871284870","pt":1724002318490,"mc":[{"id":"1.231812842","rc":[{"batb":[[0,1.7,2.69],[1,1.52,19],[2,1.5,20]],"ltp":1.16,"tv":1.99,"id":424679}]}]}
{"op":"mcm","clk":"11872344286","pt":1724008445271,"mc":[{"id":"1.231812842","rc":[{"batb":[[2,1.03,200]],"ltp":1.16,"tv":3.99,"id":424676}]}]}
{"op":"mcm","clk":"11872345168","pt":1724008450858,"mc":[{"id":"1.231812842","rc":[{"batb":[[2,1.03,200]],"ltp":1.16,"tv":1.99,"id":60443}]}]}
{"op":"mcm","clk":"11872345351","pt":1724008451978,"mc":[{"id":"1.231812842","rc":[{"batb":[[2,1.09,222.22]],"ltp":1.16,"tv":1.99,"id":60443}]}]}
{"op":"mcm","clk":"11872347711","pt":1724008465460,"mc":[{"id":"1.231812842","rc":[{"batb":[[2,1.09,222.22]],"ltp":1.16,"tv":3.99,"id":424676}]}]}
{"op":"mcm","clk":"11873086596","pt":1724013472557,"mc":[{"id":"1.231812842","rc":[{"trd":[[1.16,2]],"batb":[[1,1.61,19]],"batl":[[0,95,5.85]],"ltp":1.16,"tv":2.0,"id":424679},{"trd":[[1.16,4]],"batl":[[1,95,5.85]],"ltp":1.16,"tv":4.0,"id":424676},{"trd":[[1.16,2]],"batl":[[0,95,5.85]],"ltp":1.16,"tv":2.0,"id":60443}],"tv":8.0}]}
{"op":"mcm","clk":"11873093046","pt":1724013525586,"mc":[{"id":"1.231812842","rc":[{"batb":[[0,1.71,19],[1,1.7,2.69]],"ltp":1.16,"tv":2.0,"id":424679}]}]}
{"op":"mcm","clk":"11873421779","pt":1724016981252,"mc":[{"id":"1.231812842","rc":[{"batb":[[1,1.7,2.7]],"ltp":1.16,"tv":2.0,"id":424679},{"trd":[[1.16,4]],"ltp":1.16,"tv":4.0,"id":424676}],"tv":8.0}]}
{"op":"mcm","clk":"11873614890","pt":1724019175028,"mc":[{"id":"1.231812842","rc":[{"trd":[[1.16,4]],"ltp":1.16,"tv":4.0,"id":424676}],"tv":8.0}]}
{"op":"mcm","clk":"11874226136","pt":1724029975076,"mc":[{"id":"1.231812842","rc":[{"batb":[[1,1.7,2.69]],"ltp":1.16,"tv":2.0,"id":424679}],"tv":8.0}]}
{"op":"mcm","clk":"11874436346","pt":1724035375061,"mc":[{"id":"1.231812842","rc":[{"trd":[[1.16,4]],"ltp":1.16,"tv":3.99,"id":424676}],"tv":7.99}]}
{"op":"mcm","clk":"11874672033","pt":1724040775076,"mc":[{"id":"1.231812842","rc":[{"trd":[[1.16,4]],"ltp":1.16,"tv":4.0,"id":424676}],"tv":8.0}]}
{"op":"mcm","clk":"11875055888","pt":1724051575064,"mc":[{"id":"1.231812842","rc":[{"batb":[[1,1.7,2.69]],"ltp":1.16,"tv":2.0,"id":424679}],"tv":8.0}]}
{"op":"mcm","clk":"11875585859","pt":1724062375064,"mc":[{"id":"1.231812842","rc":[{"trd":[[1.16,4]],"ltp":1.16,"tv":3.99,"id":424676}],"tv":7.99}]}
{"op":"mcm","clk":"11875801972","pt":1724065730962,"mc":[{"id":"1.231812842","rc":[{"trd":[[1.16,2]],"batb":[[1,1.7,2.69]],"batl":[[0,95,5.85]],"ltp":1.16,"tv":2.0,"id":424679},{"trd":[[1.16,4]],"batl":[[0,1.6,1.54],[1,3.45,15],[2,95,5.85]],"ltp":1.16,"tv":4.0,"id":424676},{"trd":[[1.16,2]],"batl":[[0,95,5.85]],"ltp":1.16,"tv":2.0,"id":60443}],"tv":8.0}]}
{"op":"mcm","clk":"11875802310","pt":1724065736537,"mc":[{"id":"1.231812842","rc":[{"batl":[[0,3.45,15],[1,95,5.85],[2,990,5]],"ltp":1.16,"tv":4.0,"id":424676}]}]}
{"op":"mcm","clk":"11876418858","pt":1724075023529,"mc":[{"id":"1.231812842","rc":[{"batb":[[1,1.5,20],[2,1.09,222.22]],"ltp":1.16,"tv":2.0,"id":424679}]}]}
{"op":"mcm","clk":"11876685239","pt":1724078575084,"mc":[{"id":"1.231812842","tv":8.0}]}
{"op":"mcm","clk":"11877153064","pt":1724083975069,"mc":[{"id":"1.231812842","rc":[{"trd":[[1.16,4]],"ltp":1.16,"tv":4.0,"id":424676}],"tv":8.0}]}
{"op":"mcm","clk":"11877712292","pt":1724089375061,"mc":[{"id":"1.231812842","tv":8.0}]}
{"op":"mcm","clk":"11877865531","pt":1724090649499,"mc":[{"id":"1.231812842","rc":[{"batb":[[1,1.3,20.9]],"ltp":1.16,"tv":2.0,"id":60443}],"tv":8.0}]}
{"op":"mcm","clk":"11878357853","pt":1724094077639,"mc":[{"id":"1.231812842","rc":[{"batl":[[0,1.6,1.54],[1,3.45,15],[2,95,5.85]],"ltp":1.16,"tv":4.0,"id":424676}],"tv":8.0}]}
{"op":"mcm","clk":"11878358687","pt":1724094084942,"mc":[{"id":"1.231812842","rc":[{"batl":[[0,3.45,15],[1,95,5.85],[2,990,5]],"ltp":1.16,"tv":4.0,"id":424676}]}]}
{"op":"mcm","clk":"11878359940","pt":1724094095844,"mc":[{"id":"1.231812842","rc":[{"batb":[[0,2,1.54],[1,1.51,23],[2,1.4,20]],"ltp":1.16,"tv":4.0,"id":424676}]}]}
{"op":"mcm","clk":"11878360917","pt":1724094104863,"mc":[{"id":"1.231812842","rc":[{"batb":[[0,1.51,23],[1,1.4,20],[2,1.09,222.22]],"ltp":1.16,"tv":4.0,"id":424676}]}]}
{"op":"mcm","clk":"11878925882","pt":1724100175111,"mc":[{"id":"1.231812842","tv":8.0}]}
{"op":"mcm","clk":"11879938280","pt":1724116375096,"mc":[{"id":"1.231812842","tv":8.0}]}
{"op":"mcm","clk":"11880203874","pt":1724121775102,"mc":[{"id":"1.231812842","tv":8.0}]}
{"op":"mcm","clk":"11880389478","pt":1724127175136,"mc":[{"id":"1.231812842","tv":8.0}]}
{"op":"mcm","clk":"11880744133","pt":1724137975116,"mc":[{"id":"1.231812842","rc":[{"trd":[[1.16,4]],"ltp":1.16,"tv":4.0,"id":424676},{"batb":[[1,1.3,20.9]],"ltp":1.16,"tv":2.0,"id":60443}],"tv":8.0}]}
{"op":"mcm","clk":"11881398867","pt":1724148775110,"mc":[{"id":"1.231812842","rc":[{"trd":[[1.16,2]],"batl":[[0,95,5.85]],"ltp":1.16,"tv":1.99,"id":424679},{"trd":[[1.16,4]],"batl":[[1,95,5.85]],"ltp":1.16,"tv":3.99,"id":424676},{"trd":[[1.16,2]],"batl":[[0,95,5.85]],"ltp":1.16,"tv":1.99,"id":60443}],"tv":7.99}]}
{"op":"mcm","clk":"11881908242","pt":1724154175093,"mc":[{"id":"1.231812842","tv":8.0}]}
{"op":"mcm","clk":"11882197417","pt":1724157821229,"mc":[{"id":"1.231812842","rc":[{"batl":[[0,18,4],[1,95,5.85],[2,990,5]],"ltp":1.16,"tv":2.0,"id":424679},{"trd":[[1.16,4]],"ltp":1.16,"tv":3.99,"id":424676}],"tv":8.0}]}
{"op":"mcm","clk":"11882256169","pt":1724158573317,"mc":[{"id":"1.231812842","rc":[{"batl":[[0,1.9,1],[1,3.45,15],[2,95,5.85]],"ltp":1.16,"tv":3.99,"id":424676}]}]}
{"op":"mcm","clk":"11882260052","pt":1724158627761,"mc":[{"id":"1.231812842","rc":[{"batl":[[0,3.45,15],[1,95,5.85],[2,990,5]],"ltp":1.16,"tv":3.99,"id":424676}]}]}
{"op":"mcm","clk":"11882260064","pt":1724158627863,"mc":[{"id":"1.231812842","rc":[{"batl":[[0,1.8,1],[1,3.45,15],[2,95,5.85]],"ltp":1.16,"tv":3.99,"id":424676}]}]}
{"op":"mcm","clk":"11882293537","pt":1724159015285,"mc":[{"id":"1.231812842","rc":[{"batl":[[0,1.7,1]],"ltp":1.16,"tv":3.99,"id":424676},{"batb":[[1,1.3,20.89]],"ltp":1.16,"tv":2.0,"id":60443}]}]}
{"op":"mcm","clk":"11882726596","pt":1724163332491,"mc":[{"id":"1.231812842","rc":[{"trd":[[1.16,4]],"ltp":1.16,"tv":4.0,"id":424676},{"batb":[[1,1.3,20]],"ltp":1.16,"tv":2.0,"id":60443}],"tv":8.0}]}
{"op":"mcm","clk":"11882786622","pt":1724163960628,"mc":[{"id":"1.231812842","rc":[{"trd":[[1.71,2.62],[2.48,0.69]],"batb":[[0,1.71,17.69]],"ltp":1.71,"tv":5.31,"id":424679},{"trd":[[1.7,1]],"batl":[[0,3.45,15],[1,95,5.85],[2,990,5]],"ltp":1.7,"tv":5.0,"id":424676},{"trd":[[90,0.02]],"batl":[[0,95,5.84]],"ltp":90.0,"tv":2.01,"id":60443}],"tv":12.32}]}
{"op":"mcm","clk":"11882798904","pt":1724164094917,"mc":[{"id":"1.231812842","rc":[{"batb":[[0,1.5,20],[1,1.09,222.22],[2,1.04,1.53]],"ltp":1.71,"tv":5.31,"id":424679},{"batb":[[0,1.4,20],[1,1.09,222.22],[2,1.04,1.53]],"ltp":1.7,"tv":5.0,"id":424676}]}]}
{"op":"mcm","clk":"11882802350","pt":1724164135033,"mc":[{"id":"1.231812842","rc":[{"batb":[[0,1.41,1.7],[1,1.4,20],[2,1.09,222.22]],"ltp":1.7,"tv":5.0,"id":424676}]}]}
{"op":"mcm","clk":"11882805307","pt":1724164167174,"mc":[{"id":"1.231812842","rc":[{"batb":[[0,1.72,16],[1,1.5,20],[2,1.09,222.22]],"ltp":1.71,"tv":5.31,"id":424679}]}]}
{"op":"mcm","clk":"11883004649","pt":1724166145597,"mc":[{"id":"1.231812842","rc":[{"trd":[[1.16,4]],"batb":[[0,1.5,4],[1,1.41,1.7],[2,1.4,20]],"ltp":1.7,"tv":5.0,"id":424676}],"tv":12.33}]}
{"op":"mcm","clk":"11883005428","pt":1724166153467,"mc":[{"id":"1.231812842","rc":[{"batb":[[0,2,25.85]],"ltp":90.0,"tv":2.01,"id":60443}]}]}
{"op":"mcm","clk":"11883006549","pt":1724166166889,"mc":[{"id":"1.231812842","rc":[{"batb":[[0,1.5,6]],"ltp":1.7,"tv":5.0,"id":424676}]}]}
{"op":"mcm","clk":"11883020523","pt":1724166321734,"mc":[{"id":"1.231812842","rc":[{"batl":[[1,90,1.02],[2,95,5]],"ltp":1.71,"tv":5.31,"id":424679},{"batl":[[1,90,1.02],[2,95,5]],"ltp":1.7,"tv":5.0,"id":424676},{"batl":[[0,90,1.01],[1,95,5],[2,990,5]],"ltp":90.0,"tv":2.01,"id":60443}]}]}
{"op":"mcm","clk":"11883026379","pt":1724166380049,"mc":[{"id":"1.231812842","rc":[{"batl":[[2,990,5.17]],"ltp":90.0,"tv":2.01,"id":60443}]}]}
{"op":"mcm","clk":"11883029325","pt":1724166408255,"mc":[{"id":"1.231812842","rc":[{"batl":[[2,990,5.34]],"ltp":90.0,"tv":2.01,"id":60443}]}]}
{"op":"mcm","clk":"11883036434","pt":1724166468209,"mc":[{"id":"1.231812842","rc":[{"batl":[[2,990,5.51]],"ltp":90.0,"tv":2.01,"id":60443}]}]}
{"op":"mcm","clk":"11883120221","pt":1724167160418,"mc":[{"id":"1.231812842","rc":[{"batb":[[0,1.67,2],[1,1.5,6],[2,1.41,1.7]],"ltp":1.7,"tv":5.0,"id":424676}]}]}
{"op":"mcm","clk":"11884006649","pt":1724173064634,"mc":[{"id":"1.231812842","rc":[{"batb":[[1,1.41,1.7],[2,1.4,20]],"ltp":1.7,"tv":5.0,"id":424676}]}]}
{"op":"mcm","clk":"11884408811","pt":1724175775064,"mc":[{"id":"1.231812842","rc":[{"trd":[[1.16,4]],"ltp":1.7,"tv":5.0,"id":424676}],"tv":12.33}]}
{"op":"mcm","clk":"11884562123","pt":1724176900488,"mc":[{"id":"1.231812842","rc":[{"batl":[[0,17.5,1],[1,18,4],[2,90,1.02]],"ltp":1.71,"tv":5.31,"id":424679},{"batl":[[0,3.4,1],[1,3.45,15],[2,90,1.02]],"ltp":1.7,"tv":5.0,"id":424676},{"batl":[[0,85,1.17],[1,95,5.84]],"ltp":90.0,"tv":2.01,"id":60443}],"tv":12.33}]}
{"op":"mcm","clk":"11885249098","pt":1724181175080,"mc":[{"id":"1.231812842","tv":12.33}]}
{"op":"mcm","clk":"11885642022","pt":1724183658283,"mc":[{"id":"1.231812842","rc":[{"batl":[[0,17.5,5],[1,90,1.02],[2,95,5]],"ltp":1.71,"tv":5.31,"id":424679},{"batl":[[0,3.4,16],[1,90,1.02],[2,95,5]],"ltp":1.7,"tv":5.0,"id":424676}]}]}
{"op":"mcm","clk":"11886323628","pt":1724191532267,"mc":[{"id":"1.231812842","rc":[{"batb":[[0,1.5,20],[1,1.09,222.22],[2,1.04,1.53]],"ltp":1.71,"tv":5.31,"id":424679},{"trd":[[1.16,4]],"batb":[[1,1.4,20],[2,1.09,222.22]],"ltp":1.7,"tv":5.0,"id":424676}],"tv":12.33}]}
{"op":"mcm","clk":"11886325835","pt":1724191570995,"mc":[{"id":"1.231812842","rc":[{"batl":[[0,2.5,1],[1,17.5,5],[2,90,1.02]],"ltp":1.71,"tv":5.31,"id":424679}]}]}
{"op":"mcm","clk":"11886326092","pt":1724191575774,"mc":[{"id":"1.231812842","rc":[{"batl":[[1,17.5,4]],"ltp":1.71,"tv":5.31,"id":424679},{"batl":[[0,3.4,15]],"ltp":1.7,"tv":5.0,"id":424676}]}]}
{"op":"mcm","clk":"11887024600","pt":1724202775083,"mc":[{"id":"1.231812842","tv":12.33}]}
{"op":"mcm","clk":"11887683768","pt":1724224144603,"mc":[{"id":"1.231812842","rc":[{"trd":[[2.5,0.01]],"batl":[[0,17.5,4.99],[1,90,1.02],[2,95,5]],"ltp":2.5,"tv":5.32,"id":424679},{"trd":[[1.72,0.01]],"ltp":1.72,"tv":5.01,"id":424676}],"tv":12.35}]}
{"op":"mcm","clk":"11887683937","pt":1724224149949,"mc":[{"id":"1.231812842","rc":[{"batl":[[0,17,1.99],[1,17.5,4],[2,90,1.02]],"ltp":2.5,"tv":5.32,"id":424679}]}]}
{"op":"mcm","clk":"11887684000","pt":1724224151847,"mc":[{"id":"1.231812842","rc":[{"trd":[[1.5,0.02]],"batb":[[0,1.5,19.99]],"ltp":1.5,"tv":5.34,"id":424679}],"tv":12.37}]}
{"op":"mcm","clk":"11887700383","pt":1724224375099,"mc":[{"id":"1.231812842","tv":12.37}]}
{"op":"mcm","clk":"11887744236","pt":1724225847375,"mc":[{"id":"1.231812842","rc":[{"batl":[[0,17,1]],"ltp":1.5,"tv":5.34,"id":424679}]}]}
{"op":"mcm","clk":"11887744270","pt":1724225848396,"mc":[{"id":"1.231812842","rc":[{"batl":[[0,3.35,1],[1,3.4,15],[2,90,1.02]],"ltp":1.72,"tv":5.01,"id":424676}]}]}
{"op":"mcm","clk":"11887745160","pt":1724225873789,"mc":[{"id":"1.231812842","rc":[{"batl":[[0,16,1],[1,17,1],[2,17.5,4]],"ltp":1.5,"tv":5.34,"id":424679}]}]}
{"op":"mcm","clk":"11887745243","pt":1724225876297,"mc":[{"id":"1.231812842","rc":[{"batl":[[1,17.5,4],[2,90,1.02]],"ltp":1.5,"tv":5.34,"id":424679}]}]}
{"op":"mcm","clk":"11887745410","pt":1724225881834,"mc":[{"id":"1.231812842","rc":[{"batl":[[0,15.5,1],[1,16,1],[2,17.5,4]],"ltp":1.5,"tv":5.34,"id":424679}]}]}
{"op":"mcm","clk":"11888063575","pt":1724232952446,"mc":[{"id":"1.231812842","rc":[{"batb":[[1,1.04,1.53],[2,1.03,200]],"ltp":1.5,"tv":5.34,"id":424679},{"batb":[[2,1.04,1.53]],"ltp":1.72,"tv":5.01,"id":424676},{"batb":[[2,1.04,1.53]],"batl":[[1,180,1.01],[2,870,0.34]],"ltp":90.0,"tv":2.02,"id":60443}],"tv":12.37}]}
{"op":"mcm","clk":"11888064374","pt":1724232964758,"mc":[{"id":"1.231812842","rc":[{"batb":[[2,1.03,283.33]],"ltp":1.5,"tv":5.34,"id":424679},{"batb":[[2,1.04,64.03]],"ltp":1.72,"tv":5.01,"id":424676}]}]}
{"op":"mcm","clk":"11888064415","pt":1724232965331,"mc":[{"id":"1.231812842","rc":[{"batb":[[1,1.08,31.25],[2,1.07,35.71]],"ltp":1.5,"tv":5.34,"id":424679},{"batb":[[2,1.08,31.25]],"ltp":1.72,"tv":5.01,"id":424676},{"batb":[[2,1.08,31.25]],"ltp":90.0,"tv":2.02,"id":60443}]}]}
{"op":"mcm","clk":"11888064717","pt":1724232971065,"mc":[{"id":"1.231812842","rc":[{"batl":[[1,95,5.84],[2,990,5.51]],"ltp":90.0,"tv":2.02,"id":60443}]}]}
{"op":"mcm","clk":"11888225821","pt":1724235175062,"mc":[{"id":"1.231812842","rc":[{"trd":[[1.16,2]],"ltp":1.5,"tv":5.34,"id":424679},{"trd":[[1.16,4]],"batl":[[2,90,1.02]],"ltp":1.72,"tv":5.01,"id":424676},{"trd":[[1.16,2]],"ltp":90.0,"tv":2.01,"id":60443}],"tv":12.37}]}
{"op":"mcm","clk":"11888688597","pt":1724240575093,"mc":[{"id":"1.231812842","tv":12.37}]}
{"op":"mcm","clk":"11888787121","pt":1724241806232,"mc":[{"id":"1.231812842","rc":[{"batl":[[0,15.5,5],[2,90,1.02]],"ltp":1.5,"tv":5.34,"id":424679}]}]}
{"op":"mcm","clk":"11888787639","pt":1724241814440,"mc":[{"id":"1.231812842","rc":[{"batl":[[1,3.5,15]],"ltp":1.72,"tv":5.01,"id":424676}]}]}
{"op":"mcm","clk":"11889081650","pt":1724245975080,"mc":[{"id":"1.231812842","tv":12.37}]}
{"op":"mcm","clk":"11889234255","pt":1724248567017,"mc":[{"id":"1.231812842","rc":[{"batl":[[0,15,1],[1,15.5,5]],"ltp":1.5,"tv":5.34,"id":424679}]}]}
{"op":"mcm","clk":"11889234366","pt":1724248569017,"mc":[{"id":"1.231812842","rc":[{"batl":[[1,15.5,4]],"ltp":1.5,"tv":5.34,"id":424679}]}]}
{"op":"mcm","clk":"11889234608","pt":1724248574657,"mc":[{"id":"1.231812842","rc":[{"batl":[[0,14.5,1],[1,15,1],[2,15.5,4]],"ltp":1.5,"tv":5.34,"id":424679}]}]}
{"op":"mcm","clk":"11889315506","pt":1724249886058,"mc":[{"id":"1.231812842","rc":[{"trd":[[1.16,2]],"ltp":1.5,"tv":5.33,"id":424679},{"trd":[[1.16,4]],"batl":[[0,3.35,1.12]],"ltp":1.72,"tv":5.0,"id":424676},{"trd":[[1.16,2]],"ltp":90.0,"tv":2.01,"id":60443}],"tv":12.36}]}
{"op":"mcm","clk":"11889316451","pt":1724249896573,"mc":[{"id":"1.231812842","rc":[{"batl":[[0,3.35,1.21]],"ltp":1.72,"tv":5.0,"id":424676}]}]}
{"op":"mcm","clk":"11889316782","pt":1724249900864,"mc":[{"id":"1.231812842","rc":[{"batl":[[0,3.35,1.33]],"ltp":1.72,"tv":5.0,"id":424676}]}]}
{"op":"mcm","clk":"11889317379","pt":1724249909356,"mc":[{"id":"1.231812842","rc":[{"batl":[[0,3.35,1.21]],"ltp":1.72,"tv":5.0,"id":424676}]}]}
{"op":"mcm","clk":"11889317523","pt":1724249911465,"mc":[{"id":"1.231812842","rc":[{"batl":[[0,3.35,1]],"ltp":1.72,"tv":5.0,"id":424676}]}]}
{"op":"mcm","clk":"11889466122","pt":1724252081827,"mc":[{"id":"1.231812842","rc":[{"batl":[[2,90,1.15]],"ltp":1.72,"tv":5.0,"id":424676}]}]}
{"op":"mcm","clk":"11889466392","pt":1724252085960,"mc":[{"id":"1.231812842","rc":[{"batl":[[2,90,1.02]],"ltp":1.72,"tv":5.0,"id":424676}]}]}
{"op":"mcm","clk":"11890009562","pt":1724256775103,"mc":[{"id":"1.231812842","tv":12.36}]}
{"op":"mcm","clk":"11890515439","pt":1724260754927,"mc":[{"id":"1.231812842","rc":[{"trd":[[1.16,4]],"batb":[[1,1.5,20]],"ltp":1.72,"tv":5.0,"id":424676}],"tv":12.36}]}
{"op":"mcm","clk":"11890941661","pt":1724264357699,"mc":[{"id":"1.231812842","rc":[{"batl":[[0,12.5,1],[1,14.5,1]],"ltp":1.5,"tv":5.33,"id":424679}],"tv":12.36}]}
{"op":"mcm","clk":"11890942477","pt":1724264362706,"mc":[{"id":"1.231812842","rc":[{"batl":[[1,15.5,4],[2,90,1.02]],"ltp":1.5,"tv":5.33,"id":424679}]}]}
{"op":"mcm","clk":"11890943441","pt":1724264368404,"mc":[{"id":"1.231812842","rc":[{"batl":[[0,12,1],[1,12.5,1],[2,15.5,4]],"ltp":1.5,"tv":5.33,"id":424679}]}]}
{"op":"mcm","clk":"11891435617","pt":1724267575077,"mc":[{"id":"1.231812842","tv":12.36}]}
{"op":"mcm","clk":"11892140233","pt":1724272975059,"mc":[{"id":"1.231812842","rc":[{"trd":[[1.16,4]],"ltp":1.72,"tv":5.0,"id":424676}],"tv":12.36}]}
{"op":"mcm","clk":"11892355417","pt":1724275504981,"mc":[{"id":"1.231812842","rc":[{"batb":[[1,1.5,1],[2,1.3,20]],"ltp":90.0,"tv":2.01,"id":60443}]}]}
{"op":"mcm","clk":"11892356394","pt":1724275515270,"mc":[{"id":"1.231812842","rc":[{"batb":[[1,1.5,21]],"ltp":1.72,"tv":5.0,"id":424676}]}]}
{"op":"mcm","clk":"11892605931","pt":1724278375036,"mc":[{"id":"1.231812842","tv":12.36}]}
{"op":"mcm","clk":"11893078940","pt":1724283775113,"mc":[{"id":"1.231812842","rc":[{"trd":[[1.16,4]],"ltp":1.72,"tv":5.01,"id":424676}],"tv":12.36}]}
{"op":"mcm","clk":"11893271268","pt":1724286666914,"mc":[{"id":"1.231812842","rc":[{"trd":[[1.67,0.02]],"batb":[[0,1.67,1.99]],"ltp":1.67,"tv":5.02,"id":424676}],"tv":12.38}]}
{"op":"mcm","clk":"11893271774","pt":1724286674622,"mc":[{"id":"1.231812842","rc":[{"trd":[[1.5,0.04]],"batb":[[0,1.5,19.98]],"ltp":1.5,"tv":5.35,"id":424679}],"tv":12.4}]}
{"op":"mcm","clk":"11893382369","pt":1724288470345,"mc":[{"id":"1.231812842","rc":[{"trd":[[1.16,4]],"batl":[[0,2,4],[1,3.35,1],[2,3.5,15]],"ltp":1.67,"tv":5.02,"id":424676}],"tv":12.4}]}
{"op":"mcm","clk":"11893382496","pt":1724288472636,"mc":[{"id":"1.231812842","rc":[{"batl":[[1,3.5,15],[2,90,1.02]],"ltp":1.67,"tv":5.02,"id":424676}]}]}
{"op":"mcm","clk":"11894132024","pt":1724305027132,"mc":[{"id":"1.231812842","rc":[{"batl":[[0,12,1.54]],"ltp":1.5,"tv":5.35,"id":424679}]}]}
{"op":"mcm","clk":"11894132343","pt":1724305033157,"mc":[{"id":"1.231812842","rc":[{"batb":[[0,2.12,2.29],[1,1.5,19.98],[2,1.08,31.25]],"ltp":1.5,"tv":5.35,"id":424679}]}]}
{"op":"mcm","clk":"11894132608","pt":1724305038556,"mc":[{"id":"1.231812842","rc":[{"batb":[[1,1.55,4.59],[2,1.5,19.98]],"ltp":1.5,"tv":5.35,"id":424679}]}]}
{"op":"mcm","clk":"11894132964","pt":1724305046164,"mc":[{"id":"1.231812842","rc":[{"batl":[[0,85,1.55]],"ltp":90.0,"tv":2.01,"id":60443}]}]}
{"op":"mcm","clk":"11894134104","pt":1724305070729,"mc":[{"id":"1.231812842","rc":[{"batl":[[0,85,1.17]],"ltp":90.0,"tv":2.01,"id":60443}]}]}
{"op":"mcm","clk":"11894134110","pt":1724305070832,"mc":[{"id":"1.231812842","rc":[{"batl":[[0,85,1.55]],"ltp":90.0,"tv":2.01,"id":60443}]}]}
{"op":"mcm","clk":"11894135763","pt":1724305106268,"mc":[{"id":"1.231812842","rc":[{"batb":[[0,2.12,2.83]],"ltp":1.5,"tv":5.35,"id":424679}]}]}
{"op":"mcm","clk":"11894174478","pt":1724305775814,"mc":[{"id":"1.231812842","rc":[{"batl":[[0,46,1.32],[1,85,1.17],[2,95,5.83]],"ltp":90.0,"tv":2.01,"id":60443}]}]}
{"op":"mcm","clk":"11894174542","pt":1724305778017,"mc":[{"id":"1.231812842","rc":[{"batl":[[1,90,1.01],[2,95,5]],"ltp":90.0,"tv":2.01,"id":60443}]}]}
{"op":"mcm","clk":"11894174705","pt":1724305783554,"mc":[{"id":"1.231812842","rc":[{"batl":[[0,44,1.93],[1,90,1.39]],"ltp":90.0,"tv":2.01,"id":60443}]}]}
{"op":"mcm","clk":"11894232968","pt":1724307386461,"mc":[{"id":"1.231812842","rc":[{"trd":[[2,8]],"batb":[[0,1.67,2.07]],"batl":[[0,3.5,15],[1,90,1.02],[2,95,5]],"ltp":2.0,"tv":13.02,"id":424676}],"tv":20.4}]}
{"op":"mcm","clk":"11894232987","pt":1724307387073,"mc":[{"id":"1.231812842","rc":[{"batl":[[0,3.45,1],[1,3.5,15],[2,90,1.02]],"ltp":2.0,"tv":13.02,"id":424676}]}]}
{"op":"mcm","clk":"11894233134","pt":1724307390877,"mc":[{"id":"1.231812842","rc":[{"batb":[[0,1.67,1.99]],"ltp":2.0,"tv":13.02,"id":424676}]}]}
{"op":"mcm","clk":"11894234928","pt":1724307433838,"mc":[{"id":"1.231812842","rc":[{"batl":[[0,2.64,3.04],[1,3.45,1],[2,3.5,15]],"ltp":2.0,"tv":13.02,"id":424676}]}]}
{"op":"mcm","clk":"11894235048","pt":1724307437330,"mc":[{"id":"1.231812842","rc":[{"batl":[[1,3.5,15],[2,90,1.02]],"ltp":2.0,"tv":13.02,"id":424676}]}]}
{"op":"mcm","clk":"11894235141","pt":1724307439630,"mc":[{"id":"1.231812842","rc":[{"batl":[[0,3.5,15],[1,90,1.02],[2,95,5]],"ltp":2.0,"tv":13.02,"id":424676}]}]}
{"op":"mcm","clk":"11894235149","pt":1724307439829,"mc":[{"id":"1.231812842","rc":[{"batl":[[0,2.64,3.04],[1,3.5,15],[2,90,1.02]],"ltp":2.0,"tv":13.02,"id":424676}]}]}
{"op":"mcm","clk":"11894289898","pt":1724308834506,"mc":[{"id":"1.231812842","rc":[{"batb":[[1,1.8,4.59]],"ltp":1.5,"tv":5.35,"id":424679}]}]}
{"op":"mcm","clk":"11894290222","pt":1724308841890,"mc":[{"id":"1.231812842","rc":[{"batl":[[0,36,1.32],[1,44,1],[2,90,1.01]],"ltp":90.0,"tv":2.01,"id":60443}]}]}
{"op":"mcm","clk":"11894290338","pt":1724308845987,"mc":[{"id":"1.231812842","rc":[{"batl":[[1,90,1.01],[2,95,5]],"ltp":90.0,"tv":2.01,"id":60443}]}]}
{"op":"mcm","clk":"11894290558","pt":1724308851615,"mc":[{"id":"1.231812842","rc":[{"batl":[[0,34,1.93],[1,90,1.39]],"ltp":90.0,"tv":2.01,"id":60443}]}]}
{"op":"mcm","clk":"11894290774","pt":1724308856952,"mc":[{"id":"1.231812842","rc":[{"batl":[[0,16,1.47],[1,34,1],[2,90,1.39]],"ltp":90.0,"tv":2.01,"id":60443}]}]}
{"op":"mcm","clk":"11894290962","pt":1724308862743,"mc":[{"id":"1.231812842","rc":[{"batl":[[1,90,1.39],[2,95,5]],"ltp":90.0,"tv":2.01,"id":60443}]}]}
{"op":"mcm","clk":"11894291167","pt":1724308868232,"mc":[{"id":"1.231812842","rc":[{"batl":[[0,15.5,1.54],[1,28,1.32],[2,90,1.01]],"ltp":90.0,"tv":2.01,"id":60443}]}]}
{"op":"mcm","clk":"11894377688","pt":1724310775059,"mc":[{"id":"1.231812842","rc":[{"batb":[[0,2.12,2.83],[1,1.8,4.58]],"ltp":1.5,"tv":5.35,"id":424679},{"trd":[[2,8]],"batl":[[0,2.64,3.03]],"ltp":2.0,"tv":13.02,"id":424676}],"tv":20.4}]}
{"op":"mcm","clk":"11894531431","pt":1724314872860,"mc":[{"id":"1.231812842","rc":[{"trd":[[1.16,2]],"batb":[[0,2.5,100],[1,2.12,2.83],[2,1.8,4.58]],"ltp":1.5,"tv":5.35,"id":424679},{"trd":[[1.16,4],[2,8]],"batl":[[2,90,1.02]],"ltp":2.0,"tv":13.02,"id":424676},{"trd":[[1.16,2]],"batb":[[0,2,25.85]],"batl":[[2,90,1]],"ltp":90.0,"tv":2.01,"id":60443}],"tv":20.39}]}
{"op":"mcm","clk":"11894532968","pt":1724314907602,"mc":[{"id":"1.231812842","rc":[{"batb":[[0,2.12,2.83],[1,1.8,4.58],[2,1.5,19.98]],"ltp":1.5,"tv":5.35,"id":424679}]}]}
{"op":"mcm","clk":"11894533390","pt":1724314916905,"mc":[{"id":"1.231812842","rc":[{"batb":[[0,3.25,100],[1,2.12,2.83],[2,1.8,4.58]],"ltp":1.5,"tv":5.35,"id":424679}]}]}
{"op":"mcm","clk":"11894603496","pt":1724316182002,"mc":[{"id":"1.231812842","rc":[{"trd":[[3.25,2]],"batb":[[0,3.25,99]],"ltp":3.25,"tv":7.35,"id":424679}],"tv":22.39}]}
{"op":"mcm","clk":"11894604174","pt":1724316194783,"mc":[{"id":"1.231812842","rc":[{"batl":[[0,4,1],[1,12,1.53],[2,12.5,1]],"ltp":3.25,"tv":7.35,"id":424679}]}]}
{"op":"mcm","clk":"11894604223","pt":1724316195804,"mc":[{"id":"1.231812842","rc":[{"batl":[[1,12.5,1.53],[2,15.5,4]],"ltp":3.25,"tv":7.35,"id":424679}]}]}
{"op":"mcm","clk":"11894635989","pt":1724316769037,"mc":[{"id":"1.231812842","rc":[{"batl":[[0,15.5,2.47],[1,90,1.39],[2,95,5]],"ltp":90.0,"tv":2.01,"id":60443}]}]}
{"op":"mcm","clk":"11894658679","pt":1724317257663,"mc":[{"id":"1.231812842","rc":[{"batb":[[1,2.12,2.82],[2,1.8,4.58]],"ltp":3.25,"tv":7.35,"id":424679},{"trd":[[1.16,3.99],[2,7.99]],"batl":[[0,2.64,3.33]],"ltp":2.0,"tv":13.01,"id":424676},{"batl":[[0,15.5,2.77],[1,90,1.38]],"ltp":90.0,"tv":2.01,"id":60443}],"tv":22.38}]}
{"op":"mcm","clk":"11894658693","pt":1724317258026,"mc":[{"id":"1.231812842","rc":[{"batb":[[0,1.67,2.29]],"ltp":2.0,"tv":13.01,"id":424676},{"batb":[[0,2.46,1.15],[1,2,25],[2,1.5,1]],"ltp":90.0,"tv":2.01,"id":60443}]}]}
{"op":"mcm","clk":"11894658753","pt":1724317259628,"mc":[{"id":"1.231812842","rc":[{"batl":[[0,15.5,1.77]],"ltp":90.0,"tv":2.01,"id":60443}]}]}
{"op":"mcm","clk":"11894659276","pt":1724317270643,"mc":[{"id":"1.231812842","rc":[{"batl":[[0,14.5,1.53],[1,15.5,1.23],[2,90,1.38]],"ltp":90.0,"tv":2.01,"id":60443}]}]}
{"op":"mcm","clk":"11894672364","pt":1724317562695,"mc":[{"id":"1.231812842","rc":[{"batl":[[0,2.64,3.03]],"ltp":2.0,"tv":13.01,"id":424676},{"batl":[[1,28,1.31],[2,90,1]],"ltp":90.0,"tv":2.01,"id":60443}]}]}
{"op":"mcm","clk":"11894672575","pt":1724317566632,"mc":[{"id":"1.231812842","rc":[{"batb":[[0,1.67,2.59]],"batl":[[0,2.64,3.33]],"ltp":2.0,"tv":13.01,"id":424676},{"batb":[[0,2.46,1.45]],"batl":[[0,14.5,1.83]],"ltp":90.0,"tv":2.01,"id":60443}]}]}
{"op":"mcm","clk":"11894672858","pt":1724317571425,"mc":[{"id":"1.231812842","rc":[{"batb":[[0,1.67,2.29]],"ltp":2.0,"tv":13.01,"id":424676},{"batb":[[0,2.46,1.15]],"batl":[[0,15.5,1.77],[1,90,1.38],[2,95,5]],"ltp":90.0,"tv":2.01,"id":60443}]}]}
{"op":"mcm","clk":"11894673399","pt":1724317582505,"mc":[{"id":"1.231812842","rc":[{"batl":[[0,13.5,1],[1,15.5,1.77],[2,90,1.38]],"ltp":90.0,"tv":2.01,"id":60443}]}]}
{"op":"mcm","clk":"11894674853","pt":1724317614342,"mc":[{"id":"1.231812842","rc":[{"batl":[[0,2.5,1],[1,2.64,3.33],[2,3.5,15]],"ltp":2.0,"tv":13.01,"id":424676}]}]}
{"op":"mcm","clk":"11894677863","pt":1724317678040,"mc":[{"id":"1.231812842","rc":[{"batb":[[0,1.68,20.3],[1,1.67,1.99],[2,1.5,21]],"ltp":2.0,"tv":13.01,"id":424676}]}]}
{"op":"mcm","clk":"11894678094","pt":1724317682924,"mc":[{"id":"1.231812842","rc":[{"batl":[[0,15.5,1.77],[1,90,1.38],[2,95,5]],"ltp":90.0,"tv":2.01,"id":60443}]}]}
{"op":"mcm","clk":"11894678386","pt":1724317688332,"mc":[{"id":"1.231812842","rc":[{"batl":[[0,10,1],[1,15.5,1.77],[2,90,1.38]],"ltp":90.0,"tv":2.01,"id":60443}]}]}
{"op":"mcm","clk":"11894678845","pt":1724317697764,"mc":[{"id":"1.231812842","rc":[{"batb":[[0,3.35,20],[1,3.25,99],[2,2.12,2.82]],"ltp":3.25,"tv":7.35,"id":424679}]}]}
{"op":"mcm","clk":"11894678948","pt":1724317699568,"mc":[{"id":"1.231812842","rc":[{"batl":[[0,15.5,1.77],[1,90,1.38],[2,95,5]],"ltp":90.0,"tv":2.01,"id":60443}]}]}
{"op":"mcm","clk":"11894679118","pt":1724317702742,"mc":[{"id":"1.231812842","rc":[{"trd":[[4,2]],"batb":[[0,4,2.8],[1,3.35,20],[2,3.25,99]],"batl":[[0,12.5,1.53],[1,15.5,4],[2,90,1.02]],"ltp":4.0,"tv":9.35,"id":424679}],"tv":24.38}]}
{"op":"mcm","clk":"11894679186","pt":1724317704071,"mc":[{"id":"1.231812842","rc":[{"batl":[[0,12.5,1.83]],"ltp":4.0,"tv":9.35,"id":424679}]}]}
{"op":"mcm","clk":"11894679261","pt":1724317705160,"mc":[{"id":"1.231812842","rc":[{"batl":[[0,12,1.83],[1,12.5,1],[2,15.5,4]],"ltp":4.0,"tv":9.35,"id":424679},{"batl":[[0,6.4,1],[1,15.5,1.77],[2,90,1.38]],"ltp":90.0,"tv":2.01,"id":60443}]}]}
{"op":"mcm","clk":"11894679339","pt":1724317706344,"mc":[{"id":"1.231812842","rc":[{"batl":[[0,4.9,5],[1,6.4,1],[2,15.5,1.77]],"ltp":90.0,"tv":2.01,"id":60443}]}]}
{"op":"mcm","clk":"11894679761","pt":1724317714570,"mc":[{"id":"1.231812842","rc":[{"batb":[[0,4,3.1]],"ltp":4.0,"tv":9.35,"id":424679}]}]}
{"op":"mcm","clk":"11894679833","pt":1724317716275,"mc":[{"id":"1.231812842","rc":[{"batl":[[1,15.5,1.77],[2,90,1.38]],"ltp":90.0,"tv":2.01,"id":60443}]}]}
{"op":"mcm","clk":"11894680243","pt":1724317725376,"mc":[{"id":"1.231812842","rc":[{"batb":[[0,4.1,20.3],[1,4,2.8]],"ltp":4.0,"tv":9.35,"id":424679}]}]}
{"op":"mcm","clk":"11894680351","pt":1724317727689,"mc":[{"id":"1.231812842","rc":[{"batl":[[1,28,1.22],[2,90,1]],"ltp":90.0,"tv":2.01,"id":60443}]}]}
{"op":"mcm","clk":"11894687173","pt":1724317858693,"mc":[{"id":"1.231812842","rc":[{"batl":[[0,2.5,1.3]],"ltp":2.0,"tv":13.01,"id":424676},{"batl":[[0,4.9,5.3]],"ltp":90.0,"tv":2.01,"id":60443}]}]}
{"op":"mcm","clk":"11894687179","pt":1724317858795,"mc":[{"id":"1.231812842","rc":[{"batb":[[0,1.68,20.6]],"ltp":2.0,"tv":13.01,"id":424676},{"batb":[[0,2.46,1.45]],"ltp":90.0,"tv":2.01,"id":60443}]}]}
{"op":"mcm","clk":"11894687615","pt":1724317867608,"mc":[{"id":"1.231812842","rc":[{"batb":[[0,2.46,1.15]],"ltp":90.0,"tv":2.01,"id":60443}]}]}
{"op":"mcm","clk":"11894687642","pt":1724317868385,"mc":[{"id":"1.231812842","rc":[{"batb":[[0,1.68,20.3]],"ltp":2.0,"tv":13.01,"id":424676}]}]}
{"op":"mcm","clk":"11894687706","pt":1724317869603,"mc":[{"id":"1.231812842","rc":[{"batl":[[1,2.64,3.03]],"ltp":2.0,"tv":13.01,"id":424676},{"batl":[[1,48,1.08],[2,95,5.83]],"ltp":90.0,"tv":2.01,"id":60443}]}]}
{"op":"mcm","clk":"11894694667","pt":1724318016238,"mc":[{"id":"1.231812842","rc":[{"batl":[[0,12,1.53]],"ltp":4.0,"tv":9.35,"id":424679}]}]}
{"op":"mcm","clk":"11894695010","pt":1724318023761,"mc":[{"id":"1.231812842","rc":[{"batl":[[0,12,1.83]],"ltp":4.0,"tv":9.35,"id":424679}]}]}
{"op":"mcm","clk":"11894695062","pt":1724318024737,"mc":[{"id":"1.231812842","rc":[{"batb":[[0,4.1,20]],"ltp":4.0,"tv":9.35,"id":424679}]}]}
{"op":"mcm","clk":"11894695479","pt":1724318034688,"mc":[{"id":"1.231812842","rc":[{"batb":[[0,4.1,20.3]],"ltp":4.0,"tv":9.35,"id":424679}]}]}
{"op":"mcm","clk":"11894700705","pt":1724318140674,"mc":[{"id":"1.231812842","rc":[{"batl":[[0,2.5,1.6]],"ltp":2.0,"tv":13.01,"id":424676},{"batl":[[0,4.9,5.6]],"ltp":90.0,"tv":2.01,"id":60443}]}]}
{"op":"mcm","clk":"11894700723","pt":1724318140983,"mc":[{"id":"1.231812842","rc":[{"batb":[[0,1.68,20.6]],"ltp":2.0,"tv":13.01,"id":424676},{"batb":[[0,2.46,1.45]],"ltp":90.0,"tv":2.01,"id":60443}]}]}
{"op":"mcm","clk":"11894700820","pt":1724318142683,"mc":[{"id":"1.231812842","rc":[{"batb":[[0,2.46,1.15]],"ltp":90.0,"tv":2.01,"id":60443}]}]}
{"op":"mcm","clk":"11894700832","pt":1724318142886,"mc":[{"id":"1.231812842","rc":[{"batb":[[0,1.68,20.3]],"ltp":2.0,"tv":13.01,"id":424676}]}]}
{"op":"mcm","clk":"11894700898","pt":1724318144582,"mc":[{"id":"1.231812842","rc":[{"batl":[[0,2.5,1.3]],"ltp":2.0,"tv":13.01,"id":424676},{"batl":[[0,4.9,5.3]],"ltp":90.0,"tv":2.01,"id":60443}]}]}
{"op":"mcm","clk":"11894709899","pt":1724318336920,"mc":[{"id":"1.231812842","rc":[{"batl":[[0,12,1.53]],"ltp":4.0,"tv":9.35,"id":424679}]}]}
{"op":"mcm","clk":"11894710453","pt":1724318346613,"mc":[{"id":"1.231812842","rc":[{"batl":[[0,12,1.83]],"ltp":4.0,"tv":9.35,"id":424679}]}]}
{"op":"mcm","clk":"11894715625","pt":1724318456740,"mc":[{"id":"1.231812842","rc":[{"batb":[[0,1.68,20]],"batl":[[0,2.5,1.6]],"ltp":2.0,"tv":13.01,"id":424676},{"batl":[[0,4.9,5.6]],"ltp":90.0,"tv":2.01,"id":60443}]}]}
{"op":"mcm","clk":"11894715642","pt":1724318457050,"mc":[{"id":"1.231812842","rc":[{"batb":[[0,1.68,20.3]],"ltp":2.0,"tv":13.01,"id":424676},{"batb":[[0,2.46,1.45]],"ltp":90.0,"tv":2.01,"id":60443}]}]}
{"op":"mcm","clk":"11894715689","pt":1724318458448,"mc":[{"id":"1.231812842","rc":[{"batb":[[0,2.46,1.15]],"ltp":90.0,"tv":2.01,"id":60443}]}]}
{"op":"mcm","clk":"11894715718","pt":1724318459434,"mc":[{"id":"1.231812842","rc":[{"batl":[[0,2.5,1.3]],"ltp":2.0,"tv":13.01,"id":424676},{"batl":[[0,4.9,5.3]],"ltp":90.0,"tv":2.01,"id":60443}]}]}
{"op":"mcm","clk":"11894719705","pt":1724318564087,"mc":[{"id":"1.231812842","rc":[{"batb":[[2,2.12,2.82]],"ltp":4.0,"tv":9.35,"id":424679}]}]}
{"op":"mcm","clk":"11894723716","pt":1724318656182,"mc":[{"id":"1.231812842","rc":[{"batb":[[0,4.1,20]],"batl":[[0,12,1.53]],"ltp":4.0,"tv":9.35,"id":424679}]}]}
{"op":"mcm","clk":"11894723766","pt":1724318657380,"mc":[{"id":"1.231812842","rc":[{"batb":[[0,4.1,20.3]],"batl":[[0,12,1.83]],"ltp":4.0,"tv":9.35,"id":424679}]}]}
{"op":"mcm","clk":"11894726247","pt":1724318715953,"mc":[{"id":"1.231812842","rc":[{"batb":[[0,4.4,2.8],[1,4.1,20.3]],"ltp":4.0,"tv":9.35,"id":424679}]}]}
{"op":"mcm","clk":"11894728600","pt":1724318773542,"mc":[{"id":"1.231812842","rc":[{"batb":[[0,1.68,20.6]],"batl":[[0,2.5,1.6]],"ltp":2.0,"tv":13.01,"id":424676},{"batb":[[0,2.46,1.45]],"batl":[[0,4.9,5.6]],"ltp":90.0,"tv":2.01,"id":60443}]}]}
{"op":"mcm","clk":"11894728645","pt":1724318774624,"mc":[{"id":"1.231812842","rc":[{"batb":[[0,2.46,1.15]],"ltp":90.0,"tv":2.01,"id":60443}]}]}
{"op":"mcm","clk":"11894728656","pt":1724318774830,"mc":[{"id":"1.231812842","rc":[{"batb":[[0,1.68,20.3]],"ltp":2.0,"tv":13.01,"id":424676}]}]}
{"op":"mcm","clk":"11894728725","pt":1724318776731,"mc":[{"id":"1.231812842","rc":[{"batl":[[0,2.5,1.3]],"ltp":2.0,"tv":13.01,"id":424676},{"batl":[[0,4.9,5.3]],"ltp":90.0,"tv":2.01,"id":60443}]}]}
{"op":"mcm","clk":"11894737127","pt":1724318964542,"mc":[{"id":"1.231812842","rc":[{"batb":[[0,4.4,3.1],[1,4.1,20]],"ltp":4.0,"tv":9.35,"id":424679}]}]}
{"op":"mcm","clk":"11894743003","pt":1724319093202,"mc":[{"id":"1.231812842","rc":[{"batb":[[0,1.68,20.6]],"batl":[[0,2.5,1.6]],"ltp":2.0,"tv":13.01,"id":424676},{"batb":[[0,2.46,1.45]],"batl":[[0,4.9,5.6]],"ltp":90.0,"tv":2.01,"id":60443}]}]}
{"op":"mcm","clk":"11894743272","pt":1724319099505,"mc":[{"id":"1.231812842","rc":[{"batb":[[0,1.68,20.3]],"ltp":2.0,"tv":13.01,"id":424676},{"batb":[[0,2.46,1.15]],"ltp":90.0,"tv":2.01,"id":60443}]}]}
{"op":"mcm","clk":"11894743382","pt":1724319102218,"mc":[{"id":"1.231812842","rc":[{"batl":[[0,2.5,1.3]],"ltp":2.0,"tv":13.01,"id":424676},{"batl":[[0,4.9,5.3]],"ltp":90.0,"tv":2.01,"id":60443}]}]}
{"op":"mcm","clk":"11894749456","pt":1724319232169,"mc":[{"id":"1.231812842","rc":[{"batb":[[0,4.4,2.8]],"batl":[[0,12,1.53]],"ltp":4.0,"tv":9.35,"id":424679}]}]}
{"op":"mcm","clk":"11894749643","pt":1724319235880,"mc":[{"id":"1.231812842","rc":[{"batb":[[0,4.4,3.1]],"batl":[[0,12,1.83]],"ltp":4.0,"tv":9.35,"id":424679}]}]}
{"op":"mcm","clk":"11894757263","pt":1724319393162,"mc":[{"id":"1.231812842","rc":[{"batb":[[0,4.5,20.3],[1,4.4,2.8]],"ltp":4.0,"tv":9.35,"id":424679}]}]}
{"op":"mcm","clk":"11894758008","pt":1724319406149,"mc":[{"id":"1.231812842","rc":[{"batb":[[0,1.68,20.6]],"batl":[[0,2.5,1.6]],"ltp":2.0,"tv":13.01,"id":424676},{"batb":[[0,2.46,1.45]],"batl":[[0,4.9,5.6]],"ltp":90.0,"tv":2.01,"id":60443}]}]}
{"op":"mcm","clk":"11894762870","pt":1724319495496,"mc":[{"id":"1.231812842","rc":[{"batb":[[0,1.68,20.3]],"ltp":2.0,"tv":13.01,"id":424676},{"batb":[[0,2.46,1.15]],"ltp":90.0,"tv":2.01,"id":60443}]}]}
{"op":"mcm","clk":"11894762930","pt":1724319496474,"mc":[{"id":"1.231812842","rc":[{"batl":[[0,2.5,1.3]],"ltp":2.0,"tv":13.01,"id":424676},{"batl":[[0,4.9,5.3]],"ltp":90.0,"tv":2.01,"id":60443}]}]}
{"op":"mcm","clk":"11894765341","pt":1724319544607,"mc":[{"id":"1.231812842","rc":[{"batb":[[0,4.5,20]],"batl":[[0,12,1.53]],"ltp":4.0,"tv":9.35,"id":424679}]}]}
{"op":"mcm","clk":"11894774172","pt":1724319709214,"mc":[{"id":"1.231812842","rc":[{"batb":[[0,1.68,20.6]],"batl":[[0,2.5,1.6]],"ltp":2.0,"tv":13.01,"id":424676},{"batb":[[0,2.46,1.45]],"batl":[[0,4.9,5.6]],"ltp":90.0,"tv":2.01,"id":60443}]}]}
{"op":"mcm","clk":"11894780162","pt":1724319818720,"mc":[{"id":"1.231812842","rc":[{"batb":[[0,1.68,20.3]],"ltp":2.0,"tv":13.01,"id":424676}]}]}
{"op":"mcm","clk":"11894780237","pt":1724319820215,"mc":[{"id":"1.231812842","rc":[{"batb":[[0,2.46,1.15]],"ltp":90.0,"tv":2.01,"id":60443}]}]}
{"op":"mcm","clk":"11894780305","pt":1724319821556,"mc":[{"id":"1.231812842","rc":[{"batl":[[0,2.5,1.3]],"ltp":2.0,"tv":13.01,"id":424676},{"batl":[[0,4.9,5.3]],"ltp":90.0,"tv":2.01,"id":60443}]}]}
{"op":"mcm","clk":"11894782092","pt":1724319864367,"mc":[{"id":"1.231812842","rc":[{"batl":[[2,180,1]],"ltp":90.0,"tv":2.01,"id":60443}]}]}
{"op":"mcm","clk":"11894788057","pt":1724319987713,"mc":[{"id":"1.231812842","rc":[{"batl":[[0,5,1],[1,6,1],[2,8,1]],"ltp":4.0,"tv":9.35,"id":424679},{"batl":[[1,5,1],[2,6,1]],"ltp":90.0,"tv":2.01,"id":60443}]}]}
{"op":"mcm","clk":"11894788103","pt":1724319988426,"mc":[{"id":"1.231812842","rc":[{"trd":[[4.5,4]],"batb":[[0,4.5,18]],"ltp":4.5,"tv":13.35,"id":424679},{"batl":[[2,3.5,16]],"ltp":2.0,"tv":13.01,"id":424676},{"batl":[[0,3.5,1],[1,4,1],[2,4.9,5.3]],"ltp":90.0,"tv":2.01,"id":60443}],"tv":28.38}]}
{"op":"mcm","clk":"11894788164","pt":1724319989202,"mc":[{"id":"1.231812842","rc":[{"batb":[[2,2.82,1.42]],"ltp":4.5,"tv":13.35,"id":424679}]}]}
{"op":"mcm","clk":"11894788220","pt":1724319990495,"mc":[{"id":"1.231812842","rc":[{"batl":[[0,2.5,1]],"ltp":2.0,"tv":13.01,"id":424676},{"batl":[[2,4.9,5]],"ltp":90.0,"tv":2.01,"id":60443}]}]}
{"op":"mcm","clk":"11894788678","pt":1724319998230,"mc":[{"id":"1.231812842","rc":[{"batb":[[0,1.68,20]],"ltp":2.0,"tv":13.01,"id":424676},{"batb":[[0,2,25.85],[1,1.5,1],[2,1.3,20]],"ltp":90.0,"tv":2.01,"id":60443}]}]}
{"op":"mcm","clk":"11894788764","pt":1724320000026,"mc":[{"id":"1.231812842","rc":[{"batl":[[0,2.5,1.3]],"ltp":2.0,"tv":13.01,"id":424676},{"batb":[[0,2.46,1.15],[1,2,25],[2,1.5,1]],"ltp":90.0,"tv":2.01,"id":60443}]}]}
{"op":"mcm","clk":"11894799626","pt":1724320214747,"mc":[{"id":"1.231812842","rc":[{"batb":[[0,1.67,1.99],[1,1.5,21],[2,1.08,31.25]],"ltp":2.0,"tv":13.01,"id":424676}]}]}
{"op":"mcm","clk":"11894799634","pt":1724320214851,"mc":[{"id":"1.231812842","rc":[{"batb":[[0,2,20],[1,1.67,1.99],[2,1.5,21]],"ltp":2.0,"tv":13.01,"id":424676}]}]}
{"op":"mcm","clk":"11894799727","pt":1724320216467,"mc":[{"id":"1.231812842","rc":[{"trd":[[2,9.99]],"batb":[[0,2,19]],"ltp":2.0,"tv":15.01,"id":424676}],"tv":30.38}]}
{"op":"mcm","clk":"11894800264","pt":1724320227260,"mc":[{"id":"1.231812842","rc":[{"batb":[[2,4.3,5.89]],"ltp":4.5,"tv":13.35,"id":424679},{"batl":[[1,2.62,12],[2,2.64,15.03]],"ltp":2.0,"tv":15.01,"id":424676},{"batb":[[1,2.4,10.56],[2,2,43]],"ltp":90.0,"tv":2.01,"id":60443}]}]}
{"op":"mcm","clk":"11894800333","pt":1724320228757,"mc":[{"id":"1.231812842","rc":[{"batl":[[0,3.45,5],[1,3.5,1],[2,4,1]],"ltp":90.0,"tv":2.01,"id":60443}]}]}
{"op":"mcm","clk":"11894800408","pt":1724320230499,"mc":[{"id":"1.231812842","rc":[{"batb":[[1,4.4,8.05]],"ltp":4.5,"tv":13.35,"id":424679},{"batb":[[1,1.96,18.59],[2,1.67,1.99]],"ltp":2.0,"tv":15.01,"id":424676},{"batb":[[2,2.2,14.87]],"ltp":90.0,"tv":2.01,"id":60443}]}]}
{"op":"mcm","clk":"11894803674","pt":1724320295252,"mc":[{"id":"1.231812842","rc":[{"batb":[[0,2.4,11.41],[1,2.2,14.87],[2,2,43]],"ltp":90.0,"tv":2.01,"id":60443}]}]}
{"op":"mcm","clk":"11894804281","pt":1724320306554,"mc":[{"id":"1.231812842","rc":[{"batl":[[0,2.5,1]],"ltp":2.0,"tv":15.01,"id":424676}]}]}
{"op":"mcm","clk":"11894814793","pt":1724320506079,"mc":[{"id":"1.231812842","rc":[{"batb":[[2,4.3,8.95]],"ltp":4.5,"tv":13.35,"id":424679},{"batb":[[2,1.9,6.93]],"ltp":2.0,"tv":15.01,"id":424676},{"batb":[[1,2.34,5.63],[2,2.2,14.87]],"ltp":90.0,"tv":2.01,"id":60443}]}]}
{"op":"mcm","clk":"11894814883","pt":1724320507682,"mc":[{"id":"1.231812842","rc":[{"batb":[[1,2.34,18.94],[2,2,43]],"ltp":90.0,"tv":2.01,"id":60443}]}]}
{"op":"mcm","clk":"11894821702","pt":1724320632528,"mc":[{"id":"1.231812842","rc":[{"batl":[[0,2.04,1],[1,2.5,1],[2,2.62,12]],"ltp":2.0,"tv":15.01,"id":424676}]}]}
{"op":"mcm","clk":"11894826454","pt":1724320712491,"mc":[{"id":"1.231812842","rc":[{"batb":[[0,2.5,25],[1,2.4,11.41],[2,2.34,18.94]],"ltp":90.0,"tv":2.01,"id":60443}]}]}
{"op":"mcm","clk":"11894826581","pt":1724320714814,"mc":[{"id":"1.231812842","rc":[{"batb":[[1,2.48,12.06],[2,2.4,11.41]],"ltp":90.0,"tv":2.01,"id":60443}]}]}
{"op":"mcm","clk":"11894829228","pt":1724320762440,"mc":[{"id":"1.231812842","rc":[{"batb":[[1,1.9,6.93],[2,1.67,1.99]],"ltp":2.0,"tv":15.01,"id":424676},{"trd":[[3.45,10]],"batl":[[0,3.5,1],[1,4,1],[2,5,1]],"ltp":3.45,"tv":12.01,"id":60443}],"tv":40.38}]}
{"op":"mcm","clk":"11894829245","pt":1724320762849,"mc":[{"id":"1.231812842","rc":[{"batb":[[1,1.9,26.75]],"ltp":2.0,"tv":15.01,"id":424676}]}]}
{"op":"mcm","clk":"11894831526","pt":1724320802648,"mc":[{"id":"1.231812842","marketDefinition":{"bspMarket":false,"turnInPlayEnabled":true,"persistenceEnabled":true,"marketBaseRate":5.0,"eventId":"33494847","eventTypeId":"4","numberOfWinners":1,"bettingType":"ODDS","marketType":"MATCH_ODDS","marketTime":"2024-08-22T10:00:00.000Z","suspendTime":"2024-08-22T10:00:00.000Z","bspReconciled":false,"complete":true,"inPlay":true,"crossMatching":true,"runnersVoidable":false,"numberOfActiveRunners":3,"betDelay":5,"status":"OPEN","runners":[{"status":"ACTIVE","sortPriority":1,"id":424676,"name":"Surrey"},{"status":"ACTIVE","sortPriority":2,"id":424679,"name":"Lancashire"},{"status":"ACTIVE","sortPriority":3,"id":60443,"name":"The Draw"}],"regulators":["MR_INT"],"countryCode":"GB","discountAllowed":true,"timezone":"GMT","openDate":"2024-08-22T10:00:00.000Z","version":6090703681,"name":"Match Odds","eventName":"Surrey v Lancashire"},"rc":[{"batb":[[0,2.82,1.42],[1,2.62,1.33],[2,2.12,2.82]],"ltp":4.5,"tv":13.35,"id":424679},{"batb":[[0,1.5,20],[1,1.08,31.25],[2,1.07,35.71]],"batl":[[0,2.64,3.03],[1,3.5,16],[2,4,1]],"ltp":2.0,"tv":15.01,"id":424676},{"batb":[[1,1.3,20],[2,1.08,31.25]],"ltp":3.45,"tv":12.01,"id":60443}]}]}
{"op":"mcm","clk":"11894832543","pt":1724320817750,"mc":[{"id":"1.231812842","rc":[{"batb":[[2,2.12,2.82]],"ltp":4.5,"tv":13.35,"id":424679},{"trd":[[1.16,3.99],[2,9.99]],"batl":[[0,2.64,3.03]],"ltp":2.0,"tv":15.0,"id":424676}],"tv":40.37}]}
{"op":"mcm","clk":"11894833748","pt":1724320836423,"mc":[{"id":"1.231812842","rc":[{"trd":[[5,2]],"batl":[[0,6,1],[1,8,1],[2,10,1]],"ltp":5.0,"tv":15.35,"id":424679}],"tv":42.37}]}
{"op":"mcm","clk":"11894834333","pt":1724320845678,"mc":[{"id":"1.231812842","rc":[{"batl":[[0,5.9,1],[1,6,1],[2,8,1]],"ltp":5.0,"tv":15.35,"id":424679}]}]}
{"op":"mcm","clk":"11894834376","pt":1724320846352,"mc":[{"id":"1.231812842","rc":[{"batb":[[0,3.05,1.64],[1,2.82,1.42],[2,2.62,1.33]],"ltp":5.0,"tv":15.35,"id":424679}]}]}
{"op":"mcm","clk":"11894834566","pt":1724320849341,"mc":[{"id":"1.231812842","rc":[{"trd":[[5.9,2]],"batl":[[0,6,1],[1,8,1],[2,10,1]],"ltp":5.9,"tv":17.35,"id":424679}],"tv":44.37}]}
{"op":"mcm","clk":"11894834770","pt":1724320852752,"mc":[{"id":"1.231812842","rc":[{"batb":[[2,1.07,36.71]],"ltp":2.0,"tv":15.0,"id":424676}]}]}
{"op":"mcm","clk":"11894834802","pt":1724320853267,"mc":[{"id":"1.231812842","rc":[{"batb":[[2,1.07,35.71]],"ltp":2.0,"tv":15.0,"id":424676}]}]}
{"op":"mcm","clk":"11894835101","pt":1724320858350,"mc":[{"id":"1.231812842","rc":[{"batl":[[0,6,1.3]],"ltp":5.9,"tv":17.35,"id":424679},{"batb":[[0,1.5,20.3]],"ltp":2.0,"tv":15.0,"id":424676}]}]}
{"op":"mcm","clk":"11894835367","pt":1724320862275,"mc":[{"id":"1.231812842","rc":[{"batb":[[0,3.1,1.9],[1,3.05,1.64],[2,2.82,1.42]],"ltp":5.9,"tv":17.35,"id":424679}]}]}
{"op":"mcm","clk":"11894835714","pt":1724320867862,"mc":[{"id":"1.231812842","rc":[{"trd":[[5.8,0.6],[6,1.4]],"batl":[[0,8,1.3],[1,10,1],[2,15,1.53]],"ltp":6.0,"tv":19.35,"id":424679}],"tv":46.37}]}
{"op":"mcm","clk":"11894836074","pt":1724320873486,"mc":[{"id":"1.231812842","rc":[{"batl":[[0,7.8,1.3],[1,8,1],[2,10,1]],"ltp":6.0,"tv":19.35,"id":424679}]}]}
{"op":"mcm","clk":"11894836227","pt":1724320876482,"mc":[{"id":"1.231812842","rc":[{"batb":[[0,3.55,1.18],[1,3.1,1.9],[2,3.05,1.64]],"ltp":6.0,"tv":19.35,"id":424679}]}]}
{"op":"mcm","clk":"11894836411","pt":1724320879686,"mc":[{"id":"1.231812842","rc":[{"batb":[[1,3.05,1.64],[2,2.82,1.42]],"ltp":6.0,"tv":19.35,"id":424679}]}]}
{"op":"mcm","clk":"11894837157","pt":1724320890195,"mc":[{"id":"1.231812842","rc":[{"batb":[[0,3.6,1.64],[1,3.55,1.18],[2,3.05,1.64]],"ltp":6.0,"tv":19.35,"id":424679}]}]}
{"op":"mcm","clk":"11894838503","pt":1724320912261,"mc":[{"id":"1.231812842","rc":[{"batl":[[0,2.64,3.33]],"ltp":2.0,"tv":15.0,"id":424676}]}]}
{"op":"mcm","clk":"11894847475","pt":1724321059110,"mc":[{"id":"1.231812842","rc":[{"trd":[[3.6,3.28]],"batb":[[0,3.55,1.18],[1,3.05,1.64],[2,2.82,1.42]],"batl":[[0,7.8,1.66]],"ltp":3.6,"tv":22.63,"id":424679}],"tv":49.65}]}
{"op":"mcm","clk":"11894847926","pt":1724321065605,"mc":[{"id":"1.231812842","rc":[{"batl":[[0,7.8,1.3]],"ltp":3.6,"tv":22.63,"id":424679}]}]}
{"op":"mcm","clk":"11894848222","pt":1724321070703,"mc":[{"id":"1.231812842","rc":[{"trd":[[3.55,0.72]],"batb":[[0,3.55,1.82]],"ltp":3.55,"tv":23.35,"id":424679}],"tv":50.37}]}
{"op":"mcm","clk":"11894848524","pt":1724321075802,"mc":[{"id":"1.231812842","rc":[{"batb":[[0,3.6,4],[1,3.55,1.82],[2,3.05,1.64]],"ltp":3.55,"tv":23.35,"id":424679}]}]}
{"op":"mcm","clk":"11894848675","pt":1724321078212,"mc":[{"id":"1.231812842","rc":[{"batb":[[0,3.55,1.82],[1,3.05,1.64],[2,2.82,1.42]],"ltp":3.55,"tv":23.35,"id":424679}]}]}
{"op":"mcm","clk":"11894849622","pt":1724321092408,"mc":[{"id":"1.231812842","rc":[{"batb":[[0,3.6,4],[1,3.55,1.82],[2,3.05,1.64]],"ltp":3.55,"tv":23.35,"id":424679}]}]}
{"op":"mcm","clk":"11894849783","pt":1724321094728,"mc":[{"id":"1.231812842","rc":[{"batb":[[0,3.55,1.82],[1,3.05,1.64],[2,2.82,1.42]],"ltp":3.55,"tv":23.35,"id":424679}]}]}
{"op":"mcm","clk":"11894853716","pt":1724321154571,"mc":[{"id":"1.231812842","rc":[{"batb":[[0,1.5,20.6]],"ltp":2.0,"tv":15.0,"id":424676}]}]}
{"op":"mcm","clk":"11894856870","pt":1724321209975,"mc":[{"id":"1.231812842","rc":[{"batl":[[0,2.64,3.63]],"ltp":2.0,"tv":15.0,"id":424676}]}]}
{"op":"mcm","clk":"11894861465","pt":1724321286348,"mc":[{"id":"1.231812842","rc":[{"batl":[[0,2.64,3.33]],"ltp":2.0,"tv":15.0,"id":424676}]}]}
{"op":"mcm","clk":"11894861590","pt":1724321288460,"mc":[{"id":"1.231812842","rc":[{"batb":[[0,1.5,20.3]],"ltp":2.0,"tv":15.0,"id":424676}]}]}
{"op":"mcm","clk":"11894871245","pt":1724321445735,"mc":[{"id":"1.231812842","rc":[{"batb":[[2,1.07,36.01]],"ltp":2.0,"tv":15.0,"id":424676}]}]}
{"op":"mcm","clk":"11894871255","pt":1724321445943,"mc":[{"id":"1.231812842","rc":[{"batb":[[2,1.07,35.71]],"ltp":2.0,"tv":15.0,"id":424676}]}]}
{"op":"mcm","clk":"11894871562","pt":1724321451036,"mc":[{"id":"1.231812842","rc":[{"batb":[[0,1.5,20.6]],"ltp":2.0,"tv":15.0,"id":424676}]}]}
{"op":"mcm","clk":"11894874641","pt":1724321506676,"mc":[{"id":"1.231812842","rc":[{"batl":[[0,2.64,3.63]],"ltp":2.0,"tv":15.0,"id":424676}]}]}
{"op":"mcm","clk":"11894875175","pt":1724321516899,"mc":[{"id":"1.231812842","rc":[{"batb":[[0,2,20],[1,1.5,20.6],[2,1.08,31.25]],"ltp":2.0,"tv":15.0,"id":424676}]}]}
{"op":"mcm","clk":"11894888709","pt":1724321586486,"mc":[{"id":"1.231812842","rc":[{"batb":[[1,1.5,20.3]],"batl":[[0,2.64,3.33]],"ltp":2.0,"tv":15.0,"id":424676}]}]}
{"op":"mcm","clk":"11894899700","pt":1724321749786,"mc":[{"id":"1.231812842","rc":[{"batb":[[1,1.5,20]],"ltp":2.0,"tv":15.0,"id":424676}]}]}
{"op":"mcm","clk":"11894900607","pt":1724321763979,"mc":[{"id":"1.231812842","rc":[{"trd":[[2,11.99]],"batb":[[0,2,19]],"ltp":2.0,"tv":17.0,"id":424676}],"tv":52.37}]}
{"op":"mcm","clk":"11894903393","pt":1724321807349,"mc":[{"id":"1.231812842","rc":[{"batl":[[0,2.64,3.03]],"ltp":2.0,"tv":17.0,"id":424676}]}]}
{"op":"mcm","clk":"11894907383","pt":1724321864319,"mc":[{"id":"1.231812842","rc":[{"trd":[[3.5,2]],"batb":[[0,3.5,1],[1,2.5,25],[2,1.3,20]],"batl":[[0,4,1],[1,5,1],[2,6,1]],"ltp":3.5,"tv":14.01,"id":60443}],"tv":54.37}]}
{"op":"mcm","clk":"11894907497","pt":1724321865717,"mc":[{"id":"1.231812842","rc":[{"batl":[[0,8,1.3],[1,10,1],[2,15,1.53]],"ltp":3.55,"tv":23.35,"id":424679},{"batb":[[0,2.5,25],[1,1.3,20],[2,1.08,31.25]],"ltp":3.5,"tv":14.01,"id":60443}]}]}
{"op":"mcm","clk":"11894908096","pt":1724321874027,"mc":[{"id":"1.231812842","rc":[{"batb":[[0,2.62,1.33],[1,2.5,25],[2,1.3,20]],"ltp":3.5,"tv":14.01,"id":60443}]}]}
{"op":"mcm","clk":"11894908223","pt":1724321876000,"mc":[{"id":"1.231812842","rc":[{"batl":[[0,7.8,1.3],[1,8,1],[2,10,1]],"ltp":3.55,"tv":23.35,"id":424679}]}]}
{"op":"mcm","clk":"11894910506","pt":1724321910460,"mc":[{"id":"1.231812842","rc":[{"batb":[[0,1.5,20],[1,1.08,31.25],[2,1.07,35.71]],"ltp":2.0,"tv":17.0,"id":424676}]}]}
{"op":"mcm","clk":"11894911488","pt":1724321923677,"mc":[{"id":"1.231812842","rc":[{"batb":[[2,1.07,36.71]],"ltp":2.0,"tv":17.0,"id":424676}]}]}
{"op":"mcm","clk":"11894911515","pt":1724321924088,"mc":[{"id":"1.231812842","rc":[{"batb":[[2,1.07,35.71]],"ltp":2.0,"tv":17.0,"id":424676}]}]}
{"op":"mcm","clk":"11894911836","pt":1724321929464,"mc":[{"id":"1.231812842","rc":[{"batb":[[0,1.5,20.3]],"batl":[[0,2.5,20],[1,2.64,3.03],[2,3.5,16]],"ltp":2.0,"tv":17.0,"id":424676}]}]}
{"op":"mcm","clk":"11894913238","pt":1724321951506,"mc":[{"id":"1.231812842","rc":[{"batl":[[0,2.5,20.3]],"ltp":2.0,"tv":17.0,"id":424676}]}]}
{"op":"mcm","clk":"11894928742","pt":1724322217718,"mc":[{"id":"1.231812842","rc":[{"batb":[[2,1.07,36.71]],"ltp":2.0,"tv":17.0,"id":424676}]}]}
{"op":"mcm","clk":"11894928783","pt":1724322218290,"mc":[{"id":"1.231812842","rc":[{"batb":[[2,1.07,35.71]],"ltp":2.0,"tv":17.0,"id":424676}]}]}
{"op":"mcm","clk":"11894928891","pt":1724322219885,"mc":[{"id":"1.231812842","rc":[{"batb":[[0,1.5,20]],"ltp":2.0,"tv":17.0,"id":424676}]}]}
{"op":"mcm","clk":"11894929117","pt":1724322223399,"mc":[{"id":"1.231812842","rc":[{"batb":[[0,1.5,20.3]],"ltp":2.0,"tv":17.0,"id":424676}]}]}
{"op":"mcm","clk":"11894930144","pt":1724322241208,"mc":[{"id":"1.231812842","rc":[{"batl":[[0,2.5,20]],"ltp":2.0,"tv":17.0,"id":424676}]}]}
{"op":"mcm","clk":"11894930376","pt":1724322245146,"mc":[{"id":"1.231812842","rc":[{"batl":[[0,2.5,20.3]],"ltp":2.0,"tv":17.0,"id":424676}]}]}
{"op":"mcm","clk":"11894935422","pt":1724322327743,"mc":[{"id":"1.231812842","rc":[{"trd":[[6,1.7]],"batl":[[0,8,1],[1,10,1],[2,15,1.53]],"ltp":6.0,"tv":23.65,"id":424679},{"trd":[[1.71,1.05],[1.72,0.61]],"batb":[[0,1.5,20]],"batl":[[0,1.71,36.65],[1,2.5,20.3],[2,2.64,3.03]],"ltp":1.71,"tv":18.65,"id":424676},{"trd":[[4,0.45]],"batl":[[0,5,1.55],[1,6,1],[2,8,1]],"ltp":4.0,"tv":14.46,"id":60443}],"tv":56.77}]}
{"op":"mcm","clk":"11894936294","pt":1724322341347,"mc":[{"id":"1.231812842","rc":[{"batb":[[0,3.55,2.33]],"ltp":6.0,"tv":23.65,"id":424679}]}]}
{"op":"mcm","clk":"11894936609","pt":1724322346288,"mc":[{"id":"1.231812842","rc":[{"batl":[[0,5,1.85]],"ltp":4.0,"tv":14.46,"id":60443}]}]}
{"op":"mcm","clk":"11894940926","pt":1724322417173,"mc":[{"id":"1.231812842","rc":[{"trd":[[1.71,3.05]],"batl":[[0,1.71,35.65]],"ltp":1.71,"tv":20.65,"id":424676}],"tv":58.77}]}
{"op":"mcm","clk":"11894946953","pt":1724322510640,"mc":[{"id":"1.231812842","rc":[{"batl":[[0,2.5,20.3],[1,2.64,3.03],[2,3.5,16]],"ltp":1.71,"tv":20.65,"id":424676}]}]}
{"op":"mcm","clk":"11894947339","pt":1724322516561,"mc":[{"id":"1.231812842","rc":[{"batl":[[0,7.8,1],[1,8,1],[2,10,1]],"ltp":6.0,"tv":23.65,"id":424679}]}]}
{"op":"mcm","clk":"11894948175","pt":1724322531792,"mc":[{"id":"1.231812842","rc":[{"batb":[[0,2.62,1.63]],"ltp":4.0,"tv":14.46,"id":60443}]}]}
{"op":"mcm","clk":"11894948295","pt":1724322534373,"mc":[{"id":"1.231812842","rc":[{"batl":[[0,2.5,20]],"ltp":1.71,"tv":20.65,"id":424676}]}]}
{"op":"mcm","clk":"11894948521","pt":1724322538783,"mc":[{"id":"1.231812842","rc":[{"trd":[[7.8,0.28]],"batl":[[0,8,1.72],[1,10,1],[2,15,1.53]],"ltp":7.8,"tv":23.93,"id":424679},{"trd":[[1.6,1.38]],"batl":[[0,1.6,34.62],[1,2.5,20],[2,2.64,3.03]],"ltp":1.6,"tv":22.03,"id":424676},{"trd":[[4,1]],"batl":[[0,5,1.3]],"ltp":4.0,"tv":15.01,"id":60443}],"tv":60.98}]}
{"op":"mcm","clk":"11894948702","pt":1724322542189,"mc":[{"id":"1.231812842","rc":[{"batl":[[1,2.5,20.3]],"ltp":1.6,"tv":22.03,"id":424676}]}]}
{"op":"mcm","clk":"11894948829","pt":1724322544512,"mc":[{"id":"1.231812842","rc":[{"batb":[[0,3.6,4],[1,3.55,2.33],[2,3.05,1.64]],"ltp":7.8,"tv":23.93,"id":424679},{"batb":[[0,2.64,4.3],[1,2.62,1.33],[2,2.5,25]],"ltp":4.0,"tv":15.01,"id":60443}]}]}
{"op":"mcm","clk":"11894948934","pt":1724322546312,"mc":[{"id":"1.231812842","rc":[{"batb":[[0,3.55,2.33],[1,3.05,1.64],[2,2.82,1.42]],"ltp":7.8,"tv":23.93,"id":424679},{"batb":[[0,2.82,1.42],[1,2.62,1.63]],"ltp":4.0,"tv":15.01,"id":60443}]}]}
{"op":"mcm","clk":"11894949127","pt":1724322549914,"mc":[{"id":"1.231812842","rc":[{"batb":[[0,3.55,2.71]],"ltp":7.8,"tv":23.93,"id":424679}]}]}
{"op":"mcm","clk":"11894949432","pt":1724322555619,"mc":[{"id":"1.231812842","rc":[{"batl":[[0,2.5,20.3],[1,2.64,3.03],[2,3.5,16]],"ltp":1.6,"tv":22.03,"id":424676}]}]}
{"op":"mcm","clk":"11894950553","pt":1724322575624,"mc":[{"id":"1.231812842","rc":[{"trd":[[7.8,1],[8,0.11]],"batl":[[0,10,1.89],[1,15,1.53],[2,15.5,4]],"ltp":8.0,"tv":24.76,"id":424679},{"trd":[[1.48,3.36],[1.49,0.99],[1.5,40]],"batb":[[0,1.08,31.25],[1,1.07,35.71],[2,1.06,41.67]],"batl":[[0,1.5,10.65],[1,2.5,20.3],[2,2.64,3.03]],"ltp":1.48,"tv":66.38,"id":424676},{"trd":[[4.9,0.3],[5,1]],"batl":[[0,6,1],[1,8,1],[2,10,1]],"ltp":5.0,"tv":16.31,"id":60443}],"tv":107.46}]}
{"op":"mcm","clk":"11894950733","pt":1724322578240,"mc":[{"id":"1.231812842","rc":[{"batb":[[0,3.55,2.33]],"ltp":8.0,"tv":24.76,"id":424679}]}]}
{"op":"mcm","clk":"11894951127","pt":1724322585536,"mc":[{"id":"1.231812842","rc":[{"batb":[[0,3.05,1.64],[1,2.82,1.42],[2,2.62,1.63]],"ltp":5.0,"tv":16.31,"id":60443}]}]}
{"op":"mcm","clk":"11894951325","pt":1724322588840,"mc":[{"id":"1.231812842","rc":[{"batb":[[0,6.2,1.26],[1,3.55,2.33],[2,3.05,1.64]],"ltp":8.0,"tv":24.76,"id":424679}]}]}
{"op":"mcm","clk":"11894951615","pt":1724322593783,"mc":[{"id":"1.231812842","rc":[{"batl":[[0,2.5,20.3],[1,2.64,3.03],[2,3.5,16]],"ltp":1.48,"tv":66.38,"id":424676}]}]}
{"op":"mcm","clk":"11894955668","pt":1724322665685,"mc":[{"id":"1.231812842","rc":[{"batb":[[0,1.08,31.55]],"ltp":1.48,"tv":66.38,"id":424676}]}]}
{"op":"mcm","clk":"11894966044","pt":1724322840668,"mc":[{"id":"1.231812842","rc":[{"batb":[[2,2.62,1.33]],"ltp":5.0,"tv":16.31,"id":60443}]}]}
{"op":"mcm","clk":"11894966636","pt":1724322851863,"mc":[{"id":"1.231812842","rc":[{"batl":[[0,2.5,20]],"ltp":1.48,"tv":66.38,"id":424676}]}]}
{"op":"mcm","clk":"11894966766","pt":1724322854183,"mc":[{"id":"1.231812842","rc":[{"batl":[[0,2.5,20.3]],"ltp":1.48,"tv":66.38,"id":424676}]}]}
{"op":"mcm","clk":"11894971940","pt":1724322956380,"mc":[{"id":"1.231812842","rc":[{"batb":[[0,1.08,31.25]],"ltp":1.48,"tv":66.38,"id":424676}]}]}
{"op":"mcm","clk":"11894972327","pt":1724322963582,"mc":[{"id":"1.231812842","rc":[{"batb":[[0,1.08,31.55]],"ltp":1.48,"tv":66.38,"id":424676}]}]}
{"op":"mcm","clk":"11894983495","pt":1724323168821,"mc":[{"id":"1.231812842","rc":[{"batl":[[0,2.5,20]],"ltp":1.48,"tv":66.38,"id":424676}]}]}
{"op":"mcm","clk":"11894983867","pt":1724323176308,"mc":[{"id":"1.231812842","rc":[{"batl":[[0,2.5,20.3]],"ltp":1.48,"tv":66.38,"id":424676}]}]}
{"op":"mcm","clk":"11894989167","pt":1724323275758,"mc":[{"id":"1.231812842","rc":[{"batb":[[0,1.08,31.25]],"ltp":1.48,"tv":66.38,"id":424676}]}]}
{"op":"mcm","clk":"11894989264","pt":1724323277664,"mc":[{"id":"1.231812842","rc":[{"batb":[[1,1.07,36.01]],"ltp":1.48,"tv":66.38,"id":424676}]}]}
{"op":"mcm","clk":"11894989280","pt":1724323277869,"mc":[{"id":"1.231812842","rc":[{"batb":[[1,1.07,35.71]],"ltp":1.48,"tv":66.38,"id":424676}]}]}
{"op":"mcm","clk":"11894989558","pt":1724323282949,"mc":[{"id":"1.231812842","rc":[{"batb":[[0,1.08,31.55]],"ltp":1.48,"tv":66.38,"id":424676}]}]}
{"op":"mcm","clk":"11894999647","pt":1724323461868,"mc":[{"id":"1.231812842","rc":[{"batl":[[0,2.5,20]],"ltp":1.48,"tv":66.38,"id":424676}]}]}
{"op":"mcm","clk":"11895000190","pt":1724323470860,"mc":[{"id":"1.231812842","rc":[{"batl":[[0,2.5,20.3]],"ltp":1.48,"tv":66.38,"id":424676}]}]}
{"op":"mcm","clk":"11895004011","pt":1724323536137,"mc":[{"id":"1.231812842","rc":[{"batb":[[0,5.8,1.52],[1,3.05,1.64],[2,2.82,1.42]],"ltp":5.0,"tv":16.31,"id":60443}]}]}
{"op":"mcm","clk":"11895005810","pt":1724323566979,"mc":[{"id":"1.231812842","rc":[{"batb":[[0,3.05,1.64],[1,2.82,1.42],[2,2.62,1.33]],"ltp":5.0,"tv":16.31,"id":60443}]}]}
{"op":"mcm","clk":"11895006773","pt":1724323583874,"mc":[{"id":"1.231812842","rc":[{"batb":[[0,5.8,1.52],[1,3.05,1.64],[2,2.82,1.42]],"ltp":5.0,"tv":16.31,"id":60443}]}]}
{"op":"mcm","clk":"11895007471","pt":1724323595548,"mc":[{"id":"1.231812842","rc":[{"batb":[[0,1.08,31.25]],"ltp":1.48,"tv":66.38,"id":424676}]}]}
{"op":"mcm","clk":"11895007681","pt":1724323598385,"mc":[{"id":"1.231812842","rc":[{"batl":[[0,1.5,6],[1,2.5,20.3],[2,2.64,3.03]],"ltp":1.48,"tv":66.38,"id":424676}]}]}
{"op":"mcm","clk":"11895008168","pt":1724323606572,"mc":[{"id":"1.231812842","rc":[{"batb":[[0,3.05,1.64],[1,2.82,1.42],[2,2.62,1.33]],"ltp":5.0,"tv":16.31,"id":60443}]}]}
{"op":"mcm","clk":"11895018327","pt":1724323761301,"mc":[{"id":"1.231812842","rc":[{"batl":[[1,2.5,20]],"ltp":1.48,"tv":66.38,"id":424676}]}]}
{"op":"mcm","clk":"11895031249","pt":1724323970869,"mc":[{"id":"1.231812842","rc":[{"trd":[[6,2.7],[6.2,2.52]],"batb":[[0,3.55,2.33],[1,3.05,1.64],[2,2.82,1.42]],"ltp":6.0,"tv":28.28,"id":424679},{"trd":[[1.5,44]],"batl":[[0,1.5,2]],"ltp":1.5,"tv":70.38,"id":424676},{"trd":[[6,1]],"batl":[[0,8,1],[1,10,1],[2,15,1.53]],"ltp":6.0,"tv":17.31,"id":60443}],"tv":115.98}]}
{"op":"mcm","clk":"11895031670","pt":1724323981185,"mc":[{"id":"1.231812842","rc":[{"batl":[[0,9.8,1.89],[1,10,1],[2,15,1.53]],"ltp":6.0,"tv":28.28,"id":424679},{"batb":[[0,3.55,1.69],[1,3.05,1.64],[2,2.82,1.42]],"batl":[[0,7.8,1],[1,8,1],[2,10,1]],"ltp":6.0,"tv":17.31,"id":60443}]}]}
{"op":"mcm","clk":"11895031859","pt":1724323985959,"mc":[{"id":"1.231812842","rc":[{"batb":[[0,3.55,2.63]],"ltp":6.0,"tv":28.28,"id":424679}]}]}
{"op":"mcm","clk":"11895032825","pt":1724324008232,"mc":[{"id":"1.231812842","rc":[{"batl":[[0,9.6,1.19],[1,9.8,1],[2,10,1]],"ltp":6.0,"tv":28.28,"id":424679}]}]}
{"op":"mcm","clk":"11895032889","pt":1724324009560,"mc":[{"id":"1.231812842","rc":[{"batl":[[1,10,1],[2,15,1.53]],"ltp":6.0,"tv":28.28,"id":424679}]}]}
{"op":"mcm","clk":"11895033365","pt":1724324020007,"mc":[{"id":"1.231812842","rc":[{"batl":[[0,9.4,1.89],[1,10,1.3]],"ltp":6.0,"tv":28.28,"id":424679}]}]}
{"op":"mcm","clk":"11895038174","pt":1724324120039,"mc":[{"id":"1.231812842","rc":[{"trd":[[8,0.49]],"batl":[[0,9.4,1.51]],"ltp":8.0,"tv":28.66,"id":424679},{"trd":[[1.5,46]],"batl":[[0,2.5,20],[1,2.64,3.03],[2,3.5,16]],"ltp":1.5,"tv":72.38,"id":424676},{"trd":[[4.8,0.62]],"batl":[[0,7.8,1.9]],"ltp":4.8,"tv":17.93,"id":60443}],"tv":118.99}]}
{"op":"mcm","clk":"11895038973","pt":1724324137439,"mc":[{"id":"1.231812842","rc":[{"batl":[[0,2.5,20.3]],"ltp":1.5,"tv":72.38,"id":424676}]}]}
{"op":"mcm","clk":"11895039042","pt":1724324138824,"mc":[{"id":"1.231812842","rc":[{"batl":[[0,7.8,1]],"ltp":4.8,"tv":17.93,"id":60443}]}]}
{"op":"mcm","clk":"11895039878","pt":1724324156384,"mc":[{"id":"1.231812842","rc":[{"batl":[[0,3.7,1.52],[1,7.8,1],[2,8,1]],"ltp":4.8,"tv":17.93,"id":60443}]}]}
{"op":"mcm","clk":"11895040049","pt":1724324159980,"mc":[{"id":"1.231812842","rc":[{"batl":[[1,8,1],[2,10,1]],"ltp":4.8,"tv":17.93,"id":60443}]}]}
{"op":"mcm","clk":"11895042252","pt":1724324206549,"mc":[{"id":"1.231812842","rc":[{"batb":[[0,1.08,31.55]],"ltp":1.5,"tv":72.38,"id":424676}]}]}
{"op":"mcm","clk":"11895042949","pt":1724324219747,"mc":[{"id":"1.231812842","rc":[{"batl":[[0,8,1],[1,10,1],[2,15,1.53]],"ltp":4.8,"tv":17.93,"id":60443}]}]}
{"op":"mcm","clk":"11895043307","pt":1724324226160,"mc":[{"id":"1.231812842","rc":[{"batl":[[0,7.8,1],[1,8,1],[2,10,1]],"ltp":4.8,"tv":17.93,"id":60443}]}]}
{"op":"mcm","clk":"11895046932","pt":1724324295808,"mc":[{"id":"1.231812842","rc":[{"batb":[[0,3.55,2.93]],"ltp":8.0,"tv":28.66,"id":424679}]}]}
{"op":"mcm","clk":"11895047027","pt":1724324297721,"mc":[{"id":"1.231812842","rc":[{"batb":[[0,3.55,2.63]],"ltp":8.0,"tv":28.66,"id":424679}]}]}
{"op":"mcm","clk":"11895047750","pt":1724324312941,"mc":[{"id":"1.231812842","rc":[{"batl":[[1,10,1]],"ltp":8.0,"tv":28.66,"id":424679}]}]}
{"op":"mcm","clk":"11895048011","pt":1724324317931,"mc":[{"id":"1.231812842","rc":[{"batl":[[0,9.4,1.81]],"ltp":8.0,"tv":28.66,"id":424679}]}]}
{"op":"mcm","clk":"11895054130","pt":1724324429378,"mc":[{"id":"1.231812842","rc":[{"trd":[[6.2,2.52]],"ltp":8.0,"tv":28.66,"id":424679},{"trd":[[1.16,3.99],[2,11.99]],"batl":[[0,2.5,20]],"ltp":1.5,"tv":72.39,"id":424676}],"tv":118.99}]}
{"op":"mcm","clk":"11895054813","pt":1724324440483,"mc":[{"id":"1.231812842","rc":[{"batl":[[0,2.5,20.3]],"ltp":1.5,"tv":72.39,"id":424676}]}]}
{"op":"mcm","clk":"11895057154","pt":1724324479724,"mc":[{"id":"1.231812842","rc":[{"batb":[[0,1.4,2.96],[1,1.08,31.25],[2,1.07,35.71]],"ltp":1.5,"tv":72.39,"id":424676}]}]}
{"op":"mcm","clk":"11895057695","pt":1724324488759,"mc":[{"id":"1.231812842","rc":[{"batb":[[0,1.08,31.55],[1,1.07,35.71],[2,1.06,41.67]],"ltp":1.5,"tv":72.39,"id":424676}]}]}
{"op":"mcm","clk":"11895057731","pt":1724324489366,"mc":[{"id":"1.231812842","rc":[{"batb":[[0,1.08,31.25]],"ltp":1.5,"tv":72.39,"id":424676}]}]}
{"op":"mcm","clk":"11895058173","pt":1724324496473,"mc":[{"id":"1.231812842","rc":[{"batb":[[0,1.08,31.55]],"ltp":1.5,"tv":72.39,"id":424676}]}]}
{"op":"mcm","clk":"11895064438","pt":1724324596371,"mc":[{"id":"1.231812842","rc":[{"batb":[[0,3.55,2.93]],"ltp":8.0,"tv":28.66,"id":424679}]}]}
{"op":"mcm","clk":"11895064491","pt":1724324597052,"mc":[{"id":"1.231812842","rc":[{"batb":[[0,3.55,2.63]],"ltp":8.0,"tv":28.66,"id":424679}]}]}
{"op":"mcm","clk":"11895065528","pt":1724324613683,"mc":[{"id":"1.231812842","rc":[{"batl":[[0,9.4,1.51]],"ltp":8.0,"tv":28.66,"id":424679}]}]}
{"op":"mcm","clk":"11895065898","pt":1724324619979,"mc":[{"id":"1.231812842","rc":[{"batl":[[0,9.4,1.81]],"ltp":8.0,"tv":28.66,"id":424679}]}]}
{"op":"mcm","clk":"11895070806","pt":1724324696551,"mc":[{"id":"1.231812842","rc":[{"trd":[[1.41,0.6]],"batb":[[0,1.08,31.25]],"batl":[[0,2.5,20.99]],"ltp":1.41,"tv":72.98,"id":424676}],"tv":119.59}]}
{"op":"mcm","clk":"11895071055","pt":1724324700348,"mc":[{"id":"1.231812842","rc":[{"batl":[[0,2.5,20.3]],"ltp":1.41,"tv":72.98,"id":424676}]}]}
{"op":"mcm","clk":"11895072192","pt":1724324718158,"mc":[{"id":"1.231812842","rc":[{"batl":[[0,2.28,1.29],[1,2.5,20],[2,2.64,3.03]],"ltp":1.41,"tv":72.98,"id":424676}]}]}
{"op":"mcm","clk":"11895072522","pt":1724324723790,"mc":[{"id":"1.231812842","rc":[{"batl":[[0,2.5,20.3],[1,2.64,3.03],[2,3.5,16]],"ltp":1.41,"tv":72.98,"id":424676}]}]}
{"op":"mcm","clk":"11895073316","pt":1724324738088,"mc":[{"id":"1.231812842","rc":[{"batl":[[0,1.4,1.52],[1,2.5,20.3],[2,2.64,3.03]],"ltp":1.41,"tv":72.98,"id":424676}]}]}
{"op":"mcm","clk":"11895073883","pt":1724324746690,"mc":[{"id":"1.231812842","rc":[{"batl":[[1,2.5,20]],"ltp":1.41,"tv":72.98,"id":424676}]}]}
{"op":"mcm","clk":"11895074433","pt":1724324754220,"mc":[{"id":"1.231812842","rc":[{"batl":[[0,2.5,20],[1,2.64,3.03],[2,3.5,16]],"ltp":1.41,"tv":72.98,"id":424676}]}]}
{"op":"mcm","clk":"11895075558","pt":1724324772044,"mc":[{"id":"1.231812842","rc":[{"batl":[[0,2.5,20.3]],"ltp":1.41,"tv":72.98,"id":424676}]}]}
{"op":"mcm","clk":"11895075639","pt":1724324773333,"mc":[{"id":"1.231812842","rc":[{"batb":[[0,1.08,32.24]],"ltp":1.41,"tv":72.98,"id":424676}]}]}
{"op":"mcm","clk":"11895075914","pt":1724324777924,"mc":[{"id":"1.231812842","rc":[{"batl":[[0,10,1.81],[1,15,1.53],[2,15.5,4]],"ltp":8.0,"tv":28.66,"id":424679}]}]}
{"op":"mcm","clk":"11895075979","pt":1724324778842,"mc":[{"id":"1.231812842","rc":[{"batb":[[0,1.08,31.25]],"ltp":1.41,"tv":72.98,"id":424676}]}]}
{"op":"mcm","clk":"11895076603","pt":1724324788427,"mc":[{"id":"1.231812842","rc":[{"batl":[[0,9.8,1.81],[1,10,1],[2,15,1.53]],"ltp":8.0,"tv":28.66,"id":424679}]}]}
{"op":"mcm","clk":"11895077194","pt":1724324798070,"mc":[{"id":"1.231812842","rc":[{"batb":[[0,2.08,1.52],[1,1.08,31.25],[2,1.07,35.71]],"ltp":1.41,"tv":72.98,"id":424676}]}]}
{"op":"mcm","clk":"11895077366","pt":1724324800657,"mc":[{"id":"1.231812842","rc":[{"batl":[[0,10,1.81],[1,15,1.53],[2,15.5,4]],"ltp":8.0,"tv":28.66,"id":424679},{"batb":[[2,1.07,36.71]],"ltp":1.41,"tv":72.98,"id":424676}]}]}
{"op":"mcm","clk":"11895077401","pt":1724324801176,"mc":[{"id":"1.231812842","rc":[{"batb":[[2,1.07,35.71]],"ltp":1.41,"tv":72.98,"id":424676}]}]}
{"op":"mcm","clk":"11895077694","pt":1724324806245,"mc":[{"id":"1.231812842","rc":[{"batb":[[1,1.08,31.55]],"ltp":1.41,"tv":72.98,"id":424676}]}]}
{"op":"mcm","clk":"11895077983","pt":1724324810765,"mc":[{"id":"1.231812842","rc":[{"batl":[[0,7.8,1],[1,10,1.81],[2,15,1.53]],"ltp":8.0,"tv":28.66,"id":424679}]}]}
{"op":"mcm","clk":"11895078074","pt":1724324811966,"mc":[{"id":"1.231812842","rc":[{"batb":[[0,1.08,31.55],[1,1.07,35.71],[2,1.06,41.67]],"ltp":1.41,"tv":72.98,"id":424676}]}]}
{"op":"mcm","clk":"11895079799","pt":1724324839667,"mc":[{"id":"1.231812842","rc":[{"batl":[[0,1.39,1.52],[1,2.5,20.3],[2,2.64,3.03]],"ltp":1.41,"tv":72.98,"id":424676}]}]}
{"op":"mcm","clk":"11895080562","pt":1724324852478,"mc":[{"id":"1.231812842","rc":[{"trd":[[1.39,3.05]],"batb":[[0,1.39,1.52],[1,1.08,31.55],[2,1.07,35.71]],"batl":[[0,2.5,20.3],[1,2.64,3.03],[2,3.5,16]],"ltp":1.39,"tv":76.03,"id":424676}],"tv":122.64}]}
{"op":"mcm","clk":"11895081947","pt":1724324875307,"mc":[{"id":"1.231812842","rc":[{"batl":[[0,1.44,1.52],[1,2.5,20.3],[2,2.64,3.03]],"ltp":1.39,"tv":76.03,"id":424676}]}]}
{"op":"mcm","clk":"11895083074","pt":1724324893028,"mc":[{"id":"1.231812842","rc":[{"batl":[[0,2.5,20.3],[1,2.64,3.03],[2,3.5,16]],"ltp":1.39,"tv":76.03,"id":424676}]}]}
{"op":"mcm","clk":"11895083405","pt":1724324898124,"mc":[{"id":"1.231812842","rc":[{"batb":[[0,3.55,2.33]],"ltp":8.0,"tv":28.66,"id":424679}]}]}
{"op":"mcm","clk":"11895085014","pt":1724324922881,"mc":[{"id":"1.231812842","rc":[{"batl":[[1,10,1.51]],"ltp":8.0,"tv":28.66,"id":424679}]}]}
{"op":"mcm","clk":"11895085189","pt":1724324925866,"mc":[{"id":"1.231812842","rc":[{"batb":[[0,2.08,1.52],[1,1.39,1.52],[2,1.08,31.55]],"ltp":1.39,"tv":76.03,"id":424676}]}]}
{"op":"mcm","clk":"11895086024","pt":1724324938689,"mc":[{"id":"1.231812842","rc":[{"batb":[[0,1.39,1.52],[1,1.08,31.55],[2,1.07,35.71]],"ltp":1.39,"tv":76.03,"id":424676}]}]}
{"op":"mcm","clk":"11895086336","pt":1724324942804,"mc":[{"id":"1.231812842","rc":[{"batl":[[0,1.79,4],[1,2.5,20.3],[2,2.64,3.03]],"ltp":1.39,"tv":76.03,"id":424676}]}]}
{"op":"mcm","clk":"11895086440","pt":1724324944409,"mc":[{"id":"1.231812842","rc":[{"batl":[[0,2.5,20.3],[1,2.64,3.03],[2,3.5,16]],"ltp":1.39,"tv":76.03,"id":424676}]}]}
{"op":"mcm","clk":"11895087463","pt":1724324959411,"mc":[{"id":"1.231812842","rc":[{"batb":[[1,1.26,31.99],[2,1.08,31.25]],"ltp":1.39,"tv":76.03,"id":424676}]}]}
{"op":"mcm","clk":"11895088114","pt":1724324970332,"mc":[{"id":"1.231812842","rc":[{"batl":[[0,1.45,1.52],[1,2.5,20.3],[2,2.64,3.03]],"ltp":1.39,"tv":76.03,"id":424676}]}]}
{"op":"mcm","clk":"11895088816","pt":1724324982833,"mc":[{"id":"1.231812842","rc":[{"batl":[[0,2.5,20.3],[1,2.64,3.03],[2,3.5,16]],"ltp":1.39,"tv":76.03,"id":424676}]}]}
{"op":"mcm","clk":"11895089418","pt":1724324993933,"mc":[{"id":"1.231812842","rc":[{"batb":[[1,1.08,31.55],[2,1.07,35.71]],"ltp":1.39,"tv":76.03,"id":424676}]}]}
{"op":"mcm","clk":"11895090311","pt":1724325010675,"mc":[{"id":"1.231812842","rc":[{"batb":[[1,1.26,31.99],[2,1.08,31.25]],"ltp":1.39,"tv":76.03,"id":424676}]}]}
{"op":"mcm","clk":"11895090956","pt":1724325022291,"mc":[{"id":"1.231812842","rc":[{"batb":[[1,1.08,31.55],[2,1.07,35.71]],"ltp":1.39,"tv":76.03,"id":424676}]}]}
{"op":"mcm","clk":"11895091790","pt":1724325037501,"mc":[{"id":"1.231812842","rc":[{"batb":[[0,2.1,1.52],[1,1.39,1.52],[2,1.08,31.55]],"ltp":1.39,"tv":76.03,"id":424676}]}]}
{"op":"mcm","clk":"11895091821","pt":1724325038020,"mc":[{"id":"1.231812842","rc":[{"trd":[[2.1,1.52]],"batb":[[0,1.39,2.29],[1,1.08,31.55],[2,1.07,35.71]],"ltp":2.1,"tv":77.56,"id":424676}],"tv":124.16}]}
{"op":"mcm","clk":"11895092316","pt":1724325046527,"mc":[{"id":"1.231812842","rc":[{"batb":[[0,1.39,1.52]],"ltp":2.1,"tv":77.56,"id":424676}]}]}
{"op":"mcm","clk":"11895092979","pt":1724325058740,"mc":[{"id":"1.231812842","rc":[{"batl":[[0,7.8,1.46]],"ltp":4.8,"tv":17.93,"id":60443}]}]}
{"op":"mcm","clk":"11895093215","pt":1724325062438,"mc":[{"id":"1.231812842","rc":[{"trd":[[3.55,1.52]],"batb":[[0,3.55,1.53]],"ltp":3.55,"tv":29.46,"id":424679},{"trd":[[2.28,0.6],[2.3,1.23]],"batl":[[0,2.5,20]],"ltp":2.3,"tv":79.38,"id":424676},{"trd":[[3.55,0.8]],"batb":[[0,3.05,2.53],[1,2.82,1.42],[2,2.62,1.33]],"ltp":3.55,"tv":18.73,"id":60443}],"tv":127.59}]}
{"op":"mcm","clk":"11895093519","pt":1724325067548,"mc":[{"id":"1.231812842","rc":[{"batb":[[0,3.6,4],[1,3.55,1.53],[2,3.05,1.64]],"ltp":3.55,"tv":29.46,"id":424679},{"batb":[[0,3.1,4.89],[1,3.05,1.64],[2,2.82,1.42]],"ltp":3.55,"tv":18.73,"id":60443}]}]}
{"op":"mcm","clk":"11895093648","pt":1724325070023,"mc":[{"id":"1.231812842","rc":[{"batb":[[0,3.55,1.53],[1,3.05,1.64],[2,2.82,1.42]],"ltp":3.55,"tv":29.46,"id":424679},{"batb":[[0,3.05,2.53],[1,2.82,1.42],[2,2.62,1.33]],"ltp":3.55,"tv":18.73,"id":60443}]}]}
{"op":"mcm","clk":"11895094143","pt":1724325078561,"mc":[{"id":"1.231812842","rc":[{"batb":[[0,3.1,1.19],[1,3.05,1.64],[2,2.82,1.42]],"ltp":3.55,"tv":18.73,"id":60443}]}]}
{"op":"mcm","clk":"11895094329","pt":1724325081643,"mc":[{"id":"1.231812842","rc":[{"batb":[[0,3.6,4],[1,3.55,1.53],[2,3.05,1.64]],"ltp":3.55,"tv":29.46,"id":424679},{"batb":[[0,3.1,5.19]],"ltp":3.55,"tv":18.73,"id":60443}]}]}
{"op":"mcm","clk":"11895094501","pt":1724325084172,"mc":[{"id":"1.231812842","rc":[{"batb":[[0,3.55,1.53],[1,3.05,1.64],[2,2.82,1.42]],"ltp":3.55,"tv":29.46,"id":424679},{"batb":[[0,2,1.52],[1,1.39,1.52],[2,1.08,31.55]],"ltp":2.3,"tv":79.38,"id":424676},{"batb":[[0,3.1,1.19]],"ltp":3.55,"tv":18.73,"id":60443}]}]}
{"op":"mcm","clk":"11895094776","pt":1724325088545,"mc":[{"id":"1.231812842","rc":[{"batl":[[0,2.5,20.3]],"ltp":2.3,"tv":79.38,"id":424676}]}]}
{"op":"mcm","clk":"11895094854","pt":1724325089775,"mc":[{"id":"1.231812842","rc":[{"batl":[[0,8,1.46],[1,10,1],[2,15,1.53]],"ltp":3.55,"tv":18.73,"id":60443}]}]}
{"op":"mcm","clk":"11895095235","pt":1724325096852,"mc":[{"id":"1.231812842","rc":[{"batb":[[0,1.39,1.52],[1,1.08,31.55],[2,1.07,35.71]],"ltp":2.3,"tv":79.38,"id":424676}]}]}
{"op":"mcm","clk":"11895095416","pt":1724325100271,"mc":[{"id":"1.231812842","rc":[{"batl":[[0,7.2,1],[1,8,1.46],[2,10,1]],"ltp":3.55,"tv":18.73,"id":60443}]}]}
{"op":"mcm","clk":"11895095695","pt":1724325105786,"mc":[{"id":"1.231812842","rc":[{"batb":[[1,1.08,31.25]],"ltp":2.3,"tv":79.38,"id":424676}]}]}
{"op":"mcm","clk":"11895095969","pt":1724325110579,"mc":[{"id":"1.231812842","rc":[{"batl":[[1,8,1.76]],"ltp":3.55,"tv":18.73,"id":60443}]}]}
{"op":"mcm","clk":"11895095984","pt":1724325110786,"mc":[{"id":"1.231812842","rc":[{"batb":[[0,1.39,1.82]],"ltp":2.3,"tv":79.38,"id":424676}]}]}
{"op":"mcm","clk":"11895096852","pt":1724325124482,"mc":[{"id":"1.231812842","rc":[{"trd":[[1.39,6.1],[1.4,0.6]],"batb":[[0,1.08,31.25],[1,1.07,35.71],[2,1.06,41.67]],"batl":[[0,2.5,20.31]],"ltp":1.39,"tv":83.03,"id":424676}],"tv":131.23}]}
{"op":"mcm","clk":"11895098122","pt":1724325145509,"mc":[{"id":"1.231812842","rc":[{"trd":[[1.39,6.11]],"batb":[[0,1.39,2.28],[1,1.08,31.25],[2,1.07,35.71]],"batl":[[0,2.5,20.3]],"ltp":1.39,"tv":83.04,"id":424676}],"tv":131.25}]}
{"op":"mcm","clk":"11895098848","pt":1724325157927,"mc":[{"id":"1.231812842","rc":[{"batl":[[0,2.28,1.06],[1,2.5,20],[2,2.64,3.03]],"ltp":1.39,"tv":83.04,"id":424676}]}]}
{"op":"mcm","clk":"11895102043","pt":1724325210698,"mc":[{"id":"1.231812842","rc":[{"batl":[[0,2.5,20.83],[1,2.64,3.03],[2,3.5,16]],"ltp":1.39,"tv":83.04,"id":424676}]}]}
{"op":"mcm","clk":"11895102446","pt":1724325216686,"mc":[{"id":"1.231812842","rc":[{"batl":[[0,2.1,1.07],[1,2.5,20.3],[2,2.64,3.03]],"ltp":1.39,"tv":83.04,"id":424676}]}]}
{"op":"mcm","clk":"11895103131","pt":1724325227744,"mc":[{"id":"1.231812842","rc":[{"batl":[[2,3.5,16]],"ltp":1.39,"tv":83.04,"id":424676}]}]}
{"op":"mcm","clk":"11895103478","pt":1724325232830,"mc":[{"id":"1.231812842","rc":[{"batl":[[0,2.1,4.79]],"ltp":1.39,"tv":83.04,"id":424676}]}]}
{"op":"mcm","clk":"11895110876","pt":1724325359609,"mc":[{"id":"1.231812842","rc":[{"batb":[[0,7.2,1.11],[1,3.55,1.53],[2,3.05,1.64]],"ltp":3.55,"tv":29.46,"id":424679}]}]}
{"op":"mcm","clk":"11895111073","pt":1724325362616,"mc":[{"id":"1.231812842","rc":[{"batl":[[0,10,1.51],[1,15,1.53],[2,15.5,4]],"ltp":3.55,"tv":29.46,"id":424679}]}]}
{"op":"mcm","clk":"11895111155","pt":1724325364114,"mc":[{"id":"1.231812842","rc":[{"batb":[[0,3.55,1.53],[1,3.05,1.64],[2,2.82,1.42]],"ltp":3.55,"tv":29.46,"id":424679}]}]}
{"op":"mcm","clk":"11895111714","pt":1724325373132,"mc":[{"id":"1.231812842","rc":[{"batl":[[0,9.8,1.51],[1,10,1],[2,15,1.53]],"ltp":3.55,"tv":29.46,"id":424679}]}]}
{"op":"mcm","clk":"11895112361","pt":1724325383930,"mc":[{"id":"1.231812842","rc":[{"batl":[[0,9.8,1.81]],"ltp":3.55,"tv":29.46,"id":424679}]}]}
{"op":"mcm","clk":"11895113137","pt":1724325396961,"mc":[{"id":"1.231812842","rc":[{"batb":[[0,3.05,2.53],[1,2.82,1.42],[2,2.62,1.33]],"ltp":3.55,"tv":18.73,"id":60443}]}]}
{"op":"mcm","clk":"11895113496","pt":1724325403039,"mc":[{"id":"1.231812842","rc":[{"trd":[[8,1.51]],"batb":[[0,3.55,2.13]],"batl":[[0,9.8,1.3]],"ltp":8.0,"tv":30.48,"id":424679}],"tv":132.27}]}
{"op":"mcm","clk":"11895113703","pt":1724325406651,"mc":[{"id":"1.231812842","rc":[{"batl":[[1,2.5,20]],"ltp":1.39,"tv":83.04,"id":424676}]}]}
{"op":"mcm","clk":"11895113722","pt":1724325407060,"mc":[{"id":"1.231812842","rc":[{"batb":[[0,3.55,1.83]],"ltp":8.0,"tv":30.48,"id":424679},{"batl":[[0,2.1,5.09]],"ltp":1.39,"tv":83.04,"id":424676},{"batb":[[0,3.15,1.19],[1,3.05,1.64],[2,2.82,1.42]],"ltp":3.55,"tv":18.73,"id":60443}]}]}
{"op":"mcm","clk":"11895113770","pt":1724325408187,"mc":[{"id":"1.231812842","rc":[{"batb":[[0,3.6,4.3],[1,3.55,1.53],[2,3.05,1.64]],"ltp":8.0,"tv":30.48,"id":424679}]}]}
{"op":"mcm","clk":"11895113811","pt":1724325408969,"mc":[{"id":"1.231812842","rc":[{"batb":[[0,4.1,1.95],[1,3.6,4.3],[2,3.55,1.53]],"ltp":8.0,"tv":30.48,"id":424679}]}]}
{"op":"mcm","clk":"11895113878","pt":1724325410364,"mc":[{"id":"1.231812842","rc":[{"batb":[[1,3.55,1.83],[2,3.05,1.64]],"ltp":8.0,"tv":30.48,"id":424679}]}]}
{"op":"mcm","clk":"11895114315","pt":1724325417566,"mc":[{"id":"1.231812842","rc":[{"batb":[[0,4.2,4],[1,4.1,1.95],[2,3.55,1.83]],"ltp":8.0,"tv":30.48,"id":424679}]}]}
{"op":"mcm","clk":"11895114485","pt":1724325420073,"mc":[{"id":"1.231812842","rc":[{"batb":[[0,4.1,1.95],[1,3.55,1.83],[2,3.05,1.64]],"ltp":8.0,"tv":30.48,"id":424679}]}]}
{"op":"mcm","clk":"11895114667","pt":1724325422679,"mc":[{"id":"1.231812842","rc":[{"batb":[[2,1.07,36.01]],"ltp":1.39,"tv":83.04,"id":424676}]}]}
{"op":"mcm","clk":"11895114679","pt":1724325422884,"mc":[{"id":"1.231812842","rc":[{"batb":[[2,1.07,35.71]],"ltp":1.39,"tv":83.04,"id":424676}]}]}
{"op":"mcm","clk":"11895114861","pt":1724325425575,"mc":[{"id":"1.231812842","rc":[{"batl":[[1,8,1.46]],"ltp":3.55,"tv":18.73,"id":60443}]}]}
{"op":"mcm","clk":"11895115011","pt":1724325427688,"mc":[{"id":"1.231812842","rc":[{"batl":[[0,7.2,1.3]],"ltp":3.55,"tv":18.73,"id":60443}]}]}
{"op":"mcm","clk":"11895115036","pt":1724325427993,"mc":[{"id":"1.231812842","rc":[{"batb":[[0,1.39,2.58]],"ltp":1.39,"tv":83.04,"id":424676}]}]}
{"op":"mcm","clk":"11895115589","pt":1724325437397,"mc":[{"id":"1.231812842","rc":[{"batb":[[0,8,1.11],[1,4.1,1.95],[2,3.55,1.83]],"ltp":8.0,"tv":30.48,"id":424679}]}]}
{"op":"mcm","clk":"11895115802","pt":1724325440502,"mc":[{"id":"1.231812842","rc":[{"batl":[[0,10,1.3],[1,15,1.53],[2,15.5,4]],"ltp":8.0,"tv":30.48,"id":424679}]}]}
{"op":"mcm","clk":"11895116173","pt":1724325446301,"mc":[{"id":"1.231812842","rc":[{"batb":[[0,4.1,1.95],[1,3.55,1.83],[2,3.05,1.64]],"ltp":8.0,"tv":30.48,"id":424679}]}]}
{"op":"mcm","clk":"11895116816","pt":1724325456741,"mc":[{"id":"1.231812842","rc":[{"batl":[[0,9.8,1.3],[1,10,1],[2,15,1.53]],"ltp":8.0,"tv":30.48,"id":424679}]}]}
{"op":"mcm","clk":"11895122151","pt":1724325545720,"mc":[{"id":"1.231812842","rc":[{"batl":[[0,4.2,1.11],[1,9.8,1.3],[2,10,1]],"ltp":8.0,"tv":30.48,"id":424679}]}]}
{"op":"mcm","clk":"11895122180","pt":1724325546341,"mc":[{"id":"1.231812842","rc":[{"batl":[[1,10,1.3],[2,15,1.53]],"ltp":8.0,"tv":30.48,"id":424679}]}]}
{"op":"mcm","clk":"11895122631","pt":1724325554256,"mc":[{"id":"1.231812842","rc":[{"batl":[[0,10,1.3],[1,15,1.53],[2,15.5,4]],"ltp":8.0,"tv":30.48,"id":424679}]}]}
{"op":"mcm","clk":"11895123107","pt":1724325562437,"mc":[{"id":"1.231812842","rc":[{"batl":[[0,9.8,1.3],[1,10,1],[2,15,1.53]],"ltp":8.0,"tv":30.48,"id":424679}]}]}
{"op":"mcm","clk":"11895124206","pt":1724325582983,"mc":[{"id":"1.231812842","rc":[{"batb":[[0,9,1.11],[1,4.1,1.95],[2,3.55,1.83]],"ltp":8.0,"tv":30.48,"id":424679}]}]}
{"op":"mcm","clk":"11895124330","pt":1724325585399,"mc":[{"id":"1.231812842","rc":[{"batl":[[0,10,1.3],[1,15,1.53],[2,15.5,4]],"ltp":8.0,"tv":30.48,"id":424679}]}]}
{"op":"mcm","clk":"11895124570","pt":1724325590604,"mc":[{"id":"1.231812842","rc":[{"batb":[[0,4.1,1.95],[1,3.55,1.83],[2,3.05,1.64]],"ltp":8.0,"tv":30.48,"id":424679}]}]}
{"op":"mcm","clk":"11895125124","pt":1724325601413,"mc":[{"id":"1.231812842","rc":[{"batl":[[0,9.8,1.3],[1,10,1],[2,15,1.53]],"ltp":8.0,"tv":30.48,"id":424679}]}]}
{"op":"mcm","clk":"11895128703","pt":1724325662799,"mc":[{"id":"1.231812842","rc":[{"batl":[[0,9.8,1]],"ltp":8.0,"tv":30.48,"id":424679}]}]}
{"op":"mcm","clk":"11895130016","pt":1724325683918,"mc":[{"id":"1.231812842","rc":[{"batl":[[0,4.2,1.11],[1,9.8,1],[2,10,1]],"ltp":8.0,"tv":30.48,"id":424679}]}]}
{"op":"mcm","clk":"11895130096","pt":1724325685515,"mc":[{"id":"1.231812842","rc":[{"batl":[[1,10,1],[2,15,1.53]],"ltp":8.0,"tv":30.48,"id":424679}]}]}
{"op":"mcm","clk":"11895130452","pt":1724325691612,"mc":[{"id":"1.231812842","rc":[{"batl":[[0,10,1],[1,15,1.53],[2,15.5,4]],"ltp":8.0,"tv":30.48,"id":424679}]}]}
{"op":"mcm","clk":"11895130785","pt":1724325697434,"mc":[{"id":"1.231812842","rc":[{"batl":[[0,2.1,4.55]],"ltp":1.39,"tv":83.04,"id":424676}]}]}
{"op":"mcm","clk":"11895130880","pt":1724325699139,"mc":[{"id":"1.231812842","rc":[{"batl":[[0,2.08,1.13],[1,2.1,3.72],[2,2.5,20]],"ltp":1.39,"tv":83.04,"id":424676}]}]}
{"op":"mcm","clk":"11895131010","pt":1724325701653,"mc":[{"id":"1.231812842","rc":[{"batl":[[0,9.8,1],[1,10,1],[2,15,1.53]],"ltp":8.0,"tv":30.48,"id":424679}]}]}
{"op":"mcm","clk":"11895131053","pt":1724325702532,"mc":[{"id":"1.231812842","rc":[{"batl":[[0,2,1.07],[1,2.1,4.32]],"ltp":1.39,"tv":83.04,"id":424676}]}]}
{"op":"mcm","clk":"11895131414","pt":1724325708633,"mc":[{"id":"1.231812842","rc":[{"batb":[[1,3.55,1.53]],"ltp":8.0,"tv":30.48,"id":424679},{"batl":[[1,2.1,4.02]],"ltp":1.39,"tv":83.04,"id":424676}]}]}
{"op":"mcm","clk":"11895131430","pt":1724325708840,"mc":[{"id":"1.231812842","rc":[{"batb":[[0,3.05,2.53],[1,2.82,1.42],[2,2.62,1.33]],"ltp":3.55,"tv":18.73,"id":60443}]}]}
{"op":"mcm","clk":"11895131608","pt":1724325711668,"mc":[{"id":"1.231812842","rc":[{"batb":[[0,3.2,1.19],[1,3.05,1.64],[2,2.82,1.42]],"ltp":3.55,"tv":18.73,"id":60443}]}]}
{"op":"mcm","clk":"11895133054","pt":1724325734482,"mc":[{"id":"1.231812842","rc":[{"batb":[[0,9.4,1.11],[1,4.1,1.95],[2,3.55,1.53]],"ltp":8.0,"tv":30.48,"id":424679}]}]}
{"op":"mcm","clk":"11895133138","pt":1724325735668,"mc":[{"id":"1.231812842","rc":[{"batl":[[0,10,1],[1,15,1.53],[2,15.5,4]],"ltp":8.0,"tv":30.48,"id":424679}]}]}
{"op":"mcm","clk":"11895133414","pt":1724325739763,"mc":[{"id":"1.231812842","rc":[{"batb":[[2,1.07,36.71]],"ltp":1.39,"tv":83.04,"id":424676}]}]}
{"op":"mcm","clk":"11895133451","pt":1724325740282,"mc":[{"id":"1.231812842","rc":[{"batb":[[0,4.1,1.95],[1,3.55,1.53],[2,3.05,1.64]],"ltp":8.0,"tv":30.48,"id":424679},{"batb":[[0,1.39,2.28],[2,1.07,35.71]],"ltp":1.39,"tv":83.04,"id":424676},{"batl":[[0,7.2,1]],"ltp":3.55,"tv":18.73,"id":60443}]}]}
{"op":"mcm","clk":"11895133782","pt":1724325745413,"mc":[{"id":"1.231812842","rc":[{"batb":[[0,1.39,2.58]],"ltp":1.39,"tv":83.04,"id":424676},{"batl":[[0,7.2,1.3]],"ltp":3.55,"tv":18.73,"id":60443}]}]}
{"op":"mcm","clk":"11895133835","pt":1724325746183,"mc":[{"id":"1.231812842","rc":[{"batl":[[0,9.8,1],[1,10,1],[2,15,1.53]],"ltp":8.0,"tv":30.48,"id":424679}]}]}
{"op":"mcm","clk":"11895135010","pt":1724325765694,"mc":[{"id":"1.231812842","rc":[{"batl":[[0,1.41,2.66],[1,2,1.07],[2,2.1,4.02]],"ltp":1.39,"tv":83.04,"id":424676}]}]}
{"op":"mcm","clk":"11895135894","pt":1724325780342,"mc":[{"id":"1.231812842","rc":[{"trd":[[1.41,5.91]],"batb":[[0,1.39,2.98]],"batl":[[0,2,1.07],[1,2.1,4.02],[2,2.5,20]],"ltp":1.41,"tv":88.35,"id":424676}],"tv":137.58}]}
{"op":"mcm","clk":"11895137391","pt":1724325805847,"mc":[{"id":"1.231812842","rc":[{"batl":[[0,1.98,1.07],[1,2.1,4.55]],"ltp":1.41,"tv":88.35,"id":424676}]}]}
{"op":"mcm","clk":"11895137509","pt":1724325807658,"mc":[{"id":"1.231812842","rc":[{"trd":[[1.9,1.07],[1.98,1.06]],"batl":[[0,2.1,4.55],[1,2.5,20],[2,3.5,16]],"ltp":1.98,"tv":90.48,"id":424676}],"tv":139.71}]}
{"op":"mcm","clk":"11895137586","pt":1724325809050,"mc":[{"id":"1.231812842","rc":[{"batl":[[0,4.2,1.11],[1,9.8,1],[2,10,1]],"ltp":8.0,"tv":30.48,"id":424679}]}]}
{"op":"mcm","clk":"11895137860","pt":1724325813605,"mc":[{"id":"1.231812842","rc":[{"batl":[[1,10,1],[2,15,1]],"ltp":8.0,"tv":30.48,"id":424679}]}]}
{"op":"mcm","clk":"11895137931","pt":1724325814897,"mc":[{"id":"1.231812842","rc":[{"batl":[[1,10,1.53]],"ltp":8.0,"tv":30.48,"id":424679}]}]}
{"op":"mcm","clk":"11895138032","pt":1724325816701,"mc":[{"id":"1.231812842","rc":[{"batl":[[0,10,1.53],[1,15,1],[2,15.5,4]],"ltp":8.0,"tv":30.48,"id":424679}]}]}
{"op":"mcm","clk":"11895138463","pt":1724325824169,"mc":[{"id":"1.231812842","rc":[{"batl":[[0,9.8,1.53],[1,10,1],[2,15,1]],"ltp":8.0,"tv":30.48,"id":424679}]}]}
{"op":"mcm","clk":"11895138689","pt":1724325828382,"mc":[{"id":"1.231812842","rc":[{"batl":[[1,8,1]],"ltp":3.55,"tv":18.73,"id":60443}]}]}
{"op":"mcm","clk":"11895138861","pt":1724325831416,"mc":[{"id":"1.231812842","rc":[{"batl":[[0,2,1.07],[1,2.1,4.02],[2,2.5,20]],"ltp":1.98,"tv":90.48,"id":424676}]}]}
{"op":"mcm","clk":"11895138982","pt":1724325833513,"mc":[{"id":"1.231812842","rc":[{"batl":[[0,7.2,1.76]],"ltp":3.55,"tv":18.73,"id":60443}]}]}
{"op":"mcm","clk":"11895139292","pt":1724325838703,"mc":[{"id":"1.231812842","rc":[{"batb":[[0,1.95,2.66],[1,1.39,2.98],[2,1.08,31.25]],"ltp":1.98,"tv":90.48,"id":424676}]}]}
{"op":"mcm","clk":"11895139470","pt":1724325841428,"mc":[{"id":"1.231812842","rc":[{"batl":[[0,10,1.53],[1,15,1],[2,15.5,4]],"ltp":8.0,"tv":30.48,"id":424679},{"batl":[[0,8,1.76],[1,10,1],[2,15,1.53]],"ltp":3.55,"tv":18.73,"id":60443}]}]}
{"op":"mcm","clk":"11895140060","pt":1724325852003,"mc":[{"id":"1.231812842","rc":[{"batl":[[0,8.8,1],[1,10,1.53],[2,15,1]],"ltp":8.0,"tv":30.48,"id":424679}]}]}
{"op":"mcm","clk":"11895140422","pt":1724325858203,"mc":[{"id":"1.231812842","rc":[{"batl":[[0,2.1,4.55],[1,2.5,20],[2,3.5,16]],"ltp":1.98,"tv":90.48,"id":424676}]}]}
{"op":"mcm","clk":"11895140458","pt":1724325858824,"mc":[{"id":"1.231812842","rc":[{"batb":[[0,1.39,2.98],[1,1.08,31.25],[2,1.07,35.71]],"ltp":1.98,"tv":90.48,"id":424676}]}]}
{"op":"mcm","clk":"11895140734","pt":1724325863313,"mc":[{"id":"1.231812842","rc":[{"batl":[[0,1.96,1.07],[1,2.1,4.02],[2,2.5,20]],"ltp":1.98,"tv":90.48,"id":424676}]}]}
{"op":"mcm","clk":"11895140897","pt":1724325866455,"mc":[{"id":"1.231812842","rc":[{"batl":[[0,1.95,2.06],[1,2.1,4.55]],"ltp":1.98,"tv":90.48,"id":424676}]}]}
{"op":"mcm","clk":"11895141039","pt":1724325868721,"mc":[{"id":"1.231812842","rc":[{"batl":[[0,1.96,1.07],[1,2.1,4.02]],"ltp":1.98,"tv":90.48,"id":424676},{"batl":[[0,7.8,1.76],[1,8,1],[2,10,1]],"ltp":3.55,"tv":18.73,"id":60443}]}]}
{"op":"mcm","clk":"11895141197","pt":1724325871612,"mc":[{"id":"1.231812842","rc":[{"batl":[[0,2.1,4.55],[1,2.5,20],[2,3.5,16]],"ltp":1.98,"tv":90.48,"id":424676}]}]}
{"op":"mcm","clk":"11895141460","pt":1724325876737,"mc":[{"id":"1.231812842","rc":[{"batl":[[0,1.96,1.07],[1,2.1,4.02],[2,2.5,20]],"ltp":1.98,"tv":90.48,"id":424676}]}]}
{"op":"mcm","clk":"11895142108","pt":1724325888232,"mc":[{"id":"1.231812842","rc":[{"batb":[[0,8.2,1.11],[1,4.1,1.95],[2,3.55,1.53]],"ltp":8.0,"tv":30.48,"id":424679}]}]}
{"op":"mcm","clk":"11895142184","pt":1724325889673,"mc":[{"id":"1.231812842","rc":[{"batl":[[0,1.42,2.43],[1,1.96,1.07],[2,2.1,4.02]],"ltp":1.98,"tv":90.48,"id":424676}]}]}
{"op":"mcm","clk":"11895142294","pt":1724325891543,"mc":[{"id":"1.231812842","rc":[{"batl":[[0,10,1.53],[1,15,1],[2,15.5,4]],"ltp":8.0,"tv":30.48,"id":424679},{"batl":[[0,8,1.76],[1,10,1],[2,15,1.53]],"ltp":3.55,"tv":18.73,"id":60443}]}]}
{"op":"mcm","clk":"11895142438","pt":1724325893872,"mc":[{"id":"1.231812842","rc":[{"batb":[[0,4.1,1.95],[1,3.55,1.53],[2,3.05,1.64]],"ltp":8.0,"tv":30.48,"id":424679}]}]}
{"op":"mcm","clk":"11895142914","pt":1724325902150,"mc":[{"id":"1.231812842","rc":[{"batl":[[0,9.8,1.53],[1,10,1],[2,15,1]],"ltp":8.0,"tv":30.48,"id":424679},{"batl":[[0,7.8,1.76],[1,8,1],[2,10,1]],"ltp":3.55,"tv":18.73,"id":60443}]}]}
{"op":"mcm","clk":"11895143638","pt":1724325913973,"mc":[{"id":"1.231812842","rc":[{"batb":[[0,8.6,1.11],[1,4.1,1.95],[2,3.55,1.53]],"ltp":8.0,"tv":30.48,"id":424679}]}]}
{"op":"mcm","clk":"11895143845","pt":1724325917783,"mc":[{"id":"1.231812842","rc":[{"batb":[[0,4.1,1.95],[1,3.55,1.53],[2,3.05,1.64]],"ltp":8.0,"tv":30.48,"id":424679}]}]}
{"op":"mcm","clk":"11895145061","pt":1724325933327,"mc":[{"id":"1.231812842","rc":[{"trd":[[1.42,4.87]],"batb":[[0,1.41,1.01],[1,1.39,2.58],[2,1.08,31.25]],"batl":[[0,1.96,1.07],[1,2.1,4.02],[2,2.5,20]],"ltp":1.42,"tv":95.35,"id":424676}],"tv":144.57}]}
{"op":"mcm","clk":"11895145728","pt":1724325940002,"mc":[{"id":"1.231812842","rc":[{"batl":[[0,4.2,1.11],[1,9.8,1.53],[2,10,1]],"ltp":8.0,"tv":30.48,"id":424679}]}]}
{"op":"mcm","clk":"11895145851","pt":1724325941609,"mc":[{"id":"1.231812842","rc":[{"batl":[[1,10,1.53],[2,15,1]],"ltp":8.0,"tv":30.48,"id":424679}]}]}
{"op":"mcm","clk":"11895146045","pt":1724325944723,"mc":[{"id":"1.231812842","rc":[{"batl":[[0,10,1.53],[1,15,1],[2,15.5,4]],"ltp":8.0,"tv":30.48,"id":424679}]}]}
{"op":"mcm","clk":"11895146278","pt":1724325947716,"mc":[{"id":"1.231812842","rc":[{"batl":[[1,2.08,1.06],[2,2.1,3.72]],"ltp":1.42,"tv":95.35,"id":424676}]}]}
{"op":"mcm","clk":"11895146621","pt":1724325952231,"mc":[{"id":"1.231812842","rc":[{"batl":[[0,9.8,1.53],[1,10,1],[2,15,1]],"ltp":8.0,"tv":30.48,"id":424679}]}]}
{"op":"mcm","clk":"11895147154","pt":1724325960812,"mc":[{"id":"1.231812842","rc":[{"batb":[[0,1.39,2.98],[1,1.08,31.25],[2,1.07,35.71]],"ltp":1.42,"tv":95.35,"id":424676}]}]}
{"op":"mcm","clk":"11895147763","pt":1724325970630,"mc":[{"id":"1.231812842","rc":[{"batb":[[0,1.9,2.66],[1,1.39,2.98],[2,1.08,31.25]],"ltp":1.42,"tv":95.35,"id":424676}]}]}
{"op":"mcm","clk":"11895147832","pt":1724325971766,"mc":[{"id":"1.231812842","rc":[{"batl":[[1,2.1,4.48],[2,2.5,20]],"ltp":1.42,"tv":95.35,"id":424676}]}]}
{"op":"mcm","clk":"11895148011","pt":1724325975027,"mc":[{"id":"1.231812842","rc":[{"batl":[[0,10,1.53],[1,15,1],[2,15.5,4]],"ltp":8.0,"tv":30.48,"id":424679},{"batl":[[0,1.96,1.37]],"ltp":1.42,"tv":95.35,"id":424676},{"batl":[[0,8,1.76],[1,10,1],[2,15,1.53]],"ltp":3.55,"tv":18.73,"id":60443}]}]}
{"op":"mcm","clk":"11895148599","pt":1724325985572,"mc":[{"id":"1.231812842","rc":[{"batl":[[0,8.8,1],[1,10,1.53],[2,15,1]],"ltp":8.0,"tv":30.48,"id":424679},{"batb":[[0,3.05,2.53],[1,2.82,1.42],[2,2.62,1.33]],"ltp":3.55,"tv":18.73,"id":60443}]}]}
{"op":"mcm","clk":"11895148653","pt":1724325986255,"mc":[{"id":"1.231812842","rc":[{"batb":[[0,3.25,1.19],[1,3.05,1.64],[2,2.82,1.42]],"ltp":3.55,"tv":18.73,"id":60443}]}]}
{"op":"mcm","clk":"11895149914","pt":1724326008890,"mc":[{"id":"1.231812842","rc":[{"trd":[[1.9,6.38]],"batb":[[0,1.39,2.98],[1,1.08,31.25],[2,1.07,35.71]],"batl":[[0,1.95,1.23],[1,2.04,1.3],[2,2.1,3.72]],"ltp":1.9,"tv":100.66,"id":424676}],"tv":149.88}]}
{"op":"mcm","clk":"11895150200","pt":1724326013803,"mc":[{"id":"1.231812842","rc":[{"batl":[[1,2.1,4.25],[2,2.5,20]],"ltp":1.9,"tv":100.66,"id":424676}]}]}
{"op":"mcm","clk":"11895150438","pt":1724326019010,"mc":[{"id":"1.231812842","rc":[{"batl":[[0,7.8,1.76],[1,8,1],[2,10,1]],"ltp":3.55,"tv":18.73,"id":60443}]}]}
{"op":"mcm","clk":"11895152006","pt":1724326038342,"mc":[{"id":"1.231812842","rc":[{"batb":[[0,1.39,3.28]],"ltp":1.9,"tv":100.66,"id":424676},{"batl":[[0,7.6,1.06],[1,7.8,1],[2,8,1]],"ltp":3.55,"tv":18.73,"id":60443}]}]}
{"op":"mcm","clk":"11895152506","pt":1724326042738,"mc":[{"id":"1.231812842","rc":[{"batb":[[0,1.39,2.98]],"ltp":1.9,"tv":100.66,"id":424676},{"batl":[[0,8,1.76],[1,10,1],[2,15,1.53]],"ltp":3.55,"tv":18.73,"id":60443}]}]}
{"op":"mcm","clk":"11895153400","pt":1724326052421,"mc":[{"id":"1.231812842","rc":[{"batl":[[0,7.8,1.76],[1,8,1],[2,10,1]],"ltp":3.55,"tv":18.73,"id":60443}]}]}
{"op":"mcm","clk":"11895155447","pt":1724326075157,"mc":[{"id":"1.231812842","rc":[{"batb":[[0,8.4,1.11],[1,4.1,1.95],[2,3.55,1.53]],"batl":[[0,10,1.53],[1,15,1],[2,15.5,4]],"ltp":8.0,"tv":30.48,"id":424679},{"batl":[[0,8,1.76],[1,10,1],[2,15,1.53]],"ltp":3.55,"tv":18.73,"id":60443}]}]}
{"op":"mcm","clk":"11895156155","pt":1724326081685,"mc":[{"id":"1.231812842","rc":[{"batb":[[0,4.1,1.95],[1,3.55,1.53],[2,3.05,1.64]],"ltp":8.0,"tv":30.48,"id":424679}]}]}
{"op":"mcm","clk":"11895156602","pt":1724326085776,"mc":[{"id":"1.231812842","rc":[{"batl":[[0,6.6,1],[1,8,1.76],[2,10,1]],"ltp":3.55,"tv":18.73,"id":60443}]}]}
{"op":"mcm","clk":"11895157293","pt":1724326091388,"mc":[{"id":"1.231812842","rc":[{"batl":[[0,9.8,1.53],[1,10,1],[2,15,1]],"ltp":8.0,"tv":30.48,"id":424679}]}]}
{"op":"mcm","clk":"11895158955","pt":1724326108492,"mc":[{"id":"1.231812842","rc":[{"trd":[[9,1.07]],"batb":[[0,4.1,2.53]],"batl":[[0,9.8,1]],"ltp":9.0,"tv":31.55,"id":424679}],"tv":150.95}]}
{"op":"mcm","clk":"11895159344","pt":1724326113420,"mc":[{"id":"1.231812842","rc":[{"batb":[[0,4.1,1.95]],"ltp":9.0,"tv":31.55,"id":424679}]}]}
{"op":"mcm","clk":"11895160803","pt":1724326136225,"mc":[{"id":"1.231812842","rc":[{"batb":[[0,1.4,1.23],[1,1.39,2.28],[2,1.08,31.25]],"ltp":1.9,"tv":100.66,"id":424676}]}]}
{"op":"mcm","clk":"11895160890","pt":1724326137724,"mc":[{"id":"1.231812842","rc":[{"batb":[[0,1.4,2.23]],"ltp":1.9,"tv":100.66,"id":424676}]}]}
{"op":"mcm","clk":"11895161539","pt":1724326148465,"mc":[{"id":"1.231812842","rc":[{"batb":[[0,8.8,1.25],[1,4.1,1.95],[2,3.55,1.53]],"ltp":9.0,"tv":31.55,"id":424679}]}]}
{"op":"mcm","clk":"11895161822","pt":1724326152765,"mc":[{"id":"1.231812842","rc":[{"batb":[[0,4.1,1.95],[1,3.55,1.53],[2,3.05,1.64]],"ltp":9.0,"tv":31.55,"id":424679}]}]}
{"op":"mcm","clk":"11895163535","pt":1724326180968,"mc":[{"id":"1.231812842","rc":[{"batl":[[0,4.2,1.11],[1,9.8,1],[2,10,1]],"ltp":9.0,"tv":31.55,"id":424679}]}]}
{"op":"mcm","clk":"11895163826","pt":1724326186577,"mc":[{"id":"1.231812842","rc":[{"batl":[[0,10,1],[1,15,1],[2,15.5,4]],"ltp":9.0,"tv":31.55,"id":424679},{"batl":[[0,8,1.76],[1,10,1],[2,15,1.53]],"ltp":3.55,"tv":18.73,"id":60443}]}]}
{"op":"mcm","clk":"11895164444","pt":1724326197190,"mc":[{"id":"1.231812842","rc":[{"batl":[[0,9.8,1],[1,10,1],[2,15,1]],"ltp":9.0,"tv":31.55,"id":424679},{"batl":[[0,7.8,1.76],[1,8,1],[2,10,1]],"ltp":3.55,"tv":18.73,"id":60443}]}]}
{"op":"mcm","clk":"11895166748","pt":1724326232945,"mc":[{"id":"1.231812842","rc":[{"batb":[[0,8.8,1.11],[1,4.1,1.95],[2,3.55,1.53]],"ltp":9.0,"tv":31.55,"id":424679}]}]}
{"op":"mcm","clk":"11895166987","pt":1724326236752,"mc":[{"id":"1.231812842","rc":[{"batl":[[0,10,1],[1,15,1],[2,15.5,4]],"ltp":9.0,"tv":31.55,"id":424679},{"batl":[[0,8,1.76],[1,10,1],[2,15,1.53]],"ltp":3.55,"tv":18.73,"id":60443}]}]}
{"op":"mcm","clk":"11895167077","pt":1724326238147,"mc":[{"id":"1.231812842","rc":[{"batb":[[0,4.1,1.95],[1,3.55,1.53],[2,3.05,1.64]],"ltp":9.0,"tv":31.55,"id":424679}]}]}
{"op":"mcm","clk":"11895167702","pt":1724326247379,"mc":[{"id":"1.231812842","rc":[{"batl":[[0,9.8,1],[1,10,1],[2,15,1]],"ltp":9.0,"tv":31.55,"id":424679},{"batl":[[0,7.8,1.76],[1,8,1],[2,10,1]],"ltp":3.55,"tv":18.73,"id":60443}]}]}
{"op":"mcm","clk":"11895168447","pt":1724326258681,"mc":[{"id":"1.231812842","rc":[{"trd":[[1.43,1.07]],"batb":[[0,1.4,1.7]],"batl":[[0,1.42,1.9],[1,1.95,1.23],[2,2.1,4.25]],"ltp":1.43,"tv":101.72,"id":424676}],"tv":152.02}]}
{"op":"mcm","clk":"11895169180","pt":1724326270716,"mc":[{"id":"1.231812842","rc":[{"batb":[[0,1.39,2.98],[1,1.08,31.25],[2,1.07,35.71]],"batl":[[0,1.95,1.23],[1,2.1,4.25],[2,2.5,20]],"ltp":1.43,"tv":101.72,"id":424676}]}]}
{"op":"mcm","clk":"11895169243","pt":1724326271595,"mc":[{"id":"1.231812842","rc":[{"batb":[[0,1.42,3.05],[1,1.39,2.98],[2,1.08,31.25]],"ltp":1.43,"tv":101.72,"id":424676}]}]}
{"op":"mcm","clk":"11895169274","pt":1724326272013,"mc":[{"id":"1.231812842","rc":[{"batl":[[0,4.2,1.11],[1,9.8,1],[2,10,1]],"ltp":9.0,"tv":31.55,"id":424679}]}]}
{"op":"mcm","clk":"11895169462","pt":1724326274283,"mc":[{"id":"1.231812842","rc":[{"batb":[[0,1.41,1.16],[1,1.39,2.58]],"batl":[[0,1.96,1.46],[1,2.1,3.72]],"ltp":1.43,"tv":101.72,"id":424676}]}]}
{"op":"mcm","clk":"11895169560","pt":1724326275881,"mc":[{"id":"1.231812842","rc":[{"batl":[[1,10,1],[2,15,1]],"ltp":9.0,"tv":31.55,"id":424679},{"batb":[[0,1.45,1],[1,1.41,1.16],[2,1.39,2.58]],"ltp":1.43,"tv":101.72,"id":424676}]}]}
{"op":"mcm","clk":"11895169630","pt":1724326277323,"mc":[{"id":"1.231812842","rc":[{"batb":[[1,1.39,2.98],[2,1.08,31.25]],"ltp":1.43,"tv":101.72,"id":424676}]}]}
{"op":"mcm","clk":"11895169721","pt":1724326278891,"mc":[{"id":"1.231812842","rc":[{"batl":[[0,10,1],[1,15,1],[2,15.5,4]],"ltp":9.0,"tv":31.55,"id":424679}]}]}
{"op":"mcm","clk":"11895169794","pt":1724326280086,"mc":[{"id":"1.231812842","rc":[{"batb":[[0,1.39,2.98],[1,1.08,31.25],[2,1.07,35.71]],"ltp":1.43,"tv":101.72,"id":424676}]}]}
{"op":"mcm","clk":"11895169872","pt":1724326281318,"mc":[{"id":"1.231812842","rc":[{"batl":[[0,1.94,1.23],[1,2.1,4.25]],"ltp":1.43,"tv":101.72,"id":424676},{"batb":[[0,3.05,2.53],[1,2.82,1.42],[2,2.62,1.33]],"ltp":3.55,"tv":18.73,"id":60443}]}]}
{"op":"mcm","clk":"11895169933","pt":1724326282403,"mc":[{"id":"1.231812842","rc":[{"batb":[[0,1.41,1.16],[1,1.39,2.58],[2,1.08,31.25]],"ltp":1.43,"tv":101.72,"id":424676}]}]}
{"op":"mcm","clk":"11895170168","pt":1724326286329,"mc":[{"id":"1.231812842","rc":[{"batl":[[0,9.8,1],[1,10,1],[2,15,1]],"ltp":9.0,"tv":31.55,"id":424679}]}]}
{"op":"mcm","clk":"11895170340","pt":1724326288707,"mc":[{"id":"1.231812842","rc":[{"batl":[[0,1.92,1.37],[1,2.1,4.55]],"ltp":1.43,"tv":101.72,"id":424676}]}]}
{"op":"mcm","clk":"11895170958","pt":1724326298223,"mc":[{"id":"1.231812842","rc":[{"batb":[[1,1.4,1.3],[2,1.39,2.28]],"ltp":1.43,"tv":101.72,"id":424676}]}]}
{"op":"mcm","clk":"11895171482","pt":1724326305853,"mc":[{"id":"1.231812842","rc":[{"batb":[[0,4.1,2.48]],"ltp":9.0,"tv":31.55,"id":424679}]}]}
{"op":"mcm","clk":"11895171574","pt":1724326307250,"mc":[{"id":"1.231812842","rc":[{"batb":[[1,1.4,1]],"ltp":1.43,"tv":101.72,"id":424676},{"batl":[[0,7.8,1.46]],"ltp":3.55,"tv":18.73,"id":60443}]}]}
{"op":"mcm","clk":"11895172025","pt":1724326313527,"mc":[{"id":"1.231812842","rc":[{"batb":[[0,1.42,1.06],[1,1.4,1.4]],"ltp":1.43,"tv":101.72,"id":424676}]}]}
{"op":"mcm","clk":"11895172459","pt":1724326318530,"mc":[{"id":"1.231812842","rc":[{"batb":[[0,9,1.25],[1,4.1,2.48],[2,3.55,1.53]],"ltp":9.0,"tv":31.55,"id":424679}]}]}
{"op":"mcm","clk":"11895172694","pt":1724326320337,"mc":[{"id":"1.231812842","rc":[{"batl":[[0,10,1],[1,15,1],[2,15.5,4]],"ltp":9.0,"tv":31.55,"id":424679},{"batl":[[0,8,1.46],[1,10,1],[2,15,1.53]],"ltp":3.55,"tv":18.73,"id":60443}]}]}
{"op":"mcm","clk":"11895172960","pt":1724326324774,"mc":[{"id":"1.231812842","rc":[{"batb":[[0,4.1,2.48],[1,3.55,1.53],[2,3.05,1.64]],"ltp":9.0,"tv":31.55,"id":424679}]}]}
{"op":"mcm","clk":"11895173357","pt":1724326330946,"mc":[{"id":"1.231812842","rc":[{"batl":[[0,9.8,1],[1,10,1],[2,15,1]],"ltp":9.0,"tv":31.55,"id":424679},{"batl":[[0,7.8,1.46],[1,8,1],[2,10,1]],"ltp":3.55,"tv":18.73,"id":60443}]}]}
{"op":"mcm","clk":"11895175941","pt":1724326370184,"mc":[{"id":"1.231812842","rc":[{"batb":[[0,1.42,2.06]],"ltp":1.43,"tv":101.72,"id":424676}]}]}
{"op":"mcm","clk":"11895176608","pt":1724326381928,"mc":[{"id":"1.231812842","rc":[{"trd":[[4.4,1.07]],"batb":[[0,4.1,1.95]],"batl":[[0,9.8,1.58]],"ltp":4.4,"tv":32.62,"id":424679}],"tv":153.08}]}
{"op":"mcm","clk":"11895176821","pt":1724326385515,"mc":[{"id":"1.231812842","rc":[{"batl":[[0,9.8,1]],"ltp":4.4,"tv":32.62,"id":424679}]}]}
{"op":"mcm","clk":"11895176930","pt":1724326387006,"mc":[{"id":"1.231812842","rc":[{"batb":[[0,4.2,4],[1,4.1,1.95],[2,3.55,1.53]],"ltp":4.4,"tv":32.62,"id":424679}]}]}
{"op":"mcm","clk":"11895177089","pt":1724326389330,"mc":[{"id":"1.231812842","rc":[{"batb":[[0,4.1,1.95],[1,3.55,1.53],[2,3.05,1.64]],"ltp":4.4,"tv":32.62,"id":424679},{"batl":[[0,1.94,1.23],[1,2.1,4.25]],"ltp":1.43,"tv":101.72,"id":424676}]}]}
{"op":"mcm","clk":"11895177385","pt":1724326393929,"mc":[{"id":"1.231812842","rc":[{"batl":[[0,1.92,1.37],[1,2.1,4.55]],"ltp":1.43,"tv":101.72,"id":424676}]}]}
{"op":"mcm","clk":"11895177836","pt":1724326399039,"mc":[{"id":"1.231812842","rc":[{"batb":[[1,1.4,1]],"ltp":1.43,"tv":101.72,"id":424676}]}]}
{"op":"mcm","clk":"11895178032","pt":1724326401832,"mc":[{"id":"1.231812842","rc":[{"batl":[[0,9.8,1.53]],"ltp":4.4,"tv":32.62,"id":424679}]}]}
{"op":"mcm","clk":"11895178967","pt":1724326416658,"mc":[{"id":"1.231812842","rc":[{"trd":[[1.9,7.17]],"batb":[[0,1.9,1.6],[1,1.42,2.06],[2,1.4,1]],"batl":[[0,1.96,1.37],[1,2.1,3.72]],"ltp":1.9,"tv":102.52,"id":424676}],"tv":153.88}]}
{"op":"mcm","clk":"11895179166","pt":1724326419534,"mc":[{"id":"1.231812842","rc":[{"batl":[[0,4.3,1.11],[1,9.8,1.53],[2,10,1]],"ltp":4.4,"tv":32.62,"id":424679}]}]}
{"op":"mcm","clk":"11895179234","pt":1724326420562,"mc":[{"id":"1.231812842","rc":[{"batl":[[1,10,1.53],[2,15,1]],"ltp":4.4,"tv":32.62,"id":424679},{"batl":[[0,8,1.46],[1,10,1],[2,15,1.53]],"ltp":3.55,"tv":18.73,"id":60443}]}]}
{"op":"mcm","clk":"11895179330","pt":1724326421972,"mc":[{"id":"1.231812842","rc":[{"batl":[[0,2.1,4.55],[1,2.5,20],[2,3.5,16]],"ltp":1.9,"tv":102.52,"id":424676}]}]}
{"op":"mcm","clk":"11895179646","pt":1724326427055,"mc":[{"id":"1.231812842","rc":[{"batl":[[0,10,1.53],[1,15,1],[2,15.5,4]],"ltp":4.4,"tv":32.62,"id":424679},{"trd":[[1.9,8.24]],"batb":[[0,1.9,1.06]],"ltp":1.9,"tv":103.58,"id":424676}],"tv":154.94}]}
{"op":"mcm","clk":"11895180290","pt":1724326436760,"mc":[{"id":"1.231812842","rc":[{"batl":[[0,9.8,1.53],[1,10,1],[2,15,1]],"ltp":4.4,"tv":32.62,"id":424679}]}]}
{"op":"mcm","clk":"11895180547","pt":1724326440763,"mc":[{"id":"1.231812842","rc":[{"batb":[[0,1.42,2.06],[1,1.4,1],[2,1.39,2.28]],"ltp":1.9,"tv":103.58,"id":424676}]}]}
{"op":"mcm","clk":"11895180682","pt":1724326442687,"mc":[{"id":"1.231812842","rc":[{"batl":[[0,1.96,1.37],[1,2.1,3.72],[2,2.5,20]],"ltp":1.9,"tv":103.58,"id":424676},{"batl":[[0,7.8,1.46],[1,8,1],[2,10,1]],"ltp":3.55,"tv":18.73,"id":60443}]}]}
{"op":"mcm","clk":"11895180905","pt":1724326445483,"mc":[{"id":"1.231812842","rc":[{"batb":[[0,3.1,1.19],[1,3.05,1.64],[2,2.82,1.42]],"ltp":3.55,"tv":18.73,"id":60443}]}]}
{"op":"mcm","clk":"11895181575","pt":1724326455278,"mc":[{"id":"1.231812842","rc":[{"batb":[[0,1.44,1.3],[1,1.42,1.3],[2,1.4,1]],"ltp":1.9,"tv":103.58,"id":424676}]}]}
{"op":"mcm","clk":"11895182098","pt":1724326462712,"mc":[{"id":"1.231812842","rc":[{"trd":[[1.46,1.07]],"batb":[[0,1.42,2.06],[1,1.4,1],[2,1.39,2.28]],"batl":[[0,1.9,1.42],[1,2.1,4.55]],"ltp":1.46,"tv":104.65,"id":424676}],"tv":156.01}]}
{"op":"mcm","clk":"11895182667","pt":1724326471791,"mc":[{"id":"1.231812842","rc":[{"batl":[[0,1.96,1.37],[1,2.1,3.72]],"ltp":1.46,"tv":104.65,"id":424676}]}]}
{"op":"mcm","clk":"11895182839","pt":1724326474788,"mc":[{"id":"1.231812842","rc":[{"batl":[[0,2.1,4.55],[1,2.5,20],[2,3.5,16]],"ltp":1.46,"tv":104.65,"id":424676}]}]}
{"op":"mcm","clk":"11895182959","pt":1724326477009,"mc":[{"id":"1.231812842","rc":[{"batl":[[0,1.46,1.33],[1,2.1,4.55],[2,2.5,20]],"ltp":1.46,"tv":104.65,"id":424676}]}]}
{"op":"mcm","clk":"11895183170","pt":1724326479916,"mc":[{"id":"1.231812842","rc":[{"batl":[[1,1.96,1.37],[2,2.1,3.72]],"ltp":1.46,"tv":104.65,"id":424676}]}]}
{"op":"mcm","clk":"11895183424","pt":1724326483717,"mc":[{"id":"1.231812842","rc":[{"batb":[[0,1.42,1.06]],"ltp":1.46,"tv":104.65,"id":424676}]}]}
{"op":"mcm","clk":"11895183641","pt":1724326486909,"mc":[{"id":"1.231812842","rc":[{"trd":[[1.46,3.72]],"batb":[[0,1.46,1.72],[1,1.42,1.06],[2,1.4,1]],"batl":[[0,1.96,1.37],[1,2.1,3.72],[2,2.5,20]],"ltp":1.46,"tv":107.3,"id":424676}],"tv":158.66}]}
{"op":"mcm","clk":"11895183742","pt":1724326488814,"mc":[{"id":"1.231812842","rc":[{"batb":[[0,1.47,1],[1,1.46,1.72],[2,1.42,1.06]],"ltp":1.46,"tv":107.3,"id":424676}]}]}
{"op":"mcm","clk":"11895183860","pt":1724326490822,"mc":[{"id":"1.231812842","rc":[{"batb":[[0,9,1.11],[1,4.1,1.95],[2,3.55,1.53]],"ltp":4.4,"tv":32.62,"id":424679}]}]}
{"op":"mcm","clk":"11895183998","pt":1724326492904,"mc":[{"id":"1.231812842","rc":[{"batl":[[0,10,1.53],[1,15,1],[2,15.5,4]],"ltp":4.4,"tv":32.62,"id":424679},{"batl":[[0,8,1.46],[1,10,1],[2,15,1.53]],"ltp":3.55,"tv":18.73,"id":60443}]}]}
{"op":"mcm","clk":"11895184237","pt":1724326496427,"mc":[{"id":"1.231812842","rc":[{"batb":[[0,4.1,1.95],[1,3.55,1.53],[2,3.05,1.64]],"ltp":4.4,"tv":32.62,"id":424679},{"batb":[[0,1.46,1.72],[1,1.42,1.06],[2,1.4,1]],"ltp":1.46,"tv":107.3,"id":424676}]}]}
{"op":"mcm","clk":"11895184272","pt":1724326497003,"mc":[{"id":"1.231812842","rc":[{"batb":[[0,1.44,1.72],[1,1.4,1.3],[2,1.39,2.28]],"ltp":1.46,"tv":107.3,"id":424676}]}]}
{"op":"mcm","clk":"11895184682","pt":1724326503547,"mc":[{"id":"1.231812842","rc":[{"batl":[[0,9.8,1.53],[1,10,1],[2,15,1]],"ltp":4.4,"tv":32.62,"id":424679},{"batl":[[0,7.8,1.46],[1,8,1],[2,10,1]],"ltp":3.55,"tv":18.73,"id":60443}]}]}
{"op":"mcm","clk":"11895186287","pt":1724326527650,"mc":[{"id":"1.231812842","rc":[{"trd":[[1.86,1.07]],"batb":[[0,1.46,1.75],[1,1.42,1.06],[2,1.4,1]],"batl":[[0,2.1,4.55],[1,2.5,20],[2,3.5,16]],"ltp":1.86,"tv":108.37,"id":424676}],"tv":159.73}]}
{"op":"mcm","clk":"11895186570","pt":1724326531586,"mc":[{"id":"1.231812842","rc":[{"batb":[[2,1.41,1]],"ltp":1.86,"tv":108.37,"id":424676}]}]}
{"op":"mcm","clk":"11895186907","pt":1724326536965,"mc":[{"id":"1.231812842","rc":[{"batb":[[0,1.44,1.72],[1,1.41,1.3],[2,1.4,1]],"ltp":1.86,"tv":108.37,"id":424676}]}]}
{"op":"mcm","clk":"11895187034","pt":1724326538795,"mc":[{"id":"1.231812842","rc":[{"batl":[[0,4.3,1.11],[1,9.8,1.53],[2,10,1]],"ltp":4.4,"tv":32.62,"id":424679}]}]}
{"op":"mcm","clk":"11895187278","pt":1724326542109,"mc":[{"id":"1.231812842","rc":[{"batb":[[0,1.86,1.33],[1,1.44,1.72],[2,1.41,1.3]],"ltp":1.86,"tv":108.37,"id":424676},{"batl":[[0,7.8,1.76]],"ltp":3.55,"tv":18.73,"id":60443}]}]}
{"op":"mcm","clk":"11895187348","pt":1724326543022,"mc":[{"id":"1.231812842","rc":[{"batl":[[1,10,1.53],[2,15,1]],"ltp":4.4,"tv":32.62,"id":424679},{"batl":[[0,8,1.76],[1,10,1],[2,15,1.53]],"ltp":3.55,"tv":18.73,"id":60443}]}]}
{"op":"mcm","clk":"11895187497","pt":1724326545475,"mc":[{"id":"1.231812842","rc":[{"batl":[[0,10,1.53],[1,15,1],[2,15.5,4]],"ltp":4.4,"tv":32.62,"id":424679}]}]}
{"op":"mcm","clk":"11895188014","pt":1724326553716,"mc":[{"id":"1.231812842","rc":[{"batl":[[0,9.8,1.53],[1,10,1],[2,15,1]],"ltp":4.4,"tv":32.62,"id":424679},{"batl":[[0,6.6,1],[1,8,1.76],[2,10,1]],"ltp":3.55,"tv":18.73,"id":60443}]}]}
{"op":"mcm","clk":"11895188095","pt":1724326554810,"mc":[{"id":"1.231812842","rc":[{"batb":[[0,1.44,1.72],[1,1.41,1.3],[2,1.4,1]],"ltp":1.86,"tv":108.37,"id":424676}]}]}
{"op":"mcm","clk":"11895188434","pt":1724326560413,"mc":[{"id":"1.231812842","rc":[{"batb":[[0,1.46,1.72],[1,1.42,1.06],[2,1.41,1]],"ltp":1.86,"tv":108.37,"id":424676}]}]}
{"op":"mcm","clk":"11895188502","pt":1724326561504,"mc":[{"id":"1.231812842","rc":[{"batl":[[0,1.96,1.37],[1,2.1,3.72],[2,2.5,20]],"ltp":1.86,"tv":108.37,"id":424676}]}]}
{"op":"mcm","clk":"11895189988","pt":1724326587729,"mc":[{"id":"1.231812842","rc":[{"batl":[[0,1.48,1.77],[1,1.96,1.37],[2,2.1,3.72]],"ltp":1.86,"tv":108.37,"id":424676}]}]}
{"op":"mcm","clk":"11895190245","pt":1724326593039,"mc":[{"id":"1.231812842","rc":[{"batl":[[0,8,1.76],[1,10,1],[2,15,1.53]],"ltp":3.55,"tv":18.73,"id":60443}]}]}
{"op":"mcm","clk":"11895190461","pt":1724326597055,"mc":[{"id":"1.231812842","rc":[{"batl":[[1,1.95,1.13],[2,2.1,4.25]],"ltp":1.86,"tv":108.37,"id":424676}]}]}
{"op":"mcm","clk":"11895190608","pt":1724326599735,"mc":[{"id":"1.231812842","rc":[{"batl":[[1,1.96,1.37],[2,2.1,3.72]],"ltp":1.86,"tv":108.37,"id":424676}]}]}
{"op":"mcm","clk":"11895190822","pt":1724326603661,"mc":[{"id":"1.231812842","rc":[{"batl":[[0,7.8,1.76],[1,8,1],[2,10,1]],"ltp":3.55,"tv":18.73,"id":60443}]}]}
{"op":"mcm","clk":"11895190857","pt":1724326604177,"mc":[{"id":"1.231812842","rc":[{"batb":[[2,1.4,1]],"ltp":1.86,"tv":108.37,"id":424676}]}]}
{"op":"mcm","clk":"11895190897","pt":1724326604852,"mc":[{"id":"1.231812842","rc":[{"batl":[[0,1.96,1.37],[1,2.1,3.72],[2,2.5,20]],"ltp":1.86,"tv":108.37,"id":424676}]}]}
{"op":"mcm","clk":"11895191143","pt":1724326609275,"mc":[{"id":"1.231812842","rc":[{"batb":[[0,1.51,1],[1,1.46,1.72],[2,1.42,1.06]],"ltp":1.86,"tv":108.37,"id":424676}]}]}
{"op":"mcm","clk":"11895191233","pt":1724326611076,"mc":[{"id":"1.231812842","rc":[{"batb":[[0,1.46,1.72],[1,1.42,1.06],[2,1.4,1]],"ltp":1.86,"tv":108.37,"id":424676}]}]}
{"op":"mcm","clk":"11895192235","pt":1724326629693,"mc":[{"id":"1.231812842","rc":[{"batl":[[0,1.48,1.77],[1,1.96,1.37],[2,2.1,3.72]],"ltp":1.86,"tv":108.37,"id":424676}]}]}
{"op":"mcm","clk":"11895192435","pt":1724326633377,"mc":[{"id":"1.231812842","rc":[{"batb":[[1,1.4,1.76],[2,1.39,2.28]],"ltp":1.86,"tv":108.37,"id":424676}]}]}
{"op":"mcm","clk":"11895192653","pt":1724326637000,"mc":[{"id":"1.231812842","rc":[{"batb":[[1,1.42,1.76],[2,1.4,1]],"ltp":1.86,"tv":108.37,"id":424676}]}]}
{"op":"mcm","clk":"11895192781","pt":1724326639692,"mc":[{"id":"1.231812842","rc":[{"batb":[[0,1.46,2.02]],"ltp":1.86,"tv":108.37,"id":424676}]}]}
{"op":"mcm","clk":"11895192940","pt":1724326642791,"mc":[{"id":"1.231812842","rc":[{"batl":[[0,1.96,1.37],[1,2.1,3.72],[2,2.5,20]],"ltp":1.86,"tv":108.37,"id":424676}]}]}
{"op":"mcm","clk":"11895195712","pt":1724326689681,"mc":[{"id":"1.231812842","rc":[{"trd":[[1.86,2.13]],"batb":[[0,1.92,1.24],[1,1.46,2.02],[2,1.42,1.76]],"batl":[[0,2.1,4.55],[1,2.5,20],[2,3.5,16]],"ltp":1.86,"tv":109.44,"id":424676}],"tv":160.8}]}
{"op":"mcm","clk":"11895195937","pt":1724326693263,"mc":[{"id":"1.231812842","rc":[{"batl":[[0,10,1.53],[1,15,1],[2,15.5,4]],"ltp":4.4,"tv":32.62,"id":424679},{"batl":[[0,8,1.76],[1,10,1],[2,15,1.53]],"ltp":3.55,"tv":18.73,"id":60443}]}]}
{"op":"mcm","clk":"11895196535","pt":1724326703963,"mc":[{"id":"1.231812842","rc":[{"batl":[[0,9.2,1],[1,10,1.53],[2,15,1]],"ltp":4.4,"tv":32.62,"id":424679},{"batl":[[0,6.6,1],[1,8,1.76],[2,10,1]],"ltp":3.55,"tv":18.73,"id":60443}]}]}
{"op":"mcm","clk":"11895197084","pt":1724326712702,"mc":[{"id":"1.231812842","rc":[{"batb":[[0,1.46,2.02],[1,1.42,1.76],[2,1.4,1]],"ltp":1.86,"tv":109.44,"id":424676}]}]}
{"op":"mcm","clk":"11895197346","pt":1724326717510,"mc":[{"id":"1.231812842","rc":[{"batl":[[0,1.92,1],[1,2.1,4.55],[2,2.5,20]],"ltp":1.86,"tv":109.44,"id":424676}]}]}
{"op":"mcm","clk":"11895197505","pt":1724326720108,"mc":[{"id":"1.231812842","rc":[{"batl":[[0,2.1,4.55],[1,2.5,20],[2,3.5,16]],"ltp":1.86,"tv":109.44,"id":424676}]}]}
{"op":"mcm","clk":"11895197664","pt":1724326722129,"mc":[{"id":"1.231812842","rc":[{"batl":[[1,10,1]],"ltp":4.4,"tv":32.62,"id":424679}]}]}
{"op":"mcm","clk":"11895197902","pt":1724326726316,"mc":[{"id":"1.231812842","rc":[{"batb":[[0,1.46,1.26]],"ltp":1.86,"tv":109.44,"id":424676},{"batb":[[0,3.05,2.53],[1,2.82,1.42],[2,2.62,1.33]],"ltp":3.55,"tv":18.73,"id":60443}]}]}
{"op":"mcm","clk":"11895197956","pt":1724326727195,"mc":[{"id":"1.231812842","rc":[{"batl":[[0,9.2,1.53]],"ltp":4.4,"tv":32.62,"id":424679}]}]}
{"op":"mcm","clk":"11895198205","pt":1724326731704,"mc":[{"id":"1.231812842","rc":[{"batb":[[0,1.47,1.06],[1,1.44,1.72],[2,1.42,1]],"ltp":1.86,"tv":109.44,"id":424676}]}]}
{"op":"mcm","clk":"11895198502","pt":1724326736809,"mc":[{"id":"1.231812842","rc":[{"batb":[[0,3.1,1.19],[1,3.05,1.64],[2,2.82,1.42]],"ltp":3.55,"tv":18.73,"id":60443}]}]}
{"op":"mcm","clk":"11895198972","pt":1724326744741,"mc":[{"id":"1.231812842","rc":[{"batl":[[0,1.5,1.77],[1,2.1,4.55],[2,2.5,20]],"ltp":1.86,"tv":109.44,"id":424676}]}]}
{"op":"mcm","clk":"11895199214","pt":1724326749026,"mc":[{"id":"1.231812842","rc":[{"batl":[[0,8,1.76],[1,10,1],[2,15,1.53]],"ltp":3.55,"tv":18.73,"id":60443}]}]}
{"op":"mcm","clk":"11895199756","pt":1724326759569,"mc":[{"id":"1.231812842","rc":[{"batl":[[0,7.8,1.76],[1,8,1],[2,10,1]],"ltp":3.55,"tv":18.73,"id":60443}]}]}
{"op":"mcm","clk":"11895199774","pt":1724326759838,"mc":[{"id":"1.231812842","rc":[{"batl":[[0,2.1,4.55],[1,2.5,20],[2,3.5,16]],"ltp":1.86,"tv":109.44,"id":424676}]}]}
{"op":"mcm","clk":"11895201110","pt":1724326782680,"mc":[{"id":"1.231812842","rc":[{"batb":[[0,1.9,1.77],[1,1.47,1.06],[2,1.44,1.72]],"ltp":1.86,"tv":109.44,"id":424676}]}]}
{"op":"mcm","clk":"11895201440","pt":1724326788764,"mc":[{"id":"1.231812842","rc":[{"batl":[[0,10,1.53],[1,15,1],[2,15.5,4]],"ltp":4.4,"tv":32.62,"id":424679},{"batb":[[0,1.47,1.06],[1,1.44,1.72],[2,1.42,1]],"ltp":1.86,"tv":109.44,"id":424676}]}]}
{"op":"mcm","clk":"11895202024","pt":1724326798499,"mc":[{"id":"1.231812842","rc":[{"batl":[[0,9.8,1.53],[1,10,1],[2,15,1]],"ltp":4.4,"tv":32.62,"id":424679}]}]}
{"op":"mcm","clk":"11895202047","pt":1724326798914,"mc":[{"id":"1.231812842","rc":[{"batb":[[2,1.4,1]],"ltp":1.86,"tv":109.44,"id":424676}]}]}
{"op":"mcm","clk":"11895202783","pt":1724326812225,"mc":[{"id":"1.231812842","rc":[{"trd":[[1.47,0.48],[1.48,4.88]],"batb":[[0,1.46,1.02],[1,1.4,1.76],[2,1.39,2.28]],"ltp":1.47,"tv":111.44,"id":424676}],"tv":162.8}]}
{"op":"mcm","clk":"11895203002","pt":1724326816099,"mc":[{"id":"1.231812842","rc":[{"batl":[[0,7.6,1.06],[1,7.8,1],[2,8,1]],"ltp":3.55,"tv":18.73,"id":60443}]}]}
{"op":"mcm","clk":"11895203076","pt":1724326817537,"mc":[{"id":"1.231812842","rc":[{"batl":[[0,7.8,1.76],[1,8,1],[2,10,1]],"ltp":3.55,"tv":18.73,"id":60443}]}]}
{"op":"mcm","clk":"11895203383","pt":1724326822525,"mc":[{"id":"1.231812842","rc":[{"batl":[[0,1.96,1.11],[1,2.1,3.72],[2,2.5,20]],"ltp":1.47,"tv":111.44,"id":424676}]}]}
{"op":"mcm","clk":"11895207510","pt":1724326893616,"mc":[{"id":"1.231812842","rc":[{"batl":[[0,2.1,4.53],[1,2.5,20],[2,3.5,16]],"ltp":1.47,"tv":111.44,"id":424676}]}]}
{"op":"mcm","clk":"11895207602","pt":1724326895010,"mc":[{"id":"1.231812842","rc":[{"batl":[[0,1.96,1.11],[1,2.1,3.72],[2,2.5,20]],"ltp":1.47,"tv":111.44,"id":424676}]}]}
{"op":"mcm","clk":"11895209924","pt":1724326939668,"mc":[{"id":"1.231812842","rc":[{"batb":[[0,1.44,1.72],[1,1.4,1]],"ltp":1.47,"tv":111.44,"id":424676}]}]}
{"op":"mcm","clk":"11895210202","pt":1724326944175,"mc":[{"id":"1.231812842","rc":[{"batb":[[0,1.46,1.26],[1,1.4,1.76]],"ltp":1.47,"tv":111.44,"id":424676}]}]}
{"op":"mcm","clk":"11895224466","pt":1724327036659,"mc":[{"id":"1.231812842","rc":[{"batb":[[0,3.05,2.53],[1,2.82,1.42],[2,2.62,1.33]],"ltp":3.55,"tv":18.73,"id":60443}]}]}
{"op":"mcm","clk":"11895224858","pt":1724327043381,"mc":[{"id":"1.231812842","rc":[{"batb":[[0,3.15,1.19],[1,3.05,1.64],[2,2.82,1.42]],"ltp":3.55,"tv":18.73,"id":60443}]}]}
{"op":"mcm","clk":"11895228465","pt":1724327115546,"mc":[{"id":"1.231812842","rc":[{"batl":[[0,7.8,1.46]],"ltp":3.55,"tv":18.73,"id":60443}]}]}
{"op":"mcm","clk":"11895228760","pt":1724327120555,"mc":[{"id":"1.231812842","rc":[{"batl":[[0,7.8,1.76]],"ltp":3.55,"tv":18.73,"id":60443}]}]}
{"op":"mcm","clk":"11895232385","pt":1724327192267,"mc":[{"id":"1.231812842","rc":[{"batl":[[0,2.1,4.53],[1,2.5,20],[2,3.5,16]],"ltp":1.47,"tv":111.44,"id":424676}]}]}
{"op":"mcm","clk":"11895232563","pt":1724327196440,"mc":[{"id":"1.231812842","rc":[{"batl":[[0,1.96,1.11],[1,2.1,3.72],[2,2.5,20]],"ltp":1.47,"tv":111.44,"id":424676}]}]}
{"op":"mcm","clk":"11895235019","pt":1724327239119,"mc":[{"id":"1.231812842","rc":[{"batb":[[0,1.44,1.72],[1,1.4,1]],"ltp":1.47,"tv":111.44,"id":424676}]}]}
{"op":"mcm","clk":"11895235456","pt":1724327246801,"mc":[{"id":"1.231812842","rc":[{"batb":[[0,1.46,1.26],[1,1.4,1.76]],"ltp":1.47,"tv":111.44,"id":424676}]}]}
{"op":"mcm","clk":"11895241554","pt":1724327356521,"mc":[{"id":"1.231812842","rc":[{"batb":[[0,3.2,1.19]],"ltp":3.55,"tv":18.73,"id":60443}]}]}
{"op":"mcm","clk":"11895241839","pt":1724327361459,"mc":[{"id":"1.231812842","rc":[{"batl":[[0,1.49,1.52],[1,1.96,1.11],[2,2.1,3.72]],"ltp":1.47,"tv":111.44,"id":424676}]}]}
{"op":"mcm","clk":"11895242689","pt":1724327375956,"mc":[{"id":"1.231812842","rc":[{"batl":[[0,1.96,1.11],[1,2.1,3.72],[2,2.5,20]],"ltp":1.47,"tv":111.44,"id":424676}]}]}
{"op":"mcm","clk":"11895243681","pt":1724327392863,"mc":[{"id":"1.231812842","rc":[{"trd":[[1.9,8.78]],"batb":[[0,1.93,1.25],[1,1.46,1.26],[2,1.4,1.76]],"batl":[[0,2.1,4.55],[1,2.5,20],[2,3.5,16]],"ltp":1.9,"tv":111.99,"id":424676}],"tv":163.35}]}
{"op":"mcm","clk":"11895243794","pt":1724327394979,"mc":[{"id":"1.231812842","rc":[{"batl":[[0,8,1.76],[1,10,1],[2,15,1.53]],"ltp":3.55,"tv":18.73,"id":60443}]}]}
{"op":"mcm","clk":"11895244072","pt":1724327400487,"mc":[{"id":"1.231812842","rc":[{"batl":[[0,10,1.53],[1,15,1],[2,15.5,4]],"ltp":4.4,"tv":32.62,"id":424679}]}]}
{"op":"mcm","clk":"11895244472","pt":1724327405513,"mc":[{"id":"1.231812842","rc":[{"batl":[[0,6.6,1],[1,8,1.76],[2,10,1]],"ltp":3.55,"tv":18.73,"id":60443}]}]}
{"op":"mcm","clk":"11895244492","pt":1724327405776,"mc":[{"id":"1.231812842","rc":[{"batb":[[2,1.4,1]],"ltp":1.9,"tv":111.99,"id":424676}]}]}
{"op":"mcm","clk":"11895244546","pt":1724327406816,"mc":[{"id":"1.231812842","rc":[{"trd":[[1.93,2.5]],"batb":[[0,1.46,1.26],[1,1.4,1],[2,1.39,2.28]],"batl":[[0,1.96,1.11],[1,2.1,3.72],[2,2.5,20]],"ltp":1.93,"tv":114.49,"id":424676}],"tv":165.85}]}
{"op":"mcm","clk":"11895244703","pt":1724327409200,"mc":[{"id":"1.231812842","rc":[{"batl":[[0,2.1,4.55],[1,2.5,20],[2,3.5,16]],"ltp":1.93,"tv":114.49,"id":424676}]}]}
{"op":"mcm","clk":"11895244806","pt":1724327411016,"mc":[{"id":"1.231812842","rc":[{"batl":[[0,8.6,1],[1,10,1.53],[2,15,1]],"ltp":4.4,"tv":32.62,"id":424679},{"batb":[[0,1.47,1.06],[1,1.4,1.96]],"ltp":1.93,"tv":114.49,"id":424676}]}]}
{"op":"mcm","clk":"11895245774","pt":1724327429417,"mc":[{"id":"1.231812842","rc":[{"batl":[[0,1.51,1.52],[1,2.1,4.55],[2,2.5,20]],"ltp":1.93,"tv":114.49,"id":424676},{"batl":[[1,8,1.46]],"ltp":3.55,"tv":18.73,"id":60443}]}]}
{"op":"mcm","clk":"11895246031","pt":1724327433930,"mc":[{"id":"1.231812842","rc":[{"batl":[[0,8,1.46],[1,10,1],[2,15,1.53]],"ltp":3.55,"tv":18.73,"id":60443}]}]}
{"op":"mcm","clk":"11895246125","pt":1724327435429,"mc":[{"id":"1.231812842","rc":[{"trd":[[4.1,3.88],[5.2,0.44]],"batb":[[0,3.55,1.54],[1,3.05,1.64],[2,2.82,1.42]],"ltp":4.1,"tv":36.94,"id":424679},{"trd":[[1.51,1.52]],"batl":[[0,2.1,4.55],[1,2.5,20],[2,3.5,16]],"ltp":1.51,"tv":116.01,"id":424676},{"trd":[[6.8,0.34]],"batl":[[0,8,1.12]],"ltp":6.8,"tv":19.07,"id":60443}],"tv":172.03}]}
{"op":"mcm","clk":"11895246365","pt":1724327440557,"mc":[{"id":"1.231812842","rc":[{"batb":[[0,3.6,4.01],[1,3.55,1.53],[2,3.05,1.64]],"ltp":4.1,"tv":36.94,"id":424679},{"batb":[[0,3.25,4.89],[1,3.05,1.94]],"ltp":6.8,"tv":19.07,"id":60443}]}]}
{"op":"mcm","clk":"11895246485","pt":1724327442736,"mc":[{"id":"1.231812842","rc":[{"batb":[[0,3.55,1.54],[1,3.05,1.64],[2,2.82,1.42]],"ltp":4.1,"tv":36.94,"id":424679},{"batb":[[0,3.2,1.19],[1,3.05,1.64]],"ltp":6.8,"tv":19.07,"id":60443}]}]}
{"op":"mcm","clk":"11895246570","pt":1724327444438,"mc":[{"id":"1.231812842","rc":[{"batl":[[0,7.8,1.12],[1,8,1],[2,10,1]],"ltp":6.8,"tv":19.07,"id":60443}]}]}
{"op":"mcm","clk":"11895246717","pt":1724327447249,"mc":[{"id":"1.231812842","rc":[{"batb":[[0,3.55,1.84]],"ltp":4.1,"tv":36.94,"id":424679},{"batl":[[0,7.8,1.42]],"ltp":6.8,"tv":19.07,"id":60443}]}]}
{"op":"mcm","clk":"11895247013","pt":1724327452175,"mc":[{"id":"1.231812842","rc":[{"batb":[[0,3.6,4.31],[1,3.55,1.53],[2,3.05,1.64]],"ltp":4.1,"tv":36.94,"id":424679},{"batb":[[0,3.25,4.89],[1,3.05,1.94]],"ltp":6.8,"tv":19.07,"id":60443}]}]}
{"op":"mcm","clk":"11895247240","pt":1724327455658,"mc":[{"id":"1.231812842","rc":[{"batb":[[0,3.55,1.84],[1,3.05,1.64],[2,2.82,1.42]],"ltp":4.1,"tv":36.94,"id":424679},{"batb":[[0,3.2,1.19],[1,3.05,1.64]],"ltp":6.8,"tv":19.07,"id":60443}]}]}
{"op":"mcm","clk":"11895247352","pt":1724327457566,"mc":[{"id":"1.231812842","rc":[{"batl":[[1,10,1]],"ltp":4.1,"tv":36.94,"id":424679}]}]}
{"op":"mcm","clk":"11895247615","pt":1724327461959,"mc":[{"id":"1.231812842","rc":[{"batl":[[0,8.6,1.53]],"ltp":4.1,"tv":36.94,"id":424679}]}]}
{"op":"mcm","clk":"11895247693","pt":1724327463358,"mc":[{"id":"1.231812842","rc":[{"batb":[[0,3.4,1.42],[1,3.05,1.94]],"ltp":6.8,"tv":19.07,"id":60443}]}]}
{"op":"mcm","clk":"11895248748","pt":1724327479410,"mc":[{"id":"1.231812842","rc":[{"batl":[[0,8.6,1.83]],"ltp":4.1,"tv":36.94,"id":424679}]}]}
{"op":"mcm","clk":"11895249315","pt":1724327488173,"mc":[{"id":"1.231812842","rc":[{"batl":[[0,1.54,1.52],[1,2.1,4.55],[2,2.5,20]],"ltp":1.51,"tv":116.01,"id":424676}]}]}
{"op":"mcm","clk":"11895249739","pt":1724327495121,"mc":[{"id":"1.231812842","rc":[{"batl":[[1,2.1,4.25]],"ltp":1.51,"tv":116.01,"id":424676}]}]}
{"op":"mcm","clk":"11895250184","pt":1724327502517,"mc":[{"id":"1.231812842","rc":[{"batl":[[0,2.1,4.25],[1,2.5,20],[2,3.5,16]],"ltp":1.51,"tv":116.01,"id":424676}]}]}
{"op":"mcm","clk":"11895250466","pt":1724327507104,"mc":[{"id":"1.231812842","rc":[{"batl":[[0,1.54,1],[1,2.1,4.25],[2,2.5,20]],"ltp":1.51,"tv":116.01,"id":424676}]}]}
{"op":"mcm","clk":"11895250576","pt":1724327508697,"mc":[{"id":"1.231812842","rc":[{"batl":[[0,2.1,4.25],[1,2.5,20],[2,3.5,16]],"ltp":1.51,"tv":116.01,"id":424676}]}]}
{"op":"mcm","clk":"11895251106","pt":1724327517554,"mc":[{"id":"1.231812842","rc":[{"batl":[[0,2.1,4.55]],"ltp":1.51,"tv":116.01,"id":424676}]}]}
{"op":"mcm","clk":"11895253006","pt":1724327549054,"mc":[{"id":"1.231812842","rc":[{"trd":[[4.1,3.9]],"batb":[[0,3.55,1.83]],"batl":[[0,3.7,1.24],[1,8.6,1.83],[2,10,1]],"ltp":4.1,"tv":36.96,"id":424679}],"tv":172.05}]}
{"op":"mcm","clk":"11895253089","pt":1724327550756,"mc":[{"id":"1.231812842","rc":[{"batl":[[0,8,1.42],[1,10,1],[2,15,1.53]],"ltp":6.8,"tv":19.07,"id":60443}]}]}
{"op":"mcm","clk":"11895253095","pt":1724327550858,"mc":[{"id":"1.231812842","rc":[{"batl":[[1,10,1.83],[2,15,1]],"ltp":4.1,"tv":36.96,"id":424679}]}]}
{"op":"mcm","clk":"11895253163","pt":1724327552453,"mc":[{"id":"1.231812842","rc":[{"trd":[[3.7,0.2]],"batl":[[0,3.7,1.04]],"ltp":3.7,"tv":37.16,"id":424679},{"trd":[[1.71,3.49]],"ltp":1.71,"tv":116.46,"id":424676},{"trd":[[6.8,0.45]],"batl":[[0,8,1.31]],"ltp":6.8,"tv":19.18,"id":60443}],"tv":172.81}]}
{"op":"mcm","clk":"11895253379","pt":1724327555665,"mc":[{"id":"1.231812842","rc":[{"batl":[[0,10,1.83],[1,15,1],[2,15.5,4]],"ltp":3.7,"tv":37.16,"id":424679}]}]}
{"op":"mcm","clk":"11895253498","pt":1724327557600,"mc":[{"id":"1.231812842","rc":[{"batb":[[0,3.45,4.89],[1,3.05,2.47]],"ltp":6.8,"tv":19.18,"id":60443}]}]}
{"op":"mcm","clk":"11895253557","pt":1724327558491,"mc":[{"id":"1.231812842","rc":[{"batb":[[0,1.48,1.06],[1,1.46,1.26],[2,1.4,1]],"ltp":1.71,"tv":116.46,"id":424676}]}]}
{"op":"mcm","clk":"11895253612","pt":1724327559468,"mc":[{"id":"1.231812842","rc":[{"batl":[[0,8,1],[1,10,1.83],[2,15,1]],"ltp":3.7,"tv":37.16,"id":424679}]}]}
{"op":"mcm","clk":"11895253636","pt":1724327559885,"mc":[{"id":"1.231812842","rc":[{"batb":[[0,3.4,1.42],[1,3.05,1.94]],"ltp":6.8,"tv":19.18,"id":60443}]}]}
{"op":"mcm","clk":"11895253738","pt":1724327561698,"mc":[{"id":"1.231812842","rc":[{"batb":[[0,3.6,4.3],[1,3.55,1.53],[2,3.05,1.64]],"batl":[[1,9.8,1.83],[2,10,1]],"ltp":3.7,"tv":37.16,"id":424679},{"batb":[[1,1.4,1.96],[2,1.39,2.28]],"ltp":1.71,"tv":116.46,"id":424676},{"batl":[[0,7.8,1.31],[1,8,1],[2,10,1]],"ltp":6.8,"tv":19.18,"id":60443}]}]}
{"op":"mcm","clk":"11895253816","pt":1724327563197,"mc":[{"id":"1.231812842","rc":[{"batb":[[0,3.55,1.83],[1,3.05,1.64],[2,2.82,1.42]],"ltp":3.7,"tv":37.16,"id":424679}]}]}
{"op":"mcm","clk":"11895254047","pt":1724327567507,"mc":[{"id":"1.231812842","rc":[{"batl":[[1,10,1.83],[2,15,1]],"ltp":3.7,"tv":37.16,"id":424679}]}]}
{"op":"mcm","clk":"11895254091","pt":1724327568288,"mc":[{"id":"1.231812842","rc":[{"batb":[[0,3.45,4.89],[1,3.05,2.47]],"ltp":6.8,"tv":19.18,"id":60443}]}]}
{"op":"mcm","clk":"11895254123","pt":1724327568811,"mc":[{"id":"1.231812842","rc":[{"batb":[[0,1.9,1.52],[1,1.48,1.06],[2,1.4,1.96]],"ltp":1.71,"tv":116.46,"id":424676}]}]}
{"op":"mcm","clk":"11895254251","pt":1724327570684,"mc":[{"id":"1.231812842","rc":[{"batb":[[0,3.4,1.42],[1,3.05,1.94]],"ltp":6.8,"tv":19.18,"id":60443}]}]}
{"op":"mcm","clk":"11895254700","pt":1724327578086,"mc":[{"id":"1.231812842","rc":[{"batl":[[0,7.8,1],[1,8,1],[2,10,1.83]],"ltp":3.7,"tv":37.16,"id":424679}]}]}
{"op":"mcm","clk":"11895255040","pt":1724327583599,"mc":[{"id":"1.231812842","rc":[{"batb":[[0,1.48,1.06],[1,1.4,1.96],[2,1.39,2.28]],"ltp":1.71,"tv":116.46,"id":424676}]}]}
{"op":"mcm","clk":"11895255648","pt":1724327592104,"mc":[{"id":"1.231812842","rc":[{"batl":[[0,3.7,1.25],[1,7.8,1],[2,8,1]],"ltp":3.7,"tv":37.16,"id":424679}]}]}
{"op":"mcm","clk":"11895255860","pt":1724327595299,"mc":[{"id":"1.231812842","rc":[{"batl":[[1,8,1],[2,10,1.83]],"ltp":3.7,"tv":37.16,"id":424679},{"batl":[[0,8,1.31],[1,10,1],[2,15,1.53]],"ltp":6.8,"tv":19.18,"id":60443}]}]}
{"op":"mcm","clk":"11895256040","pt":1724327597934,"mc":[{"id":"1.231812842","rc":[{"batl":[[0,8,1],[1,10,1.83],[2,15,1]],"ltp":3.7,"tv":37.16,"id":424679}]}]}
{"op":"mcm","clk":"11895256606","pt":1724327605939,"mc":[{"id":"1.231812842","rc":[{"batl":[[0,7.8,1],[1,8,1],[2,10,1.83]],"ltp":3.7,"tv":37.16,"id":424679},{"batl":[[0,7.8,1.31],[1,8,1],[2,10,1]],"ltp":6.8,"tv":19.18,"id":60443}]}]}
{"op":"mcm","clk":"11895257216","pt":1724327615062,"mc":[{"id":"1.231812842","rc":[{"batb":[[0,1.48,2.06]],"ltp":1.71,"tv":116.46,"id":424676}]}]}
{"op":"mcm","clk":"11895257464","pt":1724327619332,"mc":[{"id":"1.231812842","rc":[{"batl":[[0,3.65,1.25],[1,7.8,1],[2,8,1]],"ltp":3.7,"tv":37.16,"id":424679}]}]}
{"op":"mcm","clk":"11895257663","pt":1724327623142,"mc":[{"id":"1.231812842","rc":[{"batl":[[1,8,1],[2,10,1.83]],"ltp":3.7,"tv":37.16,"id":424679},{"batl":[[0,8,1.31],[1,10,1],[2,15,1.53]],"ltp":6.8,"tv":19.18,"id":60443}]}]}
{"op":"mcm","clk":"11895257898","pt":1724327627465,"mc":[{"id":"1.231812842","rc":[{"batl":[[0,8,1],[1,10,1.83],[2,15,1]],"ltp":3.7,"tv":37.16,"id":424679}]}]}
{"op":"mcm","clk":"11895258293","pt":1724327633682,"mc":[{"id":"1.231812842","rc":[{"batl":[[0,7.8,1],[1,8,1],[2,10,1.83]],"ltp":3.7,"tv":37.16,"id":424679},{"batl":[[0,7.8,1.31],[1,8,1],[2,10,1]],"ltp":6.8,"tv":19.18,"id":60443}]}]}
{"op":"mcm","clk":"11895258473","pt":1724327636669,"mc":[{"id":"1.231812842","rc":[{"batb":[[1,3.05,1.64]],"ltp":6.8,"tv":19.18,"id":60443}]}]}
{"op":"mcm","clk":"11895258984","pt":1724327643855,"mc":[{"id":"1.231812842","rc":[{"batb":[[0,3.45,1.19],[1,3.05,2.17]],"ltp":6.8,"tv":19.18,"id":60443}]}]}
{"op":"mcm","clk":"11895261328","pt":1724327678794,"mc":[{"id":"1.231812842","rc":[{"batl":[[0,7.8,1.3]],"ltp":6.8,"tv":19.18,"id":60443}]}]}
{"op":"mcm","clk":"11895261583","pt":1724327683398,"mc":[{"id":"1.231812842","rc":[{"batb":[[1,3.05,1.64]],"ltp":6.8,"tv":19.18,"id":60443}]}]}
{"op":"mcm","clk":"11895261892","pt":1724327688495,"mc":[{"id":"1.231812842","rc":[{"batb":[[0,3.55,1.42],[1,3.05,1.94]],"ltp":6.8,"tv":19.18,"id":60443}]}]}
{"op":"mcm","clk":"11895262453","pt":1724327696493,"mc":[{"id":"1.231812842","rc":[{"batb":[[0,7.2,1.25],[1,3.55,1.83],[2,3.05,1.64]],"ltp":3.7,"tv":37.16,"id":424679}]}]}
{"op":"mcm","clk":"11895262765","pt":1724327701132,"mc":[{"id":"1.231812842","rc":[{"batl":[[0,8,1],[1,10,1.83],[2,15,1]],"ltp":3.7,"tv":37.16,"id":424679},{"batl":[[0,8,1.3],[1,10,1],[2,15,1.53]],"ltp":6.8,"tv":19.18,"id":60443}]}]}
{"op":"mcm","clk":"11895262906","pt":1724327703217,"mc":[{"id":"1.231812842","rc":[{"batb":[[0,3.55,1.83],[1,3.05,1.64],[2,2.82,1.42]],"ltp":3.7,"tv":37.16,"id":424679}]}]}
{"op":"mcm","clk":"11895263534","pt":1724327711714,"mc":[{"id":"1.231812842","rc":[{"batl":[[0,7.8,1],[1,8,1],[2,10,1.83]],"ltp":3.7,"tv":37.16,"id":424679},{"batl":[[0,7.8,1.3],[1,8,1],[2,10,1]],"ltp":6.8,"tv":19.18,"id":60443}]}]}
{"op":"mcm","clk":"11895264455","pt":1724327724462,"mc":[{"id":"1.231812842","rc":[{"batl":[[0,3.65,1.25],[1,7.8,1],[2,8,1]],"ltp":3.7,"tv":37.16,"id":424679}]}]}
{"op":"mcm","clk":"11895264794","pt":1724327728951,"mc":[{"id":"1.231812842","rc":[{"batl":[[1,8,1],[2,10,1.83]],"ltp":3.7,"tv":37.16,"id":424679},{"batl":[[0,8,1.3],[1,10,1],[2,15,1.53]],"ltp":6.8,"tv":19.18,"id":60443}]}]}
{"op":"mcm","clk":"11895264846","pt":1724327729777,"mc":[{"id":"1.231812842","rc":[{"batl":[[0,8,1],[1,10,1.83],[2,15,1]],"ltp":3.7,"tv":37.16,"id":424679}]}]}
{"op":"mcm","clk":"11895265357","pt":1724327739556,"mc":[{"id":"1.231812842","rc":[{"batl":[[0,7.8,1],[1,8,1],[2,10,1.83]],"ltp":3.7,"tv":37.16,"id":424679},{"batl":[[0,7.8,1.3],[1,8,1],[2,10,1]],"ltp":6.8,"tv":19.18,"id":60443}]}]}
{"op":"mcm","clk":"11895265420","pt":1724327740693,"mc":[{"id":"1.231812842","rc":[{"batl":[[0,7.8,1]],"ltp":6.8,"tv":19.18,"id":60443}]}]}
{"op":"mcm","clk":"11895265437","pt":1724327740962,"mc":[{"id":"1.231812842","rc":[{"batb":[[0,3.55,1.53]],"ltp":3.7,"tv":37.16,"id":424679}]}]}
{"op":"mcm","clk":"11895265545","pt":1724327742665,"mc":[{"id":"1.231812842","rc":[{"batl":[[0,3.65,1.25],[1,7.8,1],[2,8,1]],"ltp":3.7,"tv":37.16,"id":424679}]}]}
{"op":"mcm","clk":"11895265723","pt":1724327745663,"mc":[{"id":"1.231812842","rc":[{"batl":[[1,8,1],[2,10,1.83]],"ltp":3.7,"tv":37.16,"id":424679},{"batl":[[0,8,1],[1,10,1],[2,15,1.53]],"ltp":6.8,"tv":19.18,"id":60443}]}]}
{"op":"mcm","clk":"11895265834","pt":1724327747377,"mc":[{"id":"1.231812842","rc":[{"batl":[[0,8,1],[1,10,1.83],[2,15,1]],"ltp":3.7,"tv":37.16,"id":424679}]}]}
{"op":"mcm","clk":"11895266382","pt":1724327756302,"mc":[{"id":"1.231812842","rc":[{"batl":[[0,7.8,1],[1,8,1],[2,10,1.83]],"ltp":3.7,"tv":37.16,"id":424679},{"batl":[[0,7.8,1],[1,8,1],[2,10,1]],"ltp":6.8,"tv":19.18,"id":60443}]}]}
{"op":"mcm","clk":"11895267865","pt":1724327780387,"mc":[{"id":"1.231812842","rc":[{"batl":[[2,10,1.53]],"ltp":3.7,"tv":37.16,"id":424679}]}]}
{"op":"mcm","clk":"11895269535","pt":1724327808180,"mc":[{"id":"1.231812842","rc":[{"batl":[[0,3.65,1.25],[1,7.8,1],[2,8,1]],"ltp":3.7,"tv":37.16,"id":424679}]}]}
{"op":"mcm","clk":"11895269807","pt":1724327812444,"mc":[{"id":"1.231812842","rc":[{"batl":[[0,8,1],[1,10,1.53],[2,15,1]],"ltp":3.7,"tv":37.16,"id":424679},{"batl":[[0,8,1],[1,10,1],[2,15,1.53]],"ltp":6.8,"tv":19.18,"id":60443}]}]}
{"op":"mcm","clk":"11895270458","pt":1724327823052,"mc":[{"id":"1.231812842","rc":[{"batl":[[0,7.8,1],[1,8,1],[2,10,1]],"ltp":6.8,"tv":19.18,"id":60443}]}]}
{"op":"mcm","clk":"11895270768","pt":1724327828653,"mc":[{"id":"1.231812842","rc":[{"batl":[[0,7.8,1],[1,8,1],[2,10,1.53]],"ltp":3.7,"tv":37.16,"id":424679}]}]}
{"op":"mcm","clk":"11895271305","pt":1724327839063,"mc":[{"id":"1.231812842","rc":[{"batl":[[0,3.65,1.25],[1,7.8,1],[2,8,1]],"ltp":3.7,"tv":37.16,"id":424679}]}]}
{"op":"mcm","clk":"11895271383","pt":1724327840354,"mc":[{"id":"1.231812842","rc":[{"batl":[[1,8,1],[2,10,1.53]],"ltp":3.7,"tv":37.16,"id":424679},{"batl":[[0,8,1],[1,10,1],[2,15,1.53]],"ltp":6.8,"tv":19.18,"id":60443}]}]}
{"op":"mcm","clk":"11895271423","pt":1724327840969,"mc":[{"id":"1.231812842","rc":[{"batl":[[0,8,1],[1,10,1.53],[2,15,1]],"ltp":3.7,"tv":37.16,"id":424679}]}]}
{"op":"mcm","clk":"11895271959","pt":1724327850914,"mc":[{"id":"1.231812842","rc":[{"batl":[[0,7.8,1],[1,8,1],[2,10,1.53]],"ltp":3.7,"tv":37.16,"id":424679},{"batl":[[0,7.8,1],[1,8,1],[2,10,1]],"ltp":6.8,"tv":19.18,"id":60443}]}]}
{"op":"mcm","clk":"11895272271","pt":1724327857018,"mc":[{"id":"1.231812842","rc":[{"batb":[[0,1.48,1.76]],"ltp":1.71,"tv":116.46,"id":424676}]}]}
{"op":"mcm","clk":"11895272460","pt":1724327860686,"mc":[{"id":"1.231812842","rc":[{"batb":[[0,1.48,2.06]],"ltp":1.71,"tv":116.46,"id":424676}]}]}
{"op":"mcm","clk":"11895275594","pt":1724327918640,"mc":[{"id":"1.231812842","rc":[{"batb":[[0,7.2,1.25],[1,3.55,1.53],[2,3.05,1.64]],"ltp":3.7,"tv":37.16,"id":424679}]}]}
{"op":"mcm","clk":"11895275860","pt":1724327923875,"mc":[{"id":"1.231812842","rc":[{"batb":[[0,3.55,1.53],[1,3.05,1.64],[2,2.82,1.42]],"batl":[[0,8,1],[1,10,1.53],[2,15,1]],"ltp":3.7,"tv":37.16,"id":424679},{"batl":[[0,8,1],[1,10,1],[2,15,1.53]],"ltp":6.8,"tv":19.18,"id":60443}]}]}
{"op":"mcm","clk":"11895276415","pt":1724327934362,"mc":[{"id":"1.231812842","rc":[{"batl":[[0,7.8,1],[1,8,1],[2,10,1.53]],"ltp":3.7,"tv":37.16,"id":424679},{"batl":[[0,7.8,1],[1,8,1],[2,10,1]],"ltp":6.8,"tv":19.18,"id":60443}]}]}
{"op":"mcm","clk":"11895277028","pt":1724327944991,"mc":[{"id":"1.231812842","rc":[{"batb":[[1,3.05,1.64]],"ltp":6.8,"tv":19.18,"id":60443}]}]}
{"op":"mcm","clk":"11895285795","pt":1724328118880,"mc":[{"id":"1.231812842","rc":[{"trd":[[1.39,6.12],[1.41,5.91],[1.42,4.87],[1.46,3.72],[1.86,2.14],[1.9,8.79],[1.93,2.5],[2,11.99]],"batb":[[0,1.48,1.3],[2,1.39,2.28]],"batl":[[0,2.1,4.55]],"ltp":1.71,"tv":116.48,"id":424676}],"tv":172.83}]}
{"op":"mcm","clk":"11895286252","pt":1724328124001,"mc":[{"id":"1.231812842","rc":[{"batb":[[0,1.49,1.06],[1,1.48,1],[2,1.4,1.96]],"ltp":1.71,"tv":116.48,"id":424676}]}]}
{"op":"mcm","clk":"11895286498","pt":1724328128704,"mc":[{"id":"1.231812842","rc":[{"batl":[[2,10,1]],"ltp":3.7,"tv":37.16,"id":424679}]}]}
{"op":"mcm","clk":"11895286564","pt":1724328129893,"mc":[{"id":"1.231812842","rc":[{"batl":[[0,2.1,4.25]],"ltp":1.71,"tv":116.48,"id":424676}]}]}
{"op":"mcm","clk":"11895286790","pt":1724328133791,"mc":[{"id":"1.231812842","rc":[{"batl":[[0,7.8,1.53]],"ltp":3.7,"tv":37.16,"id":424679}]}]}
{"op":"mcm","clk":"11895286844","pt":1724328134980,"mc":[{"id":"1.231812842","rc":[{"batl":[[0,2.1,4.55]],"ltp":1.71,"tv":116.48,"id":424676}]}]}
{"op":"mcm","clk":"11895287889","pt":1724328154830,"mc":[{"id":"1.231812842","rc":[{"batl":[[0,7.4,1.37],[1,7.8,1],[2,8,1]],"ltp":3.7,"tv":37.16,"id":424679}]}]}
{"op":"mcm","clk":"11895288064","pt":1724328157628,"mc":[{"id":"1.231812842","rc":[{"batl":[[1,8,1],[2,10,1]],"ltp":3.7,"tv":37.16,"id":424679}]}]}
{"op":"mcm","clk":"11895288431","pt":1724328165344,"mc":[{"id":"1.231812842","rc":[{"batb":[[0,1.48,1.76],[1,1.4,1.96],[2,1.39,2.28]],"ltp":1.71,"tv":116.48,"id":424676}]}]}
{"op":"mcm","clk":"11895288566","pt":1724328168235,"mc":[{"id":"1.231812842","rc":[{"batl":[[0,7.2,1.83],[1,8,1.53]],"ltp":3.7,"tv":37.16,"id":424679}]}]}
{"op":"mcm","clk":"11895288645","pt":1724328169936,"mc":[{"id":"1.231812842","rc":[{"batb":[[0,1.5,1.06],[1,1.48,1],[2,1.4,1.96]],"ltp":1.71,"tv":116.48,"id":424676}]}]}
{"op":"mcm","clk":"11895289087","pt":1724328178224,"mc":[{"id":"1.231812842","rc":[{"batb":[[1,1.4,1.96],[2,1.39,2.28]],"ltp":1.71,"tv":116.48,"id":424676}]}]}
{"op":"mcm","clk":"11895289359","pt":1724328183350,"mc":[{"id":"1.231812842","rc":[{"batb":[[0,1.5,2.06]],"ltp":1.71,"tv":116.48,"id":424676}]}]}
{"op":"mcm","clk":"11895289847","pt":1724328193537,"mc":[{"id":"1.231812842","rc":[{"batl":[[0,7.2,1]],"ltp":3.7,"tv":37.16,"id":424679}]}]}
{"op":"mcm","clk":"11895291391","pt":1724328224582,"mc":[{"id":"1.231812842","rc":[{"batl":[[0,5.3,1.11]],"ltp":3.7,"tv":37.16,"id":424679}]}]}
{"op":"mcm","clk":"11895302507","pt":1724328431234,"mc":[{"id":"1.231812842","rc":[{"batl":[[0,2.1,4.25]],"ltp":1.71,"tv":116.48,"id":424676}]}]}
{"op":"mcm","clk":"11895302832","pt":1724328436256,"mc":[{"id":"1.231812842","rc":[{"batl":[[0,2.1,4.55]],"ltp":1.71,"tv":116.48,"id":424676}]}]}
{"op":"mcm","clk":"11895303912","pt":1724328456662,"mc":[{"id":"1.231812842","rc":[{"batb":[[0,1.5,1.76]],"ltp":1.71,"tv":116.48,"id":424676}]}]}
{"op":"mcm","clk":"11895304147","pt":1724328461370,"mc":[{"id":"1.231812842","rc":[{"batb":[[0,1.51,1.06],[1,1.5,1],[2,1.4,1.96]],"ltp":1.71,"tv":116.48,"id":424676}]}]}
{"op":"mcm","clk":"11895307818","pt":1724328527860,"mc":[{"id":"1.231812842","rc":[{"batb":[[1,1.4,1.96],[2,1.39,2.28]],"ltp":1.71,"tv":116.48,"id":424676}]}]}
{"op":"mcm","clk":"11895308074","pt":1724328532941,"mc":[{"id":"1.231812842","rc":[{"batb":[[0,1.51,2.06]],"ltp":1.71,"tv":116.48,"id":424676}]}]}
{"op":"mcm","clk":"11895310399","pt":1724328573993,"mc":[{"id":"1.231812842","rc":[{"batl":[[1,3.5,16],[2,4,1]],"ltp":1.71,"tv":116.48,"id":424676}]}]}
{"op":"mcm","clk":"11895311837","pt":1724328597225,"mc":[{"id":"1.231812842","rc":[{"batl":[[0,1.99,10.53],[1,2.1,4.02],[2,3.5,16]],"ltp":1.71,"tv":116.48,"id":424676}]}]}
{"op":"mcm","clk":"11895322110","pt":1724328752280,"mc":[{"id":"1.231812842","rc":[{"batb":[[1,3.05,2.49]],"ltp":6.8,"tv":19.18,"id":60443}]}]}
{"op":"mcm","clk":"11895323019","pt":1724328763981,"mc":[{"id":"1.231812842","rc":[{"batl":[[1,2.1,3.72]],"ltp":1.71,"tv":116.48,"id":424676}]}]}
{"op":"mcm","clk":"11895323253","pt":1724328767314,"mc":[{"id":"1.231812842","rc":[{"batl":[[0,1.99,10.83]],"ltp":1.71,"tv":116.48,"id":424676}]}]}
{"op":"mcm","clk":"11895324733","pt":1724328787240,"mc":[{"id":"1.231812842","rc":[{"batb":[[0,1.51,1.76]],"ltp":1.71,"tv":116.48,"id":424676}]}]}
{"op":"mcm","clk":"11895324825","pt":1724328788223,"mc":[{"id":"1.231812842","rc":[{"batb":[[0,1.51,2.06]],"ltp":1.71,"tv":116.48,"id":424676}]}]}
{"op":"mcm","clk":"11895342929","pt":1724329046810,"mc":[{"id":"1.231812842","rc":[{"batl":[[0,1.98,1.13],[1,1.99,10],[2,2.1,3.72]],"ltp":1.71,"tv":116.48,"id":424676}]}]}
{"op":"mcm","clk":"11895343811","pt":1724329063840,"mc":[{"id":"1.231812842","rc":[{"batl":[[0,1.99,10.83],[1,2.1,3.72],[2,3.5,16]],"ltp":1.71,"tv":116.48,"id":424676}]}]}
{"op":"mcm","clk":"11895346134","pt":1724329104366,"mc":[{"id":"1.231812842","rc":[{"batb":[[0,1.51,1.76]],"ltp":1.71,"tv":116.48,"id":424676}]}]}
{"op":"mcm","clk":"11895346187","pt":1724329105142,"mc":[{"id":"1.231812842","rc":[{"batb":[[0,1.51,2.06]],"ltp":1.71,"tv":116.48,"id":424676}]}]}
{"op":"mcm","clk":"11895346676","pt":1724329113889,"mc":[{"id":"1.231812842","rc":[{"batb":[[0,3.75,50],[1,3.55,1.53],[2,3.05,1.64]],"ltp":3.7,"tv":37.16,"id":424679}]}]}
{"op":"mcm","clk":"11895356553","pt":1724329294745,"mc":[{"id":"1.231812842","rc":[{"batl":[[1,3.5,16],[2,4,1]],"ltp":1.71,"tv":116.48,"id":424676}]}]}
{"op":"mcm","clk":"11895357350","pt":1724329309671,"mc":[{"id":"1.231812842","rc":[{"batl":[[0,1.96,1.42],[1,1.99,10.3],[2,3.5,16]],"ltp":1.71,"tv":116.48,"id":424676}]}]}
{"op":"mcm","clk":"11895360357","pt":1724329360623,"mc":[{"id":"1.231812842","rc":[{"batl":[[1,1.99,10]],"ltp":1.71,"tv":116.48,"id":424676}]}]}
{"op":"mcm","clk":"11895360812","pt":1724329368061,"mc":[{"id":"1.231812842","rc":[{"batl":[[0,1.95,1.19],[1,1.99,10.53]],"ltp":1.71,"tv":116.48,"id":424676}]}]}
{"op":"mcm","clk":"11895362109","pt":1724329388985,"mc":[{"id":"1.231812842","rc":[{"batb":[[0,1.51,1.76]],"ltp":1.71,"tv":116.48,"id":424676}]}]}
{"op":"mcm","clk":"11895362612","pt":1724329398388,"mc":[{"id":"1.231812842","rc":[{"batb":[[0,1.51,2.06]],"ltp":1.71,"tv":116.48,"id":424676}]}]}
{"op":"mcm","clk":"11895377247","pt":1724329658962,"mc":[{"id":"1.231812842","rc":[{"batl":[[0,1.96,1.42],[1,1.99,10]],"ltp":1.71,"tv":116.48,"id":424676}]}]}
{"op":"mcm","clk":"11895377447","pt":1724329662146,"mc":[{"id":"1.231812842","rc":[{"batl":[[0,1.95,1.19],[1,1.99,10.53]],"ltp":1.71,"tv":116.48,"id":424676}]}]}
{"op":"mcm","clk":"11895379116","pt":1724329689693,"mc":[{"id":"1.231812842","rc":[{"batb":[[0,1.51,1.76]],"ltp":1.71,"tv":116.48,"id":424676}]}]}
{"op":"mcm","clk":"11895379427","pt":1724329694905,"mc":[{"id":"1.231812842","rc":[{"batb":[[0,1.51,2.06]],"ltp":1.71,"tv":116.48,"id":424676}]}]}
{"op":"mcm","clk":"11895398661","pt":1724329991434,"mc":[{"id":"1.231812842","rc":[{"batl":[[0,1.96,1.42],[1,1.99,10]],"ltp":1.71,"tv":116.48,"id":424676}]}]}
{"op":"mcm","clk":"11895398881","pt":1724329994851,"mc":[{"id":"1.231812842","rc":[{"batl":[[0,1.95,1.19],[1,1.99,10.53]],"ltp":1.71,"tv":116.48,"id":424676}]}]}
{"op":"mcm","clk":"11895401045","pt":1724330030182,"mc":[{"id":"1.231812842","rc":[{"batb":[[0,1.51,1.76]],"ltp":1.71,"tv":116.48,"id":424676}]}]}
{"op":"mcm","clk":"11895401344","pt":1724330034395,"mc":[{"id":"1.231812842","rc":[{"batb":[[0,1.51,2.06]],"ltp":1.71,"tv":116.48,"id":424676}]}]}
{"op":"mcm","clk":"11895414517","pt":1724330242398,"mc":[{"id":"1.231812842","rc":[{"batl":[[0,1.96,1.42],[1,1.99,10]],"ltp":1.71,"tv":116.48,"id":424676}]}]}
{"op":"mcm","clk":"11895414567","pt":1724330243424,"mc":[{"id":"1.231812842","rc":[{"batl":[[0,1.95,1.19],[1,1.99,10.53]],"ltp":1.71,"tv":116.48,"id":424676}]}]}
{"op":"mcm","clk":"11895419238","pt":1724330316591,"mc":[{"id":"1.231812842","rc":[{"batb":[[0,1.51,2.36]],"ltp":1.71,"tv":116.48,"id":424676}]}]}
{"op":"mcm","clk":"11895419336","pt":1724330318085,"mc":[{"id":"1.231812842","rc":[{"batb":[[0,1.51,2.06]],"ltp":1.71,"tv":116.48,"id":424676}]}]}
{"op":"mcm","clk":"11895433507","pt":1724330546155,"mc":[{"id":"1.231812842","rc":[{"batl":[[0,1.96,1.42],[1,1.99,10]],"ltp":1.71,"tv":116.48,"id":424676}]}]}
{"op":"mcm","clk":"11895433588","pt":1724330547134,"mc":[{"id":"1.231812842","rc":[{"batl":[[0,1.95,1.19],[1,1.99,10.53]],"ltp":1.71,"tv":116.48,"id":424676}]}]}
{"op":"mcm","clk":"11895436896","pt":1724330601879,"mc":[{"id":"1.231812842","rc":[{"batb":[[0,1.51,1.76]],"ltp":1.71,"tv":116.48,"id":424676}]}]}
{"op":"mcm","clk":"11895437457","pt":1724330609984,"mc":[{"id":"1.231812842","rc":[{"batb":[[0,1.51,2.06]],"ltp":1.71,"tv":116.48,"id":424676}]}]}
{"op":"mcm","clk":"11895440119","pt":1724330648235,"mc":[{"id":"1.231812842","rc":[{"batb":[[1,3.65,10.9],[2,3.55,1.53]],"ltp":3.7,"tv":37.16,"id":424679}]}]}
{"op":"mcm","clk":"11895440431","pt":1724330653322,"mc":[{"id":"1.231812842","rc":[{"trd":[[5.3,1.11]],"batl":[[0,8,1.53],[1,10,1],[2,15,1]],"ltp":5.3,"tv":38.27,"id":424679},{"trd":[[1.46,9.68],[1.51,5.05],[1.52,0.6]],"batb":[[0,1.4,1],[1,1.39,2.28],[2,1.26,31.57]],"ltp":1.46,"tv":126.56,"id":424676},{"trd":[[7.8,0.76]],"batl":[[0,8,1.24],[1,10,1],[2,15,1.53]],"ltp":7.8,"tv":19.94,"id":60443}],"tv":184.79}]}
{"op":"mcm","clk":"11895440458","pt":1724330653839,"mc":[{"id":"1.231812842","rc":[{"batb":[[2,1.08,31.25]],"ltp":1.46,"tv":126.56,"id":424676}]}]}
{"op":"mcm","clk":"11895440755","pt":1724330658440,"mc":[{"id":"1.231812842","rc":[{"batb":[[0,3.8,4],[1,3.75,50],[2,3.65,10.9]],"ltp":5.3,"tv":38.27,"id":424679},{"batb":[[0,3.6,4.53],[1,3.35,1.74],[2,3.05,1.64]],"ltp":7.8,"tv":19.94,"id":60443}]}]}
{"op":"mcm","clk":"11895440885","pt":1724330660749,"mc":[{"id":"1.231812842","rc":[{"batb":[[0,3.75,50],[1,3.65,10.9],[2,3.55,1.53]],"ltp":5.3,"tv":38.27,"id":424679},{"batb":[[0,3.55,1.42],[1,3.05,2.49],[2,2.82,1.42]],"ltp":7.8,"tv":19.94,"id":60443}]}]}
{"op":"mcm","clk":"11895441018","pt":1724330662666,"mc":[{"id":"1.231812842","rc":[{"batl":[[0,7.8,1.53],[1,8,1],[2,10,1]],"ltp":5.3,"tv":38.27,"id":424679}]}]}
{"op":"mcm","clk":"11895441029","pt":1724330662769,"mc":[{"id":"1.231812842","rc":[{"batb":[[0,3.6,2.18],[1,3.35,1.74],[2,3.05,1.64]],"ltp":7.8,"tv":19.94,"id":60443}]}]}
{"op":"mcm","clk":"11895441430","pt":1724330668963,"mc":[{"id":"1.231812842","rc":[{"batb":[[0,3.8,4],[1,3.75,50],[2,3.65,10.9]],"ltp":5.3,"tv":38.27,"id":424679},{"batb":[[0,3.65,4],[1,3.6,2.18],[2,3.35,1.74]],"ltp":7.8,"tv":19.94,"id":60443}]}]}
{"op":"mcm","clk":"11895441609","pt":1724330671650,"mc":[{"id":"1.231812842","rc":[{"batb":[[0,3.75,50],[1,3.65,10.9],[2,3.55,1.53]],"ltp":5.3,"tv":38.27,"id":424679},{"batb":[[0,3.6,2.18],[1,3.35,1.74],[2,3.05,1.64]],"ltp":7.8,"tv":19.94,"id":60443}]}]}
{"op":"mcm","clk":"11895441996","pt":1724330677288,"mc":[{"id":"1.231812842","rc":[{"batl":[[1,1.99,10]],"ltp":1.46,"tv":126.56,"id":424676}]}]}
{"op":"mcm","clk":"11895442276","pt":1724330682373,"mc":[{"id":"1.231812842","rc":[{"batl":[[0,1.95,1.72]],"ltp":1.46,"tv":126.56,"id":424676}]}]}
{"op":"mcm","clk":"11895442980","pt":1724330693668,"mc":[{"id":"1.231812842","rc":[{"batl":[[0,1.94,1.29],[1,1.99,10.89]],"ltp":1.46,"tv":126.56,"id":424676}]}]}
{"op":"mcm","clk":"11895448984","pt":1724330780788,"mc":[{"id":"1.231812842","rc":[{"batl":[[0,1.45,1.53],[1,1.94,1.29],[2,1.99,10.89]],"ltp":1.46,"tv":126.56,"id":424676}]}]}
{"op":"mcm","clk":"11895450043","pt":1724330796531,"mc":[{"id":"1.231812842","rc":[{"batl":[[0,1.94,1.29],[1,1.99,10.89],[2,3.5,16]],"ltp":1.46,"tv":126.56,"id":424676}]}]}
{"op":"mcm","clk":"11895450104","pt":1724330797201,"mc":[{"id":"1.231812842","rc":[{"batb":[[1,3.55,1.53],[2,3.05,1.64]],"ltp":5.3,"tv":38.27,"id":424679}]}]}
{"op":"mcm","clk":"11895452230","pt":1724330825428,"mc":[{"id":"1.231812842","rc":[{"batb":[[0,1.85,1.53],[1,1.4,1],[2,1.39,2.28]],"ltp":1.46,"tv":126.56,"id":424676}]}]}
{"op":"mcm","clk":"11895452708","pt":1724330830347,"mc":[{"id":"1.231812842","rc":[{"batl":[[0,8,1.53],[1,10,1],[2,15,1]],"ltp":5.3,"tv":38.27,"id":424679}]}]}
{"op":"mcm","clk":"11895453645","pt":1724330841754,"mc":[{"id":"1.231812842","rc":[{"batb":[[0,1.4,1],[1,1.39,2.28],[2,1.08,31.25]],"ltp":1.46,"tv":126.56,"id":424676}]}]}
{"op":"mcm","clk":"11895453861","pt":1724330844380,"mc":[{"id":"1.231812842","rc":[{"batl":[[0,1.95,1.88],[1,1.99,10]],"ltp":1.46,"tv":126.56,"id":424676}]}]}
{"op":"mcm","clk":"11895454563","pt":1724330851980,"mc":[{"id":"1.231812842","rc":[{"batl":[[0,7.8,1.53],[1,8,1],[2,10,1]],"ltp":5.3,"tv":38.27,"id":424679}]}]}
{"op":"mcm","clk":"11895454975","pt":1724330856781,"mc":[{"id":"1.231812842","rc":[{"batl":[[0,1.94,1.29],[1,1.99,10.89]],"ltp":1.46,"tv":126.56,"id":424676}]}]}
{"op":"mcm","clk":"11895458101","pt":1724330896085,"mc":[{"id":"1.231812842","rc":[{"batl":[[0,1.44,1.53],[1,1.94,1.29],[2,1.99,10.89]],"ltp":1.46,"tv":126.56,"id":424676}]}]}
{"op":"mcm","clk":"11895458293","pt":1724330898314,"mc":[{"id":"1.231812842","rc":[{"batl":[[1,1.94,2.29]],"ltp":1.46,"tv":126.56,"id":424676}]}]}
{"op":"mcm","clk":"11895458968","pt":1724330906925,"mc":[{"id":"1.231812842","rc":[{"batb":[[0,1.4,1.3]],"ltp":1.46,"tv":126.56,"id":424676}]}]}
{"op":"mcm","clk":"11895459201","pt":1724330909835,"mc":[{"id":"1.231812842","rc":[{"batl":[[0,1.94,2.29],[1,1.99,10.89],[2,3.5,16]],"ltp":1.46,"tv":126.56,"id":424676}]}]}
{"op":"mcm","clk":"11895460626","pt":1724330928011,"mc":[{"id":"1.231812842","rc":[{"trd":[[1.88,0.92]],"batb":[[0,1.88,1.07],[1,1.4,1.3],[2,1.39,2.28]],"batl":[[0,1.94,1.83]],"ltp":1.88,"tv":127.48,"id":424676}],"tv":185.7}]}
{"op":"mcm","clk":"11895461461","pt":1724330937947,"mc":[{"id":"1.231812842","rc":[{"trd":[[1.88,2.44]],"batb":[[0,1.4,1.61],[1,1.39,2.28],[2,1.08,31.25]],"ltp":1.88,"tv":129.0,"id":424676}],"tv":187.23}]}
{"op":"mcm","clk":"11895461801","pt":1724330941827,"mc":[{"id":"1.231812842","rc":[{"batb":[[0,1.4,1.3]],"ltp":1.88,"tv":129.0,"id":424676}]}]}
{"op":"mcm","clk":"11895461998","pt":1724330944316,"mc":[{"id":"1.231812842","rc":[{"batl":[[0,1.94,1.3]],"ltp":1.88,"tv":129.0,"id":424676}]}]}
{"op":"mcm","clk":"11895462375","pt":1724330949431,"mc":[{"id":"1.231812842","rc":[{"batl":[[0,1.94,1.83]],"ltp":1.88,"tv":129.0,"id":424676}]}]}
{"op":"mcm","clk":"11895463043","pt":1724330957540,"mc":[{"id":"1.231812842","rc":[{"trd":[[1.39,6.82],[1.4,2.6],[1.41,6.51]],"batb":[[0,1.39,1.93],[1,1.08,31.25],[2,1.07,35.71]],"ltp":1.39,"tv":132.3,"id":424676}],"tv":190.53}]}
{"op":"mcm","clk":"11895464703","pt":1724330977660,"mc":[{"id":"1.231812842","rc":[{"batl":[[0,1.45,1.53],[1,1.94,1.83],[2,1.99,10.89]],"ltp":1.39,"tv":132.3,"id":424676}]}]}
{"op":"mcm","clk":"11895467939","pt":1724331016915,"mc":[{"id":"1.231812842","rc":[{"batl":[[0,1.94,1.83],[1,1.99,10.89],[2,3.5,16]],"ltp":1.39,"tv":132.3,"id":424676}]}]}
{"op":"mcm","clk":"11895471025","pt":1724331059151,"mc":[{"id":"1.231812842","rc":[{"batb":[[0,1.85,1.53],[1,1.39,1.93],[2,1.08,31.25]],"ltp":1.39,"tv":132.3,"id":424676}]}]}
{"op":"mcm","clk":"11895471353","pt":1724331064253,"mc":[{"id":"1.231812842","rc":[{"batl":[[0,8,1.53],[1,10,1],[2,15,1]],"ltp":5.3,"tv":38.27,"id":424679}]}]}
{"op":"mcm","clk":"11895474273","pt":1724331116716,"mc":[{"id":"1.231812842","rc":[{"batb":[[0,1.39,1.93],[1,1.08,31.25],[2,1.07,35.71]],"ltp":1.39,"tv":132.3,"id":424676}]}]}
{"op":"mcm","clk":"11895474734","pt":1724331124828,"mc":[{"id":"1.231812842","rc":[{"batl":[[0,7.8,1.53],[1,8,1],[2,10,1]],"ltp":5.3,"tv":38.27,"id":424679}]}]}
{"op":"mcm","clk":"11895476480","pt":1724331152748,"mc":[{"id":"1.231812842","rc":[{"batl":[[0,1.45,1.53],[1,1.94,1.83],[2,1.99,10.89]],"ltp":1.39,"tv":132.3,"id":424676}]}]}
{"op":"mcm","clk":"11895476820","pt":1724331158260,"mc":[{"id":"1.231812842","rc":[{"batl":[[1,1.94,1.53]],"ltp":1.39,"tv":132.3,"id":424676}]}]}
{"op":"mcm","clk":"11895477207","pt":1724331164861,"mc":[{"id":"1.231812842","rc":[{"batl":[[0,1.94,1.53],[1,1.99,10.89],[2,3.5,16]],"ltp":1.39,"tv":132.3,"id":424676}]}]}
{"op":"mcm","clk":"11895478064","pt":1724331179987,"mc":[{"id":"1.231812842","rc":[{"batb":[[0,1.85,1.53],[1,1.39,1.93],[2,1.08,31.25]],"ltp":1.39,"tv":132.3,"id":424676}]}]}
{"op":"mcm","clk":"11895478124","pt":1724331181067,"mc":[{"id":"1.231812842","rc":[{"batl":[[0,8,1.53],[1,10,1],[2,15,1]],"ltp":5.3,"tv":38.27,"id":424679}]}]}
{"op":"mcm","clk":"11895478259","pt":1724331183491,"mc":[{"id":"1.231812842","rc":[{"batl":[[0,1.94,1.83]],"ltp":1.39,"tv":132.3,"id":424676}]}]}
{"op":"mcm","clk":"11895478869","pt":1724331194002,"mc":[{"id":"1.231812842","rc":[{"batb":[[0,1.39,1.93],[1,1.08,31.25],[2,1.07,35.71]],"ltp":1.39,"tv":132.3,"id":424676}]}]}
{"op":"mcm","clk":"11895479390","pt":1724331202812,"mc":[{"id":"1.231812842","rc":[{"batl":[[0,7.8,1.53],[1,8,1],[2,10,1]],"ltp":5.3,"tv":38.27,"id":424679}]}]}
{"op":"mcm","clk":"11895479857","pt":1724331211733,"mc":[{"id":"1.231812842","rc":[{"batb":[[0,1.39,2.23]],"ltp":1.39,"tv":132.3,"id":424676}]}]}
{"op":"mcm","clk":"11895480314","pt":1724331219912,"mc":[{"id":"1.231812842","rc":[{"batb":[[0,5.2,1.53],[1,3.6,2.18],[2,3.35,1.74]],"ltp":7.8,"tv":19.94,"id":60443}]}]}
{"op":"mcm","clk":"11895480598","pt":1724331224710,"mc":[{"id":"1.231812842","rc":[{"batl":[[0,1.94,1.3]],"ltp":1.39,"tv":132.3,"id":424676}]}]}
{"op":"mcm","clk":"11895480639","pt":1724331225638,"mc":[{"id":"1.231812842","rc":[{"batb":[[1,3.55,1.42],[2,3.05,2.49]],"ltp":7.8,"tv":19.94,"id":60443}]}]}
{"op":"mcm","clk":"11895480879","pt":1724331229801,"mc":[{"id":"1.231812842","rc":[{"batl":[[0,1.94,1.83]],"ltp":1.39,"tv":132.3,"id":424676}]}]}
{"op":"mcm","clk":"11895481105","pt":1724331234134,"mc":[{"id":"1.231812842","rc":[{"batb":[[0,7.6,1.53],[1,5.2,1.53],[2,3.55,1.42]],"ltp":7.8,"tv":19.94,"id":60443}]}]}
{"op":"mcm","clk":"11895481193","pt":1724331236125,"mc":[{"id":"1.231812842","rc":[{"batb":[[1,5.3,1.12],[2,5.2,1.53]],"ltp":7.8,"tv":19.94,"id":60443}]}]}
{"op":"mcm","clk":"11895481544","pt":1724331242520,"mc":[{"id":"1.231812842","rc":[{"batb":[[0,3.55,1.42],[1,3.05,2.49],[2,2.82,1.42]],"ltp":7.8,"tv":19.94,"id":60443}]}]}
{"op":"mcm","clk":"11895482115","pt":1724331252835,"mc":[{"id":"1.231812842","rc":[{"batb":[[0,3.6,2.18],[1,3.35,1.74],[2,3.05,1.64]],"ltp":7.8,"tv":19.94,"id":60443}]}]}
{"op":"mcm","clk":"11895482367","pt":1724331256861,"mc":[{"id":"1.231812842","rc":[{"batb":[[0,6,1.53],[1,3.6,2.18],[2,3.35,1.74]],"ltp":7.8,"tv":19.94,"id":60443}]}]}
{"op":"mcm","clk":"11895482504","pt":1724331259026,"mc":[{"id":"1.231812842","rc":[{"batb":[[1,3.55,1.42],[2,3.05,2.49]],"ltp":7.8,"tv":19.94,"id":60443}]}]}
{"op":"mcm","clk":"11895482941","pt":1724331267953,"mc":[{"id":"1.231812842","rc":[{"batl":[[0,1.45,1.53],[1,1.94,1.83],[2,1.99,10.89]],"ltp":1.39,"tv":132.3,"id":424676}]}]}
{"op":"mcm","clk":"11895483336","pt":1724331275746,"mc":[{"id":"1.231812842","rc":[{"batl":[[0,8,1.53],[1,10,1],[2,15,1]],"ltp":5.3,"tv":38.27,"id":424679},{"trd":[[7.8,1.24],[8,2]],"batb":[[0,9.6,1.82],[1,6,2.49],[2,3.55,1.42]],"batl":[[0,10,1],[1,15,1.53],[2,21,1]],"ltp":8.0,"tv":22.42,"id":60443}],"tv":193.0}]}
{"op":"mcm","clk":"11895483656","pt":1724331281358,"mc":[{"id":"1.231812842","rc":[{"batb":[[1,6,1.53]],"ltp":8.0,"tv":22.42,"id":60443}]}]}
{"op":"mcm","clk":"11895483704","pt":1724331282079,"mc":[{"id":"1.231812842","rc":[{"batb":[[2,4.1,1.95]],"ltp":8.0,"tv":22.42,"id":60443}]}]}
{"op":"mcm","clk":"11895484346","pt":1724331293880,"mc":[{"id":"1.231812842","rc":[{"batl":[[1,1.95,1.72],[2,1.99,10]],"ltp":1.39,"tv":132.3,"id":424676}]}]}
{"op":"mcm","clk":"11895484554","pt":1724331297396,"mc":[{"id":"1.231812842","rc":[{"trd":[[9.8,0.6]],"batb":[[0,9.6,2.32]],"ltp":9.8,"tv":23.02,"id":60443}],"tv":193.6}]}
{"op":"mcm","clk":"11895484867","pt":1724331302516,"mc":[{"id":"1.231812842","rc":[{"batb":[[0,4.1,2.45],[1,3.55,1.42],[2,3.05,2.49]],"ltp":9.8,"tv":23.02,"id":60443}]}]}
{"op":"mcm","clk":"11895485153","pt":1724331307715,"mc":[{"id":"1.231812842","rc":[{"batb":[[0,4.2,4.5],[1,4.1,1.95],[2,3.55,1.42]],"ltp":9.8,"tv":23.02,"id":60443}]}]}
{"op":"mcm","clk":"11895485202","pt":1724331308602,"mc":[{"id":"1.231812842","rc":[{"batb":[[0,4.2,4]],"batl":[[0,10,1.5]],"ltp":9.8,"tv":23.02,"id":60443}]}]}
{"op":"mcm","clk":"11895485284","pt":1724331310220,"mc":[{"id":"1.231812842","rc":[{"batb":[[0,4.1,1.95],[1,3.55,1.42],[2,3.05,2.49]],"ltp":9.8,"tv":23.02,"id":60443}]}]}
{"op":"mcm","clk":"11895485525","pt":1724331314198,"mc":[{"id":"1.231812842","rc":[{"batl":[[0,7.8,1.53],[1,8,1],[2,10,1]],"ltp":5.3,"tv":38.27,"id":424679}]}]}
{"op":"mcm","clk":"11895485763","pt":1724331318029,"mc":[{"id":"1.231812842","rc":[{"batb":[[0,7,1.53],[1,4.1,1.95],[2,3.55,1.42]],"ltp":9.8,"tv":23.02,"id":60443}]}]}
{"op":"mcm","clk":"11895485874","pt":1724331319732,"mc":[{"id":"1.231812842","rc":[{"batl":[[0,1.45,3.05]],"ltp":1.39,"tv":132.3,"id":424676},{"batb":[[1,4.2,1.16],[2,4.1,1.95]],"ltp":9.8,"tv":23.02,"id":60443}]}]}
{"op":"mcm","clk":"11895486411","pt":1724331329605,"mc":[{"id":"1.231812842","rc":[{"batb":[[0,9,1.53],[1,7,1.53],[2,4.2,1.16]],"ltp":9.8,"tv":23.02,"id":60443}]}]}
{"op":"mcm","clk":"11895486524","pt":1724331331423,"mc":[{"id":"1.231812842","rc":[{"batl":[[0,8,1.53],[1,10,1],[2,15,1]],"ltp":5.3,"tv":38.27,"id":424679},{"batb":[[2,4.1,1.95]],"ltp":9.8,"tv":23.02,"id":60443}]}]}
{"op":"mcm","clk":"11895487332","pt":1724331346282,"mc":[{"id":"1.231812842","rc":[{"batl":[[0,1.45,1.53]],"ltp":1.39,"tv":132.3,"id":424676}]}]}
{"op":"mcm","clk":"11895487403","pt":1724331347564,"mc":[{"id":"1.231812842","rc":[{"batb":[[0,9,2.06]],"ltp":9.8,"tv":23.02,"id":60443}]}]}
{"op":"mcm","clk":"11895487703","pt":1724331353077,"mc":[{"id":"1.231812842","rc":[{"batl":[[0,1.95,1.72],[1,1.99,10],[2,3.5,16]],"ltp":1.39,"tv":132.3,"id":424676}]}]}
{"op":"mcm","clk":"11895487781","pt":1724331354267,"mc":[{"id":"1.231812842","rc":[{"batb":[[0,4.1,2.48],[1,3.55,1.42],[2,3.05,2.49]],"ltp":9.8,"tv":23.02,"id":60443}]}]}
{"op":"mcm","clk":"11895489001","pt":1724331373490,"mc":[{"id":"1.231812842","rc":[{"batb":[[0,1.55,1.53],[1,1.39,2.23],[2,1.08,31.25]],"ltp":1.39,"tv":132.3,"id":424676}]}]}
{"op":"mcm","clk":"11895489302","pt":1724331378212,"mc":[{"id":"1.231812842","rc":[{"batb":[[0,8,2.06],[1,4.1,1.95],[2,3.55,1.42]],"ltp":9.8,"tv":23.02,"id":60443}]}]}
{"op":"mcm","clk":"11895489535","pt":1724331381520,"mc":[{"id":"1.231812842","rc":[{"batl":[[0,10,1]],"ltp":9.8,"tv":23.02,"id":60443}]}]}
{"op":"mcm","clk":"11895490660","pt":1724331398440,"mc":[{"id":"1.231812842","rc":[{"batb":[[0,1.39,2.23],[1,1.08,31.25],[2,1.07,35.71]],"ltp":1.39,"tv":132.3,"id":424676}]}]}
{"op":"mcm","clk":"11895491808","pt":1724331416966,"mc":[{"id":"1.231812842","rc":[{"batl":[[0,1.43,1.53],[1,1.95,1.72],[2,1.99,10]],"ltp":1.39,"tv":132.3,"id":424676}]}]}
{"op":"mcm","clk":"11895492560","pt":1724331430064,"mc":[{"id":"1.231812842","rc":[{"batl":[[0,1.95,1.72],[1,1.99,10],[2,3.5,16]],"ltp":1.39,"tv":132.3,"id":424676}]}]}
{"op":"mcm","clk":"11895493536","pt":1724331446211,"mc":[{"id":"1.231812842","rc":[{"batb":[[0,1.56,1.53],[1,1.39,2.23],[2,1.08,31.25]],"ltp":1.39,"tv":132.3,"id":424676}]}]}
{"op":"mcm","clk":"11895493830","pt":1724331451624,"mc":[{"id":"1.231812842","rc":[{"batb":[[0,4.1,2.48],[1,3.55,1.42],[2,3.05,2.49]],"ltp":9.8,"tv":23.02,"id":60443}]}]}
{"op":"mcm","clk":"11895494284","pt":1724331458948,"mc":[{"id":"1.231812842","rc":[{"batl":[[0,9.8,1],[1,10,1],[2,15,1.53]],"ltp":9.8,"tv":23.02,"id":60443}]}]}
{"op":"mcm","clk":"11895494896","pt":1724331468817,"mc":[{"id":"1.231812842","rc":[{"trd":[[9.2,1.06]],"batb":[[0,4.1,1.95]],"batl":[[0,4.3,1],[1,9.8,1],[2,10,1]],"ltp":9.2,"tv":24.08,"id":60443}],"tv":194.66}]}
{"op":"mcm","clk":"11895495023","pt":1724331470764,"mc":[{"id":"1.231812842","rc":[{"batl":[[1,10,1],[2,15,1.53]],"ltp":9.2,"tv":24.08,"id":60443}]}]}
{"op":"mcm","clk":"11895495117","pt":1724331472053,"mc":[{"id":"1.231812842","rc":[{"trd":[[4.1,3.06]],"batb":[[0,3.55,1.84],[1,3.05,2.49],[2,2.82,1.42]],"ltp":4.1,"tv":27.13,"id":60443}],"tv":197.71}]}
{"op":"mcm","clk":"11895495242","pt":1724331473923,"mc":[{"id":"1.231812842","rc":[{"trd":[[4.3,2]],"batl":[[0,10,1],[1,15,1.53],[2,21,1]],"ltp":4.3,"tv":29.13,"id":60443}],"tv":199.71}]}
{"op":"mcm","clk":"11895495360","pt":1724331475637,"mc":[{"id":"1.231812842","rc":[{"batl":[[0,7.8,1.53],[1,8,1],[2,10,1]],"ltp":5.3,"tv":38.27,"id":424679}]}]}
{"op":"mcm","clk":"11895495460","pt":1724331477052,"mc":[{"id":"1.231812842","rc":[{"batl":[[0,1.95,1.42]],"ltp":1.39,"tv":132.3,"id":424676}]}]}
{"op":"mcm","clk":"11895495581","pt":1724331479016,"mc":[{"id":"1.231812842","rc":[{"batb":[[0,3.6,4.95],[1,3.35,1.74],[2,3.05,1.64]],"ltp":4.3,"tv":29.13,"id":60443}]}]}
{"op":"mcm","clk":"11895495741","pt":1724331481417,"mc":[{"id":"1.231812842","rc":[{"batb":[[0,1.39,2.23],[1,1.08,31.25],[2,1.07,35.71]],"ltp":1.39,"tv":132.3,"id":424676},{"batb":[[0,3.55,1.84],[1,3.05,2.49],[2,2.82,1.42]],"batl":[[0,9.8,1],[1,10,1],[2,15,1.53]],"ltp":4.3,"tv":29.13,"id":60443}]}]}
{"op":"mcm","clk":"11895496015","pt":1724331485661,"mc":[{"id":"1.231812842","rc":[{"batl":[[0,4.5,1.53],[1,9.8,1],[2,10,1]],"ltp":4.3,"tv":29.13,"id":60443}]}]}
{"op":"mcm","clk":"11895496140","pt":1724331487327,"mc":[{"id":"1.231812842","rc":[{"batl":[[1,10,1],[2,15,1.53]],"ltp":4.3,"tv":29.13,"id":60443}]}]}
{"op":"mcm","clk":"11895496346","pt":1724331490458,"mc":[{"id":"1.231812842","rc":[{"batb":[[0,3.6,1.25],[1,3.35,1.74],[2,3.05,1.64]],"ltp":4.3,"tv":29.13,"id":60443}]}]}
{"op":"mcm","clk":"11895496370","pt":1724331490835,"mc":[{"id":"1.231812842","rc":[{"batb":[[0,3.6,5.25]],"ltp":4.3,"tv":29.13,"id":60443}]}]}
{"op":"mcm","clk":"11895496543","pt":1724331493655,"mc":[{"id":"1.231812842","rc":[{"batb":[[0,3.6,1.25]],"ltp":4.3,"tv":29.13,"id":60443}]}]}
{"op":"mcm","clk":"11895496931","pt":1724331499874,"mc":[{"id":"1.231812842","rc":[{"trd":[[4.1,3.89]],"batb":[[0,3.55,1.72],[1,3.05,2.49],[2,2.82,1.42]],"batl":[[0,3.8,1.11],[1,4.5,1.53],[2,10,1]],"ltp":4.1,"tv":29.97,"id":60443}],"tv":200.55}]}
{"op":"mcm","clk":"11895497076","pt":1724331502162,"mc":[{"id":"1.231812842","rc":[{"batb":[[0,1.39,1.93]],"ltp":1.39,"tv":132.3,"id":424676}]}]}
{"op":"mcm","clk":"11895497173","pt":1724331503859,"mc":[{"id":"1.231812842","rc":[{"trd":[[1.82,1.07]],"batb":[[0,1.39,2.92]],"batl":[[0,1.99,10.89],[1,3.5,16],[2,4,1]],"ltp":1.82,"tv":133.37,"id":424676}],"tv":201.62}]}
{"op":"mcm","clk":"11895497349","pt":1724331507288,"mc":[{"id":"1.231812842","rc":[{"batl":[[2,8,1]],"ltp":4.1,"tv":29.97,"id":60443}]}]}
{"op":"mcm","clk":"11895497404","pt":1724331508516,"mc":[{"id":"1.231812842","rc":[{"batb":[[0,1.56,1.29],[1,1.39,1.93],[2,1.08,31.25]],"batl":[[0,1.95,1.19],[1,1.99,10],[2,3.5,16]],"ltp":1.82,"tv":133.37,"id":424676}]}]}
{"op":"mcm","clk":"11895497610","pt":1724331511776,"mc":[{"id":"1.231812842","rc":[{"batl":[[0,3.8,2.63]],"ltp":4.1,"tv":29.97,"id":60443}]}]}
{"op":"mcm","clk":"11895497792","pt":1724331515066,"mc":[{"id":"1.231812842","rc":[{"batl":[[0,8,1.53],[1,10,1],[2,15,1]],"ltp":5.3,"tv":38.27,"id":424679}]}]}
{"op":"mcm","clk":"11895498656","pt":1724331530813,"mc":[{"id":"1.231812842","rc":[{"batb":[[0,1.39,2.23],[1,1.08,31.25],[2,1.07,35.71]],"ltp":1.82,"tv":133.37,"id":424676}]}]}
{"op":"mcm","clk":"11895499634","pt":1724331547422,"mc":[{"id":"1.231812842","rc":[{"trd":[[7.4,0.13]],"batl":[[0,8,1.4]],"ltp":7.4,"tv":38.4,"id":424679},{"trd":[[1.66,0.57]],"ltp":1.66,"tv":133.94,"id":424676},{"trd":[[3.8,0.25]],"batl":[[0,3.8,2.38]],"ltp":3.8,"tv":30.22,"id":60443}],"tv":202.57}]}
{"op":"mcm","clk":"11895512220","pt":1724331741041,"mc":[{"id":"1.231812842","rc":[{"trd":[[1.39,6.81],[1.41,6.5],[1.42,4.87],[1.46,9.67],[1.51,5.05],[1.86,2.13],[1.88,2.44],[1.9,8.78],[1.93,2.5],[2,11.99]],"batb":[[0,1.39,2.23]],"ltp":1.66,"tv":133.91,"id":424676},{"trd":[[4.1,3.89]],"batl":[[0,8,1],[1,10,1],[2,15,1.53]],"ltp":3.8,"tv":30.22,"id":60443}],"tv":202.53}]}
{"op":"mcm","clk":"11895512727","pt":1724331748426,"mc":[{"id":"1.231812842","rc":[{"batl":[[0,7.8,1.4],[1,8,1],[2,10,1]],"ltp":7.4,"tv":38.4,"id":424679},{"batl":[[0,7.8,1],[1,8,1],[2,10,1]],"ltp":3.8,"tv":30.22,"id":60443}]}]}
{"op":"mcm","clk":"11895517153","pt":1724331812121,"mc":[{"id":"1.231812842","rc":[{"batb":[[0,3.55,1.42]],"ltp":3.8,"tv":30.22,"id":60443}]}]}
{"op":"mcm","clk":"11895517597","pt":1724331818386,"mc":[{"id":"1.231812842","rc":[{"batb":[[0,7,1.52],[1,3.55,1.42],[2,3.05,2.49]],"ltp":3.8,"tv":30.22,"id":60443}]}]}
{"op":"mcm","clk":"11895518104","pt":1724331826750,"mc":[{"id":"1.231812842","rc":[{"batb":[[0,1.39,1.93],[2,1.07,36.01]],"batl":[[0,1.99,10.88],[1,3.5,16],[2,4,1]],"ltp":1.66,"tv":133.91,"id":424676}]}]}
{"op":"mcm","clk":"11895518125","pt":1724331826908,"mc":[{"id":"1.231812842","rc":[{"batb":[[2,1.07,35.71]],"ltp":1.66,"tv":133.91,"id":424676},{"batl":[[0,8,1],[1,10,1],[2,15,1.53]],"ltp":3.8,"tv":30.22,"id":60443}]}]}
{"op":"mcm","clk":"11895518334","pt":1724331829937,"mc":[{"id":"1.231812842","rc":[{"batl":[[0,1.45,1.52],[1,1.99,10.88],[2,3.5,16]],"ltp":1.66,"tv":133.91,"id":424676}]}]}
{"op":"mcm","clk":"11895518456","pt":1724331832029,"mc":[{"id":"1.231812842","rc":[{"batb":[[0,1.39,2.23]],"ltp":1.66,"tv":133.91,"id":424676}]}]}
{"op":"mcm","clk":"11895518859","pt":1724331839129,"mc":[{"id":"1.231812842","rc":[{"trd":[[8,4]],"batb":[[0,7,2.05]],"batl":[[0,10,1],[1,15,1.53],[2,21,1]],"ltp":8.0,"tv":32.22,"id":60443}],"tv":204.53}]}
{"op":"mcm","clk":"11895518945","pt":1724331840436,"mc":[{"id":"1.231812842","rc":[{"batl":[[0,1.99,10.88],[1,3.5,16],[2,4,1]],"ltp":1.66,"tv":133.91,"id":424676}]}]}
{"op":"mcm","clk":"11895519067","pt":1724331842317,"mc":[{"id":"1.231812842","rc":[{"batb":[[0,8,2.05],[1,7,1.52],[2,3.55,1.42]],"ltp":8.0,"tv":32.22,"id":60443}]}]}
{"op":"mcm","clk":"11895519198","pt":1724331844234,"mc":[{"id":"1.231812842","rc":[{"batb":[[1,7.2,4],[2,7,1.52]],"ltp":8.0,"tv":32.22,"id":60443}]}]}
{"op":"mcm","clk":"11895519367","pt":1724331847450,"mc":[{"id":"1.231812842","rc":[{"batb":[[1,7,1.52],[2,4.1,1.95]],"ltp":8.0,"tv":32.22,"id":60443}]}]}
{"op":"mcm","clk":"11895523554","pt":1724331911128,"mc":[{"id":"1.231812842","rc":[{"batb":[[0,1.08,31.55],[1,1.07,35.71],[2,1.06,41.67]],"ltp":1.66,"tv":133.91,"id":424676}]}]}
{"op":"mcm","clk":"11895523935","pt":1724331916433,"mc":[{"id":"1.231812842","rc":[{"batb":[[0,1.35,2.23],[1,1.08,31.25],[2,1.07,35.71]],"ltp":1.66,"tv":133.91,"id":424676}]}]}
{"op":"mcm","clk":"11895537215","pt":1724332126858,"mc":[{"id":"1.231812842","rc":[{"batb":[[0,4.1,1.95],[1,3.55,1.42],[2,3.05,2.49]],"ltp":8.0,"tv":32.22,"id":60443}]}]}
{"op":"mcm","clk":"11895537507","pt":1724332132481,"mc":[{"id":"1.231812842","rc":[{"batl":[[0,9.8,1],[1,10,1],[2,15,1.53]],"ltp":8.0,"tv":32.22,"id":60443}]}]}
{"op":"mcm","clk":"11895537913","pt":1724332138706,"mc":[{"id":"1.231812842","rc":[{"batl":[[0,4.7,1.52]],"ltp":8.0,"tv":32.22,"id":60443}]}]}
{"op":"mcm","clk":"11895537959","pt":1724332139293,"mc":[{"id":"1.231812842","rc":[{"batl":[[0,1.98,1.18],[1,1.99,10],[2,3.5,16]],"ltp":1.66,"tv":133.91,"id":424676}]}]}
{"op":"mcm","clk":"11895538781","pt":1724332151192,"mc":[{"id":"1.231812842","rc":[{"batl":[[0,4.2,1.52],[1,4.7,1.52],[2,10,1]],"ltp":8.0,"tv":32.22,"id":60443}]}]}
{"op":"mcm","clk":"11895539091","pt":1724332156317,"mc":[{"id":"1.231812842","rc":[{"trd":[[4.2,3.04]],"batl":[[0,4.7,1.52],[1,10,1],[2,15,1.53]],"ltp":4.2,"tv":35.26,"id":60443}],"tv":207.58}]}
{"op":"mcm","clk":"11895539295","pt":1724332160039,"mc":[{"id":"1.231812842","rc":[{"batb":[[0,1.35,1.93]],"ltp":1.66,"tv":133.91,"id":424676}]}]}
{"op":"mcm","clk":"11895539639","pt":1724332166038,"mc":[{"id":"1.231812842","rc":[{"batl":[[0,4.2,1.52],[1,4.7,1.52],[2,10,1]],"ltp":4.2,"tv":35.26,"id":60443}]}]}
{"op":"mcm","clk":"11895539936","pt":1724332171426,"mc":[{"id":"1.231812842","rc":[{"trd":[[4.2,6.09]],"batl":[[0,4.7,1.52],[1,10,1],[2,15,1.53]],"ltp":4.2,"tv":38.31,"id":60443}],"tv":210.62}]}
{"op":"mcm","clk":"11895540175","pt":1724332176499,"mc":[{"id":"1.231812842","rc":[{"batb":[[0,1.35,2.23]],"ltp":1.66,"tv":133.91,"id":424676}]}]}
{"op":"mcm","clk":"11895540514","pt":1724332182736,"mc":[{"id":"1.231812842","rc":[{"batl":[[0,4.3,1.52],[1,4.7,1.52],[2,10,1]],"ltp":4.2,"tv":38.31,"id":60443}]}]}
{"op":"mcm","clk":"11895545562","pt":1724332263103,"mc":[{"id":"1.231812842","rc":[{"batb":[[2,3.25,12.26]],"ltp":7.4,"tv":38.4,"id":424679},{"batb":[[1,1.32,30.19],[2,1.08,31.25]],"ltp":1.66,"tv":133.91,"id":424676}]}]}
{"op":"mcm","clk":"11895546553","pt":1724332278724,"mc":[{"id":"1.231812842","rc":[{"batb":[[2,3.05,1.64]],"ltp":7.4,"tv":38.4,"id":424679},{"batb":[[1,1.08,31.25],[2,1.07,35.71]],"ltp":1.66,"tv":133.91,"id":424676}]}]}
{"op":"mcm","clk":"11895563891","pt":1724332402080,"mc":[{"id":"1.231812842","rc":[{"batb":[[0,3.55,1.42],[1,3.05,2.49],[2,2.82,1.42]],"ltp":4.2,"tv":38.31,"id":60443}]}]}
{"op":"mcm","clk":"11895564186","pt":1724332407205,"mc":[{"id":"1.231812842","rc":[{"trd":[[4.3,5.04]],"batb":[[0,3.55,1.85]],"batl":[[0,4.7,1.52],[1,10,1],[2,15,1.53]],"ltp":4.3,"tv":41.35,"id":60443}],"tv":213.67}]}
{"op":"mcm","clk":"11895564371","pt":1724332410471,"mc":[{"id":"1.231812842","rc":[{"batb":[[0,3.55,1.42]],"ltp":4.3,"tv":41.35,"id":60443}]}]}
{"op":"mcm","clk":"11895564685","pt":1724332415609,"mc":[{"id":"1.231812842","rc":[{"trd":[[4.7,0.86]],"batl":[[0,4.7,1.1]],"ltp":4.7,"tv":42.21,"id":60443}],"tv":214.52}]}
{"op":"mcm","clk":"11895564824","pt":1724332417991,"mc":[{"id":"1.231812842","rc":[{"batl":[[0,3.95,1.52],[1,4.7,1.1],[2,10,1]],"ltp":4.7,"tv":42.21,"id":60443}]}]}
{"op":"mcm","clk":"11895564875","pt":1724332418772,"mc":[{"id":"1.231812842","rc":[{"batl":[[2,8,1]],"ltp":4.7,"tv":42.21,"id":60443}]}]}
{"op":"mcm","clk":"11895565058","pt":1724332421668,"mc":[{"id":"1.231812842","rc":[{"batl":[[0,3.75,1.52],[1,3.95,1.52],[2,4.7,1.1]],"ltp":4.7,"tv":42.21,"id":60443}]}]}
{"op":"mcm","clk":"11895565112","pt":1724332422698,"mc":[{"id":"1.231812842","rc":[{"batl":[[0,8,1.4],[1,10,1],[2,15,1]],"ltp":7.4,"tv":38.4,"id":424679}]}]}
{"op":"mcm","clk":"11895565995","pt":1724332437016,"mc":[{"id":"1.231812842","rc":[{"batb":[[0,3.35,1.38],[1,3.05,1.64]],"ltp":4.7,"tv":42.21,"id":60443}]}]}
{"op":"mcm","clk":"11895566293","pt":1724332442137,"mc":[{"id":"1.231812842","rc":[{"trd":[[3.75,1.78]],"batl":[[0,3.95,2.16],[1,4.7,1.1],[2,8,1]],"ltp":3.75,"tv":43.99,"id":60443}],"tv":216.3}]}
{"op":"mcm","clk":"11895566634","pt":1724332447610,"mc":[{"id":"1.231812842","rc":[{"batl":[[2,6,1]],"ltp":3.75,"tv":43.99,"id":60443}]}]}
{"op":"mcm","clk":"11895566769","pt":1724332449745,"mc":[{"id":"1.231812842","rc":[{"batl":[[0,1.99,10.88],[1,3.5,16],[2,4,1]],"ltp":1.66,"tv":133.91,"id":424676}]}]}
{"op":"mcm","clk":"11895567005","pt":1724332454249,"mc":[{"id":"1.231812842","rc":[{"batl":[[0,1.97,1.18],[1,1.99,10],[2,3.5,16]],"ltp":1.66,"tv":133.91,"id":424676}]}]}
{"op":"mcm","clk":"11895567237","pt":1724332458327,"mc":[{"id":"1.231812842","rc":[{"batl":[[0,3.7,1.52],[1,3.95,2.16],[2,4.7,1.1]],"ltp":3.75,"tv":43.99,"id":60443}]}]}
{"op":"mcm","clk":"11895568028","pt":1724332471156,"mc":[{"id":"1.231812842","rc":[{"batl":[[0,6,1],[1,8,1],[2,10,1]],"ltp":3.75,"tv":43.99,"id":60443}]}]}
{"op":"mcm","clk":"11895568439","pt":1724332477872,"mc":[{"id":"1.231812842","rc":[{"batl":[[0,7.8,1.4],[1,8,1],[2,10,1]],"ltp":7.4,"tv":38.4,"id":424679}]}]}
{"op":"mcm","clk":"11895569397","pt":1724332493904,"mc":[{"id":"1.231812842","rc":[{"batl":[[0,5.4,1.52],[1,6,1],[2,8,1]],"ltp":3.75,"tv":43.99,"id":60443}]}]}
{"op":"mcm","clk":"11895569710","pt":1724332499193,"mc":[{"id":"1.231812842","rc":[{"batb":[[0,1.35,1.93]],"ltp":1.66,"tv":133.91,"id":424676}]}]}
{"op":"mcm","clk":"11895569942","pt":1724332502559,"mc":[{"id":"1.231812842","rc":[{"batb":[[0,1.35,2.23]],"ltp":1.66,"tv":133.91,"id":424676}]}]}
{"op":"mcm","clk":"11895573959","pt":1724332561242,"mc":[{"id":"1.231812842","rc":[{"batl":[[0,6,1],[1,8,1],[2,10,1]],"ltp":3.75,"tv":43.99,"id":60443}]}]}
{"op":"mcm","clk":"11895575647","pt":1724332586009,"mc":[{"id":"1.231812842","rc":[{"batl":[[0,7.8,1]],"ltp":7.4,"tv":38.4,"id":424679},{"batb":[[0,1.08,31.55],[1,1.07,35.71],[2,1.06,41.67]],"ltp":1.66,"tv":133.91,"id":424676},{"batb":[[0,3.05,2.49],[1,2.82,1.42],[2,2.62,1.33]],"ltp":3.75,"tv":43.99,"id":60443}]}]}
{"op":"mcm","clk":"11895576906","pt":1724332604324,"mc":[{"id":"1.231812842","rc":[{"batl":[[0,1.95,1.42],[1,1.99,10.3]],"ltp":1.66,"tv":133.91,"id":424676}]}]}
{"op":"mcm","clk":"11895580113","pt":1724332655557,"mc":[{"id":"1.231812842","rc":[{"batb":[[2,3.25,12.26]],"ltp":7.4,"tv":38.4,"id":424679},{"batb":[[0,1.32,30.49],[1,1.08,31.25],[2,1.07,35.71]],"ltp":1.66,"tv":133.91,"id":424676}]}]}
{"op":"mcm","clk":"11895580162","pt":1724332656375,"mc":[{"id":"1.231812842","rc":[{"batb":[[2,3.05,1.64]],"ltp":7.4,"tv":38.4,"id":424679},{"batb":[[0,1.08,31.55],[1,1.07,35.71],[2,1.06,41.67]],"ltp":1.66,"tv":133.91,"id":424676}]}]}
{"op":"mcm","clk":"11895580467","pt":1724332661164,"mc":[{"id":"1.231812842","rc":[{"batb":[[0,1.38,29.2],[1,1.08,31.25],[2,1.07,35.71]],"ltp":1.66,"tv":133.91,"id":424676}]}]}
{"op":"mcm","clk":"11895580906","pt":1724332669179,"mc":[{"id":"1.231812842","rc":[{"batb":[[0,1.08,31.55],[1,1.07,35.71],[2,1.06,41.67]],"ltp":1.66,"tv":133.91,"id":424676}]}]}
{"op":"mcm","clk":"11895582168","pt":1724332688226,"mc":[{"id":"1.231812842","rc":[{"batb":[[0,1.38,29.2],[1,1.08,31.25],[2,1.07,35.71]],"ltp":1.66,"tv":133.91,"id":424676}]}]}
{"op":"mcm","clk":"11895583108","pt":1724332703095,"mc":[{"id":"1.231812842","rc":[{"batb":[[0,1.08,31.55],[1,1.07,35.71],[2,1.06,41.67]],"ltp":1.66,"tv":133.91,"id":424676}]}]}
{"op":"mcm","clk":"11895585295","pt":1724332737264,"mc":[{"id":"1.231812842","rc":[{"batl":[[1,1.99,10]],"ltp":1.66,"tv":133.91,"id":424676}]}]}
{"op":"mcm","clk":"11895585628","pt":1724332742358,"mc":[{"id":"1.231812842","rc":[{"batl":[[0,1.95,1.72]],"ltp":1.66,"tv":133.91,"id":424676}]}]}
{"op":"mcm","clk":"11895587023","pt":1724332764166,"mc":[{"id":"1.231812842","rc":[{"batb":[[0,1.08,31.25]],"ltp":1.66,"tv":133.91,"id":424676}]}]}
{"op":"mcm","clk":"11895587288","pt":1724332768393,"mc":[{"id":"1.231812842","rc":[{"batb":[[0,1.08,31.55]],"ltp":1.66,"tv":133.91,"id":424676}]}]}
{"op":"mcm","clk":"11895601111","pt":1724332995745,"mc":[{"id":"1.231812842","rc":[{"batl":[[0,4,1.52],[1,6,1],[2,8,1]],"ltp":3.75,"tv":43.99,"id":60443}]}]}
{"op":"mcm","clk":"11895601145","pt":1724332996139,"mc":[{"id":"1.231812842","rc":[{"batl":[[0,8,1],[1,10,1],[2,15,1]],"ltp":7.4,"tv":38.4,"id":424679}]}]}
{"op":"mcm","clk":"11895601332","pt":1724332999340,"mc":[{"id":"1.231812842","rc":[{"batl":[[0,1.94,1.13],[1,1.99,10.88]],"ltp":1.66,"tv":133.91,"id":424676}]}]}
{"op":"mcm","clk":"11895601417","pt":1724333000860,"mc":[{"id":"1.231812842","rc":[{"batl":[[0,1.95,1.72],[1,1.99,10]],"ltp":1.66,"tv":133.91,"id":424676}]}]}
{"op":"mcm","clk":"11895603784","pt":1724333039399,"mc":[{"id":"1.231812842","rc":[{"batb":[[0,1.08,31.25]],"ltp":1.66,"tv":133.91,"id":424676}]}]}
{"op":"mcm","clk":"11895613733","pt":1724333189593,"mc":[{"id":"1.231812842","rc":[{"batl":[[0,6,1],[1,8,1],[2,10,1]],"ltp":3.75,"tv":43.99,"id":60443}]}]}
{"op":"mcm","clk":"11895614176","pt":1724333196005,"mc":[{"id":"1.231812842","rc":[{"batl":[[0,7.8,1],[1,8,1],[2,10,1]],"ltp":7.4,"tv":38.4,"id":424679}]}]}
{"op":"mcm","clk":"11895614493","pt":1724333200747,"mc":[{"id":"1.231812842","rc":[{"batb":[[0,1.08,31.55]],"ltp":1.66,"tv":133.91,"id":424676}]}]}
{"op":"mcm","clk":"11895614509","pt":1724333200910,"mc":[{"id":"1.231812842","rc":[{"batb":[[0,7,1.52],[1,3.75,50],[2,3.55,1.53]],"ltp":7.4,"tv":38.4,"id":424679}]}]}
{"op":"mcm","clk":"11895614581","pt":1724333202139,"mc":[{"id":"1.231812842","rc":[{"batl":[[0,8,1],[1,10,1],[2,15,1]],"ltp":7.4,"tv":38.4,"id":424679}]}]}
{"op":"mcm","clk":"11895615337","pt":1724333214355,"mc":[{"id":"1.231812842","rc":[{"trd":[[8,3.51]],"batb":[[0,7,2.05]],"batl":[[0,10,1],[1,15,1],[2,15.5,4]],"ltp":8.0,"tv":40.4,"id":424679}],"tv":218.3}]}
{"op":"mcm","clk":"11895615569","pt":1724333218066,"mc":[{"id":"1.231812842","rc":[{"batb":[[0,8,2.05],[1,7,1.52],[2,3.75,50]],"ltp":8.0,"tv":40.4,"id":424679}]}]}
{"op":"mcm","clk":"11895615670","pt":1724333219462,"mc":[{"id":"1.231812842","rc":[{"batb":[[1,7.2,4],[2,7,1.52]],"ltp":8.0,"tv":40.4,"id":424679}]}]}
{"op":"mcm","clk":"11895615804","pt":1724333221748,"mc":[{"id":"1.231812842","rc":[{"batb":[[1,7,1.52],[2,4.1,1.95]],"ltp":8.0,"tv":40.4,"id":424679}]}]}
{"op":"mcm","clk":"11895616944","pt":1724333238248,"mc":[{"id":"1.231812842","rc":[{"batb":[[0,9,1.52],[1,8,2.05],[2,7,1.52]],"ltp":8.0,"tv":40.4,"id":424679}]}]}
{"op":"mcm","clk":"11895617512","pt":1724333247918,"mc":[{"id":"1.231812842","rc":[{"batb":[[0,1.37,1.3],[1,1.08,31.25],[2,1.07,35.71]],"ltp":1.66,"tv":133.91,"id":424676}]}]}
{"op":"mcm","clk":"11895617708","pt":1724333250943,"mc":[{"id":"1.231812842","rc":[{"batb":[[0,4.1,1.95],[1,3.75,50],[2,3.55,1.53]],"ltp":8.0,"tv":40.4,"id":424679}]}]}
{"op":"mcm","clk":"11895618055","pt":1724333257236,"mc":[{"id":"1.231812842","rc":[{"batl":[[0,9.8,1],[1,10,1],[2,15,1]],"ltp":8.0,"tv":40.4,"id":424679}]}]}
{"op":"mcm","clk":"11895618134","pt":1724333258527,"mc":[{"id":"1.231812842","rc":[{"batb":[[0,8,1.52],[1,4.1,1.95],[2,3.75,50]],"ltp":8.0,"tv":40.4,"id":424679}]}]}
{"op":"mcm","clk":"11895618388","pt":1724333262346,"mc":[{"id":"1.231812842","rc":[{"batb":[[1,1.35,29.43],[2,1.08,31.25]],"ltp":1.66,"tv":133.91,"id":424676}]}]}
{"op":"mcm","clk":"11895618453","pt":1724333263378,"mc":[{"id":"1.231812842","rc":[{"batb":[[1,7.8,1.52],[2,4.1,1.95]],"batl":[[0,10,1],[1,15,1],[2,15.5,4]],"ltp":8.0,"tv":40.4,"id":424679},{"batb":[[1,1.08,31.25],[2,1.07,35.71]],"ltp":1.66,"tv":133.91,"id":424676}]}]}
{"op":"mcm","clk":"11895620778","pt":1724333303600,"mc":[{"id":"1.231812842","rc":[{"batl":[[0,1.95,1.42]],"ltp":1.66,"tv":133.91,"id":424676}]}]}
{"op":"mcm","clk":"11895627200","pt":1724333406516,"mc":[{"id":"1.231812842","rc":[{"batb":[[0,4.1,1.95],[1,3.75,50],[2,3.55,1.53]],"ltp":8.0,"tv":40.4,"id":424679}]}]}
{"op":"mcm","clk":"11895627586","pt":1724333413124,"mc":[{"id":"1.231812842","rc":[{"batl":[[0,9.8,1],[1,10,1],[2,15,1]],"ltp":8.0,"tv":40.4,"id":424679}]}]}
{"op":"mcm","clk":"11895628088","pt":1724333420439,"mc":[{"id":"1.231812842","rc":[{"batl":[[0,4.2,1.52],[1,9.8,1],[2,10,1]],"ltp":8.0,"tv":40.4,"id":424679}]}]}
{"op":"mcm","clk":"11895628156","pt":1724333421518,"mc":[{"id":"1.231812842","rc":[{"batl":[[0,1.95,1.72]],"ltp":1.66,"tv":133.91,"id":424676}]}]}
{"op":"mcm","clk":"11895628263","pt":1724333422927,"mc":[{"id":"1.231812842","rc":[{"trd":[[4.1,6.94]],"batb":[[0,3.75,50.43],[1,3.55,1.53],[2,3.05,1.64]],"ltp":4.1,"tv":43.44,"id":424679}],"tv":221.35}]}
{"op":"mcm","clk":"11895628377","pt":1724333424842,"mc":[{"id":"1.231812842","rc":[{"batl":[[1,10,1],[2,15,1]],"ltp":4.1,"tv":43.44,"id":424679}]}]}
{"op":"mcm","clk":"11895628827","pt":1724333431451,"mc":[{"id":"1.231812842","rc":[{"trd":[[4.1,7.8]],"batb":[[0,3.75,50]],"batl":[[0,4,1.1],[1,4.2,1.52],[2,10,1]],"ltp":4.1,"tv":44.3,"id":424679}],"tv":222.2}]}
{"op":"mcm","clk":"11895629021","pt":1724333434446,"mc":[{"id":"1.231812842","rc":[{"batl":[[0,3.9,1.52],[1,4,1.1],[2,4.2,1.52]],"ltp":4.1,"tv":44.3,"id":424679}]}]}
{"op":"mcm","clk":"11895629079","pt":1724333435437,"mc":[{"id":"1.231812842","rc":[{"batb":[[0,3.75,50.3]],"ltp":4.1,"tv":44.3,"id":424679}]}]}
{"op":"mcm","clk":"11895630809","pt":1724333460654,"mc":[{"id":"1.231812842","rc":[{"batb":[[0,1.08,31.55],[1,1.07,35.71],[2,1.06,41.67]],"ltp":1.66,"tv":133.91,"id":424676}]}]}
{"op":"mcm","clk":"11895633549","pt":1724333503835,"mc":[{"id":"1.231812842","rc":[{"batb":[[0,1.08,31.25]],"ltp":1.66,"tv":133.91,"id":424676}]}]}
{"op":"mcm","clk":"11895641417","pt":1724333628280,"mc":[{"id":"1.231812842","rc":[{"batb":[[0,3.75,50]],"ltp":4.1,"tv":44.3,"id":424679},{"batl":[[0,1.95,1.42]],"ltp":1.66,"tv":133.91,"id":424676}]}]}
{"op":"mcm","clk":"11895641726","pt":1724333633383,"mc":[{"id":"1.231812842","rc":[{"trd":[[3.9,1.01]],"batl":[[0,4,1.61],[1,4.2,1.52],[2,8,1]],"ltp":3.9,"tv":45.31,"id":424679},{"trd":[[1.73,2.28]],"ltp":1.73,"tv":136.19,"id":424676},{"trd":[[6,2.18]],"batl":[[0,8,1.08],[1,10,1],[2,15,1]],"ltp":6.0,"tv":45.17,"id":60443}],"tv":226.68}]}
{"op":"mcm","clk":"11895642040","pt":1724333638458,"mc":[{"id":"1.231812842","rc":[{"batb":[[0,3.1,4.85],[1,3.05,1.64],[2,2.82,1.42]],"ltp":6.0,"tv":45.17,"id":60443}]}]}
{"op":"mcm","clk":"11895642195","pt":1724333641089,"mc":[{"id":"1.231812842","rc":[{"trd":[[3.9,1.14]],"batl":[[0,4,1.49]],"ltp":3.9,"tv":45.44,"id":424679},{"trd":[[1.73,2.56]],"batl":[[0,1.73,1.72],[1,1.95,1.42],[2,1.99,10]],"ltp":1.73,"tv":136.47,"id":424676},{"trd":[[6,2.26]],"batb":[[0,3.05,2.49],[1,2.82,1.42],[2,2.62,1.33]],"batl":[[0,8,1]],"ltp":6.0,"tv":45.25,"id":60443}],"tv":227.16}]}
{"op":"mcm","clk":"11895642269","pt":1724333641865,"mc":[{"id":"1.231812842","rc":[{"batb":[[0,3.55,1.55],[1,3.05,2.49],[2,2.82,1.42]],"ltp":6.0,"tv":45.25,"id":60443}]}]}
{"op":"mcm","clk":"11895642733","pt":1724333648589,"mc":[{"id":"1.231812842","rc":[{"trd":[[3.75,0.16]],"batb":[[0,3.75,49.92]],"ltp":3.75,"tv":45.6,"id":424679},{"trd":[[8,4.16]],"batl":[[0,10,1.92],[1,15,1],[2,21,1]],"ltp":8.0,"tv":45.41,"id":60443}],"tv":227.48}]}
{"op":"mcm","clk":"11895642820","pt":1724333649674,"mc":[{"id":"1.231812842","rc":[{"batb":[[0,3.6,4],[1,3.55,1.55],[2,3.05,2.49]],"ltp":8.0,"tv":45.41,"id":60443}]}]}
{"op":"mcm","clk":"11895642954","pt":1724333652093,"mc":[{"id":"1.231812842","rc":[{"batl":[[0,3.9,1.91],[1,4,1.1],[2,4.2,1.52]],"ltp":3.75,"tv":45.6,"id":424679},{"batb":[[0,3.55,1.55],[1,3.05,2.49],[2,2.82,1.42]],"ltp":8.0,"tv":45.41,"id":60443}]}]}
{"op":"mcm","clk":"11895643024","pt":1724333653093,"mc":[{"id":"1.231812842","rc":[{"batb":[[0,3.55,1.69]],"ltp":8.0,"tv":45.41,"id":60443}]}]}
{"op":"mcm","clk":"11895643352","pt":1724333658100,"mc":[{"id":"1.231812842","rc":[{"batl":[[0,9.8,1.92],[1,10,1],[2,15,1]],"ltp":8.0,"tv":45.41,"id":60443}]}]}
{"op":"mcm","clk":"11895645460","pt":1724333690427,"mc":[{"id":"1.231812842","rc":[{"trd":[[3.9,1.96]],"batl":[[0,3.9,1.09]],"ltp":3.9,"tv":46.42,"id":424679},{"trd":[[1.61,2]],"ltp":1.61,"tv":138.47,"id":424676},{"trd":[[8,4.56]],"batl":[[0,9.8,1.52]],"ltp":8.0,"tv":45.81,"id":60443}],"tv":230.7}]}
{"op":"mcm","clk":"11895656597","pt":1724333864896,"mc":[{"id":"1.231812842","rc":[{"batl":[[0,8,1],[1,10,1],[2,15,1]],"ltp":3.9,"tv":46.42,"id":424679}]}]}
{"op":"mcm","clk":"11895657263","pt":1724333875205,"mc":[{"id":"1.231812842","rc":[{"batl":[[0,7.8,1],[1,8,1],[2,10,1]],"ltp":3.9,"tv":46.42,"id":424679}]}]}
{"op":"mcm","clk":"11895657343","pt":1724333876711,"mc":[{"id":"1.231812842","rc":[{"batb":[[1,1.07,36.71]],"ltp":1.61,"tv":138.47,"id":424676}]}]}
{"op":"mcm","clk":"11895657366","pt":1724333877113,"mc":[{"id":"1.231812842","rc":[{"batb":[[1,1.07,35.71]],"ltp":1.61,"tv":138.47,"id":424676}]}]}
{"op":"mcm","clk":"11895657468","pt":1724333879023,"mc":[{"id":"1.231812842","rc":[{"batb":[[0,7,1.52],[1,3.75,49.92],[2,3.55,1.53]],"ltp":3.9,"tv":46.42,"id":424679}]}]}
{"op":"mcm","clk":"11895657619","pt":1724333881309,"mc":[{"id":"1.231812842","rc":[{"batl":[[0,8,1],[1,10,1],[2,15,1]],"ltp":3.9,"tv":46.42,"id":424679}]}]}
{"op":"mcm","clk":"11895657691","pt":1724333882232,"mc":[{"id":"1.231812842","rc":[{"trd":[[8,5.51]],"batb":[[0,7,2.05]],"batl":[[0,10,1],[1,15,1],[2,15.5,4]],"ltp":8.0,"tv":48.42,"id":424679},{"batb":[[0,1.08,31.55]],"ltp":1.61,"tv":138.47,"id":424676},{"batb":[[0,3.55,1.99]],"ltp":8.0,"tv":45.81,"id":60443}],"tv":232.7}]}
