{"op":"mcm","clk":"11795140970","pt":1723108868511,"mc":[{"id":"1.231581430","marketDefinition":{"bspMarket":false,"turnInPlayEnabled":true,"persistenceEnabled":true,"marketBaseRate":5.0,"eventId":"33477741","eventTypeId":"4","numberOfWinners":1,"bettingType":"ODDS","marketType":"MATCH_ODDS","marketTime":"2024-08-11T10:00:00.000Z","suspendTime":"2024-08-11T10:00:00.000Z","bspReconciled":false,"complete":true,"inPlay":false,"crossMatching":false,"runnersVoidable":false,"numberOfActiveRunners":2,"betDelay":0,"status":"OPEN","runners":[{"status":"ACTIVE","sortPriority":1,"id":31377,"name":"Leicestershire"},{"status":"ACTIVE","sortPriority":2,"id":169,"name":"Glamorgan"}],"regulators":["MR_INT"],"countryCode":"GB","discountAllowed":false,"timezone":"GMT","openDate":"2024-08-11T10:00:00.000Z","version":6061697168,"name":"Match Odds","eventName":"Leicestershire v Glamorgan"},"rc":[{"batb":[[0,1.01,20]],"ltp":0.0,"tv":0.0,"id":169},{"batb":[[0,1.01,20]],"ltp":0.0,"tv":0.0,"id":31377}]}]}
{"op":"mcm","clk":"11795141011","pt":1723108869126,"mc":[{"id":"1.231581430","marketDefinition":{"bspMarket":false,"turnInPlayEnabled":true,"persistenceEnabled":true,"marketBaseRate":5.0,"eventId":"33477741","eventTypeId":"4","numberOfWinners":1,"bettingType":"ODDS","marketType":"MATCH_ODDS","marketTime":"2024-08-11T10:00:00.000Z","suspendTime":"2024-08-11T10:00:00.000Z","bspReconciled":false,"complete":true,"inPlay":false,"crossMatching":false,"runnersVoidable":false,"numberOfActiveRunners":2,"betDelay":0,"status":"OPEN","runners":[{"status":"ACTIVE","sortPriority":1,"id":31377,"name":"Leicestershire"},{"status":"ACTIVE","sortPriority":2,"id":169,"name":"Glamorgan"}],"regulators":["MR_INT"],"countryCode":"GB","discountAllowed":true,"timezone":"GMT","openDate":"2024-08-11T10:00:00.000Z","version":6061697168,"name":"Match Odds","eventName":"Leicestershire v Glamorgan"},"rc":[{"batb":[[0,1.03,200],[1,1.02,200],[2,1.01,220]],"ltp":0.0,"tv":0.0,"id":169},{"batb":[[0,1.03,200],[1,1.02,200],[2,1.01,220]],"ltp":0.0,"tv":0.0,"id":31377}]}]}
{"op":"mcm","clk":"11795243470","pt":1723110975182,"mc":[{"id":"1.231581430","rc":[{"batb":[[2,1.01,227.87]],"ltp":0.0,"tv":0.0,"id":169},{"batb":[[2,1.01,227.87]],"ltp":0.0,"tv":0.0,"id":31377}]}]}
{"op":"mcm","clk":"11795244227","pt":1723110988697,"mc":[{"id":"1.231581430","rc":[{"batb":[[1,1.02,207.87]],"ltp":0.0,"tv":0.0,"id":169},{"batb":[[1,1.02,207.87]],"ltp":0.0,"tv":0.0,"id":31377}]}]}
{"op":"mcm","clk":"11795245070","pt":1723111003301,"mc":[{"id":"1.231581430","rc":[{"batb":[[1,1.02,247.25]],"ltp":0.0,"tv":0.0,"id":169},{"batb":[[1,1.02,247.25]],"ltp":0.0,"tv":0.0,"id":31377}]}]}
{"op":"mcm","clk":"11795245891","pt":1723111017135,"mc":[{"id":"1.231581430","rc":[{"batb":[[0,1.03,207.87]],"ltp":0.0,"tv":0.0,"id":169},{"batb":[[0,1.03,207.87]],"ltp":0.0,"tv":0.0,"id":31377}]}]}
{"op":"mcm","clk":"11795246638","pt":1723111030641,"mc":[{"id":"1.231581430","rc":[{"batb":[[0,1.04,7.87],[1,1.03,207.87],[2,1.02,247.25]],"ltp":0.0,"tv":0.0,"id":169},{"batb":[[0,1.04,7.87],[1,1.03,207.87],[2,1.02,247.25]],"ltp":0.0,"tv":0.0,"id":31377}]}]}
{"op":"mcm","clk":"11795247412","pt":1723111044740,"mc":[{"id":"1.231581430","rc":[{"batb":[[0,1.05,7.87],[1,1.04,7.87],[2,1.03,207.87]],"ltp":0.0,"tv":0.0,"id":169},{"batb":[[0,1.05,7.87],[1,1.04,7.87],[2,1.03,207.87]],"ltp":0.0,"tv":0.0,"id":31377}]}]}
{"op":"mcm","clk":"11795248272","pt":1723111060871,"mc":[{"id":"1.231581430","rc":[{"batb":[[0,1.06,7.87],[1,1.05,7.87],[2,1.04,7.87]],"ltp":0.0,"tv":0.0,"id":169},{"batb":[[0,1.06,7.87],[1,1.05,7.87],[2,1.04,7.87]],"ltp":0.0,"tv":0.0,"id":31377}]}]}
{"op":"mcm","clk":"11795249255","pt":1723111078952,"mc":[{"id":"1.231581430","rc":[{"batb":[[0,1.07,7.87],[1,1.06,7.87],[2,1.05,7.87]],"ltp":0.0,"tv":0.0,"id":169},{"batb":[[0,1.07,7.87],[1,1.06,7.87],[2,1.05,7.87]],"ltp":0.0,"tv":0.0,"id":31377}]}]}
{"op":"mcm","clk":"11795250214","pt":1723111093789,"mc":[{"id":"1.231581430","rc":[{"batb":[[0,1.08,7.87],[1,1.07,7.87],[2,1.06,7.87]],"ltp":0.0,"tv":0.0,"id":169},{"batb":[[0,1.08,7.87],[1,1.07,7.87],[2,1.06,7.87]],"ltp":0.0,"tv":0.0,"id":31377}]}]}
{"op":"mcm","clk":"11795305633","pt":1723111974768,"mc":[{"id":"1.231581430","rc":[{"batb":[[0,1.08,7.89],[1,1.07,7.89],[2,1.06,7.89]],"ltp":0.0,"tv":0.0,"id":169},{"batb":[[0,1.08,7.89],[1,1.07,7.89],[2,1.06,7.89]],"ltp":0.0,"tv":0.0,"id":31377}]}]}
{"op":"mcm","clk":"11795533976","pt":1723115773445,"mc":[{"id":"1.231581430","rc":[{"batb":[[0,1.08,7.88],[1,1.07,7.88],[2,1.06,7.88]],"ltp":0.0,"tv":0.0,"id":169},{"batb":[[0,1.08,7.88],[1,1.07,7.88],[2,1.06,7.88]],"ltp":0.0,"tv":0.0,"id":31377}]}]}
{"op":"mcm","clk":"11795535250","pt":1723115799113,"mc":[{"id":"1.231581430","marketDefinition":{"bspMarket":false,"turnInPlayEnabled":true,"persistenceEnabled":true,"marketBaseRate":5.0,"eventId":"33477741","eventTypeId":"4","numberOfWinners":1,"bettingType":"ODDS","marketType":"MATCH_ODDS","marketTime":"2024-08-11T10:00:00.000Z","suspendTime":"2024-08-11T10:00:00.000Z","bspReconciled":false,"complete":true,"inPlay":false,"crossMatching":true,"runnersVoidable":false,"numberOfActiveRunners":2,"betDelay":0,"status":"OPEN","runners":[{"status":"ACTIVE","sortPriority":1,"id":31377,"name":"Leicestershire"},{"status":"ACTIVE","sortPriority":2,"id":169,"name":"Glamorgan"}],"regulators":["MR_INT"],"countryCode":"GB","discountAllowed":true,"timezone":"GMT","openDate":"2024-08-11T10:00:00.000Z","version":6061697168,"name":"Match Odds","eventName":"Leicestershire v Glamorgan"}}]}
{"op":"mcm","clk":"11795869918","pt":1723122774767,"mc":[{"id":"1.231581430","rc":[{"batb":[[0,1.08,7.89],[1,1.07,7.89],[2,1.06,7.89]],"ltp":0.0,"tv":0.0,"id":169},{"batb":[[0,1.08,7.89],[1,1.07,7.89],[2,1.06,7.89]],"ltp":0.0,"tv":0.0,"id":31377}]}]}
{"op":"mcm","clk":"11796153349","pt":1723128174767,"mc":[{"id":"1.231581430","rc":[{"batb":[[0,1.08,7.87],[1,1.07,7.87],[2,1.06,7.87]],"ltp":0.0,"tv":0.0,"id":169},{"batb":[[0,1.08,7.87],[1,1.07,7.87],[2,1.06,7.87]],"ltp":0.0,"tv":0.0,"id":31377}]}]}
{"op":"mcm","clk":"11796260701","pt":1723129859378,"mc":[{"id":"1.231581430","rc":[{"batb":[[0,1.25,100],[1,1.08,7.86],[2,1.07,7.86]],"ltp":0.0,"tv":0.0,"id":169},{"batb":[[0,1.25,100],[1,1.08,7.86],[2,1.07,7.86]],"ltp":0.0,"tv":0.0,"id":31377}]}]}
{"op":"mcm","clk":"11796552736","pt":1723133574801,"mc":[{"id":"1.231581430","rc":[{"batb":[[1,1.08,7.85],[2,1.07,7.85]],"ltp":0.0,"tv":0.0,"id":169},{"batb":[[1,1.08,7.85],[2,1.07,7.85]],"ltp":0.0,"tv":0.0,"id":31377}]}]}
{"op":"mcm","clk":"11797047005","pt":1723138470301,"mc":[{"id":"1.231581430","rc":[{"batb":[[0,1.26,2.75],[1,1.25,100],[2,1.08,7.85]],"ltp":0.0,"tv":0.0,"id":31377}]}]}
{"op":"mcm","clk":"11797048566","pt":1723138486425,"mc":[{"id":"1.231581430","rc":[{"batb":[[0,1.25,100.96]],"ltp":0.0,"tv":0.0,"id":169}]}]}
{"op":"mcm","clk":"11797049663","pt":1723138498926,"mc":[{"id":"1.231581430","rc":[{"batb":[[0,1.25,100.96],[1,1.08,7.85],[2,1.07,7.85]],"ltp":0.0,"tv":0.0,"id":31377}]}]}
{"op":"mcm","clk":"11797051531","pt":1723138516452,"mc":[{"id":"1.231581430","rc":[{"batb":[[0,1.25,100]],"ltp":0.0,"tv":0.0,"id":31377}]}]}
{"op":"mcm","clk":"11797051540","pt":1723138516558,"mc":[{"id":"1.231581430","rc":[{"batb":[[0,1.27,1.21],[1,1.25,100],[2,1.08,7.85]],"ltp":0.0,"tv":0.0,"id":31377}]}]}
{"op":"mcm","clk":"11797052213","pt":1723138523795,"mc":[{"id":"1.231581430","rc":[{"batb":[[0,1.28,1.25],[1,1.25,100],[2,1.08,7.85]],"ltp":0.0,"tv":0.0,"id":169}]}]}
{"op":"mcm","clk":"11797053863","pt":1723138540717,"mc":[{"id":"1.231581430","rc":[{"batb":[[0,1.27,2.17]],"ltp":0.0,"tv":0.0,"id":31377}]}]}
{"op":"mcm","clk":"11797055165","pt":1723138554372,"mc":[{"id":"1.231581430","rc":[{"batb":[[0,1.28,2.21]],"ltp":0.0,"tv":0.0,"id":169}]}]}
{"op":"mcm","clk":"11797859908","pt":1723144374770,"mc":[{"id":"1.231581430","rc":[{"batb":[[0,1.28,2.21],[2,1.08,7.84]],"ltp":0.0,"tv":0.0,"id":169},{"batb":[[0,1.27,2.17],[2,1.08,7.84]],"ltp":0.0,"tv":0.0,"id":31377}]}]}
{"op":"mcm","clk":"11798413878","pt":1723149774770,"mc":[{"id":"1.231581430","rc":[{"batb":[[2,1.08,7.85]],"ltp":0.0,"tv":0.0,"id":169},{"batb":[[2,1.08,7.85]],"ltp":0.0,"tv":0.0,"id":31377}]}]}
{"op":"mcm","clk":"11798504979","pt":1723151570482,"mc":[{"id":"1.231581430","rc":[{"batb":[[2,1.08,7.84]],"ltp":0.0,"tv":0.0,"id":169},{"batb":[[2,1.08,7.84]],"ltp":0.0,"tv":0.0,"id":31377}]}]}
{"op":"mcm","clk":"11798862813","pt":1723160574768,"mc":[{"id":"1.231581430","rc":[{"batb":[[0,1.28,2.21],[2,1.08,7.85]],"ltp":0.0,"tv":0.0,"id":169},{"batb":[[0,1.27,2.17],[2,1.08,7.85]],"ltp":0.0,"tv":0.0,"id":31377}]}]}
{"op":"mcm","clk":"11799063291","pt":1723165974769,"mc":[{"id":"1.231581430","rc":[{"batb":[[2,1.08,7.85]],"ltp":0.0,"tv":0.0,"id":169},{"batb":[[2,1.08,7.85]],"ltp":0.0,"tv":0.0,"id":31377}]}]}
{"op":"mcm","clk":"11799278587","pt":1723171374769,"mc":[{"id":"1.231581430","rc":[{"batb":[[0,1.28,2.21],[2,1.08,7.84]],"ltp":0.0,"tv":0.0,"id":169},{"batb":[[0,1.27,2.17],[2,1.08,7.84]],"ltp":0.0,"tv":0.0,"id":31377}]}]}
{"op":"mcm","clk":"11799464460","pt":1723176774767,"mc":[{"id":"1.231581430","rc":[{"batb":[[0,1.28,2.2],[2,1.08,7.84]],"ltp":0.0,"tv":0.0,"id":169},{"batb":[[0,1.27,2.17],[2,1.08,7.84]],"ltp":0.0,"tv":0.0,"id":31377}]}]}
{"op":"mcm","clk":"11799639334","pt":1723182174769,"mc":[{"id":"1.231581430","rc":[{"batb":[[0,1.28,2.21],[2,1.08,7.84]],"ltp":0.0,"tv":0.0,"id":169},{"batb":[[0,1.27,2.17],[2,1.08,7.84]],"ltp":0.0,"tv":0.0,"id":31377}]}]}
{"op":"mcm","clk":"11799789076","pt":1723187574767,"mc":[{"id":"1.231581430","rc":[{"batb":[[0,1.28,2.2],[2,1.08,7.83]],"ltp":0.0,"tv":0.0,"id":169},{"batb":[[0,1.27,2.17],[2,1.08,7.83]],"ltp":0.0,"tv":0.0,"id":31377}]}]}
{"op":"mcm","clk":"11799851697","pt":1723189566905,"mc":[{"id":"1.231581430","rc":[{"batl":[[0,1000,0.02]],"ltp":0.0,"tv":0.0,"id":169},{"batl":[[0,1000,0.02]],"ltp":0.0,"tv":0.0,"id":31377}]}]}
{"op":"mcm","clk":"11799963605","pt":1723192974769,"mc":[{"id":"1.231581430","rc":[{"batb":[[0,1.28,2.2],[2,1.08,7.84]],"ltp":0.0,"tv":0.0,"id":169},{"batb":[[0,1.27,2.17],[2,1.08,7.84]],"ltp":0.0,"tv":0.0,"id":31377}]}]}
{"op":"mcm","clk":"11800334053","pt":1723198374769,"mc":[{"id":"1.231581430","rc":[{"batb":[[2,1.08,7.84]],"ltp":0.0,"tv":0.0,"id":169},{"batb":[[2,1.08,7.84]],"ltp":0.0,"tv":0.0,"id":31377}]}]}
{"op":"mcm","clk":"11800789639","pt":1723203774779,"mc":[{"id":"1.231581430","rc":[{"batb":[[0,1.28,2.21],[2,1.08,7.85]],"ltp":0.0,"tv":0.0,"id":169},{"batb":[[0,1.27,2.17],[2,1.08,7.85]],"ltp":0.0,"tv":0.0,"id":31377}]}]}
{"op":"mcm","clk":"11801209728","pt":1723209174773,"mc":[{"id":"1.231581430","rc":[{"batb":[[0,1.28,2.21],[2,1.08,7.85]],"ltp":0.0,"tv":0.0,"id":169},{"batb":[[0,1.27,2.17],[2,1.08,7.85]],"ltp":0.0,"tv":0.0,"id":31377}]}]}
{"op":"mcm","clk":"11801480081","pt":1723213284365,"mc":[{"id":"1.231581430","rc":[{"batb":[[2,1.08,7.85]],"ltp":0.0,"tv":0.0,"id":169},{"batb":[[2,1.08,7.85]],"batl":[[0,3,5],[1,1000,0.02]],"ltp":0.0,"tv":0.0,"id":31377}]}]}
{"op":"mcm","clk":"11801990225","pt":1723219974771,"mc":[{"id":"1.231581430","rc":[{"batb":[[0,1.28,2.2],[2,1.08,7.84]],"ltp":0.0,"tv":0.0,"id":169},{"batb":[[0,1.27,2.17],[2,1.08,7.84]],"ltp":0.0,"tv":0.0,"id":31377}]}]}
{"op":"mcm","clk":"11802207153","pt":1723221507682,"mc":[{"id":"1.231581430","rc":[{"batb":[[1,1.08,7.84],[2,1.07,7.84]],"ltp":0.0,"tv":0.0,"id":169},{"batb":[[1,1.08,7.84],[2,1.07,7.84]],"ltp":0.0,"tv":0.0,"id":31377}]}]}
{"op":"mcm","clk":"11802214920","pt":1723221557432,"mc":[{"id":"1.231581430","rc":[{"batb":[[1,1.08,320.34]],"ltp":0.0,"tv":0.0,"id":169},{"batb":[[1,1.13,192.31],[2,1.08,320.34]],"ltp":0.0,"tv":0.0,"id":31377}]}]}
{"op":"mcm","clk":"11802215034","pt":1723221558024,"mc":[{"id":"1.231581430","rc":[{"batb":[[0,1.48,52.08],[1,1.43,58.14],[2,1.38,65.79]],"ltp":0.0,"tv":0.0,"id":169},{"batb":[[0,1.48,52.08],[1,1.43,58.14],[2,1.38,65.79]],"ltp":0.0,"tv":0.0,"id":31377}]}]}
{"op":"mcm","clk":"11802338770","pt":1723222457917,"mc":[{"id":"1.231581430","rc":[{"batb":[[0,1.49,6.72],[1,1.48,52.08],[2,1.43,58.14]],"ltp":0.0,"tv":0.0,"id":169},{"batb":[[0,1.49,7.69],[1,1.48,52.08],[2,1.43,58.14]],"ltp":0.0,"tv":0.0,"id":31377}]}]}
{"op":"mcm","clk":"11802634295","pt":1723224317594,"mc":[{"id":"1.231581430","rc":[{"trd":[[1.5,0.07]],"batb":[[0,1.49,6.73]],"ltp":1.5,"tv":0.07,"id":169},{"trd":[[3,0.04]],"batb":[[0,1.49,7.7]],"batl":[[0,3,4.96]],"ltp":3.0,"tv":0.04,"id":31377}],"tv":0.11}]}
{"op":"mcm","clk":"11802725047","pt":1723224821287,"mc":[{"id":"1.231581430","rc":[{"batb":[[0,1.94,44.45],[1,1.49,6.73],[2,1.48,52.08]],"ltp":1.5,"tv":0.07,"id":169},{"batb":[[0,1.99,42.21],[1,1.49,7.7],[2,1.48,52.08]],"ltp":3.0,"tv":0.04,"id":31377}]}]}
{"op":"mcm","clk":"11802963525","pt":1723226039453,"mc":[{"id":"1.231581430","rc":[{"batb":[[1,1.48,52.08],[2,1.43,58.14]],"ltp":3.0,"tv":0.04,"id":31377}]}]}
{"op":"mcm","clk":"11802963587","pt":1723226039827,"mc":[{"id":"1.231581430","rc":[{"batb":[[1,1.48,52.08],[2,1.43,58.14]],"ltp":1.5,"tv":0.07,"id":169}]}]}
{"op":"mcm","clk":"11806057226","pt":1723278182092,"mc":[{"id":"1.231581430","rc":[{"trd":[[1.99,2]],"batb":[[0,1.99,41.21]],"ltp":1.99,"tv":2.04,"id":31377}],"tv":2.11}]}
{"op":"mcm","clk":"11806057447","pt":1723278184884,"mc":[{"id":"1.231581430","rc":[{"batb":[[0,1.99,42.21]],"ltp":1.99,"tv":2.04,"id":31377}]}]}
{"op":"mcm","clk":"11806104808","pt":1723278734387,"mc":[{"id":"1.231581430","rc":[{"batb":[[1,1.08,7.85],[2,1.07,7.85]],"ltp":1.5,"tv":0.07,"id":169},{"batb":[[1,1.08,7.85],[2,1.07,7.85]],"ltp":1.99,"tv":2.04,"id":31377}]}]}
{"op":"mcm","clk":"11806128074","pt":1723278979422,"mc":[{"id":"1.231581430","rc":[{"batb":[[1,1.25,1200],[2,1.08,7.85]],"ltp":1.99,"tv":2.04,"id":31377}]}]}
{"op":"mcm","clk":"11806128088","pt":1723278979526,"mc":[{"id":"1.231581430","rc":[{"batb":[[1,1.25,1200],[2,1.08,7.85]],"ltp":1.5,"tv":0.07,"id":169}]}]}
{"op":"mcm","clk":"11806135308","pt":1723279056149,"mc":[{"id":"1.231581430","rc":[{"batb":[[1,1.08,7.85],[2,1.07,7.85]],"ltp":1.5,"tv":0.07,"id":169},{"batb":[[1,1.08,7.85],[2,1.07,7.85]],"ltp":1.99,"tv":2.04,"id":31377}]}]}
{"op":"mcm","clk":"11806135529","pt":1723279058761,"mc":[{"id":"1.231581430","rc":[{"batb":[[1,1.3,1000],[2,1.08,7.85]],"ltp":1.5,"tv":0.07,"id":169},{"batb":[[1,1.3,1000],[2,1.08,7.85]],"ltp":1.99,"tv":2.04,"id":31377}]}]}
{"op":"mcm","clk":"11806612684","pt":1723283358228,"mc":[{"id":"1.231581430","rc":[{"batb":[[1,1.74,1],[2,1.3,1000]],"ltp":1.5,"tv":0.07,"id":169},{"batb":[[1,1.74,1],[2,1.3,1000]],"ltp":1.99,"tv":2.04,"id":31377}]}]}
{"op":"mcm","clk":"11809557753","pt":1723299707876,"mc":[{"id":"1.231581430","rc":[{"batb":[[0,1.94,41.53]],"ltp":1.5,"tv":0.07,"id":169},{"batb":[[0,1.99,39.43]],"ltp":1.99,"tv":2.04,"id":31377}]}]}
{"op":"mcm","clk":"11811022971","pt":1723305360904,"mc":[{"id":"1.231581430","rc":[{"batb":[[0,1.99,60.43]],"ltp":1.99,"tv":2.04,"id":31377}]}]}
{"op":"mcm","clk":"11811026272","pt":1723305379025,"mc":[{"id":"1.231581430","rc":[{"batl":[[0,2.14,20.79],[1,3,4.96],[2,1000,0.02]],"ltp":1.99,"tv":2.04,"id":31377}]}]}
{"op":"mcm","clk":"11812561658","pt":1723313352105,"mc":[{"id":"1.231581430","rc":[{"batl":[[1,2.4,5],[2,3,4.96]],"ltp":1.99,"tv":2.04,"id":31377}]}]}
{"op":"mcm","clk":"11813698143","pt":1723319799373,"mc":[{"id":"1.231581430","rc":[{"batb":[[1,1.91,4.56],[2,1.74,1]],"ltp":1.99,"tv":2.04,"id":31377}]}]}
{"op":"mcm","clk":"11813699592","pt":1723319809391,"mc":[{"id":"1.231581430","rc":[{"batb":[[1,1.81,4.56],[2,1.74,1]],"ltp":1.5,"tv":0.07,"id":169}]}]}
{"op":"mcm","clk":"11813701132","pt":1723319820713,"mc":[{"id":"1.231581430","rc":[{"batb":[[2,1.81,4.56]],"ltp":1.99,"tv":2.04,"id":31377}]}]}
{"op":"mcm","clk":"11813704626","pt":1723319844398,"mc":[{"id":"1.231581430","rc":[{"batl":[[1,2.3,4.56],[2,2.4,5]],"ltp":1.99,"tv":2.04,"id":31377}]}]}
{"op":"mcm","clk":"11813706782","pt":1723319858705,"mc":[{"id":"1.231581430","rc":[{"batl":[[0,2.3,4.56],[1,1000,0.02]],"ltp":1.5,"tv":0.07,"id":169}]}]}
{"op":"mcm","clk":"11814142205","pt":1723324845609,"mc":[{"id":"1.231581430","rc":[{"trd":[[1.99,4.22]],"batb":[[0,1.99,59.32]],"ltp":1.99,"tv":4.26,"id":31377}],"tv":4.33}]}
{"op":"mcm","clk":"11814142372","pt":1723324848816,"mc":[{"id":"1.231581430","rc":[{"batb":[[0,1.99,60.43]],"ltp":1.99,"tv":4.26,"id":31377}]}]}
{"op":"mcm","clk":"11814423115","pt":1723330343954,"mc":[{"id":"1.231581430","rc":[{"trd":[[1.94,3]],"batb":[[0,1.94,40.03]],"ltp":1.94,"tv":3.07,"id":169}],"tv":7.33}]}
{"op":"mcm","clk":"11814423248","pt":1723330346832,"mc":[{"id":"1.231581430","rc":[{"batb":[[0,1.94,41.53]],"ltp":1.94,"tv":3.07,"id":169}]}]}
{"op":"mcm","clk":"11814432855","pt":1723330550613,"mc":[{"id":"1.231581430","rc":[{"batb":[[2,1.78,9]],"ltp":1.94,"tv":3.07,"id":169}]}]}
{"op":"mcm","clk":"11814486364","pt":1723331510186,"mc":[{"id":"1.231581430","rc":[{"batb":[[2,1.74,1]],"ltp":1.94,"tv":3.07,"id":169}]}]}
{"op":"mcm","clk":"11815741954","pt":1723350028418,"mc":[{"id":"1.231581430","rc":[{"batl":[[0,2.06,1.82],[1,2.14,20.79],[2,2.3,4.56]],"ltp":1.99,"tv":4.26,"id":31377}]}]}
{"op":"mcm","clk":"11815742729","pt":1723350043428,"mc":[{"id":"1.231581430","rc":[{"batl":[[0,2.14,20.79],[1,2.3,4.56],[2,2.4,5]],"ltp":1.99,"tv":4.26,"id":31377}]}]}
{"op":"mcm","clk":"11816046634","pt":1723359838111,"mc":[{"id":"1.231581430","rc":[{"batl":[[2,2.4,9.64]],"ltp":1.99,"tv":4.26,"id":31377}]}]}
{"op":"mcm","clk":"11816106344","pt":1723361081638,"mc":[{"id":"1.231581430","rc":[{"batl":[[0,2,5],[1,2.3,4.56],[2,1000,0.02]],"ltp":1.94,"tv":3.07,"id":169}]}]}
{"op":"mcm","clk":"11816110470","pt":1723361171243,"mc":[{"id":"1.231581430","rc":[{"trd":[[2,5]],"batl":[[0,2.3,4.56],[1,1000,0.02],[2,1000,0]],"ltp":2.0,"tv":8.07,"id":169},{"trd":[[2,5]],"ltp":2.0,"tv":9.25,"id":31377}],"tv":17.33}]}
{"op":"mcm","clk":"11816154170","pt":1723362263403,"mc":[{"id":"1.231581430","rc":[{"batl":[[1,2.4,9.64],[2,3,4.96]],"ltp":2.0,"tv":9.25,"id":31377}]}]}
{"op":"mcm","clk":"11816154206","pt":1723362264426,"mc":[{"id":"1.231581430","rc":[{"batl":[[0,1000,0.02],[1,1000,0]],"ltp":2.0,"tv":8.07,"id":169}]}]}
{"op":"mcm","clk":"11816154625","pt":1723362275318,"mc":[{"id":"1.231581430","rc":[{"batb":[[1,1.81,4.56],[2,1.74,1]],"ltp":2.0,"tv":9.25,"id":31377}]}]}
{"op":"mcm","clk":"11816154714","pt":1723362277472,"mc":[{"id":"1.231581430","rc":[{"batb":[[1,1.74,1],[2,1.71,4.56]],"ltp":2.0,"tv":8.07,"id":169}]}]}
{"op":"mcm","clk":"11816154789","pt":1723362279368,"mc":[{"id":"1.231581430","rc":[{"batb":[[1,1.74,1],[2,1.56,7.21]],"ltp":2.0,"tv":9.25,"id":31377}]}]}
{"op":"mcm","clk":"11816155187","pt":1723362288823,"mc":[{"id":"1.231581430","rc":[{"batb":[[2,1.3,1000]],"ltp":2.0,"tv":8.07,"id":169}]}]}
{"op":"mcm","clk":"11816194111","pt":1723363201876,"mc":[{"id":"1.231581430","rc":[{"batb":[[1,1.93,19.37],[2,1.74,1]],"ltp":2.0,"tv":8.07,"id":169},{"batb":[[1,1.98,18.38],[2,1.74,1]],"ltp":2.0,"tv":9.25,"id":31377}]}]}
{"op":"mcm","clk":"11816227177","pt":1723363820954,"mc":[{"id":"1.231581430","rc":[{"trd":[[2.02,2]],"ltp":2.02,"tv":10.07,"id":169},{"trd":[[1.99,6.25]],"batb":[[0,1.99,58.4]],"ltp":1.99,"tv":11.29,"id":31377}],"tv":21.36}]}
{"op":"mcm","clk":"11816312720","pt":1723365370127,"mc":[{"id":"1.231581430","rc":[{"batl":[[0,2,786],[1,1000,0.02]],"ltp":2.02,"tv":10.07,"id":169},{"batb":[[0,1.99,76.59]],"ltp":1.99,"tv":11.29,"id":31377}]}]}
{"op":"mcm","clk":"11816424328","pt":1723366802111,"mc":[{"id":"1.231581430","rc":[{"batb":[[0,1.94,5]],"ltp":2.02,"tv":10.07,"id":169},{"batb":[[0,1.99,37.16]],"ltp":1.99,"tv":11.29,"id":31377}]}]}
{"op":"mcm","clk":"11816424425","pt":1723366803011,"mc":[{"id":"1.231581430","rc":[{"batb":[[1,1.87,20.7]],"ltp":2.02,"tv":10.07,"id":169}]}]}
{"op":"mcm","clk":"11816438961","pt":1723366999166,"mc":[{"id":"1.231581430","rc":[{"batl":[[1,2.4,5]],"ltp":1.99,"tv":11.29,"id":31377}]}]}
{"op":"mcm","clk":"11816439108","pt":1723367001031,"mc":[{"id":"1.231581430","rc":[{"batl":[[2,2.58,4.64]],"ltp":1.99,"tv":11.29,"id":31377}]}]}
{"op":"mcm","clk":"11816439656","pt":1723367008360,"mc":[{"id":"1.231581430","rc":[{"batl":[[1,2.4,9.64],[2,3,4.96]],"ltp":1.99,"tv":11.29,"id":31377}]}]}
{"op":"mcm","clk":"11816466186","pt":1723367359457,"mc":[{"id":"1.231581430","rc":[{"batb":[[0,2,18.97],[1,1.99,18.19],[2,1.98,18.38]],"ltp":1.99,"tv":11.29,"id":31377}]}]}
{"op":"mcm","clk":"11816466971","pt":1723367370362,"mc":[{"id":"1.231581430","rc":[{"batl":[[0,2.4,9.64],[1,3,4.96],[2,1000,0.02]],"ltp":1.99,"tv":11.29,"id":31377}]}]}
{"op":"mcm","clk":"11816467005","pt":1723367370824,"mc":[{"id":"1.231581430","rc":[{"batb":[[1,1.74,1],[2,1.3,1000]],"ltp":2.02,"tv":10.07,"id":169},{"batb":[[1,1.74,1],[2,1.56,7.21]],"ltp":1.99,"tv":11.29,"id":31377}]}]}
{"op":"mcm","clk":"11816467316","pt":1723367375330,"mc":[{"id":"1.231581430","rc":[{"batb":[[1,1.99,5],[2,1.74,1]],"ltp":1.99,"tv":11.29,"id":31377}]}]}
{"op":"mcm","clk":"11816467340","pt":1723367375642,"mc":[{"id":"1.231581430","rc":[{"batl":[[0,2.12,21],[1,2.4,9.64],[2,3,4.96]],"ltp":1.99,"tv":11.29,"id":31377}]}]}
{"op":"mcm","clk":"11816467464","pt":1723367377350,"mc":[{"id":"1.231581430","rc":[{"batb":[[1,1.89,20.24],[2,1.74,1]],"ltp":2.02,"tv":10.07,"id":169},{"batb":[[1,1.99,23.19]],"ltp":1.99,"tv":11.29,"id":31377}]}]}
{"op":"mcm","clk":"11816467696","pt":1723367380465,"mc":[{"id":"1.231581430","rc":[{"batb":[[1,1.99,18.19]],"ltp":1.99,"tv":11.29,"id":31377}]}]}
{"op":"mcm","clk":"11816480440","pt":1723367573969,"mc":[{"id":"1.231581430","rc":[{"batb":[[0,1.96,52.08],[1,1.94,5],[2,1.89,20.24]],"ltp":2.02,"tv":10.07,"id":169}]}]}
{"op":"mcm","clk":"11816480660","pt":1723367576999,"mc":[{"id":"1.231581430","rc":[{"batb":[[1,1.95,18.96]],"ltp":2.02,"tv":10.07,"id":169}]}]}
{"op":"mcm","clk":"11816528616","pt":1723368278463,"mc":[{"id":"1.231581430","rc":[{"trd":[[2,448.18]],"batl":[[0,2,564.41]],"ltp":2.0,"tv":453.25,"id":169}],"tv":464.54}]}
{"op":"mcm","clk":"11816528853","pt":1723368281484,"mc":[{"id":"1.231581430","rc":[{"batb":[[0,2.02,10],[1,2,36.98],[2,1.99,18.19]],"ltp":1.99,"tv":11.29,"id":31377}]}]}
{"op":"mcm","clk":"11816529190","pt":1723368285917,"mc":[{"id":"1.231581430","rc":[{"batb":[[0,2,36.98],[1,1.99,18.19],[2,1.74,1]],"ltp":1.99,"tv":11.29,"id":31377}]}]}
{"op":"mcm","clk":"11816529441","pt":1723368289304,"mc":[{"id":"1.231581430","rc":[{"batb":[[0,2.04,10],[1,2,36.98],[2,1.99,18.19]],"ltp":1.99,"tv":11.29,"id":31377}]}]}
{"op":"mcm","clk":"11816530083","pt":1723368297507,"mc":[{"id":"1.231581430","rc":[{"batb":[[0,2,36.98],[1,1.99,18.19],[2,1.74,1]],"ltp":1.99,"tv":11.29,"id":31377}]}]}
{"op":"mcm","clk":"11816530430","pt":1723368301835,"mc":[{"id":"1.231581430","rc":[{"batb":[[0,2.02,10],[1,2,36.98],[2,1.99,18.19]],"ltp":1.99,"tv":11.29,"id":31377}]}]}
{"op":"mcm","clk":"11816531244","pt":1723368309724,"mc":[{"id":"1.231581430","rc":[{"batb":[[0,2,36.98],[1,1.99,18.19],[2,1.74,1]],"ltp":1.99,"tv":11.29,"id":31377}]}]}
{"op":"mcm","clk":"11816531601","pt":1723368313843,"mc":[{"id":"1.231581430","rc":[{"batb":[[0,2.02,10],[1,2,36.98],[2,1.99,18.19]],"ltp":1.99,"tv":11.29,"id":31377}]}]}
{"op":"mcm","clk":"11816532284","pt":1723368321955,"mc":[{"id":"1.231581430","rc":[{"batb":[[0,2,36.98],[1,1.99,18.19],[2,1.74,1]],"ltp":1.99,"tv":11.29,"id":31377}]}]}
{"op":"mcm","clk":"11816532945","pt":1723368330157,"mc":[{"id":"1.231581430","rc":[{"batb":[[0,2.02,10],[1,2,36.98],[2,1.99,18.19]],"ltp":1.99,"tv":11.29,"id":31377}]}]}
{"op":"mcm","clk":"11816533846","pt":1723368341359,"mc":[{"id":"1.231581430","rc":[{"batb":[[0,2,36.98],[1,1.99,18.19],[2,1.74,1]],"ltp":1.99,"tv":11.29,"id":31377}]}]}
{"op":"mcm","clk":"11816534344","pt":1723368347466,"mc":[{"id":"1.231581430","rc":[{"batb":[[0,2.02,10],[1,2,36.98],[2,1.99,18.19]],"ltp":1.99,"tv":11.29,"id":31377}]}]}
{"op":"mcm","clk":"11816535143","pt":1723368356190,"mc":[{"id":"1.231581430","rc":[{"batb":[[0,2,36.98],[1,1.99,18.19],[2,1.74,1]],"ltp":1.99,"tv":11.29,"id":31377}]}]}
{"op":"mcm","clk":"11816535566","pt":1723368361287,"mc":[{"id":"1.231581430","rc":[{"batb":[[0,2.02,10],[1,2,36.98],[2,1.99,18.19]],"ltp":1.99,"tv":11.29,"id":31377}]}]}
{"op":"mcm","clk":"11816536146","pt":1723368368005,"mc":[{"id":"1.231581430","rc":[{"batb":[[0,2,36.98],[1,1.99,18.19],[2,1.74,1]],"ltp":1.99,"tv":11.29,"id":31377}]}]}
{"op":"mcm","clk":"11816536484","pt":1723368371898,"mc":[{"id":"1.231581430","rc":[{"batb":[[0,2.02,10],[1,2,36.98],[2,1.99,18.19]],"ltp":1.99,"tv":11.29,"id":31377}]}]}
{"op":"mcm","clk":"11816537174","pt":1723368381218,"mc":[{"id":"1.231581430","rc":[{"batb":[[0,2,36.98],[1,1.99,18.19],[2,1.74,1]],"ltp":1.99,"tv":11.29,"id":31377}]}]}
{"op":"mcm","clk":"11816537452","pt":1723368383722,"mc":[{"id":"1.231581430","rc":[{"batb":[[0,2.04,10],[1,2,36.98],[2,1.99,18.19]],"ltp":1.99,"tv":11.29,"id":31377}]}]}
{"op":"mcm","clk":"11816538364","pt":1723368395023,"mc":[{"id":"1.231581430","rc":[{"batb":[[0,2,36.98],[1,1.99,18.19],[2,1.74,1]],"ltp":1.99,"tv":11.29,"id":31377}]}]}
{"op":"mcm","clk":"11816538939","pt":1723368402746,"mc":[{"id":"1.231581430","rc":[{"batb":[[0,2.02,10],[1,2,36.98],[2,1.99,18.19]],"ltp":1.99,"tv":11.29,"id":31377}]}]}
{"op":"mcm","clk":"11816539866","pt":1723368415041,"mc":[{"id":"1.231581430","rc":[{"batb":[[0,2,36.98],[1,1.99,18.19],[2,1.74,1]],"ltp":1.99,"tv":11.29,"id":31377}]}]}
{"op":"mcm","clk":"11816551029","pt":1723368561156,"mc":[{"id":"1.231581430","rc":[{"batb":[[0,2,18.01]],"batl":[[0,2.4,9.64],[1,3,4.96],[2,1000,0.02]],"ltp":1.99,"tv":11.29,"id":31377}]}]}
{"op":"mcm","clk":"11816555535","pt":1723368617458,"mc":[{"id":"1.231581430","rc":[{"batl":[[0,2.4,5]],"ltp":1.99,"tv":11.29,"id":31377}]}]}
{"op":"mcm","clk":"11816581915","pt":1723368947628,"mc":[{"id":"1.231581430","rc":[{"trd":[[2,5.2]],"batb":[[0,2,17.91]],"ltp":2.0,"tv":11.49,"id":31377}],"tv":464.74}]}
{"op":"mcm","clk":"11816585494","pt":1723369001776,"mc":[{"id":"1.231581430","rc":[{"trd":[[2,5.58]],"batb":[[0,2,17.72]],"ltp":2.0,"tv":11.87,"id":31377}],"tv":465.12}]}
{"op":"mcm","clk":"11816586131","pt":1723369010679,"mc":[{"id":"1.231581430","rc":[{"batb":[[2,1.89,75.19]],"ltp":2.0,"tv":11.87,"id":31377}]}]}
{"op":"mcm","clk":"11816595081","pt":1723369140967,"mc":[{"id":"1.231581430","rc":[{"batl":[[0,1.97,10],[1,2,564.41],[2,1000,0.02]],"ltp":2.0,"tv":453.25,"id":169}]}]}
{"op":"mcm","clk":"11816599059","pt":1723369194103,"mc":[{"id":"1.231581430","rc":[{"trd":[[1.96,20]],"batb":[[0,1.96,42.08]],"batl":[[0,2,564.41],[1,1000,0.02],[2,1000,0]],"ltp":1.96,"tv":473.25,"id":169}],"tv":485.12}]}
{"op":"mcm","clk":"11816599479","pt":1723369200444,"mc":[{"id":"1.231581430","rc":[{"batb":[[2,1.94,83.06]],"ltp":1.96,"tv":473.25,"id":169},{"batb":[[1,1.99,97.06]],"ltp":2.0,"tv":11.87,"id":31377}]}]}
{"op":"mcm","clk":"11816609948","pt":1723369336004,"mc":[{"id":"1.231581430","rc":[{"batl":[[1,2.58,4.64],[2,3,4.96]],"ltp":2.0,"tv":11.87,"id":31377}]}]}
{"op":"mcm","clk":"11816610509","pt":1723369343220,"mc":[{"id":"1.231581430","rc":[{"batl":[[0,2.4,9.64],[1,3,4.96],[2,1000,0.02]],"ltp":2.0,"tv":11.87,"id":31377}]}]}
{"op":"mcm","clk":"11816616001","pt":1723369417218,"mc":[{"id":"1.231581430","rc":[{"batb":[[0,1.98,79.67],[1,1.96,60.85],[2,1.95,18.96]],"ltp":1.96,"tv":473.25,"id":169},{"batb":[[1,1.99,18.19],[2,1.94,83.06]],"ltp":2.0,"tv":11.87,"id":31377}]}]}
{"op":"mcm","clk":"11816616190","pt":1723369419202,"mc":[{"id":"1.231581430","rc":[{"batb":[[1,1.97,18.57],[2,1.96,60.85]],"ltp":1.96,"tv":473.25,"id":169}]}]}
{"op":"mcm","clk":"11816616437","pt":1723369422289,"mc":[{"id":"1.231581430","rc":[{"batb":[[0,1.96,60.85],[1,1.95,18.96],[2,1.89,20.24]],"ltp":1.96,"tv":473.25,"id":169},{"batb":[[2,1.89,75.19]],"ltp":2.0,"tv":11.87,"id":31377}]}]}
{"op":"mcm","clk":"11816616820","pt":1723369426821,"mc":[{"id":"1.231581430","rc":[{"batb":[[0,1.98,79.67],[1,1.96,60.85],[2,1.95,18.96]],"ltp":1.96,"tv":473.25,"id":169},{"batb":[[2,1.94,83.06]],"ltp":2.0,"tv":11.87,"id":31377}]}]}
{"op":"mcm","clk":"11816617024","pt":1723369429227,"mc":[{"id":"1.231581430","rc":[{"batb":[[1,1.97,18.57],[2,1.96,60.85]],"ltp":1.96,"tv":473.25,"id":169}]}]}
{"op":"mcm","clk":"11816617271","pt":1723369432235,"mc":[{"id":"1.231581430","rc":[{"batb":[[0,1.96,60.85],[1,1.95,18.96],[2,1.89,20.24]],"ltp":1.96,"tv":473.25,"id":169},{"batb":[[2,1.89,75.19]],"ltp":2.0,"tv":11.87,"id":31377}]}]}
{"op":"mcm","clk":"11816617652","pt":1723369436819,"mc":[{"id":"1.231581430","rc":[{"batb":[[0,1.98,79.67],[1,1.96,60.85],[2,1.95,18.96]],"ltp":1.96,"tv":473.25,"id":169},{"batb":[[2,1.94,83.06]],"ltp":2.0,"tv":11.87,"id":31377}]}]}
{"op":"mcm","clk":"11816617859","pt":1723369439212,"mc":[{"id":"1.231581430","rc":[{"batb":[[1,1.97,18.57],[2,1.96,60.85]],"ltp":1.96,"tv":473.25,"id":169}]}]}
{"op":"mcm","clk":"11816618138","pt":1723369442330,"mc":[{"id":"1.231581430","rc":[{"batb":[[0,1.96,60.85],[1,1.95,18.96],[2,1.89,20.24]],"ltp":1.96,"tv":473.25,"id":169},{"batb":[[2,1.89,75.19]],"ltp":2.0,"tv":11.87,"id":31377}]}]}
{"op":"mcm","clk":"11816618549","pt":1723369446950,"mc":[{"id":"1.231581430","rc":[{"batb":[[0,1.98,79.67],[1,1.96,60.85],[2,1.95,18.96]],"ltp":1.96,"tv":473.25,"id":169},{"batb":[[2,1.94,83.06]],"ltp":2.0,"tv":11.87,"id":31377}]}]}
{"op":"mcm","clk":"11816618766","pt":1723369449245,"mc":[{"id":"1.231581430","rc":[{"batb":[[1,1.97,18.57],[2,1.96,60.85]],"ltp":1.96,"tv":473.25,"id":169}]}]}
{"op":"mcm","clk":"11816619016","pt":1723369452262,"mc":[{"id":"1.231581430","rc":[{"batb":[[0,1.96,60.85],[1,1.95,18.96],[2,1.89,20.24]],"ltp":1.96,"tv":473.25,"id":169},{"batb":[[2,1.89,75.19]],"ltp":2.0,"tv":11.87,"id":31377}]}]}
{"op":"mcm","clk":"11816619423","pt":1723369456947,"mc":[{"id":"1.231581430","rc":[{"batb":[[0,1.98,79.67],[1,1.96,60.85],[2,1.95,18.96]],"ltp":1.96,"tv":473.25,"id":169},{"batb":[[2,1.94,83.06]],"ltp":2.0,"tv":11.87,"id":31377}]}]}
{"op":"mcm","clk":"11816619633","pt":1723369459140,"mc":[{"id":"1.231581430","rc":[{"batb":[[1,1.97,18.57],[2,1.96,60.85]],"ltp":1.96,"tv":473.25,"id":169}]}]}
{"op":"mcm","clk":"11816619912","pt":1723369462255,"mc":[{"id":"1.231581430","rc":[{"batb":[[0,1.96,60.85],[1,1.95,18.96],[2,1.89,20.24]],"ltp":1.96,"tv":473.25,"id":169},{"batb":[[2,1.89,75.19]],"ltp":2.0,"tv":11.87,"id":31377}]}]}
{"op":"mcm","clk":"11816620369","pt":1723369467361,"mc":[{"id":"1.231581430","rc":[{"batb":[[0,1.98,79.67],[1,1.96,60.85],[2,1.95,18.96]],"ltp":1.96,"tv":473.25,"id":169},{"batb":[[2,1.94,83.06]],"ltp":2.0,"tv":11.87,"id":31377}]}]}
{"op":"mcm","clk":"11816620517","pt":1723369469172,"mc":[{"id":"1.231581430","rc":[{"batb":[[1,1.97,18.57],[2,1.96,60.85]],"ltp":1.96,"tv":473.25,"id":169}]}]}
{"op":"mcm","clk":"11816620735","pt":1723369472066,"mc":[{"id":"1.231581430","rc":[{"batb":[[0,1.97,18.57],[1,1.96,60.85],[2,1.95,18.96]],"ltp":1.96,"tv":473.25,"id":169},{"batb":[[2,1.89,75.19]],"ltp":2.0,"tv":11.87,"id":31377}]}]}
{"op":"mcm","clk":"11816620786","pt":1723369472684,"mc":[{"id":"1.231581430","rc":[{"batb":[[0,1.96,60.85],[1,1.95,18.96],[2,1.89,20.24]],"ltp":1.96,"tv":473.25,"id":169}]}]}
{"op":"mcm","clk":"11816621114","pt":1723369477070,"mc":[{"id":"1.231581430","rc":[{"batb":[[0,1.98,79.67],[1,1.96,60.85],[2,1.95,18.96]],"ltp":1.96,"tv":473.25,"id":169},{"batb":[[2,1.94,83.06]],"ltp":2.0,"tv":11.87,"id":31377}]}]}
{"op":"mcm","clk":"11816621295","pt":1723369479205,"mc":[{"id":"1.231581430","rc":[{"batb":[[1,1.97,18.57],[2,1.96,60.85]],"ltp":1.96,"tv":473.25,"id":169}]}]}
{"op":"mcm","clk":"11816621533","pt":1723369482132,"mc":[{"id":"1.231581430","rc":[{"batb":[[0,1.97,18.57],[1,1.96,60.85],[2,1.95,18.96]],"ltp":1.96,"tv":473.25,"id":169},{"batb":[[2,1.89,75.19]],"ltp":2.0,"tv":11.87,"id":31377}]}]}
{"op":"mcm","clk":"11816621595","pt":1723369482708,"mc":[{"id":"1.231581430","rc":[{"batb":[[0,1.96,60.85],[1,1.95,18.96],[2,1.89,20.24]],"ltp":1.96,"tv":473.25,"id":169}]}]}
{"op":"mcm","clk":"11816621833","pt":1723369485345,"mc":[{"id":"1.231581430","rc":[{"trd":[[2,5.78]],"batb":[[0,2,17.62]],"ltp":2.0,"tv":12.07,"id":31377}],"tv":485.32}]}
{"op":"mcm","clk":"11816621982","pt":1723369487104,"mc":[{"id":"1.231581430","rc":[{"batb":[[0,1.98,79.67],[1,1.96,60.85],[2,1.95,18.96]],"ltp":1.96,"tv":473.25,"id":169},{"batb":[[2,1.94,83.06]],"ltp":2.0,"tv":12.07,"id":31377}]}]}
{"op":"mcm","clk":"11816622175","pt":1723369489234,"mc":[{"id":"1.231581430","rc":[{"batb":[[1,1.97,18.57],[2,1.96,60.85]],"ltp":1.96,"tv":473.25,"id":169}]}]}
{"op":"mcm","clk":"11816622407","pt":1723369492207,"mc":[{"id":"1.231581430","rc":[{"batb":[[0,1.97,18.57],[1,1.96,60.85],[2,1.95,18.96]],"ltp":1.96,"tv":473.25,"id":169},{"batb":[[2,1.89,75.19]],"ltp":2.0,"tv":12.07,"id":31377}]}]}
{"op":"mcm","clk":"11816622447","pt":1723369492725,"mc":[{"id":"1.231581430","rc":[{"batb":[[0,1.96,60.85],[1,1.95,18.96],[2,1.89,20.24]],"ltp":1.96,"tv":473.25,"id":169}]}]}
{"op":"mcm","clk":"11816622794","pt":1723369497218,"mc":[{"id":"1.231581430","rc":[{"batb":[[0,1.98,79.67],[1,1.96,60.85],[2,1.95,18.96]],"ltp":1.96,"tv":473.25,"id":169},{"batb":[[2,1.94,83.06]],"ltp":2.0,"tv":12.07,"id":31377}]}]}
{"op":"mcm","clk":"11816622929","pt":1723369499209,"mc":[{"id":"1.231581430","rc":[{"batb":[[1,1.97,18.57],[2,1.96,60.85]],"ltp":1.96,"tv":473.25,"id":169}]}]}
{"op":"mcm","clk":"11816623187","pt":1723369502258,"mc":[{"id":"1.231581430","rc":[{"batb":[[0,1.97,18.57],[1,1.96,60.85],[2,1.95,18.96]],"ltp":1.96,"tv":473.25,"id":169},{"batb":[[2,1.89,75.19]],"ltp":2.0,"tv":12.07,"id":31377}]}]}
{"op":"mcm","clk":"11816623245","pt":1723369502728,"mc":[{"id":"1.231581430","rc":[{"batb":[[0,1.96,60.85],[1,1.95,18.96],[2,1.89,20.24]],"ltp":1.96,"tv":473.25,"id":169}]}]}
{"op":"mcm","clk":"11816623715","pt":1723369507228,"mc":[{"id":"1.231581430","rc":[{"trd":[[2,448.46]],"batb":[[0,1.98,79.67],[1,1.96,60.85],[2,1.95,18.96]],"batl":[[0,2,564.27]],"ltp":2.0,"tv":473.53,"id":169},{"batb":[[2,1.94,83.06]],"ltp":2.0,"tv":12.07,"id":31377}],"tv":485.6}]}
{"op":"mcm","clk":"11816623881","pt":1723369509253,"mc":[{"id":"1.231581430","rc":[{"batb":[[1,1.97,18.57],[2,1.96,60.85]],"ltp":2.0,"tv":473.53,"id":169}]}]}
{"op":"mcm","clk":"11816624124","pt":1723369512433,"mc":[{"id":"1.231581430","rc":[{"batb":[[0,1.97,18.57],[1,1.96,60.85],[2,1.95,18.96]],"ltp":2.0,"tv":473.53,"id":169},{"batb":[[2,1.89,75.19]],"ltp":2.0,"tv":12.07,"id":31377}]}]}
{"op":"mcm","clk":"11816624157","pt":1723369512850,"mc":[{"id":"1.231581430","rc":[{"batb":[[0,1.96,60.85],[1,1.95,18.96],[2,1.89,20.24]],"ltp":2.0,"tv":473.53,"id":169}]}]}
{"op":"mcm","clk":"11816624540","pt":1723369517359,"mc":[{"id":"1.231581430","rc":[{"batb":[[0,1.98,79.67],[1,1.96,60.85],[2,1.95,18.96]],"ltp":2.0,"tv":473.53,"id":169},{"batb":[[2,1.94,83.06]],"ltp":2.0,"tv":12.07,"id":31377}]}]}
{"op":"mcm","clk":"11816624738","pt":1723369519236,"mc":[{"id":"1.231581430","rc":[{"batb":[[1,1.97,18.57],[2,1.96,60.85]],"ltp":2.0,"tv":473.53,"id":169}]}]}
{"op":"mcm","clk":"11816625003","pt":1723369522467,"mc":[{"id":"1.231581430","rc":[{"batb":[[0,1.97,18.57],[1,1.96,60.85],[2,1.95,18.96]],"ltp":2.0,"tv":473.53,"id":169},{"batb":[[2,1.89,75.19]],"ltp":2.0,"tv":12.07,"id":31377}]}]}
{"op":"mcm","clk":"11816625029","pt":1723369522781,"mc":[{"id":"1.231581430","rc":[{"batb":[[0,1.96,60.85],[1,1.95,18.96],[2,1.89,20.24]],"ltp":2.0,"tv":473.53,"id":169}]}]}
{"op":"mcm","clk":"11816625376","pt":1723369527360,"mc":[{"id":"1.231581430","rc":[{"batb":[[0,1.98,79.67],[1,1.96,60.85],[2,1.95,18.96]],"ltp":2.0,"tv":473.53,"id":169},{"batb":[[2,1.94,83.06]],"ltp":2.0,"tv":12.07,"id":31377}]}]}
{"op":"mcm","clk":"11816625523","pt":1723369529300,"mc":[{"id":"1.231581430","rc":[{"batb":[[1,1.97,18.57],[2,1.96,60.85]],"ltp":2.0,"tv":473.53,"id":169}]}]}
{"op":"mcm","clk":"11816625822","pt":1723369532482,"mc":[{"id":"1.231581430","rc":[{"batb":[[0,1.97,18.57],[1,1.96,60.85],[2,1.95,18.96]],"ltp":2.0,"tv":473.53,"id":169},{"batb":[[2,1.89,75.19]],"ltp":2.0,"tv":12.07,"id":31377}]}]}
{"op":"mcm","clk":"11816625859","pt":1723369532795,"mc":[{"id":"1.231581430","rc":[{"batb":[[0,1.96,60.85],[1,1.95,18.96],[2,1.89,20.24]],"ltp":2.0,"tv":473.53,"id":169}]}]}
{"op":"mcm","clk":"11816626248","pt":1723369537499,"mc":[{"id":"1.231581430","rc":[{"batb":[[0,1.98,79.67],[1,1.96,60.85],[2,1.95,18.96]],"ltp":2.0,"tv":473.53,"id":169},{"batb":[[2,1.94,83.06]],"ltp":2.0,"tv":12.07,"id":31377}]}]}
{"op":"mcm","clk":"11816626394","pt":1723369539273,"mc":[{"id":"1.231581430","rc":[{"batb":[[1,1.97,18.57],[2,1.96,60.85]],"ltp":2.0,"tv":473.53,"id":169}]}]}
{"op":"mcm","clk":"11816626710","pt":1723369542475,"mc":[{"id":"1.231581430","rc":[{"batb":[[0,1.97,18.57],[1,1.96,60.85],[2,1.95,18.96]],"ltp":2.0,"tv":473.53,"id":169},{"batb":[[2,1.89,75.19]],"ltp":2.0,"tv":12.07,"id":31377}]}]}
{"op":"mcm","clk":"11816626731","pt":1723369542785,"mc":[{"id":"1.231581430","rc":[{"batb":[[0,1.96,60.85],[1,1.95,18.96],[2,1.89,20.24]],"ltp":2.0,"tv":473.53,"id":169}]}]}
{"op":"mcm","clk":"11816627174","pt":1723369547521,"mc":[{"id":"1.231581430","rc":[{"batb":[[0,1.98,79.67],[1,1.96,60.85],[2,1.95,18.96]],"ltp":2.0,"tv":473.53,"id":169},{"batb":[[2,1.94,83.06]],"ltp":2.0,"tv":12.07,"id":31377}]}]}
{"op":"mcm","clk":"11816627342","pt":1723369549293,"mc":[{"id":"1.231581430","rc":[{"batb":[[1,1.97,18.57],[2,1.96,60.85]],"ltp":2.0,"tv":473.53,"id":169}]}]}
{"op":"mcm","clk":"11816627657","pt":1723369552918,"mc":[{"id":"1.231581430","rc":[{"batb":[[0,1.96,60.85],[1,1.95,18.96],[2,1.89,20.24]],"ltp":2.0,"tv":473.53,"id":169},{"batb":[[2,1.89,75.19]],"ltp":2.0,"tv":12.07,"id":31377}]}]}
{"op":"mcm","clk":"11816628060","pt":1723369557577,"mc":[{"id":"1.231581430","rc":[{"batb":[[0,1.98,79.67],[1,1.96,60.85],[2,1.95,18.96]],"ltp":2.0,"tv":473.53,"id":169},{"batb":[[2,1.94,83.06]],"ltp":2.0,"tv":12.07,"id":31377}]}]}
{"op":"mcm","clk":"11816628201","pt":1723369559342,"mc":[{"id":"1.231581430","rc":[{"batb":[[1,1.97,18.57],[2,1.96,60.85]],"ltp":2.0,"tv":473.53,"id":169}]}]}
{"op":"mcm","clk":"11816628488","pt":1723369562845,"mc":[{"id":"1.231581430","rc":[{"batb":[[0,1.96,60.85],[1,1.95,18.96],[2,1.89,20.24]],"ltp":2.0,"tv":473.53,"id":169},{"batb":[[2,1.89,75.19]],"ltp":2.0,"tv":12.07,"id":31377}]}]}
{"op":"mcm","clk":"11816628872","pt":1723369567597,"mc":[{"id":"1.231581430","rc":[{"batb":[[0,1.98,79.67],[1,1.96,60.85],[2,1.95,18.96]],"ltp":2.0,"tv":473.53,"id":169},{"batb":[[2,1.94,83.06]],"ltp":2.0,"tv":12.07,"id":31377}]}]}
{"op":"mcm","clk":"11816629020","pt":1723369569315,"mc":[{"id":"1.231581430","rc":[{"batb":[[1,1.97,18.57],[2,1.96,60.85]],"ltp":2.0,"tv":473.53,"id":169}]}]}
{"op":"mcm","clk":"11816629408","pt":1723369573343,"mc":[{"id":"1.231581430","rc":[{"batb":[[0,1.96,60.85],[1,1.95,18.96],[2,1.89,20.24]],"ltp":2.0,"tv":473.53,"id":169},{"batb":[[2,1.89,75.19]],"ltp":2.0,"tv":12.07,"id":31377}]}]}
{"op":"mcm","clk":"11816629805","pt":1723369577705,"mc":[{"id":"1.231581430","rc":[{"batb":[[0,1.98,79.67],[1,1.96,60.85],[2,1.95,18.96]],"ltp":2.0,"tv":473.53,"id":169},{"batb":[[2,1.94,83.06]],"ltp":2.0,"tv":12.07,"id":31377}]}]}
{"op":"mcm","clk":"11816630033","pt":1723369580309,"mc":[{"id":"1.231581430","rc":[{"batb":[[1,1.97,18.57],[2,1.96,60.85]],"ltp":2.0,"tv":473.53,"id":169}]}]}
{"op":"mcm","clk":"11816630354","pt":1723369583371,"mc":[{"id":"1.231581430","rc":[{"batb":[[0,1.96,60.85],[1,1.95,18.96],[2,1.89,20.24]],"ltp":2.0,"tv":473.53,"id":169},{"batb":[[2,1.89,75.19]],"ltp":2.0,"tv":12.07,"id":31377}]}]}
{"op":"mcm","clk":"11816630742","pt":1723369588149,"mc":[{"id":"1.231581430","rc":[{"batb":[[0,1.98,79.67],[1,1.96,60.85],[2,1.95,18.96]],"ltp":2.0,"tv":473.53,"id":169},{"batb":[[2,1.94,83.06]],"batl":[[0,2.36,4.64],[1,2.4,5],[2,3,4.96]],"ltp":2.0,"tv":12.07,"id":31377}]}]}
{"op":"mcm","clk":"11816630909","pt":1723369590272,"mc":[{"id":"1.231581430","rc":[{"batb":[[1,1.97,18.57],[2,1.96,60.85]],"ltp":2.0,"tv":473.53,"id":169}]}]}
{"op":"mcm","clk":"11816631180","pt":1723369593284,"mc":[{"id":"1.231581430","rc":[{"batb":[[0,1.96,60.85],[1,1.95,18.96],[2,1.89,20.24]],"ltp":2.0,"tv":473.53,"id":169},{"batb":[[2,1.89,75.19]],"ltp":2.0,"tv":12.07,"id":31377}]}]}
{"op":"mcm","clk":"11816631559","pt":1723369597880,"mc":[{"id":"1.231581430","rc":[{"batb":[[0,1.98,79.67],[1,1.96,60.85],[2,1.95,18.96]],"ltp":2.0,"tv":473.53,"id":169},{"batb":[[2,1.94,83.06]],"ltp":2.0,"tv":12.07,"id":31377}]}]}
{"op":"mcm","clk":"11816631750","pt":1723369600275,"mc":[{"id":"1.231581430","rc":[{"batb":[[1,1.97,18.57],[2,1.96,60.85]],"ltp":2.0,"tv":473.53,"id":169}]}]}
{"op":"mcm","clk":"11816631971","pt":1723369603294,"mc":[{"id":"1.231581430","rc":[{"batb":[[0,1.96,60.85],[1,1.95,18.96],[2,1.89,20.24]],"ltp":2.0,"tv":473.53,"id":169},{"batb":[[2,1.89,75.19]],"ltp":2.0,"tv":12.07,"id":31377}]}]}
{"op":"mcm","clk":"11816632278","pt":1723369607914,"mc":[{"id":"1.231581430","rc":[{"batb":[[0,1.98,79.67],[1,1.96,60.85],[2,1.95,18.96]],"ltp":2.0,"tv":473.53,"id":169},{"batb":[[2,1.94,83.06]],"ltp":2.0,"tv":12.07,"id":31377}]}]}
{"op":"mcm","clk":"11816632466","pt":1723369610290,"mc":[{"id":"1.231581430","rc":[{"batb":[[1,1.97,18.57],[2,1.96,60.85]],"ltp":2.0,"tv":473.53,"id":169}]}]}
{"op":"mcm","clk":"11816632687","pt":1723369613407,"mc":[{"id":"1.231581430","rc":[{"batb":[[0,1.96,60.85],[1,1.95,18.96],[2,1.89,20.24]],"ltp":2.0,"tv":473.53,"id":169},{"batb":[[2,1.89,75.19]],"ltp":2.0,"tv":12.07,"id":31377}]}]}
{"op":"mcm","clk":"11816633029","pt":1723369618006,"mc":[{"id":"1.231581430","rc":[{"batb":[[0,1.98,79.67],[1,1.96,60.85],[2,1.95,18.96]],"ltp":2.0,"tv":473.53,"id":169},{"batb":[[2,1.94,83.06]],"ltp":2.0,"tv":12.07,"id":31377}]}]}
{"op":"mcm","clk":"11816633238","pt":1723369620289,"mc":[{"id":"1.231581430","rc":[{"batb":[[1,1.97,18.57],[2,1.96,60.85]],"ltp":2.0,"tv":473.53,"id":169}]}]}
{"op":"mcm","clk":"11816633492","pt":1723369623438,"mc":[{"id":"1.231581430","rc":[{"batb":[[0,1.96,60.85],[1,1.95,18.96],[2,1.89,20.24]],"ltp":2.0,"tv":473.53,"id":169},{"batb":[[2,1.89,75.19]],"ltp":2.0,"tv":12.07,"id":31377}]}]}
{"op":"mcm","clk":"11816633857","pt":1723369628031,"mc":[{"id":"1.231581430","rc":[{"batb":[[0,1.98,79.67],[1,1.96,60.85],[2,1.95,18.96]],"ltp":2.0,"tv":473.53,"id":169},{"batb":[[2,1.94,83.06]],"ltp":2.0,"tv":12.07,"id":31377}]}]}
{"op":"mcm","clk":"11816634063","pt":1723369630327,"mc":[{"id":"1.231581430","rc":[{"batb":[[1,1.97,18.57],[2,1.96,60.85]],"ltp":2.0,"tv":473.53,"id":169}]}]}
{"op":"mcm","clk":"11816634315","pt":1723369633347,"mc":[{"id":"1.231581430","rc":[{"batb":[[0,1.96,60.85],[1,1.95,18.96],[2,1.89,20.24]],"ltp":2.0,"tv":473.53,"id":169},{"batb":[[2,1.89,75.19]],"ltp":2.0,"tv":12.07,"id":31377}]}]}
{"op":"mcm","clk":"11816634737","pt":1723369638149,"mc":[{"id":"1.231581430","rc":[{"batb":[[0,1.98,79.67],[1,1.96,60.85],[2,1.95,18.96]],"ltp":2.0,"tv":473.53,"id":169},{"batb":[[2,1.94,83.06]],"ltp":2.0,"tv":12.07,"id":31377}]}]}
{"op":"mcm","clk":"11816634957","pt":1723369640348,"mc":[{"id":"1.231581430","rc":[{"batb":[[1,1.97,18.57],[2,1.96,60.85]],"ltp":2.0,"tv":473.53,"id":169}]}]}
{"op":"mcm","clk":"11816635207","pt":1723369643144,"mc":[{"id":"1.231581430","rc":[{"batb":[[0,1.97,18.57],[1,1.96,60.85],[2,1.95,18.96]],"ltp":2.0,"tv":473.53,"id":169},{"batb":[[2,1.89,75.19]],"ltp":2.0,"tv":12.07,"id":31377}]}]}
{"op":"mcm","clk":"11816635280","pt":1723369643823,"mc":[{"id":"1.231581430","rc":[{"batb":[[0,1.96,60.85],[1,1.95,18.96],[2,1.89,20.24]],"ltp":2.0,"tv":473.53,"id":169}]}]}
{"op":"mcm","clk":"11816635636","pt":1723369648144,"mc":[{"id":"1.231581430","rc":[{"batb":[[0,1.98,79.67],[1,1.96,60.85],[2,1.95,18.96]],"ltp":2.0,"tv":473.53,"id":169},{"batb":[[2,1.94,83.06]],"ltp":2.0,"tv":12.07,"id":31377}]}]}
{"op":"mcm","clk":"11816635806","pt":1723369650334,"mc":[{"id":"1.231581430","rc":[{"batb":[[1,1.97,18.57],[2,1.96,60.85]],"ltp":2.0,"tv":473.53,"id":169}]}]}
{"op":"mcm","clk":"11816636014","pt":1723369653275,"mc":[{"id":"1.231581430","rc":[{"batb":[[0,1.97,18.57],[1,1.96,60.85],[2,1.95,18.96]],"ltp":2.0,"tv":473.53,"id":169},{"batb":[[2,1.89,75.19]],"ltp":2.0,"tv":12.07,"id":31377}]}]}
{"op":"mcm","clk":"11816636063","pt":1723369653850,"mc":[{"id":"1.231581430","rc":[{"batb":[[0,1.96,60.85],[1,1.95,18.96],[2,1.89,20.24]],"ltp":2.0,"tv":473.53,"id":169}]}]}
{"op":"mcm","clk":"11816636457","pt":1723369658267,"mc":[{"id":"1.231581430","rc":[{"batb":[[0,1.98,79.67],[1,1.96,60.85],[2,1.95,18.96]],"ltp":2.0,"tv":473.53,"id":169},{"batb":[[2,1.94,83.06]],"ltp":2.0,"tv":12.07,"id":31377}]}]}
{"op":"mcm","clk":"11816636618","pt":1723369660391,"mc":[{"id":"1.231581430","rc":[{"batb":[[1,1.97,18.57],[2,1.96,60.85]],"ltp":2.0,"tv":473.53,"id":169}]}]}
{"op":"mcm","clk":"11816636848","pt":1723369663374,"mc":[{"id":"1.231581430","rc":[{"batb":[[0,1.97,18.57],[1,1.96,60.85],[2,1.95,18.96]],"ltp":2.0,"tv":473.53,"id":169},{"batb":[[2,1.89,75.19]],"ltp":2.0,"tv":12.07,"id":31377}]}]}
{"op":"mcm","clk":"11816636897","pt":1723369663988,"mc":[{"id":"1.231581430","rc":[{"batb":[[0,1.96,60.85],[1,1.95,18.96],[2,1.89,20.24]],"ltp":2.0,"tv":473.53,"id":169}]}]}
{"op":"mcm","clk":"11816637223","pt":1723369668289,"mc":[{"id":"1.231581430","rc":[{"batb":[[0,1.98,79.67],[1,1.96,60.85],[2,1.95,18.96]],"ltp":2.0,"tv":473.53,"id":169},{"batb":[[2,1.94,83.06]],"ltp":2.0,"tv":12.07,"id":31377}]}]}
{"op":"mcm","clk":"11816637395","pt":1723369670378,"mc":[{"id":"1.231581430","rc":[{"batb":[[1,1.97,18.57],[2,1.96,60.85]],"ltp":2.0,"tv":473.53,"id":169}]}]}
{"op":"mcm","clk":"11816637645","pt":1723369673397,"mc":[{"id":"1.231581430","rc":[{"batb":[[0,1.97,18.57],[1,1.96,60.85],[2,1.95,18.96]],"ltp":2.0,"tv":473.53,"id":169},{"batb":[[2,1.89,75.19]],"ltp":2.0,"tv":12.07,"id":31377}]}]}
{"op":"mcm","clk":"11816637688","pt":1723369673913,"mc":[{"id":"1.231581430","rc":[{"batb":[[0,1.96,60.85],[1,1.95,18.96],[2,1.89,20.24]],"ltp":2.0,"tv":473.53,"id":169}]}]}
{"op":"mcm","clk":"11816638073","pt":1723369678400,"mc":[{"id":"1.231581430","rc":[{"batb":[[0,1.98,79.67],[1,1.96,60.85],[2,1.95,18.96]],"ltp":2.0,"tv":473.53,"id":169},{"batb":[[2,1.94,83.06]],"ltp":2.0,"tv":12.07,"id":31377}]}]}
{"op":"mcm","clk":"11816638223","pt":1723369680320,"mc":[{"id":"1.231581430","rc":[{"batb":[[1,1.97,18.57],[2,1.96,60.85]],"ltp":2.0,"tv":473.53,"id":169}]}]}
{"op":"mcm","clk":"11816638527","pt":1723369683399,"mc":[{"id":"1.231581430","rc":[{"batb":[[0,1.97,18.57],[1,1.96,60.85],[2,1.95,18.96]],"ltp":2.0,"tv":473.53,"id":169},{"batb":[[2,1.89,75.19]],"ltp":2.0,"tv":12.07,"id":31377}]}]}
{"op":"mcm","clk":"11816638581","pt":1723369683921,"mc":[{"id":"1.231581430","rc":[{"batb":[[0,1.96,60.85],[1,1.95,18.96],[2,1.89,20.24]],"ltp":2.0,"tv":473.53,"id":169}]}]}
{"op":"mcm","clk":"11816638944","pt":1723369688398,"mc":[{"id":"1.231581430","rc":[{"batb":[[0,1.98,79.67],[1,1.96,60.85],[2,1.95,18.96]],"ltp":2.0,"tv":473.53,"id":169},{"batb":[[2,1.94,83.06]],"ltp":2.0,"tv":12.07,"id":31377}]}]}
{"op":"mcm","clk":"11816639079","pt":1723369690321,"mc":[{"id":"1.231581430","rc":[{"batb":[[1,1.97,18.57],[2,1.96,60.85]],"ltp":2.0,"tv":473.53,"id":169}]}]}
{"op":"mcm","clk":"11816639317","pt":1723369693512,"mc":[{"id":"1.231581430","rc":[{"batb":[[0,1.97,18.57],[1,1.96,60.85],[2,1.95,18.96]],"ltp":2.0,"tv":473.53,"id":169},{"batb":[[2,1.89,75.19]],"ltp":2.0,"tv":12.07,"id":31377}]}]}
{"op":"mcm","clk":"11816639359","pt":1723369693928,"mc":[{"id":"1.231581430","rc":[{"batb":[[0,1.96,60.85],[1,1.95,18.96],[2,1.89,20.24]],"ltp":2.0,"tv":473.53,"id":169}]}]}
{"op":"mcm","clk":"11816639816","pt":1723369698524,"mc":[{"id":"1.231581430","rc":[{"batb":[[0,1.98,79.67],[1,1.96,60.85],[2,1.95,18.96]],"ltp":2.0,"tv":473.53,"id":169},{"batb":[[2,1.94,83.06]],"ltp":2.0,"tv":12.07,"id":31377}]}]}
{"op":"mcm","clk":"11816640003","pt":1723369700338,"mc":[{"id":"1.231581430","rc":[{"batb":[[1,1.97,18.57],[2,1.96,60.85]],"ltp":2.0,"tv":473.53,"id":169}]}]}
{"op":"mcm","clk":"11816640306","pt":1723369703510,"mc":[{"id":"1.231581430","rc":[{"batb":[[0,1.97,18.57],[1,1.96,60.85],[2,1.95,18.96]],"ltp":2.0,"tv":473.53,"id":169},{"batb":[[2,1.89,75.19]],"ltp":2.0,"tv":12.07,"id":31377}]}]}
{"op":"mcm","clk":"11816640352","pt":1723369703926,"mc":[{"id":"1.231581430","rc":[{"batb":[[0,1.96,60.85],[1,1.95,18.96],[2,1.89,20.24]],"ltp":2.0,"tv":473.53,"id":169}]}]}
{"op":"mcm","clk":"11816640764","pt":1723369708524,"mc":[{"id":"1.231581430","rc":[{"batb":[[0,1.98,79.67],[1,1.96,60.85],[2,1.95,18.96]],"ltp":2.0,"tv":473.53,"id":169},{"batb":[[2,1.94,83.06]],"ltp":2.0,"tv":12.07,"id":31377}]}]}
{"op":"mcm","clk":"11816640909","pt":1723369710338,"mc":[{"id":"1.231581430","rc":[{"batb":[[1,1.97,18.57],[2,1.96,60.85]],"ltp":2.0,"tv":473.53,"id":169}]}]}
{"op":"mcm","clk":"11816641241","pt":1723369713829,"mc":[{"id":"1.231581430","rc":[{"batb":[[0,1.96,60.85],[1,1.95,18.96],[2,1.89,20.24]],"ltp":2.0,"tv":473.53,"id":169},{"batb":[[2,1.89,75.19]],"ltp":2.0,"tv":12.07,"id":31377}]}]}
{"op":"mcm","clk":"11816641619","pt":1723369718619,"mc":[{"id":"1.231581430","rc":[{"batb":[[0,1.98,79.67],[1,1.96,60.85],[2,1.95,18.96]],"ltp":2.0,"tv":473.53,"id":169},{"batb":[[2,1.94,83.06]],"ltp":2.0,"tv":12.07,"id":31377}]}]}
{"op":"mcm","clk":"11816641749","pt":1723369720341,"mc":[{"id":"1.231581430","rc":[{"batb":[[1,1.97,18.57],[2,1.96,60.85]],"ltp":2.0,"tv":473.53,"id":169}]}]}
{"op":"mcm","clk":"11816642024","pt":1723369723974,"mc":[{"id":"1.231581430","rc":[{"batb":[[0,1.96,60.85],[1,1.95,18.96],[2,1.89,20.24]],"ltp":2.0,"tv":473.53,"id":169},{"batb":[[2,1.89,75.19]],"ltp":2.0,"tv":12.07,"id":31377}]}]}
{"op":"mcm","clk":"11816642384","pt":1723369728644,"mc":[{"id":"1.231581430","rc":[{"batb":[[0,1.98,79.67],[1,1.96,60.85],[2,1.95,18.96]],"ltp":2.0,"tv":473.53,"id":169},{"batb":[[2,1.94,83.06]],"ltp":2.0,"tv":12.07,"id":31377}]}]}
{"op":"mcm","clk":"11816642524","pt":1723369730345,"mc":[{"id":"1.231581430","rc":[{"batb":[[1,1.97,18.57],[2,1.96,60.85]],"ltp":2.0,"tv":473.53,"id":169}]}]}
{"op":"mcm","clk":"11816642907","pt":1723369734347,"mc":[{"id":"1.231581430","rc":[{"batb":[[0,1.96,60.85],[1,1.95,18.96],[2,1.89,20.24]],"ltp":2.0,"tv":473.53,"id":169},{"batb":[[2,1.89,75.19]],"ltp":2.0,"tv":12.07,"id":31377}]}]}
{"op":"mcm","clk":"11816643298","pt":1723369738741,"mc":[{"id":"1.231581430","rc":[{"batb":[[0,1.98,79.67],[1,1.96,60.85],[2,1.95,18.96]],"ltp":2.0,"tv":473.53,"id":169},{"batb":[[2,1.94,83.06]],"ltp":2.0,"tv":12.07,"id":31377}]}]}
{"op":"mcm","clk":"11816643515","pt":1723369741377,"mc":[{"id":"1.231581430","rc":[{"batb":[[1,1.97,18.57],[2,1.96,60.85]],"ltp":2.0,"tv":473.53,"id":169}]}]}
{"op":"mcm","clk":"11816643735","pt":1723369744387,"mc":[{"id":"1.231581430","rc":[{"batb":[[0,1.96,60.85],[1,1.95,18.96],[2,1.89,20.24]],"ltp":2.0,"tv":473.53,"id":169},{"batb":[[2,1.89,75.19]],"ltp":2.0,"tv":12.07,"id":31377}]}]}
{"op":"mcm","clk":"11816644110","pt":1723369748771,"mc":[{"id":"1.231581430","rc":[{"batb":[[0,1.98,79.67],[1,1.96,60.85],[2,1.95,18.96]],"ltp":2.0,"tv":473.53,"id":169},{"batb":[[2,1.94,83.06]],"ltp":2.0,"tv":12.07,"id":31377}]}]}
{"op":"mcm","clk":"11816644337","pt":1723369751388,"mc":[{"id":"1.231581430","rc":[{"batb":[[1,1.97,18.57],[2,1.96,60.85]],"ltp":2.0,"tv":473.53,"id":169}]}]}
{"op":"mcm","clk":"11816644609","pt":1723369754391,"mc":[{"id":"1.231581430","rc":[{"batb":[[0,1.96,60.85],[1,1.95,18.96],[2,1.89,20.24]],"ltp":2.0,"tv":473.53,"id":169},{"batb":[[2,1.89,75.19]],"ltp":2.0,"tv":12.07,"id":31377}]}]}
{"op":"mcm","clk":"11816644694","pt":1723369755268,"mc":[{"id":"1.231581430","rc":[{"batl":[[0,2,564.74]],"ltp":2.0,"tv":473.53,"id":169}]}]}
{"op":"mcm","clk":"11816644997","pt":1723369758897,"mc":[{"id":"1.231581430","rc":[{"batb":[[2,1.94,83.06]],"ltp":2.0,"tv":12.07,"id":31377}]}]}
{"op":"mcm","clk":"11816646292","pt":1723369774295,"mc":[{"id":"1.231581430","rc":[{"batb":[[2,1.9,100]],"batl":[[1,1000,0.28]],"ltp":2.0,"tv":473.53,"id":169}]}]}
{"op":"mcm","clk":"11816647883","pt":1723369793510,"mc":[{"id":"1.231581430","rc":[{"batl":[[0,2,564.27]],"ltp":2.0,"tv":473.53,"id":169}]}]}
{"op":"mcm","clk":"11816647943","pt":1723369794131,"mc":[{"id":"1.231581430","rc":[{"batb":[[0,1.98,79.67],[1,1.96,60.85],[2,1.95,18.96]],"ltp":2.0,"tv":473.53,"id":169}]}]}
{"op":"mcm","clk":"11816648143","pt":1723369796413,"mc":[{"id":"1.231581430","rc":[{"batb":[[1,1.97,18.57],[2,1.96,60.85]],"ltp":2.0,"tv":473.53,"id":169}]}]}
{"op":"mcm","clk":"11816648399","pt":1723369799424,"mc":[{"id":"1.231581430","rc":[{"batb":[[0,1.96,60.85],[1,1.95,18.96],[2,1.9,100]],"ltp":2.0,"tv":473.53,"id":169},{"batb":[[2,1.89,75.19]],"ltp":2.0,"tv":12.07,"id":31377}]}]}
{"op":"mcm","clk":"11816648670","pt":1723369802507,"mc":[{"id":"1.231581430","rc":[{"batl":[[0,2,564.74]],"ltp":2.0,"tv":473.53,"id":169}]}]}
{"op":"mcm","clk":"11816648846","pt":1723369804248,"mc":[{"id":"1.231581430","rc":[{"batb":[[2,1.94,83.06]],"ltp":2.0,"tv":12.07,"id":31377}]}]}
{"op":"mcm","clk":"11816649545","pt":1723369812214,"mc":[{"id":"1.231581430","rc":[{"batl":[[0,2,564.27]],"ltp":2.0,"tv":473.53,"id":169}]}]}
{"op":"mcm","clk":"11816649760","pt":1723369814354,"mc":[{"id":"1.231581430","rc":[{"batb":[[0,1.98,79.67],[1,1.96,60.85],[2,1.95,18.96]],"ltp":2.0,"tv":473.53,"id":169}]}]}
{"op":"mcm","clk":"11816649986","pt":1723369816479,"mc":[{"id":"1.231581430","rc":[{"batb":[[1,1.97,18.57],[2,1.96,60.85]],"ltp":2.0,"tv":473.53,"id":169}]}]}
{"op":"mcm","clk":"11816650242","pt":1723369819360,"mc":[{"id":"1.231581430","rc":[{"batb":[[0,1.97,18.57],[1,1.96,60.85],[2,1.95,18.96]],"ltp":2.0,"tv":473.53,"id":169},{"batb":[[2,1.89,75.19]],"ltp":2.0,"tv":12.07,"id":31377}]}]}
{"op":"mcm","clk":"11816650285","pt":1723369819973,"mc":[{"id":"1.231581430","rc":[{"batb":[[0,1.96,60.85],[1,1.95,18.96],[2,1.9,100]],"ltp":2.0,"tv":473.53,"id":169}]}]}
{"op":"mcm","clk":"11816650462","pt":1723369822060,"mc":[{"id":"1.231581430","rc":[{"batl":[[0,2,564.74]],"ltp":2.0,"tv":473.53,"id":169}]}]}
{"op":"mcm","clk":"11816650632","pt":1723369824396,"mc":[{"id":"1.231581430","rc":[{"batb":[[2,1.94,83.06]],"ltp":2.0,"tv":12.07,"id":31377}]}]}
{"op":"mcm","clk":"11816650989","pt":1723369828286,"mc":[{"id":"1.231581430","rc":[{"batl":[[0,2,564.27]],"ltp":2.0,"tv":473.53,"id":169}]}]}
{"op":"mcm","clk":"11816651089","pt":1723369829382,"mc":[{"id":"1.231581430","rc":[{"batb":[[0,1.98,79.67],[1,1.96,60.85],[2,1.95,18.96]],"ltp":2.0,"tv":473.53,"id":169}]}]}
{"op":"mcm","clk":"11816651294","pt":1723369831511,"mc":[{"id":"1.231581430","rc":[{"batb":[[1,1.97,18.57],[2,1.96,60.85]],"ltp":2.0,"tv":473.53,"id":169}]}]}
{"op":"mcm","clk":"11816651602","pt":1723369834447,"mc":[{"id":"1.231581430","rc":[{"batb":[[0,1.97,18.57],[1,1.96,60.85],[2,1.95,18.96]],"ltp":2.0,"tv":473.53,"id":169},{"batb":[[2,1.89,75.19]],"ltp":2.0,"tv":12.07,"id":31377}]}]}
{"op":"mcm","clk":"11816651662","pt":1723369834967,"mc":[{"id":"1.231581430","rc":[{"batb":[[0,1.96,60.85],[1,1.95,18.96],[2,1.9,100]],"ltp":2.0,"tv":473.53,"id":169}]}]}
{"op":"mcm","clk":"11816652087","pt":1723369839452,"mc":[{"id":"1.231581430","rc":[{"batb":[[0,1.98,79.67],[1,1.96,60.85],[2,1.95,18.96]],"ltp":2.0,"tv":473.53,"id":169},{"batb":[[2,1.94,83.06]],"ltp":2.0,"tv":12.07,"id":31377}]}]}
{"op":"mcm","clk":"11816652257","pt":1723369841486,"mc":[{"id":"1.231581430","rc":[{"batb":[[1,1.97,18.57],[2,1.96,60.85]],"ltp":2.0,"tv":473.53,"id":169}]}]}
{"op":"mcm","clk":"11816652355","pt":1723369842581,"mc":[{"id":"1.231581430","rc":[{"trd":[[1.98,0.94]],"batb":[[0,1.98,79.2]],"ltp":1.98,"tv":474.47,"id":169}],"tv":486.54}]}
{"op":"mcm","clk":"11816652521","pt":1723369844501,"mc":[{"id":"1.231581430","rc":[{"batb":[[0,1.97,18.57],[1,1.96,60.85],[2,1.95,18.96]],"ltp":1.98,"tv":474.47,"id":169},{"batb":[[2,1.89,75.19]],"ltp":2.0,"tv":12.07,"id":31377}]}]}
{"op":"mcm","clk":"11816652567","pt":1723369844977,"mc":[{"id":"1.231581430","rc":[{"batb":[[0,1.96,60.85],[1,1.95,18.96],[2,1.9,100]],"ltp":1.98,"tv":474.47,"id":169}]}]}
{"op":"mcm","clk":"11816652976","pt":1723369849488,"mc":[{"id":"1.231581430","rc":[{"batb":[[0,1.98,79.67],[1,1.96,60.85],[2,1.95,18.96]],"ltp":1.98,"tv":474.47,"id":169},{"batb":[[2,1.94,83.06]],"ltp":2.0,"tv":12.07,"id":31377}]}]}
{"op":"mcm","clk":"11816653124","pt":1723369851509,"mc":[{"id":"1.231581430","rc":[{"batb":[[1,1.97,18.57],[2,1.96,60.85]],"ltp":1.98,"tv":474.47,"id":169}]}]}
{"op":"mcm","clk":"11816653446","pt":1723369854997,"mc":[{"id":"1.231581430","rc":[{"batb":[[0,1.96,60.85],[1,1.95,18.96],[2,1.9,100]],"ltp":1.98,"tv":474.47,"id":169},{"batb":[[2,1.89,75.19]],"ltp":2.0,"tv":12.07,"id":31377}]}]}
{"op":"mcm","clk":"11816653829","pt":1723369859646,"mc":[{"id":"1.231581430","rc":[{"batb":[[0,1.98,79.67],[1,1.96,60.85],[2,1.95,18.96]],"ltp":1.98,"tv":474.47,"id":169},{"batb":[[2,1.94,83.06]],"ltp":2.0,"tv":12.07,"id":31377}]}]}
{"op":"mcm","clk":"11816654012","pt":1723369861723,"mc":[{"id":"1.231581430","rc":[{"batb":[[1,1.97,18.57],[2,1.96,60.85]],"ltp":1.98,"tv":474.47,"id":169}]}]}
{"op":"mcm","clk":"11816654368","pt":1723369865303,"mc":[{"id":"1.231581430","rc":[{"batb":[[0,1.96,60.85],[1,1.95,18.96],[2,1.9,100]],"ltp":1.98,"tv":474.47,"id":169},{"batb":[[2,1.89,75.19]],"ltp":2.0,"tv":12.07,"id":31377}]}]}
{"op":"mcm","clk":"11816654746","pt":1723369869612,"mc":[{"id":"1.231581430","rc":[{"batb":[[0,1.98,79.67],[1,1.96,60.85],[2,1.95,18.96]],"ltp":1.98,"tv":474.47,"id":169},{"batb":[[2,1.94,83.06]],"ltp":2.0,"tv":12.07,"id":31377}]}]}
{"op":"mcm","clk":"11816654902","pt":1723369871432,"mc":[{"id":"1.231581430","rc":[{"batb":[[1,1.97,18.57],[2,1.96,60.85]],"ltp":1.98,"tv":474.47,"id":169}]}]}
{"op":"mcm","clk":"11816655221","pt":1723369874968,"mc":[{"id":"1.231581430","rc":[{"batb":[[0,1.96,60.85],[1,1.95,18.96],[2,1.9,100]],"ltp":1.98,"tv":474.47,"id":169},{"batb":[[2,1.89,75.19]],"ltp":2.0,"tv":12.07,"id":31377}]}]}
{"op":"mcm","clk":"11816655633","pt":1723369879773,"mc":[{"id":"1.231581430","rc":[{"batb":[[0,1.98,79.67],[1,1.96,60.85],[2,1.95,18.96]],"ltp":1.98,"tv":474.47,"id":169},{"batb":[[2,1.94,83.06]],"ltp":2.0,"tv":12.07,"id":31377}]}]}
{"op":"mcm","clk":"11816655766","pt":1723369881451,"mc":[{"id":"1.231581430","rc":[{"batb":[[1,1.97,18.57],[2,1.96,60.85]],"ltp":1.98,"tv":474.47,"id":169}]}]}
{"op":"mcm","clk":"11816656190","pt":1723369885461,"mc":[{"id":"1.231581430","rc":[{"batb":[[0,1.96,60.85],[1,1.95,18.96],[2,1.9,100]],"ltp":1.98,"tv":474.47,"id":169},{"batb":[[2,1.89,75.19]],"ltp":2.0,"tv":12.07,"id":31377}]}]}
{"op":"mcm","clk":"11816656607","pt":1723369889785,"mc":[{"id":"1.231581430","rc":[{"batb":[[0,1.98,79.67],[1,1.96,60.85],[2,1.95,18.96]],"ltp":1.98,"tv":474.47,"id":169},{"batb":[[2,1.94,83.06]],"ltp":2.0,"tv":12.07,"id":31377}]}]}
{"op":"mcm","clk":"11816656766","pt":1723369891450,"mc":[{"id":"1.231581430","rc":[{"batb":[[1,1.97,18.57],[2,1.96,60.85]],"ltp":1.98,"tv":474.47,"id":169}]}]}
{"op":"mcm","clk":"11816657164","pt":1723369895493,"mc":[{"id":"1.231581430","rc":[{"batb":[[0,1.96,60.85],[1,1.95,18.96],[2,1.9,100]],"ltp":1.98,"tv":474.47,"id":169},{"batb":[[2,1.89,75.19]],"ltp":2.0,"tv":12.07,"id":31377}]}]}
{"op":"mcm","clk":"11816657505","pt":1723369899876,"mc":[{"id":"1.231581430","rc":[{"batb":[[0,1.98,79.67],[1,1.96,60.85],[2,1.95,18.96]],"ltp":1.98,"tv":474.47,"id":169},{"batb":[[2,1.94,83.06]],"ltp":2.0,"tv":12.07,"id":31377}]}]}
{"op":"mcm","clk":"11816657715","pt":1723369902509,"mc":[{"id":"1.231581430","rc":[{"batb":[[1,1.97,18.57],[2,1.96,60.85]],"ltp":1.98,"tv":474.47,"id":169}]}]}
{"op":"mcm","clk":"11816657976","pt":1723369905509,"mc":[{"id":"1.231581430","rc":[{"batb":[[0,1.96,60.85],[1,1.95,18.96],[2,1.9,100]],"ltp":1.98,"tv":474.47,"id":169},{"batb":[[2,1.89,75.19]],"ltp":2.0,"tv":12.07,"id":31377}]}]}
{"op":"mcm","clk":"11816658329","pt":1723369909886,"mc":[{"id":"1.231581430","rc":[{"batb":[[0,1.98,79.67],[1,1.96,60.85],[2,1.95,18.96]],"ltp":1.98,"tv":474.47,"id":169},{"batb":[[2,1.94,83.06]],"ltp":2.0,"tv":12.07,"id":31377}]}]}
{"op":"mcm","clk":"11816658534","pt":1723369912533,"mc":[{"id":"1.231581430","rc":[{"batb":[[1,1.97,18.57],[2,1.96,60.85]],"ltp":1.98,"tv":474.47,"id":169}]}]}
{"op":"mcm","clk":"11816658764","pt":1723369915043,"mc":[{"id":"1.231581430","rc":[{"batb":[[0,1.97,18.57],[1,1.96,60.85],[2,1.95,18.96]],"ltp":1.98,"tv":474.47,"id":169},{"batb":[[2,1.89,75.19]],"ltp":2.0,"tv":12.07,"id":31377}]}]}
{"op":"mcm","clk":"11816658817","pt":1723369915607,"mc":[{"id":"1.231581430","rc":[{"batb":[[0,1.96,60.85],[1,1.95,18.96],[2,1.9,100]],"ltp":1.98,"tv":474.47,"id":169}]}]}
{"op":"mcm","clk":"11816659166","pt":1723369920005,"mc":[{"id":"1.231581430","rc":[{"batb":[[0,1.98,79.67],[1,1.96,60.85],[2,1.95,18.96]],"ltp":1.98,"tv":474.47,"id":169},{"batb":[[2,1.94,83.06]],"ltp":2.0,"tv":12.07,"id":31377}]}]}
{"op":"mcm","clk":"11816659360","pt":1723369922506,"mc":[{"id":"1.231581430","rc":[{"batb":[[1,1.97,18.57],[2,1.96,60.85]],"ltp":1.98,"tv":474.47,"id":169}]}]}
{"op":"mcm","clk":"11816659580","pt":1723369925006,"mc":[{"id":"1.231581430","rc":[{"batb":[[0,1.97,18.57],[1,1.96,60.85],[2,1.95,18.96]],"ltp":1.98,"tv":474.47,"id":169},{"batb":[[2,1.89,75.19]],"ltp":2.0,"tv":12.07,"id":31377}]}]}
{"op":"mcm","clk":"11816659617","pt":1723369925528,"mc":[{"id":"1.231581430","rc":[{"batb":[[0,1.96,60.85],[1,1.95,18.96],[2,1.9,100]],"ltp":1.98,"tv":474.47,"id":169}]}]}
{"op":"mcm","clk":"11816659982","pt":1723369930044,"mc":[{"id":"1.231581430","rc":[{"batb":[[0,1.98,79.67],[1,1.96,60.85],[2,1.95,18.96]],"ltp":1.98,"tv":474.47,"id":169},{"batb":[[2,1.94,83.06]],"ltp":2.0,"tv":12.07,"id":31377}]}]}
{"op":"mcm","clk":"11816660199","pt":1723369932749,"mc":[{"id":"1.231581430","rc":[{"batb":[[1,1.97,18.57],[2,1.96,60.85]],"ltp":1.98,"tv":474.47,"id":169}]}]}
{"op":"mcm","clk":"11816660423","pt":1723369935162,"mc":[{"id":"1.231581430","rc":[{"batb":[[0,1.97,18.57],[1,1.96,60.85],[2,1.95,18.96]],"ltp":1.98,"tv":474.47,"id":169},{"batb":[[2,1.89,75.19]],"ltp":2.0,"tv":12.07,"id":31377}]}]}
{"op":"mcm","clk":"11816660445","pt":1723369935527,"mc":[{"id":"1.231581430","rc":[{"batb":[[0,1.96,60.85],[1,1.95,18.96],[2,1.9,100]],"ltp":1.98,"tv":474.47,"id":169}]}]}
{"op":"mcm","clk":"11816660845","pt":1723369940159,"mc":[{"id":"1.231581430","rc":[{"batb":[[0,1.98,79.67],[1,1.96,60.85],[2,1.95,18.96]],"ltp":1.98,"tv":474.47,"id":169},{"batb":[[2,1.94,83.06]],"ltp":2.0,"tv":12.07,"id":31377}]}]}
{"op":"mcm","clk":"11816661033","pt":1723369942547,"mc":[{"id":"1.231581430","rc":[{"batb":[[1,1.97,18.57],[2,1.96,60.85]],"ltp":1.98,"tv":474.47,"id":169}]}]}
{"op":"mcm","clk":"11816661228","pt":1723369945247,"mc":[{"id":"1.231581430","rc":[{"batb":[[0,1.97,18.57],[1,1.96,60.85],[2,1.95,18.96]],"ltp":1.98,"tv":474.47,"id":169},{"batb":[[2,1.89,75.19]],"ltp":2.0,"tv":12.07,"id":31377}]}]}
{"op":"mcm","clk":"11816661265","pt":1723369945668,"mc":[{"id":"1.231581430","rc":[{"batb":[[0,1.96,60.85],[1,1.95,18.96],[2,1.9,100]],"ltp":1.98,"tv":474.47,"id":169}]}]}
{"op":"mcm","clk":"11816661580","pt":1723369950275,"mc":[{"id":"1.231581430","rc":[{"batb":[[0,1.98,79.67],[1,1.96,60.85],[2,1.95,18.96]],"ltp":1.98,"tv":474.47,"id":169},{"batb":[[2,1.94,83.06]],"ltp":2.0,"tv":12.07,"id":31377}]}]}
{"op":"mcm","clk":"11816661744","pt":1723369952459,"mc":[{"id":"1.231581430","rc":[{"batb":[[1,1.97,18.57],[2,1.96,60.85]],"ltp":1.98,"tv":474.47,"id":169}]}]}
{"op":"mcm","clk":"11816661978","pt":1723369955464,"mc":[{"id":"1.231581430","rc":[{"batb":[[0,1.96,60.85],[1,1.95,18.96],[2,1.9,100]],"ltp":1.98,"tv":474.47,"id":169},{"batb":[[2,1.89,75.19]],"ltp":2.0,"tv":12.07,"id":31377}]}]}
{"op":"mcm","clk":"11816662345","pt":1723369960247,"mc":[{"id":"1.231581430","rc":[{"batb":[[0,1.98,79.67],[1,1.96,60.85],[2,1.95,18.96]],"ltp":1.98,"tv":474.47,"id":169},{"batb":[[2,1.94,83.06]],"ltp":2.0,"tv":12.07,"id":31377}]}]}
{"op":"mcm","clk":"11816662515","pt":1723369962470,"mc":[{"id":"1.231581430","rc":[{"batb":[[1,1.97,18.57],[2,1.96,60.85]],"ltp":1.98,"tv":474.47,"id":169}]}]}
{"op":"mcm","clk":"11816662700","pt":1723369965480,"mc":[{"id":"1.231581430","rc":[{"batb":[[0,1.97,18.57],[1,1.96,60.85],[2,1.95,18.96]],"ltp":1.98,"tv":474.47,"id":169},{"batb":[[2,1.89,75.19]],"ltp":2.0,"tv":12.07,"id":31377}]}]}
{"op":"mcm","clk":"11816662746","pt":1723369966054,"mc":[{"id":"1.231581430","rc":[{"batb":[[0,1.96,60.85],[1,1.95,18.96],[2,1.9,100]],"ltp":1.98,"tv":474.47,"id":169}]}]}
{"op":"mcm","clk":"11816663058","pt":1723369970380,"mc":[{"id":"1.231581430","rc":[{"batb":[[0,1.98,79.67],[1,1.96,60.85],[2,1.95,18.96]],"ltp":1.98,"tv":474.47,"id":169},{"batb":[[2,1.94,83.06]],"ltp":2.0,"tv":12.07,"id":31377}]}]}
{"op":"mcm","clk":"11816663192","pt":1723369972519,"mc":[{"id":"1.231581430","rc":[{"batb":[[1,1.97,18.57],[2,1.96,60.85]],"ltp":1.98,"tv":474.47,"id":169}]}]}
{"op":"mcm","clk":"11816663410","pt":1723369975473,"mc":[{"id":"1.231581430","rc":[{"batb":[[0,1.97,18.57],[1,1.96,60.85],[2,1.95,18.96]],"ltp":1.98,"tv":474.47,"id":169},{"batb":[[2,1.89,75.19]],"ltp":2.0,"tv":12.07,"id":31377}]}]}
{"op":"mcm","clk":"11816663448","pt":1723369976094,"mc":[{"id":"1.231581430","rc":[{"batb":[[0,1.96,60.85],[1,1.95,18.96],[2,1.9,100]],"ltp":1.98,"tv":474.47,"id":169}]}]}
{"op":"mcm","clk":"11816663723","pt":1723369980378,"mc":[{"id":"1.231581430","rc":[{"batb":[[0,1.98,79.67],[1,1.96,60.85],[2,1.95,18.96]],"ltp":1.98,"tv":474.47,"id":169},{"batb":[[2,1.94,83.06]],"ltp":2.0,"tv":12.07,"id":31377}]}]}
{"op":"mcm","clk":"11816663869","pt":1723369982510,"mc":[{"id":"1.231581430","rc":[{"batb":[[1,1.97,18.57],[2,1.96,60.85]],"ltp":1.98,"tv":474.47,"id":169}]}]}
{"op":"mcm","clk":"11816664159","pt":1723369985993,"mc":[{"id":"1.231581430","rc":[{"batb":[[0,1.96,60.85],[1,1.95,18.96],[2,1.9,100]],"ltp":1.98,"tv":474.47,"id":169},{"batb":[[2,1.89,75.19]],"ltp":2.0,"tv":12.07,"id":31377}]}]}
{"op":"mcm","clk":"11816664531","pt":1723369990519,"mc":[{"id":"1.231581430","rc":[{"batb":[[0,1.98,79.67],[1,1.96,60.85],[2,1.95,18.96]],"ltp":1.98,"tv":474.47,"id":169},{"batb":[[2,1.94,83.06]],"ltp":2.0,"tv":12.07,"id":31377}]}]}
{"op":"mcm","clk":"11816664674","pt":1723369992527,"mc":[{"id":"1.231581430","rc":[{"batb":[[1,1.97,18.57],[2,1.96,60.85]],"ltp":1.98,"tv":474.47,"id":169}]}]}
{"op":"mcm","clk":"11816664914","pt":1723369996147,"mc":[{"id":"1.231581430","rc":[{"batb":[[0,1.96,60.85],[1,1.95,18.96],[2,1.9,100]],"ltp":1.98,"tv":474.47,"id":169},{"batb":[[2,1.89,75.19]],"ltp":2.0,"tv":12.07,"id":31377}]}]}
{"op":"mcm","clk":"11816665269","pt":1723370000520,"mc":[{"id":"1.231581430","rc":[{"batb":[[0,1.98,79.67],[1,1.96,60.85],[2,1.95,18.96]],"ltp":1.98,"tv":474.47,"id":169},{"batb":[[2,1.94,83.06]],"ltp":2.0,"tv":12.07,"id":31377}]}]}
{"op":"mcm","clk":"11816665437","pt":1723370002750,"mc":[{"id":"1.231581430","rc":[{"batb":[[1,1.97,18.57],[2,1.96,60.85]],"ltp":1.98,"tv":474.47,"id":169}]}]}
{"op":"mcm","clk":"11816665743","pt":1723370006038,"mc":[{"id":"1.231581430","rc":[{"batb":[[0,1.96,60.85],[1,1.95,18.96],[2,1.9,100]],"ltp":1.98,"tv":474.47,"id":169},{"batb":[[2,1.89,75.19]],"ltp":2.0,"tv":12.07,"id":31377}]}]}
{"op":"mcm","clk":"11816666178","pt":1723370010682,"mc":[{"id":"1.231581430","rc":[{"batb":[[0,1.98,79.67],[1,1.96,60.85],[2,1.95,18.96]],"ltp":1.98,"tv":474.47,"id":169},{"batb":[[2,1.94,83.06]],"ltp":2.0,"tv":12.07,"id":31377}]}]}
{"op":"mcm","clk":"11816666322","pt":1723370012563,"mc":[{"id":"1.231581430","rc":[{"batb":[[1,1.97,18.57],[2,1.96,60.85]],"ltp":1.98,"tv":474.47,"id":169}]}]}
{"op":"mcm","clk":"11816666644","pt":1723370016154,"mc":[{"id":"1.231581430","rc":[{"batb":[[0,1.96,60.85],[1,1.95,18.96],[2,1.9,100]],"ltp":1.98,"tv":474.47,"id":169},{"batb":[[2,1.89,75.19]],"ltp":2.0,"tv":12.07,"id":31377}]}]}
{"op":"mcm","clk":"11816667034","pt":1723370020702,"mc":[{"id":"1.231581430","rc":[{"batb":[[0,1.98,79.67],[1,1.96,60.85],[2,1.95,18.96]],"ltp":1.98,"tv":474.47,"id":169},{"batb":[[2,1.94,83.06]],"ltp":2.0,"tv":12.07,"id":31377}]}]}
{"op":"mcm","clk":"11816667185","pt":1723370022593,"mc":[{"id":"1.231581430","rc":[{"batb":[[1,1.97,18.57],[2,1.96,60.85]],"ltp":1.98,"tv":474.47,"id":169}]}]}
{"op":"mcm","clk":"11816667481","pt":1723370026187,"mc":[{"id":"1.231581430","rc":[{"batb":[[0,1.96,60.85],[1,1.95,18.96],[2,1.9,100]],"ltp":1.98,"tv":474.47,"id":169},{"batb":[[2,1.89,75.19]],"ltp":2.0,"tv":12.07,"id":31377}]}]}
{"op":"mcm","clk":"11816667872","pt":1723370030776,"mc":[{"id":"1.231581430","rc":[{"batb":[[0,1.98,79.67],[1,1.96,60.85],[2,1.95,18.96]],"ltp":1.98,"tv":474.47,"id":169},{"batb":[[2,1.94,83.06]],"ltp":2.0,"tv":12.07,"id":31377}]}]}
{"op":"mcm","clk":"11816668055","pt":1723370032606,"mc":[{"id":"1.231581430","rc":[{"batb":[[1,1.97,18.57],[2,1.96,60.85]],"ltp":1.98,"tv":474.47,"id":169}]}]}
{"op":"mcm","clk":"11816668345","pt":1723370036102,"mc":[{"id":"1.231581430","rc":[{"batb":[[0,1.96,60.85],[1,1.95,18.96],[2,1.9,100]],"ltp":1.98,"tv":474.47,"id":169},{"batb":[[2,1.89,75.19]],"ltp":2.0,"tv":12.07,"id":31377}]}]}
{"op":"mcm","clk":"11816668724","pt":1723370040808,"mc":[{"id":"1.231581430","rc":[{"batb":[[0,1.98,79.67],[1,1.96,60.85],[2,1.95,18.96]],"ltp":1.98,"tv":474.47,"id":169},{"batb":[[2,1.94,83.06]],"ltp":2.0,"tv":12.07,"id":31377}]}]}
{"op":"mcm","clk":"11816668836","pt":1723370042003,"mc":[{"id":"1.231581430","rc":[{"trd":[[2,9.55]],"batb":[[0,2,15.73]],"ltp":2.0,"tv":15.84,"id":31377}],"tv":490.31}]}
{"op":"mcm","clk":"11816668893","pt":1723370042630,"mc":[{"id":"1.231581430","rc":[{"batb":[[1,1.97,18.57],[2,1.96,60.85]],"ltp":1.98,"tv":474.47,"id":169}]}]}
{"op":"mcm","clk":"11816669167","pt":1723370045928,"mc":[{"id":"1.231581430","rc":[{"batb":[[0,1.97,18.57],[1,1.96,60.85],[2,1.95,18.96]],"ltp":1.98,"tv":474.47,"id":169},{"batb":[[2,1.89,75.19]],"ltp":2.0,"tv":15.84,"id":31377}]}]}
{"op":"mcm","clk":"11816669223","pt":1723370046604,"mc":[{"id":"1.231581430","rc":[{"batb":[[0,1.96,60.85],[1,1.95,18.96],[2,1.9,100]],"ltp":1.98,"tv":474.47,"id":169}]}]}
{"op":"mcm","clk":"11816669472","pt":1723370049930,"mc":[{"id":"1.231581430","rc":[{"batl":[[0,2,564.37]],"ltp":1.98,"tv":474.47,"id":169}]}]}
{"op":"mcm","clk":"11816669538","pt":1723370050922,"mc":[{"id":"1.231581430","rc":[{"batb":[[2,1.94,83.06]],"ltp":2.0,"tv":15.84,"id":31377}]}]}
{"op":"mcm","clk":"11816669753","pt":1723370053735,"mc":[{"id":"1.231581430","rc":[{"batl":[[0,2,564.27]],"ltp":1.98,"tv":474.47,"id":169}]}]}
{"op":"mcm","clk":"11816669917","pt":1723370055898,"mc":[{"id":"1.231581430","rc":[{"batb":[[0,1.98,79.67],[1,1.96,60.85],[2,1.95,18.96]],"ltp":1.98,"tv":474.47,"id":169}]}]}
{"op":"mcm","clk":"11816670067","pt":1723370057615,"mc":[{"id":"1.231581430","rc":[{"batb":[[1,1.97,18.57],[2,1.96,60.85]],"ltp":1.98,"tv":474.47,"id":169}]}]}
{"op":"mcm","clk":"11816670380","pt":1723370061412,"mc":[{"id":"1.231581430","rc":[{"trd":[[1.97,0.2]],"batb":[[0,1.97,18.46],[1,1.96,60.85],[2,1.95,18.96]],"ltp":1.97,"tv":474.67,"id":169},{"batb":[[2,1.89,75.19]],"ltp":2.0,"tv":15.84,"id":31377}],"tv":490.52}]}
{"op":"mcm","clk":"11816670392","pt":1723370061728,"mc":[{"id":"1.231581430","rc":[{"batb":[[0,1.96,60.85],[1,1.95,18.96],[2,1.9,100]],"ltp":1.97,"tv":474.67,"id":169}]}]}
{"op":"mcm","clk":"11816670706","pt":1723370066006,"mc":[{"id":"1.231581430","rc":[{"batb":[[0,1.98,79.67],[1,1.96,60.85],[2,1.95,18.96]],"ltp":1.97,"tv":474.67,"id":169},{"batb":[[2,1.94,83.06]],"ltp":2.0,"tv":15.84,"id":31377}]}]}
{"op":"mcm","clk":"11816671184","pt":1723370071628,"mc":[{"id":"1.231581430","rc":[{"batb":[[1,1.97,18.57],[2,1.96,60.85]],"ltp":1.97,"tv":474.67,"id":169}]}]}
{"op":"mcm","clk":"11816671533","pt":1723370076029,"mc":[{"id":"1.231581430","rc":[{"batb":[[0,1.97,18.57],[1,1.96,60.85],[2,1.95,18.96]],"ltp":1.97,"tv":474.67,"id":169},{"batb":[[2,1.89,75.19]],"ltp":2.0,"tv":15.84,"id":31377}]}]}
{"op":"mcm","clk":"11816671590","pt":1723370076650,"mc":[{"id":"1.231581430","rc":[{"batb":[[0,1.96,60.85],[1,1.95,18.96],[2,1.9,100]],"ltp":1.97,"tv":474.67,"id":169}]}]}
{"op":"mcm","clk":"11816671967","pt":1723370081070,"mc":[{"id":"1.231581430","rc":[{"batb":[[0,1.98,79.67],[1,1.96,60.85],[2,1.95,18.96]],"ltp":1.97,"tv":474.67,"id":169},{"batb":[[2,1.94,83.06]],"ltp":2.0,"tv":15.84,"id":31377}]}]}
{"op":"mcm","clk":"11816672184","pt":1723370083552,"mc":[{"id":"1.231581430","rc":[{"batb":[[1,1.97,18.57],[2,1.96,60.85]],"ltp":1.97,"tv":474.67,"id":169}]}]}
{"op":"mcm","clk":"11816672372","pt":1723370086156,"mc":[{"id":"1.231581430","rc":[{"batb":[[0,1.97,18.57],[1,1.96,60.85],[2,1.95,18.96]],"ltp":1.97,"tv":474.67,"id":169},{"batb":[[2,1.89,75.19]],"ltp":2.0,"tv":15.84,"id":31377}]}]}
{"op":"mcm","clk":"11816672410","pt":1723370086678,"mc":[{"id":"1.231581430","rc":[{"batb":[[0,1.96,60.85],[1,1.95,18.96],[2,1.9,100]],"ltp":1.97,"tv":474.67,"id":169}]}]}
{"op":"mcm","clk":"11816672763","pt":1723370091249,"mc":[{"id":"1.231581430","rc":[{"batb":[[0,1.98,79.67],[1,1.96,60.85],[2,1.95,18.96]],"ltp":1.97,"tv":474.67,"id":169},{"batb":[[2,1.94,83.06]],"ltp":2.0,"tv":15.84,"id":31377}]}]}
{"op":"mcm","clk":"11816672975","pt":1723370093586,"mc":[{"id":"1.231581430","rc":[{"batb":[[1,1.97,18.57],[2,1.96,60.85]],"ltp":1.97,"tv":474.67,"id":169}]}]}
{"op":"mcm","clk":"11816673202","pt":1723370096288,"mc":[{"id":"1.231581430","rc":[{"batb":[[0,1.97,18.57],[1,1.96,60.85],[2,1.95,18.96]],"ltp":1.97,"tv":474.67,"id":169},{"batb":[[2,1.89,75.19]],"ltp":2.0,"tv":15.84,"id":31377}]}]}
{"op":"mcm","clk":"11816673228","pt":1723370096603,"mc":[{"id":"1.231581430","rc":[{"batb":[[0,1.96,60.85],[1,1.95,18.96],[2,1.9,100]],"ltp":1.97,"tv":474.67,"id":169}]}]}
{"op":"mcm","clk":"11816673684","pt":1723370101297,"mc":[{"id":"1.231581430","rc":[{"batb":[[0,1.98,79.67],[1,1.96,60.85],[2,1.95,18.96]],"ltp":1.97,"tv":474.67,"id":169},{"batb":[[2,1.94,83.06]],"ltp":2.0,"tv":15.84,"id":31377}]}]}
{"op":"mcm","clk":"11816674012","pt":1723370103586,"mc":[{"id":"1.231581430","rc":[{"batb":[[1,1.97,18.57],[2,1.96,60.85]],"ltp":1.97,"tv":474.67,"id":169}]}]}
{"op":"mcm","clk":"11816674331","pt":1723370106407,"mc":[{"id":"1.231581430","rc":[{"batb":[[0,1.97,18.57],[1,1.96,60.85],[2,1.95,18.96]],"ltp":1.97,"tv":474.67,"id":169},{"batb":[[2,1.9,11.22]],"ltp":2.0,"tv":15.84,"id":31377}]}]}
{"op":"mcm","clk":"11816674361","pt":1723370106566,"mc":[{"id":"1.231581430","rc":[{"batb":[[0,1.96,60.85],[1,1.95,18.96],[2,1.9,100]],"ltp":1.97,"tv":474.67,"id":169}]}]}
{"op":"mcm","clk":"11816674925","pt":1723370111402,"mc":[{"id":"1.231581430","rc":[{"batb":[[0,1.98,79.67],[1,1.96,60.85],[2,1.95,18.96]],"ltp":1.97,"tv":474.67,"id":169},{"batb":[[2,1.94,83.06]],"ltp":2.0,"tv":15.84,"id":31377}]}]}
{"op":"mcm","clk":"11816675161","pt":1723370113592,"mc":[{"id":"1.231581430","rc":[{"batb":[[1,1.97,18.57],[2,1.96,60.85]],"ltp":1.97,"tv":474.67,"id":169}]}]}
{"op":"mcm","clk":"11816675530","pt":1723370117097,"mc":[{"id":"1.231581430","rc":[{"batb":[[0,1.96,60.85],[1,1.95,18.96],[2,1.9,100]],"ltp":1.97,"tv":474.67,"id":169},{"batb":[[2,1.9,11.22]],"ltp":2.0,"tv":15.84,"id":31377}]}]}
{"op":"mcm","clk":"11816675987","pt":1723370121522,"mc":[{"id":"1.231581430","rc":[{"batb":[[0,1.98,79.67],[1,1.96,60.85],[2,1.95,18.96]],"ltp":1.97,"tv":474.67,"id":169},{"batb":[[2,1.94,83.06]],"ltp":2.0,"tv":15.84,"id":31377}]}]}
{"op":"mcm","clk":"11816676165","pt":1723370123610,"mc":[{"id":"1.231581430","rc":[{"batb":[[1,1.97,18.57],[2,1.96,60.85]],"ltp":1.97,"tv":474.67,"id":169}]}]}
{"op":"mcm","clk":"11816676485","pt":1723370127093,"mc":[{"id":"1.231581430","rc":[{"batb":[[0,1.96,60.85],[1,1.95,18.96],[2,1.9,100]],"ltp":1.97,"tv":474.67,"id":169},{"batb":[[2,1.9,11.22]],"ltp":2.0,"tv":15.84,"id":31377}]}]}
{"op":"mcm","clk":"11816676891","pt":1723370131511,"mc":[{"id":"1.231581430","rc":[{"batb":[[0,1.98,79.67],[1,1.96,60.85],[2,1.95,18.96]],"ltp":1.97,"tv":474.67,"id":169},{"batb":[[2,1.94,83.06]],"ltp":2.0,"tv":15.84,"id":31377}]}]}
{"op":"mcm","clk":"11816677058","pt":1723370133598,"mc":[{"id":"1.231581430","rc":[{"batb":[[1,1.97,18.57],[2,1.96,60.85]],"ltp":1.97,"tv":474.67,"id":169}]}]}
{"op":"mcm","clk":"11816677351","pt":1723370137117,"mc":[{"id":"1.231581430","rc":[{"batb":[[0,1.96,60.85],[1,1.95,18.96],[2,1.9,100]],"ltp":1.97,"tv":474.67,"id":169},{"batb":[[2,1.9,11.22]],"ltp":2.0,"tv":15.84,"id":31377}]}]}
{"op":"mcm","clk":"11816677789","pt":1723370141634,"mc":[{"id":"1.231581430","rc":[{"batb":[[0,1.98,79.67],[1,1.96,60.85],[2,1.95,18.96]],"ltp":1.97,"tv":474.67,"id":169},{"batb":[[2,1.94,83.06]],"ltp":2.0,"tv":15.84,"id":31377}]}]}
{"op":"mcm","clk":"11816677935","pt":1723370143241,"mc":[{"id":"1.231581430","rc":[{"batb":[[2,1.95,31.66]],"ltp":1.97,"tv":474.67,"id":169},{"batl":[[2,3,16.96]],"ltp":2.0,"tv":15.84,"id":31377}]}]}
{"op":"mcm","clk":"11816677970","pt":1723370143608,"mc":[{"id":"1.231581430","rc":[{"batb":[[1,1.97,18.57],[2,1.96,60.85]],"ltp":1.97,"tv":474.67,"id":169}]}]}
{"op":"mcm","clk":"11816678305","pt":1723370147240,"mc":[{"id":"1.231581430","rc":[{"batb":[[0,1.96,60.85],[1,1.95,31.66],[2,1.9,100]],"ltp":1.97,"tv":474.67,"id":169},{"batb":[[2,1.9,11.22]],"ltp":2.0,"tv":15.84,"id":31377}]}]}
{"op":"mcm","clk":"11816678733","pt":1723370151654,"mc":[{"id":"1.231581430","rc":[{"batb":[[0,1.98,79.67],[1,1.96,60.85],[2,1.95,31.66]],"ltp":1.97,"tv":474.67,"id":169},{"batb":[[2,1.94,83.06]],"ltp":2.0,"tv":15.84,"id":31377}]}]}
{"op":"mcm","clk":"11816678984","pt":1723370154353,"mc":[{"id":"1.231581430","rc":[{"batb":[[1,1.97,18.57],[2,1.96,60.85]],"ltp":1.97,"tv":474.67,"id":169}]}]}
{"op":"mcm","clk":"11816679262","pt":1723370157174,"mc":[{"id":"1.231581430","rc":[{"batb":[[0,1.96,60.85],[1,1.95,31.66],[2,1.9,100]],"ltp":1.97,"tv":474.67,"id":169},{"batb":[[2,1.9,11.22]],"ltp":2.0,"tv":15.84,"id":31377}]}]}
{"op":"mcm","clk":"11816679680","pt":1723370161752,"mc":[{"id":"1.231581430","rc":[{"batb":[[0,1.98,79.67],[1,1.96,60.85],[2,1.95,31.66]],"ltp":1.97,"tv":474.67,"id":169},{"batb":[[2,1.94,83.06]],"ltp":2.0,"tv":15.84,"id":31377}]}]}
{"op":"mcm","clk":"11816679879","pt":1723370163633,"mc":[{"id":"1.231581430","rc":[{"batb":[[1,1.97,18.57],[2,1.96,60.85]],"ltp":1.97,"tv":474.67,"id":169}]}]}
{"op":"mcm","clk":"11816680199","pt":1723370167164,"mc":[{"id":"1.231581430","rc":[{"batb":[[0,1.96,60.85],[1,1.95,31.66],[2,1.9,100]],"ltp":1.97,"tv":474.67,"id":169},{"batb":[[2,1.9,11.22]],"ltp":2.0,"tv":15.84,"id":31377}]}]}
{"op":"mcm","clk":"11816680641","pt":1723370171780,"mc":[{"id":"1.231581430","rc":[{"batb":[[0,1.98,79.67],[1,1.96,60.85],[2,1.95,31.66]],"ltp":1.97,"tv":474.67,"id":169},{"batb":[[2,1.94,83.06]],"ltp":2.0,"tv":15.84,"id":31377}]}]}
{"op":"mcm","clk":"11816680810","pt":1723370173669,"mc":[{"id":"1.231581430","rc":[{"batb":[[1,1.97,18.57],[2,1.96,60.85]],"ltp":1.97,"tv":474.67,"id":169}]}]}
{"op":"mcm","clk":"11816681155","pt":1723370177291,"mc":[{"id":"1.231581430","rc":[{"batb":[[0,1.96,60.85],[1,1.95,31.66],[2,1.9,100]],"ltp":1.97,"tv":474.67,"id":169},{"batb":[[2,1.9,11.22]],"ltp":2.0,"tv":15.84,"id":31377}]}]}
{"op":"mcm","clk":"11816681585","pt":1723370181876,"mc":[{"id":"1.231581430","rc":[{"batb":[[0,1.98,79.67],[1,1.96,60.85],[2,1.95,31.66]],"ltp":1.97,"tv":474.67,"id":169},{"batb":[[2,1.94,83.06]],"ltp":2.0,"tv":15.84,"id":31377}]}]}
{"op":"mcm","clk":"11816681771","pt":1723370183695,"mc":[{"id":"1.231581430","rc":[{"batb":[[1,1.97,18.57],[2,1.96,60.85]],"ltp":1.97,"tv":474.67,"id":169}]}]}
{"op":"mcm","clk":"11816682222","pt":1723370187195,"mc":[{"id":"1.231581430","rc":[{"batb":[[0,1.96,60.85],[1,1.95,31.66],[2,1.9,100]],"ltp":1.97,"tv":474.67,"id":169},{"batb":[[2,1.9,11.22]],"ltp":2.0,"tv":15.84,"id":31377}]}]}
{"op":"mcm","clk":"11816682683","pt":1723370191993,"mc":[{"id":"1.231581430","rc":[{"batb":[[0,1.98,79.67],[1,1.96,60.85],[2,1.95,31.66]],"ltp":1.97,"tv":474.67,"id":169},{"batb":[[2,1.94,83.06]],"ltp":2.0,"tv":15.84,"id":31377}]}]}
{"op":"mcm","clk":"11816682857","pt":1723370193709,"mc":[{"id":"1.231581430","rc":[{"batb":[[1,1.97,18.57],[2,1.96,60.85]],"ltp":1.97,"tv":474.67,"id":169}]}]}
{"op":"mcm","clk":"11816683253","pt":1723370197187,"mc":[{"id":"1.231581430","rc":[{"batb":[[0,1.96,60.85],[1,1.95,31.66],[2,1.9,100]],"ltp":1.97,"tv":474.67,"id":169},{"batb":[[2,1.9,11.22]],"ltp":2.0,"tv":15.84,"id":31377}]}]}
{"op":"mcm","clk":"11816683871","pt":1723370202083,"mc":[{"id":"1.231581430","rc":[{"batb":[[0,1.98,79.67],[1,1.96,60.85],[2,1.95,31.66]],"ltp":1.97,"tv":474.67,"id":169},{"batb":[[2,1.94,83.06]],"ltp":2.0,"tv":15.84,"id":31377}]}]}
{"op":"mcm","clk":"11816684168","pt":1723370204691,"mc":[{"id":"1.231581430","rc":[{"batb":[[1,1.97,18.57],[2,1.96,60.85]],"ltp":1.97,"tv":474.67,"id":169}]}]}
{"op":"mcm","clk":"11816684428","pt":1723370207124,"mc":[{"id":"1.231581430","rc":[{"batb":[[0,1.97,18.57],[1,1.96,60.85],[2,1.95,31.66]],"ltp":1.97,"tv":474.67,"id":169},{"batb":[[2,1.9,11.22]],"ltp":2.0,"tv":15.84,"id":31377}]}]}
{"op":"mcm","clk":"11816684495","pt":1723370207707,"mc":[{"id":"1.231581430","rc":[{"batb":[[0,1.96,60.85],[1,1.95,31.66],[2,1.9,100]],"ltp":1.97,"tv":474.67,"id":169}]}]}
{"op":"mcm","clk":"11816684954","pt":1723370212115,"mc":[{"id":"1.231581430","rc":[{"batb":[[0,1.98,79.67],[1,1.96,60.85],[2,1.95,31.66]],"ltp":1.97,"tv":474.67,"id":169},{"batb":[[2,1.94,83.06]],"ltp":2.0,"tv":15.84,"id":31377}]}]}
{"op":"mcm","clk":"11816685208","pt":1723370214725,"mc":[{"id":"1.231581430","rc":[{"batb":[[1,1.97,18.57],[2,1.96,60.85]],"ltp":1.97,"tv":474.67,"id":169}]}]}
{"op":"mcm","clk":"11816685451","pt":1723370217220,"mc":[{"id":"1.231581430","rc":[{"batb":[[0,1.97,18.57],[1,1.96,60.85],[2,1.95,31.66]],"batl":[[0,1.99,18],[1,2,564.27],[2,1000,0.28]],"ltp":1.97,"tv":474.67,"id":169},{"batb":[[2,1.9,11.22]],"ltp":2.0,"tv":15.84,"id":31377}]}]}
{"op":"mcm","clk":"11816685496","pt":1723370217739,"mc":[{"id":"1.231581430","rc":[{"batb":[[0,1.96,60.85],[1,1.95,31.66],[2,1.9,100]],"ltp":1.97,"tv":474.67,"id":169}]}]}
{"op":"mcm","clk":"11816685975","pt":1723370222226,"mc":[{"id":"1.231581430","rc":[{"batb":[[0,1.98,79.67],[1,1.96,60.85],[2,1.95,31.66]],"ltp":1.97,"tv":474.67,"id":169},{"batb":[[2,1.94,83.06]],"ltp":2.0,"tv":15.84,"id":31377}]}]}
{"op":"mcm","clk":"11816686237","pt":1723370224737,"mc":[{"id":"1.231581430","rc":[{"batb":[[1,1.97,18.57],[2,1.96,60.85]],"ltp":1.97,"tv":474.67,"id":169}]}]}
{"op":"mcm","clk":"11816686502","pt":1723370227336,"mc":[{"id":"1.231581430","rc":[{"batb":[[0,1.97,18.57],[1,1.96,60.85],[2,1.95,31.66]],"ltp":1.97,"tv":474.67,"id":169},{"batb":[[2,1.9,11.22]],"ltp":2.0,"tv":15.84,"id":31377}]}]}
{"op":"mcm","clk":"11816686532","pt":1723370227749,"mc":[{"id":"1.231581430","rc":[{"batb":[[0,1.96,60.85],[1,1.95,31.66],[2,1.9,100]],"ltp":1.97,"tv":474.67,"id":169}]}]}
{"op":"mcm","clk":"11816686973","pt":1723370232219,"mc":[{"id":"1.231581430","rc":[{"batb":[[0,1.98,79.67],[1,1.96,60.85],[2,1.95,31.66]],"ltp":1.97,"tv":474.67,"id":169},{"batb":[[2,1.94,83.06]],"ltp":2.0,"tv":15.84,"id":31377}]}]}
{"op":"mcm","clk":"11816687259","pt":1723370234757,"mc":[{"id":"1.231581430","rc":[{"batb":[[1,1.97,18.57],[2,1.96,60.85]],"ltp":1.97,"tv":474.67,"id":169}]}]}
{"op":"mcm","clk":"11816687512","pt":1723370237363,"mc":[{"id":"1.231581430","rc":[{"batb":[[0,1.97,18.57],[1,1.96,60.85],[2,1.95,31.66]],"ltp":1.97,"tv":474.67,"id":169},{"batb":[[2,1.9,11.22]],"ltp":2.0,"tv":15.84,"id":31377}]}]}
{"op":"mcm","clk":"11816687562","pt":1723370237841,"mc":[{"id":"1.231581430","rc":[{"batb":[[0,1.96,60.85],[1,1.95,31.66],[2,1.9,100]],"ltp":1.97,"tv":474.67,"id":169}]}]}
{"op":"mcm","clk":"11816688077","pt":1723370242356,"mc":[{"id":"1.231581430","rc":[{"batb":[[0,1.98,79.67],[1,1.96,60.85],[2,1.95,31.66]],"ltp":1.97,"tv":474.67,"id":169},{"batb":[[2,1.94,83.06]],"ltp":2.0,"tv":15.84,"id":31377}]}]}
{"op":"mcm","clk":"11816688306","pt":1723370244748,"mc":[{"id":"1.231581430","rc":[{"batb":[[1,1.97,18.57],[2,1.96,60.85]],"ltp":1.97,"tv":474.67,"id":169}]}]}
{"op":"mcm","clk":"11816688605","pt":1723370247756,"mc":[{"id":"1.231581430","rc":[{"batb":[[0,1.96,60.85],[1,1.95,31.66],[2,1.9,100]],"ltp":1.97,"tv":474.67,"id":169},{"batb":[[2,1.9,11.22]],"ltp":2.0,"tv":15.84,"id":31377}]}]}
{"op":"mcm","clk":"11816688698","pt":1723370248749,"mc":[{"id":"1.231581430","rc":[{"batb":[[0,1.96,60.95]],"ltp":1.97,"tv":474.67,"id":169}]}]}
{"op":"mcm","clk":"11816689062","pt":1723370252596,"mc":[{"id":"1.231581430","rc":[{"batb":[[0,1.98,79.67],[1,1.96,60.95],[2,1.95,31.66]],"ltp":1.97,"tv":474.67,"id":169},{"batb":[[2,1.94,83.06]],"ltp":2.0,"tv":15.84,"id":31377}]}]}
{"op":"mcm","clk":"11816689284","pt":1723370254697,"mc":[{"id":"1.231581430","rc":[{"batb":[[1,1.97,18.57],[2,1.96,60.95]],"ltp":1.97,"tv":474.67,"id":169}]}]}
{"op":"mcm","clk":"11816689665","pt":1723370258256,"mc":[{"id":"1.231581430","rc":[{"batb":[[0,1.96,60.95],[1,1.95,31.66],[2,1.9,100]],"ltp":1.97,"tv":474.67,"id":169},{"batb":[[2,1.9,11.22]],"ltp":2.0,"tv":15.84,"id":31377}]}]}
{"op":"mcm","clk":"11816690095","pt":1723370262582,"mc":[{"id":"1.231581430","rc":[{"batb":[[0,1.98,79.67],[1,1.96,60.95],[2,1.95,31.66]],"ltp":1.97,"tv":474.67,"id":169},{"batb":[[2,1.94,83.06]],"ltp":2.0,"tv":15.84,"id":31377}]}]}
{"op":"mcm","clk":"11816690340","pt":1723370264780,"mc":[{"id":"1.231581430","rc":[{"batb":[[1,1.97,18.57],[2,1.96,60.95]],"ltp":1.97,"tv":474.67,"id":169}]}]}
{"op":"mcm","clk":"11816690733","pt":1723370268165,"mc":[{"id":"1.231581430","rc":[{"batb":[[0,1.96,60.95],[1,1.95,31.66],[2,1.9,100]],"ltp":1.97,"tv":474.67,"id":169},{"batb":[[2,1.9,11.22]],"ltp":2.0,"tv":15.84,"id":31377}]}]}
{"op":"mcm","clk":"11816691151","pt":1723370272716,"mc":[{"id":"1.231581430","rc":[{"batb":[[0,1.98,79.67],[1,1.96,60.95],[2,1.95,31.66]],"ltp":1.97,"tv":474.67,"id":169},{"batb":[[2,1.94,83.06]],"ltp":2.0,"tv":15.84,"id":31377}]}]}
{"op":"mcm","clk":"11816691344","pt":1723370274692,"mc":[{"id":"1.231581430","rc":[{"batb":[[1,1.97,18.57],[2,1.96,60.95]],"ltp":1.97,"tv":474.67,"id":169}]}]}
{"op":"mcm","clk":"11816691662","pt":1723370278170,"mc":[{"id":"1.231581430","rc":[{"batb":[[0,1.96,60.95],[1,1.95,31.66],[2,1.9,100]],"ltp":1.97,"tv":474.67,"id":169},{"batb":[[2,1.9,11.22]],"ltp":2.0,"tv":15.84,"id":31377}]}]}
{"op":"mcm","clk":"11816692147","pt":1723370282679,"mc":[{"id":"1.231581430","rc":[{"batb":[[0,1.98,79.67],[1,1.96,60.95],[2,1.95,31.66]],"ltp":1.97,"tv":474.67,"id":169},{"batb":[[2,1.94,83.06]],"ltp":2.0,"tv":15.84,"id":31377}]}]}
{"op":"mcm","clk":"11816692385","pt":1723370284813,"mc":[{"id":"1.231581430","rc":[{"batb":[[1,1.97,18.57],[2,1.96,60.95]],"ltp":1.97,"tv":474.67,"id":169}]}]}
{"op":"mcm","clk":"11816692575","pt":1723370286695,"mc":[{"id":"1.231581430","rc":[{"trd":[[2,10.87]],"batb":[[0,2,15.07]],"ltp":2.0,"tv":17.16,"id":31377}],"tv":491.83}]}
{"op":"mcm","clk":"11816692733","pt":1723370288297,"mc":[{"id":"1.231581430","rc":[{"batb":[[0,1.96,60.95],[1,1.95,31.66],[2,1.9,100]],"ltp":1.97,"tv":474.67,"id":169},{"batb":[[2,1.9,11.22]],"ltp":2.0,"tv":17.16,"id":31377}]}]}
{"op":"mcm","clk":"11816693245","pt":1723370292830,"mc":[{"id":"1.231581430","rc":[{"batb":[[0,1.98,79.67],[1,1.96,60.95],[2,1.95,31.66]],"ltp":1.97,"tv":474.67,"id":169},{"batb":[[2,1.94,83.06]],"ltp":2.0,"tv":17.16,"id":31377}]}]}
{"op":"mcm","clk":"11816693476","pt":1723370294704,"mc":[{"id":"1.231581430","rc":[{"batb":[[1,1.97,18.57],[2,1.96,60.95]],"ltp":1.97,"tv":474.67,"id":169}]}]}
{"op":"mcm","clk":"11816693865","pt":1723370298232,"mc":[{"id":"1.231581430","rc":[{"batb":[[0,1.96,60.95],[1,1.95,31.66],[2,1.9,100]],"ltp":1.97,"tv":474.67,"id":169},{"batb":[[2,1.9,11.22]],"ltp":2.0,"tv":17.16,"id":31377}]}]}
{"op":"mcm","clk":"11816694417","pt":1723370302834,"mc":[{"id":"1.231581430","rc":[{"batb":[[0,1.98,79.67],[1,1.96,60.95],[2,1.95,31.66]],"ltp":1.97,"tv":474.67,"id":169},{"batb":[[2,1.94,83.06]],"ltp":2.0,"tv":17.16,"id":31377}]}]}
{"op":"mcm","clk":"11816694674","pt":1723370304727,"mc":[{"id":"1.231581430","rc":[{"batb":[[1,1.97,18.57],[2,1.96,60.95]],"ltp":1.97,"tv":474.67,"id":169}]}]}
{"op":"mcm","clk":"11816695083","pt":1723370308317,"mc":[{"id":"1.231581430","rc":[{"batb":[[0,1.96,60.95],[1,1.95,31.66],[2,1.9,100]],"ltp":1.97,"tv":474.67,"id":169},{"batb":[[2,1.9,11.22]],"ltp":2.0,"tv":17.16,"id":31377}]}]}
{"op":"mcm","clk":"11816695578","pt":1723370312935,"mc":[{"id":"1.231581430","rc":[{"batb":[[0,1.98,79.67],[1,1.96,60.95],[2,1.95,31.66]],"ltp":1.97,"tv":474.67,"id":169},{"batb":[[2,1.94,83.06]],"ltp":2.0,"tv":17.16,"id":31377}]}]}
{"op":"mcm","clk":"11816695793","pt":1723370314762,"mc":[{"id":"1.231581430","rc":[{"batb":[[1,1.97,18.57],[2,1.96,60.95]],"ltp":1.97,"tv":474.67,"id":169}]}]}
{"op":"mcm","clk":"11816696181","pt":1723370318252,"mc":[{"id":"1.231581430","rc":[{"batb":[[0,1.96,60.95],[1,1.95,31.66],[2,1.9,100]],"ltp":1.97,"tv":474.67,"id":169},{"batb":[[2,1.9,11.22]],"ltp":2.0,"tv":17.16,"id":31377}]}]}
{"op":"mcm","clk":"11816696690","pt":1723370322933,"mc":[{"id":"1.231581430","rc":[{"batb":[[0,1.98,79.67],[1,1.96,60.95],[2,1.95,31.66]],"ltp":1.97,"tv":474.67,"id":169},{"batb":[[2,1.94,83.06]],"batl":[[0,2.4,5],[1,3,16.96],[2,1000,0.27]],"ltp":2.0,"tv":17.16,"id":31377}]}]}
{"op":"mcm","clk":"11816696867","pt":1723370324745,"mc":[{"id":"1.231581430","rc":[{"batb":[[1,1.97,18.57],[2,1.96,60.95]],"ltp":1.97,"tv":474.67,"id":169}]}]}
{"op":"mcm","clk":"11816697214","pt":1723370328169,"mc":[{"id":"1.231581430","rc":[{"batb":[[0,1.97,18.57],[1,1.96,60.95],[2,1.95,31.66]],"ltp":1.97,"tv":474.67,"id":169},{"batb":[[2,1.9,11.22]],"ltp":2.0,"tv":17.16,"id":31377}]}]}
{"op":"mcm","clk":"11816697276","pt":1723370328738,"mc":[{"id":"1.231581430","rc":[{"batb":[[0,1.96,60.95],[1,1.95,31.66],[2,1.9,100]],"ltp":1.97,"tv":474.67,"id":169}]}]}
{"op":"mcm","clk":"11816697718","pt":1723370333063,"mc":[{"id":"1.231581430","rc":[{"batb":[[0,1.98,79.67],[1,1.96,60.95],[2,1.95,31.66]],"ltp":1.97,"tv":474.67,"id":169},{"batb":[[2,1.94,83.06]],"ltp":2.0,"tv":17.16,"id":31377}]}]}
{"op":"mcm","clk":"11816697892","pt":1723370334771,"mc":[{"id":"1.231581430","rc":[{"batb":[[1,1.97,18.57],[2,1.96,60.95]],"ltp":1.97,"tv":474.67,"id":169}]}]}
{"op":"mcm","clk":"11816698208","pt":1723370338398,"mc":[{"id":"1.231581430","rc":[{"batb":[[0,1.96,60.95],[1,1.95,31.66],[2,1.9,100]],"ltp":1.97,"tv":474.67,"id":169},{"batb":[[2,1.9,11.22]],"ltp":2.0,"tv":17.16,"id":31377}]}]}
{"op":"mcm","clk":"11816698851","pt":1723370343079,"mc":[{"id":"1.231581430","rc":[{"batb":[[0,1.98,79.67],[1,1.96,60.95],[2,1.95,31.66]],"ltp":1.97,"tv":474.67,"id":169},{"batb":[[2,1.94,83.06]],"ltp":2.0,"tv":17.16,"id":31377}]}]}
{"op":"mcm","clk":"11816699060","pt":1723370344797,"mc":[{"id":"1.231581430","rc":[{"batb":[[1,1.97,18.57],[2,1.96,60.95]],"ltp":1.97,"tv":474.67,"id":169}]}]}
{"op":"mcm","clk":"11816699448","pt":1723370348174,"mc":[{"id":"1.231581430","rc":[{"batb":[[0,1.97,18.57],[1,1.96,60.95],[2,1.95,31.66]],"ltp":1.97,"tv":474.67,"id":169},{"batb":[[2,1.9,11.22]],"ltp":2.0,"tv":17.16,"id":31377}]}]}
{"op":"mcm","clk":"11816699517","pt":1723370348809,"mc":[{"id":"1.231581430","rc":[{"batb":[[0,1.96,60.95],[1,1.95,31.66],[2,1.9,100]],"ltp":1.97,"tv":474.67,"id":169}]}]}
{"op":"mcm","clk":"11816699961","pt":1723370353223,"mc":[{"id":"1.231581430","rc":[{"batb":[[0,1.98,79.67],[1,1.96,60.95],[2,1.95,31.66]],"ltp":1.97,"tv":474.67,"id":169},{"batb":[[2,1.94,83.06]],"ltp":2.0,"tv":17.16,"id":31377}]}]}
{"op":"mcm","clk":"11816700251","pt":1723370355816,"mc":[{"id":"1.231581430","rc":[{"batb":[[1,1.97,18.57],[2,1.96,60.95]],"ltp":1.97,"tv":474.67,"id":169}]}]}
{"op":"mcm","clk":"11816700524","pt":1723370358302,"mc":[{"id":"1.231581430","rc":[{"batb":[[0,1.97,18.57],[1,1.96,60.95],[2,1.95,31.66]],"ltp":1.97,"tv":474.67,"id":169},{"batb":[[2,1.9,11.22]],"ltp":2.0,"tv":17.16,"id":31377}]}]}
{"op":"mcm","clk":"11816700572","pt":1723370358819,"mc":[{"id":"1.231581430","rc":[{"batb":[[0,1.96,60.95],[1,1.95,31.66],[2,1.9,100]],"ltp":1.97,"tv":474.67,"id":169}]}]}
{"op":"mcm","clk":"11816701039","pt":1723370363307,"mc":[{"id":"1.231581430","rc":[{"batb":[[0,1.98,79.67],[1,1.96,60.95],[2,1.95,31.66]],"ltp":1.97,"tv":474.67,"id":169},{"batb":[[2,1.94,83.06]],"ltp":2.0,"tv":17.16,"id":31377}]}]}
{"op":"mcm","clk":"11816701304","pt":1723370365806,"mc":[{"id":"1.231581430","rc":[{"batb":[[1,1.97,18.57],[2,1.96,60.95]],"ltp":1.97,"tv":474.67,"id":169}]}]}
{"op":"mcm","clk":"11816701593","pt":1723370368305,"mc":[{"id":"1.231581430","rc":[{"batb":[[0,1.97,18.57],[1,1.96,60.95],[2,1.95,31.66]],"ltp":1.97,"tv":474.67,"id":169},{"batb":[[2,1.9,11.22]],"ltp":2.0,"tv":17.16,"id":31377}]}]}
{"op":"mcm","clk":"11816701647","pt":1723370368823,"mc":[{"id":"1.231581430","rc":[{"batb":[[0,1.96,60.95],[1,1.95,31.66],[2,1.9,100]],"ltp":1.97,"tv":474.67,"id":169}]}]}
{"op":"mcm","clk":"11816702078","pt":1723370373302,"mc":[{"id":"1.231581430","rc":[{"batb":[[0,1.98,79.67],[1,1.96,60.95],[2,1.95,31.66]],"ltp":1.97,"tv":474.67,"id":169},{"batb":[[2,1.94,83.06]],"ltp":2.0,"tv":17.16,"id":31377}]}]}
{"op":"mcm","clk":"11816702347","pt":1723370375796,"mc":[{"id":"1.231581430","rc":[{"batb":[[1,1.97,18.57],[2,1.96,60.95]],"ltp":1.97,"tv":474.67,"id":169}]}]}
{"op":"mcm","clk":"11816702591","pt":1723370378331,"mc":[{"id":"1.231581430","rc":[{"batb":[[0,1.97,18.57],[1,1.96,60.95],[2,1.95,31.66]],"ltp":1.97,"tv":474.67,"id":169},{"batb":[[2,1.9,11.22]],"ltp":2.0,"tv":17.16,"id":31377}]}]}
{"op":"mcm","clk":"11816702647","pt":1723370378800,"mc":[{"id":"1.231581430","rc":[{"batb":[[0,1.96,60.95],[1,1.95,31.66],[2,1.9,100]],"ltp":1.97,"tv":474.67,"id":169}]}]}
{"op":"mcm","clk":"11816703067","pt":1723370383416,"mc":[{"id":"1.231581430","rc":[{"batb":[[0,1.98,79.67],[1,1.96,60.95],[2,1.95,31.66]],"ltp":1.97,"tv":474.67,"id":169},{"batb":[[2,1.94,83.06]],"ltp":2.0,"tv":17.16,"id":31377}]}]}
{"op":"mcm","clk":"11816703322","pt":1723370385853,"mc":[{"id":"1.231581430","rc":[{"batb":[[1,1.97,18.57],[2,1.96,60.95]],"ltp":1.97,"tv":474.67,"id":169}]}]}
{"op":"mcm","clk":"11816703510","pt":1723370387419,"mc":[{"id":"1.231581430","rc":[{"batl":[[2,1000,0.54]],"ltp":1.97,"tv":474.67,"id":169}]}]}
{"op":"mcm","clk":"11816703628","pt":1723370388453,"mc":[{"id":"1.231581430","rc":[{"trd":[[1.98,1.46]],"batb":[[0,1.97,18.57],[1,1.96,60.95],[2,1.95,31.66]],"batl":[[2,1000,0.28]],"ltp":1.98,"tv":475.19,"id":169},{"batb":[[2,1.9,11.22]],"ltp":2.0,"tv":17.16,"id":31377}],"tv":492.35}]}
{"op":"mcm","clk":"11816703673","pt":1723370388815,"mc":[{"id":"1.231581430","rc":[{"batb":[[0,1.96,60.95],[1,1.95,31.66],[2,1.9,100]],"ltp":1.98,"tv":475.19,"id":169}]}]}
{"op":"mcm","clk":"11816704130","pt":1723370393436,"mc":[{"id":"1.231581430","rc":[{"batb":[[2,1.93,83.96]],"ltp":2.0,"tv":17.16,"id":31377}]}]}
{"op":"mcm","clk":"11816705261","pt":1723370402135,"mc":[{"id":"1.231581430","marketDefinition":{"bspMarket":false,"turnInPlayEnabled":true,"persistenceEnabled":true,"marketBaseRate":5.0,"eventId":"33477741","eventTypeId":"4","numberOfWinners":1,"bettingType":"ODDS","marketType":"MATCH_ODDS","marketTime":"2024-08-11T10:00:00.000Z","suspendTime":"2024-08-11T10:00:00.000Z","bspReconciled":false,"complete":true,"inPlay":false,"crossMatching":true,"runnersVoidable":false,"numberOfActiveRunners":2,"betDelay":0,"status":"SUSPENDED","runners":[{"status":"ACTIVE","sortPriority":1,"id":31377,"name":"Leicestershire"},{"status":"ACTIVE","sortPriority":2,"id":169,"name":"Glamorgan"}],"regulators":["MR_INT"],"countryCode":"GB","discountAllowed":true,"timezone":"GMT","openDate":"2024-08-11T10:00:00.000Z","version":6068983118,"name":"Match Odds","eventName":"Leicestershire v Glamorgan"}}]}
{"op":"mcm","clk":"11816705355","pt":1723370402789,"mc":[{"id":"1.231581430","rc":[{"batb":[[0,1.96,42.18],[1,1.95,12.7]],"ltp":1.98,"tv":475.19,"id":169},{"batb":[[0,1.93,83.96],[1,1.9,11.22],[2,1.89,75.19]],"ltp":2.0,"tv":17.16,"id":31377}]}]}
{"op":"mcm","clk":"11816705486","pt":1723370403605,"mc":[{"id":"1.231581430","rc":[{"batb":[[0,1.9,11.22],[1,1.89,75.19],[2,1.8,20]],"ltp":2.0,"tv":17.16,"id":31377}]}]}
{"op":"mcm","clk":"11816705843","pt":1723370405506,"mc":[{"id":"1.231581430","marketDefinition":{"bspMarket":false,"turnInPlayEnabled":true,"persistenceEnabled":true,"marketBaseRate":5.0,"eventId":"33477741","eventTypeId":"4","numberOfWinners":1,"bettingType":"ODDS","marketType":"MATCH_ODDS","marketTime":"2024-08-11T10:00:00.000Z","suspendTime":"2024-08-11T10:00:00.000Z","bspReconciled":false,"complete":true,"inPlay":true,"crossMatching":true,"runnersVoidable":false,"numberOfActiveRunners":2,"betDelay":5,"status":"OPEN","runners":[{"status":"ACTIVE","sortPriority":1,"id":31377,"name":"Leicestershire"},{"status":"ACTIVE","sortPriority":2,"id":169,"name":"Glamorgan"}],"regulators":["MR_INT"],"countryCode":"GB","discountAllowed":true,"timezone":"GMT","openDate":"2024-08-11T10:00:00.000Z","version":6068984066,"name":"Match Odds","eventName":"Leicestershire v Glamorgan"},"rc":[{"batb":[[0,1.8,20.1],[1,1.74,1],[2,1.7,3]],"batl":[[0,1000,0.28],[1,2,0],[2,1000,0]],"ltp":1.98,"tv":475.19,"id":169},{"batb":[[0,1.8,20],[1,1.74,1.09],[2,1.7,3]],"batl":[[0,1000,0.27],[1,3,0],[2,1000,0]],"ltp":2.0,"tv":17.16,"id":31377}]}]}
{"op":"mcm","clk":"11816707381","pt":1723370416141,"mc":[{"id":"1.231581430","rc":[{"batl":[[0,4.2,12.26],[1,1000,0.02]],"ltp":1.98,"tv":475.19,"id":169}]}]}
{"op":"mcm","clk":"11816707991","pt":1723370421233,"mc":[{"id":"1.231581430","rc":[{"batl":[[1,1000,0.12]],"ltp":1.98,"tv":475.19,"id":169},{"batl":[[0,4.3,12.33],[1,1000,0.12]],"ltp":2.0,"tv":17.16,"id":31377}]}]}
{"op":"mcm","clk":"11816710147","pt":1723370440984,"mc":[{"id":"1.231581430","rc":[{"batl":[[1,1000,0.13]],"ltp":1.98,"tv":475.19,"id":169}]}]}
{"op":"mcm","clk":"11816710352","pt":1723370443075,"mc":[{"id":"1.231581430","rc":[{"batb":[[0,1.84,20],[1,1.8,20],[2,1.74,1.09]],"ltp":2.0,"tv":17.16,"id":31377}]}]}
{"op":"mcm","clk":"11816712203","pt":1723370461471,"mc":[{"id":"1.231581430","rc":[{"batb":[[0,1.84,22.1],[1,1.8,20],[2,1.74,1]],"ltp":1.98,"tv":475.19,"id":169}]}]}
{"op":"mcm","clk":"11816713534","pt":1723370473216,"mc":[{"id":"1.231581430","rc":[{"batl":[[1,1000,0.48]],"ltp":1.98,"tv":475.19,"id":169},{"batl":[[1,1000,0.47]],"ltp":2.0,"tv":17.16,"id":31377}]}]}
{"op":"mcm","clk":"11816714033","pt":1723370478421,"mc":[{"id":"1.231581430","rc":[{"batl":[[1,1000,0.13]],"ltp":1.98,"tv":475.19,"id":169},{"batl":[[1,1000,0.12]],"ltp":2.0,"tv":17.16,"id":31377}]}]}
{"op":"mcm","clk":"11816714525","pt":1723370483424,"mc":[{"id":"1.231581430","rc":[{"trd":[[1.96,20.18]],"batb":[[0,1.84,22.01]],"batl":[[0,4.2,12.61]],"ltp":1.96,"tv":475.37,"id":169},{"batl":[[0,4.3,12.68]],"ltp":2.0,"tv":17.16,"id":31377}],"tv":492.54}]}
{"op":"mcm","clk":"11816718189","pt":1723370522383,"mc":[{"id":"1.231581430","rc":[{"batl":[[1,1000,0.48]],"ltp":1.96,"tv":475.37,"id":169},{"batl":[[1,1000,0.47]],"ltp":2.0,"tv":17.16,"id":31377}]}]}
{"op":"mcm","clk":"11816718297","pt":1723370522964,"mc":[{"id":"1.231581430","rc":[{"batl":[[1,1000,0.13]],"ltp":1.96,"tv":475.37,"id":169},{"batl":[[1,1000,0.12]],"ltp":2.0,"tv":17.16,"id":31377}]}]}
{"op":"mcm","clk":"11816718837","pt":1723370528063,"mc":[{"id":"1.231581430","rc":[{"batl":[[0,4.2,12.96]],"ltp":1.96,"tv":475.37,"id":169},{"batl":[[0,4.3,13.03]],"ltp":2.0,"tv":17.16,"id":31377}]}]}
{"op":"mcm","clk":"11816719745","pt":1723370537378,"mc":[{"id":"1.231581430","rc":[{"trd":[[1.84,7.3]],"batb":[[0,1.84,16.35]],"ltp":1.84,"tv":24.46,"id":31377}],"tv":499.83}]}
{"op":"mcm","clk":"11816720898","pt":1723370549853,"mc":[{"id":"1.231581430","rc":[{"trd":[[1.96,20.19]],"batb":[[0,1.84,22]],"ltp":1.96,"tv":475.38,"id":169},{"trd":[[2.06,0.01]],"batb":[[0,2.06,13.65],[1,1.84,16.35],[2,1.8,20]],"ltp":2.06,"tv":24.46,"id":31377}],"tv":499.85}]}
{"op":"mcm","clk":"11816721043","pt":1723370551118,"mc":[{"id":"1.231581430","rc":[{"batb":[[0,1.84,16.35],[1,1.8,20],[2,1.74,1.09]],"ltp":2.06,"tv":24.46,"id":31377}]}]}
{"op":"mcm","clk":"11816721622","pt":1723370556423,"mc":[{"id":"1.231581430","rc":[{"batb":[[0,2.1,13.43],[1,1.84,16.35],[2,1.8,20]],"ltp":2.06,"tv":24.46,"id":31377}]}]}
{"op":"mcm","clk":"11816721769","pt":1723370557729,"mc":[{"id":"1.231581430","rc":[{"batb":[[0,1.84,16.35],[1,1.8,20],[2,1.74,1.09]],"ltp":2.06,"tv":24.46,"id":31377}]}]}
{"op":"mcm","clk":"11816722737","pt":1723370566611,"mc":[{"id":"1.231581430","rc":[{"batb":[[0,2.08,13.54],[1,1.84,16.35],[2,1.8,20]],"ltp":2.06,"tv":24.46,"id":31377}]}]}
{"op":"mcm","clk":"11816722894","pt":1723370568120,"mc":[{"id":"1.231581430","rc":[{"batb":[[0,1.84,16.35],[1,1.8,20],[2,1.74,1.09]],"ltp":2.06,"tv":24.46,"id":31377}]}]}
{"op":"mcm","clk":"11816723091","pt":1723370570106,"mc":[{"id":"1.231581430","rc":[{"batl":[[0,4.2,12.61]],"ltp":1.96,"tv":475.38,"id":169},{"batl":[[0,4.3,12.68]],"ltp":2.06,"tv":24.46,"id":31377}]}]}
{"op":"mcm","clk":"11816723413","pt":1723370573119,"mc":[{"id":"1.231581430","rc":[{"batb":[[0,2.12,13.31],[1,1.84,16.35],[2,1.8,20]],"ltp":2.06,"tv":24.46,"id":31377}]}]}
{"op":"mcm","clk":"11816723548","pt":1723370574536,"mc":[{"id":"1.231581430","rc":[{"batb":[[0,1.84,16.35],[1,1.8,20],[2,1.74,1.09]],"ltp":2.06,"tv":24.46,"id":31377}]}]}
{"op":"mcm","clk":"11816723699","pt":1723370576240,"mc":[{"id":"1.231581430","rc":[{"trd":[[1.84,0.02]],"batb":[[0,1.84,21.99]],"ltp":1.84,"tv":475.4,"id":169}],"tv":499.87}]}
{"op":"mcm","clk":"11816724109","pt":1723370580733,"mc":[{"id":"1.231581430","rc":[{"batb":[[0,2.1,13.47],[1,1.84,16.35],[2,1.8,20]],"ltp":2.06,"tv":24.46,"id":31377}]}]}
{"op":"mcm","clk":"11816724273","pt":1723370582251,"mc":[{"id":"1.231581430","rc":[{"batb":[[0,1.84,16.35],[1,1.8,20],[2,1.74,1.09]],"ltp":2.06,"tv":24.46,"id":31377}]}]}
{"op":"mcm","clk":"11816724997","pt":1723370588478,"mc":[{"id":"1.231581430","rc":[{"batl":[[0,4.2,12.96]],"ltp":1.84,"tv":475.4,"id":169},{"batb":[[0,2.1,13.47],[1,1.84,16.35],[2,1.8,20]],"batl":[[0,4.3,13.03]],"ltp":2.06,"tv":24.46,"id":31377}]}]}
{"op":"mcm","clk":"11816725053","pt":1723370589058,"mc":[{"id":"1.231581430","rc":[{"batb":[[0,1.84,16.35],[1,1.8,20],[2,1.74,1.09]],"ltp":2.06,"tv":24.46,"id":31377}]}]}
{"op":"mcm","clk":"11816725864","pt":1723370595386,"mc":[{"id":"1.231581430","rc":[{"batb":[[0,2.08,13.54],[1,1.84,16.35],[2,1.8,20]],"ltp":2.06,"tv":24.46,"id":31377}]}]}
{"op":"mcm","clk":"11816726051","pt":1723370596864,"mc":[{"id":"1.231581430","rc":[{"batb":[[0,1.84,16.35],[1,1.8,20],[2,1.74,1.09]],"ltp":2.06,"tv":24.46,"id":31377}]}]}
{"op":"mcm","clk":"11816726247","pt":1723370598595,"mc":[{"id":"1.231581430","rc":[{"trd":[[1.84,7.5]],"batb":[[0,1.84,16.25]],"ltp":1.84,"tv":24.67,"id":31377}],"tv":500.07}]}
{"op":"mcm","clk":"11816727063","pt":1723370606299,"mc":[{"id":"1.231581430","rc":[{"batl":[[0,2.4,5],[1,4.3,13.03],[2,1000,0.12]],"ltp":1.84,"tv":24.67,"id":31377}]}]}
{"op":"mcm","clk":"11816727166","pt":1723370607195,"mc":[{"id":"1.231581430","rc":[{"batb":[[0,2.08,13.54],[1,1.84,16.25],[2,1.8,20]],"ltp":1.84,"tv":24.67,"id":31377}]}]}
{"op":"mcm","clk":"11816727313","pt":1723370608600,"mc":[{"id":"1.231581430","rc":[{"batb":[[0,1.84,16.25],[1,1.8,20],[2,1.74,1.09]],"ltp":1.84,"tv":24.67,"id":31377}]}]}
{"op":"mcm","clk":"11816728276","pt":1723370617686,"mc":[{"id":"1.231581430","rc":[{"batb":[[0,1.8,20],[1,1.74,1],[2,1.7,4]],"ltp":1.84,"tv":475.4,"id":169}]}]}
{"op":"mcm","clk":"11816728392","pt":1723370618813,"mc":[{"id":"1.231581430","rc":[{"batb":[[2,1.71,16.48]],"ltp":1.84,"tv":475.4,"id":169},{"batb":[[0,2.08,13.54],[1,1.84,16.25],[2,1.8,20]],"ltp":1.84,"tv":24.67,"id":31377}]}]}
{"op":"mcm","clk":"11816728570","pt":1723370620497,"mc":[{"id":"1.231581430","rc":[{"batb":[[2,1.7,4]],"ltp":1.84,"tv":475.4,"id":169},{"batb":[[0,1.84,16.25],[1,1.8,20],[2,1.74,1.09]],"ltp":1.84,"tv":24.67,"id":31377}]}]}
{"op":"mcm","clk":"11816729091","pt":1723370625394,"mc":[{"id":"1.231581430","rc":[{"batb":[[0,2.14,13.2],[1,1.84,16.25],[2,1.8,20]],"ltp":1.84,"tv":24.67,"id":31377}]}]}
{"op":"mcm","clk":"11816729155","pt":1723370625919,"mc":[{"id":"1.231581430","rc":[{"batb":[[0,1.84,16.25],[1,1.8,20],[2,1.74,1.09]],"ltp":1.84,"tv":24.67,"id":31377}]}]}
{"op":"mcm","clk":"11816730093","pt":1723370633900,"mc":[{"id":"1.231581430","rc":[{"batb":[[2,1.7,3.5]],"ltp":1.84,"tv":475.4,"id":169}]}]}
{"op":"mcm","clk":"11816730251","pt":1723370635155,"mc":[{"id":"1.231581430","rc":[{"batl":[[0,4.2,12.61]],"ltp":1.84,"tv":475.4,"id":169},{"batb":[[0,2.06,13.7],[1,1.84,16.25],[2,1.8,20]],"batl":[[1,4.3,12.68]],"ltp":1.84,"tv":24.67,"id":31377}]}]}
{"op":"mcm","clk":"11816730452","pt":1723370636730,"mc":[{"id":"1.231581430","rc":[{"batb":[[0,1.8,20],[1,1.74,1.09],[2,1.7,3.5]],"ltp":1.84,"tv":24.67,"id":31377}]}]}
{"op":"mcm","clk":"11816730873","pt":1723370640099,"mc":[{"id":"1.231581430","rc":[{"batb":[[2,1.71,16.48]],"ltp":1.84,"tv":475.4,"id":169}]}]}
{"op":"mcm","clk":"11816731522","pt":1723370645348,"mc":[{"id":"1.231581430","rc":[{"batb":[[0,2.08,13.54],[1,1.8,20],[2,1.74,1.09]],"ltp":1.84,"tv":24.67,"id":31377}]}]}
{"op":"mcm","clk":"11816731795","pt":1723370647448,"mc":[{"id":"1.231581430","rc":[{"batb":[[2,1.7,3.5]],"batl":[[1,1000,0.48]],"ltp":1.84,"tv":475.4,"id":169},{"batb":[[0,1.8,20],[1,1.74,1.09],[2,1.7,3.5]],"batl":[[2,1000,0.47]],"ltp":1.84,"tv":24.67,"id":31377}]}]}
{"op":"mcm","clk":"11816731854","pt":1723370647816,"mc":[{"id":"1.231581430","rc":[{"batl":[[1,1000,0.13]],"ltp":1.84,"tv":475.4,"id":169},{"batl":[[2,1000,0.12]],"ltp":1.84,"tv":24.67,"id":31377}]}]}
{"op":"mcm","clk":"11816732338","pt":1723370651832,"mc":[{"id":"1.231581430","rc":[{"batb":[[0,2.14,13.2],[1,1.8,20],[2,1.74,1.09]],"ltp":1.84,"tv":24.67,"id":31377}]}]}
{"op":"mcm","clk":"11816732490","pt":1723370652932,"mc":[{"id":"1.231581430","rc":[{"batb":[[2,1.7,3.98]],"batl":[[0,4.2,12.96]],"ltp":1.84,"tv":475.4,"id":169},{"batb":[[0,1.8,20],[1,1.74,1.09],[2,1.7,3.98]],"batl":[[0,2.4,5.35]],"ltp":1.84,"tv":24.67,"id":31377}]}]}
{"op":"mcm","clk":"11816732937","pt":1723370656739,"mc":[{"id":"1.231581430","rc":[{"batb":[[0,2.08,12],[1,1.8,20],[2,1.74,1.09]],"ltp":1.84,"tv":24.67,"id":31377}]}]}
{"op":"mcm","clk":"11816733715","pt":1723370663157,"mc":[{"id":"1.231581430","rc":[{"batb":[[0,2.14,13.16],[1,2.08,12],[2,1.8,20]],"ltp":1.84,"tv":24.67,"id":31377}]}]}
{"op":"mcm","clk":"11816733879","pt":1723370664677,"mc":[{"id":"1.231581430","rc":[{"batb":[[0,2.08,12],[1,1.8,20],[2,1.74,1.09]],"ltp":1.84,"tv":24.67,"id":31377}]}]}
{"op":"mcm","clk":"11816734251","pt":1723370668166,"mc":[{"id":"1.231581430","rc":[{"batb":[[0,2.1,10.5],[1,2.08,12],[2,1.8,20]],"ltp":1.84,"tv":24.67,"id":31377}]}]}
{"op":"mcm","clk":"11816734543","pt":1723370670947,"mc":[{"id":"1.231581430","rc":[{"batb":[[0,2.14,13.16],[1,2.1,10.5],[2,2.08,12]],"ltp":1.84,"tv":24.67,"id":31377}]}]}
{"op":"mcm","clk":"11816734715","pt":1723370672379,"mc":[{"id":"1.231581430","rc":[{"batb":[[0,2.1,10.5],[1,2.08,12],[2,1.8,20]],"ltp":1.84,"tv":24.67,"id":31377}]}]}
{"op":"mcm","clk":"11816735940","pt":1723370684160,"mc":[{"id":"1.231581430","rc":[{"trd":[[2.08,24],[2.1,21]],"batb":[[0,1.8,20],[1,1.74,1.09],[2,1.7,3.98]],"batl":[[0,2.08,177.5],[1,2.4,5.35],[2,4.3,12.68]],"ltp":2.08,"tv":69.67,"id":31377}],"tv":545.07}]}
{"op":"mcm","clk":"11816736595","pt":1723370690775,"mc":[{"id":"1.231581430","rc":[{"batb":[[2,1.72,16.91]],"ltp":1.84,"tv":475.4,"id":169},{"trd":[[2.08,51.16]],"batl":[[0,2.08,163.92]],"ltp":2.08,"tv":96.83,"id":31377}],"tv":572.24}]}
{"op":"mcm","clk":"11816737291","pt":1723370697287,"mc":[{"id":"1.231581430","rc":[{"trd":[[2.08,78.33]],"batl":[[0,2.08,150.34]],"ltp":2.08,"tv":124.0,"id":31377}],"tv":599.4}]}
{"op":"mcm","clk":"11816737485","pt":1723370699214,"mc":[{"id":"1.231581430","rc":[{"batb":[[2,1.7,3.98]],"ltp":1.84,"tv":475.4,"id":169}]}]}
{"op":"mcm","clk":"11816737856","pt":1723370702689,"mc":[{"id":"1.231581430","rc":[{"trd":[[2.08,105.41]],"batl":[[0,2.08,136.8]],"ltp":2.08,"tv":151.08,"id":31377}],"tv":626.48}]}
{"op":"mcm","clk":"11816738090","pt":1723370704738,"mc":[{"id":"1.231581430","rc":[{"batb":[[0,1.86,180.32],[1,1.8,20],[2,1.74,1.09]],"ltp":2.08,"tv":151.08,"id":31377}]}]}
{"op":"mcm","clk":"11816738477","pt":1723370708002,"mc":[{"id":"1.231581430","rc":[{"batb":[[1,1.76,16.04],[2,1.74,1]],"ltp":1.84,"tv":475.4,"id":169},{"batb":[[0,2.02,13.98],[1,1.86,180.32],[2,1.8,20]],"ltp":2.08,"tv":151.08,"id":31377}]}]}
{"op":"mcm","clk":"11816738645","pt":1723370709606,"mc":[{"id":"1.231581430","rc":[{"batb":[[1,1.74,1],[2,1.7,3.98]],"ltp":1.84,"tv":475.4,"id":169},{"batb":[[0,1.86,180.32],[1,1.8,20],[2,1.74,1.09]],"ltp":2.08,"tv":151.08,"id":31377}]}]}
{"op":"mcm","clk":"11816739366","pt":1723370715929,"mc":[{"id":"1.231581430","rc":[{"batb":[[1,1.77,15.93],[2,1.74,1]],"ltp":1.84,"tv":475.4,"id":169},{"batb":[[0,2,14.09],[1,1.86,180.32],[2,1.8,20]],"ltp":2.08,"tv":151.08,"id":31377}]}]}
{"op":"mcm","clk":"11816739518","pt":1723370717136,"mc":[{"id":"1.231581430","rc":[{"batl":[[0,4.2,12.61]],"ltp":1.84,"tv":475.4,"id":169},{"batl":[[2,4.3,12.33]],"ltp":2.08,"tv":151.08,"id":31377}]}]}
{"op":"mcm","clk":"11816739624","pt":1723370718029,"mc":[{"id":"1.231581430","rc":[{"batb":[[1,1.74,1],[2,1.7,3.48]],"ltp":1.84,"tv":475.4,"id":169},{"batb":[[0,1.86,180.32],[1,1.8,20],[2,1.74,1.09]],"ltp":2.08,"tv":151.08,"id":31377}]}]}
{"op":"mcm","clk":"11816739926","pt":1723370720509,"mc":[{"id":"1.231581430","rc":[{"trd":[[2.08,379.01]],"batb":[[0,2.08,63.2],[1,1.86,180.32],[2,1.8,20]],"batl":[[0,2.4,5.35],[1,4.3,12.33],[2,1000,0.12]],"ltp":2.08,"tv":424.68,"id":31377}],"tv":900.08}]}
{"op":"mcm","clk":"11816740377","pt":1723370724235,"mc":[{"id":"1.231581430","rc":[{"batb":[[1,1.77,15.93],[2,1.74,1]],"ltp":1.84,"tv":475.4,"id":169},{"batb":[[0,2,14.09]],"ltp":2.08,"tv":424.68,"id":31377}]}]}
{"op":"mcm","clk":"11816740430","pt":1723370724650,"mc":[{"id":"1.231581430","rc":[{"batb":[[1,1.74,1],[2,1.7,3.48]],"ltp":1.84,"tv":475.4,"id":169},{"batb":[[0,1.86,180.32],[1,1.8,20],[2,1.74,1.09]],"ltp":2.08,"tv":424.68,"id":31377}]}]}
{"op":"mcm","clk":"11816741678","pt":1723370735379,"mc":[{"id":"1.231581430","rc":[{"trd":[[1.86,0.2]],"batb":[[0,1.86,180.22]],"ltp":1.86,"tv":424.87,"id":31377}],"tv":900.28}]}
{"op":"mcm","clk":"11816743426","pt":1723370750485,"mc":[{"id":"1.231581430","rc":[{"batl":[[0,4.2,12.96]],"ltp":1.84,"tv":475.4,"id":169},{"batl":[[1,4.3,12.68]],"ltp":1.86,"tv":424.87,"id":31377}]}]}
{"op":"mcm","clk":"11816746719","pt":1723370775453,"mc":[{"id":"1.231581430","rc":[{"batl":[[0,2,5],[1,4.2,12.96],[2,1000,0.13]],"ltp":1.84,"tv":475.4,"id":169}]}]}
{"op":"mcm","clk":"11816747792","pt":1723370783457,"mc":[{"id":"1.231581430","rc":[{"batb":[[0,1.88,18.04],[1,1.86,180.22],[2,1.8,20]],"ltp":1.86,"tv":424.87,"id":31377}]}]}
{"op":"mcm","clk":"11816748399","pt":1723370787836,"mc":[{"id":"1.231581430","rc":[{"batl":[[0,4.2,12.61],[1,1000,0.13],[2,1000,0]],"ltp":1.84,"tv":475.4,"id":169},{"batl":[[0,2.4,5]],"ltp":1.86,"tv":424.87,"id":31377}]}]}
{"op":"mcm","clk":"11816748672","pt":1723370789947,"mc":[{"id":"1.231581430","rc":[{"batb":[[2,1.7,3]],"ltp":1.84,"tv":475.4,"id":169}]}]}
{"op":"mcm","clk":"11816749040","pt":1723370792945,"mc":[{"id":"1.231581430","rc":[{"batl":[[0,1.97,5],[1,4.2,12.61],[2,1000,0.13]],"ltp":1.84,"tv":475.4,"id":169}]}]}
{"op":"mcm","clk":"11816749892","pt":1723370800080,"mc":[{"id":"1.231581430","rc":[{"batb":[[0,1.81,18.04],[1,1.8,20],[2,1.74,1]],"ltp":1.84,"tv":475.4,"id":169}]}]}
{"op":"mcm","clk":"11816750781","pt":1723370807383,"mc":[{"id":"1.231581430","rc":[{"batb":[[0,2.06,13.66],[1,1.88,18.04],[2,1.86,180.22]],"ltp":1.86,"tv":424.87,"id":31377}]}]}
{"op":"mcm","clk":"11816750963","pt":1723370808894,"mc":[{"id":"1.231581430","rc":[{"batl":[[0,4.2,12.61],[1,1000,0.13],[2,1000,0]],"ltp":1.84,"tv":475.4,"id":169}]}]}
{"op":"mcm","clk":"11816751380","pt":1723370812505,"mc":[{"id":"1.231581430","rc":[{"batb":[[0,1.8,20],[1,1.74,1],[2,1.72,16.36]],"batl":[[0,4.2,12.96]],"ltp":1.84,"tv":475.4,"id":169},{"batb":[[1,1.86,180.22],[2,1.8,20]],"batl":[[1,4.3,13.03]],"ltp":1.86,"tv":424.87,"id":31377}]}]}
{"op":"mcm","clk":"11816751554","pt":1723370813977,"mc":[{"id":"1.231581430","rc":[{"batl":[[0,1.92,5],[1,4.2,12.96],[2,1000,0.13]],"ltp":1.84,"tv":475.4,"id":169}]}]}
{"op":"mcm","clk":"11816753495","pt":1723370828894,"mc":[{"id":"1.231581430","rc":[{"batl":[[0,4.2,12.96],[1,1000,0.13],[2,1000,0]],"ltp":1.84,"tv":475.4,"id":169}]}]}
{"op":"mcm","clk":"11816753788","pt":1723370831385,"mc":[{"id":"1.231581430","rc":[{"batl":[[1,4.3,12.68]],"ltp":1.86,"tv":424.87,"id":31377}]}]}
{"op":"mcm","clk":"11816753919","pt":1723370832394,"mc":[{"id":"1.231581430","rc":[{"batl":[[0,4.2,12.61]],"ltp":1.84,"tv":475.4,"id":169}]}]}
{"op":"mcm","clk":"11816754122","pt":1723370833983,"mc":[{"id":"1.231581430","rc":[{"batb":[[2,1.7,3]],"batl":[[0,1.86,5],[1,4.2,12.61],[2,1000,0.13]],"ltp":1.84,"tv":475.4,"id":169},{"batb":[[0,1.86,180.22],[1,1.8,20],[2,1.74,1.09]],"ltp":1.86,"tv":424.87,"id":31377}]}]}
{"op":"mcm","clk":"11816755677","pt":1723370846153,"mc":[{"id":"1.231581430","rc":[{"batl":[[0,4.2,12.61],[1,1000,0.13],[2,1000,0]],"ltp":1.84,"tv":475.4,"id":169}]}]}
{"op":"mcm","clk":"11816755811","pt":1723370847427,"mc":[{"id":"1.231581430","rc":[{"batb":[[0,1.8,20.91]],"ltp":1.84,"tv":475.4,"id":169}]}]}
{"op":"mcm","clk":"11816756295","pt":1723370851252,"mc":[{"id":"1.231581430","rc":[{"trd":[[1.81,1.82]],"batb":[[0,1.8,20]],"batl":[[0,1.81,4.09],[1,4.2,12.61],[2,1000,0.13]],"ltp":1.81,"tv":477.22,"id":169}],"tv":902.1}]}
{"op":"mcm","clk":"11816756735","pt":1723370854994,"mc":[{"id":"1.231581430","rc":[{"batl":[[1,4.2,12.96]],"ltp":1.81,"tv":477.22,"id":169},{"batl":[[1,4.3,13.03]],"ltp":1.86,"tv":424.87,"id":31377}]}]}
{"op":"mcm","clk":"11816757250","pt":1723370859443,"mc":[{"id":"1.231581430","rc":[{"batb":[[0,1.8,20],[1,1.74,1.09],[2,1.7,3.97]],"ltp":1.86,"tv":424.87,"id":31377}]}]}
{"op":"mcm","clk":"11816757629","pt":1723370862348,"mc":[{"id":"1.231581430","rc":[{"trd":[[1.8,11.51]],"batb":[[0,1.8,8.49]],"ltp":1.8,"tv":488.73,"id":169},{"trd":[[2.26,9.17]],"ltp":2.26,"tv":434.04,"id":31377}],"tv":922.78}]}
{"op":"mcm","clk":"11816757913","pt":1723370864557,"mc":[{"id":"1.231581430","rc":[{"batb":[[0,1.87,180.22],[1,1.8,20],[2,1.74,1.09]],"ltp":2.26,"tv":434.04,"id":31377}]}]}
{"op":"mcm","clk":"11816758890","pt":1723370872920,"mc":[{"id":"1.231581430","rc":[{"batl":[[0,4.2,12.96],[1,1000,0.13],[2,1000,0]],"ltp":1.8,"tv":488.73,"id":169}]}]}
{"op":"mcm","clk":"11816759427","pt":1723370878074,"mc":[{"id":"1.231581430","rc":[{"trd":[[1.8,19.69]],"batb":[[0,1.8,4.4]],"ltp":1.8,"tv":496.91,"id":169}],"tv":930.96}]}
{"op":"mcm","clk":"11816759583","pt":1723370879663,"mc":[{"id":"1.231581430","rc":[{"batb":[[0,2.12,13.27],[1,1.87,180.22],[2,1.8,20]],"ltp":2.26,"tv":434.04,"id":31377}]}]}
{"op":"mcm","clk":"11816760555","pt":1723370888152,"mc":[{"id":"1.231581430","rc":[{"batl":[[0,4.2,12.61]],"ltp":1.8,"tv":496.91,"id":169},{"batl":[[1,4.3,12.68]],"ltp":2.26,"tv":434.04,"id":31377}]}]}
{"op":"mcm","clk":"11816760943","pt":1723370891666,"mc":[{"id":"1.231581430","rc":[{"batb":[[1,1.87,181.06]],"ltp":2.26,"tv":434.04,"id":31377}]}]}
{"op":"mcm","clk":"11816761785","pt":1723370899260,"mc":[{"id":"1.231581430","rc":[{"batb":[[0,1.84,4.51],[1,1.8,4.4],[2,1.74,1]],"ltp":1.8,"tv":496.91,"id":169},{"batb":[[0,1.87,181.06],[1,1.8,20],[2,1.74,1.09]],"ltp":2.26,"tv":434.04,"id":31377}]}]}
{"op":"mcm","clk":"11816761913","pt":1723370900362,"mc":[{"id":"1.231581430","rc":[{"batl":[[1,1000,0.48]],"ltp":1.8,"tv":496.91,"id":169},{"batl":[[2,1000,0.47]],"ltp":2.26,"tv":434.04,"id":31377}]}]}
{"op":"mcm","clk":"11816761991","pt":1723370900880,"mc":[{"id":"1.231581430","rc":[{"batl":[[1,1000,0.13]],"ltp":1.8,"tv":496.91,"id":169},{"batl":[[2,1000,0.12]],"ltp":2.26,"tv":434.04,"id":31377}]}]}
{"op":"mcm","clk":"11816762644","pt":1723370905973,"mc":[{"id":"1.231581430","rc":[{"batl":[[0,4.2,12.96]],"ltp":1.8,"tv":496.91,"id":169},{"batb":[[0,2.1,13.43],[1,1.87,181.06],[2,1.8,20]],"batl":[[1,4.3,13.03]],"ltp":2.26,"tv":434.04,"id":31377}]}]}
{"op":"mcm","clk":"11816762834","pt":1723370907400,"mc":[{"id":"1.231581430","rc":[{"batb":[[0,1.87,181.06],[1,1.8,20],[2,1.74,1.09]],"ltp":2.26,"tv":434.04,"id":31377}]}]}
{"op":"mcm","clk":"11816764442","pt":1723370920706,"mc":[{"id":"1.231581430","rc":[{"batb":[[0,2.1,13.43],[1,1.87,181.06],[2,1.8,20]],"ltp":2.26,"tv":434.04,"id":31377}]}]}
{"op":"mcm","clk":"11816764675","pt":1723370922395,"mc":[{"id":"1.231581430","rc":[{"batb":[[0,1.87,181.06],[1,1.8,20],[2,1.74,1.09]],"ltp":2.26,"tv":434.04,"id":31377}]}]}
{"op":"mcm","clk":"11816766354","pt":1723370933602,"mc":[{"id":"1.231581430","rc":[{"batb":[[0,1.8,4.4],[1,1.74,1],[2,1.7,3]],"ltp":1.8,"tv":496.91,"id":169}]}]}
{"op":"mcm","clk":"11816766612","pt":1723370935804,"mc":[{"id":"1.231581430","rc":[{"batb":[[2,1.7,19.59]],"ltp":1.8,"tv":496.91,"id":169},{"batb":[[0,2.1,13.43],[1,1.87,181.06],[2,1.8,20]],"ltp":2.26,"tv":434.04,"id":31377}]}]}
{"op":"mcm","clk":"11816767112","pt":1723370939990,"mc":[{"id":"1.231581430","rc":[{"batb":[[1,1.87,181.16]],"ltp":2.26,"tv":434.04,"id":31377}]}]}
{"op":"mcm","clk":"11816767439","pt":1723370942308,"mc":[{"id":"1.231581430","rc":[{"batl":[[0,4.2,12.61]],"ltp":1.8,"tv":496.91,"id":169},{"batl":[[1,4.3,12.68]],"ltp":2.26,"tv":434.04,"id":31377}]}]}
{"op":"mcm","clk":"11816768465","pt":1723370950240,"mc":[{"id":"1.231581430","rc":[{"batb":[[2,1.7,3]],"ltp":1.8,"tv":496.91,"id":169}]}]}
{"op":"mcm","clk":"11816769994","pt":1723370961447,"mc":[{"id":"1.231581430","rc":[{"trd":[[1.91,9.02]],"batl":[[0,4.2,12.96]],"ltp":1.91,"tv":505.93,"id":169},{"trd":[[2.1,29.21]],"batb":[[0,2.1,5.22]],"batl":[[1,4.3,13.03]],"ltp":2.1,"tv":442.25,"id":31377}],"tv":948.19}]}
{"op":"mcm","clk":"11816770089","pt":1723370962035,"mc":[{"id":"1.231581430","rc":[{"trd":[[1.8,19.73]],"batb":[[0,1.8,4.38]],"ltp":1.8,"tv":505.97,"id":169}],"tv":948.23}]}
{"op":"mcm","clk":"11816770397","pt":1723370964346,"mc":[{"id":"1.231581430","rc":[{"batb":[[0,1.8,5.29]],"ltp":1.8,"tv":505.97,"id":169}]}]}
{"op":"mcm","clk":"11816771371","pt":1723370971879,"mc":[{"id":"1.231581430","rc":[{"batb":[[0,2.12,8.04],[1,2.1,5.22],[2,1.87,181.16]],"ltp":2.1,"tv":442.25,"id":31377}]}]}
{"op":"mcm","clk":"11816771472","pt":1723370972678,"mc":[{"id":"1.231581430","rc":[{"batb":[[1,1.87,181.16],[2,1.8,20]],"ltp":2.1,"tv":442.25,"id":31377}]}]}
{"op":"mcm","clk":"11816772100","pt":1723370977636,"mc":[{"id":"1.231581430","rc":[{"batb":[[0,2.14,5.15],[1,2.12,8.04],[2,1.87,181.16]],"ltp":2.1,"tv":442.25,"id":31377}]}]}
{"op":"mcm","clk":"11816772307","pt":1723370979373,"mc":[{"id":"1.231581430","rc":[{"batb":[[0,1.87,181.16],[1,1.8,20],[2,1.74,1.09]],"ltp":2.1,"tv":442.25,"id":31377}]}]}
{"op":"mcm","clk":"11816773151","pt":1723370985645,"mc":[{"id":"1.231581430","rc":[{"batb":[[2,1.7,19.59]],"ltp":1.8,"tv":505.97,"id":169},{"batb":[[0,2.1,13.43],[1,1.87,181.16],[2,1.8,20]],"ltp":2.1,"tv":442.25,"id":31377}]}]}
{"op":"mcm","clk":"11816773374","pt":1723370987230,"mc":[{"id":"1.231581430","rc":[{"batb":[[2,1.7,3]],"ltp":1.8,"tv":505.97,"id":169},{"batb":[[0,1.87,181.16],[1,1.8,20],[2,1.74,1.09]],"ltp":2.1,"tv":442.25,"id":31377}]}]}
{"op":"mcm","clk":"11816774922","pt":1723370998969,"mc":[{"id":"1.231581430","rc":[{"batb":[[2,1.72,16.43]],"ltp":1.8,"tv":505.97,"id":169},{"batb":[[0,2.08,13.58],[1,1.87,181.16],[2,1.8,20]],"ltp":2.1,"tv":442.25,"id":31377}]}]}
{"op":"mcm","clk":"11816775514","pt":1723371003410,"mc":[{"id":"1.231581430","rc":[{"batb":[[2,1.7,3]],"ltp":1.8,"tv":505.97,"id":169},{"batb":[[0,1.87,181.16],[1,1.8,20],[2,1.74,1.09]],"ltp":2.1,"tv":442.25,"id":31377}]}]}
{"op":"mcm","clk":"11816776231","pt":1723371008368,"mc":[{"id":"1.231581430","rc":[{"batb":[[1,1.74,17.2]],"ltp":1.8,"tv":505.97,"id":169},{"batb":[[0,2.04,13.82],[1,1.87,181.16],[2,1.8,20]],"ltp":2.1,"tv":442.25,"id":31377}]}]}
{"op":"mcm","clk":"11816776292","pt":1723371008901,"mc":[{"id":"1.231581430","rc":[{"batb":[[1,1.74,1]],"ltp":1.8,"tv":505.97,"id":169},{"batb":[[0,1.87,181.16],[1,1.8,20],[2,1.74,1.09]],"ltp":2.1,"tv":442.25,"id":31377}]}]}
{"op":"mcm","clk":"11816776530","pt":1723371010796,"mc":[{"id":"1.231581430","rc":[{"batb":[[0,1.96,10.5],[1,1.87,181.16],[2,1.8,20]],"ltp":2.1,"tv":442.25,"id":31377}]}]}
{"op":"mcm","clk":"11816778481","pt":1723371025421,"mc":[{"id":"1.231581430","rc":[{"batb":[[1,1.87,180.32]],"ltp":2.1,"tv":442.25,"id":31377}]}]}
{"op":"mcm","clk":"11816778693","pt":1723371026800,"mc":[{"id":"1.231581430","rc":[{"batb":[[2,1.7,19.59]],"ltp":1.8,"tv":505.97,"id":169},{"batb":[[0,2.1,13.43]],"ltp":2.1,"tv":442.25,"id":31377}]}]}
{"op":"mcm","clk":"11816779048","pt":1723371029273,"mc":[{"id":"1.231581430","rc":[{"batl":[[1,4.3,12.68]],"ltp":2.1,"tv":442.25,"id":31377}]}]}
{"op":"mcm","clk":"11816779196","pt":1723371030420,"mc":[{"id":"1.231581430","rc":[{"batl":[[0,4.2,12.61]],"ltp":1.8,"tv":505.97,"id":169}]}]}
{"op":"mcm","clk":"11816779226","pt":1723371030632,"mc":[{"id":"1.231581430","rc":[{"batb":[[1,1.87,181.16]],"ltp":2.1,"tv":442.25,"id":31377}]}]}
{"op":"mcm","clk":"11816779390","pt":1723371031837,"mc":[{"id":"1.231581430","rc":[{"batb":[[0,2.12,10.5],[1,2.1,13.43],[2,1.87,181.16]],"ltp":2.1,"tv":442.25,"id":31377}]}]}
{"op":"mcm","clk":"11816780083","pt":1723371036942,"mc":[{"id":"1.231581430","rc":[{"batb":[[2,1.7,3]],"ltp":1.8,"tv":505.97,"id":169},{"batb":[[1,1.87,181.16],[2,1.8,20]],"ltp":2.1,"tv":442.25,"id":31377}]}]}
{"op":"mcm","clk":"11816780645","pt":1723371041799,"mc":[{"id":"1.231581430","rc":[{"batb":[[2,1.73,16.31]],"ltp":1.8,"tv":505.97,"id":169},{"batb":[[1,2.06,13.7],[2,1.87,181.16]],"ltp":2.1,"tv":442.25,"id":31377}]}]}
{"op":"mcm","clk":"11816781132","pt":1723371045493,"mc":[{"id":"1.231581430","rc":[{"batb":[[2,1.7,3]],"ltp":1.8,"tv":505.97,"id":169},{"batb":[[1,1.8,20.94],[2,1.74,1.09]],"ltp":2.1,"tv":442.25,"id":31377}]}]}
{"op":"mcm","clk":"11816783609","pt":1723371065448,"mc":[{"id":"1.231581430","rc":[{"batb":[[1,1.8,20.1]],"ltp":2.1,"tv":442.25,"id":31377}]}]}
{"op":"mcm","clk":"11816783734","pt":1723371066508,"mc":[{"id":"1.231581430","rc":[{"batl":[[0,2.24,250],[1,2.4,5],[2,4.3,12.68]],"ltp":2.1,"tv":442.25,"id":31377}]}]}
{"op":"mcm","clk":"11816783856","pt":1723371067510,"mc":[{"id":"1.231581430","rc":[{"batl":[[0,4.2,12.96]],"ltp":1.8,"tv":505.97,"id":169},{"batl":[[2,4.3,13.03]],"ltp":2.1,"tv":442.25,"id":31377}]}]}
{"op":"mcm","clk":"11816783963","pt":1723371068449,"mc":[{"id":"1.231581430","rc":[{"batb":[[0,1.8,4.38]],"ltp":1.8,"tv":505.97,"id":169}]}]}
{"op":"mcm","clk":"11816786049","pt":1723371085372,"mc":[{"id":"1.231581430","rc":[{"batl":[[0,2.4,1.58],[1,4.2,12.26],[2,1000,0.13]],"ltp":1.8,"tv":505.97,"id":169}]}]}
{"op":"mcm","clk":"11816786102","pt":1723371085793,"mc":[{"id":"1.231581430","rc":[{"batb":[[0,1.8,20.1],[1,1.74,1.09],[2,1.7,3.96]],"ltp":2.1,"tv":442.25,"id":31377}]}]}
{"op":"mcm","clk":"11816786560","pt":1723371089466,"mc":[{"id":"1.231581430","rc":[{"batl":[[0,2.4,5],[1,4.3,13.03],[2,1000,0.12]],"ltp":2.1,"tv":442.25,"id":31377}]}]}
{"op":"mcm","clk":"11816786725","pt":1723371090782,"mc":[{"id":"1.231581430","rc":[{"batb":[[0,2.16,10.5],[1,1.8,20.1],[2,1.74,1.09]],"ltp":2.1,"tv":442.25,"id":31377}]}]}
{"op":"mcm","clk":"11816787206","pt":1723371094575,"mc":[{"id":"1.231581430","rc":[{"batl":[[0,2.22,250],[1,2.4,5],[2,4.3,13.03]],"ltp":2.1,"tv":442.25,"id":31377}]}]}
{"op":"mcm","clk":"11816788394","pt":1723371104391,"mc":[{"id":"1.231581430","rc":[{"batl":[[0,4.2,12.96],[1,1000,0.13],[2,1000,0]],"ltp":1.8,"tv":505.97,"id":169}]}]}
{"op":"mcm","clk":"11816788874","pt":1723371108543,"mc":[{"id":"1.231581430","rc":[{"batl":[[0,2.4,5],[1,4.3,13.03],[2,1000,0.12]],"ltp":2.1,"tv":442.25,"id":31377}]}]}
{"op":"mcm","clk":"11816788987","pt":1723371109530,"mc":[{"id":"1.231581430","rc":[{"batl":[[0,2.4,1.59],[1,4.2,12.26],[2,1000,0.13]],"ltp":1.8,"tv":505.97,"id":169}]}]}
{"op":"mcm","clk":"11816789172","pt":1723371111048,"mc":[{"id":"1.231581430","rc":[{"batb":[[0,1.8,20.1],[1,1.74,1.09],[2,1.7,3.96]],"ltp":2.1,"tv":442.25,"id":31377}]}]}
{"op":"mcm","clk":"11816789499","pt":1723371113683,"mc":[{"id":"1.231581430","rc":[{"batl":[[0,2.2,250],[1,2.4,5],[2,4.3,13.03]],"ltp":2.1,"tv":442.25,"id":31377}]}]}
{"op":"mcm","clk":"11816790073","pt":1723371118068,"mc":[{"id":"1.231581430","rc":[{"batl":[[0,2.4,1.24]],"ltp":1.8,"tv":505.97,"id":169},{"batl":[[2,4.3,12.68]],"ltp":2.1,"tv":442.25,"id":31377}]}]}
{"op":"mcm","clk":"11816790215","pt":1723371119083,"mc":[{"id":"1.231581430","rc":[{"batb":[[2,1.7,3.48]],"ltp":2.1,"tv":442.25,"id":31377}]}]}
{"op":"mcm","clk":"11816790391","pt":1723371120274,"mc":[{"id":"1.231581430","rc":[{"batl":[[0,2.4,5],[1,4.3,12.68],[2,1000,0.12]],"ltp":2.1,"tv":442.25,"id":31377}]}]}
{"op":"mcm","clk":"11816792994","pt":1723371141502,"mc":[{"id":"1.231581430","rc":[{"batb":[[1,1.79,15.76],[2,1.74,1]],"ltp":1.8,"tv":505.97,"id":169},{"batb":[[0,1.98,14.25],[1,1.8,20.1],[2,1.74,1.09]],"ltp":2.1,"tv":442.25,"id":31377}]}]}
{"op":"mcm","clk":"11816793092","pt":1723371142392,"mc":[{"id":"1.231581430","rc":[{"batl":[[0,2.4,1.59]],"ltp":1.8,"tv":505.97,"id":169},{"batl":[[0,2.4,5.35]],"ltp":2.1,"tv":442.25,"id":31377}]}]}
{"op":"mcm","clk":"11816793205","pt":1723371143284,"mc":[{"id":"1.231581430","rc":[{"batb":[[1,1.74,1],[2,1.7,3.48]],"ltp":1.8,"tv":505.97,"id":169},{"batb":[[0,1.8,20.1],[1,1.74,1.09],[2,1.7,3.96]],"ltp":2.1,"tv":442.25,"id":31377}]}]}
{"op":"mcm","clk":"11816793817","pt":1723371148225,"mc":[{"id":"1.231581430","rc":[{"batb":[[1,1.76,16.04],[2,1.74,1]],"ltp":1.8,"tv":505.97,"id":169},{"batb":[[0,2.02,13.98],[1,1.8,20.1],[2,1.74,1.09]],"ltp":2.1,"tv":442.25,"id":31377}]}]}
{"op":"mcm","clk":"11816794590","pt":1723371154600,"mc":[{"id":"1.231581430","rc":[{"batl":[[0,2.1,2.69],[1,4.2,12.96]],"ltp":1.8,"tv":505.97,"id":169}]}]}
{"op":"mcm","clk":"11816795341","pt":1723371160750,"mc":[{"id":"1.231581430","rc":[{"batb":[[1,1.74,1],[2,1.7,3.48]],"ltp":1.8,"tv":505.97,"id":169},{"batb":[[0,1.8,20.1],[1,1.74,1.09],[2,1.7,3.96]],"ltp":2.1,"tv":442.25,"id":31377}]}]}
{"op":"mcm","clk":"11816796061","pt":1723371166927,"mc":[{"id":"1.231581430","rc":[{"batl":[[1,4.2,12.61]],"ltp":1.8,"tv":505.97,"id":169},{"batl":[[1,4.3,12.33]],"ltp":2.1,"tv":442.25,"id":31377}]}]}
{"op":"mcm","clk":"11816796239","pt":1723371168445,"mc":[{"id":"1.231581430","rc":[{"batb":[[2,1.7,3.48]],"ltp":2.1,"tv":442.25,"id":31377}]}]}
{"op":"mcm","clk":"11816796379","pt":1723371169646,"mc":[{"id":"1.231581430","rc":[{"batb":[[0,2.18,9.79],[1,1.8,20.1],[2,1.74,1.09]],"ltp":2.1,"tv":442.25,"id":31377}]}]}
{"op":"mcm","clk":"11816796860","pt":1723371173455,"mc":[{"id":"1.231581430","rc":[{"batb":[[1,1.78,15.88],[2,1.74,1]],"ltp":1.8,"tv":505.97,"id":169},{"batb":[[1,2,14.13],[2,1.8,20.1]],"ltp":2.1,"tv":442.25,"id":31377}]}]}
{"op":"mcm","clk":"11816796909","pt":1723371173837,"mc":[{"id":"1.231581430","rc":[{"batb":[[1,1.74,1],[2,1.7,3.48]],"ltp":1.8,"tv":505.97,"id":169},{"batb":[[1,1.8,20.1],[2,1.74,1.09]],"ltp":2.1,"tv":442.25,"id":31377}]}]}
{"op":"mcm","clk":"11816808956","pt":1723371181430,"mc":[{"id":"1.231581430","rc":[{"trd":[[1.85,0.1]],"ltp":1.85,"tv":506.07,"id":169},{"trd":[[2.18,0.09]],"batb":[[0,2.18,9.7]],"ltp":2.18,"tv":442.34,"id":31377}],"tv":948.42}]}
{"op":"mcm","clk":"11816809586","pt":1723371186367,"mc":[{"id":"1.231581430","rc":[{"batl":[[1,4.2,12.96]],"ltp":1.85,"tv":506.07,"id":169},{"batl":[[1,4.3,12.68]],"ltp":2.18,"tv":442.34,"id":31377}]}]}
{"op":"mcm","clk":"11816812810","pt":1723371211327,"mc":[{"id":"1.231581430","rc":[{"batb":[[2,1.7,3]],"batl":[[1,4.2,12.61]],"ltp":1.85,"tv":506.07,"id":169}]}]}
{"op":"mcm","clk":"11816812936","pt":1723371212186,"mc":[{"id":"1.231581430","rc":[{"batl":[[0,2.4,5]],"ltp":2.18,"tv":442.34,"id":31377}]}]}
{"op":"mcm","clk":"11816814856","pt":1723371227804,"mc":[{"id":"1.231581430","rc":[{"batl":[[1,4.2,12.96]],"ltp":1.85,"tv":506.07,"id":169},{"trd":[[2.18,19.49]],"batb":[[0,1.8,20.1],[1,1.74,1.09],[2,1.7,3.96]],"batl":[[0,2.18,40.3],[1,2.4,5],[2,4.3,13.03]],"ltp":2.18,"tv":461.74,"id":31377}],"tv":967.82}]}
{"op":"mcm","clk":"11816815771","pt":1723371234827,"mc":[{"id":"1.231581430","rc":[{"batb":[[0,1.85,15.25],[1,1.8,4.38],[2,1.74,1]],"ltp":1.85,"tv":506.07,"id":169},{"batb":[[0,1.91,14.77],[1,1.8,20.1],[2,1.74,1.09]],"ltp":2.18,"tv":461.74,"id":31377}]}]}
{"op":"mcm","clk":"11816816018","pt":1723371236620,"mc":[{"id":"1.231581430","rc":[{"batb":[[0,1.8,4.38],[1,1.74,1],[2,1.7,3]],"ltp":1.85,"tv":506.07,"id":169},{"batb":[[0,1.8,20.1],[1,1.74,1.09],[2,1.7,3.96]],"ltp":2.18,"tv":461.74,"id":31377}]}]}
{"op":"mcm","clk":"11816816219","pt":1723371238576,"mc":[{"id":"1.231581430","rc":[{"batl":[[0,2.4,5],[1,4.3,13.03],[2,1000,0.12]],"ltp":2.18,"tv":461.74,"id":31377}]}]}
{"op":"mcm","clk":"11816819088","pt":1723371262767,"mc":[{"id":"1.231581430","rc":[{"batb":[[0,1.84,15.33],[1,1.8,4.38],[2,1.74,1]],"batl":[[1,4.2,12.61]],"ltp":1.85,"tv":506.07,"id":169},{"batb":[[0,1.92,14.69],[1,1.8,20.1],[2,1.74,1.09]],"batl":[[1,4.3,12.68]],"ltp":2.18,"tv":461.74,"id":31377}]}]}
{"op":"mcm","clk":"11816819250","pt":1723371264073,"mc":[{"id":"1.231581430","rc":[{"batb":[[0,1.8,4.38],[1,1.74,1],[2,1.7,3]],"ltp":1.85,"tv":506.07,"id":169},{"batb":[[0,1.8,20.1],[1,1.74,1.09],[2,1.7,3.48]],"ltp":2.18,"tv":461.74,"id":31377}]}]}
{"op":"mcm","clk":"11816821380","pt":1723371281423,"mc":[{"id":"1.231581430","rc":[{"batl":[[1,4.2,12.96]],"ltp":1.85,"tv":506.07,"id":169},{"batb":[[2,1.7,3.96]],"batl":[[1,4.3,13.03]],"ltp":2.18,"tv":461.74,"id":31377}]}]}
{"op":"mcm","clk":"11816822152","pt":1723371287588,"mc":[{"id":"1.231581430","rc":[{"batb":[[0,2.18,9.79],[1,1.8,20.1],[2,1.74,1.09]],"ltp":2.18,"tv":461.74,"id":31377}]}]}
{"op":"mcm","clk":"11816825769","pt":1723371316457,"mc":[{"id":"1.231581430","rc":[{"batl":[[1,4.2,12.61]],"ltp":1.85,"tv":506.07,"id":169},{"batl":[[1,4.3,12.68]],"ltp":2.18,"tv":461.74,"id":31377}]}]}
{"op":"mcm","clk":"11816826033","pt":1723371318621,"mc":[{"id":"1.231581430","rc":[{"trd":[[2.18,39.07]],"batb":[[0,1.8,20.1],[1,1.74,1.09],[2,1.7,3.48]],"batl":[[0,2.18,40.21],[1,2.4,5],[2,4.3,12.68]],"ltp":2.18,"tv":481.32,"id":31377}],"tv":987.4}]}
{"op":"mcm","clk":"11816826647","pt":1723371323379,"mc":[{"id":"1.231581430","rc":[{"batl":[[0,2.18,40.31]],"ltp":2.18,"tv":481.32,"id":31377}]}]}
{"op":"mcm","clk":"11816827263","pt":1723371328054,"mc":[{"id":"1.231581430","rc":[{"batl":[[0,2.4,5.1],[1,4.3,12.68],[2,1000,0.12]],"ltp":2.18,"tv":481.32,"id":31377}]}]}
{"op":"mcm","clk":"11816827458","pt":1723371329431,"mc":[{"id":"1.231581430","rc":[{"batl":[[2,1000,0.48]],"ltp":1.85,"tv":506.07,"id":169},{"batl":[[2,1000,0.47]],"ltp":2.18,"tv":481.32,"id":31377}]}]}
{"op":"mcm","clk":"11816827523","pt":1723371329948,"mc":[{"id":"1.231581430","rc":[{"batl":[[2,1000,0.13]],"ltp":1.85,"tv":506.07,"id":169},{"batl":[[2,1000,0.12]],"ltp":2.18,"tv":481.32,"id":31377}]}]}
{"op":"mcm","clk":"11816828185","pt":1723371335081,"mc":[{"id":"1.231581430","rc":[{"batb":[[0,1.85,15.25],[1,1.8,4.38],[2,1.74,1]],"batl":[[1,4.2,12.96]],"ltp":1.85,"tv":506.07,"id":169},{"batb":[[0,1.91,14.77],[1,1.8,20.1],[2,1.74,1.09]],"batl":[[1,4.3,13.03]],"ltp":2.18,"tv":481.32,"id":31377}]}]}
{"op":"mcm","clk":"11816828302","pt":1723371335982,"mc":[{"id":"1.231581430","rc":[{"batb":[[0,1.8,4.38],[1,1.74,1],[2,1.7,3]],"ltp":1.85,"tv":506.07,"id":169},{"batb":[[0,1.8,20.1],[1,1.74,1.09],[2,1.7,3.48]],"ltp":2.18,"tv":481.32,"id":31377}]}]}
{"op":"mcm","clk":"11816828928","pt":1723371340967,"mc":[{"id":"1.231581430","rc":[{"batb":[[0,1.83,15.45],[1,1.8,4.38],[2,1.74,1]],"ltp":1.85,"tv":506.07,"id":169},{"batb":[[0,1.94,14.57],[1,1.8,20.1],[2,1.74,1.09]],"ltp":2.18,"tv":481.32,"id":31377}]}]}
{"op":"mcm","clk":"11816829005","pt":1723371341550,"mc":[{"id":"1.231581430","rc":[{"batl":[[1,2.6,6.98],[2,4.2,12.26]],"ltp":1.85,"tv":506.07,"id":169}]}]}
{"op":"mcm","clk":"11816829814","pt":1723371347829,"mc":[{"id":"1.231581430","rc":[{"batl":[[1,4,6.2],[2,4.3,12.33]],"ltp":2.18,"tv":481.32,"id":31377}]}]}
{"op":"mcm","clk":"11816830031","pt":1723371349412,"mc":[{"id":"1.231581430","rc":[{"batb":[[0,1.8,4.38],[1,1.74,1],[2,1.7,3]],"batl":[[0,2.1,1.8]],"ltp":1.85,"tv":506.07,"id":169},{"batb":[[0,1.8,20.1],[1,1.74,1.09],[2,1.7,3.48]],"ltp":2.18,"tv":481.32,"id":31377}]}]}
{"op":"mcm","clk":"11816830654","pt":1723371353919,"mc":[{"id":"1.231581430","rc":[{"batl":[[0,1.85,1.13],[1,2.1,1.8],[2,2.6,6.98]],"ltp":1.85,"tv":506.07,"id":169}]}]}
{"op":"mcm","clk":"11816830754","pt":1723371354594,"mc":[{"id":"1.231581430","rc":[{"trd":[[1.84,0.14]],"batl":[[0,1.85,1.9]],"ltp":1.84,"tv":506.19,"id":169},{"trd":[[2.18,39.17]],"batl":[[0,2.4,5]],"ltp":2.18,"tv":481.42,"id":31377}],"tv":987.62}]}
{"op":"mcm","clk":"11816832475","pt":1723371366981,"mc":[{"id":"1.231581430","rc":[{"trd":[[1.83,1.55],[1.85,2.36]],"batl":[[0,2.1,1.8],[1,2.6,6.98],[2,4.2,12.26]],"ltp":1.85,"tv":510.0,"id":169}],"tv":991.43}]}
{"op":"mcm","clk":"11816832810","pt":1723371369711,"mc":[{"id":"1.231581430","rc":[{"batb":[[0,2.22,9.47],[1,1.8,20.1],[2,1.74,1.09]],"ltp":2.18,"tv":481.42,"id":31377}]}]}
{"op":"mcm","clk":"11816833161","pt":1723371372398,"mc":[{"id":"1.231581430","rc":[{"trd":[[1.82,11.55]],"ltp":1.82,"tv":521.55,"id":169},{"trd":[[2.22,9.47]],"batb":[[0,1.8,20.1],[1,1.74,1.09],[2,1.7,3.48]],"ltp":2.22,"tv":490.89,"id":31377}],"tv":1012.45}]}
{"op":"mcm","clk":"11816835872","pt":1723371392675,"mc":[{"id":"1.231581430","rc":[{"batl":[[0,2.4,5.94]],"ltp":2.22,"tv":490.89,"id":31377}]}]}
{"op":"mcm","clk":"11816836817","pt":1723371400365,"mc":[{"id":"1.231581430","rc":[{"batl":[[1,2.6,6.63]],"ltp":1.82,"tv":521.55,"id":169},{"batl":[[1,4,5.85]],"ltp":2.22,"tv":490.89,"id":31377}]}]}
{"op":"mcm","clk":"11816837027","pt":1723371401896,"mc":[{"id":"1.231581430","rc":[{"batb":[[2,1.7,3]],"ltp":2.22,"tv":490.89,"id":31377}]}]}
{"op":"mcm","clk":"11816837472","pt":1723371405387,"mc":[{"id":"1.231581430","rc":[{"batb":[[0,1.85,15.28],[1,1.8,4.38],[2,1.74,1]],"ltp":1.82,"tv":521.55,"id":169},{"batb":[[0,1.92,14.73],[1,1.8,20.1],[2,1.74,1.09]],"ltp":2.22,"tv":490.89,"id":31377}]}]}
{"op":"mcm","clk":"11816839616","pt":1723371422238,"mc":[{"id":"1.231581430","rc":[{"batl":[[0,2.4,5]],"ltp":2.22,"tv":490.89,"id":31377}]}]}
{"op":"mcm","clk":"11816839810","pt":1723371423398,"mc":[{"id":"1.231581430","rc":[{"batl":[[1,2.6,6.98]],"ltp":1.82,"tv":521.55,"id":169},{"batl":[[1,4,6.2]],"ltp":2.22,"tv":490.89,"id":31377}]}]}
{"op":"mcm","clk":"11816840312","pt":1723371427205,"mc":[{"id":"1.231581430","rc":[{"batb":[[0,1.8,4.38],[1,1.74,1],[2,1.7,3]],"ltp":1.82,"tv":521.55,"id":169},{"batb":[[0,1.8,20.1],[1,1.74,1.09],[2,1.7,3]],"ltp":2.22,"tv":490.89,"id":31377}]}]}
{"op":"mcm","clk":"11816841857","pt":1723371438944,"mc":[{"id":"1.231581430","rc":[{"batb":[[0,1.87,15.13],[1,1.8,4.38],[2,1.74,1]],"ltp":1.82,"tv":521.55,"id":169},{"batb":[[0,1.9,14.99],[1,1.8,20],[2,1.74,1.09]],"ltp":2.22,"tv":490.89,"id":31377}]}]}
{"op":"mcm","clk":"11816843372","pt":1723371450960,"mc":[{"id":"1.231581430","rc":[{"batb":[[0,1.92,10.5],[1,1.9,14.99],[2,1.8,20]],"ltp":2.22,"tv":490.89,"id":31377}]}]}
{"op":"mcm","clk":"11816843760","pt":1723371454551,"mc":[{"id":"1.231581430","rc":[{"batb":[[0,1.8,4.38],[1,1.74,1],[2,1.7,3]],"ltp":1.82,"tv":521.55,"id":169},{"batb":[[1,1.8,20.1],[2,1.74,1.09]],"ltp":2.22,"tv":490.89,"id":31377}]}]}
{"op":"mcm","clk":"11816844304","pt":1723371459264,"mc":[{"id":"1.231581430","rc":[{"batl":[[1,2.6,6.63]],"ltp":1.82,"tv":521.55,"id":169},{"batl":[[1,4,5.85]],"ltp":2.22,"tv":490.89,"id":31377}]}]}
{"op":"mcm","clk":"11816845311","pt":1723371468178,"mc":[{"id":"1.231581430","rc":[{"batb":[[0,1.82,2.71],[1,1.8,4.38],[2,1.74,1]],"ltp":1.82,"tv":521.55,"id":169}]}]}
{"op":"mcm","clk":"11816846816","pt":1723371481413,"mc":[{"id":"1.231581430","rc":[{"batb":[[0,1.93,22.5]],"batl":[[1,4,6.2]],"ltp":2.22,"tv":490.89,"id":31377}]}]}
{"op":"mcm","clk":"11816846841","pt":1723371481623,"mc":[{"id":"1.231581430","rc":[{"batl":[[0,2.1,100],[1,2.4,5],[2,4,6.2]],"ltp":2.22,"tv":490.89,"id":31377}]}]}
{"op":"mcm","clk":"11816847138","pt":1723371484433,"mc":[{"id":"1.231581430","rc":[{"batl":[[1,2.6,6.98]],"ltp":1.82,"tv":521.55,"id":169}]}]}
{"op":"mcm","clk":"11816847305","pt":1723371486011,"mc":[{"id":"1.231581430","rc":[{"batb":[[0,1.94,10.5],[1,1.93,22.5],[2,1.8,20.1]],"ltp":2.22,"tv":490.89,"id":31377}]}]}
{"op":"mcm","clk":"11816849674","pt":1723371506460,"mc":[{"id":"1.231581430","rc":[{"batl":[[1,2.6,6.63]],"ltp":1.82,"tv":521.55,"id":169},{"batl":[[2,4,5.85]],"ltp":2.22,"tv":490.89,"id":31377}]}]}
{"op":"mcm","clk":"11816850078","pt":1723371510336,"mc":[{"id":"1.231581430","rc":[{"batl":[[0,2.6,6.63],[1,4.2,12.26],[2,1000,0.13]],"ltp":1.82,"tv":521.55,"id":169},{"batl":[[0,2.4,5],[1,4,5.85],[2,4.3,12.33]],"ltp":2.22,"tv":490.89,"id":31377}]}]}
{"op":"mcm","clk":"11816850190","pt":1723371511330,"mc":[{"id":"1.231581430","rc":[{"trd":[[1.94,1.88]],"batb":[[0,1.94,9.56]],"ltp":1.94,"tv":492.77,"id":31377}],"tv":1014.33}]}
{"op":"mcm","clk":"11816850844","pt":1723371517967,"mc":[{"id":"1.231581430","rc":[{"batb":[[1,1.8,20.1],[2,1.74,1.09]],"ltp":1.94,"tv":492.77,"id":31377}]}]}
{"op":"mcm","clk":"11816851045","pt":1723371520065,"mc":[{"id":"1.231581430","rc":[{"batl":[[0,2.6,6.78]],"ltp":1.82,"tv":521.55,"id":169},{"batb":[[0,1.8,20.1],[1,1.74,1.09],[2,1.7,3.49]],"ltp":1.94,"tv":492.77,"id":31377}]}]}
{"op":"mcm","clk":"11816851382","pt":1723371523272,"mc":[{"id":"1.231581430","rc":[{"batb":[[0,1.83,15.41],[1,1.82,2.71],[2,1.8,4.38]],"ltp":1.82,"tv":521.55,"id":169},{"batb":[[0,1.93,14.61],[1,1.8,20.1],[2,1.74,1.09]],"ltp":1.94,"tv":492.77,"id":31377}]}]}
{"op":"mcm","clk":"11816851570","pt":1723371524954,"mc":[{"id":"1.231581430","rc":[{"batb":[[0,1.82,2.71],[1,1.8,4.38],[2,1.74,1]],"ltp":1.82,"tv":521.55,"id":169},{"batb":[[0,2.14,9.56]],"ltp":1.94,"tv":492.77,"id":31377}]}]}
{"op":"mcm","clk":"11816851739","pt":1723371526772,"mc":[{"id":"1.231581430","rc":[{"batl":[[0,2.6,7.13]],"ltp":1.82,"tv":521.55,"id":169},{"batl":[[1,4,6.2]],"ltp":1.94,"tv":492.77,"id":31377}]}]}
{"op":"mcm","clk":"11816851897","pt":1723371527977,"mc":[{"id":"1.231581430","rc":[{"batl":[[0,2.6,6.98]],"ltp":1.82,"tv":521.55,"id":169}]}]}
{"op":"mcm","clk":"11816852077","pt":1723371529665,"mc":[{"id":"1.231581430","rc":[{"trd":[[1.88,10.88]],"batb":[[0,1.94,3.69],[1,1.82,2.71],[2,1.8,4.38]],"ltp":1.88,"tv":532.44,"id":169},{"trd":[[2.14,9.56]],"batb":[[0,1.83,15.55],[1,1.8,20]],"ltp":2.14,"tv":502.33,"id":31377}],"tv":1034.77}]}
{"op":"mcm","clk":"11816852227","pt":1723371531280,"mc":[{"id":"1.231581430","rc":[{"batb":[[0,1.82,2.71],[1,1.8,4.38],[2,1.74,1]],"ltp":1.88,"tv":532.44,"id":169},{"batb":[[0,1.8,20.1],[1,1.74,1.09],[2,1.7,3.98]],"ltp":2.14,"tv":502.33,"id":31377}]}]}
{"op":"mcm","clk":"11816852784","pt":1723371536369,"mc":[{"id":"1.231581430","rc":[{"batb":[[0,1.96,14.41],[1,1.82,2.71],[2,1.8,4.38]],"ltp":1.88,"tv":532.44,"id":169},{"batb":[[0,1.81,15.71],[1,1.8,20],[2,1.74,1.09]],"ltp":2.14,"tv":502.33,"id":31377}]}]}
{"op":"mcm","clk":"11816853339","pt":1723371541171,"mc":[{"id":"1.231581430","rc":[{"batb":[[0,1.84,13.6],[1,1.81,15.61],[2,1.8,20]],"batl":[[0,2.34,4.64],[1,2.4,5],[2,4,6.2]],"ltp":2.14,"tv":502.33,"id":31377}]}]}
{"op":"mcm","clk":"11816853612","pt":1723371543368,"mc":[{"id":"1.231581430","rc":[{"trd":[[1.96,20.49]],"batb":[[0,1.96,14.26]],"ltp":1.96,"tv":532.73,"id":169}],"tv":1035.07}]}
{"op":"mcm","clk":"11816853743","pt":1723371544578,"mc":[{"id":"1.231581430","rc":[{"batl":[[0,4.2,12.96],[1,1000,0.13],[2,1000,0]],"ltp":1.96,"tv":532.73,"id":169}]}]}
{"op":"mcm","clk":"11816854313","pt":1723371549702,"mc":[{"id":"1.231581430","rc":[{"batl":[[0,4,7.25],[1,4.2,12],[2,1000,0.13]],"ltp":1.96,"tv":532.73,"id":169}]}]}
{"op":"mcm","clk":"11816854449","pt":1723371550987,"mc":[{"id":"1.231581430","rc":[{"batb":[[1,1.8,4.38],[2,1.74,1]],"ltp":1.96,"tv":532.73,"id":169}]}]}
{"op":"mcm","clk":"11816854942","pt":1723371554895,"mc":[{"id":"1.231581430","rc":[{"batb":[[0,1.8,4.38],[1,1.74,1],[2,1.7,3]],"ltp":1.96,"tv":532.73,"id":169},{"batb":[[0,1.84,13.5],[1,1.8,20],[2,1.74,1.09]],"ltp":2.14,"tv":502.33,"id":31377}]}]}
{"op":"mcm","clk":"11816855035","pt":1723371555680,"mc":[{"id":"1.231581430","rc":[{"batl":[[0,2.4,5],[1,4,6.2],[2,4.3,12.33]],"ltp":2.14,"tv":502.33,"id":31377}]}]}
{"op":"mcm","clk":"11816855351","pt":1723371558387,"mc":[{"id":"1.231581430","rc":[{"batl":[[0,3.95,1.05],[1,4,6.28],[2,4.2,12]],"ltp":1.96,"tv":532.73,"id":169}]}]}
{"op":"mcm","clk":"11816855490","pt":1723371559488,"mc":[{"id":"1.231581430","rc":[{"batb":[[0,1.99,14.21],[1,1.8,4.38],[2,1.74,1]],"ltp":1.96,"tv":532.73,"id":169},{"batb":[[2,1.79,15.81]],"ltp":2.14,"tv":502.33,"id":31377}]}]}
{"op":"mcm","clk":"11816855897","pt":1723371563094,"mc":[{"id":"1.231581430","rc":[{"batl":[[1,4,5.85]],"ltp":2.14,"tv":502.33,"id":31377}]}]}
{"op":"mcm","clk":"11816856079","pt":1723371564921,"mc":[{"id":"1.231581430","rc":[{"batb":[[0,1.8,4.38],[1,1.74,1],[2,1.7,3]],"ltp":1.96,"tv":532.73,"id":169},{"batb":[[2,1.74,1.09]],"ltp":2.14,"tv":502.33,"id":31377}]}]}
{"op":"mcm","clk":"11816856286","pt":1723371566902,"mc":[{"id":"1.231581430","rc":[{"batl":[[0,4,6.99],[1,4.2,12],[2,1000,0.13]],"ltp":1.96,"tv":532.73,"id":169}]}]}
{"op":"mcm","clk":"11816857868","pt":1723371582513,"mc":[{"id":"1.231581430","rc":[{"batl":[[0,3.95,1.05],[1,4,6.28],[2,4.2,12]],"ltp":1.96,"tv":532.73,"id":169},{"batl":[[1,4,6.2]],"ltp":2.14,"tv":502.33,"id":31377}]}]}
{"op":"mcm","clk":"11816857918","pt":1723371582926,"mc":[{"id":"1.231581430","rc":[{"batb":[[2,1.7,3.5]],"ltp":1.96,"tv":532.73,"id":169},{"batl":[[0,2.24,5.15],[1,2.4,5],[2,4,6.2]],"ltp":2.14,"tv":502.33,"id":31377}]}]}
{"op":"mcm","clk":"11816858208","pt":1723371585745,"mc":[{"id":"1.231581430","rc":[{"trd":[[1.74,2],[1.8,34.9]],"batb":[[0,1.7,3.5],[1,1.55,172.16],[2,1.53,171.53]],"batl":[[0,1.74,3.92],[1,3.95,1.05],[2,4,6.28]],"ltp":1.74,"tv":549.9,"id":169},{"trd":[[2.24,5.15]],"batl":[[0,2.4,5],[1,4,6.2],[2,4.3,12.33]],"ltp":2.24,"tv":507.48,"id":31377}],"tv":1057.39}]}
{"op":"mcm","clk":"11816858704","pt":1723371590438,"mc":[{"id":"1.231581430","rc":[{"batb":[[0,1.92,14.73],[1,1.7,3.5],[2,1.55,172.16]],"batl":[[0,3.95,1.05],[1,4,6.28],[2,4.2,12]],"ltp":1.74,"tv":549.9,"id":169},{"batb":[[0,1.85,15.28],[1,1.84,13.5],[2,1.8,20]],"ltp":2.24,"tv":507.48,"id":31377}]}]}
{"op":"mcm","clk":"11816858735","pt":1723371590753,"mc":[{"id":"1.231581430","rc":[{"batb":[[0,1.7,3.5],[1,1.55,172.16],[2,1.53,171.53]],"ltp":1.74,"tv":549.9,"id":169},{"batb":[[0,1.84,13.5],[1,1.8,20],[2,1.74,1.09]],"ltp":2.24,"tv":507.48,"id":31377}]}]}
{"op":"mcm","clk":"11816859841","pt":1723371600646,"mc":[{"id":"1.231581430","rc":[{"batb":[[0,1.8,20],[1,1.74,1.09],[2,1.7,3.97]],"ltp":2.24,"tv":507.48,"id":31377}]}]}
{"op":"mcm","clk":"11816860004","pt":1723371602148,"mc":[{"id":"1.231581430","rc":[{"batb":[[0,1.93,14.65],[1,1.7,3.5],[2,1.55,172.16]],"ltp":1.74,"tv":549.9,"id":169},{"batb":[[0,1.84,15.37],[1,1.8,20],[2,1.74,1.09]],"ltp":2.24,"tv":507.48,"id":31377}]}]}
{"op":"mcm","clk":"11816860170","pt":1723371603750,"mc":[{"id":"1.231581430","rc":[{"batb":[[0,1.7,3.5],[1,1.55,172.16],[2,1.53,171.53]],"ltp":1.74,"tv":549.9,"id":169},{"batb":[[0,1.8,20],[1,1.74,1.09],[2,1.7,3.97]],"ltp":2.24,"tv":507.48,"id":31377}]}]}
{"op":"mcm","clk":"11816860357","pt":1723371605455,"mc":[{"id":"1.231581430","rc":[{"batl":[[0,4,7.25],[1,4.2,12],[2,1000,0.13]],"ltp":1.74,"tv":549.9,"id":169}]}]}
{"op":"mcm","clk":"11816861029","pt":1723371611344,"mc":[{"id":"1.231581430","rc":[{"batb":[[0,1.91,14.81],[1,1.7,3.5],[2,1.55,172.16]],"batl":[[0,3.95,1.05],[1,4,6.28],[2,4.2,12]],"ltp":1.74,"tv":549.9,"id":169},{"batb":[[0,1.86,15.21],[1,1.8,20],[2,1.74,1.09]],"ltp":2.24,"tv":507.48,"id":31377}]}]}
{"op":"mcm","clk":"11816861186","pt":1723371612876,"mc":[{"id":"1.231581430","rc":[{"batb":[[0,1.7,3.5],[1,1.55,172.16],[2,1.53,171.53]],"ltp":1.74,"tv":549.9,"id":169},{"batb":[[0,1.81,10.5]],"ltp":2.24,"tv":507.48,"id":31377}]}]}
{"op":"mcm","clk":"11816861499","pt":1723371615876,"mc":[{"id":"1.231581430","rc":[{"batb":[[0,1.79,3.43],[1,1.7,3.5],[2,1.55,172.16]],"ltp":1.74,"tv":549.9,"id":169}]}]}
{"op":"mcm","clk":"11816861771","pt":1723371618075,"mc":[{"id":"1.231581430","rc":[{"trd":[[1.93,0.19]],"batl":[[0,4,7.25],[1,4.2,12],[2,1000,0.13]],"ltp":1.93,"tv":550.09,"id":169}],"tv":1057.58}]}
{"op":"mcm","clk":"11816862151","pt":1723371621384,"mc":[{"id":"1.231581430","rc":[{"batb":[[0,1.7,3.5],[1,1.55,172.16],[2,1.53,171.53]],"ltp":1.93,"tv":550.09,"id":169}]}]}
{"op":"mcm","clk":"11816862275","pt":1723371622289,"mc":[{"id":"1.231581430","rc":[{"batl":[[0,4,6.9]],"ltp":1.93,"tv":550.09,"id":169},{"batl":[[1,4,5.85]],"ltp":2.24,"tv":507.48,"id":31377}]}]}
{"op":"mcm","clk":"11816862437","pt":1723371623488,"mc":[{"id":"1.231581430","rc":[{"batb":[[1,1.55,171.61]],"ltp":1.93,"tv":550.09,"id":169}]}]}
{"op":"mcm","clk":"11816862980","pt":1723371628380,"mc":[{"id":"1.231581430","rc":[{"batb":[[0,2.02,13.98],[1,1.7,3.5],[2,1.55,171.61]],"ltp":1.93,"tv":550.09,"id":169},{"batb":[[2,1.76,16.04]],"ltp":2.24,"tv":507.48,"id":31377}]}]}
{"op":"mcm","clk":"11816863185","pt":1723371630073,"mc":[{"id":"1.231581430","rc":[{"batb":[[0,1.7,3.5],[1,1.55,171.61],[2,1.53,171.53]],"ltp":1.93,"tv":550.09,"id":169},{"batb":[[2,1.74,1.09]],"ltp":2.24,"tv":507.48,"id":31377}]}]}
{"op":"mcm","clk":"11816863835","pt":1723371635034,"mc":[{"id":"1.231581430","rc":[{"batb":[[0,2.08,13.54],[1,1.7,3.5],[2,1.55,171.61]],"ltp":1.93,"tv":550.09,"id":169}]}]}
{"op":"mcm","clk":"11816864587","pt":1723371641201,"mc":[{"id":"1.231581430","rc":[{"batl":[[0,1.83,2.36],[1,2.4,5],[2,4,5.85]],"ltp":2.24,"tv":507.48,"id":31377}]}]}
{"op":"mcm","clk":"11816864962","pt":1723371644196,"mc":[{"id":"1.231581430","rc":[{"batb":[[1,1.8,11.72],[2,1.7,3.5]],"ltp":1.93,"tv":550.09,"id":169}]}]}
{"op":"mcm","clk":"11816865264","pt":1723371646487,"mc":[{"id":"1.231581430","rc":[{"trd":[[1.81,0.2]],"batb":[[0,1.81,10.4]],"batl":[[0,2.4,5],[1,4,5.85],[2,4.3,12.33]],"ltp":1.81,"tv":507.68,"id":31377}],"tv":1057.78}]}
{"op":"mcm","clk":"11816865850","pt":1723371651457,"mc":[{"id":"1.231581430","rc":[{"batl":[[0,4,7.25]],"ltp":1.93,"tv":550.09,"id":169},{"batl":[[1,4,6.2]],"ltp":1.81,"tv":507.68,"id":31377}]}]}
{"op":"mcm","clk":"11816865885","pt":1723371651674,"mc":[{"id":"1.231581430","rc":[{"batb":[[2,1.7,3.99]],"ltp":1.93,"tv":550.09,"id":169}]}]}
{"op":"mcm","clk":"11816867644","pt":1723371666430,"mc":[{"id":"1.231581430","rc":[{"batl":[[0,2.24,5.15],[1,2.4,5],[2,4,6.2]],"ltp":1.81,"tv":507.68,"id":31377}]}]}
{"op":"mcm","clk":"11816868439","pt":1723371672443,"mc":[{"id":"1.231581430","rc":[{"batb":[[0,2,45.08]],"ltp":1.93,"tv":550.09,"id":169},{"trd":[[1.8,2.7],[1.81,21]],"batb":[[0,1.8,18.65],[1,1.74,1.09],[2,1.7,3.48]],"ltp":1.8,"tv":531.19,"id":31377}],"tv":1081.28}]}
{"op":"mcm","clk":"11816868531","pt":1723371673179,"mc":[{"id":"1.231581430","rc":[{"batl":[[0,1.9,100],[1,2.24,5.15],[2,2.4,5]],"ltp":1.8,"tv":531.19,"id":31377}]}]}
{"op":"mcm","clk":"11816869491","pt":1723371680744,"mc":[{"id":"1.231581430","rc":[{"trd":[[2.1,0.04]],"ltp":2.1,"tv":550.13,"id":169},{"trd":[[1.9,0.04]],"batl":[[0,1.9,99.96]],"ltp":1.9,"tv":531.23,"id":31377}],"tv":1081.36}]}
{"op":"mcm","clk":"11816869738","pt":1723371682626,"mc":[{"id":"1.231581430","rc":[{"batb":[[0,2.08,13.54],[1,2,45.08],[2,1.8,11.72]],"ltp":2.1,"tv":550.13,"id":169},{"batb":[[2,1.71,16.96]],"ltp":1.9,"tv":531.23,"id":31377}]}]}
{"op":"mcm","clk":"11816869855","pt":1723371683520,"mc":[{"id":"1.231581430","rc":[{"batl":[[1,2.4,5],[2,4,6.2]],"ltp":1.9,"tv":531.23,"id":31377}]}]}
{"op":"mcm","clk":"11816870762","pt":1723371691429,"mc":[{"id":"1.231581430","rc":[{"batb":[[2,1.7,3.99]],"ltp":2.1,"tv":550.13,"id":169}]}]}
{"op":"mcm","clk":"11816870880","pt":1723371692419,"mc":[{"id":"1.231581430","rc":[{"batl":[[0,4,6.9]],"ltp":2.1,"tv":550.13,"id":169}]}]}
{"op":"mcm","clk":"11816870903","pt":1723371692624,"mc":[{"id":"1.231581430","rc":[{"batl":[[2,4,5.85]],"ltp":1.9,"tv":531.23,"id":31377}]}]}
{"op":"mcm","clk":"11816871185","pt":1723371694942,"mc":[{"id":"1.231581430","rc":[{"batb":[[2,1.7,3.49]],"ltp":2.1,"tv":550.13,"id":169},{"batb":[[2,1.71,16.48]],"ltp":1.9,"tv":531.23,"id":31377}]}]}
{"op":"mcm","clk":"11816871858","pt":1723371701035,"mc":[{"id":"1.231581430","rc":[{"batb":[[0,2,45.08],[1,1.7,3.49],[2,1.6,45.09]],"ltp":2.1,"tv":550.13,"id":169},{"batb":[[2,1.7,3]],"ltp":1.9,"tv":531.23,"id":31377}]}]}
{"op":"mcm","clk":"11816872432","pt":1723371706075,"mc":[{"id":"1.231581430","rc":[{"batb":[[0,2.04,13.82],[1,2,45.08],[2,1.7,3.49]],"ltp":2.1,"tv":550.13,"id":169},{"batb":[[1,1.74,17.29]],"ltp":1.9,"tv":531.23,"id":31377}]}]}
{"op":"mcm","clk":"11816872515","pt":1723371706753,"mc":[{"id":"1.231581430","rc":[{"batb":[[1,1.7,3.49],[2,1.6,45.09]],"ltp":2.1,"tv":550.13,"id":169}]}]}
{"op":"mcm","clk":"11816873379","pt":1723371713998,"mc":[{"id":"1.231581430","rc":[{"batb":[[0,1.7,3.49],[1,1.6,45.09],[2,1.55,171.53]],"ltp":2.1,"tv":550.13,"id":169},{"batb":[[1,1.74,1.09]],"ltp":1.9,"tv":531.23,"id":31377}]}]}
{"op":"mcm","clk":"11816873766","pt":1723371717295,"mc":[{"id":"1.231581430","rc":[{"batl":[[0,4,7.25]],"ltp":2.1,"tv":550.13,"id":169},{"batl":[[1,2.4,5.35]],"ltp":1.9,"tv":531.23,"id":31377}]}]}
{"op":"mcm","clk":"11816873805","pt":1723371717609,"mc":[{"id":"1.231581430","rc":[{"batb":[[0,1.7,3.97]],"ltp":2.1,"tv":550.13,"id":169}]}]}
{"op":"mcm","clk":"11816874476","pt":1723371723099,"mc":[{"id":"1.231581430","rc":[{"batl":[[0,2.4,5.35],[1,4,5.85],[2,4.3,12.33]],"ltp":1.9,"tv":531.23,"id":31377}]}]}
{"op":"mcm","clk":"11816875427","pt":1723371731089,"mc":[{"id":"1.231581430","rc":[{"batb":[[0,1.93,225.41],[1,1.8,18.65],[2,1.74,1.09]],"ltp":1.9,"tv":531.23,"id":31377}]}]}
{"op":"mcm","clk":"11816876810","pt":1723371741906,"mc":[{"id":"1.231581430","rc":[{"batl":[[0,1.74,2.36],[1,4,7.25],[2,4.2,12]],"ltp":2.1,"tv":550.13,"id":169},{"batb":[[1,1.9,13.53],[2,1.8,18.65]],"ltp":1.9,"tv":531.23,"id":31377}]}]}
{"op":"mcm","clk":"11816877356","pt":1723371746161,"mc":[{"id":"1.231581430","rc":[{"batl":[[0,4,7.25],[1,4.2,12],[2,1000,0.13]],"ltp":2.1,"tv":550.13,"id":169}]}]}
{"op":"mcm","clk":"11816877568","pt":1723371747664,"mc":[{"id":"1.231581430","rc":[{"batb":[[0,1.93,225.51]],"ltp":1.9,"tv":531.23,"id":31377}]}]}
{"op":"mcm","clk":"11816878074","pt":1723371751778,"mc":[{"id":"1.231581430","rc":[{"batb":[[0,1.73,16.79],[1,1.7,3.49],[2,1.6,45.09]],"ltp":2.1,"tv":550.13,"id":169},{"batb":[[0,2.06,13.7],[1,1.93,225.51],[2,1.9,13.53]],"ltp":1.9,"tv":531.23,"id":31377}]}]}
{"op":"mcm","clk":"11816878272","pt":1723371753372,"mc":[{"id":"1.231581430","rc":[{"batb":[[0,1.7,3.97],[1,1.6,45.09],[2,1.55,171.53]],"ltp":2.1,"tv":550.13,"id":169},{"batb":[[0,1.93,225.51],[1,1.9,13.53],[2,1.8,18.65]],"ltp":1.9,"tv":531.23,"id":31377}]}]}
{"op":"mcm","clk":"11816878568","pt":1723371755600,"mc":[{"id":"1.231581430","rc":[{"batb":[[0,1.73,270.97],[1,1.7,3.49],[2,1.6,45.09]],"ltp":2.1,"tv":550.13,"id":169}]}]}
{"op":"mcm","clk":"11816878858","pt":1723371758087,"mc":[{"id":"1.231581430","rc":[{"batb":[[0,1.7,3.97],[1,1.6,45.09],[2,1.55,171.53]],"ltp":2.1,"tv":550.13,"id":169}]}]}
{"op":"mcm","clk":"11816879063","pt":1723371759785,"mc":[{"id":"1.231581430","rc":[{"batb":[[0,1.72,17.4],[1,1.7,3],[2,1.6,45.09]],"ltp":2.1,"tv":550.13,"id":169},{"batb":[[0,2.08,13.58],[1,1.9,13.63]],"ltp":1.9,"tv":531.23,"id":31377}]}]}
{"op":"mcm","clk":"11816879236","pt":1723371761215,"mc":[{"id":"1.231581430","rc":[{"batb":[[0,1.7,3.97],[1,1.6,45.09],[2,1.55,171.53]],"ltp":2.1,"tv":550.13,"id":169},{"batb":[[0,1.9,13.63],[1,1.8,18.65],[2,1.74,1.09]],"ltp":1.9,"tv":531.23,"id":31377}]}]}
{"op":"mcm","clk":"11816879609","pt":1723371764180,"mc":[{"id":"1.231581430","rc":[{"batb":[[0,1.99,9.02],[1,1.9,13.63],[2,1.8,18.65]],"ltp":1.9,"tv":531.23,"id":31377}]}]}
{"op":"mcm","clk":"11816879726","pt":1723371765221,"mc":[{"id":"1.231581430","rc":[{"batb":[[1,1.95,5.87],[2,1.94,225.41]],"ltp":1.9,"tv":531.23,"id":31377}]}]}
{"op":"mcm","clk":"11816879912","pt":1723371766496,"mc":[{"id":"1.231581430","rc":[{"batl":[[1,4,5.5]],"ltp":1.9,"tv":531.23,"id":31377}]}]}
{"op":"mcm","clk":"11816880034","pt":1723371767395,"mc":[{"id":"1.231581430","rc":[{"batl":[[0,4,6.9]],"ltp":2.1,"tv":550.13,"id":169},{"batb":[[0,2,250.93],[1,1.99,9.02],[2,1.95,5.87]],"ltp":1.9,"tv":531.23,"id":31377}]}]}
{"op":"mcm","clk":"11816880166","pt":1723371768404,"mc":[{"id":"1.231581430","rc":[{"trd":[[2,14.52]],"batb":[[0,2,249.11]],"ltp":2.0,"tv":534.87,"id":31377}],"tv":1085.0}]}
{"op":"mcm","clk":"11816880272","pt":1723371769188,"mc":[{"id":"1.231581430","rc":[{"batb":[[0,1.7,3.48]],"ltp":2.1,"tv":550.13,"id":169}]}]}
{"op":"mcm","clk":"11816880569","pt":1723371771416,"mc":[{"id":"1.231581430","rc":[{"batb":[[0,1.71,16.96],[1,1.7,3],[2,1.6,45.09]],"ltp":2.1,"tv":550.13,"id":169},{"batb":[[0,2.08,13.54],[1,2,249.11],[2,1.99,9.02]],"ltp":2.0,"tv":534.87,"id":31377}]}]}
{"op":"mcm","clk":"11816880597","pt":1723371771620,"mc":[{"id":"1.231581430","rc":[{"batl":[[0,1.92,1.8],[1,4,6.9],[2,4.2,12]],"ltp":2.1,"tv":550.13,"id":169}]}]}
{"op":"mcm","clk":"11816880938","pt":1723371774213,"mc":[{"id":"1.231581430","rc":[{"batb":[[0,1.7,3.48],[1,1.6,45.09],[2,1.55,171.53]],"ltp":2.1,"tv":550.13,"id":169},{"batb":[[0,2,249.11],[1,1.99,9.02],[2,1.95,5.87]],"ltp":2.0,"tv":534.87,"id":31377}]}]}
{"op":"mcm","clk":"11816881030","pt":1723371774899,"mc":[{"id":"1.231581430","rc":[{"batb":[[1,1.55,171.61],[2,1.53,171.53]],"ltp":2.1,"tv":550.13,"id":169}]}]}
{"op":"mcm","clk":"11816881284","pt":1723371776899,"mc":[{"id":"1.231581430","rc":[{"batb":[[2,1.9,13.63]],"ltp":2.0,"tv":534.87,"id":31377}]}]}
{"op":"mcm","clk":"11816881579","pt":1723371779204,"mc":[{"id":"1.231581430","rc":[{"batb":[[1,1.68,16.82],[2,1.55,171.61]],"ltp":2.1,"tv":550.13,"id":169},{"batb":[[0,2.14,13.2],[1,2,249.11],[2,1.99,9.02]],"ltp":2.0,"tv":534.87,"id":31377}]}]}
{"op":"mcm","clk":"11816881752","pt":1723371780733,"mc":[{"id":"1.231581430","rc":[{"batb":[[1,1.55,171.61],[2,1.53,171.53]],"ltp":2.1,"tv":550.13,"id":169},{"batb":[[0,2,474.52],[1,1.99,9.02],[2,1.9,13.53]],"ltp":2.0,"tv":534.87,"id":31377}]}]}
{"op":"mcm","clk":"11816882556","pt":1723371786919,"mc":[{"id":"1.231581430","rc":[{"batb":[[1,1.67,16.95],[2,1.55,171.53]],"ltp":2.1,"tv":550.13,"id":169},{"batb":[[0,2.14,13.16],[1,2,474.52],[2,1.99,9.02]],"ltp":2.0,"tv":534.87,"id":31377}]}]}
{"op":"mcm","clk":"11816882902","pt":1723371789717,"mc":[{"id":"1.231581430","rc":[{"batb":[[1,1.55,171.61],[2,1.53,171.53]],"ltp":2.1,"tv":550.13,"id":169},{"batb":[[0,2,474.52],[1,1.99,9.02],[2,1.9,13.53]],"ltp":2.0,"tv":534.87,"id":31377}]}]}
{"op":"mcm","clk":"11816883130","pt":1723371791407,"mc":[{"id":"1.231581430","rc":[{"batb":[[1,1.9,13.53],[2,1.8,18.65]],"ltp":2.0,"tv":534.87,"id":31377}]}]}
{"op":"mcm","clk":"11816883393","pt":1723371793443,"mc":[{"id":"1.231581430","rc":[{"batb":[[1,1.8,18.65],[2,1.74,1.09]],"ltp":2.0,"tv":534.87,"id":31377}]}]}
{"op":"mcm","clk":"11816883515","pt":1723371794438,"mc":[{"id":"1.231581430","rc":[{"batl":[[1,1.98,31.5],[2,4,7.25]],"ltp":2.1,"tv":550.13,"id":169},{"batl":[[1,4,5.85]],"ltp":2.0,"tv":534.87,"id":31377}]}]}
{"op":"mcm","clk":"11816883544","pt":1723371794610,"mc":[{"id":"1.231581430","rc":[{"batb":[[0,1.72,16.91],[1,1.7,3],[2,1.55,171.61]],"ltp":2.1,"tv":550.13,"id":169},{"batb":[[0,2.08,13.58],[1,2,474.52],[2,1.8,19.09]],"ltp":2.0,"tv":534.87,"id":31377}]}]}
{"op":"mcm","clk":"11816883719","pt":1723371796127,"mc":[{"id":"1.231581430","rc":[{"trd":[[1.72,3.76],[1.73,0.96]],"batb":[[0,1.72,14.55]],"ltp":1.72,"tv":554.84,"id":169}],"tv":1089.72}]}
{"op":"mcm","clk":"11816884345","pt":1723371801228,"mc":[{"id":"1.231581430","rc":[{"batb":[[0,1.7,3],[1,1.55,171.61],[2,1.53,171.53]],"ltp":1.72,"tv":554.84,"id":169},{"batb":[[0,2,474.52],[1,1.8,19.09],[2,1.74,1.09]],"ltp":2.0,"tv":534.87,"id":31377}]}]}
{"op":"mcm","clk":"11816884477","pt":1723371802171,"mc":[{"id":"1.231581430","rc":[{"batl":[[0,2.34,100],[1,2.4,5.35],[2,4,5.85]],"ltp":2.0,"tv":534.87,"id":31377}]}]}
{"op":"mcm","clk":"11816884645","pt":1723371803543,"mc":[{"id":"1.231581430","rc":[{"batb":[[0,1.73,1.76],[1,1.7,3],[2,1.55,171.61]],"ltp":1.72,"tv":554.84,"id":169}]}]}
{"op":"mcm","clk":"11816885153","pt":1723371807241,"mc":[{"id":"1.231581430","rc":[{"batl":[[1,1.98,31.93]],"ltp":1.72,"tv":554.84,"id":169}]}]}
{"op":"mcm","clk":"11816885187","pt":1723371807556,"mc":[{"id":"1.231581430","rc":[{"batl":[[1,1.98,32.03]],"ltp":1.72,"tv":554.84,"id":169}]}]}
{"op":"mcm","clk":"11816885319","pt":1723371808757,"mc":[{"id":"1.231581430","rc":[{"batb":[[0,1.74,14.44],[1,1.73,1.76],[2,1.7,3]],"ltp":1.72,"tv":554.84,"id":169},{"batb":[[0,2.04,13.82],[1,2,474.52],[2,1.8,19.09]],"ltp":2.0,"tv":534.87,"id":31377}]}]}
{"op":"mcm","clk":"11816885763","pt":1723371812490,"mc":[{"id":"1.231581430","rc":[{"batb":[[0,1.7,3],[1,1.55,171.61],[2,1.53,171.53]],"batl":[[0,1.91,5.5],[1,1.92,1.8],[2,1.98,31.93]],"ltp":1.72,"tv":554.84,"id":169},{"batb":[[0,2,474.52],[1,1.8,19.09],[2,1.74,1.09]],"ltp":2.0,"tv":534.87,"id":31377}]}]}
{"op":"mcm","clk":"11816886011","pt":1723371814389,"mc":[{"id":"1.231581430","rc":[{"batl":[[0,1.75,2.36],[1,1.91,5.5],[2,1.92,1.8]],"ltp":1.72,"tv":554.84,"id":169}]}]}
{"op":"mcm","clk":"11816886317","pt":1723371816975,"mc":[{"id":"1.231581430","rc":[{"batl":[[0,2.4,5.35],[1,4,5.85],[2,4.3,12.33]],"ltp":2.0,"tv":534.87,"id":31377}]}]}
{"op":"mcm","clk":"11816886604","pt":1723371819504,"mc":[{"id":"1.231581430","rc":[{"batb":[[0,1.73,16.31],[1,1.7,3],[2,1.55,171.61]],"batl":[[0,1.91,5.5],[1,1.92,1.8],[2,1.98,31.93]],"ltp":1.72,"tv":554.84,"id":169},{"batb":[[0,2.06,13.7],[1,2,474.52],[2,1.8,19.09]],"ltp":2.0,"tv":534.87,"id":31377}]}]}
{"op":"mcm","clk":"11816887124","pt":1723371823817,"mc":[{"id":"1.231581430","rc":[{"batl":[[0,2.14,22.55],[1,2.4,5.35],[2,4,5.85]],"ltp":2.0,"tv":534.87,"id":31377}]}]}
{"op":"mcm","clk":"11816887276","pt":1723371825188,"mc":[{"id":"1.231581430","rc":[{"batb":[[0,1.7,3],[1,1.55,171.61],[2,1.53,171.53]],"ltp":1.72,"tv":554.84,"id":169},{"batb":[[0,2,474.52],[1,1.8,19.09],[2,1.74,1.09]],"ltp":2.0,"tv":534.87,"id":31377}]}]}
{"op":"mcm","clk":"11816887367","pt":1723371825876,"mc":[{"id":"1.231581430","rc":[{"batl":[[0,2.4,5.35],[1,4,5.85],[2,4.3,12.33]],"ltp":2.0,"tv":534.87,"id":31377}]}]}
{"op":"mcm","clk":"11816887680","pt":1723371828404,"mc":[{"id":"1.231581430","rc":[{"batl":[[0,2.4,5]],"ltp":2.0,"tv":534.87,"id":31377}]}]}
{"op":"mcm","clk":"11816887752","pt":1723371828981,"mc":[{"id":"1.231581430","rc":[{"batl":[[2,3.95,1.04]],"ltp":1.72,"tv":554.84,"id":169}]}]}
{"op":"mcm","clk":"11816888027","pt":1723371831356,"mc":[{"id":"1.231581430","rc":[{"batb":[[0,1.73,16.31],[1,1.7,3],[2,1.55,171.61]],"ltp":1.72,"tv":554.84,"id":169},{"batb":[[0,2.06,13.7],[1,2,474.52],[2,1.8,19.09]],"ltp":2.0,"tv":534.87,"id":31377}]}]}
{"op":"mcm","clk":"11816888060","pt":1723371831670,"mc":[{"id":"1.231581430","rc":[{"batb":[[0,1.7,3],[1,1.55,171.61],[2,1.53,171.53]],"ltp":1.72,"tv":554.84,"id":169},{"batb":[[0,2,474.52],[1,1.8,19.09],[2,1.74,1.09]],"ltp":2.0,"tv":534.87,"id":31377}]}]}
{"op":"mcm","clk":"11816888350","pt":1723371834067,"mc":[{"id":"1.231581430","rc":[{"batl":[[2,2.3,32.28]],"ltp":1.72,"tv":554.84,"id":169}]}]}
{"op":"mcm","clk":"11816888641","pt":1723371836587,"mc":[{"id":"1.231581430","rc":[{"batb":[[1,1.68,16.82],[2,1.55,171.61]],"ltp":1.72,"tv":554.84,"id":169},{"batb":[[0,2.14,13.2],[1,2,474.52],[2,1.8,19.09]],"ltp":2.0,"tv":534.87,"id":31377}]}]}
{"op":"mcm","clk":"11816891057","pt":1723371857501,"mc":[{"id":"1.231581430","rc":[{"trd":[[2.14,35.96]],"batb":[[0,2,474.52],[1,1.8,19.09],[2,1.74,1.09]],"batl":[[0,2.14,9.35],[1,2.4,5],[2,4,5.85]],"ltp":2.14,"tv":561.27,"id":31377}],"tv":1116.12}]}
{"op":"mcm","clk":"11816891171","pt":1723371858675,"mc":[{"id":"1.231581430","rc":[{"batb":[[0,1.7,3.1],[1,1.55,171.61],[2,1.53,171.53]],"ltp":1.72,"tv":554.84,"id":169}]}]}
{"op":"mcm","clk":"11816891534","pt":1723371861986,"mc":[{"id":"1.231581430","rc":[{"batb":[[0,1.87,2.46],[1,1.7,3],[2,1.55,171.61]],"ltp":1.72,"tv":554.84,"id":169},{"batl":[[2,2.96,4.47]],"ltp":2.14,"tv":561.27,"id":31377}]}]}
{"op":"mcm","clk":"11816891826","pt":1723371864394,"mc":[{"id":"1.231581430","rc":[{"batl":[[2,4,5.85]],"ltp":2.14,"tv":561.27,"id":31377}]}]}
{"op":"mcm","clk":"11816892072","pt":1723371866715,"mc":[{"id":"1.231581430","rc":[{"batb":[[0,1.7,3.1],[1,1.55,171.61],[2,1.53,171.53]],"ltp":1.72,"tv":554.84,"id":169}]}]}
{"op":"mcm","clk":"11816892402","pt":1723371869504,"mc":[{"id":"1.231581430","rc":[{"batb":[[1,1.81,6.7],[2,1.8,19.09]],"batl":[[2,2.82,4.12]],"ltp":2.14,"tv":561.27,"id":31377}]}]}
{"op":"mcm","clk":"11816893129","pt":1723371876007,"mc":[{"id":"1.231581430","rc":[{"trd":[[1.91,11.13]],"batl":[[0,1.91,3.39]],"ltp":1.91,"tv":556.95,"id":169},{"trd":[[2.08,380.95]],"batb":[[1,1.8,19.09],[2,1.74,1.09]],"batl":[[2,4,6.2]],"ltp":2.08,"tv":563.21,"id":31377}],"tv":1120.17}]}
{"op":"mcm","clk":"11816894270","pt":1723371886421,"mc":[{"id":"1.231581430","rc":[{"batl":[[2,2.3,31.93]],"ltp":1.91,"tv":556.95,"id":169},{"batl":[[2,4,5.85]],"ltp":2.08,"tv":563.21,"id":31377}]}]}
{"op":"mcm","clk":"11816894393","pt":1723371887530,"mc":[{"id":"1.231581430","rc":[{"batb":[[1,1.8,18.65]],"ltp":2.08,"tv":563.21,"id":31377}]}]}
{"op":"mcm","clk":"11816894807","pt":1723371891513,"mc":[{"id":"1.231581430","rc":[{"batb":[[0,2.12,10.31],[1,2,474.52],[2,1.8,18.65]],"ltp":2.08,"tv":563.21,"id":31377}]}]}
{"op":"mcm","clk":"11816895024","pt":1723371893515,"mc":[{"id":"1.231581430","rc":[{"trd":[[2.12,9.02]],"batb":[[0,2.12,5.8]],"ltp":2.12,"tv":572.23,"id":31377}],"tv":1129.19}]}
{"op":"mcm","clk":"11816895377","pt":1723371896455,"mc":[{"id":"1.231581430","rc":[{"batb":[[1,2,225.41]],"ltp":2.12,"tv":572.23,"id":31377}]}]}
{"op":"mcm","clk":"11816896056","pt":1723371902465,"mc":[{"id":"1.231581430","rc":[{"batl":[[2,2.84,4.12]],"ltp":2.12,"tv":572.23,"id":31377}]}]}
{"op":"mcm","clk":"11816896069","pt":1723371902566,"mc":[{"id":"1.231581430","rc":[{"batb":[[1,1.8,18.65],[2,1.74,1.09]],"ltp":2.12,"tv":572.23,"id":31377}]}]}
{"op":"mcm","clk":"11816896346","pt":1723371904844,"mc":[{"id":"1.231581430","rc":[{"batl":[[2,4,5.85]],"ltp":2.12,"tv":572.23,"id":31377}]}]}
{"op":"mcm","clk":"11816896732","pt":1723371907659,"mc":[{"id":"1.231581430","rc":[{"trd":[[2.12,12.46]],"batb":[[0,2.12,4.08]],"ltp":2.12,"tv":575.67,"id":31377}],"tv":1132.62}]}
{"op":"mcm","clk":"11816897018","pt":1723371909951,"mc":[{"id":"1.231581430","rc":[{"batb":[[2,1.76,6.7]],"batl":[[2,2.82,4.12]],"ltp":2.12,"tv":575.67,"id":31377}]}]}
{"op":"mcm","clk":"11816897266","pt":1723371911700,"mc":[{"id":"1.231581430","rc":[{"batb":[[2,1.74,1.09]],"batl":[[2,4,5.85]],"ltp":2.12,"tv":575.67,"id":31377}]}]}
{"op":"mcm","clk":"11816899397","pt":1723371927912,"mc":[{"id":"1.231581430","rc":[{"batl":[[2,4,6.2]],"ltp":2.12,"tv":575.67,"id":31377}]}]}
{"op":"mcm","clk":"11816899980","pt":1723371932119,"mc":[{"id":"1.231581430","rc":[{"batl":[[2,2.84,4.12]],"ltp":2.12,"tv":575.67,"id":31377}]}]}
{"op":"mcm","clk":"11816900283","pt":1723371934401,"mc":[{"id":"1.231581430","rc":[{"batl":[[2,4,6.2]],"ltp":2.12,"tv":575.67,"id":31377}]}]}
{"op":"mcm","clk":"11816900941","pt":1723371939505,"mc":[{"id":"1.231581430","rc":[{"batb":[[2,1.76,6.7]],"batl":[[2,2.82,4.12]],"ltp":2.12,"tv":575.67,"id":31377}]}]}
{"op":"mcm","clk":"11816901300","pt":1723371942216,"mc":[{"id":"1.231581430","rc":[{"trd":[[1.87,5.9],[1.88,11.08]],"batb":[[0,1.7,3]],"ltp":1.87,"tv":563.05,"id":169},{"trd":[[2.14,41.12]],"batl":[[0,2.14,4.19]],"ltp":2.14,"tv":580.83,"id":31377}],"tv":1143.88}]}
{"op":"mcm","clk":"11816902169","pt":1723371949118,"mc":[{"id":"1.231581430","rc":[{"batb":[[2,1.74,1.09]],"batl":[[2,4,6.2]],"ltp":2.14,"tv":580.83,"id":31377}]}]}
{"op":"mcm","clk":"11816903185","pt":1723371956233,"mc":[{"id":"1.231581430","rc":[{"batb":[[0,2.14,2.56]],"batl":[[0,2.4,5],[1,4,6.2],[2,4.3,12.33]],"ltp":2.14,"tv":580.83,"id":31377}]}]}
{"op":"mcm","clk":"11816903880","pt":1723371961465,"mc":[{"id":"1.231581430","rc":[{"batb":[[0,2.16,4.08],[1,2.14,2.56],[2,1.8,18.65]],"batl":[[1,4,5.85]],"ltp":2.14,"tv":580.83,"id":31377}]}]}
{"op":"mcm","clk":"11816903891","pt":1723371961518,"mc":[{"id":"1.231581430","rc":[{"batb":[[0,1.75,16.16],[1,1.7,3],[2,1.55,171.61]],"ltp":1.87,"tv":563.05,"id":169},{"batb":[[2,2.04,13.86]],"ltp":2.14,"tv":580.83,"id":31377}]}]}
{"op":"mcm","clk":"11816905084","pt":1723371970566,"mc":[{"id":"1.231581430","rc":[{"trd":[[2.16,0.2]],"batb":[[0,2.16,3.98]],"ltp":2.16,"tv":581.03,"id":31377}],"tv":1144.08}]}
{"op":"mcm","clk":"11816905414","pt":1723371973173,"mc":[{"id":"1.231581430","rc":[{"batl":[[1,2.84,4.12],[2,4,5.85]],"ltp":2.16,"tv":581.03,"id":31377}]}]}
{"op":"mcm","clk":"11816905679","pt":1723371975441,"mc":[{"id":"1.231581430","rc":[{"batl":[[1,4,5.85],[2,4.3,12.33]],"ltp":2.16,"tv":581.03,"id":31377}]}]}
{"op":"mcm","clk":"11816906358","pt":1723371980394,"mc":[{"id":"1.231581430","rc":[{"batl":[[1,2.82,4.12],[2,4,5.85]],"ltp":2.16,"tv":581.03,"id":31377}]}]}
{"op":"mcm","clk":"11816906747","pt":1723371983269,"mc":[{"id":"1.231581430","rc":[{"batl":[[2,2.3,32.28]],"ltp":1.87,"tv":563.05,"id":169},{"batl":[[2,4,6.2]],"ltp":2.16,"tv":581.03,"id":31377}]}]}
{"op":"mcm","clk":"11816907445","pt":1723371988461,"mc":[{"id":"1.231581430","rc":[{"batb":[[0,1.7,3],[1,1.55,171.61],[2,1.53,171.53]],"ltp":1.87,"tv":563.05,"id":169},{"batb":[[2,1.8,18.65]],"ltp":2.16,"tv":581.03,"id":31377}]}]}
{"op":"mcm","clk":"11816907672","pt":1723371990153,"mc":[{"id":"1.231581430","rc":[{"batl":[[1,4,6.2],[2,4.3,12.33]],"ltp":2.16,"tv":581.03,"id":31377}]}]}
{"op":"mcm","clk":"11816907889","pt":1723371991894,"mc":[{"id":"1.231581430","rc":[{"batb":[[0,2.14,2.56],[1,1.8,18.65],[2,1.74,1.54]],"ltp":2.16,"tv":581.03,"id":31377}]}]}
{"op":"mcm","clk":"11816908252","pt":1723371994566,"mc":[{"id":"1.231581430","rc":[{"batl":[[0,1.92,1.8],[1,2.3,32.28],[2,4,6.9]],"ltp":1.87,"tv":563.05,"id":169}]}]}
{"op":"mcm","clk":"11816909660","pt":1723372004776,"mc":[{"id":"1.231581430","rc":[{"batb":[[0,1.81,15.61],[1,1.7,3],[2,1.55,171.61]],"ltp":1.87,"tv":563.05,"id":169},{"batb":[[1,1.96,14.41],[2,1.8,18.65]],"batl":[[1,2.72,4.12],[2,4,6.2]],"ltp":2.16,"tv":581.03,"id":31377}]}]}
{"op":"mcm","clk":"11816910474","pt":1723372010787,"mc":[{"id":"1.231581430","rc":[{"batb":[[0,1.7,3],[1,1.55,171.61],[2,1.53,171.53]],"ltp":1.87,"tv":563.05,"id":169},{"batb":[[1,1.8,18.65],[2,1.74,1.54]],"ltp":2.16,"tv":581.03,"id":31377}]}]}
{"op":"mcm","clk":"11816910644","pt":1723372011997,"mc":[{"id":"1.231581430","rc":[{"batb":[[2,1.74,8.75]],"ltp":2.16,"tv":581.03,"id":31377}]}]}
{"op":"mcm","clk":"11816911816","pt":1723372020776,"mc":[{"id":"1.231581430","rc":[{"batb":[[2,1.74,1.54]],"batl":[[1,4,6.2],[2,4.3,12.33]],"ltp":2.16,"tv":581.03,"id":31377}]}]}
{"op":"mcm","clk":"11816912464","pt":1723372025384,"mc":[{"id":"1.231581430","rc":[{"batl":[[2,4,6.55]],"ltp":1.87,"tv":563.05,"id":169},{"batl":[[1,4,5.85]],"ltp":2.16,"tv":581.03,"id":31377}]}]}
{"op":"mcm","clk":"11816912759","pt":1723372027487,"mc":[{"id":"1.231581430","rc":[{"batb":[[0,1.79,15.81],[1,1.7,3],[2,1.55,171.61]],"ltp":1.87,"tv":563.05,"id":169},{"batb":[[1,1.99,14.21],[2,1.8,18.65]],"ltp":2.16,"tv":581.03,"id":31377}]}]}
{"op":"mcm","clk":"11816912990","pt":1723372029199,"mc":[{"id":"1.231581430","rc":[{"batb":[[0,1.7,3],[1,1.55,171.61],[2,1.53,171.53]],"ltp":1.87,"tv":563.05,"id":169}]}]}
{"op":"mcm","clk":"11816913701","pt":1723372034193,"mc":[{"id":"1.231581430","rc":[{"batb":[[0,1.77,15.93],[1,1.7,3],[2,1.55,171.61]],"ltp":1.87,"tv":563.05,"id":169}]}]}
{"op":"mcm","clk":"11816913974","pt":1723372035992,"mc":[{"id":"1.231581430","rc":[{"batb":[[1,1.8,18.65],[2,1.74,1.54]],"ltp":2.16,"tv":581.03,"id":31377}]}]}
{"op":"mcm","clk":"11816914737","pt":1723372041399,"mc":[{"id":"1.231581430","rc":[{"batb":[[1,2.02,13.98],[2,1.8,18.65]],"ltp":2.16,"tv":581.03,"id":31377}]}]}
{"op":"mcm","clk":"11816914854","pt":1723372042302,"mc":[{"id":"1.231581430","rc":[{"batb":[[0,2.16,9.96],[1,2.14,2.56],[2,2.02,13.98]],"ltp":2.16,"tv":581.03,"id":31377}]}]}
{"op":"mcm","clk":"11816915056","pt":1723372043812,"mc":[{"id":"1.231581430","rc":[{"trd":[[1.77,1.8]],"batb":[[0,1.7,3],[1,1.55,171.61],[2,1.53,171.53]],"ltp":1.77,"tv":564.85,"id":169},{"batb":[[2,1.8,18.65]],"ltp":2.16,"tv":581.03,"id":31377}],"tv":1145.89}]}
{"op":"mcm","clk":"11816915255","pt":1723372045426,"mc":[{"id":"1.231581430","rc":[{"batl":[[1,2.74,4.12],[2,4,5.85]],"ltp":2.16,"tv":581.03,"id":31377}]}]}
{"op":"mcm","clk":"11816915902","pt":1723372050408,"mc":[{"id":"1.231581430","rc":[{"batb":[[0,1.74,16.2],[1,1.7,3],[2,1.55,171.61]],"batl":[[2,4,6.9]],"ltp":1.77,"tv":564.85,"id":169},{"batb":[[2,2.04,13.82]],"batl":[[2,4,6.2]],"ltp":2.16,"tv":581.03,"id":31377}]}]}
{"op":"mcm","clk":"11816916016","pt":1723372051296,"mc":[{"id":"1.231581430","rc":[{"batb":[[0,1.7,3],[1,1.55,171.61],[2,1.53,171.53]],"ltp":1.77,"tv":564.85,"id":169},{"trd":[[2.16,7.5]],"batb":[[0,2.16,6.31]],"ltp":2.16,"tv":588.33,"id":31377}],"tv":1153.18}]}
{"op":"mcm","clk":"11816916235","pt":1723372053023,"mc":[{"id":"1.231581430","rc":[{"batb":[[1,1.57,8.73],[2,1.55,171.53]],"ltp":1.77,"tv":564.85,"id":169}]}]}
{"op":"mcm","clk":"11816916572","pt":1723372055607,"mc":[{"id":"1.231581430","rc":[{"batb":[[0,1.72,16.36],[1,1.7,3],[2,1.57,8.73]],"ltp":1.77,"tv":564.85,"id":169}]}]}
{"op":"mcm","clk":"11816917931","pt":1723372065845,"mc":[{"id":"1.231581430","rc":[{"batb":[[0,1.7,3],[1,1.57,8.73],[2,1.55,171.53]],"ltp":1.77,"tv":564.85,"id":169}]}]}
{"op":"mcm","clk":"11816918589","pt":1723372070749,"mc":[{"id":"1.231581430","rc":[{"batb":[[0,1.74,16.2],[1,1.7,3],[2,1.57,8.73]],"ltp":1.77,"tv":564.85,"id":169}]}]}
{"op":"mcm","clk":"11816918740","pt":1723372071828,"mc":[{"id":"1.231581430","rc":[{"trd":[[1.74,2.13]],"batb":[[0,1.74,16.06]],"ltp":1.74,"tv":564.99,"id":169},{"trd":[[2.36,0.1]],"ltp":2.36,"tv":588.43,"id":31377}],"tv":1153.42}]}
{"op":"mcm","clk":"11816919141","pt":1723372075066,"mc":[{"id":"1.231581430","rc":[{"batb":[[0,1.7,3],[1,1.57,8.73],[2,1.55,171.53]],"ltp":1.74,"tv":564.99,"id":169}]}]}
{"op":"mcm","clk":"11816919383","pt":1723372076801,"mc":[{"id":"1.231581430","rc":[{"batl":[[1,4,6.2],[2,4.3,12.33]],"ltp":2.36,"tv":588.43,"id":31377}]}]}
{"op":"mcm","clk":"11816919779","pt":1723372079997,"mc":[{"id":"1.231581430","rc":[{"batb":[[0,1.76,16.04],[1,1.7,3],[2,1.57,8.73]],"ltp":1.74,"tv":564.99,"id":169}]}]}
{"op":"mcm","clk":"11816919987","pt":1723372081587,"mc":[{"id":"1.231581430","rc":[{"trd":[[1.76,0.2]],"batb":[[0,1.76,15.93]],"ltp":1.76,"tv":565.19,"id":169}],"tv":1153.62}]}
{"op":"mcm","clk":"11816921029","pt":1723372089313,"mc":[{"id":"1.231581430","rc":[{"batb":[[2,1.8,18.65]],"ltp":2.36,"tv":588.43,"id":31377}]}]}
{"op":"mcm","clk":"11816921720","pt":1723372094307,"mc":[{"id":"1.231581430","rc":[{"batl":[[1,2.3,31.93]],"ltp":1.76,"tv":565.19,"id":169},{"batb":[[2,2,14.09]],"ltp":2.36,"tv":588.43,"id":31377}]}]}
{"op":"mcm","clk":"11816921814","pt":1723372094996,"mc":[{"id":"1.231581430","rc":[{"batl":[[1,4,5.85]],"ltp":2.36,"tv":588.43,"id":31377}]}]}
{"op":"mcm","clk":"11816921900","pt":1723372095628,"mc":[{"id":"1.231581430","rc":[{"trd":[[1.76,0.41]],"batb":[[0,1.76,15.83]],"ltp":1.76,"tv":565.4,"id":169},{"batl":[[1,2.74,4.12],[2,4,5.85]],"ltp":2.36,"tv":588.43,"id":31377}],"tv":1153.83}]}
{"op":"mcm","clk":"11816922317","pt":1723372098579,"mc":[{"id":"1.231581430","rc":[{"batl":[[1,4,5.85],[2,4.3,12.33]],"ltp":2.36,"tv":588.43,"id":31377}]}]}
{"op":"mcm","clk":"11816922458","pt":1723372099731,"mc":[{"id":"1.231581430","rc":[{"batb":[[0,1.7,3],[1,1.57,8.73],[2,1.55,171.53]],"ltp":1.76,"tv":565.4,"id":169},{"batb":[[2,1.8,18.65]],"ltp":2.36,"tv":588.43,"id":31377}]}]}
{"op":"mcm","clk":"11816922773","pt":1723372101804,"mc":[{"id":"1.231581430","rc":[{"trd":[[2.16,20.1]],"batb":[[0,2.14,2.57],[1,1.8,18.65],[2,1.74,1.56]],"ltp":2.16,"tv":601.03,"id":31377}],"tv":1166.43}]}
{"op":"mcm","clk":"11816923665","pt":1723372108464,"mc":[{"id":"1.231581430","rc":[{"batb":[[0,1.78,15.88],[1,1.7,3],[2,1.57,8.73]],"ltp":1.76,"tv":565.4,"id":169},{"batb":[[1,2,14.13],[2,1.8,18.65]],"ltp":2.16,"tv":601.03,"id":31377}]}]}
{"op":"mcm","clk":"11816923853","pt":1723372109815,"mc":[{"id":"1.231581430","rc":[{"batb":[[1,1.8,18.65],[2,1.74,1.56]],"ltp":2.16,"tv":601.03,"id":31377}]}]}
{"op":"mcm","clk":"11816923997","pt":1723372111024,"mc":[{"id":"1.231581430","rc":[{"batb":[[0,1.7,3],[1,1.57,8.73],[2,1.55,171.53]],"ltp":1.76,"tv":565.4,"id":169}]}]}
{"op":"mcm","clk":"11816924441","pt":1723372114762,"mc":[{"id":"1.231581430","rc":[{"batb":[[1,1.98,14.25],[2,1.8,18.65]],"ltp":2.16,"tv":601.03,"id":31377}]}]}
{"op":"mcm","clk":"11816924606","pt":1723372116081,"mc":[{"id":"1.231581430","rc":[{"batb":[[1,1.8,18.65],[2,1.74,1.56]],"ltp":2.16,"tv":601.03,"id":31377}]}]}
{"op":"mcm","clk":"11816925375","pt":1723372122168,"mc":[{"id":"1.231581430","rc":[{"batb":[[0,1.81,15.61],[1,1.7,3],[2,1.57,8.73]],"ltp":1.76,"tv":565.4,"id":169},{"batb":[[1,1.96,14.41],[2,1.8,18.65]],"ltp":2.16,"tv":601.03,"id":31377}]}]}
{"op":"mcm","clk":"11816925631","pt":1723372124055,"mc":[{"id":"1.231581430","rc":[{"batb":[[0,1.7,3],[1,1.57,8.73],[2,1.55,171.53]],"ltp":1.76,"tv":565.4,"id":169},{"batb":[[1,1.8,18.65],[2,1.74,1.56]],"ltp":2.16,"tv":601.03,"id":31377}]}]}
{"op":"mcm","clk":"11816926189","pt":1723372128371,"mc":[{"id":"1.231581430","rc":[{"batl":[[1,2.74,4.12],[2,4,5.85]],"ltp":2.16,"tv":601.03,"id":31377}]}]}
{"op":"mcm","clk":"11816926537","pt":1723372131047,"mc":[{"id":"1.231581430","rc":[{"batl":[[1,4,5.85],[2,4.3,12.33]],"ltp":2.16,"tv":601.03,"id":31377}]}]}
{"op":"mcm","clk":"11816926855","pt":1723372133461,"mc":[{"id":"1.231581430","rc":[{"batl":[[2,4,7.25]],"ltp":1.76,"tv":565.4,"id":169},{"batl":[[1,4,6.2]],"ltp":2.16,"tv":601.03,"id":31377}]}]}
{"op":"mcm","clk":"11816926927","pt":1723372133992,"mc":[{"id":"1.231581430","rc":[{"batb":[[0,1.8,15.72],[1,1.7,3],[2,1.57,8.73]],"ltp":1.76,"tv":565.4,"id":169},{"batb":[[1,1.98,14.3],[2,1.8,18.65]],"ltp":2.16,"tv":601.03,"id":31377}]}]}
{"op":"mcm","clk":"11816928012","pt":1723372142505,"mc":[{"id":"1.231581430","rc":[{"batb":[[0,2.14,2.56]],"ltp":2.16,"tv":601.03,"id":31377}]}]}
{"op":"mcm","clk":"11816928061","pt":1723372142920,"mc":[{"id":"1.231581430","rc":[{"batl":[[0,2.3,31.93],[1,4,7.25],[2,4.2,12]],"ltp":1.76,"tv":565.4,"id":169}]}]}
{"op":"mcm","clk":"11816929795","pt":1723372155715,"mc":[{"id":"1.231581430","rc":[{"batb":[[0,2.16,9.96],[1,2.14,2.56],[2,1.98,14.3]],"ltp":2.16,"tv":601.03,"id":31377}]}]}
{"op":"mcm","clk":"11816929911","pt":1723372156553,"mc":[{"id":"1.231581430","rc":[{"batb":[[0,1.7,3],[1,1.57,8.73],[2,1.55,171.53]],"ltp":1.76,"tv":565.4,"id":169},{"batb":[[2,1.8,18.65]],"ltp":2.16,"tv":601.03,"id":31377}]}]}
{"op":"mcm","clk":"11816930187","pt":1723372158692,"mc":[{"id":"1.231581430","rc":[{"batl":[[1,2.76,4.12],[2,4,6.2]],"ltp":2.16,"tv":601.03,"id":31377}]}]}
{"op":"mcm","clk":"11816930833","pt":1723372163409,"mc":[{"id":"1.231581430","rc":[{"trd":[[1.87,17.4],[1.88,13.75]],"batb":[[0,1.78,15.88],[1,1.7,3],[2,1.57,8.73]],"ltp":1.88,"tv":579.57,"id":169},{"trd":[[2.14,43.89],[2.16,30.06]],"batb":[[0,2,14.13],[1,1.8,18.65],[2,1.74,1.56]],"batl":[[0,2.14,11.6],[1,2.4,5],[2,2.76,4.12]],"ltp":2.14,"tv":613.76,"id":31377}],"tv":1193.33}]}
{"op":"mcm","clk":"11816930928","pt":1723372164094,"mc":[{"id":"1.231581430","rc":[{"batb":[[0,1.7,3],[1,1.57,8.73],[2,1.55,171.53]],"ltp":1.88,"tv":579.57,"id":169},{"batb":[[0,1.8,18.65],[1,1.74,1.56],[2,1.7,3.49]],"batl":[[0,2.4,5],[1,2.76,4.12],[2,4,6.2]],"ltp":2.14,"tv":613.76,"id":31377}]}]}
{"op":"mcm","clk":"11816931100","pt":1723372165298,"mc":[{"id":"1.231581430","rc":[{"batl":[[0,2.42,1.13],[1,4,6.55]],"ltp":1.88,"tv":579.57,"id":169}]}]}
{"op":"mcm","clk":"11816931224","pt":1723372166129,"mc":[{"id":"1.231581430","rc":[{"batb":[[1,1.75,7.68],[2,1.74,1.09]],"ltp":2.14,"tv":613.76,"id":31377}]}]}
{"op":"mcm","clk":"11816931783","pt":1723372170319,"mc":[{"id":"1.231581430","rc":[{"batb":[[0,1.81,15.61],[1,1.7,3],[2,1.57,8.73]],"ltp":1.88,"tv":579.57,"id":169},{"batb":[[0,1.96,14.41],[1,1.8,18.65],[2,1.75,7.68]],"ltp":2.14,"tv":613.76,"id":31377}]}]}
{"op":"mcm","clk":"11816931884","pt":1723372171164,"mc":[{"id":"1.231581430","rc":[{"batl":[[0,3.95,1.04],[1,4,6.28]],"ltp":1.88,"tv":579.57,"id":169},{"batb":[[2,1.75,7.21]],"batl":[[2,4,5.85]],"ltp":2.14,"tv":613.76,"id":31377}]}]}
{"op":"mcm","clk":"11816932485","pt":1723372175722,"mc":[{"id":"1.231581430","rc":[{"batb":[[2,1.74,1.09]],"batl":[[1,4,5.85],[2,4.3,12.33]],"ltp":2.14,"tv":613.76,"id":31377}]}]}
{"op":"mcm","clk":"11816933231","pt":1723372181449,"mc":[{"id":"1.231581430","rc":[{"batb":[[0,1.7,3],[1,1.57,8.73],[2,1.55,171.53]],"ltp":1.88,"tv":579.57,"id":169},{"batb":[[0,1.8,18.75],[1,1.74,1.09],[2,1.7,3.49]],"ltp":2.14,"tv":613.76,"id":31377}]}]}
{"op":"mcm","clk":"11816933757","pt":1723372185559,"mc":[{"id":"1.231581430","rc":[{"batb":[[0,1.79,15.76],[1,1.7,3],[2,1.57,8.73]],"ltp":1.88,"tv":579.57,"id":169},{"batb":[[0,1.98,14.25],[1,1.8,18.75],[2,1.74,1.09]],"ltp":2.14,"tv":613.76,"id":31377}]}]}
{"op":"mcm","clk":"11816933931","pt":1723372186876,"mc":[{"id":"1.231581430","rc":[{"batb":[[0,1.7,3],[1,1.57,8.73],[2,1.55,171.53]],"ltp":1.88,"tv":579.57,"id":169},{"batb":[[0,1.8,18.75],[1,1.74,1.09],[2,1.7,3.49]],"ltp":2.14,"tv":613.76,"id":31377}]}]}
{"op":"mcm","clk":"11816935258","pt":1723372196391,"mc":[{"id":"1.231581430","rc":[{"batl":[[0,2.42,1.13],[1,4,6.55]],"ltp":1.88,"tv":579.57,"id":169},{"batl":[[1,2.64,4.12],[2,4,6.2]],"ltp":2.14,"tv":613.76,"id":31377}]}]}
{"op":"mcm","clk":"11816935339","pt":1723372196962,"mc":[{"id":"1.231581430","rc":[{"trd":[[1.71,0.1]],"batb":[[0,1.86,15.21],[1,1.7,3],[2,1.57,9.29]],"batl":[[0,1.95,4.04],[1,4,7.25]],"ltp":1.71,"tv":579.67,"id":169},{"trd":[[2.4,0.07]],"batb":[[0,1.91,14.81],[1,1.8,18.75],[2,1.74,1.56]],"batl":[[0,2.4,4.93]],"ltp":2.4,"tv":613.83,"id":31377}],"tv":1193.51}]}
{"op":"mcm","clk":"11816935486","pt":1723372198184,"mc":[{"id":"1.231581430","rc":[{"batb":[[0,1.7,3],[1,1.57,9.29],[2,1.55,171.53]],"ltp":1.71,"tv":579.67,"id":169},{"batb":[[0,1.8,18.75],[1,1.74,1.56],[2,1.7,3.49]],"batl":[[1,4,6.2],[2,4.3,12.33]],"ltp":2.4,"tv":613.83,"id":31377}]}]}
{"op":"mcm","clk":"11816936142","pt":1723372202275,"mc":[{"id":"1.231581430","rc":[{"batb":[[0,2.36,1.57],[1,1.8,18.75],[2,1.74,1.56]],"ltp":2.4,"tv":613.83,"id":31377}]}]}
{"op":"mcm","clk":"11816936296","pt":1723372203166,"mc":[{"id":"1.231581430","rc":[{"batb":[[1,1.93,14.65],[2,1.8,18.75]],"batl":[[1,2.62,4.12],[2,4,6.2]],"ltp":2.4,"tv":613.83,"id":31377}]}]}
{"op":"mcm","clk":"11816936535","pt":1723372204595,"mc":[{"id":"1.231581430","rc":[{"batb":[[1,1.8,18.75],[2,1.74,1.56]],"ltp":2.4,"tv":613.83,"id":31377}]}]}
{"op":"mcm","clk":"11816937706","pt":1723372212202,"mc":[{"id":"1.231581430","rc":[{"batl":[[1,4,6.2],[2,4.3,12.33]],"ltp":2.4,"tv":613.83,"id":31377}]}]}
{"op":"mcm","clk":"11816937951","pt":1723372213881,"mc":[{"id":"1.231581430","rc":[{"batb":[[0,1.8,18.75],[1,1.74,1.56],[2,1.7,3.49]],"ltp":2.4,"tv":613.83,"id":31377}]}]}
{"op":"mcm","clk":"11816938413","pt":1723372217204,"mc":[{"id":"1.231581430","rc":[{"batb":[[0,1.7,3.1]],"batl":[[0,1.93,2.09],[1,1.95,3.61],[2,4,7.25]],"ltp":1.71,"tv":579.67,"id":169}]}]}
{"op":"mcm","clk":"11816939502","pt":1723372224511,"mc":[{"id":"1.231581430","rc":[{"batl":[[2,4,6.9]],"ltp":1.71,"tv":579.67,"id":169},{"batl":[[1,4,5.85]],"ltp":2.4,"tv":613.83,"id":31377}]}]}
{"op":"mcm","clk":"11816939567","pt":1723372224906,"mc":[{"id":"1.231581430","rc":[{"batb":[[2,1.7,3]],"ltp":2.4,"tv":613.83,"id":31377}]}]}
{"op":"mcm","clk":"11816940113","pt":1723372228432,"mc":[{"id":"1.231581430","rc":[{"batb":[[0,1.78,15.94],[1,1.7,3],[2,1.57,9.29]],"ltp":1.71,"tv":579.67,"id":169},{"batb":[[0,1.99,14.18],[1,1.8,18.75],[2,1.74,1.56]],"ltp":2.4,"tv":613.83,"id":31377}]}]}
{"op":"mcm","clk":"11816940433","pt":1723372230430,"mc":[{"id":"1.231581430","rc":[{"batb":[[0,1.7,3.1],[1,1.57,9.29],[2,1.55,171.53]],"batl":[[0,1.95,4.04],[1,4,6.9],[2,4.2,12]],"ltp":1.71,"tv":579.67,"id":169},{"batb":[[0,1.8,18.75],[1,1.74,1.56],[2,1.7,3]],"ltp":2.4,"tv":613.83,"id":31377}]}]}
{"op":"mcm","clk":"11816940669","pt":1723372232006,"mc":[{"id":"1.231581430","rc":[{"batb":[[0,2.1,10.5],[1,1.8,18.75],[2,1.74,1.56]],"ltp":2.4,"tv":613.83,"id":31377}]}]}
{"op":"mcm","clk":"11816941173","pt":1723372235419,"mc":[{"id":"1.231581430","rc":[{"batb":[[0,1.82,15.49],[1,1.7,3],[2,1.57,9.29]],"ltp":1.71,"tv":579.67,"id":169},{"batb":[[1,1.94,14.53],[2,1.8,18.75]],"batl":[[1,2.66,4.12],[2,4,5.85]],"ltp":2.4,"tv":613.83,"id":31377}]}]}
{"op":"mcm","clk":"11816941187","pt":1723372235516,"mc":[{"id":"1.231581430","rc":[{"batl":[[0,1.91,1.66],[1,1.95,4.04],[2,4,6.9]],"ltp":1.71,"tv":579.67,"id":169}]}]}
{"op":"mcm","clk":"11816941459","pt":1723372237433,"mc":[{"id":"1.231581430","rc":[{"batb":[[1,1.74,45],[2,1.7,3]],"ltp":1.71,"tv":579.67,"id":169},{"batl":[[1,4,5.85],[2,4.3,12.33]],"ltp":2.4,"tv":613.83,"id":31377}]}]}
{"op":"mcm","clk":"11816941853","pt":1723372240145,"mc":[{"id":"1.231581430","rc":[{"batb":[[2,1.85,22.5]],"ltp":2.4,"tv":613.83,"id":31377}]}]}
{"op":"mcm","clk":"11816941940","pt":1723372240743,"mc":[{"id":"1.231581430","rc":[{"batl":[[0,1.95,4.04],[1,4,6.9],[2,4.2,12]],"ltp":1.71,"tv":579.67,"id":169}]}]}
{"op":"mcm","clk":"11816942207","pt":1723372242339,"mc":[{"id":"1.231581430","rc":[{"trd":[[1.91,13.13]],"ltp":1.91,"tv":581.67,"id":169},{"trd":[[2.1,31.03]],"batb":[[0,2.1,8.68]],"batl":[[1,2.62,4.12],[2,4,5.85]],"ltp":2.1,"tv":615.65,"id":31377}],"tv":1197.33}]}
{"op":"mcm","clk":"11816943229","pt":1723372249438,"mc":[{"id":"1.231581430","rc":[{"batl":[[1,4,7.25]],"ltp":1.91,"tv":581.67,"id":169},{"batl":[[2,4,6.2]],"ltp":2.1,"tv":615.65,"id":31377}]}]}
{"op":"mcm","clk":"11816943597","pt":1723372252056,"mc":[{"id":"1.231581430","rc":[{"batl":[[1,4,6.2],[2,4.3,12.33]],"ltp":2.1,"tv":615.65,"id":31377}]}]}
{"op":"mcm","clk":"11816946376","pt":1723372273787,"mc":[{"id":"1.231581430","rc":[{"batb":[[0,1.74,45],[1,1.7,3],[2,1.57,9.29]],"ltp":1.91,"tv":581.67,"id":169},{"batb":[[1,1.85,22.5],[2,1.8,18.65]],"ltp":2.1,"tv":615.65,"id":31377}]}]}
{"op":"mcm","clk":"11816946777","pt":1723372276984,"mc":[{"id":"1.231581430","rc":[{"batb":[[2,1.57,8.73]],"batl":[[1,4,6.9]],"ltp":1.91,"tv":581.67,"id":169},{"batl":[[1,4,5.85]],"ltp":2.1,"tv":615.65,"id":31377}]}]}
{"op":"mcm","clk":"11816947008","pt":1723372278672,"mc":[{"id":"1.231581430","rc":[{"batb":[[0,1.8,15.69],[1,1.74,45],[2,1.7,3]],"ltp":1.91,"tv":581.67,"id":169},{"batb":[[1,1.97,14.33],[2,1.85,22.5]],"ltp":2.1,"tv":615.65,"id":31377}]}]}
{"op":"mcm","clk":"11816947212","pt":1723372280190,"mc":[{"id":"1.231581430","rc":[{"batb":[[0,1.74,45],[1,1.7,3],[2,1.57,8.73]],"ltp":1.91,"tv":581.67,"id":169},{"batb":[[1,1.85,22.5],[2,1.8,18.65]],"ltp":2.1,"tv":615.65,"id":31377}]}]}
{"op":"mcm","clk":"11816947437","pt":1723372281873,"mc":[{"id":"1.231581430","rc":[{"trd":[[2.1,48.39]],"batb":[[0,1.85,22.5],[1,1.8,18.65],[2,1.74,1.09]],"batl":[[0,2.1,41.32],[1,2.4,4.93],[2,4,5.85]],"ltp":2.1,"tv":633.01,"id":31377}],"tv":1214.69}]}
{"op":"mcm","clk":"11816949099","pt":1723372294376,"mc":[{"id":"1.231581430","rc":[{"trd":[[1.9,45.67]],"batl":[[0,1.9,205.26],[1,1.95,4.04],[2,4,6.9]],"ltp":1.9,"tv":627.34,"id":169},{"trd":[[2.1,89.71]],"batl":[[0,2.4,4.93],[1,4,5.85],[2,4.3,12.33]],"ltp":2.1,"tv":674.33,"id":31377}],"tv":1301.67}]}
{"op":"mcm","clk":"11816949239","pt":1723372295476,"mc":[{"id":"1.231581430","rc":[{"batl":[[0,1.88,270.49],[1,1.9,205.26],[2,1.95,4.04]],"ltp":1.9,"tv":627.34,"id":169}]}]}
{"op":"mcm","clk":"11816949779","pt":1723372299986,"mc":[{"id":"1.231581430","rc":[{"batl":[[1,4,6.2]],"ltp":2.1,"tv":674.33,"id":31377}]}]}
{"op":"mcm","clk":"11816949908","pt":1723372300987,"mc":[{"id":"1.231581430","rc":[{"batb":[[0,2.1,9.02],[1,1.85,22.5],[2,1.8,18.65]],"ltp":2.1,"tv":674.33,"id":31377}]}]}
{"op":"mcm","clk":"11816950009","pt":1723372301818,"mc":[{"id":"1.231581430","rc":[{"batl":[[1,1.9,211.57]],"ltp":1.9,"tv":627.34,"id":169}]}]}
{"op":"mcm","clk":"11816950232","pt":1723372303507,"mc":[{"id":"1.231581430","rc":[{"batb":[[2,1.61,22.59]],"ltp":1.9,"tv":627.34,"id":169}]}]}
{"op":"mcm","clk":"11816950403","pt":1723372305026,"mc":[{"id":"1.231581430","rc":[{"batb":[[0,1.7,3],[1,1.61,22.59],[2,1.57,8.64]],"batl":[[0,1.88,270.57]],"ltp":1.9,"tv":627.34,"id":169}]}]}
{"op":"mcm","clk":"11816950469","pt":1723372305606,"mc":[{"id":"1.231581430","rc":[{"batl":[[1,1.9,205.26]],"ltp":1.9,"tv":627.34,"id":169}]}]}
{"op":"mcm","clk":"11816951056","pt":1723372310188,"mc":[{"id":"1.231581430","rc":[{"batb":[[0,2.36,9.02],[1,2.1,9.02],[2,1.85,22.5]],"ltp":2.1,"tv":674.33,"id":31377}]}]}
{"op":"mcm","clk":"11816951825","pt":1723372316535,"mc":[{"id":"1.231581430","rc":[{"trd":[[1.7,0.02],[1.71,7.02]],"batb":[[0,1.7,2.99]],"ltp":1.7,"tv":634.28,"id":169},{"trd":[[2.4,5]],"batl":[[0,4,6.2],[1,4.3,12.33],[2,1000,0.12]],"ltp":2.4,"tv":679.26,"id":31377}],"tv":1313.54}]}
{"op":"mcm","clk":"11816952714","pt":1723372323821,"mc":[{"id":"1.231581430","rc":[{"trd":[[1.67,0.09],[1.7,3.01]],"batb":[[0,1.61,22.5],[1,1.57,8.64],[2,1.55,172.17]],"ltp":1.67,"tv":637.36,"id":169},{"trd":[[2.44,2.08],[2.5,0.06]],"batb":[[0,2.5,9.16],[1,2.36,9.02],[2,2.1,9.02]],"ltp":2.5,"tv":681.4,"id":31377}],"tv":1318.76}]}
{"op":"mcm","clk":"11816952911","pt":1723372325471,"mc":[{"id":"1.231581430","rc":[{"batl":[[0,1.71,45.08],[1,1.88,270.57],[2,1.9,205.26]],"ltp":1.67,"tv":637.36,"id":169},{"batb":[[0,2.36,9.02],[1,2.1,9.02],[2,1.85,22.5]],"ltp":2.5,"tv":681.4,"id":31377}]}]}
{"op":"mcm","clk":"11816953254","pt":1723372328448,"mc":[{"id":"1.231581430","rc":[{"batl":[[2,1.95,4.04]],"ltp":1.67,"tv":637.36,"id":169}]}]}
{"op":"mcm","clk":"11816953345","pt":1723372329369,"mc":[{"id":"1.231581430","rc":[{"batl":[[1,1.88,272.35]],"ltp":1.67,"tv":637.36,"id":169},{"batb":[[0,2.5,2.14],[1,2.36,9.02],[2,2.1,9.02]],"ltp":2.5,"tv":681.4,"id":31377}]}]}
{"op":"mcm","clk":"11816953568","pt":1723372330861,"mc":[{"id":"1.231581430","rc":[{"batb":[[0,2.36,9.02],[1,2.1,9.02],[2,1.85,22.5]],"ltp":2.5,"tv":681.4,"id":31377}]}]}
{"op":"mcm","clk":"11816953759","pt":1723372332337,"mc":[{"id":"1.231581430","rc":[{"batl":[[1,1.88,270.57]],"ltp":1.67,"tv":637.36,"id":169}]}]}
{"op":"mcm","clk":"11816954227","pt":1723372335876,"mc":[{"id":"1.231581430","rc":[{"batl":[[2,2.6,1.13]],"ltp":1.67,"tv":637.36,"id":169}]}]}
{"op":"mcm","clk":"11816954385","pt":1723372337117,"mc":[{"id":"1.231581430","rc":[{"batb":[[0,2.5,11.3],[1,2.36,9.02],[2,2.1,9.02]],"ltp":2.5,"tv":681.4,"id":31377}]}]}
{"op":"mcm","clk":"11816954462","pt":1723372337677,"mc":[{"id":"1.231581430","rc":[{"batb":[[0,2.36,9.02],[1,2.1,9.02],[2,1.85,22.5]],"ltp":2.5,"tv":681.4,"id":31377}]}]}
{"op":"mcm","clk":"11816955169","pt":1723372343395,"mc":[{"id":"1.231581430","rc":[{"batl":[[2,3.95,1.04]],"ltp":1.67,"tv":637.36,"id":169},{"batl":[[0,4,5.85]],"ltp":2.5,"tv":681.4,"id":31377}]}]}
{"op":"mcm","clk":"11816955249","pt":1723372343973,"mc":[{"id":"1.231581430","rc":[{"batb":[[0,2.5,11.26],[1,2.36,9.02],[2,2.1,9.02]],"ltp":2.5,"tv":681.4,"id":31377}]}]}
{"op":"mcm","clk":"11816955466","pt":1723372345563,"mc":[{"id":"1.231581430","rc":[{"batb":[[0,2.36,9.02],[1,2.1,9.02],[2,1.85,22.5]],"ltp":2.5,"tv":681.4,"id":31377}]}]}
{"op":"mcm","clk":"11816955856","pt":1723372348567,"mc":[{"id":"1.231581430","rc":[{"batb":[[2,1.44,10.07]],"ltp":1.67,"tv":637.36,"id":169}]}]}
{"op":"mcm","clk":"11816956316","pt":1723372351875,"mc":[{"id":"1.231581430","rc":[{"batb":[[2,1.5,19.41]],"batl":[[0,1.69,3.61],[1,1.71,45.08],[2,1.88,270.57]],"ltp":1.67,"tv":637.36,"id":169},{"batb":[[0,2.5,11.26],[1,2.36,9.02],[2,2.1,9.02]],"ltp":2.5,"tv":681.4,"id":31377}]}]}
{"op":"mcm","clk":"11816956689","pt":1723372354511,"mc":[{"id":"1.231581430","rc":[{"batb":[[2,1.44,10.07]],"ltp":1.67,"tv":637.36,"id":169},{"batb":[[0,2.36,9.02],[1,2.1,9.02],[2,1.85,22.5]],"ltp":2.5,"tv":681.4,"id":31377}]}]}
{"op":"mcm","clk":"11816956819","pt":1723372355298,"mc":[{"id":"1.231581430","rc":[{"batb":[[0,2.1,9.02],[1,1.85,22.5],[2,1.8,18.65]],"ltp":2.5,"tv":681.4,"id":31377}]}]}
{"op":"mcm","clk":"11816956966","pt":1723372356296,"mc":[{"id":"1.231581430","rc":[{"batb":[[0,1.85,22.5],[1,1.8,18.65],[2,1.74,1.09]],"ltp":2.5,"tv":681.4,"id":31377}]}]}
{"op":"mcm","clk":"11816957052","pt":1723372356980,"mc":[{"id":"1.231581430","rc":[{"batb":[[0,1.57,8.64],[1,1.44,10.07],[2,1.38,343.05]],"ltp":1.67,"tv":637.36,"id":169},{"batb":[[0,1.8,18.65],[1,1.74,1.09],[2,1.7,3]],"ltp":2.5,"tv":681.4,"id":31377}]}]}
{"op":"mcm","clk":"11816957230","pt":1723372358300,"mc":[{"id":"1.231581430","rc":[{"batb":[[2,1.41,343.05]],"batl":[[1,1.7,3.43],[2,1.71,45.08]],"ltp":1.67,"tv":637.36,"id":169}]}]}
{"op":"mcm","clk":"11816957499","pt":1723372360110,"mc":[{"id":"1.231581430","rc":[{"trd":[[1.57,0.19]],"batb":[[0,1.57,8.55],[1,1.5,19.41],[2,1.44,9.43]],"ltp":1.57,"tv":637.55,"id":169},{"batb":[[0,2.5,11.26],[1,1.8,18.65],[2,1.74,1.09]],"ltp":2.5,"tv":681.4,"id":31377}],"tv":1318.95}]}
{"op":"mcm","clk":"11816957688","pt":1723372361414,"mc":[{"id":"1.231581430","rc":[{"batb":[[0,1.8,18.65],[1,1.74,1.09],[2,1.7,3]],"ltp":2.5,"tv":681.4,"id":31377}]}]}
{"op":"mcm","clk":"11816958331","pt":1723372366319,"mc":[{"id":"1.231581430","rc":[{"batb":[[1,1.53,1.07],[2,1.5,18.77]],"ltp":1.57,"tv":637.55,"id":169},{"batb":[[0,2.54,11.15],[1,1.8,18.65],[2,1.74,1.09]],"ltp":2.5,"tv":681.4,"id":31377}]}]}
{"op":"mcm","clk":"11816958507","pt":1723372367690,"mc":[{"id":"1.231581430","rc":[{"batb":[[0,1.53,1.07],[1,1.5,18.77],[2,1.44,9.43]],"ltp":1.57,"tv":637.55,"id":169}]}]}
{"op":"mcm","clk":"11816958906","pt":1723372370836,"mc":[{"id":"1.231581430","rc":[{"batb":[[2,1.44,6.28]],"ltp":1.57,"tv":637.55,"id":169}]}]}
{"op":"mcm","clk":"11816959381","pt":1723372374400,"mc":[{"id":"1.231581430","rc":[{"batb":[[0,1.53,1.17]],"ltp":1.57,"tv":637.55,"id":169}]}]}
{"op":"mcm","clk":"11816959511","pt":1723372375435,"mc":[{"id":"1.231581430","rc":[{"batb":[[0,1.62,53.53],[1,1.53,1.17],[2,1.5,18.77]],"ltp":1.57,"tv":637.55,"id":169}]}]}
{"op":"mcm","clk":"11816959690","pt":1723372376851,"mc":[{"id":"1.231581430","rc":[{"batb":[[2,1.44,6.28]],"ltp":1.57,"tv":637.55,"id":169},{"batb":[[0,1.8,18.65],[1,1.74,1.09],[2,1.7,3]],"ltp":2.5,"tv":681.4,"id":31377}]}]}
{"op":"mcm","clk":"11816960366","pt":1723372381913,"mc":[{"id":"1.231581430","rc":[{"batb":[[1,1.56,3.26],[2,1.53,1.07]],"ltp":1.57,"tv":637.55,"id":169}]}]}
{"op":"mcm","clk":"11816960521","pt":1723372383130,"mc":[{"id":"1.231581430","rc":[{"batb":[[0,2.5,11.3],[1,1.8,18.65],[2,1.74,1.09]],"batl":[[0,4.3,12.68],[1,1000,0.12],[2,1000,0]],"ltp":2.5,"tv":681.4,"id":31377}]}]}
{"op":"mcm","clk":"11816960697","pt":1723372384548,"mc":[{"id":"1.231581430","rc":[{"batb":[[0,1.8,18.65],[1,1.74,1.09],[2,1.7,3]],"ltp":2.5,"tv":681.4,"id":31377}]}]}
{"op":"mcm","clk":"11816961102","pt":1723372387647,"mc":[{"id":"1.231581430","rc":[{"batl":[[1,7,5.5],[2,1000,0.12]],"ltp":2.5,"tv":681.4,"id":31377}]}]}
{"op":"mcm","clk":"11816961558","pt":1723372390844,"mc":[{"id":"1.231581430","rc":[{"batb":[[0,2.48,11.41],[1,1.86,22.5],[2,1.8,18.65]],"ltp":2.5,"tv":681.4,"id":31377}]}]}
{"op":"mcm","clk":"11816961797","pt":1723372392635,"mc":[{"id":"1.231581430","rc":[{"batb":[[0,1.86,22.5],[1,1.8,18.65],[2,1.74,1.09]],"ltp":2.5,"tv":681.4,"id":31377}]}]}
{"op":"mcm","clk":"11816962130","pt":1723372395363,"mc":[{"id":"1.231581430","rc":[{"trd":[[1.69,0.27]],"batl":[[0,1.69,5.12]],"ltp":1.69,"tv":637.82,"id":169},{"trd":[[2.44,2.27]],"ltp":2.44,"tv":681.59,"id":31377}],"tv":1319.41}]}
{"op":"mcm","clk":"11816962508","pt":1723372398158,"mc":[{"id":"1.231581430","rc":[{"trd":[[1.62,12.62]],"batb":[[0,1.62,47.22]],"ltp":1.62,"tv":650.44,"id":169}],"tv":1332.03}]}
{"op":"mcm","clk":"11816963037","pt":1723372401471,"mc":[{"id":"1.231581430","rc":[{"batb":[[0,1.64,3.07],[1,1.62,47.22],[2,1.56,3.26]],"batl":[[0,1.69,3.34]],"ltp":1.62,"tv":650.44,"id":169}]}]}
{"op":"mcm","clk":"11816963571","pt":1723372405157,"mc":[{"id":"1.231581430","rc":[{"batb":[[2,1.53,1.17]],"ltp":1.62,"tv":650.44,"id":169}]}]}
{"op":"mcm","clk":"11816963740","pt":1723372406463,"mc":[{"id":"1.231581430","rc":[{"batl":[[0,1.68,1.78],[1,1.69,3.34]],"ltp":1.62,"tv":650.44,"id":169}]}]}
{"op":"mcm","clk":"11816964240","pt":1723372410572,"mc":[{"id":"1.231581430","rc":[{"batb":[[0,1.64,3.17]],"ltp":1.62,"tv":650.44,"id":169}]}]}
{"op":"mcm","clk":"11816965573","pt":1723372420420,"mc":[{"id":"1.231581430","rc":[{"batl":[[0,4.3,12.33]],"ltp":2.44,"tv":681.59,"id":31377}]}]}
{"op":"mcm","clk":"11816965620","pt":1723372420835,"mc":[{"id":"1.231581430","rc":[{"batb":[[2,1.44,6.81]],"ltp":1.62,"tv":650.44,"id":169}]}]}
{"op":"mcm","clk":"11816966824","pt":1723372428998,"mc":[{"id":"1.231581430","rc":[{"batb":[[0,2.5,7.7],[1,2.48,11.41],[2,1.86,22.5]],"ltp":2.44,"tv":681.59,"id":31377}]}]}
{"op":"mcm","clk":"11816966949","pt":1723372430048,"mc":[{"id":"1.231581430","rc":[{"batb":[[1,1.86,22.5],[2,1.8,18.65]],"ltp":2.44,"tv":681.59,"id":31377}]}]}
{"op":"mcm","clk":"11816967239","pt":1723372432138,"mc":[{"id":"1.231581430","rc":[{"batb":[[1,1.92,5.67],[2,1.86,22.5]],"batl":[[0,3.75,3.09],[1,4.3,12.33],[2,7,5.5]],"ltp":2.44,"tv":681.59,"id":31377}]}]}
{"op":"mcm","clk":"11816967308","pt":1723372432715,"mc":[{"id":"1.231581430","rc":[{"trd":[[2.5,0.24]],"batb":[[0,2.5,7.61]],"ltp":2.5,"tv":681.77,"id":31377}],"tv":1332.21}]}
{"op":"mcm","clk":"11816967521","pt":1723372434452,"mc":[{"id":"1.231581430","rc":[{"batb":[[1,1.86,22.5],[2,1.8,18.65]],"batl":[[0,4.3,12.33],[1,7,5.5],[2,1000,0.12]],"ltp":2.5,"tv":681.77,"id":31377}]}]}
{"op":"mcm","clk":"11816967561","pt":1723372434724,"mc":[{"id":"1.231581430","rc":[{"batl":[[0,1.69,3.34],[1,1.71,45.08],[2,1.88,270.57]],"ltp":1.62,"tv":650.44,"id":169}]}]}
{"op":"mcm","clk":"11816967746","pt":1723372436044,"mc":[{"id":"1.231581430","rc":[{"trd":[[2.5,0.44]],"batb":[[0,2.5,7.51]],"ltp":2.5,"tv":681.97,"id":31377}],"tv":1332.41}]}
{"op":"mcm","clk":"11816968211","pt":1723372439336,"mc":[{"id":"1.231581430","rc":[{"batl":[[0,3.45,3.09],[1,4.3,12.33],[2,7,5.5]],"ltp":2.5,"tv":681.97,"id":31377}]}]}
{"op":"mcm","clk":"11816968234","pt":1723372439540,"mc":[{"id":"1.231581430","rc":[{"batb":[[1,2.12,5.67],[2,1.86,22.5]],"ltp":2.5,"tv":681.97,"id":31377}]}]}
{"op":"mcm","clk":"11816968755","pt":1723372443540,"mc":[{"id":"1.231581430","rc":[{"trd":[[1.67,3.09]],"ltp":1.67,"tv":653.44,"id":169},{"trd":[[2.5,2.44]],"batb":[[0,2.5,5.51]],"ltp":2.5,"tv":683.97,"id":31377}],"tv":1337.41}]}
{"op":"mcm","clk":"11816970451","pt":1723372457065,"mc":[{"id":"1.231581430","rc":[{"trd":[[1.66,0.2]],"batb":[[0,1.62,47.22],[1,1.44,6.81],[2,1.41,343.05]],"batl":[[0,1.64,5.85],[1,1.69,3.34],[2,1.71,45.08]],"ltp":1.66,"tv":653.64,"id":169},{"batb":[[0,2.12,5.67],[1,1.86,22.5],[2,1.8,18.65]],"ltp":2.5,"tv":683.97,"id":31377}],"tv":1337.61}]}
{"op":"mcm","clk":"11816971169","pt":1723372461988,"mc":[{"id":"1.231581430","rc":[{"batb":[[0,2.58,5.51],[1,2.12,5.67],[2,1.86,22.5]],"ltp":2.5,"tv":683.97,"id":31377}]}]}
{"op":"mcm","clk":"11816972074","pt":1723372468601,"mc":[{"id":"1.231581430","rc":[{"batl":[[2,1.88,270.57]],"ltp":1.66,"tv":653.64,"id":169}]}]}
{"op":"mcm","clk":"11816973264","pt":1723372478617,"mc":[{"id":"1.231581430","rc":[{"batb":[[1,1.86,22.5],[2,1.8,18.65]],"batl":[[0,4.3,12.33],[1,7,5.5],[2,1000,0.12]],"ltp":2.5,"tv":683.97,"id":31377}]}]}
{"op":"mcm","clk":"11816975486","pt":1723372496413,"mc":[{"id":"1.231581430","rc":[{"trd":[[1.62,12.68]],"batb":[[0,1.62,47.19]],"ltp":1.62,"tv":653.7,"id":169}],"tv":1337.68}]}
{"op":"mcm","clk":"11816975654","pt":1723372497893,"mc":[{"id":"1.231581430","rc":[{"batb":[[1,1.93,5.67],[2,1.86,22.5]],"batl":[[0,3.75,3.09],[1,4.3,12.33],[2,7,5.5]],"ltp":2.5,"tv":683.97,"id":31377}]}]}
{"op":"mcm","clk":"11816975977","pt":1723372500323,"mc":[{"id":"1.231581430","rc":[{"batb":[[1,1.86,22.5],[2,1.8,18.65]],"batl":[[0,4.3,12.33],[1,7,5.5],[2,1000,0.12]],"ltp":2.5,"tv":683.97,"id":31377}]}]}
{"op":"mcm","clk":"11816976646","pt":1723372505480,"mc":[{"id":"1.231581430","rc":[{"batb":[[1,2.12,5.67],[2,1.86,22.5]],"ltp":2.5,"tv":683.97,"id":31377}]}]}
{"op":"mcm","clk":"11816976682","pt":1723372505739,"mc":[{"id":"1.231581430","rc":[{"batb":[[1,1.86,22.5],[2,1.8,18.65]],"ltp":2.5,"tv":683.97,"id":31377}]}]}
{"op":"mcm","clk":"11816979226","pt":1723372525959,"mc":[{"id":"1.231581430","rc":[{"trd":[[1.64,0.1]],"batl":[[0,1.69,3.34],[1,1.88,270.57],[2,4,6.98]],"ltp":1.64,"tv":653.8,"id":169},{"trd":[[2.58,0.06]],"batb":[[0,2.58,5.45]],"ltp":2.58,"tv":684.03,"id":31377}],"tv":1337.84}]}
{"op":"mcm","clk":"11816979642","pt":1723372529273,"mc":[{"id":"1.231581430","rc":[{"batb":[[0,1.86,22.5],[1,1.8,18.65],[2,1.74,1.09]],"ltp":2.58,"tv":684.03,"id":31377}]}]}
{"op":"mcm","clk":"11816980364","pt":1723372535270,"mc":[{"id":"1.231581430","rc":[{"batl":[[0,1.88,270.57],[1,4,6.98],[2,4.2,12]],"ltp":1.64,"tv":653.8,"id":169},{"batb":[[0,2.12,10.3],[1,1.86,22.5],[2,1.8,18.65]],"batl":[[0,3.8,3.09],[1,4.3,12.33],[2,7,5.5]],"ltp":2.58,"tv":684.03,"id":31377}]}]}
{"op":"mcm","clk":"11816980425","pt":1723372535696,"mc":[{"id":"1.231581430","rc":[{"batb":[[1,1.52,19.08],[2,1.44,6.28]],"ltp":1.64,"tv":653.8,"id":169},{"batb":[[0,2.46,11.47],[1,2.12,10.3],[2,1.86,22.5]],"ltp":2.58,"tv":684.03,"id":31377}]}]}
{"op":"mcm","clk":"11816980621","pt":1723372537343,"mc":[{"id":"1.231581430","rc":[{"batb":[[0,2.12,10.3],[1,1.86,22.5],[2,1.8,18.65]],"batl":[[0,4.3,12.33],[1,7,5.5],[2,1000,0.12]],"ltp":2.58,"tv":684.03,"id":31377}]}]}
{"op":"mcm","clk":"11816981283","pt":1723372542477,"mc":[{"id":"1.231581430","rc":[{"batl":[[0,3.45,3.09],[1,4.3,12.33],[2,7,5.5]],"ltp":2.58,"tv":684.03,"id":31377}]}]}
{"op":"mcm","clk":"11816981414","pt":1723372543368,"mc":[{"id":"1.231581430","rc":[{"batb":[[0,2.46,11.47],[1,2.12,10.3],[2,1.86,22.5]],"ltp":2.58,"tv":684.03,"id":31377}]}]}
{"op":"mcm","clk":"11816981623","pt":1723372544899,"mc":[{"id":"1.231581430","rc":[{"batb":[[0,2.12,10.3],[1,1.86,22.5],[2,1.8,18.65]],"ltp":2.58,"tv":684.03,"id":31377}]}]}
{"op":"mcm","clk":"11816981819","pt":1723372546274,"mc":[{"id":"1.231581430","rc":[{"trd":[[1.74,2.21]],"batl":[[0,1.88,270.49]],"ltp":1.74,"tv":653.88,"id":169},{"trd":[[2.12,12.54],[2.34,0.06]],"batb":[[0,2.12,10.26]],"ltp":2.12,"tv":684.17,"id":31377}],"tv":1338.06}]}
{"op":"mcm","clk":"11816982300","pt":1723372549688,"mc":[{"id":"1.231581430","rc":[{"batl":[[0,4,6.98],[1,4.2,12],[2,1000,0.13]],"ltp":1.74,"tv":653.88,"id":169}]}]}
{"op":"mcm","clk":"11816982521","pt":1723372551259,"mc":[{"id":"1.231581430","rc":[{"batb":[[0,2.46,11.47]],"batl":[[0,4.3,12.33],[1,7,5.5],[2,1000,0.12]],"ltp":2.12,"tv":684.17,"id":31377}]}]}
{"op":"mcm","clk":"11816982677","pt":1723372552477,"mc":[{"id":"1.231581430","rc":[{"batb":[[0,1.86,22.5],[1,1.8,18.65],[2,1.74,1.09]],"ltp":2.12,"tv":684.17,"id":31377}]}]}
{"op":"mcm","clk":"11816982859","pt":1723372553763,"mc":[{"id":"1.231581430","rc":[{"batb":[[1,1.44,6.81],[2,1.41,343.05]],"ltp":1.74,"tv":653.88,"id":169}]}]}
{"op":"mcm","clk":"11816983009","pt":1723372554803,"mc":[{"id":"1.231581430","rc":[{"batl":[[0,1.87,270.49],[1,4,6.98],[2,4.2,12]],"ltp":1.74,"tv":653.88,"id":169}]}]}
{"op":"mcm","clk":"11816984258","pt":1723372564374,"mc":[{"id":"1.231581430","rc":[{"batb":[[0,2.46,11.47],[1,1.86,22.5],[2,1.8,18.65]],"ltp":2.12,"tv":684.17,"id":31377}]}]}
{"op":"mcm","clk":"11816984343","pt":1723372564991,"mc":[{"id":"1.231581430","rc":[{"batl":[[0,1.8,2.71],[1,1.87,270.49],[2,4,6.98]],"ltp":1.74,"tv":653.88,"id":169}]}]}
{"op":"mcm","clk":"11816984467","pt":1723372565884,"mc":[{"id":"1.231581430","rc":[{"batb":[[0,1.86,22.5],[1,1.8,18.65],[2,1.74,1.09]],"ltp":2.12,"tv":684.17,"id":31377}]}]}
{"op":"mcm","clk":"11816984884","pt":1723372569384,"mc":[{"id":"1.231581430","rc":[{"batb":[[0,2.14,5.15],[1,2.08,5.67],[2,1.86,22.5]],"batl":[[0,3.8,3.09],[1,4.3,12.33],[2,7,5.5]],"ltp":2.12,"tv":684.17,"id":31377}]}]}
{"op":"mcm","clk":"11816985160","pt":1723372571582,"mc":[{"id":"1.231581430","rc":[{"batl":[[0,4.3,12.33],[1,7,5.5],[2,1000,0.12]],"ltp":2.12,"tv":684.17,"id":31377}]}]}
{"op":"mcm","clk":"11816985841","pt":1723372576708,"mc":[{"id":"1.231581430","rc":[{"batl":[[0,3.45,3.09],[1,4.3,12.33],[2,7,5.5]],"ltp":2.12,"tv":684.17,"id":31377}]}]}
{"op":"mcm","clk":"11816986345","pt":1723372580494,"mc":[{"id":"1.231581430","rc":[{"batl":[[0,1.77,13.5],[1,1.8,2.71],[2,1.87,270.49]],"ltp":1.74,"tv":653.88,"id":169}]}]}
{"op":"mcm","clk":"11816986744","pt":1723372583496,"mc":[{"id":"1.231581430","rc":[{"batl":[[0,1.74,45],[1,1.77,13.5],[2,1.8,2.71]],"ltp":1.74,"tv":653.88,"id":169}]}]}
{"op":"mcm","clk":"11816986990","pt":1723372585439,"mc":[{"id":"1.231581430","rc":[{"batb":[[0,1.86,22.5],[1,1.8,18.65],[2,1.74,1.09]],"batl":[[0,4.3,12.33],[1,7,5.5],[2,1000,0.12]],"ltp":2.12,"tv":684.17,"id":31377}]}]}
{"op":"mcm","clk":"11816987909","pt":1723372593007,"mc":[{"id":"1.231581430","rc":[{"batl":[[0,1.73,6.49],[1,1.74,45],[2,1.77,13.5]],"ltp":1.74,"tv":653.88,"id":169}]}]}
