{"op":"mcm","clk":"11946527351","pt":1724473876910,"mc":[{"id":"1.232215600","marketDefinition":{"bspMarket":false,"turnInPlayEnabled":true,"persistenceEnabled":true,"marketBaseRate":5.0,"eventId":"33522473","eventTypeId":"4","numberOfWinners":1,"bettingType":"ODDS","marketType":"MATCH_ODDS","marketTime":"2024-08-24T15:45:00.000Z","suspendTime":"2024-08-24T15:45:00.000Z","bspReconciled":false,"complete":true,"inPlay":false,"crossMatching":true,"runnersVoidable":false,"numberOfActiveRunners":2,"betDelay":0,"status":"OPEN","runners":[{"status":"ACTIVE","sortPriority":1,"id":72857114,"name":"Boca Raton Trailblazers"},{"status":"ACTIVE","sortPriority":2,"id":67083366,"name":"New York Strikers"}],"regulators":["MR_INT"],"countryCode":"GB","discountAllowed":false,"timezone":"GMT","openDate":"2024-08-24T15:45:00.000Z","version":6093992886,"name":"Match Odds","eventName":"Boca Raton Trailblazers v New York Strikers"},"rc":[{"batb":[[0,1.03,200],[1,1.02,200],[2,1.01,220]],"ltp":0.0,"tv":0.0,"id":67083366},{"batb":[[0,1.03,200],[1,1.02,200],[2,1.01,220]],"ltp":0.0,"tv":0.0,"id":72857114}]}]}
{"op":"mcm","clk":"11946527457","pt":1724473880429,"mc":[{"id":"1.232215600","marketDefinition":{"bspMarket":false,"turnInPlayEnabled":true,"persistenceEnabled":true,"marketBaseRate":5.0,"eventId":"33522473","eventTypeId":"4","numberOfWinners":1,"bettingType":"ODDS","marketType":"MATCH_ODDS","marketTime":"2024-08-24T15:45:00.000Z","suspendTime":"2024-08-24T15:45:00.000Z","bspReconciled":false,"complete":true,"inPlay":false,"crossMatching":true,"runnersVoidable":false,"numberOfActiveRunners":2,"betDelay":0,"status":"OPEN","runners":[{"status":"ACTIVE","sortPriority":1,"id":72857114,"name":"Boca Raton Trailblazers"},{"status":"ACTIVE","sortPriority":2,"id":67083366,"name":"New York Strikers"}],"regulators":["MR_INT"],"countryCode":"GB","discountAllowed":true,"timezone":"GMT","openDate":"2024-08-24T15:45:00.000Z","version":6093992886,"name":"Match Odds","eventName":"Boca Raton Trailblazers v New York Strikers"}}]}
{"op":"mcm","clk":"11946552343","pt":1724474501386,"mc":[{"id":"1.232215600","rc":[{"batb":[[0,1.05,5.19],[1,1.03,200],[2,1.02,200]],"ltp":0.0,"tv":0.0,"id":72857114}]}]}
{"op":"mcm","clk":"11946590931","pt":1724475528817,"mc":[{"id":"1.232215600","rc":[{"batb":[[0,1.21,24.75],[1,1.05,5.19],[2,1.03,200]],"ltp":0.0,"tv":0.0,"id":72857114}]}]}
{"op":"mcm","clk":"11946593339","pt":1724475583790,"mc":[{"id":"1.232215600","rc":[{"batb":[[0,1.21,24.75],[1,1.03,200],[2,1.02,200]],"ltp":0.0,"tv":0.0,"id":67083366}]}]}
{"op":"mcm","clk":"11946703802","pt":1724477308485,"mc":[{"id":"1.232215600","rc":[{"batb":[[0,1.4,5],[1,1.21,24.75],[2,1.05,5.19]],"ltp":0.0,"tv":0.0,"id":72857114}]}]}
{"op":"mcm","clk":"11946704862","pt":1724477319496,"mc":[{"id":"1.232215600","rc":[{"batb":[[0,1.4,5],[1,1.21,24.75],[2,1.03,200]],"ltp":0.0,"tv":0.0,"id":67083366}]}]}
{"op":"mcm","clk":"11946759371","pt":1724478408667,"mc":[{"id":"1.232215600","rc":[{"batl":[[0,3,0.93]],"ltp":0.0,"tv":0.0,"id":72857114}]}]}
{"op":"mcm","clk":"11946759999","pt":1724478419673,"mc":[{"id":"1.232215600","rc":[{"batl":[[0,3,0.93]],"ltp":0.0,"tv":0.0,"id":67083366}]}]}
{"op":"mcm","clk":"11946760989","pt":1724478438686,"mc":[{"id":"1.232215600","rc":[{"batl":[[0,3.4,3.59]],"ltp":0.0,"tv":0.0,"id":72857114}]}]}
{"op":"mcm","clk":"11946761639","pt":1724478452670,"mc":[{"id":"1.232215600","rc":[{"batl":[[0,3.4,3.47]],"ltp":0.0,"tv":0.0,"id":67083366}]}]}
{"op":"mcm","clk":"11946827253","pt":1724479887801,"mc":[{"id":"1.232215600","rc":[{"batb":[[0,1.51,20],[1,1.4,5],[2,1.21,24.75]],"ltp":0.0,"tv":0.0,"id":67083366}]}]}
{"op":"mcm","clk":"11946878444","pt":1724480866971,"mc":[{"id":"1.232215600","rc":[{"batb":[[2,1.22,6.02]],"ltp":0.0,"tv":0.0,"id":67083366},{"batb":[[1,1.22,6.18],[2,1.21,24.75]],"ltp":0.0,"tv":0.0,"id":72857114}]}]}
{"op":"mcm","clk":"11946920921","pt":1724481615742,"mc":[{"id":"1.232215600","rc":[{"batl":[[0,3,1.01],[1,3.4,2.66]],"ltp":0.0,"tv":0.0,"id":72857114}]}]}
{"op":"mcm","clk":"11946921463","pt":1724481624745,"mc":[{"id":"1.232215600","rc":[{"batl":[[0,3,1.01],[1,3.4,2.54]],"ltp":0.0,"tv":0.0,"id":67083366}]}]}
{"op":"mcm","clk":"11946966002","pt":1724482106681,"mc":[{"id":"1.232215600","rc":[{"batl":[[0,3.4,3.59],[1,3.4,0]],"ltp":0.0,"tv":0.0,"id":72857114}]}]}
{"op":"mcm","clk":"11946966312","pt":1724482112717,"mc":[{"id":"1.232215600","rc":[{"batl":[[0,3.4,3.47],[1,3.4,0]],"ltp":0.0,"tv":0.0,"id":67083366}]}]}
{"op":"mcm","clk":"11947015021","pt":1724482968664,"mc":[{"id":"1.232215600","rc":[{"batb":[[0,1.52,1.76],[1,1.51,20],[2,1.4,5]],"ltp":0.0,"tv":0.0,"id":67083366}]}]}
{"op":"mcm","clk":"11947401935","pt":1724487528440,"mc":[{"id":"1.232215600","rc":[{"batl":[[0,2.5,1],[1,3.4,3.59]],"ltp":0.0,"tv":0.0,"id":72857114}]}]}
{"op":"mcm","clk":"11947404476","pt":1724487552071,"mc":[{"id":"1.232215600","rc":[{"batl":[[0,2.5,1],[1,3.4,3.47]],"ltp":0.0,"tv":0.0,"id":67083366}]}]}
{"op":"mcm","clk":"11947438520","pt":1724487889668,"mc":[{"id":"1.232215600","rc":[{"batb":[[0,1.42,8.23],[1,1.4,5],[2,1.22,6.18]],"batl":[[0,2.14,5.15],[1,2.5,1],[2,3.4,3.59]],"ltp":0.0,"tv":0.0,"id":72857114}]}]}
{"op":"mcm","clk":"11947620138","pt":1724489347963,"mc":[{"id":"1.232215600","rc":[{"batb":[[0,2.48,1.06],[1,1.52,1.76],[2,1.51,20]],"ltp":0.0,"tv":0.0,"id":67083366}]}]}
{"op":"mcm","clk":"11947620496","pt":1724489350861,"mc":[{"id":"1.232215600","rc":[{"batb":[[0,1.52,1.76],[1,1.51,20],[2,1.4,5]],"ltp":0.0,"tv":0.0,"id":67083366}]}]}
{"op":"mcm","clk":"11947622710","pt":1724489370421,"mc":[{"id":"1.232215600","rc":[{"batb":[[0,2.1,1.06],[1,1.42,8.23],[2,1.4,5]],"ltp":0.0,"tv":0.0,"id":72857114}]}]}
{"op":"mcm","clk":"11947623069","pt":1724489373588,"mc":[{"id":"1.232215600","rc":[{"batb":[[0,1.42,8.23],[1,1.4,5],[2,1.22,6.18]],"ltp":0.0,"tv":0.0,"id":72857114}]}]}
{"op":"mcm","clk":"11947625030","pt":1724489390145,"mc":[{"id":"1.232215600","rc":[{"batb":[[0,2.46,1.06],[1,1.52,1.76],[2,1.51,20]],"ltp":0.0,"tv":0.0,"id":67083366}]}]}
{"op":"mcm","clk":"11947625345","pt":1724489392737,"mc":[{"id":"1.232215600","rc":[{"batb":[[0,1.52,1.76],[1,1.51,20],[2,1.4,5]],"ltp":0.0,"tv":0.0,"id":67083366}]}]}
{"op":"mcm","clk":"11947627962","pt":1724489412974,"mc":[{"id":"1.232215600","rc":[{"batb":[[0,2.1,1.06],[1,1.42,8.23],[2,1.4,5]],"ltp":0.0,"tv":0.0,"id":72857114}]}]}
{"op":"mcm","clk":"11947628564","pt":1724489416277,"mc":[{"id":"1.232215600","rc":[{"batb":[[0,1.42,8.23],[1,1.4,5],[2,1.22,6.18]],"ltp":0.0,"tv":0.0,"id":72857114}]}]}
{"op":"mcm","clk":"11947630040","pt":1724489427180,"mc":[{"id":"1.232215600","rc":[{"batb":[[0,2.1,1.06],[1,1.42,8.23],[2,1.4,5]],"ltp":0.0,"tv":0.0,"id":72857114}]}]}
{"op":"mcm","clk":"11947630436","pt":1724489430485,"mc":[{"id":"1.232215600","rc":[{"batb":[[0,1.42,8.23],[1,1.4,5],[2,1.22,6.18]],"ltp":0.0,"tv":0.0,"id":72857114}]}]}
{"op":"mcm","clk":"11947630677","pt":1724489432674,"mc":[{"id":"1.232215600","rc":[{"batl":[[0,2.1,3.52],[1,2.14,5.15],[2,2.5,1]],"ltp":0.0,"tv":0.0,"id":72857114}]}]}
{"op":"mcm","clk":"11947630815","pt":1724489433776,"mc":[{"id":"1.232215600","rc":[{"batl":[[0,2.1,8.67],[1,2.5,1],[2,3.4,3.59]],"ltp":0.0,"tv":0.0,"id":72857114}]}]}
{"op":"mcm","clk":"11947631170","pt":1724489436795,"mc":[{"id":"1.232215600","rc":[{"batl":[[0,2.1,5.15]],"ltp":0.0,"tv":0.0,"id":72857114}]}]}
{"op":"mcm","clk":"11947632874","pt":1724489451921,"mc":[{"id":"1.232215600","rc":[{"batb":[[0,2.46,1.06],[1,1.52,1.76],[2,1.51,20]],"ltp":0.0,"tv":0.0,"id":67083366}]}]}
{"op":"mcm","clk":"11947633165","pt":1724489454211,"mc":[{"id":"1.232215600","rc":[{"batb":[[0,1.52,1.76],[1,1.51,20],[2,1.4,5]],"ltp":0.0,"tv":0.0,"id":67083366}]}]}
{"op":"mcm","clk":"11947635605","pt":1724489472914,"mc":[{"id":"1.232215600","rc":[{"batb":[[0,2.08,1.06],[1,1.42,8.23],[2,1.4,5]],"ltp":0.0,"tv":0.0,"id":72857114}]}]}
{"op":"mcm","clk":"11947635888","pt":1724489474935,"mc":[{"id":"1.232215600","rc":[{"batb":[[0,1.42,8.23],[1,1.4,5],[2,1.22,6.18]],"ltp":0.0,"tv":0.0,"id":72857114}]}]}
{"op":"mcm","clk":"11947636000","pt":1724489475612,"mc":[{"id":"1.232215600","rc":[{"batl":[[0,2.08,3.52],[1,2.1,5.15],[2,2.5,1]],"ltp":0.0,"tv":0.0,"id":72857114}]}]}
{"op":"mcm","clk":"11947636183","pt":1724489476914,"mc":[{"id":"1.232215600","rc":[{"batl":[[0,2.08,8.67],[1,2.5,1],[2,3.4,3.59]],"ltp":0.0,"tv":0.0,"id":72857114}]}]}
{"op":"mcm","clk":"11947636564","pt":1724489479723,"mc":[{"id":"1.232215600","rc":[{"batl":[[0,2.08,5.15]],"ltp":0.0,"tv":0.0,"id":72857114}]}]}
{"op":"mcm","clk":"11947637980","pt":1724489490163,"mc":[{"id":"1.232215600","rc":[{"batb":[[0,2.48,1.06],[1,1.52,1.76],[2,1.51,20]],"ltp":0.0,"tv":0.0,"id":67083366}]}]}
{"op":"mcm","clk":"11947638269","pt":1724489492150,"mc":[{"id":"1.232215600","rc":[{"batb":[[0,1.52,1.76],[1,1.51,20],[2,1.4,5]],"ltp":0.0,"tv":0.0,"id":67083366}]}]}
{"op":"mcm","clk":"11947640232","pt":1724489507775,"mc":[{"id":"1.232215600","rc":[{"batb":[[0,2.06,1.06],[1,1.42,8.23],[2,1.4,5]],"ltp":0.0,"tv":0.0,"id":72857114}]}]}
{"op":"mcm","clk":"11947640503","pt":1724489510103,"mc":[{"id":"1.232215600","rc":[{"batb":[[0,1.42,8.23],[1,1.4,5],[2,1.22,6.18]],"ltp":0.0,"tv":0.0,"id":72857114}]}]}
{"op":"mcm","clk":"11947640568","pt":1724489510722,"mc":[{"id":"1.232215600","rc":[{"batl":[[0,2,3.52],[1,2.08,5.15],[2,2.5,1]],"ltp":0.0,"tv":0.0,"id":72857114}]}]}
{"op":"mcm","clk":"11947641140","pt":1724489515722,"mc":[{"id":"1.232215600","rc":[{"batl":[[0,2.08,5.15],[1,2.5,1],[2,3.4,3.59]],"ltp":0.0,"tv":0.0,"id":72857114}]}]}
{"op":"mcm","clk":"11947642640","pt":1724489527965,"mc":[{"id":"1.232215600","rc":[{"batb":[[0,2.06,1.06],[1,1.42,8.23],[2,1.4,5]],"ltp":0.0,"tv":0.0,"id":72857114}]}]}
{"op":"mcm","clk":"11947643041","pt":1724489531171,"mc":[{"id":"1.232215600","rc":[{"batb":[[0,1.42,8.23],[1,1.4,5],[2,1.22,6.18]],"ltp":0.0,"tv":0.0,"id":72857114}]}]}
{"op":"mcm","clk":"11947644703","pt":1724489545675,"mc":[{"id":"1.232215600","rc":[{"batb":[[0,2.06,1.06],[1,1.42,8.23],[2,1.4,5]],"ltp":0.0,"tv":0.0,"id":72857114}]}]}
{"op":"mcm","clk":"11947645045","pt":1724489548774,"mc":[{"id":"1.232215600","rc":[{"batb":[[0,1.42,8.23],[1,1.4,5],[2,1.22,6.18]],"ltp":0.0,"tv":0.0,"id":72857114}]}]}
{"op":"mcm","clk":"11947646586","pt":1724489563422,"mc":[{"id":"1.232215600","rc":[{"batb":[[0,2.48,1.06],[1,1.52,1.76],[2,1.51,20]],"ltp":0.0,"tv":0.0,"id":67083366}]}]}
{"op":"mcm","clk":"11947646771","pt":1724489565278,"mc":[{"id":"1.232215600","rc":[{"batb":[[0,1.52,1.76],[1,1.51,20],[2,1.4,5]],"ltp":0.0,"tv":0.0,"id":67083366}]}]}
{"op":"mcm","clk":"11947647995","pt":1724489575841,"mc":[{"id":"1.232215600","rc":[{"batb":[[0,2.06,1.06],[1,1.42,8.23],[2,1.4,5]],"ltp":0.0,"tv":0.0,"id":72857114}]}]}
{"op":"mcm","clk":"11947648375","pt":1724489578624,"mc":[{"id":"1.232215600","rc":[{"batb":[[0,1.42,8.23],[1,1.4,5],[2,1.22,6.18]],"ltp":0.0,"tv":0.0,"id":72857114}]}]}
{"op":"mcm","clk":"11947681914","pt":1724489878791,"mc":[{"id":"1.232215600","rc":[{"batb":[[0,2.48,1.06],[1,1.52,1.76],[2,1.51,20]],"ltp":0.0,"tv":0.0,"id":67083366}]}]}
{"op":"mcm","clk":"11947682239","pt":1724489881906,"mc":[{"id":"1.232215600","rc":[{"batb":[[0,1.52,1.76],[1,1.51,20],[2,1.4,5]],"ltp":0.0,"tv":0.0,"id":67083366}]}]}
{"op":"mcm","clk":"11947693421","pt":1724489974431,"mc":[{"id":"1.232215600","rc":[{"batb":[[0,2.48,1.06],[1,1.52,1.76],[2,1.51,20]],"ltp":0.0,"tv":0.0,"id":67083366}]}]}
{"op":"mcm","clk":"11947693875","pt":1724489978415,"mc":[{"id":"1.232215600","rc":[{"batb":[[0,1.52,1.76],[1,1.51,20],[2,1.4,5]],"ltp":0.0,"tv":0.0,"id":67083366}]}]}
{"op":"mcm","clk":"11947695574","pt":1724489992155,"mc":[{"id":"1.232215600","rc":[{"batb":[[0,2.06,1.06],[1,1.42,8.23],[2,1.4,5]],"ltp":0.0,"tv":0.0,"id":72857114}]}]}
{"op":"mcm","clk":"11947696017","pt":1724489995627,"mc":[{"id":"1.232215600","rc":[{"batb":[[0,1.42,8.23],[1,1.4,5],[2,1.22,6.18]],"batl":[[0,2.06,3.52],[1,2.08,5.15],[2,2.5,1]],"ltp":0.0,"tv":0.0,"id":72857114}]}]}
{"op":"mcm","clk":"11947696129","pt":1724489996664,"mc":[{"id":"1.232215600","rc":[{"batl":[[0,2.06,8.67],[1,2.5,1],[2,3.4,3.59]],"ltp":0.0,"tv":0.0,"id":72857114}]}]}
{"op":"mcm","clk":"11947696497","pt":1724489999733,"mc":[{"id":"1.232215600","rc":[{"batl":[[0,2.06,5.15]],"ltp":0.0,"tv":0.0,"id":72857114}]}]}
{"op":"mcm","clk":"11947698316","pt":1724490011772,"mc":[{"id":"1.232215600","rc":[{"batb":[[0,2.04,1.06],[1,1.42,8.23],[2,1.4,5]],"batl":[[0,2.06,5.14]],"ltp":0.0,"tv":0.0,"id":72857114}]}]}
{"op":"mcm","clk":"11947698692","pt":1724490014677,"mc":[{"id":"1.232215600","rc":[{"trd":[[2.04,2.12]],"batb":[[0,1.42,8.23],[1,1.4,5],[2,1.22,6.18]],"batl":[[0,2.04,2.46],[1,2.06,5.14],[2,2.5,1]],"ltp":2.04,"tv":2.11,"id":72857114}],"tv":2.11}]}
{"op":"mcm","clk":"11947698923","pt":1724490016180,"mc":[{"id":"1.232215600","rc":[{"batl":[[0,2.04,7.6],[1,2.5,1],[2,3.4,3.59]],"ltp":2.04,"tv":2.11,"id":72857114}]}]}
{"op":"mcm","clk":"11947699288","pt":1724490018776,"mc":[{"id":"1.232215600","rc":[{"batl":[[0,2.04,5.14]],"ltp":2.04,"tv":2.11,"id":72857114}]}]}
{"op":"mcm","clk":"11947701516","pt":1724490034114,"mc":[{"id":"1.232215600","rc":[{"batb":[[0,2,1.06],[1,1.42,8.23],[2,1.4,5]],"ltp":2.04,"tv":2.11,"id":72857114}]}]}
{"op":"mcm","clk":"11947701990","pt":1724490037408,"mc":[{"id":"1.232215600","rc":[{"batb":[[0,1.42,8.23],[1,1.4,5],[2,1.22,6.18]],"ltp":2.04,"tv":2.11,"id":72857114}]}]}
{"op":"mcm","clk":"11947702031","pt":1724490037724,"mc":[{"id":"1.232215600","rc":[{"batl":[[0,2,3.52],[1,2.04,5.14],[2,2.5,1]],"ltp":2.04,"tv":2.11,"id":72857114}]}]}
{"op":"mcm","clk":"11947702658","pt":1724490041680,"mc":[{"id":"1.232215600","rc":[{"batl":[[0,2.04,5.14],[1,2.5,1],[2,3.4,3.59]],"ltp":2.04,"tv":2.11,"id":72857114}]}]}
{"op":"mcm","clk":"11947704550","pt":1724490054953,"mc":[{"id":"1.232215600","rc":[{"batb":[[0,1.98,1.06],[1,1.42,8.23],[2,1.4,5]],"ltp":2.04,"tv":2.11,"id":72857114}]}]}
{"op":"mcm","clk":"11947704902","pt":1724490057586,"mc":[{"id":"1.232215600","rc":[{"batb":[[0,1.42,8.23],[1,1.4,5],[2,1.22,6.18]],"ltp":2.04,"tv":2.11,"id":72857114}]}]}
{"op":"mcm","clk":"11947705077","pt":1724490058689,"mc":[{"id":"1.232215600","rc":[{"batl":[[0,1.98,3.52],[1,2.04,5.14],[2,2.5,1]],"ltp":2.04,"tv":2.11,"id":72857114}]}]}
{"op":"mcm","clk":"11947705648","pt":1724490062806,"mc":[{"id":"1.232215600","rc":[{"batl":[[0,2.04,5.14],[1,2.5,1],[2,3.4,3.59]],"ltp":2.04,"tv":2.11,"id":72857114}]}]}
{"op":"mcm","clk":"11947707056","pt":1724490071617,"mc":[{"id":"1.232215600","rc":[{"batb":[[0,1.97,1.06],[1,1.42,8.23],[2,1.4,5]],"ltp":2.04,"tv":2.11,"id":72857114}]}]}
{"op":"mcm","clk":"11947707490","pt":1724490074716,"mc":[{"id":"1.232215600","rc":[{"trd":[[1.97,2.12]],"batb":[[0,1.42,8.23],[1,1.4,5],[2,1.22,6.18]],"batl":[[0,1.97,2.46],[1,2.04,5.14],[2,2.5,1]],"ltp":1.97,"tv":4.23,"id":72857114}],"tv":4.23}]}
{"op":"mcm","clk":"11947707974","pt":1724490077796,"mc":[{"id":"1.232215600","rc":[{"trd":[[2.5,2],[3,1.15]],"batl":[[0,3.4,2.89],[1,3.4,0]],"ltp":3.0,"tv":3.15,"id":67083366}],"tv":7.38}]}
{"op":"mcm","clk":"11947708101","pt":1724490078719,"mc":[{"id":"1.232215600","rc":[{"batl":[[0,2.04,5.14],[1,2.5,1],[2,3.4,3.59]],"ltp":1.97,"tv":4.23,"id":72857114}]}]}
{"op":"mcm","clk":"11947713140","pt":1724490113744,"mc":[{"id":"1.232215600","rc":[{"batl":[[0,2,1.06],[1,3.4,2.89]],"ltp":3.0,"tv":3.15,"id":67083366}]}]}
{"op":"mcm","clk":"11947713763","pt":1724490118052,"mc":[{"id":"1.232215600","rc":[{"batl":[[0,3.4,2.89],[1,3.4,0]],"ltp":3.0,"tv":3.15,"id":67083366}]}]}
{"op":"mcm","clk":"11947713862","pt":1724490118676,"mc":[{"id":"1.232215600","rc":[{"batl":[[0,2,3.52],[1,2.04,5.14],[2,2.5,1]],"ltp":1.97,"tv":4.23,"id":72857114}]}]}
{"op":"mcm","clk":"11947714367","pt":1724490121697,"mc":[{"id":"1.232215600","rc":[{"batl":[[0,2.04,5.14],[1,2.5,1],[2,3.4,3.59]],"ltp":1.97,"tv":4.23,"id":72857114}]}]}
{"op":"mcm","clk":"11947716648","pt":1724490138307,"mc":[{"id":"1.232215600","rc":[{"batb":[[0,1.96,1.06],[1,1.42,8.23],[2,1.4,5]],"ltp":1.97,"tv":4.23,"id":72857114}]}]}
{"op":"mcm","clk":"11947717217","pt":1724490142985,"mc":[{"id":"1.232215600","rc":[{"batb":[[0,1.42,8.23],[1,1.4,5],[2,1.22,6.18]],"ltp":1.97,"tv":4.23,"id":72857114}]}]}
{"op":"mcm","clk":"11947720755","pt":1724490168429,"mc":[{"id":"1.232215600","rc":[{"batb":[[0,1.95,1.51],[1,1.42,8.23],[2,1.4,5]],"ltp":1.97,"tv":4.23,"id":72857114}]}]}
{"op":"mcm","clk":"11947721334","pt":1724490172998,"mc":[{"id":"1.232215600","rc":[{"batb":[[0,1.42,8.23],[1,1.4,5],[2,1.22,6.18]],"ltp":1.97,"tv":4.23,"id":72857114}]}]}
{"op":"mcm","clk":"11947722936","pt":1724490184750,"mc":[{"id":"1.232215600","rc":[{"trd":[[3,1.5]],"batl":[[0,3.4,2.54]],"ltp":3.0,"tv":3.5,"id":67083366},{"trd":[[1.5,0.7]],"batl":[[0,2.04,5.5]],"ltp":1.5,"tv":4.94,"id":72857114}],"tv":8.44}]}
{"op":"mcm","clk":"11947723141","pt":1724490186233,"mc":[{"id":"1.232215600","rc":[{"batl":[[0,2.04,5.14]],"ltp":1.5,"tv":4.94,"id":72857114}]}]}
{"op":"mcm","clk":"11947727967","pt":1724490222370,"mc":[{"id":"1.232215600","rc":[{"batb":[[0,3,1.06],[1,1.52,1.76],[2,1.51,20]],"ltp":3.0,"tv":3.5,"id":67083366}]}]}
{"op":"mcm","clk":"11947728643","pt":1724490227620,"mc":[{"id":"1.232215600","rc":[{"batb":[[0,1.52,1.76],[1,1.51,20],[2,1.4,5]],"ltp":3.0,"tv":3.5,"id":67083366}]}]}
{"op":"mcm","clk":"11947728889","pt":1724490229584,"mc":[{"id":"1.232215600","rc":[{"batl":[[0,3,1],[1,3.4,2.54]],"ltp":3.0,"tv":3.5,"id":67083366}]}]}
{"op":"mcm","clk":"11947729420","pt":1724490233593,"mc":[{"id":"1.232215600","rc":[{"batl":[[0,3.4,2.54],[1,3.4,0]],"ltp":3.0,"tv":3.5,"id":67083366}]}]}
{"op":"mcm","clk":"11947731448","pt":1724490247715,"mc":[{"id":"1.232215600","rc":[{"batb":[[0,1.95,1.06],[1,1.42,8.23],[2,1.4,5]],"ltp":1.5,"tv":4.94,"id":72857114}]}]}
{"op":"mcm","clk":"11947732060","pt":1724490251723,"mc":[{"id":"1.232215600","rc":[{"trd":[[1.95,2.12]],"batb":[[0,1.42,8.23],[1,1.4,5],[2,1.22,6.18]],"batl":[[0,1.95,2.46],[1,2.04,5.14],[2,2.5,1]],"ltp":1.95,"tv":7.06,"id":72857114}],"tv":10.56}]}
{"op":"mcm","clk":"11947732640","pt":1724490255737,"mc":[{"id":"1.232215600","rc":[{"batl":[[0,2.04,5.14],[1,2.5,1],[2,3.4,3.59]],"ltp":1.95,"tv":7.06,"id":72857114}]}]}
{"op":"mcm","clk":"11947733108","pt":1724490258307,"mc":[{"id":"1.232215600","rc":[{"batl":[[0,1.94,182.13],[1,2.04,5.14],[2,2.5,1]],"ltp":1.95,"tv":7.06,"id":72857114}]}]}
{"op":"mcm","clk":"11947734902","pt":1724490271210,"mc":[{"id":"1.232215600","rc":[{"batb":[[0,1.5,182.13],[1,1.42,8.23],[2,1.4,5]],"ltp":1.95,"tv":7.06,"id":72857114}]}]}
{"op":"mcm","clk":"11947736087","pt":1724490280037,"mc":[{"id":"1.232215600","rc":[{"batb":[[0,2.96,1.06],[1,1.52,1.76],[2,1.51,20]],"ltp":3.0,"tv":3.5,"id":67083366}]}]}
{"op":"mcm","clk":"11947736430","pt":1724490282761,"mc":[{"id":"1.232215600","rc":[{"batb":[[0,1.52,1.76],[1,1.51,20],[2,1.4,5]],"ltp":3.0,"tv":3.5,"id":67083366}]}]}
{"op":"mcm","clk":"11947736527","pt":1724490283752,"mc":[{"id":"1.232215600","rc":[{"batb":[[0,1.52,3.52],[1,1.5,182.13],[2,1.42,8.23]],"ltp":1.95,"tv":7.06,"id":72857114}]}]}
{"op":"mcm","clk":"11947736766","pt":1724490285650,"mc":[{"id":"1.232215600","rc":[{"batb":[[0,1.52,185.65]],"ltp":1.95,"tv":7.06,"id":72857114}]}]}
{"op":"mcm","clk":"11947737054","pt":1724490287780,"mc":[{"id":"1.232215600","rc":[{"batb":[[0,1.52,182.13]],"ltp":1.95,"tv":7.06,"id":72857114}]}]}
{"op":"mcm","clk":"11947738039","pt":1724490294946,"mc":[{"id":"1.232215600","rc":[{"batb":[[0,1.55,182.13],[1,1.52,182.13],[2,1.5,182.13]],"ltp":1.95,"tv":7.06,"id":72857114}]}]}
{"op":"mcm","clk":"11947738827","pt":1724490301247,"mc":[{"id":"1.232215600","rc":[{"batb":[[0,1.9,1.06],[1,1.42,8.23],[2,1.4,5]],"batl":[[0,2.04,5.14],[1,2.5,1],[2,3.4,3.59]],"ltp":1.95,"tv":7.06,"id":72857114}]}]}
{"op":"mcm","clk":"11947739435","pt":1724490305402,"mc":[{"id":"1.232215600","rc":[{"trd":[[1.9,2.12]],"batb":[[0,1.42,8.23],[1,1.4,5],[2,1.22,6.18]],"batl":[[0,1.9,184.59],[1,2.04,5.14],[2,2.5,1]],"ltp":1.9,"tv":9.18,"id":72857114}],"tv":12.68}]}
{"op":"mcm","clk":"11947739830","pt":1724490308061,"mc":[{"id":"1.232215600","rc":[{"batl":[[0,1.9,2.46]],"ltp":1.9,"tv":9.18,"id":72857114}]}]}
{"op":"mcm","clk":"11947740059","pt":1724490309778,"mc":[{"id":"1.232215600","rc":[{"batl":[[0,2.04,5.14],[1,2.5,1],[2,3.4,3.59]],"ltp":1.9,"tv":9.18,"id":72857114}]}]}
{"op":"mcm","clk":"11947742801","pt":1724490328135,"mc":[{"id":"1.232215600","rc":[{"batb":[[0,1.89,1.51],[1,1.42,8.23],[2,1.4,5]],"ltp":1.9,"tv":9.18,"id":72857114}]}]}
{"op":"mcm","clk":"11947743095","pt":1724490330079,"mc":[{"id":"1.232215600","rc":[{"batb":[[0,1.42,8.23],[1,1.4,5],[2,1.22,6.18]],"ltp":1.9,"tv":9.18,"id":72857114}]}]}
{"op":"mcm","clk":"11947747637","pt":1724490362812,"mc":[{"id":"1.232215600","rc":[{"batb":[[0,2.92,1.06],[1,1.52,1.76],[2,1.51,20]],"ltp":3.0,"tv":3.5,"id":67083366}]}]}
{"op":"mcm","clk":"11947747923","pt":1724490364677,"mc":[{"id":"1.232215600","rc":[{"trd":[[2.92,1.06]],"batb":[[0,1.52,1.76],[1,1.51,20],[2,1.4,5]],"ltp":2.92,"tv":4.56,"id":67083366},{"trd":[[1.53,2.02]],"batb":[[0,1.54,1.5],[1,1.42,8.23],[2,1.4,5]],"ltp":1.53,"tv":11.2,"id":72857114}],"tv":15.76}]}
{"op":"mcm","clk":"11947748504","pt":1724490368787,"mc":[{"id":"1.232215600","rc":[{"batb":[[0,1.42,8.23],[1,1.4,5],[2,1.22,6.18]],"ltp":1.53,"tv":11.2,"id":72857114}]}]}
{"op":"mcm","clk":"11947750637","pt":1724490385406,"mc":[{"id":"1.232215600","rc":[{"batb":[[0,2.82,1.06],[1,1.52,1.76],[2,1.51,20]],"ltp":2.92,"tv":4.56,"id":67083366}]}]}
{"op":"mcm","clk":"11947750927","pt":1724490387276,"mc":[{"id":"1.232215600","rc":[{"batb":[[0,1.52,1.76],[1,1.51,20],[2,1.4,5]],"ltp":2.92,"tv":4.56,"id":67083366}]}]}
{"op":"mcm","clk":"11947751119","pt":1724490388672,"mc":[{"id":"1.232215600","rc":[{"batb":[[0,1.55,3.52],[1,1.42,8.23],[2,1.4,5]],"ltp":1.53,"tv":11.2,"id":72857114}]}]}
{"op":"mcm","clk":"11947751510","pt":1724490392099,"mc":[{"id":"1.232215600","rc":[{"batl":[[0,2.92,1],[1,3.4,2.54]],"ltp":2.92,"tv":4.56,"id":67083366}]}]}
{"op":"mcm","clk":"11947751581","pt":1724490392673,"mc":[{"id":"1.232215600","rc":[{"batb":[[0,1.42,8.23],[1,1.4,5],[2,1.22,6.18]],"ltp":1.53,"tv":11.2,"id":72857114}]}]}
{"op":"mcm","clk":"11947752313","pt":1724490398329,"mc":[{"id":"1.232215600","rc":[{"batb":[[0,1.57,182.13],[1,1.42,8.23],[2,1.4,5]],"ltp":1.53,"tv":11.2,"id":72857114}]}]}
{"op":"mcm","clk":"11947755017","pt":1724490418862,"mc":[{"id":"1.232215600","rc":[{"batb":[[0,2.7,1.51],[1,1.52,1.76],[2,1.51,20]],"ltp":2.92,"tv":4.56,"id":67083366}]}]}
{"op":"mcm","clk":"11947755446","pt":1724490421545,"mc":[{"id":"1.232215600","rc":[{"batb":[[0,1.52,1.76],[1,1.51,20],[2,1.4,5]],"ltp":2.92,"tv":4.56,"id":67083366}]}]}
{"op":"mcm","clk":"11947755876","pt":1724490424733,"mc":[{"id":"1.232215600","rc":[{"batb":[[0,1.59,2],[1,1.57,182.13],[2,1.42,8.23]],"ltp":1.53,"tv":11.2,"id":72857114}]}]}
{"op":"mcm","clk":"11947760262","pt":1724490458111,"mc":[{"id":"1.232215600","rc":[{"batb":[[1,1.42,8.23],[2,1.4,5]],"ltp":1.53,"tv":11.2,"id":72857114}]}]}
{"op":"mcm","clk":"11947763201","pt":1724490482547,"mc":[{"id":"1.232215600","rc":[{"trd":[[1.96,0.51]],"ltp":1.96,"tv":5.07,"id":67083366},{"trd":[[2.04,2.61]],"batl":[[0,2.04,4.65]],"ltp":2.04,"tv":11.69,"id":72857114}],"tv":16.77}]}
{"op":"mcm","clk":"11947766253","pt":1724490505646,"mc":[{"id":"1.232215600","rc":[{"batb":[[0,2.66,1.06],[1,1.52,1.76],[2,1.51,20]],"ltp":1.96,"tv":5.07,"id":67083366}]}]}
{"op":"mcm","clk":"11947766750","pt":1724490509450,"mc":[{"id":"1.232215600","rc":[{"batb":[[0,1.52,1.76],[1,1.51,20],[2,1.4,5]],"ltp":1.96,"tv":5.07,"id":67083366}]}]}
{"op":"mcm","clk":"11947767033","pt":1724490511678,"mc":[{"id":"1.232215600","rc":[{"batb":[[0,1.61,3.52],[1,1.59,2],[2,1.42,8.23]],"ltp":2.04,"tv":11.69,"id":72857114}]}]}
{"op":"mcm","clk":"11947767566","pt":1724490515793,"mc":[{"id":"1.232215600","rc":[{"batb":[[0,1.59,2],[1,1.42,8.23],[2,1.4,5]],"ltp":2.04,"tv":11.69,"id":72857114}]}]}
{"op":"mcm","clk":"11947769332","pt":1724490529090,"mc":[{"id":"1.232215600","rc":[{"batb":[[0,1.97,1.51],[1,1.59,2],[2,1.42,8.23]],"ltp":2.04,"tv":11.69,"id":72857114}]}]}
{"op":"mcm","clk":"11947769658","pt":1724490531519,"mc":[{"id":"1.232215600","rc":[{"batb":[[0,1.59,2],[1,1.42,8.23],[2,1.4,5]],"ltp":2.04,"tv":11.69,"id":72857114}]}]}
{"op":"mcm","clk":"11947771412","pt":1724490544535,"mc":[{"id":"1.232215600","rc":[{"batb":[[0,1.95,1.51],[1,1.59,2],[2,1.42,8.23]],"ltp":2.04,"tv":11.69,"id":72857114}]}]}
{"op":"mcm","clk":"11947771875","pt":1724490548124,"mc":[{"id":"1.232215600","rc":[{"batb":[[0,1.59,2],[1,1.42,8.23],[2,1.4,5]],"ltp":2.04,"tv":11.69,"id":72857114}]}]}
{"op":"mcm","clk":"11947774899","pt":1724490570864,"mc":[{"id":"1.232215600","rc":[{"batb":[[0,1.93,1.51],[1,1.59,2],[2,1.42,8.23]],"ltp":2.04,"tv":11.69,"id":72857114}]}]}
{"op":"mcm","clk":"11947775545","pt":1724490575565,"mc":[{"id":"1.232215600","rc":[{"batb":[[0,1.59,2],[1,1.42,8.23],[2,1.4,5]],"ltp":2.04,"tv":11.69,"id":72857114}]}]}
{"op":"mcm","clk":"11947775989","pt":1724490578952,"mc":[{"id":"1.232215600","rc":[{"batl":[[0,3.4,2.54],[1,3.4,0]],"ltp":1.96,"tv":5.07,"id":67083366},{"batb":[[0,1.42,8.23],[1,1.4,5],[2,1.22,6.18]],"ltp":2.04,"tv":11.69,"id":72857114}]}]}
{"op":"mcm","clk":"11947778286","pt":1724490596869,"mc":[{"id":"1.232215600","rc":[{"batb":[[0,3,1.06],[1,1.52,1.76],[2,1.51,20]],"ltp":1.96,"tv":5.07,"id":67083366}]}]}
{"op":"mcm","clk":"11947778794","pt":1724490600772,"mc":[{"id":"1.232215600","rc":[{"batb":[[0,1.52,1.76],[1,1.51,20],[2,1.4,5]],"ltp":1.96,"tv":5.07,"id":67083366}]}]}
{"op":"mcm","clk":"11947779055","pt":1724490602667,"mc":[{"id":"1.232215600","rc":[{"batb":[[0,1.5,3.52],[1,1.42,8.23],[2,1.4,5]],"ltp":2.04,"tv":11.69,"id":72857114}]}]}
{"op":"mcm","clk":"11947779634","pt":1724490606788,"mc":[{"id":"1.232215600","rc":[{"batb":[[0,1.42,8.23],[1,1.4,5],[2,1.22,6.18]],"ltp":2.04,"tv":11.69,"id":72857114}]}]}
{"op":"mcm","clk":"11947783135","pt":1724490632422,"mc":[{"id":"1.232215600","rc":[{"batb":[[0,2.86,1.06],[1,1.52,1.76],[2,1.51,20]],"ltp":1.96,"tv":5.07,"id":67083366}]}]}
{"op":"mcm","clk":"11947783530","pt":1724490635732,"mc":[{"id":"1.232215600","rc":[{"batb":[[0,1.52,1.76],[1,1.51,20],[2,1.4,5]],"ltp":1.96,"tv":5.07,"id":67083366},{"batb":[[0,1.54,3.52],[1,1.42,8.23],[2,1.4,5]],"ltp":2.04,"tv":11.69,"id":72857114}]}]}
{"op":"mcm","clk":"11947784187","pt":1724490640710,"mc":[{"id":"1.232215600","rc":[{"batb":[[0,1.42,8.23],[1,1.4,5],[2,1.22,6.18]],"ltp":2.04,"tv":11.69,"id":72857114}]}]}
{"op":"mcm","clk":"11947785633","pt":1724490650251,"mc":[{"id":"1.232215600","rc":[{"batb":[[0,2.8,1.06],[1,1.52,1.76],[2,1.51,20]],"ltp":1.96,"tv":5.07,"id":67083366}]}]}
{"op":"mcm","clk":"11947786281","pt":1724490654827,"mc":[{"id":"1.232215600","rc":[{"batb":[[0,1.52,1.76],[1,1.51,20],[2,1.4,5]],"ltp":1.96,"tv":5.07,"id":67083366}]}]}
{"op":"mcm","clk":"11947786390","pt":1724490655654,"mc":[{"id":"1.232215600","rc":[{"batb":[[0,1.42,9.15]],"ltp":2.04,"tv":11.69,"id":72857114}]}]}
{"op":"mcm","clk":"11947788622","pt":1724490670677,"mc":[{"id":"1.232215600","rc":[{"batb":[[0,1.97,1.09],[1,1.42,9.15],[2,1.4,5]],"ltp":2.04,"tv":11.69,"id":72857114}]}]}
{"op":"mcm","clk":"11947788738","pt":1724490671667,"mc":[{"id":"1.232215600","rc":[{"trd":[[1.97,3.97]],"batb":[[0,1.56,1.09],[1,1.42,8.23]],"ltp":1.97,"tv":13.54,"id":72857114}],"tv":18.62}]}
{"op":"mcm","clk":"11947789051","pt":1724490673955,"mc":[{"id":"1.232215600","rc":[{"batb":[[0,1.42,9.15],[1,1.4,5],[2,1.22,6.18]],"ltp":1.97,"tv":13.54,"id":72857114}]}]}
{"op":"mcm","clk":"11947791332","pt":1724490691017,"mc":[{"id":"1.232215600","rc":[{"batb":[[0,1.92,1.06],[1,1.42,9.15],[2,1.4,5]],"ltp":1.97,"tv":13.54,"id":72857114}]}]}
{"op":"mcm","clk":"11947791851","pt":1724490694720,"mc":[{"id":"1.232215600","rc":[{"trd":[[1.92,2.12]],"batb":[[0,1.42,9.15],[1,1.4,5],[2,1.22,6.18]],"batl":[[0,1.92,2.46],[1,2.04,4.65],[2,2.5,1]],"ltp":1.92,"tv":15.66,"id":72857114}],"tv":20.74}]}
{"op":"mcm","clk":"11947791957","pt":1724490695708,"mc":[{"id":"1.232215600","rc":[{"batl":[[0,1.92,3.39]],"ltp":1.92,"tv":15.66,"id":72857114}]}]}
{"op":"mcm","clk":"11947792331","pt":1724490698813,"mc":[{"id":"1.232215600","rc":[{"batl":[[0,2.04,5.57],[1,2.5,1],[2,3.4,3.59]],"ltp":1.92,"tv":15.66,"id":72857114}]}]}
{"op":"mcm","clk":"11947799514","pt":1724490752489,"mc":[{"id":"1.232215600","rc":[{"batb":[[0,1.8,1.06],[1,1.42,9.15],[2,1.4,5]],"ltp":1.92,"tv":15.66,"id":72857114}]}]}
{"op":"mcm","clk":"11947799687","pt":1724490753692,"mc":[{"id":"1.232215600","rc":[{"batl":[[0,3.4,3.47]],"ltp":1.96,"tv":5.07,"id":67083366}]}]}
{"op":"mcm","clk":"11947800533","pt":1724490759685,"mc":[{"id":"1.232215600","rc":[{"batb":[[0,1.42,9.15],[1,1.4,5],[2,1.22,6.18]],"ltp":1.92,"tv":15.66,"id":72857114}]}]}
{"op":"mcm","clk":"11947803038","pt":1724490778601,"mc":[{"id":"1.232215600","rc":[{"batb":[[0,1.8,1.06],[1,1.42,9.15],[2,1.4,5]],"ltp":1.92,"tv":15.66,"id":72857114}]}]}
{"op":"mcm","clk":"11947803892","pt":1724490784639,"mc":[{"id":"1.232215600","rc":[{"batb":[[0,1.42,9.15],[1,1.4,5],[2,1.22,6.18]],"ltp":1.92,"tv":15.66,"id":72857114}]}]}
{"op":"mcm","clk":"11947805247","pt":1724490794745,"mc":[{"id":"1.232215600","rc":[{"batl":[[0,1.88,1.85],[1,2.04,4.65],[2,2.5,1]],"ltp":1.92,"tv":15.66,"id":72857114}]}]}
{"op":"mcm","clk":"11947806021","pt":1724490800470,"mc":[{"id":"1.232215600","rc":[{"batb":[[0,1.74,1.51],[1,1.42,9.15],[2,1.4,5]],"ltp":1.92,"tv":15.66,"id":72857114}]}]}
{"op":"mcm","clk":"11947807008","pt":1724490807457,"mc":[{"id":"1.232215600","rc":[{"batb":[[0,1.42,9.15],[1,1.4,5],[2,1.22,6.18]],"ltp":1.92,"tv":15.66,"id":72857114}]}]}
{"op":"mcm","clk":"11947808500","pt":1724490818259,"mc":[{"id":"1.232215600","rc":[{"batb":[[0,1.74,1.09],[1,1.42,9.15],[2,1.4,5]],"ltp":1.92,"tv":15.66,"id":72857114}]}]}
{"op":"mcm","clk":"11947809834","pt":1724490828389,"mc":[{"id":"1.232215600","rc":[{"batb":[[0,1.42,9.15],[1,1.4,5],[2,1.22,6.18]],"ltp":1.92,"tv":15.66,"id":72857114}]}]}
{"op":"mcm","clk":"11947814169","pt":1724490860639,"mc":[{"id":"1.232215600","rc":[{"batb":[[0,1.74,1.09],[1,1.42,9.15],[2,1.4,5]],"ltp":1.92,"tv":15.66,"id":72857114}]}]}
{"op":"mcm","clk":"11947814758","pt":1724490864833,"mc":[{"id":"1.232215600","rc":[{"trd":[[1.74,1.85]],"batb":[[0,1.56,1.09],[1,1.42,8.23]],"batl":[[0,2.04,5.57],[1,2.5,1],[2,3.4,3.59]],"ltp":1.74,"tv":17.51,"id":72857114}],"tv":22.59}]}
{"op":"mcm","clk":"11947814951","pt":1724490866242,"mc":[{"id":"1.232215600","rc":[{"batb":[[0,1.42,9.15],[1,1.4,5],[2,1.22,6.18]],"ltp":1.74,"tv":17.51,"id":72857114}]}]}
{"op":"mcm","clk":"11947820810","pt":1724490907709,"mc":[{"id":"1.232215600","rc":[{"batl":[[0,1.96,1.1],[1,2.04,4.65],[2,2.5,1]],"ltp":1.74,"tv":17.51,"id":72857114}]}]}
{"op":"mcm","clk":"11947821222","pt":1724490910725,"mc":[{"id":"1.232215600","rc":[{"batb":[[0,1.5,2.64],[1,1.42,8.23],[2,1.4,5]],"ltp":1.74,"tv":17.51,"id":72857114}]}]}
{"op":"mcm","clk":"11947822031","pt":1724490915819,"mc":[{"id":"1.232215600","rc":[{"batl":[[0,1.95,1.1]],"ltp":1.74,"tv":17.51,"id":72857114}]}]}
{"op":"mcm","clk":"11947823486","pt":1724490926854,"mc":[{"id":"1.232215600","rc":[{"batl":[[0,1.95,1.01]],"ltp":1.74,"tv":17.51,"id":72857114}]}]}
{"op":"mcm","clk":"11947824899","pt":1724490937661,"mc":[{"id":"1.232215600","rc":[{"batl":[[0,3,1.01],[1,3.4,2.54]],"ltp":1.96,"tv":5.07,"id":67083366}]}]}
{"op":"mcm","clk":"11947828172","pt":1724490959891,"mc":[{"id":"1.232215600","rc":[{"batl":[[0,2.04,5.62],[1,2.5,1],[2,3.4,3.59]],"ltp":1.74,"tv":17.51,"id":72857114}]}]}
{"op":"mcm","clk":"11947829625","pt":1724490968834,"mc":[{"id":"1.232215600","rc":[{"batl":[[0,3.4,3.51],[1,3.4,0]],"ltp":1.96,"tv":5.07,"id":67083366}]}]}
{"op":"mcm","clk":"11947835517","pt":1724491010748,"mc":[{"id":"1.232215600","rc":[{"batl":[[0,3.4,3.47]],"ltp":1.96,"tv":5.07,"id":67083366}]}]}
{"op":"mcm","clk":"11947836058","pt":1724491014668,"mc":[{"id":"1.232215600","rc":[{"batl":[[0,2.04,5.57]],"ltp":1.74,"tv":17.51,"id":72857114}]}]}
{"op":"mcm","clk":"11947838441","pt":1724491031704,"mc":[{"id":"1.232215600","rc":[{"batl":[[0,2.04,5.63]],"ltp":1.74,"tv":17.51,"id":72857114}]}]}
{"op":"mcm","clk":"11947840526","pt":1724491045908,"mc":[{"id":"1.232215600","rc":[{"batl":[[0,2.04,5.63]],"ltp":1.74,"tv":17.51,"id":72857114}]}]}
{"op":"mcm","clk":"11947841590","pt":1724491052841,"mc":[{"id":"1.232215600","rc":[{"batl":[[0,2.04,5.64]],"ltp":1.74,"tv":17.51,"id":72857114}]}]}
{"op":"mcm","clk":"11947842482","pt":1724491058819,"mc":[{"id":"1.232215600","rc":[{"batl":[[0,2.04,5.64]],"ltp":1.74,"tv":17.51,"id":72857114}]}]}
{"op":"mcm","clk":"11947843353","pt":1724491064840,"mc":[{"id":"1.232215600","rc":[{"batl":[[0,2.04,5.64]],"ltp":1.74,"tv":17.51,"id":72857114}]}]}
{"op":"mcm","clk":"11947844559","pt":1724491073135,"mc":[{"id":"1.232215600","rc":[{"batl":[[0,1.8,20],[1,2.04,5.64],[2,2.5,1]],"ltp":1.74,"tv":17.51,"id":72857114}]}]}
{"op":"mcm","clk":"11947846551","pt":1724491086676,"mc":[{"id":"1.232215600","rc":[{"batl":[[0,3.4,3.53]],"ltp":1.96,"tv":5.07,"id":67083366}]}]}
{"op":"mcm","clk":"11947847790","pt":1724491096095,"mc":[{"id":"1.232215600","rc":[{"batb":[[0,1.56,20.93],[1,1.5,1.72],[2,1.42,8.23]],"ltp":1.74,"tv":17.51,"id":72857114}]}]}
{"op":"mcm","clk":"11947848285","pt":1724491099868,"mc":[{"id":"1.232215600","rc":[{"batl":[[0,2.04,5.64],[1,2.5,1],[2,3.4,3.59]],"ltp":1.74,"tv":17.51,"id":72857114}]}]}
{"op":"mcm","clk":"11947849700","pt":1724491110695,"mc":[{"id":"1.232215600","rc":[{"batl":[[0,1.92,20.93],[1,2.04,4.71],[2,2.5,1]],"ltp":1.74,"tv":17.51,"id":72857114}]}]}
{"op":"mcm","clk":"11947857145","pt":1724491162875,"mc":[{"id":"1.232215600","rc":[{"batl":[[0,3.4,3.47],[1,4,0.06]],"ltp":1.96,"tv":5.07,"id":67083366}]}]}
{"op":"mcm","clk":"11947858269","pt":1724491170765,"mc":[{"id":"1.232215600","rc":[{"batl":[[1,2.04,4.65]],"ltp":1.74,"tv":17.51,"id":72857114}]}]}
{"op":"mcm","clk":"11947858515","pt":1724491172555,"mc":[{"id":"1.232215600","rc":[{"trd":[[1.56,5.04],[1.6,1.85]],"batb":[[0,1.56,17.48]],"ltp":1.56,"tv":24.4,"id":72857114}],"tv":29.48}]}
{"op":"mcm","clk":"11947862309","pt":1724491198676,"mc":[{"id":"1.232215600","rc":[{"batb":[[0,1.56,18.41]],"ltp":1.56,"tv":24.4,"id":72857114}]}]}
{"op":"mcm","clk":"11947863125","pt":1724491203829,"mc":[{"id":"1.232215600","rc":[{"batl":[[1,4,0.08]],"ltp":1.96,"tv":5.07,"id":67083366}]}]}
{"op":"mcm","clk":"11947864733","pt":1724491214700,"mc":[{"id":"1.232215600","rc":[{"batl":[[0,1.88,1.85],[1,1.92,20],[2,2.04,4.65]],"ltp":1.56,"tv":24.4,"id":72857114}]}]}
{"op":"mcm","clk":"11947867444","pt":1724491233840,"mc":[{"id":"1.232215600","rc":[{"batl":[[0,3,1.01],[1,3.4,2.54]],"ltp":1.96,"tv":5.07,"id":67083366}]}]}
{"op":"mcm","clk":"11947869530","pt":1724491248856,"mc":[{"id":"1.232215600","rc":[{"batl":[[2,2.04,4.74]],"ltp":1.56,"tv":24.4,"id":72857114}]}]}
{"op":"mcm","clk":"11947893396","pt":1724491412242,"mc":[{"id":"1.232215600","rc":[{"batb":[[0,2.26,30.85],[1,1.52,1.76],[2,1.51,20]],"ltp":1.96,"tv":5.07,"id":67083366},{"batb":[[0,1.72,53.99],[1,1.56,18.41],[2,1.5,1.72]],"ltp":1.56,"tv":24.4,"id":72857114}]}]}
{"op":"mcm","clk":"11947894817","pt":1724491420619,"mc":[{"id":"1.232215600","rc":[{"batb":[[1,1.62,4.62],[2,1.56,18.41]],"ltp":1.56,"tv":24.4,"id":72857114}]}]}
{"op":"mcm","clk":"11947896661","pt":1724491432729,"mc":[{"id":"1.232215600","rc":[{"batb":[[1,1.56,18.41],[2,1.5,1.72]],"ltp":1.56,"tv":24.4,"id":72857114}]}]}
{"op":"mcm","clk":"11947897359","pt":1724491437367,"mc":[{"id":"1.232215600","rc":[{"trd":[[2.26,6.44]],"ltp":2.26,"tv":11.51,"id":67083366}],"tv":35.92}]}
{"op":"mcm","clk":"11947906990","pt":1724491495144,"mc":[{"id":"1.232215600","rc":[{"trd":[[1.72,5.04]],"batb":[[0,1.72,51.47]],"ltp":1.72,"tv":29.44,"id":72857114}],"tv":40.96}]}
{"op":"mcm","clk":"11947907392","pt":1724491497607,"mc":[{"id":"1.232215600","rc":[{"batb":[[0,1.72,53.99]],"ltp":1.72,"tv":29.44,"id":72857114}]}]}
{"op":"mcm","clk":"11947907801","pt":1724491500413,"mc":[{"id":"1.232215600","rc":[{"batb":[[1,1.5,2.64],[2,1.42,8.23]],"ltp":1.72,"tv":29.44,"id":72857114}]}]}
{"op":"mcm","clk":"11947908364","pt":1724491503832,"mc":[{"id":"1.232215600","rc":[{"batl":[[1,2.04,4.74],[2,2.5,1]],"ltp":1.72,"tv":29.44,"id":72857114}]}]}
{"op":"mcm","clk":"11947933760","pt":1724491666717,"mc":[{"id":"1.232215600","rc":[{"batl":[[0,3.4,3.47],[1,3.4,0]],"ltp":2.26,"tv":11.51,"id":67083366}]}]}
{"op":"mcm","clk":"11947935294","pt":1724491676808,"mc":[{"id":"1.232215600","rc":[{"batl":[[1,2.04,4.65]],"ltp":1.72,"tv":29.44,"id":72857114}]}]}
{"op":"mcm","clk":"11948185990","pt":1724493091932,"mc":[{"id":"1.232215600","rc":[{"trd":[[1.72,6]],"batb":[[0,1.72,53.51],[1,1.42,8.23],[2,1.4,5]],"batl":[[0,2.04,4.65],[1,2.5,1],[2,2.5,0]],"ltp":1.72,"tv":30.4,"id":72857114}],"tv":41.92}]}
{"op":"mcm","clk":"11948186343","pt":1724493094226,"mc":[{"id":"1.232215600","rc":[{"batb":[[0,1.72,53.99]],"ltp":1.72,"tv":30.4,"id":72857114}]}]}
{"op":"mcm","clk":"11948260793","pt":1724493638373,"mc":[{"id":"1.232215600","rc":[{"batb":[[1,1.4,5],[2,1.21,24.75]],"batl":[[0,2.5,1],[1,2.5,0]],"ltp":1.72,"tv":30.4,"id":72857114}]}]}
{"op":"mcm","clk":"11948261083","pt":1724493640359,"mc":[{"id":"1.232215600","rc":[{"batb":[[1,1.41,8.74],[2,1.4,5]],"batl":[[0,2.14,5.14],[1,2.5,1]],"ltp":1.72,"tv":30.4,"id":72857114}]}]}
{"op":"mcm","clk":"11948474150","pt":1724494711770,"mc":[{"id":"1.232215600","rc":[{"batb":[[1,1.51,20],[2,1.4,5]],"ltp":2.26,"tv":11.51,"id":67083366}]}]}
{"op":"mcm","clk":"11949117348","pt":1724497975155,"mc":[{"id":"1.232215600","rc":[{"batb":[[1,1.41,8.74]],"batl":[[0,2.14,5.14]],"ltp":1.72,"tv":30.4,"id":72857114}]}]}
{"op":"mcm","clk":"11950592744","pt":1724505452024,"mc":[{"id":"1.232215600","rc":[{"batb":[[2,1.21,24.75]],"ltp":1.72,"tv":30.4,"id":72857114},{"batb":[[2,1.21,24.75]],"ltp":2.26,"tv":11.51,"id":67083366}]}]}
{"op":"mcm","clk":"11950770163","pt":1724506392724,"mc":[{"id":"1.232215600","rc":[{"batb":[[1,1.66,66.16],[2,1.41,8.74]],"ltp":1.72,"tv":30.4,"id":72857114}]}]}
{"op":"mcm","clk":"11950774249","pt":1724506413752,"mc":[{"id":"1.232215600","rc":[{"batb":[[1,2.1,66.16],[2,1.51,20]],"ltp":2.26,"tv":11.51,"id":67083366}]}]}
{"op":"mcm","clk":"11950794513","pt":1724506515906,"mc":[{"id":"1.232215600","rc":[{"batb":[[0,1.72,59.65]],"ltp":1.72,"tv":30.4,"id":72857114},{"batb":[[0,2.26,34.08]],"ltp":2.26,"tv":11.51,"id":67083366}]}]}
{"op":"mcm","clk":"11950895098","pt":1724507042831,"mc":[{"id":"1.232215600","rc":[{"trd":[[2.26,10.84]],"batb":[[0,2.26,31.88]],"ltp":2.26,"tv":15.91,"id":67083366}],"tv":46.32}]}
{"op":"mcm","clk":"11950896153","pt":1724507047984,"mc":[{"id":"1.232215600","rc":[{"batb":[[0,2.26,34.08]],"ltp":2.26,"tv":15.91,"id":67083366}]}]}
{"op":"mcm","clk":"11950906291","pt":1724507101202,"mc":[{"id":"1.232215600","rc":[{"batb":[[1,1.71,25.09],[2,1.66,66.16]],"ltp":1.72,"tv":30.4,"id":72857114},{"batb":[[1,2.24,14.37],[2,2.1,66.16]],"ltp":2.26,"tv":15.91,"id":67083366}]}]}
{"op":"mcm","clk":"11951021688","pt":1724507754251,"mc":[{"id":"1.232215600","rc":[{"batb":[[0,1.79,4],[1,1.72,59.65],[2,1.71,25.09]],"ltp":1.72,"tv":30.4,"id":72857114}]}]}
{"op":"mcm","clk":"11951021775","pt":1724507754651,"mc":[{"id":"1.232215600","rc":[{"batb":[[1,1.72,84.39]],"ltp":1.72,"tv":30.4,"id":72857114}]}]}
{"op":"mcm","clk":"11951080672","pt":1724508054773,"mc":[{"id":"1.232215600","rc":[{"trd":[[1.79,5.56]],"batb":[[0,1.79,1.22]],"ltp":1.79,"tv":35.96,"id":72857114}],"tv":51.88}]}
{"op":"mcm","clk":"11951102905","pt":1724508138190,"mc":[{"id":"1.232215600","rc":[{"batb":[[0,1.73,5.04]],"ltp":1.79,"tv":35.96,"id":72857114}]}]}
{"op":"mcm","clk":"11951103759","pt":1724508141387,"mc":[{"id":"1.232215600","rc":[{"batb":[[0,1.72,84.43],[1,1.71,25.09],[2,1.66,66.16]],"ltp":1.79,"tv":35.96,"id":72857114}]}]}
{"op":"mcm","clk":"11951105379","pt":1724508147427,"mc":[{"id":"1.232215600","rc":[{"batb":[[0,1.73,5.04],[1,1.72,84.39],[2,1.71,25.09]],"ltp":1.79,"tv":35.96,"id":72857114}]}]}
{"op":"mcm","clk":"11951106307","pt":1724508150666,"mc":[{"id":"1.232215600","rc":[{"batb":[[0,1.72,84.43],[1,1.71,25.09],[2,1.66,66.16]],"ltp":1.79,"tv":35.96,"id":72857114}]}]}
{"op":"mcm","clk":"11951113176","pt":1724508174994,"mc":[{"id":"1.232215600","rc":[{"trd":[[1.8,5]],"batb":[[0,1.79,4.04],[1,1.72,84.39],[2,1.71,25.09]],"ltp":1.8,"tv":40.96,"id":72857114},{"trd":[[2.26,14.82]],"batb":[[0,2.26,30.1]],"ltp":2.26,"tv":19.89,"id":67083366}],"tv":60.86}]}
{"op":"mcm","clk":"11951114353","pt":1724508179410,"mc":[{"id":"1.232215600","rc":[{"trd":[[1.8,10]],"ltp":1.8,"tv":45.96,"id":72857114},{"trd":[[2.26,18.8]],"ltp":2.26,"tv":23.87,"id":67083366}],"tv":69.84}]}
{"op":"mcm","clk":"11951115525","pt":1724508183820,"mc":[{"id":"1.232215600","rc":[{"trd":[[1.8,15]],"ltp":1.8,"tv":50.96,"id":72857114},{"trd":[[2.26,22.78]],"ltp":2.26,"tv":27.85,"id":67083366}],"tv":78.82}]}
{"op":"mcm","clk":"11951116812","pt":1724508188728,"mc":[{"id":"1.232215600","rc":[{"trd":[[1.8,20]],"ltp":1.8,"tv":55.96,"id":72857114},{"trd":[[2.26,26.76]],"ltp":2.26,"tv":31.83,"id":67083366}],"tv":87.8}]}
{"op":"mcm","clk":"11951118190","pt":1724508193923,"mc":[{"id":"1.232215600","rc":[{"trd":[[1.8,25]],"ltp":1.8,"tv":60.96,"id":72857114},{"trd":[[2.26,30.74]],"ltp":2.26,"tv":35.81,"id":67083366}],"tv":96.78}]}
{"op":"mcm","clk":"11951119515","pt":1724508198945,"mc":[{"id":"1.232215600","rc":[{"trd":[[1.8,30]],"ltp":1.8,"tv":65.96,"id":72857114},{"trd":[[2.26,34.72]],"ltp":2.26,"tv":39.79,"id":67083366}],"tv":105.76}]}
{"op":"mcm","clk":"11951120805","pt":1724508203948,"mc":[{"id":"1.232215600","rc":[{"trd":[[1.8,35]],"ltp":1.8,"tv":70.96,"id":72857114},{"trd":[[2.26,38.7]],"ltp":2.26,"tv":43.77,"id":67083366}],"tv":114.74}]}
{"op":"mcm","clk":"11951122129","pt":1724508208944,"mc":[{"id":"1.232215600","rc":[{"trd":[[1.8,40]],"ltp":1.8,"tv":75.96,"id":72857114},{"trd":[[2.26,42.68]],"ltp":2.26,"tv":47.75,"id":67083366}],"tv":123.72}]}
{"op":"mcm","clk":"11951123516","pt":1724508214230,"mc":[{"id":"1.232215600","rc":[{"trd":[[1.8,45]],"ltp":1.8,"tv":80.96,"id":72857114},{"trd":[[2.26,46.66]],"ltp":2.26,"tv":51.73,"id":67083366}],"tv":132.7}]}
{"op":"mcm","clk":"11951124783","pt":1724508218854,"mc":[{"id":"1.232215600","rc":[{"batb":[[0,2.26,34.08]],"ltp":2.26,"tv":51.73,"id":67083366}]}]}
{"op":"mcm","clk":"11951124984","pt":1724508219538,"mc":[{"id":"1.232215600","rc":[{"trd":[[1.8,50]],"ltp":1.8,"tv":85.96,"id":72857114},{"trd":[[2.26,50.64]],"batb":[[0,2.26,30.1]],"ltp":2.26,"tv":55.71,"id":67083366}],"tv":141.68}]}
{"op":"mcm","clk":"11951126255","pt":1724508224043,"mc":[{"id":"1.232215600","rc":[{"trd":[[1.8,55]],"ltp":1.8,"tv":90.96,"id":72857114},{"trd":[[2.26,54.62]],"ltp":2.26,"tv":59.69,"id":67083366}],"tv":150.66}]}
{"op":"mcm","clk":"11951127635","pt":1724508229347,"mc":[{"id":"1.232215600","rc":[{"trd":[[1.8,60]],"ltp":1.8,"tv":95.96,"id":72857114},{"trd":[[2.26,58.6]],"ltp":2.26,"tv":63.67,"id":67083366}],"tv":159.64}]}
{"op":"mcm","clk":"11951129010","pt":1724508234256,"mc":[{"id":"1.232215600","rc":[{"trd":[[1.8,65]],"ltp":1.8,"tv":100.96,"id":72857114},{"trd":[[2.26,62.58]],"ltp":2.26,"tv":67.65,"id":67083366}],"tv":168.62}]}
{"op":"mcm","clk":"11951130460","pt":1724508239256,"mc":[{"id":"1.232215600","rc":[{"batb":[[0,1.8,5],[1,1.79,4.04],[2,1.72,84.39]],"ltp":1.8,"tv":100.96,"id":72857114},{"batb":[[0,2.24,14.37],[1,2.1,66.16],[2,1.51,20]],"ltp":2.26,"tv":67.65,"id":67083366}]}]}
{"op":"mcm","clk":"11951130653","pt":1724508240014,"mc":[{"id":"1.232215600","rc":[{"batb":[[0,2.1,66.16],[1,2.08,16.49]],"ltp":2.26,"tv":67.65,"id":67083366}]}]}
{"op":"mcm","clk":"11951131509","pt":1724508242607,"mc":[{"id":"1.232215600","rc":[{"batb":[[0,1.79,4.04],[1,1.72,84.39],[2,1.71,25.09]],"ltp":1.8,"tv":100.96,"id":72857114}]}]}
{"op":"mcm","clk":"11951132881","pt":1724508246702,"mc":[{"id":"1.232215600","rc":[{"batb":[[0,1.8,5],[1,1.79,4.04],[2,1.72,84.39]],"ltp":1.8,"tv":100.96,"id":72857114}]}]}
{"op":"mcm","clk":"11951134080","pt":1724508250514,"mc":[{"id":"1.232215600","rc":[{"batb":[[0,1.79,4.04],[1,1.72,84.39],[2,1.71,25.09]],"ltp":1.8,"tv":100.96,"id":72857114}]}]}
{"op":"mcm","clk":"11951140397","pt":1724508272215,"mc":[{"id":"1.232215600","rc":[{"batb":[[0,1.8,5],[1,1.79,4.04],[2,1.72,84.39]],"ltp":1.8,"tv":100.96,"id":72857114}]}]}
{"op":"mcm","clk":"11951141380","pt":1724508275079,"mc":[{"id":"1.232215600","rc":[{"batb":[[0,1.79,4.04],[1,1.72,84.39],[2,1.71,25.09]],"ltp":1.8,"tv":100.96,"id":72857114}]}]}
{"op":"mcm","clk":"11951148709","pt":1724508301301,"mc":[{"id":"1.232215600","rc":[{"batb":[[0,1.87,5],[1,1.86,4],[2,1.79,4.04]],"ltp":1.8,"tv":100.96,"id":72857114}]}]}
{"op":"mcm","clk":"11951149781","pt":1724508304829,"mc":[{"id":"1.232215600","rc":[{"batb":[[0,1.86,4],[1,1.79,4.04],[2,1.72,84.39]],"ltp":1.8,"tv":100.96,"id":72857114}]}]}
{"op":"mcm","clk":"11951157874","pt":1724508332325,"mc":[{"id":"1.232215600","rc":[{"batb":[[0,1.87,5],[1,1.86,4],[2,1.79,4.04]],"ltp":1.8,"tv":100.96,"id":72857114}]}]}
{"op":"mcm","clk":"11951158869","pt":1724508335755,"mc":[{"id":"1.232215600","rc":[{"batb":[[0,1.86,4],[1,1.79,4.04],[2,1.72,84.39]],"ltp":1.8,"tv":100.96,"id":72857114}]}]}
{"op":"mcm","clk":"11951160271","pt":1724508340820,"mc":[{"id":"1.232215600","rc":[{"batb":[[0,1.89,5],[1,1.88,4],[2,1.86,4]],"ltp":1.8,"tv":100.96,"id":72857114}]}]}
{"op":"mcm","clk":"11951161260","pt":1724508344151,"mc":[{"id":"1.232215600","rc":[{"batb":[[0,1.88,4],[1,1.86,4],[2,1.79,4.04]],"ltp":1.8,"tv":100.96,"id":72857114}]}]}
{"op":"mcm","clk":"11951162212","pt":1724508347032,"mc":[{"id":"1.232215600","rc":[{"batb":[[0,1.89,5],[1,1.88,4],[2,1.86,4]],"ltp":1.8,"tv":100.96,"id":72857114}]}]}
{"op":"mcm","clk":"11951163240","pt":1724508350442,"mc":[{"id":"1.232215600","rc":[{"batb":[[0,1.88,4],[1,1.86,4],[2,1.79,4.04]],"ltp":1.8,"tv":100.96,"id":72857114}]}]}
{"op":"mcm","clk":"11951164536","pt":1724508354750,"mc":[{"id":"1.232215600","rc":[{"batb":[[0,1.89,5],[1,1.88,4],[2,1.86,4]],"ltp":1.8,"tv":100.96,"id":72857114}]}]}
{"op":"mcm","clk":"11951165460","pt":1724508358083,"mc":[{"id":"1.232215600","rc":[{"batb":[[0,1.88,4],[1,1.86,4],[2,1.79,4.04]],"ltp":1.8,"tv":100.96,"id":72857114}]}]}
{"op":"mcm","clk":"11951167776","pt":1724508365869,"mc":[{"id":"1.232215600","rc":[{"batb":[[0,1.89,5],[1,1.88,4],[2,1.86,4]],"ltp":1.8,"tv":100.96,"id":72857114}]}]}
{"op":"mcm","clk":"11951168733","pt":1724508369196,"mc":[{"id":"1.232215600","rc":[{"batb":[[0,1.88,4],[1,1.86,4],[2,1.79,4.04]],"ltp":1.8,"tv":100.96,"id":72857114}]}]}
{"op":"mcm","clk":"11951175762","pt":1724508392003,"mc":[{"id":"1.232215600","rc":[{"batb":[[0,1.89,5],[1,1.88,4],[2,1.86,4]],"ltp":1.8,"tv":100.96,"id":72857114}]}]}
{"op":"mcm","clk":"11951176812","pt":1724508395589,"mc":[{"id":"1.232215600","rc":[{"batb":[[0,1.88,4],[1,1.86,4],[2,1.79,4.04]],"ltp":1.8,"tv":100.96,"id":72857114}]}]}
{"op":"mcm","clk":"11951178117","pt":1724508399912,"mc":[{"id":"1.232215600","rc":[{"batb":[[0,1.89,5],[1,1.88,4],[2,1.86,4]],"ltp":1.8,"tv":100.96,"id":72857114}]}]}
{"op":"mcm","clk":"11951179160","pt":1724508403401,"mc":[{"id":"1.232215600","rc":[{"batb":[[0,1.88,4],[1,1.86,4],[2,1.79,4.04]],"ltp":1.8,"tv":100.96,"id":72857114}]}]}
{"op":"mcm","clk":"11951190175","pt":1724508438370,"mc":[{"id":"1.232215600","rc":[{"batb":[[0,1.89,5],[1,1.88,4],[2,1.86,4]],"ltp":1.8,"tv":100.96,"id":72857114}]}]}
{"op":"mcm","clk":"11951191235","pt":1724508441757,"mc":[{"id":"1.232215600","rc":[{"batb":[[0,1.88,4],[1,1.86,4],[2,1.79,4.04]],"ltp":1.8,"tv":100.96,"id":72857114}]}]}
{"op":"mcm","clk":"11951192253","pt":1724508445056,"mc":[{"id":"1.232215600","rc":[{"batb":[[0,1.89,5],[1,1.88,4],[2,1.86,4]],"ltp":1.8,"tv":100.96,"id":72857114}]}]}
{"op":"mcm","clk":"11951193316","pt":1724508448481,"mc":[{"id":"1.232215600","rc":[{"batb":[[0,1.88,4],[1,1.86,4],[2,1.79,4.04]],"ltp":1.8,"tv":100.96,"id":72857114}]}]}
{"op":"mcm","clk":"11951211548","pt":1724508507946,"mc":[{"id":"1.232215600","rc":[{"batb":[[0,1.89,5],[1,1.88,4],[2,1.86,4]],"ltp":1.8,"tv":100.96,"id":72857114}]}]}
{"op":"mcm","clk":"11951212756","pt":1724508511860,"mc":[{"id":"1.232215600","rc":[{"batb":[[0,1.88,4],[1,1.86,4],[2,1.79,4.04]],"ltp":1.8,"tv":100.96,"id":72857114}]}]}
{"op":"mcm","clk":"11951213761","pt":1724508515343,"mc":[{"id":"1.232215600","rc":[{"batb":[[0,1.89,5],[1,1.88,4],[2,1.86,4]],"ltp":1.8,"tv":100.96,"id":72857114}]}]}
{"op":"mcm","clk":"11951214756","pt":1724508518743,"mc":[{"id":"1.232215600","rc":[{"batb":[[0,1.88,4],[1,1.86,4],[2,1.79,4.04]],"ltp":1.8,"tv":100.96,"id":72857114}]}]}
{"op":"mcm","clk":"11951224769","pt":1724508551791,"mc":[{"id":"1.232215600","rc":[{"batb":[[0,1.89,5],[1,1.88,4],[2,1.86,4]],"ltp":1.8,"tv":100.96,"id":72857114}]}]}
{"op":"mcm","clk":"11951225740","pt":1724508554994,"mc":[{"id":"1.232215600","rc":[{"batb":[[0,1.88,4],[1,1.86,4],[2,1.79,4.04]],"ltp":1.8,"tv":100.96,"id":72857114}]}]}
{"op":"mcm","clk":"11951238708","pt":1724508597642,"mc":[{"id":"1.232215600","rc":[{"batb":[[0,1.89,5],[1,1.88,4],[2,1.86,4]],"ltp":1.8,"tv":100.96,"id":72857114}]}]}
{"op":"mcm","clk":"11951239823","pt":1724508601266,"mc":[{"id":"1.232215600","rc":[{"batb":[[0,1.88,4],[1,1.86,4],[2,1.79,4.04]],"ltp":1.8,"tv":100.96,"id":72857114}]}]}
{"op":"mcm","clk":"11951241143","pt":1724508605747,"mc":[{"id":"1.232215600","rc":[{"batb":[[0,1.89,5],[1,1.88,4],[2,1.86,4]],"ltp":1.8,"tv":100.96,"id":72857114}]}]}
{"op":"mcm","clk":"11951242172","pt":1724508609163,"mc":[{"id":"1.232215600","rc":[{"batb":[[0,1.88,4],[1,1.86,4],[2,1.79,4.04]],"ltp":1.8,"tv":100.96,"id":72857114}]}]}
{"op":"mcm","clk":"11951243054","pt":1724508611761,"mc":[{"id":"1.232215600","rc":[{"batb":[[0,1.89,5],[1,1.88,4],[2,1.86,4]],"ltp":1.8,"tv":100.96,"id":72857114}]}]}
{"op":"mcm","clk":"11951244099","pt":1724508615157,"mc":[{"id":"1.232215600","rc":[{"batb":[[0,1.88,4],[1,1.86,4],[2,1.79,4.04]],"ltp":1.8,"tv":100.96,"id":72857114}]}]}
{"op":"mcm","clk":"11951260607","pt":1724508666329,"mc":[{"id":"1.232215600","rc":[{"batb":[[0,1.89,5],[1,1.88,4],[2,1.86,4]],"ltp":1.8,"tv":100.96,"id":72857114}]}]}
{"op":"mcm","clk":"11951261713","pt":1724508669841,"mc":[{"id":"1.232215600","rc":[{"batb":[[0,1.88,4],[1,1.86,4],[2,1.79,4.04]],"ltp":1.8,"tv":100.96,"id":72857114}]}]}
{"op":"mcm","clk":"11951268697","pt":1724508692113,"mc":[{"id":"1.232215600","rc":[{"batb":[[0,1.89,5],[1,1.88,4],[2,1.86,4]],"ltp":1.8,"tv":100.96,"id":72857114}]}]}
{"op":"mcm","clk":"11951269750","pt":1724508695401,"mc":[{"id":"1.232215600","rc":[{"batb":[[0,1.88,4],[1,1.86,4],[2,1.72,84.39]],"ltp":1.8,"tv":100.96,"id":72857114}]}]}
{"op":"mcm","clk":"11951270241","pt":1724508696867,"mc":[{"id":"1.232215600","rc":[{"batb":[[1,1.72,84.39],[2,1.66,93.14]],"ltp":1.8,"tv":100.96,"id":72857114}]}]}
{"op":"mcm","clk":"11951270988","pt":1724508699397,"mc":[{"id":"1.232215600","rc":[{"batb":[[0,1.72,84.39],[1,1.66,93.14],[2,1.41,8.74]],"ltp":1.8,"tv":100.96,"id":72857114}]}]}
{"op":"mcm","clk":"11951271053","pt":1724508699558,"mc":[{"id":"1.232215600","rc":[{"batb":[[0,1.73,5],[1,1.72,84.39],[2,1.66,93.14]],"ltp":1.8,"tv":100.96,"id":72857114}]}]}
{"op":"mcm","clk":"11951272123","pt":1724508702885,"mc":[{"id":"1.232215600","rc":[{"batb":[[0,1.72,84.39],[1,1.66,93.14],[2,1.41,8.74]],"ltp":1.8,"tv":100.96,"id":72857114}]}]}
{"op":"mcm","clk":"11951278741","pt":1724508724109,"mc":[{"id":"1.232215600","rc":[{"batb":[[0,1.73,5],[1,1.72,84.39],[2,1.66,93.14]],"ltp":1.8,"tv":100.96,"id":72857114}]}]}
{"op":"mcm","clk":"11951279768","pt":1724508727624,"mc":[{"id":"1.232215600","rc":[{"batb":[[0,1.72,84.39],[1,1.66,93.14],[2,1.41,8.74]],"ltp":1.8,"tv":100.96,"id":72857114}]}]}
{"op":"mcm","clk":"11951284305","pt":1724508742256,"mc":[{"id":"1.232215600","rc":[{"batb":[[0,1.73,5],[1,1.72,84.39],[2,1.66,93.14]],"ltp":1.8,"tv":100.96,"id":72857114}]}]}
{"op":"mcm","clk":"11951285445","pt":1724508745674,"mc":[{"id":"1.232215600","rc":[{"batb":[[0,1.72,84.39],[1,1.66,93.14],[2,1.41,8.74]],"ltp":1.8,"tv":100.96,"id":72857114}]}]}
{"op":"mcm","clk":"11951287586","pt":1724508752874,"mc":[{"id":"1.232215600","rc":[{"batb":[[0,1.73,5],[1,1.72,84.39],[2,1.66,93.14]],"ltp":1.8,"tv":100.96,"id":72857114}]}]}
{"op":"mcm","clk":"11951288654","pt":1724508756332,"mc":[{"id":"1.232215600","rc":[{"batb":[[0,1.72,84.39],[1,1.66,93.14],[2,1.41,8.74]],"ltp":1.8,"tv":100.96,"id":72857114}]}]}
{"op":"mcm","clk":"11951289333","pt":1724508758592,"mc":[{"id":"1.232215600","rc":[{"batb":[[0,1.73,5],[1,1.72,84.39],[2,1.66,93.14]],"ltp":1.8,"tv":100.96,"id":72857114}]}]}
{"op":"mcm","clk":"11951290431","pt":1724508762090,"mc":[{"id":"1.232215600","rc":[{"batb":[[0,1.72,84.39],[1,1.66,93.14],[2,1.41,8.74]],"ltp":1.8,"tv":100.96,"id":72857114}]}]}
{"op":"mcm","clk":"11951313884","pt":1724508780274,"mc":[{"id":"1.232215600","rc":[{"batb":[[0,1.73,5],[1,1.72,84.39],[2,1.66,93.14]],"ltp":1.8,"tv":100.96,"id":72857114}]}]}
{"op":"mcm","clk":"11951314895","pt":1724508783614,"mc":[{"id":"1.232215600","rc":[{"batb":[[0,1.72,84.39],[1,1.66,93.14],[2,1.41,8.74]],"ltp":1.8,"tv":100.96,"id":72857114}]}]}
{"op":"mcm","clk":"11951324051","pt":1724508813566,"mc":[{"id":"1.232215600","rc":[{"batb":[[0,1.73,5],[1,1.72,84.39],[2,1.66,93.14]],"ltp":1.8,"tv":100.96,"id":72857114}]}]}
{"op":"mcm","clk":"11951325064","pt":1724508816910,"mc":[{"id":"1.232215600","rc":[{"batb":[[0,1.72,84.39],[1,1.66,93.14],[2,1.41,8.74]],"ltp":1.8,"tv":100.96,"id":72857114}]}]}
{"op":"mcm","clk":"11951337386","pt":1724508857329,"mc":[{"id":"1.232215600","rc":[{"batb":[[0,1.73,5],[1,1.72,84.39],[2,1.66,93.14]],"ltp":1.8,"tv":100.96,"id":72857114}]}]}
{"op":"mcm","clk":"11951338545","pt":1724508861037,"mc":[{"id":"1.232215600","rc":[{"batb":[[0,1.72,84.39],[1,1.66,93.14],[2,1.41,8.74]],"ltp":1.8,"tv":100.96,"id":72857114}]}]}
{"op":"mcm","clk":"11951347954","pt":1724508892891,"mc":[{"id":"1.232215600","rc":[{"batb":[[0,1.73,5],[1,1.72,84.39],[2,1.66,93.14]],"batl":[[0,2.5,1],[1,2.5,0]],"ltp":1.8,"tv":100.96,"id":72857114}]}]}
{"op":"mcm","clk":"11951349021","pt":1724508896214,"mc":[{"id":"1.232215600","rc":[{"batb":[[0,1.72,84.39],[1,1.66,93.14],[2,1.21,24.75]],"ltp":1.8,"tv":100.96,"id":72857114}]}]}
{"op":"mcm","clk":"11951350773","pt":1724508901790,"mc":[{"id":"1.232215600","rc":[{"batb":[[0,1.73,5],[1,1.72,84.39],[2,1.66,93.14]],"ltp":1.8,"tv":100.96,"id":72857114}]}]}
{"op":"mcm","clk":"11951351934","pt":1724508905336,"mc":[{"id":"1.232215600","rc":[{"batb":[[0,1.72,84.39],[1,1.66,93.14],[2,1.21,24.75]],"ltp":1.8,"tv":100.96,"id":72857114}]}]}
{"op":"mcm","clk":"11951355525","pt":1724508916895,"mc":[{"id":"1.232215600","rc":[{"batb":[[0,1.73,5],[1,1.72,84.39],[2,1.66,93.14]],"ltp":1.8,"tv":100.96,"id":72857114}]}]}
{"op":"mcm","clk":"11951356285","pt":1724508919622,"mc":[{"id":"1.232215600","rc":[{"batl":[[0,2.24,5.14],[1,2.5,1]],"ltp":1.8,"tv":100.96,"id":72857114}]}]}
{"op":"mcm","clk":"11951356568","pt":1724508920578,"mc":[{"id":"1.232215600","rc":[{"batb":[[0,1.72,84.39],[1,1.66,93.14],[2,1.43,8.23]],"ltp":1.8,"tv":100.96,"id":72857114}]}]}
{"op":"mcm","clk":"11951364101","pt":1724508945970,"mc":[{"id":"1.232215600","rc":[{"batb":[[0,1.73,5],[1,1.72,84.39],[2,1.66,93.14]],"ltp":1.8,"tv":100.96,"id":72857114}]}]}
{"op":"mcm","clk":"11951365135","pt":1724508949643,"mc":[{"id":"1.232215600","rc":[{"batb":[[0,1.72,84.39],[1,1.66,93.14],[2,1.43,8.23]],"ltp":1.8,"tv":100.96,"id":72857114}]}]}
{"op":"mcm","clk":"11951368422","pt":1724508960388,"mc":[{"id":"1.232215600","rc":[{"batb":[[0,1.73,5],[1,1.72,84.39],[2,1.66,93.14]],"ltp":1.8,"tv":100.96,"id":72857114}]}]}
{"op":"mcm","clk":"11951369400","pt":1724508963669,"mc":[{"id":"1.232215600","rc":[{"batb":[[0,1.72,84.39],[1,1.66,93.14],[2,1.43,8.23]],"ltp":1.8,"tv":100.96,"id":72857114}]}]}
{"op":"mcm","clk":"11951371840","pt":1724508972973,"mc":[{"id":"1.232215600","rc":[{"batb":[[0,1.73,5],[1,1.72,84.39],[2,1.66,93.14]],"ltp":1.8,"tv":100.96,"id":72857114}]}]}
{"op":"mcm","clk":"11951373097","pt":1724508975913,"mc":[{"id":"1.232215600","rc":[{"batb":[[0,1.72,84.39],[1,1.66,93.14],[2,1.43,8.23]],"ltp":1.8,"tv":100.96,"id":72857114}]}]}
{"op":"mcm","clk":"11951381282","pt":1724509002234,"mc":[{"id":"1.232215600","rc":[{"batb":[[0,1.73,5],[1,1.72,84.39],[2,1.66,93.14]],"ltp":1.8,"tv":100.96,"id":72857114}]}]}
{"op":"mcm","clk":"11951382410","pt":1724509005704,"mc":[{"id":"1.232215600","rc":[{"batb":[[0,1.72,84.39],[1,1.66,93.14],[2,1.43,8.23]],"ltp":1.8,"tv":100.96,"id":72857114}]}]}
{"op":"mcm","clk":"11951394624","pt":1724509045382,"mc":[{"id":"1.232215600","rc":[{"batb":[[0,1.73,5],[1,1.72,84.39],[2,1.66,93.14]],"ltp":1.8,"tv":100.96,"id":72857114}]}]}
{"op":"mcm","clk":"11951395749","pt":1724509048881,"mc":[{"id":"1.232215600","rc":[{"batb":[[0,1.72,84.39],[1,1.66,93.14],[2,1.43,8.23]],"ltp":1.8,"tv":100.96,"id":72857114}]}]}
{"op":"mcm","clk":"11951407771","pt":1724509089410,"mc":[{"id":"1.232215600","rc":[{"batb":[[0,1.73,5],[1,1.72,84.39],[2,1.66,93.14]],"ltp":1.8,"tv":100.96,"id":72857114}]}]}
{"op":"mcm","clk":"11951408831","pt":1724509093073,"mc":[{"id":"1.232215600","rc":[{"batb":[[0,1.72,84.39],[1,1.66,93.14],[2,1.43,8.23]],"ltp":1.8,"tv":100.96,"id":72857114}]}]}
{"op":"mcm","clk":"11951424472","pt":1724509146018,"mc":[{"id":"1.232215600","rc":[{"batb":[[0,1.73,5],[1,1.72,84.39],[2,1.66,93.14]],"ltp":1.8,"tv":100.96,"id":72857114}]}]}
{"op":"mcm","clk":"11951425457","pt":1724509149357,"mc":[{"id":"1.232215600","rc":[{"batb":[[0,1.72,84.39],[1,1.66,93.14],[2,1.43,8.23]],"ltp":1.8,"tv":100.96,"id":72857114}]}]}
{"op":"mcm","clk":"11951434376","pt":1724509178576,"mc":[{"id":"1.232215600","rc":[{"batb":[[0,1.73,5],[1,1.72,84.39],[2,1.66,93.14]],"ltp":1.8,"tv":100.96,"id":72857114}]}]}
{"op":"mcm","clk":"11951435363","pt":1724509182001,"mc":[{"id":"1.232215600","rc":[{"batb":[[0,1.72,84.39],[1,1.66,93.14],[2,1.43,8.23]],"ltp":1.8,"tv":100.96,"id":72857114}]}]}
{"op":"mcm","clk":"11951437577","pt":1724509189678,"mc":[{"id":"1.232215600","rc":[{"batb":[[0,1.73,5],[1,1.72,84.39],[2,1.66,93.14]],"ltp":1.8,"tv":100.96,"id":72857114}]}]}
{"op":"mcm","clk":"11951438666","pt":1724509193229,"mc":[{"id":"1.232215600","rc":[{"batb":[[0,1.72,84.39],[1,1.66,93.14],[2,1.43,8.23]],"ltp":1.8,"tv":100.96,"id":72857114}]}]}
{"op":"mcm","clk":"11951451628","pt":1724509234661,"mc":[{"id":"1.232215600","rc":[{"batb":[[0,1.73,5],[1,1.72,84.39],[2,1.66,93.14]],"ltp":1.8,"tv":100.96,"id":72857114}]}]}
{"op":"mcm","clk":"11951452635","pt":1724509237897,"mc":[{"id":"1.232215600","rc":[{"batb":[[0,1.72,84.39],[1,1.66,93.14],[2,1.43,8.23]],"ltp":1.8,"tv":100.96,"id":72857114}]}]}
{"op":"mcm","clk":"11951469147","pt":1724509293382,"mc":[{"id":"1.232215600","rc":[{"batb":[[0,1.73,5],[1,1.72,84.39],[2,1.66,93.14]],"ltp":1.8,"tv":100.96,"id":72857114}]}]}
{"op":"mcm","clk":"11951470168","pt":1724509296010,"mc":[{"id":"1.232215600","rc":[{"batb":[[0,1.72,84.39],[1,1.66,93.14],[2,1.43,8.23]],"ltp":1.8,"tv":100.96,"id":72857114}]}]}
{"op":"mcm","clk":"11951483140","pt":1724509337818,"mc":[{"id":"1.232215600","rc":[{"batb":[[0,1.73,5],[1,1.72,84.39],[2,1.66,93.14]],"ltp":1.8,"tv":100.96,"id":72857114}]}]}
{"op":"mcm","clk":"11951484265","pt":1724509341393,"mc":[{"id":"1.232215600","rc":[{"batb":[[0,1.72,84.39],[1,1.66,93.14],[2,1.43,8.23]],"ltp":1.8,"tv":100.96,"id":72857114}]}]}
{"op":"mcm","clk":"11951487861","pt":1724509352822,"mc":[{"id":"1.232215600","rc":[{"batb":[[0,1.73,5],[1,1.72,84.39],[2,1.66,93.14]],"ltp":1.8,"tv":100.96,"id":72857114}]}]}
{"op":"mcm","clk":"11951488982","pt":1724509356437,"mc":[{"id":"1.232215600","rc":[{"batb":[[0,1.72,84.39],[1,1.66,93.14],[2,1.43,8.23]],"ltp":1.8,"tv":100.96,"id":72857114}]}]}
{"op":"mcm","clk":"11951497361","pt":1724509383003,"mc":[{"id":"1.232215600","rc":[{"batb":[[0,1.73,5],[1,1.72,84.39],[2,1.66,93.14]],"ltp":1.8,"tv":100.96,"id":72857114}]}]}
{"op":"mcm","clk":"11951498473","pt":1724509386587,"mc":[{"id":"1.232215600","rc":[{"batb":[[0,1.72,84.39],[1,1.66,93.14],[2,1.43,8.23]],"ltp":1.8,"tv":100.96,"id":72857114}]}]}
{"op":"mcm","clk":"11951511241","pt":1724509428332,"mc":[{"id":"1.232215600","rc":[{"batb":[[0,1.73,5],[1,1.72,84.39],[2,1.66,93.14]],"ltp":1.8,"tv":100.96,"id":72857114}]}]}
{"op":"mcm","clk":"11951512257","pt":1724509431825,"mc":[{"id":"1.232215600","rc":[{"batb":[[0,1.72,84.39],[1,1.66,93.14],[2,1.43,8.23]],"ltp":1.8,"tv":100.96,"id":72857114}]}]}
{"op":"mcm","clk":"11951525304","pt":1724509473976,"mc":[{"id":"1.232215600","rc":[{"batb":[[0,1.73,5],[1,1.72,84.39],[2,1.66,93.14]],"ltp":1.8,"tv":100.96,"id":72857114}]}]}
{"op":"mcm","clk":"11951526284","pt":1724509477275,"mc":[{"id":"1.232215600","rc":[{"batb":[[0,1.72,84.39],[1,1.66,93.14],[2,1.43,8.23]],"ltp":1.8,"tv":100.96,"id":72857114}]}]}
{"op":"mcm","clk":"11951556538","pt":1724509576887,"mc":[{"id":"1.232215600","rc":[{"batb":[[0,1.73,5],[1,1.72,84.39],[2,1.66,93.14]],"ltp":1.8,"tv":100.96,"id":72857114}]}]}
{"op":"mcm","clk":"11951557608","pt":1724509580403,"mc":[{"id":"1.232215600","rc":[{"batb":[[0,1.72,84.39],[1,1.66,93.14],[2,1.43,8.23]],"ltp":1.8,"tv":100.96,"id":72857114}]}]}
{"op":"mcm","clk":"11951570250","pt":1724509621731,"mc":[{"id":"1.232215600","rc":[{"batb":[[0,1.73,5],[1,1.72,84.39],[2,1.66,93.14]],"ltp":1.8,"tv":100.96,"id":72857114}]}]}
{"op":"mcm","clk":"11951571294","pt":1724509625105,"mc":[{"id":"1.232215600","rc":[{"batb":[[0,1.72,84.39],[1,1.66,93.14],[2,1.43,8.23]],"ltp":1.8,"tv":100.96,"id":72857114}]}]}
{"op":"mcm","clk":"11951578381","pt":1724509648226,"mc":[{"id":"1.232215600","rc":[{"batb":[[0,1.73,5],[1,1.72,84.39],[2,1.66,93.14]],"ltp":1.8,"tv":100.96,"id":72857114}]}]}
{"op":"mcm","clk":"11951579453","pt":1724509651858,"mc":[{"id":"1.232215600","rc":[{"batb":[[0,1.72,84.39],[1,1.66,93.14],[2,1.43,8.23]],"ltp":1.8,"tv":100.96,"id":72857114}]}]}
{"op":"mcm","clk":"11951584013","pt":1724509667617,"mc":[{"id":"1.232215600","rc":[{"batb":[[0,1.73,5],[1,1.72,84.39],[2,1.66,93.14]],"ltp":1.8,"tv":100.96,"id":72857114}]}]}
{"op":"mcm","clk":"11951585046","pt":1724509670858,"mc":[{"id":"1.232215600","rc":[{"batb":[[0,1.72,84.39],[1,1.66,93.14],[2,1.43,8.23]],"ltp":1.8,"tv":100.96,"id":72857114}]}]}
{"op":"mcm","clk":"11951597417","pt":1724509713465,"mc":[{"id":"1.232215600","rc":[{"batb":[[0,1.73,5],[1,1.72,84.39],[2,1.66,93.14]],"ltp":1.8,"tv":100.96,"id":72857114}]}]}
{"op":"mcm","clk":"11951598463","pt":1724509716656,"mc":[{"id":"1.232215600","rc":[{"batb":[[0,1.72,84.39],[1,1.66,93.14],[2,1.43,8.23]],"ltp":1.8,"tv":100.96,"id":72857114}]}]}
{"op":"mcm","clk":"11951611324","pt":1724509758964,"mc":[{"id":"1.232215600","rc":[{"batb":[[0,1.73,5],[1,1.72,84.39],[2,1.66,93.14]],"ltp":1.8,"tv":100.96,"id":72857114}]}]}
{"op":"mcm","clk":"11951612449","pt":1724509762458,"mc":[{"id":"1.232215600","rc":[{"batb":[[0,1.72,84.39],[1,1.66,93.14],[2,1.43,8.23]],"ltp":1.8,"tv":100.96,"id":72857114}]}]}
{"op":"mcm","clk":"11951642106","pt":1724509855609,"mc":[{"id":"1.232215600","rc":[{"batb":[[0,1.73,5],[1,1.72,84.39],[2,1.66,93.14]],"ltp":1.8,"tv":100.96,"id":72857114}]}]}
{"op":"mcm","clk":"11951643164","pt":1724509859231,"mc":[{"id":"1.232215600","rc":[{"batb":[[0,1.72,84.39],[1,1.66,93.14],[2,1.43,8.23]],"ltp":1.8,"tv":100.96,"id":72857114}]}]}
{"op":"mcm","clk":"11951650064","pt":1724509880861,"mc":[{"id":"1.232215600","rc":[{"batb":[[0,1.73,5],[1,1.72,84.39],[2,1.66,93.14]],"ltp":1.8,"tv":100.96,"id":72857114}]}]}
{"op":"mcm","clk":"11951651070","pt":1724509884166,"mc":[{"id":"1.232215600","rc":[{"batb":[[0,1.72,84.39],[1,1.66,93.14],[2,1.43,8.23]],"ltp":1.8,"tv":100.96,"id":72857114}]}]}
{"op":"mcm","clk":"11951653678","pt":1724509892199,"mc":[{"id":"1.232215600","rc":[{"batb":[[0,1.73,5],[1,1.72,84.39],[2,1.66,93.14]],"ltp":1.8,"tv":100.96,"id":72857114}]}]}
{"op":"mcm","clk":"11951654999","pt":1724509896145,"mc":[{"id":"1.232215600","rc":[{"batb":[[0,1.72,84.39],[1,1.66,93.14],[2,1.43,8.23]],"ltp":1.8,"tv":100.96,"id":72857114}]}]}
{"op":"mcm","clk":"11951673785","pt":1724509953628,"mc":[{"id":"1.232215600","rc":[{"batb":[[0,1.73,5],[1,1.72,84.39],[2,1.66,93.14]],"ltp":1.8,"tv":100.96,"id":72857114}]}]}
{"op":"mcm","clk":"11951674921","pt":1724509957096,"mc":[{"id":"1.232215600","rc":[{"batb":[[0,1.72,84.39],[1,1.66,93.14],[2,1.43,8.23]],"ltp":1.8,"tv":100.96,"id":72857114}]}]}
{"op":"mcm","clk":"11951683473","pt":1724509984079,"mc":[{"id":"1.232215600","rc":[{"batb":[[0,1.73,5],[1,1.72,84.39],[2,1.66,93.14]],"ltp":1.8,"tv":100.96,"id":72857114}]}]}
{"op":"mcm","clk":"11951684548","pt":1724509987473,"mc":[{"id":"1.232215600","rc":[{"batb":[[0,1.72,84.39],[1,1.66,93.14],[2,1.43,8.23]],"ltp":1.8,"tv":100.96,"id":72857114}]}]}
{"op":"mcm","clk":"11951688829","pt":1724510000930,"mc":[{"id":"1.232215600","rc":[{"batb":[[0,1.73,5],[1,1.72,84.39],[2,1.66,93.14]],"ltp":1.8,"tv":100.96,"id":72857114}]}]}
{"op":"mcm","clk":"11951689874","pt":1724510004345,"mc":[{"id":"1.232215600","rc":[{"batb":[[0,1.72,84.39],[1,1.66,93.14],[2,1.43,8.23]],"ltp":1.8,"tv":100.96,"id":72857114}]}]}
{"op":"mcm","clk":"11951705410","pt":1724510054411,"mc":[{"id":"1.232215600","rc":[{"batb":[[0,1.73,5],[1,1.72,84.39],[2,1.66,93.14]],"ltp":1.8,"tv":100.96,"id":72857114}]}]}
{"op":"mcm","clk":"11951706553","pt":1724510057842,"mc":[{"id":"1.232215600","rc":[{"batb":[[0,1.72,84.39],[1,1.66,93.14],[2,1.43,8.23]],"ltp":1.8,"tv":100.96,"id":72857114}]}]}
{"op":"mcm","clk":"11951724115","pt":1724510111508,"mc":[{"id":"1.232215600","rc":[{"batb":[[0,1.73,5],[1,1.72,84.39],[2,1.66,93.14]],"ltp":1.8,"tv":100.96,"id":72857114}]}]}
{"op":"mcm","clk":"11951725175","pt":1724510114827,"mc":[{"id":"1.232215600","rc":[{"batb":[[0,1.72,84.39],[1,1.66,93.14],[2,1.43,8.23]],"ltp":1.8,"tv":100.96,"id":72857114}]}]}
{"op":"mcm","clk":"11951731657","pt":1724510134838,"mc":[{"id":"1.232215600","rc":[{"batb":[[0,1.73,5],[1,1.72,84.39],[2,1.66,93.14]],"ltp":1.8,"tv":100.96,"id":72857114}]}]}
{"op":"mcm","clk":"11951732772","pt":1724510138375,"mc":[{"id":"1.232215600","rc":[{"batb":[[0,1.72,84.39],[1,1.66,93.14],[2,1.43,8.23]],"ltp":1.8,"tv":100.96,"id":72857114}]}]}
{"op":"mcm","clk":"11951742750","pt":1724510170429,"mc":[{"id":"1.232215600","rc":[{"batb":[[0,1.73,5],[1,1.72,84.39],[2,1.66,93.14]],"ltp":1.8,"tv":100.96,"id":72857114}]}]}
{"op":"mcm","clk":"11951743760","pt":1724510173728,"mc":[{"id":"1.232215600","rc":[{"batb":[[0,1.72,84.39],[1,1.66,93.14],[2,1.43,8.23]],"ltp":1.8,"tv":100.96,"id":72857114}]}]}
{"op":"mcm","clk":"11951761567","pt":1724510227619,"mc":[{"id":"1.232215600","rc":[{"batb":[[0,1.73,5],[1,1.72,84.39],[2,1.66,93.14]],"ltp":1.8,"tv":100.96,"id":72857114}]}]}
{"op":"mcm","clk":"11951762736","pt":1724510231097,"mc":[{"id":"1.232215600","rc":[{"batb":[[0,1.72,84.39],[1,1.66,93.14],[2,1.43,8.23]],"ltp":1.8,"tv":100.96,"id":72857114}]}]}
{"op":"mcm","clk":"11951780649","pt":1724510284541,"mc":[{"id":"1.232215600","rc":[{"batb":[[0,1.73,5],[1,1.72,84.39],[2,1.66,93.14]],"ltp":1.8,"tv":100.96,"id":72857114}]}]}
{"op":"mcm","clk":"11951781837","pt":1724510288068,"mc":[{"id":"1.232215600","rc":[{"batb":[[0,1.72,84.39],[1,1.66,93.14],[2,1.43,8.23]],"ltp":1.8,"tv":100.96,"id":72857114}]}]}
{"op":"mcm","clk":"11951796017","pt":1724510330618,"mc":[{"id":"1.232215600","rc":[{"batb":[[0,1.73,5],[1,1.72,84.39],[2,1.66,93.14]],"ltp":1.8,"tv":100.96,"id":72857114}]}]}
{"op":"mcm","clk":"11951797014","pt":1724510333952,"mc":[{"id":"1.232215600","rc":[{"batb":[[0,1.72,84.39],[1,1.66,93.14],[2,1.43,8.23]],"ltp":1.8,"tv":100.96,"id":72857114}]}]}
{"op":"mcm","clk":"11951812098","pt":1724510381633,"mc":[{"id":"1.232215600","rc":[{"batb":[[0,1.73,5],[1,1.72,84.39],[2,1.66,93.14]],"ltp":1.8,"tv":100.96,"id":72857114}]}]}
{"op":"mcm","clk":"11951813163","pt":1724510384833,"mc":[{"id":"1.232215600","rc":[{"batb":[[0,1.72,84.39],[1,1.66,93.14],[2,1.43,8.23]],"ltp":1.8,"tv":100.96,"id":72857114}]}]}
{"op":"mcm","clk":"11951846035","pt":1724510486813,"mc":[{"id":"1.232215600","rc":[{"batb":[[0,1.73,5],[1,1.72,84.39],[2,1.66,93.14]],"ltp":1.8,"tv":100.96,"id":72857114}]}]}
{"op":"mcm","clk":"11951847094","pt":1724510490154,"mc":[{"id":"1.232215600","rc":[{"batb":[[0,1.72,84.39],[1,1.66,93.14],[2,1.43,8.23]],"ltp":1.8,"tv":100.96,"id":72857114}]}]}
{"op":"mcm","clk":"11951854770","pt":1724510513963,"mc":[{"id":"1.232215600","rc":[{"batb":[[0,1.73,5],[1,1.72,84.39],[2,1.66,93.14]],"ltp":1.8,"tv":100.96,"id":72857114}]}]}
{"op":"mcm","clk":"11951855918","pt":1724510517686,"mc":[{"id":"1.232215600","rc":[{"batb":[[0,1.72,84.39],[1,1.66,93.14],[2,1.43,8.23]],"ltp":1.8,"tv":100.96,"id":72857114}]}]}
{"op":"mcm","clk":"11951857432","pt":1724510524712,"mc":[{"id":"1.232215600","rc":[{"batb":[[0,1.73,5],[1,1.72,84.39],[2,1.66,93.14]],"ltp":1.8,"tv":100.96,"id":72857114}]}]}
{"op":"mcm","clk":"11951858435","pt":1724510526679,"mc":[{"id":"1.232215600","rc":[{"batb":[[0,1.72,84.39],[1,1.66,93.14],[2,1.43,8.23]],"ltp":1.8,"tv":100.96,"id":72857114}]}]}
{"op":"mcm","clk":"11951860597","pt":1724510532653,"mc":[{"id":"1.232215600","rc":[{"batb":[[0,1.73,5],[1,1.72,84.39],[2,1.66,93.14]],"ltp":1.8,"tv":100.96,"id":72857114}]}]}
{"op":"mcm","clk":"11951861780","pt":1724510536125,"mc":[{"id":"1.232215600","rc":[{"batb":[[0,1.72,84.39],[1,1.66,93.14],[2,1.43,8.23]],"ltp":1.8,"tv":100.96,"id":72857114}]}]}
{"op":"mcm","clk":"11951870566","pt":1724510562447,"mc":[{"id":"1.232215600","rc":[{"batb":[[0,1.73,5],[1,1.72,84.39],[2,1.66,93.14]],"ltp":1.8,"tv":100.96,"id":72857114}]}]}
{"op":"mcm","clk":"11951871701","pt":1724510565969,"mc":[{"id":"1.232215600","rc":[{"batb":[[0,1.72,84.39],[1,1.66,93.14],[2,1.43,8.23]],"ltp":1.8,"tv":100.96,"id":72857114}]}]}
{"op":"mcm","clk":"11951875029","pt":1724510576809,"mc":[{"id":"1.232215600","rc":[{"batb":[[0,1.73,5],[1,1.72,84.39],[2,1.66,93.14]],"ltp":1.8,"tv":100.96,"id":72857114}]}]}
{"op":"mcm","clk":"11951876056","pt":1724510580150,"mc":[{"id":"1.232215600","rc":[{"batb":[[0,1.72,84.39],[1,1.66,93.14],[2,1.43,8.23]],"ltp":1.8,"tv":100.96,"id":72857114}]}]}
{"op":"mcm","clk":"11951883144","pt":1724510602344,"mc":[{"id":"1.232215600","rc":[{"trd":[[1.91,26.42]],"batb":[[0,1.73,5],[1,1.72,84.39],[2,1.66,93.14]],"ltp":1.91,"tv":127.38,"id":72857114},{"trd":[[2.1,24.03]],"batb":[[0,2.1,42.13]],"ltp":2.1,"tv":91.67,"id":67083366}],"tv":219.06}]}
{"op":"mcm","clk":"11951884276","pt":1724510605672,"mc":[{"id":"1.232215600","rc":[{"batb":[[0,1.72,84.39],[1,1.66,93.14],[2,1.43,8.23]],"ltp":1.91,"tv":127.38,"id":72857114}]}]}
{"op":"mcm","clk":"11951892577","pt":1724510630622,"mc":[{"id":"1.232215600","rc":[{"batb":[[0,1.73,5],[1,1.72,84.39],[2,1.66,93.14]],"ltp":1.91,"tv":127.38,"id":72857114}]}]}
{"op":"mcm","clk":"11951893576","pt":1724510633910,"mc":[{"id":"1.232215600","rc":[{"batb":[[0,1.72,84.39],[1,1.66,93.14],[2,1.43,8.23]],"ltp":1.91,"tv":127.38,"id":72857114}]}]}
{"op":"mcm","clk":"11951899914","pt":1724510654085,"mc":[{"id":"1.232215600","rc":[{"batl":[[0,1.89,2],[1,2.24,5.14],[2,2.5,1]],"ltp":1.91,"tv":127.38,"id":72857114}]}]}
{"op":"mcm","clk":"11951900197","pt":1724510654979,"mc":[{"id":"1.232215600","rc":[{"batb":[[0,2.1,58.32]],"ltp":2.1,"tv":91.67,"id":67083366}]}]}
{"op":"mcm","clk":"11951915665","pt":1724510704890,"mc":[{"id":"1.232215600","rc":[{"batb":[[0,1.72,29.74]],"ltp":1.91,"tv":127.38,"id":72857114}]}]}
{"op":"mcm","clk":"11951915925","pt":1724510705646,"mc":[{"id":"1.232215600","rc":[{"batb":[[0,1.72,5]],"ltp":1.91,"tv":127.38,"id":72857114}]}]}
{"op":"mcm","clk":"11951969045","pt":1724510889776,"mc":[{"id":"1.232215600","rc":[{"trd":[[1.72,7.04]],"batb":[[0,1.72,4.48]],"ltp":1.72,"tv":128.42,"id":72857114}],"tv":220.1}]}
{"op":"mcm","clk":"11951969243","pt":1724510890473,"mc":[{"id":"1.232215600","rc":[{"batb":[[0,1.72,5]],"ltp":1.72,"tv":128.42,"id":72857114}]}]}
{"op":"mcm","clk":"11952120804","pt":1724511671894,"mc":[{"id":"1.232215600","rc":[{"batb":[[0,1.72,5.7]],"batl":[[0,1.88,1.54],[1,1.89,2],[2,2.24,5.14]],"ltp":1.72,"tv":128.42,"id":72857114}]}]}
{"op":"mcm","clk":"11952135363","pt":1724511743271,"mc":[{"id":"1.232215600","rc":[{"batb":[[0,1.73,2.11],[1,1.72,5],[2,1.66,93.14]],"ltp":1.72,"tv":128.42,"id":72857114}]}]}
{"op":"mcm","clk":"11952193610","pt":1724511972040,"mc":[{"id":"1.232215600","rc":[{"batl":[[0,1.89,2],[1,2.24,5.14],[2,2.5,1]],"ltp":1.72,"tv":128.42,"id":72857114}]}]}
{"op":"mcm","clk":"11952193719","pt":1724511972450,"mc":[{"id":"1.232215600","rc":[{"batb":[[0,1.73,1.41]],"ltp":1.72,"tv":128.42,"id":72857114}]}]}
{"op":"mcm","clk":"11952194294","pt":1724511974364,"mc":[{"id":"1.232215600","rc":[{"batb":[[0,1.73,2.1]],"batl":[[0,1.88,1.54],[1,1.89,2],[2,2.24,5.14]],"ltp":1.72,"tv":128.42,"id":72857114}]}]}
{"op":"mcm","clk":"11952214924","pt":1724512043807,"mc":[{"id":"1.232215600","rc":[{"batb":[[0,1.72,5.69],[1,1.66,93.14],[2,1.43,8.23]],"ltp":1.72,"tv":128.42,"id":72857114}]}]}
{"op":"mcm","clk":"11952218839","pt":1724512056457,"mc":[{"id":"1.232215600","rc":[{"batb":[[0,1.73,2.1],[1,1.72,5],[2,1.66,93.14]],"ltp":1.72,"tv":128.42,"id":72857114}]}]}
{"op":"mcm","clk":"11952283958","pt":1724512275223,"mc":[{"id":"1.232215600","rc":[{"batb":[[0,1.73,1.41]],"batl":[[0,1.89,2],[1,2.24,5.14],[2,2.5,1]],"ltp":1.72,"tv":128.42,"id":72857114}]}]}
{"op":"mcm","clk":"11952286218","pt":1724512282716,"mc":[{"id":"1.232215600","rc":[{"batb":[[0,1.73,2.1]],"batl":[[0,1.88,1.54],[1,1.89,2],[2,2.24,5.14]],"ltp":1.72,"tv":128.42,"id":72857114}]}]}
{"op":"mcm","clk":"11952306192","pt":1724512357028,"mc":[{"id":"1.232215600","rc":[{"batb":[[0,1.72,5.69],[1,1.66,93.14],[2,1.43,8.23]],"ltp":1.72,"tv":128.42,"id":72857114}]}]}
{"op":"mcm","clk":"11952312094","pt":1724512378440,"mc":[{"id":"1.232215600","rc":[{"batb":[[0,1.73,2.1],[1,1.72,5],[2,1.66,93.14]],"ltp":1.72,"tv":128.42,"id":72857114}]}]}
{"op":"mcm","clk":"11952326884","pt":1724512431801,"mc":[{"id":"1.232215600","rc":[{"batl":[[2,2.5,1]],"ltp":1.72,"tv":128.42,"id":72857114}]}]}
{"op":"mcm","clk":"11952370928","pt":1724512583215,"mc":[{"id":"1.232215600","rc":[{"batb":[[0,1.73,1.41]],"ltp":1.72,"tv":128.42,"id":72857114}]}]}
{"op":"mcm","clk":"11952371044","pt":1724512583618,"mc":[{"id":"1.232215600","rc":[{"batl":[[0,1.89,2],[1,2.5,1],[2,2.5,0]],"ltp":1.72,"tv":128.42,"id":72857114}]}]}
{"op":"mcm","clk":"11952375690","pt":1724512600173,"mc":[{"id":"1.232215600","rc":[{"batb":[[0,1.73,2.1]],"batl":[[0,1.88,1.54],[1,1.89,2],[2,2.5,1]],"ltp":1.72,"tv":128.42,"id":72857114}]}]}
{"op":"mcm","clk":"11952395875","pt":1724512672250,"mc":[{"id":"1.232215600","rc":[{"batb":[[0,1.8,80],[1,1.73,2.1],[2,1.72,5]],"ltp":1.72,"tv":128.42,"id":72857114}]}]}
{"op":"mcm","clk":"11952396009","pt":1724512672745,"mc":[{"id":"1.232215600","rc":[{"batb":[[2,1.66,93.14]],"ltp":1.72,"tv":128.42,"id":72857114}]}]}
{"op":"mcm","clk":"11952396436","pt":1724512674376,"mc":[{"id":"1.232215600","rc":[{"batb":[[1,1.79,22.54],[2,1.73,2.1]],"ltp":1.72,"tv":128.42,"id":72857114}]}]}
{"op":"mcm","clk":"11952397869","pt":1724512678922,"mc":[{"id":"1.232215600","rc":[{"batb":[[2,1.66,93.84]],"ltp":1.72,"tv":128.42,"id":72857114}]}]}
{"op":"mcm","clk":"11952402087","pt":1724512693065,"mc":[{"id":"1.232215600","rc":[{"batl":[[2,2.38,4.63]],"ltp":1.72,"tv":128.42,"id":72857114}]}]}
{"op":"mcm","clk":"11952413900","pt":1724512731273,"mc":[{"id":"1.232215600","rc":[{"batb":[[0,1.81,378.47],[1,1.8,102.26],[2,1.79,22.54]],"ltp":1.72,"tv":128.42,"id":72857114}]}]}
{"op":"mcm","clk":"11952429696","pt":1724512786263,"mc":[{"id":"1.232215600","rc":[{"batb":[[1,1.8,80],[2,1.66,66.85]],"ltp":1.72,"tv":128.42,"id":72857114},{"batb":[[0,2.1,42.13],[1,1.51,20],[2,1.21,24.75]],"ltp":2.1,"tv":91.67,"id":67083366}]}]}
{"op":"mcm","clk":"11952432210","pt":1724512794429,"mc":[{"id":"1.232215600","rc":[{"trd":[[1.81,110.02]],"batb":[[0,1.81,323.47]],"ltp":1.81,"tv":238.44,"id":72857114}],"tv":330.12}]}
{"op":"mcm","clk":"11952433510","pt":1724512798729,"mc":[{"id":"1.232215600","rc":[{"batb":[[0,1.84,364.26],[1,1.81,323.47],[2,1.8,80]],"ltp":1.81,"tv":238.44,"id":72857114}]}]}
{"op":"mcm","clk":"11952436032","pt":1724512807120,"mc":[{"id":"1.232215600","rc":[{"trd":[[1.88,3.08],[1.89,4],[1.91,64.48]],"batb":[[0,1.85,5],[1,1.84,364.26],[2,1.81,323.47]],"batl":[[0,2.38,4.63],[1,2.5,1],[2,2.38,0]],"ltp":1.91,"tv":283.58,"id":72857114},{"trd":[[2.1,58.64]],"batb":[[0,2.1,7.51]],"ltp":2.1,"tv":126.29,"id":67083366}],"tv":409.88}]}
{"op":"mcm","clk":"11952436972","pt":1724512810358,"mc":[{"id":"1.232215600","rc":[{"batb":[[0,1.84,364.26],[1,1.81,323.47],[2,1.8,80]],"ltp":1.91,"tv":283.58,"id":72857114}]}]}
{"op":"mcm","clk":"11952438893","pt":1724512816085,"mc":[{"id":"1.232215600","rc":[{"batb":[[0,1.85,5],[1,1.84,364.26],[2,1.81,323.47]],"batl":[[0,2.36,2.06],[1,2.38,4.63],[2,2.5,1]],"ltp":1.91,"tv":283.58,"id":72857114}]}]}
{"op":"mcm","clk":"11952439360","pt":1724512817582,"mc":[{"id":"1.232215600","rc":[{"batl":[[0,2.36,6.69],[1,2.5,1],[2,2.5,0]],"ltp":1.91,"tv":283.58,"id":72857114}]}]}
{"op":"mcm","clk":"11952440100","pt":1724512819815,"mc":[{"id":"1.232215600","rc":[{"batb":[[0,1.84,364.26],[1,1.81,323.47],[2,1.66,66.85]],"ltp":1.91,"tv":283.58,"id":72857114}]}]}
{"op":"mcm","clk":"11952445580","pt":1724512838221,"mc":[{"id":"1.232215600","rc":[{"batl":[[0,1.85,4],[1,2.36,6.69],[2,2.5,1]],"ltp":1.91,"tv":283.58,"id":72857114}]}]}
{"op":"mcm","clk":"11952445645","pt":1724512838434,"mc":[{"id":"1.232215600","rc":[{"trd":[[1.85,8]],"batb":[[0,1.85,1],[1,1.84,364.26],[2,1.81,323.47]],"batl":[[0,2.36,6.69],[1,2.5,1],[2,2.5,0]],"ltp":1.85,"tv":291.58,"id":72857114}],"tv":417.88}]}
{"op":"mcm","clk":"11952446649","pt":1724512841922,"mc":[{"id":"1.232215600","rc":[{"batb":[[0,1.84,364.26],[1,1.81,323.47],[2,1.66,66.85]],"ltp":1.85,"tv":291.58,"id":72857114}]}]}
{"op":"mcm","clk":"11952447608","pt":1724512845346,"mc":[{"id":"1.232215600","rc":[{"batb":[[0,1.85,5],[1,1.84,364.26],[2,1.81,323.47]],"ltp":1.85,"tv":291.58,"id":72857114},{"trd":[[2.1,59]],"batb":[[0,2.1,7.33]],"ltp":2.1,"tv":126.65,"id":67083366}],"tv":418.24}]}
{"op":"mcm","clk":"11952448127","pt":1724512847245,"mc":[{"id":"1.232215600","rc":[{"batb":[[0,1.85,85]],"ltp":1.85,"tv":291.58,"id":72857114}]}]}
{"op":"mcm","clk":"11952448589","pt":1724512848821,"mc":[{"id":"1.232215600","rc":[{"batb":[[0,1.85,80]],"ltp":1.85,"tv":291.58,"id":72857114}]}]}
{"op":"mcm","clk":"11952449984","pt":1724512853938,"mc":[{"id":"1.232215600","rc":[{"batb":[[0,1.86,5],[1,1.85,80],[2,1.84,364.26]],"ltp":1.85,"tv":291.58,"id":72857114}]}]}
{"op":"mcm","clk":"11952450857","pt":1724512857365,"mc":[{"id":"1.232215600","rc":[{"batb":[[0,1.85,80],[1,1.84,364.26],[2,1.81,323.47]],"ltp":1.85,"tv":291.58,"id":72857114}]}]}
{"op":"mcm","clk":"11952452365","pt":1724512862777,"mc":[{"id":"1.232215600","rc":[{"batl":[[0,1.86,20],[1,2.36,6.69],[2,2.5,1]],"ltp":1.85,"tv":291.58,"id":72857114}]}]}
{"op":"mcm","clk":"11952454631","pt":1724512871240,"mc":[{"id":"1.232215600","rc":[{"batb":[[0,1.86,5],[1,1.85,80],[2,1.84,364.26]],"batl":[[0,2.36,6.69],[1,2.5,1],[2,2.5,0]],"ltp":1.85,"tv":291.58,"id":72857114}]}]}
{"op":"mcm","clk":"11952455528","pt":1724512874556,"mc":[{"id":"1.232215600","rc":[{"batb":[[0,1.85,80],[1,1.84,364.26],[2,1.81,323.47]],"ltp":1.85,"tv":291.58,"id":72857114}]}]}
{"op":"mcm","clk":"11952459007","pt":1724512887179,"mc":[{"id":"1.232215600","rc":[{"trd":[[2.1,59.91]],"batb":[[0,2.1,6.88]],"ltp":2.1,"tv":127.56,"id":67083366}],"tv":419.15}]}
{"op":"mcm","clk":"11952459086","pt":1724512887432,"mc":[{"id":"1.232215600","rc":[{"batb":[[0,1.86,5],[1,1.85,80],[2,1.84,364.26]],"ltp":1.85,"tv":291.58,"id":72857114}]}]}
{"op":"mcm","clk":"11952460071","pt":1724512890709,"mc":[{"id":"1.232215600","rc":[{"batb":[[0,1.85,80],[1,1.84,364.26],[2,1.81,323.47]],"ltp":1.85,"tv":291.58,"id":72857114}]}]}
{"op":"mcm","clk":"11952461271","pt":1724512894226,"mc":[{"id":"1.232215600","rc":[{"batb":[[0,1.86,5],[1,1.85,81],[2,1.84,364.26]],"ltp":1.85,"tv":291.58,"id":72857114},{"trd":[[2.1,60.11]],"batb":[[0,2.1,6.78]],"ltp":2.1,"tv":127.76,"id":67083366}],"tv":419.34}]}
{"op":"mcm","clk":"11952461452","pt":1724512894708,"mc":[{"id":"1.232215600","rc":[{"batb":[[1,1.74,1.06],[2,1.51,20]],"ltp":2.1,"tv":127.76,"id":67083366}]}]}
{"op":"mcm","clk":"11952462052","pt":1724512896613,"mc":[{"id":"1.232215600","rc":[{"trd":[[1.86,0.2]],"batb":[[0,1.86,4.9]],"ltp":1.86,"tv":291.78,"id":72857114}],"tv":419.54}]}
{"op":"mcm","clk":"11952462422","pt":1724512897752,"mc":[{"id":"1.232215600","rc":[{"batb":[[0,1.85,81],[1,1.84,364.26],[2,1.81,323.47]],"ltp":1.86,"tv":291.78,"id":72857114}]}]}
{"op":"mcm","clk":"11952462780","pt":1724512898904,"mc":[{"id":"1.232215600","rc":[{"batb":[[0,1.86,126.68],[1,1.85,81],[2,1.84,364.26]],"ltp":1.86,"tv":291.78,"id":72857114}]}]}
{"op":"mcm","clk":"11952463171","pt":1724512900206,"mc":[{"id":"1.232215600","rc":[{"batb":[[0,1.87,5],[1,1.86,126.68],[2,1.85,81]],"ltp":1.86,"tv":291.78,"id":72857114}]}]}
{"op":"mcm","clk":"11952464249","pt":1724512903575,"mc":[{"id":"1.232215600","rc":[{"batb":[[0,1.86,126.68],[1,1.85,81],[2,1.84,364.26]],"ltp":1.86,"tv":291.78,"id":72857114}]}]}
{"op":"mcm","clk":"11952465113","pt":1724512906469,"mc":[{"id":"1.232215600","rc":[{"batb":[[0,1.87,5],[1,1.86,126.68],[2,1.85,81]],"ltp":1.86,"tv":291.78,"id":72857114}]}]}
{"op":"mcm","clk":"11952466198","pt":1724512910299,"mc":[{"id":"1.232215600","rc":[{"batb":[[0,1.86,126.68],[1,1.85,81],[2,1.84,364.26]],"ltp":1.86,"tv":291.78,"id":72857114}]}]}
{"op":"mcm","clk":"11952467159","pt":1724512913186,"mc":[{"id":"1.232215600","rc":[{"batb":[[0,1.85,81],[1,1.84,364.26],[2,1.81,323.47]],"ltp":1.86,"tv":291.78,"id":72857114}]}]}
{"op":"mcm","clk":"11952467307","pt":1724512913523,"mc":[{"id":"1.232215600","rc":[{"batb":[[0,1.86,5],[1,1.85,81],[2,1.84,364.26]],"ltp":1.86,"tv":291.78,"id":72857114}]}]}
{"op":"mcm","clk":"11952468214","pt":1724512915869,"mc":[{"id":"1.232215600","rc":[{"trd":[[1.86,0.34]],"batb":[[0,1.86,4.86]],"ltp":1.86,"tv":291.92,"id":72857114},{"trd":[[2.18,0.12]],"ltp":2.18,"tv":127.87,"id":67083366}],"tv":419.79}]}
{"op":"mcm","clk":"11952468539","pt":1724512916833,"mc":[{"id":"1.232215600","rc":[{"batb":[[0,1.85,81],[1,1.84,364.26],[2,1.81,323.47]],"ltp":1.86,"tv":291.92,"id":72857114}]}]}
{"op":"mcm","clk":"11952470478","pt":1724512923154,"mc":[{"id":"1.232215600","rc":[{"batb":[[0,1.86,5],[1,1.85,81],[2,1.84,364.26]],"ltp":1.86,"tv":291.92,"id":72857114},{"trd":[[2.1,60.3]],"batb":[[0,2.1,6.68]],"ltp":2.1,"tv":128.07,"id":67083366}],"tv":419.99}]}
{"op":"mcm","clk":"11952471610","pt":1724512926968,"mc":[{"id":"1.232215600","rc":[{"batb":[[0,1.85,81],[1,1.84,364.26],[2,1.81,323.47]],"ltp":1.86,"tv":291.92,"id":72857114},{"trd":[[2.1,60.5]],"batb":[[0,2.1,6.59]],"ltp":2.1,"tv":128.26,"id":67083366}],"tv":420.18}]}
{"op":"mcm","clk":"11952472915","pt":1724512931284,"mc":[{"id":"1.232215600","rc":[{"batb":[[0,1.86,5],[1,1.85,81],[2,1.84,364.26]],"ltp":1.86,"tv":291.92,"id":72857114}]}]}
{"op":"mcm","clk":"11952474054","pt":1724512934889,"mc":[{"id":"1.232215600","rc":[{"batb":[[0,1.85,81],[1,1.84,364.26],[2,1.81,323.47]],"ltp":1.86,"tv":291.92,"id":72857114}]}]}
{"op":"mcm","clk":"11952476676","pt":1724512944706,"mc":[{"id":"1.232215600","rc":[{"batb":[[0,1.86,5],[1,1.85,81],[2,1.84,364.26]],"ltp":1.86,"tv":291.92,"id":72857114},{"batb":[[0,2.12,5],[1,2.1,6.59],[2,1.74,1.06]],"batl":[[0,2.2,0.1]],"ltp":2.1,"tv":128.26,"id":67083366}]}]}
{"op":"mcm","clk":"11952477557","pt":1724512948189,"mc":[{"id":"1.232215600","rc":[{"batb":[[0,1.85,81],[1,1.84,364.26],[2,1.81,323.47]],"ltp":1.86,"tv":291.92,"id":72857114},{"batb":[[0,2.1,6.59],[1,1.74,1.06],[2,1.51,20]],"ltp":2.1,"tv":128.26,"id":67083366}]}]}
{"op":"mcm","clk":"11952485408","pt":1724512977706,"mc":[{"id":"1.232215600","rc":[{"batb":[[0,1.86,5],[1,1.85,81]],"ltp":1.86,"tv":291.92,"id":72857114},{"batb":[[0,2.12,5],[1,2.1,6.59],[2,1.74,1.06]],"ltp":2.1,"tv":128.26,"id":67083366}]}]}
{"op":"mcm","clk":"11952486195","pt":1724512980878,"mc":[{"id":"1.232215600","rc":[{"batb":[[0,1.85,81],[1,1.81,323.47],[2,1.66,66.16]],"ltp":1.86,"tv":291.92,"id":72857114},{"batb":[[0,2.1,6.59],[1,1.74,1.06],[2,1.51,20]],"ltp":2.1,"tv":128.26,"id":67083366}]}]}
{"op":"mcm","clk":"11952492052","pt":1724513004373,"mc":[{"id":"1.232215600","rc":[{"batb":[[0,1.89,5],[1,1.88,24.62],[2,1.85,81]],"ltp":1.86,"tv":291.92,"id":72857114},{"batb":[[0,2.12,5],[1,2.1,6.59],[2,1.74,1.06]],"ltp":2.1,"tv":128.26,"id":67083366}]}]}
{"op":"mcm","clk":"11952492919","pt":1724513007758,"mc":[{"id":"1.232215600","rc":[{"batb":[[0,1.88,24.62],[1,1.87,24.62]],"ltp":1.86,"tv":291.92,"id":72857114},{"batb":[[0,2.1,6.59],[1,1.74,1.06],[2,1.51,20]],"ltp":2.1,"tv":128.26,"id":67083366}]}]}
{"op":"mcm","clk":"11952493987","pt":1724513011350,"mc":[{"id":"1.232215600","rc":[{"batb":[[0,1.89,5],[1,1.88,24.62],[2,1.87,24.62]],"ltp":1.86,"tv":291.92,"id":72857114},{"batb":[[0,2.12,5],[1,2.1,6.59],[2,1.74,1.06]],"ltp":2.1,"tv":128.26,"id":67083366}]}]}
{"op":"mcm","clk":"11952495050","pt":1724513014634,"mc":[{"id":"1.232215600","rc":[{"batb":[[0,1.88,24.62],[1,1.87,24.62],[2,1.86,24.62]],"ltp":1.86,"tv":291.92,"id":72857114},{"batb":[[0,2.1,6.59],[1,1.74,1.06],[2,1.51,20]],"batl":[[0,2.2,0.19]],"ltp":2.1,"tv":128.26,"id":67083366}]}]}
{"op":"mcm","clk":"11952495391","pt":1724513015624,"mc":[{"id":"1.232215600","rc":[{"batb":[[0,1.9,80],[1,1.88,24.62],[2,1.87,24.62]],"ltp":1.86,"tv":291.92,"id":72857114}]}]}
{"op":"mcm","clk":"11952497574","pt":1724513022987,"mc":[{"id":"1.232215600","rc":[{"trd":[[1.9,2.56],[1.91,76.68]],"batb":[[0,1.9,79.56]],"ltp":1.9,"tv":304.56,"id":72857114},{"trd":[[2.1,71.59],[2.12,0.59]],"batb":[[0,1.74,1.06],[1,1.51,20],[2,1.21,24.75]],"batl":[[0,2.2,0.1]],"ltp":2.12,"tv":139.94,"id":67083366}],"tv":444.51}]}
{"op":"mcm","clk":"11952498435","pt":1724513025975,"mc":[{"id":"1.232215600","rc":[{"batb":[[0,1.91,5],[1,1.9,79.56],[2,1.88,24.62]],"ltp":1.9,"tv":304.56,"id":72857114},{"batb":[[0,1.75,1.37],[1,1.74,1.06],[2,1.51,20]],"ltp":2.12,"tv":139.94,"id":67083366}]}]}
{"op":"mcm","clk":"11952498784","pt":1724513027099,"mc":[{"id":"1.232215600","rc":[{"batl":[[0,2.34,4.63],[1,2.36,2.06],[2,2.5,1]],"ltp":1.9,"tv":304.56,"id":72857114}]}]}
{"op":"mcm","clk":"11952499295","pt":1724513028996,"mc":[{"id":"1.232215600","rc":[{"batb":[[1,1.88,24.62],[2,1.87,24.62]],"ltp":1.9,"tv":304.56,"id":72857114}]}]}
{"op":"mcm","clk":"11952499878","pt":1724513031096,"mc":[{"id":"1.232215600","rc":[{"trd":[[1.81,756.95],[1.83,0.12],[1.85,170],[1.86,49.58],[1.87,49.24],[1.88,52.32]],"batb":[[0,1.66,66.16],[1,1.48,7.72],[2,1.21,24.75]],"batl":[[0,1.71,2449.88],[1,2.34,4.63],[2,2.36,2.06]],"ltp":1.81,"tv":1261.33,"id":72857114},{"trd":[[2.2,0.1]],"batb":[[0,1.76,2.71],[1,1.75,1.37],[2,1.74,1.06]],"ltp":2.2,"tv":140.04,"id":67083366}],"tv":1401.38}]}
{"op":"mcm","clk":"11952500196","pt":1724513032193,"mc":[{"id":"1.232215600","rc":[{"batl":[[1,2.32,4.63]],"ltp":1.81,"tv":1261.33,"id":72857114}]}]}
{"op":"mcm","clk":"11952501510","pt":1724513037103,"mc":[{"id":"1.232215600","rc":[{"batb":[[0,1.67,5],[1,1.66,66.16],[2,1.48,7.72]],"batl":[[0,2.32,4.63],[1,2.36,2.06],[2,2.5,1]],"ltp":1.81,"tv":1261.33,"id":72857114}]}]}
{"op":"mcm","clk":"11952501773","pt":1724513038096,"mc":[{"id":"1.232215600","rc":[{"batb":[[0,1.71,101.35],[1,1.67,5],[2,1.66,66.16]],"ltp":1.81,"tv":1261.33,"id":72857114}]}]}
{"op":"mcm","clk":"11952502033","pt":1724513039134,"mc":[{"id":"1.232215600","rc":[{"batb":[[0,1.72,5],[1,1.71,101.35],[2,1.67,5]],"ltp":1.81,"tv":1261.33,"id":72857114}]}]}
{"op":"mcm","clk":"11952502352","pt":1724513040321,"mc":[{"id":"1.232215600","rc":[{"batb":[[2,1.66,66.16]],"ltp":1.81,"tv":1261.33,"id":72857114}]}]}
{"op":"mcm","clk":"11952503484","pt":1724513044411,"mc":[{"id":"1.232215600","rc":[{"batb":[[0,1.73,6.54],[1,1.72,5],[2,1.71,101.35]],"ltp":1.81,"tv":1261.33,"id":72857114},{"batl":[[0,2.4,0.11]],"ltp":2.2,"tv":140.04,"id":67083366}]}]}
{"op":"mcm","clk":"11952504235","pt":1724513047031,"mc":[{"id":"1.232215600","rc":[{"batb":[[0,1.73,1.54]],"ltp":1.81,"tv":1261.33,"id":72857114}]}]}
{"op":"mcm","clk":"11952505411","pt":1724513051224,"mc":[{"id":"1.232215600","rc":[{"batb":[[2,1.66,66.16]],"ltp":1.81,"tv":1261.33,"id":72857114},{"batl":[[0,2.3,41.89],[1,2.4,0.11]],"ltp":2.2,"tv":140.04,"id":67083366}]}]}
{"op":"mcm","clk":"11952505730","pt":1724513052044,"mc":[{"id":"1.232215600","rc":[{"trd":[[1.76,4]],"ltp":1.76,"tv":1265.33,"id":72857114},{"trd":[[2.3,3.06]],"batl":[[0,2.3,38.83]],"ltp":2.3,"tv":143.1,"id":67083366}],"tv":1408.44}]}
{"op":"mcm","clk":"11952506708","pt":1724513055137,"mc":[{"id":"1.232215600","rc":[{"batl":[[0,2.4,0.11],[1,2.4,0]],"ltp":2.3,"tv":143.1,"id":67083366}]}]}
{"op":"mcm","clk":"11952509579","pt":1724513064346,"mc":[{"id":"1.232215600","rc":[{"trd":[[1.71,0.15],[1.72,17.04],[1.73,3.08]],"batb":[[0,1.68,5],[1,1.66,66.16],[2,1.48,7.72]],"batl":[[0,1.7,576.64],[1,2.32,4.63],[2,2.36,2.06]],"ltp":1.71,"tv":1278.57,"id":72857114},{"trd":[[2.4,0.11]],"ltp":2.4,"tv":143.21,"id":67083366}],"tv":1421.78}]}
{"op":"mcm","clk":"11952510142","pt":1724513066349,"mc":[{"id":"1.232215600","rc":[{"batl":[[1,2.3,49.42],[2,2.32,4.63]],"ltp":1.71,"tv":1278.57,"id":72857114}]}]}
{"op":"mcm","clk":"11952510414","pt":1724513067349,"mc":[{"id":"1.232215600","rc":[{"trd":[[1.7,0.28]],"batb":[[1,1.66,93.14]],"batl":[[0,1.7,576.36],[1,2.3,54.05],[2,2.36,2.06]],"ltp":1.7,"tv":1278.85,"id":72857114},{"trd":[[2.42,0.2]],"batb":[[0,2.4,12.72],[1,1.76,2.71],[2,1.75,1.37]],"ltp":2.42,"tv":143.41,"id":67083366}],"tv":1422.26}]}
{"op":"mcm","clk":"11952510949","pt":1724513069282,"mc":[{"id":"1.232215600","rc":[{"trd":[[1.7,855.66]],"batl":[[0,2.3,54.05],[1,2.36,2.06],[2,2.5,1]],"ltp":1.7,"tv":2134.23,"id":72857114}],"tv":2277.64}]}
{"op":"mcm","clk":"11952511179","pt":1724513070103,"mc":[{"id":"1.232215600","rc":[{"batb":[[0,1.69,5],[1,1.68,5],[2,1.66,93.14]],"ltp":1.7,"tv":2134.23,"id":72857114},{"batb":[[0,1.76,2.71],[1,1.75,1.37],[2,1.74,1.06]],"batl":[[0,2.42,41.89]],"ltp":2.42,"tv":143.41,"id":67083366}]}]}
{"op":"mcm","clk":"11952511508","pt":1724513071284,"mc":[{"id":"1.232215600","rc":[{"batl":[[0,2.3,4.63]],"ltp":1.7,"tv":2134.23,"id":72857114},{"batb":[[1,1.75,25.12]],"ltp":2.42,"tv":143.41,"id":67083366}]}]}
{"op":"mcm","clk":"11952511616","pt":1724513071711,"mc":[{"id":"1.232215600","rc":[{"batb":[[2,1.66,66.16]],"ltp":1.7,"tv":2134.23,"id":72857114},{"batb":[[1,1.75,1.37]],"ltp":2.42,"tv":143.41,"id":67083366}]}]}
{"op":"mcm","clk":"11952512250","pt":1724513074072,"mc":[{"id":"1.232215600","rc":[{"batb":[[0,1.68,5],[1,1.66,66.16],[2,1.48,7.72]],"ltp":1.7,"tv":2134.23,"id":72857114}]}]}
{"op":"mcm","clk":"11952512843","pt":1724513076362,"mc":[{"id":"1.232215600","rc":[{"batl":[[0,1.88,24.92],[1,2.3,4.63],[2,2.36,2.06]],"ltp":1.7,"tv":2134.23,"id":72857114}]}]}
{"op":"mcm","clk":"11952513551","pt":1724513079059,"mc":[{"id":"1.232215600","rc":[{"trd":[[1.7,855.67]],"batb":[[0,1.69,25.81],[1,1.68,5],[2,1.66,66.16]],"ltp":1.7,"tv":2134.24,"id":72857114},{"trd":[[2.42,0.21]],"batb":[[0,2.12,5],[1,2.1,16.19],[2,1.76,2.71]],"batl":[[0,2.42,41.88]],"ltp":2.42,"tv":143.42,"id":67083366}],"tv":2277.66}]}
{"op":"mcm","clk":"11952514316","pt":1724513082048,"mc":[{"id":"1.232215600","rc":[{"batb":[[0,2.1,16.19],[1,1.76,2.71],[2,1.75,1.37]],"ltp":2.42,"tv":143.42,"id":67083366}]}]}
{"op":"mcm","clk":"11952515268","pt":1724513085829,"mc":[{"id":"1.232215600","rc":[{"trd":[[1.88,52.52]],"batl":[[0,1.88,24.72]],"ltp":1.88,"tv":2134.44,"id":72857114},{"trd":[[2.12,0.77]],"batb":[[0,2.12,5],[1,2.1,16.19],[2,1.76,2.71]],"ltp":2.12,"tv":143.6,"id":67083366}],"tv":2278.04}]}
{"op":"mcm","clk":"11952515518","pt":1724513086762,"mc":[{"id":"1.232215600","rc":[{"batb":[[0,1.69,26.54]],"batl":[[0,1.87,1.54],[1,1.88,24.72],[2,2.3,4.63]],"ltp":1.88,"tv":2134.44,"id":72857114}]}]}
{"op":"mcm","clk":"11952515901","pt":1724513088132,"mc":[{"id":"1.232215600","rc":[{"trd":[[1.87,52.32]],"batb":[[0,1.89,5],[1,1.88,26.54],[2,1.68,5.74]],"batl":[[0,2.3,4.63],[1,2.36,2.06],[2,2.5,1]],"ltp":1.87,"tv":2137.52,"id":72857114},{"batb":[[1,1.76,2.71],[2,1.75,1.37]],"ltp":2.12,"tv":143.6,"id":67083366}],"tv":2281.13}]}
{"op":"mcm","clk":"11952516256","pt":1724513089350,"mc":[{"id":"1.232215600","rc":[{"batb":[[2,1.66,66.89]],"ltp":1.87,"tv":2137.52,"id":72857114},{"batb":[[0,1.76,2.71],[1,1.75,1.37],[2,1.74,1.06]],"ltp":2.12,"tv":143.6,"id":67083366}]}]}
{"op":"mcm","clk":"11952516311","pt":1724513089538,"mc":[{"id":"1.232215600","rc":[{"batb":[[1,1.88,46.78]],"ltp":1.87,"tv":2137.52,"id":72857114}]}]}
{"op":"mcm","clk":"11952516804","pt":1724513091246,"mc":[{"id":"1.232215600","rc":[{"batb":[[0,1.88,46.78],[1,1.66,66.89],[2,1.48,7.72]],"ltp":1.87,"tv":2137.52,"id":72857114}]}]}
{"op":"mcm","clk":"11952517071","pt":1724513092243,"mc":[{"id":"1.232215600","rc":[{"batb":[[1,1.8,24.62],[2,1.66,66.89]],"ltp":1.87,"tv":2137.52,"id":72857114}]}]}
{"op":"mcm","clk":"11952518055","pt":1724513096144,"mc":[{"id":"1.232215600","rc":[{"trd":[[1.88,52.72]],"batb":[[0,1.89,5],[1,1.88,46.68],[2,1.8,24.62]],"ltp":1.88,"tv":2137.72,"id":72857114}],"tv":2281.32}]}
{"op":"mcm","clk":"11952518736","pt":1724513098942,"mc":[{"id":"1.232215600","rc":[{"batb":[[2,1.82,24.62]],"ltp":1.88,"tv":2137.72,"id":72857114}]}]}
{"op":"mcm","clk":"11952518881","pt":1724513099462,"mc":[{"id":"1.232215600","rc":[{"batb":[[0,1.88,46.68],[1,1.82,24.62],[2,1.8,24.62]],"ltp":1.88,"tv":2137.72,"id":72857114}]}]}
{"op":"mcm","clk":"11952520220","pt":1724513104142,"mc":[{"id":"1.232215600","rc":[{"batb":[[0,1.89,5],[1,1.88,46.68],[2,1.82,24.62]],"batl":[[0,2.3,4.73]],"ltp":1.88,"tv":2137.72,"id":72857114}]}]}
{"op":"mcm","clk":"11952521350","pt":1724513107725,"mc":[{"id":"1.232215600","rc":[{"batb":[[0,1.88,46.68],[1,1.82,24.62],[2,1.8,24.62]],"ltp":1.88,"tv":2137.72,"id":72857114}]}]}
{"op":"mcm","clk":"11952522592","pt":1724513112155,"mc":[{"id":"1.232215600","rc":[{"batb":[[0,1.89,5],[1,1.88,46.68],[2,1.82,24.62]],"ltp":1.88,"tv":2137.72,"id":72857114}]}]}
{"op":"mcm","clk":"11952523303","pt":1724513114493,"mc":[{"id":"1.232215600","rc":[{"trd":[[1.82,20.52],[1.88,99.4],[1.89,9]],"batb":[[0,1.82,4.1],[1,1.8,24.62],[2,1.78,24.62]],"ltp":1.82,"tv":2209.91,"id":72857114},{"trd":[[2.14,45.42],[2.22,16.82]],"ltp":2.22,"tv":205.84,"id":67083366}],"tv":2415.76}]}
{"op":"mcm","clk":"11952524071","pt":1724513117100,"mc":[{"id":"1.232215600","rc":[{"batb":[[0,1.83,5],[1,1.82,4.1],[2,1.8,24.62]],"batl":[[1,2.5,1],[2,2.5,0]],"ltp":1.82,"tv":2209.91,"id":72857114}]}]}
{"op":"mcm","clk":"11952525033","pt":1724513120347,"mc":[{"id":"1.232215600","rc":[{"trd":[[1.76,25.22],[1.78,24.62],[1.8,89.62],[1.82,24.62],[1.83,5.12]],"batb":[[0,1.76,40.32],[1,1.7,28.43],[2,1.66,196.31]],"ltp":1.76,"tv":2289.47,"id":72857114},{"trd":[[2.22,24.3],[2.26,82.19],[2.3,22.11],[2.32,16.1]],"batb":[[0,1.91,5],[1,1.9,49.23],[2,1.76,2.71]],"ltp":2.32,"tv":268.08,"id":67083366}],"tv":2557.56}]}
{"op":"mcm","clk":"11952525488","pt":1724513121840,"mc":[{"id":"1.232215600","rc":[{"batb":[[0,1.77,5],[1,1.76,40.32],[2,1.75,23.75]],"ltp":1.76,"tv":2289.47,"id":72857114},{"batb":[[1,1.9,69.02]],"ltp":2.32,"tv":268.08,"id":67083366}]}]}
{"op":"mcm","clk":"11952525828","pt":1724513122706,"mc":[{"id":"1.232215600","rc":[{"batb":[[1,1.76,63.75]],"batl":[[0,2.28,2.15],[1,2.3,4.63],[2,2.5,1]],"ltp":1.76,"tv":2289.47,"id":72857114}]}]}
{"op":"mcm","clk":"11952526304","pt":1724513124198,"mc":[{"id":"1.232215600","rc":[{"trd":[[2.12,0.12]],"batb":[[1,1.76,40.32],[2,1.7,28.43]],"batl":[[0,2.28,6.78],[1,2.5,1],[2,2.5,0]],"ltp":2.12,"tv":2289.59,"id":72857114},{"trd":[[1.9,0.13]],"batb":[[0,1.9,49.1],[1,1.76,2.71],[2,1.75,1.37]],"ltp":1.9,"tv":268.21,"id":67083366}],"tv":2557.81}]}
{"op":"mcm","clk":"11952526575","pt":1724513125146,"mc":[{"id":"1.232215600","rc":[{"batb":[[0,1.76,63.75],[1,1.7,28.43],[2,1.66,196.31]],"ltp":2.12,"tv":2289.59,"id":72857114},{"batb":[[1,1.89,20.02],[2,1.76,2.71]],"ltp":1.9,"tv":268.21,"id":67083366}]}]}
{"op":"mcm","clk":"11952526855","pt":1724513126119,"mc":[{"id":"1.232215600","rc":[{"batb":[[0,1.76,40.32]],"ltp":2.12,"tv":2289.59,"id":72857114},{"batb":[[1,1.76,2.71],[2,1.75,1.37]],"ltp":1.9,"tv":268.21,"id":67083366}]}]}
{"op":"mcm","clk":"11952527012","pt":1724513126615,"mc":[{"id":"1.232215600","rc":[{"batb":[[0,1.91,5],[1,1.9,49.1],[2,1.76,2.71]],"ltp":1.9,"tv":268.21,"id":67083366}]}]}
{"op":"mcm","clk":"11952528048","pt":1724513130203,"mc":[{"id":"1.232215600","rc":[{"trd":[[2.12,0.24]],"batb":[[0,1.77,5],[1,1.76,40.32],[2,1.7,28.43]],"ltp":2.12,"tv":2289.71,"id":72857114},{"trd":[[1.9,0.26]],"batb":[[0,1.9,48.97],[1,1.76,2.71],[2,1.75,1.37]],"ltp":1.9,"tv":268.34,"id":67083366}],"tv":2558.06}]}
{"op":"mcm","clk":"11952528654","pt":1724513132417,"mc":[{"id":"1.232215600","rc":[{"batb":[[0,1.8,10],[1,1.77,5],[2,1.76,40.32]],"ltp":2.12,"tv":2289.71,"id":72857114},{"batb":[[0,1.91,5],[1,1.9,48.97],[2,1.76,2.71]],"ltp":1.9,"tv":268.34,"id":67083366}]}]}
{"op":"mcm","clk":"11952528907","pt":1724513133414,"mc":[{"id":"1.232215600","rc":[{"batb":[[1,1.76,40.32],[2,1.7,28.43]],"ltp":2.12,"tv":2289.71,"id":72857114}]}]}
{"op":"mcm","clk":"11952529299","pt":1724513135030,"mc":[{"id":"1.232215600","rc":[{"trd":[[2.1,0.12]],"ltp":2.1,"tv":2289.83,"id":72857114},{"trd":[[1.91,0.13]],"batb":[[0,1.91,4.87]],"ltp":1.91,"tv":268.47,"id":67083366}],"tv":2558.31}]}
{"op":"mcm","clk":"11952529583","pt":1724513136046,"mc":[{"id":"1.232215600","rc":[{"batb":[[0,1.81,5],[1,1.8,10],[2,1.76,40.32]],"ltp":2.1,"tv":2289.83,"id":72857114},{"batb":[[0,1.9,48.97],[1,1.76,2.71],[2,1.75,1.37]],"ltp":1.91,"tv":268.47,"id":67083366}]}]}
{"op":"mcm","clk":"11952530569","pt":1724513139862,"mc":[{"id":"1.232215600","rc":[{"batb":[[0,1.8,10.12],[1,1.76,40.32],[2,1.7,28.43]],"ltp":2.1,"tv":2289.83,"id":72857114}]}]}
{"op":"mcm","clk":"11952530993","pt":1724513141413,"mc":[{"id":"1.232215600","rc":[{"trd":[[2.1,0.24]],"batb":[[0,1.8,10]],"ltp":2.1,"tv":2289.95,"id":72857114},{"trd":[[1.91,0.26]],"batb":[[0,1.95,61.41],[1,1.9,48.97],[2,1.76,2.71]],"ltp":1.91,"tv":268.6,"id":67083366}],"tv":2558.56}]}
{"op":"mcm","clk":"11952532803","pt":1724513148492,"mc":[{"id":"1.232215600","rc":[{"batb":[[0,1.85,3],[1,1.8,10],[2,1.76,40.32]],"ltp":2.1,"tv":2289.95,"id":72857114}]}]}
{"op":"mcm","clk":"11952535338","pt":1724513158791,"mc":[{"id":"1.232215600","rc":[{"trd":[[1.85,170.2]],"batb":[[0,1.85,2.9]],"ltp":1.85,"tv":2290.15,"id":72857114}],"tv":2558.76}]}
{"op":"mcm","clk":"11952537038","pt":1724513166108,"mc":[{"id":"1.232215600","rc":[{"batb":[[0,1.86,5],[1,1.85,86.57],[2,1.8,10]],"ltp":1.85,"tv":2290.15,"id":72857114}]}]}
{"op":"mcm","clk":"11952537398","pt":1724513167856,"mc":[{"id":"1.232215600","rc":[{"trd":[[1.86,49.77]],"batb":[[0,1.86,4.9]],"ltp":1.86,"tv":2290.35,"id":72857114}],"tv":2558.95}]}
{"op":"mcm","clk":"11952537820","pt":1724513169537,"mc":[{"id":"1.232215600","rc":[{"batb":[[0,1.85,86.57],[1,1.8,10],[2,1.76,40.32]],"ltp":1.86,"tv":2290.35,"id":72857114}]}]}
{"op":"mcm","clk":"11952538569","pt":1724513172409,"mc":[{"id":"1.232215600","rc":[{"trd":[[1.86,49.97]],"batb":[[0,1.86,4.9],[1,1.85,86.57],[2,1.8,10]],"ltp":1.86,"tv":2290.54,"id":72857114}],"tv":2559.15}]}
{"op":"mcm","clk":"11952539176","pt":1724513174875,"mc":[{"id":"1.232215600","rc":[{"batl":[[0,1.96,0.1]],"ltp":1.91,"tv":268.6,"id":67083366}]}]}
{"op":"mcm","clk":"11952539393","pt":1724513175682,"mc":[{"id":"1.232215600","rc":[{"batb":[[0,1.85,86.57],[1,1.8,10],[2,1.76,40.32]],"ltp":1.86,"tv":2290.54,"id":72857114}]}]}
{"op":"mcm","clk":"11952540009","pt":1724513177946,"mc":[{"id":"1.232215600","rc":[{"batb":[[0,1.86,5],[1,1.85,86.57],[2,1.8,10]],"ltp":1.86,"tv":2290.54,"id":72857114},{"trd":[[1.96,0.71]],"batb":[[0,1.96,4.9],[1,1.95,61.41],[2,1.9,48.97]],"batl":[[0,2,0.49]],"ltp":1.96,"tv":268.8,"id":67083366}],"tv":2559.35}]}
{"op":"mcm","clk":"11952540863","pt":1724513181264,"mc":[{"id":"1.232215600","rc":[{"batb":[[0,1.85,86.57],[1,1.8,10],[2,1.76,40.32]],"ltp":1.86,"tv":2290.54,"id":72857114},{"batb":[[0,1.95,61.41],[1,1.9,48.97],[2,1.76,2.71]],"ltp":1.96,"tv":268.8,"id":67083366}]}]}
{"op":"mcm","clk":"11952541745","pt":1724513185295,"mc":[{"id":"1.232215600","rc":[{"batb":[[0,1.86,5],[1,1.85,86.57],[2,1.8,10]],"ltp":1.86,"tv":2290.54,"id":72857114},{"batb":[[0,1.96,5],[1,1.95,61.41],[2,1.9,48.97]],"ltp":1.96,"tv":268.8,"id":67083366}]}]}
{"op":"mcm","clk":"11952541861","pt":1724513185520,"mc":[{"id":"1.232215600","rc":[{"batb":[[2,1.76,2.71]],"ltp":1.96,"tv":268.8,"id":67083366}]}]}
{"op":"mcm","clk":"11952542207","pt":1724513186446,"mc":[{"id":"1.232215600","rc":[{"batl":[[0,2.06,2.57],[1,2.28,6.78],[2,2.5,1]],"ltp":1.86,"tv":2290.54,"id":72857114}]}]}
{"op":"mcm","clk":"11952542675","pt":1724513188382,"mc":[{"id":"1.232215600","rc":[{"batb":[[0,1.85,86.57],[1,1.8,10],[2,1.76,40.32]],"ltp":1.86,"tv":2290.54,"id":72857114},{"batb":[[0,1.95,61.41],[1,1.76,2.71],[2,1.75,1.37]],"ltp":1.96,"tv":268.8,"id":67083366}]}]}
{"op":"mcm","clk":"11952543693","pt":1724513192385,"mc":[{"id":"1.232215600","rc":[{"trd":[[2,0.98]],"batb":[[0,2,48.74],[1,1.95,61.41],[2,1.76,2.71]],"ltp":2.0,"tv":269.78,"id":67083366}],"tv":2560.33}]}
{"op":"mcm","clk":"11952543743","pt":1724513192543,"mc":[{"id":"1.232215600","rc":[{"batb":[[0,1.86,5],[1,1.85,86.57],[2,1.8,10]],"ltp":1.86,"tv":2290.54,"id":72857114}]}]}
{"op":"mcm","clk":"11952544436","pt":1724513194813,"mc":[{"id":"1.232215600","rc":[{"batb":[[0,2.16,74.05],[1,2,48.74],[2,1.95,61.41]],"ltp":2.0,"tv":269.78,"id":67083366}]}]}
{"op":"mcm","clk":"11952544757","pt":1724513195886,"mc":[{"id":"1.232215600","rc":[{"batb":[[0,1.85,86.57],[1,1.8,10],[2,1.79,108.73]],"ltp":1.86,"tv":2290.54,"id":72857114}]}]}
{"op":"mcm","clk":"11952545304","pt":1724513198106,"mc":[{"id":"1.232215600","rc":[{"trd":[[1.85,171.06],[1.86,54.97]],"batb":[[0,1.85,85.71]],"ltp":1.85,"tv":2296.4,"id":72857114},{"trd":[[2.18,5.12]],"batl":[[0,2.44,0.1]],"ltp":2.18,"tv":274.78,"id":67083366}],"tv":2571.19}]}
{"op":"mcm","clk":"11952546579","pt":1724513203229,"mc":[{"id":"1.232215600","rc":[{"trd":[[2.16,0.2]],"batb":[[0,2.16,73.95]],"ltp":2.16,"tv":274.98,"id":67083366}],"tv":2571.39}]}
{"op":"mcm","clk":"11952546629","pt":1724513203446,"mc":[{"id":"1.232215600","rc":[{"trd":[[1.85,171.92],[1.86,59.97]],"batb":[[0,1.85,84.85]],"ltp":1.85,"tv":2302.26,"id":72857114},{"trd":[[2.18,10.12]],"ltp":2.18,"tv":279.98,"id":67083366}],"tv":2582.25}]}
{"op":"mcm","clk":"11952546977","pt":1724513204824,"mc":[{"id":"1.232215600","rc":[{"batb":[[0,2.16,74.05]],"ltp":2.18,"tv":279.98,"id":67083366}]}]}
{"op":"mcm","clk":"11952547527","pt":1724513207139,"mc":[{"id":"1.232215600","rc":[{"trd":[[1.85,172.78],[1.86,64.97]],"batb":[[0,1.85,83.99]],"ltp":1.85,"tv":2308.12,"id":72857114},{"trd":[[2.16,0.39],[2.18,15.12]],"batb":[[0,2.16,73.95],[2,1.76,2.71]],"ltp":2.18,"tv":285.18,"id":67083366}],"tv":2593.3}]}
{"op":"mcm","clk":"11952547768","pt":1724513208131,"mc":[{"id":"1.232215600","rc":[{"trd":[[1.85,173.1]],"batb":[[0,1.8,10],[1,1.79,108.73],[2,1.76,40.32]],"ltp":1.85,"tv":2308.44,"id":72857114},{"trd":[[2.18,15.39]],"batb":[[0,2.18,41.99],[1,2.16,73.95],[2,2,48.74]],"ltp":2.18,"tv":285.45,"id":67083366}],"tv":2593.89}]}
{"op":"mcm","clk":"11952547894","pt":1724513208629,"mc":[{"id":"1.232215600","rc":[{"trd":[[2.18,15.58]],"batb":[[0,2.18,41.89]],"ltp":2.18,"tv":285.64,"id":67083366}],"tv":2594.09}]}
{"op":"mcm","clk":"11952548295","pt":1724513210259,"mc":[{"id":"1.232215600","rc":[{"batb":[[0,1.81,5],[1,1.8,10],[2,1.79,108.73]],"ltp":1.85,"tv":2308.44,"id":72857114},{"trd":[[2.2,0.29]],"batb":[[0,2.2,4.9],[1,2.18,41.89],[2,2.16,74.05]],"ltp":2.2,"tv":285.84,"id":67083366}],"tv":2594.29}]}
{"op":"mcm","clk":"11952548579","pt":1724513211453,"mc":[{"id":"1.232215600","rc":[{"trd":[[1.84,5.86],[1.85,187.24]],"ltp":1.85,"tv":2328.44,"id":72857114},{"trd":[[2.18,27.58],[2.2,5.19]],"batb":[[0,2.18,29.89],[1,2.16,74.05],[2,2,48.74]],"ltp":2.18,"tv":302.74,"id":67083366}],"tv":2631.19}]}
{"op":"mcm","clk":"11952549154","pt":1724513213761,"mc":[{"id":"1.232215600","rc":[{"batb":[[0,1.8,10],[1,1.79,108.73],[2,1.75,61.54]],"ltp":1.85,"tv":2328.44,"id":72857114},{"batb":[[0,2.2,5],[1,2.18,29.89],[2,2.16,74.05]],"ltp":2.18,"tv":302.74,"id":67083366}]}]}
{"op":"mcm","clk":"11952550003","pt":1724513217065,"mc":[{"id":"1.232215600","rc":[{"batb":[[0,2.18,29.89],[1,2.16,74.05],[2,2,48.74]],"ltp":2.18,"tv":302.74,"id":67083366}]}]}
{"op":"mcm","clk":"11952550080","pt":1724513217444,"mc":[{"id":"1.232215600","rc":[{"batb":[[0,1.81,5],[1,1.8,10],[2,1.79,108.73]],"ltp":1.85,"tv":2328.44,"id":72857114}]}]}
{"op":"mcm","clk":"11952550463","pt":1724513218984,"mc":[{"id":"1.232215600","rc":[{"trd":[[1.85,222.46]],"batb":[[0,1.85,48.45],[1,1.81,5],[2,1.8,10]],"ltp":1.85,"tv":2363.66,"id":72857114},{"trd":[[2.18,57.47]],"batb":[[0,2.16,74.05],[1,2,48.74],[2,1.76,2.71]],"ltp":2.18,"tv":332.63,"id":67083366}],"tv":2696.3}]}
{"op":"mcm","clk":"11952550703","pt":1724513219970,"mc":[{"id":"1.232215600","rc":[{"trd":[[1.85,228.35]],"batb":[[0,1.85,42.56]],"ltp":1.85,"tv":2369.55,"id":72857114},{"trd":[[2.18,62.47]],"ltp":2.18,"tv":337.63,"id":67083366}],"tv":2707.19}]}
{"op":"mcm","clk":"11952550887","pt":1724513220766,"mc":[{"id":"1.232215600","rc":[{"batb":[[1,1.8,10],[2,1.79,108.73]],"ltp":1.85,"tv":2369.55,"id":72857114}]}]}
{"op":"mcm","clk":"11952551979","pt":1724513225184,"mc":[{"id":"1.232215600","rc":[{"trd":[[1.85,313.47]],"batb":[[0,1.8,10],[1,1.79,108.73],[2,1.75,61.54]],"batl":[[0,1.85,6.67],[1,2.06,2.57],[2,2.28,6.78]],"ltp":1.85,"tv":2454.67,"id":72857114},{"batb":[[0,2.18,5],[1,2.16,74.05],[2,2,48.74]],"ltp":2.18,"tv":337.63,"id":67083366}],"tv":2792.31}]}
{"op":"mcm","clk":"11952552418","pt":1724513227165,"mc":[{"id":"1.232215600","rc":[{"trd":[[1.85,332.7],[1.87,137.85]],"batb":[[0,1.87,1158.43],[1,1.8,10],[2,1.79,108.73]],"batl":[[0,2.06,2.57],[1,2.28,6.78],[2,2.5,1]],"ltp":1.87,"tv":2559.43,"id":72857114},{"trd":[[2.16,74.44],[2.18,67.47]],"batb":[[0,2,48.74],[1,1.76,2.71],[2,1.75,1.37]],"ltp":2.16,"tv":416.68,"id":67083366}],"tv":2976.12}]}
{"op":"mcm","clk":"11952552534","pt":1724513227436,"mc":[{"id":"1.232215600","rc":[{"batb":[[0,1.88,5],[1,1.87,1158.43],[2,1.8,10]],"ltp":1.87,"tv":2559.43,"id":72857114}]}]}
{"op":"mcm","clk":"11952553338","pt":1724513230790,"mc":[{"id":"1.232215600","rc":[{"batb":[[0,1.87,1158.43],[1,1.8,10],[2,1.79,108.73]],"ltp":1.87,"tv":2559.43,"id":72857114},{"batb":[[0,2.02,5],[1,2,48.74],[2,1.76,2.71]],"ltp":2.16,"tv":416.68,"id":67083366}]}]}
{"op":"mcm","clk":"11952553846","pt":1724513232985,"mc":[{"id":"1.232215600","rc":[{"batb":[[0,1.88,5],[1,1.87,1158.43],[2,1.8,10]],"ltp":1.87,"tv":2559.43,"id":72857114},{"batb":[[1,1.76,2.71],[2,1.75,1.37]],"ltp":2.16,"tv":416.68,"id":67083366}]}]}
{"op":"mcm","clk":"11952554150","pt":1724513234317,"mc":[{"id":"1.232215600","rc":[{"batb":[[0,1.76,2.71],[1,1.75,1.37],[2,1.74,1.06]],"ltp":2.16,"tv":416.68,"id":67083366}]}]}
{"op":"mcm","clk":"11952554667","pt":1724513236405,"mc":[{"id":"1.232215600","rc":[{"batb":[[0,1.87,1158.43],[1,1.8,10],[2,1.79,108.73]],"ltp":1.87,"tv":2559.43,"id":72857114}]}]}
{"op":"mcm","clk":"11952555076","pt":1724513238298,"mc":[{"id":"1.232215600","rc":[{"batl":[[0,1.88,49.23],[1,2.06,2.57],[2,2.28,6.78]],"ltp":1.87,"tv":2559.43,"id":72857114}]}]}
{"op":"mcm","clk":"11952555436","pt":1724513239722,"mc":[{"id":"1.232215600","rc":[{"batl":[[0,1.88,49.33]],"ltp":1.87,"tv":2559.43,"id":72857114}]}]}
{"op":"mcm","clk":"11952558971","pt":1724513254410,"mc":[{"id":"1.232215600","rc":[{"trd":[[1.87,187.09],[1.88,99.51]],"batb":[[0,1.87,1137.81]],"batl":[[0,1.88,49.22]],"ltp":1.87,"tv":2608.78,"id":72857114},{"trd":[[2.12,0.87]],"batl":[[0,2.16,4],[1,2.44,0.1]],"ltp":2.12,"tv":416.78,"id":67083366}],"tv":3025.57}]}
{"op":"mcm","clk":"11952561825","pt":1724513265210,"mc":[{"id":"1.232215600","rc":[{"batl":[[0,1.88,49.12]],"ltp":1.87,"tv":2608.78,"id":72857114}]}]}
{"op":"mcm","clk":"11952564158","pt":1724513274812,"mc":[{"id":"1.232215600","rc":[{"batl":[[0,1.88,28.32]],"ltp":1.87,"tv":2608.78,"id":72857114}]}]}
{"op":"mcm","clk":"11952564502","pt":1724513276328,"mc":[{"id":"1.232215600","rc":[{"batl":[[2,2.28,2.15]],"ltp":1.87,"tv":2608.78,"id":72857114}]}]}
{"op":"mcm","clk":"11952565838","pt":1724513280742,"mc":[{"id":"1.232215600","rc":[{"trd":[[1.86,69.62],[1.87,2462.71]],"batb":[[0,1.8,10],[1,1.79,108.73],[2,1.66,66.89]],"batl":[[0,1.85,4690.87],[1,1.88,28.32],[2,2.06,2.57]],"ltp":1.86,"tv":4889.05,"id":72857114},{"trd":[[2.16,78.44]],"batl":[[0,2.44,0.1],[1,2.44,0]],"ltp":2.16,"tv":420.78,"id":67083366}],"tv":5309.84}]}
{"op":"mcm","clk":"11952566218","pt":1724513282335,"mc":[{"id":"1.232215600","rc":[{"trd":[[1.85,341.08]],"batl":[[0,1.85,4686.68]],"ltp":1.85,"tv":4897.43,"id":72857114}],"tv":5318.22}]}
{"op":"mcm","clk":"11952566819","pt":1724513284820,"mc":[{"id":"1.232215600","rc":[{"batl":[[0,1.84,4],[1,1.85,4690.68],[2,1.88,28.32]],"ltp":1.85,"tv":4897.43,"id":72857114},{"batb":[[0,2.2,5],[1,2.18,4],[2,2.16,4]],"ltp":2.16,"tv":420.78,"id":67083366}]}]}
{"op":"mcm","clk":"11952567107","pt":1724513285935,"mc":[{"id":"1.232215600","rc":[{"batl":[[0,1.88,28.32],[1,2.06,2.57],[2,2.28,2.15]],"ltp":1.85,"tv":4897.43,"id":72857114},{"batb":[[1,1.76,2.71],[2,1.75,1.37]],"ltp":2.16,"tv":420.78,"id":67083366}]}]}
{"op":"mcm","clk":"11952567697","pt":1724513288278,"mc":[{"id":"1.232215600","rc":[{"batb":[[0,1.76,2.71],[1,1.75,1.37],[2,1.74,1.06]],"ltp":2.16,"tv":420.78,"id":67083366}]}]}
{"op":"mcm","clk":"11952567946","pt":1724513289302,"mc":[{"id":"1.232215600","rc":[{"trd":[[1.88,99.7]],"batl":[[0,1.88,28.22]],"ltp":1.88,"tv":4897.63,"id":72857114}],"tv":5318.41}]}
{"op":"mcm","clk":"11952568268","pt":1724513290683,"mc":[{"id":"1.232215600","rc":[{"trd":[[1.88,99.81]],"batl":[[0,1.88,28.11]],"ltp":1.88,"tv":4897.74,"id":72857114},{"trd":[[2.12,0.96]],"ltp":2.12,"tv":420.87,"id":67083366}],"tv":5318.62}]}
{"op":"mcm","clk":"11952568998","pt":1724513293412,"mc":[{"id":"1.232215600","rc":[{"batl":[[0,2.44,0.37]],"ltp":2.12,"tv":420.87,"id":67083366}]}]}
{"op":"mcm","clk":"11952573327","pt":1724513310778,"mc":[{"id":"1.232215600","rc":[{"trd":[[1.79,23.18],[1.8,109.62],[1.83,5.45]],"batb":[[0,1.79,99.92],[1,1.66,66.89],[2,1.62,35.41]],"ltp":1.79,"tv":4935.69,"id":72857114},{"trd":[[2.2,5.47]],"batl":[[0,2.44,0.1]],"ltp":2.2,"tv":421.15,"id":67083366}],"tv":5356.84}]}
{"op":"mcm","clk":"11952574494","pt":1724513315411,"mc":[{"id":"1.232215600","rc":[{"trd":[[1.88,99.92]],"batb":[[0,1.79,108.73]],"batl":[[0,1.88,28]],"ltp":1.88,"tv":4935.8,"id":72857114},{"trd":[[2.12,1.06]],"ltp":2.12,"tv":421.24,"id":67083366}],"tv":5357.05}]}
{"op":"mcm","clk":"11952574561","pt":1724513315705,"mc":[{"id":"1.232215600","rc":[{"batl":[[0,2.24,41.89],[1,2.44,0.1]],"ltp":2.12,"tv":421.24,"id":67083366}]}]}
{"op":"mcm","clk":"11952575691","pt":1724513320406,"mc":[{"id":"1.232215600","rc":[{"trd":[[1.79,23.65]],"ltp":1.79,"tv":4936.27,"id":72857114},{"trd":[[2.28,0.37]],"batl":[[0,2.44,0.1],[1,2.44,0]],"ltp":2.28,"tv":421.61,"id":67083366}],"tv":5357.89}]}
{"op":"mcm","clk":"11952577003","pt":1724513326143,"mc":[{"id":"1.232215600","rc":[{"trd":[[1.88,100.83]],"batl":[[0,1.88,27.55]],"ltp":1.88,"tv":4937.17,"id":72857114},{"batb":[[1,1.74,1.06],[2,1.55,8.33]],"ltp":2.28,"tv":421.61,"id":67083366}],"tv":5358.79}]}
{"op":"mcm","clk":"11952577098","pt":1724513326503,"mc":[{"id":"1.232215600","rc":[{"trd":[[1.79,241.11]],"batb":[[0,1.66,66.89],[1,1.62,35.41],[2,1.55,8.33]],"batl":[[0,1.79,5429.73],[1,1.88,27.55],[2,2.06,2.57]],"ltp":1.79,"tv":5154.63,"id":72857114}],"tv":5576.25}]}
{"op":"mcm","clk":"11952577678","pt":1724513329128,"mc":[{"id":"1.232215600","rc":[{"batb":[[0,1.77,1.34],[1,1.76,2.71],[2,1.74,1.06]],"batl":[[0,2.42,1.03],[1,2.44,0.1]],"ltp":2.28,"tv":421.61,"id":67083366}]}]}
{"op":"mcm","clk":"11952578246","pt":1724513331182,"mc":[{"id":"1.232215600","rc":[{"batl":[[0,1.88,27.55],[1,2.06,2.57],[2,2.28,2.15]],"ltp":1.79,"tv":5154.63,"id":72857114},{"batb":[[1,1.74,1.06],[2,1.55,8.33]],"ltp":2.28,"tv":421.61,"id":67083366}]}]}
{"op":"mcm","clk":"11952578501","pt":1724513332160,"mc":[{"id":"1.232215600","rc":[{"batb":[[0,1.78,2.64],[1,1.77,1.34],[2,1.74,1.06]],"batl":[[0,2.4,2.06],[1,2.42,1.03],[2,2.44,0.1]],"ltp":2.28,"tv":421.61,"id":67083366}]}]}
{"op":"mcm","clk":"11952579440","pt":1724513335880,"mc":[{"id":"1.232215600","rc":[{"trd":[[1.71,237.93]],"batl":[[0,1.71,2531.45],[1,1.88,27.55],[2,2.06,2.57]],"ltp":1.71,"tv":5392.41,"id":72857114},{"trd":[[2.4,169.53]],"batl":[[0,2.42,1.03],[1,2.44,0.1],[2,2.44,0]],"ltp":2.4,"tv":591.03,"id":67083366}],"tv":5983.45}]}
{"op":"mcm","clk":"11952580810","pt":1724513341389,"mc":[{"id":"1.232215600","rc":[{"batl":[[0,1.71,2448.25]],"ltp":1.71,"tv":5392.41,"id":72857114}]}]}
{"op":"mcm","clk":"11952581589","pt":1724513345088,"mc":[{"id":"1.232215600","rc":[{"batl":[[0,1.71,2452.25]],"ltp":1.71,"tv":5392.41,"id":72857114},{"batb":[[0,2.4,4],[1,1.78,2.64],[2,1.77,1.34]],"ltp":2.4,"tv":591.03,"id":67083366}]}]}
{"op":"mcm","clk":"11952581832","pt":1724513346193,"mc":[{"id":"1.232215600","rc":[{"batl":[[0,1.71,2212.25]],"ltp":1.71,"tv":5392.41,"id":72857114}]}]}
{"op":"mcm","clk":"11952582224","pt":1724513347963,"mc":[{"id":"1.232215600","rc":[{"trd":[[1.71,291.11]],"batl":[[0,1.71,2159.07]],"ltp":1.71,"tv":5445.59,"id":72857114},{"trd":[[2.4,215.42]],"batb":[[0,1.78,2.64],[1,1.77,1.34],[2,1.74,1.06]],"ltp":2.4,"tv":636.92,"id":67083366}],"tv":6082.52}]}
{"op":"mcm","clk":"11952582404","pt":1724513348893,"mc":[{"id":"1.232215600","rc":[{"trd":[[1.71,299.49]],"batl":[[0,1.71,2154.88]],"ltp":1.71,"tv":5453.97,"id":72857114}],"tv":6090.9}]}
{"op":"mcm","clk":"11952582615","pt":1724513349874,"mc":[{"id":"1.232215600","rc":[{"batl":[[0,1.71,2031.8]],"ltp":1.71,"tv":5453.97,"id":72857114}]}]}
{"op":"mcm","clk":"11952582871","pt":1724513350978,"mc":[{"id":"1.232215600","rc":[{"trd":[[1.71,339.49]],"batl":[[0,1.71,2011.8]],"ltp":1.71,"tv":5493.97,"id":72857114}],"tv":6130.9}]}
{"op":"mcm","clk":"11952583174","pt":1724513352207,"mc":[{"id":"1.232215600","rc":[{"batl":[[0,1.71,1949.4]],"ltp":1.71,"tv":5493.97,"id":72857114}]}]}
{"op":"mcm","clk":"11952583520","pt":1724513353701,"mc":[{"id":"1.232215600","rc":[{"trd":[[1.71,339.85]],"batl":[[0,1.71,1949.22]],"ltp":1.71,"tv":5494.33,"id":72857114}],"tv":6131.26}]}
{"op":"mcm","clk":"11952584712","pt":1724513358991,"mc":[{"id":"1.232215600","rc":[{"trd":[[1.71,539.85]],"batb":[[2,1.6,123.08]],"batl":[[0,1.71,1849.22]],"ltp":1.71,"tv":5694.33,"id":72857114}],"tv":6331.26}]}
{"op":"mcm","clk":"11952584970","pt":1724513360201,"mc":[{"id":"1.232215600","rc":[{"batb":[[0,2.4,4],[1,1.78,2.64],[2,1.77,1.34]],"ltp":2.4,"tv":636.92,"id":67083366}]}]}
{"op":"mcm","clk":"11952585881","pt":1724513363821,"mc":[{"id":"1.232215600","rc":[{"trd":[[1.71,710.39]],"batl":[[0,1.71,1678.68]],"ltp":1.71,"tv":5864.87,"id":72857114},{"trd":[[2.4,344.93]],"batb":[[0,1.78,2.64],[1,1.77,1.34],[2,1.74,1.06]],"ltp":2.4,"tv":766.43,"id":67083366}],"tv":6631.31}]}
{"op":"mcm","clk":"11952588422","pt":1724513375327,"mc":[{"id":"1.232215600","rc":[{"batb":[[0,2.4,4],[1,1.78,2.64],[2,1.77,1.34]],"ltp":2.4,"tv":766.43,"id":67083366}]}]}
{"op":"mcm","clk":"11952588941","pt":1724513377251,"mc":[{"id":"1.232215600","rc":[{"batb":[[2,1.6,126.08]],"ltp":1.71,"tv":5864.87,"id":72857114}]}]}
{"op":"mcm","clk":"11952589130","pt":1724513378109,"mc":[{"id":"1.232215600","rc":[{"trd":[[1.71,711.3]],"batl":[[0,1.71,1678.23]],"ltp":1.71,"tv":5865.78,"id":72857114}],"tv":6632.21}]}
{"op":"mcm","clk":"11952590325","pt":1724513383767,"mc":[{"id":"1.232215600","rc":[{"batb":[[0,1.69,1.01],[1,1.66,66.16],[2,1.62,35.41]],"ltp":1.71,"tv":5865.78,"id":72857114},{"trd":[[2.4,345.38]],"batb":[[0,2.4,3.77]],"ltp":2.4,"tv":766.89,"id":67083366}],"tv":6632.67}]}
{"op":"mcm","clk":"11952591028","pt":1724513387053,"mc":[{"id":"1.232215600","rc":[{"batb":[[0,1.69,167.81]],"ltp":1.71,"tv":5865.78,"id":72857114}]}]}
{"op":"mcm","clk":"11952591957","pt":1724513391203,"mc":[{"id":"1.232215600","rc":[{"trd":[[1.71,712.98]],"batl":[[0,1.71,1677.39]],"ltp":1.71,"tv":5867.46,"id":72857114}],"tv":6634.35}]}
{"op":"mcm","clk":"11952592455","pt":1724513393354,"mc":[{"id":"1.232215600","rc":[{"batl":[[0,1.71,1533.41]],"ltp":1.71,"tv":5867.46,"id":72857114},{"trd":[[2.4,345.58]],"batb":[[0,2.4,3.67]],"ltp":2.4,"tv":767.09,"id":67083366}],"tv":6634.55}]}
{"op":"mcm","clk":"11952592675","pt":1724513394342,"mc":[{"id":"1.232215600","rc":[{"trd":[[1.71,766.62]],"batb":[[0,1.69,167.54]],"batl":[[0,1.71,1479.77]],"ltp":1.71,"tv":5921.1,"id":72857114},{"trd":[[2.4,391.14]],"batb":[[0,1.78,2.64],[1,1.77,1.34],[2,1.74,1.06]],"ltp":2.4,"tv":812.65,"id":67083366}],"tv":6733.75}]}
{"op":"mcm","clk":"11952592784","pt":1724513394830,"mc":[{"id":"1.232215600","rc":[{"trd":[[1.71,816.53]],"batl":[[0,1.71,1429.86]],"ltp":1.71,"tv":5971.01,"id":72857114},{"trd":[[2.4,426.7]],"ltp":2.4,"tv":848.21,"id":67083366}],"tv":6819.22}]}
{"op":"mcm","clk":"11952594141","pt":1724513401222,"mc":[{"id":"1.232215600","rc":[{"batb":[[2,1.64,3]],"ltp":1.71,"tv":5971.01,"id":72857114}]}]}
{"op":"mcm","clk":"11952594592","pt":1724513402261,"mc":[{"id":"1.232215600","rc":[{"batb":[[2,1.64,10.72]],"ltp":1.71,"tv":5971.01,"id":72857114}]}]}
{"op":"mcm","clk":"11952594675","pt":1724513402420,"mc":[{"id":"1.232215600","rc":[{"trd":[[1.71,816.67]],"batl":[[0,1.71,1429.72]],"ltp":1.71,"tv":5971.15,"id":72857114},{"trd":[[2.4,426.8]],"ltp":2.4,"tv":848.3,"id":67083366}],"tv":6819.46}]}
{"op":"mcm","clk":"11952595069","pt":1724513403515,"mc":[{"id":"1.232215600","rc":[{"trd":[[1.71,1151.75]],"batl":[[0,1.71,1262.18]],"ltp":1.71,"tv":6306.23,"id":72857114}],"tv":7154.54}]}
{"op":"mcm","clk":"11952595576","pt":1724513405600,"mc":[{"id":"1.232215600","rc":[{"batb":[[0,2.4,4],[1,1.78,2.64],[2,1.77,1.34]],"ltp":2.4,"tv":848.3,"id":67083366}]}]}
{"op":"mcm","clk":"11952596257","pt":1724513408198,"mc":[{"id":"1.232215600","rc":[{"trd":[[1.71,1989.43]],"batl":[[0,1.71,843.34]],"ltp":1.71,"tv":7143.91,"id":72857114}],"tv":7992.22}]}
{"op":"mcm","clk":"11952597229","pt":1724513412315,"mc":[{"id":"1.232215600","rc":[{"trd":[[1.71,1989.97]],"batb":[[0,1.7,1.54],[1,1.69,167.54],[2,1.66,66.16]],"batl":[[0,1.71,843.07]],"ltp":1.71,"tv":7144.45,"id":72857114}],"tv":7992.76}]}
{"op":"mcm","clk":"11952597717","pt":1724513414505,"mc":[{"id":"1.232215600","rc":[{"trd":[[1.71,2121.97]],"batl":[[0,1.71,777.07]],"ltp":1.71,"tv":7276.45,"id":72857114}],"tv":8124.76}]}
{"op":"mcm","clk":"11952598151","pt":1724513415822,"mc":[{"id":"1.232215600","rc":[{"trd":[[2.4,426.99]],"batb":[[0,2.4,3.9]],"ltp":2.4,"tv":848.5,"id":67083366}],"tv":8124.96}]}
{"op":"mcm","clk":"11952599661","pt":1724513422349,"mc":[{"id":"1.232215600","rc":[{"trd":[[1.71,2253.97]],"batl":[[0,1.71,711.07]],"ltp":1.71,"tv":7408.45,"id":72857114}],"tv":8256.96}]}
{"op":"mcm","clk":"11952600005","pt":1724513423957,"mc":[{"id":"1.232215600","rc":[{"batb":[[0,1.7,169.08]],"ltp":1.71,"tv":7408.45,"id":72857114}]}]}
{"op":"mcm","clk":"11952601473","pt":1724513430361,"mc":[{"id":"1.232215600","rc":[{"trd":[[2.4,427.08]],"batb":[[0,2.4,3.86]],"ltp":2.4,"tv":848.58,"id":67083366}],"tv":8257.04}]}
{"op":"mcm","clk":"11952601681","pt":1724513431442,"mc":[{"id":"1.232215600","rc":[{"trd":[[1.71,2385.97]],"batl":[[0,1.71,645.07]],"ltp":1.71,"tv":7540.45,"id":72857114}],"tv":8389.04}]}
{"op":"mcm","clk":"11952602090","pt":1724513433289,"mc":[{"id":"1.232215600","rc":[{"trd":[[2.4,427.27]],"batb":[[0,2.4,3.76]],"ltp":2.4,"tv":848.78,"id":67083366}],"tv":8389.24}]}
{"op":"mcm","clk":"11952602668","pt":1724513435874,"mc":[{"id":"1.232215600","rc":[{"trd":[[1.71,2387.74]],"batl":[[0,1.71,643.3]],"ltp":1.71,"tv":7542.22,"id":72857114},{"trd":[[2.4,436.05]],"batb":[[0,1.78,2.64],[1,1.77,1.34],[2,1.74,1.06]],"ltp":2.4,"tv":857.56,"id":67083366}],"tv":8399.79}]}
{"op":"mcm","clk":"11952603267","pt":1724513438755,"mc":[{"id":"1.232215600","rc":[{"trd":[[1.71,2519.74]],"batl":[[0,1.71,577.3]],"ltp":1.71,"tv":7674.22,"id":72857114}],"tv":8531.79}]}
{"op":"mcm","clk":"11952604026","pt":1724513442337,"mc":[{"id":"1.232215600","rc":[{"trd":[[1.71,2854.82]],"batl":[[0,1.71,409.76]],"ltp":1.71,"tv":8009.3,"id":72857114}],"tv":8866.87}]}
{"op":"mcm","clk":"11952604782","pt":1724513446174,"mc":[{"id":"1.232215600","rc":[{"trd":[[1.71,2856.57]],"batl":[[0,1.71,408.01]],"ltp":1.71,"tv":8011.05,"id":72857114},{"trd":[[2.4,437.3]],"ltp":2.4,"tv":858.81,"id":67083366}],"tv":8869.87}]}
{"op":"mcm","clk":"11952605111","pt":1724513447747,"mc":[{"id":"1.232215600","rc":[{"trd":[[1.71,2988.57]],"batl":[[0,1.71,342.01]],"ltp":1.71,"tv":8143.05,"id":72857114}],"tv":9001.87}]}
{"op":"mcm","clk":"11952605456","pt":1724513449468,"mc":[{"id":"1.232215600","rc":[{"trd":[[1.71,2992.99]],"batl":[[0,1.71,339.8]],"ltp":1.71,"tv":8147.47,"id":72857114}],"tv":9006.29}]}
{"op":"mcm","clk":"11952605728","pt":1724513450873,"mc":[{"id":"1.232215600","rc":[{"batb":[[0,2.4,4],[1,1.78,2.64],[2,1.77,1.34]],"ltp":2.4,"tv":858.81,"id":67083366}]}]}
{"op":"mcm","clk":"11952606611","pt":1724513455319,"mc":[{"id":"1.232215600","rc":[{"trd":[[1.71,3672.59],[1.72,22.62]],"batb":[[0,1.73,2571.29],[1,1.7,169.08],[2,1.69,167.54]],"batl":[[0,1.88,27.55],[1,2.06,2.57],[2,2.32,4.73]],"ltp":1.72,"tv":8832.65,"id":72857114},{"trd":[[2.4,441.3]],"batb":[[0,1.78,2.64],[1,1.77,1.34],[2,1.74,1.06]],"ltp":2.4,"tv":862.81,"id":67083366}],"tv":9695.47}]}
{"op":"mcm","clk":"11952606866","pt":1724513456515,"mc":[{"id":"1.232215600","rc":[{"batb":[[0,1.75,114.53],[1,1.73,2571.29],[2,1.7,169.08]],"ltp":1.72,"tv":8832.65,"id":72857114}]}]}
{"op":"mcm","clk":"11952607350","pt":1724513458990,"mc":[{"id":"1.232215600","rc":[{"batl":[[0,1.87,2.06],[1,1.88,27.55],[2,2.06,2.57]],"ltp":1.72,"tv":8832.65,"id":72857114}]}]}
{"op":"mcm","clk":"11952607554","pt":1724513460017,"mc":[{"id":"1.232215600","rc":[{"batl":[[0,2.42,1.13]],"ltp":2.4,"tv":862.81,"id":67083366}]}]}
{"op":"mcm","clk":"11952608113","pt":1724513462816,"mc":[{"id":"1.232215600","rc":[{"batl":[[0,2.42,1.03]],"ltp":2.4,"tv":862.81,"id":67083366}]}]}
{"op":"mcm","clk":"11952609017","pt":1724513467024,"mc":[{"id":"1.232215600","rc":[{"trd":[[1.75,200]],"batb":[[0,1.75,14.53]],"ltp":1.75,"tv":9032.65,"id":72857114}],"tv":9895.47}]}
{"op":"mcm","clk":"11952609894","pt":1724513471629,"mc":[{"id":"1.232215600","rc":[{"batb":[[0,1.73,2571.29],[1,1.7,169.08],[2,1.69,167.54]],"ltp":1.75,"tv":9032.65,"id":72857114}]}]}
{"op":"mcm","clk":"11952610408","pt":1724513473949,"mc":[{"id":"1.232215600","rc":[{"trd":[[1.87,2464.77]],"batb":[[0,1.7,169.08],[1,1.69,167.54],[2,1.66,66.16]],"batl":[[0,1.88,27.55],[1,2.06,2.57],[2,2.3,4.73]],"ltp":1.87,"tv":9034.71,"id":72857114},{"trd":[[2.14,47.22]],"batl":[[0,2.14,9.96],[1,2.42,1.03],[2,2.44,0.1]],"ltp":2.14,"tv":864.61,"id":67083366}],"tv":9899.32}]}
{"op":"mcm","clk":"11952611120","pt":1724513477223,"mc":[{"id":"1.232215600","rc":[{"batl":[[0,2.42,1.96],[1,2.44,0.1],[2,2.44,0]],"ltp":2.14,"tv":864.61,"id":67083366}]}]}
{"op":"mcm","clk":"11952611319","pt":1724513478262,"mc":[{"id":"1.232215600","rc":[{"trd":[[1.88,100.94]],"batl":[[0,1.88,27.44]],"ltp":1.88,"tv":9034.82,"id":72857114},{"trd":[[2.12,1.16]],"ltp":2.12,"tv":864.71,"id":67083366}],"tv":9899.53}]}
{"op":"mcm","clk":"11952611709","pt":1724513480040,"mc":[{"id":"1.232215600","rc":[{"batl":[[0,1.88,30.01]],"ltp":1.88,"tv":9034.82,"id":72857114},{"batl":[[0,2.42,1.03]],"ltp":2.12,"tv":864.71,"id":67083366}]}]}
{"op":"mcm","clk":"11952612090","pt":1724513482041,"mc":[{"id":"1.232215600","rc":[{"batb":[[0,1.71,2.06],[1,1.7,169.08],[2,1.69,167.54]],"ltp":1.88,"tv":9034.82,"id":72857114}]}]}
{"op":"mcm","clk":"11952612541","pt":1724513484239,"mc":[{"id":"1.232215600","rc":[{"batl":[[0,1.87,100],[1,1.88,30.01],[2,2.06,2.57]],"ltp":1.88,"tv":9034.82,"id":72857114}]}]}
{"op":"mcm","clk":"11952613168","pt":1724513487120,"mc":[{"id":"1.232215600","rc":[{"batl":[[0,2.22,10],[1,2.42,1.13],[2,2.44,0.1]],"ltp":2.12,"tv":864.71,"id":67083366}]}]}
{"op":"mcm","clk":"11952613354","pt":1724513488147,"mc":[{"id":"1.232215600","rc":[{"trd":[[1.87,2464.98]],"batl":[[0,1.87,99.79]],"ltp":1.87,"tv":9035.03,"id":72857114},{"trd":[[2.14,47.4]],"ltp":2.14,"tv":864.89,"id":67083366}],"tv":9899.92}]}
{"op":"mcm","clk":"11952614049","pt":1724513491409,"mc":[{"id":"1.232215600","rc":[{"batb":[[2,1.66,66.16]],"ltp":1.87,"tv":9035.03,"id":72857114}]}]}
{"op":"mcm","clk":"11952614308","pt":1724513492501,"mc":[{"id":"1.232215600","rc":[{"trd":[[1.87,2466.28]],"batl":[[0,1.87,98.49]],"ltp":1.87,"tv":9036.33,"id":72857114},{"trd":[[2.14,48.54]],"ltp":2.14,"tv":866.03,"id":67083366}],"tv":9902.36}]}
{"op":"mcm","clk":"11952614706","pt":1724513494224,"mc":[{"id":"1.232215600","rc":[{"trd":[[1.87,2468.64]],"batl":[[0,1.87,97.31]],"ltp":1.87,"tv":9038.69,"id":72857114}],"tv":9904.72}]}
{"op":"mcm","clk":"11952615137","pt":1724513496290,"mc":[{"id":"1.232215600","rc":[{"batb":[[0,1.81,4],[1,1.71,2.06],[2,1.7,169.08]],"batl":[[0,1.87,101.31]],"ltp":1.87,"tv":9038.69,"id":72857114},{"batb":[[0,2.14,4],[1,1.78,2.64],[2,1.77,1.34]],"batl":[[0,2.22,14]],"ltp":2.14,"tv":866.03,"id":67083366}]}]}
{"op":"mcm","clk":"11952615358","pt":1724513497192,"mc":[{"id":"1.232215600","rc":[{"trd":[[1.81,772.95]],"batb":[[0,1.71,2.06],[1,1.7,169.08],[2,1.66,66.16]],"ltp":1.81,"tv":9054.69,"id":72857114},{"trd":[[2.22,30.82]],"batl":[[0,2.22,3.48]],"ltp":2.22,"tv":872.55,"id":67083366}],"tv":9927.24}]}
{"op":"mcm","clk":"11952616427","pt":1724513502203,"mc":[{"id":"1.232215600","rc":[{"batl":[[1,2.42,1.03]],"ltp":2.22,"tv":872.55,"id":67083366}]}]}
{"op":"mcm","clk":"11952616918","pt":1724513504414,"mc":[{"id":"1.232215600","rc":[{"trd":[[1.81,777.22]],"batl":[[0,1.8,123.08],[1,1.81,15.73],[2,1.87,101.31]],"ltp":1.81,"tv":9058.96,"id":72857114},{"trd":[[2.22,34.3]],"batb":[[0,2.16,5],[1,2.14,4],[2,1.78,2.64]],"batl":[[0,2.42,1.03],[1,2.44,0.1],[2,2.44,0]],"ltp":2.22,"tv":876.03,"id":67083366}],"tv":9934.99}]}
{"op":"mcm","clk":"11952617723","pt":1724513507745,"mc":[{"id":"1.232215600","rc":[{"batb":[[0,2.14,4],[1,1.78,2.64],[2,1.77,1.34]],"ltp":2.22,"tv":876.03,"id":67083366}]}]}
{"op":"mcm","clk":"11952619600","pt":1724513516247,"mc":[{"id":"1.232215600","rc":[{"batb":[[0,2.16,5],[1,2.14,4],[2,1.78,2.64]],"batl":[[1,3.75,0.8]],"ltp":2.22,"tv":876.03,"id":67083366}]}]}
{"op":"mcm","clk":"11952619725","pt":1724513516694,"mc":[{"id":"1.232215600","rc":[{"batb":[[0,1.72,167.54],[1,1.71,2.06],[2,1.7,169.08]],"ltp":1.81,"tv":9058.96,"id":72857114}]}]}
{"op":"mcm","clk":"11952620194","pt":1724513518084,"mc":[{"id":"1.232215600","rc":[{"trd":[[1.8,109.85]],"batl":[[0,1.8,122.85]],"ltp":1.8,"tv":9059.19,"id":72857114},{"trd":[[2.24,0.18]],"ltp":2.24,"tv":876.21,"id":67083366}],"tv":9935.4}]}
{"op":"mcm","clk":"11952620518","pt":1724513519352,"mc":[{"id":"1.232215600","rc":[{"batb":[[0,2.14,4],[1,1.78,2.64],[2,1.77,1.34]],"ltp":2.24,"tv":876.21,"id":67083366}]}]}
{"op":"mcm","clk":"11952622426","pt":1724513528050,"mc":[{"id":"1.232215600","rc":[{"trd":[[1.8,109.97]],"batl":[[0,1.8,122.73]],"ltp":1.8,"tv":9059.31,"id":72857114},{"trd":[[2.24,0.28]],"batb":[[0,2.16,5],[1,2.14,4],[2,1.78,2.64]],"ltp":2.24,"tv":876.31,"id":67083366}],"tv":9935.62}]}
{"op":"mcm","clk":"11952622727","pt":1724513529577,"mc":[{"id":"1.232215600","rc":[{"trd":[[1.8,120.51]],"batl":[[0,1.8,112.19]],"ltp":1.8,"tv":9069.85,"id":72857114},{"trd":[[2.24,8.75]],"ltp":2.24,"tv":884.77,"id":67083366}],"tv":9954.63}]}
{"op":"mcm","clk":"11952623141","pt":1724513531594,"mc":[{"id":"1.232215600","rc":[{"batb":[[0,2.14,4],[1,1.78,2.64],[2,1.77,1.34]],"ltp":2.24,"tv":884.77,"id":67083366}]}]}
{"op":"mcm","clk":"11952624678","pt":1724513538323,"mc":[{"id":"1.232215600","rc":[{"batl":[[1,1.87,4],[2,1.88,30.01]],"ltp":1.8,"tv":9069.85,"id":72857114}]}]}
{"op":"mcm","clk":"11952624697","pt":1724513538440,"mc":[{"id":"1.232215600","rc":[{"batb":[[0,2.16,5],[1,2.14,4],[2,1.78,2.64]],"ltp":2.24,"tv":884.77,"id":67083366}]}]}
{"op":"mcm","clk":"11952625397","pt":1724513541724,"mc":[{"id":"1.232215600","rc":[{"batb":[[0,2.14,4],[1,1.78,2.64],[2,1.77,1.34]],"ltp":2.24,"tv":884.77,"id":67083366}]}]}
{"op":"mcm","clk":"11952627727","pt":1724513552368,"mc":[{"id":"1.232215600","rc":[{"batb":[[0,2.16,5],[1,2.14,4],[2,1.78,2.64]],"ltp":2.24,"tv":884.77,"id":67083366}]}]}
{"op":"mcm","clk":"11952628340","pt":1724513555134,"mc":[{"id":"1.232215600","rc":[{"trd":[[1.8,120.63]],"batl":[[0,1.8,112.07]],"ltp":1.8,"tv":9069.97,"id":72857114},{"trd":[[2.24,8.84]],"ltp":2.24,"tv":884.87,"id":67083366}],"tv":9954.84}]}
{"op":"mcm","clk":"11952628480","pt":1724513555735,"mc":[{"id":"1.232215600","rc":[{"batb":[[0,2.14,4],[1,1.78,2.64],[2,1.77,1.34]],"ltp":2.24,"tv":884.87,"id":67083366}]}]}
{"op":"mcm","clk":"11952631388","pt":1724513569963,"mc":[{"id":"1.232215600","rc":[{"batb":[[0,2.16,5],[1,2.14,4],[2,1.78,2.64]],"ltp":2.24,"tv":884.87,"id":67083366}]}]}
{"op":"mcm","clk":"11952632132","pt":1724513573366,"mc":[{"id":"1.232215600","rc":[{"batb":[[0,2.14,4],[1,1.78,2.64],[2,1.77,1.34]],"ltp":2.24,"tv":884.87,"id":67083366}]}]}
{"op":"mcm","clk":"11952633658","pt":1724513580891,"mc":[{"id":"1.232215600","rc":[{"trd":[[1.8,123.97]],"batl":[[0,1.8,110.4]],"ltp":1.8,"tv":9073.31,"id":72857114},{"batb":[[0,2.16,5],[1,2.14,4],[2,1.78,2.64]],"ltp":2.24,"tv":884.87,"id":67083366}],"tv":9958.18}]}
{"op":"mcm","clk":"11952634358","pt":1724513584271,"mc":[{"id":"1.232215600","rc":[{"batb":[[0,2.14,4],[1,1.78,2.64],[2,1.77,1.34]],"ltp":2.24,"tv":884.87,"id":67083366}]}]}
{"op":"mcm","clk":"11952637495","pt":1724513598811,"mc":[{"id":"1.232215600","rc":[{"batb":[[0,2.16,5],[1,2.14,4],[2,1.78,2.64]],"ltp":2.24,"tv":884.87,"id":67083366}]}]}
{"op":"mcm","clk":"11952638209","pt":1724513602446,"mc":[{"id":"1.232215600","rc":[{"batb":[[0,2.14,4],[1,1.78,2.64],[2,1.77,1.34]],"ltp":2.24,"tv":884.87,"id":67083366}]}]}
{"op":"mcm","clk":"11952639541","pt":1724513609320,"mc":[{"id":"1.232215600","rc":[{"trd":[[1.8,124.09]],"batl":[[0,1.8,110.28]],"ltp":1.8,"tv":9073.43,"id":72857114},{"trd":[[2.24,8.94]],"ltp":2.24,"tv":884.97,"id":67083366}],"tv":9958.4}]}
{"op":"mcm","clk":"11952639592","pt":1724513609607,"mc":[{"id":"1.232215600","rc":[{"batb":[[0,2.16,5],[1,2.14,4],[2,1.78,2.64]],"ltp":2.24,"tv":884.97,"id":67083366}]}]}
{"op":"mcm","clk":"11952640277","pt":1724513612926,"mc":[{"id":"1.232215600","rc":[{"batb":[[0,2.14,4],[1,1.78,2.64],[2,1.77,1.34]],"ltp":2.24,"tv":884.97,"id":67083366}]}]}
{"op":"mcm","clk":"11952642231","pt":1724513622335,"mc":[{"id":"1.232215600","rc":[{"trd":[[1.8,124.77]],"batl":[[0,1.8,109.6]],"ltp":1.8,"tv":9074.11,"id":72857114},{"trd":[[2.24,9.48]],"ltp":2.24,"tv":885.51,"id":67083366}],"tv":9959.63}]}
{"op":"mcm","clk":"11952642274","pt":1724513622530,"mc":[{"id":"1.232215600","rc":[{"batb":[[0,2.16,5],[1,2.14,4],[2,1.78,2.64]],"ltp":2.24,"tv":885.51,"id":67083366}]}]}
{"op":"mcm","clk":"11952642667","pt":1724513624520,"mc":[{"id":"1.232215600","rc":[{"batb":[[0,1.75,4.61],[1,1.72,167.54],[2,1.71,2.06]],"ltp":1.8,"tv":9074.11,"id":72857114}]}]}
{"op":"mcm","clk":"11952642969","pt":1724513626031,"mc":[{"id":"1.232215600","rc":[{"batb":[[0,2.14,4],[1,1.78,2.64],[2,1.77,1.34]],"ltp":2.24,"tv":885.51,"id":67083366}]}]}
{"op":"mcm","clk":"11952643986","pt":1724513630350,"mc":[{"id":"1.232215600","rc":[{"batb":[[0,2.16,5],[1,2.14,4],[2,1.78,2.64]],"batl":[[0,2.34,309.65]],"ltp":2.24,"tv":885.51,"id":67083366}]}]}
{"op":"mcm","clk":"11952644381","pt":1724513632354,"mc":[{"id":"1.232215600","rc":[{"batb":[[0,1.75,8.61]],"batl":[[0,1.79,4],[1,1.8,113.6],[2,1.87,4]],"ltp":1.8,"tv":9074.11,"id":72857114},{"batb":[[1,1.78,2.64],[2,1.74,1.06]],"batl":[[0,2.32,4],[1,2.34,313.65],[2,3.75,0.8]],"ltp":2.24,"tv":885.51,"id":67083366}]}]}
{"op":"mcm","clk":"11952644539","pt":1724513633241,"mc":[{"id":"1.232215600","rc":[{"batl":[[0,1.8,109.6],[1,1.88,30.01],[2,2.06,2.57]],"ltp":1.8,"tv":9074.11,"id":72857114},{"batb":[[0,1.74,1.06],[1,1.55,8.33],[2,1.51,20]],"ltp":2.24,"tv":885.51,"id":67083366}]}]}
{"op":"mcm","clk":"11952644654","pt":1724513633833,"mc":[{"id":"1.232215600","rc":[{"batb":[[0,1.75,1.37],[1,1.74,1.06],[2,1.55,8.33]],"ltp":2.24,"tv":885.51,"id":67083366}]}]}
{"op":"mcm","clk":"11952645179","pt":1724513636730,"mc":[{"id":"1.232215600","rc":[{"trd":[[1.8,125.16]],"batl":[[0,1.8,109.21]],"ltp":1.8,"tv":9074.5,"id":72857114},{"trd":[[2.24,9.8]],"ltp":2.24,"tv":885.83,"id":67083366}],"tv":9960.33}]}
{"op":"mcm","clk":"11952646063","pt":1724513641354,"mc":[{"id":"1.232215600","rc":[{"trd":[[2.32,24.1],[2.34,522.4]],"batl":[[0,2.34,52.45],[1,3.75,0.8],[2,3.75,0]],"ltp":2.34,"tv":1416.23,"id":67083366}],"tv":10490.73}]}
{"op":"mcm","clk":"11952646873","pt":1724513646057,"mc":[{"id":"1.232215600","rc":[{"batb":[[0,1.76,2.06],[1,1.75,1.37],[2,1.74,1.06]],"ltp":2.34,"tv":1416.23,"id":67083366}]}]}
{"op":"mcm","clk":"11952646975","pt":1724513646767,"mc":[{"id":"1.232215600","rc":[{"trd":[[1.8,234.37]],"batl":[[0,1.88,30.01],[1,2.06,2.57],[2,2.3,4.73]],"ltp":1.8,"tv":9183.71,"id":72857114},{"trd":[[2.24,97.56]],"batl":[[0,2.34,52.75]],"ltp":2.24,"tv":1503.98,"id":67083366}],"tv":10687.7}]}
{"op":"mcm","clk":"11952647543","pt":1724513649757,"mc":[{"id":"1.232215600","rc":[{"batb":[[0,1.8,10],[1,1.75,8.61],[2,1.72,167.54]],"ltp":1.8,"tv":9183.71,"id":72857114}]}]}
{"op":"mcm","clk":"11952649505","pt":1724513660309,"mc":[{"id":"1.232215600","rc":[{"batb":[[1,1.75,4]],"ltp":1.8,"tv":9183.71,"id":72857114}]}]}
{"op":"mcm","clk":"11952649959","pt":1724513662486,"mc":[{"id":"1.232215600","rc":[{"trd":[[1.8,254.73]],"batb":[[0,1.75,4],[1,1.72,167.54],[2,1.71,2.06]],"batl":[[0,1.8,13.64],[1,1.88,30.01],[2,2.06,2.57]],"ltp":1.8,"tv":9204.07,"id":72857114},{"trd":[[2.24,97.85]],"batl":[[0,2.34,52.45]],"ltp":2.24,"tv":1504.28,"id":67083366}],"tv":10708.35}]}
{"op":"mcm","clk":"11952650481","pt":1724513664565,"mc":[{"id":"1.232215600","rc":[{"batl":[[0,2.28,8.38],[1,2.34,52.45],[2,3.75,0.8]],"ltp":2.24,"tv":1504.28,"id":67083366}]}]}
{"op":"mcm","clk":"11952651304","pt":1724513667781,"mc":[{"id":"1.232215600","rc":[{"batb":[[0,1.79,108.73],[1,1.75,4],[2,1.72,167.54]],"ltp":1.8,"tv":9204.07,"id":72857114}]}]}
{"op":"mcm","clk":"11952651675","pt":1724513669395,"mc":[{"id":"1.232215600","rc":[{"batl":[[1,1.88,2.57]],"ltp":1.8,"tv":9204.07,"id":72857114}]}]}
{"op":"mcm","clk":"11952651950","pt":1724513670613,"mc":[{"id":"1.232215600","rc":[{"trd":[[1.8,263.11]],"batl":[[0,1.8,9.45]],"ltp":1.8,"tv":9212.45,"id":72857114},{"batl":[[2,4.5,1.03]],"ltp":2.24,"tv":1504.28,"id":67083366}],"tv":10716.73}]}
{"op":"mcm","clk":"11952652753","pt":1724513674725,"mc":[{"id":"1.232215600","rc":[{"trd":[[1.79,364.19],[1.8,265.85]],"batb":[[0,1.79,47.19]],"batl":[[0,1.8,6.71]],"ltp":1.8,"tv":9338.27,"id":72857114},{"trd":[[2.24,100.05]],"ltp":2.24,"tv":1506.48,"id":67083366}],"tv":10844.75}]}
{"op":"mcm","clk":"11952653148","pt":1724513676618,"mc":[{"id":"1.232215600","rc":[{"batl":[[0,2.34,52.45],[1,4.5,1.03],[2,4.5,0]],"ltp":2.24,"tv":1506.48,"id":67083366}]}]}
{"op":"mcm","clk":"11952653393","pt":1724513677802,"mc":[{"id":"1.232215600","rc":[{"batb":[[0,1.79,112.73]],"ltp":1.8,"tv":9338.27,"id":72857114},{"batl":[[0,2.26,4],[1,2.28,4],[2,2.34,52.45]],"ltp":2.24,"tv":1506.48,"id":67083366}]}]}
{"op":"mcm","clk":"11952657542","pt":1724513972320,"mc":[{"id":"1.232215600","marketDefinition":{"bspMarket":false,"turnInPlayEnabled":true,"persistenceEnabled":true,"marketBaseRate":5.0,"eventId":"33522473","eventTypeId":"4","numberOfWinners":1,"bettingType":"ODDS","marketType":"MATCH_ODDS","marketTime":"2024-08-24T15:45:00.000Z","suspendTime":"2024-08-24T15:45:00.000Z","bspReconciled":false,"complete":true,"inPlay":false,"crossMatching":true,"runnersVoidable":false,"numberOfActiveRunners":2,"betDelay":0,"status":"SUSPENDED","runners":[{"status":"ACTIVE","sortPriority":1,"id":72857114,"name":"Boca Raton Trailblazers"},{"status":"ACTIVE","sortPriority":2,"id":67083366,"name":"New York Strikers"}],"regulators":["MR_INT"],"countryCode":"GB","discountAllowed":true,"timezone":"GMT","openDate":"2024-08-24T15:45:00.000Z","version":6095789138,"name":"Match Odds","eventName":"Boca Raton Trailblazers v New York Strikers"}}]}
{"op":"mcm","clk":"11952701450","pt":1724517334537,"mc":[{"id":"1.232215600","marketDefinition":{"bspMarket":false,"turnInPlayEnabled":true,"persistenceEnabled":true,"marketBaseRate":5.0,"eventId":"33522473","eventTypeId":"4","numberOfWinners":1,"bettingType":"ODDS","marketType":"MATCH_ODDS","marketTime":"2024-08-24T15:45:00.000Z","suspendTime":"2024-08-24T15:45:00.000Z","bspReconciled":false,"complete":true,"inPlay":true,"crossMatching":true,"runnersVoidable":false,"numberOfActiveRunners":2,"betDelay":5,"status":"OPEN","runners":[{"status":"ACTIVE","sortPriority":1,"id":72857114,"name":"Boca Raton Trailblazers"},{"status":"ACTIVE","sortPriority":2,"id":67083366,"name":"New York Strikers"}],"regulators":["MR_INT"],"countryCode":"GB","discountAllowed":true,"timezone":"GMT","openDate":"2024-08-24T15:45:00.000Z","version":6096109683,"name":"Match Odds","eventName":"Boca Raton Trailblazers v New York Strikers"}}]}
{"op":"mcm","clk":"11952702741","pt":1724517387328,"mc":[{"id":"1.232215600","rc":[{"batl":[[0,1.9,378.47]],"ltp":1.8,"tv":9338.27,"id":72857114}]}]}
{"op":"mcm","clk":"11952703651","pt":1724517395519,"mc":[{"id":"1.232215600","rc":[{"batb":[[0,1.2,0.8]],"ltp":2.24,"tv":1506.48,"id":67083366}]}]}
{"op":"mcm","clk":"11952704634","pt":1724517406113,"mc":[{"id":"1.232215600","rc":[{"trd":[[1.9,11.05]],"batl":[[0,1.9,374.17]],"ltp":1.9,"tv":9346.76,"id":72857114},{"trd":[[2.1,71.69]],"ltp":2.1,"tv":1506.58,"id":67083366}],"tv":10853.34}]}
{"op":"mcm","clk":"11952704815","pt":1724517408630,"mc":[{"id":"1.232215600","rc":[{"trd":[[1.9,15.68]],"batl":[[0,1.9,369.54]],"ltp":1.9,"tv":9351.39,"id":72857114},{"trd":[[2.1,75.88]],"ltp":2.1,"tv":1510.77,"id":67083366}],"tv":10862.16}]}
{"op":"mcm","clk":"11952704937","pt":1724517410040,"mc":[{"id":"1.232215600","rc":[{"trd":[[1.9,24.59]],"batl":[[0,1.9,360.63]],"ltp":1.9,"tv":9360.3,"id":72857114},{"trd":[[2.1,83.94]],"ltp":2.1,"tv":1518.83,"id":67083366}],"tv":10879.13}]}
{"op":"mcm","clk":"11952705395","pt":1724517415057,"mc":[{"id":"1.232215600","rc":[{"trd":[[1.9,26.9]],"batl":[[0,1.9,358.32]],"ltp":1.9,"tv":9362.61,"id":72857114},{"trd":[[2.1,86.03]],"ltp":2.1,"tv":1520.92,"id":67083366}],"tv":10883.53}]}
{"op":"mcm","clk":"11952705477","pt":1724517416260,"mc":[{"id":"1.232215600","rc":[{"batb":[[0,1.01,41.84]],"ltp":2.1,"tv":1520.92,"id":67083366}]}]}
{"op":"mcm","clk":"11952705565","pt":1724517417156,"mc":[{"id":"1.232215600","rc":[{"trd":[[1.9,743.54]],"batb":[[0,1.9,57]],"ltp":1.9,"tv":10079.25,"id":72857114},{"batl":[[0,2.1,2.51]],"ltp":2.1,"tv":1520.92,"id":67083366}],"tv":11600.17}]}
{"op":"mcm","clk":"11952705619","pt":1724517417845,"mc":[{"id":"1.232215600","rc":[{"batl":[[0,2.1,305.29]],"ltp":2.1,"tv":1520.92,"id":67083366}]}]}
{"op":"mcm","clk":"11952705793","pt":1724517420239,"mc":[{"id":"1.232215600","rc":[{"batb":[[0,1.9,472.32]],"ltp":1.9,"tv":10079.25,"id":72857114},{"batl":[[0,2.1,307.38]],"ltp":2.1,"tv":1520.92,"id":67083366}]}]}
{"op":"mcm","clk":"11952705845","pt":1724517420762,"mc":[{"id":"1.232215600","rc":[{"batl":[[0,2.1,3311.57]],"ltp":2.1,"tv":1520.92,"id":67083366}]}]}
{"op":"mcm","clk":"11952706031","pt":1724517422766,"mc":[{"id":"1.232215600","rc":[{"batl":[[0,2.1,3008.79]],"ltp":2.1,"tv":1520.92,"id":67083366}]}]}
{"op":"mcm","clk":"11952706129","pt":1724517423858,"mc":[{"id":"1.232215600","rc":[{"batl":[[0,2.1,3008.89]],"ltp":2.1,"tv":1520.92,"id":67083366}]}]}
{"op":"mcm","clk":"11952706188","pt":1724517424638,"mc":[{"id":"1.232215600","rc":[{"batl":[[0,2.1,3006.38]],"ltp":2.1,"tv":1520.92,"id":67083366}]}]}
{"op":"mcm","clk":"11952706387","pt":1724517427073,"mc":[{"id":"1.232215600","rc":[{"batl":[[0,2.1,3006.28]],"ltp":2.1,"tv":1520.92,"id":67083366}]}]}
{"op":"mcm","clk":"11952706436","pt":1724517427445,"mc":[{"id":"1.232215600","rc":[{"batl":[[0,2.1,3010.04]],"ltp":2.1,"tv":1520.92,"id":67083366}]}]}
{"op":"mcm","clk":"11952706969","pt":1724517432977,"mc":[{"id":"1.232215600","rc":[{"batb":[[1,1.4,1544]],"ltp":1.9,"tv":10079.25,"id":72857114}]}]}
{"op":"mcm","clk":"11952707120","pt":1724517434378,"mc":[{"id":"1.232215600","rc":[{"batb":[[0,1.25,26.49]],"ltp":2.1,"tv":1520.92,"id":67083366}]}]}
{"op":"mcm","clk":"11952707307","pt":1724517436371,"mc":[{"id":"1.232215600","rc":[{"batb":[[0,1.43,1544],[1,1.25,26.49]],"ltp":2.1,"tv":1520.92,"id":67083366}]}]}
{"op":"mcm","clk":"11952707383","pt":1724517437158,"mc":[{"id":"1.232215600","rc":[{"batb":[[0,1.41,1544]],"ltp":2.1,"tv":1520.92,"id":67083366}]}]}
{"op":"mcm","clk":"11952707504","pt":1724517438342,"mc":[{"id":"1.232215600","rc":[{"batb":[[0,1.3,1544]],"ltp":2.1,"tv":1520.92,"id":67083366}]}]}
{"op":"mcm","clk":"11952707706","pt":1724517440366,"mc":[{"id":"1.232215600","rc":[{"trd":[[1.9,743.74]],"batb":[[0,1.9,472.22]],"ltp":1.9,"tv":10079.45,"id":72857114},{"trd":[[1.3,2.72]],"batb":[[0,1.3,1542.64]],"ltp":1.3,"tv":1523.64,"id":67083366}],"tv":11603.09}]}
{"op":"mcm","clk":"11952707784","pt":1724517441255,"mc":[{"id":"1.232215600","rc":[{"batb":[[0,1.9,415.32]],"ltp":1.9,"tv":10079.45,"id":72857114}]}]}
{"op":"mcm","clk":"11952707892","pt":1724517442754,"mc":[{"id":"1.232215600","rc":[{"batb":[[0,1.34,1544],[1,1.3,1542.64],[2,1.25,26.49]],"ltp":1.3,"tv":1523.64,"id":67083366}]}]}
{"op":"mcm","clk":"11952708658","pt":1724517450378,"mc":[{"id":"1.232215600","rc":[{"batb":[[0,1.42,418.84],[1,1.34,1544],[2,1.3,1542.64]],"ltp":1.3,"tv":1523.64,"id":67083366}]}]}
{"op":"mcm","clk":"11952708737","pt":1724517450862,"mc":[{"id":"1.232215600","rc":[{"batb":[[2,1.3,1543.48]],"ltp":1.3,"tv":1523.64,"id":67083366}]}]}
{"op":"mcm","clk":"11952709257","pt":1724517454359,"mc":[{"id":"1.232215600","rc":[{"trd":[[1.9,743.94]],"batb":[[0,1.9,415.22]],"ltp":1.9,"tv":10079.65,"id":72857114},{"batb":[[1,1.4,25.13],[2,1.34,1544]],"ltp":1.3,"tv":1523.64,"id":67083366}],"tv":11603.29}]}
{"op":"mcm","clk":"11952709351","pt":1724517454990,"mc":[{"id":"1.232215600","rc":[{"batl":[[0,3.75,2.51]],"ltp":1.9,"tv":10079.65,"id":72857114},{"batb":[[0,1.62,418.38],[1,1.42,418.84],[2,1.4,25.13]],"ltp":1.3,"tv":1523.64,"id":67083366}]}]}
{"op":"mcm","clk":"11952709563","pt":1724517456192,"mc":[{"id":"1.232215600","rc":[{"trd":[[1.9,746.96]],"batb":[[0,1.9,413.71]],"ltp":1.9,"tv":10082.67,"id":72857114},{"batb":[[2,1.4,33.51]],"ltp":1.3,"tv":1523.64,"id":67083366}],"tv":11606.31}]}
{"op":"mcm","clk":"11952709807","pt":1724517457704,"mc":[{"id":"1.232215600","rc":[{"batb":[[2,1.4,12.57]],"ltp":1.3,"tv":1523.64,"id":67083366}]}]}
{"op":"mcm","clk":"11952710617","pt":1724517462974,"mc":[{"id":"1.232215600","rc":[{"batl":[[0,2.06,1544],[1,2.1,3010.04]],"ltp":1.3,"tv":1523.64,"id":67083366}]}]}
{"op":"mcm","clk":"11952710731","pt":1724517463603,"mc":[{"id":"1.232215600","rc":[{"batb":[[1,1.41,84.51],[2,1.4,1544]],"ltp":1.9,"tv":10082.67,"id":72857114}]}]}
{"op":"mcm","clk":"11952711425","pt":1724517468141,"mc":[{"id":"1.232215600","rc":[{"trd":[[1.94,0.18]],"ltp":1.94,"tv":10082.85,"id":72857114},{"trd":[[2.06,0.17]],"batb":[[0,1.63,4.19],[1,1.62,418.38],[2,1.42,418.84]],"batl":[[0,2.06,1543.83]],"ltp":2.06,"tv":1523.81,"id":67083366}],"tv":11606.66}]}
{"op":"mcm","clk":"11952711667","pt":1724517469718,"mc":[{"id":"1.232215600","rc":[{"batb":[[0,1.68,83.77],[1,1.63,4.19],[2,1.62,418.38]],"ltp":2.06,"tv":1523.81,"id":67083366}]}]}
{"op":"mcm","clk":"11952711777","pt":1724517470502,"mc":[{"id":"1.232215600","rc":[{"batb":[[1,1.63,5.03]],"ltp":2.06,"tv":1523.81,"id":67083366}]}]}
{"op":"mcm","clk":"11952712128","pt":1724517472693,"mc":[{"id":"1.232215600","rc":[{"batb":[[0,2.02,167.54],[1,1.9,413.71],[2,1.41,84.51]],"ltp":1.94,"tv":10082.85,"id":72857114},{"batl":[[1,2.1,3219.23]],"ltp":2.06,"tv":1523.81,"id":67083366}]}]}
{"op":"mcm","clk":"11952712392","pt":1724517474211,"mc":[{"id":"1.232215600","rc":[{"batb":[[1,1.63,4.19]],"ltp":2.06,"tv":1523.81,"id":67083366}]}]}
{"op":"mcm","clk":"11952712658","pt":1724517475794,"mc":[{"id":"1.232215600","rc":[{"trd":[[1.68,0.2]],"batb":[[0,1.68,83.67]],"batl":[[0,2.06,1544.01]],"ltp":1.68,"tv":1524.0,"id":67083366}],"tv":11606.86}]}
{"op":"mcm","clk":"11952712866","pt":1724517477026,"mc":[{"id":"1.232215600","rc":[{"batb":[[1,1.98,80],[2,1.9,413.71]],"ltp":1.94,"tv":10082.85,"id":72857114}]}]}
{"op":"mcm","clk":"11952713842","pt":1724517481127,"mc":[{"id":"1.232215600","rc":[{"batb":[[2,1.95,16.76]],"ltp":1.94,"tv":10082.85,"id":72857114},{"batb":[[0,1.7,100],[1,1.68,83.67],[2,1.63,4.19]],"ltp":1.68,"tv":1524.0,"id":67083366}]}]}
{"op":"mcm","clk":"11952713922","pt":1724517481509,"mc":[{"id":"1.232215600","rc":[{"batb":[[1,1.95,16.76],[2,1.9,413.71]],"ltp":1.94,"tv":10082.85,"id":72857114}]}]}
{"op":"mcm","clk":"11952714418","pt":1724517483933,"mc":[{"id":"1.232215600","rc":[{"trd":[[2.02,8.08]],"batb":[[0,2.02,159.46]],"ltp":2.02,"tv":10090.93,"id":72857114},{"trd":[[1.98,0.36],[1.99,8.2]],"batl":[[0,2.06,1543.83]],"ltp":1.99,"tv":1532.57,"id":67083366}],"tv":11623.5}]}
{"op":"mcm","clk":"11952715256","pt":1724517488532,"mc":[{"id":"1.232215600","rc":[{"trd":[[1.7,83.68]],"batb":[[0,1.7,58.16]],"ltp":1.7,"tv":1616.25,"id":67083366}],"tv":11707.18}]}
{"op":"mcm","clk":"11952715540","pt":1724517490339,"mc":[{"id":"1.232215600","rc":[{"trd":[[2.02,8.28]],"batb":[[0,2.02,159.36],[1,1.9,413.71],[2,1.41,84.51]],"ltp":2.02,"tv":10091.13,"id":72857114}],"tv":11707.38}]}
{"op":"mcm","clk":"11952715653","pt":1724517491152,"mc":[{"id":"1.232215600","rc":[{"batb":[[2,1.4,1544]],"ltp":2.02,"tv":10091.13,"id":72857114},{"batb":[[0,1.72,1288.68],[1,1.7,58.16],[2,1.68,83.67]],"ltp":1.7,"tv":1616.25,"id":67083366}]}]}
{"op":"mcm","clk":"11952716185","pt":1724517494320,"mc":[{"id":"1.232215600","rc":[{"trd":[[2.02,8.47],[2.4,0.11]],"batb":[[0,2.02,159.26]],"ltp":2.02,"tv":10091.43,"id":72857114},{"trd":[[1.72,0.35]],"batb":[[0,1.72,1288.43]],"ltp":1.72,"tv":1616.59,"id":67083366}],"tv":11708.03}]}
{"op":"mcm","clk":"11952716220","pt":1724517494533,"mc":[{"id":"1.232215600","rc":[{"batl":[[1,2.1,3217.14]],"ltp":1.72,"tv":1616.59,"id":67083366}]}]}
{"op":"mcm","clk":"11952716364","pt":1724517495436,"mc":[{"id":"1.232215600","rc":[{"batb":[[1,2,16.76],[2,1.9,413.71]],"ltp":2.02,"tv":10091.43,"id":72857114}]}]}
{"op":"mcm","clk":"11952716743","pt":1724517498041,"mc":[{"id":"1.232215600","rc":[{"batb":[[0,2.02,159.36]],"ltp":2.02,"tv":10091.43,"id":72857114}]}]}
{"op":"mcm","clk":"11952716939","pt":1724517499249,"mc":[{"id":"1.232215600","rc":[{"trd":[[2.3,0.2]],"batb":[[0,2.02,117.52]],"ltp":2.3,"tv":10091.63,"id":72857114}],"tv":11708.23}]}
{"op":"mcm","clk":"11952717377","pt":1724517502327,"mc":[{"id":"1.232215600","rc":[{"batb":[[0,2.06,80],[1,2.02,117.52],[2,2,16.76]],"ltp":2.3,"tv":10091.63,"id":72857114},{"batb":[[0,1.74,135.03],[1,1.72,1288.43],[2,1.7,58.16]],"ltp":1.72,"tv":1616.59,"id":67083366}]}]}
{"op":"mcm","clk":"11952717594","pt":1724517503753,"mc":[{"id":"1.232215600","rc":[{"trd":[[2.36,4.19]],"ltp":2.36,"tv":10095.82,"id":72857114},{"trd":[[1.74,5.68]],"batb":[[0,1.74,129.35]],"ltp":1.74,"tv":1622.27,"id":67083366}],"tv":11718.1}]}
{"op":"mcm","clk":"11952717975","pt":1724517506349,"mc":[{"id":"1.232215600","rc":[{"batl":[[0,1.86,332.26],[1,2.06,1543.83],[2,2.1,3217.14]],"ltp":1.74,"tv":1622.27,"id":67083366}]}]}
{"op":"mcm","clk":"11952718071","pt":1724517507120,"mc":[{"id":"1.232215600","rc":[{"trd":[[1.74,5.88]],"batb":[[0,1.74,129.25]],"ltp":1.74,"tv":1622.47,"id":67083366}],"tv":11718.29}]}
{"op":"mcm","clk":"11952718168","pt":1724517507964,"mc":[{"id":"1.232215600","rc":[{"batb":[[1,1.73,83.67],[2,1.72,1288.43]],"batl":[[0,2.06,1543.83],[1,2.1,3212.95],[2,2.1,0]],"ltp":1.74,"tv":1622.47,"id":67083366}]}]}
{"op":"mcm","clk":"11952718654","pt":1724517511247,"mc":[{"id":"1.232215600","rc":[{"trd":[[2.06,1.36]],"batb":[[0,2.06,79.32]],"ltp":2.06,"tv":10097.18,"id":72857114},{"batl":[[0,1.91,332.26],[1,2.06,1543.83],[2,2.1,3212.95]],"ltp":1.74,"tv":1622.47,"id":67083366}],"tv":11719.66}]}
{"op":"mcm","clk":"11952718822","pt":1724517512252,"mc":[{"id":"1.232215600","rc":[{"trd":[[2.08,0.1]],"batb":[[0,2.02,117.52],[1,2,16.76],[2,1.9,413.71]],"ltp":2.08,"tv":10097.28,"id":72857114},{"trd":[[1.91,0.37]],"batl":[[0,1.91,332.15]],"ltp":1.91,"tv":1622.58,"id":67083366}],"tv":11719.86}]}
{"op":"mcm","clk":"11952719069","pt":1724517514042,"mc":[{"id":"1.232215600","rc":[{"trd":[[1.91,2.05]],"batl":[[0,1.91,331.31]],"ltp":1.91,"tv":1624.26,"id":67083366}],"tv":11721.54}]}
{"op":"mcm","clk":"11952719187","pt":1724517515054,"mc":[{"id":"1.232215600","rc":[{"trd":[[2.08,0.51]],"ltp":2.08,"tv":10097.69,"id":72857114},{"trd":[[1.91,128.02]],"batl":[[0,1.91,268.1]],"ltp":1.91,"tv":1750.23,"id":67083366}],"tv":11847.92}]}
{"op":"mcm","clk":"11952719354","pt":1724517516161,"mc":[{"id":"1.232215600","rc":[{"batb":[[0,1.8,8],[1,1.74,129.25],[2,1.73,83.67]],"ltp":1.91,"tv":1750.23,"id":67083366}]}]}
{"op":"mcm","clk":"11952719901","pt":1724517520281,"mc":[{"id":"1.232215600","rc":[{"batb":[[0,1.76,1.67]],"ltp":1.91,"tv":1750.23,"id":67083366}]}]}
{"op":"mcm","clk":"11952720605","pt":1724517525355,"mc":[{"id":"1.232215600","rc":[{"trd":[[1.74,6.72]],"batb":[[0,1.74,128.83],[1,1.73,83.67],[2,1.72,1288.43]],"batl":[[0,1.9,8.38],[1,1.91,268.1],[2,2.06,1543.83]],"ltp":1.74,"tv":1751.07,"id":67083366}],"tv":11848.76}]}
{"op":"mcm","clk":"11952720827","pt":1724517526988,"mc":[{"id":"1.232215600","rc":[{"batb":[[0,2,16.76],[1,1.9,413.71],[2,1.4,1544]],"ltp":2.08,"tv":10097.69,"id":72857114}]}]}
{"op":"mcm","clk":"11952720952","pt":1724517527989,"mc":[{"id":"1.232215600","rc":[{"trd":[[2.1,0.34]],"ltp":2.1,"tv":10097.79,"id":72857114},{"trd":[[1.9,0.37]],"batl":[[0,1.9,12.46]],"ltp":1.9,"tv":1751.18,"id":67083366}],"tv":11848.97}]}
{"op":"mcm","clk":"11952721048","pt":1724517528792,"mc":[{"id":"1.232215600","rc":[{"batb":[[0,1.8,20.92],[1,1.74,128.83],[2,1.73,83.67]],"ltp":1.9,"tv":1751.18,"id":67083366}]}]}
{"op":"mcm","clk":"11952721564","pt":1724517532679,"mc":[{"id":"1.232215600","rc":[{"batl":[[0,1.87,598.28],[1,1.9,12.46],[2,1.91,268.1]],"ltp":1.9,"tv":1751.18,"id":67083366}]}]}
{"op":"mcm","clk":"11952721866","pt":1724517535381,"mc":[{"id":"1.232215600","rc":[{"trd":[[2.14,1.36]],"ltp":2.14,"tv":10099.15,"id":72857114},{"trd":[[1.87,1.56]],"batl":[[0,1.87,596.72]],"ltp":1.87,"tv":1752.74,"id":67083366}],"tv":11851.89}]}
{"op":"mcm","clk":"11952721966","pt":1724517536176,"mc":[{"id":"1.232215600","rc":[{"batb":[[2,1.73,633.57]],"ltp":1.87,"tv":1752.74,"id":67083366}]}]}
{"op":"mcm","clk":"11952722109","pt":1724517537277,"mc":[{"id":"1.232215600","rc":[{"trd":[[2.14,1.54]],"ltp":2.14,"tv":10099.33,"id":72857114},{"trd":[[1.87,1.77]],"batl":[[0,1.87,596.51],[1,1.9,4.19]],"ltp":1.87,"tv":1752.95,"id":67083366}],"tv":11852.28}]}
{"op":"mcm","clk":"11952722213","pt":1724517538169,"mc":[{"id":"1.232215600","rc":[{"trd":[[2.14,1.64]],"ltp":2.14,"tv":10099.43,"id":72857114},{"trd":[[1.8,0.9],[1.87,1.88]],"batb":[[0,1.8,20.47]],"batl":[[0,1.87,596.4]],"ltp":1.87,"tv":1753.96,"id":67083366}],"tv":11853.4}]}
{"op":"mcm","clk":"11952722361","pt":1724517539174,"mc":[{"id":"1.232215600","rc":[{"batb":[[0,1.8,12.09],[1,1.75,58.16],[2,1.74,128.83]],"ltp":1.87,"tv":1753.96,"id":67083366}]}]}
{"op":"mcm","clk":"11952722475","pt":1724517539958,"mc":[{"id":"1.232215600","rc":[{"batl":[[0,1.83,1453.96],[1,1.87,596.4],[2,1.9,4.19]],"ltp":1.87,"tv":1753.96,"id":67083366}]}]}
{"op":"mcm","clk":"11952722561","pt":1724517540697,"mc":[{"id":"1.232215600","rc":[{"batb":[[0,1.8,3.71]],"ltp":1.87,"tv":1753.96,"id":67083366}]}]}
{"op":"mcm","clk":"11952722697","pt":1724517541785,"mc":[{"id":"1.232215600","rc":[{"batb":[[0,1.75,58.16],[1,1.74,128.83],[2,1.73,83.67]],"batl":[[0,1.8,38.13],[1,1.83,1453.96],[2,1.87,596.4]],"ltp":1.87,"tv":1753.96,"id":67083366}]}]}
{"op":"mcm","clk":"11952722939","pt":1724517544088,"mc":[{"id":"1.232215600","rc":[{"trd":[[2.24,0.1]],"batl":[[0,3.75,3.14]],"ltp":2.24,"tv":10099.52,"id":72857114},{"trd":[[1.8,1.02]],"batl":[[0,1.8,38.01]],"ltp":1.8,"tv":1754.08,"id":67083366}],"tv":11853.61}]}
{"op":"mcm","clk":"11952723000","pt":1724517544694,"mc":[{"id":"1.232215600","rc":[{"trd":[[2.24,0.19]],"ltp":2.24,"tv":10099.62,"id":72857114},{"trd":[[1.8,1.14]],"batl":[[0,1.8,37.89],[2,1.85,245.7]],"ltp":1.8,"tv":1754.2,"id":67083366}],"tv":11853.83}]}
{"op":"mcm","clk":"11952723121","pt":1724517545809,"mc":[{"id":"1.232215600","rc":[{"trd":[[2.24,2.7],[2.3,0.27]],"batl":[[0,3.75,3.07]],"ltp":2.3,"tv":10102.21,"id":72857114},{"trd":[[1.76,0.1],[1.8,4.26]],"batl":[[0,1.8,34.77]],"ltp":1.76,"tv":1757.42,"id":67083366}],"tv":11859.63}]}
{"op":"mcm","clk":"11952723297","pt":1724517547280,"mc":[{"id":"1.232215600","rc":[{"batl":[[0,1.83,1454.59],[1,1.85,245.7],[2,1.87,596.4]],"ltp":1.76,"tv":1757.42,"id":67083366}]}]}
{"op":"mcm","clk":"11952723516","pt":1724517549298,"mc":[{"id":"1.232215600","rc":[{"trd":[[1.8,5.53]],"batb":[[0,1.81,45.77],[1,1.75,58.16],[2,1.74,128.83]],"batl":[[0,1.83,992.42]],"ltp":1.8,"tv":1758.69,"id":67083366}],"tv":11860.9}]}
{"op":"mcm","clk":"11952723662","pt":1724517550398,"mc":[{"id":"1.232215600","rc":[{"trd":[[1.81,16.76]],"batb":[[0,1.81,37.39]],"ltp":1.81,"tv":1775.45,"id":67083366}],"tv":11877.66}]}
{"op":"mcm","clk":"11952723936","pt":1724517552299,"mc":[{"id":"1.232215600","rc":[{"trd":[[2.2,5.03]],"ltp":2.2,"tv":10107.24,"id":72857114},{"trd":[[1.83,6.05]],"batb":[[0,1.81,55.69]],"batl":[[0,1.83,986.37]],"ltp":1.83,"tv":1781.5,"id":67083366}],"tv":11888.74}]}
{"op":"mcm","clk":"11952724003","pt":1724517552894,"mc":[{"id":"1.232215600","rc":[{"batl":[[2,1.87,604.4]],"ltp":1.83,"tv":1781.5,"id":67083366}]}]}
{"op":"mcm","clk":"11952724174","pt":1724517554315,"mc":[{"id":"1.232215600","rc":[{"trd":[[1.81,60.22]],"batb":[[0,1.81,33.96]],"batl":[[1,1.87,604.4],[2,2.1,3212.95]],"ltp":1.81,"tv":1824.96,"id":67083366}],"tv":11932.2}]}
{"op":"mcm","clk":"11952724376","pt":1724517556007,"mc":[{"id":"1.232215600","rc":[{"batl":[[0,2.3,1.4],[1,3.75,2.51]],"ltp":2.2,"tv":10107.24,"id":72857114}]}]}
{"op":"mcm","clk":"11952724497","pt":1724517556981,"mc":[{"id":"1.232215600","rc":[{"trd":[[2.2,5.13]],"batl":[[0,2.3,1.5]],"ltp":2.2,"tv":10107.33,"id":72857114},{"trd":[[1.81,61.31],[1.83,6.17]],"batb":[[0,1.81,33.42]],"batl":[[0,1.83,986.25]],"ltp":1.81,"tv":1826.16,"id":67083366}],"tv":11933.5}]}
{"op":"mcm","clk":"11952724767","pt":1724517559303,"mc":[{"id":"1.232215600","rc":[{"batl":[[1,3.75,2.61]],"ltp":2.2,"tv":10107.33,"id":72857114}]}]}
{"op":"mcm","clk":"11952724855","pt":1724517560194,"mc":[{"id":"1.232215600","rc":[{"trd":[[2.2,5.22]],"ltp":2.2,"tv":10107.43,"id":72857114},{"trd":[[1.83,6.29]],"batl":[[0,1.83,1231.83]],"ltp":1.83,"tv":1826.28,"id":67083366}],"tv":11933.72}]}
{"op":"mcm","clk":"11952725021","pt":1724517562079,"mc":[{"id":"1.232215600","rc":[{"batb":[[1,1.74,128.83],[2,1.73,83.67]],"ltp":1.83,"tv":1826.28,"id":67083366}]}]}
{"op":"mcm","clk":"11952725315","pt":1724517564397,"mc":[{"id":"1.232215600","rc":[{"trd":[[1.81,61.5]],"batb":[[0,1.81,33.32]],"ltp":1.81,"tv":1826.48,"id":67083366}],"tv":11933.91}]}
{"op":"mcm","clk":"11952725422","pt":1724517565292,"mc":[{"id":"1.232215600","rc":[{"trd":[[1.81,61.86]],"batb":[[0,1.81,33.14]],"ltp":1.81,"tv":1826.84,"id":67083366}],"tv":11934.28}]}
{"op":"mcm","clk":"11952725522","pt":1724517566282,"mc":[{"id":"1.232215600","rc":[{"trd":[[1.81,78.62]],"batb":[[0,1.81,24.76],[1,1.8,64.16],[2,1.74,128.83]],"ltp":1.81,"tv":1843.6,"id":67083366}],"tv":11951.04}]}
{"op":"mcm","clk":"11952725702","pt":1724517567315,"mc":[{"id":"1.232215600","rc":[{"trd":[[1.8,37.29],[1.81,128.14]],"batb":[[0,1.8,48.28],[1,1.74,128.83],[2,1.73,83.67]],"batl":[[0,1.83,308.75]],"ltp":1.8,"tv":1924.88,"id":67083366}],"tv":12032.32}]}
{"op":"mcm","clk":"11952726058","pt":1724517569316,"mc":[{"id":"1.232215600","rc":[{"trd":[[2.2,8.21],[2.22,0.36]],"batl":[[0,2.3,1.4]],"ltp":2.2,"tv":10110.78,"id":72857114},{"trd":[[1.81,128.58],[1.83,9.88]],"batl":[[0,1.83,305.16]],"ltp":1.83,"tv":1928.91,"id":67083366}],"tv":12039.7}]}
{"op":"mcm","clk":"11952726208","pt":1724517570107,"mc":[{"id":"1.232215600","rc":[{"batl":[[0,1.83,305.26]],"ltp":1.83,"tv":1928.91,"id":67083366}]}]}
{"op":"mcm","clk":"11952726277","pt":1724517570527,"mc":[{"id":"1.232215600","rc":[{"trd":[[2.2,8.23],[2.22,0.44]],"ltp":2.2,"tv":10110.88,"id":72857114},{"trd":[[1.81,128.68],[1.83,9.9]],"batl":[[0,1.83,305.14]],"ltp":1.83,"tv":1929.03,"id":67083366}],"tv":12039.91}]}
{"op":"mcm","clk":"11952726555","pt":1724517572005,"mc":[{"id":"1.232215600","rc":[{"trd":[[2.2,9.7]],"ltp":2.2,"tv":10112.35,"id":72857114},{"trd":[[1.83,11.67]],"batl":[[0,1.83,303.37]],"ltp":1.83,"tv":1930.8,"id":67083366}],"tv":12043.15}]}
{"op":"mcm","clk":"11952726747","pt":1724517573241,"mc":[{"id":"1.232215600","rc":[{"batl":[[0,3.75,3.17],[1,3.75,0]],"ltp":2.2,"tv":10112.35,"id":72857114},{"batl":[[0,1.81,11.76],[1,1.83,303.37],[2,1.87,604.4]],"ltp":1.83,"tv":1930.8,"id":67083366}]}]}
{"op":"mcm","clk":"11952726910","pt":1724517574333,"mc":[{"id":"1.232215600","rc":[{"trd":[[2.22,1.47]],"ltp":2.22,"tv":10113.38,"id":72857114},{"trd":[[1.81,129.94]],"batl":[[0,1.81,14.69]],"ltp":1.81,"tv":1932.06,"id":67083366}],"tv":12045.44}]}
{"op":"mcm","clk":"11952727020","pt":1724517574916,"mc":[{"id":"1.232215600","rc":[{"trd":[[1.81,150.94],[1.83,49.31]],"batl":[[0,1.83,284.55],[1,1.87,604.4],[2,2.1,3212.95]],"ltp":1.83,"tv":1990.7,"id":67083366}],"tv":12104.08}]}
{"op":"mcm","clk":"11952727366","pt":1724517576927,"mc":[{"id":"1.232215600","rc":[{"trd":[[2.2,9.8]],"ltp":2.2,"tv":10113.48,"id":72857114},{"trd":[[1.83,49.43]],"batl":[[0,1.83,284.43],[2,2.1,3003.76]],"ltp":1.83,"tv":1990.82,"id":67083366}],"tv":12104.3}]}
{"op":"mcm","clk":"11952727550","pt":1724517578236,"mc":[{"id":"1.232215600","rc":[{"trd":[[1.83,51.61]],"batl":[[0,1.83,283.34]],"ltp":1.83,"tv":1993.0,"id":67083366}],"tv":12106.48}]}
{"op":"mcm","clk":"11952727874","pt":1724517580395,"mc":[{"id":"1.232215600","rc":[{"batb":[[1,1.4,1544],[2,1.4,0]],"ltp":2.2,"tv":10113.48,"id":72857114},{"batl":[[2,2.1,3.76]],"ltp":1.83,"tv":1993.0,"id":67083366}]}]}
{"op":"mcm","clk":"11952727979","pt":1724517581143,"mc":[{"id":"1.232215600","rc":[{"batb":[[0,1.8,15.05]],"ltp":1.83,"tv":1993.0,"id":67083366}]}]}
{"op":"mcm","clk":"11952728045","pt":1724517581513,"mc":[{"id":"1.232215600","rc":[{"trd":[[2.2,10.89]],"ltp":2.2,"tv":10114.56,"id":72857114},{"trd":[[1.83,52.92]],"batl":[[0,1.83,282.03]],"ltp":1.83,"tv":1994.31,"id":67083366}],"tv":12108.88}]}
{"op":"mcm","clk":"11952728784","pt":1724517586737,"mc":[{"id":"1.232215600","rc":[{"trd":[[2.2,10.99]],"ltp":2.2,"tv":10114.66,"id":72857114},{"trd":[[1.83,53.04]],"batl":[[0,1.83,281.91]],"ltp":1.83,"tv":1994.43,"id":67083366}],"tv":12109.09}]}
{"op":"mcm","clk":"11952729005","pt":1724517588411,"mc":[{"id":"1.232215600","rc":[{"batb":[[0,1.83,871.94],[1,1.8,15.05],[2,1.74,128.83]],"batl":[[0,1.87,604.4],[1,2.1,3.76],[2,2.1,0]],"ltp":1.83,"tv":1994.43,"id":67083366}]}]}
{"op":"mcm","clk":"11952729110","pt":1724517589051,"mc":[{"id":"1.232215600","rc":[{"batl":[[0,2.2,4.19],[1,3.75,3.17]],"ltp":2.2,"tv":10114.66,"id":72857114}]}]}
{"op":"mcm","clk":"11952729404","pt":1724517591149,"mc":[{"id":"1.232215600","rc":[{"batb":[[0,1.83,1111.94]],"ltp":1.83,"tv":1994.43,"id":67083366}]}]}
{"op":"mcm","clk":"11952729569","pt":1724517592288,"mc":[{"id":"1.232215600","rc":[{"batl":[[0,2.2,4.29]],"ltp":2.2,"tv":10114.66,"id":72857114}]}]}
{"op":"mcm","clk":"11952729805","pt":1724517593645,"mc":[{"id":"1.232215600","rc":[{"batb":[[1,1.4,0]],"ltp":2.2,"tv":10114.66,"id":72857114},{"batb":[[0,1.83,1174.34]],"ltp":1.83,"tv":1994.43,"id":67083366}]}]}
{"op":"mcm","clk":"11952729966","pt":1724517594649,"mc":[{"id":"1.232215600","rc":[{"trd":[[1.83,61.42]],"batb":[[0,1.83,1170.15],[1,1.8,16.66]],"ltp":1.83,"tv":2002.81,"id":67083366}],"tv":12117.47}]}
{"op":"mcm","clk":"11952730140","pt":1724517596184,"mc":[{"id":"1.232215600","rc":[{"batl":[[0,2.2,6.8]],"ltp":2.2,"tv":10114.66,"id":72857114}]}]}
{"op":"mcm","clk":"11952730194","pt":1724517596707,"mc":[{"id":"1.232215600","rc":[{"batb":[[0,1.83,1107.75]],"ltp":1.83,"tv":2002.81,"id":67083366}]}]}
{"op":"mcm","clk":"11952730333","pt":1724517597874,"mc":[{"id":"1.232215600","rc":[{"batl":[[0,2.2,6.96]],"ltp":2.2,"tv":10114.66,"id":72857114}]}]}
{"op":"mcm","clk":"11952730499","pt":1724517599085,"mc":[{"id":"1.232215600","rc":[{"batl":[[0,1.85,8],[1,1.87,8],[2,2.1,3.76]],"ltp":1.83,"tv":2002.81,"id":67083366}]}]}
{"op":"mcm","clk":"11952730616","pt":1724517599983,"mc":[{"id":"1.232215600","rc":[{"trd":[[2.16,0.1]],"batb":[[1,1.91,84.51]],"ltp":2.16,"tv":10114.76,"id":72857114},{"trd":[[1.85,0.11]],"batl":[[0,1.85,7.89],[1,2.1,3.76],[2,2.1,0]],"ltp":1.85,"tv":2002.92,"id":67083366}],"tv":12117.68}]}
{"op":"mcm","clk":"11952730766","pt":1724517601399,"mc":[{"id":"1.232215600","rc":[{"batl":[[0,2.1,3.76],[1,2.1,0]],"ltp":1.85,"tv":2002.92,"id":67083366}]}]}
{"op":"mcm","clk":"11952730884","pt":1724517602565,"mc":[{"id":"1.232215600","rc":[{"batb":[[0,1.87,62.4],[1,1.83,1107.75],[2,1.8,16.66]],"ltp":1.85,"tv":2002.92,"id":67083366}]}]}
{"op":"mcm","clk":"11952731102","pt":1724517604380,"mc":[{"id":"1.232215600","rc":[{"batl":[[0,2.2,7.28]],"ltp":2.16,"tv":10114.76,"id":72857114},{"trd":[[1.87,2.08]],"batb":[[0,1.87,62.3]],"ltp":1.87,"tv":2003.11,"id":67083366}],"tv":12117.88}]}
{"op":"mcm","clk":"11952731217","pt":1724517605289,"mc":[{"id":"1.232215600","rc":[{"trd":[[1.87,11.18]],"batb":[[0,1.87,57.75],[1,1.83,1353.45]],"ltp":1.87,"tv":2012.22,"id":67083366}],"tv":12126.98}]}
{"op":"mcm","clk":"11952731322","pt":1724517605985,"mc":[{"id":"1.232215600","rc":[{"batb":[[0,1.87,99.59],[1,1.83,1113.45]],"ltp":1.87,"tv":2012.22,"id":67083366}]}]}
{"op":"mcm","clk":"11952731691","pt":1724517608786,"mc":[{"id":"1.232215600","rc":[{"trd":[[1.87,11.38]],"batb":[[0,1.87,99.49],[1,1.83,867.75]],"ltp":1.87,"tv":2012.41,"id":67083366}],"tv":12127.18}]}
{"op":"mcm","clk":"11952731867","pt":1724517610413,"mc":[{"id":"1.232215600","rc":[{"trd":[[1.87,12.53]],"batb":[[0,1.87,98.91]],"ltp":1.87,"tv":2013.57,"id":67083366}],"tv":12128.33}]}
{"op":"mcm","clk":"11952732046","pt":1724517611590,"mc":[{"id":"1.232215600","rc":[{"batb":[[0,1.87,64.09]],"ltp":1.87,"tv":2013.57,"id":67083366}]}]}
{"op":"mcm","clk":"11952732271","pt":1724517613171,"mc":[{"id":"1.232215600","rc":[{"trd":[[1.87,13.26]],"batb":[[0,1.87,63.73],[1,1.8,16.66],[2,1.74,128.83]],"batl":[[0,1.94,8.38],[1,2.1,3.76]],"ltp":1.87,"tv":2014.29,"id":67083366}],"tv":12129.06}]}
{"op":"mcm","clk":"11952732550","pt":1724517615384,"mc":[{"id":"1.232215600","rc":[{"batl":[[0,2.2,6.96]],"ltp":2.16,"tv":10114.76,"id":72857114},{"batl":[[0,1.93,598.28],[1,1.94,8.38],[2,2.1,3.76]],"ltp":1.87,"tv":2014.29,"id":67083366}]}]}
{"op":"mcm","clk":"11952732717","pt":1724517616611,"mc":[{"id":"1.232215600","rc":[{"batl":[[2,1.96,1.6]],"ltp":1.87,"tv":2014.29,"id":67083366}]}]}
{"op":"mcm","clk":"11952733040","pt":1724517619023,"mc":[{"id":"1.232215600","rc":[{"trd":[[1.87,14.44]],"batb":[[0,1.87,63.14],[2,1.73,83.67]],"ltp":1.87,"tv":2015.47,"id":67083366}],"tv":12130.24}]}
{"op":"mcm","clk":"11952733211","pt":1724517620396,"mc":[{"id":"1.232215600","rc":[{"trd":[[1.87,57.04]],"batb":[[0,1.8,16.66],[1,1.73,83.67],[2,1.7,2]],"batl":[[0,1.87,587.48],[1,1.93,598.28],[2,1.94,8.38]],"ltp":1.87,"tv":2058.07,"id":67083366}],"tv":12172.84}]}
{"op":"mcm","clk":"11952733408","pt":1724517622000,"mc":[{"id":"1.232215600","rc":[{"batl":[[0,1.87,587.58]],"ltp":1.87,"tv":2058.07,"id":67083366}]}]}
{"op":"mcm","clk":"11952733827","pt":1724517624914,"mc":[{"id":"1.232215600","rc":[{"batl":[[0,1.87,6.38]],"ltp":1.87,"tv":2058.07,"id":67083366}]}]}
{"op":"mcm","clk":"11952734023","pt":1724517626438,"mc":[{"id":"1.232215600","rc":[{"batb":[[0,2.16,2.51],[1,2,16.76],[2,1.91,84.51]],"ltp":2.16,"tv":10114.76,"id":72857114}]}]}
{"op":"mcm","clk":"11952734272","pt":1724517628256,"mc":[{"id":"1.232215600","rc":[{"batl":[[0,1.87,6.47]],"ltp":1.87,"tv":2058.07,"id":67083366}]}]}
{"op":"mcm","clk":"11952734413","pt":1724517629311,"mc":[{"id":"1.232215600","rc":[{"trd":[[2.16,2.7]],"batb":[[0,2,16.76],[1,1.91,84.51],[2,1.91,0]],"ltp":2.16,"tv":10117.37,"id":72857114},{"trd":[[1.87,73.04]],"batb":[[0,1.87,230.49],[1,1.8,16.66],[2,1.73,83.67]],"batl":[[0,1.93,598.28],[1,1.94,8.38],[2,1.96,1.6]],"ltp":1.87,"tv":2074.07,"id":67083366}],"tv":12191.44}]}
{"op":"mcm","clk":"11952734517","pt":1724517630306,"mc":[{"id":"1.232215600","rc":[{"batb":[[1,1.84,4.19],[2,1.8,16.66]],"ltp":1.87,"tv":2074.07,"id":67083366}]}]}
{"op":"mcm","clk":"11952734564","pt":1724517630725,"mc":[{"id":"1.232215600","rc":[{"trd":[[1.87,74.86]],"batb":[[0,1.87,291.98]],"ltp":1.87,"tv":2075.89,"id":67083366}],"tv":12193.26}]}
{"op":"mcm","clk":"11952734700","pt":1724517631620,"mc":[{"id":"1.232215600","rc":[{"trd":[[2.16,6.43]],"ltp":2.16,"tv":10121.1,"id":72857114},{"trd":[[1.87,79.17]],"batb":[[0,1.87,287.67]],"ltp":1.87,"tv":2080.2,"id":67083366}],"tv":12201.3}]}
{"op":"mcm","clk":"11952735043","pt":1724517634335,"mc":[{"id":"1.232215600","rc":[{"batl":[[0,2.2,7.8]],"ltp":2.16,"tv":10121.1,"id":72857114}]}]}
{"op":"mcm","clk":"11952735161","pt":1724517635337,"mc":[{"id":"1.232215600","rc":[{"batl":[[2,2.1,3.86]],"ltp":1.87,"tv":2080.2,"id":67083366}]}]}
{"op":"mcm","clk":"11952735405","pt":1724517637157,"mc":[{"id":"1.232215600","rc":[{"batl":[[0,2.2,7.9]],"ltp":2.16,"tv":10121.1,"id":72857114},{"trd":[[1.87,79.36]],"batb":[[0,1.87,287.57]],"batl":[[0,1.9,644.34],[1,1.93,598.28],[2,1.94,8.38]],"ltp":1.87,"tv":2080.4,"id":67083366}],"tv":12201.5}]}
{"op":"mcm","clk":"11952735567","pt":1724517638305,"mc":[{"id":"1.232215600","rc":[{"batl":[[0,2.14,1.17],[1,2.2,7.06],[2,3.75,3.17]],"ltp":2.16,"tv":10121.1,"id":72857114}]}]}
{"op":"mcm","clk":"11952735698","pt":1724517639306,"mc":[{"id":"1.232215600","rc":[{"trd":[[1.9,0.57]],"batl":[[0,1.9,644.24],[1,1.91,55.38],[2,1.93,598.28]],"ltp":1.9,"tv":2080.6,"id":67083366}],"tv":12201.7}]}
{"op":"mcm","clk":"11952735758","pt":1724517639832,"mc":[{"id":"1.232215600","rc":[{"trd":[[1.87,79.56]],"batb":[[0,1.87,287.47]],"ltp":1.87,"tv":2080.79,"id":67083366}],"tv":12201.89}]}
{"op":"mcm","clk":"11952735907","pt":1724517641317,"mc":[{"id":"1.232215600","rc":[{"trd":[[1.87,79.95]],"batb":[[0,1.87,287.27]],"ltp":1.87,"tv":2081.19,"id":67083366}],"tv":12202.29}]}
{"op":"mcm","clk":"11952735996","pt":1724517642012,"mc":[{"id":"1.232215600","rc":[{"batl":[[0,2.2,7.9],[1,3.75,3.17],[2,3.75,0]],"ltp":2.16,"tv":10121.1,"id":72857114}]}]}
{"op":"mcm","clk":"11952736140","pt":1724517643217,"mc":[{"id":"1.232215600","rc":[{"trd":[[1.87,80.32]],"batb":[[0,1.87,287.09]],"batl":[[0,1.91,55.48],[1,1.93,598.28],[2,1.94,8.38]],"ltp":1.87,"tv":2081.55,"id":67083366}],"tv":12202.65}]}
{"op":"mcm","clk":"11952736212","pt":1724517643847,"mc":[{"id":"1.232215600","rc":[{"trd":[[2.12,3.64],[2.14,3.32],[2.16,7.72]],"batl":[[0,2.2,6.96]],"ltp":2.16,"tv":10127.47,"id":72857114},{"trd":[[1.87,81.58]],"batb":[[0,1.87,285.83]],"ltp":1.87,"tv":2082.81,"id":67083366}],"tv":12210.28}]}
{"op":"mcm","clk":"11952736358","pt":1724517644847,"mc":[{"id":"1.232215600","rc":[{"trd":[[2.08,0.6]],"ltp":2.08,"tv":10127.56,"id":72857114},{"trd":[[1.87,86.5],[1.91,128.13]],"batb":[[0,1.87,283.37]],"batl":[[0,1.91,55.37]],"ltp":1.91,"tv":2087.84,"id":67083366}],"tv":12215.41}]}
{"op":"mcm","clk":"11952736660","pt":1724517647355,"mc":[{"id":"1.232215600","rc":[{"trd":[[1.87,86.88]],"batb":[[0,1.87,283.02]],"batl":[[1,1.93,606.65]],"ltp":1.87,"tv":2088.23,"id":67083366}],"tv":12215.79}]}
{"op":"mcm","clk":"11952736764","pt":1724517648308,"mc":[{"id":"1.232215600","rc":[{"batl":[[1,1.92,644.24],[2,1.93,606.65]],"ltp":1.87,"tv":2088.23,"id":67083366}]}]}
{"op":"mcm","clk":"11952736787","pt":1724517648523,"mc":[{"id":"1.232215600","rc":[{"trd":[[2.16,11.91]],"ltp":2.16,"tv":10131.75,"id":72857114},{"trd":[[1.87,91.72]],"batb":[[0,1.87,278.18]],"ltp":1.87,"tv":2093.07,"id":67083366}],"tv":12224.82}]}
{"op":"mcm","clk":"11952737020","pt":1724517650216,"mc":[{"id":"1.232215600","rc":[{"trd":[[2.16,12.75]],"batl":[[0,2.2,7.06]],"ltp":2.16,"tv":10132.59,"id":72857114},{"trd":[[1.87,92.69]],"batb":[[0,1.87,277.21]],"ltp":1.87,"tv":2094.04,"id":67083366}],"tv":12226.63}]}
{"op":"mcm","clk":"11952737039","pt":1724517650421,"mc":[{"id":"1.232215600","rc":[{"trd":[[2.1,0.42]],"batl":[[0,2.2,6.97]],"ltp":2.1,"tv":10132.68,"id":72857114},{"trd":[[1.9,0.66]],"ltp":1.9,"tv":2094.13,"id":67083366}],"tv":12226.82}]}
{"op":"mcm","clk":"11952737251","pt":1724517652315,"mc":[{"id":"1.232215600","rc":[{"trd":[[2.1,0.43]],"batl":[[0,2.2,2.77]],"ltp":2.1,"tv":10132.69,"id":72857114},{"trd":[[1.87,92.87],[1.9,0.67]],"batb":[[0,1.87,277.12]],"ltp":1.87,"tv":2094.32,"id":67083366}],"tv":12227.02}]}
{"op":"mcm","clk":"11952737329","pt":1724517653043,"mc":[{"id":"1.232215600","rc":[{"trd":[[2.1,0.53]],"ltp":2.1,"tv":10132.79,"id":72857114},{"trd":[[1.87,109.63],[1.9,0.78]],"batb":[[0,1.87,268.74]],"batl":[[0,1.89,8.27],[1,1.91,55.37],[2,1.92,644.24]],"ltp":1.87,"tv":2111.19,"id":67083366}],"tv":12243.98}]}
{"op":"mcm","clk":"11952737594","pt":1724517655216,"mc":[{"id":"1.232215600","rc":[{"batl":[[0,3.75,3.43],[1,3.75,0]],"ltp":2.1,"tv":10132.79,"id":72857114}]}]}
{"op":"mcm","clk":"11952737743","pt":1724517656272,"mc":[{"id":"1.232215600","rc":[{"trd":[[2.12,3.74]],"ltp":2.12,"tv":10132.88,"id":72857114},{"trd":[[1.89,0.11]],"batl":[[0,1.89,8.16]],"ltp":1.89,"tv":2111.3,"id":67083366}],"tv":12244.19}]}
{"op":"mcm","clk":"11952737871","pt":1724517657309,"mc":[{"id":"1.232215600","rc":[{"trd":[[2.12,4.11]],"ltp":2.12,"tv":10133.25,"id":72857114},{"trd":[[1.89,0.52]],"batb":[[0,1.87,268.84]],"batl":[[0,1.89,7.75]],"ltp":1.89,"tv":2111.71,"id":67083366}],"tv":12244.97}]}
{"op":"mcm","clk":"11952737942","pt":1724517657887,"mc":[{"id":"1.232215600","rc":[{"trd":[[2.16,54.64]],"ltp":2.16,"tv":10175.14,"id":72857114},{"trd":[[1.87,158.4]],"batb":[[0,1.87,220.26]],"ltp":1.87,"tv":2160.48,"id":67083366}],"tv":12335.63}]}
{"op":"mcm","clk":"11952738214","pt":1724517660300,"mc":[{"id":"1.232215600","rc":[{"trd":[[1.87,158.99]],"batb":[[0,1.87,219.96]],"ltp":1.87,"tv":2161.08,"id":67083366}],"tv":12336.22}]}
{"op":"mcm","clk":"11952738556","pt":1724517663001,"mc":[{"id":"1.232215600","rc":[{"trd":[[1.89,0.72]],"batl":[[0,1.89,7.65]],"ltp":1.89,"tv":2161.27,"id":67083366}],"tv":12336.42}]}
{"op":"mcm","clk":"11952739019","pt":1724517666306,"mc":[{"id":"1.232215600","rc":[{"trd":[[2.16,54.74]],"ltp":2.16,"tv":10175.24,"id":72857114},{"trd":[[1.87,159.25]],"batb":[[0,1.87,219.78]],"ltp":1.87,"tv":2161.53,"id":67083366}],"tv":12336.77}]}
{"op":"mcm","clk":"11952739158","pt":1724517667407,"mc":[{"id":"1.232215600","rc":[{"trd":[[2.12,4.2]],"ltp":2.12,"tv":10175.33,"id":72857114},{"trd":[[1.87,164.46],[1.89,0.83]],"batb":[[0,1.87,217.17]],"batl":[[0,1.89,7.54]],"ltp":1.87,"tv":2166.85,"id":67083366}],"tv":12342.19}]}
{"op":"mcm","clk":"11952739243","pt":1724517668195,"mc":[{"id":"1.232215600","rc":[{"trd":[[2.12,8.39]],"ltp":2.12,"tv":10179.52,"id":72857114},{"trd":[[1.89,5.53]],"batl":[[0,1.89,2.84],[1,1.9,55.38],[2,1.91,55.37]],"ltp":1.89,"tv":2171.55,"id":67083366}],"tv":12351.08}]}
{"op":"mcm","clk":"11952739320","pt":1724517668908,"mc":[{"id":"1.232215600","rc":[{"trd":[[2.16,96.63]],"ltp":2.16,"tv":10221.41,"id":72857114},{"trd":[[1.87,212.85]],"batb":[[0,1.87,168.78]],"batl":[[1,1.9,713.27]],"ltp":1.87,"tv":2219.94,"id":67083366}],"tv":12441.36}]}
{"op":"mcm","clk":"11952739445","pt":1724517669984,"mc":[{"id":"1.232215600","rc":[{"trd":[[1.87,212.98]],"batb":[[0,1.87,168.72]],"ltp":1.87,"tv":2220.07,"id":67083366}],"tv":12441.48}]}
{"op":"mcm","clk":"11952739611","pt":1724517671513,"mc":[{"id":"1.232215600","rc":[{"trd":[[2.2,11.25]],"batl":[[0,3.75,3.17]],"ltp":2.2,"tv":10221.67,"id":72857114},{"trd":[[1.83,61.73],[1.84,8.38],[1.87,213.17]],"batb":[[0,1.8,16.66],[1,1.73,83.67],[2,1.7,2]],"batl":[[0,1.81,14578.83],[1,1.87,3581.28],[2,1.89,2.84]],"ltp":1.83,"tv":2228.95,"id":67083366}],"tv":12450.63}]}
{"op":"mcm","clk":"11952740049","pt":1724517675262,"mc":[{"id":"1.232215600","rc":[{"batl":[[1,1.87,3624.34]],"ltp":1.83,"tv":2228.95,"id":67083366}]}]}
{"op":"mcm","clk":"11952740199","pt":1724517676409,"mc":[{"id":"1.232215600","rc":[{"trd":[[2.22,1.57]],"ltp":2.22,"tv":10221.77,"id":72857114},{"trd":[[1.81,151.06]],"batl":[[0,1.81,14578.71],[1,1.87,3624.44]],"ltp":1.81,"tv":2229.07,"id":67083366}],"tv":12450.85}]}
{"op":"mcm","clk":"11952740363","pt":1724517677735,"mc":[{"id":"1.232215600","rc":[{"trd":[[1.81,163.62]],"batl":[[0,1.81,14572.43]],"ltp":1.81,"tv":2241.63,"id":67083366}],"tv":12463.41}]}
{"op":"mcm","clk":"11952740483","pt":1724517678834,"mc":[{"id":"1.232215600","rc":[{"batl":[[1,1.87,43.25]],"ltp":1.81,"tv":2241.63,"id":67083366}]}]}
{"op":"mcm","clk":"11952740587","pt":1724517679831,"mc":[{"id":"1.232215600","rc":[{"batl":[[1,1.87,42.08]],"ltp":1.81,"tv":2241.63,"id":67083366}]}]}
{"op":"mcm","clk":"11952740749","pt":1724517681331,"mc":[{"id":"1.232215600","rc":[{"batl":[[1,1.87,44.08]],"ltp":1.81,"tv":2241.63,"id":67083366}]}]}
{"op":"mcm","clk":"11952740849","pt":1724517682132,"mc":[{"id":"1.232215600","rc":[{"trd":[[1.8,70.61]],"batb":[[0,1.73,83.67],[1,1.7,2],[2,1.55,1099.8]],"batl":[[0,1.8,14566.67],[1,1.81,14572.43],[2,1.87,43.98]],"ltp":1.8,"tv":2274.95,"id":67083366}],"tv":12496.73}]}
{"op":"mcm","clk":"11952740962","pt":1724517683132,"mc":[{"id":"1.232215600","rc":[{"trd":[[1.8,390.61]],"batl":[[0,1.8,14406.67]],"ltp":1.8,"tv":2594.95,"id":67083366}],"tv":12816.73}]}
{"op":"mcm","clk":"11952741015","pt":1724517683555,"mc":[{"id":"1.232215600","rc":[{"trd":[[2.24,2.8]],"ltp":2.24,"tv":10221.87,"id":72857114},{"trd":[[1.8,390.73]],"batl":[[0,1.8,14406.55]],"ltp":1.8,"tv":2595.07,"id":67083366}],"tv":12816.95}]}
{"op":"mcm","clk":"11952741256","pt":1724517685246,"mc":[{"id":"1.232215600","rc":[{"trd":[[1.8,1030.05]],"batl":[[0,1.8,14086.89]],"ltp":1.8,"tv":3234.39,"id":67083366}],"tv":13456.27}]}
{"op":"mcm","clk":"11952741512","pt":1724517687252,"mc":[{"id":"1.232215600","rc":[{"trd":[[2.24,5.31]],"ltp":2.24,"tv":10224.38,"id":72857114},{"trd":[[1.8,1033.17]],"batl":[[0,1.8,14591.58]],"ltp":1.8,"tv":3237.51,"id":67083366}],"tv":13461.9}]}
{"op":"mcm","clk":"11952741565","pt":1724517687663,"mc":[{"id":"1.232215600","rc":[{"trd":[[1.8,1074.77]],"batb":[[1,1.72,55.38],[2,1.7,2]],"batl":[[0,1.8,14570.78]],"ltp":1.8,"tv":3279.11,"id":67083366}],"tv":13503.5}]}
{"op":"mcm","clk":"11952741795","pt":1724517689252,"mc":[{"id":"1.232215600","rc":[{"batb":[[0,2.26,3.35],[1,2,16.76],[2,1.91,84.51]],"ltp":2.24,"tv":10224.38,"id":72857114},{"batl":[[0,1.8,14570.88]],"ltp":1.8,"tv":3279.11,"id":67083366}]}]}
{"op":"mcm","clk":"11952741939","pt":1724517690252,"mc":[{"id":"1.232215600","rc":[{"trd":[[2.26,0.36]],"batb":[[0,2.26,3.17]],"ltp":2.26,"tv":10224.74,"id":72857114},{"batl":[[0,1.8,14068.27]],"ltp":1.8,"tv":3279.11,"id":67083366}],"tv":13503.86}]}
{"op":"mcm","clk":"11952742121","pt":1724517691637,"mc":[{"id":"1.232215600","rc":[{"trd":[[1.8,1074.97]],"batl":[[0,1.8,14068.17]],"ltp":1.8,"tv":3279.31,"id":67083366}],"tv":13504.05}]}
{"op":"mcm","clk":"11952742348","pt":1724517693372,"mc":[{"id":"1.232215600","rc":[{"trd":[[1.8,1076.65]],"batl":[[0,1.8,14067.23]],"ltp":1.8,"tv":3280.99,"id":67083366}],"tv":13505.73}]}
{"op":"mcm","clk":"11952742597","pt":1724517695568,"mc":[{"id":"1.232215600","rc":[{"batl":[[0,1.8,14067.33]],"ltp":1.8,"tv":3280.99,"id":67083366}]}]}
{"op":"mcm","clk":"11952742794","pt":1724517697147,"mc":[{"id":"1.232215600","rc":[{"trd":[[2.24,6.33]],"batb":[[0,2,16.76],[1,1.91,84.51],[2,1.91,0]],"ltp":2.24,"tv":10225.76,"id":72857114},{"trd":[[1.8,1285.92]],"batl":[[0,1.8,13956.86]],"ltp":1.8,"tv":3490.26,"id":67083366}],"tv":13716.02}]}
{"op":"mcm","clk":"11952742948","pt":1724517698366,"mc":[{"id":"1.232215600","rc":[{"trd":[[2.24,6.44]],"ltp":2.24,"tv":10225.87,"id":72857114},{"trd":[[1.8,1286.06]],"batb":[[0,1.76,69.23],[1,1.74,4.19],[2,1.73,83.67]],"batl":[[0,1.8,13956.72]],"ltp":1.8,"tv":3490.4,"id":67083366}],"tv":13716.27}]}
{"op":"mcm","clk":"11952743020","pt":1724517698948,"mc":[{"id":"1.232215600","rc":[{"trd":[[2.24,8.95]],"ltp":2.24,"tv":10228.38,"id":72857114},{"trd":[[1.8,1289.18]],"batl":[[0,1.8,13953.6]],"ltp":1.8,"tv":3493.52,"id":67083366}],"tv":13721.9}]}
{"op":"mcm","clk":"11952743157","pt":1724517700163,"mc":[{"id":"1.232215600","rc":[{"trd":[[1.8,3916.88]],"batb":[[0,1.76,143.9]],"batl":[[0,1.8,12639.75],[2,1.87,2.09]],"ltp":1.8,"tv":6121.22,"id":67083366}],"tv":16349.6}]}
{"op":"mcm","clk":"11952743293","pt":1724517701171,"mc":[{"id":"1.232215600","rc":[{"trd":[[1.76,2.44]],"batb":[[0,1.76,142.73]],"ltp":1.76,"tv":6123.56,"id":67083366}],"tv":16351.94}]}
{"op":"mcm","clk":"11952743450","pt":1724517702186,"mc":[{"id":"1.232215600","rc":[{"trd":[[2.24,9.08]],"ltp":2.24,"tv":10228.51,"id":72857114},{"trd":[[1.8,3917.04]],"batl":[[0,1.8,12639.59]],"ltp":1.8,"tv":6123.72,"id":67083366}],"tv":16352.23}]}
{"op":"mcm","clk":"11952743584","pt":1724517703127,"mc":[{"id":"1.232215600","rc":[{"batl":[[0,3.75,3.3]],"ltp":2.24,"tv":10228.51,"id":72857114}]}]}
{"op":"mcm","clk":"11952743626","pt":1724517703447,"mc":[{"id":"1.232215600","rc":[{"batb":[[0,1.76,74.67]],"ltp":1.8,"tv":6123.72,"id":67083366}]}]}
{"op":"mcm","clk":"11952743998","pt":1724517706178,"mc":[{"id":"1.232215600","rc":[{"trd":[[1.8,3935.32]],"batl":[[0,1.8,12630.45]],"ltp":1.8,"tv":6142.0,"id":67083366}],"tv":16370.51}]}
{"op":"mcm","clk":"11952744078","pt":1724517706754,"mc":[{"id":"1.232215600","rc":[{"trd":[[2.26,0.44]],"batl":[[0,3.75,3.23]],"ltp":2.26,"tv":10228.58,"id":72857114},{"trd":[[1.79,0.1]],"ltp":1.79,"tv":6142.1,"id":67083366}],"tv":16370.68}]}
{"op":"mcm","clk":"11952744307","pt":1724517708349,"mc":[{"id":"1.232215600","rc":[{"trd":[[2.26,0.5]],"batl":[[0,3.75,3.17]],"ltp":2.26,"tv":10228.64,"id":72857114},{"trd":[[1.78,0.04],[1.79,0.17],[1.8,3938.12]],"batl":[[0,1.8,12629.05]],"ltp":1.8,"tv":6145.01,"id":67083366}],"tv":16373.66}]}
{"op":"mcm","clk":"11952744383","pt":1724517709244,"mc":[{"id":"1.232215600","rc":[{"batb":[[0,1.74,4.19],[1,1.73,83.67],[2,1.7,2]],"ltp":1.8,"tv":6145.01,"id":67083366}]}]}
{"op":"mcm","clk":"11952744457","pt":1724517709760,"mc":[{"id":"1.232215600","rc":[{"trd":[[2.3,0.83]],"batl":[[0,3.75,2.61]],"ltp":2.3,"tv":10229.2,"id":72857114},{"trd":[[1.76,3.17]],"batl":[[0,1.76,4.47],[1,1.8,12629.05],[2,1.81,14572.43]],"ltp":1.76,"tv":6145.74,"id":67083366}],"tv":16374.95}]}
{"op":"mcm","clk":"11952744604","pt":1724517710763,"mc":[{"id":"1.232215600","rc":[{"batb":[[0,1.73,83.67],[1,1.7,2],[2,1.55,1099.8]],"ltp":1.76,"tv":6145.74,"id":67083366}]}]}
{"op":"mcm","clk":"11952744805","pt":1724517712353,"mc":[{"id":"1.232215600","rc":[{"trd":[[1.76,3.53]],"batl":[[0,1.76,4.29],[1,1.8,12628.95]],"ltp":1.76,"tv":6146.11,"id":67083366}],"tv":16375.31}]}
{"op":"mcm","clk":"11952744907","pt":1724517713248,"mc":[{"id":"1.232215600","rc":[{"trd":[[1.8,6515.48]],"batb":[[0,1.78,70.38],[1,1.73,83.67],[2,1.7,2]],"batl":[[0,1.8,11340.27],[1,1.81,14572.43],[2,1.87,2.09]],"ltp":1.8,"tv":8723.47,"id":67083366}],"tv":18952.67}]}
{"op":"mcm","clk":"11952745141","pt":1724517715147,"mc":[{"id":"1.232215600","rc":[{"trd":[[1.8,6517.16]],"batb":[[0,1.78,69.55]],"batl":[[0,1.8,11339.43]],"ltp":1.8,"tv":8725.15,"id":67083366}],"tv":18954.35}]}
{"op":"mcm","clk":"11952745246","pt":1724517716045,"mc":[{"id":"1.232215600","rc":[{"trd":[[1.78,42.08],[1.8,6643.56]],"batb":[[0,1.78,48.53]],"batl":[[0,1.8,11276.23]],"ltp":1.78,"tv":8893.58,"id":67083366}],"tv":19122.79}]}
{"op":"mcm","clk":"11952745451","pt":1724517717771,"mc":[{"id":"1.232215600","rc":[{"batl":[[2,1.9,4.64]],"ltp":1.78,"tv":8893.58,"id":67083366}]}]}
{"op":"mcm","clk":"11952745737","pt":1724517720186,"mc":[{"id":"1.232215600","rc":[{"trd":[[2.24,9.17]],"batl":[[0,3.75,2.7]],"ltp":2.24,"tv":10229.3,"id":72857114},{"trd":[[1.78,42.28],[1.8,6643.68]],"batb":[[0,1.78,48.43]],"batl":[[0,1.8,11276.11]],"ltp":1.78,"tv":8893.9,"id":67083366}],"tv":19123.2}]}
{"op":"mcm","clk":"11952745981","pt":1724517722365,"mc":[{"id":"1.232215600","rc":[{"batb":[[2,1.7,1466.33]],"ltp":1.78,"tv":8893.9,"id":67083366}]}]}
{"op":"mcm","clk":"11952746039","pt":1724517722891,"mc":[{"id":"1.232215600","rc":[{"batb":[[1,1.76,332.26],[2,1.73,83.67]],"ltp":1.78,"tv":8893.9,"id":67083366}]}]}
{"op":"mcm","clk":"11952746143","pt":1724517723894,"mc":[{"id":"1.232215600","rc":[{"trd":[[1.78,42.47]],"batb":[[0,1.78,48.33],[1,1.76,339.37]],"ltp":1.78,"tv":8894.1,"id":67083366}],"tv":19123.4}]}
{"op":"mcm","clk":"11952746412","pt":1724517726368,"mc":[{"id":"1.232215600","rc":[{"trd":[[1.8,6685.28]],"batl":[[0,1.8,11255.31]],"ltp":1.8,"tv":8935.7,"id":67083366}],"tv":19165.0}]}
{"op":"mcm","clk":"11952746501","pt":1724517727118,"mc":[{"id":"1.232215600","rc":[{"trd":[[1.78,47.92]],"batb":[[0,1.78,45.61]],"ltp":1.78,"tv":8941.14,"id":67083366}],"tv":19170.44}]}
{"op":"mcm","clk":"11952746597","pt":1724517727799,"mc":[{"id":"1.232215600","rc":[{"trd":[[2.26,0.67]],"ltp":2.26,"tv":10229.47,"id":72857114},{"trd":[[1.79,0.39]],"batl":[[0,1.79,1.45],[1,1.8,11255.31],[2,1.81,14572.43]],"ltp":1.79,"tv":8941.36,"id":67083366}],"tv":19170.84}]}
{"op":"mcm","clk":"11952746787","pt":1724517729291,"mc":[{"id":"1.232215600","rc":[{"trd":[[2.3,0.93]],"batl":[[0,3.75,2.61]],"ltp":2.3,"tv":10229.57,"id":72857114},{"trd":[[1.76,17.88]],"batb":[[0,1.73,83.67],[1,1.7,1466.33],[2,1.55,1099.8]],"batl":[[0,1.76,148.22],[1,1.79,1.45],[2,1.8,11255.31]],"ltp":1.76,"tv":8955.71,"id":67083366}],"tv":19185.28}]}
{"op":"mcm","clk":"11952746929","pt":1724517730293,"mc":[{"id":"1.232215600","rc":[{"batb":[[0,2.3,2.51],[1,2,16.76],[2,1.91,84.51]],"ltp":2.3,"tv":10229.57,"id":72857114},{"batl":[[1,1.79,1.46]],"ltp":1.76,"tv":8955.71,"id":67083366}]}]}
{"op":"mcm","clk":"11952747063","pt":1724517731295,"mc":[{"id":"1.232215600","rc":[{"trd":[[2.3,1.13]],"batb":[[0,2.3,2.41]],"ltp":2.3,"tv":10229.76,"id":72857114},{"batb":[[0,1.76,17.91],[1,1.73,83.67],[2,1.7,1466.33]],"batl":[[0,1.79,1.46],[1,1.8,11255.31],[2,1.81,14572.43]],"ltp":1.76,"tv":8955.71,"id":67083366}],"tv":19185.48}]}
{"op":"mcm","clk":"11952747139","pt":1724517731871,"mc":[{"id":"1.232215600","rc":[{"batb":[[0,2,17.5],[1,1.91,84.51],[2,1.91,0]],"ltp":2.3,"tv":10229.76,"id":72857114}]}]}
{"op":"mcm","clk":"11952747286","pt":1724517733196,"mc":[{"id":"1.232215600","rc":[{"trd":[[2.32,0.1]],"ltp":2.32,"tv":10229.86,"id":72857114},{"trd":[[1.75,0.13]],"batb":[[0,1.73,83.67],[1,1.7,1466.33],[2,1.55,1099.8]],"batl":[[0,1.75,3789.07],[1,1.79,1.46],[2,1.8,11255.31]],"ltp":1.75,"tv":8955.84,"id":67083366}],"tv":19185.71}]}
{"op":"mcm","clk":"11952747681","pt":1724517736288,"mc":[{"id":"1.232215600","rc":[{"trd":[[2.32,0.37]],"ltp":2.32,"tv":10230.13,"id":72857114},{"trd":[[1.75,0.49]],"batl":[[0,1.75,3788.71]],"ltp":1.75,"tv":8956.2,"id":67083366}],"tv":19186.34}]}
{"op":"mcm","clk":"11952747806","pt":1724517737292,"mc":[{"id":"1.232215600","rc":[{"trd":[[2.32,0.56]],"ltp":2.32,"tv":10230.32,"id":72857114},{"trd":[[1.75,0.74]],"batb":[[0,1.73,573.72]],"batl":[[0,1.75,3788.46],[1,1.78,1.1],[2,1.79,1.45]],"ltp":1.75,"tv":8956.45,"id":67083366}],"tv":19186.78}]}
{"op":"mcm","clk":"11952747915","pt":1724517738288,"mc":[{"id":"1.232215600","rc":[{"trd":[[1.75,0.94]],"batl":[[0,1.75,3788.36],[1,1.78,1.19]],"ltp":1.75,"tv":8956.65,"id":67083366}],"tv":19186.97}]}
{"op":"mcm","clk":"11952747985","pt":1724517738769,"mc":[{"id":"1.232215600","rc":[{"trd":[[1.75,168.48]],"batb":[[0,1.73,593.41]],"batl":[[0,1.75,3704.59]],"ltp":1.75,"tv":9124.19,"id":67083366}],"tv":19354.51}]}
{"op":"mcm","clk":"11952748138","pt":1724517740308,"mc":[{"id":"1.232215600","rc":[{"batb":[[1,1.72,55.38],[2,1.7,1466.33]],"batl":[[1,1.79,1.8],[2,1.8,11255.31]],"ltp":1.75,"tv":9124.19,"id":67083366}]}]}
{"op":"mcm","clk":"11952748213","pt":1724517740995,"mc":[{"id":"1.232215600","rc":[{"trd":[[2.32,44.32]],"ltp":2.32,"tv":10274.08,"id":72857114},{"trd":[[1.75,227.03]],"batl":[[0,1.75,3646.31],[1,1.78,2.83],[2,1.79,1.45]],"ltp":1.75,"tv":9182.74,"id":67083366}],"tv":19456.83}]}
{"op":"mcm","clk":"11952748301","pt":1724517741695,"mc":[{"id":"1.232215600","rc":[{"batl":[[1,1.78,22.83]],"ltp":1.75,"tv":9182.74,"id":67083366}]}]}
{"op":"mcm","clk":"11952748488","pt":1724517743206,"mc":[{"id":"1.232215600","rc":[{"batb":[[1,1.91,0]],"ltp":2.32,"tv":10274.08,"id":72857114},{"trd":[[1.75,1064.71]],"batl":[[0,1.75,3227.47],[1,1.78,20.11]],"ltp":1.75,"tv":10020.42,"id":67083366}],"tv":20294.51}]}
{"op":"mcm","clk":"11952748522","pt":1724517743570,"mc":[{"id":"1.232215600","rc":[{"trd":[[2.32,211.86]],"ltp":2.32,"tv":10441.62,"id":72857114},{"trd":[[1.75,1286.82]],"batl":[[0,1.75,3005.36]],"ltp":1.75,"tv":10242.53,"id":67083366}],"tv":20684.16}]}
{"op":"mcm","clk":"11952749013","pt":1724517747410,"mc":[{"id":"1.232215600","rc":[{"trd":[[1.73,164.34],[1.75,1287.02]],"batb":[[0,1.73,511.24]],"batl":[[0,1.75,3005.26]],"ltp":1.73,"tv":10407.07,"id":67083366}],"tv":20848.69}]}
{"op":"mcm","clk":"11952749118","pt":1724517748286,"mc":[{"id":"1.232215600","rc":[{"trd":[[1.75,2962.38]],"batl":[[0,1.75,2092.91]],"ltp":1.75,"tv":12082.43,"id":67083366}],"tv":22524.05}]}
{"op":"mcm","clk":"11952749241","pt":1724517749301,"mc":[{"id":"1.232215600","rc":[{"batb":[[0,1.73,21.19]],"ltp":1.75,"tv":12082.43,"id":67083366}]}]}
{"op":"mcm","clk":"11952749328","pt":1724517750199,"mc":[{"id":"1.232215600","rc":[{"trd":[[1.73,169.92]],"batb":[[0,1.73,16.9]],"ltp":1.73,"tv":12088.0,"id":67083366}],"tv":22529.63}]}
{"op":"mcm","clk":"11952749409","pt":1724517751089,"mc":[{"id":"1.232215600","rc":[{"batl":[[1,1.78,20.2]],"ltp":1.73,"tv":12088.0,"id":67083366}]}]}
{"op":"mcm","clk":"11952749507","pt":1724517751987,"mc":[{"id":"1.232215600","rc":[{"trd":[[1.73,171.6]],"batb":[[0,1.73,16.06]],"ltp":1.73,"tv":12089.68,"id":67083366}],"tv":22531.31}]}
{"op":"mcm","clk":"11952749593","pt":1724517752792,"mc":[{"id":"1.232215600","rc":[{"trd":[[1.73,171.62]],"batb":[[0,1.73,16.05],[1,1.7,1466.33],[2,1.55,1099.8]],"ltp":1.73,"tv":12089.7,"id":67083366}],"tv":22531.33}]}
{"op":"mcm","clk":"11952749678","pt":1724517753482,"mc":[{"id":"1.232215600","rc":[{"trd":[[2.32,211.95]],"ltp":2.32,"tv":10441.72,"id":72857114},{"trd":[[1.75,2962.51]],"batl":[[0,1.75,2092.78]],"ltp":1.75,"tv":12089.83,"id":67083366}],"tv":22531.56}]}
{"op":"mcm","clk":"11952749910","pt":1724517755487,"mc":[{"id":"1.232215600","rc":[{"trd":[[1.73,177.06]],"batb":[[0,1.73,13.33]],"ltp":1.73,"tv":12095.28,"id":67083366}],"tv":22537.0}]}
{"op":"mcm","clk":"11952750113","pt":1724517757388,"mc":[{"id":"1.232215600","rc":[{"trd":[[2.32,212.05]],"ltp":2.32,"tv":10441.82,"id":72857114},{"trd":[[1.75,2962.64]],"batl":[[0,1.75,2092.65]],"ltp":1.75,"tv":12095.41,"id":67083366}],"tv":22537.23}]}
{"op":"mcm","clk":"11952750127","pt":1724517757516,"mc":[{"id":"1.232215600","rc":[{"batb":[[0,1.7,1466.33],[1,1.55,1099.8],[2,1.4,4.19]],"ltp":1.75,"tv":12095.41,"id":67083366}]}]}
{"op":"mcm","clk":"11952750314","pt":1724517758983,"mc":[{"id":"1.232215600","rc":[{"trd":[[1.73,182.51]],"batl":[[0,1.75,2020.62]],"ltp":1.73,"tv":12100.85,"id":67083366}],"tv":22542.67}]}
{"op":"mcm","clk":"11952750444","pt":1724517760414,"mc":[{"id":"1.232215600","rc":[{"batl":[[1,1.78,20.11]],"ltp":1.73,"tv":12100.85,"id":67083366}]}]}
{"op":"mcm","clk":"11952750489","pt":1724517760782,"mc":[{"id":"1.232215600","rc":[{"trd":[[2.32,212.15]],"ltp":2.32,"tv":10441.91,"id":72857114},{"trd":[[1.75,2962.77]],"batl":[[0,1.75,2020.49]],"ltp":1.75,"tv":12100.98,"id":67083366}],"tv":22542.9}]}
{"op":"mcm","clk":"11952750634","pt":1724517762204,"mc":[{"id":"1.232215600","rc":[{"batl":[[0,1.75,1948.49],[2,1.8,11255.31]],"ltp":1.75,"tv":12100.98,"id":67083366}]}]}
{"op":"mcm","clk":"11952751222","pt":1724517767254,"mc":[{"id":"1.232215600","rc":[{"batb":[[0,1.71,166.13],[1,1.7,1466.33],[2,1.55,1099.8]],"ltp":1.75,"tv":12100.98,"id":67083366}]}]}
{"op":"mcm","clk":"11952751318","pt":1724517767941,"mc":[{"id":"1.232215600","rc":[{"batb":[[0,2,16.76]],"ltp":2.32,"tv":10441.91,"id":72857114}]}]}
{"op":"mcm","clk":"11952751745","pt":1724517771303,"mc":[{"id":"1.232215600","rc":[{"batb":[[0,1.71,332.26]],"ltp":1.75,"tv":12100.98,"id":67083366}]}]}
{"op":"mcm","clk":"11952751852","pt":1724517772349,"mc":[{"id":"1.232215600","rc":[{"trd":[[1.75,2962.96]],"batb":[[2,1.55,1119.49]],"batl":[[0,1.75,1942.15]],"ltp":1.75,"tv":12101.18,"id":67083366}],"tv":22543.1}]}
{"op":"mcm","clk":"11952752516","pt":1724517778139,"mc":[{"id":"1.232215600","rc":[{"batb":[[0,1.71,336.45]],"batl":[[1,1.8,11255.42],[2,1.81,14572.43]],"ltp":1.75,"tv":12101.18,"id":67083366}]}]}
{"op":"mcm","clk":"11952752700","pt":1724517779351,"mc":[{"id":"1.232215600","rc":[{"batb":[[0,2,17.6]],"ltp":2.32,"tv":10441.91,"id":72857114},{"trd":[[1.71,8.38],[1.75,2967.98]],"batb":[[0,1.7,1466.33],[1,1.55,1119.49],[2,1.4,4.19]],"batl":[[0,1.71,3413.55],[1,1.75,1939.64],[2,1.8,11255.42]],"ltp":1.71,"tv":12114.58,"id":67083366}],"tv":22556.5}]}
{"op":"mcm","clk":"11952752783","pt":1724517779837,"mc":[{"id":"1.232215600","rc":[{"trd":[[2.42,0.2]],"batb":[[0,2,17.5]],"ltp":2.42,"tv":10442.11,"id":72857114},{"batl":[[0,1.71,3295.9]],"ltp":1.71,"tv":12114.58,"id":67083366}],"tv":22556.69}]}
{"op":"mcm","clk":"11952753534","pt":1724517784464,"mc":[{"id":"1.232215600","rc":[{"trd":[[2.42,0.39]],"batb":[[0,2,17.4]],"ltp":2.42,"tv":10442.31,"id":72857114}],"tv":22556.89}]}
{"op":"mcm","clk":"11952753785","pt":1724517786058,"mc":[{"id":"1.232215600","rc":[{"trd":[[2.42,0.59]],"batb":[[0,2,17.3]],"ltp":2.42,"tv":10442.5,"id":72857114}],"tv":22557.09}]}
{"op":"mcm","clk":"11952753890","pt":1724517786851,"mc":[{"id":"1.232215600","rc":[{"trd":[[2.4,1.2]],"batb":[[0,2,16.76]],"ltp":2.4,"tv":10443.59,"id":72857114},{"trd":[[1.71,9.91]],"batl":[[0,1.71,3295.28]],"ltp":1.71,"tv":12116.11,"id":67083366}],"tv":22559.71}]}
{"op":"mcm","clk":"11952754076","pt":1724517788345,"mc":[{"id":"1.232215600","rc":[{"trd":[[2.4,1.65]],"batb":[[0,2,16.86]],"ltp":2.4,"tv":10444.05,"id":72857114},{"trd":[[1.71,10.55]],"batl":[[0,1.71,3294.64]],"ltp":1.71,"tv":12116.75,"id":67083366}],"tv":22560.8}]}
{"op":"mcm","clk":"11952754202","pt":1724517789351,"mc":[{"id":"1.232215600","rc":[{"batl":[[0,1.71,3694.64]],"ltp":1.71,"tv":12116.75,"id":67083366}]}]}
{"op":"mcm","clk":"11952754331","pt":1724517790365,"mc":[{"id":"1.232215600","rc":[{"trd":[[2.4,2.46]],"batb":[[0,2,16.76]],"batl":[[0,3.75,2.7]],"ltp":2.4,"tv":10444.86,"id":72857114},{"trd":[[1.71,11.69]],"batl":[[0,1.71,3685.54]],"ltp":1.71,"tv":12117.89,"id":67083366}],"tv":22562.75}]}
{"op":"mcm","clk":"11952754382","pt":1724517790775,"mc":[{"id":"1.232215600","rc":[{"batl":[[0,1.71,3685.63]],"ltp":1.71,"tv":12117.89,"id":67083366}]}]}
{"op":"mcm","clk":"11952754527","pt":1724517792171,"mc":[{"id":"1.232215600","rc":[{"trd":[[2.4,2.56]],"ltp":2.4,"tv":10444.96,"id":72857114},{"trd":[[1.71,11.83]],"batl":[[0,1.71,3685.49]],"ltp":1.71,"tv":12118.03,"id":67083366}],"tv":22562.99}]}
{"op":"mcm","clk":"11952754620","pt":1724517792961,"mc":[{"id":"1.232215600","rc":[{"trd":[[2.4,4.33]],"ltp":2.4,"tv":10446.72,"id":72857114},{"trd":[[1.7,84.4],[1.71,14.31]],"batb":[[0,1.7,1465.97]],"batl":[[0,1.71,3683.01]],"ltp":1.7,"tv":12121.23,"id":67083366}],"tv":22567.96}]}
{"op":"mcm","clk":"11952754804","pt":1724517794290,"mc":[{"id":"1.232215600","rc":[{"batb":[[1,1.67,59.08],[2,1.55,1119.49]],"batl":[[0,1.71,3458.06]],"ltp":1.7,"tv":12121.23,"id":67083366}]}]}
{"op":"mcm","clk":"11952755017","pt":1724517795987,"mc":[{"id":"1.232215600","rc":[{"batl":[[0,1.71,3291.93]],"ltp":1.7,"tv":12121.23,"id":67083366}]}]}
{"op":"mcm","clk":"11952755111","pt":1724517796794,"mc":[{"id":"1.232215600","rc":[{"trd":[[1.71,18.49]],"batl":[[0,1.71,3288.94],[2,1.8,11255.32]],"ltp":1.71,"tv":12125.41,"id":67083366}],"tv":22572.14}]}
{"op":"mcm","clk":"11952755309","pt":1724517798377,"mc":[{"id":"1.232215600","rc":[{"batl":[[0,3.75,2.61]],"ltp":2.4,"tv":10446.72,"id":72857114},{"trd":[[1.7,124.4],[1.71,125.37]],"batb":[[0,1.7,1445.97]],"batl":[[0,1.71,3235.5]],"ltp":1.7,"tv":12272.29,"id":67083366}],"tv":22719.02}]}
{"op":"mcm","clk":"11952755586","pt":1724517800696,"mc":[{"id":"1.232215600","rc":[{"trd":[[2.4,4.78]],"ltp":2.4,"tv":10447.18,"id":72857114},{"trd":[[1.71,126.01]],"batl":[[0,1.71,3234.86]],"ltp":1.71,"tv":12272.93,"id":67083366}],"tv":22720.11}]}
{"op":"mcm","clk":"11952755750","pt":1724517802276,"mc":[{"id":"1.232215600","rc":[{"trd":[[1.71,3071.51]],"batl":[[0,1.71,1762.11]],"ltp":1.71,"tv":15218.43,"id":67083366}],"tv":25665.62}]}
{"op":"mcm","clk":"11952755855","pt":1724517803053,"mc":[{"id":"1.232215600","rc":[{"trd":[[1.71,3071.99]],"batl":[[0,1.71,1761.87]],"ltp":1.71,"tv":15218.91,"id":67083366}],"tv":25666.09}]}
{"op":"mcm","clk":"11952756119","pt":1724517805168,"mc":[{"id":"1.232215600","rc":[{"trd":[[2.4,4.88]],"ltp":2.4,"tv":10447.27,"id":72857114},{"trd":[[1.71,3072.13]],"batb":[[2,1.58,3.2]],"batl":[[0,1.71,1761.73]],"ltp":1.71,"tv":15219.05,"id":67083366}],"tv":25666.33}]}
{"op":"mcm","clk":"11952756356","pt":1724517807271,"mc":[{"id":"1.232215600","rc":[{"trd":[[2.4,5.26]],"ltp":2.4,"tv":10447.66,"id":72857114},{"trd":[[1.71,3072.67]],"batl":[[0,1.71,1761.19]],"ltp":1.71,"tv":15219.59,"id":67083366}],"tv":25667.25}]}
{"op":"mcm","clk":"11952756408","pt":1724517807793,"mc":[{"id":"1.232215600","rc":[{"trd":[[1.71,3073.06]],"batb":[[0,1.71,546.6],[1,1.7,1445.97],[2,1.67,59.08]],"batl":[[0,1.75,1939.64],[1,1.8,11255.32],[2,1.81,14572.43]],"ltp":1.71,"tv":15219.98,"id":67083366}],"tv":25667.65}]}
{"op":"mcm","clk":"11952756601","pt":1724517809376,"mc":[{"id":"1.232215600","rc":[{"trd":[[2.32,212.25]],"batl":[[0,3.75,2.8]],"ltp":2.32,"tv":10447.75,"id":72857114},{"trd":[[1.75,2968.11]],"batl":[[0,1.75,1939.51]],"ltp":1.75,"tv":15220.11,"id":67083366}],"tv":25667.87}]}
{"op":"mcm","clk":"11952756697","pt":1724517809960,"mc":[{"id":"1.232215600","rc":[{"trd":[[1.71,3074.88]],"batb":[[0,1.71,545.69]],"ltp":1.71,"tv":15221.93,"id":67083366}],"tv":25669.69}]}
{"op":"mcm","clk":"11952756879","pt":1724517811278,"mc":[{"id":"1.232215600","rc":[{"trd":[[2.4,5.65],[2.42,1.23]],"batl":[[0,3.75,2.61]],"ltp":2.42,"tv":10448.79,"id":72857114},{"trd":[[1.71,3075.79]],"batb":[[0,1.71,546.52]],"ltp":1.71,"tv":15222.84,"id":67083366}],"tv":25671.63}]}
{"op":"mcm","clk":"11952757023","pt":1724517812498,"mc":[{"id":"1.232215600","rc":[{"batl":[[0,3.75,3.45]],"ltp":2.42,"tv":10448.79,"id":72857114},{"trd":[[1.71,3075.99]],"batb":[[0,1.71,546.42]],"ltp":1.71,"tv":15223.04,"id":67083366}],"tv":25671.83}]}
{"op":"mcm","clk":"11952757148","pt":1724517813558,"mc":[{"id":"1.232215600","rc":[{"batl":[[0,2.4,10.53],[1,3.75,2.61]],"ltp":2.42,"tv":10448.79,"id":72857114}]}]}
{"op":"mcm","clk":"11952757273","pt":1724517814877,"mc":[{"id":"1.232215600","rc":[{"batl":[[0,2.4,12.03]],"ltp":2.42,"tv":10448.79,"id":72857114},{"batb":[[0,1.71,546.52]],"ltp":1.71,"tv":15223.04,"id":67083366}]}]}
{"op":"mcm","clk":"11952757373","pt":1724517815772,"mc":[{"id":"1.232215600","rc":[{"trd":[[1.71,3076.19]],"batb":[[0,1.71,544.68]],"ltp":1.71,"tv":15223.24,"id":67083366}],"tv":25672.03}]}
{"op":"mcm","clk":"11952757543","pt":1724517817565,"mc":[{"id":"1.232215600","rc":[{"batl":[[0,2.4,12.32]],"ltp":2.42,"tv":10448.79,"id":72857114}]}]}
{"op":"mcm","clk":"11952757710","pt":1724517819195,"mc":[{"id":"1.232215600","rc":[{"batl":[[0,2.4,13.16]],"ltp":2.42,"tv":10448.79,"id":72857114}]}]}
{"op":"mcm","clk":"11952757756","pt":1724517819578,"mc":[{"id":"1.232215600","rc":[{"batl":[[0,2.4,14]],"ltp":2.42,"tv":10448.79,"id":72857114}]}]}
{"op":"mcm","clk":"11952757908","pt":1724517821306,"mc":[{"id":"1.232215600","rc":[{"batb":[[1,1.12,41.89]],"ltp":2.42,"tv":10448.79,"id":72857114},{"batl":[[0,1.74,4.19],[1,1.75,1939.51],[2,1.8,11255.32]],"ltp":1.71,"tv":15223.24,"id":67083366}]}]}
{"op":"mcm","clk":"11952758014","pt":1724517822410,"mc":[{"id":"1.232215600","rc":[{"batl":[[0,2.4,15.19]],"ltp":2.42,"tv":10448.79,"id":72857114}]}]}
{"op":"mcm","clk":"11952758249","pt":1724517824750,"mc":[{"id":"1.232215600","rc":[{"batl":[[0,2.4,15.09]],"ltp":2.42,"tv":10448.79,"id":72857114}]}]}
{"op":"mcm","clk":"11952758548","pt":1724517827344,"mc":[{"id":"1.232215600","rc":[{"trd":[[2.4,5.98]],"batl":[[0,2.4,14.93]],"ltp":2.4,"tv":10449.11,"id":72857114},{"trd":[[1.75,3379.41]],"batl":[[0,1.75,1733.86],[1,1.8,11255.32],[2,1.81,14572.43]],"ltp":1.75,"tv":15634.54,"id":67083366}],"tv":26083.65}]}
{"op":"mcm","clk":"11952758673","pt":1724517828092,"mc":[{"id":"1.232215600","rc":[{"trd":[[2.32,212.54]],"batl":[[0,2.4,13.84]],"ltp":2.32,"tv":10449.4,"id":72857114},{"trd":[[1.75,3379.79]],"batl":[[0,1.75,1733.48]],"ltp":1.75,"tv":15634.92,"id":67083366}],"tv":26084.32}]}
{"op":"mcm","clk":"11952758791","pt":1724517828846,"mc":[{"id":"1.232215600","rc":[{"trd":[[2.32,213.54]],"batl":[[0,2.4,13.55]],"ltp":2.32,"tv":10450.4,"id":72857114},{"trd":[[1.71,3076.35],[1.75,3381.12]],"batb":[[0,1.71,544.6]],"batl":[[0,1.75,1732.15]],"ltp":1.75,"tv":15636.41,"id":67083366}],"tv":26086.81}]}
{"op":"mcm","clk":"11952758988","pt":1724517830181,"mc":[{"id":"1.232215600","rc":[{"batl":[[0,2.4,11.37]],"ltp":2.32,"tv":10450.4,"id":72857114},{"trd":[[1.71,3083.53],[1.75,3381.48]],"batb":[[0,1.71,541.01]],"batl":[[0,1.75,1731.97]],"ltp":1.75,"tv":15643.95,"id":67083366}],"tv":26094.35}]}
{"op":"mcm","clk":"11952759409","pt":1724517833387,"mc":[{"id":"1.232215600","rc":[{"trd":[[1.73,182.7]],"batb":[[0,1.73,86.44],[1,1.71,541.01],[2,1.7,1445.97]],"ltp":1.73,"tv":15644.15,"id":67083366}],"tv":26094.55}]}
{"op":"mcm","clk":"11952759913","pt":1724517837108,"mc":[{"id":"1.232215600","rc":[{"batl":[[0,2.4,11.47]],"ltp":2.32,"tv":10450.4,"id":72857114}]}]}
{"op":"mcm","clk":"11952760207","pt":1724517839277,"mc":[{"id":"1.232215600","rc":[{"trd":[[2.34,0.07]],"batl":[[0,2.4,1.71]],"ltp":2.34,"tv":10450.47,"id":72857114},{"trd":[[1.74,6.81]],"ltp":1.74,"tv":15644.24,"id":67083366}],"tv":26094.72}]}
{"op":"mcm","clk":"11952760563","pt":1724517841770,"mc":[{"id":"1.232215600","rc":[{"batl":[[0,2.4,1.8]],"ltp":2.34,"tv":10450.47,"id":72857114}]}]}
{"op":"mcm","clk":"11952760708","pt":1724517842899,"mc":[{"id":"1.232215600","rc":[{"trd":[[2.32,213.84],[2.34,0.32],[2.38,1.96]],"batl":[[0,2.4,1.68]],"ltp":2.38,"tv":10452.98,"id":72857114},{"trd":[[1.73,185.4],[1.75,3381.88]],"batb":[[0,1.73,83.74]],"batl":[[0,1.75,1731.57]],"ltp":1.73,"tv":15647.34,"id":67083366}],"tv":26100.33}]}
{"op":"mcm","clk":"11952760857","pt":1724517844283,"mc":[{"id":"1.232215600","rc":[{"trd":[[1.75,3481.88]],"batl":[[0,1.75,1681.57]],"ltp":1.75,"tv":15747.34,"id":67083366}],"tv":26200.33}]}
{"op":"mcm","clk":"11952760925","pt":1724517844905,"mc":[{"id":"1.232215600","rc":[{"trd":[[2.32,215.34]],"ltp":2.32,"tv":10454.48,"id":72857114},{"trd":[[1.75,3483.87]],"batl":[[0,1.75,1679.58]],"ltp":1.75,"tv":15749.33,"id":67083366}],"tv":26203.82}]}
{"op":"mcm","clk":"11952760996","pt":1724517845489,"mc":[{"id":"1.232215600","rc":[{"trd":[[1.73,185.6]],"batb":[[0,1.73,83.64]],"ltp":1.73,"tv":15749.53,"id":67083366}],"tv":26204.02}]}
{"op":"mcm","clk":"11952761167","pt":1724517847069,"mc":[{"id":"1.232215600","rc":[{"batb":[[1,1.7,1446.07],[2,1.55,1119.49]],"ltp":1.73,"tv":15749.53,"id":67083366}]}]}
{"op":"mcm","clk":"11952761407","pt":1724517849307,"mc":[{"id":"1.232215600","rc":[{"trd":[[2.32,216.43]],"ltp":2.32,"tv":10455.57,"id":72857114},{"trd":[[1.75,3485.32]],"batl":[[0,1.75,1678.13]],"ltp":1.75,"tv":15750.98,"id":67083366}],"tv":26206.56}]}
{"op":"mcm","clk":"11952761467","pt":1724517849797,"mc":[{"id":"1.232215600","rc":[{"batb":[[0,1.74,1.67],[1,1.73,83.64],[2,1.7,1446.07]],"ltp":1.75,"tv":15750.98,"id":67083366}]}]}
{"op":"mcm","clk":"11952761622","pt":1724517850995,"mc":[{"id":"1.232215600","rc":[{"trd":[[2.32,226.12]],"ltp":2.32,"tv":10465.26,"id":72857114},{"trd":[[1.75,3498.17]],"batl":[[0,1.75,1665.28]],"ltp":1.75,"tv":15763.83,"id":67083366}],"tv":26229.1}]}
{"op":"mcm","clk":"11952761745","pt":1724517851686,"mc":[{"id":"1.232215600","rc":[{"batb":[[0,1.73,83.64],[1,1.7,1446.07],[2,1.55,1119.49]],"ltp":1.75,"tv":15763.83,"id":67083366}]}]}
{"op":"mcm","clk":"11952761946","pt":1724517853284,"mc":[{"id":"1.232215600","rc":[{"trd":[[2.32,226.3]],"ltp":2.32,"tv":10465.44,"id":72857114},{"trd":[[1.75,3498.53]],"batb":[[0,1.74,2.75],[1,1.73,83.64],[2,1.7,1446.07]],"batl":[[0,1.75,1664.98]],"ltp":1.75,"tv":15764.19,"id":67083366}],"tv":26229.64}]}
{"op":"mcm","clk":"11952762139","pt":1724517854779,"mc":[{"id":"1.232215600","rc":[{"trd":[[2.32,227.97]],"ltp":2.32,"tv":10467.11,"id":72857114},{"trd":[[1.75,3500.74]],"batl":[[0,1.75,1662.77]],"ltp":1.75,"tv":15766.4,"id":67083366}],"tv":26233.52}]}
{"op":"mcm","clk":"11952762282","pt":1724517856091,"mc":[{"id":"1.232215600","rc":[{"trd":[[1.74,7.01]],"batb":[[0,1.74,2.66]],"ltp":1.74,"tv":15766.59,"id":67083366}],"tv":26233.71}]}
