{"op":"mcm","clk":"11782155163","pt":1722778554947,"mc":[{"id":"1.231447835","marketDefinition":{"bspMarket":false,"turnInPlayEnabled":true,"persistenceEnabled":true,"marketBaseRate":5.0,"eventId":"33468175","eventTypeId":"4","numberOfWinners":1,"bettingType":"ODDS","marketType":"MATCH_ODDS","marketTime":"2024-08-08T10:00:00.000Z","suspendTime":"2024-08-08T10:00:00.000Z","bspReconciled":false,"complete":true,"inPlay":false,"crossMatching":false,"runnersVoidable":false,"numberOfActiveRunners":2,"betDelay":0,"status":"OPEN","runners":[{"status":"ACTIVE","sortPriority":1,"id":2120,"name":"Warwickshire"},{"status":"ACTIVE","sortPriority":2,"id":169,"name":"Glamorgan"}],"regulators":["MR_INT"],"countryCode":"GB","discountAllowed":false,"timezone":"GMT","openDate":"2024-08-08T10:00:00.000Z","version":6056573536,"name":"Match Odds","eventName":"Warwickshire v Glamorgan"},"rc":[{"batb":[[0,1.03,200],[1,1.02,200],[2,1.01,220]],"ltp":0.0,"tv":0.0,"id":169},{"batb":[[0,1.03,200],[1,1.02,200],[2,1.01,220]],"ltp":0.0,"tv":0.0,"id":2120}]}]}
{"op":"mcm","clk":"11782155320","pt":1722778556112,"mc":[{"id":"1.231447835","marketDefinition":{"bspMarket":false,"turnInPlayEnabled":true,"persistenceEnabled":true,"marketBaseRate":5.0,"eventId":"33468175","eventTypeId":"4","numberOfWinners":1,"bettingType":"ODDS","marketType":"MATCH_ODDS","marketTime":"2024-08-08T10:00:00.000Z","suspendTime":"2024-08-08T10:00:00.000Z","bspReconciled":false,"complete":true,"inPlay":false,"crossMatching":false,"runnersVoidable":false,"numberOfActiveRunners":2,"betDelay":0,"status":"OPEN","runners":[{"status":"ACTIVE","sortPriority":1,"id":2120,"name":"Warwickshire"},{"status":"ACTIVE","sortPriority":2,"id":169,"name":"Glamorgan"}],"regulators":["MR_INT"],"countryCode":"GB","discountAllowed":true,"timezone":"GMT","openDate":"2024-08-08T10:00:00.000Z","version":6056573536,"name":"Match Odds","eventName":"Warwickshire v Glamorgan"}}]}
{"op":"mcm","clk":"11783549525","pt":1722787454093,"mc":[{"id":"1.231447835","rc":[{"batb":[[2,1.01,220.78]],"ltp":0.0,"tv":0.0,"id":2120},{"batb":[[2,1.01,220.78]],"ltp":0.0,"tv":0.0,"id":169}]}]}
{"op":"mcm","clk":"11783879634","pt":1722789412929,"mc":[{"id":"1.231447835","rc":[{"batb":[[2,1.01,228.59]],"ltp":0.0,"tv":0.0,"id":2120},{"batb":[[2,1.01,228.59]],"ltp":0.0,"tv":0.0,"id":169}]}]}
{"op":"mcm","clk":"11783881476","pt":1722789425538,"mc":[{"id":"1.231447835","marketDefinition":{"bspMarket":false,"turnInPlayEnabled":true,"persistenceEnabled":true,"marketBaseRate":5.0,"eventId":"33468175","eventTypeId":"4","numberOfWinners":1,"bettingType":"ODDS","marketType":"MATCH_ODDS","marketTime":"2024-08-08T10:00:00.000Z","suspendTime":"2024-08-08T10:00:00.000Z","bspReconciled":false,"complete":true,"inPlay":false,"crossMatching":true,"runnersVoidable":false,"numberOfActiveRunners":2,"betDelay":0,"status":"OPEN","runners":[{"status":"ACTIVE","sortPriority":1,"id":2120,"name":"Warwickshire"},{"status":"ACTIVE","sortPriority":2,"id":169,"name":"Glamorgan"}],"regulators":["MR_INT"],"countryCode":"GB","discountAllowed":true,"timezone":"GMT","openDate":"2024-08-08T10:00:00.000Z","version":6056573536,"name":"Match Odds","eventName":"Warwickshire v Glamorgan"},"rc":[{"batb":[[1,1.02,207.81]],"ltp":0.0,"tv":0.0,"id":2120},{"batb":[[1,1.02,207.81]],"ltp":0.0,"tv":0.0,"id":169}]}]}
{"op":"mcm","clk":"11783883489","pt":1722789438991,"mc":[{"id":"1.231447835","rc":[{"batb":[[1,1.02,246.85]],"ltp":0.0,"tv":0.0,"id":2120},{"batb":[[1,1.02,246.85]],"ltp":0.0,"tv":0.0,"id":169}]}]}
{"op":"mcm","clk":"11783885672","pt":1722789452683,"mc":[{"id":"1.231447835","rc":[{"batb":[[0,1.03,207.81]],"ltp":0.0,"tv":0.0,"id":2120},{"batb":[[0,1.03,207.81]],"ltp":0.0,"tv":0.0,"id":169}]}]}
{"op":"mcm","clk":"11783888091","pt":1722789468098,"mc":[{"id":"1.231447835","rc":[{"batb":[[0,1.04,7.81],[1,1.03,207.81],[2,1.02,246.85]],"ltp":0.0,"tv":0.0,"id":2120},{"batb":[[0,1.04,7.81],[1,1.03,207.81],[2,1.02,246.85]],"ltp":0.0,"tv":0.0,"id":169}]}]}
{"op":"mcm","clk":"11783889861","pt":1722789480035,"mc":[{"id":"1.231447835","rc":[{"batb":[[0,1.05,7.81],[1,1.04,7.81],[2,1.03,207.81]],"ltp":0.0,"tv":0.0,"id":2120},{"batb":[[0,1.05,7.81],[1,1.04,7.81],[2,1.03,207.81]],"ltp":0.0,"tv":0.0,"id":169}]}]}
{"op":"mcm","clk":"11783892588","pt":1722789497322,"mc":[{"id":"1.231447835","rc":[{"batb":[[0,1.06,7.81],[1,1.05,7.81],[2,1.04,7.81]],"ltp":0.0,"tv":0.0,"id":2120},{"batb":[[0,1.06,7.81],[1,1.05,7.81],[2,1.04,7.81]],"ltp":0.0,"tv":0.0,"id":169}]}]}
{"op":"mcm","clk":"11783894996","pt":1722789512968,"mc":[{"id":"1.231447835","rc":[{"batb":[[0,1.07,7.81],[1,1.06,7.81],[2,1.05,7.81]],"ltp":0.0,"tv":0.0,"id":2120},{"batb":[[0,1.07,7.81],[1,1.06,7.81],[2,1.05,7.81]],"ltp":0.0,"tv":0.0,"id":169}]}]}
{"op":"mcm","clk":"11783898098","pt":1722789533148,"mc":[{"id":"1.231447835","rc":[{"batb":[[0,1.08,7.81],[1,1.07,7.81],[2,1.06,7.81]],"ltp":0.0,"tv":0.0,"id":2120},{"batb":[[0,1.08,7.81],[1,1.07,7.81],[2,1.06,7.81]],"ltp":0.0,"tv":0.0,"id":169}]}]}
{"op":"mcm","clk":"11784540037","pt":1722793616766,"mc":[{"id":"1.231447835","rc":[{"batb":[[0,1.38,131.58],[1,1.33,151.52],[2,1.28,178.57]],"ltp":0.0,"tv":0.0,"id":169},{"batb":[[0,1.38,131.58],[1,1.33,151.52],[2,1.28,178.57]],"ltp":0.0,"tv":0.0,"id":2120}]}]}
{"op":"mcm","clk":"11784603400","pt":1722794123524,"mc":[{"id":"1.231447835","rc":[{"batb":[[0,1.39,6.83],[1,1.38,131.58],[2,1.33,151.52]],"ltp":0.0,"tv":0.0,"id":169},{"batb":[[0,1.39,6.4],[1,1.38,131.58],[2,1.33,151.52]],"ltp":0.0,"tv":0.0,"id":2120}]}]}
{"op":"mcm","clk":"11784712857","pt":1722794927425,"mc":[{"id":"1.231447835","rc":[{"batb":[[0,2.26,3.51],[1,1.39,6.83],[2,1.38,131.58]],"ltp":0.0,"tv":0.0,"id":169},{"batb":[[0,1.73,6.07],[1,1.39,6.4],[2,1.38,131.58]],"ltp":0.0,"tv":0.0,"id":2120}]}]}
{"op":"mcm","clk":"11784938796","pt":1722796335942,"mc":[{"id":"1.231447835","rc":[{"batb":[[1,1.38,131.58],[2,1.33,151.52]],"ltp":0.0,"tv":0.0,"id":2120},{"batb":[[1,1.38,131.58],[2,1.33,151.52]],"ltp":0.0,"tv":0.0,"id":169}]}]}
{"op":"mcm","clk":"11786755508","pt":1722813374743,"mc":[{"id":"1.231447835","rc":[{"batb":[[1,1.66,251],[2,1.38,131.58]],"ltp":0.0,"tv":0.0,"id":169}]}]}
{"op":"mcm","clk":"11786756910","pt":1722813404833,"mc":[{"id":"1.231447835","rc":[{"batb":[[1,1.41,232],[2,1.38,131.58]],"ltp":0.0,"tv":0.0,"id":2120}]}]}
{"op":"mcm","clk":"11786819653","pt":1722814712961,"mc":[{"id":"1.231447835","rc":[{"batb":[[1,1.67,12.5],[2,1.66,251]],"ltp":0.0,"tv":0.0,"id":169},{"batl":[[0,2.5,8.34]],"ltp":0.0,"tv":0.0,"id":2120}]}]}
{"op":"mcm","clk":"11786820161","pt":1722814726560,"mc":[{"id":"1.231447835","rc":[{"batb":[[1,1.68,251],[2,1.67,12.5]],"ltp":0.0,"tv":0.0,"id":169}]}]}
{"op":"mcm","clk":"11786820195","pt":1722814727560,"mc":[{"id":"1.231447835","rc":[{"batb":[[2,1.38,131.58]],"ltp":0.0,"tv":0.0,"id":169},{"batb":[[1,1.42,11.69],[2,1.41,232]],"ltp":0.0,"tv":0.0,"id":2120}]}]}
{"op":"mcm","clk":"11786820233","pt":1722814728736,"mc":[{"id":"1.231447835","rc":[{"batl":[[0,3.4,4.65]],"ltp":0.0,"tv":0.0,"id":169}]}]}
{"op":"mcm","clk":"11786820658","pt":1722814739880,"mc":[{"id":"1.231447835","rc":[{"batb":[[1,1.43,232],[2,1.42,11.69]],"ltp":0.0,"tv":0.0,"id":2120}]}]}
{"op":"mcm","clk":"11786820690","pt":1722814740595,"mc":[{"id":"1.231447835","rc":[{"batb":[[2,1.38,131.58]],"ltp":0.0,"tv":0.0,"id":2120}]}]}
{"op":"mcm","clk":"11786868713","pt":1722816059076,"mc":[{"id":"1.231447835","rc":[{"batb":[[1,1.69,12.5],[2,1.68,251]],"ltp":0.0,"tv":0.0,"id":169},{"batl":[[0,2.46,8.57]],"ltp":0.0,"tv":0.0,"id":2120}]}]}
{"op":"mcm","clk":"11786868784","pt":1722816061386,"mc":[{"id":"1.231447835","rc":[{"batl":[[0,3.3,5.08]],"ltp":0.0,"tv":0.0,"id":169},{"batb":[[1,1.44,11.69],[2,1.43,232]],"ltp":0.0,"tv":0.0,"id":2120}]}]}
{"op":"mcm","clk":"11787065290","pt":1722822174850,"mc":[{"id":"1.231447835","rc":[{"batb":[[1,1.69,12.51]],"batl":[[0,3.3,5.08]],"ltp":0.0,"tv":0.0,"id":169},{"batb":[[1,1.44,11.7]],"batl":[[0,2.46,8.57]],"ltp":0.0,"tv":0.0,"id":2120}]}]}
{"op":"mcm","clk":"11787097461","pt":1722823170033,"mc":[{"id":"1.231447835","rc":[{"batb":[[0,1.69,12.51],[1,1.68,251],[2,1.38,131.58]],"ltp":0.0,"tv":0.0,"id":169},{"batb":[[0,1.44,11.7],[1,1.43,232],[2,1.38,131.58]],"ltp":0.0,"tv":0.0,"id":2120}]}]}
{"op":"mcm","clk":"11787117145","pt":1722823854931,"mc":[{"id":"1.231447835","rc":[{"batb":[[0,1.69,19.64]],"batl":[[0,3.3,5.08]],"ltp":0.0,"tv":0.0,"id":169},{"batb":[[0,1.44,18.94]],"batl":[[0,2.46,8.57]],"ltp":0.0,"tv":0.0,"id":2120}]}]}
{"op":"mcm","clk":"11787161265","pt":1722825361213,"mc":[{"id":"1.231447835","rc":[{"batb":[[0,2.26,3.51],[1,1.69,19.64],[2,1.68,251]],"ltp":0.0,"tv":0.0,"id":169},{"batb":[[0,1.73,6.07],[1,1.44,18.94],[2,1.43,232]],"ltp":0.0,"tv":0.0,"id":2120}]}]}
{"op":"mcm","clk":"11787162571","pt":1722825406920,"mc":[{"id":"1.231447835","rc":[{"batb":[[1,1.44,11.7]],"ltp":0.0,"tv":0.0,"id":2120}]}]}
{"op":"mcm","clk":"11787162581","pt":1722825407230,"mc":[{"id":"1.231447835","rc":[{"batb":[[1,1.69,12.51]],"ltp":0.0,"tv":0.0,"id":169}]}]}
{"op":"mcm","clk":"11787222082","pt":1722827574840,"mc":[{"id":"1.231447835","rc":[{"batb":[[1,1.69,12.5]],"batl":[[0,3.3,5.08]],"ltp":0.0,"tv":0.0,"id":169},{"batb":[[1,1.44,11.69]],"batl":[[0,2.46,8.57]],"ltp":0.0,"tv":0.0,"id":2120}]}]}
{"op":"mcm","clk":"11787335352","pt":1722832974851,"mc":[{"id":"1.231447835","rc":[{"batb":[[1,1.69,12.51]],"batl":[[0,3.3,5.08]],"ltp":0.0,"tv":0.0,"id":169},{"batb":[[1,1.44,11.7]],"batl":[[0,2.46,8.57]],"ltp":0.0,"tv":0.0,"id":2120}]}]}
{"op":"mcm","clk":"11787428965","pt":1722838374829,"mc":[{"id":"1.231447835","rc":[{"batb":[[1,1.69,12.54]],"batl":[[0,3.3,5.09]],"ltp":0.0,"tv":0.0,"id":169},{"batb":[[1,1.44,11.72]],"batl":[[0,2.46,8.59]],"ltp":0.0,"tv":0.0,"id":2120}]}]}
{"op":"mcm","clk":"11787565273","pt":1722843774878,"mc":[{"id":"1.231447835","rc":[{"batb":[[1,1.69,12.54]],"ltp":0.0,"tv":0.0,"id":169},{"batb":[[1,1.44,11.73]],"batl":[[0,2.46,8.59]],"ltp":0.0,"tv":0.0,"id":2120}]}]}
{"op":"mcm","clk":"11787776167","pt":1722849174844,"mc":[{"id":"1.231447835","rc":[{"batb":[[1,1.69,12.57]],"batl":[[0,3.3,5.11]],"ltp":0.0,"tv":0.0,"id":169},{"batb":[[1,1.44,11.75]],"batl":[[0,2.46,8.61]],"ltp":0.0,"tv":0.0,"id":2120}]}]}
{"op":"mcm","clk":"11788070445","pt":1722854020982,"mc":[{"id":"1.231447835","rc":[{"batb":[[1,1.69,12.58]],"batl":[[0,3.3,5.11]],"ltp":0.0,"tv":0.0,"id":169},{"batb":[[1,1.44,11.77]],"batl":[[0,2.46,8.62]],"ltp":0.0,"tv":0.0,"id":2120}]}]}
{"op":"mcm","clk":"11788425686","pt":1722859974864,"mc":[{"id":"1.231447835","rc":[{"batb":[[1,1.69,12.58]],"ltp":0.0,"tv":0.0,"id":169},{"batb":[[1,1.44,11.77]],"ltp":0.0,"tv":0.0,"id":2120}]}]}
{"op":"mcm","clk":"11788785608","pt":1722865374855,"mc":[{"id":"1.231447835","rc":[{"batb":[[1,1.69,12.62]],"batl":[[0,3.3,5.13]],"ltp":0.0,"tv":0.0,"id":169},{"batb":[[1,1.44,11.8]],"batl":[[0,2.46,8.65]],"ltp":0.0,"tv":0.0,"id":2120}]}]}
{"op":"mcm","clk":"11788958265","pt":1722867709654,"mc":[{"id":"1.231447835","rc":[{"batb":[[0,2.26,3.04],[1,1.69,12.59]],"batl":[[0,3.3,5.11]],"ltp":0.0,"tv":0.0,"id":169},{"batb":[[0,1.73,5.25],[1,1.44,11.77]],"batl":[[0,2.46,8.63]],"ltp":0.0,"tv":0.0,"id":2120}]}]}
{"op":"mcm","clk":"11789052890","pt":1722868996396,"mc":[{"id":"1.231447835","rc":[{"batb":[[1,1.69,20.24]],"ltp":0.0,"tv":0.0,"id":169},{"batb":[[1,1.44,18.35]],"ltp":0.0,"tv":0.0,"id":2120}]}]}
{"op":"mcm","clk":"11789192250","pt":1722870774850,"mc":[{"id":"1.231447835","rc":[{"batb":[[1,1.69,20.27]],"batl":[[0,3.3,5.12]],"ltp":0.0,"tv":0.0,"id":169},{"batb":[[1,1.44,18.38]],"batl":[[0,2.46,8.64]],"ltp":0.0,"tv":0.0,"id":2120}]}]}
{"op":"mcm","clk":"11789724940","pt":1722876174841,"mc":[{"id":"1.231447835","rc":[{"batb":[[1,1.69,20.23]],"batl":[[0,3.3,5.11]],"ltp":0.0,"tv":0.0,"id":169},{"batb":[[1,1.44,18.35]],"batl":[[0,2.46,8.62]],"ltp":0.0,"tv":0.0,"id":2120}]}]}
{"op":"mcm","clk":"11790011929","pt":1722878750721,"mc":[{"id":"1.231447835","rc":[{"trd":[[2.26,0.06]],"batb":[[0,2.26,2.98],[1,1.69,20.24]],"ltp":2.26,"tv":0.06,"id":169},{"trd":[[1.8,0.07]],"batb":[[1,1.44,18.35]],"batl":[[0,2.46,8.62]],"ltp":1.8,"tv":0.07,"id":2120}],"tv":0.13}]}
{"op":"mcm","clk":"11790012116","pt":1722878752446,"mc":[{"id":"1.231447835","rc":[{"batb":[[0,2.26,3.04]],"ltp":2.26,"tv":0.06,"id":169}]}]}
{"op":"mcm","clk":"11790323351","pt":1722881574828,"mc":[{"id":"1.231447835","rc":[{"batb":[[1,1.69,20.25]],"batl":[[0,3.3,5.11]],"ltp":2.26,"tv":0.06,"id":169},{"batb":[[1,1.44,18.36]],"batl":[[0,2.46,8.62]],"ltp":1.8,"tv":0.07,"id":2120}]}]}
{"op":"mcm","clk":"11790624890","pt":1722884044949,"mc":[{"id":"1.231447835","rc":[{"batb":[[1,1.74,17.32],[2,1.69,20.25]],"ltp":2.26,"tv":0.06,"id":169},{"batb":[[0,1.74,17.32],[1,1.73,5.25],[2,1.44,18.36]],"ltp":1.8,"tv":0.07,"id":2120}]}]}
{"op":"mcm","clk":"11790625105","pt":1722884046812,"mc":[{"id":"1.231447835","rc":[{"batb":[[2,1.69,7.67]],"ltp":2.26,"tv":0.06,"id":169},{"batb":[[2,1.44,6.59]],"ltp":1.8,"tv":0.07,"id":2120}]}]}
{"op":"mcm","clk":"11790902111","pt":1722886974828,"mc":[{"id":"1.231447835","rc":[{"batb":[[2,1.44,6.59]],"ltp":1.8,"tv":0.07,"id":2120},{"batb":[[2,1.69,7.67]],"ltp":2.26,"tv":0.06,"id":169}]}]}
{"op":"mcm","clk":"11791231507","pt":1722892374817,"mc":[{"id":"1.231447835","rc":[{"batb":[[2,1.44,6.58]],"ltp":1.8,"tv":0.07,"id":2120},{"batb":[[2,1.69,7.65]],"ltp":2.26,"tv":0.06,"id":169}]}]}
{"op":"mcm","clk":"11791630958","pt":1722903174856,"mc":[{"id":"1.231447835","rc":[{"batb":[[2,1.44,6.58]],"ltp":1.8,"tv":0.07,"id":2120},{"batb":[[2,1.69,7.65]],"ltp":2.26,"tv":0.06,"id":169}]}]}
{"op":"mcm","clk":"11791908292","pt":1722908574842,"mc":[{"id":"1.231447835","rc":[{"batb":[[2,1.44,6.57]],"ltp":1.8,"tv":0.07,"id":2120},{"batb":[[2,1.69,7.64]],"ltp":2.26,"tv":0.06,"id":169}]}]}
{"op":"mcm","clk":"11792130585","pt":1722913974854,"mc":[{"id":"1.231447835","rc":[{"batb":[[2,1.44,6.58]],"ltp":1.8,"tv":0.07,"id":2120},{"batb":[[2,1.69,7.65]],"ltp":2.26,"tv":0.06,"id":169}]}]}
{"op":"mcm","clk":"11792311026","pt":1722919374841,"mc":[{"id":"1.231447835","rc":[{"batb":[[2,1.44,6.58]],"ltp":1.8,"tv":0.07,"id":2120},{"batb":[[2,1.69,7.65]],"ltp":2.26,"tv":0.06,"id":169}]}]}
{"op":"mcm","clk":"11792443177","pt":1722924774834,"mc":[{"id":"1.231447835","rc":[{"batb":[[2,1.44,6.59]],"ltp":1.8,"tv":0.07,"id":2120},{"batb":[[2,1.69,7.66]],"ltp":2.26,"tv":0.06,"id":169}]}]}
{"op":"mcm","clk":"11792498165","pt":1722926751142,"mc":[{"id":"1.231447835","rc":[{"trd":[[1.8,0.14]],"ltp":1.8,"tv":0.14,"id":2120},{"trd":[[2.26,0.12]],"batb":[[0,2.26,2.98]],"ltp":2.26,"tv":0.12,"id":169}],"tv":0.26}]}
{"op":"mcm","clk":"11792498271","pt":1722926755249,"mc":[{"id":"1.231447835","rc":[{"batb":[[0,2.26,3.04]],"ltp":2.26,"tv":0.12,"id":169}]}]}
{"op":"mcm","clk":"11792580449","pt":1722930174856,"mc":[{"id":"1.231447835","rc":[{"batb":[[2,1.69,7.67]],"ltp":2.26,"tv":0.12,"id":169},{"batb":[[2,1.44,6.59]],"ltp":1.8,"tv":0.14,"id":2120}]}]}
{"op":"mcm","clk":"11792757911","pt":1722935574842,"mc":[{"id":"1.231447835","rc":[{"batb":[[2,1.69,7.68]],"ltp":2.26,"tv":0.12,"id":169},{"batb":[[2,1.44,6.61]],"ltp":1.8,"tv":0.14,"id":2120}]}]}
{"op":"mcm","clk":"11792905478","pt":1722938401646,"mc":[{"id":"1.231447835","rc":[{"batb":[[0,2.26,30.46]],"ltp":2.26,"tv":0.12,"id":169},{"batb":[[1,1.73,52.58]],"ltp":1.8,"tv":0.14,"id":2120}]}]}
{"op":"mcm","clk":"11792945757","pt":1722939089827,"mc":[{"id":"1.231447835","rc":[{"batb":[[0,1.74,17.32],[1,1.69,7.69],[2,1.68,251]],"ltp":2.26,"tv":0.12,"id":169},{"batb":[[1,1.44,6.62],[2,1.43,232]],"ltp":1.8,"tv":0.14,"id":2120}]}]}
{"op":"mcm","clk":"11793090626","pt":1722941071428,"mc":[{"id":"1.231447835","rc":[{"batb":[[1,1.73,52.58],[2,1.44,6.62]],"ltp":1.8,"tv":0.14,"id":2120},{"batb":[[0,2.26,30.46],[1,1.74,17.32],[2,1.69,7.69]],"ltp":2.26,"tv":0.12,"id":169}]}]}
{"op":"mcm","clk":"11793187331","pt":1722942404674,"mc":[{"id":"1.231447835","rc":[{"batb":[[2,1.43,232]],"ltp":1.8,"tv":0.14,"id":2120},{"batb":[[2,1.68,251]],"ltp":2.26,"tv":0.12,"id":169}]}]}
{"op":"mcm","clk":"11793895003","pt":1722954111373,"mc":[{"id":"1.231447835","rc":[{"batb":[[0,2.26,30.01]],"ltp":2.26,"tv":0.12,"id":169},{"batb":[[1,1.73,51.81]],"ltp":1.8,"tv":0.14,"id":2120}]}]}
{"op":"mcm","clk":"11794774755","pt":1722967552967,"mc":[{"id":"1.231447835","rc":[{"trd":[[1.8,0.21]],"ltp":1.8,"tv":0.21,"id":2120},{"trd":[[2.26,0.18]],"batb":[[0,2.26,29.95]],"ltp":2.26,"tv":0.18,"id":169}],"tv":0.39}]}
{"op":"mcm","clk":"11794775184","pt":1722967556575,"mc":[{"id":"1.231447835","rc":[{"batb":[[0,2.26,30.01]],"ltp":2.26,"tv":0.18,"id":169}]}]}
{"op":"mcm","clk":"11794909924","pt":1722968778353,"mc":[{"id":"1.231447835","rc":[{"trd":[[2.26,0.24]],"batb":[[0,2.26,29.95]],"ltp":2.26,"tv":0.24,"id":169},{"trd":[[1.8,0.28]],"ltp":1.8,"tv":0.28,"id":2120}],"tv":0.52}]}
{"op":"mcm","clk":"11794910312","pt":1722968781866,"mc":[{"id":"1.231447835","rc":[{"batb":[[0,2.26,30.01]],"ltp":2.26,"tv":0.24,"id":169}]}]}
{"op":"mcm","clk":"11795035499","pt":1722969969204,"mc":[{"id":"1.231447835","rc":[{"trd":[[2.26,0.3]],"batb":[[0,2.26,29.95]],"ltp":2.26,"tv":0.3,"id":169},{"trd":[[1.8,0.35]],"ltp":1.8,"tv":0.35,"id":2120}],"tv":0.65}]}
{"op":"mcm","clk":"11795035791","pt":1722969971844,"mc":[{"id":"1.231447835","rc":[{"batb":[[0,2.26,30.01]],"ltp":2.26,"tv":0.3,"id":169}]}]}
{"op":"mcm","clk":"11795570616","pt":1722975951510,"mc":[{"id":"1.231447835","rc":[{"trd":[[2.26,0.36]],"batb":[[0,2.26,29.95]],"ltp":2.26,"tv":0.36,"id":169},{"trd":[[1.8,0.42]],"ltp":1.8,"tv":0.42,"id":2120}],"tv":0.78}]}
{"op":"mcm","clk":"11795570956","pt":1722975956318,"mc":[{"id":"1.231447835","rc":[{"batb":[[0,2.26,30.01]],"ltp":2.26,"tv":0.36,"id":169}]}]}
{"op":"mcm","clk":"11795643673","pt":1722977152404,"mc":[{"id":"1.231447835","rc":[{"trd":[[2.26,0.42]],"batb":[[0,2.26,29.95]],"ltp":2.26,"tv":0.42,"id":169},{"trd":[[1.8,0.49]],"ltp":1.8,"tv":0.49,"id":2120}],"tv":0.91}]}
{"op":"mcm","clk":"11795643903","pt":1722977156376,"mc":[{"id":"1.231447835","rc":[{"batb":[[0,2.26,30.01]],"ltp":2.26,"tv":0.42,"id":169}]}]}
{"op":"mcm","clk":"11795714303","pt":1722978352648,"mc":[{"id":"1.231447835","rc":[{"trd":[[2.26,0.48]],"batb":[[0,2.26,29.95]],"ltp":2.26,"tv":0.48,"id":169},{"trd":[[1.8,0.56]],"ltp":1.8,"tv":0.56,"id":2120}],"tv":1.04}]}
{"op":"mcm","clk":"11795714481","pt":1722978356646,"mc":[{"id":"1.231447835","rc":[{"batb":[[0,2.26,30.01]],"ltp":2.26,"tv":0.48,"id":169}]}]}
{"op":"mcm","clk":"11795776402","pt":1722979553099,"mc":[{"id":"1.231447835","rc":[{"trd":[[2.26,0.54]],"batb":[[0,2.26,29.95]],"ltp":2.26,"tv":0.54,"id":169},{"trd":[[1.8,0.63]],"ltp":1.8,"tv":0.63,"id":2120}],"tv":1.17}]}
{"op":"mcm","clk":"11795776540","pt":1722979556481,"mc":[{"id":"1.231447835","rc":[{"batb":[[0,2.26,30.01]],"ltp":2.26,"tv":0.54,"id":169}]}]}
{"op":"mcm","clk":"11795833898","pt":1722980752433,"mc":[{"id":"1.231447835","rc":[{"trd":[[2.26,0.6]],"batb":[[0,2.26,29.95]],"ltp":2.26,"tv":0.6,"id":169},{"trd":[[1.8,0.7]],"ltp":1.8,"tv":0.7,"id":2120}],"tv":1.3}]}
{"op":"mcm","clk":"11795834077","pt":1722980756736,"mc":[{"id":"1.231447835","rc":[{"batb":[[0,2.26,30.01]],"ltp":2.26,"tv":0.6,"id":169}]}]}
{"op":"mcm","clk":"11795890363","pt":1722981951811,"mc":[{"id":"1.231447835","rc":[{"trd":[[2.26,0.66]],"batb":[[0,2.26,29.95]],"ltp":2.26,"tv":0.66,"id":169},{"trd":[[1.8,0.77]],"ltp":1.8,"tv":0.77,"id":2120}],"tv":1.43}]}
{"op":"mcm","clk":"11795890547","pt":1722981956627,"mc":[{"id":"1.231447835","rc":[{"batb":[[0,2.26,30.01]],"ltp":2.26,"tv":0.66,"id":169}]}]}
{"op":"mcm","clk":"11795978716","pt":1722984351144,"mc":[{"id":"1.231447835","rc":[{"trd":[[2.26,0.72]],"batb":[[0,2.26,29.95]],"ltp":2.26,"tv":0.72,"id":169},{"trd":[[1.8,0.84]],"ltp":1.8,"tv":0.84,"id":2120}],"tv":1.56}]}
{"op":"mcm","clk":"11795978767","pt":1722984352371,"mc":[{"id":"1.231447835","rc":[{"batb":[[0,2.26,30.01]],"ltp":2.26,"tv":0.72,"id":169}]}]}
{"op":"mcm","clk":"11796020143","pt":1722985542731,"mc":[{"id":"1.231447835","rc":[{"trd":[[2.26,0.78]],"batb":[[0,2.26,29.95]],"ltp":2.26,"tv":0.78,"id":169},{"trd":[[1.8,0.91]],"ltp":1.8,"tv":0.91,"id":2120}],"tv":1.69}]}
{"op":"mcm","clk":"11796020187","pt":1722985543916,"mc":[{"id":"1.231447835","rc":[{"batb":[[0,2.26,30.01]],"ltp":2.26,"tv":0.78,"id":169}]}]}
{"op":"mcm","clk":"11796074093","pt":1722986752058,"mc":[{"id":"1.231447835","rc":[{"trd":[[2.26,0.84]],"batb":[[0,2.26,29.95]],"ltp":2.26,"tv":0.84,"id":169},{"trd":[[1.8,0.98]],"ltp":1.8,"tv":0.98,"id":2120}],"tv":1.82}]}
{"op":"mcm","clk":"11796074192","pt":1722986754579,"mc":[{"id":"1.231447835","rc":[{"batb":[[0,2.26,30.01]],"ltp":2.26,"tv":0.84,"id":169}]}]}
{"op":"mcm","clk":"11796132949","pt":1722987951309,"mc":[{"id":"1.231447835","rc":[{"trd":[[2.26,0.9]],"batb":[[0,2.26,29.95]],"ltp":2.26,"tv":0.9,"id":169},{"trd":[[1.8,1.05]],"ltp":1.8,"tv":1.05,"id":2120}],"tv":1.95}]}
{"op":"mcm","clk":"11796133109","pt":1722987954694,"mc":[{"id":"1.231447835","rc":[{"batb":[[0,2.26,30.01]],"ltp":2.26,"tv":0.9,"id":169}]}]}
{"op":"mcm","clk":"11796189865","pt":1722989153556,"mc":[{"id":"1.231447835","rc":[{"trd":[[2.26,0.96]],"batb":[[0,2.26,29.95]],"ltp":2.26,"tv":0.96,"id":169},{"trd":[[1.8,1.12]],"ltp":1.8,"tv":1.12,"id":2120}],"tv":2.08}]}
{"op":"mcm","clk":"11796189960","pt":1722989155667,"mc":[{"id":"1.231447835","rc":[{"batb":[[0,2.26,30.01]],"ltp":2.26,"tv":0.96,"id":169}]}]}
{"op":"mcm","clk":"11796249818","pt":1722990352222,"mc":[{"id":"1.231447835","rc":[{"trd":[[2.26,1.02]],"batb":[[0,2.26,29.95]],"ltp":2.26,"tv":1.02,"id":169},{"trd":[[1.8,1.19]],"ltp":1.8,"tv":1.19,"id":2120}],"tv":2.21}]}
{"op":"mcm","clk":"11796249858","pt":1722990353454,"mc":[{"id":"1.231447835","rc":[{"batb":[[0,2.26,30.01]],"ltp":2.26,"tv":1.02,"id":169}]}]}
{"op":"mcm","clk":"11796293585","pt":1722991551609,"mc":[{"id":"1.231447835","rc":[{"trd":[[2.26,1.08]],"batb":[[0,2.26,29.95]],"ltp":2.26,"tv":1.08,"id":169},{"trd":[[1.8,1.26]],"ltp":1.8,"tv":1.26,"id":2120}],"tv":2.34}]}
{"op":"mcm","clk":"11796293627","pt":1722991553101,"mc":[{"id":"1.231447835","rc":[{"batb":[[0,2.26,30.01]],"ltp":2.26,"tv":1.08,"id":169}]}]}
{"op":"mcm","clk":"11796341830","pt":1722992752917,"mc":[{"id":"1.231447835","rc":[{"trd":[[2.26,1.14]],"ltp":2.26,"tv":1.14,"id":169},{"trd":[[1.8,1.33]],"ltp":1.8,"tv":1.33,"id":2120}],"tv":2.47}]}
{"op":"mcm","clk":"11796395083","pt":1722993951892,"mc":[{"id":"1.231447835","rc":[{"trd":[[2.26,1.2]],"batb":[[0,2.26,29.95]],"ltp":2.26,"tv":1.2,"id":169},{"trd":[[1.8,1.4]],"ltp":1.8,"tv":1.4,"id":2120}],"tv":2.6}]}
{"op":"mcm","clk":"11796395150","pt":1722993953478,"mc":[{"id":"1.231447835","rc":[{"batb":[[0,2.26,30.01]],"ltp":2.26,"tv":1.2,"id":169}]}]}
{"op":"mcm","clk":"11796446206","pt":1722995151131,"mc":[{"id":"1.231447835","rc":[{"trd":[[2.26,1.26]],"batb":[[0,2.26,29.95]],"ltp":2.26,"tv":1.26,"id":169},{"trd":[[1.8,1.47]],"ltp":1.8,"tv":1.47,"id":2120}],"tv":2.73}]}
{"op":"mcm","clk":"11796446300","pt":1722995153800,"mc":[{"id":"1.231447835","rc":[{"batb":[[0,2.26,30.01]],"ltp":2.26,"tv":1.26,"id":169}]}]}
{"op":"mcm","clk":"11796530186","pt":1722997551102,"mc":[{"id":"1.231447835","rc":[{"trd":[[2.26,1.32]],"batb":[[0,2.26,29.95]],"ltp":2.26,"tv":1.32,"id":169},{"trd":[[1.8,1.54]],"ltp":1.8,"tv":1.54,"id":2120}],"tv":2.86}]}
{"op":"mcm","clk":"11796530359","pt":1722997555855,"mc":[{"id":"1.231447835","rc":[{"batb":[[0,2.26,30.01]],"ltp":2.26,"tv":1.32,"id":169}]}]}
{"op":"mcm","clk":"11796752384","pt":1723007152474,"mc":[{"id":"1.231447835","rc":[{"trd":[[2.26,1.38]],"batb":[[0,2.26,29.95]],"ltp":2.26,"tv":1.38,"id":169},{"trd":[[1.8,1.61]],"ltp":1.8,"tv":1.61,"id":2120}],"tv":2.99}]}
{"op":"mcm","clk":"11796752444","pt":1723007154581,"mc":[{"id":"1.231447835","rc":[{"batb":[[0,2.26,30.01]],"ltp":2.26,"tv":1.38,"id":169}]}]}
{"op":"mcm","clk":"11796961833","pt":1723015552000,"mc":[{"id":"1.231447835","rc":[{"trd":[[2.26,1.44]],"batb":[[0,2.26,29.95]],"ltp":2.26,"tv":1.44,"id":169},{"trd":[[1.8,1.68]],"ltp":1.8,"tv":1.68,"id":2120}],"tv":3.12}]}
{"op":"mcm","clk":"11796961942","pt":1723015554716,"mc":[{"id":"1.231447835","rc":[{"batb":[[0,2.26,30.01]],"ltp":2.26,"tv":1.44,"id":169}]}]}
{"op":"mcm","clk":"11797009986","pt":1723016753050,"mc":[{"id":"1.231447835","rc":[{"trd":[[2.26,1.5]],"batb":[[0,2.26,29.95]],"ltp":2.26,"tv":1.5,"id":169},{"trd":[[1.8,1.75]],"ltp":1.8,"tv":1.75,"id":2120}],"tv":3.25}]}
{"op":"mcm","clk":"11797010051","pt":1723016754742,"mc":[{"id":"1.231447835","rc":[{"batb":[[0,2.26,30.01]],"ltp":2.26,"tv":1.5,"id":169}]}]}
{"op":"mcm","clk":"11797058199","pt":1723017962710,"mc":[{"id":"1.231447835","rc":[{"trd":[[2.26,1.56]],"batb":[[0,2.26,29.95]],"ltp":2.26,"tv":1.56,"id":169},{"trd":[[1.8,1.82]],"ltp":1.8,"tv":1.82,"id":2120}],"tv":3.38}]}
{"op":"mcm","clk":"11797058278","pt":1723017964921,"mc":[{"id":"1.231447835","rc":[{"batb":[[0,2.26,30.01]],"ltp":2.26,"tv":1.56,"id":169}]}]}
{"op":"mcm","clk":"11797091155","pt":1723018859034,"mc":[{"id":"1.231447835","rc":[{"trd":[[1.74,2]],"batb":[[0,1.74,16.32]],"ltp":1.74,"tv":3.82,"id":2120}],"tv":5.38}]}
{"op":"mcm","clk":"11797091475","pt":1723018867441,"mc":[{"id":"1.231447835","rc":[{"trd":[[2.26,3.56]],"batb":[[0,2.26,29.01]],"ltp":2.26,"tv":3.56,"id":169}],"tv":7.38}]}
{"op":"mcm","clk":"11797091626","pt":1723018870773,"mc":[{"id":"1.231447835","rc":[{"trd":[[2.26,5.56]],"batb":[[0,2.26,28.01]],"ltp":2.26,"tv":5.56,"id":169}],"tv":9.37}]}
{"op":"mcm","clk":"11797091693","pt":1723018872267,"mc":[{"id":"1.231447835","rc":[{"batb":[[0,2.26,30.01]],"ltp":2.26,"tv":5.56,"id":169}]}]}
{"op":"mcm","clk":"11797091787","pt":1723018874633,"mc":[{"id":"1.231447835","rc":[{"trd":[[2.26,7.56]],"batb":[[0,2.26,29.01]],"ltp":2.26,"tv":7.56,"id":169}],"tv":11.37}]}
{"op":"mcm","clk":"11797091889","pt":1723018877271,"mc":[{"id":"1.231447835","rc":[{"batb":[[0,2.26,30.01]],"ltp":2.26,"tv":7.56,"id":169}]}]}
{"op":"mcm","clk":"11797390807","pt":1723023963940,"mc":[{"id":"1.231447835","rc":[{"trd":[[2.26,7.62]],"batb":[[0,2.26,29.95]],"ltp":2.26,"tv":7.62,"id":169},{"trd":[[1.8,1.89]],"ltp":1.8,"tv":3.89,"id":2120}],"tv":11.51}]}
{"op":"mcm","clk":"11797391071","pt":1723023967676,"mc":[{"id":"1.231447835","rc":[{"batb":[[0,2.26,30.01]],"ltp":2.26,"tv":7.62,"id":169}]}]}
{"op":"mcm","clk":"11798710557","pt":1723040507745,"mc":[{"id":"1.231447835","rc":[{"batb":[[0,2.26,35.24]],"ltp":2.26,"tv":7.62,"id":169},{"batb":[[1,1.73,60.83]],"ltp":1.8,"tv":3.89,"id":2120}]}]}
{"op":"mcm","clk":"11799183564","pt":1723045656092,"mc":[{"id":"1.231447835","rc":[{"batb":[[2,1.25,100]],"ltp":2.26,"tv":7.62,"id":169},{"batb":[[2,1.25,100]],"ltp":1.8,"tv":3.89,"id":2120}]}]}
{"op":"mcm","clk":"11799293450","pt":1723046785468,"mc":[{"id":"1.231447835","rc":[{"trd":[[2.26,7.68]],"batb":[[0,2.26,35.18]],"ltp":2.26,"tv":7.68,"id":169},{"trd":[[1.8,1.96]],"ltp":1.8,"tv":3.96,"id":2120}],"tv":11.64}]}
{"op":"mcm","clk":"11799293531","pt":1723046786251,"mc":[{"id":"1.231447835","rc":[{"batb":[[0,2.26,35.24]],"ltp":2.26,"tv":7.68,"id":169}]}]}
{"op":"mcm","clk":"11799295423","pt":1723046804789,"mc":[{"id":"1.231447835","rc":[{"batb":[[2,1.08,7.86]],"ltp":2.26,"tv":7.68,"id":169},{"batb":[[2,1.08,7.86]],"ltp":1.8,"tv":3.96,"id":2120}]}]}
{"op":"mcm","clk":"11799304798","pt":1723046893088,"mc":[{"id":"1.231447835","rc":[{"batb":[[2,1.23,217.39]],"ltp":2.26,"tv":7.68,"id":169},{"batb":[[2,1.18,277.78]],"ltp":1.8,"tv":3.96,"id":2120}]}]}
{"op":"mcm","clk":"11799304857","pt":1723046893564,"mc":[{"id":"1.231447835","rc":[{"batb":[[2,1.53,94.34]],"ltp":2.26,"tv":7.68,"id":169},{"batb":[[2,1.53,94.34]],"ltp":1.8,"tv":3.96,"id":2120}]}]}
{"op":"mcm","clk":"11799305292","pt":1723046898071,"mc":[{"id":"1.231447835","rc":[{"batb":[[1,1.73,90.83]],"ltp":1.8,"tv":3.96,"id":2120}]}]}
{"op":"mcm","clk":"11799306084","pt":1723046905814,"mc":[{"id":"1.231447835","rc":[{"batl":[[0,1.84,21.9]],"ltp":1.8,"tv":3.96,"id":2120}]}]}
{"op":"mcm","clk":"11799306418","pt":1723046909015,"mc":[{"id":"1.231447835","rc":[{"batl":[[0,1.85,21.9]],"ltp":1.8,"tv":3.96,"id":2120}]}]}
{"op":"mcm","clk":"11799380050","pt":1723047625985,"mc":[{"id":"1.231447835","rc":[{"batb":[[0,1.74,20.78]],"ltp":1.8,"tv":3.96,"id":2120}]}]}
{"op":"mcm","clk":"11799424993","pt":1723048104845,"mc":[{"id":"1.231447835","rc":[{"batb":[[0,2.26,35.94]],"ltp":2.26,"tv":7.68,"id":169}]}]}
{"op":"mcm","clk":"11799427273","pt":1723048127643,"mc":[{"id":"1.231447835","rc":[{"batb":[[0,2.26,35.24]],"ltp":2.26,"tv":7.68,"id":169}]}]}
{"op":"mcm","clk":"11799428513","pt":1723048141689,"mc":[{"id":"1.231447835","rc":[{"batb":[[0,2.34,1.05],[1,2.26,35.24],[2,1.74,17.32]],"ltp":2.26,"tv":7.68,"id":169}]}]}
{"op":"mcm","clk":"11799429033","pt":1723048146606,"mc":[{"id":"1.231447835","rc":[{"batb":[[0,2.26,35.24],[1,1.74,17.32],[2,1.53,94.34]],"ltp":2.26,"tv":7.68,"id":169}]}]}
{"op":"mcm","clk":"11799430547","pt":1723048161579,"mc":[{"id":"1.231447835","rc":[{"batb":[[0,2.26,36.22]],"ltp":2.26,"tv":7.68,"id":169}]}]}
{"op":"mcm","clk":"11799431428","pt":1723048170902,"mc":[{"id":"1.231447835","rc":[{"batb":[[0,2.26,35.24]],"ltp":2.26,"tv":7.68,"id":169}]}]}
{"op":"mcm","clk":"11799432517","pt":1723048183629,"mc":[{"id":"1.231447835","rc":[{"batb":[[0,2.28,1.4],[1,2.26,35.24],[2,1.74,17.32]],"ltp":2.26,"tv":7.68,"id":169}]}]}
{"op":"mcm","clk":"11799432928","pt":1723048189189,"mc":[{"id":"1.231447835","rc":[{"batb":[[0,2.26,35.24],[1,1.74,17.32],[2,1.53,94.34]],"ltp":2.26,"tv":7.68,"id":169}]}]}
{"op":"mcm","clk":"11799434630","pt":1723048207508,"mc":[{"id":"1.231447835","rc":[{"batb":[[0,2.34,1.4],[1,2.26,35.24],[2,1.74,17.32]],"ltp":2.26,"tv":7.68,"id":169}]}]}
{"op":"mcm","clk":"11799435167","pt":1723048213049,"mc":[{"id":"1.231447835","rc":[{"batb":[[0,2.26,35.24],[1,1.74,17.32],[2,1.53,94.34]],"ltp":2.26,"tv":7.68,"id":169}]}]}
{"op":"mcm","clk":"11799436453","pt":1723048227679,"mc":[{"id":"1.231447835","rc":[{"batl":[[0,2.28,1.4]],"ltp":2.26,"tv":7.68,"id":169}]}]}
{"op":"mcm","clk":"11799436638","pt":1723048229672,"mc":[{"id":"1.231447835","rc":[{"batb":[[0,1.74,16.32]],"ltp":1.8,"tv":3.96,"id":2120}]}]}
{"op":"mcm","clk":"11799438619","pt":1723048249957,"mc":[{"id":"1.231447835","rc":[{"batb":[[0,1.74,20.78]],"ltp":1.8,"tv":3.96,"id":2120}]}]}
{"op":"mcm","clk":"11799439257","pt":1723048256677,"mc":[{"id":"1.231447835","rc":[{"batb":[[0,2.34,1.4],[1,2.26,35.24],[2,1.74,17.32]],"ltp":2.26,"tv":7.68,"id":169}]}]}
{"op":"mcm","clk":"11799439639","pt":1723048261174,"mc":[{"id":"1.231447835","rc":[{"batb":[[0,2.26,35.24],[1,1.74,17.32],[2,1.53,94.34]],"ltp":2.26,"tv":7.68,"id":169}]}]}
{"op":"mcm","clk":"11799440442","pt":1723048270278,"mc":[{"id":"1.231447835","rc":[{"batb":[[0,2.34,1.05],[1,2.26,35.24],[2,1.74,17.32]],"ltp":2.26,"tv":7.68,"id":169}]}]}
{"op":"mcm","clk":"11799441139","pt":1723048277196,"mc":[{"id":"1.231447835","rc":[{"batb":[[0,2.26,35.24],[1,1.74,17.32],[2,1.53,94.34]],"ltp":2.26,"tv":7.68,"id":169}]}]}
{"op":"mcm","clk":"11799442828","pt":1723048294508,"mc":[{"id":"1.231447835","rc":[{"batb":[[0,2.34,1.4],[1,2.26,35.24],[2,1.74,17.32]],"ltp":2.26,"tv":7.68,"id":169}]}]}
{"op":"mcm","clk":"11799443408","pt":1723048301123,"mc":[{"id":"1.231447835","rc":[{"batb":[[0,2.26,35.24],[1,1.74,17.32],[2,1.53,94.34]],"ltp":2.26,"tv":7.68,"id":169}]}]}
{"op":"mcm","clk":"11799445283","pt":1723048319940,"mc":[{"id":"1.231447835","rc":[{"batl":[[0,2.28,1.4]],"ltp":2.26,"tv":7.68,"id":169}]}]}
{"op":"mcm","clk":"11799445408","pt":1723048321039,"mc":[{"id":"1.231447835","rc":[{"batb":[[0,1.74,16.32]],"ltp":1.8,"tv":3.96,"id":2120}]}]}
{"op":"mcm","clk":"11799449605","pt":1723048363466,"mc":[{"id":"1.231447835","rc":[{"batb":[[0,1.74,20.78]],"ltp":1.8,"tv":3.96,"id":2120}]}]}
{"op":"mcm","clk":"11799451490","pt":1723048382485,"mc":[{"id":"1.231447835","rc":[{"batb":[[0,2.34,1.4],[1,2.26,35.24],[2,1.74,17.32]],"ltp":2.26,"tv":7.68,"id":169}]}]}
{"op":"mcm","clk":"11799452163","pt":1723048388415,"mc":[{"id":"1.231447835","rc":[{"batb":[[0,2.26,35.24],[1,1.74,17.32],[2,1.53,94.34]],"ltp":2.26,"tv":7.68,"id":169}]}]}
{"op":"mcm","clk":"11799454217","pt":1723048407430,"mc":[{"id":"1.231447835","rc":[{"batl":[[0,2.28,1.05]],"ltp":2.26,"tv":7.68,"id":169}]}]}
{"op":"mcm","clk":"11799454428","pt":1723048409039,"mc":[{"id":"1.231447835","rc":[{"batb":[[0,1.74,16.32]],"ltp":1.8,"tv":3.96,"id":2120}]}]}
{"op":"mcm","clk":"11799457026","pt":1723048433336,"mc":[{"id":"1.231447835","rc":[{"batb":[[0,2.34,1.05],[1,2.26,35.24],[2,1.74,17.32]],"ltp":2.26,"tv":7.68,"id":169}]}]}
{"op":"mcm","clk":"11799457826","pt":1723048440862,"mc":[{"id":"1.231447835","rc":[{"batb":[[0,2.26,35.24],[1,1.74,17.32],[2,1.53,94.34]],"ltp":2.26,"tv":7.68,"id":169}]}]}
{"op":"mcm","clk":"11799459561","pt":1723048457169,"mc":[{"id":"1.231447835","rc":[{"batl":[[0,2.28,1.05]],"ltp":2.26,"tv":7.68,"id":169}]}]}
{"op":"mcm","clk":"11799461198","pt":1723048474129,"mc":[{"id":"1.231447835","rc":[{"batb":[[0,1.74,20.78]],"ltp":1.8,"tv":3.96,"id":2120}]}]}
{"op":"mcm","clk":"11799462522","pt":1723048486840,"mc":[{"id":"1.231447835","rc":[{"batb":[[0,2.34,1.07],[1,2.26,35.24],[2,1.74,17.32]],"ltp":2.26,"tv":7.68,"id":169}]}]}
{"op":"mcm","clk":"11799463152","pt":1723048492863,"mc":[{"id":"1.231447835","rc":[{"batb":[[0,2.26,35.24],[1,1.74,17.32],[2,1.53,94.34]],"ltp":2.26,"tv":7.68,"id":169}]}]}
{"op":"mcm","clk":"11799465890","pt":1723048519920,"mc":[{"id":"1.231447835","rc":[{"batl":[[0,2.28,1.05]],"ltp":2.26,"tv":7.68,"id":169},{"batb":[[0,1.74,16.32]],"ltp":1.8,"tv":3.96,"id":2120}]}]}
{"op":"mcm","clk":"11799469149","pt":1723048550636,"mc":[{"id":"1.231447835","rc":[{"batb":[[0,2.34,1.05],[1,2.26,35.24],[2,1.74,17.32]],"ltp":2.26,"tv":7.68,"id":169}]}]}
{"op":"mcm","clk":"11799469716","pt":1723048556161,"mc":[{"id":"1.231447835","rc":[{"batb":[[0,2.26,35.24],[1,1.74,17.32],[2,1.53,94.34]],"ltp":2.26,"tv":7.68,"id":169}]}]}
{"op":"mcm","clk":"11799472704","pt":1723048586577,"mc":[{"id":"1.231447835","rc":[{"batb":[[0,1.74,20.78]],"ltp":1.8,"tv":3.96,"id":2120}]}]}
{"op":"mcm","clk":"11799472865","pt":1723048587981,"mc":[{"id":"1.231447835","rc":[{"batl":[[0,2.28,1.05]],"ltp":2.26,"tv":7.68,"id":169}]}]}
{"op":"mcm","clk":"11799472900","pt":1723048588293,"mc":[{"id":"1.231447835","rc":[{"batb":[[0,1.74,16.32]],"ltp":1.8,"tv":3.96,"id":2120}]}]}
{"op":"mcm","clk":"11799478044","pt":1723048639621,"mc":[{"id":"1.231447835","rc":[{"batb":[[0,2.34,1.05],[1,2.26,35.24],[2,1.74,17.32]],"ltp":2.26,"tv":7.68,"id":169}]}]}
{"op":"mcm","clk":"11799478580","pt":1723048645408,"mc":[{"id":"1.231447835","rc":[{"batb":[[0,2.26,35.24],[1,1.74,17.32],[2,1.53,94.34]],"ltp":2.26,"tv":7.68,"id":169}]}]}
{"op":"mcm","clk":"11799480871","pt":1723048672455,"mc":[{"id":"1.231447835","rc":[{"batl":[[0,2.28,1.05]],"ltp":2.26,"tv":7.68,"id":169}]}]}
{"op":"mcm","clk":"11799482456","pt":1723048690471,"mc":[{"id":"1.231447835","rc":[{"batb":[[0,1.74,20.78]],"ltp":1.8,"tv":3.96,"id":2120}]}]}
{"op":"mcm","clk":"11799485427","pt":1723048724316,"mc":[{"id":"1.231447835","rc":[{"batb":[[0,2.34,1.05],[1,2.26,35.24],[2,1.74,17.32]],"ltp":2.26,"tv":7.68,"id":169}]}]}
{"op":"mcm","clk":"11799486065","pt":1723048731622,"mc":[{"id":"1.231447835","rc":[{"batb":[[0,2.26,35.24],[1,1.74,17.32],[2,1.53,94.34]],"ltp":2.26,"tv":7.68,"id":169}]}]}
{"op":"mcm","clk":"11799493471","pt":1723048816305,"mc":[{"id":"1.231447835","rc":[{"batl":[[0,2.28,1.05]],"ltp":2.26,"tv":7.68,"id":169}]}]}
{"op":"mcm","clk":"11799493637","pt":1723048818131,"mc":[{"id":"1.231447835","rc":[{"batb":[[0,1.74,16.32]],"ltp":1.8,"tv":3.96,"id":2120}]}]}
{"op":"mcm","clk":"11799496653","pt":1723048854455,"mc":[{"id":"1.231447835","rc":[{"batb":[[0,1.74,20.78]],"ltp":1.8,"tv":3.96,"id":2120}]}]}
{"op":"mcm","clk":"11799496893","pt":1723048857559,"mc":[{"id":"1.231447835","rc":[{"batl":[[0,2.28,1.05]],"ltp":2.26,"tv":7.68,"id":169}]}]}
{"op":"mcm","clk":"11799497014","pt":1723048858979,"mc":[{"id":"1.231447835","rc":[{"batb":[[0,1.74,16.32]],"ltp":1.8,"tv":3.96,"id":2120}]}]}
{"op":"mcm","clk":"11799498968","pt":1723048881460,"mc":[{"id":"1.231447835","rc":[{"batb":[[0,2.34,1.05],[1,2.26,35.24],[2,1.74,17.32]],"ltp":2.26,"tv":7.68,"id":169}]}]}
{"op":"mcm","clk":"11799499478","pt":1723048887899,"mc":[{"id":"1.231447835","rc":[{"batb":[[0,2.26,35.24],[1,1.74,17.32],[2,1.53,94.34]],"ltp":2.26,"tv":7.68,"id":169}]}]}
{"op":"mcm","clk":"11799501148","pt":1723048909539,"mc":[{"id":"1.231447835","rc":[{"batl":[[0,2.28,1.05]],"ltp":2.26,"tv":7.68,"id":169}]}]}
{"op":"mcm","clk":"11799503494","pt":1723048942116,"mc":[{"id":"1.231447835","rc":[{"batb":[[0,2.34,1.05],[1,2.26,35.24],[2,1.74,17.32]],"ltp":2.26,"tv":7.68,"id":169}]}]}
{"op":"mcm","clk":"11799503992","pt":1723048948773,"mc":[{"id":"1.231447835","rc":[{"batb":[[0,2.26,35.24],[1,1.74,17.32],[2,1.53,94.34]],"ltp":2.26,"tv":7.68,"id":169}]}]}
{"op":"mcm","clk":"11799505401","pt":1723048968184,"mc":[{"id":"1.231447835","rc":[{"batb":[[0,1.74,20.78]],"ltp":1.8,"tv":3.96,"id":2120}]}]}
{"op":"mcm","clk":"11799515136","pt":1723048981293,"mc":[{"id":"1.231447835","rc":[{"batl":[[0,2.28,1.05]],"ltp":2.26,"tv":7.68,"id":169}]}]}
{"op":"mcm","clk":"11799515204","pt":1723048982228,"mc":[{"id":"1.231447835","rc":[{"batb":[[0,1.74,16.32]],"ltp":1.8,"tv":3.96,"id":2120}]}]}
{"op":"mcm","clk":"11799517574","pt":1723049013240,"mc":[{"id":"1.231447835","rc":[{"batb":[[0,2.34,1.05],[1,2.26,35.24],[2,1.74,17.32]],"ltp":2.26,"tv":7.68,"id":169}]}]}
{"op":"mcm","clk":"11799518105","pt":1723049019884,"mc":[{"id":"1.231447835","rc":[{"batb":[[0,2.26,35.24],[1,1.74,17.32],[2,1.53,94.34]],"ltp":2.26,"tv":7.68,"id":169}]}]}
{"op":"mcm","clk":"11799520508","pt":1723049050083,"mc":[{"id":"1.231447835","rc":[{"batl":[[0,2.28,1.05]],"ltp":2.26,"tv":7.68,"id":169}]}]}
{"op":"mcm","clk":"11799523354","pt":1723049084438,"mc":[{"id":"1.231447835","rc":[{"batb":[[0,1.74,20.78]],"ltp":1.8,"tv":3.96,"id":2120}]}]}
{"op":"mcm","clk":"11799523572","pt":1723049087368,"mc":[{"id":"1.231447835","rc":[{"batb":[[0,2.34,1.05],[1,2.26,35.24],[2,1.74,17.32]],"ltp":2.26,"tv":7.68,"id":169}]}]}
{"op":"mcm","clk":"11799524193","pt":1723049095660,"mc":[{"id":"1.231447835","rc":[{"batb":[[0,2.26,35.24],[1,1.74,17.32],[2,1.53,94.34]],"ltp":2.26,"tv":7.68,"id":169}]}]}
{"op":"mcm","clk":"11799525319","pt":1723049109286,"mc":[{"id":"1.231447835","rc":[{"batb":[[0,2.34,1.05],[1,2.26,35.24],[2,1.74,17.32]],"ltp":2.26,"tv":7.68,"id":169}]}]}
{"op":"mcm","clk":"11799526058","pt":1723049117676,"mc":[{"id":"1.231447835","rc":[{"batb":[[0,2.26,35.24],[1,1.74,17.32],[2,1.53,94.34]],"ltp":2.26,"tv":7.68,"id":169}]}]}
{"op":"mcm","clk":"11799528808","pt":1723049150914,"mc":[{"id":"1.231447835","rc":[{"batl":[[0,2.28,1.05]],"ltp":2.26,"tv":7.68,"id":169}]}]}
{"op":"mcm","clk":"11799528842","pt":1723049151456,"mc":[{"id":"1.231447835","rc":[{"batb":[[0,1.74,16.32]],"ltp":1.8,"tv":3.96,"id":2120}]}]}
{"op":"mcm","clk":"11799529863","pt":1723049163054,"mc":[{"id":"1.231447835","rc":[{"trd":[[1.8,2.03]],"ltp":1.8,"tv":4.03,"id":2120},{"trd":[[2.26,7.74]],"batb":[[0,2.26,35.18]],"ltp":2.26,"tv":7.74,"id":169}],"tv":11.77}]}
{"op":"mcm","clk":"11799530287","pt":1723049167248,"mc":[{"id":"1.231447835","rc":[{"batb":[[0,2.26,35.24]],"ltp":2.26,"tv":7.74,"id":169}]}]}
{"op":"mcm","clk":"11799532653","pt":1723049196195,"mc":[{"id":"1.231447835","rc":[{"batb":[[0,1.74,20.78]],"ltp":1.8,"tv":4.03,"id":2120}]}]}
{"op":"mcm","clk":"11799533624","pt":1723049209006,"mc":[{"id":"1.231447835","rc":[{"batb":[[0,2.34,1.05],[1,2.26,35.24],[2,1.74,17.32]],"ltp":2.26,"tv":7.74,"id":169}]}]}
{"op":"mcm","clk":"11799534032","pt":1723049214105,"mc":[{"id":"1.231447835","rc":[{"batb":[[0,2.26,35.24],[1,1.74,17.32],[2,1.53,94.34]],"ltp":2.26,"tv":7.74,"id":169}]}]}
{"op":"mcm","clk":"11799539860","pt":1723049287771,"mc":[{"id":"1.231447835","rc":[{"batb":[[0,1.74,16.32]],"ltp":1.8,"tv":4.03,"id":2120},{"batl":[[0,2.28,1.05]],"ltp":2.26,"tv":7.74,"id":169}]}]}
{"op":"mcm","clk":"11799541775","pt":1723049311813,"mc":[{"id":"1.231447835","rc":[{"batb":[[0,1.74,20.78]],"ltp":1.8,"tv":4.03,"id":2120}]}]}
{"op":"mcm","clk":"11799543225","pt":1723049329640,"mc":[{"id":"1.231447835","rc":[{"batb":[[0,2.34,1.05],[1,2.26,35.24],[2,1.74,17.32]],"ltp":2.26,"tv":7.74,"id":169}]}]}
{"op":"mcm","clk":"11799543579","pt":1723049335204,"mc":[{"id":"1.231447835","rc":[{"batb":[[0,2.26,35.24],[1,1.74,17.32],[2,1.53,94.34]],"ltp":2.26,"tv":7.74,"id":169}]}]}
{"op":"mcm","clk":"11799545661","pt":1723049363241,"mc":[{"id":"1.231447835","rc":[{"batl":[[0,2.28,1.05]],"ltp":2.26,"tv":7.74,"id":169}]}]}
{"op":"mcm","clk":"11799545828","pt":1723049365366,"mc":[{"id":"1.231447835","rc":[{"batb":[[0,1.74,16.32]],"ltp":1.8,"tv":4.03,"id":2120}]}]}
{"op":"mcm","clk":"11799550311","pt":1723049426834,"mc":[{"id":"1.231447835","rc":[{"batb":[[0,1.74,20.78]],"ltp":1.8,"tv":4.03,"id":2120}]}]}
{"op":"mcm","clk":"11799550990","pt":1723049436475,"mc":[{"id":"1.231447835","rc":[{"batb":[[0,2.34,1.05],[1,2.26,35.24],[2,1.74,17.32]],"ltp":2.26,"tv":7.74,"id":169}]}]}
{"op":"mcm","clk":"11799551630","pt":1723049445381,"mc":[{"id":"1.231447835","rc":[{"batb":[[0,2.26,35.24],[1,1.74,17.32],[2,1.53,94.34]],"ltp":2.26,"tv":7.74,"id":169}]}]}
{"op":"mcm","clk":"11799553161","pt":1723049468169,"mc":[{"id":"1.231447835","rc":[{"batl":[[0,2.28,1.05]],"ltp":2.26,"tv":7.74,"id":169}]}]}
{"op":"mcm","clk":"11799553236","pt":1723049469309,"mc":[{"id":"1.231447835","rc":[{"batb":[[0,1.74,16.32]],"ltp":1.8,"tv":4.03,"id":2120}]}]}
{"op":"mcm","clk":"11799554777","pt":1723049490108,"mc":[{"id":"1.231447835","rc":[{"batl":[[0,1.8,100],[1,1.85,21.9]],"ltp":1.8,"tv":4.03,"id":2120}]}]}
{"op":"mcm","clk":"11799555214","pt":1723049495229,"mc":[{"id":"1.231447835","rc":[{"batl":[[1,1.81,200],[2,1.85,21.9]],"ltp":1.8,"tv":4.03,"id":2120}]}]}
{"op":"mcm","clk":"11799555610","pt":1723049499846,"mc":[{"id":"1.231447835","rc":[{"batl":[[2,1.82,300]],"ltp":1.8,"tv":4.03,"id":2120}]}]}
{"op":"mcm","clk":"11799556222","pt":1723049507726,"mc":[{"id":"1.231447835","rc":[{"batl":[[0,2.28,1.05]],"ltp":2.26,"tv":7.74,"id":169}]}]}
{"op":"mcm","clk":"11799558122","pt":1723049532176,"mc":[{"id":"1.231447835","rc":[{"batb":[[0,1.74,20.78]],"ltp":1.8,"tv":4.03,"id":2120}]}]}
{"op":"mcm","clk":"11799560039","pt":1723049556931,"mc":[{"id":"1.231447835","rc":[{"batb":[[0,2.34,1.05],[1,2.26,35.24],[2,1.74,17.32]],"ltp":2.26,"tv":7.74,"id":169}]}]}
{"op":"mcm","clk":"11799560529","pt":1723049563305,"mc":[{"id":"1.231447835","rc":[{"batb":[[0,2.26,35.24],[1,1.74,17.32],[2,1.53,94.34]],"ltp":2.26,"tv":7.74,"id":169}]}]}
{"op":"mcm","clk":"11799563638","pt":1723049601355,"mc":[{"id":"1.231447835","rc":[{"batl":[[0,2.28,1.05]],"ltp":2.26,"tv":7.74,"id":169}]}]}
{"op":"mcm","clk":"11799563826","pt":1723049603487,"mc":[{"id":"1.231447835","rc":[{"batb":[[0,1.74,16.32]],"ltp":1.8,"tv":4.03,"id":2120}]}]}
{"op":"mcm","clk":"11799566705","pt":1723049640873,"mc":[{"id":"1.231447835","rc":[{"batb":[[0,1.74,20.78]],"ltp":1.8,"tv":4.03,"id":2120}]}]}
{"op":"mcm","clk":"11799567662","pt":1723049654096,"mc":[{"id":"1.231447835","rc":[{"batb":[[0,2.34,1.05],[1,2.26,35.24],[2,1.74,17.32]],"ltp":2.26,"tv":7.74,"id":169}]}]}
{"op":"mcm","clk":"11799568228","pt":1723049661539,"mc":[{"id":"1.231447835","rc":[{"batb":[[0,2.26,35.24],[1,1.74,17.32],[2,1.53,94.34]],"ltp":2.26,"tv":7.74,"id":169}]}]}
{"op":"mcm","clk":"11799570901","pt":1723049695283,"mc":[{"id":"1.231447835","rc":[{"batb":[[0,2.34,1.05],[1,2.26,35.24],[2,1.74,17.32]],"ltp":2.26,"tv":7.74,"id":169}]}]}
{"op":"mcm","clk":"11799571518","pt":1723049702460,"mc":[{"id":"1.231447835","rc":[{"batb":[[0,2.26,35.24],[1,1.74,17.32],[2,1.53,94.34]],"ltp":2.26,"tv":7.74,"id":169}]}]}
{"op":"mcm","clk":"11799574233","pt":1723049733332,"mc":[{"id":"1.231447835","rc":[{"batl":[[0,2.28,1.05]],"ltp":2.26,"tv":7.74,"id":169}]}]}
{"op":"mcm","clk":"11799574353","pt":1723049734632,"mc":[{"id":"1.231447835","rc":[{"batb":[[0,1.74,16.32]],"ltp":1.8,"tv":4.03,"id":2120}]}]}
{"op":"mcm","clk":"11799576760","pt":1723049763035,"mc":[{"id":"1.231447835","rc":[{"batb":[[0,1.74,20.78]],"ltp":1.8,"tv":4.03,"id":2120}]}]}
{"op":"mcm","clk":"11799579501","pt":1723049796564,"mc":[{"id":"1.231447835","rc":[{"batb":[[0,2.34,1.05],[1,2.26,35.24],[2,1.74,17.32]],"ltp":2.26,"tv":7.74,"id":169}]}]}
{"op":"mcm","clk":"11799580109","pt":1723049804577,"mc":[{"id":"1.231447835","rc":[{"batb":[[0,2.26,35.24],[1,1.74,17.32],[2,1.53,94.34]],"ltp":2.26,"tv":7.74,"id":169}]}]}
{"op":"mcm","clk":"11799582980","pt":1723049843197,"mc":[{"id":"1.231447835","rc":[{"batl":[[0,2.28,1.05]],"ltp":2.26,"tv":7.74,"id":169}]}]}
{"op":"mcm","clk":"11799583150","pt":1723049845332,"mc":[{"id":"1.231447835","rc":[{"batb":[[0,1.74,16.32]],"ltp":1.8,"tv":4.03,"id":2120}]}]}
{"op":"mcm","clk":"11799585476","pt":1723049879440,"mc":[{"id":"1.231447835","rc":[{"batb":[[0,2.34,1.05],[1,2.26,35.24],[2,1.74,17.32]],"ltp":2.26,"tv":7.74,"id":169}]}]}
{"op":"mcm","clk":"11799585764","pt":1723049884284,"mc":[{"id":"1.231447835","rc":[{"batb":[[0,1.74,20.78]],"ltp":1.8,"tv":4.03,"id":2120}]}]}
{"op":"mcm","clk":"11799585866","pt":1723049886051,"mc":[{"id":"1.231447835","rc":[{"batb":[[0,2.26,35.24],[1,1.74,17.32],[2,1.53,94.34]],"ltp":2.26,"tv":7.74,"id":169}]}]}
{"op":"mcm","clk":"11799590706","pt":1723049955458,"mc":[{"id":"1.231447835","rc":[{"batl":[[0,2.28,1.05]],"ltp":2.26,"tv":7.74,"id":169}]}]}
{"op":"mcm","clk":"11799590821","pt":1723049956767,"mc":[{"id":"1.231447835","rc":[{"batb":[[0,1.74,16.32]],"ltp":1.8,"tv":4.03,"id":2120}]}]}
{"op":"mcm","clk":"11799594048","pt":1723049995927,"mc":[{"id":"1.231447835","rc":[{"batb":[[0,2.34,1.05],[1,2.26,35.24],[2,1.74,17.32]],"ltp":2.26,"tv":7.74,"id":169}]}]}
{"op":"mcm","clk":"11799594767","pt":1723050002523,"mc":[{"id":"1.231447835","rc":[{"batb":[[0,2.26,35.24],[1,1.74,17.32],[2,1.53,94.34]],"ltp":2.26,"tv":7.74,"id":169}]}]}
{"op":"mcm","clk":"11799595087","pt":1723050005818,"mc":[{"id":"1.231447835","rc":[{"batb":[[0,1.74,20.78]],"ltp":1.8,"tv":4.03,"id":2120}]}]}
{"op":"mcm","clk":"11799602967","pt":1723050090909,"mc":[{"id":"1.231447835","rc":[{"batl":[[0,2.28,1.05]],"ltp":2.26,"tv":7.74,"id":169}]}]}
{"op":"mcm","clk":"11799603235","pt":1723050093110,"mc":[{"id":"1.231447835","rc":[{"batb":[[0,1.74,16.32]],"ltp":1.8,"tv":4.03,"id":2120}]}]}
{"op":"mcm","clk":"11799606388","pt":1723050129504,"mc":[{"id":"1.231447835","rc":[{"batb":[[0,1.74,20.78]],"ltp":1.8,"tv":4.03,"id":2120}]}]}
{"op":"mcm","clk":"11799614801","pt":1723050214906,"mc":[{"id":"1.231447835","rc":[{"batl":[[0,1.79,7.08],[1,1.8,100],[2,1.81,200]],"ltp":1.8,"tv":4.03,"id":2120}]}]}
{"op":"mcm","clk":"11799619535","pt":1723050259400,"mc":[{"id":"1.231447835","rc":[{"batb":[[0,2.34,1.05],[1,2.26,35.24],[2,1.74,17.32]],"ltp":2.26,"tv":7.74,"id":169}]}]}
{"op":"mcm","clk":"11799620275","pt":1723050266620,"mc":[{"id":"1.231447835","rc":[{"batb":[[0,2.26,35.24],[1,1.74,17.32],[2,1.53,94.34]],"ltp":2.26,"tv":7.74,"id":169}]}]}
{"op":"mcm","clk":"11799623663","pt":1723050300988,"mc":[{"id":"1.231447835","rc":[{"batl":[[0,2.28,1.05]],"ltp":2.26,"tv":7.74,"id":169}]}]}
{"op":"mcm","clk":"11799623821","pt":1723050302363,"mc":[{"id":"1.231447835","rc":[{"batb":[[0,1.74,16.32]],"ltp":1.8,"tv":4.03,"id":2120}]}]}
{"op":"mcm","clk":"11799624501","pt":1723050309206,"mc":[{"id":"1.231447835","rc":[{"batb":[[0,1.74,20.78]],"ltp":1.8,"tv":4.03,"id":2120}]}]}
{"op":"mcm","clk":"11799627719","pt":1723050342023,"mc":[{"id":"1.231447835","rc":[{"batl":[[0,2.28,1.05]],"ltp":2.26,"tv":7.74,"id":169}]}]}
{"op":"mcm","clk":"11799627886","pt":1723050343599,"mc":[{"id":"1.231447835","rc":[{"batb":[[0,1.74,16.32]],"ltp":1.8,"tv":4.03,"id":2120}]}]}
{"op":"mcm","clk":"11799635808","pt":1723050421464,"mc":[{"id":"1.231447835","rc":[{"batb":[[0,2.34,1.05],[1,2.26,35.24],[2,1.74,17.32]],"ltp":2.26,"tv":7.74,"id":169}]}]}
{"op":"mcm","clk":"11799636370","pt":1723050425943,"mc":[{"id":"1.231447835","rc":[{"batb":[[0,1.74,20.78]],"ltp":1.8,"tv":4.03,"id":2120}]}]}
{"op":"mcm","clk":"11799637133","pt":1723050432760,"mc":[{"id":"1.231447835","rc":[{"batb":[[0,2.26,35.24],[1,1.74,17.32],[2,1.53,94.34]],"ltp":2.26,"tv":7.74,"id":169}]}]}
{"op":"mcm","clk":"11799643236","pt":1723050488807,"mc":[{"id":"1.231447835","rc":[{"batb":[[0,1.74,16.32]],"ltp":1.8,"tv":4.03,"id":2120},{"batl":[[0,2.28,1.05]],"ltp":2.26,"tv":7.74,"id":169}]}]}
{"op":"mcm","clk":"11799646985","pt":1723050532348,"mc":[{"id":"1.231447835","rc":[{"batb":[[0,2.34,1.05],[1,2.26,35.24],[2,1.74,17.32]],"ltp":2.26,"tv":7.74,"id":169}]}]}
{"op":"mcm","clk":"11799647732","pt":1723050540697,"mc":[{"id":"1.231447835","rc":[{"batb":[[0,2.34,2.1]],"ltp":2.26,"tv":7.74,"id":169}]}]}
{"op":"mcm","clk":"11799648005","pt":1723050543390,"mc":[{"id":"1.231447835","rc":[{"batb":[[0,1.74,20.78]],"ltp":1.8,"tv":4.03,"id":2120}]}]}
{"op":"mcm","clk":"11799648316","pt":1723050546282,"mc":[{"id":"1.231447835","rc":[{"batb":[[0,2.34,1.05]],"ltp":2.26,"tv":7.74,"id":169}]}]}
{"op":"mcm","clk":"11799649207","pt":1723050555899,"mc":[{"id":"1.231447835","rc":[{"batb":[[0,2.26,35.24],[1,1.74,17.32],[2,1.53,94.34]],"ltp":2.26,"tv":7.74,"id":169}]}]}
{"op":"mcm","clk":"11800092298","pt":1723054374908,"mc":[{"id":"1.231447835","rc":[{"batb":[[0,1.74,20.79]],"batl":[[0,1.79,7.09]],"ltp":1.8,"tv":4.03,"id":2120}]}]}
{"op":"mcm","clk":"11800533075","pt":1723057406288,"mc":[{"id":"1.231447835","rc":[{"batb":[[0,1.74,20.79],[1,1.73,60.83]],"batl":[[0,1.79,7.09]],"ltp":1.8,"tv":4.03,"id":2120}]}]}
{"op":"mcm","clk":"11800533213","pt":1723057407116,"mc":[{"id":"1.231447835","rc":[{"batb":[[0,1.74,16.32]],"ltp":1.8,"tv":4.03,"id":2120}]}]}
{"op":"mcm","clk":"11800535161","pt":1723057420809,"mc":[{"id":"1.231447835","rc":[{"batb":[[1,1.73,95.83]],"ltp":1.8,"tv":4.03,"id":2120}]}]}
{"op":"mcm","clk":"11800535280","pt":1723057421709,"mc":[{"id":"1.231447835","rc":[{"batb":[[0,1.74,21.03]],"ltp":1.8,"tv":4.03,"id":2120}]}]}
{"op":"mcm","clk":"11800625241","pt":1723058066417,"mc":[{"id":"1.231447835","rc":[{"batl":[[0,1.77,100],[1,1.78,200],[2,1.79,307.09]],"ltp":1.8,"tv":4.03,"id":2120}]}]}
{"op":"mcm","clk":"11800625509","pt":1723058068332,"mc":[{"id":"1.231447835","rc":[{"batl":[[2,1.79,300]],"ltp":1.8,"tv":4.03,"id":2120}]}]}
{"op":"mcm","clk":"11800717686","pt":1723058789917,"mc":[{"id":"1.231447835","rc":[{"batb":[[0,2.3,11.47],[1,2.26,35.24],[2,1.74,17.32]],"ltp":2.26,"tv":7.74,"id":169},{"batl":[[0,1.76,4.91],[1,1.77,100],[2,1.78,200]],"ltp":1.8,"tv":4.03,"id":2120}]}]}
{"op":"mcm","clk":"11800718315","pt":1723058794619,"mc":[{"id":"1.231447835","rc":[{"batb":[[1,1.74,17.32],[2,1.53,94.34]],"ltp":2.26,"tv":7.74,"id":169},{"batb":[[1,1.73,35]],"ltp":1.8,"tv":4.03,"id":2120}]}]}
{"op":"mcm","clk":"11800718430","pt":1723058795706,"mc":[{"id":"1.231447835","rc":[{"batb":[[0,1.74,16.32]],"ltp":1.8,"tv":4.03,"id":2120}]}]}
{"op":"mcm","clk":"11800730827","pt":1723058895528,"mc":[{"id":"1.231447835","rc":[{"trd":[[1.76,5.54]],"batl":[[0,1.76,2.13]],"ltp":1.76,"tv":9.57,"id":2120}],"tv":17.31}]}
{"op":"mcm","clk":"11800745479","pt":1723059015987,"mc":[{"id":"1.231447835","rc":[{"batb":[[2,1.61,4.58]],"ltp":1.76,"tv":9.57,"id":2120}]}]}
{"op":"mcm","clk":"11800752160","pt":1723059070261,"mc":[{"id":"1.231447835","rc":[{"batl":[[0,2.62,4.58]],"ltp":2.26,"tv":7.74,"id":169}]}]}
{"op":"mcm","clk":"11800753454","pt":1723059080957,"mc":[{"id":"1.231447835","rc":[{"batb":[[1,2.04,4.58],[2,1.74,17.32]],"ltp":2.26,"tv":7.74,"id":169}]}]}
{"op":"mcm","clk":"11800866219","pt":1723059899016,"mc":[{"id":"1.231447835","rc":[{"trd":[[2.3,8]],"batb":[[0,2.3,7.47]],"ltp":2.3,"tv":15.74,"id":169}],"tv":25.31}]}
{"op":"mcm","clk":"11800993356","pt":1723061177991,"mc":[{"id":"1.231447835","rc":[{"batb":[[1,2.04,4.58]],"batl":[[0,2.62,4.58]],"ltp":2.3,"tv":15.74,"id":169},{"trd":[[1.76,9.81],[1.77,6.56]],"batb":[[2,1.61,4.58]],"batl":[[0,1.77,96.72],[1,1.78,200],[2,1.79,300]],"ltp":1.77,"tv":20.4,"id":2120}],"tv":36.14}]}
{"op":"mcm","clk":"11800993396","pt":1723061178370,"mc":[{"id":"1.231447835","rc":[{"batb":[[0,1.74,21.28]],"ltp":1.77,"tv":20.4,"id":2120}]}]}
{"op":"mcm","clk":"11801102344","pt":1723062514833,"mc":[{"id":"1.231447835","rc":[{"batb":[[0,1.75,51.1],[1,1.74,21.28],[2,1.73,35]],"ltp":1.77,"tv":20.4,"id":2120}]}]}
{"op":"mcm","clk":"11801102385","pt":1723062515601,"mc":[{"id":"1.231447835","rc":[{"batb":[[0,1.76,4.91],[1,1.75,51.1],[2,1.74,16.32]],"ltp":1.77,"tv":20.4,"id":2120}]}]}
{"op":"mcm","clk":"11801109902","pt":1723062652181,"mc":[{"id":"1.231447835","rc":[{"batl":[[0,2.32,10],[1,2.62,4.58]],"ltp":2.3,"tv":15.74,"id":169}]}]}
{"op":"mcm","clk":"11801118692","pt":1723062807643,"mc":[{"id":"1.231447835","rc":[{"batb":[[1,1.74,16.32],[2,1.73,35]],"ltp":1.77,"tv":20.4,"id":2120}]}]}
{"op":"mcm","clk":"11801118853","pt":1723062810371,"mc":[{"id":"1.231447835","rc":[{"batl":[[2,1.79,303]],"ltp":1.77,"tv":20.4,"id":2120}]}]}
{"op":"mcm","clk":"11801237877","pt":1723065174865,"mc":[{"id":"1.231447835","rc":[{"trd":[[1.76,9.81],[1.77,6.56]],"ltp":1.77,"tv":20.4,"id":2120},{"batb":[[1,2.04,4.58]],"batl":[[1,2.62,4.58]],"ltp":2.3,"tv":15.74,"id":169}],"tv":36.14}]}
{"op":"mcm","clk":"11801249719","pt":1723065287400,"mc":[{"id":"1.231447835","rc":[{"batb":[[1,1.74,17.32],[2,1.53,94.34]],"batl":[[1,2.62,0]],"ltp":2.3,"tv":15.74,"id":169}]}]}
{"op":"mcm","clk":"11801283046","pt":1723066037295,"mc":[{"id":"1.231447835","rc":[{"trd":[[2.3,22.94]],"batb":[[0,1.75,10]],"batl":[[0,2.32,10.53]],"ltp":2.3,"tv":30.68,"id":169}],"tv":51.08}]}
{"op":"mcm","clk":"11801283080","pt":1723066038270,"mc":[{"id":"1.231447835","rc":[{"batl":[[1,2.34,11.27]],"ltp":2.3,"tv":30.68,"id":169}]}]}
{"op":"mcm","clk":"11801283108","pt":1723066039194,"mc":[{"id":"1.231447835","rc":[{"batb":[[1,1.74,76.33]],"ltp":1.77,"tv":20.4,"id":2120},{"batb":[[0,2.24,35.81],[1,1.75,10],[2,1.74,17.32]],"ltp":2.3,"tv":30.68,"id":169}]}]}
{"op":"mcm","clk":"11801283163","pt":1723066040577,"mc":[{"id":"1.231447835","rc":[{"batb":[[1,1.74,17.32],[2,1.53,94.34]],"ltp":2.3,"tv":30.68,"id":169}]}]}
{"op":"mcm","clk":"11801499508","pt":1723070574872,"mc":[{"id":"1.231447835","rc":[{"trd":[[2.3,22.94]],"batl":[[1,2.34,11.27]],"ltp":2.3,"tv":30.68,"id":169},{"trd":[[1.76,9.81]],"ltp":1.77,"tv":20.4,"id":2120}],"tv":51.08}]}
{"op":"mcm","clk":"11801632292","pt":1723073963392,"mc":[{"id":"1.231447835","rc":[{"trd":[[2.3,22.95]],"batl":[[1,2.34,11.28]],"ltp":2.3,"tv":30.69,"id":169},{"trd":[[1.76,11.81],[1.77,6.56]],"batb":[[0,1.76,3.91]],"ltp":1.76,"tv":22.4,"id":2120}],"tv":53.09}]}
{"op":"mcm","clk":"11801656169","pt":1723074709553,"mc":[{"id":"1.231447835","rc":[{"batl":[[2,1.79,323.55]],"ltp":1.76,"tv":22.4,"id":2120}]}]}
{"op":"mcm","clk":"11801700475","pt":1723075974887,"mc":[{"id":"1.231447835","rc":[{"trd":[[1.76,11.82],[1.77,6.57]],"batb":[[0,1.76,3.91]],"batl":[[2,1.79,323.55]],"ltp":1.76,"tv":22.41,"id":2120},{"trd":[[2.3,22.96]],"batl":[[1,2.34,11.29]],"ltp":2.3,"tv":30.69,"id":169}],"tv":53.11}]}
{"op":"mcm","clk":"11801833514","pt":1723079556952,"mc":[{"id":"1.231447835","rc":[{"batb":[[1,1.75,59.21],[2,1.74,16.32]],"batl":[[2,1.79,323.56]],"ltp":1.76,"tv":22.41,"id":2120},{"trd":[[2.3,22.96]],"batb":[[0,2.22,36.4]],"batl":[[1,2.34,11.29]],"ltp":2.3,"tv":30.69,"id":169}],"tv":53.11}]}
{"op":"mcm","clk":"11801833522","pt":1723079557158,"mc":[{"id":"1.231447835","rc":[{"batb":[[0,2.24,10],[1,2.22,36.4],[2,1.74,17.32]],"ltp":2.3,"tv":30.69,"id":169}]}]}
{"op":"mcm","clk":"11801833650","pt":1723079560561,"mc":[{"id":"1.231447835","rc":[{"batb":[[0,2.22,36.4],[1,1.74,17.32],[2,1.53,94.34]],"ltp":2.3,"tv":30.69,"id":169}]}]}
{"op":"mcm","clk":"11801833730","pt":1723079562975,"mc":[{"id":"1.231447835","rc":[{"batb":[[0,2.24,10],[1,2.22,36.4],[2,1.74,17.32]],"ltp":2.3,"tv":30.69,"id":169}]}]}
{"op":"mcm","clk":"11801833837","pt":1723079566360,"mc":[{"id":"1.231447835","rc":[{"batb":[[0,2.22,36.4],[1,1.74,17.32],[2,1.53,94.34]],"ltp":2.3,"tv":30.69,"id":169}]}]}
{"op":"mcm","clk":"11801833950","pt":1723079569349,"mc":[{"id":"1.231447835","rc":[{"batb":[[0,2.24,10],[1,2.22,36.4],[2,1.74,17.32]],"ltp":2.3,"tv":30.69,"id":169}]}]}
{"op":"mcm","clk":"11801834040","pt":1723079572684,"mc":[{"id":"1.231447835","rc":[{"batb":[[0,2.22,36.4],[1,1.74,17.32],[2,1.53,94.34]],"ltp":2.3,"tv":30.69,"id":169}]}]}
{"op":"mcm","clk":"11801834126","pt":1723079575159,"mc":[{"id":"1.231447835","rc":[{"batb":[[0,2.24,10],[1,2.22,36.4],[2,1.74,17.32]],"ltp":2.3,"tv":30.69,"id":169}]}]}
{"op":"mcm","clk":"11801834215","pt":1723079578494,"mc":[{"id":"1.231447835","rc":[{"batb":[[0,2.22,36.4],[1,1.74,17.32],[2,1.53,94.34]],"ltp":2.3,"tv":30.69,"id":169}]}]}
{"op":"mcm","clk":"11801834313","pt":1723079581080,"mc":[{"id":"1.231447835","rc":[{"batb":[[0,2.24,10],[1,2.22,36.4],[2,1.74,17.32]],"ltp":2.3,"tv":30.69,"id":169}]}]}
{"op":"mcm","clk":"11801834414","pt":1723079584480,"mc":[{"id":"1.231447835","rc":[{"batb":[[0,2.22,36.4],[1,1.74,17.32],[2,1.53,94.34]],"ltp":2.3,"tv":30.69,"id":169}]}]}
{"op":"mcm","clk":"11801834482","pt":1723079586896,"mc":[{"id":"1.231447835","rc":[{"batb":[[0,2.24,10],[1,2.22,36.4],[2,1.74,17.32]],"ltp":2.3,"tv":30.69,"id":169}]}]}
{"op":"mcm","clk":"11801834570","pt":1723079590185,"mc":[{"id":"1.231447835","rc":[{"batb":[[0,2.22,36.4],[1,1.74,17.32],[2,1.53,94.34]],"ltp":2.3,"tv":30.69,"id":169}]}]}
{"op":"mcm","clk":"11801834655","pt":1723079592596,"mc":[{"id":"1.231447835","rc":[{"batb":[[0,2.24,10],[1,2.22,36.4],[2,1.74,17.32]],"ltp":2.3,"tv":30.69,"id":169}]}]}
{"op":"mcm","clk":"11801834777","pt":1723079595997,"mc":[{"id":"1.231447835","rc":[{"batb":[[0,2.22,36.4],[1,1.74,17.32],[2,1.53,94.34]],"ltp":2.3,"tv":30.69,"id":169}]}]}
{"op":"mcm","clk":"11801834852","pt":1723079598614,"mc":[{"id":"1.231447835","rc":[{"batb":[[0,2.24,10],[1,2.22,36.4],[2,1.74,17.32]],"ltp":2.3,"tv":30.69,"id":169}]}]}
{"op":"mcm","clk":"11801834962","pt":1723079602014,"mc":[{"id":"1.231447835","rc":[{"batb":[[0,2.22,36.4],[1,1.74,17.32],[2,1.53,94.34]],"ltp":2.3,"tv":30.69,"id":169}]}]}
{"op":"mcm","clk":"11801835028","pt":1723079604542,"mc":[{"id":"1.231447835","rc":[{"batb":[[0,2.24,10],[1,2.22,36.4],[2,1.74,17.32]],"ltp":2.3,"tv":30.69,"id":169}]}]}
{"op":"mcm","clk":"11801835161","pt":1723079607926,"mc":[{"id":"1.231447835","rc":[{"batb":[[0,2.22,36.4],[1,1.74,17.32],[2,1.53,94.34]],"ltp":2.3,"tv":30.69,"id":169}]}]}
{"op":"mcm","clk":"11801835255","pt":1723079610442,"mc":[{"id":"1.231447835","rc":[{"batb":[[0,2.24,10],[1,2.22,36.4],[2,1.74,17.32]],"ltp":2.3,"tv":30.69,"id":169}]}]}
{"op":"mcm","clk":"11801835391","pt":1723079613848,"mc":[{"id":"1.231447835","rc":[{"batb":[[0,2.22,36.4],[1,1.74,17.32],[2,1.53,94.34]],"ltp":2.3,"tv":30.69,"id":169}]}]}
{"op":"mcm","clk":"11801835528","pt":1723079617544,"mc":[{"id":"1.231447835","rc":[{"batb":[[0,2.24,10],[1,2.22,36.4],[2,1.74,17.32]],"ltp":2.3,"tv":30.69,"id":169}]}]}
{"op":"mcm","clk":"11801835630","pt":1723079621144,"mc":[{"id":"1.231447835","rc":[{"batb":[[0,2.22,36.4],[1,1.74,17.32],[2,1.53,94.34]],"ltp":2.3,"tv":30.69,"id":169}]}]}
{"op":"mcm","clk":"11801835744","pt":1723079623968,"mc":[{"id":"1.231447835","rc":[{"batb":[[0,2.24,10],[1,2.22,36.4],[2,1.74,17.32]],"ltp":2.3,"tv":30.69,"id":169}]}]}
{"op":"mcm","clk":"11801835885","pt":1723079627371,"mc":[{"id":"1.231447835","rc":[{"batb":[[0,2.22,36.4],[1,1.74,17.32],[2,1.53,94.34]],"ltp":2.3,"tv":30.69,"id":169}]}]}
{"op":"mcm","clk":"11801835939","pt":1723079629872,"mc":[{"id":"1.231447835","rc":[{"batb":[[0,2.24,10],[1,2.22,36.4],[2,1.74,17.32]],"ltp":2.3,"tv":30.69,"id":169}]}]}
{"op":"mcm","clk":"11801836052","pt":1723079633261,"mc":[{"id":"1.231447835","rc":[{"batb":[[0,2.22,36.4],[1,1.74,17.32],[2,1.53,94.34]],"ltp":2.3,"tv":30.69,"id":169}]}]}
{"op":"mcm","clk":"11801836168","pt":1723079637163,"mc":[{"id":"1.231447835","rc":[{"batb":[[0,2.24,10],[1,2.22,36.4],[2,1.74,17.32]],"ltp":2.3,"tv":30.69,"id":169}]}]}
{"op":"mcm","clk":"11801836288","pt":1723079640576,"mc":[{"id":"1.231447835","rc":[{"batb":[[0,2.22,36.4],[1,1.74,17.32],[2,1.53,94.34]],"ltp":2.3,"tv":30.69,"id":169}]}]}
{"op":"mcm","clk":"11801836367","pt":1723079642987,"mc":[{"id":"1.231447835","rc":[{"batb":[[0,2.24,10],[1,2.22,36.4],[2,1.74,17.32]],"ltp":2.3,"tv":30.69,"id":169}]}]}
{"op":"mcm","clk":"11801836504","pt":1723079646491,"mc":[{"id":"1.231447835","rc":[{"batb":[[0,2.22,36.4],[1,1.74,17.32],[2,1.53,94.34]],"ltp":2.3,"tv":30.69,"id":169}]}]}
{"op":"mcm","clk":"11801836586","pt":1723079649067,"mc":[{"id":"1.231447835","rc":[{"batb":[[0,2.24,10],[1,2.22,36.4],[2,1.74,17.32]],"ltp":2.3,"tv":30.69,"id":169}]}]}
{"op":"mcm","clk":"11801836690","pt":1723079652508,"mc":[{"id":"1.231447835","rc":[{"batb":[[0,2.22,36.4],[1,1.74,17.32],[2,1.53,94.34]],"ltp":2.3,"tv":30.69,"id":169}]}]}
{"op":"mcm","clk":"11801836809","pt":1723079655086,"mc":[{"id":"1.231447835","rc":[{"batb":[[0,2.24,10],[1,2.22,36.4],[2,1.74,17.32]],"ltp":2.3,"tv":30.69,"id":169}]}]}
{"op":"mcm","clk":"11801836896","pt":1723079658413,"mc":[{"id":"1.231447835","rc":[{"batb":[[0,2.22,36.4],[1,1.74,17.32],[2,1.53,94.34]],"ltp":2.3,"tv":30.69,"id":169}]}]}
{"op":"mcm","clk":"11801837017","pt":1723079662007,"mc":[{"id":"1.231447835","rc":[{"batb":[[0,2.24,10],[1,2.22,36.4],[2,1.74,17.32]],"ltp":2.3,"tv":30.69,"id":169}]}]}
{"op":"mcm","clk":"11801837118","pt":1723079665304,"mc":[{"id":"1.231447835","rc":[{"batb":[[0,2.22,36.4],[1,1.74,17.32],[2,1.53,94.34]],"ltp":2.3,"tv":30.69,"id":169}]}]}
{"op":"mcm","clk":"11801837223","pt":1723079668394,"mc":[{"id":"1.231447835","rc":[{"batb":[[0,2.24,10],[1,2.22,36.4],[2,1.74,17.32]],"ltp":2.3,"tv":30.69,"id":169}]}]}
{"op":"mcm","clk":"11801837334","pt":1723079672188,"mc":[{"id":"1.231447835","rc":[{"batb":[[0,2.22,36.4],[1,1.74,17.32],[2,1.53,94.34]],"ltp":2.3,"tv":30.69,"id":169}]}]}
{"op":"mcm","clk":"11801837424","pt":1723079675222,"mc":[{"id":"1.231447835","rc":[{"batb":[[0,2.24,10],[1,2.22,36.4],[2,1.74,17.32]],"ltp":2.3,"tv":30.69,"id":169}]}]}
{"op":"mcm","clk":"11801837527","pt":1723079678714,"mc":[{"id":"1.231447835","rc":[{"batb":[[0,2.22,36.4],[1,1.74,17.32],[2,1.53,94.34]],"ltp":2.3,"tv":30.69,"id":169}]}]}
{"op":"mcm","clk":"11801837606","pt":1723079681909,"mc":[{"id":"1.231447835","rc":[{"batb":[[0,2.24,10],[1,2.22,36.4],[2,1.74,17.32]],"ltp":2.3,"tv":30.69,"id":169}]}]}
{"op":"mcm","clk":"11801837705","pt":1723079685302,"mc":[{"id":"1.231447835","rc":[{"batb":[[0,2.22,36.4],[1,1.74,17.32],[2,1.53,94.34]],"ltp":2.3,"tv":30.69,"id":169}]}]}
{"op":"mcm","clk":"11801837815","pt":1723079688127,"mc":[{"id":"1.231447835","rc":[{"batb":[[0,2.24,10],[1,2.22,36.4],[2,1.74,17.32]],"ltp":2.3,"tv":30.69,"id":169}]}]}
{"op":"mcm","clk":"11801837932","pt":1723079691636,"mc":[{"id":"1.231447835","rc":[{"batb":[[0,2.22,36.4],[1,1.74,17.32],[2,1.53,94.34]],"ltp":2.3,"tv":30.69,"id":169}]}]}
{"op":"mcm","clk":"11801838011","pt":1723079694105,"mc":[{"id":"1.231447835","rc":[{"batb":[[0,2.24,10],[1,2.22,36.4],[2,1.74,17.32]],"ltp":2.3,"tv":30.69,"id":169}]}]}
{"op":"mcm","clk":"11801838122","pt":1723079697540,"mc":[{"id":"1.231447835","rc":[{"batb":[[0,2.22,36.4],[1,1.74,17.32],[2,1.53,94.34]],"ltp":2.3,"tv":30.69,"id":169}]}]}
{"op":"mcm","clk":"11801838232","pt":1723079700018,"mc":[{"id":"1.231447835","rc":[{"batb":[[0,2.24,10],[1,2.22,36.4],[2,1.74,17.32]],"ltp":2.3,"tv":30.69,"id":169}]}]}
{"op":"mcm","clk":"11801838344","pt":1723079703408,"mc":[{"id":"1.231447835","rc":[{"batb":[[0,2.22,36.4],[1,1.74,17.32],[2,1.53,94.34]],"ltp":2.3,"tv":30.69,"id":169}]}]}
{"op":"mcm","clk":"11801838431","pt":1723079706041,"mc":[{"id":"1.231447835","rc":[{"batb":[[0,2.24,10],[1,2.22,36.4],[2,1.74,17.32]],"ltp":2.3,"tv":30.69,"id":169}]}]}
{"op":"mcm","clk":"11801838543","pt":1723079709440,"mc":[{"id":"1.231447835","rc":[{"batb":[[0,2.22,36.4],[1,1.74,17.32],[2,1.53,94.34]],"ltp":2.3,"tv":30.69,"id":169}]}]}
{"op":"mcm","clk":"11801838655","pt":1723079712326,"mc":[{"id":"1.231447835","rc":[{"batb":[[0,2.24,10],[1,2.22,36.4],[2,1.74,17.32]],"ltp":2.3,"tv":30.69,"id":169}]}]}
{"op":"mcm","clk":"11801838765","pt":1723079715863,"mc":[{"id":"1.231447835","rc":[{"batb":[[0,2.22,36.4],[1,1.74,17.32],[2,1.53,94.34]],"ltp":2.3,"tv":30.69,"id":169}]}]}
{"op":"mcm","clk":"11801838849","pt":1723079718337,"mc":[{"id":"1.231447835","rc":[{"batb":[[0,2.24,10],[1,2.22,36.4],[2,1.74,17.32]],"ltp":2.3,"tv":30.69,"id":169}]}]}
{"op":"mcm","clk":"11801838961","pt":1723079721944,"mc":[{"id":"1.231447835","rc":[{"batb":[[0,2.22,36.4],[1,1.74,17.32],[2,1.53,94.34]],"ltp":2.3,"tv":30.69,"id":169}]}]}
{"op":"mcm","clk":"11801839054","pt":1723079724771,"mc":[{"id":"1.231447835","rc":[{"batb":[[0,2.24,10],[1,2.22,36.4],[2,1.74,17.32]],"ltp":2.3,"tv":30.69,"id":169}]}]}
{"op":"mcm","clk":"11801839199","pt":1723079728333,"mc":[{"id":"1.231447835","rc":[{"batb":[[0,2.22,36.4],[1,1.74,17.32],[2,1.53,94.34]],"ltp":2.3,"tv":30.69,"id":169}]}]}
{"op":"mcm","clk":"11801839304","pt":1723079731268,"mc":[{"id":"1.231447835","rc":[{"batb":[[0,2.24,10],[1,2.22,36.4],[2,1.74,17.32]],"ltp":2.3,"tv":30.69,"id":169}]}]}
{"op":"mcm","clk":"11801839415","pt":1723079734764,"mc":[{"id":"1.231447835","rc":[{"batb":[[0,2.22,36.4],[1,1.74,17.32],[2,1.53,94.34]],"ltp":2.3,"tv":30.69,"id":169}]}]}
{"op":"mcm","clk":"11801839483","pt":1723079737381,"mc":[{"id":"1.231447835","rc":[{"batb":[[0,2.24,10],[1,2.22,36.4],[2,1.74,17.32]],"ltp":2.3,"tv":30.69,"id":169}]}]}
{"op":"mcm","clk":"11801839587","pt":1723079740661,"mc":[{"id":"1.231447835","rc":[{"batb":[[0,2.22,36.4],[1,1.74,17.32],[2,1.53,94.34]],"ltp":2.3,"tv":30.69,"id":169}]}]}
{"op":"mcm","clk":"11801839657","pt":1723079743274,"mc":[{"id":"1.231447835","rc":[{"batb":[[0,2.24,10],[1,2.22,36.4],[2,1.74,17.32]],"ltp":2.3,"tv":30.69,"id":169}]}]}
{"op":"mcm","clk":"11801839760","pt":1723079746772,"mc":[{"id":"1.231447835","rc":[{"batb":[[0,2.22,36.4],[1,1.74,17.32],[2,1.53,94.34]],"ltp":2.3,"tv":30.69,"id":169}]}]}
{"op":"mcm","clk":"11801839856","pt":1723079749084,"mc":[{"id":"1.231447835","rc":[{"batb":[[0,2.24,10],[1,2.22,36.4],[2,1.74,17.32]],"ltp":2.3,"tv":30.69,"id":169}]}]}
{"op":"mcm","clk":"11801839951","pt":1723079752379,"mc":[{"id":"1.231447835","rc":[{"batb":[[0,2.22,36.4],[1,1.74,17.32],[2,1.53,94.34]],"ltp":2.3,"tv":30.69,"id":169}]}]}
{"op":"mcm","clk":"11801840057","pt":1723079754754,"mc":[{"id":"1.231447835","rc":[{"batb":[[0,2.24,10],[1,2.22,36.4],[2,1.74,17.32]],"ltp":2.3,"tv":30.69,"id":169}]}]}
{"op":"mcm","clk":"11801840161","pt":1723079758198,"mc":[{"id":"1.231447835","rc":[{"batb":[[0,2.22,36.4],[1,1.74,17.32],[2,1.53,94.34]],"ltp":2.3,"tv":30.69,"id":169}]}]}
{"op":"mcm","clk":"11801840312","pt":1723079761802,"mc":[{"id":"1.231447835","rc":[{"batb":[[0,2.24,10],[1,2.22,36.4],[2,1.74,17.32]],"ltp":2.3,"tv":30.69,"id":169}]}]}
{"op":"mcm","clk":"11801840425","pt":1723079765199,"mc":[{"id":"1.231447835","rc":[{"batb":[[0,2.22,36.4],[1,1.74,17.32],[2,1.53,94.34]],"ltp":2.3,"tv":30.69,"id":169}]}]}
{"op":"mcm","clk":"11801840504","pt":1723079767472,"mc":[{"id":"1.231447835","rc":[{"batb":[[0,2.24,10],[1,2.22,36.4],[2,1.74,17.32]],"ltp":2.3,"tv":30.69,"id":169}]}]}
{"op":"mcm","clk":"11801840608","pt":1723079770791,"mc":[{"id":"1.231447835","rc":[{"batb":[[0,2.22,36.4],[1,1.74,17.32],[2,1.53,94.34]],"ltp":2.3,"tv":30.69,"id":169}]}]}
{"op":"mcm","clk":"11801840715","pt":1723079773789,"mc":[{"id":"1.231447835","rc":[{"batb":[[0,2.24,10],[1,2.22,36.4],[2,1.74,17.32]],"ltp":2.3,"tv":30.69,"id":169}]}]}
{"op":"mcm","clk":"11801840848","pt":1723079777400,"mc":[{"id":"1.231447835","rc":[{"batb":[[0,2.22,36.4],[1,1.74,17.32],[2,1.53,94.34]],"ltp":2.3,"tv":30.69,"id":169}]}]}
{"op":"mcm","clk":"11801840938","pt":1723079779976,"mc":[{"id":"1.231447835","rc":[{"batb":[[0,2.24,10],[1,2.22,36.4],[2,1.74,17.32]],"ltp":2.3,"tv":30.69,"id":169}]}]}
{"op":"mcm","clk":"11801841060","pt":1723079783311,"mc":[{"id":"1.231447835","rc":[{"batb":[[0,2.22,36.4],[1,1.74,17.32],[2,1.53,94.34]],"ltp":2.3,"tv":30.69,"id":169}]}]}
{"op":"mcm","clk":"11801841189","pt":1723079787275,"mc":[{"id":"1.231447835","rc":[{"batb":[[0,2.24,10],[1,2.22,36.4],[2,1.74,17.32]],"ltp":2.3,"tv":30.69,"id":169}]}]}
{"op":"mcm","clk":"11801841294","pt":1723079790513,"mc":[{"id":"1.231447835","rc":[{"batb":[[0,2.22,36.4],[1,1.74,17.32],[2,1.53,94.34]],"ltp":2.3,"tv":30.69,"id":169}]}]}
{"op":"mcm","clk":"11801841391","pt":1723079793397,"mc":[{"id":"1.231447835","rc":[{"batb":[[0,2.24,10],[1,2.22,36.4],[2,1.74,17.32]],"ltp":2.3,"tv":30.69,"id":169}]}]}
{"op":"mcm","clk":"11801841521","pt":1723079797147,"mc":[{"id":"1.231447835","rc":[{"batb":[[0,2.22,36.4],[1,1.74,17.32],[2,1.53,94.34]],"ltp":2.3,"tv":30.69,"id":169}]}]}
{"op":"mcm","clk":"11801841593","pt":1723079799375,"mc":[{"id":"1.231447835","rc":[{"batb":[[0,2.24,10],[1,2.22,36.4],[2,1.74,17.32]],"ltp":2.3,"tv":30.69,"id":169}]}]}
{"op":"mcm","clk":"11801841706","pt":1723079802871,"mc":[{"id":"1.231447835","rc":[{"batb":[[0,2.22,36.4],[1,1.74,17.32],[2,1.53,94.34]],"ltp":2.3,"tv":30.69,"id":169}]}]}
{"op":"mcm","clk":"11801841795","pt":1723079805651,"mc":[{"id":"1.231447835","rc":[{"batb":[[0,2.24,10],[1,2.22,36.4],[2,1.74,17.32]],"ltp":2.3,"tv":30.69,"id":169}]}]}
{"op":"mcm","clk":"11801841912","pt":1723079809144,"mc":[{"id":"1.231447835","rc":[{"batb":[[0,2.22,36.4],[1,1.74,17.32],[2,1.53,94.34]],"ltp":2.3,"tv":30.69,"id":169}]}]}
{"op":"mcm","clk":"11801841985","pt":1723079811364,"mc":[{"id":"1.231447835","rc":[{"batb":[[0,2.24,10],[1,2.22,36.4],[2,1.74,17.32]],"ltp":2.3,"tv":30.69,"id":169}]}]}
{"op":"mcm","clk":"11801842109","pt":1723079814855,"mc":[{"id":"1.231447835","rc":[{"batb":[[0,2.22,36.4],[1,1.74,17.32],[2,1.53,94.34]],"ltp":2.3,"tv":30.69,"id":169}]}]}
{"op":"mcm","clk":"11801842181","pt":1723079817380,"mc":[{"id":"1.231447835","rc":[{"batb":[[0,2.24,10],[1,2.22,36.4],[2,1.74,17.32]],"ltp":2.3,"tv":30.69,"id":169}]}]}
{"op":"mcm","clk":"11801842292","pt":1723079820748,"mc":[{"id":"1.231447835","rc":[{"batb":[[0,2.22,36.4],[1,1.74,17.32],[2,1.53,94.34]],"ltp":2.3,"tv":30.69,"id":169}]}]}
{"op":"mcm","clk":"11801842397","pt":1723079823477,"mc":[{"id":"1.231447835","rc":[{"batb":[[0,2.24,10],[1,2.22,36.4],[2,1.74,17.32]],"ltp":2.3,"tv":30.69,"id":169}]}]}
{"op":"mcm","clk":"11801842515","pt":1723079826883,"mc":[{"id":"1.231447835","rc":[{"batb":[[0,2.22,36.4],[1,1.74,17.32],[2,1.53,94.34]],"ltp":2.3,"tv":30.69,"id":169}]}]}
{"op":"mcm","clk":"11801842593","pt":1723079829564,"mc":[{"id":"1.231447835","rc":[{"batb":[[0,2.24,10],[1,2.22,36.4],[2,1.74,17.32]],"ltp":2.3,"tv":30.69,"id":169}]}]}
{"op":"mcm","clk":"11801842710","pt":1723079833165,"mc":[{"id":"1.231447835","rc":[{"batb":[[0,2.22,36.4],[1,1.74,17.32],[2,1.53,94.34]],"ltp":2.3,"tv":30.69,"id":169}]}]}
{"op":"mcm","clk":"11801842766","pt":1723079835381,"mc":[{"id":"1.231447835","rc":[{"batb":[[0,2.24,10],[1,2.22,36.4],[2,1.74,17.32]],"ltp":2.3,"tv":30.69,"id":169}]}]}
{"op":"mcm","clk":"11801842907","pt":1723079839004,"mc":[{"id":"1.231447835","rc":[{"batb":[[0,2.22,36.4],[1,1.74,17.32],[2,1.53,94.34]],"ltp":2.3,"tv":30.69,"id":169}]}]}
{"op":"mcm","clk":"11801842995","pt":1723079841887,"mc":[{"id":"1.231447835","rc":[{"batb":[[0,2.24,10],[1,2.22,36.4],[2,1.74,17.32]],"ltp":2.3,"tv":30.69,"id":169}]}]}
{"op":"mcm","clk":"11801843106","pt":1723079845310,"mc":[{"id":"1.231447835","rc":[{"batb":[[0,2.22,36.4],[1,1.74,17.32],[2,1.53,94.34]],"ltp":2.3,"tv":30.69,"id":169}]}]}
{"op":"mcm","clk":"11801843195","pt":1723079847714,"mc":[{"id":"1.231447835","rc":[{"batb":[[0,2.24,10],[1,2.22,36.4],[2,1.74,17.32]],"ltp":2.3,"tv":30.69,"id":169}]}]}
{"op":"mcm","clk":"11801843318","pt":1723079851521,"mc":[{"id":"1.231447835","rc":[{"batb":[[0,2.22,36.4],[1,1.74,17.32],[2,1.53,94.34]],"ltp":2.3,"tv":30.69,"id":169}]}]}
{"op":"mcm","clk":"11801843419","pt":1723079854498,"mc":[{"id":"1.231447835","rc":[{"batb":[[0,2.24,10],[1,2.22,36.4],[2,1.74,17.32]],"ltp":2.3,"tv":30.69,"id":169}]}]}
{"op":"mcm","clk":"11801843540","pt":1723079858304,"mc":[{"id":"1.231447835","rc":[{"batb":[[0,2.22,36.4],[1,1.74,17.32],[2,1.53,94.34]],"ltp":2.3,"tv":30.69,"id":169}]}]}
{"op":"mcm","clk":"11801843629","pt":1723079861332,"mc":[{"id":"1.231447835","rc":[{"batb":[[0,2.24,10],[1,2.22,36.4],[2,1.74,17.32]],"ltp":2.3,"tv":30.69,"id":169}]}]}
{"op":"mcm","clk":"11801843730","pt":1723079864817,"mc":[{"id":"1.231447835","rc":[{"batb":[[0,2.22,36.4],[1,1.74,17.32],[2,1.53,94.34]],"ltp":2.3,"tv":30.69,"id":169}]}]}
{"op":"mcm","clk":"11801843810","pt":1723079867688,"mc":[{"id":"1.231447835","rc":[{"batb":[[0,2.24,10],[1,2.22,36.4],[2,1.74,17.32]],"ltp":2.3,"tv":30.69,"id":169}]}]}
{"op":"mcm","clk":"11801843921","pt":1723079871026,"mc":[{"id":"1.231447835","rc":[{"batb":[[0,2.22,36.4],[1,1.74,17.32],[2,1.53,94.34]],"ltp":2.3,"tv":30.69,"id":169}]}]}
{"op":"mcm","clk":"11801844002","pt":1723079873224,"mc":[{"id":"1.231447835","rc":[{"batb":[[0,2.24,10],[1,2.22,36.4],[2,1.74,17.32]],"ltp":2.3,"tv":30.69,"id":169}]}]}
{"op":"mcm","clk":"11801844130","pt":1723079876613,"mc":[{"id":"1.231447835","rc":[{"batb":[[0,2.22,36.4],[1,1.74,17.32],[2,1.53,94.34]],"ltp":2.3,"tv":30.69,"id":169}]}]}
{"op":"mcm","clk":"11801844229","pt":1723079879121,"mc":[{"id":"1.231447835","rc":[{"batb":[[0,2.24,10],[1,2.22,36.4],[2,1.74,17.32]],"ltp":2.3,"tv":30.69,"id":169}]}]}
{"op":"mcm","clk":"11801844343","pt":1723079882458,"mc":[{"id":"1.231447835","rc":[{"batb":[[0,2.22,36.4],[1,1.74,17.32],[2,1.53,94.34]],"ltp":2.3,"tv":30.69,"id":169}]}]}
{"op":"mcm","clk":"11801844433","pt":1723079885213,"mc":[{"id":"1.231447835","rc":[{"batb":[[0,2.24,10],[1,2.22,36.4],[2,1.74,17.32]],"ltp":2.3,"tv":30.69,"id":169}]}]}
{"op":"mcm","clk":"11801844535","pt":1723079888755,"mc":[{"id":"1.231447835","rc":[{"batb":[[0,2.22,36.4],[1,1.74,17.32],[2,1.53,94.34]],"ltp":2.3,"tv":30.69,"id":169}]}]}
{"op":"mcm","clk":"11801844612","pt":1723079890963,"mc":[{"id":"1.231447835","rc":[{"batb":[[0,2.24,10],[1,2.22,36.4],[2,1.74,17.32]],"ltp":2.3,"tv":30.69,"id":169}]}]}
{"op":"mcm","clk":"11801844724","pt":1723079894358,"mc":[{"id":"1.231447835","rc":[{"batb":[[0,2.22,36.4],[1,1.74,17.32],[2,1.53,94.34]],"ltp":2.3,"tv":30.69,"id":169}]}]}
{"op":"mcm","clk":"11801844813","pt":1723079897752,"mc":[{"id":"1.231447835","rc":[{"batb":[[0,2.24,10],[1,2.22,36.4],[2,1.74,17.32]],"ltp":2.3,"tv":30.69,"id":169}]}]}
{"op":"mcm","clk":"11801844911","pt":1723079901147,"mc":[{"id":"1.231447835","rc":[{"batb":[[0,2.22,36.4],[1,1.74,17.32],[2,1.53,94.34]],"ltp":2.3,"tv":30.69,"id":169}]}]}
{"op":"mcm","clk":"11801844991","pt":1723079903559,"mc":[{"id":"1.231447835","rc":[{"batb":[[0,2.24,10],[1,2.22,36.4],[2,1.74,17.32]],"ltp":2.3,"tv":30.69,"id":169}]}]}
{"op":"mcm","clk":"11801845112","pt":1723079906950,"mc":[{"id":"1.231447835","rc":[{"batb":[[0,2.22,36.4],[1,1.74,17.32],[2,1.53,94.34]],"ltp":2.3,"tv":30.69,"id":169}]}]}
{"op":"mcm","clk":"11801845202","pt":1723079909581,"mc":[{"id":"1.231447835","rc":[{"batb":[[0,2.24,10],[1,2.22,36.4],[2,1.74,17.32]],"ltp":2.3,"tv":30.69,"id":169}]}]}
{"op":"mcm","clk":"11801845346","pt":1723079913238,"mc":[{"id":"1.231447835","rc":[{"batb":[[0,2.22,36.4],[1,1.74,17.32],[2,1.53,94.34]],"ltp":2.3,"tv":30.69,"id":169}]}]}
{"op":"mcm","clk":"11801845466","pt":1723079916573,"mc":[{"id":"1.231447835","rc":[{"batb":[[0,2.24,10],[1,2.22,36.4],[2,1.74,17.32]],"ltp":2.3,"tv":30.69,"id":169}]}]}
{"op":"mcm","clk":"11801845583","pt":1723079919958,"mc":[{"id":"1.231447835","rc":[{"batb":[[0,2.22,36.4],[1,1.74,17.32],[2,1.53,94.34]],"ltp":2.3,"tv":30.69,"id":169}]}]}
{"op":"mcm","clk":"11801845658","pt":1723079922170,"mc":[{"id":"1.231447835","rc":[{"batb":[[0,2.24,10],[1,2.22,36.4],[2,1.74,17.32]],"ltp":2.3,"tv":30.69,"id":169}]}]}
{"op":"mcm","clk":"11801845803","pt":1723079925459,"mc":[{"id":"1.231447835","rc":[{"batb":[[0,2.22,36.4],[1,1.74,17.32],[2,1.53,94.34]],"ltp":2.3,"tv":30.69,"id":169}]}]}
{"op":"mcm","clk":"11801845941","pt":1723079928979,"mc":[{"id":"1.231447835","rc":[{"batb":[[0,2.24,10],[1,2.22,36.4],[2,1.74,17.32]],"ltp":2.3,"tv":30.69,"id":169}]}]}
{"op":"mcm","clk":"11801846054","pt":1723079932371,"mc":[{"id":"1.231447835","rc":[{"batb":[[0,2.22,36.4],[1,1.74,17.32],[2,1.53,94.34]],"ltp":2.3,"tv":30.69,"id":169}]}]}
{"op":"mcm","clk":"11801846151","pt":1723079934891,"mc":[{"id":"1.231447835","rc":[{"batb":[[0,2.24,10],[1,2.22,36.4],[2,1.74,17.32]],"ltp":2.3,"tv":30.69,"id":169}]}]}
{"op":"mcm","clk":"11801846267","pt":1723079938071,"mc":[{"id":"1.231447835","rc":[{"batb":[[0,2.22,36.4],[1,1.74,17.32],[2,1.53,94.34]],"ltp":2.3,"tv":30.69,"id":169}]}]}
{"op":"mcm","clk":"11801846423","pt":1723079942692,"mc":[{"id":"1.231447835","rc":[{"batb":[[0,2.24,10],[1,2.22,36.4],[2,1.74,17.32]],"ltp":2.3,"tv":30.69,"id":169}]}]}
{"op":"mcm","clk":"11801846545","pt":1723079945874,"mc":[{"id":"1.231447835","rc":[{"batb":[[0,2.22,36.4],[1,1.74,17.32],[2,1.53,94.34]],"ltp":2.3,"tv":30.69,"id":169}]}]}
{"op":"mcm","clk":"11801846635","pt":1723079948180,"mc":[{"id":"1.231447835","rc":[{"batb":[[0,2.24,10],[1,2.22,36.4],[2,1.74,17.32]],"ltp":2.3,"tv":30.69,"id":169}]}]}
{"op":"mcm","clk":"11801846796","pt":1723079951769,"mc":[{"id":"1.231447835","rc":[{"batb":[[0,2.22,36.4],[1,1.74,17.32],[2,1.53,94.34]],"ltp":2.3,"tv":30.69,"id":169}]}]}
{"op":"mcm","clk":"11801846926","pt":1723079955406,"mc":[{"id":"1.231447835","rc":[{"batb":[[0,2.24,10],[1,2.22,36.4],[2,1.74,17.32]],"ltp":2.3,"tv":30.69,"id":169}]}]}
{"op":"mcm","clk":"11801847065","pt":1723079959118,"mc":[{"id":"1.231447835","rc":[{"batb":[[0,2.22,36.4],[1,1.74,17.32],[2,1.53,94.34]],"ltp":2.3,"tv":30.69,"id":169}]}]}
{"op":"mcm","clk":"11801847166","pt":1723079961892,"mc":[{"id":"1.231447835","rc":[{"batb":[[0,2.24,10],[1,2.22,36.4],[2,1.74,17.32]],"ltp":2.3,"tv":30.69,"id":169}]}]}
{"op":"mcm","clk":"11801847268","pt":1723079965274,"mc":[{"id":"1.231447835","rc":[{"batb":[[0,2.22,36.4],[1,1.74,17.32],[2,1.53,94.34]],"ltp":2.3,"tv":30.69,"id":169}]}]}
{"op":"mcm","clk":"11801847381","pt":1723079968508,"mc":[{"id":"1.231447835","rc":[{"batb":[[0,2.24,10],[1,2.22,36.4],[2,1.74,17.32]],"ltp":2.3,"tv":30.69,"id":169}]}]}
{"op":"mcm","clk":"11801847487","pt":1723079971894,"mc":[{"id":"1.231447835","rc":[{"batb":[[0,2.22,36.4],[1,1.74,17.32],[2,1.53,94.34]],"ltp":2.3,"tv":30.69,"id":169}]}]}
{"op":"mcm","clk":"11801847574","pt":1723079974308,"mc":[{"id":"1.231447835","rc":[{"batb":[[0,2.24,10],[1,2.22,36.4],[2,1.74,17.32]],"ltp":2.3,"tv":30.69,"id":169}]}]}
{"op":"mcm","clk":"11801847693","pt":1723079978015,"mc":[{"id":"1.231447835","rc":[{"batb":[[0,2.22,36.4],[1,1.74,17.32],[2,1.53,94.34]],"ltp":2.3,"tv":30.69,"id":169}]}]}
{"op":"mcm","clk":"11801847786","pt":1723079980590,"mc":[{"id":"1.231447835","rc":[{"batb":[[0,2.24,10],[1,2.22,36.4],[2,1.74,17.32]],"ltp":2.3,"tv":30.69,"id":169}]}]}
{"op":"mcm","clk":"11801847921","pt":1723079984136,"mc":[{"id":"1.231447835","rc":[{"batb":[[0,2.22,36.4],[1,1.74,17.32],[2,1.53,94.34]],"ltp":2.3,"tv":30.69,"id":169}]}]}
{"op":"mcm","clk":"11801848039","pt":1723079987021,"mc":[{"id":"1.231447835","rc":[{"batb":[[0,2.24,10],[1,2.22,36.4],[2,1.74,17.32]],"ltp":2.3,"tv":30.69,"id":169}]}]}
{"op":"mcm","clk":"11801848161","pt":1723079990622,"mc":[{"id":"1.231447835","rc":[{"batb":[[0,2.22,36.4],[1,1.74,17.32],[2,1.53,94.34]],"ltp":2.3,"tv":30.69,"id":169}]}]}
{"op":"mcm","clk":"11801848214","pt":1723079992825,"mc":[{"id":"1.231447835","rc":[{"batb":[[0,2.24,10],[1,2.22,36.4],[2,1.74,17.32]],"ltp":2.3,"tv":30.69,"id":169}]}]}
{"op":"mcm","clk":"11801848330","pt":1723079996209,"mc":[{"id":"1.231447835","rc":[{"batb":[[0,2.22,36.4],[1,1.74,17.32],[2,1.53,94.34]],"ltp":2.3,"tv":30.69,"id":169}]}]}
{"op":"mcm","clk":"11801848420","pt":1723079998622,"mc":[{"id":"1.231447835","rc":[{"batb":[[0,2.24,10],[1,2.22,36.4],[2,1.74,17.32]],"ltp":2.3,"tv":30.69,"id":169}]}]}
{"op":"mcm","clk":"11801848563","pt":1723080002228,"mc":[{"id":"1.231447835","rc":[{"batb":[[0,2.22,36.4],[1,1.74,17.32],[2,1.53,94.34]],"ltp":2.3,"tv":30.69,"id":169}]}]}
{"op":"mcm","clk":"11801848708","pt":1723080005619,"mc":[{"id":"1.231447835","rc":[{"batb":[[0,2.24,10],[1,2.22,36.4],[2,1.74,17.32]],"ltp":2.3,"tv":30.69,"id":169}]}]}
{"op":"mcm","clk":"11801848832","pt":1723080008969,"mc":[{"id":"1.231447835","rc":[{"batb":[[0,2.22,36.4],[1,1.74,17.32],[2,1.53,94.34]],"ltp":2.3,"tv":30.69,"id":169}]}]}
{"op":"mcm","clk":"11801848907","pt":1723080011443,"mc":[{"id":"1.231447835","rc":[{"batb":[[0,2.24,10],[1,2.22,36.4],[2,1.74,17.32]],"ltp":2.3,"tv":30.69,"id":169}]}]}
{"op":"mcm","clk":"11801849037","pt":1723080014772,"mc":[{"id":"1.231447835","rc":[{"batb":[[0,2.22,36.4],[1,1.74,17.32],[2,1.53,94.34]],"ltp":2.3,"tv":30.69,"id":169}]}]}
{"op":"mcm","clk":"11801849157","pt":1723080017553,"mc":[{"id":"1.231447835","rc":[{"batb":[[0,2.24,10],[1,2.22,36.4],[2,1.74,17.32]],"ltp":2.3,"tv":30.69,"id":169}]}]}
{"op":"mcm","clk":"11801849279","pt":1723080021044,"mc":[{"id":"1.231447835","rc":[{"batb":[[0,2.22,36.4],[1,1.74,17.32],[2,1.53,94.34]],"ltp":2.3,"tv":30.69,"id":169}]}]}
{"op":"mcm","clk":"11801849354","pt":1723080023405,"mc":[{"id":"1.231447835","rc":[{"batb":[[0,2.24,10],[1,2.22,36.4],[2,1.74,17.32]],"ltp":2.3,"tv":30.69,"id":169}]}]}
{"op":"mcm","clk":"11801849496","pt":1723080026754,"mc":[{"id":"1.231447835","rc":[{"batb":[[0,2.22,36.4],[1,1.74,17.32],[2,1.53,94.34]],"ltp":2.3,"tv":30.69,"id":169}]}]}
{"op":"mcm","clk":"11801849557","pt":1723080029055,"mc":[{"id":"1.231447835","rc":[{"batb":[[0,2.24,10],[1,2.22,36.4],[2,1.74,17.32]],"ltp":2.3,"tv":30.69,"id":169}]}]}
{"op":"mcm","clk":"11801849682","pt":1723080032364,"mc":[{"id":"1.231447835","rc":[{"batb":[[0,2.22,36.4],[1,1.74,17.32],[2,1.53,94.34]],"ltp":2.3,"tv":30.69,"id":169}]}]}
{"op":"mcm","clk":"11801849782","pt":1723080034988,"mc":[{"id":"1.231447835","rc":[{"batb":[[0,2.24,10],[1,2.22,36.4],[2,1.74,17.32]],"ltp":2.3,"tv":30.69,"id":169}]}]}
{"op":"mcm","clk":"11801849933","pt":1723080038483,"mc":[{"id":"1.231447835","rc":[{"batb":[[0,2.22,36.4],[1,1.74,17.32],[2,1.53,94.34]],"ltp":2.3,"tv":30.69,"id":169}]}]}
{"op":"mcm","clk":"11801850057","pt":1723080040964,"mc":[{"id":"1.231447835","rc":[{"batb":[[0,2.24,10],[1,2.22,36.4],[2,1.74,17.32]],"ltp":2.3,"tv":30.69,"id":169}]}]}
{"op":"mcm","clk":"11801850171","pt":1723080044400,"mc":[{"id":"1.231447835","rc":[{"batb":[[0,2.22,36.4],[1,1.74,17.32],[2,1.53,94.34]],"ltp":2.3,"tv":30.69,"id":169}]}]}
{"op":"mcm","clk":"11801850291","pt":1723080047171,"mc":[{"id":"1.231447835","rc":[{"batb":[[0,2.24,10],[1,2.22,36.4],[2,1.74,17.32]],"ltp":2.3,"tv":30.69,"id":169}]}]}
{"op":"mcm","clk":"11801850427","pt":1723080050660,"mc":[{"id":"1.231447835","rc":[{"batb":[[0,2.22,36.4],[1,1.74,17.32],[2,1.53,94.34]],"ltp":2.3,"tv":30.69,"id":169}]}]}
{"op":"mcm","clk":"11801850545","pt":1723080053803,"mc":[{"id":"1.231447835","rc":[{"batb":[[0,2.24,10],[1,2.22,36.4],[2,1.74,17.32]],"ltp":2.3,"tv":30.69,"id":169}]}]}
{"op":"mcm","clk":"11801850666","pt":1723080057177,"mc":[{"id":"1.231447835","rc":[{"batb":[[0,2.22,36.4],[1,1.74,17.32],[2,1.53,94.34]],"ltp":2.3,"tv":30.69,"id":169}]}]}
{"op":"mcm","clk":"11801850748","pt":1723080059792,"mc":[{"id":"1.231447835","rc":[{"batb":[[0,2.24,10],[1,2.22,36.4],[2,1.74,17.32]],"ltp":2.3,"tv":30.69,"id":169}]}]}
{"op":"mcm","clk":"11801850918","pt":1723080063286,"mc":[{"id":"1.231447835","rc":[{"batb":[[0,2.22,36.4],[1,1.74,17.32],[2,1.53,94.34]],"ltp":2.3,"tv":30.69,"id":169}]}]}
{"op":"mcm","clk":"11801851027","pt":1723080066009,"mc":[{"id":"1.231447835","rc":[{"batb":[[0,2.24,10],[1,2.22,36.4],[2,1.74,17.32]],"ltp":2.3,"tv":30.69,"id":169}]}]}
{"op":"mcm","clk":"11801851194","pt":1723080069709,"mc":[{"id":"1.231447835","rc":[{"batb":[[0,2.22,36.4],[1,1.74,17.32],[2,1.53,94.34]],"ltp":2.3,"tv":30.69,"id":169}]}]}
{"op":"mcm","clk":"11801851302","pt":1723080072680,"mc":[{"id":"1.231447835","rc":[{"batb":[[0,2.24,10],[1,2.22,36.4],[2,1.74,17.32]],"ltp":2.3,"tv":30.69,"id":169}]}]}
{"op":"mcm","clk":"11801851427","pt":1723080076113,"mc":[{"id":"1.231447835","rc":[{"batb":[[0,2.22,36.4],[1,1.74,17.32],[2,1.53,94.34]],"ltp":2.3,"tv":30.69,"id":169}]}]}
{"op":"mcm","clk":"11801851539","pt":1723080079087,"mc":[{"id":"1.231447835","rc":[{"batb":[[0,2.24,10],[1,2.22,36.4],[2,1.74,17.32]],"ltp":2.3,"tv":30.69,"id":169}]}]}
{"op":"mcm","clk":"11801851682","pt":1723080082530,"mc":[{"id":"1.231447835","rc":[{"batb":[[0,2.22,36.4],[1,1.74,17.32],[2,1.53,94.34]],"ltp":2.3,"tv":30.69,"id":169}]}]}
{"op":"mcm","clk":"11801851780","pt":1723080084993,"mc":[{"id":"1.231447835","rc":[{"batb":[[0,2.24,10],[1,2.22,36.4],[2,1.74,17.32]],"ltp":2.3,"tv":30.69,"id":169}]}]}
{"op":"mcm","clk":"11801851921","pt":1723080089016,"mc":[{"id":"1.231447835","rc":[{"batb":[[0,2.22,36.4],[1,1.74,17.32],[2,1.53,94.34]],"ltp":2.3,"tv":30.69,"id":169}]}]}
{"op":"mcm","clk":"11801852046","pt":1723080092911,"mc":[{"id":"1.231447835","rc":[{"batb":[[0,2.24,10],[1,2.22,36.4],[2,1.74,17.32]],"ltp":2.3,"tv":30.69,"id":169}]}]}
{"op":"mcm","clk":"11801852164","pt":1723080096410,"mc":[{"id":"1.231447835","rc":[{"batb":[[0,2.22,36.4],[1,1.74,17.32],[2,1.53,94.34]],"ltp":2.3,"tv":30.69,"id":169}]}]}
{"op":"mcm","clk":"11801852284","pt":1723080100011,"mc":[{"id":"1.231447835","rc":[{"batb":[[0,2.24,10],[1,2.22,36.4],[2,1.74,17.32]],"ltp":2.3,"tv":30.69,"id":169}]}]}
{"op":"mcm","clk":"11801852407","pt":1723080103405,"mc":[{"id":"1.231447835","rc":[{"batb":[[0,2.22,36.4],[1,1.74,17.32],[2,1.53,94.34]],"ltp":2.3,"tv":30.69,"id":169}]}]}
{"op":"mcm","clk":"11801852494","pt":1723080105728,"mc":[{"id":"1.231447835","rc":[{"batb":[[0,2.24,10],[1,2.22,36.4],[2,1.74,17.32]],"ltp":2.3,"tv":30.69,"id":169}]}]}
{"op":"mcm","clk":"11801852610","pt":1723080109217,"mc":[{"id":"1.231447835","rc":[{"batb":[[0,2.22,36.4],[1,1.74,17.32],[2,1.53,94.34]],"ltp":2.3,"tv":30.69,"id":169}]}]}
{"op":"mcm","clk":"11801852730","pt":1723080112569,"mc":[{"id":"1.231447835","rc":[{"batb":[[0,2.24,10],[1,2.22,36.4],[2,1.74,17.32]],"ltp":2.3,"tv":30.69,"id":169}]}]}
{"op":"mcm","clk":"11801852840","pt":1723080116072,"mc":[{"id":"1.231447835","rc":[{"batb":[[0,2.22,36.4],[1,1.74,17.32],[2,1.53,94.34]],"ltp":2.3,"tv":30.69,"id":169}]}]}
{"op":"mcm","clk":"11801852952","pt":1723080118231,"mc":[{"id":"1.231447835","rc":[{"batb":[[0,2.24,10],[1,2.22,36.4],[2,1.74,17.32]],"ltp":2.3,"tv":30.69,"id":169}]}]}
{"op":"mcm","clk":"11801853090","pt":1723080121835,"mc":[{"id":"1.231447835","rc":[{"batb":[[0,2.22,36.4],[1,1.74,17.32],[2,1.53,94.34]],"ltp":2.3,"tv":30.69,"id":169}]}]}
{"op":"mcm","clk":"11801853190","pt":1723080124347,"mc":[{"id":"1.231447835","rc":[{"batb":[[0,2.24,10],[1,2.22,36.4],[2,1.74,17.32]],"ltp":2.3,"tv":30.69,"id":169}]}]}
{"op":"mcm","clk":"11801853333","pt":1723080127765,"mc":[{"id":"1.231447835","rc":[{"batb":[[0,2.22,36.4],[1,1.74,17.32],[2,1.53,94.34]],"ltp":2.3,"tv":30.69,"id":169}]}]}
{"op":"mcm","clk":"11801853449","pt":1723080130270,"mc":[{"id":"1.231447835","rc":[{"batb":[[0,2.24,10],[1,2.22,36.4],[2,1.74,17.32]],"ltp":2.3,"tv":30.69,"id":169}]}]}
{"op":"mcm","clk":"11801853570","pt":1723080133667,"mc":[{"id":"1.231447835","rc":[{"batb":[[0,2.22,36.4],[1,1.74,17.32],[2,1.53,94.34]],"ltp":2.3,"tv":30.69,"id":169}]}]}
{"op":"mcm","clk":"11801853662","pt":1723080136289,"mc":[{"id":"1.231447835","rc":[{"batb":[[0,2.24,10],[1,2.22,36.4],[2,1.74,17.32]],"ltp":2.3,"tv":30.69,"id":169}]}]}
{"op":"mcm","clk":"11801853776","pt":1723080139578,"mc":[{"id":"1.231447835","rc":[{"batb":[[0,2.22,36.4],[1,1.74,17.32],[2,1.53,94.34]],"ltp":2.3,"tv":30.69,"id":169}]}]}
{"op":"mcm","clk":"11801853908","pt":1723080142787,"mc":[{"id":"1.231447835","rc":[{"batb":[[0,2.24,10],[1,2.22,36.4],[2,1.74,17.32]],"ltp":2.3,"tv":30.69,"id":169}]}]}
{"op":"mcm","clk":"11801854068","pt":1723080146588,"mc":[{"id":"1.231447835","rc":[{"batb":[[0,2.22,36.4],[1,1.74,17.32],[2,1.53,94.34]],"ltp":2.3,"tv":30.69,"id":169}]}]}
{"op":"mcm","clk":"11801854227","pt":1723080150085,"mc":[{"id":"1.231447835","rc":[{"batb":[[0,2.24,10],[1,2.22,36.4],[2,1.74,17.32]],"ltp":2.3,"tv":30.69,"id":169}]}]}
{"op":"mcm","clk":"11801854368","pt":1723080153380,"mc":[{"id":"1.231447835","rc":[{"batb":[[0,2.22,36.4],[1,1.74,17.32],[2,1.53,94.34]],"ltp":2.3,"tv":30.69,"id":169}]}]}
{"op":"mcm","clk":"11801854475","pt":1723080155867,"mc":[{"id":"1.231447835","rc":[{"batb":[[0,2.24,10],[1,2.22,36.4],[2,1.74,17.32]],"ltp":2.3,"tv":30.69,"id":169}]}]}
{"op":"mcm","clk":"11801854597","pt":1723080159207,"mc":[{"id":"1.231447835","rc":[{"batb":[[0,2.22,36.4],[1,1.74,17.32],[2,1.53,94.34]],"ltp":2.3,"tv":30.69,"id":169}]}]}
{"op":"mcm","clk":"11801854782","pt":1723080163593,"mc":[{"id":"1.231447835","rc":[{"batb":[[0,2.24,10],[1,2.22,36.4],[2,1.74,17.32]],"ltp":2.3,"tv":30.69,"id":169}]}]}
{"op":"mcm","clk":"11801854916","pt":1723080167194,"mc":[{"id":"1.231447835","rc":[{"batb":[[0,2.22,36.4],[1,1.74,17.32],[2,1.53,94.34]],"ltp":2.3,"tv":30.69,"id":169}]}]}
{"op":"mcm","clk":"11801855009","pt":1723080169518,"mc":[{"id":"1.231447835","rc":[{"batb":[[0,2.24,10],[1,2.22,36.4],[2,1.74,17.32]],"ltp":2.3,"tv":30.69,"id":169}]}]}
{"op":"mcm","clk":"11801855136","pt":1723080173022,"mc":[{"id":"1.231447835","rc":[{"batb":[[0,2.22,36.4],[1,1.74,17.32],[2,1.53,94.34]],"ltp":2.3,"tv":30.69,"id":169}]}]}
{"op":"mcm","clk":"11801855267","pt":1723080175599,"mc":[{"id":"1.231447835","rc":[{"batb":[[0,2.24,10],[1,2.22,36.4],[2,1.74,17.32]],"ltp":2.3,"tv":30.69,"id":169}]}]}
{"op":"mcm","clk":"11801855399","pt":1723080179101,"mc":[{"id":"1.231447835","rc":[{"batb":[[0,2.22,36.4],[1,1.74,17.32],[2,1.53,94.34]],"ltp":2.3,"tv":30.69,"id":169}]}]}
{"op":"mcm","clk":"11801855597","pt":1723080184091,"mc":[{"id":"1.231447835","rc":[{"batb":[[0,2.24,10],[1,2.22,36.4],[2,1.74,17.32]],"ltp":2.3,"tv":30.69,"id":169}]}]}
{"op":"mcm","clk":"11801855739","pt":1723080187437,"mc":[{"id":"1.231447835","rc":[{"batb":[[0,2.22,36.4],[1,1.74,17.32],[2,1.53,94.34]],"ltp":2.3,"tv":30.69,"id":169}]}]}
{"op":"mcm","clk":"11801855862","pt":1723080190420,"mc":[{"id":"1.231447835","rc":[{"batb":[[0,2.24,10],[1,2.22,36.4],[2,1.74,17.32]],"ltp":2.3,"tv":30.69,"id":169}]}]}
{"op":"mcm","clk":"11801855978","pt":1723080194233,"mc":[{"id":"1.231447835","rc":[{"batb":[[0,2.22,36.4],[1,1.74,17.32],[2,1.53,94.34]],"ltp":2.3,"tv":30.69,"id":169}]}]}
{"op":"mcm","clk":"11801856113","pt":1723080197415,"mc":[{"id":"1.231447835","rc":[{"batb":[[0,2.24,10],[1,2.22,36.4],[2,1.74,17.32]],"ltp":2.3,"tv":30.69,"id":169}]}]}
{"op":"mcm","clk":"11801856247","pt":1723080200914,"mc":[{"id":"1.231447835","rc":[{"batb":[[0,2.22,36.4],[1,1.74,17.32],[2,1.53,94.34]],"ltp":2.3,"tv":30.69,"id":169}]}]}
{"op":"mcm","clk":"11801856346","pt":1723080203432,"mc":[{"id":"1.231447835","rc":[{"batb":[[0,2.24,10],[1,2.22,36.4],[2,1.74,17.32]],"ltp":2.3,"tv":30.69,"id":169}]}]}
{"op":"mcm","clk":"11801856501","pt":1723080207030,"mc":[{"id":"1.231447835","rc":[{"batb":[[0,2.22,36.4],[1,1.74,17.32],[2,1.53,94.34]],"ltp":2.3,"tv":30.69,"id":169}]}]}
{"op":"mcm","clk":"11801856594","pt":1723080210055,"mc":[{"id":"1.231447835","rc":[{"batb":[[0,2.24,10],[1,2.22,36.4],[2,1.74,17.32]],"ltp":2.3,"tv":30.69,"id":169}]}]}
{"op":"mcm","clk":"11801856748","pt":1723080213464,"mc":[{"id":"1.231447835","rc":[{"batb":[[0,2.22,36.4],[1,1.74,17.32],[2,1.53,94.34]],"ltp":2.3,"tv":30.69,"id":169}]}]}
{"op":"mcm","clk":"11801856942","pt":1723080218048,"mc":[{"id":"1.231447835","rc":[{"batb":[[0,2.24,10],[1,2.22,36.4],[2,1.74,17.32]],"ltp":2.3,"tv":30.69,"id":169}]}]}
{"op":"mcm","clk":"11801857074","pt":1723080221451,"mc":[{"id":"1.231447835","rc":[{"batb":[[0,2.22,36.4],[1,1.74,17.32],[2,1.53,94.34]],"ltp":2.3,"tv":30.69,"id":169}]}]}
{"op":"mcm","clk":"11801857235","pt":1723080224445,"mc":[{"id":"1.231447835","rc":[{"batb":[[0,2.24,10],[1,2.22,36.4],[2,1.74,17.32]],"ltp":2.3,"tv":30.69,"id":169}]}]}
{"op":"mcm","clk":"11801857376","pt":1723080227840,"mc":[{"id":"1.231447835","rc":[{"batb":[[0,2.22,36.4],[1,1.74,17.32],[2,1.53,94.34]],"ltp":2.3,"tv":30.69,"id":169}]}]}
{"op":"mcm","clk":"11801857510","pt":1723080230666,"mc":[{"id":"1.231447835","rc":[{"batb":[[0,2.24,10],[1,2.22,36.4],[2,1.74,17.32]],"ltp":2.3,"tv":30.69,"id":169}]}]}
{"op":"mcm","clk":"11801857621","pt":1723080234169,"mc":[{"id":"1.231447835","rc":[{"batb":[[0,2.22,36.4],[1,1.74,17.32],[2,1.53,94.34]],"ltp":2.3,"tv":30.69,"id":169}]}]}
{"op":"mcm","clk":"11801857712","pt":1723080236480,"mc":[{"id":"1.231447835","rc":[{"batb":[[0,2.24,10],[1,2.22,36.4],[2,1.74,17.32]],"ltp":2.3,"tv":30.69,"id":169}]}]}
{"op":"mcm","clk":"11801857822","pt":1723080239870,"mc":[{"id":"1.231447835","rc":[{"batb":[[0,2.22,36.4],[1,1.74,17.32],[2,1.53,94.34]],"ltp":2.3,"tv":30.69,"id":169}]}]}
{"op":"mcm","clk":"11801857930","pt":1723080242349,"mc":[{"id":"1.231447835","rc":[{"batb":[[0,2.24,10],[1,2.22,36.4],[2,1.74,17.32]],"ltp":2.3,"tv":30.69,"id":169}]}]}
{"op":"mcm","clk":"11801858085","pt":1723080245949,"mc":[{"id":"1.231447835","rc":[{"batb":[[0,2.22,36.4],[1,1.74,17.32],[2,1.53,94.34]],"ltp":2.3,"tv":30.69,"id":169}]}]}
{"op":"mcm","clk":"11801858176","pt":1723080248361,"mc":[{"id":"1.231447835","rc":[{"batb":[[0,2.24,10],[1,2.22,36.4],[2,1.74,17.32]],"ltp":2.3,"tv":30.69,"id":169}]}]}
{"op":"mcm","clk":"11801858339","pt":1723080251860,"mc":[{"id":"1.231447835","rc":[{"batb":[[0,2.22,36.4],[1,1.74,17.32],[2,1.53,94.34]],"ltp":2.3,"tv":30.69,"id":169}]}]}
{"op":"mcm","clk":"11801858435","pt":1723080254475,"mc":[{"id":"1.231447835","rc":[{"batb":[[0,2.24,10],[1,2.22,36.4],[2,1.74,17.32]],"ltp":2.3,"tv":30.69,"id":169}]}]}
{"op":"mcm","clk":"11801858558","pt":1723080257966,"mc":[{"id":"1.231447835","rc":[{"batb":[[0,2.22,36.4],[1,1.74,17.32],[2,1.53,94.34]],"ltp":2.3,"tv":30.69,"id":169}]}]}
{"op":"mcm","clk":"11801858684","pt":1723080261306,"mc":[{"id":"1.231447835","rc":[{"batb":[[0,2.24,10],[1,2.22,36.4],[2,1.74,17.32]],"ltp":2.3,"tv":30.69,"id":169}]}]}
{"op":"mcm","clk":"11801858788","pt":1723080264799,"mc":[{"id":"1.231447835","rc":[{"batb":[[0,2.22,36.4],[1,1.74,17.32],[2,1.53,94.34]],"ltp":2.3,"tv":30.69,"id":169}]}]}
{"op":"mcm","clk":"11801858848","pt":1723080267008,"mc":[{"id":"1.231447835","rc":[{"batb":[[0,2.24,10],[1,2.22,36.4],[2,1.74,17.32]],"ltp":2.3,"tv":30.69,"id":169}]}]}
{"op":"mcm","clk":"11801858968","pt":1723080270502,"mc":[{"id":"1.231447835","rc":[{"batb":[[0,2.22,36.4],[1,1.74,17.32],[2,1.53,94.34]],"ltp":2.3,"tv":30.69,"id":169}]}]}
{"op":"mcm","clk":"11801859062","pt":1723080273075,"mc":[{"id":"1.231447835","rc":[{"batb":[[0,2.24,10],[1,2.22,36.4],[2,1.74,17.32]],"ltp":2.3,"tv":30.69,"id":169}]}]}
{"op":"mcm","clk":"11801859186","pt":1723080276380,"mc":[{"id":"1.231447835","rc":[{"batb":[[0,2.22,36.4],[1,1.74,17.32],[2,1.53,94.34]],"ltp":2.3,"tv":30.69,"id":169}]}]}
{"op":"mcm","clk":"11801859286","pt":1723080279207,"mc":[{"id":"1.231447835","rc":[{"batb":[[0,2.24,10],[1,2.22,36.4],[2,1.74,17.32]],"ltp":2.3,"tv":30.69,"id":169}]}]}
{"op":"mcm","clk":"11801859410","pt":1723080282606,"mc":[{"id":"1.231447835","rc":[{"batb":[[0,2.22,36.4],[1,1.74,17.32],[2,1.53,94.34]],"ltp":2.3,"tv":30.69,"id":169}]}]}
{"op":"mcm","clk":"11801859521","pt":1723080285331,"mc":[{"id":"1.231447835","rc":[{"batb":[[0,2.24,10],[1,2.22,36.4],[2,1.74,17.32]],"ltp":2.3,"tv":30.69,"id":169}]}]}
{"op":"mcm","clk":"11801859655","pt":1723080288726,"mc":[{"id":"1.231447835","rc":[{"batb":[[0,2.22,36.4],[1,1.74,17.32],[2,1.53,94.34]],"ltp":2.3,"tv":30.69,"id":169}]}]}
{"op":"mcm","clk":"11801859785","pt":1723080291919,"mc":[{"id":"1.231447835","rc":[{"batb":[[0,2.24,10],[1,2.22,36.4],[2,1.74,17.32]],"ltp":2.3,"tv":30.69,"id":169}]}]}
{"op":"mcm","clk":"11801859957","pt":1723080295827,"mc":[{"id":"1.231447835","rc":[{"batb":[[0,2.22,36.4],[1,1.74,17.32],[2,1.53,94.34]],"ltp":2.3,"tv":30.69,"id":169}]}]}
{"op":"mcm","clk":"11801860062","pt":1723080298705,"mc":[{"id":"1.231447835","rc":[{"batb":[[0,2.24,10],[1,2.22,36.4],[2,1.74,17.32]],"ltp":2.3,"tv":30.69,"id":169}]}]}
{"op":"mcm","clk":"11801860199","pt":1723080302214,"mc":[{"id":"1.231447835","rc":[{"batb":[[0,2.22,36.4],[1,1.74,17.32],[2,1.53,94.34]],"ltp":2.3,"tv":30.69,"id":169}]}]}
{"op":"mcm","clk":"11801860292","pt":1723080304704,"mc":[{"id":"1.231447835","rc":[{"batb":[[0,2.24,10],[1,2.22,36.4],[2,1.74,17.32]],"ltp":2.3,"tv":30.69,"id":169}]}]}
{"op":"mcm","clk":"11801860435","pt":1723080308246,"mc":[{"id":"1.231447835","rc":[{"batb":[[0,2.22,36.4],[1,1.74,17.32],[2,1.53,94.34]],"ltp":2.3,"tv":30.69,"id":169}]}]}
{"op":"mcm","clk":"11801860576","pt":1723080312417,"mc":[{"id":"1.231447835","rc":[{"batb":[[0,2.24,10],[1,2.22,36.4],[2,1.74,17.32]],"ltp":2.3,"tv":30.69,"id":169}]}]}
{"op":"mcm","clk":"11801860711","pt":1723080315857,"mc":[{"id":"1.231447835","rc":[{"batb":[[0,2.22,36.4],[1,1.74,17.32],[2,1.53,94.34]],"ltp":2.3,"tv":30.69,"id":169}]}]}
{"op":"mcm","clk":"11801860834","pt":1723080318632,"mc":[{"id":"1.231447835","rc":[{"batb":[[0,2.24,10],[1,2.22,36.4],[2,1.74,17.32]],"ltp":2.3,"tv":30.69,"id":169}]}]}
{"op":"mcm","clk":"11801860968","pt":1723080322032,"mc":[{"id":"1.231447835","rc":[{"batb":[[0,2.22,36.4],[1,1.74,17.32],[2,1.53,94.34]],"ltp":2.3,"tv":30.69,"id":169}]}]}
{"op":"mcm","clk":"11801861054","pt":1723080324946,"mc":[{"id":"1.231447835","rc":[{"batb":[[0,2.24,10],[1,2.22,36.4],[2,1.74,17.32]],"ltp":2.3,"tv":30.69,"id":169}]}]}
{"op":"mcm","clk":"11801861198","pt":1723080328437,"mc":[{"id":"1.231447835","rc":[{"batb":[[0,2.22,36.4],[1,1.74,17.32],[2,1.53,94.34]],"ltp":2.3,"tv":30.69,"id":169}]}]}
{"op":"mcm","clk":"11801861285","pt":1723080331049,"mc":[{"id":"1.231447835","rc":[{"batb":[[0,2.24,10],[1,2.22,36.4],[2,1.74,17.32]],"ltp":2.3,"tv":30.69,"id":169}]}]}
{"op":"mcm","clk":"11801861415","pt":1723080334448,"mc":[{"id":"1.231447835","rc":[{"batb":[[0,2.22,36.4],[1,1.74,17.32],[2,1.53,94.34]],"ltp":2.3,"tv":30.69,"id":169}]}]}
{"op":"mcm","clk":"11801861552","pt":1723080337334,"mc":[{"id":"1.231447835","rc":[{"batb":[[0,2.24,10],[1,2.22,36.4],[2,1.74,17.32]],"ltp":2.3,"tv":30.69,"id":169}]}]}
{"op":"mcm","clk":"11801861675","pt":1723080340872,"mc":[{"id":"1.231447835","rc":[{"batb":[[0,2.22,36.4],[1,1.74,17.32],[2,1.53,94.34]],"ltp":2.3,"tv":30.69,"id":169}]}]}
{"op":"mcm","clk":"11801861757","pt":1723080343241,"mc":[{"id":"1.231447835","rc":[{"batb":[[0,2.24,10],[1,2.22,36.4],[2,1.74,17.32]],"ltp":2.3,"tv":30.69,"id":169}]}]}
{"op":"mcm","clk":"11801861929","pt":1723080346694,"mc":[{"id":"1.231447835","rc":[{"batb":[[0,2.22,36.4],[1,1.74,17.32],[2,1.53,94.34]],"ltp":2.3,"tv":30.69,"id":169}]}]}
{"op":"mcm","clk":"11801862044","pt":1723080348954,"mc":[{"id":"1.231447835","rc":[{"batb":[[0,2.24,10],[1,2.22,36.4],[2,1.74,17.32]],"ltp":2.3,"tv":30.69,"id":169}]}]}
{"op":"mcm","clk":"11801862202","pt":1723080352352,"mc":[{"id":"1.231447835","rc":[{"batb":[[0,2.22,36.4],[1,1.74,17.32],[2,1.53,94.34]],"ltp":2.3,"tv":30.69,"id":169}]}]}
{"op":"mcm","clk":"11801862385","pt":1723080356464,"mc":[{"id":"1.231447835","rc":[{"batb":[[0,2.24,10],[1,2.22,36.4],[2,1.74,17.32]],"ltp":2.3,"tv":30.69,"id":169}]}]}
{"op":"mcm","clk":"11801862551","pt":1723080360004,"mc":[{"id":"1.231447835","rc":[{"batb":[[0,2.22,36.4],[1,1.74,17.32],[2,1.53,94.34]],"ltp":2.3,"tv":30.69,"id":169}]}]}
{"op":"mcm","clk":"11801862663","pt":1723080362372,"mc":[{"id":"1.231447835","rc":[{"batb":[[0,2.24,10],[1,2.22,36.4],[2,1.74,17.32]],"ltp":2.3,"tv":30.69,"id":169}]}]}
{"op":"mcm","clk":"11801862817","pt":1723080365817,"mc":[{"id":"1.231447835","rc":[{"batb":[[0,2.22,36.4],[1,1.74,17.32],[2,1.53,94.34]],"ltp":2.3,"tv":30.69,"id":169}]}]}
{"op":"mcm","clk":"11801862993","pt":1723080369569,"mc":[{"id":"1.231447835","rc":[{"batb":[[0,2.24,10],[1,2.22,36.4],[2,1.74,17.32]],"ltp":2.3,"tv":30.69,"id":169}]}]}
{"op":"mcm","clk":"11801863174","pt":1723080372927,"mc":[{"id":"1.231447835","rc":[{"batb":[[0,2.22,36.4],[1,1.74,17.32],[2,1.53,94.34]],"ltp":2.3,"tv":30.69,"id":169}]}]}
{"op":"mcm","clk":"11801863275","pt":1723080375502,"mc":[{"id":"1.231447835","rc":[{"batb":[[0,2.24,10],[1,2.22,36.4],[2,1.74,17.32]],"ltp":2.3,"tv":30.69,"id":169}]}]}
{"op":"mcm","clk":"11801863407","pt":1723080378938,"mc":[{"id":"1.231447835","rc":[{"batb":[[0,2.22,36.4],[1,1.74,17.32],[2,1.53,94.34]],"ltp":2.3,"tv":30.69,"id":169}]}]}
{"op":"mcm","clk":"11801863531","pt":1723080381818,"mc":[{"id":"1.231447835","rc":[{"batb":[[0,2.24,10],[1,2.22,36.4],[2,1.74,17.32]],"ltp":2.3,"tv":30.69,"id":169}]}]}
{"op":"mcm","clk":"11801863674","pt":1723080385009,"mc":[{"id":"1.231447835","rc":[{"batb":[[0,2.22,36.4],[1,1.74,17.32],[2,1.53,94.34]],"ltp":2.3,"tv":30.69,"id":169}]}]}
{"op":"mcm","clk":"11801863788","pt":1723080387939,"mc":[{"id":"1.231447835","rc":[{"batb":[[0,2.24,10],[1,2.22,36.4],[2,1.74,17.32]],"ltp":2.3,"tv":30.69,"id":169}]}]}
{"op":"mcm","clk":"11801863905","pt":1723080391432,"mc":[{"id":"1.231447835","rc":[{"batb":[[0,2.22,36.4],[1,1.74,17.32],[2,1.53,94.34]],"ltp":2.3,"tv":30.69,"id":169}]}]}
{"op":"mcm","clk":"11801864011","pt":1723080393803,"mc":[{"id":"1.231447835","rc":[{"batb":[[0,2.24,10],[1,2.22,36.4],[2,1.74,17.32]],"ltp":2.3,"tv":30.69,"id":169}]}]}
{"op":"mcm","clk":"11801864147","pt":1723080397144,"mc":[{"id":"1.231447835","rc":[{"batb":[[0,2.22,36.4],[1,1.74,17.32],[2,1.53,94.34]],"ltp":2.3,"tv":30.69,"id":169}]}]}
{"op":"mcm","clk":"11801864294","pt":1723080400433,"mc":[{"id":"1.231447835","rc":[{"batb":[[0,2.24,10],[1,2.22,36.4],[2,1.74,17.32]],"ltp":2.3,"tv":30.69,"id":169}]}]}
{"op":"mcm","clk":"11801864436","pt":1723080403727,"mc":[{"id":"1.231447835","rc":[{"batb":[[0,2.22,36.4],[1,1.74,17.32],[2,1.53,94.34]],"ltp":2.3,"tv":30.69,"id":169}]}]}
{"op":"mcm","clk":"11801864550","pt":1723080406355,"mc":[{"id":"1.231447835","rc":[{"batb":[[0,2.24,10],[1,2.22,36.4],[2,1.74,17.32]],"ltp":2.3,"tv":30.69,"id":169}]}]}
{"op":"mcm","clk":"11801864646","pt":1723080409642,"mc":[{"id":"1.231447835","rc":[{"batb":[[0,2.22,36.4],[1,1.74,17.32],[2,1.53,94.34]],"ltp":2.3,"tv":30.69,"id":169}]}]}
{"op":"mcm","clk":"11801864794","pt":1723080413333,"mc":[{"id":"1.231447835","rc":[{"batb":[[0,2.24,10],[1,2.22,36.4],[2,1.74,17.32]],"ltp":2.3,"tv":30.69,"id":169}]}]}
{"op":"mcm","clk":"11801864915","pt":1723080416726,"mc":[{"id":"1.231447835","rc":[{"batb":[[0,2.22,36.4],[1,1.74,17.32],[2,1.53,94.34]],"ltp":2.3,"tv":30.69,"id":169}]}]}
{"op":"mcm","clk":"11801865019","pt":1723080419550,"mc":[{"id":"1.231447835","rc":[{"batb":[[0,2.24,10],[1,2.22,36.4],[2,1.74,17.32]],"ltp":2.3,"tv":30.69,"id":169}]}]}
{"op":"mcm","clk":"11801865177","pt":1723080422852,"mc":[{"id":"1.231447835","rc":[{"batb":[[0,2.22,36.4],[1,1.74,17.32],[2,1.53,94.34]],"ltp":2.3,"tv":30.69,"id":169}]}]}
{"op":"mcm","clk":"11801865279","pt":1723080425466,"mc":[{"id":"1.231447835","rc":[{"batb":[[0,2.24,10],[1,2.22,36.4],[2,1.74,17.32]],"ltp":2.3,"tv":30.69,"id":169}]}]}
{"op":"mcm","clk":"11801865431","pt":1723080428777,"mc":[{"id":"1.231447835","rc":[{"batb":[[0,2.22,36.4],[1,1.74,17.32],[2,1.53,94.34]],"ltp":2.3,"tv":30.69,"id":169}]}]}
{"op":"mcm","clk":"11801865545","pt":1723080431555,"mc":[{"id":"1.231447835","rc":[{"batb":[[0,2.24,10],[1,2.22,36.4],[2,1.74,17.32]],"ltp":2.3,"tv":30.69,"id":169}]}]}
{"op":"mcm","clk":"11801865721","pt":1723080434852,"mc":[{"id":"1.231447835","rc":[{"batb":[[0,2.22,36.4],[1,1.74,17.32],[2,1.53,94.34]],"ltp":2.3,"tv":30.69,"id":169}]}]}
{"op":"mcm","clk":"11801865850","pt":1723080437890,"mc":[{"id":"1.231447835","rc":[{"batb":[[0,2.24,10],[1,2.22,36.4],[2,1.74,17.32]],"ltp":2.3,"tv":30.69,"id":169}]}]}
{"op":"mcm","clk":"11801866063","pt":1723080442506,"mc":[{"id":"1.231447835","rc":[{"batb":[[0,2.22,36.4],[1,1.74,17.32],[2,1.53,94.34]],"ltp":2.3,"tv":30.69,"id":169}]}]}
{"op":"mcm","clk":"11801866141","pt":1723080444769,"mc":[{"id":"1.231447835","rc":[{"batb":[[0,2.24,10],[1,2.22,36.4],[2,1.74,17.32]],"ltp":2.3,"tv":30.69,"id":169}]}]}
{"op":"mcm","clk":"11801866330","pt":1723080449185,"mc":[{"id":"1.231447835","rc":[{"batb":[[0,2.22,36.4],[1,1.74,17.32],[2,1.53,94.34]],"ltp":2.3,"tv":30.69,"id":169}]}]}
{"op":"mcm","clk":"11801866440","pt":1723080451808,"mc":[{"id":"1.231447835","rc":[{"batb":[[0,2.24,10],[1,2.22,36.4],[2,1.74,17.32]],"ltp":2.3,"tv":30.69,"id":169}]}]}
{"op":"mcm","clk":"11801866639","pt":1723080455199,"mc":[{"id":"1.231447835","rc":[{"batb":[[0,2.22,36.4],[1,1.74,17.32],[2,1.53,94.34]],"ltp":2.3,"tv":30.69,"id":169}]}]}
{"op":"mcm","clk":"11801866814","pt":1723080457626,"mc":[{"id":"1.231447835","rc":[{"batb":[[0,2.24,10],[1,2.22,36.4],[2,1.74,17.32]],"ltp":2.3,"tv":30.69,"id":169}]}]}
{"op":"mcm","clk":"11801866965","pt":1723080461106,"mc":[{"id":"1.231447835","rc":[{"batb":[[0,2.22,36.4],[1,1.74,17.32],[2,1.53,94.34]],"ltp":2.3,"tv":30.69,"id":169}]}]}
{"op":"mcm","clk":"11801867059","pt":1723080463520,"mc":[{"id":"1.231447835","rc":[{"batb":[[0,2.24,10],[1,2.22,36.4],[2,1.74,17.32]],"ltp":2.3,"tv":30.69,"id":169}]}]}
{"op":"mcm","clk":"11801867203","pt":1723080466924,"mc":[{"id":"1.231447835","rc":[{"batb":[[0,2.22,36.4],[1,1.74,17.32],[2,1.53,94.34]],"ltp":2.3,"tv":30.69,"id":169}]}]}
{"op":"mcm","clk":"11801867275","pt":1723080469027,"mc":[{"id":"1.231447835","rc":[{"batb":[[0,2.24,10],[1,2.22,36.4],[2,1.74,17.32]],"ltp":2.3,"tv":30.69,"id":169}]}]}
{"op":"mcm","clk":"11801867398","pt":1723080472242,"mc":[{"id":"1.231447835","rc":[{"batb":[[0,2.22,36.4],[1,1.74,17.32],[2,1.53,94.34]],"ltp":2.3,"tv":30.69,"id":169}]}]}
{"op":"mcm","clk":"11801867546","pt":1723080475937,"mc":[{"id":"1.231447835","rc":[{"batb":[[0,2.24,10],[1,2.22,36.4],[2,1.74,17.32]],"ltp":2.3,"tv":30.69,"id":169}]}]}
{"op":"mcm","clk":"11801867687","pt":1723080479737,"mc":[{"id":"1.231447835","rc":[{"batb":[[0,2.22,36.4],[1,1.74,17.32],[2,1.53,94.34]],"ltp":2.3,"tv":30.69,"id":169}]}]}
{"op":"mcm","clk":"11801867792","pt":1723080482115,"mc":[{"id":"1.231447835","rc":[{"batb":[[0,2.24,10],[1,2.22,36.4],[2,1.74,17.32]],"ltp":2.3,"tv":30.69,"id":169}]}]}
{"op":"mcm","clk":"11801867957","pt":1723080485928,"mc":[{"id":"1.231447835","rc":[{"batb":[[0,2.22,36.4],[1,1.74,17.32],[2,1.53,94.34]],"ltp":2.3,"tv":30.69,"id":169}]}]}
{"op":"mcm","clk":"11801868098","pt":1723080489042,"mc":[{"id":"1.231447835","rc":[{"batb":[[0,2.24,10],[1,2.22,36.4],[2,1.74,17.32]],"ltp":2.3,"tv":30.69,"id":169}]}]}
{"op":"mcm","clk":"11801868269","pt":1723080492716,"mc":[{"id":"1.231447835","rc":[{"batb":[[0,2.22,36.4],[1,1.74,17.32],[2,1.53,94.34]],"ltp":2.3,"tv":30.69,"id":169}]}]}
{"op":"mcm","clk":"11801868384","pt":1723080495540,"mc":[{"id":"1.231447835","rc":[{"batb":[[0,2.24,10],[1,2.22,36.4],[2,1.74,17.32]],"ltp":2.3,"tv":30.69,"id":169}]}]}
{"op":"mcm","clk":"11801868554","pt":1723080499025,"mc":[{"id":"1.231447835","rc":[{"batb":[[0,2.22,36.4],[1,1.74,17.32],[2,1.53,94.34]],"ltp":2.3,"tv":30.69,"id":169}]}]}
{"op":"mcm","clk":"11801868680","pt":1723080501337,"mc":[{"id":"1.231447835","rc":[{"batb":[[0,2.24,10],[1,2.22,36.4],[2,1.74,17.32]],"ltp":2.3,"tv":30.69,"id":169}]}]}
{"op":"mcm","clk":"11801868832","pt":1723080504727,"mc":[{"id":"1.231447835","rc":[{"batb":[[0,2.22,36.4],[1,1.74,17.32],[2,1.53,94.34]],"ltp":2.3,"tv":30.69,"id":169}]}]}
{"op":"mcm","clk":"11801868956","pt":1723080507423,"mc":[{"id":"1.231447835","rc":[{"batb":[[0,2.24,10],[1,2.22,36.4],[2,1.74,17.32]],"ltp":2.3,"tv":30.69,"id":169}]}]}
{"op":"mcm","clk":"11801869106","pt":1723080510964,"mc":[{"id":"1.231447835","rc":[{"batb":[[0,2.22,36.4],[1,1.74,17.32],[2,1.53,94.34]],"ltp":2.3,"tv":30.69,"id":169}]}]}
{"op":"mcm","clk":"11801869224","pt":1723080513536,"mc":[{"id":"1.231447835","rc":[{"batb":[[0,2.24,10],[1,2.22,36.4],[2,1.74,17.32]],"ltp":2.3,"tv":30.69,"id":169}]}]}
{"op":"mcm","clk":"11801869378","pt":1723080517053,"mc":[{"id":"1.231447835","rc":[{"batb":[[0,2.22,36.4],[1,1.74,17.32],[2,1.53,94.34]],"ltp":2.3,"tv":30.69,"id":169}]}]}
{"op":"mcm","clk":"11801869527","pt":1723080519976,"mc":[{"id":"1.231447835","rc":[{"batb":[[0,2.24,10],[1,2.22,36.4],[2,1.74,17.32]],"ltp":2.3,"tv":30.69,"id":169}]}]}
{"op":"mcm","clk":"11801869705","pt":1723080523373,"mc":[{"id":"1.231447835","rc":[{"batb":[[0,2.22,36.4],[1,1.74,17.32],[2,1.53,94.34]],"ltp":2.3,"tv":30.69,"id":169}]}]}
{"op":"mcm","clk":"11801869823","pt":1723080525582,"mc":[{"id":"1.231447835","rc":[{"batb":[[0,2.24,10],[1,2.22,36.4],[2,1.74,17.32]],"ltp":2.3,"tv":30.69,"id":169}]}]}
{"op":"mcm","clk":"11801869964","pt":1723080528970,"mc":[{"id":"1.231447835","rc":[{"batb":[[0,2.22,36.4],[1,1.74,17.32],[2,1.53,94.34]],"ltp":2.3,"tv":30.69,"id":169}]}]}
{"op":"mcm","clk":"11801870144","pt":1723080532886,"mc":[{"id":"1.231447835","rc":[{"batb":[[0,2.24,10],[1,2.22,36.4],[2,1.74,17.32]],"ltp":2.3,"tv":30.69,"id":169}]}]}
{"op":"mcm","clk":"11801870323","pt":1723080536848,"mc":[{"id":"1.231447835","rc":[{"batb":[[0,2.22,36.4],[1,1.74,17.32],[2,1.53,94.34]],"ltp":2.3,"tv":30.69,"id":169}]}]}
{"op":"mcm","clk":"11801870458","pt":1723080539888,"mc":[{"id":"1.231447835","rc":[{"batb":[[0,2.24,10],[1,2.22,36.4],[2,1.74,17.32]],"ltp":2.3,"tv":30.69,"id":169}]}]}
{"op":"mcm","clk":"11801870624","pt":1723080543397,"mc":[{"id":"1.231447835","rc":[{"batb":[[0,2.22,36.4],[1,1.74,17.32],[2,1.53,94.34]],"ltp":2.3,"tv":30.69,"id":169}]}]}
{"op":"mcm","clk":"11801870754","pt":1723080546089,"mc":[{"id":"1.231447835","rc":[{"batb":[[0,2.24,10],[1,2.22,36.4],[2,1.74,17.32]],"ltp":2.3,"tv":30.69,"id":169}]}]}
{"op":"mcm","clk":"11801870927","pt":1723080549701,"mc":[{"id":"1.231447835","rc":[{"batb":[[0,2.22,36.4],[1,1.74,17.32],[2,1.53,94.34]],"ltp":2.3,"tv":30.69,"id":169}]}]}
{"op":"mcm","clk":"11801871102","pt":1723080553116,"mc":[{"id":"1.231447835","rc":[{"batb":[[0,2.24,10],[1,2.22,36.4],[2,1.74,17.32]],"ltp":2.3,"tv":30.69,"id":169}]}]}
{"op":"mcm","clk":"11801871278","pt":1723080556311,"mc":[{"id":"1.231447835","rc":[{"batb":[[0,2.22,36.4],[1,1.74,17.32],[2,1.53,94.34]],"ltp":2.3,"tv":30.69,"id":169}]}]}
{"op":"mcm","clk":"11801871375","pt":1723080558889,"mc":[{"id":"1.231447835","rc":[{"batb":[[0,2.24,10],[1,2.22,36.4],[2,1.74,17.32]],"ltp":2.3,"tv":30.69,"id":169}]}]}
{"op":"mcm","clk":"11801871536","pt":1723080562297,"mc":[{"id":"1.231447835","rc":[{"batb":[[0,2.22,36.4],[1,1.74,17.32],[2,1.53,94.34]],"ltp":2.3,"tv":30.69,"id":169}]}]}
{"op":"mcm","clk":"11801871650","pt":1723080565400,"mc":[{"id":"1.231447835","rc":[{"batb":[[0,2.24,10],[1,2.22,36.4],[2,1.74,17.32]],"ltp":2.3,"tv":30.69,"id":169}]}]}
{"op":"mcm","clk":"11801871791","pt":1723080568809,"mc":[{"id":"1.231447835","rc":[{"batb":[[0,2.22,36.4],[1,1.74,17.32],[2,1.53,94.34]],"ltp":2.3,"tv":30.69,"id":169}]}]}
{"op":"mcm","clk":"11801871944","pt":1723080572631,"mc":[{"id":"1.231447835","rc":[{"batb":[[0,2.24,10],[1,2.22,36.4],[2,1.74,17.32]],"ltp":2.3,"tv":30.69,"id":169}]}]}
{"op":"mcm","clk":"11801872096","pt":1723080576019,"mc":[{"id":"1.231447835","rc":[{"batb":[[0,2.22,36.4],[1,1.74,17.32],[2,1.53,94.34]],"ltp":2.3,"tv":30.69,"id":169}]}]}
{"op":"mcm","clk":"11801872226","pt":1723080578900,"mc":[{"id":"1.231447835","rc":[{"batb":[[0,2.24,10],[1,2.22,36.4],[2,1.74,17.32]],"ltp":2.3,"tv":30.69,"id":169}]}]}
{"op":"mcm","clk":"11801872375","pt":1723080582422,"mc":[{"id":"1.231447835","rc":[{"batb":[[0,2.22,36.4],[1,1.74,17.32],[2,1.53,94.34]],"ltp":2.3,"tv":30.69,"id":169}]}]}
{"op":"mcm","clk":"11801872483","pt":1723080584838,"mc":[{"id":"1.231447835","rc":[{"batb":[[0,2.24,10],[1,2.22,36.4],[2,1.74,17.32]],"ltp":2.3,"tv":30.69,"id":169}]}]}
{"op":"mcm","clk":"11801872617","pt":1723080588218,"mc":[{"id":"1.231447835","rc":[{"batb":[[0,2.22,36.4],[1,1.74,17.32],[2,1.53,94.34]],"ltp":2.3,"tv":30.69,"id":169}]}]}
{"op":"mcm","clk":"11801872738","pt":1723080590728,"mc":[{"id":"1.231447835","rc":[{"batb":[[0,2.24,10],[1,2.22,36.4],[2,1.74,17.32]],"ltp":2.3,"tv":30.69,"id":169}]}]}
{"op":"mcm","clk":"11801872889","pt":1723080594063,"mc":[{"id":"1.231447835","rc":[{"batb":[[0,2.22,36.4],[1,1.74,17.32],[2,1.53,94.34]],"ltp":2.3,"tv":30.69,"id":169}]}]}
{"op":"mcm","clk":"11801873020","pt":1723080596735,"mc":[{"id":"1.231447835","rc":[{"batb":[[0,2.24,10],[1,2.22,36.4],[2,1.74,17.32]],"ltp":2.3,"tv":30.69,"id":169}]}]}
{"op":"mcm","clk":"11801873169","pt":1723080600020,"mc":[{"id":"1.231447835","rc":[{"batb":[[0,2.22,36.4],[1,1.74,17.32],[2,1.53,94.34]],"ltp":2.3,"tv":30.69,"id":169}]}]}
{"op":"mcm","clk":"11801873316","pt":1723080602850,"mc":[{"id":"1.231447835","rc":[{"batb":[[0,2.24,10],[1,2.22,36.4],[2,1.74,17.32]],"ltp":2.3,"tv":30.69,"id":169}]}]}
{"op":"mcm","clk":"11801873506","pt":1723080606343,"mc":[{"id":"1.231447835","rc":[{"batb":[[0,2.22,36.4],[1,1.74,17.32],[2,1.53,94.34]],"ltp":2.3,"tv":30.69,"id":169}]}]}
{"op":"mcm","clk":"11801873633","pt":1723080608956,"mc":[{"id":"1.231447835","rc":[{"batb":[[0,2.24,10],[1,2.22,36.4],[2,1.74,17.32]],"ltp":2.3,"tv":30.69,"id":169}]}]}
{"op":"mcm","clk":"11801873799","pt":1723080612344,"mc":[{"id":"1.231447835","rc":[{"batb":[[0,2.22,36.4],[1,1.74,17.32],[2,1.53,94.34]],"ltp":2.3,"tv":30.69,"id":169}]}]}
{"op":"mcm","clk":"11801873933","pt":1723080614864,"mc":[{"id":"1.231447835","rc":[{"batb":[[0,2.24,10],[1,2.22,36.4],[2,1.74,17.32]],"ltp":2.3,"tv":30.69,"id":169}]}]}
{"op":"mcm","clk":"11801874084","pt":1723080618557,"mc":[{"id":"1.231447835","rc":[{"batb":[[0,2.22,36.4],[1,1.74,17.32],[2,1.53,94.34]],"ltp":2.3,"tv":30.69,"id":169}]}]}
{"op":"mcm","clk":"11801874199","pt":1723080620744,"mc":[{"id":"1.231447835","rc":[{"batb":[[0,2.24,10],[1,2.22,36.4],[2,1.74,17.32]],"ltp":2.3,"tv":30.69,"id":169}]}]}
{"op":"mcm","clk":"11801874368","pt":1723080624385,"mc":[{"id":"1.231447835","rc":[{"batb":[[0,2.22,36.4],[1,1.74,17.32],[2,1.53,94.34]],"ltp":2.3,"tv":30.69,"id":169}]}]}
{"op":"mcm","clk":"11801874480","pt":1723080627055,"mc":[{"id":"1.231447835","rc":[{"batb":[[0,2.24,10],[1,2.22,36.4],[2,1.74,17.32]],"ltp":2.3,"tv":30.69,"id":169}]}]}
{"op":"mcm","clk":"11801874620","pt":1723080630647,"mc":[{"id":"1.231447835","rc":[{"batb":[[0,2.22,36.4],[1,1.74,17.32],[2,1.53,94.34]],"ltp":2.3,"tv":30.69,"id":169}]}]}
{"op":"mcm","clk":"11801874769","pt":1723080634180,"mc":[{"id":"1.231447835","rc":[{"batb":[[0,2.24,10],[1,2.22,36.4],[2,1.74,17.32]],"ltp":2.3,"tv":30.69,"id":169}]}]}
{"op":"mcm","clk":"11801874918","pt":1723080637574,"mc":[{"id":"1.231447835","rc":[{"batb":[[0,2.22,36.4],[1,1.74,17.32],[2,1.53,94.34]],"ltp":2.3,"tv":30.69,"id":169}]}]}
{"op":"mcm","clk":"11801875040","pt":1723080639875,"mc":[{"id":"1.231447835","rc":[{"batb":[[0,2.24,10],[1,2.22,36.4],[2,1.74,17.32]],"ltp":2.3,"tv":30.69,"id":169}]}]}
{"op":"mcm","clk":"11801875178","pt":1723080643160,"mc":[{"id":"1.231447835","rc":[{"batb":[[0,2.22,36.4],[1,1.74,17.32],[2,1.53,94.34]],"ltp":2.3,"tv":30.69,"id":169}]}]}
{"op":"mcm","clk":"11801875276","pt":1723080645871,"mc":[{"id":"1.231447835","rc":[{"batb":[[0,2.24,10],[1,2.22,36.4],[2,1.74,17.32]],"ltp":2.3,"tv":30.69,"id":169}]}]}
{"op":"mcm","clk":"11801875409","pt":1723080649265,"mc":[{"id":"1.231447835","rc":[{"batb":[[0,2.22,36.4],[1,1.74,17.32],[2,1.53,94.34]],"ltp":2.3,"tv":30.69,"id":169}]}]}
{"op":"mcm","clk":"11801875527","pt":1723080651990,"mc":[{"id":"1.231447835","rc":[{"batb":[[0,2.24,10],[1,2.22,36.4],[2,1.74,17.32]],"ltp":2.3,"tv":30.69,"id":169}]}]}
{"op":"mcm","clk":"11801875729","pt":1723080656303,"mc":[{"id":"1.231447835","rc":[{"batb":[[0,2.22,36.4],[1,1.74,17.32],[2,1.53,94.34]],"ltp":2.3,"tv":30.69,"id":169}]}]}
{"op":"mcm","clk":"11801875846","pt":1723080658668,"mc":[{"id":"1.231447835","rc":[{"batb":[[0,2.24,10],[1,2.22,36.4],[2,1.74,17.32]],"ltp":2.3,"tv":30.69,"id":169}]}]}
{"op":"mcm","clk":"11801875993","pt":1723080662108,"mc":[{"id":"1.231447835","rc":[{"batb":[[0,2.22,36.4],[1,1.74,17.32],[2,1.53,94.34]],"ltp":2.3,"tv":30.69,"id":169}]}]}
{"op":"mcm","clk":"11801876147","pt":1723080665803,"mc":[{"id":"1.231447835","rc":[{"batb":[[0,2.24,10],[1,2.22,36.4],[2,1.74,17.32]],"ltp":2.3,"tv":30.69,"id":169}]}]}
{"op":"mcm","clk":"11801876316","pt":1723080669396,"mc":[{"id":"1.231447835","rc":[{"batb":[[0,2.22,36.4],[1,1.74,17.32],[2,1.53,94.34]],"ltp":2.3,"tv":30.69,"id":169}]}]}
{"op":"mcm","clk":"11801876465","pt":1723080672125,"mc":[{"id":"1.231447835","rc":[{"batb":[[0,2.24,10],[1,2.22,36.4],[2,1.74,17.32]],"ltp":2.3,"tv":30.69,"id":169}]}]}
{"op":"mcm","clk":"11801876648","pt":1723080675512,"mc":[{"id":"1.231447835","rc":[{"batb":[[0,2.22,36.4],[1,1.74,17.32],[2,1.53,94.34]],"ltp":2.3,"tv":30.69,"id":169}]}]}
{"op":"mcm","clk":"11801876761","pt":1723080678128,"mc":[{"id":"1.231447835","rc":[{"batb":[[0,2.24,10],[1,2.22,36.4],[2,1.74,17.32]],"ltp":2.3,"tv":30.69,"id":169}]}]}
{"op":"mcm","clk":"11801876932","pt":1723080681515,"mc":[{"id":"1.231447835","rc":[{"batb":[[0,2.22,36.4],[1,1.74,17.32],[2,1.53,94.34]],"ltp":2.3,"tv":30.69,"id":169}]}]}
{"op":"mcm","clk":"11801877049","pt":1723080684230,"mc":[{"id":"1.231447835","rc":[{"batb":[[0,2.24,10],[1,2.22,36.4],[2,1.74,17.32]],"ltp":2.3,"tv":30.69,"id":169}]}]}
{"op":"mcm","clk":"11801877197","pt":1723080687725,"mc":[{"id":"1.231447835","rc":[{"batb":[[0,2.22,36.4],[1,1.74,17.32],[2,1.53,94.34]],"ltp":2.3,"tv":30.69,"id":169}]}]}
{"op":"mcm","clk":"11801877356","pt":1723080691529,"mc":[{"id":"1.231447835","rc":[{"batb":[[0,2.24,10],[1,2.22,36.4],[2,1.74,17.32]],"ltp":2.3,"tv":30.69,"id":169}]}]}
{"op":"mcm","clk":"11801877521","pt":1723080695121,"mc":[{"id":"1.231447835","rc":[{"batb":[[0,2.22,36.4],[1,1.74,17.32],[2,1.53,94.34]],"ltp":2.3,"tv":30.69,"id":169}]}]}
{"op":"mcm","clk":"11801877638","pt":1723080697323,"mc":[{"id":"1.231447835","rc":[{"batb":[[0,2.24,10],[1,2.22,36.4],[2,1.74,17.32]],"ltp":2.3,"tv":30.69,"id":169}]}]}
{"op":"mcm","clk":"11801877800","pt":1723080700866,"mc":[{"id":"1.231447835","rc":[{"batb":[[0,2.22,36.4],[1,1.74,17.32],[2,1.53,94.34]],"ltp":2.3,"tv":30.69,"id":169}]}]}
{"op":"mcm","clk":"11801877902","pt":1723080703325,"mc":[{"id":"1.231447835","rc":[{"batb":[[0,2.24,10],[1,2.22,36.4],[2,1.74,17.32]],"ltp":2.3,"tv":30.69,"id":169}]}]}
{"op":"mcm","clk":"11801878096","pt":1723080707030,"mc":[{"id":"1.231447835","rc":[{"batb":[[0,2.22,36.4],[1,1.74,17.32],[2,1.53,94.34]],"ltp":2.3,"tv":30.69,"id":169}]}]}
{"op":"mcm","clk":"11801878230","pt":1723080709851,"mc":[{"id":"1.231447835","rc":[{"batb":[[0,2.24,10],[1,2.22,36.4],[2,1.74,17.32]],"ltp":2.3,"tv":30.69,"id":169}]}]}
{"op":"mcm","clk":"11801878436","pt":1723080713185,"mc":[{"id":"1.231447835","rc":[{"batb":[[0,2.22,36.4],[1,1.74,17.32],[2,1.53,94.34]],"ltp":2.3,"tv":30.69,"id":169}]}]}
{"op":"mcm","clk":"11801878622","pt":1723080717561,"mc":[{"id":"1.231447835","rc":[{"batb":[[0,2.24,10],[1,2.22,36.4],[2,1.74,17.32]],"ltp":2.3,"tv":30.69,"id":169}]}]}
{"op":"mcm","clk":"11801878805","pt":1723080720947,"mc":[{"id":"1.231447835","rc":[{"batb":[[0,2.22,36.4],[1,1.74,17.32],[2,1.53,94.34]],"ltp":2.3,"tv":30.69,"id":169}]}]}
{"op":"mcm","clk":"11801878903","pt":1723080723470,"mc":[{"id":"1.231447835","rc":[{"batb":[[0,2.24,10],[1,2.22,36.4],[2,1.74,17.32]],"ltp":2.3,"tv":30.69,"id":169}]}]}
{"op":"mcm","clk":"11801879115","pt":1723080726756,"mc":[{"id":"1.231447835","rc":[{"batb":[[0,2.22,36.4],[1,1.74,17.32],[2,1.53,94.34]],"ltp":2.3,"tv":30.69,"id":169}]}]}
{"op":"mcm","clk":"11801879258","pt":1723080729675,"mc":[{"id":"1.231447835","rc":[{"batb":[[0,2.24,10],[1,2.22,36.4],[2,1.74,17.32]],"ltp":2.3,"tv":30.69,"id":169}]}]}
{"op":"mcm","clk":"11801879495","pt":1723080733167,"mc":[{"id":"1.231447835","rc":[{"batb":[[0,2.22,36.4],[1,1.74,17.32],[2,1.53,94.34]],"ltp":2.3,"tv":30.69,"id":169}]}]}
{"op":"mcm","clk":"11801879595","pt":1723080735888,"mc":[{"id":"1.231447835","rc":[{"batb":[[0,2.24,10],[1,2.22,36.4],[2,1.74,17.32]],"ltp":2.3,"tv":30.69,"id":169}]}]}
{"op":"mcm","clk":"11801879743","pt":1723080739265,"mc":[{"id":"1.231447835","rc":[{"batb":[[0,2.22,36.4],[1,1.74,17.32],[2,1.53,94.34]],"ltp":2.3,"tv":30.69,"id":169}]}]}
{"op":"mcm","clk":"11801879884","pt":1723080742601,"mc":[{"id":"1.231447835","rc":[{"batb":[[0,2.24,10],[1,2.22,36.4],[2,1.74,17.32]],"ltp":2.3,"tv":30.69,"id":169}]}]}
{"op":"mcm","clk":"11801880061","pt":1723080746094,"mc":[{"id":"1.231447835","rc":[{"batb":[[0,2.22,36.4],[1,1.74,17.32],[2,1.53,94.34]],"ltp":2.3,"tv":30.69,"id":169}]}]}
{"op":"mcm","clk":"11801880154","pt":1723080748573,"mc":[{"id":"1.231447835","rc":[{"batb":[[0,2.24,10],[1,2.22,36.4],[2,1.74,17.32]],"ltp":2.3,"tv":30.69,"id":169}]}]}
{"op":"mcm","clk":"11801880290","pt":1723080752004,"mc":[{"id":"1.231447835","rc":[{"batb":[[0,2.22,36.4],[1,1.74,17.32],[2,1.53,94.34]],"ltp":2.3,"tv":30.69,"id":169}]}]}
{"op":"mcm","clk":"11801880446","pt":1723080755706,"mc":[{"id":"1.231447835","rc":[{"batb":[[0,2.24,10],[1,2.22,36.4],[2,1.74,17.32]],"ltp":2.3,"tv":30.69,"id":169}]}]}
{"op":"mcm","clk":"11801880670","pt":1723080759004,"mc":[{"id":"1.231447835","rc":[{"batb":[[0,2.22,36.4],[1,1.74,17.32],[2,1.53,94.34]],"ltp":2.3,"tv":30.69,"id":169}]}]}
{"op":"mcm","clk":"11801880815","pt":1723080761784,"mc":[{"id":"1.231447835","rc":[{"batb":[[0,2.24,10],[1,2.22,36.4],[2,1.74,17.32]],"ltp":2.3,"tv":30.69,"id":169}]}]}
{"op":"mcm","clk":"11801880968","pt":1723080765521,"mc":[{"id":"1.231447835","rc":[{"batb":[[0,2.22,36.4],[1,1.74,17.32],[2,1.53,94.34]],"ltp":2.3,"tv":30.69,"id":169}]}]}
{"op":"mcm","clk":"11801881097","pt":1723080768091,"mc":[{"id":"1.231447835","rc":[{"batb":[[0,2.24,10],[1,2.22,36.4],[2,1.74,17.32]],"ltp":2.3,"tv":30.69,"id":169}]}]}
{"op":"mcm","clk":"11801881297","pt":1723080771321,"mc":[{"id":"1.231447835","rc":[{"batb":[[0,2.22,36.4],[1,1.74,17.32],[2,1.53,94.34]],"ltp":2.3,"tv":30.69,"id":169}]}]}
{"op":"mcm","clk":"11801881369","pt":1723080773929,"mc":[{"id":"1.231447835","rc":[{"batb":[[0,2.24,10],[1,2.22,36.4],[2,1.74,17.32]],"ltp":2.3,"tv":30.69,"id":169}]}]}
{"op":"mcm","clk":"11801881542","pt":1723080777212,"mc":[{"id":"1.231447835","rc":[{"batb":[[0,2.22,36.4],[1,1.74,17.32],[2,1.53,94.34]],"ltp":2.3,"tv":30.69,"id":169}]}]}
{"op":"mcm","clk":"11801881793","pt":1723080780037,"mc":[{"id":"1.231447835","rc":[{"batb":[[0,2.24,10],[1,2.22,36.4],[2,1.74,17.32]],"ltp":2.3,"tv":30.69,"id":169}]}]}
{"op":"mcm","clk":"11801882015","pt":1723080783324,"mc":[{"id":"1.231447835","rc":[{"batb":[[0,2.22,36.4],[1,1.74,17.32],[2,1.53,94.34]],"ltp":2.3,"tv":30.69,"id":169}]}]}
{"op":"mcm","clk":"11801882148","pt":1723080785838,"mc":[{"id":"1.231447835","rc":[{"batb":[[0,2.24,10],[1,2.22,36.4],[2,1.74,17.32]],"ltp":2.3,"tv":30.69,"id":169}]}]}
{"op":"mcm","clk":"11801882352","pt":1723080789245,"mc":[{"id":"1.231447835","rc":[{"batb":[[0,2.22,36.4],[1,1.74,17.32],[2,1.53,94.34]],"ltp":2.3,"tv":30.69,"id":169}]}]}
{"op":"mcm","clk":"11801882542","pt":1723080792021,"mc":[{"id":"1.231447835","rc":[{"batb":[[0,2.24,10],[1,2.22,36.4],[2,1.74,17.32]],"ltp":2.3,"tv":30.69,"id":169}]}]}
{"op":"mcm","clk":"11801882663","pt":1723080795249,"mc":[{"id":"1.231447835","rc":[{"batb":[[0,2.22,36.4],[1,1.74,17.32],[2,1.53,94.34]],"ltp":2.3,"tv":30.69,"id":169}]}]}
{"op":"mcm","clk":"11801882815","pt":1723080799147,"mc":[{"id":"1.231447835","rc":[{"batb":[[0,2.24,10],[1,2.22,36.4],[2,1.74,17.32]],"ltp":2.3,"tv":30.69,"id":169}]}]}
{"op":"mcm","clk":"11801882972","pt":1723080802435,"mc":[{"id":"1.231447835","rc":[{"batb":[[0,2.22,36.4],[1,1.74,17.32],[2,1.53,94.34]],"ltp":2.3,"tv":30.69,"id":169}]}]}
{"op":"mcm","clk":"11801883073","pt":1723080805047,"mc":[{"id":"1.231447835","rc":[{"batb":[[0,2.24,10],[1,2.22,36.4],[2,1.74,17.32]],"ltp":2.3,"tv":30.69,"id":169}]}]}
{"op":"mcm","clk":"11801883252","pt":1723080808648,"mc":[{"id":"1.231447835","rc":[{"batb":[[0,2.22,36.4],[1,1.74,17.32],[2,1.53,94.34]],"ltp":2.3,"tv":30.69,"id":169}]}]}
{"op":"mcm","clk":"11801883418","pt":1723080812547,"mc":[{"id":"1.231447835","rc":[{"batb":[[0,2.24,10],[1,2.22,36.4],[2,1.74,17.32]],"ltp":2.3,"tv":30.69,"id":169}]}]}
{"op":"mcm","clk":"11801883699","pt":1723080816347,"mc":[{"id":"1.231447835","rc":[{"batb":[[0,2.22,36.4],[1,1.74,17.32],[2,1.53,94.34]],"ltp":2.3,"tv":30.69,"id":169}]}]}
{"op":"mcm","clk":"11801883877","pt":1723080818858,"mc":[{"id":"1.231447835","rc":[{"batb":[[0,2.24,10],[1,2.22,36.4],[2,1.74,17.32]],"ltp":2.3,"tv":30.69,"id":169}]}]}
{"op":"mcm","clk":"11801884179","pt":1723080822498,"mc":[{"id":"1.231447835","rc":[{"batb":[[0,2.22,36.4],[1,1.74,17.32],[2,1.53,94.34]],"ltp":2.3,"tv":30.69,"id":169}]}]}
{"op":"mcm","clk":"11801884470","pt":1723080826966,"mc":[{"id":"1.231447835","rc":[{"batb":[[0,2.24,10],[1,2.22,36.4],[2,1.74,17.32]],"ltp":2.3,"tv":30.69,"id":169}]}]}
{"op":"mcm","clk":"11801884645","pt":1723080830695,"mc":[{"id":"1.231447835","rc":[{"batb":[[0,2.22,36.4],[1,1.74,17.32],[2,1.53,94.34]],"ltp":2.3,"tv":30.69,"id":169}]}]}
{"op":"mcm","clk":"11801884785","pt":1723080833063,"mc":[{"id":"1.231447835","rc":[{"batb":[[0,2.24,10],[1,2.22,36.4],[2,1.74,17.32]],"ltp":2.3,"tv":30.69,"id":169}]}]}
{"op":"mcm","clk":"11801884924","pt":1723080836502,"mc":[{"id":"1.231447835","rc":[{"batb":[[0,2.22,36.4],[1,1.74,17.32],[2,1.53,94.34]],"ltp":2.3,"tv":30.69,"id":169}]}]}
{"op":"mcm","clk":"11801885057","pt":1723080839475,"mc":[{"id":"1.231447835","rc":[{"batb":[[0,2.24,10],[1,2.22,36.4],[2,1.74,17.32]],"ltp":2.3,"tv":30.69,"id":169}]}]}
{"op":"mcm","clk":"11801885234","pt":1723080843013,"mc":[{"id":"1.231447835","rc":[{"batb":[[0,2.22,36.4],[1,1.74,17.32],[2,1.53,94.34]],"ltp":2.3,"tv":30.69,"id":169}]}]}
{"op":"mcm","clk":"11801885355","pt":1723080846089,"mc":[{"id":"1.231447835","rc":[{"batb":[[0,2.24,10],[1,2.22,36.4],[2,1.74,17.32]],"ltp":2.3,"tv":30.69,"id":169}]}]}
{"op":"mcm","clk":"11801885535","pt":1723080849676,"mc":[{"id":"1.231447835","rc":[{"batb":[[0,2.22,36.4],[1,1.74,17.32],[2,1.53,94.34]],"ltp":2.3,"tv":30.69,"id":169}]}]}
{"op":"mcm","clk":"11801885749","pt":1723080852801,"mc":[{"id":"1.231447835","rc":[{"batb":[[0,2.24,10],[1,2.22,36.4],[2,1.74,17.32]],"ltp":2.3,"tv":30.69,"id":169}]}]}
{"op":"mcm","clk":"11801885905","pt":1723080856290,"mc":[{"id":"1.231447835","rc":[{"batb":[[0,2.22,36.4],[1,1.74,17.32],[2,1.53,94.34]],"ltp":2.3,"tv":30.69,"id":169}]}]}
{"op":"mcm","clk":"11801886068","pt":1723080860138,"mc":[{"id":"1.231447835","rc":[{"batb":[[0,2.24,10],[1,2.22,36.4],[2,1.74,17.32]],"ltp":2.3,"tv":30.69,"id":169}]}]}
{"op":"mcm","clk":"11801886272","pt":1723080863626,"mc":[{"id":"1.231447835","rc":[{"batb":[[0,2.22,36.4],[1,1.74,17.32],[2,1.53,94.34]],"ltp":2.3,"tv":30.69,"id":169}]}]}
{"op":"mcm","clk":"11801886397","pt":1723080866305,"mc":[{"id":"1.231447835","rc":[{"batb":[[0,2.24,10],[1,2.22,36.4],[2,1.74,17.32]],"ltp":2.3,"tv":30.69,"id":169}]}]}
{"op":"mcm","clk":"11801886551","pt":1723080870144,"mc":[{"id":"1.231447835","rc":[{"batb":[[0,2.22,36.4],[1,1.74,17.32],[2,1.53,94.34]],"ltp":2.3,"tv":30.69,"id":169}]}]}
{"op":"mcm","clk":"11801886830","pt":1723080876445,"mc":[{"id":"1.231447835","rc":[{"batb":[[0,2.24,10],[1,2.22,36.4],[2,1.74,17.32]],"ltp":2.3,"tv":30.69,"id":169}]}]}
{"op":"mcm","clk":"11801886978","pt":1723080879839,"mc":[{"id":"1.231447835","rc":[{"batb":[[0,2.22,36.4],[1,1.74,17.32],[2,1.53,94.34]],"ltp":2.3,"tv":30.69,"id":169}]}]}
{"op":"mcm","clk":"11801887092","pt":1723080882719,"mc":[{"id":"1.231447835","rc":[{"batb":[[0,2.24,10],[1,2.22,36.4],[2,1.74,17.32]],"ltp":2.3,"tv":30.69,"id":169}]}]}
{"op":"mcm","clk":"11801887241","pt":1723080886253,"mc":[{"id":"1.231447835","rc":[{"batb":[[0,2.22,36.4],[1,1.74,17.32],[2,1.53,94.34]],"ltp":2.3,"tv":30.69,"id":169}]}]}
{"op":"mcm","clk":"11801887348","pt":1723080888665,"mc":[{"id":"1.231447835","rc":[{"batb":[[0,2.24,10],[1,2.22,36.4],[2,1.74,17.32]],"ltp":2.3,"tv":30.69,"id":169}]}]}
{"op":"mcm","clk":"11801887494","pt":1723080892050,"mc":[{"id":"1.231447835","rc":[{"batb":[[0,2.22,36.4],[1,1.74,17.32],[2,1.53,94.34]],"ltp":2.3,"tv":30.69,"id":169}]}]}
{"op":"mcm","clk":"11801887579","pt":1723080894322,"mc":[{"id":"1.231447835","rc":[{"batb":[[0,2.24,10],[1,2.22,36.4],[2,1.74,17.32]],"ltp":2.3,"tv":30.69,"id":169}]}]}
{"op":"mcm","clk":"11801887698","pt":1723080897751,"mc":[{"id":"1.231447835","rc":[{"batb":[[0,2.22,36.4],[1,1.74,17.32],[2,1.53,94.34]],"ltp":2.3,"tv":30.69,"id":169}]}]}
{"op":"mcm","clk":"11801887814","pt":1723080900464,"mc":[{"id":"1.231447835","rc":[{"batb":[[0,2.24,10],[1,2.22,36.4],[2,1.74,17.32]],"ltp":2.3,"tv":30.69,"id":169}]}]}
{"op":"mcm","clk":"11801887999","pt":1723080904075,"mc":[{"id":"1.231447835","rc":[{"batb":[[0,2.22,36.4],[1,1.74,17.32],[2,1.53,94.34]],"ltp":2.3,"tv":30.69,"id":169}]}]}
{"op":"mcm","clk":"11801888087","pt":1723080906485,"mc":[{"id":"1.231447835","rc":[{"batb":[[0,2.24,10],[1,2.22,36.4],[2,1.74,17.32]],"ltp":2.3,"tv":30.69,"id":169}]}]}
{"op":"mcm","clk":"11801888209","pt":1723080909766,"mc":[{"id":"1.231447835","rc":[{"batb":[[0,2.22,36.4],[1,1.74,17.32],[2,1.53,94.34]],"ltp":2.3,"tv":30.69,"id":169}]}]}
{"op":"mcm","clk":"11801888320","pt":1723080912791,"mc":[{"id":"1.231447835","rc":[{"batb":[[0,2.24,10],[1,2.22,36.4],[2,1.74,17.32]],"ltp":2.3,"tv":30.69,"id":169}]}]}
{"op":"mcm","clk":"11801888454","pt":1723080916177,"mc":[{"id":"1.231447835","rc":[{"batb":[[0,2.22,36.4],[1,1.74,17.32],[2,1.53,94.34]],"ltp":2.3,"tv":30.69,"id":169}]}]}
{"op":"mcm","clk":"11801888565","pt":1723080919000,"mc":[{"id":"1.231447835","rc":[{"batb":[[0,2.24,10],[1,2.22,36.4],[2,1.74,17.32]],"ltp":2.3,"tv":30.69,"id":169}]}]}
{"op":"mcm","clk":"11801888669","pt":1723080922588,"mc":[{"id":"1.231447835","rc":[{"batb":[[0,2.22,36.4],[1,1.74,17.32],[2,1.53,94.34]],"ltp":2.3,"tv":30.69,"id":169}]}]}
{"op":"mcm","clk":"11801888756","pt":1723080924999,"mc":[{"id":"1.231447835","rc":[{"batb":[[0,2.24,10],[1,2.22,36.4],[2,1.74,17.32]],"ltp":2.3,"tv":30.69,"id":169}]}]}
{"op":"mcm","clk":"11801888873","pt":1723080928479,"mc":[{"id":"1.231447835","rc":[{"batb":[[0,2.22,36.4],[1,1.74,17.32],[2,1.53,94.34]],"ltp":2.3,"tv":30.69,"id":169}]}]}
{"op":"mcm","clk":"11801888994","pt":1723080931768,"mc":[{"id":"1.231447835","rc":[{"batb":[[0,2.24,10],[1,2.22,36.4],[2,1.74,17.32]],"ltp":2.3,"tv":30.69,"id":169}]}]}
{"op":"mcm","clk":"11801889131","pt":1723080935303,"mc":[{"id":"1.231447835","rc":[{"batb":[[0,2.22,36.4],[1,1.74,17.32],[2,1.53,94.34]],"ltp":2.3,"tv":30.69,"id":169}]}]}
{"op":"mcm","clk":"11801889315","pt":1723080939515,"mc":[{"id":"1.231447835","rc":[{"batb":[[0,2.24,10],[1,2.22,36.4],[2,1.74,17.32]],"ltp":2.3,"tv":30.69,"id":169}]}]}
{"op":"mcm","clk":"11801889444","pt":1723080943103,"mc":[{"id":"1.231447835","rc":[{"batb":[[0,2.22,36.4],[1,1.74,17.32],[2,1.53,94.34]],"ltp":2.3,"tv":30.69,"id":169}]}]}
{"op":"mcm","clk":"11801889517","pt":1723080945826,"mc":[{"id":"1.231447835","rc":[{"batb":[[0,2.24,10],[1,2.22,36.4],[2,1.74,17.32]],"ltp":2.3,"tv":30.69,"id":169}]}]}
{"op":"mcm","clk":"11801889622","pt":1723080949521,"mc":[{"id":"1.231447835","rc":[{"batb":[[0,2.22,36.4],[1,1.74,17.32],[2,1.53,94.34]],"ltp":2.3,"tv":30.69,"id":169}]}]}
{"op":"mcm","clk":"11801889690","pt":1723080951883,"mc":[{"id":"1.231447835","rc":[{"batb":[[0,2.24,10],[1,2.22,36.4],[2,1.74,17.32]],"ltp":2.3,"tv":30.69,"id":169}]}]}
{"op":"mcm","clk":"11801889817","pt":1723080955228,"mc":[{"id":"1.231447835","rc":[{"batb":[[0,2.22,36.4],[1,1.74,17.32],[2,1.53,94.34]],"ltp":2.3,"tv":30.69,"id":169}]}]}
{"op":"mcm","clk":"11801889968","pt":1723080958933,"mc":[{"id":"1.231447835","rc":[{"batb":[[0,2.24,10],[1,2.22,36.4],[2,1.74,17.32]],"ltp":2.3,"tv":30.69,"id":169}]}]}
{"op":"mcm","clk":"11801890075","pt":1723080962323,"mc":[{"id":"1.231447835","rc":[{"batb":[[0,2.22,36.4],[1,1.74,17.32],[2,1.53,94.34]],"ltp":2.3,"tv":30.69,"id":169}]}]}
{"op":"mcm","clk":"11801890294","pt":1723080967613,"mc":[{"id":"1.231447835","rc":[{"batb":[[0,2.24,10],[1,2.22,36.4],[2,1.74,17.32]],"ltp":2.3,"tv":30.69,"id":169}]}]}
{"op":"mcm","clk":"11801890448","pt":1723080971042,"mc":[{"id":"1.231447835","rc":[{"batb":[[0,2.22,36.4],[1,1.74,17.32],[2,1.53,94.34]],"ltp":2.3,"tv":30.69,"id":169}]}]}
{"op":"mcm","clk":"11801890550","pt":1723080973453,"mc":[{"id":"1.231447835","rc":[{"batb":[[0,2.24,10],[1,2.22,36.4],[2,1.74,17.32]],"ltp":2.3,"tv":30.69,"id":169}]}]}
{"op":"mcm","clk":"11801890670","pt":1723080976947,"mc":[{"id":"1.231447835","rc":[{"batb":[[0,2.22,36.4],[1,1.74,17.32],[2,1.53,94.34]],"ltp":2.3,"tv":30.69,"id":169}]}]}
{"op":"mcm","clk":"11801890741","pt":1723080979322,"mc":[{"id":"1.231447835","rc":[{"batb":[[0,2.24,10],[1,2.22,36.4],[2,1.74,17.32]],"ltp":2.3,"tv":30.69,"id":169}]}]}
{"op":"mcm","clk":"11801890880","pt":1723080982961,"mc":[{"id":"1.231447835","rc":[{"batb":[[0,2.22,36.4],[1,1.74,17.32],[2,1.53,94.34]],"ltp":2.3,"tv":30.69,"id":169}]}]}
{"op":"mcm","clk":"11801890995","pt":1723080985728,"mc":[{"id":"1.231447835","rc":[{"batb":[[0,2.24,10],[1,2.22,36.4],[2,1.74,17.32]],"ltp":2.3,"tv":30.69,"id":169}]}]}
{"op":"mcm","clk":"11801891095","pt":1723080989065,"mc":[{"id":"1.231447835","rc":[{"batb":[[0,2.22,36.4],[1,1.74,17.32],[2,1.53,94.34]],"ltp":2.3,"tv":30.69,"id":169}]}]}
{"op":"mcm","clk":"11801891172","pt":1723080991435,"mc":[{"id":"1.231447835","rc":[{"batb":[[0,2.24,10],[1,2.22,36.4],[2,1.74,17.32]],"ltp":2.3,"tv":30.69,"id":169}]}]}
{"op":"mcm","clk":"11801891288","pt":1723080994869,"mc":[{"id":"1.231447835","rc":[{"batb":[[0,2.22,36.4],[1,1.74,17.32],[2,1.53,94.34]],"ltp":2.3,"tv":30.69,"id":169}]}]}
{"op":"mcm","clk":"11801891375","pt":1723080997439,"mc":[{"id":"1.231447835","rc":[{"batb":[[0,2.24,10],[1,2.22,36.4],[2,1.74,17.32]],"ltp":2.3,"tv":30.69,"id":169}]}]}
{"op":"mcm","clk":"11801891493","pt":1723081000773,"mc":[{"id":"1.231447835","rc":[{"batb":[[0,2.22,36.4],[1,1.74,17.32],[2,1.53,94.34]],"ltp":2.3,"tv":30.69,"id":169}]}]}
{"op":"mcm","clk":"11801891610","pt":1723081003489,"mc":[{"id":"1.231447835","rc":[{"batb":[[0,2.24,10],[1,2.22,36.4],[2,1.74,17.32]],"ltp":2.3,"tv":30.69,"id":169}]}]}
{"op":"mcm","clk":"11801891733","pt":1723081006983,"mc":[{"id":"1.231447835","rc":[{"batb":[[0,2.22,36.4],[1,1.74,17.32],[2,1.53,94.34]],"ltp":2.3,"tv":30.69,"id":169}]}]}
{"op":"mcm","clk":"11801891813","pt":1723081009292,"mc":[{"id":"1.231447835","rc":[{"batb":[[0,2.24,10],[1,2.22,36.4],[2,1.74,17.32]],"ltp":2.3,"tv":30.69,"id":169}]}]}
{"op":"mcm","clk":"11801891932","pt":1723081012982,"mc":[{"id":"1.231447835","rc":[{"batb":[[0,2.22,36.4],[1,1.74,17.32],[2,1.53,94.34]],"ltp":2.3,"tv":30.69,"id":169}]}]}
{"op":"mcm","clk":"11801892028","pt":1723081016365,"mc":[{"id":"1.231447835","rc":[{"batb":[[0,2.24,10],[1,2.22,36.4],[2,1.74,17.32]],"ltp":2.3,"tv":30.69,"id":169}]}]}
{"op":"mcm","clk":"11801892110","pt":1723081019698,"mc":[{"id":"1.231447835","rc":[{"batb":[[0,2.22,36.4],[1,1.74,17.32],[2,1.53,94.34]],"ltp":2.3,"tv":30.69,"id":169}]}]}
{"op":"mcm","clk":"11801892181","pt":1723081022108,"mc":[{"id":"1.231447835","rc":[{"batb":[[0,2.24,10],[1,2.22,36.4],[2,1.74,17.32]],"ltp":2.3,"tv":30.69,"id":169}]}]}
{"op":"mcm","clk":"11801892307","pt":1723081025399,"mc":[{"id":"1.231447835","rc":[{"batb":[[0,2.22,36.4],[1,1.74,17.32],[2,1.53,94.34]],"ltp":2.3,"tv":30.69,"id":169}]}]}
{"op":"mcm","clk":"11801892397","pt":1723081027881,"mc":[{"id":"1.231447835","rc":[{"batb":[[0,2.24,10],[1,2.22,36.4],[2,1.74,17.32]],"ltp":2.3,"tv":30.69,"id":169}]}]}
{"op":"mcm","clk":"11801892603","pt":1723081031113,"mc":[{"id":"1.231447835","rc":[{"batb":[[0,2.22,36.4],[1,1.74,17.32],[2,1.53,94.34]],"ltp":2.3,"tv":30.69,"id":169}]}]}
{"op":"mcm","clk":"11801892713","pt":1723081033990,"mc":[{"id":"1.231447835","rc":[{"batb":[[0,2.24,10],[1,2.22,36.4],[2,1.74,17.32]],"ltp":2.3,"tv":30.69,"id":169}]}]}
{"op":"mcm","clk":"11801892843","pt":1723081037392,"mc":[{"id":"1.231447835","rc":[{"batb":[[0,2.22,36.4],[1,1.74,17.32],[2,1.53,94.34]],"ltp":2.3,"tv":30.69,"id":169}]}]}
{"op":"mcm","clk":"11801892910","pt":1723081039716,"mc":[{"id":"1.231447835","rc":[{"batb":[[0,2.24,10],[1,2.22,36.4],[2,1.74,17.32]],"ltp":2.3,"tv":30.69,"id":169}]}]}
{"op":"mcm","clk":"11801893038","pt":1723081043008,"mc":[{"id":"1.231447835","rc":[{"batb":[[0,2.22,36.4],[1,1.74,17.32],[2,1.53,94.34]],"ltp":2.3,"tv":30.69,"id":169}]}]}
{"op":"mcm","clk":"11801893150","pt":1723081045427,"mc":[{"id":"1.231447835","rc":[{"batb":[[0,2.24,10],[1,2.22,36.4],[2,1.74,17.32]],"ltp":2.3,"tv":30.69,"id":169}]}]}
{"op":"mcm","clk":"11801893302","pt":1723081048814,"mc":[{"id":"1.231447835","rc":[{"batb":[[0,2.22,36.4],[1,1.74,17.32],[2,1.53,94.34]],"ltp":2.3,"tv":30.69,"id":169}]}]}
{"op":"mcm","clk":"11801893415","pt":1723081051841,"mc":[{"id":"1.231447835","rc":[{"batb":[[0,2.24,10],[1,2.22,36.4],[2,1.74,17.32]],"ltp":2.3,"tv":30.69,"id":169}]}]}
{"op":"mcm","clk":"11801893528","pt":1723081055125,"mc":[{"id":"1.231447835","rc":[{"batb":[[0,2.22,36.4],[1,1.74,17.32],[2,1.53,94.34]],"ltp":2.3,"tv":30.69,"id":169}]}]}
{"op":"mcm","clk":"11801893620","pt":1723081057634,"mc":[{"id":"1.231447835","rc":[{"batb":[[0,2.24,10],[1,2.22,36.4],[2,1.74,17.32]],"ltp":2.3,"tv":30.69,"id":169}]}]}
{"op":"mcm","clk":"11801893779","pt":1723081061026,"mc":[{"id":"1.231447835","rc":[{"batb":[[0,2.22,36.4],[1,1.74,17.32],[2,1.53,94.34]],"ltp":2.3,"tv":30.69,"id":169}]}]}
{"op":"mcm","clk":"11801893866","pt":1723081063946,"mc":[{"id":"1.231447835","rc":[{"batb":[[0,2.24,10],[1,2.22,36.4],[2,1.74,17.32]],"ltp":2.3,"tv":30.69,"id":169}]}]}
{"op":"mcm","clk":"11801894030","pt":1723081067261,"mc":[{"id":"1.231447835","rc":[{"batb":[[0,2.22,36.4],[1,1.74,17.32],[2,1.53,94.34]],"ltp":2.3,"tv":30.69,"id":169}]}]}
{"op":"mcm","clk":"11801894203","pt":1723081071629,"mc":[{"id":"1.231447835","rc":[{"batb":[[0,2.24,10],[1,2.22,36.4],[2,1.74,17.32]],"ltp":2.3,"tv":30.69,"id":169}]}]}
{"op":"mcm","clk":"11801894344","pt":1723081075135,"mc":[{"id":"1.231447835","rc":[{"batb":[[0,2.22,36.4],[1,1.74,17.32],[2,1.53,94.34]],"ltp":2.3,"tv":30.69,"id":169}]}]}
{"op":"mcm","clk":"11801894457","pt":1723081077652,"mc":[{"id":"1.231447835","rc":[{"batb":[[0,2.24,10],[1,2.22,36.4],[2,1.74,17.32]],"ltp":2.3,"tv":30.69,"id":169}]}]}
{"op":"mcm","clk":"11801894606","pt":1723081081181,"mc":[{"id":"1.231447835","rc":[{"batb":[[0,2.22,36.4],[1,1.74,17.32],[2,1.53,94.34]],"ltp":2.3,"tv":30.69,"id":169}]}]}
{"op":"mcm","clk":"11801894696","pt":1723081083645,"mc":[{"id":"1.231447835","rc":[{"batb":[[0,2.24,10],[1,2.22,36.4],[2,1.74,17.32]],"ltp":2.3,"tv":30.69,"id":169}]}]}
{"op":"mcm","clk":"11801894813","pt":1723081086884,"mc":[{"id":"1.231447835","rc":[{"batb":[[0,2.22,36.4],[1,1.74,17.32],[2,1.53,94.34]],"ltp":2.3,"tv":30.69,"id":169}]}]}
{"op":"mcm","clk":"11801894919","pt":1723081089396,"mc":[{"id":"1.231447835","rc":[{"batb":[[0,2.24,10],[1,2.22,36.4],[2,1.74,17.32]],"ltp":2.3,"tv":30.69,"id":169}]}]}
{"op":"mcm","clk":"11801895052","pt":1723081092887,"mc":[{"id":"1.231447835","rc":[{"batb":[[0,2.22,36.4],[1,1.74,17.32],[2,1.53,94.34]],"ltp":2.3,"tv":30.69,"id":169}]}]}
{"op":"mcm","clk":"11801895124","pt":1723081095092,"mc":[{"id":"1.231447835","rc":[{"batb":[[0,2.24,10],[1,2.22,36.4],[2,1.74,17.32]],"ltp":2.3,"tv":30.69,"id":169}]}]}
{"op":"mcm","clk":"11801895263","pt":1723081098379,"mc":[{"id":"1.231447835","rc":[{"batb":[[0,2.22,36.4],[1,1.74,17.32],[2,1.53,94.34]],"ltp":2.3,"tv":30.69,"id":169}]}]}
{"op":"mcm","clk":"11801895372","pt":1723081101198,"mc":[{"id":"1.231447835","rc":[{"batb":[[0,2.24,10],[1,2.22,36.4],[2,1.74,17.32]],"ltp":2.3,"tv":30.69,"id":169}]}]}
{"op":"mcm","clk":"11801895486","pt":1723081104791,"mc":[{"id":"1.231447835","rc":[{"batb":[[0,2.22,36.4],[1,1.74,17.32],[2,1.53,94.34]],"ltp":2.3,"tv":30.69,"id":169}]}]}
{"op":"mcm","clk":"11801895614","pt":1723081108076,"mc":[{"id":"1.231447835","rc":[{"batb":[[0,2.24,10],[1,2.22,36.4],[2,1.74,17.32]],"ltp":2.3,"tv":30.69,"id":169}]}]}
{"op":"mcm","clk":"11801895756","pt":1723081111413,"mc":[{"id":"1.231447835","rc":[{"batb":[[0,2.22,36.4],[1,1.74,17.32],[2,1.53,94.34]],"ltp":2.3,"tv":30.69,"id":169}]}]}
{"op":"mcm","clk":"11801895844","pt":1723081113689,"mc":[{"id":"1.231447835","rc":[{"batb":[[0,2.24,10],[1,2.22,36.4],[2,1.74,17.32]],"ltp":2.3,"tv":30.69,"id":169}]}]}
{"op":"mcm","clk":"11801895997","pt":1723081117189,"mc":[{"id":"1.231447835","rc":[{"batb":[[0,2.22,36.4],[1,1.74,17.32],[2,1.53,94.34]],"ltp":2.3,"tv":30.69,"id":169}]}]}
{"op":"mcm","clk":"11801896143","pt":1723081120834,"mc":[{"id":"1.231447835","rc":[{"batb":[[0,2.24,10],[1,2.22,36.4],[2,1.74,17.32]],"ltp":2.3,"tv":30.69,"id":169}]}]}
{"op":"mcm","clk":"11801896272","pt":1723081124221,"mc":[{"id":"1.231447835","rc":[{"batb":[[0,2.22,36.4],[1,1.74,17.32],[2,1.53,94.34]],"ltp":2.3,"tv":30.69,"id":169}]}]}
{"op":"mcm","clk":"11801896365","pt":1723081127099,"mc":[{"id":"1.231447835","rc":[{"batb":[[0,2.24,10],[1,2.22,36.4],[2,1.74,17.32]],"ltp":2.3,"tv":30.69,"id":169}]}]}
{"op":"mcm","clk":"11801896519","pt":1723081130645,"mc":[{"id":"1.231447835","rc":[{"batb":[[0,2.22,36.4],[1,1.74,17.32],[2,1.53,94.34]],"ltp":2.3,"tv":30.69,"id":169}]}]}
{"op":"mcm","clk":"11801896615","pt":1723081133213,"mc":[{"id":"1.231447835","rc":[{"batb":[[0,2.24,10],[1,2.22,36.4],[2,1.74,17.32]],"ltp":2.3,"tv":30.69,"id":169}]}]}
{"op":"mcm","clk":"11801896780","pt":1723081136851,"mc":[{"id":"1.231447835","rc":[{"batb":[[0,2.22,36.4],[1,1.74,17.32],[2,1.53,94.34]],"ltp":2.3,"tv":30.69,"id":169}]}]}
{"op":"mcm","clk":"11801896890","pt":1723081139524,"mc":[{"id":"1.231447835","rc":[{"batb":[[0,2.24,10],[1,2.22,36.4],[2,1.74,17.32]],"ltp":2.3,"tv":30.69,"id":169}]}]}
{"op":"mcm","clk":"11801897003","pt":1723081142931,"mc":[{"id":"1.231447835","rc":[{"batb":[[0,2.22,36.4],[1,1.74,17.32],[2,1.53,94.34]],"ltp":2.3,"tv":30.69,"id":169}]}]}
{"op":"mcm","clk":"11801897075","pt":1723081145347,"mc":[{"id":"1.231447835","rc":[{"batb":[[0,2.24,10],[1,2.22,36.4],[2,1.74,17.32]],"ltp":2.3,"tv":30.69,"id":169}]}]}
{"op":"mcm","clk":"11801897201","pt":1723081148951,"mc":[{"id":"1.231447835","rc":[{"batb":[[0,2.22,36.4],[1,1.74,17.32],[2,1.53,94.34]],"ltp":2.3,"tv":30.69,"id":169}]}]}
{"op":"mcm","clk":"11801897444","pt":1723081154760,"mc":[{"id":"1.231447835","rc":[{"batb":[[0,2.24,10],[1,2.22,36.4],[2,1.74,17.32]],"ltp":2.3,"tv":30.69,"id":169}]}]}
{"op":"mcm","clk":"11801897604","pt":1723081158156,"mc":[{"id":"1.231447835","rc":[{"batb":[[0,2.22,36.4],[1,1.74,17.32],[2,1.53,94.34]],"ltp":2.3,"tv":30.69,"id":169}]}]}
{"op":"mcm","clk":"11801897691","pt":1723081160526,"mc":[{"id":"1.231447835","rc":[{"batb":[[0,2.24,10],[1,2.22,36.4],[2,1.74,17.32]],"ltp":2.3,"tv":30.69,"id":169}]}]}
{"op":"mcm","clk":"11801897810","pt":1723081164029,"mc":[{"id":"1.231447835","rc":[{"batb":[[0,2.22,36.4],[1,1.74,17.32],[2,1.53,94.34]],"ltp":2.3,"tv":30.69,"id":169}]}]}
{"op":"mcm","clk":"11801897904","pt":1723081167068,"mc":[{"id":"1.231447835","rc":[{"batb":[[0,2.24,10],[1,2.22,36.4],[2,1.74,17.32]],"ltp":2.3,"tv":30.69,"id":169}]}]}
{"op":"mcm","clk":"11801898014","pt":1723081170356,"mc":[{"id":"1.231447835","rc":[{"batb":[[0,2.22,36.4],[1,1.74,17.32],[2,1.53,94.34]],"ltp":2.3,"tv":30.69,"id":169}]}]}
{"op":"mcm","clk":"11801898078","pt":1723081172992,"mc":[{"id":"1.231447835","rc":[{"batb":[[0,2.24,10],[1,2.22,36.4],[2,1.74,17.32]],"ltp":2.3,"tv":30.69,"id":169}]}]}
{"op":"mcm","clk":"11801898196","pt":1723081176467,"mc":[{"id":"1.231447835","rc":[{"batb":[[0,2.22,36.4],[1,1.74,17.32],[2,1.53,94.34]],"ltp":2.3,"tv":30.69,"id":169}]}]}
{"op":"mcm","clk":"11801898280","pt":1723081178669,"mc":[{"id":"1.231447835","rc":[{"batb":[[0,2.24,10],[1,2.22,36.4],[2,1.74,17.32]],"ltp":2.3,"tv":30.69,"id":169}]}]}
{"op":"mcm","clk":"11801898397","pt":1723081181953,"mc":[{"id":"1.231447835","rc":[{"batb":[[0,2.22,36.4],[1,1.74,17.32],[2,1.53,94.34]],"ltp":2.3,"tv":30.69,"id":169}]}]}
{"op":"mcm","clk":"11801898484","pt":1723081185290,"mc":[{"id":"1.231447835","rc":[{"batb":[[0,2.24,10],[1,2.22,36.4],[2,1.74,17.32]],"ltp":2.3,"tv":30.69,"id":169}]}]}
{"op":"mcm","clk":"11801898569","pt":1723081188774,"mc":[{"id":"1.231447835","rc":[{"batb":[[0,2.22,36.4],[1,1.74,17.32],[2,1.53,94.34]],"ltp":2.3,"tv":30.69,"id":169}]}]}
{"op":"mcm","clk":"11801898622","pt":1723081191792,"mc":[{"id":"1.231447835","rc":[{"batb":[[0,2.24,10],[1,2.22,36.4],[2,1.74,17.32]],"ltp":2.3,"tv":30.69,"id":169}]}]}
{"op":"mcm","clk":"11801898695","pt":1723081195179,"mc":[{"id":"1.231447835","rc":[{"batb":[[0,2.22,36.4],[1,1.74,17.32],[2,1.53,94.34]],"ltp":2.3,"tv":30.69,"id":169}]}]}
{"op":"mcm","clk":"11801898796","pt":1723081198686,"mc":[{"id":"1.231447835","rc":[{"batb":[[0,2.24,10],[1,2.22,36.4],[2,1.74,17.32]],"ltp":2.3,"tv":30.69,"id":169}]}]}
{"op":"mcm","clk":"11801898875","pt":1723081201975,"mc":[{"id":"1.231447835","rc":[{"batb":[[0,2.22,36.4],[1,1.74,17.32],[2,1.53,94.34]],"ltp":2.3,"tv":30.69,"id":169}]}]}
{"op":"mcm","clk":"11801898972","pt":1723081204999,"mc":[{"id":"1.231447835","rc":[{"batb":[[0,2.24,10],[1,2.22,36.4],[2,1.74,17.32]],"ltp":2.3,"tv":30.69,"id":169}]}]}
{"op":"mcm","clk":"11801899090","pt":1723081208885,"mc":[{"id":"1.231447835","rc":[{"batb":[[0,2.22,36.4],[1,1.74,17.32],[2,1.53,94.34]],"ltp":2.3,"tv":30.69,"id":169}]}]}
{"op":"mcm","clk":"11801899173","pt":1723081211197,"mc":[{"id":"1.231447835","rc":[{"batb":[[0,2.24,10],[1,2.22,36.4],[2,1.74,17.32]],"ltp":2.3,"tv":30.69,"id":169}]}]}
{"op":"mcm","clk":"11801899269","pt":1723081214482,"mc":[{"id":"1.231447835","rc":[{"batb":[[0,2.22,36.4],[1,1.74,17.32],[2,1.53,94.34]],"ltp":2.3,"tv":30.69,"id":169}]}]}
{"op":"mcm","clk":"11801899342","pt":1723081217602,"mc":[{"id":"1.231447835","rc":[{"batb":[[0,2.24,10],[1,2.22,36.4],[2,1.74,17.32]],"ltp":2.3,"tv":30.69,"id":169}]}]}
{"op":"mcm","clk":"11801899437","pt":1723081220936,"mc":[{"id":"1.231447835","rc":[{"batb":[[0,2.22,36.4],[1,1.74,17.32],[2,1.53,94.34]],"ltp":2.3,"tv":30.69,"id":169}]}]}
{"op":"mcm","clk":"11801899561","pt":1723081223510,"mc":[{"id":"1.231447835","rc":[{"batb":[[0,2.24,10],[1,2.22,36.4],[2,1.74,17.32]],"ltp":2.3,"tv":30.69,"id":169}]}]}
{"op":"mcm","clk":"11801899674","pt":1723081227004,"mc":[{"id":"1.231447835","rc":[{"batb":[[0,2.22,36.4],[1,1.74,17.32],[2,1.53,94.34]],"ltp":2.3,"tv":30.69,"id":169}]}]}
{"op":"mcm","clk":"11801899802","pt":1723081230614,"mc":[{"id":"1.231447835","rc":[{"batb":[[0,2.24,10],[1,2.22,36.4],[2,1.74,17.32]],"ltp":2.3,"tv":30.69,"id":169}]}]}
{"op":"mcm","clk":"11801899933","pt":1723081234014,"mc":[{"id":"1.231447835","rc":[{"batb":[[0,2.22,36.4],[1,1.74,17.32],[2,1.53,94.34]],"ltp":2.3,"tv":30.69,"id":169}]}]}
{"op":"mcm","clk":"11801900031","pt":1723081237050,"mc":[{"id":"1.231447835","rc":[{"batb":[[0,2.24,10],[1,2.22,36.4],[2,1.74,17.32]],"ltp":2.3,"tv":30.69,"id":169}]}]}
{"op":"mcm","clk":"11801900178","pt":1723081240654,"mc":[{"id":"1.231447835","rc":[{"batb":[[0,2.22,36.4],[1,1.74,17.32],[2,1.53,94.34]],"ltp":2.3,"tv":30.69,"id":169}]}]}
{"op":"mcm","clk":"11801900286","pt":1723081242937,"mc":[{"id":"1.231447835","rc":[{"batb":[[0,2.24,10],[1,2.22,36.4],[2,1.74,17.32]],"ltp":2.3,"tv":30.69,"id":169}]}]}
{"op":"mcm","clk":"11801900410","pt":1723081246640,"mc":[{"id":"1.231447835","rc":[{"batb":[[0,2.22,36.4],[1,1.74,17.32],[2,1.53,94.34]],"ltp":2.3,"tv":30.69,"id":169}]}]}
{"op":"mcm","clk":"11801900505","pt":1723081249261,"mc":[{"id":"1.231447835","rc":[{"batb":[[0,2.24,10],[1,2.22,36.4],[2,1.74,17.32]],"ltp":2.3,"tv":30.69,"id":169}]}]}
{"op":"mcm","clk":"11801900627","pt":1723081252755,"mc":[{"id":"1.231447835","rc":[{"batb":[[0,2.22,36.4],[1,1.74,17.32],[2,1.53,94.34]],"ltp":2.3,"tv":30.69,"id":169}]}]}
{"op":"mcm","clk":"11801900720","pt":1723081255324,"mc":[{"id":"1.231447835","rc":[{"batb":[[0,2.24,10],[1,2.22,36.4],[2,1.74,17.32]],"ltp":2.3,"tv":30.69,"id":169}]}]}
{"op":"mcm","clk":"11801900841","pt":1723081258661,"mc":[{"id":"1.231447835","rc":[{"batb":[[0,2.22,36.4],[1,1.74,17.32],[2,1.53,94.34]],"ltp":2.3,"tv":30.69,"id":169}]}]}
{"op":"mcm","clk":"11801900940","pt":1723081261132,"mc":[{"id":"1.231447835","rc":[{"batb":[[0,2.24,10],[1,2.22,36.4],[2,1.74,17.32]],"ltp":2.3,"tv":30.69,"id":169}]}]}
{"op":"mcm","clk":"11801901073","pt":1723081264574,"mc":[{"id":"1.231447835","rc":[{"batb":[[0,2.22,36.4],[1,1.74,17.32],[2,1.53,94.34]],"ltp":2.3,"tv":30.69,"id":169}]}]}
{"op":"mcm","clk":"11801901194","pt":1723081267661,"mc":[{"id":"1.231447835","rc":[{"batb":[[0,2.24,10],[1,2.22,36.4],[2,1.74,17.32]],"ltp":2.3,"tv":30.69,"id":169}]}]}
{"op":"mcm","clk":"11801901291","pt":1723081270851,"mc":[{"id":"1.231447835","rc":[{"batb":[[0,2.22,36.4],[1,1.74,17.32],[2,1.53,94.34]],"ltp":2.3,"tv":30.69,"id":169}]}]}
{"op":"mcm","clk":"11801901453","pt":1723081275366,"mc":[{"id":"1.231447835","rc":[{"batb":[[0,2.24,10],[1,2.22,36.4],[2,1.74,17.32]],"ltp":2.3,"tv":30.69,"id":169}]}]}
{"op":"mcm","clk":"11801901561","pt":1723081278565,"mc":[{"id":"1.231447835","rc":[{"batb":[[0,2.22,36.4],[1,1.74,17.32],[2,1.53,94.34]],"ltp":2.3,"tv":30.69,"id":169}]}]}
{"op":"mcm","clk":"11801901681","pt":1723081282475,"mc":[{"id":"1.231447835","rc":[{"batb":[[0,2.24,10],[1,2.22,36.4],[2,1.74,17.32]],"ltp":2.3,"tv":30.69,"id":169}]}]}
{"op":"mcm","clk":"11801901802","pt":1723081286485,"mc":[{"id":"1.231447835","rc":[{"batb":[[0,2.22,36.4],[1,1.74,17.32],[2,1.53,94.34]],"ltp":2.3,"tv":30.69,"id":169}]}]}
{"op":"mcm","clk":"11801901885","pt":1723081289063,"mc":[{"id":"1.231447835","rc":[{"batb":[[0,2.24,10],[1,2.22,36.4],[2,1.74,17.32]],"ltp":2.3,"tv":30.69,"id":169}]}]}
{"op":"mcm","clk":"11801902007","pt":1723081293588,"mc":[{"id":"1.231447835","rc":[{"batb":[[0,2.22,36.4],[1,1.74,17.32],[2,1.53,94.34]],"ltp":2.3,"tv":30.69,"id":169}]}]}
{"op":"mcm","clk":"11801902105","pt":1723081295897,"mc":[{"id":"1.231447835","rc":[{"batb":[[0,2.24,10],[1,2.22,36.4],[2,1.74,17.32]],"ltp":2.3,"tv":30.69,"id":169}]}]}
{"op":"mcm","clk":"11801902206","pt":1723081299387,"mc":[{"id":"1.231447835","rc":[{"batb":[[0,2.22,36.4],[1,1.74,17.32],[2,1.53,94.34]],"ltp":2.3,"tv":30.69,"id":169}]}]}
{"op":"mcm","clk":"11801902311","pt":1723081302280,"mc":[{"id":"1.231447835","rc":[{"batb":[[0,2.24,10],[1,2.22,36.4],[2,1.74,17.32]],"ltp":2.3,"tv":30.69,"id":169}]}]}
{"op":"mcm","clk":"11801902415","pt":1723081305875,"mc":[{"id":"1.231447835","rc":[{"batb":[[0,2.22,36.4],[1,1.74,17.32],[2,1.53,94.34]],"ltp":2.3,"tv":30.69,"id":169}]}]}
{"op":"mcm","clk":"11801902503","pt":1723081309313,"mc":[{"id":"1.231447835","rc":[{"batb":[[0,2.24,10],[1,2.22,36.4],[2,1.74,17.32]],"ltp":2.3,"tv":30.69,"id":169}]}]}
{"op":"mcm","clk":"11801902600","pt":1723081312703,"mc":[{"id":"1.231447835","rc":[{"batb":[[0,2.22,36.4],[1,1.74,17.32],[2,1.53,94.34]],"ltp":2.3,"tv":30.69,"id":169}]}]}
{"op":"mcm","clk":"11801902679","pt":1723081315222,"mc":[{"id":"1.231447835","rc":[{"batb":[[0,2.24,10],[1,2.22,36.4],[2,1.74,17.32]],"ltp":2.3,"tv":30.69,"id":169}]}]}
{"op":"mcm","clk":"11801902761","pt":1723081318502,"mc":[{"id":"1.231447835","rc":[{"batb":[[0,2.22,36.4],[1,1.74,17.32],[2,1.53,94.34]],"ltp":2.3,"tv":30.69,"id":169}]}]}
{"op":"mcm","clk":"11801902857","pt":1723081321226,"mc":[{"id":"1.231447835","rc":[{"batb":[[0,2.24,10],[1,2.22,36.4],[2,1.74,17.32]],"ltp":2.3,"tv":30.69,"id":169}]}]}
{"op":"mcm","clk":"11801902961","pt":1723081324625,"mc":[{"id":"1.231447835","rc":[{"batb":[[0,2.22,36.4],[1,1.74,17.32],[2,1.53,94.34]],"ltp":2.3,"tv":30.69,"id":169}]}]}
{"op":"mcm","clk":"11801903059","pt":1723081327039,"mc":[{"id":"1.231447835","rc":[{"batb":[[0,2.24,10],[1,2.22,36.4],[2,1.74,17.32]],"ltp":2.3,"tv":30.69,"id":169}]}]}
{"op":"mcm","clk":"11801903198","pt":1723081330335,"mc":[{"id":"1.231447835","rc":[{"batb":[[0,2.22,36.4],[1,1.74,17.32],[2,1.53,94.34]],"ltp":2.3,"tv":30.69,"id":169}]}]}
{"op":"mcm","clk":"11801903293","pt":1723081333217,"mc":[{"id":"1.231447835","rc":[{"batb":[[0,2.24,10],[1,2.22,36.4],[2,1.74,17.32]],"ltp":2.3,"tv":30.69,"id":169}]}]}
{"op":"mcm","clk":"11801903420","pt":1723081336458,"mc":[{"id":"1.231447835","rc":[{"batb":[[0,2.22,36.4],[1,1.74,17.32],[2,1.53,94.34]],"ltp":2.3,"tv":30.69,"id":169}]}]}
{"op":"mcm","clk":"11801903532","pt":1723081339138,"mc":[{"id":"1.231447835","rc":[{"batb":[[0,2.24,10],[1,2.22,36.4],[2,1.74,17.32]],"ltp":2.3,"tv":30.69,"id":169}]}]}
{"op":"mcm","clk":"11801903663","pt":1723081342484,"mc":[{"id":"1.231447835","rc":[{"batb":[[0,2.22,36.4],[1,1.74,17.32],[2,1.53,94.34]],"ltp":2.3,"tv":30.69,"id":169}]}]}
{"op":"mcm","clk":"11801903780","pt":1723081345150,"mc":[{"id":"1.231447835","rc":[{"batb":[[0,2.24,10],[1,2.22,36.4],[2,1.74,17.32]],"ltp":2.3,"tv":30.69,"id":169}]}]}
{"op":"mcm","clk":"11801903911","pt":1723081348392,"mc":[{"id":"1.231447835","rc":[{"batb":[[0,2.22,36.4],[1,1.74,17.32],[2,1.53,94.34]],"ltp":2.3,"tv":30.69,"id":169}]}]}
{"op":"mcm","clk":"11801904059","pt":1723081351384,"mc":[{"id":"1.231447835","rc":[{"batb":[[0,2.24,10],[1,2.22,36.4],[2,1.74,17.32]],"ltp":2.3,"tv":30.69,"id":169}]}]}
{"op":"mcm","clk":"11801904174","pt":1723081354759,"mc":[{"id":"1.231447835","rc":[{"batb":[[0,2.22,36.4],[1,1.74,17.32],[2,1.53,94.34]],"ltp":2.3,"tv":30.69,"id":169}]}]}
{"op":"mcm","clk":"11801904256","pt":1723081357376,"mc":[{"id":"1.231447835","rc":[{"batb":[[0,2.24,10],[1,2.22,36.4],[2,1.74,17.32]],"ltp":2.3,"tv":30.69,"id":169}]}]}
{"op":"mcm","clk":"11801904372","pt":1723081360976,"mc":[{"id":"1.231447835","rc":[{"batb":[[0,2.22,36.4],[1,1.74,17.32],[2,1.53,94.34]],"ltp":2.3,"tv":30.69,"id":169}]}]}
{"op":"mcm","clk":"11801904512","pt":1723081365344,"mc":[{"id":"1.231447835","rc":[{"batb":[[0,2.24,10],[1,2.22,36.4],[2,1.74,17.32]],"ltp":2.3,"tv":30.69,"id":169}]}]}
{"op":"mcm","clk":"11801904643","pt":1723081369048,"mc":[{"id":"1.231447835","rc":[{"batb":[[0,2.22,36.4],[1,1.74,17.32],[2,1.53,94.34]],"ltp":2.3,"tv":30.69,"id":169}]}]}
{"op":"mcm","clk":"11801904742","pt":1723081371670,"mc":[{"id":"1.231447835","rc":[{"batb":[[0,2.24,10],[1,2.22,36.4],[2,1.74,17.32]],"ltp":2.3,"tv":30.69,"id":169}]}]}
{"op":"mcm","clk":"11801914576","pt":1723081375205,"mc":[{"id":"1.231447835","rc":[{"batb":[[0,2.22,36.4],[1,1.74,17.32],[2,1.53,94.34]],"ltp":2.3,"tv":30.69,"id":169}]}]}
{"op":"mcm","clk":"11801914699","pt":1723081378467,"mc":[{"id":"1.231447835","rc":[{"batb":[[0,2.24,10],[1,2.22,36.4],[2,1.74,17.32]],"ltp":2.3,"tv":30.69,"id":169}]}]}
{"op":"mcm","clk":"11801914801","pt":1723081381911,"mc":[{"id":"1.231447835","rc":[{"batb":[[0,2.22,36.4],[1,1.74,17.32],[2,1.53,94.34]],"ltp":2.3,"tv":30.69,"id":169}]}]}
{"op":"mcm","clk":"11801914893","pt":1723081384594,"mc":[{"id":"1.231447835","rc":[{"batb":[[0,2.24,10],[1,2.22,36.4],[2,1.74,17.32]],"ltp":2.3,"tv":30.69,"id":169}]}]}
{"op":"mcm","clk":"11801914989","pt":1723081387875,"mc":[{"id":"1.231447835","rc":[{"batb":[[0,2.22,36.4],[1,1.74,17.32],[2,1.53,94.34]],"ltp":2.3,"tv":30.69,"id":169}]}]}
{"op":"mcm","clk":"11801915100","pt":1723081390707,"mc":[{"id":"1.231447835","rc":[{"batb":[[0,2.24,10],[1,2.22,36.4],[2,1.74,17.32]],"ltp":2.3,"tv":30.69,"id":169}]}]}
{"op":"mcm","clk":"11801915209","pt":1723081394305,"mc":[{"id":"1.231447835","rc":[{"batb":[[0,2.22,36.4],[1,1.74,17.32],[2,1.53,94.34]],"ltp":2.3,"tv":30.69,"id":169}]}]}
{"op":"mcm","clk":"11801915268","pt":1723081396415,"mc":[{"id":"1.231447835","rc":[{"batb":[[0,2.24,10],[1,2.22,36.4],[2,1.74,17.32]],"ltp":2.3,"tv":30.69,"id":169}]}]}
{"op":"mcm","clk":"11801915379","pt":1723081399913,"mc":[{"id":"1.231447835","rc":[{"batb":[[0,2.22,36.4],[1,1.74,17.32],[2,1.53,94.34]],"ltp":2.3,"tv":30.69,"id":169}]}]}
{"op":"mcm","clk":"11801915444","pt":1723081402229,"mc":[{"id":"1.231447835","rc":[{"batb":[[0,2.24,10],[1,2.22,36.4],[2,1.74,17.32]],"ltp":2.3,"tv":30.69,"id":169}]}]}
{"op":"mcm","clk":"11801915551","pt":1723081405642,"mc":[{"id":"1.231447835","rc":[{"batb":[[0,2.22,36.4],[1,1.74,17.32],[2,1.53,94.34]],"ltp":2.3,"tv":30.69,"id":169}]}]}
{"op":"mcm","clk":"11801915641","pt":1723081408226,"mc":[{"id":"1.231447835","rc":[{"batb":[[0,2.24,10],[1,2.22,36.4],[2,1.74,17.32]],"ltp":2.3,"tv":30.69,"id":169}]}]}
{"op":"mcm","clk":"11801915766","pt":1723081411637,"mc":[{"id":"1.231447835","rc":[{"batb":[[0,2.22,36.4],[1,1.74,17.32],[2,1.53,94.34]],"ltp":2.3,"tv":30.69,"id":169}]}]}
{"op":"mcm","clk":"11801915909","pt":1723081415138,"mc":[{"id":"1.231447835","rc":[{"batb":[[0,2.24,10],[1,2.22,36.4],[2,1.74,17.32]],"ltp":2.3,"tv":30.69,"id":169}]}]}
{"op":"mcm","clk":"11801916006","pt":1723081418324,"mc":[{"id":"1.231447835","rc":[{"batb":[[0,2.22,36.4],[1,1.74,17.32],[2,1.53,94.34]],"ltp":2.3,"tv":30.69,"id":169}]}]}
{"op":"mcm","clk":"11801916170","pt":1723081423316,"mc":[{"id":"1.231447835","rc":[{"batb":[[0,2.24,10],[1,2.22,36.4],[2,1.74,17.32]],"ltp":2.3,"tv":30.69,"id":169}]}]}
{"op":"mcm","clk":"11801916303","pt":1723081426862,"mc":[{"id":"1.231447835","rc":[{"batb":[[0,2.22,36.4],[1,1.74,17.32],[2,1.53,94.34]],"ltp":2.3,"tv":30.69,"id":169}]}]}
{"op":"mcm","clk":"11801916398","pt":1723081429757,"mc":[{"id":"1.231447835","rc":[{"batb":[[0,2.24,10],[1,2.22,36.4],[2,1.74,17.32]],"ltp":2.3,"tv":30.69,"id":169}]}]}
{"op":"mcm","clk":"11801916529","pt":1723081433054,"mc":[{"id":"1.231447835","rc":[{"batb":[[0,2.22,36.4],[1,1.74,17.32],[2,1.53,94.34]],"ltp":2.3,"tv":30.69,"id":169}]}]}
{"op":"mcm","clk":"11801954500","pt":1723082402429,"mc":[{"id":"1.231447835","rc":[{"batb":[[0,2.24,10],[1,2.22,36.4],[2,1.74,17.32]],"ltp":2.3,"tv":30.69,"id":169}]}]}
{"op":"mcm","clk":"11801954727","pt":1723082406339,"mc":[{"id":"1.231447835","rc":[{"trd":[[2.3,22.95]],"batb":[[0,2.22,36.4],[1,1.74,17.32],[2,1.53,94.34]],"batl":[[1,2.34,11.29]],"ltp":2.3,"tv":30.69,"id":169},{"trd":[[1.76,11.82],[1.77,6.57]],"batb":[[0,1.76,3.91]],"batl":[[2,1.79,323.6]],"ltp":1.76,"tv":22.41,"id":2120}],"tv":53.1}]}
{"op":"mcm","clk":"11801954888","pt":1723082409134,"mc":[{"id":"1.231447835","rc":[{"batb":[[0,2.24,10],[1,2.22,36.4],[2,1.74,17.32]],"ltp":2.3,"tv":30.69,"id":169}]}]}
{"op":"mcm","clk":"11801955063","pt":1723082412427,"mc":[{"id":"1.231447835","rc":[{"batb":[[0,2.22,36.4],[1,1.74,17.32],[2,1.53,94.34]],"ltp":2.3,"tv":30.69,"id":169}]}]}
{"op":"mcm","clk":"11801955249","pt":1723082415932,"mc":[{"id":"1.231447835","rc":[{"batb":[[0,2.24,10],[1,2.22,36.4],[2,1.74,17.32]],"ltp":2.3,"tv":30.69,"id":169}]}]}
{"op":"mcm","clk":"11801955441","pt":1723082419909,"mc":[{"id":"1.231447835","rc":[{"batb":[[0,2.22,36.4],[1,1.74,17.32],[2,1.53,94.34]],"ltp":2.3,"tv":30.69,"id":169}]}]}
{"op":"mcm","clk":"11801955537","pt":1723082422126,"mc":[{"id":"1.231447835","rc":[{"batb":[[0,2.24,10],[1,2.22,36.4],[2,1.74,17.32]],"ltp":2.3,"tv":30.69,"id":169}]}]}
{"op":"mcm","clk":"11801955685","pt":1723082425529,"mc":[{"id":"1.231447835","rc":[{"batb":[[0,2.22,36.4],[1,1.74,17.32],[2,1.53,94.34]],"ltp":2.3,"tv":30.69,"id":169}]}]}
{"op":"mcm","clk":"11801955793","pt":1723082428235,"mc":[{"id":"1.231447835","rc":[{"batb":[[0,2.24,10],[1,2.22,36.4],[2,1.74,17.32]],"ltp":2.3,"tv":30.69,"id":169}]}]}
{"op":"mcm","clk":"11801955930","pt":1723082431743,"mc":[{"id":"1.231447835","rc":[{"batb":[[0,2.22,36.4],[1,1.74,17.32],[2,1.53,94.34]],"ltp":2.3,"tv":30.69,"id":169}]}]}
{"op":"mcm","clk":"11801956028","pt":1723082434051,"mc":[{"id":"1.231447835","rc":[{"batb":[[0,2.24,10],[1,2.22,36.4],[2,1.74,17.32]],"ltp":2.3,"tv":30.69,"id":169}]}]}
{"op":"mcm","clk":"11801956166","pt":1723082437545,"mc":[{"id":"1.231447835","rc":[{"batb":[[0,2.22,36.4],[1,1.74,17.32],[2,1.53,94.34]],"ltp":2.3,"tv":30.69,"id":169}]}]}
{"op":"mcm","clk":"11801956313","pt":1723082440639,"mc":[{"id":"1.231447835","rc":[{"batb":[[0,2.24,10],[1,2.22,36.4],[2,1.74,17.32]],"ltp":2.3,"tv":30.69,"id":169}]}]}
{"op":"mcm","clk":"11801956441","pt":1723082443973,"mc":[{"id":"1.231447835","rc":[{"batb":[[0,2.22,36.4],[1,1.74,17.32],[2,1.53,94.34]],"ltp":2.3,"tv":30.69,"id":169}]}]}
{"op":"mcm","clk":"11801956511","pt":1723082446180,"mc":[{"id":"1.231447835","rc":[{"batb":[[0,2.24,10],[1,2.22,36.4],[2,1.74,17.32]],"ltp":2.3,"tv":30.69,"id":169}]}]}
{"op":"mcm","clk":"11801956642","pt":1723082449566,"mc":[{"id":"1.231447835","rc":[{"batb":[[0,2.22,36.4],[1,1.74,17.32],[2,1.53,94.34]],"ltp":2.3,"tv":30.69,"id":169}]}]}
{"op":"mcm","clk":"11801956816","pt":1723082454388,"mc":[{"id":"1.231447835","rc":[{"batb":[[0,2.24,10],[1,2.22,36.4],[2,1.74,17.32]],"ltp":2.3,"tv":30.69,"id":169}]}]}
{"op":"mcm","clk":"11801956976","pt":1723082457992,"mc":[{"id":"1.231447835","rc":[{"batb":[[0,2.22,36.4],[1,1.74,17.32],[2,1.53,94.34]],"ltp":2.3,"tv":30.69,"id":169}]}]}
{"op":"mcm","clk":"11801957091","pt":1723082460205,"mc":[{"id":"1.231447835","rc":[{"batb":[[0,2.24,10],[1,2.22,36.4],[2,1.74,17.32]],"ltp":2.3,"tv":30.69,"id":169}]}]}
{"op":"mcm","clk":"11801957257","pt":1723082464102,"mc":[{"id":"1.231447835","rc":[{"batb":[[0,2.22,36.4],[1,1.74,17.32],[2,1.53,94.34]],"ltp":2.3,"tv":30.69,"id":169}]}]}
{"op":"mcm","clk":"11801957396","pt":1723082467584,"mc":[{"id":"1.231447835","rc":[{"batb":[[0,2.24,10],[1,2.22,36.4],[2,1.74,17.32]],"ltp":2.3,"tv":30.69,"id":169}]}]}
{"op":"mcm","clk":"11801957521","pt":1723082470978,"mc":[{"id":"1.231447835","rc":[{"batb":[[0,2.22,36.4],[1,1.74,17.32],[2,1.53,94.34]],"ltp":2.3,"tv":30.69,"id":169}]}]}
{"op":"mcm","clk":"11801957660","pt":1723082474386,"mc":[{"id":"1.231447835","rc":[{"batb":[[0,2.24,10],[1,2.22,36.4],[2,1.74,17.32]],"ltp":2.3,"tv":30.69,"id":169}]}]}
{"op":"mcm","clk":"11801957776","pt":1723082477778,"mc":[{"id":"1.231447835","rc":[{"batb":[[0,2.22,36.4],[1,1.74,17.32],[2,1.53,94.34]],"ltp":2.3,"tv":30.69,"id":169}]}]}
{"op":"mcm","clk":"11801957871","pt":1723082480196,"mc":[{"id":"1.231447835","rc":[{"batb":[[0,2.24,10],[1,2.22,36.4],[2,1.74,17.32]],"ltp":2.3,"tv":30.69,"id":169}]}]}
{"op":"mcm","clk":"11801958012","pt":1723082483499,"mc":[{"id":"1.231447835","rc":[{"batb":[[0,2.22,36.4],[1,1.74,17.32],[2,1.53,94.34]],"ltp":2.3,"tv":30.69,"id":169}]}]}
{"op":"mcm","clk":"11801958146","pt":1723082485917,"mc":[{"id":"1.231447835","rc":[{"batb":[[0,2.24,10],[1,2.22,36.4],[2,1.74,17.32]],"ltp":2.3,"tv":30.69,"id":169}]}]}
{"op":"mcm","clk":"11801958341","pt":1723082489319,"mc":[{"id":"1.231447835","rc":[{"batb":[[0,2.22,36.4],[1,1.74,17.32],[2,1.53,94.34]],"ltp":2.3,"tv":30.69,"id":169}]}]}
{"op":"mcm","clk":"11801958497","pt":1723082491991,"mc":[{"id":"1.231447835","rc":[{"batb":[[0,2.24,10],[1,2.22,36.4],[2,1.74,17.32]],"ltp":2.3,"tv":30.69,"id":169}]}]}
{"op":"mcm","clk":"11801958632","pt":1723082495332,"mc":[{"id":"1.231447835","rc":[{"batb":[[0,2.22,36.4],[1,1.74,17.32],[2,1.53,94.34]],"ltp":2.3,"tv":30.69,"id":169}]}]}
{"op":"mcm","clk":"11801958714","pt":1723082497641,"mc":[{"id":"1.231447835","rc":[{"batb":[[0,2.24,10],[1,2.22,36.4],[2,1.74,17.32]],"ltp":2.3,"tv":30.69,"id":169}]}]}
{"op":"mcm","clk":"11801958875","pt":1723082501047,"mc":[{"id":"1.231447835","rc":[{"batb":[[0,2.22,36.4],[1,1.74,17.32],[2,1.53,94.34]],"ltp":2.3,"tv":30.69,"id":169}]}]}
{"op":"mcm","clk":"11801959071","pt":1723082505220,"mc":[{"id":"1.231447835","rc":[{"batb":[[0,2.24,10],[1,2.22,36.4],[2,1.74,17.32]],"ltp":2.3,"tv":30.69,"id":169}]}]}
{"op":"mcm","clk":"11801959278","pt":1723082509246,"mc":[{"id":"1.231447835","rc":[{"batb":[[0,2.22,36.4],[1,1.74,17.32],[2,1.53,94.34]],"ltp":2.3,"tv":30.69,"id":169}]}]}
{"op":"mcm","clk":"11801959436","pt":1723082511833,"mc":[{"id":"1.231447835","rc":[{"batb":[[0,2.24,10],[1,2.22,36.4],[2,1.74,17.32]],"ltp":2.3,"tv":30.69,"id":169}]}]}
{"op":"mcm","clk":"11801959614","pt":1723082515359,"mc":[{"id":"1.231447835","rc":[{"batb":[[0,2.22,36.4],[1,1.74,17.32],[2,1.53,94.34]],"ltp":2.3,"tv":30.69,"id":169}]}]}
{"op":"mcm","clk":"11801959763","pt":1723082518655,"mc":[{"id":"1.231447835","rc":[{"batb":[[0,2.24,10],[1,2.22,36.4],[2,1.74,17.32]],"ltp":2.3,"tv":30.69,"id":169}]}]}
{"op":"mcm","clk":"11801959946","pt":1723082521957,"mc":[{"id":"1.231447835","rc":[{"batb":[[0,2.22,36.4],[1,1.74,17.32],[2,1.53,94.34]],"ltp":2.3,"tv":30.69,"id":169}]}]}
{"op":"mcm","clk":"11801960119","pt":1723082525944,"mc":[{"id":"1.231447835","rc":[{"batb":[[0,2.24,10],[1,2.22,36.4],[2,1.74,17.32]],"ltp":2.3,"tv":30.69,"id":169}]}]}
{"op":"mcm","clk":"11801960274","pt":1723082529343,"mc":[{"id":"1.231447835","rc":[{"batb":[[0,2.22,36.4],[1,1.74,17.32],[2,1.53,94.34]],"ltp":2.3,"tv":30.69,"id":169}]}]}
{"op":"mcm","clk":"11801960424","pt":1723082532379,"mc":[{"id":"1.231447835","rc":[{"batb":[[0,2.24,10],[1,2.22,36.4],[2,1.74,17.32]],"ltp":2.3,"tv":30.69,"id":169}]}]}
{"op":"mcm","clk":"11801960627","pt":1723082535884,"mc":[{"id":"1.231447835","rc":[{"batb":[[0,2.22,36.4],[1,1.74,17.32],[2,1.53,94.34]],"ltp":2.3,"tv":30.69,"id":169}]}]}
{"op":"mcm","clk":"11801960797","pt":1723082539179,"mc":[{"id":"1.231447835","rc":[{"batb":[[0,2.24,10],[1,2.22,36.4],[2,1.74,17.32]],"ltp":2.3,"tv":30.69,"id":169}]}]}
{"op":"mcm","clk":"11801960942","pt":1723082542462,"mc":[{"id":"1.231447835","rc":[{"batb":[[0,2.22,36.4],[1,1.74,17.32],[2,1.53,94.34]],"ltp":2.3,"tv":30.69,"id":169}]}]}
{"op":"mcm","clk":"11801961130","pt":1723082546671,"mc":[{"id":"1.231447835","rc":[{"batb":[[0,2.24,10],[1,2.22,36.4],[2,1.74,17.32]],"ltp":2.3,"tv":30.69,"id":169}]}]}
{"op":"mcm","clk":"11801961261","pt":1723082550175,"mc":[{"id":"1.231447835","rc":[{"batb":[[0,2.22,36.4],[1,1.74,17.32],[2,1.53,94.34]],"ltp":2.3,"tv":30.69,"id":169}]}]}
{"op":"mcm","clk":"11801961368","pt":1723082552687,"mc":[{"id":"1.231447835","rc":[{"batb":[[0,2.24,10],[1,2.22,36.4],[2,1.74,17.32]],"ltp":2.3,"tv":30.69,"id":169}]}]}
{"op":"mcm","clk":"11801961493","pt":1723082555974,"mc":[{"id":"1.231447835","rc":[{"batb":[[0,2.22,36.4],[1,1.74,17.32],[2,1.53,94.34]],"ltp":2.3,"tv":30.69,"id":169}]}]}
{"op":"mcm","clk":"11801961750","pt":1723082561489,"mc":[{"id":"1.231447835","rc":[{"batb":[[0,2.24,10],[1,2.22,36.4],[2,1.74,17.32]],"ltp":2.3,"tv":30.69,"id":169}]}]}
{"op":"mcm","clk":"11801961901","pt":1723082565076,"mc":[{"id":"1.231447835","rc":[{"batb":[[0,2.22,36.4],[1,1.74,17.32],[2,1.53,94.34]],"ltp":2.3,"tv":30.69,"id":169}]}]}
{"op":"mcm","clk":"11801961991","pt":1723082567600,"mc":[{"id":"1.231447835","rc":[{"batb":[[0,2.24,10],[1,2.22,36.4],[2,1.74,17.32]],"ltp":2.3,"tv":30.69,"id":169}]}]}
{"op":"mcm","clk":"11801962130","pt":1723082570996,"mc":[{"id":"1.231447835","rc":[{"batb":[[0,2.22,36.4],[1,1.74,17.32],[2,1.53,94.34]],"ltp":2.3,"tv":30.69,"id":169}]}]}
{"op":"mcm","clk":"11801962299","pt":1723082574915,"mc":[{"id":"1.231447835","rc":[{"batb":[[0,2.24,10],[1,2.22,36.4],[2,1.74,17.32]],"ltp":2.3,"tv":30.69,"id":169}]}]}
{"op":"mcm","clk":"11801962460","pt":1723082578413,"mc":[{"id":"1.231447835","rc":[{"batb":[[0,2.22,36.4],[1,1.74,17.32],[2,1.53,94.34]],"ltp":2.3,"tv":30.69,"id":169}]}]}
{"op":"mcm","clk":"11801962624","pt":1723082582120,"mc":[{"id":"1.231447835","rc":[{"batb":[[0,2.24,10],[1,2.22,36.4],[2,1.74,17.32]],"ltp":2.3,"tv":30.69,"id":169}]}]}
{"op":"mcm","clk":"11801962771","pt":1723082585318,"mc":[{"id":"1.231447835","rc":[{"batb":[[0,2.22,36.4],[1,1.74,17.32],[2,1.53,94.34]],"ltp":2.3,"tv":30.69,"id":169}]}]}
{"op":"mcm","clk":"11801962920","pt":1723082588027,"mc":[{"id":"1.231447835","rc":[{"batb":[[0,2.24,10],[1,2.22,36.4],[2,1.74,17.32]],"ltp":2.3,"tv":30.69,"id":169}]}]}
{"op":"mcm","clk":"11801963125","pt":1723082591511,"mc":[{"id":"1.231447835","rc":[{"batb":[[0,2.22,36.4],[1,1.74,17.32],[2,1.53,94.34]],"ltp":2.3,"tv":30.69,"id":169}]}]}
{"op":"mcm","clk":"11801963253","pt":1723082593800,"mc":[{"id":"1.231447835","rc":[{"batb":[[0,2.24,10],[1,2.22,36.4],[2,1.74,17.32]],"ltp":2.3,"tv":30.69,"id":169}]}]}
{"op":"mcm","clk":"11801963419","pt":1723082597414,"mc":[{"id":"1.231447835","rc":[{"batb":[[0,2.22,36.4],[1,1.74,17.32],[2,1.53,94.34]],"ltp":2.3,"tv":30.69,"id":169}]}]}
{"op":"mcm","clk":"11801963553","pt":1723082600626,"mc":[{"id":"1.231447835","rc":[{"batb":[[0,2.24,10],[1,2.22,36.4],[2,1.74,17.32]],"ltp":2.3,"tv":30.69,"id":169}]}]}
{"op":"mcm","clk":"11801963713","pt":1723082604024,"mc":[{"id":"1.231447835","rc":[{"batb":[[0,2.22,36.4],[1,1.74,17.32],[2,1.53,94.34]],"ltp":2.3,"tv":30.69,"id":169}]}]}
{"op":"mcm","clk":"11801963856","pt":1723082606628,"mc":[{"id":"1.231447835","rc":[{"batb":[[0,2.24,10],[1,2.22,36.4],[2,1.74,17.32]],"ltp":2.3,"tv":30.69,"id":169}]}]}
{"op":"mcm","clk":"11801964023","pt":1723082610027,"mc":[{"id":"1.231447835","rc":[{"batb":[[0,2.22,36.4],[1,1.74,17.32],[2,1.53,94.34]],"ltp":2.3,"tv":30.69,"id":169}]}]}
{"op":"mcm","clk":"11801964211","pt":1723082613441,"mc":[{"id":"1.231447835","rc":[{"batb":[[0,2.24,10],[1,2.22,36.4],[2,1.74,17.32]],"ltp":2.3,"tv":30.69,"id":169}]}]}
{"op":"mcm","clk":"11801964403","pt":1723082616851,"mc":[{"id":"1.231447835","rc":[{"batb":[[0,2.22,36.4],[1,1.74,17.32],[2,1.53,94.34]],"ltp":2.3,"tv":30.69,"id":169}]}]}
{"op":"mcm","clk":"11801964623","pt":1723082620517,"mc":[{"id":"1.231447835","rc":[{"batb":[[0,2.24,10],[1,2.22,36.4],[2,1.74,17.32]],"ltp":2.3,"tv":30.69,"id":169}]}]}
{"op":"mcm","clk":"11801964819","pt":1723082623831,"mc":[{"id":"1.231447835","rc":[{"batb":[[0,2.22,36.4],[1,1.74,17.32],[2,1.53,94.34]],"ltp":2.3,"tv":30.69,"id":169}]}]}
{"op":"mcm","clk":"11801964966","pt":1723082626722,"mc":[{"id":"1.231447835","rc":[{"batb":[[0,2.24,10],[1,2.22,36.4],[2,1.74,17.32]],"ltp":2.3,"tv":30.69,"id":169}]}]}
{"op":"mcm","clk":"11801965128","pt":1723082630072,"mc":[{"id":"1.231447835","rc":[{"batb":[[0,2.22,36.4],[1,1.74,17.32],[2,1.53,94.34]],"ltp":2.3,"tv":30.69,"id":169}]}]}
{"op":"mcm","clk":"11801965260","pt":1723082632958,"mc":[{"id":"1.231447835","rc":[{"batb":[[0,2.24,10],[1,2.22,36.4],[2,1.74,17.32]],"ltp":2.3,"tv":30.69,"id":169}]}]}
{"op":"mcm","clk":"11801965453","pt":1723082636387,"mc":[{"id":"1.231447835","rc":[{"batb":[[0,2.22,36.4],[1,1.74,17.32],[2,1.53,94.34]],"ltp":2.3,"tv":30.69,"id":169}]}]}
{"op":"mcm","clk":"11801965567","pt":1723082638860,"mc":[{"id":"1.231447835","rc":[{"batb":[[0,2.24,10],[1,2.22,36.4],[2,1.74,17.32]],"ltp":2.3,"tv":30.69,"id":169}]}]}
{"op":"mcm","clk":"11801965772","pt":1723082642265,"mc":[{"id":"1.231447835","rc":[{"batb":[[0,2.22,36.4],[1,1.74,17.32],[2,1.53,94.34]],"ltp":2.3,"tv":30.69,"id":169}]}]}
{"op":"mcm","clk":"11801965901","pt":1723082644854,"mc":[{"id":"1.231447835","rc":[{"batb":[[0,2.24,10],[1,2.22,36.4],[2,1.74,17.32]],"ltp":2.3,"tv":30.69,"id":169}]}]}
{"op":"mcm","clk":"11801966060","pt":1723082648161,"mc":[{"id":"1.231447835","rc":[{"batb":[[0,2.22,36.4],[1,1.74,17.32],[2,1.53,94.34]],"ltp":2.3,"tv":30.69,"id":169}]}]}
{"op":"mcm","clk":"11801966232","pt":1723082651159,"mc":[{"id":"1.231447835","rc":[{"batb":[[0,2.24,10],[1,2.22,36.4],[2,1.74,17.32]],"ltp":2.3,"tv":30.69,"id":169}]}]}
{"op":"mcm","clk":"11801966418","pt":1723082655383,"mc":[{"id":"1.231447835","rc":[{"batb":[[0,2.22,36.4],[1,1.74,17.32],[2,1.53,94.34]],"ltp":2.3,"tv":30.69,"id":169}]}]}
{"op":"mcm","clk":"11801966583","pt":1723082658790,"mc":[{"id":"1.231447835","rc":[{"batb":[[0,2.24,10],[1,2.22,36.4],[2,1.74,17.32]],"ltp":2.3,"tv":30.69,"id":169}]}]}
{"op":"mcm","clk":"11801966750","pt":1723082662068,"mc":[{"id":"1.231447835","rc":[{"batb":[[0,2.22,36.4],[1,1.74,17.32],[2,1.53,94.34]],"ltp":2.3,"tv":30.69,"id":169}]}]}
{"op":"mcm","clk":"11801966903","pt":1723082665264,"mc":[{"id":"1.231447835","rc":[{"batb":[[0,2.24,10],[1,2.22,36.4],[2,1.74,17.32]],"ltp":2.3,"tv":30.69,"id":169}]}]}
{"op":"mcm","clk":"11801967074","pt":1723082668665,"mc":[{"id":"1.231447835","rc":[{"batb":[[0,2.22,36.4],[1,1.74,17.32],[2,1.53,94.34]],"ltp":2.3,"tv":30.69,"id":169}]}]}
{"op":"mcm","clk":"11801967223","pt":1723082671858,"mc":[{"id":"1.231447835","rc":[{"batb":[[0,2.24,10],[1,2.22,36.4],[2,1.74,17.32]],"ltp":2.3,"tv":30.69,"id":169}]}]}
{"op":"mcm","clk":"11801967376","pt":1723082675102,"mc":[{"id":"1.231447835","rc":[{"batb":[[0,2.22,36.4],[1,1.74,17.32],[2,1.53,94.34]],"ltp":2.3,"tv":30.69,"id":169}]}]}
{"op":"mcm","clk":"11801967499","pt":1723082677678,"mc":[{"id":"1.231447835","rc":[{"batb":[[0,2.24,10],[1,2.22,36.4],[2,1.74,17.32]],"ltp":2.3,"tv":30.69,"id":169}]}]}
{"op":"mcm","clk":"11801967664","pt":1723082680879,"mc":[{"id":"1.231447835","rc":[{"batb":[[0,2.22,36.4],[1,1.74,17.32],[2,1.53,94.34]],"ltp":2.3,"tv":30.69,"id":169}]}]}
{"op":"mcm","clk":"11801967795","pt":1723082683714,"mc":[{"id":"1.231447835","rc":[{"batb":[[0,2.24,10],[1,2.22,36.4],[2,1.74,17.32]],"ltp":2.3,"tv":30.69,"id":169}]}]}
{"op":"mcm","clk":"11801967959","pt":1723082687082,"mc":[{"id":"1.231447835","rc":[{"batb":[[0,2.22,36.4],[1,1.74,17.32],[2,1.53,94.34]],"ltp":2.3,"tv":30.69,"id":169}]}]}
{"op":"mcm","clk":"11801968065","pt":1723082689604,"mc":[{"id":"1.231447835","rc":[{"batb":[[0,2.24,10],[1,2.22,36.4],[2,1.74,17.32]],"ltp":2.3,"tv":30.69,"id":169}]}]}
{"op":"mcm","clk":"11801968243","pt":1723082692890,"mc":[{"id":"1.231447835","rc":[{"batb":[[0,2.22,36.4],[1,1.74,17.32],[2,1.53,94.34]],"ltp":2.3,"tv":30.69,"id":169}]}]}
{"op":"mcm","clk":"11801968407","pt":1723082696407,"mc":[{"id":"1.231447835","rc":[{"batb":[[0,2.24,10],[1,2.22,36.4],[2,1.74,17.32]],"ltp":2.3,"tv":30.69,"id":169}]}]}
{"op":"mcm","clk":"11801968581","pt":1723082699815,"mc":[{"id":"1.231447835","rc":[{"batb":[[0,2.22,36.4],[1,1.74,17.32],[2,1.53,94.34]],"ltp":2.3,"tv":30.69,"id":169}]}]}
{"op":"mcm","clk":"11801968735","pt":1723082702933,"mc":[{"id":"1.231447835","rc":[{"batb":[[0,2.24,10],[1,2.22,36.4],[2,1.74,17.32]],"ltp":2.3,"tv":30.69,"id":169}]}]}
{"op":"mcm","clk":"11801968872","pt":1723082706235,"mc":[{"id":"1.231447835","rc":[{"batb":[[0,2.22,36.4],[1,1.74,17.32],[2,1.53,94.34]],"ltp":2.3,"tv":30.69,"id":169}]}]}
{"op":"mcm","clk":"11801968993","pt":1723082708923,"mc":[{"id":"1.231447835","rc":[{"batb":[[0,2.24,10],[1,2.22,36.4],[2,1.74,17.32]],"ltp":2.3,"tv":30.69,"id":169}]}]}
{"op":"mcm","clk":"11801969155","pt":1723082712324,"mc":[{"id":"1.231447835","rc":[{"batb":[[0,2.22,36.4],[1,1.74,17.32],[2,1.53,94.34]],"ltp":2.3,"tv":30.69,"id":169}]}]}
{"op":"mcm","clk":"11801969267","pt":1723082714746,"mc":[{"id":"1.231447835","rc":[{"batb":[[0,2.24,10],[1,2.22,36.4],[2,1.74,17.32]],"ltp":2.3,"tv":30.69,"id":169}]}]}
{"op":"mcm","clk":"11801969412","pt":1723082718015,"mc":[{"id":"1.231447835","rc":[{"batb":[[0,2.22,36.4],[1,1.74,17.32],[2,1.53,94.34]],"ltp":2.3,"tv":30.69,"id":169}]}]}
{"op":"mcm","clk":"11801969548","pt":1723082720710,"mc":[{"id":"1.231447835","rc":[{"batb":[[0,2.24,10],[1,2.22,36.4],[2,1.74,17.32]],"ltp":2.3,"tv":30.69,"id":169}]}]}
{"op":"mcm","clk":"11801969683","pt":1723082723957,"mc":[{"id":"1.231447835","rc":[{"batb":[[0,2.22,36.4],[1,1.74,17.32],[2,1.53,94.34]],"ltp":2.3,"tv":30.69,"id":169}]}]}
{"op":"mcm","clk":"11801970056","pt":1723082731774,"mc":[{"id":"1.231447835","rc":[{"batb":[[0,2.24,10],[1,2.22,36.4],[2,1.74,17.32]],"ltp":2.3,"tv":30.69,"id":169}]}]}
{"op":"mcm","clk":"11801970214","pt":1723082735078,"mc":[{"id":"1.231447835","rc":[{"batb":[[0,2.22,36.4],[1,1.74,17.32],[2,1.53,94.34]],"ltp":2.3,"tv":30.69,"id":169}]}]}
{"op":"mcm","clk":"11801970336","pt":1723082737355,"mc":[{"id":"1.231447835","rc":[{"batb":[[0,2.24,10],[1,2.22,36.4],[2,1.74,17.32]],"ltp":2.3,"tv":30.69,"id":169}]}]}
{"op":"mcm","clk":"11801970527","pt":1723082740766,"mc":[{"id":"1.231447835","rc":[{"batb":[[0,2.22,36.4],[1,1.74,17.32],[2,1.53,94.34]],"ltp":2.3,"tv":30.69,"id":169}]}]}
{"op":"mcm","clk":"11801970664","pt":1723082743546,"mc":[{"id":"1.231447835","rc":[{"batb":[[0,2.24,10],[1,2.22,36.4],[2,1.74,17.32]],"ltp":2.3,"tv":30.69,"id":169}]}]}
{"op":"mcm","clk":"11801970846","pt":1723082747247,"mc":[{"id":"1.231447835","rc":[{"batb":[[0,2.22,36.4],[1,1.74,17.32],[2,1.53,94.34]],"ltp":2.3,"tv":30.69,"id":169}]}]}
{"op":"mcm","clk":"11801970965","pt":1723082749873,"mc":[{"id":"1.231447835","rc":[{"batb":[[0,2.24,10],[1,2.22,36.4],[2,1.74,17.32]],"ltp":2.3,"tv":30.69,"id":169}]}]}
{"op":"mcm","clk":"11801971169","pt":1723082753265,"mc":[{"id":"1.231447835","rc":[{"batb":[[0,2.22,36.4],[1,1.74,17.32],[2,1.53,94.34]],"ltp":2.3,"tv":30.69,"id":169}]}]}
{"op":"mcm","clk":"11801971342","pt":1723082756777,"mc":[{"id":"1.231447835","rc":[{"batb":[[0,2.24,10],[1,2.22,36.4],[2,1.74,17.32]],"ltp":2.3,"tv":30.69,"id":169}]}]}
{"op":"mcm","clk":"11801971537","pt":1723082760296,"mc":[{"id":"1.231447835","rc":[{"batb":[[0,2.22,36.4],[1,1.74,17.32],[2,1.53,94.34]],"ltp":2.3,"tv":30.69,"id":169}]}]}
{"op":"mcm","clk":"11801971723","pt":1723082763081,"mc":[{"id":"1.231447835","rc":[{"batb":[[0,2.24,10],[1,2.22,36.4],[2,1.74,17.32]],"ltp":2.3,"tv":30.69,"id":169}]}]}
{"op":"mcm","clk":"11801971915","pt":1723082766478,"mc":[{"id":"1.231447835","rc":[{"batb":[[0,2.22,36.4],[1,1.74,17.32],[2,1.53,94.34]],"ltp":2.3,"tv":30.69,"id":169}]}]}
{"op":"mcm","clk":"11801972147","pt":1723082770179,"mc":[{"id":"1.231447835","rc":[{"batb":[[0,2.24,10],[1,2.22,36.4],[2,1.74,17.32]],"ltp":2.3,"tv":30.69,"id":169}]}]}
{"op":"mcm","clk":"11801972318","pt":1723082773571,"mc":[{"id":"1.231447835","rc":[{"batb":[[0,2.22,36.4],[1,1.74,17.32],[2,1.53,94.34]],"ltp":2.3,"tv":30.69,"id":169}]}]}
{"op":"mcm","clk":"11801972468","pt":1723082776702,"mc":[{"id":"1.231447835","rc":[{"batb":[[0,2.24,10],[1,2.22,36.4],[2,1.74,17.32]],"ltp":2.3,"tv":30.69,"id":169}]}]}
{"op":"mcm","clk":"11801972653","pt":1723082780303,"mc":[{"id":"1.231447835","rc":[{"batb":[[0,2.22,36.4],[1,1.74,17.32],[2,1.53,94.34]],"ltp":2.3,"tv":30.69,"id":169}]}]}
{"op":"mcm","clk":"11801972799","pt":1723082783073,"mc":[{"id":"1.231447835","rc":[{"batb":[[0,2.24,10],[1,2.22,36.4],[2,1.74,17.32]],"ltp":2.3,"tv":30.69,"id":169}]}]}
{"op":"mcm","clk":"11801972984","pt":1723082786478,"mc":[{"id":"1.231447835","rc":[{"batb":[[0,2.22,36.4],[1,1.74,17.32],[2,1.53,94.34]],"ltp":2.3,"tv":30.69,"id":169}]}]}
{"op":"mcm","clk":"11801973126","pt":1723082789317,"mc":[{"id":"1.231447835","rc":[{"batb":[[0,2.24,10],[1,2.22,36.4],[2,1.74,17.32]],"ltp":2.3,"tv":30.69,"id":169}]}]}
{"op":"mcm","clk":"11801973320","pt":1723082792816,"mc":[{"id":"1.231447835","rc":[{"batb":[[0,2.22,36.4],[1,1.74,17.32],[2,1.53,94.34]],"ltp":2.3,"tv":30.69,"id":169}]}]}
{"op":"mcm","clk":"11801973516","pt":1723082796219,"mc":[{"id":"1.231447835","rc":[{"batb":[[0,2.24,10],[1,2.22,36.4],[2,1.74,17.32]],"ltp":2.3,"tv":30.69,"id":169}]}]}
{"op":"mcm","clk":"11801973694","pt":1723082799627,"mc":[{"id":"1.231447835","rc":[{"batb":[[0,2.22,36.4],[1,1.74,17.32],[2,1.53,94.34]],"ltp":2.3,"tv":30.69,"id":169}]}]}
{"op":"mcm","clk":"11801973883","pt":1723082803132,"mc":[{"id":"1.231447835","rc":[{"batb":[[0,2.24,10],[1,2.22,36.4],[2,1.74,17.32]],"ltp":2.3,"tv":30.69,"id":169}]}]}
{"op":"mcm","clk":"11801974034","pt":1723082806330,"mc":[{"id":"1.231447835","rc":[{"batb":[[0,2.22,36.4],[1,1.74,17.32],[2,1.53,94.34]],"ltp":2.3,"tv":30.69,"id":169}]}]}
{"op":"mcm","clk":"11801974180","pt":1723082809113,"mc":[{"id":"1.231447835","rc":[{"batb":[[0,2.24,10],[1,2.22,36.4],[2,1.74,17.32]],"ltp":2.3,"tv":30.69,"id":169}]}]}
{"op":"mcm","clk":"11801974354","pt":1723082812519,"mc":[{"id":"1.231447835","rc":[{"batb":[[0,2.22,36.4],[1,1.74,17.32],[2,1.53,94.34]],"ltp":2.3,"tv":30.69,"id":169}]}]}
{"op":"mcm","clk":"11801974547","pt":1723082816253,"mc":[{"id":"1.231447835","rc":[{"batb":[[0,2.24,10],[1,2.22,36.4],[2,1.74,17.32]],"ltp":2.3,"tv":30.69,"id":169}]}]}
{"op":"mcm","clk":"11801974733","pt":1723082819752,"mc":[{"id":"1.231447835","rc":[{"batb":[[0,2.22,36.4],[1,1.74,17.32],[2,1.53,94.34]],"ltp":2.3,"tv":30.69,"id":169}]}]}
{"op":"mcm","clk":"11801974987","pt":1723082824035,"mc":[{"id":"1.231447835","rc":[{"batb":[[0,2.24,10],[1,2.22,36.4],[2,1.74,17.32]],"ltp":2.3,"tv":30.69,"id":169}]}]}
{"op":"mcm","clk":"11801975205","pt":1723082827551,"mc":[{"id":"1.231447835","rc":[{"batb":[[0,2.22,36.4],[1,1.74,17.32],[2,1.53,94.34]],"ltp":2.3,"tv":30.69,"id":169}]}]}
{"op":"mcm","clk":"11801975417","pt":1723082831052,"mc":[{"id":"1.231447835","rc":[{"batb":[[0,2.24,10],[1,2.22,36.4],[2,1.74,17.32]],"ltp":2.3,"tv":30.69,"id":169}]}]}
{"op":"mcm","clk":"11801975669","pt":1723082834662,"mc":[{"id":"1.231447835","rc":[{"batb":[[0,2.22,36.4],[1,1.74,17.32],[2,1.53,94.34]],"ltp":2.3,"tv":30.69,"id":169}]}]}
{"op":"mcm","clk":"11801975802","pt":1723082837339,"mc":[{"id":"1.231447835","rc":[{"batb":[[0,2.24,10],[1,2.22,36.4],[2,1.74,17.32]],"ltp":2.3,"tv":30.69,"id":169}]}]}
{"op":"mcm","clk":"11801975962","pt":1723082840942,"mc":[{"id":"1.231447835","rc":[{"batb":[[0,2.22,36.4],[1,1.74,17.32],[2,1.53,94.34]],"ltp":2.3,"tv":30.69,"id":169}]}]}
{"op":"mcm","clk":"11801976121","pt":1723082844239,"mc":[{"id":"1.231447835","rc":[{"batb":[[0,2.24,10],[1,2.22,36.4],[2,1.74,17.32]],"ltp":2.3,"tv":30.69,"id":169}]}]}
{"op":"mcm","clk":"11801976271","pt":1723082847887,"mc":[{"id":"1.231447835","rc":[{"batb":[[0,2.22,36.4],[1,1.74,17.32],[2,1.53,94.34]],"ltp":2.3,"tv":30.69,"id":169}]}]}
{"op":"mcm","clk":"11801976370","pt":1723082850252,"mc":[{"id":"1.231447835","rc":[{"batb":[[0,2.24,10],[1,2.22,36.4],[2,1.74,17.32]],"ltp":2.3,"tv":30.69,"id":169}]}]}
{"op":"mcm","clk":"11801976546","pt":1723082853752,"mc":[{"id":"1.231447835","rc":[{"batb":[[0,2.22,36.4],[1,1.74,17.32],[2,1.53,94.34]],"ltp":2.3,"tv":30.69,"id":169}]}]}
{"op":"mcm","clk":"11801976660","pt":1723082855962,"mc":[{"id":"1.231447835","rc":[{"batb":[[0,2.24,10],[1,2.22,36.4],[2,1.74,17.32]],"ltp":2.3,"tv":30.69,"id":169}]}]}
{"op":"mcm","clk":"11801976853","pt":1723082859366,"mc":[{"id":"1.231447835","rc":[{"batb":[[0,2.22,36.4],[1,1.74,17.32],[2,1.53,94.34]],"ltp":2.3,"tv":30.69,"id":169}]}]}
{"op":"mcm","clk":"11801977004","pt":1723082862604,"mc":[{"id":"1.231447835","rc":[{"batb":[[0,2.24,10],[1,2.22,36.4],[2,1.74,17.32]],"ltp":2.3,"tv":30.69,"id":169}]}]}
{"op":"mcm","clk":"11801977168","pt":1723082866094,"mc":[{"id":"1.231447835","rc":[{"batb":[[0,2.22,36.4],[1,1.74,17.32],[2,1.53,94.34]],"ltp":2.3,"tv":30.69,"id":169}]}]}
{"op":"mcm","clk":"11801977314","pt":1723082869887,"mc":[{"id":"1.231447835","rc":[{"batb":[[0,2.24,10],[1,2.22,36.4],[2,1.74,17.32]],"ltp":2.3,"tv":30.69,"id":169}]}]}
{"op":"mcm","clk":"11801977447","pt":1723082873276,"mc":[{"id":"1.231447835","rc":[{"batb":[[0,2.22,36.4],[1,1.74,17.32],[2,1.53,94.34]],"ltp":2.3,"tv":30.69,"id":169}]}]}
{"op":"mcm","clk":"11801977590","pt":1723082876369,"mc":[{"id":"1.231447835","rc":[{"batb":[[0,2.24,10],[1,2.22,36.4],[2,1.74,17.32]],"ltp":2.3,"tv":30.69,"id":169}]}]}
{"op":"mcm","clk":"11801977732","pt":1723082879610,"mc":[{"id":"1.231447835","rc":[{"batb":[[0,2.22,36.4],[1,1.74,17.32],[2,1.53,94.34]],"ltp":2.3,"tv":30.69,"id":169}]}]}
{"op":"mcm","clk":"11801977900","pt":1723082882810,"mc":[{"id":"1.231447835","rc":[{"batb":[[0,2.24,10],[1,2.22,36.4],[2,1.74,17.32]],"ltp":2.3,"tv":30.69,"id":169}]}]}
{"op":"mcm","clk":"11801978089","pt":1723082886210,"mc":[{"id":"1.231447835","rc":[{"batb":[[0,2.22,36.4],[1,1.74,17.32],[2,1.53,94.34]],"ltp":2.3,"tv":30.69,"id":169}]}]}
{"op":"mcm","clk":"11801978257","pt":1723082889093,"mc":[{"id":"1.231447835","rc":[{"batb":[[0,2.24,10],[1,2.22,36.4],[2,1.74,17.32]],"ltp":2.3,"tv":30.69,"id":169}]}]}
{"op":"mcm","clk":"11801978460","pt":1723082892392,"mc":[{"id":"1.231447835","rc":[{"batb":[[0,2.22,36.4],[1,1.74,17.32],[2,1.53,94.34]],"ltp":2.3,"tv":30.69,"id":169}]}]}
{"op":"mcm","clk":"11801978572","pt":1723082895013,"mc":[{"id":"1.231447835","rc":[{"batb":[[0,2.24,10],[1,2.22,36.4],[2,1.74,17.32]],"ltp":2.3,"tv":30.69,"id":169}]}]}
{"op":"mcm","clk":"11801978713","pt":1723082898308,"mc":[{"id":"1.231447835","rc":[{"batb":[[0,2.22,36.4],[1,1.74,17.32],[2,1.53,94.34]],"ltp":2.3,"tv":30.69,"id":169}]}]}
{"op":"mcm","clk":"11801978845","pt":1723082900829,"mc":[{"id":"1.231447835","rc":[{"batb":[[0,2.24,10],[1,2.22,36.4],[2,1.74,17.32]],"ltp":2.3,"tv":30.69,"id":169}]}]}
{"op":"mcm","clk":"11801979017","pt":1723082904124,"mc":[{"id":"1.231447835","rc":[{"batb":[[0,2.22,36.4],[1,1.74,17.32],[2,1.53,94.34]],"ltp":2.3,"tv":30.69,"id":169}]}]}
{"op":"mcm","clk":"11801979157","pt":1723082906921,"mc":[{"id":"1.231447835","rc":[{"batb":[[0,2.24,10],[1,2.22,36.4],[2,1.74,17.32]],"ltp":2.3,"tv":30.69,"id":169}]}]}
{"op":"mcm","clk":"11801979322","pt":1723082910402,"mc":[{"id":"1.231447835","rc":[{"batb":[[0,2.22,36.4],[1,1.74,17.32],[2,1.53,94.34]],"ltp":2.3,"tv":30.69,"id":169}]}]}
{"op":"mcm","clk":"11801979519","pt":1723082914534,"mc":[{"id":"1.231447835","rc":[{"batb":[[0,2.24,10],[1,2.22,36.4],[2,1.74,17.32]],"ltp":2.3,"tv":30.69,"id":169}]}]}
{"op":"mcm","clk":"11801979675","pt":1723082917955,"mc":[{"id":"1.231447835","rc":[{"batb":[[0,2.22,36.4],[1,1.74,17.32],[2,1.53,94.34]],"ltp":2.3,"tv":30.69,"id":169}]}]}
{"op":"mcm","clk":"11801979835","pt":1723082920750,"mc":[{"id":"1.231447835","rc":[{"batb":[[0,2.24,10],[1,2.22,36.4],[2,1.74,17.32]],"ltp":2.3,"tv":30.69,"id":169}]}]}
{"op":"mcm","clk":"11801980019","pt":1723082924460,"mc":[{"id":"1.231447835","rc":[{"batb":[[0,2.22,36.4],[1,1.74,17.32],[2,1.53,94.34]],"ltp":2.3,"tv":30.69,"id":169}]}]}
{"op":"mcm","clk":"11801980130","pt":1723082926729,"mc":[{"id":"1.231447835","rc":[{"batb":[[0,2.24,10],[1,2.22,36.4],[2,1.74,17.32]],"ltp":2.3,"tv":30.69,"id":169}]}]}
{"op":"mcm","clk":"11801980369","pt":1723082930347,"mc":[{"id":"1.231447835","rc":[{"batb":[[0,2.22,36.4],[1,1.74,17.32],[2,1.53,94.34]],"ltp":2.3,"tv":30.69,"id":169}]}]}
{"op":"mcm","clk":"11801980509","pt":1723082933033,"mc":[{"id":"1.231447835","rc":[{"batb":[[0,2.24,10],[1,2.22,36.4],[2,1.74,17.32]],"ltp":2.3,"tv":30.69,"id":169}]}]}
{"op":"mcm","clk":"11801980695","pt":1723082936492,"mc":[{"id":"1.231447835","rc":[{"batb":[[0,2.22,36.4],[1,1.74,17.32],[2,1.53,94.34]],"ltp":2.3,"tv":30.69,"id":169}]}]}
{"op":"mcm","clk":"11801980841","pt":1723082939063,"mc":[{"id":"1.231447835","rc":[{"batb":[[0,2.24,10],[1,2.22,36.4],[2,1.74,17.32]],"ltp":2.3,"tv":30.69,"id":169}]}]}
{"op":"mcm","clk":"11801981075","pt":1723082942581,"mc":[{"id":"1.231447835","rc":[{"batb":[[0,2.22,36.4],[1,1.74,17.32],[2,1.53,94.34]],"ltp":2.3,"tv":30.69,"id":169}]}]}
{"op":"mcm","clk":"11801981230","pt":1723082945466,"mc":[{"id":"1.231447835","rc":[{"batb":[[0,2.24,10],[1,2.22,36.4],[2,1.74,17.32]],"ltp":2.3,"tv":30.69,"id":169}]}]}
{"op":"mcm","clk":"11801981441","pt":1723082949380,"mc":[{"id":"1.231447835","rc":[{"batb":[[0,2.22,36.4],[1,1.74,17.32],[2,1.53,94.34]],"ltp":2.3,"tv":30.69,"id":169}]}]}
{"op":"mcm","clk":"11801981650","pt":1723082953261,"mc":[{"id":"1.231447835","rc":[{"batb":[[0,2.24,10],[1,2.22,36.4],[2,1.74,17.32]],"ltp":2.3,"tv":30.69,"id":169}]}]}
{"op":"mcm","clk":"11801981842","pt":1723082957161,"mc":[{"id":"1.231447835","rc":[{"batb":[[0,2.22,36.4],[1,1.74,17.32],[2,1.53,94.34]],"ltp":2.3,"tv":30.69,"id":169}]}]}
{"op":"mcm","clk":"11801982023","pt":1723082960579,"mc":[{"id":"1.231447835","rc":[{"batb":[[0,2.24,10],[1,2.22,36.4],[2,1.74,17.32]],"ltp":2.3,"tv":30.69,"id":169}]}]}
{"op":"mcm","clk":"11801982178","pt":1723082963763,"mc":[{"id":"1.231447835","rc":[{"batb":[[0,2.22,36.4],[1,1.74,17.32],[2,1.53,94.34]],"ltp":2.3,"tv":30.69,"id":169}]}]}
{"op":"mcm","clk":"11801982340","pt":1723082967109,"mc":[{"id":"1.231447835","rc":[{"batb":[[0,2.24,10],[1,2.22,36.4],[2,1.74,17.32]],"ltp":2.3,"tv":30.69,"id":169}]}]}
{"op":"mcm","clk":"11801982455","pt":1723082970209,"mc":[{"id":"1.231447835","rc":[{"batb":[[0,2.22,36.4],[1,1.74,17.32],[2,1.53,94.34]],"ltp":2.3,"tv":30.69,"id":169}]}]}
{"op":"mcm","clk":"11801982570","pt":1723082972693,"mc":[{"id":"1.231447835","rc":[{"batb":[[0,2.24,10],[1,2.22,36.4],[2,1.74,17.32]],"ltp":2.3,"tv":30.69,"id":169}]}]}
{"op":"mcm","clk":"11801982700","pt":1723082975985,"mc":[{"id":"1.231447835","rc":[{"batb":[[0,2.22,36.4],[1,1.74,17.32],[2,1.53,94.34]],"ltp":2.3,"tv":30.69,"id":169}]}]}
{"op":"mcm","clk":"11801982824","pt":1723082978403,"mc":[{"id":"1.231447835","rc":[{"batb":[[0,2.24,10],[1,2.22,36.4],[2,1.74,17.32]],"ltp":2.3,"tv":30.69,"id":169}]}]}
{"op":"mcm","clk":"11801983049","pt":1723082981811,"mc":[{"id":"1.231447835","rc":[{"batb":[[0,2.22,36.4],[1,1.74,17.32],[2,1.53,94.34]],"ltp":2.3,"tv":30.69,"id":169}]}]}
{"op":"mcm","clk":"11801983171","pt":1723082984079,"mc":[{"id":"1.231447835","rc":[{"batb":[[0,2.24,10],[1,2.22,36.4],[2,1.74,17.32]],"ltp":2.3,"tv":30.69,"id":169}]}]}
{"op":"mcm","clk":"11801983346","pt":1723082987425,"mc":[{"id":"1.231447835","rc":[{"batb":[[0,2.22,36.4],[1,1.74,17.32],[2,1.53,94.34]],"ltp":2.3,"tv":30.69,"id":169}]}]}
{"op":"mcm","clk":"11801983500","pt":1723082990302,"mc":[{"id":"1.231447835","rc":[{"batb":[[0,2.24,10],[1,2.22,36.4],[2,1.74,17.32]],"ltp":2.3,"tv":30.69,"id":169}]}]}
{"op":"mcm","clk":"11801983657","pt":1723082993892,"mc":[{"id":"1.231447835","rc":[{"batb":[[0,2.22,36.4],[1,1.74,17.32],[2,1.53,94.34]],"ltp":2.3,"tv":30.69,"id":169}]}]}
{"op":"mcm","clk":"11801983782","pt":1723082997493,"mc":[{"id":"1.231447835","rc":[{"batb":[[0,2.24,10],[1,2.22,36.4],[2,1.74,17.32]],"ltp":2.3,"tv":30.69,"id":169}]}]}
{"op":"mcm","clk":"11801984010","pt":1723083000820,"mc":[{"id":"1.231447835","rc":[{"batb":[[0,2.22,36.4],[1,1.74,17.32],[2,1.53,94.34]],"ltp":2.3,"tv":30.69,"id":169}]}]}
{"op":"mcm","clk":"11801984199","pt":1723083003902,"mc":[{"id":"1.231447835","rc":[{"batb":[[0,2.24,10],[1,2.22,36.4],[2,1.74,17.32]],"ltp":2.3,"tv":30.69,"id":169}]}]}
{"op":"mcm","clk":"11801984344","pt":1723083007333,"mc":[{"id":"1.231447835","rc":[{"batb":[[0,2.22,36.4],[1,1.74,17.32],[2,1.53,94.34]],"ltp":2.3,"tv":30.69,"id":169}]}]}
{"op":"mcm","clk":"11801984465","pt":1723083010008,"mc":[{"id":"1.231447835","rc":[{"batb":[[0,2.24,10],[1,2.22,36.4],[2,1.74,17.32]],"ltp":2.3,"tv":30.69,"id":169}]}]}
{"op":"mcm","clk":"11801984589","pt":1723083013388,"mc":[{"id":"1.231447835","rc":[{"batb":[[0,2.22,36.4],[1,1.74,17.32],[2,1.53,94.34]],"ltp":2.3,"tv":30.69,"id":169}]}]}
{"op":"mcm","clk":"11801984690","pt":1723083016103,"mc":[{"id":"1.231447835","rc":[{"batb":[[0,2.24,10],[1,2.22,36.4],[2,1.74,17.32]],"ltp":2.3,"tv":30.69,"id":169}]}]}
{"op":"mcm","clk":"11801984840","pt":1723083019537,"mc":[{"id":"1.231447835","rc":[{"batb":[[0,2.22,36.4],[1,1.74,17.32],[2,1.53,94.34]],"ltp":2.3,"tv":30.69,"id":169}]}]}
{"op":"mcm","clk":"11801985002","pt":1723083023232,"mc":[{"id":"1.231447835","rc":[{"batb":[[0,2.24,10],[1,2.22,36.4],[2,1.74,17.32]],"ltp":2.3,"tv":30.69,"id":169}]}]}
{"op":"mcm","clk":"11801985123","pt":1723083026735,"mc":[{"id":"1.231447835","rc":[{"batb":[[0,2.22,36.4],[1,1.74,17.32],[2,1.53,94.34]],"ltp":2.3,"tv":30.69,"id":169}]}]}
{"op":"mcm","clk":"11801985248","pt":1723083029926,"mc":[{"id":"1.231447835","rc":[{"batb":[[0,2.24,10],[1,2.22,36.4],[2,1.74,17.32]],"ltp":2.3,"tv":30.69,"id":169}]}]}
{"op":"mcm","clk":"11801985380","pt":1723083033321,"mc":[{"id":"1.231447835","rc":[{"batb":[[0,2.22,36.4],[1,1.74,17.32],[2,1.53,94.34]],"ltp":2.3,"tv":30.69,"id":169}]}]}
{"op":"mcm","clk":"11801985477","pt":1723083036144,"mc":[{"id":"1.231447835","rc":[{"batb":[[0,2.24,10],[1,2.22,36.4],[2,1.74,17.32]],"ltp":2.3,"tv":30.69,"id":169}]}]}
{"op":"mcm","clk":"11801985604","pt":1723083039341,"mc":[{"id":"1.231447835","rc":[{"batb":[[0,2.22,36.4],[1,1.74,17.32],[2,1.53,94.34]],"ltp":2.3,"tv":30.69,"id":169}]}]}
{"op":"mcm","clk":"11801985746","pt":1723083042548,"mc":[{"id":"1.231447835","rc":[{"batb":[[0,2.24,10],[1,2.22,36.4],[2,1.74,17.32]],"ltp":2.3,"tv":30.69,"id":169}]}]}
{"op":"mcm","clk":"11801985877","pt":1723083046287,"mc":[{"id":"1.231447835","rc":[{"batb":[[0,2.22,36.4],[1,1.74,17.32],[2,1.53,94.34]],"ltp":2.3,"tv":30.69,"id":169}]}]}
{"op":"mcm","clk":"11801985959","pt":1723083048434,"mc":[{"id":"1.231447835","rc":[{"batb":[[0,2.24,10],[1,2.22,36.4],[2,1.74,17.32]],"ltp":2.3,"tv":30.69,"id":169}]}]}
{"op":"mcm","clk":"11801986104","pt":1723083052052,"mc":[{"id":"1.231447835","rc":[{"batb":[[0,2.22,36.4],[1,1.74,17.32],[2,1.53,94.34]],"ltp":2.3,"tv":30.69,"id":169}]}]}
{"op":"mcm","clk":"11801986200","pt":1723083055387,"mc":[{"id":"1.231447835","rc":[{"batb":[[0,2.24,10],[1,2.22,36.4],[2,1.74,17.32]],"ltp":2.3,"tv":30.69,"id":169}]}]}
{"op":"mcm","clk":"11801986299","pt":1723083058770,"mc":[{"id":"1.231447835","rc":[{"batb":[[0,2.22,36.4],[1,1.74,17.32],[2,1.53,94.34]],"ltp":2.3,"tv":30.69,"id":169}]}]}
{"op":"mcm","clk":"11801986434","pt":1723083062570,"mc":[{"id":"1.231447835","rc":[{"batb":[[0,2.24,10],[1,2.22,36.4],[2,1.74,17.32]],"ltp":2.3,"tv":30.69,"id":169}]}]}
{"op":"mcm","clk":"11801986550","pt":1723083066066,"mc":[{"id":"1.231447835","rc":[{"batb":[[0,2.22,36.4],[1,1.74,17.32],[2,1.53,94.34]],"ltp":2.3,"tv":30.69,"id":169}]}]}
{"op":"mcm","clk":"11801986655","pt":1723083068785,"mc":[{"id":"1.231447835","rc":[{"batb":[[0,2.24,10],[1,2.22,36.4],[2,1.74,17.32]],"ltp":2.3,"tv":30.69,"id":169}]}]}
{"op":"mcm","clk":"11801986772","pt":1723083072178,"mc":[{"id":"1.231447835","rc":[{"batb":[[0,2.22,36.4],[1,1.74,17.32],[2,1.53,94.34]],"ltp":2.3,"tv":30.69,"id":169}]}]}
{"op":"mcm","clk":"11801986915","pt":1723083075977,"mc":[{"id":"1.231447835","rc":[{"batb":[[0,2.24,10],[1,2.22,36.4],[2,1.74,17.32]],"ltp":2.3,"tv":30.69,"id":169}]}]}
{"op":"mcm","clk":"11801987019","pt":1723083079294,"mc":[{"id":"1.231447835","rc":[{"batb":[[0,2.22,36.4],[1,1.74,17.32],[2,1.53,94.34]],"ltp":2.3,"tv":30.69,"id":169}]}]}
{"op":"mcm","clk":"11801987111","pt":1723083081910,"mc":[{"id":"1.231447835","rc":[{"batb":[[0,2.24,10],[1,2.22,36.4],[2,1.74,17.32]],"ltp":2.3,"tv":30.69,"id":169}]}]}
{"op":"mcm","clk":"11801987228","pt":1723083085305,"mc":[{"id":"1.231447835","rc":[{"batb":[[0,2.22,36.4],[1,1.74,17.32],[2,1.53,94.34]],"ltp":2.3,"tv":30.69,"id":169}]}]}
{"op":"mcm","clk":"11801987332","pt":1723083087878,"mc":[{"id":"1.231447835","rc":[{"batb":[[0,2.24,10],[1,2.22,36.4],[2,1.74,17.32]],"ltp":2.3,"tv":30.69,"id":169}]}]}
{"op":"mcm","clk":"11801987436","pt":1723083091214,"mc":[{"id":"1.231447835","rc":[{"batb":[[0,2.22,36.4],[1,1.74,17.32],[2,1.53,94.34]],"ltp":2.3,"tv":30.69,"id":169}]}]}
{"op":"mcm","clk":"11801987540","pt":1723083093994,"mc":[{"id":"1.231447835","rc":[{"batb":[[0,2.24,10],[1,2.22,36.4],[2,1.74,17.32]],"ltp":2.3,"tv":30.69,"id":169}]}]}
{"op":"mcm","clk":"11801987656","pt":1723083097391,"mc":[{"id":"1.231447835","rc":[{"batb":[[0,2.22,36.4],[1,1.74,17.32],[2,1.53,94.34]],"ltp":2.3,"tv":30.69,"id":169}]}]}
{"op":"mcm","clk":"11801987839","pt":1723083100991,"mc":[{"id":"1.231447835","rc":[{"batb":[[0,2.24,10],[1,2.22,36.4],[2,1.74,17.32]],"ltp":2.3,"tv":30.69,"id":169}]}]}
{"op":"mcm","clk":"11801987996","pt":1723083104735,"mc":[{"id":"1.231447835","rc":[{"batb":[[0,2.22,36.4],[1,1.74,17.32],[2,1.53,94.34]],"ltp":2.3,"tv":30.69,"id":169}]}]}
{"op":"mcm","clk":"11801988091","pt":1723083106999,"mc":[{"id":"1.231447835","rc":[{"batb":[[0,2.24,10],[1,2.22,36.4],[2,1.74,17.32]],"ltp":2.3,"tv":30.69,"id":169}]}]}
{"op":"mcm","clk":"11801988230","pt":1723083110342,"mc":[{"id":"1.231447835","rc":[{"batb":[[0,2.22,36.4],[1,1.74,17.32],[2,1.53,94.34]],"ltp":2.3,"tv":30.69,"id":169}]}]}
{"op":"mcm","clk":"11801988366","pt":1723083112929,"mc":[{"id":"1.231447835","rc":[{"batb":[[0,2.24,10],[1,2.22,36.4],[2,1.74,17.32]],"ltp":2.3,"tv":30.69,"id":169}]}]}
{"op":"mcm","clk":"11801988533","pt":1723083116359,"mc":[{"id":"1.231447835","rc":[{"batb":[[0,2.22,36.4],[1,1.74,17.32],[2,1.53,94.34]],"ltp":2.3,"tv":30.69,"id":169}]}]}
{"op":"mcm","clk":"11801988664","pt":1723083119439,"mc":[{"id":"1.231447835","rc":[{"batb":[[0,2.24,10],[1,2.22,36.4],[2,1.74,17.32]],"ltp":2.3,"tv":30.69,"id":169}]}]}
{"op":"mcm","clk":"11801988829","pt":1723083122851,"mc":[{"id":"1.231447835","rc":[{"batb":[[0,2.22,36.4],[1,1.74,17.32],[2,1.53,94.34]],"ltp":2.3,"tv":30.69,"id":169}]}]}
{"op":"mcm","clk":"11801988944","pt":1723083125533,"mc":[{"id":"1.231447835","rc":[{"batb":[[0,2.24,10],[1,2.22,36.4],[2,1.74,17.32]],"ltp":2.3,"tv":30.69,"id":169}]}]}
{"op":"mcm","clk":"11801989121","pt":1723083129340,"mc":[{"id":"1.231447835","rc":[{"batb":[[0,2.22,36.4],[1,1.74,17.32],[2,1.53,94.34]],"ltp":2.3,"tv":30.69,"id":169}]}]}
{"op":"mcm","clk":"11801989250","pt":1723083132165,"mc":[{"id":"1.231447835","rc":[{"batb":[[0,2.24,10],[1,2.22,36.4],[2,1.74,17.32]],"ltp":2.3,"tv":30.69,"id":169}]}]}
{"op":"mcm","clk":"11801989418","pt":1723083135571,"mc":[{"id":"1.231447835","rc":[{"batb":[[0,2.22,36.4],[1,1.74,17.32],[2,1.53,94.34]],"ltp":2.3,"tv":30.69,"id":169}]}]}
{"op":"mcm","clk":"11801989530","pt":1723083138663,"mc":[{"id":"1.231447835","rc":[{"batb":[[0,2.24,10],[1,2.22,36.4],[2,1.74,17.32]],"ltp":2.3,"tv":30.69,"id":169}]}]}
{"op":"mcm","clk":"11801989678","pt":1723083142160,"mc":[{"id":"1.231447835","rc":[{"batb":[[0,2.22,36.4],[1,1.74,17.32],[2,1.53,94.34]],"ltp":2.3,"tv":30.69,"id":169}]}]}
{"op":"mcm","clk":"11801989815","pt":1723083144643,"mc":[{"id":"1.231447835","rc":[{"batb":[[0,2.24,10],[1,2.22,36.4],[2,1.74,17.32]],"ltp":2.3,"tv":30.69,"id":169}]}]}
{"op":"mcm","clk":"11801989943","pt":1723083148077,"mc":[{"id":"1.231447835","rc":[{"batb":[[0,2.22,36.4],[1,1.74,17.32],[2,1.53,94.34]],"ltp":2.3,"tv":30.69,"id":169}]}]}
{"op":"mcm","clk":"11801990100","pt":1723083151157,"mc":[{"id":"1.231447835","rc":[{"batb":[[0,2.24,10],[1,2.22,36.4],[2,1.74,17.32]],"ltp":2.3,"tv":30.69,"id":169}]}]}
{"op":"mcm","clk":"11801990258","pt":1723083154564,"mc":[{"id":"1.231447835","rc":[{"batb":[[0,2.22,36.4],[1,1.74,17.32],[2,1.53,94.34]],"ltp":2.3,"tv":30.69,"id":169}]}]}
{"op":"mcm","clk":"11801990366","pt":1723083157105,"mc":[{"id":"1.231447835","rc":[{"batb":[[0,2.24,10],[1,2.22,36.4],[2,1.74,17.32]],"ltp":2.3,"tv":30.69,"id":169}]}]}
{"op":"mcm","clk":"11801990544","pt":1723083160609,"mc":[{"id":"1.231447835","rc":[{"batb":[[0,2.22,36.4],[1,1.74,17.32],[2,1.53,94.34]],"ltp":2.3,"tv":30.69,"id":169}]}]}
{"op":"mcm","clk":"11801990676","pt":1723083163305,"mc":[{"id":"1.231447835","rc":[{"batb":[[0,2.24,10],[1,2.22,36.4],[2,1.74,17.32]],"ltp":2.3,"tv":30.69,"id":169}]}]}
{"op":"mcm","clk":"11801990852","pt":1723083166904,"mc":[{"id":"1.231447835","rc":[{"batb":[[0,2.22,36.4],[1,1.74,17.32],[2,1.53,94.34]],"ltp":2.3,"tv":30.69,"id":169}]}]}
{"op":"mcm","clk":"11801990946","pt":1723083169376,"mc":[{"id":"1.231447835","rc":[{"batb":[[0,2.24,10],[1,2.22,36.4],[2,1.74,17.32]],"ltp":2.3,"tv":30.69,"id":169}]}]}
{"op":"mcm","clk":"11801991103","pt":1723083172820,"mc":[{"id":"1.231447835","rc":[{"batb":[[0,2.22,36.4],[1,1.74,17.32],[2,1.53,94.34]],"ltp":2.3,"tv":30.69,"id":169}]}]}
{"op":"mcm","clk":"11801991191","pt":1723083175282,"mc":[{"id":"1.231447835","rc":[{"batb":[[0,2.24,10],[1,2.22,36.4],[2,1.74,17.32]],"ltp":2.3,"tv":30.69,"id":169}]}]}
{"op":"mcm","clk":"11801991316","pt":1723083178817,"mc":[{"id":"1.231447835","rc":[{"batb":[[0,2.22,36.4],[1,1.74,17.32],[2,1.53,94.34]],"ltp":2.3,"tv":30.69,"id":169}]}]}
{"op":"mcm","clk":"11801991449","pt":1723083182229,"mc":[{"id":"1.231447835","rc":[{"batb":[[0,2.24,10],[1,2.22,36.4],[2,1.74,17.32]],"ltp":2.3,"tv":30.69,"id":169}]}]}
{"op":"mcm","clk":"11801991609","pt":1723083185522,"mc":[{"id":"1.231447835","rc":[{"batb":[[0,2.22,36.4],[1,1.74,17.32],[2,1.53,94.34]],"ltp":2.3,"tv":30.69,"id":169}]}]}
{"op":"mcm","clk":"11801991726","pt":1723083188032,"mc":[{"id":"1.231447835","rc":[{"batb":[[0,2.24,10],[1,2.22,36.4],[2,1.74,17.32]],"ltp":2.3,"tv":30.69,"id":169}]}]}
{"op":"mcm","clk":"11801991909","pt":1723083191639,"mc":[{"id":"1.231447835","rc":[{"batb":[[0,2.22,36.4],[1,1.74,17.32],[2,1.53,94.34]],"ltp":2.3,"tv":30.69,"id":169}]}]}
{"op":"mcm","clk":"11801992036","pt":1723083194324,"mc":[{"id":"1.231447835","rc":[{"batb":[[0,2.24,10],[1,2.22,36.4],[2,1.74,17.32]],"ltp":2.3,"tv":30.69,"id":169}]}]}
{"op":"mcm","clk":"11801992165","pt":1723083197710,"mc":[{"id":"1.231447835","rc":[{"batb":[[0,2.22,36.4],[1,1.74,17.32],[2,1.53,94.34]],"ltp":2.3,"tv":30.69,"id":169}]}]}
{"op":"mcm","clk":"11801992283","pt":1723083200948,"mc":[{"id":"1.231447835","rc":[{"batb":[[0,2.24,10],[1,2.22,36.4],[2,1.74,17.32]],"ltp":2.3,"tv":30.69,"id":169}]}]}
{"op":"mcm","clk":"11801992393","pt":1723083204337,"mc":[{"id":"1.231447835","rc":[{"batb":[[0,2.22,36.4],[1,1.74,17.32],[2,1.53,94.34]],"ltp":2.3,"tv":30.69,"id":169}]}]}
{"op":"mcm","clk":"11801992519","pt":1723083207423,"mc":[{"id":"1.231447835","rc":[{"batb":[[0,2.24,10],[1,2.22,36.4],[2,1.74,17.32]],"ltp":2.3,"tv":30.69,"id":169}]}]}
{"op":"mcm","clk":"11801992656","pt":1723083210734,"mc":[{"id":"1.231447835","rc":[{"batb":[[0,2.22,36.4],[1,1.74,17.32],[2,1.53,94.34]],"ltp":2.3,"tv":30.69,"id":169}]}]}
{"op":"mcm","clk":"11801992760","pt":1723083213434,"mc":[{"id":"1.231447835","rc":[{"batb":[[0,2.24,10],[1,2.22,36.4],[2,1.74,17.32]],"ltp":2.3,"tv":30.69,"id":169}]}]}
{"op":"mcm","clk":"11801992901","pt":1723083216929,"mc":[{"id":"1.231447835","rc":[{"batb":[[0,2.22,36.4],[1,1.74,17.32],[2,1.53,94.34]],"ltp":2.3,"tv":30.69,"id":169}]}]}
{"op":"mcm","clk":"11801993080","pt":1723083220874,"mc":[{"id":"1.231447835","rc":[{"batb":[[0,2.24,10],[1,2.22,36.4],[2,1.74,17.32]],"ltp":2.3,"tv":30.69,"id":169}]}]}
{"op":"mcm","clk":"11801993219","pt":1723083224265,"mc":[{"id":"1.231447835","rc":[{"batb":[[0,2.22,36.4],[1,1.74,17.32],[2,1.53,94.34]],"ltp":2.3,"tv":30.69,"id":169}]}]}
{"op":"mcm","clk":"11801993392","pt":1723083228072,"mc":[{"id":"1.231447835","rc":[{"batb":[[0,2.24,10],[1,2.22,36.4],[2,1.74,17.32]],"ltp":2.3,"tv":30.69,"id":169}]}]}
{"op":"mcm","clk":"11801993560","pt":1723083231676,"mc":[{"id":"1.231447835","rc":[{"batb":[[0,2.22,36.4],[1,1.74,17.32],[2,1.53,94.34]],"ltp":2.3,"tv":30.69,"id":169}]}]}
{"op":"mcm","clk":"11801993699","pt":1723083234775,"mc":[{"id":"1.231447835","rc":[{"batb":[[0,2.24,10],[1,2.22,36.4],[2,1.74,17.32]],"ltp":2.3,"tv":30.69,"id":169}]}]}
