{"op":"mcm","clk":"11777158590","pt":1722333537280,"mc":[{"id":"1.231243109","marketDefinition":{"bspMarket":false,"turnInPlayEnabled":true,"persistenceEnabled":true,"marketBaseRate":5.0,"eventId":"33455129","eventTypeId":"4","numberOfWinners":1,"bettingType":"ODDS","marketType":"MATCH_ODDS","marketTime":"2024-08-02T14:00:00.000Z","suspendTime":"2024-08-02T14:00:00.000Z","bspReconciled":false,"complete":true,"inPlay":false,"crossMatching":true,"runnersVoidable":false,"numberOfActiveRunners":2,"betDelay":0,"status":"OPEN","runners":[{"status":"ACTIVE","sortPriority":1,"id":40380901,"name":"Oval Invincibles W"},{"status":"ACTIVE","sortPriority":2,"id":40380900,"name":"Northern Superchargers W"}],"regulators":["MR_INT"],"countryCode":"GB","discountAllowed":true,"timezone":"GMT","openDate":"2024-08-02T14:00:00.000Z","version":6047222330,"name":"Match Odds","eventName":"Oval Invincibles W v Northern Superchargers W"},"rc":[{"batb":[[0,1.01,20]],"ltp":0.0,"tv":0.0,"id":40380900},{"batb":[[0,1.01,20]],"ltp":0.0,"tv":0.0,"id":40380901}]}]}
{"op":"mcm","clk":"11777158630","pt":1722333537651,"mc":[{"id":"1.231243109","rc":[{"batb":[[0,1.03,200],[1,1.02,200],[2,1.01,220]],"ltp":0.0,"tv":0.0,"id":40380900},{"batb":[[0,1.03,200],[1,1.02,200],[2,1.01,220]],"ltp":0.0,"tv":0.0,"id":40380901}]}]}
{"op":"mcm","clk":"11777175414","pt":1722333717648,"mc":[{"id":"1.231243109","marketDefinition":{"bspMarket":false,"turnInPlayEnabled":true,"persistenceEnabled":true,"marketBaseRate":5.0,"eventId":"33455129","eventTypeId":"4","numberOfWinners":1,"bettingType":"ODDS","marketType":"MATCH_ODDS","marketTime":"2024-08-02T12:00:00.000Z","suspendTime":"2024-08-02T12:00:00.000Z","bspReconciled":false,"complete":true,"inPlay":false,"crossMatching":true,"runnersVoidable":false,"numberOfActiveRunners":2,"betDelay":0,"status":"OPEN","runners":[{"status":"ACTIVE","sortPriority":1,"id":40380901,"name":"Oval Invincibles W"},{"status":"ACTIVE","sortPriority":2,"id":40380900,"name":"Northern Superchargers W"}],"regulators":["MR_INT"],"countryCode":"GB","discountAllowed":true,"timezone":"GMT","openDate":"2024-08-02T14:00:00.000Z","version":6047223143,"name":"Match Odds","eventName":"Oval Invincibles W v Northern Superchargers W"}}]}
{"op":"mcm","clk":"11777175698","pt":1722333720636,"mc":[{"id":"1.231243109","marketDefinition":{"bspMarket":false,"turnInPlayEnabled":true,"persistenceEnabled":true,"marketBaseRate":5.0,"eventId":"33455129","eventTypeId":"4","numberOfWinners":1,"bettingType":"ODDS","marketType":"MATCH_ODDS","marketTime":"2024-08-02T12:00:00.000Z","suspendTime":"2024-08-02T12:00:00.000Z","bspReconciled":false,"complete":true,"inPlay":false,"crossMatching":true,"runnersVoidable":false,"numberOfActiveRunners":2,"betDelay":0,"status":"OPEN","runners":[{"status":"ACTIVE","sortPriority":1,"id":40380901,"name":"Oval Invincibles W"},{"status":"ACTIVE","sortPriority":2,"id":40380900,"name":"Northern Superchargers W"}],"regulators":["MR_INT"],"countryCode":"GB","discountAllowed":true,"timezone":"GMT","openDate":"2024-08-02T12:00:00.000Z","version":6047223143,"name":"Match Odds","eventName":"Oval Invincibles W v Northern Superchargers W"}}]}
{"op":"mcm","clk":"11777417130","pt":1722336103243,"mc":[{"id":"1.231243109","rc":[{"batb":[[2,1.01,25220]],"ltp":0.0,"tv":0.0,"id":40380900},{"batb":[[2,1.01,25220]],"ltp":0.0,"tv":0.0,"id":40380901}]}]}
{"op":"mcm","clk":"11777417162","pt":1722336103548,"mc":[{"id":"1.231243109","rc":[{"batb":[[0,1.1,25000],[1,1.09,25000],[2,1.08,25000]],"ltp":0.0,"tv":0.0,"id":40380900},{"batb":[[0,1.1,25000],[1,1.09,25000],[2,1.08,25000]],"ltp":0.0,"tv":0.0,"id":40380901}]}]}
{"op":"mcm","clk":"11778603669","pt":1722347863167,"mc":[{"id":"1.231243109","rc":[{"batb":[[0,1.1,10000]],"ltp":0.0,"tv":0.0,"id":40380901}]}]}
{"op":"mcm","clk":"11778603772","pt":1722347864043,"mc":[{"id":"1.231243109","rc":[{"batb":[[0,1.08,25000],[1,1.07,25000],[2,1.06,25000]],"ltp":0.0,"tv":0.0,"id":40380901}]}]}
{"op":"mcm","clk":"11778603890","pt":1722347865280,"mc":[{"id":"1.231243109","rc":[{"batb":[[0,1.07,15000],[1,1.06,10000],[2,1.05,25000]],"ltp":0.0,"tv":0.0,"id":40380901}]}]}
{"op":"mcm","clk":"11778603927","pt":1722347865542,"mc":[{"id":"1.231243109","rc":[{"batb":[[0,1.05,25000],[1,1.04,25000],[2,1.03,25200]],"ltp":0.0,"tv":0.0,"id":40380901}]}]}
{"op":"mcm","clk":"11778604057","pt":1722347866678,"mc":[{"id":"1.231243109","rc":[{"batb":[[0,1.04,25000],[1,1.03,25200],[2,1.02,25200]],"ltp":0.0,"tv":0.0,"id":40380901}]}]}
{"op":"mcm","clk":"11778604615","pt":1722347871182,"mc":[{"id":"1.231243109","rc":[{"batb":[[0,1.09,10000],[1,1.08,25000],[2,1.07,25000]],"ltp":0.0,"tv":0.0,"id":40380900}]}]}
{"op":"mcm","clk":"11778604727","pt":1722347872062,"mc":[{"id":"1.231243109","rc":[{"batb":[[0,1.06,25000],[1,1.05,25000],[2,1.04,25000]],"ltp":0.0,"tv":0.0,"id":40380900}]}]}
{"op":"mcm","clk":"11778604825","pt":1722347872942,"mc":[{"id":"1.231243109","rc":[{"batb":[[0,1.05,25000],[1,1.04,25000],[2,1.03,25200]],"ltp":0.0,"tv":0.0,"id":40380900}]}]}
{"op":"mcm","clk":"11780235494","pt":1722360972883,"mc":[{"id":"1.231243109","rc":[{"batb":[[0,1.25,100],[1,1.05,25000],[2,1.04,25000]],"ltp":0.0,"tv":0.0,"id":40380900},{"batb":[[0,1.25,100],[1,1.04,25000],[2,1.03,25200]],"ltp":0.0,"tv":0.0,"id":40380901}]}]}
{"op":"mcm","clk":"11781471344","pt":1722370562406,"mc":[{"id":"1.231243109","rc":[{"batb":[[0,1.26,10],[1,1.25,100],[2,1.05,25000]],"ltp":0.0,"tv":0.0,"id":40380900},{"batb":[[0,1.26,10],[1,1.25,100],[2,1.04,25000]],"ltp":0.0,"tv":0.0,"id":40380901}]}]}
{"op":"mcm","clk":"11781662719","pt":1722373873702,"mc":[{"id":"1.231243109","rc":[{"batb":[[0,1.27,18],[1,1.26,10],[2,1.25,100]],"ltp":0.0,"tv":0.0,"id":40380901}]}]}
{"op":"mcm","clk":"11781662978","pt":1722373880520,"mc":[{"id":"1.231243109","rc":[{"batb":[[0,1.3,16],[1,1.26,10],[2,1.25,100]],"ltp":0.0,"tv":0.0,"id":40380900}]}]}
{"op":"mcm","clk":"11781667493","pt":1722373981738,"mc":[{"id":"1.231243109","rc":[{"batb":[[0,1.31,27.32],[1,1.3,16],[2,1.26,10]],"ltp":0.0,"tv":0.0,"id":40380900},{"batb":[[0,1.28,30.24],[1,1.27,18],[2,1.26,10]],"ltp":0.0,"tv":0.0,"id":40380901}]}]}
{"op":"mcm","clk":"11781677476","pt":1722374239438,"mc":[{"id":"1.231243109","rc":[{"batb":[[0,1.32,10],[1,1.31,27.32],[2,1.3,16]],"ltp":0.0,"tv":0.0,"id":40380900},{"batb":[[0,1.29,10],[1,1.28,30.24],[2,1.27,18]],"ltp":0.0,"tv":0.0,"id":40380901}]}]}
{"op":"mcm","clk":"11781745422","pt":1722375782220,"mc":[{"id":"1.231243109","rc":[{"batb":[[1,1.3,16],[2,1.25,100]],"ltp":0.0,"tv":0.0,"id":40380900},{"batb":[[1,1.27,18],[2,1.25,100]],"ltp":0.0,"tv":0.0,"id":40380901}]}]}
{"op":"mcm","clk":"11781751306","pt":1722375927299,"mc":[{"id":"1.231243109","rc":[{"batb":[[0,1.33,25.66],[1,1.32,10],[2,1.3,16]],"ltp":0.0,"tv":0.0,"id":40380900},{"batb":[[0,1.3,28.23],[1,1.29,10],[2,1.27,18]],"ltp":0.0,"tv":0.0,"id":40380901}]}]}
{"op":"mcm","clk":"11781784781","pt":1722377097844,"mc":[{"id":"1.231243109","rc":[{"batb":[[0,1.33,25.66]],"ltp":0.0,"tv":0.0,"id":40380900},{"trd":[[1.3,0.14]],"batb":[[0,1.3,28.16]],"ltp":1.3,"tv":0.14,"id":40380901}],"tv":0.14}]}
{"op":"mcm","clk":"11781804097","pt":1722377727874,"mc":[{"id":"1.231243109","rc":[{"batb":[[0,1.32,10],[1,1.3,16],[2,1.25,100]],"ltp":0.0,"tv":0.0,"id":40380900},{"batb":[[0,1.29,10],[1,1.27,18],[2,1.25,100]],"ltp":1.3,"tv":0.14,"id":40380901}]}]}
{"op":"mcm","clk":"11781804174","pt":1722377730084,"mc":[{"id":"1.231243109","rc":[{"batb":[[0,1.34,10]],"ltp":0.0,"tv":0.0,"id":40380900},{"batb":[[0,1.31,10]],"ltp":1.3,"tv":0.14,"id":40380901}]}]}
{"op":"mcm","clk":"11781810107","pt":1722377865575,"mc":[{"id":"1.231243109","rc":[{"batb":[[0,1.35,24.2],[1,1.34,10],[2,1.3,16]],"ltp":0.0,"tv":0.0,"id":40380900}]}]}
{"op":"mcm","clk":"11781872724","pt":1722379665845,"mc":[{"id":"1.231243109","rc":[{"batb":[[0,1.34,10],[1,1.3,16],[2,1.25,100]],"ltp":0.0,"tv":0.0,"id":40380900}]}]}
{"op":"mcm","clk":"11781877178","pt":1722379791598,"mc":[{"id":"1.231243109","rc":[{"batb":[[0,1.35,24.2],[1,1.34,10],[2,1.3,16]],"ltp":0.0,"tv":0.0,"id":40380900}]}]}
{"op":"mcm","clk":"11781939143","pt":1722381591840,"mc":[{"id":"1.231243109","rc":[{"batb":[[0,1.34,10],[1,1.3,16],[2,1.25,100]],"ltp":0.0,"tv":0.0,"id":40380900}]}]}
{"op":"mcm","clk":"11781943127","pt":1722381714474,"mc":[{"id":"1.231243109","rc":[{"batb":[[0,1.35,24.2],[1,1.34,10],[2,1.3,16]],"ltp":0.0,"tv":0.0,"id":40380900}]}]}
{"op":"mcm","clk":"11782006141","pt":1722383514750,"mc":[{"id":"1.231243109","rc":[{"batb":[[0,1.34,10],[1,1.3,16],[2,1.25,100]],"ltp":0.0,"tv":0.0,"id":40380900}]}]}
{"op":"mcm","clk":"11782009649","pt":1722383623378,"mc":[{"id":"1.231243109","rc":[{"batb":[[0,1.35,24.2],[1,1.34,10],[2,1.3,16]],"ltp":0.0,"tv":0.0,"id":40380900}]}]}
{"op":"mcm","clk":"11782086715","pt":1722385423587,"mc":[{"id":"1.231243109","rc":[{"batb":[[0,1.34,10],[1,1.3,16],[2,1.25,100]],"ltp":0.0,"tv":0.0,"id":40380900}]}]}
{"op":"mcm","clk":"11782091131","pt":1722385526292,"mc":[{"id":"1.231243109","rc":[{"batb":[[0,1.35,24.19],[1,1.34,10],[2,1.3,16]],"ltp":0.0,"tv":0.0,"id":40380900}]}]}
{"op":"mcm","clk":"11782188320","pt":1722387326567,"mc":[{"id":"1.231243109","rc":[{"batb":[[0,1.34,10],[1,1.3,16],[2,1.25,100]],"ltp":0.0,"tv":0.0,"id":40380900}]}]}
{"op":"mcm","clk":"11782193221","pt":1722387418683,"mc":[{"id":"1.231243109","rc":[{"batb":[[0,1.35,24.19],[1,1.34,10],[2,1.3,16]],"ltp":0.0,"tv":0.0,"id":40380900}]}]}
{"op":"mcm","clk":"11782286668","pt":1722389218927,"mc":[{"id":"1.231243109","rc":[{"batb":[[0,1.34,10],[1,1.3,16],[2,1.25,100]],"ltp":0.0,"tv":0.0,"id":40380900}]}]}
{"op":"mcm","clk":"11782291320","pt":1722389299548,"mc":[{"id":"1.231243109","rc":[{"batb":[[0,1.35,24.19],[1,1.34,10],[2,1.3,16]],"ltp":0.0,"tv":0.0,"id":40380900}]}]}
{"op":"mcm","clk":"11782387849","pt":1722391099797,"mc":[{"id":"1.231243109","rc":[{"batb":[[0,1.34,10],[1,1.3,16],[2,1.25,100]],"ltp":0.0,"tv":0.0,"id":40380900}]}]}
{"op":"mcm","clk":"11782391705","pt":1722391166173,"mc":[{"id":"1.231243109","rc":[{"batb":[[0,1.35,24.19],[1,1.34,10],[2,1.3,16]],"ltp":0.0,"tv":0.0,"id":40380900}]}]}
{"op":"mcm","clk":"11782434298","pt":1722391974779,"mc":[{"id":"1.231243109","rc":[{"batb":[[0,1.35,24.2]],"ltp":0.0,"tv":0.0,"id":40380900}]}]}
{"op":"mcm","clk":"11782494806","pt":1722392966333,"mc":[{"id":"1.231243109","rc":[{"batb":[[0,1.34,10],[1,1.3,16],[2,1.25,100]],"ltp":0.0,"tv":0.0,"id":40380900}]}]}
{"op":"mcm","clk":"11782497025","pt":1722393012122,"mc":[{"id":"1.231243109","rc":[{"batb":[[0,1.35,24.2],[1,1.34,10],[2,1.3,16]],"ltp":0.0,"tv":0.0,"id":40380900}]}]}
{"op":"mcm","clk":"11782568058","pt":1722394812442,"mc":[{"id":"1.231243109","rc":[{"batb":[[0,1.34,10],[1,1.3,16],[2,1.25,100]],"ltp":0.0,"tv":0.0,"id":40380900}]}]}
{"op":"mcm","clk":"11782568711","pt":1722394824863,"mc":[{"id":"1.231243109","rc":[{"batb":[[0,1.35,24.2],[1,1.34,10],[2,1.3,16]],"ltp":0.0,"tv":0.0,"id":40380900}]}]}
{"op":"mcm","clk":"11782632553","pt":1722396625033,"mc":[{"id":"1.231243109","rc":[{"batb":[[0,1.34,10],[1,1.3,16],[2,1.25,100]],"ltp":0.0,"tv":0.0,"id":40380900}]}]}
{"op":"mcm","clk":"11782632595","pt":1722396626159,"mc":[{"id":"1.231243109","rc":[{"batb":[[0,1.35,24.2],[1,1.34,10],[2,1.3,16]],"ltp":0.0,"tv":0.0,"id":40380900}]}]}
{"op":"mcm","clk":"11782697744","pt":1722398426389,"mc":[{"id":"1.231243109","rc":[{"batb":[[0,1.34,10],[1,1.3,16],[2,1.25,100]],"ltp":0.0,"tv":0.0,"id":40380900}]}]}
{"op":"mcm","clk":"11782703566","pt":1722398557748,"mc":[{"id":"1.231243109","rc":[{"batb":[[0,1.35,24.2],[1,1.34,10],[2,1.3,16]],"ltp":0.0,"tv":0.0,"id":40380900}]}]}
{"op":"mcm","clk":"11782772202","pt":1722400357921,"mc":[{"id":"1.231243109","rc":[{"batb":[[0,1.34,10],[1,1.3,16],[2,1.25,100]],"ltp":0.0,"tv":0.0,"id":40380900}]}]}
{"op":"mcm","clk":"11782777005","pt":1722400483169,"mc":[{"id":"1.231243109","rc":[{"batb":[[0,1.35,24.2],[1,1.34,10],[2,1.3,16]],"ltp":0.0,"tv":0.0,"id":40380900}]}]}
{"op":"mcm","clk":"11782852915","pt":1722402283421,"mc":[{"id":"1.231243109","rc":[{"batb":[[0,1.34,10],[1,1.3,16],[2,1.25,100]],"ltp":0.0,"tv":0.0,"id":40380900}]}]}
{"op":"mcm","clk":"11782858724","pt":1722402408971,"mc":[{"id":"1.231243109","rc":[{"batb":[[0,1.35,24.2],[1,1.34,10],[2,1.3,16]],"ltp":0.0,"tv":0.0,"id":40380900}]}]}
{"op":"mcm","clk":"11782949601","pt":1722404209231,"mc":[{"id":"1.231243109","rc":[{"batb":[[0,1.34,10],[1,1.3,16],[2,1.25,100]],"ltp":0.0,"tv":0.0,"id":40380900}]}]}
{"op":"mcm","clk":"11782953413","pt":1722404314640,"mc":[{"id":"1.231243109","rc":[{"batb":[[0,1.35,24.2],[1,1.34,10],[2,1.3,16]],"ltp":0.0,"tv":0.0,"id":40380900}]}]}
{"op":"mcm","clk":"11782974699","pt":1722404843614,"mc":[{"id":"1.231243109","rc":[{"batb":[[0,1.36,16],[1,1.35,24.2],[2,1.34,10]],"ltp":0.0,"tv":0.0,"id":40380900},{"batb":[[0,1.32,18],[1,1.31,10]],"ltp":1.3,"tv":0.14,"id":40380901}]}]}
{"op":"mcm","clk":"11783034419","pt":1722406114898,"mc":[{"id":"1.231243109","rc":[{"batb":[[1,1.34,10],[2,1.25,100]],"ltp":0.0,"tv":0.0,"id":40380900}]}]}
{"op":"mcm","clk":"11783038425","pt":1722406210112,"mc":[{"id":"1.231243109","rc":[{"batb":[[0,1.37,22.89],[1,1.36,16],[2,1.34,10]],"ltp":0.0,"tv":0.0,"id":40380900}]}]}
{"op":"mcm","clk":"11783121260","pt":1722408010390,"mc":[{"id":"1.231243109","rc":[{"batb":[[0,1.36,16],[1,1.34,10],[2,1.25,100]],"ltp":0.0,"tv":0.0,"id":40380900}]}]}
{"op":"mcm","clk":"11783125788","pt":1722408106695,"mc":[{"id":"1.231243109","rc":[{"batb":[[0,1.37,22.89],[1,1.36,16],[2,1.34,10]],"ltp":0.0,"tv":0.0,"id":40380900}]}]}
{"op":"mcm","clk":"11783190154","pt":1722409514582,"mc":[{"id":"1.231243109","rc":[{"batb":[[0,1.38,10],[1,1.37,22.9],[2,1.36,16]],"ltp":0.0,"tv":0.0,"id":40380900},{"batb":[[0,1.38,10],[1,1.32,18]],"ltp":1.3,"tv":0.14,"id":40380901}]}]}
{"op":"mcm","clk":"11783206328","pt":1722409906820,"mc":[{"id":"1.231243109","rc":[{"batb":[[1,1.36,16],[2,1.25,100]],"ltp":0.0,"tv":0.0,"id":40380900}]}]}
{"op":"mcm","clk":"11783209939","pt":1722410002552,"mc":[{"id":"1.231243109","rc":[{"batb":[[0,1.39,21.73],[1,1.38,10],[2,1.36,16]],"ltp":0.0,"tv":0.0,"id":40380900}]}]}
{"op":"mcm","clk":"11783259333","pt":1722411278762,"mc":[{"id":"1.231243109","rc":[{"batb":[[1,1.35,69.92],[2,1.32,18]],"ltp":1.3,"tv":0.14,"id":40380901}]}]}
{"op":"mcm","clk":"11783267763","pt":1722411523945,"mc":[{"id":"1.231243109","rc":[{"batb":[[2,1.36,22.97]],"ltp":0.0,"tv":0.0,"id":40380900},{"batb":[[1,1.36,6.47],[2,1.35,69.92]],"ltp":1.3,"tv":0.14,"id":40380901}]}]}
{"op":"mcm","clk":"11783277837","pt":1722411802742,"mc":[{"id":"1.231243109","rc":[{"batb":[[0,1.38,10],[1,1.36,22.97],[2,1.35,69.92]],"ltp":0.0,"tv":0.0,"id":40380900}]}]}
{"op":"mcm","clk":"11783281313","pt":1722411901668,"mc":[{"id":"1.231243109","rc":[{"batb":[[0,1.39,21.73],[1,1.38,10],[2,1.36,22.97]],"ltp":0.0,"tv":0.0,"id":40380900}]}]}
{"op":"mcm","clk":"11783347173","pt":1722413574781,"mc":[{"id":"1.231243109","rc":[{"batb":[[0,1.39,21.71],[2,1.36,22.97]],"ltp":0.0,"tv":0.0,"id":40380900},{"batb":[[1,1.36,6.47],[2,1.35,69.9]],"ltp":1.3,"tv":0.13,"id":40380901}]}]}
{"op":"mcm","clk":"11783359860","pt":1722413701842,"mc":[{"id":"1.231243109","rc":[{"batb":[[0,1.38,10],[1,1.36,22.97],[2,1.35,69.9]],"ltp":0.0,"tv":0.0,"id":40380900}]}]}
{"op":"mcm","clk":"11783364468","pt":1722413799725,"mc":[{"id":"1.231243109","rc":[{"batb":[[0,1.39,21.71],[1,1.38,10],[2,1.36,22.97]],"ltp":0.0,"tv":0.0,"id":40380900}]}]}
{"op":"mcm","clk":"11783417162","pt":1722415081656,"mc":[{"id":"1.231243109","rc":[{"batb":[[0,1.4,10],[1,1.39,21.71]],"ltp":0.0,"tv":0.0,"id":40380900}]}]}
{"op":"mcm","clk":"11783434534","pt":1722415508947,"mc":[{"id":"1.231243109","rc":[{"trd":[[1.4,0.14]],"batb":[[0,1.4,9.93]],"ltp":1.4,"tv":0.14,"id":40380900}],"tv":0.27}]}
{"op":"mcm","clk":"11783437465","pt":1722415592220,"mc":[{"id":"1.231243109","rc":[{"batb":[[0,1.36,6.47],[1,1.35,69.9],[2,1.32,18]],"ltp":1.3,"tv":0.13,"id":40380901}]}]}
{"op":"mcm","clk":"11783437471","pt":1722415592326,"mc":[{"id":"1.231243109","rc":[{"batb":[[0,1.37,10],[1,1.36,6.47],[2,1.35,69.9]],"ltp":1.3,"tv":0.13,"id":40380901}]}]}
{"op":"mcm","clk":"11783437753","pt":1722415599970,"mc":[{"id":"1.231243109","rc":[{"batb":[[1,1.36,22.97],[2,1.35,69.9]],"ltp":1.4,"tv":0.14,"id":40380900}]}]}
{"op":"mcm","clk":"11783441367","pt":1722415696697,"mc":[{"id":"1.231243109","rc":[{"batb":[[0,1.41,20.65],[1,1.4,9.93],[2,1.36,22.97]],"ltp":1.4,"tv":0.14,"id":40380900}]}]}
{"op":"mcm","clk":"11783462708","pt":1722416174185,"mc":[{"id":"1.231243109","rc":[{"batb":[[1,1.36,22.97],[2,1.35,69.9]],"ltp":1.4,"tv":0.14,"id":40380900}]}]}
{"op":"mcm","clk":"11783462715","pt":1722416174288,"mc":[{"id":"1.231243109","rc":[{"batb":[[0,1.42,9.93],[1,1.41,20.65],[2,1.36,22.97]],"ltp":1.4,"tv":0.14,"id":40380900}]}]}
{"op":"mcm","clk":"11783516314","pt":1722417496810,"mc":[{"id":"1.231243109","rc":[{"batb":[[1,1.36,22.98],[2,1.35,69.97]],"ltp":1.4,"tv":0.14,"id":40380900},{"batb":[[1,1.36,6.48],[2,1.35,69.97]],"ltp":1.3,"tv":0.14,"id":40380901}]}]}
{"op":"mcm","clk":"11783520035","pt":1722417591620,"mc":[{"id":"1.231243109","rc":[{"batb":[[0,1.43,19.72],[1,1.42,9.93],[2,1.36,22.98]],"ltp":1.4,"tv":0.14,"id":40380900}]}]}
{"op":"mcm","clk":"11783556880","pt":1722418343550,"mc":[{"id":"1.231243109","rc":[{"batb":[[0,1.44,9.93],[1,1.43,19.72]],"ltp":1.4,"tv":0.14,"id":40380900}]}]}
{"op":"mcm","clk":"11783613611","pt":1722419391858,"mc":[{"id":"1.231243109","rc":[{"batb":[[1,1.36,22.98],[2,1.35,69.97]],"ltp":1.4,"tv":0.14,"id":40380900}]}]}
{"op":"mcm","clk":"11783617169","pt":1722419473985,"mc":[{"id":"1.231243109","rc":[{"batb":[[0,1.45,18.84],[1,1.44,9.93],[2,1.36,22.98]],"ltp":1.4,"tv":0.14,"id":40380900}]}]}
{"op":"mcm","clk":"11783626364","pt":1722419672008,"mc":[{"id":"1.231243109","rc":[{"batb":[[0,1.46,9.93],[1,1.45,18.84]],"ltp":1.4,"tv":0.14,"id":40380900}]}]}
{"op":"mcm","clk":"11783721061","pt":1722421274142,"mc":[{"id":"1.231243109","rc":[{"batb":[[1,1.36,22.98],[2,1.35,69.96]],"ltp":1.4,"tv":0.14,"id":40380900},{"batb":[[1,1.36,6.48],[2,1.35,69.96]],"ltp":1.3,"tv":0.14,"id":40380901}]}]}
{"op":"mcm","clk":"11783725733","pt":1722421348953,"mc":[{"id":"1.231243109","rc":[{"batb":[[0,1.47,18.04],[1,1.46,9.93],[2,1.36,22.98]],"ltp":1.4,"tv":0.14,"id":40380900}]}]}
{"op":"mcm","clk":"11783753662","pt":1722421804220,"mc":[{"id":"1.231243109","rc":[{"batb":[[1,1.36,22.98],[2,1.35,69.96]],"ltp":1.4,"tv":0.14,"id":40380900}]}]}
{"op":"mcm","clk":"11783753669","pt":1722421804322,"mc":[{"id":"1.231243109","rc":[{"batb":[[0,1.48,9.93],[1,1.47,18.04],[2,1.36,22.98]],"ltp":1.4,"tv":0.14,"id":40380900}]}]}
{"op":"mcm","clk":"11783842946","pt":1722423149085,"mc":[{"id":"1.231243109","rc":[{"batb":[[1,1.36,22.98],[2,1.35,69.96]],"ltp":1.4,"tv":0.14,"id":40380900}]}]}
{"op":"mcm","clk":"11783847338","pt":1722423207361,"mc":[{"id":"1.231243109","rc":[{"batb":[[0,1.49,17.3],[1,1.48,9.93],[2,1.36,22.98]],"ltp":1.4,"tv":0.14,"id":40380900}]}]}
{"op":"mcm","clk":"11783888552","pt":1722423901059,"mc":[{"id":"1.231243109","rc":[{"batb":[[0,1.5,9.93],[1,1.49,17.31],[2,1.36,22.97]],"ltp":1.4,"tv":0.14,"id":40380900},{"batb":[[1,1.36,6.47],[2,1.35,69.92]],"ltp":1.3,"tv":0.14,"id":40380901}]}]}
{"op":"mcm","clk":"11783963238","pt":1722425007436,"mc":[{"id":"1.231243109","rc":[{"batb":[[1,1.36,22.97],[2,1.35,69.92]],"ltp":1.4,"tv":0.14,"id":40380900}]}]}
{"op":"mcm","clk":"11783965809","pt":1722425053782,"mc":[{"id":"1.231243109","rc":[{"batb":[[0,1.51,16.63],[1,1.5,9.93],[2,1.36,22.97]],"ltp":1.4,"tv":0.14,"id":40380900}]}]}
{"op":"mcm","clk":"11784000151","pt":1722425594027,"mc":[{"id":"1.231243109","rc":[{"batb":[[0,1.52,9.93],[1,1.51,16.63]],"ltp":1.4,"tv":0.14,"id":40380900}]}]}
{"op":"mcm","clk":"11784077859","pt":1722426853923,"mc":[{"id":"1.231243109","rc":[{"batb":[[1,1.36,22.97],[2,1.35,69.92]],"ltp":1.4,"tv":0.14,"id":40380900}]}]}
{"op":"mcm","clk":"11784078405","pt":1722426864153,"mc":[{"id":"1.231243109","rc":[{"batb":[[0,1.53,16],[1,1.52,9.93],[2,1.36,22.97]],"ltp":1.4,"tv":0.14,"id":40380900}]}]}
{"op":"mcm","clk":"11784207296","pt":1722428664346,"mc":[{"id":"1.231243109","rc":[{"batb":[[0,1.52,9.93],[1,1.36,22.97],[2,1.35,69.92]],"ltp":1.4,"tv":0.14,"id":40380900},{"batb":[[2,1.35,69.92]],"ltp":1.3,"tv":0.14,"id":40380901}]}]}
{"op":"mcm","clk":"11784217888","pt":1722428784267,"mc":[{"id":"1.231243109","rc":[{"batb":[[0,1.53,16],[1,1.52,9.93],[2,1.36,22.97]],"ltp":1.4,"tv":0.14,"id":40380900}]}]}
{"op":"mcm","clk":"11784281850","pt":1722429514995,"mc":[{"id":"1.231243109","rc":[{"batb":[[0,1.54,9.93],[1,1.53,16]],"ltp":1.4,"tv":0.14,"id":40380900}]}]}
{"op":"mcm","clk":"11784387934","pt":1722430584572,"mc":[{"id":"1.231243109","rc":[{"batb":[[1,1.36,22.97],[2,1.35,69.92]],"ltp":1.4,"tv":0.14,"id":40380900}]}]}
{"op":"mcm","clk":"11784396343","pt":1722430684162,"mc":[{"id":"1.231243109","rc":[{"batb":[[0,1.55,15.41],[1,1.54,9.93],[2,1.36,22.97]],"ltp":1.4,"tv":0.14,"id":40380900}]}]}
{"op":"mcm","clk":"11784422214","pt":1722430978825,"mc":[{"id":"1.231243109","rc":[{"batb":[[0,1.55,15.42],[2,1.36,22.97]],"ltp":1.4,"tv":0.14,"id":40380900},{"batb":[[1,1.36,6.47],[2,1.35,69.88]],"ltp":1.3,"tv":0.14,"id":40380901}]}]}
{"op":"mcm","clk":"11784424219","pt":1722431002160,"mc":[{"id":"1.231243109","rc":[{"batb":[[2,1.36,16]],"ltp":1.4,"tv":0.14,"id":40380900},{"batb":[[1,1.35,69.88],[2,1.32,18]],"ltp":1.3,"tv":0.14,"id":40380901}]}]}
{"op":"mcm","clk":"11784546066","pt":1722432484345,"mc":[{"id":"1.231243109","rc":[{"batb":[[0,1.54,9.93],[1,1.36,16],[2,1.35,69.88]],"ltp":1.4,"tv":0.14,"id":40380900}]}]}
{"op":"mcm","clk":"11784553217","pt":1722432563905,"mc":[{"id":"1.231243109","rc":[{"batb":[[0,1.55,15.42],[1,1.54,9.93],[2,1.36,16]],"ltp":1.4,"tv":0.14,"id":40380900}]}]}
{"op":"mcm","clk":"11784706013","pt":1722434364104,"mc":[{"id":"1.231243109","rc":[{"batb":[[0,1.54,9.93],[1,1.36,16],[2,1.35,69.88]],"ltp":1.4,"tv":0.14,"id":40380900}]}]}
{"op":"mcm","clk":"11784710525","pt":1722434414529,"mc":[{"id":"1.231243109","rc":[{"batb":[[0,1.55,15.43],[1,1.54,9.93],[2,1.36,16]],"ltp":1.4,"tv":0.14,"id":40380900},{"batb":[[1,1.35,69.91]],"ltp":1.3,"tv":0.14,"id":40380901}]}]}
{"op":"mcm","clk":"11784856230","pt":1722436214675,"mc":[{"id":"1.231243109","rc":[{"batb":[[0,1.54,9.93],[1,1.36,16],[2,1.35,69.91]],"ltp":1.4,"tv":0.14,"id":40380900}]}]}
{"op":"mcm","clk":"11784858594","pt":1722436245219,"mc":[{"id":"1.231243109","rc":[{"batb":[[0,1.55,15.43],[1,1.54,9.93],[2,1.36,16]],"ltp":1.4,"tv":0.14,"id":40380900}]}]}
{"op":"mcm","clk":"11785021983","pt":1722437985401,"mc":[{"id":"1.231243109","rc":[{"batb":[[0,1.56,9.93],[1,1.55,15.43]],"ltp":1.4,"tv":0.14,"id":40380900}]}]}
{"op":"mcm","clk":"11785028996","pt":1722438045454,"mc":[{"id":"1.231243109","rc":[{"batb":[[1,1.36,16],[2,1.35,69.9]],"ltp":1.4,"tv":0.14,"id":40380900},{"batb":[[1,1.35,69.9]],"ltp":1.3,"tv":0.13,"id":40380901}]}]}
{"op":"mcm","clk":"11785030645","pt":1722438059695,"mc":[{"id":"1.231243109","rc":[{"batb":[[0,1.57,14.85],[1,1.56,9.93],[2,1.36,16]],"ltp":1.4,"tv":0.14,"id":40380900}]}]}
{"op":"mcm","clk":"11785154554","pt":1722439185001,"mc":[{"id":"1.231243109","rc":[{"batb":[[0,1.58,16],[1,1.57,14.85],[2,1.56,9.93]],"ltp":1.4,"tv":0.14,"id":40380900},{"batb":[[0,1.38,18],[1,1.37,10],[2,1.35,69.9]],"ltp":1.3,"tv":0.13,"id":40380901}]}]}
{"op":"mcm","clk":"11785213094","pt":1722439859978,"mc":[{"id":"1.231243109","rc":[{"batb":[[1,1.56,9.93],[2,1.35,69.9]],"ltp":1.4,"tv":0.14,"id":40380900}]}]}
{"op":"mcm","clk":"11785223844","pt":1722439977201,"mc":[{"id":"1.231243109","rc":[{"batb":[[0,1.59,14.35],[1,1.58,16],[2,1.56,9.93]],"ltp":1.4,"tv":0.14,"id":40380900}]}]}
{"op":"mcm","clk":"11785415429","pt":1722441777497,"mc":[{"id":"1.231243109","rc":[{"batb":[[0,1.58,16],[1,1.56,9.93],[2,1.35,69.91]],"ltp":1.4,"tv":0.14,"id":40380900},{"batb":[[2,1.35,69.91]],"ltp":1.3,"tv":0.13,"id":40380901}]}]}
{"op":"mcm","clk":"11785425914","pt":1722441865965,"mc":[{"id":"1.231243109","rc":[{"batb":[[0,1.59,14.36],[1,1.58,16],[2,1.56,9.93]],"ltp":1.4,"tv":0.14,"id":40380900}]}]}
{"op":"mcm","clk":"11785435294","pt":1722441949683,"mc":[{"id":"1.231243109","rc":[{"batb":[[0,1.6,9.93],[1,1.59,14.36],[2,1.58,16]],"ltp":1.4,"tv":0.14,"id":40380900},{"batb":[[0,1.39,10],[1,1.38,18]],"ltp":1.3,"tv":0.13,"id":40380901}]}]}
{"op":"mcm","clk":"11785652285","pt":1722443666162,"mc":[{"id":"1.231243109","rc":[{"batb":[[1,1.58,16],[2,1.35,69.91]],"ltp":1.4,"tv":0.14,"id":40380900}]}]}
{"op":"mcm","clk":"11785660906","pt":1722443716394,"mc":[{"id":"1.231243109","rc":[{"batb":[[0,1.61,13.89],[1,1.6,9.93],[2,1.58,16]],"ltp":1.4,"tv":0.14,"id":40380900}]}]}
{"op":"mcm","clk":"11785895093","pt":1722445344498,"mc":[{"id":"1.231243109","rc":[{"batb":[[0,1.62,9.93],[1,1.61,13.87]],"ltp":1.4,"tv":0.14,"id":40380900},{"batb":[[2,1.35,69.93]],"ltp":1.3,"tv":0.13,"id":40380901}]}]}
{"op":"mcm","clk":"11785923029","pt":1722445516598,"mc":[{"id":"1.231243109","rc":[{"batb":[[1,1.58,16],[2,1.35,69.93]],"ltp":1.4,"tv":0.14,"id":40380900}]}]}
{"op":"mcm","clk":"11785939950","pt":1722445618796,"mc":[{"id":"1.231243109","rc":[{"batb":[[0,1.63,13.43],[1,1.62,9.93],[2,1.58,16]],"ltp":1.4,"tv":0.14,"id":40380900}]}]}
{"op":"mcm","clk":"11786155657","pt":1722446910607,"mc":[{"id":"1.231243109","rc":[{"batb":[[0,1.4,60],[1,1.39,10],[2,1.38,18]],"ltp":1.3,"tv":0.13,"id":40380901}]}]}
{"op":"mcm","clk":"11786240347","pt":1722447419041,"mc":[{"id":"1.231243109","rc":[{"batb":[[0,1.62,9.93],[1,1.58,16],[2,1.4,60]],"ltp":1.4,"tv":0.14,"id":40380900}]}]}
{"op":"mcm","clk":"11786243929","pt":1722447440074,"mc":[{"id":"1.231243109","rc":[{"batb":[[0,1.63,13.43],[1,1.62,9.93],[2,1.58,16]],"ltp":1.4,"tv":0.14,"id":40380900}]}]}
{"op":"mcm","clk":"11786246475","pt":1722447455605,"mc":[{"id":"1.231243109","rc":[{"batb":[[0,1.41,6.58],[1,1.4,60],[2,1.39,10]],"ltp":1.3,"tv":0.13,"id":40380901}]}]}
{"op":"mcm","clk":"11786500950","pt":1722449240355,"mc":[{"id":"1.231243109","rc":[{"batb":[[0,1.62,9.93],[1,1.58,16],[2,1.41,7.16]],"ltp":1.4,"tv":0.14,"id":40380900}]}]}
{"op":"mcm","clk":"11786513008","pt":1722449317406,"mc":[{"id":"1.231243109","rc":[{"batb":[[0,1.63,13.44],[1,1.62,9.93],[2,1.58,16]],"ltp":1.4,"tv":0.14,"id":40380900}]}]}
{"op":"mcm","clk":"11786774405","pt":1722451117668,"mc":[{"id":"1.231243109","rc":[{"batb":[[0,1.62,9.93],[1,1.58,16],[2,1.41,7.16]],"ltp":1.4,"tv":0.14,"id":40380900}]}]}
{"op":"mcm","clk":"11786779102","pt":1722451150309,"mc":[{"id":"1.231243109","rc":[{"batb":[[0,1.63,13.44],[1,1.62,9.93],[2,1.58,16]],"ltp":1.4,"tv":0.14,"id":40380900}]}]}
{"op":"mcm","clk":"11786989443","pt":1722452950591,"mc":[{"id":"1.231243109","rc":[{"batb":[[0,1.62,9.93],[1,1.58,16],[2,1.41,7.15]],"ltp":1.4,"tv":0.14,"id":40380900},{"batb":[[0,1.41,6.57]],"ltp":1.3,"tv":0.14,"id":40380901}]}]}
{"op":"mcm","clk":"11786995851","pt":1722453008665,"mc":[{"id":"1.231243109","rc":[{"batb":[[0,1.63,13.44],[1,1.62,9.93],[2,1.58,16]],"ltp":1.4,"tv":0.14,"id":40380900}]}]}
{"op":"mcm","clk":"11787010840","pt":1722453156812,"mc":[{"id":"1.231243109","rc":[{"batl":[[0,5,0.78]],"ltp":1.4,"tv":0.14,"id":40380900},{"batl":[[0,5,0.78]],"ltp":1.3,"tv":0.14,"id":40380901}]}]}
{"op":"mcm","clk":"11787011809","pt":1722453165618,"mc":[{"id":"1.231243109","rc":[{"batl":[[0,6,1.56]],"ltp":1.4,"tv":0.14,"id":40380900},{"batl":[[0,6,1.56]],"ltp":1.3,"tv":0.14,"id":40380901}]}]}
{"op":"mcm","clk":"11787012762","pt":1722453173929,"mc":[{"id":"1.231243109","rc":[{"batl":[[1,7,0.78]],"ltp":1.4,"tv":0.14,"id":40380900},{"batl":[[1,7,0.78]],"ltp":1.3,"tv":0.14,"id":40380901}]}]}
{"op":"mcm","clk":"11787026253","pt":1722453298180,"mc":[{"id":"1.231243109","rc":[{"batb":[[0,1.64,9.93],[1,1.63,13.44]],"ltp":1.4,"tv":0.14,"id":40380900},{"batb":[[0,1.42,10],[1,1.41,6.57],[2,1.4,60]],"ltp":1.3,"tv":0.14,"id":40380901}]}]}
{"op":"mcm","clk":"11787171392","pt":1722454808906,"mc":[{"id":"1.231243109","rc":[{"batb":[[1,1.58,16],[2,1.41,7.15]],"ltp":1.4,"tv":0.14,"id":40380900}]}]}
{"op":"mcm","clk":"11787177542","pt":1722454875970,"mc":[{"id":"1.231243109","rc":[{"batb":[[0,1.65,13.02],[1,1.64,9.93],[2,1.58,16]],"ltp":1.4,"tv":0.14,"id":40380900}]}]}
{"op":"mcm","clk":"11787259748","pt":1722455874262,"mc":[{"id":"1.231243109","rc":[{"batb":[[0,1.66,9.93],[1,1.65,13.02]],"ltp":1.4,"tv":0.14,"id":40380900}]}]}
{"op":"mcm","clk":"11787270126","pt":1722456019526,"mc":[{"id":"1.231243109","rc":[{"batb":[[1,1.65,13.02]],"ltp":1.4,"tv":0.14,"id":40380900},{"batb":[[1,1.41,6.57]],"ltp":1.3,"tv":0.14,"id":40380901}]}]}
{"op":"mcm","clk":"11787318712","pt":1722456676264,"mc":[{"id":"1.231243109","rc":[{"batb":[[1,1.58,16],[2,1.41,7.15]],"ltp":1.4,"tv":0.14,"id":40380900}]}]}
{"op":"mcm","clk":"11787319205","pt":1722456682772,"mc":[{"id":"1.231243109","rc":[{"batb":[[0,1.67,12.63],[1,1.66,9.93],[2,1.58,16]],"ltp":1.4,"tv":0.14,"id":40380900}]}]}
{"op":"mcm","clk":"11787320149","pt":1722456698565,"mc":[{"id":"1.231243109","rc":[{"batb":[[0,1.68,9.93],[1,1.67,12.63]],"ltp":1.4,"tv":0.14,"id":40380900}]}]}
{"op":"mcm","clk":"11787429119","pt":1722458395549,"mc":[{"id":"1.231243109","rc":[{"batl":[[0,1.61,1.56],[1,6,1.56],[2,7,0.78]],"ltp":1.3,"tv":0.13,"id":40380901}]}]}
{"op":"mcm","clk":"11787429410","pt":1722458401177,"mc":[{"id":"1.231243109","rc":[{"batl":[[0,6,1.56],[1,7,0.78],[2,7,0]],"ltp":1.3,"tv":0.13,"id":40380901}]}]}
{"op":"mcm","clk":"11787434569","pt":1722458482960,"mc":[{"id":"1.231243109","rc":[{"batb":[[1,1.58,16],[2,1.41,7.15]],"ltp":1.4,"tv":0.14,"id":40380900}]}]}
{"op":"mcm","clk":"11787435213","pt":1722458494069,"mc":[{"id":"1.231243109","rc":[{"batb":[[0,1.69,12.26],[1,1.68,9.93],[2,1.58,16]],"ltp":1.4,"tv":0.14,"id":40380900}]}]}
{"op":"mcm","clk":"11787494014","pt":1722459805460,"mc":[{"id":"1.231243109","rc":[{"batb":[[0,1.72,9.93],[1,1.69,12.27]],"ltp":1.4,"tv":0.14,"id":40380900}]}]}
{"op":"mcm","clk":"11787515477","pt":1722460294348,"mc":[{"id":"1.231243109","rc":[{"batb":[[1,1.58,16],[2,1.41,7.15]],"ltp":1.4,"tv":0.14,"id":40380900}]}]}
{"op":"mcm","clk":"11787516890","pt":1722460321374,"mc":[{"id":"1.231243109","rc":[{"batb":[[0,1.73,11.59],[1,1.72,9.93],[2,1.58,16]],"ltp":1.4,"tv":0.14,"id":40380900}]}]}
{"op":"mcm","clk":"11787551249","pt":1722461083171,"mc":[{"id":"1.231243109","rc":[{"batb":[[0,1.74,9.93],[1,1.73,11.59]],"ltp":1.4,"tv":0.14,"id":40380900}]}]}
{"op":"mcm","clk":"11787602863","pt":1722462121613,"mc":[{"id":"1.231243109","rc":[{"batb":[[1,1.58,16],[2,1.41,7.15]],"ltp":1.4,"tv":0.14,"id":40380900}]}]}
{"op":"mcm","clk":"11787613625","pt":1722462183746,"mc":[{"id":"1.231243109","rc":[{"batb":[[0,1.75,11.28],[1,1.74,9.93],[2,1.58,16]],"ltp":1.4,"tv":0.14,"id":40380900}]}]}
{"op":"mcm","clk":"11787617557","pt":1722462260434,"mc":[{"id":"1.231243109","rc":[{"batb":[[0,1.76,9.93],[1,1.75,11.28]],"ltp":1.4,"tv":0.14,"id":40380900}]}]}
{"op":"mcm","clk":"11787696500","pt":1722463983924,"mc":[{"id":"1.231243109","rc":[{"batb":[[1,1.58,16],[2,1.41,7.15]],"ltp":1.4,"tv":0.14,"id":40380900},{"batb":[[1,1.41,6.56]],"ltp":1.3,"tv":0.13,"id":40380901}]}]}
{"op":"mcm","clk":"11787699455","pt":1722464039583,"mc":[{"id":"1.231243109","rc":[{"batb":[[0,1.77,10.99],[1,1.76,9.93],[2,1.58,16]],"ltp":1.4,"tv":0.14,"id":40380900}]}]}
{"op":"mcm","clk":"11787807385","pt":1722465839934,"mc":[{"id":"1.231243109","rc":[{"batb":[[0,1.76,9.93],[1,1.58,16],[2,1.41,7.15]],"ltp":1.4,"tv":0.14,"id":40380900}]}]}
{"op":"mcm","clk":"11787809845","pt":1722465880896,"mc":[{"id":"1.231243109","rc":[{"batb":[[0,1.77,10.99],[1,1.76,9.93],[2,1.58,16]],"ltp":1.4,"tv":0.14,"id":40380900}]}]}
{"op":"mcm","clk":"11787901822","pt":1722467574795,"mc":[{"id":"1.231243109","rc":[{"batb":[[0,1.77,10.99]],"ltp":1.4,"tv":0.14,"id":40380900},{"batb":[[1,1.41,6.56]],"ltp":1.3,"tv":0.13,"id":40380901}]}]}
{"op":"mcm","clk":"11787914670","pt":1722467681175,"mc":[{"id":"1.231243109","rc":[{"batb":[[0,1.76,9.93],[1,1.58,16],[2,1.41,7.15]],"ltp":1.4,"tv":0.14,"id":40380900}]}]}
{"op":"mcm","clk":"11787916819","pt":1722467718517,"mc":[{"id":"1.231243109","rc":[{"batb":[[0,1.77,10.99],[1,1.76,9.93],[2,1.58,16]],"ltp":1.4,"tv":0.14,"id":40380900}]}]}
{"op":"mcm","clk":"11788021504","pt":1722469518709,"mc":[{"id":"1.231243109","rc":[{"batb":[[0,1.76,9.93],[1,1.58,16],[2,1.41,7.15]],"ltp":1.4,"tv":0.14,"id":40380900}]}]}
{"op":"mcm","clk":"11788023109","pt":1722469546352,"mc":[{"id":"1.231243109","rc":[{"batb":[[0,1.77,10.99],[1,1.76,9.93],[2,1.58,16]],"ltp":1.4,"tv":0.14,"id":40380900}]}]}
{"op":"mcm","clk":"11788126423","pt":1722471346489,"mc":[{"id":"1.231243109","rc":[{"batb":[[0,1.76,9.93],[1,1.58,16],[2,1.41,7.15]],"ltp":1.4,"tv":0.14,"id":40380900},{"batb":[[1,1.41,6.57]],"ltp":1.3,"tv":0.13,"id":40380901}]}]}
{"op":"mcm","clk":"11788126831","pt":1722471352317,"mc":[{"id":"1.231243109","rc":[{"batb":[[0,1.77,10.99],[1,1.76,9.93],[2,1.58,16]],"ltp":1.4,"tv":0.14,"id":40380900}]}]}
{"op":"mcm","clk":"11788258857","pt":1722473152601,"mc":[{"id":"1.231243109","rc":[{"batb":[[0,1.76,9.93],[1,1.58,16],[2,1.41,7.15]],"ltp":1.4,"tv":0.14,"id":40380900}]}]}
{"op":"mcm","clk":"11788262366","pt":1722473205632,"mc":[{"id":"1.231243109","rc":[{"batb":[[0,1.77,10.99],[1,1.76,9.93],[2,1.58,16]],"ltp":1.4,"tv":0.14,"id":40380900}]}]}
{"op":"mcm","clk":"11788394979","pt":1722475005891,"mc":[{"id":"1.231243109","rc":[{"batb":[[0,1.76,9.93],[1,1.58,16],[2,1.41,7.15]],"ltp":1.4,"tv":0.14,"id":40380900}]}]}
{"op":"mcm","clk":"11788398915","pt":1722475054653,"mc":[{"id":"1.231243109","rc":[{"batb":[[0,1.77,10.99],[1,1.76,9.93],[2,1.58,16]],"ltp":1.4,"tv":0.14,"id":40380900}]}]}
{"op":"mcm","clk":"11788542618","pt":1722476854797,"mc":[{"id":"1.231243109","rc":[{"batb":[[0,1.76,9.93],[1,1.58,16],[2,1.41,7.15]],"ltp":1.4,"tv":0.14,"id":40380900}]}]}
{"op":"mcm","clk":"11788545587","pt":1722476888120,"mc":[{"id":"1.231243109","rc":[{"batb":[[0,1.77,10.99],[1,1.76,9.93],[2,1.58,16]],"ltp":1.4,"tv":0.14,"id":40380900}]}]}
{"op":"mcm","clk":"11788655959","pt":1722478374811,"mc":[{"id":"1.231243109","rc":[{"batb":[[0,1.77,10.99]],"ltp":1.4,"tv":0.14,"id":40380900}]}]}
{"op":"mcm","clk":"11788680289","pt":1722478688325,"mc":[{"id":"1.231243109","rc":[{"batb":[[0,1.76,9.93],[1,1.58,16],[2,1.41,7.15]],"ltp":1.4,"tv":0.14,"id":40380900}]}]}
{"op":"mcm","clk":"11788680419","pt":1722478690441,"mc":[{"id":"1.231243109","rc":[{"batb":[[0,1.77,10.99],[1,1.76,9.93],[2,1.58,16]],"ltp":1.4,"tv":0.14,"id":40380900}]}]}
{"op":"mcm","clk":"11788783729","pt":1722480490598,"mc":[{"id":"1.231243109","rc":[{"batb":[[0,1.76,9.93],[1,1.58,16],[2,1.41,7.15]],"ltp":1.4,"tv":0.14,"id":40380900}]}]}
{"op":"mcm","clk":"11788786274","pt":1722480536554,"mc":[{"id":"1.231243109","rc":[{"batb":[[0,1.77,10.99],[1,1.76,9.93],[2,1.58,16]],"ltp":1.4,"tv":0.14,"id":40380900}]}]}
{"op":"mcm","clk":"11788874092","pt":1722482336693,"mc":[{"id":"1.231243109","rc":[{"batb":[[0,1.76,9.93],[1,1.58,16],[2,1.41,7.15]],"ltp":1.4,"tv":0.14,"id":40380900},{"batb":[[1,1.41,6.57]],"ltp":1.3,"tv":0.13,"id":40380901}]}]}
{"op":"mcm","clk":"11788874893","pt":1722482356531,"mc":[{"id":"1.231243109","rc":[{"batb":[[0,1.77,10.99],[1,1.76,9.93],[2,1.58,16]],"ltp":1.4,"tv":0.14,"id":40380900}]}]}
{"op":"mcm","clk":"11788946152","pt":1722484156792,"mc":[{"id":"1.231243109","rc":[{"batb":[[0,1.76,9.93],[1,1.58,16],[2,1.41,7.15]],"ltp":1.4,"tv":0.14,"id":40380900}]}]}
{"op":"mcm","clk":"11788948048","pt":1722484216152,"mc":[{"id":"1.231243109","rc":[{"batb":[[0,1.77,10.99],[1,1.76,9.93],[2,1.58,16]],"ltp":1.4,"tv":0.14,"id":40380900}]}]}
{"op":"mcm","clk":"11789025003","pt":1722486016364,"mc":[{"id":"1.231243109","rc":[{"batb":[[0,1.76,9.93],[1,1.58,16],[2,1.41,7.15]],"ltp":1.4,"tv":0.14,"id":40380900}]}]}
{"op":"mcm","clk":"11789026818","pt":1722486056635,"mc":[{"id":"1.231243109","rc":[{"batb":[[0,1.77,11],[1,1.76,9.93],[2,1.58,16]],"ltp":1.4,"tv":0.14,"id":40380900}]}]}
{"op":"mcm","clk":"11789101432","pt":1722487856916,"mc":[{"id":"1.231243109","rc":[{"batb":[[0,1.76,9.93],[1,1.58,16],[2,1.41,7.15]],"ltp":1.4,"tv":0.14,"id":40380900}]}]}
{"op":"mcm","clk":"11789102458","pt":1722487892657,"mc":[{"id":"1.231243109","rc":[{"batb":[[0,1.77,11],[1,1.76,9.93],[2,1.58,16]],"ltp":1.4,"tv":0.14,"id":40380900}]}]}
{"op":"mcm","clk":"11789151548","pt":1722489174801,"mc":[{"id":"1.231243109","rc":[{"batb":[[0,1.77,11]],"ltp":1.4,"tv":0.14,"id":40380900},{"batb":[[1,1.41,6.57]],"ltp":1.3,"tv":0.13,"id":40380901}]}]}
{"op":"mcm","clk":"11789178201","pt":1722489692989,"mc":[{"id":"1.231243109","rc":[{"batb":[[0,1.76,9.93],[1,1.58,16],[2,1.41,7.15]],"ltp":1.4,"tv":0.14,"id":40380900}]}]}
{"op":"mcm","clk":"11789179576","pt":1722489724083,"mc":[{"id":"1.231243109","rc":[{"batb":[[0,1.77,11],[1,1.76,9.93],[2,1.58,16]],"ltp":1.4,"tv":0.14,"id":40380900}]}]}
{"op":"mcm","clk":"11789195022","pt":1722490103119,"mc":[{"id":"1.231243109","rc":[{"batb":[[0,1.78,16],[1,1.77,11],[2,1.76,9.93]],"ltp":1.4,"tv":0.14,"id":40380900},{"batb":[[0,1.43,18],[1,1.42,10],[2,1.41,6.57]],"ltp":1.3,"tv":0.13,"id":40380901}]}]}
{"op":"mcm","clk":"11789245831","pt":1722491524371,"mc":[{"id":"1.231243109","rc":[{"batb":[[1,1.76,9.93],[2,1.41,7.15]],"ltp":1.4,"tv":0.14,"id":40380900}]}]}
{"op":"mcm","clk":"11789246866","pt":1722491555514,"mc":[{"id":"1.231243109","rc":[{"batb":[[0,1.79,10.72],[1,1.78,16],[2,1.76,9.93]],"ltp":1.4,"tv":0.14,"id":40380900}]}]}
{"op":"mcm","clk":"11789253090","pt":1722491740421,"mc":[{"id":"1.231243109","rc":[{"batl":[[0,1.9,225],[1,6,1.56],[2,7,0.78]],"ltp":1.3,"tv":0.13,"id":40380901}]}]}
{"op":"mcm","clk":"11789253499","pt":1722491754632,"mc":[{"id":"1.231243109","rc":[{"batb":[[0,1.55,450],[1,1.43,18],[2,1.42,10]],"ltp":1.3,"tv":0.13,"id":40380901}]}]}
{"op":"mcm","clk":"11789267074","pt":1722492107090,"mc":[{"id":"1.231243109","rc":[{"batb":[[0,1.79,10.72]],"ltp":1.4,"tv":0.14,"id":40380900},{"batb":[[0,1.56,6.57],[1,1.55,450],[2,1.43,18]],"ltp":1.3,"tv":0.13,"id":40380901}]}]}
{"op":"mcm","clk":"11789281687","pt":1722492415911,"mc":[{"id":"1.231243109","rc":[{"batb":[[0,1.58,80],[1,1.56,6.57],[2,1.55,450]],"ltp":1.3,"tv":0.13,"id":40380901}]}]}
{"op":"mcm","clk":"11789284096","pt":1722492475306,"mc":[{"id":"1.231243109","rc":[{"batl":[[0,1.89,11.05],[1,1.9,225],[2,6,1.56]],"ltp":1.3,"tv":0.13,"id":40380901}]}]}
{"op":"mcm","clk":"11789289651","pt":1722492650470,"mc":[{"id":"1.231243109","rc":[{"batb":[[0,2.12,9.99],[1,1.79,10.72],[2,1.78,16]],"ltp":1.4,"tv":0.14,"id":40380900}]}]}
{"op":"mcm","clk":"11789307714","pt":1722493143577,"mc":[{"id":"1.231243109","rc":[{"batb":[[0,2.14,9.93],[1,2.12,9.99],[2,1.79,10.72]],"ltp":1.4,"tv":0.14,"id":40380900},{"batb":[[0,1.59,10],[1,1.58,80],[2,1.56,6.57]],"ltp":1.3,"tv":0.13,"id":40380901}]}]}
{"op":"mcm","clk":"11789317098","pt":1722493355701,"mc":[{"id":"1.231243109","rc":[{"batb":[[2,1.78,16]],"ltp":1.4,"tv":0.14,"id":40380900}]}]}
{"op":"mcm","clk":"11789321420","pt":1722493458312,"mc":[{"id":"1.231243109","rc":[{"batb":[[0,1.62,450],[1,1.59,10],[2,1.58,80]],"ltp":1.3,"tv":0.13,"id":40380901}]}]}
{"op":"mcm","clk":"11789323256","pt":1722493502963,"mc":[{"id":"1.231243109","rc":[{"batl":[[0,1.84,112.5],[1,1.89,11.05],[2,1.9,225]],"ltp":1.3,"tv":0.13,"id":40380901}]}]}
{"op":"mcm","clk":"11789323307","pt":1722493504158,"mc":[{"id":"1.231243109","rc":[{"batb":[[1,1.78,16],[2,1.4,60]],"ltp":1.4,"tv":0.14,"id":40380900},{"batl":[[1,1.9,225],[2,6,1.56]],"ltp":1.3,"tv":0.13,"id":40380901}]}]}
{"op":"mcm","clk":"11789342607","pt":1722493989183,"mc":[{"id":"1.231243109","rc":[{"batb":[[0,2.2,7.32],[1,2.14,9.93],[2,1.78,16]],"ltp":1.4,"tv":0.14,"id":40380900},{"batb":[[0,1.63,6.57],[1,1.62,450],[2,1.59,10]],"ltp":1.3,"tv":0.13,"id":40380901}]}]}
{"op":"mcm","clk":"11789354844","pt":1722494244179,"mc":[{"id":"1.231243109","rc":[{"batl":[[0,2.6,13.86],[1,6,1.56],[2,7,0.78]],"ltp":1.4,"tv":0.14,"id":40380900},{"batb":[[0,1.63,23.5]],"ltp":1.3,"tv":0.13,"id":40380901}]}]}
{"op":"mcm","clk":"11789356999","pt":1722494285419,"mc":[{"id":"1.231243109","rc":[{"batb":[[0,2.2,12.34]],"ltp":1.4,"tv":0.14,"id":40380900},{"batl":[[0,1.83,5.95],[1,1.84,112.5],[2,1.9,225]],"ltp":1.3,"tv":0.13,"id":40380901}]}]}
{"op":"mcm","clk":"11789384546","pt":1722494790317,"mc":[{"id":"1.231243109","rc":[{"batb":[[0,2.22,3],[1,2.2,12.34],[2,2.14,9.93]],"ltp":1.4,"tv":0.14,"id":40380900},{"batb":[[0,1.64,4.12],[1,1.63,23.5],[2,1.62,450]],"ltp":1.3,"tv":0.14,"id":40380901}]}]}
{"op":"mcm","clk":"11789586825","pt":1722499974793,"mc":[{"id":"1.231243109","rc":[{"batb":[[1,2.2,12.38]],"batl":[[0,2.6,13.89],[1,6,1.56],[2,7,0.78]],"ltp":1.4,"tv":0.14,"id":40380900},{"batb":[[1,1.63,23.56]],"batl":[[0,1.83,5.96]],"ltp":1.3,"tv":0.14,"id":40380901}]}]}
{"op":"mcm","clk":"11789807885","pt":1722504612714,"mc":[{"id":"1.231243109","rc":[{"batl":[[0,2.6,13.88],[1,6,1.56]],"ltp":1.4,"tv":0.14,"id":40380900},{"batb":[[1,1.63,23.55]],"batl":[[0,1.83,5.96]],"ltp":1.3,"tv":0.14,"id":40380901}]}]}
{"op":"mcm","clk":"11789808531","pt":1722504623547,"mc":[{"id":"1.231243109","rc":[{"batb":[[0,1.65,8],[1,1.64,4.12],[2,1.63,23.55]],"ltp":1.3,"tv":0.14,"id":40380901}]}]}
{"op":"mcm","clk":"11790066337","pt":1722508846013,"mc":[{"id":"1.231243109","rc":[{"batb":[[1,2.2,12.4]],"batl":[[0,2.6,13.9],[1,6,1.57],[2,7,0.78]],"ltp":1.4,"tv":0.14,"id":40380900},{"batb":[[0,1.7,10],[1,1.65,8],[2,1.64,4.12]],"batl":[[0,1.83,5.97]],"ltp":1.3,"tv":0.14,"id":40380901}]}]}
{"op":"mcm","clk":"11790087512","pt":1722509140892,"mc":[{"id":"1.231243109","rc":[{"batb":[[1,2.2,5.04]],"ltp":1.4,"tv":0.14,"id":40380900}]}]}
{"op":"mcm","clk":"11790118328","pt":1722509556310,"mc":[{"id":"1.231243109","rc":[{"batb":[[0,1.71,1],[1,1.7,10],[2,1.65,8]],"ltp":1.3,"tv":0.14,"id":40380901}]}]}
{"op":"mcm","clk":"11790119533","pt":1722509574348,"mc":[{"id":"1.231243109","rc":[{"batb":[[0,1.71,1.06]],"ltp":1.3,"tv":0.14,"id":40380901}]}]}
{"op":"mcm","clk":"11790120387","pt":1722509587101,"mc":[{"id":"1.231243109","rc":[{"batb":[[0,1.7,10.06],[1,1.65,8],[2,1.64,4.12]],"ltp":1.3,"tv":0.14,"id":40380901}]}]}
{"op":"mcm","clk":"11790207843","pt":1722510774793,"mc":[{"id":"1.231243109","rc":[{"batb":[[1,2.2,5.03]],"batl":[[0,2.6,13.88],[1,6,1.57],[2,7,0.78]],"ltp":1.4,"tv":0.14,"id":40380900},{"batl":[[0,1.83,5.96]],"ltp":1.3,"tv":0.14,"id":40380901}]}]}
{"op":"mcm","clk":"11790225398","pt":1722510944287,"mc":[{"id":"1.231243109","rc":[{"batl":[[0,1.8,25.52],[1,1.83,5.96],[2,1.84,112.5]],"ltp":1.3,"tv":0.14,"id":40380901}]}]}
{"op":"mcm","clk":"11790225481","pt":1722510945473,"mc":[{"id":"1.231243109","rc":[{"batb":[[1,2.14,9.93],[2,1.7,10]],"ltp":1.4,"tv":0.14,"id":40380900},{"batl":[[1,1.84,112.5],[2,1.9,225]],"ltp":1.3,"tv":0.14,"id":40380901}]}]}
{"op":"mcm","clk":"11790403056","pt":1722513510041,"mc":[{"id":"1.231243109","rc":[{"batl":[[0,1.79,5],[1,1.8,25.52],[2,1.84,112.5]],"ltp":1.3,"tv":0.14,"id":40380901}]}]}
{"op":"mcm","clk":"11790606043","pt":1722516174795,"mc":[{"id":"1.231243109","rc":[{"batl":[[0,2.6,13.87],[1,6,1.56],[2,7,0.78]],"ltp":1.4,"tv":0.14,"id":40380900}]}]}
{"op":"mcm","clk":"11790737644","pt":1722517973293,"mc":[{"id":"1.231243109","rc":[{"batl":[[0,2.6,13.87],[1,6,1.56]],"ltp":1.4,"tv":0.14,"id":40380900},{"batl":[[0,1.73,138.46],[1,1.79,5],[2,1.8,25.52]],"ltp":1.3,"tv":0.14,"id":40380901}]}]}
{"op":"mcm","clk":"11790754234","pt":1722518302426,"mc":[{"id":"1.231243109","rc":[{"batl":[[0,1.73,4153.84]],"ltp":1.3,"tv":0.14,"id":40380901}]}]}
{"op":"mcm","clk":"11790756539","pt":1722518350339,"mc":[{"id":"1.231243109","rc":[{"batl":[[0,6,1.56],[1,7,0.78],[2,7,0]],"ltp":1.4,"tv":0.14,"id":40380900}]}]}
{"op":"mcm","clk":"11790759159","pt":1722518403914,"mc":[{"id":"1.231243109","rc":[{"batl":[[0,1.73,3115.3]],"ltp":1.3,"tv":0.14,"id":40380901}]}]}
{"op":"mcm","clk":"11790772568","pt":1722518704294,"mc":[{"id":"1.231243109","rc":[{"batb":[[0,2.38,12.52],[1,2.22,3],[2,2.14,9.93]],"ltp":1.4,"tv":0.14,"id":40380900}]}]}
{"op":"mcm","clk":"11790774846","pt":1722518754791,"mc":[{"id":"1.231243109","rc":[{"batl":[[0,1.72,16.94],[1,1.73,3115.3],[2,1.79,5]],"ltp":1.3,"tv":0.14,"id":40380901}]}]}
{"op":"mcm","clk":"11790785192","pt":1722518981118,"mc":[{"id":"1.231243109","rc":[{"batb":[[1,1.64,4.12],[2,1.59,10]],"ltp":1.3,"tv":0.14,"id":40380901}]}]}
{"op":"mcm","clk":"11790797339","pt":1722519260836,"mc":[{"id":"1.231243109","rc":[{"trd":[[2.38,0.08]],"batb":[[0,2.38,12.48],[1,1.7,10],[2,1.35,70.05]],"ltp":2.38,"tv":0.22,"id":40380900},{"batb":[[0,1.7,10],[1,1.58,124],[2,1.35,70.05]],"ltp":1.3,"tv":0.14,"id":40380901}],"tv":0.36}]}
{"op":"mcm","clk":"11790799122","pt":1722519302873,"mc":[{"id":"1.231243109","rc":[{"batb":[[2,1.05,25000]],"ltp":2.38,"tv":0.22,"id":40380900}]}]}
{"op":"mcm","clk":"11790799253","pt":1722519305392,"mc":[{"id":"1.231243109","rc":[{"batb":[[2,1.04,25000]],"ltp":1.3,"tv":0.14,"id":40380901}]}]}
{"op":"mcm","clk":"11790826362","pt":1722519939223,"mc":[{"id":"1.231243109","rc":[{"trd":[[1.7,0.14]],"batb":[[0,1.7,9.93]],"ltp":1.7,"tv":0.28,"id":40380901}],"tv":0.5}]}
{"op":"mcm","clk":"11790900597","pt":1722521456374,"mc":[{"id":"1.231243109","rc":[{"batb":[[0,2.38,12.47]],"batl":[[0,6,1.56]],"ltp":2.38,"tv":0.22,"id":40380900},{"trd":[[1.7,20]],"batb":[[0,1.58,124],[1,1.04,25000],[2,1.03,25200]],"batl":[[0,1.7,102.57],[1,1.72,16.94],[2,1.73,3115.3]],"ltp":1.7,"tv":20.14,"id":40380901}],"tv":20.36}]}
{"op":"mcm","clk":"11790900668","pt":1722521457993,"mc":[{"id":"1.231243109","rc":[{"batb":[[0,1.7,10],[1,1.05,25000],[2,1.04,25000]],"ltp":2.38,"tv":0.22,"id":40380900},{"batl":[[1,1.73,3115.3],[2,1.79,5]],"ltp":1.7,"tv":20.14,"id":40380901}]}]}
{"op":"mcm","clk":"11790914182","pt":1722521582979,"mc":[{"id":"1.231243109","rc":[{"batl":[[1,1.79,5],[2,1.8,25.52]],"ltp":1.7,"tv":20.14,"id":40380901}]}]}
{"op":"mcm","clk":"11790914228","pt":1722521583656,"mc":[{"id":"1.231243109","rc":[{"batl":[[0,1.68,2769.23],[1,1.7,102.57],[2,1.79,5]],"ltp":1.7,"tv":20.14,"id":40380901}]}]}
{"op":"mcm","clk":"11790920542","pt":1722521750777,"mc":[{"id":"1.231243109","rc":[{"batb":[[1,1.05,5.19],[2,1.04,25000]],"ltp":1.7,"tv":20.14,"id":40380901}]}]}
{"op":"mcm","clk":"11790930637","pt":1722522037221,"mc":[{"id":"1.231243109","rc":[{"batb":[[0,1.59,100],[1,1.58,124],[2,1.05,5.19]],"ltp":1.7,"tv":20.14,"id":40380901}]}]}
{"op":"mcm","clk":"11790940137","pt":1722522326750,"mc":[{"id":"1.231243109","rc":[{"batb":[[0,2.48,11.69],[1,1.7,10],[2,1.05,25000]],"ltp":2.38,"tv":0.22,"id":40380900},{"batl":[[0,1.67,17.15],[1,1.68,2769.23],[2,1.7,102.57]],"ltp":1.7,"tv":20.14,"id":40380901}]}]}
{"op":"mcm","clk":"11790960018","pt":1722522828088,"mc":[{"id":"1.231243109","rc":[{"batb":[[0,1.6,4.91],[1,1.59,100],[2,1.58,124]],"ltp":1.7,"tv":20.14,"id":40380901}]}]}
{"op":"mcm","clk":"11790987114","pt":1722523552063,"mc":[{"id":"1.231243109","rc":[{"batl":[[1,1.7,102.57],[2,1.79,5]],"ltp":1.7,"tv":20.14,"id":40380901}]}]}
{"op":"mcm","clk":"11790987152","pt":1722523552839,"mc":[{"id":"1.231243109","rc":[{"batb":[[0,1.7,10],[1,1.05,25000],[2,1.04,25000]],"ltp":2.38,"tv":0.22,"id":40380900},{"batl":[[0,1.7,102.57],[1,1.79,5],[2,1.8,25.52]],"ltp":1.7,"tv":20.14,"id":40380901}]}]}
{"op":"mcm","clk":"11791009485","pt":1722524276544,"mc":[{"id":"1.231243109","rc":[{"batl":[[0,1.69,5.04],[1,1.7,102.57],[2,1.79,5]],"ltp":1.7,"tv":20.14,"id":40380901}]}]}
{"op":"mcm","clk":"11791010905","pt":1722524335152,"mc":[{"id":"1.231243109","rc":[{"batb":[[0,1.61,182.13],[1,1.6,4.91],[2,1.59,100]],"ltp":1.7,"tv":20.14,"id":40380901}]}]}
{"op":"mcm","clk":"11791010987","pt":1722524337745,"mc":[{"id":"1.231243109","rc":[{"batb":[[1,1.59,100],[2,1.58,124]],"ltp":1.7,"tv":20.14,"id":40380901}]}]}
{"op":"mcm","clk":"11791011397","pt":1722524354948,"mc":[{"id":"1.231243109","rc":[{"batb":[[0,1.59,100],[1,1.58,124],[2,1.05,5.19]],"ltp":1.7,"tv":20.14,"id":40380901}]}]}
{"op":"mcm","clk":"11791013149","pt":1722524416642,"mc":[{"id":"1.231243109","rc":[{"batl":[[0,6,1.56],[1,7,0.78]],"ltp":2.38,"tv":0.22,"id":40380900},{"batl":[[0,1.64,1.82],[1,1.69,5.04],[2,1.7,102.57]],"ltp":1.7,"tv":20.14,"id":40380901}]}]}
{"op":"mcm","clk":"11791013923","pt":1722524436827,"mc":[{"id":"1.231243109","rc":[{"batl":[[0,1.69,5.04],[1,1.7,102.57],[2,1.79,5]],"ltp":1.7,"tv":20.14,"id":40380901}]}]}
{"op":"mcm","clk":"11791023570","pt":1722524736586,"mc":[{"id":"1.231243109","rc":[{"batb":[[0,1.61,182.13],[1,1.59,100],[2,1.58,124]],"ltp":1.7,"tv":20.14,"id":40380901}]}]}
{"op":"mcm","clk":"11791033569","pt":1722525058930,"mc":[{"id":"1.231243109","rc":[{"batl":[[0,2.62,5.46],[1,6,1.56],[2,7,0.78]],"ltp":2.38,"tv":0.22,"id":40380900}]}]}
{"op":"mcm","clk":"11791050411","pt":1722525520127,"mc":[{"id":"1.231243109","rc":[{"batb":[[0,1.62,9.38],[1,1.61,182.13],[2,1.59,100]],"ltp":1.7,"tv":20.14,"id":40380901}]}]}
{"op":"mcm","clk":"11791075293","pt":1722526195365,"mc":[{"id":"1.231243109","rc":[{"batb":[[2,1.59,103.35]],"ltp":1.7,"tv":20.14,"id":40380901}]}]}
{"op":"mcm","clk":"11791075340","pt":1722526196361,"mc":[{"id":"1.231243109","rc":[{"batb":[[2,1.59,100]],"ltp":1.7,"tv":20.14,"id":40380901}]}]}
{"op":"mcm","clk":"11791126539","pt":1722527276986,"mc":[{"id":"1.231243109","rc":[{"batb":[[2,1.58,124]],"ltp":1.7,"tv":20.14,"id":40380901}]}]}
{"op":"mcm","clk":"11791194932","pt":1722528637328,"mc":[{"id":"1.231243109","rc":[{"batl":[[0,2.62,5.47],[1,6,1.57],[2,7,0.78]],"ltp":2.38,"tv":0.22,"id":40380900},{"batb":[[0,1.62,9.4]],"batl":[[0,1.69,5.05]],"ltp":1.7,"tv":20.14,"id":40380901}]}]}
{"op":"mcm","clk":"11791373913","pt":1722530946889,"mc":[{"id":"1.231243109","rc":[{"batl":[[0,1.64,2],[1,1.69,5.05],[2,1.7,102.57]],"ltp":1.7,"tv":20.14,"id":40380901}]}]}
{"op":"mcm","clk":"11791400245","pt":1722531249399,"mc":[{"id":"1.231243109","rc":[{"trd":[[1.64,4]],"batb":[[0,1.64,7],[1,1.62,9.4],[2,1.61,182.13]],"batl":[[0,1.69,5.05],[1,1.7,102.57],[2,1.79,5]],"ltp":1.64,"tv":24.14,"id":40380901}],"tv":24.36}]}
{"op":"mcm","clk":"11791425631","pt":1722531530280,"mc":[{"id":"1.231243109","rc":[{"batl":[[1,1.7,128.09]],"ltp":1.64,"tv":24.14,"id":40380901}]}]}
{"op":"mcm","clk":"11791451921","pt":1722531739442,"mc":[{"id":"1.231243109","rc":[{"batl":[[0,2.62,5.47],[1,6,1.57],[2,7,0.78]],"ltp":2.38,"tv":0.22,"id":40380900},{"batb":[[1,1.62,9.4]],"batl":[[0,1.69,5.06]],"ltp":1.64,"tv":24.14,"id":40380901}]}]}
{"op":"mcm","clk":"11791455272","pt":1722531763070,"mc":[{"id":"1.231243109","rc":[{"batl":[[2,1.75,553.85]],"ltp":1.64,"tv":24.14,"id":40380901}]}]}
{"op":"mcm","clk":"11791523877","pt":1722532252942,"mc":[{"id":"1.231243109","rc":[{"batb":[[0,2.44,4.71],[1,1.7,10],[2,1.05,25000]],"ltp":2.38,"tv":0.22,"id":40380900}]}]}
{"op":"mcm","clk":"11791528024","pt":1722532283175,"mc":[{"id":"1.231243109","rc":[{"batl":[[0,1.68,2769.23],[1,1.69,5.06],[2,1.7,128.09]],"ltp":1.64,"tv":24.14,"id":40380901}]}]}
{"op":"mcm","clk":"11791528287","pt":1722532285078,"mc":[{"id":"1.231243109","rc":[{"batb":[[0,1.7,10],[1,1.05,25000],[2,1.04,25000]],"ltp":2.38,"tv":0.22,"id":40380900},{"batl":[[1,1.7,128.09],[2,1.75,553.85]],"ltp":1.64,"tv":24.14,"id":40380901}]}]}
{"op":"mcm","clk":"11791609899","pt":1722532802050,"mc":[{"id":"1.231243109","rc":[{"batl":[[0,1.67,3],[1,1.68,2769.23],[2,1.7,128.09]],"ltp":1.64,"tv":24.14,"id":40380901}]}]}
{"op":"mcm","clk":"11791637807","pt":1722533005416,"mc":[{"id":"1.231243109","rc":[{"batb":[[0,2.48,11.26],[1,1.7,10],[2,1.05,25000]],"ltp":2.38,"tv":0.22,"id":40380900},{"batl":[[0,1.67,19.52]],"ltp":1.64,"tv":24.14,"id":40380901}]}]}
{"op":"mcm","clk":"11791773153","pt":1722533887211,"mc":[{"id":"1.231243109","rc":[{"batl":[[1,1.7,128.09],[2,1.75,553.85]],"ltp":1.64,"tv":24.14,"id":40380901}]}]}
{"op":"mcm","clk":"11791773390","pt":1722533888707,"mc":[{"id":"1.231243109","rc":[{"batb":[[0,1.7,10],[1,1.05,25000],[2,1.04,25000]],"ltp":2.38,"tv":0.22,"id":40380900},{"batl":[[0,1.67,3]],"ltp":1.64,"tv":24.14,"id":40380901}]}]}
{"op":"mcm","clk":"11791776148","pt":1722533904961,"mc":[{"id":"1.231243109","rc":[{"batl":[[0,1.66,2769.09],[1,1.67,3],[2,1.7,128.09]],"ltp":1.64,"tv":24.14,"id":40380901}]}]}
{"op":"mcm","clk":"11791893591","pt":1722534626878,"mc":[{"id":"1.231243109","rc":[{"batb":[[0,2.52,11.26],[1,1.7,10],[2,1.05,25000]],"ltp":2.38,"tv":0.22,"id":40380900},{"batl":[[0,1.65,16.99],[1,1.66,2769.09],[2,1.67,3]],"ltp":1.64,"tv":24.14,"id":40380901}]}]}
{"op":"mcm","clk":"11792010796","pt":1722535454974,"mc":[{"id":"1.231243109","rc":[{"trd":[[2.54,10]],"batb":[[0,2.52,11.28]],"batl":[[0,2.62,5.48]],"ltp":2.54,"tv":10.22,"id":40380900},{"trd":[[1.65,49.41]],"batb":[[0,1.65,308.93],[1,1.64,7],[2,1.62,9.42]],"batl":[[0,1.66,2769.09],[1,1.67,3],[2,1.69,20]],"ltp":1.65,"tv":73.55,"id":40380901}],"tv":83.77}]}
{"op":"mcm","clk":"11792010965","pt":1722535456094,"mc":[{"id":"1.231243109","rc":[{"batb":[[0,1.7,10],[1,1.05,25000],[2,1.04,25000]],"batl":[[0,6,1.57],[1,7,0.78],[2,7,0]],"ltp":2.54,"tv":10.22,"id":40380900},{"batb":[[0,1.65,325.94],[2,1.61,182.13]],"ltp":1.65,"tv":73.55,"id":40380901}]}]}
{"op":"mcm","clk":"11792018224","pt":1722535500234,"mc":[{"id":"1.231243109","rc":[{"batl":[[0,1.66,2598.42]],"ltp":1.65,"tv":73.55,"id":40380901}]}]}
{"op":"mcm","clk":"11792018256","pt":1722535500436,"mc":[{"id":"1.231243109","rc":[{"batb":[[0,1.71,10],[1,1.7,10],[2,1.05,25000]],"ltp":2.54,"tv":10.22,"id":40380900}]}]}
{"op":"mcm","clk":"11792018861","pt":1722535503855,"mc":[{"id":"1.231243109","rc":[{"batb":[[0,1.7,10],[1,1.05,25000],[2,1.04,25000]],"ltp":2.54,"tv":10.22,"id":40380900}]}]}
{"op":"mcm","clk":"11792043630","pt":1722535648911,"mc":[{"id":"1.231243109","rc":[{"batb":[[0,1.71,10],[1,1.7,10],[2,1.05,25000]],"ltp":2.54,"tv":10.22,"id":40380900},{"batb":[[0,1.65,17.01]],"ltp":1.65,"tv":73.55,"id":40380901}]}]}
{"op":"mcm","clk":"11792043772","pt":1722535649699,"mc":[{"id":"1.231243109","rc":[{"batb":[[0,2.52,11.48],[1,1.71,10],[2,1.7,10]],"ltp":2.54,"tv":10.22,"id":40380900},{"batb":[[0,1.64,7],[1,1.62,26.61]],"ltp":1.65,"tv":73.55,"id":40380901}]}]}
{"op":"mcm","clk":"11792044164","pt":1722535652098,"mc":[{"id":"1.231243109","rc":[{"batb":[[1,1.7,10],[2,1.05,25000]],"ltp":2.54,"tv":10.22,"id":40380900}]}]}
{"op":"mcm","clk":"11792048165","pt":1722535676188,"mc":[{"id":"1.231243109","rc":[{"batb":[[0,2.54,10]],"ltp":2.54,"tv":10.22,"id":40380900},{"batl":[[0,1.66,2460.01]],"ltp":1.65,"tv":73.55,"id":40380901}]}]}
{"op":"mcm","clk":"11792048606","pt":1722535678827,"mc":[{"id":"1.231243109","rc":[{"batb":[[0,1.7,10],[1,1.05,25000],[2,1.04,25000]],"ltp":2.54,"tv":10.22,"id":40380900}]}]}
{"op":"mcm","clk":"11792062405","pt":1722535760215,"mc":[{"id":"1.231243109","rc":[{"batb":[[0,2.54,10],[1,2.52,11.43],[2,1.7,10]],"ltp":2.54,"tv":10.22,"id":40380900}]}]}
{"op":"mcm","clk":"11792062824","pt":1722535762645,"mc":[{"id":"1.231243109","rc":[{"batb":[[1,1.7,10],[2,1.05,25000]],"ltp":2.54,"tv":10.22,"id":40380900}]}]}
{"op":"mcm","clk":"11792062994","pt":1722535763554,"mc":[{"id":"1.231243109","rc":[{"batb":[[0,1.7,10],[1,1.05,25000],[2,1.04,25000]],"ltp":2.54,"tv":10.22,"id":40380900}]}]}
{"op":"mcm","clk":"11792064715","pt":1722535773344,"mc":[{"id":"1.231243109","rc":[{"batb":[[0,1.71,10],[1,1.7,10],[2,1.05,25000]],"ltp":2.54,"tv":10.22,"id":40380900}]}]}
{"op":"mcm","clk":"11792065274","pt":1722535776520,"mc":[{"id":"1.231243109","rc":[{"batb":[[0,1.7,10],[1,1.05,25000],[2,1.04,25000]],"ltp":2.54,"tv":10.22,"id":40380900}]}]}
{"op":"mcm","clk":"11792079641","pt":1722535862295,"mc":[{"id":"1.231243109","rc":[{"batb":[[0,1.71,10],[1,1.7,10],[2,1.05,25000]],"ltp":2.54,"tv":10.22,"id":40380900}]}]}
{"op":"mcm","clk":"11792080158","pt":1722535865492,"mc":[{"id":"1.231243109","rc":[{"batb":[[0,1.7,10],[1,1.05,25000],[2,1.04,25000]],"ltp":2.54,"tv":10.22,"id":40380900}]}]}
{"op":"mcm","clk":"11792080763","pt":1722535868979,"mc":[{"id":"1.231243109","rc":[{"batb":[[0,2.54,10],[1,2.52,10.96],[2,1.7,10]],"ltp":2.54,"tv":10.22,"id":40380900}]}]}
{"op":"mcm","clk":"11792081048","pt":1722535870785,"mc":[{"id":"1.231243109","rc":[{"batb":[[1,1.7,10],[2,1.05,25000]],"ltp":2.54,"tv":10.22,"id":40380900}]}]}
{"op":"mcm","clk":"11792081316","pt":1722535872419,"mc":[{"id":"1.231243109","rc":[{"batb":[[0,1.7,10],[1,1.05,25000],[2,1.04,25000]],"ltp":2.54,"tv":10.22,"id":40380900}]}]}
{"op":"mcm","clk":"11792086795","pt":1722535908199,"mc":[{"id":"1.231243109","rc":[{"batb":[[0,1.71,10],[1,1.7,10],[2,1.05,25000]],"ltp":2.54,"tv":10.22,"id":40380900}]}]}
{"op":"mcm","clk":"11792087320","pt":1722535911639,"mc":[{"id":"1.231243109","rc":[{"batb":[[0,1.7,10],[1,1.05,25000],[2,1.04,25000]],"ltp":2.54,"tv":10.22,"id":40380900}]}]}
{"op":"mcm","clk":"11792094184","pt":1722535951770,"mc":[{"id":"1.231243109","rc":[{"batb":[[0,1.71,10],[1,1.7,10],[2,1.05,25000]],"ltp":2.54,"tv":10.22,"id":40380900}]}]}
{"op":"mcm","clk":"11792094762","pt":1722535955219,"mc":[{"id":"1.231243109","rc":[{"batb":[[0,1.7,10],[1,1.05,25000],[2,1.04,25000]],"ltp":2.54,"tv":10.22,"id":40380900}]}]}
{"op":"mcm","clk":"11792100050","pt":1722535984844,"mc":[{"id":"1.231243109","rc":[{"batb":[[0,2.54,10],[1,2.52,11.26],[2,1.7,10]],"ltp":2.54,"tv":10.22,"id":40380900}]}]}
{"op":"mcm","clk":"11792100382","pt":1722535986783,"mc":[{"id":"1.231243109","rc":[{"batb":[[1,1.7,10],[2,1.05,25000]],"ltp":2.54,"tv":10.22,"id":40380900}]}]}
{"op":"mcm","clk":"11792100621","pt":1722535988273,"mc":[{"id":"1.231243109","rc":[{"batb":[[0,1.7,10],[1,1.05,25000],[2,1.04,25000]],"ltp":2.54,"tv":10.22,"id":40380900}]}]}
{"op":"mcm","clk":"11792119182","pt":1722536099245,"mc":[{"id":"1.231243109","rc":[{"batb":[[0,2.52,11.11],[1,1.7,10],[2,1.05,25000]],"ltp":2.54,"tv":10.22,"id":40380900}]}]}
{"op":"mcm","clk":"11792119216","pt":1722536099438,"mc":[{"id":"1.231243109","rc":[{"batb":[[0,2.54,10],[1,2.52,11.11],[2,1.7,10]],"ltp":2.54,"tv":10.22,"id":40380900}]}]}
{"op":"mcm","clk":"11792119609","pt":1722536101434,"mc":[{"id":"1.231243109","rc":[{"batb":[[1,1.7,10],[2,1.05,25000]],"ltp":2.54,"tv":10.22,"id":40380900}]}]}
{"op":"mcm","clk":"11792119885","pt":1722536102732,"mc":[{"id":"1.231243109","rc":[{"batb":[[0,1.7,10],[1,1.05,25000],[2,1.04,25000]],"ltp":2.54,"tv":10.22,"id":40380900}]}]}
{"op":"mcm","clk":"11792134171","pt":1722536190617,"mc":[{"id":"1.231243109","rc":[{"batb":[[0,1.71,10],[1,1.7,10],[2,1.05,25000]],"ltp":2.54,"tv":10.22,"id":40380900}]}]}
{"op":"mcm","clk":"11792134683","pt":1722536193914,"mc":[{"id":"1.231243109","rc":[{"batb":[[0,1.7,10],[1,1.05,25000],[2,1.04,25000]],"ltp":2.54,"tv":10.22,"id":40380900}]}]}
{"op":"mcm","clk":"11792137720","pt":1722536213671,"mc":[{"id":"1.231243109","rc":[{"batb":[[0,2.54,10],[1,2.52,11.21],[2,1.7,10]],"ltp":2.54,"tv":10.22,"id":40380900}]}]}
{"op":"mcm","clk":"11792137956","pt":1722536215136,"mc":[{"id":"1.231243109","rc":[{"batb":[[1,1.7,10],[2,1.05,25000]],"ltp":2.54,"tv":10.22,"id":40380900}]}]}
{"op":"mcm","clk":"11792138247","pt":1722536217092,"mc":[{"id":"1.231243109","rc":[{"batb":[[0,1.7,10],[1,1.05,25000],[2,1.04,25000]],"ltp":2.54,"tv":10.22,"id":40380900}]}]}
{"op":"mcm","clk":"11792140476","pt":1722536231252,"mc":[{"id":"1.231243109","rc":[{"batb":[[0,1.71,10],[1,1.7,10],[2,1.05,25000]],"ltp":2.54,"tv":10.22,"id":40380900}]}]}
{"op":"mcm","clk":"11792140983","pt":1722536234542,"mc":[{"id":"1.231243109","rc":[{"batb":[[0,1.7,10],[1,1.05,25000],[2,1.04,25000]],"ltp":2.54,"tv":10.22,"id":40380900}]}]}
{"op":"mcm","clk":"11792143021","pt":1722536248024,"mc":[{"id":"1.231243109","rc":[{"batb":[[0,1.71,10],[1,1.7,10],[2,1.05,25000]],"ltp":2.54,"tv":10.22,"id":40380900}]}]}
{"op":"mcm","clk":"11792143579","pt":1722536251279,"mc":[{"id":"1.231243109","rc":[{"batb":[[0,1.7,10],[1,1.05,25000],[2,1.04,25000]],"ltp":2.54,"tv":10.22,"id":40380900}]}]}
{"op":"mcm","clk":"11792145457","pt":1722536263695,"mc":[{"id":"1.231243109","rc":[{"batb":[[0,1.71,10],[1,1.7,10],[2,1.05,25000]],"ltp":2.54,"tv":10.22,"id":40380900}]}]}
{"op":"mcm","clk":"11792145985","pt":1722536267303,"mc":[{"id":"1.231243109","rc":[{"batb":[[0,1.7,10],[1,1.05,25000],[2,1.04,25000]],"ltp":2.54,"tv":10.22,"id":40380900}]}]}
{"op":"mcm","clk":"11792147497","pt":1722536277005,"mc":[{"id":"1.231243109","rc":[{"batb":[[0,1.71,10],[1,1.7,10],[2,1.05,25000]],"ltp":2.54,"tv":10.22,"id":40380900}]}]}
{"op":"mcm","clk":"11792147974","pt":1722536280219,"mc":[{"id":"1.231243109","rc":[{"batb":[[0,1.7,10],[1,1.05,25000],[2,1.04,25000]],"ltp":2.54,"tv":10.22,"id":40380900}]}]}
{"op":"mcm","clk":"11792150339","pt":1722536296333,"mc":[{"id":"1.231243109","rc":[{"batb":[[0,1.71,10],[1,1.7,10],[2,1.05,25000]],"ltp":2.54,"tv":10.22,"id":40380900}]}]}
{"op":"mcm","clk":"11792150868","pt":1722536299832,"mc":[{"id":"1.231243109","rc":[{"batb":[[0,1.7,10],[1,1.05,25000],[2,1.04,25000]],"ltp":2.54,"tv":10.22,"id":40380900}]}]}
{"op":"mcm","clk":"11792151905","pt":1722536306899,"mc":[{"id":"1.231243109","rc":[{"batb":[[0,1.71,10],[1,1.7,10],[2,1.05,25000]],"ltp":2.54,"tv":10.22,"id":40380900}]}]}
{"op":"mcm","clk":"11792152467","pt":1722536309636,"mc":[{"id":"1.231243109","rc":[{"batb":[[0,1.7,10],[1,1.05,25000],[2,1.04,25000]],"ltp":2.54,"tv":10.22,"id":40380900}]}]}
{"op":"mcm","clk":"11792155209","pt":1722536327268,"mc":[{"id":"1.231243109","rc":[{"batb":[[0,2.54,10],[1,2.52,11.02],[2,1.7,10]],"ltp":2.54,"tv":10.22,"id":40380900}]}]}
{"op":"mcm","clk":"11792155505","pt":1722536329284,"mc":[{"id":"1.231243109","rc":[{"batb":[[1,1.7,10],[2,1.05,25000]],"ltp":2.54,"tv":10.22,"id":40380900}]}]}
{"op":"mcm","clk":"11792155687","pt":1722536330670,"mc":[{"id":"1.231243109","rc":[{"batb":[[0,1.7,10],[1,1.05,25000],[2,1.04,25000]],"ltp":2.54,"tv":10.22,"id":40380900}]}]}
{"op":"mcm","clk":"11792170176","pt":1722536427708,"mc":[{"id":"1.231243109","rc":[{"batb":[[0,1.71,10],[1,1.7,10],[2,1.05,25000]],"ltp":2.54,"tv":10.22,"id":40380900}]}]}
{"op":"mcm","clk":"11792170756","pt":1722536431793,"mc":[{"id":"1.231243109","rc":[{"batb":[[0,1.7,10],[1,1.05,25000],[2,1.04,25000]],"ltp":2.54,"tv":10.22,"id":40380900}]}]}
{"op":"mcm","clk":"11792171348","pt":1722536436213,"mc":[{"id":"1.231243109","rc":[{"batb":[[0,1.71,10],[1,1.7,10],[2,1.05,25000]],"ltp":2.54,"tv":10.22,"id":40380900}]}]}
{"op":"mcm","clk":"11792171844","pt":1722536439694,"mc":[{"id":"1.231243109","rc":[{"batb":[[0,1.7,10],[1,1.05,25000],[2,1.04,25000]],"ltp":2.54,"tv":10.22,"id":40380900}]}]}
{"op":"mcm","clk":"11792172099","pt":1722536441415,"mc":[{"id":"1.231243109","rc":[{"batb":[[0,2.52,11.18],[1,1.7,10],[2,1.05,25000]],"ltp":2.54,"tv":10.22,"id":40380900}]}]}
{"op":"mcm","clk":"11792197560","pt":1722536611441,"mc":[{"id":"1.231243109","rc":[{"batb":[[0,2.54,10],[1,2.52,11.18],[2,1.7,10]],"ltp":2.54,"tv":10.22,"id":40380900}]}]}
{"op":"mcm","clk":"11792197683","pt":1722536612327,"mc":[{"id":"1.231243109","rc":[{"batb":[[1,1.7,10],[2,1.05,25000]],"ltp":2.54,"tv":10.22,"id":40380900}]}]}
{"op":"mcm","clk":"11792198054","pt":1722536614857,"mc":[{"id":"1.231243109","rc":[{"batb":[[0,1.7,10],[1,1.05,25000],[2,1.04,25000]],"ltp":2.54,"tv":10.22,"id":40380900}]}]}
{"op":"mcm","clk":"11792198326","pt":1722536616617,"mc":[{"id":"1.231243109","rc":[{"batb":[[0,2.52,11.38],[1,1.7,10],[2,1.05,25000]],"ltp":2.54,"tv":10.22,"id":40380900}]}]}
{"op":"mcm","clk":"11792220650","pt":1722536772829,"mc":[{"id":"1.231243109","rc":[{"batb":[[0,2.54,10],[1,2.52,11.38],[2,1.7,10]],"ltp":2.54,"tv":10.22,"id":40380900}]}]}
{"op":"mcm","clk":"11792220850","pt":1722536774402,"mc":[{"id":"1.231243109","rc":[{"batb":[[1,1.7,10],[2,1.05,25000]],"ltp":2.54,"tv":10.22,"id":40380900}]}]}
{"op":"mcm","clk":"11792221088","pt":1722536776244,"mc":[{"id":"1.231243109","rc":[{"batb":[[0,1.7,10],[1,1.05,25000],[2,1.04,25000]],"ltp":2.54,"tv":10.22,"id":40380900}]}]}
{"op":"mcm","clk":"11792221444","pt":1722536778619,"mc":[{"id":"1.231243109","rc":[{"batb":[[0,2.54,10],[1,2.52,11.13],[2,1.7,10]],"ltp":2.54,"tv":10.22,"id":40380900}]}]}
{"op":"mcm","clk":"11792221727","pt":1722536780731,"mc":[{"id":"1.231243109","rc":[{"batb":[[1,1.7,10],[2,1.05,25000]],"ltp":2.54,"tv":10.22,"id":40380900}]}]}
{"op":"mcm","clk":"11792221917","pt":1722536782040,"mc":[{"id":"1.231243109","rc":[{"batb":[[0,1.7,10],[1,1.05,25000],[2,1.04,25000]],"ltp":2.54,"tv":10.22,"id":40380900}]}]}
{"op":"mcm","clk":"11792237543","pt":1722536891895,"mc":[{"id":"1.231243109","rc":[{"batb":[[0,2.54,10],[1,2.52,11.12],[2,1.7,10]],"ltp":2.54,"tv":10.22,"id":40380900}]}]}
{"op":"mcm","clk":"11792237767","pt":1722536893611,"mc":[{"id":"1.231243109","rc":[{"batb":[[1,1.7,10],[2,1.05,25000]],"ltp":2.54,"tv":10.22,"id":40380900}]}]}
{"op":"mcm","clk":"11792238006","pt":1722536895268,"mc":[{"id":"1.231243109","rc":[{"batb":[[0,1.7,10],[1,1.05,25000],[2,1.04,25000]],"ltp":2.54,"tv":10.22,"id":40380900}]}]}
{"op":"mcm","clk":"11792254109","pt":1722537006685,"mc":[{"id":"1.231243109","rc":[{"batb":[[0,2.54,10],[1,2.52,11.45],[2,1.7,10]],"ltp":2.54,"tv":10.22,"id":40380900}]}]}
{"op":"mcm","clk":"11792254406","pt":1722537008595,"mc":[{"id":"1.231243109","rc":[{"batb":[[1,1.7,10],[2,1.05,25000]],"ltp":2.54,"tv":10.22,"id":40380900}]}]}
{"op":"mcm","clk":"11792254628","pt":1722537009973,"mc":[{"id":"1.231243109","rc":[{"batb":[[0,1.7,10],[1,1.05,25000],[2,1.04,25000]],"ltp":2.54,"tv":10.22,"id":40380900}]}]}
{"op":"mcm","clk":"11792256373","pt":1722537021088,"mc":[{"id":"1.231243109","rc":[{"batb":[[0,1.71,10],[1,1.7,10],[2,1.05,25000]],"ltp":2.54,"tv":10.22,"id":40380900}]}]}
{"op":"mcm","clk":"11792256913","pt":1722537024645,"mc":[{"id":"1.231243109","rc":[{"batb":[[0,1.7,10],[1,1.05,25000],[2,1.04,25000]],"ltp":2.54,"tv":10.22,"id":40380900}]}]}
{"op":"mcm","clk":"11792259413","pt":1722537042087,"mc":[{"id":"1.231243109","rc":[{"batb":[[0,1.71,10],[1,1.7,10],[2,1.05,25000]],"ltp":2.54,"tv":10.22,"id":40380900}]}]}
{"op":"mcm","clk":"11792259964","pt":1722537045503,"mc":[{"id":"1.231243109","rc":[{"batb":[[0,1.7,10],[1,1.05,25000],[2,1.04,25000]],"ltp":2.54,"tv":10.22,"id":40380900}]}]}
{"op":"mcm","clk":"11792271007","pt":1722537121978,"mc":[{"id":"1.231243109","rc":[{"batb":[[0,2.54,10],[1,2.52,11.45],[2,1.7,10]],"ltp":2.54,"tv":10.22,"id":40380900}]}]}
{"op":"mcm","clk":"11792271318","pt":1722537124110,"mc":[{"id":"1.231243109","rc":[{"batb":[[1,1.7,10],[2,1.05,25000]],"ltp":2.54,"tv":10.22,"id":40380900}]}]}
{"op":"mcm","clk":"11792271499","pt":1722537125217,"mc":[{"id":"1.231243109","rc":[{"batb":[[0,1.7,10],[1,1.05,25000],[2,1.04,25000]],"ltp":2.54,"tv":10.22,"id":40380900}]}]}
{"op":"mcm","clk":"11792285176","pt":1722537217984,"mc":[{"id":"1.231243109","rc":[{"batb":[[0,1.71,10],[1,1.7,10],[2,1.05,25000]],"ltp":2.54,"tv":10.22,"id":40380900}]}]}
{"op":"mcm","clk":"11792285629","pt":1722537221384,"mc":[{"id":"1.231243109","rc":[{"batb":[[0,1.7,10],[1,1.05,25000],[2,1.04,25000]],"ltp":2.54,"tv":10.22,"id":40380900}]}]}
{"op":"mcm","clk":"11792287192","pt":1722537231492,"mc":[{"id":"1.231243109","rc":[{"batb":[[0,1.71,10],[1,1.7,10],[2,1.05,25000]],"ltp":2.54,"tv":10.22,"id":40380900}]}]}
{"op":"mcm","clk":"11792287664","pt":1722537235073,"mc":[{"id":"1.231243109","rc":[{"batb":[[0,2.52,11.09]],"ltp":2.54,"tv":10.22,"id":40380900}]}]}
{"op":"mcm","clk":"11792321019","pt":1722537459659,"mc":[{"id":"1.231243109","rc":[{"batb":[[0,2.54,10],[1,2.52,11.09],[2,1.7,10]],"ltp":2.54,"tv":10.22,"id":40380900}]}]}
{"op":"mcm","clk":"11792321329","pt":1722537461568,"mc":[{"id":"1.231243109","rc":[{"batb":[[1,1.7,10],[2,1.05,25000]],"ltp":2.54,"tv":10.22,"id":40380900}]}]}
{"op":"mcm","clk":"11792321560","pt":1722537463029,"mc":[{"id":"1.231243109","rc":[{"batb":[[0,1.7,10],[1,1.05,25000],[2,1.04,25000]],"ltp":2.54,"tv":10.22,"id":40380900}]}]}
{"op":"mcm","clk":"11792321636","pt":1722537463550,"mc":[{"id":"1.231243109","rc":[{"batb":[[0,2.52,10.99],[1,1.7,10],[2,1.05,25000]],"ltp":2.54,"tv":10.22,"id":40380900}]}]}
{"op":"mcm","clk":"11792327093","pt":1722537500874,"mc":[{"id":"1.231243109","rc":[{"batb":[[0,2.54,10],[1,2.52,10.99],[2,1.7,10]],"ltp":2.54,"tv":10.22,"id":40380900}]}]}
{"op":"mcm","clk":"11792327473","pt":1722537503150,"mc":[{"id":"1.231243109","rc":[{"batb":[[1,1.7,10],[2,1.05,25000]],"ltp":2.54,"tv":10.22,"id":40380900}]}]}
{"op":"mcm","clk":"11792327625","pt":1722537504151,"mc":[{"id":"1.231243109","rc":[{"batb":[[0,1.7,10],[1,1.05,25000],[2,1.04,25000]],"ltp":2.54,"tv":10.22,"id":40380900}]}]}
{"op":"mcm","clk":"11792338701","pt":1722537577273,"mc":[{"id":"1.231243109","rc":[{"batb":[[0,2.52,11.48],[1,1.7,10],[2,1.05,25000]],"ltp":2.54,"tv":10.22,"id":40380900}]}]}
{"op":"mcm","clk":"11792338720","pt":1722537577375,"mc":[{"id":"1.231243109","rc":[{"batb":[[0,2.54,10],[1,2.52,11.48],[2,1.7,10]],"ltp":2.54,"tv":10.22,"id":40380900}]}]}
{"op":"mcm","clk":"11792339056","pt":1722537579557,"mc":[{"id":"1.231243109","rc":[{"batb":[[1,1.7,10],[2,1.05,25000]],"ltp":2.54,"tv":10.22,"id":40380900}]}]}
{"op":"mcm","clk":"11792339214","pt":1722537580685,"mc":[{"id":"1.231243109","rc":[{"batb":[[0,1.7,10],[1,1.05,25000],[2,1.04,25000]],"ltp":2.54,"tv":10.22,"id":40380900}]}]}
{"op":"mcm","clk":"11792349565","pt":1722537645345,"mc":[{"id":"1.231243109","rc":[{"batb":[[0,1.71,10],[1,1.7,10],[2,1.05,25000]],"ltp":2.54,"tv":10.22,"id":40380900}]}]}
{"op":"mcm","clk":"11792350139","pt":1722537649259,"mc":[{"id":"1.231243109","rc":[{"batb":[[0,1.7,10],[1,1.05,25000],[2,1.04,25000]],"ltp":2.54,"tv":10.22,"id":40380900}]}]}
{"op":"mcm","clk":"11792356884","pt":1722537692221,"mc":[{"id":"1.231243109","rc":[{"batb":[[0,2.54,10],[1,2.52,11.4],[2,1.7,10]],"ltp":2.54,"tv":10.22,"id":40380900}]}]}
{"op":"mcm","clk":"11792357178","pt":1722537694216,"mc":[{"id":"1.231243109","rc":[{"batb":[[1,1.7,10],[2,1.05,25000]],"ltp":2.54,"tv":10.22,"id":40380900}]}]}
{"op":"mcm","clk":"11792357392","pt":1722537695679,"mc":[{"id":"1.231243109","rc":[{"batb":[[0,1.7,10],[1,1.05,25000],[2,1.04,25000]],"ltp":2.54,"tv":10.22,"id":40380900}]}]}
{"op":"mcm","clk":"11792384784","pt":1722537807942,"mc":[{"id":"1.231243109","rc":[{"batb":[[0,2.54,10],[1,2.52,11.04],[2,1.7,10]],"ltp":2.54,"tv":10.22,"id":40380900}]}]}
{"op":"mcm","clk":"11792385015","pt":1722537809533,"mc":[{"id":"1.231243109","rc":[{"batb":[[1,1.7,10],[2,1.05,25000]],"ltp":2.54,"tv":10.22,"id":40380900}]}]}
{"op":"mcm","clk":"11792385310","pt":1722537811284,"mc":[{"id":"1.231243109","rc":[{"batb":[[0,1.7,10],[1,1.05,25000],[2,1.04,25000]],"ltp":2.54,"tv":10.22,"id":40380900}]}]}
{"op":"mcm","clk":"11792402688","pt":1722537921380,"mc":[{"id":"1.231243109","rc":[{"batb":[[0,2.54,10],[1,2.52,11.09],[2,1.7,10]],"ltp":2.54,"tv":10.22,"id":40380900}]}]}
{"op":"mcm","clk":"11792403079","pt":1722537923819,"mc":[{"id":"1.231243109","rc":[{"batb":[[1,1.7,10],[2,1.05,25000]],"ltp":2.54,"tv":10.22,"id":40380900}]}]}
{"op":"mcm","clk":"11792403224","pt":1722537924713,"mc":[{"id":"1.231243109","rc":[{"batb":[[0,1.7,10],[1,1.05,25000],[2,1.04,25000]],"ltp":2.54,"tv":10.22,"id":40380900}]}]}
{"op":"mcm","clk":"11792410103","pt":1722537966477,"mc":[{"id":"1.231243109","rc":[{"batb":[[0,1.71,10],[1,1.7,10],[2,1.05,25000]],"ltp":2.54,"tv":10.22,"id":40380900}]}]}
{"op":"mcm","clk":"11792410698","pt":1722537969879,"mc":[{"id":"1.231243109","rc":[{"batb":[[0,1.7,10],[1,1.05,25000],[2,1.04,25000]],"ltp":2.54,"tv":10.22,"id":40380900}]}]}
{"op":"mcm","clk":"11792412361","pt":1722537978943,"mc":[{"id":"1.231243109","rc":[{"batb":[[0,1.71,10],[1,1.7,10],[2,1.05,25000]],"ltp":2.54,"tv":10.22,"id":40380900}]}]}
{"op":"mcm","clk":"11792412921","pt":1722537982362,"mc":[{"id":"1.231243109","rc":[{"batb":[[0,1.7,10],[1,1.05,25000],[2,1.04,25000]],"ltp":2.54,"tv":10.22,"id":40380900}]}]}
{"op":"mcm","clk":"11792414886","pt":1722537993857,"mc":[{"id":"1.231243109","rc":[{"batb":[[0,1.71,10],[1,1.7,10],[2,1.05,25000]],"ltp":2.54,"tv":10.22,"id":40380900},{"batb":[[2,1.58,124]],"ltp":1.65,"tv":73.55,"id":40380901}]}]}
{"op":"mcm","clk":"11792414998","pt":1722537994497,"mc":[{"id":"1.231243109","rc":[{"batb":[[1,1.59,17.65]],"ltp":1.65,"tv":73.55,"id":40380901}]}]}
{"op":"mcm","clk":"11792415449","pt":1722537997162,"mc":[{"id":"1.231243109","rc":[{"batb":[[0,1.7,10],[1,1.05,25000],[2,1.04,25000]],"ltp":2.54,"tv":10.22,"id":40380900}]}]}
{"op":"mcm","clk":"11792416374","pt":1722538002883,"mc":[{"id":"1.231243109","rc":[{"batb":[[0,1.71,10],[1,1.7,10],[2,1.05,25000]],"ltp":2.54,"tv":10.22,"id":40380900}]}]}
{"op":"mcm","clk":"11792416944","pt":1722538006434,"mc":[{"id":"1.231243109","rc":[{"batb":[[0,1.7,10],[1,1.05,25000],[2,1.04,25000]],"ltp":2.54,"tv":10.22,"id":40380900}]}]}
{"op":"mcm","clk":"11792417961","pt":1722538013111,"mc":[{"id":"1.231243109","rc":[{"batb":[[0,1.71,10],[1,1.7,10],[2,1.05,25000]],"ltp":2.54,"tv":10.22,"id":40380900}]}]}
{"op":"mcm","clk":"11792418472","pt":1722538016631,"mc":[{"id":"1.231243109","rc":[{"batb":[[0,1.7,10],[1,1.05,25000],[2,1.04,25000]],"ltp":2.54,"tv":10.22,"id":40380900}]}]}
{"op":"mcm","clk":"11792421523","pt":1722538035267,"mc":[{"id":"1.231243109","rc":[{"batb":[[0,2.52,11.35],[1,1.7,10],[2,1.05,25000]],"ltp":2.54,"tv":10.22,"id":40380900}]}]}
{"op":"mcm","clk":"11792421560","pt":1722538035438,"mc":[{"id":"1.231243109","rc":[{"batb":[[0,2.54,10],[1,2.52,11.35],[2,1.7,10]],"ltp":2.54,"tv":10.22,"id":40380900}]}]}
{"op":"mcm","clk":"11792421971","pt":1722538037941,"mc":[{"id":"1.231243109","rc":[{"batb":[[1,1.7,10],[2,1.05,25000]],"ltp":2.54,"tv":10.22,"id":40380900}]}]}
{"op":"mcm","clk":"11792422082","pt":1722538038743,"mc":[{"id":"1.231243109","rc":[{"batb":[[0,1.7,10],[1,1.05,25000],[2,1.04,25000]],"ltp":2.54,"tv":10.22,"id":40380900}]}]}
{"op":"mcm","clk":"11792423826","pt":1722538049583,"mc":[{"id":"1.231243109","rc":[{"batb":[[0,1.71,10],[1,1.7,10],[2,1.05,25000]],"ltp":2.54,"tv":10.22,"id":40380900}]}]}
{"op":"mcm","clk":"11792424378","pt":1722538053206,"mc":[{"id":"1.231243109","rc":[{"batb":[[0,1.7,10],[1,1.05,25000],[2,1.04,25000]],"ltp":2.54,"tv":10.22,"id":40380900}]}]}
{"op":"mcm","clk":"11792425388","pt":1722538060212,"mc":[{"id":"1.231243109","rc":[{"batb":[[0,1.71,10],[1,1.7,10],[2,1.05,25000]],"ltp":2.54,"tv":10.22,"id":40380900}]}]}
{"op":"mcm","clk":"11792425928","pt":1722538063501,"mc":[{"id":"1.231243109","rc":[{"batb":[[0,1.7,10],[1,1.05,25000],[2,1.04,25000]],"ltp":2.54,"tv":10.22,"id":40380900}]}]}
{"op":"mcm","clk":"11792427120","pt":1722538071231,"mc":[{"id":"1.231243109","rc":[{"batl":[[0,1.66,2368.95]],"ltp":1.65,"tv":73.55,"id":40380901}]}]}
{"op":"mcm","clk":"11792427139","pt":1722538071337,"mc":[{"id":"1.231243109","rc":[{"batb":[[0,1.71,10],[1,1.7,10],[2,1.05,25000]],"ltp":2.54,"tv":10.22,"id":40380900}]}]}
{"op":"mcm","clk":"11792427664","pt":1722538074618,"mc":[{"id":"1.231243109","rc":[{"batb":[[0,1.7,10],[1,1.05,25000],[2,1.04,25000]],"ltp":2.54,"tv":10.22,"id":40380900}]}]}
{"op":"mcm","clk":"11792428337","pt":1722538079229,"mc":[{"id":"1.231243109","rc":[{"batb":[[0,1.71,10],[1,1.7,10],[2,1.05,25000]],"ltp":2.54,"tv":10.22,"id":40380900}]}]}
{"op":"mcm","clk":"11792428558","pt":1722538080639,"mc":[{"id":"1.231243109","rc":[{"batl":[[0,1.66,2350.74]],"ltp":1.65,"tv":73.55,"id":40380901}]}]}
{"op":"mcm","clk":"11792428819","pt":1722538082562,"mc":[{"id":"1.231243109","rc":[{"batb":[[0,1.7,10],[1,1.05,25000],[2,1.04,25000]],"ltp":2.54,"tv":10.22,"id":40380900}]}]}
{"op":"mcm","clk":"11792430406","pt":1722538093438,"mc":[{"id":"1.231243109","rc":[{"batb":[[0,1.71,10],[1,1.7,10],[2,1.05,25000]],"ltp":2.54,"tv":10.22,"id":40380900},{"batl":[[0,1.66,2332.53]],"ltp":1.65,"tv":73.55,"id":40380901}]}]}
{"op":"mcm","clk":"11792430859","pt":1722538096643,"mc":[{"id":"1.231243109","rc":[{"batb":[[0,1.7,10],[1,1.05,25000],[2,1.04,25000]],"ltp":2.54,"tv":10.22,"id":40380900}]}]}
{"op":"mcm","clk":"11792432832","pt":1722538109347,"mc":[{"id":"1.231243109","rc":[{"batb":[[0,1.71,10],[1,1.7,10],[2,1.05,25000]],"ltp":2.54,"tv":10.22,"id":40380900}]}]}
{"op":"mcm","clk":"11792433292","pt":1722538112773,"mc":[{"id":"1.231243109","rc":[{"batb":[[0,1.7,10],[1,1.05,25000],[2,1.04,25000]],"ltp":2.54,"tv":10.22,"id":40380900}]}]}
{"op":"mcm","clk":"11792434816","pt":1722538123359,"mc":[{"id":"1.231243109","rc":[{"batb":[[0,1.71,10],[1,1.7,10],[2,1.05,25000]],"ltp":2.54,"tv":10.22,"id":40380900}]}]}
{"op":"mcm","clk":"11792435322","pt":1722538126763,"mc":[{"id":"1.231243109","rc":[{"batb":[[0,1.7,10],[1,1.05,25000],[2,1.04,25000]],"ltp":2.54,"tv":10.22,"id":40380900}]}]}
{"op":"mcm","clk":"11792436228","pt":1722538133083,"mc":[{"id":"1.231243109","rc":[{"batb":[[0,1.71,10],[1,1.7,10],[2,1.05,25000]],"ltp":2.54,"tv":10.22,"id":40380900}]}]}
{"op":"mcm","clk":"11792436712","pt":1722538136515,"mc":[{"id":"1.231243109","rc":[{"batb":[[0,1.7,10],[1,1.05,25000],[2,1.04,25000]],"ltp":2.54,"tv":10.22,"id":40380900}]}]}
{"op":"mcm","clk":"11792437139","pt":1722538139329,"mc":[{"id":"1.231243109","rc":[{"batb":[[0,1.71,10],[1,1.7,10],[2,1.05,25000]],"ltp":2.54,"tv":10.22,"id":40380900}]}]}
{"op":"mcm","clk":"11792437642","pt":1722538142710,"mc":[{"id":"1.231243109","rc":[{"batb":[[0,1.7,10],[1,1.05,25000],[2,1.04,25000]],"ltp":2.54,"tv":10.22,"id":40380900}]}]}
{"op":"mcm","clk":"11792438676","pt":1722538149873,"mc":[{"id":"1.231243109","rc":[{"batb":[[0,2.54,10],[1,2.52,11.46],[2,1.7,10]],"ltp":2.54,"tv":10.22,"id":40380900}]}]}
{"op":"mcm","clk":"11792438914","pt":1722538151536,"mc":[{"id":"1.231243109","rc":[{"batb":[[1,1.7,10],[2,1.05,25000]],"ltp":2.54,"tv":10.22,"id":40380900}]}]}
{"op":"mcm","clk":"11792439137","pt":1722538153233,"mc":[{"id":"1.231243109","rc":[{"batb":[[0,1.7,10],[1,1.05,25000],[2,1.04,25000]],"ltp":2.54,"tv":10.22,"id":40380900}]}]}
{"op":"mcm","clk":"11792440163","pt":1722538160236,"mc":[{"id":"1.231243109","rc":[{"batb":[[0,1.71,10],[1,1.7,10],[2,1.05,25000]],"ltp":2.54,"tv":10.22,"id":40380900}]}]}
{"op":"mcm","clk":"11792440714","pt":1722538163638,"mc":[{"id":"1.231243109","rc":[{"batb":[[0,1.7,10],[1,1.05,25000],[2,1.04,25000]],"ltp":2.54,"tv":10.22,"id":40380900}]}]}
{"op":"mcm","clk":"11792442000","pt":1722538172018,"mc":[{"id":"1.231243109","rc":[{"batb":[[0,1.71,10],[1,1.7,10],[2,1.05,25000]],"ltp":2.54,"tv":10.22,"id":40380900}]}]}
{"op":"mcm","clk":"11792442526","pt":1722538175455,"mc":[{"id":"1.231243109","rc":[{"batb":[[0,1.7,10],[1,1.05,25000],[2,1.04,25000]],"ltp":2.54,"tv":10.22,"id":40380900}]}]}
{"op":"mcm","clk":"11792442921","pt":1722538177957,"mc":[{"id":"1.231243109","rc":[{"batb":[[0,1.71,10],[1,1.7,10],[2,1.05,25000]],"ltp":2.54,"tv":10.22,"id":40380900}]}]}
{"op":"mcm","clk":"11792443379","pt":1722538181371,"mc":[{"id":"1.231243109","rc":[{"batb":[[0,1.7,10],[1,1.05,25000],[2,1.04,25000]],"ltp":2.54,"tv":10.22,"id":40380900}]}]}
{"op":"mcm","clk":"11792445834","pt":1722538199877,"mc":[{"id":"1.231243109","rc":[{"batb":[[0,1.71,10],[1,1.7,10],[2,1.05,25000]],"ltp":2.54,"tv":10.22,"id":40380900}]}]}
{"op":"mcm","clk":"11792446244","pt":1722538203198,"mc":[{"id":"1.231243109","rc":[{"batb":[[0,1.7,10],[1,1.05,25000],[2,1.04,25000]],"ltp":2.54,"tv":10.22,"id":40380900}]}]}
{"op":"mcm","clk":"11792451233","pt":1722538237340,"mc":[{"id":"1.231243109","rc":[{"batb":[[0,1.71,10],[1,1.7,10],[2,1.05,25000]],"ltp":2.54,"tv":10.22,"id":40380900}]}]}
{"op":"mcm","clk":"11792451684","pt":1722538240624,"mc":[{"id":"1.231243109","rc":[{"batb":[[0,1.7,10],[1,1.05,25000],[2,1.04,25000]],"ltp":2.54,"tv":10.22,"id":40380900}]}]}
{"op":"mcm","clk":"11792454575","pt":1722538263580,"mc":[{"id":"1.231243109","rc":[{"batb":[[0,2.54,10],[1,2.52,11.47],[2,1.7,10]],"ltp":2.54,"tv":10.22,"id":40380900}]}]}
{"op":"mcm","clk":"11792454805","pt":1722538265409,"mc":[{"id":"1.231243109","rc":[{"batb":[[1,1.7,10],[2,1.05,25000]],"ltp":2.54,"tv":10.22,"id":40380900}]}]}
{"op":"mcm","clk":"11792454979","pt":1722538266793,"mc":[{"id":"1.231243109","rc":[{"batb":[[0,1.7,10],[1,1.05,25000],[2,1.04,25000]],"ltp":2.54,"tv":10.22,"id":40380900}]}]}
{"op":"mcm","clk":"11792458237","pt":1722538293433,"mc":[{"id":"1.231243109","rc":[{"batb":[[0,1.71,10],[1,1.7,10],[2,1.05,25000]],"ltp":2.54,"tv":10.22,"id":40380900}]}]}
{"op":"mcm","clk":"11792458738","pt":1722538296740,"mc":[{"id":"1.231243109","rc":[{"batb":[[0,1.7,10],[1,1.05,25000],[2,1.04,25000]],"ltp":2.54,"tv":10.22,"id":40380900}]}]}
{"op":"mcm","clk":"11792460479","pt":1722538310451,"mc":[{"id":"1.231243109","rc":[{"batb":[[0,1.71,10],[1,1.7,10],[2,1.05,25000]],"ltp":2.54,"tv":10.22,"id":40380900}]}]}
{"op":"mcm","clk":"11792460850","pt":1722538313941,"mc":[{"id":"1.231243109","rc":[{"batb":[[0,1.7,10],[1,1.05,25000],[2,1.04,25000]],"ltp":2.54,"tv":10.22,"id":40380900}]}]}
{"op":"mcm","clk":"11792463289","pt":1722538333861,"mc":[{"id":"1.231243109","rc":[{"batb":[[0,1.71,10],[1,1.7,10],[2,1.05,25000]],"ltp":2.54,"tv":10.22,"id":40380900}]}]}
{"op":"mcm","clk":"11792463806","pt":1722538337360,"mc":[{"id":"1.231243109","rc":[{"batb":[[0,1.7,10],[1,1.05,25000],[2,1.04,25000]],"ltp":2.54,"tv":10.22,"id":40380900}]}]}
{"op":"mcm","clk":"11792466282","pt":1722538357687,"mc":[{"id":"1.231243109","rc":[{"batb":[[0,1.71,10],[1,1.7,10],[2,1.05,25000]],"ltp":2.54,"tv":10.22,"id":40380900}]}]}
{"op":"mcm","clk":"11792466682","pt":1722538361194,"mc":[{"id":"1.231243109","rc":[{"batb":[[0,1.7,10],[1,1.05,25000],[2,1.04,25000]],"ltp":2.54,"tv":10.22,"id":40380900}]}]}
{"op":"mcm","clk":"11792467367","pt":1722538366894,"mc":[{"id":"1.231243109","rc":[{"batb":[[0,1.71,10],[1,1.7,10],[2,1.05,25000]],"ltp":2.54,"tv":10.22,"id":40380900}]}]}
{"op":"mcm","clk":"11792467797","pt":1722538370199,"mc":[{"id":"1.231243109","rc":[{"batb":[[0,1.7,10],[1,1.05,25000],[2,1.04,25000]],"ltp":2.54,"tv":10.22,"id":40380900}]}]}
{"op":"mcm","clk":"11792468823","pt":1722538379004,"mc":[{"id":"1.231243109","rc":[{"batb":[[0,2.54,10],[1,2.52,11.13],[2,1.7,10]],"ltp":2.54,"tv":10.22,"id":40380900}]}]}
{"op":"mcm","clk":"11792469101","pt":1722538381390,"mc":[{"id":"1.231243109","rc":[{"batb":[[1,1.7,10],[2,1.05,25000]],"ltp":2.54,"tv":10.22,"id":40380900}]}]}
{"op":"mcm","clk":"11792469207","pt":1722538382321,"mc":[{"id":"1.231243109","rc":[{"batb":[[0,1.7,10],[1,1.05,25000],[2,1.04,25000]],"ltp":2.54,"tv":10.22,"id":40380900}]}]}
{"op":"mcm","clk":"11792469531","pt":1722538385029,"mc":[{"id":"1.231243109","rc":[{"batb":[[0,1.71,10],[1,1.7,10],[2,1.05,25000]],"ltp":2.54,"tv":10.22,"id":40380900}]}]}
{"op":"mcm","clk":"11792469899","pt":1722538388422,"mc":[{"id":"1.231243109","rc":[{"batb":[[0,1.7,10],[1,1.05,25000],[2,1.04,25000]],"ltp":2.54,"tv":10.22,"id":40380900}]}]}
{"op":"mcm","clk":"11792471177","pt":1722538398751,"mc":[{"id":"1.231243109","rc":[{"batb":[[0,1.71,10],[1,1.7,10],[2,1.05,25000]],"ltp":2.54,"tv":10.22,"id":40380900}]}]}
{"op":"mcm","clk":"11792471561","pt":1722538402082,"mc":[{"id":"1.231243109","rc":[{"batb":[[0,1.7,10],[1,1.05,25000],[2,1.04,25000]],"ltp":2.54,"tv":10.22,"id":40380900}]}]}
{"op":"mcm","clk":"11792472433","pt":1722538409775,"mc":[{"id":"1.231243109","rc":[{"batb":[[0,1.71,10],[1,1.7,10],[2,1.05,25000]],"ltp":2.54,"tv":10.22,"id":40380900}]}]}
{"op":"mcm","clk":"11792472803","pt":1722538413266,"mc":[{"id":"1.231243109","rc":[{"batb":[[0,1.7,10],[1,1.05,25000],[2,1.04,25000]],"ltp":2.54,"tv":10.22,"id":40380900}]}]}
{"op":"mcm","clk":"11792473744","pt":1722538422292,"mc":[{"id":"1.231243109","rc":[{"batb":[[0,1.71,10],[1,1.7,10],[2,1.05,25000]],"ltp":2.54,"tv":10.22,"id":40380900}]}]}
{"op":"mcm","clk":"11792474090","pt":1722538425893,"mc":[{"id":"1.231243109","rc":[{"batb":[[0,1.7,10],[1,1.05,25000],[2,1.04,25000]],"ltp":2.54,"tv":10.22,"id":40380900}]}]}
{"op":"mcm","clk":"11792474351","pt":1722538428186,"mc":[{"id":"1.231243109","rc":[{"batb":[[0,1.71,10],[1,1.7,10],[2,1.05,25000]],"ltp":2.54,"tv":10.22,"id":40380900}]}]}
{"op":"mcm","clk":"11792474729","pt":1722538431693,"mc":[{"id":"1.231243109","rc":[{"batb":[[0,1.7,10],[1,1.05,25000],[2,1.04,25000]],"ltp":2.54,"tv":10.22,"id":40380900}]}]}
{"op":"mcm","clk":"11792475556","pt":1722538439199,"mc":[{"id":"1.231243109","rc":[{"batb":[[0,1.71,10],[1,1.7,10],[2,1.05,25000]],"ltp":2.54,"tv":10.22,"id":40380900}]}]}
{"op":"mcm","clk":"11792475929","pt":1722538442594,"mc":[{"id":"1.231243109","rc":[{"batb":[[0,1.7,10],[1,1.05,25000],[2,1.04,25000]],"ltp":2.54,"tv":10.22,"id":40380900}]}]}
{"op":"mcm","clk":"11792476734","pt":1722538448902,"mc":[{"id":"1.231243109","rc":[{"batb":[[0,1.71,10],[1,1.7,10],[2,1.05,25000]],"ltp":2.54,"tv":10.22,"id":40380900}]}]}
{"op":"mcm","clk":"11792477174","pt":1722538452423,"mc":[{"id":"1.231243109","rc":[{"batb":[[0,1.7,10],[1,1.05,25000],[2,1.04,25000]],"ltp":2.54,"tv":10.22,"id":40380900}]}]}
{"op":"mcm","clk":"11792477659","pt":1722538457314,"mc":[{"id":"1.231243109","rc":[{"batb":[[0,1.71,10],[1,1.7,10],[2,1.05,25000]],"ltp":2.54,"tv":10.22,"id":40380900}]}]}
{"op":"mcm","clk":"11792478012","pt":1722538460705,"mc":[{"id":"1.231243109","rc":[{"batb":[[0,1.7,10],[1,1.05,25000],[2,1.04,25000]],"ltp":2.54,"tv":10.22,"id":40380900}]}]}
{"op":"mcm","clk":"11792478380","pt":1722538464121,"mc":[{"id":"1.231243109","rc":[{"batb":[[0,1.71,10],[1,1.7,10],[2,1.05,25000]],"ltp":2.54,"tv":10.22,"id":40380900}]}]}
{"op":"mcm","clk":"11792478740","pt":1722538467530,"mc":[{"id":"1.231243109","rc":[{"batb":[[0,1.7,10],[1,1.05,25000],[2,1.04,25000]],"ltp":2.54,"tv":10.22,"id":40380900}]}]}
{"op":"mcm","clk":"11792479070","pt":1722538470641,"mc":[{"id":"1.231243109","rc":[{"batb":[[0,1.71,10],[1,1.7,10],[2,1.05,25000]],"ltp":2.54,"tv":10.22,"id":40380900}]}]}
{"op":"mcm","clk":"11792479410","pt":1722538474027,"mc":[{"id":"1.231243109","rc":[{"batb":[[0,1.7,10],[1,1.05,25000],[2,1.04,25000]],"ltp":2.54,"tv":10.22,"id":40380900}]}]}
{"op":"mcm","clk":"11792480678","pt":1722538485228,"mc":[{"id":"1.231243109","rc":[{"batb":[[0,1.71,10],[1,1.7,10],[2,1.05,25000]],"ltp":2.54,"tv":10.22,"id":40380900}]}]}
{"op":"mcm","clk":"11792481026","pt":1722538488664,"mc":[{"id":"1.231243109","rc":[{"batb":[[0,1.7,10],[1,1.05,25000],[2,1.04,25000]],"ltp":2.54,"tv":10.22,"id":40380900}]}]}
{"op":"mcm","clk":"11792481727","pt":1722538495257,"mc":[{"id":"1.231243109","rc":[{"batb":[[0,2.54,10],[1,2.52,11.41],[2,1.7,10]],"ltp":2.54,"tv":10.22,"id":40380900}]}]}
{"op":"mcm","clk":"11792481880","pt":1722538496763,"mc":[{"id":"1.231243109","rc":[{"batb":[[1,1.7,10],[2,1.05,25000]],"ltp":2.54,"tv":10.22,"id":40380900}]}]}
{"op":"mcm","clk":"11792482093","pt":1722538498765,"mc":[{"id":"1.231243109","rc":[{"batb":[[0,1.7,10],[1,1.05,25000],[2,1.04,25000]],"ltp":2.54,"tv":10.22,"id":40380900}]}]}
{"op":"mcm","clk":"11792482537","pt":1722538502966,"mc":[{"id":"1.231243109","rc":[{"batb":[[0,1.71,10],[1,1.7,10],[2,1.05,25000]],"ltp":2.54,"tv":10.22,"id":40380900}]}]}
{"op":"mcm","clk":"11792482907","pt":1722538506481,"mc":[{"id":"1.231243109","rc":[{"batb":[[0,1.7,10],[1,1.05,25000],[2,1.04,25000]],"ltp":2.54,"tv":10.22,"id":40380900}]}]}
{"op":"mcm","clk":"11792483358","pt":1722538510084,"mc":[{"id":"1.231243109","rc":[{"batb":[[0,1.71,10],[1,1.7,10],[2,1.05,25000]],"ltp":2.54,"tv":10.22,"id":40380900}]}]}
{"op":"mcm","clk":"11792483808","pt":1722538513344,"mc":[{"id":"1.231243109","rc":[{"batb":[[0,1.7,10],[1,1.05,25000],[2,1.04,25000]],"ltp":2.54,"tv":10.22,"id":40380900}]}]}
{"op":"mcm","clk":"11792486399","pt":1722538536883,"mc":[{"id":"1.231243109","rc":[{"batb":[[0,1.71,10],[1,1.7,10],[2,1.05,25000]],"ltp":2.54,"tv":10.22,"id":40380900}]}]}
{"op":"mcm","clk":"11792486712","pt":1722538540334,"mc":[{"id":"1.231243109","rc":[{"batb":[[0,1.7,10],[1,1.05,25000],[2,1.04,25000]],"ltp":2.54,"tv":10.22,"id":40380900}]}]}
{"op":"mcm","clk":"11792486973","pt":1722538542637,"mc":[{"id":"1.231243109","rc":[{"batb":[[0,1.71,10],[1,1.7,10],[2,1.05,25000]],"ltp":2.54,"tv":10.22,"id":40380900}]}]}
{"op":"mcm","clk":"11792487345","pt":1722538546132,"mc":[{"id":"1.231243109","rc":[{"batb":[[0,1.7,10],[1,1.05,25000],[2,1.04,25000]],"ltp":2.54,"tv":10.22,"id":40380900}]}]}
{"op":"mcm","clk":"11792488227","pt":1722538554838,"mc":[{"id":"1.231243109","rc":[{"batb":[[0,1.71,10],[1,1.7,10],[2,1.05,25000]],"ltp":2.54,"tv":10.22,"id":40380900}]}]}
{"op":"mcm","clk":"11792488559","pt":1722538558365,"mc":[{"id":"1.231243109","rc":[{"batb":[[0,1.7,10],[1,1.05,25000],[2,1.04,25000]],"ltp":2.54,"tv":10.22,"id":40380900}]}]}
{"op":"mcm","clk":"11792488973","pt":1722538562638,"mc":[{"id":"1.231243109","rc":[{"batb":[[0,1.71,10],[1,1.7,10],[2,1.05,25000]],"ltp":2.54,"tv":10.22,"id":40380900}]}]}
{"op":"mcm","clk":"11792489298","pt":1722538566008,"mc":[{"id":"1.231243109","rc":[{"batb":[[0,1.7,10],[1,1.05,25000],[2,1.04,25000]],"ltp":2.54,"tv":10.22,"id":40380900}]}]}
{"op":"mcm","clk":"11792490204","pt":1722538575223,"mc":[{"id":"1.231243109","rc":[{"batb":[[0,1.71,10],[1,1.7,10],[2,1.05,25000]],"ltp":2.54,"tv":10.22,"id":40380900}]}]}
{"op":"mcm","clk":"11792490502","pt":1722538578657,"mc":[{"id":"1.231243109","rc":[{"batb":[[0,1.7,10],[1,1.05,25000],[2,1.04,25000]],"ltp":2.54,"tv":10.22,"id":40380900}]}]}
{"op":"mcm","clk":"11792491545","pt":1722538589169,"mc":[{"id":"1.231243109","rc":[{"batb":[[0,1.71,10],[1,1.7,10],[2,1.05,25000]],"ltp":2.54,"tv":10.22,"id":40380900}]}]}
{"op":"mcm","clk":"11792491939","pt":1722538592568,"mc":[{"id":"1.231243109","rc":[{"batb":[[0,1.7,10],[1,1.05,25000],[2,1.04,25000]],"ltp":2.54,"tv":10.22,"id":40380900}]}]}
{"op":"mcm","clk":"11792493902","pt":1722538610089,"mc":[{"id":"1.231243109","rc":[{"batb":[[0,2.54,10],[1,2.52,11.01],[2,1.7,10]],"ltp":2.54,"tv":10.22,"id":40380900}]}]}
{"op":"mcm","clk":"11792494112","pt":1722538612083,"mc":[{"id":"1.231243109","rc":[{"batb":[[1,1.7,10],[2,1.05,25000]],"ltp":2.54,"tv":10.22,"id":40380900}]}]}
{"op":"mcm","clk":"11792494242","pt":1722538613388,"mc":[{"id":"1.231243109","rc":[{"batb":[[0,1.7,10],[1,1.05,25000],[2,1.04,25000]],"ltp":2.54,"tv":10.22,"id":40380900}]}]}
{"op":"mcm","clk":"11792494984","pt":1722538620206,"mc":[{"id":"1.231243109","rc":[{"batb":[[0,1.71,10],[1,1.7,10],[2,1.05,25000]],"ltp":2.54,"tv":10.22,"id":40380900}]}]}
{"op":"mcm","clk":"11792495331","pt":1722538623604,"mc":[{"id":"1.231243109","rc":[{"batb":[[0,1.7,10],[1,1.05,25000],[2,1.04,25000]],"ltp":2.54,"tv":10.22,"id":40380900}]}]}
{"op":"mcm","clk":"11792495917","pt":1722538629513,"mc":[{"id":"1.231243109","rc":[{"batb":[[0,1.71,10],[1,1.7,10],[2,1.05,25000]],"ltp":2.54,"tv":10.22,"id":40380900}]}]}
{"op":"mcm","clk":"11792496262","pt":1722538632913,"mc":[{"id":"1.231243109","rc":[{"batb":[[0,1.7,10],[1,1.05,25000],[2,1.04,25000]],"ltp":2.54,"tv":10.22,"id":40380900}]}]}
{"op":"mcm","clk":"11792496579","pt":1722538635689,"mc":[{"id":"1.231243109","rc":[{"batb":[[0,1.71,10],[1,1.7,10],[2,1.05,25000]],"ltp":2.54,"tv":10.22,"id":40380900}]}]}
{"op":"mcm","clk":"11792496923","pt":1722538639121,"mc":[{"id":"1.231243109","rc":[{"batb":[[0,1.7,10],[1,1.05,25000],[2,1.04,25000]],"ltp":2.54,"tv":10.22,"id":40380900}]}]}
{"op":"mcm","clk":"11792497250","pt":1722538642102,"mc":[{"id":"1.231243109","rc":[{"batb":[[0,1.71,10],[1,1.7,10],[2,1.05,25000]],"ltp":2.54,"tv":10.22,"id":40380900}]}]}
{"op":"mcm","clk":"11792497601","pt":1722538645704,"mc":[{"id":"1.231243109","rc":[{"batb":[[0,1.7,10],[1,1.05,25000],[2,1.04,25000]],"ltp":2.54,"tv":10.22,"id":40380900}]}]}
{"op":"mcm","clk":"11792498051","pt":1722538649337,"mc":[{"id":"1.231243109","rc":[{"batb":[[0,1.71,10],[1,1.7,10],[2,1.05,25000]],"ltp":2.54,"tv":10.22,"id":40380900}]}]}
{"op":"mcm","clk":"11792498427","pt":1722538652675,"mc":[{"id":"1.231243109","rc":[{"batb":[[0,1.7,10],[1,1.05,25000],[2,1.04,25000]],"ltp":2.54,"tv":10.22,"id":40380900}]}]}
{"op":"mcm","clk":"11792499219","pt":1722538660975,"mc":[{"id":"1.231243109","rc":[{"batb":[[0,1.71,10],[1,1.7,10],[2,1.05,25000]],"ltp":2.54,"tv":10.22,"id":40380900}]}]}
{"op":"mcm","clk":"11792499564","pt":1722538664302,"mc":[{"id":"1.231243109","rc":[{"batb":[[0,1.7,10],[1,1.05,25000],[2,1.04,25000]],"ltp":2.54,"tv":10.22,"id":40380900}]}]}
{"op":"mcm","clk":"11792500710","pt":1722538675314,"mc":[{"id":"1.231243109","rc":[{"batb":[[0,1.71,10],[1,1.7,10],[2,1.05,25000]],"ltp":2.54,"tv":10.22,"id":40380900}]}]}
{"op":"mcm","clk":"11792501003","pt":1722538678602,"mc":[{"id":"1.231243109","rc":[{"batb":[[0,1.7,10],[1,1.05,25000],[2,1.04,25000]],"ltp":2.54,"tv":10.22,"id":40380900}]}]}
{"op":"mcm","clk":"11792501792","pt":1722538685821,"mc":[{"id":"1.231243109","rc":[{"batb":[[0,1.71,10],[1,1.7,10],[2,1.05,25000]],"ltp":2.54,"tv":10.22,"id":40380900}]}]}
{"op":"mcm","clk":"11792502178","pt":1722538689012,"mc":[{"id":"1.231243109","rc":[{"batb":[[0,1.7,10],[1,1.05,25000],[2,1.04,25000]],"ltp":2.54,"tv":10.22,"id":40380900}]}]}
{"op":"mcm","clk":"11792504721","pt":1722538714543,"mc":[{"id":"1.231243109","rc":[{"batb":[[0,1.71,10],[1,1.7,10],[2,1.05,25000]],"ltp":2.54,"tv":10.22,"id":40380900},{"batb":[[1,1.59,23.74]],"ltp":1.65,"tv":73.55,"id":40380901}]}]}
{"op":"mcm","clk":"11792505058","pt":1722538718042,"mc":[{"id":"1.231243109","rc":[{"batb":[[0,1.7,10],[1,1.05,25000],[2,1.04,25000]],"ltp":2.54,"tv":10.22,"id":40380900}]}]}
{"op":"mcm","clk":"11792505651","pt":1722538723572,"mc":[{"id":"1.231243109","rc":[{"batb":[[0,2.54,10],[1,2.52,11.48],[2,1.7,10]],"ltp":2.54,"tv":10.22,"id":40380900}]}]}
{"op":"mcm","clk":"11792505841","pt":1722538725350,"mc":[{"id":"1.231243109","rc":[{"batb":[[1,1.7,10],[2,1.05,25000]],"ltp":2.54,"tv":10.22,"id":40380900}]}]}
{"op":"mcm","clk":"11792505983","pt":1722538726856,"mc":[{"id":"1.231243109","rc":[{"batb":[[0,1.7,10],[1,1.05,25000],[2,1.04,25000]],"ltp":2.54,"tv":10.22,"id":40380900}]}]}
{"op":"mcm","clk":"11792514740","pt":1722538807246,"mc":[{"id":"1.231243109","rc":[{"batb":[[0,2.54,10],[1,2.52,11.33],[2,1.7,10]],"batl":[[0,6,1.57]],"ltp":2.54,"tv":10.22,"id":40380900},{"trd":[[1.65,49.42]],"batb":[[1,1.59,23.75]],"ltp":1.65,"tv":73.55,"id":40380901}],"tv":83.78}]}
{"op":"mcm","clk":"11792515136","pt":1722538810614,"mc":[{"id":"1.231243109","rc":[{"batb":[[0,2.52,11.33],[1,1.7,10],[2,1.05,25000]],"ltp":2.54,"tv":10.22,"id":40380900}]}]}
{"op":"mcm","clk":"11792571494","pt":1722539309512,"mc":[{"id":"1.231243109","rc":[{"batb":[[0,2.54,10],[1,2.52,11.33],[2,1.7,10]],"ltp":2.54,"tv":10.22,"id":40380900}]}]}
{"op":"mcm","clk":"11792571705","pt":1722539311277,"mc":[{"id":"1.231243109","rc":[{"batb":[[1,1.7,10],[2,1.05,25000]],"ltp":2.54,"tv":10.22,"id":40380900}]}]}
{"op":"mcm","clk":"11792571924","pt":1722539313162,"mc":[{"id":"1.231243109","rc":[{"batb":[[0,2.52,11.42]],"ltp":2.54,"tv":10.22,"id":40380900}]}]}
{"op":"mcm","clk":"11792576067","pt":1722539351845,"mc":[{"id":"1.231243109","rc":[{"batb":[[0,2.54,10]],"ltp":2.54,"tv":10.22,"id":40380900}]}]}
{"op":"mcm","clk":"11792576423","pt":1722539355118,"mc":[{"id":"1.231243109","rc":[{"batb":[[0,1.7,10],[1,1.05,25000],[2,1.04,25000]],"ltp":2.54,"tv":10.22,"id":40380900}]}]}
{"op":"mcm","clk":"11792584577","pt":1722539426100,"mc":[{"id":"1.231243109","rc":[{"batb":[[0,2.54,10],[1,2.52,11.35],[2,1.7,10]],"ltp":2.54,"tv":10.22,"id":40380900}]}]}
{"op":"mcm","clk":"11792584845","pt":1722539428112,"mc":[{"id":"1.231243109","rc":[{"batb":[[1,1.7,10],[2,1.05,25000]],"ltp":2.54,"tv":10.22,"id":40380900}]}]}
{"op":"mcm","clk":"11792585034","pt":1722539429528,"mc":[{"id":"1.231243109","rc":[{"batb":[[0,1.7,10],[1,1.05,25000],[2,1.04,25000]],"ltp":2.54,"tv":10.22,"id":40380900}]}]}
{"op":"mcm","clk":"11792590704","pt":1722539479822,"mc":[{"id":"1.231243109","rc":[{"batb":[[0,1.71,10],[1,1.7,10],[2,1.05,25000]],"ltp":2.54,"tv":10.22,"id":40380900}]}]}
{"op":"mcm","clk":"11792591112","pt":1722539483408,"mc":[{"id":"1.231243109","rc":[{"batb":[[0,1.7,10],[1,1.05,25000],[2,1.04,25000]],"ltp":2.54,"tv":10.22,"id":40380900}]}]}
{"op":"mcm","clk":"11792597889","pt":1722539541277,"mc":[{"id":"1.231243109","rc":[{"batb":[[0,2.54,10],[1,2.52,11.33],[2,1.7,10]],"ltp":2.54,"tv":10.22,"id":40380900}]}]}
{"op":"mcm","clk":"11792598127","pt":1722539543182,"mc":[{"id":"1.231243109","rc":[{"batb":[[1,1.7,10],[2,1.05,25000]],"ltp":2.54,"tv":10.22,"id":40380900}]}]}
{"op":"mcm","clk":"11792598293","pt":1722539544633,"mc":[{"id":"1.231243109","rc":[{"batb":[[0,1.7,10],[1,1.05,25000],[2,1.04,25000]],"ltp":2.54,"tv":10.22,"id":40380900}]}]}
{"op":"mcm","clk":"11792611394","pt":1722539657278,"mc":[{"id":"1.231243109","rc":[{"batb":[[0,2.52,10.98],[1,1.7,10],[2,1.05,25000]],"ltp":2.54,"tv":10.22,"id":40380900}]}]}
{"op":"mcm","clk":"11792611411","pt":1722539657387,"mc":[{"id":"1.231243109","rc":[{"batb":[[0,2.54,10],[1,2.52,10.98],[2,1.7,10]],"ltp":2.54,"tv":10.22,"id":40380900}]}]}
{"op":"mcm","clk":"11792611677","pt":1722539659470,"mc":[{"id":"1.231243109","rc":[{"batb":[[1,1.7,10],[2,1.05,25000]],"ltp":2.54,"tv":10.22,"id":40380900}]}]}
{"op":"mcm","clk":"11792611829","pt":1722539660774,"mc":[{"id":"1.231243109","rc":[{"batb":[[0,1.7,10],[1,1.05,25000],[2,1.04,25000]],"ltp":2.54,"tv":10.22,"id":40380900}]}]}
{"op":"mcm","clk":"11792616353","pt":1722539700352,"mc":[{"id":"1.231243109","rc":[{"batb":[[0,1.71,10],[1,1.7,10],[2,1.05,25000]],"ltp":2.54,"tv":10.22,"id":40380900}]}]}
{"op":"mcm","clk":"11792616799","pt":1722539703720,"mc":[{"id":"1.231243109","rc":[{"batb":[[0,1.7,10],[1,1.05,25000],[2,1.04,25000]],"ltp":2.54,"tv":10.22,"id":40380900}]}]}
{"op":"mcm","clk":"11792625035","pt":1722539773655,"mc":[{"id":"1.231243109","rc":[{"batb":[[0,2.54,10],[1,2.52,11.35],[2,1.7,10]],"ltp":2.54,"tv":10.22,"id":40380900}]}]}
{"op":"mcm","clk":"11792625214","pt":1722539775505,"mc":[{"id":"1.231243109","rc":[{"batb":[[1,1.7,10],[2,1.05,25000]],"ltp":2.54,"tv":10.22,"id":40380900}]}]}
{"op":"mcm","clk":"11792625386","pt":1722539776927,"mc":[{"id":"1.231243109","rc":[{"batb":[[0,1.7,10],[1,1.05,25000],[2,1.04,25000]],"ltp":2.54,"tv":10.22,"id":40380900}]}]}
{"op":"mcm","clk":"11792630175","pt":1722539825138,"mc":[{"id":"1.231243109","rc":[{"batb":[[0,1.71,10],[1,1.7,10],[2,1.05,25000]],"ltp":2.54,"tv":10.22,"id":40380900}]}]}
{"op":"mcm","clk":"11792630537","pt":1722539828521,"mc":[{"id":"1.231243109","rc":[{"batb":[[0,1.7,10],[1,1.05,25000],[2,1.04,25000]],"ltp":2.54,"tv":10.22,"id":40380900}]}]}
{"op":"mcm","clk":"11792633979","pt":1722539858875,"mc":[{"id":"1.231243109","rc":[{"batb":[[0,1.71,10],[1,1.7,10],[2,1.05,25000]],"ltp":2.54,"tv":10.22,"id":40380900}]}]}
{"op":"mcm","clk":"11792634363","pt":1722539862401,"mc":[{"id":"1.231243109","rc":[{"batb":[[0,1.7,10],[1,1.05,25000],[2,1.04,25000]],"ltp":2.54,"tv":10.22,"id":40380900}]}]}
{"op":"mcm","clk":"11792636406","pt":1722539879773,"mc":[{"id":"1.231243109","rc":[{"batb":[[0,1.71,10],[1,1.7,10],[2,1.05,25000]],"ltp":2.54,"tv":10.22,"id":40380900}]}]}
{"op":"mcm","clk":"11792636872","pt":1722539883500,"mc":[{"id":"1.231243109","rc":[{"batb":[[0,1.7,10],[1,1.05,25000],[2,1.04,25000]],"ltp":2.54,"tv":10.22,"id":40380900}]}]}
{"op":"mcm","clk":"11792637156","pt":1722539885988,"mc":[{"id":"1.231243109","rc":[{"batb":[[0,2.54,10],[1,2.52,11.11],[2,1.7,10]],"ltp":2.54,"tv":10.22,"id":40380900}]}]}
{"op":"mcm","clk":"11792637423","pt":1722539888311,"mc":[{"id":"1.231243109","rc":[{"batb":[[1,1.7,10],[2,1.05,25000]],"ltp":2.54,"tv":10.22,"id":40380900}]}]}
{"op":"mcm","clk":"11792637550","pt":1722539889375,"mc":[{"id":"1.231243109","rc":[{"batb":[[0,1.7,10],[1,1.05,25000],[2,1.04,25000]],"ltp":2.54,"tv":10.22,"id":40380900}]}]}
{"op":"mcm","clk":"11792641029","pt":1722539922729,"mc":[{"id":"1.231243109","rc":[{"batb":[[0,1.71,10],[1,1.7,10],[2,1.05,25000]],"ltp":2.54,"tv":10.22,"id":40380900}]}]}
{"op":"mcm","clk":"11792641361","pt":1722539926145,"mc":[{"id":"1.231243109","rc":[{"batb":[[0,1.7,10],[1,1.05,25000],[2,1.04,25000]],"ltp":2.54,"tv":10.22,"id":40380900}]}]}
{"op":"mcm","clk":"11792649521","pt":1722540001749,"mc":[{"id":"1.231243109","rc":[{"batb":[[0,1.71,10],[1,1.7,10],[2,1.05,25000]],"ltp":2.54,"tv":10.22,"id":40380900}]}]}
{"op":"mcm","clk":"11792649708","pt":1722540003662,"mc":[{"id":"1.231243109","rc":[{"batb":[[0,2.52,11.09],[1,1.71,10],[2,1.7,10]],"ltp":2.54,"tv":10.22,"id":40380900}]}]}
{"op":"mcm","clk":"11792649855","pt":1722540005163,"mc":[{"id":"1.231243109","rc":[{"batb":[[1,1.7,10],[2,1.05,25000]],"ltp":2.54,"tv":10.22,"id":40380900}]}]}
{"op":"mcm","clk":"11792650211","pt":1722540008566,"mc":[{"id":"1.231243109","rc":[{"batb":[[0,2.54,10],[1,2.52,11.09],[2,1.7,10]],"ltp":2.54,"tv":10.22,"id":40380900}]}]}
{"op":"mcm","clk":"11792650381","pt":1722540010172,"mc":[{"id":"1.231243109","rc":[{"batb":[[1,1.7,10],[2,1.05,25000]],"ltp":2.54,"tv":10.22,"id":40380900}]}]}
{"op":"mcm","clk":"11792650641","pt":1722540012257,"mc":[{"id":"1.231243109","rc":[{"batb":[[0,1.7,10],[1,1.05,25000],[2,1.04,25000]],"ltp":2.54,"tv":10.22,"id":40380900}]}]}
{"op":"mcm","clk":"11792654402","pt":1722540048823,"mc":[{"id":"1.231243109","rc":[{"batb":[[0,1.71,10],[1,1.7,10],[2,1.05,25000]],"ltp":2.54,"tv":10.22,"id":40380900}]}]}
{"op":"mcm","clk":"11792654729","pt":1722540052221,"mc":[{"id":"1.231243109","rc":[{"batb":[[0,1.7,10],[1,1.05,25000],[2,1.04,25000]],"ltp":2.54,"tv":10.22,"id":40380900}]}]}
{"op":"mcm","clk":"11792655637","pt":1722540060733,"mc":[{"id":"1.231243109","rc":[{"batb":[[0,1.71,10],[1,1.7,10],[2,1.05,25000]],"ltp":2.54,"tv":10.22,"id":40380900}]}]}
{"op":"mcm","clk":"11792656027","pt":1722540064144,"mc":[{"id":"1.231243109","rc":[{"batb":[[0,1.7,10],[1,1.05,25000],[2,1.04,25000]],"ltp":2.54,"tv":10.22,"id":40380900}]}]}
{"op":"mcm","clk":"11792662289","pt":1722540127711,"mc":[{"id":"1.231243109","rc":[{"batb":[[0,2.54,10],[1,2.52,11.32],[2,1.7,10]],"ltp":2.54,"tv":10.22,"id":40380900}]}]}
{"op":"mcm","clk":"11792662684","pt":1722540131012,"mc":[{"id":"1.231243109","rc":[{"batb":[[0,2.52,11.32],[1,1.7,10],[2,1.05,25000]],"ltp":2.54,"tv":10.22,"id":40380900}]}]}
{"op":"mcm","clk":"11792671189","pt":1722540213431,"mc":[{"id":"1.231243109","rc":[{"batb":[[0,2.54,10],[1,2.52,11.32],[2,1.7,10]],"ltp":2.54,"tv":10.22,"id":40380900}]}]}
{"op":"mcm","clk":"11792671299","pt":1722540214429,"mc":[{"id":"1.231243109","rc":[{"batb":[[1,1.7,10],[2,1.05,25000]],"ltp":2.54,"tv":10.22,"id":40380900}]}]}
{"op":"mcm","clk":"11792671582","pt":1722540217194,"mc":[{"id":"1.231243109","rc":[{"batb":[[0,1.7,10],[1,1.05,25000],[2,1.04,25000]],"ltp":2.54,"tv":10.22,"id":40380900}]}]}
{"op":"mcm","clk":"11792674319","pt":1722540245266,"mc":[{"id":"1.231243109","rc":[{"batb":[[0,2.52,11.13],[1,1.7,10],[2,1.05,25000]],"ltp":2.54,"tv":10.22,"id":40380900}]}]}
{"op":"mcm","clk":"11792674330","pt":1722540245367,"mc":[{"id":"1.231243109","rc":[{"batb":[[0,2.54,10],[1,2.52,11.13],[2,1.7,10]],"ltp":2.54,"tv":10.22,"id":40380900}]}]}
{"op":"mcm","clk":"11792674660","pt":1722540248756,"mc":[{"id":"1.231243109","rc":[{"batb":[[0,2.52,11.13],[1,1.7,10],[2,1.05,25000]],"ltp":2.54,"tv":10.22,"id":40380900}]}]}
{"op":"mcm","clk":"11792677651","pt":1722540280633,"mc":[{"id":"1.231243109","rc":[{"batb":[[0,2.54,10],[1,2.52,11.13],[2,1.7,10]],"ltp":2.54,"tv":10.22,"id":40380900}]}]}
{"op":"mcm","clk":"11792677800","pt":1722540282300,"mc":[{"id":"1.231243109","rc":[{"batb":[[1,1.7,10],[2,1.05,25000]],"ltp":2.54,"tv":10.22,"id":40380900}]}]}
{"op":"mcm","clk":"11792677943","pt":1722540284121,"mc":[{"id":"1.231243109","rc":[{"batb":[[0,1.7,10],[1,1.05,25000],[2,1.04,25000]],"ltp":2.54,"tv":10.22,"id":40380900}]}]}
{"op":"mcm","clk":"11792679464","pt":1722540299608,"mc":[{"id":"1.231243109","rc":[{"batb":[[0,1.71,10],[1,1.7,10],[2,1.05,25000]],"ltp":2.54,"tv":10.22,"id":40380900}]}]}
{"op":"mcm","clk":"11792679771","pt":1722540302933,"mc":[{"id":"1.231243109","rc":[{"batb":[[0,1.7,10],[1,1.05,25000],[2,1.04,25000]],"ltp":2.54,"tv":10.22,"id":40380900}]}]}
{"op":"mcm","clk":"11792682602","pt":1722540333884,"mc":[{"id":"1.231243109","rc":[{"batb":[[0,1.71,10],[1,1.7,10],[2,1.05,25000]],"ltp":2.54,"tv":10.22,"id":40380900}]}]}
{"op":"mcm","clk":"11792682933","pt":1722540337322,"mc":[{"id":"1.231243109","rc":[{"batb":[[0,1.7,10],[1,1.05,25000],[2,1.04,25000]],"ltp":2.54,"tv":10.22,"id":40380900}]}]}
{"op":"mcm","clk":"11792685050","pt":1722540364058,"mc":[{"id":"1.231243109","rc":[{"batb":[[0,2.54,10],[1,2.52,10.99],[2,1.7,10]],"ltp":2.54,"tv":10.22,"id":40380900}]}]}
{"op":"mcm","clk":"11792685308","pt":1722540367440,"mc":[{"id":"1.231243109","rc":[{"batb":[[0,1.7,10],[1,1.05,25000],[2,1.04,25000]],"ltp":2.54,"tv":10.22,"id":40380900}]}]}
{"op":"mcm","clk":"11792686750","pt":1722540385374,"mc":[{"id":"1.231243109","rc":[{"batb":[[0,1.71,10],[1,1.7,10],[2,1.05,25000]],"ltp":2.54,"tv":10.22,"id":40380900}]}]}
{"op":"mcm","clk":"11792687083","pt":1722540388976,"mc":[{"id":"1.231243109","rc":[{"batb":[[0,1.7,10],[1,1.05,25000],[2,1.04,25000]],"ltp":2.54,"tv":10.22,"id":40380900}]}]}
{"op":"mcm","clk":"11792687444","pt":1722540393100,"mc":[{"id":"1.231243109","rc":[{"batb":[[0,1.71,10],[1,1.7,10],[2,1.05,25000]],"ltp":2.54,"tv":10.22,"id":40380900}]}]}
{"op":"mcm","clk":"11792687745","pt":1722540396364,"mc":[{"id":"1.231243109","rc":[{"batb":[[0,1.7,10],[1,1.05,25000],[2,1.04,25000]],"ltp":2.54,"tv":10.22,"id":40380900}]}]}
{"op":"mcm","clk":"11792689406","pt":1722540417334,"mc":[{"id":"1.231243109","rc":[{"batb":[[0,1.71,10],[1,1.7,10],[2,1.05,25000]],"ltp":2.54,"tv":10.22,"id":40380900}]}]}
{"op":"mcm","clk":"11792689660","pt":1722540420634,"mc":[{"id":"1.231243109","rc":[{"batb":[[0,1.7,10],[1,1.05,25000],[2,1.04,25000]],"ltp":2.54,"tv":10.22,"id":40380900}]}]}
{"op":"mcm","clk":"11792689928","pt":1722540423634,"mc":[{"id":"1.231243109","rc":[{"batb":[[0,1.71,10],[1,1.7,10],[2,1.05,25000]],"ltp":2.54,"tv":10.22,"id":40380900}]}]}
{"op":"mcm","clk":"11792690205","pt":1722540427013,"mc":[{"id":"1.231243109","rc":[{"batb":[[0,1.7,10],[1,1.05,25000],[2,1.04,25000]],"ltp":2.54,"tv":10.22,"id":40380900}]}]}
{"op":"mcm","clk":"11792690545","pt":1722540431032,"mc":[{"id":"1.231243109","rc":[{"batb":[[0,1.71,10],[1,1.7,10],[2,1.05,25000]],"ltp":2.54,"tv":10.22,"id":40380900}]}]}
{"op":"mcm","clk":"11792690849","pt":1722540434510,"mc":[{"id":"1.231243109","rc":[{"batb":[[0,1.7,10],[1,1.05,25000],[2,1.04,25000]],"ltp":2.54,"tv":10.22,"id":40380900}]}]}
{"op":"mcm","clk":"11792691131","pt":1722540437760,"mc":[{"id":"1.231243109","rc":[{"batb":[[0,1.71,10],[1,1.7,10],[2,1.05,25000]],"ltp":2.54,"tv":10.22,"id":40380900}]}]}
{"op":"mcm","clk":"11792691358","pt":1722540441152,"mc":[{"id":"1.231243109","rc":[{"batb":[[0,1.7,10],[1,1.05,25000],[2,1.04,25000]],"ltp":2.54,"tv":10.22,"id":40380900}]}]}
{"op":"mcm","clk":"11792694270","pt":1722540477766,"mc":[{"id":"1.231243109","rc":[{"batb":[[0,2.54,10],[1,2.52,11.05],[2,1.7,10]],"ltp":2.54,"tv":10.22,"id":40380900}]}]}
{"op":"mcm","clk":"11792694439","pt":1722540479965,"mc":[{"id":"1.231243109","rc":[{"batb":[[1,1.7,10],[2,1.05,25000]],"ltp":2.54,"tv":10.22,"id":40380900}]}]}
{"op":"mcm","clk":"11792694542","pt":1722540481262,"mc":[{"id":"1.231243109","rc":[{"batb":[[0,1.7,10],[1,1.05,25000],[2,1.04,25000]],"ltp":2.54,"tv":10.22,"id":40380900}]}]}
{"op":"mcm","clk":"11792699152","pt":1722540533841,"mc":[{"id":"1.231243109","rc":[{"batb":[[0,1.71,10],[1,1.7,10],[2,1.05,25000]],"ltp":2.54,"tv":10.22,"id":40380900}]}]}
{"op":"mcm","clk":"11792699476","pt":1722540537437,"mc":[{"id":"1.231243109","rc":[{"batb":[[0,1.7,10],[1,1.05,25000],[2,1.04,25000]],"ltp":2.54,"tv":10.22,"id":40380900}]}]}
{"op":"mcm","clk":"11792700171","pt":1722540545546,"mc":[{"id":"1.231243109","rc":[{"batb":[[0,1.71,10],[1,1.7,10],[2,1.05,25000]],"ltp":2.54,"tv":10.22,"id":40380900}]}]}
{"op":"mcm","clk":"11792700475","pt":1722540549164,"mc":[{"id":"1.231243109","rc":[{"batb":[[0,1.7,10],[1,1.05,25000],[2,1.04,25000]],"ltp":2.54,"tv":10.22,"id":40380900}]}]}
{"op":"mcm","clk":"11792701450","pt":1722540560172,"mc":[{"id":"1.231243109","rc":[{"batb":[[0,1.71,10],[1,1.7,10],[2,1.05,25000]],"ltp":2.54,"tv":10.22,"id":40380900}]}]}
{"op":"mcm","clk":"11792701722","pt":1722540563566,"mc":[{"id":"1.231243109","rc":[{"batb":[[0,1.7,10],[1,1.05,25000],[2,1.04,25000]],"ltp":2.54,"tv":10.22,"id":40380900}]}]}
{"op":"mcm","clk":"11792703122","pt":1722540579102,"mc":[{"id":"1.231243109","rc":[{"batb":[[0,1.71,10],[1,1.7,10],[2,1.05,25000]],"ltp":2.54,"tv":10.22,"id":40380900}]}]}
{"op":"mcm","clk":"11792703485","pt":1722540582696,"mc":[{"id":"1.231243109","rc":[{"batb":[[0,1.7,10],[1,1.05,25000],[2,1.04,25000]],"ltp":2.54,"tv":10.22,"id":40380900}]}]}
{"op":"mcm","clk":"11792704096","pt":1722540589814,"mc":[{"id":"1.231243109","rc":[{"batb":[[0,2.52,11.32],[1,1.71,10],[2,1.7,10]],"ltp":2.54,"tv":10.22,"id":40380900}]}]}
{"op":"mcm","clk":"11792704361","pt":1722540592795,"mc":[{"id":"1.231243109","rc":[{"batb":[[1,1.7,10],[2,1.05,25000]],"ltp":2.54,"tv":10.22,"id":40380900}]}]}
{"op":"mcm","clk":"11792704616","pt":1722540595505,"mc":[{"id":"1.231243109","rc":[{"batb":[[0,2.54,10],[1,2.52,11.32],[2,1.7,10]],"ltp":2.54,"tv":10.22,"id":40380900}]}]}
{"op":"mcm","clk":"11792704817","pt":1722540597628,"mc":[{"id":"1.231243109","rc":[{"batb":[[1,1.7,10],[2,1.05,25000]],"ltp":2.54,"tv":10.22,"id":40380900}]}]}
{"op":"mcm","clk":"11792704916","pt":1722540598935,"mc":[{"id":"1.231243109","rc":[{"batb":[[0,1.7,10],[1,1.05,25000],[2,1.04,25000]],"ltp":2.54,"tv":10.22,"id":40380900}]}]}
{"op":"mcm","clk":"11792705725","pt":1722540608016,"mc":[{"id":"1.231243109","rc":[{"batb":[[0,1.71,10],[1,1.7,10],[2,1.05,25000]],"ltp":2.54,"tv":10.22,"id":40380900}]}]}
{"op":"mcm","clk":"11792706021","pt":1722540611541,"mc":[{"id":"1.231243109","rc":[{"batb":[[0,1.7,10],[1,1.05,25000],[2,1.04,25000]],"ltp":2.54,"tv":10.22,"id":40380900}]}]}
{"op":"mcm","clk":"11792706398","pt":1722540615941,"mc":[{"id":"1.231243109","rc":[{"batb":[[0,1.71,10],[1,1.7,10],[2,1.05,25000]],"ltp":2.54,"tv":10.22,"id":40380900}]}]}
{"op":"mcm","clk":"11792706683","pt":1722540619439,"mc":[{"id":"1.231243109","rc":[{"batb":[[0,1.7,10],[1,1.05,25000],[2,1.04,25000]],"ltp":2.54,"tv":10.22,"id":40380900}]}]}
{"op":"mcm","clk":"11792707115","pt":1722540625141,"mc":[{"id":"1.231243109","rc":[{"batb":[[0,1.71,10],[1,1.7,10],[2,1.05,25000]],"ltp":2.54,"tv":10.22,"id":40380900}]}]}
{"op":"mcm","clk":"11792707368","pt":1722540628574,"mc":[{"id":"1.231243109","rc":[{"batb":[[0,1.7,10],[1,1.05,25000],[2,1.04,25000]],"ltp":2.54,"tv":10.22,"id":40380900}]}]}
{"op":"mcm","clk":"11792707949","pt":1722540635950,"mc":[{"id":"1.231243109","rc":[{"batb":[[0,1.71,10],[1,1.7,10],[2,1.05,25000]],"ltp":2.54,"tv":10.22,"id":40380900}]}]}
{"op":"mcm","clk":"11792708204","pt":1722540639452,"mc":[{"id":"1.231243109","rc":[{"batb":[[0,1.7,10],[1,1.05,25000],[2,1.04,25000]],"ltp":2.54,"tv":10.22,"id":40380900}]}]}
{"op":"mcm","clk":"11792708560","pt":1722540643649,"mc":[{"id":"1.231243109","rc":[{"batb":[[0,1.71,10],[1,1.7,10],[2,1.05,25000]],"ltp":2.54,"tv":10.22,"id":40380900}]}]}
{"op":"mcm","clk":"11792708837","pt":1722540647095,"mc":[{"id":"1.231243109","rc":[{"batb":[[0,1.7,10],[1,1.05,25000],[2,1.04,25000]],"ltp":2.54,"tv":10.22,"id":40380900}]}]}
{"op":"mcm","clk":"11792709083","pt":1722540650176,"mc":[{"id":"1.231243109","rc":[{"batb":[[0,1.71,10],[1,1.7,10],[2,1.05,25000]],"ltp":2.54,"tv":10.22,"id":40380900}]}]}
{"op":"mcm","clk":"11792709324","pt":1722540653588,"mc":[{"id":"1.231243109","rc":[{"batb":[[0,1.7,10],[1,1.05,25000],[2,1.04,25000]],"ltp":2.54,"tv":10.22,"id":40380900}]}]}
{"op":"mcm","clk":"11792709616","pt":1722540657267,"mc":[{"id":"1.231243109","rc":[{"batb":[[0,1.71,10],[1,1.7,10],[2,1.05,25000]],"ltp":2.54,"tv":10.22,"id":40380900}]}]}
{"op":"mcm","clk":"11792709929","pt":1722540660789,"mc":[{"id":"1.231243109","rc":[{"batb":[[0,1.7,10],[1,1.05,25000],[2,1.04,25000]],"ltp":2.54,"tv":10.22,"id":40380900}]}]}
{"op":"mcm","clk":"11792710215","pt":1722540663876,"mc":[{"id":"1.231243109","rc":[{"batb":[[0,1.71,10],[1,1.7,10],[2,1.05,25000]],"ltp":2.54,"tv":10.22,"id":40380900}]}]}
{"op":"mcm","clk":"11792710543","pt":1722540667481,"mc":[{"id":"1.231243109","rc":[{"batb":[[0,1.7,10],[1,1.05,25000],[2,1.04,25000]],"ltp":2.54,"tv":10.22,"id":40380900}]}]}
{"op":"mcm","clk":"11792710825","pt":1722540670991,"mc":[{"id":"1.231243109","rc":[{"batb":[[0,1.71,10],[1,1.7,10],[2,1.05,25000]],"ltp":2.54,"tv":10.22,"id":40380900}]}]}
{"op":"mcm","clk":"11792711121","pt":1722540674599,"mc":[{"id":"1.231243109","rc":[{"batb":[[0,1.7,10],[1,1.05,25000],[2,1.04,25000]],"ltp":2.54,"tv":10.22,"id":40380900}]}]}
{"op":"mcm","clk":"11792711414","pt":1722540678414,"mc":[{"id":"1.231243109","rc":[{"batb":[[0,1.71,10],[1,1.7,10],[2,1.05,25000]],"ltp":2.54,"tv":10.22,"id":40380900}]}]}
{"op":"mcm","clk":"11792711744","pt":1722540681719,"mc":[{"id":"1.231243109","rc":[{"batb":[[0,1.7,10],[1,1.05,25000],[2,1.04,25000]],"ltp":2.54,"tv":10.22,"id":40380900}]}]}
{"op":"mcm","clk":"11792712928","pt":1722540695835,"mc":[{"id":"1.231243109","rc":[{"batb":[[0,1.71,10],[1,1.7,10],[2,1.05,25000]],"ltp":2.54,"tv":10.22,"id":40380900}]}]}
{"op":"mcm","clk":"11792713160","pt":1722540698551,"mc":[{"id":"1.231243109","rc":[{"batb":[[0,2.52,11.09],[1,1.71,10],[2,1.7,10]],"ltp":2.54,"tv":10.22,"id":40380900}]}]}
{"op":"mcm","clk":"11792713228","pt":1722540699328,"mc":[{"id":"1.231243109","rc":[{"batb":[[1,1.7,10],[2,1.05,25000]],"ltp":2.54,"tv":10.22,"id":40380900}]}]}
{"op":"mcm","clk":"11792713420","pt":1722540701825,"mc":[{"id":"1.231243109","rc":[{"batb":[[0,2.54,10],[1,2.52,11.09],[2,1.7,10]],"ltp":2.54,"tv":10.22,"id":40380900}]}]}
{"op":"mcm","clk":"11792713533","pt":1722540703034,"mc":[{"id":"1.231243109","rc":[{"batb":[[1,1.7,10],[2,1.05,25000]],"ltp":2.54,"tv":10.22,"id":40380900}]}]}
{"op":"mcm","clk":"11792713697","pt":1722540705227,"mc":[{"id":"1.231243109","rc":[{"batb":[[0,1.7,10],[1,1.05,25000],[2,1.04,25000]],"ltp":2.54,"tv":10.22,"id":40380900}]}]}
{"op":"mcm","clk":"11792714155","pt":1722540710804,"mc":[{"id":"1.231243109","rc":[{"batb":[[0,1.71,10],[1,1.7,10],[2,1.05,25000]],"ltp":2.54,"tv":10.22,"id":40380900}]}]}
{"op":"mcm","clk":"11792714427","pt":1722540714076,"mc":[{"id":"1.231243109","rc":[{"batb":[[0,1.7,10],[1,1.05,25000],[2,1.04,25000]],"ltp":2.54,"tv":10.22,"id":40380900}]}]}
{"op":"mcm","clk":"11792714749","pt":1722540717977,"mc":[{"id":"1.231243109","rc":[{"batb":[[0,1.71,10],[1,1.7,10],[2,1.05,25000]],"ltp":2.54,"tv":10.22,"id":40380900}]}]}
{"op":"mcm","clk":"11792715017","pt":1722540721473,"mc":[{"id":"1.231243109","rc":[{"batb":[[0,1.7,10],[1,1.05,25000],[2,1.04,25000]],"ltp":2.54,"tv":10.22,"id":40380900}]}]}
{"op":"mcm","clk":"11792715457","pt":1722540726388,"mc":[{"id":"1.231243109","rc":[{"batb":[[0,1.71,10],[1,1.7,10],[2,1.05,25000]],"ltp":2.54,"tv":10.22,"id":40380900}]}]}
{"op":"mcm","clk":"11792715737","pt":1722540729885,"mc":[{"id":"1.231243109","rc":[{"batb":[[0,1.7,10],[1,1.05,25000],[2,1.04,25000]],"ltp":2.54,"tv":10.22,"id":40380900}]}]}
{"op":"mcm","clk":"11792718169","pt":1722540759325,"mc":[{"id":"1.231243109","rc":[{"batb":[[0,1.71,10],[1,1.7,10],[2,1.05,25000]],"ltp":2.54,"tv":10.22,"id":40380900}]}]}
{"op":"mcm","clk":"11792718434","pt":1722540762724,"mc":[{"id":"1.231243109","rc":[{"batb":[[0,1.7,10],[1,1.05,25000],[2,1.04,25000]],"ltp":2.54,"tv":10.22,"id":40380900}]}]}
{"op":"mcm","clk":"11792718913","pt":1722540768858,"mc":[{"id":"1.231243109","rc":[{"batb":[[0,1.71,10],[1,1.7,10],[2,1.05,25000]],"ltp":2.54,"tv":10.22,"id":40380900}]}]}
{"op":"mcm","clk":"11792719170","pt":1722540772245,"mc":[{"id":"1.231243109","rc":[{"batb":[[0,1.7,10],[1,1.05,25000],[2,1.04,25000]],"ltp":2.54,"tv":10.22,"id":40380900}]}]}
{"op":"mcm","clk":"11792719324","pt":1722540774388,"mc":[{"id":"1.231243109","rc":[{"batb":[[0,1.71,10],[1,1.7,10],[2,1.05,25000]],"ltp":2.54,"tv":10.22,"id":40380900}]}]}
{"op":"mcm","clk":"11792719620","pt":1722540777768,"mc":[{"id":"1.231243109","rc":[{"batb":[[0,1.7,10],[1,1.05,25000],[2,1.04,25000]],"ltp":2.54,"tv":10.22,"id":40380900}]}]}
{"op":"mcm","clk":"11792720854","pt":1722540793281,"mc":[{"id":"1.231243109","rc":[{"batb":[[0,1.71,10],[1,1.7,10],[2,1.05,25000]],"ltp":2.54,"tv":10.22,"id":40380900}]}]}
{"op":"mcm","clk":"11792721118","pt":1722540796774,"mc":[{"id":"1.231243109","rc":[{"batb":[[0,1.7,10],[1,1.05,25000],[2,1.04,25000]],"ltp":2.54,"tv":10.22,"id":40380900}]}]}
{"op":"mcm","clk":"11792721976","pt":1722540807982,"mc":[{"id":"1.231243109","rc":[{"batb":[[0,2.54,10],[1,2.52,11.11],[2,1.7,10]],"ltp":2.54,"tv":10.22,"id":40380900}]}]}
{"op":"mcm","clk":"11792722116","pt":1722540809494,"mc":[{"id":"1.231243109","rc":[{"batb":[[1,1.7,10],[2,1.05,25000]],"ltp":2.54,"tv":10.22,"id":40380900}]}]}
{"op":"mcm","clk":"11792722270","pt":1722540811173,"mc":[{"id":"1.231243109","rc":[{"batb":[[0,1.7,10],[1,1.05,25000],[2,1.04,25000]],"ltp":2.54,"tv":10.22,"id":40380900}]}]}
{"op":"mcm","clk":"11792722733","pt":1722540816792,"mc":[{"id":"1.231243109","rc":[{"batb":[[0,1.71,10],[1,1.7,10],[2,1.05,25000]],"ltp":2.54,"tv":10.22,"id":40380900}]}]}
{"op":"mcm","clk":"11792723032","pt":1722540820199,"mc":[{"id":"1.231243109","rc":[{"batb":[[0,1.7,10],[1,1.05,25000],[2,1.04,25000]],"ltp":2.54,"tv":10.22,"id":40380900}]}]}
{"op":"mcm","clk":"11792724289","pt":1722540835427,"mc":[{"id":"1.231243109","rc":[{"batb":[[0,1.71,10],[1,1.7,10],[2,1.05,25000]],"ltp":2.54,"tv":10.22,"id":40380900}]}]}
{"op":"mcm","clk":"11792724530","pt":1722540838820,"mc":[{"id":"1.231243109","rc":[{"batb":[[0,1.7,10],[1,1.05,25000],[2,1.04,25000]],"ltp":2.54,"tv":10.22,"id":40380900}]}]}
{"op":"mcm","clk":"11792725211","pt":1722540846491,"mc":[{"id":"1.231243109","rc":[{"batb":[[0,1.71,10],[1,1.7,10],[2,1.05,25000]],"ltp":2.54,"tv":10.22,"id":40380900}]}]}
{"op":"mcm","clk":"11792725507","pt":1722540850082,"mc":[{"id":"1.231243109","rc":[{"batb":[[0,1.7,10],[1,1.05,25000],[2,1.04,25000]],"ltp":2.54,"tv":10.22,"id":40380900}]}]}
{"op":"mcm","clk":"11792725862","pt":1722540854182,"mc":[{"id":"1.231243109","rc":[{"batb":[[0,1.71,10],[1,1.7,10],[2,1.05,25000]],"ltp":2.54,"tv":10.22,"id":40380900}]}]}
{"op":"mcm","clk":"11792726190","pt":1722540857471,"mc":[{"id":"1.231243109","rc":[{"batb":[[0,1.7,10],[1,1.05,25000],[2,1.04,25000]],"ltp":2.54,"tv":10.22,"id":40380900}]}]}
{"op":"mcm","clk":"11792726569","pt":1722540861775,"mc":[{"id":"1.231243109","rc":[{"batb":[[0,1.71,10],[1,1.7,10],[2,1.05,25000]],"ltp":2.54,"tv":10.22,"id":40380900}]}]}
{"op":"mcm","clk":"11792726884","pt":1722540865276,"mc":[{"id":"1.231243109","rc":[{"batb":[[0,1.7,10],[1,1.05,25000],[2,1.04,25000]],"ltp":2.54,"tv":10.22,"id":40380900}]}]}
{"op":"mcm","clk":"11792727223","pt":1722540869492,"mc":[{"id":"1.231243109","rc":[{"batb":[[0,1.71,10],[1,1.7,10],[2,1.05,25000]],"ltp":2.54,"tv":10.22,"id":40380900}]}]}
{"op":"mcm","clk":"11792727531","pt":1722540872889,"mc":[{"id":"1.231243109","rc":[{"batb":[[0,1.7,10],[1,1.05,25000],[2,1.04,25000]],"ltp":2.54,"tv":10.22,"id":40380900}]}]}
{"op":"mcm","clk":"11792728201","pt":1722540881301,"mc":[{"id":"1.231243109","rc":[{"batb":[[0,1.71,10],[1,1.7,10],[2,1.05,25000]],"ltp":2.54,"tv":10.22,"id":40380900}]}]}
{"op":"mcm","clk":"11792728471","pt":1722540884690,"mc":[{"id":"1.231243109","rc":[{"batb":[[0,1.7,10],[1,1.05,25000],[2,1.04,25000]],"ltp":2.54,"tv":10.22,"id":40380900}]}]}
{"op":"mcm","clk":"11792731014","pt":1722540913862,"mc":[{"id":"1.231243109","rc":[{"batb":[[0,2.54,10],[1,2.52,11.46],[2,1.7,10]],"ltp":2.54,"tv":10.22,"id":40380900}]}]}
{"op":"mcm","clk":"11792731199","pt":1722540915949,"mc":[{"id":"1.231243109","rc":[{"batb":[[1,1.7,10],[2,1.05,25000]],"ltp":2.54,"tv":10.22,"id":40380900}]}]}
{"op":"mcm","clk":"11792731288","pt":1722540917147,"mc":[{"id":"1.231243109","rc":[{"batb":[[0,1.7,10],[1,1.05,25000],[2,1.04,25000]],"ltp":2.54,"tv":10.22,"id":40380900}]}]}
{"op":"mcm","clk":"11792740805","pt":1722541020958,"mc":[{"id":"1.231243109","rc":[{"batb":[[0,2.54,10],[1,2.52,11.33],[2,1.7,10]],"ltp":2.54,"tv":10.22,"id":40380900}]}]}
{"op":"mcm","clk":"11792740989","pt":1722541022947,"mc":[{"id":"1.231243109","rc":[{"batb":[[1,1.7,10],[2,1.05,25000]],"ltp":2.54,"tv":10.22,"id":40380900}]}]}
{"op":"mcm","clk":"11792741136","pt":1722541024359,"mc":[{"id":"1.231243109","rc":[{"batb":[[0,1.7,10],[1,1.05,25000],[2,1.04,25000]],"ltp":2.54,"tv":10.22,"id":40380900}]}]}
{"op":"mcm","clk":"11792750632","pt":1722541126246,"mc":[{"id":"1.231243109","rc":[{"batb":[[0,2.52,11.47],[1,1.7,10],[2,1.05,25000]],"ltp":2.54,"tv":10.22,"id":40380900}]}]}
{"op":"mcm","clk":"11792750642","pt":1722541126351,"mc":[{"id":"1.231243109","rc":[{"batb":[[0,2.54,10],[1,2.52,11.47],[2,1.7,10]],"ltp":2.54,"tv":10.22,"id":40380900}]}]}
{"op":"mcm","clk":"11792750825","pt":1722541128264,"mc":[{"id":"1.231243109","rc":[{"batb":[[1,1.7,10],[2,1.05,25000]],"ltp":2.54,"tv":10.22,"id":40380900}]}]}
{"op":"mcm","clk":"11792750997","pt":1722541129878,"mc":[{"id":"1.231243109","rc":[{"batb":[[0,1.7,10],[1,1.05,25000],[2,1.04,25000]],"ltp":2.54,"tv":10.22,"id":40380900}]}]}
{"op":"mcm","clk":"11792759919","pt":1722541230270,"mc":[{"id":"1.231243109","rc":[{"batb":[[0,2.54,10],[1,2.52,11.26],[2,1.7,10]],"ltp":2.54,"tv":10.22,"id":40380900}]}]}
{"op":"mcm","clk":"11792760087","pt":1722541232161,"mc":[{"id":"1.231243109","rc":[{"batb":[[1,1.7,10],[2,1.05,25000]],"ltp":2.54,"tv":10.22,"id":40380900}]}]}
{"op":"mcm","clk":"11792760183","pt":1722541233575,"mc":[{"id":"1.231243109","rc":[{"batb":[[0,1.7,10],[1,1.05,25000],[2,1.04,25000]],"ltp":2.54,"tv":10.22,"id":40380900}]}]}
{"op":"mcm","clk":"11792768293","pt":1722541333100,"mc":[{"id":"1.231243109","rc":[{"batb":[[0,2.54,10],[1,2.52,11.08],[2,1.7,10]],"ltp":2.54,"tv":10.22,"id":40380900}]}]}
{"op":"mcm","clk":"11792768507","pt":1722541335461,"mc":[{"id":"1.231243109","rc":[{"batb":[[1,1.7,10],[2,1.05,25000]],"ltp":2.54,"tv":10.22,"id":40380900}]}]}
{"op":"mcm","clk":"11792768590","pt":1722541336459,"mc":[{"id":"1.231243109","rc":[{"batb":[[0,1.7,10],[1,1.05,25000],[2,1.04,25000]],"ltp":2.54,"tv":10.22,"id":40380900}]}]}
{"op":"mcm","clk":"11792775642","pt":1722541426055,"mc":[{"id":"1.231243109","rc":[{"batb":[[0,1.71,10],[1,1.7,10],[2,1.05,25000]],"ltp":2.54,"tv":10.22,"id":40380900}]}]}
{"op":"mcm","clk":"11792775888","pt":1722541429468,"mc":[{"id":"1.231243109","rc":[{"batb":[[0,1.7,10],[1,1.05,25000],[2,1.04,25000]],"ltp":2.54,"tv":10.22,"id":40380900}]}]}
{"op":"mcm","clk":"11792776450","pt":1722541437083,"mc":[{"id":"1.231243109","rc":[{"batb":[[0,2.54,10],[1,2.52,11.2],[2,1.7,10]],"ltp":2.54,"tv":10.22,"id":40380900}]}]}
{"op":"mcm","clk":"11792776631","pt":1722541439443,"mc":[{"id":"1.231243109","rc":[{"batb":[[1,1.7,10],[2,1.05,25000]],"ltp":2.54,"tv":10.22,"id":40380900}]}]}
{"op":"mcm","clk":"11792776690","pt":1722541440446,"mc":[{"id":"1.231243109","rc":[{"batb":[[0,1.7,10],[1,1.05,25000],[2,1.04,25000]],"ltp":2.54,"tv":10.22,"id":40380900}]}]}
{"op":"mcm","clk":"11792779475","pt":1722541477706,"mc":[{"id":"1.231243109","rc":[{"batb":[[0,1.71,10],[1,1.7,10],[2,1.05,25000]],"ltp":2.54,"tv":10.22,"id":40380900}]}]}
{"op":"mcm","clk":"11792779763","pt":1722541481415,"mc":[{"id":"1.231243109","rc":[{"batb":[[0,1.7,10],[1,1.05,25000],[2,1.04,25000]],"ltp":2.54,"tv":10.22,"id":40380900}]}]}
{"op":"mcm","clk":"11792786097","pt":1722541543181,"mc":[{"id":"1.231243109","rc":[{"batb":[[0,2.54,10],[1,2.52,11.05],[2,1.7,10]],"ltp":2.54,"tv":10.22,"id":40380900}]}]}
{"op":"mcm","clk":"11792786384","pt":1722541546512,"mc":[{"id":"1.231243109","rc":[{"batb":[[0,2.52,11.05],[1,1.7,10],[2,1.05,25000]],"ltp":2.54,"tv":10.22,"id":40380900}]}]}
{"op":"mcm","clk":"11792789470","pt":1722541579093,"mc":[{"id":"1.231243109","rc":[{"batb":[[0,2.54,10]],"ltp":2.54,"tv":10.22,"id":40380900}]}]}
{"op":"mcm","clk":"11792789764","pt":1722541582008,"mc":[{"id":"1.231243109","rc":[{"batb":[[0,1.7,10],[1,1.05,25000],[2,1.04,25000]],"ltp":2.54,"tv":10.22,"id":40380900}]}]}
{"op":"mcm","clk":"11792790053","pt":1722541585099,"mc":[{"id":"1.231243109","rc":[{"batb":[[0,1.71,10],[1,1.7,10],[2,1.05,25000]],"ltp":2.54,"tv":10.22,"id":40380900}]}]}
{"op":"mcm","clk":"11792790336","pt":1722541588600,"mc":[{"id":"1.231243109","rc":[{"batb":[[0,1.7,10],[1,1.05,25000],[2,1.04,25000]],"ltp":2.54,"tv":10.22,"id":40380900}]}]}
{"op":"mcm","clk":"11792790793","pt":1722541594705,"mc":[{"id":"1.231243109","rc":[{"batb":[[0,1.71,10],[1,1.7,10],[2,1.05,25000]],"ltp":2.54,"tv":10.22,"id":40380900}]}]}
{"op":"mcm","clk":"11792791055","pt":1722541598202,"mc":[{"id":"1.231243109","rc":[{"batb":[[0,1.7,10],[1,1.05,25000],[2,1.04,25000]],"ltp":2.54,"tv":10.22,"id":40380900}]}]}
{"op":"mcm","clk":"11792791557","pt":1722541604522,"mc":[{"id":"1.231243109","rc":[{"batb":[[0,1.71,10],[1,1.7,10],[2,1.05,25000]],"ltp":2.54,"tv":10.22,"id":40380900}]}]}
{"op":"mcm","clk":"11792791832","pt":1722541607911,"mc":[{"id":"1.231243109","rc":[{"batb":[[0,1.7,10],[1,1.05,25000],[2,1.04,25000]],"ltp":2.54,"tv":10.22,"id":40380900}]}]}
{"op":"mcm","clk":"11792792128","pt":1722541611429,"mc":[{"id":"1.231243109","rc":[{"batb":[[0,1.71,10],[1,1.7,10],[2,1.05,25000]],"ltp":2.54,"tv":10.22,"id":40380900}]}]}
{"op":"mcm","clk":"11792792384","pt":1722541614725,"mc":[{"id":"1.231243109","rc":[{"batb":[[0,1.7,10],[1,1.05,25000],[2,1.04,25000]],"ltp":2.54,"tv":10.22,"id":40380900}]}]}
{"op":"mcm","clk":"11792793518","pt":1722541629259,"mc":[{"id":"1.231243109","rc":[{"batb":[[0,1.71,10],[1,1.7,10],[2,1.05,25000]],"ltp":2.54,"tv":10.22,"id":40380900}]}]}
{"op":"mcm","clk":"11792793803","pt":1722541632666,"mc":[{"id":"1.231243109","rc":[{"batb":[[0,1.7,10],[1,1.05,25000],[2,1.04,25000]],"ltp":2.54,"tv":10.22,"id":40380900}]}]}
{"op":"mcm","clk":"11792794093","pt":1722541636479,"mc":[{"id":"1.231243109","rc":[{"batb":[[0,1.71,10],[1,1.7,10],[2,1.05,25000]],"ltp":2.54,"tv":10.22,"id":40380900}]}]}
{"op":"mcm","clk":"11792794370","pt":1722541639874,"mc":[{"id":"1.231243109","rc":[{"batb":[[0,1.7,10],[1,1.05,25000],[2,1.04,25000]],"ltp":2.54,"tv":10.22,"id":40380900}]}]}
{"op":"mcm","clk":"11792794934","pt":1722541647102,"mc":[{"id":"1.231243109","rc":[{"batb":[[0,2.54,10],[1,2.52,11.11],[2,1.7,10]],"ltp":2.54,"tv":10.22,"id":40380900}]}]}
{"op":"mcm","clk":"11792795077","pt":1722541648991,"mc":[{"id":"1.231243109","rc":[{"batb":[[1,1.7,10],[2,1.05,25000]],"ltp":2.54,"tv":10.22,"id":40380900}]}]}
{"op":"mcm","clk":"11792795180","pt":1722541650299,"mc":[{"id":"1.231243109","rc":[{"batb":[[0,1.7,10],[1,1.05,25000],[2,1.04,25000]],"ltp":2.54,"tv":10.22,"id":40380900}]}]}
{"op":"mcm","clk":"11792801711","pt":1722541732913,"mc":[{"id":"1.231243109","rc":[{"batb":[[0,1.71,10],[1,1.7,10],[2,1.05,25000]],"ltp":2.54,"tv":10.22,"id":40380900}]}]}
{"op":"mcm","clk":"11792801999","pt":1722541736302,"mc":[{"id":"1.231243109","rc":[{"batb":[[0,1.7,10],[1,1.05,25000],[2,1.04,25000]],"ltp":2.54,"tv":10.22,"id":40380900}]}]}
{"op":"mcm","clk":"11792802585","pt":1722541742996,"mc":[{"id":"1.231243109","rc":[{"batb":[[0,1.71,10],[1,1.7,10],[2,1.05,25000]],"ltp":2.54,"tv":10.22,"id":40380900}]}]}
{"op":"mcm","clk":"11792802890","pt":1722541746504,"mc":[{"id":"1.231243109","rc":[{"batb":[[0,1.7,10],[1,1.05,25000],[2,1.04,25000]],"ltp":2.54,"tv":10.22,"id":40380900}]}]}
{"op":"mcm","clk":"11792803473","pt":1722541754116,"mc":[{"id":"1.231243109","rc":[{"batb":[[0,2.54,10],[1,2.52,10.97],[2,1.7,10]],"ltp":2.54,"tv":10.22,"id":40380900}]}]}
{"op":"mcm","clk":"11792803669","pt":1722541756714,"mc":[{"id":"1.231243109","rc":[{"batb":[[1,1.7,10],[2,1.05,25000]],"ltp":2.54,"tv":10.22,"id":40380900}]}]}
{"op":"mcm","clk":"11792803731","pt":1722541757436,"mc":[{"id":"1.231243109","rc":[{"batb":[[0,1.7,10],[1,1.05,25000],[2,1.04,25000]],"ltp":2.54,"tv":10.22,"id":40380900}]}]}
{"op":"mcm","clk":"11792804306","pt":1722541765050,"mc":[{"id":"1.231243109","rc":[{"batb":[[0,1.71,10],[1,1.7,10],[2,1.05,25000]],"ltp":2.54,"tv":10.22,"id":40380900}]}]}
{"op":"mcm","clk":"11792804556","pt":1722541768220,"mc":[{"id":"1.231243109","rc":[{"batb":[[0,1.7,10],[1,1.05,25000],[2,1.04,25000]],"ltp":2.54,"tv":10.22,"id":40380900}]}]}
{"op":"mcm","clk":"11792804757","pt":1722541771012,"mc":[{"id":"1.231243109","rc":[{"batb":[[0,1.71,10],[1,1.7,10],[2,1.05,25000]],"ltp":2.54,"tv":10.22,"id":40380900}]}]}
{"op":"mcm","clk":"11792805024","pt":1722541774426,"mc":[{"id":"1.231243109","rc":[{"batb":[[0,1.7,10],[1,1.05,25000],[2,1.04,25000]],"ltp":2.54,"tv":10.22,"id":40380900}]}]}
{"op":"mcm","clk":"11792805675","pt":1722541783123,"mc":[{"id":"1.231243109","rc":[{"batb":[[0,1.71,10],[1,1.7,10],[2,1.05,25000]],"ltp":2.54,"tv":10.22,"id":40380900}]}]}
{"op":"mcm","clk":"11792805932","pt":1722541786537,"mc":[{"id":"1.231243109","rc":[{"batb":[[0,1.7,10],[1,1.05,25000],[2,1.04,25000]],"ltp":2.54,"tv":10.22,"id":40380900}]}]}
{"op":"mcm","clk":"11792806663","pt":1722541796358,"mc":[{"id":"1.231243109","rc":[{"batb":[[0,1.71,10],[1,1.7,10],[2,1.05,25000]],"ltp":2.54,"tv":10.22,"id":40380900}]}]}
{"op":"mcm","clk":"11792806902","pt":1722541799759,"mc":[{"id":"1.231243109","rc":[{"batb":[[0,1.7,10],[1,1.05,25000],[2,1.04,25000]],"ltp":2.54,"tv":10.22,"id":40380900}]}]}
{"op":"mcm","clk":"11792807552","pt":1722541807752,"mc":[{"id":"1.231243109","rc":[{"batb":[[0,1.71,10],[1,1.7,10],[2,1.05,25000]],"ltp":2.54,"tv":10.22,"id":40380900}]}]}
{"op":"mcm","clk":"11792807860","pt":1722541811045,"mc":[{"id":"1.231243109","rc":[{"batb":[[0,1.7,10],[1,1.05,25000],[2,1.04,25000]],"ltp":2.54,"tv":10.22,"id":40380900}]}]}
{"op":"mcm","clk":"11792808263","pt":1722541815864,"mc":[{"id":"1.231243109","rc":[{"batb":[[0,1.71,10],[1,1.7,10],[2,1.05,25000]],"ltp":2.54,"tv":10.22,"id":40380900}]}]}
{"op":"mcm","clk":"11792808552","pt":1722541819387,"mc":[{"id":"1.231243109","rc":[{"batb":[[0,1.7,10],[1,1.05,25000],[2,1.04,25000]],"ltp":2.54,"tv":10.22,"id":40380900}]}]}
{"op":"mcm","clk":"11792808825","pt":1722541822600,"mc":[{"id":"1.231243109","rc":[{"batb":[[0,1.71,10],[1,1.7,10],[2,1.05,25000]],"ltp":2.54,"tv":10.22,"id":40380900}]}]}
{"op":"mcm","clk":"11792809060","pt":1722541825874,"mc":[{"id":"1.231243109","rc":[{"batb":[[0,1.7,10],[1,1.05,25000],[2,1.04,25000]],"ltp":2.54,"tv":10.22,"id":40380900}]}]}
{"op":"mcm","clk":"11792809470","pt":1722541830997,"mc":[{"id":"1.231243109","rc":[{"batb":[[0,1.71,10],[1,1.7,10],[2,1.05,25000]],"ltp":2.54,"tv":10.22,"id":40380900}]}]}
{"op":"mcm","clk":"11792809716","pt":1722541834520,"mc":[{"id":"1.231243109","rc":[{"batb":[[0,1.7,10],[1,1.05,25000],[2,1.04,25000]],"ltp":2.54,"tv":10.22,"id":40380900}]}]}
{"op":"mcm","clk":"11792809982","pt":1722541838102,"mc":[{"id":"1.231243109","rc":[{"batb":[[0,1.71,10],[1,1.7,10],[2,1.05,25000]],"ltp":2.54,"tv":10.22,"id":40380900}]}]}
{"op":"mcm","clk":"11792810220","pt":1722541841316,"mc":[{"id":"1.231243109","rc":[{"batb":[[0,1.7,10],[1,1.05,25000],[2,1.04,25000]],"ltp":2.54,"tv":10.22,"id":40380900}]}]}
{"op":"mcm","clk":"11792810409","pt":1722541843705,"mc":[{"id":"1.231243109","rc":[{"batb":[[0,1.71,10],[1,1.7,10],[2,1.05,25000]],"ltp":2.54,"tv":10.22,"id":40380900}]}]}
{"op":"mcm","clk":"11792810730","pt":1722541847018,"mc":[{"id":"1.231243109","rc":[{"batb":[[0,1.7,10],[1,1.05,25000],[2,1.04,25000]],"ltp":2.54,"tv":10.22,"id":40380900}]}]}
{"op":"mcm","clk":"11792811039","pt":1722541850702,"mc":[{"id":"1.231243109","rc":[{"batb":[[0,1.71,10],[1,1.7,10],[2,1.05,25000]],"ltp":2.54,"tv":10.22,"id":40380900}]}]}
{"op":"mcm","clk":"11792811325","pt":1722541854225,"mc":[{"id":"1.231243109","rc":[{"batb":[[0,1.7,10],[1,1.05,25000],[2,1.04,25000]],"ltp":2.54,"tv":10.22,"id":40380900}]}]}
{"op":"mcm","clk":"11792811604","pt":1722541857700,"mc":[{"id":"1.231243109","rc":[{"batb":[[0,1.71,10],[1,1.7,10],[2,1.05,25000]],"ltp":2.54,"tv":10.22,"id":40380900}]}]}
{"op":"mcm","clk":"11792811872","pt":1722541861014,"mc":[{"id":"1.231243109","rc":[{"batb":[[0,2.52,11.01]],"ltp":2.54,"tv":10.22,"id":40380900}]}]}
{"op":"mcm","clk":"11792812115","pt":1722541864039,"mc":[{"id":"1.231243109","rc":[{"batb":[[0,2.54,10],[1,2.52,11.01],[2,1.7,10]],"ltp":2.54,"tv":10.22,"id":40380900}]}]}
{"op":"mcm","clk":"11792812173","pt":1722541864922,"mc":[{"id":"1.231243109","rc":[{"batb":[[1,1.7,10],[2,1.05,25000]],"ltp":2.54,"tv":10.22,"id":40380900}]}]}
{"op":"mcm","clk":"11792812357","pt":1722541867309,"mc":[{"id":"1.231243109","rc":[{"batb":[[0,1.7,10],[1,1.05,25000],[2,1.04,25000]],"ltp":2.54,"tv":10.22,"id":40380900}]}]}
{"op":"mcm","clk":"11792812845","pt":1722541874525,"mc":[{"id":"1.231243109","rc":[{"batb":[[0,1.71,10],[1,1.7,10],[2,1.05,25000]],"ltp":2.54,"tv":10.22,"id":40380900}]}]}
{"op":"mcm","clk":"11792813090","pt":1722541877747,"mc":[{"id":"1.231243109","rc":[{"batb":[[0,1.7,10],[1,1.05,25000],[2,1.04,25000]],"ltp":2.54,"tv":10.22,"id":40380900}]}]}
{"op":"mcm","clk":"11792813311","pt":1722541881087,"mc":[{"id":"1.231243109","rc":[{"batb":[[0,1.71,10],[1,1.7,10],[2,1.05,25000]],"ltp":2.54,"tv":10.22,"id":40380900}]}]}
{"op":"mcm","clk":"11792813592","pt":1722541884452,"mc":[{"id":"1.231243109","rc":[{"batb":[[0,1.7,10],[1,1.05,25000],[2,1.04,25000]],"ltp":2.54,"tv":10.22,"id":40380900}]}]}
{"op":"mcm","clk":"11792813790","pt":1722541886940,"mc":[{"id":"1.231243109","rc":[{"batb":[[0,1.71,10],[1,1.7,10],[2,1.05,25000]],"ltp":2.54,"tv":10.22,"id":40380900}]}]}
{"op":"mcm","clk":"11792814029","pt":1722541890378,"mc":[{"id":"1.231243109","rc":[{"batb":[[0,1.7,10],[1,1.05,25000],[2,1.04,25000]],"ltp":2.54,"tv":10.22,"id":40380900}]}]}
{"op":"mcm","clk":"11792814223","pt":1722541892880,"mc":[{"id":"1.231243109","rc":[{"batb":[[0,1.71,10],[1,1.7,10],[2,1.05,25000]],"ltp":2.54,"tv":10.22,"id":40380900}]}]}
{"op":"mcm","clk":"11792814488","pt":1722541896249,"mc":[{"id":"1.231243109","rc":[{"batb":[[0,1.7,10],[1,1.05,25000],[2,1.04,25000]],"ltp":2.54,"tv":10.22,"id":40380900}]}]}
{"op":"mcm","clk":"11792814814","pt":1722541901070,"mc":[{"id":"1.231243109","rc":[{"batb":[[0,1.71,10],[1,1.7,10],[2,1.05,25000]],"ltp":2.54,"tv":10.22,"id":40380900}]}]}
{"op":"mcm","clk":"11792815021","pt":1722541904384,"mc":[{"id":"1.231243109","rc":[{"batb":[[0,1.7,10],[1,1.05,25000],[2,1.04,25000]],"ltp":2.54,"tv":10.22,"id":40380900}]}]}
{"op":"mcm","clk":"11792815230","pt":1722541907497,"mc":[{"id":"1.231243109","rc":[{"batb":[[0,1.71,10],[1,1.7,10],[2,1.05,25000]],"ltp":2.54,"tv":10.22,"id":40380900}]}]}
{"op":"mcm","clk":"11792815441","pt":1722541910817,"mc":[{"id":"1.231243109","rc":[{"batb":[[0,1.7,10],[1,1.05,25000],[2,1.04,25000]],"ltp":2.54,"tv":10.22,"id":40380900}]}]}
{"op":"mcm","clk":"11792815582","pt":1722541913002,"mc":[{"id":"1.231243109","rc":[{"batb":[[0,1.71,10],[1,1.7,10],[2,1.05,25000]],"ltp":2.54,"tv":10.22,"id":40380900}]}]}
{"op":"mcm","clk":"11792815822","pt":1722541916328,"mc":[{"id":"1.231243109","rc":[{"batb":[[0,1.7,10],[1,1.05,25000],[2,1.04,25000]],"ltp":2.54,"tv":10.22,"id":40380900}]}]}
{"op":"mcm","clk":"11792816077","pt":1722541920112,"mc":[{"id":"1.231243109","rc":[{"batb":[[0,1.71,10],[1,1.7,10],[2,1.05,25000]],"ltp":2.54,"tv":10.22,"id":40380900}]}]}
{"op":"mcm","clk":"11792816339","pt":1722541923416,"mc":[{"id":"1.231243109","rc":[{"batb":[[0,1.7,10],[1,1.05,25000],[2,1.04,25000]],"ltp":2.54,"tv":10.22,"id":40380900}]}]}
{"op":"mcm","clk":"11792816529","pt":1722541925939,"mc":[{"id":"1.231243109","rc":[{"batb":[[0,1.71,10],[1,1.7,10],[2,1.05,25000]],"ltp":2.54,"tv":10.22,"id":40380900}]}]}
{"op":"mcm","clk":"11792816883","pt":1722541930502,"mc":[{"id":"1.231243109","rc":[{"batb":[[0,1.7,10],[1,1.05,25000],[2,1.04,25000]],"ltp":2.54,"tv":10.22,"id":40380900}]}]}
{"op":"mcm","clk":"11792817098","pt":1722541933239,"mc":[{"id":"1.231243109","rc":[{"batb":[[0,1.71,10],[1,1.7,10],[2,1.05,25000]],"ltp":2.54,"tv":10.22,"id":40380900}]}]}
{"op":"mcm","clk":"11792817380","pt":1722541936512,"mc":[{"id":"1.231243109","rc":[{"batb":[[0,1.7,10],[1,1.05,25000],[2,1.04,25000]],"ltp":2.54,"tv":10.22,"id":40380900}]}]}
{"op":"mcm","clk":"11792817514","pt":1722541938641,"mc":[{"id":"1.231243109","rc":[{"batb":[[0,1.71,10],[1,1.7,10],[2,1.05,25000]],"ltp":2.54,"tv":10.22,"id":40380900}]}]}
{"op":"mcm","clk":"11792817725","pt":1722541942046,"mc":[{"id":"1.231243109","rc":[{"batb":[[0,1.7,10],[1,1.05,25000],[2,1.04,25000]],"ltp":2.54,"tv":10.22,"id":40380900}]}]}
{"op":"mcm","clk":"11792817925","pt":1722541944834,"mc":[{"id":"1.231243109","rc":[{"batb":[[0,1.71,10],[1,1.7,10],[2,1.05,25000]],"ltp":2.54,"tv":10.22,"id":40380900}]}]}
{"op":"mcm","clk":"11792818164","pt":1722541948138,"mc":[{"id":"1.231243109","rc":[{"batb":[[0,1.7,10],[1,1.05,25000],[2,1.04,25000]],"ltp":2.54,"tv":10.22,"id":40380900}]}]}
{"op":"mcm","clk":"11792818599","pt":1722541954228,"mc":[{"id":"1.231243109","rc":[{"batb":[[0,1.71,10],[1,1.7,10],[2,1.05,25000]],"ltp":2.54,"tv":10.22,"id":40380900}]}]}
{"op":"mcm","clk":"11792818899","pt":1722541957760,"mc":[{"id":"1.231243109","rc":[{"batb":[[0,1.7,10],[1,1.05,25000],[2,1.04,25000]],"ltp":2.54,"tv":10.22,"id":40380900}]}]}
{"op":"mcm","clk":"11792819077","pt":1722541960190,"mc":[{"id":"1.231243109","rc":[{"batb":[[0,1.71,10],[1,1.7,10],[2,1.05,25000]],"ltp":2.54,"tv":10.22,"id":40380900}]}]}
{"op":"mcm","clk":"11792819345","pt":1722541963362,"mc":[{"id":"1.231243109","rc":[{"batb":[[0,1.7,10],[1,1.05,25000],[2,1.04,25000]],"ltp":2.54,"tv":10.22,"id":40380900}]}]}
{"op":"mcm","clk":"11792819580","pt":1722541966450,"mc":[{"id":"1.231243109","rc":[{"batb":[[0,1.71,10],[1,1.7,10],[2,1.05,25000]],"ltp":2.54,"tv":10.22,"id":40380900}]}]}
{"op":"mcm","clk":"11792819647","pt":1722541967383,"mc":[{"id":"1.231243109","rc":[{"batb":[[0,2.52,11.02],[1,1.71,10],[2,1.7,10]],"ltp":2.54,"tv":10.22,"id":40380900}]}]}
{"op":"mcm","clk":"11792819811","pt":1722541969861,"mc":[{"id":"1.231243109","rc":[{"batb":[[1,1.7,10],[2,1.05,25000]],"ltp":2.54,"tv":10.22,"id":40380900}]}]}
{"op":"mcm","clk":"11792820034","pt":1722541973171,"mc":[{"id":"1.231243109","rc":[{"batb":[[0,2.54,10],[1,2.52,11.02],[2,1.7,10]],"ltp":2.54,"tv":10.22,"id":40380900}]}]}
{"op":"mcm","clk":"11792820191","pt":1722541975190,"mc":[{"id":"1.231243109","rc":[{"batb":[[1,1.7,10],[2,1.05,48999.97]],"ltp":2.54,"tv":10.22,"id":40380900}]}]}
{"op":"mcm","clk":"11792820285","pt":1722541976275,"mc":[{"id":"1.231243109","rc":[{"batb":[[2,1.07,11428.56]],"ltp":2.54,"tv":10.22,"id":40380900}]}]}
{"op":"mcm","clk":"11792820365","pt":1722541977155,"mc":[{"id":"1.231243109","rc":[{"batb":[[0,1.7,10],[1,1.08,14999.97],[2,1.07,17142.84]],"ltp":2.54,"tv":10.22,"id":40380900}]}]}
{"op":"mcm","clk":"11792820422","pt":1722541978085,"mc":[{"id":"1.231243109","rc":[{"batb":[[1,1.1,3999.99],[2,1.09,8888.88]],"ltp":2.54,"tv":10.22,"id":40380900}]}]}
{"op":"mcm","clk":"11792820523","pt":1722541979179,"mc":[{"id":"1.231243109","rc":[{"batb":[[0,1.71,10],[1,1.7,10],[2,1.12,3333.33]],"ltp":2.54,"tv":10.22,"id":40380900}]}]}
{"op":"mcm","clk":"11792820529","pt":1722541979288,"mc":[{"id":"1.231243109","rc":[{"batb":[[2,1.12,6666.66]],"ltp":2.54,"tv":10.22,"id":40380900}]}]}
{"op":"mcm","clk":"11792820770","pt":1722541982093,"mc":[{"id":"1.231243109","rc":[{"batb":[[0,1.7,10],[1,1.12,6666.66],[2,1.11,7272.72]],"ltp":2.54,"tv":10.22,"id":40380900}]}]}
{"op":"mcm","clk":"11792821035","pt":1722541985205,"mc":[{"id":"1.231243109","rc":[{"batb":[[0,1.71,10],[1,1.7,10],[2,1.12,6666.66]],"ltp":2.54,"tv":10.22,"id":40380900}]}]}
{"op":"mcm","clk":"11792821289","pt":1722541988622,"mc":[{"id":"1.231243109","rc":[{"batb":[[0,1.7,10],[1,1.12,6666.66],[2,1.11,7272.72]],"ltp":2.54,"tv":10.22,"id":40380900}]}]}
{"op":"mcm","clk":"11792821528","pt":1722541991669,"mc":[{"id":"1.231243109","rc":[{"batb":[[0,1.71,10],[1,1.7,10],[2,1.12,6666.66]],"ltp":2.54,"tv":10.22,"id":40380900}]}]}
{"op":"mcm","clk":"11792821793","pt":1722541994990,"mc":[{"id":"1.231243109","rc":[{"batb":[[0,1.7,10],[1,1.12,6666.66],[2,1.11,7272.72]],"ltp":2.54,"tv":10.22,"id":40380900}]}]}
{"op":"mcm","clk":"11792821993","pt":1722541997417,"mc":[{"id":"1.231243109","rc":[{"batb":[[0,1.71,10],[1,1.7,10],[2,1.12,6666.66]],"ltp":2.54,"tv":10.22,"id":40380900}]}]}
{"op":"mcm","clk":"11792822282","pt":1722542000590,"mc":[{"id":"1.231243109","rc":[{"batb":[[0,1.7,10],[1,1.12,6666.66],[2,1.11,7272.72]],"ltp":2.54,"tv":10.22,"id":40380900}]}]}
{"op":"mcm","clk":"11792822481","pt":1722542003229,"mc":[{"id":"1.231243109","rc":[{"batb":[[0,1.71,10],[1,1.7,10],[2,1.12,6666.66]],"ltp":2.54,"tv":10.22,"id":40380900}]}]}
{"op":"mcm","clk":"11792822733","pt":1722542006692,"mc":[{"id":"1.231243109","rc":[{"batb":[[0,1.7,10],[1,1.12,6666.66],[2,1.11,7272.72]],"ltp":2.54,"tv":10.22,"id":40380900}]}]}
{"op":"mcm","clk":"11792822972","pt":1722542009793,"mc":[{"id":"1.231243109","rc":[{"batb":[[0,1.71,10],[1,1.7,10],[2,1.12,6666.66]],"ltp":2.54,"tv":10.22,"id":40380900}]}]}
{"op":"mcm","clk":"11792823222","pt":1722542013138,"mc":[{"id":"1.231243109","rc":[{"batb":[[0,1.7,10],[1,1.12,6666.66],[2,1.11,7272.72]],"ltp":2.54,"tv":10.22,"id":40380900}]}]}
{"op":"mcm","clk":"11792823408","pt":1722542015414,"mc":[{"id":"1.231243109","rc":[{"batb":[[0,1.71,10],[1,1.7,10],[2,1.12,6666.66]],"ltp":2.54,"tv":10.22,"id":40380900}]}]}
{"op":"mcm","clk":"11792823672","pt":1722542018624,"mc":[{"id":"1.231243109","rc":[{"batb":[[0,1.7,10],[1,1.12,6666.66],[2,1.11,7272.72]],"ltp":2.54,"tv":10.22,"id":40380900}]}]}
{"op":"mcm","clk":"11792823957","pt":1722542022359,"mc":[{"id":"1.231243109","rc":[{"batb":[[0,1.71,10],[1,1.7,10],[2,1.12,6666.66]],"ltp":2.54,"tv":10.22,"id":40380900}]}]}
{"op":"mcm","clk":"11792824208","pt":1722542025774,"mc":[{"id":"1.231243109","rc":[{"batb":[[0,1.7,10],[1,1.12,6666.66],[2,1.11,7272.72]],"ltp":2.54,"tv":10.22,"id":40380900}]}]}
{"op":"mcm","clk":"11792824400","pt":1722542028259,"mc":[{"id":"1.231243109","rc":[{"batb":[[0,1.71,10],[1,1.7,10],[2,1.12,6666.66]],"ltp":2.54,"tv":10.22,"id":40380900}]}]}
{"op":"mcm","clk":"11792824653","pt":1722542031684,"mc":[{"id":"1.231243109","rc":[{"batb":[[0,1.7,10],[1,1.12,6666.66],[2,1.11,7272.72]],"ltp":2.54,"tv":10.22,"id":40380900}]}]}
{"op":"mcm","clk":"11792824810","pt":1722542033761,"mc":[{"id":"1.231243109","rc":[{"batb":[[0,1.71,10],[1,1.7,10],[2,1.12,6666.66]],"ltp":2.54,"tv":10.22,"id":40380900}]}]}
{"op":"mcm","clk":"11792825088","pt":1722542037189,"mc":[{"id":"1.231243109","rc":[{"batb":[[0,1.7,10],[1,1.12,6666.66],[2,1.11,7272.72]],"ltp":2.54,"tv":10.22,"id":40380900}]}]}
{"op":"mcm","clk":"11792825402","pt":1722542041500,"mc":[{"id":"1.231243109","rc":[{"batb":[[0,1.71,10],[1,1.7,10],[2,1.12,6666.66]],"ltp":2.54,"tv":10.22,"id":40380900}]}]}
{"op":"mcm","clk":"11792825648","pt":1722542044797,"mc":[{"id":"1.231243109","rc":[{"batb":[[0,1.7,10],[1,1.12,6666.66],[2,1.11,7272.72]],"ltp":2.54,"tv":10.22,"id":40380900}]}]}
{"op":"mcm","clk":"11792825838","pt":1722542047288,"mc":[{"id":"1.231243109","rc":[{"batb":[[0,1.71,10],[1,1.7,10],[2,1.12,6666.66]],"ltp":2.54,"tv":10.22,"id":40380900}]}]}
{"op":"mcm","clk":"11792826117","pt":1722542050779,"mc":[{"id":"1.231243109","rc":[{"batb":[[0,1.7,10],[1,1.12,6666.66],[2,1.11,7272.72]],"ltp":2.54,"tv":10.22,"id":40380900}]}]}
{"op":"mcm","clk":"11792826342","pt":1722542054199,"mc":[{"id":"1.231243109","rc":[{"batb":[[0,1.71,10],[1,1.7,10],[2,1.12,6666.66]],"ltp":2.54,"tv":10.22,"id":40380900}]}]}
{"op":"mcm","clk":"11792826585","pt":1722542057613,"mc":[{"id":"1.231243109","rc":[{"batb":[[0,1.7,10],[1,1.12,6666.66],[2,1.11,7272.72]],"ltp":2.54,"tv":10.22,"id":40380900}]}]}
{"op":"mcm","clk":"11792826825","pt":1722542060926,"mc":[{"id":"1.231243109","rc":[{"batb":[[0,1.71,10],[1,1.7,10],[2,1.12,6666.66]],"ltp":2.54,"tv":10.22,"id":40380900}]}]}
{"op":"mcm","clk":"11792827072","pt":1722542064400,"mc":[{"id":"1.231243109","rc":[{"batb":[[0,1.7,10],[1,1.12,6666.66],[2,1.11,7272.72]],"ltp":2.54,"tv":10.22,"id":40380900}]}]}
{"op":"mcm","clk":"11792827235","pt":1722542067130,"mc":[{"id":"1.231243109","rc":[{"batb":[[0,1.71,10],[1,1.7,10],[2,1.12,6666.66]],"ltp":2.54,"tv":10.22,"id":40380900}]}]}
{"op":"mcm","clk":"11792827499","pt":1722542070633,"mc":[{"id":"1.231243109","rc":[{"batb":[[0,1.7,10],[1,1.12,6666.66],[2,1.11,7272.72]],"ltp":2.54,"tv":10.22,"id":40380900}]}]}
{"op":"mcm","clk":"11792827701","pt":1722542073013,"mc":[{"id":"1.231243109","rc":[{"batb":[[0,1.71,10],[1,1.7,10],[2,1.12,6666.66]],"ltp":2.54,"tv":10.22,"id":40380900}]}]}
{"op":"mcm","clk":"11792827731","pt":1722542073419,"mc":[{"id":"1.231243109","rc":[{"batb":[[0,2.52,11],[1,1.71,10],[2,1.7,10]],"ltp":2.54,"tv":10.22,"id":40380900}]}]}
{"op":"mcm","clk":"11792827983","pt":1722542076434,"mc":[{"id":"1.231243109","rc":[{"batb":[[1,1.7,10],[2,1.12,6666.66]],"ltp":2.54,"tv":10.22,"id":40380900}]}]}
{"op":"mcm","clk":"11792828189","pt":1722542079358,"mc":[{"id":"1.231243109","rc":[{"batb":[[0,2.54,10],[1,2.52,11],[2,1.7,10]],"ltp":2.54,"tv":10.22,"id":40380900}]}]}
{"op":"mcm","clk":"11792828264","pt":1722542080438,"mc":[{"id":"1.231243109","rc":[{"batb":[[1,1.7,10],[2,1.12,6666.66]],"ltp":2.54,"tv":10.22,"id":40380900}]}]}
{"op":"mcm","clk":"11792828426","pt":1722542082909,"mc":[{"id":"1.231243109","rc":[{"batb":[[0,1.7,10],[1,1.12,6666.66],[2,1.11,7272.72]],"ltp":2.54,"tv":10.22,"id":40380900}]}]}
{"op":"mcm","clk":"11792828621","pt":1722542085619,"mc":[{"id":"1.231243109","rc":[{"batb":[[0,1.71,10],[1,1.7,10],[2,1.12,6666.66]],"ltp":2.54,"tv":10.22,"id":40380900}]}]}
{"op":"mcm","clk":"11792828846","pt":1722542089068,"mc":[{"id":"1.231243109","rc":[{"batb":[[0,1.7,10],[1,1.12,6666.66],[2,1.11,7272.72]],"ltp":2.54,"tv":10.22,"id":40380900}]}]}
{"op":"mcm","clk":"11792829020","pt":1722542091458,"mc":[{"id":"1.231243109","rc":[{"batb":[[0,1.71,10],[1,1.7,10],[2,1.12,6666.66]],"ltp":2.54,"tv":10.22,"id":40380900}]}]}
{"op":"mcm","clk":"11792829255","pt":1722542094957,"mc":[{"id":"1.231243109","rc":[{"batb":[[0,1.7,10],[1,1.12,6666.66],[2,1.11,7272.72]],"ltp":2.54,"tv":10.22,"id":40380900}]}]}
{"op":"mcm","clk":"11792829398","pt":1722542097267,"mc":[{"id":"1.231243109","rc":[{"batb":[[0,1.71,10],[1,1.7,10],[2,1.12,6666.66]],"ltp":2.54,"tv":10.22,"id":40380900}]}]}
{"op":"mcm","clk":"11792829599","pt":1722542100671,"mc":[{"id":"1.231243109","rc":[{"batb":[[0,1.7,10],[1,1.12,6666.66],[2,1.11,7272.72]],"ltp":2.54,"tv":10.22,"id":40380900}]}]}
{"op":"mcm","clk":"11792829746","pt":1722542103256,"mc":[{"id":"1.231243109","rc":[{"batb":[[0,1.71,10],[1,1.7,10],[2,1.12,6666.66]],"ltp":2.54,"tv":10.22,"id":40380900}]}]}
{"op":"mcm","clk":"11792829971","pt":1722542106664,"mc":[{"id":"1.231243109","rc":[{"batb":[[0,1.7,10],[1,1.12,6666.66],[2,1.11,7272.72]],"ltp":2.54,"tv":10.22,"id":40380900}]}]}
{"op":"mcm","clk":"11792830174","pt":1722542109865,"mc":[{"id":"1.231243109","rc":[{"batb":[[0,1.71,10],[1,1.7,10],[2,1.12,6666.66]],"ltp":2.54,"tv":10.22,"id":40380900}]}]}
{"op":"mcm","clk":"11792830381","pt":1722542113069,"mc":[{"id":"1.231243109","rc":[{"batb":[[0,1.7,10],[1,1.12,6666.66],[2,1.11,7272.72]],"ltp":2.54,"tv":10.22,"id":40380900}]}]}
{"op":"mcm","clk":"11792830608","pt":1722542116470,"mc":[{"id":"1.231243109","rc":[{"batb":[[0,1.71,10],[1,1.7,10],[2,1.12,6666.66]],"ltp":2.54,"tv":10.22,"id":40380900}]}]}
{"op":"mcm","clk":"11792830854","pt":1722542120095,"mc":[{"id":"1.231243109","rc":[{"batb":[[0,1.7,10],[1,1.12,6666.66],[2,1.11,7272.72]],"ltp":2.54,"tv":10.22,"id":40380900}]}]}
{"op":"mcm","clk":"11792831007","pt":1722542122385,"mc":[{"id":"1.231243109","rc":[{"batb":[[0,1.71,10],[1,1.7,10],[2,1.12,6666.66]],"ltp":2.54,"tv":10.22,"id":40380900}]}]}
{"op":"mcm","clk":"11792831252","pt":1722542125895,"mc":[{"id":"1.231243109","rc":[{"batb":[[0,1.7,10],[1,1.12,6666.66],[2,1.11,7272.72]],"ltp":2.54,"tv":10.22,"id":40380900}]}]}
{"op":"mcm","clk":"11792831429","pt":1722542128491,"mc":[{"id":"1.231243109","rc":[{"batb":[[0,1.71,10],[1,1.7,10],[2,1.12,6666.66]],"ltp":2.54,"tv":10.22,"id":40380900}]}]}
{"op":"mcm","clk":"11792831700","pt":1722542131902,"mc":[{"id":"1.231243109","rc":[{"batb":[[0,1.7,10],[1,1.12,6666.66],[2,1.11,7272.72]],"ltp":2.54,"tv":10.22,"id":40380900}]}]}
{"op":"mcm","clk":"11792831886","pt":1722542134282,"mc":[{"id":"1.231243109","rc":[{"batb":[[0,1.71,10],[1,1.7,10],[2,1.12,6666.66]],"ltp":2.54,"tv":10.22,"id":40380900}]}]}
{"op":"mcm","clk":"11792832121","pt":1722542137688,"mc":[{"id":"1.231243109","rc":[{"batb":[[0,1.7,10],[1,1.12,6666.66],[2,1.11,7272.72]],"ltp":2.54,"tv":10.22,"id":40380900}]}]}
{"op":"mcm","clk":"11792832247","pt":1722542139970,"mc":[{"id":"1.231243109","rc":[{"batb":[[0,1.71,10],[1,1.7,10],[2,1.12,6666.66]],"ltp":2.54,"tv":10.22,"id":40380900}]}]}
{"op":"mcm","clk":"11792832496","pt":1722542143385,"mc":[{"id":"1.231243109","rc":[{"batb":[[0,1.7,10],[1,1.12,6666.66],[2,1.11,7272.72]],"ltp":2.54,"tv":10.22,"id":40380900}]}]}
{"op":"mcm","clk":"11792832632","pt":1722542145495,"mc":[{"id":"1.231243109","rc":[{"batb":[[0,1.71,10],[1,1.7,10],[2,1.12,6666.66]],"ltp":2.54,"tv":10.22,"id":40380900}]}]}
{"op":"mcm","clk":"11792832863","pt":1722542148898,"mc":[{"id":"1.231243109","rc":[{"batb":[[0,1.7,10],[1,1.12,6666.66],[2,1.11,7272.72]],"ltp":2.54,"tv":10.22,"id":40380900}]}]}
{"op":"mcm","clk":"11792833029","pt":1722542151635,"mc":[{"id":"1.231243109","rc":[{"batb":[[0,1.71,10],[1,1.7,10],[2,1.12,6666.66]],"ltp":2.54,"tv":10.22,"id":40380900}]}]}
{"op":"mcm","clk":"11792833277","pt":1722542154841,"mc":[{"id":"1.231243109","rc":[{"batb":[[0,1.7,10],[1,1.12,6666.66],[2,1.11,7272.72]],"ltp":2.54,"tv":10.22,"id":40380900}]}]}
{"op":"mcm","clk":"11792833498","pt":1722542157748,"mc":[{"id":"1.231243109","rc":[{"batb":[[0,1.71,10],[1,1.7,10],[2,1.12,6666.66]],"ltp":2.54,"tv":10.22,"id":40380900}]}]}
{"op":"mcm","clk":"11792833725","pt":1722542161254,"mc":[{"id":"1.231243109","rc":[{"batb":[[0,1.7,10],[1,1.12,6666.66],[2,1.11,7272.72]],"ltp":2.54,"tv":10.22,"id":40380900}]}]}
{"op":"mcm","clk":"11792833870","pt":1722542163554,"mc":[{"id":"1.231243109","rc":[{"batb":[[0,1.71,10],[1,1.7,10],[2,1.12,6666.66]],"ltp":2.54,"tv":10.22,"id":40380900}]}]}
{"op":"mcm","clk":"11792834126","pt":1722542167006,"mc":[{"id":"1.231243109","rc":[{"batb":[[0,1.7,10],[1,1.12,6666.66],[2,1.11,7272.72]],"ltp":2.54,"tv":10.22,"id":40380900}]}]}
{"op":"mcm","clk":"11792834256","pt":1722542169228,"mc":[{"id":"1.231243109","rc":[{"batb":[[0,1.71,10],[1,1.7,10],[2,1.12,6666.66]],"ltp":2.54,"tv":10.22,"id":40380900}]}]}
{"op":"mcm","clk":"11792834509","pt":1722542172629,"mc":[{"id":"1.231243109","rc":[{"batb":[[0,1.7,10],[1,1.12,6666.66],[2,1.11,7272.72]],"ltp":2.54,"tv":10.22,"id":40380900}]}]}
{"op":"mcm","clk":"11792834666","pt":1722542174847,"mc":[{"id":"1.231243109","rc":[{"batb":[[0,1.71,10],[1,1.7,10],[2,1.12,6666.66]],"ltp":2.54,"tv":10.22,"id":40380900}]}]}
{"op":"mcm","clk":"11792834894","pt":1722542178350,"mc":[{"id":"1.231243109","rc":[{"batb":[[0,1.7,10],[1,1.12,6666.66],[2,1.11,7272.72]],"ltp":2.54,"tv":10.22,"id":40380900}]}]}
{"op":"mcm","clk":"11792834979","pt":1722542179333,"mc":[{"id":"1.231243109","rc":[{"batb":[[0,2.52,11.18],[1,1.7,10],[2,1.12,6666.66]],"ltp":2.54,"tv":10.22,"id":40380900}]}]}
{"op":"mcm","clk":"11792835090","pt":1722542180834,"mc":[{"id":"1.231243109","rc":[{"batb":[[0,2.54,10],[1,2.52,11.18],[2,1.7,10]],"ltp":2.54,"tv":10.22,"id":40380900}]}]}
{"op":"mcm","clk":"11792835167","pt":1722542181964,"mc":[{"id":"1.231243109","rc":[{"batb":[[1,1.7,10],[2,1.12,6666.66]],"ltp":2.54,"tv":10.22,"id":40380900}]}]}
{"op":"mcm","clk":"11792835335","pt":1722542184260,"mc":[{"id":"1.231243109","rc":[{"batb":[[0,1.7,10],[1,1.12,6666.66],[2,1.11,7272.72]],"ltp":2.54,"tv":10.22,"id":40380900}]}]}
{"op":"mcm","clk":"11792835589","pt":1722542187965,"mc":[{"id":"1.231243109","rc":[{"batb":[[0,1.71,10],[1,1.7,10],[2,1.12,6666.66]],"ltp":2.54,"tv":10.22,"id":40380900}]}]}
{"op":"mcm","clk":"11792835839","pt":1722542191266,"mc":[{"id":"1.231243109","rc":[{"batb":[[0,1.7,10],[1,1.12,6666.66],[2,1.11,7272.72]],"ltp":2.54,"tv":10.22,"id":40380900}]}]}
{"op":"mcm","clk":"11792836183","pt":1722542196352,"mc":[{"id":"1.231243109","rc":[{"batb":[[0,1.71,10],[1,1.7,10],[2,1.12,6666.66]],"ltp":2.54,"tv":10.22,"id":40380900}]}]}
{"op":"mcm","clk":"11792836412","pt":1722542199875,"mc":[{"id":"1.231243109","rc":[{"batb":[[0,1.7,10],[1,1.12,6666.66],[2,1.11,7272.72]],"ltp":2.54,"tv":10.22,"id":40380900}]}]}
{"op":"mcm","clk":"11792836602","pt":1722542203181,"mc":[{"id":"1.231243109","rc":[{"batb":[[0,1.71,10],[1,1.7,10],[2,1.12,6666.66]],"ltp":2.54,"tv":10.22,"id":40380900}]}]}
{"op":"mcm","clk":"11792836851","pt":1722542206731,"mc":[{"id":"1.231243109","rc":[{"batb":[[0,1.7,10],[1,1.12,6666.66],[2,1.11,7272.72]],"ltp":2.54,"tv":10.22,"id":40380900}]}]}
{"op":"mcm","clk":"11792836984","pt":1722542208888,"mc":[{"id":"1.231243109","rc":[{"batb":[[0,1.71,10],[1,1.7,10],[2,1.12,6666.66]],"ltp":2.54,"tv":10.22,"id":40380900}]}]}
{"op":"mcm","clk":"11792837227","pt":1722542212309,"mc":[{"id":"1.231243109","rc":[{"batb":[[0,1.7,10],[1,1.12,6666.66],[2,1.11,7272.72]],"ltp":2.54,"tv":10.22,"id":40380900}]}]}
{"op":"mcm","clk":"11792837405","pt":1722542214467,"mc":[{"id":"1.231243109","rc":[{"batb":[[0,1.71,10],[1,1.7,10],[2,1.12,6666.66]],"ltp":2.54,"tv":10.22,"id":40380900}]}]}
{"op":"mcm","clk":"11792837676","pt":1722542218140,"mc":[{"id":"1.231243109","rc":[{"batb":[[0,1.7,10],[1,1.12,6666.66],[2,1.11,7272.72]],"ltp":2.54,"tv":10.22,"id":40380900}]}]}
{"op":"mcm","clk":"11792837929","pt":1722542221101,"mc":[{"id":"1.231243109","rc":[{"batb":[[0,1.71,10],[1,1.7,10],[2,1.12,6666.66]],"ltp":2.54,"tv":10.22,"id":40380900}]}]}
{"op":"mcm","clk":"11792838140","pt":1722542224780,"mc":[{"id":"1.231243109","rc":[{"batb":[[0,1.7,10],[1,1.12,6666.66],[2,1.11,7272.72]],"ltp":2.54,"tv":10.22,"id":40380900}]}]}
{"op":"mcm","clk":"11792838386","pt":1722542228281,"mc":[{"id":"1.231243109","rc":[{"batb":[[0,1.71,10],[1,1.7,10],[2,1.12,6666.66]],"ltp":2.54,"tv":10.22,"id":40380900}]}]}
{"op":"mcm","clk":"11792838597","pt":1722542231690,"mc":[{"id":"1.231243109","rc":[{"batb":[[0,1.7,10],[1,1.12,6666.66],[2,1.11,7272.72]],"ltp":2.54,"tv":10.22,"id":40380900}]}]}
{"op":"mcm","clk":"11792838773","pt":1722542234828,"mc":[{"id":"1.231243109","rc":[{"batb":[[0,1.71,10],[1,1.7,10],[2,1.12,6666.66]],"ltp":2.54,"tv":10.22,"id":40380900}]}]}
{"op":"mcm","clk":"11792838981","pt":1722542238233,"mc":[{"id":"1.231243109","rc":[{"batb":[[0,1.7,10],[1,1.12,6666.66],[2,1.11,7272.72]],"ltp":2.54,"tv":10.22,"id":40380900}]}]}
{"op":"mcm","clk":"11792839119","pt":1722542240631,"mc":[{"id":"1.231243109","rc":[{"batb":[[0,1.71,10],[1,1.7,10],[2,1.12,6666.66]],"ltp":2.54,"tv":10.22,"id":40380900}]}]}
{"op":"mcm","clk":"11792839291","pt":1722542244031,"mc":[{"id":"1.231243109","rc":[{"batb":[[0,1.7,10],[1,1.12,6666.66],[2,1.11,7272.72]],"ltp":2.54,"tv":10.22,"id":40380900}]}]}
{"op":"mcm","clk":"11792839414","pt":1722542246449,"mc":[{"id":"1.231243109","rc":[{"batb":[[0,1.71,10],[1,1.7,10],[2,1.12,6666.66]],"ltp":2.54,"tv":10.22,"id":40380900}]}]}
{"op":"mcm","clk":"11792839608","pt":1722542249827,"mc":[{"id":"1.231243109","rc":[{"batb":[[0,1.7,10],[1,1.12,6666.66],[2,1.11,7272.72]],"ltp":2.54,"tv":10.22,"id":40380900}]}]}
{"op":"mcm","clk":"11792839755","pt":1722542252140,"mc":[{"id":"1.231243109","rc":[{"batb":[[0,1.71,10],[1,1.7,10],[2,1.12,6666.66]],"ltp":2.54,"tv":10.22,"id":40380900}]}]}
{"op":"mcm","clk":"11792839961","pt":1722542255447,"mc":[{"id":"1.231243109","rc":[{"batb":[[0,1.7,10],[1,1.12,6666.66],[2,1.11,7272.72]],"ltp":2.54,"tv":10.22,"id":40380900}]}]}
{"op":"mcm","clk":"11792840206","pt":1722542259534,"mc":[{"id":"1.231243109","rc":[{"batb":[[0,1.71,10],[1,1.7,10],[2,1.12,6666.66]],"ltp":2.54,"tv":10.22,"id":40380900}]}]}
{"op":"mcm","clk":"11792840417","pt":1722542262745,"mc":[{"id":"1.231243109","rc":[{"batb":[[0,1.7,10],[1,1.12,6666.66],[2,1.11,7272.72]],"ltp":2.54,"tv":10.22,"id":40380900}]}]}
{"op":"mcm","clk":"11792840585","pt":1722542265157,"mc":[{"id":"1.231243109","rc":[{"batb":[[0,1.71,10],[1,1.7,10],[2,1.12,6666.66]],"ltp":2.54,"tv":10.22,"id":40380900}]}]}
{"op":"mcm","clk":"11792840799","pt":1722542268365,"mc":[{"id":"1.231243109","rc":[{"batb":[[0,1.7,10],[1,1.12,6666.66],[2,1.11,7272.72]],"ltp":2.54,"tv":10.22,"id":40380900}]}]}
{"op":"mcm","clk":"11792840987","pt":1722542271463,"mc":[{"id":"1.231243109","rc":[{"batb":[[0,1.71,10],[1,1.7,10],[2,1.12,6666.66]],"ltp":2.54,"tv":10.22,"id":40380900}]}]}
{"op":"mcm","clk":"11792841142","pt":1722542273863,"mc":[{"id":"1.231243109","rc":[{"trd":[[1.64,6.48]],"batb":[[0,1.64,5.76]],"ltp":1.64,"tv":76.04,"id":40380901}],"tv":86.26}]}
{"op":"mcm","clk":"11792841202","pt":1722542274881,"mc":[{"id":"1.231243109","rc":[{"batb":[[0,1.7,10],[1,1.12,6666.66],[2,1.11,7272.72]],"ltp":2.54,"tv":10.22,"id":40380900}]}]}
{"op":"mcm","clk":"11792841367","pt":1722542277168,"mc":[{"id":"1.231243109","rc":[{"batb":[[0,1.71,10],[1,1.7,10],[2,1.12,6666.66]],"ltp":2.54,"tv":10.22,"id":40380900}]}]}
{"op":"mcm","clk":"11792841596","pt":1722542280382,"mc":[{"id":"1.231243109","rc":[{"batb":[[0,1.7,10],[1,1.12,6666.66],[2,1.11,7272.72]],"ltp":2.54,"tv":10.22,"id":40380900}]}]}
{"op":"mcm","clk":"11792841866","pt":1722542284208,"mc":[{"id":"1.231243109","rc":[{"batb":[[0,1.71,10],[1,1.7,10],[2,1.12,6666.66]],"ltp":2.54,"tv":10.22,"id":40380900}]}]}
{"op":"mcm","clk":"11792841939","pt":1722542285200,"mc":[{"id":"1.231243109","rc":[{"batb":[[0,2.52,11.47],[1,1.71,10],[2,1.7,10]],"ltp":2.54,"tv":10.22,"id":40380900}]}]}
{"op":"mcm","clk":"11792842125","pt":1722542287586,"mc":[{"id":"1.231243109","rc":[{"batb":[[1,1.7,10],[2,1.12,6666.66]],"ltp":2.54,"tv":10.22,"id":40380900}]}]}
{"op":"mcm","clk":"11792842285","pt":1722542289793,"mc":[{"id":"1.231243109","rc":[{"batb":[[0,2.54,10],[1,2.52,11.47],[2,1.7,10]],"ltp":2.54,"tv":10.22,"id":40380900}]}]}
{"op":"mcm","clk":"11792842388","pt":1722542291296,"mc":[{"id":"1.231243109","rc":[{"batb":[[1,1.7,10],[2,1.12,6666.66]],"ltp":2.54,"tv":10.22,"id":40380900}]}]}
{"op":"mcm","clk":"11792842499","pt":1722542293182,"mc":[{"id":"1.231243109","rc":[{"batb":[[0,1.7,10],[1,1.12,6666.66],[2,1.11,7272.72]],"ltp":2.54,"tv":10.22,"id":40380900}]}]}
{"op":"mcm","clk":"11792842679","pt":1722542296231,"mc":[{"id":"1.231243109","rc":[{"batb":[[0,1.71,10],[1,1.7,10],[2,1.12,6666.66]],"ltp":2.54,"tv":10.22,"id":40380900}]}]}
{"op":"mcm","clk":"11792842925","pt":1722542299495,"mc":[{"id":"1.231243109","rc":[{"batb":[[0,1.7,10],[1,1.12,6666.66],[2,1.11,7272.72]],"ltp":2.54,"tv":10.22,"id":40380900}]}]}
{"op":"mcm","clk":"11792845945","pt":1722542348250,"mc":[{"id":"1.231243109","rc":[{"batl":[[0,1.65,24],[1,1.66,2332.53],[2,1.67,3]],"ltp":1.64,"tv":76.04,"id":40380901}]}]}
{"op":"mcm","clk":"11792848537","pt":1722542391320,"mc":[{"id":"1.231243109","rc":[{"batb":[[0,2.52,11.49],[1,1.7,10],[2,1.12,6666.66]],"ltp":2.54,"tv":10.22,"id":40380900}]}]}
{"op":"mcm","clk":"11792849028","pt":1722542400342,"mc":[{"id":"1.231243109","rc":[{"batb":[[0,2.54,10],[1,2.52,11.49],[2,1.7,10]],"ltp":2.54,"tv":10.22,"id":40380900}]}]}
{"op":"mcm","clk":"11792849261","pt":1722542403711,"mc":[{"id":"1.231243109","rc":[{"batb":[[0,2.52,11.48],[1,1.7,10],[2,1.12,6666.66]],"batl":[[0,6,1.57]],"ltp":2.54,"tv":10.22,"id":40380900},{"trd":[[1.64,6.48],[1.65,49.41]],"batb":[[1,1.59,23.74]],"ltp":1.64,"tv":76.03,"id":40380901}],"tv":86.25}]}
{"op":"mcm","clk":"11792849442","pt":1722542406310,"mc":[{"id":"1.231243109","rc":[{"batb":[[0,2.54,10],[1,2.52,11.48],[2,1.7,10]],"ltp":2.54,"tv":10.22,"id":40380900}]}]}
{"op":"mcm","clk":"11792849661","pt":1722542409844,"mc":[{"id":"1.231243109","rc":[{"batb":[[0,2.52,11.48],[1,1.7,10],[2,1.12,6666.66]],"ltp":2.54,"tv":10.22,"id":40380900}]}]}
{"op":"mcm","clk":"11792849832","pt":1722542412118,"mc":[{"id":"1.231243109","rc":[{"batb":[[0,2.54,10],[1,2.52,11.48],[2,1.7,10]],"ltp":2.54,"tv":10.22,"id":40380900}]}]}
{"op":"mcm","clk":"11792850064","pt":1722542415432,"mc":[{"id":"1.231243109","rc":[{"batb":[[0,2.52,11.48],[1,1.7,10],[2,1.12,6666.66]],"ltp":2.54,"tv":10.22,"id":40380900}]}]}
{"op":"mcm","clk":"11792850232","pt":1722542417759,"mc":[{"id":"1.231243109","rc":[{"batb":[[0,2.54,10],[1,2.52,11.48],[2,1.7,10]],"ltp":2.54,"tv":10.22,"id":40380900}]}]}
{"op":"mcm","clk":"11792850473","pt":1722542421030,"mc":[{"id":"1.231243109","rc":[{"batb":[[0,2.52,11.48],[1,1.7,10],[2,1.12,6666.66]],"ltp":2.54,"tv":10.22,"id":40380900}]}]}
{"op":"mcm","clk":"11792850619","pt":1722542423353,"mc":[{"id":"1.231243109","rc":[{"batb":[[0,2.54,10],[1,2.52,11.48],[2,1.7,10]],"ltp":2.54,"tv":10.22,"id":40380900}]}]}
{"op":"mcm","clk":"11792850827","pt":1722542426868,"mc":[{"id":"1.231243109","rc":[{"batb":[[0,2.52,11.48],[1,1.7,10],[2,1.12,6666.66]],"ltp":2.54,"tv":10.22,"id":40380900}]}]}
{"op":"mcm","clk":"11792851080","pt":1722542430550,"mc":[{"id":"1.231243109","rc":[{"batb":[[0,2.54,10],[1,2.52,11.48],[2,1.7,10]],"ltp":2.54,"tv":10.22,"id":40380900}]}]}
{"op":"mcm","clk":"11792851300","pt":1722542433756,"mc":[{"id":"1.231243109","rc":[{"batb":[[0,2.52,11.48],[1,1.7,10],[2,1.12,6666.66]],"ltp":2.54,"tv":10.22,"id":40380900}]}]}
{"op":"mcm","clk":"11792851515","pt":1722542436973,"mc":[{"id":"1.231243109","rc":[{"batb":[[0,2.54,10],[1,2.52,11.48],[2,1.7,10]],"ltp":2.54,"tv":10.22,"id":40380900}]}]}
{"op":"mcm","clk":"11792851712","pt":1722542440372,"mc":[{"id":"1.231243109","rc":[{"batb":[[0,2.52,11.48],[1,1.7,10],[2,1.12,6666.66]],"ltp":2.54,"tv":10.22,"id":40380900}]}]}
{"op":"mcm","clk":"11792851864","pt":1722542442989,"mc":[{"id":"1.231243109","rc":[{"batb":[[0,2.54,10],[1,2.52,11.48],[2,1.7,10]],"ltp":2.54,"tv":10.22,"id":40380900}]}]}
{"op":"mcm","clk":"11792852086","pt":1722542446397,"mc":[{"id":"1.231243109","rc":[{"batb":[[0,2.52,11.48],[1,1.7,10],[2,1.12,6666.66]],"ltp":2.54,"tv":10.22,"id":40380900}]}]}
{"op":"mcm","clk":"11792852300","pt":1722542449399,"mc":[{"id":"1.231243109","rc":[{"batb":[[0,2.54,10],[1,2.52,11.48],[2,1.7,10]],"ltp":2.54,"tv":10.22,"id":40380900}]}]}
{"op":"mcm","clk":"11792852525","pt":1722542452703,"mc":[{"id":"1.231243109","rc":[{"batb":[[0,2.52,11.48],[1,1.7,10],[2,1.12,6666.66]],"ltp":2.54,"tv":10.22,"id":40380900}]}]}
{"op":"mcm","clk":"11792852670","pt":1722542455085,"mc":[{"id":"1.231243109","rc":[{"batb":[[0,2.54,10],[1,2.52,11.48],[2,1.7,10]],"ltp":2.54,"tv":10.22,"id":40380900}]}]}
{"op":"mcm","clk":"11792852692","pt":1722542455597,"mc":[{"id":"1.231243109","rc":[{"batb":[[1,1.6,800],[2,1.59,23.74]],"ltp":1.64,"tv":76.03,"id":40380901}]}]}
{"op":"mcm","clk":"11792852787","pt":1722542457196,"mc":[{"id":"1.231243109","rc":[{"batb":[[2,1.58,124]],"ltp":1.64,"tv":76.03,"id":40380901}]}]}
{"op":"mcm","clk":"11792852797","pt":1722542457298,"mc":[{"id":"1.231243109","rc":[{"batb":[[1,1.61,17.44],[2,1.6,800]],"ltp":1.64,"tv":76.03,"id":40380901}]}]}
{"op":"mcm","clk":"11792852871","pt":1722542458390,"mc":[{"id":"1.231243109","rc":[{"batb":[[0,2.52,11.48],[1,1.7,10],[2,1.12,6666.66]],"ltp":2.54,"tv":10.22,"id":40380900}]}]}
{"op":"mcm","clk":"11792853045","pt":1722542460710,"mc":[{"id":"1.231243109","rc":[{"batb":[[0,2.54,10],[1,2.52,11.48],[2,1.7,10]],"ltp":2.54,"tv":10.22,"id":40380900}]}]}
{"op":"mcm","clk":"11792853293","pt":1722542464028,"mc":[{"id":"1.231243109","rc":[{"batb":[[0,2.52,11.48],[1,1.7,10],[2,1.12,6666.66]],"ltp":2.54,"tv":10.22,"id":40380900}]}]}
{"op":"mcm","clk":"11792853430","pt":1722542466413,"mc":[{"id":"1.231243109","rc":[{"batb":[[0,2.54,10],[1,2.52,11.48],[2,1.7,10]],"ltp":2.54,"tv":10.22,"id":40380900}]}]}
{"op":"mcm","clk":"11792853668","pt":1722542469842,"mc":[{"id":"1.231243109","rc":[{"batb":[[0,2.52,11.48],[1,1.7,10],[2,1.12,6666.66]],"ltp":2.54,"tv":10.22,"id":40380900}]}]}
{"op":"mcm","clk":"11792853810","pt":1722542472130,"mc":[{"id":"1.231243109","rc":[{"batb":[[0,2.54,10],[1,2.52,11.48],[2,1.7,10]],"ltp":2.54,"tv":10.22,"id":40380900}]}]}
{"op":"mcm","clk":"11792854017","pt":1722542475534,"mc":[{"id":"1.231243109","rc":[{"batb":[[0,2.52,11.48],[1,1.7,10],[2,1.12,6666.66]],"ltp":2.54,"tv":10.22,"id":40380900}]}]}
{"op":"mcm","clk":"11792854144","pt":1722542477754,"mc":[{"id":"1.231243109","rc":[{"batb":[[0,2.54,10],[1,2.52,11.48],[2,1.7,10]],"ltp":2.54,"tv":10.22,"id":40380900}]}]}
{"op":"mcm","clk":"11792854465","pt":1722542481081,"mc":[{"id":"1.231243109","rc":[{"batb":[[0,2.52,11.48],[1,1.7,10],[2,1.12,6666.66]],"ltp":2.54,"tv":10.22,"id":40380900}]}]}
{"op":"mcm","clk":"11792854694","pt":1722542483350,"mc":[{"id":"1.231243109","rc":[{"batb":[[0,2.54,10],[1,2.52,11.48],[2,1.7,10]],"ltp":2.54,"tv":10.22,"id":40380900}]}]}
{"op":"mcm","clk":"11792854908","pt":1722542486730,"mc":[{"id":"1.231243109","rc":[{"batb":[[0,2.52,11.48],[1,1.7,10],[2,1.12,6666.66]],"ltp":2.54,"tv":10.22,"id":40380900}]}]}
{"op":"mcm","clk":"11792855170","pt":1722542490255,"mc":[{"id":"1.231243109","rc":[{"batb":[[0,2.54,10],[1,2.52,11.48],[2,1.7,10]],"ltp":2.54,"tv":10.22,"id":40380900}]}]}
{"op":"mcm","clk":"11792855408","pt":1722542493533,"mc":[{"id":"1.231243109","rc":[{"batb":[[0,2.52,11.48],[1,1.7,10],[2,1.12,6666.66]],"ltp":2.54,"tv":10.22,"id":40380900}]}]}
{"op":"mcm","clk":"11792855554","pt":1722542495859,"mc":[{"id":"1.231243109","rc":[{"batb":[[0,2.54,10],[1,2.52,11.48],[2,1.7,10]],"ltp":2.54,"tv":10.22,"id":40380900}]}]}
{"op":"mcm","clk":"11792855736","pt":1722542499280,"mc":[{"id":"1.231243109","rc":[{"batb":[[0,2.52,11.48],[1,1.7,10],[2,1.12,6666.66]],"ltp":2.54,"tv":10.22,"id":40380900}]}]}
{"op":"mcm","clk":"11792855865","pt":1722542501567,"mc":[{"id":"1.231243109","rc":[{"batb":[[0,2.54,10],[1,2.52,11.48],[2,1.7,10]],"ltp":2.54,"tv":10.22,"id":40380900}]}]}
{"op":"mcm","clk":"11792856050","pt":1722542504977,"mc":[{"id":"1.231243109","rc":[{"batb":[[0,2.52,11.48],[1,1.7,10],[2,1.12,6666.66]],"ltp":2.54,"tv":10.22,"id":40380900}]}]}
{"op":"mcm","clk":"11792856287","pt":1722542508981,"mc":[{"id":"1.231243109","rc":[{"batb":[[0,2.54,10],[1,2.52,11.48],[2,1.7,10]],"ltp":2.54,"tv":10.22,"id":40380900}]}]}
{"op":"mcm","clk":"11792856498","pt":1722542512500,"mc":[{"id":"1.231243109","rc":[{"batb":[[0,2.52,11.48],[1,1.7,10],[2,1.12,6666.66]],"ltp":2.54,"tv":10.22,"id":40380900}]}]}
{"op":"mcm","clk":"11792856669","pt":1722542515199,"mc":[{"id":"1.231243109","rc":[{"batb":[[0,2.54,10],[1,2.52,11.48],[2,1.7,10]],"ltp":2.54,"tv":10.22,"id":40380900}]}]}
{"op":"mcm","clk":"11792856888","pt":1722542518689,"mc":[{"id":"1.231243109","rc":[{"batb":[[0,2.52,11.48],[1,1.7,10],[2,1.12,6666.66]],"ltp":2.54,"tv":10.22,"id":40380900}]}]}
{"op":"mcm","clk":"11792857119","pt":1722542522269,"mc":[{"id":"1.231243109","rc":[{"batb":[[0,2.54,10],[1,2.52,11.48],[2,1.7,10]],"ltp":2.54,"tv":10.22,"id":40380900}]}]}
{"op":"mcm","clk":"11792857311","pt":1722542525798,"mc":[{"id":"1.231243109","rc":[{"batb":[[0,2.52,11.48],[1,1.7,10],[2,1.12,6666.66]],"ltp":2.54,"tv":10.22,"id":40380900}]}]}
{"op":"mcm","clk":"11792857466","pt":1722542528694,"mc":[{"id":"1.231243109","rc":[{"batb":[[0,2.54,10],[1,2.52,11.48],[2,1.7,10]],"ltp":2.54,"tv":10.22,"id":40380900}]}]}
{"op":"mcm","clk":"11792857634","pt":1722542532009,"mc":[{"id":"1.231243109","rc":[{"batb":[[0,2.52,11.48],[1,1.7,10],[2,1.12,6666.66]],"ltp":2.54,"tv":10.22,"id":40380900}]}]}
{"op":"mcm","clk":"11792857829","pt":1722542535220,"mc":[{"id":"1.231243109","rc":[{"batb":[[0,2.54,10],[1,2.52,11.48],[2,1.7,10]],"ltp":2.54,"tv":10.22,"id":40380900}]}]}
{"op":"mcm","clk":"11792858047","pt":1722542538637,"mc":[{"id":"1.231243109","rc":[{"batb":[[0,2.52,11.48],[1,1.7,10],[2,1.12,6666.66]],"ltp":2.54,"tv":10.22,"id":40380900}]}]}
{"op":"mcm","clk":"11792858188","pt":1722542541136,"mc":[{"id":"1.231243109","rc":[{"batb":[[0,2.54,10],[1,2.52,11.48],[2,1.7,10]],"ltp":2.54,"tv":10.22,"id":40380900}]}]}
{"op":"mcm","clk":"11792858362","pt":1722542544644,"mc":[{"id":"1.231243109","rc":[{"batb":[[0,2.52,11.48],[1,1.7,10],[2,1.12,6666.66]],"ltp":2.54,"tv":10.22,"id":40380900}]}]}
{"op":"mcm","clk":"11792858509","pt":1722542546922,"mc":[{"id":"1.231243109","rc":[{"batb":[[0,2.54,10],[1,2.52,11.48],[2,1.7,10]],"ltp":2.54,"tv":10.22,"id":40380900}]}]}
{"op":"mcm","clk":"11792858756","pt":1722542550441,"mc":[{"id":"1.231243109","rc":[{"batb":[[0,2.52,11.48],[1,1.7,10],[2,1.12,6666.66]],"ltp":2.54,"tv":10.22,"id":40380900}]}]}
{"op":"mcm","clk":"11792858882","pt":1722542552715,"mc":[{"id":"1.231243109","rc":[{"batb":[[0,2.54,10],[1,2.52,11.48],[2,1.7,10]],"ltp":2.54,"tv":10.22,"id":40380900}]}]}
{"op":"mcm","clk":"11792859093","pt":1722542556036,"mc":[{"id":"1.231243109","rc":[{"batb":[[0,2.52,11.48],[1,1.7,10],[2,1.12,6666.66]],"ltp":2.54,"tv":10.22,"id":40380900}]}]}
{"op":"mcm","clk":"11792859198","pt":1722542558353,"mc":[{"id":"1.231243109","rc":[{"batb":[[0,2.54,10],[1,2.52,11.48],[2,1.7,10]],"ltp":2.54,"tv":10.22,"id":40380900}]}]}
{"op":"mcm","clk":"11792859374","pt":1722542561769,"mc":[{"id":"1.231243109","rc":[{"batb":[[0,2.52,11.48],[1,1.7,10],[2,1.12,6666.66]],"ltp":2.54,"tv":10.22,"id":40380900}]}]}
{"op":"mcm","clk":"11792859508","pt":1722542564042,"mc":[{"id":"1.231243109","rc":[{"batb":[[0,2.54,10],[1,2.52,11.48],[2,1.7,10]],"ltp":2.54,"tv":10.22,"id":40380900}]}]}
{"op":"mcm","clk":"11792859643","pt":1722542566525,"mc":[{"id":"1.231243109","rc":[{"batb":[[1,1.61,177.44]],"ltp":1.64,"tv":76.03,"id":40380901}]}]}
{"op":"mcm","clk":"11792859689","pt":1722542567448,"mc":[{"id":"1.231243109","rc":[{"batb":[[0,2.52,11.48],[1,1.7,10],[2,1.12,6666.66]],"ltp":2.54,"tv":10.22,"id":40380900}]}]}
{"op":"mcm","clk":"11792859798","pt":1722542569878,"mc":[{"id":"1.231243109","rc":[{"batb":[[0,2.54,10],[1,2.52,11.48],[2,1.7,10]],"ltp":2.54,"tv":10.22,"id":40380900}]}]}
{"op":"mcm","clk":"11792859970","pt":1722542573238,"mc":[{"id":"1.231243109","rc":[{"batb":[[0,2.52,11.48],[1,1.7,10],[2,1.12,6666.66]],"ltp":2.54,"tv":10.22,"id":40380900}]}]}
{"op":"mcm","clk":"11792860110","pt":1722542575453,"mc":[{"id":"1.231243109","rc":[{"batb":[[0,2.54,10],[1,2.52,11.48],[2,1.7,10]],"ltp":2.54,"tv":10.22,"id":40380900}]}]}
{"op":"mcm","clk":"11792860313","pt":1722542578763,"mc":[{"id":"1.231243109","rc":[{"batb":[[0,2.52,11.48],[1,1.7,10],[2,1.12,6666.66]],"ltp":2.54,"tv":10.22,"id":40380900}]}]}
{"op":"mcm","clk":"11792860475","pt":1722542581246,"mc":[{"id":"1.231243109","rc":[{"batb":[[0,2.54,10],[1,2.52,11.48],[2,1.7,10]],"ltp":2.54,"tv":10.22,"id":40380900}]}]}
{"op":"mcm","clk":"11792860705","pt":1722542584561,"mc":[{"id":"1.231243109","rc":[{"batb":[[0,2.52,11.48],[1,1.7,10],[2,1.12,6666.66]],"ltp":2.54,"tv":10.22,"id":40380900}]}]}
{"op":"mcm","clk":"11792860913","pt":1722542587762,"mc":[{"id":"1.231243109","rc":[{"batb":[[0,2.54,10],[1,2.52,11.48],[2,1.7,10]],"ltp":2.54,"tv":10.22,"id":40380900}]}]}
{"op":"mcm","clk":"11792861154","pt":1722542591200,"mc":[{"id":"1.231243109","rc":[{"batb":[[0,2.52,11.48],[1,1.7,10],[2,1.12,6666.66]],"ltp":2.54,"tv":10.22,"id":40380900}]}]}
{"op":"mcm","clk":"11792861285","pt":1722542593592,"mc":[{"id":"1.231243109","rc":[{"batb":[[0,2.54,10],[1,2.52,11.48],[2,1.7,10]],"ltp":2.54,"tv":10.22,"id":40380900}]}]}
{"op":"mcm","clk":"11792861424","pt":1722542596892,"mc":[{"id":"1.231243109","rc":[{"batb":[[0,2.52,11.48],[1,1.7,10],[2,1.12,6666.66]],"ltp":2.54,"tv":10.22,"id":40380900}]}]}
{"op":"mcm","clk":"11792861593","pt":1722542599697,"mc":[{"id":"1.231243109","rc":[{"batb":[[0,2.54,10],[1,2.52,11.48],[2,1.7,10]],"ltp":2.54,"tv":10.22,"id":40380900}]}]}
{"op":"mcm","clk":"11792861748","pt":1722542603013,"mc":[{"id":"1.231243109","rc":[{"batb":[[0,2.52,11.48],[1,1.7,10],[2,1.12,6666.66]],"ltp":2.54,"tv":10.22,"id":40380900}]}]}
{"op":"mcm","clk":"11792861861","pt":1722542605396,"mc":[{"id":"1.231243109","rc":[{"batb":[[0,2.54,10],[1,2.52,11.48],[2,1.7,10]],"ltp":2.54,"tv":10.22,"id":40380900}]}]}
{"op":"mcm","clk":"11792862025","pt":1722542608813,"mc":[{"id":"1.231243109","rc":[{"batb":[[0,2.52,11.48],[1,1.7,10],[2,1.12,6666.66]],"ltp":2.54,"tv":10.22,"id":40380900}]}]}
{"op":"mcm","clk":"11792862215","pt":1722542612517,"mc":[{"id":"1.231243109","rc":[{"batb":[[0,2.54,10],[1,2.52,11.48],[2,1.7,10]],"ltp":2.54,"tv":10.22,"id":40380900}]}]}
{"op":"mcm","clk":"11792862416","pt":1722542615938,"mc":[{"id":"1.231243109","rc":[{"batb":[[0,2.52,11.48],[1,1.7,10],[2,1.12,6666.66]],"ltp":2.54,"tv":10.22,"id":40380900}]}]}
{"op":"mcm","clk":"11792862567","pt":1722542618230,"mc":[{"id":"1.231243109","rc":[{"batb":[[0,2.54,10],[1,2.52,11.48],[2,1.7,10]],"ltp":2.54,"tv":10.22,"id":40380900}]}]}
{"op":"mcm","clk":"11792862744","pt":1722542621417,"mc":[{"id":"1.231243109","rc":[{"batb":[[0,2.52,11.48],[1,1.7,10],[2,1.12,6666.66]],"ltp":2.54,"tv":10.22,"id":40380900}]}]}
{"op":"mcm","clk":"11792862871","pt":1722542623839,"mc":[{"id":"1.231243109","rc":[{"batb":[[0,2.54,10],[1,2.52,11.48],[2,1.7,10]],"ltp":2.54,"tv":10.22,"id":40380900}]}]}
{"op":"mcm","clk":"11792863051","pt":1722542627446,"mc":[{"id":"1.231243109","rc":[{"batb":[[0,2.52,11.48],[1,1.7,10],[2,1.12,6666.66]],"ltp":2.54,"tv":10.22,"id":40380900}]}]}
{"op":"mcm","clk":"11792863162","pt":1722542629840,"mc":[{"id":"1.231243109","rc":[{"batb":[[0,2.54,10],[1,2.52,11.48],[2,1.7,10]],"ltp":2.54,"tv":10.22,"id":40380900}]}]}
{"op":"mcm","clk":"11792863314","pt":1722542633160,"mc":[{"id":"1.231243109","rc":[{"batb":[[0,2.52,11.48],[1,1.7,10],[2,1.12,6666.66]],"ltp":2.54,"tv":10.22,"id":40380900}]}]}
{"op":"mcm","clk":"11792863405","pt":1722542635546,"mc":[{"id":"1.231243109","rc":[{"batb":[[0,2.54,10],[1,2.52,11.48],[2,1.7,10]],"ltp":2.54,"tv":10.22,"id":40380900}]}]}
{"op":"mcm","clk":"11792863574","pt":1722542639066,"mc":[{"id":"1.231243109","rc":[{"batb":[[0,2.52,11.48],[1,1.7,10],[2,1.12,6666.66]],"ltp":2.54,"tv":10.22,"id":40380900}]}]}
{"op":"mcm","clk":"11792863729","pt":1722542642237,"mc":[{"id":"1.231243109","rc":[{"batb":[[0,2.54,10],[1,2.52,11.48],[2,1.7,10]],"ltp":2.54,"tv":10.22,"id":40380900}]}]}
{"op":"mcm","clk":"11792863902","pt":1722542645661,"mc":[{"id":"1.231243109","rc":[{"batb":[[0,2.52,11.48],[1,1.7,10],[2,1.12,6666.66]],"ltp":2.54,"tv":10.22,"id":40380900}]}]}
{"op":"mcm","clk":"11792864045","pt":1722542647955,"mc":[{"id":"1.231243109","rc":[{"batb":[[0,2.54,10],[1,2.52,11.48],[2,1.7,10]],"ltp":2.54,"tv":10.22,"id":40380900}]}]}
{"op":"mcm","clk":"11792864239","pt":1722542651356,"mc":[{"id":"1.231243109","rc":[{"batb":[[0,2.52,11.48],[1,1.7,10],[2,1.12,6666.66]],"ltp":2.54,"tv":10.22,"id":40380900}]}]}
{"op":"mcm","clk":"11792864396","pt":1722542653858,"mc":[{"id":"1.231243109","rc":[{"batb":[[0,2.54,10],[1,2.52,11.48],[2,1.7,10]],"ltp":2.54,"tv":10.22,"id":40380900}]}]}
{"op":"mcm","clk":"11792864627","pt":1722542657379,"mc":[{"id":"1.231243109","rc":[{"batb":[[0,2.52,11.48],[1,1.7,10],[2,1.12,6666.66]],"ltp":2.54,"tv":10.22,"id":40380900}]}]}
{"op":"mcm","clk":"11792864818","pt":1722542660089,"mc":[{"id":"1.231243109","rc":[{"batb":[[0,2.54,10],[1,2.52,11.48],[2,1.7,10]],"ltp":2.54,"tv":10.22,"id":40380900}]}]}
{"op":"mcm","clk":"11792865049","pt":1722542663488,"mc":[{"id":"1.231243109","rc":[{"batb":[[0,2.52,11.48],[1,1.7,10],[2,1.12,6666.66]],"ltp":2.54,"tv":10.22,"id":40380900}]}]}
{"op":"mcm","clk":"11792865229","pt":1722542666505,"mc":[{"id":"1.231243109","rc":[{"batb":[[0,2.54,10],[1,2.52,11.48],[2,1.7,10]],"ltp":2.54,"tv":10.22,"id":40380900}]}]}
{"op":"mcm","clk":"11792865404","pt":1722542669888,"mc":[{"id":"1.231243109","rc":[{"batb":[[0,2.52,11.48],[1,1.7,10],[2,1.12,6666.66]],"ltp":2.54,"tv":10.22,"id":40380900}]}]}
{"op":"mcm","clk":"11792865540","pt":1722542672796,"mc":[{"id":"1.231243109","rc":[{"batb":[[0,2.54,10],[1,2.52,11.48],[2,1.7,10]],"ltp":2.54,"tv":10.22,"id":40380900}]}]}
{"op":"mcm","clk":"11792865728","pt":1722542676105,"mc":[{"id":"1.231243109","rc":[{"batb":[[0,2.52,11.48],[1,1.7,10],[2,1.12,6666.66]],"ltp":2.54,"tv":10.22,"id":40380900}]}]}
{"op":"mcm","clk":"11792865849","pt":1722542678800,"mc":[{"id":"1.231243109","rc":[{"batb":[[0,2.54,10],[1,2.52,11.48],[2,1.7,10]],"ltp":2.54,"tv":10.22,"id":40380900}]}]}
{"op":"mcm","clk":"11792866015","pt":1722542682200,"mc":[{"id":"1.231243109","rc":[{"batb":[[0,2.52,11.48],[1,1.7,10],[2,1.12,6666.66]],"ltp":2.54,"tv":10.22,"id":40380900}]}]}
{"op":"mcm","clk":"11792866139","pt":1722542684482,"mc":[{"id":"1.231243109","rc":[{"batb":[[0,2.54,10],[1,2.52,11.48],[2,1.7,10]],"ltp":2.54,"tv":10.22,"id":40380900}]}]}
{"op":"mcm","clk":"11792866313","pt":1722542688012,"mc":[{"id":"1.231243109","rc":[{"batb":[[0,2.52,11.48],[1,1.7,10],[2,1.12,6666.66]],"ltp":2.54,"tv":10.22,"id":40380900}]}]}
{"op":"mcm","clk":"11792866440","pt":1722542690226,"mc":[{"id":"1.231243109","rc":[{"batb":[[0,2.54,10],[1,2.52,11.48],[2,1.7,10]],"ltp":2.54,"tv":10.22,"id":40380900}]}]}
{"op":"mcm","clk":"11792866624","pt":1722542693424,"mc":[{"id":"1.231243109","rc":[{"batb":[[0,2.52,11.48],[1,1.7,10],[2,1.12,6666.66]],"ltp":2.54,"tv":10.22,"id":40380900}]}]}
{"op":"mcm","clk":"11792866756","pt":1722542695916,"mc":[{"id":"1.231243109","rc":[{"batb":[[0,2.54,10],[1,2.52,11.48],[2,1.7,10]],"ltp":2.54,"tv":10.22,"id":40380900}]}]}
{"op":"mcm","clk":"11792866920","pt":1722542699318,"mc":[{"id":"1.231243109","rc":[{"batb":[[0,2.52,11.48],[1,1.7,10],[2,1.12,6666.66]],"ltp":2.54,"tv":10.22,"id":40380900}]}]}
{"op":"mcm","clk":"11792867079","pt":1722542702227,"mc":[{"id":"1.231243109","rc":[{"batb":[[0,2.54,10],[1,2.52,11.48],[2,1.7,10]],"ltp":2.54,"tv":10.22,"id":40380900}]}]}
{"op":"mcm","clk":"11792867275","pt":1722542705750,"mc":[{"id":"1.231243109","rc":[{"batb":[[0,2.52,11.48],[1,1.7,10],[2,1.12,6666.66]],"ltp":2.54,"tv":10.22,"id":40380900}]}]}
{"op":"mcm","clk":"11792867383","pt":1722542708024,"mc":[{"id":"1.231243109","rc":[{"batb":[[0,2.54,10],[1,2.52,11.48],[2,1.7,10]],"ltp":2.54,"tv":10.22,"id":40380900}]}]}
{"op":"mcm","clk":"11792867525","pt":1722542711332,"mc":[{"id":"1.231243109","rc":[{"batb":[[0,2.52,11.48],[1,1.7,10],[2,1.12,6666.66]],"ltp":2.54,"tv":10.22,"id":40380900}]}]}
{"op":"mcm","clk":"11792867645","pt":1722542713654,"mc":[{"id":"1.231243109","rc":[{"batb":[[0,2.54,10],[1,2.52,11.48],[2,1.7,10]],"ltp":2.54,"tv":10.22,"id":40380900}]}]}
{"op":"mcm","clk":"11792867822","pt":1722542717066,"mc":[{"id":"1.231243109","rc":[{"batb":[[0,2.52,11.48],[1,1.7,10],[2,1.12,6666.66]],"ltp":2.54,"tv":10.22,"id":40380900}]}]}
{"op":"mcm","clk":"11792867938","pt":1722542719244,"mc":[{"id":"1.231243109","rc":[{"batb":[[0,2.54,10],[1,2.52,11.48],[2,1.7,10]],"ltp":2.54,"tv":10.22,"id":40380900}]}]}
{"op":"mcm","clk":"11792868094","pt":1722542722662,"mc":[{"id":"1.231243109","rc":[{"batb":[[0,2.52,11.48],[1,1.7,10],[2,1.12,6666.66]],"ltp":2.54,"tv":10.22,"id":40380900}]}]}
{"op":"mcm","clk":"11792868223","pt":1722542725451,"mc":[{"id":"1.231243109","rc":[{"batb":[[0,2.54,10],[1,2.52,11.48],[2,1.7,10]],"ltp":2.54,"tv":10.22,"id":40380900}]}]}
{"op":"mcm","clk":"11792868380","pt":1722542728856,"mc":[{"id":"1.231243109","rc":[{"batb":[[0,2.52,11.48],[1,1.7,10],[2,1.12,6666.66]],"ltp":2.54,"tv":10.22,"id":40380900}]}]}
{"op":"mcm","clk":"11792868505","pt":1722542731490,"mc":[{"id":"1.231243109","rc":[{"batb":[[0,2.54,10],[1,2.52,11.48],[2,1.7,10]],"ltp":2.54,"tv":10.22,"id":40380900}]}]}
{"op":"mcm","clk":"11792868677","pt":1722542734953,"mc":[{"id":"1.231243109","rc":[{"batb":[[0,2.52,11.48],[1,1.7,10],[2,1.12,6666.66]],"ltp":2.54,"tv":10.22,"id":40380900}]}]}
{"op":"mcm","clk":"11792868851","pt":1722542738163,"mc":[{"id":"1.231243109","rc":[{"batb":[[0,2.54,10],[1,2.52,11.48],[2,1.7,10]],"ltp":2.54,"tv":10.22,"id":40380900}]}]}
{"op":"mcm","clk":"11792869002","pt":1722542741581,"mc":[{"id":"1.231243109","rc":[{"batb":[[0,2.52,11.48],[1,1.7,10],[2,1.12,6666.66]],"ltp":2.54,"tv":10.22,"id":40380900}]}]}
{"op":"mcm","clk":"11792869171","pt":1722542744804,"mc":[{"id":"1.231243109","rc":[{"batb":[[0,2.54,10],[1,2.52,11.48],[2,1.7,10]],"ltp":2.54,"tv":10.22,"id":40380900}]}]}
{"op":"mcm","clk":"11792869348","pt":1722542748105,"mc":[{"id":"1.231243109","rc":[{"batb":[[0,2.52,11.48],[1,1.7,10],[2,1.12,6666.66]],"ltp":2.54,"tv":10.22,"id":40380900}]}]}
{"op":"mcm","clk":"11792869491","pt":1722542750600,"mc":[{"id":"1.231243109","rc":[{"batb":[[0,2.54,10],[1,2.52,11.48],[2,1.7,10]],"ltp":2.54,"tv":10.22,"id":40380900}]}]}
{"op":"mcm","clk":"11792869676","pt":1722542753908,"mc":[{"id":"1.231243109","rc":[{"batb":[[0,2.52,11.48],[1,1.7,10],[2,1.12,6666.66]],"ltp":2.54,"tv":10.22,"id":40380900}]}]}
{"op":"mcm","clk":"11792869796","pt":1722542756500,"mc":[{"id":"1.231243109","rc":[{"batb":[[0,2.54,10],[1,2.52,11.48],[2,1.7,10]],"ltp":2.54,"tv":10.22,"id":40380900}]}]}
{"op":"mcm","clk":"11792870001","pt":1722542760014,"mc":[{"id":"1.231243109","rc":[{"batb":[[0,2.52,11.48],[1,1.7,10],[2,1.12,6666.66]],"ltp":2.54,"tv":10.22,"id":40380900}]}]}
{"op":"mcm","clk":"11792870122","pt":1722542762305,"mc":[{"id":"1.231243109","rc":[{"batb":[[0,2.54,10],[1,2.52,11.48],[2,1.7,10]],"ltp":2.54,"tv":10.22,"id":40380900}]}]}
{"op":"mcm","clk":"11792870277","pt":1722542765720,"mc":[{"id":"1.231243109","rc":[{"batb":[[0,2.52,11.48],[1,1.7,10],[2,1.12,6666.66]],"ltp":2.54,"tv":10.22,"id":40380900}]}]}
{"op":"mcm","clk":"11792870431","pt":1722542768006,"mc":[{"id":"1.231243109","rc":[{"batb":[[0,2.54,10],[1,2.52,11.48],[2,1.7,10]],"ltp":2.54,"tv":10.22,"id":40380900}]}]}
{"op":"mcm","clk":"11792870615","pt":1722542771420,"mc":[{"id":"1.231243109","rc":[{"batb":[[0,2.52,11.48],[1,1.7,10],[2,1.12,6666.66]],"ltp":2.54,"tv":10.22,"id":40380900}]}]}
{"op":"mcm","clk":"11792870737","pt":1722542773804,"mc":[{"id":"1.231243109","rc":[{"batb":[[0,2.54,10],[1,2.52,11.48],[2,1.7,10]],"ltp":2.54,"tv":10.22,"id":40380900}]}]}
{"op":"mcm","clk":"11792870856","pt":1722542777011,"mc":[{"id":"1.231243109","rc":[{"batb":[[0,2.52,11.48],[1,1.7,10],[2,1.12,6666.66]],"ltp":2.54,"tv":10.22,"id":40380900}]}]}
{"op":"mcm","clk":"11792870981","pt":1722542779428,"mc":[{"id":"1.231243109","rc":[{"batb":[[0,2.54,10],[1,2.52,11.48],[2,1.7,10]],"ltp":2.54,"tv":10.22,"id":40380900}]}]}
{"op":"mcm","clk":"11792871134","pt":1722542782641,"mc":[{"id":"1.231243109","rc":[{"batb":[[0,2.52,11.48],[1,1.7,10],[2,1.12,6666.66]],"ltp":2.54,"tv":10.22,"id":40380900}]}]}
{"op":"mcm","clk":"11792871267","pt":1722542785032,"mc":[{"id":"1.231243109","rc":[{"batb":[[0,2.54,10],[1,2.52,11.48],[2,1.7,10]],"ltp":2.54,"tv":10.22,"id":40380900}]}]}
{"op":"mcm","clk":"11792871458","pt":1722542788528,"mc":[{"id":"1.231243109","rc":[{"batb":[[0,2.52,11.48],[1,1.7,10],[2,1.12,6666.66]],"ltp":2.54,"tv":10.22,"id":40380900}]}]}
{"op":"mcm","clk":"11792871602","pt":1722542791049,"mc":[{"id":"1.231243109","rc":[{"batb":[[0,2.54,10],[1,2.52,11.48],[2,1.7,10]],"ltp":2.54,"tv":10.22,"id":40380900}]}]}
{"op":"mcm","clk":"11792871751","pt":1722542794265,"mc":[{"id":"1.231243109","rc":[{"batb":[[0,2.52,11.48],[1,1.7,10],[2,1.12,6666.66]],"ltp":2.54,"tv":10.22,"id":40380900}]}]}
{"op":"mcm","clk":"11792871868","pt":1722542796646,"mc":[{"id":"1.231243109","rc":[{"batb":[[0,2.54,10],[1,2.52,11.48],[2,1.7,10]],"ltp":2.54,"tv":10.22,"id":40380900}]}]}
{"op":"mcm","clk":"11792872030","pt":1722542800054,"mc":[{"id":"1.231243109","rc":[{"batb":[[0,2.52,11.48],[1,1.7,10],[2,1.12,6666.66]],"ltp":2.54,"tv":10.22,"id":40380900}]}]}
{"op":"mcm","clk":"11792872128","pt":1722542802230,"mc":[{"id":"1.231243109","rc":[{"batb":[[0,2.54,10],[1,2.52,11.48],[2,1.7,10]],"ltp":2.54,"tv":10.22,"id":40380900}]}]}
{"op":"mcm","clk":"11792872346","pt":1722542805536,"mc":[{"id":"1.231243109","rc":[{"batb":[[0,2.52,11.48],[1,1.7,10],[2,1.12,6666.66]],"ltp":2.54,"tv":10.22,"id":40380900}]}]}
{"op":"mcm","clk":"11792872495","pt":1722542807959,"mc":[{"id":"1.231243109","rc":[{"batb":[[0,2.54,10],[1,2.52,11.48],[2,1.7,10]],"ltp":2.54,"tv":10.22,"id":40380900}]}]}
{"op":"mcm","clk":"11792872699","pt":1722542811466,"mc":[{"id":"1.231243109","rc":[{"batb":[[0,2.52,11.48],[1,1.7,10],[2,1.12,6666.66]],"ltp":2.54,"tv":10.22,"id":40380900}]}]}
{"op":"mcm","clk":"11792872816","pt":1722542813681,"mc":[{"id":"1.231243109","rc":[{"batb":[[0,2.54,10],[1,2.52,11.48],[2,1.7,10]],"ltp":2.54,"tv":10.22,"id":40380900}]}]}
{"op":"mcm","clk":"11792872980","pt":1722542816880,"mc":[{"id":"1.231243109","rc":[{"batb":[[0,2.52,11.48],[1,1.7,10],[2,1.12,6666.66]],"ltp":2.54,"tv":10.22,"id":40380900}]}]}
{"op":"mcm","clk":"11792873085","pt":1722542819462,"mc":[{"id":"1.231243109","rc":[{"batb":[[0,2.54,10],[1,2.52,11.48],[2,1.7,10]],"ltp":2.54,"tv":10.22,"id":40380900}]}]}
{"op":"mcm","clk":"11792873232","pt":1722542822764,"mc":[{"id":"1.231243109","rc":[{"batb":[[0,2.52,11.48],[1,1.7,10],[2,1.12,6666.66]],"ltp":2.54,"tv":10.22,"id":40380900}]}]}
{"op":"mcm","clk":"11792873349","pt":1722542825081,"mc":[{"id":"1.231243109","rc":[{"batb":[[0,2.54,10],[1,2.52,11.48],[2,1.7,10]],"ltp":2.54,"tv":10.22,"id":40380900}]}]}
{"op":"mcm","clk":"11792873533","pt":1722542828387,"mc":[{"id":"1.231243109","rc":[{"batb":[[0,2.52,11.48],[1,1.7,10],[2,1.12,6666.66]],"ltp":2.54,"tv":10.22,"id":40380900}]}]}
{"op":"mcm","clk":"11792873649","pt":1722542830768,"mc":[{"id":"1.231243109","rc":[{"batb":[[0,2.54,10],[1,2.52,11.48],[2,1.7,10]],"ltp":2.54,"tv":10.22,"id":40380900}]}]}
{"op":"mcm","clk":"11792873787","pt":1722542834177,"mc":[{"id":"1.231243109","rc":[{"batb":[[0,2.52,11.48],[1,1.7,10],[2,1.12,6666.66]],"ltp":2.54,"tv":10.22,"id":40380900}]}]}
{"op":"mcm","clk":"11792873934","pt":1722542837589,"mc":[{"id":"1.231243109","rc":[{"batb":[[0,2.54,10],[1,2.52,11.48],[2,1.7,10]],"ltp":2.54,"tv":10.22,"id":40380900}]}]}
{"op":"mcm","clk":"11792874097","pt":1722542840788,"mc":[{"id":"1.231243109","rc":[{"batb":[[0,2.52,11.48],[1,1.7,10],[2,1.12,6666.66]],"ltp":2.54,"tv":10.22,"id":40380900}]}]}
{"op":"mcm","clk":"11792874235","pt":1722542843507,"mc":[{"id":"1.231243109","rc":[{"batb":[[0,2.54,10],[1,2.52,11.48],[2,1.7,10]],"ltp":2.54,"tv":10.22,"id":40380900}]}]}
{"op":"mcm","clk":"11792874379","pt":1722542846814,"mc":[{"id":"1.231243109","rc":[{"batb":[[0,2.52,11.48],[1,1.7,10],[2,1.12,6666.66]],"ltp":2.54,"tv":10.22,"id":40380900}]}]}
{"op":"mcm","clk":"11792874474","pt":1722542848991,"mc":[{"id":"1.231243109","rc":[{"batb":[[0,2.54,10],[1,2.52,11.48],[2,1.7,10]],"ltp":2.54,"tv":10.22,"id":40380900}]}]}
{"op":"mcm","clk":"11792874686","pt":1722542852404,"mc":[{"id":"1.231243109","rc":[{"batb":[[0,2.52,11.48],[1,1.7,10],[2,1.12,6666.66]],"ltp":2.54,"tv":10.22,"id":40380900}]}]}
{"op":"mcm","clk":"11792874840","pt":1722542855035,"mc":[{"id":"1.231243109","rc":[{"batb":[[0,2.54,10],[1,2.52,11.48],[2,1.7,10]],"ltp":2.54,"tv":10.22,"id":40380900}]}]}
{"op":"mcm","clk":"11792874988","pt":1722542858410,"mc":[{"id":"1.231243109","rc":[{"batb":[[0,2.52,11.48],[1,1.7,10],[2,1.12,6666.66]],"ltp":2.54,"tv":10.22,"id":40380900}]}]}
{"op":"mcm","clk":"11792875137","pt":1722542861724,"mc":[{"id":"1.231243109","rc":[{"batb":[[0,2.54,10],[1,2.52,11.48],[2,1.7,10]],"ltp":2.54,"tv":10.22,"id":40380900}]}]}
{"op":"mcm","clk":"11792875300","pt":1722542865029,"mc":[{"id":"1.231243109","rc":[{"batb":[[0,2.52,11.48],[1,1.7,10],[2,1.12,6666.66]],"ltp":2.54,"tv":10.22,"id":40380900}]}]}
{"op":"mcm","clk":"11792875458","pt":1722542868547,"mc":[{"id":"1.231243109","rc":[{"batb":[[0,2.54,10],[1,2.52,11.48],[2,1.7,10]],"ltp":2.54,"tv":10.22,"id":40380900}]}]}
{"op":"mcm","clk":"11792875613","pt":1722542872011,"mc":[{"id":"1.231243109","rc":[{"batb":[[0,2.52,11.48],[1,1.7,10],[2,1.12,6666.66]],"ltp":2.54,"tv":10.22,"id":40380900}]}]}
{"op":"mcm","clk":"11792875715","pt":1722542874441,"mc":[{"id":"1.231243109","rc":[{"batb":[[0,2.54,10],[1,2.52,11.48],[2,1.7,10]],"ltp":2.54,"tv":10.22,"id":40380900}]}]}
{"op":"mcm","clk":"11792875894","pt":1722542877754,"mc":[{"id":"1.231243109","rc":[{"batb":[[0,2.52,11.48],[1,1.7,10],[2,1.12,6666.66]],"ltp":2.54,"tv":10.22,"id":40380900}]}]}
{"op":"mcm","clk":"11792876009","pt":1722542880043,"mc":[{"id":"1.231243109","rc":[{"batb":[[0,2.54,10],[1,2.52,11.48],[2,1.7,10]],"ltp":2.54,"tv":10.22,"id":40380900}]}]}
{"op":"mcm","clk":"11792876198","pt":1722542883361,"mc":[{"id":"1.231243109","rc":[{"batb":[[0,2.52,11.48],[1,1.7,10],[2,1.12,6666.66]],"ltp":2.54,"tv":10.22,"id":40380900}]}]}
{"op":"mcm","clk":"11792876307","pt":1722542885855,"mc":[{"id":"1.231243109","rc":[{"batb":[[0,2.54,10],[1,2.52,11.48],[2,1.7,10]],"ltp":2.54,"tv":10.22,"id":40380900}]}]}
{"op":"mcm","clk":"11792876504","pt":1722542889381,"mc":[{"id":"1.231243109","rc":[{"batb":[[0,2.52,11.48],[1,1.7,10],[2,1.12,6666.66]],"ltp":2.54,"tv":10.22,"id":40380900}]}]}
{"op":"mcm","clk":"11792876666","pt":1722542892597,"mc":[{"id":"1.231243109","rc":[{"batb":[[0,2.54,10],[1,2.52,11.48],[2,1.7,10]],"ltp":2.54,"tv":10.22,"id":40380900}]}]}
{"op":"mcm","clk":"11792876809","pt":1722542895754,"mc":[{"id":"1.231243109","rc":[{"batb":[[0,2.52,11.48],[1,1.7,10],[2,1.12,6666.66]],"ltp":2.54,"tv":10.22,"id":40380900}]}]}
{"op":"mcm","clk":"11792876906","pt":1722542897875,"mc":[{"id":"1.231243109","rc":[{"batb":[[0,2.54,10],[1,2.52,11.48],[2,1.7,10]],"ltp":2.54,"tv":10.22,"id":40380900}]}]}
{"op":"mcm","clk":"11792877043","pt":1722542901397,"mc":[{"id":"1.231243109","rc":[{"batb":[[0,2.52,11.48],[1,1.7,10],[2,1.12,6666.66]],"ltp":2.54,"tv":10.22,"id":40380900}]}]}
{"op":"mcm","clk":"11792877134","pt":1722542903672,"mc":[{"id":"1.231243109","rc":[{"batb":[[0,2.54,10],[1,2.52,11.48],[2,1.7,10]],"ltp":2.54,"tv":10.22,"id":40380900}]}]}
{"op":"mcm","clk":"11792877302","pt":1722542907183,"mc":[{"id":"1.231243109","rc":[{"batb":[[0,2.52,11.48],[1,1.7,10],[2,1.12,6666.66]],"ltp":2.54,"tv":10.22,"id":40380900}]}]}
{"op":"mcm","clk":"11792877483","pt":1722542910604,"mc":[{"id":"1.231243109","rc":[{"batb":[[0,2.54,10],[1,2.52,11.48],[2,1.7,10]],"ltp":2.54,"tv":10.22,"id":40380900}]}]}
{"op":"mcm","clk":"11792877622","pt":1722542914129,"mc":[{"id":"1.231243109","rc":[{"batb":[[0,2.52,11.48],[1,1.7,10],[2,1.12,6666.66]],"ltp":2.54,"tv":10.22,"id":40380900}]}]}
{"op":"mcm","clk":"11792877821","pt":1722542918430,"mc":[{"id":"1.231243109","rc":[{"batb":[[0,2.54,10],[1,2.52,11.48],[2,1.7,10]],"ltp":2.54,"tv":10.22,"id":40380900}]}]}
{"op":"mcm","clk":"11792878019","pt":1722542921914,"mc":[{"id":"1.231243109","rc":[{"batb":[[0,2.52,11.48],[1,1.7,10],[2,1.12,6666.66]],"ltp":2.54,"tv":10.22,"id":40380900}]}]}
{"op":"mcm","clk":"11792878146","pt":1722542924341,"mc":[{"id":"1.231243109","rc":[{"batb":[[0,2.54,10],[1,2.52,11.48],[2,1.7,10]],"ltp":2.54,"tv":10.22,"id":40380900}]}]}
{"op":"mcm","clk":"11792878324","pt":1722542927718,"mc":[{"id":"1.231243109","rc":[{"batb":[[0,2.52,11.48],[1,1.7,10],[2,1.12,6666.66]],"ltp":2.54,"tv":10.22,"id":40380900}]}]}
{"op":"mcm","clk":"11792878441","pt":1722542930041,"mc":[{"id":"1.231243109","rc":[{"batb":[[0,2.54,10],[1,2.52,11.48],[2,1.7,10]],"ltp":2.54,"tv":10.22,"id":40380900}]}]}
{"op":"mcm","clk":"11792878604","pt":1722542933419,"mc":[{"id":"1.231243109","rc":[{"batb":[[0,2.52,11.48],[1,1.7,10],[2,1.12,6666.66]],"ltp":2.54,"tv":10.22,"id":40380900}]}]}
{"op":"mcm","clk":"11792878728","pt":1722542935750,"mc":[{"id":"1.231243109","rc":[{"batb":[[0,2.54,10],[1,2.52,11.48],[2,1.7,10]],"ltp":2.54,"tv":10.22,"id":40380900}]}]}
{"op":"mcm","clk":"11792878903","pt":1722542939047,"mc":[{"id":"1.231243109","rc":[{"batb":[[0,2.52,11.48],[1,1.7,10],[2,1.12,6666.66]],"ltp":2.54,"tv":10.22,"id":40380900}]}]}
{"op":"mcm","clk":"11792879038","pt":1722542941956,"mc":[{"id":"1.231243109","rc":[{"batb":[[0,2.54,10],[1,2.52,11.48],[2,1.7,10]],"ltp":2.54,"tv":10.22,"id":40380900}]}]}
{"op":"mcm","clk":"11792879193","pt":1722542945377,"mc":[{"id":"1.231243109","rc":[{"batb":[[0,2.52,11.48],[1,1.7,10],[2,1.12,6666.66]],"ltp":2.54,"tv":10.22,"id":40380900}]}]}
{"op":"mcm","clk":"11792879298","pt":1722542948075,"mc":[{"id":"1.231243109","rc":[{"batb":[[0,2.54,10],[1,2.52,11.48],[2,1.7,10]],"ltp":2.54,"tv":10.22,"id":40380900}]}]}
{"op":"mcm","clk":"11792879443","pt":1722542951387,"mc":[{"id":"1.231243109","rc":[{"batb":[[0,2.52,11.48],[1,1.7,10],[2,1.12,6666.66]],"ltp":2.54,"tv":10.22,"id":40380900}]}]}
{"op":"mcm","clk":"11792879572","pt":1722542953770,"mc":[{"id":"1.231243109","rc":[{"batb":[[0,2.54,10],[1,2.52,11.48],[2,1.7,10]],"ltp":2.54,"tv":10.22,"id":40380900}]}]}
{"op":"mcm","clk":"11792879716","pt":1722542957182,"mc":[{"id":"1.231243109","rc":[{"batb":[[0,2.52,11.48],[1,1.7,10],[2,1.12,6666.66]],"ltp":2.54,"tv":10.22,"id":40380900},{"batb":[[0,1.64,34.54]],"ltp":1.64,"tv":76.03,"id":40380901}]}]}
{"op":"mcm","clk":"11792879750","pt":1722542957800,"mc":[{"id":"1.231243109","rc":[{"batb":[[0,1.64,51.65],[1,1.61,160]],"ltp":1.64,"tv":76.03,"id":40380901}]}]}
{"op":"mcm","clk":"11792879883","pt":1722542960119,"mc":[{"id":"1.231243109","rc":[{"batb":[[0,2.54,10],[1,2.52,11.48],[2,1.7,10]],"ltp":2.54,"tv":10.22,"id":40380900}]}]}
{"op":"mcm","clk":"11792880029","pt":1722542963426,"mc":[{"id":"1.231243109","rc":[{"batb":[[0,2.52,11.48],[1,1.7,10],[2,1.12,6666.66]],"ltp":2.54,"tv":10.22,"id":40380900}]}]}
{"op":"mcm","clk":"11792880103","pt":1722542965808,"mc":[{"id":"1.231243109","rc":[{"batb":[[0,2.54,10],[1,2.52,11.48],[2,1.7,10]],"ltp":2.54,"tv":10.22,"id":40380900}]}]}
{"op":"mcm","clk":"11792880241","pt":1722542969110,"mc":[{"id":"1.231243109","rc":[{"batb":[[0,2.52,11.48],[1,1.7,10],[2,1.12,6666.66]],"ltp":2.54,"tv":10.22,"id":40380900}]}]}
{"op":"mcm","clk":"11792880340","pt":1722542971536,"mc":[{"id":"1.231243109","rc":[{"batb":[[0,2.54,10],[1,2.52,11.48],[2,1.7,10]],"ltp":2.54,"tv":10.22,"id":40380900}]}]}
{"op":"mcm","clk":"11792880488","pt":1722542974901,"mc":[{"id":"1.231243109","rc":[{"batb":[[0,2.52,11.48],[1,1.7,10],[2,1.12,6666.66]],"ltp":2.54,"tv":10.22,"id":40380900}]}]}
{"op":"mcm","clk":"11792880631","pt":1722542977230,"mc":[{"id":"1.231243109","rc":[{"batb":[[0,2.54,10],[1,2.52,11.48],[2,1.7,10]],"ltp":2.54,"tv":10.22,"id":40380900}]}]}
{"op":"mcm","clk":"11792880798","pt":1722542980749,"mc":[{"id":"1.231243109","rc":[{"batb":[[0,2.52,11.48],[1,1.7,10],[2,1.12,6666.66]],"ltp":2.54,"tv":10.22,"id":40380900}]}]}
{"op":"mcm","clk":"11792880905","pt":1722542982929,"mc":[{"id":"1.231243109","rc":[{"batb":[[0,2.54,10],[1,2.52,11.48],[2,1.7,10]],"ltp":2.54,"tv":10.22,"id":40380900}]}]}
{"op":"mcm","clk":"11792881066","pt":1722542986345,"mc":[{"id":"1.231243109","rc":[{"batb":[[0,2.52,11.48],[1,1.7,10],[2,1.12,6666.66]],"ltp":2.54,"tv":10.22,"id":40380900}]}]}
{"op":"mcm","clk":"11792881205","pt":1722542989038,"mc":[{"id":"1.231243109","rc":[{"batb":[[0,2.54,10],[1,2.52,11.48],[2,1.7,10]],"ltp":2.54,"tv":10.22,"id":40380900}]}]}
{"op":"mcm","clk":"11792881384","pt":1722542992267,"mc":[{"id":"1.231243109","rc":[{"batb":[[0,2.52,11.48],[1,1.7,10],[2,1.12,6666.66]],"ltp":2.54,"tv":10.22,"id":40380900}]}]}
{"op":"mcm","clk":"11792881582","pt":1722542996144,"mc":[{"id":"1.231243109","rc":[{"batb":[[0,2.54,10],[1,2.52,11.48],[2,1.7,10]],"ltp":2.54,"tv":10.22,"id":40380900}]}]}
{"op":"mcm","clk":"11792881714","pt":1722542998942,"mc":[{"id":"1.231243109","rc":[{"trd":[[2.54,13.11]],"batb":[[0,2.54,6.89]],"ltp":2.54,"tv":13.33,"id":40380900},{"trd":[[1.65,102.19]],"batl":[[0,1.66,2332.53],[1,1.67,3],[2,1.69,20]],"ltp":1.65,"tv":128.81,"id":40380901}],"tv":142.14}]}
{"op":"mcm","clk":"11792881743","pt":1722542999466,"mc":[{"id":"1.231243109","rc":[{"batb":[[0,2.52,11.48],[1,1.7,10],[2,1.12,6666.66]],"ltp":2.54,"tv":13.33,"id":40380900}]}]}
{"op":"mcm","clk":"11792881891","pt":1722543002369,"mc":[{"id":"1.231243109","rc":[{"batb":[[0,2.54,10],[1,2.52,11.48],[2,1.7,10]],"ltp":2.54,"tv":13.33,"id":40380900}]}]}
{"op":"mcm","clk":"11792881976","pt":1722543003849,"mc":[{"id":"1.231243109","rc":[{"batb":[[1,1.7,10],[2,1.12,6666.66]],"ltp":2.54,"tv":13.33,"id":40380900}]}]}
{"op":"mcm","clk":"11792882057","pt":1722543005660,"mc":[{"id":"1.231243109","rc":[{"batb":[[0,1.7,10],[1,1.12,6666.66],[2,1.11,7272.72]],"ltp":2.54,"tv":13.33,"id":40380900}]}]}
{"op":"mcm","clk":"11792882167","pt":1722543008147,"mc":[{"id":"1.231243109","rc":[{"batb":[[0,2.54,10],[1,2.52,11.14],[2,1.7,10]],"ltp":2.54,"tv":13.33,"id":40380900}]}]}
{"op":"mcm","clk":"11792882255","pt":1722543010162,"mc":[{"id":"1.231243109","rc":[{"batb":[[1,1.7,10],[2,1.12,6666.66]],"ltp":2.54,"tv":13.33,"id":40380900}]}]}
{"op":"mcm","clk":"11792882330","pt":1722543011458,"mc":[{"id":"1.231243109","rc":[{"batb":[[0,1.7,10],[1,1.12,6666.66],[2,1.11,7272.72]],"ltp":2.54,"tv":13.33,"id":40380900}]}]}
{"op":"mcm","clk":"11792882446","pt":1722543013788,"mc":[{"id":"1.231243109","rc":[{"batb":[[0,1.71,10],[1,1.7,10],[2,1.12,6666.66]],"ltp":2.54,"tv":13.33,"id":40380900}]}]}
{"op":"mcm","clk":"11792882610","pt":1722543017194,"mc":[{"id":"1.231243109","rc":[{"batb":[[0,1.7,10],[1,1.12,6666.66],[2,1.11,7272.72]],"ltp":2.54,"tv":13.33,"id":40380900}]}]}
{"op":"mcm","clk":"11792882767","pt":1722543019783,"mc":[{"id":"1.231243109","rc":[{"batb":[[0,1.71,10],[1,1.7,10],[2,1.12,6666.66]],"ltp":2.54,"tv":13.33,"id":40380900}]}]}
{"op":"mcm","clk":"11792882899","pt":1722543022995,"mc":[{"id":"1.231243109","rc":[{"batb":[[0,1.7,10],[1,1.12,6666.66],[2,1.11,7272.72]],"ltp":2.54,"tv":13.33,"id":40380900}]}]}
{"op":"mcm","clk":"11792883013","pt":1722543025366,"mc":[{"id":"1.231243109","rc":[{"batb":[[0,1.71,10],[1,1.7,10],[2,1.12,6666.66]],"ltp":2.54,"tv":13.33,"id":40380900}]}]}
{"op":"mcm","clk":"11792883165","pt":1722543028680,"mc":[{"id":"1.231243109","rc":[{"batb":[[0,1.7,10],[1,1.12,6666.66],[2,1.11,7272.72]],"ltp":2.54,"tv":13.33,"id":40380900}]}]}
{"op":"mcm","clk":"11792883302","pt":1722543031079,"mc":[{"id":"1.231243109","rc":[{"batb":[[0,1.71,10],[1,1.7,10],[2,1.12,6666.66]],"ltp":2.54,"tv":13.33,"id":40380900}]}]}
{"op":"mcm","clk":"11792883467","pt":1722543034505,"mc":[{"id":"1.231243109","rc":[{"batb":[[0,1.7,10],[1,1.12,6666.66],[2,1.11,7272.72]],"ltp":2.54,"tv":13.33,"id":40380900}]}]}
{"op":"mcm","clk":"11792883619","pt":1722543037714,"mc":[{"id":"1.231243109","rc":[{"batb":[[0,1.71,10],[1,1.7,10],[2,1.12,6666.66]],"ltp":2.54,"tv":13.33,"id":40380900}]}]}
{"op":"mcm","clk":"11792883760","pt":1722543040920,"mc":[{"id":"1.231243109","rc":[{"batb":[[0,1.7,10],[1,1.12,6666.66],[2,1.11,7272.72]],"ltp":2.54,"tv":13.33,"id":40380900}]}]}
{"op":"mcm","clk":"11792883876","pt":1722543043306,"mc":[{"id":"1.231243109","rc":[{"batb":[[0,1.71,10],[1,1.7,10],[2,1.12,6666.66]],"ltp":2.54,"tv":13.33,"id":40380900}]}]}
{"op":"mcm","clk":"11792884011","pt":1722543046666,"mc":[{"id":"1.231243109","rc":[{"batb":[[0,1.7,10],[1,1.12,6666.66],[2,1.11,7272.72]],"ltp":2.54,"tv":13.33,"id":40380900}]}]}
{"op":"mcm","clk":"11792884122","pt":1722543049109,"mc":[{"id":"1.231243109","rc":[{"batb":[[0,1.71,10],[1,1.7,10],[2,1.12,6666.66]],"ltp":2.54,"tv":13.33,"id":40380900}]}]}
{"op":"mcm","clk":"11792884257","pt":1722543052528,"mc":[{"id":"1.231243109","rc":[{"batb":[[0,1.7,10],[1,1.12,6666.66],[2,1.11,7272.72]],"ltp":2.54,"tv":13.33,"id":40380900}]}]}
{"op":"mcm","clk":"11792884463","pt":1722543056730,"mc":[{"id":"1.231243109","rc":[{"batb":[[0,1.71,10],[1,1.7,10],[2,1.12,6666.66]],"ltp":2.54,"tv":13.33,"id":40380900}]}]}
{"op":"mcm","clk":"11792884630","pt":1722543060245,"mc":[{"id":"1.231243109","rc":[{"batb":[[0,1.7,10],[1,1.12,6666.66],[2,1.11,7272.72]],"ltp":2.54,"tv":13.33,"id":40380900}]}]}
{"op":"mcm","clk":"11792884745","pt":1722543062443,"mc":[{"id":"1.231243109","rc":[{"batb":[[0,1.71,10],[1,1.7,10],[2,1.12,6666.66]],"ltp":2.54,"tv":13.33,"id":40380900}]}]}
{"op":"mcm","clk":"11792884951","pt":1722543065954,"mc":[{"id":"1.231243109","rc":[{"batb":[[0,1.7,10],[1,1.12,6666.66],[2,1.11,7272.72]],"ltp":2.54,"tv":13.33,"id":40380900}]}]}
{"op":"mcm","clk":"11792885119","pt":1722543068554,"mc":[{"id":"1.231243109","rc":[{"batb":[[0,1.71,10],[1,1.7,10],[2,1.12,6666.66]],"ltp":2.54,"tv":13.33,"id":40380900}]}]}
{"op":"mcm","clk":"11792885264","pt":1722543072058,"mc":[{"id":"1.231243109","rc":[{"batb":[[0,1.7,10],[1,1.12,6666.66],[2,1.11,7272.72]],"ltp":2.54,"tv":13.33,"id":40380900}]}]}
{"op":"mcm","clk":"11792885358","pt":1722543074340,"mc":[{"id":"1.231243109","rc":[{"batb":[[0,1.71,10],[1,1.7,10],[2,1.12,6666.66]],"ltp":2.54,"tv":13.33,"id":40380900}]}]}
{"op":"mcm","clk":"11792885513","pt":1722543077649,"mc":[{"id":"1.231243109","rc":[{"batb":[[0,1.7,10],[1,1.12,6666.66],[2,1.11,7272.72]],"ltp":2.54,"tv":13.33,"id":40380900}]}]}
{"op":"mcm","clk":"11792885617","pt":1722543080377,"mc":[{"id":"1.231243109","rc":[{"batb":[[0,1.71,10],[1,1.7,10],[2,1.12,6666.66]],"ltp":2.54,"tv":13.33,"id":40380900}]}]}
{"op":"mcm","clk":"11792885754","pt":1722543083783,"mc":[{"id":"1.231243109","rc":[{"batb":[[0,1.7,10],[1,1.12,6666.66],[2,1.11,7272.72]],"ltp":2.54,"tv":13.33,"id":40380900}]}]}
{"op":"mcm","clk":"11792885870","pt":1722543086282,"mc":[{"id":"1.231243109","rc":[{"batb":[[0,1.71,10],[1,1.7,10],[2,1.12,6666.66]],"ltp":2.54,"tv":13.33,"id":40380900}]}]}
{"op":"mcm","clk":"11792886026","pt":1722543089675,"mc":[{"id":"1.231243109","rc":[{"batb":[[0,1.7,10],[1,1.12,6666.66],[2,1.11,7272.72]],"ltp":2.54,"tv":13.33,"id":40380900}]}]}
{"op":"mcm","clk":"11792886131","pt":1722543092095,"mc":[{"id":"1.231243109","rc":[{"batb":[[0,1.71,10],[1,1.7,10],[2,1.12,6666.66]],"ltp":2.54,"tv":13.33,"id":40380900}]}]}
{"op":"mcm","clk":"11792886273","pt":1722543095565,"mc":[{"id":"1.231243109","rc":[{"batb":[[0,1.7,10],[1,1.12,6666.66],[2,1.11,7272.72]],"ltp":2.54,"tv":13.33,"id":40380900}]}]}
{"op":"mcm","clk":"11792886424","pt":1722543099588,"mc":[{"id":"1.231243109","rc":[{"batb":[[0,1.71,10],[1,1.7,10],[2,1.12,6666.66]],"ltp":2.54,"tv":13.33,"id":40380900}]}]}
{"op":"mcm","clk":"11792886582","pt":1722543103004,"mc":[{"id":"1.231243109","rc":[{"batb":[[0,1.7,10],[1,1.12,6666.66],[2,1.11,7272.72]],"ltp":2.54,"tv":13.33,"id":40380900}]}]}
{"op":"mcm","clk":"11792886746","pt":1722543106214,"mc":[{"id":"1.231243109","rc":[{"batb":[[0,1.71,10],[1,1.7,10],[2,1.12,6666.66]],"ltp":2.54,"tv":13.33,"id":40380900}]}]}
