{"op":"mcm","clk":"11795123132","pt":1722593778272,"mc":[{"id":"1.231344137","marketDefinition":{"bspMarket":false,"turnInPlayEnabled":true,"persistenceEnabled":true,"marketBaseRate":5.0,"eventId":"33462743","eventTypeId":"4","numberOfWinners":1,"bettingType":"ODDS","marketType":"MATCH_ODDS","marketTime":"2024-08-04T10:00:00.000Z","suspendTime":"2024-08-04T10:00:00.000Z","bspReconciled":false,"complete":true,"inPlay":false,"crossMatching":false,"runnersVoidable":false,"numberOfActiveRunners":2,"betDelay":0,"status":"OPEN","runners":[{"status":"ACTIVE","sortPriority":1,"id":2219,"name":"Gloucestershire"},{"status":"ACTIVE","sortPriority":2,"id":2120,"name":"Warwickshire"}],"regulators":["MR_INT"],"countryCode":"GB","discountAllowed":false,"timezone":"GMT","openDate":"2024-08-04T10:00:00.000Z","version":6051291826,"name":"Match Odds","eventName":"Gloucestershire v Warwickshire"},"rc":[{"batb":[[0,1.03,200],[1,1.02,200],[2,1.01,220]],"ltp":0.0,"tv":0.0,"id":2219},{"batb":[[0,1.03,200],[1,1.02,200],[2,1.01,220]],"ltp":0.0,"tv":0.0,"id":2120}]}]}
{"op":"mcm","clk":"11795123251","pt":1722593779829,"mc":[{"id":"1.231344137","marketDefinition":{"bspMarket":false,"turnInPlayEnabled":true,"persistenceEnabled":true,"marketBaseRate":5.0,"eventId":"33462743","eventTypeId":"4","numberOfWinners":1,"bettingType":"ODDS","marketType":"MATCH_ODDS","marketTime":"2024-08-04T10:00:00.000Z","suspendTime":"2024-08-04T10:00:00.000Z","bspReconciled":false,"complete":true,"inPlay":false,"crossMatching":false,"runnersVoidable":false,"numberOfActiveRunners":2,"betDelay":0,"status":"OPEN","runners":[{"status":"ACTIVE","sortPriority":1,"id":2219,"name":"Gloucestershire"},{"status":"ACTIVE","sortPriority":2,"id":2120,"name":"Warwickshire"}],"regulators":["MR_INT"],"countryCode":"GB","discountAllowed":true,"timezone":"GMT","openDate":"2024-08-04T10:00:00.000Z","version":6051291826,"name":"Match Odds","eventName":"Gloucestershire v Warwickshire"}}]}
{"op":"mcm","clk":"11795543017","pt":1722599019120,"mc":[{"id":"1.231344137","rc":[{"batb":[[2,1.01,227.85]],"ltp":0.0,"tv":0.0,"id":2219},{"batb":[[2,1.01,227.85]],"ltp":0.0,"tv":0.0,"id":2120}]}]}
{"op":"mcm","clk":"11795543925","pt":1722599031662,"mc":[{"id":"1.231344137","rc":[{"batb":[[1,1.02,207.85]],"ltp":0.0,"tv":0.0,"id":2219},{"batb":[[1,1.02,207.85]],"ltp":0.0,"tv":0.0,"id":2120}]}]}
{"op":"mcm","clk":"11795544862","pt":1722599043448,"mc":[{"id":"1.231344137","rc":[{"batb":[[0,1.03,207.85]],"ltp":0.0,"tv":0.0,"id":2219},{"batb":[[0,1.03,207.85]],"ltp":0.0,"tv":0.0,"id":2120}]}]}
{"op":"mcm","clk":"11795545927","pt":1722599056151,"mc":[{"id":"1.231344137","rc":[{"batb":[[0,1.04,3.93],[1,1.03,207.85],[2,1.02,207.85]],"ltp":0.0,"tv":0.0,"id":2219},{"batb":[[0,1.04,3.93],[1,1.03,207.85],[2,1.02,207.85]],"ltp":0.0,"tv":0.0,"id":2120}]}]}
{"op":"mcm","clk":"11795547229","pt":1722599072160,"mc":[{"id":"1.231344137","rc":[{"batb":[[0,1.05,3.93],[1,1.04,3.93],[2,1.03,207.85]],"ltp":0.0,"tv":0.0,"id":2219},{"batb":[[0,1.05,3.93],[1,1.04,3.93],[2,1.03,207.85]],"ltp":0.0,"tv":0.0,"id":2120}]}]}
{"op":"mcm","clk":"11795548231","pt":1722599084684,"mc":[{"id":"1.231344137","rc":[{"batb":[[0,1.05,4.71]],"ltp":0.0,"tv":0.0,"id":2219},{"batb":[[0,1.05,4.71]],"ltp":0.0,"tv":0.0,"id":2120}]}]}
{"op":"mcm","clk":"11795549225","pt":1722599097478,"mc":[{"id":"1.231344137","rc":[{"batb":[[0,1.07,7.85],[1,1.05,4.71],[2,1.04,3.93]],"ltp":0.0,"tv":0.0,"id":2219},{"batb":[[0,1.07,7.85],[1,1.05,4.71],[2,1.04,3.93]],"ltp":0.0,"tv":0.0,"id":2120}]}]}
{"op":"mcm","clk":"11795550454","pt":1722599111109,"mc":[{"id":"1.231344137","rc":[{"batb":[[0,1.08,7.85],[1,1.07,7.85],[2,1.05,4.71]],"ltp":0.0,"tv":0.0,"id":2219},{"batb":[[0,1.08,7.85],[1,1.07,7.85],[2,1.05,4.71]],"ltp":0.0,"tv":0.0,"id":2120}]}]}
{"op":"mcm","clk":"11795840343","pt":1722602574888,"mc":[{"id":"1.231344137","rc":[{"batb":[[0,1.08,7.85],[1,1.07,7.85],[2,1.05,4.71]],"ltp":0.0,"tv":0.0,"id":2219},{"batb":[[0,1.08,7.85],[1,1.07,7.85],[2,1.05,4.71]],"ltp":0.0,"tv":0.0,"id":2120}]}]}
{"op":"mcm","clk":"11796247146","pt":1722607974889,"mc":[{"id":"1.231344137","rc":[{"batb":[[0,1.08,7.79],[1,1.07,7.79],[2,1.05,4.68]],"ltp":0.0,"tv":0.0,"id":2219},{"batb":[[0,1.08,7.79],[1,1.07,7.79],[2,1.05,4.68]],"ltp":0.0,"tv":0.0,"id":2120}]}]}
{"op":"mcm","clk":"11796507852","pt":1722611332210,"mc":[{"id":"1.231344137","rc":[{"batb":[[0,1.2,3.15],[1,1.08,7.81],[2,1.07,7.81]],"ltp":0.0,"tv":0.0,"id":2219},{"batb":[[0,1.08,7.81],[1,1.07,7.81],[2,1.05,4.69]],"ltp":0.0,"tv":0.0,"id":2120}]}]}
{"op":"mcm","clk":"11796508598","pt":1722611342009,"mc":[{"id":"1.231344137","rc":[{"batb":[[0,1.21,3.15],[1,1.08,7.81],[2,1.07,7.81]],"ltp":0.0,"tv":0.0,"id":2120}]}]}
{"op":"mcm","clk":"11796508859","pt":1722611346059,"mc":[{"id":"1.231344137","marketDefinition":{"bspMarket":false,"turnInPlayEnabled":true,"persistenceEnabled":true,"marketBaseRate":5.0,"eventId":"33462743","eventTypeId":"4","numberOfWinners":1,"bettingType":"ODDS","marketType":"MATCH_ODDS","marketTime":"2024-08-04T10:00:00.000Z","suspendTime":"2024-08-04T10:00:00.000Z","bspReconciled":false,"complete":true,"inPlay":false,"crossMatching":true,"runnersVoidable":false,"numberOfActiveRunners":2,"betDelay":0,"status":"OPEN","runners":[{"status":"ACTIVE","sortPriority":1,"id":2219,"name":"Gloucestershire"},{"status":"ACTIVE","sortPriority":2,"id":2120,"name":"Warwickshire"}],"regulators":["MR_INT"],"countryCode":"GB","discountAllowed":true,"timezone":"GMT","openDate":"2024-08-04T10:00:00.000Z","version":6051291826,"name":"Match Odds","eventName":"Gloucestershire v Warwickshire"}}]}
{"op":"mcm","clk":"11796673115","pt":1722613429319,"mc":[{"id":"1.231344137","rc":[{"batb":[[0,1.08,7.81],[1,1.07,7.81],[2,1.05,4.69]],"ltp":0.0,"tv":0.0,"id":2120}]}]}
{"op":"mcm","clk":"11796673370","pt":1722613433041,"mc":[{"id":"1.231344137","rc":[{"batb":[[0,1.08,7.81],[1,1.07,7.81],[2,1.05,4.69]],"ltp":0.0,"tv":0.0,"id":2219}]}]}
{"op":"mcm","clk":"11797149162","pt":1722617632785,"mc":[{"id":"1.231344137","rc":[{"batb":[[0,1.18,277.78],[1,1.13,384.62],[2,1.08,7.81]],"ltp":0.0,"tv":0.0,"id":2219},{"batb":[[0,1.13,384.62],[1,1.08,7.81],[2,1.07,7.81]],"ltp":0.0,"tv":0.0,"id":2120}]}]}
{"op":"mcm","clk":"11797149224","pt":1722617633263,"mc":[{"id":"1.231344137","rc":[{"batb":[[0,1.38,131.58],[1,1.33,151.52],[2,1.28,178.57]],"ltp":0.0,"tv":0.0,"id":2219},{"batb":[[0,1.38,131.58],[1,1.33,151.52],[2,1.28,178.57]],"ltp":0.0,"tv":0.0,"id":2120}]}]}
{"op":"mcm","clk":"11797686991","pt":1722620601810,"mc":[{"id":"1.231344137","rc":[{"batb":[[0,1.39,6.79],[1,1.38,131.58],[2,1.33,151.52]],"ltp":0.0,"tv":0.0,"id":2219}]}]}
{"op":"mcm","clk":"11797687049","pt":1722620602085,"mc":[{"id":"1.231344137","rc":[{"batb":[[0,1.39,7.44],[1,1.38,131.58],[2,1.33,151.52]],"ltp":0.0,"tv":0.0,"id":2120}]}]}
{"op":"mcm","clk":"11798347063","pt":1722624175112,"mc":[{"id":"1.231344137","rc":[{"batb":[[0,1.39,6.79]],"ltp":0.0,"tv":0.0,"id":2219},{"batb":[[0,1.39,7.44]],"ltp":0.0,"tv":0.0,"id":2120}]}]}
{"op":"mcm","clk":"11798734319","pt":1722626257935,"mc":[{"id":"1.231344137","rc":[{"batb":[[0,1.4,21.41],[1,1.39,6.79],[2,1.38,131.58]],"ltp":0.0,"tv":0.0,"id":2219},{"batb":[[0,1.4,21.41],[1,1.39,7.43],[2,1.38,131.58]],"ltp":0.0,"tv":0.0,"id":2120}]}]}
{"op":"mcm","clk":"11798986496","pt":1722628062691,"mc":[{"id":"1.231344137","rc":[{"batb":[[0,1.39,6.79],[1,1.38,131.58],[2,1.33,151.52]],"ltp":0.0,"tv":0.0,"id":2219},{"batb":[[0,1.39,7.43],[1,1.38,131.58],[2,1.33,151.52]],"ltp":0.0,"tv":0.0,"id":2120}]}]}
{"op":"mcm","clk":"11798989461","pt":1722628083155,"mc":[{"id":"1.231344137","rc":[{"batb":[[0,1.4,21.41],[1,1.39,6.79],[2,1.38,131.58]],"ltp":0.0,"tv":0.0,"id":2219},{"batb":[[0,1.4,21.41],[1,1.39,7.43],[2,1.38,131.58]],"ltp":0.0,"tv":0.0,"id":2120}]}]}
{"op":"mcm","clk":"11799163088","pt":1722629575109,"mc":[{"id":"1.231344137","rc":[{"batb":[[0,1.4,21.41],[1,1.39,6.78]],"ltp":0.0,"tv":0.0,"id":2219},{"batb":[[0,1.4,21.41],[1,1.39,7.43]],"ltp":0.0,"tv":0.0,"id":2120}]}]}
{"op":"mcm","clk":"11799202941","pt":1722629885753,"mc":[{"id":"1.231344137","rc":[{"batb":[[0,1.39,6.78],[1,1.38,131.58],[2,1.33,151.52]],"ltp":0.0,"tv":0.0,"id":2219},{"batb":[[0,1.39,7.43],[1,1.38,131.58],[2,1.33,151.52]],"ltp":0.0,"tv":0.0,"id":2120}]}]}
{"op":"mcm","clk":"11799220098","pt":1722630053022,"mc":[{"id":"1.231344137","rc":[{"batb":[[0,1.4,21.41],[1,1.39,6.78],[2,1.38,131.58]],"ltp":0.0,"tv":0.0,"id":2219},{"batb":[[0,1.4,21.41],[1,1.39,7.43],[2,1.38,131.58]],"ltp":0.0,"tv":0.0,"id":2120}]}]}
{"op":"mcm","clk":"11799362628","pt":1722631857778,"mc":[{"id":"1.231344137","rc":[{"batb":[[0,1.39,6.78],[1,1.38,131.58],[2,1.33,151.52]],"ltp":0.0,"tv":0.0,"id":2219},{"batb":[[0,1.39,7.43],[1,1.38,131.58],[2,1.33,151.52]],"ltp":0.0,"tv":0.0,"id":2120}]}]}
{"op":"mcm","clk":"11799369796","pt":1722631974284,"mc":[{"id":"1.231344137","rc":[{"batb":[[0,1.4,21.41],[1,1.39,6.78],[2,1.38,131.58]],"ltp":0.0,"tv":0.0,"id":2219},{"batb":[[0,1.4,21.41],[1,1.39,7.43],[2,1.38,131.58]],"ltp":0.0,"tv":0.0,"id":2120}]}]}
{"op":"mcm","clk":"11799447069","pt":1722633781456,"mc":[{"id":"1.231344137","rc":[{"batb":[[0,1.39,6.79],[1,1.38,131.58],[2,1.33,151.52]],"ltp":0.0,"tv":0.0,"id":2219},{"batb":[[0,1.39,7.43],[1,1.38,131.58],[2,1.33,151.52]],"ltp":0.0,"tv":0.0,"id":2120}]}]}
{"op":"mcm","clk":"11799450532","pt":1722633852791,"mc":[{"id":"1.231344137","rc":[{"batb":[[0,1.4,21.41],[1,1.39,6.79],[2,1.38,131.58]],"ltp":0.0,"tv":0.0,"id":2219}]}]}
{"op":"mcm","clk":"11799450542","pt":1722633852895,"mc":[{"id":"1.231344137","rc":[{"batb":[[0,1.4,21.41],[1,1.39,7.43],[2,1.38,131.58]],"ltp":0.0,"tv":0.0,"id":2120}]}]}
{"op":"mcm","clk":"11799545769","pt":1722635653561,"mc":[{"id":"1.231344137","rc":[{"batb":[[0,1.39,6.79],[1,1.38,131.58],[2,1.33,151.52]],"ltp":0.0,"tv":0.0,"id":2219},{"batb":[[0,1.39,7.43],[1,1.38,131.58],[2,1.33,151.52]],"ltp":0.0,"tv":0.0,"id":2120}]}]}
{"op":"mcm","clk":"11799548693","pt":1722635717618,"mc":[{"id":"1.231344137","rc":[{"batb":[[0,1.4,21.41],[1,1.39,6.79],[2,1.38,131.58]],"ltp":0.0,"tv":0.0,"id":2219},{"batb":[[0,1.4,21.41],[1,1.39,7.43],[2,1.38,131.58]],"ltp":0.0,"tv":0.0,"id":2120}]}]}
{"op":"mcm","clk":"11799554829","pt":1722635865188,"mc":[{"id":"1.231344137","rc":[{"batb":[[0,1.41,85.22],[1,1.4,21.41],[2,1.39,7.43]],"ltp":0.0,"tv":0.0,"id":2120}]}]}
{"op":"mcm","clk":"11799554883","pt":1722635866216,"mc":[{"id":"1.231344137","rc":[{"batb":[[0,1.41,85.22],[1,1.4,21.41],[2,1.39,6.79]],"ltp":0.0,"tv":0.0,"id":2219}]}]}
{"op":"mcm","clk":"11799624295","pt":1722637518808,"mc":[{"id":"1.231344137","rc":[{"batb":[[0,1.41,85.28],[1,1.39,6.79],[2,1.38,131.58]],"ltp":0.0,"tv":0.0,"id":2219},{"batb":[[0,1.41,85.28],[1,1.39,7.43],[2,1.38,131.58]],"ltp":0.0,"tv":0.0,"id":2120}]}]}
{"op":"mcm","clk":"11799627010","pt":1722637576996,"mc":[{"id":"1.231344137","rc":[{"batb":[[0,1.42,20.39],[1,1.41,85.28],[2,1.39,6.79]],"ltp":0.0,"tv":0.0,"id":2219},{"batb":[[0,1.42,20.39],[1,1.41,85.28],[2,1.39,7.43]],"ltp":0.0,"tv":0.0,"id":2120}]}]}
{"op":"mcm","clk":"11799648585","pt":1722637981763,"mc":[{"id":"1.231344137","rc":[{"batb":[[0,1.42,27.18],[2,1.38,131.58]],"ltp":0.0,"tv":0.0,"id":2219},{"batb":[[0,1.42,27.83],[2,1.38,131.58]],"ltp":0.0,"tv":0.0,"id":2120}]}]}
{"op":"mcm","clk":"11799714134","pt":1722639378116,"mc":[{"id":"1.231344137","rc":[{"batb":[[0,1.42,6.79]],"ltp":0.0,"tv":0.0,"id":2219},{"batb":[[0,1.42,7.43]],"ltp":0.0,"tv":0.0,"id":2120}]}]}
{"op":"mcm","clk":"11799716027","pt":1722639429557,"mc":[{"id":"1.231344137","rc":[{"batb":[[0,1.43,19.92],[1,1.42,6.79],[2,1.41,85.28]],"ltp":0.0,"tv":0.0,"id":2219},{"batb":[[0,1.43,19.92],[1,1.42,7.43],[2,1.41,85.28]],"ltp":0.0,"tv":0.0,"id":2120}]}]}
{"op":"mcm","clk":"11799807065","pt":1722641230241,"mc":[{"id":"1.231344137","rc":[{"batb":[[0,1.42,6.79],[1,1.41,85.28],[2,1.38,131.58]],"ltp":0.0,"tv":0.0,"id":2219},{"batb":[[0,1.42,7.43],[1,1.41,85.28],[2,1.38,131.58]],"ltp":0.0,"tv":0.0,"id":2120}]}]}
{"op":"mcm","clk":"11799809530","pt":1722641277498,"mc":[{"id":"1.231344137","rc":[{"batb":[[0,1.43,19.92],[1,1.42,6.79],[2,1.41,85.28]],"ltp":0.0,"tv":0.0,"id":2219},{"batb":[[0,1.43,19.92],[1,1.42,7.43],[2,1.41,85.28]],"ltp":0.0,"tv":0.0,"id":2120}]}]}
{"op":"mcm","clk":"11799886807","pt":1722643077710,"mc":[{"id":"1.231344137","rc":[{"batb":[[0,1.42,7.43],[1,1.41,85.28],[2,1.38,131.58]],"ltp":0.0,"tv":0.0,"id":2120}]}]}
{"op":"mcm","clk":"11799886815","pt":1722643077863,"mc":[{"id":"1.231344137","rc":[{"batb":[[0,1.42,6.79],[1,1.41,85.28],[2,1.38,131.58]],"ltp":0.0,"tv":0.0,"id":2219}]}]}
{"op":"mcm","clk":"11799887478","pt":1722643094592,"mc":[{"id":"1.231344137","rc":[{"batb":[[0,1.42,11.31]],"ltp":0.0,"tv":0.0,"id":2219},{"batb":[[0,1.42,11.99]],"ltp":0.0,"tv":0.0,"id":2120}]}]}
{"op":"mcm","clk":"11799887555","pt":1722643096390,"mc":[{"id":"1.231344137","rc":[{"batb":[[0,1.42,6.79]],"ltp":0.0,"tv":0.0,"id":2219},{"batb":[[0,1.42,7.43]],"ltp":0.0,"tv":0.0,"id":2120}]}]}
{"op":"mcm","clk":"11799888370","pt":1722643116349,"mc":[{"id":"1.231344137","rc":[{"batb":[[0,1.43,19.92],[1,1.42,6.79],[2,1.41,85.28]],"ltp":0.0,"tv":0.0,"id":2219},{"batb":[[0,1.43,19.92],[1,1.42,7.43],[2,1.41,85.28]],"ltp":0.0,"tv":0.0,"id":2120}]}]}
{"op":"mcm","clk":"11799967371","pt":1722644916712,"mc":[{"id":"1.231344137","rc":[{"batb":[[0,1.42,6.79],[1,1.41,85.28],[2,1.38,131.58]],"ltp":0.0,"tv":0.0,"id":2219},{"batb":[[0,1.42,7.43],[1,1.41,85.28],[2,1.38,131.58]],"ltp":0.0,"tv":0.0,"id":2120}]}]}
{"op":"mcm","clk":"11799968575","pt":1722644941957,"mc":[{"id":"1.231344137","rc":[{"batb":[[0,1.43,19.92],[1,1.42,6.79],[2,1.41,85.28]],"ltp":0.0,"tv":0.0,"id":2219},{"batb":[[0,1.43,19.92],[1,1.42,7.43],[2,1.41,85.28]],"ltp":0.0,"tv":0.0,"id":2120}]}]}
{"op":"mcm","clk":"11800057778","pt":1722646742705,"mc":[{"id":"1.231344137","rc":[{"batb":[[0,1.42,6.79],[1,1.41,85.28],[2,1.38,131.58]],"ltp":0.0,"tv":0.0,"id":2219}]}]}
{"op":"mcm","clk":"11800057789","pt":1722646742912,"mc":[{"id":"1.231344137","rc":[{"batb":[[0,1.42,7.43],[1,1.41,85.28],[2,1.38,131.58]],"ltp":0.0,"tv":0.0,"id":2120}]}]}
{"op":"mcm","clk":"11800057978","pt":1722646747088,"mc":[{"id":"1.231344137","rc":[{"batb":[[0,1.42,11.31]],"ltp":0.0,"tv":0.0,"id":2219},{"batb":[[0,1.42,11.99]],"ltp":0.0,"tv":0.0,"id":2120}]}]}
{"op":"mcm","clk":"11800058075","pt":1722646749405,"mc":[{"id":"1.231344137","rc":[{"batb":[[0,1.42,6.79]],"ltp":0.0,"tv":0.0,"id":2219},{"batb":[[0,1.42,7.43]],"ltp":0.0,"tv":0.0,"id":2120}]}]}
{"op":"mcm","clk":"11800058328","pt":1722646755699,"mc":[{"id":"1.231344137","rc":[{"batb":[[0,1.43,19.92],[1,1.42,6.79],[2,1.41,85.28]],"ltp":0.0,"tv":0.0,"id":2219},{"batb":[[0,1.43,19.92],[1,1.42,7.43],[2,1.41,85.28]],"ltp":0.0,"tv":0.0,"id":2120}]}]}
{"op":"mcm","clk":"11800124246","pt":1722648556764,"mc":[{"id":"1.231344137","rc":[{"batb":[[0,1.42,7.43],[1,1.41,85.28],[2,1.38,131.58]],"ltp":0.0,"tv":0.0,"id":2120}]}]}
{"op":"mcm","clk":"11800124253","pt":1722648556969,"mc":[{"id":"1.231344137","rc":[{"batb":[[0,1.42,6.79],[1,1.41,85.28],[2,1.38,131.58]],"ltp":0.0,"tv":0.0,"id":2219}]}]}
{"op":"mcm","clk":"11800124521","pt":1722648566610,"mc":[{"id":"1.231344137","rc":[{"batb":[[0,1.43,19.92],[1,1.42,6.79],[2,1.41,85.28]],"ltp":0.0,"tv":0.0,"id":2219},{"batb":[[0,1.43,19.92],[1,1.42,7.43],[2,1.41,85.28]],"ltp":0.0,"tv":0.0,"id":2120}]}]}
{"op":"mcm","clk":"11800187137","pt":1722650367296,"mc":[{"id":"1.231344137","rc":[{"batb":[[0,1.42,6.79],[1,1.41,85.28],[2,1.38,131.58]],"ltp":0.0,"tv":0.0,"id":2219},{"batb":[[0,1.42,7.43],[1,1.41,85.28],[2,1.38,131.58]],"ltp":0.0,"tv":0.0,"id":2120}]}]}
{"op":"mcm","clk":"11800187244","pt":1722650370284,"mc":[{"id":"1.231344137","rc":[{"batb":[[0,1.42,11.31]],"ltp":0.0,"tv":0.0,"id":2219},{"batb":[[0,1.42,11.99]],"ltp":0.0,"tv":0.0,"id":2120}]}]}
{"op":"mcm","clk":"11800187292","pt":1722650371671,"mc":[{"id":"1.231344137","rc":[{"batb":[[0,1.42,6.79]],"ltp":0.0,"tv":0.0,"id":2219},{"batb":[[0,1.42,7.43]],"ltp":0.0,"tv":0.0,"id":2120}]}]}
{"op":"mcm","clk":"11800187329","pt":1722650372390,"mc":[{"id":"1.231344137","rc":[{"batb":[[0,1.43,19.92],[1,1.42,6.79],[2,1.41,85.28]],"ltp":0.0,"tv":0.0,"id":2219},{"batb":[[0,1.43,19.92],[1,1.42,7.43],[2,1.41,85.28]],"ltp":0.0,"tv":0.0,"id":2120}]}]}
{"op":"mcm","clk":"11800278885","pt":1722652176733,"mc":[{"id":"1.231344137","rc":[{"batb":[[0,1.42,6.79],[1,1.41,85.28],[2,1.38,131.58]],"ltp":0.0,"tv":0.0,"id":2219},{"batb":[[0,1.42,7.43],[1,1.41,85.28],[2,1.38,131.58]],"ltp":0.0,"tv":0.0,"id":2120}]}]}
{"op":"mcm","clk":"11800286776","pt":1722652326361,"mc":[{"id":"1.231344137","rc":[{"batb":[[0,1.43,19.92],[1,1.42,6.79],[2,1.41,85.28]],"ltp":0.0,"tv":0.0,"id":2219},{"batb":[[0,1.43,19.92],[1,1.42,7.43],[2,1.41,85.28]],"ltp":0.0,"tv":0.0,"id":2120}]}]}
{"op":"mcm","clk":"11800364764","pt":1722654127799,"mc":[{"id":"1.231344137","rc":[{"batb":[[0,1.42,7.43],[1,1.41,85.28],[2,1.38,131.58]],"ltp":0.0,"tv":0.0,"id":2120}]}]}
{"op":"mcm","clk":"11800364772","pt":1722654127959,"mc":[{"id":"1.231344137","rc":[{"batb":[[0,1.42,6.79],[1,1.41,85.28],[2,1.38,131.58]],"ltp":0.0,"tv":0.0,"id":2219}]}]}
{"op":"mcm","clk":"11800371022","pt":1722654271666,"mc":[{"id":"1.231344137","rc":[{"batb":[[0,1.43,19.92],[1,1.42,6.79],[2,1.41,85.28]],"ltp":0.0,"tv":0.0,"id":2219},{"batb":[[0,1.43,19.92],[1,1.42,7.43],[2,1.41,85.28]],"ltp":0.0,"tv":0.0,"id":2120}]}]}
{"op":"mcm","clk":"11800417417","pt":1722655350226,"mc":[{"id":"1.231344137","rc":[{"batb":[[0,1.43,20.47]],"ltp":0.0,"tv":0.0,"id":2219}]}]}
{"op":"mcm","clk":"11800417869","pt":1722655360170,"mc":[{"id":"1.231344137","rc":[{"batb":[[0,1.43,20.47]],"ltp":0.0,"tv":0.0,"id":2120}]}]}
{"op":"mcm","clk":"11800450532","pt":1722656072434,"mc":[{"id":"1.231344137","rc":[{"batb":[[0,1.42,7.33],[1,1.41,85.28],[2,1.38,131.58]],"ltp":0.0,"tv":0.0,"id":2219},{"batb":[[0,1.42,7.98],[1,1.41,85.28],[2,1.38,131.58]],"ltp":0.0,"tv":0.0,"id":2120}]}]}
{"op":"mcm","clk":"11800455550","pt":1722656172536,"mc":[{"id":"1.231344137","rc":[{"batb":[[0,1.42,11.88]],"ltp":0.0,"tv":0.0,"id":2219},{"batb":[[0,1.42,12.56]],"ltp":0.0,"tv":0.0,"id":2120}]}]}
{"op":"mcm","clk":"11800455656","pt":1722656174543,"mc":[{"id":"1.231344137","rc":[{"batb":[[0,1.42,7.33]],"ltp":0.0,"tv":0.0,"id":2219},{"batb":[[0,1.42,7.98]],"ltp":0.0,"tv":0.0,"id":2120}]}]}
{"op":"mcm","clk":"11800456865","pt":1722656198469,"mc":[{"id":"1.231344137","rc":[{"batb":[[0,1.43,20.47],[1,1.42,6.79],[2,1.41,85.28]],"ltp":0.0,"tv":0.0,"id":2219},{"batb":[[0,1.43,20.47],[1,1.42,7.43],[2,1.41,85.28]],"ltp":0.0,"tv":0.0,"id":2120}]}]}
{"op":"mcm","clk":"11800549083","pt":1722657999700,"mc":[{"id":"1.231344137","rc":[{"batb":[[0,1.42,7.33],[1,1.41,85.28],[2,1.38,131.58]],"ltp":0.0,"tv":0.0,"id":2219},{"batb":[[0,1.42,7.98],[1,1.41,85.28],[2,1.38,131.58]],"ltp":0.0,"tv":0.0,"id":2120}]}]}
{"op":"mcm","clk":"11800554776","pt":1722658122766,"mc":[{"id":"1.231344137","rc":[{"batb":[[0,1.43,20.47],[1,1.42,6.79],[2,1.41,85.28]],"ltp":0.0,"tv":0.0,"id":2219},{"batb":[[0,1.43,20.47],[1,1.42,7.43],[2,1.41,85.28]],"ltp":0.0,"tv":0.0,"id":2120}]}]}
{"op":"mcm","clk":"11800628628","pt":1722659924513,"mc":[{"id":"1.231344137","rc":[{"batb":[[0,1.42,7.33],[1,1.41,85.28],[2,1.38,131.58]],"ltp":0.0,"tv":0.0,"id":2219},{"batb":[[0,1.42,7.98],[1,1.41,85.28],[2,1.38,131.58]],"ltp":0.0,"tv":0.0,"id":2120}]}]}
{"op":"mcm","clk":"11800629609","pt":1722659952051,"mc":[{"id":"1.231344137","rc":[{"batb":[[0,1.42,11.88]],"ltp":0.0,"tv":0.0,"id":2219},{"batb":[[0,1.42,12.56]],"ltp":0.0,"tv":0.0,"id":2120}]}]}
{"op":"mcm","clk":"11800629672","pt":1722659953845,"mc":[{"id":"1.231344137","rc":[{"batb":[[0,1.42,7.33]],"ltp":0.0,"tv":0.0,"id":2219},{"batb":[[0,1.42,7.98]],"ltp":0.0,"tv":0.0,"id":2120}]}]}
{"op":"mcm","clk":"11800632695","pt":1722660033833,"mc":[{"id":"1.231344137","rc":[{"batb":[[0,1.43,20.47],[1,1.42,6.79],[2,1.41,85.28]],"ltp":0.0,"tv":0.0,"id":2219},{"batb":[[0,1.43,20.47],[1,1.42,7.43],[2,1.41,85.28]],"ltp":0.0,"tv":0.0,"id":2120}]}]}
{"op":"mcm","clk":"11800687276","pt":1722661834241,"mc":[{"id":"1.231344137","rc":[{"batb":[[0,1.42,7.33],[1,1.41,85.28],[2,1.38,131.58]],"ltp":0.0,"tv":0.0,"id":2219},{"batb":[[0,1.42,7.98],[1,1.41,85.28],[2,1.38,131.58]],"ltp":0.0,"tv":0.0,"id":2120}]}]}
{"op":"mcm","clk":"11800688943","pt":1722661883585,"mc":[{"id":"1.231344137","rc":[{"batb":[[0,1.42,11.88]],"ltp":0.0,"tv":0.0,"id":2219},{"batb":[[0,1.42,12.56]],"ltp":0.0,"tv":0.0,"id":2120}]}]}
{"op":"mcm","clk":"11800688978","pt":1722661884505,"mc":[{"id":"1.231344137","rc":[{"batb":[[0,1.42,7.33]],"ltp":0.0,"tv":0.0,"id":2219},{"batb":[[0,1.42,7.98]],"ltp":0.0,"tv":0.0,"id":2120}]}]}
{"op":"mcm","clk":"11800690775","pt":1722661934748,"mc":[{"id":"1.231344137","rc":[{"batb":[[0,1.43,20.47],[1,1.42,6.79],[2,1.41,85.28]],"ltp":0.0,"tv":0.0,"id":2219},{"batb":[[0,1.43,20.47],[1,1.42,7.43],[2,1.41,85.28]],"ltp":0.0,"tv":0.0,"id":2120}]}]}
{"op":"mcm","clk":"11800730390","pt":1722662770920,"mc":[{"id":"1.231344137","rc":[{"batb":[[0,1.71,7],[1,1.43,20.47],[2,1.42,6.79]],"ltp":0.0,"tv":0.0,"id":2219},{"batb":[[0,1.44,10.55],[1,1.43,19.92],[2,1.42,7.43]],"ltp":0.0,"tv":0.0,"id":2120}]}]}
{"op":"mcm","clk":"11800760127","pt":1722663735684,"mc":[{"id":"1.231344137","rc":[{"batb":[[1,1.42,7.33],[2,1.41,85.28]],"ltp":0.0,"tv":0.0,"id":2219}]}]}
{"op":"mcm","clk":"11800760134","pt":1722663735889,"mc":[{"id":"1.231344137","rc":[{"batb":[[1,1.42,7.43],[2,1.41,85.28]],"ltp":0.0,"tv":0.0,"id":2120}]}]}
{"op":"mcm","clk":"11800763643","pt":1722663835292,"mc":[{"id":"1.231344137","rc":[{"batb":[[0,1.72,11.9],[1,1.71,7],[2,1.42,7.33]],"ltp":0.0,"tv":0.0,"id":2219},{"batb":[[0,1.45,19.58],[1,1.44,10],[2,1.42,7.43]],"ltp":0.0,"tv":0.0,"id":2120}]}]}
{"op":"mcm","clk":"11800790805","pt":1722664545567,"mc":[{"id":"1.231344137","rc":[{"batb":[[0,1.73,7],[1,1.72,11.9]],"ltp":0.0,"tv":0.0,"id":2219},{"batb":[[0,1.46,10.55],[1,1.45,19.04]],"ltp":0.0,"tv":0.0,"id":2120}]}]}
{"op":"mcm","clk":"11800795802","pt":1722664699935,"mc":[{"id":"1.231344137","rc":[{"batb":[[0,1.76,7]],"ltp":0.0,"tv":0.0,"id":2219}]}]}
{"op":"mcm","clk":"11800829563","pt":1722665635768,"mc":[{"id":"1.231344137","rc":[{"batb":[[1,1.42,7.33],[2,1.41,85.28]],"ltp":0.0,"tv":0.0,"id":2219},{"batb":[[1,1.42,7.43],[2,1.41,85.28]],"ltp":0.0,"tv":0.0,"id":2120}]}]}
{"op":"mcm","clk":"11800833257","pt":1722665737715,"mc":[{"id":"1.231344137","rc":[{"batb":[[0,1.77,11.12],[1,1.76,7],[2,1.42,7.33]],"ltp":0.0,"tv":0.0,"id":2219},{"batb":[[0,1.47,18.77],[1,1.46,10],[2,1.42,7.43]],"ltp":0.0,"tv":0.0,"id":2120}]}]}
{"op":"mcm","clk":"11800839175","pt":1722665924633,"mc":[{"id":"1.231344137","rc":[{"batb":[[0,1.78,7],[1,1.77,11.12]],"ltp":0.0,"tv":0.0,"id":2219},{"batb":[[0,1.48,10.55],[1,1.47,18.22]],"ltp":0.0,"tv":0.0,"id":2120}]}]}
{"op":"mcm","clk":"11800842710","pt":1722666029219,"mc":[{"id":"1.231344137","rc":[{"batb":[[0,1.83,7]],"ltp":0.0,"tv":0.0,"id":2219}]}]}
{"op":"mcm","clk":"11800915090","pt":1722667538242,"mc":[{"id":"1.231344137","rc":[{"batb":[[1,1.42,7.33],[2,1.41,85.28]],"ltp":0.0,"tv":0.0,"id":2219},{"batb":[[1,1.42,7.43],[2,1.41,85.28]],"ltp":0.0,"tv":0.0,"id":2120}]}]}
{"op":"mcm","clk":"11800928529","pt":1722667899086,"mc":[{"id":"1.231344137","rc":[{"batb":[[1,1.42,6.79]],"ltp":0.0,"tv":0.0,"id":2219},{"batb":[[0,1.48,10]],"ltp":0.0,"tv":0.0,"id":2120}]}]}
{"op":"mcm","clk":"11801315575","pt":1722675101683,"mc":[{"id":"1.231344137","rc":[{"batb":[[0,1.82,7]],"ltp":0.0,"tv":0.0,"id":2219}]}]}
{"op":"mcm","clk":"11803437318","pt":1722690903360,"mc":[{"id":"1.231344137","rc":[{"batb":[[0,2.22,36.46],[1,1.82,7],[2,1.42,6.79]],"ltp":0.0,"tv":0.0,"id":2219},{"batb":[[0,1.75,59.31],[1,1.48,10],[2,1.42,7.43]],"ltp":0.0,"tv":0.0,"id":2120}]}]}
{"op":"mcm","clk":"11803756254","pt":1722692730411,"mc":[{"id":"1.231344137","rc":[{"batb":[[2,1.41,85.28]],"ltp":0.0,"tv":0.0,"id":2219},{"batb":[[2,1.41,85.28]],"ltp":0.0,"tv":0.0,"id":2120}]}]}
{"op":"mcm","clk":"11804269967","pt":1722694908265,"mc":[{"id":"1.231344137","rc":[{"batb":[[0,2.22,33.1]],"ltp":0.0,"tv":0.0,"id":2219},{"batb":[[0,1.75,53.85]],"ltp":0.0,"tv":0.0,"id":2120}]}]}
{"op":"mcm","clk":"11805865083","pt":1722700881458,"mc":[{"id":"1.231344137","rc":[{"batb":[[0,1.8,273.31],[1,1.75,53.85],[2,1.48,10]],"ltp":0.0,"tv":0.0,"id":2120}]}]}
{"op":"mcm","clk":"11805866019","pt":1722700886802,"mc":[{"id":"1.231344137","rc":[{"trd":[[1.8,546.62]],"batb":[[0,1.75,53.85],[1,1.48,10],[2,1.41,85.28]],"ltp":1.8,"tv":546.61,"id":2120}],"tv":546.61}]}
{"op":"mcm","clk":"11805867990","pt":1722700898073,"mc":[{"id":"1.231344137","rc":[{"batb":[[0,1.8,468.53],[1,1.75,53.85],[2,1.48,10]],"ltp":1.8,"tv":546.61,"id":2120}]}]}
{"op":"mcm","clk":"11805868695","pt":1722700902269,"mc":[{"id":"1.231344137","rc":[{"trd":[[1.8,1483.68]],"batb":[[0,1.75,53.85],[1,1.48,10],[2,1.41,85.28]],"ltp":1.8,"tv":1483.67,"id":2120}],"tv":1483.67}]}
{"op":"mcm","clk":"11805870155","pt":1722700910703,"mc":[{"id":"1.231344137","rc":[{"batb":[[0,1.8,468.53],[1,1.75,53.85],[2,1.48,10]],"ltp":1.8,"tv":1483.67,"id":2120}]}]}
{"op":"mcm","clk":"11805870782","pt":1722700914607,"mc":[{"id":"1.231344137","rc":[{"trd":[[1.8,2420.74]],"batb":[[0,1.75,53.85],[1,1.48,10],[2,1.41,85.28]],"ltp":1.8,"tv":2420.74,"id":2120}],"tv":2420.74}]}
{"op":"mcm","clk":"11805872022","pt":1722700921919,"mc":[{"id":"1.231344137","rc":[{"batb":[[0,1.8,468.53],[1,1.75,53.85],[2,1.48,10]],"ltp":1.8,"tv":2420.74,"id":2120}]}]}
{"op":"mcm","clk":"11805872709","pt":1722700925628,"mc":[{"id":"1.231344137","rc":[{"trd":[[1.8,3357.8]],"batb":[[0,1.75,53.85],[1,1.48,10],[2,1.41,85.28]],"ltp":1.8,"tv":3357.8,"id":2120}],"tv":3357.8}]}
{"op":"mcm","clk":"11805873714","pt":1722700932029,"mc":[{"id":"1.231344137","rc":[{"batb":[[0,1.8,468.53],[1,1.75,53.85],[2,1.48,10]],"ltp":1.8,"tv":3357.8,"id":2120}]}]}
{"op":"mcm","clk":"11805874330","pt":1722700935845,"mc":[{"id":"1.231344137","rc":[{"trd":[[1.8,4294.86]],"batb":[[0,1.75,53.85],[1,1.48,10],[2,1.41,85.28]],"ltp":1.8,"tv":4294.86,"id":2120}],"tv":4294.86}]}
{"op":"mcm","clk":"11805875650","pt":1722700944042,"mc":[{"id":"1.231344137","rc":[{"batb":[[0,1.8,468.53],[1,1.75,53.85],[2,1.48,10]],"ltp":1.8,"tv":4294.86,"id":2120}]}]}
{"op":"mcm","clk":"11805876293","pt":1722700947811,"mc":[{"id":"1.231344137","rc":[{"trd":[[1.8,4309.28]],"batb":[[0,1.8,461.32]],"ltp":1.8,"tv":4309.27,"id":2120}],"tv":4309.27}]}
{"op":"mcm","clk":"11805877775","pt":1722700956447,"mc":[{"id":"1.231344137","rc":[{"trd":[[1.8,5231.92]],"batb":[[0,1.75,53.85],[1,1.48,10],[2,1.41,85.28]],"batl":[[0,1.8,7.21]],"ltp":1.8,"tv":5231.92,"id":2120}],"tv":5231.92}]}
{"op":"mcm","clk":"11805879973","pt":1722700969187,"mc":[{"id":"1.231344137","rc":[{"batb":[[0,2.22,37.1]],"batl":[[0,2.34,4]],"ltp":0.0,"tv":0.0,"id":2219}]}]}
{"op":"mcm","clk":"11805881173","pt":1722700976195,"mc":[{"id":"1.231344137","rc":[{"batb":[[0,1.79,468.53],[1,1.75,53.85],[2,1.48,10]],"ltp":1.8,"tv":5231.92,"id":2120}]}]}
{"op":"mcm","clk":"11805881495","pt":1722700978087,"mc":[{"id":"1.231344137","rc":[{"trd":[[1.79,937.06]],"batb":[[0,1.75,53.85],[1,1.48,10],[2,1.41,85.28]],"ltp":1.79,"tv":6168.98,"id":2120}],"tv":6168.98}]}
{"op":"mcm","clk":"11805883150","pt":1722700987695,"mc":[{"id":"1.231344137","rc":[{"batb":[[0,1.79,468.53],[1,1.76,7.21],[2,1.75,53.85]],"ltp":1.79,"tv":6168.98,"id":2120}]}]}
{"op":"mcm","clk":"11805883863","pt":1722700991176,"mc":[{"id":"1.231344137","rc":[{"trd":[[1.79,1874.12]],"batb":[[0,1.76,7.21],[1,1.75,53.85],[2,1.48,10]],"ltp":1.79,"tv":7106.04,"id":2120}],"tv":7106.04}]}
{"op":"mcm","clk":"11805885391","pt":1722700999515,"mc":[{"id":"1.231344137","rc":[{"batb":[[0,2.24,4],[1,2.22,37.1],[2,1.82,7]],"batl":[[0,2.32,4],[1,2.34,4]],"ltp":0.0,"tv":0.0,"id":2219},{"batb":[[0,1.76,11.21]],"batl":[[0,1.82,4]],"ltp":1.79,"tv":7106.04,"id":2120}]}]}
{"op":"mcm","clk":"11805885530","pt":1722701000321,"mc":[{"id":"1.231344137","rc":[{"batb":[[0,2.22,33.1],[1,1.82,7],[2,1.41,85.28]],"ltp":0.0,"tv":0.0,"id":2219},{"batb":[[0,1.79,468.53],[1,1.76,11.21],[2,1.75,53.85]],"ltp":1.79,"tv":7106.04,"id":2120}]}]}
{"op":"mcm","clk":"11805886719","pt":1722701006328,"mc":[{"id":"1.231344137","rc":[{"trd":[[1.79,2811.18]],"batb":[[0,1.76,11.21],[1,1.75,53.85],[2,1.48,10]],"ltp":1.79,"tv":8043.1,"id":2120}],"tv":8043.1}]}
{"op":"mcm","clk":"11805888033","pt":1722701014634,"mc":[{"id":"1.231344137","rc":[{"batb":[[0,2.24,4],[1,2.22,37.1],[2,1.82,7]],"ltp":0.0,"tv":0.0,"id":2219},{"batl":[[0,1.82,4]],"ltp":1.79,"tv":8043.1,"id":2120}]}]}
{"op":"mcm","clk":"11805888822","pt":1722701019606,"mc":[{"id":"1.231344137","rc":[{"batb":[[0,1.79,468.53],[1,1.76,11.21],[2,1.75,53.85]],"ltp":1.79,"tv":8043.1,"id":2120}]}]}
{"op":"mcm","clk":"11805888879","pt":1722701019921,"mc":[{"id":"1.231344137","rc":[{"batb":[[0,2.22,33.1],[1,1.82,7],[2,1.41,85.28]],"ltp":0.0,"tv":0.0,"id":2219}]}]}
{"op":"mcm","clk":"11805889262","pt":1722701022210,"mc":[{"id":"1.231344137","rc":[{"batb":[[1,1.78,4.51],[2,1.76,11.21]],"ltp":1.79,"tv":8043.1,"id":2120}]}]}
{"op":"mcm","clk":"11805889815","pt":1722701025717,"mc":[{"id":"1.231344137","rc":[{"trd":[[1.79,3748.24]],"batb":[[0,1.78,4.51],[1,1.76,4],[2,1.75,53.85]],"ltp":1.79,"tv":8980.16,"id":2120}],"tv":8980.16}]}
{"op":"mcm","clk":"11805890511","pt":1722701029788,"mc":[{"id":"1.231344137","rc":[{"batb":[[0,2.24,4],[1,2.22,37.1],[2,1.82,7]],"ltp":0.0,"tv":0.0,"id":2219},{"batl":[[0,1.82,4]],"ltp":1.79,"tv":8980.16,"id":2120}]}]}
{"op":"mcm","clk":"11805893109","pt":1722701044958,"mc":[{"id":"1.231344137","rc":[{"batl":[[0,1.81,4],[1,1.82,4]],"ltp":1.79,"tv":8980.16,"id":2120}]}]}
{"op":"mcm","clk":"11805895811","pt":1722701061701,"mc":[{"id":"1.231344137","rc":[{"batb":[[0,2.22,33.1],[1,1.82,7],[2,1.41,85.28]],"ltp":0.0,"tv":0.0,"id":2219},{"batb":[[0,1.8,468.53],[1,1.78,4.51],[2,1.76,4]],"ltp":1.79,"tv":8980.16,"id":2120}]}]}
{"op":"mcm","clk":"11805896495","pt":1722701065957,"mc":[{"id":"1.231344137","rc":[{"trd":[[1.8,6168.99]],"batb":[[0,1.78,4.51],[1,1.76,4],[2,1.75,53.85]],"ltp":1.8,"tv":9917.22,"id":2120}],"tv":9917.22}]}
{"op":"mcm","clk":"11805898005","pt":1722701075181,"mc":[{"id":"1.231344137","rc":[{"batb":[[0,2.24,4],[1,2.22,37.1],[2,1.82,7]],"ltp":0.0,"tv":0.0,"id":2219},{"batl":[[0,1.82,4]],"ltp":1.8,"tv":9917.22,"id":2120}]}]}
{"op":"mcm","clk":"11805898225","pt":1722701076415,"mc":[{"id":"1.231344137","rc":[{"batb":[[0,1.79,468.53],[1,1.78,4.51],[2,1.76,4]],"ltp":1.8,"tv":9917.22,"id":2120}]}]}
{"op":"mcm","clk":"11805898335","pt":1722701077110,"mc":[{"id":"1.231344137","rc":[{"batb":[[0,2.22,33.1],[1,1.82,7],[2,1.41,85.28]],"ltp":0.0,"tv":0.0,"id":2219}]}]}
{"op":"mcm","clk":"11805898902","pt":1722701080512,"mc":[{"id":"1.231344137","rc":[{"trd":[[1.79,4685.3]],"batb":[[0,1.78,4.51],[1,1.76,4],[2,1.75,53.85]],"ltp":1.79,"tv":10854.28,"id":2120}],"tv":10854.28}]}
{"op":"mcm","clk":"11805900545","pt":1722701090304,"mc":[{"id":"1.231344137","rc":[{"batb":[[0,2.24,4],[1,2.22,37.1],[2,1.82,7]],"ltp":0.0,"tv":0.0,"id":2219},{"batl":[[0,1.82,4]],"ltp":1.79,"tv":10854.28,"id":2120}]}]}
{"op":"mcm","clk":"11805900788","pt":1722701091737,"mc":[{"id":"1.231344137","rc":[{"batb":[[0,2.22,33.1],[1,1.82,7],[2,1.41,85.28]],"ltp":0.0,"tv":0.0,"id":2219},{"batb":[[0,1.79,468.53],[1,1.78,4.51],[2,1.76,4]],"ltp":1.79,"tv":10854.28,"id":2120}]}]}
{"op":"mcm","clk":"11805901338","pt":1722701095039,"mc":[{"id":"1.231344137","rc":[{"trd":[[1.79,5622.36]],"batb":[[0,1.78,4.51],[1,1.76,4],[2,1.75,53.85]],"ltp":1.79,"tv":11791.35,"id":2120}],"tv":11791.35}]}
{"op":"mcm","clk":"11805903188","pt":1722701105531,"mc":[{"id":"1.231344137","rc":[{"batb":[[0,2.22,37.1]],"batl":[[0,2.26,4],[1,2.32,4],[2,2.34,4]],"ltp":0.0,"tv":0.0,"id":2219},{"batb":[[0,1.81,4],[1,1.8,472.53],[2,1.78,4.51]],"ltp":1.79,"tv":11791.35,"id":2120}]}]}
{"op":"mcm","clk":"11805903683","pt":1722701108521,"mc":[{"id":"1.231344137","rc":[{"trd":[[1.8,7098.05],[1.81,8]],"batb":[[0,1.8,4],[1,1.78,4.51],[2,1.75,53.85]],"ltp":1.8,"tv":12728.41,"id":2120}],"tv":12728.41}]}
{"op":"mcm","clk":"11805904418","pt":1722701113030,"mc":[{"id":"1.231344137","rc":[{"batb":[[0,1.78,4.51],[1,1.75,53.85],[2,1.48,10]],"ltp":1.8,"tv":12728.41,"id":2120}]}]}
{"op":"mcm","clk":"11805905640","pt":1722701119625,"mc":[{"id":"1.231344137","rc":[{"batb":[[0,1.75,53.85],[1,1.48,10],[2,1.41,85.28]],"ltp":1.8,"tv":12728.41,"id":2120}]}]}
{"op":"mcm","clk":"11805905787","pt":1722701120633,"mc":[{"id":"1.231344137","rc":[{"batl":[[0,2.34,4]],"ltp":0.0,"tv":0.0,"id":2219}]}]}
{"op":"mcm","clk":"11805906281","pt":1722701123649,"mc":[{"id":"1.231344137","rc":[{"batb":[[0,1.8,468.53],[1,1.75,53.85],[2,1.48,10]],"ltp":1.8,"tv":12728.41,"id":2120}]}]}
{"op":"mcm","clk":"11805907381","pt":1722701130378,"mc":[{"id":"1.231344137","rc":[{"batb":[[1,1.79,7.21],[2,1.75,53.85]],"ltp":1.8,"tv":12728.41,"id":2120}]}]}
{"op":"mcm","clk":"11805908241","pt":1722701135771,"mc":[{"id":"1.231344137","rc":[{"batl":[[0,2.26,4],[1,2.34,4]],"ltp":0.0,"tv":0.0,"id":2219},{"batb":[[0,1.8,472.53]],"ltp":1.8,"tv":12728.41,"id":2120}]}]}
{"op":"mcm","clk":"11805910574","pt":1722701150379,"mc":[{"id":"1.231344137","rc":[{"trd":[[1.8,8027.3]],"batb":[[0,1.8,7.9]],"ltp":1.8,"tv":13657.66,"id":2120}],"tv":13657.66}]}
{"op":"mcm","clk":"11805910723","pt":1722701151764,"mc":[{"id":"1.231344137","rc":[{"batb":[[0,2.24,4],[1,2.22,37.1],[2,1.82,7]],"batl":[[0,2.34,4],[1,2.34,0]],"ltp":0.0,"tv":0.0,"id":2219},{"batb":[[0,1.8,3.9]],"batl":[[0,1.81,4],[1,1.82,4]],"ltp":1.8,"tv":13657.66,"id":2120}]}]}
{"op":"mcm","clk":"11805911260","pt":1722701154584,"mc":[{"id":"1.231344137","rc":[{"batb":[[0,1.79,7.21],[1,1.75,53.85],[2,1.48,10]],"ltp":1.8,"tv":13657.66,"id":2120}]}]}
{"op":"mcm","clk":"11805911377","pt":1722701155385,"mc":[{"id":"1.231344137","rc":[{"batb":[[0,1.82,7],[1,1.41,85.28],[2,1.3,633.33]],"ltp":0.0,"tv":0.0,"id":2219},{"batb":[[1,1.48,10],[2,1.41,85.28]],"ltp":1.8,"tv":13657.66,"id":2120}]}]}
{"op":"mcm","clk":"11805912007","pt":1722701159900,"mc":[{"id":"1.231344137","rc":[{"batb":[[0,2.22,33.1],[1,1.82,7],[2,1.41,85.28]],"ltp":0.0,"tv":0.0,"id":2219},{"batb":[[1,1.75,53.85],[2,1.48,10]],"ltp":1.8,"tv":13657.66,"id":2120}]}]}
{"op":"mcm","clk":"11805913016","pt":1722701166116,"mc":[{"id":"1.231344137","rc":[{"batb":[[0,2.24,4],[1,2.22,37.1],[2,1.82,7]],"ltp":0.0,"tv":0.0,"id":2219},{"batl":[[0,1.81,4],[1,1.82,4]],"ltp":1.8,"tv":13657.66,"id":2120}]}]}
{"op":"mcm","clk":"11805913435","pt":1722701168313,"mc":[{"id":"1.231344137","rc":[{"batb":[[0,1.8,468.53],[1,1.79,7.21],[2,1.75,53.85]],"ltp":1.8,"tv":13657.66,"id":2120}]}]}
{"op":"mcm","clk":"11805913639","pt":1722701169402,"mc":[{"id":"1.231344137","rc":[{"batb":[[0,2.22,33.1],[1,1.82,7],[2,1.41,85.28]],"ltp":0.0,"tv":0.0,"id":2219}]}]}
{"op":"mcm","clk":"11805914200","pt":1722701172795,"mc":[{"id":"1.231344137","rc":[{"trd":[[1.8,8964.36]],"batb":[[0,1.79,7.21],[1,1.75,53.85],[2,1.48,10]],"ltp":1.8,"tv":14594.72,"id":2120}],"tv":14594.72}]}
{"op":"mcm","clk":"11805915581","pt":1722701181620,"mc":[{"id":"1.231344137","rc":[{"batb":[[0,2.24,4],[1,2.22,37.1],[2,1.82,7]],"ltp":0.0,"tv":0.0,"id":2219},{"batb":[[0,1.8,468.53],[1,1.79,7.21],[2,1.75,53.85]],"batl":[[0,1.81,4],[1,1.82,4]],"ltp":1.8,"tv":14594.72,"id":2120}]}]}
{"op":"mcm","clk":"11805915636","pt":1722701182028,"mc":[{"id":"1.231344137","rc":[{"batb":[[0,2.22,33.1],[1,1.82,7],[2,1.41,85.28]],"ltp":0.0,"tv":0.0,"id":2219}]}]}
{"op":"mcm","clk":"11805916285","pt":1722701185949,"mc":[{"id":"1.231344137","rc":[{"trd":[[1.8,9901.42]],"batb":[[0,1.79,7.21],[1,1.75,53.85],[2,1.48,10]],"ltp":1.8,"tv":15531.78,"id":2120}],"tv":15531.78}]}
{"op":"mcm","clk":"11805917778","pt":1722701195658,"mc":[{"id":"1.231344137","rc":[{"batb":[[0,1.8,468.53],[1,1.79,7.21],[2,1.75,53.85]],"ltp":1.8,"tv":15531.78,"id":2120}]}]}
{"op":"mcm","clk":"11805917909","pt":1722701196446,"mc":[{"id":"1.231344137","rc":[{"batb":[[0,2.22,37.1]],"batl":[[0,2.26,4]],"ltp":0.0,"tv":0.0,"id":2219},{"batb":[[0,1.8,472.53]],"ltp":1.8,"tv":15531.78,"id":2120}]}]}
{"op":"mcm","clk":"11805918551","pt":1722701200445,"mc":[{"id":"1.231344137","rc":[{"trd":[[1.8,10838.48]],"batb":[[0,1.8,4]],"ltp":1.8,"tv":16468.84,"id":2120}],"tv":16468.84}]}
{"op":"mcm","clk":"11805918767","pt":1722701201626,"mc":[{"id":"1.231344137","rc":[{"batb":[[0,1.79,7.21],[1,1.75,53.85],[2,1.48,10]],"ltp":1.8,"tv":16468.84,"id":2120}]}]}
{"op":"mcm","clk":"11805920423","pt":1722701211569,"mc":[{"id":"1.231344137","rc":[{"batb":[[0,2.24,4],[1,2.22,37.1],[2,1.82,7]],"ltp":0.0,"tv":0.0,"id":2219},{"batl":[[0,1.81,4],[1,1.82,4]],"ltp":1.8,"tv":16468.84,"id":2120}]}]}
{"op":"mcm","clk":"11805921076","pt":1722701215146,"mc":[{"id":"1.231344137","rc":[{"batb":[[1,2.22,4]],"ltp":0.0,"tv":0.0,"id":2219},{"batb":[[1,1.48,10],[2,1.41,85.28]],"ltp":1.8,"tv":16468.84,"id":2120}]}]}
{"op":"mcm","clk":"11805921186","pt":1722701215839,"mc":[{"id":"1.231344137","rc":[{"batb":[[0,1.82,7],[1,1.41,85.28],[2,1.3,633.33]],"ltp":0.0,"tv":0.0,"id":2219}]}]}
{"op":"mcm","clk":"11805921904","pt":1722701220062,"mc":[{"id":"1.231344137","rc":[{"batb":[[0,2.22,33.1],[1,1.82,7],[2,1.41,85.28]],"ltp":0.0,"tv":0.0,"id":2219},{"batb":[[1,1.75,53.85],[2,1.48,10]],"ltp":1.8,"tv":16468.84,"id":2120}]}]}
{"op":"mcm","clk":"11805923123","pt":1722701226694,"mc":[{"id":"1.231344137","rc":[{"batb":[[0,2.24,4],[1,2.22,37.1],[2,1.82,7]],"ltp":0.0,"tv":0.0,"id":2219},{"batl":[[0,1.81,4],[1,1.82,4]],"ltp":1.8,"tv":16468.84,"id":2120}]}]}
{"op":"mcm","clk":"11805923893","pt":1722701230791,"mc":[{"id":"1.231344137","rc":[{"batb":[[0,1.82,7],[1,1.41,85.28],[2,1.3,633.33]],"ltp":0.0,"tv":0.0,"id":2219},{"batb":[[1,1.48,10],[2,1.41,85.28]],"ltp":1.8,"tv":16468.84,"id":2120}]}]}
{"op":"mcm","clk":"11805924695","pt":1722701235174,"mc":[{"id":"1.231344137","rc":[{"batb":[[0,2.22,33.1],[1,1.82,7],[2,1.41,85.28]],"ltp":0.0,"tv":0.0,"id":2219},{"batb":[[1,1.75,53.85],[2,1.48,10]],"ltp":1.8,"tv":16468.84,"id":2120}]}]}
{"op":"mcm","clk":"11805925102","pt":1722701237406,"mc":[{"id":"1.231344137","rc":[{"batb":[[0,1.8,468.53],[1,1.79,7.21],[2,1.75,53.85]],"ltp":1.8,"tv":16468.84,"id":2120}]}]}
{"op":"mcm","clk":"11805925849","pt":1722701241395,"mc":[{"id":"1.231344137","rc":[{"trd":[[1.8,11775.55]],"batb":[[0,1.79,7.21],[1,1.75,53.85],[2,1.48,10]],"ltp":1.8,"tv":17405.9,"id":2120}],"tv":17405.9}]}
{"op":"mcm","clk":"11805925951","pt":1722701242007,"mc":[{"id":"1.231344137","rc":[{"batb":[[0,2.22,37.1]],"batl":[[0,2.26,4]],"ltp":0.0,"tv":0.0,"id":2219},{"batl":[[0,1.81,4],[1,1.82,4]],"ltp":1.8,"tv":17405.9,"id":2120}]}]}
{"op":"mcm","clk":"11805928278","pt":1722701254546,"mc":[{"id":"1.231344137","rc":[{"batb":[[0,2.22,33.1]],"ltp":0.0,"tv":0.0,"id":2219},{"batb":[[0,1.8,468.53],[1,1.79,7.21],[2,1.75,53.85]],"ltp":1.8,"tv":17405.9,"id":2120}]}]}
{"op":"mcm","clk":"11805928336","pt":1722701254947,"mc":[{"id":"1.231344137","rc":[{"batb":[[1,1.83,18.04],[2,1.82,7]],"ltp":0.0,"tv":0.0,"id":2219}]}]}
{"op":"mcm","clk":"11805928750","pt":1722701257147,"mc":[{"id":"1.231344137","rc":[{"batb":[[0,1.8,472.53]],"ltp":1.8,"tv":17405.9,"id":2120}]}]}
{"op":"mcm","clk":"11805928985","pt":1722701258443,"mc":[{"id":"1.231344137","rc":[{"trd":[[1.8,12712.61]],"batb":[[0,1.8,4]],"ltp":1.8,"tv":18342.96,"id":2120}],"tv":18342.96}]}
{"op":"mcm","clk":"11805929067","pt":1722701258970,"mc":[{"id":"1.231344137","rc":[{"batb":[[0,1.79,7.21],[1,1.75,53.85],[2,1.48,10]],"ltp":1.8,"tv":18342.96,"id":2120}]}]}
{"op":"mcm","clk":"11805931370","pt":1722701272367,"mc":[{"id":"1.231344137","rc":[{"batb":[[0,2.24,4],[1,2.22,37.1],[2,1.83,18.04]],"ltp":0.0,"tv":0.0,"id":2219},{"batl":[[0,1.81,4],[1,1.82,4]],"ltp":1.8,"tv":18342.96,"id":2120}]}]}
{"op":"mcm","clk":"11805931901","pt":1722701275374,"mc":[{"id":"1.231344137","rc":[{"batb":[[1,2.22,4]],"ltp":0.0,"tv":0.0,"id":2219},{"batb":[[1,1.48,10],[2,1.41,85.28]],"ltp":1.8,"tv":18342.96,"id":2120}]}]}
{"op":"mcm","clk":"11805931999","pt":1722701276078,"mc":[{"id":"1.231344137","rc":[{"batb":[[0,1.83,18.04],[1,1.82,7],[2,1.41,85.28]],"ltp":0.0,"tv":0.0,"id":2219},{"batb":[[0,1.8,468.53],[1,1.79,7.21],[2,1.48,10]],"ltp":1.8,"tv":18342.96,"id":2120}]}]}
{"op":"mcm","clk":"11805932786","pt":1722701280249,"mc":[{"id":"1.231344137","rc":[{"batb":[[0,2.22,33.1],[1,1.83,18.04],[2,1.82,7]],"ltp":0.0,"tv":0.0,"id":2219},{"batb":[[2,1.75,53.85]],"ltp":1.8,"tv":18342.96,"id":2120}]}]}
{"op":"mcm","clk":"11805933006","pt":1722701281543,"mc":[{"id":"1.231344137","rc":[{"trd":[[1.8,13649.67]],"batb":[[0,1.79,7.21],[1,1.75,53.85],[2,1.48,10]],"ltp":1.8,"tv":19280.02,"id":2120}],"tv":19280.02}]}
{"op":"mcm","clk":"11805934167","pt":1722701288246,"mc":[{"id":"1.231344137","rc":[{"batb":[[0,2.24,4],[1,2.22,37.1],[2,1.83,18.04]],"ltp":0.0,"tv":0.0,"id":2219},{"batl":[[0,1.81,4],[1,1.82,4]],"ltp":1.8,"tv":19280.02,"id":2120}]}]}
{"op":"mcm","clk":"11805934570","pt":1722701290647,"mc":[{"id":"1.231344137","rc":[{"batb":[[0,1.83,18.04],[1,1.82,7],[2,1.41,85.28]],"ltp":0.0,"tv":0.0,"id":2219},{"batb":[[1,1.48,10],[2,1.41,85.28]],"ltp":1.8,"tv":19280.02,"id":2120}]}]}
{"op":"mcm","clk":"11805934824","pt":1722701292054,"mc":[{"id":"1.231344137","rc":[{"batb":[[0,1.8,468.53],[1,1.79,7.21],[2,1.48,10]],"ltp":1.8,"tv":19280.02,"id":2120}]}]}
{"op":"mcm","clk":"11805935425","pt":1722701295370,"mc":[{"id":"1.231344137","rc":[{"batb":[[0,2.22,33.1],[1,1.83,18.04],[2,1.82,7]],"ltp":0.0,"tv":0.0,"id":2219},{"batb":[[2,1.75,53.85]],"ltp":1.8,"tv":19280.02,"id":2120}]}]}
{"op":"mcm","clk":"11805935715","pt":1722701297157,"mc":[{"id":"1.231344137","rc":[{"trd":[[1.8,14586.73]],"batb":[[0,1.81,18.04]],"ltp":1.8,"tv":20217.09,"id":2120}],"tv":20217.09}]}
{"op":"mcm","clk":"11805936916","pt":1722701303575,"mc":[{"id":"1.231344137","rc":[{"batb":[[0,2.22,37.1]],"ltp":0.0,"tv":0.0,"id":2219},{"batl":[[0,1.82,4]],"ltp":1.8,"tv":20217.09,"id":2120}]}]}
{"op":"mcm","clk":"11805938560","pt":1722701312566,"mc":[{"id":"1.231344137","rc":[{"batb":[[1,1.75,53.85],[2,1.48,10]],"ltp":1.8,"tv":20217.09,"id":2120}]}]}
{"op":"mcm","clk":"11805938894","pt":1722701314376,"mc":[{"id":"1.231344137","rc":[{"batb":[[0,1.75,53.85],[1,1.48,10],[2,1.41,85.28]],"ltp":1.8,"tv":20217.09,"id":2120}]}]}
{"op":"mcm","clk":"11805939656","pt":1722701318683,"mc":[{"id":"1.231344137","rc":[{"batl":[[0,2.34,4]],"ltp":0.0,"tv":0.0,"id":2219}]}]}
{"op":"mcm","clk":"11805940255","pt":1722701322203,"mc":[{"id":"1.231344137","rc":[{"batb":[[0,1.81,468.53],[1,1.75,53.85],[2,1.48,10]],"ltp":1.8,"tv":20217.09,"id":2120}]}]}
{"op":"mcm","clk":"11805940379","pt":1722701322894,"mc":[{"id":"1.231344137","rc":[{"batb":[[0,2.22,33.1]],"ltp":0.0,"tv":0.0,"id":2219}]}]}
{"op":"mcm","clk":"11805940988","pt":1722701326274,"mc":[{"id":"1.231344137","rc":[{"trd":[[1.81,945.06]],"batb":[[0,1.75,53.85],[1,1.48,10],[2,1.41,85.28]],"ltp":1.81,"tv":21154.15,"id":2120}],"tv":21154.15}]}
{"op":"mcm","clk":"11805941283","pt":1722701327986,"mc":[{"id":"1.231344137","rc":[{"batb":[[0,1.8,6.31],[1,1.75,53.85],[2,1.48,10]],"ltp":1.81,"tv":21154.15,"id":2120}]}]}
{"op":"mcm","clk":"11805941552","pt":1722701329480,"mc":[{"id":"1.231344137","rc":[{"trd":[[2.22,14.79]],"batb":[[0,2.24,10],[1,2.22,18.31],[2,1.83,18.04]],"ltp":2.22,"tv":14.79,"id":2219},{"trd":[[1.82,18.04]],"ltp":1.82,"tv":21172.19,"id":2120}],"tv":21186.98}]}
{"op":"mcm","clk":"11805941742","pt":1722701330584,"mc":[{"id":"1.231344137","rc":[{"batb":[[1,1.83,18.04],[2,1.82,7]],"ltp":2.22,"tv":14.79,"id":2219},{"batb":[[1,1.48,10],[2,1.41,85.28]],"ltp":1.82,"tv":21172.19,"id":2120}]}]}
{"op":"mcm","clk":"11805942174","pt":1722701333004,"mc":[{"id":"1.231344137","rc":[{"batb":[[0,1.83,18.04],[1,1.82,7],[2,1.41,85.28]],"ltp":2.22,"tv":14.79,"id":2219}]}]}
{"op":"mcm","clk":"11805942615","pt":1722701335511,"mc":[{"id":"1.231344137","rc":[{"batb":[[0,2.22,33.1],[1,1.83,18.04],[2,1.82,7]],"ltp":2.22,"tv":14.79,"id":2219},{"batb":[[1,1.75,53.85],[2,1.48,10]],"ltp":1.82,"tv":21172.19,"id":2120}]}]}
{"op":"mcm","clk":"11805942825","pt":1722701336685,"mc":[{"id":"1.231344137","rc":[{"batb":[[0,1.81,468.53],[1,1.8,6.31],[2,1.75,53.85]],"ltp":1.82,"tv":21172.19,"id":2120}]}]}
{"op":"mcm","clk":"11805943750","pt":1722701341705,"mc":[{"id":"1.231344137","rc":[{"trd":[[1.81,1882.12]],"batb":[[0,1.8,6.31],[1,1.75,53.85],[2,1.48,10]],"ltp":1.81,"tv":22109.25,"id":2120}],"tv":22124.04}]}
{"op":"mcm","clk":"11805945043","pt":1722701349115,"mc":[{"id":"1.231344137","rc":[{"batb":[[0,2.24,4],[1,2.22,37.1],[2,1.83,18.04]],"ltp":2.22,"tv":14.79,"id":2219},{"batl":[[0,1.81,4],[1,1.82,4]],"ltp":1.81,"tv":22109.25,"id":2120}]}]}
{"op":"mcm","clk":"11805945253","pt":1722701350334,"mc":[{"id":"1.231344137","rc":[{"trd":[[2.24,4]],"batb":[[0,2.22,37.1],[1,1.83,18.04],[2,1.82,7]],"ltp":2.24,"tv":18.79,"id":2219},{"trd":[[1.81,1895.07]],"batb":[[0,1.81,459.58],[1,1.8,6.31],[2,1.75,53.85]],"batl":[[0,1.82,4],[1,1.82,0]],"ltp":1.81,"tv":22122.2,"id":2120}],"tv":22140.99}]}
{"op":"mcm","clk":"11805945355","pt":1722701350927,"mc":[{"id":"1.231344137","rc":[{"batb":[[0,2.22,33.1]],"ltp":2.24,"tv":18.79,"id":2219},{"batl":[[0,1.94,2.71]],"ltp":1.81,"tv":22122.2,"id":2120}]}]}
{"op":"mcm","clk":"11805946363","pt":1722701356645,"mc":[{"id":"1.231344137","rc":[{"trd":[[1.8,14599.35],[1.81,2814.23]],"batb":[[0,1.75,53.85],[1,1.48,10],[2,1.41,85.28]],"batl":[[0,1.8,2.64],[1,1.94,2.71]],"ltp":1.8,"tv":23053.98,"id":2120}],"tv":23072.77}]}
{"op":"mcm","clk":"11805947609","pt":1722701364219,"mc":[{"id":"1.231344137","rc":[{"batb":[[0,2.24,4],[1,2.22,33.1],[2,1.83,18.04]],"batl":[[0,2.32,4],[1,2.34,4]],"ltp":2.24,"tv":18.79,"id":2219},{"batb":[[0,1.76,4],[1,1.75,57.85],[2,1.48,10]],"batl":[[0,1.94,2.71],[1,1.94,0]],"ltp":1.8,"tv":23053.98,"id":2120}]}]}
{"op":"mcm","clk":"11805950528","pt":1722701379478,"mc":[{"id":"1.231344137","rc":[{"batl":[[0,1.81,4],[1,1.94,2.71]],"ltp":1.8,"tv":23053.98,"id":2120}]}]}
{"op":"mcm","clk":"11805951627","pt":1722701385542,"mc":[{"id":"1.231344137","rc":[{"batb":[[0,2.24,10]],"ltp":2.24,"tv":18.79,"id":2219},{"batb":[[0,1.8,468.53],[1,1.76,4],[2,1.75,57.85]],"batl":[[0,1.94,2.71],[1,1.94,0]],"ltp":1.8,"tv":23053.98,"id":2120}]}]}
{"op":"mcm","clk":"11805952236","pt":1722701388957,"mc":[{"id":"1.231344137","rc":[{"batb":[[0,2.22,33.1],[1,1.83,18.04],[2,1.82,7]],"ltp":2.24,"tv":18.79,"id":2219}]}]}
{"op":"mcm","clk":"11805952424","pt":1722701389927,"mc":[{"id":"1.231344137","rc":[{"trd":[[1.8,15536.41]],"batb":[[0,1.76,4],[1,1.75,57.85],[2,1.48,10]],"ltp":1.8,"tv":23991.04,"id":2120}],"tv":24009.83}]}
{"op":"mcm","clk":"11805953242","pt":1722701394759,"mc":[{"id":"1.231344137","rc":[{"batb":[[0,2.24,10],[1,2.22,37.1],[2,1.83,18.04]],"ltp":2.24,"tv":18.79,"id":2219},{"batl":[[0,1.82,4],[1,1.94,2.71]],"ltp":1.8,"tv":23991.04,"id":2120}]}]}
{"op":"mcm","clk":"11805953857","pt":1722701398430,"mc":[{"id":"1.231344137","rc":[{"batb":[[0,2.22,37.1],[1,1.83,18.04],[2,1.82,7]],"ltp":2.24,"tv":18.79,"id":2219},{"batb":[[0,1.8,468.53],[1,1.76,4],[2,1.75,57.85]],"ltp":1.8,"tv":23991.04,"id":2120}]}]}
{"op":"mcm","clk":"11805953939","pt":1722701398963,"mc":[{"id":"1.231344137","rc":[{"batb":[[0,2.22,33.1]],"ltp":2.24,"tv":18.79,"id":2219},{"batl":[[0,1.94,2.71],[1,1.94,0]],"ltp":1.8,"tv":23991.04,"id":2120}]}]}
{"op":"mcm","clk":"11805954590","pt":1722701402655,"mc":[{"id":"1.231344137","rc":[{"trd":[[1.8,16473.47]],"batb":[[0,1.76,4],[1,1.75,57.85],[2,1.48,10]],"ltp":1.8,"tv":24928.1,"id":2120}],"tv":24946.89}]}
{"op":"mcm","clk":"11805954648","pt":1722701402977,"mc":[{"id":"1.231344137","rc":[{"batb":[[0,2.24,10],[1,2.22,33.1],[2,1.83,18.04]],"ltp":2.24,"tv":18.79,"id":2219}]}]}
{"op":"mcm","clk":"11805954818","pt":1722701403836,"mc":[{"id":"1.231344137","rc":[{"batb":[[0,1.77,9.02],[1,1.76,4],[2,1.75,57.85]],"ltp":1.8,"tv":24928.1,"id":2120}]}]}
{"op":"mcm","clk":"11805955304","pt":1722701406355,"mc":[{"id":"1.231344137","rc":[{"batb":[[0,2.22,33.1],[1,1.83,18.04],[2,1.82,7]],"ltp":2.24,"tv":18.79,"id":2219}]}]}
{"op":"mcm","clk":"11805955924","pt":1722701409776,"mc":[{"id":"1.231344137","rc":[{"batb":[[0,1.77,13.02]],"ltp":1.8,"tv":24928.1,"id":2120}]}]}
{"op":"mcm","clk":"11805955961","pt":1722701409985,"mc":[{"id":"1.231344137","rc":[{"batb":[[0,2.24,10],[1,2.22,37.1],[2,1.83,18.04]],"ltp":2.24,"tv":18.79,"id":2219},{"batl":[[0,1.82,4],[1,1.94,2.71]],"ltp":1.8,"tv":24928.1,"id":2120}]}]}
{"op":"mcm","clk":"11805956560","pt":1722701413158,"mc":[{"id":"1.231344137","rc":[{"batb":[[0,2.22,37.1],[1,1.83,18.04],[2,1.82,7]],"ltp":2.24,"tv":18.79,"id":2219}]}]}
{"op":"mcm","clk":"11805956776","pt":1722701414489,"mc":[{"id":"1.231344137","rc":[{"trd":[[1.77,26.04]],"batb":[[0,1.76,4],[1,1.75,57.85],[2,1.48,10]],"batl":[[0,1.77,455.51],[1,1.82,4],[2,1.94,2.71]],"ltp":1.77,"tv":24954.14,"id":2120}],"tv":24972.93}]}
{"op":"mcm","clk":"11805956898","pt":1722701415180,"mc":[{"id":"1.231344137","rc":[{"batb":[[0,1.75,53.85],[1,1.48,10],[2,1.41,85.28]],"ltp":1.77,"tv":24954.14,"id":2120}]}]}
{"op":"mcm","clk":"11805957142","pt":1722701416460,"mc":[{"id":"1.231344137","rc":[{"trd":[[1.77,937.06]],"batb":[[0,1.8,13.02],[1,1.75,53.85],[2,1.48,10]],"batl":[[0,1.82,4],[1,1.94,2.71],[2,1.94,0]],"ltp":1.77,"tv":25865.16,"id":2120}],"tv":25883.95}]}
{"op":"mcm","clk":"11805958463","pt":1722701423584,"mc":[{"id":"1.231344137","rc":[{"batb":[[0,1.75,53.85],[1,1.48,10],[2,1.41,85.28]],"ltp":1.77,"tv":25865.16,"id":2120}]}]}
{"op":"mcm","clk":"11805958733","pt":1722701425069,"mc":[{"id":"1.231344137","rc":[{"batb":[[0,2.24,10],[1,2.22,37.1],[2,1.83,18.04]],"batl":[[0,2.32,4],[1,2.34,4]],"ltp":2.24,"tv":18.79,"id":2219}]}]}
{"op":"mcm","clk":"11805959327","pt":1722701428395,"mc":[{"id":"1.231344137","rc":[{"batb":[[0,2.22,37.1],[1,1.83,18.04],[2,1.82,7]],"ltp":2.24,"tv":18.79,"id":2219}]}]}
{"op":"mcm","clk":"11805961356","pt":1722701439789,"mc":[{"id":"1.231344137","rc":[{"batb":[[0,2.24,10],[1,2.22,37.1],[2,1.83,18.04]],"ltp":2.24,"tv":18.79,"id":2219},{"batl":[[0,1.81,9.02],[1,1.82,4],[2,1.94,2.71]],"ltp":1.77,"tv":25865.16,"id":2120}]}]}
{"op":"mcm","clk":"11805961962","pt":1722701443305,"mc":[{"id":"1.231344137","rc":[{"batb":[[0,2.22,37.1],[1,1.83,18.04],[2,1.82,7]],"ltp":2.24,"tv":18.79,"id":2219}]}]}
{"op":"mcm","clk":"11805962733","pt":1722701447681,"mc":[{"id":"1.231344137","rc":[{"batb":[[0,2.24,10],[1,2.22,37.1],[2,1.83,18.04]],"ltp":2.24,"tv":18.79,"id":2219},{"batb":[[0,1.8,468.53],[1,1.75,53.85],[2,1.48,10]],"ltp":1.77,"tv":25865.16,"id":2120}]}]}
{"op":"mcm","clk":"11805962831","pt":1722701448315,"mc":[{"id":"1.231344137","rc":[{"batb":[[1,2.22,33.1]],"ltp":2.24,"tv":18.79,"id":2219},{"batl":[[1,1.94,2.71],[2,1.94,0]],"ltp":1.77,"tv":25865.16,"id":2120}]}]}
{"op":"mcm","clk":"11805963261","pt":1722701450960,"mc":[{"id":"1.231344137","rc":[{"batb":[[0,1.83,18.04],[1,1.82,7],[2,1.41,85.28]],"ltp":2.24,"tv":18.79,"id":2219},{"batb":[[1,1.48,10],[2,1.41,85.28]],"ltp":1.77,"tv":25865.16,"id":2120}]}]}
{"op":"mcm","clk":"11805964101","pt":1722701455441,"mc":[{"id":"1.231344137","rc":[{"batb":[[0,1.84,10],[1,1.83,18.04],[2,1.82,7]],"batl":[[0,2.24,4],[1,2.26,4],[2,2.32,4]],"ltp":2.24,"tv":18.79,"id":2219},{"batb":[[0,1.8,472.53]],"ltp":1.77,"tv":25865.16,"id":2120}]}]}
{"op":"mcm","clk":"11805964194","pt":1722701455918,"mc":[{"id":"1.231344137","rc":[{"batb":[[0,2.22,33.1],[1,1.84,10],[2,1.83,18.04]],"ltp":2.24,"tv":18.79,"id":2219},{"batb":[[1,1.75,53.85],[2,1.48,10]],"ltp":1.77,"tv":25865.16,"id":2120}]}]}
{"op":"mcm","clk":"11805964786","pt":1722701458594,"mc":[{"id":"1.231344137","rc":[{"batb":[[1,1.83,18.04],[2,1.82,7]],"ltp":2.24,"tv":18.79,"id":2219}]}]}
{"op":"mcm","clk":"11805965760","pt":1722701463929,"mc":[{"id":"1.231344137","rc":[{"trd":[[1.8,17254.35]],"batb":[[0,1.8,82.09]],"ltp":1.8,"tv":26646.05,"id":2120}],"tv":26664.84}]}
{"op":"mcm","clk":"11805966940","pt":1722701470301,"mc":[{"id":"1.231344137","rc":[{"batb":[[0,2.22,37.1]],"ltp":2.24,"tv":18.79,"id":2219}]}]}
{"op":"mcm","clk":"11805968980","pt":1722701481527,"mc":[{"id":"1.231344137","rc":[{"trd":[[1.8,17394.91]],"batb":[[0,1.8,11.81]],"ltp":1.8,"tv":26786.61,"id":2120}],"tv":26805.4}]}
{"op":"mcm","clk":"11805971967","pt":1722701498820,"mc":[{"id":"1.231344137","rc":[{"batb":[[0,1.75,53.85],[1,1.48,10],[2,1.41,85.28]],"ltp":1.8,"tv":26786.61,"id":2120}]}]}
{"op":"mcm","clk":"11805972296","pt":1722701500676,"mc":[{"id":"1.231344137","rc":[{"batb":[[0,2.24,10],[1,2.22,37.1],[2,1.83,18.04]],"batl":[[0,2.34,4]],"ltp":2.24,"tv":18.79,"id":2219},{"batb":[[0,1.75,57.85]],"batl":[[0,1.81,13.02]],"ltp":1.8,"tv":26786.61,"id":2120}]}]}
{"op":"mcm","clk":"11805972843","pt":1722701503882,"mc":[{"id":"1.231344137","rc":[{"batb":[[0,2.22,37.1],[1,1.83,18.04],[2,1.82,7]],"ltp":2.24,"tv":18.79,"id":2219}]}]}
{"op":"mcm","clk":"11805973476","pt":1722701507469,"mc":[{"id":"1.231344137","rc":[{"batb":[[0,2.24,10],[1,2.22,33.1],[2,1.83,18.04]],"ltp":2.24,"tv":18.79,"id":2219},{"batb":[[0,1.8,468.53],[1,1.75,57.85],[2,1.48,10]],"batl":[[0,1.81,9.02]],"ltp":1.8,"tv":26786.61,"id":2120}]}]}
{"op":"mcm","clk":"11805974006","pt":1722701510471,"mc":[{"id":"1.231344137","rc":[{"batb":[[0,2.22,33.1],[1,1.83,18.04],[2,1.82,7]],"ltp":2.24,"tv":18.79,"id":2219}]}]}
{"op":"mcm","clk":"11805974484","pt":1722701513277,"mc":[{"id":"1.231344137","rc":[{"batb":[[0,2.24,10],[1,2.22,33.1],[2,1.83,18.04]],"ltp":2.24,"tv":18.79,"id":2219},{"trd":[[1.8,18331.97]],"batb":[[0,1.75,57.85],[1,1.48,10],[2,1.41,85.28]],"ltp":1.8,"tv":27723.67,"id":2120}],"tv":27742.46}]}
{"op":"mcm","clk":"11805974942","pt":1722701515687,"mc":[{"id":"1.231344137","rc":[{"batb":[[0,2.24,14]],"batl":[[0,2.32,4],[1,2.34,4]],"ltp":2.24,"tv":18.79,"id":2219},{"batl":[[0,1.81,13.02]],"ltp":1.8,"tv":27723.67,"id":2120}]}]}
{"op":"mcm","clk":"11805975142","pt":1722701516790,"mc":[{"id":"1.231344137","rc":[{"batb":[[0,2.24,4]],"ltp":2.24,"tv":18.79,"id":2219}]}]}
{"op":"mcm","clk":"11805976141","pt":1722701522301,"mc":[{"id":"1.231344137","rc":[{"batb":[[0,1.75,58.75]],"ltp":1.8,"tv":27723.67,"id":2120}]}]}
{"op":"mcm","clk":"11805976757","pt":1722701525485,"mc":[{"id":"1.231344137","rc":[{"batb":[[0,2.24,10]],"ltp":2.24,"tv":18.79,"id":2219},{"batb":[[0,1.8,469.43],[1,1.75,57.85],[2,1.48,10]],"batl":[[0,1.81,9.02]],"ltp":1.8,"tv":27723.67,"id":2120}]}]}
{"op":"mcm","clk":"11805976922","pt":1722701526303,"mc":[{"id":"1.231344137","rc":[{"batb":[[1,1.83,18.04],[2,1.82,7]],"ltp":2.24,"tv":18.79,"id":2219},{"batb":[[1,1.75,4]],"ltp":1.8,"tv":27723.67,"id":2120}]}]}
{"op":"mcm","clk":"11805977432","pt":1722701529009,"mc":[{"id":"1.231344137","rc":[{"batb":[[0,1.83,18.04],[1,1.82,7],[2,1.41,85.28]],"ltp":2.24,"tv":18.79,"id":2219}]}]}
{"op":"mcm","clk":"11805977882","pt":1722701531203,"mc":[{"id":"1.231344137","rc":[{"batb":[[0,2.22,33.1],[1,1.83,18.04],[2,1.82,7]],"batl":[[0,2.24,4],[1,2.26,4],[2,2.32,4]],"ltp":2.24,"tv":18.79,"id":2219},{"batb":[[0,1.8,473.43],[1,1.75,57.85]],"ltp":1.8,"tv":27723.67,"id":2120}]}]}
{"op":"mcm","clk":"11805979487","pt":1722701540420,"mc":[{"id":"1.231344137","rc":[{"trd":[[1.8,19269.04]],"batb":[[0,1.8,4.9]],"ltp":1.8,"tv":28660.73,"id":2120}],"tv":28679.52}]}
{"op":"mcm","clk":"11805979639","pt":1722701541229,"mc":[{"id":"1.231344137","rc":[{"batb":[[0,1.75,58.75],[1,1.48,10],[2,1.41,85.28]],"ltp":1.8,"tv":28660.73,"id":2120}]}]}
{"op":"mcm","clk":"11805980548","pt":1722701546219,"mc":[{"id":"1.231344137","rc":[{"batb":[[0,2.24,10],[1,2.22,37.1],[2,1.83,18.04]],"batl":[[0,2.32,4],[1,2.34,4]],"ltp":2.24,"tv":18.79,"id":2219},{"batl":[[0,1.81,13.02]],"ltp":1.8,"tv":28660.73,"id":2120}]}]}
{"op":"mcm","clk":"11805981216","pt":1722701549998,"mc":[{"id":"1.231344137","rc":[{"batb":[[0,2.22,37.1],[1,1.83,18.04],[2,1.82,7]],"ltp":2.24,"tv":18.79,"id":2219}]}]}
{"op":"mcm","clk":"11805982591","pt":1722701557750,"mc":[{"id":"1.231344137","rc":[{"batb":[[0,1.75,57.85]],"ltp":1.8,"tv":28660.73,"id":2120}]}]}
{"op":"mcm","clk":"11805982617","pt":1722701557903,"mc":[{"id":"1.231344137","rc":[{"batb":[[0,2.24,10],[1,2.22,37.1],[2,1.83,18.04]],"ltp":2.24,"tv":18.79,"id":2219}]}]}
{"op":"mcm","clk":"11805983208","pt":1722701561300,"mc":[{"id":"1.231344137","rc":[{"batb":[[0,2.24,4]],"ltp":2.24,"tv":18.79,"id":2219}]}]}
{"op":"mcm","clk":"11805987346","pt":1722701585545,"mc":[{"id":"1.231344137","rc":[{"batb":[[0,2.24,10],[1,2.22,33.1]],"ltp":2.24,"tv":18.79,"id":2219},{"batb":[[0,1.8,468.53],[1,1.75,57.85],[2,1.48,10]],"batl":[[0,1.81,9.02]],"ltp":1.8,"tv":28660.73,"id":2120}]}]}
{"op":"mcm","clk":"11805987494","pt":1722701586360,"mc":[{"id":"1.231344137","rc":[{"batb":[[1,1.83,18.04],[2,1.82,7]],"ltp":2.24,"tv":18.79,"id":2219},{"batb":[[1,1.75,4]],"ltp":1.8,"tv":28660.73,"id":2120}]}]}
{"op":"mcm","clk":"11805987943","pt":1722701588723,"mc":[{"id":"1.231344137","rc":[{"batb":[[0,1.83,18.04],[1,1.82,7],[2,1.41,85.28]],"ltp":2.24,"tv":18.79,"id":2219}]}]}
{"op":"mcm","clk":"11805988409","pt":1722701591458,"mc":[{"id":"1.231344137","rc":[{"trd":[[2.24,12]],"batb":[[0,2.24,6],[1,2.22,33.1],[2,1.83,18.04]],"batl":[[0,2.26,4],[1,2.32,4],[2,2.34,4]],"ltp":2.24,"tv":26.79,"id":2219},{"batb":[[0,1.8,472.53],[1,1.75,57.85]],"ltp":1.8,"tv":28660.73,"id":2120}],"tv":28687.52}]}
{"op":"mcm","clk":"11805988613","pt":1722701592671,"mc":[{"id":"1.231344137","rc":[{"trd":[[1.8,20206.1]],"batb":[[0,1.8,4]],"ltp":1.8,"tv":29597.79,"id":2120}],"tv":29624.58}]}
{"op":"mcm","clk":"11805988696","pt":1722701593149,"mc":[{"id":"1.231344137","rc":[{"batl":[[0,2.32,4],[1,2.34,4],[2,2.34,0]],"ltp":2.24,"tv":26.79,"id":2219},{"batb":[[0,1.75,57.85],[1,1.48,10],[2,1.41,85.28]],"ltp":1.8,"tv":29597.79,"id":2120}]}]}
{"op":"mcm","clk":"11805988951","pt":1722701594638,"mc":[{"id":"1.231344137","rc":[{"batb":[[0,2.22,33.1],[1,1.83,18.04],[2,1.82,7]],"ltp":2.24,"tv":26.79,"id":2219}]}]}
{"op":"mcm","clk":"11805990163","pt":1722701601451,"mc":[{"id":"1.231344137","rc":[{"batb":[[0,2.24,10]],"ltp":2.24,"tv":26.79,"id":2219},{"batb":[[0,1.8,468.53],[1,1.75,4],[2,1.48,10]],"ltp":1.8,"tv":29597.79,"id":2120}]}]}
{"op":"mcm","clk":"11805990779","pt":1722701604567,"mc":[{"id":"1.231344137","rc":[{"batb":[[0,1.83,18.04],[1,1.82,7],[2,1.41,85.28]],"ltp":2.24,"tv":26.79,"id":2219}]}]}
{"op":"mcm","clk":"11805990911","pt":1722701605261,"mc":[{"id":"1.231344137","rc":[{"trd":[[1.8,21143.16]],"batb":[[0,1.75,4],[1,1.48,10],[2,1.41,85.28]],"ltp":1.8,"tv":30534.85,"id":2120}],"tv":30561.64}]}
{"op":"mcm","clk":"11805991141","pt":1722701606489,"mc":[{"id":"1.231344137","rc":[{"batb":[[0,2.22,33.1],[1,1.83,18.04],[2,1.82,7]],"ltp":2.24,"tv":26.79,"id":2219},{"batb":[[0,1.75,53.85]],"ltp":1.8,"tv":30534.85,"id":2120}]}]}
{"op":"mcm","clk":"11805994003","pt":1722701621669,"mc":[{"id":"1.231344137","rc":[{"batb":[[0,2.24,4],[1,2.22,37.1],[2,1.83,18.04]],"batl":[[0,2.34,4]],"ltp":2.24,"tv":26.79,"id":2219},{"batb":[[0,1.75,57.85]],"batl":[[0,1.81,13.02]],"ltp":1.8,"tv":30534.85,"id":2120}]}]}
{"op":"mcm","clk":"11805994042","pt":1722701621878,"mc":[{"id":"1.231344137","rc":[{"batb":[[0,2.26,10],[1,2.24,4],[2,2.22,37.1]],"ltp":2.24,"tv":26.79,"id":2219}]}]}
{"op":"mcm","clk":"11805994689","pt":1722701625187,"mc":[{"id":"1.231344137","rc":[{"batb":[[0,2.24,4],[1,2.22,37.1],[2,1.83,18.04]],"ltp":2.24,"tv":26.79,"id":2219}]}]}
{"op":"mcm","clk":"11805996751","pt":1722701636512,"mc":[{"id":"1.231344137","rc":[{"trd":[[2.26,10]],"batb":[[1,2.22,4]],"ltp":2.26,"tv":36.79,"id":2219},{"trd":[[1.8,21155.71]],"batb":[[0,1.8,455.97],[1,1.75,4],[2,1.48,10]],"ltp":1.8,"tv":30547.41,"id":2120}],"tv":30584.2}]}
{"op":"mcm","clk":"11805996824","pt":1722701636902,"mc":[{"id":"1.231344137","rc":[{"batb":[[0,1.83,18.04],[1,1.82,7],[2,1.41,85.28]],"batl":[[0,2.26,4],[1,2.34,4]],"ltp":2.26,"tv":36.79,"id":2219},{"batb":[[0,1.8,459.97]],"batl":[[0,1.81,9.02]],"ltp":1.8,"tv":30547.41,"id":2120}]}]}
{"op":"mcm","clk":"11805997446","pt":1722701640814,"mc":[{"id":"1.231344137","rc":[{"trd":[[2.26,14]],"batl":[[0,2.34,4],[1,2.34,0]],"ltp":2.26,"tv":40.79,"id":2219},{"trd":[[1.75,7.02],[1.79,5627.42],[1.8,22075.66]],"batb":[[0,1.48,10.49],[1,1.41,85.28],[2,1.3,633.33]],"ltp":1.75,"tv":31479.42,"id":2120}],"tv":31520.21}]}
{"op":"mcm","clk":"11805997541","pt":1722701641526,"mc":[{"id":"1.231344137","rc":[{"batb":[[0,2.22,33.1],[1,1.84,10],[2,1.83,18.04]],"ltp":2.26,"tv":40.79,"id":2219},{"batb":[[0,1.75,53.85],[1,1.48,10],[2,1.41,85.28]],"ltp":1.75,"tv":31479.42,"id":2120}]}]}
{"op":"mcm","clk":"11805998015","pt":1722701644233,"mc":[{"id":"1.231344137","rc":[{"batb":[[1,1.83,18.04],[2,1.82,7]],"ltp":2.26,"tv":40.79,"id":2219}]}]}
{"op":"mcm","clk":"11805999484","pt":1722701652242,"mc":[{"id":"1.231344137","rc":[{"batb":[[0,2.26,10],[1,2.24,4],[2,2.22,37.1]],"batl":[[0,2.34,4]],"ltp":2.26,"tv":40.79,"id":2219},{"batb":[[0,1.75,57.85]],"batl":[[0,1.81,13.02]],"ltp":1.75,"tv":31479.42,"id":2120}]}]}
{"op":"mcm","clk":"11806000150","pt":1722701655530,"mc":[{"id":"1.231344137","rc":[{"batb":[[0,2.24,4],[1,2.22,37.1],[2,1.83,18.04]],"ltp":2.26,"tv":40.79,"id":2219}]}]}
{"op":"mcm","clk":"11806001081","pt":1722701660734,"mc":[{"id":"1.231344137","rc":[{"batl":[[1,1.94,0]],"ltp":1.75,"tv":31479.42,"id":2120}]}]}
{"op":"mcm","clk":"11806001123","pt":1722701660973,"mc":[{"id":"1.231344137","rc":[{"batb":[[0,2.26,10],[1,2.24,4],[2,2.22,37.1]],"ltp":2.26,"tv":40.79,"id":2219}]}]}
{"op":"mcm","clk":"11806001770","pt":1722701664353,"mc":[{"id":"1.231344137","rc":[{"batb":[[0,2.24,4],[1,2.22,37.1],[2,1.83,18.04]],"ltp":2.26,"tv":40.79,"id":2219}]}]}
{"op":"mcm","clk":"11806005618","pt":1722701685480,"mc":[{"id":"1.231344137","rc":[{"batb":[[0,2.26,10],[1,2.24,4],[2,2.22,37.1]],"ltp":2.26,"tv":40.79,"id":2219},{"batb":[[0,1.79,468.53],[1,1.75,57.85],[2,1.48,10]],"ltp":1.75,"tv":31479.42,"id":2120}]}]}
{"op":"mcm","clk":"11806005712","pt":1722701686044,"mc":[{"id":"1.231344137","rc":[{"batb":[[1,2.22,33.1],[2,1.83,18.04]],"ltp":2.26,"tv":40.79,"id":2219},{"batl":[[0,1.81,9.02]],"ltp":1.75,"tv":31479.42,"id":2120}]}]}
{"op":"mcm","clk":"11806005866","pt":1722701686947,"mc":[{"id":"1.231344137","rc":[{"batb":[[1,1.83,18.04],[2,1.82,7]],"ltp":2.26,"tv":40.79,"id":2219},{"batb":[[1,1.75,4]],"ltp":1.75,"tv":31479.42,"id":2120}]}]}
{"op":"mcm","clk":"11806006208","pt":1722701688753,"mc":[{"id":"1.231344137","rc":[{"batb":[[0,1.83,18.04],[1,1.82,7],[2,1.41,85.28]],"ltp":2.26,"tv":40.79,"id":2219}]}]}
{"op":"mcm","clk":"11806006523","pt":1722701690549,"mc":[{"id":"1.231344137","rc":[{"trd":[[1.79,6564.48]],"batb":[[0,1.75,4],[1,1.48,10],[2,1.41,85.28]],"ltp":1.79,"tv":32416.48,"id":2120}],"tv":32457.27}]}
{"op":"mcm","clk":"11806006583","pt":1722701690974,"mc":[{"id":"1.231344137","rc":[{"batb":[[0,1.48,10],[1,1.41,85.28],[2,1.3,633.33]],"ltp":1.79,"tv":32416.48,"id":2120}]}]}
{"op":"mcm","clk":"11806006757","pt":1722701691879,"mc":[{"id":"1.231344137","rc":[{"batb":[[0,2.22,33.1],[1,1.83,18.04],[2,1.82,7]],"ltp":2.26,"tv":40.79,"id":2219},{"batb":[[0,1.75,53.85],[1,1.48,10],[2,1.41,85.28]],"ltp":1.79,"tv":32416.48,"id":2120}]}]}
{"op":"mcm","clk":"11806007780","pt":1722701697560,"mc":[{"id":"1.231344137","rc":[{"batb":[[0,2.26,10],[1,2.24,4],[2,2.22,37.1]],"batl":[[0,2.34,4]],"ltp":2.26,"tv":40.79,"id":2219},{"batb":[[0,1.75,57.85]],"batl":[[0,1.81,13.02]],"ltp":1.79,"tv":32416.48,"id":2120}]}]}
{"op":"mcm","clk":"11806007960","pt":1722701698570,"mc":[{"id":"1.231344137","rc":[{"batb":[[0,1.79,468.53],[1,1.75,57.85],[2,1.48,10]],"ltp":1.79,"tv":32416.48,"id":2120}]}]}
{"op":"mcm","clk":"11806008047","pt":1722701699062,"mc":[{"id":"1.231344137","rc":[{"batb":[[1,2.22,33.1],[2,1.83,18.04]],"ltp":2.26,"tv":40.79,"id":2219},{"batl":[[0,1.81,9.02]],"ltp":1.79,"tv":32416.48,"id":2120}]}]}
{"op":"mcm","clk":"11806008404","pt":1722701700884,"mc":[{"id":"1.231344137","rc":[{"batb":[[0,2.22,33.1],[1,1.83,18.04],[2,1.82,7]],"ltp":2.26,"tv":40.79,"id":2219}]}]}
{"op":"mcm","clk":"11806008913","pt":1722701703662,"mc":[{"id":"1.231344137","rc":[{"batb":[[0,2.24,10],[1,2.22,33.1],[2,1.83,18.04]],"ltp":2.26,"tv":40.79,"id":2219},{"trd":[[1.79,7501.54]],"batb":[[0,1.75,57.85],[1,1.48,10],[2,1.41,85.28]],"ltp":1.79,"tv":33353.54,"id":2120}],"tv":33394.33}]}
{"op":"mcm","clk":"11806009548","pt":1722701707076,"mc":[{"id":"1.231344137","rc":[{"batb":[[0,2.22,33.1],[1,1.83,18.04],[2,1.82,7]],"ltp":2.26,"tv":40.79,"id":2219}]}]}
{"op":"mcm","clk":"11806010573","pt":1722701712604,"mc":[{"id":"1.231344137","rc":[{"batb":[[0,2.22,37.1]],"ltp":2.26,"tv":40.79,"id":2219},{"batl":[[0,1.81,13.02]],"ltp":1.79,"tv":33353.54,"id":2120}]}]}
{"op":"mcm","clk":"11806010617","pt":1722701712844,"mc":[{"id":"1.231344137","rc":[{"batb":[[0,2.24,10],[1,2.22,37.1],[2,1.83,18.04]],"ltp":2.26,"tv":40.79,"id":2219}]}]}
{"op":"mcm","clk":"11806010920","pt":1722701714410,"mc":[{"id":"1.231344137","rc":[{"batb":[[1,2.22,33.1]],"ltp":2.26,"tv":40.79,"id":2219},{"batb":[[0,1.79,468.53],[1,1.75,57.85],[2,1.48,10]],"batl":[[0,1.81,9.02]],"ltp":1.79,"tv":33353.54,"id":2120}]}]}
{"op":"mcm","clk":"11806011256","pt":1722701716009,"mc":[{"id":"1.231344137","rc":[{"batb":[[0,2.22,33.1],[1,1.83,18.04],[2,1.82,7]],"ltp":2.26,"tv":40.79,"id":2219}]}]}
{"op":"mcm","clk":"11806011994","pt":1722701720208,"mc":[{"id":"1.231344137","rc":[{"batb":[[0,2.24,10],[1,2.22,33.1],[2,1.83,18.04]],"ltp":2.26,"tv":40.79,"id":2219},{"trd":[[1.79,8438.6]],"batb":[[0,1.75,57.85],[1,1.48,10],[2,1.41,85.28]],"ltp":1.79,"tv":34290.6,"id":2120}],"tv":34331.39}]}
{"op":"mcm","clk":"11806012685","pt":1722701724017,"mc":[{"id":"1.231344137","rc":[{"batb":[[0,2.22,33.1],[1,1.83,18.04],[2,1.82,7]],"ltp":2.26,"tv":40.79,"id":2219}]}]}
{"op":"mcm","clk":"11806013339","pt":1722701727718,"mc":[{"id":"1.231344137","rc":[{"batb":[[0,2.22,37.1]],"ltp":2.26,"tv":40.79,"id":2219},{"batl":[[0,1.81,13.02]],"ltp":1.79,"tv":34290.6,"id":2120}]}]}
{"op":"mcm","clk":"11806013373","pt":1722701727885,"mc":[{"id":"1.231344137","rc":[{"batb":[[0,2.24,10],[1,2.22,37.1],[2,1.83,18.04]],"ltp":2.26,"tv":40.79,"id":2219}]}]}
{"op":"mcm","clk":"11806013955","pt":1722701731196,"mc":[{"id":"1.231344137","rc":[{"batb":[[0,2.22,37.1],[1,1.83,18.04],[2,1.82,7]],"ltp":2.26,"tv":40.79,"id":2219}]}]}
{"op":"mcm","clk":"11806016116","pt":1722701742813,"mc":[{"id":"1.231344137","rc":[{"batb":[[0,2.24,4],[1,2.22,37.1],[2,1.83,18.04]],"ltp":2.26,"tv":40.79,"id":2219}]}]}
{"op":"mcm","clk":"11806016136","pt":1722701742893,"mc":[{"id":"1.231344137","rc":[{"batb":[[0,2.26,10],[1,2.24,4],[2,2.22,37.1]],"ltp":2.26,"tv":40.79,"id":2219}]}]}
{"op":"mcm","clk":"11806016800","pt":1722701746351,"mc":[{"id":"1.231344137","rc":[{"batb":[[0,2.24,4],[1,2.22,37.1],[2,1.83,18.04]],"ltp":2.26,"tv":40.79,"id":2219}]}]}
{"op":"mcm","clk":"11806017347","pt":1722701749218,"mc":[{"id":"1.231344137","rc":[{"batb":[[0,2.26,10],[1,2.22,33.1]],"ltp":2.26,"tv":40.79,"id":2219},{"batb":[[0,1.79,468.53],[1,1.75,57.85],[2,1.48,10]],"batl":[[0,1.81,9.02]],"ltp":1.79,"tv":34290.6,"id":2120}]}]}
{"op":"mcm","clk":"11806017958","pt":1722701752309,"mc":[{"id":"1.231344137","rc":[{"batb":[[0,1.83,18.04],[1,1.82,7],[2,1.41,85.28]],"ltp":2.26,"tv":40.79,"id":2219},{"batb":[[1,1.75,4]],"ltp":1.79,"tv":34290.6,"id":2120}]}]}
{"op":"mcm","clk":"11806018103","pt":1722701753096,"mc":[{"id":"1.231344137","rc":[{"trd":[[1.79,9375.66]],"batb":[[0,1.75,4],[1,1.48,10],[2,1.41,85.28]],"ltp":1.79,"tv":35227.66,"id":2120}],"tv":35268.45}]}
{"op":"mcm","clk":"11806018232","pt":1722701753847,"mc":[{"id":"1.231344137","rc":[{"batb":[[0,1.48,10],[1,1.41,85.28],[2,1.3,633.33]],"ltp":1.79,"tv":35227.66,"id":2120}]}]}
{"op":"mcm","clk":"11806018917","pt":1722701757221,"mc":[{"id":"1.231344137","rc":[{"batb":[[0,2.22,33.1],[1,1.83,18.04],[2,1.82,7]],"ltp":2.26,"tv":40.79,"id":2219},{"batb":[[0,1.75,53.85],[1,1.48,10],[2,1.41,85.28]],"ltp":1.79,"tv":35227.66,"id":2120}]}]}
{"op":"mcm","clk":"11806019573","pt":1722701760686,"mc":[{"id":"1.231344137","rc":[{"batb":[[0,1.79,468.53],[1,1.75,53.85],[2,1.48,10]],"ltp":1.79,"tv":35227.66,"id":2120}]}]}
{"op":"mcm","clk":"11806020413","pt":1722701764622,"mc":[{"id":"1.231344137","rc":[{"trd":[[1.79,10312.72]],"batb":[[0,1.75,53.85],[1,1.48,10],[2,1.41,85.28]],"ltp":1.79,"tv":36164.73,"id":2120}],"tv":36205.52}]}
{"op":"mcm","clk":"11806021846","pt":1722701771435,"mc":[{"id":"1.231344137","rc":[{"batb":[[1,1.63,9.02],[2,1.48,10]],"ltp":1.79,"tv":36164.73,"id":2120}]}]}
{"op":"mcm","clk":"11806022160","pt":1722701773162,"mc":[{"id":"1.231344137","rc":[{"batb":[[0,2.26,10],[1,2.24,4],[2,2.22,37.1]],"batl":[[0,2.34,4]],"ltp":2.26,"tv":40.79,"id":2219},{"batb":[[0,1.75,57.85]],"batl":[[0,1.81,13.02]],"ltp":1.79,"tv":36164.73,"id":2120}]}]}
{"op":"mcm","clk":"11806022819","pt":1722701776464,"mc":[{"id":"1.231344137","rc":[{"batb":[[0,2.24,4],[1,2.22,37.1],[2,1.83,18.04]],"ltp":2.26,"tv":40.79,"id":2219}]}]}
{"op":"mcm","clk":"11806024246","pt":1722701783769,"mc":[{"id":"1.231344137","rc":[{"batb":[[0,1.79,468.53],[1,1.75,57.85],[2,1.63,9.02]],"ltp":1.79,"tv":36164.73,"id":2120}]}]}
{"op":"mcm","clk":"11806024316","pt":1722701784149,"mc":[{"id":"1.231344137","rc":[{"batb":[[0,2.26,10],[1,2.22,33.1]],"ltp":2.26,"tv":40.79,"id":2219},{"batl":[[0,1.81,9.02]],"ltp":1.79,"tv":36164.73,"id":2120}]}]}
{"op":"mcm","clk":"11806024961","pt":1722701787368,"mc":[{"id":"1.231344137","rc":[{"batb":[[0,1.83,18.04],[1,1.82,7],[2,1.41,85.28]],"ltp":2.26,"tv":40.79,"id":2219},{"batb":[[1,1.75,4]],"ltp":1.79,"tv":36164.73,"id":2120}]}]}
{"op":"mcm","clk":"11806025166","pt":1722701788256,"mc":[{"id":"1.231344137","rc":[{"batl":[[0,2.28,4],[1,2.34,4]],"ltp":2.26,"tv":40.79,"id":2219},{"batb":[[0,1.79,472.53]],"ltp":1.79,"tv":36164.73,"id":2120}]}]}
{"op":"mcm","clk":"11806025616","pt":1722701790491,"mc":[{"id":"1.231344137","rc":[{"batb":[[0,1.84,10],[1,1.83,18.04],[2,1.82,7]],"ltp":2.26,"tv":40.79,"id":2219},{"trd":[[1.79,11249.78]],"batb":[[0,1.79,4]],"ltp":1.79,"tv":37101.79,"id":2120}],"tv":37142.58}]}
{"op":"mcm","clk":"11806025693","pt":1722701790857,"mc":[{"id":"1.231344137","rc":[{"batb":[[0,1.63,9.02],[1,1.48,10],[2,1.41,85.28]],"ltp":1.79,"tv":37101.79,"id":2120}]}]}
{"op":"mcm","clk":"11806025985","pt":1722701792361,"mc":[{"id":"1.231344137","rc":[{"batb":[[0,2.22,33.1],[1,1.84,10],[2,1.83,18.04]],"ltp":2.26,"tv":40.79,"id":2219},{"batb":[[0,1.75,53.85],[1,1.63,9.02],[2,1.48,10]],"ltp":1.79,"tv":37101.79,"id":2120}]}]}
{"op":"mcm","clk":"11806026291","pt":1722701793854,"mc":[{"id":"1.231344137","rc":[{"batb":[[1,1.83,18.04],[2,1.82,7]],"ltp":2.26,"tv":40.79,"id":2219}]}]}
{"op":"mcm","clk":"11806027136","pt":1722701798171,"mc":[{"id":"1.231344137","rc":[{"batb":[[0,1.79,468.53],[1,1.75,53.85],[2,1.63,9.02]],"ltp":1.79,"tv":37101.79,"id":2120}]}]}
{"op":"mcm","clk":"11806027858","pt":1722701803716,"mc":[{"id":"1.231344137","rc":[{"trd":[[1.79,12186.84]],"batb":[[0,1.75,53.85],[1,1.63,9.02],[2,1.48,10]],"ltp":1.79,"tv":38038.85,"id":2120}],"tv":38079.64}]}
{"op":"mcm","clk":"11806028306","pt":1722701804416,"mc":[{"id":"1.231344137","rc":[{"batb":[[0,1.79,4],[1,1.75,53.85],[2,1.63,9.02]],"ltp":1.79,"tv":38038.85,"id":2120}]}]}
{"op":"mcm","clk":"11806028426","pt":1722701804881,"mc":[{"id":"1.231344137","rc":[{"batb":[[0,1.75,53.85],[1,1.63,9.02],[2,1.48,10]],"ltp":1.79,"tv":38038.85,"id":2120}]}]}
{"op":"mcm","clk":"11806029267","pt":1722701808883,"mc":[{"id":"1.231344137","rc":[{"batb":[[0,1.79,468.53],[1,1.75,53.85],[2,1.63,9.02]],"ltp":1.79,"tv":38038.85,"id":2120}]}]}
{"op":"mcm","clk":"11806030217","pt":1722701813208,"mc":[{"id":"1.231344137","rc":[{"trd":[[1.75,61.12],[1.79,13123.9]],"batb":[[0,1.75,26.8],[1,1.63,9.02],[2,1.48,10]],"ltp":1.75,"tv":39030.01,"id":2120}],"tv":39070.8}]}
{"op":"mcm","clk":"11806031021","pt":1722701817495,"mc":[{"id":"1.231344137","rc":[{"batb":[[0,1.75,53.85]],"ltp":1.75,"tv":39030.01,"id":2120}]}]}
{"op":"mcm","clk":"11806031255","pt":1722701818564,"mc":[{"id":"1.231344137","rc":[{"batb":[[0,2.24,10],[1,2.22,37.1],[2,1.83,18.04]],"batl":[[0,2.34,4]],"ltp":2.26,"tv":40.79,"id":2219}]}]}
{"op":"mcm","clk":"11806031821","pt":1722701821781,"mc":[{"id":"1.231344137","rc":[{"batb":[[0,2.22,37.1],[1,1.83,18.04],[2,1.82,7]],"ltp":2.26,"tv":40.79,"id":2219}]}]}
{"op":"mcm","clk":"11806031887","pt":1722701822102,"mc":[{"id":"1.231344137","rc":[{"batb":[[0,2.22,33.1]],"ltp":2.26,"tv":40.79,"id":2219},{"batb":[[0,1.79,468.53],[1,1.75,53.85],[2,1.63,9.02]],"ltp":1.75,"tv":39030.01,"id":2120}]}]}
{"op":"mcm","clk":"11806032143","pt":1722701823505,"mc":[{"id":"1.231344137","rc":[{"batb":[[1,1.76,18.04],[2,1.75,53.85]],"ltp":1.75,"tv":39030.01,"id":2120}]}]}
{"op":"mcm","clk":"11806032736","pt":1722701826208,"mc":[{"id":"1.231344137","rc":[{"batb":[[0,2.24,10],[1,2.22,33.1],[2,1.83,18.04]],"ltp":2.26,"tv":40.79,"id":2219},{"trd":[[1.79,14060.96]],"batb":[[0,1.76,18.04],[1,1.75,53.85],[2,1.63,9.02]],"ltp":1.79,"tv":39967.07,"id":2120}],"tv":40007.86}]}
{"op":"mcm","clk":"11806033444","pt":1722701829508,"mc":[{"id":"1.231344137","rc":[{"batb":[[0,2.22,33.1],[1,1.83,18.04],[2,1.82,7]],"ltp":2.26,"tv":40.79,"id":2219}]}]}
{"op":"mcm","clk":"11806034156","pt":1722701832820,"mc":[{"id":"1.231344137","rc":[{"batb":[[0,2.24,10],[1,2.22,33.1],[2,1.83,18.04]],"ltp":2.26,"tv":40.79,"id":2219}]}]}
{"op":"mcm","clk":"11806034359","pt":1722701833727,"mc":[{"id":"1.231344137","rc":[{"batb":[[0,2.24,14]],"batl":[[0,2.32,4],[1,2.34,4]],"ltp":2.26,"tv":40.79,"id":2219},{"batb":[[0,1.76,22.04]],"batl":[[0,1.81,4]],"ltp":1.79,"tv":39967.07,"id":2120}]}]}
{"op":"mcm","clk":"11806034849","pt":1722701835796,"mc":[{"id":"1.231344137","rc":[{"batb":[[0,2.24,10]],"ltp":2.26,"tv":40.79,"id":2219},{"batb":[[0,1.79,468.53],[1,1.76,22.04],[2,1.75,53.85]],"ltp":1.79,"tv":39967.07,"id":2120}]}]}
{"op":"mcm","clk":"11806034944","pt":1722701836218,"mc":[{"id":"1.231344137","rc":[{"batb":[[0,2.22,33.1],[1,1.83,18.04],[2,1.82,7]],"ltp":2.26,"tv":40.79,"id":2219}]}]}
{"op":"mcm","clk":"11806035606","pt":1722701839503,"mc":[{"id":"1.231344137","rc":[{"batb":[[0,2.24,10],[1,2.22,33.1],[2,1.83,18.04]],"ltp":2.26,"tv":40.79,"id":2219},{"trd":[[1.79,14998.02]],"batb":[[0,1.76,22.04],[1,1.75,53.85],[2,1.63,9.02]],"ltp":1.79,"tv":40904.13,"id":2120}],"tv":40944.92}]}
{"op":"mcm","clk":"11806036253","pt":1722701842806,"mc":[{"id":"1.231344137","rc":[{"batb":[[0,2.22,33.1],[1,1.83,18.04],[2,1.82,7]],"ltp":2.26,"tv":40.79,"id":2219}]}]}
{"op":"mcm","clk":"11806037442","pt":1722701848820,"mc":[{"id":"1.231344137","rc":[{"batb":[[0,2.24,10],[1,2.22,33.1],[2,1.83,18.04]],"batl":[[0,2.26,4],[1,2.32,4],[2,2.34,4]],"ltp":2.26,"tv":40.79,"id":2219},{"batb":[[0,1.8,21.06],[1,1.79,468.53],[2,1.76,22.04]],"ltp":1.79,"tv":40904.13,"id":2120}]}]}
{"op":"mcm","clk":"11806038017","pt":1722701851517,"mc":[{"id":"1.231344137","rc":[{"batb":[[0,2.22,33.1],[1,1.83,18.04],[2,1.82,7]],"ltp":2.26,"tv":40.79,"id":2219}]}]}
{"op":"mcm","clk":"11806038106","pt":1722701851932,"mc":[{"id":"1.231344137","rc":[{"trd":[[1.79,15892.98],[1.8,22117.77]],"batb":[[0,1.79,21.05],[1,1.76,22.04],[2,1.75,53.85]],"ltp":1.79,"tv":41841.19,"id":2120}],"tv":41881.98}]}
{"op":"mcm","clk":"11806038648","pt":1722701854340,"mc":[{"id":"1.231344137","rc":[{"batl":[[0,1.81,16.96]],"ltp":1.79,"tv":41841.19,"id":2120}]}]}
{"op":"mcm","clk":"11806040439","pt":1722701863252,"mc":[{"id":"1.231344137","rc":[{"batb":[[0,1.76,22.04],[1,1.75,53.85],[2,1.63,9.02]],"ltp":1.79,"tv":41841.19,"id":2120}]}]}
{"op":"mcm","clk":"11806040594","pt":1722701864054,"mc":[{"id":"1.231344137","rc":[{"batb":[[0,2.24,4],[1,2.22,37.1],[2,1.83,18.04]],"batl":[[0,2.32,4],[1,2.34,4],[2,2.34,0]],"ltp":2.26,"tv":40.79,"id":2219},{"batb":[[0,1.79,4],[1,1.76,22.04],[2,1.75,53.85]],"batl":[[0,1.81,20.96]],"ltp":1.79,"tv":41841.19,"id":2120}]}]}
{"op":"mcm","clk":"11806042209","pt":1722701872761,"mc":[{"id":"1.231344137","rc":[{"batb":[[1,2.22,4]],"ltp":2.26,"tv":40.79,"id":2219},{"batb":[[0,1.8,468.53],[1,1.79,4],[2,1.76,22.04]],"ltp":1.79,"tv":41841.19,"id":2120}]}]}
{"op":"mcm","clk":"11806042386","pt":1722701873804,"mc":[{"id":"1.231344137","rc":[{"batb":[[0,1.84,10],[1,1.83,18.04],[2,1.82,7]],"ltp":2.26,"tv":40.79,"id":2219},{"batl":[[0,2.2,13.95]],"ltp":1.79,"tv":41841.19,"id":2120}]}]}
{"op":"mcm","clk":"11806042420","pt":1722701873992,"mc":[{"id":"1.231344137","rc":[{"batb":[[0,1.81,10],[1,1.8,468.53],[2,1.79,4]],"ltp":1.79,"tv":41841.19,"id":2120}]}]}
{"op":"mcm","clk":"11806042919","pt":1722701876580,"mc":[{"id":"1.231344137","rc":[{"batb":[[0,1.83,18.04],[1,1.82,7],[2,1.41,85.28]],"ltp":2.26,"tv":40.79,"id":2219}]}]}
{"op":"mcm","clk":"11806043115","pt":1722701877713,"mc":[{"id":"1.231344137","rc":[{"batb":[[0,2.22,33.1],[1,1.83,18.04],[2,1.82,7]],"ltp":2.26,"tv":40.79,"id":2219},{"batb":[[0,1.8,468.53],[1,1.79,4],[2,1.76,22.04]],"ltp":1.79,"tv":41841.19,"id":2120}]}]}
{"op":"mcm","clk":"11806043542","pt":1722701879796,"mc":[{"id":"1.231344137","rc":[{"batl":[[0,2.26,4],[1,2.32,4],[2,2.34,4]],"ltp":2.26,"tv":40.79,"id":2219},{"trd":[[1.8,23054.83]],"batb":[[0,1.8,4]],"ltp":1.8,"tv":42778.25,"id":2120}],"tv":42819.04}]}
{"op":"mcm","clk":"11806043637","pt":1722701880294,"mc":[{"id":"1.231344137","rc":[{"trd":[[2.24,20.08]],"batb":[[0,2.24,1.92],[1,2.22,33.1],[2,1.83,18.04]],"batl":[[0,2.32,4],[1,2.34,4],[2,2.34,0]],"ltp":2.24,"tv":48.87,"id":2219},{"trd":[[1.81,2824.23]],"batb":[[0,1.76,22.04],[1,1.75,53.85],[2,1.63,9.02]],"ltp":1.81,"tv":42788.25,"id":2120}],"tv":42837.12}]}
{"op":"mcm","clk":"11806044337","pt":1722701883696,"mc":[{"id":"1.231344137","rc":[{"batb":[[0,2.22,33.1],[1,1.83,18.04],[2,1.82,7]],"ltp":2.24,"tv":48.87,"id":2219}]}]}
{"op":"mcm","clk":"11806046508","pt":1722701894384,"mc":[{"id":"1.231344137","rc":[{"batb":[[0,2.24,14],[1,2.22,37.1],[2,1.83,18.04]],"ltp":2.24,"tv":48.87,"id":2219},{"batl":[[0,1.81,4],[1,1.82,4]],"ltp":1.81,"tv":42788.25,"id":2120}]}]}
{"op":"mcm","clk":"11806046923","pt":1722701896509,"mc":[{"id":"1.231344137","rc":[{"batl":[[0,1.8,17.06],[1,1.81,4],[2,1.82,4]],"ltp":1.81,"tv":42788.25,"id":2120}]}]}
{"op":"mcm","clk":"11806047178","pt":1722701897691,"mc":[{"id":"1.231344137","rc":[{"batb":[[0,2.24,4]],"ltp":2.24,"tv":48.87,"id":2219}]}]}
{"op":"mcm","clk":"11806047359","pt":1722701898693,"mc":[{"id":"1.231344137","rc":[{"batl":[[0,1.81,20.96],[1,1.82,4],[2,1.82,0]],"ltp":1.81,"tv":42788.25,"id":2120}]}]}
{"op":"mcm","clk":"11806052293","pt":1722701922784,"mc":[{"id":"1.231344137","rc":[{"batb":[[0,2.28,10],[1,2.26,351.4],[2,2.24,4]],"ltp":2.24,"tv":48.87,"id":2219},{"batb":[[0,1.76,18.04]],"ltp":1.81,"tv":42788.25,"id":2120}]}]}
{"op":"mcm","clk":"11806052462","pt":1722701923694,"mc":[{"id":"1.231344137","rc":[{"batl":[[0,1.79,17.15],[1,1.81,4],[2,1.82,4]],"ltp":1.81,"tv":42788.25,"id":2120}]}]}
{"op":"mcm","clk":"11806052628","pt":1722701924589,"mc":[{"id":"1.231344137","rc":[{"batb":[[0,2.28,14]],"ltp":2.24,"tv":48.87,"id":2219},{"batl":[[0,1.78,4],[1,1.79,21.15],[2,1.81,4]],"ltp":1.81,"tv":42788.25,"id":2120}]}]}
{"op":"mcm","clk":"11806052907","pt":1722701926071,"mc":[{"id":"1.231344137","rc":[{"batb":[[0,2.28,4]],"ltp":2.24,"tv":48.87,"id":2219}]}]}
{"op":"mcm","clk":"11806053685","pt":1722701930168,"mc":[{"id":"1.231344137","rc":[{"batb":[[1,2.24,4],[2,2.22,37.1]],"ltp":2.24,"tv":48.87,"id":2219}]}]}
{"op":"mcm","clk":"11806053993","pt":1722701931804,"mc":[{"id":"1.231344137","rc":[{"batl":[[1,1.79,4]],"ltp":1.81,"tv":42788.25,"id":2120}]}]}
{"op":"mcm","clk":"11806054087","pt":1722701932309,"mc":[{"id":"1.231344137","rc":[{"batb":[[0,2.22,33.1],[1,1.83,18.04],[2,1.82,7]],"ltp":2.24,"tv":48.87,"id":2219}]}]}
{"op":"mcm","clk":"11806055307","pt":1722701938783,"mc":[{"id":"1.231344137","rc":[{"batb":[[0,2.3,351.4],[1,2.22,33.1],[2,1.83,18.04]],"ltp":2.24,"tv":48.87,"id":2219}]}]}
{"op":"mcm","clk":"11806055480","pt":1722701939692,"mc":[{"id":"1.231344137","rc":[{"batb":[[0,2.3,355.4]],"ltp":2.24,"tv":48.87,"id":2219},{"batl":[[0,1.77,4]],"ltp":1.81,"tv":42788.25,"id":2120}]}]}
{"op":"mcm","clk":"11806055567","pt":1722701940220,"mc":[{"id":"1.231344137","rc":[{"batl":[[0,1.77,21.35]],"ltp":1.81,"tv":42788.25,"id":2120}]}]}
{"op":"mcm","clk":"11806056119","pt":1722701942997,"mc":[{"id":"1.231344137","rc":[{"batb":[[1,1.83,18.04],[2,1.82,7]],"ltp":2.24,"tv":48.87,"id":2219},{"batb":[[1,1.63,9.02],[2,1.48,10]],"ltp":1.81,"tv":42788.25,"id":2120}]}]}
{"op":"mcm","clk":"11806057656","pt":1722701951087,"mc":[{"id":"1.231344137","rc":[{"trd":[[2.3,702.8]],"batb":[[0,2.3,4]],"ltp":2.3,"tv":751.66,"id":2219}],"tv":43539.92}]}
{"op":"mcm","clk":"11806057934","pt":1722701952565,"mc":[{"id":"1.231344137","rc":[{"batb":[[0,1.83,18.04],[1,1.82,7],[2,1.41,85.28]],"ltp":2.3,"tv":751.66,"id":2219}]}]}
{"op":"mcm","clk":"11806058019","pt":1722701952987,"mc":[{"id":"1.231344137","rc":[{"batb":[[0,2.22,33.1],[1,1.83,18.04],[2,1.82,7]],"ltp":2.3,"tv":751.66,"id":2219},{"batb":[[1,1.75,53.85],[2,1.63,9.02]],"ltp":1.81,"tv":42788.25,"id":2120}]}]}
{"op":"mcm","clk":"11806058344","pt":1722701954810,"mc":[{"id":"1.231344137","rc":[{"batb":[[0,2.24,4],[1,2.22,37.1],[2,1.83,18.04]],"ltp":2.3,"tv":751.66,"id":2219},{"batl":[[0,1.81,16.96]],"ltp":1.81,"tv":42788.25,"id":2120}]}]}
{"op":"mcm","clk":"11806058364","pt":1722701954911,"mc":[{"id":"1.231344137","rc":[{"batl":[[0,2.32,4]],"ltp":2.3,"tv":751.66,"id":2219},{"batb":[[0,1.76,22.04]],"batl":[[0,1.81,20.96],[1,1.82,4]],"ltp":1.81,"tv":42788.25,"id":2120}]}]}
{"op":"mcm","clk":"11806061146","pt":1722701969804,"mc":[{"id":"1.231344137","rc":[{"batb":[[0,2.3,351.4],[1,2.24,4],[2,2.22,37.1]],"batl":[[0,2.34,1.42]],"ltp":2.3,"tv":751.66,"id":2219},{"batb":[[0,1.76,18.04]],"ltp":1.81,"tv":42788.25,"id":2120}]}]}
{"op":"mcm","clk":"11806061319","pt":1722701970711,"mc":[{"id":"1.231344137","rc":[{"batb":[[0,2.3,355.4]],"ltp":2.3,"tv":751.66,"id":2219},{"batl":[[0,1.77,4],[1,1.81,4],[2,1.82,4]],"ltp":1.81,"tv":42788.25,"id":2120}]}]}
{"op":"mcm","clk":"11806061956","pt":1722701973704,"mc":[{"id":"1.231344137","rc":[{"trd":[[2.3,1405.59]],"batb":[[0,2.3,4],[2,2.22,4]],"ltp":2.3,"tv":1454.46,"id":2219},{"batb":[[1,1.63,9.02],[2,1.48,10]],"ltp":1.81,"tv":42788.25,"id":2120}],"tv":44242.72}]}
{"op":"mcm","clk":"11806062077","pt":1722701974342,"mc":[{"id":"1.231344137","rc":[{"batb":[[0,1.83,18.04],[1,1.82,7],[2,1.41,85.28]],"ltp":2.3,"tv":1454.46,"id":2219}]}]}
{"op":"mcm","clk":"11806062489","pt":1722701976633,"mc":[{"id":"1.231344137","rc":[{"batb":[[0,1.77,10],[1,1.76,18.04],[2,1.63,9.02]],"batl":[[0,2.2,13.95]],"ltp":1.81,"tv":42788.25,"id":2120}]}]}
{"op":"mcm","clk":"11806062771","pt":1722701978031,"mc":[{"id":"1.231344137","rc":[{"batb":[[0,2.22,33.1],[1,1.83,18.04],[2,1.82,7]],"ltp":2.3,"tv":1454.46,"id":2219},{"batb":[[2,1.75,53.85]],"ltp":1.81,"tv":42788.25,"id":2120}]}]}
{"op":"mcm","clk":"11806063216","pt":1722701980329,"mc":[{"id":"1.231344137","rc":[{"batb":[[0,1.76,18.04],[1,1.75,53.85],[2,1.63,9.02]],"ltp":1.81,"tv":42788.25,"id":2120}]}]}
{"op":"mcm","clk":"11806063372","pt":1722701981234,"mc":[{"id":"1.231344137","rc":[{"batb":[[0,2.3,351.4],[1,2.22,33.1],[2,1.83,18.04]],"ltp":2.3,"tv":1454.46,"id":2219}]}]}
{"op":"mcm","clk":"11806063749","pt":1722701983216,"mc":[{"id":"1.231344137","rc":[{"batb":[[1,1.83,18.04],[2,1.82,7]],"ltp":2.3,"tv":1454.46,"id":2219},{"batb":[[1,1.63,9.02],[2,1.48,10]],"ltp":1.81,"tv":42788.25,"id":2120}]}]}
{"op":"mcm","clk":"11806063922","pt":1722701984222,"mc":[{"id":"1.231344137","rc":[{"batl":[[0,1.77,17.35]],"ltp":1.81,"tv":42788.25,"id":2120}]}]}
{"op":"mcm","clk":"11806064150","pt":1722701985407,"mc":[{"id":"1.231344137","rc":[{"trd":[[2.3,2108.39]],"batb":[[0,2.3,4]],"ltp":2.3,"tv":2157.25,"id":2219},{"batl":[[0,1.77,21.35]],"ltp":1.81,"tv":42788.25,"id":2120}],"tv":44945.51}]}
{"op":"mcm","clk":"11806064378","pt":1722701986628,"mc":[{"id":"1.231344137","rc":[{"batl":[[0,1.77,4]],"ltp":1.81,"tv":42788.25,"id":2120}]}]}
{"op":"mcm","clk":"11806064456","pt":1722701987005,"mc":[{"id":"1.231344137","rc":[{"batb":[[0,1.83,18.04],[1,1.82,7],[2,1.41,85.28]],"ltp":2.3,"tv":2157.25,"id":2219}]}]}
{"op":"mcm","clk":"11806064670","pt":1722701988326,"mc":[{"id":"1.231344137","rc":[{"batb":[[0,2.22,33.1],[1,1.83,18.04],[2,1.82,7]],"ltp":2.3,"tv":2157.25,"id":2219},{"batb":[[0,1.77,9.02],[1,1.76,18.04],[2,1.75,53.85]],"ltp":1.81,"tv":42788.25,"id":2120}]}]}
{"op":"mcm","clk":"11806065980","pt":1722701995638,"mc":[{"id":"1.231344137","rc":[{"trd":[[2.3,2115.33]],"batb":[[0,2.3,344.46],[1,2.22,33.1],[2,1.83,18.04]],"ltp":2.3,"tv":2164.19,"id":2219},{"trd":[[1.77,946.08]],"batb":[[0,1.76,18.04],[1,1.75,53.85],[2,1.63,9.02]],"ltp":1.77,"tv":42797.27,"id":2120}],"tv":44961.47}]}
{"op":"mcm","clk":"11806066488","pt":1722701998254,"mc":[{"id":"1.231344137","rc":[{"batb":[[1,1.83,18.04],[2,1.82,7]],"ltp":2.3,"tv":2164.19,"id":2219},{"batb":[[1,1.63,9.02],[2,1.48,10]],"ltp":1.77,"tv":42797.27,"id":2120}]}]}
{"op":"mcm","clk":"11806066804","pt":1722702000244,"mc":[{"id":"1.231344137","rc":[{"batb":[[0,2.3,348.46]],"ltp":2.3,"tv":2164.19,"id":2219},{"batl":[[0,1.77,4]],"ltp":1.77,"tv":42797.27,"id":2120}]}]}
{"op":"mcm","clk":"11806067035","pt":1722702001526,"mc":[{"id":"1.231344137","rc":[{"trd":[[2.28,2.94],[2.3,2812.24]],"batb":[[0,1.83,18.04],[1,1.82,7],[2,1.41,85.28]],"ltp":2.28,"tv":2864.05,"id":2219},{"trd":[[1.77,949.87]],"batl":[[0,1.77,0.21]],"ltp":1.77,"tv":42801.06,"id":2120}],"tv":45665.12}]}
{"op":"mcm","clk":"11806067319","pt":1722702003135,"mc":[{"id":"1.231344137","rc":[{"batb":[[0,2.22,33.1],[1,1.83,18.04],[2,1.82,7]],"ltp":2.28,"tv":2864.05,"id":2219},{"batb":[[1,1.75,53.85],[2,1.63,9.02]],"ltp":1.77,"tv":42801.06,"id":2120}]}]}
{"op":"mcm","clk":"11806067542","pt":1722702004338,"mc":[{"id":"1.231344137","rc":[{"batl":[[0,1.81,16.96]],"ltp":1.77,"tv":42801.06,"id":2120}]}]}
{"op":"mcm","clk":"11806069574","pt":1722702015534,"mc":[{"id":"1.231344137","rc":[{"batb":[[0,2.3,351.4],[1,2.24,4],[2,2.22,37.1]],"batl":[[0,2.32,4],[1,2.34,1.42]],"ltp":2.28,"tv":2864.05,"id":2219},{"batb":[[0,1.76,22.04]],"batl":[[0,1.81,20.96]],"ltp":1.77,"tv":42801.06,"id":2120}]}]}
{"op":"mcm","clk":"11806069713","pt":1722702016369,"mc":[{"id":"1.231344137","rc":[{"batb":[[0,1.76,18.04]],"batl":[[0,1.81,4]],"ltp":1.77,"tv":42801.06,"id":2120}]}]}
{"op":"mcm","clk":"11806070047","pt":1722702018336,"mc":[{"id":"1.231344137","rc":[{"batb":[[2,2.22,4]],"ltp":2.28,"tv":2864.05,"id":2219},{"batb":[[1,1.63,9.02],[2,1.48,10]],"ltp":1.77,"tv":42801.06,"id":2120}]}]}
{"op":"mcm","clk":"11806070156","pt":1722702019060,"mc":[{"id":"1.231344137","rc":[{"trd":[[2.32,13.12]],"ltp":2.32,"tv":2877.16,"id":2219},{"trd":[[1.76,17.29]],"batb":[[0,1.63,9.77],[1,1.48,10],[2,1.41,85.28]],"ltp":1.76,"tv":42818.35,"id":2120}],"tv":45695.52}]}
{"op":"mcm","clk":"11806070428","pt":1722702020659,"mc":[{"id":"1.231344137","rc":[{"trd":[[2.3,3515.03]],"batb":[[0,1.83,18.04],[1,1.82,7],[2,1.41,85.28]],"ltp":2.3,"tv":3579.96,"id":2219}],"tv":46398.32}]}
{"op":"mcm","clk":"11806070614","pt":1722702021748,"mc":[{"id":"1.231344137","rc":[{"batl":[[0,2.2,13.95]],"ltp":1.76,"tv":42818.35,"id":2120}]}]}
{"op":"mcm","clk":"11806070650","pt":1722702021973,"mc":[{"id":"1.231344137","rc":[{"batb":[[0,1.64,10.75],[1,1.63,9.02],[2,1.48,10]],"ltp":1.76,"tv":42818.35,"id":2120}]}]}
{"op":"mcm","clk":"11806070872","pt":1722702023257,"mc":[{"id":"1.231344137","rc":[{"batb":[[0,2.22,33.1],[1,1.83,18.04],[2,1.82,7]],"ltp":2.3,"tv":3579.96,"id":2219},{"batb":[[0,1.75,54.6],[1,1.64,10],[2,1.63,9.02]],"ltp":1.76,"tv":42818.35,"id":2120}]}]}
{"op":"mcm","clk":"11806071088","pt":1722702024440,"mc":[{"id":"1.231344137","rc":[{"batb":[[0,2.24,10],[1,2.22,33.1],[2,1.83,18.04]],"batl":[[0,2.32,13.12]],"ltp":2.3,"tv":3579.96,"id":2219}]}]}
{"op":"mcm","clk":"11806071215","pt":1722702025154,"mc":[{"id":"1.231344137","rc":[{"batb":[[1,1.63,9.02],[2,1.48,10]],"ltp":1.76,"tv":42818.35,"id":2120}]}]}
{"op":"mcm","clk":"11806071692","pt":1722702027868,"mc":[{"id":"1.231344137","rc":[{"batb":[[0,2.22,33.1],[1,1.83,18.04],[2,1.82,7]],"ltp":2.3,"tv":3579.96,"id":2219}]}]}
{"op":"mcm","clk":"11806072247","pt":1722702030645,"mc":[{"id":"1.231344137","rc":[{"batb":[[0,2.24,4],[1,2.22,37.1],[2,1.83,18.04]],"batl":[[0,2.32,17.12]],"ltp":2.3,"tv":3579.96,"id":2219}]}]}
{"op":"mcm","clk":"11806072914","pt":1722702033946,"mc":[{"id":"1.231344137","rc":[{"batl":[[0,1.8,27.05]],"ltp":1.76,"tv":42818.35,"id":2120}]}]}
{"op":"mcm","clk":"11806073225","pt":1722702035572,"mc":[{"id":"1.231344137","rc":[{"batl":[[0,1.79,17.15],[1,1.8,27.05]],"ltp":1.76,"tv":42818.35,"id":2120}]}]}
{"op":"mcm","clk":"11806074981","pt":1722702045762,"mc":[{"id":"1.231344137","rc":[{"batb":[[0,2.26,4],[1,2.24,4],[2,2.22,37.1]],"ltp":2.3,"tv":3579.96,"id":2219},{"batb":[[0,1.75,58.6]],"batl":[[0,1.79,21.15]],"ltp":1.76,"tv":42818.35,"id":2120}]}]}
{"op":"mcm","clk":"11806075054","pt":1722702046172,"mc":[{"id":"1.231344137","rc":[{"batl":[[1,2.34,1.42]],"ltp":2.3,"tv":3579.96,"id":2219}]}]}
{"op":"mcm","clk":"11806075602","pt":1722702048784,"mc":[{"id":"1.231344137","rc":[{"batb":[[0,2.3,351.4],[1,2.26,4],[2,2.24,4]],"ltp":2.3,"tv":3579.96,"id":2219}]}]}
{"op":"mcm","clk":"11806075654","pt":1722702049123,"mc":[{"id":"1.231344137","rc":[{"batl":[[0,2.32,13.12]],"ltp":2.3,"tv":3579.96,"id":2219},{"batb":[[0,1.75,54.6]],"ltp":1.76,"tv":42818.35,"id":2120}]}]}
{"op":"mcm","clk":"11806075939","pt":1722702050777,"mc":[{"id":"1.231344137","rc":[{"batl":[[0,1.79,4]],"ltp":1.76,"tv":42818.35,"id":2120}]}]}
{"op":"mcm","clk":"11806075959","pt":1722702050881,"mc":[{"id":"1.231344137","rc":[{"trd":[[1.76,18.79]],"batb":[[0,1.75,53.85]],"batl":[[0,1.76,16.69],[1,1.79,4],[2,1.8,27.05]],"ltp":1.76,"tv":42819.85,"id":2120}],"tv":46399.82}]}
{"op":"mcm","clk":"11806076350","pt":1722702053110,"mc":[{"id":"1.231344137","rc":[{"trd":[[2.3,4217.83]],"batb":[[0,2.26,4],[1,2.24,4],[2,2.22,37.1]],"ltp":2.3,"tv":4282.75,"id":2219}],"tv":47102.61}]}
{"op":"mcm","clk":"11806076716","pt":1722702055299,"mc":[{"id":"1.231344137","rc":[{"batl":[[0,1.79,4],[1,1.8,27.05],[2,1.8,0]],"ltp":1.76,"tv":42819.85,"id":2120}]}]}
{"op":"mcm","clk":"11806077709","pt":1722702060896,"mc":[{"id":"1.231344137","rc":[{"batl":[[0,2.32,17.12]],"ltp":2.3,"tv":4282.75,"id":2219},{"batb":[[0,1.75,57.85]],"ltp":1.76,"tv":42819.85,"id":2120}]}]}
{"op":"mcm","clk":"11806078182","pt":1722702063618,"mc":[{"id":"1.231344137","rc":[{"batb":[[0,2.3,351.4],[1,2.26,4],[2,2.24,4]],"ltp":2.3,"tv":4282.75,"id":2219}]}]}
{"op":"mcm","clk":"11806078301","pt":1722702064297,"mc":[{"id":"1.231344137","rc":[{"batl":[[0,2.32,13.12]],"ltp":2.3,"tv":4282.75,"id":2219},{"batb":[[0,1.75,53.85]],"ltp":1.76,"tv":42819.85,"id":2120}]}]}
{"op":"mcm","clk":"11806079069","pt":1722702068405,"mc":[{"id":"1.231344137","rc":[{"trd":[[2.3,4920.63]],"batb":[[0,2.26,4],[1,2.24,4],[2,2.22,37.1]],"ltp":2.3,"tv":4985.55,"id":2219}],"tv":47805.41}]}
{"op":"mcm","clk":"11806080455","pt":1722702076110,"mc":[{"id":"1.231344137","rc":[{"batl":[[0,2.32,17.12]],"ltp":2.3,"tv":4985.55,"id":2219},{"batb":[[0,1.75,57.85]],"ltp":1.76,"tv":42819.85,"id":2120}]}]}
{"op":"mcm","clk":"11806080883","pt":1722702078387,"mc":[{"id":"1.231344137","rc":[{"batl":[[0,1.79,20.42]],"ltp":1.76,"tv":42819.85,"id":2120}]}]}
{"op":"mcm","clk":"11806081598","pt":1722702082674,"mc":[{"id":"1.231344137","rc":[{"batb":[[0,2.3,351.4],[1,2.26,4],[2,2.24,4]],"ltp":2.3,"tv":4985.55,"id":2219}]}]}
{"op":"mcm","clk":"11806081658","pt":1722702082984,"mc":[{"id":"1.231344137","rc":[{"batl":[[0,2.32,13.12]],"ltp":2.3,"tv":4985.55,"id":2219},{"batb":[[0,1.75,53.85]],"ltp":1.76,"tv":42819.85,"id":2120}]}]}
{"op":"mcm","clk":"11806082039","pt":1722702085120,"mc":[{"id":"1.231344137","rc":[{"batl":[[0,1.79,4]],"ltp":1.76,"tv":42819.85,"id":2120}]}]}
{"op":"mcm","clk":"11806082448","pt":1722702087484,"mc":[{"id":"1.231344137","rc":[{"trd":[[2.3,5623.42]],"batb":[[0,2.26,4],[1,2.24,4],[2,2.22,37.1]],"ltp":2.3,"tv":5688.35,"id":2219}],"tv":48508.21}]}
{"op":"mcm","clk":"11806083104","pt":1722702091205,"mc":[{"id":"1.231344137","rc":[{"batl":[[0,2.32,17.12]],"ltp":2.3,"tv":5688.35,"id":2219},{"batb":[[0,1.75,57.85]],"ltp":1.76,"tv":42819.85,"id":2120}]}]}
{"op":"mcm","clk":"11806087177","pt":1722702115600,"mc":[{"id":"1.231344137","rc":[{"batb":[[0,2.3,351.4],[1,2.26,4],[2,2.24,4]],"batl":[[0,2.32,13.12]],"ltp":2.3,"tv":5688.35,"id":2219},{"batb":[[0,1.75,53.85]],"ltp":1.76,"tv":42819.85,"id":2120}]}]}
{"op":"mcm","clk":"11806087223","pt":1722702115915,"mc":[{"id":"1.231344137","rc":[{"batl":[[0,1.76,16.69],[1,1.79,4],[2,1.8,27.05]],"ltp":1.76,"tv":42819.85,"id":2120}]}]}
{"op":"mcm","clk":"11806088188","pt":1722702121623,"mc":[{"id":"1.231344137","rc":[{"trd":[[2.3,6326.22]],"batb":[[0,2.26,4],[1,2.24,4],[2,2.22,37.1]],"batl":[[0,2.32,17.12]],"ltp":2.3,"tv":6391.14,"id":2219},{"batb":[[0,1.75,57.85]],"ltp":1.76,"tv":42819.85,"id":2120}],"tv":49211.0}]}
{"op":"mcm","clk":"11806088630","pt":1722702124447,"mc":[{"id":"1.231344137","rc":[{"batl":[[0,1.79,20.42],[1,1.8,27.05],[2,1.8,0]],"ltp":1.76,"tv":42819.85,"id":2120}]}]}
{"op":"mcm","clk":"11806090703","pt":1722702136830,"mc":[{"id":"1.231344137","rc":[{"batb":[[0,2.28,4],[1,2.26,4],[2,2.24,4]],"ltp":2.3,"tv":6391.14,"id":2219}]}]}
{"op":"mcm","clk":"11806091273","pt":1722702140342,"mc":[{"id":"1.231344137","rc":[{"batl":[[1,1.8,0]],"ltp":1.76,"tv":42819.85,"id":2120}]}]}
{"op":"mcm","clk":"11806091659","pt":1722702142723,"mc":[{"id":"1.231344137","rc":[{"batb":[[0,2.26,4],[1,2.24,4],[2,2.22,37.1]],"ltp":2.3,"tv":6391.14,"id":2219},{"batl":[[0,1.79,4],[1,1.8,16.32]],"ltp":1.76,"tv":42819.85,"id":2120}]}]}
{"op":"mcm","clk":"11806092063","pt":1722702144749,"mc":[{"id":"1.231344137","rc":[{"batb":[[0,2.24,4],[1,2.22,37.1],[2,1.83,18.04]],"ltp":2.3,"tv":6391.14,"id":2219},{"batl":[[0,1.81,16.23],[1,1.8,0]],"ltp":1.76,"tv":42819.85,"id":2120}]}]}
{"op":"mcm","clk":"11806093414","pt":1722702152028,"mc":[{"id":"1.231344137","rc":[{"batl":[[0,1.81,20.23]],"ltp":1.76,"tv":42819.85,"id":2120}]}]}
{"op":"mcm","clk":"11806094522","pt":1722702158549,"mc":[{"id":"1.231344137","rc":[{"batl":[[0,1.79,27.05],[1,1.81,20.23]],"ltp":1.76,"tv":42819.85,"id":2120}]}]}
{"op":"mcm","clk":"11806094610","pt":1722702159076,"mc":[{"id":"1.231344137","rc":[{"batl":[[0,1.78,16.5],[1,1.79,27.05],[2,1.81,4]],"ltp":1.76,"tv":42819.85,"id":2120}]}]}
{"op":"mcm","clk":"11806095957","pt":1722702167240,"mc":[{"id":"1.231344137","rc":[{"batb":[[0,2.28,4],[1,2.24,4],[2,2.22,37.1]],"ltp":2.3,"tv":6391.14,"id":2219},{"batl":[[0,1.78,20.5]],"ltp":1.76,"tv":42819.85,"id":2120}]}]}
{"op":"mcm","clk":"11806105777","pt":1722702226112,"mc":[{"id":"1.231344137","rc":[{"batb":[[1,1.48,10],[2,1.41,85.28]],"ltp":1.76,"tv":42819.85,"id":2120}]}]}
{"op":"mcm","clk":"11806127330","pt":1722702364732,"mc":[{"id":"1.231344137","rc":[{"trd":[[2.28,26.95]],"batb":[[0,2.24,4],[1,2.22,37.1],[2,1.82,7]],"batl":[[0,2.28,448.52],[1,2.32,17.12],[2,2.34,1.42]],"ltp":2.28,"tv":6415.15,"id":2219},{"trd":[[1.78,20.5]],"batl":[[0,1.79,27.05],[1,1.81,4],[2,1.81,0]],"ltp":1.78,"tv":42840.36,"id":2120}],"tv":49255.51}]}
{"op":"mcm","clk":"11806127372","pt":1722702365049,"mc":[{"id":"1.231344137","rc":[{"batb":[[0,2.22,33.1],[1,1.82,7],[2,1.41,85.28]],"ltp":2.28,"tv":6415.15,"id":2219},{"batl":[[1,1.81,0]],"ltp":1.78,"tv":42840.36,"id":2120}]}]}
{"op":"mcm","clk":"11806127575","pt":1722702366431,"mc":[{"id":"1.231344137","rc":[{"batl":[[0,2.28,461.87],[1,2.32,4]],"ltp":2.28,"tv":6415.15,"id":2219}]}]}
{"op":"mcm","clk":"11806129628","pt":1722702379134,"mc":[{"id":"1.231344137","rc":[{"batl":[[0,2.28,465.87]],"ltp":2.28,"tv":6415.15,"id":2219},{"batb":[[0,1.78,4],[1,1.75,57.85],[2,1.48,10]],"ltp":1.78,"tv":42840.36,"id":2120}]}]}
{"op":"mcm","clk":"11806130274","pt":1722702383056,"mc":[{"id":"1.231344137","rc":[{"batl":[[0,2.28,17.35]],"ltp":2.28,"tv":6415.15,"id":2219}]}]}
{"op":"mcm","clk":"11806130676","pt":1722702385542,"mc":[{"id":"1.231344137","rc":[{"batb":[[0,2.24,10],[1,2.22,33.1],[2,1.82,7]],"batl":[[0,2.32,17.12],[1,2.34,1.42],[2,2.34,0]],"ltp":2.28,"tv":6415.15,"id":2219},{"batb":[[0,1.75,57.85],[1,1.48,10],[2,1.41,85.28]],"ltp":1.78,"tv":42840.36,"id":2120}]}]}
{"op":"mcm","clk":"11806130964","pt":1722702387431,"mc":[{"id":"1.231344137","rc":[{"batb":[[0,1.76,5.84],[1,1.75,57.85],[2,1.48,10]],"ltp":1.78,"tv":42840.36,"id":2120}]}]}
{"op":"mcm","clk":"11806131190","pt":1722702388863,"mc":[{"id":"1.231344137","rc":[{"batb":[[0,2.22,33.1],[1,1.82,7],[2,1.41,85.28]],"ltp":2.28,"tv":6415.15,"id":2219}]}]}
{"op":"mcm","clk":"11806132048","pt":1722702394377,"mc":[{"id":"1.231344137","rc":[{"batb":[[0,2.26,4],[1,2.22,33.1],[2,1.82,7]],"batl":[[0,2.3,4],[1,2.32,17.12],[2,2.34,1.42]],"ltp":2.28,"tv":6415.15,"id":2219},{"batb":[[0,1.76,9.84]],"batl":[[0,1.78,4],[1,1.79,31.05]],"ltp":1.78,"tv":42840.36,"id":2120}]}]}
{"op":"mcm","clk":"11806133483","pt":1722702403597,"mc":[{"id":"1.231344137","rc":[{"trd":[[2.3,6334.21]],"batb":[[0,2.3,347.4],[1,2.26,4],[2,2.22,33.1]],"batl":[[0,2.32,13.12],[1,2.34,1.42],[2,2.34,0]],"ltp":2.3,"tv":6423.15,"id":2219},{"batb":[[0,1.76,5.84],[1,1.75,53.85]],"ltp":1.78,"tv":42840.36,"id":2120}],"tv":49263.51}]}
{"op":"mcm","clk":"11806133727","pt":1722702405395,"mc":[{"id":"1.231344137","rc":[{"batb":[[2,1.82,7]],"ltp":2.3,"tv":6423.15,"id":2219},{"batb":[[0,1.48,10],[1,1.41,85.28],[2,1.3,633.33]],"ltp":1.78,"tv":42840.36,"id":2120}]}]}
{"op":"mcm","clk":"11806134162","pt":1722702408280,"mc":[{"id":"1.231344137","rc":[{"batb":[[0,2.32,12],[1,2.3,347.4],[2,2.26,4]],"batl":[[0,3.4,8.95],[1,2.34,0]],"ltp":2.3,"tv":6423.15,"id":2219}]}]}
{"op":"mcm","clk":"11806134360","pt":1722702409566,"mc":[{"id":"1.231344137","rc":[{"trd":[[2.3,7013.01],[2.32,37.12]],"batb":[[0,2.3,8],[1,2.26,4],[2,1.82,7]],"ltp":2.3,"tv":7125.94,"id":2219},{"batl":[[0,1.79,27.05],[1,1.79,0]],"ltp":1.78,"tv":42840.36,"id":2120}],"tv":49966.3}]}
{"op":"mcm","clk":"11806134497","pt":1722702410460,"mc":[{"id":"1.231344137","rc":[{"batb":[[2,2.22,33.1]],"ltp":2.3,"tv":7125.94,"id":2219},{"batb":[[0,1.75,53.85],[1,1.48,10],[2,1.41,85.28]],"ltp":1.78,"tv":42840.36,"id":2120}]}]}
{"op":"mcm","clk":"11806134989","pt":1722702413863,"mc":[{"id":"1.231344137","rc":[{"batb":[[0,2.26,4],[1,2.22,33.1],[2,1.82,7]],"ltp":2.3,"tv":7125.94,"id":2219}]}]}
{"op":"mcm","clk":"11806135611","pt":1722702417684,"mc":[{"id":"1.231344137","rc":[{"batb":[[0,2.3,351.4],[1,2.26,4],[2,2.22,33.1]],"ltp":2.3,"tv":7125.94,"id":2219}]}]}
{"op":"mcm","clk":"11806136394","pt":1722702422876,"mc":[{"id":"1.231344137","rc":[{"trd":[[2.3,7715.8]],"batb":[[0,2.26,4],[1,2.22,33.1],[2,1.82,7]],"ltp":2.3,"tv":7828.73,"id":2219}],"tv":50669.1}]}
{"op":"mcm","clk":"11806136696","pt":1722702424613,"mc":[{"id":"1.231344137","rc":[{"batl":[[0,2.34,4]],"ltp":2.3,"tv":7828.73,"id":2219},{"batb":[[0,1.75,57.85]],"batl":[[0,1.79,31.05]],"ltp":1.78,"tv":42840.36,"id":2120}]}]}
{"op":"mcm","clk":"11806137778","pt":1722702431300,"mc":[{"id":"1.231344137","rc":[{"batl":[[0,2.32,13.12],[1,2.34,4]],"ltp":2.3,"tv":7828.73,"id":2219}]}]}
{"op":"mcm","clk":"11806138204","pt":1722702433822,"mc":[{"id":"1.231344137","rc":[{"batb":[[0,1.76,5.45],[1,1.75,57.85],[2,1.48,10]],"ltp":1.78,"tv":42840.36,"id":2120}]}]}
{"op":"mcm","clk":"11806139086","pt":1722702439707,"mc":[{"id":"1.231344137","rc":[{"batb":[[0,2.28,4],[1,2.26,4],[2,2.22,33.1]],"batl":[[0,2.32,17.12]],"ltp":2.3,"tv":7828.73,"id":2219},{"batb":[[0,1.76,9.45]],"batl":[[0,1.78,4],[1,1.79,31.05]],"ltp":1.78,"tv":42840.36,"id":2120}]}]}
{"op":"mcm","clk":"11806139201","pt":1722702440303,"mc":[{"id":"1.231344137","rc":[{"batl":[[2,2.36,1.42]],"ltp":2.3,"tv":7828.73,"id":2219}]}]}
{"op":"mcm","clk":"11806143362","pt":1722702467619,"mc":[{"id":"1.231344137","rc":[{"batb":[[0,2.3,351.4],[1,2.28,4],[2,2.26,4]],"batl":[[0,2.32,13.12],[1,2.36,1.42],[2,2.36,0]],"ltp":2.3,"tv":7828.73,"id":2219},{"batb":[[0,1.76,5.45],[1,1.75,53.85]],"ltp":1.78,"tv":42840.36,"id":2120}]}]}
{"op":"mcm","clk":"11806143434","pt":1722702468243,"mc":[{"id":"1.231344137","rc":[{"batl":[[1,2.34,1.4]],"ltp":2.3,"tv":7828.73,"id":2219},{"batb":[[0,1.75,53.85],[1,1.48,10],[2,1.41,85.28]],"ltp":1.78,"tv":42840.36,"id":2120}]}]}
{"op":"mcm","clk":"11806143819","pt":1722702470528,"mc":[{"id":"1.231344137","rc":[{"trd":[[2.3,8418.6]],"batb":[[0,2.3,4]],"ltp":2.3,"tv":8531.53,"id":2219},{"batl":[[0,1.76,4],[1,1.77,4],[2,1.78,4]],"ltp":1.78,"tv":42840.36,"id":2120}],"tv":51371.89}]}
{"op":"mcm","clk":"11806143922","pt":1722702471259,"mc":[{"id":"1.231344137","rc":[{"batb":[[0,2.28,4],[1,2.26,4],[2,2.22,33.1]],"ltp":2.3,"tv":8531.53,"id":2219},{"batl":[[0,1.79,27.05],[1,1.77,0],[2,1.78,0]],"ltp":1.78,"tv":42840.36,"id":2120}]}]}
{"op":"mcm","clk":"11806144623","pt":1722702476433,"mc":[{"id":"1.231344137","rc":[{"batb":[[0,2.3,351.4],[1,2.28,4],[2,2.26,4]],"ltp":2.3,"tv":8531.53,"id":2219}]}]}
{"op":"mcm","clk":"11806145220","pt":1722702480547,"mc":[{"id":"1.231344137","rc":[{"trd":[[2.3,9121.39]],"batb":[[0,2.28,4],[1,2.26,4],[2,2.22,33.1]],"ltp":2.3,"tv":9234.33,"id":2219},{"batb":[[0,1.76,5.14],[1,1.75,53.85],[2,1.48,10]],"ltp":1.78,"tv":42840.36,"id":2120}],"tv":52074.69}]}
{"op":"mcm","clk":"11806146020","pt":1722702485438,"mc":[{"id":"1.231344137","rc":[{"batb":[[0,2.3,351.4],[1,2.28,4],[2,2.26,4]],"batl":[[0,2.32,17.12]],"ltp":2.3,"tv":9234.33,"id":2219},{"batb":[[0,1.76,9.14]],"batl":[[0,1.78,4],[1,1.79,31.05]],"ltp":1.78,"tv":42840.36,"id":2120}]}]}
{"op":"mcm","clk":"11806146173","pt":1722702486548,"mc":[{"id":"1.231344137","rc":[{"batb":[[0,1.76,4]],"ltp":1.78,"tv":42840.36,"id":2120}]}]}
{"op":"mcm","clk":"11806146300","pt":1722702487244,"mc":[{"id":"1.231344137","rc":[{"batl":[[0,2.32,13.12]],"ltp":2.3,"tv":9234.33,"id":2219},{"batb":[[0,1.75,53.85],[1,1.48,10],[2,1.41,85.28]],"ltp":1.78,"tv":42840.36,"id":2120}]}]}
{"op":"mcm","clk":"11806146400","pt":1722702487862,"mc":[{"id":"1.231344137","rc":[{"trd":[[2.3,9824.19]],"batb":[[0,2.28,4],[1,2.26,4],[2,2.22,33.1]],"ltp":2.3,"tv":9937.12,"id":2219}],"tv":52777.48}]}
{"op":"mcm","clk":"11806147011","pt":1722702491939,"mc":[{"id":"1.231344137","rc":[{"batb":[[0,2.3,351.4],[1,2.28,4],[2,2.26,4]],"ltp":2.3,"tv":9937.12,"id":2219}]}]}
{"op":"mcm","clk":"11806147443","pt":1722702494847,"mc":[{"id":"1.231344137","rc":[{"trd":[[2.3,10526.98]],"batb":[[0,2.28,4],[1,2.26,4],[2,2.22,33.1]],"ltp":2.3,"tv":10639.92,"id":2219}],"tv":53480.28}]}
{"op":"mcm","clk":"11806148241","pt":1722702499643,"mc":[{"id":"1.231344137","rc":[{"batb":[[0,2.3,351.4],[1,2.28,4],[2,2.26,4]],"ltp":2.3,"tv":10639.92,"id":2219}]}]}
{"op":"mcm","clk":"11806148380","pt":1722702500577,"mc":[{"id":"1.231344137","rc":[{"batb":[[0,2.3,355.4]],"ltp":2.3,"tv":10639.92,"id":2219},{"batl":[[0,1.76,4],[1,1.77,4],[2,1.78,4]],"ltp":1.78,"tv":42840.36,"id":2120}]}]}
{"op":"mcm","clk":"11806148667","pt":1722702502468,"mc":[{"id":"1.231344137","rc":[{"trd":[[2.3,11229.78]],"batb":[[0,2.3,4]],"ltp":2.3,"tv":11342.71,"id":2219}],"tv":54183.07}]}
{"op":"mcm","clk":"11806148765","pt":1722702503053,"mc":[{"id":"1.231344137","rc":[{"batb":[[0,2.28,4],[1,2.26,4],[2,2.22,33.1]],"ltp":2.3,"tv":11342.71,"id":2219},{"batl":[[0,1.79,27.05],[1,1.77,0],[2,1.78,0]],"ltp":1.78,"tv":42840.36,"id":2120}]}]}
{"op":"mcm","clk":"11806149376","pt":1722702506967,"mc":[{"id":"1.231344137","rc":[{"batb":[[0,2.3,351.4],[1,2.28,4],[2,2.26,4]],"ltp":2.3,"tv":11342.71,"id":2219}]}]}
{"op":"mcm","clk":"11806149968","pt":1722702510485,"mc":[{"id":"1.231344137","rc":[{"trd":[[2.3,11932.57]],"batb":[[0,2.28,4],[1,2.26,4],[2,2.22,33.1]],"ltp":2.3,"tv":12045.51,"id":2219}],"tv":54885.87}]}
{"op":"mcm","clk":"11806150862","pt":1722702515768,"mc":[{"id":"1.231344137","rc":[{"batb":[[0,2.3,351.4],[1,2.28,4],[2,2.26,4]],"batl":[[0,2.32,17.12]],"ltp":2.3,"tv":12045.51,"id":2219},{"batb":[[0,1.75,57.85]],"batl":[[0,1.79,31.05]],"ltp":1.78,"tv":42840.36,"id":2120}]}]}
{"op":"mcm","clk":"11806150966","pt":1722702516478,"mc":[{"id":"1.231344137","rc":[{"batl":[[0,2.32,13.12]],"ltp":2.3,"tv":12045.51,"id":2219},{"batb":[[0,1.75,53.85]],"ltp":1.78,"tv":42840.36,"id":2120}]}]}
{"op":"mcm","clk":"11806151262","pt":1722702518272,"mc":[{"id":"1.231344137","rc":[{"trd":[[2.3,12635.37]],"batb":[[0,2.28,4],[1,2.26,4],[2,2.22,33.1]],"ltp":2.3,"tv":12748.3,"id":2219}],"tv":55588.66}]}
{"op":"mcm","clk":"11806151953","pt":1722702522679,"mc":[{"id":"1.231344137","rc":[{"batb":[[0,2.3,351.4],[1,2.28,4],[2,2.26,4]],"ltp":2.3,"tv":12748.3,"id":2219}]}]}
{"op":"mcm","clk":"11806152506","pt":1722702526169,"mc":[{"id":"1.231344137","rc":[{"trd":[[2.3,13338.17]],"batb":[[0,2.28,4],[1,2.26,4],[2,2.22,33.1]],"ltp":2.3,"tv":13451.1,"id":2219}],"tv":56291.46}]}
{"op":"mcm","clk":"11806152716","pt":1722702527385,"mc":[{"id":"1.231344137","rc":[{"batb":[[0,1.76,5.14],[1,1.75,53.85],[2,1.48,10]],"ltp":1.78,"tv":42840.36,"id":2120}]}]}
{"op":"mcm","clk":"11806153414","pt":1722702531679,"mc":[{"id":"1.231344137","rc":[{"batb":[[0,2.3,351.4],[1,2.28,4],[2,2.26,4]],"ltp":2.3,"tv":13451.1,"id":2219},{"batb":[[0,1.75,53.85],[1,1.48,10],[2,1.41,85.28]],"batl":[[0,1.78,4],[1,1.79,31.05]],"ltp":1.78,"tv":42840.36,"id":2120}]}]}
{"op":"mcm","clk":"11806153829","pt":1722702534335,"mc":[{"id":"1.231344137","rc":[{"trd":[[2.3,14040.96]],"batb":[[0,2.28,4],[1,2.26,4],[2,2.22,33.1]],"ltp":2.3,"tv":14153.89,"id":2219}],"tv":56994.26}]}
{"op":"mcm","clk":"11806154560","pt":1722702538697,"mc":[{"id":"1.231344137","rc":[{"batb":[[0,2.3,351.4],[1,2.28,4],[2,2.26,4]],"ltp":2.3,"tv":14153.89,"id":2219}]}]}
{"op":"mcm","clk":"11806155161","pt":1722702542310,"mc":[{"id":"1.231344137","rc":[{"trd":[[2.3,14743.76]],"batb":[[0,2.28,4],[1,2.26,4],[2,2.22,33.1]],"ltp":2.3,"tv":14856.69,"id":2219}],"tv":57697.05}]}
{"op":"mcm","clk":"11806155823","pt":1722702546123,"mc":[{"id":"1.231344137","rc":[{"batl":[[0,2.32,17.12]],"ltp":2.3,"tv":14856.69,"id":2219},{"batb":[[0,1.75,57.85]],"ltp":1.78,"tv":42840.36,"id":2120}]}]}
{"op":"mcm","clk":"11806156108","pt":1722702547822,"mc":[{"id":"1.231344137","rc":[{"batb":[[0,2.3,351.4],[1,2.28,4],[2,2.26,4]],"batl":[[0,2.32,13.12]],"ltp":2.3,"tv":14856.69,"id":2219},{"batb":[[0,1.75,53.85]],"ltp":1.78,"tv":42840.36,"id":2120}]}]}
{"op":"mcm","clk":"11806156669","pt":1722702551031,"mc":[{"id":"1.231344137","rc":[{"trd":[[2.3,15446.55]],"batb":[[0,2.28,4],[1,2.26,4],[2,2.22,33.1]],"ltp":2.3,"tv":15559.49,"id":2219}],"tv":58399.85}]}
{"op":"mcm","clk":"11806157453","pt":1722702555522,"mc":[{"id":"1.231344137","rc":[{"batb":[[0,2.3,351.4],[1,2.28,4],[2,2.26,4]],"ltp":2.3,"tv":15559.49,"id":2219}]}]}
{"op":"mcm","clk":"11806157985","pt":1722702558816,"mc":[{"id":"1.231344137","rc":[{"trd":[[2.3,16149.35]],"batb":[[0,2.28,4],[1,2.26,4],[2,2.22,33.1]],"ltp":2.3,"tv":16262.28,"id":2219}],"tv":59102.64}]}
{"op":"mcm","clk":"11806158411","pt":1722702561255,"mc":[{"id":"1.231344137","rc":[{"batl":[[0,2.32,17.12]],"ltp":2.3,"tv":16262.28,"id":2219},{"batb":[[0,1.75,57.85]],"ltp":1.78,"tv":42840.36,"id":2120}]}]}
{"op":"mcm","clk":"11806158866","pt":1722702563747,"mc":[{"id":"1.231344137","rc":[{"batb":[[0,2.3,351.4],[1,2.28,4],[2,2.26,4]],"ltp":2.3,"tv":16262.28,"id":2219}]}]}
{"op":"mcm","clk":"11806158963","pt":1722702564336,"mc":[{"id":"1.231344137","rc":[{"batl":[[0,2.32,13.12]],"ltp":2.3,"tv":16262.28,"id":2219},{"batb":[[0,1.75,53.85]],"ltp":1.78,"tv":42840.36,"id":2120}]}]}
{"op":"mcm","clk":"11806159385","pt":1722702566835,"mc":[{"id":"1.231344137","rc":[{"trd":[[2.3,16852.14]],"batb":[[0,2.28,4],[1,2.26,4],[2,2.22,33.1]],"ltp":2.3,"tv":16965.08,"id":2219}],"tv":59805.44}]}
{"op":"mcm","clk":"11806160114","pt":1722702571562,"mc":[{"id":"1.231344137","rc":[{"batb":[[0,2.3,351.4],[1,2.28,4],[2,2.26,4]],"ltp":2.3,"tv":16965.08,"id":2219}]}]}
{"op":"mcm","clk":"11806160639","pt":1722702574969,"mc":[{"id":"1.231344137","rc":[{"trd":[[2.3,17554.94]],"batb":[[0,2.28,4],[1,2.26,4],[2,2.22,33.1]],"ltp":2.3,"tv":17667.87,"id":2219}],"tv":60508.23}]}
{"op":"mcm","clk":"11806160864","pt":1722702576349,"mc":[{"id":"1.231344137","rc":[{"batl":[[0,2.32,17.12]],"ltp":2.3,"tv":17667.87,"id":2219},{"batb":[[0,1.76,5.14],[1,1.75,57.85],[2,1.48,10]],"ltp":1.78,"tv":42840.36,"id":2120}]}]}
{"op":"mcm","clk":"11806161369","pt":1722702579619,"mc":[{"id":"1.231344137","rc":[{"batb":[[0,2.3,351.4],[1,2.28,4],[2,2.26,4]],"ltp":2.3,"tv":17667.87,"id":2219}]}]}
{"op":"mcm","clk":"11806161535","pt":1722702580734,"mc":[{"id":"1.231344137","rc":[{"batl":[[0,2.32,13.12]],"ltp":2.3,"tv":17667.87,"id":2219},{"batb":[[1,1.48,10],[2,1.41,85.28]],"ltp":1.78,"tv":42840.36,"id":2120}]}]}
{"op":"mcm","clk":"11806161588","pt":1722702581050,"mc":[{"id":"1.231344137","rc":[{"batb":[[0,1.48,10],[1,1.41,85.28],[2,1.3,633.33]],"ltp":1.78,"tv":42840.36,"id":2120}]}]}
{"op":"mcm","clk":"11806162003","pt":1722702583556,"mc":[{"id":"1.231344137","rc":[{"trd":[[2.3,18257.67],[2.32,63.42]],"batb":[[0,2.3,12.03]],"batl":[[0,3.4,17.92],[1,2.34,0]],"ltp":2.3,"tv":18396.9,"id":2219}],"tv":61237.26}]}
{"op":"mcm","clk":"11806162364","pt":1722702585723,"mc":[{"id":"1.231344137","rc":[{"batb":[[0,2.3,10.03]],"batl":[[0,3.4,8.97]],"ltp":2.3,"tv":18396.9,"id":2219},{"batb":[[0,1.75,53.85],[1,1.48,10],[2,1.41,85.28]],"ltp":1.78,"tv":42840.36,"id":2120}]}]}
{"op":"mcm","clk":"11806162468","pt":1722702586357,"mc":[{"id":"1.231344137","rc":[{"batb":[[0,2.28,4.03],[1,2.26,4],[2,2.22,33.1]],"ltp":2.3,"tv":18396.9,"id":2219}]}]}
{"op":"mcm","clk":"11806162748","pt":1722702588255,"mc":[{"id":"1.231344137","rc":[{"batb":[[0,2.32,2],[1,2.3,351.43],[2,2.28,4]],"ltp":2.3,"tv":18396.9,"id":2219}]}]}
{"op":"mcm","clk":"11806163058","pt":1722702590252,"mc":[{"id":"1.231344137","rc":[{"batb":[[0,2.3,351.43],[1,2.28,4],[2,2.26,4]],"ltp":2.3,"tv":18396.9,"id":2219}]}]}
{"op":"mcm","clk":"11806163309","pt":1722702591652,"mc":[{"id":"1.231344137","rc":[{"trd":[[2.3,18952.41],[2.32,71.41]],"batb":[[0,2.3,8.03]],"ltp":2.3,"tv":19099.64,"id":2219},{"batb":[[0,1.75,57.85]],"batl":[[0,1.76,4],[1,1.77,4],[2,1.78,4]],"ltp":1.78,"tv":42840.36,"id":2120}],"tv":61940.0}]}
{"op":"mcm","clk":"11806163455","pt":1722702592534,"mc":[{"id":"1.231344137","rc":[{"batb":[[0,2.3,4.03]],"ltp":2.3,"tv":19099.64,"id":2219},{"batl":[[0,1.79,27.05],[1,1.77,0],[2,1.78,0]],"ltp":1.78,"tv":42840.36,"id":2120}]}]}
{"op":"mcm","clk":"11806164192","pt":1722702597364,"mc":[{"id":"1.231344137","rc":[{"batb":[[0,2.32,351.4],[1,2.3,4.03],[2,2.28,4]],"ltp":2.3,"tv":19099.64,"id":2219}]}]}
{"op":"mcm","clk":"11806164296","pt":1722702598076,"mc":[{"id":"1.231344137","rc":[{"batb":[[0,1.75,53.85]],"ltp":1.78,"tv":42840.36,"id":2120}]}]}
{"op":"mcm","clk":"11806164836","pt":1722702601073,"mc":[{"id":"1.231344137","rc":[{"trd":[[2.32,774.21]],"batb":[[0,2.3,4.03],[1,2.28,4],[2,2.26,4]],"ltp":2.32,"tv":19802.43,"id":2219}],"tv":62642.8}]}
{"op":"mcm","clk":"11806165876","pt":1722702606762,"mc":[{"id":"1.231344137","rc":[{"batl":[[0,2.32,4],[1,2.34,4]],"ltp":2.32,"tv":19802.43,"id":2219}]}]}
{"op":"mcm","clk":"11806165904","pt":1722702606888,"mc":[{"id":"1.231344137","rc":[{"batl":[[2,2.36,1.4]],"ltp":2.32,"tv":19802.43,"id":2219},{"batb":[[0,1.75,57.85]],"ltp":1.78,"tv":42840.36,"id":2120}]}]}
{"op":"mcm","clk":"11806166341","pt":1722702609471,"mc":[{"id":"1.231344137","rc":[{"batl":[[0,2.32,17.15]],"ltp":2.32,"tv":19802.43,"id":2219}]}]}
{"op":"mcm","clk":"11806166581","pt":1722702610764,"mc":[{"id":"1.231344137","rc":[{"batb":[[0,2.3,355.43]],"batl":[[0,2.32,13.15],[1,2.34,1.4],[2,2.36,0]],"ltp":2.32,"tv":19802.43,"id":2219},{"batb":[[0,1.75,53.85]],"ltp":1.78,"tv":42840.36,"id":2120}]}]}
{"op":"mcm","clk":"11806167076","pt":1722702613365,"mc":[{"id":"1.231344137","rc":[{"trd":[[2.3,19663.27]],"batb":[[0,2.28,4],[1,2.26,4],[2,2.22,33.1]],"batl":[[0,2.3,44.57],[1,2.32,13.15],[2,2.34,1.4]],"ltp":2.3,"tv":20513.29,"id":2219}],"tv":63353.65}]}
{"op":"mcm","clk":"11806167205","pt":1722702614156,"mc":[{"id":"1.231344137","rc":[{"batb":[[0,2.26,4],[1,2.22,33.1],[2,1.82,7]],"batl":[[0,2.3,395.97]],"ltp":2.3,"tv":20513.29,"id":2219}]}]}
{"op":"mcm","clk":"11806168567","pt":1722702622405,"mc":[{"id":"1.231344137","rc":[{"batb":[[0,2.22,33.1],[1,1.82,7],[2,1.41,85.28]],"batl":[[0,2.28,4],[1,2.3,399.97],[2,2.32,13.15]],"ltp":2.3,"tv":20513.29,"id":2219},{"batb":[[0,1.76,4],[1,1.75,53.85],[2,1.48,10]],"ltp":1.78,"tv":42840.36,"id":2120}]}]}
{"op":"mcm","clk":"11806168644","pt":1722702622871,"mc":[{"id":"1.231344137","rc":[{"batl":[[2,2.34,1.4]],"ltp":2.3,"tv":20513.29,"id":2219}]}]}
{"op":"mcm","clk":"11806169011","pt":1722702625194,"mc":[{"id":"1.231344137","rc":[{"batl":[[1,2.3,48.57],[2,2.34,0]],"ltp":2.3,"tv":20513.29,"id":2219}]}]}
{"op":"mcm","clk":"11806170982","pt":1722702637092,"mc":[{"id":"1.231344137","rc":[{"batb":[[0,2.26,4],[1,2.22,33.1],[2,1.82,7]],"ltp":2.3,"tv":20513.29,"id":2219},{"batl":[[0,1.79,31.05]],"ltp":1.78,"tv":42840.36,"id":2120}]}]}
{"op":"mcm","clk":"11806172169","pt":1722702643911,"mc":[{"id":"1.231344137","rc":[{"batb":[[0,1.77,5.24],[1,1.76,4],[2,1.75,53.85]],"ltp":1.78,"tv":42840.36,"id":2120}]}]}
{"op":"mcm","clk":"11806174643","pt":1722702659614,"mc":[{"id":"1.231344137","rc":[{"batb":[[0,2.22,33.1],[1,1.82,7],[2,1.41,85.28]],"ltp":2.3,"tv":20513.29,"id":2219}]}]}
{"op":"mcm","clk":"11806175956","pt":1722702667431,"mc":[{"id":"1.231344137","rc":[{"batb":[[0,2.22,37.1]],"ltp":2.3,"tv":20513.29,"id":2219},{"batl":[[0,1.81,4],[1,1.82,4]],"ltp":1.78,"tv":42840.36,"id":2120}]}]}
{"op":"mcm","clk":"11806176355","pt":1722702669644,"mc":[{"id":"1.231344137","rc":[{"trd":[[2.28,30.95]],"batl":[[0,2.3,48.57],[1,2.3,0]],"ltp":2.28,"tv":20517.29,"id":2219},{"trd":[[1.78,25.62]],"batl":[[0,1.78,12.92],[1,1.81,4],[2,1.82,4]],"ltp":1.78,"tv":42845.48,"id":2120}],"tv":63362.77}]}
{"op":"mcm","clk":"11806178551","pt":1722702682550,"mc":[{"id":"1.231344137","rc":[{"batl":[[0,1.78,16.92]],"ltp":1.78,"tv":42845.48,"id":2120}]}]}
{"op":"mcm","clk":"11806181628","pt":1722702700657,"mc":[{"id":"1.231344137","rc":[{"trd":[[2.28,43.44]],"ltp":2.28,"tv":20529.79,"id":2219},{"trd":[[1.78,41.62]],"batl":[[0,1.81,4.92],[1,1.82,4],[2,1.82,0]],"ltp":1.78,"tv":42861.48,"id":2120}],"tv":63391.27}]}
{"op":"mcm","clk":"11806181715","pt":1722702701137,"mc":[{"id":"1.231344137","rc":[{"batl":[[0,1.81,4]],"ltp":1.78,"tv":42861.48,"id":2120}]}]}
{"op":"mcm","clk":"11806183646","pt":1722702712789,"mc":[{"id":"1.231344137","rc":[{"batb":[[0,1.77,9.24]],"batl":[[0,1.8,9.02],[1,1.81,4],[2,1.82,4]],"ltp":1.78,"tv":42861.48,"id":2120}]}]}
{"op":"mcm","clk":"11806186326","pt":1722702727992,"mc":[{"id":"1.231344137","rc":[{"batb":[[0,2.24,4],[1,2.22,37.1],[2,1.82,7]],"ltp":2.28,"tv":20529.79,"id":2219},{"batl":[[0,1.8,13.02]],"ltp":1.78,"tv":42861.48,"id":2120}]}]}
{"op":"mcm","clk":"11806187014","pt":1722702731795,"mc":[{"id":"1.231344137","rc":[{"batl":[[1,2.32,13.15]],"ltp":2.28,"tv":20529.79,"id":2219}]}]}
{"op":"mcm","clk":"11806187481","pt":1722702734633,"mc":[{"id":"1.231344137","rc":[{"batl":[[0,2.28,166.33],[1,2.3,48.57]],"ltp":2.28,"tv":20529.79,"id":2219},{"batl":[[0,1.8,9.02],[1,1.81,0],[2,1.82,0]],"ltp":1.78,"tv":42861.48,"id":2120}]}]}
{"op":"mcm","clk":"11806187567","pt":1722702735111,"mc":[{"id":"1.231344137","rc":[{"batb":[[0,2.22,33.1],[1,1.82,7],[2,1.41,85.28]],"ltp":2.28,"tv":20529.79,"id":2219},{"batb":[[0,1.77,4]],"ltp":1.78,"tv":42861.48,"id":2120}]}]}
{"op":"mcm","clk":"11806187712","pt":1722702736022,"mc":[{"id":"1.231344137","rc":[{"batl":[[0,2.26,8.17],[1,2.28,166.33],[2,2.3,48.57]],"ltp":2.28,"tv":20529.79,"id":2219}]}]}
{"op":"mcm","clk":"11806188941","pt":1722702743251,"mc":[{"id":"1.231344137","rc":[{"batl":[[0,2.26,12.17]],"ltp":2.28,"tv":20529.79,"id":2219},{"batb":[[0,1.79,4],[1,1.77,4],[2,1.76,4]],"ltp":1.78,"tv":42861.48,"id":2120}]}]}
{"op":"mcm","clk":"11806189862","pt":1722702748655,"mc":[{"id":"1.231344137","rc":[{"batl":[[0,2.26,4],[1,2.3,48.57],[2,2.3,0]],"ltp":2.28,"tv":20529.79,"id":2219}]}]}
{"op":"mcm","clk":"11806189915","pt":1722702748933,"mc":[{"id":"1.231344137","rc":[{"batl":[[0,2.3,48.57],[1,2.3,0]],"ltp":2.28,"tv":20529.79,"id":2219},{"batb":[[0,1.77,4],[1,1.76,4],[2,1.75,53.85]],"ltp":1.78,"tv":42861.48,"id":2120}]}]}
{"op":"mcm","clk":"11806191714","pt":1722702758547,"mc":[{"id":"1.231344137","rc":[{"batb":[[0,2.24,4],[1,2.22,33.1],[2,1.82,7]],"ltp":2.28,"tv":20529.79,"id":2219},{"batl":[[0,1.79,4],[1,1.8,13.02]],"ltp":1.78,"tv":42861.48,"id":2120}]}]}
{"op":"mcm","clk":"11806191798","pt":1722702759060,"mc":[{"id":"1.231344137","rc":[{"batl":[[0,1.8,9.02],[1,1.8,0]],"ltp":1.78,"tv":42861.48,"id":2120}]}]}
{"op":"mcm","clk":"11806193699","pt":1722702769762,"mc":[{"id":"1.231344137","rc":[{"batb":[[0,2.26,39.04],[1,2.24,4],[2,2.22,33.1]],"batl":[[1,2.32,1.42]],"ltp":2.28,"tv":20529.79,"id":2219}]}]}
{"op":"mcm","clk":"11806194356","pt":1722702773651,"mc":[{"id":"1.231344137","rc":[{"batb":[[0,2.26,43.04]],"ltp":2.28,"tv":20529.79,"id":2219},{"batl":[[0,1.79,4],[1,1.8,13.02]],"ltp":1.78,"tv":42861.48,"id":2120}]}]}
{"op":"mcm","clk":"11806194418","pt":1722702773967,"mc":[{"id":"1.231344137","rc":[{"batl":[[0,1.79,9.14]],"ltp":1.78,"tv":42861.48,"id":2120}]}]}
{"op":"mcm","clk":"11806195518","pt":1722702780107,"mc":[{"id":"1.231344137","rc":[{"batb":[[0,1.77,9.16]],"ltp":1.78,"tv":42861.48,"id":2120}]}]}
{"op":"mcm","clk":"11806195756","pt":1722702781388,"mc":[{"id":"1.231344137","rc":[{"batb":[[2,1.82,7]],"ltp":2.28,"tv":20529.79,"id":2219},{"batb":[[2,1.48,10]],"ltp":1.78,"tv":42861.48,"id":2120}]}]}
{"op":"mcm","clk":"11806196051","pt":1722702782993,"mc":[{"id":"1.231344137","rc":[{"batb":[[0,2.26,4]],"ltp":2.28,"tv":20529.79,"id":2219}]}]}
{"op":"mcm","clk":"11806196307","pt":1722702784472,"mc":[{"id":"1.231344137","rc":[{"batl":[[0,1.79,4]],"ltp":1.78,"tv":42861.48,"id":2120}]}]}
{"op":"mcm","clk":"11806196717","pt":1722702786709,"mc":[{"id":"1.231344137","rc":[{"batb":[[2,2.22,33.1]],"ltp":2.28,"tv":20529.79,"id":2219},{"batb":[[2,1.75,53.85]],"batl":[[0,1.8,9.02],[1,1.8,0]],"ltp":1.78,"tv":42861.48,"id":2120}]}]}
{"op":"mcm","clk":"11806196806","pt":1722702787192,"mc":[{"id":"1.231344137","rc":[{"batb":[[0,2.24,4],[1,2.22,33.1],[2,1.82,7]],"ltp":2.28,"tv":20529.79,"id":2219}]}]}
{"op":"mcm","clk":"11806197095","pt":1722702788775,"mc":[{"id":"1.231344137","rc":[{"batb":[[0,2.28,39.04],[1,2.24,4],[2,2.22,33.1]],"ltp":2.28,"tv":20529.79,"id":2219},{"batl":[[0,1.8,13.02]],"ltp":1.78,"tv":42861.48,"id":2120}]}]}
{"op":"mcm","clk":"11806197586","pt":1722702791480,"mc":[{"id":"1.231344137","rc":[{"batb":[[2,1.82,7]],"ltp":2.28,"tv":20529.79,"id":2219},{"batb":[[2,1.48,10]],"ltp":1.78,"tv":42861.48,"id":2120}]}]}
{"op":"mcm","clk":"11806198552","pt":1722702796689,"mc":[{"id":"1.231344137","rc":[{"trd":[[2.24,29.61],[2.28,121.53]],"batb":[[0,2.22,33.1],[1,1.83,10]],"batl":[[0,2.32,1.42],[1,2.32,0]],"ltp":2.24,"tv":20617.4,"id":2219},{"trd":[[1.8,23056.73]],"batb":[[0,1.77,5.16],[2,1.75,53.85]],"batl":[[0,1.8,7.12]],"ltp":1.8,"tv":42863.38,"id":2120}],"tv":63480.78}]}
{"op":"mcm","clk":"11806198703","pt":1722702797508,"mc":[{"id":"1.231344137","rc":[{"batb":[[0,1.76,4],[1,1.75,53.85],[2,1.48,10]],"ltp":1.8,"tv":42863.38,"id":2120}]}]}
{"op":"mcm","clk":"11806199030","pt":1722702799710,"mc":[{"id":"1.231344137","rc":[{"batb":[[1,1.82,7],[2,1.41,85.28]],"ltp":2.24,"tv":20617.4,"id":2219}]}]}
{"op":"mcm","clk":"11806199833","pt":1722702804102,"mc":[{"id":"1.231344137","rc":[{"batb":[[0,2.24,4],[1,2.22,33.1],[2,1.82,7]],"batl":[[0,2.32,4]],"ltp":2.24,"tv":20617.4,"id":2219}]}]}
{"op":"mcm","clk":"11806201529","pt":1722702814139,"mc":[{"id":"1.231344137","rc":[{"batb":[[0,2.28,23.43],[1,2.24,4],[2,2.22,33.1]],"batl":[[1,2.34,1.42]],"ltp":2.24,"tv":20617.4,"id":2219}]}]}
{"op":"mcm","clk":"11806202384","pt":1722702819220,"mc":[{"id":"1.231344137","rc":[{"batb":[[0,2.28,27.43]],"ltp":2.24,"tv":20617.4,"id":2219},{"batl":[[0,1.78,4],[1,1.79,4],[2,1.8,7.12]],"ltp":1.8,"tv":42863.38,"id":2120}]}]}
{"op":"mcm","clk":"11806204233","pt":1722702830443,"mc":[{"id":"1.231344137","rc":[{"trd":[[2.28,179.41]],"batb":[[0,2.24,4],[1,2.22,33.1],[2,1.82,7]],"ltp":2.28,"tv":20675.28,"id":2219},{"trd":[[1.78,45.5]],"batb":[[0,1.76,8.54]],"batl":[[0,1.79,4.12],[1,1.8,7.12],[2,1.8,0]],"ltp":1.78,"tv":42867.26,"id":2120}],"tv":63542.54}]}
{"op":"mcm","clk":"11806204305","pt":1722702830853,"mc":[{"id":"1.231344137","rc":[{"batl":[[0,1.8,7.12],[1,1.8,0]],"ltp":1.78,"tv":42867.26,"id":2120}]}]}
{"op":"mcm","clk":"11806206512","pt":1722702843458,"mc":[{"id":"1.231344137","rc":[{"batb":[[0,2.28,30.45],[1,2.24,4],[2,2.22,33.1]],"ltp":2.28,"tv":20675.28,"id":2219}]}]}
{"op":"mcm","clk":"11806207200","pt":1722702847450,"mc":[{"id":"1.231344137","rc":[{"batb":[[2,1.82,7]],"ltp":2.28,"tv":20675.28,"id":2219},{"batb":[[0,1.76,4.54],[1,1.48,10],[2,1.41,85.28]],"ltp":1.78,"tv":42867.26,"id":2120}]}]}
{"op":"mcm","clk":"11806207368","pt":1722702848549,"mc":[{"id":"1.231344137","rc":[{"batb":[[0,1.48,10],[1,1.41,85.28],[2,1.3,633.33]],"ltp":1.78,"tv":42867.26,"id":2120}]}]}
{"op":"mcm","clk":"11806207475","pt":1722702849136,"mc":[{"id":"1.231344137","rc":[{"batb":[[0,2.3,12],[1,2.28,30.45]],"batl":[[0,3.4,8.97]],"ltp":2.28,"tv":20675.28,"id":2219}]}]}
{"op":"mcm","clk":"11806207851","pt":1722702851463,"mc":[{"id":"1.231344137","rc":[{"batb":[[0,2.3,10]],"ltp":2.28,"tv":20675.28,"id":2219}]}]}
{"op":"mcm","clk":"11806207994","pt":1722702852358,"mc":[{"id":"1.231344137","rc":[{"batb":[[0,2.28,30.45],[1,2.22,33.1]],"ltp":2.28,"tv":20675.28,"id":2219},{"batb":[[0,1.75,53.85],[1,1.48,10],[2,1.41,85.28]],"ltp":1.78,"tv":42867.26,"id":2120}]}]}
{"op":"mcm","clk":"11806208160","pt":1722702853364,"mc":[{"id":"1.231344137","rc":[{"batl":[[0,2.32,13.15]],"ltp":2.28,"tv":20675.28,"id":2219}]}]}
{"op":"mcm","clk":"11806210188","pt":1722702864673,"mc":[{"id":"1.231344137","rc":[{"batb":[[0,2.28,34.45]],"batl":[[0,2.32,17.15]],"ltp":2.28,"tv":20675.28,"id":2219},{"batb":[[0,1.75,57.85]],"batl":[[0,1.79,4],[1,1.8,7.12]],"ltp":1.78,"tv":42867.26,"id":2120}]}]}
{"op":"mcm","clk":"11806212063","pt":1722702875277,"mc":[{"id":"1.231344137","rc":[{"batb":[[0,1.76,5.85],[1,1.75,57.85],[2,1.48,10]],"ltp":1.78,"tv":42867.26,"id":2120}]}]}
{"op":"mcm","clk":"11806212481","pt":1722702877664,"mc":[{"id":"1.231344137","rc":[{"trd":[[2.28,248.12]],"batb":[[0,1.83,10],[1,1.82,7],[2,1.41,85.28]],"ltp":2.28,"tv":20743.99,"id":2219},{"batb":[[0,1.76,9.02],[1,1.75,4]],"batl":[[0,1.8,7.12],[1,1.8,0]],"ltp":1.78,"tv":42867.26,"id":2120}],"tv":63611.26}]}
{"op":"mcm","clk":"11806212888","pt":1722702879924,"mc":[{"id":"1.231344137","rc":[{"batb":[[0,1.76,13.02]],"ltp":1.78,"tv":42867.26,"id":2120}]}]}
{"op":"mcm","clk":"11806213067","pt":1722702880885,"mc":[{"id":"1.231344137","rc":[{"batb":[[0,1.82,7],[1,1.41,85.28],[2,1.3,633.33]],"ltp":2.28,"tv":20743.99,"id":2219}]}]}
{"op":"mcm","clk":"11806213262","pt":1722702881995,"mc":[{"id":"1.231344137","rc":[{"batb":[[0,2.22,33.1],[1,1.82,7],[2,1.41,85.28]],"ltp":2.28,"tv":20743.99,"id":2219},{"batb":[[1,1.75,57.85]],"ltp":1.78,"tv":42867.26,"id":2120}]}]}
{"op":"mcm","clk":"11806214285","pt":1722702887575,"mc":[{"id":"1.231344137","rc":[{"batb":[[0,2.28,34.36],[1,2.22,33.1],[2,1.82,7]],"ltp":2.28,"tv":20743.99,"id":2219}]}]}
{"op":"mcm","clk":"11806215046","pt":1722702892006,"mc":[{"id":"1.231344137","rc":[{"batb":[[1,1.82,7],[2,1.41,85.28]],"ltp":2.28,"tv":20743.99,"id":2219},{"batb":[[1,1.75,4]],"ltp":1.78,"tv":42867.26,"id":2120}]}]}
{"op":"mcm","clk":"11806215606","pt":1722702895091,"mc":[{"id":"1.231344137","rc":[{"batb":[[0,2.28,38.36]],"batl":[[0,2.32,4]],"ltp":2.28,"tv":20743.99,"id":2219},{"batl":[[0,1.78,4],[1,1.79,4],[2,1.8,7.12]],"ltp":1.78,"tv":42867.26,"id":2120}]}]}
{"op":"mcm","clk":"11806216996","pt":1722702902692,"mc":[{"id":"1.231344137","rc":[{"trd":[[2.28,327.87]],"batb":[[0,1.82,7],[1,1.41,85.28],[2,1.3,633.33]],"ltp":2.28,"tv":20823.74,"id":2219},{"trd":[[1.78,49.38]],"batl":[[0,1.79,4.12],[1,1.8,7.12],[2,1.8,0]],"ltp":1.78,"tv":42871.14,"id":2120}],"tv":63694.88}]}
{"op":"mcm","clk":"11806217136","pt":1722702903421,"mc":[{"id":"1.231344137","rc":[{"batb":[[0,1.83,10],[1,1.82,7],[2,1.41,85.28]],"ltp":2.28,"tv":20823.74,"id":2219},{"batl":[[0,1.8,7.12],[1,1.8,0]],"ltp":1.78,"tv":42871.14,"id":2120}]}]}
{"op":"mcm","clk":"11806217735","pt":1722702906543,"mc":[{"id":"1.231344137","rc":[{"batb":[[0,1.82,7],[1,1.41,85.28],[2,1.3,633.33]],"ltp":2.28,"tv":20823.74,"id":2219}]}]}
{"op":"mcm","clk":"11806217855","pt":1722702907094,"mc":[{"id":"1.231344137","rc":[{"batb":[[0,2.22,33.1],[1,1.82,7],[2,1.41,85.28]],"ltp":2.28,"tv":20823.74,"id":2219},{"batb":[[1,1.75,57.85]],"ltp":1.78,"tv":42871.14,"id":2120}]}]}
{"op":"mcm","clk":"11806218473","pt":1722702910418,"mc":[{"id":"1.231344137","rc":[{"batb":[[0,2.24,4],[1,2.22,33.1],[2,1.82,7]],"batl":[[0,2.3,4],[1,2.32,4]],"ltp":2.28,"tv":20823.74,"id":2219},{"batb":[[0,1.77,4],[1,1.76,13.02],[2,1.75,57.85]],"ltp":1.78,"tv":42871.14,"id":2120}]}]}
{"op":"mcm","clk":"11806219312","pt":1722702914816,"mc":[{"id":"1.231344137","rc":[{"batb":[[0,2.28,39.04],[1,2.24,4],[2,2.22,33.1]],"ltp":2.28,"tv":20823.74,"id":2219}]}]}
{"op":"mcm","clk":"11806219348","pt":1722702914978,"mc":[{"id":"1.231344137","rc":[{"batl":[[2,2.34,1.42]],"ltp":2.28,"tv":20823.74,"id":2219}]}]}
{"op":"mcm","clk":"11806219696","pt":1722702917129,"mc":[{"id":"1.231344137","rc":[{"batb":[[2,1.82,7]],"ltp":2.28,"tv":20823.74,"id":2219},{"batb":[[2,1.75,4]],"ltp":1.78,"tv":42871.14,"id":2120}]}]}
{"op":"mcm","clk":"11806220333","pt":1722702920806,"mc":[{"id":"1.231344137","rc":[{"trd":[[2.28,405.87]],"batb":[[0,2.26,10.05]],"ltp":2.28,"tv":20901.74,"id":2219}],"tv":63772.88}]}
{"op":"mcm","clk":"11806220602","pt":1722702922103,"mc":[{"id":"1.231344137","rc":[{"batb":[[2,2.22,33.1]],"ltp":2.28,"tv":20901.74,"id":2219},{"batb":[[2,1.75,57.85]],"ltp":1.78,"tv":42871.14,"id":2120}]}]}
{"op":"mcm","clk":"11806220965","pt":1722702924011,"mc":[{"id":"1.231344137","rc":[{"batb":[[0,2.24,4.05],[1,2.22,33.1],[2,1.82,7]],"ltp":2.28,"tv":20901.74,"id":2219}]}]}
{"op":"mcm","clk":"11806221261","pt":1722702925507,"mc":[{"id":"1.231344137","rc":[{"batl":[[0,2.3,4]],"ltp":2.28,"tv":20901.74,"id":2219}]}]}
{"op":"mcm","clk":"11806222603","pt":1722702932716,"mc":[{"id":"1.231344137","rc":[{"batb":[[0,2.24,4]],"ltp":2.28,"tv":20901.74,"id":2219}]}]}
{"op":"mcm","clk":"11806225394","pt":1722702948748,"mc":[{"id":"1.231344137","rc":[{"batl":[[1,2.38,200.69]],"ltp":2.28,"tv":20901.74,"id":2219}]}]}
{"op":"mcm","clk":"11806229108","pt":1722702968548,"mc":[{"id":"1.231344137","rc":[{"batl":[[1,2.36,179.6],[2,2.38,200.69]],"ltp":2.28,"tv":20901.74,"id":2219}]}]}
{"op":"mcm","clk":"11806229996","pt":1722702973257,"mc":[{"id":"1.231344137","rc":[{"batl":[[1,2.32,13.15],[2,2.36,179.6]],"ltp":2.28,"tv":20901.74,"id":2219}]}]}
{"op":"mcm","clk":"11806236960","pt":1722703009475,"mc":[{"id":"1.231344137","rc":[{"batb":[[0,2.22,33.1],[1,1.82,7],[2,1.41,85.28]],"batl":[[0,2.3,204.69]],"ltp":2.28,"tv":20901.74,"id":2219}]}]}
{"op":"mcm","clk":"11806237084","pt":1722703010100,"mc":[{"id":"1.231344137","rc":[{"batl":[[0,2.28,13.38],[1,2.3,204.69]],"ltp":2.28,"tv":20901.74,"id":2219}]}]}
{"op":"mcm","clk":"11806238271","pt":1722703016792,"mc":[{"id":"1.231344137","rc":[{"batl":[[0,2.28,17.38],[1,2.3,384.29],[2,2.36,0]],"ltp":2.28,"tv":20901.74,"id":2219},{"batb":[[0,1.78,4],[1,1.77,4],[2,1.76,13.02]],"ltp":1.78,"tv":42871.14,"id":2120}]}]}
{"op":"mcm","clk":"11806241123","pt":1722703031541,"mc":[{"id":"1.231344137","rc":[{"batl":[[0,2.26,4],[1,2.28,17.38],[2,2.3,384.29]],"ltp":2.28,"tv":20901.74,"id":2219},{"batb":[[0,1.79,4],[1,1.78,4],[2,1.77,4]],"ltp":1.78,"tv":42871.14,"id":2120}]}]}
{"op":"mcm","clk":"11806251215","pt":1722703086270,"mc":[{"id":"1.231344137","rc":[{"batl":[[2,2.3,204.69]],"ltp":2.28,"tv":20901.74,"id":2219}]}]}
{"op":"mcm","clk":"11806251426","pt":1722703087377,"mc":[{"id":"1.231344137","rc":[{"batl":[[2,2.3,4]],"ltp":2.28,"tv":20901.74,"id":2219}]}]}
{"op":"mcm","clk":"11806252364","pt":1722703092194,"mc":[{"id":"1.231344137","rc":[{"batb":[[0,2.24,4],[1,2.22,33.1],[2,1.82,7]],"ltp":2.28,"tv":20901.74,"id":2219}]}]}
{"op":"mcm","clk":"11806267908","pt":1722703172632,"mc":[{"id":"1.231344137","rc":[{"trd":[[1.8,23070.79]],"batl":[[0,1.8,0.09]],"ltp":1.8,"tv":42885.19,"id":2120}],"tv":63786.94}]}
{"op":"mcm","clk":"11806269879","pt":1722703182949,"mc":[{"id":"1.231344137","rc":[{"batl":[[0,1.81,4.09]],"ltp":1.8,"tv":42885.19,"id":2120}]}]}
{"op":"mcm","clk":"11806273220","pt":1722703200831,"mc":[{"id":"1.231344137","rc":[{"trd":[[2.24,37.41]],"batb":[[0,2.22,33.2],[1,1.82,7],[2,1.41,85.28]],"ltp":2.24,"tv":20909.54,"id":2219}],"tv":63794.74}]}
{"op":"mcm","clk":"11806275690","pt":1722703213186,"mc":[{"id":"1.231344137","rc":[{"batb":[[0,2.22,37.2]],"ltp":2.24,"tv":20909.54,"id":2219}]}]}
{"op":"mcm","clk":"11806277030","pt":1722703219973,"mc":[{"id":"1.231344137","rc":[{"trd":[[1.8,23070.97],[1.81,2831.85]],"batl":[[0,1.81,0.19]],"ltp":1.81,"tv":42893.0,"id":2120}],"tv":63802.54}]}
{"op":"mcm","clk":"11806278496","pt":1722703228281,"mc":[{"id":"1.231344137","rc":[{"batl":[[0,1.82,4.19]],"ltp":1.81,"tv":42893.0,"id":2120}]}]}
{"op":"mcm","clk":"11806279528","pt":1722703233797,"mc":[{"id":"1.231344137","rc":[{"trd":[[2.22,48.39],[2.24,37.51]],"batb":[[0,2.14,35.43],[1,1.83,10],[2,1.82,7]],"ltp":2.22,"tv":20943.24,"id":2219},{"trd":[[1.81,2832.35],[1.82,67.02]],"ltp":1.82,"tv":42942.48,"id":2120}],"tv":63885.73}]}
{"op":"mcm","clk":"11806279573","pt":1722703234012,"mc":[{"id":"1.231344137","rc":[{"batb":[[0,1.76,9.02],[1,1.75,53.85],[2,1.48,10]],"ltp":1.82,"tv":42942.48,"id":2120}]}]}
{"op":"mcm","clk":"11806279908","pt":1722703235773,"mc":[{"id":"1.231344137","rc":[{"batl":[[1,2.28,4],[2,2.3,17.26]],"ltp":2.22,"tv":20943.24,"id":2219}]}]}
{"op":"mcm","clk":"11806279945","pt":1722703235978,"mc":[{"id":"1.231344137","rc":[{"batl":[[0,2.3,13.26],[1,2.28,0],[2,2.3,0]],"ltp":2.22,"tv":20943.24,"id":2219}]}]}
{"op":"mcm","clk":"11806280124","pt":1722703236912,"mc":[{"id":"1.231344137","rc":[{"batb":[[1,1.82,7],[2,1.41,85.28]],"ltp":2.22,"tv":20943.24,"id":2219}]}]}
{"op":"mcm","clk":"11806280334","pt":1722703237992,"mc":[{"id":"1.231344137","rc":[{"batl":[[0,2.32,13.15]],"ltp":2.22,"tv":20943.24,"id":2219}]}]}
{"op":"mcm","clk":"11806283085","pt":1722703252801,"mc":[{"id":"1.231344137","rc":[{"batl":[[0,1.87,9.02]],"ltp":1.82,"tv":42942.48,"id":2120}]}]}
{"op":"mcm","clk":"11806283127","pt":1722703253005,"mc":[{"id":"1.231344137","rc":[{"batb":[[0,2.16,10],[1,2.14,35.43],[2,1.82,7]],"ltp":2.22,"tv":20943.24,"id":2219}]}]}
{"op":"mcm","clk":"11806283735","pt":1722703256442,"mc":[{"id":"1.231344137","rc":[{"batb":[[0,2.14,35.43],[1,1.82,7],[2,1.41,85.28]],"ltp":2.22,"tv":20943.24,"id":2219}]}]}
{"op":"mcm","clk":"11806286230","pt":1722703269815,"mc":[{"id":"1.231344137","rc":[{"batb":[[0,2.16,10],[1,2.14,35.43],[2,1.82,7]],"ltp":2.22,"tv":20943.24,"id":2219}]}]}
{"op":"mcm","clk":"11806286413","pt":1722703270817,"mc":[{"id":"1.231344137","rc":[{"batb":[[0,1.76,14.17]],"ltp":1.82,"tv":42942.48,"id":2120}]}]}
{"op":"mcm","clk":"11806286829","pt":1722703273120,"mc":[{"id":"1.231344137","rc":[{"batb":[[0,2.14,35.43],[1,1.82,7],[2,1.41,85.28]],"ltp":2.22,"tv":20943.24,"id":2219}]}]}
{"op":"mcm","clk":"11806287153","pt":1722703274927,"mc":[{"id":"1.231344137","rc":[{"batl":[[0,2.28,3.9],[1,2.32,13.15]],"ltp":2.22,"tv":20943.24,"id":2219}]}]}
{"op":"mcm","clk":"11806287766","pt":1722703278005,"mc":[{"id":"1.231344137","rc":[{"batb":[[0,2.16,10],[1,2.14,35.43],[2,1.82,7]],"ltp":2.22,"tv":20943.24,"id":2219}]}]}
{"op":"mcm","clk":"11806288407","pt":1722703281350,"mc":[{"id":"1.231344137","rc":[{"batb":[[0,2.14,35.43],[1,1.82,7],[2,1.41,85.28]],"ltp":2.22,"tv":20943.24,"id":2219}]}]}
{"op":"mcm","clk":"11806290552","pt":1722703292384,"mc":[{"id":"1.231344137","rc":[{"batb":[[0,2.16,10],[1,2.14,35.43],[2,1.82,7]],"ltp":2.22,"tv":20943.24,"id":2219}]}]}
{"op":"mcm","clk":"11806291211","pt":1722703295769,"mc":[{"id":"1.231344137","rc":[{"batb":[[0,2.14,35.43],[1,1.82,7],[2,1.41,85.28]],"ltp":2.22,"tv":20943.24,"id":2219}]}]}
{"op":"mcm","clk":"11806293054","pt":1722703306099,"mc":[{"id":"1.231344137","rc":[{"batb":[[0,2.16,10],[1,2.14,35.43],[2,1.82,7]],"batl":[[0,2.32,13.15],[1,2.32,0]],"ltp":2.22,"tv":20943.24,"id":2219}]}]}
{"op":"mcm","clk":"11806293495","pt":1722703308482,"mc":[{"id":"1.231344137","rc":[{"batb":[[0,2.24,19.52],[1,2.16,10],[2,2.14,35.43]],"batl":[[1,2.34,1.48]],"ltp":2.22,"tv":20943.24,"id":2219}]}]}
{"op":"mcm","clk":"11806293674","pt":1722703309489,"mc":[{"id":"1.231344137","rc":[{"batb":[[1,2.14,35.43],[2,1.82,7]],"ltp":2.22,"tv":20943.24,"id":2219}]}]}
{"op":"mcm","clk":"11806295387","pt":1722703318918,"mc":[{"id":"1.231344137","rc":[{"batb":[[0,2.24,23.52]],"batl":[[0,2.3,4],[1,2.32,17.15],[2,2.34,1.48]],"ltp":2.22,"tv":20943.24,"id":2219},{"batb":[[0,1.76,18.17]],"batl":[[0,1.81,4],[1,1.87,9.02]],"ltp":1.82,"tv":42942.48,"id":2120}]}]}
{"op":"mcm","clk":"11806299631","pt":1722703341323,"mc":[{"id":"1.231344137","rc":[{"batb":[[0,2.26,7.81],[1,2.24,23.52],[2,2.14,35.43]],"ltp":2.22,"tv":20943.24,"id":2219}]}]}
{"op":"mcm","clk":"11806301064","pt":1722703349131,"mc":[{"id":"1.231344137","rc":[{"batb":[[0,2.26,11.81]],"ltp":2.22,"tv":20943.24,"id":2219},{"batb":[[0,1.77,4],[1,1.76,18.17],[2,1.75,53.85]],"batl":[[0,1.8,4],[1,1.81,4],[2,1.87,9.02]],"ltp":1.82,"tv":42942.48,"id":2120}]}]}
{"op":"mcm","clk":"11806302863","pt":1722703358450,"mc":[{"id":"1.231344137","rc":[{"trd":[[2.26,37.42]],"batb":[[0,2.24,23.62],[1,2.14,35.43],[2,1.82,7]],"ltp":2.26,"tv":20966.66,"id":2219}],"tv":63909.15}]}
{"op":"mcm","clk":"11806308429","pt":1722703387668,"mc":[{"id":"1.231344137","rc":[{"batb":[[0,2.26,15.72],[1,2.24,23.52],[2,2.14,35.43]],"ltp":2.26,"tv":20966.66,"id":2219}]}]}
{"op":"mcm","clk":"11806316926","pt":1722703437778,"mc":[{"id":"1.231344137","rc":[{"batb":[[0,2.28,3.9],[1,2.26,15.72],[2,2.24,23.52]],"ltp":2.26,"tv":20966.66,"id":2219}]}]}
{"op":"mcm","clk":"11806317235","pt":1722703439745,"mc":[{"id":"1.231344137","rc":[{"batl":[[0,1.79,4],[1,1.8,4],[2,1.81,4]],"ltp":1.82,"tv":42942.48,"id":2120}]}]}
{"op":"mcm","clk":"11806323540","pt":1722703475687,"mc":[{"id":"1.231344137","rc":[{"batb":[[0,2.26,15.72],[1,2.24,23.52],[2,2.14,35.43]],"ltp":2.26,"tv":20966.66,"id":2219}]}]}
{"op":"mcm","clk":"11806325737","pt":1722703488804,"mc":[{"id":"1.231344137","rc":[{"trd":[[2.26,71.88]],"batb":[[0,2.24,23.52],[1,2.14,35.43],[2,1.82,7]],"ltp":2.26,"tv":21001.12,"id":2219},{"trd":[[1.79,15896.8]],"batl":[[0,1.8,4.18],[1,1.81,4],[2,1.87,9.02]],"ltp":1.79,"tv":42946.3,"id":2120}],"tv":63947.43}]}
{"op":"mcm","clk":"11806325840","pt":1722703489436,"mc":[{"id":"1.231344137","rc":[{"batl":[[0,1.8,4]],"ltp":1.79,"tv":42946.3,"id":2120}]}]}
{"op":"mcm","clk":"11806328254","pt":1722703503441,"mc":[{"id":"1.231344137","rc":[{"batb":[[0,2.26,11.71],[1,2.24,23.52],[2,2.14,35.43]],"ltp":2.26,"tv":21001.12,"id":2219}]}]}
{"op":"mcm","clk":"11806330533","pt":1722703515260,"mc":[{"id":"1.231344137","rc":[{"batb":[[0,2.26,15.71]],"ltp":2.26,"tv":21001.12,"id":2219}]}]}
{"op":"mcm","clk":"11806332365","pt":1722703525538,"mc":[{"id":"1.231344137","rc":[{"trd":[[2.26,103.11]],"batb":[[0,2.24,23.62],[1,2.14,35.43],[2,1.82,7]],"ltp":2.26,"tv":21032.35,"id":2219}],"tv":63978.66}]}
{"op":"mcm","clk":"11806333755","pt":1722703534070,"mc":[{"id":"1.231344137","rc":[{"batb":[[0,2.26,15.72],[1,2.24,23.52],[2,2.14,35.43]],"ltp":2.26,"tv":21032.35,"id":2219}]}]}
{"op":"mcm","clk":"11806341183","pt":1722703575736,"mc":[{"id":"1.231344137","rc":[{"trd":[[2.26,134.35]],"batb":[[0,2.24,23.62],[1,2.14,35.43],[2,1.82,7]],"ltp":2.26,"tv":21063.59,"id":2219}],"tv":64009.89}]}
{"op":"mcm","clk":"11806342845","pt":1722703584437,"mc":[{"id":"1.231344137","rc":[{"batb":[[0,2.28,23.43],[1,2.24,23.62],[2,2.14,35.43]],"ltp":2.26,"tv":21063.59,"id":2219}]}]}
{"op":"mcm","clk":"11806343005","pt":1722703585135,"mc":[{"id":"1.231344137","rc":[{"batb":[[2,1.82,7]],"ltp":2.26,"tv":21063.59,"id":2219},{"batb":[[2,1.48,10]],"ltp":1.79,"tv":42946.3,"id":2120}]}]}
{"op":"mcm","clk":"11806343382","pt":1722703587219,"mc":[{"id":"1.231344137","rc":[{"batb":[[1,1.76,13.02]],"ltp":1.79,"tv":42946.3,"id":2120}]}]}
{"op":"mcm","clk":"11806343981","pt":1722703590837,"mc":[{"id":"1.231344137","rc":[{"batb":[[0,2.28,27.43]],"ltp":2.26,"tv":21063.59,"id":2219},{"batl":[[0,1.79,4],[1,1.8,4],[2,1.81,4]],"ltp":1.79,"tv":42946.3,"id":2120}]}]}
{"op":"mcm","clk":"11806344811","pt":1722703595451,"mc":[{"id":"1.231344137","rc":[{"trd":[[2.28,460.52]],"batb":[[0,2.24,23.72],[1,1.82,7],[2,1.41,85.28]],"ltp":2.28,"tv":21118.24,"id":2219}],"tv":64064.55}]}
{"op":"mcm","clk":"11806344956","pt":1722703595938,"mc":[{"id":"1.231344137","rc":[{"batb":[[0,2.24,23.62]],"ltp":2.28,"tv":21118.24,"id":2219},{"batl":[[0,1.8,4],[1,1.81,4],[2,1.87,9.02]],"ltp":1.79,"tv":42946.3,"id":2120}]}]}
{"op":"mcm","clk":"11806345783","pt":1722703600038,"mc":[{"id":"1.231344137","rc":[{"batb":[[1,2.14,35.43],[2,1.82,7]],"ltp":2.28,"tv":21118.24,"id":2219},{"batb":[[2,1.75,53.85]],"ltp":1.79,"tv":42946.3,"id":2120}]}]}
{"op":"mcm","clk":"11806347007","pt":1722703606781,"mc":[{"id":"1.231344137","rc":[{"batb":[[0,2.28,23.43],[1,2.24,23.62],[2,2.14,35.43]],"ltp":2.28,"tv":21118.24,"id":2219}]}]}
{"op":"mcm","clk":"11806347731","pt":1722703610163,"mc":[{"id":"1.231344137","rc":[{"batb":[[2,1.82,7]],"ltp":2.28,"tv":21118.24,"id":2219},{"batb":[[2,1.48,10]],"ltp":1.79,"tv":42946.3,"id":2120}]}]}
{"op":"mcm","clk":"11806348862","pt":1722703616276,"mc":[{"id":"1.231344137","rc":[{"trd":[[2.28,507.38]],"batb":[[0,2.24,23.62],[1,1.82,7],[2,1.41,85.28]],"ltp":2.28,"tv":21165.1,"id":2219}],"tv":64111.4}]}
{"op":"mcm","clk":"11806349538","pt":1722703620095,"mc":[{"id":"1.231344137","rc":[{"batb":[[1,2.14,35.43],[2,1.82,7]],"ltp":2.28,"tv":21165.1,"id":2219},{"batb":[[2,1.75,53.85]],"ltp":1.79,"tv":42946.3,"id":2120}]}]}
{"op":"mcm","clk":"11806350289","pt":1722703624419,"mc":[{"id":"1.231344137","rc":[{"batb":[[0,2.28,23.43],[1,2.24,23.62],[2,2.14,35.43]],"ltp":2.28,"tv":21165.1,"id":2219}]}]}
{"op":"mcm","clk":"11806350453","pt":1722703625250,"mc":[{"id":"1.231344137","rc":[{"batb":[[2,1.82,7]],"ltp":2.28,"tv":21165.1,"id":2219},{"batb":[[2,1.48,10]],"ltp":1.79,"tv":42946.3,"id":2120}]}]}
{"op":"mcm","clk":"11806352317","pt":1722703636174,"mc":[{"id":"1.231344137","rc":[{"batb":[[0,2.28,27.43]],"ltp":2.28,"tv":21165.1,"id":2219},{"batl":[[0,1.79,4],[1,1.8,4],[2,1.81,4]],"ltp":1.79,"tv":42946.3,"id":2120}]}]}
{"op":"mcm","clk":"11806353218","pt":1722703641316,"mc":[{"id":"1.231344137","rc":[{"trd":[[2.28,562.03]],"batb":[[0,2.24,23.72],[1,1.82,7],[2,1.41,85.28]],"ltp":2.28,"tv":21219.75,"id":2219}],"tv":64166.06}]}
{"op":"mcm","clk":"11806353338","pt":1722703642001,"mc":[{"id":"1.231344137","rc":[{"batb":[[0,2.24,23.62]],"ltp":2.28,"tv":21219.75,"id":2219},{"batl":[[0,1.8,4],[1,1.81,4],[2,1.87,9.02]],"ltp":1.79,"tv":42946.3,"id":2120}]}]}
{"op":"mcm","clk":"11806353900","pt":1722703645230,"mc":[{"id":"1.231344137","rc":[{"batb":[[1,2.14,35.43],[2,1.82,7]],"ltp":2.28,"tv":21219.75,"id":2219},{"batb":[[2,1.75,53.85]],"ltp":1.79,"tv":42946.3,"id":2120}]}]}
{"op":"mcm","clk":"11806355563","pt":1722703654516,"mc":[{"id":"1.231344137","rc":[{"batb":[[0,2.28,23.43],[1,2.24,23.62],[2,2.14,35.43]],"ltp":2.28,"tv":21219.75,"id":2219}]}]}
{"op":"mcm","clk":"11806355709","pt":1722703655317,"mc":[{"id":"1.231344137","rc":[{"batb":[[2,1.82,7]],"ltp":2.28,"tv":21219.75,"id":2219},{"batb":[[2,1.48,10]],"ltp":1.79,"tv":42946.3,"id":2120}]}]}
{"op":"mcm","clk":"11806356443","pt":1722703659499,"mc":[{"id":"1.231344137","rc":[{"trd":[[2.28,608.89]],"batb":[[0,2.24,23.62],[1,1.82,7],[2,1.41,85.28]],"ltp":2.28,"tv":21266.61,"id":2219}],"tv":64212.91}]}
{"op":"mcm","clk":"11806356599","pt":1722703660309,"mc":[{"id":"1.231344137","rc":[{"batb":[[1,2.14,35.43],[2,1.82,7]],"ltp":2.28,"tv":21266.61,"id":2219},{"batb":[[2,1.75,53.85]],"ltp":1.79,"tv":42946.3,"id":2120}]}]}
{"op":"mcm","clk":"11806357544","pt":1722703665316,"mc":[{"id":"1.231344137","rc":[{"batb":[[0,2.28,23.43],[1,2.24,23.62]],"ltp":2.28,"tv":21266.61,"id":2219},{"batb":[[2,1.48,10]],"ltp":1.79,"tv":42946.3,"id":2120}]}]}
{"op":"mcm","clk":"11806357760","pt":1722703666432,"mc":[{"id":"1.231344137","rc":[{"batb":[[0,2.28,27.43]],"ltp":2.28,"tv":21266.61,"id":2219},{"batl":[[0,1.79,4],[1,1.8,4],[2,1.81,4]],"ltp":1.79,"tv":42946.3,"id":2120}]}]}
{"op":"mcm","clk":"11806359022","pt":1722703673149,"mc":[{"id":"1.231344137","rc":[{"trd":[[2.28,663.54]],"batb":[[0,2.24,23.62],[1,1.82,7],[2,1.41,85.28]],"ltp":2.28,"tv":21321.27,"id":2219},{"batl":[[0,1.8,4],[1,1.81,4],[2,1.87,9.02]],"ltp":1.79,"tv":42946.3,"id":2120}],"tv":64267.57}]}
{"op":"mcm","clk":"11806359426","pt":1722703675305,"mc":[{"id":"1.231344137","rc":[{"batb":[[1,2.14,35.43],[2,1.82,7]],"ltp":2.28,"tv":21321.27,"id":2219},{"batb":[[2,1.75,53.85]],"ltp":1.79,"tv":42946.3,"id":2120}]}]}
{"op":"mcm","clk":"11806360027","pt":1722703678521,"mc":[{"id":"1.231344137","rc":[{"batb":[[0,2.28,23.43],[1,2.24,23.62],[2,2.14,35.43]],"ltp":2.28,"tv":21321.27,"id":2219}]}]}
{"op":"mcm","clk":"11806360354","pt":1722703680324,"mc":[{"id":"1.231344137","rc":[{"batb":[[2,1.82,7]],"ltp":2.28,"tv":21321.27,"id":2219},{"batb":[[2,1.48,10]],"ltp":1.79,"tv":42946.3,"id":2120}]}]}
{"op":"mcm","clk":"11806360580","pt":1722703681652,"mc":[{"id":"1.231344137","rc":[{"batb":[[0,2.28,27.43]],"ltp":2.28,"tv":21321.27,"id":2219},{"batl":[[0,1.79,4],[1,1.8,4],[2,1.81,4]],"ltp":1.79,"tv":42946.3,"id":2120}]}]}
{"op":"mcm","clk":"11806360707","pt":1722703682348,"mc":[{"id":"1.231344137","rc":[{"trd":[[2.28,710.4]],"batb":[[0,2.28,4]],"ltp":2.28,"tv":21368.12,"id":2219}],"tv":64314.42}]}
{"op":"mcm","clk":"11806360796","pt":1722703682949,"mc":[{"id":"1.231344137","rc":[{"batb":[[0,2.24,23.62],[1,1.82,7],[2,1.41,85.28]],"ltp":2.28,"tv":21368.12,"id":2219},{"batl":[[0,1.8,4],[1,1.81,4],[2,1.87,9.02]],"ltp":1.79,"tv":42946.3,"id":2120}]}]}
{"op":"mcm","clk":"11806361242","pt":1722703685339,"mc":[{"id":"1.231344137","rc":[{"batb":[[1,2.14,35.43],[2,1.82,7]],"ltp":2.28,"tv":21368.12,"id":2219},{"batb":[[2,1.75,53.85]],"ltp":1.79,"tv":42946.3,"id":2120}]}]}
{"op":"mcm","clk":"11806362671","pt":1722703693240,"mc":[{"id":"1.231344137","rc":[{"batb":[[0,2.28,23.43],[1,2.24,23.62],[2,2.14,35.43]],"ltp":2.28,"tv":21368.12,"id":2219}]}]}
{"op":"mcm","clk":"11806363096","pt":1722703695570,"mc":[{"id":"1.231344137","rc":[{"batb":[[2,1.82,7]],"ltp":2.28,"tv":21368.12,"id":2219},{"batb":[[2,1.48,10]],"ltp":1.79,"tv":42946.3,"id":2120}]}]}
{"op":"mcm","clk":"11806363293","pt":1722703696779,"mc":[{"id":"1.231344137","rc":[{"batb":[[0,2.28,27.43]],"ltp":2.28,"tv":21368.12,"id":2219},{"batl":[[0,1.79,4],[1,1.8,4],[2,1.81,4]],"ltp":1.79,"tv":42946.3,"id":2120}]}]}
{"op":"mcm","clk":"11806364351","pt":1722703702751,"mc":[{"id":"1.231344137","rc":[{"trd":[[2.28,765.05]],"batb":[[0,2.24,23.62],[1,1.82,7],[2,1.41,85.28]],"ltp":2.28,"tv":21422.78,"id":2219},{"batl":[[0,1.8,4],[1,1.81,4],[2,1.87,9.02]],"ltp":1.79,"tv":42946.3,"id":2120}],"tv":64369.08}]}
{"op":"mcm","clk":"11806364912","pt":1722703705440,"mc":[{"id":"1.231344137","rc":[{"batb":[[1,2.14,35.43],[2,1.82,7]],"ltp":2.28,"tv":21422.78,"id":2219},{"batb":[[2,1.75,53.85]],"ltp":1.79,"tv":42946.3,"id":2120}]}]}
{"op":"mcm","clk":"11806365478","pt":1722703708381,"mc":[{"id":"1.231344137","rc":[{"batb":[[0,2.28,23.43],[1,2.24,23.62],[2,2.14,35.43]],"ltp":2.28,"tv":21422.78,"id":2219}]}]}
{"op":"mcm","clk":"11806365868","pt":1722703710449,"mc":[{"id":"1.231344137","rc":[{"batb":[[2,1.82,7]],"ltp":2.28,"tv":21422.78,"id":2219},{"batb":[[2,1.48,10]],"ltp":1.79,"tv":42946.3,"id":2120}]}]}
{"op":"mcm","clk":"11806366175","pt":1722703711863,"mc":[{"id":"1.231344137","rc":[{"batb":[[0,2.28,27.43]],"ltp":2.28,"tv":21422.78,"id":2219},{"batl":[[0,1.79,4],[1,1.8,4],[2,1.81,4]],"ltp":1.79,"tv":42946.3,"id":2120}]}]}
{"op":"mcm","clk":"11806366679","pt":1722703714767,"mc":[{"id":"1.231344137","rc":[{"trd":[[2.28,819.71]],"batb":[[0,2.24,23.72],[1,1.82,7],[2,1.41,85.28]],"ltp":2.28,"tv":21477.43,"id":2219}],"tv":64423.74}]}
{"op":"mcm","clk":"11806366796","pt":1722703715448,"mc":[{"id":"1.231344137","rc":[{"batb":[[0,2.24,23.62],[1,2.14,35.43],[2,1.82,7]],"ltp":2.28,"tv":21477.43,"id":2219},{"batb":[[2,1.75,53.85]],"batl":[[0,1.8,4],[1,1.81,4],[2,1.87,9.02]],"ltp":1.79,"tv":42946.3,"id":2120}]}]}
{"op":"mcm","clk":"11806367811","pt":1722703721154,"mc":[{"id":"1.231344137","rc":[{"batb":[[0,2.28,23.43],[1,2.24,23.62],[2,2.14,35.43]],"ltp":2.28,"tv":21477.43,"id":2219}]}]}
{"op":"mcm","clk":"11806368596","pt":1722703725672,"mc":[{"id":"1.231344137","rc":[{"batb":[[2,1.82,7]],"ltp":2.28,"tv":21477.43,"id":2219},{"batb":[[2,1.48,10]],"ltp":1.79,"tv":42946.3,"id":2120}]}]}
{"op":"mcm","clk":"11806368832","pt":1722703726964,"mc":[{"id":"1.231344137","rc":[{"batl":[[0,1.79,4],[1,1.8,4],[2,1.81,4]],"ltp":1.79,"tv":42946.3,"id":2120}]}]}
{"op":"mcm","clk":"11806372454","pt":1722703747310,"mc":[{"id":"1.231344137","rc":[{"trd":[[2.28,866.57]],"batb":[[0,2.24,23.62],[1,1.82,7],[2,1.41,85.28]],"ltp":2.28,"tv":21524.29,"id":2219},{"batl":[[0,1.8,4],[1,1.81,4],[2,1.87,9.02]],"ltp":1.79,"tv":42946.3,"id":2120}],"tv":64470.59}]}
{"op":"mcm","clk":"11806373347","pt":1722703750643,"mc":[{"id":"1.231344137","rc":[{"batb":[[1,2.14,35.43],[2,1.82,7]],"ltp":2.28,"tv":21524.29,"id":2219},{"batb":[[2,1.75,53.85]],"ltp":1.79,"tv":42946.3,"id":2120}]}]}
{"op":"mcm","clk":"11806374661","pt":1722703757900,"mc":[{"id":"1.231344137","rc":[{"batb":[[0,2.28,31.24],[1,2.24,23.62],[2,2.14,35.43]],"ltp":2.28,"tv":21524.29,"id":2219}]}]}
{"op":"mcm","clk":"11806375171","pt":1722703760690,"mc":[{"id":"1.231344137","rc":[{"batb":[[2,1.82,7]],"ltp":2.28,"tv":21524.29,"id":2219},{"batb":[[2,1.48,10]],"ltp":1.79,"tv":42946.3,"id":2120}]}]}
{"op":"mcm","clk":"11806377296","pt":1722703772515,"mc":[{"id":"1.231344137","rc":[{"batl":[[0,1.79,4],[1,1.8,4],[2,1.81,4]],"ltp":1.79,"tv":42946.3,"id":2120}]}]}
{"op":"mcm","clk":"11806379166","pt":1722703783741,"mc":[{"id":"1.231344137","rc":[{"trd":[[2.28,929.04]],"batb":[[0,2.24,23.62],[1,1.82,7],[2,1.41,85.28]],"ltp":2.28,"tv":21586.76,"id":2219},{"batl":[[0,1.8,4],[1,1.81,4],[2,1.87,9.02]],"ltp":1.79,"tv":42946.3,"id":2120}],"tv":64533.06}]}
{"op":"mcm","clk":"11806379516","pt":1722703785842,"mc":[{"id":"1.231344137","rc":[{"batb":[[1,2.14,35.43],[2,1.82,7]],"ltp":2.28,"tv":21586.76,"id":2219},{"batb":[[2,1.75,53.85]],"ltp":1.79,"tv":42946.3,"id":2120}]}]}
{"op":"mcm","clk":"11806380397","pt":1722703790934,"mc":[{"id":"1.231344137","rc":[{"batb":[[0,2.28,23.43],[1,2.24,23.62],[2,2.14,35.43]],"ltp":2.28,"tv":21586.76,"id":2219}]}]}
{"op":"mcm","clk":"11806381246","pt":1722703796036,"mc":[{"id":"1.231344137","rc":[{"batb":[[2,1.82,7]],"ltp":2.28,"tv":21586.76,"id":2219},{"batb":[[2,1.48,10]],"ltp":1.79,"tv":42946.3,"id":2120}]}]}
{"op":"mcm","clk":"11806382376","pt":1722703802769,"mc":[{"id":"1.231344137","rc":[{"batl":[[0,1.79,4],[1,1.8,4],[2,1.81,4]],"ltp":1.79,"tv":42946.3,"id":2120}]}]}
{"op":"mcm","clk":"11806385256","pt":1722703818699,"mc":[{"id":"1.231344137","rc":[{"trd":[[2.26,137.52],[2.28,975.89]],"batb":[[0,2.24,23.52],[1,1.82,7],[2,1.41,85.28]],"batl":[[0,2.3,4.63]],"ltp":2.26,"tv":21636.78,"id":2219},{"trd":[[1.79,15900.8]],"batl":[[0,1.8,4],[1,1.81,4],[2,1.87,9.02]],"ltp":1.79,"tv":42950.3,"id":2120}],"tv":64587.09}]}
{"op":"mcm","clk":"11806385731","pt":1722703821079,"mc":[{"id":"1.231344137","rc":[{"batb":[[1,2.14,35.43],[2,1.82,7]],"ltp":2.26,"tv":21636.78,"id":2219},{"batb":[[2,1.75,53.85]],"ltp":1.79,"tv":42950.3,"id":2120}]}]}
{"op":"mcm","clk":"11806385963","pt":1722703822292,"mc":[{"id":"1.231344137","rc":[{"batl":[[0,2.3,4]],"ltp":2.26,"tv":21636.78,"id":2219}]}]}
{"op":"mcm","clk":"11806387666","pt":1722703832071,"mc":[{"id":"1.231344137","rc":[{"batb":[[0,2.28,23.43],[1,2.24,23.52],[2,2.14,35.43]],"ltp":2.26,"tv":21636.78,"id":2219}]}]}
{"op":"mcm","clk":"11806387821","pt":1722703832962,"mc":[{"id":"1.231344137","rc":[{"batl":[[0,1.79,4],[1,1.8,4],[2,1.81,4]],"ltp":1.79,"tv":42950.3,"id":2120}]}]}
{"op":"mcm","clk":"11806388354","pt":1722703836112,"mc":[{"id":"1.231344137","rc":[{"batb":[[2,1.82,7]],"ltp":2.26,"tv":21636.78,"id":2219},{"batb":[[2,1.48,10]],"ltp":1.79,"tv":42950.3,"id":2120}]}]}
{"op":"mcm","clk":"11806391026","pt":1722703851185,"mc":[{"id":"1.231344137","rc":[{"trd":[[2.26,140.69],[2.28,1022.74]],"batb":[[0,2.24,23.52],[1,2.14,35.43]],"batl":[[0,2.3,4.73]],"ltp":2.26,"tv":21686.8,"id":2219},{"trd":[[1.79,15904.8]],"batb":[[2,1.75,53.85]],"batl":[[0,1.8,4],[1,1.81,4],[2,1.87,9.02]],"ltp":1.79,"tv":42954.3,"id":2120}],"tv":64641.11}]}
{"op":"mcm","clk":"11806391502","pt":1722703854064,"mc":[{"id":"1.231344137","rc":[{"batl":[[0,2.3,4]],"ltp":2.26,"tv":21686.8,"id":2219}]}]}
{"op":"mcm","clk":"11806392700","pt":1722703861804,"mc":[{"id":"1.231344137","rc":[{"batb":[[0,2.28,23.43],[1,2.24,23.52],[2,2.14,35.43]],"ltp":2.26,"tv":21686.8,"id":2219}]}]}
{"op":"mcm","clk":"11806392929","pt":1722703863200,"mc":[{"id":"1.231344137","rc":[{"batl":[[0,1.79,4],[1,1.8,4],[2,1.81,4]],"ltp":1.79,"tv":42954.3,"id":2120}]}]}
{"op":"mcm","clk":"11806393456","pt":1722703866180,"mc":[{"id":"1.231344137","rc":[{"batb":[[2,1.82,7]],"ltp":2.26,"tv":21686.8,"id":2219},{"batb":[[2,1.48,10]],"ltp":1.79,"tv":42954.3,"id":2120}]}]}
{"op":"mcm","clk":"11806395277","pt":1722703876289,"mc":[{"id":"1.231344137","rc":[{"trd":[[2.26,143.86],[2.28,1069.6]],"batb":[[0,2.24,23.52],[1,2.14,35.43]],"batl":[[0,2.3,4.73]],"ltp":2.26,"tv":21736.83,"id":2219},{"trd":[[1.79,15908.8]],"batb":[[2,1.75,53.85]],"batl":[[0,1.8,4],[1,1.81,4],[2,1.87,9.02]],"ltp":1.79,"tv":42958.3,"id":2120}],"tv":64695.13}]}
{"op":"mcm","clk":"11806395783","pt":1722703879289,"mc":[{"id":"1.231344137","rc":[{"batl":[[0,2.3,4]],"ltp":2.26,"tv":21736.83,"id":2219}]}]}
{"op":"mcm","clk":"11806397885","pt":1722703890532,"mc":[{"id":"1.231344137","rc":[{"batb":[[0,2.28,23.43],[1,2.24,23.52],[2,2.14,35.43]],"ltp":2.26,"tv":21736.83,"id":2219}]}]}
{"op":"mcm","clk":"11806398051","pt":1722703891315,"mc":[{"id":"1.231344137","rc":[{"batb":[[2,1.82,7]],"ltp":2.26,"tv":21736.83,"id":2219},{"batb":[[2,1.48,10]],"ltp":1.79,"tv":42958.3,"id":2120}]}]}
{"op":"mcm","clk":"11806398475","pt":1722703893525,"mc":[{"id":"1.231344137","rc":[{"batl":[[0,1.79,4],[1,1.8,4],[2,1.81,4]],"ltp":1.79,"tv":42958.3,"id":2120}]}]}
{"op":"mcm","clk":"11806399644","pt":1722703899623,"mc":[{"id":"1.231344137","rc":[{"trd":[[2.26,147.03],[2.28,1116.45]],"batb":[[0,2.24,23.52],[1,1.82,7],[2,1.41,85.28]],"batl":[[0,2.3,4.73]],"ltp":2.26,"tv":21786.85,"id":2219},{"trd":[[1.79,15912.8]],"batl":[[0,1.8,4],[1,1.81,4],[2,1.87,9.02]],"ltp":1.79,"tv":42962.3,"id":2120}],"tv":64749.16}]}
{"op":"mcm","clk":"11806399952","pt":1722703901315,"mc":[{"id":"1.231344137","rc":[{"batb":[[1,2.14,35.43],[2,1.82,7]],"ltp":2.26,"tv":21786.85,"id":2219},{"batb":[[2,1.75,53.85]],"ltp":1.79,"tv":42962.3,"id":2120}]}]}
{"op":"mcm","clk":"11806400177","pt":1722703902534,"mc":[{"id":"1.231344137","rc":[{"batl":[[0,2.3,4]],"ltp":2.26,"tv":21786.85,"id":2219}]}]}
{"op":"mcm","clk":"11806401537","pt":1722703909515,"mc":[{"id":"1.231344137","rc":[{"batb":[[0,2.28,23.43],[1,2.24,23.52],[2,2.14,35.43]],"ltp":2.26,"tv":21786.85,"id":2219}]}]}
{"op":"mcm","clk":"11806401896","pt":1722703911494,"mc":[{"id":"1.231344137","rc":[{"batb":[[2,1.82,7]],"ltp":2.26,"tv":21786.85,"id":2219},{"batb":[[2,1.48,10]],"ltp":1.79,"tv":42962.3,"id":2120}]}]}
{"op":"mcm","clk":"11806402852","pt":1722703916551,"mc":[{"id":"1.231344137","rc":[{"trd":[[2.28,1163.3]],"batb":[[0,2.24,19.52],[1,2.14,35.43]],"batl":[[0,2.26,3.9],[1,2.3,4],[2,2.32,17.15]],"ltp":2.28,"tv":21833.7,"id":2219},{"batb":[[2,1.75,53.85]],"ltp":1.79,"tv":42962.3,"id":2120}],"tv":64796.01}]}
{"op":"mcm","clk":"11806403236","pt":1722703918763,"mc":[{"id":"1.231344137","rc":[{"batl":[[1,2.3,17.26],[2,2.32,4]],"ltp":2.28,"tv":21833.7,"id":2219}]}]}
{"op":"mcm","clk":"11806403818","pt":1722703921798,"mc":[{"id":"1.231344137","rc":[{"batl":[[0,2.3,17.26],[1,2.32,4],[2,2.34,1.48]],"ltp":2.28,"tv":21833.7,"id":2219}]}]}
{"op":"mcm","clk":"11806405220","pt":1722703929287,"mc":[{"id":"1.231344137","rc":[{"trd":[[2.24,79.68]],"batb":[[0,2.16,10]],"ltp":2.24,"tv":21875.87,"id":2219},{"trd":[[1.8,23074.86]],"batl":[[0,1.81,4.11],[1,1.87,9.02],[2,1.87,0]],"ltp":1.8,"tv":42966.19,"id":2120}],"tv":64842.07}]}
{"op":"mcm","clk":"11806405321","pt":1722703929866,"mc":[{"id":"1.231344137","rc":[{"batl":[[0,1.87,9.02],[1,1.87,0]],"ltp":1.8,"tv":42966.19,"id":2120}]}]}
{"op":"mcm","clk":"11806405852","pt":1722703932562,"mc":[{"id":"1.231344137","rc":[{"batb":[[0,2.14,35.43],[1,1.82,7],[2,1.41,85.28]],"ltp":2.24,"tv":21875.87,"id":2219}]}]}
{"op":"mcm","clk":"11806409455","pt":1722703952787,"mc":[{"id":"1.231344137","rc":[{"batb":[[0,2.24,39.04],[1,2.14,35.43],[2,1.82,7]],"ltp":2.24,"tv":21875.87,"id":2219}]}]}
{"op":"mcm","clk":"11806409634","pt":1722703953891,"mc":[{"id":"1.231344137","rc":[{"batl":[[0,1.81,4],[1,1.87,9.02]],"ltp":1.8,"tv":42966.19,"id":2120}]}]}
{"op":"mcm","clk":"11806415617","pt":1722703989629,"mc":[{"id":"1.231344137","rc":[{"trd":[[2.24,157.77]],"batb":[[0,2.16,10]],"batl":[[0,2.24,3.9],[1,2.3,17.26],[2,2.32,4]],"ltp":2.24,"tv":21953.96,"id":2219},{"batl":[[0,1.87,9.02],[1,1.87,0]],"ltp":1.8,"tv":42966.19,"id":2120}],"tv":64920.15}]}
{"op":"mcm","clk":"11806416151","pt":1722703992529,"mc":[{"id":"1.231344137","rc":[{"batb":[[0,2.14,35.43],[1,1.82,7],[2,1.41,85.28]],"batl":[[0,2.3,17.26],[1,2.32,4],[2,2.34,1.48]],"ltp":2.24,"tv":21953.96,"id":2219}]}]}
{"op":"mcm","clk":"11806418052","pt":1722704004242,"mc":[{"id":"1.231344137","rc":[{"batb":[[0,2.26,23.43],[1,2.14,35.43],[2,1.82,7]],"ltp":2.24,"tv":21953.96,"id":2219}]}]}
{"op":"mcm","clk":"11806419758","pt":1722704014261,"mc":[{"id":"1.231344137","rc":[{"batl":[[0,1.8,4],[1,1.87,9.02]],"ltp":1.8,"tv":42966.19,"id":2120}]}]}
{"op":"mcm","clk":"11806421452","pt":1722704024801,"mc":[{"id":"1.231344137","rc":[{"trd":[[2.24,160.99],[2.26,193.88]],"batb":[[0,2.16,10]],"batl":[[0,2.3,17.95]],"ltp":2.24,"tv":22004.03,"id":2219},{"trd":[[1.8,23078.86]],"batl":[[0,1.87,9.02],[1,1.87,0]],"ltp":1.8,"tv":42970.19,"id":2120}],"tv":64974.23}]}
{"op":"mcm","clk":"11806422007","pt":1722704028097,"mc":[{"id":"1.231344137","rc":[{"batb":[[0,2.14,35.43],[1,1.82,7],[2,1.41,85.28]],"ltp":2.24,"tv":22004.03,"id":2219}]}]}
{"op":"mcm","clk":"11806422143","pt":1722704028891,"mc":[{"id":"1.231344137","rc":[{"batl":[[0,2.3,17.26]],"ltp":2.24,"tv":22004.03,"id":2219}]}]}
{"op":"mcm","clk":"11806423192","pt":1722704035781,"mc":[{"id":"1.231344137","rc":[{"batb":[[0,2.28,23.43],[1,2.14,35.43],[2,1.82,7]],"ltp":2.24,"tv":22004.03,"id":2219}]}]}
{"op":"mcm","clk":"11806423369","pt":1722704037019,"mc":[{"id":"1.231344137","rc":[{"batb":[[1,1.82,7],[2,1.41,85.28]],"ltp":2.24,"tv":22004.03,"id":2219},{"batb":[[2,1.48,10]],"ltp":1.8,"tv":42970.19,"id":2120}]}]}
{"op":"mcm","clk":"11806424276","pt":1722704043005,"mc":[{"id":"1.231344137","rc":[{"trd":[[2.28,1210.15]],"batb":[[0,1.83,10]],"batl":[[0,2.26,3.9],[1,2.3,17.26],[2,2.32,4]],"ltp":2.28,"tv":22050.88,"id":2219}],"tv":65021.08}]}
{"op":"mcm","clk":"11806424656","pt":1722704045420,"mc":[{"id":"1.231344137","rc":[{"batl":[[0,2.3,17.26],[1,2.32,4],[2,2.34,1.48]],"ltp":2.28,"tv":22050.88,"id":2219}]}]}
{"op":"mcm","clk":"11806424775","pt":1722704046204,"mc":[{"id":"1.231344137","rc":[{"batb":[[0,1.82,7],[1,1.41,85.28],[2,1.3,633.33]],"ltp":2.28,"tv":22050.88,"id":2219}]}]}
{"op":"mcm","clk":"11806424909","pt":1722704046888,"mc":[{"id":"1.231344137","rc":[{"batb":[[0,2.14,35.43],[1,1.82,7],[2,1.41,85.28]],"ltp":2.28,"tv":22050.88,"id":2219},{"batb":[[2,1.75,53.85]],"ltp":1.8,"tv":42970.19,"id":2120}]}]}
{"op":"mcm","clk":"11806425850","pt":1722704053207,"mc":[{"id":"1.231344137","rc":[{"batb":[[0,2.28,23.43],[1,2.14,35.43],[2,1.82,7]],"ltp":2.28,"tv":22050.88,"id":2219}]}]}
{"op":"mcm","clk":"11806426420","pt":1722704057032,"mc":[{"id":"1.231344137","rc":[{"batb":[[1,1.82,7],[2,1.41,85.28]],"ltp":2.28,"tv":22050.88,"id":2219},{"batb":[[2,1.48,10]],"ltp":1.8,"tv":42970.19,"id":2120}]}]}
{"op":"mcm","clk":"11806426819","pt":1722704059507,"mc":[{"id":"1.231344137","rc":[{"batl":[[0,1.79,4],[1,1.87,9.02]],"ltp":1.8,"tv":42970.19,"id":2120}]}]}
{"op":"mcm","clk":"11806427565","pt":1722704064021,"mc":[{"id":"1.231344137","rc":[{"trd":[[2.26,197.05],[2.28,1257.01]],"batb":[[0,1.83,10]],"batl":[[0,2.3,18]],"ltp":2.26,"tv":22100.91,"id":2219},{"trd":[[1.79,15916.8]],"batl":[[0,1.87,9.02],[1,1.87,0]],"ltp":1.79,"tv":42974.19,"id":2120}],"tv":65075.1}]}
{"op":"mcm","clk":"11806428030","pt":1722704066721,"mc":[{"id":"1.231344137","rc":[{"batl":[[0,2.3,17.26]],"ltp":2.26,"tv":22100.91,"id":2219}]}]}
{"op":"mcm","clk":"11806428166","pt":1722704067454,"mc":[{"id":"1.231344137","rc":[{"batb":[[0,2.14,35.43]],"ltp":2.26,"tv":22100.91,"id":2219},{"batb":[[2,1.75,53.85]],"ltp":1.79,"tv":42974.19,"id":2120}]}]}
{"op":"mcm","clk":"11806430372","pt":1722704081657,"mc":[{"id":"1.231344137","rc":[{"batb":[[0,2.28,23.43],[1,2.14,35.43],[2,1.82,7]],"ltp":2.26,"tv":22100.91,"id":2219}]}]}
{"op":"mcm","clk":"11806430444","pt":1722704082024,"mc":[{"id":"1.231344137","rc":[{"batb":[[1,1.82,7],[2,1.41,85.28]],"ltp":2.26,"tv":22100.91,"id":2219},{"batb":[[2,1.48,10]],"ltp":1.79,"tv":42974.19,"id":2120}]}]}
{"op":"mcm","clk":"11806431526","pt":1722704089331,"mc":[{"id":"1.231344137","rc":[{"trd":[[2.28,1303.86]],"batb":[[0,1.83,10]],"batl":[[0,2.26,3.9],[1,2.3,17.26],[2,2.32,4]],"ltp":2.28,"tv":22147.76,"id":2219}],"tv":65121.95}]}
{"op":"mcm","clk":"11806431988","pt":1722704092561,"mc":[{"id":"1.231344137","rc":[{"batb":[[0,2.14,35.43]],"batl":[[0,2.3,17.26],[1,2.32,4],[2,2.34,1.48]],"ltp":2.28,"tv":22147.76,"id":2219},{"batb":[[2,1.75,53.85]],"ltp":1.79,"tv":42974.19,"id":2120}]}]}
{"op":"mcm","clk":"11806433564","pt":1722704102844,"mc":[{"id":"1.231344137","rc":[{"batb":[[0,2.28,23.43],[1,2.14,35.43],[2,1.82,7]],"ltp":2.28,"tv":22147.76,"id":2219}]}]}
{"op":"mcm","clk":"11806433770","pt":1722704103951,"mc":[{"id":"1.231344137","rc":[{"batl":[[0,1.87,9.73]],"ltp":1.79,"tv":42974.19,"id":2120}]}]}
{"op":"mcm","clk":"11806433954","pt":1722704104956,"mc":[{"id":"1.231344137","rc":[{"batl":[[0,1.79,4],[1,1.87,9.73]],"ltp":1.79,"tv":42974.19,"id":2120}]}]}
{"op":"mcm","clk":"11806434366","pt":1722704107274,"mc":[{"id":"1.231344137","rc":[{"batb":[[1,1.82,7],[2,1.41,85.28]],"ltp":2.28,"tv":22147.76,"id":2219},{"batb":[[2,1.48,10]],"ltp":1.79,"tv":42974.19,"id":2120}]}]}
{"op":"mcm","clk":"11806436342","pt":1722704119753,"mc":[{"id":"1.231344137","rc":[{"trd":[[2.26,200.22],[2.28,1350.71]],"batb":[[0,1.82,7],[1,1.41,85.28],[2,1.3,633.33]],"batl":[[0,2.3,18]],"ltp":2.26,"tv":22197.78,"id":2219},{"trd":[[1.79,15920.8]],"batl":[[0,1.87,9.73],[1,1.87,0]],"ltp":1.79,"tv":42978.19,"id":2120}],"tv":65175.98}]}
{"op":"mcm","clk":"11806436365","pt":1722704119961,"mc":[{"id":"1.231344137","rc":[{"batb":[[0,1.83,10],[1,1.82,7],[2,1.41,85.28]],"ltp":2.26,"tv":22197.78,"id":2219}]}]}
{"op":"mcm","clk":"11806436771","pt":1722704122582,"mc":[{"id":"1.231344137","rc":[{"batb":[[0,2.14,35.43],[1,1.83,10],[2,1.82,7]],"batl":[[0,2.3,17.26]],"ltp":2.26,"tv":22197.78,"id":2219},{"batb":[[2,1.75,53.85]],"ltp":1.79,"tv":42978.19,"id":2120}]}]}
{"op":"mcm","clk":"11806436871","pt":1722704123165,"mc":[{"id":"1.231344137","rc":[{"batb":[[1,1.82,7],[2,1.41,85.28]],"ltp":2.26,"tv":22197.78,"id":2219}]}]}
{"op":"mcm","clk":"11806438446","pt":1722704132776,"mc":[{"id":"1.231344137","rc":[{"batb":[[0,2.28,23.43],[1,2.14,35.43],[2,1.82,7]],"ltp":2.26,"tv":22197.78,"id":2219}]}]}
{"op":"mcm","clk":"11806439181","pt":1722704137372,"mc":[{"id":"1.231344137","rc":[{"batb":[[1,1.82,7],[2,1.41,85.28]],"ltp":2.26,"tv":22197.78,"id":2219},{"batb":[[2,1.48,10]],"ltp":1.79,"tv":42978.19,"id":2120}]}]}
{"op":"mcm","clk":"11806442253","pt":1722704157385,"mc":[{"id":"1.231344137","rc":[{"trd":[[2.28,1397.57]],"batb":[[0,2.14,35.43],[1,1.83,10],[2,1.82,7]],"ltp":2.28,"tv":22244.64,"id":2219},{"batb":[[2,1.75,53.85]],"ltp":1.79,"tv":42978.19,"id":2120}],"tv":65222.83}]}
{"op":"mcm","clk":"11806442673","pt":1722704160218,"mc":[{"id":"1.231344137","rc":[{"batb":[[1,1.82,7],[2,1.41,85.28]],"ltp":2.28,"tv":22244.64,"id":2219}]}]}
{"op":"mcm","clk":"11806444509","pt":1722704172594,"mc":[{"id":"1.231344137","rc":[{"batb":[[0,2.28,23.43],[1,2.14,35.43],[2,1.82,7]],"ltp":2.28,"tv":22244.64,"id":2219}]}]}
{"op":"mcm","clk":"11806445264","pt":1722704177613,"mc":[{"id":"1.231344137","rc":[{"batb":[[1,1.82,7],[2,1.41,85.28]],"ltp":2.28,"tv":22244.64,"id":2219},{"batb":[[2,1.48,10]],"ltp":1.79,"tv":42978.19,"id":2120}]}]}
{"op":"mcm","clk":"11806445705","pt":1722704180733,"mc":[{"id":"1.231344137","rc":[{"trd":[[2.28,1444.42]],"batb":[[0,1.82,7],[1,1.41,85.28],[2,1.3,633.33]],"batl":[[0,2.18,3.9],[1,2.3,17.26],[2,2.32,4]],"ltp":2.28,"tv":22291.49,"id":2219}],"tv":65269.68}]}
{"op":"mcm","clk":"11806445719","pt":1722704180836,"mc":[{"id":"1.231344137","rc":[{"batb":[[0,1.83,10],[1,1.82,7],[2,1.41,85.28]],"ltp":2.28,"tv":22291.49,"id":2219}]}]}
{"op":"mcm","clk":"11806445935","pt":1722704182551,"mc":[{"id":"1.231344137","rc":[{"batb":[[0,2.14,35.43],[1,1.83,10],[2,1.82,7]],"ltp":2.28,"tv":22291.49,"id":2219},{"batb":[[2,1.75,53.85]],"ltp":1.79,"tv":42978.19,"id":2120}]}]}
{"op":"mcm","clk":"11806446006","pt":1722704183022,"mc":[{"id":"1.231344137","rc":[{"batl":[[0,2.3,17.26],[1,2.32,4],[2,2.34,1.48]],"ltp":2.28,"tv":22291.49,"id":2219}]}]}
{"op":"mcm","clk":"11806446155","pt":1722704184016,"mc":[{"id":"1.231344137","rc":[{"batb":[[1,1.82,7],[2,1.41,85.28]],"ltp":2.28,"tv":22291.49,"id":2219}]}]}
{"op":"mcm","clk":"11806447461","pt":1722704192831,"mc":[{"id":"1.231344137","rc":[{"batb":[[0,2.28,23.43],[1,2.14,35.43],[2,1.82,7]],"ltp":2.28,"tv":22291.49,"id":2219}]}]}
{"op":"mcm","clk":"11806448179","pt":1722704197580,"mc":[{"id":"1.231344137","rc":[{"batb":[[1,1.82,7],[2,1.41,85.28]],"ltp":2.28,"tv":22291.49,"id":2219},{"batb":[[2,1.48,10]],"ltp":1.79,"tv":42978.19,"id":2120}]}]}
{"op":"mcm","clk":"11806448475","pt":1722704199675,"mc":[{"id":"1.231344137","rc":[{"trd":[[2.28,1491.27]],"batb":[[0,1.82,7],[1,1.41,85.28],[2,1.3,633.33]],"batl":[[0,2.22,3.9],[1,2.3,17.26],[2,2.32,4]],"ltp":2.28,"tv":22338.34,"id":2219}],"tv":65316.54}]}
{"op":"mcm","clk":"11806448545","pt":1722704200142,"mc":[{"id":"1.231344137","rc":[{"batb":[[0,1.83,10],[1,1.82,7],[2,1.41,85.28]],"ltp":2.28,"tv":22338.34,"id":2219}]}]}
{"op":"mcm","clk":"11806448936","pt":1722704202635,"mc":[{"id":"1.231344137","rc":[{"batb":[[0,2.14,35.43],[1,1.83,10],[2,1.82,7]],"ltp":2.28,"tv":22338.34,"id":2219},{"batb":[[2,1.75,53.85]],"ltp":1.79,"tv":42978.19,"id":2120}]}]}
{"op":"mcm","clk":"11806449054","pt":1722704203472,"mc":[{"id":"1.231344137","rc":[{"batb":[[1,1.82,7],[2,1.41,85.28]],"batl":[[0,2.3,17.26],[1,2.32,4],[2,2.34,1.48]],"ltp":2.28,"tv":22338.34,"id":2219}]}]}
{"op":"mcm","clk":"11806451689","pt":1722704221061,"mc":[{"id":"1.231344137","rc":[{"batb":[[0,2.16,10],[1,2.14,35.43],[2,1.82,7]],"ltp":2.28,"tv":22338.34,"id":2219},{"batl":[[0,1.87,9.02]],"ltp":1.79,"tv":42978.19,"id":2120}]}]}
{"op":"mcm","clk":"11806452170","pt":1722704224277,"mc":[{"id":"1.231344137","rc":[{"batb":[[0,2.14,35.43],[1,1.82,7],[2,1.41,85.28]],"ltp":2.28,"tv":22338.34,"id":2219}]}]}
{"op":"mcm","clk":"11806453709","pt":1722704233583,"mc":[{"id":"1.231344137","rc":[{"batb":[[0,2.16,10],[1,2.14,35.43],[2,1.82,7]],"batl":[[0,2.28,153.83],[1,2.3,17.26],[2,2.32,4]],"ltp":2.28,"tv":22338.34,"id":2219}]}]}
{"op":"mcm","clk":"11806453948","pt":1722704235182,"mc":[{"id":"1.231344137","rc":[{"batl":[[0,2.26,13.5],[1,2.28,153.83],[2,2.3,4]],"ltp":2.28,"tv":22338.34,"id":2219}]}]}
{"op":"mcm","clk":"11806454209","pt":1722704237199,"mc":[{"id":"1.231344137","rc":[{"batb":[[0,2.14,35.43],[1,1.82,7],[2,1.41,85.28]],"ltp":2.28,"tv":22338.34,"id":2219}]}]}
{"op":"mcm","clk":"11806454797","pt":1722704241003,"mc":[{"id":"1.231344137","rc":[{"batb":[[0,2.16,10],[1,2.14,35.43],[2,1.82,7]],"batl":[[0,2.26,17.5]],"ltp":2.28,"tv":22338.34,"id":2219}]}]}
{"op":"mcm","clk":"11806455274","pt":1722704244190,"mc":[{"id":"1.231344137","rc":[{"batb":[[0,2.14,35.43],[1,1.82,7],[2,1.41,85.28]],"ltp":2.28,"tv":22338.34,"id":2219}]}]}
{"op":"mcm","clk":"11806456363","pt":1722704251091,"mc":[{"id":"1.231344137","rc":[{"batb":[[0,2.16,10],[1,2.14,35.43],[2,1.82,7]],"batl":[[1,2.3,4],[2,2.32,4]],"ltp":2.28,"tv":22338.34,"id":2219}]}]}
{"op":"mcm","clk":"11806456556","pt":1722704252396,"mc":[{"id":"1.231344137","rc":[{"batl":[[0,2.3,17.26],[1,2.32,4],[2,2.32,0]],"ltp":2.28,"tv":22338.34,"id":2219}]}]}
{"op":"mcm","clk":"11806456835","pt":1722704254278,"mc":[{"id":"1.231344137","rc":[{"batb":[[0,2.14,35.43],[1,1.82,7],[2,1.41,85.28]],"ltp":2.28,"tv":22338.34,"id":2219}]}]}
{"op":"mcm","clk":"11806459078","pt":1722704268823,"mc":[{"id":"1.231344137","rc":[{"batb":[[0,2.22,39.04],[1,2.14,35.43],[2,1.82,7]],"ltp":2.28,"tv":22338.34,"id":2219}]}]}
{"op":"mcm","clk":"11806469218","pt":1722704337787,"mc":[{"id":"1.231344137","rc":[{"batl":[[0,2.28,153.83],[1,2.3,4],[2,2.32,4]],"ltp":2.28,"tv":22338.34,"id":2219}]}]}
{"op":"mcm","clk":"11806469273","pt":1722704338197,"mc":[{"id":"1.231344137","rc":[{"batl":[[0,2.26,11.56],[1,2.28,153.83],[2,2.3,4]],"ltp":2.28,"tv":22338.34,"id":2219},{"batb":[[0,1.79,14.59],[1,1.77,4],[2,1.76,13.02]],"ltp":1.79,"tv":42978.19,"id":2120}]}]}
{"op":"mcm","clk":"11806470053","pt":1722704343078,"mc":[{"id":"1.231344137","rc":[{"batb":[[1,1.82,7],[2,1.41,85.28]],"ltp":2.28,"tv":22338.34,"id":2219}]}]}
{"op":"mcm","clk":"11806470638","pt":1722704346698,"mc":[{"id":"1.231344137","rc":[{"batl":[[0,2.26,15.56]],"ltp":2.28,"tv":22338.34,"id":2219},{"batb":[[0,1.79,18.59]],"ltp":1.79,"tv":42978.19,"id":2120}]}]}
{"op":"mcm","clk":"11806471880","pt":1722704354988,"mc":[{"id":"1.231344137","rc":[{"batl":[[0,2.26,29.06]],"ltp":2.28,"tv":22338.34,"id":2219}]}]}
{"op":"mcm","clk":"11806472901","pt":1722704361802,"mc":[{"id":"1.231344137","rc":[{"batb":[[0,1.8,4],[1,1.79,18.59],[2,1.77,4]],"ltp":1.79,"tv":42978.19,"id":2120}]}]}
{"op":"mcm","clk":"11806476689","pt":1722704387215,"mc":[{"id":"1.231344137","rc":[{"batl":[[1,2.3,4],[2,2.32,4]],"ltp":2.28,"tv":22338.34,"id":2219}]}]}
{"op":"mcm","clk":"11806476926","pt":1722704388824,"mc":[{"id":"1.231344137","rc":[{"batl":[[0,2.26,4]],"ltp":2.28,"tv":22338.34,"id":2219},{"batb":[[1,1.79,4]],"ltp":1.79,"tv":42978.19,"id":2120}]}]}
{"op":"mcm","clk":"11806477023","pt":1722704389511,"mc":[{"id":"1.231344137","rc":[{"batl":[[1,2.28,13.38],[2,2.3,4]],"ltp":2.28,"tv":22338.34,"id":2219},{"batb":[[0,1.79,4],[1,1.77,4],[2,1.76,13.02]],"ltp":1.79,"tv":42978.19,"id":2120}]}]}
{"op":"mcm","clk":"11806477345","pt":1722704391747,"mc":[{"id":"1.231344137","rc":[{"batl":[[1,2.3,4],[2,2.32,4]],"ltp":2.28,"tv":22338.34,"id":2219}]}]}
{"op":"mcm","clk":"11806477435","pt":1722704392322,"mc":[{"id":"1.231344137","rc":[{"batl":[[0,2.3,17.26],[1,2.32,4],[2,2.34,153.83]],"ltp":2.28,"tv":22338.34,"id":2219},{"batb":[[0,1.77,4],[1,1.76,13.02],[2,1.48,10]],"ltp":1.79,"tv":42978.19,"id":2120}]}]}
{"op":"mcm","clk":"11806477562","pt":1722704393253,"mc":[{"id":"1.231344137","rc":[{"batb":[[1,2.14,35.43],[2,1.82,7]],"ltp":2.28,"tv":22338.34,"id":2219},{"batb":[[2,1.75,53.85]],"ltp":1.79,"tv":42978.19,"id":2120}]}]}
{"op":"mcm","clk":"11806490635","pt":1722704476750,"mc":[{"id":"1.231344137","rc":[{"batl":[[2,2.34,0]],"ltp":2.28,"tv":22338.34,"id":2219}]}]}
{"op":"mcm","clk":"11806491581","pt":1722704482764,"mc":[{"id":"1.231344137","rc":[{"batb":[[0,2.14,35.43],[1,1.82,7],[2,1.41,85.28]],"ltp":2.28,"tv":22338.34,"id":2219}]}]}
{"op":"mcm","clk":"11806491617","pt":1722704482975,"mc":[{"id":"1.231344137","rc":[{"batb":[[0,2.16,10],[1,2.14,35.43],[2,1.82,7]],"ltp":2.28,"tv":22338.34,"id":2219}]}]}
{"op":"mcm","clk":"11806492179","pt":1722704486328,"mc":[{"id":"1.231344137","rc":[{"batb":[[0,2.14,35.43],[1,1.82,7],[2,1.41,85.28]],"ltp":2.28,"tv":22338.34,"id":2219}]}]}
{"op":"mcm","clk":"11806501592","pt":1722704546815,"mc":[{"id":"1.231344137","rc":[{"trd":[[2.14,78.38]],"batb":[[0,1.83,10]],"ltp":2.14,"tv":22416.72,"id":2219},{"trd":[[1.87,8.61]],"batl":[[0,1.87,0.41]],"ltp":1.87,"tv":42986.8,"id":2120}],"tv":65403.53}]}
{"op":"mcm","clk":"11806501625","pt":1722704547021,"mc":[{"id":"1.231344137","rc":[{"batl":[[0,2.3,13.26],[1,2.32,0]],"ltp":2.14,"tv":22416.72,"id":2219}]}]}
{"op":"mcm","clk":"11806501906","pt":1722704548819,"mc":[{"id":"1.231344137","rc":[{"batl":[[0,2.32,13.15]],"ltp":2.14,"tv":22416.72,"id":2219}]}]}
{"op":"mcm","clk":"11806501971","pt":1722704549224,"mc":[{"id":"1.231344137","rc":[{"batb":[[0,2.06,38.1],[1,1.83,10],[2,1.82,7]],"ltp":2.14,"tv":22416.72,"id":2219}]}]}
{"op":"mcm","clk":"11806502096","pt":1722704550014,"mc":[{"id":"1.231344137","rc":[{"batb":[[1,1.82,7],[2,1.41,85.28]],"ltp":2.14,"tv":22416.72,"id":2219}]}]}
{"op":"mcm","clk":"11806505486","pt":1722704572724,"mc":[{"id":"1.231344137","rc":[{"batb":[[0,2.14,10],[1,2.12,42.95],[2,2.06,38.1]],"ltp":2.14,"tv":22416.72,"id":2219}]}]}
{"op":"mcm","clk":"11806505981","pt":1722704576118,"mc":[{"id":"1.231344137","rc":[{"batb":[[0,2.12,42.95],[1,2.06,38.1],[2,1.82,7]],"ltp":2.14,"tv":22416.72,"id":2219}]}]}
{"op":"mcm","clk":"11806506749","pt":1722704581032,"mc":[{"id":"1.231344137","rc":[{"batb":[[0,2.14,10],[1,2.12,42.95],[2,2.06,38.1]],"ltp":2.14,"tv":22416.72,"id":2219},{"batb":[[1,1.76,18.17]],"ltp":1.87,"tv":42986.8,"id":2120}]}]}
{"op":"mcm","clk":"11806507286","pt":1722704584232,"mc":[{"id":"1.231344137","rc":[{"batb":[[0,2.12,42.95],[1,2.06,38.1],[2,1.82,7]],"ltp":2.14,"tv":22416.72,"id":2219}]}]}
{"op":"mcm","clk":"11806508515","pt":1722704591553,"mc":[{"id":"1.231344137","rc":[{"batb":[[0,2.08,10]],"ltp":2.14,"tv":22416.72,"id":2219}]}]}
{"op":"mcm","clk":"11806509032","pt":1722704594951,"mc":[{"id":"1.231344137","rc":[{"batb":[[0,2.06,38.1],[1,1.82,7],[2,1.41,85.28]],"ltp":2.14,"tv":22416.72,"id":2219}]}]}
{"op":"mcm","clk":"11806510104","pt":1722704601765,"mc":[{"id":"1.231344137","rc":[{"batb":[[0,2.12,42.95],[1,2.06,38.1],[2,1.82,7]],"ltp":2.14,"tv":22416.72,"id":2219}]}]}
{"op":"mcm","clk":"11806510126","pt":1722704601870,"mc":[{"id":"1.231344137","rc":[{"batb":[[0,2.14,10],[1,2.12,42.95],[2,2.06,38.1]],"ltp":2.14,"tv":22416.72,"id":2219}]}]}
{"op":"mcm","clk":"11806510640","pt":1722704605068,"mc":[{"id":"1.231344137","rc":[{"batb":[[0,2.12,42.95],[1,2.06,38.1],[2,1.82,7]],"ltp":2.14,"tv":22416.72,"id":2219}]}]}
{"op":"mcm","clk":"11806514926","pt":1722704629387,"mc":[{"id":"1.231344137","rc":[{"batb":[[0,2.08,10]],"ltp":2.14,"tv":22416.72,"id":2219}]}]}
{"op":"mcm","clk":"11806515560","pt":1722704632776,"mc":[{"id":"1.231344137","rc":[{"batb":[[0,2.06,38.1],[1,1.82,7],[2,1.41,85.28]],"ltp":2.14,"tv":22416.72,"id":2219}]}]}
{"op":"mcm","clk":"11806519908","pt":1722704657595,"mc":[{"id":"1.231344137","rc":[{"batb":[[0,2.16,10],[1,2.14,109.32],[2,2.06,38.1]],"ltp":2.14,"tv":22416.72,"id":2219}]}]}
{"op":"mcm","clk":"11806520416","pt":1722704660836,"mc":[{"id":"1.231344137","rc":[{"batb":[[0,2.14,109.32],[1,2.06,38.1],[2,1.82,7]],"ltp":2.14,"tv":22416.72,"id":2219}]}]}
{"op":"mcm","clk":"11806522138","pt":1722704670741,"mc":[{"id":"1.231344137","rc":[{"trd":[[2.14,297.03]],"batb":[[0,2.08,10]],"ltp":2.14,"tv":22635.37,"id":2219}],"tv":65622.17}]}
{"op":"mcm","clk":"11806522673","pt":1722704673941,"mc":[{"id":"1.231344137","rc":[{"batb":[[0,2.06,38.1],[1,1.82,7],[2,1.41,85.28]],"ltp":2.14,"tv":22635.37,"id":2219}]}]}
{"op":"mcm","clk":"11806525486","pt":1722704690941,"mc":[{"id":"1.231344137","rc":[{"batb":[[0,2.2,10],[1,2.18,156.18],[2,2.06,38.1]],"ltp":2.14,"tv":22635.37,"id":2219}]}]}
{"op":"mcm","clk":"11806526098","pt":1722704694567,"mc":[{"id":"1.231344137","rc":[{"batb":[[0,2.18,156.18],[1,2.06,38.1],[2,1.82,7]],"batl":[[0,2.3,4],[1,2.32,13.15]],"ltp":2.14,"tv":22635.37,"id":2219}]}]}
{"op":"mcm","clk":"11806526883","pt":1722704699042,"mc":[{"id":"1.231344137","rc":[{"trd":[[2.18,312.35]],"batb":[[0,2.08,10]],"ltp":2.18,"tv":22947.72,"id":2219}],"tv":65934.53}]}
{"op":"mcm","clk":"11806527473","pt":1722704702467,"mc":[{"id":"1.231344137","rc":[{"batb":[[0,2.06,38.1],[1,1.82,7],[2,1.41,85.28]],"ltp":2.18,"tv":22947.72,"id":2219}]}]}
{"op":"mcm","clk":"11806529441","pt":1722704713773,"mc":[{"id":"1.231344137","rc":[{"batb":[[0,2.18,156.18],[1,2.06,38.1],[2,1.82,7]],"ltp":2.18,"tv":22947.72,"id":2219}]}]}
{"op":"mcm","clk":"11806529461","pt":1722704713879,"mc":[{"id":"1.231344137","rc":[{"batb":[[0,2.2,10],[1,2.18,156.18],[2,2.06,38.1]],"ltp":2.18,"tv":22947.72,"id":2219}]}]}
{"op":"mcm","clk":"11806530048","pt":1722704717162,"mc":[{"id":"1.231344137","rc":[{"batb":[[0,2.18,156.18],[1,2.06,38.1],[2,1.82,7]],"ltp":2.18,"tv":22947.72,"id":2219}]}]}
{"op":"mcm","clk":"11806530774","pt":1722704721402,"mc":[{"id":"1.231344137","rc":[{"trd":[[2.18,624.71]],"batb":[[0,2.08,10]],"ltp":2.18,"tv":23260.08,"id":2219}],"tv":66246.88}]}
{"op":"mcm","clk":"11806531391","pt":1722704724780,"mc":[{"id":"1.231344137","rc":[{"batb":[[0,2.06,38.1],[1,1.82,7],[2,1.41,85.28]],"ltp":2.18,"tv":23260.08,"id":2219}]}]}
{"op":"mcm","clk":"11806532667","pt":1722704731781,"mc":[{"id":"1.231344137","rc":[{"batb":[[0,2.2,10],[1,2.18,156.18],[2,2.06,38.1]],"ltp":2.18,"tv":23260.08,"id":2219}]}]}
{"op":"mcm","clk":"11806532832","pt":1722704732579,"mc":[{"id":"1.231344137","rc":[{"batb":[[0,2.2,21.73]],"ltp":2.18,"tv":23260.08,"id":2219},{"batl":[[0,1.84,13.63],[1,1.87,0.41]],"ltp":1.87,"tv":42986.8,"id":2120}]}]}
{"op":"mcm","clk":"11806533388","pt":1722704735679,"mc":[{"id":"1.231344137","rc":[{"trd":[[2.18,913.6],[2.2,23.45]],"batb":[[0,2.18,11.73],[1,2.06,38.1],[2,1.82,7]],"ltp":2.18,"tv":23572.43,"id":2219}],"tv":66559.23}]}
{"op":"mcm","clk":"11806533570","pt":1722704736678,"mc":[{"id":"1.231344137","rc":[{"batl":[[0,1.87,0.41],[1,1.87,0]],"ltp":1.87,"tv":42986.8,"id":2120}]}]}
{"op":"mcm","clk":"11806533726","pt":1722704737574,"mc":[{"id":"1.231344137","rc":[{"batb":[[0,2.2,10],[1,2.18,11.73],[2,2.06,38.1]],"batl":[[0,2.28,13.38],[1,2.3,15.21]],"ltp":2.18,"tv":23572.43,"id":2219}]}]}
{"op":"mcm","clk":"11806534173","pt":1722704739890,"mc":[{"id":"1.231344137","rc":[{"batl":[[0,2.26,4],[1,2.28,17.38],[2,2.3,15.21]],"ltp":2.18,"tv":23572.43,"id":2219},{"batb":[[0,1.79,4],[1,1.78,4],[2,1.77,4]],"ltp":1.87,"tv":42986.8,"id":2120}]}]}
{"op":"mcm","clk":"11806534421","pt":1722704741105,"mc":[{"id":"1.231344137","rc":[{"batb":[[0,2.18,11.73],[1,2.06,38.1],[2,1.82,7]],"batl":[[2,2.3,4]],"ltp":2.18,"tv":23572.43,"id":2219}]}]}
{"op":"mcm","clk":"11806535184","pt":1722704744905,"mc":[{"id":"1.231344137","rc":[{"batl":[[0,2.26,15.41]],"ltp":2.18,"tv":23572.43,"id":2219}]}]}
{"op":"mcm","clk":"11806535518","pt":1722704746595,"mc":[{"id":"1.231344137","rc":[{"batl":[[0,2.2,9.37],[1,2.26,15.41],[2,2.28,17.38]],"ltp":2.18,"tv":23572.43,"id":2219}]}]}
{"op":"mcm","clk":"11806535644","pt":1722704747225,"mc":[{"id":"1.231344137","rc":[{"batl":[[2,2.28,4]],"ltp":2.18,"tv":23572.43,"id":2219}]}]}
{"op":"mcm","clk":"11806535882","pt":1722704748583,"mc":[{"id":"1.231344137","rc":[{"batl":[[1,2.26,4]],"ltp":2.18,"tv":23572.43,"id":2219}]}]}
{"op":"mcm","clk":"11806536089","pt":1722704749789,"mc":[{"id":"1.231344137","rc":[{"batb":[[0,1.76,9.02],[1,1.75,53.85],[2,1.48,10]],"ltp":1.87,"tv":42986.8,"id":2120}]}]}
{"op":"mcm","clk":"11806536258","pt":1722704750789,"mc":[{"id":"1.231344137","rc":[{"batb":[[0,2.2,10],[1,2.18,11.73],[2,2.06,38.1]],"batl":[[0,2.32,11.12]],"ltp":2.18,"tv":23572.43,"id":2219}]}]}
{"op":"mcm","clk":"11806536291","pt":1722704750998,"mc":[{"id":"1.231344137","rc":[{"batl":[[0,2.32,24.27]],"ltp":2.18,"tv":23572.43,"id":2219}]}]}
{"op":"mcm","clk":"11806536674","pt":1722704752718,"mc":[{"id":"1.231344137","rc":[{"batb":[[0,1.76,15.28]],"ltp":1.87,"tv":42986.8,"id":2120}]}]}
{"op":"mcm","clk":"11806537000","pt":1722704754301,"mc":[{"id":"1.231344137","rc":[{"trd":[[2.18,937.03]],"batb":[[0,2.06,38.12],[1,1.82,7],[2,1.41,85.28]],"ltp":2.18,"tv":23595.85,"id":2219}],"tv":66582.66}]}
{"op":"mcm","clk":"11806538058","pt":1722704759730,"mc":[{"id":"1.231344137","rc":[{"batb":[[0,2.08,10],[1,2.06,38.1],[2,1.82,7]],"ltp":2.18,"tv":23595.85,"id":2219}]}]}
{"op":"mcm","clk":"11806538672","pt":1722704763001,"mc":[{"id":"1.231344137","rc":[{"batb":[[0,2.06,38.1],[1,1.82,7],[2,1.41,85.28]],"ltp":2.18,"tv":23595.85,"id":2219}]}]}
{"op":"mcm","clk":"11806540123","pt":1722704770705,"mc":[{"id":"1.231344137","rc":[{"batb":[[0,2.2,10],[1,2.18,156.18],[2,2.06,38.1]],"ltp":2.18,"tv":23595.85,"id":2219}]}]}
{"op":"mcm","clk":"11806540795","pt":1722704774115,"mc":[{"id":"1.231344137","rc":[{"batb":[[0,2.18,156.18],[1,2.06,38.1],[2,1.82,7]],"ltp":2.18,"tv":23595.85,"id":2219}]}]}
{"op":"mcm","clk":"11806541212","pt":1722704776454,"mc":[{"id":"1.231344137","rc":[{"batb":[[0,2.2,10],[1,2.18,156.18],[2,2.06,38.1]],"ltp":2.18,"tv":23595.85,"id":2219},{"batl":[[0,1.84,13.63],[1,1.87,0.41]],"ltp":1.87,"tv":42986.8,"id":2120}]}]}
{"op":"mcm","clk":"11806541359","pt":1722704777143,"mc":[{"id":"1.231344137","rc":[{"trd":[[2.18,1229.38],[2.2,43.46]],"batb":[[0,2.18,10],[1,2.06,38.1],[2,1.82,7]],"ltp":2.18,"tv":23908.2,"id":2219}],"tv":66895.01}]}
{"op":"mcm","clk":"11806541674","pt":1722704778730,"mc":[{"id":"1.231344137","rc":[{"batl":[[0,1.87,0.41],[1,1.87,0]],"ltp":1.87,"tv":42986.8,"id":2120}]}]}
{"op":"mcm","clk":"11806543036","pt":1722704785433,"mc":[{"id":"1.231344137","rc":[{"trd":[[2.18,1248.12]],"batb":[[0,2.08,10.63]],"ltp":2.18,"tv":23926.94,"id":2219}],"tv":66913.75}]}
{"op":"mcm","clk":"11806543699","pt":1722704788655,"mc":[{"id":"1.231344137","rc":[{"batb":[[0,2.06,38.1],[1,1.82,7],[2,1.41,85.28]],"ltp":2.18,"tv":23926.94,"id":2219}]}]}
{"op":"mcm","clk":"11806545335","pt":1722704796747,"mc":[{"id":"1.231344137","rc":[{"batb":[[0,2.22,10],[1,2.2,156.18],[2,2.06,38.1]],"ltp":2.18,"tv":23926.94,"id":2219}]}]}
{"op":"mcm","clk":"11806546055","pt":1722704800381,"mc":[{"id":"1.231344137","rc":[{"batb":[[0,2.2,156.18],[1,2.06,38.1],[2,1.82,7]],"batl":[[0,2.32,28.27]],"ltp":2.18,"tv":23926.94,"id":2219}]}]}
{"op":"mcm","clk":"11806546966","pt":1722704804647,"mc":[{"id":"1.231344137","rc":[{"trd":[[2.2,355.81]],"batb":[[0,2.06,38.1],[1,1.82,7],[2,1.41,85.28]],"ltp":2.2,"tv":24239.3,"id":2219}],"tv":67226.1}]}
{"op":"mcm","clk":"11806547006","pt":1722704804852,"mc":[{"id":"1.231344137","rc":[{"batb":[[0,2.08,10],[1,2.06,38.1],[2,1.82,7]],"ltp":2.2,"tv":24239.3,"id":2219}]}]}
{"op":"mcm","clk":"11806547624","pt":1722704808156,"mc":[{"id":"1.231344137","rc":[{"batb":[[0,2.06,38.1],[1,1.82,7],[2,1.41,85.28]],"ltp":2.2,"tv":24239.3,"id":2219}]}]}
{"op":"mcm","clk":"11806548226","pt":1722704811383,"mc":[{"id":"1.231344137","rc":[{"batb":[[0,2.08,10],[1,2.06,38.1],[2,1.82,7]],"ltp":2.2,"tv":24239.3,"id":2219},{"batl":[[0,1.92,90.57]],"ltp":1.87,"tv":42986.8,"id":2120}]}]}
{"op":"mcm","clk":"11806548826","pt":1722704814549,"mc":[{"id":"1.231344137","rc":[{"batb":[[0,2.06,38.1],[1,1.82,7],[2,1.41,85.28]],"ltp":2.2,"tv":24239.3,"id":2219}]}]}
{"op":"mcm","clk":"11806549047","pt":1722704815692,"mc":[{"id":"1.231344137","rc":[{"batb":[[0,2.18,156.18],[1,2.06,38.1],[2,1.82,7]],"ltp":2.2,"tv":24239.3,"id":2219},{"trd":[[1.87,9.43],[1.92,155.34]],"batl":[[0,1.92,12.49]],"ltp":1.92,"tv":43142.97,"id":2120}],"tv":67382.27}]}
{"op":"mcm","clk":"11806550511","pt":1722704822988,"mc":[{"id":"1.231344137","rc":[{"trd":[[2.18,1560.47]],"batb":[[0,2.08,10]],"ltp":2.18,"tv":24551.65,"id":2219}],"tv":67694.63}]}
{"op":"mcm","clk":"11806551131","pt":1722704826152,"mc":[{"id":"1.231344137","rc":[{"batb":[[0,2.06,38.1],[1,1.82,7],[2,1.41,85.28]],"ltp":2.18,"tv":24551.65,"id":2219}]}]}
{"op":"mcm","clk":"11806552288","pt":1722704832090,"mc":[{"id":"1.231344137","rc":[{"batb":[[0,2.18,156.18],[1,2.08,10],[2,2.06,38.1]],"ltp":2.18,"tv":24551.65,"id":2219}]}]}
{"op":"mcm","clk":"11806552992","pt":1722704835390,"mc":[{"id":"1.231344137","rc":[{"batb":[[1,2.06,38.1],[2,1.82,7]],"ltp":2.18,"tv":24551.65,"id":2219}]}]}
{"op":"mcm","clk":"11806553465","pt":1722704837680,"mc":[{"id":"1.231344137","rc":[{"trd":[[2.18,1872.83]],"batb":[[0,2.08,10]],"ltp":2.18,"tv":24864.01,"id":2219}],"tv":68006.98}]}
{"op":"mcm","clk":"11806554074","pt":1722704841096,"mc":[{"id":"1.231344137","rc":[{"batb":[[0,2.06,38.1],[1,1.82,7],[2,1.41,85.28]],"ltp":2.18,"tv":24864.01,"id":2219}]}]}
{"op":"mcm","clk":"11806555925","pt":1722704850786,"mc":[{"id":"1.231344137","rc":[{"batb":[[0,2.2,10],[1,2.18,156.18],[2,2.06,38.1]],"ltp":2.18,"tv":24864.01,"id":2219},{"batl":[[0,1.84,13.63]],"ltp":1.92,"tv":43142.97,"id":2120}]}]}
{"op":"mcm","clk":"11806556429","pt":1722704853395,"mc":[{"id":"1.231344137","rc":[{"batb":[[0,2.18,156.18],[1,2.06,38.1],[2,1.82,7]],"ltp":2.18,"tv":24864.01,"id":2219}]}]}
{"op":"mcm","clk":"11806556598","pt":1722704854294,"mc":[{"id":"1.231344137","rc":[{"trd":[[2.18,2185.18]],"batb":[[0,2.06,38.1],[1,1.82,7],[2,1.41,85.28]],"ltp":2.18,"tv":25176.36,"id":2219}],"tv":68319.33}]}
{"op":"mcm","clk":"11806558770","pt":1722704865420,"mc":[{"id":"1.231344137","rc":[{"batb":[[0,2.2,10],[1,2.18,156.18],[2,2.06,38.1]],"ltp":2.18,"tv":25176.36,"id":2219}]}]}
{"op":"mcm","clk":"11806559389","pt":1722704868624,"mc":[{"id":"1.231344137","rc":[{"batb":[[0,2.18,156.18],[1,2.06,38.1],[2,1.82,7]],"ltp":2.18,"tv":25176.36,"id":2219}]}]}
{"op":"mcm","clk":"11806559664","pt":1722704870019,"mc":[{"id":"1.231344137","rc":[{"trd":[[2.18,2497.53]],"batb":[[0,2.06,38.1],[1,1.82,7],[2,1.41,85.28]],"ltp":2.18,"tv":25488.71,"id":2219}],"tv":68631.69}]}
{"op":"mcm","clk":"11806561549","pt":1722704880329,"mc":[{"id":"1.231344137","rc":[{"batb":[[0,2.2,10],[1,2.18,156.18],[2,2.06,38.1]],"ltp":2.18,"tv":25488.71,"id":2219}]}]}
{"op":"mcm","clk":"11806562142","pt":1722704883621,"mc":[{"id":"1.231344137","rc":[{"batb":[[0,2.18,156.18],[1,2.06,38.1],[2,1.82,7]],"ltp":2.18,"tv":25488.71,"id":2219}]}]}
{"op":"mcm","clk":"11806562231","pt":1722704884105,"mc":[{"id":"1.231344137","rc":[{"trd":[[2.18,2809.89]],"batb":[[0,2.06,38.1],[1,1.82,7],[2,1.41,85.28]],"ltp":2.18,"tv":25801.07,"id":2219}],"tv":68944.04}]}
{"op":"mcm","clk":"11806564034","pt":1722704893813,"mc":[{"id":"1.231344137","rc":[{"batb":[[0,2.2,10],[1,2.18,156.18],[2,2.06,38.1]],"ltp":2.18,"tv":25801.07,"id":2219}]}]}
{"op":"mcm","clk":"11806564158","pt":1722704894544,"mc":[{"id":"1.231344137","rc":[{"batl":[[0,1.84,13.63]],"ltp":1.92,"tv":43142.97,"id":2120}]}]}
{"op":"mcm","clk":"11806564734","pt":1722704897632,"mc":[{"id":"1.231344137","rc":[{"trd":[[2.18,3122.24]],"batb":[[0,2.06,38.1],[1,1.82,7],[2,1.41,85.28]],"ltp":2.18,"tv":26113.42,"id":2219}],"tv":69256.39}]}
{"op":"mcm","clk":"11806565017","pt":1722704899157,"mc":[{"id":"1.231344137","rc":[{"batb":[[0,2.08,10],[1,2.06,38.1],[2,1.82,7]],"ltp":2.18,"tv":26113.42,"id":2219}]}]}
{"op":"mcm","clk":"11806565587","pt":1722704902334,"mc":[{"id":"1.231344137","rc":[{"batb":[[0,2.06,38.1],[1,1.82,7],[2,1.41,85.28]],"ltp":2.18,"tv":26113.42,"id":2219}]}]}
{"op":"mcm","clk":"11806566574","pt":1722704907773,"mc":[{"id":"1.231344137","rc":[{"batb":[[0,2.08,10],[1,2.06,38.1],[2,1.82,7]],"batl":[[0,2.3,64.83],[1,2.32,28.27]],"ltp":2.18,"tv":26113.42,"id":2219}]}]}
{"op":"mcm","clk":"11806566643","pt":1722704908151,"mc":[{"id":"1.231344137","rc":[{"trd":[[2.3,19792.89]],"batb":[[0,2.18,156.18],[1,2.08,10],[2,2.06,38.1]],"batl":[[0,2.32,28.29],[1,2.32,0]],"ltp":2.3,"tv":26243.04,"id":2219}],"tv":69386.02}]}
{"op":"mcm","clk":"11806567194","pt":1722704911170,"mc":[{"id":"1.231344137","rc":[{"batb":[[1,2.06,38.1],[2,1.82,7]],"ltp":2.3,"tv":26243.04,"id":2219}]}]}
{"op":"mcm","clk":"11806567443","pt":1722704912138,"mc":[{"id":"1.231344137","rc":[{"trd":[[2.18,3434.59]],"batb":[[0,2.06,38.1],[1,1.82,7],[2,1.41,85.28]],"ltp":2.18,"tv":26555.4,"id":2219}],"tv":69698.37}]}
{"op":"mcm","clk":"11806568948","pt":1722704920161,"mc":[{"id":"1.231344137","rc":[{"batb":[[0,2.2,10],[1,2.18,156.18],[2,2.06,38.1]],"ltp":2.18,"tv":26555.4,"id":2219}]}]}
{"op":"mcm","clk":"11806569152","pt":1722704921175,"mc":[{"id":"1.231344137","rc":[{"batl":[[0,2.3,4.02],[1,2.32,28.27]],"ltp":2.18,"tv":26555.4,"id":2219}]}]}
{"op":"mcm","clk":"11806569533","pt":1722704923462,"mc":[{"id":"1.231344137","rc":[{"batb":[[0,2.18,156.18],[1,2.06,38.1],[2,1.82,7]],"ltp":2.18,"tv":26555.4,"id":2219}]}]}
{"op":"mcm","clk":"11806569710","pt":1722704924369,"mc":[{"id":"1.231344137","rc":[{"trd":[[2.18,3746.95]],"batb":[[0,2.06,38.1],[1,1.82,7],[2,1.41,85.28]],"ltp":2.18,"tv":26867.75,"id":2219}],"tv":70010.72}]}
{"op":"mcm","clk":"11806570234","pt":1722704927480,"mc":[{"id":"1.231344137","rc":[{"batb":[[0,2.08,10],[1,2.06,38.1],[2,1.82,7]],"batl":[[0,2.3,4]],"ltp":2.18,"tv":26867.75,"id":2219}]}]}
{"op":"mcm","clk":"11806570784","pt":1722704930765,"mc":[{"id":"1.231344137","rc":[{"batb":[[0,2.06,38.1],[1,1.82,7],[2,1.41,85.28]],"ltp":2.18,"tv":26867.75,"id":2219}]}]}
{"op":"mcm","clk":"11806571459","pt":1722704934517,"mc":[{"id":"1.231344137","rc":[{"batb":[[0,2.2,10],[1,2.18,156.18],[2,2.06,38.1]],"ltp":2.18,"tv":26867.75,"id":2219}]}]}
{"op":"mcm","clk":"11806571660","pt":1722704935591,"mc":[{"id":"1.231344137","rc":[{"batl":[[0,1.84,13.63]],"ltp":1.92,"tv":43142.97,"id":2120}]}]}
{"op":"mcm","clk":"11806572151","pt":1722704938380,"mc":[{"id":"1.231344137","rc":[{"trd":[[2.18,4059.3]],"batb":[[0,2.06,38.1],[1,1.82,7],[2,1.41,85.28]],"ltp":2.18,"tv":27180.1,"id":2219}],"tv":70323.08}]}
{"op":"mcm","clk":"11806572427","pt":1722704940090,"mc":[{"id":"1.231344137","rc":[{"batb":[[0,2.08,10],[1,2.06,38.1],[2,1.82,7]],"ltp":2.18,"tv":27180.1,"id":2219}]}]}
{"op":"mcm","clk":"11806573006","pt":1722704943790,"mc":[{"id":"1.231344137","rc":[{"batb":[[0,2.06,38.1],[1,1.82,7],[2,1.41,85.28]],"ltp":2.18,"tv":27180.1,"id":2219}]}]}
{"op":"mcm","clk":"11806573954","pt":1722704948422,"mc":[{"id":"1.231344137","rc":[{"batb":[[0,2.2,10],[1,2.18,156.18],[2,2.06,38.1]],"ltp":2.18,"tv":27180.1,"id":2219}]}]}
{"op":"mcm","clk":"11806574543","pt":1722704951783,"mc":[{"id":"1.231344137","rc":[{"batb":[[0,2.18,156.18],[1,2.06,38.1],[2,1.82,7]],"ltp":2.18,"tv":27180.1,"id":2219}]}]}
{"op":"mcm","clk":"11806574594","pt":1722704951993,"mc":[{"id":"1.231344137","rc":[{"trd":[[2.18,4371.65]],"batb":[[0,2.06,38.1],[1,1.82,7],[2,1.41,85.28]],"ltp":2.18,"tv":27492.46,"id":2219}],"tv":70635.43}]}
{"op":"mcm","clk":"11806575582","pt":1722704957704,"mc":[{"id":"1.231344137","rc":[{"trd":[[2.06,38.1]],"batb":[[0,1.82,7],[1,1.41,85.28],[2,1.3,633.33]],"ltp":2.06,"tv":27530.56,"id":2219},{"trd":[[1.95,40.25]],"batb":[[0,1.95,9.75],[1,1.76,15.28],[2,1.75,53.85]],"ltp":1.95,"tv":43183.22,"id":2120}],"tv":70713.78}]}
{"op":"mcm","clk":"11806575713","pt":1722704958397,"mc":[{"id":"1.231344137","rc":[{"batb":[[0,1.83,10],[1,1.82,7],[2,1.41,85.28]],"batl":[[0,2.3,17.26],[1,2.32,15.12]],"ltp":2.06,"tv":27530.56,"id":2219}]}]}
{"op":"mcm","clk":"11806575948","pt":1722704959824,"mc":[{"id":"1.231344137","rc":[{"batl":[[1,2.32,4]],"ltp":2.06,"tv":27530.56,"id":2219},{"batb":[[1,1.76,9.02]],"ltp":1.95,"tv":43183.22,"id":2120}]}]}
{"op":"mcm","clk":"11806576185","pt":1722704961202,"mc":[{"id":"1.231344137","rc":[{"batb":[[0,1.99,40.8]],"ltp":2.06,"tv":27530.56,"id":2219}]}]}
{"op":"mcm","clk":"11806576474","pt":1722704962813,"mc":[{"id":"1.231344137","rc":[{"batb":[[1,1.94,100],[2,1.76,9.02]],"ltp":1.95,"tv":43183.22,"id":2120}]}]}
{"op":"mcm","clk":"11806576644","pt":1722704963811,"mc":[{"id":"1.231344137","rc":[{"batb":[[0,2,10],[1,1.99,40.8],[2,1.82,7]],"batl":[[0,2.06,12.52],[1,2.3,4],[2,2.32,17.15]],"ltp":2.06,"tv":27530.56,"id":2219}]}]}
{"op":"mcm","clk":"11806577214","pt":1722704966710,"mc":[{"id":"1.231344137","rc":[{"batb":[[0,1.99,40.8],[1,1.82,7],[2,1.41,85.28]],"batl":[[0,2.04,4],[1,2.06,16.52],[2,2.3,4]],"ltp":2.06,"tv":27530.56,"id":2219},{"batb":[[0,1.95,13.75]],"ltp":1.95,"tv":43183.22,"id":2120}]}]}
{"op":"mcm","clk":"11806577253","pt":1722704966923,"mc":[{"id":"1.231344137","rc":[{"batb":[[2,1.93,150]],"ltp":1.95,"tv":43183.22,"id":2120}]}]}
{"op":"mcm","clk":"11806580021","pt":1722704981730,"mc":[{"id":"1.231344137","rc":[{"batb":[[0,1.96,4],[1,1.95,13.75],[2,1.94,100]],"ltp":1.95,"tv":43183.22,"id":2120}]}]}
{"op":"mcm","clk":"11806580380","pt":1722704983849,"mc":[{"id":"1.231344137","rc":[{"batl":[[0,2,90.88]],"ltp":1.95,"tv":43183.22,"id":2120}]}]}
{"op":"mcm","clk":"11806580946","pt":1722704986856,"mc":[{"id":"1.231344137","rc":[{"batl":[[0,2.04,18.95]],"ltp":2.06,"tv":27530.56,"id":2219}]}]}
{"op":"mcm","clk":"11806581233","pt":1722704988518,"mc":[{"id":"1.231344137","rc":[{"batl":[[0,2.02,12.78],[1,2.04,18.95],[2,2.06,16.52]],"ltp":2.06,"tv":27530.56,"id":2219}]}]}
{"op":"mcm","clk":"11806582716","pt":1722704996834,"mc":[{"id":"1.231344137","rc":[{"batl":[[0,2.02,16.78]],"ltp":2.06,"tv":27530.56,"id":2219},{"batb":[[0,1.98,4],[1,1.96,4],[2,1.95,13.75]],"ltp":1.95,"tv":43183.22,"id":2120}]}]}
{"op":"mcm","clk":"11806583983","pt":1722705003554,"mc":[{"id":"1.231344137","rc":[{"trd":[[2.02,24.99]],"batl":[[0,2.02,4.28]],"ltp":2.02,"tv":27555.55,"id":2219},{"batb":[[0,1.96,4],[1,1.95,13.75],[2,1.94,100]],"ltp":1.95,"tv":43183.22,"id":2120}],"tv":70738.77}]}
{"op":"mcm","clk":"11806584252","pt":1722705004943,"mc":[{"id":"1.231344137","rc":[{"batl":[[0,2.02,4]],"ltp":2.02,"tv":27555.55,"id":2219}]}]}
{"op":"mcm","clk":"11806603656","pt":1722705112162,"mc":[{"id":"1.231344137","rc":[{"trd":[[2.02,28.99]],"batl":[[0,2.04,18.95],[1,2.06,16.52],[2,2.28,70.28]],"ltp":2.02,"tv":27559.55,"id":2219},{"trd":[[1.98,4.08]],"batl":[[0,1.98,0.92]],"ltp":1.98,"tv":43187.3,"id":2120}],"tv":70746.85}]}
{"op":"mcm","clk":"11806604548","pt":1722705117590,"mc":[{"id":"1.231344137","rc":[{"batb":[[0,1.99,44.8]],"ltp":2.02,"tv":27559.55,"id":2219}]}]}
{"op":"mcm","clk":"11806607715","pt":1722705136287,"mc":[{"id":"1.231344137","rc":[{"trd":[[2.04,18.14]],"batl":[[0,2.04,9.88]],"ltp":2.04,"tv":27577.69,"id":2219}],"tv":70764.99}]}
{"op":"mcm","clk":"11806609786","pt":1722705147780,"mc":[{"id":"1.231344137","rc":[{"batl":[[0,2.04,13.88]],"ltp":2.04,"tv":27577.69,"id":2219}]}]}
{"op":"mcm","clk":"11806612175","pt":1722705160993,"mc":[{"id":"1.231344137","rc":[{"batl":[[0,2,182.66]],"ltp":1.98,"tv":43187.3,"id":2120}]}]}
{"op":"mcm","clk":"11806612337","pt":1722705161996,"mc":[{"id":"1.231344137","rc":[{"batb":[[0,2.02,12.38],[1,1.99,44.8],[2,1.82,7]],"ltp":2.04,"tv":27577.69,"id":2219},{"batl":[[0,1.99,13.52],[1,2,182.66]],"ltp":1.98,"tv":43187.3,"id":2120}]}]}
{"op":"mcm","clk":"11806613229","pt":1722705166986,"mc":[{"id":"1.231344137","rc":[{"batb":[[1,1.99,4]],"ltp":2.04,"tv":27577.69,"id":2219}]}]}
{"op":"mcm","clk":"11806625805","pt":1722705175722,"mc":[{"id":"1.231344137","rc":[{"batb":[[1,1.82,7],[2,1.41,85.28]],"ltp":2.04,"tv":27577.69,"id":2219},{"batl":[[1,2,0]],"ltp":1.98,"tv":43187.3,"id":2120}]}]}
{"op":"mcm","clk":"11806626013","pt":1722705176826,"mc":[{"id":"1.231344137","rc":[{"batb":[[0,1.83,10]],"ltp":2.04,"tv":27577.69,"id":2219}]}]}
{"op":"mcm","clk":"11806626037","pt":1722705176931,"mc":[{"id":"1.231344137","rc":[{"trd":[[2.04,22.17]],"batb":[[0,1.99,40.8],[1,1.83,10],[2,1.82,7]],"batl":[[0,2.04,11.86]],"ltp":2.04,"tv":27581.71,"id":2219}],"tv":70769.02}]}
{"op":"mcm","clk":"11806626654","pt":1722705180123,"mc":[{"id":"1.231344137","rc":[{"batb":[[1,1.82,7],[2,1.41,85.28]],"ltp":2.04,"tv":27581.71,"id":2219}]}]}
{"op":"mcm","clk":"11806628959","pt":1722705193024,"mc":[{"id":"1.231344137","rc":[{"batb":[[0,1.99,44.8]],"ltp":2.04,"tv":27581.71,"id":2219}]}]}
{"op":"mcm","clk":"11806629862","pt":1722705198151,"mc":[{"id":"1.231344137","rc":[{"trd":[[2.04,45.89],[2.06,87.96],[2.08,183.12]],"batb":[[0,2,10],[1,1.99,40.8],[2,1.82,7]],"batl":[[0,2.28,70.28],[1,2.3,175.79],[2,2.32,4]],"ltp":2.08,"tv":27838.41,"id":2219},{"trd":[[1.93,96.83],[1.94,100],[1.95,54],[1.96,4]],"batb":[[0,1.93,53.17],[1,1.92,200],[2,1.91,250]],"ltp":1.93,"tv":43401.88,"id":2120}],"tv":71240.3}]}
{"op":"mcm","clk":"11806630147","pt":1722705199735,"mc":[{"id":"1.231344137","rc":[{"batb":[[0,2,22.61]],"ltp":2.08,"tv":27838.41,"id":2219}]}]}
{"op":"mcm","clk":"11806630478","pt":1722705201429,"mc":[{"id":"1.231344137","rc":[{"batb":[[0,2,12.61]],"ltp":2.08,"tv":27838.41,"id":2219}]}]}
{"op":"mcm","clk":"11806631732","pt":1722705208131,"mc":[{"id":"1.231344137","rc":[{"batl":[[0,2.06,4],[1,2.08,4],[2,2.28,70.28]],"ltp":2.08,"tv":27838.41,"id":2219}]}]}
{"op":"mcm","clk":"11806633067","pt":1722705215957,"mc":[{"id":"1.231344137","rc":[{"trd":[[2.06,95.96]],"batb":[[0,2.06,32.53],[1,2,12.61],[2,1.99,40.8]],"batl":[[0,2.08,4],[1,2.28,70.28],[2,2.3,175.79]],"ltp":2.06,"tv":27846.41,"id":2219}],"tv":71248.3}]}
{"op":"mcm","clk":"11806633380","pt":1722705217541,"mc":[{"id":"1.231344137","rc":[{"batb":[[0,2.06,44.78],[1,1.82,7],[2,1.41,85.28]],"ltp":2.06,"tv":27846.41,"id":2219}]}]}
{"op":"mcm","clk":"11806634414","pt":1722705223188,"mc":[{"id":"1.231344137","rc":[{"batb":[[0,1.93,57.17]],"ltp":1.93,"tv":43401.88,"id":2120}]}]}
{"op":"mcm","clk":"11806637455","pt":1722705241824,"mc":[{"id":"1.231344137","rc":[{"trd":[[1.93,106.57]],"batb":[[0,1.93,52.3]],"ltp":1.93,"tv":43411.62,"id":2120}],"tv":71258.04}]}
{"op":"mcm","clk":"11806639392","pt":1722705253540,"mc":[{"id":"1.231344137","rc":[{"batb":[[0,2.06,12.25]],"ltp":2.06,"tv":27846.41,"id":2219},{"batb":[[0,1.94,4],[1,1.93,52.3],[2,1.92,200]],"ltp":1.93,"tv":43411.62,"id":2120}]}]}
{"op":"mcm","clk":"11806639576","pt":1722705254504,"mc":[{"id":"1.231344137","rc":[{"batb":[[0,1.83,10],[2,1.42,17.76]],"ltp":2.06,"tv":27846.41,"id":2219}]}]}
{"op":"mcm","clk":"11806640167","pt":1722705257826,"mc":[{"id":"1.231344137","rc":[{"batb":[[0,1.99,40.8]],"ltp":2.06,"tv":27846.41,"id":2219}]}]}
{"op":"mcm","clk":"11806640382","pt":1722705259039,"mc":[{"id":"1.231344137","rc":[{"batb":[[0,2,12.61],[1,1.99,40.8],[2,1.82,7]],"ltp":2.06,"tv":27846.41,"id":2219}]}]}
{"op":"mcm","clk":"11806642061","pt":1722705268551,"mc":[{"id":"1.231344137","rc":[{"batl":[[0,2.06,4],[1,2.08,4],[2,2.28,70.28]],"ltp":2.06,"tv":27846.41,"id":2219}]}]}
{"op":"mcm","clk":"11806642254","pt":1722705269658,"mc":[{"id":"1.231344137","rc":[{"batb":[[0,1.94,8.34]],"ltp":1.93,"tv":43411.62,"id":2120}]}]}
{"op":"mcm","clk":"11806651089","pt":1722705321291,"mc":[{"id":"1.231344137","rc":[{"trd":[[2.06,103.96]],"batb":[[0,2.06,10.38],[1,2,12.61],[2,1.99,40.8]],"batl":[[0,2.08,4],[1,2.28,70.28],[2,2.3,175.79]],"ltp":2.06,"tv":27854.41,"id":2219}],"tv":71266.04}]}
{"op":"mcm","clk":"11806651276","pt":1722705322368,"mc":[{"id":"1.231344137","rc":[{"batb":[[2,1.82,7]],"ltp":2.06,"tv":27854.41,"id":2219}]}]}
{"op":"mcm","clk":"11806651378","pt":1722705323127,"mc":[{"id":"1.231344137","rc":[{"batb":[[1,1.82,7],[2,1.41,85.28]],"ltp":2.06,"tv":27854.41,"id":2219}]}]}
{"op":"mcm","clk":"11806660531","pt":1722705376947,"mc":[{"id":"1.231344137","rc":[{"batb":[[0,2.06,10.28]],"ltp":2.06,"tv":27854.41,"id":2219}]}]}
{"op":"mcm","clk":"11806661303","pt":1722705381325,"mc":[{"id":"1.231344137","rc":[{"trd":[[2.08,197.4]],"batb":[[0,1.83,10]],"batl":[[0,2.28,70.28],[1,2.3,175.79],[2,2.32,4]],"ltp":2.08,"tv":27868.69,"id":2219},{"trd":[[1.94,106.73]],"batb":[[0,1.94,1.61]],"ltp":1.94,"tv":43418.35,"id":2120}],"tv":71287.05}]}
{"op":"mcm","clk":"11806661495","pt":1722705382534,"mc":[{"id":"1.231344137","rc":[{"batb":[[0,1.99,40.8],[1,1.83,10],[2,1.82,7]],"ltp":2.08,"tv":27868.69,"id":2219}]}]}
{"op":"mcm","clk":"11806661678","pt":1722705383650,"mc":[{"id":"1.231344137","rc":[{"batb":[[0,2,12.61],[1,1.99,40.8],[2,1.83,10]],"ltp":2.08,"tv":27868.69,"id":2219},{"batb":[[0,1.93,52.3],[1,1.92,200],[2,1.91,250]],"ltp":1.94,"tv":43418.35,"id":2120}]}]}
{"op":"mcm","clk":"11806661858","pt":1722705384721,"mc":[{"id":"1.231344137","rc":[{"batb":[[2,1.82,7]],"ltp":2.08,"tv":27868.69,"id":2219}]}]}
{"op":"mcm","clk":"11806662022","pt":1722705385724,"mc":[{"id":"1.231344137","rc":[{"trd":[[2.08,206.17]],"ltp":2.08,"tv":27877.46,"id":2219},{"trd":[[1.93,116.02]],"batb":[[0,1.94,10],[1,1.93,42.85],[2,1.92,200]],"batl":[[0,2,2.65]],"ltp":1.93,"tv":43427.8,"id":2120}],"tv":71305.27}]}
{"op":"mcm","clk":"11806662690","pt":1722705389610,"mc":[{"id":"1.231344137","rc":[{"batb":[[0,2.02,10],[1,2,12.61],[2,1.99,40.8]],"batl":[[0,2.06,4],[1,2.08,4],[2,2.28,70.28]],"ltp":2.08,"tv":27877.46,"id":2219},{"batb":[[0,1.94,4]],"ltp":1.93,"tv":43427.8,"id":2120}]}]}
{"op":"mcm","clk":"11806663357","pt":1722705393153,"mc":[{"id":"1.231344137","rc":[{"batb":[[0,2,12.61],[1,1.99,40.8],[2,1.82,7]],"ltp":2.08,"tv":27877.46,"id":2219},{"batb":[[0,1.95,10],[1,1.94,4],[2,1.93,42.85]],"ltp":1.93,"tv":43427.8,"id":2120}]}]}
{"op":"mcm","clk":"11806663935","pt":1722705396450,"mc":[{"id":"1.231344137","rc":[{"batb":[[0,1.94,4],[1,1.93,42.85],[2,1.92,200]],"ltp":1.93,"tv":43427.8,"id":2120}]}]}
{"op":"mcm","clk":"11806679736","pt":1722705484761,"mc":[{"id":"1.231344137","rc":[{"batl":[[0,2.04,3.9],[1,2.06,4],[2,2.08,4]],"ltp":2.08,"tv":27877.46,"id":2219},{"batb":[[0,1.95,10],[1,1.94,4],[2,1.93,42.85]],"ltp":1.93,"tv":43427.8,"id":2120}]}]}
{"op":"mcm","clk":"11806680351","pt":1722705487956,"mc":[{"id":"1.231344137","rc":[{"batb":[[0,1.94,4],[1,1.93,42.85],[2,1.92,200]],"ltp":1.93,"tv":43427.8,"id":2120}]}]}
{"op":"mcm","clk":"11806681390","pt":1722705493646,"mc":[{"id":"1.231344137","rc":[{"batl":[[0,2.06,4],[1,2.08,4],[2,2.28,70.28]],"ltp":2.08,"tv":27877.46,"id":2219},{"batb":[[0,1.95,10],[1,1.94,4],[2,1.93,42.85]],"ltp":1.93,"tv":43427.8,"id":2120}]}]}
{"op":"mcm","clk":"11806681669","pt":1722705495281,"mc":[{"id":"1.231344137","rc":[{"batb":[[0,1.95,14]],"batl":[[0,2,6.65]],"ltp":1.93,"tv":43427.8,"id":2120}]}]}
{"op":"mcm","clk":"11806682066","pt":1722705497170,"mc":[{"id":"1.231344137","rc":[{"batb":[[0,1.94,4],[1,1.93,42.85],[2,1.92,200]],"ltp":1.93,"tv":43427.8,"id":2120}]}]}
{"op":"mcm","clk":"11806685073","pt":1722705514760,"mc":[{"id":"1.231344137","rc":[{"batb":[[0,2.02,15.62],[1,2,12.61],[2,1.99,40.8]],"ltp":2.08,"tv":27877.46,"id":2219},{"batb":[[0,1.95,10],[1,1.94,4],[2,1.93,42.85]],"ltp":1.93,"tv":43427.8,"id":2120}]}]}
{"op":"mcm","clk":"11806685677","pt":1722705518482,"mc":[{"id":"1.231344137","rc":[{"batb":[[2,1.82,7]],"ltp":2.08,"tv":27877.46,"id":2219},{"batb":[[0,1.94,4],[1,1.93,42.85],[2,1.92,200]],"batl":[[0,2,2.65]],"ltp":1.93,"tv":43427.8,"id":2120}]}]}
{"op":"mcm","clk":"11806686447","pt":1722705523111,"mc":[{"id":"1.231344137","rc":[{"batb":[[2,1.99,40.8]],"ltp":2.08,"tv":27877.46,"id":2219},{"batb":[[0,1.95,10],[1,1.94,4],[2,1.93,42.85]],"ltp":1.93,"tv":43427.8,"id":2120}]}]}
{"op":"mcm","clk":"11806686833","pt":1722705525487,"mc":[{"id":"1.231344137","rc":[{"batb":[[0,1.95,14]],"batl":[[0,1.99,4],[1,2,2.65]],"ltp":1.93,"tv":43427.8,"id":2120}]}]}
{"op":"mcm","clk":"11806686982","pt":1722705526287,"mc":[{"id":"1.231344137","rc":[{"batb":[[0,1.95,4]],"ltp":1.93,"tv":43427.8,"id":2120}]}]}
{"op":"mcm","clk":"11806687217","pt":1722705527720,"mc":[{"id":"1.231344137","rc":[{"batb":[[0,1.94,4],[1,1.93,42.85],[2,1.92,200]],"batl":[[1,2,0]],"ltp":1.93,"tv":43427.8,"id":2120}]}]}
{"op":"mcm","clk":"11806687354","pt":1722705528482,"mc":[{"id":"1.231344137","rc":[{"batl":[[0,1.98,2.68]],"ltp":1.93,"tv":43427.8,"id":2120}]}]}
{"op":"mcm","clk":"11806687716","pt":1722705530595,"mc":[{"id":"1.231344137","rc":[{"batb":[[0,2.04,12.37],[1,2.02,15.62]],"ltp":2.08,"tv":27877.46,"id":2219}]}]}
{"op":"mcm","clk":"11806688165","pt":1722705533232,"mc":[{"id":"1.231344137","rc":[{"batb":[[0,2.04,27.98],[1,1.82,7],[2,1.41,85.28]],"ltp":2.08,"tv":27877.46,"id":2219}]}]}
{"op":"mcm","clk":"11806688418","pt":1722705534820,"mc":[{"id":"1.231344137","rc":[{"batb":[[0,2.04,15.62]],"ltp":2.08,"tv":27877.46,"id":2219}]}]}
{"op":"mcm","clk":"11806827103","pt":1722706309091,"mc":[{"id":"1.231344137","rc":[{"batb":[[0,1.83,10]],"ltp":2.08,"tv":27877.46,"id":2219}]}]}
{"op":"mcm","clk":"11806827396","pt":1722706310879,"mc":[{"id":"1.231344137","rc":[{"batb":[[0,1.99,40.8],[1,1.83,10],[2,1.82,7]],"ltp":2.08,"tv":27877.46,"id":2219}]}]}
{"op":"mcm","clk":"11806827650","pt":1722706312390,"mc":[{"id":"1.231344137","rc":[{"batb":[[1,1.82,7],[2,1.41,85.28]],"ltp":2.08,"tv":27877.46,"id":2219}]}]}
{"op":"mcm","clk":"11806827797","pt":1722706313182,"mc":[{"id":"1.231344137","rc":[{"batb":[[0,2,12.61],[1,1.99,40.8],[2,1.82,7]],"ltp":2.08,"tv":27877.46,"id":2219},{"batb":[[0,1.95,10],[1,1.94,4],[2,1.93,42.85]],"batl":[[0,2,2.65]],"ltp":1.93,"tv":43427.8,"id":2120}]}]}
{"op":"mcm","clk":"11806828388","pt":1722706316598,"mc":[{"id":"1.231344137","rc":[{"batb":[[0,1.94,4],[1,1.93,42.85],[2,1.92,200]],"ltp":1.93,"tv":43427.8,"id":2120}]}]}
{"op":"mcm","clk":"11806886679","pt":1722706647650,"mc":[{"id":"1.231344137","rc":[{"trd":[[2,12.18]],"batb":[[0,1.99,41.23],[1,1.82,7],[2,1.41,85.28]],"ltp":2.0,"tv":27889.64,"id":2219},{"trd":[[2,17.49]],"ltp":2.0,"tv":43445.29,"id":2120}],"tv":71334.93}]}
{"op":"mcm","clk":"11806886751","pt":1722706648066,"mc":[{"id":"1.231344137","rc":[{"batb":[[0,1.99,40.8]],"ltp":2.0,"tv":27889.64,"id":2219}]}]}
{"op":"mcm","clk":"11806888553","pt":1722706657864,"mc":[{"id":"1.231344137","rc":[{"batb":[[0,1.99,44.8]],"ltp":2.0,"tv":27889.64,"id":2219}]}]}
