{"op":"mcm","clk":"11814166150","pt":1723325405720,"mc":[{"id":"1.231679052","marketDefinition":{"bspMarket":false,"turnInPlayEnabled":true,"persistenceEnabled":true,"marketBaseRate":5.0,"eventId":"33484467","eventTypeId":"4","numberOfWinners":1,"bettingType":"ODDS","marketType":"MATCH_ODDS","marketTime":"2024-08-11T16:00:00.000Z","suspendTime":"2024-08-11T16:00:00.000Z","bspReconciled":false,"complete":true,"inPlay":false,"crossMatching":true,"runnersVoidable":false,"numberOfActiveRunners":2,"betDelay":0,"status":"OPEN","runners":[{"status":"ACTIVE","sortPriority":1,"id":19144241,"name":"Montreal Tigers"},{"status":"ACTIVE","sortPriority":2,"id":19144236,"name":"Toronto Nationals"}],"regulators":["MR_INT"],"countryCode":"GB","discountAllowed":false,"timezone":"GMT","openDate":"2024-08-11T16:00:00.000Z","version":6068162673,"name":"Match Odds","eventName":"Montreal Tigers v Toronto Nationals"},"rc":[{"batb":[[0,1.01,20]],"ltp":0.0,"tv":0.0,"id":19144236},{"batb":[[0,1.01,20]],"ltp":0.0,"tv":0.0,"id":19144241}]}]}
{"op":"mcm","clk":"11814166223","pt":1723325407395,"mc":[{"id":"1.231679052","rc":[{"batb":[[0,1.03,200],[1,1.02,200],[2,1.01,220]],"ltp":0.0,"tv":0.0,"id":19144236},{"batb":[[0,1.03,200],[1,1.02,200],[2,1.01,220]],"ltp":0.0,"tv":0.0,"id":19144241}]}]}
{"op":"mcm","clk":"11814166236","pt":1723325407404,"mc":[{"id":"1.231679052","marketDefinition":{"bspMarket":false,"turnInPlayEnabled":true,"persistenceEnabled":true,"marketBaseRate":5.0,"eventId":"33484467","eventTypeId":"4","numberOfWinners":1,"bettingType":"ODDS","marketType":"MATCH_ODDS","marketTime":"2024-08-11T16:00:00.000Z","suspendTime":"2024-08-11T16:00:00.000Z","bspReconciled":false,"complete":true,"inPlay":false,"crossMatching":true,"runnersVoidable":false,"numberOfActiveRunners":2,"betDelay":0,"status":"OPEN","runners":[{"status":"ACTIVE","sortPriority":1,"id":19144241,"name":"Montreal Tigers"},{"status":"ACTIVE","sortPriority":2,"id":19144236,"name":"Toronto Nationals"}],"regulators":["MR_INT"],"countryCode":"GB","discountAllowed":true,"timezone":"GMT","openDate":"2024-08-11T16:00:00.000Z","version":6068162673,"name":"Match Odds","eventName":"Montreal Tigers v Toronto Nationals"}}]}
{"op":"mcm","clk":"11814169753","pt":1723325489295,"mc":[{"id":"1.231679052","rc":[{"batb":[[1,1.02,3396.4],[2,1.01,6424.97]],"ltp":0.0,"tv":0.0,"id":19144236},{"batb":[[0,1.04,1635.51],[1,1.03,2364.67],[2,1.02,3396.4]],"ltp":0.0,"tv":0.0,"id":19144241}]}]}
{"op":"mcm","clk":"11814169819","pt":1723325490121,"mc":[{"id":"1.231679052","rc":[{"batb":[[0,1.04,1635.51],[1,1.03,2364.67],[2,1.02,3396.4]],"ltp":0.0,"tv":0.0,"id":19144236}]}]}
{"op":"mcm","clk":"11814214734","pt":1723326361652,"mc":[{"id":"1.231679052","rc":[{"batb":[[0,1.79,18.28],[1,1.04,1635.51],[2,1.03,2364.67]],"ltp":0.0,"tv":0.0,"id":19144236},{"batb":[[0,1.43,26.85],[1,1.04,1635.51],[2,1.03,2364.67]],"ltp":0.0,"tv":0.0,"id":19144241}]}]}
{"op":"mcm","clk":"11814218636","pt":1723326442088,"mc":[{"id":"1.231679052","rc":[{"batb":[[0,2.08,7.74],[1,1.79,18.28],[2,1.04,1635.51]],"ltp":0.0,"tv":0.0,"id":19144236},{"batb":[[0,1.71,9.42],[1,1.43,26.85],[2,1.04,1635.51]],"ltp":0.0,"tv":0.0,"id":19144241}]}]}
{"op":"mcm","clk":"11814228288","pt":1723326662037,"mc":[{"id":"1.231679052","rc":[{"batb":[[1,1.04,1635.51],[2,1.03,2364.67]],"ltp":0.0,"tv":0.0,"id":19144236},{"batb":[[1,1.04,1635.51],[2,1.03,2364.67]],"ltp":0.0,"tv":0.0,"id":19144241}]}]}
{"op":"mcm","clk":"11814246353","pt":1723327143624,"mc":[{"id":"1.231679052","rc":[{"batb":[[0,1.65,19.85]],"ltp":0.0,"tv":0.0,"id":19144236},{"batb":[[0,1.39,27.63]],"ltp":0.0,"tv":0.0,"id":19144241}]}]}
{"op":"mcm","clk":"11814267433","pt":1723327611880,"mc":[{"id":"1.231679052","rc":[{"batb":[[0,2.06,7.8],[1,1.65,19.85],[2,1.04,1635.51]],"ltp":0.0,"tv":0.0,"id":19144236},{"batb":[[0,1.72,9.35],[1,1.39,27.63],[2,1.04,1635.51]],"ltp":0.0,"tv":0.0,"id":19144241}]}]}
{"op":"mcm","clk":"11814273615","pt":1723327743893,"mc":[{"id":"1.231679052","rc":[{"batb":[[1,1.04,1635.51],[2,1.03,2364.67]],"ltp":0.0,"tv":0.0,"id":19144236},{"batb":[[1,1.04,1635.51],[2,1.03,2364.67]],"ltp":0.0,"tv":0.0,"id":19144241}]}]}
{"op":"mcm","clk":"11814283121","pt":1723327926351,"mc":[{"id":"1.231679052","rc":[{"batb":[[0,2.08,36.15],[1,2.06,7.8],[2,1.04,1635.51]],"ltp":0.0,"tv":0.0,"id":19144236},{"batb":[[0,1.84,46.47],[1,1.72,9.35],[2,1.04,1635.51]],"ltp":0.0,"tv":0.0,"id":19144241}]}]}
{"op":"mcm","clk":"11814299957","pt":1723328043998,"mc":[{"id":"1.231679052","rc":[{"batb":[[1,1.74,9.3]],"ltp":0.0,"tv":0.0,"id":19144241}]}]}
{"op":"mcm","clk":"11814463880","pt":1723331097540,"mc":[{"id":"1.231679052","rc":[{"batb":[[1,1.04,1635.51],[2,1.03,2364.67]],"ltp":0.0,"tv":0.0,"id":19144236},{"batb":[[1,1.04,1635.51],[2,1.03,2364.67]],"ltp":0.0,"tv":0.0,"id":19144241}]}]}
{"op":"mcm","clk":"11814518363","pt":1723332069241,"mc":[{"id":"1.231679052","rc":[{"trd":[[2.2,32.53]],"batb":[[0,1.04,1635.51],[1,1.03,2364.67],[2,1.02,3396.4]],"ltp":2.2,"tv":32.53,"id":19144236},{"trd":[[1.84,38.89]],"batb":[[0,1.76,51.37]],"ltp":1.84,"tv":38.89,"id":19144241}],"tv":71.42}]}
{"op":"mcm","clk":"11814518374","pt":1723332069445,"mc":[{"id":"1.231679052","rc":[{"batb":[[0,1.66,39.46],[1,1.04,1635.51],[2,1.03,2364.67]],"ltp":2.2,"tv":32.53,"id":19144236}]}]}
{"op":"mcm","clk":"11814518648","pt":1723332074116,"mc":[{"id":"1.231679052","rc":[{"batb":[[0,2.12,34.85],[1,1.66,39.46],[2,1.04,1635.51]],"ltp":2.2,"tv":32.53,"id":19144236}]}]}
{"op":"mcm","clk":"11814525779","pt":1723332216788,"mc":[{"id":"1.231679052","rc":[{"batb":[[1,1.04,1635.51],[2,1.03,2364.67]],"ltp":2.2,"tv":32.53,"id":19144236}]}]}
{"op":"mcm","clk":"11814534289","pt":1723332376098,"mc":[{"id":"1.231679052","rc":[{"batb":[[1,2.08,7.76],[2,1.04,1635.51]],"ltp":2.2,"tv":32.53,"id":19144236},{"batb":[[1,1.72,9.39],[2,1.04,1635.51]],"ltp":1.84,"tv":38.89,"id":19144241}]}]}
{"op":"mcm","clk":"11814592332","pt":1723333283439,"mc":[{"id":"1.231679052","rc":[{"batb":[[1,1.04,1635.51],[2,1.03,2364.67]],"ltp":2.2,"tv":32.53,"id":19144236},{"batb":[[1,1.04,1635.51],[2,1.03,2364.67]],"ltp":1.84,"tv":38.89,"id":19144241}]}]}
{"op":"mcm","clk":"11814627821","pt":1723333602501,"mc":[{"id":"1.231679052","rc":[{"batb":[[1,2.08,7.74],[2,1.04,1635.51]],"ltp":2.2,"tv":32.53,"id":19144236},{"batb":[[1,1.71,9.42],[2,1.04,1635.51]],"ltp":1.84,"tv":38.89,"id":19144241}]}]}
{"op":"mcm","clk":"11814762369","pt":1723335463798,"mc":[{"id":"1.231679052","rc":[{"batb":[[1,1.04,1635.51],[2,1.03,2364.67]],"ltp":2.2,"tv":32.53,"id":19144236},{"batb":[[1,1.04,1635.51],[2,1.03,2364.67]],"ltp":1.84,"tv":38.89,"id":19144241}]}]}
{"op":"mcm","clk":"11814767006","pt":1723335520479,"mc":[{"id":"1.231679052","rc":[{"batb":[[1,2.1,7.7],[2,1.04,1635.51]],"ltp":2.2,"tv":32.53,"id":19144236},{"batb":[[1,1.71,9.45],[2,1.04,1635.51]],"ltp":1.84,"tv":38.89,"id":19144241}]}]}
{"op":"mcm","clk":"11814788841","pt":1723335792363,"mc":[{"id":"1.231679052","rc":[{"batb":[[1,1.04,1635.51],[2,1.03,2364.67]],"ltp":2.2,"tv":32.53,"id":19144236},{"batb":[[1,1.04,1635.51],[2,1.03,2364.67]],"ltp":1.84,"tv":38.89,"id":19144241}]}]}
{"op":"mcm","clk":"11814815432","pt":1723336158506,"mc":[{"id":"1.231679052","rc":[{"batb":[[1,2.1,7.7],[2,1.04,1635.51]],"ltp":2.2,"tv":32.53,"id":19144236},{"batb":[[1,1.71,9.45],[2,1.04,1635.51]],"ltp":1.84,"tv":38.89,"id":19144241}]}]}
{"op":"mcm","clk":"11814828953","pt":1723336334381,"mc":[{"id":"1.231679052","rc":[{"batb":[[1,1.04,1635.51],[2,1.03,2364.67]],"ltp":2.2,"tv":32.53,"id":19144236},{"batb":[[1,1.04,1635.51],[2,1.03,2364.67]],"ltp":1.84,"tv":38.89,"id":19144241}]}]}
{"op":"mcm","clk":"11814850222","pt":1723336606627,"mc":[{"id":"1.231679052","rc":[{"batb":[[1,2.1,7.7],[2,1.04,1635.51]],"ltp":2.2,"tv":32.53,"id":19144236},{"batb":[[1,1.71,9.45],[2,1.04,1635.51]],"ltp":1.84,"tv":38.89,"id":19144241}]}]}
{"op":"mcm","clk":"11814859851","pt":1723336730344,"mc":[{"id":"1.231679052","rc":[{"batb":[[1,1.04,1635.51],[2,1.03,2364.67]],"ltp":2.2,"tv":32.53,"id":19144236},{"batb":[[1,1.04,1635.51],[2,1.03,2364.67]],"ltp":1.84,"tv":38.89,"id":19144241}]}]}
{"op":"mcm","clk":"11814864693","pt":1723336787571,"mc":[{"id":"1.231679052","rc":[{"batb":[[1,2.1,7.7],[2,1.04,1635.51]],"ltp":2.2,"tv":32.53,"id":19144236},{"batb":[[1,1.71,9.45],[2,1.04,1635.51]],"ltp":1.84,"tv":38.89,"id":19144241}]}]}
{"op":"mcm","clk":"11814889693","pt":1723337090800,"mc":[{"id":"1.231679052","rc":[{"batb":[[1,1.04,1635.51],[2,1.03,2364.67]],"ltp":2.2,"tv":32.53,"id":19144236},{"batb":[[1,1.04,1635.51],[2,1.03,2364.67]],"ltp":1.84,"tv":38.89,"id":19144241}]}]}
{"op":"mcm","clk":"11814903611","pt":1723337247595,"mc":[{"id":"1.231679052","rc":[{"batb":[[1,2.1,7.7],[2,1.04,1635.51]],"ltp":2.2,"tv":32.53,"id":19144236},{"batb":[[1,1.71,9.45],[2,1.04,1635.51]],"ltp":1.84,"tv":38.89,"id":19144241}]}]}
{"op":"mcm","clk":"11815265798","pt":1723342088796,"mc":[{"id":"1.231679052","rc":[{"batb":[[1,1.04,1635.51],[2,1.03,2364.67]],"ltp":2.2,"tv":32.53,"id":19144236},{"batb":[[1,1.04,1635.51],[2,1.03,2364.67]],"ltp":1.84,"tv":38.89,"id":19144241}]}]}
{"op":"mcm","clk":"11815305947","pt":1723342703248,"mc":[{"id":"1.231679052","rc":[{"batb":[[1,2.1,7.7],[2,1.04,1635.51]],"ltp":2.2,"tv":32.53,"id":19144236},{"batb":[[1,1.71,9.45],[2,1.04,1635.51]],"ltp":1.84,"tv":38.89,"id":19144241}]}]}
{"op":"mcm","clk":"11815335437","pt":1723343092226,"mc":[{"id":"1.231679052","rc":[{"batb":[[1,1.04,1635.51],[2,1.03,2364.67]],"ltp":2.2,"tv":32.53,"id":19144236},{"batb":[[1,1.04,1635.51],[2,1.03,2364.67]],"ltp":1.84,"tv":38.89,"id":19144241}]}]}
{"op":"mcm","clk":"11815370591","pt":1723343600799,"mc":[{"id":"1.231679052","rc":[{"batb":[[1,2.1,7.7],[2,1.04,1635.51]],"ltp":2.2,"tv":32.53,"id":19144236},{"batb":[[1,1.71,9.45],[2,1.04,1635.51]],"ltp":1.84,"tv":38.89,"id":19144241}]}]}
{"op":"mcm","clk":"11815540549","pt":1723346220599,"mc":[{"id":"1.231679052","rc":[{"trd":[[2.12,1.04]],"batb":[[0,2.12,34.33]],"ltp":2.12,"tv":33.56,"id":19144236}],"tv":72.45}]}
{"op":"mcm","clk":"11815540720","pt":1723346223219,"mc":[{"id":"1.231679052","rc":[{"batb":[[0,2.12,34.85]],"ltp":2.12,"tv":33.56,"id":19144236}]}]}
{"op":"mcm","clk":"11815640438","pt":1723348220593,"mc":[{"id":"1.231679052","rc":[{"batb":[[1,1.04,1635.51],[2,1.03,2364.67]],"ltp":2.12,"tv":33.56,"id":19144236},{"batb":[[1,1.04,1635.51],[2,1.03,2364.67]],"ltp":1.84,"tv":38.89,"id":19144241}]}]}
{"op":"mcm","clk":"11815642195","pt":1723348260948,"mc":[{"id":"1.231679052","rc":[{"batl":[[0,1.9,21]],"ltp":1.84,"tv":38.89,"id":19144241}]}]}
{"op":"mcm","clk":"11815689830","pt":1723349203627,"mc":[{"id":"1.231679052","rc":[{"batb":[[1,2.1,7.68],[2,1.04,1635.51]],"ltp":2.12,"tv":33.56,"id":19144236},{"batb":[[1,1.7,9.48],[2,1.04,1635.51]],"ltp":1.84,"tv":38.89,"id":19144241}]}]}
{"op":"mcm","clk":"11815760244","pt":1723350487773,"mc":[{"id":"1.231679052","rc":[{"batl":[[0,1.88,30],[1,1.9,21]],"ltp":1.84,"tv":38.89,"id":19144241}]}]}
{"op":"mcm","clk":"11815762004","pt":1723350534894,"mc":[{"id":"1.231679052","rc":[{"batl":[[0,1.9,21],[1,1.9,0]],"ltp":1.84,"tv":38.89,"id":19144241}]}]}
{"op":"mcm","clk":"11815822059","pt":1723352119316,"mc":[{"id":"1.231679052","rc":[{"batb":[[2,1.05,5.19]],"ltp":1.84,"tv":38.89,"id":19144241}]}]}
{"op":"mcm","clk":"11815946766","pt":1723355829638,"mc":[{"id":"1.231679052","rc":[{"batl":[[0,1.89,15],[1,1.9,21]],"ltp":1.84,"tv":38.89,"id":19144241}]}]}
{"op":"mcm","clk":"11815992142","pt":1723357767543,"mc":[{"id":"1.231679052","rc":[{"batb":[[1,1.04,1635.51],[2,1.03,2364.67]],"ltp":2.12,"tv":33.56,"id":19144236},{"batb":[[1,1.05,5.19],[2,1.04,1635.51]],"ltp":1.84,"tv":38.89,"id":19144241}]}]}
{"op":"mcm","clk":"11816063969","pt":1723360342633,"mc":[{"id":"1.231679052","rc":[{"trd":[[2.12,21.04]],"batb":[[0,2.12,24.85]],"ltp":2.12,"tv":53.56,"id":19144236}],"tv":92.45}]}
{"op":"mcm","clk":"11816064014","pt":1723360343621,"mc":[{"id":"1.231679052","rc":[{"batb":[[0,2.12,34.85]],"ltp":2.12,"tv":53.56,"id":19144236}]}]}
{"op":"mcm","clk":"11816162075","pt":1723362452674,"mc":[{"id":"1.231679052","rc":[{"batb":[[1,2.1,7.68],[2,1.04,1635.51]],"ltp":2.12,"tv":53.56,"id":19144236},{"batb":[[1,1.7,9.48],[2,1.05,5.19]],"ltp":1.84,"tv":38.89,"id":19144241}]}]}
{"op":"mcm","clk":"11816226620","pt":1723363809672,"mc":[{"id":"1.231679052","rc":[{"trd":[[1.76,5.16]],"batb":[[0,1.76,48.79]],"ltp":1.76,"tv":44.04,"id":19144241}],"tv":97.61}]}
{"op":"mcm","clk":"11816226854","pt":1723363814153,"mc":[{"id":"1.231679052","rc":[{"batb":[[0,1.76,51.37]],"ltp":1.76,"tv":44.04,"id":19144241}]}]}
{"op":"mcm","clk":"11816258524","pt":1723364418019,"mc":[{"id":"1.231679052","rc":[{"batb":[[2,1.26,4.7]],"ltp":1.76,"tv":44.04,"id":19144241}]}]}
{"op":"mcm","clk":"11816258901","pt":1723364423485,"mc":[{"id":"1.231679052","rc":[{"batb":[[2,1.26,4.7]],"ltp":2.12,"tv":53.56,"id":19144236}]}]}
{"op":"mcm","clk":"11816421377","pt":1723366759612,"mc":[{"id":"1.231679052","rc":[{"batb":[[1,1.26,4.7],[2,1.04,1635.51]],"ltp":2.12,"tv":53.56,"id":19144236},{"batb":[[1,1.26,4.7],[2,1.05,5.19]],"ltp":1.76,"tv":44.04,"id":19144241}]}]}
{"op":"mcm","clk":"11816552330","pt":1723368579479,"mc":[{"id":"1.231679052","rc":[{"batb":[[1,1.26,100.85]],"ltp":1.76,"tv":44.04,"id":19144241}]}]}
{"op":"mcm","clk":"11816552593","pt":1723368583264,"mc":[{"id":"1.231679052","rc":[{"batb":[[1,1.26,100.85]],"ltp":2.12,"tv":53.56,"id":19144236}]}]}
{"op":"mcm","clk":"11816602307","pt":1723369236670,"mc":[{"id":"1.231679052","rc":[{"batb":[[1,1.72,92.94],[2,1.26,100.85]],"ltp":1.76,"tv":44.04,"id":19144241}]}]}
{"op":"mcm","clk":"11816603129","pt":1723369246365,"mc":[{"id":"1.231679052","rc":[{"batb":[[1,2.06,63.13],[2,1.26,100.85]],"ltp":2.12,"tv":53.56,"id":19144236}]}]}
{"op":"mcm","clk":"11816647629","pt":1723369790079,"mc":[{"id":"1.231679052","rc":[{"batb":[[2,1.74,17.32]],"ltp":2.12,"tv":53.56,"id":19144236},{"batb":[[1,1.74,17.32],[2,1.72,92.94]],"ltp":1.76,"tv":44.04,"id":19144241}]}]}
{"op":"mcm","clk":"11816846482","pt":1723371478356,"mc":[{"id":"1.231679052","rc":[{"trd":[[1.76,7.16]],"batb":[[0,1.76,50.37]],"ltp":1.76,"tv":46.04,"id":19144241}],"tv":99.61}]}
{"op":"mcm","clk":"11816846621","pt":1723371479621,"mc":[{"id":"1.231679052","rc":[{"batb":[[0,1.76,51.37]],"ltp":1.76,"tv":46.04,"id":19144241}]}]}
{"op":"mcm","clk":"11816847035","pt":1723371483525,"mc":[{"id":"1.231679052","rc":[{"trd":[[1.89,2]],"batl":[[0,1.89,14]],"ltp":1.89,"tv":48.04,"id":19144241}],"tv":101.61}]}
{"op":"mcm","clk":"11816909357","pt":1723372002669,"mc":[{"id":"1.231679052","rc":[{"batb":[[1,2.1,7.68],[2,2.06,63.13]],"ltp":2.12,"tv":53.56,"id":19144236}]}]}
{"op":"mcm","clk":"11817078654","pt":1723373332671,"mc":[{"id":"1.231679052","rc":[{"batb":[[1,2.06,63.13],[2,1.74,17.32]],"ltp":2.12,"tv":53.56,"id":19144236}]}]}
{"op":"mcm","clk":"11817081758","pt":1723373356908,"mc":[{"id":"1.231679052","rc":[{"batb":[[1,2.1,7.68],[2,2.06,63.13]],"ltp":2.12,"tv":53.56,"id":19144236}]}]}
{"op":"mcm","clk":"11817241000","pt":1723374852459,"mc":[{"id":"1.231679052","rc":[{"batb":[[1,2.06,63.13],[2,1.74,17.32]],"ltp":2.12,"tv":53.56,"id":19144236}]}]}
{"op":"mcm","clk":"11817263241","pt":1723375024121,"mc":[{"id":"1.231679052","rc":[{"batl":[[0,1.88,21],[1,1.89,14]],"ltp":1.89,"tv":48.04,"id":19144241}]}]}
{"op":"mcm","clk":"11817548004","pt":1723377275297,"mc":[{"id":"1.231679052","rc":[{"batb":[[1,2.1,7.68],[2,2.06,63.13]],"ltp":2.12,"tv":53.56,"id":19144236}]}]}
{"op":"mcm","clk":"11817671667","pt":1723378475942,"mc":[{"id":"1.231679052","rc":[{"batb":[[0,2.3,2.36],[1,2.12,34.85],[2,2.1,7.68]],"ltp":2.12,"tv":53.56,"id":19144236}]}]}
{"op":"mcm","clk":"11817672676","pt":1723378486654,"mc":[{"id":"1.231679052","rc":[{"batb":[[0,2.12,34.85],[1,2.1,7.68],[2,2.06,63.13]],"ltp":2.12,"tv":53.56,"id":19144236}]}]}
{"op":"mcm","clk":"11817680391","pt":1723378556542,"mc":[{"id":"1.231679052","rc":[{"batb":[[0,1.87,2.36],[1,1.76,51.37],[2,1.74,17.32]],"ltp":1.89,"tv":48.04,"id":19144241}]}]}
{"op":"mcm","clk":"11817681886","pt":1723378570155,"mc":[{"id":"1.231679052","rc":[{"batb":[[0,1.76,51.37],[1,1.74,17.32],[2,1.72,92.94]],"ltp":1.89,"tv":48.04,"id":19144241}]}]}
{"op":"mcm","clk":"11817683267","pt":1723378582861,"mc":[{"id":"1.231679052","rc":[{"batb":[[0,2.3,2.36],[1,2.12,34.85],[2,2.1,7.68]],"ltp":2.12,"tv":53.56,"id":19144236}]}]}
{"op":"mcm","clk":"11817684588","pt":1723378594974,"mc":[{"id":"1.231679052","rc":[{"batb":[[0,2.12,34.85],[1,2.1,7.68],[2,2.06,63.13]],"ltp":2.12,"tv":53.56,"id":19144236}]}]}
{"op":"mcm","clk":"11817686139","pt":1723378609689,"mc":[{"id":"1.231679052","rc":[{"batb":[[0,1.87,2.36],[1,1.76,51.37],[2,1.74,17.32]],"ltp":1.89,"tv":48.04,"id":19144241}]}]}
{"op":"mcm","clk":"11817687563","pt":1723378623414,"mc":[{"id":"1.231679052","rc":[{"batb":[[0,1.76,51.37],[1,1.74,17.32],[2,1.72,92.94]],"ltp":1.89,"tv":48.04,"id":19144241}]}]}
{"op":"mcm","clk":"11817687815","pt":1723378625745,"mc":[{"id":"1.231679052","rc":[{"trd":[[2.12,28.33]],"batb":[[0,2.12,31.2]],"ltp":2.12,"tv":60.86,"id":19144236}],"tv":108.9}]}
{"op":"mcm","clk":"11817687992","pt":1723378627318,"mc":[{"id":"1.231679052","rc":[{"batb":[[0,2.12,66.05]],"ltp":2.12,"tv":60.86,"id":19144236}]}]}
{"op":"mcm","clk":"11817688007","pt":1723378627423,"mc":[{"id":"1.231679052","rc":[{"batb":[[0,2.12,34.85]],"ltp":2.12,"tv":60.86,"id":19144236}]}]}
{"op":"mcm","clk":"11817689373","pt":1723378639519,"mc":[{"id":"1.231679052","rc":[{"batb":[[0,2.3,3.14],[1,2.12,34.85],[2,2.1,7.68]],"ltp":2.12,"tv":60.86,"id":19144236}]}]}
{"op":"mcm","clk":"11817690985","pt":1723378655034,"mc":[{"id":"1.231679052","rc":[{"batb":[[2,2.06,63.13]],"ltp":2.12,"tv":60.86,"id":19144236}]}]}
{"op":"mcm","clk":"11817691171","pt":1723378656645,"mc":[{"id":"1.231679052","rc":[{"batb":[[0,2.12,34.85],[1,2.06,63.13],[2,1.74,17.32]],"ltp":2.12,"tv":60.86,"id":19144236}]}]}
{"op":"mcm","clk":"11817692838","pt":1723378672274,"mc":[{"id":"1.231679052","rc":[{"batb":[[0,1.87,2.36],[1,1.76,51.37],[2,1.74,17.32]],"ltp":1.89,"tv":48.04,"id":19144241}]}]}
{"op":"mcm","clk":"11817694249","pt":1723378686161,"mc":[{"id":"1.231679052","rc":[{"batb":[[0,1.76,51.37],[1,1.74,17.32],[2,1.72,92.94]],"ltp":1.89,"tv":48.04,"id":19144241}]}]}
{"op":"mcm","clk":"11817695462","pt":1723378697877,"mc":[{"id":"1.231679052","rc":[{"batb":[[0,2.3,2.36],[1,2.12,34.85],[2,2.06,63.13]],"ltp":2.12,"tv":60.86,"id":19144236}]}]}
{"op":"mcm","clk":"11817696870","pt":1723378711997,"mc":[{"id":"1.231679052","rc":[{"batb":[[0,2.12,34.85],[1,2.06,63.13],[2,1.74,17.32]],"ltp":2.12,"tv":60.86,"id":19144236}]}]}
{"op":"mcm","clk":"11817698764","pt":1723378727798,"mc":[{"id":"1.231679052","rc":[{"batb":[[0,1.87,2.36],[1,1.76,51.37],[2,1.74,17.32]],"ltp":1.89,"tv":48.04,"id":19144241}]}]}
{"op":"mcm","clk":"11817699944","pt":1723378738475,"mc":[{"id":"1.231679052","rc":[{"trd":[[1.87,4.72]],"batb":[[0,1.76,51.37],[1,1.74,17.32],[2,1.72,92.94]],"batl":[[0,1.88,21.13]],"ltp":1.87,"tv":52.76,"id":19144241}],"tv":113.62}]}
{"op":"mcm","clk":"11817700855","pt":1723378747266,"mc":[{"id":"1.231679052","rc":[{"batb":[[0,1.8,2.49],[1,1.76,51.37],[2,1.74,17.32]],"ltp":1.87,"tv":52.76,"id":19144241}]}]}
{"op":"mcm","clk":"11817701009","pt":1723378748848,"mc":[{"id":"1.231679052","rc":[{"trd":[[1.87,4.98]],"batb":[[0,1.87,2.22],[1,1.8,2.49],[2,1.76,51.37]],"batl":[[0,1.88,21]],"ltp":1.87,"tv":53.02,"id":19144241}],"tv":113.88}]}
{"op":"mcm","clk":"11817702770","pt":1723378765857,"mc":[{"id":"1.231679052","rc":[{"batb":[[0,1.8,2.49],[1,1.76,51.37],[2,1.74,17.32]],"ltp":1.87,"tv":53.02,"id":19144241}]}]}
{"op":"mcm","clk":"11817704210","pt":1723378779655,"mc":[{"id":"1.231679052","rc":[{"batb":[[0,2.24,2.36],[1,2.12,34.85],[2,2.06,63.13]],"ltp":2.12,"tv":60.86,"id":19144236}]}]}
{"op":"mcm","clk":"11817705671","pt":1723378794211,"mc":[{"id":"1.231679052","rc":[{"batb":[[0,2.12,34.85],[1,2.06,63.13],[2,1.74,17.32]],"ltp":2.12,"tv":60.86,"id":19144236}]}]}
{"op":"mcm","clk":"11817706877","pt":1723378807200,"mc":[{"id":"1.231679052","rc":[{"batb":[[0,1.87,2.36],[1,1.8,2.49],[2,1.76,51.37]],"ltp":1.87,"tv":53.02,"id":19144241}]}]}
{"op":"mcm","clk":"11817708123","pt":1723378820107,"mc":[{"id":"1.231679052","rc":[{"batb":[[0,1.8,2.49],[1,1.76,51.37],[2,1.74,17.32]],"ltp":1.87,"tv":53.02,"id":19144241}]}]}
{"op":"mcm","clk":"11817711313","pt":1723378852060,"mc":[{"id":"1.231679052","rc":[{"batb":[[0,2.24,2.36],[1,2.12,34.85],[2,2.06,63.13]],"ltp":2.12,"tv":60.86,"id":19144236}]}]}
{"op":"mcm","clk":"11817712546","pt":1723378864843,"mc":[{"id":"1.231679052","rc":[{"batb":[[0,2.12,34.85],[1,2.06,63.13],[2,1.74,17.32]],"ltp":2.12,"tv":60.86,"id":19144236}]}]}
{"op":"mcm","clk":"11817717757","pt":1723378919005,"mc":[{"id":"1.231679052","rc":[{"batb":[[0,1.87,2.36],[1,1.8,2.49],[2,1.76,51.37]],"ltp":1.87,"tv":53.02,"id":19144241}]}]}
{"op":"mcm","clk":"11817719518","pt":1723378937526,"mc":[{"id":"1.231679052","rc":[{"batb":[[0,1.8,2.49],[1,1.76,51.37],[2,1.74,17.32]],"ltp":1.87,"tv":53.02,"id":19144241}]}]}
{"op":"mcm","clk":"11817723302","pt":1723378976570,"mc":[{"id":"1.231679052","rc":[{"batb":[[0,1.87,2.36],[1,1.8,2.49],[2,1.76,51.37]],"ltp":1.87,"tv":53.02,"id":19144241}]}]}
{"op":"mcm","clk":"11817726601","pt":1723379009286,"mc":[{"id":"1.231679052","rc":[{"batb":[[0,1.8,2.49],[1,1.76,51.37],[2,1.74,17.32]],"ltp":1.87,"tv":53.02,"id":19144241}]}]}
{"op":"mcm","clk":"11817733178","pt":1723379072090,"mc":[{"id":"1.231679052","rc":[{"batb":[[0,2.24,3.14],[1,2.12,34.85],[2,2.06,63.13]],"ltp":2.12,"tv":60.86,"id":19144236}]}]}
{"op":"mcm","clk":"11817735826","pt":1723379099924,"mc":[{"id":"1.231679052","rc":[{"batb":[[0,2.12,34.85],[1,2.06,63.13],[2,1.74,17.32]],"ltp":2.12,"tv":60.86,"id":19144236}]}]}
{"op":"mcm","clk":"11817738439","pt":1723379126031,"mc":[{"id":"1.231679052","rc":[{"batb":[[0,1.87,2.36],[1,1.8,2.49],[2,1.76,51.37]],"ltp":1.87,"tv":53.02,"id":19144241}]}]}
{"op":"mcm","clk":"11817741027","pt":1723379154855,"mc":[{"id":"1.231679052","rc":[{"batb":[[0,1.8,2.49],[1,1.76,51.37],[2,1.74,17.32]],"ltp":1.87,"tv":53.02,"id":19144241}]}]}
{"op":"mcm","clk":"11817743851","pt":1723379184693,"mc":[{"id":"1.231679052","rc":[{"batb":[[0,2.24,2.36],[1,2.12,34.85],[2,2.06,63.13]],"ltp":2.12,"tv":60.86,"id":19144236}]}]}
{"op":"mcm","clk":"11817746689","pt":1723379217330,"mc":[{"id":"1.231679052","rc":[{"batb":[[0,2.12,34.85],[1,2.06,63.13],[2,1.74,17.32]],"ltp":2.12,"tv":60.86,"id":19144236}]}]}
{"op":"mcm","clk":"11817748574","pt":1723379238462,"mc":[{"id":"1.231679052","rc":[{"batb":[[0,1.87,2.36],[1,1.8,2.49],[2,1.76,51.37]],"ltp":1.87,"tv":53.02,"id":19144241}]}]}
{"op":"mcm","clk":"11817750029","pt":1723379253963,"mc":[{"id":"1.231679052","rc":[{"batb":[[0,1.8,2.49],[1,1.76,51.37],[2,1.74,17.32]],"ltp":1.87,"tv":53.02,"id":19144241}]}]}
{"op":"mcm","clk":"11817751866","pt":1723379273274,"mc":[{"id":"1.231679052","rc":[{"batb":[[0,1.87,2.36],[1,1.8,2.49],[2,1.76,51.37]],"ltp":1.87,"tv":53.02,"id":19144241}]}]}
{"op":"mcm","clk":"11817754302","pt":1723379297015,"mc":[{"id":"1.231679052","rc":[{"batb":[[0,1.8,2.49],[1,1.76,51.37],[2,1.74,17.32]],"ltp":1.87,"tv":53.02,"id":19144241}]}]}
{"op":"mcm","clk":"11817761210","pt":1723379365400,"mc":[{"id":"1.231679052","rc":[{"batb":[[0,2.24,2.36],[1,2.12,34.85],[2,2.06,63.13]],"ltp":2.12,"tv":60.86,"id":19144236}]}]}
{"op":"mcm","clk":"11817765914","pt":1723379411770,"mc":[{"id":"1.231679052","rc":[{"batb":[[0,2.12,34.85],[1,2.06,63.13],[2,1.74,17.32]],"ltp":2.12,"tv":60.86,"id":19144236}]}]}
{"op":"mcm","clk":"11817768933","pt":1723379439019,"mc":[{"id":"1.231679052","rc":[{"batb":[[0,1.87,2.36],[1,1.8,2.49],[2,1.76,51.37]],"ltp":1.87,"tv":53.02,"id":19144241}]}]}
{"op":"mcm","clk":"11817772430","pt":1723379472853,"mc":[{"id":"1.231679052","rc":[{"batb":[[0,1.8,2.49],[1,1.76,51.37],[2,1.74,17.32]],"ltp":1.87,"tv":53.02,"id":19144241}]}]}
{"op":"mcm","clk":"11817773737","pt":1723379485067,"mc":[{"id":"1.231679052","rc":[{"batb":[[0,2.24,2.36],[1,2.12,34.85],[2,2.06,63.13]],"ltp":2.12,"tv":60.86,"id":19144236}]}]}
{"op":"mcm","clk":"11817777084","pt":1723379519275,"mc":[{"id":"1.231679052","rc":[{"batb":[[0,2.12,34.85],[1,2.06,63.13],[2,1.74,17.32]],"ltp":2.12,"tv":60.86,"id":19144236}]}]}
{"op":"mcm","clk":"11817782002","pt":1723379567056,"mc":[{"id":"1.231679052","rc":[{"batb":[[0,1.87,2.36],[1,1.8,2.49],[2,1.76,51.37]],"ltp":1.87,"tv":53.02,"id":19144241}]}]}
{"op":"mcm","clk":"11817784562","pt":1723379591784,"mc":[{"id":"1.231679052","rc":[{"batb":[[0,1.8,2.49],[1,1.76,51.37],[2,1.74,17.32]],"ltp":1.87,"tv":53.02,"id":19144241}]}]}
{"op":"mcm","clk":"11817791015","pt":1723379655052,"mc":[{"id":"1.231679052","rc":[{"batb":[[0,2.24,2.36],[1,2.12,34.85],[2,2.06,63.13]],"ltp":2.12,"tv":60.86,"id":19144236}]}]}
{"op":"mcm","clk":"11817794482","pt":1723379689473,"mc":[{"id":"1.231679052","rc":[{"batb":[[0,2.12,34.85],[1,2.06,63.13],[2,1.74,17.32]],"ltp":2.12,"tv":60.86,"id":19144236}]}]}
{"op":"mcm","clk":"11817808287","pt":1723379825144,"mc":[{"id":"1.231679052","rc":[{"batb":[[0,1.87,3.14],[1,1.8,2.49],[2,1.76,51.37]],"ltp":1.87,"tv":53.02,"id":19144241}]}]}
{"op":"mcm","clk":"11817812188","pt":1723379856660,"mc":[{"id":"1.231679052","rc":[{"batb":[[0,1.8,2.49],[1,1.76,51.37],[2,1.74,17.32]],"ltp":1.87,"tv":53.02,"id":19144241}]}]}
{"op":"mcm","clk":"11817813273","pt":1723379865770,"mc":[{"id":"1.231679052","rc":[{"batb":[[0,2.24,3.14],[1,2.12,34.85],[2,2.06,63.13]],"ltp":2.12,"tv":60.86,"id":19144236}]}]}
{"op":"mcm","clk":"11817816096","pt":1723379891401,"mc":[{"id":"1.231679052","rc":[{"batb":[[0,2.12,34.85],[1,2.06,63.13],[2,1.74,17.32]],"ltp":2.12,"tv":60.86,"id":19144236}]}]}
{"op":"mcm","clk":"11817819162","pt":1723379920235,"mc":[{"id":"1.231679052","rc":[{"batb":[[0,1.87,2.36],[1,1.8,2.49],[2,1.76,51.37]],"ltp":1.87,"tv":53.02,"id":19144241}]}]}
{"op":"mcm","clk":"11817823012","pt":1723379953276,"mc":[{"id":"1.231679052","rc":[{"batb":[[0,1.8,2.49],[1,1.76,51.37],[2,1.74,17.32]],"ltp":1.87,"tv":53.02,"id":19144241}]}]}
{"op":"mcm","clk":"11817834066","pt":1723380052476,"mc":[{"id":"1.231679052","rc":[{"batb":[[0,2.24,2.36],[1,2.12,34.85],[2,2.06,63.13]],"ltp":2.12,"tv":60.86,"id":19144236}]}]}
{"op":"mcm","clk":"11817838587","pt":1723380093444,"mc":[{"id":"1.231679052","rc":[{"batb":[[0,2.12,34.85],[1,2.06,63.13],[2,1.74,17.32]],"ltp":2.12,"tv":60.86,"id":19144236}]}]}
{"op":"mcm","clk":"11817844155","pt":1723380144801,"mc":[{"id":"1.231679052","rc":[{"batb":[[0,1.87,2.36],[1,1.8,2.49],[2,1.76,51.37]],"ltp":1.87,"tv":53.02,"id":19144241}]}]}
{"op":"mcm","clk":"11817847669","pt":1723380176450,"mc":[{"id":"1.231679052","rc":[{"batb":[[0,1.8,2.49],[1,1.76,51.37],[2,1.74,17.32]],"ltp":1.87,"tv":53.02,"id":19144241}]}]}
{"op":"mcm","clk":"11817850339","pt":1723380199376,"mc":[{"id":"1.231679052","rc":[{"batb":[[0,2.24,2.36],[1,2.12,34.85],[2,2.06,63.13]],"ltp":2.12,"tv":60.86,"id":19144236}]}]}
{"op":"mcm","clk":"11817854354","pt":1723380235386,"mc":[{"id":"1.231679052","rc":[{"batb":[[0,2.12,34.85],[1,2.06,63.13],[2,1.74,17.32]],"ltp":2.12,"tv":60.86,"id":19144236}]}]}
{"op":"mcm","clk":"11817856939","pt":1723380257439,"mc":[{"id":"1.231679052","rc":[{"batb":[[0,1.87,2.36],[1,1.8,2.49],[2,1.76,51.37]],"ltp":1.87,"tv":53.02,"id":19144241}]}]}
{"op":"mcm","clk":"11817859409","pt":1723380278070,"mc":[{"id":"1.231679052","rc":[{"batb":[[0,1.8,2.49],[1,1.76,51.37],[2,1.74,17.32]],"ltp":1.87,"tv":53.02,"id":19144241}]}]}
{"op":"mcm","clk":"11817861856","pt":1723380299091,"mc":[{"id":"1.231679052","rc":[{"batb":[[0,1.87,2.36],[1,1.8,2.49],[2,1.76,51.37]],"ltp":1.87,"tv":53.02,"id":19144241}]}]}
{"op":"mcm","clk":"11817867035","pt":1723380341622,"mc":[{"id":"1.231679052","rc":[{"batb":[[0,1.8,2.49],[1,1.76,51.37],[2,1.74,17.32]],"ltp":1.87,"tv":53.02,"id":19144241}]}]}
{"op":"mcm","clk":"11817875402","pt":1723380412025,"mc":[{"id":"1.231679052","rc":[{"batb":[[0,2.24,2.36],[1,2.12,34.85],[2,2.06,63.13]],"ltp":2.12,"tv":60.86,"id":19144236}]}]}
{"op":"mcm","clk":"11817880636","pt":1723380458069,"mc":[{"id":"1.231679052","rc":[{"batb":[[0,2.12,34.85],[1,2.06,63.13],[2,1.74,17.32]],"ltp":2.12,"tv":60.86,"id":19144236}]}]}
{"op":"mcm","clk":"11817889469","pt":1723380534821,"mc":[{"id":"1.231679052","rc":[{"batb":[[0,1.87,2.36],[1,1.8,2.49],[2,1.76,51.37]],"ltp":1.87,"tv":53.02,"id":19144241}]}]}
{"op":"mcm","clk":"11817891473","pt":1723380553781,"mc":[{"id":"1.231679052","rc":[{"batb":[[1,1.8,22.18]],"ltp":1.87,"tv":53.02,"id":19144241}]}]}
{"op":"mcm","clk":"11817892762","pt":1723380566259,"mc":[{"id":"1.231679052","rc":[{"batl":[[1,1.89,0]],"ltp":1.87,"tv":53.02,"id":19144241}]}]}
{"op":"mcm","clk":"11817893162","pt":1723380570292,"mc":[{"id":"1.231679052","rc":[{"batb":[[0,1.8,22.18],[1,1.76,51.37],[2,1.74,17.32]],"ltp":1.87,"tv":53.02,"id":19144241}]}]}
{"op":"mcm","clk":"11817895411","pt":1723380590626,"mc":[{"id":"1.231679052","rc":[{"batb":[[1,1.77,1],[2,1.76,51.37]],"ltp":1.87,"tv":53.02,"id":19144241}]}]}
{"op":"mcm","clk":"11817896089","pt":1723380596933,"mc":[{"id":"1.231679052","rc":[{"batb":[[0,2.24,2.36],[1,2.12,34.85],[2,2.06,63.13]],"ltp":2.12,"tv":60.86,"id":19144236}]}]}
{"op":"mcm","clk":"11817901485","pt":1723380649892,"mc":[{"id":"1.231679052","rc":[{"batb":[[0,2.12,34.85],[1,2.06,63.13],[2,1.74,17.32]],"ltp":2.12,"tv":60.86,"id":19144236}]}]}
{"op":"mcm","clk":"11817904318","pt":1723380678846,"mc":[{"id":"1.231679052","rc":[{"batb":[[0,1.87,2.36],[1,1.8,22.18],[2,1.77,1]],"ltp":1.87,"tv":53.02,"id":19144241}]}]}
{"op":"mcm","clk":"11817911475","pt":1723380757110,"mc":[{"id":"1.231679052","rc":[{"batb":[[0,1.8,22.18],[1,1.77,1],[2,1.76,51.37]],"ltp":1.87,"tv":53.02,"id":19144241}]}]}
{"op":"mcm","clk":"11817912442","pt":1723380769331,"mc":[{"id":"1.231679052","rc":[{"batb":[[0,1.8,19.69]],"ltp":1.87,"tv":53.02,"id":19144241}]}]}
{"op":"mcm","clk":"11817913540","pt":1723380782646,"mc":[{"id":"1.231679052","rc":[{"batb":[[0,1.82,2.49],[1,1.8,19.69],[2,1.77,1]],"ltp":1.87,"tv":53.02,"id":19144241}]}]}
{"op":"mcm","clk":"11817914018","pt":1723380787665,"mc":[{"id":"1.231679052","rc":[{"batb":[[1,1.77,1],[2,1.76,51.37]],"ltp":1.87,"tv":53.02,"id":19144241}]}]}
{"op":"mcm","clk":"11817914820","pt":1723380797000,"mc":[{"id":"1.231679052","rc":[{"batb":[[1,1.77,20.69]],"ltp":1.87,"tv":53.02,"id":19144241}]}]}
{"op":"mcm","clk":"11817915044","pt":1723380799899,"mc":[{"id":"1.231679052","rc":[{"batb":[[0,2.2,2.36],[1,2.12,34.85],[2,2.06,63.13]],"ltp":2.12,"tv":60.86,"id":19144236}]}]}
{"op":"mcm","clk":"11817921477","pt":1723380880642,"mc":[{"id":"1.231679052","rc":[{"batb":[[0,2.12,34.85],[1,2.06,63.13],[2,1.74,17.32]],"ltp":2.12,"tv":60.86,"id":19144236}]}]}
{"op":"mcm","clk":"11817937849","pt":1723381067289,"mc":[{"id":"1.231679052","rc":[{"batb":[[1,1.77,1]],"ltp":1.87,"tv":53.02,"id":19144241}]}]}
{"op":"mcm","clk":"11817937914","pt":1723381067967,"mc":[{"id":"1.231679052","rc":[{"trd":[[1.77,0.14],[1.82,4.98]],"batb":[[0,1.76,52.3],[1,1.74,17.32],[2,1.72,92.94]],"ltp":1.77,"tv":58.14,"id":19144241}],"tv":119.0}]}
{"op":"mcm","clk":"11817939042","pt":1723381079860,"mc":[{"id":"1.231679052","rc":[{"batb":[[0,1.77,20.62],[1,1.76,51.37],[2,1.74,17.32]],"ltp":1.77,"tv":58.14,"id":19144241}]}]}
{"op":"mcm","clk":"11817962404","pt":1723381300524,"mc":[{"id":"1.231679052","rc":[{"batb":[[0,1.87,2.36],[1,1.77,20.62],[2,1.76,51.37]],"ltp":1.77,"tv":58.14,"id":19144241}]}]}
{"op":"mcm","clk":"11817992684","pt":1723381537467,"mc":[{"id":"1.231679052","rc":[{"trd":[[2.12,29.91]],"batb":[[0,2.12,34.06]],"ltp":2.12,"tv":62.43,"id":19144236}],"tv":120.58}]}
{"op":"mcm","clk":"11817993380","pt":1723381542457,"mc":[{"id":"1.231679052","rc":[{"batb":[[0,2.12,34.85]],"ltp":2.12,"tv":62.43,"id":19144236}]}]}
{"op":"mcm","clk":"11818037585","pt":1723381871606,"mc":[{"id":"1.231679052","rc":[{"batb":[[0,1.77,20.62],[1,1.76,51.37],[2,1.74,17.32]],"ltp":1.77,"tv":58.14,"id":19144241}]}]}
{"op":"mcm","clk":"11818038616","pt":1723381879545,"mc":[{"id":"1.231679052","rc":[{"trd":[[2.3,0.72]],"ltp":2.3,"tv":63.16,"id":19144236},{"trd":[[1.77,1.08]],"batb":[[0,1.77,19.68]],"ltp":1.77,"tv":59.08,"id":19144241}],"tv":122.24}]}
{"op":"mcm","clk":"11818069297","pt":1723382022624,"mc":[{"id":"1.231679052","rc":[{"batb":[[0,2.28,2.36],[1,2.12,34.85],[2,2.06,63.13]],"ltp":2.3,"tv":63.16,"id":19144236}]}]}
{"op":"mcm","clk":"11818077759","pt":1723382085168,"mc":[{"id":"1.231679052","rc":[{"batb":[[0,2.12,34.85],[1,2.06,63.13],[2,1.74,17.32]],"ltp":2.3,"tv":63.16,"id":19144236}]}]}
{"op":"mcm","clk":"11818079742","pt":1723382100376,"mc":[{"id":"1.231679052","rc":[{"batb":[[0,1.87,2.36],[1,1.77,19.68],[2,1.76,51.37]],"ltp":1.77,"tv":59.08,"id":19144241}]}]}
{"op":"mcm","clk":"11818080953","pt":1723382109703,"mc":[{"id":"1.231679052","rc":[{"batl":[[0,1.88,46.76]],"ltp":1.77,"tv":59.08,"id":19144241}]}]}
{"op":"mcm","clk":"11818083248","pt":1723382127593,"mc":[{"id":"1.231679052","rc":[{"batl":[[1,1.95,25.76]],"ltp":1.77,"tv":59.08,"id":19144241}]}]}
{"op":"mcm","clk":"11818084085","pt":1723382134036,"mc":[{"id":"1.231679052","rc":[{"batb":[[0,1.77,19.68],[1,1.76,51.37],[2,1.74,17.32]],"ltp":1.77,"tv":59.08,"id":19144241}]}]}
{"op":"mcm","clk":"11818085648","pt":1723382145614,"mc":[{"id":"1.231679052","rc":[{"batb":[[0,2.28,2.36],[1,2.12,34.85],[2,2.06,63.13]],"ltp":2.3,"tv":63.16,"id":19144236}]}]}
{"op":"mcm","clk":"11818091620","pt":1723382185567,"mc":[{"id":"1.231679052","rc":[{"batb":[[0,2.12,34.85],[1,2.06,63.13],[2,1.74,17.32]],"ltp":2.3,"tv":63.16,"id":19144236}]}]}
{"op":"mcm","clk":"11818093143","pt":1723382195683,"mc":[{"id":"1.231679052","rc":[{"trd":[[1.87,11.26]],"ltp":1.87,"tv":65.36,"id":19144241}],"tv":128.52}]}
{"op":"mcm","clk":"11818095914","pt":1723382215212,"mc":[{"id":"1.231679052","rc":[{"trd":[[1.87,15.98]],"ltp":1.87,"tv":70.08,"id":19144241}],"tv":133.24}]}
{"op":"mcm","clk":"11818098130","pt":1723382230654,"mc":[{"id":"1.231679052","rc":[{"trd":[[2.3,5.19]],"ltp":2.3,"tv":67.63,"id":19144236},{"trd":[[1.77,6.89]],"batb":[[0,1.77,13.87]],"ltp":1.77,"tv":75.89,"id":19144241}],"tv":143.52}]}
{"op":"mcm","clk":"11818102205","pt":1723382260720,"mc":[{"id":"1.231679052","rc":[{"trd":[[1.87,22.26]],"ltp":1.87,"tv":82.17,"id":19144241}],"tv":149.8}]}
{"op":"mcm","clk":"11818106676","pt":1723382293769,"mc":[{"id":"1.231679052","rc":[{"trd":[[1.77,13.53]],"batb":[[0,1.77,10.55]],"ltp":1.77,"tv":88.81,"id":19144241}],"tv":156.44}]}
{"op":"mcm","clk":"11818108307","pt":1723382306550,"mc":[{"id":"1.231679052","rc":[{"trd":[[1.87,25.4]],"ltp":1.87,"tv":91.96,"id":19144241}],"tv":159.59}]}
{"op":"mcm","clk":"11818125123","pt":1723382441391,"mc":[{"id":"1.231679052","rc":[{"batb":[[0,1.76,51.37],[1,1.74,17.32],[2,1.72,92.94]],"ltp":1.87,"tv":91.96,"id":19144241}]}]}
{"op":"mcm","clk":"11818131688","pt":1723382490136,"mc":[{"id":"1.231679052","rc":[{"batb":[[0,1.77,9.85],[1,1.76,51.37],[2,1.74,17.32]],"ltp":1.87,"tv":91.96,"id":19144241}]}]}
{"op":"mcm","clk":"11818132605","pt":1723382497544,"mc":[{"id":"1.231679052","rc":[{"batb":[[0,1.76,51.37],[1,1.74,17.32],[2,1.72,92.94]],"ltp":1.87,"tv":91.96,"id":19144241}]}]}
{"op":"mcm","clk":"11818140267","pt":1723382560131,"mc":[{"id":"1.231679052","rc":[{"trd":[[1.87,31.68]],"ltp":1.87,"tv":98.24,"id":19144241}],"tv":165.87}]}
{"op":"mcm","clk":"11818142587","pt":1723382579381,"mc":[{"id":"1.231679052","rc":[{"trd":[[1.76,17.16]],"batb":[[0,1.76,46.37]],"ltp":1.76,"tv":108.24,"id":19144241}],"tv":175.87}]}
{"op":"mcm","clk":"11818143053","pt":1723382582967,"mc":[{"id":"1.231679052","rc":[{"batb":[[0,1.76,51.37]],"ltp":1.76,"tv":108.24,"id":19144241}]}]}
{"op":"mcm","clk":"11818146791","pt":1723382613309,"mc":[{"id":"1.231679052","rc":[{"batb":[[0,1.86,3.14],[1,1.76,51.37],[2,1.74,17.32]],"ltp":1.76,"tv":108.24,"id":19144241}]}]}
{"op":"mcm","clk":"11818146810","pt":1723382613419,"mc":[{"id":"1.231679052","rc":[{"trd":[[1.86,6.28]],"batb":[[0,1.76,51.37],[1,1.74,17.32],[2,1.72,92.94]],"ltp":1.86,"tv":114.52,"id":19144241}],"tv":182.15}]}
{"op":"mcm","clk":"11818148785","pt":1723382628505,"mc":[{"id":"1.231679052","rc":[{"trd":[[2.32,2.52]],"ltp":2.32,"tv":70.15,"id":19144236},{"trd":[[1.76,20.48]],"batb":[[0,1.76,48.05]],"ltp":1.76,"tv":117.84,"id":19144241}],"tv":187.99}]}
{"op":"mcm","clk":"11818149301","pt":1723382633119,"mc":[{"id":"1.231679052","rc":[{"batb":[[0,1.76,51.37]],"ltp":1.76,"tv":117.84,"id":19144241}]}]}
{"op":"mcm","clk":"11818439054","pt":1723384801762,"mc":[{"id":"1.231679052","rc":[{"batb":[[1,2.1,16.37],[2,2.06,63.13]],"ltp":2.32,"tv":70.15,"id":19144236},{"batb":[[1,1.75,24.01],[2,1.74,17.32]],"ltp":1.76,"tv":117.84,"id":19144241}]}]}
{"op":"mcm","clk":"11818445393","pt":1723384849091,"mc":[{"id":"1.231679052","rc":[{"batb":[[1,2.1,24.07]],"ltp":2.32,"tv":70.15,"id":19144236}]}]}
{"op":"mcm","clk":"11818447112","pt":1723384862260,"mc":[{"id":"1.231679052","rc":[{"batb":[[1,2.1,16.37]],"ltp":2.32,"tv":70.15,"id":19144236}]}]}
{"op":"mcm","clk":"11818509030","pt":1723385281968,"mc":[{"id":"1.231679052","rc":[{"batb":[[0,2.12,51.93]],"ltp":2.32,"tv":70.15,"id":19144236}]}]}
{"op":"mcm","clk":"11818511179","pt":1723385294747,"mc":[{"id":"1.231679052","rc":[{"batb":[[0,2.12,50.93]],"ltp":2.32,"tv":70.15,"id":19144236}]}]}
{"op":"mcm","clk":"11818512263","pt":1723385300556,"mc":[{"id":"1.231679052","rc":[{"batb":[[0,2.3,2.14],[1,2.12,50.93],[2,2.1,16.37]],"ltp":2.32,"tv":70.15,"id":19144236}]}]}
{"op":"mcm","clk":"11818515145","pt":1723385316457,"mc":[{"id":"1.231679052","rc":[{"batb":[[0,2.12,50.93],[1,2.1,16.37],[2,2.06,63.13]],"ltp":2.32,"tv":70.15,"id":19144236}]}]}
{"op":"mcm","clk":"11818517103","pt":1723385328069,"mc":[{"id":"1.231679052","rc":[{"trd":[[1.79,2]],"ltp":1.79,"tv":119.84,"id":19144241}],"tv":189.99}]}
{"op":"mcm","clk":"11818517988","pt":1723385333113,"mc":[{"id":"1.231679052","rc":[{"trd":[[1.88,1.9]],"batl":[[0,1.88,45.81]],"ltp":1.88,"tv":121.74,"id":19144241}],"tv":191.89}]}
{"op":"mcm","clk":"11818519506","pt":1723385341302,"mc":[{"id":"1.231679052","rc":[{"batl":[[0,1.88,46.8]],"ltp":1.88,"tv":121.74,"id":19144241}]}]}
{"op":"mcm","clk":"11818521521","pt":1723385352726,"mc":[{"id":"1.231679052","rc":[{"batl":[[0,1.88,45.81]],"ltp":1.88,"tv":121.74,"id":19144241}]}]}
{"op":"mcm","clk":"11818525127","pt":1723385374234,"mc":[{"id":"1.231679052","rc":[{"batb":[[0,2.28,1.14],[1,2.12,50.93],[2,2.1,16.37]],"ltp":2.32,"tv":70.15,"id":19144236}]}]}
{"op":"mcm","clk":"11818527607","pt":1723385389339,"mc":[{"id":"1.231679052","rc":[{"batb":[[0,2.12,50.93],[1,2.1,16.37],[2,2.06,63.13]],"ltp":2.32,"tv":70.15,"id":19144236}]}]}
{"op":"mcm","clk":"11818550152","pt":1723385528524,"mc":[{"id":"1.231679052","rc":[{"trd":[[1.76,22.5]],"batb":[[0,1.76,50.36]],"ltp":1.76,"tv":123.76,"id":19144241}],"tv":193.91}]}
{"op":"mcm","clk":"11818550855","pt":1723385532812,"mc":[{"id":"1.231679052","rc":[{"batb":[[0,1.76,51.37]],"ltp":1.76,"tv":123.76,"id":19144241}]}]}
{"op":"mcm","clk":"11818644381","pt":1723386110890,"mc":[{"id":"1.231679052","rc":[{"batb":[[0,2.12,52.05]],"ltp":2.32,"tv":70.15,"id":19144236},{"batb":[[0,1.76,53]],"ltp":1.76,"tv":123.76,"id":19144241}]}]}
{"op":"mcm","clk":"11818722217","pt":1723386630351,"mc":[{"id":"1.231679052","rc":[{"batb":[[0,1.77,5.67],[1,1.76,53],[2,1.75,24.01]],"ltp":1.76,"tv":123.76,"id":19144241}]}]}
{"op":"mcm","clk":"11818722290","pt":1723386630757,"mc":[{"id":"1.231679052","rc":[{"batb":[[1,1.76,76.7]],"ltp":1.76,"tv":123.76,"id":19144241}]}]}
{"op":"mcm","clk":"11818724254","pt":1723386644734,"mc":[{"id":"1.231679052","rc":[{"batl":[[0,1.87,5.67],[1,1.88,45.81],[2,1.95,25.76]],"ltp":1.76,"tv":123.76,"id":19144241}]}]}
{"op":"mcm","clk":"11818735661","pt":1723386719416,"mc":[{"id":"1.231679052","rc":[{"batl":[[0,1.88,45.81],[1,1.95,25.76],[2,1.95,0]],"ltp":1.76,"tv":123.76,"id":19144241}]}]}
{"op":"mcm","clk":"11818736558","pt":1723386725866,"mc":[{"id":"1.231679052","rc":[{"batb":[[0,1.76,76.7],[1,1.75,24.01],[2,1.74,17.32]],"ltp":1.76,"tv":123.76,"id":19144241}]}]}
{"op":"mcm","clk":"11818781446","pt":1723387019981,"mc":[{"id":"1.231679052","rc":[{"batl":[[1,1.95,45.76]],"ltp":1.76,"tv":123.76,"id":19144241}]}]}
{"op":"mcm","clk":"11818797687","pt":1723387121760,"mc":[{"id":"1.231679052","rc":[{"batl":[[2,2.34,4.64]],"ltp":1.76,"tv":123.76,"id":19144241}]}]}
{"op":"mcm","clk":"11818835441","pt":1723387363640,"mc":[{"id":"1.231679052","rc":[{"trd":[[1.87,36.4]],"ltp":1.87,"tv":128.47,"id":19144241}],"tv":198.63}]}
{"op":"mcm","clk":"11818848612","pt":1723387382778,"mc":[{"id":"1.231679052","rc":[{"trd":[[1.76,27.49]],"batb":[[0,1.76,74.2]],"ltp":1.76,"tv":133.47,"id":19144241}],"tv":203.62}]}
{"op":"mcm","clk":"11818849418","pt":1723387387394,"mc":[{"id":"1.231679052","rc":[{"batb":[[0,1.76,76.7]],"ltp":1.76,"tv":133.47,"id":19144241}]}]}
{"op":"mcm","clk":"11818852602","pt":1723387408607,"mc":[{"id":"1.231679052","rc":[{"batl":[[0,1.86,7.5],[1,1.88,45.81],[2,1.95,45.76]],"ltp":1.76,"tv":133.47,"id":19144241}]}]}
{"op":"mcm","clk":"11818882725","pt":1723387592772,"mc":[{"id":"1.231679052","rc":[{"batl":[[0,1.88,45.81],[1,1.95,45.76],[2,2.34,4.64]],"ltp":1.76,"tv":133.47,"id":19144241}]}]}
{"op":"mcm","clk":"11818949668","pt":1723388124750,"mc":[{"id":"1.231679052","rc":[{"batl":[[0,1.87,20],[1,1.88,45.81],[2,1.95,25.76]],"ltp":1.76,"tv":133.47,"id":19144241}]}]}
{"op":"mcm","clk":"11818952124","pt":1723388145664,"mc":[{"id":"1.231679052","rc":[{"batl":[[0,1.88,45.81],[1,1.95,25.76],[2,2.34,4.64]],"ltp":1.76,"tv":133.47,"id":19144241}]}]}
{"op":"mcm","clk":"11818979959","pt":1723388403284,"mc":[{"id":"1.231679052","rc":[{"batb":[[0,2.12,21.08]],"ltp":2.32,"tv":70.15,"id":19144236},{"batb":[[0,1.76,5],[1,1.74,17.32],[2,1.72,92.94]],"ltp":1.76,"tv":133.47,"id":19144241}]}]}
{"op":"mcm","clk":"11818980024","pt":1723388403775,"mc":[{"id":"1.231679052","rc":[{"batb":[[2,1.72,117.96]],"ltp":1.76,"tv":133.47,"id":19144241}]}]}
{"op":"mcm","clk":"11819063921","pt":1723389057490,"mc":[{"id":"1.231679052","rc":[{"batl":[[2,2.34,0]],"ltp":1.76,"tv":133.47,"id":19144241}]}]}
{"op":"mcm","clk":"11819064175","pt":1723389059317,"mc":[{"id":"1.231679052","rc":[{"batl":[[2,2.34,4.64]],"ltp":1.76,"tv":133.47,"id":19144241}]}]}
{"op":"mcm","clk":"11819100017","pt":1723389303533,"mc":[{"id":"1.231679052","rc":[{"batb":[[1,2.1,24.05]],"ltp":2.32,"tv":70.15,"id":19144236}]}]}
{"op":"mcm","clk":"11819156801","pt":1723389672966,"mc":[{"id":"1.231679052","rc":[{"batl":[[0,1.88,25.76]],"ltp":1.76,"tv":133.47,"id":19144241}]}]}
{"op":"mcm","clk":"11819188040","pt":1723389875762,"mc":[{"id":"1.231679052","rc":[{"batb":[[0,2.14,1],[1,2.12,21.08],[2,2.1,24.05]],"ltp":2.32,"tv":70.15,"id":19144236},{"batb":[[1,1.75,1.22],[2,1.74,17.32]],"ltp":1.76,"tv":133.47,"id":19144241}]}]}
{"op":"mcm","clk":"11819195463","pt":1723389926344,"mc":[{"id":"1.231679052","rc":[{"batl":[[0,1.87,20.05],[1,1.88,25.76],[2,1.95,25.76]],"ltp":1.76,"tv":133.47,"id":19144241}]}]}
{"op":"mcm","clk":"11819200786","pt":1723389959690,"mc":[{"id":"1.231679052","rc":[{"batb":[[2,2.1,16.37]],"ltp":2.32,"tv":70.15,"id":19144236}]}]}
{"op":"mcm","clk":"11819215540","pt":1723390064899,"mc":[{"id":"1.231679052","rc":[{"trd":[[1.76,27.75]],"batb":[[0,1.76,4.87]],"ltp":1.76,"tv":133.73,"id":19144241}],"tv":203.88}]}
{"op":"mcm","clk":"11819215623","pt":1723390065568,"mc":[{"id":"1.231679052","rc":[{"batb":[[0,1.76,5]],"ltp":1.76,"tv":133.73,"id":19144241}]}]}
{"op":"mcm","clk":"11819239482","pt":1723390236295,"mc":[{"id":"1.231679052","rc":[{"batb":[[1,2.12,16.08]],"ltp":2.32,"tv":70.15,"id":19144236},{"trd":[[1.84,48.89]],"batb":[[0,1.75,1.22],[1,1.74,17.32],[2,1.72,117.96]],"ltp":1.84,"tv":143.73,"id":19144241}],"tv":213.88}]}
{"op":"mcm","clk":"11819240226","pt":1723390241290,"mc":[{"id":"1.231679052","rc":[{"batb":[[0,1.8,5],[1,1.75,1.22],[2,1.74,17.32]],"ltp":1.84,"tv":143.73,"id":19144241}]}]}
{"op":"mcm","clk":"11819243853","pt":1723390266312,"mc":[{"id":"1.231679052","rc":[{"batl":[[0,1.87,23.05]],"ltp":1.84,"tv":143.73,"id":19144241}]}]}
{"op":"mcm","clk":"11819253225","pt":1723390333401,"mc":[{"id":"1.231679052","rc":[{"trd":[[1.87,49.74]],"batl":[[0,1.87,16.38]],"ltp":1.87,"tv":157.07,"id":19144241}],"tv":227.22}]}
{"op":"mcm","clk":"11819253527","pt":1723390335482,"mc":[{"id":"1.231679052","rc":[{"trd":[[1.75,2.44],[1.8,10]],"batb":[[0,1.74,17.32],[1,1.72,117.96],[2,1.33,303.03]],"batl":[[0,1.8,94.09],[1,1.87,16.38],[2,1.88,25.76]],"ltp":1.75,"tv":169.51,"id":19144241}],"tv":239.66}]}
{"op":"mcm","clk":"11819253816","pt":1723390337393,"mc":[{"id":"1.231679052","rc":[{"batb":[[0,2.22,14.76],[1,2.14,1],[2,2.12,16.08]],"ltp":2.32,"tv":70.15,"id":19144236}]}]}
{"op":"mcm","clk":"11819256570","pt":1723390357232,"mc":[{"id":"1.231679052","rc":[{"batl":[[0,1.87,16.38],[1,1.88,25.76],[2,1.95,25.76]],"ltp":1.75,"tv":169.51,"id":19144241}]}]}
{"op":"mcm","clk":"11819256613","pt":1723390357540,"mc":[{"id":"1.231679052","rc":[{"batb":[[0,2.14,1],[1,2.12,16.08],[2,2.1,16.37]],"ltp":2.32,"tv":70.15,"id":19144236}]}]}
{"op":"mcm","clk":"11819258631","pt":1723390371054,"mc":[{"id":"1.231679052","rc":[{"trd":[[1.72,153.54],[1.74,34.64]],"batb":[[0,1.72,16.17],[1,1.33,303.03],[2,1.26,4.7]],"ltp":1.72,"tv":357.69,"id":19144241}],"tv":427.84}]}
{"op":"mcm","clk":"11819272134","pt":1723390467225,"mc":[{"id":"1.231679052","rc":[{"trd":[[1.72,185.88]],"batb":[[0,1.59,24.76]],"batl":[[0,1.72,69.6],[1,1.87,16.38],[2,1.88,25.76]],"ltp":1.72,"tv":390.03,"id":19144241}],"tv":460.18}]}
{"op":"mcm","clk":"11819272188","pt":1723390467541,"mc":[{"id":"1.231679052","rc":[{"batb":[[1,2.06,63.13],[2,1.74,17.32]],"ltp":2.32,"tv":70.15,"id":19144236}]}]}
{"op":"mcm","clk":"11819272467","pt":1723390469564,"mc":[{"id":"1.231679052","rc":[{"batb":[[0,2.36,13.24],[1,2.14,1],[2,2.06,63.13]],"ltp":2.32,"tv":70.15,"id":19144236}]}]}
{"op":"mcm","clk":"11819272833","pt":1723390472261,"mc":[{"id":"1.231679052","rc":[{"batb":[[2,2.08,5]],"ltp":2.32,"tv":70.15,"id":19144236}]}]}
{"op":"mcm","clk":"11819304387","pt":1723390696767,"mc":[{"id":"1.231679052","rc":[{"trd":[[1.72,186.12]],"batl":[[0,1.72,69.48]],"ltp":1.72,"tv":390.27,"id":19144241}],"tv":460.42}]}
{"op":"mcm","clk":"11819320618","pt":1723390803798,"mc":[{"id":"1.231679052","rc":[{"batb":[[2,2.08,74.6]],"ltp":2.32,"tv":70.15,"id":19144236}]}]}
{"op":"mcm","clk":"11819330967","pt":1723390881674,"mc":[{"id":"1.231679052","rc":[{"trd":[[1.72,206.7]],"batl":[[0,1.72,59.19]],"ltp":1.72,"tv":410.85,"id":19144241}],"tv":481.0}]}
{"op":"mcm","clk":"11819331199","pt":1723390883405,"mc":[{"id":"1.231679052","rc":[{"trd":[[1.72,206.88]],"batl":[[0,1.72,59.09]],"ltp":1.72,"tv":411.04,"id":19144241}],"tv":481.19}]}
{"op":"mcm","clk":"11819338227","pt":1723390935017,"mc":[{"id":"1.231679052","rc":[{"trd":[[1.68,80.44]],"ltp":1.68,"tv":491.48,"id":19144241}],"tv":561.63}]}
{"op":"mcm","clk":"11819343395","pt":1723390975177,"mc":[{"id":"1.231679052","rc":[{"trd":[[1.68,160.89]],"ltp":1.68,"tv":571.92,"id":19144241}],"tv":642.07}]}
{"op":"mcm","clk":"11819343698","pt":1723390977597,"mc":[{"id":"1.231679052","rc":[{"batb":[[0,1.6,13.53],[1,1.59,24.76],[2,1.33,303.03]],"ltp":1.68,"tv":571.92,"id":19144241}]}]}
{"op":"mcm","clk":"11819343928","pt":1723390979271,"mc":[{"id":"1.231679052","rc":[{"batb":[[1,1.59,55.28]],"ltp":1.68,"tv":571.92,"id":19144241}]}]}
{"op":"mcm","clk":"11819344077","pt":1723390980374,"mc":[{"id":"1.231679052","rc":[{"batl":[[0,2.68,4.51]],"ltp":2.32,"tv":70.15,"id":19144236}]}]}
{"op":"mcm","clk":"11819348347","pt":1723391011326,"mc":[{"id":"1.231679052","rc":[{"trd":[[2.38,0.91]],"ltp":2.38,"tv":71.06,"id":19144236},{"trd":[[1.72,208.14]],"batl":[[0,1.72,57.83]],"ltp":1.72,"tv":573.18,"id":19144241}],"tv":644.25}]}
{"op":"mcm","clk":"11819348413","pt":1723391011844,"mc":[{"id":"1.231679052","rc":[{"batb":[[0,1.62,48.59],[1,1.6,13.53],[2,1.59,30.52]],"ltp":1.72,"tv":573.18,"id":19144241}]}]}
{"op":"mcm","clk":"11819348785","pt":1723391014338,"mc":[{"id":"1.231679052","rc":[{"batb":[[1,1.61,29.53],[2,1.6,13.53]],"ltp":1.72,"tv":573.18,"id":19144241}]}]}
{"op":"mcm","clk":"11819348841","pt":1723391014710,"mc":[{"id":"1.231679052","rc":[{"batb":[[1,2.24,64.97],[2,2.14,1]],"ltp":2.38,"tv":71.06,"id":19144236}]}]}
{"op":"mcm","clk":"11819351761","pt":1723391036393,"mc":[{"id":"1.231679052","rc":[{"trd":[[2.38,1]],"ltp":2.38,"tv":71.15,"id":19144236},{"trd":[[1.72,208.27]],"batl":[[0,1.72,57.7]],"ltp":1.72,"tv":573.31,"id":19144241}],"tv":644.47}]}
{"op":"mcm","clk":"11819351890","pt":1723391037339,"mc":[{"id":"1.231679052","rc":[{"batb":[[0,1.63,7.21],[1,1.62,48.59],[2,1.61,29.53]],"ltp":1.72,"tv":573.31,"id":19144241}]}]}
{"op":"mcm","clk":"11819352015","pt":1723391038364,"mc":[{"id":"1.231679052","rc":[{"batb":[[1,1.62,77.64]],"ltp":1.72,"tv":573.31,"id":19144241}]}]}
{"op":"mcm","clk":"11819355974","pt":1723391067688,"mc":[{"id":"1.231679052","rc":[{"batb":[[0,1.64,47.99],[1,1.63,7.21],[2,1.62,29.05]],"ltp":1.72,"tv":573.31,"id":19144241}]}]}
{"op":"mcm","clk":"11819356219","pt":1723391069383,"mc":[{"id":"1.231679052","rc":[{"batb":[[1,1.63,35.79]],"ltp":1.72,"tv":573.31,"id":19144241}]}]}
{"op":"mcm","clk":"11819357673","pt":1723391080021,"mc":[{"id":"1.231679052","rc":[{"batb":[[1,1.63,28.58]],"ltp":1.72,"tv":573.31,"id":19144241}]}]}
{"op":"mcm","clk":"11819365529","pt":1723391140269,"mc":[{"id":"1.231679052","rc":[{"trd":[[1.72,323.67]],"batb":[[0,1.72,77.3],[1,1.64,47.99],[2,1.63,28.58]],"batl":[[0,1.87,16.38],[1,1.88,25.76],[2,1.95,25.76]],"ltp":1.72,"tv":688.71,"id":19144241}],"tv":759.87}]}
{"op":"mcm","clk":"11819365684","pt":1723391141386,"mc":[{"id":"1.231679052","rc":[{"batb":[[0,2.24,64.97],[1,2.22,14.76]],"ltp":2.38,"tv":71.15,"id":19144236},{"batb":[[1,1.65,7.21],[2,1.64,76.13]],"ltp":1.72,"tv":688.71,"id":19144241}]}]}
{"op":"mcm","clk":"11819365977","pt":1723391143383,"mc":[{"id":"1.231679052","rc":[{"batb":[[1,1.71,25.37],[2,1.65,7.21]],"ltp":1.72,"tv":688.71,"id":19144241}]}]}
{"op":"mcm","clk":"11819366280","pt":1723391145385,"mc":[{"id":"1.231679052","rc":[{"batl":[[0,2.38,2.92],[1,2.68,4.51]],"ltp":2.38,"tv":71.15,"id":19144236},{"batb":[[0,1.74,108.88],[1,1.72,77.3],[2,1.71,25.37]],"ltp":1.72,"tv":688.71,"id":19144241}]}]}
{"op":"mcm","clk":"11819366403","pt":1723391146394,"mc":[{"id":"1.231679052","rc":[{"batb":[[1,1.72,102.32]],"ltp":1.72,"tv":688.71,"id":19144241}]}]}
{"op":"mcm","clk":"11819366530","pt":1723391147386,"mc":[{"id":"1.231679052","rc":[{"batb":[[1,1.73,24.67],[2,1.72,102.32]],"ltp":1.72,"tv":688.71,"id":19144241}]}]}
{"op":"mcm","clk":"11819372060","pt":1723391188128,"mc":[{"id":"1.231679052","rc":[{"batl":[[0,1.8,13.38],[1,1.87,3],[2,1.88,25.76]],"ltp":1.72,"tv":688.71,"id":19144241}]}]}
{"op":"mcm","clk":"11819392408","pt":1723391356043,"mc":[{"id":"1.231679052","rc":[{"trd":[[2.24,5.84]],"batb":[[0,2.24,62.05]],"batl":[[0,2.68,4.51],[1,2.68,0]],"ltp":2.24,"tv":76.99,"id":19144236}],"tv":765.71}]}
{"op":"mcm","clk":"11819393011","pt":1723391361161,"mc":[{"id":"1.231679052","rc":[{"batb":[[0,2.24,64.97]],"ltp":2.24,"tv":76.99,"id":19144236}]}]}
{"op":"mcm","clk":"11819393455","pt":1723391364837,"mc":[{"id":"1.231679052","rc":[{"batl":[[1,4.5,0.23]],"ltp":2.24,"tv":76.99,"id":19144236}]}]}
{"op":"mcm","clk":"11819429234","pt":1723391702889,"mc":[{"id":"1.231679052","rc":[{"batb":[[2,2.14,9.86]],"ltp":2.24,"tv":76.99,"id":19144236}]}]}
{"op":"mcm","clk":"11819430433","pt":1723391713199,"mc":[{"id":"1.231679052","rc":[{"batb":[[0,2.14,9.86],[1,2.06,63.13],[2,1.74,17.32]],"batl":[[1,2.82,16.45],[2,4.5,0.23]],"ltp":2.24,"tv":76.99,"id":19144236},{"batb":[[0,1.72,102.32],[1,1.71,25.37],[2,1.66,11.43]],"ltp":1.72,"tv":688.71,"id":19144241}]}]}
{"op":"mcm","clk":"11819430495","pt":1723391713714,"mc":[{"id":"1.231679052","rc":[{"batb":[[0,2.14,25.66]],"ltp":2.24,"tv":76.99,"id":19144236}]}]}
{"op":"mcm","clk":"11819439961","pt":1723391801708,"mc":[{"id":"1.231679052","rc":[{"trd":[[2.24,7.66]],"ltp":2.24,"tv":78.81,"id":19144236},{"trd":[[1.8,12.27]],"batl":[[0,1.8,11.11]],"ltp":1.8,"tv":690.98,"id":19144241}],"tv":769.8}]}
{"op":"mcm","clk":"11819440192","pt":1723391804209,"mc":[{"id":"1.231679052","rc":[{"trd":[[1.72,329.51]],"batb":[[0,1.72,99.4]],"ltp":1.72,"tv":696.82,"id":19144241}],"tv":775.64}]}
{"op":"mcm","clk":"11819460380","pt":1723391989289,"mc":[{"id":"1.231679052","rc":[{"trd":[[1.72,330.03]],"batb":[[0,1.72,99.14]],"ltp":1.72,"tv":697.34,"id":19144241}],"tv":776.16}]}
{"op":"mcm","clk":"11819462621","pt":1723392006847,"mc":[{"id":"1.231679052","marketDefinition":{"bspMarket":false,"turnInPlayEnabled":true,"persistenceEnabled":true,"marketBaseRate":5.0,"eventId":"33484467","eventTypeId":"4","numberOfWinners":1,"bettingType":"ODDS","marketType":"MATCH_ODDS","marketTime":"2024-08-11T16:00:00.000Z","suspendTime":"2024-08-11T16:00:00.000Z","bspReconciled":false,"complete":true,"inPlay":true,"crossMatching":true,"runnersVoidable":false,"numberOfActiveRunners":2,"betDelay":5,"status":"OPEN","runners":[{"status":"ACTIVE","sortPriority":1,"id":19144241,"name":"Montreal Tigers"},{"status":"ACTIVE","sortPriority":2,"id":19144236,"name":"Toronto Nationals"}],"regulators":["MR_INT"],"countryCode":"GB","discountAllowed":true,"timezone":"GMT","openDate":"2024-08-11T16:00:00.000Z","version":6070030057,"name":"Match Odds","eventName":"Montreal Tigers v Toronto Nationals"},"rc":[{"batb":[[0,1.74,17.32],[1,1.53,188.68],[2,1.43,232.56]],"batl":[[0,4.5,0.23],[1,2.82,0],[2,4.5,0]],"ltp":2.24,"tv":78.81,"id":19144236},{"batb":[[0,1.33,303.03],[1,1.26,4.7],[2,1.23,434.78]],"batl":[[0,1.87,3],[1,1.88,25.76],[2,1.95,25.76]],"ltp":1.72,"tv":697.34,"id":19144241}]}]}
{"op":"mcm","clk":"11819463824","pt":1723392017729,"mc":[{"id":"1.231679052","rc":[{"batb":[[0,1.33,303.11]],"ltp":1.72,"tv":697.34,"id":19144241}]}]}
{"op":"mcm","clk":"11819464121","pt":1723392020711,"mc":[{"id":"1.231679052","rc":[{"batl":[[0,10,0.33]],"ltp":2.24,"tv":78.81,"id":19144236}]}]}
{"op":"mcm","clk":"11819464566","pt":1723392025518,"mc":[{"id":"1.231679052","rc":[{"batb":[[0,1.33,303.03]],"ltp":1.72,"tv":697.34,"id":19144241}]}]}
{"op":"mcm","clk":"11819464803","pt":1723392028333,"mc":[{"id":"1.231679052","rc":[{"batb":[[0,1.81,1.38],[1,1.33,303.03],[2,1.26,4.7]],"ltp":1.72,"tv":697.34,"id":19144241}]}]}
{"op":"mcm","clk":"11819465433","pt":1723392035069,"mc":[{"id":"1.231679052","rc":[{"batb":[[1,1.37,30],[2,1.33,303.03]],"ltp":1.72,"tv":697.34,"id":19144241}]}]}
{"op":"mcm","clk":"11819465889","pt":1723392039362,"mc":[{"id":"1.231679052","rc":[{"batb":[[2,1.36,26.67]],"ltp":1.72,"tv":697.34,"id":19144241}]}]}
{"op":"mcm","clk":"11819466043","pt":1723392040859,"mc":[{"id":"1.231679052","rc":[{"batb":[[0,1.37,30],[1,1.36,26.67],[2,1.33,303.03]],"ltp":1.72,"tv":697.34,"id":19144241}]}]}
{"op":"mcm","clk":"11819466616","pt":1723392046560,"mc":[{"id":"1.231679052","rc":[{"batl":[[0,1.86,12],[1,1.87,3],[2,1.88,25.76]],"ltp":1.72,"tv":697.34,"id":19144241}]}]}
{"op":"mcm","clk":"11819467316","pt":1723392053061,"mc":[{"id":"1.231679052","rc":[{"batl":[[0,1.62,1.38],[1,1.86,12],[2,1.87,3]],"ltp":1.72,"tv":697.34,"id":19144241}]}]}
{"op":"mcm","clk":"11819467639","pt":1723392055877,"mc":[{"id":"1.231679052","rc":[{"trd":[[2.6,0.24]],"ltp":2.6,"tv":79.05,"id":19144236},{"trd":[[1.62,0.38]],"batb":[[0,1.37,30.08]],"batl":[[0,1.62,1]],"ltp":1.62,"tv":697.72,"id":19144241}],"tv":776.78}]}
{"op":"mcm","clk":"11819469281","pt":1723392070893,"mc":[{"id":"1.231679052","rc":[{"batl":[[0,1.86,12],[1,1.87,3],[2,1.88,25.76]],"ltp":1.62,"tv":697.72,"id":19144241}]}]}
{"op":"mcm","clk":"11819470353","pt":1723392079919,"mc":[{"id":"1.231679052","rc":[{"batb":[[0,1.5,9.49],[1,1.37,30.08],[2,1.36,26.67]],"ltp":1.62,"tv":697.72,"id":19144241}]}]}
{"op":"mcm","clk":"11819470463","pt":1723392080998,"mc":[{"id":"1.231679052","rc":[{"batb":[[0,1.84,1.38],[1,1.5,9.49],[2,1.37,30.08]],"ltp":1.62,"tv":697.72,"id":19144241}]}]}
{"op":"mcm","clk":"11819470555","pt":1723392081691,"mc":[{"id":"1.231679052","rc":[{"batb":[[2,1.36,26.75]],"ltp":1.62,"tv":697.72,"id":19144241}]}]}
{"op":"mcm","clk":"11819471340","pt":1723392088761,"mc":[{"id":"1.231679052","rc":[{"trd":[[1.84,51.09]],"batb":[[0,1.5,9.77],[1,1.36,26.75],[2,1.33,303.03]],"ltp":1.84,"tv":699.92,"id":19144241}],"tv":778.97}]}
{"op":"mcm","clk":"11819471591","pt":1723392090904,"mc":[{"id":"1.231679052","rc":[{"batb":[[0,1.5,9.49]],"batl":[[0,1.84,11.72],[1,1.86,12],[2,1.87,3]],"ltp":1.84,"tv":699.92,"id":19144241}]}]}
{"op":"mcm","clk":"11819471914","pt":1723392093828,"mc":[{"id":"1.231679052","rc":[{"batl":[[0,1.84,16.23]],"ltp":1.84,"tv":699.92,"id":19144241}]}]}
{"op":"mcm","clk":"11819472076","pt":1723392095363,"mc":[{"id":"1.231679052","rc":[{"batl":[[0,10,0.68]],"ltp":2.6,"tv":79.05,"id":19144236}]}]}
{"op":"mcm","clk":"11819472094","pt":1723392095525,"mc":[{"id":"1.231679052","rc":[{"batb":[[1,1.53,189.18]],"ltp":2.6,"tv":79.05,"id":19144236},{"batb":[[1,1.36,27.51]],"ltp":1.84,"tv":699.92,"id":19144241}]}]}
{"op":"mcm","clk":"11819472567","pt":1723392100322,"mc":[{"id":"1.231679052","rc":[{"trd":[[2.18,0.93]],"ltp":2.18,"tv":79.98,"id":19144236},{"trd":[[1.84,52.19]],"batl":[[0,1.84,46.88]],"ltp":1.84,"tv":701.02,"id":19144241}],"tv":781.0}]}
{"op":"mcm","clk":"11819472801","pt":1723392102723,"mc":[{"id":"1.231679052","rc":[{"batl":[[0,1.84,47.87]],"ltp":1.84,"tv":701.02,"id":19144241}]}]}
{"op":"mcm","clk":"11819473249","pt":1723392107417,"mc":[{"id":"1.231679052","rc":[{"batl":[[0,3.7,17.65],[1,10,0.33]],"ltp":2.18,"tv":79.98,"id":19144236}]}]}
{"op":"mcm","clk":"11819473596","pt":1723392111233,"mc":[{"id":"1.231679052","rc":[{"batl":[[0,1.8,1.12],[1,1.84,46.88],[2,1.86,12]],"ltp":1.84,"tv":701.02,"id":19144241}]}]}
{"op":"mcm","clk":"11819474280","pt":1723392117336,"mc":[{"id":"1.231679052","rc":[{"batb":[[0,1.5,10.48]],"batl":[[1,1.84,47.21]],"ltp":1.84,"tv":701.02,"id":19144241}]}]}
{"op":"mcm","clk":"11819474352","pt":1723392118041,"mc":[{"id":"1.231679052","rc":[{"trd":[[1.55,1.68],[1.8,15.03]],"batb":[[0,1.5,9.64]],"batl":[[0,1.84,47.21],[1,1.86,12],[2,1.87,3]],"ltp":1.55,"tv":705.46,"id":19144241}],"tv":785.44}]}
{"op":"mcm","clk":"11819475261","pt":1723392126834,"mc":[{"id":"1.231679052","rc":[{"batb":[[0,1.5,29.33]],"ltp":1.55,"tv":705.46,"id":19144241}]}]}
{"op":"mcm","clk":"11819475630","pt":1723392130448,"mc":[{"id":"1.231679052","rc":[{"batl":[[1,1.87,3],[2,1.88,25.76]],"ltp":1.55,"tv":705.46,"id":19144241}]}]}
{"op":"mcm","clk":"11819475811","pt":1723392132131,"mc":[{"id":"1.231679052","rc":[{"batb":[[0,1.77,1.38],[1,1.5,29.33],[2,1.36,27.51]],"ltp":1.55,"tv":705.46,"id":19144241}]}]}
{"op":"mcm","clk":"11819475859","pt":1723392132547,"mc":[{"id":"1.231679052","rc":[{"trd":[[1.77,15.73]],"batb":[[0,1.5,29.61],[1,1.36,27.51],[2,1.33,303.03]],"ltp":1.77,"tv":707.66,"id":19144241}],"tv":787.64}]}
{"op":"mcm","clk":"11819475976","pt":1723392133539,"mc":[{"id":"1.231679052","rc":[{"batb":[[0,1.52,1.42],[1,1.5,29.18],[2,1.36,27.51]],"ltp":1.77,"tv":707.66,"id":19144241}]}]}
{"op":"mcm","clk":"11819476114","pt":1723392134843,"mc":[{"id":"1.231679052","rc":[{"batb":[[0,1.52,1.47]],"ltp":1.77,"tv":707.66,"id":19144241}]}]}
{"op":"mcm","clk":"11819476191","pt":1723392135528,"mc":[{"id":"1.231679052","rc":[{"batl":[[0,1.83,12],[1,1.84,47.21],[2,1.87,3]],"ltp":1.77,"tv":707.66,"id":19144241}]}]}
{"op":"mcm","clk":"11819476502","pt":1723392138552,"mc":[{"id":"1.231679052","rc":[{"batb":[[0,1.52,1.19]],"ltp":1.77,"tv":707.66,"id":19144241}]}]}
{"op":"mcm","clk":"11819477038","pt":1723392143366,"mc":[{"id":"1.231679052","rc":[{"batb":[[0,1.52,1.33]],"ltp":1.77,"tv":707.66,"id":19144241}]}]}
{"op":"mcm","clk":"11819477143","pt":1723392144352,"mc":[{"id":"1.231679052","rc":[{"batb":[[1,1.5,9.49]],"ltp":1.77,"tv":707.66,"id":19144241}]}]}
{"op":"mcm","clk":"11819477475","pt":1723392147165,"mc":[{"id":"1.231679052","rc":[{"batl":[[0,1.83,12.99]],"ltp":1.77,"tv":707.66,"id":19144241}]}]}
{"op":"mcm","clk":"11819477578","pt":1723392148266,"mc":[{"id":"1.231679052","rc":[{"batl":[[0,1.79,1.37],[1,1.83,12],[2,1.84,47.21]],"ltp":1.77,"tv":707.66,"id":19144241}]}]}
{"op":"mcm","clk":"11819477681","pt":1723392149264,"mc":[{"id":"1.231679052","rc":[{"trd":[[2.8,0.45]],"batl":[[0,2.8,8.57],[1,3.7,17.65],[2,10,0.33]],"ltp":2.8,"tv":80.43,"id":19144236},{"trd":[[1.55,2.79],[1.6,0.28]],"batb":[[0,1.52,1.04]],"ltp":1.55,"tv":709.05,"id":19144241}],"tv":789.48}]}
{"op":"mcm","clk":"11819477885","pt":1723392151183,"mc":[{"id":"1.231679052","rc":[{"batl":[[2,1000,0.68]],"ltp":2.8,"tv":80.43,"id":19144236}]}]}
{"op":"mcm","clk":"11819477923","pt":1723392151553,"mc":[{"id":"1.231679052","rc":[{"batl":[[2,10,0.33]],"ltp":2.8,"tv":80.43,"id":19144236}]}]}
{"op":"mcm","clk":"11819478386","pt":1723392156108,"mc":[{"id":"1.231679052","rc":[{"batl":[[0,1.83,12.99],[1,1.84,47.21],[2,1.87,3]],"ltp":1.55,"tv":709.05,"id":19144241}]}]}
{"op":"mcm","clk":"11819478448","pt":1723392156746,"mc":[{"id":"1.231679052","rc":[{"batb":[[0,1.74,17.62]],"batl":[[1,3.7,18]],"ltp":2.8,"tv":80.43,"id":19144236},{"batb":[[2,1.43,1.65]],"ltp":1.55,"tv":709.05,"id":19144241}]}]}
{"op":"mcm","clk":"11819478692","pt":1723392158899,"mc":[{"id":"1.231679052","rc":[{"batb":[[0,1.58,53.33],[1,1.52,1.04],[2,1.5,9.49]],"ltp":1.55,"tv":709.05,"id":19144241}]}]}
{"op":"mcm","clk":"11819478769","pt":1723392159500,"mc":[{"id":"1.231679052","rc":[{"trd":[[2.2,34.21],[2.26,0.79]],"ltp":2.2,"tv":82.89,"id":19144236},{"trd":[[1.79,2.99],[1.83,2.02]],"batl":[[0,1.83,9.98]],"ltp":1.83,"tv":712.06,"id":19144241}],"tv":794.96}]}
{"op":"mcm","clk":"11819478943","pt":1723392161135,"mc":[{"id":"1.231679052","rc":[{"batb":[[1,1.55,19.69],[2,1.52,1.04]],"ltp":1.83,"tv":712.06,"id":19144241}]}]}
{"op":"mcm","clk":"11819479229","pt":1723392163627,"mc":[{"id":"1.231679052","rc":[{"batb":[[1,1.52,1.04],[2,1.5,9.49]],"ltp":1.83,"tv":712.06,"id":19144241}]}]}
{"op":"mcm","clk":"11819480188","pt":1723392172612,"mc":[{"id":"1.231679052","rc":[{"batb":[[1,1.5,10.48],[2,1.43,1.65]],"ltp":1.83,"tv":712.06,"id":19144241}]}]}
{"op":"mcm","clk":"11819480562","pt":1723392176063,"mc":[{"id":"1.231679052","rc":[{"batb":[[2,1.43,1.57]],"ltp":1.83,"tv":712.06,"id":19144241}]}]}
{"op":"mcm","clk":"11819480846","pt":1723392178741,"mc":[{"id":"1.231679052","rc":[{"trd":[[1.58,36.08]],"batb":[[0,1.58,35.29]],"ltp":1.58,"tv":748.14,"id":19144241}],"tv":831.04}]}
{"op":"mcm","clk":"11819480947","pt":1723392179630,"mc":[{"id":"1.231679052","rc":[{"batb":[[0,1.6,19.69],[1,1.58,35.29],[2,1.5,10.48]],"ltp":1.58,"tv":748.14,"id":19144241}]}]}
{"op":"mcm","clk":"11819482203","pt":1723392192027,"mc":[{"id":"1.231679052","rc":[{"batb":[[0,1.58,35.29],[1,1.5,10.48],[2,1.43,1.57]],"ltp":1.58,"tv":748.14,"id":19144241}]}]}
{"op":"mcm","clk":"11819482581","pt":1723392195392,"mc":[{"id":"1.231679052","rc":[{"batl":[[1,3.7,17.65]],"ltp":2.2,"tv":82.89,"id":19144236}]}]}
{"op":"mcm","clk":"11819482632","pt":1723392195905,"mc":[{"id":"1.231679052","rc":[{"batb":[[1,1.53,188.68]],"ltp":2.2,"tv":82.89,"id":19144236},{"batb":[[2,1.36,27.48]],"ltp":1.58,"tv":748.14,"id":19144241}]}]}
{"op":"mcm","clk":"11819483099","pt":1723392200191,"mc":[{"id":"1.231679052","rc":[{"batb":[[0,2.24,12.6],[1,1.74,17.62],[2,1.53,188.68]],"ltp":2.2,"tv":82.89,"id":19144236},{"batb":[[0,1.62,17.42],[1,1.58,35.29],[2,1.5,10.48]],"ltp":1.58,"tv":748.14,"id":19144241}]}]}
{"op":"mcm","clk":"11819483382","pt":1723392202591,"mc":[{"id":"1.231679052","rc":[{"batb":[[0,1.62,18.41]],"ltp":1.58,"tv":748.14,"id":19144241}]}]}
{"op":"mcm","clk":"11819483840","pt":1723392205983,"mc":[{"id":"1.231679052","rc":[{"batb":[[2,1.5,9.49]],"ltp":1.58,"tv":748.14,"id":19144241}]}]}
{"op":"mcm","clk":"11819484193","pt":1723392209283,"mc":[{"id":"1.231679052","rc":[{"trd":[[1.62,7.42]],"batb":[[0,1.62,13.9],[2,1.36,27.48]],"batl":[[1,1.84,46.88]],"ltp":1.62,"tv":755.18,"id":19144241}],"tv":838.07}]}
{"op":"mcm","clk":"11819485069","pt":1723392217191,"mc":[{"id":"1.231679052","rc":[{"batb":[[1,1.74,18]],"batl":[[1,3.7,18]],"ltp":2.2,"tv":82.89,"id":19144236},{"batb":[[2,1.41,1.66]],"ltp":1.62,"tv":755.18,"id":19144241}]}]}
{"op":"mcm","clk":"11819485185","pt":1723392218293,"mc":[{"id":"1.231679052","rc":[{"batb":[[0,1.63,24.4],[1,1.62,13.9],[2,1.58,35.29]],"ltp":1.62,"tv":755.18,"id":19144241}]}]}
{"op":"mcm","clk":"11819485519","pt":1723392221405,"mc":[{"id":"1.231679052","rc":[{"batb":[[0,1.74,18],[1,1.53,188.68],[2,1.43,232.56]],"ltp":2.2,"tv":82.89,"id":19144236},{"batb":[[1,1.58,35.29],[2,1.41,1.66]],"ltp":1.62,"tv":755.18,"id":19144241}]}]}
{"op":"mcm","clk":"11819485825","pt":1723392224075,"mc":[{"id":"1.231679052","rc":[{"batb":[[0,1.63,21]],"ltp":1.62,"tv":755.18,"id":19144241}]}]}
{"op":"mcm","clk":"11819486109","pt":1723392226405,"mc":[{"id":"1.231679052","rc":[{"batb":[[0,2.2,12.82],[1,1.74,18],[2,1.53,188.68]],"ltp":2.2,"tv":82.89,"id":19144236},{"batb":[[0,1.64,13.79],[1,1.63,21],[2,1.58,35.29]],"ltp":1.62,"tv":755.18,"id":19144241}]}]}
{"op":"mcm","clk":"11819486709","pt":1723392230923,"mc":[{"id":"1.231679052","rc":[{"batl":[[0,1.83,10.79]],"ltp":1.62,"tv":755.18,"id":19144241}]}]}
{"op":"mcm","clk":"11819486898","pt":1723392232280,"mc":[{"id":"1.231679052","rc":[{"trd":[[1.64,2.85]],"batb":[[0,1.64,12.37],[1,1.63,24.52]],"ltp":1.64,"tv":758.02,"id":19144241}],"tv":840.92}]}
{"op":"mcm","clk":"11819487916","pt":1723392241125,"mc":[{"id":"1.231679052","rc":[{"batb":[[0,1.64,13.68]],"ltp":1.64,"tv":758.02,"id":19144241}]}]}
{"op":"mcm","clk":"11819488036","pt":1723392242130,"mc":[{"id":"1.231679052","rc":[{"batl":[[0,1.81,9.95],[1,1.83,9.98],[2,1.84,46.88]],"ltp":1.64,"tv":758.02,"id":19144241}]}]}
{"op":"mcm","clk":"11819488547","pt":1723392246321,"mc":[{"id":"1.231679052","rc":[{"batb":[[0,1.74,18],[1,1.53,188.68],[2,1.43,232.56]],"ltp":2.2,"tv":82.89,"id":19144236},{"batb":[[0,1.63,21],[1,1.58,35.29],[2,1.41,1.66]],"ltp":1.64,"tv":758.02,"id":19144241}]}]}
{"op":"mcm","clk":"11819488894","pt":1723392249422,"mc":[{"id":"1.231679052","rc":[{"batl":[[0,1.8,1.36],[1,1.81,9.14],[2,1.83,9.98]],"ltp":1.64,"tv":758.02,"id":19144241}]}]}
{"op":"mcm","clk":"11819489427","pt":1723392254085,"mc":[{"id":"1.231679052","rc":[{"batb":[[0,2.24,12.6],[1,1.74,18],[2,1.53,188.68]],"ltp":2.2,"tv":82.89,"id":19144236},{"batb":[[1,1.62,17.42],[2,1.58,35.29]],"batl":[[1,1.83,9.98],[2,1.84,46.88]],"ltp":1.64,"tv":758.02,"id":19144241}]}]}
{"op":"mcm","clk":"11819489560","pt":1723392255158,"mc":[{"id":"1.231679052","rc":[{"batb":[[0,1.74,18],[1,1.53,188.68],[2,1.43,232.56]],"ltp":2.2,"tv":82.89,"id":19144236},{"batb":[[1,1.58,35.29],[2,1.41,1.66]],"ltp":1.64,"tv":758.02,"id":19144241}]}]}
{"op":"mcm","clk":"11819489934","pt":1723392257881,"mc":[{"id":"1.231679052","rc":[{"batb":[[0,1.74,17.7]],"batl":[[1,3.7,17.65]],"ltp":2.2,"tv":82.89,"id":19144236},{"batb":[[2,1.36,27.52]],"ltp":1.64,"tv":758.02,"id":19144241}]}]}
{"op":"mcm","clk":"11819490736","pt":1723392264562,"mc":[{"id":"1.231679052","rc":[{"batb":[[0,1.91,1.38],[1,1.74,17.32],[2,1.53,188.68]],"ltp":2.2,"tv":82.89,"id":19144236}]}]}
{"op":"mcm","clk":"11819491403","pt":1723392270188,"mc":[{"id":"1.231679052","rc":[{"batb":[[0,2.24,13.6],[1,1.74,17.7]],"ltp":2.2,"tv":82.89,"id":19144236},{"batb":[[1,1.62,17.42],[2,1.58,35.29]],"ltp":1.64,"tv":758.02,"id":19144241}]}]}
{"op":"mcm","clk":"11819491609","pt":1723392272009,"mc":[{"id":"1.231679052","rc":[{"batb":[[0,1.62,17.42],[1,1.58,35.29],[2,1.36,27.52]],"batl":[[2,1.84,36.26]],"ltp":1.64,"tv":758.02,"id":19144241}]}]}
{"op":"mcm","clk":"11819491864","pt":1723392274310,"mc":[{"id":"1.231679052","rc":[{"trd":[[2.54,0.94]],"batb":[[0,2.24,12.66]],"ltp":2.54,"tv":83.83,"id":19144236},{"trd":[[1.65,1.45]],"ltp":1.65,"tv":759.47,"id":19144241}],"tv":843.31}]}
{"op":"mcm","clk":"11819492362","pt":1723392278290,"mc":[{"id":"1.231679052","rc":[{"batb":[[1,1.74,18.09]],"batl":[[2,10,0.68]],"ltp":2.54,"tv":83.83,"id":19144236},{"batl":[[0,1.83,10.79],[1,1.84,36.26],[2,1.87,3]],"ltp":1.65,"tv":759.47,"id":19144241}]}]}
{"op":"mcm","clk":"11819492680","pt":1723392280612,"mc":[{"id":"1.231679052","rc":[{"trd":[[2.26,1.43],[2.54,1.06]],"batb":[[0,2.24,12.6]],"batl":[[0,2.26,4.7],[1,2.8,8.57],[2,3.7,17.65]],"ltp":2.26,"tv":84.59,"id":19144236},{"trd":[[1.79,3.8]],"batl":[[0,1.83,9.98]],"ltp":1.79,"tv":760.28,"id":19144241}],"tv":844.88}]}
{"op":"mcm","clk":"11819492958","pt":1723392282988,"mc":[{"id":"1.231679052","rc":[{"batb":[[0,1.74,18.09],[1,1.53,188.68],[2,1.43,232.56]],"ltp":2.26,"tv":84.59,"id":19144236},{"batb":[[0,1.58,35.29],[1,1.36,27.52],[2,1.33,303.03]],"ltp":1.79,"tv":760.28,"id":19144241}]}]}
{"op":"mcm","clk":"11819493933","pt":1723392291744,"mc":[{"id":"1.231679052","rc":[{"trd":[[2.26,3.35]],"batl":[[0,2.26,3.74]],"ltp":2.26,"tv":86.51,"id":19144236}],"tv":846.8}]}
{"op":"mcm","clk":"11819494517","pt":1723392296101,"mc":[{"id":"1.231679052","rc":[{"batb":[[0,1.58,36.28]],"ltp":1.79,"tv":760.28,"id":19144241}]}]}
{"op":"mcm","clk":"11819494977","pt":1723392299724,"mc":[{"id":"1.231679052","rc":[{"trd":[[2.26,7.09]],"batl":[[0,2.8,8.57],[1,3.7,17.65],[2,10,0.68]],"ltp":2.26,"tv":90.25,"id":19144236},{"trd":[[1.79,8.52]],"batl":[[0,1.79,5.78],[1,1.83,9.98],[2,1.84,36.26]],"ltp":1.79,"tv":765.0,"id":19144241}],"tv":855.26}]}
{"op":"mcm","clk":"11819495087","pt":1723392300720,"mc":[{"id":"1.231679052","rc":[{"batl":[[0,1.79,15.66]],"ltp":1.79,"tv":765.0,"id":19144241}]}]}
{"op":"mcm","clk":"11819495223","pt":1723392301741,"mc":[{"id":"1.231679052","rc":[{"batl":[[0,1.79,16.98]],"ltp":1.79,"tv":765.0,"id":19144241}]}]}
{"op":"mcm","clk":"11819495711","pt":1723392305415,"mc":[{"id":"1.231679052","rc":[{"batb":[[0,1.6,20.68],[1,1.58,35.29],[2,1.36,27.52]],"ltp":1.79,"tv":765.0,"id":19144241}]}]}
{"op":"mcm","clk":"11819495913","pt":1723392306837,"mc":[{"id":"1.231679052","rc":[{"batl":[[0,1.79,21.48]],"ltp":1.79,"tv":765.0,"id":19144241}]}]}
{"op":"mcm","clk":"11819496104","pt":1723392308363,"mc":[{"id":"1.231679052","rc":[{"trd":[[2.26,8.21]],"ltp":2.26,"tv":91.38,"id":19144236},{"trd":[[1.79,9.94]],"batl":[[0,1.79,20.06]],"ltp":1.79,"tv":766.42,"id":19144241}],"tv":857.8}]}
{"op":"mcm","clk":"11819496120","pt":1723392308424,"mc":[{"id":"1.231679052","rc":[{"batb":[[0,2.22,12.71],[1,1.74,18.09],[2,1.53,188.68]],"ltp":2.26,"tv":91.38,"id":19144236},{"batb":[[0,1.63,18.3],[1,1.6,19.69],[2,1.58,35.29]],"ltp":1.79,"tv":766.42,"id":19144241}]}]}
{"op":"mcm","clk":"11819496500","pt":1723392311429,"mc":[{"id":"1.231679052","rc":[{"batl":[[1,10,1.03],[2,10,0]],"ltp":2.26,"tv":91.38,"id":19144236}]}]}
{"op":"mcm","clk":"11819497163","pt":1723392316160,"mc":[{"id":"1.231679052","rc":[{"batb":[[1,1.58,35.29],[2,1.33,303.88]],"ltp":1.79,"tv":766.42,"id":19144241}]}]}
{"op":"mcm","clk":"11819497336","pt":1723392317261,"mc":[{"id":"1.231679052","rc":[{"batl":[[1,10,0.68]],"ltp":2.26,"tv":91.38,"id":19144236}]}]}
{"op":"mcm","clk":"11819497404","pt":1723392317849,"mc":[{"id":"1.231679052","rc":[{"batb":[[1,1.74,17.71]],"ltp":2.26,"tv":91.38,"id":19144236},{"batb":[[2,1.33,303.03]],"ltp":1.79,"tv":766.42,"id":19144241}]}]}
{"op":"mcm","clk":"11819497615","pt":1723392319363,"mc":[{"id":"1.231679052","rc":[{"trd":[[2.26,11.93]],"ltp":2.26,"tv":95.1,"id":19144236},{"trd":[[1.79,14.63]],"batl":[[0,1.79,15.36]],"ltp":1.79,"tv":771.12,"id":19144241}],"tv":866.22}]}
{"op":"mcm","clk":"11819498665","pt":1723392326273,"mc":[{"id":"1.231679052","rc":[{"batb":[[0,1.65,27.99]],"ltp":1.79,"tv":771.12,"id":19144241}]}]}
{"op":"mcm","clk":"11819499317","pt":1723392331274,"mc":[{"id":"1.231679052","rc":[{"batb":[[0,1.65,45.14]],"ltp":1.79,"tv":771.12,"id":19144241}]}]}
{"op":"mcm","clk":"11819499614","pt":1723392333363,"mc":[{"id":"1.231679052","rc":[{"batl":[[1,1000,1.03]],"ltp":2.26,"tv":95.1,"id":19144236}]}]}
{"op":"mcm","clk":"11819499679","pt":1723392333876,"mc":[{"id":"1.231679052","rc":[{"batl":[[1,10,0.68]],"ltp":2.26,"tv":95.1,"id":19144236}]}]}
{"op":"mcm","clk":"11819499814","pt":1723392334774,"mc":[{"id":"1.231679052","rc":[{"batb":[[0,2.28,1.45],[1,2.22,12.71],[2,1.74,17.71]],"ltp":2.26,"tv":95.1,"id":19144236}]}]}
{"op":"mcm","clk":"11819500104","pt":1723392336893,"mc":[{"id":"1.231679052","rc":[{"batl":[[0,1.79,16.02]],"ltp":1.79,"tv":771.12,"id":19144241}]}]}
{"op":"mcm","clk":"11819500407","pt":1723392338954,"mc":[{"id":"1.231679052","rc":[{"batb":[[2,1.74,18.11]],"batl":[[1,10,1.03]],"ltp":2.26,"tv":95.1,"id":19144236},{"batb":[[2,1.33,303.93]],"ltp":1.79,"tv":771.12,"id":19144241}]}]}
{"op":"mcm","clk":"11819502381","pt":1723392352335,"mc":[{"id":"1.231679052","rc":[{"batl":[[0,1.79,6.47]],"ltp":1.79,"tv":771.12,"id":19144241}]}]}
{"op":"mcm","clk":"11819504447","pt":1723392368110,"mc":[{"id":"1.231679052","rc":[{"batb":[[0,1.66,13.53],[1,1.65,45.14],[2,1.58,35.29]],"ltp":1.79,"tv":771.12,"id":19144241}]}]}
{"op":"mcm","clk":"11819505157","pt":1723392374241,"mc":[{"id":"1.231679052","rc":[{"batb":[[0,2.28,2.44]],"ltp":2.26,"tv":95.1,"id":19144236}]}]}
{"op":"mcm","clk":"11819505442","pt":1723392376458,"mc":[{"id":"1.231679052","rc":[{"batb":[[1,1.65,18.14]],"ltp":1.79,"tv":771.12,"id":19144241}]}]}
{"op":"mcm","clk":"11819505800","pt":1723392379224,"mc":[{"id":"1.231679052","rc":[{"batb":[[0,1.66,14.66]],"ltp":1.79,"tv":771.12,"id":19144241}]}]}
{"op":"mcm","clk":"11819505896","pt":1723392380165,"mc":[{"id":"1.231679052","rc":[{"batb":[[2,1.74,17.72]],"batl":[[1,10,0.68]],"ltp":2.26,"tv":95.1,"id":19144236}]}]}
{"op":"mcm","clk":"11819506311","pt":1723392383548,"mc":[{"id":"1.231679052","rc":[{"batb":[[0,2.28,1.45]],"ltp":2.26,"tv":95.1,"id":19144236}]}]}
{"op":"mcm","clk":"11819506654","pt":1723392386338,"mc":[{"id":"1.231679052","rc":[{"batb":[[0,1.68,27],[1,1.66,14.66],[2,1.58,36.28]],"ltp":1.79,"tv":771.12,"id":19144241}]}]}
{"op":"mcm","clk":"11819507175","pt":1723392390465,"mc":[{"id":"1.231679052","rc":[{"batb":[[2,1.63,18.3]],"ltp":1.79,"tv":771.12,"id":19144241}]}]}
{"op":"mcm","clk":"11819508579","pt":1723392399845,"mc":[{"id":"1.231679052","rc":[{"batb":[[2,1.74,18.14]],"batl":[[1,10,1.03]],"ltp":2.26,"tv":95.1,"id":19144236}]}]}
{"op":"mcm","clk":"11819512167","pt":1723392427804,"mc":[{"id":"1.231679052","rc":[{"batb":[[1,1.74,18.14],[2,1.53,188.68]],"ltp":2.26,"tv":95.1,"id":19144236},{"batb":[[2,1.58,36.28]],"ltp":1.79,"tv":771.12,"id":19144241}]}]}
{"op":"mcm","clk":"11819512767","pt":1723392432829,"mc":[{"id":"1.231679052","rc":[{"batb":[[1,2.18,12.93],[2,1.74,18.14]],"ltp":2.26,"tv":95.1,"id":19144236},{"batb":[[2,1.65,18.07]],"ltp":1.79,"tv":771.12,"id":19144241}]}]}
{"op":"mcm","clk":"11819513131","pt":1723392435692,"mc":[{"id":"1.231679052","rc":[{"batb":[[1,1.74,18.14],[2,1.53,188.68]],"ltp":2.26,"tv":95.1,"id":19144236},{"batb":[[2,1.58,36.28]],"ltp":1.79,"tv":771.12,"id":19144241}]}]}
{"op":"mcm","clk":"11819513516","pt":1723392438920,"mc":[{"id":"1.231679052","rc":[{"batl":[[2,1.84,31.75]],"ltp":1.79,"tv":771.12,"id":19144241}]}]}
{"op":"mcm","clk":"11819513806","pt":1723392441151,"mc":[{"id":"1.231679052","rc":[{"batb":[[1,1.74,17.74]],"batl":[[1,10,0.68]],"ltp":2.26,"tv":95.1,"id":19144236}]}]}
{"op":"mcm","clk":"11819514046","pt":1723392443108,"mc":[{"id":"1.231679052","rc":[{"batl":[[0,1.79,1.97]],"ltp":1.79,"tv":771.12,"id":19144241}]}]}
{"op":"mcm","clk":"11819514174","pt":1723392444007,"mc":[{"id":"1.231679052","rc":[{"batb":[[1,2.18,12.93],[2,1.74,17.74]],"ltp":2.26,"tv":95.1,"id":19144236},{"batb":[[2,1.65,18.07]],"ltp":1.79,"tv":771.12,"id":19144241}]}]}
{"op":"mcm","clk":"11819515944","pt":1723392457134,"mc":[{"id":"1.231679052","rc":[{"batl":[[1,1.84,31.75],[2,1.87,3]],"ltp":1.79,"tv":771.12,"id":19144241}]}]}
{"op":"mcm","clk":"11819516888","pt":1723392463245,"mc":[{"id":"1.231679052","rc":[{"batb":[[2,1.74,18.16]],"batl":[[1,10,1.03]],"ltp":2.26,"tv":95.1,"id":19144236}]}]}
{"op":"mcm","clk":"11819517717","pt":1723392470360,"mc":[{"id":"1.231679052","rc":[{"batb":[[0,1.7,1.09],[1,1.68,27],[2,1.66,14.66]],"ltp":1.79,"tv":771.12,"id":19144241}]}]}
{"op":"mcm","clk":"11819518675","pt":1723392478368,"mc":[{"id":"1.231679052","rc":[{"batb":[[1,1.66,14.66],[2,1.65,18.07]],"ltp":1.79,"tv":771.12,"id":19144241}]}]}
{"op":"mcm","clk":"11819519432","pt":1723392484760,"mc":[{"id":"1.231679052","rc":[{"batb":[[1,1.74,18.16],[2,1.53,188.68]],"ltp":2.26,"tv":95.1,"id":19144236},{"batb":[[2,1.39,2.79]],"ltp":1.79,"tv":771.12,"id":19144241}]}]}
{"op":"mcm","clk":"11819520248","pt":1723392491640,"mc":[{"id":"1.231679052","rc":[{"batl":[[0,1.79,1.31]],"ltp":1.79,"tv":771.12,"id":19144241}]}]}
{"op":"mcm","clk":"11819520554","pt":1723392494288,"mc":[{"id":"1.231679052","rc":[{"batb":[[1,2.18,12.93],[2,1.74,18.16]],"ltp":2.26,"tv":95.1,"id":19144236},{"batb":[[2,1.65,18.07]],"ltp":1.79,"tv":771.12,"id":19144241}]}]}
{"op":"mcm","clk":"11819521067","pt":1723392498271,"mc":[{"id":"1.231679052","rc":[{"batb":[[1,1.66,13.53]],"ltp":1.79,"tv":771.12,"id":19144241}]}]}
{"op":"mcm","clk":"11819521205","pt":1723392499383,"mc":[{"id":"1.231679052","rc":[{"batb":[[2,1.74,17.74]],"batl":[[1,10,0.68]],"ltp":2.26,"tv":95.1,"id":19144236}]}]}
{"op":"mcm","clk":"11819521758","pt":1723392503674,"mc":[{"id":"1.231679052","rc":[{"batb":[[2,1.65,17.08]],"ltp":1.79,"tv":771.12,"id":19144241}]}]}
{"op":"mcm","clk":"11819523492","pt":1723392518289,"mc":[{"id":"1.231679052","rc":[{"batl":[[1,10,1.03]],"ltp":2.26,"tv":95.1,"id":19144236}]}]}
{"op":"mcm","clk":"11819523515","pt":1723392518497,"mc":[{"id":"1.231679052","rc":[{"batb":[[2,1.74,18.15]],"ltp":2.26,"tv":95.1,"id":19144236}]}]}
{"op":"mcm","clk":"11819524582","pt":1723392527373,"mc":[{"id":"1.231679052","rc":[{"batb":[[0,2.18,12.93],[1,1.74,18.15],[2,1.53,188.68]],"ltp":2.26,"tv":95.1,"id":19144236}]}]}
{"op":"mcm","clk":"11819525709","pt":1723392536014,"mc":[{"id":"1.231679052","rc":[{"batl":[[0,2.8,9.57]],"ltp":2.26,"tv":95.1,"id":19144236}]}]}
{"op":"mcm","clk":"11819526170","pt":1723392539915,"mc":[{"id":"1.231679052","rc":[{"batb":[[2,1.39,1.8]],"ltp":1.79,"tv":771.12,"id":19144241}]}]}
{"op":"mcm","clk":"11819526779","pt":1723392544824,"mc":[{"id":"1.231679052","rc":[{"batb":[[1,1.67,16.93],[2,1.66,13.53]],"ltp":1.79,"tv":771.12,"id":19144241}]}]}
{"op":"mcm","clk":"11819526943","pt":1723392546209,"mc":[{"id":"1.231679052","rc":[{"batb":[[0,1.74,18.15],[1,1.53,188.68],[2,1.43,232.56]],"ltp":2.26,"tv":95.1,"id":19144236},{"batb":[[1,1.66,13.53],[2,1.39,1.8]],"ltp":1.79,"tv":771.12,"id":19144241}]}]}
{"op":"mcm","clk":"11819528210","pt":1723392556853,"mc":[{"id":"1.231679052","rc":[{"batb":[[0,1.74,18.18]],"ltp":2.26,"tv":95.1,"id":19144236}]}]}
{"op":"mcm","clk":"11819528578","pt":1723392559649,"mc":[{"id":"1.231679052","rc":[{"batb":[[0,2.14,13.19],[1,1.74,18.15],[2,1.53,188.68]],"ltp":2.26,"tv":95.1,"id":19144236},{"batb":[[1,1.67,16.86],[2,1.66,13.53]],"ltp":1.79,"tv":771.12,"id":19144241}]}]}
{"op":"mcm","clk":"11819528719","pt":1723392560759,"mc":[{"id":"1.231679052","rc":[{"batb":[[0,1.74,18.18],[1,1.53,188.68],[2,1.43,232.56]],"ltp":2.26,"tv":95.1,"id":19144236},{"batb":[[1,1.66,13.53],[2,1.39,1.8]],"ltp":1.79,"tv":771.12,"id":19144241}]}]}
{"op":"mcm","clk":"11819529307","pt":1723392565252,"mc":[{"id":"1.231679052","rc":[{"batl":[[1,10,0.68]],"ltp":2.26,"tv":95.1,"id":19144236}]}]}
{"op":"mcm","clk":"11819529368","pt":1723392565635,"mc":[{"id":"1.231679052","rc":[{"batb":[[0,1.74,17.76]],"ltp":2.26,"tv":95.1,"id":19144236},{"batb":[[2,1.33,303.93]],"ltp":1.79,"tv":771.12,"id":19144241}]}]}
{"op":"mcm","clk":"11819530073","pt":1723392571371,"mc":[{"id":"1.231679052","rc":[{"batl":[[0,1.84,31.75],[1,1.87,3],[2,1.88,25.76]],"ltp":1.79,"tv":771.12,"id":19144241}]}]}
{"op":"mcm","clk":"11819531236","pt":1723392580983,"mc":[{"id":"1.231679052","rc":[{"batb":[[0,2.14,13.19],[1,1.74,17.73],[2,1.53,188.68]],"ltp":2.26,"tv":95.1,"id":19144236},{"batb":[[1,1.67,16.86],[2,1.66,13.53]],"ltp":1.79,"tv":771.12,"id":19144241}]}]}
{"op":"mcm","clk":"11819531439","pt":1723392582382,"mc":[{"id":"1.231679052","rc":[{"batb":[[0,1.74,17.76],[1,1.53,188.68],[2,1.43,232.56]],"ltp":2.26,"tv":95.1,"id":19144236},{"batb":[[1,1.66,13.53],[2,1.33,303.93]],"ltp":1.79,"tv":771.12,"id":19144241}]}]}
{"op":"mcm","clk":"11819532004","pt":1723392587293,"mc":[{"id":"1.231679052","rc":[{"batb":[[0,1.74,18.22]],"batl":[[1,10,1.03]],"ltp":2.26,"tv":95.1,"id":19144236},{"batb":[[2,1.39,1.7]],"ltp":1.79,"tv":771.12,"id":19144241}]}]}
{"op":"mcm","clk":"11819532795","pt":1723392594084,"mc":[{"id":"1.231679052","rc":[{"batb":[[0,2.2,4.54],[1,1.74,18.19],[2,1.53,188.68]],"ltp":2.26,"tv":95.1,"id":19144236}]}]}
{"op":"mcm","clk":"11819533364","pt":1723392598585,"mc":[{"id":"1.231679052","rc":[{"batl":[[1,1.87,13.82]],"ltp":1.79,"tv":771.12,"id":19144241}]}]}
{"op":"mcm","clk":"11819534106","pt":1723392604677,"mc":[{"id":"1.231679052","rc":[{"batb":[[1,2.16,13.09],[2,1.74,18.19]],"ltp":2.26,"tv":95.1,"id":19144236},{"batb":[[1,1.67,16.93],[2,1.66,13.53]],"ltp":1.79,"tv":771.12,"id":19144241}]}]}
{"op":"mcm","clk":"11819535453","pt":1723392615014,"mc":[{"id":"1.231679052","rc":[{"batb":[[1,1.74,18.19],[2,1.53,188.68]],"ltp":2.26,"tv":95.1,"id":19144236},{"batb":[[1,1.66,13.53],[2,1.39,1.7]],"ltp":1.79,"tv":771.12,"id":19144241}]}]}
{"op":"mcm","clk":"11819536741","pt":1723392624710,"mc":[{"id":"1.231679052","rc":[{"batb":[[1,2.16,13.09],[2,1.74,18.19]],"ltp":2.26,"tv":95.1,"id":19144236},{"batb":[[1,1.67,16.93],[2,1.66,13.53]],"ltp":1.79,"tv":771.12,"id":19144241}]}]}
{"op":"mcm","clk":"11819538322","pt":1723392637328,"mc":[{"id":"1.231679052","rc":[{"batb":[[2,1.74,17.78]],"batl":[[1,10,0.68]],"ltp":2.26,"tv":95.1,"id":19144236}]}]}
{"op":"mcm","clk":"11819538619","pt":1723392639648,"mc":[{"id":"1.231679052","rc":[{"trd":[[2.28,0.03]],"batb":[[0,2.2,4.51]],"ltp":2.28,"tv":95.13,"id":19144236},{"trd":[[1.79,14.68]],"batb":[[0,1.7,2.04]],"ltp":1.79,"tv":771.16,"id":19144241}],"tv":866.29}]}
{"op":"mcm","clk":"11819539907","pt":1723392650548,"mc":[{"id":"1.231679052","rc":[{"batb":[[0,1.7,1.09]],"ltp":1.79,"tv":771.16,"id":19144241}]}]}
{"op":"mcm","clk":"11819541008","pt":1723392659144,"mc":[{"id":"1.231679052","rc":[{"batb":[[0,2.2,4.56]],"ltp":2.28,"tv":95.13,"id":19144236}]}]}
{"op":"mcm","clk":"11819541056","pt":1723392659558,"mc":[{"id":"1.231679052","rc":[{"batb":[[2,1.33,303.83]],"ltp":1.79,"tv":771.16,"id":19144241}]}]}
{"op":"mcm","clk":"11819542400","pt":1723392669640,"mc":[{"id":"1.231679052","rc":[{"batb":[[2,1.74,18.24]],"batl":[[1,10,1.03]],"ltp":2.28,"tv":95.13,"id":19144236},{"batb":[[2,1.44,1.6]],"ltp":1.79,"tv":771.16,"id":19144241}]}]}
{"op":"mcm","clk":"11819543323","pt":1723392676751,"mc":[{"id":"1.231679052","rc":[{"batb":[[1,1.68,13.53],[2,1.67,16.93]],"ltp":1.79,"tv":771.16,"id":19144241}]}]}
{"op":"mcm","clk":"11819549580","pt":1723392723614,"mc":[{"id":"1.231679052","rc":[{"batb":[[0,1.7,1.3]],"batl":[[0,1.83,1.82],[1,1.84,31.75],[2,1.87,13.82]],"ltp":1.79,"tv":771.16,"id":19144241}]}]}
{"op":"mcm","clk":"11819550265","pt":1723392729039,"mc":[{"id":"1.231679052","rc":[{"batl":[[1,10,0.68]],"ltp":2.28,"tv":95.13,"id":19144236}]}]}
{"op":"mcm","clk":"11819550366","pt":1723392729940,"mc":[{"id":"1.231679052","rc":[{"batb":[[2,1.74,17.78]],"ltp":2.28,"tv":95.13,"id":19144236}]}]}
{"op":"mcm","clk":"11819550775","pt":1723392733440,"mc":[{"id":"1.231679052","rc":[{"batb":[[0,2.16,13.14],[1,1.74,17.78],[2,1.53,188.68]],"ltp":2.28,"tv":95.13,"id":19144236}]}]}
{"op":"mcm","clk":"11819552552","pt":1723392747443,"mc":[{"id":"1.231679052","rc":[{"batl":[[0,1.84,31.75],[1,1.87,13.82],[2,1.88,25.76]],"ltp":1.79,"tv":771.16,"id":19144241}]}]}
{"op":"mcm","clk":"11819553045","pt":1723392751239,"mc":[{"id":"1.231679052","rc":[{"batl":[[1,10,1.03]],"ltp":2.28,"tv":95.13,"id":19144236}]}]}
{"op":"mcm","clk":"11819553073","pt":1723392751458,"mc":[{"id":"1.231679052","rc":[{"batb":[[1,1.74,18.24]],"ltp":2.28,"tv":95.13,"id":19144236}]}]}
{"op":"mcm","clk":"11819554466","pt":1723392763149,"mc":[{"id":"1.231679052","rc":[{"batl":[[0,1.84,32.65]],"ltp":1.79,"tv":771.16,"id":19144241}]}]}
{"op":"mcm","clk":"11819567629","pt":1723392789105,"mc":[{"id":"1.231679052","rc":[{"batb":[[1,1.74,17.78]],"batl":[[1,10,0.68]],"ltp":2.28,"tv":95.13,"id":19144236}]}]}
{"op":"mcm","clk":"11819570629","pt":1723392812322,"mc":[{"id":"1.231679052","rc":[{"trd":[[2.18,2.32],[2.2,34.31],[2.24,8.39]],"batb":[[0,2.16,13.09]],"ltp":2.18,"tv":97.34,"id":19144236},{"trd":[[1.8,15.93],[1.84,53.84]],"batl":[[0,1.84,30.1]],"ltp":1.84,"tv":773.71,"id":19144241}],"tv":871.06}]}
{"op":"mcm","clk":"11819570652","pt":1723392812531,"mc":[{"id":"1.231679052","rc":[{"batb":[[1,1.74,18.24]],"batl":[[1,10,1.03]],"ltp":2.18,"tv":97.34,"id":19144236}]}]}
{"op":"mcm","clk":"11819574165","pt":1723392841139,"mc":[{"id":"1.231679052","rc":[{"batl":[[1,10,0.68]],"ltp":2.18,"tv":97.34,"id":19144236}]}]}
{"op":"mcm","clk":"11819574228","pt":1723392841619,"mc":[{"id":"1.231679052","rc":[{"batb":[[1,1.74,17.78]],"ltp":2.18,"tv":97.34,"id":19144236}]}]}
{"op":"mcm","clk":"11819576140","pt":1723392856034,"mc":[{"id":"1.231679052","rc":[{"batb":[[0,1.7,1.35]],"ltp":1.84,"tv":773.71,"id":19144241}]}]}
{"op":"mcm","clk":"11819577220","pt":1723392864373,"mc":[{"id":"1.231679052","rc":[{"batb":[[1,1.74,18.24]],"batl":[[1,10,1.03]],"ltp":2.18,"tv":97.34,"id":19144236}]}]}
{"op":"mcm","clk":"11819580498","pt":1723392890418,"mc":[{"id":"1.231679052","rc":[{"batb":[[0,1.76,2.48],[1,1.7,1.09],[2,1.68,13.53]],"ltp":1.84,"tv":773.71,"id":19144241}]}]}
{"op":"mcm","clk":"11819580718","pt":1723392892366,"mc":[{"id":"1.231679052","rc":[{"batl":[[1,10,0.68]],"ltp":2.18,"tv":97.34,"id":19144236}]}]}
{"op":"mcm","clk":"11819580773","pt":1723392892679,"mc":[{"id":"1.231679052","rc":[{"batb":[[1,1.74,17.78]],"ltp":2.18,"tv":97.34,"id":19144236}]}]}
{"op":"mcm","clk":"11819581336","pt":1723392896899,"mc":[{"id":"1.231679052","rc":[{"batb":[[1,1.68,13.53],[2,1.67,16.93]],"ltp":1.84,"tv":773.71,"id":19144241}]}]}
{"op":"mcm","clk":"11819581449","pt":1723392897777,"mc":[{"id":"1.231679052","rc":[{"batb":[[0,1.74,17.78],[1,1.53,188.68],[2,1.43,232.56]],"ltp":2.18,"tv":97.34,"id":19144236},{"batb":[[2,1.33,303.83]],"ltp":1.84,"tv":773.71,"id":19144241}]}]}
{"op":"mcm","clk":"11819581827","pt":1723392900623,"mc":[{"id":"1.231679052","rc":[{"batb":[[0,1.76,2.93]],"ltp":1.84,"tv":773.71,"id":19144241}]}]}
{"op":"mcm","clk":"11819582108","pt":1723392902709,"mc":[{"id":"1.231679052","rc":[{"batb":[[0,2.12,13.31],[1,1.74,17.78],[2,1.53,188.68]],"ltp":2.18,"tv":97.34,"id":19144236}]}]}
{"op":"mcm","clk":"11819582799","pt":1723392907315,"mc":[{"id":"1.231679052","rc":[{"batl":[[1,10,1.03]],"ltp":2.18,"tv":97.34,"id":19144236}]}]}
{"op":"mcm","clk":"11819582832","pt":1723392907528,"mc":[{"id":"1.231679052","rc":[{"batb":[[1,1.74,18.24]],"ltp":2.18,"tv":97.34,"id":19144236},{"batb":[[2,1.44,1.6]],"ltp":1.84,"tv":773.71,"id":19144241}]}]}
{"op":"mcm","clk":"11819583102","pt":1723392909196,"mc":[{"id":"1.231679052","rc":[{"batb":[[1,1.68,30.28]],"ltp":1.84,"tv":773.71,"id":19144241}]}]}
{"op":"mcm","clk":"11819584790","pt":1723392922027,"mc":[{"id":"1.231679052","rc":[{"trd":[[1.76,31.36],[1.78,0.9]],"batb":[[0,1.68,30.7],[1,1.44,1.6],[2,1.33,303.03]],"ltp":1.76,"tv":778.22,"id":19144241}],"tv":875.57}]}
{"op":"mcm","clk":"11819586740","pt":1723392936139,"mc":[{"id":"1.231679052","rc":[{"batb":[[1,1.74,17.78]],"batl":[[1,10,0.68]],"ltp":2.18,"tv":97.34,"id":19144236},{"batb":[[1,1.33,303.83],[2,1.26,4.7]],"ltp":1.76,"tv":778.22,"id":19144241}]}]}
{"op":"mcm","clk":"11819587007","pt":1723392938241,"mc":[{"id":"1.231679052","rc":[{"batb":[[0,1.77,12],[1,1.68,30.7],[2,1.33,303.83]],"ltp":1.76,"tv":778.22,"id":19144241}]}]}
{"op":"mcm","clk":"11819587267","pt":1723392940170,"mc":[{"id":"1.231679052","rc":[{"batb":[[0,1.74,17.78],[1,1.53,188.68],[2,1.43,232.56]],"ltp":2.18,"tv":97.34,"id":19144236},{"batb":[[1,1.68,13.95]],"ltp":1.76,"tv":778.22,"id":19144241}]}]}
{"op":"mcm","clk":"11819589086","pt":1723392953234,"mc":[{"id":"1.231679052","rc":[{"batb":[[0,1.74,18.25]],"batl":[[1,10,1.03]],"ltp":2.18,"tv":97.34,"id":19144236},{"batb":[[2,1.44,1.6]],"ltp":1.76,"tv":778.22,"id":19144241}]}]}
{"op":"mcm","clk":"11819590424","pt":1723392962742,"mc":[{"id":"1.231679052","rc":[{"batb":[[0,1.68,13.95],[1,1.44,1.6],[2,1.33,303.03]],"batl":[[0,1.77,6.13],[1,1.84,30.1],[2,1.87,13.82]],"ltp":1.76,"tv":778.22,"id":19144241}]}]}
{"op":"mcm","clk":"11819591004","pt":1723392966466,"mc":[{"id":"1.231679052","rc":[{"batl":[[0,1.84,30.1],[1,1.87,13.82],[2,1.88,25.76]],"ltp":1.76,"tv":778.22,"id":19144241}]}]}
{"op":"mcm","clk":"11819591217","pt":1723392968068,"mc":[{"id":"1.231679052","rc":[{"batb":[[0,1.68,14.52]],"ltp":1.76,"tv":778.22,"id":19144241}]}]}
{"op":"mcm","clk":"11819591453","pt":1723392969665,"mc":[{"id":"1.231679052","rc":[{"batb":[[0,2.16,13.04],[1,1.74,18.25],[2,1.53,188.68]],"ltp":2.18,"tv":97.34,"id":19144236},{"batb":[[1,1.66,16.97],[2,1.44,1.6]],"ltp":1.76,"tv":778.22,"id":19144241}]}]}
{"op":"mcm","clk":"11819592177","pt":1723392975009,"mc":[{"id":"1.231679052","rc":[{"trd":[[2.32,2.53]],"batl":[[0,2.8,9.56]],"ltp":2.32,"tv":97.35,"id":19144236},{"trd":[[1.75,2.45],[1.76,32.2],[1.78,2.04]],"batb":[[0,1.68,13.53]],"ltp":1.75,"tv":780.21,"id":19144241}],"tv":877.56}]}
{"op":"mcm","clk":"11819593546","pt":1723392983855,"mc":[{"id":"1.231679052","rc":[{"batb":[[1,1.44,1.6],[2,1.33,303.03]],"ltp":1.75,"tv":780.21,"id":19144241}]}]}
{"op":"mcm","clk":"11819593909","pt":1723392986444,"mc":[{"id":"1.231679052","rc":[{"batl":[[0,1.82,12],[1,1.84,30.1],[2,1.87,13.82]],"ltp":1.75,"tv":780.21,"id":19144241}]}]}
{"op":"mcm","clk":"11819594234","pt":1723392988802,"mc":[{"id":"1.231679052","rc":[{"batb":[[0,1.68,30.35]],"ltp":1.75,"tv":780.21,"id":19144241}]}]}
{"op":"mcm","clk":"11819595425","pt":1723392997083,"mc":[{"id":"1.231679052","rc":[{"batb":[[1,1.74,17.79]],"batl":[[1,10,0.68]],"ltp":2.32,"tv":97.35,"id":19144236},{"batb":[[1,1.33,303.83],[2,1.26,4.7]],"ltp":1.75,"tv":780.21,"id":19144241}]}]}
{"op":"mcm","clk":"11819596639","pt":1723393005307,"mc":[{"id":"1.231679052","rc":[{"batl":[[1,1000,1.03]],"ltp":2.32,"tv":97.35,"id":19144236}]}]}
{"op":"mcm","clk":"11819596705","pt":1723393005727,"mc":[{"id":"1.231679052","rc":[{"batl":[[1,10,0.68]],"ltp":2.32,"tv":97.35,"id":19144236}]}]}
{"op":"mcm","clk":"11819597441","pt":1723393010836,"mc":[{"id":"1.231679052","rc":[{"batb":[[1,1.74,18.21]],"batl":[[1,10,1.03]],"ltp":2.32,"tv":97.35,"id":19144236},{"batb":[[1,1.42,1.63],[2,1.33,303.03]],"ltp":1.75,"tv":780.21,"id":19144241}]}]}
{"op":"mcm","clk":"11819598246","pt":1723393016760,"mc":[{"id":"1.231679052","rc":[{"batl":[[0,1.84,30.1],[1,1.87,13.82],[2,1.88,25.76]],"ltp":1.75,"tv":780.21,"id":19144241}]}]}
{"op":"mcm","clk":"11819601445","pt":1723393041199,"mc":[{"id":"1.231679052","rc":[{"batb":[[1,1.74,17.74]],"batl":[[1,10,0.68]],"ltp":2.32,"tv":97.35,"id":19144236},{"batb":[[1,1.33,303.86],[2,1.26,4.7]],"ltp":1.75,"tv":780.21,"id":19144241}]}]}
{"op":"mcm","clk":"11819603745","pt":1723393057303,"mc":[{"id":"1.231679052","rc":[{"batl":[[1,1000,1.03]],"ltp":2.32,"tv":97.35,"id":19144236}]}]}
{"op":"mcm","clk":"11819603837","pt":1723393057779,"mc":[{"id":"1.231679052","rc":[{"batl":[[1,10,0.68]],"ltp":2.32,"tv":97.35,"id":19144236}]}]}
{"op":"mcm","clk":"11819604042","pt":1723393059327,"mc":[{"id":"1.231679052","rc":[{"batl":[[0,2.42,1.06],[1,2.8,8.57],[2,10,0.68]],"ltp":2.32,"tv":97.35,"id":19144236}]}]}
{"op":"mcm","clk":"11819604588","pt":1723393063304,"mc":[{"id":"1.231679052","rc":[{"batb":[[1,1.74,18.16]],"batl":[[2,10,1.03]],"ltp":2.32,"tv":97.35,"id":19144236},{"batb":[[1,1.42,1.63],[2,1.33,303.03]],"ltp":1.75,"tv":780.21,"id":19144241}]}]}
{"op":"mcm","clk":"11819604652","pt":1723393063675,"mc":[{"id":"1.231679052","rc":[{"batl":[[0,1.83,2.22],[1,1.84,30.1],[2,1.87,13.82]],"ltp":1.75,"tv":780.21,"id":19144241}]}]}
{"op":"mcm","clk":"11819606681","pt":1723393078818,"mc":[{"id":"1.231679052","rc":[{"batb":[[0,1.74,18.16],[1,1.53,188.68],[2,1.43,232.56]],"ltp":2.32,"tv":97.35,"id":19144236}]}]}
{"op":"mcm","clk":"11819607394","pt":1723393083741,"mc":[{"id":"1.231679052","rc":[{"batb":[[0,2.12,13.27],[1,1.74,18.16],[2,1.53,188.68]],"ltp":2.32,"tv":97.35,"id":19144236}]}]}
{"op":"mcm","clk":"11819610202","pt":1723393103087,"mc":[{"id":"1.231679052","rc":[{"trd":[[1.83,6.46]],"batb":[[0,1.68,30.42]],"batl":[[0,1.84,30.1],[1,1.87,13.82],[2,1.88,25.76]],"ltp":1.83,"tv":784.65,"id":19144241}],"tv":882.0}]}
{"op":"mcm","clk":"11819612685","pt":1723393120361,"mc":[{"id":"1.231679052","rc":[{"batl":[[0,1.84,29]],"ltp":1.83,"tv":784.65,"id":19144241}]}]}
{"op":"mcm","clk":"11819614337","pt":1723393131792,"mc":[{"id":"1.231679052","rc":[{"batb":[[0,2.12,13.32]],"ltp":2.32,"tv":97.35,"id":19144236}]}]}
{"op":"mcm","clk":"11819615009","pt":1723393136375,"mc":[{"id":"1.231679052","rc":[{"batl":[[2,10,0.68]],"ltp":2.32,"tv":97.35,"id":19144236}]}]}
{"op":"mcm","clk":"11819615093","pt":1723393137014,"mc":[{"id":"1.231679052","rc":[{"batb":[[1,1.74,17.74]],"ltp":2.32,"tv":97.35,"id":19144236},{"batb":[[1,1.33,303.83],[2,1.26,4.7]],"ltp":1.83,"tv":784.65,"id":19144241}]}]}
{"op":"mcm","clk":"11819616777","pt":1723393148208,"mc":[{"id":"1.231679052","rc":[{"trd":[[2.32,3.52],[2.42,0.06]],"batl":[[0,2.8,8.57],[1,10,0.68],[2,10,0]],"ltp":2.42,"tv":98.41,"id":19144236},{"trd":[[1.7,0.09],[1.75,3.76],[1.83,6.6]],"batb":[[0,1.68,30.35]],"batl":[[0,1.75,48.53],[1,1.84,29],[2,1.87,13.82]],"ltp":1.7,"tv":786.19,"id":19144241}],"tv":884.6}]}
{"op":"mcm","clk":"11819616977","pt":1723393149609,"mc":[{"id":"1.231679052","rc":[{"batb":[[0,1.68,13.53]],"ltp":1.7,"tv":786.19,"id":19144241}]}]}
{"op":"mcm","clk":"11819617174","pt":1723393151022,"mc":[{"id":"1.231679052","rc":[{"batb":[[0,1.74,17.79],[1,1.53,188.68],[2,1.43,232.56]],"ltp":2.42,"tv":98.41,"id":19144236}]}]}
{"op":"mcm","clk":"11819617549","pt":1723393153342,"mc":[{"id":"1.231679052","rc":[{"batl":[[1,1000,1.03]],"ltp":2.42,"tv":98.41,"id":19144236}]}]}
{"op":"mcm","clk":"11819617629","pt":1723393153823,"mc":[{"id":"1.231679052","rc":[{"batl":[[1,10,0.68]],"ltp":2.42,"tv":98.41,"id":19144236}]}]}
{"op":"mcm","clk":"11819617952","pt":1723393156035,"mc":[{"id":"1.231679052","rc":[{"batb":[[0,2.16,13.14],[1,1.74,17.74],[2,1.53,188.68]],"ltp":2.42,"tv":98.41,"id":19144236}]}]}
{"op":"mcm","clk":"11819618404","pt":1723393158934,"mc":[{"id":"1.231679052","rc":[{"batb":[[1,1.74,18.2]],"batl":[[1,10,1.03]],"ltp":2.42,"tv":98.41,"id":19144236},{"batb":[[1,1.44,1.6],[2,1.33,303.03]],"ltp":1.7,"tv":786.19,"id":19144241}]}]}
{"op":"mcm","clk":"11819618832","pt":1723393161823,"mc":[{"id":"1.231679052","rc":[{"batl":[[0,1.84,29],[1,1.87,13.82],[2,1.88,25.76]],"ltp":1.7,"tv":786.19,"id":19144241}]}]}
{"op":"mcm","clk":"11819619685","pt":1723393167353,"mc":[{"id":"1.231679052","rc":[{"batb":[[0,1.74,18.25],[1,1.53,188.68],[2,1.43,232.56]],"ltp":2.42,"tv":98.41,"id":19144236},{"trd":[[1.68,187.95]],"batb":[[0,1.44,1.6],[1,1.33,303.03],[2,1.26,4.7]],"batl":[[0,1.68,35],[1,1.84,29],[2,1.87,13.82]],"ltp":1.68,"tv":813.25,"id":19144241}],"tv":911.66}]}
{"op":"mcm","clk":"11819619906","pt":1723393168726,"mc":[{"id":"1.231679052","rc":[{"batb":[[0,1.67,16.86],[1,1.44,1.6],[2,1.33,303.03]],"ltp":1.68,"tv":813.25,"id":19144241}]}]}
{"op":"mcm","clk":"11819620150","pt":1723393170529,"mc":[{"id":"1.231679052","rc":[{"batb":[[0,1.44,1.6],[1,1.33,303.03],[2,1.26,4.7]],"ltp":1.68,"tv":813.25,"id":19144241}]}]}
{"op":"mcm","clk":"11819620816","pt":1723393175175,"mc":[{"id":"1.231679052","rc":[{"batl":[[0,1.68,36.1]],"ltp":1.68,"tv":813.25,"id":19144241}]}]}
{"op":"mcm","clk":"11819621068","pt":1723393177047,"mc":[{"id":"1.231679052","rc":[{"batb":[[0,2.2,12.87],[1,1.74,18.2],[2,1.53,188.68]],"ltp":2.42,"tv":98.41,"id":19144236},{"batb":[[0,1.64,17.2],[1,1.44,1.6],[2,1.33,303.03]],"ltp":1.68,"tv":813.25,"id":19144241}]}]}
{"op":"mcm","clk":"11819621267","pt":1723393178595,"mc":[{"id":"1.231679052","rc":[{"batb":[[0,1.74,18.25],[1,1.53,188.68],[2,1.43,232.56]],"ltp":2.42,"tv":98.41,"id":19144236},{"batb":[[0,1.44,1.6],[1,1.33,303.03],[2,1.26,4.7]],"ltp":1.68,"tv":813.25,"id":19144241}]}]}
{"op":"mcm","clk":"11819621522","pt":1723393180276,"mc":[{"id":"1.231679052","rc":[{"batl":[[0,1.68,35]],"ltp":1.68,"tv":813.25,"id":19144241}]}]}
{"op":"mcm","clk":"11819622132","pt":1723393184982,"mc":[{"id":"1.231679052","rc":[{"batb":[[0,2.2,12.87],[1,1.74,18.2],[2,1.53,188.68]],"ltp":2.42,"tv":98.41,"id":19144236},{"batb":[[0,1.64,17.2],[1,1.44,1.6],[2,1.33,303.03]],"ltp":1.68,"tv":813.25,"id":19144241}]}]}
{"op":"mcm","clk":"11819622413","pt":1723393187171,"mc":[{"id":"1.231679052","rc":[{"batb":[[0,1.74,18.25],[1,1.53,188.68],[2,1.43,232.56]],"ltp":2.42,"tv":98.41,"id":19144236},{"batb":[[0,1.44,1.6],[1,1.33,303.03],[2,1.26,4.7]],"batl":[[0,1.84,29],[1,1.87,13.82],[2,1.88,25.76]],"ltp":1.68,"tv":813.25,"id":19144241}]}]}
{"op":"mcm","clk":"11819623092","pt":1723393192262,"mc":[{"id":"1.231679052","rc":[{"batl":[[0,1.64,35],[1,1.84,29],[2,1.87,13.82]],"ltp":1.68,"tv":813.25,"id":19144241}]}]}
{"op":"mcm","clk":"11819623226","pt":1723393193154,"mc":[{"id":"1.231679052","rc":[{"batb":[[0,2.24,12.6],[1,1.74,18.25],[2,1.53,188.68]],"ltp":2.42,"tv":98.41,"id":19144236},{"batb":[[0,1.62,17.42],[1,1.44,1.6],[2,1.33,303.03]],"ltp":1.68,"tv":813.25,"id":19144241}]}]}
{"op":"mcm","clk":"11819623382","pt":1723393194282,"mc":[{"id":"1.231679052","rc":[{"batb":[[0,1.74,18.25],[1,1.53,188.68],[2,1.43,232.56]],"ltp":2.42,"tv":98.41,"id":19144236},{"batb":[[0,1.55,19.69]],"ltp":1.68,"tv":813.25,"id":19144241}]}]}
{"op":"mcm","clk":"11819624262","pt":1723393200901,"mc":[{"id":"1.231679052","rc":[{"batb":[[0,2.22,12.71],[1,1.74,18.25],[2,1.53,188.68]],"ltp":2.42,"tv":98.41,"id":19144236},{"batb":[[0,1.63,17.31],[1,1.55,19.69],[2,1.44,1.6]],"ltp":1.68,"tv":813.25,"id":19144241}]}]}
{"op":"mcm","clk":"11819624448","pt":1723393202176,"mc":[{"id":"1.231679052","rc":[{"batb":[[0,1.74,18.25],[1,1.53,188.68],[2,1.43,232.56]],"ltp":2.42,"tv":98.41,"id":19144236},{"batb":[[0,1.55,19.69],[1,1.44,1.6],[2,1.33,303.03]],"ltp":1.68,"tv":813.25,"id":19144241}]}]}
{"op":"mcm","clk":"11819625457","pt":1723393209086,"mc":[{"id":"1.231679052","rc":[{"batb":[[0,2.22,12.71],[1,1.74,18.25],[2,1.53,188.68]],"ltp":2.42,"tv":98.41,"id":19144236},{"batb":[[0,1.63,17.31],[1,1.55,19.69],[2,1.44,1.6]],"ltp":1.68,"tv":813.25,"id":19144241}]}]}
{"op":"mcm","clk":"11819625630","pt":1723393210304,"mc":[{"id":"1.231679052","rc":[{"batb":[[0,1.74,18.25],[1,1.53,188.68],[2,1.43,232.56]],"ltp":2.42,"tv":98.41,"id":19144236}]}]}
{"op":"mcm","clk":"11819625671","pt":1723393210572,"mc":[{"id":"1.231679052","rc":[{"trd":[[1.64,3.57]],"batb":[[0,1.55,19.69],[1,1.44,1.6],[2,1.33,303.03]],"batl":[[0,1.64,34.64]],"ltp":1.64,"tv":813.97,"id":19144241}],"tv":912.38}]}
{"op":"mcm","clk":"11819626244","pt":1723393214785,"mc":[{"id":"1.231679052","rc":[{"trd":[[1.64,55.85]],"batl":[[0,1.64,8.5]],"ltp":1.64,"tv":866.25,"id":19144241}],"tv":964.66}]}
{"op":"mcm","clk":"11819626341","pt":1723393215571,"mc":[{"id":"1.231679052","rc":[{"trd":[[2.56,5.45]],"ltp":2.56,"tv":103.85,"id":19144236},{"trd":[[1.64,64.35]],"batl":[[0,1.84,29],[1,1.87,13.82],[2,1.88,25.76]],"ltp":1.64,"tv":874.75,"id":19144241}],"tv":978.61}]}
{"op":"mcm","clk":"11819626845","pt":1723393219308,"mc":[{"id":"1.231679052","rc":[{"batl":[[1,10,0.68]],"ltp":2.56,"tv":103.85,"id":19144236},{"batb":[[1,1.33,303.83],[2,1.26,4.7]],"ltp":1.64,"tv":874.75,"id":19144241}]}]}
{"op":"mcm","clk":"11819626873","pt":1723393219517,"mc":[{"id":"1.231679052","rc":[{"batb":[[0,1.74,17.83]],"ltp":2.56,"tv":103.85,"id":19144236}]}]}
{"op":"mcm","clk":"11819627045","pt":1723393220785,"mc":[{"id":"1.231679052","rc":[{"batb":[[0,1.64,7.3],[1,1.55,19.69],[2,1.33,303.83]],"ltp":1.64,"tv":874.75,"id":19144241}]}]}
{"op":"mcm","clk":"11819627112","pt":1723393221413,"mc":[{"id":"1.231679052","rc":[{"batb":[[0,2.18,12.98],[1,1.74,17.78],[2,1.53,188.68]],"ltp":2.56,"tv":103.85,"id":19144236},{"batb":[[0,1.65,17.08],[1,1.64,7.3],[2,1.55,19.69]],"ltp":1.64,"tv":874.75,"id":19144241}]}]}
{"op":"mcm","clk":"11819627377","pt":1723393223329,"mc":[{"id":"1.231679052","rc":[{"batb":[[0,1.74,17.83],[1,1.53,188.68],[2,1.43,232.56]],"ltp":2.56,"tv":103.85,"id":19144236},{"batb":[[0,1.64,7.3],[1,1.55,19.69],[2,1.33,303.83]],"ltp":1.64,"tv":874.75,"id":19144241}]}]}
{"op":"mcm","clk":"11819627498","pt":1723393224218,"mc":[{"id":"1.231679052","rc":[{"batl":[[0,1.84,29.05]],"ltp":1.64,"tv":874.75,"id":19144241}]}]}
{"op":"mcm","clk":"11819628040","pt":1723393228307,"mc":[{"id":"1.231679052","rc":[{"batb":[[0,2.14,13.25],[1,1.74,17.78],[2,1.53,188.68]],"ltp":2.56,"tv":103.85,"id":19144236},{"batb":[[0,1.68,16.82],[1,1.64,7.3],[2,1.55,19.69]],"ltp":1.64,"tv":874.75,"id":19144241}]}]}
{"op":"mcm","clk":"11819628096","pt":1723393228729,"mc":[{"id":"1.231679052","rc":[{"batb":[[1,1.55,19.69],[2,1.33,303.83]],"ltp":1.64,"tv":874.75,"id":19144241}]}]}
{"op":"mcm","clk":"11819628460","pt":1723393230994,"mc":[{"id":"1.231679052","rc":[{"batb":[[0,1.55,19.69],[1,1.33,303.83],[2,1.26,4.7]],"ltp":1.64,"tv":874.75,"id":19144241}]}]}
{"op":"mcm","clk":"11819628791","pt":1723393232827,"mc":[{"id":"1.231679052","rc":[{"batb":[[0,1.74,17.83],[1,1.53,188.68],[2,1.43,232.56]],"ltp":2.56,"tv":103.85,"id":19144236}]}]}
{"op":"mcm","clk":"11819629212","pt":1723393235999,"mc":[{"id":"1.231679052","rc":[{"batb":[[0,1.66,16.97],[1,1.55,19.69],[2,1.33,303.83]],"ltp":1.64,"tv":874.75,"id":19144241}]}]}
{"op":"mcm","clk":"11819629434","pt":1723393237522,"mc":[{"id":"1.231679052","rc":[{"batb":[[0,1.55,19.69],[1,1.33,303.83],[2,1.26,4.7]],"ltp":1.64,"tv":874.75,"id":19144241}]}]}
{"op":"mcm","clk":"11819630034","pt":1723393242502,"mc":[{"id":"1.231679052","rc":[{"batb":[[0,2.14,13.25],[1,1.74,17.78],[2,1.53,188.68]],"ltp":2.56,"tv":103.85,"id":19144236},{"batb":[[0,1.68,16.82],[1,1.55,19.69],[2,1.33,303.83]],"ltp":1.64,"tv":874.75,"id":19144241}]}]}
{"op":"mcm","clk":"11819630365","pt":1723393245149,"mc":[{"id":"1.231679052","rc":[{"batb":[[1,1.56,11.52],[2,1.55,19.69]],"ltp":1.64,"tv":874.75,"id":19144241}]}]}
{"op":"mcm","clk":"11819630484","pt":1723393246041,"mc":[{"id":"1.231679052","rc":[{"batb":[[1,1.74,18.13]],"batl":[[1,10,1.03]],"ltp":2.56,"tv":103.85,"id":19144236}]}]}
{"op":"mcm","clk":"11819631233","pt":1723393251146,"mc":[{"id":"1.231679052","rc":[{"trd":[[2.18,2.36],[2.2,34.41],[2.28,0.07]],"batb":[[0,2.14,13.2]],"ltp":2.18,"tv":104.03,"id":19144236},{"trd":[[1.77,15.78],[1.84,53.89]],"batl":[[0,1.84,28.96]],"ltp":1.84,"tv":874.85,"id":19144241}],"tv":978.88}]}
{"op":"mcm","clk":"11819631538","pt":1723393253548,"mc":[{"id":"1.231679052","rc":[{"batb":[[0,1.56,11.52],[1,1.55,19.69],[2,1.44,1.6]],"ltp":1.84,"tv":874.85,"id":19144241}]}]}
{"op":"mcm","clk":"11819632219","pt":1723393258452,"mc":[{"id":"1.231679052","rc":[{"batb":[[0,1.66,16.97],[1,1.56,11.52],[2,1.55,19.69]],"ltp":1.84,"tv":874.85,"id":19144241}]}]}
{"op":"mcm","clk":"11819633337","pt":1723393266072,"mc":[{"id":"1.231679052","rc":[{"batl":[[0,1.68,4.76],[1,1.84,28.96],[2,1.87,13.82]],"ltp":1.84,"tv":874.85,"id":19144241}]}]}
{"op":"mcm","clk":"11819633474","pt":1723393267077,"mc":[{"id":"1.231679052","rc":[{"batb":[[0,1.74,18.13],[1,1.53,188.68],[2,1.43,232.56]],"ltp":2.18,"tv":104.03,"id":19144236},{"batb":[[0,1.56,11.52],[1,1.55,19.69],[2,1.44,1.6]],"ltp":1.84,"tv":874.85,"id":19144241}]}]}
{"op":"mcm","clk":"11819634385","pt":1723393273238,"mc":[{"id":"1.231679052","rc":[{"batb":[[0,2.2,12.82],[1,1.74,18.13],[2,1.53,188.68]],"ltp":2.18,"tv":104.03,"id":19144236},{"batb":[[0,1.64,17.2],[1,1.56,11.52],[2,1.55,19.69]],"ltp":1.84,"tv":874.85,"id":19144241}]}]}
{"op":"mcm","clk":"11819634613","pt":1723393274872,"mc":[{"id":"1.231679052","rc":[{"batb":[[0,1.74,18.13],[1,1.53,188.68],[2,1.43,232.56]],"ltp":2.18,"tv":104.03,"id":19144236},{"batb":[[0,1.56,11.52],[1,1.55,19.69],[2,1.44,1.6]],"ltp":1.84,"tv":874.85,"id":19144241}]}]}
{"op":"mcm","clk":"11819634761","pt":1723393275867,"mc":[{"id":"1.231679052","rc":[{"batl":[[0,1.84,28.96],[1,1.87,13.82],[2,1.88,25.76]],"ltp":1.84,"tv":874.85,"id":19144241}]}]}
{"op":"mcm","clk":"11819634890","pt":1723393276879,"mc":[{"id":"1.231679052","rc":[{"batb":[[1,1.44,1.6],[2,1.33,303.03]],"batl":[[0,1.84,29.22]],"ltp":1.84,"tv":874.85,"id":19144241}]}]}
{"op":"mcm","clk":"11819635512","pt":1723393281350,"mc":[{"id":"1.231679052","rc":[{"batb":[[0,2.16,13.09],[1,1.74,17.67],[2,1.53,188.68]],"batl":[[1,10,0.68]],"ltp":2.18,"tv":104.03,"id":19144236},{"trd":[[1.66,0.52]],"batb":[[0,1.68,3.39],[1,1.67,16.93],[2,1.56,11.52]],"batl":[[0,1.84,28.96]],"ltp":1.66,"tv":875.37,"id":19144241}],"tv":979.4}]}
{"op":"mcm","clk":"11819636096","pt":1723393285390,"mc":[{"id":"1.231679052","rc":[{"batb":[[2,1.59,2.19]],"ltp":1.66,"tv":875.37,"id":19144241}]}]}
{"op":"mcm","clk":"11819636947","pt":1723393291756,"mc":[{"id":"1.231679052","rc":[{"trd":[[1.67,2.75],[1.68,194.72]],"batb":[[0,1.67,15.56],[1,1.59,2.19],[2,1.56,11.52]],"ltp":1.67,"tv":884.89,"id":19144241}],"tv":988.92}]}
{"op":"mcm","clk":"11819637046","pt":1723393292585,"mc":[{"id":"1.231679052","rc":[{"batb":[[1,1.62,2.43],[2,1.59,2.19]],"ltp":1.67,"tv":884.89,"id":19144241}]}]}
{"op":"mcm","clk":"11819637329","pt":1723393294588,"mc":[{"id":"1.231679052","rc":[{"batl":[[0,2.78,9.02],[1,2.8,8.57],[2,10,0.68]],"ltp":2.18,"tv":104.03,"id":19144236}]}]}
{"op":"mcm","clk":"11819637915","pt":1723393299295,"mc":[{"id":"1.231679052","rc":[{"batb":[[0,1.68,1.26],[1,1.67,15.56],[2,1.62,2.43]],"ltp":1.67,"tv":884.89,"id":19144241}]}]}
{"op":"mcm","clk":"11819638309","pt":1723393302360,"mc":[{"id":"1.231679052","rc":[{"batl":[[2,10,1.03]],"ltp":2.18,"tv":104.03,"id":19144236}]}]}
{"op":"mcm","clk":"11819638323","pt":1723393302465,"mc":[{"id":"1.231679052","rc":[{"batb":[[1,1.74,18.09]],"ltp":2.18,"tv":104.03,"id":19144236},{"trd":[[1.67,8.5],[1.68,197.24]],"batb":[[0,1.67,12.68],[1,1.62,2.43],[2,1.59,2.19]],"ltp":1.67,"tv":893.16,"id":19144241}],"tv":997.2}]}
{"op":"mcm","clk":"11819639502","pt":1723393312188,"mc":[{"id":"1.231679052","rc":[{"batb":[[0,1.68,4.13],[1,1.67,12.68],[2,1.62,2.43]],"ltp":1.67,"tv":893.16,"id":19144241}]}]}
{"op":"mcm","clk":"11819640436","pt":1723393319411,"mc":[{"id":"1.231679052","rc":[{"batl":[[0,1.78,7.21],[1,1.84,28.96],[2,1.87,13.82]],"ltp":1.67,"tv":893.16,"id":19144241}]}]}
{"op":"mcm","clk":"11819641057","pt":1723393324310,"mc":[{"id":"1.231679052","rc":[{"batl":[[2,10,0.68]],"ltp":2.18,"tv":104.03,"id":19144236}]}]}
{"op":"mcm","clk":"11819641157","pt":1723393325006,"mc":[{"id":"1.231679052","rc":[{"batb":[[1,1.74,17.74]],"ltp":2.18,"tv":104.03,"id":19144236}]}]}
{"op":"mcm","clk":"11819643397","pt":1723393341738,"mc":[{"id":"1.231679052","rc":[{"batb":[[0,1.67,12.68],[1,1.62,2.43],[2,1.59,2.19]],"ltp":1.67,"tv":893.16,"id":19144241}]}]}
{"op":"mcm","clk":"11819643562","pt":1723393343023,"mc":[{"id":"1.231679052","rc":[{"batl":[[2,10,1.03]],"ltp":2.18,"tv":104.03,"id":19144236}]}]}
{"op":"mcm","clk":"11819643609","pt":1723393343434,"mc":[{"id":"1.231679052","rc":[{"batb":[[1,1.74,18.16]],"ltp":2.18,"tv":104.03,"id":19144236}]}]}
{"op":"mcm","clk":"11819644103","pt":1723393346636,"mc":[{"id":"1.231679052","rc":[{"batb":[[1,1.66,4.29],[2,1.62,2.43]],"ltp":1.67,"tv":893.16,"id":19144241}]}]}
{"op":"mcm","clk":"11819644303","pt":1723393348330,"mc":[{"id":"1.231679052","rc":[{"trd":[[2.28,0.09]],"ltp":2.28,"tv":104.05,"id":19144236},{"trd":[[1.78,2.06]],"batl":[[0,1.77,3.65],[1,1.78,7.19],[2,1.84,28.96]],"ltp":1.78,"tv":893.18,"id":19144241}],"tv":997.23}]}
{"op":"mcm","clk":"11819644811","pt":1723393352723,"mc":[{"id":"1.231679052","rc":[{"batb":[[0,1.74,18.16],[1,1.53,188.68],[2,1.43,232.56]],"ltp":2.28,"tv":104.05,"id":19144236},{"batb":[[0,1.62,2.43],[1,1.59,2.19],[2,1.38,1.72]],"ltp":1.78,"tv":893.18,"id":19144241}]}]}
{"op":"mcm","clk":"11819645157","pt":1723393355656,"mc":[{"id":"1.231679052","rc":[{"batl":[[0,2.78,9.57]],"ltp":2.28,"tv":104.05,"id":19144236}]}]}
{"op":"mcm","clk":"11819645583","pt":1723393359035,"mc":[{"id":"1.231679052","rc":[{"batb":[[0,2.18,12.93],[1,1.74,18.16],[2,1.53,188.68]],"ltp":2.28,"tv":104.05,"id":19144236},{"batb":[[0,1.65,17.08],[1,1.62,2.43],[2,1.59,2.19]],"ltp":1.78,"tv":893.18,"id":19144241}]}]}
{"op":"mcm","clk":"11819647865","pt":1723393377369,"mc":[{"id":"1.231679052","rc":[{"batb":[[1,1.74,17.74]],"batl":[[2,10,0.68]],"ltp":2.28,"tv":104.05,"id":19144236}]}]}
{"op":"mcm","clk":"11819648726","pt":1723393384171,"mc":[{"id":"1.231679052","rc":[{"trd":[[1.77,15.9]],"batl":[[0,1.77,3.59]],"ltp":1.77,"tv":893.3,"id":19144241}],"tv":997.35}]}
{"op":"mcm","clk":"11819648796","pt":1723393384642,"mc":[{"id":"1.231679052","rc":[{"batl":[[0,2.52,9.57],[1,2.78,9.02],[2,2.8,8.57]],"ltp":2.28,"tv":104.05,"id":19144236}]}]}
{"op":"mcm","clk":"11819649405","pt":1723393389350,"mc":[{"id":"1.231679052","rc":[{"trd":[[2.46,0.55]],"batl":[[0,2.52,9.02]],"ltp":2.46,"tv":104.59,"id":19144236},{"trd":[[1.65,2.67],[1.68,198.04]],"batb":[[0,1.65,16.48]],"ltp":1.65,"tv":895.32,"id":19144241}],"tv":999.92}]}
{"op":"mcm","clk":"11819649469","pt":1723393389868,"mc":[{"id":"1.231679052","rc":[{"batl":[[0,1.76,4.51],[1,1.77,3.59],[2,1.78,7.19]],"ltp":1.65,"tv":895.32,"id":19144241}]}]}
{"op":"mcm","clk":"11819649717","pt":1723393391974,"mc":[{"id":"1.231679052","rc":[{"batb":[[1,1.74,18.14]],"ltp":2.46,"tv":104.59,"id":19144236}]}]}
{"op":"mcm","clk":"11819650306","pt":1723393396374,"mc":[{"id":"1.231679052","rc":[{"batl":[[1,2.8,8.57],[2,10,1.03]],"ltp":2.46,"tv":104.59,"id":19144236}]}]}
{"op":"mcm","clk":"11819651922","pt":1723393408996,"mc":[{"id":"1.231679052","rc":[{"batb":[[0,1.76,40.57],[1,1.65,16.48],[2,1.62,2.43]],"batl":[[0,1.77,3.59],[1,1.78,7.19],[2,1.84,28.96]],"ltp":1.65,"tv":895.32,"id":19144241}]}]}
{"op":"mcm","clk":"11819652165","pt":1723393410877,"mc":[{"id":"1.231679052","rc":[{"batb":[[0,1.74,18.14],[1,1.53,188.68],[2,1.43,232.56]],"ltp":2.46,"tv":104.59,"id":19144236},{"batb":[[1,1.62,2.43],[2,1.59,2.19]],"ltp":1.65,"tv":895.32,"id":19144241}]}]}
{"op":"mcm","clk":"11819652573","pt":1723393414079,"mc":[{"id":"1.231679052","rc":[{"trd":[[1.76,81.24]],"batb":[[0,1.76,16.05]],"ltp":1.76,"tv":944.36,"id":19144241}],"tv":1048.96}]}
{"op":"mcm","clk":"11819652872","pt":1723393416183,"mc":[{"id":"1.231679052","rc":[{"batb":[[0,1.62,2.43],[1,1.59,2.19],[2,1.37,1.87]],"ltp":1.76,"tv":944.36,"id":19144241}]}]}
{"op":"mcm","clk":"11819653187","pt":1723393418703,"mc":[{"id":"1.231679052","rc":[{"batl":[[0,1.78,7.19],[1,1.84,28.96],[2,1.87,13.82]],"ltp":1.76,"tv":944.36,"id":19144241}]}]}
{"op":"mcm","clk":"11819654283","pt":1723393427332,"mc":[{"id":"1.231679052","rc":[{"batb":[[0,2.16,13.09],[1,1.74,18.14],[2,1.53,188.68]],"ltp":2.46,"tv":104.59,"id":19144236},{"batb":[[0,1.77,45.08],[1,1.67,16.93],[2,1.62,2.43]],"ltp":1.76,"tv":944.36,"id":19144241}]}]}
{"op":"mcm","clk":"11819654470","pt":1723393428820,"mc":[{"id":"1.231679052","rc":[{"batb":[[0,1.74,18.14],[1,1.53,188.68],[2,1.43,232.56]],"ltp":2.46,"tv":104.59,"id":19144236},{"batb":[[1,1.62,2.43],[2,1.59,2.19]],"ltp":1.76,"tv":944.36,"id":19144241}]}]}
{"op":"mcm","clk":"11819654691","pt":1723393430515,"mc":[{"id":"1.231679052","rc":[{"trd":[[2.28,5.7]],"batl":[[0,2.28,30.45],[1,2.52,9.02],[2,2.8,8.57]],"ltp":2.28,"tv":110.2,"id":19144236},{"trd":[[1.78,9.25]],"batl":[[0,1.84,28.96],[1,1.87,13.82],[2,1.88,25.76]],"ltp":1.78,"tv":951.55,"id":19144241}],"tv":1061.76}]}
{"op":"mcm","clk":"11819655147","pt":1723393434236,"mc":[{"id":"1.231679052","rc":[{"batb":[[1,1.59,2.19],[2,1.37,1.87]],"ltp":1.78,"tv":951.55,"id":19144241}]}]}
{"op":"mcm","clk":"11819655254","pt":1723393435125,"mc":[{"id":"1.231679052","rc":[{"batb":[[0,1.59,2.19],[1,1.37,1.87],[2,1.33,303.03]],"ltp":1.78,"tv":951.55,"id":19144241}]}]}
{"op":"mcm","clk":"11819655326","pt":1723393435752,"mc":[{"id":"1.231679052","rc":[{"batb":[[0,1.74,17.72]],"ltp":2.28,"tv":110.2,"id":19144236},{"batb":[[1,1.33,303.98],[2,1.26,4.7]],"ltp":1.78,"tv":951.55,"id":19144241}]}]}
{"op":"mcm","clk":"11819655961","pt":1723393440699,"mc":[{"id":"1.231679052","rc":[{"trd":[[2.28,5.9]],"batl":[[0,2.28,30.25]],"ltp":2.28,"tv":110.4,"id":19144236},{"trd":[[1.78,9.51]],"ltp":1.78,"tv":951.81,"id":19144241}],"tv":1062.21}]}
{"op":"mcm","clk":"11819656175","pt":1723393442343,"mc":[{"id":"1.231679052","rc":[{"batl":[[0,1.83,2.22],[1,1.84,28.96],[2,1.87,13.82]],"ltp":1.78,"tv":951.81,"id":19144241}]}]}
{"op":"mcm","clk":"11819656917","pt":1723393448336,"mc":[{"id":"1.231679052","rc":[{"batl":[[0,1.83,5.81]],"ltp":1.78,"tv":951.81,"id":19144241}]}]}
{"op":"mcm","clk":"11819657143","pt":1723393450060,"mc":[{"id":"1.231679052","rc":[{"trd":[[2.28,6.18]],"batl":[[0,2.28,29.97]],"ltp":2.28,"tv":110.68,"id":19144236},{"trd":[[1.78,9.87],[1.83,18.22],[1.84,60.31]],"batl":[[0,1.84,25.75],[1,1.87,13.82],[2,1.88,25.76]],"ltp":1.78,"tv":970.21,"id":19144241}],"tv":1080.89}]}
{"op":"mcm","clk":"11819657581","pt":1723393453649,"mc":[{"id":"1.231679052","rc":[{"batb":[[0,1.74,18.19]],"ltp":2.28,"tv":110.68,"id":19144236},{"batb":[[1,1.37,1.76],[2,1.33,303.03]],"ltp":1.78,"tv":970.21,"id":19144241}]}]}
{"op":"mcm","clk":"11819659316","pt":1723393466925,"mc":[{"id":"1.231679052","rc":[{"batb":[[0,1.74,18.24]],"ltp":2.28,"tv":110.68,"id":19144236}]}]}
{"op":"mcm","clk":"11819659807","pt":1723393470475,"mc":[{"id":"1.231679052","rc":[{"batl":[[0,1.83,1.08],[1,1.84,25.75],[2,1.87,13.82]],"ltp":1.78,"tv":970.21,"id":19144241}]}]}
{"op":"mcm","clk":"11819660503","pt":1723393475945,"mc":[{"id":"1.231679052","rc":[{"batl":[[0,1.83,11.08]],"ltp":1.78,"tv":970.21,"id":19144241}]}]}
{"op":"mcm","clk":"11819663090","pt":1723393495983,"mc":[{"id":"1.231679052","rc":[{"trd":[[2.28,6.33]],"batl":[[0,2.28,29.82]],"ltp":2.28,"tv":110.83,"id":19144236},{"trd":[[1.78,10.07]],"ltp":1.78,"tv":970.4,"id":19144241}],"tv":1081.24}]}
{"op":"mcm","clk":"11819663255","pt":1723393497402,"mc":[{"id":"1.231679052","rc":[{"trd":[[2.28,6.34]],"batl":[[0,2.28,29.81]],"ltp":2.28,"tv":110.84,"id":19144236},{"trd":[[1.78,10.08]],"ltp":1.78,"tv":970.41,"id":19144241}],"tv":1081.26}]}
{"op":"mcm","clk":"11819663517","pt":1723393499699,"mc":[{"id":"1.231679052","rc":[{"batb":[[0,1.59,2.5]],"ltp":1.78,"tv":970.41,"id":19144241}]}]}
{"op":"mcm","clk":"11819664128","pt":1723393503816,"mc":[{"id":"1.231679052","rc":[{"batb":[[0,1.74,17.84]],"ltp":2.28,"tv":110.84,"id":19144236},{"batb":[[1,1.33,303.84],[2,1.26,4.7]],"ltp":1.78,"tv":970.41,"id":19144241}]}]}
{"op":"mcm","clk":"11819664811","pt":1723393508722,"mc":[{"id":"1.231679052","rc":[{"batb":[[0,1.59,2.19]],"ltp":1.78,"tv":970.41,"id":19144241}]}]}
{"op":"mcm","clk":"11819666606","pt":1723393521740,"mc":[{"id":"1.231679052","rc":[{"batb":[[0,1.74,17.79]],"ltp":2.28,"tv":110.84,"id":19144236}]}]}
{"op":"mcm","clk":"11819666825","pt":1723393523339,"mc":[{"id":"1.231679052","rc":[{"batb":[[0,1.74,18.26]],"ltp":2.28,"tv":110.84,"id":19144236},{"batb":[[1,1.43,1.62],[2,1.33,303.03]],"ltp":1.78,"tv":970.41,"id":19144241}]}]}
{"op":"mcm","clk":"11819667526","pt":1723393528808,"mc":[{"id":"1.231679052","rc":[{"trd":[[2.28,6.44]],"batl":[[0,2.28,29.71]],"ltp":2.28,"tv":110.94,"id":19144236},{"trd":[[1.78,10.21]],"ltp":1.78,"tv":970.54,"id":19144241}],"tv":1081.49}]}
{"op":"mcm","clk":"11819668081","pt":1723393533333,"mc":[{"id":"1.231679052","rc":[{"batl":[[0,1.83,11.1]],"ltp":1.78,"tv":970.54,"id":19144241}]}]}
{"op":"mcm","clk":"11819669978","pt":1723393548842,"mc":[{"id":"1.231679052","rc":[{"trd":[[2.28,6.47]],"batl":[[0,2.28,29.68]],"ltp":2.28,"tv":110.97,"id":19144236},{"trd":[[1.78,10.24]],"ltp":1.78,"tv":970.58,"id":19144241}],"tv":1081.55}]}
{"op":"mcm","clk":"11819670595","pt":1723393553859,"mc":[{"id":"1.231679052","rc":[{"batb":[[0,1.8,865.38],[1,1.59,2.19],[2,1.43,1.62]],"ltp":1.78,"tv":970.58,"id":19144241}]}]}
{"op":"mcm","clk":"11819670713","pt":1723393554961,"mc":[{"id":"1.231679052","rc":[{"trd":[[2.28,36.15]],"batl":[[0,2.52,9.02],[1,2.8,8.57],[2,10,1.03]],"ltp":2.28,"tv":140.65,"id":19144236},{"trd":[[1.78,48.26],[1.8,1746.69]],"batb":[[0,1.59,2.19],[1,1.43,1.62],[2,1.33,303.03]],"batl":[[0,1.78,1138.27],[1,1.83,11.1],[2,1.84,25.75]],"ltp":1.78,"tv":2739.36,"id":19144241}],"tv":2880.01}]}
{"op":"mcm","clk":"11819671415","pt":1723393560660,"mc":[{"id":"1.231679052","rc":[{"batb":[[0,2.12,13.27],[1,1.74,18.26],[2,1.53,188.68]],"ltp":2.28,"tv":140.65,"id":19144236},{"batb":[[0,1.68,16.75],[1,1.59,2.19],[2,1.43,1.62]],"batl":[[0,1.83,11.1],[1,1.84,25.75],[2,1.87,13.82]],"ltp":1.78,"tv":2739.36,"id":19144241}]}]}
{"op":"mcm","clk":"11819671724","pt":1723393563076,"mc":[{"id":"1.231679052","rc":[{"batb":[[0,1.74,18.26],[1,1.53,188.68],[2,1.43,232.56]],"ltp":2.28,"tv":140.65,"id":19144236},{"batb":[[0,1.59,2.19],[1,1.43,1.62],[2,1.33,303.03]],"ltp":1.78,"tv":2739.36,"id":19144241}]}]}
{"op":"mcm","clk":"11819672093","pt":1723393566368,"mc":[{"id":"1.231679052","rc":[{"batb":[[0,1.78,1730.77],[1,1.59,2.19],[2,1.43,1.62]],"ltp":1.78,"tv":2739.36,"id":19144241}]}]}
{"op":"mcm","clk":"11819673846","pt":1723393581378,"mc":[{"id":"1.231679052","rc":[{"batb":[[1,1.66,4.01],[2,1.59,2.19]],"ltp":1.78,"tv":2739.36,"id":19144241}]}]}
{"op":"mcm","clk":"11819674319","pt":1723393585296,"mc":[{"id":"1.231679052","rc":[{"batb":[[0,1.74,17.79]],"batl":[[2,10,0.68]],"ltp":2.28,"tv":140.65,"id":19144236},{"trd":[[1.78,864.92]],"batb":[[0,1.78,1322.44]],"ltp":1.78,"tv":3556.02,"id":19144241}],"tv":3696.67}]}
{"op":"mcm","clk":"11819675451","pt":1723393594675,"mc":[{"id":"1.231679052","rc":[{"batl":[[0,1.8,235.29],[1,1.83,11.1],[2,1.84,25.75]],"ltp":1.78,"tv":3556.02,"id":19144241}]}]}
{"op":"mcm","clk":"11819676377","pt":1723393602573,"mc":[{"id":"1.231679052","rc":[{"batb":[[1,1.68,13.53],[2,1.66,4.01]],"ltp":1.78,"tv":3556.02,"id":19144241}]}]}
{"op":"mcm","clk":"11819676676","pt":1723393605302,"mc":[{"id":"1.231679052","rc":[{"trd":[[1.78,865.58]],"batb":[[0,1.78,1322.11]],"ltp":1.78,"tv":3556.68,"id":19144241}],"tv":3697.33}]}
{"op":"mcm","clk":"11819677299","pt":1723393610220,"mc":[{"id":"1.231679052","rc":[{"batl":[[2,10,1.03]],"ltp":2.28,"tv":140.65,"id":19144236}]}]}
{"op":"mcm","clk":"11819677323","pt":1723393610426,"mc":[{"id":"1.231679052","rc":[{"batb":[[0,1.74,18.26]],"ltp":2.28,"tv":140.65,"id":19144236}]}]}
{"op":"mcm","clk":"11819678171","pt":1723393617232,"mc":[{"id":"1.231679052","rc":[{"trd":[[1.8,1746.83]],"batl":[[0,1.8,235.22]],"ltp":1.8,"tv":3556.82,"id":19144241}],"tv":3697.47}]}
{"op":"mcm","clk":"11819681268","pt":1723393641348,"mc":[{"id":"1.231679052","rc":[{"batl":[[2,10,0.68]],"ltp":2.28,"tv":140.65,"id":19144236}]}]}
{"op":"mcm","clk":"11819681337","pt":1723393641821,"mc":[{"id":"1.231679052","rc":[{"batb":[[0,1.74,17.79]],"ltp":2.28,"tv":140.65,"id":19144236}]}]}
{"op":"mcm","clk":"11819682841","pt":1723393654373,"mc":[{"id":"1.231679052","rc":[{"batb":[[0,1.78,1322.42]],"ltp":1.8,"tv":3556.82,"id":19144241}]}]}
{"op":"mcm","clk":"11819683973","pt":1723393663387,"mc":[{"id":"1.231679052","rc":[{"batl":[[2,10,1.03]],"ltp":2.28,"tv":140.65,"id":19144236}]}]}
{"op":"mcm","clk":"11819683998","pt":1723393663596,"mc":[{"id":"1.231679052","rc":[{"batb":[[0,1.74,18.26]],"ltp":2.28,"tv":140.65,"id":19144236}]}]}
{"op":"mcm","clk":"11819684877","pt":1723393670681,"mc":[{"id":"1.231679052","rc":[{"trd":[[1.78,965.58]],"batb":[[0,1.78,1272.42]],"ltp":1.78,"tv":3656.82,"id":19144241}],"tv":3797.47}]}
{"op":"mcm","clk":"11819685932","pt":1723393678597,"mc":[{"id":"1.231679052","rc":[{"batl":[[2,1.84,261.04]],"ltp":1.78,"tv":3656.82,"id":19144241}]}]}
{"op":"mcm","clk":"11819686140","pt":1723393680216,"mc":[{"id":"1.231679052","rc":[{"trd":[[1.78,968.04]],"batb":[[0,1.78,1271.19]],"ltp":1.78,"tv":3659.28,"id":19144241}],"tv":3799.93}]}
{"op":"mcm","clk":"11819687236","pt":1723393688305,"mc":[{"id":"1.231679052","rc":[{"batb":[[0,1.74,17.79]],"batl":[[2,10,0.68]],"ltp":2.28,"tv":140.65,"id":19144236}]}]}
{"op":"mcm","clk":"11819689651","pt":1723393706569,"mc":[{"id":"1.231679052","rc":[{"batb":[[0,1.74,18.26]],"batl":[[2,10,1.03]],"ltp":2.28,"tv":140.65,"id":19144236}]}]}
{"op":"mcm","clk":"11819691482","pt":1723393720044,"mc":[{"id":"1.231679052","rc":[{"trd":[[1.78,968.62]],"batb":[[0,1.78,1270.9]],"ltp":1.78,"tv":3659.85,"id":19144241}],"tv":3800.51}]}
{"op":"mcm","clk":"11819693362","pt":1723393734499,"mc":[{"id":"1.231679052","rc":[{"batb":[[2,1.59,2.19]],"ltp":1.78,"tv":3659.85,"id":19144241}]}]}
{"op":"mcm","clk":"11819694079","pt":1723393739586,"mc":[{"id":"1.231679052","rc":[{"batb":[[1,1.68,18.27]],"ltp":1.78,"tv":3659.85,"id":19144241}]}]}
{"op":"mcm","clk":"11819695123","pt":1723393747210,"mc":[{"id":"1.231679052","rc":[{"batb":[[0,1.74,17.79]],"batl":[[2,10,0.68]],"ltp":2.28,"tv":140.65,"id":19144236}]}]}
{"op":"mcm","clk":"11819695418","pt":1723393749392,"mc":[{"id":"1.231679052","rc":[{"trd":[[2.24,10.67]],"ltp":2.24,"tv":142.93,"id":19144236},{"trd":[[1.8,1749.67]],"batl":[[0,1.8,232.38]],"ltp":1.8,"tv":3662.69,"id":19144241}],"tv":3805.63}]}
{"op":"mcm","clk":"11819697559","pt":1723393764303,"mc":[{"id":"1.231679052","rc":[{"batl":[[2,10,1.03]],"ltp":2.24,"tv":142.93,"id":19144236}]}]}
{"op":"mcm","clk":"11819697591","pt":1723393764616,"mc":[{"id":"1.231679052","rc":[{"batb":[[0,1.74,18.26]],"ltp":2.24,"tv":142.93,"id":19144236}]}]}
{"op":"mcm","clk":"11819701670","pt":1723393793850,"mc":[{"id":"1.231679052","rc":[{"batl":[[0,2.8,8.57],[1,10,1.03],[2,10,0]],"ltp":2.24,"tv":142.93,"id":19144236}]}]}
{"op":"mcm","clk":"11819703936","pt":1723393808331,"mc":[{"id":"1.231679052","rc":[{"batb":[[0,1.74,17.79]],"ltp":2.24,"tv":142.93,"id":19144236}]}]}
{"op":"mcm","clk":"11819703968","pt":1723393808541,"mc":[{"id":"1.231679052","rc":[{"batl":[[1,10,0.68]],"ltp":2.24,"tv":142.93,"id":19144236}]}]}
{"op":"mcm","clk":"11819707184","pt":1723393829003,"mc":[{"id":"1.231679052","rc":[{"batb":[[0,1.74,18.26]],"batl":[[1,10,1.03]],"ltp":2.24,"tv":142.93,"id":19144236}]}]}
{"op":"mcm","clk":"11819713451","pt":1723393870429,"mc":[{"id":"1.231679052","rc":[{"batb":[[0,1.78,1270.59]],"ltp":1.8,"tv":3662.69,"id":19144241}]}]}
{"op":"mcm","clk":"11819714194","pt":1723393875506,"mc":[{"id":"1.231679052","rc":[{"batb":[[0,1.78,1270.89]],"ltp":1.8,"tv":3662.69,"id":19144241}]}]}
{"op":"mcm","clk":"11819715159","pt":1723393882212,"mc":[{"id":"1.231679052","rc":[{"batl":[[1,10,0.68]],"ltp":2.24,"tv":142.93,"id":19144236}]}]}
{"op":"mcm","clk":"11819715228","pt":1723393882635,"mc":[{"id":"1.231679052","rc":[{"batb":[[0,1.74,17.79]],"ltp":2.24,"tv":142.93,"id":19144236}]}]}
{"op":"mcm","clk":"11819716638","pt":1723393891825,"mc":[{"id":"1.231679052","rc":[{"batb":[[0,1.78,1270.59]],"ltp":1.8,"tv":3662.69,"id":19144241}]}]}
{"op":"mcm","clk":"11819717524","pt":1723393896933,"mc":[{"id":"1.231679052","rc":[{"trd":[[1.8,1750.27]],"batl":[[0,1.8,232.08]],"ltp":1.8,"tv":3663.3,"id":19144241}],"tv":3806.23}]}
{"op":"mcm","clk":"11819718214","pt":1723393901252,"mc":[{"id":"1.231679052","rc":[{"batb":[[0,1.74,18.26]],"batl":[[1,10,1.03]],"ltp":2.24,"tv":142.93,"id":19144236}]}]}
{"op":"mcm","clk":"11819721881","pt":1723393925520,"mc":[{"id":"1.231679052","rc":[{"trd":[[2.24,10.74]],"ltp":2.24,"tv":143.01,"id":19144236},{"trd":[[1.8,1750.36]],"batl":[[0,1.8,231.99]],"ltp":1.8,"tv":3663.39,"id":19144241}],"tv":3806.4}]}
{"op":"mcm","clk":"11819724251","pt":1723393940846,"mc":[{"id":"1.231679052","rc":[{"batb":[[0,1.74,17.79]],"batl":[[1,10,0.68]],"ltp":2.24,"tv":143.01,"id":19144236}]}]}
{"op":"mcm","clk":"11819728099","pt":1723393964190,"mc":[{"id":"1.231679052","rc":[{"batl":[[1,10,1.03]],"ltp":2.24,"tv":143.01,"id":19144236}]}]}
{"op":"mcm","clk":"11819728191","pt":1723393964614,"mc":[{"id":"1.231679052","rc":[{"batb":[[0,1.74,18.26]],"ltp":2.24,"tv":143.01,"id":19144236}]}]}
{"op":"mcm","clk":"11819732365","pt":1723393990247,"mc":[{"id":"1.231679052","rc":[{"batl":[[1,10,0.68]],"ltp":2.24,"tv":143.01,"id":19144236}]}]}
{"op":"mcm","clk":"11819732493","pt":1723393991039,"mc":[{"id":"1.231679052","rc":[{"batb":[[0,1.74,17.79]],"batl":[[0,10,0.68],[1,10,0]],"ltp":2.24,"tv":143.01,"id":19144236}]}]}
{"op":"mcm","clk":"11819732946","pt":1723393993702,"mc":[{"id":"1.231679052","rc":[{"trd":[[1.8,1750.62]],"batl":[[0,1.8,231.86]],"ltp":1.8,"tv":3663.64,"id":19144241}],"tv":3806.66}]}
{"op":"mcm","clk":"11819734397","pt":1723394002326,"mc":[{"id":"1.231679052","rc":[{"batl":[[0,1000,1.03]],"ltp":2.24,"tv":143.01,"id":19144236}]}]}
{"op":"mcm","clk":"11819734462","pt":1723394002737,"mc":[{"id":"1.231679052","rc":[{"batl":[[0,10,0.68]],"ltp":2.24,"tv":143.01,"id":19144236}]}]}
{"op":"mcm","clk":"11819734687","pt":1723394003948,"mc":[{"id":"1.231679052","rc":[{"batl":[[0,1.8,231.27]],"ltp":1.8,"tv":3663.64,"id":19144241}]}]}
{"op":"mcm","clk":"11819735345","pt":1723394007862,"mc":[{"id":"1.231679052","rc":[{"batb":[[0,1.74,18.26]],"batl":[[0,10,1.03]],"ltp":2.24,"tv":143.01,"id":19144236}]}]}
{"op":"mcm","clk":"11819738670","pt":1723394028700,"mc":[{"id":"1.231679052","rc":[{"batl":[[0,1.8,230.98]],"ltp":1.8,"tv":3663.64,"id":19144241}]}]}
{"op":"mcm","clk":"11819739249","pt":1723394032338,"mc":[{"id":"1.231679052","rc":[{"batl":[[0,10,0.68]],"ltp":2.24,"tv":143.01,"id":19144236}]}]}
{"op":"mcm","clk":"11819739351","pt":1723394032920,"mc":[{"id":"1.231679052","rc":[{"batb":[[0,1.74,17.79]],"ltp":2.24,"tv":143.01,"id":19144236}]}]}
{"op":"mcm","clk":"11819740246","pt":1723394038232,"mc":[{"id":"1.231679052","rc":[{"trd":[[1.78,1058.62]],"batb":[[0,1.78,1225.59]],"ltp":1.78,"tv":3753.64,"id":19144241}],"tv":3896.66}]}
{"op":"mcm","clk":"11819742011","pt":1723394048140,"mc":[{"id":"1.231679052","rc":[{"batb":[[0,1.74,18.26]],"batl":[[0,10,1.03]],"ltp":2.24,"tv":143.01,"id":19144236}]}]}
{"op":"mcm","clk":"11819746660","pt":1723394077315,"mc":[{"id":"1.231679052","rc":[{"batl":[[0,10,0.68]],"ltp":2.24,"tv":143.01,"id":19144236}]}]}
{"op":"mcm","clk":"11819746716","pt":1723394077679,"mc":[{"id":"1.231679052","rc":[{"batb":[[0,1.74,17.79]],"ltp":2.24,"tv":143.01,"id":19144236}]}]}
{"op":"mcm","clk":"11819748956","pt":1723394091302,"mc":[{"id":"1.231679052","rc":[{"batl":[[0,10,1.03]],"ltp":2.24,"tv":143.01,"id":19144236}]}]}
{"op":"mcm","clk":"11819748993","pt":1723394091498,"mc":[{"id":"1.231679052","rc":[{"batb":[[0,1.74,18.26]],"ltp":2.24,"tv":143.01,"id":19144236}]}]}
{"op":"mcm","clk":"11819758103","pt":1723394150148,"mc":[{"id":"1.231679052","rc":[{"batl":[[0,10,0.68]],"ltp":2.24,"tv":143.01,"id":19144236}]}]}
{"op":"mcm","clk":"11819758156","pt":1723394150461,"mc":[{"id":"1.231679052","rc":[{"batb":[[0,1.74,17.79]],"ltp":2.24,"tv":143.01,"id":19144236}]}]}
{"op":"mcm","clk":"11819759465","pt":1723394158752,"mc":[{"id":"1.231679052","rc":[{"batb":[[1,1.68,13.53]],"ltp":1.78,"tv":3753.64,"id":19144241}]}]}
{"op":"mcm","clk":"11819760751","pt":1723394167156,"mc":[{"id":"1.231679052","rc":[{"batb":[[0,1.74,18.26]],"batl":[[0,10,1.03]],"ltp":2.24,"tv":143.01,"id":19144236}]}]}
{"op":"mcm","clk":"11819763258","pt":1723394182964,"mc":[{"id":"1.231679052","rc":[{"trd":[[1.78,1058.78]],"batb":[[0,1.78,1225.51]],"ltp":1.78,"tv":3753.81,"id":19144241}],"tv":3896.82}]}
{"op":"mcm","clk":"11819768729","pt":1723394216093,"mc":[{"id":"1.231679052","rc":[{"batb":[[0,1.74,17.79]],"batl":[[0,10,0.68]],"ltp":2.24,"tv":143.01,"id":19144236}]}]}
{"op":"mcm","clk":"11819771352","pt":1723394232629,"mc":[{"id":"1.231679052","rc":[{"batb":[[1,1.26,4.7],[2,1.1,10024.22]],"ltp":2.24,"tv":143.01,"id":19144236}]}]}
{"op":"mcm","clk":"11819771532","pt":1723394233729,"mc":[{"id":"1.231679052","rc":[{"batb":[[0,1.74,18.26]],"batl":[[0,10,1.03]],"ltp":2.24,"tv":143.01,"id":19144236}]}]}
{"op":"mcm","clk":"11819774199","pt":1723394250126,"mc":[{"id":"1.231679052","rc":[{"batl":[[0,1.83,11.1],[1,1.84,25.75],[2,1.87,13.82]],"ltp":1.78,"tv":3753.81,"id":19144241}]}]}
{"op":"mcm","clk":"11819775285","pt":1723394257144,"mc":[{"id":"1.231679052","rc":[{"batb":[[0,1.74,17.79]],"batl":[[0,10,0.68]],"ltp":2.24,"tv":143.01,"id":19144236}]}]}
{"op":"mcm","clk":"11819777407","pt":1723394271371,"mc":[{"id":"1.231679052","rc":[{"batl":[[0,1000,1.03]],"ltp":2.24,"tv":143.01,"id":19144236}]}]}
{"op":"mcm","clk":"11819777473","pt":1723394271752,"mc":[{"id":"1.231679052","rc":[{"batl":[[0,10,0.68]],"ltp":2.24,"tv":143.01,"id":19144236}]}]}
{"op":"mcm","clk":"11819778217","pt":1723394276853,"mc":[{"id":"1.231679052","rc":[{"batb":[[0,1.74,18.26]],"batl":[[0,10,1.03]],"ltp":2.24,"tv":143.01,"id":19144236}]}]}
{"op":"mcm","clk":"11819784628","pt":1723394318233,"mc":[{"id":"1.231679052","rc":[{"batl":[[0,10,0.68]],"ltp":2.24,"tv":143.01,"id":19144236}]}]}
{"op":"mcm","clk":"11819784655","pt":1723394318432,"mc":[{"id":"1.231679052","rc":[{"batb":[[0,1.74,17.79]],"ltp":2.24,"tv":143.01,"id":19144236}]}]}
{"op":"mcm","clk":"11819786466","pt":1723394329930,"mc":[{"id":"1.231679052","rc":[{"batl":[[0,11,0.74]],"ltp":2.24,"tv":143.01,"id":19144236}]}]}
{"op":"mcm","clk":"11819787715","pt":1723394338226,"mc":[{"id":"1.231679052","rc":[{"batb":[[0,1.74,18.26]],"batl":[[0,10,1.03],[1,11,0.07]],"ltp":2.24,"tv":143.01,"id":19144236}]}]}
{"op":"mcm","clk":"11819788787","pt":1723394345032,"mc":[{"id":"1.231679052","rc":[{"batl":[[1,25,0.13]],"ltp":2.24,"tv":143.01,"id":19144236}]}]}
{"op":"mcm","clk":"11819795786","pt":1723394392393,"mc":[{"id":"1.231679052","rc":[{"batb":[[0,1.74,17.79]],"batl":[[0,25,0.81],[1,25,0]],"ltp":2.24,"tv":143.01,"id":19144236}]}]}
{"op":"mcm","clk":"11819796387","pt":1723394396520,"mc":[{"id":"1.231679052","rc":[{"batb":[[0,2.28,1.43],[1,1.74,17.79],[2,1.26,4.7]],"ltp":2.24,"tv":143.01,"id":19144236}]}]}
{"op":"mcm","clk":"11819798406","pt":1723394409098,"mc":[{"id":"1.231679052","rc":[{"batb":[[1,1.74,18.26]],"batl":[[0,10,1.03],[1,25,0.13]],"ltp":2.24,"tv":143.01,"id":19144236}]}]}
{"op":"mcm","clk":"11819801650","pt":1723394428122,"mc":[{"id":"1.231679052","rc":[{"batb":[[0,1.74,18.26],[1,1.26,4.7],[2,1.23,1086.96]],"ltp":2.24,"tv":143.01,"id":19144236}]}]}
{"op":"mcm","clk":"11819802368","pt":1723394432953,"mc":[{"id":"1.231679052","rc":[{"batl":[[1,1.87,13.82],[2,1.88,25.76]],"ltp":1.78,"tv":3753.81,"id":19144241}]}]}
{"op":"mcm","clk":"11819802744","pt":1723394435368,"mc":[{"id":"1.231679052","rc":[{"batl":[[0,25,0.81],[1,25,0]],"ltp":2.24,"tv":143.01,"id":19144236}]}]}
{"op":"mcm","clk":"11819802806","pt":1723394435753,"mc":[{"id":"1.231679052","rc":[{"batb":[[0,1.74,17.79]],"ltp":2.24,"tv":143.01,"id":19144236}]}]}
{"op":"mcm","clk":"11819803836","pt":1723394442580,"mc":[{"id":"1.231679052","rc":[{"batl":[[0,2.22,1.43],[1,25,0.81]],"ltp":2.24,"tv":143.01,"id":19144236}]}]}
{"op":"mcm","clk":"11819805591","pt":1723394453311,"mc":[{"id":"1.231679052","rc":[{"batl":[[1,1000,1.16]],"ltp":2.24,"tv":143.01,"id":19144236}]}]}
{"op":"mcm","clk":"11819805656","pt":1723394453679,"mc":[{"id":"1.231679052","rc":[{"batl":[[1,25,0.81]],"ltp":2.24,"tv":143.01,"id":19144236}]}]}
{"op":"mcm","clk":"11819806450","pt":1723394458785,"mc":[{"id":"1.231679052","rc":[{"batb":[[1,1.26,5.19]],"batl":[[1,10,1.03],[2,25,0.13]],"ltp":2.24,"tv":143.01,"id":19144236}]}]}
{"op":"mcm","clk":"11819806639","pt":1723394460005,"mc":[{"id":"1.231679052","rc":[{"batl":[[0,10,1.03],[1,25,0.13],[2,25,0]],"ltp":2.24,"tv":143.01,"id":19144236}]}]}
{"op":"mcm","clk":"11819808976","pt":1723394474692,"mc":[{"id":"1.231679052","rc":[{"batb":[[0,2.28,1.43],[1,1.74,17.79],[2,1.26,5.19]],"ltp":2.24,"tv":143.01,"id":19144236}]}]}
{"op":"mcm","clk":"11819810730","pt":1723394485918,"mc":[{"id":"1.231679052","rc":[{"batb":[[0,1.74,17.79],[1,1.26,5.19],[2,1.23,1086.96]],"ltp":2.24,"tv":143.01,"id":19144236}]}]}
{"op":"mcm","clk":"11819813033","pt":1723394500051,"mc":[{"id":"1.231679052","rc":[{"batl":[[0,2.22,1.43],[1,10,1.03],[2,25,0.13]],"ltp":2.24,"tv":143.01,"id":19144236}]}]}
{"op":"mcm","clk":"11819813279","pt":1723394501751,"mc":[{"id":"1.231679052","rc":[{"trd":[[2.22,0.22]],"batl":[[0,2.22,1.2]],"ltp":2.22,"tv":143.23,"id":19144236},{"trd":[[1.81,0.27]],"ltp":1.81,"tv":3754.08,"id":19144241}],"tv":3897.32}]}
{"op":"mcm","clk":"11819814617","pt":1723394510371,"mc":[{"id":"1.231679052","rc":[{"batb":[[0,1.74,17.32]],"batl":[[1,25,0.81],[2,25,0]],"ltp":2.22,"tv":143.23,"id":19144236}]}]}
{"op":"mcm","clk":"11819814636","pt":1723394510478,"mc":[{"id":"1.231679052","rc":[{"trd":[[2.22,0.77]],"batl":[[0,3,1.01],[1,25,0.46]],"ltp":2.22,"tv":143.78,"id":19144236},{"trd":[[1.81,0.94]],"ltp":1.81,"tv":3754.75,"id":19144241}],"tv":3898.53}]}
{"op":"mcm","clk":"11819815868","pt":1723394518181,"mc":[{"id":"1.231679052","rc":[{"batl":[[0,25,0.81],[1,25,0]],"ltp":2.22,"tv":143.78,"id":19144236}]}]}
{"op":"mcm","clk":"11819817051","pt":1723394525282,"mc":[{"id":"1.231679052","rc":[{"trd":[[1.78,1060.7]],"batb":[[0,1.78,1224.55]],"ltp":1.78,"tv":3756.67,"id":19144241}],"tv":3900.45}]}
{"op":"mcm","clk":"11819817368","pt":1723394527376,"mc":[{"id":"1.231679052","rc":[{"batb":[[0,1.74,17.79]],"batl":[[0,10,1.03],[1,25,0.13]],"ltp":2.22,"tv":143.78,"id":19144236}]}]}
{"op":"mcm","clk":"11819818010","pt":1723394531479,"mc":[{"id":"1.231679052","rc":[{"trd":[[1.83,20.37]],"batl":[[0,1.83,10]],"ltp":1.83,"tv":3758.83,"id":19144241}],"tv":3902.61}]}
{"op":"mcm","clk":"11819818983","pt":1723394537359,"mc":[{"id":"1.231679052","rc":[{"batl":[[0,2.22,1.43],[1,10,1.03],[2,25,0.13]],"ltp":2.22,"tv":143.78,"id":19144236},{"batl":[[0,1.82,10.67],[1,1.83,10],[2,1.87,13.82]],"ltp":1.83,"tv":3758.83,"id":19144241}]}]}
{"op":"mcm","clk":"11819820853","pt":1723394549279,"mc":[{"id":"1.231679052","rc":[{"trd":[[1.82,26.32],[1.83,21.21]],"batl":[[0,1.83,9.58],[1,1.87,13.82],[2,1.88,25.76]],"ltp":1.83,"tv":3781.01,"id":19144241}],"tv":3924.79}]}
{"op":"mcm","clk":"11819821223","pt":1723394551498,"mc":[{"id":"1.231679052","rc":[{"batl":[[0,10,1.03],[1,25,0.13],[2,25,0]],"ltp":2.22,"tv":143.78,"id":19144236}]}]}
{"op":"mcm","clk":"11819822456","pt":1723394559108,"mc":[{"id":"1.231679052","rc":[{"batl":[[0,25,0.81],[1,25,0]],"ltp":2.22,"tv":143.78,"id":19144236}]}]}
{"op":"mcm","clk":"11819822569","pt":1723394559676,"mc":[{"id":"1.231679052","rc":[{"batb":[[1,1.26,4.7]],"ltp":2.22,"tv":143.78,"id":19144236}]}]}
{"op":"mcm","clk":"11819822925","pt":1723394561888,"mc":[{"id":"1.231679052","rc":[{"batl":[[0,1.83,9.61]],"ltp":1.83,"tv":3781.01,"id":19144241}]}]}
{"op":"mcm","clk":"11819825081","pt":1723394575326,"mc":[{"id":"1.231679052","rc":[{"batl":[[0,1000,1.16]],"ltp":2.22,"tv":143.78,"id":19144236}]}]}
{"op":"mcm","clk":"11819825151","pt":1723394575697,"mc":[{"id":"1.231679052","rc":[{"batl":[[0,25,0.81]],"ltp":2.22,"tv":143.78,"id":19144236}]}]}
{"op":"mcm","clk":"11819825886","pt":1723394580806,"mc":[{"id":"1.231679052","rc":[{"batb":[[0,1.74,18.26]],"batl":[[0,10,1.03],[1,25,0.13]],"ltp":2.22,"tv":143.78,"id":19144236}]}]}
{"op":"mcm","clk":"11819829936","pt":1723394606171,"mc":[{"id":"1.231679052","rc":[{"batl":[[0,1.83,9.58]],"ltp":1.83,"tv":3781.01,"id":19144241}]}]}
{"op":"mcm","clk":"11819833611","pt":1723394627348,"mc":[{"id":"1.231679052","rc":[{"batl":[[0,25,0.81],[1,25,0]],"ltp":2.22,"tv":143.78,"id":19144236}]}]}
{"op":"mcm","clk":"11819833682","pt":1723394627771,"mc":[{"id":"1.231679052","rc":[{"batb":[[0,1.74,17.79]],"ltp":2.22,"tv":143.78,"id":19144236}]}]}
{"op":"mcm","clk":"11819836717","pt":1723394645074,"mc":[{"id":"1.231679052","rc":[{"batb":[[0,1.74,18.26]],"batl":[[0,10,1.03],[1,25,0.13]],"ltp":2.22,"tv":143.78,"id":19144236}]}]}
{"op":"mcm","clk":"11819837499","pt":1723394649914,"mc":[{"id":"1.231679052","rc":[{"batb":[[0,1.79,2.22],[1,1.78,1224.55],[2,1.68,13.53]],"ltp":1.83,"tv":3781.01,"id":19144241}]}]}
{"op":"mcm","clk":"11819837878","pt":1723394652283,"mc":[{"id":"1.231679052","rc":[{"trd":[[1.78,1078.56],[1.79,19.12]],"batb":[[0,1.78,1215.62],[1,1.68,13.53],[2,1.59,2.19]],"ltp":1.78,"tv":3803.31,"id":19144241}],"tv":3947.09}]}
{"op":"mcm","clk":"11819840106","pt":1723394666363,"mc":[{"id":"1.231679052","rc":[{"batl":[[0,1.82,2.22],[1,1.83,9.58],[2,1.87,13.82]],"ltp":1.78,"tv":3803.31,"id":19144241}]}]}
{"op":"mcm","clk":"11819842793","pt":1723394684131,"mc":[{"id":"1.231679052","rc":[{"batb":[[0,1.74,17.79]],"batl":[[0,25,0.81],[1,25,0]],"ltp":2.22,"tv":143.78,"id":19144236}]}]}
{"op":"mcm","clk":"11819844109","pt":1723394693317,"mc":[{"id":"1.231679052","rc":[{"batb":[[0,1.68,13.53],[1,1.59,2.19],[2,1.3,1.14]],"ltp":1.78,"tv":3803.31,"id":19144241}]}]}
{"op":"mcm","clk":"11819845152","pt":1723394699836,"mc":[{"id":"1.231679052","rc":[{"batb":[[0,2.1,13.43],[1,1.74,17.79],[2,1.26,4.7]],"ltp":2.22,"tv":143.78,"id":19144236},{"batb":[[0,1.7,16.59],[1,1.68,13.53],[2,1.59,2.19]],"ltp":1.78,"tv":3803.31,"id":19144241}]}]}
{"op":"mcm","clk":"11819846488","pt":1723394707357,"mc":[{"id":"1.231679052","rc":[{"batb":[[1,1.74,18.21]],"batl":[[0,10,1.03],[1,25,0.13]],"ltp":2.22,"tv":143.78,"id":19144236}]}]}
{"op":"mcm","clk":"11819848195","pt":1723394718096,"mc":[{"id":"1.231679052","rc":[{"trd":[[1.7,6.77]],"batb":[[0,1.7,13.25]],"ltp":1.7,"tv":3809.98,"id":19144241}],"tv":3953.77}]}
{"op":"mcm","clk":"11819849470","pt":1723394726266,"mc":[{"id":"1.231679052","rc":[{"batb":[[0,1.7,16.59]],"ltp":1.7,"tv":3809.98,"id":19144241}]}]}
{"op":"mcm","clk":"11819852516","pt":1723394746214,"mc":[{"id":"1.231679052","rc":[{"batl":[[0,25,0.81],[1,25,0]],"ltp":2.22,"tv":143.78,"id":19144236}]}]}
{"op":"mcm","clk":"11819852617","pt":1723394746907,"mc":[{"id":"1.231679052","rc":[{"batb":[[1,1.74,17.74]],"ltp":2.22,"tv":143.78,"id":19144236}]}]}
{"op":"mcm","clk":"11819855515","pt":1723394764339,"mc":[{"id":"1.231679052","rc":[{"batb":[[0,1.71,4.2],[1,1.7,16.59],[2,1.68,13.53]],"ltp":1.7,"tv":3809.98,"id":19144241}]}]}
{"op":"mcm","clk":"11819855925","pt":1723394766613,"mc":[{"id":"1.231679052","rc":[{"batb":[[1,1.74,18.17]],"batl":[[0,10,1.03],[1,25,0.13]],"ltp":2.22,"tv":143.78,"id":19144236}]}]}
{"op":"mcm","clk":"11819856095","pt":1723394767656,"mc":[{"id":"1.231679052","rc":[{"batb":[[0,1.74,18.17],[1,1.26,4.7],[2,1.1,10024.22]],"ltp":2.22,"tv":143.78,"id":19144236},{"batb":[[1,1.68,13.53],[2,1.59,2.19]],"ltp":1.7,"tv":3809.98,"id":19144241}]}]}
{"op":"mcm","clk":"11819857179","pt":1723394774220,"mc":[{"id":"1.231679052","rc":[{"batb":[[0,2.12,13.27],[1,1.74,18.17],[2,1.26,4.7]],"ltp":2.22,"tv":143.78,"id":19144236},{"batb":[[1,1.68,30.28]],"ltp":1.7,"tv":3809.98,"id":19144241}]}]}
{"op":"mcm","clk":"11819857375","pt":1723394775430,"mc":[{"id":"1.231679052","rc":[{"batb":[[0,1.74,18.17],[1,1.26,4.7],[2,1.1,10024.22]],"ltp":2.22,"tv":143.78,"id":19144236},{"batb":[[1,1.68,13.53]],"ltp":1.7,"tv":3809.98,"id":19144241}]}]}
{"op":"mcm","clk":"11819858536","pt":1723394782734,"mc":[{"id":"1.231679052","rc":[{"trd":[[2.2,37.14]],"ltp":2.2,"tv":146.51,"id":19144236},{"trd":[[1.82,28.54],[1.83,22.29]],"batl":[[0,1.83,8.5],[1,1.87,13.82],[2,1.88,25.76]],"ltp":1.83,"tv":3813.28,"id":19144241}],"tv":3959.8}]}
{"op":"mcm","clk":"11819859869","pt":1723394791030,"mc":[{"id":"1.231679052","rc":[{"batb":[[0,2.12,13.31],[1,1.74,18.17],[2,1.26,4.7]],"ltp":2.2,"tv":146.51,"id":19144236},{"batb":[[1,1.69,16.71],[2,1.68,13.53]],"ltp":1.83,"tv":3813.28,"id":19144241}]}]}
{"op":"mcm","clk":"11819862478","pt":1723394806178,"mc":[{"id":"1.231679052","rc":[{"batb":[[1,1.74,17.75]],"batl":[[0,25,0.81],[1,25,0]],"ltp":2.2,"tv":146.51,"id":19144236}]}]}
{"op":"mcm","clk":"11819864259","pt":1723394817792,"mc":[{"id":"1.231679052","rc":[{"batb":[[0,1.72,2.22],[1,1.71,4.2],[2,1.69,16.71]],"ltp":1.83,"tv":3813.28,"id":19144241}]}]}
{"op":"mcm","clk":"11819865829","pt":1723394827384,"mc":[{"id":"1.231679052","rc":[{"batl":[[0,10,1.03],[1,25,0.13]],"ltp":2.2,"tv":146.51,"id":19144236}]}]}
{"op":"mcm","clk":"11819865866","pt":1723394827596,"mc":[{"id":"1.231679052","rc":[{"batb":[[1,1.74,18.18]],"ltp":2.2,"tv":146.51,"id":19144236}]}]}
{"op":"mcm","clk":"11819868194","pt":1723394842176,"mc":[{"id":"1.231679052","rc":[{"batb":[[0,1.74,18.18],[1,1.26,4.7],[2,1.1,10024.22]],"ltp":2.2,"tv":146.51,"id":19144236},{"batb":[[2,1.68,13.53]],"ltp":1.83,"tv":3813.28,"id":19144241}]}]}
{"op":"mcm","clk":"11819870235","pt":1723394855827,"mc":[{"id":"1.231679052","rc":[{"batb":[[1,1.68,13.53],[2,1.59,2.19]],"ltp":1.83,"tv":3813.28,"id":19144241}]}]}
{"op":"mcm","clk":"11819871074","pt":1723394860931,"mc":[{"id":"1.231679052","rc":[{"batb":[[0,1.73,4.2],[1,1.72,2.22],[2,1.68,13.53]],"ltp":1.83,"tv":3813.28,"id":19144241}]}]}
{"op":"mcm","clk":"11819871422","pt":1723394863355,"mc":[{"id":"1.231679052","rc":[{"batb":[[0,1.74,17.75]],"batl":[[0,25,0.81],[1,25,0]],"ltp":2.2,"tv":146.51,"id":19144236}]}]}
{"op":"mcm","clk":"11819871809","pt":1723394865916,"mc":[{"id":"1.231679052","rc":[{"batb":[[0,2.1,13.43],[1,1.74,17.75],[2,1.26,4.7]],"ltp":2.2,"tv":146.51,"id":19144236},{"batb":[[2,1.7,16.59]],"ltp":1.83,"tv":3813.28,"id":19144241}]}]}
{"op":"mcm","clk":"11819874791","pt":1723394884354,"mc":[{"id":"1.231679052","rc":[{"batb":[[1,1.74,18.19]],"batl":[[0,10,1.03],[1,25,0.13]],"ltp":2.2,"tv":146.51,"id":19144236}]}]}
{"op":"mcm","clk":"11819877192","pt":1723394899667,"mc":[{"id":"1.231679052","rc":[{"trd":[[2.38,3.71]],"ltp":2.38,"tv":149.22,"id":19144236},{"trd":[[1.73,3.73]],"batb":[[0,1.72,2.69],[1,1.7,16.59],[2,1.68,13.53]],"ltp":1.73,"tv":3817.01,"id":19144241}],"tv":3966.24}]}
{"op":"mcm","clk":"11819877520","pt":1723394901556,"mc":[{"id":"1.231679052","rc":[{"batb":[[0,1.74,18.19],[1,1.26,4.7],[2,1.1,10024.22]],"ltp":2.38,"tv":149.22,"id":19144236},{"batb":[[1,1.68,13.53],[2,1.59,2.19]],"ltp":1.73,"tv":3817.01,"id":19144241}]}]}
{"op":"mcm","clk":"11819878493","pt":1723394907449,"mc":[{"id":"1.231679052","rc":[{"batb":[[0,1.72,2.22]],"ltp":1.73,"tv":3817.01,"id":19144241}]}]}
{"op":"mcm","clk":"11819879125","pt":1723394911671,"mc":[{"id":"1.231679052","rc":[{"batb":[[0,2.1,13.43],[1,1.74,18.19],[2,1.26,4.7]],"ltp":2.38,"tv":149.22,"id":19144236},{"batb":[[1,1.7,16.59],[2,1.68,13.53]],"ltp":1.73,"tv":3817.01,"id":19144241}]}]}
{"op":"mcm","clk":"11819880621","pt":1723394920771,"mc":[{"id":"1.231679052","rc":[{"batb":[[1,1.68,13.53],[2,1.59,2.19]],"ltp":1.73,"tv":3817.01,"id":19144241}]}]}
{"op":"mcm","clk":"11819881480","pt":1723394926253,"mc":[{"id":"1.231679052","rc":[{"batl":[[0,25,0.81],[1,25,0]],"ltp":2.38,"tv":149.22,"id":19144236},{"batb":[[1,1.68,30.28]],"ltp":1.73,"tv":3817.01,"id":19144241}]}]}
{"op":"mcm","clk":"11819881542","pt":1723394926674,"mc":[{"id":"1.231679052","rc":[{"batb":[[1,1.74,17.76]],"ltp":2.38,"tv":149.22,"id":19144236}]}]}
{"op":"mcm","clk":"11819881656","pt":1723394927418,"mc":[{"id":"1.231679052","rc":[{"batb":[[1,1.68,13.53]],"ltp":1.73,"tv":3817.01,"id":19144241}]}]}
{"op":"mcm","clk":"11819882445","pt":1723394932296,"mc":[{"id":"1.231679052","rc":[{"batb":[[1,1.7,16.59],[2,1.68,13.53]],"ltp":1.73,"tv":3817.01,"id":19144241}]}]}
{"op":"mcm","clk":"11819882463","pt":1723394932410,"mc":[{"id":"1.231679052","rc":[{"batl":[[0,1.82,4.03],[1,1.83,8.5],[2,1.87,13.82]],"ltp":1.73,"tv":3817.01,"id":19144241}]}]}
{"op":"mcm","clk":"11819884737","pt":1723394947293,"mc":[{"id":"1.231679052","rc":[{"batb":[[1,1.74,18.2]],"batl":[[0,10,1.03],[1,25,0.13]],"ltp":2.38,"tv":149.22,"id":19144236}]}]}
{"op":"mcm","clk":"11819884754","pt":1723394947396,"mc":[{"id":"1.231679052","rc":[{"batl":[[0,1.83,8.5],[1,1.87,13.82],[2,1.88,25.76]],"ltp":1.73,"tv":3817.01,"id":19144241}]}]}
{"op":"mcm","clk":"11819885459","pt":1723394952211,"mc":[{"id":"1.231679052","rc":[{"trd":[[2.2,44.21]],"batb":[[0,1.74,18.2],[1,1.26,4.7],[2,1.1,10024.22]],"batl":[[0,3,1.34],[1,25,0.46]],"ltp":2.2,"tv":156.29,"id":19144236},{"trd":[[1.83,30.79]],"batb":[[1,1.68,13.53],[2,1.59,2.19]],"batl":[[0,1.87,13.82],[1,1.88,25.76],[2,1.93,7.21]],"ltp":1.83,"tv":3825.51,"id":19144241}],"tv":3981.81}]}
{"op":"mcm","clk":"11819885509","pt":1723394952522,"mc":[{"id":"1.231679052","rc":[{"trd":[[2.2,44.85]],"batl":[[0,10,1.03],[1,25,0.13]],"ltp":2.2,"tv":156.93,"id":19144236},{"trd":[[1.83,31.56]],"batl":[[0,1.8,3.27],[1,1.87,13.82],[2,1.88,25.76]],"ltp":1.83,"tv":3826.28,"id":19144241}],"tv":3983.22}]}
{"op":"mcm","clk":"11819886161","pt":1723394956522,"mc":[{"id":"1.231679052","rc":[{"batb":[[0,1.75,2.22],[1,1.72,2.22],[2,1.68,13.53]],"ltp":1.83,"tv":3826.28,"id":19144241}]}]}
{"op":"mcm","clk":"11819887562","pt":1723394965797,"mc":[{"id":"1.231679052","rc":[{"batb":[[0,1.72,2.22],[1,1.68,13.53],[2,1.59,2.19]],"ltp":1.83,"tv":3826.28,"id":19144241}]}]}
{"op":"mcm","clk":"11819888725","pt":1723394973807,"mc":[{"id":"1.231679052","rc":[{"batb":[[0,2.1,13.47],[1,1.74,18.2],[2,1.26,4.7]],"ltp":2.2,"tv":156.93,"id":19144236},{"batb":[[1,1.71,16.54],[2,1.68,13.53]],"ltp":1.83,"tv":3826.28,"id":19144241}]}]}
{"op":"mcm","clk":"11819890505","pt":1723394986280,"mc":[{"id":"1.231679052","rc":[{"batb":[[1,1.74,17.76]],"batl":[[0,25,0.81],[1,25,0]],"ltp":2.2,"tv":156.93,"id":19144236}]}]}
{"op":"mcm","clk":"11819890884","pt":1723394988756,"mc":[{"id":"1.231679052","rc":[{"batl":[[0,25,0.86]],"ltp":2.2,"tv":156.93,"id":19144236}]}]}
{"op":"mcm","clk":"11819891168","pt":1723394990650,"mc":[{"id":"1.231679052","rc":[{"batb":[[0,1.73,3.65],[1,1.72,2.22],[2,1.71,16.54]],"ltp":1.83,"tv":3826.28,"id":19144241}]}]}
{"op":"mcm","clk":"11819891477","pt":1723394992855,"mc":[{"id":"1.231679052","rc":[{"batb":[[0,1.74,17.76],[1,1.26,4.7],[2,1.1,10024.22]],"ltp":2.2,"tv":156.93,"id":19144236},{"batb":[[2,1.68,13.53]],"ltp":1.83,"tv":3826.28,"id":19144241}]}]}
{"op":"mcm","clk":"11819892884","pt":1723395002372,"mc":[{"id":"1.231679052","rc":[{"batb":[[0,2.08,13.58],[1,1.74,17.76],[2,1.26,4.7]],"ltp":2.2,"tv":156.93,"id":19144236}]}]}
{"op":"mcm","clk":"11819893708","pt":1723395007574,"mc":[{"id":"1.231679052","rc":[{"batb":[[1,1.74,18.2]],"batl":[[0,10,1.07],[1,25,0.13]],"ltp":2.2,"tv":156.93,"id":19144236}]}]}
{"op":"mcm","clk":"11819894142","pt":1723395010816,"mc":[{"id":"1.231679052","rc":[{"trd":[[2.24,10.93]],"ltp":2.24,"tv":157.12,"id":19144236},{"trd":[[1.8,1750.85]],"batl":[[0,1.8,3.04]],"ltp":1.8,"tv":3826.51,"id":19144241}],"tv":3983.63}]}
{"op":"mcm","clk":"11819895161","pt":1723395017898,"mc":[{"id":"1.231679052","rc":[{"batb":[[1,1.72,18.65]],"ltp":1.8,"tv":3826.51,"id":19144241}]}]}
{"op":"mcm","clk":"11819899276","pt":1723395046458,"mc":[{"id":"1.231679052","rc":[{"batb":[[0,1.72,18.65],[1,1.68,13.53],[2,1.59,2.19]],"ltp":1.8,"tv":3826.51,"id":19144241}]}]}
{"op":"mcm","clk":"11819899532","pt":1723395048338,"mc":[{"id":"1.231679052","rc":[{"batb":[[0,1.74,18.2],[1,1.26,4.7],[2,1.1,10024.22]],"batl":[[0,25,0.86],[1,25,0]],"ltp":2.24,"tv":157.12,"id":19144236},{"batb":[[0,1.72,2.22]],"ltp":1.8,"tv":3826.51,"id":19144241}]}]}
{"op":"mcm","clk":"11819899562","pt":1723395048552,"mc":[{"id":"1.231679052","rc":[{"batb":[[0,1.74,17.76]],"ltp":2.24,"tv":157.12,"id":19144236}]}]}
{"op":"mcm","clk":"11819900333","pt":1723395053755,"mc":[{"id":"1.231679052","rc":[{"batb":[[0,2.1,13.47],[1,1.74,17.76],[2,1.26,4.7]],"ltp":2.24,"tv":157.12,"id":19144236},{"batb":[[1,1.71,16.54],[2,1.68,13.53]],"ltp":1.8,"tv":3826.51,"id":19144241}]}]}
{"op":"mcm","clk":"11819900970","pt":1723395058368,"mc":[{"id":"1.231679052","rc":[{"batl":[[0,1.8,3.1]],"ltp":1.8,"tv":3826.51,"id":19144241}]}]}
{"op":"mcm","clk":"11819902342","pt":1723395068286,"mc":[{"id":"1.231679052","rc":[{"batb":[[1,1.74,18.2]],"batl":[[0,10,1.07],[1,25,0.13]],"ltp":2.24,"tv":157.12,"id":19144236}]}]}
{"op":"mcm","clk":"11819908427","pt":1723395109392,"mc":[{"id":"1.231679052","rc":[{"batl":[[0,25,0.86],[1,25,0]],"ltp":2.24,"tv":157.12,"id":19144236}]}]}
{"op":"mcm","clk":"11819908509","pt":1723395109812,"mc":[{"id":"1.231679052","rc":[{"batb":[[1,1.74,17.76]],"ltp":2.24,"tv":157.12,"id":19144236}]}]}
{"op":"mcm","clk":"11819910615","pt":1723395124395,"mc":[{"id":"1.231679052","rc":[{"batl":[[0,1000,1.21]],"ltp":2.24,"tv":157.12,"id":19144236}]}]}
{"op":"mcm","clk":"11819910662","pt":1723395124808,"mc":[{"id":"1.231679052","rc":[{"batl":[[0,25,0.86]],"ltp":2.24,"tv":157.12,"id":19144236}]}]}
{"op":"mcm","clk":"11819911341","pt":1723395129948,"mc":[{"id":"1.231679052","rc":[{"batb":[[1,1.74,18.2]],"batl":[[0,10,1.07],[1,25,0.13]],"ltp":2.24,"tv":157.12,"id":19144236}]}]}
{"op":"mcm","clk":"11819913812","pt":1723395148253,"mc":[{"id":"1.231679052","rc":[{"trd":[[2.26,11.95]],"ltp":2.26,"tv":157.13,"id":19144236},{"trd":[[1.79,19.14]],"batl":[[0,1.8,3.08]],"ltp":1.79,"tv":3826.53,"id":19144241}],"tv":3983.67}]}
{"op":"mcm","clk":"11819916623","pt":1723395168723,"mc":[{"id":"1.231679052","rc":[{"batb":[[1,1.74,17.76]],"batl":[[0,25,0.86],[1,25,0]],"ltp":2.26,"tv":157.13,"id":19144236}]}]}
{"op":"mcm","clk":"11819917323","pt":1723395173744,"mc":[{"id":"1.231679052","rc":[{"batl":[[0,1.87,13.87],[1,1.88,25.76],[2,1.93,7.21]],"ltp":1.79,"tv":3826.53,"id":19144241}]}]}
{"op":"mcm","clk":"11819919476","pt":1723395189056,"mc":[{"id":"1.231679052","rc":[{"batb":[[1,1.74,18.2]],"batl":[[0,10,1.07],[1,25,0.13]],"ltp":2.26,"tv":157.13,"id":19144236}]}]}
{"op":"mcm","clk":"11819924043","pt":1723395219719,"mc":[{"id":"1.231679052","rc":[{"trd":[[2.38,3.76]],"batl":[[0,10,1.03]],"ltp":2.38,"tv":157.18,"id":19144236},{"trd":[[1.72,334.54]],"batb":[[0,1.71,16.54],[1,1.68,13.53],[2,1.59,2.19]],"batl":[[0,1.72,85.71],[1,1.87,13.87],[2,1.88,25.76]],"ltp":1.72,"tv":3831.04,"id":19144241}],"tv":3988.23}]}
{"op":"mcm","clk":"11819924238","pt":1723395221136,"mc":[{"id":"1.231679052","rc":[{"batb":[[0,1.74,18.2],[1,1.26,4.7],[2,1.1,10024.22]],"ltp":2.38,"tv":157.18,"id":19144236},{"batb":[[0,1.68,13.53],[1,1.59,2.19],[2,1.4,1.62]],"ltp":1.72,"tv":3831.04,"id":19144241}]}]}
{"op":"mcm","clk":"11819925472","pt":1723395230127,"mc":[{"id":"1.231679052","rc":[{"batb":[[0,1.74,17.76]],"batl":[[0,25,0.81],[1,25,0]],"ltp":2.38,"tv":157.18,"id":19144236}]}]}
{"op":"mcm","clk":"11819925512","pt":1723395230446,"mc":[{"id":"1.231679052","rc":[{"batb":[[2,1.3,1.07]],"ltp":1.72,"tv":3831.04,"id":19144241}]}]}
{"op":"mcm","clk":"11819927563","pt":1723395245163,"mc":[{"id":"1.231679052","rc":[{"batb":[[2,1.32,1.83]],"ltp":1.72,"tv":3831.04,"id":19144241}]}]}
{"op":"mcm","clk":"11819928307","pt":1723395250288,"mc":[{"id":"1.231679052","rc":[{"batb":[[0,1.74,18.18]],"batl":[[0,10,1.03],[1,25,0.13]],"ltp":2.38,"tv":157.18,"id":19144236}]}]}
{"op":"mcm","clk":"11819928696","pt":1723395253391,"mc":[{"id":"1.231679052","rc":[{"trd":[[1.72,338.98]],"batb":[[0,1.68,15.35]],"batl":[[0,1.72,83.49]],"ltp":1.72,"tv":3835.48,"id":19144241}],"tv":3992.67}]}
{"op":"mcm","clk":"11819928754","pt":1723395253752,"mc":[{"id":"1.231679052","rc":[{"trd":[[2.38,23.53]],"ltp":2.38,"tv":176.95,"id":19144236},{"trd":[[1.72,366.33]],"batl":[[0,1.72,56.14]],"ltp":1.72,"tv":3862.83,"id":19144241}],"tv":4039.78}]}
{"op":"mcm","clk":"11819930574","pt":1723395266365,"mc":[{"id":"1.231679052","rc":[{"trd":[[1.68,204.12]],"batb":[[0,1.68,12.31]],"ltp":1.68,"tv":3868.91,"id":19144241}],"tv":4045.86}]}
{"op":"mcm","clk":"11819933606","pt":1723395289209,"mc":[{"id":"1.231679052","rc":[{"batl":[[0,25,0.81],[1,25,0]],"ltp":2.38,"tv":176.95,"id":19144236}]}]}
{"op":"mcm","clk":"11819933671","pt":1723395289695,"mc":[{"id":"1.231679052","rc":[{"batb":[[0,1.74,17.74]],"ltp":2.38,"tv":176.95,"id":19144236},{"batb":[[2,1.32,1.09]],"ltp":1.68,"tv":3868.91,"id":19144241}]}]}
{"op":"mcm","clk":"11819935508","pt":1723395302714,"mc":[{"id":"1.231679052","rc":[{"batb":[[0,1.68,10.49]],"ltp":1.68,"tv":3868.91,"id":19144241}]}]}
{"op":"mcm","clk":"11819935897","pt":1723395305318,"mc":[{"id":"1.231679052","rc":[{"batb":[[2,1.32,2.18]],"ltp":1.68,"tv":3868.91,"id":19144241}]}]}
{"op":"mcm","clk":"11819936278","pt":1723395307839,"mc":[{"id":"1.231679052","rc":[{"batb":[[0,1.71,1.82],[1,1.68,10.49],[2,1.59,2.19]],"ltp":1.68,"tv":3868.91,"id":19144241}]}]}
{"op":"mcm","clk":"11819936765","pt":1723395310852,"mc":[{"id":"1.231679052","rc":[{"batb":[[0,1.74,18.16]],"batl":[[0,10,1.03],[1,25,0.13]],"ltp":2.38,"tv":176.95,"id":19144236}]}]}
{"op":"mcm","clk":"11819936968","pt":1723395312128,"mc":[{"id":"1.231679052","rc":[{"batl":[[0,1.87,13.87],[1,1.88,25.76],[2,1.93,7.21]],"ltp":1.68,"tv":3868.91,"id":19144241}]}]}
{"op":"mcm","clk":"11819937759","pt":1723395317218,"mc":[{"id":"1.231679052","rc":[{"trd":[[1.68,225.1],[1.71,3.64]],"batb":[[0,1.59,2.19],[1,1.32,2.18],[2,1.26,5.03]],"batl":[[0,1.68,43.83],[1,1.87,13.87],[2,1.88,25.76]],"ltp":1.68,"tv":3893.53,"id":19144241}],"tv":4070.49}]}
{"op":"mcm","clk":"11819937874","pt":1723395317952,"mc":[{"id":"1.231679052","rc":[{"batb":[[0,2.1,13.43],[1,1.74,18.16],[2,1.26,4.7]],"ltp":2.38,"tv":176.95,"id":19144236},{"trd":[[1.68,258.28]],"batl":[[0,1.68,27.24]],"ltp":1.68,"tv":3926.71,"id":19144241}],"tv":4103.66}]}
{"op":"mcm","clk":"11819938369","pt":1723395321434,"mc":[{"id":"1.231679052","rc":[{"batb":[[0,1.74,18.16],[1,1.26,4.7],[2,1.1,10024.22]],"ltp":2.38,"tv":176.95,"id":19144236}]}]}
{"op":"mcm","clk":"11819941208","pt":1723395342071,"mc":[{"id":"1.231679052","rc":[{"batb":[[0,1.74,18.21]],"ltp":2.38,"tv":176.95,"id":19144236},{"batb":[[1,1.32,1.09]],"ltp":1.68,"tv":3926.71,"id":19144241}]}]}
{"op":"mcm","clk":"11819941632","pt":1723395345381,"mc":[{"id":"1.231679052","rc":[{"trd":[[2.46,4.8]],"ltp":2.46,"tv":181.2,"id":19144236},{"trd":[[1.68,264.5]],"batl":[[0,1.68,21.02]],"ltp":1.68,"tv":3932.93,"id":19144241}],"tv":4114.13}]}
{"op":"mcm","clk":"11819942014","pt":1723395348096,"mc":[{"id":"1.231679052","rc":[{"batb":[[0,1.74,17.79]],"batl":[[0,25,0.81],[1,25,0]],"ltp":2.46,"tv":181.2,"id":19144236}]}]}
{"op":"mcm","clk":"11819942423","pt":1723395351384,"mc":[{"id":"1.231679052","rc":[{"batb":[[0,1.6,1.82],[1,1.59,2.19],[2,1.32,1.09]],"ltp":1.68,"tv":3932.93,"id":19144241}]}]}
{"op":"mcm","clk":"11819942640","pt":1723395352882,"mc":[{"id":"1.231679052","rc":[{"batb":[[1,1.59,21.88]],"ltp":1.68,"tv":3932.93,"id":19144241}]}]}
{"op":"mcm","clk":"11819942808","pt":1723395354193,"mc":[{"id":"1.231679052","rc":[{"trd":[[1.68,306.54]],"batb":[[0,1.7,2895.65],[1,1.6,1.82],[2,1.59,21.88]],"batl":[[0,1.87,13.87],[1,1.88,25.76],[2,1.93,7.21]],"ltp":1.68,"tv":3974.97,"id":19144241}],"tv":4156.17}]}
{"op":"mcm","clk":"11819943503","pt":1723395359367,"mc":[{"id":"1.231679052","rc":[{"batb":[[0,2.18,12.98],[1,1.74,17.74],[2,1.26,4.7]],"ltp":2.46,"tv":181.2,"id":19144236},{"batb":[[1,1.65,17.08],[2,1.6,1.82]],"ltp":1.68,"tv":3974.97,"id":19144241}]}]}
{"op":"mcm","clk":"11819943662","pt":1723395360571,"mc":[{"id":"1.231679052","rc":[{"batb":[[0,1.74,17.79],[1,1.26,4.7],[2,1.1,10024.22]],"ltp":2.46,"tv":181.2,"id":19144236},{"batb":[[1,1.6,1.82],[2,1.59,21.88]],"ltp":1.68,"tv":3974.97,"id":19144241}]}]}
{"op":"mcm","clk":"11819943942","pt":1723395362687,"mc":[{"id":"1.231679052","rc":[{"batl":[[0,2.46,1.46],[1,25,0.81]],"ltp":2.46,"tv":181.2,"id":19144236}]}]}
{"op":"mcm","clk":"11819944118","pt":1723395363795,"mc":[{"id":"1.231679052","rc":[{"batl":[[0,1.78,7.21],[1,1.87,13.87],[2,1.88,25.76]],"ltp":1.68,"tv":3974.97,"id":19144241}]}]}
{"op":"mcm","clk":"11819944315","pt":1723395365313,"mc":[{"id":"1.231679052","rc":[{"batb":[[1,1.6,2.6]],"ltp":1.68,"tv":3974.97,"id":19144241}]}]}
{"op":"mcm","clk":"11819944341","pt":1723395365468,"mc":[{"id":"1.231679052","rc":[{"batb":[[0,2.1,13.48],[1,1.74,17.74],[2,1.26,4.7]],"ltp":2.46,"tv":181.2,"id":19144236},{"batb":[[0,1.7,2912.24]],"ltp":1.68,"tv":3974.97,"id":19144241}]}]}
{"op":"mcm","clk":"11819944798","pt":1723395368858,"mc":[{"id":"1.231679052","rc":[{"batb":[[1,1.74,18.17]],"batl":[[1,10,1.03],[2,25,0.13]],"ltp":2.46,"tv":181.2,"id":19144236}]}]}
{"op":"mcm","clk":"11819946440","pt":1723395382412,"mc":[{"id":"1.231679052","rc":[{"batl":[[0,1.77,4.86],[1,1.78,7.21],[2,1.87,13.87]],"ltp":1.68,"tv":3974.97,"id":19144241}]}]}
{"op":"mcm","clk":"11819946647","pt":1723395383986,"mc":[{"id":"1.231679052","rc":[{"batb":[[0,1.7,2895.65]],"ltp":1.68,"tv":3974.97,"id":19144241}]}]}
{"op":"mcm","clk":"11819947790","pt":1723395392806,"mc":[{"id":"1.231679052","rc":[{"batb":[[1,1.59,22.65],[2,1.32,1.83]],"ltp":1.68,"tv":3974.97,"id":19144241}]}]}
{"op":"mcm","clk":"11819948764","pt":1723395400836,"mc":[{"id":"1.231679052","rc":[{"batb":[[1,1.59,2.96]],"ltp":1.68,"tv":3974.97,"id":19144241}]}]}
{"op":"mcm","clk":"11819949536","pt":1723395406738,"mc":[{"id":"1.231679052","rc":[{"batb":[[2,1.3,1.07]],"ltp":1.68,"tv":3974.97,"id":19144241}]}]}
{"op":"mcm","clk":"11819949798","pt":1723395408936,"mc":[{"id":"1.231679052","rc":[{"batb":[[0,2.1,13.43]],"ltp":2.46,"tv":181.2,"id":19144236}]}]}
{"op":"mcm","clk":"11819950146","pt":1723395411758,"mc":[{"id":"1.231679052","rc":[{"batb":[[1,1.74,17.75]],"batl":[[1,25,0.81],[2,25,0]],"ltp":2.46,"tv":181.2,"id":19144236},{"batl":[[2,1.87,13.82]],"ltp":1.68,"tv":3974.97,"id":19144241}]}]}
{"op":"mcm","clk":"11819950950","pt":1723395418150,"mc":[{"id":"1.231679052","rc":[{"batb":[[0,1.59,2.96],[1,1.3,1.07],[2,1.26,4.7]],"ltp":1.68,"tv":3974.97,"id":19144241}]}]}
{"op":"mcm","clk":"11819951722","pt":1723395423948,"mc":[{"id":"1.231679052","rc":[{"batb":[[0,1.74,17.75],[1,1.26,4.7],[2,1.1,10024.22]],"ltp":2.46,"tv":181.2,"id":19144236}]}]}
{"op":"mcm","clk":"11819951895","pt":1723395425368,"mc":[{"id":"1.231679052","rc":[{"batl":[[1,1000,1.16]],"ltp":2.46,"tv":181.2,"id":19144236}]}]}
{"op":"mcm","clk":"11819951940","pt":1723395425730,"mc":[{"id":"1.231679052","rc":[{"batl":[[1,25,0.81]],"ltp":2.46,"tv":181.2,"id":19144236}]}]}
{"op":"mcm","clk":"11819952558","pt":1723395430862,"mc":[{"id":"1.231679052","rc":[{"batb":[[0,1.74,18.17]],"batl":[[1,10,1.03],[2,25,0.13]],"ltp":2.46,"tv":181.2,"id":19144236},{"batb":[[1,1.37,1.69],[2,1.26,5.03]],"ltp":1.68,"tv":3974.97,"id":19144241}]}]}
{"op":"mcm","clk":"11819953406","pt":1723395437864,"mc":[{"id":"1.231679052","rc":[{"batl":[[0,1.77,4.91]],"ltp":1.68,"tv":3974.97,"id":19144241}]}]}
{"op":"mcm","clk":"11819955005","pt":1723395449362,"mc":[{"id":"1.231679052","rc":[{"batb":[[0,1.59,2.19]],"ltp":1.68,"tv":3974.97,"id":19144241}]}]}
{"op":"mcm","clk":"11819957050","pt":1723395466478,"mc":[{"id":"1.231679052","rc":[{"batl":[[0,1.78,7.26],[1,1.87,13.82],[2,1.88,25.76]],"ltp":1.68,"tv":3974.97,"id":19144241}]}]}
{"op":"mcm","clk":"11819957532","pt":1723395470299,"mc":[{"id":"1.231679052","rc":[{"batb":[[0,1.74,17.74]],"batl":[[1,25,0.81],[2,25,0]],"ltp":2.46,"tv":181.2,"id":19144236}]}]}
{"op":"mcm","clk":"11819957604","pt":1723395470815,"mc":[{"id":"1.231679052","rc":[{"batb":[[1,1.3,1.28],[2,1.26,4.7]],"ltp":1.68,"tv":3974.97,"id":19144241}]}]}
{"op":"mcm","clk":"11819957691","pt":1723395471599,"mc":[{"id":"1.231679052","rc":[{"batl":[[0,1.72,4.86],[1,1.78,7.26],[2,1.87,13.82]],"ltp":1.68,"tv":3974.97,"id":19144241}]}]}
{"op":"mcm","clk":"11819957908","pt":1723395473601,"mc":[{"id":"1.231679052","rc":[{"batb":[[0,2.1,13.43],[1,1.74,17.74],[2,1.26,4.7]],"ltp":2.46,"tv":181.2,"id":19144236}]}]}
{"op":"mcm","clk":"11819958200","pt":1723395475891,"mc":[{"id":"1.231679052","rc":[{"batb":[[0,1.74,17.74],[1,1.26,4.7],[2,1.1,10024.22]],"ltp":2.46,"tv":181.2,"id":19144236}]}]}
{"op":"mcm","clk":"11819958755","pt":1723395480424,"mc":[{"id":"1.231679052","rc":[{"batl":[[0,1.78,7.26],[1,1.87,13.82],[2,1.88,25.76]],"ltp":1.68,"tv":3974.97,"id":19144241}]}]}
{"op":"mcm","clk":"11819959438","pt":1723395485534,"mc":[{"id":"1.231679052","rc":[{"batl":[[0,1.75,4.91],[1,1.78,7.21],[2,1.87,13.82]],"ltp":1.68,"tv":3974.97,"id":19144241}]}]}
{"op":"mcm","clk":"11819959589","pt":1723395486844,"mc":[{"id":"1.231679052","rc":[{"batb":[[0,2.12,13.31],[1,1.74,17.74],[2,1.26,4.7]],"ltp":2.46,"tv":181.2,"id":19144236}]}]}
{"op":"mcm","clk":"11819959667","pt":1723395487435,"mc":[{"id":"1.231679052","rc":[{"batb":[[0,1.74,17.74],[1,1.26,4.7],[2,1.1,10024.22]],"ltp":2.46,"tv":181.2,"id":19144236}]}]}
{"op":"mcm","clk":"11819959987","pt":1723395490252,"mc":[{"id":"1.231679052","rc":[{"batl":[[1,1000,1.16]],"ltp":2.46,"tv":181.2,"id":19144236}]}]}
{"op":"mcm","clk":"11819960037","pt":1723395490775,"mc":[{"id":"1.231679052","rc":[{"batl":[[1,25,0.81]],"ltp":2.46,"tv":181.2,"id":19144236}]}]}
{"op":"mcm","clk":"11819960343","pt":1723395493154,"mc":[{"id":"1.231679052","rc":[{"batb":[[2,1.1,6.19]],"ltp":2.46,"tv":181.2,"id":19144236}]}]}
{"op":"mcm","clk":"11819960705","pt":1723395495857,"mc":[{"id":"1.231679052","rc":[{"batb":[[0,1.74,18.16]],"batl":[[1,10,1.03],[2,25,0.13]],"ltp":2.46,"tv":181.2,"id":19144236},{"batb":[[1,1.37,1.87],[2,1.26,5.03]],"ltp":1.68,"tv":3974.97,"id":19144241}]}]}
{"op":"mcm","clk":"11819965214","pt":1723395532914,"mc":[{"id":"1.231679052","rc":[{"batb":[[0,1.74,17.74]],"batl":[[1,25,0.81],[2,25,0]],"ltp":2.46,"tv":181.2,"id":19144236},{"batb":[[1,1.3,1.25],[2,1.26,4.7]],"ltp":1.68,"tv":3974.97,"id":19144241}]}]}
{"op":"mcm","clk":"11819966701","pt":1723395544327,"mc":[{"id":"1.231679052","rc":[{"batl":[[1,1000,1.16]],"ltp":2.46,"tv":181.2,"id":19144236},{"batb":[[1,1.35,1.92],[2,1.26,5.03]],"ltp":1.68,"tv":3974.97,"id":19144241}]}]}
{"op":"mcm","clk":"11819966757","pt":1723395544700,"mc":[{"id":"1.231679052","rc":[{"batl":[[1,25,0.81]],"ltp":2.46,"tv":181.2,"id":19144236}]}]}
{"op":"mcm","clk":"11819967471","pt":1723395549824,"mc":[{"id":"1.231679052","rc":[{"batb":[[0,1.74,18.16]],"batl":[[1,10,1.03],[2,25,0.13]],"ltp":2.46,"tv":181.2,"id":19144236}]}]}
{"op":"mcm","clk":"11819969177","pt":1723395562039,"mc":[{"id":"1.231679052","rc":[{"trd":[[1.75,3.86]],"batb":[[0,1.75,1.13],[1,1.59,2.19],[2,1.35,1.92]],"batl":[[0,1.78,7.21],[1,1.87,13.82],[2,1.88,25.76]],"ltp":1.75,"tv":3975.07,"id":19144241}],"tv":4156.27}]}
{"op":"mcm","clk":"11819969766","pt":1723395566529,"mc":[{"id":"1.231679052","rc":[{"trd":[[1.75,6.12]],"batb":[[0,1.59,2.19],[1,1.35,1.92],[2,1.26,5.03]],"batl":[[0,1.7,3.73],[1,1.78,7.21],[2,1.87,13.82]],"ltp":1.75,"tv":3977.33,"id":19144241}],"tv":4158.53}]}
{"op":"mcm","clk":"11819969946","pt":1723395568152,"mc":[{"id":"1.231679052","rc":[{"batb":[[0,2.1,13.43],[1,1.74,18.16],[2,1.26,4.7]],"ltp":2.46,"tv":181.2,"id":19144236}]}]}
{"op":"mcm","clk":"11819970331","pt":1723395571260,"mc":[{"id":"1.231679052","rc":[{"batb":[[0,1.74,18.16],[1,1.26,4.7],[2,1.1,6.19]],"ltp":2.46,"tv":181.2,"id":19144236}]}]}
{"op":"mcm","clk":"11819970708","pt":1723395574349,"mc":[{"id":"1.231679052","rc":[{"batl":[[0,1.78,7.21],[1,1.87,13.82],[2,1.88,25.76]],"ltp":1.75,"tv":3977.33,"id":19144241}]}]}
{"op":"mcm","clk":"11819971090","pt":1723395577579,"mc":[{"id":"1.231679052","rc":[{"batb":[[0,2.12,13.31],[1,1.74,18.16],[2,1.26,4.7]],"ltp":2.46,"tv":181.2,"id":19144236}]}]}
{"op":"mcm","clk":"11819971390","pt":1723395579669,"mc":[{"id":"1.231679052","rc":[{"batb":[[0,1.74,18.16],[1,1.26,4.7],[2,1.1,6.19]],"ltp":2.46,"tv":181.2,"id":19144236},{"batb":[[0,1.7,1.18],[1,1.59,2.19],[2,1.35,1.92]],"ltp":1.75,"tv":3977.33,"id":19144241}]}]}
{"op":"mcm","clk":"11819972179","pt":1723395585972,"mc":[{"id":"1.231679052","rc":[{"batb":[[0,2.1,13.47],[1,1.74,18.16],[2,1.26,4.7]],"ltp":2.46,"tv":181.2,"id":19144236}]}]}
{"op":"mcm","clk":"11819972803","pt":1723395591270,"mc":[{"id":"1.231679052","rc":[{"batl":[[1,25,0.81],[2,25,0]],"ltp":2.46,"tv":181.2,"id":19144236}]}]}
{"op":"mcm","clk":"11819972847","pt":1723395591580,"mc":[{"id":"1.231679052","rc":[{"batb":[[1,1.74,17.74]],"ltp":2.46,"tv":181.2,"id":19144236},{"batb":[[2,1.35,1]],"ltp":1.75,"tv":3977.33,"id":19144241}]}]}
{"op":"mcm","clk":"11819974458","pt":1723395602301,"mc":[{"id":"1.231679052","rc":[{"batb":[[0,1.71,10.5],[1,1.7,1.18],[2,1.59,2.19]],"ltp":1.75,"tv":3977.33,"id":19144241}]}]}
{"op":"mcm","clk":"11819974665","pt":1723395603314,"mc":[{"id":"1.231679052","rc":[{"batb":[[0,1.74,17.74],[1,1.26,4.7],[2,1.1,6.19]],"ltp":2.46,"tv":181.2,"id":19144236}]}]}
{"op":"mcm","clk":"11819975564","pt":1723395608435,"mc":[{"id":"1.231679052","rc":[{"batl":[[0,1.75,3.73],[1,1.78,7.21],[2,1.87,13.82]],"ltp":1.75,"tv":3977.33,"id":19144241}]}]}
{"op":"mcm","clk":"11819976166","pt":1723395612331,"mc":[{"id":"1.231679052","rc":[{"batb":[[0,1.74,18.16]],"batl":[[1,10,1.03],[2,25,0.13]],"ltp":2.46,"tv":181.2,"id":19144236}]}]}
{"op":"mcm","clk":"11819977414","pt":1723395620323,"mc":[{"id":"1.231679052","rc":[{"batb":[[0,1.71,11.68]],"ltp":1.75,"tv":3977.33,"id":19144241}]}]}
{"op":"mcm","clk":"11819978020","pt":1723395624831,"mc":[{"id":"1.231679052","rc":[{"batl":[[0,1.78,7.21],[1,1.87,13.82],[2,1.88,25.76]],"ltp":1.75,"tv":3977.33,"id":19144241}]}]}
{"op":"mcm","clk":"11819978716","pt":1723395629965,"mc":[{"id":"1.231679052","rc":[{"trd":[[1.71,10.4]],"batb":[[0,1.71,8.3]],"ltp":1.71,"tv":3984.08,"id":19144241}],"tv":4165.29}]}
{"op":"mcm","clk":"11819979854","pt":1723395638371,"mc":[{"id":"1.231679052","rc":[{"trd":[[1.78,1079.74]],"batl":[[0,1.78,6.62]],"ltp":1.78,"tv":3985.26,"id":19144241}],"tv":4166.47}]}
{"op":"mcm","clk":"11819981876","pt":1723395653960,"mc":[{"id":"1.231679052","rc":[{"batb":[[0,1.74,17.74]],"batl":[[1,25,0.81],[2,25,0]],"ltp":2.46,"tv":181.2,"id":19144236},{"batl":[[0,1.78,5.45]],"ltp":1.78,"tv":3985.26,"id":19144241}]}]}
{"op":"mcm","clk":"11819984680","pt":1723395673269,"mc":[{"id":"1.231679052","rc":[{"batb":[[0,1.74,18.17]],"batl":[[1,10,1.03],[2,25,0.13]],"ltp":2.46,"tv":181.2,"id":19144236}]}]}
{"op":"mcm","clk":"11819989641","pt":1723395706235,"mc":[{"id":"1.231679052","rc":[{"trd":[[1.78,1084.18]],"batl":[[0,1.78,3.23]],"ltp":1.78,"tv":3989.7,"id":19144241}],"tv":4170.91}]}
{"op":"mcm","clk":"11819990592","pt":1723395712255,"mc":[{"id":"1.231679052","rc":[{"batb":[[0,1.74,17.75]],"batl":[[1,25,0.81],[2,25,0]],"ltp":2.46,"tv":181.2,"id":19144236}]}]}
{"op":"mcm","clk":"11819990644","pt":1723395712527,"mc":[{"id":"1.231679052","rc":[{"trd":[[2.42,5.92]],"batb":[[0,2.42,39.22],[1,1.74,17.75],[2,1.26,4.7]],"ltp":2.42,"tv":187.06,"id":19144236},{"trd":[[1.71,18.7]],"batb":[[0,1.7,1.18],[1,1.59,2.19],[2,1.3,1.25]],"ltp":1.71,"tv":3998.0,"id":19144241}],"tv":4185.07}]}
{"op":"mcm","clk":"11819991559","pt":1723395718612,"mc":[{"id":"1.231679052","rc":[{"batb":[[1,2.08,13.58],[2,1.74,17.75]],"ltp":2.42,"tv":187.06,"id":19144236}]}]}
{"op":"mcm","clk":"11819992070","pt":1723395721670,"mc":[{"id":"1.231679052","rc":[{"batb":[[1,1.74,17.75],[2,1.26,4.7]],"ltp":2.42,"tv":187.06,"id":19144236}]}]}
{"op":"mcm","clk":"11819992705","pt":1723395725814,"mc":[{"id":"1.231679052","rc":[{"trd":[[2.42,11.08]],"batb":[[0,2.42,34.06]],"ltp":2.42,"tv":192.22,"id":19144236},{"trd":[[1.71,26]],"ltp":1.71,"tv":4005.31,"id":19144241}],"tv":4197.53}]}
{"op":"mcm","clk":"11819993110","pt":1723395728130,"mc":[{"id":"1.231679052","rc":[{"batb":[[2,1.31,2.05]],"ltp":1.71,"tv":4005.31,"id":19144241}]}]}
{"op":"mcm","clk":"11819993980","pt":1723395733268,"mc":[{"id":"1.231679052","rc":[{"batb":[[1,1.74,18.17]],"batl":[[1,10,1.03],[2,25,0.13]],"ltp":2.42,"tv":192.22,"id":19144236}]}]}
{"op":"mcm","clk":"11819996158","pt":1723395746332,"mc":[{"id":"1.231679052","rc":[{"batb":[[1,2.12,13.27],[2,1.74,18.17]],"ltp":2.42,"tv":192.22,"id":19144236}]}]}
{"op":"mcm","clk":"11819996281","pt":1723395747061,"mc":[{"id":"1.231679052","rc":[{"trd":[[2.42,15.32]],"batb":[[0,2.42,31.94]],"ltp":2.42,"tv":196.46,"id":19144236}],"tv":4201.77}]}
{"op":"mcm","clk":"11819997583","pt":1723395754065,"mc":[{"id":"1.231679052","rc":[{"trd":[[2.42,15.46]],"batb":[[0,2.42,31.8]],"ltp":2.42,"tv":196.6,"id":19144236},{"trd":[[1.71,26.2]],"ltp":1.71,"tv":4005.51,"id":19144241}],"tv":4202.11}]}
{"op":"mcm","clk":"11820000477","pt":1723395772271,"mc":[{"id":"1.231679052","rc":[{"batb":[[0,2.42,30]],"ltp":2.42,"tv":196.6,"id":19144236}]}]}
{"op":"mcm","clk":"11820000768","pt":1723395774065,"mc":[{"id":"1.231679052","rc":[{"batb":[[2,1.74,17.74]],"batl":[[1,25,0.81],[2,25,0]],"ltp":2.42,"tv":196.6,"id":19144236},{"batb":[[2,1.31,1.13]],"ltp":1.71,"tv":4005.51,"id":19144241}]}]}
{"op":"mcm","clk":"11820000835","pt":1723395774620,"mc":[{"id":"1.231679052","rc":[{"batb":[[1,1.74,17.74],[2,1.26,4.7]],"ltp":2.42,"tv":196.6,"id":19144236}]}]}
{"op":"mcm","clk":"11820002468","pt":1723395785069,"mc":[{"id":"1.231679052","rc":[{"batb":[[1,2.14,13.2],[2,1.74,17.74]],"ltp":2.42,"tv":196.6,"id":19144236}]}]}
{"op":"mcm","clk":"11820002999","pt":1723395788265,"mc":[{"id":"1.231679052","rc":[{"batb":[[2,1.31,2.26]],"ltp":1.71,"tv":4005.51,"id":19144241}]}]}
{"op":"mcm","clk":"11820003438","pt":1723395791004,"mc":[{"id":"1.231679052","rc":[{"batb":[[0,1.59,2.19],[1,1.31,2.26],[2,1.26,5.03]],"batl":[[0,1.7,3.25],[1,1.78,3.23],[2,1.87,13.82]],"ltp":1.71,"tv":4005.51,"id":19144241}]}]}
{"op":"mcm","clk":"11820003845","pt":1723395793350,"mc":[{"id":"1.231679052","rc":[{"batl":[[1,10,1.03],[2,25,0.13]],"ltp":2.42,"tv":196.6,"id":19144236}]}]}
{"op":"mcm","clk":"11820003877","pt":1723395793562,"mc":[{"id":"1.231679052","rc":[{"batb":[[2,1.74,18.16]],"ltp":2.42,"tv":196.6,"id":19144236}]}]}
{"op":"mcm","clk":"11820006044","pt":1723395805974,"mc":[{"id":"1.231679052","rc":[{"batb":[[1,1.74,18.16],[2,1.26,4.7]],"ltp":2.42,"tv":196.6,"id":19144236}]}]}
{"op":"mcm","clk":"11820006936","pt":1723395810905,"mc":[{"id":"1.231679052","rc":[{"batb":[[1,2.2,12.82],[2,1.74,18.16]],"ltp":2.42,"tv":196.6,"id":19144236}]}]}
{"op":"mcm","clk":"11820007138","pt":1723395812091,"mc":[{"id":"1.231679052","rc":[{"batb":[[1,1.74,18.16],[2,1.26,4.7]],"ltp":2.42,"tv":196.6,"id":19144236}]}]}
{"op":"mcm","clk":"11820007892","pt":1723395816995,"mc":[{"id":"1.231679052","rc":[{"batb":[[1,2.16,13.04],[2,1.74,18.16]],"ltp":2.42,"tv":196.6,"id":19144236}]}]}
{"op":"mcm","clk":"11820009178","pt":1723395825117,"mc":[{"id":"1.231679052","rc":[{"trd":[[1.7,7.4]],"batb":[[0,1.7,1.5],[1,1.59,2.19],[2,1.31,2.26]],"batl":[[0,1.78,3.23],[1,1.87,13.82],[2,1.88,25.76]],"ltp":1.7,"tv":4006.15,"id":19144241}],"tv":4202.75}]}
{"op":"mcm","clk":"11820009580","pt":1723395827277,"mc":[{"id":"1.231679052","rc":[{"batb":[[2,1.31,1.13]],"ltp":1.7,"tv":4006.15,"id":19144241}]}]}
{"op":"mcm","clk":"11820009689","pt":1723395828016,"mc":[{"id":"1.231679052","rc":[{"batb":[[0,1.7,1.79]],"ltp":1.7,"tv":4006.15,"id":19144241}]}]}
{"op":"mcm","clk":"11820010327","pt":1723395831998,"mc":[{"id":"1.231679052","rc":[{"batb":[[2,1.74,17.74]],"batl":[[1,25,0.81],[2,25,0]],"ltp":2.42,"tv":196.6,"id":19144236}]}]}
{"op":"mcm","clk":"11820012898","pt":1723395846930,"mc":[{"id":"1.231679052","rc":[{"batb":[[2,1.31,2.26]],"ltp":1.7,"tv":4006.15,"id":19144241}]}]}
{"op":"mcm","clk":"11820013795","pt":1723395852035,"mc":[{"id":"1.231679052","rc":[{"batb":[[2,1.74,18.17]],"batl":[[1,10,1.03],[2,25,0.13]],"ltp":2.42,"tv":196.6,"id":19144236}]}]}
{"op":"mcm","clk":"11820014343","pt":1723395855106,"mc":[{"id":"1.231679052","rc":[{"batb":[[0,1.7,1.5]],"ltp":1.7,"tv":4006.15,"id":19144241}]}]}
{"op":"mcm","clk":"11820014724","pt":1723395857324,"mc":[{"id":"1.231679052","rc":[{"trd":[[2.42,23.98]],"batb":[[0,2.42,21.48]],"ltp":2.42,"tv":205.12,"id":19144236},{"trd":[[1.71,38.26]],"ltp":1.71,"tv":4018.21,"id":19144241}],"tv":4223.33}]}
{"op":"mcm","clk":"11820018339","pt":1723395878877,"mc":[{"id":"1.231679052","rc":[{"batb":[[1,1.74,18.17],[2,1.26,4.7]],"ltp":2.42,"tv":205.12,"id":19144236}]}]}
{"op":"mcm","clk":"11820019164","pt":1723395883898,"mc":[{"id":"1.231679052","rc":[{"batb":[[1,2.12,13.31],[2,1.74,18.17]],"ltp":2.42,"tv":205.12,"id":19144236}]}]}
{"op":"mcm","clk":"11820020557","pt":1723395891187,"mc":[{"id":"1.231679052","rc":[{"batb":[[2,1.31,1.13]],"ltp":1.71,"tv":4018.21,"id":19144241}]}]}
{"op":"mcm","clk":"11820021741","pt":1723395897181,"mc":[{"id":"1.231679052","rc":[{"batb":[[2,1.74,17.75]],"batl":[[1,25,0.81],[2,25,0]],"ltp":2.42,"tv":205.12,"id":19144236}]}]}
{"op":"mcm","clk":"11820023368","pt":1723395906213,"mc":[{"id":"1.231679052","rc":[{"trd":[[2.42,24.89]],"batb":[[0,2.42,20.57]],"ltp":2.42,"tv":206.03,"id":19144236},{"trd":[[1.71,39.55]],"ltp":1.71,"tv":4019.49,"id":19144241}],"tv":4225.52}]}
{"op":"mcm","clk":"11820024466","pt":1723395912153,"mc":[{"id":"1.231679052","rc":[{"batb":[[2,1.31,2.26]],"ltp":1.71,"tv":4019.49,"id":19144241}]}]}
{"op":"mcm","clk":"11820025354","pt":1723395917227,"mc":[{"id":"1.231679052","rc":[{"batb":[[2,1.74,18.18]],"batl":[[1,10,1.03],[2,25,0.13]],"ltp":2.42,"tv":206.03,"id":19144236}]}]}
{"op":"mcm","clk":"11820026895","pt":1723395926244,"mc":[{"id":"1.231679052","rc":[{"batb":[[0,1.59,2.19],[1,1.31,2.26],[2,1.26,5.03]],"batl":[[0,1.78,3.95]],"ltp":1.71,"tv":4019.49,"id":19144241}]}]}
{"op":"mcm","clk":"11820027020","pt":1723395926931,"mc":[{"id":"1.231679052","rc":[{"batb":[[1,1.74,18.18],[2,1.26,4.7]],"ltp":2.42,"tv":206.03,"id":19144236}]}]}
{"op":"mcm","clk":"11820027462","pt":1723395929322,"mc":[{"id":"1.231679052","rc":[{"batb":[[0,2.44,1.8],[1,2.42,20.57],[2,1.74,18.18]],"ltp":2.42,"tv":206.03,"id":19144236}]}]}
{"op":"mcm","clk":"11820027913","pt":1723395931851,"mc":[{"id":"1.231679052","rc":[{"batb":[[2,2.16,13.09]],"ltp":2.42,"tv":206.03,"id":19144236}]}]}
{"op":"mcm","clk":"11820028307","pt":1723395933966,"mc":[{"id":"1.231679052","rc":[{"trd":[[2.44,0.39]],"batb":[[0,2.44,1.41]],"ltp":2.44,"tv":206.42,"id":19144236},{"trd":[[1.7,9.41]],"batl":[[0,1.78,3.23]],"ltp":1.7,"tv":4021.5,"id":19144241}],"tv":4227.92}]}
{"op":"mcm","clk":"11820028396","pt":1723395934448,"mc":[{"id":"1.231679052","rc":[{"trd":[[2.46,7.72]],"batl":[[0,10,1.03],[1,25,0.13],[2,25,0]],"ltp":2.46,"tv":209.34,"id":19144236}],"tv":4230.84}]}
{"op":"mcm","clk":"11820029450","pt":1723395940434,"mc":[{"id":"1.231679052","rc":[{"batb":[[2,1.74,18.18]],"ltp":2.46,"tv":209.34,"id":19144236}]}]}
{"op":"mcm","clk":"11820030324","pt":1723395945373,"mc":[{"id":"1.231679052","rc":[{"batb":[[2,2.2,12.82]],"ltp":2.46,"tv":209.34,"id":19144236}]}]}
{"op":"mcm","clk":"11820030472","pt":1723395946162,"mc":[{"id":"1.231679052","rc":[{"batb":[[1,1.31,1.13]],"ltp":1.7,"tv":4021.5,"id":19144241}]}]}
{"op":"mcm","clk":"11820031514","pt":1723395952281,"mc":[{"id":"1.231679052","rc":[{"batl":[[0,25,0.81],[1,25,0]],"ltp":2.46,"tv":209.34,"id":19144236}]}]}
{"op":"mcm","clk":"11820031752","pt":1723395953548,"mc":[{"id":"1.231679052","rc":[{"batb":[[2,1.74,17.75]],"ltp":2.46,"tv":209.34,"id":19144236}]}]}
{"op":"mcm","clk":"11820032553","pt":1723395958443,"mc":[{"id":"1.231679052","rc":[{"batb":[[2,2.16,13.09]],"ltp":2.46,"tv":209.34,"id":19144236}]}]}
{"op":"mcm","clk":"11820032743","pt":1723395959495,"mc":[{"id":"1.231679052","rc":[{"batb":[[2,1.74,17.75]],"ltp":2.46,"tv":209.34,"id":19144236}]}]}
{"op":"mcm","clk":"11820033571","pt":1723395964478,"mc":[{"id":"1.231679052","rc":[{"batb":[[2,2.08,13.54]],"ltp":2.46,"tv":209.34,"id":19144236}]}]}
{"op":"mcm","clk":"11820034300","pt":1723395969188,"mc":[{"id":"1.231679052","rc":[{"batb":[[2,1.3,1.5]],"ltp":1.7,"tv":4021.5,"id":19144241}]}]}
{"op":"mcm","clk":"11820035181","pt":1723395974291,"mc":[{"id":"1.231679052","rc":[{"batl":[[0,10,1.03],[1,25,0.13]],"ltp":2.46,"tv":209.34,"id":19144236}]}]}
{"op":"mcm","clk":"11820035647","pt":1723395976769,"mc":[{"id":"1.231679052","rc":[{"batb":[[2,1.74,18.12]],"ltp":2.46,"tv":209.34,"id":19144236}]}]}
{"op":"mcm","clk":"11820036551","pt":1723395981778,"mc":[{"id":"1.231679052","rc":[{"batb":[[2,2.22,12.71]],"ltp":2.46,"tv":209.34,"id":19144236}]}]}
{"op":"mcm","clk":"11820036660","pt":1723395982412,"mc":[{"id":"1.231679052","rc":[{"trd":[[2.44,0.44]],"batb":[[0,2.44,1.36]],"ltp":2.44,"tv":209.39,"id":19144236},{"trd":[[1.7,9.48]],"ltp":1.7,"tv":4021.57,"id":19144241}],"tv":4230.96}]}
{"op":"mcm","clk":"11820041043","pt":1723396008724,"mc":[{"id":"1.231679052","rc":[{"batb":[[0,2.42,20.57],[1,2.22,12.71],[2,1.74,18.12]],"ltp":2.44,"tv":209.39,"id":19144236}]}]}
{"op":"mcm","clk":"11820041346","pt":1723396010845,"mc":[{"id":"1.231679052","rc":[{"batb":[[1,1.74,18.12],[2,1.26,4.7]],"ltp":2.44,"tv":209.39,"id":19144236}]}]}
{"op":"mcm","clk":"11820041877","pt":1723396014302,"mc":[{"id":"1.231679052","rc":[{"batl":[[0,2.44,1.35],[1,10,1.03],[2,25,0.13]],"ltp":2.44,"tv":209.39,"id":19144236},{"batb":[[1,1.3,1.5],[2,1.26,4.7]],"ltp":1.7,"tv":4021.57,"id":19144241}]}]}
{"op":"mcm","clk":"11820042117","pt":1723396015731,"mc":[{"id":"1.231679052","rc":[{"batb":[[1,2.18,12.98],[2,1.74,18.12]],"ltp":2.44,"tv":209.39,"id":19144236}]}]}
{"op":"mcm","clk":"11820042565","pt":1723396018646,"mc":[{"id":"1.231679052","rc":[{"batb":[[1,1.74,18.12],[2,1.26,4.7]],"ltp":2.44,"tv":209.39,"id":19144236}]}]}
{"op":"mcm","clk":"11820042751","pt":1723396019941,"mc":[{"id":"1.231679052","rc":[{"trd":[[2.44,3.14]],"batb":[[1,1.74,17.69]],"batl":[[0,25,0.81],[1,10,0],[2,25,0]],"ltp":2.44,"tv":212.09,"id":19144236}],"tv":4233.66}]}
{"op":"mcm","clk":"11820043895","pt":1723396026767,"mc":[{"id":"1.231679052","rc":[{"batb":[[1,2.08,13.54],[2,1.74,17.69]],"ltp":2.44,"tv":212.09,"id":19144236}]}]}
{"op":"mcm","clk":"11820044696","pt":1723396031362,"mc":[{"id":"1.231679052","rc":[{"batb":[[0,2.42,19.67]],"ltp":2.44,"tv":212.09,"id":19144236},{"batb":[[1,1.31,1.13],[2,1.3,1.5]],"ltp":1.7,"tv":4021.57,"id":19144241}]}]}
{"op":"mcm","clk":"11820045429","pt":1723396035784,"mc":[{"id":"1.231679052","rc":[{"batb":[[0,1.6,2.22],[1,1.59,2.19],[2,1.31,1.13]],"ltp":1.7,"tv":4021.57,"id":19144241}]}]}
{"op":"mcm","clk":"11820045594","pt":1723396036680,"mc":[{"id":"1.231679052","rc":[{"batb":[[2,1.74,18.06]],"batl":[[0,10,1.03],[1,25,0.13]],"ltp":2.44,"tv":212.09,"id":19144236}]}]}
{"op":"mcm","clk":"11820045914","pt":1723396038563,"mc":[{"id":"1.231679052","rc":[{"batb":[[1,1.74,18.06],[2,1.26,4.7]],"ltp":2.44,"tv":212.09,"id":19144236}]}]}
{"op":"mcm","clk":"11820046586","pt":1723396042389,"mc":[{"id":"1.231679052","rc":[{"trd":[[1.6,4.06]],"batb":[[0,1.59,2.52],[1,1.31,1.13],[2,1.3,1.5]],"ltp":1.6,"tv":4025.35,"id":19144241}],"tv":4237.44}]}
{"op":"mcm","clk":"11820048001","pt":1723396050093,"mc":[{"id":"1.231679052","rc":[{"batb":[[0,2.42,15.97],[1,2.12,13.31],[2,1.74,18.06]],"ltp":2.44,"tv":212.09,"id":19144236}]}]}
{"op":"mcm","clk":"11820048278","pt":1723396051576,"mc":[{"id":"1.231679052","rc":[{"batb":[[1,1.74,18.06],[2,1.26,4.7]],"ltp":2.44,"tv":212.09,"id":19144236}]}]}
{"op":"mcm","clk":"11820049116","pt":1723396056550,"mc":[{"id":"1.231679052","rc":[{"batb":[[1,2.08,13.54],[2,1.74,18.06]],"ltp":2.44,"tv":212.09,"id":19144236}]}]}
{"op":"mcm","clk":"11820050534","pt":1723396065096,"mc":[{"id":"1.231679052","rc":[{"batb":[[2,1.26,5.03]],"ltp":1.6,"tv":4025.35,"id":19144241}]}]}
{"op":"mcm","clk":"11820051051","pt":1723396067788,"mc":[{"id":"1.231679052","rc":[{"batb":[[0,1.61,7.21],[1,1.59,2.52],[2,1.31,1.13]],"ltp":1.6,"tv":4025.35,"id":19144241}]}]}
{"op":"mcm","clk":"11820051459","pt":1723396070067,"mc":[{"id":"1.231679052","rc":[{"batb":[[1,1.74,17.69],[2,1.26,4.7]],"batl":[[0,25,0.81],[1,25,0]],"ltp":2.44,"tv":212.09,"id":19144236}]}]}
{"op":"mcm","clk":"11820052279","pt":1723396075096,"mc":[{"id":"1.231679052","rc":[{"batb":[[1,2.16,13.04],[2,1.74,17.69]],"ltp":2.44,"tv":212.09,"id":19144236},{"trd":[[1.66,4.48]],"batb":[[0,1.66,14.99],[1,1.61,7.21],[2,1.59,2.52]],"ltp":1.66,"tv":4029.31,"id":19144241}],"tv":4241.4}]}
{"op":"mcm","clk":"11820052374","pt":1723396075628,"mc":[{"id":"1.231679052","rc":[{"batb":[[1,1.74,17.69],[2,1.26,4.7]],"ltp":2.44,"tv":212.09,"id":19144236},{"batb":[[0,1.61,7.21],[1,1.59,2.52],[2,1.31,1.13]],"ltp":1.66,"tv":4029.31,"id":19144241}]}]}
{"op":"mcm","clk":"11820054132","pt":1723396085418,"mc":[{"id":"1.231679052","rc":[{"batb":[[1,2.18,12.93],[2,1.74,17.69]],"ltp":2.44,"tv":212.09,"id":19144236},{"batb":[[0,1.65,17.08],[1,1.61,7.21],[2,1.59,2.52]],"ltp":1.66,"tv":4029.31,"id":19144241}]}]}
{"op":"mcm","clk":"11820054347","pt":1723396086524,"mc":[{"id":"1.231679052","rc":[{"batb":[[1,1.74,17.69],[2,1.26,4.7]],"ltp":2.44,"tv":212.09,"id":19144236},{"batb":[[0,1.61,7.21],[1,1.59,2.52],[2,1.31,1.13]],"ltp":1.66,"tv":4029.31,"id":19144241}]}]}
{"op":"mcm","clk":"11820055060","pt":1723396090298,"mc":[{"id":"1.231679052","rc":[{"batl":[[0,1000,1.16]],"ltp":2.44,"tv":212.09,"id":19144236},{"batb":[[2,1.31,2.26]],"ltp":1.66,"tv":4029.31,"id":19144241}]}]}
{"op":"mcm","clk":"11820055131","pt":1723396090718,"mc":[{"id":"1.231679052","rc":[{"batl":[[0,25,0.81]],"ltp":2.44,"tv":212.09,"id":19144236}]}]}
{"op":"mcm","clk":"11820056127","pt":1723396096043,"mc":[{"id":"1.231679052","rc":[{"batb":[[1,2.18,12.93],[2,1.74,18.07]],"batl":[[0,10,1.03],[1,25,0.13]],"ltp":2.44,"tv":212.09,"id":19144236},{"batb":[[0,1.65,17.08],[1,1.61,7.21],[2,1.59,2.52]],"ltp":1.66,"tv":4029.31,"id":19144241}]}]}
{"op":"mcm","clk":"11820056442","pt":1723396097243,"mc":[{"id":"1.231679052","rc":[{"batb":[[1,1.74,18.07],[2,1.26,4.7]],"ltp":2.44,"tv":212.09,"id":19144236},{"batb":[[0,1.61,7.21],[1,1.59,2.52],[2,1.31,2.26]],"ltp":1.66,"tv":4029.31,"id":19144241}]}]}
{"op":"mcm","clk":"11820057994","pt":1723396104333,"mc":[{"id":"1.231679052","rc":[{"trd":[[2.42,25.11]],"batb":[[0,2.42,15.75],[1,2.18,12.93],[2,1.74,18.07]],"ltp":2.42,"tv":212.31,"id":19144236},{"trd":[[1.71,39.87]],"batb":[[0,1.65,17.08],[1,1.61,7.21],[2,1.59,2.52]],"ltp":1.71,"tv":4029.63,"id":19144241}],"tv":4241.94}]}
{"op":"mcm","clk":"11820058089","pt":1723396104960,"mc":[{"id":"1.231679052","rc":[{"batb":[[1,1.74,18.07],[2,1.26,4.7]],"ltp":2.42,"tv":212.31,"id":19144236},{"batb":[[0,1.61,7.21],[1,1.59,2.52],[2,1.31,2.26]],"ltp":1.71,"tv":4029.63,"id":19144241}]}]}
{"op":"mcm","clk":"11820058822","pt":1723396109020,"mc":[{"id":"1.231679052","rc":[{"batb":[[1,1.59,2.19]],"ltp":1.71,"tv":4029.63,"id":19144241}]}]}
{"op":"mcm","clk":"11820059190","pt":1723396111012,"mc":[{"id":"1.231679052","rc":[{"batb":[[1,2.18,12.93],[2,1.74,18.07]],"ltp":2.42,"tv":212.31,"id":19144236},{"batb":[[0,1.65,17.08],[1,1.61,7.21],[2,1.59,2.19]],"ltp":1.71,"tv":4029.63,"id":19144241}]}]}
{"op":"mcm","clk":"11820059354","pt":1723396111949,"mc":[{"id":"1.231679052","rc":[{"batb":[[1,1.74,18.07],[2,1.26,4.7]],"ltp":2.42,"tv":212.31,"id":19144236},{"batb":[[0,1.61,7.21],[1,1.59,2.19],[2,1.31,2.26]],"ltp":1.71,"tv":4029.63,"id":19144241}]}]}
{"op":"mcm","clk":"11820060458","pt":1723396118432,"mc":[{"id":"1.231679052","rc":[{"batb":[[1,2.18,12.93],[2,1.74,18.07]],"ltp":2.42,"tv":212.31,"id":19144236},{"batb":[[0,1.65,17.08],[1,1.61,7.21],[2,1.59,2.19]],"ltp":1.71,"tv":4029.63,"id":19144241}]}]}
{"op":"mcm","clk":"11820060707","pt":1723396119951,"mc":[{"id":"1.231679052","rc":[{"batb":[[1,1.74,18.07],[2,1.26,4.7]],"ltp":2.42,"tv":212.31,"id":19144236},{"batb":[[0,1.61,7.21],[1,1.59,2.19],[2,1.31,2.26]],"ltp":1.71,"tv":4029.63,"id":19144241}]}]}
{"op":"mcm","clk":"11820061839","pt":1723396126254,"mc":[{"id":"1.231679052","rc":[{"batb":[[1,2.18,12.93],[2,1.74,18.07]],"ltp":2.42,"tv":212.31,"id":19144236},{"batb":[[0,1.65,17.08],[1,1.61,7.21],[2,1.59,2.19]],"ltp":1.71,"tv":4029.63,"id":19144241}]}]}
{"op":"mcm","clk":"11820062238","pt":1723396128781,"mc":[{"id":"1.231679052","rc":[{"batb":[[1,1.74,18.07],[2,1.26,4.7]],"ltp":2.42,"tv":212.31,"id":19144236},{"batb":[[0,1.61,7.21],[1,1.59,2.19],[2,1.31,2.26]],"ltp":1.71,"tv":4029.63,"id":19144241}]}]}
{"op":"mcm","clk":"11820062669","pt":1723396131098,"mc":[{"id":"1.231679052","rc":[{"batb":[[2,1.31,1.13]],"ltp":1.71,"tv":4029.63,"id":19144241}]}]}
{"op":"mcm","clk":"11820063382","pt":1723396135249,"mc":[{"id":"1.231679052","rc":[{"batb":[[1,2.18,12.93],[2,1.74,18.07]],"ltp":2.42,"tv":212.31,"id":19144236},{"batb":[[0,1.65,17.08],[1,1.61,7.21],[2,1.59,2.19]],"batl":[[0,1.7,1.88],[1,1.78,3.23],[2,1.87,13.82]],"ltp":1.71,"tv":4029.63,"id":19144241}]}]}
{"op":"mcm","clk":"11820063747","pt":1723396137359,"mc":[{"id":"1.231679052","rc":[{"batl":[[0,25,0.81],[1,25,0]],"ltp":2.42,"tv":212.31,"id":19144236}]}]}
{"op":"mcm","clk":"11820063840","pt":1723396137877,"mc":[{"id":"1.231679052","rc":[{"batb":[[1,1.74,17.7],[2,1.26,4.7]],"ltp":2.42,"tv":212.31,"id":19144236},{"batb":[[0,1.61,7.21],[1,1.59,2.19],[2,1.31,1.13]],"ltp":1.71,"tv":4029.63,"id":19144241}]}]}
{"op":"mcm","clk":"11820064940","pt":1723396144250,"mc":[{"id":"1.231679052","rc":[{"batb":[[1,2.18,12.93],[2,1.74,17.7]],"ltp":2.42,"tv":212.31,"id":19144236},{"batb":[[0,1.65,17.08],[1,1.61,7.21],[2,1.59,2.19]],"ltp":1.71,"tv":4029.63,"id":19144241}]}]}
{"op":"mcm","clk":"11820065279","pt":1723396146376,"mc":[{"id":"1.231679052","rc":[{"batb":[[1,1.74,17.7],[2,1.26,4.7]],"ltp":2.42,"tv":212.31,"id":19144236},{"batb":[[0,1.61,7.21],[1,1.59,2.19],[2,1.31,1.13]],"ltp":1.71,"tv":4029.63,"id":19144241}]}]}
{"op":"mcm","clk":"11820066321","pt":1723396152388,"mc":[{"id":"1.231679052","rc":[{"batl":[[0,2.52,2.37],[1,25,0.81]],"ltp":2.42,"tv":212.31,"id":19144236}]}]}
{"op":"mcm","clk":"11820066337","pt":1723396152448,"mc":[{"id":"1.231679052","rc":[{"batb":[[1,2.18,12.98],[2,1.74,17.7]],"ltp":2.42,"tv":212.31,"id":19144236},{"batb":[[0,1.66,17.04],[1,1.61,7.21],[2,1.59,2.19]],"ltp":1.71,"tv":4029.63,"id":19144241}]}]}
{"op":"mcm","clk":"11820066595","pt":1723396153877,"mc":[{"id":"1.231679052","rc":[{"batb":[[1,1.74,17.7],[2,1.26,4.7]],"ltp":2.42,"tv":212.31,"id":19144236},{"trd":[[1.7,11.45]],"batb":[[0,1.61,7.21],[1,1.59,2.19],[2,1.31,1.13]],"batl":[[0,1.78,4.13],[1,1.87,13.82],[2,1.88,25.76]],"ltp":1.7,"tv":4031.59,"id":19144241}],"tv":4243.9}]}
{"op":"mcm","clk":"11820066824","pt":1723396155198,"mc":[{"id":"1.231679052","rc":[{"batl":[[1,10,1.03],[2,25,0.13]],"ltp":2.42,"tv":212.31,"id":19144236}]}]}
{"op":"mcm","clk":"11820066866","pt":1723396155396,"mc":[{"id":"1.231679052","rc":[{"batb":[[1,1.74,18.1]],"ltp":2.42,"tv":212.31,"id":19144236}]}]}
{"op":"mcm","clk":"11820067695","pt":1723396160077,"mc":[{"id":"1.231679052","rc":[{"batb":[[1,2.18,12.93],[2,1.74,18.1]],"batl":[[0,10,1.03],[1,25,0.13],[2,25,0]],"ltp":2.42,"tv":212.31,"id":19144236}]}]}
{"op":"mcm","clk":"11820068550","pt":1723396164882,"mc":[{"id":"1.231679052","rc":[{"batl":[[0,2.5,2.37],[1,10,1.03],[2,25,0.13]],"ltp":2.42,"tv":212.31,"id":19144236}]}]}
{"op":"mcm","clk":"11820068889","pt":1723396166790,"mc":[{"id":"1.231679052","rc":[{"batb":[[0,1.65,17.15],[1,1.61,7.21],[2,1.59,2.19]],"ltp":1.7,"tv":4031.59,"id":19144241}]}]}
{"op":"mcm","clk":"11820069013","pt":1723396167517,"mc":[{"id":"1.231679052","rc":[{"batb":[[0,1.61,7.21],[1,1.59,2.19],[2,1.31,1.13]],"ltp":1.7,"tv":4031.59,"id":19144241}]}]}
{"op":"mcm","clk":"11820069950","pt":1723396172695,"mc":[{"id":"1.231679052","rc":[{"trd":[[2.5,1.2]],"batl":[[0,2.5,1.18]],"ltp":2.5,"tv":213.5,"id":19144236},{"trd":[[1.66,6.28]],"ltp":1.66,"tv":4033.39,"id":19144241}],"tv":4246.9}]}
{"op":"mcm","clk":"11820070675","pt":1723396176813,"mc":[{"id":"1.231679052","rc":[{"batl":[[0,10,1.03],[1,25,0.13],[2,25,0]],"ltp":2.5,"tv":213.5,"id":19144236}]}]}
{"op":"mcm","clk":"11820071090","pt":1723396179293,"mc":[{"id":"1.231679052","rc":[{"batb":[[0,1.65,17.08],[1,1.61,7.21],[2,1.59,2.19]],"ltp":1.66,"tv":4033.39,"id":19144241}]}]}
{"op":"mcm","clk":"11820071477","pt":1723396181599,"mc":[{"id":"1.231679052","rc":[{"batb":[[1,1.74,18.1],[2,1.26,4.7]],"ltp":2.5,"tv":213.5,"id":19144236},{"batb":[[0,1.61,7.21],[1,1.59,2.19],[2,1.31,1.13]],"ltp":1.66,"tv":4033.39,"id":19144241}]}]}
{"op":"mcm","clk":"11820072294","pt":1723396186406,"mc":[{"id":"1.231679052","rc":[{"batl":[[0,1.66,1.35],[1,1.78,4.13],[2,1.87,13.82]],"ltp":1.66,"tv":4033.39,"id":19144241}]}]}
{"op":"mcm","clk":"11820072549","pt":1723396188033,"mc":[{"id":"1.231679052","rc":[{"batb":[[1,2.18,12.93],[2,1.74,18.1]],"ltp":2.5,"tv":213.5,"id":19144236},{"batb":[[0,1.65,17.08],[1,1.61,7.21],[2,1.59,2.19]],"ltp":1.66,"tv":4033.39,"id":19144241}]}]}
{"op":"mcm","clk":"11820072668","pt":1723396188716,"mc":[{"id":"1.231679052","rc":[{"batb":[[1,1.74,18.1],[2,1.26,4.7]],"ltp":2.5,"tv":213.5,"id":19144236},{"batb":[[0,1.61,7.21],[1,1.59,2.19],[2,1.31,1.13]],"ltp":1.66,"tv":4033.39,"id":19144241}]}]}
{"op":"mcm","clk":"11820072921","pt":1723396190305,"mc":[{"id":"1.231679052","rc":[{"batb":[[2,1.3,1.5]],"ltp":1.66,"tv":4033.39,"id":19144241}]}]}
{"op":"mcm","clk":"11820073077","pt":1723396191243,"mc":[{"id":"1.231679052","rc":[{"batl":[[0,1.78,4.13],[1,1.87,13.82],[2,1.88,25.76]],"ltp":1.66,"tv":4033.39,"id":19144241}]}]}
{"op":"mcm","clk":"11820073773","pt":1723396195341,"mc":[{"id":"1.231679052","rc":[{"batb":[[1,2.2,12.82],[2,1.74,18.1]],"ltp":2.5,"tv":213.5,"id":19144236},{"batb":[[0,1.64,17.2],[1,1.61,7.21],[2,1.59,2.19]],"ltp":1.66,"tv":4033.39,"id":19144241}]}]}
{"op":"mcm","clk":"11820073945","pt":1723396196344,"mc":[{"id":"1.231679052","rc":[{"batb":[[1,1.74,17.72],[2,1.26,4.7]],"batl":[[0,25,0.81],[1,25,0]],"ltp":2.5,"tv":213.5,"id":19144236},{"batb":[[0,1.61,7.21],[1,1.59,2.19],[2,1.3,1.5]],"ltp":1.66,"tv":4033.39,"id":19144241}]}]}
{"op":"mcm","clk":"11820074452","pt":1723396199348,"mc":[{"id":"1.231679052","rc":[{"trd":[[1.61,7.48]],"batb":[[0,1.61,3.47]],"ltp":1.61,"tv":4040.87,"id":19144241}],"tv":4254.38}]}
{"op":"mcm","clk":"11820075062","pt":1723396202859,"mc":[{"id":"1.231679052","rc":[{"batb":[[1,2.18,12.93],[2,1.74,17.72]],"ltp":2.5,"tv":213.5,"id":19144236},{"batb":[[0,1.65,17.08],[1,1.61,3.47],[2,1.59,2.19]],"ltp":1.61,"tv":4040.87,"id":19144241}]}]}
{"op":"mcm","clk":"11820075308","pt":1723396204238,"mc":[{"id":"1.231679052","rc":[{"batb":[[1,1.74,17.72],[2,1.26,4.7]],"ltp":2.5,"tv":213.5,"id":19144236},{"batb":[[0,1.61,3.47],[1,1.59,2.19],[2,1.3,1.5]],"ltp":1.61,"tv":4040.87,"id":19144241}]}]}
{"op":"mcm","clk":"11820075466","pt":1723396205128,"mc":[{"id":"1.231679052","rc":[{"batb":[[0,1.61,2.12]],"ltp":1.61,"tv":4040.87,"id":19144241}]}]}
{"op":"mcm","clk":"11820076395","pt":1723396210958,"mc":[{"id":"1.231679052","rc":[{"batb":[[1,2.12,13.27],[2,1.74,17.72]],"ltp":2.5,"tv":213.5,"id":19144236},{"batb":[[2,1.31,1.13]],"ltp":1.61,"tv":4040.87,"id":19144241}]}]}
{"op":"mcm","clk":"11820076576","pt":1723396212023,"mc":[{"id":"1.231679052","rc":[{"batb":[[1,1.74,17.72],[2,1.26,4.7]],"ltp":2.5,"tv":213.5,"id":19144236}]}]}
{"op":"mcm","clk":"11820077193","pt":1723396216074,"mc":[{"id":"1.231679052","rc":[{"batb":[[1,1.74,18.1]],"batl":[[0,10,1.03],[1,25,0.13]],"ltp":2.5,"tv":213.5,"id":19144236}]}]}
{"op":"mcm","clk":"11820079428","pt":1723396228784,"mc":[{"id":"1.231679052","rc":[{"batl":[[0,1.7,5.41],[1,1.78,3.23],[2,1.87,13.82]],"ltp":1.61,"tv":4040.87,"id":19144241}]}]}
{"op":"mcm","clk":"11820080664","pt":1723396236166,"mc":[{"id":"1.231679052","rc":[{"batb":[[1,2.14,13.16],[2,1.74,18.1]],"ltp":2.5,"tv":213.5,"id":19144236}]}]}
{"op":"mcm","clk":"11820083316","pt":1723396251988,"mc":[{"id":"1.231679052","rc":[{"batl":[[0,1.7,5.28]],"ltp":1.61,"tv":4040.87,"id":19144241}]}]}
{"op":"mcm","clk":"11820083686","pt":1723396254199,"mc":[{"id":"1.231679052","rc":[{"batb":[[2,1.74,17.7]],"batl":[[0,25,0.81],[1,25,0]],"ltp":2.5,"tv":213.5,"id":19144236}]}]}
{"op":"mcm","clk":"11820085761","pt":1723396266489,"mc":[{"id":"1.231679052","rc":[{"batb":[[0,2.14,13.16],[1,1.74,17.7],[2,1.26,4.7]],"ltp":2.5,"tv":213.5,"id":19144236}]}]}
{"op":"mcm","clk":"11820086316","pt":1723396269724,"mc":[{"id":"1.231679052","rc":[{"batb":[[0,1.74,17.7],[1,1.26,4.7],[2,1.1,10024.22]],"ltp":2.5,"tv":213.5,"id":19144236}]}]}
{"op":"mcm","clk":"11820087106","pt":1723396274330,"mc":[{"id":"1.231679052","rc":[{"batb":[[0,1.74,18.08]],"batl":[[0,10,1.03],[1,25,0.13]],"ltp":2.5,"tv":213.5,"id":19144236}]}]}
{"op":"mcm","clk":"11820092996","pt":1723396308988,"mc":[{"id":"1.231679052","rc":[{"batl":[[0,10,1.07]],"ltp":2.5,"tv":213.5,"id":19144236}]}]}
{"op":"mcm","clk":"11820093806","pt":1723396313766,"mc":[{"id":"1.231679052","rc":[{"batb":[[2,1.3,1.5]],"ltp":1.61,"tv":4040.87,"id":19144241}]}]}
{"op":"mcm","clk":"11820094733","pt":1723396319178,"mc":[{"id":"1.231679052","rc":[{"batl":[[0,25,0.86],[1,25,0]],"ltp":2.5,"tv":213.5,"id":19144236}]}]}
{"op":"mcm","clk":"11820094821","pt":1723396319801,"mc":[{"id":"1.231679052","rc":[{"batb":[[0,1.74,17.7]],"ltp":2.5,"tv":213.5,"id":19144236}]}]}
{"op":"mcm","clk":"11820097453","pt":1723396334209,"mc":[{"id":"1.231679052","rc":[{"batb":[[2,1.3,2.67]],"ltp":1.61,"tv":4040.87,"id":19144241}]}]}
{"op":"mcm","clk":"11820098367","pt":1723396339321,"mc":[{"id":"1.231679052","rc":[{"batl":[[0,10,1.07],[1,25,0.13]],"ltp":2.5,"tv":213.5,"id":19144236}]}]}
{"op":"mcm","clk":"11820098405","pt":1723396339493,"mc":[{"id":"1.231679052","rc":[{"batb":[[0,1.74,18.08]],"ltp":2.5,"tv":213.5,"id":19144236}]}]}
{"op":"mcm","clk":"11820101029","pt":1723396353891,"mc":[{"id":"1.231679052","rc":[{"batl":[[0,1.7,4.69]],"ltp":1.61,"tv":4040.87,"id":19144241}]}]}
{"op":"mcm","clk":"11820103265","pt":1723396365994,"mc":[{"id":"1.231679052","rc":[{"batl":[[1,1.78,3.3]],"ltp":1.61,"tv":4040.87,"id":19144241}]}]}
{"op":"mcm","clk":"11820103757","pt":1723396368790,"mc":[{"id":"1.231679052","rc":[{"batb":[[2,1.3,1.5]],"ltp":1.61,"tv":4040.87,"id":19144241}]}]}
{"op":"mcm","clk":"11820104044","pt":1723396370471,"mc":[{"id":"1.231679052","rc":[{"batl":[[0,1.7,4.56]],"ltp":1.61,"tv":4040.87,"id":19144241}]}]}
{"op":"mcm","clk":"11820104689","pt":1723396374207,"mc":[{"id":"1.231679052","rc":[{"batl":[[0,25,0.86],[1,25,0]],"ltp":2.5,"tv":213.5,"id":19144236}]}]}
{"op":"mcm","clk":"11820104781","pt":1723396374707,"mc":[{"id":"1.231679052","rc":[{"batb":[[0,1.74,17.7]],"ltp":2.5,"tv":213.5,"id":19144236}]}]}
{"op":"mcm","clk":"11820107891","pt":1723396392205,"mc":[{"id":"1.231679052","rc":[{"batb":[[2,1.3,2.67]],"ltp":1.61,"tv":4040.87,"id":19144241}]}]}
{"op":"mcm","clk":"11820108781","pt":1723396397028,"mc":[{"id":"1.231679052","rc":[{"batb":[[0,1.74,18.08]],"batl":[[0,10,1.07],[1,25,0.13]],"ltp":2.5,"tv":213.5,"id":19144236}]}]}
{"op":"mcm","clk":"11820109262","pt":1723396399618,"mc":[{"id":"1.231679052","rc":[{"batl":[[0,1.64,1],[1,1.7,4.56],[2,1.78,3.3]],"ltp":1.61,"tv":4040.87,"id":19144241}]}]}
{"op":"mcm","clk":"11820111582","pt":1723396412342,"mc":[{"id":"1.231679052","rc":[{"trd":[[1.64,66.35]],"batb":[[0,1.61,2.23]],"batl":[[0,1.7,4.56],[1,1.78,3.3],[2,1.87,13.82]],"ltp":1.64,"tv":4042.87,"id":19144241}],"tv":4256.38}]}
{"op":"mcm","clk":"11820112005","pt":1723396414614,"mc":[{"id":"1.231679052","rc":[{"batb":[[0,1.64,1.4],[1,1.61,2.12],[2,1.59,2.19]],"ltp":1.64,"tv":4042.87,"id":19144241}]}]}
{"op":"mcm","clk":"11820116345","pt":1723396437974,"mc":[{"id":"1.231679052","rc":[{"batl":[[0,1.78,3.35],[1,1.87,13.82],[2,1.88,25.76]],"ltp":1.64,"tv":4042.87,"id":19144241}]}]}
{"op":"mcm","clk":"11820117160","pt":1723396442259,"mc":[{"id":"1.231679052","rc":[{"batb":[[0,1.74,17.7]],"batl":[[0,25,0.86],[1,25,0]],"ltp":2.5,"tv":213.5,"id":19144236}]}]}
{"op":"mcm","clk":"11820117954","pt":1723396446156,"mc":[{"id":"1.231679052","rc":[{"batb":[[0,2.1,13.43],[1,1.74,17.7],[2,1.26,4.7]],"ltp":2.5,"tv":213.5,"id":19144236}]}]}
{"op":"mcm","clk":"11820119217","pt":1723396452738,"mc":[{"id":"1.231679052","rc":[{"batb":[[0,1.74,17.7],[1,1.26,4.7],[2,1.1,10024.22]],"ltp":2.5,"tv":213.5,"id":19144236}]}]}
{"op":"mcm","clk":"11820120045","pt":1723396457482,"mc":[{"id":"1.231679052","rc":[{"batb":[[0,2.14,13.2],[1,1.74,17.7],[2,1.26,4.7]],"ltp":2.5,"tv":213.5,"id":19144236}]}]}
{"op":"mcm","clk":"11820120365","pt":1723396459269,"mc":[{"id":"1.231679052","rc":[{"batb":[[1,1.74,18.08]],"batl":[[0,10,1.07],[1,25,0.13]],"ltp":2.5,"tv":213.5,"id":19144236}]}]}
{"op":"mcm","clk":"11820120875","pt":1723396462181,"mc":[{"id":"1.231679052","rc":[{"batb":[[0,1.61,2.23],[1,1.59,2.19],[2,1.3,2.42]],"ltp":1.64,"tv":4042.87,"id":19144241}]}]}
{"op":"mcm","clk":"11820123229","pt":1723396476195,"mc":[{"id":"1.231679052","rc":[{"batl":[[0,1.76,2.34],[1,1.78,3.23],[2,1.87,13.82]],"ltp":1.64,"tv":4042.87,"id":19144241}]}]}
{"op":"mcm","clk":"11820123313","pt":1723396476670,"mc":[{"id":"1.231679052","rc":[{"batl":[[1,1.77,11],[2,1.78,3.23]],"ltp":1.64,"tv":4042.87,"id":19144241}]}]}
{"op":"mcm","clk":"11820125081","pt":1723396487382,"mc":[{"id":"1.231679052","rc":[{"batb":[[2,1.3,1.25]],"ltp":1.64,"tv":4042.87,"id":19144241}]}]}
{"op":"mcm","clk":"11820125848","pt":1723396492098,"mc":[{"id":"1.231679052","rc":[{"batl":[[0,25,0.86],[1,25,0]],"ltp":2.5,"tv":213.5,"id":19144236}]}]}
{"op":"mcm","clk":"11820125897","pt":1723396492410,"mc":[{"id":"1.231679052","rc":[{"batb":[[1,1.74,17.7]],"ltp":2.5,"tv":213.5,"id":19144236}]}]}
{"op":"mcm","clk":"11820130326","pt":1723396518067,"mc":[{"id":"1.231679052","rc":[{"batb":[[1,1.74,18.08]],"batl":[[0,10,1.07],[1,25,0.13]],"ltp":2.5,"tv":213.5,"id":19144236},{"batb":[[2,1.36,1.89]],"ltp":1.64,"tv":4042.87,"id":19144241}]}]}
{"op":"mcm","clk":"11820131263","pt":1723396523188,"mc":[{"id":"1.231679052","rc":[{"batb":[[0,1.62,6.11],[1,1.61,2.12],[2,1.59,2.19]],"ltp":1.64,"tv":4042.87,"id":19144241}]}]}
{"op":"mcm","clk":"11820132319","pt":1723396529192,"mc":[{"id":"1.231679052","rc":[{"batb":[[0,1.66,16.97],[1,1.62,6.11],[2,1.61,2.12]],"ltp":1.64,"tv":4042.87,"id":19144241}]}]}
{"op":"mcm","clk":"11820132500","pt":1723396530285,"mc":[{"id":"1.231679052","rc":[{"batb":[[0,1.74,18.08],[1,1.26,4.7],[2,1.1,10024.22]],"ltp":2.5,"tv":213.5,"id":19144236},{"batb":[[0,1.62,6.11],[1,1.61,2.12],[2,1.59,2.19]],"ltp":1.64,"tv":4042.87,"id":19144241}]}]}
{"op":"mcm","clk":"11820133403","pt":1723396535661,"mc":[{"id":"1.231679052","rc":[{"batl":[[0,1.74,2.83],[1,1.76,2.22],[2,1.77,11]],"ltp":1.64,"tv":4042.87,"id":19144241}]}]}
{"op":"mcm","clk":"11820137488","pt":1723396561291,"mc":[{"id":"1.231679052","rc":[{"batl":[[0,25,0.86],[1,25,0]],"ltp":2.5,"tv":213.5,"id":19144236}]}]}
{"op":"mcm","clk":"11820137516","pt":1723396561457,"mc":[{"id":"1.231679052","rc":[{"batb":[[0,1.74,17.7]],"ltp":2.5,"tv":213.5,"id":19144236}]}]}
{"op":"mcm","clk":"11820139856","pt":1723396575091,"mc":[{"id":"1.231679052","rc":[{"batl":[[0,1.74,2.76]],"ltp":1.64,"tv":4042.87,"id":19144241}]}]}
{"op":"mcm","clk":"11820140401","pt":1723396578212,"mc":[{"id":"1.231679052","rc":[{"batb":[[0,1.74,18.08]],"batl":[[0,10,1.07],[1,25,0.13]],"ltp":2.5,"tv":213.5,"id":19144236}]}]}
{"op":"mcm","clk":"11820141374","pt":1723396583502,"mc":[{"id":"1.231679052","rc":[{"batl":[[0,10,1.03]],"ltp":2.5,"tv":213.5,"id":19144236}]}]}
{"op":"mcm","clk":"11820146689","pt":1723396614628,"mc":[{"id":"1.231679052","rc":[{"trd":[[2.28,41.11],[2.3,6.89],[2.34,2.02],[2.42,25.15]],"ltp":2.28,"tv":222.21,"id":19144236},{"trd":[[1.7,11.5],[1.74,37.35],[1.76,83.46],[1.77,22.3]],"batl":[[0,1.77,4.6],[1,1.78,3.23],[2,1.87,13.82]],"ltp":1.77,"tv":4054.25,"id":19144241}],"tv":4276.47}]}
{"op":"mcm","clk":"11820147402","pt":1723396618319,"mc":[{"id":"1.231679052","rc":[{"batb":[[0,1.74,17.7]],"batl":[[0,25,0.81],[1,25,0]],"ltp":2.28,"tv":222.21,"id":19144236}]}]}
{"op":"mcm","clk":"11820148125","pt":1723396622739,"mc":[{"id":"1.231679052","rc":[{"batb":[[0,2.16,13.09],[1,1.74,17.7],[2,1.26,4.7]],"ltp":2.28,"tv":222.21,"id":19144236},{"batb":[[0,1.67,16.93],[1,1.62,6.11],[2,1.61,2.12]],"ltp":1.77,"tv":4054.25,"id":19144241}]}]}
{"op":"mcm","clk":"11820149962","pt":1723396633060,"mc":[{"id":"1.231679052","rc":[{"batb":[[1,1.61,2.23],[2,1.59,2.19]],"batl":[[0,1.78,3.23],[1,1.87,13.82],[2,1.88,25.76]],"ltp":1.77,"tv":4054.25,"id":19144241}]}]}
{"op":"mcm","clk":"11820151060","pt":1723396639298,"mc":[{"id":"1.231679052","rc":[{"batb":[[1,1.74,18.11]],"batl":[[0,10,1.03],[1,25,0.13]],"ltp":2.28,"tv":222.21,"id":19144236}]}]}
{"op":"mcm","clk":"11820151092","pt":1723396639512,"mc":[{"id":"1.231679052","rc":[{"batb":[[0,1.74,18.11],[1,1.26,4.7],[2,1.1,10024.22]],"ltp":2.28,"tv":222.21,"id":19144236}]}]}
{"op":"mcm","clk":"11820151809","pt":1723396644121,"mc":[{"id":"1.231679052","rc":[{"batb":[[0,1.61,2.23],[1,1.59,2.19],[2,1.34,1.98]],"ltp":1.77,"tv":4054.25,"id":19144241}]}]}
{"op":"mcm","clk":"11820151876","pt":1723396644486,"mc":[{"id":"1.231679052","rc":[{"batb":[[0,2.12,13.27],[1,1.74,18.11],[2,1.26,4.7]],"ltp":2.28,"tv":222.21,"id":19144236}]}]}
{"op":"mcm","clk":"11820152807","pt":1723396649793,"mc":[{"id":"1.231679052","rc":[{"batb":[[0,1.74,18.11],[1,1.26,4.7],[2,1.1,10024.22]],"ltp":2.28,"tv":222.21,"id":19144236}]}]}
{"op":"mcm","clk":"11820156143","pt":1723396669740,"mc":[{"id":"1.231679052","rc":[{"batb":[[0,1.62,6.61],[1,1.61,2.12],[2,1.59,2.19]],"ltp":1.77,"tv":4054.25,"id":19144241}]}]}
{"op":"mcm","clk":"11820157590","pt":1723396679158,"mc":[{"id":"1.231679052","rc":[{"batb":[[0,1.74,17.73]],"batl":[[0,25,0.81],[1,25,0]],"ltp":2.28,"tv":222.21,"id":19144236}]}]}
{"op":"mcm","clk":"11820160989","pt":1723396698740,"mc":[{"id":"1.231679052","rc":[{"batb":[[0,1.74,18.11]],"batl":[[0,10,1.03],[1,25,0.13]],"ltp":2.28,"tv":222.21,"id":19144236}]}]}
{"op":"mcm","clk":"11820167846","pt":1723396739315,"mc":[{"id":"1.231679052","rc":[{"batl":[[0,25,0.81],[1,25,0]],"ltp":2.28,"tv":222.21,"id":19144236}]}]}
{"op":"mcm","clk":"11820167952","pt":1723396739946,"mc":[{"id":"1.231679052","rc":[{"batb":[[0,1.74,17.7]],"ltp":2.28,"tv":222.21,"id":19144236}]}]}
{"op":"mcm","clk":"11820171298","pt":1723396759657,"mc":[{"id":"1.231679052","rc":[{"batb":[[0,1.74,18.08]],"batl":[[0,10,1.03],[1,25,0.13]],"ltp":2.28,"tv":222.21,"id":19144236}]}]}
{"op":"mcm","clk":"11820172000","pt":1723396764131,"mc":[{"id":"1.231679052","rc":[{"trd":[[1.62,8.8]],"batb":[[0,1.62,5.81]],"ltp":1.62,"tv":4055.63,"id":19144241}],"tv":4277.85}]}
{"op":"mcm","clk":"11820172329","pt":1723396766452,"mc":[{"id":"1.231679052","rc":[{"batb":[[0,2.6,2.14],[1,1.74,18.08],[2,1.26,4.7]],"ltp":2.28,"tv":222.21,"id":19144236}]}]}
