{"op":"mcm","clk":"11808847824","pt":1723190510349,"mc":[{"id":"1.231613187","marketDefinition":{"bspMarket":false,"turnInPlayEnabled":true,"persistenceEnabled":true,"marketBaseRate":5.0,"eventId":"33480112","eventTypeId":"4","numberOfWinners":1,"bettingType":"ODDS","marketType":"MATCH_ODDS","marketTime":"2024-08-11T09:00:00.000Z","suspendTime":"2024-08-11T09:00:00.000Z","bspReconciled":false,"complete":true,"inPlay":false,"crossMatching":false,"runnersVoidable":false,"numberOfActiveRunners":2,"betDelay":0,"status":"OPEN","runners":[{"status":"ACTIVE","sortPriority":1,"id":12482925,"name":"Scotland Women"},{"status":"ACTIVE","sortPriority":2,"id":12474498,"name":"Papua New Guinea Women"}],"regulators":["MR_INT"],"countryCode":"GB","discountAllowed":false,"timezone":"GMT","openDate":"2024-08-11T09:00:00.000Z","version":6062838754,"name":"Match Odds","eventName":"Scotland Women v Papua New Guinea Women"},"rc":[{"batb":[[0,1.03,200],[1,1.02,200],[2,1.01,220]],"ltp":0.0,"tv":0.0,"id":12474498},{"batb":[[0,1.03,200],[1,1.02,200],[2,1.01,220]],"ltp":0.0,"tv":0.0,"id":12482925}]}]}
{"op":"mcm","clk":"11808847881","pt":1723190511844,"mc":[{"id":"1.231613187","marketDefinition":{"bspMarket":false,"turnInPlayEnabled":true,"persistenceEnabled":true,"marketBaseRate":5.0,"eventId":"33480112","eventTypeId":"4","numberOfWinners":1,"bettingType":"ODDS","marketType":"MATCH_ODDS","marketTime":"2024-08-11T09:00:00.000Z","suspendTime":"2024-08-11T09:00:00.000Z","bspReconciled":false,"complete":true,"inPlay":false,"crossMatching":false,"runnersVoidable":false,"numberOfActiveRunners":2,"betDelay":0,"status":"OPEN","runners":[{"status":"ACTIVE","sortPriority":1,"id":12482925,"name":"Scotland Women"},{"status":"ACTIVE","sortPriority":2,"id":12474498,"name":"Papua New Guinea Women"}],"regulators":["MR_INT"],"countryCode":"GB","discountAllowed":true,"timezone":"GMT","openDate":"2024-08-11T09:00:00.000Z","version":6062838754,"name":"Match Odds","eventName":"Scotland Women v Papua New Guinea Women"}}]}
{"op":"mcm","clk":"11808853132","pt":1723190615782,"mc":[{"id":"1.231613187","rc":[{"batb":[[0,1.03,2359.85],[1,1.02,3389.29],[2,1.01,6411.17]],"ltp":0.0,"tv":0.0,"id":12482925}]}]}
{"op":"mcm","clk":"11808853173","pt":1723190616247,"mc":[{"id":"1.231613187","rc":[{"batb":[[0,1.04,1631.87],[1,1.03,2359.85],[2,1.02,3389.29]],"ltp":0.0,"tv":0.0,"id":12474498},{"batb":[[0,1.04,1631.87],[1,1.03,2359.85],[2,1.02,3389.29]],"ltp":0.0,"tv":0.0,"id":12482925}]}]}
{"op":"mcm","clk":"11808907293","pt":1723191619968,"mc":[{"id":"1.231613187","rc":[{"batb":[[0,1.05,100],[1,1.04,1631.87],[2,1.03,2359.85]],"ltp":0.0,"tv":0.0,"id":12474498},{"batb":[[0,1.05,100],[1,1.04,1631.87],[2,1.03,2359.85]],"ltp":0.0,"tv":0.0,"id":12482925}]}]}
{"op":"mcm","clk":"11808908442","pt":1723191638980,"mc":[{"id":"1.231613187","marketDefinition":{"bspMarket":false,"turnInPlayEnabled":true,"persistenceEnabled":true,"marketBaseRate":5.0,"eventId":"33480112","eventTypeId":"4","numberOfWinners":1,"bettingType":"ODDS","marketType":"MATCH_ODDS","marketTime":"2024-08-11T09:00:00.000Z","suspendTime":"2024-08-11T09:00:00.000Z","bspReconciled":false,"complete":true,"inPlay":false,"crossMatching":true,"runnersVoidable":false,"numberOfActiveRunners":2,"betDelay":0,"status":"OPEN","runners":[{"status":"ACTIVE","sortPriority":1,"id":12482925,"name":"Scotland Women"},{"status":"ACTIVE","sortPriority":2,"id":12474498,"name":"Papua New Guinea Women"}],"regulators":["MR_INT"],"countryCode":"GB","discountAllowed":true,"timezone":"GMT","openDate":"2024-08-11T09:00:00.000Z","version":6062838754,"name":"Match Odds","eventName":"Scotland Women v Papua New Guinea Women"}}]}
{"op":"mcm","clk":"11809055898","pt":1723194774866,"mc":[{"id":"1.231613187","rc":[{"batb":[[1,1.04,1630.89],[2,1.03,2358.56]],"ltp":0.0,"tv":0.0,"id":12474498},{"batb":[[1,1.04,1630.89],[2,1.03,2358.56]],"ltp":0.0,"tv":0.0,"id":12482925}]}]}
{"op":"mcm","clk":"11809352829","pt":1723199654343,"mc":[{"id":"1.231613187","rc":[{"batb":[[0,1.19,19],[1,1.05,100],[2,1.04,1630.89]],"ltp":0.0,"tv":0.0,"id":12482925}]}]}
{"op":"mcm","clk":"11809354027","pt":1723199669761,"mc":[{"id":"1.231613187","rc":[{"batb":[[0,1.91,10],[1,1.05,100],[2,1.04,1630.89]],"ltp":0.0,"tv":0.0,"id":12474498}]}]}
{"op":"mcm","clk":"11809391858","pt":1723200174876,"mc":[{"id":"1.231613187","rc":[{"batb":[[2,1.04,1631.87]],"ltp":0.0,"tv":0.0,"id":12474498},{"batb":[[2,1.04,1631.87]],"ltp":0.0,"tv":0.0,"id":12482925}]}]}
{"op":"mcm","clk":"11809642090","pt":1723203401200,"mc":[{"id":"1.231613187","rc":[{"batb":[[0,1.91,15],[2,1.04,1633.54]],"ltp":0.0,"tv":0.0,"id":12474498},{"batb":[[0,1.2,5],[1,1.19,19],[2,1.05,100]],"ltp":0.0,"tv":0.0,"id":12482925}]}]}
{"op":"mcm","clk":"11809642786","pt":1723203409203,"mc":[{"id":"1.231613187","rc":[{"batb":[[0,1.92,5],[1,1.91,10],[2,1.05,100]],"ltp":0.0,"tv":0.0,"id":12474498}]}]}
{"op":"mcm","clk":"11811480983","pt":1723221145541,"mc":[{"id":"1.231613187","rc":[{"batb":[[0,3.7,15.47],[1,1.92,5],[2,1.91,10]],"ltp":0.0,"tv":0.0,"id":12474498},{"batb":[[0,1.32,130.59],[1,1.2,5],[2,1.19,19]],"ltp":0.0,"tv":0.0,"id":12482925}]}]}
{"op":"mcm","clk":"11811580657","pt":1723221724610,"mc":[{"id":"1.231613187","rc":[{"batl":[[0,2,300]],"ltp":0.0,"tv":0.0,"id":12482925}]}]}
{"op":"mcm","clk":"11811664843","pt":1723222153806,"mc":[{"id":"1.231613187","rc":[{"batl":[[0,1.6,40],[1,2,300]],"ltp":0.0,"tv":0.0,"id":12482925}]}]}
{"op":"mcm","clk":"11811700684","pt":1723222415908,"mc":[{"id":"1.231613187","rc":[{"batb":[[1,1.91,10],[2,1.04,1632.15]],"ltp":0.0,"tv":0.0,"id":12474498},{"batb":[[1,1.19,19],[2,1.1,3000]],"ltp":0.0,"tv":0.0,"id":12482925}]}]}
{"op":"mcm","clk":"11812630269","pt":1723227174853,"mc":[{"id":"1.231613187","rc":[{"batb":[[2,1.04,1632.01]],"ltp":0.0,"tv":0.0,"id":12474498}]}]}
{"op":"mcm","clk":"11813543639","pt":1723231179059,"mc":[{"id":"1.231613187","rc":[{"batb":[[1,1.04,1632.29],[2,1.03,2361.19]],"ltp":0.0,"tv":0.0,"id":12474498},{"batb":[[1,1.1,3000],[2,1.04,1632.29]],"ltp":0.0,"tv":0.0,"id":12482925}]}]}
{"op":"mcm","clk":"11813546594","pt":1723231193267,"mc":[{"id":"1.231613187","rc":[{"batl":[[0,1.37,20],[1,1.6,40],[2,2,300]],"ltp":0.0,"tv":0.0,"id":12482925}]}]}
{"op":"mcm","clk":"11813706974","pt":1723231945440,"mc":[{"id":"1.231613187","rc":[{"batl":[[1,2,300],[2,2,0]],"ltp":0.0,"tv":0.0,"id":12482925}]}]}
{"op":"mcm","clk":"11814037413","pt":1723233667836,"mc":[{"id":"1.231613187","rc":[{"batb":[[1,1.04,1631.73],[2,1.03,2360.45]],"ltp":0.0,"tv":0.0,"id":12474498},{"batb":[[0,1.32,177.98],[2,1.04,1631.73]],"ltp":0.0,"tv":0.0,"id":12482925}]}]}
{"op":"mcm","clk":"11814531334","pt":1723237974858,"mc":[{"id":"1.231613187","rc":[{"batb":[[1,1.04,1631.59],[2,1.03,2360.26]],"ltp":0.0,"tv":0.0,"id":12474498},{"batb":[[2,1.04,1631.59]],"ltp":0.0,"tv":0.0,"id":12482925}]}]}
{"op":"mcm","clk":"11814822179","pt":1723243374837,"mc":[{"id":"1.231613187","rc":[{"batb":[[1,1.04,1635.51],[2,1.03,2365.45]],"ltp":0.0,"tv":0.0,"id":12474498},{"batb":[[2,1.04,1635.51]],"ltp":0.0,"tv":0.0,"id":12482925}]}]}
{"op":"mcm","clk":"11815073525","pt":1723246879159,"mc":[{"id":"1.231613187","rc":[{"batb":[[0,1.32,178.08]],"ltp":0.0,"tv":0.0,"id":12482925}]}]}
{"op":"mcm","clk":"11815341151","pt":1723249889736,"mc":[{"id":"1.231613187","rc":[{"batb":[[0,1.32,178.07]],"ltp":0.0,"tv":0.0,"id":12482925}]}]}
{"op":"mcm","clk":"11816828366","pt":1723273066360,"mc":[{"id":"1.231613187","rc":[{"batl":[[0,2,300],[1,2,0]],"ltp":0.0,"tv":0.0,"id":12482925}]}]}
{"op":"mcm","clk":"11816831412","pt":1723273141151,"mc":[{"id":"1.231613187","rc":[{"batb":[[1,1.3,20],[2,1.1,3000]],"ltp":0.0,"tv":0.0,"id":12482925}]}]}
{"op":"mcm","clk":"11816832014","pt":1723273157303,"mc":[{"id":"1.231613187","rc":[{"batl":[[0,1.54,10],[1,2,300]],"ltp":0.0,"tv":0.0,"id":12482925}]}]}
{"op":"mcm","clk":"11816876267","pt":1723273964856,"mc":[{"id":"1.231613187","rc":[{"batl":[[0,1.54,5]],"ltp":0.0,"tv":0.0,"id":12482925}]}]}
{"op":"mcm","clk":"11817162980","pt":1723278734701,"mc":[{"id":"1.231613187","rc":[{"batb":[[2,1.04,1635.51]],"batl":[[1,2,0]],"ltp":0.0,"tv":0.0,"id":12482925}]}]}
{"op":"mcm","clk":"11817173630","pt":1723278886730,"mc":[{"id":"1.231613187","rc":[{"batb":[[2,1.1,2000]],"ltp":0.0,"tv":0.0,"id":12482925}]}]}
{"op":"mcm","clk":"11817173893","pt":1723278890947,"mc":[{"id":"1.231613187","rc":[{"batl":[[1,2,200]],"ltp":0.0,"tv":0.0,"id":12482925}]}]}
{"op":"mcm","clk":"11817299760","pt":1723280714593,"mc":[{"id":"1.231613187","rc":[{"trd":[[3.7,0.04]],"batb":[[0,3.7,15.45]],"ltp":3.7,"tv":0.04,"id":12474498}],"tv":0.04}]}
{"op":"mcm","clk":"11817299975","pt":1723280716624,"mc":[{"id":"1.231613187","rc":[{"batb":[[0,3.7,15.47]],"ltp":3.7,"tv":0.04,"id":12474498}]}]}
{"op":"mcm","clk":"11817377640","pt":1723281348687,"mc":[{"id":"1.231613187","rc":[{"batb":[[1,1.1,2000],[2,1.04,1635.51]],"batl":[[0,2,200],[1,2,0]],"ltp":0.0,"tv":0.0,"id":12482925}]}]}
{"op":"mcm","clk":"11817378884","pt":1723281359996,"mc":[{"id":"1.231613187","rc":[{"batl":[[0,1.54,5],[1,2,200]],"ltp":0.0,"tv":0.0,"id":12482925}]}]}
{"op":"mcm","clk":"11817380100","pt":1723281370636,"mc":[{"id":"1.231613187","rc":[{"batb":[[1,1.25,5],[2,1.1,2000]],"ltp":0.0,"tv":0.0,"id":12482925}]}]}
{"op":"mcm","clk":"11818122801","pt":1723287521535,"mc":[{"id":"1.231613187","rc":[{"batb":[[1,1.03,200.79],[2,1.02,200.79]],"ltp":3.7,"tv":0.04,"id":12474498}]}]}
{"op":"mcm","clk":"11818141941","pt":1723287647736,"mc":[{"id":"1.231613187","rc":[{"batb":[[0,1.32,130.59]],"ltp":0.0,"tv":0.0,"id":12482925}]}]}
{"op":"mcm","clk":"11819373419","pt":1723293807453,"mc":[{"id":"1.231613187","rc":[{"trd":[[4.2,2.58]],"ltp":4.2,"tv":2.62,"id":12474498},{"trd":[[1.32,8.22]],"batb":[[0,1.32,312.32]],"ltp":1.32,"tv":8.22,"id":12482925}],"tv":10.84}]}
{"op":"mcm","clk":"11819374021","pt":1723293810249,"mc":[{"id":"1.231613187","rc":[{"batb":[[0,1.32,320.54]],"ltp":1.32,"tv":8.22,"id":12482925}]}]}
{"op":"mcm","clk":"11819742262","pt":1723295660104,"mc":[{"id":"1.231613187","rc":[{"batl":[[0,1.36,36.16],[1,1.54,5],[2,2,200]],"ltp":1.32,"tv":8.22,"id":12482925}]}]}
{"op":"mcm","clk":"11819743483","pt":1723295666031,"mc":[{"id":"1.231613187","rc":[{"batl":[[1,1.38,41.33],[2,1.54,5]],"ltp":1.32,"tv":8.22,"id":12482925}]}]}
{"op":"mcm","clk":"11819744893","pt":1723295673039,"mc":[{"id":"1.231613187","rc":[{"batl":[[2,1.41,56.83]],"ltp":1.32,"tv":8.22,"id":12482925}]}]}
{"op":"mcm","clk":"11820114291","pt":1723297486469,"mc":[{"id":"1.231613187","rc":[{"trd":[[1.32,12.22]],"batb":[[0,1.32,318.54]],"ltp":1.32,"tv":12.22,"id":12482925}],"tv":14.84}]}
{"op":"mcm","clk":"11820587882","pt":1723299707792,"mc":[{"id":"1.231613187","rc":[{"batb":[[0,3.7,14.46]],"ltp":4.2,"tv":2.62,"id":12474498},{"batb":[[0,1.32,309.95]],"ltp":1.32,"tv":12.22,"id":12482925}]}]}
{"op":"mcm","clk":"11821715833","pt":1723304201935,"mc":[{"id":"1.231613187","rc":[{"trd":[[1.32,22.22]],"batb":[[0,1.32,304.95]],"ltp":1.32,"tv":22.22,"id":12482925}],"tv":24.84}]}
{"op":"mcm","clk":"11823252857","pt":1723311817977,"mc":[{"id":"1.231613187","rc":[{"batb":[[0,1.32,122]],"ltp":1.32,"tv":22.22,"id":12482925}]}]}
{"op":"mcm","clk":"11823302179","pt":1723312052385,"mc":[{"id":"1.231613187","rc":[{"batb":[[0,1.32,311.98]],"ltp":1.32,"tv":22.22,"id":12482925}]}]}
{"op":"mcm","clk":"11823524003","pt":1723313149878,"mc":[{"id":"1.231613187","rc":[{"trd":[[1.36,6]],"batl":[[0,1.36,33.16]],"ltp":1.36,"tv":28.22,"id":12482925}],"tv":30.84}]}
{"op":"mcm","clk":"11823527841","pt":1723313167004,"mc":[{"id":"1.231613187","rc":[{"trd":[[1.36,16]],"batl":[[0,1.36,28.16]],"ltp":1.36,"tv":38.22,"id":12482925}],"tv":40.84}]}
{"op":"mcm","clk":"11824493523","pt":1723318062676,"mc":[{"id":"1.231613187","rc":[{"batb":[[0,1.32,311.95]],"ltp":1.36,"tv":38.22,"id":12482925}]}]}
{"op":"mcm","clk":"11825258373","pt":1723322394845,"mc":[{"id":"1.231613187","rc":[{"trd":[[3.75,0.52]],"ltp":3.75,"tv":3.13,"id":12474498},{"trd":[[1.36,17.43]],"batl":[[0,1.36,26.74]],"ltp":1.36,"tv":39.64,"id":12482925}],"tv":42.78}]}
{"op":"mcm","clk":"11825445788","pt":1723324271345,"mc":[{"id":"1.231613187","rc":[{"batb":[[0,1.33,9.64],[1,1.32,311.95],[2,1.25,5]],"ltp":1.36,"tv":39.64,"id":12482925}]}]}
{"op":"mcm","clk":"11825465232","pt":1723324384887,"mc":[{"id":"1.231613187","rc":[{"batb":[[1,1.32,122]],"ltp":1.36,"tv":39.64,"id":12482925}]}]}
{"op":"mcm","clk":"11825485828","pt":1723324628389,"mc":[{"id":"1.231613187","rc":[{"trd":[[1.33,31.12]],"batb":[[0,1.32,310.53],[1,1.25,5],[2,1.1,2000]],"batl":[[0,1.36,26.9]],"ltp":1.33,"tv":70.76,"id":12482925}],"tv":73.9}]}
{"op":"mcm","clk":"11825559932","pt":1723325562596,"mc":[{"id":"1.231613187","rc":[{"batl":[[0,1.35,20.83],[1,1.36,26.74],[2,1.38,41.33]],"ltp":1.33,"tv":70.76,"id":12482925}]}]}
{"op":"mcm","clk":"11825633432","pt":1723326738760,"mc":[{"id":"1.231613187","rc":[{"batb":[[0,1.32,122]],"ltp":1.33,"tv":70.76,"id":12482925}]}]}
{"op":"mcm","clk":"11825639428","pt":1723326841303,"mc":[{"id":"1.231613187","rc":[{"batb":[[0,1.32,310.53]],"ltp":1.33,"tv":70.76,"id":12482925}]}]}
{"op":"mcm","clk":"11825816341","pt":1723329774813,"mc":[{"id":"1.231613187","rc":[{"trd":[[3.75,0.52],[4.2,2.58]],"ltp":3.75,"tv":3.13,"id":12474498},{"trd":[[1.33,31.09],[1.36,17.4]],"batl":[[0,1.35,20.76],[1,1.36,26.66],[2,1.38,41.21]],"ltp":1.33,"tv":70.7,"id":12482925}],"tv":73.83}]}
{"op":"mcm","clk":"11826040058","pt":1723332478375,"mc":[{"id":"1.231613187","rc":[{"batb":[[1,1.1,2000],[2,1.03,200.79]],"ltp":1.33,"tv":70.7,"id":12482925}]}]}
{"op":"mcm","clk":"11826040147","pt":1723332479359,"mc":[{"id":"1.231613187","rc":[{"trd":[[1.32,1102.56]],"batb":[[0,1.1,2000],[1,1.03,200.79],[2,1.02,200.79]],"batl":[[0,1.32,4611.02],[1,1.35,20.76],[2,1.36,26.66]],"ltp":1.32,"tv":1151.04,"id":12482925}],"tv":1154.17}]}
{"op":"mcm","clk":"11826040250","pt":1723332480856,"mc":[{"id":"1.231613187","rc":[{"batb":[[0,1.28,139.43],[1,1.1,2000],[2,1.03,200.79]],"ltp":1.32,"tv":1151.04,"id":12482925}]}]}
{"op":"mcm","clk":"11826264712","pt":1723335565629,"mc":[{"id":"1.231613187","rc":[{"trd":[[4.1,0.91]],"ltp":4.1,"tv":4.04,"id":12474498},{"trd":[[1.32,1105.39]],"batl":[[0,1.32,4608.19]],"ltp":1.32,"tv":1153.87,"id":12482925}],"tv":1157.92}]}
{"op":"mcm","clk":"11826990015","pt":1723346160296,"mc":[{"id":"1.231613187","rc":[{"batl":[[0,1.31,112.5],[1,1.32,4608.19],[2,1.35,20.76]],"ltp":1.32,"tv":1153.87,"id":12482925}]}]}
{"op":"mcm","clk":"11826991082","pt":1723346176499,"mc":[{"id":"1.231613187","rc":[{"batl":[[2,1.34,112.66]],"ltp":1.32,"tv":1153.87,"id":12482925}]}]}
{"op":"mcm","clk":"11827042954","pt":1723347263266,"mc":[{"id":"1.231613187","rc":[{"batl":[[0,1.3,89.51],[1,1.31,112.5],[2,1.32,4608.19]],"ltp":1.32,"tv":1153.87,"id":12482925}]}]}
{"op":"mcm","clk":"11827043384","pt":1723347274363,"mc":[{"id":"1.231613187","rc":[{"batl":[[0,1.31,112.5],[1,1.32,4608.19],[2,1.34,112.66]],"ltp":1.32,"tv":1153.87,"id":12482925}]}]}
{"op":"mcm","clk":"11827076599","pt":1723348018328,"mc":[{"id":"1.231613187","rc":[{"trd":[[4.2,3.12]],"ltp":4.2,"tv":4.59,"id":12474498},{"trd":[[1.31,1.75]],"batl":[[0,1.31,110.75]],"ltp":1.31,"tv":1155.62,"id":12482925}],"tv":1160.22}]}
{"op":"mcm","clk":"11827081044","pt":1723348122306,"mc":[{"id":"1.231613187","rc":[{"trd":[[4.2,3.85]],"ltp":4.2,"tv":5.32,"id":12474498},{"trd":[[1.31,4.09]],"batl":[[0,1.31,108.41]],"ltp":1.31,"tv":1157.96,"id":12482925}],"tv":1163.29}]}
{"op":"mcm","clk":"11827105218","pt":1723348636332,"mc":[{"id":"1.231613187","rc":[{"trd":[[1.28,0.26]],"batb":[[0,1.28,139.3]],"ltp":1.28,"tv":1158.22,"id":12482925}],"tv":1163.55}]}
{"op":"mcm","clk":"11827105291","pt":1723348637830,"mc":[{"id":"1.231613187","rc":[{"batb":[[0,1.28,278.73]],"ltp":1.28,"tv":1158.22,"id":12482925}]}]}
{"op":"mcm","clk":"11827105295","pt":1723348637929,"mc":[{"id":"1.231613187","rc":[{"batb":[[0,1.28,139.43]],"ltp":1.28,"tv":1158.22,"id":12482925}]}]}
{"op":"mcm","clk":"11827139552","pt":1723349306537,"mc":[{"id":"1.231613187","rc":[{"batl":[[0,1.3,112.5],[1,1.31,108.41],[2,1.32,4608.19]],"ltp":1.28,"tv":1158.22,"id":12482925}]}]}
{"op":"mcm","clk":"11827139817","pt":1723349313730,"mc":[{"id":"1.231613187","rc":[{"batl":[[0,1.31,108.41],[1,1.32,4608.19],[2,1.34,112.66]],"ltp":1.28,"tv":1158.22,"id":12482925}]}]}
{"op":"mcm","clk":"11827140548","pt":1723349331348,"mc":[{"id":"1.231613187","rc":[{"batl":[[0,1.3,90],[1,1.31,108.41],[2,1.32,4608.19]],"ltp":1.28,"tv":1158.22,"id":12482925}]}]}
{"op":"mcm","clk":"11827140804","pt":1723349337756,"mc":[{"id":"1.231613187","rc":[{"batl":[[0,1.31,108.41],[1,1.32,4608.19],[2,1.34,112.66]],"ltp":1.28,"tv":1158.22,"id":12482925}]}]}
{"op":"mcm","clk":"11827141770","pt":1723349361236,"mc":[{"id":"1.231613187","rc":[{"batl":[[0,1.3,67.5],[1,1.31,108.41],[2,1.32,4608.19]],"ltp":1.28,"tv":1158.22,"id":12482925}]}]}
{"op":"mcm","clk":"11827142044","pt":1723349367651,"mc":[{"id":"1.231613187","rc":[{"batl":[[0,1.31,108.41],[1,1.32,4608.19],[2,1.34,112.66]],"ltp":1.28,"tv":1158.22,"id":12482925}]}]}
{"op":"mcm","clk":"11827142551","pt":1723349384386,"mc":[{"id":"1.231613187","rc":[{"batl":[[0,1.3,94.5],[1,1.31,108.41],[2,1.32,4608.19]],"ltp":1.28,"tv":1158.22,"id":12482925}]}]}
{"op":"mcm","clk":"11827142771","pt":1723349390895,"mc":[{"id":"1.231613187","rc":[{"batl":[[0,1.31,108.41],[1,1.32,4608.19],[2,1.34,112.66]],"ltp":1.28,"tv":1158.22,"id":12482925}]}]}
{"op":"mcm","clk":"11827172211","pt":1723350126494,"mc":[{"id":"1.231613187","rc":[{"batb":[[0,1.29,45],[1,1.28,139.43],[2,1.1,2000]],"ltp":1.28,"tv":1158.22,"id":12482925}]}]}
{"op":"mcm","clk":"11827197492","pt":1723350803387,"mc":[{"id":"1.231613187","rc":[{"batl":[[0,1.3,11.14],[1,1.31,108.41],[2,1.32,4608.19]],"ltp":1.28,"tv":1158.22,"id":12482925}]}]}
{"op":"mcm","clk":"11827203403","pt":1723350947585,"mc":[{"id":"1.231613187","rc":[{"batb":[[2,1.17,45]],"ltp":1.28,"tv":1158.22,"id":12482925}]}]}
{"op":"mcm","clk":"11827209574","pt":1723351131248,"mc":[{"id":"1.231613187","rc":[{"trd":[[1.29,2]],"batb":[[0,1.29,44]],"ltp":1.29,"tv":1160.22,"id":12482925}],"tv":1165.55}]}
{"op":"mcm","clk":"11827232195","pt":1723351435433,"mc":[{"id":"1.231613187","rc":[{"trd":[[1.29,4]],"batb":[[0,1.29,43]],"ltp":1.29,"tv":1162.22,"id":12482925}],"tv":1167.55}]}
{"op":"mcm","clk":"11827232278","pt":1723351437738,"mc":[{"id":"1.231613187","rc":[{"trd":[[1.3,3.96]],"batl":[[0,1.3,9.16]],"ltp":1.3,"tv":1166.18,"id":12482925}],"tv":1171.51}]}
{"op":"mcm","clk":"11827232996","pt":1723351456740,"mc":[{"id":"1.231613187","rc":[{"trd":[[1.29,6]],"batb":[[0,1.29,42]],"ltp":1.29,"tv":1168.18,"id":12482925}],"tv":1173.51}]}
{"op":"mcm","clk":"11827233461","pt":1723351466442,"mc":[{"id":"1.231613187","rc":[{"trd":[[1.29,8]],"batb":[[0,1.29,41]],"ltp":1.29,"tv":1170.18,"id":12482925}],"tv":1175.51}]}
{"op":"mcm","clk":"11827234602","pt":1723351496288,"mc":[{"id":"1.231613187","rc":[{"trd":[[1.3,4.1]],"batl":[[0,1.3,9.09]],"ltp":1.3,"tv":1170.33,"id":12482925}],"tv":1175.65}]}
{"op":"mcm","clk":"11827235387","pt":1723351514243,"mc":[{"id":"1.231613187","rc":[{"trd":[[1.29,10]],"batb":[[0,1.29,40]],"ltp":1.29,"tv":1172.33,"id":12482925}],"tv":1177.65}]}
{"op":"mcm","clk":"11827235706","pt":1723351521124,"mc":[{"id":"1.231613187","rc":[{"trd":[[1.3,10.06]],"batl":[[0,1.3,6.11]],"ltp":1.3,"tv":1178.29,"id":12482925}],"tv":1183.61}]}
{"op":"mcm","clk":"11827237172","pt":1723351552774,"mc":[{"id":"1.231613187","rc":[{"trd":[[1.29,12]],"batb":[[0,1.29,39]],"ltp":1.29,"tv":1180.29,"id":12482925}],"tv":1185.61}]}
{"op":"mcm","clk":"11827237898","pt":1723351568596,"mc":[{"id":"1.231613187","rc":[{"trd":[[1.29,14]],"batb":[[0,1.29,38]],"ltp":1.29,"tv":1182.29,"id":12482925}],"tv":1187.61}]}
{"op":"mcm","clk":"11827238049","pt":1723351572611,"mc":[{"id":"1.231613187","rc":[{"trd":[[1.3,14.04]],"batl":[[0,1.3,4.12]],"ltp":1.3,"tv":1186.27,"id":12482925}],"tv":1191.59}]}
{"op":"mcm","clk":"11827246247","pt":1723351764852,"mc":[{"id":"1.231613187","rc":[{"trd":[[1.29,16]],"batb":[[0,1.29,37]],"ltp":1.29,"tv":1188.27,"id":12482925}],"tv":1193.59}]}
{"op":"mcm","clk":"11827253879","pt":1723351997085,"mc":[{"id":"1.231613187","rc":[{"batb":[[0,4.1,12.59]],"ltp":4.2,"tv":5.32,"id":12474498},{"batb":[[1,1.27,144.6]],"ltp":1.29,"tv":1188.27,"id":12482925}]}]}
{"op":"mcm","clk":"11827303996","pt":1723353312176,"mc":[{"id":"1.231613187","rc":[{"batl":[[0,1.3,11.77]],"ltp":1.29,"tv":1188.27,"id":12482925}]}]}
{"op":"mcm","clk":"11827313221","pt":1723353535473,"mc":[{"id":"1.231613187","rc":[{"batb":[[0,4.2,4],[1,4.1,12.59],[2,1.03,200.79]],"batl":[[0,4.4,19.7]],"ltp":4.2,"tv":5.32,"id":12474498}]}]}
{"op":"mcm","clk":"11827313292","pt":1723353537983,"mc":[{"id":"1.231613187","rc":[{"batb":[[0,4.1,12.59],[1,1.03,200.79],[2,1.02,200.79]],"ltp":4.2,"tv":5.32,"id":12474498}]}]}
{"op":"mcm","clk":"11827313369","pt":1723353540182,"mc":[{"id":"1.231613187","rc":[{"batb":[[0,4.2,4],[1,4.1,12.59],[2,1.03,200.79]],"ltp":4.2,"tv":5.32,"id":12474498}]}]}
{"op":"mcm","clk":"11827313474","pt":1723353542502,"mc":[{"id":"1.231613187","rc":[{"batb":[[0,4.1,12.59],[1,1.03,200.79],[2,1.02,200.79]],"ltp":4.2,"tv":5.32,"id":12474498}]}]}
{"op":"mcm","clk":"11827313560","pt":1723353544814,"mc":[{"id":"1.231613187","rc":[{"batb":[[0,4.2,4],[1,4.1,12.59],[2,1.03,200.79]],"ltp":4.2,"tv":5.32,"id":12474498}]}]}
{"op":"mcm","clk":"11827313621","pt":1723353546976,"mc":[{"id":"1.231613187","rc":[{"batb":[[0,4.1,12.59],[1,1.03,200.79],[2,1.02,200.79]],"ltp":4.2,"tv":5.32,"id":12474498}]}]}
{"op":"mcm","clk":"11827313690","pt":1723353549284,"mc":[{"id":"1.231613187","rc":[{"batb":[[0,4.2,4],[1,4.1,12.59],[2,1.03,200.79]],"ltp":4.2,"tv":5.32,"id":12474498}]}]}
{"op":"mcm","clk":"11827313766","pt":1723353551594,"mc":[{"id":"1.231613187","rc":[{"batb":[[0,4.1,12.59],[1,1.03,200.79],[2,1.02,200.79]],"ltp":4.2,"tv":5.32,"id":12474498}]}]}
{"op":"mcm","clk":"11827313857","pt":1723353554518,"mc":[{"id":"1.231613187","rc":[{"batb":[[0,4.2,4],[1,4.1,12.59],[2,1.03,200.79]],"ltp":4.2,"tv":5.32,"id":12474498}]}]}
{"op":"mcm","clk":"11827313926","pt":1723353556728,"mc":[{"id":"1.231613187","rc":[{"batb":[[0,4.1,12.59],[1,1.03,200.79],[2,1.02,200.79]],"ltp":4.2,"tv":5.32,"id":12474498}]}]}
{"op":"mcm","clk":"11827314011","pt":1723353559033,"mc":[{"id":"1.231613187","rc":[{"batb":[[0,4.2,4],[1,4.1,12.59],[2,1.03,200.79]],"ltp":4.2,"tv":5.32,"id":12474498}]}]}
{"op":"mcm","clk":"11827314093","pt":1723353561337,"mc":[{"id":"1.231613187","rc":[{"batb":[[0,4.1,12.59],[1,1.03,200.79],[2,1.02,200.79]],"ltp":4.2,"tv":5.32,"id":12474498}]}]}
{"op":"mcm","clk":"11827314153","pt":1723353563894,"mc":[{"id":"1.231613187","rc":[{"batb":[[0,4.2,4],[1,4.1,12.59],[2,1.03,200.79]],"ltp":4.2,"tv":5.32,"id":12474498}]}]}
{"op":"mcm","clk":"11827314222","pt":1723353566199,"mc":[{"id":"1.231613187","rc":[{"batb":[[0,4.1,12.59],[1,1.03,200.79],[2,1.02,200.79]],"ltp":4.2,"tv":5.32,"id":12474498}]}]}
{"op":"mcm","clk":"11827314306","pt":1723353568510,"mc":[{"id":"1.231613187","rc":[{"batb":[[0,4.2,4],[1,4.1,12.59],[2,1.03,200.79]],"ltp":4.2,"tv":5.32,"id":12474498}]}]}
{"op":"mcm","clk":"11827314384","pt":1723353570813,"mc":[{"id":"1.231613187","rc":[{"batb":[[0,4.1,12.59],[1,1.03,200.79],[2,1.02,200.79]],"ltp":4.2,"tv":5.32,"id":12474498}]}]}
{"op":"mcm","clk":"11827314508","pt":1723353574155,"mc":[{"id":"1.231613187","rc":[{"batb":[[0,4.2,4],[1,4.1,12.59],[2,1.03,200.79]],"ltp":4.2,"tv":5.32,"id":12474498}]}]}
{"op":"mcm","clk":"11827314599","pt":1723353576411,"mc":[{"id":"1.231613187","rc":[{"batb":[[0,4.1,12.59],[1,1.03,200.79],[2,1.02,200.79]],"ltp":4.2,"tv":5.32,"id":12474498}]}]}
{"op":"mcm","clk":"11827314694","pt":1723353578819,"mc":[{"id":"1.231613187","rc":[{"batb":[[0,4.2,4],[1,4.1,12.59],[2,1.03,200.79]],"ltp":4.2,"tv":5.32,"id":12474498},{"trd":[[1.3,14.85]],"batl":[[0,1.3,11.37]],"ltp":1.3,"tv":1189.07,"id":12482925}],"tv":1194.39}]}
{"op":"mcm","clk":"11827314757","pt":1723353581046,"mc":[{"id":"1.231613187","rc":[{"batb":[[0,4.1,12.59],[1,1.03,200.79],[2,1.02,200.79]],"ltp":4.2,"tv":5.32,"id":12474498}]}]}
{"op":"mcm","clk":"11827314846","pt":1723353583361,"mc":[{"id":"1.231613187","rc":[{"batb":[[0,4.2,4],[1,4.1,12.59],[2,1.03,200.79]],"ltp":4.2,"tv":5.32,"id":12474498}]}]}
{"op":"mcm","clk":"11827314947","pt":1723353585735,"mc":[{"id":"1.231613187","rc":[{"batb":[[0,4.1,12.59],[1,1.03,200.79],[2,1.02,200.79]],"ltp":4.2,"tv":5.32,"id":12474498}]}]}
{"op":"mcm","clk":"11827315091","pt":1723353588755,"mc":[{"id":"1.231613187","rc":[{"batb":[[0,4.2,4],[1,4.1,12.59],[2,1.03,200.79]],"ltp":4.2,"tv":5.32,"id":12474498}]}]}
{"op":"mcm","clk":"11827315165","pt":1723353590864,"mc":[{"id":"1.231613187","rc":[{"batb":[[0,4.1,12.59],[1,1.03,200.79],[2,1.02,200.79]],"ltp":4.2,"tv":5.32,"id":12474498}]}]}
{"op":"mcm","clk":"11827315268","pt":1723353593272,"mc":[{"id":"1.231613187","rc":[{"batb":[[0,4.2,4],[1,4.1,12.59],[2,1.03,200.79]],"ltp":4.2,"tv":5.32,"id":12474498}]}]}
{"op":"mcm","clk":"11827315345","pt":1723353595576,"mc":[{"id":"1.231613187","rc":[{"batb":[[0,4.1,12.59],[1,1.03,200.79],[2,1.02,200.79]],"ltp":4.2,"tv":5.32,"id":12474498}]}]}
{"op":"mcm","clk":"11827315362","pt":1723353596139,"mc":[{"id":"1.231613187","rc":[{"trd":[[1.3,15.05]],"batl":[[0,1.3,11.27]],"ltp":1.3,"tv":1189.27,"id":12482925}],"tv":1194.59}]}
{"op":"mcm","clk":"11827315440","pt":1723353598463,"mc":[{"id":"1.231613187","rc":[{"batb":[[0,4.2,4],[1,4.1,12.59],[2,1.03,200.79]],"ltp":4.2,"tv":5.32,"id":12474498}]}]}
{"op":"mcm","clk":"11827315517","pt":1723353600840,"mc":[{"id":"1.231613187","rc":[{"batb":[[0,4.1,12.59],[1,1.03,200.79],[2,1.02,200.79]],"ltp":4.2,"tv":5.32,"id":12474498}]}]}
{"op":"mcm","clk":"11827315617","pt":1723353603063,"mc":[{"id":"1.231613187","rc":[{"batb":[[0,4.2,4],[1,4.1,12.59],[2,1.03,200.79]],"ltp":4.2,"tv":5.32,"id":12474498}]}]}
{"op":"mcm","clk":"11827315700","pt":1723353605374,"mc":[{"id":"1.231613187","rc":[{"batb":[[0,4.1,12.59],[1,1.03,200.79],[2,1.02,200.79]],"ltp":4.2,"tv":5.32,"id":12474498}]}]}
{"op":"mcm","clk":"11827315768","pt":1723353607480,"mc":[{"id":"1.231613187","rc":[{"batb":[[0,4.2,4],[1,4.1,12.59],[2,1.03,200.79]],"ltp":4.2,"tv":5.32,"id":12474498}]}]}
{"op":"mcm","clk":"11827315833","pt":1723353609893,"mc":[{"id":"1.231613187","rc":[{"batb":[[0,4.1,12.59],[1,1.03,200.79],[2,1.02,200.79]],"ltp":4.2,"tv":5.32,"id":12474498}]}]}
{"op":"mcm","clk":"11827315903","pt":1723353612097,"mc":[{"id":"1.231613187","rc":[{"batb":[[0,4.2,4],[1,4.1,12.59],[2,1.03,200.79]],"ltp":4.2,"tv":5.32,"id":12474498}]}]}
{"op":"mcm","clk":"11827315980","pt":1723353614467,"mc":[{"id":"1.231613187","rc":[{"batb":[[0,4.1,12.59],[1,1.03,200.79],[2,1.02,200.79]],"ltp":4.2,"tv":5.32,"id":12474498}]}]}
{"op":"mcm","clk":"11827316079","pt":1723353616691,"mc":[{"id":"1.231613187","rc":[{"batb":[[0,4.2,4],[1,4.1,12.59],[2,1.03,200.79]],"ltp":4.2,"tv":5.32,"id":12474498}]}]}
{"op":"mcm","clk":"11827316189","pt":1723353619012,"mc":[{"id":"1.231613187","rc":[{"batb":[[0,4.1,12.59],[1,1.03,200.79],[2,1.02,200.79]],"ltp":4.2,"tv":5.32,"id":12474498}]}]}
{"op":"mcm","clk":"11827316268","pt":1723353621269,"mc":[{"id":"1.231613187","rc":[{"batb":[[0,4.2,4],[1,4.1,12.59],[2,1.03,200.79]],"ltp":4.2,"tv":5.32,"id":12474498}]}]}
{"op":"mcm","clk":"11827316332","pt":1723353623477,"mc":[{"id":"1.231613187","rc":[{"batb":[[0,4.1,12.59],[1,1.03,200.79],[2,1.02,200.79]],"ltp":4.2,"tv":5.32,"id":12474498}]}]}
{"op":"mcm","clk":"11827316398","pt":1723353625678,"mc":[{"id":"1.231613187","rc":[{"batb":[[0,4.2,4],[1,4.1,12.59],[2,1.03,200.79]],"ltp":4.2,"tv":5.32,"id":12474498}]}]}
{"op":"mcm","clk":"11827316484","pt":1723353627981,"mc":[{"id":"1.231613187","rc":[{"batb":[[0,4.1,12.59],[1,1.03,200.79],[2,1.02,200.79]],"ltp":4.2,"tv":5.32,"id":12474498}]}]}
{"op":"mcm","clk":"11827316581","pt":1723353630294,"mc":[{"id":"1.231613187","rc":[{"batb":[[0,4.2,4],[1,4.1,12.59],[2,1.03,200.79]],"ltp":4.2,"tv":5.32,"id":12474498}]}]}
{"op":"mcm","clk":"11827316678","pt":1723353632597,"mc":[{"id":"1.231613187","rc":[{"batb":[[0,4.1,12.59],[1,1.03,200.79],[2,1.02,200.79]],"ltp":4.2,"tv":5.32,"id":12474498}]}]}
{"op":"mcm","clk":"11827316776","pt":1723353634896,"mc":[{"id":"1.231613187","rc":[{"batb":[[0,4.2,4],[1,4.1,12.59],[2,1.03,200.79]],"ltp":4.2,"tv":5.32,"id":12474498}]}]}
{"op":"mcm","clk":"11827316869","pt":1723353637206,"mc":[{"id":"1.231613187","rc":[{"batb":[[0,4.1,12.59],[1,1.03,200.79],[2,1.02,200.79]],"ltp":4.2,"tv":5.32,"id":12474498}]}]}
{"op":"mcm","clk":"11827316959","pt":1723353639617,"mc":[{"id":"1.231613187","rc":[{"batb":[[0,4.2,4],[1,4.1,12.59],[2,1.03,200.79]],"ltp":4.2,"tv":5.32,"id":12474498}]}]}
{"op":"mcm","clk":"11827317055","pt":1723353642041,"mc":[{"id":"1.231613187","rc":[{"batb":[[0,4.1,12.59],[1,1.03,200.79],[2,1.02,200.79]],"ltp":4.2,"tv":5.32,"id":12474498}]}]}
{"op":"mcm","clk":"11827317154","pt":1723353644350,"mc":[{"id":"1.231613187","rc":[{"batb":[[0,4.2,4],[1,4.1,12.59],[2,1.03,200.79]],"ltp":4.2,"tv":5.32,"id":12474498}]}]}
{"op":"mcm","clk":"11827317279","pt":1723353646658,"mc":[{"id":"1.231613187","rc":[{"batb":[[0,4.1,12.59],[1,1.03,200.79],[2,1.02,200.79]],"ltp":4.2,"tv":5.32,"id":12474498}]}]}
{"op":"mcm","clk":"11827317382","pt":1723353648917,"mc":[{"id":"1.231613187","rc":[{"batb":[[0,4.2,4],[1,4.1,12.59],[2,1.03,200.79]],"ltp":4.2,"tv":5.32,"id":12474498}]}]}
{"op":"mcm","clk":"11827317465","pt":1723353651124,"mc":[{"id":"1.231613187","rc":[{"batb":[[0,4.1,12.59],[1,1.03,200.79],[2,1.02,200.79]],"ltp":4.2,"tv":5.32,"id":12474498}]}]}
{"op":"mcm","clk":"11827317566","pt":1723353653639,"mc":[{"id":"1.231613187","rc":[{"batb":[[0,4.2,4],[1,4.1,12.59],[2,1.03,200.79]],"ltp":4.2,"tv":5.32,"id":12474498}]}]}
{"op":"mcm","clk":"11827317644","pt":1723353655938,"mc":[{"id":"1.231613187","rc":[{"batb":[[0,4.1,12.59],[1,1.03,200.79],[2,1.02,200.79]],"ltp":4.2,"tv":5.32,"id":12474498}]}]}
{"op":"mcm","clk":"11827317762","pt":1723353658247,"mc":[{"id":"1.231613187","rc":[{"batb":[[0,4.2,4],[1,4.1,12.59],[2,1.03,200.79]],"ltp":4.2,"tv":5.32,"id":12474498}]}]}
{"op":"mcm","clk":"11827317844","pt":1723353660556,"mc":[{"id":"1.231613187","rc":[{"batb":[[0,4.1,12.59],[1,1.03,200.79],[2,1.02,200.79]],"ltp":4.2,"tv":5.32,"id":12474498}]}]}
{"op":"mcm","clk":"11827317923","pt":1723353662866,"mc":[{"id":"1.231613187","rc":[{"batb":[[0,4.2,4],[1,4.1,12.59],[2,1.03,200.79]],"ltp":4.2,"tv":5.32,"id":12474498}]}]}
{"op":"mcm","clk":"11827318008","pt":1723353665090,"mc":[{"id":"1.231613187","rc":[{"batb":[[0,4.1,12.59],[1,1.03,200.79],[2,1.02,200.79]],"ltp":4.2,"tv":5.32,"id":12474498}]}]}
{"op":"mcm","clk":"11827318097","pt":1723353667571,"mc":[{"id":"1.231613187","rc":[{"batb":[[0,4.2,4],[1,4.1,12.59],[2,1.03,200.79]],"ltp":4.2,"tv":5.32,"id":12474498}]}]}
{"op":"mcm","clk":"11827318161","pt":1723353669974,"mc":[{"id":"1.231613187","rc":[{"batb":[[0,4.1,12.59],[1,1.03,200.79],[2,1.02,200.79]],"ltp":4.2,"tv":5.32,"id":12474498}]}]}
{"op":"mcm","clk":"11827318248","pt":1723353672288,"mc":[{"id":"1.231613187","rc":[{"batb":[[0,4.2,4],[1,4.1,12.59],[2,1.03,200.79]],"ltp":4.2,"tv":5.32,"id":12474498}]}]}
{"op":"mcm","clk":"11827318326","pt":1723353674559,"mc":[{"id":"1.231613187","rc":[{"batb":[[0,4.1,12.59],[1,1.03,200.79],[2,1.02,200.79]],"ltp":4.2,"tv":5.32,"id":12474498}]}]}
{"op":"mcm","clk":"11827318431","pt":1723353676967,"mc":[{"id":"1.231613187","rc":[{"batb":[[0,4.2,4],[1,4.1,12.59],[2,1.03,200.79]],"ltp":4.2,"tv":5.32,"id":12474498}]}]}
{"op":"mcm","clk":"11827318518","pt":1723353679279,"mc":[{"id":"1.231613187","rc":[{"batb":[[0,4.1,12.59],[1,1.03,200.79],[2,1.02,200.79]],"ltp":4.2,"tv":5.32,"id":12474498}]}]}
{"op":"mcm","clk":"11827318594","pt":1723353681592,"mc":[{"id":"1.231613187","rc":[{"batb":[[0,4.2,4],[1,4.1,12.59],[2,1.03,200.79]],"ltp":4.2,"tv":5.32,"id":12474498}]}]}
{"op":"mcm","clk":"11827318672","pt":1723353683902,"mc":[{"id":"1.231613187","rc":[{"batb":[[0,4.1,12.59],[1,1.03,200.79],[2,1.02,200.79]],"ltp":4.2,"tv":5.32,"id":12474498}]}]}
{"op":"mcm","clk":"11827318769","pt":1723353686470,"mc":[{"id":"1.231613187","rc":[{"batb":[[0,4.2,4],[1,4.1,12.59],[2,1.03,200.79]],"ltp":4.2,"tv":5.32,"id":12474498}]}]}
{"op":"mcm","clk":"11827318844","pt":1723353688783,"mc":[{"id":"1.231613187","rc":[{"batb":[[0,4.1,12.59],[1,1.03,200.79],[2,1.02,200.79]],"ltp":4.2,"tv":5.32,"id":12474498}]}]}
{"op":"mcm","clk":"11827318910","pt":1723353690987,"mc":[{"id":"1.231613187","rc":[{"batb":[[0,4.2,4],[1,4.1,12.59],[2,1.03,200.79]],"ltp":4.2,"tv":5.32,"id":12474498}]}]}
{"op":"mcm","clk":"11827319002","pt":1723353693297,"mc":[{"id":"1.231613187","rc":[{"batb":[[0,4.1,12.59],[1,1.03,200.79],[2,1.02,200.79]],"ltp":4.2,"tv":5.32,"id":12474498}]}]}
{"op":"mcm","clk":"11827319092","pt":1723353695704,"mc":[{"id":"1.231613187","rc":[{"batb":[[0,4.2,4],[1,4.1,12.59],[2,1.03,200.79]],"ltp":4.2,"tv":5.32,"id":12474498}]}]}
{"op":"mcm","clk":"11827319166","pt":1723353698113,"mc":[{"id":"1.231613187","rc":[{"batb":[[0,4.1,12.59],[1,1.03,200.79],[2,1.02,200.79]],"ltp":4.2,"tv":5.32,"id":12474498}]}]}
{"op":"mcm","clk":"11827319281","pt":1723353700472,"mc":[{"id":"1.231613187","rc":[{"batb":[[0,4.2,4],[1,4.1,12.59],[2,1.03,200.79]],"ltp":4.2,"tv":5.32,"id":12474498}]}]}
{"op":"mcm","clk":"11827319380","pt":1723353702897,"mc":[{"id":"1.231613187","rc":[{"batb":[[0,4.1,12.59],[1,1.03,200.79],[2,1.02,200.79]],"ltp":4.2,"tv":5.32,"id":12474498}]}]}
{"op":"mcm","clk":"11827319471","pt":1723353705104,"mc":[{"id":"1.231613187","rc":[{"batb":[[0,4.2,4],[1,4.1,12.59],[2,1.03,200.79]],"ltp":4.2,"tv":5.32,"id":12474498}]}]}
{"op":"mcm","clk":"11827319575","pt":1723353707518,"mc":[{"id":"1.231613187","rc":[{"batb":[[0,4.1,12.59],[1,1.03,200.79],[2,1.02,200.79]],"ltp":4.2,"tv":5.32,"id":12474498}]}]}
{"op":"mcm","clk":"11827319663","pt":1723353709684,"mc":[{"id":"1.231613187","rc":[{"batb":[[0,4.2,4],[1,4.1,12.59],[2,1.03,200.79]],"ltp":4.2,"tv":5.32,"id":12474498}]}]}
{"op":"mcm","clk":"11827319771","pt":1723353711892,"mc":[{"id":"1.231613187","rc":[{"batb":[[0,4.1,12.59],[1,1.03,200.79],[2,1.02,200.79]],"ltp":4.2,"tv":5.32,"id":12474498}]}]}
{"op":"mcm","clk":"11827319861","pt":1723353714403,"mc":[{"id":"1.231613187","rc":[{"batb":[[0,4.2,4],[1,4.1,12.59],[2,1.03,200.79]],"ltp":4.2,"tv":5.32,"id":12474498}]}]}
{"op":"mcm","clk":"11827319961","pt":1723353716813,"mc":[{"id":"1.231613187","rc":[{"batb":[[0,4.1,12.59],[1,1.03,200.79],[2,1.02,200.79]],"ltp":4.2,"tv":5.32,"id":12474498}]}]}
{"op":"mcm","clk":"11827320034","pt":1723353719018,"mc":[{"id":"1.231613187","rc":[{"batb":[[0,4.2,4],[1,4.1,12.59],[2,1.03,200.79]],"ltp":4.2,"tv":5.32,"id":12474498}]}]}
{"op":"mcm","clk":"11827320166","pt":1723353722527,"mc":[{"id":"1.231613187","rc":[{"batb":[[0,4.1,12.59],[1,1.03,200.79],[2,1.02,200.79]],"ltp":4.2,"tv":5.32,"id":12474498}]}]}
{"op":"mcm","clk":"11827320278","pt":1723353724838,"mc":[{"id":"1.231613187","rc":[{"batb":[[0,4.2,4],[1,4.1,12.59],[2,1.03,200.79]],"ltp":4.2,"tv":5.32,"id":12474498}]}]}
{"op":"mcm","clk":"11827320405","pt":1723353727352,"mc":[{"id":"1.231613187","rc":[{"batb":[[0,4.1,12.59],[1,1.03,200.79],[2,1.02,200.79]],"ltp":4.2,"tv":5.32,"id":12474498}]}]}
{"op":"mcm","clk":"11827320499","pt":1723353729710,"mc":[{"id":"1.231613187","rc":[{"batb":[[0,4.2,4],[1,4.1,12.59],[2,1.03,200.79]],"ltp":4.2,"tv":5.32,"id":12474498}]}]}
{"op":"mcm","clk":"11827320582","pt":1723353732030,"mc":[{"id":"1.231613187","rc":[{"batb":[[0,4.1,12.59],[1,1.03,200.79],[2,1.02,200.79]],"ltp":4.2,"tv":5.32,"id":12474498}]}]}
{"op":"mcm","clk":"11827320667","pt":1723353734537,"mc":[{"id":"1.231613187","rc":[{"batb":[[0,4.2,4],[1,4.1,12.59],[2,1.03,200.79]],"ltp":4.2,"tv":5.32,"id":12474498}]}]}
{"op":"mcm","clk":"11827320754","pt":1723353736737,"mc":[{"id":"1.231613187","rc":[{"batb":[[0,4.1,12.59],[1,1.03,200.79],[2,1.02,200.79]],"ltp":4.2,"tv":5.32,"id":12474498}]}]}
{"op":"mcm","clk":"11827320841","pt":1723353738955,"mc":[{"id":"1.231613187","rc":[{"batb":[[0,4.2,4],[1,4.1,12.59],[2,1.03,200.79]],"ltp":4.2,"tv":5.32,"id":12474498}]}]}
{"op":"mcm","clk":"11827320925","pt":1723353741364,"mc":[{"id":"1.231613187","rc":[{"batb":[[0,4.1,12.59],[1,1.03,200.79],[2,1.02,200.79]],"ltp":4.2,"tv":5.32,"id":12474498}]}]}
{"op":"mcm","clk":"11827320997","pt":1723353743571,"mc":[{"id":"1.231613187","rc":[{"batb":[[0,4.2,4],[1,4.1,12.59],[2,1.03,200.79]],"ltp":4.2,"tv":5.32,"id":12474498}]}]}
{"op":"mcm","clk":"11827321065","pt":1723353746039,"mc":[{"id":"1.231613187","rc":[{"batb":[[0,4.1,12.59],[1,1.03,200.79],[2,1.02,200.79]],"ltp":4.2,"tv":5.32,"id":12474498}]}]}
{"op":"mcm","clk":"11827321148","pt":1723353748447,"mc":[{"id":"1.231613187","rc":[{"batb":[[0,4.2,4],[1,4.1,12.59],[2,1.03,200.79]],"ltp":4.2,"tv":5.32,"id":12474498}]}]}
{"op":"mcm","clk":"11827321233","pt":1723353750869,"mc":[{"id":"1.231613187","rc":[{"batb":[[0,4.1,12.59],[1,1.03,200.79],[2,1.02,200.79]],"ltp":4.2,"tv":5.32,"id":12474498}]}]}
{"op":"mcm","clk":"11827321312","pt":1723353753082,"mc":[{"id":"1.231613187","rc":[{"batb":[[0,4.2,4],[1,4.1,12.59],[2,1.03,200.79]],"ltp":4.2,"tv":5.32,"id":12474498}]}]}
{"op":"mcm","clk":"11827321400","pt":1723353755370,"mc":[{"id":"1.231613187","rc":[{"batb":[[0,4.1,12.59],[1,1.03,200.79],[2,1.02,200.79]],"ltp":4.2,"tv":5.32,"id":12474498}]}]}
{"op":"mcm","clk":"11827321465","pt":1723353757747,"mc":[{"id":"1.231613187","rc":[{"batb":[[0,4.2,4],[1,4.1,12.59],[2,1.03,200.79]],"ltp":4.2,"tv":5.32,"id":12474498}]}]}
{"op":"mcm","clk":"11827321540","pt":1723353760046,"mc":[{"id":"1.231613187","rc":[{"batb":[[0,4.1,12.59],[1,1.03,200.79],[2,1.02,200.79]],"ltp":4.2,"tv":5.32,"id":12474498}]}]}
{"op":"mcm","clk":"11827321610","pt":1723353762394,"mc":[{"id":"1.231613187","rc":[{"batb":[[0,4.2,4],[1,4.1,12.59],[2,1.03,200.79]],"ltp":4.2,"tv":5.32,"id":12474498}]}]}
{"op":"mcm","clk":"11827321697","pt":1723353764667,"mc":[{"id":"1.231613187","rc":[{"batb":[[0,4.1,12.59],[1,1.03,200.79],[2,1.02,200.79]],"ltp":4.2,"tv":5.32,"id":12474498}]}]}
{"op":"mcm","clk":"11827321780","pt":1723353767272,"mc":[{"id":"1.231613187","rc":[{"batb":[[0,4.2,4],[1,4.1,12.59],[2,1.03,200.79]],"ltp":4.2,"tv":5.32,"id":12474498}]}]}
{"op":"mcm","clk":"11827321862","pt":1723353769673,"mc":[{"id":"1.231613187","rc":[{"batb":[[0,4.1,12.59],[1,1.03,200.79],[2,1.02,200.79]],"ltp":4.2,"tv":5.32,"id":12474498}]}]}
{"op":"mcm","clk":"11827321925","pt":1723353771971,"mc":[{"id":"1.231613187","rc":[{"batb":[[0,4.2,4],[1,4.1,12.59],[2,1.03,200.79]],"ltp":4.2,"tv":5.32,"id":12474498}]}]}
{"op":"mcm","clk":"11827322024","pt":1723353774475,"mc":[{"id":"1.231613187","rc":[{"batb":[[0,4.1,12.59],[1,1.03,200.79],[2,1.02,200.79]],"ltp":4.2,"tv":5.32,"id":12474498}]}]}
{"op":"mcm","clk":"11827322165","pt":1723353778620,"mc":[{"id":"1.231613187","rc":[{"batb":[[0,4.2,4],[1,4.1,12.59],[2,1.03,200.79]],"ltp":4.2,"tv":5.32,"id":12474498}]}]}
{"op":"mcm","clk":"11827322233","pt":1723353781023,"mc":[{"id":"1.231613187","rc":[{"batb":[[0,4.1,12.59],[1,1.03,200.79],[2,1.02,200.79]],"ltp":4.2,"tv":5.32,"id":12474498}]}]}
{"op":"mcm","clk":"11827322356","pt":1723353784885,"mc":[{"id":"1.231613187","rc":[{"batb":[[0,4.2,4],[1,4.1,12.59],[2,1.03,200.79]],"ltp":4.2,"tv":5.32,"id":12474498}]}]}
{"op":"mcm","clk":"11827322440","pt":1723353787193,"mc":[{"id":"1.231613187","rc":[{"batb":[[0,4.1,12.59],[1,1.03,200.79],[2,1.02,200.79]],"ltp":4.2,"tv":5.32,"id":12474498}]}]}
{"op":"mcm","clk":"11827322580","pt":1723353790321,"mc":[{"id":"1.231613187","rc":[{"batb":[[0,4.2,4],[1,4.1,12.59],[2,1.03,200.79]],"ltp":4.2,"tv":5.32,"id":12474498}]}]}
{"op":"mcm","clk":"11827322685","pt":1723353792494,"mc":[{"id":"1.231613187","rc":[{"batb":[[0,4.1,12.59],[1,1.03,200.79],[2,1.02,200.79]],"ltp":4.2,"tv":5.32,"id":12474498}]}]}
{"op":"mcm","clk":"11827322788","pt":1723353795521,"mc":[{"id":"1.231613187","rc":[{"batb":[[0,4.2,4],[1,4.1,12.59],[2,1.03,200.79]],"ltp":4.2,"tv":5.32,"id":12474498}]}]}
{"op":"mcm","clk":"11827322869","pt":1723353797826,"mc":[{"id":"1.231613187","rc":[{"batb":[[0,4.1,12.59],[1,1.03,200.79],[2,1.02,200.79]],"ltp":4.2,"tv":5.32,"id":12474498}]}]}
{"op":"mcm","clk":"11827322953","pt":1723353800035,"mc":[{"id":"1.231613187","rc":[{"batb":[[0,4.2,4],[1,4.1,12.59],[2,1.03,200.79]],"ltp":4.2,"tv":5.32,"id":12474498}]}]}
{"op":"mcm","clk":"11827323051","pt":1723353802294,"mc":[{"id":"1.231613187","rc":[{"batb":[[0,4.1,12.59],[1,1.03,200.79],[2,1.02,200.79]],"ltp":4.2,"tv":5.32,"id":12474498}]}]}
{"op":"mcm","clk":"11827323123","pt":1723353804514,"mc":[{"id":"1.231613187","rc":[{"batb":[[0,4.2,4],[1,4.1,12.59],[2,1.03,200.79]],"ltp":4.2,"tv":5.32,"id":12474498}]}]}
{"op":"mcm","clk":"11827323221","pt":1723353807024,"mc":[{"id":"1.231613187","rc":[{"batb":[[0,4.1,12.59],[1,1.03,200.79],[2,1.02,200.79]],"ltp":4.2,"tv":5.32,"id":12474498}]}]}
{"op":"mcm","clk":"11827323314","pt":1723353809235,"mc":[{"id":"1.231613187","rc":[{"batb":[[0,4.2,4],[1,4.1,12.59],[2,1.03,200.79]],"ltp":4.2,"tv":5.32,"id":12474498}]}]}
{"op":"mcm","clk":"11827323415","pt":1723353811653,"mc":[{"id":"1.231613187","rc":[{"batb":[[0,4.1,12.59],[1,1.03,200.79],[2,1.02,200.79]],"ltp":4.2,"tv":5.32,"id":12474498}]}]}
{"op":"mcm","clk":"11827323514","pt":1723353814222,"mc":[{"id":"1.231613187","rc":[{"batb":[[0,4.2,4],[1,4.1,12.59],[2,1.03,200.79]],"ltp":4.2,"tv":5.32,"id":12474498}]}]}
{"op":"mcm","clk":"11827323615","pt":1723353816432,"mc":[{"id":"1.231613187","rc":[{"batb":[[0,4.1,12.59],[1,1.03,200.79],[2,1.02,200.79]],"ltp":4.2,"tv":5.32,"id":12474498}]}]}
{"op":"mcm","clk":"11827323703","pt":1723353818740,"mc":[{"id":"1.231613187","rc":[{"batb":[[0,4.2,4],[1,4.1,12.59],[2,1.03,200.79]],"ltp":4.2,"tv":5.32,"id":12474498}]}]}
{"op":"mcm","clk":"11827323813","pt":1723353821149,"mc":[{"id":"1.231613187","rc":[{"batb":[[0,4.1,12.59],[1,1.03,200.79],[2,1.02,200.79]],"ltp":4.2,"tv":5.32,"id":12474498}]}]}
{"op":"mcm","clk":"11827323889","pt":1723353823355,"mc":[{"id":"1.231613187","rc":[{"batb":[[0,4.2,4],[1,4.1,12.59],[2,1.03,200.79]],"ltp":4.2,"tv":5.32,"id":12474498}]}]}
{"op":"mcm","clk":"11827323975","pt":1723353825751,"mc":[{"id":"1.231613187","rc":[{"batb":[[0,4.1,12.59],[1,1.03,200.79],[2,1.02,200.79]],"ltp":4.2,"tv":5.32,"id":12474498}]}]}
{"op":"mcm","clk":"11827324088","pt":1723353828673,"mc":[{"id":"1.231613187","rc":[{"batb":[[0,4.2,4],[1,4.1,12.59],[2,1.03,200.79]],"ltp":4.2,"tv":5.32,"id":12474498}]}]}
{"op":"mcm","clk":"11827324178","pt":1723353830980,"mc":[{"id":"1.231613187","rc":[{"batb":[[0,4.1,12.59],[1,1.03,200.79],[2,1.02,200.79]],"ltp":4.2,"tv":5.32,"id":12474498}]}]}
{"op":"mcm","clk":"11827324299","pt":1723353833550,"mc":[{"id":"1.231613187","rc":[{"batb":[[0,4.2,4],[1,4.1,12.59],[2,1.03,200.79]],"ltp":4.2,"tv":5.32,"id":12474498}]}]}
{"op":"mcm","clk":"11827324401","pt":1723353835767,"mc":[{"id":"1.231613187","rc":[{"batb":[[0,4.1,12.59],[1,1.03,200.79],[2,1.02,200.79]],"ltp":4.2,"tv":5.32,"id":12474498}]}]}
{"op":"mcm","clk":"11827324487","pt":1723353838344,"mc":[{"id":"1.231613187","rc":[{"batb":[[0,4.2,4],[1,4.1,12.59],[2,1.03,200.79]],"ltp":4.2,"tv":5.32,"id":12474498}]}]}
{"op":"mcm","clk":"11827324584","pt":1723353840766,"mc":[{"id":"1.231613187","rc":[{"batb":[[0,4.1,12.59],[1,1.03,200.79],[2,1.02,200.79]],"ltp":4.2,"tv":5.32,"id":12474498}]}]}
{"op":"mcm","clk":"11827324722","pt":1723353843350,"mc":[{"id":"1.231613187","rc":[{"batb":[[0,4.2,4],[1,4.1,12.59],[2,1.03,200.79]],"ltp":4.2,"tv":5.32,"id":12474498}]}]}
{"op":"mcm","clk":"11827324837","pt":1723353845668,"mc":[{"id":"1.231613187","rc":[{"batb":[[0,4.1,12.59],[1,1.03,200.79],[2,1.02,200.79]],"ltp":4.2,"tv":5.32,"id":12474498}]}]}
{"op":"mcm","clk":"11827324911","pt":1723353848184,"mc":[{"id":"1.231613187","rc":[{"batb":[[0,4.2,4],[1,4.1,12.59],[2,1.03,200.79]],"ltp":4.2,"tv":5.32,"id":12474498}]}]}
{"op":"mcm","clk":"11827324991","pt":1723353850392,"mc":[{"id":"1.231613187","rc":[{"batb":[[0,4.1,12.59],[1,1.03,200.79],[2,1.02,200.79]],"ltp":4.2,"tv":5.32,"id":12474498}]}]}
{"op":"mcm","clk":"11827325087","pt":1723353853381,"mc":[{"id":"1.231613187","rc":[{"batb":[[0,4.2,4],[1,4.1,12.59],[2,1.03,200.79]],"ltp":4.2,"tv":5.32,"id":12474498}]}]}
{"op":"mcm","clk":"11827325240","pt":1723353855681,"mc":[{"id":"1.231613187","rc":[{"batb":[[0,4.1,12.59],[1,1.03,200.79],[2,1.02,200.79]],"ltp":4.2,"tv":5.32,"id":12474498}]}]}
{"op":"mcm","clk":"11827325360","pt":1723353858295,"mc":[{"id":"1.231613187","rc":[{"batb":[[0,4.2,4],[1,4.1,12.59],[2,1.03,200.79]],"ltp":4.2,"tv":5.32,"id":12474498}]}]}
{"op":"mcm","clk":"11827325480","pt":1723353860916,"mc":[{"id":"1.231613187","rc":[{"batb":[[0,4.1,12.59],[1,1.03,200.79],[2,1.02,200.79]],"ltp":4.2,"tv":5.32,"id":12474498}]}]}
{"op":"mcm","clk":"11827325604","pt":1723353863791,"mc":[{"id":"1.231613187","rc":[{"batb":[[0,4.2,4],[1,4.1,12.59],[2,1.03,200.79]],"ltp":4.2,"tv":5.32,"id":12474498}]}]}
{"op":"mcm","clk":"11827325689","pt":1723353866311,"mc":[{"id":"1.231613187","rc":[{"batb":[[0,4.1,12.59],[1,1.03,200.79],[2,1.02,200.79]],"ltp":4.2,"tv":5.32,"id":12474498}]}]}
{"op":"mcm","clk":"11827325825","pt":1723353869701,"mc":[{"id":"1.231613187","rc":[{"batb":[[0,4.2,4],[1,4.1,12.59],[2,1.03,200.79]],"ltp":4.2,"tv":5.32,"id":12474498}]}]}
{"op":"mcm","clk":"11827325920","pt":1723353872015,"mc":[{"id":"1.231613187","rc":[{"batb":[[0,4.1,12.59],[1,1.03,200.79],[2,1.02,200.79]],"ltp":4.2,"tv":5.32,"id":12474498}]}]}
{"op":"mcm","clk":"11827326000","pt":1723353874289,"mc":[{"id":"1.231613187","rc":[{"batb":[[0,4.2,4],[1,4.1,12.59],[2,1.03,200.79]],"ltp":4.2,"tv":5.32,"id":12474498}]}]}
{"op":"mcm","clk":"11827326094","pt":1723353876724,"mc":[{"id":"1.231613187","rc":[{"batb":[[0,4.1,12.59],[1,1.03,200.79],[2,1.02,200.79]],"ltp":4.2,"tv":5.32,"id":12474498}]}]}
{"op":"mcm","clk":"11827326195","pt":1723353879094,"mc":[{"id":"1.231613187","rc":[{"batb":[[0,4.2,4],[1,4.1,12.59],[2,1.03,200.79]],"ltp":4.2,"tv":5.32,"id":12474498}]}]}
{"op":"mcm","clk":"11827326337","pt":1723353881396,"mc":[{"id":"1.231613187","rc":[{"batb":[[0,4.1,12.59],[1,1.03,200.79],[2,1.02,200.79]],"ltp":4.2,"tv":5.32,"id":12474498}]}]}
{"op":"mcm","clk":"11827326452","pt":1723353883926,"mc":[{"id":"1.231613187","rc":[{"batb":[[0,4.2,4],[1,4.1,12.59],[2,1.03,200.79]],"ltp":4.2,"tv":5.32,"id":12474498}]}]}
{"op":"mcm","clk":"11827326578","pt":1723353886309,"mc":[{"id":"1.231613187","rc":[{"batb":[[0,4.1,12.59],[1,1.03,200.79],[2,1.02,200.79]],"ltp":4.2,"tv":5.32,"id":12474498}]}]}
{"op":"mcm","clk":"11827326687","pt":1723353888800,"mc":[{"id":"1.231613187","rc":[{"batb":[[0,4.2,4],[1,4.1,12.59],[2,1.03,200.79]],"ltp":4.2,"tv":5.32,"id":12474498}]}]}
{"op":"mcm","clk":"11827326776","pt":1723353891119,"mc":[{"id":"1.231613187","rc":[{"batb":[[0,4.1,12.59],[1,1.03,200.79],[2,1.02,200.79]],"ltp":4.2,"tv":5.32,"id":12474498}]}]}
{"op":"mcm","clk":"11827326889","pt":1723353893838,"mc":[{"id":"1.231613187","rc":[{"batb":[[0,4.2,4],[1,4.1,12.59],[2,1.03,200.79]],"ltp":4.2,"tv":5.32,"id":12474498}]}]}
{"op":"mcm","clk":"11827326958","pt":1723353896247,"mc":[{"id":"1.231613187","rc":[{"batb":[[0,4.1,12.59],[1,1.03,200.79],[2,1.02,200.79]],"ltp":4.2,"tv":5.32,"id":12474498}]}]}
{"op":"mcm","clk":"11827327065","pt":1723353899442,"mc":[{"id":"1.231613187","rc":[{"batb":[[0,4.2,4],[1,4.1,12.59],[2,1.03,200.79]],"ltp":4.2,"tv":5.32,"id":12474498}]}]}
{"op":"mcm","clk":"11827327170","pt":1723353901869,"mc":[{"id":"1.231613187","rc":[{"batb":[[0,4.1,12.59],[1,1.03,200.79],[2,1.02,200.79]],"ltp":4.2,"tv":5.32,"id":12474498}]}]}
{"op":"mcm","clk":"11827327285","pt":1723353904341,"mc":[{"id":"1.231613187","rc":[{"batb":[[0,4.2,4],[1,4.1,12.59],[2,1.03,200.79]],"ltp":4.2,"tv":5.32,"id":12474498}]}]}
{"op":"mcm","clk":"11827327382","pt":1723353906750,"mc":[{"id":"1.231613187","rc":[{"batb":[[0,4.1,12.59],[1,1.03,200.79],[2,1.02,200.79]],"ltp":4.2,"tv":5.32,"id":12474498}]}]}
{"op":"mcm","clk":"11827327506","pt":1723353908962,"mc":[{"id":"1.231613187","rc":[{"batb":[[0,4.2,4],[1,4.1,12.59],[2,1.03,200.79]],"ltp":4.2,"tv":5.32,"id":12474498}]}]}
{"op":"mcm","clk":"11827327601","pt":1723353911272,"mc":[{"id":"1.231613187","rc":[{"batb":[[0,4.1,12.59],[1,1.03,200.79],[2,1.02,200.79]],"ltp":4.2,"tv":5.32,"id":12474498}]}]}
{"op":"mcm","clk":"11827327706","pt":1723353913839,"mc":[{"id":"1.231613187","rc":[{"batb":[[0,4.2,4],[1,4.1,12.59],[2,1.03,200.79]],"ltp":4.2,"tv":5.32,"id":12474498}]}]}
{"op":"mcm","clk":"11827327810","pt":1723353916155,"mc":[{"id":"1.231613187","rc":[{"batb":[[0,4.1,12.59],[1,1.03,200.79],[2,1.02,200.79]],"ltp":4.2,"tv":5.32,"id":12474498}]}]}
{"op":"mcm","clk":"11827327920","pt":1723353919183,"mc":[{"id":"1.231613187","rc":[{"batb":[[0,4.2,4],[1,4.1,12.59],[2,1.03,200.79]],"ltp":4.2,"tv":5.32,"id":12474498}]}]}
{"op":"mcm","clk":"11827328009","pt":1723353921592,"mc":[{"id":"1.231613187","rc":[{"batb":[[0,4.1,12.59],[1,1.03,200.79],[2,1.02,200.79]],"ltp":4.2,"tv":5.32,"id":12474498}]}]}
{"op":"mcm","clk":"11827328135","pt":1723353925456,"mc":[{"id":"1.231613187","rc":[{"batb":[[0,4.2,4],[1,4.1,12.59],[2,1.03,200.79]],"ltp":4.2,"tv":5.32,"id":12474498}]}]}
{"op":"mcm","clk":"11827328242","pt":1723353928277,"mc":[{"id":"1.231613187","rc":[{"batb":[[0,4.1,12.59],[1,1.03,200.79],[2,1.02,200.79]],"ltp":4.2,"tv":5.32,"id":12474498}]}]}
{"op":"mcm","clk":"11827328365","pt":1723353930998,"mc":[{"id":"1.231613187","rc":[{"batb":[[0,4.2,4],[1,4.1,12.59],[2,1.03,200.79]],"ltp":4.2,"tv":5.32,"id":12474498}]}]}
{"op":"mcm","clk":"11827328459","pt":1723353933302,"mc":[{"id":"1.231613187","rc":[{"batb":[[0,4.1,12.59],[1,1.03,200.79],[2,1.02,200.79]],"ltp":4.2,"tv":5.32,"id":12474498}]}]}
{"op":"mcm","clk":"11827328558","pt":1723353935613,"mc":[{"id":"1.231613187","rc":[{"batb":[[0,4.2,4],[1,4.1,12.59],[2,1.03,200.79]],"ltp":4.2,"tv":5.32,"id":12474498}]}]}
{"op":"mcm","clk":"11827328666","pt":1723353937776,"mc":[{"id":"1.231613187","rc":[{"batb":[[0,4.1,12.59],[1,1.03,200.79],[2,1.02,200.79]],"ltp":4.2,"tv":5.32,"id":12474498}]}]}
{"op":"mcm","clk":"11827328750","pt":1723353940082,"mc":[{"id":"1.231613187","rc":[{"batb":[[0,4.2,4],[1,4.1,12.59],[2,1.03,200.79]],"ltp":4.2,"tv":5.32,"id":12474498}]}]}
{"op":"mcm","clk":"11827328851","pt":1723353942288,"mc":[{"id":"1.231613187","rc":[{"batb":[[0,4.1,12.59],[1,1.03,200.79],[2,1.02,200.79]],"ltp":4.2,"tv":5.32,"id":12474498}]}]}
{"op":"mcm","clk":"11827328958","pt":1723353944600,"mc":[{"id":"1.231613187","rc":[{"batb":[[0,4.2,4],[1,4.1,12.59],[2,1.03,200.79]],"ltp":4.2,"tv":5.32,"id":12474498}]}]}
{"op":"mcm","clk":"11827329055","pt":1723353947106,"mc":[{"id":"1.231613187","rc":[{"batb":[[0,4.1,12.59],[1,1.03,200.79],[2,1.02,200.79]],"ltp":4.2,"tv":5.32,"id":12474498}]}]}
{"op":"mcm","clk":"11827329152","pt":1723353949310,"mc":[{"id":"1.231613187","rc":[{"batb":[[0,4.2,4],[1,4.1,12.59],[2,1.03,200.79]],"ltp":4.2,"tv":5.32,"id":12474498}]}]}
{"op":"mcm","clk":"11827329251","pt":1723353951616,"mc":[{"id":"1.231613187","rc":[{"batb":[[0,4.1,12.59],[1,1.03,200.79],[2,1.02,200.79]],"ltp":4.2,"tv":5.32,"id":12474498}]}]}
{"op":"mcm","clk":"11827329420","pt":1723353955214,"mc":[{"id":"1.231613187","rc":[{"batb":[[0,4.2,4],[1,4.1,12.59],[2,1.03,200.79]],"ltp":4.2,"tv":5.32,"id":12474498}]}]}
{"op":"mcm","clk":"11827329537","pt":1723353957890,"mc":[{"id":"1.231613187","rc":[{"batb":[[0,4.1,12.59],[1,1.03,200.79],[2,1.02,200.79]],"ltp":4.2,"tv":5.32,"id":12474498}]}]}
{"op":"mcm","clk":"11827329645","pt":1723353960200,"mc":[{"id":"1.231613187","rc":[{"batb":[[0,4.2,4],[1,4.1,12.59],[2,1.03,200.79]],"ltp":4.2,"tv":5.32,"id":12474498}]}]}
{"op":"mcm","clk":"11827329763","pt":1723353962511,"mc":[{"id":"1.231613187","rc":[{"batb":[[0,4.1,12.59],[1,1.03,200.79],[2,1.02,200.79]],"ltp":4.2,"tv":5.32,"id":12474498}]}]}
{"op":"mcm","clk":"11827329926","pt":1723353966224,"mc":[{"id":"1.231613187","rc":[{"batb":[[0,4.2,4],[1,4.1,12.59],[2,1.03,200.79]],"ltp":4.2,"tv":5.32,"id":12474498}]}]}
{"op":"mcm","clk":"11827330009","pt":1723353968531,"mc":[{"id":"1.231613187","rc":[{"batb":[[0,4.1,12.59],[1,1.03,200.79],[2,1.02,200.79]],"ltp":4.2,"tv":5.32,"id":12474498}]}]}
{"op":"mcm","clk":"11827330088","pt":1723353970936,"mc":[{"id":"1.231613187","rc":[{"batb":[[0,4.2,4],[1,4.1,12.59],[2,1.03,200.79]],"ltp":4.2,"tv":5.32,"id":12474498}]}]}
{"op":"mcm","clk":"11827330184","pt":1723353973140,"mc":[{"id":"1.231613187","rc":[{"batb":[[0,4.1,12.59],[1,1.03,200.79],[2,1.02,200.79]],"ltp":4.2,"tv":5.32,"id":12474498}]}]}
{"op":"mcm","clk":"11827330273","pt":1723353975605,"mc":[{"id":"1.231613187","rc":[{"batb":[[0,4.2,4],[1,4.1,12.59],[2,1.03,200.79]],"ltp":4.2,"tv":5.32,"id":12474498}]}]}
{"op":"mcm","clk":"11827330370","pt":1723353978012,"mc":[{"id":"1.231613187","rc":[{"batb":[[0,4.1,12.59],[1,1.03,200.79],[2,1.02,200.79]],"ltp":4.2,"tv":5.32,"id":12474498}]}]}
{"op":"mcm","clk":"11827330471","pt":1723353980217,"mc":[{"id":"1.231613187","rc":[{"batb":[[0,4.2,4],[1,4.1,12.59],[2,1.03,200.79]],"ltp":4.2,"tv":5.32,"id":12474498}]}]}
{"op":"mcm","clk":"11827330588","pt":1723353982727,"mc":[{"id":"1.231613187","rc":[{"batb":[[0,4.1,12.59],[1,1.03,200.79],[2,1.02,200.79]],"ltp":4.2,"tv":5.32,"id":12474498}]}]}
{"op":"mcm","clk":"11827330676","pt":1723353984929,"mc":[{"id":"1.231613187","rc":[{"batb":[[0,4.2,4],[1,4.1,12.59],[2,1.03,200.79]],"ltp":4.2,"tv":5.32,"id":12474498}]}]}
{"op":"mcm","clk":"11827330759","pt":1723353987335,"mc":[{"id":"1.231613187","rc":[{"batb":[[0,4.1,12.59],[1,1.03,200.79],[2,1.02,200.79]],"ltp":4.2,"tv":5.32,"id":12474498}]}]}
{"op":"mcm","clk":"11827330841","pt":1723353989651,"mc":[{"id":"1.231613187","rc":[{"batb":[[0,4.2,4],[1,4.1,12.59],[2,1.03,200.79]],"ltp":4.2,"tv":5.32,"id":12474498}]}]}
{"op":"mcm","clk":"11827330922","pt":1723353991973,"mc":[{"id":"1.231613187","rc":[{"batb":[[0,4.1,12.59],[1,1.03,200.79],[2,1.02,200.79]],"ltp":4.2,"tv":5.32,"id":12474498}]}]}
{"op":"mcm","clk":"11827331020","pt":1723353994640,"mc":[{"id":"1.231613187","rc":[{"batb":[[0,4.2,4],[1,4.1,12.59],[2,1.03,200.79]],"ltp":4.2,"tv":5.32,"id":12474498}]}]}
{"op":"mcm","clk":"11827331088","pt":1723353996838,"mc":[{"id":"1.231613187","rc":[{"batb":[[0,4.1,12.59],[1,1.03,200.79],[2,1.02,200.79]],"ltp":4.2,"tv":5.32,"id":12474498}]}]}
{"op":"mcm","clk":"11827331191","pt":1723353999342,"mc":[{"id":"1.231613187","rc":[{"batb":[[0,4.2,4],[1,4.1,12.59],[2,1.03,200.79]],"ltp":4.2,"tv":5.32,"id":12474498}]}]}
{"op":"mcm","clk":"11827331283","pt":1723354001759,"mc":[{"id":"1.231613187","rc":[{"batb":[[0,4.1,12.59],[1,1.03,200.79],[2,1.02,200.79]],"ltp":4.2,"tv":5.32,"id":12474498}]}]}
{"op":"mcm","clk":"11827331359","pt":1723354004165,"mc":[{"id":"1.231613187","rc":[{"batb":[[0,4.2,4],[1,4.1,12.59],[2,1.03,200.79]],"ltp":4.2,"tv":5.32,"id":12474498}]}]}
{"op":"mcm","clk":"11827331448","pt":1723354006478,"mc":[{"id":"1.231613187","rc":[{"batb":[[0,4.1,12.59],[1,1.03,200.79],[2,1.02,200.79]],"ltp":4.2,"tv":5.32,"id":12474498}]}]}
{"op":"mcm","clk":"11827331537","pt":1723354008994,"mc":[{"id":"1.231613187","rc":[{"batb":[[0,4.2,4],[1,4.1,12.59],[2,1.03,200.79]],"ltp":4.2,"tv":5.32,"id":12474498}]}]}
{"op":"mcm","clk":"11827331627","pt":1723354011375,"mc":[{"id":"1.231613187","rc":[{"batb":[[0,4.1,12.59],[1,1.03,200.79],[2,1.02,200.79]],"ltp":4.2,"tv":5.32,"id":12474498}]}]}
{"op":"mcm","clk":"11827331726","pt":1723354013678,"mc":[{"id":"1.231613187","rc":[{"batb":[[0,4.2,4],[1,4.1,12.59],[2,1.03,200.79]],"ltp":4.2,"tv":5.32,"id":12474498}]}]}
{"op":"mcm","clk":"11827331825","pt":1723354016289,"mc":[{"id":"1.231613187","rc":[{"batb":[[0,4.1,12.59],[1,1.03,200.79],[2,1.02,200.79]],"ltp":4.2,"tv":5.32,"id":12474498}]}]}
{"op":"mcm","clk":"11827331944","pt":1723354019372,"mc":[{"id":"1.231613187","rc":[{"batb":[[0,4.2,4],[1,4.1,12.59],[2,1.03,200.79]],"ltp":4.2,"tv":5.32,"id":12474498}]}]}
{"op":"mcm","clk":"11827332042","pt":1723354021684,"mc":[{"id":"1.231613187","rc":[{"batb":[[0,4.1,12.59],[1,1.03,200.79],[2,1.02,200.79]],"ltp":4.2,"tv":5.32,"id":12474498}]}]}
{"op":"mcm","clk":"11827332141","pt":1723354023903,"mc":[{"id":"1.231613187","rc":[{"batb":[[0,4.2,4],[1,4.1,12.59],[2,1.03,200.79]],"ltp":4.2,"tv":5.32,"id":12474498}]}]}
{"op":"mcm","clk":"11827332236","pt":1723354026209,"mc":[{"id":"1.231613187","rc":[{"batb":[[0,4.1,12.59],[1,1.03,200.79],[2,1.02,200.79]],"ltp":4.2,"tv":5.32,"id":12474498}]}]}
{"op":"mcm","clk":"11827332324","pt":1723354028370,"mc":[{"id":"1.231613187","rc":[{"batb":[[0,4.2,4],[1,4.1,12.59],[2,1.03,200.79]],"ltp":4.2,"tv":5.32,"id":12474498}]}]}
{"op":"mcm","clk":"11827332413","pt":1723354030785,"mc":[{"id":"1.231613187","rc":[{"batb":[[0,4.1,12.59],[1,1.03,200.79],[2,1.02,200.79]],"ltp":4.2,"tv":5.32,"id":12474498}]}]}
{"op":"mcm","clk":"11827332504","pt":1723354033180,"mc":[{"id":"1.231613187","rc":[{"batb":[[0,4.2,4],[1,4.1,12.59],[2,1.03,200.79]],"ltp":4.2,"tv":5.32,"id":12474498}]}]}
{"op":"mcm","clk":"11827332584","pt":1723354035492,"mc":[{"id":"1.231613187","rc":[{"batb":[[0,4.1,12.59],[1,1.03,200.79],[2,1.02,200.79]],"ltp":4.2,"tv":5.32,"id":12474498}]}]}
{"op":"mcm","clk":"11827332674","pt":1723354037800,"mc":[{"id":"1.231613187","rc":[{"batb":[[0,4.2,4],[1,4.1,12.59],[2,1.03,200.79]],"ltp":4.2,"tv":5.32,"id":12474498}]}]}
{"op":"mcm","clk":"11827332774","pt":1723354040105,"mc":[{"id":"1.231613187","rc":[{"batb":[[0,4.1,12.59],[1,1.03,200.79],[2,1.02,200.79]],"ltp":4.2,"tv":5.32,"id":12474498}]}]}
{"op":"mcm","clk":"11827332858","pt":1723354042626,"mc":[{"id":"1.231613187","rc":[{"batb":[[0,4.2,4],[1,4.1,12.59],[2,1.03,200.79]],"ltp":4.2,"tv":5.32,"id":12474498}]}]}
{"op":"mcm","clk":"11827332939","pt":1723354045194,"mc":[{"id":"1.231613187","rc":[{"batb":[[0,4.1,12.59],[1,1.03,200.79],[2,1.02,200.79]],"ltp":4.2,"tv":5.32,"id":12474498}]}]}
{"op":"mcm","clk":"11827333026","pt":1723354047612,"mc":[{"id":"1.231613187","rc":[{"batb":[[0,4.2,4],[1,4.1,12.59],[2,1.03,200.79]],"ltp":4.2,"tv":5.32,"id":12474498}]}]}
{"op":"mcm","clk":"11827333113","pt":1723354050328,"mc":[{"id":"1.231613187","rc":[{"batb":[[0,4.1,12.59],[1,1.03,200.79],[2,1.02,200.79]],"ltp":4.2,"tv":5.32,"id":12474498}]}]}
{"op":"mcm","clk":"11827333216","pt":1723354052538,"mc":[{"id":"1.231613187","rc":[{"batb":[[0,4.2,4],[1,4.1,12.59],[2,1.03,200.79]],"ltp":4.2,"tv":5.32,"id":12474498}]}]}
{"op":"mcm","clk":"11827333330","pt":1723354054700,"mc":[{"id":"1.231613187","rc":[{"batb":[[0,4.1,12.59],[1,1.03,200.79],[2,1.02,200.79]],"ltp":4.2,"tv":5.32,"id":12474498}]}]}
{"op":"mcm","clk":"11827333524","pt":1723354057321,"mc":[{"id":"1.231613187","rc":[{"batb":[[0,4.2,4],[1,4.1,12.59],[2,1.03,200.79]],"ltp":4.2,"tv":5.32,"id":12474498}]}]}
{"op":"mcm","clk":"11827333657","pt":1723354059630,"mc":[{"id":"1.231613187","rc":[{"batb":[[0,4.1,12.59],[1,1.03,200.79],[2,1.02,200.79]],"ltp":4.2,"tv":5.32,"id":12474498}]}]}
{"op":"mcm","clk":"11827333808","pt":1723354062016,"mc":[{"id":"1.231613187","rc":[{"batb":[[0,4.2,4],[1,4.1,12.59],[2,1.03,200.79]],"ltp":4.2,"tv":5.32,"id":12474498}]}]}
{"op":"mcm","clk":"11827333938","pt":1723354064329,"mc":[{"id":"1.231613187","rc":[{"batb":[[0,4.1,12.59],[1,1.03,200.79],[2,1.02,200.79]],"ltp":4.2,"tv":5.32,"id":12474498}]}]}
{"op":"mcm","clk":"11827334019","pt":1723354066837,"mc":[{"id":"1.231613187","rc":[{"batb":[[0,4.2,4],[1,4.1,12.59],[2,1.03,200.79]],"ltp":4.2,"tv":5.32,"id":12474498}]}]}
{"op":"mcm","clk":"11827334106","pt":1723354069044,"mc":[{"id":"1.231613187","rc":[{"batb":[[0,4.1,12.59],[1,1.03,200.79],[2,1.02,200.79]],"ltp":4.2,"tv":5.32,"id":12474498}]}]}
{"op":"mcm","clk":"11827334234","pt":1723354072036,"mc":[{"id":"1.231613187","rc":[{"batb":[[0,4.2,4],[1,4.1,12.59],[2,1.03,200.79]],"ltp":4.2,"tv":5.32,"id":12474498}]}]}
{"op":"mcm","clk":"11827334304","pt":1723354074345,"mc":[{"id":"1.231613187","rc":[{"batb":[[0,4.1,12.59],[1,1.03,200.79],[2,1.02,200.79]],"ltp":4.2,"tv":5.32,"id":12474498}]}]}
{"op":"mcm","clk":"11827334398","pt":1723354076665,"mc":[{"id":"1.231613187","rc":[{"batb":[[0,4.2,4],[1,4.1,12.59],[2,1.03,200.79]],"ltp":4.2,"tv":5.32,"id":12474498}]}]}
{"op":"mcm","clk":"11827334506","pt":1723354078936,"mc":[{"id":"1.231613187","rc":[{"batb":[[0,4.1,12.59],[1,1.03,200.79],[2,1.02,200.79]],"ltp":4.2,"tv":5.32,"id":12474498}]}]}
{"op":"mcm","clk":"11827334629","pt":1723354081768,"mc":[{"id":"1.231613187","rc":[{"batb":[[0,4.2,4],[1,4.1,12.59],[2,1.03,200.79]],"ltp":4.2,"tv":5.32,"id":12474498}]}]}
{"op":"mcm","clk":"11827334730","pt":1723354084040,"mc":[{"id":"1.231613187","rc":[{"batb":[[0,4.1,12.59],[1,1.03,200.79],[2,1.02,200.79]],"ltp":4.2,"tv":5.32,"id":12474498}]}]}
{"op":"mcm","clk":"11827334859","pt":1723354086663,"mc":[{"id":"1.231613187","rc":[{"batb":[[0,4.2,4],[1,4.1,12.59],[2,1.03,200.79]],"ltp":4.2,"tv":5.32,"id":12474498}]}]}
{"op":"mcm","clk":"11827334954","pt":1723354088972,"mc":[{"id":"1.231613187","rc":[{"batb":[[0,4.1,12.59],[1,1.03,200.79],[2,1.02,200.79]],"ltp":4.2,"tv":5.32,"id":12474498}]}]}
{"op":"mcm","clk":"11827335051","pt":1723354091587,"mc":[{"id":"1.231613187","rc":[{"batb":[[0,4.2,4],[1,4.1,12.59],[2,1.03,200.79]],"ltp":4.2,"tv":5.32,"id":12474498}]}]}
{"op":"mcm","clk":"11827335143","pt":1723354093952,"mc":[{"id":"1.231613187","rc":[{"batb":[[0,4.1,12.59],[1,1.03,200.79],[2,1.02,200.79]],"ltp":4.2,"tv":5.32,"id":12474498}]}]}
{"op":"mcm","clk":"11827335250","pt":1723354096994,"mc":[{"id":"1.231613187","rc":[{"batb":[[0,4.2,4],[1,4.1,12.59],[2,1.03,200.79]],"ltp":4.2,"tv":5.32,"id":12474498}]}]}
{"op":"mcm","clk":"11827335344","pt":1723354099361,"mc":[{"id":"1.231613187","rc":[{"batb":[[0,4.1,12.59],[1,1.03,200.79],[2,1.02,200.79]],"ltp":4.2,"tv":5.32,"id":12474498}]}]}
{"op":"mcm","clk":"11827335448","pt":1723354102177,"mc":[{"id":"1.231613187","rc":[{"batb":[[0,4.2,4],[1,4.1,12.59],[2,1.03,200.79]],"ltp":4.2,"tv":5.32,"id":12474498}]}]}
{"op":"mcm","clk":"11827335535","pt":1723354104605,"mc":[{"id":"1.231613187","rc":[{"batb":[[0,4.1,12.59],[1,1.03,200.79],[2,1.02,200.79]],"ltp":4.2,"tv":5.32,"id":12474498}]}]}
{"op":"mcm","clk":"11827335625","pt":1723354106871,"mc":[{"id":"1.231613187","rc":[{"batb":[[0,4.2,4],[1,4.1,12.59],[2,1.03,200.79]],"ltp":4.2,"tv":5.32,"id":12474498}]}]}
{"op":"mcm","clk":"11827335718","pt":1723354109184,"mc":[{"id":"1.231613187","rc":[{"batb":[[0,4.1,12.59],[1,1.03,200.79],[2,1.02,200.79]],"ltp":4.2,"tv":5.32,"id":12474498}]}]}
{"op":"mcm","clk":"11827335815","pt":1723354111807,"mc":[{"id":"1.231613187","rc":[{"batb":[[0,4.2,4],[1,4.1,12.59],[2,1.03,200.79]],"ltp":4.2,"tv":5.32,"id":12474498}]}]}
{"op":"mcm","clk":"11827335916","pt":1723354114327,"mc":[{"id":"1.231613187","rc":[{"batb":[[0,4.1,12.59],[1,1.03,200.79],[2,1.02,200.79]],"ltp":4.2,"tv":5.32,"id":12474498}]}]}
{"op":"mcm","clk":"11827336026","pt":1723354116689,"mc":[{"id":"1.231613187","rc":[{"batb":[[0,4.2,4],[1,4.1,12.59],[2,1.03,200.79]],"ltp":4.2,"tv":5.32,"id":12474498}]}]}
{"op":"mcm","clk":"11827336122","pt":1723354119010,"mc":[{"id":"1.231613187","rc":[{"batb":[[0,4.1,12.59],[1,1.03,200.79],[2,1.02,200.79]],"ltp":4.2,"tv":5.32,"id":12474498}]}]}
{"op":"mcm","clk":"11827336235","pt":1723354121223,"mc":[{"id":"1.231613187","rc":[{"batb":[[0,4.2,4],[1,4.1,12.59],[2,1.03,200.79]],"ltp":4.2,"tv":5.32,"id":12474498}]}]}
{"op":"mcm","clk":"11827336344","pt":1723354123390,"mc":[{"id":"1.231613187","rc":[{"batb":[[0,4.1,12.59],[1,1.03,200.79],[2,1.02,200.79]],"ltp":4.2,"tv":5.32,"id":12474498}]}]}
{"op":"mcm","clk":"11827336439","pt":1723354125999,"mc":[{"id":"1.231613187","rc":[{"batb":[[0,4.2,4],[1,4.1,12.59],[2,1.03,200.79]],"ltp":4.2,"tv":5.32,"id":12474498}]}]}
{"op":"mcm","clk":"11827336596","pt":1723354129920,"mc":[{"id":"1.231613187","rc":[{"batb":[[0,4.1,12.59],[1,1.03,200.79],[2,1.02,200.79]],"ltp":4.2,"tv":5.32,"id":12474498}]}]}
{"op":"mcm","clk":"11827336688","pt":1723354132036,"mc":[{"id":"1.231613187","rc":[{"batb":[[0,4.2,4],[1,4.1,12.59],[2,1.03,200.79]],"ltp":4.2,"tv":5.32,"id":12474498}]}]}
{"op":"mcm","clk":"11827336762","pt":1723354134263,"mc":[{"id":"1.231613187","rc":[{"batb":[[0,4.1,12.59],[1,1.03,200.79],[2,1.02,200.79]],"ltp":4.2,"tv":5.32,"id":12474498}]}]}
{"op":"mcm","clk":"11827336876","pt":1723354136700,"mc":[{"id":"1.231613187","rc":[{"batb":[[0,4.2,4],[1,4.1,12.59],[2,1.03,200.79]],"ltp":4.2,"tv":5.32,"id":12474498}]}]}
{"op":"mcm","clk":"11827336983","pt":1723354139110,"mc":[{"id":"1.231613187","rc":[{"batb":[[0,4.1,12.59],[1,1.03,200.79],[2,1.02,200.79]],"ltp":4.2,"tv":5.32,"id":12474498}]}]}
{"op":"mcm","clk":"11827337094","pt":1723354141624,"mc":[{"id":"1.231613187","rc":[{"batb":[[0,4.2,4],[1,4.1,12.59],[2,1.03,200.79]],"ltp":4.2,"tv":5.32,"id":12474498}]}]}
{"op":"mcm","clk":"11827337187","pt":1723354143925,"mc":[{"id":"1.231613187","rc":[{"batb":[[0,4.1,12.59],[1,1.03,200.79],[2,1.02,200.79]],"ltp":4.2,"tv":5.32,"id":12474498}]}]}
{"op":"mcm","clk":"11827337287","pt":1723354146639,"mc":[{"id":"1.231613187","rc":[{"batb":[[0,4.2,4],[1,4.1,12.59],[2,1.03,200.79]],"ltp":4.2,"tv":5.32,"id":12474498}]}]}
{"op":"mcm","clk":"11827337377","pt":1723354149050,"mc":[{"id":"1.231613187","rc":[{"batb":[[0,4.1,12.59],[1,1.03,200.79],[2,1.02,200.79]],"ltp":4.2,"tv":5.32,"id":12474498}]}]}
{"op":"mcm","clk":"11827337497","pt":1723354151218,"mc":[{"id":"1.231613187","rc":[{"batb":[[0,4.2,4],[1,4.1,12.59],[2,1.03,200.79]],"ltp":4.2,"tv":5.32,"id":12474498}]}]}
{"op":"mcm","clk":"11827337618","pt":1723354154124,"mc":[{"id":"1.231613187","rc":[{"batb":[[0,4.1,12.59],[1,1.03,200.79],[2,1.02,200.79]],"ltp":4.2,"tv":5.32,"id":12474498}]}]}
{"op":"mcm","clk":"11827337755","pt":1723354156350,"mc":[{"id":"1.231613187","rc":[{"batb":[[0,4.2,4],[1,4.1,12.59],[2,1.03,200.79]],"ltp":4.2,"tv":5.32,"id":12474498}]}]}
{"op":"mcm","clk":"11827337877","pt":1723354158921,"mc":[{"id":"1.231613187","rc":[{"batb":[[0,4.1,12.59],[1,1.03,200.79],[2,1.02,200.79]],"ltp":4.2,"tv":5.32,"id":12474498}]}]}
{"op":"mcm","clk":"11827338017","pt":1723354161129,"mc":[{"id":"1.231613187","rc":[{"batb":[[0,4.2,4],[1,4.1,12.59],[2,1.03,200.79]],"ltp":4.2,"tv":5.32,"id":12474498}]}]}
{"op":"mcm","clk":"11827338142","pt":1723354163438,"mc":[{"id":"1.231613187","rc":[{"batb":[[0,4.1,12.59],[1,1.03,200.79],[2,1.02,200.79]],"ltp":4.2,"tv":5.32,"id":12474498}]}]}
{"op":"mcm","clk":"11827338260","pt":1723354165638,"mc":[{"id":"1.231613187","rc":[{"batb":[[0,4.2,4],[1,4.1,12.59],[2,1.03,200.79]],"ltp":4.2,"tv":5.32,"id":12474498}]}]}
{"op":"mcm","clk":"11827338376","pt":1723354168766,"mc":[{"id":"1.231613187","rc":[{"batb":[[0,4.1,12.59],[1,1.03,200.79],[2,1.02,200.79]],"ltp":4.2,"tv":5.32,"id":12474498}]}]}
{"op":"mcm","clk":"11827338484","pt":1723354170964,"mc":[{"id":"1.231613187","rc":[{"batb":[[0,4.2,4],[1,4.1,12.59],[2,1.03,200.79]],"ltp":4.2,"tv":5.32,"id":12474498}]}]}
{"op":"mcm","clk":"11827338569","pt":1723354173268,"mc":[{"id":"1.231613187","rc":[{"batb":[[0,4.1,12.59],[1,1.03,200.79],[2,1.02,200.79]],"ltp":4.2,"tv":5.32,"id":12474498}]}]}
{"op":"mcm","clk":"11827338651","pt":1723354175441,"mc":[{"id":"1.231613187","rc":[{"batb":[[0,4.2,4],[1,4.1,12.59],[2,1.03,200.79]],"ltp":4.2,"tv":5.32,"id":12474498}]}]}
{"op":"mcm","clk":"11827338762","pt":1723354177948,"mc":[{"id":"1.231613187","rc":[{"batb":[[0,4.1,12.59],[1,1.03,200.79],[2,1.02,200.79]],"ltp":4.2,"tv":5.32,"id":12474498}]}]}
{"op":"mcm","clk":"11827338850","pt":1723354180054,"mc":[{"id":"1.231613187","rc":[{"batb":[[0,4.2,4],[1,4.1,12.59],[2,1.03,200.79]],"ltp":4.2,"tv":5.32,"id":12474498}]}]}
{"op":"mcm","clk":"11827338927","pt":1723354182568,"mc":[{"id":"1.231613187","rc":[{"batb":[[0,4.1,12.59],[1,1.03,200.79],[2,1.02,200.79]],"ltp":4.2,"tv":5.32,"id":12474498}]}]}
{"op":"mcm","clk":"11827339020","pt":1723354184772,"mc":[{"id":"1.231613187","rc":[{"batb":[[0,4.2,4],[1,4.1,12.59],[2,1.03,200.79]],"ltp":4.2,"tv":5.32,"id":12474498}]}]}
{"op":"mcm","clk":"11827339133","pt":1723354187281,"mc":[{"id":"1.231613187","rc":[{"batb":[[0,4.1,12.59],[1,1.03,200.79],[2,1.02,200.79]],"ltp":4.2,"tv":5.32,"id":12474498}]}]}
{"op":"mcm","clk":"11827339241","pt":1723354189486,"mc":[{"id":"1.231613187","rc":[{"batb":[[0,4.2,4],[1,4.1,12.59],[2,1.03,200.79]],"ltp":4.2,"tv":5.32,"id":12474498}]}]}
{"op":"mcm","clk":"11827339358","pt":1723354191894,"mc":[{"id":"1.231613187","rc":[{"batb":[[0,4.1,12.59],[1,1.03,200.79],[2,1.02,200.79]],"ltp":4.2,"tv":5.32,"id":12474498}]}]}
{"op":"mcm","clk":"11827339454","pt":1723354194061,"mc":[{"id":"1.231613187","rc":[{"batb":[[0,4.2,4],[1,4.1,12.59],[2,1.03,200.79]],"ltp":4.2,"tv":5.32,"id":12474498}]}]}
{"op":"mcm","clk":"11827339530","pt":1723354196474,"mc":[{"id":"1.231613187","rc":[{"batb":[[0,4.1,12.59],[1,1.03,200.79],[2,1.02,200.79]],"ltp":4.2,"tv":5.32,"id":12474498}]}]}
{"op":"mcm","clk":"11827339607","pt":1723354198773,"mc":[{"id":"1.231613187","rc":[{"batb":[[0,4.2,4],[1,4.1,12.59],[2,1.03,200.79]],"ltp":4.2,"tv":5.32,"id":12474498}]}]}
{"op":"mcm","clk":"11827339711","pt":1723354201498,"mc":[{"id":"1.231613187","rc":[{"batb":[[0,4.1,12.59],[1,1.03,200.79],[2,1.02,200.79]],"ltp":4.2,"tv":5.32,"id":12474498}]}]}
{"op":"mcm","clk":"11827339881","pt":1723354204800,"mc":[{"id":"1.231613187","rc":[{"batb":[[0,4.2,4],[1,4.1,12.59],[2,1.03,200.79]],"ltp":4.2,"tv":5.32,"id":12474498}]}]}
{"op":"mcm","clk":"11827339993","pt":1723354207212,"mc":[{"id":"1.231613187","rc":[{"batb":[[0,4.1,12.59],[1,1.03,200.79],[2,1.02,200.79]],"ltp":4.2,"tv":5.32,"id":12474498}]}]}
{"op":"mcm","clk":"11827340116","pt":1723354209525,"mc":[{"id":"1.231613187","rc":[{"batb":[[0,4.2,4],[1,4.1,12.59],[2,1.03,200.79]],"ltp":4.2,"tv":5.32,"id":12474498}]}]}
{"op":"mcm","clk":"11827340211","pt":1723354211787,"mc":[{"id":"1.231613187","rc":[{"batb":[[0,4.1,12.59],[1,1.03,200.79],[2,1.02,200.79]],"ltp":4.2,"tv":5.32,"id":12474498}]}]}
{"op":"mcm","clk":"11827340329","pt":1723354214103,"mc":[{"id":"1.231613187","rc":[{"batb":[[0,4.2,4],[1,4.1,12.59],[2,1.03,200.79]],"ltp":4.2,"tv":5.32,"id":12474498}]}]}
{"op":"mcm","clk":"11827340435","pt":1723354216520,"mc":[{"id":"1.231613187","rc":[{"batb":[[0,4.1,12.59],[1,1.03,200.79],[2,1.02,200.79]],"ltp":4.2,"tv":5.32,"id":12474498}]}]}
{"op":"mcm","clk":"11827340595","pt":1723354218897,"mc":[{"id":"1.231613187","rc":[{"batb":[[0,4.2,4],[1,4.1,12.59],[2,1.03,200.79]],"ltp":4.2,"tv":5.32,"id":12474498}]}]}
{"op":"mcm","clk":"11827340699","pt":1723354221302,"mc":[{"id":"1.231613187","rc":[{"batb":[[0,4.1,12.59],[1,1.03,200.79],[2,1.02,200.79]],"ltp":4.2,"tv":5.32,"id":12474498}]}]}
{"op":"mcm","clk":"11827340835","pt":1723354223716,"mc":[{"id":"1.231613187","rc":[{"batb":[[0,4.2,4],[1,4.1,12.59],[2,1.03,200.79]],"ltp":4.2,"tv":5.32,"id":12474498}]}]}
{"op":"mcm","clk":"11827340922","pt":1723354225928,"mc":[{"id":"1.231613187","rc":[{"batb":[[0,4.1,12.59],[1,1.03,200.79],[2,1.02,200.79]],"ltp":4.2,"tv":5.32,"id":12474498}]}]}
{"op":"mcm","clk":"11827341022","pt":1723354228346,"mc":[{"id":"1.231613187","rc":[{"batb":[[0,4.2,4],[1,4.1,12.59],[2,1.03,200.79]],"ltp":4.2,"tv":5.32,"id":12474498}]}]}
{"op":"mcm","clk":"11827341106","pt":1723354230762,"mc":[{"id":"1.231613187","rc":[{"batb":[[0,4.1,12.59],[1,1.03,200.79],[2,1.02,200.79]],"ltp":4.2,"tv":5.32,"id":12474498}]}]}
{"op":"mcm","clk":"11827341232","pt":1723354233337,"mc":[{"id":"1.231613187","rc":[{"batb":[[0,4.2,4],[1,4.1,12.59],[2,1.03,200.79]],"ltp":4.2,"tv":5.32,"id":12474498}]}]}
{"op":"mcm","clk":"11827341327","pt":1723354235641,"mc":[{"id":"1.231613187","rc":[{"batb":[[0,4.1,12.59],[1,1.03,200.79],[2,1.02,200.79]],"ltp":4.2,"tv":5.32,"id":12474498}]}]}
{"op":"mcm","clk":"11827341433","pt":1723354238152,"mc":[{"id":"1.231613187","rc":[{"batb":[[0,4.2,4],[1,4.1,12.59],[2,1.03,200.79]],"ltp":4.2,"tv":5.32,"id":12474498}]}]}
{"op":"mcm","clk":"11827341501","pt":1723354240761,"mc":[{"id":"1.231613187","rc":[{"batb":[[0,4.1,12.59],[1,1.03,200.79],[2,1.02,200.79]],"ltp":4.2,"tv":5.32,"id":12474498}]}]}
{"op":"mcm","clk":"11827341565","pt":1723354243065,"mc":[{"id":"1.231613187","rc":[{"batb":[[0,4.2,4],[1,4.1,12.59],[2,1.03,200.79]],"ltp":4.2,"tv":5.32,"id":12474498}]}]}
{"op":"mcm","clk":"11827341657","pt":1723354245371,"mc":[{"id":"1.231613187","rc":[{"batb":[[0,4.1,12.59],[1,1.03,200.79],[2,1.02,200.79]],"ltp":4.2,"tv":5.32,"id":12474498}]}]}
{"op":"mcm","clk":"11827341749","pt":1723354247676,"mc":[{"id":"1.231613187","rc":[{"batb":[[0,4.2,4],[1,4.1,12.59],[2,1.03,200.79]],"ltp":4.2,"tv":5.32,"id":12474498}]}]}
{"op":"mcm","clk":"11827341835","pt":1723354249926,"mc":[{"id":"1.231613187","rc":[{"batb":[[0,4.1,12.59],[1,1.03,200.79],[2,1.02,200.79]],"ltp":4.2,"tv":5.32,"id":12474498}]}]}
{"op":"mcm","clk":"11827341933","pt":1723354252231,"mc":[{"id":"1.231613187","rc":[{"batb":[[0,4.2,4],[1,4.1,12.59],[2,1.03,200.79]],"ltp":4.2,"tv":5.32,"id":12474498}]}]}
{"op":"mcm","clk":"11827342027","pt":1723354254738,"mc":[{"id":"1.231613187","rc":[{"batb":[[0,4.1,12.59],[1,1.03,200.79],[2,1.02,200.79]],"ltp":4.2,"tv":5.32,"id":12474498}]}]}
{"op":"mcm","clk":"11827342101","pt":1723354257043,"mc":[{"id":"1.231613187","rc":[{"batb":[[0,4.2,4],[1,4.1,12.59],[2,1.03,200.79]],"ltp":4.2,"tv":5.32,"id":12474498}]}]}
{"op":"mcm","clk":"11827342195","pt":1723354259462,"mc":[{"id":"1.231613187","rc":[{"batb":[[0,4.1,12.59],[1,1.03,200.79],[2,1.02,200.79]],"ltp":4.2,"tv":5.32,"id":12474498}]}]}
{"op":"mcm","clk":"11827342282","pt":1723354261782,"mc":[{"id":"1.231613187","rc":[{"batb":[[0,4.2,4],[1,4.1,12.59],[2,1.03,200.79]],"ltp":4.2,"tv":5.32,"id":12474498}]}]}
{"op":"mcm","clk":"11827342366","pt":1723354264267,"mc":[{"id":"1.231613187","rc":[{"batb":[[0,4.1,12.59],[1,1.03,200.79],[2,1.02,200.79]],"ltp":4.2,"tv":5.32,"id":12474498}]}]}
{"op":"mcm","clk":"11827342463","pt":1723354266568,"mc":[{"id":"1.231613187","rc":[{"batb":[[0,4.2,4],[1,4.1,12.59],[2,1.03,200.79]],"ltp":4.2,"tv":5.32,"id":12474498}]}]}
{"op":"mcm","clk":"11827342538","pt":1723354268986,"mc":[{"id":"1.231613187","rc":[{"batb":[[0,4.1,12.59],[1,1.03,200.79],[2,1.02,200.79]],"ltp":4.2,"tv":5.32,"id":12474498}]}]}
{"op":"mcm","clk":"11827342616","pt":1723354271759,"mc":[{"id":"1.231613187","rc":[{"batb":[[0,4.2,4],[1,4.1,12.59],[2,1.03,200.79]],"ltp":4.2,"tv":5.32,"id":12474498}]}]}
{"op":"mcm","clk":"11827342669","pt":1723354273961,"mc":[{"id":"1.231613187","rc":[{"batb":[[0,4.1,12.59],[1,1.03,200.79],[2,1.02,200.79]],"ltp":4.2,"tv":5.32,"id":12474498}]}]}
{"op":"mcm","clk":"11827342784","pt":1723354277090,"mc":[{"id":"1.231613187","rc":[{"batb":[[0,4.2,4],[1,4.1,12.59],[2,1.03,200.79]],"ltp":4.2,"tv":5.32,"id":12474498}]}]}
{"op":"mcm","clk":"11827342881","pt":1723354279501,"mc":[{"id":"1.231613187","rc":[{"batb":[[0,4.1,12.59],[1,1.03,200.79],[2,1.02,200.79]],"ltp":4.2,"tv":5.32,"id":12474498}]}]}
{"op":"mcm","clk":"11827342958","pt":1723354281705,"mc":[{"id":"1.231613187","rc":[{"batb":[[0,4.2,4],[1,4.1,12.59],[2,1.03,200.79]],"ltp":4.2,"tv":5.32,"id":12474498}]}]}
{"op":"mcm","clk":"11827343038","pt":1723354284012,"mc":[{"id":"1.231613187","rc":[{"batb":[[0,4.1,12.59],[1,1.03,200.79],[2,1.02,200.79]],"ltp":4.2,"tv":5.32,"id":12474498}]}]}
{"op":"mcm","clk":"11827343141","pt":1723354286622,"mc":[{"id":"1.231613187","rc":[{"batb":[[0,4.2,4],[1,4.1,12.59],[2,1.03,200.79]],"ltp":4.2,"tv":5.32,"id":12474498}]}]}
{"op":"mcm","clk":"11827343206","pt":1723354288925,"mc":[{"id":"1.231613187","rc":[{"batb":[[0,4.1,12.59],[1,1.03,200.79],[2,1.02,200.79]],"ltp":4.2,"tv":5.32,"id":12474498}]}]}
{"op":"mcm","clk":"11827343286","pt":1723354291186,"mc":[{"id":"1.231613187","rc":[{"batb":[[0,4.2,4],[1,4.1,12.59],[2,1.03,200.79]],"ltp":4.2,"tv":5.32,"id":12474498}]}]}
{"op":"mcm","clk":"11827343385","pt":1723354293599,"mc":[{"id":"1.231613187","rc":[{"batb":[[0,4.1,12.59],[1,1.03,200.79],[2,1.02,200.79]],"ltp":4.2,"tv":5.32,"id":12474498}]}]}
{"op":"mcm","clk":"11827343486","pt":1723354296114,"mc":[{"id":"1.231613187","rc":[{"batb":[[0,4.2,4],[1,4.1,12.59],[2,1.03,200.79]],"ltp":4.2,"tv":5.32,"id":12474498}]}]}
{"op":"mcm","clk":"11827343547","pt":1723354298320,"mc":[{"id":"1.231613187","rc":[{"batb":[[0,4.1,12.59],[1,1.03,200.79],[2,1.02,200.79]],"ltp":4.2,"tv":5.32,"id":12474498}]}]}
{"op":"mcm","clk":"11827343624","pt":1723354301187,"mc":[{"id":"1.231613187","rc":[{"batb":[[0,4.2,4],[1,4.1,12.59],[2,1.03,200.79]],"ltp":4.2,"tv":5.32,"id":12474498}]}]}
{"op":"mcm","clk":"11827343685","pt":1723354303605,"mc":[{"id":"1.231613187","rc":[{"batb":[[0,4.1,12.59],[1,1.03,200.79],[2,1.02,200.79]],"ltp":4.2,"tv":5.32,"id":12474498}]}]}
{"op":"mcm","clk":"11827343752","pt":1723354305918,"mc":[{"id":"1.231613187","rc":[{"batb":[[0,4.2,4],[1,4.1,12.59],[2,1.03,200.79]],"ltp":4.2,"tv":5.32,"id":12474498}]}]}
{"op":"mcm","clk":"11827343850","pt":1723354308225,"mc":[{"id":"1.231613187","rc":[{"batb":[[0,4.1,12.59],[1,1.03,200.79],[2,1.02,200.79]],"ltp":4.2,"tv":5.32,"id":12474498}]}]}
{"op":"mcm","clk":"11827343976","pt":1723354311211,"mc":[{"id":"1.231613187","rc":[{"batb":[[0,4.2,4],[1,4.1,12.59],[2,1.03,200.79]],"ltp":4.2,"tv":5.32,"id":12474498}]}]}
{"op":"mcm","clk":"11827344060","pt":1723354313518,"mc":[{"id":"1.231613187","rc":[{"batb":[[0,4.1,12.59],[1,1.03,200.79],[2,1.02,200.79]],"ltp":4.2,"tv":5.32,"id":12474498}]}]}
{"op":"mcm","clk":"11827344155","pt":1723354316698,"mc":[{"id":"1.231613187","rc":[{"batb":[[0,4.2,4],[1,4.1,12.59],[2,1.03,200.79]],"ltp":4.2,"tv":5.32,"id":12474498}]}]}
{"op":"mcm","clk":"11827344230","pt":1723354318909,"mc":[{"id":"1.231613187","rc":[{"batb":[[0,4.1,12.59],[1,1.03,200.79],[2,1.02,200.79]],"ltp":4.2,"tv":5.32,"id":12474498}]}]}
{"op":"mcm","clk":"11827344334","pt":1723354321934,"mc":[{"id":"1.231613187","rc":[{"batb":[[0,4.2,4],[1,4.1,12.59],[2,1.03,200.79]],"ltp":4.2,"tv":5.32,"id":12474498}]}]}
{"op":"mcm","clk":"11827344438","pt":1723354324254,"mc":[{"id":"1.231613187","rc":[{"batb":[[0,4.1,12.59],[1,1.03,200.79],[2,1.02,200.79]],"ltp":4.2,"tv":5.32,"id":12474498}]}]}
{"op":"mcm","clk":"11827344529","pt":1723354326513,"mc":[{"id":"1.231613187","rc":[{"batb":[[0,4.2,4],[1,4.1,12.59],[2,1.03,200.79]],"ltp":4.2,"tv":5.32,"id":12474498}]}]}
{"op":"mcm","clk":"11827344605","pt":1723354328931,"mc":[{"id":"1.231613187","rc":[{"batb":[[0,4.1,12.59],[1,1.03,200.79],[2,1.02,200.79]],"ltp":4.2,"tv":5.32,"id":12474498}]}]}
{"op":"mcm","clk":"11827344721","pt":1723354332121,"mc":[{"id":"1.231613187","rc":[{"batb":[[0,4.2,4],[1,4.1,12.59],[2,1.03,200.79]],"ltp":4.2,"tv":5.32,"id":12474498}]}]}
{"op":"mcm","clk":"11827344814","pt":1723354334435,"mc":[{"id":"1.231613187","rc":[{"batb":[[0,4.1,12.59],[1,1.03,200.79],[2,1.02,200.79]],"ltp":4.2,"tv":5.32,"id":12474498}]}]}
{"op":"mcm","clk":"11827345063","pt":1723354340145,"mc":[{"id":"1.231613187","rc":[{"batb":[[0,4.2,4],[1,4.1,12.59],[2,1.03,200.79]],"ltp":4.2,"tv":5.32,"id":12474498}]}]}
{"op":"mcm","clk":"11827345162","pt":1723354343118,"mc":[{"id":"1.231613187","rc":[{"batb":[[0,4.1,12.59],[1,1.03,200.79],[2,1.02,200.79]],"ltp":4.2,"tv":5.32,"id":12474498}]}]}
{"op":"mcm","clk":"11827345243","pt":1723354345333,"mc":[{"id":"1.231613187","rc":[{"batb":[[0,4.2,4],[1,4.1,12.59],[2,1.03,200.79]],"ltp":4.2,"tv":5.32,"id":12474498}]}]}
{"op":"mcm","clk":"11827345325","pt":1723354347742,"mc":[{"id":"1.231613187","rc":[{"batb":[[0,4.1,12.59],[1,1.03,200.79],[2,1.02,200.79]],"ltp":4.2,"tv":5.32,"id":12474498}]}]}
{"op":"mcm","clk":"11827345394","pt":1723354349847,"mc":[{"id":"1.231613187","rc":[{"batb":[[0,4.2,4],[1,4.1,12.59],[2,1.03,200.79]],"ltp":4.2,"tv":5.32,"id":12474498}]}]}
{"op":"mcm","clk":"11827345497","pt":1723354352163,"mc":[{"id":"1.231613187","rc":[{"batb":[[0,4.1,12.59],[1,1.03,200.79],[2,1.02,200.79]],"ltp":4.2,"tv":5.32,"id":12474498}]}]}
{"op":"mcm","clk":"11827345577","pt":1723354354639,"mc":[{"id":"1.231613187","rc":[{"batb":[[0,4.2,4],[1,4.1,12.59],[2,1.03,200.79]],"ltp":4.2,"tv":5.32,"id":12474498}]}]}
{"op":"mcm","clk":"11827345661","pt":1723354357053,"mc":[{"id":"1.231613187","rc":[{"batb":[[0,4.1,12.59],[1,1.03,200.79],[2,1.02,200.79]],"ltp":4.2,"tv":5.32,"id":12474498}]}]}
{"op":"mcm","clk":"11827345770","pt":1723354359838,"mc":[{"id":"1.231613187","rc":[{"batb":[[0,4.2,4],[1,4.1,12.59],[2,1.03,200.79]],"ltp":4.2,"tv":5.32,"id":12474498}]}]}
{"op":"mcm","clk":"11827345835","pt":1723354362253,"mc":[{"id":"1.231613187","rc":[{"batb":[[0,4.1,12.59],[1,1.03,200.79],[2,1.02,200.79]],"ltp":4.2,"tv":5.32,"id":12474498}]}]}
{"op":"mcm","clk":"11827345926","pt":1723354364671,"mc":[{"id":"1.231613187","rc":[{"batb":[[0,4.2,4],[1,4.1,12.59],[2,1.03,200.79]],"ltp":4.2,"tv":5.32,"id":12474498}]}]}
{"op":"mcm","clk":"11827346011","pt":1723354366983,"mc":[{"id":"1.231613187","rc":[{"batb":[[0,4.1,12.59],[1,1.03,200.79],[2,1.02,200.79]],"ltp":4.2,"tv":5.32,"id":12474498}]}]}
{"op":"mcm","clk":"11827346097","pt":1723354369377,"mc":[{"id":"1.231613187","rc":[{"batb":[[0,4.2,4],[1,4.1,12.59],[2,1.03,200.79]],"ltp":4.2,"tv":5.32,"id":12474498}]}]}
{"op":"mcm","clk":"11827346196","pt":1723354371791,"mc":[{"id":"1.231613187","rc":[{"batb":[[0,4.1,12.59],[1,1.03,200.79],[2,1.02,200.79]],"ltp":4.2,"tv":5.32,"id":12474498}]}]}
{"op":"mcm","clk":"11827346293","pt":1723354374161,"mc":[{"id":"1.231613187","rc":[{"batb":[[0,4.2,4],[1,4.1,12.59],[2,1.03,200.79]],"ltp":4.2,"tv":5.32,"id":12474498}]}]}
{"op":"mcm","clk":"11827346388","pt":1723354376665,"mc":[{"id":"1.231613187","rc":[{"batb":[[0,4.1,12.59],[1,1.03,200.79],[2,1.02,200.79]],"ltp":4.2,"tv":5.32,"id":12474498}]}]}
{"op":"mcm","clk":"11827346515","pt":1723354379091,"mc":[{"id":"1.231613187","rc":[{"batb":[[0,4.2,4],[1,4.1,12.59],[2,1.03,200.79]],"ltp":4.2,"tv":5.32,"id":12474498}]}]}
{"op":"mcm","clk":"11827346591","pt":1723354381302,"mc":[{"id":"1.231613187","rc":[{"batb":[[0,4.1,12.59],[1,1.03,200.79],[2,1.02,200.79]],"ltp":4.2,"tv":5.32,"id":12474498}]}]}
{"op":"mcm","clk":"11827346696","pt":1723354384075,"mc":[{"id":"1.231613187","rc":[{"batb":[[0,4.2,4],[1,4.1,12.59],[2,1.03,200.79]],"ltp":4.2,"tv":5.32,"id":12474498}]}]}
{"op":"mcm","clk":"11827346781","pt":1723354386283,"mc":[{"id":"1.231613187","rc":[{"batb":[[0,4.1,12.59],[1,1.03,200.79],[2,1.02,200.79]],"ltp":4.2,"tv":5.32,"id":12474498}]}]}
{"op":"mcm","clk":"11827346893","pt":1723354389008,"mc":[{"id":"1.231613187","rc":[{"batb":[[0,4.2,4],[1,4.1,12.59],[2,1.03,200.79]],"ltp":4.2,"tv":5.32,"id":12474498}]}]}
{"op":"mcm","clk":"11827346993","pt":1723354391487,"mc":[{"id":"1.231613187","rc":[{"batb":[[0,4.1,12.59],[1,1.03,200.79],[2,1.02,200.79]],"ltp":4.2,"tv":5.32,"id":12474498}]}]}
{"op":"mcm","clk":"11827347119","pt":1723354394490,"mc":[{"id":"1.231613187","rc":[{"batb":[[0,4.2,4],[1,4.1,12.59],[2,1.03,200.79]],"ltp":4.2,"tv":5.32,"id":12474498}]}]}
{"op":"mcm","clk":"11827347216","pt":1723354396898,"mc":[{"id":"1.231613187","rc":[{"batb":[[0,4.1,12.59],[1,1.03,200.79],[2,1.02,200.79]],"ltp":4.2,"tv":5.32,"id":12474498}]}]}
{"op":"mcm","clk":"11827347307","pt":1723354399515,"mc":[{"id":"1.231613187","rc":[{"batb":[[0,4.2,4],[1,4.1,12.59],[2,1.03,200.79]],"ltp":4.2,"tv":5.32,"id":12474498}]}]}
{"op":"mcm","clk":"11827347387","pt":1723354401928,"mc":[{"id":"1.231613187","rc":[{"batb":[[0,4.1,12.59],[1,1.03,200.79],[2,1.02,200.79]],"ltp":4.2,"tv":5.32,"id":12474498}]}]}
{"op":"mcm","clk":"11827347540","pt":1723354405223,"mc":[{"id":"1.231613187","rc":[{"batb":[[0,4.2,4],[1,4.1,12.59],[2,1.03,200.79]],"ltp":4.2,"tv":5.32,"id":12474498}]}]}
{"op":"mcm","clk":"11827347646","pt":1723354407528,"mc":[{"id":"1.231613187","rc":[{"batb":[[0,4.1,12.59],[1,1.03,200.79],[2,1.02,200.79]],"ltp":4.2,"tv":5.32,"id":12474498}]}]}
{"op":"mcm","clk":"11827347745","pt":1723354409794,"mc":[{"id":"1.231613187","rc":[{"batb":[[0,4.2,4],[1,4.1,12.59],[2,1.03,200.79]],"ltp":4.2,"tv":5.32,"id":12474498}]}]}
{"op":"mcm","clk":"11827347856","pt":1723354412324,"mc":[{"id":"1.231613187","rc":[{"batb":[[0,4.1,12.59],[1,1.03,200.79],[2,1.02,200.79]],"ltp":4.2,"tv":5.32,"id":12474498}]}]}
{"op":"mcm","clk":"11827347988","pt":1723354414631,"mc":[{"id":"1.231613187","rc":[{"batb":[[0,4.2,4],[1,4.1,12.59],[2,1.03,200.79]],"ltp":4.2,"tv":5.32,"id":12474498}]}]}
{"op":"mcm","clk":"11827348123","pt":1723354416841,"mc":[{"id":"1.231613187","rc":[{"batb":[[0,4.1,12.59],[1,1.03,200.79],[2,1.02,200.79]],"ltp":4.2,"tv":5.32,"id":12474498}]}]}
{"op":"mcm","clk":"11827348224","pt":1723354419105,"mc":[{"id":"1.231613187","rc":[{"batb":[[0,4.2,4],[1,4.1,12.59],[2,1.03,200.79]],"ltp":4.2,"tv":5.32,"id":12474498}]}]}
{"op":"mcm","clk":"11827348331","pt":1723354421639,"mc":[{"id":"1.231613187","rc":[{"batb":[[0,4.1,12.59],[1,1.03,200.79],[2,1.02,200.79]],"ltp":4.2,"tv":5.32,"id":12474498}]}]}
{"op":"mcm","clk":"11827348412","pt":1723354423906,"mc":[{"id":"1.231613187","rc":[{"batb":[[0,4.2,4],[1,4.1,12.59],[2,1.03,200.79]],"ltp":4.2,"tv":5.32,"id":12474498}]}]}
{"op":"mcm","clk":"11827348485","pt":1723354426315,"mc":[{"id":"1.231613187","rc":[{"batb":[[0,4.1,12.59],[1,1.03,200.79],[2,1.02,200.79]],"ltp":4.2,"tv":5.32,"id":12474498}]}]}
{"op":"mcm","clk":"11827348599","pt":1723354429012,"mc":[{"id":"1.231613187","rc":[{"batb":[[0,4.2,4],[1,4.1,12.59],[2,1.03,200.79]],"ltp":4.2,"tv":5.32,"id":12474498}]}]}
{"op":"mcm","clk":"11827348686","pt":1723354431227,"mc":[{"id":"1.231613187","rc":[{"batb":[[0,4.1,12.59],[1,1.03,200.79],[2,1.02,200.79]],"ltp":4.2,"tv":5.32,"id":12474498}]}]}
{"op":"mcm","clk":"11827348772","pt":1723354433836,"mc":[{"id":"1.231613187","rc":[{"batb":[[0,4.2,4],[1,4.1,12.59],[2,1.03,200.79]],"ltp":4.2,"tv":5.32,"id":12474498}]}]}
{"op":"mcm","clk":"11827348860","pt":1723354436144,"mc":[{"id":"1.231613187","rc":[{"batb":[[0,4.1,12.59],[1,1.03,200.79],[2,1.02,200.79]],"ltp":4.2,"tv":5.32,"id":12474498}]}]}
{"op":"mcm","clk":"11827348948","pt":1723354438451,"mc":[{"id":"1.231613187","rc":[{"batb":[[0,4.2,4],[1,4.1,12.59],[2,1.03,200.79]],"ltp":4.2,"tv":5.32,"id":12474498}]}]}
{"op":"mcm","clk":"11827349065","pt":1723354440864,"mc":[{"id":"1.231613187","rc":[{"batb":[[0,4.1,12.59],[1,1.03,200.79],[2,1.02,200.79]],"ltp":4.2,"tv":5.32,"id":12474498}]}]}
{"op":"mcm","clk":"11827349173","pt":1723354443137,"mc":[{"id":"1.231613187","rc":[{"batb":[[0,4.2,4],[1,4.1,12.59],[2,1.03,200.79]],"ltp":4.2,"tv":5.32,"id":12474498}]}]}
{"op":"mcm","clk":"11827349273","pt":1723354445456,"mc":[{"id":"1.231613187","rc":[{"batb":[[0,4.1,12.59],[1,1.03,200.79],[2,1.02,200.79]],"ltp":4.2,"tv":5.32,"id":12474498}]}]}
{"op":"mcm","clk":"11827349367","pt":1723354447969,"mc":[{"id":"1.231613187","rc":[{"batb":[[0,4.2,4],[1,4.1,12.59],[2,1.03,200.79]],"ltp":4.2,"tv":5.32,"id":12474498}]}]}
{"op":"mcm","clk":"11827349460","pt":1723354450334,"mc":[{"id":"1.231613187","rc":[{"batb":[[0,4.1,12.59],[1,1.03,200.79],[2,1.02,200.79]],"ltp":4.2,"tv":5.32,"id":12474498}]}]}
{"op":"mcm","clk":"11827349536","pt":1723354453084,"mc":[{"id":"1.231613187","rc":[{"batb":[[0,4.2,4],[1,4.1,12.59],[2,1.03,200.79]],"ltp":4.2,"tv":5.32,"id":12474498}]}]}
{"op":"mcm","clk":"11827349615","pt":1723354455339,"mc":[{"id":"1.231613187","rc":[{"batb":[[0,4.1,12.59],[1,1.03,200.79],[2,1.02,200.79]],"ltp":4.2,"tv":5.32,"id":12474498}]}]}
{"op":"mcm","clk":"11827349715","pt":1723354457661,"mc":[{"id":"1.231613187","rc":[{"batb":[[0,4.2,4],[1,4.1,12.59],[2,1.03,200.79]],"ltp":4.2,"tv":5.32,"id":12474498}]}]}
{"op":"mcm","clk":"11827349795","pt":1723354459974,"mc":[{"id":"1.231613187","rc":[{"batb":[[0,4.1,12.59],[1,1.03,200.79],[2,1.02,200.79]],"ltp":4.2,"tv":5.32,"id":12474498}]}]}
{"op":"mcm","clk":"11827349872","pt":1723354462380,"mc":[{"id":"1.231613187","rc":[{"batb":[[0,4.2,4],[1,4.1,12.59],[2,1.03,200.79]],"ltp":4.2,"tv":5.32,"id":12474498}]}]}
{"op":"mcm","clk":"11827349938","pt":1723354464679,"mc":[{"id":"1.231613187","rc":[{"batb":[[0,4.1,12.59],[1,1.03,200.79],[2,1.02,200.79]],"ltp":4.2,"tv":5.32,"id":12474498}]}]}
{"op":"mcm","clk":"11827350059","pt":1723354468495,"mc":[{"id":"1.231613187","rc":[{"batb":[[0,4.2,4],[1,4.1,12.59],[2,1.03,200.79]],"ltp":4.2,"tv":5.32,"id":12474498}]}]}
{"op":"mcm","clk":"11827350156","pt":1723354470866,"mc":[{"id":"1.231613187","rc":[{"batb":[[0,4.1,12.59],[1,1.03,200.79],[2,1.02,200.79]],"ltp":4.2,"tv":5.32,"id":12474498}]}]}
{"op":"mcm","clk":"11827350236","pt":1723354472977,"mc":[{"id":"1.231613187","rc":[{"batb":[[0,4.2,4],[1,4.1,12.59],[2,1.03,200.79]],"ltp":4.2,"tv":5.32,"id":12474498}]}]}
{"op":"mcm","clk":"11827350330","pt":1723354475180,"mc":[{"id":"1.231613187","rc":[{"batb":[[0,4.1,12.59],[1,1.03,200.79],[2,1.02,200.79]],"ltp":4.2,"tv":5.32,"id":12474498}]}]}
{"op":"mcm","clk":"11827350420","pt":1723354477683,"mc":[{"id":"1.231613187","rc":[{"batb":[[0,4.2,4],[1,4.1,12.59],[2,1.03,200.79]],"ltp":4.2,"tv":5.32,"id":12474498}]}]}
{"op":"mcm","clk":"11827350502","pt":1723354479992,"mc":[{"id":"1.231613187","rc":[{"batb":[[0,4.1,12.59],[1,1.03,200.79],[2,1.02,200.79]],"ltp":4.2,"tv":5.32,"id":12474498}]}]}
{"op":"mcm","clk":"11827350565","pt":1723354482096,"mc":[{"id":"1.231613187","rc":[{"batb":[[0,4.2,4],[1,4.1,12.59],[2,1.03,200.79]],"ltp":4.2,"tv":5.32,"id":12474498}]}]}
{"op":"mcm","clk":"11827350664","pt":1723354484402,"mc":[{"id":"1.231613187","rc":[{"batb":[[0,4.1,12.59],[1,1.03,200.79],[2,1.02,200.79]],"ltp":4.2,"tv":5.32,"id":12474498}]}]}
{"op":"mcm","clk":"11827350789","pt":1723354487485,"mc":[{"id":"1.231613187","rc":[{"batb":[[0,4.2,4],[1,4.1,12.59],[2,1.03,200.79]],"ltp":4.2,"tv":5.32,"id":12474498}]}]}
{"op":"mcm","clk":"11827350867","pt":1723354489993,"mc":[{"id":"1.231613187","rc":[{"batb":[[0,4.1,12.59],[1,1.03,200.79],[2,1.02,200.79]],"ltp":4.2,"tv":5.32,"id":12474498}]}]}
{"op":"mcm","clk":"11827350939","pt":1723354492113,"mc":[{"id":"1.231613187","rc":[{"batb":[[0,4.2,4],[1,4.1,12.59],[2,1.03,200.79]],"ltp":4.2,"tv":5.32,"id":12474498}]}]}
{"op":"mcm","clk":"11827351012","pt":1723354494418,"mc":[{"id":"1.231613187","rc":[{"batb":[[0,4.1,12.59],[1,1.03,200.79],[2,1.02,200.79]],"ltp":4.2,"tv":5.32,"id":12474498}]}]}
{"op":"mcm","clk":"11827351094","pt":1723354496696,"mc":[{"id":"1.231613187","rc":[{"batb":[[0,4.2,4],[1,4.1,12.59],[2,1.03,200.79]],"ltp":4.2,"tv":5.32,"id":12474498}]}]}
{"op":"mcm","clk":"11827351167","pt":1723354499003,"mc":[{"id":"1.231613187","rc":[{"batb":[[0,4.1,12.59],[1,1.03,200.79],[2,1.02,200.79]],"ltp":4.2,"tv":5.32,"id":12474498}]}]}
{"op":"mcm","clk":"11827351280","pt":1723354502505,"mc":[{"id":"1.231613187","rc":[{"batb":[[0,4.2,4],[1,4.1,12.59],[2,1.03,200.79]],"ltp":4.2,"tv":5.32,"id":12474498}]}]}
{"op":"mcm","clk":"11827351358","pt":1723354504829,"mc":[{"id":"1.231613187","rc":[{"batb":[[0,4.1,12.59],[1,1.03,200.79],[2,1.02,200.79]],"ltp":4.2,"tv":5.32,"id":12474498}]}]}
{"op":"mcm","clk":"11827351456","pt":1723354507830,"mc":[{"id":"1.231613187","rc":[{"batb":[[0,4.2,4],[1,4.1,12.59],[2,1.03,200.79]],"ltp":4.2,"tv":5.32,"id":12474498}]}]}
{"op":"mcm","clk":"11827351539","pt":1723354510134,"mc":[{"id":"1.231613187","rc":[{"batb":[[0,4.1,12.59],[1,1.03,200.79],[2,1.02,200.79]],"ltp":4.2,"tv":5.32,"id":12474498}]}]}
{"op":"mcm","clk":"11827351713","pt":1723354515025,"mc":[{"id":"1.231613187","rc":[{"batb":[[0,4.2,4],[1,4.1,12.59],[2,1.03,200.79]],"ltp":4.2,"tv":5.32,"id":12474498}]}]}
{"op":"mcm","clk":"11827351797","pt":1723354517431,"mc":[{"id":"1.231613187","rc":[{"batb":[[0,4.1,12.59],[1,1.03,200.79],[2,1.02,200.79]],"ltp":4.2,"tv":5.32,"id":12474498}]}]}
{"op":"mcm","clk":"11827351924","pt":1723354521153,"mc":[{"id":"1.231613187","rc":[{"batb":[[0,4.2,4],[1,4.1,12.59],[2,1.03,200.79]],"ltp":4.2,"tv":5.32,"id":12474498}]}]}
{"op":"mcm","clk":"11827352017","pt":1723354523721,"mc":[{"id":"1.231613187","rc":[{"batb":[[0,4.1,12.59],[1,1.03,200.79],[2,1.02,200.79]],"ltp":4.2,"tv":5.32,"id":12474498}]}]}
{"op":"mcm","clk":"11827352101","pt":1723354526648,"mc":[{"id":"1.231613187","rc":[{"batb":[[0,4.2,4],[1,4.1,12.59],[2,1.03,200.79]],"ltp":4.2,"tv":5.32,"id":12474498}]}]}
{"op":"mcm","clk":"11827352177","pt":1723354529025,"mc":[{"id":"1.231613187","rc":[{"batb":[[0,4.1,12.59],[1,1.03,200.79],[2,1.02,200.79]],"ltp":4.2,"tv":5.32,"id":12474498}]}]}
{"op":"mcm","clk":"11827352259","pt":1723354531236,"mc":[{"id":"1.231613187","rc":[{"batb":[[0,4.2,4],[1,4.1,12.59],[2,1.03,200.79]],"ltp":4.2,"tv":5.32,"id":12474498}]}]}
{"op":"mcm","clk":"11827352358","pt":1723354533748,"mc":[{"id":"1.231613187","rc":[{"batb":[[0,4.1,12.59],[1,1.03,200.79],[2,1.02,200.79]],"ltp":4.2,"tv":5.32,"id":12474498}]}]}
{"op":"mcm","clk":"11827352452","pt":1723354535964,"mc":[{"id":"1.231613187","rc":[{"batb":[[0,4.2,4],[1,4.1,12.59],[2,1.03,200.79]],"ltp":4.2,"tv":5.32,"id":12474498}]}]}
{"op":"mcm","clk":"11827352554","pt":1723354538432,"mc":[{"id":"1.231613187","rc":[{"batb":[[0,4.1,12.59],[1,1.03,200.79],[2,1.02,200.79]],"ltp":4.2,"tv":5.32,"id":12474498}]}]}
{"op":"mcm","clk":"11827352643","pt":1723354540641,"mc":[{"id":"1.231613187","rc":[{"batb":[[0,4.2,4],[1,4.1,12.59],[2,1.03,200.79]],"ltp":4.2,"tv":5.32,"id":12474498}]}]}
{"op":"mcm","clk":"11827352736","pt":1723354542960,"mc":[{"id":"1.231613187","rc":[{"batb":[[0,4.1,12.59],[1,1.03,200.79],[2,1.02,200.79]],"ltp":4.2,"tv":5.32,"id":12474498}]}]}
{"op":"mcm","clk":"11827352818","pt":1723354545169,"mc":[{"id":"1.231613187","rc":[{"batb":[[0,4.2,4],[1,4.1,12.59],[2,1.03,200.79]],"ltp":4.2,"tv":5.32,"id":12474498}]}]}
{"op":"mcm","clk":"11827352926","pt":1723354547751,"mc":[{"id":"1.231613187","rc":[{"batb":[[0,4.1,12.59],[1,1.03,200.79],[2,1.02,200.79]],"ltp":4.2,"tv":5.32,"id":12474498}]}]}
{"op":"mcm","clk":"11827353025","pt":1723354550584,"mc":[{"id":"1.231613187","rc":[{"batb":[[0,4.2,4],[1,4.1,12.59],[2,1.03,200.79]],"ltp":4.2,"tv":5.32,"id":12474498}]}]}
{"op":"mcm","clk":"11827353117","pt":1723354552967,"mc":[{"id":"1.231613187","rc":[{"batb":[[0,4.1,12.59],[1,1.03,200.79],[2,1.02,200.79]],"ltp":4.2,"tv":5.32,"id":12474498}]}]}
{"op":"mcm","clk":"11827353211","pt":1723354555261,"mc":[{"id":"1.231613187","rc":[{"batb":[[0,4.2,4],[1,4.1,12.59],[2,1.03,200.79]],"ltp":4.2,"tv":5.32,"id":12474498}]}]}
{"op":"mcm","clk":"11827353313","pt":1723354557776,"mc":[{"id":"1.231613187","rc":[{"batb":[[0,4.1,12.59],[1,1.03,200.79],[2,1.02,200.79]],"ltp":4.2,"tv":5.32,"id":12474498}]}]}
{"op":"mcm","clk":"11827353398","pt":1723354560167,"mc":[{"id":"1.231613187","rc":[{"batb":[[0,4.2,4],[1,4.1,12.59],[2,1.03,200.79]],"ltp":4.2,"tv":5.32,"id":12474498}]}]}
{"op":"mcm","clk":"11827353495","pt":1723354562447,"mc":[{"id":"1.231613187","rc":[{"batb":[[0,4.1,12.59],[1,1.03,200.79],[2,1.02,200.79]],"ltp":4.2,"tv":5.32,"id":12474498}]}]}
{"op":"mcm","clk":"11827353615","pt":1723354565968,"mc":[{"id":"1.231613187","rc":[{"batb":[[0,4.2,4],[1,4.1,12.59],[2,1.03,200.79]],"ltp":4.2,"tv":5.32,"id":12474498}]}]}
{"op":"mcm","clk":"11827353776","pt":1723354570858,"mc":[{"id":"1.231613187","rc":[{"batb":[[0,4.1,12.59],[1,1.03,200.79],[2,1.02,200.79]],"ltp":4.2,"tv":5.32,"id":12474498}]}]}
{"op":"mcm","clk":"11827353941","pt":1723354575671,"mc":[{"id":"1.231613187","rc":[{"batb":[[0,4.2,4],[1,4.1,12.59],[2,1.03,200.79]],"ltp":4.2,"tv":5.32,"id":12474498}]}]}
{"op":"mcm","clk":"11827354016","pt":1723354578100,"mc":[{"id":"1.231613187","rc":[{"batb":[[0,4.1,12.59],[1,1.03,200.79],[2,1.02,200.79]],"ltp":4.2,"tv":5.32,"id":12474498}]}]}
{"op":"mcm","clk":"11827354174","pt":1723354582571,"mc":[{"id":"1.231613187","rc":[{"batb":[[0,4.2,4],[1,4.1,12.59],[2,1.03,200.79]],"ltp":4.2,"tv":5.32,"id":12474498}]}]}
{"op":"mcm","clk":"11827354243","pt":1723354584879,"mc":[{"id":"1.231613187","rc":[{"batb":[[0,4.1,12.59],[1,1.03,200.79],[2,1.02,200.79]],"ltp":4.2,"tv":5.32,"id":12474498}]}]}
{"op":"mcm","clk":"11827354325","pt":1723354587193,"mc":[{"id":"1.231613187","rc":[{"batb":[[0,4.2,4],[1,4.1,12.59],[2,1.03,200.79]],"ltp":4.2,"tv":5.32,"id":12474498}]}]}
{"op":"mcm","clk":"11827354416","pt":1723354589504,"mc":[{"id":"1.231613187","rc":[{"batb":[[0,4.1,12.59],[1,1.03,200.79],[2,1.02,200.79]],"ltp":4.2,"tv":5.32,"id":12474498}]}]}
{"op":"mcm","clk":"11827354549","pt":1723354593411,"mc":[{"id":"1.231613187","rc":[{"batb":[[0,4.2,4],[1,4.1,12.59],[2,1.03,200.79]],"ltp":4.2,"tv":5.32,"id":12474498}]}]}
{"op":"mcm","clk":"11827354611","pt":1723354595726,"mc":[{"id":"1.231613187","rc":[{"batb":[[0,4.1,12.59],[1,1.03,200.79],[2,1.02,200.79]],"ltp":4.2,"tv":5.32,"id":12474498}]}]}
{"op":"mcm","clk":"11827354704","pt":1723354598999,"mc":[{"id":"1.231613187","rc":[{"batb":[[0,4.2,4],[1,4.1,12.59],[2,1.03,200.79]],"ltp":4.2,"tv":5.32,"id":12474498}]}]}
{"op":"mcm","clk":"11827354767","pt":1723354601215,"mc":[{"id":"1.231613187","rc":[{"batb":[[0,4.1,12.59],[1,1.03,200.79],[2,1.02,200.79]],"ltp":4.2,"tv":5.32,"id":12474498}]}]}
{"op":"mcm","clk":"11827354917","pt":1723354603401,"mc":[{"id":"1.231613187","rc":[{"batb":[[0,4.2,4],[1,4.1,12.59],[2,1.03,200.79]],"ltp":4.2,"tv":5.32,"id":12474498}]}]}
{"op":"mcm","clk":"11827355012","pt":1723354606032,"mc":[{"id":"1.231613187","rc":[{"batb":[[0,4.1,12.59],[1,1.03,200.79],[2,1.02,200.79]],"ltp":4.2,"tv":5.32,"id":12474498}]}]}
{"op":"mcm","clk":"11827355090","pt":1723354608435,"mc":[{"id":"1.231613187","rc":[{"batb":[[0,4.2,4],[1,4.1,12.59],[2,1.03,200.79]],"ltp":4.2,"tv":5.32,"id":12474498}]}]}
{"op":"mcm","clk":"11827355173","pt":1723354610916,"mc":[{"id":"1.231613187","rc":[{"batb":[[0,4.1,12.59],[1,1.03,200.79],[2,1.02,200.79]],"ltp":4.2,"tv":5.32,"id":12474498}]}]}
{"op":"mcm","clk":"11827355261","pt":1723354613131,"mc":[{"id":"1.231613187","rc":[{"batb":[[0,4.2,4],[1,4.1,12.59],[2,1.03,200.79]],"ltp":4.2,"tv":5.32,"id":12474498}]}]}
{"op":"mcm","clk":"11827355360","pt":1723354615522,"mc":[{"id":"1.231613187","rc":[{"batb":[[0,4.1,12.59],[1,1.03,200.79],[2,1.02,200.79]],"ltp":4.2,"tv":5.32,"id":12474498}]}]}
{"op":"mcm","clk":"11827355437","pt":1723354617825,"mc":[{"id":"1.231613187","rc":[{"batb":[[0,4.2,4],[1,4.1,12.59],[2,1.03,200.79]],"ltp":4.2,"tv":5.32,"id":12474498}]}]}
{"op":"mcm","clk":"11827355523","pt":1723354620249,"mc":[{"id":"1.231613187","rc":[{"batb":[[0,4.1,12.59],[1,1.03,200.79],[2,1.02,200.79]],"ltp":4.2,"tv":5.32,"id":12474498}]}]}
{"op":"mcm","clk":"11827355584","pt":1723354622423,"mc":[{"id":"1.231613187","rc":[{"batb":[[0,4.2,4],[1,4.1,12.59],[2,1.03,200.79]],"ltp":4.2,"tv":5.32,"id":12474498}]}]}
{"op":"mcm","clk":"11827355657","pt":1723354624845,"mc":[{"id":"1.231613187","rc":[{"batb":[[0,4.1,12.59],[1,1.03,200.79],[2,1.02,200.79]],"ltp":4.2,"tv":5.32,"id":12474498}]}]}
{"op":"mcm","clk":"11827355790","pt":1723354628347,"mc":[{"id":"1.231613187","rc":[{"batb":[[0,4.2,4],[1,4.1,12.59],[2,1.03,200.79]],"ltp":4.2,"tv":5.32,"id":12474498}]}]}
{"op":"mcm","clk":"11827355860","pt":1723354630766,"mc":[{"id":"1.231613187","rc":[{"batb":[[0,4.1,12.59],[1,1.03,200.79],[2,1.02,200.79]],"ltp":4.2,"tv":5.32,"id":12474498}]}]}
{"op":"mcm","clk":"11827355959","pt":1723354633732,"mc":[{"id":"1.231613187","rc":[{"batb":[[0,4.2,4],[1,4.1,12.59],[2,1.03,200.79]],"ltp":4.2,"tv":5.32,"id":12474498}]}]}
{"op":"mcm","clk":"11827356045","pt":1723354636046,"mc":[{"id":"1.231613187","rc":[{"batb":[[0,4.1,12.59],[1,1.03,200.79],[2,1.02,200.79]],"ltp":4.2,"tv":5.32,"id":12474498}]}]}
{"op":"mcm","clk":"11827356151","pt":1723354639183,"mc":[{"id":"1.231613187","rc":[{"batb":[[0,4.2,4],[1,4.1,12.59],[2,1.03,200.79]],"ltp":4.2,"tv":5.32,"id":12474498}]}]}
{"op":"mcm","clk":"11827356233","pt":1723354641449,"mc":[{"id":"1.231613187","rc":[{"batb":[[0,4.1,12.59],[1,1.03,200.79],[2,1.02,200.79]],"ltp":4.2,"tv":5.32,"id":12474498}]}]}
{"op":"mcm","clk":"11827356312","pt":1723354643660,"mc":[{"id":"1.231613187","rc":[{"batb":[[0,4.2,4],[1,4.1,12.59],[2,1.03,200.79]],"ltp":4.2,"tv":5.32,"id":12474498}]}]}
{"op":"mcm","clk":"11827356401","pt":1723354646071,"mc":[{"id":"1.231613187","rc":[{"batb":[[0,4.1,12.59],[1,1.03,200.79],[2,1.02,200.79]],"ltp":4.2,"tv":5.32,"id":12474498}]}]}
{"op":"mcm","clk":"11827356471","pt":1723354648378,"mc":[{"id":"1.231613187","rc":[{"batb":[[0,4.2,4],[1,4.1,12.59],[2,1.03,200.79]],"ltp":4.2,"tv":5.32,"id":12474498}]}]}
{"op":"mcm","clk":"11827356556","pt":1723354650789,"mc":[{"id":"1.231613187","rc":[{"batb":[[0,4.1,12.59],[1,1.03,200.79],[2,1.02,200.79]],"ltp":4.2,"tv":5.32,"id":12474498}]}]}
{"op":"mcm","clk":"11827356670","pt":1723354654090,"mc":[{"id":"1.231613187","rc":[{"batb":[[0,4.2,4],[1,4.1,12.59],[2,1.03,200.79]],"ltp":4.2,"tv":5.32,"id":12474498}]}]}
{"op":"mcm","clk":"11827356765","pt":1723354656472,"mc":[{"id":"1.231613187","rc":[{"batb":[[0,4.1,12.59],[1,1.03,200.79],[2,1.02,200.79]],"ltp":4.2,"tv":5.32,"id":12474498}]}]}
{"op":"mcm","clk":"11827356855","pt":1723354658688,"mc":[{"id":"1.231613187","rc":[{"batb":[[0,4.2,4],[1,4.1,12.59],[2,1.03,200.79]],"ltp":4.2,"tv":5.32,"id":12474498}]}]}
{"op":"mcm","clk":"11827356962","pt":1723354661164,"mc":[{"id":"1.231613187","rc":[{"batb":[[0,4.1,12.59],[1,1.03,200.79],[2,1.02,200.79]],"ltp":4.2,"tv":5.32,"id":12474498}]}]}
{"op":"mcm","clk":"11827357049","pt":1723354663479,"mc":[{"id":"1.231613187","rc":[{"batb":[[0,4.2,4],[1,4.1,12.59],[2,1.03,200.79]],"ltp":4.2,"tv":5.32,"id":12474498}]}]}
{"op":"mcm","clk":"11827357136","pt":1723354666200,"mc":[{"id":"1.231613187","rc":[{"batb":[[0,4.1,12.59],[1,1.03,200.79],[2,1.02,200.79]],"ltp":4.2,"tv":5.32,"id":12474498}]}]}
{"op":"mcm","clk":"11827357226","pt":1723354668402,"mc":[{"id":"1.231613187","rc":[{"batb":[[0,4.2,4],[1,4.1,12.59],[2,1.03,200.79]],"ltp":4.2,"tv":5.32,"id":12474498}]}]}
{"op":"mcm","clk":"11827357305","pt":1723354670716,"mc":[{"id":"1.231613187","rc":[{"batb":[[0,4.1,12.59],[1,1.03,200.79],[2,1.02,200.79]],"ltp":4.2,"tv":5.32,"id":12474498}]}]}
{"op":"mcm","clk":"11827357391","pt":1723354673429,"mc":[{"id":"1.231613187","rc":[{"batb":[[0,4.2,4],[1,4.1,12.59],[2,1.03,200.79]],"ltp":4.2,"tv":5.32,"id":12474498}]}]}
{"op":"mcm","clk":"11827357482","pt":1723354675834,"mc":[{"id":"1.231613187","rc":[{"batb":[[0,4.1,12.59],[1,1.03,200.79],[2,1.02,200.79]],"ltp":4.2,"tv":5.32,"id":12474498}]}]}
{"op":"mcm","clk":"11827357565","pt":1723354678196,"mc":[{"id":"1.231613187","rc":[{"batb":[[0,4.2,4],[1,4.1,12.59],[2,1.03,200.79]],"ltp":4.2,"tv":5.32,"id":12474498}]}]}
{"op":"mcm","clk":"11827357681","pt":1723354680733,"mc":[{"id":"1.231613187","rc":[{"batb":[[0,4.1,12.59],[1,1.03,200.79],[2,1.02,200.79]],"ltp":4.2,"tv":5.32,"id":12474498}]}]}
{"op":"mcm","clk":"11827357795","pt":1723354683125,"mc":[{"id":"1.231613187","rc":[{"batb":[[0,4.2,4],[1,4.1,12.59],[2,1.03,200.79]],"ltp":4.2,"tv":5.32,"id":12474498}]}]}
{"op":"mcm","clk":"11827357899","pt":1723354685484,"mc":[{"id":"1.231613187","rc":[{"batb":[[0,4.1,12.59],[1,1.03,200.79],[2,1.02,200.79]],"ltp":4.2,"tv":5.32,"id":12474498}]}]}
{"op":"mcm","clk":"11827358017","pt":1723354688510,"mc":[{"id":"1.231613187","rc":[{"batb":[[0,4.2,4],[1,4.1,12.59],[2,1.03,200.79]],"ltp":4.2,"tv":5.32,"id":12474498}]}]}
{"op":"mcm","clk":"11827358112","pt":1723354690916,"mc":[{"id":"1.231613187","rc":[{"batb":[[0,4.1,12.59],[1,1.03,200.79],[2,1.02,200.79]],"ltp":4.2,"tv":5.32,"id":12474498}]}]}
{"op":"mcm","clk":"11827358242","pt":1723354694348,"mc":[{"id":"1.231613187","rc":[{"batb":[[0,4.2,4],[1,4.1,12.59],[2,1.03,200.79]],"ltp":4.2,"tv":5.32,"id":12474498}]}]}
{"op":"mcm","clk":"11827358339","pt":1723354696753,"mc":[{"id":"1.231613187","rc":[{"batb":[[0,4.1,12.59],[1,1.03,200.79],[2,1.02,200.79]],"ltp":4.2,"tv":5.32,"id":12474498}]}]}
{"op":"mcm","clk":"11827358427","pt":1723354699726,"mc":[{"id":"1.231613187","rc":[{"batb":[[0,4.2,4],[1,4.1,12.59],[2,1.03,200.79]],"ltp":4.2,"tv":5.32,"id":12474498}]}]}
{"op":"mcm","clk":"11827358524","pt":1723354702141,"mc":[{"id":"1.231613187","rc":[{"batb":[[0,4.1,12.59],[1,1.03,200.79],[2,1.02,200.79]],"ltp":4.2,"tv":5.32,"id":12474498}]}]}
{"op":"mcm","clk":"11827358655","pt":1723354705162,"mc":[{"id":"1.231613187","rc":[{"batb":[[0,4.2,4],[1,4.1,12.59],[2,1.03,200.79]],"ltp":4.2,"tv":5.32,"id":12474498}]}]}
{"op":"mcm","clk":"11827358730","pt":1723354707464,"mc":[{"id":"1.231613187","rc":[{"batb":[[0,4.1,12.59],[1,1.03,200.79],[2,1.02,200.79]],"ltp":4.2,"tv":5.32,"id":12474498}]}]}
{"op":"mcm","clk":"11827358825","pt":1723354709868,"mc":[{"id":"1.231613187","rc":[{"batb":[[0,4.2,4],[1,4.1,12.59],[2,1.03,200.79]],"ltp":4.2,"tv":5.32,"id":12474498}]}]}
{"op":"mcm","clk":"11827358917","pt":1723354712387,"mc":[{"id":"1.231613187","rc":[{"batb":[[0,4.1,12.59],[1,1.03,200.79],[2,1.02,200.79]],"ltp":4.2,"tv":5.32,"id":12474498}]}]}
{"op":"mcm","clk":"11827359025","pt":1723354715769,"mc":[{"id":"1.231613187","rc":[{"batb":[[0,4.2,4],[1,4.1,12.59],[2,1.03,200.79]],"ltp":4.2,"tv":5.32,"id":12474498}]}]}
{"op":"mcm","clk":"11827359113","pt":1723354718069,"mc":[{"id":"1.231613187","rc":[{"batb":[[0,4.1,12.59],[1,1.03,200.79],[2,1.02,200.79]],"ltp":4.2,"tv":5.32,"id":12474498}]}]}
{"op":"mcm","clk":"11827359245","pt":1723354722063,"mc":[{"id":"1.231613187","rc":[{"batb":[[0,4.2,4],[1,4.1,12.59],[2,1.03,200.79]],"ltp":4.2,"tv":5.32,"id":12474498}]}]}
{"op":"mcm","clk":"11827359332","pt":1723354724486,"mc":[{"id":"1.231613187","rc":[{"batb":[[0,4.1,12.59],[1,1.03,200.79],[2,1.02,200.79]],"ltp":4.2,"tv":5.32,"id":12474498}]}]}
{"op":"mcm","clk":"11827359469","pt":1723354728377,"mc":[{"id":"1.231613187","rc":[{"batb":[[0,4.2,4],[1,4.1,12.59],[2,1.03,200.79]],"ltp":4.2,"tv":5.32,"id":12474498}]}]}
{"op":"mcm","clk":"11827359569","pt":1723354730904,"mc":[{"id":"1.231613187","rc":[{"batb":[[0,4.1,12.59],[1,1.03,200.79],[2,1.02,200.79]],"ltp":4.2,"tv":5.32,"id":12474498}]}]}
{"op":"mcm","clk":"11827359661","pt":1723354733112,"mc":[{"id":"1.231613187","rc":[{"batb":[[0,4.2,4],[1,4.1,12.59],[2,1.03,200.79]],"ltp":4.2,"tv":5.32,"id":12474498}]}]}
{"op":"mcm","clk":"11827359766","pt":1723354735373,"mc":[{"id":"1.231613187","rc":[{"batb":[[0,4.1,12.59],[1,1.03,200.79],[2,1.02,200.79]],"ltp":4.2,"tv":5.32,"id":12474498}]}]}
{"op":"mcm","clk":"11827359864","pt":1723354737693,"mc":[{"id":"1.231613187","rc":[{"batb":[[0,4.2,4],[1,4.1,12.59],[2,1.03,200.79]],"ltp":4.2,"tv":5.32,"id":12474498}]}]}
{"op":"mcm","clk":"11827359943","pt":1723354740105,"mc":[{"id":"1.231613187","rc":[{"batb":[[0,4.1,12.59],[1,1.03,200.79],[2,1.02,200.79]],"ltp":4.2,"tv":5.32,"id":12474498}]}]}
{"op":"mcm","clk":"11827360026","pt":1723354742336,"mc":[{"id":"1.231613187","rc":[{"batb":[[0,4.2,4],[1,4.1,12.59],[2,1.03,200.79]],"ltp":4.2,"tv":5.32,"id":12474498}]}]}
{"op":"mcm","clk":"11827360118","pt":1723354744731,"mc":[{"id":"1.231613187","rc":[{"batb":[[0,4.1,12.59],[1,1.03,200.79],[2,1.02,200.79]],"ltp":4.2,"tv":5.32,"id":12474498}]}]}
{"op":"mcm","clk":"11827360235","pt":1723354747205,"mc":[{"id":"1.231613187","rc":[{"batb":[[0,4.2,4],[1,4.1,12.59],[2,1.03,200.79]],"ltp":4.2,"tv":5.32,"id":12474498}]}]}
{"op":"mcm","clk":"11827360359","pt":1723354749639,"mc":[{"id":"1.231613187","rc":[{"batb":[[0,4.1,12.59],[1,1.03,200.79],[2,1.02,200.79]],"ltp":4.2,"tv":5.32,"id":12474498}]}]}
{"op":"mcm","clk":"11827360511","pt":1723354752993,"mc":[{"id":"1.231613187","rc":[{"batb":[[0,4.2,4],[1,4.1,12.59],[2,1.03,200.79]],"ltp":4.2,"tv":5.32,"id":12474498}]}]}
{"op":"mcm","clk":"11827360629","pt":1723354755400,"mc":[{"id":"1.231613187","rc":[{"batb":[[0,4.1,12.59],[1,1.03,200.79],[2,1.02,200.79]],"ltp":4.2,"tv":5.32,"id":12474498}]}]}
{"op":"mcm","clk":"11827360714","pt":1723354757609,"mc":[{"id":"1.231613187","rc":[{"batb":[[0,4.2,4],[1,4.1,12.59],[2,1.03,200.79]],"ltp":4.2,"tv":5.32,"id":12474498}]}]}
{"op":"mcm","clk":"11827360800","pt":1723354760026,"mc":[{"id":"1.231613187","rc":[{"batb":[[0,4.1,12.59],[1,1.03,200.79],[2,1.02,200.79]],"ltp":4.2,"tv":5.32,"id":12474498}]}]}
{"op":"mcm","clk":"11827360929","pt":1723354762541,"mc":[{"id":"1.231613187","rc":[{"batb":[[0,4.2,4],[1,4.1,12.59],[2,1.03,200.79]],"ltp":4.2,"tv":5.32,"id":12474498}]}]}
{"op":"mcm","clk":"11827361098","pt":1723354766814,"mc":[{"id":"1.231613187","rc":[{"batb":[[0,4.1,12.59],[1,1.03,200.79],[2,1.02,200.79]],"ltp":4.2,"tv":5.32,"id":12474498}]}]}
{"op":"mcm","clk":"11827361171","pt":1723354769011,"mc":[{"id":"1.231613187","rc":[{"batb":[[0,4.2,4],[1,4.1,12.59],[2,1.03,200.79]],"ltp":4.2,"tv":5.32,"id":12474498}]}]}
{"op":"mcm","clk":"11827361263","pt":1723354771532,"mc":[{"id":"1.231613187","rc":[{"batb":[[0,4.1,12.59],[1,1.03,200.79],[2,1.02,200.79]],"ltp":4.2,"tv":5.32,"id":12474498}]}]}
{"op":"mcm","clk":"11827361398","pt":1723354774722,"mc":[{"id":"1.231613187","rc":[{"batb":[[0,4.2,4],[1,4.1,12.59],[2,1.03,200.79]],"ltp":4.2,"tv":5.32,"id":12474498}]}]}
{"op":"mcm","clk":"11827361512","pt":1723354777039,"mc":[{"id":"1.231613187","rc":[{"batb":[[0,4.1,12.59],[1,1.03,200.79],[2,1.02,200.79]],"ltp":4.2,"tv":5.32,"id":12474498}]}]}
{"op":"mcm","clk":"11827361597","pt":1723354779255,"mc":[{"id":"1.231613187","rc":[{"batb":[[0,4.2,4],[1,4.1,12.59],[2,1.03,200.79]],"ltp":4.2,"tv":5.32,"id":12474498}]}]}
{"op":"mcm","clk":"11827361670","pt":1723354781420,"mc":[{"id":"1.231613187","rc":[{"batb":[[0,4.1,12.59],[1,1.03,200.79],[2,1.02,200.79]],"ltp":4.2,"tv":5.32,"id":12474498}]}]}
{"op":"mcm","clk":"11827361758","pt":1723354783637,"mc":[{"id":"1.231613187","rc":[{"batb":[[0,4.2,4],[1,4.1,12.59],[2,1.03,200.79]],"ltp":4.2,"tv":5.32,"id":12474498}]}]}
{"op":"mcm","clk":"11827361838","pt":1723354785968,"mc":[{"id":"1.231613187","rc":[{"batb":[[0,4.1,12.59],[1,1.03,200.79],[2,1.02,200.79]],"ltp":4.2,"tv":5.32,"id":12474498}]}]}
{"op":"mcm","clk":"11827361933","pt":1723354788436,"mc":[{"id":"1.231613187","rc":[{"batb":[[0,4.2,4],[1,4.1,12.59],[2,1.03,200.79]],"ltp":4.2,"tv":5.32,"id":12474498}]}]}
{"op":"mcm","clk":"11827362025","pt":1723354790743,"mc":[{"id":"1.231613187","rc":[{"batb":[[0,4.1,12.59],[1,1.03,200.79],[2,1.02,200.79]],"ltp":4.2,"tv":5.32,"id":12474498}]}]}
{"op":"mcm","clk":"11827362119","pt":1723354793183,"mc":[{"id":"1.231613187","rc":[{"batb":[[0,4.2,4],[1,4.1,12.59],[2,1.03,200.79]],"ltp":4.2,"tv":5.32,"id":12474498}]}]}
{"op":"mcm","clk":"11827362213","pt":1723354795463,"mc":[{"id":"1.231613187","rc":[{"batb":[[0,4.1,12.59],[1,1.03,200.79],[2,1.02,200.79]],"ltp":4.2,"tv":5.32,"id":12474498}]}]}
{"op":"mcm","clk":"11827362318","pt":1723354797671,"mc":[{"id":"1.231613187","rc":[{"batb":[[0,4.2,4],[1,4.1,12.59],[2,1.03,200.79]],"ltp":4.2,"tv":5.32,"id":12474498}]}]}
{"op":"mcm","clk":"11827362395","pt":1723354800084,"mc":[{"id":"1.231613187","rc":[{"batb":[[0,4.1,12.59],[1,1.03,200.79],[2,1.02,200.79]],"ltp":4.2,"tv":5.32,"id":12474498}]}]}
{"op":"mcm","clk":"11827362548","pt":1723354803185,"mc":[{"id":"1.231613187","rc":[{"batb":[[0,4.2,4],[1,4.1,12.59],[2,1.03,200.79]],"ltp":4.2,"tv":5.32,"id":12474498}]}]}
{"op":"mcm","clk":"11827362644","pt":1723354805465,"mc":[{"id":"1.231613187","rc":[{"batb":[[0,4.1,12.59],[1,1.03,200.79],[2,1.02,200.79]],"ltp":4.2,"tv":5.32,"id":12474498}]}]}
{"op":"mcm","clk":"11827362726","pt":1723354807671,"mc":[{"id":"1.231613187","rc":[{"batb":[[0,4.2,4],[1,4.1,12.59],[2,1.03,200.79]],"ltp":4.2,"tv":5.32,"id":12474498}]}]}
{"op":"mcm","clk":"11827362819","pt":1723354810084,"mc":[{"id":"1.231613187","rc":[{"batb":[[0,4.1,12.59],[1,1.03,200.79],[2,1.02,200.79]],"ltp":4.2,"tv":5.32,"id":12474498}]}]}
{"op":"mcm","clk":"11827362952","pt":1723354813476,"mc":[{"id":"1.231613187","rc":[{"batb":[[0,4.2,4],[1,4.1,12.59],[2,1.03,200.79]],"ltp":4.2,"tv":5.32,"id":12474498}]}]}
{"op":"mcm","clk":"11827363054","pt":1723354815782,"mc":[{"id":"1.231613187","rc":[{"batb":[[0,4.1,12.59],[1,1.03,200.79],[2,1.02,200.79]],"ltp":4.2,"tv":5.32,"id":12474498}]}]}
{"op":"mcm","clk":"11827363125","pt":1723354817981,"mc":[{"id":"1.231613187","rc":[{"batb":[[0,4.2,4],[1,4.1,12.59],[2,1.03,200.79]],"ltp":4.2,"tv":5.32,"id":12474498}]}]}
{"op":"mcm","clk":"11827363224","pt":1723354820489,"mc":[{"id":"1.231613187","rc":[{"batb":[[0,4.1,12.59],[1,1.03,200.79],[2,1.02,200.79]],"ltp":4.2,"tv":5.32,"id":12474498}]}]}
{"op":"mcm","clk":"11827363304","pt":1723354822697,"mc":[{"id":"1.231613187","rc":[{"batb":[[0,4.2,4],[1,4.1,12.59],[2,1.03,200.79]],"ltp":4.2,"tv":5.32,"id":12474498}]}]}
{"op":"mcm","clk":"11827363380","pt":1723354825000,"mc":[{"id":"1.231613187","rc":[{"batb":[[0,4.1,12.59],[1,1.03,200.79],[2,1.02,200.79]],"ltp":4.2,"tv":5.32,"id":12474498}]}]}
{"op":"mcm","clk":"11827363466","pt":1723354827309,"mc":[{"id":"1.231613187","rc":[{"batb":[[0,4.2,4],[1,4.1,12.59],[2,1.03,200.79]],"ltp":4.2,"tv":5.32,"id":12474498}]}]}
{"op":"mcm","clk":"11827363534","pt":1723354829610,"mc":[{"id":"1.231613187","rc":[{"batb":[[0,4.1,12.59],[1,1.03,200.79],[2,1.02,200.79]],"ltp":4.2,"tv":5.32,"id":12474498}]}]}
{"op":"mcm","clk":"11827363610","pt":1723354831810,"mc":[{"id":"1.231613187","rc":[{"batb":[[0,4.2,4],[1,4.1,12.59],[2,1.03,200.79]],"ltp":4.2,"tv":5.32,"id":12474498}]}]}
{"op":"mcm","clk":"11827363714","pt":1723354834328,"mc":[{"id":"1.231613187","rc":[{"batb":[[0,4.1,12.59],[1,1.03,200.79],[2,1.02,200.79]],"ltp":4.2,"tv":5.32,"id":12474498}]}]}
{"op":"mcm","clk":"11827363808","pt":1723354837406,"mc":[{"id":"1.231613187","rc":[{"batb":[[0,4.2,4],[1,4.1,12.59],[2,1.03,200.79]],"ltp":4.2,"tv":5.32,"id":12474498}]}]}
{"op":"mcm","clk":"11827363875","pt":1723354839930,"mc":[{"id":"1.231613187","rc":[{"batb":[[0,4.1,12.59],[1,1.03,200.79],[2,1.02,200.79]],"ltp":4.2,"tv":5.32,"id":12474498}]}]}
{"op":"mcm","clk":"11827363976","pt":1723354842940,"mc":[{"id":"1.231613187","rc":[{"batb":[[0,4.2,4],[1,4.1,12.59],[2,1.03,200.79]],"ltp":4.2,"tv":5.32,"id":12474498}]}]}
{"op":"mcm","clk":"11827364072","pt":1723354845148,"mc":[{"id":"1.231613187","rc":[{"batb":[[0,4.1,12.59],[1,1.03,200.79],[2,1.02,200.79]],"ltp":4.2,"tv":5.32,"id":12474498}]}]}
{"op":"mcm","clk":"11827364157","pt":1723354847310,"mc":[{"id":"1.231613187","rc":[{"batb":[[0,4.2,4],[1,4.1,12.59],[2,1.03,200.79]],"ltp":4.2,"tv":5.32,"id":12474498}]}]}
{"op":"mcm","clk":"11827364272","pt":1723354849818,"mc":[{"id":"1.231613187","rc":[{"batb":[[0,4.1,12.59],[1,1.03,200.79],[2,1.02,200.79]],"ltp":4.2,"tv":5.32,"id":12474498}]}]}
{"op":"mcm","clk":"11827364358","pt":1723354852152,"mc":[{"id":"1.231613187","rc":[{"batb":[[0,4.2,4],[1,4.1,12.59],[2,1.03,200.79]],"ltp":4.2,"tv":5.32,"id":12474498}]}]}
{"op":"mcm","clk":"11827364439","pt":1723354854458,"mc":[{"id":"1.231613187","rc":[{"batb":[[0,4.1,12.59],[1,1.03,200.79],[2,1.02,200.79]],"ltp":4.2,"tv":5.32,"id":12474498}]}]}
{"op":"mcm","clk":"11827364535","pt":1723354856728,"mc":[{"id":"1.231613187","rc":[{"batb":[[0,4.2,4],[1,4.1,12.59],[2,1.03,200.79]],"ltp":4.2,"tv":5.32,"id":12474498}]}]}
{"op":"mcm","clk":"11827364616","pt":1723354859132,"mc":[{"id":"1.231613187","rc":[{"batb":[[0,4.1,12.59],[1,1.03,200.79],[2,1.02,200.79]],"ltp":4.2,"tv":5.32,"id":12474498}]}]}
{"op":"mcm","clk":"11827364745","pt":1723354862326,"mc":[{"id":"1.231613187","rc":[{"batb":[[0,4.2,4],[1,4.1,12.59],[2,1.03,200.79]],"ltp":4.2,"tv":5.32,"id":12474498}]}]}
{"op":"mcm","clk":"11827364864","pt":1723354864859,"mc":[{"id":"1.231613187","rc":[{"batb":[[0,4.1,12.59],[1,1.03,200.79],[2,1.02,200.79]],"ltp":4.2,"tv":5.32,"id":12474498}]}]}
{"op":"mcm","clk":"11827364987","pt":1723354867887,"mc":[{"id":"1.231613187","rc":[{"batb":[[0,4.2,4],[1,4.1,12.59],[2,1.03,200.79]],"ltp":4.2,"tv":5.32,"id":12474498}]}]}
{"op":"mcm","clk":"11827365081","pt":1723354870260,"mc":[{"id":"1.231613187","rc":[{"batb":[[0,4.1,12.59],[1,1.03,200.79],[2,1.02,200.79]],"ltp":4.2,"tv":5.32,"id":12474498}]}]}
{"op":"mcm","clk":"11827365204","pt":1723354873354,"mc":[{"id":"1.231613187","rc":[{"batb":[[0,4.2,4],[1,4.1,12.59],[2,1.03,200.79]],"ltp":4.2,"tv":5.32,"id":12474498}]}]}
{"op":"mcm","clk":"11827365303","pt":1723354875878,"mc":[{"id":"1.231613187","rc":[{"batb":[[0,4.1,12.59],[1,1.03,200.79],[2,1.02,200.79]],"ltp":4.2,"tv":5.32,"id":12474498}]}]}
{"op":"mcm","clk":"11827365492","pt":1723354880087,"mc":[{"id":"1.231613187","rc":[{"batb":[[0,4.2,4],[1,4.1,12.59],[2,1.03,200.79]],"ltp":4.2,"tv":5.32,"id":12474498}]}]}
{"op":"mcm","clk":"11827365607","pt":1723354882398,"mc":[{"id":"1.231613187","rc":[{"batb":[[0,4.1,12.59],[1,1.03,200.79],[2,1.02,200.79]],"ltp":4.2,"tv":5.32,"id":12474498}]}]}
{"op":"mcm","clk":"11827365724","pt":1723354885475,"mc":[{"id":"1.231613187","rc":[{"batb":[[0,4.2,4],[1,4.1,12.59],[2,1.03,200.79]],"ltp":4.2,"tv":5.32,"id":12474498}]}]}
{"op":"mcm","clk":"11827365809","pt":1723354887775,"mc":[{"id":"1.231613187","rc":[{"batb":[[0,4.1,12.59],[1,1.03,200.79],[2,1.02,200.79]],"ltp":4.2,"tv":5.32,"id":12474498}]}]}
{"op":"mcm","clk":"11827365878","pt":1723354889970,"mc":[{"id":"1.231613187","rc":[{"batb":[[0,4.2,4],[1,4.1,12.59],[2,1.03,200.79]],"ltp":4.2,"tv":5.32,"id":12474498}]}]}
{"op":"mcm","clk":"11827365970","pt":1723354892289,"mc":[{"id":"1.231613187","rc":[{"batb":[[0,4.1,12.59],[1,1.03,200.79],[2,1.02,200.79]],"ltp":4.2,"tv":5.32,"id":12474498}]}]}
{"op":"mcm","clk":"11827366114","pt":1723354895771,"mc":[{"id":"1.231613187","rc":[{"batb":[[0,4.2,4],[1,4.1,12.59],[2,1.03,200.79]],"ltp":4.2,"tv":5.32,"id":12474498}]}]}
{"op":"mcm","clk":"11827366196","pt":1723354898082,"mc":[{"id":"1.231613187","rc":[{"batb":[[0,4.1,12.59],[1,1.03,200.79],[2,1.02,200.79]],"ltp":4.2,"tv":5.32,"id":12474498}]}]}
{"op":"mcm","clk":"11827366267","pt":1723354900202,"mc":[{"id":"1.231613187","rc":[{"batb":[[0,4.2,4],[1,4.1,12.59],[2,1.03,200.79]],"ltp":4.2,"tv":5.32,"id":12474498}]}]}
{"op":"mcm","clk":"11827366366","pt":1723354902588,"mc":[{"id":"1.231613187","rc":[{"batb":[[0,4.1,12.59],[1,1.03,200.79],[2,1.02,200.79]],"ltp":4.2,"tv":5.32,"id":12474498}]}]}
{"op":"mcm","clk":"11827366494","pt":1723354905829,"mc":[{"id":"1.231613187","rc":[{"batb":[[0,4.2,4],[1,4.1,12.59],[2,1.03,200.79]],"ltp":4.2,"tv":5.32,"id":12474498}]}]}
{"op":"mcm","clk":"11827366600","pt":1723354908188,"mc":[{"id":"1.231613187","rc":[{"batb":[[0,4.1,12.59],[1,1.03,200.79],[2,1.02,200.79]],"ltp":4.2,"tv":5.32,"id":12474498}]}]}
{"op":"mcm","clk":"11827366707","pt":1723354910803,"mc":[{"id":"1.231613187","rc":[{"batb":[[0,4.2,4],[1,4.1,12.59],[2,1.03,200.79]],"ltp":4.2,"tv":5.32,"id":12474498}]}]}
{"op":"mcm","clk":"11827366790","pt":1723354913422,"mc":[{"id":"1.231613187","rc":[{"batb":[[0,4.1,12.59],[1,1.03,200.79],[2,1.02,200.79]],"ltp":4.2,"tv":5.32,"id":12474498}]}]}
{"op":"mcm","clk":"11827366898","pt":1723354916297,"mc":[{"id":"1.231613187","rc":[{"batb":[[0,4.2,4],[1,4.1,12.59],[2,1.03,200.79]],"ltp":4.2,"tv":5.32,"id":12474498}]}]}
{"op":"mcm","clk":"11827366990","pt":1723354918707,"mc":[{"id":"1.231613187","rc":[{"batb":[[0,4.1,12.59],[1,1.03,200.79],[2,1.02,200.79]],"ltp":4.2,"tv":5.32,"id":12474498}]}]}
{"op":"mcm","clk":"11827367082","pt":1723354921022,"mc":[{"id":"1.231613187","rc":[{"batb":[[0,4.2,4],[1,4.1,12.59],[2,1.03,200.79]],"ltp":4.2,"tv":5.32,"id":12474498}]}]}
{"op":"mcm","clk":"11827367180","pt":1723354923341,"mc":[{"id":"1.231613187","rc":[{"batb":[[0,4.1,12.59],[1,1.03,200.79],[2,1.02,200.79]],"ltp":4.2,"tv":5.32,"id":12474498}]}]}
{"op":"mcm","clk":"11827367281","pt":1723354925806,"mc":[{"id":"1.231613187","rc":[{"batb":[[0,4.2,4],[1,4.1,12.59],[2,1.03,200.79]],"ltp":4.2,"tv":5.32,"id":12474498}]}]}
{"op":"mcm","clk":"11827367406","pt":1723354928118,"mc":[{"id":"1.231613187","rc":[{"batb":[[0,4.1,12.59],[1,1.03,200.79],[2,1.02,200.79]],"ltp":4.2,"tv":5.32,"id":12474498}]}]}
{"op":"mcm","clk":"11827367503","pt":1723354930534,"mc":[{"id":"1.231613187","rc":[{"batb":[[0,4.2,4],[1,4.1,12.59],[2,1.03,200.79]],"ltp":4.2,"tv":5.32,"id":12474498}]}]}
{"op":"mcm","clk":"11827367580","pt":1723354932740,"mc":[{"id":"1.231613187","rc":[{"batb":[[0,4.1,12.59],[1,1.03,200.79],[2,1.02,200.79]],"ltp":4.2,"tv":5.32,"id":12474498}]}]}
{"op":"mcm","clk":"11827367710","pt":1723354935508,"mc":[{"id":"1.231613187","rc":[{"batb":[[0,4.2,4],[1,4.1,12.59],[2,1.03,200.79]],"ltp":4.2,"tv":5.32,"id":12474498}]}]}
{"op":"mcm","clk":"11827367808","pt":1723354938126,"mc":[{"id":"1.231613187","rc":[{"batb":[[0,4.1,12.59],[1,1.03,200.79],[2,1.02,200.79]],"ltp":4.2,"tv":5.32,"id":12474498}]}]}
{"op":"mcm","clk":"11827367917","pt":1723354940944,"mc":[{"id":"1.231613187","rc":[{"batb":[[0,4.2,4],[1,4.1,12.59],[2,1.03,200.79]],"ltp":4.2,"tv":5.32,"id":12474498}]}]}
{"op":"mcm","clk":"11827368012","pt":1723354943348,"mc":[{"id":"1.231613187","rc":[{"batb":[[0,4.1,12.59],[1,1.03,200.79],[2,1.02,200.79]],"ltp":4.2,"tv":5.32,"id":12474498}]}]}
{"op":"mcm","clk":"11827368081","pt":1723354945451,"mc":[{"id":"1.231613187","rc":[{"batb":[[0,4.2,4],[1,4.1,12.59],[2,1.03,200.79]],"ltp":4.2,"tv":5.32,"id":12474498}]}]}
{"op":"mcm","clk":"11827368179","pt":1723354947967,"mc":[{"id":"1.231613187","rc":[{"batb":[[0,4.1,12.59],[1,1.03,200.79],[2,1.02,200.79]],"ltp":4.2,"tv":5.32,"id":12474498}]}]}
{"op":"mcm","clk":"11827368304","pt":1723354951785,"mc":[{"id":"1.231613187","rc":[{"batb":[[0,4.2,4],[1,4.1,12.59],[2,1.03,200.79]],"ltp":4.2,"tv":5.32,"id":12474498}]}]}
{"op":"mcm","clk":"11827368398","pt":1723354954461,"mc":[{"id":"1.231613187","rc":[{"batb":[[0,4.1,12.59],[1,1.03,200.79],[2,1.02,200.79]],"ltp":4.2,"tv":5.32,"id":12474498}]}]}
{"op":"mcm","clk":"11827378529","pt":1723355264707,"mc":[{"id":"1.231613187","rc":[{"trd":[[4.3,0.46]],"ltp":4.3,"tv":5.77,"id":12474498},{"trd":[[1.3,16.56]],"batl":[[0,1.3,9.76]],"ltp":1.3,"tv":1190.78,"id":12482925}],"tv":1196.56}]}
{"op":"mcm","clk":"11827399435","pt":1723355819927,"mc":[{"id":"1.231613187","rc":[{"trd":[[4.3,0.91]],"ltp":4.3,"tv":6.22,"id":12474498},{"trd":[[1.3,18.04]],"batl":[[0,1.3,8.27]],"ltp":1.3,"tv":1192.27,"id":12482925}],"tv":1198.5}]}
{"op":"mcm","clk":"11827399835","pt":1723355830411,"mc":[{"id":"1.231613187","rc":[{"batb":[[1,1.14,171.53],[2,1.03,200.79]],"ltp":4.3,"tv":6.22,"id":12474498}]}]}
{"op":"mcm","clk":"11827399882","pt":1723355831835,"mc":[{"id":"1.231613187","rc":[{"batb":[[1,1.53,171.53],[2,1.14,171.53]],"ltp":4.3,"tv":6.22,"id":12474498}]}]}
{"op":"mcm","clk":"11827399909","pt":1723355832550,"mc":[{"id":"1.231613187","rc":[{"batb":[[1,1.56,171.53],[2,1.54,171.53]],"ltp":4.3,"tv":6.22,"id":12474498}]}]}
{"op":"mcm","clk":"11827399926","pt":1723355832915,"mc":[{"id":"1.231613187","rc":[{"batb":[[1,1.59,171.53],[2,1.56,171.53]],"ltp":4.3,"tv":6.22,"id":12474498}]}]}
{"op":"mcm","clk":"11827400018","pt":1723355835325,"mc":[{"id":"1.231613187","rc":[{"batb":[[1,1.59,171.61]],"ltp":4.3,"tv":6.22,"id":12474498}]}]}
{"op":"mcm","clk":"11827400048","pt":1723355835936,"mc":[{"id":"1.231613187","rc":[{"batb":[[2,1.58,171.53]],"ltp":4.3,"tv":6.22,"id":12474498}]}]}
{"op":"mcm","clk":"11827405570","pt":1723356000992,"mc":[{"id":"1.231613187","rc":[{"batb":[[0,4.2,4],[1,4.1,12.59],[2,1.59,171.61]],"ltp":4.3,"tv":6.22,"id":12474498}]}]}
{"op":"mcm","clk":"11827405755","pt":1723356003334,"mc":[{"id":"1.231613187","rc":[{"batb":[[0,4.1,12.59],[1,1.59,171.61],[2,1.58,171.53]],"ltp":4.3,"tv":6.22,"id":12474498}]}]}
{"op":"mcm","clk":"11827405901","pt":1723356005649,"mc":[{"id":"1.231613187","rc":[{"batb":[[0,4.2,4],[1,4.1,12.59],[2,1.59,171.61]],"ltp":4.3,"tv":6.22,"id":12474498}]}]}
{"op":"mcm","clk":"11827406010","pt":1723356008030,"mc":[{"id":"1.231613187","rc":[{"batb":[[0,4.1,12.59],[1,1.59,171.61],[2,1.58,171.53]],"ltp":4.3,"tv":6.22,"id":12474498}]}]}
{"op":"mcm","clk":"11827406112","pt":1723356010253,"mc":[{"id":"1.231613187","rc":[{"batb":[[0,4.2,4],[1,4.1,12.59],[2,1.59,171.61]],"ltp":4.3,"tv":6.22,"id":12474498}]}]}
{"op":"mcm","clk":"11827406182","pt":1723356012427,"mc":[{"id":"1.231613187","rc":[{"batb":[[0,4.1,12.59],[1,1.59,171.61],[2,1.58,171.53]],"ltp":4.3,"tv":6.22,"id":12474498}]}]}
{"op":"mcm","clk":"11827406251","pt":1723356014735,"mc":[{"id":"1.231613187","rc":[{"batb":[[0,4.2,4],[1,4.1,12.59],[2,1.59,171.61]],"ltp":4.3,"tv":6.22,"id":12474498}]}]}
{"op":"mcm","clk":"11827406349","pt":1723356016945,"mc":[{"id":"1.231613187","rc":[{"batb":[[0,4.1,12.59],[1,1.59,171.61],[2,1.58,171.53]],"ltp":4.3,"tv":6.22,"id":12474498}]}]}
{"op":"mcm","clk":"11827406484","pt":1723356019259,"mc":[{"id":"1.231613187","rc":[{"batb":[[0,4.2,4],[1,4.1,12.59],[2,1.59,171.61]],"ltp":4.3,"tv":6.22,"id":12474498}]}]}
{"op":"mcm","clk":"11827406611","pt":1723356021943,"mc":[{"id":"1.231613187","rc":[{"batb":[[0,4.1,12.59],[1,1.59,171.61],[2,1.58,171.53]],"ltp":4.3,"tv":6.22,"id":12474498}]}]}
{"op":"mcm","clk":"11827406721","pt":1723356025082,"mc":[{"id":"1.231613187","rc":[{"batb":[[0,4.2,4],[1,4.1,12.59],[2,1.59,171.61]],"ltp":4.3,"tv":6.22,"id":12474498}]}]}
{"op":"mcm","clk":"11827406802","pt":1723356027545,"mc":[{"id":"1.231613187","rc":[{"batb":[[0,4.1,12.59],[1,1.59,171.61],[2,1.58,171.53]],"ltp":4.3,"tv":6.22,"id":12474498}]}]}
{"op":"mcm","clk":"11827406882","pt":1723356030565,"mc":[{"id":"1.231613187","rc":[{"batb":[[0,4.2,4],[1,4.1,12.59],[2,1.59,171.61]],"ltp":4.3,"tv":6.22,"id":12474498}]}]}
{"op":"mcm","clk":"11827407002","pt":1723356033081,"mc":[{"id":"1.231613187","rc":[{"batb":[[0,4.1,12.59],[1,1.59,171.61],[2,1.58,171.53]],"ltp":4.3,"tv":6.22,"id":12474498}]}]}
{"op":"mcm","clk":"11827407128","pt":1723356036157,"mc":[{"id":"1.231613187","rc":[{"batb":[[0,4.2,4],[1,4.1,12.59],[2,1.59,171.61]],"ltp":4.3,"tv":6.22,"id":12474498}]}]}
{"op":"mcm","clk":"11827407216","pt":1723356038771,"mc":[{"id":"1.231613187","rc":[{"batb":[[0,4.1,12.59],[1,1.59,171.61],[2,1.58,171.53]],"ltp":4.3,"tv":6.22,"id":12474498}]}]}
{"op":"mcm","clk":"11827407322","pt":1723356041793,"mc":[{"id":"1.231613187","rc":[{"batb":[[0,4.2,4],[1,4.1,12.59],[2,1.59,171.61]],"ltp":4.3,"tv":6.22,"id":12474498}]}]}
{"op":"mcm","clk":"11827407387","pt":1723356044198,"mc":[{"id":"1.231613187","rc":[{"batb":[[0,4.1,12.59],[1,1.59,171.61],[2,1.58,171.53]],"ltp":4.3,"tv":6.22,"id":12474498}]}]}
{"op":"mcm","clk":"11827407568","pt":1723356047995,"mc":[{"id":"1.231613187","rc":[{"batb":[[0,4.2,4],[1,4.1,12.59],[2,1.59,171.61]],"ltp":4.3,"tv":6.22,"id":12474498}]}]}
{"op":"mcm","clk":"11827407660","pt":1723356050511,"mc":[{"id":"1.231613187","rc":[{"batb":[[0,4.1,12.59],[1,1.59,171.61],[2,1.58,171.53]],"ltp":4.3,"tv":6.22,"id":12474498}]}]}
{"op":"mcm","clk":"11827407922","pt":1723356054107,"mc":[{"id":"1.231613187","rc":[{"batb":[[0,4.2,4],[1,4.1,12.59],[2,1.59,171.61]],"ltp":4.3,"tv":6.22,"id":12474498}]}]}
{"op":"mcm","clk":"11827408021","pt":1723356056410,"mc":[{"id":"1.231613187","rc":[{"batb":[[0,4.1,12.59],[1,1.59,171.61],[2,1.58,171.53]],"ltp":4.3,"tv":6.22,"id":12474498}]}]}
{"op":"mcm","clk":"11827408134","pt":1723356059788,"mc":[{"id":"1.231613187","rc":[{"batb":[[0,4.2,4],[1,4.1,12.59],[2,1.59,171.61]],"ltp":4.3,"tv":6.22,"id":12474498}]}]}
{"op":"mcm","clk":"11827408231","pt":1723356062207,"mc":[{"id":"1.231613187","rc":[{"batb":[[0,4.1,12.59],[1,1.59,171.61],[2,1.58,171.53]],"ltp":4.3,"tv":6.22,"id":12474498}]}]}
{"op":"mcm","clk":"11827408303","pt":1723356064286,"mc":[{"id":"1.231613187","rc":[{"batb":[[0,4.2,4],[1,4.1,12.59],[2,1.59,171.61]],"ltp":4.3,"tv":6.22,"id":12474498}]}]}
{"op":"mcm","clk":"11827408402","pt":1723356066619,"mc":[{"id":"1.231613187","rc":[{"batb":[[0,4.1,12.59],[1,1.59,171.61],[2,1.58,171.53]],"ltp":4.3,"tv":6.22,"id":12474498}]}]}
{"op":"mcm","clk":"11827408479","pt":1723356068895,"mc":[{"id":"1.231613187","rc":[{"batb":[[0,4.2,4],[1,4.1,12.59],[2,1.59,171.61]],"ltp":4.3,"tv":6.22,"id":12474498}]}]}
{"op":"mcm","clk":"11827408557","pt":1723356071313,"mc":[{"id":"1.231613187","rc":[{"batb":[[0,4.1,12.59],[1,1.59,171.61],[2,1.58,171.53]],"ltp":4.3,"tv":6.22,"id":12474498}]}]}
{"op":"mcm","clk":"11827408625","pt":1723356073524,"mc":[{"id":"1.231613187","rc":[{"batb":[[0,4.2,4],[1,4.1,12.59],[2,1.59,171.61]],"ltp":4.3,"tv":6.22,"id":12474498}]}]}
{"op":"mcm","clk":"11827408717","pt":1723356075727,"mc":[{"id":"1.231613187","rc":[{"batb":[[0,4.1,12.59],[1,1.59,171.61],[2,1.58,171.53]],"ltp":4.3,"tv":6.22,"id":12474498}]}]}
{"op":"mcm","clk":"11827408889","pt":1723356079020,"mc":[{"id":"1.231613187","rc":[{"batb":[[0,4.2,4],[1,4.1,12.59],[2,1.59,171.61]],"ltp":4.3,"tv":6.22,"id":12474498}]}]}
{"op":"mcm","clk":"11827408987","pt":1723356081237,"mc":[{"id":"1.231613187","rc":[{"batb":[[0,4.1,12.59],[1,1.59,171.61],[2,1.58,171.53]],"ltp":4.3,"tv":6.22,"id":12474498}]}]}
{"op":"mcm","clk":"11827409056","pt":1723356083540,"mc":[{"id":"1.231613187","rc":[{"batb":[[0,4.2,4],[1,4.1,12.59],[2,1.59,171.61]],"ltp":4.3,"tv":6.22,"id":12474498}]}]}
{"op":"mcm","clk":"11827409141","pt":1723356086001,"mc":[{"id":"1.231613187","rc":[{"batb":[[0,4.1,12.59],[1,1.59,171.61],[2,1.58,171.53]],"ltp":4.3,"tv":6.22,"id":12474498}]}]}
{"op":"mcm","clk":"11827409244","pt":1723356089333,"mc":[{"id":"1.231613187","rc":[{"batb":[[0,4.2,4],[1,4.1,12.59],[2,1.59,171.61]],"ltp":4.3,"tv":6.22,"id":12474498}]}]}
{"op":"mcm","clk":"11827409348","pt":1723356091647,"mc":[{"id":"1.231613187","rc":[{"batb":[[0,4.1,12.59],[1,1.59,171.61],[2,1.58,171.53]],"ltp":4.3,"tv":6.22,"id":12474498}]}]}
{"op":"mcm","clk":"11827409509","pt":1723356095347,"mc":[{"id":"1.231613187","rc":[{"batb":[[0,4.2,4],[1,4.1,12.59],[2,1.59,171.61]],"ltp":4.3,"tv":6.22,"id":12474498}]}]}
{"op":"mcm","clk":"11827409600","pt":1723356097649,"mc":[{"id":"1.231613187","rc":[{"batb":[[0,4.1,12.59],[1,1.59,171.61],[2,1.58,171.53]],"ltp":4.3,"tv":6.22,"id":12474498}]}]}
{"op":"mcm","clk":"11827409685","pt":1723356100414,"mc":[{"id":"1.231613187","rc":[{"batb":[[0,4.2,4],[1,4.1,12.59],[2,1.59,171.61]],"ltp":4.3,"tv":6.22,"id":12474498}]}]}
{"op":"mcm","clk":"11827409768","pt":1723356102830,"mc":[{"id":"1.231613187","rc":[{"batb":[[0,4.1,12.59],[1,1.59,171.61],[2,1.58,171.53]],"ltp":4.3,"tv":6.22,"id":12474498}]}]}
{"op":"mcm","clk":"11827409856","pt":1723356105037,"mc":[{"id":"1.231613187","rc":[{"batb":[[0,4.2,4],[1,4.1,12.59],[2,1.59,171.61]],"ltp":4.3,"tv":6.22,"id":12474498}]}]}
{"op":"mcm","clk":"11827409954","pt":1723356108268,"mc":[{"id":"1.231613187","rc":[{"batb":[[0,4.1,12.59],[1,1.59,171.61],[2,1.58,171.53]],"ltp":4.3,"tv":6.22,"id":12474498}]}]}
{"op":"mcm","clk":"11827410057","pt":1723356111140,"mc":[{"id":"1.231613187","rc":[{"batb":[[0,4.2,4],[1,4.1,12.59],[2,1.59,171.61]],"ltp":4.3,"tv":6.22,"id":12474498}]}]}
{"op":"mcm","clk":"11827410133","pt":1723356113556,"mc":[{"id":"1.231613187","rc":[{"batb":[[0,4.1,12.59],[1,1.59,171.61],[2,1.58,171.53]],"ltp":4.3,"tv":6.22,"id":12474498}]}]}
{"op":"mcm","clk":"11827410194","pt":1723356115772,"mc":[{"id":"1.231613187","rc":[{"batb":[[0,4.2,4],[1,4.1,12.59],[2,1.59,171.61]],"ltp":4.3,"tv":6.22,"id":12474498}]}]}
{"op":"mcm","clk":"11827410383","pt":1723356120961,"mc":[{"id":"1.231613187","rc":[{"batb":[[0,4.1,12.59],[1,1.59,171.61],[2,1.58,171.53]],"ltp":4.3,"tv":6.22,"id":12474498}]}]}
{"op":"mcm","clk":"11827410492","pt":1723356123164,"mc":[{"id":"1.231613187","rc":[{"batb":[[0,4.2,4],[1,4.1,12.59],[2,1.59,171.61]],"ltp":4.3,"tv":6.22,"id":12474498}]}]}
{"op":"mcm","clk":"11827410594","pt":1723356125941,"mc":[{"id":"1.231613187","rc":[{"batb":[[0,4.1,12.59],[1,1.59,171.61],[2,1.58,171.53]],"ltp":4.3,"tv":6.22,"id":12474498}]}]}
{"op":"mcm","clk":"11827410660","pt":1723356128456,"mc":[{"id":"1.231613187","rc":[{"batb":[[0,4.2,4],[1,4.1,12.59],[2,1.59,171.61]],"ltp":4.3,"tv":6.22,"id":12474498}]}]}
{"op":"mcm","clk":"11827410736","pt":1723356130976,"mc":[{"id":"1.231613187","rc":[{"batb":[[0,4.1,12.59],[1,1.59,171.61],[2,1.58,171.53]],"ltp":4.3,"tv":6.22,"id":12474498}]}]}
{"op":"mcm","clk":"11827410857","pt":1723356134156,"mc":[{"id":"1.231613187","rc":[{"batb":[[0,4.2,4],[1,4.1,12.59],[2,1.59,171.61]],"ltp":4.3,"tv":6.22,"id":12474498}]}]}
{"op":"mcm","clk":"11827410937","pt":1723356136465,"mc":[{"id":"1.231613187","rc":[{"batb":[[0,4.1,12.59],[1,1.59,171.61],[2,1.58,171.53]],"ltp":4.3,"tv":6.22,"id":12474498}]}]}
{"op":"mcm","clk":"11827411040","pt":1723356138782,"mc":[{"id":"1.231613187","rc":[{"batb":[[0,4.2,4],[1,4.1,12.59],[2,1.59,171.61]],"ltp":4.3,"tv":6.22,"id":12474498}]}]}
{"op":"mcm","clk":"11827411135","pt":1723356141041,"mc":[{"id":"1.231613187","rc":[{"batb":[[0,4.1,12.59],[1,1.59,171.61],[2,1.58,171.53]],"ltp":4.3,"tv":6.22,"id":12474498}]}]}
{"op":"mcm","clk":"11827411218","pt":1723356143288,"mc":[{"id":"1.231613187","rc":[{"batb":[[0,4.2,4],[1,4.1,12.59],[2,1.59,171.61]],"ltp":4.3,"tv":6.22,"id":12474498}]}]}
{"op":"mcm","clk":"11827411295","pt":1723356145694,"mc":[{"id":"1.231613187","rc":[{"batb":[[0,4.1,12.59],[1,1.59,171.61],[2,1.58,171.53]],"ltp":4.3,"tv":6.22,"id":12474498}]}]}
{"op":"mcm","clk":"11827411425","pt":1723356148922,"mc":[{"id":"1.231613187","rc":[{"batb":[[0,4.2,4],[1,4.1,12.59],[2,1.59,171.61]],"ltp":4.3,"tv":6.22,"id":12474498}]}]}
{"op":"mcm","clk":"11827411527","pt":1723356151288,"mc":[{"id":"1.231613187","rc":[{"batb":[[0,4.1,12.59],[1,1.59,171.61],[2,1.58,171.53]],"ltp":4.3,"tv":6.22,"id":12474498}]}]}
{"op":"mcm","clk":"11827411640","pt":1723356154421,"mc":[{"id":"1.231613187","rc":[{"batb":[[0,4.2,4],[1,4.1,12.59],[2,1.59,171.61]],"ltp":4.3,"tv":6.22,"id":12474498}]}]}
{"op":"mcm","clk":"11827411733","pt":1723356156729,"mc":[{"id":"1.231613187","rc":[{"batb":[[0,4.1,12.59],[1,1.59,171.61],[2,1.58,171.53]],"ltp":4.3,"tv":6.22,"id":12474498}]}]}
{"op":"mcm","clk":"11827411836","pt":1723356159020,"mc":[{"id":"1.231613187","rc":[{"batb":[[0,4.2,4],[1,4.1,12.59],[2,1.59,171.61]],"ltp":4.3,"tv":6.22,"id":12474498}]}]}
{"op":"mcm","clk":"11827411924","pt":1723356161429,"mc":[{"id":"1.231613187","rc":[{"batb":[[0,4.1,12.59],[1,1.59,171.61],[2,1.58,171.53]],"ltp":4.3,"tv":6.22,"id":12474498}]}]}
{"op":"mcm","clk":"11827412000","pt":1723356163734,"mc":[{"id":"1.231613187","rc":[{"batb":[[0,4.2,4],[1,4.1,12.59],[2,1.59,171.61]],"ltp":4.3,"tv":6.22,"id":12474498}]}]}
{"op":"mcm","clk":"11827412102","pt":1723356166152,"mc":[{"id":"1.231613187","rc":[{"batb":[[0,4.1,12.59],[1,1.59,171.61],[2,1.58,171.53]],"ltp":4.3,"tv":6.22,"id":12474498}]}]}
{"op":"mcm","clk":"11827412198","pt":1723356168301,"mc":[{"id":"1.231613187","rc":[{"batb":[[0,4.2,4],[1,4.1,12.59],[2,1.59,171.61]],"ltp":4.3,"tv":6.22,"id":12474498}]}]}
{"op":"mcm","clk":"11827412298","pt":1723356170605,"mc":[{"id":"1.231613187","rc":[{"batb":[[0,4.1,12.59],[1,1.59,171.61],[2,1.58,171.53]],"ltp":4.3,"tv":6.22,"id":12474498}]}]}
{"op":"mcm","clk":"11827412396","pt":1723356172817,"mc":[{"id":"1.231613187","rc":[{"batb":[[0,4.2,4],[1,4.1,12.59],[2,1.59,171.61]],"ltp":4.3,"tv":6.22,"id":12474498}]}]}
{"op":"mcm","clk":"11827412499","pt":1723356175243,"mc":[{"id":"1.231613187","rc":[{"batb":[[0,4.1,12.59],[1,1.59,171.61],[2,1.58,171.53]],"ltp":4.3,"tv":6.22,"id":12474498}]}]}
{"op":"mcm","clk":"11827412552","pt":1723356177347,"mc":[{"id":"1.231613187","rc":[{"batb":[[0,4.2,4],[1,4.1,12.59],[2,1.59,171.61]],"ltp":4.3,"tv":6.22,"id":12474498}]}]}
{"op":"mcm","clk":"11827412627","pt":1723356179652,"mc":[{"id":"1.231613187","rc":[{"batb":[[0,4.1,12.59],[1,1.59,171.61],[2,1.58,171.53]],"ltp":4.3,"tv":6.22,"id":12474498}]}]}
{"op":"mcm","clk":"11827412734","pt":1723356182525,"mc":[{"id":"1.231613187","rc":[{"batb":[[0,4.2,4],[1,4.1,12.59],[2,1.59,171.61]],"ltp":4.3,"tv":6.22,"id":12474498}]}]}
{"op":"mcm","clk":"11827412842","pt":1723356185145,"mc":[{"id":"1.231613187","rc":[{"batb":[[0,4.1,12.59],[1,1.59,171.61],[2,1.58,171.53]],"ltp":4.3,"tv":6.22,"id":12474498}]}]}
{"op":"mcm","clk":"11827412931","pt":1723356187460,"mc":[{"id":"1.231613187","rc":[{"batb":[[0,4.2,4],[1,4.1,12.59],[2,1.59,171.61]],"ltp":4.3,"tv":6.22,"id":12474498}]}]}
{"op":"mcm","clk":"11827412996","pt":1723356189626,"mc":[{"id":"1.231613187","rc":[{"batb":[[0,4.1,12.59],[1,1.59,171.61],[2,1.58,171.53]],"ltp":4.3,"tv":6.22,"id":12474498}]}]}
{"op":"mcm","clk":"11827413075","pt":1723356192039,"mc":[{"id":"1.231613187","rc":[{"batb":[[0,4.2,4],[1,4.1,12.59],[2,1.59,171.61]],"ltp":4.3,"tv":6.22,"id":12474498}]}]}
{"op":"mcm","clk":"11827413180","pt":1723356194347,"mc":[{"id":"1.231613187","rc":[{"batb":[[0,4.1,12.59],[1,1.59,171.61],[2,1.58,171.53]],"ltp":4.3,"tv":6.22,"id":12474498}]}]}
{"op":"mcm","clk":"11827413299","pt":1723356197437,"mc":[{"id":"1.231613187","rc":[{"batb":[[0,4.2,4],[1,4.1,12.59],[2,1.59,171.61]],"ltp":4.3,"tv":6.22,"id":12474498}]}]}
{"op":"mcm","clk":"11827413411","pt":1723356199854,"mc":[{"id":"1.231613187","rc":[{"batb":[[0,4.1,12.59],[1,1.59,171.61],[2,1.58,171.53]],"ltp":4.3,"tv":6.22,"id":12474498}]}]}
{"op":"mcm","clk":"11827413527","pt":1723356202982,"mc":[{"id":"1.231613187","rc":[{"batb":[[0,4.2,4],[1,4.1,12.59],[2,1.59,171.61]],"ltp":4.3,"tv":6.22,"id":12474498}]}]}
{"op":"mcm","clk":"11827413610","pt":1723356205395,"mc":[{"id":"1.231613187","rc":[{"batb":[[0,4.1,12.59],[1,1.59,171.61],[2,1.58,171.53]],"ltp":4.3,"tv":6.22,"id":12474498}]}]}
{"op":"mcm","clk":"11827413728","pt":1723356207603,"mc":[{"id":"1.231613187","rc":[{"batb":[[0,4.2,4],[1,4.1,12.59],[2,1.59,171.61]],"ltp":4.3,"tv":6.22,"id":12474498}]}]}
{"op":"mcm","clk":"11827413830","pt":1723356209979,"mc":[{"id":"1.231613187","rc":[{"batb":[[0,4.1,12.59],[1,1.59,171.61],[2,1.58,171.53]],"ltp":4.3,"tv":6.22,"id":12474498}]}]}
{"op":"mcm","clk":"11827414047","pt":1723356214099,"mc":[{"id":"1.231613187","rc":[{"batb":[[0,4.2,4],[1,4.1,12.59],[2,1.59,171.61]],"ltp":4.3,"tv":6.22,"id":12474498}]}]}
{"op":"mcm","clk":"11827414144","pt":1723356216363,"mc":[{"id":"1.231613187","rc":[{"batb":[[0,4.1,12.59],[1,1.59,171.61],[2,1.58,171.53]],"ltp":4.3,"tv":6.22,"id":12474498}]}]}
{"op":"mcm","clk":"11827414227","pt":1723356218472,"mc":[{"id":"1.231613187","rc":[{"batb":[[0,4.2,4],[1,4.1,12.59],[2,1.59,171.61]],"ltp":4.3,"tv":6.22,"id":12474498}]}]}
{"op":"mcm","clk":"11827414305","pt":1723356220784,"mc":[{"id":"1.231613187","rc":[{"batb":[[0,4.1,12.59],[1,1.59,171.61],[2,1.58,171.53]],"ltp":4.3,"tv":6.22,"id":12474498}]}]}
{"op":"mcm","clk":"11827414384","pt":1723356222892,"mc":[{"id":"1.231613187","rc":[{"batb":[[0,4.2,4],[1,4.1,12.59],[2,1.59,171.61]],"ltp":4.3,"tv":6.22,"id":12474498}]}]}
{"op":"mcm","clk":"11827414481","pt":1723356225313,"mc":[{"id":"1.231613187","rc":[{"batb":[[0,4.1,12.59],[1,1.59,171.61],[2,1.58,171.53]],"ltp":4.3,"tv":6.22,"id":12474498}]}]}
{"op":"mcm","clk":"11827414600","pt":1723356228396,"mc":[{"id":"1.231613187","rc":[{"batb":[[0,4.2,4],[1,4.1,12.59],[2,1.59,171.61]],"ltp":4.3,"tv":6.22,"id":12474498}]}]}
{"op":"mcm","clk":"11827414707","pt":1723356230815,"mc":[{"id":"1.231613187","rc":[{"batb":[[0,4.1,12.59],[1,1.59,171.61],[2,1.58,171.53]],"ltp":4.3,"tv":6.22,"id":12474498}]}]}
{"op":"mcm","clk":"11827414807","pt":1723356233334,"mc":[{"id":"1.231613187","rc":[{"batb":[[0,4.2,4],[1,4.1,12.59],[2,1.59,171.61]],"ltp":4.3,"tv":6.22,"id":12474498}]}]}
{"op":"mcm","clk":"11827414907","pt":1723356235546,"mc":[{"id":"1.231613187","rc":[{"batb":[[0,4.1,12.59],[1,1.59,171.61],[2,1.58,171.53]],"ltp":4.3,"tv":6.22,"id":12474498}]}]}
{"op":"mcm","clk":"11827415013","pt":1723356237915,"mc":[{"id":"1.231613187","rc":[{"batb":[[0,4.2,4],[1,4.1,12.59],[2,1.59,171.61]],"ltp":4.3,"tv":6.22,"id":12474498}]}]}
{"op":"mcm","clk":"11827415126","pt":1723356240233,"mc":[{"id":"1.231613187","rc":[{"batb":[[0,4.1,12.59],[1,1.59,171.61],[2,1.58,171.53]],"ltp":4.3,"tv":6.22,"id":12474498}]}]}
{"op":"mcm","clk":"11827415257","pt":1723356242750,"mc":[{"id":"1.231613187","rc":[{"batb":[[0,4.2,4],[1,4.1,12.59],[2,1.59,171.61]],"ltp":4.3,"tv":6.22,"id":12474498}]}]}
{"op":"mcm","clk":"11827415336","pt":1723356245059,"mc":[{"id":"1.231613187","rc":[{"batb":[[0,4.1,12.59],[1,1.59,171.61],[2,1.58,171.53]],"ltp":4.3,"tv":6.22,"id":12474498}]}]}
{"op":"mcm","clk":"11827415439","pt":1723356247319,"mc":[{"id":"1.231613187","rc":[{"batb":[[0,4.2,4],[1,4.1,12.59],[2,1.59,171.61]],"ltp":4.3,"tv":6.22,"id":12474498}]}]}
{"op":"mcm","clk":"11827415542","pt":1723356249737,"mc":[{"id":"1.231613187","rc":[{"batb":[[0,4.1,12.59],[1,1.59,171.61],[2,1.58,171.53]],"ltp":4.3,"tv":6.22,"id":12474498}]}]}
{"op":"mcm","clk":"11827415646","pt":1723356252032,"mc":[{"id":"1.231613187","rc":[{"batb":[[0,4.2,4],[1,4.1,12.59],[2,1.59,171.61]],"ltp":4.3,"tv":6.22,"id":12474498}]}]}
{"op":"mcm","clk":"11827415762","pt":1723356254387,"mc":[{"id":"1.231613187","rc":[{"batb":[[0,4.1,12.59],[1,1.59,171.61],[2,1.58,171.53]],"ltp":4.3,"tv":6.22,"id":12474498}]}]}
{"op":"mcm","clk":"11827415875","pt":1723356257156,"mc":[{"id":"1.231613187","rc":[{"batb":[[0,4.2,4],[1,4.1,12.59],[2,1.59,171.61]],"ltp":4.3,"tv":6.22,"id":12474498}]}]}
{"op":"mcm","clk":"11827415973","pt":1723356259671,"mc":[{"id":"1.231613187","rc":[{"batb":[[0,4.1,12.59],[1,1.59,171.61],[2,1.58,171.53]],"ltp":4.3,"tv":6.22,"id":12474498}]}]}
{"op":"mcm","clk":"11827416064","pt":1723356261875,"mc":[{"id":"1.231613187","rc":[{"batb":[[0,4.2,4],[1,4.1,12.59],[2,1.59,171.61]],"ltp":4.3,"tv":6.22,"id":12474498}]}]}
{"op":"mcm","clk":"11827416185","pt":1723356264080,"mc":[{"id":"1.231613187","rc":[{"batb":[[0,4.1,12.59],[1,1.59,171.61],[2,1.58,171.53]],"ltp":4.3,"tv":6.22,"id":12474498}]}]}
{"op":"mcm","clk":"11827416296","pt":1723356266375,"mc":[{"id":"1.231613187","rc":[{"batb":[[0,4.2,4],[1,4.1,12.59],[2,1.59,171.61]],"ltp":4.3,"tv":6.22,"id":12474498}]}]}
{"op":"mcm","clk":"11827416421","pt":1723356268780,"mc":[{"id":"1.231613187","rc":[{"batb":[[0,4.1,12.59],[1,1.59,171.61],[2,1.58,171.53]],"ltp":4.3,"tv":6.22,"id":12474498}]}]}
{"op":"mcm","clk":"11827416511","pt":1723356270986,"mc":[{"id":"1.231613187","rc":[{"batb":[[0,4.2,4],[1,4.1,12.59],[2,1.59,171.61]],"ltp":4.3,"tv":6.22,"id":12474498}]}]}
{"op":"mcm","clk":"11827416636","pt":1723356273354,"mc":[{"id":"1.231613187","rc":[{"batb":[[0,4.1,12.59],[1,1.59,171.61],[2,1.58,171.53]],"ltp":4.3,"tv":6.22,"id":12474498}]}]}
{"op":"mcm","clk":"11827416753","pt":1723356275980,"mc":[{"id":"1.231613187","rc":[{"batb":[[0,4.2,4],[1,4.1,12.59],[2,1.59,171.61]],"ltp":4.3,"tv":6.22,"id":12474498}]}]}
{"op":"mcm","clk":"11827416865","pt":1723356278167,"mc":[{"id":"1.231613187","rc":[{"batb":[[0,4.1,12.59],[1,1.59,171.61],[2,1.58,171.53]],"ltp":4.3,"tv":6.22,"id":12474498}]}]}
{"op":"mcm","clk":"11827416997","pt":1723356281604,"mc":[{"id":"1.231613187","rc":[{"batb":[[0,4.2,4],[1,4.1,12.59],[2,1.59,171.61]],"ltp":4.3,"tv":6.22,"id":12474498}]}]}
{"op":"mcm","clk":"11827417126","pt":1723356284183,"mc":[{"id":"1.231613187","rc":[{"batb":[[0,4.1,12.59],[1,1.59,171.61],[2,1.58,171.53]],"ltp":4.3,"tv":6.22,"id":12474498}]}]}
{"op":"mcm","clk":"11827417252","pt":1723356286398,"mc":[{"id":"1.231613187","rc":[{"batb":[[0,4.2,4],[1,4.1,12.59],[2,1.59,171.61]],"ltp":4.3,"tv":6.22,"id":12474498}]}]}
{"op":"mcm","clk":"11827417410","pt":1723356288821,"mc":[{"id":"1.231613187","rc":[{"batb":[[0,4.1,12.59],[1,1.59,171.61],[2,1.58,171.53]],"ltp":4.3,"tv":6.22,"id":12474498}]}]}
{"op":"mcm","clk":"11827417549","pt":1723356291190,"mc":[{"id":"1.231613187","rc":[{"batb":[[0,4.2,4],[1,4.1,12.59],[2,1.59,171.61]],"ltp":4.3,"tv":6.22,"id":12474498}]}]}
{"op":"mcm","clk":"11827417708","pt":1723356293566,"mc":[{"id":"1.231613187","rc":[{"batb":[[0,4.1,12.59],[1,1.59,171.61],[2,1.58,171.53]],"ltp":4.3,"tv":6.22,"id":12474498}]}]}
{"op":"mcm","clk":"11827417806","pt":1723356295780,"mc":[{"id":"1.231613187","rc":[{"batb":[[0,4.2,4],[1,4.1,12.59],[2,1.59,171.61]],"ltp":4.3,"tv":6.22,"id":12474498}]}]}
{"op":"mcm","clk":"11827417921","pt":1723356298153,"mc":[{"id":"1.231613187","rc":[{"batb":[[0,4.1,12.59],[1,1.59,171.61],[2,1.58,171.53]],"ltp":4.3,"tv":6.22,"id":12474498}]}]}
{"op":"mcm","clk":"11827418079","pt":1723356301262,"mc":[{"id":"1.231613187","rc":[{"batb":[[0,4.2,4],[1,4.1,12.59],[2,1.59,171.61]],"ltp":4.3,"tv":6.22,"id":12474498}]}]}
{"op":"mcm","clk":"11827418263","pt":1723356303600,"mc":[{"id":"1.231613187","rc":[{"batb":[[0,4.1,12.59],[1,1.59,171.61],[2,1.58,171.53]],"ltp":4.3,"tv":6.22,"id":12474498}]}]}
{"op":"mcm","clk":"11827418430","pt":1723356306693,"mc":[{"id":"1.231613187","rc":[{"batb":[[0,4.2,4],[1,4.1,12.59],[2,1.59,171.61]],"ltp":4.3,"tv":6.22,"id":12474498}]}]}
{"op":"mcm","clk":"11827418578","pt":1723356308862,"mc":[{"id":"1.231613187","rc":[{"batb":[[0,4.1,12.59],[1,1.59,171.61],[2,1.58,171.53]],"ltp":4.3,"tv":6.22,"id":12474498}]}]}
{"op":"mcm","clk":"11827418710","pt":1723356311276,"mc":[{"id":"1.231613187","rc":[{"batb":[[0,4.2,4],[1,4.1,12.59],[2,1.59,171.61]],"ltp":4.3,"tv":6.22,"id":12474498}]}]}
{"op":"mcm","clk":"11827418861","pt":1723356313603,"mc":[{"id":"1.231613187","rc":[{"batb":[[0,4.1,12.59],[1,1.59,171.61],[2,1.58,171.53]],"ltp":4.3,"tv":6.22,"id":12474498}]}]}
{"op":"mcm","clk":"11827419008","pt":1723356315770,"mc":[{"id":"1.231613187","rc":[{"batb":[[0,4.2,4],[1,4.1,12.59],[2,1.59,171.61]],"ltp":4.3,"tv":6.22,"id":12474498}]}]}
{"op":"mcm","clk":"11827419152","pt":1723356318089,"mc":[{"id":"1.231613187","rc":[{"batb":[[0,4.1,12.59],[1,1.59,171.61],[2,1.58,171.53]],"ltp":4.3,"tv":6.22,"id":12474498}]}]}
{"op":"mcm","clk":"11827419347","pt":1723356321480,"mc":[{"id":"1.231613187","rc":[{"batb":[[0,4.2,4],[1,4.1,12.59],[2,1.59,171.61]],"ltp":4.3,"tv":6.22,"id":12474498}]}]}
{"op":"mcm","clk":"11827419507","pt":1723356324000,"mc":[{"id":"1.231613187","rc":[{"batb":[[0,4.1,12.59],[1,1.59,171.61],[2,1.58,171.53]],"ltp":4.3,"tv":6.22,"id":12474498}]}]}
{"op":"mcm","clk":"11827419600","pt":1723356326303,"mc":[{"id":"1.231613187","rc":[{"batb":[[0,4.2,4],[1,4.1,12.59],[2,1.59,171.61]],"ltp":4.3,"tv":6.22,"id":12474498}]}]}
{"op":"mcm","clk":"11827419699","pt":1723356328615,"mc":[{"id":"1.231613187","rc":[{"batb":[[0,4.1,12.59],[1,1.59,171.61],[2,1.58,171.53]],"ltp":4.3,"tv":6.22,"id":12474498}]}]}
{"op":"mcm","clk":"11827419783","pt":1723356330680,"mc":[{"id":"1.231613187","rc":[{"batb":[[0,4.2,4],[1,4.1,12.59],[2,1.59,171.61]],"ltp":4.3,"tv":6.22,"id":12474498}]}]}
{"op":"mcm","clk":"11827419901","pt":1723356333011,"mc":[{"id":"1.231613187","rc":[{"batb":[[0,4.1,12.59],[1,1.59,171.61],[2,1.58,171.53]],"ltp":4.3,"tv":6.22,"id":12474498}]}]}
{"op":"mcm","clk":"11827420039","pt":1723356336188,"mc":[{"id":"1.231613187","rc":[{"batb":[[0,4.2,4],[1,4.1,12.59],[2,1.59,171.61]],"ltp":4.3,"tv":6.22,"id":12474498}]}]}
{"op":"mcm","clk":"11827420137","pt":1723356338403,"mc":[{"id":"1.231613187","rc":[{"batb":[[0,4.1,12.59],[1,1.59,171.61],[2,1.58,171.53]],"ltp":4.3,"tv":6.22,"id":12474498}]}]}
{"op":"mcm","clk":"11827420256","pt":1723356341423,"mc":[{"id":"1.231613187","rc":[{"batb":[[0,4.2,4],[1,4.1,12.59],[2,1.59,171.61]],"ltp":4.3,"tv":6.22,"id":12474498}]}]}
{"op":"mcm","clk":"11827420380","pt":1723356343628,"mc":[{"id":"1.231613187","rc":[{"batb":[[0,4.1,12.59],[1,1.59,171.61],[2,1.58,171.53]],"ltp":4.3,"tv":6.22,"id":12474498}]}]}
{"op":"mcm","clk":"11827420490","pt":1723356345932,"mc":[{"id":"1.231613187","rc":[{"batb":[[0,4.2,4],[1,4.1,12.59],[2,1.59,171.61]],"ltp":4.3,"tv":6.22,"id":12474498}]}]}
{"op":"mcm","clk":"11827420611","pt":1723356348216,"mc":[{"id":"1.231613187","rc":[{"batb":[[0,4.1,12.59],[1,1.59,171.61],[2,1.58,171.53]],"ltp":4.3,"tv":6.22,"id":12474498}]}]}
{"op":"mcm","clk":"11827420788","pt":1723356353431,"mc":[{"id":"1.231613187","rc":[{"batb":[[0,4.2,4],[1,4.1,12.59],[2,1.59,171.61]],"ltp":4.3,"tv":6.22,"id":12474498}]}]}
{"op":"mcm","clk":"11827420861","pt":1723356355837,"mc":[{"id":"1.231613187","rc":[{"batb":[[0,4.1,12.59],[1,1.59,171.61],[2,1.58,171.53]],"ltp":4.3,"tv":6.22,"id":12474498}]}]}
{"op":"mcm","clk":"11827420991","pt":1723356359344,"mc":[{"id":"1.231613187","rc":[{"batb":[[0,4.2,4],[1,4.1,12.59],[2,1.59,171.61]],"ltp":4.3,"tv":6.22,"id":12474498}]}]}
{"op":"mcm","clk":"11827421079","pt":1723356361657,"mc":[{"id":"1.231613187","rc":[{"batb":[[0,4.1,12.59],[1,1.59,171.61],[2,1.58,171.53]],"ltp":4.3,"tv":6.22,"id":12474498}]}]}
{"op":"mcm","clk":"11827421193","pt":1723356364331,"mc":[{"id":"1.231613187","rc":[{"batb":[[0,4.2,4],[1,4.1,12.59],[2,1.59,171.61]],"ltp":4.3,"tv":6.22,"id":12474498}]}]}
{"op":"mcm","clk":"11827421275","pt":1723356366640,"mc":[{"id":"1.231613187","rc":[{"batb":[[0,4.1,12.59],[1,1.59,171.61],[2,1.58,171.53]],"ltp":4.3,"tv":6.22,"id":12474498}]}]}
{"op":"mcm","clk":"11827421404","pt":1723356370070,"mc":[{"id":"1.231613187","rc":[{"batb":[[0,4.2,4],[1,4.1,12.59],[2,1.59,171.61]],"ltp":4.3,"tv":6.22,"id":12474498}]}]}
{"op":"mcm","clk":"11827421530","pt":1723356372439,"mc":[{"id":"1.231613187","rc":[{"batb":[[0,4.1,12.59],[1,1.59,171.61],[2,1.58,171.53]],"ltp":4.3,"tv":6.22,"id":12474498}]}]}
{"op":"mcm","clk":"11827421654","pt":1723356374863,"mc":[{"id":"1.231613187","rc":[{"batb":[[0,4.2,4],[1,4.1,12.59],[2,1.59,171.61]],"ltp":4.3,"tv":6.22,"id":12474498}]}]}
{"op":"mcm","clk":"11827421760","pt":1723356377273,"mc":[{"id":"1.231613187","rc":[{"batb":[[0,4.1,12.59],[1,1.59,171.61],[2,1.58,171.53]],"ltp":4.3,"tv":6.22,"id":12474498}]}]}
{"op":"mcm","clk":"11827421865","pt":1723356379586,"mc":[{"id":"1.231613187","rc":[{"batb":[[0,4.2,4],[1,4.1,12.59],[2,1.59,171.61]],"ltp":4.3,"tv":6.22,"id":12474498}]}]}
{"op":"mcm","clk":"11827421953","pt":1723356381844,"mc":[{"id":"1.231613187","rc":[{"batb":[[0,4.1,12.59],[1,1.59,171.61],[2,1.58,171.53]],"ltp":4.3,"tv":6.22,"id":12474498}]}]}
{"op":"mcm","clk":"11827422052","pt":1723356384148,"mc":[{"id":"1.231613187","rc":[{"batb":[[0,4.2,4],[1,4.1,12.59],[2,1.59,171.61]],"ltp":4.3,"tv":6.22,"id":12474498}]}]}
{"op":"mcm","clk":"11827422175","pt":1723356386457,"mc":[{"id":"1.231613187","rc":[{"batb":[[0,4.1,12.59],[1,1.59,171.61],[2,1.58,171.53]],"ltp":4.3,"tv":6.22,"id":12474498}]}]}
{"op":"mcm","clk":"11827422268","pt":1723356388756,"mc":[{"id":"1.231613187","rc":[{"batb":[[0,4.2,4],[1,4.1,12.59],[2,1.59,171.61]],"ltp":4.3,"tv":6.22,"id":12474498}]}]}
{"op":"mcm","clk":"11827422380","pt":1723356391068,"mc":[{"id":"1.231613187","rc":[{"batb":[[0,4.1,12.59],[1,1.59,171.61],[2,1.58,171.53]],"ltp":4.3,"tv":6.22,"id":12474498}]}]}
{"op":"mcm","clk":"11827422479","pt":1723356393370,"mc":[{"id":"1.231613187","rc":[{"batb":[[0,4.2,4],[1,4.1,12.59],[2,1.59,171.61]],"ltp":4.3,"tv":6.22,"id":12474498}]}]}
{"op":"mcm","clk":"11827422555","pt":1723356395672,"mc":[{"id":"1.231613187","rc":[{"batb":[[0,4.1,12.59],[1,1.59,171.61],[2,1.58,171.53]],"ltp":4.3,"tv":6.22,"id":12474498}]}]}
{"op":"mcm","clk":"11827422642","pt":1723356397883,"mc":[{"id":"1.231613187","rc":[{"batb":[[0,4.2,4],[1,4.1,12.59],[2,1.59,171.61]],"ltp":4.3,"tv":6.22,"id":12474498}]}]}
{"op":"mcm","clk":"11827422727","pt":1723356400185,"mc":[{"id":"1.231613187","rc":[{"batb":[[0,4.1,12.59],[1,1.59,171.61],[2,1.58,171.53]],"ltp":4.3,"tv":6.22,"id":12474498}]}]}
{"op":"mcm","clk":"11827422813","pt":1723356402490,"mc":[{"id":"1.231613187","rc":[{"batb":[[0,4.2,4],[1,4.1,12.59],[2,1.59,171.61]],"ltp":4.3,"tv":6.22,"id":12474498}]}]}
{"op":"mcm","clk":"11827422901","pt":1723356405001,"mc":[{"id":"1.231613187","rc":[{"batb":[[0,4.1,12.59],[1,1.59,171.61],[2,1.58,171.53]],"ltp":4.3,"tv":6.22,"id":12474498}]}]}
{"op":"mcm","clk":"11827423007","pt":1723356407203,"mc":[{"id":"1.231613187","rc":[{"batb":[[0,4.2,4],[1,4.1,12.59],[2,1.59,171.61]],"ltp":4.3,"tv":6.22,"id":12474498}]}]}
{"op":"mcm","clk":"11827423112","pt":1723356409575,"mc":[{"id":"1.231613187","rc":[{"batb":[[0,4.1,12.59],[1,1.59,171.61],[2,1.58,171.53]],"ltp":4.3,"tv":6.22,"id":12474498}]}]}
{"op":"mcm","clk":"11827423276","pt":1723356412711,"mc":[{"id":"1.231613187","rc":[{"batb":[[0,4.2,4],[1,4.1,12.59],[2,1.59,171.61]],"ltp":4.3,"tv":6.22,"id":12474498}]}]}
{"op":"mcm","clk":"11827423395","pt":1723356415018,"mc":[{"id":"1.231613187","rc":[{"batb":[[0,4.1,12.59],[1,1.59,171.61],[2,1.58,171.53]],"ltp":4.3,"tv":6.22,"id":12474498}]}]}
{"op":"mcm","clk":"11827423512","pt":1723356417385,"mc":[{"id":"1.231613187","rc":[{"batb":[[0,4.2,4],[1,4.1,12.59],[2,1.59,171.61]],"ltp":4.3,"tv":6.22,"id":12474498}]}]}
{"op":"mcm","clk":"11827423609","pt":1723356419842,"mc":[{"id":"1.231613187","rc":[{"batb":[[0,4.1,12.59],[1,1.59,171.61],[2,1.58,171.53]],"ltp":4.3,"tv":6.22,"id":12474498}]}]}
{"op":"mcm","clk":"11827423721","pt":1723356422223,"mc":[{"id":"1.231613187","rc":[{"batb":[[0,4.2,4],[1,4.1,12.59],[2,1.59,171.61]],"ltp":4.3,"tv":6.22,"id":12474498}]}]}
{"op":"mcm","clk":"11827423812","pt":1723356424546,"mc":[{"id":"1.231613187","rc":[{"batb":[[0,4.1,12.59],[1,1.59,171.61],[2,1.58,171.53]],"ltp":4.3,"tv":6.22,"id":12474498}]}]}
{"op":"mcm","clk":"11827423902","pt":1723356426703,"mc":[{"id":"1.231613187","rc":[{"batb":[[0,4.2,4],[1,4.1,12.59],[2,1.59,171.61]],"ltp":4.3,"tv":6.22,"id":12474498}]}]}
{"op":"mcm","clk":"11827423998","pt":1723356429118,"mc":[{"id":"1.231613187","rc":[{"batb":[[0,4.1,12.59],[1,1.59,171.61],[2,1.58,171.53]],"ltp":4.3,"tv":6.22,"id":12474498}]}]}
{"op":"mcm","clk":"11827424093","pt":1723356431431,"mc":[{"id":"1.231613187","rc":[{"batb":[[0,4.2,4],[1,4.1,12.59],[2,1.59,171.61]],"ltp":4.3,"tv":6.22,"id":12474498}]}]}
{"op":"mcm","clk":"11827424171","pt":1723356433733,"mc":[{"id":"1.231613187","rc":[{"batb":[[0,4.1,12.59],[1,1.59,171.61],[2,1.58,171.53]],"ltp":4.3,"tv":6.22,"id":12474498}]}]}
{"op":"mcm","clk":"11827424313","pt":1723356437171,"mc":[{"id":"1.231613187","rc":[{"batb":[[0,4.2,4],[1,4.1,12.59],[2,1.59,171.61]],"ltp":4.3,"tv":6.22,"id":12474498}]}]}
{"op":"mcm","clk":"11827424430","pt":1723356439335,"mc":[{"id":"1.231613187","rc":[{"batb":[[0,4.1,12.59],[1,1.59,171.61],[2,1.58,171.53]],"ltp":4.3,"tv":6.22,"id":12474498}]}]}
{"op":"mcm","clk":"11827424570","pt":1723356442826,"mc":[{"id":"1.231613187","rc":[{"batb":[[0,4.2,4],[1,4.1,12.59],[2,1.59,171.61]],"ltp":4.3,"tv":6.22,"id":12474498}]}]}
{"op":"mcm","clk":"11827424677","pt":1723356445028,"mc":[{"id":"1.231613187","rc":[{"batb":[[0,4.1,12.59],[1,1.59,171.61],[2,1.58,171.53]],"ltp":4.3,"tv":6.22,"id":12474498}]}]}
{"op":"mcm","clk":"11827424814","pt":1723356448566,"mc":[{"id":"1.231613187","rc":[{"batb":[[0,4.2,4],[1,4.1,12.59],[2,1.59,171.61]],"ltp":4.3,"tv":6.22,"id":12474498}]}]}
{"op":"mcm","clk":"11827424915","pt":1723356450978,"mc":[{"id":"1.231613187","rc":[{"batb":[[0,4.1,12.59],[1,1.59,171.61],[2,1.58,171.53]],"ltp":4.3,"tv":6.22,"id":12474498}]}]}
{"op":"mcm","clk":"11827425001","pt":1723356453036,"mc":[{"id":"1.231613187","rc":[{"batb":[[0,4.2,4],[1,4.1,12.59],[2,1.59,171.61]],"ltp":4.3,"tv":6.22,"id":12474498}]}]}
{"op":"mcm","clk":"11827425096","pt":1723356455948,"mc":[{"id":"1.231613187","rc":[{"batb":[[0,4.1,12.59],[1,1.59,171.61],[2,1.58,171.53]],"ltp":4.3,"tv":6.22,"id":12474498}]}]}
{"op":"mcm","clk":"11827425210","pt":1723356459764,"mc":[{"id":"1.231613187","rc":[{"batb":[[0,4.2,4],[1,4.1,12.59],[2,1.59,171.61]],"ltp":4.3,"tv":6.22,"id":12474498}]}]}
{"op":"mcm","clk":"11827425284","pt":1723356461969,"mc":[{"id":"1.231613187","rc":[{"batb":[[0,4.1,12.59],[1,1.59,171.61],[2,1.58,171.53]],"ltp":4.3,"tv":6.22,"id":12474498}]}]}
{"op":"mcm","clk":"11827425376","pt":1723356464483,"mc":[{"id":"1.231613187","rc":[{"batb":[[0,4.2,4],[1,4.1,12.59],[2,1.59,171.61]],"ltp":4.3,"tv":6.22,"id":12474498}]}]}
{"op":"mcm","clk":"11827425477","pt":1723356467205,"mc":[{"id":"1.231613187","rc":[{"batb":[[0,4.1,12.59],[1,1.59,171.61],[2,1.58,171.53]],"ltp":4.3,"tv":6.22,"id":12474498}]}]}
{"op":"mcm","clk":"11827425569","pt":1723356469816,"mc":[{"id":"1.231613187","rc":[{"batb":[[0,4.2,4],[1,4.1,12.59],[2,1.59,171.61]],"ltp":4.3,"tv":6.22,"id":12474498}]}]}
{"op":"mcm","clk":"11827425658","pt":1723356472182,"mc":[{"id":"1.231613187","rc":[{"batb":[[0,4.1,12.59],[1,1.59,171.61],[2,1.58,171.53]],"ltp":4.3,"tv":6.22,"id":12474498}]}]}
{"op":"mcm","clk":"11827425745","pt":1723356474510,"mc":[{"id":"1.231613187","rc":[{"batb":[[0,4.2,4],[1,4.1,12.59],[2,1.59,171.61]],"ltp":4.3,"tv":6.22,"id":12474498}]}]}
{"op":"mcm","clk":"11827425860","pt":1723356476879,"mc":[{"id":"1.231613187","rc":[{"batb":[[0,4.1,12.59],[1,1.59,171.61],[2,1.58,171.53]],"ltp":4.3,"tv":6.22,"id":12474498}]}]}
{"op":"mcm","clk":"11827425997","pt":1723356480265,"mc":[{"id":"1.231613187","rc":[{"batb":[[0,4.2,4],[1,4.1,12.59],[2,1.59,171.61]],"ltp":4.3,"tv":6.22,"id":12474498}]}]}
{"op":"mcm","clk":"11827426109","pt":1723356482805,"mc":[{"id":"1.231613187","rc":[{"batb":[[0,4.1,12.59],[1,1.59,171.61],[2,1.58,171.53]],"ltp":4.3,"tv":6.22,"id":12474498}]}]}
{"op":"mcm","clk":"11827426247","pt":1723356485889,"mc":[{"id":"1.231613187","rc":[{"batb":[[0,4.2,4],[1,4.1,12.59],[2,1.59,171.61]],"ltp":4.3,"tv":6.22,"id":12474498}]}]}
{"op":"mcm","clk":"11827426350","pt":1723356488513,"mc":[{"id":"1.231613187","rc":[{"batb":[[0,4.1,12.59],[1,1.59,171.61],[2,1.58,171.53]],"ltp":4.3,"tv":6.22,"id":12474498}]}]}
{"op":"mcm","clk":"11827426456","pt":1723356490742,"mc":[{"id":"1.231613187","rc":[{"batb":[[0,4.2,4],[1,4.1,12.59],[2,1.59,171.61]],"ltp":4.3,"tv":6.22,"id":12474498}]}]}
{"op":"mcm","clk":"11827426554","pt":1723356492937,"mc":[{"id":"1.231613187","rc":[{"batb":[[0,4.1,12.59],[1,1.59,171.61],[2,1.58,171.53]],"ltp":4.3,"tv":6.22,"id":12474498}]}]}
{"op":"mcm","clk":"11827426716","pt":1723356496323,"mc":[{"id":"1.231613187","rc":[{"batb":[[0,4.2,4],[1,4.1,12.59],[2,1.59,171.61]],"ltp":4.3,"tv":6.22,"id":12474498}]}]}
{"op":"mcm","clk":"11827426830","pt":1723356498639,"mc":[{"id":"1.231613187","rc":[{"batb":[[0,4.1,12.59],[1,1.59,171.61],[2,1.58,171.53]],"ltp":4.3,"tv":6.22,"id":12474498}]}]}
{"op":"mcm","clk":"11827426924","pt":1723356500828,"mc":[{"id":"1.231613187","rc":[{"batb":[[0,4.2,4],[1,4.1,12.59],[2,1.59,171.61]],"ltp":4.3,"tv":6.22,"id":12474498}]}]}
{"op":"mcm","clk":"11827427017","pt":1723356503031,"mc":[{"id":"1.231613187","rc":[{"batb":[[0,4.1,12.59],[1,1.59,171.61],[2,1.58,171.53]],"ltp":4.3,"tv":6.22,"id":12474498}]}]}
{"op":"mcm","clk":"11827427114","pt":1723356505137,"mc":[{"id":"1.231613187","rc":[{"batb":[[0,4.2,4],[1,4.1,12.59],[2,1.59,171.61]],"ltp":4.3,"tv":6.22,"id":12474498}]}]}
{"op":"mcm","clk":"11827427184","pt":1723356507443,"mc":[{"id":"1.231613187","rc":[{"batb":[[0,4.1,12.59],[1,1.59,171.61],[2,1.58,171.53]],"ltp":4.3,"tv":6.22,"id":12474498}]}]}
{"op":"mcm","clk":"11827427211","pt":1723356508321,"mc":[{"id":"1.231613187","rc":[{"batl":[[0,1.3,30.77]],"ltp":1.3,"tv":1192.27,"id":12482925}]}]}
{"op":"mcm","clk":"11827427281","pt":1723356510333,"mc":[{"id":"1.231613187","rc":[{"batb":[[0,4.2,4],[1,4.1,12.59],[2,1.59,171.61]],"ltp":4.3,"tv":6.22,"id":12474498}]}]}
{"op":"mcm","clk":"11827427365","pt":1723356512548,"mc":[{"id":"1.231613187","rc":[{"batb":[[0,4.1,12.59],[1,1.59,171.61],[2,1.58,171.53]],"ltp":4.3,"tv":6.22,"id":12474498}]}]}
{"op":"mcm","clk":"11827427490","pt":1723356515059,"mc":[{"id":"1.231613187","rc":[{"batb":[[0,4.2,4],[1,4.1,12.59],[2,1.59,171.61]],"ltp":4.3,"tv":6.22,"id":12474498}]}]}
{"op":"mcm","clk":"11827427599","pt":1723356517324,"mc":[{"id":"1.231613187","rc":[{"batb":[[0,4.1,12.59],[1,1.59,171.61],[2,1.58,171.53]],"ltp":4.3,"tv":6.22,"id":12474498}]}]}
{"op":"mcm","clk":"11827427729","pt":1723356520553,"mc":[{"id":"1.231613187","rc":[{"batb":[[0,4.2,4],[1,4.1,12.59],[2,1.59,171.61]],"batl":[[1,23,0.52]],"ltp":4.3,"tv":6.22,"id":12474498}]}]}
{"op":"mcm","clk":"11827427820","pt":1723356523063,"mc":[{"id":"1.231613187","rc":[{"batb":[[0,4.1,12.59],[1,1.59,171.61],[2,1.58,171.53]],"ltp":4.3,"tv":6.22,"id":12474498}]}]}
{"op":"mcm","clk":"11827427969","pt":1723356526343,"mc":[{"id":"1.231613187","rc":[{"batb":[[0,4.2,4],[1,4.1,12.59],[2,1.59,171.61]],"ltp":4.3,"tv":6.22,"id":12474498}]}]}
{"op":"mcm","clk":"11827428066","pt":1723356528752,"mc":[{"id":"1.231613187","rc":[{"batb":[[0,4.1,12.59],[1,1.59,171.61],[2,1.58,171.53]],"ltp":4.3,"tv":6.22,"id":12474498}]}]}
{"op":"mcm","clk":"11827428240","pt":1723356532669,"mc":[{"id":"1.231613187","rc":[{"batb":[[0,4.2,4],[1,4.1,12.59],[2,1.59,171.61]],"ltp":4.3,"tv":6.22,"id":12474498}]}]}
{"op":"mcm","clk":"11827428329","pt":1723356534955,"mc":[{"id":"1.231613187","rc":[{"batb":[[0,4.1,12.59],[1,1.59,171.61],[2,1.58,171.53]],"ltp":4.3,"tv":6.22,"id":12474498}]}]}
{"op":"mcm","clk":"11827428464","pt":1723356538687,"mc":[{"id":"1.231613187","rc":[{"batb":[[0,4.2,4],[1,4.1,12.59],[2,1.59,171.61]],"ltp":4.3,"tv":6.22,"id":12474498}]}]}
{"op":"mcm","clk":"11827428557","pt":1723356540886,"mc":[{"id":"1.231613187","rc":[{"batb":[[0,4.1,12.59],[1,1.59,171.61],[2,1.58,171.53]],"ltp":4.3,"tv":6.22,"id":12474498}]}]}
{"op":"mcm","clk":"11827428628","pt":1723356543055,"mc":[{"id":"1.231613187","rc":[{"batb":[[0,4.2,4],[1,4.1,12.59],[2,1.59,171.61]],"ltp":4.3,"tv":6.22,"id":12474498}]}]}
{"op":"mcm","clk":"11827428736","pt":1723356545484,"mc":[{"id":"1.231613187","rc":[{"batb":[[0,4.1,12.59],[1,1.59,171.61],[2,1.58,171.53]],"ltp":4.3,"tv":6.22,"id":12474498}]}]}
{"op":"mcm","clk":"11827428855","pt":1723356548000,"mc":[{"id":"1.231613187","rc":[{"batb":[[0,4.2,4],[1,4.1,12.59],[2,1.59,171.61]],"ltp":4.3,"tv":6.22,"id":12474498}]}]}
{"op":"mcm","clk":"11827428955","pt":1723356550405,"mc":[{"id":"1.231613187","rc":[{"batb":[[0,4.1,12.59],[1,1.59,171.61],[2,1.58,171.53]],"ltp":4.3,"tv":6.22,"id":12474498}]}]}
{"op":"mcm","clk":"11827429154","pt":1723356554967,"mc":[{"id":"1.231613187","rc":[{"batb":[[0,4.2,4],[1,4.1,12.59],[2,1.59,171.61]],"ltp":4.3,"tv":6.22,"id":12474498}]}]}
{"op":"mcm","clk":"11827429274","pt":1723356557904,"mc":[{"id":"1.231613187","rc":[{"batb":[[0,4.1,12.59],[1,1.59,171.61],[2,1.58,171.53]],"ltp":4.3,"tv":6.22,"id":12474498}]}]}
{"op":"mcm","clk":"11827429390","pt":1723356561282,"mc":[{"id":"1.231613187","rc":[{"batb":[[0,4.2,4],[1,4.1,12.59],[2,1.59,171.61]],"ltp":4.3,"tv":6.22,"id":12474498}]}]}
{"op":"mcm","clk":"11827429467","pt":1723356563892,"mc":[{"id":"1.231613187","rc":[{"batb":[[0,4.1,12.59],[1,1.59,171.61],[2,1.58,171.53]],"ltp":4.3,"tv":6.22,"id":12474498}]}]}
{"op":"mcm","clk":"11827429567","pt":1723356566708,"mc":[{"id":"1.231613187","rc":[{"batb":[[0,4.2,4],[1,4.1,12.59],[2,1.59,171.61]],"ltp":4.3,"tv":6.22,"id":12474498}]}]}
{"op":"mcm","clk":"11827429639","pt":1723356569009,"mc":[{"id":"1.231613187","rc":[{"batb":[[0,4.1,12.59],[1,1.59,171.61],[2,1.58,171.53]],"ltp":4.3,"tv":6.22,"id":12474498}]}]}
{"op":"mcm","clk":"11827429744","pt":1723356572388,"mc":[{"id":"1.231613187","rc":[{"batb":[[0,4.2,4],[1,4.1,12.59],[2,1.59,171.61]],"ltp":4.3,"tv":6.22,"id":12474498}]}]}
{"op":"mcm","clk":"11827429824","pt":1723356574792,"mc":[{"id":"1.231613187","rc":[{"batb":[[0,4.1,12.59],[1,1.59,171.61],[2,1.58,171.53]],"ltp":4.3,"tv":6.22,"id":12474498}]}]}
{"op":"mcm","clk":"11827429916","pt":1723356577100,"mc":[{"id":"1.231613187","rc":[{"batb":[[0,4.2,4],[1,4.1,12.59],[2,1.59,171.61]],"ltp":4.3,"tv":6.22,"id":12474498}]}]}
{"op":"mcm","clk":"11827429991","pt":1723356579524,"mc":[{"id":"1.231613187","rc":[{"batb":[[0,4.1,12.59],[1,1.59,171.61],[2,1.58,171.53]],"ltp":4.3,"tv":6.22,"id":12474498}]}]}
{"op":"mcm","clk":"11827430069","pt":1723356581733,"mc":[{"id":"1.231613187","rc":[{"batb":[[0,4.2,4],[1,4.1,12.59],[2,1.59,171.61]],"ltp":4.3,"tv":6.22,"id":12474498}]}]}
{"op":"mcm","clk":"11827430156","pt":1723356584046,"mc":[{"id":"1.231613187","rc":[{"batb":[[0,4.1,12.59],[1,1.59,171.61],[2,1.58,171.53]],"ltp":4.3,"tv":6.22,"id":12474498}]}]}
{"op":"mcm","clk":"11827430248","pt":1723356586605,"mc":[{"id":"1.231613187","rc":[{"batb":[[0,4.2,4],[1,4.1,12.59],[2,1.59,171.61]],"ltp":4.3,"tv":6.22,"id":12474498}]}]}
{"op":"mcm","clk":"11827430356","pt":1723356588913,"mc":[{"id":"1.231613187","rc":[{"batb":[[0,4.1,12.59],[1,1.59,171.61],[2,1.58,171.53]],"ltp":4.3,"tv":6.22,"id":12474498}]}]}
{"op":"mcm","clk":"11827430432","pt":1723356591316,"mc":[{"id":"1.231613187","rc":[{"batb":[[0,4.2,4],[1,4.1,12.59],[2,1.59,171.61]],"ltp":4.3,"tv":6.22,"id":12474498}]}]}
{"op":"mcm","clk":"11827430512","pt":1723356593717,"mc":[{"id":"1.231613187","rc":[{"batb":[[0,4.1,12.59],[1,1.59,171.61],[2,1.58,171.53]],"ltp":4.3,"tv":6.22,"id":12474498}]}]}
{"op":"mcm","clk":"11827430576","pt":1723356595928,"mc":[{"id":"1.231613187","rc":[{"batb":[[0,4.2,4],[1,4.1,12.59],[2,1.59,171.61]],"ltp":4.3,"tv":6.22,"id":12474498}]}]}
{"op":"mcm","clk":"11827430656","pt":1723356598338,"mc":[{"id":"1.231613187","rc":[{"batb":[[0,4.1,12.59],[1,1.59,171.61],[2,1.58,171.53]],"ltp":4.3,"tv":6.22,"id":12474498}]}]}
{"op":"mcm","clk":"11827430741","pt":1723356600751,"mc":[{"id":"1.231613187","rc":[{"batb":[[0,4.2,4],[1,4.1,12.59],[2,1.59,171.61]],"ltp":4.3,"tv":6.22,"id":12474498}]}]}
{"op":"mcm","clk":"11827430836","pt":1723356603269,"mc":[{"id":"1.231613187","rc":[{"batb":[[0,4.1,12.59],[1,1.59,171.61],[2,1.58,171.53]],"ltp":4.3,"tv":6.22,"id":12474498}]}]}
{"op":"mcm","clk":"11827430966","pt":1723356606350,"mc":[{"id":"1.231613187","rc":[{"batb":[[0,4.2,4],[1,4.1,12.59],[2,1.59,171.61]],"ltp":4.3,"tv":6.22,"id":12474498}]}]}
{"op":"mcm","clk":"11827431033","pt":1723356608557,"mc":[{"id":"1.231613187","rc":[{"batb":[[0,4.1,12.59],[1,1.59,171.61],[2,1.58,171.53]],"ltp":4.3,"tv":6.22,"id":12474498}]}]}
{"op":"mcm","clk":"11827431106","pt":1723356610958,"mc":[{"id":"1.231613187","rc":[{"batb":[[0,4.2,4],[1,4.1,12.59],[2,1.59,171.61]],"ltp":4.3,"tv":6.22,"id":12474498}]}]}
{"op":"mcm","clk":"11827431181","pt":1723356613268,"mc":[{"id":"1.231613187","rc":[{"batb":[[0,4.1,12.59],[1,1.59,171.61],[2,1.58,171.53]],"ltp":4.3,"tv":6.22,"id":12474498}]}]}
{"op":"mcm","clk":"11827431284","pt":1723356615467,"mc":[{"id":"1.231613187","rc":[{"batb":[[0,4.2,4],[1,4.1,12.59],[2,1.59,171.61]],"ltp":4.3,"tv":6.22,"id":12474498}]}]}
{"op":"mcm","clk":"11827431375","pt":1723356617673,"mc":[{"id":"1.231613187","rc":[{"batb":[[0,4.1,12.59],[1,1.59,171.61],[2,1.58,171.53]],"ltp":4.3,"tv":6.22,"id":12474498}]}]}
{"op":"mcm","clk":"11827431471","pt":1723356620185,"mc":[{"id":"1.231613187","rc":[{"batb":[[0,4.2,4],[1,4.1,12.59],[2,1.59,171.61]],"ltp":4.3,"tv":6.22,"id":12474498}]}]}
{"op":"mcm","clk":"11827431563","pt":1723356622487,"mc":[{"id":"1.231613187","rc":[{"batb":[[0,4.1,12.59],[1,1.59,171.61],[2,1.58,171.53]],"ltp":4.3,"tv":6.22,"id":12474498}]}]}
{"op":"mcm","clk":"11827431671","pt":1723356624797,"mc":[{"id":"1.231613187","rc":[{"batb":[[0,4.2,4],[1,4.1,12.59],[2,1.59,171.61]],"ltp":4.3,"tv":6.22,"id":12474498}]}]}
{"op":"mcm","clk":"11827431751","pt":1723356627204,"mc":[{"id":"1.231613187","rc":[{"batb":[[0,4.1,12.59],[1,1.59,171.61],[2,1.58,171.53]],"ltp":4.3,"tv":6.22,"id":12474498}]}]}
{"op":"mcm","clk":"11827431864","pt":1723356630279,"mc":[{"id":"1.231613187","rc":[{"batb":[[0,4.2,4],[1,4.1,12.59],[2,1.59,171.61]],"ltp":4.3,"tv":6.22,"id":12474498}]}]}
{"op":"mcm","clk":"11827431956","pt":1723356632689,"mc":[{"id":"1.231613187","rc":[{"batb":[[0,4.1,12.59],[1,1.59,171.61],[2,1.58,171.53]],"ltp":4.3,"tv":6.22,"id":12474498}]}]}
{"op":"mcm","clk":"11827432070","pt":1723356635768,"mc":[{"id":"1.231613187","rc":[{"batb":[[0,4.2,4],[1,4.1,12.59],[2,1.59,171.61]],"ltp":4.3,"tv":6.22,"id":12474498}]}]}
{"op":"mcm","clk":"11827432166","pt":1723356638278,"mc":[{"id":"1.231613187","rc":[{"batb":[[0,4.1,12.59],[1,1.59,171.61],[2,1.58,171.53]],"ltp":4.3,"tv":6.22,"id":12474498}]}]}
{"op":"mcm","clk":"11827432269","pt":1723356640379,"mc":[{"id":"1.231613187","rc":[{"batb":[[0,4.2,4],[1,4.1,12.59],[2,1.59,171.61]],"ltp":4.3,"tv":6.22,"id":12474498}]}]}
{"op":"mcm","clk":"11827432367","pt":1723356642680,"mc":[{"id":"1.231613187","rc":[{"batb":[[0,4.1,12.59],[1,1.59,171.61],[2,1.58,171.53]],"ltp":4.3,"tv":6.22,"id":12474498}]}]}
{"op":"mcm","clk":"11827432487","pt":1723356645292,"mc":[{"id":"1.231613187","rc":[{"batb":[[0,4.2,4],[1,4.1,12.59],[2,1.59,171.61]],"ltp":4.3,"tv":6.22,"id":12474498}]}]}
{"op":"mcm","clk":"11827432584","pt":1723356647596,"mc":[{"id":"1.231613187","rc":[{"batb":[[0,4.1,12.59],[1,1.59,171.61],[2,1.58,171.53]],"ltp":4.3,"tv":6.22,"id":12474498}]}]}
{"op":"mcm","clk":"11827432687","pt":1723356649716,"mc":[{"id":"1.231613187","rc":[{"batb":[[0,4.2,4],[1,4.1,12.59],[2,1.59,171.61]],"ltp":4.3,"tv":6.22,"id":12474498}]}]}
{"op":"mcm","clk":"11827432795","pt":1723356652187,"mc":[{"id":"1.231613187","rc":[{"batb":[[0,4.1,12.59],[1,1.59,171.61],[2,1.58,171.53]],"ltp":4.3,"tv":6.22,"id":12474498}]}]}
{"op":"mcm","clk":"11827432940","pt":1723356655314,"mc":[{"id":"1.231613187","rc":[{"batb":[[0,4.2,4],[1,4.1,12.59],[2,1.59,171.61]],"ltp":4.3,"tv":6.22,"id":12474498}]}]}
{"op":"mcm","clk":"11827433039","pt":1723356657822,"mc":[{"id":"1.231613187","rc":[{"batb":[[0,4.1,12.59],[1,1.59,171.61],[2,1.58,171.53]],"ltp":4.3,"tv":6.22,"id":12474498}]}]}
{"op":"mcm","clk":"11827433165","pt":1723356660806,"mc":[{"id":"1.231613187","rc":[{"batb":[[0,4.2,4],[1,4.1,12.59],[2,1.59,171.61]],"ltp":4.3,"tv":6.22,"id":12474498}]}]}
{"op":"mcm","clk":"11827433270","pt":1723356663234,"mc":[{"id":"1.231613187","rc":[{"batb":[[0,4.1,12.59],[1,1.59,171.61],[2,1.58,171.53]],"ltp":4.3,"tv":6.22,"id":12474498}]}]}
{"op":"mcm","clk":"11827433406","pt":1723356666315,"mc":[{"id":"1.231613187","rc":[{"batb":[[0,4.2,4],[1,4.1,12.59],[2,1.59,171.61]],"ltp":4.3,"tv":6.22,"id":12474498}]}]}
{"op":"mcm","clk":"11827433498","pt":1723356668521,"mc":[{"id":"1.231613187","rc":[{"batb":[[0,4.1,12.59],[1,1.59,171.61],[2,1.58,171.53]],"ltp":4.3,"tv":6.22,"id":12474498}]}]}
{"op":"mcm","clk":"11827433576","pt":1723356671038,"mc":[{"id":"1.231613187","rc":[{"batb":[[0,4.2,4],[1,4.1,12.59],[2,1.59,171.61]],"ltp":4.3,"tv":6.22,"id":12474498}]}]}
{"op":"mcm","clk":"11827433672","pt":1723356673445,"mc":[{"id":"1.231613187","rc":[{"batb":[[0,4.1,12.59],[1,1.59,171.61],[2,1.58,171.53]],"ltp":4.3,"tv":6.22,"id":12474498}]}]}
{"op":"mcm","clk":"11827433766","pt":1723356675655,"mc":[{"id":"1.231613187","rc":[{"batb":[[0,4.2,4],[1,4.1,12.59],[2,1.59,171.61]],"ltp":4.3,"tv":6.22,"id":12474498}]}]}
{"op":"mcm","clk":"11827433869","pt":1723356677921,"mc":[{"id":"1.231613187","rc":[{"batb":[[0,4.1,12.59],[1,1.59,171.61],[2,1.58,171.53]],"ltp":4.3,"tv":6.22,"id":12474498}]}]}
{"op":"mcm","clk":"11827433967","pt":1723356680228,"mc":[{"id":"1.231613187","rc":[{"batb":[[0,4.2,4],[1,4.1,12.59],[2,1.59,171.61]],"ltp":4.3,"tv":6.22,"id":12474498}]}]}
{"op":"mcm","clk":"11827434058","pt":1723356682553,"mc":[{"id":"1.231613187","rc":[{"batb":[[0,4.1,12.59],[1,1.59,171.61],[2,1.58,171.53]],"ltp":4.3,"tv":6.22,"id":12474498}]}]}
{"op":"mcm","clk":"11827434146","pt":1723356684961,"mc":[{"id":"1.231613187","rc":[{"batb":[[0,4.2,4],[1,4.1,12.59],[2,1.59,171.61]],"ltp":4.3,"tv":6.22,"id":12474498}]}]}
{"op":"mcm","clk":"11827434244","pt":1723356687267,"mc":[{"id":"1.231613187","rc":[{"batb":[[0,4.1,12.59],[1,1.59,171.61],[2,1.58,171.53]],"ltp":4.3,"tv":6.22,"id":12474498}]}]}
{"op":"mcm","clk":"11827434413","pt":1723356690572,"mc":[{"id":"1.231613187","rc":[{"batb":[[0,4.2,4],[1,4.1,12.59],[2,1.59,171.61]],"ltp":4.3,"tv":6.22,"id":12474498}]}]}
{"op":"mcm","clk":"11827434528","pt":1723356692872,"mc":[{"id":"1.231613187","rc":[{"batb":[[0,4.1,12.59],[1,1.59,171.61],[2,1.58,171.53]],"ltp":4.3,"tv":6.22,"id":12474498}]}]}
{"op":"mcm","clk":"11827434630","pt":1723356695646,"mc":[{"id":"1.231613187","rc":[{"batb":[[0,4.2,4],[1,4.1,12.59],[2,1.59,171.61]],"ltp":4.3,"tv":6.22,"id":12474498}]}]}
{"op":"mcm","clk":"11827434729","pt":1723356698160,"mc":[{"id":"1.231613187","rc":[{"batb":[[0,4.1,12.59],[1,1.59,171.61],[2,1.58,171.53]],"ltp":4.3,"tv":6.22,"id":12474498}]}]}
{"op":"mcm","clk":"11827434819","pt":1723356700363,"mc":[{"id":"1.231613187","rc":[{"batb":[[0,4.2,4],[1,4.1,12.59],[2,1.59,171.61]],"ltp":4.3,"tv":6.22,"id":12474498}]}]}
{"op":"mcm","clk":"11827434907","pt":1723356702570,"mc":[{"id":"1.231613187","rc":[{"batb":[[0,4.1,12.59],[1,1.59,171.61],[2,1.58,171.53]],"ltp":4.3,"tv":6.22,"id":12474498}]}]}
{"op":"mcm","clk":"11827434984","pt":1723356704975,"mc":[{"id":"1.231613187","rc":[{"batb":[[0,4.2,4],[1,4.1,12.59],[2,1.59,171.61]],"ltp":4.3,"tv":6.22,"id":12474498}]}]}
{"op":"mcm","clk":"11827435090","pt":1723356707182,"mc":[{"id":"1.231613187","rc":[{"batb":[[0,4.1,12.59],[1,1.59,171.61],[2,1.58,171.53]],"ltp":4.3,"tv":6.22,"id":12474498}]}]}
{"op":"mcm","clk":"11827435212","pt":1723356710304,"mc":[{"id":"1.231613187","rc":[{"batb":[[0,4.2,4],[1,4.1,12.59],[2,1.59,171.61]],"ltp":4.3,"tv":6.22,"id":12474498}]}]}
{"op":"mcm","clk":"11827435328","pt":1723356712730,"mc":[{"id":"1.231613187","rc":[{"batb":[[0,4.1,12.59],[1,1.59,171.61],[2,1.58,171.53]],"ltp":4.3,"tv":6.22,"id":12474498}]}]}
{"op":"mcm","clk":"11827435404","pt":1723356714992,"mc":[{"id":"1.231613187","rc":[{"batb":[[0,4.2,4],[1,4.1,12.59],[2,1.59,171.61]],"ltp":4.3,"tv":6.22,"id":12474498}]}]}
{"op":"mcm","clk":"11827435510","pt":1723356717312,"mc":[{"id":"1.231613187","rc":[{"batb":[[0,4.1,12.59],[1,1.59,171.61],[2,1.58,171.53]],"ltp":4.3,"tv":6.22,"id":12474498}]}]}
{"op":"mcm","clk":"11827435593","pt":1723356719787,"mc":[{"id":"1.231613187","rc":[{"batb":[[0,4.2,4],[1,4.1,12.59],[2,1.59,171.61]],"ltp":4.3,"tv":6.22,"id":12474498}]}]}
{"op":"mcm","clk":"11827435708","pt":1723356722321,"mc":[{"id":"1.231613187","rc":[{"batb":[[0,4.1,12.59],[1,1.59,171.61],[2,1.58,171.53]],"ltp":4.3,"tv":6.22,"id":12474498}]}]}
{"op":"mcm","clk":"11827435814","pt":1723356724686,"mc":[{"id":"1.231613187","rc":[{"batb":[[0,4.2,4],[1,4.1,12.59],[2,1.59,171.61]],"ltp":4.3,"tv":6.22,"id":12474498}]}]}
{"op":"mcm","clk":"11827435916","pt":1723356727102,"mc":[{"id":"1.231613187","rc":[{"batb":[[0,4.1,12.59],[1,1.59,171.61],[2,1.58,171.53]],"ltp":4.3,"tv":6.22,"id":12474498}]}]}
{"op":"mcm","clk":"11827435992","pt":1723356729409,"mc":[{"id":"1.231613187","rc":[{"batb":[[0,4.2,4],[1,4.1,12.59],[2,1.59,171.61]],"ltp":4.3,"tv":6.22,"id":12474498}]}]}
{"op":"mcm","clk":"11827436068","pt":1723356731824,"mc":[{"id":"1.231613187","rc":[{"batb":[[0,4.1,12.59],[1,1.59,171.61],[2,1.58,171.53]],"ltp":4.3,"tv":6.22,"id":12474498}]}]}
{"op":"mcm","clk":"11827436150","pt":1723356734502,"mc":[{"id":"1.231613187","rc":[{"batb":[[0,4.2,4],[1,4.1,12.59],[2,1.59,171.61]],"ltp":4.3,"tv":6.22,"id":12474498}]}]}
{"op":"mcm","clk":"11827436220","pt":1723356736700,"mc":[{"id":"1.231613187","rc":[{"batb":[[0,4.1,12.59],[1,1.59,171.61],[2,1.58,171.53]],"ltp":4.3,"tv":6.22,"id":12474498}]}]}
{"op":"mcm","clk":"11827436300","pt":1723356739112,"mc":[{"id":"1.231613187","rc":[{"batb":[[0,4.2,4],[1,4.1,12.59],[2,1.59,171.61]],"ltp":4.3,"tv":6.22,"id":12474498}]}]}
{"op":"mcm","clk":"11827436386","pt":1723356741428,"mc":[{"id":"1.231613187","rc":[{"batb":[[0,4.1,12.59],[1,1.59,171.61],[2,1.58,171.53]],"ltp":4.3,"tv":6.22,"id":12474498}]}]}
{"op":"mcm","clk":"11827436503","pt":1723356744004,"mc":[{"id":"1.231613187","rc":[{"batb":[[0,4.2,4],[1,4.1,12.59],[2,1.59,171.61]],"ltp":4.3,"tv":6.22,"id":12474498}]}]}
{"op":"mcm","clk":"11827436613","pt":1723356746226,"mc":[{"id":"1.231613187","rc":[{"batb":[[0,4.1,12.59],[1,1.59,171.61],[2,1.58,171.53]],"ltp":4.3,"tv":6.22,"id":12474498}]}]}
{"op":"mcm","clk":"11827436731","pt":1723356749055,"mc":[{"id":"1.231613187","rc":[{"batb":[[0,4.2,4],[1,4.1,12.59],[2,1.59,171.61]],"ltp":4.3,"tv":6.22,"id":12474498}]}]}
{"op":"mcm","clk":"11827436818","pt":1723356751312,"mc":[{"id":"1.231613187","rc":[{"batb":[[0,4.1,12.59],[1,1.59,171.61],[2,1.58,171.53]],"ltp":4.3,"tv":6.22,"id":12474498}]}]}
{"op":"mcm","clk":"11827436982","pt":1723356754667,"mc":[{"id":"1.231613187","rc":[{"batb":[[0,4.2,4],[1,4.1,12.59],[2,1.59,171.61]],"ltp":4.3,"tv":6.22,"id":12474498}]}]}
{"op":"mcm","clk":"11827437076","pt":1723356756933,"mc":[{"id":"1.231613187","rc":[{"batb":[[0,4.1,12.59],[1,1.59,171.61],[2,1.58,171.53]],"ltp":4.3,"tv":6.22,"id":12474498}]}]}
{"op":"mcm","clk":"11827437167","pt":1723356759352,"mc":[{"id":"1.231613187","rc":[{"batb":[[0,4.2,4],[1,4.1,12.59],[2,1.59,171.61]],"ltp":4.3,"tv":6.22,"id":12474498}]}]}
{"op":"mcm","clk":"11827437257","pt":1723356761863,"mc":[{"id":"1.231613187","rc":[{"batb":[[0,4.1,12.59],[1,1.59,171.61],[2,1.58,171.53]],"ltp":4.3,"tv":6.22,"id":12474498}]}]}
{"op":"mcm","clk":"11827437348","pt":1723356764526,"mc":[{"id":"1.231613187","rc":[{"batb":[[0,4.2,4],[1,4.1,12.59],[2,1.59,171.61]],"ltp":4.3,"tv":6.22,"id":12474498}]}]}
{"op":"mcm","clk":"11827437438","pt":1723356766728,"mc":[{"id":"1.231613187","rc":[{"batb":[[0,4.1,12.59],[1,1.59,171.61],[2,1.58,171.53]],"ltp":4.3,"tv":6.22,"id":12474498}]}]}
{"op":"mcm","clk":"11827437596","pt":1723356771147,"mc":[{"id":"1.231613187","rc":[{"batb":[[0,4.2,4],[1,4.1,12.59],[2,1.59,171.61]],"ltp":4.3,"tv":6.22,"id":12474498}]}]}
{"op":"mcm","clk":"11827437677","pt":1723356773556,"mc":[{"id":"1.231613187","rc":[{"batb":[[0,4.1,12.59],[1,1.59,171.61],[2,1.58,171.53]],"ltp":4.3,"tv":6.22,"id":12474498}]}]}
{"op":"mcm","clk":"11827448854","pt":1723356775655,"mc":[{"id":"1.231613187","rc":[{"batb":[[0,4.2,4],[1,4.1,12.59],[2,1.59,171.61]],"ltp":4.3,"tv":6.22,"id":12474498}]}]}
{"op":"mcm","clk":"11827448956","pt":1723356777961,"mc":[{"id":"1.231613187","rc":[{"batb":[[0,4.1,12.59],[1,1.59,171.61],[2,1.58,171.53]],"ltp":4.3,"tv":6.22,"id":12474498}]}]}
{"op":"mcm","clk":"11827449030","pt":1723356780058,"mc":[{"id":"1.231613187","rc":[{"batb":[[0,4.2,4],[1,4.1,12.59],[2,1.59,171.61]],"ltp":4.3,"tv":6.22,"id":12474498}]}]}
{"op":"mcm","clk":"11827449110","pt":1723356782240,"mc":[{"id":"1.231613187","rc":[{"batb":[[0,4.1,12.59],[1,1.59,171.61],[2,1.58,171.53]],"ltp":4.3,"tv":6.22,"id":12474498}]}]}
{"op":"mcm","clk":"11827449184","pt":1723356784862,"mc":[{"id":"1.231613187","rc":[{"batb":[[0,4.2,4],[1,4.1,12.59],[2,1.59,171.61]],"ltp":4.3,"tv":6.22,"id":12474498}]}]}
{"op":"mcm","clk":"11827449262","pt":1723356787175,"mc":[{"id":"1.231613187","rc":[{"batb":[[0,4.1,12.59],[1,1.59,171.61],[2,1.58,171.53]],"ltp":4.3,"tv":6.22,"id":12474498}]}]}
{"op":"mcm","clk":"11827449356","pt":1723356789794,"mc":[{"id":"1.231613187","rc":[{"batb":[[0,4.2,4],[1,4.1,12.59],[2,1.59,171.61]],"ltp":4.3,"tv":6.22,"id":12474498}]}]}
{"op":"mcm","clk":"11827449423","pt":1723356792153,"mc":[{"id":"1.231613187","rc":[{"batb":[[0,4.1,12.59],[1,1.59,171.61],[2,1.58,171.53]],"ltp":4.3,"tv":6.22,"id":12474498}]}]}
{"op":"mcm","clk":"11827449501","pt":1723356794765,"mc":[{"id":"1.231613187","rc":[{"batb":[[0,4.2,4],[1,4.1,12.59],[2,1.59,171.61]],"ltp":4.3,"tv":6.22,"id":12474498}]}]}
{"op":"mcm","clk":"11827449606","pt":1723356797181,"mc":[{"id":"1.231613187","rc":[{"batb":[[0,4.1,12.59],[1,1.59,171.61],[2,1.58,171.53]],"ltp":4.3,"tv":6.22,"id":12474498}]}]}
{"op":"mcm","clk":"11827449725","pt":1723356799698,"mc":[{"id":"1.231613187","rc":[{"batb":[[0,4.2,4],[1,4.1,12.59],[2,1.59,171.61]],"ltp":4.3,"tv":6.22,"id":12474498}]}]}
{"op":"mcm","clk":"11827449807","pt":1723356802001,"mc":[{"id":"1.231613187","rc":[{"batb":[[0,4.1,12.59],[1,1.59,171.61],[2,1.58,171.53]],"ltp":4.3,"tv":6.22,"id":12474498}]}]}
{"op":"mcm","clk":"11827449898","pt":1723356804870,"mc":[{"id":"1.231613187","rc":[{"batb":[[0,4.2,4],[1,4.1,12.59],[2,1.59,171.61]],"ltp":4.3,"tv":6.22,"id":12474498}]}]}
{"op":"mcm","clk":"11827449976","pt":1723356807175,"mc":[{"id":"1.231613187","rc":[{"batb":[[0,4.1,12.59],[1,1.59,171.61],[2,1.58,171.53]],"ltp":4.3,"tv":6.22,"id":12474498}]}]}
{"op":"mcm","clk":"11827450041","pt":1723356809372,"mc":[{"id":"1.231613187","rc":[{"batb":[[0,4.2,4],[1,4.1,12.59],[2,1.59,171.61]],"ltp":4.3,"tv":6.22,"id":12474498}]}]}
{"op":"mcm","clk":"11827450110","pt":1723356811680,"mc":[{"id":"1.231613187","rc":[{"batb":[[0,4.1,12.59],[1,1.59,171.61],[2,1.58,171.53]],"ltp":4.3,"tv":6.22,"id":12474498}]}]}
{"op":"mcm","clk":"11827450206","pt":1723356814098,"mc":[{"id":"1.231613187","rc":[{"batb":[[0,4.2,4],[1,4.1,12.59],[2,1.59,171.61]],"ltp":4.3,"tv":6.22,"id":12474498}]}]}
{"op":"mcm","clk":"11827450312","pt":1723356816523,"mc":[{"id":"1.231613187","rc":[{"batb":[[0,4.1,12.59],[1,1.59,171.61],[2,1.58,171.53]],"ltp":4.3,"tv":6.22,"id":12474498}]}]}
{"op":"mcm","clk":"11827450388","pt":1723356818690,"mc":[{"id":"1.231613187","rc":[{"batb":[[0,4.2,4],[1,4.1,12.59],[2,1.59,171.61]],"ltp":4.3,"tv":6.22,"id":12474498}]}]}
{"op":"mcm","clk":"11827450469","pt":1723356821092,"mc":[{"id":"1.231613187","rc":[{"batb":[[0,4.1,12.59],[1,1.59,171.61],[2,1.58,171.53]],"ltp":4.3,"tv":6.22,"id":12474498}]}]}
{"op":"mcm","clk":"11827450562","pt":1723356823300,"mc":[{"id":"1.231613187","rc":[{"batb":[[0,4.2,4],[1,4.1,12.59],[2,1.59,171.61]],"ltp":4.3,"tv":6.22,"id":12474498}]}]}
{"op":"mcm","clk":"11827450646","pt":1723356825810,"mc":[{"id":"1.231613187","rc":[{"batb":[[0,4.1,12.59],[1,1.59,171.61],[2,1.58,171.53]],"ltp":4.3,"tv":6.22,"id":12474498}]}]}
{"op":"mcm","clk":"11827450718","pt":1723356828010,"mc":[{"id":"1.231613187","rc":[{"batb":[[0,4.2,4],[1,4.1,12.59],[2,1.59,171.61]],"ltp":4.3,"tv":6.22,"id":12474498}]}]}
{"op":"mcm","clk":"11827450805","pt":1723356830316,"mc":[{"id":"1.231613187","rc":[{"batb":[[0,4.1,12.59],[1,1.59,171.61],[2,1.58,171.53]],"ltp":4.3,"tv":6.22,"id":12474498}]}]}
{"op":"mcm","clk":"11827450908","pt":1723356832832,"mc":[{"id":"1.231613187","rc":[{"batb":[[0,4.2,4],[1,4.1,12.59],[2,1.59,171.61]],"ltp":4.3,"tv":6.22,"id":12474498}]}]}
{"op":"mcm","clk":"11827450967","pt":1723356835136,"mc":[{"id":"1.231613187","rc":[{"batb":[[0,4.1,12.59],[1,1.59,171.61],[2,1.58,171.53]],"ltp":4.3,"tv":6.22,"id":12474498}]}]}
{"op":"mcm","clk":"11827451026","pt":1723356837336,"mc":[{"id":"1.231613187","rc":[{"batb":[[0,4.2,4],[1,4.1,12.59],[2,1.59,171.61]],"ltp":4.3,"tv":6.22,"id":12474498}]}]}
{"op":"mcm","clk":"11827451107","pt":1723356839744,"mc":[{"id":"1.231613187","rc":[{"batb":[[0,4.1,12.59],[1,1.59,171.61],[2,1.58,171.53]],"ltp":4.3,"tv":6.22,"id":12474498}]}]}
{"op":"mcm","clk":"11827451169","pt":1723356842050,"mc":[{"id":"1.231613187","rc":[{"batb":[[0,4.2,4],[1,4.1,12.59],[2,1.59,171.61]],"ltp":4.3,"tv":6.22,"id":12474498}]}]}
{"op":"mcm","clk":"11827451245","pt":1723356844326,"mc":[{"id":"1.231613187","rc":[{"batb":[[0,4.1,12.59],[1,1.59,171.61],[2,1.58,171.53]],"ltp":4.3,"tv":6.22,"id":12474498}]}]}
{"op":"mcm","clk":"11827451350","pt":1723356846734,"mc":[{"id":"1.231613187","rc":[{"batb":[[0,4.2,4],[1,4.1,12.59],[2,1.59,171.61]],"ltp":4.3,"tv":6.22,"id":12474498}]}]}
{"op":"mcm","clk":"11827451431","pt":1723356848328,"mc":[{"id":"1.231613187","rc":[{"trd":[[4.3,1.15]],"ltp":4.3,"tv":6.46,"id":12474498},{"trd":[[1.3,18.85]],"batl":[[0,1.3,29.97]],"ltp":1.3,"tv":1193.07,"id":12482925}],"tv":1199.54}]}
{"op":"mcm","clk":"11827451456","pt":1723356848948,"mc":[{"id":"1.231613187","rc":[{"batb":[[0,4.1,12.59],[1,1.59,171.61],[2,1.58,171.53]],"ltp":4.3,"tv":6.46,"id":12474498}]}]}
{"op":"mcm","clk":"11827451543","pt":1723356851145,"mc":[{"id":"1.231613187","rc":[{"batb":[[0,4.2,4],[1,4.1,12.59],[2,1.59,171.61]],"ltp":4.3,"tv":6.46,"id":12474498}]}]}
{"op":"mcm","clk":"11827451636","pt":1723356853556,"mc":[{"id":"1.231613187","rc":[{"batb":[[0,4.1,12.59],[1,1.59,171.61],[2,1.58,171.53]],"ltp":4.3,"tv":6.46,"id":12474498}]}]}
{"op":"mcm","clk":"11827451718","pt":1723356855860,"mc":[{"id":"1.231613187","rc":[{"batb":[[0,4.2,4],[1,4.1,12.59],[2,1.59,171.61]],"ltp":4.3,"tv":6.46,"id":12474498}]}]}
{"op":"mcm","clk":"11827451843","pt":1723356858164,"mc":[{"id":"1.231613187","rc":[{"batb":[[0,4.1,12.59],[1,1.59,171.61],[2,1.58,171.53]],"ltp":4.3,"tv":6.46,"id":12474498}]}]}
{"op":"mcm","clk":"11827451986","pt":1723356861141,"mc":[{"id":"1.231613187","rc":[{"batb":[[0,4.2,4],[1,4.1,12.59],[2,1.59,171.61]],"ltp":4.3,"tv":6.46,"id":12474498}]}]}
{"op":"mcm","clk":"11827452078","pt":1723356863349,"mc":[{"id":"1.231613187","rc":[{"batb":[[0,4.1,12.59],[1,1.59,171.61],[2,1.58,171.53]],"ltp":4.3,"tv":6.46,"id":12474498}]}]}
{"op":"mcm","clk":"11827452146","pt":1723356865871,"mc":[{"id":"1.231613187","rc":[{"batb":[[0,4.2,4],[1,4.1,12.59],[2,1.59,171.61]],"ltp":4.3,"tv":6.46,"id":12474498}]}]}
{"op":"mcm","clk":"11827452225","pt":1723356868147,"mc":[{"id":"1.231613187","rc":[{"batb":[[0,4.1,12.59],[1,1.59,171.61],[2,1.58,171.53]],"ltp":4.3,"tv":6.46,"id":12474498}]}]}
{"op":"mcm","clk":"11827452285","pt":1723356870238,"mc":[{"id":"1.231613187","rc":[{"batb":[[0,4.2,4],[1,4.1,12.59],[2,1.59,171.61]],"ltp":4.3,"tv":6.46,"id":12474498}]}]}
{"op":"mcm","clk":"11827452338","pt":1723356872438,"mc":[{"id":"1.231613187","rc":[{"batb":[[0,4.1,12.59],[1,1.59,171.61],[2,1.58,171.53]],"ltp":4.3,"tv":6.46,"id":12474498}]}]}
{"op":"mcm","clk":"11827452434","pt":1723356875361,"mc":[{"id":"1.231613187","rc":[{"batb":[[0,4.2,4],[1,4.1,12.59],[2,1.59,171.61]],"ltp":4.3,"tv":6.46,"id":12474498}]}]}
{"op":"mcm","clk":"11827452529","pt":1723356877775,"mc":[{"id":"1.231613187","rc":[{"batb":[[0,4.1,12.59],[1,1.59,171.61],[2,1.58,171.53]],"ltp":4.3,"tv":6.46,"id":12474498},{"batl":[[0,1.3,7.47]],"ltp":1.3,"tv":1193.07,"id":12482925}]}]}
{"op":"mcm","clk":"11827452534","pt":1723356877881,"mc":[{"id":"1.231613187","rc":[{"batb":[[0,1.29,14.5]],"ltp":1.3,"tv":1193.07,"id":12482925}]}]}
{"op":"mcm","clk":"11827452623","pt":1723356880749,"mc":[{"id":"1.231613187","rc":[{"batb":[[0,4.2,4],[1,4.1,12.59],[2,1.59,171.61]],"ltp":4.3,"tv":6.46,"id":12474498}]}]}
{"op":"mcm","clk":"11827452691","pt":1723356883155,"mc":[{"id":"1.231613187","rc":[{"batb":[[0,4.1,12.59],[1,1.59,171.61],[2,1.58,171.53]],"ltp":4.3,"tv":6.46,"id":12474498}]}]}
{"op":"mcm","clk":"11827452766","pt":1723356885359,"mc":[{"id":"1.231613187","rc":[{"batb":[[0,4.2,4],[1,4.1,12.59],[2,1.59,171.61]],"ltp":4.3,"tv":6.46,"id":12474498}]}]}
{"op":"mcm","clk":"11827452841","pt":1723356887665,"mc":[{"id":"1.231613187","rc":[{"batb":[[0,4.1,12.59],[1,1.59,171.61],[2,1.58,171.53]],"ltp":4.3,"tv":6.46,"id":12474498}]}]}
{"op":"mcm","clk":"11827452908","pt":1723356890076,"mc":[{"id":"1.231613187","rc":[{"batb":[[0,4.2,4],[1,4.1,12.59],[2,1.59,171.61]],"ltp":4.3,"tv":6.46,"id":12474498}]}]}
{"op":"mcm","clk":"11827453003","pt":1723356892284,"mc":[{"id":"1.231613187","rc":[{"batb":[[0,4.1,12.59],[1,1.59,171.61],[2,1.58,171.53]],"ltp":4.3,"tv":6.46,"id":12474498}]}]}
{"op":"mcm","clk":"11827453130","pt":1723356895155,"mc":[{"id":"1.231613187","rc":[{"batb":[[0,4.2,4],[1,4.1,12.59],[2,1.59,171.61]],"ltp":4.3,"tv":6.46,"id":12474498}]}]}
{"op":"mcm","clk":"11827453203","pt":1723356897532,"mc":[{"id":"1.231613187","rc":[{"batb":[[0,4.1,12.59],[1,1.59,171.61],[2,1.58,171.53]],"ltp":4.3,"tv":6.46,"id":12474498}]}]}
{"op":"mcm","clk":"11827453265","pt":1723356899998,"mc":[{"id":"1.231613187","rc":[{"batb":[[0,4.2,4],[1,4.1,12.59],[2,1.59,171.61]],"ltp":4.3,"tv":6.46,"id":12474498}]}]}
{"op":"mcm","clk":"11827453391","pt":1723356902505,"mc":[{"id":"1.231613187","rc":[{"batb":[[0,4.1,12.59],[1,1.59,171.61],[2,1.58,171.53]],"ltp":4.3,"tv":6.46,"id":12474498}]}]}
{"op":"mcm","clk":"11827453503","pt":1723356904676,"mc":[{"id":"1.231613187","rc":[{"batb":[[0,4.2,4],[1,4.1,12.59],[2,1.59,171.61]],"ltp":4.3,"tv":6.46,"id":12474498}]}]}
{"op":"mcm","clk":"11827453612","pt":1723356906997,"mc":[{"id":"1.231613187","rc":[{"batb":[[0,4.1,12.59],[1,1.59,171.61],[2,1.58,171.53]],"ltp":4.3,"tv":6.46,"id":12474498}]}]}
{"op":"mcm","clk":"11827453696","pt":1723356909417,"mc":[{"id":"1.231613187","rc":[{"batb":[[0,4.2,4],[1,4.1,12.59],[2,1.59,171.61]],"ltp":4.3,"tv":6.46,"id":12474498}]}]}
{"op":"mcm","clk":"11827453783","pt":1723356911803,"mc":[{"id":"1.231613187","rc":[{"batb":[[0,4.1,12.59],[1,1.59,171.61],[2,1.58,171.53]],"ltp":4.3,"tv":6.46,"id":12474498}]}]}
{"op":"mcm","clk":"11827453862","pt":1723356914220,"mc":[{"id":"1.231613187","rc":[{"batb":[[0,4.2,4],[1,4.1,12.59],[2,1.59,171.61]],"ltp":4.3,"tv":6.46,"id":12474498}]}]}
{"op":"mcm","clk":"11827453944","pt":1723356916603,"mc":[{"id":"1.231613187","rc":[{"batb":[[0,4.1,12.59],[1,1.59,171.61],[2,1.58,171.53]],"ltp":4.3,"tv":6.46,"id":12474498}]}]}
{"op":"mcm","clk":"11827454100","pt":1723356920019,"mc":[{"id":"1.231613187","rc":[{"batb":[[0,4.2,4],[1,4.1,12.59],[2,1.59,171.61]],"ltp":4.3,"tv":6.46,"id":12474498}]}]}
{"op":"mcm","clk":"11827454213","pt":1723356922599,"mc":[{"id":"1.231613187","rc":[{"batb":[[0,4.1,12.59],[1,1.59,171.61],[2,1.58,171.53]],"ltp":4.3,"tv":6.46,"id":12474498}]}]}
{"op":"mcm","clk":"11827454315","pt":1723356924925,"mc":[{"id":"1.231613187","rc":[{"batb":[[0,4.2,4],[1,4.1,12.59],[2,1.59,171.61]],"ltp":4.3,"tv":6.46,"id":12474498}]}]}
{"op":"mcm","clk":"11827454395","pt":1723356927192,"mc":[{"id":"1.231613187","rc":[{"batb":[[0,4.1,12.59],[1,1.59,171.61],[2,1.58,171.53]],"ltp":4.3,"tv":6.46,"id":12474498}]}]}
{"op":"mcm","clk":"11827454493","pt":1723356929522,"mc":[{"id":"1.231613187","rc":[{"batb":[[0,4.2,4],[1,4.1,12.59],[2,1.59,171.61]],"ltp":4.3,"tv":6.46,"id":12474498}]}]}
{"op":"mcm","clk":"11827454590","pt":1723356931839,"mc":[{"id":"1.231613187","rc":[{"batb":[[0,4.1,12.59],[1,1.59,171.61],[2,1.58,171.53]],"ltp":4.3,"tv":6.46,"id":12474498}]}]}
{"op":"mcm","clk":"11827454713","pt":1723356934919,"mc":[{"id":"1.231613187","rc":[{"batb":[[0,4.2,4],[1,4.1,12.59],[2,1.59,171.61]],"ltp":4.3,"tv":6.46,"id":12474498}]}]}
{"op":"mcm","clk":"11827454818","pt":1723356937330,"mc":[{"id":"1.231613187","rc":[{"batb":[[0,4.1,12.59],[1,1.59,171.61],[2,1.58,171.53]],"ltp":4.3,"tv":6.46,"id":12474498}]}]}
{"op":"mcm","clk":"11827454939","pt":1723356939811,"mc":[{"id":"1.231613187","rc":[{"batb":[[0,4.2,4],[1,4.1,12.59],[2,1.59,171.61]],"ltp":4.3,"tv":6.46,"id":12474498}]}]}
{"op":"mcm","clk":"11827455009","pt":1723356942123,"mc":[{"id":"1.231613187","rc":[{"batb":[[0,4.1,12.59],[1,1.59,171.61],[2,1.58,171.53]],"ltp":4.3,"tv":6.46,"id":12474498}]}]}
{"op":"mcm","clk":"11827455073","pt":1723356944331,"mc":[{"id":"1.231613187","rc":[{"batb":[[0,4.2,4],[1,4.1,12.59],[2,1.59,171.61]],"ltp":4.3,"tv":6.46,"id":12474498}]}]}
{"op":"mcm","clk":"11827455170","pt":1723356946646,"mc":[{"id":"1.231613187","rc":[{"batb":[[0,4.1,12.59],[1,1.59,171.61],[2,1.58,171.53]],"ltp":4.3,"tv":6.46,"id":12474498}]}]}
{"op":"mcm","clk":"11827455270","pt":1723356949727,"mc":[{"id":"1.231613187","rc":[{"batb":[[0,4.2,4],[1,4.1,12.59],[2,1.59,171.61]],"ltp":4.3,"tv":6.46,"id":12474498}]}]}
{"op":"mcm","clk":"11827455336","pt":1723356952153,"mc":[{"id":"1.231613187","rc":[{"batb":[[0,4.1,12.59],[1,1.59,171.61],[2,1.58,171.53]],"ltp":4.3,"tv":6.46,"id":12474498}]}]}
{"op":"mcm","clk":"11827455432","pt":1723356954562,"mc":[{"id":"1.231613187","rc":[{"batb":[[0,4.2,4],[1,4.1,12.59],[2,1.59,171.61]],"ltp":4.3,"tv":6.46,"id":12474498}]}]}
{"op":"mcm","clk":"11827455547","pt":1723356956973,"mc":[{"id":"1.231613187","rc":[{"batb":[[0,4.1,12.59],[1,1.59,171.61],[2,1.58,171.53]],"ltp":4.3,"tv":6.46,"id":12474498}]}]}
{"op":"mcm","clk":"11827455628","pt":1723356959183,"mc":[{"id":"1.231613187","rc":[{"batb":[[0,4.2,4],[1,4.1,12.59],[2,1.59,171.61]],"ltp":4.3,"tv":6.46,"id":12474498}]}]}
{"op":"mcm","clk":"11827455715","pt":1723356961461,"mc":[{"id":"1.231613187","rc":[{"batb":[[0,4.1,12.59],[1,1.59,171.61],[2,1.58,171.53]],"ltp":4.3,"tv":6.46,"id":12474498}]}]}
{"op":"mcm","clk":"11827455808","pt":1723356964110,"mc":[{"id":"1.231613187","rc":[{"batb":[[0,4.2,4],[1,4.1,12.59],[2,1.59,171.61]],"ltp":4.3,"tv":6.46,"id":12474498}]}]}
{"op":"mcm","clk":"11827455913","pt":1723356966396,"mc":[{"id":"1.231613187","rc":[{"batb":[[0,4.1,12.59],[1,1.59,171.61],[2,1.58,171.53]],"ltp":4.3,"tv":6.46,"id":12474498}]}]}
{"op":"mcm","clk":"11827456002","pt":1723356968699,"mc":[{"id":"1.231613187","rc":[{"batb":[[0,4.2,4],[1,4.1,12.59],[2,1.59,171.61]],"ltp":4.3,"tv":6.46,"id":12474498}]}]}
{"op":"mcm","clk":"11827456083","pt":1723356971059,"mc":[{"id":"1.231613187","rc":[{"batb":[[0,4.1,12.59],[1,1.59,171.61],[2,1.58,171.53]],"ltp":4.3,"tv":6.46,"id":12474498}]}]}
{"op":"mcm","clk":"11827456164","pt":1723356973465,"mc":[{"id":"1.231613187","rc":[{"batb":[[0,4.2,4],[1,4.1,12.59],[2,1.59,171.61]],"ltp":4.3,"tv":6.46,"id":12474498}]}]}
{"op":"mcm","clk":"11827456329","pt":1723356978389,"mc":[{"id":"1.231613187","rc":[{"batb":[[0,4.1,12.59],[1,1.59,171.61],[2,1.58,171.53]],"ltp":4.3,"tv":6.46,"id":12474498}]}]}
{"op":"mcm","clk":"11827456455","pt":1723356981765,"mc":[{"id":"1.231613187","rc":[{"batb":[[0,4.2,4],[1,4.1,12.59],[2,1.59,171.61]],"ltp":4.3,"tv":6.46,"id":12474498}]}]}
{"op":"mcm","clk":"11827456537","pt":1723356984079,"mc":[{"id":"1.231613187","rc":[{"batb":[[0,4.1,12.59],[1,1.59,171.61],[2,1.58,171.53]],"ltp":4.3,"tv":6.46,"id":12474498}]}]}
{"op":"mcm","clk":"11827456628","pt":1723356986481,"mc":[{"id":"1.231613187","rc":[{"batb":[[0,4.2,4],[1,4.1,12.59],[2,1.59,171.61]],"ltp":4.3,"tv":6.46,"id":12474498}]}]}
{"op":"mcm","clk":"11827456712","pt":1723356988887,"mc":[{"id":"1.231613187","rc":[{"batb":[[0,4.1,12.59],[1,1.59,171.61],[2,1.58,171.53]],"ltp":4.3,"tv":6.46,"id":12474498}]}]}
{"op":"mcm","clk":"11827456814","pt":1723356991195,"mc":[{"id":"1.231613187","rc":[{"batb":[[0,4.2,4],[1,4.1,12.59],[2,1.59,171.61]],"ltp":4.3,"tv":6.46,"id":12474498}]}]}
{"op":"mcm","clk":"11827456883","pt":1723356993499,"mc":[{"id":"1.231613187","rc":[{"batb":[[0,4.1,12.59],[1,1.59,171.61],[2,1.58,171.53]],"ltp":4.3,"tv":6.46,"id":12474498}]}]}
{"op":"mcm","clk":"11827456977","pt":1723356996113,"mc":[{"id":"1.231613187","rc":[{"batb":[[0,4.2,4],[1,4.1,12.59],[2,1.59,171.61]],"ltp":4.3,"tv":6.46,"id":12474498}]}]}
{"op":"mcm","clk":"11827457060","pt":1723356998519,"mc":[{"id":"1.231613187","rc":[{"batb":[[0,4.1,12.59],[1,1.59,171.61],[2,1.58,171.53]],"ltp":4.3,"tv":6.46,"id":12474498}]}]}
{"op":"mcm","clk":"11827457140","pt":1723357000831,"mc":[{"id":"1.231613187","rc":[{"batb":[[0,4.2,4],[1,4.1,12.59],[2,1.59,171.61]],"ltp":4.3,"tv":6.46,"id":12474498}]}]}
{"op":"mcm","clk":"11827457201","pt":1723357003128,"mc":[{"id":"1.231613187","rc":[{"batb":[[0,4.1,12.59],[1,1.59,171.61],[2,1.58,171.53]],"ltp":4.3,"tv":6.46,"id":12474498}]}]}
{"op":"mcm","clk":"11827457266","pt":1723357005425,"mc":[{"id":"1.231613187","rc":[{"batb":[[0,4.2,4],[1,4.1,12.59],[2,1.59,171.61]],"ltp":4.3,"tv":6.46,"id":12474498}]}]}
{"op":"mcm","clk":"11827457345","pt":1723357007839,"mc":[{"id":"1.231613187","rc":[{"batb":[[0,4.1,12.59],[1,1.59,171.61],[2,1.58,171.53]],"ltp":4.3,"tv":6.46,"id":12474498}]}]}
{"op":"mcm","clk":"11827457464","pt":1723357010205,"mc":[{"id":"1.231613187","rc":[{"batb":[[0,4.2,4],[1,4.1,12.59],[2,1.59,171.61]],"ltp":4.3,"tv":6.46,"id":12474498}]}]}
{"op":"mcm","clk":"11827457555","pt":1723357012813,"mc":[{"id":"1.231613187","rc":[{"batb":[[0,4.1,12.59],[1,1.59,171.61],[2,1.58,171.53]],"ltp":4.3,"tv":6.46,"id":12474498}]}]}
{"op":"mcm","clk":"11827457624","pt":1723357015011,"mc":[{"id":"1.231613187","rc":[{"batb":[[0,4.2,4],[1,4.1,12.59],[2,1.59,171.61]],"ltp":4.3,"tv":6.46,"id":12474498}]}]}
{"op":"mcm","clk":"11827457703","pt":1723357017314,"mc":[{"id":"1.231613187","rc":[{"batb":[[0,4.1,12.59],[1,1.59,171.61],[2,1.58,171.53]],"ltp":4.3,"tv":6.46,"id":12474498}]}]}
{"op":"mcm","clk":"11827457812","pt":1723357020132,"mc":[{"id":"1.231613187","rc":[{"batb":[[0,4.2,4],[1,4.1,12.59],[2,1.59,171.61]],"ltp":4.3,"tv":6.46,"id":12474498}]}]}
{"op":"mcm","clk":"11827457915","pt":1723357022500,"mc":[{"id":"1.231613187","rc":[{"batb":[[0,4.1,12.59],[1,1.59,171.61],[2,1.58,171.53]],"ltp":4.3,"tv":6.46,"id":12474498}]}]}
{"op":"mcm","clk":"11827458015","pt":1723357025021,"mc":[{"id":"1.231613187","rc":[{"batb":[[0,4.2,4],[1,4.1,12.59],[2,1.59,171.61]],"ltp":4.3,"tv":6.46,"id":12474498}]}]}
{"op":"mcm","clk":"11827458153","pt":1723357027539,"mc":[{"id":"1.231613187","rc":[{"batb":[[0,4.1,12.59],[1,1.59,171.61],[2,1.58,171.53]],"ltp":4.3,"tv":6.46,"id":12474498}]}]}
{"op":"mcm","clk":"11827458230","pt":1723357029942,"mc":[{"id":"1.231613187","rc":[{"batb":[[0,4.2,4],[1,4.1,12.59],[2,1.59,171.61]],"ltp":4.3,"tv":6.46,"id":12474498}]}]}
{"op":"mcm","clk":"11827458318","pt":1723357032259,"mc":[{"id":"1.231613187","rc":[{"batb":[[0,4.1,12.59],[1,1.59,171.61],[2,1.58,171.53]],"ltp":4.3,"tv":6.46,"id":12474498}]}]}
{"op":"mcm","clk":"11827458392","pt":1723357034763,"mc":[{"id":"1.231613187","rc":[{"batb":[[0,4.2,4],[1,4.1,12.59],[2,1.59,171.61]],"ltp":4.3,"tv":6.46,"id":12474498}]}]}
{"op":"mcm","clk":"11827458508","pt":1723357037124,"mc":[{"id":"1.231613187","rc":[{"batb":[[0,4.1,12.59],[1,1.59,171.61],[2,1.58,171.53]],"ltp":4.3,"tv":6.46,"id":12474498}]}]}
{"op":"mcm","clk":"11827458622","pt":1723357039636,"mc":[{"id":"1.231613187","rc":[{"batb":[[0,4.2,4],[1,4.1,12.59],[2,1.59,171.61]],"ltp":4.3,"tv":6.46,"id":12474498}]}]}
{"op":"mcm","clk":"11827458717","pt":1723357041937,"mc":[{"id":"1.231613187","rc":[{"batb":[[0,4.1,12.59],[1,1.59,171.61],[2,1.58,171.53]],"ltp":4.3,"tv":6.46,"id":12474498}]}]}
{"op":"mcm","clk":"11827458829","pt":1723357045372,"mc":[{"id":"1.231613187","rc":[{"batb":[[0,4.2,4],[1,4.1,12.59],[2,1.59,171.61]],"ltp":4.3,"tv":6.46,"id":12474498}]}]}
{"op":"mcm","clk":"11827458918","pt":1723357047581,"mc":[{"id":"1.231613187","rc":[{"batb":[[0,4.1,12.59],[1,1.59,171.61],[2,1.58,171.53]],"ltp":4.3,"tv":6.46,"id":12474498}]}]}
{"op":"mcm","clk":"11827459011","pt":1723357049889,"mc":[{"id":"1.231613187","rc":[{"batb":[[0,4.2,4],[1,4.1,12.59],[2,1.59,171.61]],"ltp":4.3,"tv":6.46,"id":12474498}]}]}
{"op":"mcm","clk":"11827459094","pt":1723357052091,"mc":[{"id":"1.231613187","rc":[{"batb":[[0,4.1,12.59],[1,1.59,171.61],[2,1.58,171.53]],"ltp":4.3,"tv":6.46,"id":12474498}]}]}
{"op":"mcm","clk":"11827459265","pt":1723357054776,"mc":[{"id":"1.231613187","rc":[{"batb":[[0,4.2,4],[1,4.1,12.59],[2,1.59,171.61]],"ltp":4.3,"tv":6.46,"id":12474498}]}]}
{"op":"mcm","clk":"11827459370","pt":1723357057396,"mc":[{"id":"1.231613187","rc":[{"batb":[[0,4.1,12.59],[1,1.59,171.61],[2,1.58,171.53]],"ltp":4.3,"tv":6.46,"id":12474498}]}]}
{"op":"mcm","clk":"11827459474","pt":1723357060664,"mc":[{"id":"1.231613187","rc":[{"batb":[[0,4.2,4],[1,4.1,12.59],[2,1.59,171.61]],"ltp":4.3,"tv":6.46,"id":12474498}]}]}
{"op":"mcm","clk":"11827459561","pt":1723357063206,"mc":[{"id":"1.231613187","rc":[{"batb":[[0,4.1,12.59],[1,1.59,171.61],[2,1.58,171.53]],"ltp":4.3,"tv":6.46,"id":12474498}]}]}
{"op":"mcm","clk":"11827459671","pt":1723357065885,"mc":[{"id":"1.231613187","rc":[{"batb":[[0,4.2,4],[1,4.1,12.59],[2,1.59,171.61]],"ltp":4.3,"tv":6.46,"id":12474498}]}]}
{"op":"mcm","clk":"11827459774","pt":1723357068291,"mc":[{"id":"1.231613187","rc":[{"batb":[[0,4.1,12.59],[1,1.59,171.61],[2,1.58,171.53]],"ltp":4.3,"tv":6.46,"id":12474498}]}]}
{"op":"mcm","clk":"11827459898","pt":1723357071415,"mc":[{"id":"1.231613187","rc":[{"batb":[[0,4.2,4],[1,4.1,12.59],[2,1.59,171.61]],"ltp":4.3,"tv":6.46,"id":12474498}]}]}
{"op":"mcm","clk":"11827459979","pt":1723357073623,"mc":[{"id":"1.231613187","rc":[{"batb":[[0,4.1,12.59],[1,1.59,171.61],[2,1.58,171.53]],"ltp":4.3,"tv":6.46,"id":12474498}]}]}
{"op":"mcm","clk":"11827460075","pt":1723357075824,"mc":[{"id":"1.231613187","rc":[{"batb":[[0,4.2,4],[1,4.1,12.59],[2,1.59,171.61]],"ltp":4.3,"tv":6.46,"id":12474498}]}]}
{"op":"mcm","clk":"11827460131","pt":1723357078329,"mc":[{"id":"1.231613187","rc":[{"batb":[[0,4.1,12.59],[1,1.59,171.61],[2,1.58,171.53]],"ltp":4.3,"tv":6.46,"id":12474498}]}]}
{"op":"mcm","clk":"11827460226","pt":1723357080637,"mc":[{"id":"1.231613187","rc":[{"batb":[[0,4.2,4],[1,4.1,12.59],[2,1.59,171.61]],"ltp":4.3,"tv":6.46,"id":12474498}]}]}
{"op":"mcm","clk":"11827460349","pt":1723357083519,"mc":[{"id":"1.231613187","rc":[{"batb":[[0,4.1,12.59],[1,1.59,171.61],[2,1.58,171.53]],"ltp":4.3,"tv":6.46,"id":12474498}]}]}
{"op":"mcm","clk":"11827460449","pt":1723357085720,"mc":[{"id":"1.231613187","rc":[{"batb":[[0,4.2,4],[1,4.1,12.59],[2,1.59,171.61]],"ltp":4.3,"tv":6.46,"id":12474498}]}]}
{"op":"mcm","clk":"11827460554","pt":1723357088338,"mc":[{"id":"1.231613187","rc":[{"batb":[[0,4.1,12.59],[1,1.59,171.61],[2,1.58,171.53]],"ltp":4.3,"tv":6.46,"id":12474498}]}]}
{"op":"mcm","clk":"11827460652","pt":1723357090502,"mc":[{"id":"1.231613187","rc":[{"batb":[[0,4.2,4],[1,4.1,12.59],[2,1.59,171.61]],"ltp":4.3,"tv":6.46,"id":12474498}]}]}
{"op":"mcm","clk":"11827460748","pt":1723357093014,"mc":[{"id":"1.231613187","rc":[{"batb":[[0,4.1,12.59],[1,1.59,171.61],[2,1.58,171.53]],"ltp":4.3,"tv":6.46,"id":12474498}]}]}
{"op":"mcm","clk":"11827460834","pt":1723357095213,"mc":[{"id":"1.231613187","rc":[{"batb":[[0,4.2,4],[1,4.1,12.59],[2,1.59,171.61]],"ltp":4.3,"tv":6.46,"id":12474498}]}]}
{"op":"mcm","clk":"11827460941","pt":1723357097623,"mc":[{"id":"1.231613187","rc":[{"batb":[[0,4.1,12.59],[1,1.59,171.61],[2,1.58,171.53]],"ltp":4.3,"tv":6.46,"id":12474498}]}]}
{"op":"mcm","clk":"11827461030","pt":1723357099840,"mc":[{"id":"1.231613187","rc":[{"batb":[[0,4.2,4],[1,4.1,12.59],[2,1.59,171.61]],"ltp":4.3,"tv":6.46,"id":12474498}]}]}
{"op":"mcm","clk":"11827461117","pt":1723357102326,"mc":[{"id":"1.231613187","rc":[{"batb":[[0,4.1,12.59],[1,1.59,171.61],[2,1.58,171.53]],"ltp":4.3,"tv":6.46,"id":12474498}]}]}
{"op":"mcm","clk":"11827461190","pt":1723357104745,"mc":[{"id":"1.231613187","rc":[{"batb":[[0,4.2,4],[1,4.1,12.59],[2,1.59,171.61]],"ltp":4.3,"tv":6.46,"id":12474498}]}]}
{"op":"mcm","clk":"11827461299","pt":1723357107162,"mc":[{"id":"1.231613187","rc":[{"batb":[[0,4.1,12.59],[1,1.59,171.61],[2,1.58,171.53]],"ltp":4.3,"tv":6.46,"id":12474498}]}]}
{"op":"mcm","clk":"11827461377","pt":1723357109569,"mc":[{"id":"1.231613187","rc":[{"batb":[[0,4.2,4],[1,4.1,12.59],[2,1.59,171.61]],"ltp":4.3,"tv":6.46,"id":12474498}]}]}
{"op":"mcm","clk":"11827461473","pt":1723357111880,"mc":[{"id":"1.231613187","rc":[{"batb":[[0,4.1,12.59],[1,1.59,171.61],[2,1.58,171.53]],"ltp":4.3,"tv":6.46,"id":12474498}]}]}
{"op":"mcm","clk":"11827461572","pt":1723357114402,"mc":[{"id":"1.231613187","rc":[{"batb":[[0,4.2,4],[1,4.1,12.59],[2,1.59,171.61]],"ltp":4.3,"tv":6.46,"id":12474498}]}]}
{"op":"mcm","clk":"11827461683","pt":1723357116866,"mc":[{"id":"1.231613187","rc":[{"batb":[[0,4.1,12.59],[1,1.59,171.61],[2,1.58,171.53]],"ltp":4.3,"tv":6.46,"id":12474498}]}]}
{"op":"mcm","clk":"11827461756","pt":1723357119072,"mc":[{"id":"1.231613187","rc":[{"batb":[[0,4.2,4],[1,4.1,12.59],[2,1.59,171.61]],"ltp":4.3,"tv":6.46,"id":12474498}]}]}
