{"op":"mcm","clk":"11980445294","pt":1724835714952,"mc":[{"id":"1.232375043","marketDefinition":{"bspMarket":false,"turnInPlayEnabled":true,"persistenceEnabled":true,"marketBaseRate":5.0,"eventId":"33534236","eventTypeId":"4","numberOfWinners":1,"bettingType":"ODDS","marketType":"MATCH_ODDS","marketTime":"2024-08-29T09:45:00.000Z","suspendTime":"2024-08-29T09:45:00.000Z","bspReconciled":false,"complete":true,"inPlay":false,"crossMatching":false,"runnersVoidable":false,"numberOfActiveRunners":2,"betDelay":0,"status":"OPEN","runners":[{"status":"ACTIVE","sortPriority":1,"id":19587555,"name":"Leinster Lightning"},{"status":"ACTIVE","sortPriority":2,"id":25651861,"name":"North-West Warriors"}],"regulators":["MR_INT"],"countryCode":"GB","discountAllowed":false,"timezone":"GMT","openDate":"2024-08-29T09:45:00.000Z","version":6104633050,"name":"Match Odds","eventName":"Leinster Lightning v North-West Warriors"},"rc":[{"batb":[[0,1.03,200],[1,1.02,200],[2,1.01,220]],"ltp":0.0,"tv":0.0,"id":25651861},{"batb":[[0,1.03,200],[1,1.02,200],[2,1.01,220]],"ltp":0.0,"tv":0.0,"id":19587555}]}]}
{"op":"mcm","clk":"11980445380","pt":1724835716542,"mc":[{"id":"1.232375043","marketDefinition":{"bspMarket":false,"turnInPlayEnabled":true,"persistenceEnabled":true,"marketBaseRate":5.0,"eventId":"33534236","eventTypeId":"4","numberOfWinners":1,"bettingType":"ODDS","marketType":"MATCH_ODDS","marketTime":"2024-08-29T09:45:00.000Z","suspendTime":"2024-08-29T09:45:00.000Z","bspReconciled":false,"complete":true,"inPlay":false,"crossMatching":false,"runnersVoidable":false,"numberOfActiveRunners":2,"betDelay":0,"status":"OPEN","runners":[{"status":"ACTIVE","sortPriority":1,"id":19587555,"name":"Leinster Lightning"},{"status":"ACTIVE","sortPriority":2,"id":25651861,"name":"North-West Warriors"}],"regulators":["MR_INT"],"countryCode":"GB","discountAllowed":true,"timezone":"GMT","openDate":"2024-08-29T09:45:00.000Z","version":6104633050,"name":"Match Odds","eventName":"Leinster Lightning v North-West Warriors"}}]}
{"op":"mcm","clk":"11980575177","pt":1724837928935,"mc":[{"id":"1.232375043","rc":[{"batb":[[0,1.2,250],[1,1.03,200],[2,1.02,200]],"ltp":0.0,"tv":0.0,"id":19587555}]}]}
{"op":"mcm","clk":"11980575218","pt":1724837929649,"mc":[{"id":"1.232375043","rc":[{"batb":[[0,1.2,250],[1,1.03,200],[2,1.02,200]],"ltp":0.0,"tv":0.0,"id":25651861}]}]}
{"op":"mcm","clk":"11980670097","pt":1724839318097,"mc":[{"id":"1.232375043","rc":[{"batb":[[0,1.21,7.06],[1,1.2,250],[2,1.03,200]],"ltp":0.0,"tv":0.0,"id":25651861},{"batb":[[0,1.21,5.76],[1,1.2,250],[2,1.03,200]],"ltp":0.0,"tv":0.0,"id":19587555}]}]}
{"op":"mcm","clk":"11980670922","pt":1724839329921,"mc":[{"id":"1.232375043","marketDefinition":{"bspMarket":false,"turnInPlayEnabled":true,"persistenceEnabled":true,"marketBaseRate":5.0,"eventId":"33534236","eventTypeId":"4","numberOfWinners":1,"bettingType":"ODDS","marketType":"MATCH_ODDS","marketTime":"2024-08-29T09:45:00.000Z","suspendTime":"2024-08-29T09:45:00.000Z","bspReconciled":false,"complete":true,"inPlay":false,"crossMatching":true,"runnersVoidable":false,"numberOfActiveRunners":2,"betDelay":0,"status":"OPEN","runners":[{"status":"ACTIVE","sortPriority":1,"id":19587555,"name":"Leinster Lightning"},{"status":"ACTIVE","sortPriority":2,"id":25651861,"name":"North-West Warriors"}],"regulators":["MR_INT"],"countryCode":"GB","discountAllowed":true,"timezone":"GMT","openDate":"2024-08-29T09:45:00.000Z","version":6104633050,"name":"Match Odds","eventName":"Leinster Lightning v North-West Warriors"}}]}
{"op":"mcm","clk":"11980932848","pt":1724843244775,"mc":[{"id":"1.232375043","rc":[{"batb":[[0,1.22,38.47],[1,1.21,7.07],[2,1.2,250]],"ltp":0.0,"tv":0.0,"id":25651861},{"batb":[[0,1.22,38.47],[1,1.21,5.76],[2,1.2,250]],"ltp":0.0,"tv":0.0,"id":19587555}]}]}
{"op":"mcm","clk":"11981006285","pt":1724844166698,"mc":[{"id":"1.232375043","rc":[{"batb":[[0,1.3,4.21],[1,1.22,38.47],[2,1.21,7.07]],"ltp":0.0,"tv":0.0,"id":25651861}]}]}
{"op":"mcm","clk":"11981006986","pt":1724844178716,"mc":[{"id":"1.232375043","rc":[{"batb":[[0,1.36,7.57],[1,1.22,38.47],[2,1.21,5.76]],"ltp":0.0,"tv":0.0,"id":19587555}]}]}
{"op":"mcm","clk":"11981030404","pt":1724844606749,"mc":[{"id":"1.232375043","rc":[{"trd":[[1.36,0.02]],"batb":[[0,1.36,7.56]],"ltp":1.36,"tv":0.01,"id":19587555}],"tv":0.01}]}
{"op":"mcm","clk":"11981055758","pt":1724844990387,"mc":[{"id":"1.232375043","rc":[{"batb":[[1,1.23,7.07],[2,1.22,38.47]],"ltp":0.0,"tv":0.0,"id":25651861},{"batb":[[1,1.23,5.76],[2,1.22,38.47]],"ltp":1.36,"tv":0.01,"id":19587555}]}]}
{"op":"mcm","clk":"11981059024","pt":1724845045064,"mc":[{"id":"1.232375043","rc":[{"batb":[[2,1.2,250]],"ltp":0.0,"tv":0.0,"id":25651861},{"batb":[[2,1.2,250]],"ltp":1.36,"tv":0.01,"id":19587555}]}]}
{"op":"mcm","clk":"11981066921","pt":1724845158521,"mc":[{"id":"1.232375043","rc":[{"batb":[[0,1.31,27.3],[1,1.3,4.21],[2,1.23,7.07]],"ltp":0.0,"tv":0.0,"id":25651861},{"batb":[[0,1.37,22.87],[1,1.36,7.56],[2,1.23,5.76]],"ltp":1.36,"tv":0.01,"id":19587555}]}]}
{"op":"mcm","clk":"11981071704","pt":1724845234828,"mc":[{"id":"1.232375043","rc":[{"batb":[[0,1.31,31.51],[1,1.23,7.07],[2,1.2,250]],"ltp":0.0,"tv":0.0,"id":25651861}]}]}
{"op":"mcm","clk":"11981072078","pt":1724845241805,"mc":[{"id":"1.232375043","rc":[{"batb":[[0,1.37,30.43],[1,1.23,5.76],[2,1.2,250]],"ltp":1.36,"tv":0.01,"id":19587555}]}]}
{"op":"mcm","clk":"11981169960","pt":1724846958950,"mc":[{"id":"1.232375043","rc":[{"batb":[[0,1.31,4.22],[1,1.23,7.07]],"ltp":0.0,"tv":0.0,"id":25651861},{"batb":[[0,1.37,7.57],[1,1.23,5.76]],"ltp":1.36,"tv":0.01,"id":19587555}]}]}
{"op":"mcm","clk":"11981174910","pt":1724847051097,"mc":[{"id":"1.232375043","rc":[{"batb":[[0,1.32,26.45],[1,1.31,4.22],[2,1.23,7.07]],"ltp":0.0,"tv":0.0,"id":25651861},{"batb":[[0,1.38,22.28],[1,1.37,7.57],[2,1.23,5.76]],"ltp":1.36,"tv":0.01,"id":19587555}]}]}
{"op":"mcm","clk":"11981212761","pt":1724847655314,"mc":[{"id":"1.232375043","rc":[{"batb":[[0,1.5,66.71],[1,1.32,26.45],[2,1.31,4.22]],"ltp":0.0,"tv":0.0,"id":25651861}]}]}
{"op":"mcm","clk":"11981213465","pt":1724847668330,"mc":[{"id":"1.232375043","rc":[{"batb":[[0,1.51,3.52],[1,1.5,66.71],[2,1.32,26.45]],"ltp":0.0,"tv":0.0,"id":25651861},{"batb":[[0,1.5,66.71],[1,1.38,22.28],[2,1.37,7.57]],"ltp":1.36,"tv":0.01,"id":19587555}]}]}
{"op":"mcm","clk":"11981214611","pt":1724847688687,"mc":[{"id":"1.232375043","rc":[{"trd":[[1.5,133.42]],"batb":[[0,1.38,22.28],[1,1.37,7.57],[2,1.23,5.76]],"batl":[[0,1.5,0.93]],"ltp":1.5,"tv":133.44,"id":19587555}],"tv":133.44}]}
{"op":"mcm","clk":"11981215207","pt":1724847698464,"mc":[{"id":"1.232375043","rc":[{"batb":[[1,1.32,26.45],[2,1.31,4.22]],"ltp":0.0,"tv":0.0,"id":25651861}]}]}
{"op":"mcm","clk":"11981216468","pt":1724847721920,"mc":[{"id":"1.232375043","rc":[{"batb":[[0,1.52,65.35],[1,1.51,3.52],[2,1.32,26.45]],"ltp":0.0,"tv":0.0,"id":25651861}]}]}
{"op":"mcm","clk":"11981217013","pt":1724847731714,"mc":[{"id":"1.232375043","rc":[{"trd":[[1.52,130.7]],"batb":[[0,1.51,3.52],[1,1.32,26.45],[2,1.31,4.22]],"batl":[[0,1.52,1.74]],"ltp":1.52,"tv":130.69,"id":25651861}],"tv":264.14}]}
{"op":"mcm","clk":"11981219783","pt":1724847783496,"mc":[{"id":"1.232375043","rc":[{"batb":[[0,1.52,70.8],[1,1.51,3.52],[2,1.32,26.45]],"ltp":1.52,"tv":130.69,"id":25651861}]}]}
{"op":"mcm","clk":"11981220454","pt":1724847795720,"mc":[{"id":"1.232375043","rc":[{"trd":[[1.52,272.29]],"batb":[[0,1.51,3.52],[1,1.32,26.45],[2,1.31,4.22]],"batl":[[0,1.52,1.84]],"ltp":1.52,"tv":272.29,"id":25651861}],"tv":405.73}]}
{"op":"mcm","clk":"11981221393","pt":1724847814398,"mc":[{"id":"1.232375043","rc":[{"batb":[[1,1.33,7.07],[2,1.32,26.45]],"ltp":1.52,"tv":272.29,"id":25651861},{"batb":[[2,1.21,5.76]],"ltp":1.5,"tv":133.44,"id":19587555}]}]}
{"op":"mcm","clk":"11981223628","pt":1724847858274,"mc":[{"id":"1.232375043","rc":[{"batb":[[0,1.5,70.8],[1,1.38,22.28],[2,1.37,7.57]],"ltp":1.5,"tv":133.44,"id":19587555}]}]}
{"op":"mcm","clk":"11981224259","pt":1724847870703,"mc":[{"id":"1.232375043","rc":[{"trd":[[1.5,275.01]],"batb":[[0,1.38,22.28],[1,1.37,7.57],[2,1.21,5.76]],"batl":[[0,1.5,2.45]],"ltp":1.5,"tv":275.03,"id":19587555}],"tv":547.32}]}
{"op":"mcm","clk":"11981247427","pt":1724848374343,"mc":[{"id":"1.232375043","rc":[{"batb":[[0,1.39,5],[1,1.38,22.28],[2,1.37,7.57]],"batl":[[0,2.5,6.71]],"ltp":1.5,"tv":275.03,"id":19587555}]}]}
{"op":"mcm","clk":"11981247587","pt":1724848377638,"mc":[{"id":"1.232375043","rc":[{"batb":[[0,1.38,22.28],[1,1.37,7.57],[2,1.21,5.76]],"ltp":1.5,"tv":275.03,"id":19587555}]}]}
{"op":"mcm","clk":"11981248153","pt":1724848387861,"mc":[{"id":"1.232375043","rc":[{"batb":[[0,1.39,5],[1,1.38,22.28],[2,1.37,7.57]],"ltp":1.5,"tv":275.03,"id":19587555}]}]}
{"op":"mcm","clk":"11981248373","pt":1724848391530,"mc":[{"id":"1.232375043","rc":[{"batb":[[0,1.38,22.28],[1,1.37,7.57],[2,1.21,5.76]],"ltp":1.5,"tv":275.03,"id":19587555}]}]}
{"op":"mcm","clk":"11981276620","pt":1724848851355,"mc":[{"id":"1.232375043","rc":[{"batb":[[2,1.31,4.22]],"ltp":1.52,"tv":272.29,"id":25651861},{"batb":[[0,1.38,5]],"ltp":1.5,"tv":275.03,"id":19587555}]}]}
{"op":"mcm","clk":"11981276834","pt":1724848854568,"mc":[{"id":"1.232375043","rc":[{"batb":[[0,1.37,7.57],[1,1.21,5.76],[2,1.2,250]],"ltp":1.5,"tv":275.03,"id":19587555}]}]}
{"op":"mcm","clk":"11981278487","pt":1724848880208,"mc":[{"id":"1.232375043","rc":[{"batb":[[0,1.43,5],[1,1.42,15.08],[2,1.37,7.57]],"ltp":1.5,"tv":275.03,"id":19587555}]}]}
{"op":"mcm","clk":"11981278699","pt":1724848883422,"mc":[{"id":"1.232375043","rc":[{"batb":[[0,1.42,15.08],[1,1.37,7.57],[2,1.21,5.76]],"ltp":1.5,"tv":275.03,"id":19587555}]}]}
{"op":"mcm","clk":"11981281626","pt":1724848930360,"mc":[{"id":"1.232375043","rc":[{"batb":[[0,1.67,12.63],[1,1.51,3.52],[2,1.33,7.07]],"ltp":1.52,"tv":272.29,"id":25651861},{"batb":[[0,1.44,5],[1,1.43,19.69],[2,1.42,15.08]],"ltp":1.5,"tv":275.03,"id":19587555}]}]}
{"op":"mcm","clk":"11981281836","pt":1724848933673,"mc":[{"id":"1.232375043","rc":[{"batb":[[0,1.43,19.69],[1,1.42,15.08],[2,1.37,7.57]],"ltp":1.5,"tv":275.03,"id":19587555}]}]}
{"op":"mcm","clk":"11981283881","pt":1724848968491,"mc":[{"id":"1.232375043","rc":[{"batb":[[1,1.37,7.57],[2,1.21,5.76]],"ltp":1.5,"tv":275.03,"id":19587555}]}]}
{"op":"mcm","clk":"11981283898","pt":1724848968698,"mc":[{"id":"1.232375043","rc":[{"batb":[[0,1.44,5],[1,1.43,19.69],[2,1.37,7.57]],"ltp":1.5,"tv":275.03,"id":19587555}]}]}
{"op":"mcm","clk":"11981284111","pt":1724848972188,"mc":[{"id":"1.232375043","rc":[{"batb":[[0,1.43,19.69],[1,1.37,7.57],[2,1.21,5.76]],"ltp":1.5,"tv":275.03,"id":19587555}]}]}
{"op":"mcm","clk":"11981295159","pt":1724848983318,"mc":[{"id":"1.232375043","rc":[{"batb":[[0,1.46,5],[1,1.45,15.08],[2,1.43,19.69]],"ltp":1.5,"tv":275.03,"id":19587555}]}]}
{"op":"mcm","clk":"11981295311","pt":1724848986708,"mc":[{"id":"1.232375043","rc":[{"batb":[[0,1.45,15.08],[1,1.43,19.69],[2,1.37,7.57]],"ltp":1.5,"tv":275.03,"id":19587555}]}]}
{"op":"mcm","clk":"11981299542","pt":1724849081556,"mc":[{"id":"1.232375043","rc":[{"batb":[[0,1.46,5],[1,1.45,15.08],[2,1.43,19.69]],"ltp":1.5,"tv":275.03,"id":19587555}]}]}
{"op":"mcm","clk":"11981299699","pt":1724849085142,"mc":[{"id":"1.232375043","rc":[{"batb":[[0,1.45,15.08],[1,1.43,19.69],[2,1.37,7.57]],"ltp":1.5,"tv":275.03,"id":19587555}]}]}
{"op":"mcm","clk":"11981299972","pt":1724849092238,"mc":[{"id":"1.232375043","rc":[{"batb":[[0,1.46,5],[1,1.45,15.08],[2,1.43,19.69]],"ltp":1.5,"tv":275.03,"id":19587555}]}]}
{"op":"mcm","clk":"11981300224","pt":1724849097897,"mc":[{"id":"1.232375043","rc":[{"batb":[[0,1.45,15.08],[1,1.43,19.69],[2,1.37,7.57]],"ltp":1.5,"tv":275.03,"id":19587555}]}]}
{"op":"mcm","clk":"11981312855","pt":1724849347714,"mc":[{"id":"1.232375043","rc":[{"batb":[[0,1.46,5],[1,1.45,15.08],[2,1.43,19.69]],"ltp":1.5,"tv":275.03,"id":19587555}]}]}
{"op":"mcm","clk":"11981313034","pt":1724849350913,"mc":[{"id":"1.232375043","rc":[{"batb":[[0,1.45,15.08],[1,1.43,19.69],[2,1.37,7.57]],"ltp":1.5,"tv":275.03,"id":19587555}]}]}
{"op":"mcm","clk":"11981326573","pt":1724849603780,"mc":[{"id":"1.232375043","rc":[{"batb":[[0,1.46,5],[1,1.45,15.08],[2,1.43,19.69]],"ltp":1.5,"tv":275.03,"id":19587555}]}]}
{"op":"mcm","clk":"11981326810","pt":1724849607761,"mc":[{"id":"1.232375043","rc":[{"batb":[[0,1.45,15.08],[1,1.43,19.69],[2,1.37,7.57]],"ltp":1.5,"tv":275.03,"id":19587555}]}]}
{"op":"mcm","clk":"11981335028","pt":1724849755969,"mc":[{"id":"1.232375043","rc":[{"batb":[[0,1.46,5],[1,1.45,15.08],[2,1.43,19.69]],"ltp":1.5,"tv":275.03,"id":19587555}]}]}
{"op":"mcm","clk":"11981335232","pt":1724849759584,"mc":[{"id":"1.232375043","rc":[{"batb":[[0,1.45,15.08],[1,1.43,19.69],[2,1.37,7.57]],"ltp":1.5,"tv":275.03,"id":19587555}]}]}
{"op":"mcm","clk":"11981350324","pt":1724850063805,"mc":[{"id":"1.232375043","rc":[{"trd":[[1.52,272.24]],"batb":[[0,1.67,13.5],[2,1.33,7.07]],"ltp":1.52,"tv":272.24,"id":25651861},{"trd":[[1.5,274.96]],"batb":[[0,1.46,5],[1,1.45,15.08],[2,1.43,19.67]],"ltp":1.5,"tv":274.98,"id":19587555}],"tv":547.22}]}
{"op":"mcm","clk":"11981350485","pt":1724850067106,"mc":[{"id":"1.232375043","rc":[{"batb":[[0,1.45,15.08],[1,1.43,19.67],[2,1.37,7.57]],"ltp":1.5,"tv":274.98,"id":19587555}]}]}
{"op":"mcm","clk":"11981355250","pt":1724850174323,"mc":[{"id":"1.232375043","rc":[{"batb":[[0,1.46,5],[1,1.45,15.08],[2,1.43,19.67]],"ltp":1.5,"tv":274.98,"id":19587555}]}]}
{"op":"mcm","clk":"11981355432","pt":1724850177827,"mc":[{"id":"1.232375043","rc":[{"batb":[[0,1.45,15.08],[1,1.43,19.67],[2,1.37,7.57]],"ltp":1.5,"tv":274.98,"id":19587555}]}]}
{"op":"mcm","clk":"11981372294","pt":1724850521451,"mc":[{"id":"1.232375043","rc":[{"batb":[[0,1.46,5],[1,1.45,15.08],[2,1.43,19.67]],"ltp":1.5,"tv":274.98,"id":19587555}]}]}
{"op":"mcm","clk":"11981372492","pt":1724850524925,"mc":[{"id":"1.232375043","rc":[{"batb":[[0,1.45,15.08],[1,1.43,19.67],[2,1.37,7.57]],"ltp":1.5,"tv":274.98,"id":19587555}]}]}
{"op":"mcm","clk":"11981379545","pt":1724850658108,"mc":[{"id":"1.232375043","rc":[{"batb":[[2,1.31,4.22]],"ltp":1.52,"tv":272.24,"id":25651861},{"batb":[[0,1.46,5],[1,1.45,15.08],[2,1.43,19.67]],"ltp":1.5,"tv":274.98,"id":19587555}]}]}
{"op":"mcm","clk":"11981379696","pt":1724850661409,"mc":[{"id":"1.232375043","rc":[{"batb":[[0,1.45,15.08],[1,1.43,19.67],[2,1.37,7.57]],"ltp":1.5,"tv":274.98,"id":19587555}]}]}
{"op":"mcm","clk":"11981381576","pt":1724850699285,"mc":[{"id":"1.232375043","rc":[{"batb":[[0,1.68,1.72],[1,1.67,12.62],[2,1.51,3.52]],"ltp":1.52,"tv":272.24,"id":25651861},{"batb":[[0,1.46,5],[1,1.45,15.08],[2,1.43,19.67]],"ltp":1.5,"tv":274.98,"id":19587555}]}]}
{"op":"mcm","clk":"11981381760","pt":1724850702701,"mc":[{"id":"1.232375043","rc":[{"batb":[[0,1.45,15.08],[1,1.43,19.67],[2,1.37,7.57]],"ltp":1.5,"tv":274.98,"id":19587555}]}]}
{"op":"mcm","clk":"11981383181","pt":1724850729328,"mc":[{"id":"1.232375043","rc":[{"batb":[[0,1.45,15.86]],"ltp":1.5,"tv":274.98,"id":19587555}]}]}
{"op":"mcm","clk":"11981383246","pt":1724850730514,"mc":[{"id":"1.232375043","rc":[{"batb":[[1,1.51,3.52],[2,1.31,4.22]],"ltp":1.52,"tv":272.24,"id":25651861},{"batb":[[0,1.46,5.78],[1,1.45,15.08]],"batl":[[0,2.4,6.71]],"ltp":1.5,"tv":274.98,"id":19587555}]}]}
{"op":"mcm","clk":"11981383432","pt":1724850733947,"mc":[{"id":"1.232375043","rc":[{"batb":[[0,1.45,15.86],[1,1.37,7.57],[2,1.21,5.76]],"ltp":1.5,"tv":274.98,"id":19587555}]}]}
{"op":"mcm","clk":"11981383757","pt":1724850741220,"mc":[{"id":"1.232375043","rc":[{"batb":[[0,1.46,5.78],[1,1.45,15.08],[2,1.37,7.57]],"ltp":1.5,"tv":274.98,"id":19587555}]}]}
{"op":"mcm","clk":"11981383935","pt":1724850744829,"mc":[{"id":"1.232375043","rc":[{"batb":[[0,1.45,15.86],[1,1.37,7.57],[2,1.21,5.76]],"ltp":1.5,"tv":274.98,"id":19587555}]}]}
{"op":"mcm","clk":"11981385043","pt":1724850770157,"mc":[{"id":"1.232375043","rc":[{"batb":[[0,1.46,5.78],[1,1.45,15.08],[2,1.37,7.57]],"ltp":1.5,"tv":274.98,"id":19587555}]}]}
{"op":"mcm","clk":"11981385216","pt":1724850773688,"mc":[{"id":"1.232375043","rc":[{"batb":[[0,1.45,15.86],[1,1.37,7.57],[2,1.21,5.76]],"ltp":1.5,"tv":274.98,"id":19587555}]}]}
{"op":"mcm","clk":"11981385555","pt":1724850781078,"mc":[{"id":"1.232375043","rc":[{"batb":[[0,1.46,5.78],[1,1.45,15.08],[2,1.37,7.57]],"ltp":1.5,"tv":274.98,"id":19587555}]}]}
{"op":"mcm","clk":"11981385728","pt":1724850784793,"mc":[{"id":"1.232375043","rc":[{"batb":[[0,1.45,15.86],[1,1.37,7.57],[2,1.21,5.76]],"ltp":1.5,"tv":274.98,"id":19587555}]}]}
{"op":"mcm","clk":"11981386265","pt":1724850795509,"mc":[{"id":"1.232375043","rc":[{"batb":[[0,1.72,12.59],[1,1.51,4.4]],"ltp":1.52,"tv":272.24,"id":25651861},{"batb":[[0,1.47,5.78],[1,1.46,18.39],[2,1.45,15.08]],"ltp":1.5,"tv":274.98,"id":19587555}]}]}
{"op":"mcm","clk":"11981386443","pt":1724850798920,"mc":[{"id":"1.232375043","rc":[{"batb":[[0,1.46,19.17],[1,1.45,15.08],[2,1.37,7.57]],"ltp":1.5,"tv":274.98,"id":19587555}]}]}
{"op":"mcm","clk":"11981386570","pt":1724850801715,"mc":[{"id":"1.232375043","rc":[{"batb":[[0,1.47,5.78],[1,1.46,18.39],[2,1.45,15.08]],"ltp":1.5,"tv":274.98,"id":19587555}]}]}
{"op":"mcm","clk":"11981386740","pt":1724850805238,"mc":[{"id":"1.232375043","rc":[{"batb":[[0,1.46,19.17],[1,1.45,15.08],[2,1.37,7.57]],"ltp":1.5,"tv":274.98,"id":19587555}]}]}
{"op":"mcm","clk":"11981387501","pt":1724850821928,"mc":[{"id":"1.232375043","rc":[{"batb":[[0,1.47,5.78],[1,1.46,18.39],[2,1.45,15.08]],"ltp":1.5,"tv":274.98,"id":19587555}]}]}
{"op":"mcm","clk":"11981387671","pt":1724850825452,"mc":[{"id":"1.232375043","rc":[{"batb":[[0,1.46,19.17],[1,1.45,15.08],[2,1.37,7.57]],"ltp":1.5,"tv":274.98,"id":19587555}]}]}
{"op":"mcm","clk":"11981387843","pt":1724850829146,"mc":[{"id":"1.232375043","rc":[{"batb":[[0,1.49,5.78],[1,1.48,4.22],[2,1.46,18.39]],"ltp":1.5,"tv":274.98,"id":19587555}]}]}
{"op":"mcm","clk":"11981388008","pt":1724850832362,"mc":[{"id":"1.232375043","rc":[{"batb":[[0,1.48,5],[1,1.46,18.39],[2,1.45,15.08]],"ltp":1.5,"tv":274.98,"id":19587555}]}]}
{"op":"mcm","clk":"11981388794","pt":1724850849884,"mc":[{"id":"1.232375043","rc":[{"batb":[[0,1.49,5.78],[1,1.48,4.22],[2,1.46,18.39]],"ltp":1.5,"tv":274.98,"id":19587555}]}]}
{"op":"mcm","clk":"11981389014","pt":1724850853469,"mc":[{"id":"1.232375043","rc":[{"batb":[[0,1.48,5],[1,1.46,18.39],[2,1.45,15.08]],"ltp":1.5,"tv":274.98,"id":19587555}]}]}
{"op":"mcm","clk":"11981390048","pt":1724850881228,"mc":[{"id":"1.232375043","rc":[{"batb":[[0,1.49,5.78],[1,1.48,4.22],[2,1.46,18.39]],"ltp":1.5,"tv":274.98,"id":19587555}]}]}
{"op":"mcm","clk":"11981390193","pt":1724850885114,"mc":[{"id":"1.232375043","rc":[{"batb":[[0,1.48,5],[1,1.46,18.39],[2,1.37,7.57]],"ltp":1.5,"tv":274.98,"id":19587555}]}]}
{"op":"mcm","clk":"11981391389","pt":1724850914481,"mc":[{"id":"1.232375043","rc":[{"batb":[[0,1.49,5.78],[1,1.48,4.22],[2,1.46,18.39]],"ltp":1.5,"tv":274.98,"id":19587555}]}]}
{"op":"mcm","clk":"11981391538","pt":1724850918274,"mc":[{"id":"1.232375043","rc":[{"batb":[[0,1.48,5],[1,1.46,18.39],[2,1.37,7.57]],"ltp":1.5,"tv":274.98,"id":19587555}]}]}
{"op":"mcm","clk":"11981392460","pt":1724850941108,"mc":[{"id":"1.232375043","rc":[{"batb":[[0,1.49,5.78],[1,1.48,4.22],[2,1.46,18.39]],"ltp":1.5,"tv":274.98,"id":19587555}]}]}
{"op":"mcm","clk":"11981392586","pt":1724850944825,"mc":[{"id":"1.232375043","rc":[{"batb":[[0,1.48,5],[1,1.46,18.39],[2,1.37,7.57]],"ltp":1.5,"tv":274.98,"id":19587555}]}]}
{"op":"mcm","clk":"11981394386","pt":1724850987378,"mc":[{"id":"1.232375043","rc":[{"batb":[[0,1.49,5.78],[1,1.48,4.22],[2,1.46,18.39]],"ltp":1.5,"tv":274.98,"id":19587555}]}]}
{"op":"mcm","clk":"11981394514","pt":1724850991041,"mc":[{"id":"1.232375043","rc":[{"batb":[[0,1.48,5],[1,1.46,18.39],[2,1.37,7.57]],"ltp":1.5,"tv":274.98,"id":19587555}]}]}
{"op":"mcm","clk":"11981394693","pt":1724850995649,"mc":[{"id":"1.232375043","rc":[{"batb":[[0,1.49,5.78],[1,1.48,4.22],[2,1.46,18.39]],"ltp":1.5,"tv":274.98,"id":19587555}]}]}
{"op":"mcm","clk":"11981394837","pt":1724850999066,"mc":[{"id":"1.232375043","rc":[{"batb":[[0,1.48,5],[1,1.46,18.39],[2,1.37,7.57]],"ltp":1.5,"tv":274.98,"id":19587555}]}]}
{"op":"mcm","clk":"11981395116","pt":1724851006300,"mc":[{"id":"1.232375043","rc":[{"batb":[[0,1.49,5.78],[1,1.48,4.22],[2,1.46,18.39]],"ltp":1.5,"tv":274.98,"id":19587555}]}]}
{"op":"mcm","clk":"11981395270","pt":1724851010179,"mc":[{"id":"1.232375043","rc":[{"batb":[[0,1.48,5],[1,1.46,18.39],[2,1.37,7.57]],"ltp":1.5,"tv":274.98,"id":19587555}]}]}
{"op":"mcm","clk":"11981396941","pt":1724851053789,"mc":[{"id":"1.232375043","rc":[{"batb":[[0,1.49,5.78],[1,1.48,4.22],[2,1.46,18.39]],"ltp":1.5,"tv":274.98,"id":19587555}]}]}
{"op":"mcm","clk":"11981397089","pt":1724851057489,"mc":[{"id":"1.232375043","rc":[{"batb":[[0,1.48,5],[1,1.46,18.39],[2,1.37,7.57]],"ltp":1.5,"tv":274.98,"id":19587555}]}]}
{"op":"mcm","clk":"11981397312","pt":1724851062572,"mc":[{"id":"1.232375043","rc":[{"batb":[[0,1.49,5.78],[1,1.48,4.22],[2,1.46,18.39]],"ltp":1.5,"tv":274.98,"id":19587555}]}]}
{"op":"mcm","clk":"11981397456","pt":1724851066373,"mc":[{"id":"1.232375043","rc":[{"batb":[[0,1.48,5],[1,1.46,18.39],[2,1.37,7.57]],"ltp":1.5,"tv":274.98,"id":19587555}]}]}
{"op":"mcm","clk":"11981398079","pt":1724851080872,"mc":[{"id":"1.232375043","rc":[{"batb":[[0,1.49,5.78],[1,1.48,4.22],[2,1.46,18.39]],"ltp":1.5,"tv":274.98,"id":19587555}]}]}
{"op":"mcm","clk":"11981398247","pt":1724851084887,"mc":[{"id":"1.232375043","rc":[{"batb":[[0,1.48,5],[1,1.46,18.39],[2,1.37,7.57]],"ltp":1.5,"tv":274.98,"id":19587555}]}]}
{"op":"mcm","clk":"11981400354","pt":1724851123227,"mc":[{"id":"1.232375043","rc":[{"batb":[[0,1.49,5.78],[1,1.48,4.22],[2,1.46,18.39]],"ltp":1.5,"tv":274.98,"id":19587555}]}]}
{"op":"mcm","clk":"11981400541","pt":1724851126828,"mc":[{"id":"1.232375043","rc":[{"batb":[[0,1.48,5],[1,1.46,18.39],[2,1.37,7.57]],"ltp":1.5,"tv":274.98,"id":19587555}]}]}
{"op":"mcm","clk":"11981403524","pt":1724851183417,"mc":[{"id":"1.232375043","rc":[{"batb":[[0,1.74,3.72],[1,1.72,11.75],[2,1.51,4.4]],"ltp":1.52,"tv":272.24,"id":25651861},{"batb":[[0,1.49,5.78],[1,1.48,4.22],[2,1.46,18.39]],"ltp":1.5,"tv":274.98,"id":19587555}]}]}
{"op":"mcm","clk":"11981403722","pt":1724851186727,"mc":[{"id":"1.232375043","rc":[{"batb":[[0,1.48,5],[1,1.46,18.39],[2,1.37,7.57]],"ltp":1.5,"tv":274.98,"id":19587555}]}]}
{"op":"mcm","clk":"11981407832","pt":1724851262122,"mc":[{"id":"1.232375043","rc":[{"batb":[[0,1.49,5.78],[1,1.48,4.22],[2,1.46,18.39]],"ltp":1.5,"tv":274.98,"id":19587555}]}]}
{"op":"mcm","clk":"11981408022","pt":1724851265325,"mc":[{"id":"1.232375043","rc":[{"batb":[[0,1.48,5],[1,1.46,18.39],[2,1.37,7.57]],"ltp":1.5,"tv":274.98,"id":19587555}]}]}
{"op":"mcm","clk":"11981409020","pt":1724851284526,"mc":[{"id":"1.232375043","rc":[{"batb":[[0,1.49,5.78],[1,1.48,4.22],[2,1.46,18.39]],"ltp":1.5,"tv":274.98,"id":19587555}]}]}
{"op":"mcm","clk":"11981409164","pt":1724851287920,"mc":[{"id":"1.232375043","rc":[{"batb":[[0,1.48,5],[1,1.46,18.39],[2,1.37,7.57]],"ltp":1.5,"tv":274.98,"id":19587555}]}]}
{"op":"mcm","clk":"11981410261","pt":1724851310574,"mc":[{"id":"1.232375043","rc":[{"batb":[[0,1.49,5.78],[1,1.48,4.22],[2,1.46,18.39]],"ltp":1.5,"tv":274.98,"id":19587555}]}]}
{"op":"mcm","clk":"11981410440","pt":1724851313869,"mc":[{"id":"1.232375043","rc":[{"batb":[[0,1.48,5],[1,1.46,18.39],[2,1.37,7.57]],"ltp":1.5,"tv":274.98,"id":19587555}]}]}
{"op":"mcm","clk":"11981411699","pt":1724851337299,"mc":[{"id":"1.232375043","rc":[{"batb":[[0,1.49,5.78],[1,1.48,4.22],[2,1.46,18.39]],"batl":[[0,2.32,5.02]],"ltp":1.5,"tv":274.98,"id":19587555}]}]}
{"op":"mcm","clk":"11981411893","pt":1724851340880,"mc":[{"id":"1.232375043","rc":[{"batb":[[0,1.48,5],[1,1.46,18.39],[2,1.37,7.57]],"ltp":1.5,"tv":274.98,"id":19587555}]}]}
{"op":"mcm","clk":"11981412488","pt":1724851351807,"mc":[{"id":"1.232375043","rc":[{"batb":[[0,1.49,5.78],[1,1.48,4.22],[2,1.46,18.39]],"ltp":1.5,"tv":274.98,"id":19587555}]}]}
{"op":"mcm","clk":"11981412696","pt":1724851355053,"mc":[{"id":"1.232375043","rc":[{"batb":[[0,1.48,5],[1,1.46,18.39],[2,1.37,7.57]],"ltp":1.5,"tv":274.98,"id":19587555}]}]}
{"op":"mcm","clk":"11981412752","pt":1724851355936,"mc":[{"id":"1.232375043","rc":[{"batl":[[0,1.94,4.19],[1,2.32,5.02]],"ltp":1.5,"tv":274.98,"id":19587555}]}]}
{"op":"mcm","clk":"11981414185","pt":1724851381583,"mc":[{"id":"1.232375043","rc":[{"batb":[[0,1.52,15.08],[1,1.48,5],[2,1.46,18.39]],"ltp":1.5,"tv":274.98,"id":19587555}]}]}
{"op":"mcm","clk":"11981423981","pt":1724851554965,"mc":[{"id":"1.232375043","rc":[{"batl":[[0,1.94,5.11]],"ltp":1.5,"tv":274.98,"id":19587555}]}]}
{"op":"mcm","clk":"11981424111","pt":1724851557485,"mc":[{"id":"1.232375043","rc":[{"batb":[[0,1.53,5],[1,1.52,15.08],[2,1.48,5]],"batl":[[0,2.32,5.94],[1,2.32,0]],"ltp":1.5,"tv":274.98,"id":19587555}]}]}
{"op":"mcm","clk":"11981424296","pt":1724851560785,"mc":[{"id":"1.232375043","rc":[{"batb":[[0,1.52,15.08],[1,1.48,5],[2,1.46,18.39]],"ltp":1.5,"tv":274.98,"id":19587555}]}]}
{"op":"mcm","clk":"11981425074","pt":1724851573212,"mc":[{"id":"1.232375043","rc":[{"batb":[[0,1.53,5],[1,1.52,15.08],[2,1.48,5]],"ltp":1.5,"tv":274.98,"id":19587555}]}]}
{"op":"mcm","clk":"11981425294","pt":1724851576918,"mc":[{"id":"1.232375043","rc":[{"batb":[[0,1.52,15.08],[1,1.48,5],[2,1.46,18.39]],"ltp":1.5,"tv":274.98,"id":19587555}]}]}
{"op":"mcm","clk":"11981427172","pt":1724851608276,"mc":[{"id":"1.232375043","rc":[{"batb":[[0,1.63,5],[1,1.62,4.19],[2,1.52,15.08]],"ltp":1.5,"tv":274.98,"id":19587555}]}]}
{"op":"mcm","clk":"11981427355","pt":1724851611579,"mc":[{"id":"1.232375043","rc":[{"batb":[[0,1.62,4.19],[1,1.52,15.08],[2,1.48,5]],"ltp":1.5,"tv":274.98,"id":19587555}]}]}
{"op":"mcm","clk":"11981428037","pt":1724851622784,"mc":[{"id":"1.232375043","rc":[{"batb":[[0,1.83,4.19],[1,1.74,3.72],[2,1.72,11.75]],"ltp":1.52,"tv":272.24,"id":25651861},{"batb":[[0,1.63,5],[1,1.62,4.19],[2,1.52,15.08]],"ltp":1.5,"tv":274.98,"id":19587555}]}]}
{"op":"mcm","clk":"11981428239","pt":1724851626076,"mc":[{"id":"1.232375043","rc":[{"batb":[[0,1.62,4.19],[1,1.52,15.08],[2,1.48,5]],"ltp":1.5,"tv":274.98,"id":19587555}]}]}
{"op":"mcm","clk":"11981429111","pt":1724851639406,"mc":[{"id":"1.232375043","rc":[{"batb":[[0,1.63,5],[1,1.62,4.19],[2,1.52,15.08]],"batl":[[0,2.22,129.93],[1,2.32,5.02]],"ltp":1.5,"tv":274.98,"id":19587555}]}]}
{"op":"mcm","clk":"11981429309","pt":1724851642616,"mc":[{"id":"1.232375043","rc":[{"batb":[[0,1.62,4.19],[1,1.52,15.08],[2,1.48,5]],"ltp":1.5,"tv":274.98,"id":19587555}]}]}
{"op":"mcm","clk":"11981429849","pt":1724851652817,"mc":[{"id":"1.232375043","rc":[{"batb":[[0,1.63,5],[1,1.62,4.19],[2,1.52,15.08]],"batl":[[1,2.32,0]],"ltp":1.5,"tv":274.98,"id":19587555}]}]}
{"op":"mcm","clk":"11981430054","pt":1724851656132,"mc":[{"id":"1.232375043","rc":[{"batb":[[0,1.62,4.19],[1,1.52,15.08],[2,1.48,5]],"ltp":1.5,"tv":274.98,"id":19587555}]}]}
{"op":"mcm","clk":"11981430737","pt":1724851666435,"mc":[{"id":"1.232375043","rc":[{"batl":[[0,2.2,10.97],[1,2.22,129.01]],"ltp":1.5,"tv":274.98,"id":19587555}]}]}
{"op":"mcm","clk":"11981430740","pt":1724851666535,"mc":[{"id":"1.232375043","rc":[{"batb":[[0,1.63,5],[1,1.62,4.19],[2,1.52,15.08]],"ltp":1.5,"tv":274.98,"id":19587555}]}]}
{"op":"mcm","clk":"11981430960","pt":1724851669951,"mc":[{"id":"1.232375043","rc":[{"batb":[[0,1.62,4.19],[1,1.52,15.08],[2,1.48,5]],"ltp":1.5,"tv":274.98,"id":19587555}]}]}
{"op":"mcm","clk":"11981431428","pt":1724851677465,"mc":[{"id":"1.232375043","rc":[{"batl":[[1,2.22,0]],"ltp":1.5,"tv":274.98,"id":19587555}]}]}
{"op":"mcm","clk":"11981431441","pt":1724851677665,"mc":[{"id":"1.232375043","rc":[{"batb":[[0,1.63,5],[1,1.62,4.19],[2,1.52,15.08]],"ltp":1.5,"tv":274.98,"id":19587555}]}]}
{"op":"mcm","clk":"11981431687","pt":1724851681085,"mc":[{"id":"1.232375043","rc":[{"batb":[[0,1.62,4.19],[1,1.52,15.08],[2,1.48,5]],"ltp":1.5,"tv":274.98,"id":19587555}]}]}
{"op":"mcm","clk":"11981432546","pt":1724851693669,"mc":[{"id":"1.232375043","rc":[{"batb":[[0,1.63,5],[1,1.62,4.19],[2,1.52,15.08]],"ltp":1.5,"tv":274.98,"id":19587555}]}]}
{"op":"mcm","clk":"11981432766","pt":1724851697399,"mc":[{"id":"1.232375043","rc":[{"batb":[[0,1.62,4.19],[1,1.52,15.08],[2,1.48,5]],"ltp":1.5,"tv":274.98,"id":19587555}]}]}
{"op":"mcm","clk":"11981433203","pt":1724851705405,"mc":[{"id":"1.232375043","rc":[{"batb":[[0,1.83,5.03]],"ltp":1.52,"tv":272.24,"id":25651861},{"batb":[[0,1.63,5],[1,1.62,4.19],[2,1.52,15.08]],"ltp":1.5,"tv":274.98,"id":19587555}]}]}
{"op":"mcm","clk":"11981433410","pt":1724851708711,"mc":[{"id":"1.232375043","rc":[{"batb":[[0,1.62,4.19],[1,1.52,15.08],[2,1.48,5]],"ltp":1.5,"tv":274.98,"id":19587555}]}]}
{"op":"mcm","clk":"11981434440","pt":1724851726606,"mc":[{"id":"1.232375043","rc":[{"batb":[[0,1.63,5],[1,1.62,4.19],[2,1.52,15.08]],"ltp":1.5,"tv":274.98,"id":19587555}]}]}
{"op":"mcm","clk":"11981434664","pt":1724851730627,"mc":[{"id":"1.232375043","rc":[{"batb":[[0,1.62,4.19],[1,1.52,15.08],[2,1.48,5]],"ltp":1.5,"tv":274.98,"id":19587555}]}]}
{"op":"mcm","clk":"11981439770","pt":1724851821935,"mc":[{"id":"1.232375043","rc":[{"batb":[[0,1.63,5],[1,1.62,4.19],[2,1.52,15.08]],"ltp":1.5,"tv":274.98,"id":19587555}]}]}
{"op":"mcm","clk":"11981439967","pt":1724851825497,"mc":[{"id":"1.232375043","rc":[{"batb":[[0,1.62,4.19],[1,1.52,15.08],[2,1.48,5]],"ltp":1.5,"tv":274.98,"id":19587555}]}]}
{"op":"mcm","clk":"11981440125","pt":1724851828335,"mc":[{"id":"1.232375043","rc":[{"batb":[[0,1.63,5],[1,1.62,4.19],[2,1.52,15.08]],"ltp":1.5,"tv":274.98,"id":19587555}]}]}
{"op":"mcm","clk":"11981440318","pt":1724851832045,"mc":[{"id":"1.232375043","rc":[{"batb":[[0,1.62,4.19],[1,1.52,15.08],[2,1.48,5]],"ltp":1.5,"tv":274.98,"id":19587555}]}]}
{"op":"mcm","clk":"11981441229","pt":1724851848248,"mc":[{"id":"1.232375043","rc":[{"batb":[[0,1.63,5],[1,1.62,4.19],[2,1.52,15.08]],"ltp":1.5,"tv":274.98,"id":19587555}]}]}
{"op":"mcm","clk":"11981441417","pt":1724851852058,"mc":[{"id":"1.232375043","rc":[{"batb":[[0,1.62,4.19],[1,1.52,15.08],[2,1.48,5]],"ltp":1.5,"tv":274.98,"id":19587555}]}]}
{"op":"mcm","clk":"11981442151","pt":1724851866673,"mc":[{"id":"1.232375043","rc":[{"batb":[[0,1.63,5],[1,1.62,4.19],[2,1.52,15.08]],"ltp":1.5,"tv":274.98,"id":19587555}]}]}
{"op":"mcm","clk":"11981442361","pt":1724851870392,"mc":[{"id":"1.232375043","rc":[{"batb":[[0,1.62,4.19],[1,1.52,15.08],[2,1.48,5]],"ltp":1.5,"tv":274.98,"id":19587555}]}]}
{"op":"mcm","clk":"11981442536","pt":1724851873173,"mc":[{"id":"1.232375043","rc":[{"batb":[[0,1.63,5],[1,1.62,4.19],[2,1.52,15.08]],"ltp":1.5,"tv":274.98,"id":19587555}]}]}
{"op":"mcm","clk":"11981442771","pt":1724851876790,"mc":[{"id":"1.232375043","rc":[{"batb":[[0,1.62,4.19],[1,1.52,15.08],[2,1.48,5]],"ltp":1.5,"tv":274.98,"id":19587555}]}]}
{"op":"mcm","clk":"11981444141","pt":1724851901724,"mc":[{"id":"1.232375043","rc":[{"batb":[[0,1.63,5],[1,1.62,4.19],[2,1.52,15.08]],"ltp":1.5,"tv":274.98,"id":19587555}]}]}
{"op":"mcm","clk":"11981444319","pt":1724851905431,"mc":[{"id":"1.232375043","rc":[{"batb":[[0,1.62,4.19],[1,1.52,15.08],[2,1.48,5]],"ltp":1.5,"tv":274.98,"id":19587555}]}]}
{"op":"mcm","clk":"11981444708","pt":1724851912334,"mc":[{"id":"1.232375043","rc":[{"batb":[[0,1.63,5],[1,1.62,4.19],[2,1.52,15.08]],"ltp":1.5,"tv":274.98,"id":19587555}]}]}
{"op":"mcm","clk":"11981444955","pt":1724851915811,"mc":[{"id":"1.232375043","rc":[{"batb":[[0,1.62,4.19],[1,1.52,15.08],[2,1.48,5]],"ltp":1.5,"tv":274.98,"id":19587555}]}]}
{"op":"mcm","clk":"11981445791","pt":1724851929064,"mc":[{"id":"1.232375043","rc":[{"batb":[[0,1.63,5],[1,1.62,4.19],[2,1.52,15.08]],"batl":[[0,2.18,139.13],[1,2.2,10.05]],"ltp":1.5,"tv":274.98,"id":19587555}]}]}
{"op":"mcm","clk":"11981446017","pt":1724851932455,"mc":[{"id":"1.232375043","rc":[{"batb":[[0,1.62,4.19],[1,1.52,15.08],[2,1.48,5]],"ltp":1.5,"tv":274.98,"id":19587555}]}]}
{"op":"mcm","clk":"11981446194","pt":1724851934847,"mc":[{"id":"1.232375043","rc":[{"batb":[[0,1.63,5],[1,1.62,4.19],[2,1.52,15.08]],"batl":[[0,2.2,10.97],[1,2.2,0]],"ltp":1.5,"tv":274.98,"id":19587555}]}]}
{"op":"mcm","clk":"11981446376","pt":1724851938238,"mc":[{"id":"1.232375043","rc":[{"batb":[[0,1.62,4.19],[1,1.52,15.08],[2,1.48,5]],"ltp":1.5,"tv":274.98,"id":19587555}]}]}
{"op":"mcm","clk":"11981446909","pt":1724851947752,"mc":[{"id":"1.232375043","rc":[{"batb":[[0,1.63,5],[1,1.62,4.19],[2,1.52,15.08]],"ltp":1.5,"tv":274.98,"id":19587555}]}]}
{"op":"mcm","clk":"11981447115","pt":1724851951578,"mc":[{"id":"1.232375043","rc":[{"batb":[[0,1.62,4.19],[1,1.52,15.08],[2,1.48,5]],"ltp":1.5,"tv":274.98,"id":19587555}]}]}
{"op":"mcm","clk":"11981447490","pt":1724851958081,"mc":[{"id":"1.232375043","rc":[{"batb":[[0,1.63,5],[1,1.62,4.19],[2,1.52,15.08]],"ltp":1.5,"tv":274.98,"id":19587555}]}]}
{"op":"mcm","clk":"11981447672","pt":1724851961392,"mc":[{"id":"1.232375043","rc":[{"batb":[[0,1.62,4.19],[1,1.52,15.08],[2,1.48,5]],"ltp":1.5,"tv":274.98,"id":19587555}]}]}
{"op":"mcm","clk":"11981448008","pt":1724851968287,"mc":[{"id":"1.232375043","rc":[{"batb":[[0,1.63,5],[1,1.62,4.19],[2,1.52,15.08]],"batl":[[0,2.18,134.11],[1,2.2,10.05]],"ltp":1.5,"tv":274.98,"id":19587555}]}]}
{"op":"mcm","clk":"11981448172","pt":1724851971692,"mc":[{"id":"1.232375043","rc":[{"batb":[[0,1.62,4.19],[1,1.52,15.08],[2,1.48,5]],"ltp":1.5,"tv":274.98,"id":19587555}]}]}
{"op":"mcm","clk":"11981449523","pt":1724851993922,"mc":[{"id":"1.232375043","rc":[{"batb":[[0,1.63,5],[1,1.62,4.19],[2,1.52,15.08]],"ltp":1.5,"tv":274.98,"id":19587555}]}]}
{"op":"mcm","clk":"11981449731","pt":1724851997609,"mc":[{"id":"1.232375043","rc":[{"batb":[[0,1.62,4.19],[1,1.52,15.08],[2,1.48,5]],"ltp":1.5,"tv":274.98,"id":19587555}]}]}
{"op":"mcm","clk":"11981450185","pt":1724852004399,"mc":[{"id":"1.232375043","rc":[{"batb":[[0,1.63,5],[1,1.62,4.19],[2,1.52,15.08]],"ltp":1.5,"tv":274.98,"id":19587555}]}]}
{"op":"mcm","clk":"11981450384","pt":1724852008228,"mc":[{"id":"1.232375043","rc":[{"batb":[[0,1.62,4.19],[1,1.52,15.08],[2,1.48,5]],"ltp":1.5,"tv":274.98,"id":19587555}]}]}
{"op":"mcm","clk":"11981450713","pt":1724852014839,"mc":[{"id":"1.232375043","rc":[{"batb":[[0,1.63,5],[1,1.62,4.19],[2,1.52,15.08]],"ltp":1.5,"tv":274.98,"id":19587555}]}]}
{"op":"mcm","clk":"11981450877","pt":1724852018639,"mc":[{"id":"1.232375043","rc":[{"batb":[[0,1.62,4.19],[1,1.52,15.08],[2,1.48,5]],"ltp":1.5,"tv":274.98,"id":19587555}]}]}
{"op":"mcm","clk":"11981451070","pt":1724852021328,"mc":[{"id":"1.232375043","rc":[{"batb":[[0,1.63,5],[1,1.62,4.19],[2,1.52,15.08]],"ltp":1.5,"tv":274.98,"id":19587555}]}]}
{"op":"mcm","clk":"11981451363","pt":1724852025129,"mc":[{"id":"1.232375043","rc":[{"batb":[[0,1.62,4.19],[1,1.52,15.08],[2,1.48,5]],"ltp":1.5,"tv":274.98,"id":19587555}]}]}
{"op":"mcm","clk":"11981452245","pt":1724852040951,"mc":[{"id":"1.232375043","rc":[{"batb":[[0,1.63,5],[1,1.62,4.19],[2,1.52,15.08]],"ltp":1.5,"tv":274.98,"id":19587555}]}]}
{"op":"mcm","clk":"11981452459","pt":1724852044655,"mc":[{"id":"1.232375043","rc":[{"batb":[[0,1.62,4.19],[1,1.52,15.08],[2,1.48,5]],"ltp":1.5,"tv":274.98,"id":19587555}]}]}
{"op":"mcm","clk":"11981452696","pt":1724852049065,"mc":[{"id":"1.232375043","rc":[{"batb":[[0,1.63,5],[1,1.62,4.19],[2,1.52,15.08]],"batl":[[0,2.2,10.97],[1,2.2,0]],"ltp":1.5,"tv":274.98,"id":19587555}]}]}
{"op":"mcm","clk":"11981452880","pt":1724852052663,"mc":[{"id":"1.232375043","rc":[{"batb":[[0,1.62,4.19],[1,1.52,15.08],[2,1.48,5]],"ltp":1.5,"tv":274.98,"id":19587555}]}]}
{"op":"mcm","clk":"11981453817","pt":1724852070408,"mc":[{"id":"1.232375043","rc":[{"batb":[[0,1.63,5],[1,1.62,4.19],[2,1.52,15.08]],"ltp":1.5,"tv":274.98,"id":19587555}]}]}
{"op":"mcm","clk":"11981454114","pt":1724852074218,"mc":[{"id":"1.232375043","rc":[{"batb":[[0,1.62,4.19],[1,1.52,15.08],[2,1.48,5]],"ltp":1.5,"tv":274.98,"id":19587555}]}]}
{"op":"mcm","clk":"11981455145","pt":1724852091838,"mc":[{"id":"1.232375043","rc":[{"batb":[[0,1.63,5],[1,1.62,4.19],[2,1.52,15.08]],"ltp":1.5,"tv":274.98,"id":19587555}]}]}
{"op":"mcm","clk":"11981455380","pt":1724852095731,"mc":[{"id":"1.232375043","rc":[{"batb":[[0,1.62,4.19],[1,1.52,15.08],[2,1.48,5]],"ltp":1.5,"tv":274.98,"id":19587555}]}]}
{"op":"mcm","clk":"11981457234","pt":1724852127579,"mc":[{"id":"1.232375043","rc":[{"batb":[[0,1.63,5],[1,1.62,4.19],[2,1.52,15.08]],"ltp":1.5,"tv":274.98,"id":19587555}]}]}
{"op":"mcm","clk":"11981457437","pt":1724852131460,"mc":[{"id":"1.232375043","rc":[{"batb":[[0,1.62,4.19],[1,1.52,15.08],[2,1.48,5]],"ltp":1.5,"tv":274.98,"id":19587555}]}]}
{"op":"mcm","clk":"11981458219","pt":1724852144584,"mc":[{"id":"1.232375043","rc":[{"batb":[[0,1.63,5],[1,1.62,4.19],[2,1.52,15.08]],"ltp":1.5,"tv":274.98,"id":19587555}]}]}
{"op":"mcm","clk":"11981458398","pt":1724852148192,"mc":[{"id":"1.232375043","rc":[{"batb":[[0,1.62,4.19],[1,1.52,15.08],[2,1.48,5]],"ltp":1.5,"tv":274.98,"id":19587555}]}]}
{"op":"mcm","clk":"11981459075","pt":1724852160120,"mc":[{"id":"1.232375043","rc":[{"batb":[[0,1.63,5],[1,1.62,4.19],[2,1.52,15.08]],"batl":[[0,2.18,1.84],[1,2.2,10.05]],"ltp":1.5,"tv":274.98,"id":19587555}]}]}
{"op":"mcm","clk":"11981459289","pt":1724852163518,"mc":[{"id":"1.232375043","rc":[{"batb":[[0,1.62,4.19],[1,1.52,15.08],[2,1.48,5]],"ltp":1.5,"tv":274.98,"id":19587555}]}]}
{"op":"mcm","clk":"11981460200","pt":1724852182838,"mc":[{"id":"1.232375043","rc":[{"batb":[[0,1.63,5],[1,1.62,4.19],[2,1.52,15.08]],"ltp":1.5,"tv":274.98,"id":19587555}]}]}
{"op":"mcm","clk":"11981460397","pt":1724852186748,"mc":[{"id":"1.232375043","rc":[{"batb":[[0,1.62,4.19],[1,1.52,15.08],[2,1.48,5]],"ltp":1.5,"tv":274.98,"id":19587555}]}]}
{"op":"mcm","clk":"11981460509","pt":1724852189974,"mc":[{"id":"1.232375043","rc":[{"batb":[[0,1.63,5],[1,1.62,4.19],[2,1.52,15.08]],"ltp":1.5,"tv":274.98,"id":19587555}]}]}
{"op":"mcm","clk":"11981460661","pt":1724852193774,"mc":[{"id":"1.232375043","rc":[{"batb":[[0,1.62,4.19],[1,1.52,15.08],[2,1.48,5]],"ltp":1.5,"tv":274.98,"id":19587555}]}]}
{"op":"mcm","clk":"11981461491","pt":1724852211285,"mc":[{"id":"1.232375043","rc":[{"batb":[[0,1.63,5],[1,1.62,4.19],[2,1.52,15.08]],"ltp":1.5,"tv":274.98,"id":19587555}]}]}
{"op":"mcm","clk":"11981461674","pt":1724852215137,"mc":[{"id":"1.232375043","rc":[{"batb":[[0,1.62,4.19],[1,1.52,15.08],[2,1.48,5]],"ltp":1.5,"tv":274.98,"id":19587555}]}]}
{"op":"mcm","clk":"11981462145","pt":1724852224599,"mc":[{"id":"1.232375043","rc":[{"batb":[[0,1.63,5],[1,1.62,4.19],[2,1.52,15.08]],"ltp":1.5,"tv":274.98,"id":19587555}]}]}
{"op":"mcm","clk":"11981462348","pt":1724852228808,"mc":[{"id":"1.232375043","rc":[{"batb":[[0,1.62,4.19],[1,1.52,15.08],[2,1.48,5]],"ltp":1.5,"tv":274.98,"id":19587555}]}]}
{"op":"mcm","clk":"11981462674","pt":1724852235327,"mc":[{"id":"1.232375043","rc":[{"batb":[[0,1.63,5],[1,1.62,4.19],[2,1.52,15.08]],"ltp":1.5,"tv":274.98,"id":19587555}]}]}
{"op":"mcm","clk":"11981462839","pt":1724852239343,"mc":[{"id":"1.232375043","rc":[{"batb":[[0,1.62,4.19],[1,1.52,15.08],[2,1.48,5]],"ltp":1.5,"tv":274.98,"id":19587555}]}]}
{"op":"mcm","clk":"11981462958","pt":1724852241752,"mc":[{"id":"1.232375043","rc":[{"batb":[[0,1.63,5],[1,1.62,4.19],[2,1.52,15.08]],"ltp":1.5,"tv":274.98,"id":19587555}]}]}
{"op":"mcm","clk":"11981463092","pt":1724852244120,"mc":[{"id":"1.232375043","rc":[{"batb":[[0,1.63,5.74]],"ltp":1.5,"tv":274.98,"id":19587555}]}]}
{"op":"mcm","clk":"11981463184","pt":1724852245756,"mc":[{"id":"1.232375043","rc":[{"batb":[[0,1.62,4.93],[1,1.52,15.08],[2,1.48,5]],"ltp":1.5,"tv":274.98,"id":19587555}]}]}
{"op":"mcm","clk":"11981464898","pt":1724852278588,"mc":[{"id":"1.232375043","rc":[{"batb":[[0,1.63,5.74],[1,1.62,4.19],[2,1.52,15.08]],"ltp":1.5,"tv":274.98,"id":19587555}]}]}
{"op":"mcm","clk":"11981465104","pt":1724852282187,"mc":[{"id":"1.232375043","rc":[{"batb":[[0,1.62,4.93],[1,1.52,15.08],[2,1.48,5]],"ltp":1.5,"tv":274.98,"id":19587555}]}]}
{"op":"mcm","clk":"11981465431","pt":1724852287898,"mc":[{"id":"1.232375043","rc":[{"batb":[[0,1.63,5.74],[1,1.62,4.19],[2,1.52,15.08]],"ltp":1.5,"tv":274.98,"id":19587555}]}]}
{"op":"mcm","clk":"11981465618","pt":1724852291378,"mc":[{"id":"1.232375043","rc":[{"batb":[[0,1.62,4.93],[1,1.52,15.08],[2,1.48,5]],"ltp":1.5,"tv":274.98,"id":19587555}]}]}
{"op":"mcm","clk":"11981466367","pt":1724852304827,"mc":[{"id":"1.232375043","rc":[{"batb":[[0,1.63,5.74],[1,1.62,4.19],[2,1.52,15.08]],"batl":[[0,2.2,10.97],[1,2.2,0]],"ltp":1.5,"tv":274.98,"id":19587555}]}]}
{"op":"mcm","clk":"11981466543","pt":1724852308336,"mc":[{"id":"1.232375043","rc":[{"batb":[[0,1.62,4.93],[1,1.52,15.08],[2,1.48,5]],"ltp":1.5,"tv":274.98,"id":19587555}]}]}
{"op":"mcm","clk":"11981467333","pt":1724852323224,"mc":[{"id":"1.232375043","rc":[{"batb":[[0,1.63,5.74],[1,1.62,4.19],[2,1.52,15.08]],"ltp":1.5,"tv":274.98,"id":19587555}]}]}
{"op":"mcm","clk":"11981467506","pt":1724852326851,"mc":[{"id":"1.232375043","rc":[{"batb":[[0,1.62,4.93],[1,1.52,15.08],[2,1.48,5]],"ltp":1.5,"tv":274.98,"id":19587555}]}]}
{"op":"mcm","clk":"11981467692","pt":1724852331074,"mc":[{"id":"1.232375043","rc":[{"batb":[[0,1.63,5.74],[1,1.62,4.19],[2,1.52,15.08]],"ltp":1.5,"tv":274.98,"id":19587555}]}]}
{"op":"mcm","clk":"11981467885","pt":1724852334875,"mc":[{"id":"1.232375043","rc":[{"batb":[[0,1.62,4.93],[1,1.52,15.08],[2,1.48,5]],"ltp":1.5,"tv":274.98,"id":19587555}]}]}
{"op":"mcm","clk":"11981468014","pt":1724852337682,"mc":[{"id":"1.232375043","rc":[{"batb":[[0,1.63,5.74],[1,1.62,4.19],[2,1.52,15.08]],"ltp":1.5,"tv":274.98,"id":19587555}]}]}
{"op":"mcm","clk":"11981468184","pt":1724852341276,"mc":[{"id":"1.232375043","rc":[{"batb":[[0,1.62,4.93],[1,1.52,15.08],[2,1.48,5]],"ltp":1.5,"tv":274.98,"id":19587555}]}]}
{"op":"mcm","clk":"11981469453","pt":1724852363206,"mc":[{"id":"1.232375043","rc":[{"batb":[[0,1.63,5.74],[1,1.62,4.19],[2,1.52,15.08]],"ltp":1.5,"tv":274.98,"id":19587555}]}]}
{"op":"mcm","clk":"11981469659","pt":1724852367216,"mc":[{"id":"1.232375043","rc":[{"batb":[[0,1.62,4.93],[1,1.52,15.08],[2,1.48,5]],"ltp":1.5,"tv":274.98,"id":19587555}]}]}
{"op":"mcm","clk":"11981469960","pt":1724852373503,"mc":[{"id":"1.232375043","rc":[{"batb":[[0,1.63,5.74],[1,1.62,4.19],[2,1.52,15.08]],"ltp":1.5,"tv":274.98,"id":19587555}]}]}
{"op":"mcm","clk":"11981470161","pt":1724852377207,"mc":[{"id":"1.232375043","rc":[{"batb":[[0,1.62,4.93],[1,1.52,15.08],[2,1.48,5]],"ltp":1.5,"tv":274.98,"id":19587555}]}]}
{"op":"mcm","clk":"11981471327","pt":1724852398432,"mc":[{"id":"1.232375043","rc":[{"batb":[[0,1.63,5.74],[1,1.62,4.19],[2,1.52,15.08]],"ltp":1.5,"tv":274.98,"id":19587555}]}]}
{"op":"mcm","clk":"11981471589","pt":1724852402251,"mc":[{"id":"1.232375043","rc":[{"batb":[[0,1.62,4.93],[1,1.52,15.08],[2,1.48,5]],"ltp":1.5,"tv":274.98,"id":19587555}]}]}
{"op":"mcm","clk":"11981471632","pt":1724852403035,"mc":[{"id":"1.232375043","rc":[{"batb":[[0,1.62,137.28]],"ltp":1.5,"tv":274.98,"id":19587555}]}]}
{"op":"mcm","clk":"11981473020","pt":1724852426457,"mc":[{"id":"1.232375043","rc":[{"batb":[[0,1.63,5.74],[1,1.62,136.54],[2,1.52,15.08]],"ltp":1.5,"tv":274.98,"id":19587555}]}]}
{"op":"mcm","clk":"11981473180","pt":1724852430160,"mc":[{"id":"1.232375043","rc":[{"batb":[[0,1.62,137.28],[1,1.52,15.08],[2,1.48,5]],"ltp":1.5,"tv":274.98,"id":19587555}]}]}
{"op":"mcm","clk":"11981473523","pt":1724852436294,"mc":[{"id":"1.232375043","rc":[{"batb":[[0,1.63,5.74],[1,1.62,136.54],[2,1.52,15.08]],"ltp":1.5,"tv":274.98,"id":19587555}]}]}
{"op":"mcm","clk":"11981473715","pt":1724852440006,"mc":[{"id":"1.232375043","rc":[{"batb":[[0,1.62,137.28],[1,1.52,15.08],[2,1.48,5]],"ltp":1.5,"tv":274.98,"id":19587555}]}]}
{"op":"mcm","clk":"11981474381","pt":1724852452208,"mc":[{"id":"1.232375043","rc":[{"batl":[[0,1.91,4.19],[1,2.2,10.97]],"ltp":1.5,"tv":274.98,"id":19587555}]}]}
{"op":"mcm","clk":"11981474673","pt":1724852457412,"mc":[{"id":"1.232375043","rc":[{"batb":[[1,1.48,5],[2,1.46,18.39]],"ltp":1.5,"tv":274.98,"id":19587555}]}]}
{"op":"mcm","clk":"11981475286","pt":1724852468936,"mc":[{"id":"1.232375043","rc":[{"batb":[[0,1.63,10.79],[1,1.62,136.54],[2,1.48,5]],"ltp":1.5,"tv":274.98,"id":19587555}]}]}
{"op":"mcm","clk":"11981475550","pt":1724852473218,"mc":[{"id":"1.232375043","rc":[{"batl":[[0,1.91,5.03]],"ltp":1.5,"tv":274.98,"id":19587555}]}]}
{"op":"mcm","clk":"11981476071","pt":1724852483248,"mc":[{"id":"1.232375043","rc":[{"batb":[[0,1.62,13.72],[1,1.48,5],[2,1.46,18.39]],"ltp":1.5,"tv":274.98,"id":19587555}]}]}
{"op":"mcm","clk":"11981477622","pt":1724852512196,"mc":[{"id":"1.232375043","rc":[{"batl":[[0,1.9,9.47],[1,1.91,4.19],[2,2.2,10.97]],"ltp":1.5,"tv":274.98,"id":19587555}]}]}
{"op":"mcm","clk":"11981479420","pt":1724852540889,"mc":[{"id":"1.232375043","rc":[{"batb":[[0,1.62,14.13]],"ltp":1.5,"tv":274.98,"id":19587555}]}]}
{"op":"mcm","clk":"11981480078","pt":1724852552507,"mc":[{"id":"1.232375043","rc":[{"batb":[[0,1.5,1.19],[1,1.48,4.22]],"ltp":1.5,"tv":274.98,"id":19587555}]}]}
{"op":"mcm","clk":"11981480266","pt":1724852555742,"mc":[{"id":"1.232375043","rc":[{"batb":[[0,1.8,1.68],[1,1.74,2.88]],"ltp":1.52,"tv":272.24,"id":25651861}]}]}
{"op":"mcm","clk":"11981481473","pt":1724852576271,"mc":[{"id":"1.232375043","rc":[{"batl":[[0,1.75,3.93],[1,1.9,9.47],[2,1.91,4.19]],"ltp":1.5,"tv":274.98,"id":19587555}]}]}
{"op":"mcm","clk":"11981482632","pt":1724852595872,"mc":[{"id":"1.232375043","rc":[{"batb":[[2,1.51,4.4]],"ltp":1.52,"tv":272.24,"id":25651861},{"batb":[[2,1.37,7.57]],"batl":[[0,1.74,4.19],[1,1.75,3.93],[2,1.9,9.47]],"ltp":1.5,"tv":274.98,"id":19587555}]}]}
{"op":"mcm","clk":"11981491050","pt":1724852752556,"mc":[{"id":"1.232375043","rc":[{"batb":[[0,1.51,12.14],[1,1.48,5]],"ltp":1.5,"tv":274.98,"id":19587555}]}]}
{"op":"mcm","clk":"11981495037","pt":1724852817426,"mc":[{"id":"1.232375043","rc":[{"batb":[[0,1.52,7.12],[1,1.51,11.73],[2,1.48,5]],"ltp":1.5,"tv":274.98,"id":19587555}]}]}
{"op":"mcm","clk":"11981500092","pt":1724852896044,"mc":[{"id":"1.232375043","rc":[{"batl":[[0,1.75,3.93],[1,1.9,9.47],[2,2.2,10.97]],"ltp":1.5,"tv":274.98,"id":19587555}]}]}
{"op":"mcm","clk":"11981500502","pt":1724852904366,"mc":[{"id":"1.232375043","rc":[{"batb":[[0,1.52,7.38]],"batl":[[0,1.9,9.47],[1,2.2,10.97],[2,2.2,0]],"ltp":1.5,"tv":274.98,"id":19587555}]}]}
{"op":"mcm","clk":"11981501774","pt":1724852927133,"mc":[{"id":"1.232375043","rc":[{"batl":[[1,1.98,0.92]],"ltp":1.5,"tv":274.98,"id":19587555}]}]}
{"op":"mcm","clk":"11981503279","pt":1724852950231,"mc":[{"id":"1.232375043","rc":[{"batl":[[0,1.98,1.76],[1,1.98,0]],"ltp":1.5,"tv":274.98,"id":19587555}]}]}
{"op":"mcm","clk":"11981504406","pt":1724852969851,"mc":[{"id":"1.232375043","rc":[{"batl":[[0,1.94,5.53],[1,1.98,0.92]],"ltp":1.5,"tv":274.98,"id":19587555}]}]}
{"op":"mcm","clk":"11981514291","pt":1724853131549,"mc":[{"id":"1.232375043","rc":[{"batb":[[2,1.37,8.35]],"ltp":1.5,"tv":274.98,"id":19587555}]}]}
{"op":"mcm","clk":"11981515384","pt":1724853149079,"mc":[{"id":"1.232375043","rc":[{"batb":[[2,1.37,7.57]],"ltp":1.5,"tv":274.98,"id":19587555}]}]}
{"op":"mcm","clk":"11981516560","pt":1724853167214,"mc":[{"id":"1.232375043","rc":[{"batl":[[1,2.18,123.64]],"ltp":1.5,"tv":274.98,"id":19587555}]}]}
{"op":"mcm","clk":"11981516594","pt":1724853167896,"mc":[{"id":"1.232375043","rc":[{"batb":[[0,1.85,12.28],[1,1.74,3.72]],"ltp":1.52,"tv":272.24,"id":25651861},{"batl":[[1,2.16,10.68],[2,2.18,122.72]],"ltp":1.5,"tv":274.98,"id":19587555}]}]}
{"op":"mcm","clk":"11981516819","pt":1724853171694,"mc":[{"id":"1.232375043","rc":[{"batb":[[0,1.8,1.68],[1,1.74,2.88]],"ltp":1.52,"tv":272.24,"id":25651861}]}]}
{"op":"mcm","clk":"11981516914","pt":1724853173393,"mc":[{"id":"1.232375043","rc":[{"batl":[[1,2.16,16.74]],"ltp":1.5,"tv":274.98,"id":19587555}]}]}
{"op":"mcm","clk":"11981517139","pt":1724853177212,"mc":[{"id":"1.232375043","rc":[{"batl":[[1,2.16,139.46],[2,2.18,0]],"ltp":1.5,"tv":274.98,"id":19587555}]}]}
{"op":"mcm","clk":"11981522310","pt":1724853260511,"mc":[{"id":"1.232375043","rc":[{"batb":[[0,1.54,17.43],[1,1.52,6.71],[2,1.51,11.73]],"ltp":1.5,"tv":274.98,"id":19587555}]}]}
{"op":"mcm","clk":"11981523259","pt":1724853276843,"mc":[{"id":"1.232375043","rc":[{"batb":[[1,1.51,11.73],[2,1.37,7.57]],"ltp":1.5,"tv":274.98,"id":19587555}]}]}
{"op":"mcm","clk":"11981523845","pt":1724853286267,"mc":[{"id":"1.232375043","rc":[{"batb":[[0,1.55,7.38],[1,1.54,16.76],[2,1.51,11.73]],"ltp":1.5,"tv":274.98,"id":19587555}]}]}
{"op":"mcm","clk":"11981526736","pt":1724853335225,"mc":[{"id":"1.232375043","rc":[{"batb":[[0,1.64,1.01],[1,1.55,6.71],[2,1.54,16.76]],"batl":[[0,2.16,139.46],[1,2.16,0]],"ltp":1.5,"tv":274.98,"id":19587555}]}]}
{"op":"mcm","clk":"11981527518","pt":1724853347852,"mc":[{"id":"1.232375043","rc":[{"trd":[[2.16,31.64]],"batl":[[0,2.16,16.74]],"ltp":2.16,"tv":306.62,"id":19587555}],"tv":578.86}]}
{"op":"mcm","clk":"11981527624","pt":1724853349342,"mc":[{"id":"1.232375043","rc":[{"batb":[[1,1.55,20.31]],"ltp":2.16,"tv":306.62,"id":19587555}]}]}
{"op":"mcm","clk":"11981527741","pt":1724853351405,"mc":[{"id":"1.232375043","rc":[{"batb":[[1,1.56,8.39],[2,1.55,20.31]],"ltp":2.16,"tv":306.62,"id":19587555}]}]}
{"op":"mcm","clk":"11981528303","pt":1724853360048,"mc":[{"id":"1.232375043","rc":[{"batl":[[0,2.14,6.71],[1,2.16,16.74]],"ltp":2.16,"tv":306.62,"id":19587555}]}]}
{"op":"mcm","clk":"11981530246","pt":1724853389496,"mc":[{"id":"1.232375043","rc":[{"batl":[[1,2.16,0]],"ltp":2.16,"tv":306.62,"id":19587555}]}]}
{"op":"mcm","clk":"11981531764","pt":1724853410798,"mc":[{"id":"1.232375043","rc":[{"batb":[[0,1.88,8.38],[1,1.8,1.68],[2,1.74,2.88]],"ltp":1.52,"tv":272.24,"id":25651861}]}]}
{"op":"mcm","clk":"11981533015","pt":1724853430111,"mc":[{"id":"1.232375043","rc":[{"batb":[[0,1.88,9.22],[1,1.74,3.72],[2,1.51,4.4]],"ltp":1.52,"tv":272.24,"id":25651861}]}]}
{"op":"mcm","clk":"11981536331","pt":1724853482368,"mc":[{"id":"1.232375043","rc":[{"batb":[[0,1.57,5.41]],"ltp":2.16,"tv":306.62,"id":19587555}]}]}
{"op":"mcm","clk":"11981536561","pt":1724853485774,"mc":[{"id":"1.232375043","rc":[{"batb":[[0,1.56,8.8],[1,1.55,20.31],[2,1.54,16.76]],"ltp":2.16,"tv":306.62,"id":19587555}]}]}
{"op":"mcm","clk":"11981539815","pt":1724853537488,"mc":[{"id":"1.232375043","rc":[{"batb":[[0,1.64,1.33],[1,1.56,8.39],[2,1.55,20.31]],"ltp":2.16,"tv":306.62,"id":19587555}]}]}
{"op":"mcm","clk":"11981554635","pt":1724853765429,"mc":[{"id":"1.232375043","rc":[{"trd":[[1.52,272.43]],"batb":[[2,1.51,4.4]],"ltp":1.52,"tv":272.43,"id":25651861},{"trd":[[1.5,275.15],[2.16,31.66]],"batb":[[1,1.56,127.77],[2,1.55,20.32]],"ltp":2.16,"tv":306.83,"id":19587555}],"tv":579.26}]}
{"op":"mcm","clk":"11981554777","pt":1724853767151,"mc":[{"id":"1.232375043","rc":[{"batb":[[1,1.57,13.44],[2,1.56,127.77]],"ltp":2.16,"tv":306.83,"id":19587555}]}]}
{"op":"mcm","clk":"11981556857","pt":1724853795383,"mc":[{"id":"1.232375043","rc":[{"batb":[[1,1.57,132.81],[2,1.56,8.4]],"ltp":2.16,"tv":306.83,"id":19587555}]}]}
{"op":"mcm","clk":"11981556924","pt":1724853796467,"mc":[{"id":"1.232375043","rc":[{"batb":[[2,1.55,6.71]],"ltp":2.16,"tv":306.83,"id":19587555}]}]}
{"op":"mcm","clk":"11981556931","pt":1724853796577,"mc":[{"id":"1.232375043","rc":[{"batb":[[1,1.58,8.29],[2,1.57,132.81]],"ltp":2.16,"tv":306.83,"id":19587555}]}]}
{"op":"mcm","clk":"11981557366","pt":1724853803204,"mc":[{"id":"1.232375043","rc":[{"batl":[[0,2.14,7.55]],"ltp":2.16,"tv":306.83,"id":19587555}]}]}
{"op":"mcm","clk":"11981557810","pt":1724853809392,"mc":[{"id":"1.232375043","rc":[{"batb":[[1,1.58,127.66],[2,1.55,6.71]],"ltp":2.16,"tv":306.83,"id":19587555}]}]}
{"op":"mcm","clk":"11981557825","pt":1724853809597,"mc":[{"id":"1.232375043","rc":[{"batb":[[1,1.59,13.27],[2,1.58,127.66]],"ltp":2.16,"tv":306.83,"id":19587555}]}]}
{"op":"mcm","clk":"11981558640","pt":1724853824790,"mc":[{"id":"1.232375043","rc":[{"batb":[[1,1.59,132.64],[2,1.58,8.29]],"ltp":2.16,"tv":306.83,"id":19587555}]}]}
{"op":"mcm","clk":"11981558840","pt":1724853827451,"mc":[{"id":"1.232375043","rc":[{"batb":[[0,1.92,1.53],[1,1.88,8.38],[2,1.74,3.72]],"ltp":1.52,"tv":272.43,"id":25651861},{"batb":[[2,1.55,6.71]],"ltp":2.16,"tv":306.83,"id":19587555}]}]}
{"op":"mcm","clk":"11981558850","pt":1724853827544,"mc":[{"id":"1.232375043","rc":[{"batb":[[1,1.6,8.19],[2,1.59,132.64]],"ltp":2.16,"tv":306.83,"id":19587555}]}]}
{"op":"mcm","clk":"11981561264","pt":1724853865675,"mc":[{"id":"1.232375043","rc":[{"batb":[[1,1.6,127.56],[2,1.59,13.27]],"ltp":2.16,"tv":306.83,"id":19587555}]}]}
{"op":"mcm","clk":"11981561375","pt":1724853867485,"mc":[{"id":"1.232375043","rc":[{"batb":[[2,1.55,6.71]],"ltp":2.16,"tv":306.83,"id":19587555}]}]}
{"op":"mcm","clk":"11981561429","pt":1724853867641,"mc":[{"id":"1.232375043","rc":[{"batb":[[1,1.61,13.1],[2,1.6,127.56]],"ltp":2.16,"tv":306.83,"id":19587555}]}]}
{"op":"mcm","clk":"11981561933","pt":1724853876591,"mc":[{"id":"1.232375043","rc":[{"batl":[[0,2.04,5.86],[1,2.14,6.71]],"ltp":2.16,"tv":306.83,"id":19587555}]}]}
{"op":"mcm","clk":"11981562263","pt":1724853883077,"mc":[{"id":"1.232375043","rc":[{"batb":[[1,1.61,132.47],[2,1.6,8.19]],"ltp":2.16,"tv":306.83,"id":19587555}]}]}
{"op":"mcm","clk":"11981562303","pt":1724853883696,"mc":[{"id":"1.232375043","rc":[{"batb":[[1,1.62,8.09],[2,1.61,132.47]],"ltp":2.16,"tv":306.83,"id":19587555}]}]}
{"op":"mcm","clk":"11981563100","pt":1724853896483,"mc":[{"id":"1.232375043","rc":[{"batb":[[2,1.61,13.1]],"ltp":2.16,"tv":306.83,"id":19587555}]}]}
{"op":"mcm","clk":"11981563117","pt":1724853896800,"mc":[{"id":"1.232375043","rc":[{"batb":[[0,1.65,5.92],[1,1.64,119.78],[2,1.62,8.09]],"ltp":2.16,"tv":306.83,"id":19587555}]}]}
{"op":"mcm","clk":"11981563168","pt":1724853897719,"mc":[{"id":"1.232375043","rc":[{"batb":[[2,1.61,13.1]],"ltp":2.16,"tv":306.83,"id":19587555}]}]}
{"op":"mcm","clk":"11981563238","pt":1724853899019,"mc":[{"id":"1.232375043","rc":[{"batb":[[0,1.65,18.71],[2,1.55,6.71]],"ltp":2.16,"tv":306.83,"id":19587555}]}]}
{"op":"mcm","clk":"11981563322","pt":1724853900204,"mc":[{"id":"1.232375043","rc":[{"batb":[[0,1.65,13.71]],"ltp":2.16,"tv":306.83,"id":19587555}]}]}
{"op":"mcm","clk":"11981563884","pt":1724853908737,"mc":[{"id":"1.232375043","rc":[{"batb":[[0,1.66,5.92],[1,1.65,20.74],[2,1.64,119.78]],"ltp":2.16,"tv":306.83,"id":19587555}]}]}
{"op":"mcm","clk":"11981564113","pt":1724853912016,"mc":[{"id":"1.232375043","rc":[{"batb":[[0,1.65,21.66],[1,1.64,119.78],[2,1.55,6.71]],"ltp":2.16,"tv":306.83,"id":19587555}]}]}
{"op":"mcm","clk":"11981564890","pt":1724853925237,"mc":[{"id":"1.232375043","rc":[{"batb":[[0,1.66,5.92],[1,1.65,20.74],[2,1.64,119.78]],"batl":[[1,2.08,3.35],[2,2.14,6.71]],"ltp":2.16,"tv":306.83,"id":19587555}]}]}
{"op":"mcm","clk":"11981565033","pt":1724853928271,"mc":[{"id":"1.232375043","rc":[{"batb":[[2,1.55,7.12]],"ltp":2.16,"tv":306.83,"id":19587555}]}]}
{"op":"mcm","clk":"11981565088","pt":1724853929356,"mc":[{"id":"1.232375043","rc":[{"batb":[[0,1.65,8.87],[1,1.55,7.12],[2,1.54,16.76]],"ltp":2.16,"tv":306.83,"id":19587555}]}]}
{"op":"mcm","clk":"11981565157","pt":1724853930443,"mc":[{"id":"1.232375043","rc":[{"batb":[[0,1.64,1.33],[1,1.55,6.71]],"ltp":2.16,"tv":306.83,"id":19587555}]}]}
{"op":"mcm","clk":"11981565292","pt":1724853932447,"mc":[{"id":"1.232375043","rc":[{"batb":[[1,1.56,8.4],[2,1.55,20.32]],"ltp":2.16,"tv":306.83,"id":19587555}]}]}
{"op":"mcm","clk":"11981601221","pt":1724854394922,"mc":[{"id":"1.232375043","rc":[{"batl":[[0,2,42.68],[1,2.04,5.02],[2,2.08,3.35]],"ltp":2.16,"tv":306.83,"id":19587555}]}]}
{"op":"mcm","clk":"11981603490","pt":1724854439480,"mc":[{"id":"1.232375043","rc":[{"trd":[[1.55,0.78],[1.56,16.81],[1.64,0.82],[1.68,1.84]],"batb":[[0,1.56,5],[1,1.55,19.93],[2,1.54,16.76]],"ltp":1.55,"tv":327.07,"id":19587555}],"tv":599.5}]}
{"op":"mcm","clk":"11981603516","pt":1724854440097,"mc":[{"id":"1.232375043","rc":[{"trd":[[1.56,25.19]],"batb":[[0,1.55,20.74],[1,1.54,16.76],[2,1.51,11.73]],"ltp":1.56,"tv":335.45,"id":19587555}],"tv":607.88}]}
{"op":"mcm","clk":"11981603545","pt":1724854441080,"mc":[{"id":"1.232375043","rc":[{"trd":[[1.55,6.13],[1.56,26.81]],"batb":[[0,1.55,17.25]],"ltp":1.55,"tv":342.43,"id":19587555}],"tv":614.86}]}
{"op":"mcm","clk":"11981603589","pt":1724854442067,"mc":[{"id":"1.232375043","rc":[{"trd":[[1.55,11.94]],"batb":[[0,1.55,14.35]],"ltp":1.55,"tv":348.23,"id":19587555}],"tv":620.66}]}
{"op":"mcm","clk":"11981603652","pt":1724854443368,"mc":[{"id":"1.232375043","rc":[{"trd":[[1.55,16.77]],"batb":[[0,1.56,5],[1,1.55,11.94],[2,1.54,16.76]],"ltp":1.55,"tv":353.06,"id":19587555}],"tv":625.49}]}
{"op":"mcm","clk":"11981603708","pt":1724854444188,"mc":[{"id":"1.232375043","rc":[{"trd":[[1.56,32.5]],"batb":[[0,1.56,2.15]],"ltp":1.56,"tv":358.76,"id":19587555}],"tv":631.19}]}
{"op":"mcm","clk":"11981603745","pt":1724854445187,"mc":[{"id":"1.232375043","rc":[{"trd":[[1.55,17.21],[1.56,36.8]],"batb":[[0,1.55,11.72],[1,1.54,16.76],[2,1.51,11.73]],"ltp":1.55,"tv":363.49,"id":19587555}],"tv":635.93}]}
{"op":"mcm","clk":"11981603788","pt":1724854446010,"mc":[{"id":"1.232375043","rc":[{"batb":[[0,1.54,16.76],[1,1.52,11.95]],"ltp":1.55,"tv":363.49,"id":19587555}]}]}
{"op":"mcm","clk":"11981604553","pt":1724854460502,"mc":[{"id":"1.232375043","rc":[{"trd":[[1.54,19.33],[1.55,25.31]],"batb":[[0,1.54,8.05]],"ltp":1.55,"tv":390.92,"id":19587555}],"tv":663.35}]}
{"op":"mcm","clk":"11981604613","pt":1724854461486,"mc":[{"id":"1.232375043","rc":[{"trd":[[1.54,24.16],[1.55,27.21]],"batb":[[0,1.54,4.68]],"ltp":1.54,"tv":397.66,"id":19587555}],"tv":670.09}]}
{"op":"mcm","clk":"11981604654","pt":1724854462505,"mc":[{"id":"1.232375043","rc":[{"trd":[[1.54,29.76]],"batb":[[0,1.54,1.88],[1,1.51,11.73],[2,1.37,7.57]],"ltp":1.54,"tv":403.25,"id":19587555}],"tv":675.68}]}
{"op":"mcm","clk":"11981604710","pt":1724854463804,"mc":[{"id":"1.232375043","rc":[{"trd":[[1.54,31.61]],"batb":[[0,1.52,5.95]],"ltp":1.54,"tv":405.11,"id":19587555}],"tv":677.54}]}
{"op":"mcm","clk":"11981604750","pt":1724854464622,"mc":[{"id":"1.232375043","rc":[{"trd":[[1.52,0.1],[1.54,33.52]],"batb":[[0,1.52,4.95]],"ltp":1.52,"tv":407.11,"id":19587555}],"tv":679.54}]}
{"op":"mcm","clk":"11981604808","pt":1724854465617,"mc":[{"id":"1.232375043","rc":[{"trd":[[1.52,1.96]],"batb":[[0,1.52,4.02]],"ltp":1.52,"tv":408.97,"id":19587555}],"tv":681.4}]}
{"op":"mcm","clk":"11981604890","pt":1724854467204,"mc":[{"id":"1.232375043","rc":[{"trd":[[1.52,3.81]],"batb":[[0,1.51,11.73],[1,1.37,7.57],[2,1.2,250]],"ltp":1.52,"tv":410.82,"id":19587555}],"tv":683.25}]}
{"op":"mcm","clk":"11981605589","pt":1724854480644,"mc":[{"id":"1.232375043","rc":[{"batl":[[0,1.98,1.76],[1,2,41.84],[2,2.04,5.02]],"ltp":1.52,"tv":410.82,"id":19587555}]}]}
{"op":"mcm","clk":"11981606447","pt":1724854495355,"mc":[{"id":"1.232375043","rc":[{"batb":[[0,1.51,12.32]],"ltp":1.52,"tv":410.82,"id":19587555}]}]}
{"op":"mcm","clk":"11981607532","pt":1724854513078,"mc":[{"id":"1.232375043","rc":[{"batb":[[0,1.52,119.96],[1,1.51,11.73],[2,1.37,7.57]],"ltp":1.52,"tv":410.82,"id":19587555}]}]}
{"op":"mcm","clk":"11981607656","pt":1724854515384,"mc":[{"id":"1.232375043","rc":[{"batb":[[0,1.53,12.46],[1,1.52,119.37],[2,1.51,11.73]],"ltp":1.52,"tv":410.82,"id":19587555}]}]}
{"op":"mcm","clk":"11981610986","pt":1724854564958,"mc":[{"id":"1.232375043","rc":[{"batb":[[0,1.55,13.15],[1,1.53,11.87],[2,1.52,119.37]],"ltp":1.52,"tv":410.82,"id":19587555}]}]}
{"op":"mcm","clk":"11981615343","pt":1724854628141,"mc":[{"id":"1.232375043","rc":[{"batb":[[2,1.51,11.73]],"ltp":1.52,"tv":410.82,"id":19587555}]}]}
{"op":"mcm","clk":"11981615400","pt":1724854628926,"mc":[{"id":"1.232375043","rc":[{"batb":[[1,1.51,11.73],[2,1.37,7.57]],"ltp":1.52,"tv":410.82,"id":19587555}]}]}
{"op":"mcm","clk":"11981617912","pt":1724854665272,"mc":[{"id":"1.232375043","rc":[{"batb":[[0,1.57,12.16],[1,1.56,119.37],[2,1.55,12.56]],"ltp":1.52,"tv":410.82,"id":19587555}]}]}
{"op":"mcm","clk":"11981619064","pt":1724854681484,"mc":[{"id":"1.232375043","rc":[{"batl":[[0,1.72,4.19],[1,1.98,1.76],[2,2,41.84]],"ltp":1.52,"tv":410.82,"id":19587555}]}]}
{"op":"mcm","clk":"11981621351","pt":1724854713901,"mc":[{"id":"1.232375043","rc":[{"batb":[[0,1.64,1.01],[1,1.57,12.16],[2,1.56,119.37]],"ltp":1.52,"tv":410.82,"id":19587555}]}]}
{"op":"mcm","clk":"11981621782","pt":1724854720316,"mc":[{"id":"1.232375043","rc":[{"batb":[[1,1.57,11.57]],"ltp":1.52,"tv":410.82,"id":19587555}]}]}
{"op":"mcm","clk":"11981622066","pt":1724854724648,"mc":[{"id":"1.232375043","rc":[{"batb":[[2,1.55,12.56]],"ltp":1.52,"tv":410.82,"id":19587555}]}]}
{"op":"mcm","clk":"11981622210","pt":1724854726724,"mc":[{"id":"1.232375043","rc":[{"batb":[[1,1.55,12.56],[2,1.51,11.73]],"ltp":1.52,"tv":410.82,"id":19587555}]}]}
{"op":"mcm","clk":"11981622524","pt":1724854731229,"mc":[{"id":"1.232375043","rc":[{"batb":[[0,1.55,12.56],[1,1.51,11.73],[2,1.44,2.09]],"batl":[[0,1.64,3.18],[1,1.72,4.19],[2,1.98,1.76]],"ltp":1.52,"tv":410.82,"id":19587555}]}]}
{"op":"mcm","clk":"11981623419","pt":1724854744667,"mc":[{"id":"1.232375043","rc":[{"batb":[[0,1.64,1.01],[1,1.55,12.56],[2,1.51,11.73]],"batl":[[0,1.72,4.19],[1,1.98,1.76],[2,2,41.84]],"ltp":1.52,"tv":410.82,"id":19587555}]}]}
{"op":"mcm","clk":"11981623875","pt":1724854751959,"mc":[{"id":"1.232375043","rc":[{"batb":[[0,1.55,12.56],[1,1.51,11.73],[2,1.44,2.09]],"ltp":1.52,"tv":410.82,"id":19587555}]}]}
{"op":"mcm","clk":"11981625624","pt":1724854778468,"mc":[{"id":"1.232375043","rc":[{"batb":[[0,1.56,116.43],[1,1.55,12.56],[2,1.51,11.73]],"ltp":1.52,"tv":410.82,"id":19587555}]}]}
{"op":"mcm","clk":"11981625703","pt":1724854779499,"mc":[{"id":"1.232375043","rc":[{"batb":[[0,1.57,11.57],[1,1.56,116.43],[2,1.55,12.56]],"ltp":1.52,"tv":410.82,"id":19587555}]}]}
{"op":"mcm","clk":"11981626243","pt":1724854788783,"mc":[{"id":"1.232375043","rc":[{"batl":[[2,2.04,5.02]],"ltp":1.52,"tv":410.82,"id":19587555}]}]}
{"op":"mcm","clk":"11981629208","pt":1724854834067,"mc":[{"id":"1.232375043","rc":[{"trd":[[1.57,20.78]],"batb":[[0,1.57,1.18]],"ltp":1.57,"tv":431.6,"id":19587555}],"tv":704.03}]}
{"op":"mcm","clk":"11981629381","pt":1724854836749,"mc":[{"id":"1.232375043","rc":[{"batl":[[0,1.71,4.19],[1,1.72,4.19],[2,1.98,1.76]],"ltp":1.57,"tv":431.6,"id":19587555}]}]}
{"op":"mcm","clk":"11981629805","pt":1724854842979,"mc":[{"id":"1.232375043","rc":[{"trd":[[1.57,23.14]],"batb":[[0,1.56,116.43],[1,1.55,12.56],[2,1.51,11.73]],"batl":[[0,1.71,4.27]],"ltp":1.57,"tv":433.96,"id":19587555}],"tv":706.39}]}
{"op":"mcm","clk":"11981630487","pt":1724854852983,"mc":[{"id":"1.232375043","rc":[{"batb":[[0,1.55,12.56],[1,1.51,11.73],[2,1.44,2.09]],"ltp":1.57,"tv":433.96,"id":19587555}]}]}
{"op":"mcm","clk":"11981630873","pt":1724854857980,"mc":[{"id":"1.232375043","rc":[{"batb":[[0,1.51,11.73],[1,1.37,7.57],[2,1.2,250]],"ltp":1.57,"tv":433.96,"id":19587555}]}]}
{"op":"mcm","clk":"11981633423","pt":1724854890060,"mc":[{"id":"1.232375043","rc":[{"batb":[[0,1.51,21.78]],"batl":[[0,1.71,4.19]],"ltp":1.57,"tv":433.96,"id":19587555}]}]}
{"op":"mcm","clk":"11981648613","pt":1724855109346,"mc":[{"id":"1.232375043","rc":[{"batb":[[0,1.88,8.38],[1,1.68,1.72],[2,1.51,3.52]],"ltp":1.52,"tv":272.43,"id":25651861},{"batl":[[2,2.04,5.02]],"ltp":1.57,"tv":433.96,"id":19587555}]}]}
{"op":"mcm","clk":"11981648630","pt":1724855109551,"mc":[{"id":"1.232375043","rc":[{"batb":[[1,1.51,4.4],[2,1.31,4.22]],"ltp":1.52,"tv":272.43,"id":25651861}]}]}
{"op":"mcm","clk":"11981667102","pt":1724855392957,"mc":[{"id":"1.232375043","rc":[{"batl":[[0,1.7,25.13],[1,1.71,4.19],[2,1.72,4.19]],"ltp":1.57,"tv":433.96,"id":19587555}]}]}
{"op":"mcm","clk":"11981671426","pt":1724855444440,"mc":[{"id":"1.232375043","rc":[{"batl":[[0,1.69,2],[1,1.7,25.13],[2,1.71,4.19]],"ltp":1.57,"tv":433.96,"id":19587555}]}]}
{"op":"mcm","clk":"11981675388","pt":1724855491284,"mc":[{"id":"1.232375043","rc":[{"batb":[[0,1.51,4.4],[1,1.31,4.22],[2,1.2,250]],"ltp":1.52,"tv":272.43,"id":25651861}]}]}
{"op":"mcm","clk":"11981675550","pt":1724855493097,"mc":[{"id":"1.232375043","rc":[{"batl":[[0,1.68,1.67],[1,1.69,2],[2,1.7,25.13]],"ltp":1.57,"tv":433.96,"id":19587555}]}]}
{"op":"mcm","clk":"11981675971","pt":1724855498015,"mc":[{"id":"1.232375043","rc":[{"batl":[[2,1.71,4.19]],"ltp":1.57,"tv":433.96,"id":19587555}]}]}
{"op":"mcm","clk":"11981677020","pt":1724855510580,"mc":[{"id":"1.232375043","rc":[{"batl":[[0,1.65,4.19],[1,1.68,1.67],[2,1.69,2]],"ltp":1.57,"tv":433.96,"id":19587555}]}]}
{"op":"mcm","clk":"11981678817","pt":1724855532032,"mc":[{"id":"1.232375043","rc":[{"batb":[[0,1.51,11.73]],"ltp":1.57,"tv":433.96,"id":19587555}]}]}
{"op":"mcm","clk":"11981679608","pt":1724855542441,"mc":[{"id":"1.232375043","rc":[{"batb":[[0,1.37,7.57],[1,1.2,250],[2,1.04,1.05]],"ltp":1.57,"tv":433.96,"id":19587555}]}]}
{"op":"mcm","clk":"11981680529","pt":1724855554864,"mc":[{"id":"1.232375043","rc":[{"batb":[[0,1.42,11.73],[1,1.37,7.57],[2,1.2,250]],"ltp":1.57,"tv":433.96,"id":19587555}]}]}
{"op":"mcm","clk":"11981681685","pt":1724855570974,"mc":[{"id":"1.232375043","rc":[{"batb":[[0,1.42,23.46]],"ltp":1.57,"tv":433.96,"id":19587555}]}]}
{"op":"mcm","clk":"11981696246","pt":1724855734713,"mc":[{"id":"1.232375043","rc":[{"batb":[[0,1.51,3.52]],"ltp":1.52,"tv":272.43,"id":25651861}]}]}
{"op":"mcm","clk":"11981740144","pt":1724856157647,"mc":[{"id":"1.232375043","rc":[{"batl":[[0,1.68,1.67],[1,1.69,2],[2,1.71,4.19]],"ltp":1.57,"tv":433.96,"id":19587555}]}]}
{"op":"mcm","clk":"11981743380","pt":1724856197227,"mc":[{"id":"1.232375043","rc":[{"batl":[[0,1.63,11.73],[1,1.68,1.67],[2,1.69,2]],"ltp":1.57,"tv":433.96,"id":19587555}]}]}
{"op":"mcm","clk":"11981746870","pt":1724856236469,"mc":[{"id":"1.232375043","rc":[{"batb":[[2,1.21,7.17]],"ltp":1.57,"tv":433.96,"id":19587555}]}]}
{"op":"mcm","clk":"11981814039","pt":1724857013694,"mc":[{"id":"1.232375043","rc":[{"batb":[[0,1.31,4.22],[1,1.2,250],[2,1.04,1.05]],"ltp":1.52,"tv":272.43,"id":25651861}]}]}
{"op":"mcm","clk":"11981927019","pt":1724858164865,"mc":[{"id":"1.232375043","rc":[{"trd":[[1.52,272.11]],"batb":[[0,1.31,4.21]],"ltp":1.52,"tv":272.11,"id":25651861},{"trd":[[1.42,46.92],[1.5,274.83],[1.54,33.52],[1.55,27.21],[1.56,36.81],[1.57,23.14],[2.16,31.66]],"batb":[[0,1.37,7.56],[1,1.21,7.16],[2,1.2,250]],"batl":[[0,1.42,26.54],[1,1.63,11.73],[2,1.68,1.67]],"ltp":1.42,"tv":480.59,"id":19587555}],"tv":752.7}]}
{"op":"mcm","clk":"11981928035","pt":1724858172379,"mc":[{"id":"1.232375043","rc":[{"batl":[[0,1.63,11.73],[1,1.68,1.67],[2,1.69,2]],"ltp":1.42,"tv":480.59,"id":19587555}]}]}
{"op":"mcm","clk":"11981949504","pt":1724858358942,"mc":[{"id":"1.232375043","rc":[{"batb":[[0,1.38,16.76],[1,1.37,7.56],[2,1.21,7.16]],"ltp":1.42,"tv":480.59,"id":19587555}]}]}
{"op":"mcm","clk":"11981953129","pt":1724858389376,"mc":[{"id":"1.232375043","rc":[{"batl":[[0,1.61,8.38],[1,1.63,11.73],[2,1.68,1.67]],"ltp":1.42,"tv":480.59,"id":19587555}]}]}
{"op":"mcm","clk":"11981957749","pt":1724858432614,"mc":[{"id":"1.232375043","rc":[{"batb":[[0,1.39,16.76],[1,1.38,16.76],[2,1.37,7.56]],"ltp":1.42,"tv":480.59,"id":19587555}]}]}
{"op":"mcm","clk":"11981959905","pt":1724858456164,"mc":[{"id":"1.232375043","rc":[{"batl":[[1,1.62,10.89],[2,1.63,11.73]],"ltp":1.42,"tv":480.59,"id":19587555}]}]}
{"op":"mcm","clk":"11981960599","pt":1724858462144,"mc":[{"id":"1.232375043","rc":[{"batl":[[1,1.63,11.73],[2,1.68,1.67]],"ltp":1.42,"tv":480.59,"id":19587555}]}]}
{"op":"mcm","clk":"11981961765","pt":1724858472694,"mc":[{"id":"1.232375043","rc":[{"batl":[[1,1.62,8.38],[2,1.63,11.73]],"ltp":1.42,"tv":480.59,"id":19587555}]}]}
{"op":"mcm","clk":"11981991975","pt":1724858807797,"mc":[{"id":"1.232375043","rc":[{"batb":[[0,1.32,9],[1,1.31,4.21],[2,1.2,250]],"batl":[[0,2.7,1]],"ltp":1.52,"tv":272.11,"id":25651861}]}]}
{"op":"mcm","clk":"11981992238","pt":1724858810183,"mc":[{"id":"1.232375043","rc":[{"batb":[[0,1.32,5]],"ltp":1.52,"tv":272.11,"id":25651861}]}]}
{"op":"mcm","clk":"11981992329","pt":1724858811075,"mc":[{"id":"1.232375043","rc":[{"batb":[[0,1.31,4.21],[1,1.2,250],[2,1.04,1.05]],"ltp":1.52,"tv":272.11,"id":25651861}]}]}
{"op":"mcm","clk":"11981992569","pt":1724858813456,"mc":[{"id":"1.232375043","rc":[{"batb":[[0,1.33,5],[1,1.32,4],[2,1.31,4.21]],"batl":[[0,2.82,1]],"ltp":1.52,"tv":272.11,"id":25651861}]}]}
{"op":"mcm","clk":"11981992758","pt":1724858815486,"mc":[{"id":"1.232375043","rc":[{"batb":[[1,1.31,4.21],[2,1.2,250]],"ltp":1.52,"tv":272.11,"id":25651861}]}]}
{"op":"mcm","clk":"11981992899","pt":1724858816888,"mc":[{"id":"1.232375043","rc":[{"batb":[[0,1.31,4.21],[1,1.2,250],[2,1.04,1.05]],"ltp":1.52,"tv":272.11,"id":25651861}]}]}
{"op":"mcm","clk":"11981993045","pt":1724858818382,"mc":[{"id":"1.232375043","rc":[{"batl":[[0,2.96,1]],"ltp":1.52,"tv":272.11,"id":25651861}]}]}
{"op":"mcm","clk":"11981993069","pt":1724858818585,"mc":[{"id":"1.232375043","rc":[{"batb":[[0,1.32,4],[1,1.31,4.21],[2,1.2,250]],"ltp":1.52,"tv":272.11,"id":25651861}]}]}
{"op":"mcm","clk":"11981993283","pt":1724858821021,"mc":[{"id":"1.232375043","rc":[{"batb":[[0,1.32,5]],"ltp":1.52,"tv":272.11,"id":25651861}]}]}
{"op":"mcm","clk":"11981993630","pt":1724858824307,"mc":[{"id":"1.232375043","rc":[{"batb":[[0,1.31,4.21],[1,1.2,250],[2,1.04,1.05]],"ltp":1.52,"tv":272.11,"id":25651861}]}]}
{"op":"mcm","clk":"11981993667","pt":1724858824616,"mc":[{"id":"1.232375043","rc":[{"batb":[[0,1.32,4],[1,1.31,4.21],[2,1.2,250]],"ltp":1.52,"tv":272.11,"id":25651861}]}]}
{"op":"mcm","clk":"11981993954","pt":1724858827129,"mc":[{"id":"1.232375043","rc":[{"batb":[[0,1.32,5]],"ltp":1.52,"tv":272.11,"id":25651861}]}]}
{"op":"mcm","clk":"11981994338","pt":1724858830489,"mc":[{"id":"1.232375043","rc":[{"batb":[[0,1.32,4]],"ltp":1.52,"tv":272.11,"id":25651861}]}]}
{"op":"mcm","clk":"11981994591","pt":1724858833031,"mc":[{"id":"1.232375043","rc":[{"batb":[[0,1.32,5]],"ltp":1.52,"tv":272.11,"id":25651861}]}]}
{"op":"mcm","clk":"11981994938","pt":1724858836408,"mc":[{"id":"1.232375043","rc":[{"batb":[[0,1.31,4.21],[1,1.2,250],[2,1.04,1.05]],"ltp":1.52,"tv":272.11,"id":25651861}]}]}
{"op":"mcm","clk":"11981994962","pt":1724858836616,"mc":[{"id":"1.232375043","rc":[{"batb":[[0,1.32,4],[1,1.31,4.21],[2,1.2,250]],"ltp":1.52,"tv":272.11,"id":25651861}]}]}
{"op":"mcm","clk":"11981995192","pt":1724858839214,"mc":[{"id":"1.232375043","rc":[{"batb":[[0,1.32,5]],"ltp":1.52,"tv":272.11,"id":25651861}]}]}
{"op":"mcm","clk":"11981995483","pt":1724858842425,"mc":[{"id":"1.232375043","rc":[{"batb":[[0,1.31,4.21],[1,1.2,250],[2,1.04,1.05]],"ltp":1.52,"tv":272.11,"id":25651861}]}]}
{"op":"mcm","clk":"11981995507","pt":1724858842632,"mc":[{"id":"1.232375043","rc":[{"batb":[[0,1.32,4],[1,1.31,4.21],[2,1.2,250]],"ltp":1.52,"tv":272.11,"id":25651861}]}]}
{"op":"mcm","clk":"11981995722","pt":1724858845021,"mc":[{"id":"1.232375043","rc":[{"batb":[[0,1.32,5]],"ltp":1.52,"tv":272.11,"id":25651861}]}]}
{"op":"mcm","clk":"11981996071","pt":1724858848746,"mc":[{"id":"1.232375043","rc":[{"batb":[[0,1.32,4]],"ltp":1.52,"tv":272.11,"id":25651861}]}]}
{"op":"mcm","clk":"11981996313","pt":1724858851134,"mc":[{"id":"1.232375043","rc":[{"batb":[[0,1.32,5]],"ltp":1.52,"tv":272.11,"id":25651861}]}]}
{"op":"mcm","clk":"11981996628","pt":1724858854449,"mc":[{"id":"1.232375043","rc":[{"batb":[[0,1.31,4.21],[1,1.2,250],[2,1.04,1.05]],"ltp":1.52,"tv":272.11,"id":25651861}]}]}
{"op":"mcm","clk":"11981996641","pt":1724858854553,"mc":[{"id":"1.232375043","rc":[{"batb":[[0,1.32,4],[1,1.31,4.21],[2,1.2,250]],"ltp":1.52,"tv":272.11,"id":25651861}]}]}
{"op":"mcm","clk":"11981996876","pt":1724858857043,"mc":[{"id":"1.232375043","rc":[{"batb":[[0,1.32,5]],"ltp":1.52,"tv":272.11,"id":25651861}]}]}
{"op":"mcm","clk":"11981997207","pt":1724858860460,"mc":[{"id":"1.232375043","rc":[{"batb":[[0,1.31,4.21],[1,1.2,250],[2,1.04,1.05]],"ltp":1.52,"tv":272.11,"id":25651861}]}]}
{"op":"mcm","clk":"11981997229","pt":1724858860720,"mc":[{"id":"1.232375043","rc":[{"batb":[[0,1.32,4],[1,1.31,4.21],[2,1.2,250]],"ltp":1.52,"tv":272.11,"id":25651861}]}]}
{"op":"mcm","clk":"11981997475","pt":1724858863257,"mc":[{"id":"1.232375043","rc":[{"batb":[[0,1.32,5]],"ltp":1.52,"tv":272.11,"id":25651861}]}]}
{"op":"mcm","clk":"11981997739","pt":1724858866441,"mc":[{"id":"1.232375043","rc":[{"batb":[[0,1.31,4.21],[1,1.2,250],[2,1.04,1.05]],"ltp":1.52,"tv":272.11,"id":25651861}]}]}
{"op":"mcm","clk":"11981997763","pt":1724858866645,"mc":[{"id":"1.232375043","rc":[{"batb":[[0,1.32,4],[1,1.31,4.21],[2,1.2,250]],"ltp":1.52,"tv":272.11,"id":25651861}]}]}
{"op":"mcm","clk":"11981997978","pt":1724858869178,"mc":[{"id":"1.232375043","rc":[{"batb":[[0,1.32,5]],"ltp":1.52,"tv":272.11,"id":25651861}]}]}
{"op":"mcm","clk":"11981998259","pt":1724858872435,"mc":[{"id":"1.232375043","rc":[{"batb":[[0,1.31,4.21],[1,1.2,250],[2,1.04,1.05]],"ltp":1.52,"tv":272.11,"id":25651861}]}]}
{"op":"mcm","clk":"11981998277","pt":1724858872643,"mc":[{"id":"1.232375043","rc":[{"batb":[[0,1.32,4],[1,1.31,4.21],[2,1.2,250]],"ltp":1.52,"tv":272.11,"id":25651861}]}]}
{"op":"mcm","clk":"11981998555","pt":1724858875354,"mc":[{"id":"1.232375043","rc":[{"batb":[[0,1.32,5]],"ltp":1.52,"tv":272.11,"id":25651861}]}]}
{"op":"mcm","clk":"11981998879","pt":1724858878840,"mc":[{"id":"1.232375043","rc":[{"batb":[[0,1.32,4]],"ltp":1.52,"tv":272.11,"id":25651861}]}]}
{"op":"mcm","clk":"11981999104","pt":1724858881380,"mc":[{"id":"1.232375043","rc":[{"batb":[[0,1.32,5]],"ltp":1.52,"tv":272.11,"id":25651861}]}]}
{"op":"mcm","clk":"11981999465","pt":1724858884964,"mc":[{"id":"1.232375043","rc":[{"batb":[[0,1.32,4]],"ltp":1.52,"tv":272.11,"id":25651861}]}]}
{"op":"mcm","clk":"11981999758","pt":1724858887476,"mc":[{"id":"1.232375043","rc":[{"batb":[[0,1.32,5]],"ltp":1.52,"tv":272.11,"id":25651861}]}]}
{"op":"mcm","clk":"11982000117","pt":1724858891065,"mc":[{"id":"1.232375043","rc":[{"batb":[[0,1.32,4]],"ltp":1.52,"tv":272.11,"id":25651861}]}]}
{"op":"mcm","clk":"11982000340","pt":1724858893396,"mc":[{"id":"1.232375043","rc":[{"batb":[[0,1.31,4.21],[1,1.2,250],[2,1.04,1.05]],"ltp":1.52,"tv":272.11,"id":25651861}]}]}
{"op":"mcm","clk":"11982000357","pt":1724858893554,"mc":[{"id":"1.232375043","rc":[{"batb":[[0,1.32,5],[1,1.31,4.21],[2,1.2,250]],"ltp":1.52,"tv":272.11,"id":25651861}]}]}
{"op":"mcm","clk":"11982000697","pt":1724858897180,"mc":[{"id":"1.232375043","rc":[{"batb":[[0,1.32,4]],"ltp":1.52,"tv":272.11,"id":25651861}]}]}
{"op":"mcm","clk":"11982000878","pt":1724858899503,"mc":[{"id":"1.232375043","rc":[{"batb":[[0,1.31,4.21],[1,1.2,250],[2,1.04,1.05]],"ltp":1.52,"tv":272.11,"id":25651861}]}]}
{"op":"mcm","clk":"11982000899","pt":1724858899663,"mc":[{"id":"1.232375043","rc":[{"batb":[[0,1.32,5],[1,1.31,4.21],[2,1.2,250]],"ltp":1.52,"tv":272.11,"id":25651861}]}]}
{"op":"mcm","clk":"11982001099","pt":1724858901992,"mc":[{"id":"1.232375043","rc":[{"batb":[[0,1.33,4],[1,1.32,5],[2,1.31,4.21]],"ltp":1.52,"tv":272.11,"id":25651861}]}]}
{"op":"mcm","clk":"11982001185","pt":1724858902981,"mc":[{"id":"1.232375043","rc":[{"batb":[[1,1.31,4.21],[2,1.2,250]],"ltp":1.52,"tv":272.11,"id":25651861}]}]}
{"op":"mcm","clk":"11982001405","pt":1724858904993,"mc":[{"id":"1.232375043","rc":[{"batb":[[0,1.31,4.21],[1,1.2,250],[2,1.04,1.05]],"ltp":1.52,"tv":272.11,"id":25651861}]}]}
{"op":"mcm","clk":"11982002037","pt":1724858911603,"mc":[{"id":"1.232375043","rc":[{"batb":[[0,1.32,9],[1,1.31,4.21],[2,1.2,250]],"ltp":1.52,"tv":272.11,"id":25651861}]}]}
{"op":"mcm","clk":"11982002298","pt":1724858914703,"mc":[{"id":"1.232375043","rc":[{"batb":[[0,1.32,5]],"ltp":1.52,"tv":272.11,"id":25651861}]}]}
{"op":"mcm","clk":"11982002370","pt":1724858915690,"mc":[{"id":"1.232375043","rc":[{"batb":[[0,1.31,4.21],[1,1.2,250],[2,1.04,1.05]],"ltp":1.52,"tv":272.11,"id":25651861}]}]}
{"op":"mcm","clk":"11982004564","pt":1724858940934,"mc":[{"id":"1.232375043","rc":[{"batb":[[0,1.32,9],[1,1.31,4.21],[2,1.2,250]],"ltp":1.52,"tv":272.11,"id":25651861}]}]}
{"op":"mcm","clk":"11982004894","pt":1724858943947,"mc":[{"id":"1.232375043","rc":[{"batb":[[0,1.32,5]],"ltp":1.52,"tv":272.11,"id":25651861}]}]}
{"op":"mcm","clk":"11982004985","pt":1724858944830,"mc":[{"id":"1.232375043","rc":[{"batb":[[0,1.31,4.21],[1,1.2,250],[2,1.04,1.05]],"ltp":1.52,"tv":272.11,"id":25651861}]}]}
{"op":"mcm","clk":"11982005784","pt":1724858951739,"mc":[{"id":"1.232375043","rc":[{"batb":[[0,1.32,9],[1,1.31,4.21],[2,1.2,250]],"ltp":1.52,"tv":272.11,"id":25651861}]}]}
{"op":"mcm","clk":"11982006117","pt":1724858954540,"mc":[{"id":"1.232375043","rc":[{"batb":[[0,1.32,5]],"ltp":1.52,"tv":272.11,"id":25651861}]}]}
{"op":"mcm","clk":"11982006234","pt":1724858955580,"mc":[{"id":"1.232375043","rc":[{"batb":[[0,1.31,4.21],[1,1.2,250],[2,1.04,1.05]],"ltp":1.52,"tv":272.11,"id":25651861}]}]}
{"op":"mcm","clk":"11982007380","pt":1724858966288,"mc":[{"id":"1.232375043","rc":[{"batb":[[0,1.32,9],[1,1.31,4.21],[2,1.2,250]],"ltp":1.52,"tv":272.11,"id":25651861}]}]}
{"op":"mcm","clk":"11982007681","pt":1724858969285,"mc":[{"id":"1.232375043","rc":[{"batb":[[0,1.32,5]],"ltp":1.52,"tv":272.11,"id":25651861}]}]}
{"op":"mcm","clk":"11982007812","pt":1724858970483,"mc":[{"id":"1.232375043","rc":[{"batb":[[0,1.31,4.21],[1,1.2,250],[2,1.04,1.05]],"ltp":1.52,"tv":272.11,"id":25651861}]}]}
{"op":"mcm","clk":"11982009309","pt":1724858984109,"mc":[{"id":"1.232375043","rc":[{"batb":[[0,1.32,9],[1,1.31,4.21],[2,1.2,250]],"ltp":1.52,"tv":272.11,"id":25651861}]}]}
{"op":"mcm","clk":"11982009664","pt":1724858987398,"mc":[{"id":"1.232375043","rc":[{"batb":[[0,1.32,5]],"ltp":1.52,"tv":272.11,"id":25651861}]}]}
{"op":"mcm","clk":"11982009768","pt":1724858988280,"mc":[{"id":"1.232375043","rc":[{"batb":[[0,1.31,4.21],[1,1.2,250],[2,1.04,1.05]],"ltp":1.52,"tv":272.11,"id":25651861}]}]}
{"op":"mcm","clk":"11982009968","pt":1724858990292,"mc":[{"id":"1.232375043","rc":[{"batb":[[0,1.32,4],[1,1.31,4.21],[2,1.2,250]],"ltp":1.52,"tv":272.11,"id":25651861}]}]}
{"op":"mcm","clk":"11982010042","pt":1724858990910,"mc":[{"id":"1.232375043","rc":[{"batb":[[0,1.33,5],[1,1.32,4],[2,1.31,4.21]],"ltp":1.52,"tv":272.11,"id":25651861}]}]}
{"op":"mcm","clk":"11982010256","pt":1724858993129,"mc":[{"id":"1.232375043","rc":[{"batb":[[1,1.31,4.21],[2,1.2,250]],"ltp":1.52,"tv":272.11,"id":25651861}]}]}
{"op":"mcm","clk":"11982010415","pt":1724858994786,"mc":[{"id":"1.232375043","rc":[{"batb":[[0,1.31,4.21],[1,1.2,250],[2,1.04,1.05]],"ltp":1.52,"tv":272.11,"id":25651861}]}]}
{"op":"mcm","clk":"11982011255","pt":1724859002746,"mc":[{"id":"1.232375043","rc":[{"batb":[[0,1.32,9],[1,1.31,4.21],[2,1.2,250]],"ltp":1.52,"tv":272.11,"id":25651861}]}]}
{"op":"mcm","clk":"11982011734","pt":1724859006302,"mc":[{"id":"1.232375043","rc":[{"batb":[[0,1.31,4.21],[1,1.2,250],[2,1.04,1.05]],"ltp":1.52,"tv":272.11,"id":25651861}]}]}
{"op":"mcm","clk":"11982012357","pt":1724859011823,"mc":[{"id":"1.232375043","rc":[{"batb":[[0,1.32,9],[1,1.31,4.21],[2,1.2,250]],"ltp":1.52,"tv":272.11,"id":25651861}]}]}
{"op":"mcm","clk":"11982013140","pt":1724859018139,"mc":[{"id":"1.232375043","rc":[{"batb":[[0,1.31,4.21],[1,1.2,250],[2,1.04,1.05]],"ltp":1.52,"tv":272.11,"id":25651861}]}]}
{"op":"mcm","clk":"11982013792","pt":1724859024048,"mc":[{"id":"1.232375043","rc":[{"batb":[[0,1.32,9],[1,1.31,4.21],[2,1.2,250]],"ltp":1.52,"tv":272.11,"id":25651861}]}]}
{"op":"mcm","clk":"11982014207","pt":1724859028034,"mc":[{"id":"1.232375043","rc":[{"batb":[[0,1.32,5]],"ltp":1.52,"tv":272.11,"id":25651861}]}]}
{"op":"mcm","clk":"11982014318","pt":1724859028966,"mc":[{"id":"1.232375043","rc":[{"trd":[[2.96,0.9]],"batb":[[0,1.31,4.21],[1,1.2,250],[2,1.04,1.05]],"batl":[[0,2.96,0.1]],"ltp":2.96,"tv":273.01,"id":25651861},{"trd":[[1.51,1.76]],"ltp":1.51,"tv":482.35,"id":19587555}],"tv":755.36}]}
{"op":"mcm","clk":"11982015708","pt":1724859041597,"mc":[{"id":"1.232375043","rc":[{"batb":[[0,1.32,5],[1,1.31,4.21],[2,1.2,250]],"ltp":2.96,"tv":273.01,"id":25651861}]}]}
{"op":"mcm","clk":"11982016286","pt":1724859045787,"mc":[{"id":"1.232375043","rc":[{"batb":[[0,1.31,4.21],[1,1.2,250],[2,1.04,1.05]],"ltp":2.96,"tv":273.01,"id":25651861}]}]}
{"op":"mcm","clk":"11982024650","pt":1724859124651,"mc":[{"id":"1.232375043","rc":[{"batb":[[0,1.32,5],[1,1.31,4.21],[2,1.2,250]],"ltp":2.96,"tv":273.01,"id":25651861}]}]}
{"op":"mcm","clk":"11982025044","pt":1724859128341,"mc":[{"id":"1.232375043","rc":[{"batb":[[0,1.31,4.21],[1,1.2,250],[2,1.04,1.05]],"ltp":2.96,"tv":273.01,"id":25651861}]}]}
{"op":"mcm","clk":"11982025399","pt":1724859131862,"mc":[{"id":"1.232375043","rc":[{"batb":[[0,1.32,5],[1,1.31,4.21],[2,1.2,250]],"ltp":2.96,"tv":273.01,"id":25651861}]}]}
{"op":"mcm","clk":"11982025898","pt":1724859135996,"mc":[{"id":"1.232375043","rc":[{"batb":[[0,1.31,4.21],[1,1.2,250],[2,1.04,1.05]],"ltp":2.96,"tv":273.01,"id":25651861}]}]}
{"op":"mcm","clk":"11982027702","pt":1724859152702,"mc":[{"id":"1.232375043","rc":[{"batb":[[0,1.32,5],[1,1.31,4.21],[2,1.2,250]],"ltp":2.96,"tv":273.01,"id":25651861}]}]}
{"op":"mcm","clk":"11982028163","pt":1724859156711,"mc":[{"id":"1.232375043","rc":[{"batb":[[0,1.31,4.21],[1,1.2,250],[2,1.04,1.05]],"ltp":2.96,"tv":273.01,"id":25651861}]}]}
{"op":"mcm","clk":"11982028726","pt":1724859161821,"mc":[{"id":"1.232375043","rc":[{"batb":[[0,1.32,5],[1,1.31,4.21],[2,1.2,250]],"ltp":2.96,"tv":273.01,"id":25651861}]}]}
{"op":"mcm","clk":"11982029135","pt":1724859165721,"mc":[{"id":"1.232375043","rc":[{"batb":[[0,1.31,4.21],[1,1.2,250],[2,1.04,1.05]],"ltp":2.96,"tv":273.01,"id":25651861}]}]}
{"op":"mcm","clk":"11982031768","pt":1724859187835,"mc":[{"id":"1.232375043","rc":[{"batb":[[0,1.32,5],[1,1.31,4.21],[2,1.2,250]],"ltp":2.96,"tv":273.01,"id":25651861}]}]}
{"op":"mcm","clk":"11982032283","pt":1724859191937,"mc":[{"id":"1.232375043","rc":[{"batb":[[0,1.31,4.21],[1,1.2,250],[2,1.04,1.05]],"ltp":2.96,"tv":273.01,"id":25651861}]}]}
{"op":"mcm","clk":"11982034848","pt":1724859214480,"mc":[{"id":"1.232375043","rc":[{"batb":[[0,1.32,5],[1,1.31,4.21],[2,1.2,250]],"ltp":2.96,"tv":273.01,"id":25651861}]}]}
{"op":"mcm","clk":"11982035340","pt":1724859218370,"mc":[{"id":"1.232375043","rc":[{"batb":[[0,1.31,4.21],[1,1.2,250],[2,1.04,1.05]],"ltp":2.96,"tv":273.01,"id":25651861}]}]}
{"op":"mcm","clk":"11982037840","pt":1724859238289,"mc":[{"id":"1.232375043","rc":[{"batb":[[0,1.32,5],[1,1.31,4.21],[2,1.2,250]],"ltp":2.96,"tv":273.01,"id":25651861}]}]}
{"op":"mcm","clk":"11982038285","pt":1724859242072,"mc":[{"id":"1.232375043","rc":[{"batb":[[0,1.31,4.21],[1,1.2,250],[2,1.04,1.05]],"ltp":2.96,"tv":273.01,"id":25651861}]}]}
{"op":"mcm","clk":"11982040306","pt":1724859259977,"mc":[{"id":"1.232375043","rc":[{"batb":[[0,1.32,5],[1,1.31,4.21],[2,1.2,250]],"ltp":2.96,"tv":273.01,"id":25651861}]}]}
{"op":"mcm","clk":"11982040693","pt":1724859263308,"mc":[{"id":"1.232375043","rc":[{"batb":[[0,1.31,4.21],[1,1.2,250],[2,1.04,1.05]],"ltp":2.96,"tv":273.01,"id":25651861}]}]}
{"op":"mcm","clk":"11982041983","pt":1724859276323,"mc":[{"id":"1.232375043","rc":[{"batb":[[0,1.32,5],[1,1.31,4.21],[2,1.2,250]],"ltp":2.96,"tv":273.01,"id":25651861}]}]}
{"op":"mcm","clk":"11982042408","pt":1724859280227,"mc":[{"id":"1.232375043","rc":[{"batb":[[0,1.31,4.21],[1,1.2,250],[2,1.04,1.05]],"ltp":2.96,"tv":273.01,"id":25651861}]}]}
{"op":"mcm","clk":"11982043541","pt":1724859291121,"mc":[{"id":"1.232375043","rc":[{"batb":[[0,1.32,5],[1,1.31,4.21],[2,1.2,250]],"ltp":2.96,"tv":273.01,"id":25651861}]}]}
{"op":"mcm","clk":"11982043953","pt":1724859295030,"mc":[{"id":"1.232375043","rc":[{"batb":[[0,1.31,4.21],[1,1.2,250],[2,1.04,1.05]],"ltp":2.96,"tv":273.01,"id":25651861}]}]}
{"op":"mcm","clk":"11982053553","pt":1724859381908,"mc":[{"id":"1.232375043","rc":[{"batb":[[0,1.32,5],[1,1.31,4.21],[2,1.2,250]],"ltp":2.96,"tv":273.01,"id":25651861}]}]}
{"op":"mcm","clk":"11982053992","pt":1724859385814,"mc":[{"id":"1.232375043","rc":[{"batb":[[0,1.31,4.21],[1,1.2,250],[2,1.04,1.05]],"ltp":2.96,"tv":273.01,"id":25651861}]}]}
{"op":"mcm","clk":"11982059191","pt":1724859431163,"mc":[{"id":"1.232375043","rc":[{"batb":[[0,1.32,5],[1,1.31,4.21],[2,1.2,250]],"ltp":2.96,"tv":273.01,"id":25651861}]}]}
{"op":"mcm","clk":"11982059596","pt":1724859434866,"mc":[{"id":"1.232375043","rc":[{"batb":[[0,1.31,4.21],[1,1.2,250],[2,1.04,1.05]],"ltp":2.96,"tv":273.01,"id":25651861}]}]}
{"op":"mcm","clk":"11982061670","pt":1724859452683,"mc":[{"id":"1.232375043","rc":[{"batb":[[0,1.32,5],[1,1.31,4.21],[2,1.2,250]],"ltp":2.96,"tv":273.01,"id":25651861}]}]}
{"op":"mcm","clk":"11982062152","pt":1724859456388,"mc":[{"id":"1.232375043","rc":[{"batb":[[0,1.31,4.21],[1,1.2,250],[2,1.04,1.05]],"ltp":2.96,"tv":273.01,"id":25651861}]}]}
{"op":"mcm","clk":"11982065402","pt":1724859484117,"mc":[{"id":"1.232375043","rc":[{"batb":[[0,1.32,5],[1,1.31,4.21],[2,1.2,250]],"ltp":2.96,"tv":273.01,"id":25651861}]}]}
{"op":"mcm","clk":"11982065894","pt":1724859488523,"mc":[{"id":"1.232375043","rc":[{"batb":[[0,1.31,4.21],[1,1.2,250],[2,1.04,1.05]],"ltp":2.96,"tv":273.01,"id":25651861}]}]}
{"op":"mcm","clk":"11982066582","pt":1724859494987,"mc":[{"id":"1.232375043","rc":[{"batb":[[0,1.32,5],[1,1.31,4.21],[2,1.2,250]],"ltp":2.96,"tv":273.01,"id":25651861}]}]}
{"op":"mcm","clk":"11982066990","pt":1724859498713,"mc":[{"id":"1.232375043","rc":[{"batb":[[0,1.31,4.21],[1,1.2,250],[2,1.04,1.05]],"ltp":2.96,"tv":273.01,"id":25651861}]}]}
{"op":"mcm","clk":"11982068925","pt":1724859514936,"mc":[{"id":"1.232375043","rc":[{"batb":[[0,1.32,5],[1,1.31,4.21],[2,1.2,250]],"ltp":2.96,"tv":273.01,"id":25651861}]}]}
{"op":"mcm","clk":"11982069403","pt":1724859518842,"mc":[{"id":"1.232375043","rc":[{"batb":[[0,1.31,4.21],[1,1.2,250],[2,1.04,1.05]],"ltp":2.96,"tv":273.01,"id":25651861}]}]}
{"op":"mcm","clk":"11982069723","pt":1724859521864,"mc":[{"id":"1.232375043","rc":[{"batb":[[0,1.32,5],[1,1.31,4.21],[2,1.2,250]],"ltp":2.96,"tv":273.01,"id":25651861}]}]}
{"op":"mcm","clk":"11982070117","pt":1724859525528,"mc":[{"id":"1.232375043","rc":[{"batb":[[0,1.31,4.21],[1,1.2,250],[2,1.04,1.05]],"ltp":2.96,"tv":273.01,"id":25651861}]}]}
{"op":"mcm","clk":"11982071498","pt":1724859536453,"mc":[{"id":"1.232375043","rc":[{"batb":[[0,1.32,5],[1,1.31,4.21],[2,1.2,250]],"ltp":2.96,"tv":273.01,"id":25651861}]}]}
{"op":"mcm","clk":"11982072023","pt":1724859540372,"mc":[{"id":"1.232375043","rc":[{"batb":[[0,1.31,4.21],[1,1.2,250],[2,1.04,1.05]],"ltp":2.96,"tv":273.01,"id":25651861}]}]}
{"op":"mcm","clk":"11982072481","pt":1724859544010,"mc":[{"id":"1.232375043","rc":[{"batb":[[0,1.32,5],[1,1.31,4.21],[2,1.2,250]],"ltp":2.96,"tv":273.01,"id":25651861}]}]}
{"op":"mcm","clk":"11982072990","pt":1724859547986,"mc":[{"id":"1.232375043","rc":[{"batb":[[0,1.31,4.21],[1,1.2,250],[2,1.04,1.05]],"ltp":2.96,"tv":273.01,"id":25651861}]}]}
{"op":"mcm","clk":"11982074492","pt":1724859560731,"mc":[{"id":"1.232375043","rc":[{"batb":[[0,1.32,5],[1,1.31,4.21],[2,1.2,250]],"ltp":2.96,"tv":273.01,"id":25651861}]}]}
{"op":"mcm","clk":"11982074956","pt":1724859564912,"mc":[{"id":"1.232375043","rc":[{"batb":[[0,1.31,4.21],[1,1.2,250],[2,1.04,1.05]],"ltp":2.96,"tv":273.01,"id":25651861}]}]}
{"op":"mcm","clk":"11982084868","pt":1724859648384,"mc":[{"id":"1.232375043","rc":[{"batb":[[0,1.32,5],[1,1.31,4.21],[2,1.2,250]],"ltp":2.96,"tv":273.01,"id":25651861}]}]}
{"op":"mcm","clk":"11982085188","pt":1724859651191,"mc":[{"id":"1.232375043","rc":[{"batl":[[0,1.6,2],[1,1.61,8.38],[2,1.62,8.38]],"ltp":1.51,"tv":482.35,"id":19587555}]}]}
{"op":"mcm","clk":"11982085362","pt":1724859652772,"mc":[{"id":"1.232375043","rc":[{"batb":[[0,1.31,4.21],[1,1.2,250],[2,1.04,1.05]],"ltp":2.96,"tv":273.01,"id":25651861}]}]}
{"op":"mcm","clk":"11982085596","pt":1724859654991,"mc":[{"id":"1.232375043","rc":[{"batb":[[0,1.32,5],[1,1.31,4.21],[2,1.2,250]],"ltp":2.96,"tv":273.01,"id":25651861}]}]}
{"op":"mcm","clk":"11982086048","pt":1724859659114,"mc":[{"id":"1.232375043","rc":[{"batb":[[0,1.31,4.21],[1,1.2,250],[2,1.04,1.05]],"ltp":2.96,"tv":273.01,"id":25651861}]}]}
{"op":"mcm","clk":"11982087598","pt":1724859673028,"mc":[{"id":"1.232375043","rc":[{"batb":[[0,1.32,5],[1,1.31,4.21],[2,1.2,250]],"ltp":2.96,"tv":273.01,"id":25651861}]}]}
{"op":"mcm","clk":"11982087986","pt":1724859676704,"mc":[{"id":"1.232375043","rc":[{"batb":[[0,1.31,4.21],[1,1.2,250],[2,1.04,1.05]],"ltp":2.96,"tv":273.01,"id":25651861}]}]}
{"op":"mcm","clk":"11982088933","pt":1724859685633,"mc":[{"id":"1.232375043","rc":[{"batb":[[0,1.32,5],[1,1.31,4.21],[2,1.2,250]],"ltp":2.96,"tv":273.01,"id":25651861}]}]}
{"op":"mcm","clk":"11982089352","pt":1724859689516,"mc":[{"id":"1.232375043","rc":[{"batb":[[0,1.31,4.21],[1,1.2,250],[2,1.04,1.05]],"ltp":2.96,"tv":273.01,"id":25651861}]}]}
{"op":"mcm","clk":"11982091051","pt":1724859705097,"mc":[{"id":"1.232375043","rc":[{"batb":[[0,1.32,5],[1,1.31,4.21],[2,1.2,250]],"ltp":2.96,"tv":273.01,"id":25651861}]}]}
{"op":"mcm","clk":"11982091485","pt":1724859708838,"mc":[{"id":"1.232375043","rc":[{"batb":[[0,1.31,4.21],[1,1.2,250],[2,1.04,1.05]],"ltp":2.96,"tv":273.01,"id":25651861}]}]}
{"op":"mcm","clk":"11982092476","pt":1724859717784,"mc":[{"id":"1.232375043","rc":[{"batb":[[0,1.32,5],[1,1.31,4.21],[2,1.2,250]],"ltp":2.96,"tv":273.01,"id":25651861}]}]}
{"op":"mcm","clk":"11982092917","pt":1724859721485,"mc":[{"id":"1.232375043","rc":[{"batb":[[0,1.31,4.21],[1,1.2,250],[2,1.04,1.05]],"ltp":2.96,"tv":273.01,"id":25651861}]}]}
{"op":"mcm","clk":"11982093337","pt":1724859724691,"mc":[{"id":"1.232375043","rc":[{"batb":[[0,1.32,5],[1,1.31,4.21],[2,1.2,250]],"ltp":2.96,"tv":273.01,"id":25651861}]}]}
{"op":"mcm","clk":"11982093786","pt":1724859728594,"mc":[{"id":"1.232375043","rc":[{"batb":[[0,1.31,4.21],[1,1.2,250],[2,1.04,1.05]],"ltp":2.96,"tv":273.01,"id":25651861}]}]}
{"op":"mcm","clk":"11982097601","pt":1724859760602,"mc":[{"id":"1.232375043","rc":[{"batb":[[0,1.32,5],[1,1.31,4.21],[2,1.2,250]],"ltp":2.96,"tv":273.01,"id":25651861}]}]}
{"op":"mcm","clk":"11982098070","pt":1724859764823,"mc":[{"id":"1.232375043","rc":[{"batb":[[0,1.31,4.21],[1,1.2,250],[2,1.04,1.05]],"ltp":2.96,"tv":273.01,"id":25651861}]}]}
{"op":"mcm","clk":"11982099195","pt":1724859774714,"mc":[{"id":"1.232375043","rc":[{"batb":[[0,1.32,5],[1,1.31,4.21],[2,1.2,250]],"ltp":2.96,"tv":273.01,"id":25651861}]}]}
{"op":"mcm","clk":"11982110339","pt":1724859778972,"mc":[{"id":"1.232375043","rc":[{"batb":[[0,1.31,4.21],[1,1.2,250],[2,1.04,1.05]],"ltp":2.96,"tv":273.01,"id":25651861}]}]}
{"op":"mcm","clk":"11982119870","pt":1724859866537,"mc":[{"id":"1.232375043","rc":[{"batb":[[0,1.32,5],[1,1.31,4.21],[2,1.2,250]],"ltp":2.96,"tv":273.01,"id":25651861}]}]}
{"op":"mcm","clk":"11982120277","pt":1724859870531,"mc":[{"id":"1.232375043","rc":[{"batb":[[0,1.31,4.21],[1,1.2,250],[2,1.04,1.05]],"ltp":2.96,"tv":273.01,"id":25651861}]}]}
{"op":"mcm","clk":"11982124180","pt":1724859906205,"mc":[{"id":"1.232375043","rc":[{"batb":[[0,1.32,5],[1,1.31,4.21],[2,1.2,250]],"ltp":2.96,"tv":273.01,"id":25651861}]}]}
{"op":"mcm","clk":"11982124666","pt":1724859910047,"mc":[{"id":"1.232375043","rc":[{"batb":[[0,1.31,4.21],[1,1.2,250],[2,1.04,1.05]],"ltp":2.96,"tv":273.01,"id":25651861}]}]}
{"op":"mcm","clk":"11982130405","pt":1724859959331,"mc":[{"id":"1.232375043","rc":[{"batb":[[0,1.32,5],[1,1.31,4.21],[2,1.2,250]],"ltp":2.96,"tv":273.01,"id":25651861}]}]}
{"op":"mcm","clk":"11982130870","pt":1724859963662,"mc":[{"id":"1.232375043","rc":[{"batb":[[0,1.31,4.21],[1,1.2,250],[2,1.04,1.05]],"ltp":2.96,"tv":273.01,"id":25651861}]}]}
{"op":"mcm","clk":"11982132929","pt":1724859982054,"mc":[{"id":"1.232375043","rc":[{"batb":[[0,1.32,5],[1,1.31,4.21],[2,1.2,250]],"ltp":2.96,"tv":273.01,"id":25651861}]}]}
{"op":"mcm","clk":"11982133529","pt":1724859986676,"mc":[{"id":"1.232375043","rc":[{"batb":[[0,1.31,4.21],[1,1.2,250],[2,1.04,1.05]],"ltp":2.96,"tv":273.01,"id":25651861}]}]}
{"op":"mcm","clk":"11982135621","pt":1724860002295,"mc":[{"id":"1.232375043","rc":[{"batb":[[0,1.32,5],[1,1.31,4.21],[2,1.2,250]],"ltp":2.96,"tv":273.01,"id":25651861}]}]}
{"op":"mcm","clk":"11982136092","pt":1724860006003,"mc":[{"id":"1.232375043","rc":[{"batb":[[0,1.31,4.21],[1,1.2,250],[2,1.04,1.05]],"ltp":2.96,"tv":273.01,"id":25651861}]}]}
{"op":"mcm","clk":"11982136897","pt":1724860012426,"mc":[{"id":"1.232375043","rc":[{"batb":[[0,1.32,5],[1,1.31,4.21],[2,1.2,250]],"ltp":2.96,"tv":273.01,"id":25651861}]}]}
{"op":"mcm","clk":"11982137498","pt":1724860016801,"mc":[{"id":"1.232375043","rc":[{"batb":[[0,1.31,4.21],[1,1.2,250],[2,1.04,1.05]],"ltp":2.96,"tv":273.01,"id":25651861}]}]}
{"op":"mcm","clk":"11982145314","pt":1724860089096,"mc":[{"id":"1.232375043","rc":[{"batb":[[0,1.32,5],[1,1.31,4.21],[2,1.2,250]],"ltp":2.96,"tv":273.01,"id":25651861}]}]}
{"op":"mcm","clk":"11982145773","pt":1724860093336,"mc":[{"id":"1.232375043","rc":[{"batb":[[0,1.31,4.21],[1,1.2,250],[2,1.04,1.05]],"ltp":2.96,"tv":273.01,"id":25651861}]}]}
{"op":"mcm","clk":"11982148351","pt":1724860115150,"mc":[{"id":"1.232375043","rc":[{"batb":[[0,1.32,5],[1,1.31,4.21],[2,1.2,250]],"ltp":2.96,"tv":273.01,"id":25651861}]}]}
{"op":"mcm","clk":"11982148752","pt":1724860119045,"mc":[{"id":"1.232375043","rc":[{"batb":[[0,1.31,4.21],[1,1.2,250],[2,1.04,1.05]],"ltp":2.96,"tv":273.01,"id":25651861}]}]}
{"op":"mcm","clk":"11982151050","pt":1724860138295,"mc":[{"id":"1.232375043","rc":[{"batb":[[0,1.32,5],[1,1.31,4.21],[2,1.2,250]],"ltp":2.96,"tv":273.01,"id":25651861}]}]}
{"op":"mcm","clk":"11982151733","pt":1724860144382,"mc":[{"id":"1.232375043","rc":[{"batb":[[0,1.31,4.21],[1,1.2,250],[2,1.04,1.05]],"ltp":2.96,"tv":273.01,"id":25651861}]}]}
{"op":"mcm","clk":"11982151987","pt":1724860146582,"mc":[{"id":"1.232375043","rc":[{"batb":[[0,1.32,5],[1,1.31,4.21],[2,1.2,250]],"ltp":2.96,"tv":273.01,"id":25651861}]}]}
{"op":"mcm","clk":"11982152559","pt":1724860151378,"mc":[{"id":"1.232375043","rc":[{"batb":[[0,1.31,4.21],[1,1.2,250],[2,1.04,1.05]],"ltp":2.96,"tv":273.01,"id":25651861}]}]}
{"op":"mcm","clk":"11982153266","pt":1724860156805,"mc":[{"id":"1.232375043","rc":[{"batb":[[0,1.32,5],[1,1.31,4.21],[2,1.2,250]],"ltp":2.96,"tv":273.01,"id":25651861},{"batb":[[0,1.4,41.89],[1,1.39,16.76],[2,1.38,16.76]],"ltp":1.51,"tv":482.35,"id":19587555}]}]}
{"op":"mcm","clk":"11982153681","pt":1724860160106,"mc":[{"id":"1.232375043","rc":[{"batb":[[0,1.31,4.21],[1,1.2,250],[2,1.04,1.05]],"ltp":2.96,"tv":273.01,"id":25651861}]}]}
{"op":"mcm","clk":"11982154608","pt":1724860167688,"mc":[{"id":"1.232375043","rc":[{"batb":[[0,1.32,5],[1,1.31,4.21],[2,1.2,250]],"ltp":2.96,"tv":273.01,"id":25651861}]}]}
{"op":"mcm","clk":"11982155140","pt":1724860171798,"mc":[{"id":"1.232375043","rc":[{"batb":[[0,1.31,4.21],[1,1.2,250],[2,1.04,1.05]],"ltp":2.96,"tv":273.01,"id":25651861}]}]}
{"op":"mcm","clk":"11982156472","pt":1724860183127,"mc":[{"id":"1.232375043","rc":[{"batb":[[0,1.32,5],[1,1.31,4.21],[2,1.2,250]],"ltp":2.96,"tv":273.01,"id":25651861}]}]}
{"op":"mcm","clk":"11982156976","pt":1724860187468,"mc":[{"id":"1.232375043","rc":[{"batb":[[0,1.31,4.21],[1,1.2,250],[2,1.04,1.05]],"ltp":2.96,"tv":273.01,"id":25651861}]}]}
{"op":"mcm","clk":"11982158937","pt":1724860204262,"mc":[{"id":"1.232375043","rc":[{"batb":[[0,1.32,5],[1,1.31,4.21],[2,1.2,250]],"ltp":2.96,"tv":273.01,"id":25651861},{"batb":[[0,1.39,16.76],[1,1.38,16.76],[2,1.37,7.56]],"ltp":1.51,"tv":482.35,"id":19587555}]}]}
{"op":"mcm","clk":"11982159411","pt":1724860208066,"mc":[{"id":"1.232375043","rc":[{"batb":[[0,1.31,4.21],[1,1.2,250],[2,1.04,1.05]],"ltp":2.96,"tv":273.01,"id":25651861}]}]}
{"op":"mcm","clk":"11982162015","pt":1724860228873,"mc":[{"id":"1.232375043","rc":[{"batb":[[0,1.32,5],[1,1.31,4.21],[2,1.2,250]],"ltp":2.96,"tv":273.01,"id":25651861}]}]}
{"op":"mcm","clk":"11982162536","pt":1724860232986,"mc":[{"id":"1.232375043","rc":[{"batb":[[0,1.31,4.21],[1,1.2,250],[2,1.04,1.05]],"ltp":2.96,"tv":273.01,"id":25651861}]}]}
{"op":"mcm","clk":"11982167403","pt":1724860271936,"mc":[{"id":"1.232375043","rc":[{"batb":[[0,1.32,5],[1,1.31,4.21],[2,1.2,250]],"ltp":2.96,"tv":273.01,"id":25651861}]}]}
{"op":"mcm","clk":"11982167856","pt":1724860275733,"mc":[{"id":"1.232375043","rc":[{"batb":[[0,1.31,4.21],[1,1.2,250],[2,1.04,1.05]],"ltp":2.96,"tv":273.01,"id":25651861}]}]}
{"op":"mcm","clk":"11982169032","pt":1724860285133,"mc":[{"id":"1.232375043","rc":[{"batb":[[0,1.32,5],[1,1.31,4.21],[2,1.2,250]],"ltp":2.96,"tv":273.01,"id":25651861}]}]}
{"op":"mcm","clk":"11982169484","pt":1724860288974,"mc":[{"id":"1.232375043","rc":[{"batb":[[0,1.31,4.21],[1,1.2,250],[2,1.04,1.05]],"ltp":2.96,"tv":273.01,"id":25651861}]}]}
{"op":"mcm","clk":"11982171563","pt":1724860303477,"mc":[{"id":"1.232375043","rc":[{"batb":[[0,1.32,5],[1,1.31,4.21],[2,1.2,250]],"ltp":2.96,"tv":273.01,"id":25651861}]}]}
{"op":"mcm","clk":"11982172118","pt":1724860307487,"mc":[{"id":"1.232375043","rc":[{"batb":[[0,1.31,4.21],[1,1.2,250],[2,1.04,1.05]],"ltp":2.96,"tv":273.01,"id":25651861}]}]}
{"op":"mcm","clk":"11982175472","pt":1724860336539,"mc":[{"id":"1.232375043","rc":[{"batb":[[0,1.32,5],[1,1.31,4.21],[2,1.2,250]],"ltp":2.96,"tv":273.01,"id":25651861}]}]}
{"op":"mcm","clk":"11982176032","pt":1724860340801,"mc":[{"id":"1.232375043","rc":[{"batb":[[0,1.31,4.21],[1,1.2,250],[2,1.04,1.05]],"ltp":2.96,"tv":273.01,"id":25651861}]}]}
{"op":"mcm","clk":"11982176609","pt":1724860345678,"mc":[{"id":"1.232375043","rc":[{"batb":[[0,1.32,5],[1,1.31,4.21],[2,1.2,250]],"ltp":2.96,"tv":273.01,"id":25651861}]}]}
{"op":"mcm","clk":"11982177045","pt":1724860349167,"mc":[{"id":"1.232375043","rc":[{"batb":[[0,1.31,4.21],[1,1.2,250],[2,1.04,1.05]],"ltp":2.96,"tv":273.01,"id":25651861}]}]}
{"op":"mcm","clk":"11982177760","pt":1724860355360,"mc":[{"id":"1.232375043","rc":[{"batb":[[0,1.32,5],[1,1.31,4.21],[2,1.2,250]],"ltp":2.96,"tv":273.01,"id":25651861}]}]}
{"op":"mcm","clk":"11982178224","pt":1724860359376,"mc":[{"id":"1.232375043","rc":[{"batb":[[0,1.31,4.21],[1,1.2,250],[2,1.04,1.05]],"ltp":2.96,"tv":273.01,"id":25651861}]}]}
{"op":"mcm","clk":"11982179587","pt":1724860371723,"mc":[{"id":"1.232375043","rc":[{"batb":[[0,1.32,5],[1,1.31,4.21],[2,1.2,250]],"ltp":2.96,"tv":273.01,"id":25651861}]}]}
{"op":"mcm","clk":"11982180098","pt":1724860375522,"mc":[{"id":"1.232375043","rc":[{"batb":[[0,1.31,4.21],[1,1.2,250],[2,1.04,1.05]],"ltp":2.96,"tv":273.01,"id":25651861}]}]}
{"op":"mcm","clk":"11982181739","pt":1724860389545,"mc":[{"id":"1.232375043","rc":[{"batb":[[0,1.32,5],[1,1.31,4.21],[2,1.2,250]],"ltp":2.96,"tv":273.01,"id":25651861}]}]}
{"op":"mcm","clk":"11982182055","pt":1724860392006,"mc":[{"id":"1.232375043","rc":[{"batb":[[2,1.04,1.05]],"ltp":2.96,"tv":273.01,"id":25651861}]}]}
{"op":"mcm","clk":"11982182218","pt":1724860393401,"mc":[{"id":"1.232375043","rc":[{"batb":[[0,1.31,4.21],[1,1.04,1.05],[2,1.03,200]],"ltp":2.96,"tv":273.01,"id":25651861}]}]}
{"op":"mcm","clk":"11982183635","pt":1724860405848,"mc":[{"id":"1.232375043","rc":[{"batb":[[0,1.32,5],[1,1.31,4.21],[2,1.04,1.05]],"ltp":2.96,"tv":273.01,"id":25651861}]}]}
{"op":"mcm","clk":"11982184078","pt":1724860409939,"mc":[{"id":"1.232375043","rc":[{"batb":[[0,1.31,4.21],[1,1.04,1.05],[2,1.03,200]],"ltp":2.96,"tv":273.01,"id":25651861}]}]}
{"op":"mcm","clk":"11982185031","pt":1724860418442,"mc":[{"id":"1.232375043","rc":[{"batb":[[0,1.33,151.52],[1,1.32,5],[2,1.31,4.21]],"ltp":2.96,"tv":273.01,"id":25651861}]}]}
{"op":"mcm","clk":"11982185055","pt":1724860418650,"mc":[{"id":"1.232375043","rc":[{"batb":[[0,1.43,116.28],[1,1.38,131.58],[2,1.33,151.52]],"ltp":2.96,"tv":273.01,"id":25651861},{"batb":[[0,1.43,116.28],[1,1.39,16.76],[2,1.38,148.34]],"ltp":1.51,"tv":482.35,"id":19587555}]}]}
{"op":"mcm","clk":"11982185318","pt":1724860421246,"mc":[{"id":"1.232375043","rc":[{"batb":[[0,1.39,16.76],[1,1.38,148.34],[2,1.37,7.56]],"ltp":1.51,"tv":482.35,"id":19587555}]}]}
{"op":"mcm","clk":"11982185647","pt":1724860424156,"mc":[{"id":"1.232375043","rc":[{"batb":[[0,1.44,5],[1,1.43,116.28],[2,1.38,131.58]],"ltp":2.96,"tv":273.01,"id":25651861},{"batb":[[1,1.38,16.76]],"ltp":1.51,"tv":482.35,"id":19587555}]}]}
{"op":"mcm","clk":"11982185983","pt":1724860427584,"mc":[{"id":"1.232375043","rc":[{"batb":[[0,1.43,116.28],[1,1.38,131.58],[2,1.33,151.52]],"ltp":2.96,"tv":273.01,"id":25651861}]}]}
{"op":"mcm","clk":"11982186630","pt":1724860433485,"mc":[{"id":"1.232375043","rc":[{"batb":[[0,1.32,5],[1,1.31,4.21],[2,1.04,1.05]],"ltp":2.96,"tv":273.01,"id":25651861}]}]}
{"op":"mcm","clk":"11982187008","pt":1724860436874,"mc":[{"id":"1.232375043","rc":[{"batb":[[0,1.31,4.21],[1,1.04,1.05],[2,1.03,200]],"ltp":2.96,"tv":273.01,"id":25651861}]}]}
{"op":"mcm","clk":"11982187454","pt":1724860441181,"mc":[{"id":"1.232375043","rc":[{"batb":[[0,1.32,5],[1,1.31,4.21],[2,1.04,1.05]],"ltp":2.96,"tv":273.01,"id":25651861}]}]}
{"op":"mcm","clk":"11982187909","pt":1724860445179,"mc":[{"id":"1.232375043","rc":[{"batb":[[0,1.31,4.21],[1,1.04,1.05],[2,1.03,200]],"ltp":2.96,"tv":273.01,"id":25651861}]}]}
{"op":"mcm","clk":"11982188281","pt":1724860447993,"mc":[{"id":"1.232375043","rc":[{"batb":[[0,1.32,5],[1,1.31,4.21],[2,1.04,1.05]],"ltp":2.96,"tv":273.01,"id":25651861}]}]}
{"op":"mcm","clk":"11982188684","pt":1724860451369,"mc":[{"id":"1.232375043","rc":[{"batb":[[0,1.31,4.21],[1,1.04,1.05],[2,1.03,200]],"ltp":2.96,"tv":273.01,"id":25651861}]}]}
{"op":"mcm","clk":"11982189229","pt":1724860456514,"mc":[{"id":"1.232375043","rc":[{"batb":[[0,1.32,5],[1,1.31,4.21],[2,1.1,500]],"ltp":2.96,"tv":273.01,"id":25651861}]}]}
{"op":"mcm","clk":"11982189349","pt":1724860457413,"mc":[{"id":"1.232375043","rc":[{"batb":[[2,1.2,250]],"ltp":2.96,"tv":273.01,"id":25651861}]}]}
{"op":"mcm","clk":"11982189481","pt":1724860458487,"mc":[{"id":"1.232375043","rc":[{"batb":[[2,1.3,166.67]],"ltp":2.96,"tv":273.01,"id":25651861}]}]}
{"op":"mcm","clk":"11982189652","pt":1724860459995,"mc":[{"id":"1.232375043","rc":[{"batb":[[0,1.4,125]],"ltp":2.96,"tv":273.01,"id":25651861}]}]}
{"op":"mcm","clk":"11982190009","pt":1724860462805,"mc":[{"id":"1.232375043","rc":[{"batb":[[0,1.51,5],[1,1.5,100],[2,1.4,125]],"ltp":2.96,"tv":273.01,"id":25651861}]}]}
{"op":"mcm","clk":"11982190357","pt":1724860466125,"mc":[{"id":"1.232375043","rc":[{"batb":[[0,1.6,83.33]],"ltp":2.96,"tv":273.01,"id":25651861}]}]}
{"op":"mcm","clk":"11982190608","pt":1724860468205,"mc":[{"id":"1.232375043","rc":[{"batb":[[0,1.7,71.43],[1,1.6,83.33],[2,1.5,100]],"ltp":2.96,"tv":273.01,"id":25651861}]}]}
{"op":"mcm","clk":"11982190728","pt":1724860469391,"mc":[{"id":"1.232375043","rc":[{"batb":[[0,1.8,62.5],[1,1.71,5],[2,1.7,71.43]],"ltp":2.96,"tv":273.01,"id":25651861}]}]}
{"op":"mcm","clk":"11982191206","pt":1724860473395,"mc":[{"id":"1.232375043","rc":[{"batb":[[1,1.7,71.43],[2,1.6,83.33]],"ltp":2.96,"tv":273.01,"id":25651861}]}]}
{"op":"mcm","clk":"11982191690","pt":1724860477025,"mc":[{"id":"1.232375043","rc":[{"batb":[[0,1.81,5],[1,1.8,62.5],[2,1.7,71.43]],"ltp":2.96,"tv":273.01,"id":25651861}]}]}
{"op":"mcm","clk":"11982192107","pt":1724860480322,"mc":[{"id":"1.232375043","rc":[{"batb":[[0,2,50],[1,1.81,5],[2,1.8,62.5]],"ltp":2.96,"tv":273.01,"id":25651861}]}]}
{"op":"mcm","clk":"11982192176","pt":1724860480797,"mc":[{"id":"1.232375043","rc":[{"batb":[[1,1.8,62.5],[2,1.7,71.43]],"ltp":2.96,"tv":273.01,"id":25651861}]}]}
{"op":"mcm","clk":"11982192330","pt":1724860482053,"mc":[{"id":"1.232375043","rc":[{"batb":[[0,2.2,41.67],[1,2,50],[2,1.8,62.5]],"ltp":2.96,"tv":273.01,"id":25651861}]}]}
{"op":"mcm","clk":"11982193052","pt":1724860487902,"mc":[{"id":"1.232375043","rc":[{"batb":[[0,2.22,5],[1,2.2,41.67],[2,2,50]],"ltp":2.96,"tv":273.01,"id":25651861}]}]}
{"op":"mcm","clk":"11982193501","pt":1724860491716,"mc":[{"id":"1.232375043","rc":[{"batb":[[0,2.2,41.67],[1,2,50],[2,1.8,62.5]],"ltp":2.96,"tv":273.01,"id":25651861}]}]}
{"op":"mcm","clk":"11982197187","pt":1724860519073,"mc":[{"id":"1.232375043","rc":[{"batb":[[0,2.22,5],[1,2.2,41.67],[2,2,50]],"ltp":2.96,"tv":273.01,"id":25651861}]}]}
{"op":"mcm","clk":"11982197769","pt":1724860522867,"mc":[{"id":"1.232375043","rc":[{"batb":[[0,2.2,41.67],[1,2,50],[2,1.8,62.5]],"ltp":2.96,"tv":273.01,"id":25651861}]}]}
{"op":"mcm","clk":"11982198828","pt":1724860530353,"mc":[{"id":"1.232375043","rc":[{"batb":[[0,2.22,5],[1,2.2,41.67],[2,2,50]],"ltp":2.96,"tv":273.01,"id":25651861}]}]}
{"op":"mcm","clk":"11982199382","pt":1724860534095,"mc":[{"id":"1.232375043","rc":[{"batb":[[0,2.2,41.67],[1,2,50],[2,1.8,62.5]],"ltp":2.96,"tv":273.01,"id":25651861}]}]}
{"op":"mcm","clk":"11982199845","pt":1724860537890,"mc":[{"id":"1.232375043","rc":[{"batb":[[0,2.22,5],[1,2.2,41.67],[2,2,50]],"ltp":2.96,"tv":273.01,"id":25651861}]}]}
{"op":"mcm","clk":"11982200399","pt":1724860542098,"mc":[{"id":"1.232375043","rc":[{"batb":[[0,2.2,41.67],[1,2,50],[2,1.8,62.5]],"ltp":2.96,"tv":273.01,"id":25651861}]}]}
{"op":"mcm","clk":"11982206685","pt":1724860590224,"mc":[{"id":"1.232375043","rc":[{"batb":[[0,2.22,5],[1,2.2,41.67],[2,2,50]],"ltp":2.96,"tv":273.01,"id":25651861}]}]}
{"op":"mcm","clk":"11982207194","pt":1724860593746,"mc":[{"id":"1.232375043","rc":[{"batb":[[0,2.2,41.67],[1,2,50],[2,1.8,62.5]],"ltp":2.96,"tv":273.01,"id":25651861}]}]}
{"op":"mcm","clk":"11982208115","pt":1724860600040,"mc":[{"id":"1.232375043","rc":[{"batb":[[0,2.22,5],[1,2.2,41.67],[2,2,50]],"ltp":2.96,"tv":273.01,"id":25651861}]}]}
{"op":"mcm","clk":"11982208599","pt":1724860603855,"mc":[{"id":"1.232375043","rc":[{"batb":[[0,2.2,41.67],[1,2,50],[2,1.8,62.5]],"ltp":2.96,"tv":273.01,"id":25651861}]}]}
{"op":"mcm","clk":"11982209049","pt":1724860607849,"mc":[{"id":"1.232375043","rc":[{"batb":[[0,2.22,5],[1,2.2,41.67],[2,2,50]],"ltp":2.96,"tv":273.01,"id":25651861}]}]}
{"op":"mcm","clk":"11982209549","pt":1724860611665,"mc":[{"id":"1.232375043","rc":[{"batb":[[0,2.2,41.67],[1,2,50],[2,1.8,62.5]],"ltp":2.96,"tv":273.01,"id":25651861}]}]}
{"op":"mcm","clk":"11982210048","pt":1724860615656,"mc":[{"id":"1.232375043","rc":[{"batb":[[0,2.22,5],[1,2.2,41.67],[2,2,50]],"ltp":2.96,"tv":273.01,"id":25651861}]}]}
{"op":"mcm","clk":"11982210470","pt":1724860619164,"mc":[{"id":"1.232375043","rc":[{"batb":[[0,2.2,41.67],[1,2,50],[2,1.8,62.5]],"ltp":2.96,"tv":273.01,"id":25651861}]}]}
{"op":"mcm","clk":"11982212743","pt":1724860637041,"mc":[{"id":"1.232375043","rc":[{"batb":[[0,2.22,5],[1,2.2,41.67],[2,2,50]],"ltp":2.96,"tv":273.01,"id":25651861}]}]}
{"op":"mcm","clk":"11982213221","pt":1724860641041,"mc":[{"id":"1.232375043","rc":[{"batb":[[0,2.2,41.67],[1,2,50],[2,1.8,62.5]],"ltp":2.96,"tv":273.01,"id":25651861}]}]}
{"op":"mcm","clk":"11982214857","pt":1724860654750,"mc":[{"id":"1.232375043","rc":[{"batb":[[0,2.22,5],[1,2.2,41.67],[2,2,50]],"ltp":2.96,"tv":273.01,"id":25651861}]}]}
{"op":"mcm","clk":"11982215424","pt":1724860659069,"mc":[{"id":"1.232375043","rc":[{"batb":[[0,2.2,41.67],[1,2,50],[2,1.8,62.5]],"ltp":2.96,"tv":273.01,"id":25651861}]}]}
{"op":"mcm","clk":"11982215989","pt":1724860663391,"mc":[{"id":"1.232375043","rc":[{"batb":[[0,2.22,5],[1,2.2,41.67],[2,2,50]],"ltp":2.96,"tv":273.01,"id":25651861}]}]}
{"op":"mcm","clk":"11982216484","pt":1724860667496,"mc":[{"id":"1.232375043","rc":[{"batb":[[0,2.2,41.67],[1,2,50],[2,1.8,62.5]],"ltp":2.96,"tv":273.01,"id":25651861}]}]}
{"op":"mcm","clk":"11982217699","pt":1724860677706,"mc":[{"id":"1.232375043","rc":[{"batb":[[0,2.22,5],[1,2.2,41.67],[2,2,50]],"ltp":2.96,"tv":273.01,"id":25651861}]}]}
{"op":"mcm","clk":"11982218236","pt":1724860681925,"mc":[{"id":"1.232375043","rc":[{"batb":[[0,2.2,41.67],[1,2,50],[2,1.8,62.5]],"ltp":2.96,"tv":273.01,"id":25651861}]}]}
{"op":"mcm","clk":"11982218545","pt":1724860684329,"mc":[{"id":"1.232375043","rc":[{"batb":[[0,2.22,5],[1,2.2,41.67],[2,2,50]],"ltp":2.96,"tv":273.01,"id":25651861}]}]}
{"op":"mcm","clk":"11982219044","pt":1724860688340,"mc":[{"id":"1.232375043","rc":[{"batb":[[0,2.2,41.67],[1,2,50],[2,1.8,62.5]],"ltp":2.96,"tv":273.01,"id":25651861}]}]}
{"op":"mcm","clk":"11982219865","pt":1724860694635,"mc":[{"id":"1.232375043","rc":[{"batb":[[0,2.22,5],[1,2.2,41.67],[2,2,50]],"ltp":2.96,"tv":273.01,"id":25651861}]}]}
{"op":"mcm","clk":"11982220433","pt":1724860699151,"mc":[{"id":"1.232375043","rc":[{"batb":[[0,2.2,41.67],[1,2,50],[2,1.8,62.5]],"ltp":2.96,"tv":273.01,"id":25651861}]}]}
{"op":"mcm","clk":"11982222153","pt":1724860712240,"mc":[{"id":"1.232375043","rc":[{"batb":[[0,2.22,5],[1,2.2,41.67],[2,2,50]],"ltp":2.96,"tv":273.01,"id":25651861}]}]}
{"op":"mcm","clk":"11982222233","pt":1724860712863,"mc":[{"id":"1.232375043","rc":[{"trd":[[2.96,1]],"ltp":2.96,"tv":273.11,"id":25651861},{"trd":[[1.51,1.96]],"batl":[[0,1.6,2.8]],"ltp":1.51,"tv":482.55,"id":19587555}],"tv":755.66}]}
{"op":"mcm","clk":"11982222643","pt":1724860716246,"mc":[{"id":"1.232375043","rc":[{"batb":[[0,2.2,41.67],[1,2,50],[2,1.8,62.5]],"ltp":2.96,"tv":273.11,"id":25651861}]}]}
{"op":"mcm","clk":"11982223226","pt":1724860720989,"mc":[{"id":"1.232375043","rc":[{"batl":[[0,1.6,2]],"ltp":1.51,"tv":482.55,"id":19587555}]}]}
{"op":"mcm","clk":"11982225693","pt":1724860741119,"mc":[{"id":"1.232375043","rc":[{"batl":[[0,1.5,1],[1,1.6,2],[2,1.61,8.38]],"ltp":1.51,"tv":482.55,"id":19587555}]}]}
{"op":"mcm","clk":"11982226348","pt":1724860745899,"mc":[{"id":"1.232375043","rc":[{"batl":[[0,1.6,2],[1,1.61,8.38],[2,1.62,8.38]],"ltp":1.51,"tv":482.55,"id":19587555}]}]}
{"op":"mcm","clk":"11982227611","pt":1724860755425,"mc":[{"id":"1.232375043","rc":[{"batl":[[0,1.51,1],[1,1.6,2],[2,1.61,8.38]],"ltp":1.51,"tv":482.55,"id":19587555}]}]}
{"op":"mcm","clk":"11982228470","pt":1724860762107,"mc":[{"id":"1.232375043","rc":[{"batl":[[0,1.59,1]],"ltp":1.51,"tv":482.55,"id":19587555}]}]}
{"op":"mcm","clk":"11982232759","pt":1724860797871,"mc":[{"id":"1.232375043","rc":[{"batb":[[0,1.4,62.76],[1,1.39,16.76],[2,1.38,16.76]],"ltp":1.51,"tv":482.55,"id":19587555}]}]}
{"op":"mcm","clk":"11982246702","pt":1724860892186,"mc":[{"id":"1.232375043","rc":[{"trd":[[1.52,272.43]],"ltp":2.96,"tv":273.43,"id":25651861},{"trd":[[1.5,275.15],[1.52,3.81],[1.54,33.53],[1.55,27.23],[1.56,36.83],[1.57,23.15],[2.16,31.67]],"batl":[[0,1.55,1],[1,1.59,1],[2,1.6,2]],"ltp":1.51,"tv":482.94,"id":19587555}],"tv":756.37}]}
{"op":"mcm","clk":"11982248939","pt":1724860906964,"mc":[{"id":"1.232375043","rc":[{"trd":[[2.66,0.86],[2.68,0.59],[2.8,0.55]],"ltp":2.66,"tv":275.43,"id":25651861},{"trd":[[1.55,28.23],[1.59,1],[1.6,1.43]],"batl":[[0,1.61,8.95],[1,1.62,8.38],[2,1.63,11.73]],"ltp":1.6,"tv":486.37,"id":19587555}],"tv":761.8}]}
{"op":"mcm","clk":"11982253342","pt":1724860935629,"mc":[{"id":"1.232375043","rc":[{"batb":[[1,1.38,16.76],[2,1.37,7.57]],"ltp":1.6,"tv":486.37,"id":19587555}]}]}
{"op":"mcm","clk":"11982255009","pt":1724860947252,"mc":[{"id":"1.232375043","rc":[{"batb":[[0,1.42,16.76],[1,1.4,62.76],[2,1.38,16.76]],"ltp":1.6,"tv":486.37,"id":19587555}]}]}
{"op":"mcm","clk":"11982342932","pt":1724861507784,"mc":[{"id":"1.232375043","rc":[{"batb":[[0,1.5,1.52],[1,1.42,16.76],[2,1.4,62.76]],"ltp":1.6,"tv":486.37,"id":19587555}]}]}
{"op":"mcm","clk":"11982345131","pt":1724861521813,"mc":[{"id":"1.232375043","rc":[{"batl":[[0,1.6,1],[1,1.61,8.38],[2,1.62,8.38]],"ltp":1.6,"tv":486.37,"id":19587555}]}]}
{"op":"mcm","clk":"11982348932","pt":1724861546174,"mc":[{"id":"1.232375043","rc":[{"trd":[[1.5,277.83]],"batb":[[0,1.42,16.94],[1,1.4,62.76],[2,1.38,16.76]],"ltp":1.5,"tv":489.05,"id":19587555}],"tv":764.48}]}
{"op":"mcm","clk":"11982370772","pt":1724861688437,"mc":[{"id":"1.232375043","rc":[{"batl":[[0,1.61,8.95],[1,1.62,8.38],[2,1.63,11.73]],"ltp":1.5,"tv":489.05,"id":19587555}]}]}
{"op":"mcm","clk":"11982370968","pt":1724861689653,"mc":[{"id":"1.232375043","rc":[{"batl":[[0,1.61,8.38]],"ltp":1.5,"tv":489.05,"id":19587555}]}]}
{"op":"mcm","clk":"11982372478","pt":1724861699431,"mc":[{"id":"1.232375043","rc":[{"batl":[[0,1.59,2],[1,1.61,8.38],[2,1.62,8.38]],"ltp":1.5,"tv":489.05,"id":19587555}]}]}
{"op":"mcm","clk":"11982392772","pt":1724861830109,"mc":[{"id":"1.232375043","rc":[{"batb":[[0,2.22,5.69],[1,2.2,41.67],[2,2,50]],"ltp":2.66,"tv":275.43,"id":25651861},{"batb":[[1,1.41,7.17],[2,1.4,62.76]],"ltp":1.5,"tv":489.05,"id":19587555}]}]}
{"op":"mcm","clk":"11982496718","pt":1724862589417,"mc":[{"id":"1.232375043","rc":[{"batl":[[0,1.58,12.15],[1,1.59,2],[2,1.61,8.38]],"ltp":1.5,"tv":489.05,"id":19587555}]}]}
{"op":"mcm","clk":"11982542488","pt":1724862920882,"mc":[{"id":"1.232375043","rc":[{"batb":[[0,1.41,7.35],[1,1.4,62.76],[2,1.38,16.76]],"ltp":1.5,"tv":489.05,"id":19587555}]}]}
{"op":"mcm","clk":"11982542618","pt":1724862921775,"mc":[{"id":"1.232375043","rc":[{"batb":[[0,1.41,12.61]],"ltp":1.5,"tv":489.05,"id":19587555}]}]}
{"op":"mcm","clk":"11982599515","pt":1724863352467,"mc":[{"id":"1.232375043","rc":[{"batl":[[0,1.57,2],[1,1.58,12.15]],"ltp":1.5,"tv":489.05,"id":19587555}]}]}
{"op":"mcm","clk":"11982604143","pt":1724863387619,"mc":[{"id":"1.232375043","rc":[{"batl":[[0,1.56,4.19],[1,1.57,2],[2,1.58,12.15]],"ltp":1.5,"tv":489.05,"id":19587555}]}]}
{"op":"mcm","clk":"11982609285","pt":1724863428435,"mc":[{"id":"1.232375043","rc":[{"batl":[[0,1.56,8.38]],"ltp":1.5,"tv":489.05,"id":19587555}]}]}
{"op":"mcm","clk":"11982675239","pt":1724864012755,"mc":[{"id":"1.232375043","rc":[{"trd":[[3,0.09]],"batb":[[0,3,19.22],[1,2.22,5.69],[2,2.2,41.67]],"ltp":3.0,"tv":275.52,"id":25651861},{"trd":[[1.5,278.01]],"batb":[[0,1.43,89.81],[1,1.41,12.43],[2,1.4,62.76]],"ltp":1.5,"tv":489.23,"id":19587555}],"tv":764.75}]}
{"op":"mcm","clk":"11982675355","pt":1724864013947,"mc":[{"id":"1.232375043","rc":[{"batb":[[1,1.41,7.17]],"ltp":1.5,"tv":489.23,"id":19587555}]}]}
{"op":"mcm","clk":"11982675682","pt":1724864017561,"mc":[{"id":"1.232375043","rc":[{"batb":[[0,3,19.31]],"ltp":3.0,"tv":275.52,"id":25651861}]}]}
{"op":"mcm","clk":"11982686317","pt":1724864124977,"mc":[{"id":"1.232375043","rc":[{"batl":[[0,1.55,2],[1,1.56,8.38]],"ltp":1.5,"tv":489.23,"id":19587555}]}]}
{"op":"mcm","clk":"11982697209","pt":1724864224866,"mc":[{"id":"1.232375043","rc":[{"batb":[[0,1.44,6.74],[1,1.43,89.81],[2,1.41,7.17]],"ltp":1.5,"tv":489.23,"id":19587555}]}]}
{"op":"mcm","clk":"11982698586","pt":1724864236455,"mc":[{"id":"1.232375043","rc":[{"batl":[[0,1.49,2],[1,1.55,2],[2,1.56,8.38]],"ltp":1.5,"tv":489.23,"id":19587555}]}]}
{"op":"mcm","clk":"11982706200","pt":1724864305869,"mc":[{"id":"1.232375043","rc":[{"batl":[[0,1.46,12.99],[1,1.49,2],[2,1.55,2]],"ltp":1.5,"tv":489.23,"id":19587555}]}]}
{"op":"mcm","clk":"11982724375","pt":1724864462366,"mc":[{"id":"1.232375043","rc":[{"trd":[[1.52,272.7]],"batb":[[1,2.22,5.7]],"ltp":3.0,"tv":275.78,"id":25651861},{"trd":[[1.5,278.28]],"batb":[[2,1.41,7.17]],"batl":[[0,1.49,2],[1,1.55,2],[2,1.56,8.38]],"ltp":1.5,"tv":489.5,"id":19587555}],"tv":765.29}]}
{"op":"mcm","clk":"11982725827","pt":1724864474272,"mc":[{"id":"1.232375043","rc":[{"batl":[[0,1.46,12.99],[1,1.49,2],[2,1.55,2]],"ltp":1.5,"tv":489.5,"id":19587555}]}]}
{"op":"mcm","clk":"11982726878","pt":1724864483392,"mc":[{"id":"1.232375043","rc":[{"batl":[[0,1.49,2],[1,1.55,2],[2,1.56,8.38]],"ltp":1.5,"tv":489.5,"id":19587555}]}]}
{"op":"mcm","clk":"11982728225","pt":1724864495497,"mc":[{"id":"1.232375043","rc":[{"batl":[[0,1.46,12.99],[1,1.49,2],[2,1.55,2]],"ltp":1.5,"tv":489.5,"id":19587555}]}]}
{"op":"mcm","clk":"11982734968","pt":1724864559294,"mc":[{"id":"1.232375043","rc":[{"batb":[[1,2.2,41.67],[2,2,50]],"ltp":3.0,"tv":275.78,"id":25651861},{"batb":[[2,1.4,62.76]],"ltp":1.5,"tv":489.5,"id":19587555}]}]}
{"op":"mcm","clk":"11982739305","pt":1724864601837,"mc":[{"id":"1.232375043","rc":[{"batb":[[0,1.44,11.48]],"ltp":1.5,"tv":489.5,"id":19587555}]}]}
{"op":"mcm","clk":"11982751332","pt":1724864715951,"mc":[{"id":"1.232375043","rc":[{"batl":[[1,1.49,6.19]],"ltp":1.5,"tv":489.5,"id":19587555}]}]}
{"op":"mcm","clk":"11982841620","pt":1724865370544,"mc":[{"id":"1.232375043","rc":[{"batl":[[0,1.49,6.19],[1,1.55,2],[2,1.56,8.38]],"ltp":1.5,"tv":489.5,"id":19587555}]}]}
{"op":"mcm","clk":"11982843587","pt":1724865384419,"mc":[{"id":"1.232375043","rc":[{"batl":[[0,1.45,12.99],[1,1.49,6.19],[2,1.55,2]],"ltp":1.5,"tv":489.5,"id":19587555}]}]}
{"op":"mcm","clk":"11982858171","pt":1724865499683,"mc":[{"id":"1.232375043","rc":[{"trd":[[1.44,8.38]],"batb":[[0,1.44,7.29]],"ltp":1.44,"tv":497.88,"id":19587555}],"tv":773.67}]}
{"op":"mcm","clk":"11982860022","pt":1724865514607,"mc":[{"id":"1.232375043","rc":[{"trd":[[1.44,16.77]],"batb":[[0,1.44,3.09]],"ltp":1.44,"tv":506.27,"id":19587555}],"tv":782.06}]}
{"op":"mcm","clk":"11982886401","pt":1724865741050,"mc":[{"id":"1.232375043","rc":[{"trd":[[3.2,5.89]],"batb":[[0,3.05,4],[1,3,19.31],[2,2.2,41.67]],"batl":[[0,3.2,36.16]],"ltp":3.2,"tv":281.67,"id":25651861},{"trd":[[1.45,12.99]],"batl":[[0,1.49,6.19],[1,1.55,2],[2,1.56,8.38]],"ltp":1.45,"tv":519.26,"id":19587555}],"tv":800.94}]}
{"op":"mcm","clk":"11982886562","pt":1724865742452,"mc":[{"id":"1.232375043","rc":[{"batb":[[0,1.43,89.81],[1,1.4,62.76],[2,1.38,16.76]],"batl":[[0,1.49,12.71]],"ltp":1.45,"tv":519.26,"id":19587555}]}]}
{"op":"mcm","clk":"11982886690","pt":1724865743443,"mc":[{"id":"1.232375043","rc":[{"batb":[[0,3,19.31],[1,2.2,41.67],[2,2,50]],"ltp":3.2,"tv":281.67,"id":25651861}]}]}
{"op":"mcm","clk":"11982887092","pt":1724865746836,"mc":[{"id":"1.232375043","rc":[{"batb":[[0,3.05,4],[1,3,19.31],[2,2.2,41.67]],"ltp":3.2,"tv":281.67,"id":25651861}]}]}
{"op":"mcm","clk":"11982887406","pt":1724865749727,"mc":[{"id":"1.232375043","rc":[{"batb":[[0,3,19.31],[1,2.2,41.67],[2,2,50]],"ltp":3.2,"tv":281.67,"id":25651861}]}]}
{"op":"mcm","clk":"11982887845","pt":1724865753411,"mc":[{"id":"1.232375043","rc":[{"batb":[[0,3.05,4],[1,3,19.31],[2,2.2,41.67]],"ltp":3.2,"tv":281.67,"id":25651861}]}]}
{"op":"mcm","clk":"11982888056","pt":1724865755044,"mc":[{"id":"1.232375043","rc":[{"batb":[[2,2.2,58.43]],"ltp":3.2,"tv":281.67,"id":25651861}]}]}
{"op":"mcm","clk":"11982888251","pt":1724865756631,"mc":[{"id":"1.232375043","rc":[{"batb":[[0,3,19.31],[1,2.2,58.43],[2,2,50]],"ltp":3.2,"tv":281.67,"id":25651861}]}]}
{"op":"mcm","clk":"11982888830","pt":1724865761928,"mc":[{"id":"1.232375043","rc":[{"batb":[[0,3.05,4],[1,3,19.31],[2,2.2,58.43]],"ltp":3.2,"tv":281.67,"id":25651861}]}]}
{"op":"mcm","clk":"11982889149","pt":1724865764762,"mc":[{"id":"1.232375043","rc":[{"batb":[[0,3,19.31],[1,2.2,58.43],[2,2,50]],"ltp":3.2,"tv":281.67,"id":25651861}]}]}
{"op":"mcm","clk":"11982890681","pt":1724865777973,"mc":[{"id":"1.232375043","rc":[{"trd":[[1.49,17.04]],"batb":[[0,1.49,23.44],[1,1.43,89.81],[2,1.4,62.76]],"batl":[[0,1.55,2],[1,1.56,8.38],[2,1.61,8.38]],"ltp":1.49,"tv":536.29,"id":19587555}],"tv":817.97}]}
{"op":"mcm","clk":"11982891785","pt":1724865787969,"mc":[{"id":"1.232375043","rc":[{"batb":[[0,1.43,89.81],[1,1.4,62.76],[2,1.38,16.76]],"ltp":1.49,"tv":536.29,"id":19587555}]}]}
{"op":"mcm","clk":"11982893234","pt":1724865800799,"mc":[{"id":"1.232375043","rc":[{"trd":[[3,19.4]],"batb":[[0,2.2,58.43],[1,2,50],[2,1.8,62.5]],"ltp":3.0,"tv":300.98,"id":25651861},{"trd":[[1.5,316.9]],"batb":[[0,1.5,19.95],[1,1.43,89.81],[2,1.4,62.76]],"ltp":1.5,"tv":574.91,"id":19587555}],"tv":875.9}]}
{"op":"mcm","clk":"11982893468","pt":1724865802806,"mc":[{"id":"1.232375043","rc":[{"batb":[[0,2.92,20.11],[1,2.2,58.43],[2,2,50]],"ltp":3.0,"tv":300.98,"id":25651861}]}]}
{"op":"mcm","clk":"11982895413","pt":1724865819806,"mc":[{"id":"1.232375043","rc":[{"batb":[[0,1.5,12.91]],"ltp":1.5,"tv":574.91,"id":19587555}]}]}
{"op":"mcm","clk":"11982895498","pt":1724865820538,"mc":[{"id":"1.232375043","rc":[{"batb":[[0,1.43,89.81],[1,1.4,62.76],[2,1.38,16.76]],"ltp":1.5,"tv":574.91,"id":19587555}]}]}
{"op":"mcm","clk":"11982898768","pt":1724865848258,"mc":[{"id":"1.232375043","rc":[{"trd":[[2.92,14.18]],"batb":[[0,2.92,13.02]],"ltp":2.92,"tv":315.16,"id":25651861}],"tv":890.08}]}
{"op":"mcm","clk":"11982899335","pt":1724865853275,"mc":[{"id":"1.232375043","rc":[{"batb":[[0,2.92,20.11]],"ltp":2.92,"tv":315.16,"id":25651861}]}]}
{"op":"mcm","clk":"11982900688","pt":1724865865168,"mc":[{"id":"1.232375043","rc":[{"batl":[[0,1.52,6.71],[1,1.55,2],[2,1.56,8.38]],"ltp":1.5,"tv":574.91,"id":19587555}]}]}
{"op":"mcm","clk":"11982901428","pt":1724865871305,"mc":[{"id":"1.232375043","rc":[{"batl":[[2,1.56,4.19]],"ltp":1.5,"tv":574.91,"id":19587555}]}]}
{"op":"mcm","clk":"11982908585","pt":1724865934673,"mc":[{"id":"1.232375043","rc":[{"batb":[[1,1.41,6.71],[2,1.4,62.76]],"ltp":1.5,"tv":574.91,"id":19587555}]}]}
{"op":"mcm","clk":"11982912240","pt":1724865965823,"mc":[{"id":"1.232375043","rc":[{"trd":[[1.43,33.46]],"batb":[[0,1.43,73.08]],"ltp":1.43,"tv":608.37,"id":19587555}],"tv":923.54}]}
{"op":"mcm","clk":"11982912530","pt":1724865968512,"mc":[{"id":"1.232375043","rc":[{"batb":[[0,1.43,89.81]],"ltp":1.43,"tv":608.37,"id":19587555}]}]}
{"op":"mcm","clk":"11982912953","pt":1724865972102,"mc":[{"id":"1.232375043","rc":[{"batb":[[1,1.41,18.44]],"ltp":1.43,"tv":608.37,"id":19587555}]}]}
{"op":"mcm","clk":"11982913214","pt":1724865974245,"mc":[{"id":"1.232375043","rc":[{"batb":[[0,1.44,6.74],[1,1.43,89.81],[2,1.41,18.44]],"ltp":1.43,"tv":608.37,"id":19587555}]}]}
{"op":"mcm","clk":"11982914524","pt":1724865985144,"mc":[{"id":"1.232375043","rc":[{"trd":[[1.44,17.59]],"batb":[[0,1.44,6.33]],"ltp":1.44,"tv":609.2,"id":19587555}],"tv":924.36}]}
{"op":"mcm","clk":"11982917910","pt":1724866013363,"mc":[{"id":"1.232375043","rc":[{"batb":[[0,1.45,2.06],[1,1.44,6.33],[2,1.43,89.81]],"ltp":1.44,"tv":609.2,"id":19587555}]}]}
{"op":"mcm","clk":"11982925749","pt":1724866083673,"mc":[{"id":"1.232375043","rc":[{"trd":[[1.45,17.11]],"batb":[[0,1.44,6.33],[1,1.43,89.81],[2,1.41,18.44]],"batl":[[0,1.45,2.94],[1,1.52,6.71],[2,1.55,2]],"ltp":1.45,"tv":613.32,"id":19587555}],"tv":928.48}]}
{"op":"mcm","clk":"11982930865","pt":1724866127916,"mc":[{"id":"1.232375043","rc":[{"batl":[[0,1.52,6.71],[1,1.55,2],[2,1.56,4.19]],"ltp":1.45,"tv":613.32,"id":19587555}]}]}
{"op":"mcm","clk":"11982961195","pt":1724866376224,"mc":[{"id":"1.232375043","rc":[{"trd":[[1.44,17.79]],"batb":[[0,1.44,6.23]],"ltp":1.44,"tv":613.52,"id":19587555}],"tv":928.69}]}
{"op":"mcm","clk":"11982962125","pt":1724866384714,"mc":[{"id":"1.232375043","rc":[{"trd":[[2.92,14.38]],"batb":[[0,2.92,20.01]],"ltp":2.92,"tv":315.36,"id":25651861}],"tv":928.89}]}
{"op":"mcm","clk":"11982962641","pt":1724866389635,"mc":[{"id":"1.232375043","rc":[{"batb":[[0,2.92,20.11]],"ltp":2.92,"tv":315.36,"id":25651861}]}]}
{"op":"mcm","clk":"11982993592","pt":1724866656779,"mc":[{"id":"1.232375043","rc":[{"batb":[[0,2.2,58.43],[1,2,50],[2,1.8,62.5]],"ltp":2.92,"tv":315.36,"id":25651861},{"batb":[[1,1.41,18.44],[2,1.4,62.76]],"ltp":1.44,"tv":613.52,"id":19587555}]}]}
{"op":"mcm","clk":"11982994051","pt":1724866660205,"mc":[{"id":"1.232375043","rc":[{"batb":[[0,1.41,18.44],[1,1.4,62.76],[2,1.38,16.76]],"ltp":1.44,"tv":613.52,"id":19587555}]}]}
{"op":"mcm","clk":"11983001563","pt":1724866721587,"mc":[{"id":"1.232375043","rc":[{"batb":[[0,1.41,23.46]],"ltp":1.44,"tv":613.52,"id":19587555}]}]}
{"op":"mcm","clk":"11983007142","pt":1724866768224,"mc":[{"id":"1.232375043","rc":[{"batb":[[0,1.42,83.67],[1,1.41,23.46],[2,1.4,62.76]],"ltp":1.44,"tv":613.52,"id":19587555}]}]}
{"op":"mcm","clk":"11983032619","pt":1724866980472,"mc":[{"id":"1.232375043","rc":[{"batb":[[0,1.43,6.29],[1,1.42,83.67],[2,1.41,23.46]],"ltp":1.44,"tv":613.52,"id":19587555}]}]}
{"op":"mcm","clk":"11983048075","pt":1724867111130,"mc":[{"id":"1.232375043","rc":[{"batb":[[0,2.22,9],[1,2.2,58.43],[2,2,50]],"batl":[[0,3.9,1]],"ltp":2.92,"tv":315.36,"id":25651861}]}]}
{"op":"mcm","clk":"11983048359","pt":1724867113305,"mc":[{"id":"1.232375043","rc":[{"batb":[[0,2.22,5]],"ltp":2.92,"tv":315.36,"id":25651861}]}]}
{"op":"mcm","clk":"11983048498","pt":1724867114316,"mc":[{"id":"1.232375043","rc":[{"batb":[[0,2.2,58.43],[1,2,50],[2,1.8,62.5]],"ltp":2.92,"tv":315.36,"id":25651861}]}]}
{"op":"mcm","clk":"11983048674","pt":1724867115638,"mc":[{"id":"1.232375043","rc":[{"batb":[[0,2.22,4],[1,2.2,58.43],[2,2,50]],"ltp":2.92,"tv":315.36,"id":25651861}]}]}
{"op":"mcm","clk":"11983048849","pt":1724867116930,"mc":[{"id":"1.232375043","rc":[{"batb":[[0,2.24,5],[1,2.22,4],[2,2.2,58.43]],"ltp":2.92,"tv":315.36,"id":25651861}]}]}
{"op":"mcm","clk":"11983049039","pt":1724867118414,"mc":[{"id":"1.232375043","rc":[{"batb":[[1,2.2,58.43],[2,2,50]],"ltp":2.92,"tv":315.36,"id":25651861}]}]}
{"op":"mcm","clk":"11983049409","pt":1724867121031,"mc":[{"id":"1.232375043","rc":[{"batb":[[0,2.22,4]],"ltp":2.92,"tv":315.36,"id":25651861}]}]}
{"op":"mcm","clk":"11983049770","pt":1724867123434,"mc":[{"id":"1.232375043","rc":[{"batb":[[0,2.2,58.43],[1,2,50],[2,1.8,62.5]],"ltp":2.92,"tv":315.36,"id":25651861}]}]}
{"op":"mcm","clk":"11983049843","pt":1724867123942,"mc":[{"id":"1.232375043","rc":[{"batb":[[0,2.22,5],[1,2.2,58.43],[2,2,50]],"ltp":2.92,"tv":315.36,"id":25651861}]}]}
{"op":"mcm","clk":"11983050309","pt":1724867127323,"mc":[{"id":"1.232375043","rc":[{"batb":[[0,2.2,58.43],[1,2,50],[2,1.8,62.5]],"ltp":2.92,"tv":315.36,"id":25651861}]}]}
{"op":"mcm","clk":"11983050385","pt":1724867127841,"mc":[{"id":"1.232375043","rc":[{"batb":[[0,2.22,4],[1,2.2,58.43],[2,2,50]],"ltp":2.92,"tv":315.36,"id":25651861}]}]}
{"op":"mcm","clk":"11983050722","pt":1724867130334,"mc":[{"id":"1.232375043","rc":[{"batb":[[0,2.24,5]],"ltp":2.92,"tv":315.36,"id":25651861}]}]}
{"op":"mcm","clk":"11983051050","pt":1724867132743,"mc":[{"id":"1.232375043","rc":[{"batb":[[0,2.26,4],[1,2.24,5],[2,2.2,58.43]],"ltp":2.92,"tv":315.36,"id":25651861}]}]}
{"op":"mcm","clk":"11983051269","pt":1724867134332,"mc":[{"id":"1.232375043","rc":[{"batb":[[1,2.2,58.43],[2,2,50]],"ltp":2.92,"tv":315.36,"id":25651861}]}]}
{"op":"mcm","clk":"11983051371","pt":1724867135031,"mc":[{"id":"1.232375043","rc":[{"batb":[[0,2.2,58.43],[1,2,50],[2,1.8,62.5]],"ltp":2.92,"tv":315.36,"id":25651861}]}]}
{"op":"mcm","clk":"11983051756","pt":1724867137938,"mc":[{"id":"1.232375043","rc":[{"batb":[[0,2.22,9],[1,2.2,58.43],[2,2,50]],"ltp":2.92,"tv":315.36,"id":25651861}]}]}
{"op":"mcm","clk":"11983052169","pt":1724867140881,"mc":[{"id":"1.232375043","rc":[{"batb":[[0,2.22,5]],"ltp":2.92,"tv":315.36,"id":25651861}]}]}
{"op":"mcm","clk":"11983052344","pt":1724867142043,"mc":[{"id":"1.232375043","rc":[{"batb":[[0,2.2,58.43],[1,2,50],[2,1.8,62.5]],"ltp":2.92,"tv":315.36,"id":25651861}]}]}
{"op":"mcm","clk":"11983052666","pt":1724867144568,"mc":[{"id":"1.232375043","rc":[{"batb":[[0,2.22,9],[1,2.2,58.43],[2,2,50]],"ltp":2.92,"tv":315.36,"id":25651861}]}]}
{"op":"mcm","clk":"11983053071","pt":1724867147562,"mc":[{"id":"1.232375043","rc":[{"batb":[[0,2.22,5]],"ltp":2.92,"tv":315.36,"id":25651861}]}]}
{"op":"mcm","clk":"11983053211","pt":1724867148547,"mc":[{"id":"1.232375043","rc":[{"batb":[[0,2.2,58.43],[1,2,50],[2,1.8,62.5]],"ltp":2.92,"tv":315.36,"id":25651861}]}]}
{"op":"mcm","clk":"11983053617","pt":1724867151967,"mc":[{"id":"1.232375043","rc":[{"batb":[[0,2.22,9],[1,2.2,58.43],[2,2,50]],"ltp":2.92,"tv":315.36,"id":25651861}]}]}
{"op":"mcm","clk":"11983054031","pt":1724867155187,"mc":[{"id":"1.232375043","rc":[{"batb":[[0,2.22,5]],"ltp":2.92,"tv":315.36,"id":25651861}]}]}
{"op":"mcm","clk":"11983054148","pt":1724867156197,"mc":[{"id":"1.232375043","rc":[{"batb":[[0,2.2,58.43],[1,2,50],[2,1.8,62.5]],"ltp":2.92,"tv":315.36,"id":25651861}]}]}
{"op":"mcm","clk":"11983054480","pt":1724867158580,"mc":[{"id":"1.232375043","rc":[{"batb":[[0,2.22,9],[1,2.2,58.43],[2,2,50]],"ltp":2.92,"tv":315.36,"id":25651861}]}]}
{"op":"mcm","clk":"11983054884","pt":1724867161657,"mc":[{"id":"1.232375043","rc":[{"batb":[[0,2.22,5]],"ltp":2.92,"tv":315.36,"id":25651861}]}]}
{"op":"mcm","clk":"11983055033","pt":1724867162773,"mc":[{"id":"1.232375043","rc":[{"batb":[[0,2.2,58.43],[1,2,50],[2,1.8,62.5]],"ltp":2.92,"tv":315.36,"id":25651861}]}]}
{"op":"mcm","clk":"11983055410","pt":1724867165272,"mc":[{"id":"1.232375043","rc":[{"batb":[[0,2.22,9],[1,2.2,58.43],[2,2,50]],"ltp":2.92,"tv":315.36,"id":25651861}]}]}
{"op":"mcm","clk":"11983055830","pt":1724867168292,"mc":[{"id":"1.232375043","rc":[{"batb":[[0,2.22,5]],"ltp":2.92,"tv":315.36,"id":25651861}]}]}
{"op":"mcm","clk":"11983055966","pt":1724867169393,"mc":[{"id":"1.232375043","rc":[{"batb":[[0,2.2,58.43],[1,2,50],[2,1.8,62.5]],"ltp":2.92,"tv":315.36,"id":25651861}]}]}
{"op":"mcm","clk":"11983056161","pt":1724867170882,"mc":[{"id":"1.232375043","rc":[{"batb":[[0,2.22,4],[1,2.2,58.43],[2,2,50]],"ltp":2.92,"tv":315.36,"id":25651861}]}]}
{"op":"mcm","clk":"11983056324","pt":1724867172107,"mc":[{"id":"1.232375043","rc":[{"batb":[[0,2.24,5],[1,2.22,4],[2,2.2,58.43]],"ltp":2.92,"tv":315.36,"id":25651861}]}]}
{"op":"mcm","clk":"11983056618","pt":1724867174204,"mc":[{"id":"1.232375043","rc":[{"batb":[[1,2.2,58.43],[2,2,50]],"ltp":2.92,"tv":315.36,"id":25651861}]}]}
{"op":"mcm","clk":"11983056872","pt":1724867175988,"mc":[{"id":"1.232375043","rc":[{"batb":[[0,2.2,58.43],[1,2,50],[2,1.8,62.5]],"ltp":2.92,"tv":315.36,"id":25651861}]}]}
{"op":"mcm","clk":"11983057245","pt":1724867178523,"mc":[{"id":"1.232375043","rc":[{"batb":[[0,2.22,9],[1,2.2,58.43],[2,2,50]],"ltp":2.92,"tv":315.36,"id":25651861}]}]}
{"op":"mcm","clk":"11983057625","pt":1724867181313,"mc":[{"id":"1.232375043","rc":[{"batb":[[0,2.22,5]],"ltp":2.92,"tv":315.36,"id":25651861}]}]}
{"op":"mcm","clk":"11983057743","pt":1724867182207,"mc":[{"id":"1.232375043","rc":[{"batb":[[0,2.2,58.43],[1,2,50],[2,1.8,62.5]],"ltp":2.92,"tv":315.36,"id":25651861}]}]}
{"op":"mcm","clk":"11983058222","pt":1724867186027,"mc":[{"id":"1.232375043","rc":[{"batb":[[0,2.22,9],[1,2.2,58.43],[2,2,50]],"ltp":2.92,"tv":315.36,"id":25651861}]}]}
{"op":"mcm","clk":"11983058629","pt":1724867189085,"mc":[{"id":"1.232375043","rc":[{"batb":[[0,2.22,5]],"ltp":2.92,"tv":315.36,"id":25651861}]}]}
{"op":"mcm","clk":"11983058756","pt":1724867190192,"mc":[{"id":"1.232375043","rc":[{"batb":[[0,2.2,58.43],[1,2,50],[2,1.8,62.5]],"ltp":2.92,"tv":315.36,"id":25651861}]}]}
{"op":"mcm","clk":"11983059073","pt":1724867192315,"mc":[{"id":"1.232375043","rc":[{"batb":[[0,2.22,4],[1,2.2,58.43],[2,2,50]],"ltp":2.92,"tv":315.36,"id":25651861}]}]}
{"op":"mcm","clk":"11983059171","pt":1724867192932,"mc":[{"id":"1.232375043","rc":[{"batb":[[0,2.24,5],[1,2.22,4],[2,2.2,58.43]],"ltp":2.92,"tv":315.36,"id":25651861}]}]}
{"op":"mcm","clk":"11983059492","pt":1724867195149,"mc":[{"id":"1.232375043","rc":[{"batb":[[1,2.2,58.43],[2,2,50]],"ltp":2.92,"tv":315.36,"id":25651861}]}]}
{"op":"mcm","clk":"11983059731","pt":1724867196627,"mc":[{"id":"1.232375043","rc":[{"batb":[[0,2.2,58.43],[1,2,50],[2,1.8,62.5]],"ltp":2.92,"tv":315.36,"id":25651861}]}]}
{"op":"mcm","clk":"11983060007","pt":1724867198731,"mc":[{"id":"1.232375043","rc":[{"batb":[[0,2.22,4],[1,2.2,58.43],[2,2,50]],"ltp":2.92,"tv":315.36,"id":25651861}]}]}
{"op":"mcm","clk":"11983060135","pt":1724867199730,"mc":[{"id":"1.232375043","rc":[{"batb":[[0,2.24,5],[1,2.22,4],[2,2.2,58.43]],"ltp":2.92,"tv":315.36,"id":25651861}]}]}
{"op":"mcm","clk":"11983060480","pt":1724867202146,"mc":[{"id":"1.232375043","rc":[{"batb":[[1,2.2,58.43],[2,2,50]],"ltp":2.92,"tv":315.36,"id":25651861}]}]}
{"op":"mcm","clk":"11983060684","pt":1724867203677,"mc":[{"id":"1.232375043","rc":[{"batb":[[0,2.2,58.43],[1,2,50],[2,1.8,62.5]],"ltp":2.92,"tv":315.36,"id":25651861}]}]}
{"op":"mcm","clk":"11983060973","pt":1724867205808,"mc":[{"id":"1.232375043","rc":[{"batb":[[0,2.22,4],[1,2.2,58.43],[2,2,50]],"ltp":2.92,"tv":315.36,"id":25651861}]}]}
{"op":"mcm","clk":"11983061162","pt":1724867207233,"mc":[{"id":"1.232375043","rc":[{"batb":[[0,2.24,5],[1,2.22,4],[2,2.2,58.43]],"batl":[[0,3.8,1]],"ltp":2.92,"tv":315.36,"id":25651861}]}]}
{"op":"mcm","clk":"11983061420","pt":1724867208871,"mc":[{"id":"1.232375043","rc":[{"batb":[[1,2.2,58.43],[2,2,50]],"ltp":2.92,"tv":315.36,"id":25651861}]}]}
{"op":"mcm","clk":"11983061620","pt":1724867210502,"mc":[{"id":"1.232375043","rc":[{"batb":[[0,2.2,58.43],[1,2,50],[2,1.8,62.5]],"ltp":2.92,"tv":315.36,"id":25651861}]}]}
{"op":"mcm","clk":"11983061852","pt":1724867212073,"mc":[{"id":"1.232375043","rc":[{"batb":[[0,2.22,4],[1,2.2,58.43],[2,2,50]],"ltp":2.92,"tv":315.36,"id":25651861}]}]}
{"op":"mcm","clk":"11983061983","pt":1724867213166,"mc":[{"id":"1.232375043","rc":[{"batb":[[0,2.24,5],[1,2.22,4],[2,2.2,58.43]],"ltp":2.92,"tv":315.36,"id":25651861}]}]}
{"op":"mcm","clk":"11983062244","pt":1724867215274,"mc":[{"id":"1.232375043","rc":[{"batb":[[1,2.2,58.43],[2,2,50]],"ltp":2.92,"tv":315.36,"id":25651861}]}]}
{"op":"mcm","clk":"11983062423","pt":1724867216792,"mc":[{"id":"1.232375043","rc":[{"batb":[[0,2.2,58.43],[1,2,50],[2,1.8,62.5]],"ltp":2.92,"tv":315.36,"id":25651861}]}]}
{"op":"mcm","clk":"11983062668","pt":1724867218658,"mc":[{"id":"1.232375043","rc":[{"batb":[[0,2.22,4],[1,2.2,58.43],[2,2,50]],"ltp":2.92,"tv":315.36,"id":25651861}]}]}
{"op":"mcm","clk":"11983062803","pt":1724867219698,"mc":[{"id":"1.232375043","rc":[{"batb":[[0,2.24,5],[1,2.22,4],[2,2.2,58.43]],"ltp":2.92,"tv":315.36,"id":25651861}]}]}
{"op":"mcm","clk":"11983063053","pt":1724867221790,"mc":[{"id":"1.232375043","rc":[{"batb":[[1,2.2,58.43],[2,2,50]],"ltp":2.92,"tv":315.36,"id":25651861}]}]}
{"op":"mcm","clk":"11983063245","pt":1724867223070,"mc":[{"id":"1.232375043","rc":[{"batb":[[0,2.2,58.43],[1,2,50],[2,1.8,62.5]],"ltp":2.92,"tv":315.36,"id":25651861}]}]}
{"op":"mcm","clk":"11983063538","pt":1724867225259,"mc":[{"id":"1.232375043","rc":[{"batb":[[0,2.22,4],[1,2.2,58.43],[2,2,50]],"ltp":2.92,"tv":315.36,"id":25651861}]}]}
{"op":"mcm","clk":"11983063659","pt":1724867226271,"mc":[{"id":"1.232375043","rc":[{"batb":[[0,2.24,5],[1,2.22,4],[2,2.2,58.43]],"ltp":2.92,"tv":315.36,"id":25651861}]}]}
{"op":"mcm","clk":"11983063950","pt":1724867228386,"mc":[{"id":"1.232375043","rc":[{"batb":[[1,2.2,58.43],[2,2,50]],"ltp":2.92,"tv":315.36,"id":25651861}]}]}
{"op":"mcm","clk":"11983064158","pt":1724867229785,"mc":[{"id":"1.232375043","rc":[{"batb":[[0,2.2,58.43],[1,2,50],[2,1.8,62.5]],"ltp":2.92,"tv":315.36,"id":25651861}]}]}
{"op":"mcm","clk":"11983064414","pt":1724867231675,"mc":[{"id":"1.232375043","rc":[{"batb":[[0,2.22,4],[1,2.2,58.43],[2,2,50]],"ltp":2.92,"tv":315.36,"id":25651861}]}]}
{"op":"mcm","clk":"11983064564","pt":1724867232894,"mc":[{"id":"1.232375043","rc":[{"batb":[[0,2.24,5],[1,2.22,4],[2,2.2,58.43]],"ltp":2.92,"tv":315.36,"id":25651861}]}]}
{"op":"mcm","clk":"11983064867","pt":1724867234876,"mc":[{"id":"1.232375043","rc":[{"batb":[[1,2.2,58.43],[2,2,50]],"ltp":2.92,"tv":315.36,"id":25651861}]}]}
{"op":"mcm","clk":"11983065080","pt":1724867236499,"mc":[{"id":"1.232375043","rc":[{"batb":[[0,2.2,58.43],[1,2,50],[2,1.8,62.5]],"ltp":2.92,"tv":315.36,"id":25651861}]}]}
{"op":"mcm","clk":"11983065388","pt":1724867238296,"mc":[{"id":"1.232375043","rc":[{"batb":[[0,2.22,4],[1,2.2,58.43],[2,2,50]],"ltp":2.92,"tv":315.36,"id":25651861}]}]}
{"op":"mcm","clk":"11983065556","pt":1724867239501,"mc":[{"id":"1.232375043","rc":[{"batb":[[0,2.24,5],[1,2.22,4],[2,2.2,58.43]],"ltp":2.92,"tv":315.36,"id":25651861}]}]}
{"op":"mcm","clk":"11983065889","pt":1724867241614,"mc":[{"id":"1.232375043","rc":[{"batb":[[1,2.2,58.43],[2,2,50]],"ltp":2.92,"tv":315.36,"id":25651861}]}]}
{"op":"mcm","clk":"11983066109","pt":1724867242980,"mc":[{"id":"1.232375043","rc":[{"batb":[[0,2.2,58.43],[1,2,50],[2,1.8,62.5]],"ltp":2.92,"tv":315.36,"id":25651861},{"batl":[[1,1.54,35.23],[2,1.55,2]],"ltp":1.44,"tv":613.52,"id":19587555}]}]}
{"op":"mcm","clk":"11983066366","pt":1724867244941,"mc":[{"id":"1.232375043","rc":[{"batb":[[0,2.22,4],[1,2.2,58.43],[2,2,50]],"ltp":2.92,"tv":315.36,"id":25651861}]}]}
{"op":"mcm","clk":"11983066510","pt":1724867245915,"mc":[{"id":"1.232375043","rc":[{"batb":[[0,2.24,5],[1,2.22,4],[2,2.2,58.43]],"ltp":2.92,"tv":315.36,"id":25651861}]}]}
{"op":"mcm","clk":"11983066789","pt":1724867248029,"mc":[{"id":"1.232375043","rc":[{"batb":[[1,2.2,58.43],[2,2,50]],"ltp":2.92,"tv":315.36,"id":25651861}]}]}
{"op":"mcm","clk":"11983067020","pt":1724867249631,"mc":[{"id":"1.232375043","rc":[{"batb":[[0,2.2,58.43],[1,2,50],[2,1.8,62.5]],"ltp":2.92,"tv":315.36,"id":25651861}]}]}
{"op":"mcm","clk":"11983067274","pt":1724867251412,"mc":[{"id":"1.232375043","rc":[{"batb":[[0,2.22,4],[1,2.2,58.43],[2,2,50]],"ltp":2.92,"tv":315.36,"id":25651861}]}]}
{"op":"mcm","clk":"11983067400","pt":1724867252321,"mc":[{"id":"1.232375043","rc":[{"batb":[[0,2.24,5],[1,2.22,4],[2,2.2,58.43]],"ltp":2.92,"tv":315.36,"id":25651861}]}]}
{"op":"mcm","clk":"11983067726","pt":1724867254536,"mc":[{"id":"1.232375043","rc":[{"batb":[[1,2.2,58.43],[2,2,50]],"ltp":2.92,"tv":315.36,"id":25651861}]}]}
{"op":"mcm","clk":"11983067959","pt":1724867256039,"mc":[{"id":"1.232375043","rc":[{"batb":[[0,2.2,58.43],[1,2,50],[2,1.8,62.5]],"ltp":2.92,"tv":315.36,"id":25651861}]}]}
{"op":"mcm","clk":"11983068256","pt":1724867258106,"mc":[{"id":"1.232375043","rc":[{"batb":[[0,2.22,4],[1,2.2,58.43],[2,2,50]],"ltp":2.92,"tv":315.36,"id":25651861}]}]}
{"op":"mcm","clk":"11983068394","pt":1724867259101,"mc":[{"id":"1.232375043","rc":[{"batb":[[0,2.24,5],[1,2.22,4],[2,2.2,58.43]],"ltp":2.92,"tv":315.36,"id":25651861}]}]}
{"op":"mcm","clk":"11983068576","pt":1724867260412,"mc":[{"id":"1.232375043","rc":[{"batb":[[1,1.41,23.46],[2,1.4,62.76]],"ltp":1.44,"tv":613.52,"id":19587555}]}]}
{"op":"mcm","clk":"11983068736","pt":1724867261431,"mc":[{"id":"1.232375043","rc":[{"batb":[[1,2.2,58.43],[2,2,50]],"ltp":2.92,"tv":315.36,"id":25651861},{"batb":[[0,1.41,23.46],[1,1.4,62.76],[2,1.38,16.76]],"ltp":1.44,"tv":613.52,"id":19587555}]}]}
{"op":"mcm","clk":"11983068955","pt":1724867262751,"mc":[{"id":"1.232375043","rc":[{"batb":[[0,2.2,58.43],[1,2,50],[2,1.8,62.5]],"ltp":2.92,"tv":315.36,"id":25651861}]}]}
{"op":"mcm","clk":"11983069185","pt":1724867264146,"mc":[{"id":"1.232375043","rc":[{"batb":[[0,2.22,4],[1,2.2,58.43],[2,2,50]],"ltp":2.92,"tv":315.36,"id":25651861}]}]}
{"op":"mcm","clk":"11983069329","pt":1724867265039,"mc":[{"id":"1.232375043","rc":[{"batb":[[0,2.24,5],[1,2.22,4],[2,2.2,58.43]],"ltp":2.92,"tv":315.36,"id":25651861}]}]}
{"op":"mcm","clk":"11983069632","pt":1724867267240,"mc":[{"id":"1.232375043","rc":[{"batb":[[1,2.2,58.43],[2,2,50]],"ltp":2.92,"tv":315.36,"id":25651861}]}]}
{"op":"mcm","clk":"11983069849","pt":1724867268836,"mc":[{"id":"1.232375043","rc":[{"batb":[[0,2.2,58.43],[1,2,50],[2,1.8,62.5]],"ltp":2.92,"tv":315.36,"id":25651861}]}]}
{"op":"mcm","clk":"11983070081","pt":1724867270527,"mc":[{"id":"1.232375043","rc":[{"batb":[[0,2.22,4],[1,2.2,58.43],[2,2,50]],"ltp":2.92,"tv":315.36,"id":25651861}]}]}
{"op":"mcm","clk":"11983070193","pt":1724867271322,"mc":[{"id":"1.232375043","rc":[{"batb":[[0,2.24,5],[1,2.22,4],[2,2.2,58.43]],"ltp":2.92,"tv":315.36,"id":25651861}]}]}
{"op":"mcm","clk":"11983070541","pt":1724867273745,"mc":[{"id":"1.232375043","rc":[{"batb":[[1,2.2,58.43],[2,2,50]],"ltp":2.92,"tv":315.36,"id":25651861}]}]}
{"op":"mcm","clk":"11983070746","pt":1724867275073,"mc":[{"id":"1.232375043","rc":[{"batb":[[0,2.2,58.43],[1,2,50],[2,1.8,62.5]],"ltp":2.92,"tv":315.36,"id":25651861}]}]}
{"op":"mcm","clk":"11983071036","pt":1724867277034,"mc":[{"id":"1.232375043","rc":[{"batb":[[0,2.22,4],[1,2.2,58.43],[2,2,50]],"ltp":2.92,"tv":315.36,"id":25651861}]}]}
{"op":"mcm","clk":"11983071107","pt":1724867277557,"mc":[{"id":"1.232375043","rc":[{"batb":[[0,2.24,5],[1,2.22,4],[2,2.2,58.43]],"ltp":2.92,"tv":315.36,"id":25651861}]}]}
{"op":"mcm","clk":"11983071412","pt":1724867279739,"mc":[{"id":"1.232375043","rc":[{"batb":[[1,2.2,58.43],[2,2,50]],"ltp":2.92,"tv":315.36,"id":25651861}]}]}
{"op":"mcm","clk":"11983071663","pt":1724867281542,"mc":[{"id":"1.232375043","rc":[{"batb":[[0,2.2,58.43],[1,2,50],[2,1.8,62.5]],"ltp":2.92,"tv":315.36,"id":25651861}]}]}
{"op":"mcm","clk":"11983072030","pt":1724867284446,"mc":[{"id":"1.232375043","rc":[{"batb":[[0,2.22,9],[1,2.2,58.43],[2,2,50]],"ltp":2.92,"tv":315.36,"id":25651861}]}]}
{"op":"mcm","clk":"11983072397","pt":1724867287156,"mc":[{"id":"1.232375043","rc":[{"batb":[[0,2.22,5]],"ltp":2.92,"tv":315.36,"id":25651861}]}]}
{"op":"mcm","clk":"11983072479","pt":1724867287839,"mc":[{"id":"1.232375043","rc":[{"batb":[[0,2.2,58.43],[1,2,50],[2,1.8,62.5]],"ltp":2.92,"tv":315.36,"id":25651861}]}]}
{"op":"mcm","clk":"11983072825","pt":1724867290474,"mc":[{"id":"1.232375043","rc":[{"batb":[[0,2.22,9],[1,2.2,58.43],[2,2,50]],"ltp":2.92,"tv":315.36,"id":25651861}]}]}
{"op":"mcm","clk":"11983073226","pt":1724867293371,"mc":[{"id":"1.232375043","rc":[{"batb":[[0,2.22,5]],"ltp":2.92,"tv":315.36,"id":25651861}]}]}
{"op":"mcm","clk":"11983073353","pt":1724867294264,"mc":[{"id":"1.232375043","rc":[{"batb":[[0,2.2,58.43],[1,2,50],[2,1.8,62.5]],"ltp":2.92,"tv":315.36,"id":25651861}]}]}
{"op":"mcm","clk":"11983073671","pt":1724867296793,"mc":[{"id":"1.232375043","rc":[{"batb":[[0,2.22,9],[1,2.2,58.43],[2,2,50]],"ltp":2.92,"tv":315.36,"id":25651861}]}]}
{"op":"mcm","clk":"11983074022","pt":1724867299794,"mc":[{"id":"1.232375043","rc":[{"batb":[[0,2.22,5]],"ltp":2.92,"tv":315.36,"id":25651861}]}]}
{"op":"mcm","clk":"11983074161","pt":1724867300748,"mc":[{"id":"1.232375043","rc":[{"batb":[[0,2.2,58.43],[1,2,50],[2,1.8,62.5]],"ltp":2.92,"tv":315.36,"id":25651861}]}]}
{"op":"mcm","clk":"11983074502","pt":1724867303283,"mc":[{"id":"1.232375043","rc":[{"batb":[[0,2.22,9],[1,2.2,58.43],[2,2,50]],"ltp":2.92,"tv":315.36,"id":25651861}]}]}
{"op":"mcm","clk":"11983074903","pt":1724867306351,"mc":[{"id":"1.232375043","rc":[{"batb":[[0,2.22,5]],"ltp":2.92,"tv":315.36,"id":25651861}]}]}
{"op":"mcm","clk":"11983075053","pt":1724867307612,"mc":[{"id":"1.232375043","rc":[{"batb":[[0,2.2,58.43],[1,2,50],[2,1.8,62.5]],"ltp":2.92,"tv":315.36,"id":25651861}]}]}
{"op":"mcm","clk":"11983075376","pt":1724867309992,"mc":[{"id":"1.232375043","rc":[{"batb":[[0,2.22,9],[1,2.2,58.43],[2,2,50]],"ltp":2.92,"tv":315.36,"id":25651861}]}]}
{"op":"mcm","clk":"11983075772","pt":1724867313179,"mc":[{"id":"1.232375043","rc":[{"batb":[[0,2.22,5]],"ltp":2.92,"tv":315.36,"id":25651861}]}]}
{"op":"mcm","clk":"11983075854","pt":1724867314022,"mc":[{"id":"1.232375043","rc":[{"batb":[[0,2.2,58.43],[1,2,50],[2,1.8,62.5]],"ltp":2.92,"tv":315.36,"id":25651861}]}]}
{"op":"mcm","clk":"11983076186","pt":1724867316688,"mc":[{"id":"1.232375043","rc":[{"batb":[[0,2.22,9],[1,2.2,58.43],[2,2,50]],"ltp":2.92,"tv":315.36,"id":25651861}]}]}
{"op":"mcm","clk":"11983076609","pt":1724867319792,"mc":[{"id":"1.232375043","rc":[{"batb":[[0,2.22,5]],"ltp":2.92,"tv":315.36,"id":25651861}]}]}
{"op":"mcm","clk":"11983076748","pt":1724867320895,"mc":[{"id":"1.232375043","rc":[{"batb":[[0,2.2,58.43],[1,2,50],[2,1.8,62.5]],"ltp":2.92,"tv":315.36,"id":25651861}]}]}
{"op":"mcm","clk":"11983077026","pt":1724867323197,"mc":[{"id":"1.232375043","rc":[{"batb":[[0,2.22,9],[1,2.2,58.43],[2,2,50]],"ltp":2.92,"tv":315.36,"id":25651861}]}]}
{"op":"mcm","clk":"11983077418","pt":1724867326618,"mc":[{"id":"1.232375043","rc":[{"batb":[[0,2.22,5]],"ltp":2.92,"tv":315.36,"id":25651861}]}]}
{"op":"mcm","clk":"11983077574","pt":1724867327813,"mc":[{"id":"1.232375043","rc":[{"batb":[[0,2.2,58.43],[1,2,50],[2,1.8,62.5]],"ltp":2.92,"tv":315.36,"id":25651861}]}]}
{"op":"mcm","clk":"11983077951","pt":1724867330709,"mc":[{"id":"1.232375043","rc":[{"batb":[[0,2.22,9],[1,2.2,58.43],[2,2,50]],"ltp":2.92,"tv":315.36,"id":25651861}]}]}
{"op":"mcm","clk":"11983078409","pt":1724867334020,"mc":[{"id":"1.232375043","rc":[{"batb":[[0,2.22,5]],"ltp":2.92,"tv":315.36,"id":25651861}]}]}
{"op":"mcm","clk":"11983078513","pt":1724867334917,"mc":[{"id":"1.232375043","rc":[{"batb":[[0,2.2,58.43],[1,2,50],[2,1.8,62.5]],"ltp":2.92,"tv":315.36,"id":25651861}]}]}
{"op":"mcm","clk":"11983078737","pt":1724867336538,"mc":[{"id":"1.232375043","rc":[{"batb":[[0,2.22,4],[1,2.2,58.43],[2,2,50]],"ltp":2.92,"tv":315.36,"id":25651861}]}]}
{"op":"mcm","clk":"11983078896","pt":1724867337698,"mc":[{"id":"1.232375043","rc":[{"batb":[[0,2.24,5],[1,2.22,4],[2,2.2,58.43]],"ltp":2.92,"tv":315.36,"id":25651861}]}]}
{"op":"mcm","clk":"11983079111","pt":1724867339426,"mc":[{"id":"1.232375043","rc":[{"batb":[[1,2.2,58.43],[2,2,50]],"ltp":2.92,"tv":315.36,"id":25651861}]}]}
{"op":"mcm","clk":"11983079360","pt":1724867341320,"mc":[{"id":"1.232375043","rc":[{"batb":[[0,2.2,58.43],[1,2,50],[2,1.8,62.5]],"ltp":2.92,"tv":315.36,"id":25651861}]}]}
{"op":"mcm","clk":"11983079579","pt":1724867343000,"mc":[{"id":"1.232375043","rc":[{"batb":[[0,2.22,4],[1,2.2,58.43],[2,2,50]],"ltp":2.92,"tv":315.36,"id":25651861}]}]}
{"op":"mcm","clk":"11983079731","pt":1724867344210,"mc":[{"id":"1.232375043","rc":[{"batb":[[0,2.24,5],[1,2.22,4],[2,2.2,58.43]],"ltp":2.92,"tv":315.36,"id":25651861}]}]}
{"op":"mcm","clk":"11983079910","pt":1724867345723,"mc":[{"id":"1.232375043","rc":[{"batb":[[1,2.2,58.43],[2,2,50]],"ltp":2.92,"tv":315.36,"id":25651861}]}]}
{"op":"mcm","clk":"11983080205","pt":1724867348041,"mc":[{"id":"1.232375043","rc":[{"batb":[[0,2.22,4]],"ltp":2.92,"tv":315.36,"id":25651861}]}]}
{"op":"mcm","clk":"11983080583","pt":1724867350847,"mc":[{"id":"1.232375043","rc":[{"batb":[[0,2.24,5]],"ltp":2.92,"tv":315.36,"id":25651861}]}]}
{"op":"mcm","clk":"11983080871","pt":1724867353007,"mc":[{"id":"1.232375043","rc":[{"batb":[[0,2.26,4],[1,2.24,5],[2,2.2,58.43]],"ltp":2.92,"tv":315.36,"id":25651861}]}]}
{"op":"mcm","clk":"11983081021","pt":1724867353949,"mc":[{"id":"1.232375043","rc":[{"batb":[[1,2.2,58.43],[2,2,50]],"ltp":2.92,"tv":315.36,"id":25651861}]}]}
{"op":"mcm","clk":"11983081251","pt":1724867355537,"mc":[{"id":"1.232375043","rc":[{"batb":[[0,2.2,58.43],[1,2,50],[2,1.8,62.5]],"ltp":2.92,"tv":315.36,"id":25651861}]}]}
{"op":"mcm","clk":"11983081436","pt":1724867356932,"mc":[{"id":"1.232375043","rc":[{"batb":[[0,2.22,5],[1,2.2,58.43],[2,2,50]],"ltp":2.92,"tv":315.36,"id":25651861}]}]}
{"op":"mcm","clk":"11983081624","pt":1724867358438,"mc":[{"id":"1.232375043","rc":[{"batb":[[0,2.24,4],[1,2.22,5],[2,2.2,58.43]],"ltp":2.92,"tv":315.36,"id":25651861}]}]}
{"op":"mcm","clk":"11983081876","pt":1724867360339,"mc":[{"id":"1.232375043","rc":[{"batb":[[1,2.2,58.43],[2,2,50]],"ltp":2.92,"tv":315.36,"id":25651861}]}]}
{"op":"mcm","clk":"11983081992","pt":1724867361255,"mc":[{"id":"1.232375043","rc":[{"batb":[[0,2.2,58.43],[1,2,50],[2,1.8,62.5]],"ltp":2.92,"tv":315.36,"id":25651861}]}]}
{"op":"mcm","clk":"11983082158","pt":1724867362770,"mc":[{"id":"1.232375043","rc":[{"batb":[[0,2.22,5],[1,2.2,58.43],[2,2,50]],"ltp":2.92,"tv":315.36,"id":25651861}]}]}
{"op":"mcm","clk":"11983082357","pt":1724867364273,"mc":[{"id":"1.232375043","rc":[{"batb":[[0,2.24,4],[1,2.22,5],[2,2.2,58.43]],"ltp":2.92,"tv":315.36,"id":25651861}]}]}
{"op":"mcm","clk":"11983082605","pt":1724867366380,"mc":[{"id":"1.232375043","rc":[{"batb":[[1,2.2,58.43],[2,2,50]],"ltp":2.92,"tv":315.36,"id":25651861}]}]}
{"op":"mcm","clk":"11983082665","pt":1724867366855,"mc":[{"id":"1.232375043","rc":[{"batb":[[0,2.2,58.43],[1,2,50],[2,1.8,62.5]],"ltp":2.92,"tv":315.36,"id":25651861}]}]}
{"op":"mcm","clk":"11983083132","pt":1724867370890,"mc":[{"id":"1.232375043","rc":[{"batb":[[0,2.22,9],[1,2.2,58.43],[2,2,50]],"ltp":2.92,"tv":315.36,"id":25651861}]}]}
{"op":"mcm","clk":"11983083471","pt":1724867373689,"mc":[{"id":"1.232375043","rc":[{"batb":[[0,2.22,5]],"ltp":2.92,"tv":315.36,"id":25651861}]}]}
{"op":"mcm","clk":"11983083593","pt":1724867374892,"mc":[{"id":"1.232375043","rc":[{"batb":[[0,2.2,58.43],[1,2,50],[2,1.8,62.5]],"ltp":2.92,"tv":315.36,"id":25651861}]}]}
{"op":"mcm","clk":"11983083726","pt":1724867376194,"mc":[{"id":"1.232375043","rc":[{"batb":[[0,2.22,4],[1,2.2,58.43],[2,2,50]],"ltp":2.92,"tv":315.36,"id":25651861}]}]}
{"op":"mcm","clk":"11983083949","pt":1724867378307,"mc":[{"id":"1.232375043","rc":[{"batb":[[0,2.24,5],[1,2.22,4],[2,2.2,58.43]],"ltp":2.92,"tv":315.36,"id":25651861}]}]}
{"op":"mcm","clk":"11983084024","pt":1724867378877,"mc":[{"id":"1.232375043","rc":[{"batb":[[1,2.2,58.43],[2,2,50]],"ltp":2.92,"tv":315.36,"id":25651861}]}]}
{"op":"mcm","clk":"11983084450","pt":1724867382380,"mc":[{"id":"1.232375043","rc":[{"batb":[[0,2.22,4]],"ltp":2.92,"tv":315.36,"id":25651861}]}]}
{"op":"mcm","clk":"11983084721","pt":1724867384808,"mc":[{"id":"1.232375043","rc":[{"batb":[[0,2.24,5]],"ltp":2.92,"tv":315.36,"id":25651861}]}]}
{"op":"mcm","clk":"11983085099","pt":1724867388406,"mc":[{"id":"1.232375043","rc":[{"batb":[[0,2.2,58.43],[1,2,50],[2,1.8,62.5]],"ltp":2.92,"tv":315.36,"id":25651861}]}]}
{"op":"mcm","clk":"11983085137","pt":1724867388716,"mc":[{"id":"1.232375043","rc":[{"batb":[[0,2.22,4],[1,2.2,58.43],[2,2,50]],"ltp":2.92,"tv":315.36,"id":25651861}]}]}
{"op":"mcm","clk":"11983085448","pt":1724867391426,"mc":[{"id":"1.232375043","rc":[{"batb":[[0,2.22,5]],"ltp":2.92,"tv":315.36,"id":25651861}]}]}
{"op":"mcm","clk":"11983085842","pt":1724867394942,"mc":[{"id":"1.232375043","rc":[{"batb":[[0,2.22,4]],"ltp":2.92,"tv":315.36,"id":25651861}]}]}
{"op":"mcm","clk":"11983086134","pt":1724867397429,"mc":[{"id":"1.232375043","rc":[{"batb":[[0,2.24,5]],"ltp":2.92,"tv":315.36,"id":25651861}]}]}
{"op":"mcm","clk":"11983086610","pt":1724867401526,"mc":[{"id":"1.232375043","rc":[{"batb":[[0,2.2,58.43],[1,2,50],[2,1.8,62.5]],"ltp":2.92,"tv":315.36,"id":25651861}]}]}
{"op":"mcm","clk":"11983086646","pt":1724867401837,"mc":[{"id":"1.232375043","rc":[{"batb":[[0,2.22,4],[1,2.2,58.43],[2,2,50]],"ltp":2.92,"tv":315.36,"id":25651861}]}]}
{"op":"mcm","clk":"11983086965","pt":1724867404249,"mc":[{"id":"1.232375043","rc":[{"batb":[[0,2.24,5]],"ltp":2.92,"tv":315.36,"id":25651861}]}]}
{"op":"mcm","clk":"11983087457","pt":1724867408059,"mc":[{"id":"1.232375043","rc":[{"batb":[[0,2.22,4]],"ltp":2.92,"tv":315.36,"id":25651861}]}]}
{"op":"mcm","clk":"11983087743","pt":1724867410363,"mc":[{"id":"1.232375043","rc":[{"batb":[[0,2.24,5]],"ltp":2.92,"tv":315.36,"id":25651861}]}]}
{"op":"mcm","clk":"11983088186","pt":1724867414076,"mc":[{"id":"1.232375043","rc":[{"batb":[[0,2.22,4]],"ltp":2.92,"tv":315.36,"id":25651861}]}]}
{"op":"mcm","clk":"11983088498","pt":1724867416763,"mc":[{"id":"1.232375043","rc":[{"batb":[[0,2.22,5]],"ltp":2.92,"tv":315.36,"id":25651861}]}]}
{"op":"mcm","clk":"11983088888","pt":1724867420269,"mc":[{"id":"1.232375043","rc":[{"batb":[[0,2.24,4]],"ltp":2.92,"tv":315.36,"id":25651861}]}]}
{"op":"mcm","clk":"11983089201","pt":1724867422879,"mc":[{"id":"1.232375043","rc":[{"batb":[[0,2.22,5]],"ltp":2.92,"tv":315.36,"id":25651861}]}]}
{"op":"mcm","clk":"11983089567","pt":1724867426066,"mc":[{"id":"1.232375043","rc":[{"batb":[[0,2.24,4]],"ltp":2.92,"tv":315.36,"id":25651861}]}]}
{"op":"mcm","clk":"11983089831","pt":1724867428297,"mc":[{"id":"1.232375043","rc":[{"batb":[[0,2.2,58.43],[1,2,50],[2,1.8,62.5]],"ltp":2.92,"tv":315.36,"id":25651861}]}]}
{"op":"mcm","clk":"11983089879","pt":1724867428570,"mc":[{"id":"1.232375043","rc":[{"batb":[[0,2.22,5],[1,2.2,58.43],[2,2,50]],"ltp":2.92,"tv":315.36,"id":25651861}]}]}
{"op":"mcm","clk":"11983090301","pt":1724867431979,"mc":[{"id":"1.232375043","rc":[{"batb":[[0,2.24,4]],"ltp":2.92,"tv":315.36,"id":25651861}]}]}
{"op":"mcm","clk":"11983090592","pt":1724867434279,"mc":[{"id":"1.232375043","rc":[{"batb":[[0,2.2,58.43],[1,2,50],[2,1.8,62.5]],"ltp":2.92,"tv":315.36,"id":25651861}]}]}
{"op":"mcm","clk":"11983090632","pt":1724867434580,"mc":[{"id":"1.232375043","rc":[{"batb":[[0,2.22,5],[1,2.2,58.43],[2,2,50]],"ltp":2.92,"tv":315.36,"id":25651861}]}]}
{"op":"mcm","clk":"11983091044","pt":1724867438095,"mc":[{"id":"1.232375043","rc":[{"batb":[[0,2.22,4]],"ltp":2.92,"tv":315.36,"id":25651861}]}]}
{"op":"mcm","clk":"11983091286","pt":1724867440486,"mc":[{"id":"1.232375043","rc":[{"batb":[[0,2.2,58.43],[1,2,50],[2,1.8,62.5]],"ltp":2.92,"tv":315.36,"id":25651861}]}]}
{"op":"mcm","clk":"11983091341","pt":1724867441114,"mc":[{"id":"1.232375043","rc":[{"batb":[[0,2.22,5],[1,2.2,58.43],[2,2,50]],"ltp":2.92,"tv":315.36,"id":25651861}]}]}
{"op":"mcm","clk":"11983091718","pt":1724867444506,"mc":[{"id":"1.232375043","rc":[{"batb":[[0,2.2,58.43],[1,2,50],[2,1.8,62.5]],"ltp":2.92,"tv":315.36,"id":25651861}]}]}
{"op":"mcm","clk":"11983091739","pt":1724867444718,"mc":[{"id":"1.232375043","rc":[{"batb":[[0,2.22,4],[1,2.2,58.43],[2,2,50]],"ltp":2.92,"tv":315.36,"id":25651861}]}]}
{"op":"mcm","clk":"11983092002","pt":1724867446993,"mc":[{"id":"1.232375043","rc":[{"batb":[[0,2.2,58.43],[1,2,50],[2,1.8,62.5]],"ltp":2.92,"tv":315.36,"id":25651861}]}]}
{"op":"mcm","clk":"11983092076","pt":1724867447611,"mc":[{"id":"1.232375043","rc":[{"batb":[[0,2.22,5],[1,2.2,58.43],[2,2,50]],"ltp":2.92,"tv":315.36,"id":25651861}]}]}
{"op":"mcm","clk":"11983092472","pt":1724867451206,"mc":[{"id":"1.232375043","rc":[{"batb":[[0,2.22,4]],"ltp":2.92,"tv":315.36,"id":25651861}]}]}
{"op":"mcm","clk":"11983092761","pt":1724867454018,"mc":[{"id":"1.232375043","rc":[{"batb":[[0,2.22,5]],"ltp":2.92,"tv":315.36,"id":25651861}]}]}
{"op":"mcm","clk":"11983092877","pt":1724867455224,"mc":[{"id":"1.232375043","rc":[{"batb":[[0,1.41,18.44]],"ltp":1.44,"tv":613.52,"id":19587555}]}]}
{"op":"mcm","clk":"11983093201","pt":1724867458200,"mc":[{"id":"1.232375043","rc":[{"batb":[[0,2.24,4]],"ltp":2.92,"tv":315.36,"id":25651861}]}]}
{"op":"mcm","clk":"11983093454","pt":1724867460522,"mc":[{"id":"1.232375043","rc":[{"batb":[[0,2.26,5],[1,2.24,4],[2,2.2,58.43]],"ltp":2.92,"tv":315.36,"id":25651861}]}]}
{"op":"mcm","clk":"11983093491","pt":1724867460933,"mc":[{"id":"1.232375043","rc":[{"batb":[[1,2.2,58.43],[2,2,50]],"ltp":2.92,"tv":315.36,"id":25651861}]}]}
{"op":"mcm","clk":"11983093767","pt":1724867463514,"mc":[{"id":"1.232375043","rc":[{"batb":[[0,2.28,4],[1,2.26,5],[2,2.2,58.43]],"ltp":2.92,"tv":315.36,"id":25651861}]}]}
{"op":"mcm","clk":"11983093834","pt":1724867464030,"mc":[{"id":"1.232375043","rc":[{"batb":[[1,2.2,58.43],[2,2,50]],"ltp":2.92,"tv":315.36,"id":25651861}]}]}
{"op":"mcm","clk":"11983094096","pt":1724867466344,"mc":[{"id":"1.232375043","rc":[{"batb":[[0,2.22,5]],"ltp":2.92,"tv":315.36,"id":25651861}]}]}
{"op":"mcm","clk":"11983094518","pt":1724867469756,"mc":[{"id":"1.232375043","rc":[{"batb":[[0,2.22,4]],"ltp":2.92,"tv":315.36,"id":25651861}]}]}
{"op":"mcm","clk":"11983094766","pt":1724867472150,"mc":[{"id":"1.232375043","rc":[{"batb":[[0,2.22,5]],"ltp":2.92,"tv":315.36,"id":25651861}]}]}
{"op":"mcm","clk":"11983095081","pt":1724867474928,"mc":[{"id":"1.232375043","rc":[{"batb":[[0,2.24,4],[1,2.22,5],[2,2.2,58.43]],"ltp":2.92,"tv":315.36,"id":25651861}]}]}
{"op":"mcm","clk":"11983095195","pt":1724867476026,"mc":[{"id":"1.232375043","rc":[{"batb":[[1,2.2,58.43],[2,2,50]],"ltp":2.92,"tv":315.36,"id":25651861}]}]}
{"op":"mcm","clk":"11983095316","pt":1724867477124,"mc":[{"id":"1.232375043","rc":[{"batb":[[0,2.2,58.43],[1,2,50],[2,1.8,62.5]],"ltp":2.92,"tv":315.36,"id":25651861}]}]}
{"op":"mcm","clk":"11983095566","pt":1724867479527,"mc":[{"id":"1.232375043","rc":[{"batb":[[0,2.24,4],[1,2.22,5],[2,2.2,58.43]],"ltp":2.92,"tv":315.36,"id":25651861}]}]}
{"op":"mcm","clk":"11983095802","pt":1724867481758,"mc":[{"id":"1.232375043","rc":[{"batb":[[0,2.22,5],[1,2.2,58.43],[2,2,50]],"ltp":2.92,"tv":315.36,"id":25651861}]}]}
{"op":"mcm","clk":"11983095913","pt":1724867482644,"mc":[{"id":"1.232375043","rc":[{"batb":[[0,2.2,58.43],[1,2,50],[2,1.8,62.5]],"ltp":2.92,"tv":315.36,"id":25651861}]}]}
{"op":"mcm","clk":"11983096406","pt":1724867486524,"mc":[{"id":"1.232375043","rc":[{"batb":[[0,2.22,9],[1,2.2,58.43],[2,2,50]],"ltp":2.92,"tv":315.36,"id":25651861}]}]}
{"op":"mcm","clk":"11983096744","pt":1724867489343,"mc":[{"id":"1.232375043","rc":[{"batb":[[0,2.22,5]],"ltp":2.92,"tv":315.36,"id":25651861}]}]}
{"op":"mcm","clk":"11983096864","pt":1724867490347,"mc":[{"id":"1.232375043","rc":[{"batb":[[0,2.2,58.43],[1,2,50],[2,1.8,62.5]],"ltp":2.92,"tv":315.36,"id":25651861}]}]}
{"op":"mcm","clk":"11983097175","pt":1724867492762,"mc":[{"id":"1.232375043","rc":[{"batb":[[0,2.22,9],[1,2.2,58.43],[2,2,50]],"ltp":2.92,"tv":315.36,"id":25651861}]}]}
{"op":"mcm","clk":"11983097480","pt":1724867495149,"mc":[{"id":"1.232375043","rc":[{"batb":[[0,2.22,5]],"ltp":2.92,"tv":315.36,"id":25651861}]}]}
{"op":"mcm","clk":"11983097607","pt":1724867496144,"mc":[{"id":"1.232375043","rc":[{"batb":[[0,2.2,58.43],[1,2,50],[2,1.8,62.5]],"ltp":2.92,"tv":315.36,"id":25651861}]}]}
{"op":"mcm","clk":"11983098008","pt":1724867499250,"mc":[{"id":"1.232375043","rc":[{"batb":[[0,2.22,9],[1,2.2,58.43],[2,2,50]],"ltp":2.92,"tv":315.36,"id":25651861}]}]}
{"op":"mcm","clk":"11983098258","pt":1724867501857,"mc":[{"id":"1.232375043","rc":[{"batb":[[0,2.22,5]],"ltp":2.92,"tv":315.36,"id":25651861}]}]}
{"op":"mcm","clk":"11983098339","pt":1724867502583,"mc":[{"id":"1.232375043","rc":[{"batb":[[0,2.2,58.43],[1,2,50],[2,1.8,62.5]],"ltp":2.92,"tv":315.36,"id":25651861}]}]}
{"op":"mcm","clk":"11983098630","pt":1724867505359,"mc":[{"id":"1.232375043","rc":[{"batb":[[0,2.22,9],[1,2.2,58.43],[2,2,50]],"ltp":2.92,"tv":315.36,"id":25651861}]}]}
{"op":"mcm","clk":"11983098881","pt":1724867507859,"mc":[{"id":"1.232375043","rc":[{"batb":[[0,2.22,5]],"ltp":2.92,"tv":315.36,"id":25651861}]}]}
{"op":"mcm","clk":"11983098982","pt":1724867508885,"mc":[{"id":"1.232375043","rc":[{"batb":[[0,2.2,58.43],[1,2,50],[2,1.8,62.5]],"ltp":2.92,"tv":315.36,"id":25651861}]}]}
{"op":"mcm","clk":"11983099270","pt":1724867511685,"mc":[{"id":"1.232375043","rc":[{"batb":[[0,2.22,9],[1,2.2,58.43],[2,2,50]],"ltp":2.92,"tv":315.36,"id":25651861}]}]}
{"op":"mcm","clk":"11983099563","pt":1724867514573,"mc":[{"id":"1.232375043","rc":[{"batb":[[0,2.22,5]],"ltp":2.92,"tv":315.36,"id":25651861}]}]}
{"op":"mcm","clk":"11983099672","pt":1724867515669,"mc":[{"id":"1.232375043","rc":[{"batb":[[0,2.2,58.43],[1,2,50],[2,1.8,62.5]],"ltp":2.92,"tv":315.36,"id":25651861}]}]}
{"op":"mcm","clk":"11983099920","pt":1724867518092,"mc":[{"id":"1.232375043","rc":[{"batb":[[0,2.22,9],[1,2.2,58.43],[2,2,50]],"ltp":2.92,"tv":315.36,"id":25651861}]}]}
{"op":"mcm","clk":"11983100300","pt":1724867521523,"mc":[{"id":"1.232375043","rc":[{"batb":[[0,2.2,58.43],[1,2,50],[2,1.8,62.5]],"ltp":2.92,"tv":315.36,"id":25651861}]}]}
{"op":"mcm","clk":"11983100455","pt":1724867523093,"mc":[{"id":"1.232375043","rc":[{"batb":[[0,2.22,4],[1,2.2,58.43],[2,2,50]],"ltp":2.92,"tv":315.36,"id":25651861}]}]}
{"op":"mcm","clk":"11983100640","pt":1724867524870,"mc":[{"id":"1.232375043","rc":[{"batb":[[0,2.24,5],[1,2.22,4],[2,2.2,58.43]],"ltp":2.92,"tv":315.36,"id":25651861}]}]}
{"op":"mcm","clk":"11983100738","pt":1724867525702,"mc":[{"id":"1.232375043","rc":[{"batb":[[1,2.2,58.43],[2,2,50]],"ltp":2.92,"tv":315.36,"id":25651861}]}]}
{"op":"mcm","clk":"11983101053","pt":1724867528512,"mc":[{"id":"1.232375043","rc":[{"batb":[[0,2.22,4]],"ltp":2.92,"tv":315.36,"id":25651861},{"batb":[[0,1.41,11.73]],"ltp":1.44,"tv":613.52,"id":19587555}]}]}
{"op":"mcm","clk":"11983101320","pt":1724867530978,"mc":[{"id":"1.232375043","rc":[{"batb":[[0,2.22,5]],"ltp":2.92,"tv":315.36,"id":25651861}]}]}
{"op":"mcm","clk":"11983101681","pt":1724867534234,"mc":[{"id":"1.232375043","rc":[{"batb":[[0,2.24,4]],"ltp":2.92,"tv":315.36,"id":25651861}]}]}
{"op":"mcm","clk":"11983101784","pt":1724867535208,"mc":[{"id":"1.232375043","rc":[{"batb":[[0,1.4,62.76],[1,1.38,16.76],[2,1.37,7.58]],"ltp":1.44,"tv":613.52,"id":19587555}]}]}
{"op":"mcm","clk":"11983101920","pt":1724867536505,"mc":[{"id":"1.232375043","rc":[{"batb":[[0,2.26,5],[1,2.24,4],[2,2.2,58.43]],"ltp":2.92,"tv":315.36,"id":25651861}]}]}
{"op":"mcm","clk":"11983101958","pt":1724867536817,"mc":[{"id":"1.232375043","rc":[{"batb":[[1,2.2,58.43],[2,2,50]],"ltp":2.92,"tv":315.36,"id":25651861}]}]}
{"op":"mcm","clk":"11983102233","pt":1724867539325,"mc":[{"id":"1.232375043","rc":[{"batb":[[0,2.28,4],[1,2.26,5],[2,2.2,58.43]],"ltp":2.92,"tv":315.36,"id":25651861}]}]}
{"op":"mcm","clk":"11983102326","pt":1724867540012,"mc":[{"id":"1.232375043","rc":[{"batb":[[1,2.2,58.43],[2,2,50]],"ltp":2.92,"tv":315.36,"id":25651861}]}]}
{"op":"mcm","clk":"11983102526","pt":1724867541828,"mc":[{"id":"1.232375043","rc":[{"batb":[[0,2.2,58.43],[1,2,50],[2,1.8,62.5]],"ltp":2.92,"tv":315.36,"id":25651861}]}]}
{"op":"mcm","clk":"11983102815","pt":1724867544326,"mc":[{"id":"1.232375043","rc":[{"batb":[[0,2.22,9],[1,2.2,58.43],[2,2,50]],"ltp":2.92,"tv":315.36,"id":25651861}]}]}
{"op":"mcm","clk":"11983103115","pt":1724867546801,"mc":[{"id":"1.232375043","rc":[{"batb":[[0,2.22,5]],"ltp":2.92,"tv":315.36,"id":25651861}]}]}
{"op":"mcm","clk":"11983103236","pt":1724867547940,"mc":[{"id":"1.232375043","rc":[{"batb":[[0,2.2,58.43],[1,2,50],[2,1.8,62.5]],"ltp":2.92,"tv":315.36,"id":25651861}]}]}
{"op":"mcm","clk":"11983103573","pt":1724867550921,"mc":[{"id":"1.232375043","rc":[{"batb":[[0,2.22,9],[1,2.2,58.43],[2,2,50]],"ltp":2.92,"tv":315.36,"id":25651861}]}]}
{"op":"mcm","clk":"11983103909","pt":1724867553748,"mc":[{"id":"1.232375043","rc":[{"batb":[[0,2.22,5]],"ltp":2.92,"tv":315.36,"id":25651861}]}]}
{"op":"mcm","clk":"11983104037","pt":1724867554806,"mc":[{"id":"1.232375043","rc":[{"batb":[[0,2.2,58.43],[1,2,50],[2,1.8,62.5]],"ltp":2.92,"tv":315.36,"id":25651861}]}]}
{"op":"mcm","clk":"11983104185","pt":1724867556112,"mc":[{"id":"1.232375043","rc":[{"batb":[[0,2.22,4],[1,2.2,58.43],[2,2,50]],"ltp":2.92,"tv":315.36,"id":25651861}]}]}
{"op":"mcm","clk":"11983104329","pt":1724867557417,"mc":[{"id":"1.232375043","rc":[{"batb":[[0,2.24,5],[1,2.22,4],[2,2.2,58.43]],"ltp":2.92,"tv":315.36,"id":25651861}]}]}
{"op":"mcm","clk":"11983104508","pt":1724867558730,"mc":[{"id":"1.232375043","rc":[{"batb":[[1,2.2,58.43],[2,2,50]],"ltp":2.92,"tv":315.36,"id":25651861}]}]}
{"op":"mcm","clk":"11983104834","pt":1724867561344,"mc":[{"id":"1.232375043","rc":[{"batb":[[0,2.2,58.43],[1,2,50],[2,1.8,62.5]],"ltp":2.92,"tv":315.36,"id":25651861}]}]}
{"op":"mcm","clk":"11983104860","pt":1724867561545,"mc":[{"id":"1.232375043","rc":[{"batb":[[0,2.22,4],[1,2.2,58.43],[2,2,50]],"ltp":2.92,"tv":315.36,"id":25651861}]}]}
{"op":"mcm","clk":"11983105127","pt":1724867563832,"mc":[{"id":"1.232375043","rc":[{"batb":[[0,2.24,5]],"ltp":2.92,"tv":315.36,"id":25651861}]}]}
{"op":"mcm","clk":"11983105559","pt":1724867567442,"mc":[{"id":"1.232375043","rc":[{"batb":[[0,2.2,58.43],[1,2,50],[2,1.8,62.5]],"ltp":2.92,"tv":315.36,"id":25651861}]}]}
{"op":"mcm","clk":"11983105596","pt":1724867567765,"mc":[{"id":"1.232375043","rc":[{"batb":[[0,2.22,4],[1,2.2,58.43],[2,2,50]],"ltp":2.92,"tv":315.36,"id":25651861}]}]}
{"op":"mcm","clk":"11983105885","pt":1724867570368,"mc":[{"id":"1.232375043","rc":[{"batb":[[0,2.24,5]],"ltp":2.92,"tv":315.36,"id":25651861}]}]}
{"op":"mcm","clk":"11983106150","pt":1724867572832,"mc":[{"id":"1.232375043","rc":[{"batb":[[0,2.26,4],[1,2.24,5],[2,2.2,58.43]],"ltp":2.92,"tv":315.36,"id":25651861}]}]}
{"op":"mcm","clk":"11983106311","pt":1724867574229,"mc":[{"id":"1.232375043","rc":[{"batb":[[1,2.2,58.43],[2,2,50]],"ltp":2.92,"tv":315.36,"id":25651861}]}]}
{"op":"mcm","clk":"11983106419","pt":1724867575534,"mc":[{"id":"1.232375043","rc":[{"batb":[[0,2.2,58.43],[1,2,50],[2,1.8,62.5]],"ltp":2.92,"tv":315.36,"id":25651861}]}]}
{"op":"mcm","clk":"11983106677","pt":1724867577468,"mc":[{"id":"1.232375043","rc":[{"batb":[[0,2.22,5],[1,2.2,58.43],[2,2,50]],"ltp":2.92,"tv":315.36,"id":25651861}]}]}
{"op":"mcm","clk":"11983106747","pt":1724867578040,"mc":[{"id":"1.232375043","rc":[{"batb":[[0,2.24,4],[1,2.22,5],[2,2.2,58.43]],"ltp":2.92,"tv":315.36,"id":25651861}]}]}
{"op":"mcm","clk":"11983107137","pt":1724867581061,"mc":[{"id":"1.232375043","rc":[{"batb":[[0,2.2,58.43],[1,2,50],[2,1.8,62.5]],"ltp":2.92,"tv":315.36,"id":25651861}]}]}
{"op":"mcm","clk":"11983107389","pt":1724867583458,"mc":[{"id":"1.232375043","rc":[{"batb":[[0,2.22,9],[1,2.2,58.43],[2,2,50]],"ltp":2.92,"tv":315.36,"id":25651861}]}]}
{"op":"mcm","clk":"11983107755","pt":1724867587155,"mc":[{"id":"1.232375043","rc":[{"batb":[[0,2.2,58.43],[1,2,50],[2,1.8,62.5]],"ltp":2.92,"tv":315.36,"id":25651861}]}]}
{"op":"mcm","clk":"11983108119","pt":1724867590797,"mc":[{"id":"1.232375043","rc":[{"batb":[[0,2.22,9],[1,2.2,58.43],[2,2,50]],"ltp":2.92,"tv":315.36,"id":25651861}]}]}
{"op":"mcm","clk":"11983108484","pt":1724867593981,"mc":[{"id":"1.232375043","rc":[{"batb":[[0,2.22,5]],"ltp":2.92,"tv":315.36,"id":25651861}]}]}
{"op":"mcm","clk":"11983108559","pt":1724867594869,"mc":[{"id":"1.232375043","rc":[{"batb":[[0,2.2,58.43],[1,2,50],[2,1.8,62.5]],"ltp":2.92,"tv":315.36,"id":25651861}]}]}
{"op":"mcm","clk":"11983108710","pt":1724867596288,"mc":[{"id":"1.232375043","rc":[{"batb":[[0,2.22,4],[1,2.2,58.43],[2,2,50]],"ltp":2.92,"tv":315.36,"id":25651861}]}]}
{"op":"mcm","clk":"11983108830","pt":1724867597479,"mc":[{"id":"1.232375043","rc":[{"batb":[[0,2.24,5],[1,2.22,4],[2,2.2,58.43]],"ltp":2.92,"tv":315.36,"id":25651861}]}]}
{"op":"mcm","clk":"11983109007","pt":1724867598957,"mc":[{"id":"1.232375043","rc":[{"batb":[[1,2.2,58.43],[2,2,50]],"ltp":2.92,"tv":315.36,"id":25651861}]}]}
{"op":"mcm","clk":"11983109249","pt":1724867601457,"mc":[{"id":"1.232375043","rc":[{"batb":[[0,2.2,58.43],[1,2,50],[2,1.8,62.5]],"ltp":2.92,"tv":315.36,"id":25651861}]}]}
{"op":"mcm","clk":"11983109297","pt":1724867601966,"mc":[{"id":"1.232375043","rc":[{"batb":[[0,2.22,4],[1,2.2,58.43],[2,2,50]],"ltp":2.92,"tv":315.36,"id":25651861}]}]}
{"op":"mcm","clk":"11983109547","pt":1724867604471,"mc":[{"id":"1.232375043","rc":[{"batb":[[0,2.22,5]],"ltp":2.92,"tv":315.36,"id":25651861}]}]}
{"op":"mcm","clk":"11983109877","pt":1724867608060,"mc":[{"id":"1.232375043","rc":[{"batb":[[0,2.22,4]],"ltp":2.92,"tv":315.36,"id":25651861}]}]}
{"op":"mcm","clk":"11983110084","pt":1724867610484,"mc":[{"id":"1.232375043","rc":[{"batb":[[0,2.22,5]],"ltp":2.92,"tv":315.36,"id":25651861}]}]}
{"op":"mcm","clk":"11983110412","pt":1724867614074,"mc":[{"id":"1.232375043","rc":[{"batb":[[0,2.22,4]],"ltp":2.92,"tv":315.36,"id":25651861}]}]}
{"op":"mcm","clk":"11983110660","pt":1724867616514,"mc":[{"id":"1.232375043","rc":[{"batb":[[0,2.2,58.43],[1,2,50],[2,1.8,62.5]],"ltp":2.92,"tv":315.36,"id":25651861}]}]}
{"op":"mcm","clk":"11983110685","pt":1724867616717,"mc":[{"id":"1.232375043","rc":[{"batb":[[0,2.22,5],[1,2.2,58.43],[2,2,50]],"ltp":2.92,"tv":315.36,"id":25651861}]}]}
{"op":"mcm","clk":"11983111028","pt":1724867619493,"mc":[{"id":"1.232375043","rc":[{"batb":[[0,2.24,4],[1,2.22,5],[2,2.2,58.43]],"ltp":2.92,"tv":315.36,"id":25651861}]}]}
{"op":"mcm","clk":"11983111097","pt":1724867620000,"mc":[{"id":"1.232375043","rc":[{"batb":[[1,2.2,58.43],[2,2,50]],"ltp":2.92,"tv":315.36,"id":25651861}]}]}
{"op":"mcm","clk":"11983111273","pt":1724867621822,"mc":[{"id":"1.232375043","rc":[{"batb":[[0,2.2,58.43],[1,2,50],[2,1.8,62.5]],"ltp":2.92,"tv":315.36,"id":25651861}]}]}
{"op":"mcm","clk":"11983111469","pt":1724867623419,"mc":[{"id":"1.232375043","rc":[{"batb":[[0,2.22,5],[1,2.2,58.43],[2,2,50]],"ltp":2.92,"tv":315.36,"id":25651861}]}]}
{"op":"mcm","clk":"11983111560","pt":1724867624615,"mc":[{"id":"1.232375043","rc":[{"batb":[[0,2.24,4],[1,2.22,5],[2,2.2,58.43]],"ltp":2.92,"tv":315.36,"id":25651861}]}]}
{"op":"mcm","clk":"11983111829","pt":1724867627288,"mc":[{"id":"1.232375043","rc":[{"batb":[[0,2.2,58.43],[1,2,50],[2,1.8,62.5]],"ltp":2.92,"tv":315.36,"id":25651861}]}]}
{"op":"mcm","clk":"11983112095","pt":1724867629925,"mc":[{"id":"1.232375043","rc":[{"batb":[[0,2.22,9],[1,2.2,58.43],[2,2,50]],"ltp":2.92,"tv":315.36,"id":25651861}]}]}
{"op":"mcm","clk":"11983112362","pt":1724867632635,"mc":[{"id":"1.232375043","rc":[{"batb":[[0,2.22,5]],"ltp":2.92,"tv":315.36,"id":25651861}]}]}
{"op":"mcm","clk":"11983112489","pt":1724867633712,"mc":[{"id":"1.232375043","rc":[{"batb":[[0,2.2,58.43],[1,2,50],[2,1.8,62.5]],"ltp":2.92,"tv":315.36,"id":25651861}]}]}
{"op":"mcm","clk":"11983112763","pt":1724867636220,"mc":[{"id":"1.232375043","rc":[{"batb":[[0,2.24,5],[1,2.22,4],[2,2.2,58.43]],"ltp":2.92,"tv":315.36,"id":25651861}]}]}
{"op":"mcm","clk":"11983113004","pt":1724867638654,"mc":[{"id":"1.232375043","rc":[{"batb":[[1,2.2,58.43],[2,2,50]],"ltp":2.92,"tv":315.36,"id":25651861}]}]}
{"op":"mcm","clk":"11983113166","pt":1724867640427,"mc":[{"id":"1.232375043","rc":[{"batb":[[0,2.2,58.43],[1,2,50],[2,1.8,62.5]],"ltp":2.92,"tv":315.36,"id":25651861}]}]}
{"op":"mcm","clk":"11983113352","pt":1724867642151,"mc":[{"id":"1.232375043","rc":[{"batb":[[0,2.22,4],[1,2.2,58.43],[2,2,50]],"ltp":2.92,"tv":315.36,"id":25651861}]}]}
{"op":"mcm","clk":"11983113444","pt":1724867643057,"mc":[{"id":"1.232375043","rc":[{"batb":[[0,2.24,5],[1,2.22,4],[2,2.2,58.43]],"ltp":2.92,"tv":315.36,"id":25651861}]}]}
{"op":"mcm","clk":"11983113692","pt":1724867645319,"mc":[{"id":"1.232375043","rc":[{"batb":[[1,2.2,58.43],[2,2,50]],"ltp":2.92,"tv":315.36,"id":25651861}]}]}
{"op":"mcm","clk":"11983113817","pt":1724867646714,"mc":[{"id":"1.232375043","rc":[{"batb":[[0,2.2,58.43],[1,2,50],[2,1.8,62.5]],"ltp":2.92,"tv":315.36,"id":25651861}]}]}
{"op":"mcm","clk":"11983114097","pt":1724867649554,"mc":[{"id":"1.232375043","rc":[{"batb":[[0,2.22,9],[1,2.2,58.43],[2,2,50]],"ltp":2.92,"tv":315.36,"id":25651861}]}]}
{"op":"mcm","clk":"11983114406","pt":1724867652443,"mc":[{"id":"1.232375043","rc":[{"batb":[[0,2.22,5]],"ltp":2.92,"tv":315.36,"id":25651861}]}]}
{"op":"mcm","clk":"11983114513","pt":1724867653439,"mc":[{"id":"1.232375043","rc":[{"batb":[[0,2.2,58.43],[1,2,50],[2,1.8,62.5]],"ltp":2.92,"tv":315.36,"id":25651861}]}]}
{"op":"mcm","clk":"11983114751","pt":1724867655530,"mc":[{"id":"1.232375043","rc":[{"batb":[[0,2.22,4],[1,2.2,58.43],[2,2,50]],"ltp":2.92,"tv":315.36,"id":25651861}]}]}
{"op":"mcm","clk":"11983114810","pt":1724867656242,"mc":[{"id":"1.232375043","rc":[{"batb":[[0,2.24,5],[1,2.22,4],[2,2.2,58.43]],"ltp":2.92,"tv":315.36,"id":25651861}]}]}
{"op":"mcm","clk":"11983115018","pt":1724867658349,"mc":[{"id":"1.232375043","rc":[{"batb":[[1,2.2,58.43],[2,2,50]],"ltp":2.92,"tv":315.36,"id":25651861}]}]}
{"op":"mcm","clk":"11983115213","pt":1724867660147,"mc":[{"id":"1.232375043","rc":[{"batb":[[0,2.2,58.43],[1,2,50],[2,1.8,62.5]],"ltp":2.92,"tv":315.36,"id":25651861}]}]}
{"op":"mcm","clk":"11983115420","pt":1724867662167,"mc":[{"id":"1.232375043","rc":[{"batb":[[0,2.22,4],[1,2.2,58.43],[2,2,50]],"ltp":2.92,"tv":315.36,"id":25651861}]}]}
{"op":"mcm","clk":"11983116173","pt":1724867669937,"mc":[{"id":"1.232375043","rc":[{"batb":[[0,2.2,58.43],[1,2,50],[2,1.8,62.5]],"ltp":2.92,"tv":315.36,"id":25651861}]}]}
{"op":"mcm","clk":"11983121790","pt":1724867726208,"mc":[{"id":"1.232375043","rc":[{"batl":[[0,1.52,5.87]],"ltp":1.44,"tv":613.52,"id":19587555}]}]}
{"op":"mcm","clk":"11983124039","pt":1724867747495,"mc":[{"id":"1.232375043","rc":[{"batb":[[0,1.41,4.71],[1,1.4,62.76],[2,1.38,16.76]],"ltp":1.44,"tv":613.52,"id":19587555}]}]}
{"op":"mcm","clk":"11983126993","pt":1724867777551,"mc":[{"id":"1.232375043","rc":[{"batl":[[0,1.51,2],[1,1.52,5.87],[2,1.54,35.23]],"ltp":1.44,"tv":613.52,"id":19587555}]}]}
{"op":"mcm","clk":"11983130416","pt":1724867808965,"mc":[{"id":"1.232375043","rc":[{"batl":[[0,3.95,1]],"ltp":2.92,"tv":315.36,"id":25651861}]}]}
{"op":"mcm","clk":"11983131006","pt":1724867814747,"mc":[{"id":"1.232375043","rc":[{"batl":[[0,3.65,1]],"ltp":2.92,"tv":315.36,"id":25651861}]}]}
{"op":"mcm","clk":"11983131571","pt":1724867820703,"mc":[{"id":"1.232375043","rc":[{"batl":[[0,3.4,1]],"ltp":2.92,"tv":315.36,"id":25651861}]}]}
{"op":"mcm","clk":"11983132197","pt":1724867826994,"mc":[{"id":"1.232375043","rc":[{"batl":[[0,3.65,1]],"ltp":2.92,"tv":315.36,"id":25651861}]}]}
{"op":"mcm","clk":"11983133033","pt":1724867835214,"mc":[{"id":"1.232375043","rc":[{"batl":[[0,3.45,1]],"ltp":2.92,"tv":315.36,"id":25651861}]}]}
{"op":"mcm","clk":"11983133612","pt":1724867840278,"mc":[{"id":"1.232375043","rc":[{"batl":[[0,3.7,1]],"ltp":2.92,"tv":315.36,"id":25651861}]}]}
{"op":"mcm","clk":"11983134175","pt":1724867845704,"mc":[{"id":"1.232375043","rc":[{"batl":[[0,3.8,1]],"ltp":2.92,"tv":315.36,"id":25651861}]}]}
{"op":"mcm","clk":"11983134888","pt":1724867853035,"mc":[{"id":"1.232375043","rc":[{"batl":[[0,3.1,1]],"ltp":2.92,"tv":315.36,"id":25651861}]}]}
{"op":"mcm","clk":"11983135672","pt":1724867860623,"mc":[{"id":"1.232375043","rc":[{"batl":[[0,2.98,1]],"ltp":2.92,"tv":315.36,"id":25651861}]}]}
{"op":"mcm","clk":"11983135935","pt":1724867863345,"mc":[{"id":"1.232375043","rc":[{"trd":[[2.98,1]],"ltp":2.98,"tv":316.36,"id":25651861},{"trd":[[1.41,9.42],[1.5,318.89]],"batb":[[0,1.38,16.76],[1,1.37,7.58],[2,1.36,10.05]],"batl":[[0,1.4,14.21],[1,1.51,2],[2,1.52,5.87]],"ltp":1.41,"tv":624.93,"id":19587555}],"tv":941.3}]}
{"op":"mcm","clk":"11983137199","pt":1724867876160,"mc":[{"id":"1.232375043","rc":[{"batl":[[0,1.51,2],[1,1.52,5.87],[2,1.54,35.23]],"ltp":1.41,"tv":624.93,"id":19587555}]}]}
{"op":"mcm","clk":"11983137423","pt":1724867878458,"mc":[{"id":"1.232375043","rc":[{"batl":[[2,1.53,4.83]],"ltp":1.41,"tv":624.93,"id":19587555}]}]}
{"op":"mcm","clk":"11983142478","pt":1724867929776,"mc":[{"id":"1.232375043","rc":[{"batb":[[0,1.39,2],[1,1.38,16.76],[2,1.37,7.58]],"ltp":1.41,"tv":624.93,"id":19587555}]}]}
{"op":"mcm","clk":"11983150521","pt":1724868014352,"mc":[{"id":"1.232375043","rc":[{"trd":[[1.52,273.02]],"ltp":2.98,"tv":316.69,"id":25651861},{"trd":[[1.41,9.42],[1.44,17.79],[1.49,17.04],[1.5,319.22],[1.54,33.54],[1.55,28.23],[1.56,36.84],[1.57,23.16],[2.16,31.68]],"batb":[[2,1.37,7.59]],"batl":[[1,1.52,6.71],[2,1.53,4.83]],"ltp":1.41,"tv":625.31,"id":19587555}],"tv":942.0}]}
{"op":"mcm","clk":"11983151197","pt":1724868020643,"mc":[{"id":"1.232375043","rc":[{"trd":[[1.39,4]],"batb":[[0,1.38,3.27],[1,1.37,7.59],[2,1.36,10.05]],"ltp":1.39,"tv":629.31,"id":19587555}],"tv":946.0}]}
{"op":"mcm","clk":"11983154752","pt":1724868053362,"mc":[{"id":"1.232375043","rc":[{"batl":[[0,1.49,4.19],[1,1.51,2],[2,1.52,6.71]],"ltp":1.39,"tv":629.31,"id":19587555}]}]}
{"op":"mcm","clk":"11983161259","pt":1724868122134,"mc":[{"id":"1.232375043","rc":[{"batl":[[0,1.47,59.83],[1,1.49,4.19],[2,1.51,2]],"ltp":1.39,"tv":629.31,"id":19587555}]}]}
{"op":"mcm","clk":"11983161376","pt":1724868123455,"mc":[{"id":"1.232375043","rc":[{"batl":[[0,1.46,5.06],[1,1.47,59.83],[2,1.49,4.19]],"ltp":1.39,"tv":629.31,"id":19587555}]}]}
{"op":"mcm","clk":"11983166864","pt":1724868181107,"mc":[{"id":"1.232375043","rc":[{"batl":[[0,1.45,2.51],[1,1.46,5.06],[2,1.47,59.83]],"ltp":1.39,"tv":629.31,"id":19587555}]}]}
{"op":"mcm","clk":"11983179808","pt":1724868305899,"mc":[{"id":"1.232375043","rc":[{"batl":[[0,1.42,1.96],[1,1.45,2.51],[2,1.46,5.06]],"ltp":1.39,"tv":629.31,"id":19587555}]}]}
{"op":"mcm","clk":"11983183191","pt":1724868335022,"mc":[{"id":"1.232375043","rc":[{"batb":[[2,1.35,50.35]],"batl":[[2,1.46,9.55]],"ltp":1.39,"tv":629.31,"id":19587555}]}]}
{"op":"mcm","clk":"11983183346","pt":1724868336250,"mc":[{"id":"1.232375043","rc":[{"batl":[[0,1.45,2.51],[1,1.46,9.55],[2,1.47,59.83]],"ltp":1.39,"tv":629.31,"id":19587555}]}]}
{"op":"mcm","clk":"11983185091","pt":1724868352443,"mc":[{"id":"1.232375043","rc":[{"batl":[[0,1.43,1.94],[1,1.45,2.51],[2,1.46,9.55]],"ltp":1.39,"tv":629.31,"id":19587555}]}]}
{"op":"mcm","clk":"11983190766","pt":1724868407516,"mc":[{"id":"1.232375043","rc":[{"batl":[[1,1.45,5.02]],"ltp":1.39,"tv":629.31,"id":19587555}]}]}
{"op":"mcm","clk":"11983236193","pt":1724868831235,"mc":[{"id":"1.232375043","rc":[{"batb":[[0,3,19.31],[1,2.2,58.43],[2,2,50]],"ltp":2.98,"tv":316.69,"id":25651861}]}]}
{"op":"mcm","clk":"11983299904","pt":1724869438490,"mc":[{"id":"1.232375043","rc":[{"batb":[[0,1.38,107.87]],"ltp":1.39,"tv":629.31,"id":19587555}]}]}
{"op":"mcm","clk":"11983450422","pt":1724870686340,"mc":[{"id":"1.232375043","rc":[{"batb":[[0,3,24.49]],"ltp":2.98,"tv":316.69,"id":25651861}]}]}
{"op":"mcm","clk":"11983582513","pt":1724871746256,"mc":[{"id":"1.232375043","rc":[{"trd":[[1.52,272.75]],"batb":[[0,3,24.49]],"ltp":2.98,"tv":316.42,"id":25651861},{"trd":[[1.41,9.42],[1.44,17.79],[1.49,17.04],[1.5,318.95],[1.54,33.54],[1.55,28.23],[1.56,36.83],[1.57,23.15],[2.16,31.68]],"batb":[[0,1.38,104.6],[1,1.37,7.58],[2,1.35,50.31]],"batl":[[2,1.46,9.55]],"ltp":1.39,"tv":629.0,"id":19587555}],"tv":945.42}]}
{"op":"mcm","clk":"11983584278","pt":1724871761664,"mc":[{"id":"1.232375043","rc":[{"batl":[[0,1.43,14.93]],"ltp":1.39,"tv":629.0,"id":19587555}]}]}
{"op":"mcm","clk":"11983584408","pt":1724871762800,"mc":[{"id":"1.232375043","rc":[{"batl":[[2,1.46,4.49]],"ltp":1.39,"tv":629.0,"id":19587555}]}]}
{"op":"mcm","clk":"11983586349","pt":1724871780427,"mc":[{"id":"1.232375043","rc":[{"batb":[[0,3,19.31]],"ltp":2.98,"tv":316.42,"id":25651861}]}]}
{"op":"mcm","clk":"11983651026","pt":1724872341952,"mc":[{"id":"1.232375043","rc":[{"batb":[[2,1.36,104.6]],"ltp":1.39,"tv":629.0,"id":19587555}]}]}
{"op":"mcm","clk":"11983652956","pt":1724872358538,"mc":[{"id":"1.232375043","rc":[{"batb":[[0,1.37,7.58],[1,1.36,104.6],[2,1.35,50.31]],"ltp":1.39,"tv":629.0,"id":19587555}]}]}
{"op":"mcm","clk":"11983915125","pt":1724874816605,"mc":[{"id":"1.232375043","rc":[{"trd":[[1.43,63.32]],"batb":[[0,1.43,135.07],[1,1.37,7.58],[2,1.36,104.6]],"batl":[[0,1.45,5.02],[1,1.46,4.49],[2,1.47,59.83]],"ltp":1.43,"tv":658.86,"id":19587555}],"tv":975.28}]}
{"op":"mcm","clk":"11983915227","pt":1724874817602,"mc":[{"id":"1.232375043","rc":[{"batl":[[1,1.46,8.99]],"ltp":1.43,"tv":658.86,"id":19587555}]}]}
{"op":"mcm","clk":"11983915322","pt":1724874818698,"mc":[{"id":"1.232375043","rc":[{"batb":[[0,1.43,224.88]],"ltp":1.43,"tv":658.86,"id":19587555}]}]}
{"op":"mcm","clk":"11983919504","pt":1724874860193,"mc":[{"id":"1.232375043","rc":[{"trd":[[1.45,27.15]],"batb":[[0,1.45,130.05],[1,1.43,89.81],[2,1.37,7.58]],"batl":[[0,1.46,8.99],[1,1.47,59.83],[2,1.49,1.67]],"ltp":1.45,"tv":668.9,"id":19587555}],"tv":985.32}]}
{"op":"mcm","clk":"11983919639","pt":1724874861554,"mc":[{"id":"1.232375043","rc":[{"batl":[[0,1.46,4.49]],"ltp":1.45,"tv":668.9,"id":19587555}]}]}
{"op":"mcm","clk":"11983920682","pt":1724874872091,"mc":[{"id":"1.232375043","rc":[{"batb":[[0,1.43,89.81],[1,1.37,7.58],[2,1.36,104.6]],"ltp":1.45,"tv":668.9,"id":19587555}]}]}
{"op":"mcm","clk":"11983921708","pt":1724874881308,"mc":[{"id":"1.232375043","rc":[{"batl":[[0,1.46,9.32]],"ltp":1.45,"tv":668.9,"id":19587555}]}]}
{"op":"mcm","clk":"11984045460","pt":1724875975125,"mc":[{"id":"1.232375043","rc":[{"trd":[[1.52,272.74]],"ltp":2.98,"tv":316.41,"id":25651861},{"trd":[[1.41,9.42],[1.44,17.79],[1.49,17.03],[1.5,318.94],[1.54,33.53],[1.55,28.23],[1.56,36.83],[1.57,23.15],[2.16,31.67]],"batl":[[0,1.46,9.32]],"ltp":1.45,"tv":668.86,"id":19587555}],"tv":985.27}]}
{"op":"mcm","clk":"11984101327","pt":1724876507264,"mc":[{"id":"1.232375043","rc":[{"batl":[[0,1.46,11.32]],"ltp":1.45,"tv":668.86,"id":19587555}]}]}
{"op":"mcm","clk":"11984119381","pt":1724876696667,"mc":[{"id":"1.232375043","rc":[{"batb":[[0,3.05,8.25],[1,3,19.31],[2,2.2,58.43]],"ltp":2.98,"tv":316.41,"id":25651861},{"batb":[[1,1.37,36.47]],"ltp":1.45,"tv":668.86,"id":19587555}]}]}
{"op":"mcm","clk":"11984120912","pt":1724876714721,"mc":[{"id":"1.232375043","rc":[{"batb":[[2,2.72,16.51]],"ltp":2.98,"tv":316.41,"id":25651861}]}]}
{"op":"mcm","clk":"11984404102","pt":1724881375089,"mc":[{"id":"1.232375043","rc":[{"trd":[[1.52,272.58]],"batb":[[0,3.05,8.25],[2,2.72,16.5]],"ltp":2.98,"tv":316.25,"id":25651861},{"trd":[[1.41,9.42],[1.44,17.79],[1.49,17.04],[1.5,318.78],[1.54,33.54],[1.55,28.23],[1.56,36.83],[1.57,23.15],[2.16,31.68]],"batb":[[1,1.37,36.45]],"batl":[[0,1.46,11.32]],"ltp":1.45,"tv":668.73,"id":19587555}],"tv":984.98}]}
{"op":"mcm","clk":"11984410498","pt":1724881487044,"mc":[{"id":"1.232375043","rc":[{"trd":[[3.15,0.51]],"ltp":3.15,"tv":316.76,"id":25651861},{"trd":[[1.46,1.11]],"batl":[[0,1.46,10.21]],"ltp":1.46,"tv":669.84,"id":19587555}],"tv":986.61}]}
{"op":"mcm","clk":"11984418568","pt":1724881649793,"mc":[{"id":"1.232375043","rc":[{"batb":[[1,1.37,28.87]],"ltp":1.46,"tv":669.84,"id":19587555}]}]}
{"op":"mcm","clk":"11984509234","pt":1724884350135,"mc":[{"id":"1.232375043","rc":[{"trd":[[1.52,272.58]],"ltp":3.15,"tv":316.76,"id":25651861},{"trd":[[1.43,69.32],[1.5,318.78],[1.54,33.53],[1.55,28.23],[1.56,36.83],[2.16,31.68]],"batb":[[0,1.43,86.81]],"ltp":1.43,"tv":675.84,"id":19587555}],"tv":992.6}]}
{"op":"mcm","clk":"11984509340","pt":1724884353053,"mc":[{"id":"1.232375043","rc":[{"batb":[[0,1.43,89.81]],"ltp":1.43,"tv":675.84,"id":19587555}]}]}
{"op":"mcm","clk":"11984617173","pt":1724886775128,"mc":[{"id":"1.232375043","rc":[{"trd":[[1.52,272.55]],"batb":[[2,2.72,16.5]],"ltp":3.15,"tv":316.73,"id":25651861},{"trd":[[1.41,9.42],[1.44,17.79],[1.49,17.04],[1.5,318.75],[1.54,33.54],[1.55,28.23],[1.56,36.84],[1.57,23.16],[2.16,31.68]],"batb":[[1,1.37,28.87]],"batl":[[0,1.46,10.21]],"ltp":1.43,"tv":675.83,"id":19587555}],"tv":992.57}]}
{"op":"mcm","clk":"11984930742","pt":1724891839460,"mc":[{"id":"1.232375043","rc":[{"trd":[[1.52,272.57]],"batb":[[2,2.72,16.5]],"ltp":3.15,"tv":316.75,"id":25651861},{"trd":[[1.46,4.15],[1.5,318.77]],"batb":[[1,1.37,28.87]],"batl":[[0,1.46,8.69]],"ltp":1.46,"tv":678.88,"id":19587555}],"tv":995.64}]}
{"op":"mcm","clk":"11984932416","pt":1724891867405,"mc":[{"id":"1.232375043","rc":[{"batl":[[0,1.44,1.52],[1,1.46,8.69],[2,1.47,59.83]],"ltp":1.46,"tv":678.88,"id":19587555}]}]}
{"op":"mcm","clk":"11984932584","pt":1724891869932,"mc":[{"id":"1.232375043","rc":[{"batl":[[0,1.46,8.69],[1,1.47,59.83],[2,1.49,1.67]],"ltp":1.46,"tv":678.88,"id":19587555}]}]}
{"op":"mcm","clk":"11984936737","pt":1724891931795,"mc":[{"id":"1.232375043","rc":[{"batl":[[0,1.44,1.52],[1,1.46,8.69],[2,1.47,59.83]],"ltp":1.46,"tv":678.88,"id":19587555}]}]}
{"op":"mcm","clk":"11984936857","pt":1724891933596,"mc":[{"id":"1.232375043","rc":[{"batl":[[0,1.46,8.69],[1,1.47,59.83],[2,1.49,1.67]],"ltp":1.46,"tv":678.88,"id":19587555}]}]}
{"op":"mcm","clk":"11984939257","pt":1724891969150,"mc":[{"id":"1.232375043","rc":[{"batl":[[0,1.44,1.52],[1,1.46,8.69],[2,1.47,59.83]],"ltp":1.46,"tv":678.88,"id":19587555}]}]}
{"op":"mcm","clk":"11984939342","pt":1724891970623,"mc":[{"id":"1.232375043","rc":[{"batl":[[0,1.46,8.69],[1,1.47,59.83],[2,1.49,1.67]],"ltp":1.46,"tv":678.88,"id":19587555}]}]}
{"op":"mcm","clk":"11984945691","pt":1724892068964,"mc":[{"id":"1.232375043","rc":[{"batl":[[0,1.44,1.52],[1,1.46,8.69],[2,1.47,59.83]],"ltp":1.46,"tv":678.88,"id":19587555}]}]}
{"op":"mcm","clk":"11984945832","pt":1724892070773,"mc":[{"id":"1.232375043","rc":[{"batl":[[0,1.46,8.69],[1,1.47,59.83],[2,1.49,1.67]],"ltp":1.46,"tv":678.88,"id":19587555}]}]}
{"op":"mcm","clk":"11984947230","pt":1724892091546,"mc":[{"id":"1.232375043","rc":[{"trd":[[1.43,70.84]],"batb":[[0,1.43,89.05]],"ltp":1.43,"tv":680.4,"id":19587555}],"tv":997.16}]}
{"op":"mcm","clk":"11984947477","pt":1724892095261,"mc":[{"id":"1.232375043","rc":[{"batb":[[0,1.43,89.81]],"ltp":1.43,"tv":680.4,"id":19587555}]}]}
{"op":"mcm","clk":"11984948104","pt":1724892105467,"mc":[{"id":"1.232375043","rc":[{"trd":[[1.43,72.36]],"batb":[[0,1.43,89.05]],"ltp":1.43,"tv":681.92,"id":19587555}],"tv":998.68}]}
{"op":"mcm","clk":"11984948426","pt":1724892110259,"mc":[{"id":"1.232375043","rc":[{"batb":[[0,1.43,89.81]],"ltp":1.43,"tv":681.92,"id":19587555}]}]}
{"op":"mcm","clk":"11984949659","pt":1724892128513,"mc":[{"id":"1.232375043","rc":[{"batb":[[0,1.45,1.52],[1,1.43,89.81],[2,1.37,28.87]],"ltp":1.43,"tv":681.92,"id":19587555}]}]}
{"op":"mcm","clk":"11984949802","pt":1724892130631,"mc":[{"id":"1.232375043","rc":[{"batb":[[0,1.43,89.81],[1,1.37,28.87],[2,1.36,104.6]],"ltp":1.43,"tv":681.92,"id":19587555}]}]}
{"op":"mcm","clk":"11984951957","pt":1724892166459,"mc":[{"id":"1.232375043","rc":[{"trd":[[1.46,7.18]],"batl":[[0,1.46,2]],"ltp":1.46,"tv":684.95,"id":19587555}],"tv":1001.71}]}
{"op":"mcm","clk":"11984951962","pt":1724892166563,"mc":[{"id":"1.232375043","rc":[{"batb":[[0,1.44,6.75],[1,1.43,89.81],[2,1.37,28.87]],"ltp":1.46,"tv":684.95,"id":19587555}]}]}
{"op":"mcm","clk":"11984952028","pt":1724892167856,"mc":[{"id":"1.232375043","rc":[{"batl":[[0,1.46,6.65]],"ltp":1.46,"tv":684.95,"id":19587555}]}]}
{"op":"mcm","clk":"11984968958","pt":1724892270580,"mc":[{"id":"1.232375043","rc":[{"trd":[[1.44,20.83]],"batb":[[0,1.44,5.23]],"ltp":1.44,"tv":687.99,"id":19587555}],"tv":1004.74}]}
{"op":"mcm","clk":"11985005659","pt":1724892852971,"mc":[{"id":"1.232375043","rc":[{"batl":[[1,1.49,1.67],[2,1.51,2]],"ltp":1.44,"tv":687.99,"id":19587555}]}]}
{"op":"mcm","clk":"11985005754","pt":1724892854984,"mc":[{"id":"1.232375043","rc":[{"batl":[[0,1.46,2]],"ltp":1.44,"tv":687.99,"id":19587555}]}]}
{"op":"mcm","clk":"11985006202","pt":1724892862997,"mc":[{"id":"1.232375043","rc":[{"trd":[[1.44,31.29]],"batb":[[0,1.43,89.81],[1,1.37,28.87],[2,1.36,104.6]],"batl":[[0,1.44,36.61],[1,1.46,2],[2,1.49,1.67]],"ltp":1.44,"tv":698.45,"id":19587555}],"tv":1015.2}]}
{"op":"mcm","clk":"11985006240","pt":1724892863614,"mc":[{"id":"1.232375043","rc":[{"batl":[[0,1.44,44.28]],"ltp":1.44,"tv":698.45,"id":19587555}]}]}
{"op":"mcm","clk":"11985008051","pt":1724892895725,"mc":[{"id":"1.232375043","rc":[{"batl":[[2,1.48,16.73]],"ltp":1.44,"tv":698.45,"id":19587555}]}]}
{"op":"mcm","clk":"11985078114","pt":1724893993142,"mc":[{"id":"1.232375043","rc":[{"trd":[[1.52,272.31]],"batb":[[0,3.05,8.24],[2,2.72,16.48]],"ltp":3.15,"tv":316.49,"id":25651861},{"trd":[[1.41,9.42],[1.43,85.75],[1.44,31.28],[1.46,7.18],[1.49,17.04],[1.5,318.5],[1.54,33.53],[1.55,28.23],[1.56,36.83],[1.57,23.15],[2.16,31.67]],"batb":[[0,1.43,83.11],[1,1.37,28.84]],"batl":[[0,1.44,44.28]],"ltp":1.43,"tv":711.54,"id":19587555}],"tv":1028.03}]}
{"op":"mcm","clk":"11985078338","pt":1724893996304,"mc":[{"id":"1.232375043","rc":[{"batb":[[0,1.43,89.81]],"ltp":1.43,"tv":711.54,"id":19587555}]}]}
{"op":"mcm","clk":"11985081829","pt":1724894051511,"mc":[{"id":"1.232375043","rc":[{"batb":[[0,3.15,17.96],[1,3.05,8.24]],"ltp":3.15,"tv":316.49,"id":25651861},{"batb":[[0,1.4,96.55]],"ltp":1.43,"tv":711.54,"id":19587555}]}]}
{"op":"mcm","clk":"11985161863","pt":1724895441805,"mc":[{"id":"1.232375043","rc":[{"batb":[[1,1.36,104.6],[2,1.35,50.26]],"ltp":1.43,"tv":711.54,"id":19587555}]}]}
{"op":"mcm","clk":"11985161922","pt":1724895442779,"mc":[{"id":"1.232375043","rc":[{"batb":[[1,2.72,16.48],[2,2.2,58.43]],"ltp":3.15,"tv":316.49,"id":25651861}]}]}
{"op":"mcm","clk":"11985162030","pt":1724895444784,"mc":[{"id":"1.232375043","rc":[{"batb":[[1,2.2,58.43],[2,2,50]],"ltp":3.15,"tv":316.49,"id":25651861}]}]}
{"op":"mcm","clk":"11985247368","pt":1724896892853,"mc":[{"id":"1.232375043","rc":[{"trd":[[1.52,272.43]],"ltp":3.15,"tv":316.61,"id":25651861},{"trd":[[1.46,7.18],[1.5,318.62]],"batb":[[2,1.35,50.27]],"ltp":1.43,"tv":711.66,"id":19587555}],"tv":1028.27}]}
{"op":"mcm","clk":"11985398903","pt":1724899447677,"mc":[{"id":"1.232375043","rc":[{"trd":[[3.25,1.26]],"ltp":3.25,"tv":317.87,"id":25651861},{"trd":[[1.44,34.12]],"batl":[[0,1.44,41.44]],"ltp":1.44,"tv":714.5,"id":19587555}],"tv":1032.37}]}
{"op":"mcm","clk":"11985436949","pt":1724900165669,"mc":[{"id":"1.232375043","rc":[{"trd":[[1.4,9.86]],"batb":[[0,1.4,91.62]],"ltp":1.4,"tv":724.36,"id":19587555}],"tv":1042.23}]}
{"op":"mcm","clk":"11985437102","pt":1724900168752,"mc":[{"id":"1.232375043","rc":[{"batb":[[0,1.4,96.55]],"ltp":1.4,"tv":724.36,"id":19587555}]}]}
{"op":"mcm","clk":"11985460344","pt":1724900690927,"mc":[{"id":"1.232375043","rc":[{"trd":[[1.52,272.35]],"ltp":3.25,"tv":317.78,"id":25651861},{"trd":[[1.4,9.86],[1.41,9.42],[1.44,34.12],[1.46,7.18],[1.49,17.04],[1.5,318.54],[1.54,33.54],[1.55,28.23],[1.56,36.84],[1.57,23.16],[2.16,31.68]],"batb":[[2,1.35,50.26]],"batl":[[0,1.44,7.67]],"ltp":1.4,"tv":724.31,"id":19587555}],"tv":1042.1}]}
{"op":"mcm","clk":"11985460410","pt":1724900692263,"mc":[{"id":"1.232375043","rc":[{"batl":[[0,1.46,9.56],[1,1.48,16.73],[2,1.49,1.67]],"ltp":1.4,"tv":724.31,"id":19587555}]}]}
{"op":"mcm","clk":"11985462200","pt":1724900726516,"mc":[{"id":"1.232375043","rc":[{"batl":[[0,1.45,50.2],[1,1.46,9.56],[2,1.48,16.73]],"ltp":1.4,"tv":724.31,"id":19587555}]}]}
{"op":"mcm","clk":"11985462236","pt":1724900726983,"mc":[{"id":"1.232375043","rc":[{"batl":[[0,1.44,7.67],[1,1.45,50.2],[2,1.46,2]],"ltp":1.4,"tv":724.31,"id":19587555}]}]}
{"op":"mcm","clk":"11985466591","pt":1724900810417,"mc":[{"id":"1.232375043","rc":[{"batb":[[0,3.25,17.16]],"ltp":3.25,"tv":317.78,"id":25651861},{"batb":[[0,1.38,101.63]],"ltp":1.4,"tv":724.31,"id":19587555}]}]}
{"op":"mcm","clk":"11985472484","pt":1724900923837,"mc":[{"id":"1.232375043","rc":[{"batb":[[2,1.35,35.18]],"ltp":1.4,"tv":724.31,"id":19587555}]}]}
{"op":"mcm","clk":"11985473138","pt":1724900938968,"mc":[{"id":"1.232375043","rc":[{"batl":[[0,1.44,14.91]],"ltp":1.4,"tv":724.31,"id":19587555}]}]}
{"op":"mcm","clk":"11985476468","pt":1724901010135,"mc":[{"id":"1.232375043","rc":[{"batl":[[0,1.43,1.09],[1,1.44,14.91],[2,1.45,50.2]],"ltp":1.4,"tv":724.31,"id":19587555}]}]}
{"op":"mcm","clk":"11985486429","pt":1724901214290,"mc":[{"id":"1.232375043","rc":[{"batb":[[0,1.38,102.55]],"ltp":1.4,"tv":724.31,"id":19587555}]}]}
{"op":"mcm","clk":"11985487878","pt":1724901242041,"mc":[{"id":"1.232375043","rc":[{"batl":[[1,1.44,19.26]],"ltp":1.4,"tv":724.31,"id":19587555}]}]}
{"op":"mcm","clk":"11985497311","pt":1724901424840,"mc":[{"id":"1.232375043","rc":[{"batl":[[1,1.44,23.61]],"ltp":1.4,"tv":724.31,"id":19587555}]}]}
{"op":"mcm","clk":"11985500665","pt":1724901500441,"mc":[{"id":"1.232375043","rc":[{"batb":[[0,1.38,101.63]],"ltp":1.4,"tv":724.31,"id":19587555}]}]}
{"op":"mcm","clk":"11985539102","pt":1724902284702,"mc":[{"id":"1.232375043","rc":[{"trd":[[1.38,66.84]],"batb":[[0,1.38,68.21]],"ltp":1.38,"tv":791.15,"id":19587555}],"tv":1108.94}]}
{"op":"mcm","clk":"11985539375","pt":1724902289812,"mc":[{"id":"1.232375043","rc":[{"batb":[[0,1.38,101.63]],"ltp":1.38,"tv":791.15,"id":19587555}]}]}
{"op":"mcm","clk":"11985596459","pt":1724903470671,"mc":[{"id":"1.232375043","rc":[{"trd":[[3.25,2.29],[3.3,0.47]],"batb":[[0,3.25,16.64]],"ltp":3.25,"tv":319.29,"id":25651861},{"trd":[[1.43,86.84]],"batl":[[0,1.44,23.61],[1,1.45,50.2],[2,1.46,2]],"ltp":1.43,"tv":792.24,"id":19587555}],"tv":1111.54}]}
{"op":"mcm","clk":"11985596593","pt":1724903473488,"mc":[{"id":"1.232375043","rc":[{"batb":[[0,3.25,17.16]],"ltp":3.25,"tv":319.29,"id":25651861}]}]}
{"op":"mcm","clk":"11985645282","pt":1724904622210,"mc":[{"id":"1.232375043","tv":1111.54}]}
{"op":"mcm","clk":"11985651461","pt":1724904772960,"mc":[{"id":"1.232375043","rc":[{"trd":[[1.38,87.42]],"batb":[[0,1.38,91.34]],"ltp":1.38,"tv":812.82,"id":19587555}],"tv":1132.12}]}
{"op":"mcm","clk":"11985651624","pt":1724904777362,"mc":[{"id":"1.232375043","rc":[{"batb":[[0,1.38,101.63]],"ltp":1.38,"tv":812.82,"id":19587555}]}]}
{"op":"mcm","clk":"11985656098","pt":1724904897640,"mc":[{"id":"1.232375043","rc":[{"batl":[[0,1.43,10.3],[1,1.44,23.61],[2,1.45,50.2]],"ltp":1.38,"tv":812.82,"id":19587555}]}]}
{"op":"mcm","clk":"11985656136","pt":1724904898564,"mc":[{"id":"1.232375043","rc":[{"batl":[[1,1.44,19.26]],"ltp":1.38,"tv":812.82,"id":19587555}]}]}
{"op":"mcm","clk":"11985656171","pt":1724904899657,"mc":[{"id":"1.232375043","rc":[{"batl":[[1,1.44,12.02]],"ltp":1.38,"tv":812.82,"id":19587555}]}]}
{"op":"mcm","clk":"11985690849","pt":1724905984623,"mc":[{"id":"1.232375043","rc":[{"trd":[[1.38,94.46]],"batb":[[0,1.38,98.11]],"ltp":1.38,"tv":819.86,"id":19587555}],"tv":1139.16}]}
{"op":"mcm","clk":"11985690907","pt":1724905985950,"mc":[{"id":"1.232375043","rc":[{"batb":[[0,1.38,101.63]],"ltp":1.38,"tv":819.86,"id":19587555}]}]}
{"op":"mcm","clk":"11985691530","pt":1724906008662,"mc":[{"id":"1.232375043","rc":[{"batl":[[0,1.43,11.15]],"ltp":1.38,"tv":819.86,"id":19587555}]}]}
{"op":"mcm","clk":"11985692647","pt":1724906050973,"mc":[{"id":"1.232375043","rc":[{"trd":[[1.39,5.68],[1.43,87.24]],"batl":[[0,1.43,10.1]],"ltp":1.43,"tv":821.94,"id":19587555}],"tv":1141.24}]}
{"op":"mcm","clk":"11985697630","pt":1724906220069,"mc":[{"id":"1.232375043","rc":[{"trd":[[3.65,2.7]],"ltp":3.65,"tv":321.99,"id":25651861},{"trd":[[1.38,101.6]],"batb":[[0,1.38,94.49]],"ltp":1.38,"tv":829.08,"id":19587555}],"tv":1151.08}]}
{"op":"mcm","clk":"11985697673","pt":1724906221671,"mc":[{"id":"1.232375043","rc":[{"batb":[[0,1.38,101.63]],"ltp":1.38,"tv":829.08,"id":19587555}]}]}
{"op":"mcm","clk":"11985698819","pt":1724906264944,"mc":[{"id":"1.232375043","rc":[{"batl":[[0,1.4,1.97],[1,1.43,10.1],[2,1.44,12.02]],"ltp":1.38,"tv":829.08,"id":19587555}]}]}
{"op":"mcm","clk":"11985709645","pt":1724906628282,"mc":[{"id":"1.232375043","rc":[{"batl":[[0,3.9,1]],"ltp":3.65,"tv":321.99,"id":25651861}]}]}
{"op":"mcm","clk":"11985709868","pt":1724906633577,"mc":[{"id":"1.232375043","rc":[{"batl":[[0,4.1,1]],"ltp":3.65,"tv":321.99,"id":25651861}]}]}
{"op":"mcm","clk":"11985709968","pt":1724906636849,"mc":[{"id":"1.232375043","rc":[{"batl":[[0,3.95,1]],"ltp":3.65,"tv":321.99,"id":25651861}]}]}
{"op":"mcm","clk":"11985710121","pt":1724906640902,"mc":[{"id":"1.232375043","rc":[{"batl":[[0,4.6,1]],"ltp":3.65,"tv":321.99,"id":25651861}]}]}
{"op":"mcm","clk":"11985710205","pt":1724906644101,"mc":[{"id":"1.232375043","rc":[{"batl":[[0,4.9,1]],"ltp":3.65,"tv":321.99,"id":25651861}]}]}
{"op":"mcm","clk":"11985710442","pt":1724906649883,"mc":[{"id":"1.232375043","rc":[{"batl":[[0,4.1,1]],"ltp":3.65,"tv":321.99,"id":25651861}]}]}
{"op":"mcm","clk":"11985710595","pt":1724906653818,"mc":[{"id":"1.232375043","rc":[{"batl":[[0,3.8,1]],"ltp":3.65,"tv":321.99,"id":25651861}]}]}
{"op":"mcm","clk":"11985710743","pt":1724906658919,"mc":[{"id":"1.232375043","rc":[{"batl":[[0,3.85,1]],"ltp":3.65,"tv":321.99,"id":25651861}]}]}
{"op":"mcm","clk":"11985710869","pt":1724906663110,"mc":[{"id":"1.232375043","rc":[{"batl":[[0,3.8,1]],"ltp":3.65,"tv":321.99,"id":25651861}]}]}
{"op":"mcm","clk":"11985711053","pt":1724906669023,"mc":[{"id":"1.232375043","rc":[{"batl":[[0,3.75,1]],"ltp":3.65,"tv":321.99,"id":25651861}]}]}
{"op":"mcm","clk":"11985711218","pt":1724906674947,"mc":[{"id":"1.232375043","rc":[{"batl":[[0,3.7,1]],"ltp":3.65,"tv":321.99,"id":25651861}]}]}
{"op":"mcm","clk":"11985711303","pt":1724906678324,"mc":[{"id":"1.232375043","rc":[{"batl":[[0,3.6,1]],"ltp":3.65,"tv":321.99,"id":25651861}]}]}
{"op":"mcm","clk":"11985711441","pt":1724906682154,"mc":[{"id":"1.232375043","rc":[{"batl":[[0,3.55,1]],"ltp":3.65,"tv":321.99,"id":25651861}]}]}
{"op":"mcm","clk":"11985711605","pt":1724906686549,"mc":[{"id":"1.232375043","rc":[{"trd":[[3.5,0.79]],"batl":[[0,3.5,0.21]],"ltp":3.5,"tv":322.78,"id":25651861},{"trd":[[1.4,11.82]],"batl":[[0,1.43,10.1],[1,1.44,12.02],[2,1.45,50.2]],"ltp":1.4,"tv":831.05,"id":19587555}],"tv":1153.84}]}
{"op":"mcm","clk":"11985712064","pt":1724906701872,"mc":[{"id":"1.232375043","rc":[{"batb":[[0,1.4,4.19],[1,1.38,101.63],[2,1.36,104.6]],"ltp":1.4,"tv":831.05,"id":19587555}]}]}
{"op":"mcm","clk":"11985716844","pt":1724906846159,"mc":[{"id":"1.232375043","rc":[{"batb":[[0,1.38,101.63],[1,1.36,104.6],[2,1.35,35.18]],"ltp":1.4,"tv":831.05,"id":19587555}]}]}
{"op":"mcm","clk":"11985717169","pt":1724906856935,"mc":[{"id":"1.232375043","rc":[{"trd":[[3.3,1.98]],"ltp":3.3,"tv":324.29,"id":25651861},{"trd":[[1.43,90.73]],"batl":[[0,1.43,6.62]],"ltp":1.43,"tv":834.54,"id":19587555}],"tv":1158.83}]}
{"op":"mcm","clk":"11985717205","pt":1724906858064,"mc":[{"id":"1.232375043","rc":[{"batl":[[1,1.44,18.68]],"ltp":1.43,"tv":834.54,"id":19587555}]}]}
{"op":"mcm","clk":"11985723174","pt":1724907076377,"mc":[{"id":"1.232375043","rc":[{"batl":[[0,3.6,0.21]],"ltp":3.3,"tv":324.29,"id":25651861}]}]}
{"op":"mcm","clk":"11985725164","pt":1724907145063,"mc":[{"id":"1.232375043","rc":[{"trd":[[1.38,102.15]],"ltp":1.38,"tv":835.08,"id":19587555}],"tv":1159.38}]}
{"op":"mcm","clk":"11985727225","pt":1724907216357,"mc":[{"id":"1.232375043","rc":[{"batl":[[0,3.45,1.7],[1,3.6,0.21]],"ltp":3.3,"tv":324.29,"id":25651861}]}]}
{"op":"mcm","clk":"11985729712","pt":1724907296858,"mc":[{"id":"1.232375043","rc":[{"trd":[[3.45,0.05]],"batl":[[0,3.45,1.65]],"ltp":3.45,"tv":324.34,"id":25651861},{"trd":[[1.4,11.95]],"ltp":1.4,"tv":835.2,"id":19587555}],"tv":1159.55}]}
{"op":"mcm","clk":"11985730508","pt":1724907323692,"mc":[{"id":"1.232375043","rc":[{"batb":[[0,1.41,7.04],[1,1.38,101.63],[2,1.36,104.6]],"ltp":1.4,"tv":835.2,"id":19587555}]}]}
{"op":"mcm","clk":"11985730676","pt":1724907329933,"mc":[{"id":"1.232375043","rc":[{"batb":[[0,1.4,7.04]],"ltp":1.4,"tv":835.2,"id":19587555}]}]}
{"op":"mcm","clk":"11985739374","pt":1724907601110,"mc":[{"id":"1.232375043","rc":[{"batb":[[0,3.3,4],[1,3.25,17.16],[2,2.2,58.43]],"ltp":3.45,"tv":324.34,"id":25651861}]}]}
{"op":"mcm","clk":"11985739489","pt":1724907603786,"mc":[{"id":"1.232375043","rc":[{"trd":[[1.52,272.24],[3.65,2.7]],"batb":[[0,3.25,17.16],[1,2.2,58.43],[2,2,50]],"ltp":3.45,"tv":324.23,"id":25651861},{"trd":[[1.38,102.14],[1.4,11.94],[1.41,9.42],[1.43,90.73],[1.44,34.12],[1.46,7.17],[1.49,17.03],[1.5,318.43],[1.54,33.53],[1.55,28.23],[1.56,36.83],[1.57,23.15],[2.16,31.67]],"batb":[[0,1.4,7.04]],"batl":[[0,1.43,6.62],[1,1.44,18.68]],"ltp":1.4,"tv":835.03,"id":19587555}],"tv":1159.26}]}
{"op":"mcm","clk":"11985739657","pt":1724907607186,"mc":[{"id":"1.232375043","rc":[{"batb":[[0,3.35,4],[1,3.25,17.16],[2,2.2,58.43]],"ltp":3.45,"tv":324.23,"id":25651861}]}]}
{"op":"mcm","clk":"11985739677","pt":1724907607799,"mc":[{"id":"1.232375043","rc":[{"batl":[[1,1.44,11.01]],"ltp":1.4,"tv":835.03,"id":19587555}]}]}
{"op":"mcm","clk":"11985739877","pt":1724907612821,"mc":[{"id":"1.232375043","rc":[{"batb":[[0,3.25,17.16],[1,2.2,58.43],[2,2,50]],"ltp":3.45,"tv":324.23,"id":25651861}]}]}
{"op":"mcm","clk":"11985739924","pt":1724907614102,"mc":[{"id":"1.232375043","rc":[{"batl":[[1,1.44,17.67]],"ltp":1.4,"tv":835.03,"id":19587555}]}]}
{"op":"mcm","clk":"11985739969","pt":1724907615635,"mc":[{"id":"1.232375043","rc":[{"batb":[[0,3.3,4],[1,3.25,17.16],[2,2.2,58.43]],"ltp":3.45,"tv":324.23,"id":25651861}]}]}
{"op":"mcm","clk":"11985740094","pt":1724907619422,"mc":[{"id":"1.232375043","rc":[{"batb":[[0,3.25,17.16],[1,2.2,58.43],[2,2,50]],"ltp":3.45,"tv":324.23,"id":25651861}]}]}
{"op":"mcm","clk":"11985740283","pt":1724907624242,"mc":[{"id":"1.232375043","rc":[{"batb":[[0,3.3,4],[1,3.25,17.16],[2,2.2,58.43]],"ltp":3.45,"tv":324.23,"id":25651861}]}]}
{"op":"mcm","clk":"11985740676","pt":1724907629754,"mc":[{"id":"1.232375043","rc":[{"batb":[[0,3.25,17.16],[1,2.2,58.43],[2,2,50]],"ltp":3.45,"tv":324.23,"id":25651861}]}]}
{"op":"mcm","clk":"11985740746","pt":1724907632053,"mc":[{"id":"1.232375043","rc":[{"batb":[[0,3.3,4],[1,3.25,17.16],[2,2.2,58.43]],"ltp":3.45,"tv":324.23,"id":25651861}]}]}
{"op":"mcm","clk":"11985740869","pt":1724907635834,"mc":[{"id":"1.232375043","rc":[{"batb":[[0,3.25,17.16],[1,2.2,58.43],[2,2,50]],"ltp":3.45,"tv":324.23,"id":25651861}]}]}
{"op":"mcm","clk":"11985740989","pt":1724907638958,"mc":[{"id":"1.232375043","rc":[{"batb":[[0,3.3,4],[1,3.25,17.16],[2,2.2,58.43]],"ltp":3.45,"tv":324.23,"id":25651861}]}]}
{"op":"mcm","clk":"11985741104","pt":1724907642341,"mc":[{"id":"1.232375043","rc":[{"batb":[[0,3.25,17.16],[1,2.2,58.43],[2,2,50]],"ltp":3.45,"tv":324.23,"id":25651861}]}]}
{"op":"mcm","clk":"11985741229","pt":1724907645459,"mc":[{"id":"1.232375043","rc":[{"batb":[[0,3.3,4],[1,3.25,17.16],[2,2.2,58.43]],"ltp":3.45,"tv":324.23,"id":25651861}]}]}
{"op":"mcm","clk":"11985741393","pt":1724907649552,"mc":[{"id":"1.232375043","rc":[{"batb":[[0,3.25,17.16],[1,2.2,58.43],[2,2,50]],"ltp":3.45,"tv":324.23,"id":25651861}]}]}
{"op":"mcm","clk":"11985741569","pt":1724907654580,"mc":[{"id":"1.232375043","rc":[{"batb":[[0,3.3,4],[1,3.25,17.16],[2,2.2,58.43]],"ltp":3.45,"tv":324.23,"id":25651861}]}]}
{"op":"mcm","clk":"11985741691","pt":1724907657962,"mc":[{"id":"1.232375043","rc":[{"batb":[[0,3.25,17.16],[1,2.2,58.43],[2,2,50]],"ltp":3.45,"tv":324.23,"id":25651861}]}]}
{"op":"mcm","clk":"11985741951","pt":1724907665608,"mc":[{"id":"1.232375043","rc":[{"batb":[[0,3.3,4],[1,3.25,17.16],[2,2.2,58.43]],"ltp":3.45,"tv":324.23,"id":25651861}]}]}
{"op":"mcm","clk":"11985742130","pt":1724907671684,"mc":[{"id":"1.232375043","rc":[{"batb":[[0,3.25,17.16],[1,2.2,58.43],[2,2,50]],"ltp":3.45,"tv":324.23,"id":25651861}]}]}
{"op":"mcm","clk":"11985742228","pt":1724907674295,"mc":[{"id":"1.232375043","rc":[{"batb":[[0,3.35,4],[1,3.25,17.16],[2,2.2,58.43]],"ltp":3.45,"tv":324.23,"id":25651861}]}]}
{"op":"mcm","clk":"11985742284","pt":1724907675986,"mc":[{"id":"1.232375043","rc":[{"batl":[[1,1.44,11.01]],"ltp":1.4,"tv":835.03,"id":19587555}]}]}
{"op":"mcm","clk":"11985742469","pt":1724907681496,"mc":[{"id":"1.232375043","rc":[{"batb":[[0,3.25,17.16],[1,2.2,58.43],[2,2,50]],"ltp":3.45,"tv":324.23,"id":25651861},{"batl":[[1,1.44,15.36]],"ltp":1.4,"tv":835.03,"id":19587555}]}]}
{"op":"mcm","clk":"11985742545","pt":1724907683330,"mc":[{"id":"1.232375043","rc":[{"batb":[[0,3.4,4],[1,3.25,17.16],[2,2.2,58.43]],"ltp":3.45,"tv":324.23,"id":25651861},{"batl":[[1,1.44,22.02]],"ltp":1.4,"tv":835.03,"id":19587555}]}]}
{"op":"mcm","clk":"11985742582","pt":1724907684099,"mc":[{"id":"1.232375043","rc":[{"batl":[[1,1.44,17.67]],"ltp":1.4,"tv":835.03,"id":19587555}]}]}
{"op":"mcm","clk":"11985742832","pt":1724907690544,"mc":[{"id":"1.232375043","rc":[{"batb":[[0,3.25,17.16],[1,2.2,58.43],[2,2,50]],"ltp":3.45,"tv":324.23,"id":25651861}]}]}
{"op":"mcm","clk":"11985742970","pt":1724907693817,"mc":[{"id":"1.232375043","rc":[{"trd":[[3.45,3.34]],"batb":[[0,3.45,2.35],[1,3.25,17.16],[2,2.2,58.43]],"batl":[[0,3.6,0.21],[1,3.6,0]],"ltp":3.45,"tv":327.53,"id":25651861}],"tv":1162.56}]}
