{"op":"mcm","clk":"11888354938","pt":1724156334410,"mc":[{"id":"1.232048439","marketDefinition":{"bspMarket":false,"turnInPlayEnabled":true,"persistenceEnabled":true,"marketBaseRate":5.0,"eventId":"33511327","eventTypeId":"4","numberOfWinners":1,"bettingType":"ODDS","marketType":"MATCH_ODDS","marketTime":"2024-08-21T02:30:00.000Z","suspendTime":"2024-08-21T02:30:00.000Z","bspReconciled":false,"complete":true,"inPlay":false,"crossMatching":false,"runnersVoidable":false,"numberOfActiveRunners":2,"betDelay":0,"status":"OPEN","runners":[{"status":"ACTIVE","sortPriority":1,"id":8858694,"name":"Kuwait"},{"status":"ACTIVE","sortPriority":2,"id":247649,"name":"Hong Kong"}],"regulators":["MR_INT"],"countryCode":"GB","discountAllowed":false,"timezone":"GMT","openDate":"2024-08-21T02:30:00.000Z","version":6087496251,"name":"Match Odds","eventName":"Kuwait v Hong Kong"},"rc":[{"batb":[[0,1.03,200],[1,1.02,200],[2,1.01,220]],"ltp":0.0,"tv":0.0,"id":247649},{"batb":[[0,1.03,200],[1,1.02,200],[2,1.01,220]],"ltp":0.0,"tv":0.0,"id":8858694}]}]}
{"op":"mcm","clk":"11888354993","pt":1724156335451,"mc":[{"id":"1.232048439","marketDefinition":{"bspMarket":false,"turnInPlayEnabled":true,"persistenceEnabled":true,"marketBaseRate":5.0,"eventId":"33511327","eventTypeId":"4","numberOfWinners":1,"bettingType":"ODDS","marketType":"MATCH_ODDS","marketTime":"2024-08-21T02:30:00.000Z","suspendTime":"2024-08-21T02:30:00.000Z","bspReconciled":false,"complete":true,"inPlay":false,"crossMatching":false,"runnersVoidable":false,"numberOfActiveRunners":2,"betDelay":0,"status":"OPEN","runners":[{"status":"ACTIVE","sortPriority":1,"id":8858694,"name":"Kuwait"},{"status":"ACTIVE","sortPriority":2,"id":247649,"name":"Hong Kong"}],"regulators":["MR_INT"],"countryCode":"GB","discountAllowed":true,"timezone":"GMT","openDate":"2024-08-21T02:30:00.000Z","version":6087496251,"name":"Match Odds","eventName":"Kuwait v Hong Kong"}}]}
{"op":"mcm","clk":"11888355856","pt":1724156353236,"mc":[{"id":"1.232048439","rc":[{"batb":[[0,1.03,2349.73],[1,1.02,3374.35],[2,1.01,6382.17]],"ltp":0.0,"tv":0.0,"id":8858694}]}]}
{"op":"mcm","clk":"11888355907","pt":1724156354164,"mc":[{"id":"1.232048439","rc":[{"batb":[[0,1.04,1624.22],[1,1.03,2349.73],[2,1.02,3374.35]],"ltp":0.0,"tv":0.0,"id":247649},{"batb":[[0,1.04,1624.22],[1,1.03,2349.73],[2,1.02,3374.35]],"ltp":0.0,"tv":0.0,"id":8858694}]}]}
{"op":"mcm","clk":"11888375652","pt":1724156800427,"mc":[{"id":"1.232048439","rc":[{"batb":[[0,1.15,12.51],[1,1.04,1624.22],[2,1.03,2349.73]],"ltp":0.0,"tv":0.0,"id":8858694}]}]}
{"op":"mcm","clk":"11888377055","pt":1724156817457,"mc":[{"id":"1.232048439","rc":[{"batb":[[0,1.18,18.71],[1,1.04,1624.22],[2,1.03,2349.73]],"ltp":0.0,"tv":0.0,"id":247649}]}]}
{"op":"mcm","clk":"11888378596","pt":1724156828918,"mc":[{"id":"1.232048439","marketDefinition":{"bspMarket":false,"turnInPlayEnabled":true,"persistenceEnabled":true,"marketBaseRate":5.0,"eventId":"33511327","eventTypeId":"4","numberOfWinners":1,"bettingType":"ODDS","marketType":"MATCH_ODDS","marketTime":"2024-08-21T02:30:00.000Z","suspendTime":"2024-08-21T02:30:00.000Z","bspReconciled":false,"complete":true,"inPlay":false,"crossMatching":true,"runnersVoidable":false,"numberOfActiveRunners":2,"betDelay":0,"status":"OPEN","runners":[{"status":"ACTIVE","sortPriority":1,"id":8858694,"name":"Kuwait"},{"status":"ACTIVE","sortPriority":2,"id":247649,"name":"Hong Kong"}],"regulators":["MR_INT"],"countryCode":"GB","discountAllowed":true,"timezone":"GMT","openDate":"2024-08-21T02:30:00.000Z","version":6087496251,"name":"Match Odds","eventName":"Kuwait v Hong Kong"}}]}
{"op":"mcm","clk":"11888421238","pt":1724157745783,"mc":[{"id":"1.232048439","rc":[{"batb":[[0,1.41,106.53],[1,1.18,18.71],[2,1.04,1624.22]],"ltp":0.0,"tv":0.0,"id":247649},{"batb":[[0,3.1,20.8],[1,1.15,12.51],[2,1.04,1624.22]],"ltp":0.0,"tv":0.0,"id":8858694}]}]}
{"op":"mcm","clk":"11888429218","pt":1724157942017,"mc":[{"id":"1.232048439","rc":[{"batl":[[0,1.47,10]],"ltp":0.0,"tv":0.0,"id":247649}]}]}
{"op":"mcm","clk":"11888430728","pt":1724157973270,"mc":[{"id":"1.232048439","rc":[{"trd":[[3.1,4]],"batb":[[0,3.1,18.8]],"ltp":3.1,"tv":4.0,"id":8858694}],"tv":4.0}]}
{"op":"mcm","clk":"11888430881","pt":1724157976353,"mc":[{"id":"1.232048439","rc":[{"batb":[[0,3.1,20.8]],"ltp":3.1,"tv":4.0,"id":8858694}]}]}
{"op":"mcm","clk":"11888437497","pt":1724158105037,"mc":[{"id":"1.232048439","rc":[{"batl":[[0,1.45,2.77],[1,1.47,10]],"ltp":0.0,"tv":0.0,"id":247649}]}]}
{"op":"mcm","clk":"11888458482","pt":1724158559929,"mc":[{"id":"1.232048439","rc":[{"trd":[[1.45,0.2]],"batl":[[0,1.45,2.57]],"ltp":1.45,"tv":0.2,"id":247649},{"trd":[[3.2,0.09]],"ltp":3.2,"tv":4.08,"id":8858694}],"tv":4.28}]}
{"op":"mcm","clk":"11888459227","pt":1724158576807,"mc":[{"id":"1.232048439","rc":[{"batb":[[0,1.42,5.23],[1,1.41,106.53],[2,1.18,18.71]],"ltp":1.45,"tv":0.2,"id":247649}]}]}
{"op":"mcm","clk":"11888561139","pt":1724160641448,"mc":[{"id":"1.232048439","rc":[{"batb":[[2,1.18,18.68]],"ltp":1.45,"tv":0.2,"id":247649},{"batb":[[1,1.15,12.49],[2,1.04,1624.36]],"ltp":3.2,"tv":4.08,"id":8858694}]}]}
{"op":"mcm","clk":"11888573972","pt":1724160914432,"mc":[{"id":"1.232048439","rc":[{"batb":[[1,1.41,198.5]],"ltp":1.45,"tv":0.2,"id":247649},{"batb":[[0,3.1,38.75]],"ltp":3.2,"tv":4.08,"id":8858694}]}]}
{"op":"mcm","clk":"11888573981","pt":1724160914529,"mc":[{"id":"1.232048439","rc":[{"batb":[[1,1.41,91.97]],"ltp":1.45,"tv":0.2,"id":247649},{"batb":[[0,3.1,17.95]],"ltp":3.2,"tv":4.08,"id":8858694}]}]}
{"op":"mcm","clk":"11888574101","pt":1724160917253,"mc":[{"id":"1.232048439","rc":[{"trd":[[1.42,2]],"batb":[[0,1.42,4.23]],"ltp":1.42,"tv":2.19,"id":247649}],"tv":6.28}]}
{"op":"mcm","clk":"11888593748","pt":1724161269349,"mc":[{"id":"1.232048439","rc":[{"trd":[[1.42,7.53]],"batb":[[0,1.42,1.47]],"ltp":1.42,"tv":7.73,"id":247649}],"tv":11.82}]}
{"op":"mcm","clk":"11888657579","pt":1724162439518,"mc":[{"id":"1.232048439","rc":[{"trd":[[1.42,7.54]],"batb":[[2,1.04,1625.05]],"ltp":1.42,"tv":7.73,"id":247649},{"batb":[[1,1.15,12.5],[2,1.04,1625.05]],"ltp":3.2,"tv":4.08,"id":8858694}],"tv":11.82}]}
{"op":"mcm","clk":"11888657788","pt":1724162442887,"mc":[{"id":"1.232048439","rc":[{"batb":[[1,1.04,1625.05],[2,1.03,2350.83]],"ltp":3.2,"tv":4.08,"id":8858694}]}]}
{"op":"mcm","clk":"11888689450","pt":1724163019945,"mc":[{"id":"1.232048439","rc":[{"batl":[[0,1.44,6.23],[1,1.45,2.57],[2,1.47,10]],"ltp":1.42,"tv":7.73,"id":247649}]}]}
{"op":"mcm","clk":"11888689635","pt":1724163024043,"mc":[{"id":"1.232048439","rc":[{"batl":[[0,1.45,2.57],[1,1.47,10],[2,1.47,0]],"ltp":1.42,"tv":7.73,"id":247649}]}]}
{"op":"mcm","clk":"11888689921","pt":1724163029944,"mc":[{"id":"1.232048439","rc":[{"trd":[[1.42,10.47]],"batb":[[0,1.41,91.97],[1,1.04,1625.05],[2,1.03,2350.83]],"batl":[[0,1.42,1.65],[1,1.45,2.57],[2,1.47,10]],"ltp":1.42,"tv":10.67,"id":247649}],"tv":14.76}]}
{"op":"mcm","clk":"11888689945","pt":1724163030557,"mc":[{"id":"1.232048439","rc":[{"batl":[[2,1.47,15.05]],"ltp":1.42,"tv":10.67,"id":247649}]}]}
{"op":"mcm","clk":"11888697192","pt":1724163175953,"mc":[{"id":"1.232048439","rc":[{"batl":[[0,1.45,2.57],[1,1.47,15.05],[2,1.47,0]],"ltp":1.42,"tv":10.67,"id":247649}]}]}
{"op":"mcm","clk":"11888697936","pt":1724163189147,"mc":[{"id":"1.232048439","rc":[{"batl":[[0,1.44,1.87],[1,1.45,2.57],[2,1.47,15.05]],"ltp":1.42,"tv":10.67,"id":247649}]}]}
{"op":"mcm","clk":"11888709273","pt":1724163370959,"mc":[{"id":"1.232048439","rc":[{"trd":[[1.41,0.24]],"batb":[[0,1.41,91.85]],"ltp":1.41,"tv":10.91,"id":247649}],"tv":15.0}]}
{"op":"mcm","clk":"11888709337","pt":1724163371875,"mc":[{"id":"1.232048439","rc":[{"batb":[[0,1.41,91.97]],"ltp":1.41,"tv":10.91,"id":247649}]}]}
{"op":"mcm","clk":"11888733025","pt":1724163749464,"mc":[{"id":"1.232048439","rc":[{"trd":[[1.44,2]],"batl":[[0,1.45,3.44],[1,1.47,15.05],[2,1.47,0]],"ltp":1.44,"tv":12.91,"id":247649}],"tv":17.0}]}
{"op":"mcm","clk":"11888734050","pt":1724163768489,"mc":[{"id":"1.232048439","rc":[{"batl":[[2,1.5,5.1]],"ltp":1.44,"tv":12.91,"id":247649}]}]}
{"op":"mcm","clk":"11888734214","pt":1724163771376,"mc":[{"id":"1.232048439","rc":[{"batl":[[2,1.5,0]],"ltp":1.44,"tv":12.91,"id":247649}]}]}
{"op":"mcm","clk":"11888737090","pt":1724163820028,"mc":[{"id":"1.232048439","rc":[{"batl":[[2,1.5,5.1]],"ltp":1.44,"tv":12.91,"id":247649}]}]}
{"op":"mcm","clk":"11888936097","pt":1724166775088,"mc":[{"id":"1.232048439","rc":[{"trd":[[1.42,10.48]],"batb":[[1,1.04,1626.16],[2,1.03,2352.3]],"batl":[[1,1.47,15.06]],"ltp":1.44,"tv":12.91,"id":247649},{"batb":[[1,1.04,1626.16],[2,1.03,2352.3]],"ltp":3.2,"tv":4.08,"id":8858694}],"tv":17.0}]}
{"op":"mcm","clk":"11889022331","pt":1724167796458,"mc":[{"id":"1.232048439","rc":[{"trd":[[1.44,3]],"batl":[[0,1.45,2.94]],"ltp":1.44,"tv":13.91,"id":247649}],"tv":18.0}]}
{"op":"mcm","clk":"11889206601","pt":1724169856485,"mc":[{"id":"1.232048439","rc":[{"trd":[[1.44,3.37],[1.45,2.77]],"batb":[[1,1.04,1626.02],[2,1.03,2352.11]],"batl":[[0,1.47,15.06],[1,1.5,5.1],[2,1.5,0]],"ltp":1.45,"tv":16.85,"id":247649},{"trd":[[3.2,1.25],[3.25,0.16]],"batb":[[1,1.04,1626.02],[2,1.03,2352.11]],"batl":[[0,3.2,0.46]],"ltp":3.2,"tv":5.41,"id":8858694}],"tv":22.27}]}
{"op":"mcm","clk":"11889368847","pt":1724171695957,"mc":[{"id":"1.232048439","rc":[{"batb":[[1,1.51,24.96],[2,1.04,1626.02]],"ltp":3.2,"tv":5.41,"id":8858694}]}]}
{"op":"mcm","clk":"11889381316","pt":1724171824627,"mc":[{"id":"1.232048439","rc":[{"batb":[[1,1.11,18.81],[2,1.04,1626.02]],"ltp":1.45,"tv":16.85,"id":247649}]}]}
{"op":"mcm","clk":"11889382887","pt":1724171841383,"mc":[{"id":"1.232048439","rc":[{"batb":[[2,1.11,18.81]],"ltp":3.2,"tv":5.41,"id":8858694}]}]}
{"op":"mcm","clk":"11889661796","pt":1724174291425,"mc":[{"id":"1.232048439","rc":[{"trd":[[1.42,10.48]],"batb":[[1,1.11,18.8],[2,1.04,1634.41]],"batl":[[0,1.47,15.06]],"ltp":1.45,"tv":16.85,"id":247649},{"batb":[[1,1.51,25.03],[2,1.11,18.8]],"ltp":3.2,"tv":5.41,"id":8858694}],"tv":22.27}]}
{"op":"mcm","clk":"11889663366","pt":1724174304869,"mc":[{"id":"1.232048439","rc":[{"trd":[[3.1,8.28]],"batb":[[0,3.1,15.81]],"ltp":3.1,"tv":9.7,"id":8858694}],"tv":26.56}]}
{"op":"mcm","clk":"11889663834","pt":1724174308543,"mc":[{"id":"1.232048439","rc":[{"batb":[[0,3.1,17.95]],"ltp":3.1,"tv":9.7,"id":8858694}]}]}
{"op":"mcm","clk":"11889665248","pt":1724174319667,"mc":[{"id":"1.232048439","rc":[{"batl":[[0,1.47,19.06]],"ltp":1.45,"tv":16.85,"id":247649}]}]}
{"op":"mcm","clk":"11889667820","pt":1724174341516,"mc":[{"id":"1.232048439","rc":[{"batl":[[2,3.5,1.82]],"ltp":1.45,"tv":16.85,"id":247649}]}]}
{"op":"mcm","clk":"11889710113","pt":1724174714424,"mc":[{"id":"1.232048439","rc":[{"batl":[[0,1.45,5.13],[1,1.47,14],[2,1.5,5.1]],"ltp":1.45,"tv":16.85,"id":247649},{"trd":[[3.2,285.28]],"ltp":3.2,"tv":293.72,"id":8858694}],"tv":310.58}]}
{"op":"mcm","clk":"11889710393","pt":1724174716827,"mc":[{"id":"1.232048439","rc":[{"batl":[[0,1.47,14],[1,1.5,5.1],[2,3.5,1.82]],"ltp":1.45,"tv":16.85,"id":247649}]}]}
{"op":"mcm","clk":"11889710728","pt":1724174719730,"mc":[{"id":"1.232048439","rc":[{"batl":[[0,1.47,19.06]],"ltp":1.45,"tv":16.85,"id":247649}]}]}
{"op":"mcm","clk":"11889715177","pt":1724174759084,"mc":[{"id":"1.232048439","rc":[{"batb":[[0,3.2,249.48],[1,3.1,17.95],[2,1.51,25.03]],"ltp":3.2,"tv":293.72,"id":8858694}]}]}
{"op":"mcm","clk":"11889715317","pt":1724174760187,"mc":[{"id":"1.232048439","rc":[{"trd":[[3.2,784.24]],"batb":[[0,3.1,17.95],[1,1.51,25.03],[2,1.11,18.8]],"ltp":3.2,"tv":792.69,"id":8858694}],"tv":809.54}]}
{"op":"mcm","clk":"11889719316","pt":1724174793827,"mc":[{"id":"1.232048439","rc":[{"batb":[[0,3.2,249.48],[1,3.1,17.95],[2,1.51,25.03]],"ltp":3.2,"tv":792.69,"id":8858694}]}]}
{"op":"mcm","clk":"11889719411","pt":1724174794502,"mc":[{"id":"1.232048439","rc":[{"trd":[[3.2,1283.21]],"batb":[[0,3.1,17.95],[1,1.51,25.03],[2,1.11,18.8]],"ltp":3.2,"tv":1291.65,"id":8858694}],"tv":1308.51}]}
{"op":"mcm","clk":"11889725286","pt":1724174847700,"mc":[{"id":"1.232048439","rc":[{"batb":[[0,3.2,249.48],[1,3.1,17.95],[2,1.51,25.03]],"ltp":3.2,"tv":1291.65,"id":8858694}]}]}
{"op":"mcm","clk":"11889725405","pt":1724174848998,"mc":[{"id":"1.232048439","rc":[{"batl":[[0,1.45,5.13],[1,1.47,14],[2,1.5,5.1]],"ltp":1.45,"tv":16.85,"id":247649},{"trd":[[3.2,1782.17]],"batb":[[0,3.1,17.95],[1,1.51,25.03],[2,1.11,18.8]],"ltp":3.2,"tv":1790.61,"id":8858694}],"tv":1807.47}]}
{"op":"mcm","clk":"11889725637","pt":1724174851204,"mc":[{"id":"1.232048439","rc":[{"batl":[[0,1.47,14],[1,1.5,5.1],[2,3.5,1.82]],"ltp":1.45,"tv":16.85,"id":247649}]}]}
{"op":"mcm","clk":"11889725913","pt":1724174854094,"mc":[{"id":"1.232048439","rc":[{"batl":[[0,1.47,19.06]],"ltp":1.45,"tv":16.85,"id":247649}]}]}
{"op":"mcm","clk":"11889735817","pt":1724174939414,"mc":[{"id":"1.232048439","rc":[{"batb":[[0,3.2,249.48],[1,3.1,17.95],[2,1.51,25.03]],"ltp":3.2,"tv":1790.61,"id":8858694}]}]}
{"op":"mcm","clk":"11889736012","pt":1724174941246,"mc":[{"id":"1.232048439","rc":[{"batl":[[0,1.47,14]],"ltp":1.45,"tv":16.85,"id":247649},{"trd":[[3.2,2281.13]],"batb":[[0,3.1,17.95],[1,1.51,25.03],[2,1.11,18.8]],"ltp":3.2,"tv":2289.58,"id":8858694}],"tv":2306.44}]}
{"op":"mcm","clk":"11889738514","pt":1724174960840,"mc":[{"id":"1.232048439","rc":[{"batb":[[0,3.2,249.48],[1,3.1,17.95],[2,1.51,25.03]],"ltp":3.2,"tv":2289.58,"id":8858694}]}]}
{"op":"mcm","clk":"11889738691","pt":1724174962239,"mc":[{"id":"1.232048439","rc":[{"batb":[[0,3.25,7.64],[1,3.2,249.48],[2,3.1,17.95]],"ltp":3.2,"tv":2289.58,"id":8858694}]}]}
{"op":"mcm","clk":"11889738843","pt":1724174963354,"mc":[{"id":"1.232048439","rc":[{"trd":[[3.2,2764.82],[3.25,15.44]],"batb":[[0,3.2,7.64],[1,3.1,17.95],[2,1.51,25.03]],"ltp":3.2,"tv":2788.54,"id":8858694}],"tv":2805.4}]}
{"op":"mcm","clk":"11889739093","pt":1724174965170,"mc":[{"id":"1.232048439","rc":[{"batl":[[0,1.46,5.09],[1,1.47,14],[2,1.5,5.1]],"ltp":1.45,"tv":16.85,"id":247649},{"batb":[[0,3.25,4],[1,3.2,7.64],[2,3.1,17.95]],"batl":[[0,3.4,7.3]],"ltp":3.2,"tv":2788.54,"id":8858694}]}]}
{"op":"mcm","clk":"11889739420","pt":1724174967683,"mc":[{"id":"1.232048439","rc":[{"batb":[[0,3.2,7.64],[1,3.1,17.95],[2,1.51,25.03]],"ltp":3.2,"tv":2788.54,"id":8858694}]}]}
{"op":"mcm","clk":"11889739919","pt":1724174971356,"mc":[{"id":"1.232048439","rc":[{"batb":[[0,3.25,4],[1,3.2,7.64],[2,3.1,17.95]],"ltp":3.2,"tv":2788.54,"id":8858694}]}]}
{"op":"mcm","clk":"11889740217","pt":1724174973787,"mc":[{"id":"1.232048439","rc":[{"batb":[[0,3.2,7.64],[1,3.1,17.95],[2,1.51,25.03]],"ltp":3.2,"tv":2788.54,"id":8858694}]}]}
{"op":"mcm","clk":"11889740893","pt":1724174979763,"mc":[{"id":"1.232048439","rc":[{"batb":[[0,3.25,4],[1,3.2,7.64],[2,3.1,17.95]],"ltp":3.2,"tv":2788.54,"id":8858694}]}]}
{"op":"mcm","clk":"11889741235","pt":1724174982570,"mc":[{"id":"1.232048439","rc":[{"batb":[[0,3.2,7.64],[1,3.1,17.95],[2,1.51,25.03]],"ltp":3.2,"tv":2788.54,"id":8858694}]}]}
{"op":"mcm","clk":"11889741627","pt":1724174986097,"mc":[{"id":"1.232048439","rc":[{"batb":[[0,3.25,4],[1,3.2,7.64],[2,3.1,17.95]],"ltp":3.2,"tv":2788.54,"id":8858694}]}]}
{"op":"mcm","clk":"11889741931","pt":1724174988599,"mc":[{"id":"1.232048439","rc":[{"batb":[[0,3.2,7.64],[1,3.1,17.95],[2,1.51,25.03]],"ltp":3.2,"tv":2788.54,"id":8858694}]}]}
{"op":"mcm","clk":"11889742417","pt":1724174992801,"mc":[{"id":"1.232048439","rc":[{"batb":[[0,3.25,4],[1,3.2,7.64],[2,3.1,17.95]],"ltp":3.2,"tv":2788.54,"id":8858694}]}]}
{"op":"mcm","clk":"11889742675","pt":1724174995184,"mc":[{"id":"1.232048439","rc":[{"batb":[[0,3.2,7.64],[1,3.1,17.95],[2,1.51,25.03]],"ltp":3.2,"tv":2788.54,"id":8858694}]}]}
{"op":"mcm","clk":"11889743580","pt":1724175002688,"mc":[{"id":"1.232048439","rc":[{"batb":[[0,3.25,4],[1,3.2,7.64],[2,3.1,17.95]],"ltp":3.2,"tv":2788.54,"id":8858694}]}]}
{"op":"mcm","clk":"11889743866","pt":1724175004995,"mc":[{"id":"1.232048439","rc":[{"batb":[[0,1.42,4],[1,1.41,95.97],[2,1.11,18.8]],"ltp":1.45,"tv":16.85,"id":247649},{"batb":[[0,3.2,7.64],[1,3.1,17.95],[2,1.51,25.03]],"batl":[[0,3.4,11.3]],"ltp":3.2,"tv":2788.54,"id":8858694}]}]}
{"op":"mcm","clk":"11889744361","pt":1724175008890,"mc":[{"id":"1.232048439","rc":[{"batb":[[0,3.25,4],[1,3.2,7.64],[2,3.1,17.95]],"ltp":3.2,"tv":2788.54,"id":8858694}]}]}
{"op":"mcm","clk":"11889744635","pt":1724175011197,"mc":[{"id":"1.232048439","rc":[{"batb":[[0,3.2,7.64],[1,3.1,17.95],[2,1.51,25.03]],"ltp":3.2,"tv":2788.54,"id":8858694}]}]}
{"op":"mcm","clk":"11889744949","pt":1724175013910,"mc":[{"id":"1.232048439","rc":[{"batb":[[0,3.25,4],[1,3.2,7.64],[2,3.1,17.95]],"ltp":3.2,"tv":2788.54,"id":8858694}]}]}
{"op":"mcm","clk":"11889745286","pt":1724175016651,"mc":[{"id":"1.232048439","rc":[{"batb":[[0,3.2,7.64],[1,3.1,17.95],[2,1.51,25.03]],"ltp":3.2,"tv":2788.54,"id":8858694}]}]}
{"op":"mcm","clk":"11889745762","pt":1724175019926,"mc":[{"id":"1.232048439","rc":[{"batl":[[0,1.46,9.09]],"ltp":1.45,"tv":16.85,"id":247649},{"batb":[[0,3.25,4],[1,3.2,7.64],[2,3.1,17.95]],"ltp":3.2,"tv":2788.54,"id":8858694}]}]}
{"op":"mcm","clk":"11889746065","pt":1724175022318,"mc":[{"id":"1.232048439","rc":[{"batb":[[0,3.2,7.64],[1,3.1,17.95],[2,1.51,25.03]],"ltp":3.2,"tv":2788.54,"id":8858694}]}]}
{"op":"mcm","clk":"11889746425","pt":1724175025430,"mc":[{"id":"1.232048439","rc":[{"batb":[[0,3.25,4],[1,3.2,7.64],[2,3.1,17.95]],"ltp":3.2,"tv":2788.54,"id":8858694}]}]}
{"op":"mcm","clk":"11889747307","pt":1724175032149,"mc":[{"id":"1.232048439","rc":[{"batb":[[0,3.2,7.64],[1,3.1,17.95],[2,1.51,25.03]],"ltp":3.2,"tv":2788.54,"id":8858694}]}]}
{"op":"mcm","clk":"11889748055","pt":1724175037431,"mc":[{"id":"1.232048439","rc":[{"batb":[[0,1.41,91.97],[1,1.11,18.8],[2,1.04,1634.41]],"ltp":1.45,"tv":16.85,"id":247649},{"batb":[[0,3.25,230.29],[1,3.2,7.64],[2,3.1,17.95]],"batl":[[0,3.4,7.3]],"ltp":3.2,"tv":2788.54,"id":8858694}]}]}
{"op":"mcm","clk":"11889748144","pt":1724175038048,"mc":[{"id":"1.232048439","rc":[{"batl":[[0,1.44,5.17],[1,1.46,4],[2,1.47,14]],"ltp":1.45,"tv":16.85,"id":247649}]}]}
{"op":"mcm","clk":"11889748591","pt":1724175041241,"mc":[{"id":"1.232048439","rc":[{"batb":[[0,3.25,234.29]],"ltp":3.2,"tv":2788.54,"id":8858694}]}]}
{"op":"mcm","clk":"11889749493","pt":1724175047337,"mc":[{"id":"1.232048439","rc":[{"batl":[[0,1.45,5.13],[1,1.47,14],[2,1.5,5.1]],"ltp":1.45,"tv":16.85,"id":247649},{"trd":[[3.25,476.02]],"batb":[[0,3.25,4]],"ltp":3.25,"tv":3249.12,"id":8858694}],"tv":3265.98}]}
{"op":"mcm","clk":"11889749868","pt":1724175050255,"mc":[{"id":"1.232048439","rc":[{"batb":[[0,1.42,4],[1,1.41,95.97],[2,1.11,18.8]],"ltp":1.45,"tv":16.85,"id":247649},{"batb":[[0,3.25,8]],"batl":[[0,3.4,11.3]],"ltp":3.25,"tv":3249.12,"id":8858694}]}]}
{"op":"mcm","clk":"11889749972","pt":1724175051037,"mc":[{"id":"1.232048439","rc":[{"batb":[[0,3.25,4]],"ltp":3.25,"tv":3249.12,"id":8858694}]}]}
{"op":"mcm","clk":"11889750271","pt":1724175053365,"mc":[{"id":"1.232048439","rc":[{"batb":[[0,3.3,4],[1,3.25,4],[2,3.2,7.64]],"ltp":3.25,"tv":3249.12,"id":8858694}]}]}
{"op":"mcm","clk":"11889751217","pt":1724175060943,"mc":[{"id":"1.232048439","rc":[{"batb":[[0,3.25,4],[1,3.2,7.64],[2,3.1,17.95]],"ltp":3.25,"tv":3249.12,"id":8858694}]}]}
{"op":"mcm","clk":"11889751681","pt":1724175064175,"mc":[{"id":"1.232048439","rc":[{"batb":[[0,3.35,4],[1,3.25,4],[2,3.2,7.64]],"ltp":3.25,"tv":3249.12,"id":8858694}]}]}
{"op":"mcm","clk":"11889751928","pt":1724175066085,"mc":[{"id":"1.232048439","rc":[{"batl":[[0,1.43,4],[1,1.45,5.13],[2,1.47,14]],"ltp":1.45,"tv":16.85,"id":247649},{"batb":[[1,3.2,7.64],[2,3.1,17.95]],"ltp":3.25,"tv":3249.12,"id":8858694}]}]}
{"op":"mcm","clk":"11889751972","pt":1724175066466,"mc":[{"id":"1.232048439","rc":[{"batl":[[0,1.45,5.13],[1,1.47,14],[2,1.5,5.1]],"ltp":1.45,"tv":16.85,"id":247649}]}]}
{"op":"mcm","clk":"11889752482","pt":1724175070263,"mc":[{"id":"1.232048439","rc":[{"batb":[[0,3.2,7.64],[1,3.1,17.95],[2,1.51,25.03]],"ltp":3.25,"tv":3249.12,"id":8858694}]}]}
{"op":"mcm","clk":"11889752815","pt":1724175072794,"mc":[{"id":"1.232048439","rc":[{"batb":[[0,3.25,4],[1,3.2,7.64],[2,3.1,17.95]],"ltp":3.25,"tv":3249.12,"id":8858694}]}]}
{"op":"mcm","clk":"11889753428","pt":1724175077021,"mc":[{"id":"1.232048439","rc":[{"batb":[[0,3.2,7.64],[1,3.1,17.95],[2,1.51,25.03]],"ltp":3.25,"tv":3249.12,"id":8858694}]}]}
{"op":"mcm","clk":"11889753953","pt":1724175080776,"mc":[{"id":"1.232048439","rc":[{"batb":[[0,3.2,11.64]],"ltp":3.25,"tv":3249.12,"id":8858694}]}]}
{"op":"mcm","clk":"11889754058","pt":1724175081495,"mc":[{"id":"1.232048439","rc":[{"batb":[[0,3.25,4],[1,3.2,11.64],[2,3.1,17.95]],"ltp":3.25,"tv":3249.12,"id":8858694}]}]}
{"op":"mcm","clk":"11889754418","pt":1724175084310,"mc":[{"id":"1.232048439","rc":[{"batb":[[0,3.2,11.64],[1,3.1,17.95],[2,1.51,25.03]],"ltp":3.25,"tv":3249.12,"id":8858694}]}]}
{"op":"mcm","clk":"11889754812","pt":1724175087599,"mc":[{"id":"1.232048439","rc":[{"batb":[[0,3.25,4],[1,3.2,11.64],[2,3.1,17.95]],"ltp":3.25,"tv":3249.12,"id":8858694}]}]}
{"op":"mcm","clk":"11889755200","pt":1724175090305,"mc":[{"id":"1.232048439","rc":[{"batb":[[0,3.2,11.64],[1,3.1,17.95],[2,1.51,25.03]],"batl":[[0,3.3,230.29],[1,3.4,11.3]],"ltp":3.25,"tv":3249.12,"id":8858694}]}]}
{"op":"mcm","clk":"11889755284","pt":1724175090884,"mc":[{"id":"1.232048439","rc":[{"batb":[[0,3.2,7.64]],"batl":[[0,3.25,7.64],[1,3.3,230.29],[2,3.4,4]],"ltp":3.25,"tv":3249.12,"id":8858694}]}]}
{"op":"mcm","clk":"11889755907","pt":1724175095096,"mc":[{"id":"1.232048439","rc":[{"trd":[[3.25,491.3],[3.3,445.31]],"batb":[[0,3.25,4],[1,3.2,7.64],[2,3.1,17.95]],"batl":[[0,3.3,7.64],[1,3.4,4],[2,3.4,0]],"ltp":3.3,"tv":3709.7,"id":8858694}],"tv":3726.56}]}
{"op":"mcm","clk":"11889756089","pt":1724175096386,"mc":[{"id":"1.232048439","rc":[{"batb":[[0,1.43,4],[1,1.42,4],[2,1.41,95.97]],"batl":[[0,1.45,9.13]],"ltp":1.45,"tv":16.85,"id":247649},{"batl":[[1,3.4,0]],"ltp":3.3,"tv":3709.7,"id":8858694}]}]}
{"op":"mcm","clk":"11889756216","pt":1724175097279,"mc":[{"id":"1.232048439","rc":[{"batb":[[0,3.2,7.64],[1,3.1,17.95],[2,1.51,25.03]],"ltp":3.3,"tv":3709.7,"id":8858694}]}]}
{"op":"mcm","clk":"11889756678","pt":1724175100818,"mc":[{"id":"1.232048439","rc":[{"batb":[[0,3.25,4],[1,3.2,7.64],[2,3.1,17.95]],"ltp":3.3,"tv":3709.7,"id":8858694}]}]}
{"op":"mcm","clk":"11889757002","pt":1724175103320,"mc":[{"id":"1.232048439","rc":[{"batb":[[0,3.2,7.64],[1,3.1,17.95],[2,1.51,25.03]],"ltp":3.3,"tv":3709.7,"id":8858694}]}]}
{"op":"mcm","clk":"11889757303","pt":1724175105392,"mc":[{"id":"1.232048439","rc":[{"batb":[[0,1.42,4],[1,1.41,95.97],[2,1.11,18.8]],"ltp":1.45,"tv":16.85,"id":247649}]}]}
{"op":"mcm","clk":"11889758188","pt":1724175111431,"mc":[{"id":"1.232048439","rc":[{"batb":[[0,3.3,4],[1,3.25,4],[2,3.2,11.64]],"batl":[[0,3.4,4]],"ltp":3.3,"tv":3709.7,"id":8858694}]}]}
{"op":"mcm","clk":"11889758527","pt":1724175113715,"mc":[{"id":"1.232048439","rc":[{"batb":[[0,3.25,4],[1,3.2,11.64],[2,3.1,17.95]],"ltp":3.3,"tv":3709.7,"id":8858694}]}]}
{"op":"mcm","clk":"11889759071","pt":1724175117727,"mc":[{"id":"1.232048439","rc":[{"batb":[[0,3.3,4],[1,3.25,4],[2,3.2,11.64]],"ltp":3.3,"tv":3709.7,"id":8858694}]}]}
{"op":"mcm","clk":"11889759496","pt":1724175120533,"mc":[{"id":"1.232048439","rc":[{"batb":[[0,3.25,4],[1,3.2,11.64],[2,3.1,17.95]],"ltp":3.3,"tv":3709.7,"id":8858694}]}]}
{"op":"mcm","clk":"11889759954","pt":1724175123619,"mc":[{"id":"1.232048439","rc":[{"batb":[[0,3.3,4],[1,3.25,4],[2,3.2,11.64]],"ltp":3.3,"tv":3709.7,"id":8858694}]}]}
{"op":"mcm","clk":"11889760327","pt":1724175126321,"mc":[{"id":"1.232048439","rc":[{"batl":[[0,1.44,4],[1,1.45,9.13],[2,1.47,14]],"ltp":1.45,"tv":16.85,"id":247649},{"batb":[[0,3.25,4],[1,3.2,11.64],[2,3.1,17.95]],"ltp":3.3,"tv":3709.7,"id":8858694}]}]}
{"op":"mcm","clk":"11889760777","pt":1724175129559,"mc":[{"id":"1.232048439","rc":[{"batb":[[0,3.3,4],[1,3.25,4],[2,3.2,11.64]],"ltp":3.3,"tv":3709.7,"id":8858694}]}]}
{"op":"mcm","clk":"11889761105","pt":1724175132118,"mc":[{"id":"1.232048439","rc":[{"batb":[[0,1.41,91.97],[1,1.11,18.8],[2,1.04,1634.41]],"ltp":1.45,"tv":16.85,"id":247649},{"batb":[[0,3.3,230.29]],"ltp":3.3,"tv":3709.7,"id":8858694}]}]}
{"op":"mcm","clk":"11889761182","pt":1724175132851,"mc":[{"id":"1.232048439","rc":[{"batl":[[0,1.43,5.21],[1,1.44,4],[2,1.45,4]],"ltp":1.45,"tv":16.85,"id":247649}]}]}
{"op":"mcm","clk":"11889762282","pt":1724175141439,"mc":[{"id":"1.232048439","rc":[{"batb":[[0,1.41,95.97]],"ltp":1.45,"tv":16.85,"id":247649},{"batb":[[0,3.3,234.29]],"batl":[[0,3.45,4]],"ltp":3.3,"tv":3709.7,"id":8858694}]}]}
{"op":"mcm","clk":"11889762362","pt":1724175142117,"mc":[{"id":"1.232048439","rc":[{"batb":[[0,1.41,91.97]],"batl":[[0,1.43,9.21]],"ltp":1.45,"tv":16.85,"id":247649},{"batb":[[0,3.35,8],[1,3.3,234.29],[2,3.25,4]],"ltp":3.3,"tv":3709.7,"id":8858694}]}]}
{"op":"mcm","clk":"11889762604","pt":1724175144259,"mc":[{"id":"1.232048439","rc":[{"batb":[[0,3.35,4]],"ltp":3.3,"tv":3709.7,"id":8858694}]}]}
{"op":"mcm","clk":"11889764139","pt":1724175156334,"mc":[{"id":"1.232048439","rc":[{"batl":[[0,1.43,5.21],[1,1.47,14],[2,1.5,5.1]],"ltp":1.45,"tv":16.85,"id":247649},{"batb":[[0,3.2,7.64],[1,3.1,17.95],[2,1.51,25.03]],"ltp":3.3,"tv":3709.7,"id":8858694}]}]}
{"op":"mcm","clk":"11889764241","pt":1724175157064,"mc":[{"id":"1.232048439","rc":[{"batb":[[0,1.42,4],[1,1.41,95.97],[2,1.11,18.8]],"batl":[[0,1.47,14],[1,1.5,5.1],[2,3.5,1.82]],"ltp":1.45,"tv":16.85,"id":247649},{"batb":[[0,3.25,14],[1,3.2,7.64],[2,3.1,17.95]],"batl":[[0,3.45,4]],"ltp":3.3,"tv":3709.7,"id":8858694}]}]}
{"op":"mcm","clk":"11889764532","pt":1724175159157,"mc":[{"id":"1.232048439","rc":[{"batl":[[0,1.44,5.17],[1,1.47,14],[2,1.5,5.1]],"ltp":1.45,"tv":16.85,"id":247649},{"batb":[[0,3.25,10]],"ltp":3.3,"tv":3709.7,"id":8858694}]}]}
{"op":"mcm","clk":"11889764661","pt":1724175160043,"mc":[{"id":"1.232048439","rc":[{"batb":[[0,3.2,7.64],[1,3.1,17.95],[2,1.51,25.03]],"ltp":3.3,"tv":3709.7,"id":8858694}]}]}
{"op":"mcm","clk":"11889764773","pt":1724175160975,"mc":[{"id":"1.232048439","rc":[{"batl":[[0,1.47,14],[1,1.5,5.1],[2,3.5,1.82]],"ltp":1.45,"tv":16.85,"id":247649}]}]}
{"op":"mcm","clk":"11889764975","pt":1724175162549,"mc":[{"id":"1.232048439","rc":[{"batb":[[0,3.25,14],[1,3.2,7.64],[2,3.1,17.95]],"ltp":3.3,"tv":3709.7,"id":8858694}]}]}
{"op":"mcm","clk":"11889765298","pt":1724175164852,"mc":[{"id":"1.232048439","rc":[{"batb":[[0,3.25,10]],"ltp":3.3,"tv":3709.7,"id":8858694}]}]}
{"op":"mcm","clk":"11889765443","pt":1724175165994,"mc":[{"id":"1.232048439","rc":[{"batb":[[0,3.2,7.64],[1,3.1,17.95],[2,1.51,25.03]],"ltp":3.3,"tv":3709.7,"id":8858694}]}]}
{"op":"mcm","clk":"11889765620","pt":1724175167252,"mc":[{"id":"1.232048439","rc":[{"batl":[[0,1.46,5.09],[1,1.47,14],[2,1.5,5.1]],"ltp":1.45,"tv":16.85,"id":247649}]}]}
{"op":"mcm","clk":"11889765660","pt":1724175167663,"mc":[{"id":"1.232048439","rc":[{"batb":[[0,3.25,4],[1,3.2,7.64],[2,3.1,17.95]],"ltp":3.3,"tv":3709.7,"id":8858694}]}]}
{"op":"mcm","clk":"11889766012","pt":1724175170283,"mc":[{"id":"1.232048439","rc":[{"batb":[[0,3.2,7.64],[1,3.1,17.95],[2,1.51,25.03]],"ltp":3.3,"tv":3709.7,"id":8858694}]}]}
{"op":"mcm","clk":"11889766124","pt":1724175170865,"mc":[{"id":"1.232048439","rc":[{"batb":[[0,3.25,10],[1,3.2,7.64],[2,3.1,17.95]],"ltp":3.3,"tv":3709.7,"id":8858694}]}]}
{"op":"mcm","clk":"11889766290","pt":1724175172066,"mc":[{"id":"1.232048439","rc":[{"batl":[[0,1.45,4],[1,1.46,5.09],[2,1.47,14]],"ltp":1.45,"tv":16.85,"id":247649},{"batb":[[0,3.3,4],[1,3.25,14],[2,3.2,7.64]],"batl":[[0,3.4,4],[1,3.45,4]],"ltp":3.3,"tv":3709.7,"id":8858694}]}]}
{"op":"mcm","clk":"11889766474","pt":1724175173267,"mc":[{"id":"1.232048439","rc":[{"batl":[[1,1.47,14],[2,1.5,5.1]],"ltp":1.45,"tv":16.85,"id":247649},{"batb":[[0,3.35,4],[1,3.3,4],[2,3.25,14]],"ltp":3.3,"tv":3709.7,"id":8858694}]}]}
{"op":"mcm","clk":"11889766606","pt":1724175174261,"mc":[{"id":"1.232048439","rc":[{"batb":[[2,3.25,4]],"ltp":3.3,"tv":3709.7,"id":8858694}]}]}
{"op":"mcm","clk":"11889766669","pt":1724175174782,"mc":[{"id":"1.232048439","rc":[{"batb":[[1,3.2,7.64],[2,3.1,17.95]],"ltp":3.3,"tv":3709.7,"id":8858694}]}]}
{"op":"mcm","clk":"11889766787","pt":1724175175671,"mc":[{"id":"1.232048439","rc":[{"batl":[[0,1.45,9.13]],"ltp":1.45,"tv":16.85,"id":247649},{"batb":[[0,3.2,7.64],[1,3.1,17.95],[2,1.51,25.03]],"ltp":3.3,"tv":3709.7,"id":8858694}]}]}
{"op":"mcm","clk":"11889767186","pt":1724175178274,"mc":[{"id":"1.232048439","rc":[{"batb":[[0,3.25,4],[1,3.2,7.64],[2,3.1,17.95]],"ltp":3.3,"tv":3709.7,"id":8858694}]}]}
{"op":"mcm","clk":"11889767491","pt":1724175180588,"mc":[{"id":"1.232048439","rc":[{"batb":[[0,3.2,7.64],[1,3.1,17.95],[2,1.51,25.03]],"ltp":3.3,"tv":3709.7,"id":8858694}]}]}
{"op":"mcm","clk":"11889767934","pt":1724175183276,"mc":[{"id":"1.232048439","rc":[{"batl":[[0,3.35,230.29],[1,3.4,4],[2,3.45,4]],"ltp":3.3,"tv":3709.7,"id":8858694}]}]}
{"op":"mcm","clk":"11889768043","pt":1724175183964,"mc":[{"id":"1.232048439","rc":[{"batl":[[0,1.45,5.13]],"ltp":1.45,"tv":16.85,"id":247649},{"batb":[[0,3.25,4],[1,3.2,7.64],[2,3.1,17.95]],"ltp":3.3,"tv":3709.7,"id":8858694}]}]}
{"op":"mcm","clk":"11889768297","pt":1724175185898,"mc":[{"id":"1.232048439","rc":[{"trd":[[3.35,460.58]],"batb":[[0,3.2,7.64],[1,3.1,17.95],[2,1.51,25.03]],"batl":[[0,3.4,4],[1,3.45,4],[2,3.45,0]],"ltp":3.35,"tv":4170.28,"id":8858694}],"tv":4187.14}]}
{"op":"mcm","clk":"11889768478","pt":1724175187211,"mc":[{"id":"1.232048439","rc":[{"batl":[[0,1.45,9.13]],"ltp":1.45,"tv":16.85,"id":247649},{"batb":[[0,3.25,4],[1,3.2,11.64],[2,3.1,17.95]],"ltp":3.35,"tv":4170.28,"id":8858694}]}]}
{"op":"mcm","clk":"11889768601","pt":1724175188058,"mc":[{"id":"1.232048439","rc":[{"batb":[[0,3.3,4],[1,3.25,4],[2,3.2,11.64]],"ltp":3.35,"tv":4170.28,"id":8858694}]}]}
{"op":"mcm","clk":"11889768967","pt":1724175190690,"mc":[{"id":"1.232048439","rc":[{"batb":[[0,3.25,4],[1,3.2,11.64],[2,3.1,17.95]],"ltp":3.35,"tv":4170.28,"id":8858694}]}]}
{"op":"mcm","clk":"11889769294","pt":1724175193099,"mc":[{"id":"1.232048439","rc":[{"batb":[[0,3.3,4],[1,3.25,4],[2,3.2,11.64]],"ltp":3.35,"tv":4170.28,"id":8858694}]}]}
{"op":"mcm","clk":"11889769693","pt":1724175195998,"mc":[{"id":"1.232048439","rc":[{"batb":[[0,3.25,4],[1,3.2,11.64],[2,3.1,17.95]],"ltp":3.35,"tv":4170.28,"id":8858694}]}]}
{"op":"mcm","clk":"11889770155","pt":1724175199414,"mc":[{"id":"1.232048439","rc":[{"batb":[[0,3.3,4],[1,3.25,4],[2,3.2,11.64]],"ltp":3.35,"tv":4170.28,"id":8858694}]}]}
{"op":"mcm","clk":"11889770278","pt":1724175200197,"mc":[{"id":"1.232048439","rc":[{"batl":[[0,1.45,5.13]],"ltp":1.45,"tv":16.85,"id":247649},{"batb":[[1,3.2,7.64],[2,3.1,17.95]],"batl":[[0,3.35,230.29],[1,3.4,4],[2,3.45,4]],"ltp":3.35,"tv":4170.28,"id":8858694}]}]}
{"op":"mcm","clk":"11889770583","pt":1724175202410,"mc":[{"id":"1.232048439","rc":[{"batb":[[0,3.2,7.64],[1,3.1,17.95],[2,1.51,25.03]],"batl":[[0,3.35,234.29]],"ltp":3.35,"tv":4170.28,"id":8858694}]}]}
{"op":"mcm","clk":"11889770831","pt":1724175204387,"mc":[{"id":"1.232048439","rc":[{"batb":[[0,3.25,4],[1,3.2,7.64],[2,3.1,17.95]],"ltp":3.35,"tv":4170.28,"id":8858694}]}]}
{"op":"mcm","clk":"11889771172","pt":1724175206888,"mc":[{"id":"1.232048439","rc":[{"batb":[[0,3.2,7.64],[1,3.1,17.95],[2,1.51,25.03]],"ltp":3.35,"tv":4170.28,"id":8858694}]}]}
{"op":"mcm","clk":"11889771643","pt":1724175210207,"mc":[{"id":"1.232048439","rc":[{"trd":[[3.35,921.16]],"batb":[[0,3.25,4],[1,3.2,7.64],[2,3.1,17.95]],"batl":[[0,3.4,4],[1,3.45,4],[2,3.45,0]],"ltp":3.35,"tv":4630.87,"id":8858694}],"tv":4647.72}]}
{"op":"mcm","clk":"11889772006","pt":1724175212516,"mc":[{"id":"1.232048439","rc":[{"batb":[[0,3.2,7.64],[1,3.1,17.95],[2,1.51,25.03]],"ltp":3.35,"tv":4630.87,"id":8858694}]}]}
{"op":"mcm","clk":"11889772401","pt":1724175215703,"mc":[{"id":"1.232048439","rc":[{"batb":[[0,3.25,4],[1,3.2,7.64],[2,3.1,17.95]],"ltp":3.35,"tv":4630.87,"id":8858694}]}]}
{"op":"mcm","clk":"11889772693","pt":1724175218038,"mc":[{"id":"1.232048439","rc":[{"batl":[[0,1.45,9.13]],"ltp":1.45,"tv":16.85,"id":247649}]}]}
{"op":"mcm","clk":"11889773097","pt":1724175221107,"mc":[{"id":"1.232048439","rc":[{"batb":[[0,3.3,4],[1,3.25,4],[2,3.2,7.64]],"ltp":3.35,"tv":4630.87,"id":8858694}]}]}
{"op":"mcm","clk":"11889773375","pt":1724175223435,"mc":[{"id":"1.232048439","rc":[{"batb":[[0,3.25,4],[1,3.2,7.64],[2,3.1,17.95]],"ltp":3.35,"tv":4630.87,"id":8858694}]}]}
{"op":"mcm","clk":"11889773760","pt":1724175226137,"mc":[{"id":"1.232048439","rc":[{"batb":[[0,3.3,4],[1,3.25,4],[2,3.2,7.64]],"ltp":3.35,"tv":4630.87,"id":8858694}]}]}
{"op":"mcm","clk":"11889774058","pt":1724175228417,"mc":[{"id":"1.232048439","rc":[{"batb":[[0,3.25,4],[1,3.2,7.64],[2,3.1,17.95]],"ltp":3.35,"tv":4630.87,"id":8858694}]}]}
{"op":"mcm","clk":"11889774468","pt":1724175231437,"mc":[{"id":"1.232048439","rc":[{"batb":[[0,3.3,4],[1,3.25,4],[2,3.2,7.64]],"ltp":3.35,"tv":4630.87,"id":8858694}]}]}
{"op":"mcm","clk":"11889774583","pt":1724175232319,"mc":[{"id":"1.232048439","rc":[{"batl":[[0,1.45,5.13]],"ltp":1.45,"tv":16.85,"id":247649},{"batb":[[1,3.2,7.64],[2,3.1,17.95]],"batl":[[0,3.35,230.29],[1,3.4,4],[2,3.45,4]],"ltp":3.35,"tv":4630.87,"id":8858694}]}]}
{"op":"mcm","clk":"11889774626","pt":1724175232633,"mc":[{"id":"1.232048439","rc":[{"batl":[[0,3.35,234.29]],"ltp":3.35,"tv":4630.87,"id":8858694}]}]}
{"op":"mcm","clk":"11889774851","pt":1724175234345,"mc":[{"id":"1.232048439","rc":[{"trd":[[3.35,1381.75]],"batb":[[0,3.2,7.64],[1,3.1,17.95],[2,1.51,25.03]],"batl":[[0,3.4,4],[1,3.45,4],[2,3.45,0]],"ltp":3.35,"tv":5091.45,"id":8858694}],"tv":5108.31}]}
{"op":"mcm","clk":"11889775333","pt":1724175237928,"mc":[{"id":"1.232048439","rc":[{"batb":[[0,3.25,4],[1,3.2,7.64],[2,3.1,17.95]],"ltp":3.35,"tv":5091.45,"id":8858694}]}]}
{"op":"mcm","clk":"11889775672","pt":1724175240169,"mc":[{"id":"1.232048439","rc":[{"batb":[[0,3.2,7.64],[1,3.1,17.95],[2,1.51,25.03]],"ltp":3.35,"tv":5091.45,"id":8858694}]}]}
{"op":"mcm","clk":"11889776057","pt":1724175242948,"mc":[{"id":"1.232048439","rc":[{"batb":[[0,3.25,4],[1,3.2,7.64],[2,3.1,17.95]],"ltp":3.35,"tv":5091.45,"id":8858694}]}]}
{"op":"mcm","clk":"11889776390","pt":1724175245348,"mc":[{"id":"1.232048439","rc":[{"batb":[[0,3.2,7.64],[1,3.1,17.95],[2,1.51,25.03]],"ltp":3.35,"tv":5091.45,"id":8858694}]}]}
{"op":"mcm","clk":"11889776840","pt":1724175248036,"mc":[{"id":"1.232048439","rc":[{"batl":[[0,1.45,9.13]],"ltp":1.45,"tv":16.85,"id":247649},{"batb":[[0,3.25,8],[1,3.2,11.64],[2,3.1,17.95]],"ltp":3.35,"tv":5091.45,"id":8858694}]}]}
{"op":"mcm","clk":"11889777164","pt":1724175250391,"mc":[{"id":"1.232048439","rc":[{"batb":[[0,3.25,4]],"ltp":3.35,"tv":5091.45,"id":8858694}]}]}
{"op":"mcm","clk":"11889777578","pt":1724175253252,"mc":[{"id":"1.232048439","rc":[{"batb":[[0,3.3,4],[1,3.25,4],[2,3.2,11.64]],"ltp":3.35,"tv":5091.45,"id":8858694}]}]}
{"op":"mcm","clk":"11889777888","pt":1724175255437,"mc":[{"id":"1.232048439","rc":[{"batb":[[0,3.25,4],[1,3.2,11.64],[2,3.1,17.95]],"ltp":3.35,"tv":5091.45,"id":8858694}]}]}
{"op":"mcm","clk":"11889778536","pt":1724175260062,"mc":[{"id":"1.232048439","rc":[{"batb":[[0,3.3,4],[1,3.25,4],[2,3.2,11.64]],"ltp":3.35,"tv":5091.45,"id":8858694}]}]}
{"op":"mcm","clk":"11889778919","pt":1724175262989,"mc":[{"id":"1.232048439","rc":[{"batl":[[0,1.44,4],[1,1.45,9.13],[2,1.47,14]],"ltp":1.45,"tv":16.85,"id":247649},{"batb":[[0,3.25,4],[1,3.2,11.64],[2,3.1,17.95]],"ltp":3.35,"tv":5091.45,"id":8858694}]}]}
{"op":"mcm","clk":"11889779236","pt":1724175265284,"mc":[{"id":"1.232048439","rc":[{"batb":[[0,3.3,4],[1,3.25,4],[2,3.2,11.64]],"ltp":3.35,"tv":5091.45,"id":8858694}]}]}
{"op":"mcm","clk":"11889779598","pt":1724175267886,"mc":[{"id":"1.232048439","rc":[{"batb":[[0,3.25,4],[1,3.2,11.64],[2,3.1,17.95]],"ltp":3.35,"tv":5091.45,"id":8858694}]}]}
{"op":"mcm","clk":"11889780125","pt":1724175271659,"mc":[{"id":"1.232048439","rc":[{"batb":[[0,3.3,4],[1,3.25,4],[2,3.2,11.64]],"ltp":3.35,"tv":5091.45,"id":8858694}]}]}
{"op":"mcm","clk":"11889780433","pt":1724175273996,"mc":[{"id":"1.232048439","rc":[{"batb":[[0,3.25,4],[1,3.2,11.64],[2,3.1,17.95]],"ltp":3.35,"tv":5091.45,"id":8858694}]}]}
{"op":"mcm","clk":"11889780820","pt":1724175276970,"mc":[{"id":"1.232048439","rc":[{"batb":[[0,3.3,4],[1,3.25,4],[2,3.2,11.64]],"ltp":3.35,"tv":5091.45,"id":8858694}]}]}
{"op":"mcm","clk":"11889781184","pt":1724175279473,"mc":[{"id":"1.232048439","rc":[{"batb":[[0,3.25,4],[1,3.2,11.64],[2,3.1,17.95]],"ltp":3.35,"tv":5091.45,"id":8858694}]}]}
{"op":"mcm","clk":"11889781522","pt":1724175282070,"mc":[{"id":"1.232048439","rc":[{"batb":[[0,3.3,4],[1,3.25,4],[2,3.2,11.64]],"ltp":3.35,"tv":5091.45,"id":8858694}]}]}
{"op":"mcm","clk":"11889781843","pt":1724175284696,"mc":[{"id":"1.232048439","rc":[{"batb":[[0,3.25,4],[1,3.2,11.64],[2,3.1,17.95]],"ltp":3.35,"tv":5091.45,"id":8858694}]}]}
{"op":"mcm","clk":"11889782186","pt":1724175287166,"mc":[{"id":"1.232048439","rc":[{"batb":[[0,3.3,4],[1,3.25,4],[2,3.2,11.64]],"ltp":3.35,"tv":5091.45,"id":8858694}]}]}
{"op":"mcm","clk":"11889782496","pt":1724175289905,"mc":[{"id":"1.232048439","rc":[{"batb":[[0,3.25,4],[1,3.2,11.64],[2,3.1,17.95]],"ltp":3.35,"tv":5091.45,"id":8858694}]}]}
{"op":"mcm","clk":"11889782798","pt":1724175292405,"mc":[{"id":"1.232048439","rc":[{"batb":[[0,3.3,4],[1,3.25,4],[2,3.2,11.64]],"ltp":3.35,"tv":5091.45,"id":8858694}]}]}
{"op":"mcm","clk":"11889783124","pt":1724175295012,"mc":[{"id":"1.232048439","rc":[{"batb":[[0,3.25,4],[1,3.2,11.64],[2,3.1,17.95]],"ltp":3.35,"tv":5091.45,"id":8858694}]}]}
{"op":"mcm","clk":"11889783483","pt":1724175297678,"mc":[{"id":"1.232048439","rc":[{"batb":[[0,3.3,4],[1,3.25,4],[2,3.2,11.64]],"ltp":3.35,"tv":5091.45,"id":8858694}]}]}
{"op":"mcm","clk":"11889783827","pt":1724175300015,"mc":[{"id":"1.232048439","rc":[{"batb":[[0,3.25,4],[1,3.2,11.64],[2,3.1,17.95]],"ltp":3.35,"tv":5091.45,"id":8858694}]}]}
{"op":"mcm","clk":"11889784217","pt":1724175302705,"mc":[{"id":"1.232048439","rc":[{"batb":[[0,3.3,4],[1,3.25,4],[2,3.2,11.64]],"ltp":3.35,"tv":5091.45,"id":8858694}]}]}
{"op":"mcm","clk":"11889784597","pt":1724175305603,"mc":[{"id":"1.232048439","rc":[{"batb":[[0,3.25,4],[1,3.2,11.64],[2,3.1,17.95]],"ltp":3.35,"tv":5091.45,"id":8858694}]}]}
{"op":"mcm","clk":"11889784920","pt":1724175307918,"mc":[{"id":"1.232048439","rc":[{"batb":[[0,3.3,4],[1,3.25,4],[2,3.2,11.64]],"ltp":3.35,"tv":5091.45,"id":8858694}]}]}
{"op":"mcm","clk":"11889785257","pt":1724175310428,"mc":[{"id":"1.232048439","rc":[{"batb":[[0,3.25,4],[1,3.2,11.64],[2,3.1,17.95]],"ltp":3.35,"tv":5091.45,"id":8858694}]}]}
{"op":"mcm","clk":"11889785675","pt":1724175313321,"mc":[{"id":"1.232048439","rc":[{"batb":[[0,3.3,4],[1,3.25,4],[2,3.2,11.64]],"ltp":3.35,"tv":5091.45,"id":8858694}]}]}
{"op":"mcm","clk":"11889786057","pt":1724175316130,"mc":[{"id":"1.232048439","rc":[{"batb":[[0,3.25,4],[1,3.2,11.64],[2,3.1,17.95]],"ltp":3.35,"tv":5091.45,"id":8858694}]}]}
{"op":"mcm","clk":"11889786404","pt":1724175318643,"mc":[{"id":"1.232048439","rc":[{"batb":[[0,3.3,4],[1,3.25,4],[2,3.2,11.64]],"ltp":3.35,"tv":5091.45,"id":8858694}]}]}
{"op":"mcm","clk":"11889786758","pt":1724175321214,"mc":[{"id":"1.232048439","rc":[{"batb":[[0,3.25,4],[1,3.2,11.64],[2,3.1,17.95]],"ltp":3.35,"tv":5091.45,"id":8858694}]}]}
{"op":"mcm","clk":"11889787203","pt":1724175324140,"mc":[{"id":"1.232048439","rc":[{"batb":[[0,3.3,4],[1,3.25,4],[2,3.2,11.64]],"ltp":3.35,"tv":5091.45,"id":8858694}]}]}
{"op":"mcm","clk":"11889787565","pt":1724175326842,"mc":[{"id":"1.232048439","rc":[{"batb":[[0,3.25,4],[1,3.2,11.64],[2,3.1,17.95]],"ltp":3.35,"tv":5091.45,"id":8858694}]}]}
{"op":"mcm","clk":"11889788045","pt":1724175330721,"mc":[{"id":"1.232048439","rc":[{"batb":[[0,3.3,4],[1,3.25,4],[2,3.2,11.64]],"ltp":3.35,"tv":5091.45,"id":8858694}]}]}
{"op":"mcm","clk":"11889788452","pt":1724175333742,"mc":[{"id":"1.232048439","rc":[{"batb":[[0,3.25,4],[1,3.2,11.64],[2,3.1,17.95]],"ltp":3.35,"tv":5091.45,"id":8858694}]}]}
{"op":"mcm","clk":"11889788873","pt":1724175336930,"mc":[{"id":"1.232048439","rc":[{"batb":[[0,3.3,4],[1,3.25,4],[2,3.2,11.64]],"ltp":3.35,"tv":5091.45,"id":8858694}]}]}
{"op":"mcm","clk":"11889789240","pt":1724175339557,"mc":[{"id":"1.232048439","rc":[{"batb":[[0,3.25,4],[1,3.2,11.64],[2,3.1,17.95]],"ltp":3.35,"tv":5091.45,"id":8858694}]}]}
{"op":"mcm","clk":"11889789560","pt":1724175341747,"mc":[{"id":"1.232048439","rc":[{"batl":[[0,1.45,5.13],[1,1.47,14],[2,1.5,5.1]],"ltp":1.45,"tv":16.85,"id":247649},{"batb":[[0,3.3,4],[1,3.2,7.64]],"batl":[[0,3.35,230.29],[1,3.4,4],[2,3.45,4]],"ltp":3.35,"tv":5091.45,"id":8858694}]}]}
{"op":"mcm","clk":"11889789871","pt":1724175344049,"mc":[{"id":"1.232048439","rc":[{"batb":[[0,3.2,7.64],[1,3.1,17.95],[2,1.51,25.03]],"ltp":3.35,"tv":5091.45,"id":8858694}]}]}
{"op":"mcm","clk":"11889790202","pt":1724175346252,"mc":[{"id":"1.232048439","rc":[{"trd":[[3.35,1842.33]],"batb":[[0,3.25,4],[1,3.2,7.64],[2,3.1,17.95]],"batl":[[0,3.4,4],[1,3.45,4],[2,3.45,0]],"ltp":3.35,"tv":5552.03,"id":8858694}],"tv":5568.89}]}
{"op":"mcm","clk":"11889790515","pt":1724175348855,"mc":[{"id":"1.232048439","rc":[{"batb":[[0,3.2,7.64],[1,3.1,17.95],[2,1.51,25.03]],"ltp":3.35,"tv":5552.03,"id":8858694}]}]}
{"op":"mcm","clk":"11889790968","pt":1724175352250,"mc":[{"id":"1.232048439","rc":[{"batb":[[0,3.25,4],[1,3.2,7.64],[2,3.1,17.95]],"ltp":3.35,"tv":5552.03,"id":8858694}]}]}
{"op":"mcm","clk":"11889791387","pt":1724175355359,"mc":[{"id":"1.232048439","rc":[{"batl":[[0,1.45,9.13]],"ltp":1.45,"tv":16.85,"id":247649}]}]}
{"op":"mcm","clk":"11889791867","pt":1724175358772,"mc":[{"id":"1.232048439","rc":[{"batb":[[0,3.3,4],[1,3.25,4],[2,3.2,7.64]],"ltp":3.35,"tv":5552.03,"id":8858694}]}]}
{"op":"mcm","clk":"11889792187","pt":1724175361081,"mc":[{"id":"1.232048439","rc":[{"batb":[[0,3.25,4],[1,3.2,7.64],[2,3.1,17.95]],"ltp":3.35,"tv":5552.03,"id":8858694}]}]}
{"op":"mcm","clk":"11889792801","pt":1724175364976,"mc":[{"id":"1.232048439","rc":[{"batb":[[0,3.3,4],[1,3.25,4],[2,3.2,7.64]],"ltp":3.35,"tv":5552.03,"id":8858694}]}]}
{"op":"mcm","clk":"11889793119","pt":1724175367263,"mc":[{"id":"1.232048439","rc":[{"batb":[[0,3.25,4],[1,3.2,7.64],[2,3.1,17.95]],"ltp":3.35,"tv":5552.03,"id":8858694}]}]}
{"op":"mcm","clk":"11889793437","pt":1724175369789,"mc":[{"id":"1.232048439","rc":[{"batb":[[0,3.3,4],[1,3.25,4],[2,3.2,7.64]],"ltp":3.35,"tv":5552.03,"id":8858694}]}]}
{"op":"mcm","clk":"11889793532","pt":1724175370500,"mc":[{"id":"1.232048439","rc":[{"batl":[[0,1.44,4],[1,1.45,9.13],[2,1.47,14]],"ltp":1.45,"tv":16.85,"id":247649}]}]}
{"op":"mcm","clk":"11889793745","pt":1724175372196,"mc":[{"id":"1.232048439","rc":[{"batb":[[0,3.25,4],[1,3.2,7.64],[2,3.1,17.95]],"ltp":3.35,"tv":5552.03,"id":8858694}]}]}
{"op":"mcm","clk":"11889794060","pt":1724175374499,"mc":[{"id":"1.232048439","rc":[{"batb":[[0,3.3,4],[1,3.25,4],[2,3.2,7.64]],"ltp":3.35,"tv":5552.03,"id":8858694}]}]}
{"op":"mcm","clk":"11889794394","pt":1724175376990,"mc":[{"id":"1.232048439","rc":[{"batb":[[0,3.25,4],[1,3.2,7.64],[2,3.1,17.95]],"ltp":3.35,"tv":5552.03,"id":8858694}]}]}
{"op":"mcm","clk":"11889795056","pt":1724175381982,"mc":[{"id":"1.232048439","rc":[{"batb":[[0,3.3,4],[1,3.25,4],[2,3.2,7.64]],"ltp":3.35,"tv":5552.03,"id":8858694}]}]}
{"op":"mcm","clk":"11889795387","pt":1724175384705,"mc":[{"id":"1.232048439","rc":[{"batb":[[0,3.25,4],[1,3.2,7.64],[2,3.1,17.95]],"ltp":3.35,"tv":5552.03,"id":8858694}]}]}
{"op":"mcm","clk":"11889795685","pt":1724175387218,"mc":[{"id":"1.232048439","rc":[{"batb":[[0,3.3,4],[1,3.25,4],[2,3.2,7.64]],"ltp":3.35,"tv":5552.03,"id":8858694}]}]}
{"op":"mcm","clk":"11889796047","pt":1724175390012,"mc":[{"id":"1.232048439","rc":[{"batb":[[0,3.25,4],[1,3.2,7.64],[2,3.1,17.95]],"ltp":3.35,"tv":5552.03,"id":8858694}]}]}
{"op":"mcm","clk":"11889796453","pt":1724175393208,"mc":[{"id":"1.232048439","rc":[{"batb":[[0,3.3,4],[1,3.25,4],[2,3.2,7.64]],"ltp":3.35,"tv":5552.03,"id":8858694}]}]}
{"op":"mcm","clk":"11889796756","pt":1724175395597,"mc":[{"id":"1.232048439","rc":[{"batb":[[0,3.25,4],[1,3.2,7.64],[2,3.1,17.95]],"ltp":3.35,"tv":5552.03,"id":8858694}]}]}
{"op":"mcm","clk":"11889797060","pt":1724175398309,"mc":[{"id":"1.232048439","rc":[{"batb":[[0,3.3,4],[1,3.25,4],[2,3.2,7.64]],"ltp":3.35,"tv":5552.03,"id":8858694}]}]}
{"op":"mcm","clk":"11889797345","pt":1724175400701,"mc":[{"id":"1.232048439","rc":[{"batb":[[0,3.25,4],[1,3.2,7.64],[2,3.1,17.95]],"ltp":3.35,"tv":5552.03,"id":8858694}]}]}
{"op":"mcm","clk":"11889797636","pt":1724175403037,"mc":[{"id":"1.232048439","rc":[{"batb":[[0,3.3,4],[1,3.25,4],[2,3.2,7.64]],"ltp":3.35,"tv":5552.03,"id":8858694}]}]}
{"op":"mcm","clk":"11889797990","pt":1724175405688,"mc":[{"id":"1.232048439","rc":[{"batb":[[0,3.25,4],[1,3.2,7.64],[2,3.1,17.95]],"ltp":3.35,"tv":5552.03,"id":8858694}]}]}
{"op":"mcm","clk":"11889798434","pt":1724175409170,"mc":[{"id":"1.232048439","rc":[{"batb":[[0,3.3,4],[1,3.25,4],[2,3.2,7.64]],"ltp":3.35,"tv":5552.03,"id":8858694}]}]}
{"op":"mcm","clk":"11889798730","pt":1724175411574,"mc":[{"id":"1.232048439","rc":[{"batb":[[0,3.25,4],[1,3.2,7.64],[2,3.1,17.95]],"ltp":3.35,"tv":5552.03,"id":8858694}]}]}
{"op":"mcm","clk":"11889799074","pt":1724175414763,"mc":[{"id":"1.232048439","rc":[{"batb":[[0,3.3,4],[1,3.25,4],[2,3.2,7.64]],"ltp":3.35,"tv":5552.03,"id":8858694}]}]}
{"op":"mcm","clk":"11889799342","pt":1724175417167,"mc":[{"id":"1.232048439","rc":[{"batb":[[0,3.25,4],[1,3.2,7.64],[2,3.1,17.95]],"ltp":3.35,"tv":5552.03,"id":8858694}]}]}
{"op":"mcm","clk":"11889799718","pt":1724175420267,"mc":[{"id":"1.232048439","rc":[{"batb":[[0,3.3,4],[1,3.25,4],[2,3.2,7.64]],"ltp":3.35,"tv":5552.03,"id":8858694}]}]}
{"op":"mcm","clk":"11889800040","pt":1724175422842,"mc":[{"id":"1.232048439","rc":[{"batb":[[0,3.25,4],[1,3.2,7.64],[2,3.1,17.95]],"ltp":3.35,"tv":5552.03,"id":8858694}]}]}
{"op":"mcm","clk":"11889800176","pt":1724175424036,"mc":[{"id":"1.232048439","rc":[{"batl":[[0,3.35,230.29],[1,3.4,4],[2,3.45,4]],"ltp":3.35,"tv":5552.03,"id":8858694}]}]}
{"op":"mcm","clk":"11889800254","pt":1724175424758,"mc":[{"id":"1.232048439","rc":[{"batl":[[0,1.45,5.13],[1,1.47,14],[2,1.5,5.1]],"ltp":1.45,"tv":16.85,"id":247649},{"batb":[[0,3.2,7.64],[1,3.1,17.95],[2,1.51,25.03]],"batl":[[0,3.3,11.31],[1,3.35,230.29],[2,3.4,4]],"ltp":3.35,"tv":5552.03,"id":8858694}]}]}
{"op":"mcm","clk":"11889800482","pt":1724175426427,"mc":[{"id":"1.232048439","rc":[{"batb":[[0,3.25,4],[1,3.2,7.64],[2,3.1,17.95]],"ltp":3.35,"tv":5552.03,"id":8858694}]}]}
{"op":"mcm","clk":"11889800750","pt":1724175429179,"mc":[{"id":"1.232048439","rc":[{"batb":[[0,3.2,7.64],[1,3.1,17.95],[2,1.51,25.03]],"ltp":3.35,"tv":5552.03,"id":8858694}]}]}
{"op":"mcm","clk":"11889800951","pt":1724175430838,"mc":[{"id":"1.232048439","rc":[{"batb":[[0,1.44,4],[1,1.43,4],[2,1.42,4]],"ltp":1.45,"tv":16.85,"id":247649},{"batl":[[0,3.3,15.31]],"ltp":3.35,"tv":5552.03,"id":8858694}]}]}
{"op":"mcm","clk":"11889801131","pt":1724175432242,"mc":[{"id":"1.232048439","rc":[{"batb":[[0,3.25,4],[1,3.2,7.64],[2,3.1,17.95]],"batl":[[1,3.4,4],[2,3.45,4]],"ltp":3.35,"tv":5552.03,"id":8858694}]}]}
{"op":"mcm","clk":"11889801229","pt":1724175433176,"mc":[{"id":"1.232048439","rc":[{"batl":[[0,3.3,4]],"ltp":3.35,"tv":5552.03,"id":8858694}]}]}
{"op":"mcm","clk":"11889801363","pt":1724175434164,"mc":[{"id":"1.232048439","rc":[{"batb":[[0,1.41,91.97],[1,1.11,18.8],[2,1.04,1634.41]],"ltp":1.45,"tv":16.85,"id":247649}]}]}
{"op":"mcm","clk":"11889801430","pt":1724175434699,"mc":[{"id":"1.232048439","rc":[{"batb":[[0,3.2,7.64],[1,3.1,17.95],[2,1.51,25.03]],"ltp":3.35,"tv":5552.03,"id":8858694}]}]}
{"op":"mcm","clk":"11889802506","pt":1724175443363,"mc":[{"id":"1.232048439","rc":[{"batb":[[0,3.25,4],[1,3.2,7.64],[2,3.1,17.95]],"batl":[[0,3.3,230.29]],"ltp":3.35,"tv":5552.03,"id":8858694}]}]}
{"op":"mcm","clk":"11889802724","pt":1724175445073,"mc":[{"id":"1.232048439","rc":[{"trd":[[3.3,905.89]],"ltp":3.3,"tv":6012.61,"id":8858694}],"tv":6029.47}]}
{"op":"mcm","clk":"11889802860","pt":1724175446056,"mc":[{"id":"1.232048439","rc":[{"batb":[[0,1.42,4],[1,1.41,95.97],[2,1.11,18.8]],"ltp":1.45,"tv":16.85,"id":247649},{"batl":[[0,3.45,4]],"ltp":3.3,"tv":6012.61,"id":8858694}]}]}
{"op":"mcm","clk":"11889803642","pt":1724175451767,"mc":[{"id":"1.232048439","rc":[{"batb":[[0,3.3,4],[1,3.25,4],[2,3.2,7.64]],"ltp":3.3,"tv":6012.61,"id":8858694}]}]}
{"op":"mcm","clk":"11889803993","pt":1724175454375,"mc":[{"id":"1.232048439","rc":[{"batb":[[0,3.25,4],[1,3.2,7.64],[2,3.1,17.95]],"ltp":3.3,"tv":6012.61,"id":8858694}]}]}
{"op":"mcm","clk":"11889804507","pt":1724175457994,"mc":[{"id":"1.232048439","rc":[{"batb":[[0,3.3,4],[1,3.25,4],[2,3.2,7.64]],"ltp":3.3,"tv":6012.61,"id":8858694}]}]}
{"op":"mcm","clk":"11889804935","pt":1724175461199,"mc":[{"id":"1.232048439","rc":[{"batl":[[0,1.45,9.13]],"ltp":1.45,"tv":16.85,"id":247649},{"batb":[[0,3.25,4],[1,3.2,7.64],[2,3.1,17.95]],"batl":[[0,3.4,4],[1,3.45,4]],"ltp":3.3,"tv":6012.61,"id":8858694}]}]}
{"op":"mcm","clk":"11889805347","pt":1724175464173,"mc":[{"id":"1.232048439","rc":[{"batb":[[0,3.3,4],[1,3.25,4],[2,3.2,7.64]],"ltp":3.3,"tv":6012.61,"id":8858694}]}]}
{"op":"mcm","clk":"11889805679","pt":1724175466477,"mc":[{"id":"1.232048439","rc":[{"batb":[[0,3.25,4],[1,3.2,7.64],[2,3.1,17.95]],"ltp":3.3,"tv":6012.61,"id":8858694}]}]}
{"op":"mcm","clk":"11889806089","pt":1724175469817,"mc":[{"id":"1.232048439","rc":[{"batb":[[0,3.3,4],[1,3.25,4],[2,3.2,7.64]],"ltp":3.3,"tv":6012.61,"id":8858694}]}]}
{"op":"mcm","clk":"11889806391","pt":1724175472086,"mc":[{"id":"1.232048439","rc":[{"batb":[[0,3.25,4],[1,3.2,7.64],[2,3.1,17.95]],"ltp":3.3,"tv":6012.61,"id":8858694}]}]}
{"op":"mcm","clk":"11889806827","pt":1724175475435,"mc":[{"id":"1.232048439","rc":[{"batl":[[0,1.45,5.13]],"ltp":1.45,"tv":16.85,"id":247649},{"trd":[[3.3,913.89]],"batb":[[0,3.2,7.64],[1,3.1,17.95],[2,1.51,25.03]],"batl":[[0,3.3,226.29],[1,3.4,4],[2,3.45,4]],"ltp":3.3,"tv":6020.61,"id":8858694}],"tv":6037.47}]}
{"op":"mcm","clk":"11889806958","pt":1724175476438,"mc":[{"id":"1.232048439","rc":[{"batb":[[0,1.44,4],[1,1.43,4],[2,1.42,4]],"ltp":1.45,"tv":16.85,"id":247649},{"batl":[[0,3.3,230.29]],"ltp":3.3,"tv":6020.61,"id":8858694}]}]}
{"op":"mcm","clk":"11889807643","pt":1724175481392,"mc":[{"id":"1.232048439","rc":[{"trd":[[3.3,1374.47]],"batb":[[0,3.25,4],[1,3.2,7.64],[2,3.1,17.95]],"batl":[[0,3.4,4],[1,3.45,4],[2,3.45,0]],"ltp":3.3,"tv":6481.19,"id":8858694}],"tv":6498.05}]}
{"op":"mcm","clk":"11889807715","pt":1724175481919,"mc":[{"id":"1.232048439","rc":[{"batb":[[0,1.41,91.97],[1,1.11,18.8],[2,1.04,1634.41]],"ltp":1.45,"tv":16.85,"id":247649}]}]}
{"op":"mcm","clk":"11889807987","pt":1724175483827,"mc":[{"id":"1.232048439","rc":[{"batb":[[0,3.2,7.64],[1,3.1,17.95],[2,1.51,25.03]],"ltp":3.3,"tv":6481.19,"id":8858694}]}]}
{"op":"mcm","clk":"11889809014","pt":1724175491800,"mc":[{"id":"1.232048439","rc":[{"batb":[[0,1.42,4],[1,1.41,95.97],[2,1.11,18.8]],"ltp":1.45,"tv":16.85,"id":247649},{"batb":[[0,3.25,14],[1,3.2,11.64],[2,3.1,17.95]],"batl":[[0,3.45,4]],"ltp":3.3,"tv":6481.19,"id":8858694}]}]}
{"op":"mcm","clk":"11889809301","pt":1724175494218,"mc":[{"id":"1.232048439","rc":[{"batb":[[0,3.25,10]],"ltp":3.3,"tv":6481.19,"id":8858694}]}]}
{"op":"mcm","clk":"11889809443","pt":1724175495207,"mc":[{"id":"1.232048439","rc":[{"batb":[[0,3.2,11.64],[1,3.1,17.95],[2,1.51,25.03]],"ltp":3.3,"tv":6481.19,"id":8858694}]}]}
{"op":"mcm","clk":"11889809601","pt":1724175496427,"mc":[{"id":"1.232048439","rc":[{"batb":[[0,3.25,4],[1,3.2,11.64],[2,3.1,17.95]],"ltp":3.3,"tv":6481.19,"id":8858694}]}]}
{"op":"mcm","clk":"11889809915","pt":1724175498931,"mc":[{"id":"1.232048439","rc":[{"batb":[[0,3.25,10]],"ltp":3.3,"tv":6481.19,"id":8858694}]}]}
{"op":"mcm","clk":"11889810330","pt":1724175502228,"mc":[{"id":"1.232048439","rc":[{"batb":[[0,3.3,4],[1,3.25,10],[2,3.2,11.64]],"ltp":3.3,"tv":6481.19,"id":8858694}]}]}
{"op":"mcm","clk":"11889810359","pt":1724175502452,"mc":[{"id":"1.232048439","rc":[{"batb":[[1,3.2,11.64],[2,3.1,17.95]],"ltp":3.3,"tv":6481.19,"id":8858694}]}]}
{"op":"mcm","clk":"11889810567","pt":1724175504023,"mc":[{"id":"1.232048439","rc":[{"trd":[[3.3,1382.47]],"batb":[[0,3.2,7.64],[1,3.1,17.95],[2,1.51,25.03]],"batl":[[0,3.3,226.29],[1,3.45,4]],"ltp":3.3,"tv":6489.19,"id":8858694}],"tv":6506.05}]}
{"op":"mcm","clk":"11889810777","pt":1724175505646,"mc":[{"id":"1.232048439","rc":[{"trd":[[3.3,1835.05]],"batb":[[0,3.3,4],[1,3.2,7.64],[2,3.1,17.95]],"batl":[[0,3.45,4],[1,3.45,0]],"ltp":3.3,"tv":6941.78,"id":8858694}],"tv":6958.63}]}
{"op":"mcm","clk":"11889810915","pt":1724175506856,"mc":[{"id":"1.232048439","rc":[{"batl":[[0,1.44,4],[1,1.45,5.13],[2,1.47,14]],"ltp":1.45,"tv":16.85,"id":247649},{"batb":[[0,3.35,4],[1,3.3,4],[2,3.2,7.64]],"batl":[[0,3.4,4],[1,3.45,4]],"ltp":3.3,"tv":6941.78,"id":8858694}]}]}
{"op":"mcm","clk":"11889811132","pt":1724175508426,"mc":[{"id":"1.232048439","rc":[{"batl":[[0,1.43,5.21],[1,1.47,14],[2,1.5,5.1]],"ltp":1.45,"tv":16.85,"id":247649}]}]}
{"op":"mcm","clk":"11889811274","pt":1724175509438,"mc":[{"id":"1.232048439","rc":[{"batb":[[0,3.3,4],[1,3.2,7.64],[2,3.1,17.95]],"ltp":3.3,"tv":6941.78,"id":8858694}]}]}
{"op":"mcm","clk":"11889811369","pt":1724175510152,"mc":[{"id":"1.232048439","rc":[{"batl":[[0,1.45,5.13]],"ltp":1.45,"tv":16.85,"id":247649}]}]}
{"op":"mcm","clk":"11889811567","pt":1724175511728,"mc":[{"id":"1.232048439","rc":[{"batb":[[0,3.35,4],[1,3.3,4],[2,3.2,7.64]],"ltp":3.3,"tv":6941.78,"id":8858694}]}]}
{"op":"mcm","clk":"11889811939","pt":1724175514118,"mc":[{"id":"1.232048439","rc":[{"batl":[[0,1.47,14],[1,1.5,5.1],[2,3.5,1.82]],"ltp":1.45,"tv":16.85,"id":247649},{"batb":[[0,3.3,4],[1,3.2,7.64],[2,3.1,17.95]],"ltp":3.3,"tv":6941.78,"id":8858694}]}]}
{"op":"mcm","clk":"11889812242","pt":1724175516644,"mc":[{"id":"1.232048439","rc":[{"batb":[[0,3.35,4],[1,3.3,4],[2,3.2,7.64]],"ltp":3.3,"tv":6941.78,"id":8858694}]}]}
{"op":"mcm","clk":"11889812563","pt":1724175519154,"mc":[{"id":"1.232048439","rc":[{"batb":[[0,3.3,4],[1,3.2,7.64],[2,3.1,17.95]],"ltp":3.3,"tv":6941.78,"id":8858694}]}]}
{"op":"mcm","clk":"11889813005","pt":1724175522346,"mc":[{"id":"1.232048439","rc":[{"batl":[[0,1.44,4],[1,1.47,14],[2,1.5,5.1]],"ltp":1.45,"tv":16.85,"id":247649},{"trd":[[3.3,1842.73]],"batb":[[0,3.25,4.16]],"ltp":3.3,"tv":6949.45,"id":8858694}],"tv":6966.31}]}
{"op":"mcm","clk":"11889813438","pt":1724175525232,"mc":[{"id":"1.232048439","rc":[{"batl":[[0,1.47,14],[1,1.5,5.1],[2,3.5,1.82]],"ltp":1.45,"tv":16.85,"id":247649},{"batb":[[0,3.2,7.8],[1,3.1,17.95],[2,1.51,25.03]],"ltp":3.3,"tv":6949.45,"id":8858694}]}]}
{"op":"mcm","clk":"11889813681","pt":1724175527173,"mc":[{"id":"1.232048439","rc":[{"batb":[[0,3.25,4],[1,3.2,7.64],[2,3.1,17.95]],"ltp":3.3,"tv":6949.45,"id":8858694}]}]}
{"op":"mcm","clk":"11889813945","pt":1724175529277,"mc":[{"id":"1.232048439","rc":[{"batb":[[0,3.2,7.64],[1,3.1,17.95],[2,1.51,25.03]],"ltp":3.3,"tv":6949.45,"id":8858694}]}]}
{"op":"mcm","clk":"11889814025","pt":1724175529858,"mc":[{"id":"1.232048439","rc":[{"batl":[[0,1.46,5.09],[1,1.47,14],[2,1.5,5.1]],"ltp":1.45,"tv":16.85,"id":247649}]}]}
{"op":"mcm","clk":"11889814418","pt":1724175532439,"mc":[{"id":"1.232048439","rc":[{"batb":[[0,3.25,4],[1,3.2,7.64],[2,3.1,17.95]],"ltp":3.3,"tv":6949.45,"id":8858694}]}]}
{"op":"mcm","clk":"11889814512","pt":1724175533272,"mc":[{"id":"1.232048439","rc":[{"batl":[[0,3.3,249.48],[1,3.4,4],[2,3.45,4]],"ltp":3.3,"tv":6949.45,"id":8858694}]}]}
{"op":"mcm","clk":"11889814731","pt":1724175534947,"mc":[{"id":"1.232048439","rc":[{"batb":[[0,3.2,7.64],[1,3.1,17.95],[2,1.51,25.03]],"ltp":3.3,"tv":6949.45,"id":8858694}]}]}
{"op":"mcm","clk":"11889815031","pt":1724175537259,"mc":[{"id":"1.232048439","rc":[{"batb":[[0,1.44,4],[1,1.43,4],[2,1.42,4]],"ltp":1.45,"tv":16.85,"id":247649},{"batl":[[0,3.3,253.48]],"ltp":3.3,"tv":6949.45,"id":8858694}]}]}
{"op":"mcm","clk":"11889815081","pt":1724175537678,"mc":[{"id":"1.232048439","rc":[{"batb":[[0,3.25,4],[1,3.2,7.64],[2,3.1,17.95]],"ltp":3.3,"tv":6949.45,"id":8858694}]}]}
{"op":"mcm","clk":"11889815423","pt":1724175540089,"mc":[{"id":"1.232048439","rc":[{"batb":[[0,3.2,7.64],[1,3.1,17.95],[2,1.51,25.03]],"ltp":3.3,"tv":6949.45,"id":8858694}]}]}
{"op":"mcm","clk":"11889815846","pt":1724175543097,"mc":[{"id":"1.232048439","rc":[{"batb":[[0,3.25,4],[1,3.2,7.64],[2,3.1,17.95]],"ltp":3.3,"tv":6949.45,"id":8858694}]}]}
{"op":"mcm","clk":"11889816194","pt":1724175545772,"mc":[{"id":"1.232048439","rc":[{"batb":[[0,3.2,7.64],[1,3.1,17.95],[2,1.51,25.03]],"ltp":3.3,"tv":6949.45,"id":8858694}]}]}
{"op":"mcm","clk":"11889816528","pt":1724175548169,"mc":[{"id":"1.232048439","rc":[{"batb":[[0,3.25,4],[1,3.2,7.64],[2,3.1,17.95]],"ltp":3.3,"tv":6949.45,"id":8858694}]}]}
{"op":"mcm","clk":"11889816808","pt":1724175550367,"mc":[{"id":"1.232048439","rc":[{"batb":[[0,3.2,7.64],[1,3.1,17.95],[2,1.51,25.03]],"ltp":3.3,"tv":6949.45,"id":8858694}]}]}
{"op":"mcm","clk":"11889817496","pt":1724175555588,"mc":[{"id":"1.232048439","rc":[{"batb":[[0,3.25,4],[1,3.2,7.64],[2,3.1,17.95]],"ltp":3.3,"tv":6949.45,"id":8858694}]}]}
{"op":"mcm","clk":"11889817763","pt":1724175557383,"mc":[{"id":"1.232048439","rc":[{"trd":[[3.3,2303.31]],"batl":[[0,3.3,23.19]],"ltp":3.3,"tv":7410.03,"id":8858694}],"tv":7426.89}]}
{"op":"mcm","clk":"11889817829","pt":1724175558009,"mc":[{"id":"1.232048439","rc":[{"batb":[[0,3.2,7.64],[1,3.1,17.95],[2,1.51,25.03]],"ltp":3.3,"tv":7410.03,"id":8858694}]}]}
{"op":"mcm","clk":"11889818160","pt":1724175560416,"mc":[{"id":"1.232048439","rc":[{"batb":[[0,3.25,4],[1,3.2,7.64],[2,3.1,17.95]],"ltp":3.3,"tv":7410.03,"id":8858694}]}]}
{"op":"mcm","clk":"11889818485","pt":1724175562840,"mc":[{"id":"1.232048439","rc":[{"batb":[[0,3.2,7.64],[1,3.1,17.95],[2,1.51,25.03]],"ltp":3.3,"tv":7410.03,"id":8858694}]}]}
{"op":"mcm","clk":"11889819097","pt":1724175567489,"mc":[{"id":"1.232048439","rc":[{"batl":[[0,1.46,9.09]],"ltp":1.45,"tv":16.85,"id":247649},{"batb":[[0,3.25,4],[1,3.2,7.64],[2,3.1,17.95]],"ltp":3.3,"tv":7410.03,"id":8858694}]}]}
{"op":"mcm","clk":"11889819474","pt":1724175569920,"mc":[{"id":"1.232048439","rc":[{"batb":[[0,3.2,7.64],[1,3.1,17.95],[2,1.51,25.03]],"ltp":3.3,"tv":7410.03,"id":8858694}]}]}
{"op":"mcm","clk":"11889819675","pt":1724175571395,"mc":[{"id":"1.232048439","rc":[{"trd":[[3.3,2310.99]],"batl":[[0,3.3,19.35]],"ltp":3.3,"tv":7417.71,"id":8858694}],"tv":7434.57}]}
{"op":"mcm","clk":"11889819949","pt":1724175573543,"mc":[{"id":"1.232048439","rc":[{"batb":[[0,3.25,4],[1,3.2,7.64],[2,3.1,17.95]],"ltp":3.3,"tv":7417.71,"id":8858694}]}]}
{"op":"mcm","clk":"11889820260","pt":1724175575791,"mc":[{"id":"1.232048439","rc":[{"batb":[[0,3.2,7.64],[1,3.1,17.95],[2,1.51,25.03]],"ltp":3.3,"tv":7417.71,"id":8858694}]}]}
{"op":"mcm","clk":"11889820653","pt":1724175579318,"mc":[{"id":"1.232048439","rc":[{"batb":[[0,3.25,4],[1,3.2,7.64],[2,3.1,17.95]],"ltp":3.3,"tv":7417.71,"id":8858694}]}]}
{"op":"mcm","clk":"11889820972","pt":1724175582041,"mc":[{"id":"1.232048439","rc":[{"batb":[[0,3.2,7.64],[1,3.1,17.95],[2,1.51,25.03]],"batl":[[0,3.3,4]],"ltp":3.3,"tv":7417.71,"id":8858694}]}]}
{"op":"mcm","clk":"11889821104","pt":1724175583025,"mc":[{"id":"1.232048439","rc":[{"batb":[[0,1.41,91.97],[1,1.11,18.8],[2,1.04,1634.41]],"ltp":1.45,"tv":16.85,"id":247649}]}]}
{"op":"mcm","clk":"11889821589","pt":1724175587219,"mc":[{"id":"1.232048439","rc":[{"batb":[[0,3.25,4],[1,3.2,7.64],[2,3.1,17.95]],"batl":[[0,3.3,249.48]],"ltp":3.3,"tv":7417.71,"id":8858694}]}]}
{"op":"mcm","clk":"11889821899","pt":1724175589940,"mc":[{"id":"1.232048439","rc":[{"batl":[[0,1.46,5.09]],"ltp":1.45,"tv":16.85,"id":247649},{"batb":[[0,3.2,7.64],[1,3.1,17.95],[2,1.51,25.03]],"ltp":3.3,"tv":7417.71,"id":8858694}]}]}
{"op":"mcm","clk":"11889822522","pt":1724175594926,"mc":[{"id":"1.232048439","rc":[{"batb":[[0,3.25,4],[1,3.2,7.64],[2,3.1,17.95]],"ltp":3.3,"tv":7417.71,"id":8858694}]}]}
{"op":"mcm","clk":"11889822790","pt":1724175597133,"mc":[{"id":"1.232048439","rc":[{"batb":[[0,3.2,7.64],[1,3.1,17.95],[2,1.51,25.03]],"ltp":3.3,"tv":7417.71,"id":8858694}]}]}
{"op":"mcm","clk":"11889822881","pt":1724175597811,"mc":[{"id":"1.232048439","rc":[{"batb":[[0,1.44,4],[1,1.43,4],[2,1.41,91.97]],"ltp":1.45,"tv":16.85,"id":247649},{"batl":[[0,3.3,253.48]],"ltp":3.3,"tv":7417.71,"id":8858694}]}]}
{"op":"mcm","clk":"11889823143","pt":1724175599855,"mc":[{"id":"1.232048439","rc":[{"trd":[[3.3,2786.92]],"batb":[[0,3.25,4],[1,3.2,7.64],[2,3.1,17.95]],"batl":[[0,3.3,15.51]],"ltp":3.3,"tv":7893.64,"id":8858694}],"tv":7910.5}]}
{"op":"mcm","clk":"11889823492","pt":1724175602071,"mc":[{"id":"1.232048439","rc":[{"batb":[[0,3.2,7.64],[1,3.1,17.95],[2,1.51,25.03]],"ltp":3.3,"tv":7893.64,"id":8858694}]}]}
{"op":"mcm","clk":"11889824059","pt":1724175606080,"mc":[{"id":"1.232048439","rc":[{"batb":[[0,3.25,4],[1,3.2,7.64],[2,3.1,17.95]],"ltp":3.3,"tv":7893.64,"id":8858694}]}]}
{"op":"mcm","clk":"11889824478","pt":1724175608868,"mc":[{"id":"1.232048439","rc":[{"batb":[[0,3.2,7.64],[1,3.1,17.95],[2,1.51,25.03]],"ltp":3.3,"tv":7893.64,"id":8858694}]}]}
{"op":"mcm","clk":"11889824791","pt":1724175611230,"mc":[{"id":"1.232048439","rc":[{"batb":[[0,3.25,4],[1,3.2,7.64],[2,3.1,17.95]],"ltp":3.3,"tv":7893.64,"id":8858694}]}]}
{"op":"mcm","clk":"11889825045","pt":1724175613070,"mc":[{"id":"1.232048439","rc":[{"batl":[[0,1.45,4],[1,1.46,5.09],[2,1.47,14]],"ltp":1.45,"tv":16.85,"id":247649}]}]}
{"op":"mcm","clk":"11889825131","pt":1724175613642,"mc":[{"id":"1.232048439","rc":[{"batb":[[0,3.2,7.64],[1,3.1,17.95],[2,1.51,25.03]],"ltp":3.3,"tv":7893.64,"id":8858694}]}]}
{"op":"mcm","clk":"11889825319","pt":1724175615283,"mc":[{"id":"1.232048439","rc":[{"trd":[[3.3,2794.6]],"batl":[[0,3.3,11.68]],"ltp":3.3,"tv":7901.32,"id":8858694}],"tv":7918.18}]}
{"op":"mcm","clk":"11889825499","pt":1724175616664,"mc":[{"id":"1.232048439","rc":[{"batb":[[0,3.25,4],[1,3.2,7.64],[2,3.1,17.95]],"ltp":3.3,"tv":7901.32,"id":8858694}]}]}
{"op":"mcm","clk":"11889825886","pt":1724175619658,"mc":[{"id":"1.232048439","rc":[{"batb":[[0,3.2,7.64],[1,3.1,17.95],[2,1.51,25.03]],"ltp":3.3,"tv":7901.32,"id":8858694}]}]}
{"op":"mcm","clk":"11889826203","pt":1724175622047,"mc":[{"id":"1.232048439","rc":[{"batb":[[0,1.41,91.97],[1,1.11,18.8],[2,1.04,1634.41]],"batl":[[0,1.46,5.09],[1,1.47,14],[2,1.5,5.1]],"ltp":1.45,"tv":16.85,"id":247649}]}]}
{"op":"mcm","clk":"11889826970","pt":1724175628286,"mc":[{"id":"1.232048439","rc":[{"batb":[[0,1.42,4],[1,1.41,95.97],[2,1.11,18.8]],"ltp":1.45,"tv":16.85,"id":247649},{"batl":[[0,3.45,4]],"ltp":3.3,"tv":7901.32,"id":8858694}]}]}
{"op":"mcm","clk":"11889827010","pt":1724175628585,"mc":[{"id":"1.232048439","rc":[{"batb":[[0,3.25,14],[1,3.2,7.64],[2,3.1,17.95]],"ltp":3.3,"tv":7901.32,"id":8858694}]}]}
{"op":"mcm","clk":"11889827148","pt":1724175629581,"mc":[{"id":"1.232048439","rc":[{"batl":[[0,3.3,249.48],[1,3.45,4]],"ltp":3.3,"tv":7901.32,"id":8858694}]}]}
{"op":"mcm","clk":"11889827294","pt":1724175630780,"mc":[{"id":"1.232048439","rc":[{"batl":[[0,1.44,5.17]],"ltp":1.45,"tv":16.85,"id":247649},{"trd":[[3.25,515.8]],"batb":[[0,3.2,7.64],[1,3.1,17.95],[2,1.51,25.03]],"ltp":3.25,"tv":7925.82,"id":8858694}],"tv":7942.68}]}
{"op":"mcm","clk":"11889827571","pt":1724175633013,"mc":[{"id":"1.232048439","rc":[{"batl":[[0,1.45,5.13]],"ltp":1.45,"tv":16.85,"id":247649},{"batb":[[0,3.25,4],[1,3.2,7.64],[2,3.15,12.65]],"ltp":3.25,"tv":7925.82,"id":8858694}]}]}
{"op":"mcm","clk":"11889827879","pt":1724175635280,"mc":[{"id":"1.232048439","rc":[{"batb":[[0,3.2,7.64],[1,3.15,12.65],[2,3.1,17.95]],"ltp":3.25,"tv":7925.82,"id":8858694}]}]}
{"op":"mcm","clk":"11889828346","pt":1724175638985,"mc":[{"id":"1.232048439","rc":[{"trd":[[3.3,3278.21]],"batb":[[0,3.25,4],[1,3.2,7.64],[2,3.15,12.65]],"batl":[[0,3.3,7.68]],"ltp":3.3,"tv":8409.44,"id":8858694}],"tv":8426.29}]}
{"op":"mcm","clk":"11889828634","pt":1724175641278,"mc":[{"id":"1.232048439","rc":[{"batb":[[0,3.2,7.64],[1,3.15,12.65],[2,3.1,17.95]],"ltp":3.3,"tv":8409.44,"id":8858694}]}]}
{"op":"mcm","clk":"11889829004","pt":1724175643997,"mc":[{"id":"1.232048439","rc":[{"batb":[[0,1.44,4],[1,1.43,4],[2,1.42,4]],"batl":[[0,1.45,9.13]],"ltp":1.45,"tv":16.85,"id":247649},{"batb":[[0,3.25,4],[1,3.2,11.64],[2,3.15,12.65]],"batl":[[1,3.45,0]],"ltp":3.3,"tv":8409.44,"id":8858694}]}]}
{"op":"mcm","clk":"11889829225","pt":1724175646150,"mc":[{"id":"1.232048439","rc":[{"batb":[[2,3.1,17.95]],"ltp":3.3,"tv":8409.44,"id":8858694}]}]}
{"op":"mcm","clk":"11889829301","pt":1724175646522,"mc":[{"id":"1.232048439","rc":[{"batb":[[0,1.43,4],[1,1.42,4],[2,1.41,95.97]],"ltp":1.45,"tv":16.85,"id":247649},{"batb":[[0,3.2,11.64],[1,3.1,17.95],[2,1.51,25.03]],"ltp":3.3,"tv":8409.44,"id":8858694}]}]}
{"op":"mcm","clk":"11889829557","pt":1724175648683,"mc":[{"id":"1.232048439","rc":[{"batb":[[0,3.25,4],[1,3.2,11.64],[2,3.1,17.95]],"ltp":3.3,"tv":8409.44,"id":8858694}]}]}
{"op":"mcm","clk":"11889829842","pt":1724175651186,"mc":[{"id":"1.232048439","rc":[{"batb":[[0,3.2,11.64],[1,3.1,17.95],[2,1.51,25.03]],"ltp":3.3,"tv":8409.44,"id":8858694}]}]}
{"op":"mcm","clk":"11889829995","pt":1724175652486,"mc":[{"id":"1.232048439","rc":[{"trd":[[3.3,3282.81]],"batl":[[0,3.3,5.37]],"ltp":3.3,"tv":8414.04,"id":8858694}],"tv":8430.9}]}
{"op":"mcm","clk":"11889830348","pt":1724175655206,"mc":[{"id":"1.232048439","rc":[{"batb":[[0,3.25,4],[1,3.2,11.64],[2,3.1,17.95]],"ltp":3.3,"tv":8414.04,"id":8858694}]}]}
{"op":"mcm","clk":"11889830603","pt":1724175657242,"mc":[{"id":"1.232048439","rc":[{"batb":[[0,3.25,16.25]],"ltp":3.3,"tv":8414.04,"id":8858694}]}]}
{"op":"mcm","clk":"11889830715","pt":1724175657915,"mc":[{"id":"1.232048439","rc":[{"batb":[[0,3.25,12.25]],"ltp":3.3,"tv":8414.04,"id":8858694}]}]}
{"op":"mcm","clk":"11889830822","pt":1724175658805,"mc":[{"id":"1.232048439","rc":[{"batb":[[0,3.25,16.25]],"ltp":3.3,"tv":8414.04,"id":8858694}]}]}
{"op":"mcm","clk":"11889830916","pt":1724175659527,"mc":[{"id":"1.232048439","rc":[{"batb":[[0,1.42,4],[1,1.41,95.97],[2,1.11,18.8]],"ltp":1.45,"tv":16.85,"id":247649}]}]}
{"op":"mcm","clk":"11889831607","pt":1724175664300,"mc":[{"id":"1.232048439","rc":[{"trd":[[3.3,3290.81]],"batl":[[0,3.3,245.48]],"ltp":3.3,"tv":8422.04,"id":8858694}],"tv":8438.9}]}
{"op":"mcm","clk":"11889831635","pt":1724175664508,"mc":[{"id":"1.232048439","rc":[{"batl":[[0,1.45,5.13]],"ltp":1.45,"tv":16.85,"id":247649},{"batb":[[0,3.25,12.25],[1,3.2,7.64]],"ltp":3.3,"tv":8422.04,"id":8858694}]}]}
{"op":"mcm","clk":"11889831829","pt":1724175665817,"mc":[{"id":"1.232048439","rc":[{"batb":[[0,3.2,7.64],[1,3.1,17.95],[2,1.51,25.03]],"ltp":3.3,"tv":8422.04,"id":8858694}]}]}
{"op":"mcm","clk":"11889832197","pt":1724175668434,"mc":[{"id":"1.232048439","rc":[{"batb":[[0,3.25,4],[1,3.2,7.64],[2,3.1,17.95]],"ltp":3.3,"tv":8422.04,"id":8858694}]}]}
{"op":"mcm","clk":"11889832562","pt":1724175671247,"mc":[{"id":"1.232048439","rc":[{"batb":[[0,3.2,7.64],[1,3.1,17.95],[2,1.51,25.03]],"ltp":3.3,"tv":8422.04,"id":8858694}]}]}
{"op":"mcm","clk":"11889832677","pt":1724175672134,"mc":[{"id":"1.232048439","rc":[{"trd":[[3.3,3777.5]],"batl":[[0,3.3,2.14]],"ltp":3.3,"tv":8908.72,"id":8858694}],"tv":8925.58}]}
{"op":"mcm","clk":"11889832956","pt":1724175674010,"mc":[{"id":"1.232048439","rc":[{"batl":[[0,1.45,9.13]],"ltp":1.45,"tv":16.85,"id":247649},{"trd":[[3.3,3781.78]],"batb":[[0,3.3,1.86],[1,3.25,4],[2,3.2,11.64]],"ltp":3.3,"tv":8913.0,"id":8858694}],"tv":8929.86}]}
{"op":"mcm","clk":"11889833245","pt":1724175676247,"mc":[{"id":"1.232048439","rc":[{"batb":[[0,3.25,4],[1,3.2,11.64],[2,3.1,17.95]],"ltp":3.3,"tv":8913.0,"id":8858694}]}]}
{"op":"mcm","clk":"11889835026","pt":1724175689156,"mc":[{"id":"1.232048439","rc":[{"batb":[[0,3.3,4],[1,3.25,4],[2,3.2,11.64]],"batl":[[0,3.4,4]],"ltp":3.3,"tv":8913.0,"id":8858694}]}]}
{"op":"mcm","clk":"11889835349","pt":1724175691457,"mc":[{"id":"1.232048439","rc":[{"batb":[[0,3.25,4],[1,3.2,11.64],[2,3.1,17.95]],"ltp":3.3,"tv":8913.0,"id":8858694}]}]}
{"op":"mcm","clk":"11889835831","pt":1724175694764,"mc":[{"id":"1.232048439","rc":[{"batb":[[0,3.3,4],[1,3.25,4],[2,3.2,11.64]],"ltp":3.3,"tv":8913.0,"id":8858694}]}]}
{"op":"mcm","clk":"11889836234","pt":1724175697637,"mc":[{"id":"1.232048439","rc":[{"batb":[[0,3.25,4],[1,3.2,11.64],[2,3.1,17.95]],"ltp":3.3,"tv":8913.0,"id":8858694}]}]}
{"op":"mcm","clk":"11889836504","pt":1724175699866,"mc":[{"id":"1.232048439","rc":[{"batb":[[0,3.3,4],[1,3.25,4],[2,3.2,11.64]],"ltp":3.3,"tv":8913.0,"id":8858694}]}]}
{"op":"mcm","clk":"11889836843","pt":1724175702472,"mc":[{"id":"1.232048439","rc":[{"batb":[[0,3.25,4],[1,3.2,11.64],[2,3.1,17.95]],"ltp":3.3,"tv":8913.0,"id":8858694}]}]}
{"op":"mcm","clk":"11889837062","pt":1724175704145,"mc":[{"id":"1.232048439","rc":[{"batb":[[0,1.41,91.97],[1,1.11,18.8],[2,1.04,1634.41]],"batl":[[0,1.44,4],[1,1.45,9.13],[2,1.47,14]],"ltp":1.45,"tv":16.85,"id":247649},{"batb":[[0,3.35,4],[1,3.3,253.48],[2,3.25,4]],"ltp":3.3,"tv":8913.0,"id":8858694}]}]}
{"op":"mcm","clk":"11889837175","pt":1724175704979,"mc":[{"id":"1.232048439","rc":[{"batl":[[0,1.43,5.21],[1,1.44,4],[2,1.45,4]],"ltp":1.45,"tv":16.85,"id":247649},{"batb":[[0,3.35,23.38]],"ltp":3.3,"tv":8913.0,"id":8858694}]}]}
{"op":"mcm","clk":"11889837678","pt":1724175708952,"mc":[{"id":"1.232048439","rc":[{"batl":[[1,1.47,14],[2,1.5,5.1]],"ltp":1.45,"tv":16.85,"id":247649},{"batb":[[0,3.35,4],[1,3.3,4]],"ltp":3.3,"tv":8913.0,"id":8858694}]}]}
{"op":"mcm","clk":"11889837756","pt":1724175709471,"mc":[{"id":"1.232048439","rc":[{"batb":[[0,3.2,7.64],[1,3.1,17.95],[2,1.51,25.03]],"ltp":3.3,"tv":8913.0,"id":8858694}]}]}
{"op":"mcm","clk":"11889838043","pt":1724175711550,"mc":[{"id":"1.232048439","rc":[{"batl":[[0,1.47,14],[1,1.5,5.1],[2,3.5,1.82]],"ltp":1.45,"tv":16.85,"id":247649}]}]}
{"op":"mcm","clk":"11889838441","pt":1724175714470,"mc":[{"id":"1.232048439","rc":[{"batl":[[0,1.46,5.09],[1,1.47,14],[2,1.5,5.1]],"ltp":1.45,"tv":16.85,"id":247649}]}]}
{"op":"mcm","clk":"11889839091","pt":1724175719370,"mc":[{"id":"1.232048439","rc":[{"batb":[[0,1.42,4],[1,1.41,95.97],[2,1.11,18.8]],"ltp":1.45,"tv":16.85,"id":247649},{"batl":[[0,3.45,4]],"ltp":3.3,"tv":8913.0,"id":8858694}]}]}
{"op":"mcm","clk":"11889839119","pt":1724175719579,"mc":[{"id":"1.232048439","rc":[{"batb":[[0,3.25,14],[1,3.2,7.64],[2,3.1,17.95]],"ltp":3.3,"tv":8913.0,"id":8858694}]}]}
{"op":"mcm","clk":"11889839443","pt":1724175721991,"mc":[{"id":"1.232048439","rc":[{"batl":[[0,1.47,14],[1,1.5,5.1],[2,3.5,1.82]],"ltp":1.45,"tv":16.85,"id":247649},{"batb":[[0,3.25,10]],"ltp":3.3,"tv":8913.0,"id":8858694}]}]}
{"op":"mcm","clk":"11889839585","pt":1724175722996,"mc":[{"id":"1.232048439","rc":[{"batb":[[0,3.2,7.64],[1,3.1,17.95],[2,1.51,25.03]],"ltp":3.3,"tv":8913.0,"id":8858694}]}]}
{"op":"mcm","clk":"11889839887","pt":1724175725280,"mc":[{"id":"1.232048439","rc":[{"batb":[[0,3.25,14],[1,3.2,7.64],[2,3.1,17.95]],"ltp":3.3,"tv":8913.0,"id":8858694}]}]}
{"op":"mcm","clk":"11889840181","pt":1724175727682,"mc":[{"id":"1.232048439","rc":[{"batb":[[0,3.25,10]],"ltp":3.3,"tv":8913.0,"id":8858694}]}]}
{"op":"mcm","clk":"11889840287","pt":1724175728469,"mc":[{"id":"1.232048439","rc":[{"batb":[[0,3.2,7.64],[1,3.1,17.95],[2,1.51,25.03]],"ltp":3.3,"tv":8913.0,"id":8858694}]}]}
{"op":"mcm","clk":"11889840575","pt":1724175730565,"mc":[{"id":"1.232048439","rc":[{"batb":[[0,3.25,4],[1,3.2,7.64],[2,3.1,17.95]],"ltp":3.3,"tv":8913.0,"id":8858694}]}]}
{"op":"mcm","clk":"11889840885","pt":1724175733106,"mc":[{"id":"1.232048439","rc":[{"batb":[[0,3.25,10]],"ltp":3.3,"tv":8913.0,"id":8858694}]}]}
{"op":"mcm","clk":"11889841089","pt":1724175734579,"mc":[{"id":"1.232048439","rc":[{"batl":[[0,1.45,4],[1,1.47,14],[2,1.5,5.1]],"ltp":1.45,"tv":16.85,"id":247649},{"batb":[[0,3.3,4],[1,3.25,14],[2,3.2,7.64]],"batl":[[0,3.4,4],[1,3.45,4]],"ltp":3.3,"tv":8913.0,"id":8858694}]}]}
{"op":"mcm","clk":"11889841323","pt":1724175736409,"mc":[{"id":"1.232048439","rc":[{"batb":[[0,3.35,4],[1,3.3,16.07],[2,3.25,4]],"ltp":3.3,"tv":8913.0,"id":8858694}]}]}
{"op":"mcm","clk":"11889841625","pt":1724175738782,"mc":[{"id":"1.232048439","rc":[{"batb":[[0,3.2,7.64],[1,3.1,17.95],[2,1.51,25.03]],"ltp":3.3,"tv":8913.0,"id":8858694}]}]}
{"op":"mcm","clk":"11889842031","pt":1724175742085,"mc":[{"id":"1.232048439","rc":[{"batb":[[0,3.25,4],[1,3.2,7.64],[2,3.1,17.95]],"ltp":3.3,"tv":8913.0,"id":8858694}]}]}
{"op":"mcm","clk":"11889842418","pt":1724175745298,"mc":[{"id":"1.232048439","rc":[{"batb":[[0,3.3,245.64]],"ltp":3.3,"tv":8913.0,"id":8858694}]}]}
{"op":"mcm","clk":"11889842469","pt":1724175745806,"mc":[{"id":"1.232048439","rc":[{"batb":[[0,1.41,91.97],[1,1.11,18.8],[2,1.04,1634.41]],"ltp":1.45,"tv":16.85,"id":247649}]}]}
{"op":"mcm","clk":"11889842825","pt":1724175748716,"mc":[{"id":"1.232048439","rc":[{"trd":[[3.3,4273.06]],"batb":[[0,3.2,7.64],[1,3.1,17.95],[2,1.51,25.03]],"ltp":3.3,"tv":9404.29,"id":8858694}],"tv":9421.15}]}
{"op":"mcm","clk":"11889842961","pt":1724175749928,"mc":[{"id":"1.232048439","rc":[{"batb":[[0,1.42,4],[1,1.41,95.97],[2,1.11,18.8]],"ltp":1.45,"tv":16.85,"id":247649},{"batb":[[0,3.25,14],[1,3.2,11.64],[2,3.1,17.95]],"batl":[[0,3.45,4]],"ltp":3.3,"tv":9404.29,"id":8858694}]}]}
{"op":"mcm","clk":"11889843231","pt":1724175752219,"mc":[{"id":"1.232048439","rc":[{"batl":[[0,1.44,5.17],[1,1.45,4],[2,1.47,14]],"ltp":1.45,"tv":16.85,"id":247649},{"batb":[[0,3.25,10]],"ltp":3.3,"tv":9404.29,"id":8858694}]}]}
{"op":"mcm","clk":"11889843368","pt":1724175753322,"mc":[{"id":"1.232048439","rc":[{"batb":[[0,3.2,11.64],[1,3.1,17.95],[2,1.51,25.03]],"ltp":3.3,"tv":9404.29,"id":8858694}]}]}
{"op":"mcm","clk":"11889843496","pt":1724175754413,"mc":[{"id":"1.232048439","rc":[{"batl":[[0,1.45,4],[1,1.47,14],[2,1.5,5.1]],"ltp":1.45,"tv":16.85,"id":247649},{"batb":[[0,3.25,4],[1,3.2,11.64],[2,3.1,17.95]],"ltp":3.3,"tv":9404.29,"id":8858694}]}]}
{"op":"mcm","clk":"11889843514","pt":1724175754518,"mc":[{"id":"1.232048439","rc":[{"batl":[[0,1.45,9.13]],"ltp":1.45,"tv":16.85,"id":247649},{"batb":[[2,3.15,12.65]],"ltp":3.3,"tv":9404.29,"id":8858694}]}]}
{"op":"mcm","clk":"11889843815","pt":1724175757015,"mc":[{"id":"1.232048439","rc":[{"batb":[[0,3.25,10],[2,3.1,17.95]],"ltp":3.3,"tv":9404.29,"id":8858694}]}]}
{"op":"mcm","clk":"11889844220","pt":1724175760316,"mc":[{"id":"1.232048439","rc":[{"batb":[[0,3.2,11.64],[1,3.1,17.95],[2,1.51,25.03]],"ltp":3.3,"tv":9404.29,"id":8858694}]}]}
{"op":"mcm","clk":"11889844275","pt":1724175760721,"mc":[{"id":"1.232048439","rc":[{"batb":[[0,3.25,4],[1,3.2,11.64],[2,3.1,17.95]],"ltp":3.3,"tv":9404.29,"id":8858694}]}]}
{"op":"mcm","clk":"11889844594","pt":1724175763343,"mc":[{"id":"1.232048439","rc":[{"batb":[[0,3.25,10]],"ltp":3.3,"tv":9404.29,"id":8858694}]}]}
{"op":"mcm","clk":"11889844829","pt":1724175765225,"mc":[{"id":"1.232048439","rc":[{"batb":[[0,3.35,4],[1,3.3,4],[2,3.25,14]],"batl":[[0,3.4,4],[1,3.45,4]],"ltp":3.3,"tv":9404.29,"id":8858694}]}]}
{"op":"mcm","clk":"11889844929","pt":1724175766123,"mc":[{"id":"1.232048439","rc":[{"batl":[[0,1.45,4]],"ltp":1.45,"tv":16.85,"id":247649}]}]}
{"op":"mcm","clk":"11889845094","pt":1724175767419,"mc":[{"id":"1.232048439","rc":[{"batb":[[0,3.2,7.64],[1,3.1,17.95],[2,1.51,25.03]],"ltp":3.3,"tv":9404.29,"id":8858694}]}]}
{"op":"mcm","clk":"11889845513","pt":1724175771032,"mc":[{"id":"1.232048439","rc":[{"batb":[[0,3.25,4],[1,3.2,7.64],[2,3.1,17.95]],"ltp":3.3,"tv":9404.29,"id":8858694}]}]}
{"op":"mcm","clk":"11889845813","pt":1724175773427,"mc":[{"id":"1.232048439","rc":[{"batb":[[0,3.2,7.64],[1,3.1,17.95],[2,1.51,25.03]],"ltp":3.3,"tv":9404.29,"id":8858694}]}]}
{"op":"mcm","clk":"11889846117","pt":1724175776236,"mc":[{"id":"1.232048439","rc":[{"batb":[[0,3.25,4],[1,3.2,7.64],[2,3.1,17.95]],"ltp":3.3,"tv":9404.29,"id":8858694}]}]}
{"op":"mcm","clk":"11889846359","pt":1724175778435,"mc":[{"id":"1.232048439","rc":[{"batb":[[0,3.2,7.64],[1,3.1,17.95],[2,1.51,25.03]],"ltp":3.3,"tv":9404.29,"id":8858694}]}]}
{"op":"mcm","clk":"11889846454","pt":1724175779160,"mc":[{"id":"1.232048439","rc":[{"batb":[[0,3.3,245.64],[1,3.2,7.64],[2,3.1,17.95]],"ltp":3.3,"tv":9404.29,"id":8858694}]}]}
{"op":"mcm","clk":"11889846579","pt":1724175780048,"mc":[{"id":"1.232048439","rc":[{"batb":[[0,1.41,91.97],[1,1.11,18.8],[2,1.04,1634.41]],"batl":[[0,1.44,4],[1,1.45,4],[2,1.47,14]],"ltp":1.45,"tv":16.85,"id":247649},{"batb":[[0,3.35,4],[1,3.3,249.64],[2,3.2,7.64]],"ltp":3.3,"tv":9404.29,"id":8858694}]}]}
{"op":"mcm","clk":"11889846837","pt":1724175782039,"mc":[{"id":"1.232048439","rc":[{"trd":[[3.3,4756.35],[3.35,1850.33]],"batb":[[0,3.3,4],[1,3.2,7.64],[2,3.1,17.95]],"ltp":3.3,"tv":9895.58,"id":8858694}],"tv":9912.44}]}
{"op":"mcm","clk":"11889848234","pt":1724175792169,"mc":[{"id":"1.232048439","rc":[{"trd":[[3.3,4764.03]],"batb":[[0,3.2,7.8],[1,3.1,17.95],[2,1.51,25.03]],"ltp":3.3,"tv":9903.26,"id":8858694}],"tv":9920.11}]}
{"op":"mcm","clk":"11889848284","pt":1724175792547,"mc":[{"id":"1.232048439","rc":[{"batl":[[0,1.47,14],[1,1.5,5.1],[2,3.5,1.82]],"ltp":1.45,"tv":16.85,"id":247649}]}]}
{"op":"mcm","clk":"11889848651","pt":1724175795179,"mc":[{"id":"1.232048439","rc":[{"batb":[[0,1.42,4],[1,1.41,95.97],[2,1.11,18.8]],"ltp":1.45,"tv":16.85,"id":247649},{"batl":[[0,3.45,4]],"ltp":3.3,"tv":9903.26,"id":8858694}]}]}
{"op":"mcm","clk":"11889848687","pt":1724175795454,"mc":[{"id":"1.232048439","rc":[{"batb":[[0,3.25,14.16],[1,3.2,7.64],[2,3.1,17.95]],"ltp":3.3,"tv":9903.26,"id":8858694}]}]}
{"op":"mcm","clk":"11889848873","pt":1724175797060,"mc":[{"id":"1.232048439","rc":[{"batb":[[0,3.25,14]],"ltp":3.3,"tv":9903.26,"id":8858694}]}]}
{"op":"mcm","clk":"11889848936","pt":1724175797644,"mc":[{"id":"1.232048439","rc":[{"batb":[[0,3.25,10]],"ltp":3.3,"tv":9903.26,"id":8858694}]}]}
{"op":"mcm","clk":"11889849060","pt":1724175798780,"mc":[{"id":"1.232048439","rc":[{"batb":[[0,3.2,7.64],[1,3.1,17.95],[2,1.51,25.03]],"ltp":3.3,"tv":9903.26,"id":8858694}]}]}
{"op":"mcm","clk":"11889849469","pt":1724175801968,"mc":[{"id":"1.232048439","rc":[{"batb":[[0,3.25,14],[1,3.2,7.64],[2,3.1,17.95]],"ltp":3.3,"tv":9903.26,"id":8858694}]}]}
{"op":"mcm","clk":"11889849938","pt":1724175805366,"mc":[{"id":"1.232048439","rc":[{"trd":[[3.25,517.48]],"batb":[[0,3.25,9.16]],"batl":[[0,3.35,249.48],[1,3.45,4]],"ltp":3.25,"tv":9904.94,"id":8858694}],"tv":9921.79}]}
{"op":"mcm","clk":"11889849991","pt":1724175805777,"mc":[{"id":"1.232048439","rc":[{"batb":[[0,3.2,7.64],[1,3.1,17.95],[2,1.51,25.03]],"ltp":3.25,"tv":9904.94,"id":8858694}]}]}
{"op":"mcm","clk":"11889850760","pt":1724175810265,"mc":[{"id":"1.232048439","rc":[{"batb":[[0,3.25,4],[1,3.2,7.64],[2,3.1,17.95]],"batl":[[0,3.35,253.48]],"ltp":3.25,"tv":9904.94,"id":8858694}]}]}
{"op":"mcm","clk":"11889850864","pt":1724175810782,"mc":[{"id":"1.232048439","rc":[{"trd":[[3.35,2326.26]],"batl":[[0,3.35,15.51]],"ltp":3.35,"tv":10380.87,"id":8858694}],"tv":10397.73}]}
{"op":"mcm","clk":"11889851048","pt":1724175811958,"mc":[{"id":"1.232048439","rc":[{"batb":[[0,3.2,7.64],[1,3.1,17.95],[2,1.51,25.03]],"ltp":3.35,"tv":10380.87,"id":8858694}]}]}
{"op":"mcm","clk":"11889851415","pt":1724175814695,"mc":[{"id":"1.232048439","rc":[{"batb":[[0,3.25,4],[1,3.2,7.64],[2,3.1,17.95]],"ltp":3.35,"tv":10380.87,"id":8858694}]}]}
{"op":"mcm","clk":"11889851758","pt":1724175817164,"mc":[{"id":"1.232048439","rc":[{"batb":[[0,3.2,7.64],[1,3.1,17.95],[2,1.51,25.03]],"ltp":3.35,"tv":10380.87,"id":8858694}]}]}
{"op":"mcm","clk":"11889851959","pt":1724175818770,"mc":[{"id":"1.232048439","rc":[{"trd":[[3.35,2341.61]],"batl":[[0,3.35,3.84]],"ltp":3.35,"tv":10396.22,"id":8858694}],"tv":10413.08}]}
{"op":"mcm","clk":"11889852235","pt":1724175820775,"mc":[{"id":"1.232048439","rc":[{"batb":[[0,3.25,4],[1,3.2,7.64],[2,3.1,17.95]],"ltp":3.35,"tv":10396.22,"id":8858694}]}]}
{"op":"mcm","clk":"11889852540","pt":1724175823114,"mc":[{"id":"1.232048439","rc":[{"batb":[[0,3.2,7.64],[1,3.1,17.95],[2,1.51,25.03]],"ltp":3.35,"tv":10396.22,"id":8858694}]}]}
{"op":"mcm","clk":"11889852869","pt":1724175825411,"mc":[{"id":"1.232048439","rc":[{"batl":[[0,1.46,4],[1,1.47,14],[2,1.5,5.1]],"ltp":1.45,"tv":16.85,"id":247649}]}]}
{"op":"mcm","clk":"11889852904","pt":1724175825618,"mc":[{"id":"1.232048439","rc":[{"batb":[[0,3.25,4],[1,3.2,7.64],[2,3.1,17.95]],"ltp":3.35,"tv":10396.22,"id":8858694}]}]}
{"op":"mcm","clk":"11889853271","pt":1724175828114,"mc":[{"id":"1.232048439","rc":[{"batb":[[0,3.2,7.64],[1,3.1,17.95],[2,1.51,25.03]],"ltp":3.35,"tv":10396.22,"id":8858694}]}]}
{"op":"mcm","clk":"11889853789","pt":1724175831309,"mc":[{"id":"1.232048439","rc":[{"batb":[[0,3.25,4],[1,3.2,7.64],[2,3.1,17.95]],"ltp":3.35,"tv":10396.22,"id":8858694}]}]}
{"op":"mcm","clk":"11889853963","pt":1724175832589,"mc":[{"id":"1.232048439","rc":[{"batl":[[0,3.45,4],[1,3.45,0]],"ltp":3.35,"tv":10396.22,"id":8858694}]}]}
{"op":"mcm","clk":"11889854108","pt":1724175833824,"mc":[{"id":"1.232048439","rc":[{"batb":[[0,3.25,10]],"ltp":3.35,"tv":10396.22,"id":8858694}]}]}
{"op":"mcm","clk":"11889854330","pt":1724175835404,"mc":[{"id":"1.232048439","rc":[{"batb":[[1,3.2,20.08]],"ltp":3.35,"tv":10396.22,"id":8858694}]}]}
{"op":"mcm","clk":"11889854579","pt":1724175837388,"mc":[{"id":"1.232048439","rc":[{"batb":[[0,3.2,7.64],[1,3.1,17.95],[2,1.51,25.03]],"ltp":3.35,"tv":10396.22,"id":8858694}]}]}
{"op":"mcm","clk":"11889854604","pt":1724175837507,"mc":[{"id":"1.232048439","rc":[{"batb":[[0,3.25,16.25],[1,3.2,7.64],[2,3.1,17.95]],"ltp":3.35,"tv":10396.22,"id":8858694}]}]}
{"op":"mcm","clk":"11889854979","pt":1724175840032,"mc":[{"id":"1.232048439","rc":[{"batb":[[0,3.25,12.25]],"batl":[[0,3.35,249.48],[1,3.45,4]],"ltp":3.35,"tv":10396.22,"id":8858694}]}]}
{"op":"mcm","clk":"11889855157","pt":1724175841138,"mc":[{"id":"1.232048439","rc":[{"batl":[[0,1.45,4]],"ltp":1.45,"tv":16.85,"id":247649},{"batl":[[1,3.4,4],[2,3.45,4]],"ltp":3.35,"tv":10396.22,"id":8858694}]}]}
{"op":"mcm","clk":"11889855719","pt":1724175844973,"mc":[{"id":"1.232048439","rc":[{"batb":[[0,3.25,4]],"ltp":3.35,"tv":10396.22,"id":8858694}]}]}
{"op":"mcm","clk":"11889855932","pt":1724175846440,"mc":[{"id":"1.232048439","rc":[{"trd":[[3.35,2832.9]],"batl":[[0,3.35,3.84]],"ltp":3.35,"tv":10887.51,"id":8858694}],"tv":10904.37}]}
{"op":"mcm","clk":"11889856038","pt":1724175847272,"mc":[{"id":"1.232048439","rc":[{"batb":[[0,3.2,7.64],[1,3.1,17.95],[2,1.51,25.03]],"ltp":3.35,"tv":10887.51,"id":8858694}]}]}
{"op":"mcm","clk":"11889856374","pt":1724175849879,"mc":[{"id":"1.232048439","rc":[{"batb":[[0,3.25,4],[1,3.2,7.64],[2,3.1,17.95]],"ltp":3.35,"tv":10887.51,"id":8858694}]}]}
{"op":"mcm","clk":"11889856639","pt":1724175851665,"mc":[{"id":"1.232048439","rc":[{"batl":[[0,3.4,4],[1,3.45,4],[2,3.45,0]],"ltp":3.35,"tv":10887.51,"id":8858694}]}]}
{"op":"mcm","clk":"11889856785","pt":1724175852648,"mc":[{"id":"1.232048439","rc":[{"batb":[[0,3.2,7.64],[1,3.1,17.95],[2,1.51,25.03]],"ltp":3.35,"tv":10887.51,"id":8858694}]}]}
{"op":"mcm","clk":"11889857242","pt":1724175855986,"mc":[{"id":"1.232048439","rc":[{"batb":[[0,3.3,4],[1,3.25,4],[2,3.2,11.64]],"ltp":3.35,"tv":10887.51,"id":8858694}]}]}
{"op":"mcm","clk":"11889857554","pt":1724175858169,"mc":[{"id":"1.232048439","rc":[{"batb":[[0,3.25,4],[1,3.2,11.64],[2,3.1,17.95]],"ltp":3.35,"tv":10887.51,"id":8858694}]}]}
{"op":"mcm","clk":"11889857899","pt":1724175860875,"mc":[{"id":"1.232048439","rc":[{"batb":[[0,3.3,4],[1,3.25,4],[2,3.2,11.64]],"ltp":3.35,"tv":10887.51,"id":8858694}]}]}
{"op":"mcm","clk":"11889858240","pt":1724175863585,"mc":[{"id":"1.232048439","rc":[{"batb":[[0,3.25,4],[1,3.2,11.64],[2,3.1,17.95]],"ltp":3.35,"tv":10887.51,"id":8858694}]}]}
{"op":"mcm","clk":"11889858848","pt":1724175868293,"mc":[{"id":"1.232048439","rc":[{"batl":[[0,1.47,14],[1,1.5,5.1],[2,3.5,1.82]],"ltp":1.45,"tv":16.85,"id":247649},{"batb":[[0,3.3,4],[1,3.2,7.64]],"batl":[[0,3.35,245.64],[1,3.4,4],[2,3.45,4]],"ltp":3.35,"tv":10887.51,"id":8858694}]}]}
{"op":"mcm","clk":"11889859140","pt":1724175870378,"mc":[{"id":"1.232048439","rc":[{"batb":[[0,3.2,7.64],[1,3.1,17.95],[2,1.51,25.03]],"ltp":3.35,"tv":10887.51,"id":8858694}]}]}
{"op":"mcm","clk":"11889859192","pt":1724175870803,"mc":[{"id":"1.232048439","rc":[{"batl":[[0,1.46,5.09],[1,1.47,14],[2,1.5,5.1]],"ltp":1.45,"tv":16.85,"id":247649},{"batl":[[0,3.35,249.64]],"ltp":3.35,"tv":10887.51,"id":8858694}]}]}
{"op":"mcm","clk":"11889859329","pt":1724175871798,"mc":[{"id":"1.232048439","rc":[{"trd":[[3.35,3324.19]],"batl":[[0,3.4,4],[1,3.45,4],[2,3.45,0]],"ltp":3.35,"tv":11378.8,"id":8858694}],"tv":11395.66}]}
{"op":"mcm","clk":"11889859538","pt":1724175873265,"mc":[{"id":"1.232048439","rc":[{"batb":[[0,3.25,4],[1,3.2,7.64],[2,3.1,17.95]],"ltp":3.35,"tv":11378.8,"id":8858694}]}]}
{"op":"mcm","clk":"11889859888","pt":1724175875961,"mc":[{"id":"1.232048439","rc":[{"batb":[[0,3.2,7.64],[1,3.15,12.65]],"ltp":3.35,"tv":11378.8,"id":8858694}]}]}
{"op":"mcm","clk":"11889860337","pt":1724175879294,"mc":[{"id":"1.232048439","rc":[{"batb":[[0,3.25,4],[1,3.2,7.64],[2,3.15,12.65]],"ltp":3.35,"tv":11378.8,"id":8858694}]}]}
{"op":"mcm","clk":"11889860725","pt":1724175881991,"mc":[{"id":"1.232048439","rc":[{"batb":[[0,3.2,7.64],[1,3.15,12.65],[2,3.1,17.95]],"ltp":3.35,"tv":11378.8,"id":8858694}]}]}
{"op":"mcm","clk":"11889861102","pt":1724175885009,"mc":[{"id":"1.232048439","rc":[{"batb":[[0,3.25,4],[1,3.2,7.64],[2,3.15,12.65]],"ltp":3.35,"tv":11378.8,"id":8858694}]}]}
{"op":"mcm","clk":"11889861230","pt":1724175885994,"mc":[{"id":"1.232048439","rc":[{"batl":[[0,1.45,4],[1,1.46,5.09],[2,1.47,14]],"ltp":1.45,"tv":16.85,"id":247649}]}]}
{"op":"mcm","clk":"11889861459","pt":1724175887614,"mc":[{"id":"1.232048439","rc":[{"batb":[[0,3.2,7.64],[1,3.15,12.65],[2,3.1,17.95]],"ltp":3.35,"tv":11378.8,"id":8858694}]}]}
{"op":"mcm","clk":"11889861624","pt":1724175889012,"mc":[{"id":"1.232048439","rc":[{"batl":[[0,3.35,245.64],[1,3.4,4],[2,3.45,4]],"ltp":3.35,"tv":11378.8,"id":8858694}]}]}
{"op":"mcm","clk":"11889861690","pt":1724175889481,"mc":[{"id":"1.232048439","rc":[{"batl":[[0,1.46,5.09],[1,1.47,14],[2,1.5,5.1]],"ltp":1.45,"tv":16.85,"id":247649}]}]}
{"op":"mcm","clk":"11889861909","pt":1724175891095,"mc":[{"id":"1.232048439","rc":[{"trd":[[3.35,3815.48]],"batb":[[0,3.25,4],[1,3.2,7.64],[2,3.15,12.65]],"batl":[[0,3.4,4],[1,3.45,4],[2,3.45,0]],"ltp":3.35,"tv":11870.09,"id":8858694}],"tv":11886.94}]}
{"op":"mcm","clk":"11889862194","pt":1724175893483,"mc":[{"id":"1.232048439","rc":[{"batb":[[0,3.2,7.64],[1,3.15,12.65],[2,3.1,17.95]],"ltp":3.35,"tv":11870.09,"id":8858694}]}]}
{"op":"mcm","clk":"11889862555","pt":1724175896495,"mc":[{"id":"1.232048439","rc":[{"batb":[[0,3.25,4],[1,3.2,7.64],[2,3.15,12.65]],"ltp":3.35,"tv":11870.09,"id":8858694}]}]}
{"op":"mcm","clk":"11889862853","pt":1724175899007,"mc":[{"id":"1.232048439","rc":[{"batb":[[0,3.2,7.64],[1,3.15,12.65],[2,3.1,17.95]],"ltp":3.35,"tv":11870.09,"id":8858694}]}]}
{"op":"mcm","clk":"11889863234","pt":1724175901193,"mc":[{"id":"1.232048439","rc":[{"batl":[[0,1.46,9.09]],"ltp":1.45,"tv":16.85,"id":247649},{"batb":[[0,3.2,11.64]],"ltp":3.35,"tv":11870.09,"id":8858694}]}]}
{"op":"mcm","clk":"11889863277","pt":1724175901495,"mc":[{"id":"1.232048439","rc":[{"batb":[[0,3.25,4],[1,3.2,11.64],[2,3.15,12.65]],"ltp":3.35,"tv":11870.09,"id":8858694}]}]}
{"op":"mcm","clk":"11889863666","pt":1724175903898,"mc":[{"id":"1.232048439","rc":[{"batb":[[0,3.2,11.64],[1,3.15,12.65],[2,3.1,17.95]],"ltp":3.35,"tv":11870.09,"id":8858694}]}]}
{"op":"mcm","clk":"11889864126","pt":1724175906420,"mc":[{"id":"1.232048439","rc":[{"batl":[[0,1.46,5.09]],"ltp":1.45,"tv":16.85,"id":247649},{"batb":[[0,3.25,4],[1,3.2,7.64],[2,3.15,12.65]],"batl":[[0,3.35,245.64],[1,3.4,4],[2,3.45,4]],"ltp":3.35,"tv":11870.09,"id":8858694}]}]}
{"op":"mcm","clk":"11889864398","pt":1724175908192,"mc":[{"id":"1.232048439","rc":[{"trd":[[3.35,4306.76]],"batl":[[0,3.4,4],[1,3.45,4],[2,3.45,0]],"ltp":3.35,"tv":12361.37,"id":8858694}],"tv":12378.23}]}
{"op":"mcm","clk":"11889864440","pt":1724175908503,"mc":[{"id":"1.232048439","rc":[{"batb":[[0,3.2,7.64],[1,3.15,12.65],[2,3.1,17.95]],"ltp":3.35,"tv":12361.37,"id":8858694}]}]}
{"op":"mcm","clk":"11889864989","pt":1724175912413,"mc":[{"id":"1.232048439","rc":[{"batb":[[0,3.25,4],[1,3.2,7.64],[2,3.15,12.65]],"ltp":3.35,"tv":12361.37,"id":8858694}]}]}
{"op":"mcm","clk":"11889865345","pt":1724175914814,"mc":[{"id":"1.232048439","rc":[{"batb":[[0,3.2,7.64],[1,3.15,12.65],[2,3.1,17.95]],"ltp":3.35,"tv":12361.37,"id":8858694}]}]}
{"op":"mcm","clk":"11889865618","pt":1724175916430,"mc":[{"id":"1.232048439","rc":[{"batl":[[0,1.46,9.09]],"ltp":1.45,"tv":16.85,"id":247649},{"batb":[[0,3.2,11.64]],"ltp":3.35,"tv":12361.37,"id":8858694}]}]}
{"op":"mcm","clk":"11889865876","pt":1724175918153,"mc":[{"id":"1.232048439","rc":[{"batb":[[0,3.25,4],[1,3.2,11.64],[2,3.15,12.65]],"ltp":3.35,"tv":12361.37,"id":8858694}]}]}
{"op":"mcm","clk":"11889866270","pt":1724175920936,"mc":[{"id":"1.232048439","rc":[{"batb":[[0,3.2,11.64],[1,3.15,12.65],[2,3.1,17.95]],"ltp":3.35,"tv":12361.37,"id":8858694}]}]}
{"op":"mcm","clk":"11889866419","pt":1724175922030,"mc":[{"id":"1.232048439","rc":[{"batl":[[0,1.46,5.09]],"ltp":1.45,"tv":16.85,"id":247649},{"batb":[[0,3.2,7.64]],"batl":[[0,3.35,245.64],[1,3.4,4],[2,3.45,4]],"ltp":3.35,"tv":12361.37,"id":8858694}]}]}
{"op":"mcm","clk":"11889866575","pt":1724175923246,"mc":[{"id":"1.232048439","rc":[{"batb":[[0,3.25,4],[1,3.2,7.64],[2,3.15,12.65]],"ltp":3.35,"tv":12361.37,"id":8858694}]}]}
{"op":"mcm","clk":"11889866714","pt":1724175924335,"mc":[{"id":"1.232048439","rc":[{"trd":[[3.35,4798.05]],"batl":[[0,3.4,4],[1,3.45,4],[2,3.45,0]],"ltp":3.35,"tv":12852.66,"id":8858694}],"tv":12869.52}]}
{"op":"mcm","clk":"11889866916","pt":1724175925841,"mc":[{"id":"1.232048439","rc":[{"batb":[[0,3.2,7.64],[1,3.15,12.65],[2,3.1,17.95]],"ltp":3.35,"tv":12852.66,"id":8858694}]}]}
{"op":"mcm","clk":"11889867719","pt":1724175931636,"mc":[{"id":"1.232048439","rc":[{"batl":[[0,1.46,9.09]],"ltp":1.45,"tv":16.85,"id":247649},{"batb":[[0,3.25,4],[1,3.2,11.64],[2,3.15,12.65]],"ltp":3.35,"tv":12852.66,"id":8858694}]}]}
{"op":"mcm","clk":"11889867990","pt":1724175933817,"mc":[{"id":"1.232048439","rc":[{"batb":[[0,3.2,11.64],[1,3.15,12.65],[2,3.1,17.95]],"ltp":3.35,"tv":12852.66,"id":8858694}]}]}
{"op":"mcm","clk":"11889868482","pt":1724175937541,"mc":[{"id":"1.232048439","rc":[{"batb":[[0,3.25,4],[1,3.2,11.64],[2,3.15,12.65]],"ltp":3.35,"tv":12852.66,"id":8858694}]}]}
{"op":"mcm","clk":"11889868795","pt":1724175939849,"mc":[{"id":"1.232048439","rc":[{"batb":[[0,3.2,11.64],[1,3.15,12.65],[2,3.1,17.95]],"ltp":3.35,"tv":12852.66,"id":8858694}]}]}
{"op":"mcm","clk":"11889869249","pt":1724175943048,"mc":[{"id":"1.232048439","rc":[{"batb":[[0,3.25,4],[1,3.2,11.64],[2,3.15,12.65]],"ltp":3.35,"tv":12852.66,"id":8858694}]}]}
{"op":"mcm","clk":"11889869607","pt":1724175945460,"mc":[{"id":"1.232048439","rc":[{"batb":[[0,3.2,11.64],[1,3.15,12.65],[2,3.1,17.95]],"ltp":3.35,"tv":12852.66,"id":8858694}]}]}
{"op":"mcm","clk":"11889869984","pt":1724175948072,"mc":[{"id":"1.232048439","rc":[{"batb":[[0,3.25,4],[1,3.2,11.64],[2,3.15,12.65]],"ltp":3.35,"tv":12852.66,"id":8858694}]}]}
{"op":"mcm","clk":"11889870297","pt":1724175950267,"mc":[{"id":"1.232048439","rc":[{"batl":[[0,3.35,245.64],[1,3.4,4],[2,3.45,4]],"ltp":3.35,"tv":12852.66,"id":8858694}]}]}
{"op":"mcm","clk":"11889870350","pt":1724175950680,"mc":[{"id":"1.232048439","rc":[{"batl":[[0,1.46,5.09]],"ltp":1.45,"tv":16.85,"id":247649},{"batb":[[0,3.2,7.64],[1,3.15,12.65],[2,3.1,17.95]],"ltp":3.35,"tv":12852.66,"id":8858694}]}]}
{"op":"mcm","clk":"11889870700","pt":1724175953058,"mc":[{"id":"1.232048439","rc":[{"trd":[[3.35,5289.34]],"batb":[[0,3.25,4],[1,3.2,7.64],[2,3.15,12.65]],"batl":[[0,3.4,4],[1,3.45,4],[2,3.45,0]],"ltp":3.35,"tv":13343.95,"id":8858694}],"tv":13360.81}]}
{"op":"mcm","clk":"11889871035","pt":1724175955359,"mc":[{"id":"1.232048439","rc":[{"batb":[[0,3.2,7.64],[1,3.15,12.65],[2,3.1,17.95]],"ltp":3.35,"tv":13343.95,"id":8858694}]}]}
{"op":"mcm","clk":"11889871561","pt":1724175959385,"mc":[{"id":"1.232048439","rc":[{"batb":[[0,3.25,4],[1,3.2,7.64],[2,3.15,12.65]],"ltp":3.35,"tv":13343.95,"id":8858694}]}]}
{"op":"mcm","clk":"11889871903","pt":1724175962091,"mc":[{"id":"1.232048439","rc":[{"batl":[[0,1.45,4],[1,1.46,5.09],[2,1.47,14]],"ltp":1.45,"tv":16.85,"id":247649},{"batb":[[0,3.2,7.64],[1,3.15,12.65],[2,3.1,17.95]],"ltp":3.35,"tv":13343.95,"id":8858694}]}]}
{"op":"mcm","clk":"11889872760","pt":1724175967978,"mc":[{"id":"1.232048439","rc":[{"batb":[[0,3.25,4],[1,3.2,7.64],[2,3.15,12.65]],"ltp":3.35,"tv":13343.95,"id":8858694}]}]}
{"op":"mcm","clk":"11889873148","pt":1724175970481,"mc":[{"id":"1.232048439","rc":[{"batb":[[0,3.2,7.64],[1,3.15,12.65],[2,3.1,17.95]],"ltp":3.35,"tv":13343.95,"id":8858694}]}]}
{"op":"mcm","clk":"11889873602","pt":1724175973604,"mc":[{"id":"1.232048439","rc":[{"batb":[[0,3.25,4],[1,3.2,7.64],[2,3.15,12.65]],"ltp":3.35,"tv":13343.95,"id":8858694}]}]}
{"op":"mcm","clk":"11889873982","pt":1724175976215,"mc":[{"id":"1.232048439","rc":[{"batb":[[0,3.2,7.64],[1,3.15,12.65],[2,3.1,17.95]],"ltp":3.35,"tv":13343.95,"id":8858694}]}]}
{"op":"mcm","clk":"11889874178","pt":1724175977372,"mc":[{"id":"1.232048439","rc":[{"batb":[[0,3.25,113],[1,3.2,11.64],[2,3.15,12.65]],"ltp":3.35,"tv":13343.95,"id":8858694}]}]}
{"op":"mcm","clk":"11889874396","pt":1724175978833,"mc":[{"id":"1.232048439","rc":[{"batl":[[0,1.44,5.17],[1,1.45,4]],"ltp":1.45,"tv":16.85,"id":247649},{"batb":[[0,3.3,16.07],[1,3.25,113],[2,3.2,11.64]],"ltp":3.35,"tv":13343.95,"id":8858694}]}]}
{"op":"mcm","clk":"11889874765","pt":1724175981206,"mc":[{"id":"1.232048439","rc":[{"batb":[[0,3.3,12.07]],"ltp":3.35,"tv":13343.95,"id":8858694}]}]}
{"op":"mcm","clk":"11889875245","pt":1724175984525,"mc":[{"id":"1.232048439","rc":[{"batb":[[0,3.35,4],[1,3.3,12.07],[2,3.25,113]],"ltp":3.35,"tv":13343.95,"id":8858694}]}]}
{"op":"mcm","clk":"11889875557","pt":1724175986917,"mc":[{"id":"1.232048439","rc":[{"batb":[[0,3.3,12.07],[1,3.25,113],[2,3.2,11.64]],"ltp":3.35,"tv":13343.95,"id":8858694}]}]}
{"op":"mcm","clk":"11889876068","pt":1724175990623,"mc":[{"id":"1.232048439","rc":[{"batb":[[0,3.35,4],[1,3.3,12.07],[2,3.25,113]],"ltp":3.35,"tv":13343.95,"id":8858694}]}]}
{"op":"mcm","clk":"11889876311","pt":1724175992217,"mc":[{"id":"1.232048439","rc":[{"batl":[[0,1.43,4],[1,1.44,5.17],[2,1.45,4]],"ltp":1.45,"tv":16.85,"id":247649}]}]}
{"op":"mcm","clk":"11889876451","pt":1724175993222,"mc":[{"id":"1.232048439","rc":[{"batb":[[0,3.3,12.07],[1,3.25,113],[2,3.2,11.64]],"ltp":3.35,"tv":13343.95,"id":8858694}]}]}
{"op":"mcm","clk":"11889876921","pt":1724175996423,"mc":[{"id":"1.232048439","rc":[{"batb":[[0,3.35,4],[1,3.3,12.07],[2,3.25,113]],"ltp":3.35,"tv":13343.95,"id":8858694}]}]}
{"op":"mcm","clk":"11889877261","pt":1724175998810,"mc":[{"id":"1.232048439","rc":[{"batb":[[0,3.3,12.07],[1,3.25,113],[2,3.2,11.64]],"ltp":3.35,"tv":13343.95,"id":8858694}]}]}
{"op":"mcm","clk":"11889877830","pt":1724176003119,"mc":[{"id":"1.232048439","rc":[{"batl":[[0,1.44,5.17],[1,1.45,4],[2,1.47,14]],"ltp":1.45,"tv":16.85,"id":247649},{"trd":[[3.35,5297.34]],"batl":[[0,3.35,84.28],[1,3.4,4],[2,3.45,4]],"ltp":3.35,"tv":13351.95,"id":8858694}],"tv":13368.81}]}
{"op":"mcm","clk":"11889878388","pt":1724176007344,"mc":[{"id":"1.232048439","rc":[{"batl":[[0,1.44,9.17]],"ltp":1.45,"tv":16.85,"id":247649},{"trd":[[3.35,5305.34]],"ltp":3.35,"tv":13359.95,"id":8858694}],"tv":13376.81}]}
{"op":"mcm","clk":"11889879117","pt":1724176012561,"mc":[{"id":"1.232048439","rc":[{"trd":[[3.35,5313.34]],"batl":[[0,3.35,80.28]],"ltp":3.35,"tv":13367.95,"id":8858694}],"tv":13384.8}]}
{"op":"mcm","clk":"11889879440","pt":1724176015020,"mc":[{"id":"1.232048439","rc":[{"trd":[[3.35,5321.34]],"batl":[[0,3.35,76.28]],"ltp":3.35,"tv":13375.94,"id":8858694}],"tv":13392.8}]}
{"op":"mcm","clk":"11889880319","pt":1724176021466,"mc":[{"id":"1.232048439","rc":[{"trd":[[3.35,5329.34]],"batl":[[0,3.35,72.28]],"ltp":3.35,"tv":13383.94,"id":8858694}],"tv":13400.8}]}
{"op":"mcm","clk":"11889881177","pt":1724176027154,"mc":[{"id":"1.232048439","rc":[{"trd":[[1.41,68.72],[1.42,14.48]],"batb":[[0,1.41,27.49],[1,1.11,18.8],[2,1.04,1634.41]],"ltp":1.41,"tv":89.33,"id":247649},{"trd":[[3.35,5473.9],[3.4,9.67],[3.45,35.99]],"batb":[[0,3.35,4],[1,3.3,12.07],[2,3.25,4]],"ltp":3.45,"tv":13574.17,"id":8858694}],"tv":13663.51}]}
{"op":"mcm","clk":"11889881334","pt":1724176028139,"mc":[{"id":"1.232048439","rc":[{"batb":[[0,1.41,95.97]],"batl":[[0,1.44,5.17],[1,1.47,14],[2,1.5,5.1]],"ltp":1.41,"tv":89.33,"id":247649},{"batb":[[1,3.25,16.25],[2,3.2,11.64]],"ltp":3.45,"tv":13574.17,"id":8858694}]}]}
{"op":"mcm","clk":"11889881559","pt":1724176029755,"mc":[{"id":"1.232048439","rc":[{"batb":[[0,3.25,16.25],[1,3.2,11.64],[2,3.1,17.95]],"ltp":3.45,"tv":13574.17,"id":8858694}]}]}
{"op":"mcm","clk":"11889882472","pt":1724176036055,"mc":[{"id":"1.232048439","rc":[{"trd":[[3.25,535.44]],"batb":[[0,3.25,7.27],[1,3.2,4]],"ltp":3.25,"tv":13592.13,"id":8858694}],"tv":13681.47}]}
{"op":"mcm","clk":"11889882819","pt":1724176038354,"mc":[{"id":"1.232048439","rc":[{"batb":[[0,3.3,4],[1,3.25,7.27]],"batl":[[0,3.45,4]],"ltp":3.25,"tv":13592.13,"id":8858694}]}]}
{"op":"mcm","clk":"11889883071","pt":1724176040173,"mc":[{"id":"1.232048439","rc":[{"batb":[[0,3.2,10],[1,3.15,7.5]],"ltp":3.25,"tv":13592.13,"id":8858694}]}]}
{"op":"mcm","clk":"11889883365","pt":1724176042282,"mc":[{"id":"1.232048439","rc":[{"batl":[[0,1.45,5.13]],"ltp":1.41,"tv":89.33,"id":247649},{"batb":[[0,3.25,4],[1,3.2,10],[2,3.15,7.5]],"ltp":3.25,"tv":13592.13,"id":8858694}]}]}
{"op":"mcm","clk":"11889883671","pt":1724176044293,"mc":[{"id":"1.232048439","rc":[{"batl":[[0,1.46,5.09]],"ltp":1.41,"tv":89.33,"id":247649},{"batb":[[1,3.15,7.5],[2,3.1,17.95]],"ltp":3.25,"tv":13592.13,"id":8858694}]}]}
{"op":"mcm","clk":"11889883728","pt":1724176044563,"mc":[{"id":"1.232048439","rc":[{"batb":[[0,3.15,7.5],[1,3.1,17.95],[2,1.51,25.03]],"ltp":3.25,"tv":13592.13,"id":8858694}]}]}
{"op":"mcm","clk":"11889884297","pt":1724176048778,"mc":[{"id":"1.232048439","rc":[{"batb":[[0,3.2,14],[1,3.15,7.5],[2,3.1,17.95]],"ltp":3.25,"tv":13592.13,"id":8858694}]}]}
{"op":"mcm","clk":"11889884748","pt":1724176052000,"mc":[{"id":"1.232048439","rc":[{"batb":[[0,3.15,7.5],[1,3.1,17.95],[2,1.51,25.03]],"ltp":3.25,"tv":13592.13,"id":8858694}]}]}
{"op":"mcm","clk":"11889884872","pt":1724176052788,"mc":[{"id":"1.232048439","rc":[{"batl":[[0,1.46,9.09]],"ltp":1.41,"tv":89.33,"id":247649},{"batb":[[0,3.15,11.5]],"ltp":3.25,"tv":13592.13,"id":8858694}]}]}
{"op":"mcm","clk":"11889885268","pt":1724176055389,"mc":[{"id":"1.232048439","rc":[{"batb":[[0,3.2,14],[1,3.15,11.5],[2,3.1,17.95]],"ltp":3.25,"tv":13592.13,"id":8858694}]}]}
{"op":"mcm","clk":"11889885698","pt":1724176058413,"mc":[{"id":"1.232048439","rc":[{"batb":[[0,3.2,10]],"ltp":3.25,"tv":13592.13,"id":8858694}]}]}
{"op":"mcm","clk":"11889885841","pt":1724176059405,"mc":[{"id":"1.232048439","rc":[{"batb":[[0,3.15,11.5],[1,3.1,17.95],[2,1.51,25.03]],"ltp":3.25,"tv":13592.13,"id":8858694}]}]}
{"op":"mcm","clk":"11889886030","pt":1724176060604,"mc":[{"id":"1.232048439","rc":[{"batb":[[0,3.2,4],[1,3.15,11.5],[2,3.1,17.95]],"ltp":3.25,"tv":13592.13,"id":8858694}]}]}
{"op":"mcm","clk":"11889886223","pt":1724176061903,"mc":[{"id":"1.232048439","rc":[{"batb":[[0,3.25,10],[1,3.2,4],[2,3.15,11.5]],"ltp":3.25,"tv":13592.13,"id":8858694}]}]}
{"op":"mcm","clk":"11889886381","pt":1724176063202,"mc":[{"id":"1.232048439","rc":[{"batl":[[0,1.46,4]],"ltp":1.41,"tv":89.33,"id":247649},{"batb":[[1,3.15,7.5],[2,3.1,17.95]],"ltp":3.25,"tv":13592.13,"id":8858694}]}]}
{"op":"mcm","clk":"11889886681","pt":1724176065296,"mc":[{"id":"1.232048439","rc":[{"batb":[[0,3.15,7.5],[1,3.1,17.95],[2,1.51,25.03]],"ltp":3.25,"tv":13592.13,"id":8858694}]}]}
{"op":"mcm","clk":"11889886723","pt":1724176065707,"mc":[{"id":"1.232048439","rc":[{"batb":[[0,3.2,4],[1,3.15,7.5],[2,3.1,17.95]],"ltp":3.25,"tv":13592.13,"id":8858694}]}]}
{"op":"mcm","clk":"11889887076","pt":1724176068310,"mc":[{"id":"1.232048439","rc":[{"batb":[[0,3.2,14]],"ltp":3.25,"tv":13592.13,"id":8858694}]}]}
{"op":"mcm","clk":"11889887516","pt":1724176071818,"mc":[{"id":"1.232048439","rc":[{"batb":[[0,3.25,4],[1,3.2,4],[2,3.15,7.5]],"ltp":3.25,"tv":13592.13,"id":8858694}]}]}
{"op":"mcm","clk":"11889887621","pt":1724176072646,"mc":[{"id":"1.232048439","rc":[{"batb":[[1,3.15,7.5],[2,3.1,17.95]],"ltp":3.25,"tv":13592.13,"id":8858694}]}]}
{"op":"mcm","clk":"11889887850","pt":1724176074416,"mc":[{"id":"1.232048439","rc":[{"batb":[[0,3.2,10]],"ltp":3.25,"tv":13592.13,"id":8858694}]}]}
{"op":"mcm","clk":"11889888137","pt":1724176076826,"mc":[{"id":"1.232048439","rc":[{"batb":[[0,3.25,4],[1,3.2,10],[2,3.15,7.5]],"ltp":3.25,"tv":13592.13,"id":8858694}]}]}
{"op":"mcm","clk":"11889888267","pt":1724176077813,"mc":[{"id":"1.232048439","rc":[{"batb":[[1,3.15,7.5],[2,3.1,17.95]],"ltp":3.25,"tv":13592.13,"id":8858694}]}]}
{"op":"mcm","clk":"11889888450","pt":1724176079325,"mc":[{"id":"1.232048439","rc":[{"batb":[[0,3.15,7.5],[1,3.1,17.95],[2,1.51,25.03]],"ltp":3.25,"tv":13592.13,"id":8858694}]}]}
{"op":"mcm","clk":"11889888859","pt":1724176082175,"mc":[{"id":"1.232048439","rc":[{"batb":[[0,3.2,14],[1,3.15,7.5],[2,3.1,17.95]],"ltp":3.25,"tv":13592.13,"id":8858694}]}]}
{"op":"mcm","clk":"11889888987","pt":1724176083180,"mc":[{"id":"1.232048439","rc":[{"batb":[[0,3.2,18]],"ltp":3.25,"tv":13592.13,"id":8858694}]}]}
{"op":"mcm","clk":"11889889050","pt":1724176083701,"mc":[{"id":"1.232048439","rc":[{"batb":[[1,3.1,17.95],[2,1.51,25.03]],"ltp":3.25,"tv":13592.13,"id":8858694}]}]}
{"op":"mcm","clk":"11889889225","pt":1724176084963,"mc":[{"id":"1.232048439","rc":[{"batb":[[0,3.2,14]],"ltp":3.25,"tv":13592.13,"id":8858694}]}]}
{"op":"mcm","clk":"11889889431","pt":1724176086283,"mc":[{"id":"1.232048439","rc":[{"batb":[[0,3.1,17.95],[1,1.51,25.03],[2,1.11,18.8]],"ltp":3.25,"tv":13592.13,"id":8858694}]}]}
{"op":"mcm","clk":"11889889590","pt":1724176087472,"mc":[{"id":"1.232048439","rc":[{"batb":[[0,3.15,4],[1,3.1,17.95],[2,1.51,25.03]],"ltp":3.25,"tv":13592.13,"id":8858694}]}]}
{"op":"mcm","clk":"11889889765","pt":1724176088674,"mc":[{"id":"1.232048439","rc":[{"batb":[[0,3.2,10],[1,3.15,4],[2,3.1,17.95]],"ltp":3.25,"tv":13592.13,"id":8858694}]}]}
{"op":"mcm","clk":"11889889924","pt":1724176090079,"mc":[{"id":"1.232048439","rc":[{"batb":[[1,3.1,17.95],[2,1.51,25.03]],"ltp":3.25,"tv":13592.13,"id":8858694}]}]}
{"op":"mcm","clk":"11889890171","pt":1724176092024,"mc":[{"id":"1.232048439","rc":[{"batb":[[0,3.1,17.95],[1,1.51,25.03],[2,1.11,18.8]],"ltp":3.25,"tv":13592.13,"id":8858694}]}]}
{"op":"mcm","clk":"11889890215","pt":1724176092494,"mc":[{"id":"1.232048439","rc":[{"batb":[[0,3.15,4],[1,3.1,17.95],[2,1.51,25.03]],"ltp":3.25,"tv":13592.13,"id":8858694}]}]}
{"op":"mcm","clk":"11889890511","pt":1724176095296,"mc":[{"id":"1.232048439","rc":[{"batb":[[0,3.2,10]],"ltp":3.25,"tv":13592.13,"id":8858694}]}]}
{"op":"mcm","clk":"11889890905","pt":1724176098424,"mc":[{"id":"1.232048439","rc":[{"batl":[[0,1.45,4],[1,1.46,4],[2,1.47,14]],"ltp":1.41,"tv":89.33,"id":247649},{"batb":[[0,3.25,4]],"ltp":3.25,"tv":13592.13,"id":8858694}]}]}
{"op":"mcm","clk":"11889890949","pt":1724176098685,"mc":[{"id":"1.232048439","rc":[{"batl":[[1,1.47,14],[2,1.5,5.1]],"ltp":1.41,"tv":89.33,"id":247649}]}]}
{"op":"mcm","clk":"11889891134","pt":1724176100202,"mc":[{"id":"1.232048439","rc":[{"batb":[[0,3.1,17.95],[1,1.51,25.03],[2,1.11,18.8]],"ltp":3.25,"tv":13592.13,"id":8858694}]}]}
{"op":"mcm","clk":"11889891193","pt":1724176100719,"mc":[{"id":"1.232048439","rc":[{"batl":[[0,1.47,14],[1,1.5,5.1],[2,3.5,1.82]],"ltp":1.41,"tv":89.33,"id":247649},{"batb":[[0,3.15,10],[1,3.1,17.95],[2,1.51,25.03]],"ltp":3.25,"tv":13592.13,"id":8858694}]}]}
{"op":"mcm","clk":"11889891348","pt":1724176102429,"mc":[{"id":"1.232048439","rc":[{"batb":[[0,3.2,4],[1,3.15,10],[2,3.1,17.95]],"ltp":3.25,"tv":13592.13,"id":8858694}]}]}
{"op":"mcm","clk":"11889891579","pt":1724176104099,"mc":[{"id":"1.232048439","rc":[{"batb":[[1,3.1,17.95],[2,1.51,25.03]],"ltp":3.25,"tv":13592.13,"id":8858694}]}]}
{"op":"mcm","clk":"11889891660","pt":1724176104715,"mc":[{"id":"1.232048439","rc":[{"batb":[[0,3.1,17.95],[1,1.51,25.03],[2,1.11,18.8]],"ltp":3.25,"tv":13592.13,"id":8858694}]}]}
{"op":"mcm","clk":"11889891975","pt":1724176107000,"mc":[{"id":"1.232048439","rc":[{"batl":[[0,1.47,19.06]],"ltp":1.41,"tv":89.33,"id":247649},{"batb":[[0,3.15,14],[1,3.1,17.95],[2,1.51,25.03]],"ltp":3.25,"tv":13592.13,"id":8858694}]}]}
{"op":"mcm","clk":"11889892330","pt":1724176109333,"mc":[{"id":"1.232048439","rc":[{"batb":[[0,3.15,10]],"ltp":3.25,"tv":13592.13,"id":8858694}]}]}
{"op":"mcm","clk":"11889892463","pt":1724176110214,"mc":[{"id":"1.232048439","rc":[{"batb":[[0,3.1,17.95],[1,1.51,25.03],[2,1.11,18.8]],"ltp":3.25,"tv":13592.13,"id":8858694}]}]}
{"op":"mcm","clk":"11889892870","pt":1724176113406,"mc":[{"id":"1.232048439","rc":[{"batl":[[0,1.47,23.06]],"ltp":1.41,"tv":89.33,"id":247649}]}]}
{"op":"mcm","clk":"11889892905","pt":1724176113610,"mc":[{"id":"1.232048439","rc":[{"batb":[[0,3.15,14],[1,3.1,17.95],[2,1.51,25.03]],"ltp":3.25,"tv":13592.13,"id":8858694}]}]}
{"op":"mcm","clk":"11889893192","pt":1724176116011,"mc":[{"id":"1.232048439","rc":[{"batb":[[0,3.15,10]],"ltp":3.25,"tv":13592.13,"id":8858694}]}]}
{"op":"mcm","clk":"11889893326","pt":1724176116932,"mc":[{"id":"1.232048439","rc":[{"batb":[[0,3.1,17.95],[1,1.51,25.03],[2,1.11,18.8]],"ltp":3.25,"tv":13592.13,"id":8858694}]}]}
{"op":"mcm","clk":"11889893856","pt":1724176120742,"mc":[{"id":"1.232048439","rc":[{"batb":[[0,3.15,14],[1,3.1,17.95],[2,1.51,25.03]],"ltp":3.25,"tv":13592.13,"id":8858694}]}]}
{"op":"mcm","clk":"11889894173","pt":1724176123454,"mc":[{"id":"1.232048439","rc":[{"batb":[[0,3.15,10]],"ltp":3.25,"tv":13592.13,"id":8858694}]}]}
{"op":"mcm","clk":"11889894320","pt":1724176124543,"mc":[{"id":"1.232048439","rc":[{"batb":[[0,3.1,17.95],[1,1.51,25.03],[2,1.11,18.8]],"ltp":3.25,"tv":13592.13,"id":8858694}]}]}
{"op":"mcm","clk":"11889894682","pt":1724176127611,"mc":[{"id":"1.232048439","rc":[{"batb":[[0,3.15,14],[1,3.1,17.95],[2,1.51,25.03]],"ltp":3.25,"tv":13592.13,"id":8858694}]}]}
{"op":"mcm","clk":"11889894869","pt":1724176129230,"mc":[{"id":"1.232048439","rc":[{"batb":[[0,3.2,7.38],[1,3.15,18],[2,3.1,17.95]],"ltp":3.25,"tv":13592.13,"id":8858694}]}]}
{"op":"mcm","clk":"11889894978","pt":1724176130253,"mc":[{"id":"1.232048439","rc":[{"batb":[[1,3.15,14]],"ltp":3.25,"tv":13592.13,"id":8858694}]}]}
{"op":"mcm","clk":"11889895062","pt":1724176130936,"mc":[{"id":"1.232048439","rc":[{"batb":[[1,3.15,4]],"ltp":3.25,"tv":13592.13,"id":8858694}]}]}
{"op":"mcm","clk":"11889895156","pt":1724176131627,"mc":[{"id":"1.232048439","rc":[{"batb":[[0,3.15,4],[1,3.1,17.95],[2,1.51,25.03]],"ltp":3.25,"tv":13592.13,"id":8858694}]}]}
{"op":"mcm","clk":"11889895381","pt":1724176133435,"mc":[{"id":"1.232048439","rc":[{"batb":[[0,3.25,10],[1,3.2,4],[2,3.1,17.95]],"ltp":3.25,"tv":13592.13,"id":8858694}]}]}
{"op":"mcm","clk":"11889895449","pt":1724176133950,"mc":[{"id":"1.232048439","rc":[{"batl":[[0,1.44,5.17],[1,1.47,18],[2,1.5,5.1]],"ltp":1.41,"tv":89.33,"id":247649}]}]}
{"op":"mcm","clk":"11889895633","pt":1724176135541,"mc":[{"id":"1.232048439","rc":[{"batb":[[1,3.1,17.95],[2,1.51,25.03]],"ltp":3.25,"tv":13592.13,"id":8858694}]}]}
{"op":"mcm","clk":"11889895799","pt":1724176136926,"mc":[{"id":"1.232048439","rc":[{"batb":[[0,3.1,17.95],[1,1.51,25.03],[2,1.11,18.8]],"ltp":3.25,"tv":13592.13,"id":8858694}]}]}
{"op":"mcm","clk":"11889895948","pt":1724176138423,"mc":[{"id":"1.232048439","rc":[{"batl":[[0,1.47,18],[1,1.5,5.1],[2,3.5,1.82]],"ltp":1.41,"tv":89.33,"id":247649},{"batb":[[0,3.15,4],[1,3.1,17.95],[2,1.51,25.03]],"ltp":3.25,"tv":13592.13,"id":8858694}]}]}
{"op":"mcm","clk":"11889896076","pt":1724176139633,"mc":[{"id":"1.232048439","rc":[{"batb":[[0,3.2,10],[1,3.15,4],[2,3.1,17.95]],"ltp":3.25,"tv":13592.13,"id":8858694}]}]}
{"op":"mcm","clk":"11889896197","pt":1724176140656,"mc":[{"id":"1.232048439","rc":[{"batb":[[1,3.1,17.95],[2,1.51,25.03]],"ltp":3.25,"tv":13592.13,"id":8858694}]}]}
{"op":"mcm","clk":"11889896589","pt":1724176143875,"mc":[{"id":"1.232048439","rc":[{"batl":[[0,1.46,4],[1,1.47,18],[2,1.5,5.1]],"ltp":1.41,"tv":89.33,"id":247649},{"batb":[[0,3.2,4],[1,3.15,4],[2,3.1,17.95]],"ltp":3.25,"tv":13592.13,"id":8858694}]}]}
{"op":"mcm","clk":"11889896657","pt":1724176144454,"mc":[{"id":"1.232048439","rc":[{"batb":[[0,3.15,4],[1,3.1,17.95],[2,1.51,25.03]],"ltp":3.25,"tv":13592.13,"id":8858694}]}]}
{"op":"mcm","clk":"11889896934","pt":1724176146160,"mc":[{"id":"1.232048439","rc":[{"batb":[[0,3.2,10]],"ltp":3.25,"tv":13592.13,"id":8858694}]}]}
{"op":"mcm","clk":"11889897272","pt":1724176149164,"mc":[{"id":"1.232048439","rc":[{"batb":[[0,3.1,17.95],[1,1.51,25.03],[2,1.11,18.8]],"ltp":3.25,"tv":13592.13,"id":8858694}]}]}
{"op":"mcm","clk":"11889897320","pt":1724176149683,"mc":[{"id":"1.232048439","rc":[{"batb":[[0,3.15,4],[1,3.1,17.95],[2,1.51,25.03]],"ltp":3.25,"tv":13592.13,"id":8858694}]}]}
{"op":"mcm","clk":"11889897555","pt":1724176151364,"mc":[{"id":"1.232048439","rc":[{"batb":[[0,3.2,10],[1,3.15,4],[2,3.1,17.95]],"ltp":3.25,"tv":13592.13,"id":8858694}]}]}
{"op":"mcm","clk":"11889897634","pt":1724176152083,"mc":[{"id":"1.232048439","rc":[{"batb":[[1,3.1,17.95],[2,1.51,25.03]],"ltp":3.25,"tv":13592.13,"id":8858694}]}]}
{"op":"mcm","clk":"11889897961","pt":1724176154993,"mc":[{"id":"1.232048439","rc":[{"batb":[[0,3.15,4]],"ltp":3.25,"tv":13592.13,"id":8858694}]}]}
{"op":"mcm","clk":"11889898259","pt":1724176157391,"mc":[{"id":"1.232048439","rc":[{"batb":[[0,3.1,17.95],[1,1.51,25.03],[2,1.11,18.8]],"ltp":3.25,"tv":13592.13,"id":8858694}]}]}
{"op":"mcm","clk":"11889898345","pt":1724176157861,"mc":[{"id":"1.232048439","rc":[{"batb":[[0,3.15,10],[1,3.1,17.95],[2,1.51,25.03]],"ltp":3.25,"tv":13592.13,"id":8858694}]}]}
{"op":"mcm","clk":"11889898513","pt":1724176159059,"mc":[{"id":"1.232048439","rc":[{"batb":[[0,3.15,14]],"ltp":3.25,"tv":13592.13,"id":8858694}]}]}
{"op":"mcm","clk":"11889898687","pt":1724176160565,"mc":[{"id":"1.232048439","rc":[{"batb":[[0,3.2,4],[1,3.15,14],[2,3.1,17.95]],"ltp":3.25,"tv":13592.13,"id":8858694}]}]}
{"op":"mcm","clk":"11889898797","pt":1724176161492,"mc":[{"id":"1.232048439","rc":[{"batb":[[1,3.15,4]],"ltp":3.25,"tv":13592.13,"id":8858694}]}]}
{"op":"mcm","clk":"11889898973","pt":1724176162889,"mc":[{"id":"1.232048439","rc":[{"batb":[[0,3.15,4],[1,3.1,17.95],[2,1.51,25.03]],"ltp":3.25,"tv":13592.13,"id":8858694}]}]}
{"op":"mcm","clk":"11889899345","pt":1724176166282,"mc":[{"id":"1.232048439","rc":[{"batb":[[0,3.2,14],[1,3.15,11.5],[2,3.1,17.95]],"ltp":3.25,"tv":13592.13,"id":8858694}]}]}
{"op":"mcm","clk":"11889899533","pt":1724176168196,"mc":[{"id":"1.232048439","rc":[{"batl":[[0,1.45,5.13],[1,1.46,4],[2,1.47,18]],"ltp":1.41,"tv":89.33,"id":247649}]}]}
{"op":"mcm","clk":"11889899566","pt":1724176168460,"mc":[{"id":"1.232048439","rc":[{"batb":[[0,3.2,10]],"ltp":3.25,"tv":13592.13,"id":8858694}]}]}
{"op":"mcm","clk":"11889899714","pt":1724176169602,"mc":[{"id":"1.232048439","rc":[{"batb":[[0,3.15,11.5],[1,3.1,17.95],[2,1.51,25.03]],"ltp":3.25,"tv":13592.13,"id":8858694}]}]}
{"op":"mcm","clk":"11889899871","pt":1724176170959,"mc":[{"id":"1.232048439","rc":[{"batl":[[0,1.46,9.09],[1,1.47,18],[2,1.5,5.1]],"ltp":1.41,"tv":89.33,"id":247649},{"batb":[[0,3.2,4],[1,3.15,11.5],[2,3.1,17.95]],"ltp":3.25,"tv":13592.13,"id":8858694}]}]}
{"op":"mcm","clk":"11889900148","pt":1724176173306,"mc":[{"id":"1.232048439","rc":[{"batb":[[0,3.15,11.5],[1,3.1,17.95],[2,1.51,25.03]],"ltp":3.25,"tv":13592.13,"id":8858694}]}]}
{"op":"mcm","clk":"11889900190","pt":1724176173670,"mc":[{"id":"1.232048439","rc":[{"batb":[[0,3.2,10],[1,3.15,11.5],[2,3.1,17.95]],"ltp":3.25,"tv":13592.13,"id":8858694}]}]}
{"op":"mcm","clk":"11889900587","pt":1724176176888,"mc":[{"id":"1.232048439","rc":[{"batb":[[0,3.25,4]],"ltp":3.25,"tv":13592.13,"id":8858694}]}]}
{"op":"mcm","clk":"11889900855","pt":1724176179078,"mc":[{"id":"1.232048439","rc":[{"batb":[[0,3.15,11.5],[1,3.1,17.95],[2,1.51,25.03]],"ltp":3.25,"tv":13592.13,"id":8858694}]}]}
{"op":"mcm","clk":"11889900896","pt":1724176179490,"mc":[{"id":"1.232048439","rc":[{"batb":[[0,3.2,10],[1,3.15,11.5],[2,3.1,17.95]],"ltp":3.25,"tv":13592.13,"id":8858694}]}]}
{"op":"mcm","clk":"11889901280","pt":1724176182882,"mc":[{"id":"1.232048439","rc":[{"batb":[[0,3.25,4]],"ltp":3.25,"tv":13592.13,"id":8858694}]}]}
{"op":"mcm","clk":"11889901680","pt":1724176186223,"mc":[{"id":"1.232048439","rc":[{"batb":[[0,3.2,10]],"ltp":3.25,"tv":13592.13,"id":8858694}]}]}
{"op":"mcm","clk":"11889902035","pt":1724176189302,"mc":[{"id":"1.232048439","rc":[{"batb":[[0,3.2,14]],"ltp":3.25,"tv":13592.13,"id":8858694}]}]}
{"op":"mcm","clk":"11889902158","pt":1724176190401,"mc":[{"id":"1.232048439","rc":[{"batb":[[0,3.25,4],[1,3.15,7.5]],"ltp":3.25,"tv":13592.13,"id":8858694}]}]}
{"op":"mcm","clk":"11889902330","pt":1724176191898,"mc":[{"id":"1.232048439","rc":[{"batb":[[0,3.15,7.5],[1,3.1,17.95],[2,1.51,25.03]],"ltp":3.25,"tv":13592.13,"id":8858694}]}]}
{"op":"mcm","clk":"11889902397","pt":1724176192519,"mc":[{"id":"1.232048439","rc":[{"batb":[[0,3.2,10],[1,3.15,7.5],[2,3.1,17.95]],"ltp":3.25,"tv":13592.13,"id":8858694}]}]}
{"op":"mcm","clk":"11889902820","pt":1724176196023,"mc":[{"id":"1.232048439","rc":[{"batb":[[0,3.25,4]],"ltp":3.25,"tv":13592.13,"id":8858694}]}]}
{"op":"mcm","clk":"11889903003","pt":1724176197908,"mc":[{"id":"1.232048439","rc":[{"batb":[[0,3.15,7.5],[1,3.1,17.95],[2,1.51,25.03]],"ltp":3.25,"tv":13592.13,"id":8858694}]}]}
{"op":"mcm","clk":"11889903070","pt":1724176198529,"mc":[{"id":"1.232048439","rc":[{"batb":[[0,3.2,10],[1,3.15,7.5],[2,3.1,17.95]],"ltp":3.25,"tv":13592.13,"id":8858694}]}]}
{"op":"mcm","clk":"11889903816","pt":1724176204517,"mc":[{"id":"1.232048439","rc":[{"batb":[[0,3.2,14]],"ltp":3.25,"tv":13592.13,"id":8858694}]}]}
{"op":"mcm","clk":"11889904015","pt":1724176206435,"mc":[{"id":"1.232048439","rc":[{"batb":[[0,3.25,4]],"ltp":3.25,"tv":13592.13,"id":8858694}]}]}
{"op":"mcm","clk":"11889904430","pt":1724176209617,"mc":[{"id":"1.232048439","rc":[{"batb":[[0,3.15,7.5],[1,3.1,17.95],[2,1.51,25.03]],"ltp":3.25,"tv":13592.13,"id":8858694}]}]}
{"op":"mcm","clk":"11889904894","pt":1724176213123,"mc":[{"id":"1.232048439","rc":[{"batb":[[0,3.3,4],[1,3.15,7.5],[2,3.1,17.95]],"ltp":3.25,"tv":13592.13,"id":8858694}]}]}
{"op":"mcm","clk":"11889905092","pt":1724176214643,"mc":[{"id":"1.232048439","rc":[{"batb":[[1,3.2,10],[2,3.15,7.5]],"ltp":3.25,"tv":13592.13,"id":8858694}]}]}
{"op":"mcm","clk":"11889905732","pt":1724176219766,"mc":[{"id":"1.232048439","rc":[{"batl":[[0,1.44,4],[1,1.46,9.09],[2,1.47,18]],"ltp":1.41,"tv":89.33,"id":247649}]}]}
{"op":"mcm","clk":"11889906015","pt":1724176222055,"mc":[{"id":"1.232048439","rc":[{"batl":[[0,1.46,9.09],[1,1.47,18],[2,1.5,5.1]],"ltp":1.41,"tv":89.33,"id":247649},{"batb":[[0,3.2,10],[1,3.15,7.5],[2,3.1,17.95]],"ltp":3.25,"tv":13592.13,"id":8858694}]}]}
{"op":"mcm","clk":"11889906255","pt":1724176224140,"mc":[{"id":"1.232048439","rc":[{"batb":[[0,3.35,4]],"ltp":3.25,"tv":13592.13,"id":8858694}]}]}
{"op":"mcm","clk":"11889906819","pt":1724176229169,"mc":[{"id":"1.232048439","rc":[{"batb":[[0,3.15,7.5],[1,3.1,17.95],[2,1.51,25.03]],"ltp":3.25,"tv":13592.13,"id":8858694}]}]}
{"op":"mcm","clk":"11889906962","pt":1724176230326,"mc":[{"id":"1.232048439","rc":[{"batb":[[0,3.2,10],[1,3.15,7.5],[2,3.1,17.95]],"ltp":3.25,"tv":13592.13,"id":8858694}]}]}
{"op":"mcm","clk":"11889907144","pt":1724176231632,"mc":[{"id":"1.232048439","rc":[{"batb":[[0,3.25,4],[1,3.2,10],[2,3.15,7.5]],"ltp":3.25,"tv":13592.13,"id":8858694}]}]}
{"op":"mcm","clk":"11889907487","pt":1724176234858,"mc":[{"id":"1.232048439","rc":[{"batl":[[0,1.45,4],[1,1.46,9.09],[2,1.47,18]],"ltp":1.41,"tv":89.33,"id":247649},{"batb":[[0,3.15,7.5],[1,3.1,17.95],[2,1.51,25.03]],"ltp":3.25,"tv":13592.13,"id":8858694}]}]}
{"op":"mcm","clk":"11889908017","pt":1724176239975,"mc":[{"id":"1.232048439","rc":[{"batl":[[0,1.46,5.09],[1,1.47,14],[2,1.5,5.1]],"ltp":1.41,"tv":89.33,"id":247649},{"batb":[[0,3.2,14],[1,3.15,7.5],[2,3.1,17.95]],"batl":[[0,3.4,42.22],[1,3.45,4]],"ltp":3.25,"tv":13592.13,"id":8858694}]}]}
{"op":"mcm","clk":"11889908269","pt":1724176242372,"mc":[{"id":"1.232048439","rc":[{"batb":[[0,3.2,10]],"ltp":3.25,"tv":13592.13,"id":8858694}]}]}
{"op":"mcm","clk":"11889908377","pt":1724176243258,"mc":[{"id":"1.232048439","rc":[{"batb":[[0,3.15,7.5],[1,3.1,17.95],[2,1.51,25.03]],"ltp":3.25,"tv":13592.13,"id":8858694}]}]}
{"op":"mcm","clk":"11889908662","pt":1724176245863,"mc":[{"id":"1.232048439","rc":[{"batb":[[0,3.2,14],[1,3.15,7.5],[2,3.1,17.95]],"ltp":3.25,"tv":13592.13,"id":8858694}]}]}
{"op":"mcm","clk":"11889908961","pt":1724176248487,"mc":[{"id":"1.232048439","rc":[{"batb":[[0,3.2,10]],"ltp":3.25,"tv":13592.13,"id":8858694}]}]}
{"op":"mcm","clk":"11889909153","pt":1724176250070,"mc":[{"id":"1.232048439","rc":[{"batl":[[0,1.46,9.09]],"ltp":1.41,"tv":89.33,"id":247649},{"batb":[[0,3.15,11.5],[1,3.1,17.95],[2,1.51,25.03]],"batl":[[0,3.4,46.22]],"ltp":3.25,"tv":13592.13,"id":8858694}]}]}
{"op":"mcm","clk":"11889909289","pt":1724176251380,"mc":[{"id":"1.232048439","rc":[{"batb":[[0,3.2,4],[1,3.15,11.5],[2,3.1,17.95]],"batl":[[0,3.4,4]],"ltp":3.25,"tv":13592.13,"id":8858694}]}]}
{"op":"mcm","clk":"11889909586","pt":1724176253764,"mc":[{"id":"1.232048439","rc":[{"batb":[[0,3.2,10]],"ltp":3.25,"tv":13592.13,"id":8858694}]}]}
{"op":"mcm","clk":"11889909933","pt":1724176257188,"mc":[{"id":"1.232048439","rc":[{"batb":[[0,3.25,4]],"ltp":3.25,"tv":13592.13,"id":8858694}]}]}
{"op":"mcm","clk":"11889910365","pt":1724176260379,"mc":[{"id":"1.232048439","rc":[{"batb":[[0,3.2,10]],"ltp":3.25,"tv":13592.13,"id":8858694}]}]}
{"op":"mcm","clk":"11889910944","pt":1724176264297,"mc":[{"id":"1.232048439","rc":[{"batb":[[0,3.2,4]],"ltp":3.25,"tv":13592.13,"id":8858694}]}]}
{"op":"mcm","clk":"11889911054","pt":1724176265143,"mc":[{"id":"1.232048439","rc":[{"batb":[[0,3.2,8]],"ltp":3.25,"tv":13592.13,"id":8858694}]}]}
{"op":"mcm","clk":"11889911234","pt":1724176266588,"mc":[{"id":"1.232048439","rc":[{"batb":[[0,3.2,4]],"ltp":3.25,"tv":13592.13,"id":8858694}]}]}
{"op":"mcm","clk":"11889911699","pt":1724176270307,"mc":[{"id":"1.232048439","rc":[{"batb":[[0,3.25,4],[1,3.2,4],[2,3.15,11.5]],"ltp":3.25,"tv":13592.13,"id":8858694}]}]}
{"op":"mcm","clk":"11889911973","pt":1724176272691,"mc":[{"id":"1.232048439","rc":[{"batb":[[0,3.2,4],[1,3.15,11.5],[2,3.1,17.95]],"ltp":3.25,"tv":13592.13,"id":8858694}]}]}
{"op":"mcm","clk":"11889912282","pt":1724176274976,"mc":[{"id":"1.232048439","rc":[{"batb":[[0,3.25,4],[1,3.2,4],[2,3.15,11.5]],"ltp":3.25,"tv":13592.13,"id":8858694}]}]}
{"op":"mcm","clk":"11889912622","pt":1724176277699,"mc":[{"id":"1.232048439","rc":[{"batb":[[0,3.2,4],[1,3.15,11.5],[2,3.1,17.95]],"ltp":3.25,"tv":13592.13,"id":8858694}]}]}
{"op":"mcm","clk":"11889913031","pt":1724176280879,"mc":[{"id":"1.232048439","rc":[{"batb":[[0,3.25,4],[1,3.2,4],[2,3.15,11.5]],"ltp":3.25,"tv":13592.13,"id":8858694}]}]}
{"op":"mcm","clk":"11889913416","pt":1724176283902,"mc":[{"id":"1.232048439","rc":[{"batb":[[0,3.2,4],[1,3.15,11.5],[2,3.1,17.95]],"ltp":3.25,"tv":13592.13,"id":8858694}]}]}
{"op":"mcm","clk":"11889913786","pt":1724176287080,"mc":[{"id":"1.232048439","rc":[{"batb":[[0,3.25,4],[1,3.2,4],[2,3.15,11.5]],"ltp":3.25,"tv":13592.13,"id":8858694}]}]}
{"op":"mcm","clk":"11889914035","pt":1724176289422,"mc":[{"id":"1.232048439","rc":[{"batb":[[0,3.2,4],[1,3.15,11.5],[2,3.1,17.95]],"ltp":3.25,"tv":13592.13,"id":8858694}]}]}
{"op":"mcm","clk":"11889914440","pt":1724176292819,"mc":[{"id":"1.232048439","rc":[{"batb":[[0,3.25,4],[1,3.2,4],[2,3.15,11.5]],"ltp":3.25,"tv":13592.13,"id":8858694}]}]}
{"op":"mcm","clk":"11889914746","pt":1724176295199,"mc":[{"id":"1.232048439","rc":[{"batb":[[0,3.2,4],[1,3.15,11.5],[2,3.1,17.95]],"ltp":3.25,"tv":13592.13,"id":8858694}]}]}
{"op":"mcm","clk":"11889914786","pt":1724176295509,"mc":[{"id":"1.232048439","rc":[{"batl":[[0,1.45,4],[1,1.46,9.09],[2,1.47,14]],"ltp":1.41,"tv":89.33,"id":247649}]}]}
{"op":"mcm","clk":"11889915206","pt":1724176299292,"mc":[{"id":"1.232048439","rc":[{"batb":[[0,3.25,4],[1,3.2,4],[2,3.15,11.5]],"ltp":3.25,"tv":13592.13,"id":8858694}]}]}
{"op":"mcm","clk":"11889915519","pt":1724176301930,"mc":[{"id":"1.232048439","rc":[{"batb":[[0,3.2,4],[1,3.15,11.5],[2,3.1,17.95]],"ltp":3.25,"tv":13592.13,"id":8858694}]}]}
{"op":"mcm","clk":"11889915880","pt":1724176304516,"mc":[{"id":"1.232048439","rc":[{"batb":[[0,3.25,4],[1,3.2,4],[2,3.15,11.5]],"ltp":3.25,"tv":13592.13,"id":8858694}]}]}
{"op":"mcm","clk":"11889916168","pt":1724176307007,"mc":[{"id":"1.232048439","rc":[{"batb":[[0,3.2,4],[1,3.15,11.5],[2,3.1,17.95]],"ltp":3.25,"tv":13592.13,"id":8858694}]}]}
{"op":"mcm","clk":"11889916791","pt":1724176312332,"mc":[{"id":"1.232048439","rc":[{"batb":[[0,3.25,4],[1,3.2,4],[2,3.15,11.5]],"ltp":3.25,"tv":13592.13,"id":8858694}]}]}
{"op":"mcm","clk":"11889917077","pt":1724176314823,"mc":[{"id":"1.232048439","rc":[{"batb":[[0,3.2,4],[1,3.15,11.5],[2,3.1,17.95]],"ltp":3.25,"tv":13592.13,"id":8858694}]}]}
{"op":"mcm","clk":"11889917443","pt":1724176318040,"mc":[{"id":"1.232048439","rc":[{"batb":[[0,3.25,4],[1,3.2,4],[2,3.15,11.5]],"ltp":3.25,"tv":13592.13,"id":8858694}]}]}
{"op":"mcm","clk":"11889917763","pt":1724176320635,"mc":[{"id":"1.232048439","rc":[{"batb":[[0,3.2,4],[1,3.15,11.5],[2,3.1,17.95]],"ltp":3.25,"tv":13592.13,"id":8858694}]}]}
{"op":"mcm","clk":"11889918206","pt":1724176323830,"mc":[{"id":"1.232048439","rc":[{"batb":[[0,3.25,4],[1,3.2,4],[2,3.15,11.5]],"ltp":3.25,"tv":13592.13,"id":8858694}]}]}
{"op":"mcm","clk":"11889918556","pt":1724176326630,"mc":[{"id":"1.232048439","rc":[{"batb":[[0,3.2,4],[1,3.15,11.5],[2,3.1,17.95]],"ltp":3.25,"tv":13592.13,"id":8858694}]}]}
{"op":"mcm","clk":"11889918827","pt":1724176328959,"mc":[{"id":"1.232048439","rc":[{"batb":[[0,3.25,4],[1,3.2,4],[2,3.15,11.5]],"ltp":3.25,"tv":13592.13,"id":8858694}]}]}
{"op":"mcm","clk":"11889919113","pt":1724176331357,"mc":[{"id":"1.232048439","rc":[{"batb":[[0,3.2,4],[1,3.15,11.5],[2,3.1,17.95]],"ltp":3.25,"tv":13592.13,"id":8858694}]}]}
{"op":"mcm","clk":"11889919427","pt":1724176334153,"mc":[{"id":"1.232048439","rc":[{"batb":[[0,3.25,4],[1,3.2,4],[2,3.15,11.5]],"ltp":3.25,"tv":13592.13,"id":8858694}]}]}
{"op":"mcm","clk":"11889919750","pt":1724176336741,"mc":[{"id":"1.232048439","rc":[{"batb":[[0,3.2,4],[1,3.15,11.5],[2,3.1,17.95]],"ltp":3.25,"tv":13592.13,"id":8858694}]}]}
{"op":"mcm","clk":"11889920213","pt":1724176340586,"mc":[{"id":"1.232048439","rc":[{"batb":[[0,3.25,4],[1,3.2,4],[2,3.15,11.5]],"ltp":3.25,"tv":13592.13,"id":8858694}]}]}
{"op":"mcm","clk":"11889920457","pt":1724176342870,"mc":[{"id":"1.232048439","rc":[{"batb":[[0,3.2,4],[1,3.15,11.5],[2,3.1,17.95]],"ltp":3.25,"tv":13592.13,"id":8858694}]}]}
{"op":"mcm","clk":"11889920892","pt":1724176346648,"mc":[{"id":"1.232048439","rc":[{"batb":[[0,3.25,4],[1,3.2,4],[2,3.15,11.5]],"ltp":3.25,"tv":13592.13,"id":8858694}]}]}
{"op":"mcm","clk":"11889921146","pt":1724176349060,"mc":[{"id":"1.232048439","rc":[{"batb":[[0,3.2,4],[1,3.15,11.5],[2,3.1,17.95]],"ltp":3.25,"tv":13592.13,"id":8858694}]}]}
{"op":"mcm","clk":"11889921500","pt":1724176351892,"mc":[{"id":"1.232048439","rc":[{"batb":[[0,3.25,4],[1,3.2,4],[2,3.15,11.5]],"ltp":3.25,"tv":13592.13,"id":8858694}]}]}
{"op":"mcm","clk":"11889921798","pt":1724176354558,"mc":[{"id":"1.232048439","rc":[{"batb":[[0,3.2,4],[1,3.15,11.5],[2,3.1,17.95]],"ltp":3.25,"tv":13592.13,"id":8858694}]}]}
{"op":"mcm","clk":"11889922321","pt":1724176359581,"mc":[{"id":"1.232048439","rc":[{"batb":[[0,3.25,4],[1,3.2,4],[2,3.15,11.5]],"ltp":3.25,"tv":13592.13,"id":8858694}]}]}
{"op":"mcm","clk":"11889922561","pt":1724176362177,"mc":[{"id":"1.232048439","rc":[{"batb":[[0,3.2,4],[1,3.15,11.5],[2,3.1,17.95]],"ltp":3.25,"tv":13592.13,"id":8858694}]}]}
{"op":"mcm","clk":"11889922886","pt":1724176364785,"mc":[{"id":"1.232048439","rc":[{"batb":[[0,3.25,4],[1,3.2,4],[2,3.15,11.5]],"ltp":3.25,"tv":13592.13,"id":8858694}]}]}
{"op":"mcm","clk":"11889923220","pt":1724176367586,"mc":[{"id":"1.232048439","rc":[{"batb":[[0,3.2,4],[1,3.15,11.5],[2,3.1,17.95]],"ltp":3.25,"tv":13592.13,"id":8858694}]}]}
{"op":"mcm","clk":"11889923703","pt":1724176370772,"mc":[{"id":"1.232048439","rc":[{"batb":[[0,3.25,4],[1,3.2,4],[2,3.15,11.5]],"ltp":3.25,"tv":13592.13,"id":8858694}]}]}
{"op":"mcm","clk":"11889924040","pt":1724176373406,"mc":[{"id":"1.232048439","rc":[{"batb":[[0,3.2,4],[1,3.15,11.5],[2,3.1,17.95]],"ltp":3.25,"tv":13592.13,"id":8858694}]}]}
{"op":"mcm","clk":"11889924370","pt":1724176376100,"mc":[{"id":"1.232048439","rc":[{"batb":[[0,3.25,4],[1,3.2,4],[2,3.15,11.5]],"ltp":3.25,"tv":13592.13,"id":8858694}]}]}
{"op":"mcm","clk":"11889924687","pt":1724176379116,"mc":[{"id":"1.232048439","rc":[{"batb":[[0,3.2,4],[1,3.15,11.5],[2,3.1,17.95]],"ltp":3.25,"tv":13592.13,"id":8858694}]}]}
{"op":"mcm","clk":"11889924963","pt":1724176381402,"mc":[{"id":"1.232048439","rc":[{"batb":[[0,3.25,4],[1,3.2,4],[2,3.15,11.5]],"ltp":3.25,"tv":13592.13,"id":8858694}]}]}
{"op":"mcm","clk":"11889925315","pt":1724176384310,"mc":[{"id":"1.232048439","rc":[{"batb":[[0,3.2,4],[1,3.15,11.5],[2,3.1,17.95]],"ltp":3.25,"tv":13592.13,"id":8858694}]}]}
{"op":"mcm","clk":"11889925721","pt":1724176387984,"mc":[{"id":"1.232048439","rc":[{"batb":[[0,3.25,4],[1,3.2,4],[2,3.15,11.5]],"ltp":3.25,"tv":13592.13,"id":8858694}]}]}
{"op":"mcm","clk":"11889926064","pt":1724176390719,"mc":[{"id":"1.232048439","rc":[{"batb":[[0,3.2,4],[1,3.15,11.5],[2,3.1,17.95]],"ltp":3.25,"tv":13592.13,"id":8858694}]}]}
{"op":"mcm","clk":"11889926488","pt":1724176394318,"mc":[{"id":"1.232048439","rc":[{"batb":[[0,3.25,4],[1,3.2,4],[2,3.15,11.5]],"ltp":3.25,"tv":13592.13,"id":8858694}]}]}
{"op":"mcm","clk":"11889926843","pt":1724176397112,"mc":[{"id":"1.232048439","rc":[{"batb":[[0,3.2,4],[1,3.15,11.5],[2,3.1,17.95]],"ltp":3.25,"tv":13592.13,"id":8858694}]}]}
{"op":"mcm","clk":"11889927316","pt":1724176400737,"mc":[{"id":"1.232048439","rc":[{"batb":[[0,3.25,4],[1,3.2,4],[2,3.15,11.5]],"ltp":3.25,"tv":13592.13,"id":8858694}]}]}
{"op":"mcm","clk":"11889927648","pt":1724176403535,"mc":[{"id":"1.232048439","rc":[{"batb":[[0,3.2,4],[1,3.15,11.5],[2,3.1,17.95]],"ltp":3.25,"tv":13592.13,"id":8858694}]}]}
{"op":"mcm","clk":"11889928082","pt":1724176407151,"mc":[{"id":"1.232048439","rc":[{"batb":[[0,3.25,4],[1,3.2,4],[2,3.15,11.5]],"ltp":3.25,"tv":13592.13,"id":8858694}]}]}
{"op":"mcm","clk":"11889928505","pt":1724176409834,"mc":[{"id":"1.232048439","rc":[{"batb":[[0,3.2,4],[1,3.15,11.5],[2,3.1,17.95]],"ltp":3.25,"tv":13592.13,"id":8858694}]}]}
{"op":"mcm","clk":"11889928966","pt":1724176413424,"mc":[{"id":"1.232048439","rc":[{"batb":[[0,3.25,4],[1,3.2,4],[2,3.15,11.5]],"ltp":3.25,"tv":13592.13,"id":8858694}]}]}
{"op":"mcm","clk":"11889929295","pt":1724176416032,"mc":[{"id":"1.232048439","rc":[{"batb":[[0,3.2,4],[1,3.15,11.5],[2,3.1,17.95]],"ltp":3.25,"tv":13592.13,"id":8858694}]}]}
{"op":"mcm","clk":"11889929820","pt":1724176420140,"mc":[{"id":"1.232048439","rc":[{"batb":[[0,3.25,4],[1,3.2,4],[2,3.15,11.5]],"ltp":3.25,"tv":13592.13,"id":8858694}]}]}
{"op":"mcm","clk":"11889930124","pt":1724176422543,"mc":[{"id":"1.232048439","rc":[{"batb":[[0,3.2,4],[1,3.15,11.5],[2,3.1,17.95]],"ltp":3.25,"tv":13592.13,"id":8858694}]}]}
{"op":"mcm","clk":"11889930803","pt":1724176427554,"mc":[{"id":"1.232048439","rc":[{"batb":[[0,3.25,4],[1,3.2,4],[2,3.15,11.5]],"ltp":3.25,"tv":13592.13,"id":8858694}]}]}
{"op":"mcm","clk":"11889931132","pt":1724176430257,"mc":[{"id":"1.232048439","rc":[{"batb":[[0,3.2,4],[1,3.15,11.5],[2,3.1,17.95]],"ltp":3.25,"tv":13592.13,"id":8858694}]}]}
{"op":"mcm","clk":"11889931601","pt":1724176433648,"mc":[{"id":"1.232048439","rc":[{"batb":[[0,3.25,4],[1,3.2,4],[2,3.15,11.5]],"ltp":3.25,"tv":13592.13,"id":8858694}]}]}
{"op":"mcm","clk":"11889931926","pt":1724176436189,"mc":[{"id":"1.232048439","rc":[{"batb":[[0,3.2,4],[1,3.15,11.5],[2,3.1,17.95]],"ltp":3.25,"tv":13592.13,"id":8858694}]}]}
{"op":"mcm","clk":"11889932386","pt":1724176439782,"mc":[{"id":"1.232048439","rc":[{"batb":[[0,3.25,4],[1,3.2,4],[2,3.15,11.5]],"ltp":3.25,"tv":13592.13,"id":8858694}]}]}
{"op":"mcm","clk":"11889932756","pt":1724176442381,"mc":[{"id":"1.232048439","rc":[{"batb":[[0,3.2,4],[1,3.15,11.5],[2,3.1,17.95]],"ltp":3.25,"tv":13592.13,"id":8858694}]}]}
{"op":"mcm","clk":"11889933206","pt":1724176445769,"mc":[{"id":"1.232048439","rc":[{"batb":[[0,3.25,4],[1,3.2,4],[2,3.15,11.5]],"ltp":3.25,"tv":13592.13,"id":8858694}]}]}
{"op":"mcm","clk":"11889933542","pt":1724176448374,"mc":[{"id":"1.232048439","rc":[{"batb":[[0,3.2,4],[1,3.15,11.5],[2,3.1,17.95]],"ltp":3.25,"tv":13592.13,"id":8858694}]}]}
{"op":"mcm","clk":"11889933905","pt":1724176450872,"mc":[{"id":"1.232048439","rc":[{"batb":[[0,3.25,4],[1,3.2,4],[2,3.15,11.5]],"ltp":3.25,"tv":13592.13,"id":8858694}]}]}
{"op":"mcm","clk":"11889934182","pt":1724176453191,"mc":[{"id":"1.232048439","rc":[{"batb":[[0,3.2,4],[1,3.15,11.5],[2,3.1,17.95]],"ltp":3.25,"tv":13592.13,"id":8858694}]}]}
{"op":"mcm","clk":"11889934666","pt":1724176456986,"mc":[{"id":"1.232048439","rc":[{"batb":[[0,3.25,4],[1,3.2,4],[2,3.15,11.5]],"ltp":3.25,"tv":13592.13,"id":8858694}]}]}
{"op":"mcm","clk":"11889934952","pt":1724176459267,"mc":[{"id":"1.232048439","rc":[{"batb":[[0,3.2,4],[1,3.15,11.5],[2,3.1,17.95]],"ltp":3.25,"tv":13592.13,"id":8858694}]}]}
{"op":"mcm","clk":"11889935410","pt":1724176463123,"mc":[{"id":"1.232048439","rc":[{"batb":[[0,3.25,4],[1,3.2,4],[2,3.15,11.5]],"ltp":3.25,"tv":13592.13,"id":8858694}]}]}
{"op":"mcm","clk":"11889935742","pt":1724176465563,"mc":[{"id":"1.232048439","rc":[{"batb":[[0,3.2,4],[1,3.15,11.5],[2,3.1,17.95]],"ltp":3.25,"tv":13592.13,"id":8858694}]}]}
{"op":"mcm","clk":"11889936203","pt":1724176469498,"mc":[{"id":"1.232048439","rc":[{"batb":[[0,3.25,4],[1,3.2,4],[2,3.15,11.5]],"ltp":3.25,"tv":13592.13,"id":8858694}]}]}
{"op":"mcm","clk":"11889936507","pt":1724176471997,"mc":[{"id":"1.232048439","rc":[{"batb":[[0,3.2,4],[1,3.15,11.5],[2,3.1,17.95]],"ltp":3.25,"tv":13592.13,"id":8858694}]}]}
{"op":"mcm","clk":"11889936977","pt":1724176475418,"mc":[{"id":"1.232048439","rc":[{"batb":[[0,3.25,4],[1,3.2,4],[2,3.15,11.5]],"ltp":3.25,"tv":13592.13,"id":8858694}]}]}
{"op":"mcm","clk":"11889937345","pt":1724176478076,"mc":[{"id":"1.232048439","rc":[{"batb":[[0,3.2,4],[1,3.15,11.5],[2,3.1,17.95]],"ltp":3.25,"tv":13592.13,"id":8858694}]}]}
{"op":"mcm","clk":"11889937842","pt":1724176481881,"mc":[{"id":"1.232048439","rc":[{"batb":[[0,3.25,4],[1,3.2,4],[2,3.15,11.5]],"ltp":3.25,"tv":13592.13,"id":8858694}]}]}
{"op":"mcm","clk":"11889938206","pt":1724176484634,"mc":[{"id":"1.232048439","rc":[{"batb":[[0,3.2,4],[1,3.15,11.5],[2,3.1,17.95]],"ltp":3.25,"tv":13592.13,"id":8858694}]}]}
{"op":"mcm","clk":"11889938628","pt":1724176487495,"mc":[{"id":"1.232048439","rc":[{"batb":[[0,3.25,4],[1,3.2,4],[2,3.15,11.5]],"ltp":3.25,"tv":13592.13,"id":8858694}]}]}
{"op":"mcm","clk":"11889938952","pt":1724176490091,"mc":[{"id":"1.232048439","rc":[{"batb":[[0,3.2,4],[1,3.15,11.5],[2,3.1,17.95]],"ltp":3.25,"tv":13592.13,"id":8858694}]}]}
{"op":"mcm","clk":"11889939727","pt":1724176496501,"mc":[{"id":"1.232048439","rc":[{"batb":[[0,3.25,4],[1,3.2,4],[2,3.15,11.5]],"ltp":3.25,"tv":13592.13,"id":8858694}]}]}
{"op":"mcm","clk":"11889940056","pt":1724176499142,"mc":[{"id":"1.232048439","rc":[{"batb":[[0,3.2,4],[1,3.15,11.5],[2,3.1,17.95]],"ltp":3.25,"tv":13592.13,"id":8858694}]}]}
{"op":"mcm","clk":"11889940550","pt":1724176502814,"mc":[{"id":"1.232048439","rc":[{"batb":[[0,3.25,4],[1,3.2,4],[2,3.15,11.5]],"ltp":3.25,"tv":13592.13,"id":8858694}]}]}
{"op":"mcm","clk":"11889940901","pt":1724176505411,"mc":[{"id":"1.232048439","rc":[{"batb":[[0,3.2,4],[1,3.15,11.5],[2,3.1,17.95]],"ltp":3.25,"tv":13592.13,"id":8858694}]}]}
{"op":"mcm","clk":"11889941405","pt":1724176509437,"mc":[{"id":"1.232048439","rc":[{"batb":[[0,3.25,4],[1,3.2,4],[2,3.15,11.5]],"ltp":3.25,"tv":13592.13,"id":8858694}]}]}
{"op":"mcm","clk":"11889941746","pt":1724176512243,"mc":[{"id":"1.232048439","rc":[{"batb":[[0,3.2,4],[1,3.15,11.5],[2,3.1,17.95]],"ltp":3.25,"tv":13592.13,"id":8858694}]}]}
{"op":"mcm","clk":"11889942173","pt":1724176515524,"mc":[{"id":"1.232048439","rc":[{"batb":[[0,3.25,4],[1,3.2,4],[2,3.15,11.5]],"ltp":3.25,"tv":13592.13,"id":8858694}]}]}
{"op":"mcm","clk":"11889942480","pt":1724176517820,"mc":[{"id":"1.232048439","rc":[{"batb":[[0,3.2,4],[1,3.15,11.5],[2,3.1,17.95]],"ltp":3.25,"tv":13592.13,"id":8858694}]}]}
{"op":"mcm","clk":"11889942735","pt":1724176520062,"mc":[{"id":"1.232048439","rc":[{"batb":[[0,3.25,4],[1,3.2,4],[2,3.15,11.5]],"ltp":3.25,"tv":13592.13,"id":8858694}]}]}
{"op":"mcm","clk":"11889943088","pt":1724176522870,"mc":[{"id":"1.232048439","rc":[{"batb":[[0,3.2,4],[1,3.15,11.5],[2,3.1,17.95]],"ltp":3.25,"tv":13592.13,"id":8858694}]}]}
{"op":"mcm","clk":"11889943383","pt":1724176525474,"mc":[{"id":"1.232048439","rc":[{"batb":[[0,3.25,4],[1,3.2,4],[2,3.15,11.5]],"ltp":3.25,"tv":13592.13,"id":8858694}]}]}
{"op":"mcm","clk":"11889943740","pt":1724176527857,"mc":[{"id":"1.232048439","rc":[{"batb":[[0,3.2,4],[1,3.15,11.5],[2,3.1,17.95]],"ltp":3.25,"tv":13592.13,"id":8858694}]}]}
{"op":"mcm","clk":"11889944229","pt":1724176531562,"mc":[{"id":"1.232048439","rc":[{"batb":[[0,3.25,4],[1,3.2,4],[2,3.15,11.5]],"ltp":3.25,"tv":13592.13,"id":8858694}]}]}
{"op":"mcm","clk":"11889944589","pt":1724176534066,"mc":[{"id":"1.232048439","rc":[{"batb":[[0,3.2,4],[1,3.15,11.5],[2,3.1,17.95]],"ltp":3.25,"tv":13592.13,"id":8858694}]}]}
{"op":"mcm","clk":"11889944976","pt":1724176537071,"mc":[{"id":"1.232048439","rc":[{"batb":[[0,3.25,4],[1,3.2,4],[2,3.15,11.5]],"ltp":3.25,"tv":13592.13,"id":8858694}]}]}
{"op":"mcm","clk":"11889945333","pt":1724176539792,"mc":[{"id":"1.232048439","rc":[{"batb":[[0,3.2,4],[1,3.15,11.5],[2,3.1,17.95]],"ltp":3.25,"tv":13592.13,"id":8858694}]}]}
{"op":"mcm","clk":"11889945751","pt":1724176543273,"mc":[{"id":"1.232048439","rc":[{"batb":[[0,3.25,4],[1,3.2,4],[2,3.15,11.5]],"ltp":3.25,"tv":13592.13,"id":8858694}]}]}
{"op":"mcm","clk":"11889946032","pt":1724176545700,"mc":[{"id":"1.232048439","rc":[{"batb":[[0,3.2,4],[1,3.15,11.5],[2,3.1,17.95]],"ltp":3.25,"tv":13592.13,"id":8858694}]}]}
{"op":"mcm","clk":"11889946746","pt":1724176551170,"mc":[{"id":"1.232048439","rc":[{"batb":[[0,3.25,4],[1,3.2,4],[2,3.15,11.5]],"ltp":3.25,"tv":13592.13,"id":8858694}]}]}
{"op":"mcm","clk":"11889947099","pt":1724176553985,"mc":[{"id":"1.232048439","rc":[{"batb":[[0,3.2,4],[1,3.15,11.5],[2,3.1,17.95]],"ltp":3.25,"tv":13592.13,"id":8858694}]}]}
{"op":"mcm","clk":"11889947619","pt":1724176558356,"mc":[{"id":"1.232048439","rc":[{"batb":[[0,3.25,4],[1,3.2,4],[2,3.15,11.5]],"ltp":3.25,"tv":13592.13,"id":8858694}]}]}
{"op":"mcm","clk":"11889947993","pt":1724176560956,"mc":[{"id":"1.232048439","rc":[{"batb":[[0,3.2,4],[1,3.15,11.5],[2,3.1,17.95]],"ltp":3.25,"tv":13592.13,"id":8858694}]}]}
{"op":"mcm","clk":"11889948519","pt":1724176564274,"mc":[{"id":"1.232048439","rc":[{"batb":[[0,3.25,4],[1,3.2,4],[2,3.15,11.5]],"ltp":3.25,"tv":13592.13,"id":8858694}]}]}
{"op":"mcm","clk":"11889948828","pt":1724176566688,"mc":[{"id":"1.232048439","rc":[{"batb":[[0,3.2,4],[1,3.15,11.5],[2,3.1,17.95]],"ltp":3.25,"tv":13592.13,"id":8858694}]}]}
{"op":"mcm","clk":"11889949249","pt":1724176570058,"mc":[{"id":"1.232048439","rc":[{"batb":[[0,3.25,4],[1,3.2,4],[2,3.15,11.5]],"ltp":3.25,"tv":13592.13,"id":8858694}]}]}
{"op":"mcm","clk":"11889949570","pt":1724176572494,"mc":[{"id":"1.232048439","rc":[{"batb":[[0,3.2,4],[1,3.15,11.5],[2,3.1,17.95]],"ltp":3.25,"tv":13592.13,"id":8858694}]}]}
{"op":"mcm","clk":"11889950251","pt":1724176577781,"mc":[{"id":"1.232048439","rc":[{"batb":[[0,3.25,4],[1,3.2,4],[2,3.15,11.5]],"ltp":3.25,"tv":13592.13,"id":8858694}]}]}
{"op":"mcm","clk":"11889950530","pt":1724176580107,"mc":[{"id":"1.232048439","rc":[{"batb":[[0,3.2,4],[1,3.15,11.5],[2,3.1,17.95]],"ltp":3.25,"tv":13592.13,"id":8858694}]}]}
{"op":"mcm","clk":"11889950958","pt":1724176583283,"mc":[{"id":"1.232048439","rc":[{"batb":[[0,3.25,4],[1,3.2,4],[2,3.15,11.5]],"ltp":3.25,"tv":13592.13,"id":8858694}]}]}
{"op":"mcm","clk":"11889951245","pt":1724176585617,"mc":[{"id":"1.232048439","rc":[{"batb":[[0,3.2,4],[1,3.15,11.5],[2,3.1,17.95]],"ltp":3.25,"tv":13592.13,"id":8858694}]}]}
{"op":"mcm","clk":"11889951600","pt":1724176588731,"mc":[{"id":"1.232048439","rc":[{"batb":[[0,3.25,4],[1,3.2,4],[2,3.15,11.5]],"ltp":3.25,"tv":13592.13,"id":8858694}]}]}
{"op":"mcm","clk":"11889951865","pt":1724176591016,"mc":[{"id":"1.232048439","rc":[{"batb":[[0,3.2,4],[1,3.15,11.5],[2,3.1,17.95]],"ltp":3.25,"tv":13592.13,"id":8858694}]}]}
{"op":"mcm","clk":"11889952196","pt":1724176594233,"mc":[{"id":"1.232048439","rc":[{"batb":[[0,3.25,4],[1,3.2,4],[2,3.15,11.5]],"ltp":3.25,"tv":13592.13,"id":8858694}]}]}
{"op":"mcm","clk":"11889952432","pt":1724176596584,"mc":[{"id":"1.232048439","rc":[{"batb":[[0,3.2,4],[1,3.15,11.5],[2,3.1,17.95]],"ltp":3.25,"tv":13592.13,"id":8858694}]}]}
{"op":"mcm","clk":"11889952692","pt":1724176598912,"mc":[{"id":"1.232048439","rc":[{"batb":[[0,3.25,4],[1,3.2,4],[2,3.15,11.5]],"ltp":3.25,"tv":13592.13,"id":8858694}]}]}
{"op":"mcm","clk":"11889952957","pt":1724176601338,"mc":[{"id":"1.232048439","rc":[{"batb":[[0,1.42,16.76],[1,1.41,95.97],[2,1.11,18.8]],"ltp":1.41,"tv":89.33,"id":247649}]}]}
{"op":"mcm","clk":"11889953000","pt":1724176601709,"mc":[{"id":"1.232048439","rc":[{"batb":[[0,3.2,4],[1,3.15,11.5],[2,3.1,17.95]],"ltp":3.25,"tv":13592.13,"id":8858694}]}]}
{"op":"mcm","clk":"11889953331","pt":1724176604931,"mc":[{"id":"1.232048439","rc":[{"batb":[[0,3.25,4],[1,3.2,4],[2,3.15,11.5]],"ltp":3.25,"tv":13592.13,"id":8858694}]}]}
{"op":"mcm","clk":"11889953631","pt":1724176607637,"mc":[{"id":"1.232048439","rc":[{"batb":[[0,3.2,4],[1,3.15,11.5],[2,3.1,17.95]],"ltp":3.25,"tv":13592.13,"id":8858694}]}]}
{"op":"mcm","clk":"11889953934","pt":1724176610534,"mc":[{"id":"1.232048439","rc":[{"batb":[[0,3.25,4],[1,3.2,4],[2,3.15,11.5]],"ltp":3.25,"tv":13592.13,"id":8858694}]}]}
{"op":"mcm","clk":"11889954212","pt":1724176612920,"mc":[{"id":"1.232048439","rc":[{"batb":[[0,3.2,4],[1,3.15,11.5],[2,3.1,17.95]],"ltp":3.25,"tv":13592.13,"id":8858694}]}]}
{"op":"mcm","clk":"11889954579","pt":1724176615930,"mc":[{"id":"1.232048439","rc":[{"batb":[[0,1.42,20.76]],"ltp":1.41,"tv":89.33,"id":247649},{"batb":[[0,3.25,4],[1,3.2,4],[2,3.15,11.5]],"ltp":3.25,"tv":13592.13,"id":8858694}]}]}
{"op":"mcm","clk":"11889954855","pt":1724176618231,"mc":[{"id":"1.232048439","rc":[{"batb":[[0,3.2,4],[1,3.15,11.5],[2,3.1,17.95]],"ltp":3.25,"tv":13592.13,"id":8858694}]}]}
{"op":"mcm","clk":"11889955416","pt":1724176622418,"mc":[{"id":"1.232048439","rc":[{"batb":[[0,3.25,4],[1,3.2,4],[2,3.15,11.5]],"ltp":3.25,"tv":13592.13,"id":8858694}]}]}
{"op":"mcm","clk":"11889955688","pt":1724176624763,"mc":[{"id":"1.232048439","rc":[{"batb":[[0,3.2,4],[1,3.15,11.5],[2,3.1,17.95]],"ltp":3.25,"tv":13592.13,"id":8858694}]}]}
{"op":"mcm","clk":"11889956053","pt":1724176627536,"mc":[{"id":"1.232048439","rc":[{"batb":[[0,3.25,4],[1,3.2,4],[2,3.15,11.5]],"ltp":3.25,"tv":13592.13,"id":8858694}]}]}
{"op":"mcm","clk":"11889956170","pt":1724176628469,"mc":[{"id":"1.232048439","rc":[{"batb":[[0,1.42,4]],"ltp":1.41,"tv":89.33,"id":247649}]}]}
{"op":"mcm","clk":"11889956353","pt":1724176629921,"mc":[{"id":"1.232048439","rc":[{"batb":[[0,3.2,4],[1,3.15,11.5],[2,3.1,17.95]],"ltp":3.25,"tv":13592.13,"id":8858694}]}]}
{"op":"mcm","clk":"11889957000","pt":1724176635343,"mc":[{"id":"1.232048439","rc":[{"batb":[[0,3.25,4],[1,3.2,4],[2,3.15,11.5]],"ltp":3.25,"tv":13592.13,"id":8858694}]}]}
{"op":"mcm","clk":"11889957343","pt":1724176637971,"mc":[{"id":"1.232048439","rc":[{"batb":[[0,3.2,4],[1,3.15,11.5],[2,3.1,17.95]],"ltp":3.25,"tv":13592.13,"id":8858694}]}]}
{"op":"mcm","clk":"11889957784","pt":1724176641455,"mc":[{"id":"1.232048439","rc":[{"batb":[[0,3.25,4],[1,3.2,4],[2,3.15,11.5]],"ltp":3.25,"tv":13592.13,"id":8858694}]}]}
{"op":"mcm","clk":"11889958090","pt":1724176643744,"mc":[{"id":"1.232048439","rc":[{"batb":[[0,3.2,4],[1,3.15,11.5],[2,3.1,17.95]],"ltp":3.25,"tv":13592.13,"id":8858694}]}]}
{"op":"mcm","clk":"11889958617","pt":1724176648055,"mc":[{"id":"1.232048439","rc":[{"batb":[[0,3.25,4],[1,3.2,4],[2,3.15,11.5]],"ltp":3.25,"tv":13592.13,"id":8858694}]}]}
{"op":"mcm","clk":"11889958943","pt":1724176650885,"mc":[{"id":"1.232048439","rc":[{"batb":[[0,3.2,4],[1,3.15,11.5],[2,3.1,17.95]],"ltp":3.25,"tv":13592.13,"id":8858694}]}]}
{"op":"mcm","clk":"11889959320","pt":1724176653883,"mc":[{"id":"1.232048439","rc":[{"batb":[[0,3.25,4],[1,3.2,4],[2,3.15,11.5]],"ltp":3.25,"tv":13592.13,"id":8858694}]}]}
{"op":"mcm","clk":"11889959692","pt":1724176656660,"mc":[{"id":"1.232048439","rc":[{"batb":[[0,3.2,4],[1,3.15,11.5],[2,3.1,17.95]],"ltp":3.25,"tv":13592.13,"id":8858694}]}]}
{"op":"mcm","clk":"11889960053","pt":1724176659167,"mc":[{"id":"1.232048439","rc":[{"batb":[[0,3.25,4],[1,3.2,4],[2,3.15,11.5]],"ltp":3.25,"tv":13592.13,"id":8858694}]}]}
{"op":"mcm","clk":"11889960363","pt":1724176661469,"mc":[{"id":"1.232048439","rc":[{"batb":[[0,3.2,4],[1,3.15,11.5],[2,3.1,17.95]],"ltp":3.25,"tv":13592.13,"id":8858694}]}]}
{"op":"mcm","clk":"11889960846","pt":1724176664782,"mc":[{"id":"1.232048439","rc":[{"batb":[[0,3.25,4],[1,3.2,4],[2,3.15,11.5]],"ltp":3.25,"tv":13592.13,"id":8858694}]}]}
{"op":"mcm","clk":"11889961211","pt":1724176667590,"mc":[{"id":"1.232048439","rc":[{"batb":[[0,3.2,4],[1,3.15,11.5],[2,3.1,17.95]],"ltp":3.25,"tv":13592.13,"id":8858694}]}]}
{"op":"mcm","clk":"11889961890","pt":1724176672695,"mc":[{"id":"1.232048439","rc":[{"batb":[[0,3.25,4],[1,3.2,4],[2,3.15,11.5]],"ltp":3.25,"tv":13592.13,"id":8858694}]}]}
{"op":"mcm","clk":"11889962266","pt":1724176675592,"mc":[{"id":"1.232048439","rc":[{"batb":[[0,3.2,4],[1,3.15,11.5],[2,3.1,17.95]],"ltp":3.25,"tv":13592.13,"id":8858694}]}]}
{"op":"mcm","clk":"11889962637","pt":1724176678208,"mc":[{"id":"1.232048439","rc":[{"batb":[[0,3.25,4],[1,3.2,4],[2,3.15,11.5]],"ltp":3.25,"tv":13592.13,"id":8858694}]}]}
{"op":"mcm","clk":"11889963062","pt":1724176681090,"mc":[{"id":"1.232048439","rc":[{"batb":[[0,3.2,4],[1,3.15,11.5],[2,3.1,17.95]],"ltp":3.25,"tv":13592.13,"id":8858694}]}]}
{"op":"mcm","clk":"11889963468","pt":1724176684195,"mc":[{"id":"1.232048439","rc":[{"batb":[[0,3.25,4],[1,3.2,4],[2,3.15,11.5]],"ltp":3.25,"tv":13592.13,"id":8858694}]}]}
{"op":"mcm","clk":"11889963851","pt":1724176687094,"mc":[{"id":"1.232048439","rc":[{"batb":[[0,3.2,4],[1,3.15,11.5],[2,3.1,17.95]],"ltp":3.25,"tv":13592.13,"id":8858694}]}]}
{"op":"mcm","clk":"11889964240","pt":1724176689915,"mc":[{"id":"1.232048439","rc":[{"batb":[[0,3.25,4],[1,3.2,4],[2,3.15,11.5]],"ltp":3.25,"tv":13592.13,"id":8858694}]}]}
{"op":"mcm","clk":"11889964545","pt":1724176692326,"mc":[{"id":"1.232048439","rc":[{"batb":[[0,3.2,4],[1,3.15,11.5],[2,3.1,17.95]],"ltp":3.25,"tv":13592.13,"id":8858694}]}]}
{"op":"mcm","clk":"11889965523","pt":1724176699420,"mc":[{"id":"1.232048439","rc":[{"batb":[[0,3.25,4],[1,3.2,4],[2,3.15,11.5]],"ltp":3.25,"tv":13592.13,"id":8858694}]}]}
{"op":"mcm","clk":"11889965573","pt":1724176699803,"mc":[{"id":"1.232048439","rc":[{"batb":[[0,1.42,12.23]],"ltp":1.41,"tv":89.33,"id":247649}]}]}
{"op":"mcm","clk":"11889965786","pt":1724176701697,"mc":[{"id":"1.232048439","rc":[{"batb":[[0,3.2,4],[1,3.15,11.5],[2,3.1,17.95]],"ltp":3.25,"tv":13592.13,"id":8858694}]}]}
{"op":"mcm","clk":"11889966689","pt":1724176708439,"mc":[{"id":"1.232048439","rc":[{"batb":[[0,3.25,4],[1,3.2,4],[2,3.15,11.5]],"ltp":3.25,"tv":13592.13,"id":8858694}]}]}
{"op":"mcm","clk":"11889967058","pt":1724176710746,"mc":[{"id":"1.232048439","rc":[{"batb":[[0,3.2,4],[1,3.15,11.5],[2,3.1,17.95]],"ltp":3.25,"tv":13592.13,"id":8858694}]}]}
{"op":"mcm","clk":"11889967438","pt":1724176713523,"mc":[{"id":"1.232048439","rc":[{"batb":[[0,3.25,4],[1,3.2,4],[2,3.15,11.5]],"ltp":3.25,"tv":13592.13,"id":8858694}]}]}
{"op":"mcm","clk":"11889967803","pt":1724176716424,"mc":[{"id":"1.232048439","rc":[{"batb":[[0,3.2,4],[1,3.15,11.5],[2,3.1,17.95]],"ltp":3.25,"tv":13592.13,"id":8858694}]}]}
{"op":"mcm","clk":"11889968146","pt":1724176719130,"mc":[{"id":"1.232048439","rc":[{"batb":[[0,3.25,4],[1,3.2,4],[2,3.15,11.5]],"ltp":3.25,"tv":13592.13,"id":8858694}]}]}
{"op":"mcm","clk":"11889968426","pt":1724176721549,"mc":[{"id":"1.232048439","rc":[{"batb":[[0,3.2,4],[1,3.15,11.5],[2,3.1,17.95]],"ltp":3.25,"tv":13592.13,"id":8858694}]}]}
{"op":"mcm","clk":"11889968837","pt":1724176724372,"mc":[{"id":"1.232048439","rc":[{"trd":[[1.42,38.94]],"batb":[[0,1.41,95.97],[1,1.11,18.8],[2,1.04,1634.41]],"batl":[[0,1.42,4.53],[1,1.46,5.09]],"ltp":1.42,"tv":113.8,"id":247649},{"batb":[[0,3.25,4],[1,3.2,4],[2,3.15,11.5]],"ltp":3.25,"tv":13592.13,"id":8858694}],"tv":13705.93}]}
{"op":"mcm","clk":"11889968927","pt":1724176724948,"mc":[{"id":"1.232048439","rc":[{"batl":[[1,1.45,8.06],[2,1.46,5.09]],"ltp":1.42,"tv":113.8,"id":247649},{"batb":[[1,3.15,7.5],[2,3.1,17.95]],"ltp":3.25,"tv":13592.13,"id":8858694}]}]}
{"op":"mcm","clk":"11889969226","pt":1724176727043,"mc":[{"id":"1.232048439","rc":[{"batl":[[1,1.44,5.17],[2,1.47,14]],"ltp":1.42,"tv":113.8,"id":247649},{"batb":[[0,3.2,10]],"ltp":3.25,"tv":13592.13,"id":8858694}]}]}
{"op":"mcm","clk":"11889969484","pt":1724176728981,"mc":[{"id":"1.232048439","rc":[{"batl":[[0,1.45,5.13],[1,1.47,14],[2,1.5,5.1]],"ltp":1.42,"tv":113.8,"id":247649},{"batb":[[0,3.25,4],[1,3.2,10],[2,3.15,7.5]],"ltp":3.25,"tv":13592.13,"id":8858694}]}]}
{"op":"mcm","clk":"11889969772","pt":1724176731281,"mc":[{"id":"1.232048439","rc":[{"batb":[[0,3.15,7.5],[1,3.1,17.95],[2,1.51,25.03]],"ltp":3.25,"tv":13592.13,"id":8858694}]}]}
{"op":"mcm","clk":"11889969983","pt":1724176732962,"mc":[{"id":"1.232048439","rc":[{"batl":[[0,1.46,5.09]],"ltp":1.42,"tv":113.8,"id":247649},{"batb":[[0,3.2,10],[1,3.15,7.5],[2,3.1,17.95]],"ltp":3.25,"tv":13592.13,"id":8858694}]}]}
{"op":"mcm","clk":"11889970064","pt":1724176733583,"mc":[{"id":"1.232048439","rc":[{"batb":[[0,3.25,4],[1,3.2,10],[2,3.15,7.5]],"ltp":3.25,"tv":13592.13,"id":8858694}]}]}
{"op":"mcm","clk":"11889970420","pt":1724176736095,"mc":[{"id":"1.232048439","rc":[{"batb":[[0,3.2,10],[1,3.15,7.5],[2,3.1,17.95]],"ltp":3.25,"tv":13592.13,"id":8858694}]}]}
{"op":"mcm","clk":"11889970528","pt":1724176736773,"mc":[{"id":"1.232048439","rc":[{"batl":[[0,1.46,9.09]],"ltp":1.42,"tv":113.8,"id":247649},{"batb":[[0,3.25,4],[1,3.2,4],[2,3.15,7.5]],"ltp":3.25,"tv":13592.13,"id":8858694}]}]}
{"op":"mcm","clk":"11889971484","pt":1724176743070,"mc":[{"id":"1.232048439","rc":[{"batb":[[0,3.3,4],[1,3.25,4],[2,3.2,4]],"ltp":3.25,"tv":13592.13,"id":8858694}]}]}
{"op":"mcm","clk":"11889971566","pt":1724176743591,"mc":[{"id":"1.232048439","rc":[{"batb":[[1,3.15,7.5],[2,3.1,17.95]],"ltp":3.25,"tv":13592.13,"id":8858694}]}]}
{"op":"mcm","clk":"11889971927","pt":1724176745904,"mc":[{"id":"1.232048439","rc":[{"batb":[[0,3.15,7.5],[1,3.1,17.95],[2,1.51,25.03]],"ltp":3.25,"tv":13592.13,"id":8858694}]}]}
{"op":"mcm","clk":"11889972068","pt":1724176746904,"mc":[{"id":"1.232048439","rc":[{"batl":[[0,1.46,17.11]],"ltp":1.42,"tv":113.8,"id":247649},{"batb":[[0,3.2,10],[1,3.15,7.5],[2,3.1,17.95]],"ltp":3.25,"tv":13592.13,"id":8858694}]}]}
{"op":"mcm","clk":"11889972434","pt":1724176749269,"mc":[{"id":"1.232048439","rc":[{"batb":[[0,3.25,4],[1,3.2,10],[2,3.15,7.5]],"ltp":3.25,"tv":13592.13,"id":8858694}]}]}
{"op":"mcm","clk":"11889972558","pt":1724176750263,"mc":[{"id":"1.232048439","rc":[{"batb":[[1,3.15,7.5],[2,3.1,17.95]],"ltp":3.25,"tv":13592.13,"id":8858694}]}]}
{"op":"mcm","clk":"11889972813","pt":1724176751997,"mc":[{"id":"1.232048439","rc":[{"batl":[[0,1.45,4],[1,1.46,17.11],[2,1.47,14]],"ltp":1.42,"tv":113.8,"id":247649},{"batb":[[0,3.15,7.5],[1,3.1,17.95],[2,1.51,25.03]],"ltp":3.25,"tv":13592.13,"id":8858694}]}]}
{"op":"mcm","clk":"11889973385","pt":1724176756195,"mc":[{"id":"1.232048439","rc":[{"batb":[[0,3.2,14],[1,3.15,7.5],[2,3.1,17.95]],"ltp":3.25,"tv":13592.13,"id":8858694}]}]}
{"op":"mcm","clk":"11889973735","pt":1724176758913,"mc":[{"id":"1.232048439","rc":[{"batb":[[0,3.2,10]],"ltp":3.25,"tv":13592.13,"id":8858694}]}]}
{"op":"mcm","clk":"11889973883","pt":1724176760035,"mc":[{"id":"1.232048439","rc":[{"batb":[[0,3.15,7.5],[1,3.1,17.95],[2,1.51,25.03]],"ltp":3.25,"tv":13592.13,"id":8858694}]}]}
{"op":"mcm","clk":"11889974530","pt":1724176764906,"mc":[{"id":"1.232048439","rc":[{"batb":[[0,3.2,14],[1,3.15,7.5],[2,3.1,17.95]],"ltp":3.25,"tv":13592.13,"id":8858694}]}]}
{"op":"mcm","clk":"11889974789","pt":1724176767005,"mc":[{"id":"1.232048439","rc":[{"batb":[[0,3.25,4],[1,3.2,18],[2,3.15,7.5]],"ltp":3.25,"tv":13592.13,"id":8858694}]}]}
{"op":"mcm","clk":"11889974983","pt":1724176768209,"mc":[{"id":"1.232048439","rc":[{"batl":[[0,1.44,8.12],[1,1.45,4],[2,1.46,9.09]],"ltp":1.42,"tv":113.8,"id":247649},{"batb":[[0,3.25,11.27],[1,3.2,14],[2,3.1,17.95]],"ltp":3.25,"tv":13592.13,"id":8858694}]}]}
{"op":"mcm","clk":"11889975058","pt":1724176768684,"mc":[{"id":"1.232048439","rc":[{"batb":[[1,3.2,4]],"ltp":3.25,"tv":13592.13,"id":8858694}]}]}
{"op":"mcm","clk":"11889975234","pt":1724176769935,"mc":[{"id":"1.232048439","rc":[{"batl":[[2,1.46,4]],"ltp":1.42,"tv":113.8,"id":247649},{"batb":[[0,3.3,4],[1,3.25,4],[2,3.2,11.38]],"ltp":3.25,"tv":13592.13,"id":8858694}]}]}
{"op":"mcm","clk":"11889975461","pt":1724176771639,"mc":[{"id":"1.232048439","rc":[{"batl":[[0,1.43,5.21],[1,1.44,8.12],[2,1.45,4]],"ltp":1.42,"tv":113.8,"id":247649}]}]}
{"op":"mcm","clk":"11889975724","pt":1724176773414,"mc":[{"id":"1.232048439","rc":[{"batl":[[0,1.44,8.12],[1,1.47,14],[2,1.5,5.1]],"ltp":1.42,"tv":113.8,"id":247649},{"batb":[[0,3.1,17.95],[1,1.51,25.03],[2,1.11,18.8]],"ltp":3.25,"tv":13592.13,"id":8858694}]}]}
{"op":"mcm","clk":"11889975862","pt":1724176774410,"mc":[{"id":"1.232048439","rc":[{"batb":[[0,3.15,17.5],[1,3.1,17.95],[2,1.51,25.03]],"ltp":3.25,"tv":13592.13,"id":8858694}]}]}
{"op":"mcm","clk":"11889975952","pt":1724176775097,"mc":[{"id":"1.232048439","rc":[{"batl":[[0,1.47,14],[1,1.5,5.1],[2,3.5,1.82]],"ltp":1.42,"tv":113.8,"id":247649},{"batb":[[0,3.2,4],[1,3.15,17.5],[2,3.1,17.95]],"ltp":3.25,"tv":13592.13,"id":8858694}]}]}
{"op":"mcm","clk":"11889976343","pt":1724176778112,"mc":[{"id":"1.232048439","rc":[{"batb":[[0,3.15,7.5],[1,3.1,17.95],[2,1.51,25.03]],"ltp":3.25,"tv":13592.13,"id":8858694}]}]}
{"op":"mcm","clk":"11889976733","pt":1724176781407,"mc":[{"id":"1.232048439","rc":[{"batb":[[0,3.2,14],[1,3.15,7.5],[2,3.1,17.95]],"ltp":3.25,"tv":13592.13,"id":8858694}]}]}
{"op":"mcm","clk":"11889976841","pt":1724176782307,"mc":[{"id":"1.232048439","rc":[{"batl":[[0,1.46,4],[1,1.47,14],[2,1.5,5.1]],"ltp":1.42,"tv":113.8,"id":247649},{"batb":[[0,3.25,4],[1,3.2,18],[2,3.15,7.5]],"ltp":3.25,"tv":13592.13,"id":8858694}]}]}
{"op":"mcm","clk":"11889976970","pt":1724176783311,"mc":[{"id":"1.232048439","rc":[{"batb":[[2,3.1,17.95]],"ltp":3.25,"tv":13592.13,"id":8858694}]}]}
{"op":"mcm","clk":"11889977043","pt":1724176783937,"mc":[{"id":"1.232048439","rc":[{"batb":[[1,3.2,14]],"ltp":3.25,"tv":13592.13,"id":8858694}]}]}
{"op":"mcm","clk":"11889977210","pt":1724176785416,"mc":[{"id":"1.232048439","rc":[{"batb":[[0,3.1,17.95],[1,1.51,25.03],[2,1.11,18.8]],"ltp":3.25,"tv":13592.13,"id":8858694}]}]}
{"op":"mcm","clk":"11889977651","pt":1724176788809,"mc":[{"id":"1.232048439","rc":[{"batb":[[0,3.15,14],[1,3.1,17.95],[2,1.51,25.03]],"ltp":3.25,"tv":13592.13,"id":8858694}]}]}
{"op":"mcm","clk":"11889977935","pt":1724176791312,"mc":[{"id":"1.232048439","rc":[{"batb":[[0,3.15,10]],"ltp":3.25,"tv":13592.13,"id":8858694}]}]}
{"op":"mcm","clk":"11889978047","pt":1724176792144,"mc":[{"id":"1.232048439","rc":[{"batb":[[0,3.1,17.95],[1,1.51,25.03],[2,1.11,18.8]],"ltp":3.25,"tv":13592.13,"id":8858694}]}]}
{"op":"mcm","clk":"11889978295","pt":1724176794306,"mc":[{"id":"1.232048439","rc":[{"batb":[[0,3.2,10],[1,3.15,4],[2,3.1,17.95]],"ltp":3.25,"tv":13592.13,"id":8858694}]}]}
{"op":"mcm","clk":"11889978655","pt":1724176797422,"mc":[{"id":"1.232048439","rc":[{"batl":[[0,1.45,8.06],[1,1.46,4],[2,1.47,14]],"ltp":1.42,"tv":113.8,"id":247649},{"batb":[[0,3.25,4],[1,3.2,14]],"ltp":3.25,"tv":13592.13,"id":8858694}]}]}
{"op":"mcm","clk":"11889978771","pt":1724176798310,"mc":[{"id":"1.232048439","rc":[{"batl":[[0,1.45,12.06]],"ltp":1.42,"tv":113.8,"id":247649},{"batb":[[1,3.2,4]],"ltp":3.25,"tv":13592.13,"id":8858694}]}]}
{"op":"mcm","clk":"11889978880","pt":1724176799245,"mc":[{"id":"1.232048439","rc":[{"batl":[[0,1.45,8.06],[1,1.47,14],[2,1.5,5.1]],"ltp":1.42,"tv":113.8,"id":247649},{"batb":[[0,3.15,4],[1,3.1,17.95],[2,1.51,25.03]],"ltp":3.25,"tv":13592.13,"id":8858694}]}]}
{"op":"mcm","clk":"11889978967","pt":1724176799827,"mc":[{"id":"1.232048439","rc":[{"batl":[[0,1.47,14],[1,1.5,5.1],[2,3.5,1.82]],"ltp":1.42,"tv":113.8,"id":247649}]}]}
{"op":"mcm","clk":"11889979229","pt":1724176801338,"mc":[{"id":"1.232048439","rc":[{"batb":[[0,3.2,10]],"ltp":3.25,"tv":13592.13,"id":8858694}]}]}
{"op":"mcm","clk":"11889979864","pt":1724176805282,"mc":[{"id":"1.232048439","rc":[{"trd":[[1.42,38.95]],"batb":[[1,1.11,18.81],[2,1.04,1635.11]],"ltp":1.42,"tv":113.8,"id":247649},{"trd":[[3.2,2766.1],[3.25,535.68],[3.3,4766.22],[3.35,5476.41],[3.4,9.68],[3.45,36]],"batb":[[0,3.25,4],[2,1.51,25.04]],"ltp":3.25,"tv":13598.36,"id":8858694}],"tv":13712.17}]}
{"op":"mcm","clk":"11889980238","pt":1724176807667,"mc":[{"id":"1.232048439","rc":[{"batl":[[0,1.46,8.02],[1,1.47,14],[2,1.5,5.1]],"ltp":1.42,"tv":113.8,"id":247649},{"batb":[[0,3.15,10]],"ltp":3.25,"tv":13598.36,"id":8858694}]}]}
{"op":"mcm","clk":"11889980753","pt":1724176811349,"mc":[{"id":"1.232048439","rc":[{"batb":[[0,3.15,4]],"ltp":3.25,"tv":13598.36,"id":8858694}]}]}
{"op":"mcm","clk":"11889980941","pt":1724176812766,"mc":[{"id":"1.232048439","rc":[{"batl":[[0,1.46,12.02]],"ltp":1.42,"tv":113.8,"id":247649},{"batb":[[0,3.15,8]],"ltp":3.25,"tv":13598.36,"id":8858694}]}]}
{"op":"mcm","clk":"11889981159","pt":1724176814236,"mc":[{"id":"1.232048439","rc":[{"batb":[[0,3.2,10],[1,3.15,4],[2,3.1,17.95]],"ltp":3.25,"tv":13598.36,"id":8858694}]}]}
{"op":"mcm","clk":"11889981680","pt":1724176818058,"mc":[{"id":"1.232048439","rc":[{"batb":[[0,3.2,4]],"ltp":3.25,"tv":13598.36,"id":8858694}]}]}
{"op":"mcm","clk":"11889982029","pt":1724176820369,"mc":[{"id":"1.232048439","rc":[{"batb":[[0,3.15,4],[1,3.1,17.95],[2,1.51,25.04]],"ltp":3.25,"tv":13598.36,"id":8858694}]}]}
{"op":"mcm","clk":"11889982114","pt":1724176821004,"mc":[{"id":"1.232048439","rc":[{"batb":[[0,3.2,10],[1,3.15,4],[2,3.1,17.95]],"ltp":3.25,"tv":13598.36,"id":8858694}]}]}
{"op":"mcm","clk":"11889982596","pt":1724176824340,"mc":[{"id":"1.232048439","rc":[{"batb":[[0,3.15,4],[1,3.1,17.95],[2,1.51,25.04]],"ltp":3.25,"tv":13598.36,"id":8858694}]}]}
{"op":"mcm","clk":"11889982641","pt":1724176824748,"mc":[{"id":"1.232048439","rc":[{"batb":[[0,3.2,4],[1,3.15,4],[2,3.1,17.95]],"ltp":3.25,"tv":13598.36,"id":8858694}]}]}
{"op":"mcm","clk":"11889982770","pt":1724176825857,"mc":[{"id":"1.232048439","rc":[{"batl":[[0,1.45,5.13],[1,1.46,12.02],[2,1.47,14]],"ltp":1.42,"tv":113.8,"id":247649},{"batb":[[1,3.15,11.5]],"ltp":3.25,"tv":13598.36,"id":8858694}]}]}
{"op":"mcm","clk":"11889982973","pt":1724176827273,"mc":[{"id":"1.232048439","rc":[{"batb":[[0,3.15,11.5],[1,3.1,17.95],[2,1.51,25.04]],"ltp":3.25,"tv":13598.36,"id":8858694}]}]}
{"op":"mcm","clk":"11889983050","pt":1724176827846,"mc":[{"id":"1.232048439","rc":[{"batl":[[0,1.45,9.13]],"ltp":1.42,"tv":113.8,"id":247649},{"batb":[[0,3.2,14],[1,3.15,11.5],[2,3.1,17.95]],"ltp":3.25,"tv":13598.36,"id":8858694}]}]}
{"op":"mcm","clk":"11889983350","pt":1724176830147,"mc":[{"id":"1.232048439","rc":[{"batb":[[0,3.25,11.27],[1,3.2,14],[2,3.15,4]],"ltp":3.25,"tv":13598.36,"id":8858694}]}]}
{"op":"mcm","clk":"11889983491","pt":1724176830983,"mc":[{"id":"1.232048439","rc":[{"batb":[[1,3.2,4]],"ltp":3.25,"tv":13598.36,"id":8858694}]}]}
{"op":"mcm","clk":"11889983609","pt":1724176831558,"mc":[{"id":"1.232048439","rc":[{"batl":[[0,1.44,8.13],[1,1.45,9.13],[2,1.46,4]],"ltp":1.42,"tv":113.8,"id":247649}]}]}
{"op":"mcm","clk":"11889983785","pt":1724176832683,"mc":[{"id":"1.232048439","rc":[{"batb":[[0,3.25,7.27]],"ltp":3.25,"tv":13598.36,"id":8858694}]}]}
{"op":"mcm","clk":"11889983970","pt":1724176833880,"mc":[{"id":"1.232048439","rc":[{"batb":[[0,3.2,4],[1,3.15,4],[2,3.1,17.95]],"ltp":3.25,"tv":13598.36,"id":8858694}]}]}
{"op":"mcm","clk":"11889984123","pt":1724176834876,"mc":[{"id":"1.232048439","rc":[{"batl":[[1,1.45,5.13],[2,1.47,14]],"ltp":1.42,"tv":113.8,"id":247649},{"batb":[[0,3.25,4],[1,3.1,17.95],[2,1.51,25.04]],"ltp":3.25,"tv":13598.36,"id":8858694}]}]}
{"op":"mcm","clk":"11889984193","pt":1724176835453,"mc":[{"id":"1.232048439","rc":[{"batb":[[1,3.15,10],[2,3.1,17.95]],"ltp":3.25,"tv":13598.36,"id":8858694}]}]}
{"op":"mcm","clk":"11889984504","pt":1724176837891,"mc":[{"id":"1.232048439","rc":[{"batb":[[0,3.15,10],[1,3.1,17.95],[2,1.51,25.04]],"ltp":3.25,"tv":13598.36,"id":8858694}]}]}
{"op":"mcm","clk":"11889984702","pt":1724176839363,"mc":[{"id":"1.232048439","rc":[{"batl":[[0,1.46,5.1],[1,1.47,14],[2,1.5,5.1]],"ltp":1.42,"tv":113.8,"id":247649},{"batb":[[0,3.1,17.95],[1,1.51,25.04],[2,1.11,18.81]],"ltp":3.25,"tv":13598.36,"id":8858694}]}]}
{"op":"mcm","clk":"11889984970","pt":1724176841656,"mc":[{"id":"1.232048439","rc":[{"batb":[[0,3.15,14],[1,3.1,17.95],[2,1.51,25.04]],"ltp":3.25,"tv":13598.36,"id":8858694}]}]}
{"op":"mcm","clk":"11889985161","pt":1724176843064,"mc":[{"id":"1.232048439","rc":[{"batl":[[0,1.46,9.1]],"ltp":1.42,"tv":113.8,"id":247649},{"batb":[[0,3.2,4],[1,3.15,18],[2,3.1,17.95]],"ltp":3.25,"tv":13598.36,"id":8858694}]}]}
{"op":"mcm","clk":"11889985330","pt":1724176844165,"mc":[{"id":"1.232048439","rc":[{"batb":[[1,3.15,14]],"ltp":3.25,"tv":13598.36,"id":8858694}]}]}
{"op":"mcm","clk":"11889985453","pt":1724176845204,"mc":[{"id":"1.232048439","rc":[{"batb":[[1,3.15,4]],"ltp":3.25,"tv":13598.36,"id":8858694}]}]}
{"op":"mcm","clk":"11889985559","pt":1724176845872,"mc":[{"id":"1.232048439","rc":[{"batb":[[0,3.15,4],[1,3.1,17.95],[2,1.51,25.04]],"ltp":3.25,"tv":13598.36,"id":8858694}]}]}
{"op":"mcm","clk":"11889985862","pt":1724176847868,"mc":[{"id":"1.232048439","rc":[{"batb":[[0,3.2,14],[1,3.15,4],[2,3.1,17.95]],"ltp":3.25,"tv":13598.36,"id":8858694}]}]}
{"op":"mcm","clk":"11889986181","pt":1724176850180,"mc":[{"id":"1.232048439","rc":[{"batb":[[0,3.2,10]],"ltp":3.25,"tv":13598.36,"id":8858694}]}]}
{"op":"mcm","clk":"11889986321","pt":1724176851376,"mc":[{"id":"1.232048439","rc":[{"batb":[[0,3.15,4],[1,3.1,17.95],[2,1.51,25.04]],"ltp":3.25,"tv":13598.36,"id":8858694}]}]}
{"op":"mcm","clk":"11889986606","pt":1724176853307,"mc":[{"id":"1.232048439","rc":[{"batb":[[0,3.2,4],[1,3.15,4],[2,3.1,17.95]],"ltp":3.25,"tv":13598.36,"id":8858694}]}]}
{"op":"mcm","clk":"11889987093","pt":1724176856287,"mc":[{"id":"1.232048439","rc":[{"batb":[[0,3.2,10]],"ltp":3.25,"tv":13598.36,"id":8858694}]}]}
{"op":"mcm","clk":"11889987371","pt":1724176858384,"mc":[{"id":"1.232048439","rc":[{"batb":[[0,3.25,8],[1,3.2,14],[2,3.15,4]],"ltp":3.25,"tv":13598.36,"id":8858694}]}]}
{"op":"mcm","clk":"11889987505","pt":1724176859415,"mc":[{"id":"1.232048439","rc":[{"batl":[[0,1.46,4]],"ltp":1.42,"tv":113.8,"id":247649}]}]}
{"op":"mcm","clk":"11889987595","pt":1724176860094,"mc":[{"id":"1.232048439","rc":[{"batl":[[0,1.44,5.17],[1,1.46,4],[2,1.47,14]],"ltp":1.42,"tv":113.8,"id":247649},{"batb":[[0,3.25,4],[1,3.1,17.95],[2,1.51,25.04]],"ltp":3.25,"tv":13598.36,"id":8858694}]}]}
{"op":"mcm","clk":"11889987736","pt":1724176860895,"mc":[{"id":"1.232048439","rc":[{"batl":[[1,1.46,8.02]],"ltp":1.42,"tv":113.8,"id":247649},{"batb":[[0,3.1,17.95],[1,1.51,25.04],[2,1.11,18.81]],"ltp":3.25,"tv":13598.36,"id":8858694}]}]}
{"op":"mcm","clk":"11889987960","pt":1724176862304,"mc":[{"id":"1.232048439","rc":[{"batl":[[0,1.46,8.02],[1,1.47,14],[2,1.5,5.1]],"ltp":1.42,"tv":113.8,"id":247649}]}]}
{"op":"mcm","clk":"11889988006","pt":1724176862605,"mc":[{"id":"1.232048439","rc":[{"batb":[[0,3.15,10],[1,3.1,17.95],[2,1.51,25.04]],"ltp":3.25,"tv":13598.36,"id":8858694}]}]}
{"op":"mcm","clk":"11889988201","pt":1724176863806,"mc":[{"id":"1.232048439","rc":[{"batb":[[0,3.2,4],[1,3.15,10],[2,3.1,17.95]],"ltp":3.25,"tv":13598.36,"id":8858694}]}]}
{"op":"mcm","clk":"11889988569","pt":1724176866399,"mc":[{"id":"1.232048439","rc":[{"batb":[[0,3.1,17.95],[1,1.51,25.04],[2,1.11,18.81]],"ltp":3.25,"tv":13598.36,"id":8858694}]}]}
{"op":"mcm","clk":"11889989022","pt":1724176869290,"mc":[{"id":"1.232048439","rc":[{"batb":[[0,3.15,14],[1,3.1,17.95],[2,1.51,25.04]],"ltp":3.25,"tv":13598.36,"id":8858694}]}]}
{"op":"mcm","clk":"11889989407","pt":1724176871988,"mc":[{"id":"1.232048439","rc":[{"batb":[[0,3.15,10]],"ltp":3.25,"tv":13598.36,"id":8858694}]}]}
{"op":"mcm","clk":"11889989601","pt":1724176873431,"mc":[{"id":"1.232048439","rc":[{"batl":[[0,1.46,12.02]],"ltp":1.42,"tv":113.8,"id":247649},{"batb":[[0,3.2,4],[1,3.15,4],[2,3.1,17.95]],"ltp":3.25,"tv":13598.36,"id":8858694}]}]}
{"op":"mcm","clk":"11889989852","pt":1724176875003,"mc":[{"id":"1.232048439","rc":[{"batb":[[0,3.25,4],[1,3.1,17.95],[2,1.51,25.04]],"ltp":3.25,"tv":13598.36,"id":8858694}]}]}
{"op":"mcm","clk":"11889990234","pt":1724176878012,"mc":[{"id":"1.232048439","rc":[{"batb":[[0,3.15,10]],"ltp":3.25,"tv":13598.36,"id":8858694}]}]}
{"op":"mcm","clk":"11889990748","pt":1724176881925,"mc":[{"id":"1.232048439","rc":[{"batb":[[0,3.15,4]],"ltp":3.25,"tv":13598.36,"id":8858694}]}]}
{"op":"mcm","clk":"11889991083","pt":1724176884319,"mc":[{"id":"1.232048439","rc":[{"batb":[[0,3.1,17.95],[1,1.51,25.04],[2,1.11,18.81]],"ltp":3.25,"tv":13598.36,"id":8858694}]}]}
{"op":"mcm","clk":"11889991142","pt":1724176884732,"mc":[{"id":"1.232048439","rc":[{"batb":[[0,3.15,10],[1,3.1,17.95],[2,1.51,25.04]],"ltp":3.25,"tv":13598.36,"id":8858694}]}]}
{"op":"mcm","clk":"11889991525","pt":1724176887289,"mc":[{"id":"1.232048439","rc":[{"batb":[[0,3.2,4],[1,3.15,10],[2,3.1,17.95]],"ltp":3.25,"tv":13598.36,"id":8858694}]}]}
{"op":"mcm","clk":"11889991648","pt":1724176888130,"mc":[{"id":"1.232048439","rc":[{"batb":[[0,3.2,11.38],[1,3.1,17.95],[2,1.51,25.04]],"ltp":3.25,"tv":13598.36,"id":8858694}]}]}
{"op":"mcm","clk":"11889991724","pt":1724176888638,"mc":[{"id":"1.232048439","rc":[{"batb":[[0,3.25,4],[1,3.2,15.38],[2,3.1,17.95]],"ltp":3.25,"tv":13598.36,"id":8858694}]}]}
{"op":"mcm","clk":"11889991937","pt":1724176890144,"mc":[{"id":"1.232048439","rc":[{"batb":[[0,3.1,17.95],[1,1.51,25.04],[2,1.11,18.81]],"ltp":3.25,"tv":13598.36,"id":8858694}]}]}
{"op":"mcm","clk":"11889992042","pt":1724176890834,"mc":[{"id":"1.232048439","rc":[{"batb":[[0,3.15,10],[1,3.1,17.95],[2,1.51,25.04]],"ltp":3.25,"tv":13598.36,"id":8858694}]}]}
{"op":"mcm","clk":"11889992256","pt":1724176892453,"mc":[{"id":"1.232048439","rc":[{"batb":[[0,3.2,4],[1,3.15,10],[2,3.1,17.95]],"ltp":3.25,"tv":13598.36,"id":8858694}]}]}
{"op":"mcm","clk":"11889992579","pt":1724176894727,"mc":[{"id":"1.232048439","rc":[{"batb":[[0,3.1,17.95],[1,1.51,25.04],[2,1.11,18.81]],"ltp":3.25,"tv":13598.36,"id":8858694}]}]}
{"op":"mcm","clk":"11889992897","pt":1724176896847,"mc":[{"id":"1.232048439","rc":[{"batb":[[0,3.15,10],[1,3.1,17.95],[2,1.51,25.04]],"ltp":3.25,"tv":13598.36,"id":8858694}]}]}
{"op":"mcm","clk":"11889993001","pt":1724176897527,"mc":[{"id":"1.232048439","rc":[{"batb":[[0,3.2,4],[1,3.15,10],[2,3.1,17.95]],"ltp":3.25,"tv":13598.36,"id":8858694}]}]}
{"op":"mcm","clk":"11889993377","pt":1724176900434,"mc":[{"id":"1.232048439","rc":[{"batb":[[0,3.1,17.95],[1,1.51,25.04],[2,1.11,18.81]],"ltp":3.25,"tv":13598.36,"id":8858694}]}]}
{"op":"mcm","clk":"11889993824","pt":1724176903750,"mc":[{"id":"1.232048439","rc":[{"batb":[[0,3.15,18],[1,3.1,17.95],[2,1.51,25.04]],"ltp":3.25,"tv":13598.36,"id":8858694}]}]}
{"op":"mcm","clk":"11889994092","pt":1724176905861,"mc":[{"id":"1.232048439","rc":[{"batb":[[0,3.15,14]],"ltp":3.25,"tv":13598.36,"id":8858694}]}]}
{"op":"mcm","clk":"11889994232","pt":1724176906957,"mc":[{"id":"1.232048439","rc":[{"batb":[[0,3.15,4]],"ltp":3.25,"tv":13598.36,"id":8858694}]}]}
{"op":"mcm","clk":"11889994441","pt":1724176908538,"mc":[{"id":"1.232048439","rc":[{"batb":[[0,3.2,4],[1,3.15,4],[2,3.1,17.95]],"ltp":3.25,"tv":13598.36,"id":8858694}]}]}
{"op":"mcm","clk":"11889994806","pt":1724176910924,"mc":[{"id":"1.232048439","rc":[{"batb":[[0,3.15,4],[1,3.1,17.95],[2,1.51,25.04]],"ltp":3.25,"tv":13598.36,"id":8858694}]}]}
{"op":"mcm","clk":"11889994890","pt":1724176911542,"mc":[{"id":"1.232048439","rc":[{"batb":[[0,3.2,10],[1,3.15,4],[2,3.1,17.95]],"ltp":3.25,"tv":13598.36,"id":8858694}]}]}
{"op":"mcm","clk":"11889995385","pt":1724176915389,"mc":[{"id":"1.232048439","rc":[{"batb":[[0,3.25,4]],"ltp":3.25,"tv":13598.36,"id":8858694}]}]}
{"op":"mcm","clk":"11889995875","pt":1724176918867,"mc":[{"id":"1.232048439","rc":[{"batl":[[0,1.45,4],[1,1.46,12.02],[2,1.47,14]],"ltp":1.42,"tv":113.8,"id":247649},{"batb":[[0,3.2,10]],"ltp":3.25,"tv":13598.36,"id":8858694}]}]}
{"op":"mcm","clk":"11889996346","pt":1724176922077,"mc":[{"id":"1.232048439","rc":[{"batb":[[0,3.15,4],[1,3.1,17.95],[2,1.51,25.04]],"ltp":3.25,"tv":13598.36,"id":8858694}]}]}
{"op":"mcm","clk":"11889996422","pt":1724176922543,"mc":[{"id":"1.232048439","rc":[{"batl":[[0,1.46,12.02],[1,1.47,14],[2,1.5,5.1]],"ltp":1.42,"tv":113.8,"id":247649},{"batb":[[0,3.25,4],[1,3.15,4],[2,3.1,17.95]],"ltp":3.25,"tv":13598.36,"id":8858694}]}]}
{"op":"mcm","clk":"11889996882","pt":1724176925249,"mc":[{"id":"1.232048439","rc":[{"batb":[[0,3.15,4],[1,3.1,17.95],[2,1.51,25.04]],"ltp":3.25,"tv":13598.36,"id":8858694}]}]}
{"op":"mcm","clk":"11889996929","pt":1724176925563,"mc":[{"id":"1.232048439","rc":[{"batb":[[0,3.2,10],[1,3.15,4],[2,3.1,17.95]],"ltp":3.25,"tv":13598.36,"id":8858694}]}]}
{"op":"mcm","clk":"11889997450","pt":1724176929157,"mc":[{"id":"1.232048439","rc":[{"batb":[[0,3.2,4]],"ltp":3.25,"tv":13598.36,"id":8858694}]}]}
{"op":"mcm","clk":"11889997936","pt":1724176932076,"mc":[{"id":"1.232048439","rc":[{"batb":[[0,3.2,10]],"ltp":3.25,"tv":13598.36,"id":8858694}]}]}
{"op":"mcm","clk":"11889998255","pt":1724176934264,"mc":[{"id":"1.232048439","rc":[{"batb":[[0,3.25,8],[1,3.2,14],[2,3.15,4]],"ltp":3.25,"tv":13598.36,"id":8858694}]}]}
{"op":"mcm","clk":"11889998560","pt":1724176936347,"mc":[{"id":"1.232048439","rc":[{"batb":[[0,3.1,17.95],[1,1.51,25.04],[2,1.11,18.81]],"ltp":3.25,"tv":13598.36,"id":8858694}]}]}
{"op":"mcm","clk":"11889999010","pt":1724176939370,"mc":[{"id":"1.232048439","rc":[{"batb":[[0,3.15,14],[1,3.1,17.95],[2,1.51,25.04]],"ltp":3.25,"tv":13598.36,"id":8858694}]}]}
{"op":"mcm","clk":"11889999399","pt":1724176942087,"mc":[{"id":"1.232048439","rc":[{"batb":[[0,3.15,10]],"ltp":3.25,"tv":13598.36,"id":8858694}]}]}
{"op":"mcm","clk":"11889999569","pt":1724176943236,"mc":[{"id":"1.232048439","rc":[{"batb":[[0,3.1,17.95],[1,1.51,25.04],[2,1.11,18.81]],"ltp":3.25,"tv":13598.36,"id":8858694}]}]}
{"op":"mcm","clk":"11889999789","pt":1724176944693,"mc":[{"id":"1.232048439","rc":[{"batl":[[0,1.46,17.11]],"ltp":1.42,"tv":113.8,"id":247649},{"batb":[[0,3.2,4],[1,3.15,7.5],[2,3.1,17.95]],"ltp":3.25,"tv":13598.36,"id":8858694}]}]}
{"op":"mcm","clk":"11890000140","pt":1724176947068,"mc":[{"id":"1.232048439","rc":[{"batb":[[0,3.2,10]],"ltp":3.25,"tv":13598.36,"id":8858694}]}]}
{"op":"mcm","clk":"11890000417","pt":1724176949173,"mc":[{"id":"1.232048439","rc":[{"batb":[[0,3.25,4],[1,3.2,14],[2,3.15,7.5]],"ltp":3.25,"tv":13598.36,"id":8858694}]}]}
{"op":"mcm","clk":"11890000571","pt":1724176950374,"mc":[{"id":"1.232048439","rc":[{"batb":[[0,3.3,4],[1,3.25,11.27],[2,3.2,14]],"ltp":3.25,"tv":13598.36,"id":8858694}]}]}
{"op":"mcm","clk":"11890000711","pt":1724176951102,"mc":[{"id":"1.232048439","rc":[{"batb":[[2,3.2,4]],"ltp":3.25,"tv":13598.36,"id":8858694}]}]}
{"op":"mcm","clk":"11890000825","pt":1724176951794,"mc":[{"id":"1.232048439","rc":[{"batb":[[1,3.25,7.27],[2,3.1,17.95]],"ltp":3.25,"tv":13598.36,"id":8858694}]}]}
{"op":"mcm","clk":"11890001055","pt":1724176953169,"mc":[{"id":"1.232048439","rc":[{"batl":[[0,1.44,8.13],[1,1.46,9.1],[2,1.47,14]],"ltp":1.42,"tv":113.8,"id":247649}]}]}
{"op":"mcm","clk":"11890001147","pt":1724176953683,"mc":[{"id":"1.232048439","rc":[{"batl":[[0,1.43,5.21],[1,1.44,8.13]],"ltp":1.42,"tv":113.8,"id":247649},{"batb":[[0,3.1,17.95],[1,1.51,25.04],[2,1.11,18.81]],"ltp":3.25,"tv":13598.36,"id":8858694}]}]}
{"op":"mcm","clk":"11890001292","pt":1724176954680,"mc":[{"id":"1.232048439","rc":[{"batb":[[0,3.15,10],[1,3.1,17.95],[2,1.51,25.04]],"ltp":3.25,"tv":13598.36,"id":8858694}]}]}
{"op":"mcm","clk":"11890001642","pt":1724176956914,"mc":[{"id":"1.232048439","rc":[{"batl":[[1,1.46,8.02]],"ltp":1.42,"tv":113.8,"id":247649},{"batb":[[0,3.2,4],[1,3.15,10],[2,3.1,17.95]],"ltp":3.25,"tv":13598.36,"id":8858694}]}]}
{"op":"mcm","clk":"11890001810","pt":1724176958113,"mc":[{"id":"1.232048439","rc":[{"batl":[[0,1.45,5.13]],"ltp":1.42,"tv":113.8,"id":247649}]}]}
{"op":"mcm","clk":"11890001903","pt":1724176958698,"mc":[{"id":"1.232048439","rc":[{"batb":[[1,3.1,17.95],[2,1.51,25.04]],"ltp":3.25,"tv":13598.36,"id":8858694}]}]}
{"op":"mcm","clk":"11890002103","pt":1724176960107,"mc":[{"id":"1.232048439","rc":[{"batb":[[0,3.1,17.95],[1,1.51,25.04],[2,1.11,18.81]],"ltp":3.25,"tv":13598.36,"id":8858694}]}]}
{"op":"mcm","clk":"11890002180","pt":1724176960589,"mc":[{"id":"1.232048439","rc":[{"batl":[[0,1.46,8.02],[1,1.47,14],[2,1.5,5.1]],"ltp":1.42,"tv":113.8,"id":247649}]}]}
{"op":"mcm","clk":"11890002687","pt":1724176964306,"mc":[{"id":"1.232048439","rc":[{"batl":[[0,1.46,12.02]],"ltp":1.42,"tv":113.8,"id":247649},{"batb":[[0,3.2,4],[1,3.15,18],[2,3.1,17.95]],"ltp":3.25,"tv":13598.36,"id":8858694}]}]}
{"op":"mcm","clk":"11890003060","pt":1724176966681,"mc":[{"id":"1.232048439","rc":[{"batb":[[1,3.15,14]],"ltp":3.25,"tv":13598.36,"id":8858694}]}]}
{"op":"mcm","clk":"11890003211","pt":1724176967714,"mc":[{"id":"1.232048439","rc":[{"batb":[[0,3.15,4],[1,3.1,17.95],[2,1.51,25.04]],"ltp":3.25,"tv":13598.36,"id":8858694}]}]}
{"op":"mcm","clk":"11890003603","pt":1724176970499,"mc":[{"id":"1.232048439","rc":[{"batb":[[0,3.2,14],[1,3.15,4],[2,3.1,17.95]],"ltp":3.25,"tv":13598.36,"id":8858694}]}]}
{"op":"mcm","clk":"11890003988","pt":1724176973314,"mc":[{"id":"1.232048439","rc":[{"batb":[[0,3.2,10]],"ltp":3.25,"tv":13598.36,"id":8858694}]}]}
{"op":"mcm","clk":"11890004133","pt":1724176974315,"mc":[{"id":"1.232048439","rc":[{"batb":[[0,3.15,4],[1,3.1,17.95],[2,1.51,25.04]],"ltp":3.25,"tv":13598.36,"id":8858694}]}]}
{"op":"mcm","clk":"11890004337","pt":1724176975929,"mc":[{"id":"1.232048439","rc":[{"batb":[[0,3.2,4],[1,3.15,4],[2,3.1,17.95]],"ltp":3.25,"tv":13598.36,"id":8858694}]}]}
{"op":"mcm","clk":"11890004790","pt":1724176979432,"mc":[{"id":"1.232048439","rc":[{"batb":[[0,3.25,4],[1,3.2,14],[2,3.15,4]],"ltp":3.25,"tv":13598.36,"id":8858694}]}]}
{"op":"mcm","clk":"11890005215","pt":1724176982426,"mc":[{"id":"1.232048439","rc":[{"batb":[[1,3.2,4]],"ltp":3.25,"tv":13598.36,"id":8858694}]}]}
{"op":"mcm","clk":"11890005288","pt":1724176982909,"mc":[{"id":"1.232048439","rc":[{"batb":[[0,3.3,4],[1,3.1,17.95],[2,1.51,25.04]],"ltp":3.25,"tv":13598.36,"id":8858694}]}]}
{"op":"mcm","clk":"11890005655","pt":1724176985437,"mc":[{"id":"1.232048439","rc":[{"batb":[[0,3.15,10]],"ltp":3.25,"tv":13598.36,"id":8858694}]}]}
{"op":"mcm","clk":"11890006059","pt":1724176988118,"mc":[{"id":"1.232048439","rc":[{"batb":[[0,3.2,4],[1,3.15,10],[2,3.1,17.95]],"ltp":3.25,"tv":13598.36,"id":8858694}]}]}
{"op":"mcm","clk":"11890006139","pt":1724176988747,"mc":[{"id":"1.232048439","rc":[{"batb":[[1,3.1,17.95],[2,1.51,25.04]],"ltp":3.25,"tv":13598.36,"id":8858694}]}]}
{"op":"mcm","clk":"11890006392","pt":1724176990430,"mc":[{"id":"1.232048439","rc":[{"batb":[[0,3.1,17.95],[1,1.51,25.04],[2,1.11,18.81]],"ltp":3.25,"tv":13598.36,"id":8858694}]}]}
{"op":"mcm","clk":"11890006456","pt":1724176990941,"mc":[{"id":"1.232048439","rc":[{"batb":[[0,3.15,10],[1,3.1,17.95],[2,1.51,25.04]],"ltp":3.25,"tv":13598.36,"id":8858694}]}]}
{"op":"mcm","clk":"11890006906","pt":1724176994408,"mc":[{"id":"1.232048439","rc":[{"batb":[[0,3.2,4]],"ltp":3.25,"tv":13598.36,"id":8858694}]}]}
{"op":"mcm","clk":"11890007213","pt":1724176996233,"mc":[{"id":"1.232048439","rc":[{"batb":[[0,3.1,17.95],[1,1.51,25.04],[2,1.11,18.81]],"ltp":3.25,"tv":13598.36,"id":8858694}]}]}
{"op":"mcm","clk":"11890007463","pt":1724176997923,"mc":[{"id":"1.232048439","rc":[{"batb":[[0,3.15,10],[1,3.1,17.95],[2,1.51,25.04]],"ltp":3.25,"tv":13598.36,"id":8858694}]}]}
{"op":"mcm","clk":"11890007554","pt":1724176998540,"mc":[{"id":"1.232048439","rc":[{"batb":[[0,3.2,4],[1,3.15,10],[2,3.1,17.95]],"ltp":3.25,"tv":13598.36,"id":8858694}]}]}
{"op":"mcm","clk":"11890007958","pt":1724177001337,"mc":[{"id":"1.232048439","rc":[{"batb":[[0,3.1,17.95],[1,1.51,25.04],[2,1.11,18.81]],"ltp":3.25,"tv":13598.36,"id":8858694}]}]}
{"op":"mcm","clk":"11890008804","pt":1724177006640,"mc":[{"id":"1.232048439","rc":[{"batb":[[0,3.15,14],[1,3.1,17.95],[2,1.51,25.04]],"ltp":3.25,"tv":13598.36,"id":8858694}]}]}
{"op":"mcm","clk":"11890009240","pt":1724177009118,"mc":[{"id":"1.232048439","rc":[{"batb":[[0,3.2,7.38],[1,3.15,10],[2,3.1,17.95]],"ltp":3.25,"tv":13598.36,"id":8858694}]}]}
{"op":"mcm","clk":"11890009354","pt":1724177010043,"mc":[{"id":"1.232048439","rc":[{"batb":[[0,3.2,11.38],[1,3.1,17.95],[2,1.51,25.04]],"ltp":3.25,"tv":13598.36,"id":8858694}]}]}
{"op":"mcm","clk":"11890009506","pt":1724177011350,"mc":[{"id":"1.232048439","rc":[{"batb":[[0,3.25,4],[1,3.2,4],[2,3.1,17.95]],"ltp":3.25,"tv":13598.36,"id":8858694}]}]}
{"op":"mcm","clk":"11890009539","pt":1724177011520,"mc":[{"id":"1.232048439","rc":[{"batb":[[1,3.1,17.95],[2,1.51,25.04]],"ltp":3.25,"tv":13598.36,"id":8858694}]}]}
{"op":"mcm","clk":"11890009890","pt":1724177014244,"mc":[{"id":"1.232048439","rc":[{"batb":[[0,3.15,10]],"ltp":3.25,"tv":13598.36,"id":8858694}]}]}
{"op":"mcm","clk":"11890010298","pt":1724177017235,"mc":[{"id":"1.232048439","rc":[{"batb":[[0,3.2,4],[1,3.15,10],[2,3.1,17.95]],"ltp":3.25,"tv":13598.36,"id":8858694}]}]}
{"op":"mcm","clk":"11890010397","pt":1724177018061,"mc":[{"id":"1.232048439","rc":[{"batb":[[1,3.1,17.95],[2,1.51,25.04]],"ltp":3.25,"tv":13598.36,"id":8858694}]}]}
{"op":"mcm","clk":"11890010609","pt":1724177019643,"mc":[{"id":"1.232048439","rc":[{"batb":[[0,3.1,17.95],[1,1.51,25.04],[2,1.11,18.81]],"ltp":3.25,"tv":13598.36,"id":8858694}]}]}
{"op":"mcm","clk":"11890010937","pt":1724177021849,"mc":[{"id":"1.232048439","rc":[{"batb":[[0,3.15,14],[1,3.1,17.95],[2,1.51,25.04]],"ltp":3.25,"tv":13598.36,"id":8858694}]}]}
{"op":"mcm","clk":"11890011354","pt":1724177024375,"mc":[{"id":"1.232048439","rc":[{"batb":[[0,3.15,10]],"ltp":3.25,"tv":13598.36,"id":8858694}]}]}
{"op":"mcm","clk":"11890011433","pt":1724177024964,"mc":[{"id":"1.232048439","rc":[{"batb":[[0,3.2,4],[1,3.15,14],[2,3.1,17.95]],"ltp":3.25,"tv":13598.36,"id":8858694}]}]}
{"op":"mcm","clk":"11890011641","pt":1724177026164,"mc":[{"id":"1.232048439","rc":[{"batb":[[0,3.15,4],[1,3.1,17.95],[2,1.51,25.04]],"ltp":3.25,"tv":13598.36,"id":8858694}]}]}
{"op":"mcm","clk":"11890011984","pt":1724177028258,"mc":[{"id":"1.232048439","rc":[{"batb":[[0,3.2,14],[1,3.15,4],[2,3.1,17.95]],"ltp":3.25,"tv":13598.36,"id":8858694}]}]}
{"op":"mcm","clk":"11890012319","pt":1724177030658,"mc":[{"id":"1.232048439","rc":[{"batb":[[0,3.2,10]],"ltp":3.25,"tv":13598.36,"id":8858694}]}]}
{"op":"mcm","clk":"11890012446","pt":1724177031591,"mc":[{"id":"1.232048439","rc":[{"batb":[[0,3.15,4],[1,3.1,17.95],[2,1.51,25.04]],"ltp":3.25,"tv":13598.36,"id":8858694}]}]}
{"op":"mcm","clk":"11890012637","pt":1724177032966,"mc":[{"id":"1.232048439","rc":[{"batb":[[0,3.2,4],[1,3.15,4],[2,3.1,17.95]],"ltp":3.25,"tv":13598.36,"id":8858694}]}]}
{"op":"mcm","clk":"11890013038","pt":1724177036068,"mc":[{"id":"1.232048439","rc":[{"batb":[[0,3.2,10]],"ltp":3.25,"tv":13598.36,"id":8858694}]}]}
{"op":"mcm","clk":"11890013383","pt":1724177038694,"mc":[{"id":"1.232048439","rc":[{"batb":[[0,3.25,4],[1,3.2,10],[2,3.15,4]],"ltp":3.25,"tv":13598.36,"id":8858694}]}]}
{"op":"mcm","clk":"11890013569","pt":1724177040057,"mc":[{"id":"1.232048439","rc":[{"batl":[[0,1.45,4],[1,1.46,12.02],[2,1.47,14]],"ltp":1.42,"tv":113.8,"id":247649},{"batb":[[1,3.15,4],[2,3.1,17.95]],"ltp":3.25,"tv":13598.36,"id":8858694}]}]}
{"op":"mcm","clk":"11890013767","pt":1724177041266,"mc":[{"id":"1.232048439","rc":[{"batl":[[0,1.46,12.02],[1,1.47,14],[2,1.5,5.1]],"ltp":1.42,"tv":113.8,"id":247649},{"batb":[[0,3.1,17.95],[1,1.51,25.04],[2,1.11,18.81]],"ltp":3.25,"tv":13598.36,"id":8858694}]}]}
{"op":"mcm","clk":"11890014266","pt":1724177044400,"mc":[{"id":"1.232048439","rc":[{"batb":[[0,3.15,14],[1,3.1,17.95],[2,1.51,25.04]],"ltp":3.25,"tv":13598.36,"id":8858694}]}]}
{"op":"mcm","clk":"11890014620","pt":1724177046798,"mc":[{"id":"1.232048439","rc":[{"batb":[[0,3.15,10]],"ltp":3.25,"tv":13598.36,"id":8858694}]}]}
{"op":"mcm","clk":"11890014797","pt":1724177047887,"mc":[{"id":"1.232048439","rc":[{"batb":[[0,3.1,17.95],[1,1.51,25.04],[2,1.11,18.81]],"ltp":3.25,"tv":13598.36,"id":8858694}]}]}
{"op":"mcm","clk":"11890015133","pt":1724177050198,"mc":[{"id":"1.232048439","rc":[{"batb":[[0,3.15,14],[1,3.1,17.95],[2,1.51,25.04]],"ltp":3.25,"tv":13598.36,"id":8858694}]}]}
{"op":"mcm","clk":"11890015449","pt":1724177052595,"mc":[{"id":"1.232048439","rc":[{"batb":[[0,3.15,10]],"ltp":3.25,"tv":13598.36,"id":8858694}]}]}
{"op":"mcm","clk":"11890015586","pt":1724177053485,"mc":[{"id":"1.232048439","rc":[{"batb":[[0,3.1,17.95],[1,1.51,25.04],[2,1.11,18.81]],"ltp":3.25,"tv":13598.36,"id":8858694}]}]}
{"op":"mcm","clk":"11890015822","pt":1724177055206,"mc":[{"id":"1.232048439","rc":[{"batb":[[0,3.15,4],[1,3.1,17.95],[2,1.51,25.04]],"ltp":3.25,"tv":13598.36,"id":8858694}]}]}
{"op":"mcm","clk":"11890015858","pt":1724177055480,"mc":[{"id":"1.232048439","rc":[{"batb":[[0,3.2,4],[1,3.15,4],[2,3.1,17.95]],"ltp":3.25,"tv":13598.36,"id":8858694}]}]}
{"op":"mcm","clk":"11890016255","pt":1724177058401,"mc":[{"id":"1.232048439","rc":[{"batb":[[0,3.2,10]],"ltp":3.25,"tv":13598.36,"id":8858694}]}]}
{"op":"mcm","clk":"11890016705","pt":1724177061803,"mc":[{"id":"1.232048439","rc":[{"batb":[[0,3.2,4]],"ltp":3.25,"tv":13598.36,"id":8858694}]}]}
{"op":"mcm","clk":"11890017025","pt":1724177064392,"mc":[{"id":"1.232048439","rc":[{"batb":[[0,3.2,10]],"ltp":3.25,"tv":13598.36,"id":8858694}]}]}
{"op":"mcm","clk":"11890017298","pt":1724177066411,"mc":[{"id":"1.232048439","rc":[{"batb":[[0,3.25,4],[1,3.2,10],[2,3.15,4]],"ltp":3.25,"tv":13598.36,"id":8858694}]}]}
{"op":"mcm","clk":"11890017501","pt":1724177067815,"mc":[{"id":"1.232048439","rc":[{"batb":[[1,3.15,4],[2,3.1,17.95]],"ltp":3.25,"tv":13598.36,"id":8858694}]}]}
{"op":"mcm","clk":"11890017632","pt":1724177068815,"mc":[{"id":"1.232048439","rc":[{"batb":[[0,3.15,4],[1,3.1,17.95],[2,1.51,25.04]],"ltp":3.25,"tv":13598.36,"id":8858694}]}]}
{"op":"mcm","clk":"11890017830","pt":1724177070315,"mc":[{"id":"1.232048439","rc":[{"batl":[[0,1.46,17.11]],"ltp":1.42,"tv":113.8,"id":247649},{"batb":[[0,3.2,4],[1,3.15,11.5],[2,3.1,17.95]],"ltp":3.25,"tv":13598.36,"id":8858694}]}]}
{"op":"mcm","clk":"11890018094","pt":1724177072604,"mc":[{"id":"1.232048439","rc":[{"batb":[[0,3.25,4],[1,3.2,4],[2,3.15,11.5]],"ltp":3.25,"tv":13598.36,"id":8858694}]}]}
{"op":"mcm","clk":"11890018488","pt":1724177075410,"mc":[{"id":"1.232048439","rc":[{"batb":[[0,3.2,4],[1,3.15,11.5],[2,3.1,17.95]],"ltp":3.25,"tv":13598.36,"id":8858694}]}]}
{"op":"mcm","clk":"11890019008","pt":1724177078894,"mc":[{"id":"1.232048439","rc":[{"batb":[[0,3.25,4],[1,3.2,4],[2,3.15,11.5]],"ltp":3.25,"tv":13598.36,"id":8858694}]}]}
{"op":"mcm","clk":"11890019379","pt":1724177081760,"mc":[{"id":"1.232048439","rc":[{"batb":[[0,3.2,4],[1,3.15,11.5],[2,3.1,17.95]],"ltp":3.25,"tv":13598.36,"id":8858694}]}]}
{"op":"mcm","clk":"11890020194","pt":1724177087735,"mc":[{"id":"1.232048439","rc":[{"batb":[[0,3.25,4],[1,3.2,4],[2,3.15,11.5]],"ltp":3.25,"tv":13598.36,"id":8858694}]}]}
{"op":"mcm","clk":"11890020578","pt":1724177090549,"mc":[{"id":"1.232048439","rc":[{"batb":[[0,3.2,4],[1,3.15,11.5],[2,3.1,17.95]],"ltp":3.25,"tv":13598.36,"id":8858694}]}]}
{"op":"mcm","clk":"11890021058","pt":1724177093937,"mc":[{"id":"1.232048439","rc":[{"batb":[[0,3.25,4],[1,3.2,4],[2,3.15,11.5]],"ltp":3.25,"tv":13598.36,"id":8858694}]}]}
{"op":"mcm","clk":"11890021385","pt":1724177096439,"mc":[{"id":"1.232048439","rc":[{"batb":[[0,3.2,4],[1,3.15,11.5],[2,3.1,17.95]],"ltp":3.25,"tv":13598.36,"id":8858694}]}]}
{"op":"mcm","clk":"11890021833","pt":1724177099464,"mc":[{"id":"1.232048439","rc":[{"batb":[[0,3.25,4],[1,3.2,4],[2,3.15,11.5]],"ltp":3.25,"tv":13598.36,"id":8858694}]}]}
{"op":"mcm","clk":"11890022028","pt":1724177100837,"mc":[{"id":"1.232048439","rc":[{"batl":[[0,1.45,4],[1,1.46,17.11],[2,1.47,14]],"ltp":1.42,"tv":113.8,"id":247649}]}]}
{"op":"mcm","clk":"11890022242","pt":1724177102051,"mc":[{"id":"1.232048439","rc":[{"batb":[[0,3.2,4],[1,3.15,11.5],[2,3.1,17.95]],"ltp":3.25,"tv":13598.36,"id":8858694}]}]}
{"op":"mcm","clk":"11890022792","pt":1724177105043,"mc":[{"id":"1.232048439","rc":[{"batb":[[0,3.25,4],[1,3.2,4],[2,3.15,11.5]],"ltp":3.25,"tv":13598.36,"id":8858694}]}]}
{"op":"mcm","clk":"11890023182","pt":1724177107557,"mc":[{"id":"1.232048439","rc":[{"batb":[[0,3.2,4],[1,3.15,11.5],[2,3.1,17.95]],"ltp":3.25,"tv":13598.36,"id":8858694}]}]}
{"op":"mcm","clk":"11890023612","pt":1724177110342,"mc":[{"id":"1.232048439","rc":[{"batb":[[0,3.25,4],[1,3.2,4],[2,3.15,11.5]],"ltp":3.25,"tv":13598.36,"id":8858694}]}]}
{"op":"mcm","clk":"11890024024","pt":1724177113169,"mc":[{"id":"1.232048439","rc":[{"batb":[[0,3.2,4],[1,3.15,11.5],[2,3.1,17.95]],"ltp":3.25,"tv":13598.36,"id":8858694}]}]}
{"op":"mcm","clk":"11890024405","pt":1724177115762,"mc":[{"id":"1.232048439","rc":[{"batb":[[0,3.25,4],[1,3.2,4],[2,3.15,11.5]],"ltp":3.25,"tv":13598.36,"id":8858694}]}]}
{"op":"mcm","clk":"11890024771","pt":1724177118340,"mc":[{"id":"1.232048439","rc":[{"batb":[[0,3.2,4],[1,3.15,11.5],[2,3.1,17.95]],"ltp":3.25,"tv":13598.36,"id":8858694}]}]}
{"op":"mcm","clk":"11890025132","pt":1724177120643,"mc":[{"id":"1.232048439","rc":[{"batb":[[0,3.25,4],[1,3.2,4],[2,3.15,11.5]],"ltp":3.25,"tv":13598.36,"id":8858694}]}]}
{"op":"mcm","clk":"11890025563","pt":1724177123252,"mc":[{"id":"1.232048439","rc":[{"batb":[[0,3.2,4],[1,3.15,11.5],[2,3.1,17.95]],"ltp":3.25,"tv":13598.36,"id":8858694}]}]}
{"op":"mcm","clk":"11890026008","pt":1724177126081,"mc":[{"id":"1.232048439","rc":[{"batb":[[0,3.25,4],[1,3.2,4],[2,3.15,11.5]],"ltp":3.25,"tv":13598.36,"id":8858694}]}]}
{"op":"mcm","clk":"11890026453","pt":1724177128957,"mc":[{"id":"1.232048439","rc":[{"batb":[[0,3.2,4],[1,3.15,11.5],[2,3.1,17.95]],"ltp":3.25,"tv":13598.36,"id":8858694}]}]}
{"op":"mcm","clk":"11890027007","pt":1724177132642,"mc":[{"id":"1.232048439","rc":[{"batb":[[0,3.25,4],[1,3.2,4],[2,3.15,11.5]],"ltp":3.25,"tv":13598.36,"id":8858694}]}]}
{"op":"mcm","clk":"11890027435","pt":1724177135577,"mc":[{"id":"1.232048439","rc":[{"batb":[[0,3.2,4],[1,3.15,11.5],[2,3.1,17.95]],"ltp":3.25,"tv":13598.36,"id":8858694}]}]}
{"op":"mcm","clk":"11890027833","pt":1724177138394,"mc":[{"id":"1.232048439","rc":[{"batb":[[0,3.25,4],[1,3.2,4],[2,3.15,11.5]],"ltp":3.25,"tv":13598.36,"id":8858694}]}]}
{"op":"mcm","clk":"11890028223","pt":1724177141108,"mc":[{"id":"1.232048439","rc":[{"batb":[[0,3.2,4],[1,3.15,11.5],[2,3.1,17.95]],"ltp":3.25,"tv":13598.36,"id":8858694}]}]}
{"op":"mcm","clk":"11890029489","pt":1724177150166,"mc":[{"id":"1.232048439","rc":[{"batb":[[0,3.25,4],[1,3.2,4],[2,3.15,11.5]],"ltp":3.25,"tv":13598.36,"id":8858694}]}]}
{"op":"mcm","clk":"11890030068","pt":1724177153570,"mc":[{"id":"1.232048439","rc":[{"batb":[[0,3.2,4],[1,3.15,11.5],[2,3.1,17.95]],"ltp":3.25,"tv":13598.36,"id":8858694}]}]}
{"op":"mcm","clk":"11890030698","pt":1724177157711,"mc":[{"id":"1.232048439","rc":[{"batb":[[0,3.3,4],[1,3.2,4],[2,3.15,11.5]],"ltp":3.25,"tv":13598.36,"id":8858694}]}]}
{"op":"mcm","clk":"11890031234","pt":1724177161400,"mc":[{"id":"1.232048439","rc":[{"batl":[[0,1.44,4],[1,1.45,4],[2,1.46,17.11]],"ltp":1.42,"tv":113.8,"id":247649}]}]}
{"op":"mcm","clk":"11890031284","pt":1724177161720,"mc":[{"id":"1.232048439","rc":[{"batb":[[1,3.15,7.5],[2,3.1,17.95]],"ltp":3.25,"tv":13598.36,"id":8858694}]}]}
{"op":"mcm","clk":"11890032050","pt":1724177167397,"mc":[{"id":"1.232048439","rc":[{"batl":[[0,1.46,13.11],[1,1.47,14],[2,1.5,5.1]],"ltp":1.42,"tv":113.8,"id":247649},{"batb":[[0,3.15,7.5],[1,3.1,17.95],[2,1.51,25.04]],"ltp":3.25,"tv":13598.36,"id":8858694}]}]}
{"op":"mcm","clk":"11890032249","pt":1724177168975,"mc":[{"id":"1.232048439","rc":[{"batb":[[0,3.35,4],[1,3.15,7.5],[2,3.1,17.95]],"ltp":3.25,"tv":13598.36,"id":8858694}]}]}
{"op":"mcm","clk":"11890032527","pt":1724177171221,"mc":[{"id":"1.232048439","rc":[{"batb":[[1,3.2,10],[2,3.15,7.5]],"ltp":3.25,"tv":13598.36,"id":8858694}]}]}
{"op":"mcm","clk":"11890033067","pt":1724177174891,"mc":[{"id":"1.232048439","rc":[{"batb":[[0,3.2,10],[1,3.15,7.5],[2,3.1,17.95]],"ltp":3.25,"tv":13598.36,"id":8858694}]}]}
{"op":"mcm","clk":"11890033388","pt":1724177177201,"mc":[{"id":"1.232048439","rc":[{"batl":[[0,1.46,17.11]],"ltp":1.42,"tv":113.8,"id":247649},{"batb":[[0,3.25,8],[1,3.2,14],[2,3.15,7.5]],"ltp":3.25,"tv":13598.36,"id":8858694}]}]}
{"op":"mcm","clk":"11890033533","pt":1724177178405,"mc":[{"id":"1.232048439","rc":[{"batb":[[0,3.25,4],[1,3.2,4]],"ltp":3.25,"tv":13598.36,"id":8858694}]}]}
{"op":"mcm","clk":"11890033909","pt":1724177181116,"mc":[{"id":"1.232048439","rc":[{"batb":[[0,3.2,4],[1,3.15,7.5],[2,3.1,17.95]],"ltp":3.25,"tv":13598.36,"id":8858694}]}]}
{"op":"mcm","clk":"11890034427","pt":1724177185021,"mc":[{"id":"1.232048439","rc":[{"batb":[[0,3.25,4],[1,3.2,4],[2,3.15,7.5]],"ltp":3.25,"tv":13598.36,"id":8858694}]}]}
{"op":"mcm","clk":"11890034754","pt":1724177187422,"mc":[{"id":"1.232048439","rc":[{"batb":[[0,3.2,4],[1,3.15,7.5],[2,3.1,17.95]],"ltp":3.25,"tv":13598.36,"id":8858694}]}]}
{"op":"mcm","clk":"11890035106","pt":1724177189994,"mc":[{"id":"1.232048439","rc":[{"batb":[[0,3.25,4],[1,3.2,4],[2,3.15,7.5]],"ltp":3.25,"tv":13598.36,"id":8858694}]}]}
{"op":"mcm","clk":"11890035430","pt":1724177192440,"mc":[{"id":"1.232048439","rc":[{"batl":[[0,1.45,4],[1,1.46,17.11],[2,1.47,14]],"ltp":1.42,"tv":113.8,"id":247649},{"batb":[[0,3.2,4],[1,3.15,7.5],[2,3.1,17.95]],"ltp":3.25,"tv":13598.36,"id":8858694}]}]}
{"op":"mcm","clk":"11890035549","pt":1724177193334,"mc":[{"id":"1.232048439","rc":[{"batb":[[0,1.42,83.67],[1,1.41,95.97],[2,1.11,18.81]],"ltp":1.42,"tv":113.8,"id":247649}]}]}
{"op":"mcm","clk":"11890035815","pt":1724177195047,"mc":[{"id":"1.232048439","rc":[{"batb":[[0,3.25,4],[1,3.2,4],[2,3.15,7.5]],"ltp":3.25,"tv":13598.36,"id":8858694}]}]}
{"op":"mcm","clk":"11890036220","pt":1724177197708,"mc":[{"id":"1.232048439","rc":[{"batb":[[0,3.2,4],[1,3.15,7.5],[2,3.1,17.95]],"ltp":3.25,"tv":13598.36,"id":8858694}]}]}
{"op":"mcm","clk":"11890036550","pt":1724177200243,"mc":[{"id":"1.232048439","rc":[{"batb":[[0,3.25,4],[1,3.2,4],[2,3.15,7.5]],"ltp":3.25,"tv":13598.36,"id":8858694}]}]}
{"op":"mcm","clk":"11890036947","pt":1724177203122,"mc":[{"id":"1.232048439","rc":[{"batb":[[0,3.2,4],[1,3.15,7.5],[2,3.1,17.95]],"ltp":3.25,"tv":13598.36,"id":8858694}]}]}
{"op":"mcm","clk":"11890037288","pt":1724177205636,"mc":[{"id":"1.232048439","rc":[{"batb":[[0,3.25,4],[1,3.2,4],[2,3.15,7.5]],"ltp":3.25,"tv":13598.36,"id":8858694}]}]}
{"op":"mcm","clk":"11890037467","pt":1724177206939,"mc":[{"id":"1.232048439","rc":[{"batb":[[0,1.42,87.67]],"ltp":1.42,"tv":113.8,"id":247649}]}]}
{"op":"mcm","clk":"11890037686","pt":1724177208423,"mc":[{"id":"1.232048439","rc":[{"batb":[[0,3.2,4],[1,3.15,7.5],[2,3.1,17.95]],"ltp":3.25,"tv":13598.36,"id":8858694}]}]}
{"op":"mcm","clk":"11890038009","pt":1724177210959,"mc":[{"id":"1.232048439","rc":[{"batb":[[0,3.25,4],[1,3.2,4],[2,3.15,7.5]],"ltp":3.25,"tv":13598.36,"id":8858694}]}]}
{"op":"mcm","clk":"11890038379","pt":1724177213416,"mc":[{"id":"1.232048439","rc":[{"batb":[[0,3.2,4],[1,3.15,7.5],[2,3.1,17.95]],"ltp":3.25,"tv":13598.36,"id":8858694}]}]}
{"op":"mcm","clk":"11890038670","pt":1724177215719,"mc":[{"id":"1.232048439","rc":[{"batb":[[0,3.25,4],[1,3.2,4],[2,3.15,7.5]],"ltp":3.25,"tv":13598.36,"id":8858694}]}]}
{"op":"mcm","clk":"11890038958","pt":1724177218231,"mc":[{"id":"1.232048439","rc":[{"batb":[[0,3.2,4],[1,3.15,7.5],[2,3.1,17.95]],"ltp":3.25,"tv":13598.36,"id":8858694}]}]}
{"op":"mcm","clk":"11890039530","pt":1724177222276,"mc":[{"id":"1.232048439","rc":[{"batb":[[0,3.25,4],[1,3.2,4],[2,3.15,7.5]],"ltp":3.25,"tv":13598.36,"id":8858694}]}]}
{"op":"mcm","clk":"11890039902","pt":1724177224893,"mc":[{"id":"1.232048439","rc":[{"batb":[[0,3.2,4],[1,3.15,7.5],[2,3.1,17.95]],"ltp":3.25,"tv":13598.36,"id":8858694}]}]}
{"op":"mcm","clk":"11890040600","pt":1724177229296,"mc":[{"id":"1.232048439","rc":[{"batb":[[0,3.25,4],[1,3.2,4],[2,3.15,7.5]],"ltp":3.25,"tv":13598.36,"id":8858694}]}]}
{"op":"mcm","clk":"11890040943","pt":1724177231759,"mc":[{"id":"1.232048439","rc":[{"batb":[[0,3.2,4],[1,3.15,7.5],[2,3.1,17.95]],"ltp":3.25,"tv":13598.36,"id":8858694}]}]}
{"op":"mcm","clk":"11890042045","pt":1724177239006,"mc":[{"id":"1.232048439","rc":[{"batb":[[0,3.25,4],[1,3.2,4],[2,3.15,7.5]],"ltp":3.25,"tv":13598.36,"id":8858694}]}]}
{"op":"mcm","clk":"11890042389","pt":1724177241568,"mc":[{"id":"1.232048439","rc":[{"batb":[[0,3.2,4],[1,3.15,7.5],[2,3.1,17.95]],"ltp":3.25,"tv":13598.36,"id":8858694}]}]}
{"op":"mcm","clk":"11890042708","pt":1724177243814,"mc":[{"id":"1.232048439","rc":[{"batb":[[0,3.25,4],[1,3.2,4],[2,3.15,7.5]],"ltp":3.25,"tv":13598.36,"id":8858694}]}]}
{"op":"mcm","clk":"11890043088","pt":1724177246484,"mc":[{"id":"1.232048439","rc":[{"batb":[[0,1.42,4]],"ltp":1.42,"tv":113.8,"id":247649},{"batb":[[0,3.2,4],[1,3.15,7.5],[2,3.1,17.95]],"ltp":3.25,"tv":13598.36,"id":8858694}]}]}
{"op":"mcm","clk":"11890043505","pt":1724177249627,"mc":[{"id":"1.232048439","rc":[{"batb":[[0,3.25,4],[1,3.2,4],[2,3.15,7.5]],"ltp":3.25,"tv":13598.36,"id":8858694}]}]}
{"op":"mcm","clk":"11890043919","pt":1724177252491,"mc":[{"id":"1.232048439","rc":[{"batb":[[0,3.2,4],[1,3.15,7.5],[2,3.1,17.95]],"ltp":3.25,"tv":13598.36,"id":8858694}]}]}
{"op":"mcm","clk":"11890044378","pt":1724177255519,"mc":[{"id":"1.232048439","rc":[{"batb":[[0,3.25,4],[1,3.2,4],[2,3.15,7.5]],"ltp":3.25,"tv":13598.36,"id":8858694}]}]}
{"op":"mcm","clk":"11890044762","pt":1724177257929,"mc":[{"id":"1.232048439","rc":[{"batb":[[0,3.2,4],[1,3.15,7.5],[2,3.1,17.95]],"ltp":3.25,"tv":13598.36,"id":8858694}]}]}
{"op":"mcm","clk":"11890045622","pt":1724177263629,"mc":[{"id":"1.232048439","rc":[{"batb":[[0,3.25,4],[1,3.2,4],[2,3.15,7.5]],"ltp":3.25,"tv":13598.36,"id":8858694}]}]}
{"op":"mcm","clk":"11890045980","pt":1724177266040,"mc":[{"id":"1.232048439","rc":[{"batb":[[0,3.2,4],[1,3.15,7.5],[2,3.1,17.95]],"ltp":3.25,"tv":13598.36,"id":8858694}]}]}
{"op":"mcm","clk":"11890046425","pt":1724177269323,"mc":[{"id":"1.232048439","rc":[{"batb":[[0,3.25,4],[1,3.2,4],[2,3.15,7.5]],"ltp":3.25,"tv":13598.36,"id":8858694}]}]}
{"op":"mcm","clk":"11890046744","pt":1724177271711,"mc":[{"id":"1.232048439","rc":[{"batb":[[0,3.2,4],[1,3.15,7.5],[2,3.1,17.95]],"ltp":3.25,"tv":13598.36,"id":8858694}]}]}
{"op":"mcm","clk":"11890047093","pt":1724177274331,"mc":[{"id":"1.232048439","rc":[{"batb":[[0,3.25,4],[1,3.2,4],[2,3.15,7.5]],"ltp":3.25,"tv":13598.36,"id":8858694}]}]}
{"op":"mcm","clk":"11890047382","pt":1724177276538,"mc":[{"id":"1.232048439","rc":[{"batb":[[0,3.2,4],[1,3.15,7.5],[2,3.1,17.95]],"ltp":3.25,"tv":13598.36,"id":8858694}]}]}
{"op":"mcm","clk":"11890047849","pt":1724177279749,"mc":[{"id":"1.232048439","rc":[{"batb":[[0,3.25,4],[1,3.2,4],[2,3.15,7.5]],"ltp":3.25,"tv":13598.36,"id":8858694}]}]}
{"op":"mcm","clk":"11890048233","pt":1724177282354,"mc":[{"id":"1.232048439","rc":[{"batb":[[0,3.2,4],[1,3.15,7.5],[2,3.1,17.95]],"ltp":3.25,"tv":13598.36,"id":8858694}]}]}
{"op":"mcm","clk":"11890048963","pt":1724177286930,"mc":[{"id":"1.232048439","rc":[{"batb":[[0,3.25,4],[1,3.2,4],[2,3.15,7.5]],"ltp":3.25,"tv":13598.36,"id":8858694}]}]}
{"op":"mcm","clk":"11890049343","pt":1724177289562,"mc":[{"id":"1.232048439","rc":[{"batb":[[0,3.2,4],[1,3.15,7.5],[2,3.1,17.95]],"ltp":3.25,"tv":13598.36,"id":8858694}]}]}
{"op":"mcm","clk":"11890049653","pt":1724177291829,"mc":[{"id":"1.232048439","rc":[{"batb":[[0,3.25,4],[1,3.2,4],[2,3.15,7.5]],"ltp":3.25,"tv":13598.36,"id":8858694}]}]}
{"op":"mcm","clk":"11890049968","pt":1724177294356,"mc":[{"id":"1.232048439","rc":[{"batb":[[0,3.2,4],[1,3.15,7.5],[2,3.1,17.95]],"ltp":3.25,"tv":13598.36,"id":8858694}]}]}
{"op":"mcm","clk":"11890051932","pt":1724177305285,"mc":[{"id":"1.232048439","rc":[{"batb":[[0,3.25,4],[1,3.2,4],[2,3.15,7.5]],"ltp":3.25,"tv":13598.36,"id":8858694}]}]}
{"op":"mcm","clk":"11890052282","pt":1724177307641,"mc":[{"id":"1.232048439","rc":[{"batb":[[0,3.2,4],[1,3.15,7.5],[2,3.1,17.95]],"ltp":3.25,"tv":13598.36,"id":8858694}]}]}
{"op":"mcm","clk":"11890053715","pt":1724177315794,"mc":[{"id":"1.232048439","rc":[{"batb":[[0,3.25,4],[1,3.2,4],[2,3.15,7.5]],"ltp":3.25,"tv":13598.36,"id":8858694}]}]}
{"op":"mcm","clk":"11890054185","pt":1724177318373,"mc":[{"id":"1.232048439","rc":[{"batb":[[0,3.2,4],[1,3.15,7.5],[2,3.1,17.95]],"ltp":3.25,"tv":13598.36,"id":8858694}]}]}
{"op":"mcm","clk":"11890054972","pt":1724177323481,"mc":[{"id":"1.232048439","rc":[{"batb":[[0,3.25,4],[1,3.2,4],[2,3.15,7.5]],"ltp":3.25,"tv":13598.36,"id":8858694}]}]}
{"op":"mcm","clk":"11890055303","pt":1724177325755,"mc":[{"id":"1.232048439","rc":[{"batb":[[0,3.2,4],[1,3.15,7.5],[2,3.1,17.95]],"ltp":3.25,"tv":13598.36,"id":8858694}]}]}
{"op":"mcm","clk":"11890055862","pt":1724177329473,"mc":[{"id":"1.232048439","rc":[{"batb":[[0,3.25,4],[1,3.2,4],[2,3.15,7.5]],"ltp":3.25,"tv":13598.36,"id":8858694}]}]}
{"op":"mcm","clk":"11890056262","pt":1724177332267,"mc":[{"id":"1.232048439","rc":[{"batb":[[0,3.2,4],[1,3.15,7.5],[2,3.1,17.95]],"ltp":3.25,"tv":13598.36,"id":8858694}]}]}
{"op":"mcm","clk":"11890056568","pt":1724177334563,"mc":[{"id":"1.232048439","rc":[{"batb":[[0,3.25,4],[1,3.2,4],[2,3.15,7.5]],"ltp":3.25,"tv":13598.36,"id":8858694}]}]}
{"op":"mcm","clk":"11890056969","pt":1724177337396,"mc":[{"id":"1.232048439","rc":[{"batb":[[0,3.2,4],[1,3.15,7.5],[2,3.1,17.95]],"ltp":3.25,"tv":13598.36,"id":8858694}]}]}
{"op":"mcm","clk":"11890057120","pt":1724177338507,"mc":[{"id":"1.232048439","rc":[{"trd":[[1.42,46.95]],"batb":[[0,1.41,95.97],[1,1.11,18.81],[2,1.04,1635.11]],"batl":[[0,1.42,12.76],[1,1.45,4],[2,1.46,17.11]],"ltp":1.42,"tv":121.8,"id":247649}],"tv":13720.17}]}
{"op":"mcm","clk":"11890057678","pt":1724177342098,"mc":[{"id":"1.232048439","rc":[{"batb":[[0,3.25,4],[1,3.2,4],[2,3.15,7.5]],"ltp":3.25,"tv":13598.36,"id":8858694}]}]}
{"op":"mcm","clk":"11890057816","pt":1724177342992,"mc":[{"id":"1.232048439","rc":[{"batl":[[1,1.44,5.17],[2,1.45,4]],"ltp":1.42,"tv":121.8,"id":247649},{"batb":[[1,3.15,7.5],[2,3.1,17.95]],"ltp":3.25,"tv":13598.36,"id":8858694}]}]}
{"op":"mcm","clk":"11890058024","pt":1724177344202,"mc":[{"id":"1.232048439","rc":[{"batl":[[0,1.42,12.83],[1,1.44,13.3],[2,1.47,14]],"ltp":1.42,"tv":121.8,"id":247649}]}]}
{"op":"mcm","clk":"11890058165","pt":1724177345097,"mc":[{"id":"1.232048439","rc":[{"batb":[[0,3.2,10]],"ltp":3.25,"tv":13598.36,"id":8858694}]}]}
{"op":"mcm","clk":"11890058529","pt":1724177347306,"mc":[{"id":"1.232048439","rc":[{"batb":[[0,3.25,4],[1,3.2,10],[2,3.15,7.5]],"ltp":3.25,"tv":13598.36,"id":8858694}]}]}
{"op":"mcm","clk":"11890058657","pt":1724177348097,"mc":[{"id":"1.232048439","rc":[{"batl":[[0,1.44,13.37],[1,1.47,14],[2,1.5,5.1]],"ltp":1.42,"tv":121.8,"id":247649},{"batb":[[0,3.25,11.27],[2,3.1,17.95]],"ltp":3.25,"tv":13598.36,"id":8858694}]}]}
{"op":"mcm","clk":"11890058722","pt":1724177348516,"mc":[{"id":"1.232048439","rc":[{"batb":[[1,3.1,17.95],[2,1.51,25.04]],"ltp":3.25,"tv":13598.36,"id":8858694}]}]}
{"op":"mcm","clk":"11890058946","pt":1724177349991,"mc":[{"id":"1.232048439","rc":[{"batb":[[0,3.25,7.27]],"ltp":3.25,"tv":13598.36,"id":8858694}]}]}
{"op":"mcm","clk":"11890059114","pt":1724177351094,"mc":[{"id":"1.232048439","rc":[{"batb":[[0,3.15,17.5]],"ltp":3.25,"tv":13598.36,"id":8858694}]}]}
{"op":"mcm","clk":"11890059315","pt":1724177352302,"mc":[{"id":"1.232048439","rc":[{"batb":[[0,3.2,4],[1,3.15,17.5],[2,3.1,17.95]],"ltp":3.25,"tv":13598.36,"id":8858694}]}]}
{"op":"mcm","clk":"11890059480","pt":1724177353350,"mc":[{"id":"1.232048439","rc":[{"batl":[[0,1.46,13.18]],"ltp":1.42,"tv":121.8,"id":247649}]}]}
{"op":"mcm","clk":"11890059681","pt":1724177354410,"mc":[{"id":"1.232048439","rc":[{"batb":[[1,3.15,7.5]],"ltp":3.25,"tv":13598.36,"id":8858694}]}]}
{"op":"mcm","clk":"11890059858","pt":1724177355302,"mc":[{"id":"1.232048439","rc":[{"batb":[[0,3.15,7.5],[1,3.1,17.95],[2,1.51,25.04]],"ltp":3.25,"tv":13598.36,"id":8858694}]}]}
{"op":"mcm","clk":"11890060209","pt":1724177357827,"mc":[{"id":"1.232048439","rc":[{"batl":[[0,1.46,13.11]],"ltp":1.42,"tv":121.8,"id":247649},{"batb":[[0,3.2,14],[1,3.15,7.5],[2,3.1,17.95]],"ltp":3.25,"tv":13598.36,"id":8858694}]}]}
{"op":"mcm","clk":"11890060424","pt":1724177359314,"mc":[{"id":"1.232048439","rc":[{"batl":[[0,1.46,17.11]],"ltp":1.42,"tv":121.8,"id":247649},{"batb":[[0,3.25,4],[1,3.2,18]],"ltp":3.25,"tv":13598.36,"id":8858694}]}]}
{"op":"mcm","clk":"11890060614","pt":1724177360426,"mc":[{"id":"1.232048439","rc":[{"batb":[[1,3.2,14]],"ltp":3.25,"tv":13598.36,"id":8858694}]}]}
{"op":"mcm","clk":"11890060814","pt":1724177361433,"mc":[{"id":"1.232048439","rc":[{"batb":[[1,3.2,4]],"ltp":3.25,"tv":13598.36,"id":8858694}]}]}
{"op":"mcm","clk":"11890060927","pt":1724177362020,"mc":[{"id":"1.232048439","rc":[{"batb":[[0,3.1,17.95],[1,1.51,25.04],[2,1.11,18.81]],"ltp":3.25,"tv":13598.36,"id":8858694}]}]}
{"op":"mcm","clk":"11890061130","pt":1724177363281,"mc":[{"id":"1.232048439","rc":[{"batb":[[0,3.15,4],[1,3.1,17.95],[2,1.51,25.04]],"ltp":3.25,"tv":13598.36,"id":8858694}]}]}
{"op":"mcm","clk":"11890061213","pt":1724177363860,"mc":[{"id":"1.232048439","rc":[{"batb":[[0,3.2,10],[1,3.15,4],[2,3.1,17.95]],"ltp":3.25,"tv":13598.36,"id":8858694}]}]}
{"op":"mcm","clk":"11890061433","pt":1724177365252,"mc":[{"id":"1.232048439","rc":[{"batb":[[0,3.2,17.38]],"ltp":3.25,"tv":13598.36,"id":8858694}]}]}
{"op":"mcm","clk":"11890061567","pt":1724177365986,"mc":[{"id":"1.232048439","rc":[{"batb":[[1,3.1,17.95],[2,1.51,25.04]],"ltp":3.25,"tv":13598.36,"id":8858694}]}]}
{"op":"mcm","clk":"11890061728","pt":1724177367084,"mc":[{"id":"1.232048439","rc":[{"batb":[[0,3.2,10]],"ltp":3.25,"tv":13598.36,"id":8858694}]}]}
{"op":"mcm","clk":"11890061795","pt":1724177367480,"mc":[{"id":"1.232048439","rc":[{"batb":[[0,3.1,17.95],[1,1.51,25.04],[2,1.11,18.81]],"ltp":3.25,"tv":13598.36,"id":8858694}]}]}
{"op":"mcm","clk":"11890062009","pt":1724177368664,"mc":[{"id":"1.232048439","rc":[{"batb":[[0,3.15,4],[1,3.1,17.95],[2,1.51,25.04]],"ltp":3.25,"tv":13598.36,"id":8858694}]}]}
{"op":"mcm","clk":"11890062261","pt":1724177370076,"mc":[{"id":"1.232048439","rc":[{"batb":[[0,3.2,10],[1,3.15,4],[2,3.1,17.95]],"ltp":3.25,"tv":13598.36,"id":8858694}]}]}
{"op":"mcm","clk":"11890062446","pt":1724177371172,"mc":[{"id":"1.232048439","rc":[{"batb":[[1,3.1,17.95],[2,1.51,25.04]],"ltp":3.25,"tv":13598.36,"id":8858694}]}]}
{"op":"mcm","clk":"11890062950","pt":1724177374172,"mc":[{"id":"1.232048439","rc":[{"batb":[[0,3.15,4]],"ltp":3.25,"tv":13598.36,"id":8858694}]}]}
{"op":"mcm","clk":"11890063267","pt":1724177376310,"mc":[{"id":"1.232048439","rc":[{"batb":[[0,3.1,17.95],[1,1.51,25.04],[2,1.11,18.81]],"ltp":3.25,"tv":13598.36,"id":8858694}]}]}
{"op":"mcm","clk":"11890063429","pt":1724177377313,"mc":[{"id":"1.232048439","rc":[{"batl":[[0,1.44,16.76],[1,1.46,17.11],[2,1.47,14]],"ltp":1.42,"tv":121.8,"id":247649},{"batb":[[0,3.15,10],[1,3.1,17.95],[2,1.51,25.04]],"ltp":3.25,"tv":13598.36,"id":8858694}]}]}
{"op":"mcm","clk":"11890063697","pt":1724177378980,"mc":[{"id":"1.232048439","rc":[{"batb":[[0,3.2,4],[1,3.15,10],[2,3.1,17.95]],"ltp":3.25,"tv":13598.36,"id":8858694}]}]}
{"op":"mcm","clk":"11890063804","pt":1724177379670,"mc":[{"id":"1.232048439","rc":[{"batb":[[1,3.1,17.95],[2,1.51,25.04]],"ltp":3.25,"tv":13598.36,"id":8858694}]}]}
{"op":"mcm","clk":"11890064162","pt":1724177381890,"mc":[{"id":"1.232048439","rc":[{"batb":[[0,3.15,10]],"ltp":3.25,"tv":13598.36,"id":8858694}]}]}
{"op":"mcm","clk":"11890064681","pt":1724177385410,"mc":[{"id":"1.232048439","rc":[{"batb":[[0,3.1,17.95],[1,1.51,25.04],[2,1.11,18.81]],"ltp":3.25,"tv":13598.36,"id":8858694}]}]}
{"op":"mcm","clk":"11890064727","pt":1724177385679,"mc":[{"id":"1.232048439","rc":[{"batb":[[0,3.2,4],[1,3.1,17.95],[2,1.51,25.04]],"ltp":3.25,"tv":13598.36,"id":8858694}]}]}
