{"op":"mcm","clk":"11754684545","pt":1722423340378,"mc":[{"id":"1.231284093","marketDefinition":{"bspMarket":false,"turnInPlayEnabled":true,"persistenceEnabled":true,"marketBaseRate":5.0,"eventId":"33458119","eventTypeId":"4","numberOfWinners":1,"bettingType":"ODDS","marketType":"MATCH_ODDS","marketTime":"2024-08-02T10:00:00.000Z","suspendTime":"2024-08-02T10:00:00.000Z","bspReconciled":false,"complete":true,"inPlay":false,"crossMatching":false,"runnersVoidable":false,"numberOfActiveRunners":2,"betDelay":0,"status":"OPEN","runners":[{"status":"ACTIVE","sortPriority":1,"id":5995,"name":"Somerset"},{"status":"ACTIVE","sortPriority":2,"id":424679,"name":"Lancashire"}],"regulators":["MR_INT"],"countryCode":"GB","discountAllowed":false,"timezone":"GMT","openDate":"2024-08-02T10:00:00.000Z","version":6048600914,"name":"Match Odds","eventName":"Somerset v Lancashire"},"rc":[{"batb":[[0,1.03,200],[1,1.02,200],[2,1.01,220]],"ltp":0.0,"tv":0.0,"id":424679},{"batb":[[0,1.03,200],[1,1.02,200],[2,1.01,220]],"ltp":0.0,"tv":0.0,"id":5995}]}]}
{"op":"mcm","clk":"11754684640","pt":1722423341407,"mc":[{"id":"1.231284093","marketDefinition":{"bspMarket":false,"turnInPlayEnabled":true,"persistenceEnabled":true,"marketBaseRate":5.0,"eventId":"33458119","eventTypeId":"4","numberOfWinners":1,"bettingType":"ODDS","marketType":"MATCH_ODDS","marketTime":"2024-08-02T10:00:00.000Z","suspendTime":"2024-08-02T10:00:00.000Z","bspReconciled":false,"complete":true,"inPlay":false,"crossMatching":false,"runnersVoidable":false,"numberOfActiveRunners":2,"betDelay":0,"status":"OPEN","runners":[{"status":"ACTIVE","sortPriority":1,"id":5995,"name":"Somerset"},{"status":"ACTIVE","sortPriority":2,"id":424679,"name":"Lancashire"}],"regulators":["MR_INT"],"countryCode":"GB","discountAllowed":true,"timezone":"GMT","openDate":"2024-08-02T10:00:00.000Z","version":6048600914,"name":"Match Odds","eventName":"Somerset v Lancashire"}}]}
{"op":"mcm","clk":"11755681547","pt":1722436415943,"mc":[{"id":"1.231284093","rc":[{"batb":[[0,1.06,5.64],[1,1.03,200],[2,1.02,200]],"ltp":0.0,"tv":0.0,"id":424679}]}]}
{"op":"mcm","clk":"11755682577","pt":1722436427350,"mc":[{"id":"1.231284093","rc":[{"batb":[[0,1.25,4.39],[1,1.03,200],[2,1.02,200]],"ltp":0.0,"tv":0.0,"id":5995}]}]}
{"op":"mcm","clk":"11756692545","pt":1722445172372,"mc":[{"id":"1.231284093","rc":[{"batb":[[0,2.14,32.42],[1,1.06,5.64],[2,1.03,200]],"ltp":0.0,"tv":0.0,"id":424679},{"batb":[[0,1.8,46.2],[1,1.25,4.39],[2,1.03,200]],"ltp":0.0,"tv":0.0,"id":5995}]}]}
{"op":"mcm","clk":"11756692838","pt":1722445175481,"mc":[{"id":"1.231284093","marketDefinition":{"bspMarket":false,"turnInPlayEnabled":true,"persistenceEnabled":true,"marketBaseRate":5.0,"eventId":"33458119","eventTypeId":"4","numberOfWinners":1,"bettingType":"ODDS","marketType":"MATCH_ODDS","marketTime":"2024-08-02T10:00:00.000Z","suspendTime":"2024-08-02T10:00:00.000Z","bspReconciled":false,"complete":true,"inPlay":false,"crossMatching":true,"runnersVoidable":false,"numberOfActiveRunners":2,"betDelay":0,"status":"OPEN","runners":[{"status":"ACTIVE","sortPriority":1,"id":5995,"name":"Somerset"},{"status":"ACTIVE","sortPriority":2,"id":424679,"name":"Lancashire"}],"regulators":["MR_INT"],"countryCode":"GB","discountAllowed":true,"timezone":"GMT","openDate":"2024-08-02T10:00:00.000Z","version":6048600914,"name":"Match Odds","eventName":"Somerset v Lancashire"}}]}
{"op":"mcm","clk":"11756786114","pt":1722446036296,"mc":[{"id":"1.231284093","rc":[{"batb":[[1,1.28,178.57],[2,1.23,217.39]],"ltp":0.0,"tv":0.0,"id":424679},{"batb":[[1,1.25,4.39],[2,1.23,217.39]],"ltp":0.0,"tv":0.0,"id":5995}]}]}
{"op":"mcm","clk":"11756786157","pt":1722446036707,"mc":[{"id":"1.231284093","rc":[{"batb":[[1,1.43,116.28],[2,1.38,131.58]],"ltp":0.0,"tv":0.0,"id":424679},{"batb":[[1,1.43,116.28],[2,1.38,131.58]],"ltp":0.0,"tv":0.0,"id":5995}]}]}
{"op":"mcm","clk":"11757069415","pt":1722448529777,"mc":[{"id":"1.231284093","rc":[{"batl":[[0,1.87,35.45]],"ltp":0.0,"tv":0.0,"id":5995}]}]}
{"op":"mcm","clk":"11757140222","pt":1722449186126,"mc":[{"id":"1.231284093","rc":[{"batb":[[0,1.43,116.28],[1,1.38,131.58],[2,1.33,151.52]],"ltp":0.0,"tv":0.0,"id":424679},{"batb":[[0,1.43,116.28],[1,1.38,131.58],[2,1.33,151.52]],"ltp":0.0,"tv":0.0,"id":5995}]}]}
{"op":"mcm","clk":"11757140509","pt":1722449187888,"mc":[{"id":"1.231284093","rc":[{"batb":[[0,2.14,32.42],[1,1.43,116.28],[2,1.38,131.58]],"ltp":0.0,"tv":0.0,"id":424679},{"batb":[[0,1.8,46.2],[1,1.43,116.28],[2,1.38,131.58]],"ltp":0.0,"tv":0.0,"id":5995}]}]}
{"op":"mcm","clk":"11757581543","pt":1722452469374,"mc":[{"id":"1.231284093","rc":[{"batb":[[0,1.43,116.28],[1,1.38,131.58],[2,1.33,151.52]],"ltp":0.0,"tv":0.0,"id":424679},{"batb":[[0,1.43,116.28],[1,1.38,131.58],[2,1.33,151.52]],"ltp":0.0,"tv":0.0,"id":5995}]}]}
{"op":"mcm","clk":"11757714442","pt":1722453440812,"mc":[{"id":"1.231284093","rc":[{"batb":[[0,1.44,6.99],[1,1.43,116.28],[2,1.38,131.58]],"ltp":0.0,"tv":0.0,"id":5995}]}]}
{"op":"mcm","clk":"11757763247","pt":1722453796768,"mc":[{"id":"1.231284093","rc":[{"batb":[[0,1.44,13.04]],"ltp":0.0,"tv":0.0,"id":5995}]}]}
{"op":"mcm","clk":"11757888550","pt":1722454689959,"mc":[{"id":"1.231284093","rc":[{"batb":[[0,2.14,32.42],[1,1.43,116.28],[2,1.38,131.58]],"ltp":0.0,"tv":0.0,"id":424679},{"batb":[[0,1.8,46.2],[1,1.44,13.04],[2,1.43,116.28]],"ltp":0.0,"tv":0.0,"id":5995}]}]}
{"op":"mcm","clk":"11757889097","pt":1722454693256,"mc":[{"id":"1.231284093","rc":[{"batb":[[1,1.44,6.99]],"ltp":0.0,"tv":0.0,"id":5995}]}]}
{"op":"mcm","clk":"11758011472","pt":1722455604783,"mc":[{"id":"1.231284093","rc":[{"batb":[[1,1.43,116.28],[2,1.38,131.58]],"ltp":0.0,"tv":0.0,"id":5995}]}]}
{"op":"mcm","clk":"11758082278","pt":1722456291840,"mc":[{"id":"1.231284093","rc":[{"batl":[[0,1.82,35.45]],"ltp":0.0,"tv":0.0,"id":5995}]}]}
{"op":"mcm","clk":"11758093136","pt":1722456414199,"mc":[{"id":"1.231284093","rc":[{"trd":[[1.8,70.9]],"batb":[[0,1.8,10.75]],"ltp":1.8,"tv":70.9,"id":5995}],"tv":70.9}]}
{"op":"mcm","clk":"11758093413","pt":1722456417167,"mc":[{"id":"1.231284093","rc":[{"batb":[[0,1.8,46.2]],"ltp":1.8,"tv":70.9,"id":5995}]}]}
{"op":"mcm","clk":"11759410626","pt":1722478419340,"mc":[{"id":"1.231284093","marketDefinition":{"bspMarket":false,"turnInPlayEnabled":true,"persistenceEnabled":true,"marketBaseRate":5.0,"eventId":"33458119","eventTypeId":"4","numberOfWinners":1,"bettingType":"ODDS","marketType":"MATCH_ODDS","marketTime":"2024-08-02T13:00:00.000Z","suspendTime":"2024-08-02T13:00:00.000Z","bspReconciled":false,"complete":true,"inPlay":false,"crossMatching":true,"runnersVoidable":false,"numberOfActiveRunners":2,"betDelay":0,"status":"OPEN","runners":[{"status":"ACTIVE","sortPriority":1,"id":5995,"name":"Somerset"},{"status":"ACTIVE","sortPriority":2,"id":424679,"name":"Lancashire"}],"regulators":["MR_INT"],"countryCode":"GB","discountAllowed":true,"timezone":"GMT","openDate":"2024-08-02T10:00:00.000Z","version":6049982268,"name":"Match Odds","eventName":"Somerset v Lancashire"}}]}
{"op":"mcm","clk":"11759410703","pt":1722478420360,"mc":[{"id":"1.231284093","marketDefinition":{"bspMarket":false,"turnInPlayEnabled":true,"persistenceEnabled":true,"marketBaseRate":5.0,"eventId":"33458119","eventTypeId":"4","numberOfWinners":1,"bettingType":"ODDS","marketType":"MATCH_ODDS","marketTime":"2024-08-02T13:00:00.000Z","suspendTime":"2024-08-02T13:00:00.000Z","bspReconciled":false,"complete":true,"inPlay":false,"crossMatching":true,"runnersVoidable":false,"numberOfActiveRunners":2,"betDelay":0,"status":"OPEN","runners":[{"status":"ACTIVE","sortPriority":1,"id":5995,"name":"Somerset"},{"status":"ACTIVE","sortPriority":2,"id":424679,"name":"Lancashire"}],"regulators":["MR_INT"],"countryCode":"GB","discountAllowed":true,"timezone":"GMT","openDate":"2024-08-02T13:00:00.000Z","version":6049982268,"name":"Match Odds","eventName":"Somerset v Lancashire"}}]}
{"op":"mcm","clk":"11759783333","pt":1722484847516,"mc":[{"id":"1.231284093","rc":[{"batl":[[0,1.83,4.5]],"ltp":1.8,"tv":70.9,"id":5995}]}]}
{"op":"mcm","clk":"11759822882","pt":1722486196650,"mc":[{"id":"1.231284093","rc":[{"trd":[[1.8,83.7]],"batb":[[0,1.8,39.8]],"ltp":1.8,"tv":83.7,"id":5995}],"tv":83.7}]}
{"op":"mcm","clk":"11759822918","pt":1722486199979,"mc":[{"id":"1.231284093","rc":[{"batb":[[0,1.8,46.2]],"ltp":1.8,"tv":83.7,"id":5995}]}]}
{"op":"mcm","clk":"11760457163","pt":1722501731488,"mc":[{"id":"1.231284093","rc":[{"batb":[[0,1.43,116.28],[1,1.38,131.58],[2,1.33,151.52]],"ltp":0.0,"tv":0.0,"id":424679},{"batb":[[0,1.43,116.28],[1,1.38,131.58],[2,1.33,151.52]],"ltp":1.8,"tv":83.7,"id":5995}]}]}
{"op":"mcm","clk":"11760458131","pt":1722501746179,"mc":[{"id":"1.231284093","rc":[{"batb":[[0,1.44,5.71],[1,1.43,116.28],[2,1.38,131.58]],"ltp":1.8,"tv":83.7,"id":5995}]}]}
{"op":"mcm","clk":"11760527920","pt":1722503021906,"mc":[{"id":"1.231284093","rc":[{"batb":[[0,1.45,10],[1,1.44,5.7],[2,1.43,116.28]],"batl":[[0,2.98,0.96]],"ltp":1.8,"tv":83.7,"id":5995}]}]}
{"op":"mcm","clk":"11760527987","pt":1722503023095,"mc":[{"id":"1.231284093","rc":[{"batb":[[1,1.43,116.28],[2,1.38,131.58]],"ltp":1.8,"tv":83.7,"id":5995}]}]}
{"op":"mcm","clk":"11760528110","pt":1722503025317,"mc":[{"id":"1.231284093","rc":[{"batb":[[0,1.43,116.28],[1,1.38,131.58],[2,1.33,151.52]],"ltp":1.8,"tv":83.7,"id":5995}]}]}
{"op":"mcm","clk":"11760528246","pt":1722503027974,"mc":[{"id":"1.231284093","rc":[{"batb":[[0,1.44,10],[1,1.43,116.28],[2,1.38,131.58]],"ltp":1.8,"tv":83.7,"id":5995}]}]}
{"op":"mcm","clk":"11760528403","pt":1722503031386,"mc":[{"id":"1.231284093","rc":[{"batb":[[0,1.43,116.28],[1,1.38,131.58],[2,1.33,151.52]],"ltp":1.8,"tv":83.7,"id":5995}]}]}
{"op":"mcm","clk":"11760528415","pt":1722503031587,"mc":[{"id":"1.231284093","rc":[{"batb":[[0,1.44,5.71],[1,1.43,116.28],[2,1.38,131.58]],"ltp":1.8,"tv":83.7,"id":5995}]}]}
{"op":"mcm","clk":"11760528530","pt":1722503033813,"mc":[{"id":"1.231284093","rc":[{"batl":[[0,2.98,0.96]],"ltp":0.0,"tv":0.0,"id":424679}]}]}
{"op":"mcm","clk":"11760528589","pt":1722503034797,"mc":[{"id":"1.231284093","rc":[{"batb":[[0,1.45,10],[1,1.44,5.71],[2,1.43,116.28]],"ltp":1.8,"tv":83.7,"id":5995}]}]}
{"op":"mcm","clk":"11760528651","pt":1722503035823,"mc":[{"id":"1.231284093","rc":[{"batb":[[1,1.43,116.28],[2,1.38,131.58]],"ltp":1.8,"tv":83.7,"id":5995}]}]}
{"op":"mcm","clk":"11760528800","pt":1722503039240,"mc":[{"id":"1.231284093","rc":[{"batb":[[0,1.43,116.28],[1,1.38,131.58],[2,1.33,151.52]],"ltp":1.8,"tv":83.7,"id":5995}]}]}
{"op":"mcm","clk":"11760528969","pt":1722503042405,"mc":[{"id":"1.231284093","rc":[{"batb":[[0,1.44,10],[1,1.43,116.28],[2,1.38,131.58]],"ltp":1.8,"tv":83.7,"id":5995}]}]}
{"op":"mcm","clk":"11760529133","pt":1722503046017,"mc":[{"id":"1.231284093","rc":[{"batb":[[0,1.43,116.28],[1,1.38,131.58],[2,1.33,151.52]],"ltp":1.8,"tv":83.7,"id":5995}]}]}
{"op":"mcm","clk":"11760529294","pt":1722503049197,"mc":[{"id":"1.231284093","rc":[{"batb":[[0,1.44,10],[1,1.43,116.28],[2,1.38,131.58]],"ltp":1.8,"tv":83.7,"id":5995}]}]}
{"op":"mcm","clk":"11760529496","pt":1722503052502,"mc":[{"id":"1.231284093","rc":[{"batb":[[0,1.43,116.28],[1,1.38,131.58],[2,1.33,151.52]],"ltp":1.8,"tv":83.7,"id":5995}]}]}
{"op":"mcm","clk":"11760529589","pt":1722503054721,"mc":[{"id":"1.231284093","rc":[{"batb":[[0,1.44,10],[1,1.43,116.28],[2,1.38,131.58]],"ltp":1.8,"tv":83.7,"id":5995}]}]}
{"op":"mcm","clk":"11760529856","pt":1722503059718,"mc":[{"id":"1.231284093","rc":[{"batb":[[0,1.43,116.28],[1,1.38,131.58],[2,1.33,151.52]],"ltp":1.8,"tv":83.7,"id":5995}]}]}
{"op":"mcm","clk":"11760530092","pt":1722503063835,"mc":[{"id":"1.231284093","rc":[{"batb":[[0,1.44,10],[1,1.43,116.28],[2,1.38,131.58]],"ltp":1.8,"tv":83.7,"id":5995}]}]}
{"op":"mcm","clk":"11760530292","pt":1722503067177,"mc":[{"id":"1.231284093","rc":[{"batb":[[0,1.43,116.28],[1,1.38,131.58],[2,1.33,151.52]],"ltp":1.8,"tv":83.7,"id":5995}]}]}
{"op":"mcm","clk":"11760530470","pt":1722503070132,"mc":[{"id":"1.231284093","rc":[{"batb":[[0,1.44,10],[1,1.43,116.28],[2,1.38,131.58]],"ltp":1.8,"tv":83.7,"id":5995}]}]}
{"op":"mcm","clk":"11760530652","pt":1722503073654,"mc":[{"id":"1.231284093","rc":[{"batb":[[0,1.43,116.28],[1,1.38,131.58],[2,1.33,151.52]],"ltp":1.8,"tv":83.7,"id":5995}]}]}
{"op":"mcm","clk":"11760530700","pt":1722503074438,"mc":[{"id":"1.231284093","rc":[{"batb":[[0,1.44,5.8],[1,1.43,116.28],[2,1.38,131.58]],"ltp":0.0,"tv":0.0,"id":424679}]}]}
{"op":"mcm","clk":"11760530783","pt":1722503076052,"mc":[{"id":"1.231284093","rc":[{"batb":[[0,1.44,10],[1,1.43,116.28],[2,1.38,131.58]],"ltp":1.8,"tv":83.7,"id":5995}]}]}
{"op":"mcm","clk":"11760531037","pt":1722503080830,"mc":[{"id":"1.231284093","rc":[{"batb":[[0,1.43,116.28],[1,1.38,131.58],[2,1.33,151.52]],"ltp":1.8,"tv":83.7,"id":5995}]}]}
{"op":"mcm","clk":"11760531187","pt":1722503083754,"mc":[{"id":"1.231284093","rc":[{"batb":[[0,1.44,10],[1,1.43,116.28],[2,1.38,131.58]],"ltp":1.8,"tv":83.7,"id":5995}]}]}
{"op":"mcm","clk":"11760531343","pt":1722503087037,"mc":[{"id":"1.231284093","rc":[{"batb":[[0,1.43,116.28],[1,1.38,131.58],[2,1.33,151.52]],"ltp":1.8,"tv":83.7,"id":5995}]}]}
{"op":"mcm","clk":"11760531506","pt":1722503090265,"mc":[{"id":"1.231284093","rc":[{"batb":[[0,1.44,10],[1,1.43,116.28],[2,1.38,131.58]],"ltp":1.8,"tv":83.7,"id":5995}]}]}
{"op":"mcm","clk":"11760531718","pt":1722503093965,"mc":[{"id":"1.231284093","rc":[{"batb":[[0,1.43,116.28],[1,1.38,131.58],[2,1.33,151.52]],"ltp":1.8,"tv":83.7,"id":5995}]}]}
{"op":"mcm","clk":"11760531850","pt":1722503097089,"mc":[{"id":"1.231284093","rc":[{"batb":[[0,1.44,10],[1,1.43,116.28],[2,1.38,131.58]],"ltp":1.8,"tv":83.7,"id":5995}]}]}
{"op":"mcm","clk":"11760532011","pt":1722503100580,"mc":[{"id":"1.231284093","rc":[{"batb":[[0,1.43,116.28],[1,1.38,131.58],[2,1.33,151.52]],"ltp":1.8,"tv":83.7,"id":5995}]}]}
{"op":"mcm","clk":"11760532201","pt":1722503104590,"mc":[{"id":"1.231284093","rc":[{"batb":[[0,1.44,10],[1,1.43,116.28],[2,1.38,131.58]],"ltp":1.8,"tv":83.7,"id":5995}]}]}
{"op":"mcm","clk":"11760532356","pt":1722503107873,"mc":[{"id":"1.231284093","rc":[{"batb":[[0,1.43,116.28],[1,1.38,131.58],[2,1.33,151.52]],"ltp":1.8,"tv":83.7,"id":5995}]}]}
{"op":"mcm","clk":"11760532492","pt":1722503110291,"mc":[{"id":"1.231284093","rc":[{"batb":[[0,1.44,10],[1,1.43,116.28],[2,1.38,131.58]],"ltp":1.8,"tv":83.7,"id":5995}]}]}
{"op":"mcm","clk":"11760532674","pt":1722503113788,"mc":[{"id":"1.231284093","rc":[{"batb":[[0,1.43,116.28],[1,1.38,131.58],[2,1.33,151.52]],"ltp":1.8,"tv":83.7,"id":5995}]}]}
{"op":"mcm","clk":"11760532818","pt":1722503116417,"mc":[{"id":"1.231284093","rc":[{"batb":[[0,1.44,10],[1,1.43,116.28],[2,1.38,131.58]],"ltp":1.8,"tv":83.7,"id":5995}]}]}
{"op":"mcm","clk":"11760532994","pt":1722503119583,"mc":[{"id":"1.231284093","rc":[{"trd":[[2.98,0.04]],"batl":[[0,2.98,0.92]],"ltp":2.98,"tv":0.03,"id":424679},{"trd":[[1.5,0.07]],"batb":[[0,1.43,116.28],[1,1.38,131.58],[2,1.33,151.52]],"ltp":1.5,"tv":83.77,"id":5995}],"tv":83.8}]}
{"op":"mcm","clk":"11760533066","pt":1722503121067,"mc":[{"id":"1.231284093","rc":[{"batb":[[0,1.45,10],[1,1.44,5.8],[2,1.43,116.28]],"ltp":2.98,"tv":0.03,"id":424679}]}]}
{"op":"mcm","clk":"11760533164","pt":1722503122869,"mc":[{"id":"1.231284093","rc":[{"batb":[[0,1.44,10],[1,1.43,116.28],[2,1.38,131.58]],"ltp":1.5,"tv":83.77,"id":5995}]}]}
{"op":"mcm","clk":"11760533203","pt":1722503123591,"mc":[{"id":"1.231284093","rc":[{"batb":[[1,1.43,116.28],[2,1.38,131.58]],"ltp":2.98,"tv":0.03,"id":424679}]}]}
{"op":"mcm","clk":"11760533349","pt":1722503125904,"mc":[{"id":"1.231284093","rc":[{"batb":[[0,1.43,116.28],[1,1.38,131.58],[2,1.33,151.52]],"ltp":2.98,"tv":0.03,"id":424679}]}]}
{"op":"mcm","clk":"11760533445","pt":1722503127196,"mc":[{"id":"1.231284093","rc":[{"batb":[[0,1.43,116.28],[1,1.38,131.58],[2,1.33,151.52]],"ltp":1.5,"tv":83.77,"id":5995}]}]}
{"op":"mcm","clk":"11760533524","pt":1722503128683,"mc":[{"id":"1.231284093","rc":[{"batb":[[0,1.44,10],[1,1.43,116.28],[2,1.38,131.58]],"ltp":2.98,"tv":0.03,"id":424679}]}]}
{"op":"mcm","clk":"11760533599","pt":1722503129918,"mc":[{"id":"1.231284093","rc":[{"batb":[[0,1.44,10],[1,1.43,116.28],[2,1.38,131.58]],"ltp":1.5,"tv":83.77,"id":5995}]}]}
{"op":"mcm","clk":"11760533715","pt":1722503131920,"mc":[{"id":"1.231284093","rc":[{"batb":[[0,1.43,116.28],[1,1.38,131.58],[2,1.33,151.52]],"ltp":2.98,"tv":0.03,"id":424679}]}]}
{"op":"mcm","clk":"11760533784","pt":1722503133312,"mc":[{"id":"1.231284093","rc":[{"batb":[[0,1.43,116.28],[1,1.38,131.58],[2,1.33,151.52]],"ltp":1.5,"tv":83.77,"id":5995}]}]}
{"op":"mcm","clk":"11760533875","pt":1722503134809,"mc":[{"id":"1.231284093","rc":[{"batb":[[0,1.44,10],[1,1.43,116.28],[2,1.38,131.58]],"ltp":2.98,"tv":0.03,"id":424679}]}]}
{"op":"mcm","clk":"11760533919","pt":1722503135890,"mc":[{"id":"1.231284093","rc":[{"batb":[[0,1.44,10],[1,1.43,116.28],[2,1.38,131.58]],"ltp":1.5,"tv":83.77,"id":5995}]}]}
{"op":"mcm","clk":"11760534034","pt":1722503138208,"mc":[{"id":"1.231284093","rc":[{"batb":[[0,1.43,116.28],[1,1.38,131.58],[2,1.33,151.52]],"ltp":2.98,"tv":0.03,"id":424679}]}]}
{"op":"mcm","clk":"11760534097","pt":1722503139299,"mc":[{"id":"1.231284093","rc":[{"batb":[[0,1.43,116.28],[1,1.38,131.58],[2,1.33,151.52]],"ltp":1.5,"tv":83.77,"id":5995}]}]}
{"op":"mcm","clk":"11760534171","pt":1722503140522,"mc":[{"id":"1.231284093","rc":[{"batb":[[0,1.44,10],[1,1.43,116.28],[2,1.38,131.58]],"ltp":2.98,"tv":0.03,"id":424679}]}]}
{"op":"mcm","clk":"11760534244","pt":1722503141708,"mc":[{"id":"1.231284093","rc":[{"batb":[[0,1.44,10],[1,1.43,116.28],[2,1.38,131.58]],"ltp":1.5,"tv":83.77,"id":5995}]}]}
{"op":"mcm","clk":"11760534368","pt":1722503143718,"mc":[{"id":"1.231284093","rc":[{"batb":[[0,1.43,116.28],[1,1.38,131.58],[2,1.33,151.52]],"ltp":2.98,"tv":0.03,"id":424679}]}]}
{"op":"mcm","clk":"11760534457","pt":1722503145112,"mc":[{"id":"1.231284093","rc":[{"batb":[[0,1.44,5.71]],"ltp":1.5,"tv":83.77,"id":5995}]}]}
{"op":"mcm","clk":"11760534548","pt":1722503146802,"mc":[{"id":"1.231284093","rc":[{"batb":[[0,1.44,10],[1,1.43,116.28],[2,1.38,131.58]],"ltp":2.98,"tv":0.03,"id":424679}]}]}
{"op":"mcm","clk":"11760534628","pt":1722503148296,"mc":[{"id":"1.231284093","rc":[{"batb":[[0,1.45,10],[1,1.44,5.71],[2,1.43,116.28]],"ltp":1.5,"tv":83.77,"id":5995}]}]}
{"op":"mcm","clk":"11760534751","pt":1722503150103,"mc":[{"id":"1.231284093","rc":[{"batb":[[0,1.43,116.28],[1,1.38,131.58],[2,1.33,151.52]],"ltp":2.98,"tv":0.03,"id":424679}]}]}
{"op":"mcm","clk":"11760534782","pt":1722503150724,"mc":[{"id":"1.231284093","rc":[{"batb":[[1,1.43,116.28],[2,1.38,131.58]],"ltp":1.5,"tv":83.77,"id":5995}]}]}
{"op":"mcm","clk":"11760534833","pt":1722503151809,"mc":[{"id":"1.231284093","rc":[{"batb":[[0,1.43,116.28],[1,1.38,131.58],[2,1.33,151.52]],"ltp":1.5,"tv":83.77,"id":5995}]}]}
{"op":"mcm","clk":"11760534914","pt":1722503153406,"mc":[{"id":"1.231284093","rc":[{"batb":[[0,1.44,10],[1,1.43,116.28],[2,1.38,131.58]],"ltp":2.98,"tv":0.03,"id":424679}]}]}
{"op":"mcm","clk":"11760534963","pt":1722503154643,"mc":[{"id":"1.231284093","rc":[{"batb":[[0,1.44,10],[1,1.43,116.28],[2,1.38,131.58]],"ltp":1.5,"tv":83.77,"id":5995}]}]}
{"op":"mcm","clk":"11760535092","pt":1722503156916,"mc":[{"id":"1.231284093","rc":[{"batb":[[0,1.43,116.28],[1,1.38,131.58],[2,1.33,151.52]],"ltp":2.98,"tv":0.03,"id":424679}]}]}
{"op":"mcm","clk":"11760535163","pt":1722503158145,"mc":[{"id":"1.231284093","rc":[{"batb":[[0,1.43,116.28],[1,1.38,131.58],[2,1.33,151.52]],"ltp":1.5,"tv":83.77,"id":5995}]}]}
{"op":"mcm","clk":"11760535272","pt":1722503159912,"mc":[{"id":"1.231284093","rc":[{"batb":[[0,1.44,10],[1,1.43,116.28],[2,1.38,131.58]],"ltp":2.98,"tv":0.03,"id":424679}]}]}
{"op":"mcm","clk":"11760535401","pt":1722503161827,"mc":[{"id":"1.231284093","rc":[{"batb":[[0,1.44,10],[1,1.43,116.28],[2,1.38,131.58]],"ltp":1.5,"tv":83.77,"id":5995}]}]}
{"op":"mcm","clk":"11760535476","pt":1722503163112,"mc":[{"id":"1.231284093","rc":[{"batb":[[0,1.43,116.28],[1,1.38,131.58],[2,1.33,151.52]],"ltp":2.98,"tv":0.03,"id":424679}]}]}
{"op":"mcm","clk":"11760535599","pt":1722503165325,"mc":[{"id":"1.231284093","rc":[{"batb":[[0,1.44,10],[1,1.43,116.28],[2,1.38,131.58]],"ltp":2.98,"tv":0.03,"id":424679},{"batb":[[0,1.43,116.28],[1,1.38,131.58],[2,1.33,151.52]],"ltp":1.5,"tv":83.77,"id":5995}]}]}
{"op":"mcm","clk":"11760535710","pt":1722503167440,"mc":[{"id":"1.231284093","rc":[{"batb":[[0,1.44,10],[1,1.43,116.28],[2,1.38,131.58]],"ltp":1.5,"tv":83.77,"id":5995}]}]}
{"op":"mcm","clk":"11760535780","pt":1722503168932,"mc":[{"id":"1.231284093","rc":[{"batb":[[0,1.43,116.28],[1,1.38,131.58],[2,1.33,151.52]],"ltp":2.98,"tv":0.03,"id":424679}]}]}
{"op":"mcm","clk":"11760535893","pt":1722503170726,"mc":[{"id":"1.231284093","rc":[{"batb":[[0,1.43,116.28],[1,1.38,131.58],[2,1.33,151.52]],"ltp":1.5,"tv":83.77,"id":5995}]}]}
{"op":"mcm","clk":"11760535971","pt":1722503172016,"mc":[{"id":"1.231284093","rc":[{"batb":[[0,1.44,10],[1,1.43,116.28],[2,1.38,131.58]],"ltp":2.98,"tv":0.03,"id":424679}]}]}
{"op":"mcm","clk":"11760536054","pt":1722503173252,"mc":[{"id":"1.231284093","rc":[{"batb":[[0,1.44,10],[1,1.43,116.28],[2,1.38,131.58]],"ltp":1.5,"tv":83.77,"id":5995}]}]}
{"op":"mcm","clk":"11760536163","pt":1722503175512,"mc":[{"id":"1.231284093","rc":[{"batb":[[0,1.43,116.28],[1,1.38,131.58],[2,1.33,151.52]],"ltp":2.98,"tv":0.03,"id":424679}]}]}
{"op":"mcm","clk":"11760536229","pt":1722503176851,"mc":[{"id":"1.231284093","rc":[{"batb":[[0,1.43,116.28],[1,1.38,131.58],[2,1.33,151.52]],"ltp":1.5,"tv":83.77,"id":5995}]}]}
{"op":"mcm","clk":"11760536406","pt":1722503180244,"mc":[{"id":"1.231284093","rc":[{"batb":[[0,1.44,10],[1,1.43,116.28],[2,1.38,131.58]],"ltp":2.98,"tv":0.03,"id":424679},{"batb":[[0,1.44,10],[1,1.43,116.28],[2,1.38,131.58]],"ltp":1.5,"tv":83.77,"id":5995}]}]}
{"op":"mcm","clk":"11760536581","pt":1722503183587,"mc":[{"id":"1.231284093","rc":[{"batb":[[0,1.43,116.28],[1,1.38,131.58],[2,1.33,151.52]],"ltp":2.98,"tv":0.03,"id":424679},{"batb":[[0,1.43,116.28],[1,1.38,131.58],[2,1.33,151.52]],"ltp":1.5,"tv":83.77,"id":5995}]}]}
{"op":"mcm","clk":"11760536697","pt":1722503185806,"mc":[{"id":"1.231284093","rc":[{"batb":[[0,1.44,10],[1,1.43,116.28],[2,1.38,131.58]],"ltp":2.98,"tv":0.03,"id":424679},{"batb":[[0,1.44,10],[1,1.43,116.28],[2,1.38,131.58]],"ltp":1.5,"tv":83.77,"id":5995}]}]}
{"op":"mcm","clk":"11760536791","pt":1722503187801,"mc":[{"id":"1.231284093","rc":[{"batb":[[0,1.44,15.71]],"ltp":2.98,"tv":0.03,"id":424679}]}]}
{"op":"mcm","clk":"11760536856","pt":1722503189084,"mc":[{"id":"1.231284093","rc":[{"batb":[[0,1.44,5.71]],"ltp":2.98,"tv":0.03,"id":424679},{"batb":[[0,1.43,116.28],[1,1.38,131.58],[2,1.33,151.52]],"ltp":1.5,"tv":83.77,"id":5995}]}]}
{"op":"mcm","clk":"11760537118","pt":1722503194023,"mc":[{"id":"1.231284093","rc":[{"batb":[[0,1.45,10]],"ltp":2.98,"tv":0.03,"id":424679},{"batb":[[0,1.44,10],[1,1.43,116.28],[2,1.38,131.58]],"ltp":1.5,"tv":83.77,"id":5995}]}]}
{"op":"mcm","clk":"11760537267","pt":1722503196806,"mc":[{"id":"1.231284093","rc":[{"batb":[[0,1.43,116.28],[1,1.38,131.58],[2,1.33,151.52]],"ltp":2.98,"tv":0.03,"id":424679},{"batb":[[0,1.43,116.28],[1,1.38,131.58],[2,1.33,151.52]],"ltp":1.5,"tv":83.77,"id":5995}]}]}
{"op":"mcm","clk":"11760537407","pt":1722503199431,"mc":[{"id":"1.231284093","rc":[{"batb":[[0,1.44,10],[1,1.43,116.28],[2,1.38,131.58]],"ltp":2.98,"tv":0.03,"id":424679},{"batb":[[0,1.44,10],[1,1.43,116.28],[2,1.38,131.58]],"ltp":1.5,"tv":83.77,"id":5995}]}]}
{"op":"mcm","clk":"11760537617","pt":1722503202809,"mc":[{"id":"1.231284093","rc":[{"batb":[[0,1.43,116.28],[1,1.38,131.58],[2,1.33,151.52]],"ltp":2.98,"tv":0.03,"id":424679},{"batb":[[0,1.43,116.28],[1,1.38,131.58],[2,1.33,151.52]],"ltp":1.5,"tv":83.77,"id":5995}]}]}
{"op":"mcm","clk":"11760537761","pt":1722503205329,"mc":[{"id":"1.231284093","rc":[{"batb":[[0,1.44,10],[1,1.43,116.28],[2,1.38,131.58]],"ltp":2.98,"tv":0.03,"id":424679},{"batb":[[0,1.44,10],[1,1.43,116.28],[2,1.38,131.58]],"ltp":1.5,"tv":83.77,"id":5995}]}]}
{"op":"mcm","clk":"11760537958","pt":1722503208310,"mc":[{"id":"1.231284093","rc":[{"batb":[[0,1.43,116.28],[1,1.38,131.58],[2,1.33,151.52]],"ltp":2.98,"tv":0.03,"id":424679}]}]}
{"op":"mcm","clk":"11760537971","pt":1722503208514,"mc":[{"id":"1.231284093","rc":[{"batb":[[0,1.43,116.28],[1,1.38,131.58],[2,1.33,151.52]],"ltp":1.5,"tv":83.77,"id":5995}]}]}
{"op":"mcm","clk":"11760538094","pt":1722503210843,"mc":[{"id":"1.231284093","rc":[{"batb":[[0,1.44,10],[1,1.43,116.28],[2,1.38,131.58]],"ltp":2.98,"tv":0.03,"id":424679},{"batb":[[0,1.44,10],[1,1.43,116.28],[2,1.38,131.58]],"ltp":1.5,"tv":83.77,"id":5995}]}]}
{"op":"mcm","clk":"11760538285","pt":1722503214107,"mc":[{"id":"1.231284093","rc":[{"batb":[[0,1.43,116.28],[1,1.38,131.58],[2,1.33,151.52]],"ltp":2.98,"tv":0.03,"id":424679},{"batb":[[0,1.43,116.28],[1,1.38,131.58],[2,1.33,151.52]],"ltp":1.5,"tv":83.77,"id":5995}]}]}
{"op":"mcm","clk":"11760538390","pt":1722503216210,"mc":[{"id":"1.231284093","rc":[{"batb":[[0,1.44,10],[1,1.43,116.28],[2,1.38,131.58]],"ltp":2.98,"tv":0.03,"id":424679},{"batb":[[0,1.44,10],[1,1.43,116.28],[2,1.38,131.58]],"ltp":1.5,"tv":83.77,"id":5995}]}]}
{"op":"mcm","clk":"11760538573","pt":1722503219548,"mc":[{"id":"1.231284093","rc":[{"batb":[[0,1.43,116.28],[1,1.38,131.58],[2,1.33,151.52]],"ltp":2.98,"tv":0.03,"id":424679},{"batb":[[0,1.43,116.28],[1,1.38,131.58],[2,1.33,151.52]],"ltp":1.5,"tv":83.77,"id":5995}]}]}
{"op":"mcm","clk":"11760538805","pt":1722503222981,"mc":[{"id":"1.231284093","rc":[{"batb":[[0,1.44,10],[1,1.43,116.28],[2,1.38,131.58]],"ltp":2.98,"tv":0.03,"id":424679},{"batb":[[0,1.44,10],[1,1.43,116.28],[2,1.38,131.58]],"ltp":1.5,"tv":83.77,"id":5995}]}]}
{"op":"mcm","clk":"11760539028","pt":1722503226343,"mc":[{"id":"1.231284093","rc":[{"batb":[[0,1.43,116.28],[1,1.38,131.58],[2,1.33,151.52]],"ltp":2.98,"tv":0.03,"id":424679},{"batb":[[0,1.43,116.28],[1,1.38,131.58],[2,1.33,151.52]],"ltp":1.5,"tv":83.77,"id":5995}]}]}
{"op":"mcm","clk":"11760539178","pt":1722503228961,"mc":[{"id":"1.231284093","rc":[{"batb":[[0,1.44,10],[1,1.43,116.28],[2,1.38,131.58]],"ltp":2.98,"tv":0.03,"id":424679},{"batb":[[0,1.44,10],[1,1.43,116.28],[2,1.38,131.58]],"ltp":1.5,"tv":83.77,"id":5995}]}]}
{"op":"mcm","clk":"11760539394","pt":1722503232360,"mc":[{"id":"1.231284093","rc":[{"batb":[[0,1.43,116.28],[1,1.38,131.58],[2,1.33,151.52]],"ltp":2.98,"tv":0.03,"id":424679},{"batb":[[0,1.43,116.28],[1,1.38,131.58],[2,1.33,151.52]],"ltp":1.5,"tv":83.77,"id":5995}]}]}
{"op":"mcm","clk":"11760539546","pt":1722503234673,"mc":[{"id":"1.231284093","rc":[{"batb":[[0,1.44,10],[1,1.43,116.28],[2,1.38,131.58]],"ltp":2.98,"tv":0.03,"id":424679},{"batb":[[0,1.44,10],[1,1.43,116.28],[2,1.38,131.58]],"ltp":1.5,"tv":83.77,"id":5995}]}]}
{"op":"mcm","clk":"11760539733","pt":1722503237862,"mc":[{"id":"1.231284093","rc":[{"batb":[[0,1.43,116.28],[1,1.38,131.58],[2,1.33,151.52]],"ltp":2.98,"tv":0.03,"id":424679},{"batb":[[0,1.43,116.28],[1,1.38,131.58],[2,1.33,151.52]],"ltp":1.5,"tv":83.77,"id":5995}]}]}
{"op":"mcm","clk":"11760539908","pt":1722503240422,"mc":[{"id":"1.231284093","rc":[{"batb":[[0,1.44,10],[1,1.43,116.28],[2,1.38,131.58]],"ltp":2.98,"tv":0.03,"id":424679},{"batb":[[0,1.44,10],[1,1.43,116.28],[2,1.38,131.58]],"ltp":1.5,"tv":83.77,"id":5995}]}]}
{"op":"mcm","clk":"11760540093","pt":1722503244025,"mc":[{"id":"1.231284093","rc":[{"batb":[[0,1.43,116.28],[1,1.38,131.58],[2,1.33,151.52]],"ltp":2.98,"tv":0.03,"id":424679},{"batb":[[0,1.43,116.28],[1,1.38,131.58],[2,1.33,151.52]],"ltp":1.5,"tv":83.77,"id":5995}]}]}
{"op":"mcm","clk":"11760540216","pt":1722503246247,"mc":[{"id":"1.231284093","rc":[{"batb":[[0,1.44,10],[1,1.43,116.28],[2,1.38,131.58]],"ltp":2.98,"tv":0.03,"id":424679},{"batb":[[0,1.44,10],[1,1.43,116.28],[2,1.38,131.58]],"ltp":1.5,"tv":83.77,"id":5995}]}]}
{"op":"mcm","clk":"11760540398","pt":1722503249532,"mc":[{"id":"1.231284093","rc":[{"batb":[[0,1.43,116.28],[1,1.38,131.58],[2,1.33,151.52]],"ltp":2.98,"tv":0.03,"id":424679},{"batb":[[0,1.43,116.28],[1,1.38,131.58],[2,1.33,151.52]],"ltp":1.5,"tv":83.77,"id":5995}]}]}
{"op":"mcm","clk":"11760540535","pt":1722503251906,"mc":[{"id":"1.231284093","rc":[{"batb":[[0,1.44,10],[1,1.43,116.28],[2,1.38,131.58]],"ltp":2.98,"tv":0.03,"id":424679},{"batb":[[0,1.44,10],[1,1.43,116.28],[2,1.38,131.58]],"ltp":1.5,"tv":83.77,"id":5995}]}]}
{"op":"mcm","clk":"11760540896","pt":1722503257209,"mc":[{"id":"1.231284093","rc":[{"batb":[[0,1.43,116.28],[1,1.38,131.58],[2,1.33,151.52]],"ltp":2.98,"tv":0.03,"id":424679},{"batb":[[0,1.44,5.8]],"ltp":1.5,"tv":83.77,"id":5995}]}]}
{"op":"mcm","clk":"11760541002","pt":1722503259321,"mc":[{"id":"1.231284093","rc":[{"batb":[[0,1.44,10],[1,1.43,116.28],[2,1.38,131.58]],"ltp":2.98,"tv":0.03,"id":424679},{"batb":[[0,1.45,10],[1,1.44,5.8],[2,1.43,116.28]],"ltp":1.5,"tv":83.77,"id":5995}]}]}
{"op":"mcm","clk":"11760541023","pt":1722503259732,"mc":[{"id":"1.231284093","rc":[{"batb":[[1,1.43,116.28],[2,1.38,131.58]],"ltp":1.5,"tv":83.77,"id":5995}]}]}
{"op":"mcm","clk":"11760541194","pt":1722503262628,"mc":[{"id":"1.231284093","rc":[{"batb":[[0,1.43,116.28],[1,1.38,131.58],[2,1.33,151.52]],"ltp":2.98,"tv":0.03,"id":424679},{"batb":[[0,1.43,116.28],[1,1.38,131.58],[2,1.33,151.52]],"ltp":1.5,"tv":83.77,"id":5995}]}]}
{"op":"mcm","clk":"11760541340","pt":1722503265059,"mc":[{"id":"1.231284093","rc":[{"batb":[[0,1.44,10],[1,1.43,116.28],[2,1.38,131.58]],"ltp":2.98,"tv":0.03,"id":424679},{"batb":[[0,1.44,10],[1,1.43,116.28],[2,1.38,131.58]],"ltp":1.5,"tv":83.77,"id":5995}]}]}
{"op":"mcm","clk":"11760541541","pt":1722503268453,"mc":[{"id":"1.231284093","rc":[{"batb":[[0,1.43,116.28],[1,1.38,131.58],[2,1.33,151.52]],"ltp":2.98,"tv":0.03,"id":424679},{"batb":[[0,1.43,116.28],[1,1.38,131.58],[2,1.33,151.52]],"ltp":1.5,"tv":83.77,"id":5995}]}]}
{"op":"mcm","clk":"11760541703","pt":1722503271331,"mc":[{"id":"1.231284093","rc":[{"batb":[[0,1.44,10],[1,1.43,116.28],[2,1.38,131.58]],"ltp":2.98,"tv":0.03,"id":424679},{"batb":[[0,1.44,10],[1,1.43,116.28],[2,1.38,131.58]],"ltp":1.5,"tv":83.77,"id":5995}]}]}
{"op":"mcm","clk":"11760541906","pt":1722503274926,"mc":[{"id":"1.231284093","rc":[{"batb":[[0,1.43,116.28],[1,1.38,131.58],[2,1.33,151.52]],"ltp":2.98,"tv":0.03,"id":424679},{"batb":[[0,1.43,116.28],[1,1.38,131.58],[2,1.33,151.52]],"ltp":1.5,"tv":83.77,"id":5995}]}]}
{"op":"mcm","clk":"11760542059","pt":1722503278064,"mc":[{"id":"1.231284093","rc":[{"batb":[[0,1.44,10],[1,1.43,116.28],[2,1.38,131.58]],"ltp":2.98,"tv":0.03,"id":424679},{"batb":[[0,1.44,10],[1,1.43,116.28],[2,1.38,131.58]],"ltp":1.5,"tv":83.77,"id":5995}]}]}
{"op":"mcm","clk":"11760542244","pt":1722503281431,"mc":[{"id":"1.231284093","rc":[{"batb":[[0,1.43,116.28],[1,1.38,131.58],[2,1.33,151.52]],"ltp":2.98,"tv":0.03,"id":424679},{"batb":[[0,1.43,116.28],[1,1.38,131.58],[2,1.33,151.52]],"ltp":1.5,"tv":83.77,"id":5995}]}]}
{"op":"mcm","clk":"11760542413","pt":1722503284346,"mc":[{"id":"1.231284093","rc":[{"batb":[[0,1.44,10],[1,1.43,116.28],[2,1.38,131.58]],"ltp":2.98,"tv":0.03,"id":424679},{"batb":[[0,1.44,10],[1,1.43,116.28],[2,1.38,131.58]],"ltp":1.5,"tv":83.77,"id":5995}]}]}
{"op":"mcm","clk":"11760542614","pt":1722503287862,"mc":[{"id":"1.231284093","rc":[{"batb":[[0,1.43,116.28],[1,1.38,131.58],[2,1.33,151.52]],"ltp":2.98,"tv":0.03,"id":424679},{"batb":[[0,1.43,116.28],[1,1.38,131.58],[2,1.33,151.52]],"ltp":1.5,"tv":83.77,"id":5995}]}]}
{"op":"mcm","clk":"11760542724","pt":1722503290173,"mc":[{"id":"1.231284093","rc":[{"batb":[[0,1.44,10],[1,1.43,116.28],[2,1.38,131.58]],"ltp":2.98,"tv":0.03,"id":424679},{"batb":[[0,1.44,10],[1,1.43,116.28],[2,1.38,131.58]],"ltp":1.5,"tv":83.77,"id":5995}]}]}
{"op":"mcm","clk":"11760542904","pt":1722503293581,"mc":[{"id":"1.231284093","rc":[{"batb":[[0,1.43,116.28],[1,1.38,131.58],[2,1.33,151.52]],"ltp":2.98,"tv":0.03,"id":424679},{"batb":[[0,1.43,116.28],[1,1.38,131.58],[2,1.33,151.52]],"ltp":1.5,"tv":83.77,"id":5995}]}]}
{"op":"mcm","clk":"11760543054","pt":1722503296047,"mc":[{"id":"1.231284093","rc":[{"batb":[[0,1.44,10],[1,1.43,116.28],[2,1.38,131.58]],"ltp":2.98,"tv":0.03,"id":424679},{"batb":[[0,1.44,10],[1,1.43,116.28],[2,1.38,131.58]],"ltp":1.5,"tv":83.77,"id":5995}]}]}
{"op":"mcm","clk":"11760543186","pt":1722503297957,"mc":[{"id":"1.231284093","rc":[{"batb":[[0,1.44,15.71]],"ltp":2.98,"tv":0.03,"id":424679}]}]}
{"op":"mcm","clk":"11760543277","pt":1722503299392,"mc":[{"id":"1.231284093","rc":[{"batb":[[0,1.44,5.71]],"ltp":2.98,"tv":0.03,"id":424679},{"batb":[[0,1.43,116.28],[1,1.38,131.58],[2,1.33,151.52]],"ltp":1.5,"tv":83.77,"id":5995}]}]}
{"op":"mcm","clk":"11760543438","pt":1722503301963,"mc":[{"id":"1.231284093","rc":[{"batb":[[0,1.45,10],[1,1.44,5.71],[2,1.43,116.28]],"ltp":2.98,"tv":0.03,"id":424679},{"batb":[[0,1.44,10],[1,1.43,116.28],[2,1.38,131.58]],"ltp":1.5,"tv":83.77,"id":5995}]}]}
{"op":"mcm","clk":"11760543500","pt":1722503303085,"mc":[{"id":"1.231284093","rc":[{"batb":[[1,1.43,116.28],[2,1.38,131.58]],"ltp":2.98,"tv":0.03,"id":424679}]}]}
{"op":"mcm","clk":"11760543615","pt":1722503305260,"mc":[{"id":"1.231284093","rc":[{"batb":[[0,1.43,116.28],[1,1.38,131.58],[2,1.33,151.52]],"ltp":2.98,"tv":0.03,"id":424679},{"batb":[[0,1.43,116.28],[1,1.38,131.58],[2,1.33,151.52]],"ltp":1.5,"tv":83.77,"id":5995}]}]}
{"op":"mcm","clk":"11760543790","pt":1722503308102,"mc":[{"id":"1.231284093","rc":[{"batb":[[0,1.44,10],[1,1.43,116.28],[2,1.38,131.58]],"ltp":2.98,"tv":0.03,"id":424679},{"batb":[[0,1.44,10],[1,1.43,116.28],[2,1.38,131.58]],"ltp":1.5,"tv":83.77,"id":5995}]}]}
{"op":"mcm","clk":"11760544049","pt":1722503312477,"mc":[{"id":"1.231284093","rc":[{"batb":[[0,1.43,116.28],[1,1.38,131.58],[2,1.33,151.52]],"ltp":2.98,"tv":0.03,"id":424679},{"batb":[[0,1.43,116.28],[1,1.38,131.58],[2,1.33,151.52]],"ltp":1.5,"tv":83.77,"id":5995}]}]}
{"op":"mcm","clk":"11760544171","pt":1722503314788,"mc":[{"id":"1.231284093","rc":[{"batb":[[0,1.44,10],[1,1.43,116.28],[2,1.38,131.58]],"ltp":2.98,"tv":0.03,"id":424679},{"batb":[[0,1.44,10],[1,1.43,116.28],[2,1.38,131.58]],"ltp":1.5,"tv":83.77,"id":5995}]}]}
{"op":"mcm","clk":"11760544378","pt":1722503318186,"mc":[{"id":"1.231284093","rc":[{"batb":[[0,1.43,116.28],[1,1.38,131.58],[2,1.33,151.52]],"ltp":2.98,"tv":0.03,"id":424679},{"batb":[[0,1.43,116.28],[1,1.38,131.58],[2,1.33,151.52]],"ltp":1.5,"tv":83.77,"id":5995}]}]}
{"op":"mcm","clk":"11760544501","pt":1722503320394,"mc":[{"id":"1.231284093","rc":[{"batb":[[0,1.44,10],[1,1.43,116.28],[2,1.38,131.58]],"ltp":2.98,"tv":0.03,"id":424679},{"batb":[[0,1.44,10],[1,1.43,116.28],[2,1.38,131.58]],"ltp":1.5,"tv":83.77,"id":5995}]}]}
{"op":"mcm","clk":"11760544712","pt":1722503323808,"mc":[{"id":"1.231284093","rc":[{"batb":[[0,1.43,116.28],[1,1.38,131.58],[2,1.33,151.52]],"ltp":2.98,"tv":0.03,"id":424679},{"batb":[[0,1.43,116.28],[1,1.38,131.58],[2,1.33,151.52]],"ltp":1.5,"tv":83.77,"id":5995}]}]}
{"op":"mcm","clk":"11760544925","pt":1722503327102,"mc":[{"id":"1.231284093","rc":[{"batb":[[0,1.44,10],[1,1.43,116.28],[2,1.38,131.58]],"ltp":2.98,"tv":0.03,"id":424679},{"batb":[[0,1.44,10],[1,1.43,116.28],[2,1.38,131.58]],"ltp":1.5,"tv":83.77,"id":5995}]}]}
{"op":"mcm","clk":"11760545154","pt":1722503330507,"mc":[{"id":"1.231284093","rc":[{"batb":[[0,1.43,116.28],[1,1.38,131.58],[2,1.33,151.52]],"ltp":2.98,"tv":0.03,"id":424679},{"batb":[[0,1.43,116.28],[1,1.38,131.58],[2,1.33,151.52]],"ltp":1.5,"tv":83.77,"id":5995}]}]}
{"op":"mcm","clk":"11760545281","pt":1722503332718,"mc":[{"id":"1.231284093","rc":[{"batb":[[0,1.44,10],[1,1.43,116.28],[2,1.38,131.58]],"ltp":2.98,"tv":0.03,"id":424679},{"batb":[[0,1.44,10],[1,1.43,116.28],[2,1.38,131.58]],"ltp":1.5,"tv":83.77,"id":5995}]}]}
{"op":"mcm","clk":"11760545517","pt":1722503336124,"mc":[{"id":"1.231284093","rc":[{"batb":[[0,1.43,116.28],[1,1.38,131.58],[2,1.33,151.52]],"ltp":2.98,"tv":0.03,"id":424679},{"batb":[[0,1.43,116.28],[1,1.38,131.58],[2,1.33,151.52]],"ltp":1.5,"tv":83.77,"id":5995}]}]}
{"op":"mcm","clk":"11760545670","pt":1722503338701,"mc":[{"id":"1.231284093","rc":[{"batb":[[0,1.44,10],[1,1.43,116.28],[2,1.38,131.58]],"ltp":2.98,"tv":0.03,"id":424679},{"batb":[[0,1.44,10],[1,1.43,116.28],[2,1.38,131.58]],"ltp":1.5,"tv":83.77,"id":5995}]}]}
{"op":"mcm","clk":"11760545841","pt":1722503341896,"mc":[{"id":"1.231284093","rc":[{"batb":[[0,1.43,116.28],[1,1.38,131.58],[2,1.33,151.52]],"ltp":2.98,"tv":0.03,"id":424679},{"batb":[[0,1.43,116.28],[1,1.38,131.58],[2,1.33,151.52]],"ltp":1.5,"tv":83.77,"id":5995}]}]}
{"op":"mcm","clk":"11760546025","pt":1722503344620,"mc":[{"id":"1.231284093","rc":[{"batb":[[0,1.44,10],[1,1.43,116.28],[2,1.38,131.58]],"ltp":2.98,"tv":0.03,"id":424679},{"batb":[[0,1.44,10],[1,1.43,116.28],[2,1.38,131.58]],"ltp":1.5,"tv":83.77,"id":5995}]}]}
{"op":"mcm","clk":"11760546214","pt":1722503348015,"mc":[{"id":"1.231284093","rc":[{"batb":[[0,1.43,116.28],[1,1.38,131.58],[2,1.33,151.52]],"ltp":2.98,"tv":0.03,"id":424679},{"batb":[[0,1.43,116.28],[1,1.38,131.58],[2,1.33,151.52]],"ltp":1.5,"tv":83.77,"id":5995}]}]}
{"op":"mcm","clk":"11760546400","pt":1722503351004,"mc":[{"id":"1.231284093","rc":[{"batb":[[0,1.44,10],[1,1.43,116.28],[2,1.38,131.58]],"ltp":2.98,"tv":0.03,"id":424679},{"batb":[[0,1.44,10],[1,1.43,116.28],[2,1.38,131.58]],"ltp":1.5,"tv":83.77,"id":5995}]}]}
{"op":"mcm","clk":"11760546590","pt":1722503354444,"mc":[{"id":"1.231284093","rc":[{"batb":[[0,1.43,116.28],[1,1.38,131.58],[2,1.33,151.52]],"ltp":2.98,"tv":0.03,"id":424679},{"batb":[[0,1.43,116.28],[1,1.38,131.58],[2,1.33,151.52]],"ltp":1.5,"tv":83.77,"id":5995}]}]}
{"op":"mcm","clk":"11760546710","pt":1722503356719,"mc":[{"id":"1.231284093","rc":[{"batb":[[0,1.44,10],[1,1.43,116.28],[2,1.38,131.58]],"ltp":2.98,"tv":0.03,"id":424679},{"batb":[[0,1.44,10],[1,1.43,116.28],[2,1.38,131.58]],"ltp":1.5,"tv":83.77,"id":5995}]}]}
{"op":"mcm","clk":"11760546901","pt":1722503360018,"mc":[{"id":"1.231284093","rc":[{"batb":[[0,1.43,116.28],[1,1.38,131.58],[2,1.33,151.52]],"ltp":2.98,"tv":0.03,"id":424679},{"batb":[[0,1.43,116.28],[1,1.38,131.58],[2,1.33,151.52]],"ltp":1.5,"tv":83.77,"id":5995}]}]}
{"op":"mcm","clk":"11760547049","pt":1722503362328,"mc":[{"id":"1.231284093","rc":[{"batb":[[0,1.44,10],[1,1.43,116.28],[2,1.38,131.58]],"ltp":2.98,"tv":0.03,"id":424679},{"batb":[[0,1.44,10],[1,1.43,116.28],[2,1.38,131.58]],"ltp":1.5,"tv":83.77,"id":5995}]}]}
{"op":"mcm","clk":"11760547246","pt":1722503365532,"mc":[{"id":"1.231284093","rc":[{"batb":[[0,1.43,116.28],[1,1.38,131.58],[2,1.33,151.52]],"ltp":2.98,"tv":0.03,"id":424679},{"batb":[[0,1.43,116.28],[1,1.38,131.58],[2,1.33,151.52]],"ltp":1.5,"tv":83.77,"id":5995}]}]}
{"op":"mcm","clk":"11760547438","pt":1722503368963,"mc":[{"id":"1.231284093","rc":[{"batb":[[0,1.44,5.8],[1,1.43,116.28],[2,1.38,131.58]],"ltp":1.5,"tv":83.77,"id":5995}]}]}
{"op":"mcm","clk":"11760547543","pt":1722503370866,"mc":[{"id":"1.231284093","rc":[{"batb":[[0,1.44,10],[1,1.43,116.28],[2,1.38,131.58]],"ltp":2.98,"tv":0.03,"id":424679},{"batb":[[0,1.44,15.8]],"ltp":1.5,"tv":83.77,"id":5995}]}]}
{"op":"mcm","clk":"11760547825","pt":1722503375956,"mc":[{"id":"1.231284093","rc":[{"batb":[[0,1.43,116.28],[1,1.38,131.58],[2,1.33,151.52]],"ltp":2.98,"tv":0.03,"id":424679},{"batb":[[0,1.44,5.8]],"ltp":1.5,"tv":83.77,"id":5995}]}]}
{"op":"mcm","clk":"11760547977","pt":1722503378682,"mc":[{"id":"1.231284093","rc":[{"batb":[[0,1.44,10],[1,1.43,116.28],[2,1.38,131.58]],"ltp":2.98,"tv":0.03,"id":424679},{"batb":[[0,1.45,10],[1,1.44,5.8],[2,1.43,116.28]],"ltp":1.5,"tv":83.77,"id":5995}]}]}
{"op":"mcm","clk":"11760548038","pt":1722503379864,"mc":[{"id":"1.231284093","rc":[{"batb":[[1,1.43,116.28],[2,1.38,131.58]],"ltp":1.5,"tv":83.77,"id":5995}]}]}
{"op":"mcm","clk":"11760548175","pt":1722503382052,"mc":[{"id":"1.231284093","rc":[{"batb":[[0,1.43,116.28],[1,1.38,131.58],[2,1.33,151.52]],"ltp":2.98,"tv":0.03,"id":424679},{"batb":[[0,1.43,116.28],[1,1.38,131.58],[2,1.33,151.52]],"ltp":1.5,"tv":83.77,"id":5995}]}]}
{"op":"mcm","clk":"11760548432","pt":1722503385387,"mc":[{"id":"1.231284093","rc":[{"batb":[[0,1.44,10],[1,1.43,116.28],[2,1.38,131.58]],"ltp":2.98,"tv":0.03,"id":424679},{"batb":[[0,1.44,10],[1,1.43,116.28],[2,1.38,131.58]],"ltp":1.5,"tv":83.77,"id":5995}]}]}
{"op":"mcm","clk":"11760548726","pt":1722503389875,"mc":[{"id":"1.231284093","rc":[{"batb":[[0,1.43,116.28],[1,1.38,131.58],[2,1.33,151.52]],"ltp":2.98,"tv":0.03,"id":424679},{"batb":[[0,1.43,116.28],[1,1.38,131.58],[2,1.33,151.52]],"ltp":1.5,"tv":83.77,"id":5995}]}]}
{"op":"mcm","clk":"11760548852","pt":1722503392095,"mc":[{"id":"1.231284093","rc":[{"batb":[[0,1.44,10],[1,1.43,116.28],[2,1.38,131.58]],"ltp":2.98,"tv":0.03,"id":424679},{"batb":[[0,1.44,10],[1,1.43,116.28],[2,1.38,131.58]],"ltp":1.5,"tv":83.77,"id":5995}]}]}
{"op":"mcm","clk":"11760549025","pt":1722503395488,"mc":[{"id":"1.231284093","rc":[{"batb":[[0,1.43,116.28],[1,1.38,131.58],[2,1.33,151.52]],"ltp":2.98,"tv":0.03,"id":424679},{"batb":[[0,1.43,116.28],[1,1.38,131.58],[2,1.33,151.52]],"ltp":1.5,"tv":83.77,"id":5995}]}]}
{"op":"mcm","clk":"11760549185","pt":1722503398273,"mc":[{"id":"1.231284093","rc":[{"batb":[[0,1.44,10],[1,1.43,116.28],[2,1.38,131.58]],"ltp":2.98,"tv":0.03,"id":424679},{"batb":[[0,1.44,10],[1,1.43,116.28],[2,1.38,131.58]],"ltp":1.5,"tv":83.77,"id":5995}]}]}
{"op":"mcm","clk":"11760549401","pt":1722503401489,"mc":[{"id":"1.231284093","rc":[{"batb":[[0,1.43,116.28],[1,1.38,131.58],[2,1.33,151.52]],"ltp":2.98,"tv":0.03,"id":424679},{"batb":[[0,1.43,116.28],[1,1.38,131.58],[2,1.33,151.52]],"ltp":1.5,"tv":83.77,"id":5995}]}]}
{"op":"mcm","clk":"11760549585","pt":1722503404276,"mc":[{"id":"1.231284093","rc":[{"batb":[[0,1.44,10],[1,1.43,116.28],[2,1.38,131.58]],"ltp":2.98,"tv":0.03,"id":424679},{"batb":[[0,1.44,10],[1,1.43,116.28],[2,1.38,131.58]],"ltp":1.5,"tv":83.77,"id":5995}]}]}
{"op":"mcm","clk":"11760549802","pt":1722503407675,"mc":[{"id":"1.231284093","rc":[{"batb":[[0,1.43,116.28],[1,1.38,131.58],[2,1.33,151.52]],"ltp":2.98,"tv":0.03,"id":424679},{"batb":[[0,1.43,116.28],[1,1.38,131.58],[2,1.33,151.52]],"ltp":1.5,"tv":83.77,"id":5995}]}]}
{"op":"mcm","clk":"11760549942","pt":1722503409985,"mc":[{"id":"1.231284093","rc":[{"batb":[[0,1.45,10],[1,1.44,5.8],[2,1.43,116.28]],"ltp":2.98,"tv":0.03,"id":424679},{"batb":[[0,1.44,10],[1,1.43,116.28],[2,1.38,131.58]],"ltp":1.5,"tv":83.77,"id":5995}]}]}
{"op":"mcm","clk":"11760550068","pt":1722503412203,"mc":[{"id":"1.231284093","rc":[{"batb":[[1,1.43,116.28],[2,1.38,131.58]],"ltp":2.98,"tv":0.03,"id":424679}]}]}
{"op":"mcm","clk":"11760550147","pt":1722503413386,"mc":[{"id":"1.231284093","rc":[{"batb":[[0,1.43,116.28],[1,1.38,131.58],[2,1.33,151.52]],"ltp":2.98,"tv":0.03,"id":424679},{"batb":[[0,1.43,116.28],[1,1.38,131.58],[2,1.33,151.52]],"ltp":1.5,"tv":83.77,"id":5995}]}]}
{"op":"mcm","clk":"11760550299","pt":1722503415809,"mc":[{"id":"1.231284093","rc":[{"batb":[[0,1.44,10],[1,1.43,116.28],[2,1.38,131.58]],"ltp":2.98,"tv":0.03,"id":424679},{"batb":[[0,1.44,10],[1,1.43,116.28],[2,1.38,131.58]],"ltp":1.5,"tv":83.77,"id":5995}]}]}
{"op":"mcm","clk":"11760550498","pt":1722503419197,"mc":[{"id":"1.231284093","rc":[{"batb":[[0,1.43,116.28],[1,1.38,131.58],[2,1.33,151.52]],"ltp":2.98,"tv":0.03,"id":424679},{"batb":[[0,1.43,116.28],[1,1.38,131.58],[2,1.33,151.52]],"ltp":1.5,"tv":83.77,"id":5995}]}]}
{"op":"mcm","clk":"11760550677","pt":1722503422079,"mc":[{"id":"1.231284093","rc":[{"batb":[[0,1.44,10],[1,1.43,116.28],[2,1.38,131.58]],"ltp":2.98,"tv":0.03,"id":424679},{"batb":[[0,1.44,10],[1,1.43,116.28],[2,1.38,131.58]],"ltp":1.5,"tv":83.77,"id":5995}]}]}
{"op":"mcm","clk":"11760550848","pt":1722503425528,"mc":[{"id":"1.231284093","rc":[{"batb":[[0,1.43,116.28],[1,1.38,131.58],[2,1.33,151.52]],"ltp":2.98,"tv":0.03,"id":424679},{"batb":[[0,1.43,116.28],[1,1.38,131.58],[2,1.33,151.52]],"ltp":1.5,"tv":83.77,"id":5995}]}]}
{"op":"mcm","clk":"11760551024","pt":1722503428822,"mc":[{"id":"1.231284093","rc":[{"batb":[[0,1.44,10],[1,1.43,116.28],[2,1.38,131.58]],"ltp":2.98,"tv":0.03,"id":424679},{"batb":[[0,1.44,10],[1,1.43,116.28],[2,1.38,131.58]],"ltp":1.5,"tv":83.77,"id":5995}]}]}
{"op":"mcm","clk":"11760551190","pt":1722503432114,"mc":[{"id":"1.231284093","rc":[{"batb":[[0,1.43,116.28],[1,1.38,131.58],[2,1.33,151.52]],"ltp":2.98,"tv":0.03,"id":424679},{"batb":[[0,1.43,116.28],[1,1.38,131.58],[2,1.33,151.52]],"ltp":1.5,"tv":83.77,"id":5995}]}]}
{"op":"mcm","clk":"11760551357","pt":1722503435313,"mc":[{"id":"1.231284093","rc":[{"batb":[[0,1.44,10],[1,1.43,116.28],[2,1.38,131.58]],"ltp":2.98,"tv":0.03,"id":424679},{"batb":[[0,1.44,10],[1,1.43,116.28],[2,1.38,131.58]],"ltp":1.5,"tv":83.77,"id":5995}]}]}
{"op":"mcm","clk":"11760551534","pt":1722503438616,"mc":[{"id":"1.231284093","rc":[{"batb":[[0,1.43,116.28],[1,1.38,131.58],[2,1.33,151.52]],"ltp":2.98,"tv":0.03,"id":424679},{"batb":[[0,1.43,116.28],[1,1.38,131.58],[2,1.33,151.52]],"ltp":1.5,"tv":83.77,"id":5995}]}]}
{"op":"mcm","clk":"11760551677","pt":1722503440938,"mc":[{"id":"1.231284093","rc":[{"batb":[[0,1.44,10],[1,1.43,116.28],[2,1.38,131.58]],"ltp":2.98,"tv":0.03,"id":424679},{"batb":[[0,1.44,10],[1,1.43,116.28],[2,1.38,131.58]],"ltp":1.5,"tv":83.77,"id":5995}]}]}
{"op":"mcm","clk":"11760551884","pt":1722503444346,"mc":[{"id":"1.231284093","rc":[{"batb":[[0,1.43,116.28],[1,1.38,131.58],[2,1.33,151.52]],"ltp":2.98,"tv":0.03,"id":424679},{"batb":[[0,1.43,116.28],[1,1.38,131.58],[2,1.33,151.52]],"ltp":1.5,"tv":83.77,"id":5995}]}]}
{"op":"mcm","clk":"11760552039","pt":1722503447431,"mc":[{"id":"1.231284093","rc":[{"batb":[[0,1.44,10],[1,1.43,116.28],[2,1.38,131.58]],"ltp":2.98,"tv":0.03,"id":424679},{"batb":[[0,1.44,10],[1,1.43,116.28],[2,1.38,131.58]],"ltp":1.5,"tv":83.77,"id":5995}]}]}
{"op":"mcm","clk":"11760552222","pt":1722503450625,"mc":[{"id":"1.231284093","rc":[{"batb":[[0,1.43,116.28],[1,1.38,131.58],[2,1.33,151.52]],"ltp":2.98,"tv":0.03,"id":424679},{"batb":[[0,1.43,116.28],[1,1.38,131.58],[2,1.33,151.52]],"ltp":1.5,"tv":83.77,"id":5995}]}]}
{"op":"mcm","clk":"11760552389","pt":1722503453343,"mc":[{"id":"1.231284093","rc":[{"batb":[[0,1.44,10],[1,1.43,116.28],[2,1.38,131.58]],"ltp":2.98,"tv":0.03,"id":424679},{"batb":[[0,1.44,10],[1,1.43,116.28],[2,1.38,131.58]],"ltp":1.5,"tv":83.77,"id":5995}]}]}
{"op":"mcm","clk":"11760552620","pt":1722503457361,"mc":[{"id":"1.231284093","rc":[{"batb":[[0,1.43,116.28],[1,1.38,131.58],[2,1.33,151.52]],"ltp":2.98,"tv":0.03,"id":424679},{"batb":[[0,1.43,116.28],[1,1.38,131.58],[2,1.33,151.52]],"ltp":1.5,"tv":83.77,"id":5995}]}]}
{"op":"mcm","clk":"11760552733","pt":1722503459650,"mc":[{"id":"1.231284093","rc":[{"batb":[[0,1.44,10],[1,1.43,116.28],[2,1.38,131.58]],"ltp":2.98,"tv":0.03,"id":424679},{"batb":[[0,1.44,10],[1,1.43,116.28],[2,1.38,131.58]],"ltp":1.5,"tv":83.77,"id":5995}]}]}
{"op":"mcm","clk":"11760552918","pt":1722503462955,"mc":[{"id":"1.231284093","rc":[{"batb":[[0,1.43,116.28],[1,1.38,131.58],[2,1.33,151.52]],"ltp":2.98,"tv":0.03,"id":424679},{"batb":[[0,1.43,116.28],[1,1.38,131.58],[2,1.33,151.52]],"ltp":1.5,"tv":83.77,"id":5995}]}]}
{"op":"mcm","clk":"11760553166","pt":1722503467231,"mc":[{"id":"1.231284093","rc":[{"batb":[[0,1.44,10],[1,1.43,116.28],[2,1.38,131.58]],"ltp":2.98,"tv":0.03,"id":424679},{"batb":[[0,1.44,10],[1,1.43,116.28],[2,1.38,131.58]],"ltp":1.5,"tv":83.77,"id":5995}]}]}
{"op":"mcm","clk":"11760553364","pt":1722503470633,"mc":[{"id":"1.231284093","rc":[{"batb":[[0,1.43,116.28],[1,1.38,131.58],[2,1.33,151.52]],"ltp":2.98,"tv":0.03,"id":424679},{"batb":[[0,1.43,116.28],[1,1.38,131.58],[2,1.33,151.52]],"ltp":1.5,"tv":83.77,"id":5995}]}]}
{"op":"mcm","clk":"11760553508","pt":1722503473052,"mc":[{"id":"1.231284093","rc":[{"batb":[[0,1.44,10],[1,1.43,116.28],[2,1.38,131.58]],"ltp":2.98,"tv":0.03,"id":424679},{"batb":[[0,1.44,10],[1,1.43,116.28],[2,1.38,131.58]],"ltp":1.5,"tv":83.77,"id":5995}]}]}
{"op":"mcm","clk":"11760553724","pt":1722503476352,"mc":[{"id":"1.231284093","rc":[{"batb":[[0,1.43,116.28],[1,1.38,131.58],[2,1.33,151.52]],"ltp":2.98,"tv":0.03,"id":424679},{"batb":[[0,1.43,116.28],[1,1.38,131.58],[2,1.33,151.52]],"ltp":1.5,"tv":83.77,"id":5995}]}]}
{"op":"mcm","clk":"11760554065","pt":1722503481557,"mc":[{"id":"1.231284093","rc":[{"batb":[[0,1.44,5.8],[1,1.43,116.28],[2,1.38,131.58]],"ltp":1.5,"tv":83.77,"id":5995}]}]}
{"op":"mcm","clk":"11760554182","pt":1722503483355,"mc":[{"id":"1.231284093","rc":[{"batb":[[0,1.44,10],[1,1.43,116.28],[2,1.38,131.58]],"ltp":2.98,"tv":0.03,"id":424679},{"batb":[[0,1.45,10],[1,1.44,5.8],[2,1.43,116.28]],"ltp":1.5,"tv":83.77,"id":5995}]}]}
{"op":"mcm","clk":"11760554262","pt":1722503484535,"mc":[{"id":"1.231284093","rc":[{"batb":[[1,1.43,116.28],[2,1.38,131.58]],"ltp":1.5,"tv":83.77,"id":5995}]}]}
{"op":"mcm","clk":"11760554444","pt":1722503487679,"mc":[{"id":"1.231284093","rc":[{"batb":[[0,1.43,116.28],[1,1.38,131.58],[2,1.33,151.52]],"ltp":2.98,"tv":0.03,"id":424679},{"batb":[[0,1.43,116.28],[1,1.38,131.58],[2,1.33,151.52]],"ltp":1.5,"tv":83.77,"id":5995}]}]}
{"op":"mcm","clk":"11760554609","pt":1722503490458,"mc":[{"id":"1.231284093","rc":[{"batb":[[0,1.44,10],[1,1.43,116.28],[2,1.38,131.58]],"ltp":2.98,"tv":0.03,"id":424679},{"batb":[[0,1.44,10],[1,1.43,116.28],[2,1.38,131.58]],"ltp":1.5,"tv":83.77,"id":5995}]}]}
{"op":"mcm","clk":"11760554780","pt":1722503493655,"mc":[{"id":"1.231284093","rc":[{"batb":[[0,1.43,116.28],[1,1.38,131.58],[2,1.33,151.52]],"ltp":2.98,"tv":0.03,"id":424679},{"batb":[[0,1.43,116.28],[1,1.38,131.58],[2,1.33,151.52]],"ltp":1.5,"tv":83.77,"id":5995}]}]}
{"op":"mcm","clk":"11760554978","pt":1722503497763,"mc":[{"id":"1.231284093","rc":[{"batb":[[0,1.44,10],[1,1.43,116.28],[2,1.38,131.58]],"ltp":2.98,"tv":0.03,"id":424679},{"batb":[[0,1.44,10],[1,1.43,116.28],[2,1.38,131.58]],"ltp":1.5,"tv":83.77,"id":5995}]}]}
{"op":"mcm","clk":"11760555154","pt":1722503500958,"mc":[{"id":"1.231284093","rc":[{"batb":[[0,1.43,116.28],[1,1.38,131.58],[2,1.33,151.52]],"ltp":2.98,"tv":0.03,"id":424679},{"batb":[[0,1.43,116.28],[1,1.38,131.58],[2,1.33,151.52]],"ltp":1.5,"tv":83.77,"id":5995}]}]}
{"op":"mcm","clk":"11760555312","pt":1722503503896,"mc":[{"id":"1.231284093","rc":[{"batb":[[0,1.44,10],[1,1.43,116.28],[2,1.38,131.58]],"ltp":2.98,"tv":0.03,"id":424679},{"batb":[[0,1.44,10],[1,1.43,116.28],[2,1.38,131.58]],"ltp":1.5,"tv":83.77,"id":5995}]}]}
{"op":"mcm","clk":"11760555499","pt":1722503507199,"mc":[{"id":"1.231284093","rc":[{"batb":[[0,1.43,116.28],[1,1.38,131.58],[2,1.33,151.52]],"ltp":2.98,"tv":0.03,"id":424679},{"batb":[[0,1.43,116.28],[1,1.38,131.58],[2,1.33,151.52]],"ltp":1.5,"tv":83.77,"id":5995}]}]}
{"op":"mcm","clk":"11760555708","pt":1722503510495,"mc":[{"id":"1.231284093","rc":[{"batb":[[0,1.44,10],[1,1.43,116.28],[2,1.38,131.58]],"ltp":2.98,"tv":0.03,"id":424679},{"batb":[[0,1.44,10],[1,1.43,116.28],[2,1.38,131.58]],"ltp":1.5,"tv":83.77,"id":5995}]}]}
{"op":"mcm","clk":"11760555909","pt":1722503513821,"mc":[{"id":"1.231284093","rc":[{"batb":[[0,1.43,116.28],[1,1.38,131.58],[2,1.33,151.52]],"ltp":2.98,"tv":0.03,"id":424679},{"batb":[[0,1.43,116.28],[1,1.38,131.58],[2,1.33,151.52]],"ltp":1.5,"tv":83.77,"id":5995}]}]}
{"op":"mcm","clk":"11760556094","pt":1722503516686,"mc":[{"id":"1.231284093","rc":[{"batb":[[0,1.44,10],[1,1.43,116.28],[2,1.38,131.58]],"ltp":2.98,"tv":0.03,"id":424679},{"batb":[[0,1.44,10],[1,1.43,116.28],[2,1.38,131.58]],"ltp":1.5,"tv":83.77,"id":5995}]}]}
{"op":"mcm","clk":"11760556307","pt":1722503520079,"mc":[{"id":"1.231284093","rc":[{"batb":[[0,1.43,116.28],[1,1.38,131.58],[2,1.33,151.52]],"ltp":2.98,"tv":0.03,"id":424679},{"batb":[[0,1.43,116.28],[1,1.38,131.58],[2,1.33,151.52]],"ltp":1.5,"tv":83.77,"id":5995}]}]}
{"op":"mcm","clk":"11760556433","pt":1722503522309,"mc":[{"id":"1.231284093","rc":[{"batb":[[0,1.44,10],[1,1.43,116.28],[2,1.38,131.58]],"ltp":2.98,"tv":0.03,"id":424679},{"batb":[[0,1.44,10],[1,1.43,116.28],[2,1.38,131.58]],"ltp":1.5,"tv":83.77,"id":5995}]}]}
{"op":"mcm","clk":"11760556472","pt":1722503522974,"mc":[{"id":"1.231284093","rc":[{"batb":[[0,1.44,15.71]],"ltp":2.98,"tv":0.03,"id":424679}]}]}
{"op":"mcm","clk":"11760556605","pt":1722503525393,"mc":[{"id":"1.231284093","rc":[{"batb":[[0,1.43,116.28],[1,1.38,131.58],[2,1.33,151.52]],"ltp":1.5,"tv":83.77,"id":5995}]}]}
{"op":"mcm","clk":"11760556625","pt":1722503525697,"mc":[{"id":"1.231284093","rc":[{"batb":[[0,1.44,5.71]],"ltp":2.98,"tv":0.03,"id":424679}]}]}
{"op":"mcm","clk":"11760556850","pt":1722503529200,"mc":[{"id":"1.231284093","rc":[{"batb":[[0,1.45,10]],"ltp":2.98,"tv":0.03,"id":424679},{"batb":[[0,1.44,10],[1,1.43,116.28],[2,1.38,131.58]],"ltp":1.5,"tv":83.77,"id":5995}]}]}
{"op":"mcm","clk":"11760557000","pt":1722503531934,"mc":[{"id":"1.231284093","rc":[{"batb":[[0,1.43,116.28],[1,1.38,131.58],[2,1.33,151.52]],"ltp":2.98,"tv":0.03,"id":424679},{"batb":[[0,1.43,116.28],[1,1.38,131.58],[2,1.33,151.52]],"ltp":1.5,"tv":83.77,"id":5995}]}]}
{"op":"mcm","clk":"11760557173","pt":1722503534720,"mc":[{"id":"1.231284093","rc":[{"batb":[[0,1.44,10],[1,1.43,116.28],[2,1.38,131.58]],"ltp":2.98,"tv":0.03,"id":424679},{"batb":[[0,1.44,10],[1,1.43,116.28],[2,1.38,131.58]],"ltp":1.5,"tv":83.77,"id":5995}]}]}
{"op":"mcm","clk":"11760557358","pt":1722503538123,"mc":[{"id":"1.231284093","rc":[{"batb":[[0,1.43,116.28],[1,1.38,131.58],[2,1.33,151.52]],"ltp":2.98,"tv":0.03,"id":424679},{"batb":[[0,1.43,116.28],[1,1.38,131.58],[2,1.33,151.52]],"ltp":1.5,"tv":83.77,"id":5995}]}]}
{"op":"mcm","clk":"11760557531","pt":1722503541105,"mc":[{"id":"1.231284093","rc":[{"batb":[[0,1.44,10],[1,1.43,116.28],[2,1.38,131.58]],"ltp":2.98,"tv":0.03,"id":424679},{"batb":[[0,1.44,10],[1,1.43,116.28],[2,1.38,131.58]],"ltp":1.5,"tv":83.77,"id":5995}]}]}
{"op":"mcm","clk":"11760557703","pt":1722503544513,"mc":[{"id":"1.231284093","rc":[{"batb":[[0,1.43,116.28],[1,1.38,131.58],[2,1.33,151.52]],"ltp":2.98,"tv":0.03,"id":424679},{"batb":[[0,1.43,116.28],[1,1.38,131.58],[2,1.33,151.52]],"ltp":1.5,"tv":83.77,"id":5995}]}]}
{"op":"mcm","clk":"11760557878","pt":1722503547722,"mc":[{"id":"1.231284093","rc":[{"batb":[[0,1.44,10],[1,1.43,116.28],[2,1.38,131.58]],"ltp":2.98,"tv":0.03,"id":424679},{"batb":[[0,1.44,10],[1,1.43,116.28],[2,1.38,131.58]],"ltp":1.5,"tv":83.77,"id":5995}]}]}
{"op":"mcm","clk":"11760558092","pt":1722503550936,"mc":[{"id":"1.231284093","rc":[{"batb":[[0,1.43,116.28],[1,1.38,131.58],[2,1.33,151.52]],"ltp":2.98,"tv":0.03,"id":424679},{"batb":[[0,1.43,116.28],[1,1.38,131.58],[2,1.33,151.52]],"ltp":1.5,"tv":83.77,"id":5995}]}]}
{"op":"mcm","clk":"11760558238","pt":1722503553350,"mc":[{"id":"1.231284093","rc":[{"batb":[[0,1.44,10],[1,1.43,116.28],[2,1.38,131.58]],"ltp":2.98,"tv":0.03,"id":424679},{"batb":[[0,1.44,10],[1,1.43,116.28],[2,1.38,131.58]],"ltp":1.5,"tv":83.77,"id":5995}]}]}
{"op":"mcm","clk":"11760558480","pt":1722503556861,"mc":[{"id":"1.231284093","rc":[{"batb":[[0,1.43,116.28],[1,1.38,131.58],[2,1.33,151.52]],"ltp":2.98,"tv":0.03,"id":424679},{"batb":[[0,1.43,116.28],[1,1.38,131.58],[2,1.33,151.52]],"ltp":1.5,"tv":83.77,"id":5995}]}]}
{"op":"mcm","clk":"11760558632","pt":1722503559034,"mc":[{"id":"1.231284093","rc":[{"batb":[[0,1.44,10],[1,1.43,116.28],[2,1.38,131.58]],"ltp":2.98,"tv":0.03,"id":424679},{"batb":[[0,1.44,10],[1,1.43,116.28],[2,1.38,131.58]],"ltp":1.5,"tv":83.77,"id":5995}]}]}
{"op":"mcm","clk":"11760558829","pt":1722503562348,"mc":[{"id":"1.231284093","rc":[{"batb":[[0,1.43,116.28],[1,1.38,131.58],[2,1.33,151.52]],"ltp":2.98,"tv":0.03,"id":424679},{"batb":[[0,1.43,116.28],[1,1.38,131.58],[2,1.33,151.52]],"ltp":1.5,"tv":83.77,"id":5995}]}]}
{"op":"mcm","clk":"11760559010","pt":1722503565746,"mc":[{"id":"1.231284093","rc":[{"batb":[[0,1.44,10],[1,1.43,116.28],[2,1.38,131.58]],"ltp":2.98,"tv":0.03,"id":424679},{"batb":[[0,1.44,10],[1,1.43,116.28],[2,1.38,131.58]],"ltp":1.5,"tv":83.77,"id":5995}]}]}
{"op":"mcm","clk":"11760559200","pt":1722503569037,"mc":[{"id":"1.231284093","rc":[{"batb":[[0,1.43,116.28],[1,1.38,131.58],[2,1.33,151.52]],"ltp":2.98,"tv":0.03,"id":424679},{"batb":[[0,1.43,116.28],[1,1.38,131.58],[2,1.33,151.52]],"ltp":1.5,"tv":83.77,"id":5995}]}]}
{"op":"mcm","clk":"11760559314","pt":1722503571348,"mc":[{"id":"1.231284093","rc":[{"batb":[[0,1.44,10],[1,1.43,116.28],[2,1.38,131.58]],"ltp":2.98,"tv":0.03,"id":424679},{"batb":[[0,1.44,10],[1,1.43,116.28],[2,1.38,131.58]],"ltp":1.5,"tv":83.77,"id":5995}]}]}
{"op":"mcm","clk":"11760564267","pt":1722503575028,"mc":[{"id":"1.231284093","rc":[{"batb":[[0,1.43,116.28],[1,1.38,131.58],[2,1.33,151.52]],"ltp":2.98,"tv":0.03,"id":424679},{"batb":[[0,1.43,116.28],[1,1.38,131.58],[2,1.33,151.52]],"ltp":1.5,"tv":83.77,"id":5995}]}]}
{"op":"mcm","clk":"11760567263","pt":1722503577737,"mc":[{"id":"1.231284093","rc":[{"batb":[[0,1.44,10],[1,1.43,116.28],[2,1.38,131.58]],"ltp":2.98,"tv":0.03,"id":424679},{"batb":[[0,1.44,10],[1,1.43,116.28],[2,1.38,131.58]],"ltp":1.5,"tv":83.77,"id":5995}]}]}
{"op":"mcm","clk":"11760567439","pt":1722503581166,"mc":[{"id":"1.231284093","rc":[{"batb":[[0,1.43,116.28],[1,1.38,131.58],[2,1.33,151.52]],"ltp":2.98,"tv":0.03,"id":424679},{"batb":[[0,1.43,116.28],[1,1.38,131.58],[2,1.33,151.52]],"ltp":1.5,"tv":83.77,"id":5995}]}]}
{"op":"mcm","clk":"11760567612","pt":1722503583866,"mc":[{"id":"1.231284093","rc":[{"batb":[[0,1.44,10],[1,1.43,116.28],[2,1.38,131.58]],"ltp":2.98,"tv":0.03,"id":424679},{"batb":[[0,1.44,10],[1,1.43,116.28],[2,1.38,131.58]],"ltp":1.5,"tv":83.77,"id":5995}]}]}
{"op":"mcm","clk":"11760567817","pt":1722503587067,"mc":[{"id":"1.231284093","rc":[{"batb":[[0,1.43,116.28],[1,1.38,131.58],[2,1.33,151.52]],"ltp":2.98,"tv":0.03,"id":424679},{"batb":[[0,1.43,116.28],[1,1.38,131.58],[2,1.33,151.52]],"ltp":1.5,"tv":83.77,"id":5995}]}]}
{"op":"mcm","clk":"11760567954","pt":1722503589286,"mc":[{"id":"1.231284093","rc":[{"batb":[[0,1.44,7.71],[1,1.43,116.28],[2,1.38,131.58]],"ltp":1.5,"tv":83.77,"id":5995}]}]}
{"op":"mcm","clk":"11760567973","pt":1722503589547,"mc":[{"id":"1.231284093","rc":[{"batb":[[0,1.44,16.1],[1,1.43,116.28],[2,1.38,131.58]],"ltp":2.98,"tv":0.03,"id":424679},{"batb":[[0,1.45,10],[1,1.44,7.71],[2,1.43,116.28]],"ltp":1.5,"tv":83.77,"id":5995}]}]}
{"op":"mcm","clk":"11760568191","pt":1722503592861,"mc":[{"id":"1.231284093","rc":[{"batb":[[0,1.44,6.1]],"ltp":2.98,"tv":0.03,"id":424679},{"batb":[[0,1.44,7.71],[1,1.43,116.28],[2,1.38,131.58]],"ltp":1.5,"tv":83.77,"id":5995}]}]}
{"op":"mcm","clk":"11760568404","pt":1722503596565,"mc":[{"id":"1.231284093","rc":[{"batb":[[0,1.45,10],[1,1.44,6.1],[2,1.43,116.28]],"ltp":2.98,"tv":0.03,"id":424679},{"batb":[[0,1.45,10],[1,1.44,7.71],[2,1.43,116.28]],"ltp":1.5,"tv":83.77,"id":5995}]}]}
{"op":"mcm","clk":"11760568603","pt":1722503599868,"mc":[{"id":"1.231284093","rc":[{"batb":[[0,1.44,6.1],[1,1.43,116.28],[2,1.38,131.58]],"ltp":2.98,"tv":0.03,"id":424679},{"batb":[[0,1.44,7.71],[1,1.43,116.28],[2,1.38,131.58]],"ltp":1.5,"tv":83.77,"id":5995}]}]}
{"op":"mcm","clk":"11760568828","pt":1722503603168,"mc":[{"id":"1.231284093","rc":[{"batb":[[0,1.45,10],[1,1.44,6.1],[2,1.43,116.28]],"ltp":2.98,"tv":0.03,"id":424679},{"batb":[[0,1.45,10],[1,1.44,7.71],[2,1.43,116.28]],"ltp":1.5,"tv":83.77,"id":5995}]}]}
{"op":"mcm","clk":"11760569100","pt":1722503607897,"mc":[{"id":"1.231284093","rc":[{"batb":[[0,1.44,6.1],[1,1.43,116.28],[2,1.38,131.58]],"ltp":2.98,"tv":0.03,"id":424679},{"batb":[[0,1.44,7.71],[1,1.43,116.28],[2,1.38,131.58]],"ltp":1.5,"tv":83.77,"id":5995}]}]}
{"op":"mcm","clk":"11760569243","pt":1722503610480,"mc":[{"id":"1.231284093","rc":[{"batb":[[0,1.45,10],[1,1.44,6.1],[2,1.43,116.28]],"ltp":2.98,"tv":0.03,"id":424679},{"batb":[[0,1.45,10],[1,1.44,7.71],[2,1.43,116.28]],"ltp":1.5,"tv":83.77,"id":5995}]}]}
{"op":"mcm","clk":"11760569428","pt":1722503613881,"mc":[{"id":"1.231284093","rc":[{"batb":[[0,1.44,6.1],[1,1.43,116.28],[2,1.38,131.58]],"ltp":2.98,"tv":0.03,"id":424679},{"batb":[[0,1.44,7.71],[1,1.43,116.28],[2,1.38,131.58]],"ltp":1.5,"tv":83.77,"id":5995}]}]}
{"op":"mcm","clk":"11760569568","pt":1722503616099,"mc":[{"id":"1.231284093","rc":[{"batb":[[0,1.45,10],[1,1.44,6.1],[2,1.43,116.28]],"ltp":2.98,"tv":0.03,"id":424679},{"batb":[[0,1.45,10],[1,1.44,7.71],[2,1.43,116.28]],"ltp":1.5,"tv":83.77,"id":5995}]}]}
{"op":"mcm","clk":"11760569799","pt":1722503619509,"mc":[{"id":"1.231284093","rc":[{"batb":[[0,1.44,6.1],[1,1.43,116.28],[2,1.38,131.58]],"ltp":2.98,"tv":0.03,"id":424679},{"batb":[[0,1.44,7.71],[1,1.43,116.28],[2,1.38,131.58]],"ltp":1.5,"tv":83.77,"id":5995}]}]}
{"op":"mcm","clk":"11760569951","pt":1722503622282,"mc":[{"id":"1.231284093","rc":[{"batb":[[0,1.45,10],[1,1.44,6.1],[2,1.43,116.28]],"ltp":2.98,"tv":0.03,"id":424679},{"batb":[[0,1.45,10],[1,1.44,13.43],[2,1.43,116.28]],"ltp":1.5,"tv":83.77,"id":5995}]}]}
{"op":"mcm","clk":"11760570046","pt":1722503624083,"mc":[{"id":"1.231284093","rc":[{"batb":[[1,1.44,7.71]],"ltp":1.5,"tv":83.77,"id":5995}]}]}
{"op":"mcm","clk":"11760570141","pt":1722503625984,"mc":[{"id":"1.231284093","rc":[{"batb":[[0,1.44,12.2],[1,1.43,116.28],[2,1.38,131.58]],"ltp":2.98,"tv":0.03,"id":424679},{"batb":[[0,1.44,7.71],[1,1.43,116.28],[2,1.38,131.58]],"ltp":1.5,"tv":83.77,"id":5995}]}]}
{"op":"mcm","clk":"11760570353","pt":1722503629387,"mc":[{"id":"1.231284093","rc":[{"batb":[[0,1.45,10],[1,1.44,12.2],[2,1.43,116.28]],"ltp":2.98,"tv":0.03,"id":424679},{"batb":[[0,1.45,10],[1,1.44,7.71],[2,1.43,116.28]],"ltp":1.5,"tv":83.77,"id":5995}]}]}
{"op":"mcm","clk":"11760570506","pt":1722503632615,"mc":[{"id":"1.231284093","rc":[{"batb":[[0,1.44,6.1],[1,1.43,116.28],[2,1.38,131.58]],"ltp":2.98,"tv":0.03,"id":424679},{"batb":[[0,1.44,7.71],[1,1.43,116.28],[2,1.38,131.58]],"ltp":1.5,"tv":83.77,"id":5995}]}]}
{"op":"mcm","clk":"11760570651","pt":1722503636538,"mc":[{"id":"1.231284093","rc":[{"batb":[[0,1.45,10],[1,1.44,6.1],[2,1.43,116.28]],"ltp":2.98,"tv":0.03,"id":424679},{"batb":[[0,1.45,10],[1,1.44,7.71],[2,1.43,116.28]],"ltp":1.5,"tv":83.77,"id":5995}]}]}
{"op":"mcm","clk":"11760570803","pt":1722503639923,"mc":[{"id":"1.231284093","rc":[{"batb":[[0,1.44,6.1],[1,1.43,116.28],[2,1.38,131.58]],"ltp":2.98,"tv":0.03,"id":424679},{"batb":[[0,1.44,7.71],[1,1.43,116.28],[2,1.38,131.58]],"ltp":1.5,"tv":83.77,"id":5995}]}]}
{"op":"mcm","clk":"11760570937","pt":1722503642346,"mc":[{"id":"1.231284093","rc":[{"batb":[[0,1.45,10],[1,1.44,6.1],[2,1.43,116.28]],"ltp":2.98,"tv":0.03,"id":424679},{"batb":[[0,1.45,10],[1,1.44,7.71],[2,1.43,116.28]],"ltp":1.5,"tv":83.77,"id":5995}]}]}
{"op":"mcm","clk":"11760571178","pt":1722503647024,"mc":[{"id":"1.231284093","rc":[{"batb":[[0,1.44,6.1],[1,1.43,116.28],[2,1.38,131.58]],"ltp":2.98,"tv":0.03,"id":424679},{"batb":[[0,1.44,7.71],[1,1.43,116.28],[2,1.38,131.58]],"ltp":1.5,"tv":83.77,"id":5995}]}]}
{"op":"mcm","clk":"11760571350","pt":1722503649961,"mc":[{"id":"1.231284093","rc":[{"batb":[[0,1.45,10],[1,1.44,6.1],[2,1.43,116.28]],"ltp":2.98,"tv":0.03,"id":424679},{"batb":[[0,1.45,10],[1,1.44,7.71],[2,1.43,116.28]],"ltp":1.5,"tv":83.77,"id":5995}]}]}
{"op":"mcm","clk":"11760571538","pt":1722503653341,"mc":[{"id":"1.231284093","rc":[{"batb":[[0,1.44,6.1],[1,1.43,116.28],[2,1.38,131.58]],"ltp":2.98,"tv":0.03,"id":424679},{"batb":[[0,1.44,7.71],[1,1.43,116.28],[2,1.38,131.58]],"ltp":1.5,"tv":83.77,"id":5995}]}]}
{"op":"mcm","clk":"11760571728","pt":1722503656963,"mc":[{"id":"1.231284093","rc":[{"batb":[[0,1.45,10],[1,1.44,6.1],[2,1.43,116.28]],"ltp":2.98,"tv":0.03,"id":424679},{"batb":[[0,1.45,10],[1,1.44,7.71],[2,1.43,116.28]],"ltp":1.5,"tv":83.77,"id":5995}]}]}
{"op":"mcm","clk":"11760571948","pt":1722503661652,"mc":[{"id":"1.231284093","rc":[{"batb":[[0,1.44,6.1],[1,1.43,116.28],[2,1.38,131.58]],"ltp":2.98,"tv":0.03,"id":424679},{"batb":[[0,1.44,7.71],[1,1.43,116.28],[2,1.38,131.58]],"ltp":1.5,"tv":83.77,"id":5995}]}]}
{"op":"mcm","clk":"11760572160","pt":1722503666298,"mc":[{"id":"1.231284093","rc":[{"batb":[[0,1.45,10],[1,1.44,6.1],[2,1.43,116.28]],"ltp":2.98,"tv":0.03,"id":424679},{"batb":[[0,1.45,10],[1,1.44,7.71],[2,1.43,116.28]],"ltp":1.5,"tv":83.77,"id":5995}]}]}
{"op":"mcm","clk":"11760572327","pt":1722503669777,"mc":[{"id":"1.231284093","rc":[{"batb":[[0,1.44,6.1],[1,1.43,116.28],[2,1.38,131.58]],"ltp":2.98,"tv":0.03,"id":424679},{"batb":[[0,1.44,7.71],[1,1.43,116.28],[2,1.38,131.58]],"ltp":1.5,"tv":83.77,"id":5995}]}]}
{"op":"mcm","clk":"11760572501","pt":1722503673369,"mc":[{"id":"1.231284093","rc":[{"batb":[[0,1.45,10],[1,1.44,6.1],[2,1.43,116.28]],"ltp":2.98,"tv":0.03,"id":424679},{"batb":[[0,1.45,10],[1,1.44,7.71],[2,1.43,116.28]],"ltp":1.5,"tv":83.77,"id":5995}]}]}
{"op":"mcm","clk":"11760572688","pt":1722503676782,"mc":[{"id":"1.231284093","rc":[{"batb":[[0,1.44,6.1],[1,1.43,116.28],[2,1.38,131.58]],"ltp":2.98,"tv":0.03,"id":424679},{"batb":[[0,1.44,7.71],[1,1.43,116.28],[2,1.38,131.58]],"ltp":1.5,"tv":83.77,"id":5995}]}]}
{"op":"mcm","clk":"11760572797","pt":1722503679059,"mc":[{"id":"1.231284093","rc":[{"batb":[[0,1.45,10],[1,1.44,6.1],[2,1.43,116.28]],"ltp":2.98,"tv":0.03,"id":424679},{"batb":[[0,1.45,10],[1,1.44,7.71],[2,1.43,116.28]],"ltp":1.5,"tv":83.77,"id":5995}]}]}
{"op":"mcm","clk":"11760573048","pt":1722503684003,"mc":[{"id":"1.231284093","rc":[{"batb":[[0,1.44,6.1],[1,1.43,116.28],[2,1.38,131.58]],"ltp":2.98,"tv":0.03,"id":424679},{"batb":[[0,1.44,7.71],[1,1.43,116.28],[2,1.38,131.58]],"ltp":1.5,"tv":83.77,"id":5995}]}]}
{"op":"mcm","clk":"11760573144","pt":1722503686362,"mc":[{"id":"1.231284093","rc":[{"batb":[[0,1.45,10],[1,1.44,6.1],[2,1.43,116.28]],"ltp":2.98,"tv":0.03,"id":424679},{"batb":[[0,1.45,10],[1,1.44,7.71],[2,1.43,116.28]],"ltp":1.5,"tv":83.77,"id":5995}]}]}
{"op":"mcm","clk":"11760573259","pt":1722503689701,"mc":[{"id":"1.231284093","rc":[{"batb":[[0,1.44,6.1],[1,1.43,116.28],[2,1.38,131.58]],"ltp":2.98,"tv":0.03,"id":424679},{"batb":[[0,1.44,7.71],[1,1.43,116.28],[2,1.38,131.58]],"ltp":1.5,"tv":83.77,"id":5995}]}]}
{"op":"mcm","clk":"11760573362","pt":1722503691904,"mc":[{"id":"1.231284093","rc":[{"batb":[[0,1.45,10],[1,1.44,6.1],[2,1.43,116.28]],"ltp":2.98,"tv":0.03,"id":424679},{"batb":[[0,1.45,10],[1,1.44,7.71],[2,1.43,116.28]],"ltp":1.5,"tv":83.77,"id":5995}]}]}
{"op":"mcm","clk":"11760573539","pt":1722503695199,"mc":[{"id":"1.231284093","rc":[{"batb":[[0,1.44,6.1],[1,1.43,116.28],[2,1.38,131.58]],"ltp":2.98,"tv":0.03,"id":424679},{"batb":[[0,1.44,7.71],[1,1.43,116.28],[2,1.38,131.58]],"ltp":1.5,"tv":83.77,"id":5995}]}]}
{"op":"mcm","clk":"11760573620","pt":1722503697402,"mc":[{"id":"1.231284093","rc":[{"batb":[[0,1.45,10],[1,1.44,6.1],[2,1.43,116.28]],"ltp":2.98,"tv":0.03,"id":424679},{"batb":[[0,1.45,10],[1,1.44,7.71],[2,1.43,116.28]],"ltp":1.5,"tv":83.77,"id":5995}]}]}
{"op":"mcm","clk":"11760573757","pt":1722503700782,"mc":[{"id":"1.231284093","rc":[{"batb":[[0,1.44,6.1],[1,1.43,116.28],[2,1.38,131.58]],"ltp":2.98,"tv":0.03,"id":424679},{"batb":[[0,1.44,7.71],[1,1.43,116.28],[2,1.38,131.58]],"ltp":1.5,"tv":83.77,"id":5995}]}]}
{"op":"mcm","clk":"11760573853","pt":1722503702995,"mc":[{"id":"1.231284093","rc":[{"batb":[[0,1.45,10],[1,1.44,6.1],[2,1.43,116.28]],"ltp":2.98,"tv":0.03,"id":424679},{"batb":[[0,1.45,10],[1,1.44,7.71],[2,1.43,116.28]],"ltp":1.5,"tv":83.77,"id":5995}]}]}
{"op":"mcm","clk":"11760574009","pt":1722503706187,"mc":[{"id":"1.231284093","rc":[{"batb":[[0,1.44,6.1],[1,1.43,116.28],[2,1.38,131.58]],"ltp":2.98,"tv":0.03,"id":424679},{"batb":[[0,1.44,7.71],[1,1.43,116.28],[2,1.38,131.58]],"ltp":1.5,"tv":83.77,"id":5995}]}]}
{"op":"mcm","clk":"11760574150","pt":1722503709628,"mc":[{"id":"1.231284093","rc":[{"batb":[[0,1.45,10],[1,1.44,6.1],[2,1.43,116.28]],"ltp":2.98,"tv":0.03,"id":424679},{"batb":[[0,1.45,10],[1,1.44,7.71],[2,1.43,116.28]],"ltp":1.5,"tv":83.77,"id":5995}]}]}
{"op":"mcm","clk":"11760574317","pt":1722503713887,"mc":[{"id":"1.231284093","rc":[{"batb":[[0,1.44,6.1],[1,1.43,116.28],[2,1.38,131.58]],"ltp":2.98,"tv":0.03,"id":424679},{"batb":[[0,1.44,7.71],[1,1.43,116.28],[2,1.38,131.58]],"ltp":1.5,"tv":83.77,"id":5995}]}]}
{"op":"mcm","clk":"11760574418","pt":1722503716200,"mc":[{"id":"1.231284093","rc":[{"batb":[[0,1.45,10],[1,1.44,6.1],[2,1.43,116.28]],"ltp":2.98,"tv":0.03,"id":424679},{"batb":[[0,1.45,10],[1,1.44,7.71],[2,1.43,116.28]],"ltp":1.5,"tv":83.77,"id":5995}]}]}
{"op":"mcm","clk":"11760574525","pt":1722503719543,"mc":[{"id":"1.231284093","rc":[{"batb":[[0,1.44,6.1],[1,1.43,116.28],[2,1.38,131.58]],"ltp":2.98,"tv":0.03,"id":424679},{"batb":[[0,1.44,7.71],[1,1.43,116.28],[2,1.38,131.58]],"ltp":1.5,"tv":83.77,"id":5995}]}]}
{"op":"mcm","clk":"11760574685","pt":1722503722939,"mc":[{"id":"1.231284093","rc":[{"batb":[[0,1.45,10],[1,1.44,6.1],[2,1.43,116.28]],"ltp":2.98,"tv":0.03,"id":424679},{"batb":[[0,1.45,10],[1,1.44,7.71],[2,1.43,116.28]],"ltp":1.5,"tv":83.77,"id":5995}]}]}
{"op":"mcm","clk":"11760574838","pt":1722503726234,"mc":[{"id":"1.231284093","rc":[{"batb":[[0,1.44,6.1],[1,1.43,116.28],[2,1.38,131.58]],"ltp":2.98,"tv":0.03,"id":424679},{"batb":[[0,1.44,7.71],[1,1.43,116.28],[2,1.38,131.58]],"ltp":1.5,"tv":83.77,"id":5995}]}]}
{"op":"mcm","clk":"11760574952","pt":1722503728720,"mc":[{"id":"1.231284093","rc":[{"batb":[[0,1.45,10],[1,1.44,6.1],[2,1.43,116.28]],"ltp":2.98,"tv":0.03,"id":424679},{"batb":[[0,1.45,10],[1,1.44,7.71],[2,1.43,116.28]],"ltp":1.5,"tv":83.77,"id":5995}]}]}
{"op":"mcm","clk":"11760575105","pt":1722503732027,"mc":[{"id":"1.231284093","rc":[{"batb":[[0,1.44,6.1],[1,1.43,116.28],[2,1.38,131.58]],"ltp":2.98,"tv":0.03,"id":424679},{"batb":[[0,1.44,7.71],[1,1.43,116.28],[2,1.38,131.58]],"ltp":1.5,"tv":83.77,"id":5995}]}]}
{"op":"mcm","clk":"11760575261","pt":1722503735261,"mc":[{"id":"1.231284093","rc":[{"batb":[[0,1.45,10],[1,1.44,6.1],[2,1.43,116.28]],"ltp":2.98,"tv":0.03,"id":424679},{"batb":[[0,1.45,10],[1,1.44,7.71],[2,1.43,116.28]],"ltp":1.5,"tv":83.77,"id":5995}]}]}
{"op":"mcm","clk":"11760575475","pt":1722503740156,"mc":[{"id":"1.231284093","rc":[{"batb":[[0,1.44,6.1],[1,1.43,116.28],[2,1.38,131.58]],"ltp":2.98,"tv":0.03,"id":424679},{"batb":[[0,1.44,7.71],[1,1.43,116.28],[2,1.38,131.58]],"ltp":1.5,"tv":83.77,"id":5995}]}]}
{"op":"mcm","clk":"11760575563","pt":1722503742776,"mc":[{"id":"1.231284093","rc":[{"batb":[[0,1.45,10],[1,1.44,6.1],[2,1.43,116.28]],"ltp":2.98,"tv":0.03,"id":424679},{"batb":[[0,1.45,10],[1,1.44,7.71],[2,1.43,116.28]],"ltp":1.5,"tv":83.77,"id":5995}]}]}
{"op":"mcm","clk":"11760575699","pt":1722503746281,"mc":[{"id":"1.231284093","rc":[{"batb":[[0,1.44,6.1],[1,1.43,116.28],[2,1.38,131.58]],"ltp":2.98,"tv":0.03,"id":424679},{"batb":[[0,1.44,7.71],[1,1.43,116.28],[2,1.38,131.58]],"ltp":1.5,"tv":83.77,"id":5995}]}]}
{"op":"mcm","clk":"11760575806","pt":1722503748447,"mc":[{"id":"1.231284093","rc":[{"batb":[[0,1.45,10],[1,1.44,6.1],[2,1.43,116.28]],"ltp":2.98,"tv":0.03,"id":424679},{"batb":[[0,1.45,10],[1,1.44,7.71],[2,1.43,116.28]],"ltp":1.5,"tv":83.77,"id":5995}]}]}
{"op":"mcm","clk":"11760575936","pt":1722503751854,"mc":[{"id":"1.231284093","rc":[{"batb":[[0,1.44,6.1],[1,1.43,116.28],[2,1.38,131.58]],"ltp":2.98,"tv":0.03,"id":424679},{"batb":[[0,1.44,7.71],[1,1.43,116.28],[2,1.38,131.58]],"ltp":1.5,"tv":83.77,"id":5995}]}]}
{"op":"mcm","clk":"11760576048","pt":1722503754280,"mc":[{"id":"1.231284093","rc":[{"batb":[[0,1.45,10],[1,1.44,6.1],[2,1.43,116.28]],"ltp":2.98,"tv":0.03,"id":424679},{"batb":[[0,1.45,10],[1,1.44,7.71],[2,1.43,116.28]],"ltp":1.5,"tv":83.77,"id":5995}]}]}
{"op":"mcm","clk":"11760576257","pt":1722503758871,"mc":[{"id":"1.231284093","rc":[{"batb":[[0,1.44,6.1],[1,1.43,116.28],[2,1.38,131.58]],"ltp":2.98,"tv":0.03,"id":424679},{"batb":[[0,1.44,7.71],[1,1.43,116.28],[2,1.38,131.58]],"ltp":1.5,"tv":83.77,"id":5995}]}]}
{"op":"mcm","clk":"11760576423","pt":1722503761969,"mc":[{"id":"1.231284093","rc":[{"batb":[[0,1.45,10],[1,1.44,6.1],[2,1.43,116.28]],"ltp":2.98,"tv":0.03,"id":424679},{"batb":[[0,1.45,10],[1,1.44,7.71],[2,1.43,116.28]],"ltp":1.5,"tv":83.77,"id":5995}]}]}
{"op":"mcm","clk":"11760576646","pt":1722503765368,"mc":[{"id":"1.231284093","rc":[{"batb":[[0,1.44,6.1],[1,1.43,116.28],[2,1.38,131.58]],"ltp":2.98,"tv":0.03,"id":424679},{"batb":[[0,1.44,7.71],[1,1.43,116.28],[2,1.38,131.58]],"ltp":1.5,"tv":83.77,"id":5995}]}]}
{"op":"mcm","clk":"11760576682","pt":1722503765993,"mc":[{"id":"1.231284093","rc":[{"batb":[[0,1.44,12.2]],"ltp":2.98,"tv":0.03,"id":424679},{"batb":[[0,1.44,13.43]],"ltp":1.5,"tv":83.77,"id":5995}]}]}
{"op":"mcm","clk":"11760576822","pt":1722503768694,"mc":[{"id":"1.231284093","rc":[{"batb":[[0,1.45,10],[1,1.44,12.2],[2,1.43,116.28]],"ltp":2.98,"tv":0.03,"id":424679},{"batb":[[0,1.45,10],[1,1.44,13.43],[2,1.43,116.28]],"ltp":1.5,"tv":83.77,"id":5995}]}]}
{"op":"mcm","clk":"11760576892","pt":1722503770097,"mc":[{"id":"1.231284093","rc":[{"batb":[[1,1.44,6.1]],"ltp":2.98,"tv":0.03,"id":424679},{"batb":[[1,1.44,7.71]],"ltp":1.5,"tv":83.77,"id":5995}]}]}
{"op":"mcm","clk":"11760576981","pt":1722503772107,"mc":[{"id":"1.231284093","rc":[{"batb":[[0,1.44,6.1],[1,1.43,116.28],[2,1.38,131.58]],"ltp":2.98,"tv":0.03,"id":424679},{"batb":[[0,1.44,7.71],[1,1.43,116.28],[2,1.38,131.58]],"ltp":1.5,"tv":83.77,"id":5995}]}]}
{"op":"mcm","clk":"11760577094","pt":1722503774267,"mc":[{"id":"1.231284093","rc":[{"batb":[[0,1.45,10],[1,1.44,6.1],[2,1.43,116.28]],"ltp":2.98,"tv":0.03,"id":424679},{"batb":[[0,1.45,10],[1,1.44,7.71],[2,1.43,116.28]],"ltp":1.5,"tv":83.77,"id":5995}]}]}
{"op":"mcm","clk":"11760577259","pt":1722503777781,"mc":[{"id":"1.231284093","rc":[{"batb":[[0,1.44,6.1],[1,1.43,116.28],[2,1.38,131.58]],"ltp":2.98,"tv":0.03,"id":424679},{"batb":[[0,1.44,7.71],[1,1.43,116.28],[2,1.38,131.58]],"ltp":1.5,"tv":83.77,"id":5995}]}]}
{"op":"mcm","clk":"11760577383","pt":1722503780108,"mc":[{"id":"1.231284093","rc":[{"batb":[[0,1.45,10],[1,1.44,6.1],[2,1.43,116.28]],"ltp":2.98,"tv":0.03,"id":424679},{"batb":[[0,1.45,10],[1,1.44,7.71],[2,1.43,116.28]],"ltp":1.5,"tv":83.77,"id":5995}]}]}
{"op":"mcm","clk":"11760577570","pt":1722503783524,"mc":[{"id":"1.231284093","rc":[{"batb":[[0,1.44,6.1],[1,1.43,116.28],[2,1.38,131.58]],"ltp":2.98,"tv":0.03,"id":424679},{"batb":[[0,1.44,7.71],[1,1.43,116.28],[2,1.38,131.58]],"ltp":1.5,"tv":83.77,"id":5995}]}]}
{"op":"mcm","clk":"11760577749","pt":1722503787195,"mc":[{"id":"1.231284093","rc":[{"batb":[[0,1.45,10],[1,1.44,6.1],[2,1.43,116.28]],"ltp":2.98,"tv":0.03,"id":424679},{"batb":[[0,1.45,10],[1,1.44,7.71],[2,1.43,116.28]],"ltp":1.5,"tv":83.77,"id":5995}]}]}
{"op":"mcm","clk":"11760577992","pt":1722503792294,"mc":[{"id":"1.231284093","rc":[{"batb":[[0,1.44,6.1],[1,1.43,116.28],[2,1.38,131.58]],"ltp":2.98,"tv":0.03,"id":424679},{"batb":[[0,1.44,7.71],[1,1.43,116.28],[2,1.38,131.58]],"ltp":1.5,"tv":83.77,"id":5995}]}]}
{"op":"mcm","clk":"11760578106","pt":1722503794716,"mc":[{"id":"1.231284093","rc":[{"batb":[[0,1.45,10],[1,1.44,6.1],[2,1.43,116.28]],"ltp":2.98,"tv":0.03,"id":424679},{"batb":[[0,1.45,10],[1,1.44,7.71],[2,1.43,116.28]],"ltp":1.5,"tv":83.77,"id":5995}]}]}
{"op":"mcm","clk":"11760578250","pt":1722503798007,"mc":[{"id":"1.231284093","rc":[{"batb":[[0,1.44,6.1],[1,1.43,116.28],[2,1.38,131.58]],"ltp":2.98,"tv":0.03,"id":424679},{"batb":[[0,1.44,7.71],[1,1.43,116.28],[2,1.38,131.58]],"ltp":1.5,"tv":83.77,"id":5995}]}]}
{"op":"mcm","clk":"11760578370","pt":1722503800217,"mc":[{"id":"1.231284093","rc":[{"batb":[[0,1.45,10],[1,1.44,6.1],[2,1.43,116.28]],"ltp":2.98,"tv":0.03,"id":424679},{"batb":[[0,1.45,10],[1,1.44,7.71],[2,1.43,116.28]],"ltp":1.5,"tv":83.77,"id":5995}]}]}
{"op":"mcm","clk":"11760578519","pt":1722503803511,"mc":[{"id":"1.231284093","rc":[{"batb":[[0,1.44,6.1],[1,1.43,116.28],[2,1.38,131.58]],"ltp":2.98,"tv":0.03,"id":424679},{"batb":[[0,1.44,7.71],[1,1.43,116.28],[2,1.38,131.58]],"ltp":1.5,"tv":83.77,"id":5995}]}]}
{"op":"mcm","clk":"11760578657","pt":1722503806711,"mc":[{"id":"1.231284093","rc":[{"batb":[[0,1.45,10],[1,1.44,6.1],[2,1.43,116.28]],"ltp":2.98,"tv":0.03,"id":424679},{"batb":[[0,1.45,10],[1,1.44,7.71],[2,1.43,116.28]],"ltp":1.5,"tv":83.77,"id":5995}]}]}
{"op":"mcm","clk":"11760578795","pt":1722503810061,"mc":[{"id":"1.231284093","rc":[{"batb":[[0,1.44,6.1],[1,1.43,116.28],[2,1.38,131.58]],"ltp":2.98,"tv":0.03,"id":424679},{"batb":[[0,1.44,7.71],[1,1.43,116.28],[2,1.38,131.58]],"ltp":1.5,"tv":83.77,"id":5995}]}]}
{"op":"mcm","clk":"11760578899","pt":1722503812327,"mc":[{"id":"1.231284093","rc":[{"batb":[[0,1.45,10],[1,1.44,6.1],[2,1.43,116.28]],"ltp":2.98,"tv":0.03,"id":424679},{"batb":[[0,1.45,10],[1,1.44,7.71],[2,1.43,116.28]],"ltp":1.5,"tv":83.77,"id":5995}]}]}
{"op":"mcm","clk":"11760579066","pt":1722503815727,"mc":[{"id":"1.231284093","rc":[{"batb":[[0,1.44,6.1],[1,1.43,116.28],[2,1.38,131.58]],"ltp":2.98,"tv":0.03,"id":424679},{"batb":[[0,1.44,7.71],[1,1.43,116.28],[2,1.38,131.58]],"ltp":1.5,"tv":83.77,"id":5995}]}]}
{"op":"mcm","clk":"11760579168","pt":1722503818045,"mc":[{"id":"1.231284093","rc":[{"batb":[[0,1.45,10],[1,1.44,6.1],[2,1.43,116.28]],"ltp":2.98,"tv":0.03,"id":424679},{"batb":[[0,1.45,10],[1,1.44,7.71],[2,1.43,116.28]],"ltp":1.5,"tv":83.77,"id":5995}]}]}
{"op":"mcm","clk":"11760579355","pt":1722503821342,"mc":[{"id":"1.231284093","rc":[{"batb":[[0,1.44,7.71],[1,1.43,116.28],[2,1.38,131.58]],"ltp":1.5,"tv":83.77,"id":5995}]}]}
{"op":"mcm","clk":"11760579362","pt":1722503821445,"mc":[{"id":"1.231284093","rc":[{"batb":[[0,1.44,6.1],[1,1.43,116.28],[2,1.38,131.58]],"ltp":2.98,"tv":0.03,"id":424679}]}]}
{"op":"mcm","clk":"11760579456","pt":1722503823656,"mc":[{"id":"1.231284093","rc":[{"batb":[[0,1.45,10],[1,1.44,6.1],[2,1.43,116.28]],"ltp":2.98,"tv":0.03,"id":424679},{"batb":[[0,1.45,10],[1,1.44,7.71],[2,1.43,116.28]],"ltp":1.5,"tv":83.77,"id":5995}]}]}
{"op":"mcm","clk":"11760579615","pt":1722503826843,"mc":[{"id":"1.231284093","rc":[{"batb":[[0,1.44,6.1],[1,1.43,116.28],[2,1.38,131.58]],"ltp":2.98,"tv":0.03,"id":424679},{"batb":[[0,1.44,7.71],[1,1.43,116.28],[2,1.38,131.58]],"ltp":1.5,"tv":83.77,"id":5995}]}]}
{"op":"mcm","clk":"11760579770","pt":1722503829673,"mc":[{"id":"1.231284093","rc":[{"batb":[[0,1.45,10],[1,1.44,6.1],[2,1.43,116.28]],"ltp":2.98,"tv":0.03,"id":424679},{"batb":[[0,1.45,10],[1,1.44,7.71],[2,1.43,116.28]],"ltp":1.5,"tv":83.77,"id":5995}]}]}
{"op":"mcm","clk":"11760580009","pt":1722503834667,"mc":[{"id":"1.231284093","rc":[{"batb":[[0,1.44,6.1],[1,1.43,116.28],[2,1.38,131.58]],"ltp":2.98,"tv":0.03,"id":424679},{"batb":[[0,1.44,7.71],[1,1.43,116.28],[2,1.38,131.58]],"ltp":1.5,"tv":83.77,"id":5995}]}]}
{"op":"mcm","clk":"11760580341","pt":1722503838361,"mc":[{"id":"1.231284093","rc":[{"batb":[[0,1.45,10],[1,1.44,6.1],[2,1.43,116.28]],"ltp":2.98,"tv":0.03,"id":424679},{"batb":[[0,1.45,10],[1,1.44,7.71],[2,1.43,116.28]],"ltp":1.5,"tv":83.77,"id":5995}]}]}
{"op":"mcm","clk":"11760580402","pt":1722503839355,"mc":[{"id":"1.231284093","rc":[{"batb":[[0,2.14,32.42],[1,1.45,10],[2,1.44,6.1]],"ltp":2.98,"tv":0.03,"id":424679},{"batb":[[0,1.8,46.2],[1,1.45,10],[2,1.44,7.71]],"ltp":1.5,"tv":83.77,"id":5995}]}]}
{"op":"mcm","clk":"11760580699","pt":1722503841775,"mc":[{"id":"1.231284093","rc":[{"batb":[[1,1.44,6.1],[2,1.43,116.28]],"ltp":2.98,"tv":0.03,"id":424679},{"batb":[[1,1.44,7.71],[2,1.43,116.28]],"ltp":1.5,"tv":83.77,"id":5995}]}]}
{"op":"mcm","clk":"11760580926","pt":1722503844065,"mc":[{"id":"1.231284093","rc":[{"batb":[[0,2.16,10],[1,2.14,32.42],[2,1.44,6.1]],"ltp":2.98,"tv":0.03,"id":424679},{"batb":[[0,1.81,10],[1,1.8,46.2],[2,1.44,7.71]],"ltp":1.5,"tv":83.77,"id":5995}]}]}
{"op":"mcm","clk":"11760581125","pt":1722503847555,"mc":[{"id":"1.231284093","rc":[{"batb":[[0,2.14,32.42],[1,1.44,6.1],[2,1.43,116.28]],"ltp":2.98,"tv":0.03,"id":424679},{"batb":[[0,1.8,46.2],[1,1.44,7.71],[2,1.43,116.28]],"ltp":1.5,"tv":83.77,"id":5995}]}]}
{"op":"mcm","clk":"11760581375","pt":1722503851272,"mc":[{"id":"1.231284093","rc":[{"batb":[[0,2.16,10],[1,2.14,32.42],[2,1.44,6.1]],"ltp":2.98,"tv":0.03,"id":424679},{"batb":[[0,1.81,10],[1,1.8,46.2],[2,1.44,7.71]],"ltp":1.5,"tv":83.77,"id":5995}]}]}
{"op":"mcm","clk":"11760581570","pt":1722503854697,"mc":[{"id":"1.231284093","rc":[{"batb":[[0,2.14,32.42],[1,1.44,6.1],[2,1.43,116.28]],"ltp":2.98,"tv":0.03,"id":424679},{"batb":[[0,1.8,46.2],[1,1.44,7.71],[2,1.43,116.28]],"ltp":1.5,"tv":83.77,"id":5995}]}]}
{"op":"mcm","clk":"11760581784","pt":1722503857803,"mc":[{"id":"1.231284093","rc":[{"batb":[[0,2.16,10],[1,2.14,32.42],[2,1.44,6.1]],"ltp":2.98,"tv":0.03,"id":424679},{"batb":[[0,1.81,10],[1,1.8,46.2],[2,1.44,7.71]],"ltp":1.5,"tv":83.77,"id":5995}]}]}
{"op":"mcm","clk":"11760581996","pt":1722503861078,"mc":[{"id":"1.231284093","rc":[{"batb":[[0,2.14,32.42],[1,1.44,6.1],[2,1.43,116.28]],"ltp":2.98,"tv":0.03,"id":424679},{"batb":[[0,1.8,46.2],[1,1.44,7.71],[2,1.43,116.28]],"ltp":1.5,"tv":83.77,"id":5995}]}]}
{"op":"mcm","clk":"11760582137","pt":1722503863614,"mc":[{"id":"1.231284093","rc":[{"batb":[[0,2.16,10],[1,2.14,32.42],[2,1.44,6.1]],"ltp":2.98,"tv":0.03,"id":424679},{"batb":[[0,1.81,10],[1,1.8,46.2],[2,1.44,7.71]],"ltp":1.5,"tv":83.77,"id":5995}]}]}
{"op":"mcm","clk":"11760582351","pt":1722503866910,"mc":[{"id":"1.231284093","rc":[{"batb":[[0,2.14,32.42],[1,1.44,6.1],[2,1.43,116.28]],"ltp":2.98,"tv":0.03,"id":424679},{"batb":[[0,1.8,46.2],[1,1.44,7.71],[2,1.43,116.28]],"ltp":1.5,"tv":83.77,"id":5995}]}]}
{"op":"mcm","clk":"11760582486","pt":1722503869281,"mc":[{"id":"1.231284093","rc":[{"batb":[[0,2.18,10],[1,2.14,32.42],[2,1.44,6.1]],"ltp":2.98,"tv":0.03,"id":424679},{"batb":[[0,1.82,10],[1,1.8,46.2],[2,1.44,7.71]],"ltp":1.5,"tv":83.77,"id":5995}]}]}
{"op":"mcm","clk":"11760582835","pt":1722503874627,"mc":[{"id":"1.231284093","rc":[{"batb":[[0,1.44,6.1],[1,1.43,116.28],[2,1.38,131.58]],"ltp":2.98,"tv":0.03,"id":424679},{"batb":[[0,1.44,7.71],[1,1.43,116.28],[2,1.38,131.58]],"ltp":1.5,"tv":83.77,"id":5995}]}]}
{"op":"mcm","clk":"11760582949","pt":1722503876988,"mc":[{"id":"1.231284093","rc":[{"batb":[[0,1.45,10],[1,1.44,6.1],[2,1.43,116.28]],"ltp":2.98,"tv":0.03,"id":424679},{"batb":[[0,1.45,10],[1,1.44,7.71],[2,1.43,116.28]],"ltp":1.5,"tv":83.77,"id":5995}]}]}
{"op":"mcm","clk":"11760583058","pt":1722503879505,"mc":[{"id":"1.231284093","rc":[{"batb":[[0,2.14,32.42],[1,1.45,10],[2,1.44,6.1]],"ltp":2.98,"tv":0.03,"id":424679},{"batb":[[0,1.8,46.2],[1,1.45,10],[2,1.44,7.71]],"ltp":1.5,"tv":83.77,"id":5995}]}]}
{"op":"mcm","clk":"11760583120","pt":1722503880450,"mc":[{"id":"1.231284093","rc":[{"batb":[[1,1.44,6.1],[2,1.43,116.28]],"ltp":2.98,"tv":0.03,"id":424679},{"batb":[[1,1.44,7.71],[2,1.43,116.28]],"ltp":1.5,"tv":83.77,"id":5995}]}]}
{"op":"mcm","clk":"11760583313","pt":1722503883443,"mc":[{"id":"1.231284093","rc":[{"batb":[[0,2.16,10],[1,2.14,32.42],[2,1.44,6.1]],"ltp":2.98,"tv":0.03,"id":424679},{"batb":[[0,1.81,10],[1,1.8,46.2],[2,1.44,7.71]],"ltp":1.5,"tv":83.77,"id":5995}]}]}
{"op":"mcm","clk":"11760583494","pt":1722503886842,"mc":[{"id":"1.231284093","rc":[{"batb":[[0,2.14,32.42],[1,1.44,6.1],[2,1.43,116.28]],"ltp":2.98,"tv":0.03,"id":424679},{"batb":[[0,1.8,46.2],[1,1.44,7.71],[2,1.43,116.28]],"ltp":1.5,"tv":83.77,"id":5995}]}]}
{"op":"mcm","clk":"11760583597","pt":1722503889099,"mc":[{"id":"1.231284093","rc":[{"batb":[[0,2.16,10],[1,2.14,32.42],[2,1.44,6.1]],"ltp":2.98,"tv":0.03,"id":424679},{"batb":[[0,1.81,10],[1,1.8,46.2],[2,1.44,7.71]],"ltp":1.5,"tv":83.77,"id":5995}]}]}
{"op":"mcm","clk":"11760583810","pt":1722503892398,"mc":[{"id":"1.231284093","rc":[{"batb":[[0,2.14,32.42],[1,1.44,6.1],[2,1.43,116.28]],"ltp":2.98,"tv":0.03,"id":424679},{"batb":[[0,1.8,46.2],[1,1.44,7.71],[2,1.43,116.28]],"ltp":1.5,"tv":83.77,"id":5995}]}]}
{"op":"mcm","clk":"11760584083","pt":1722503897548,"mc":[{"id":"1.231284093","rc":[{"batb":[[0,2.16,10],[1,2.14,32.42],[2,1.44,6.1]],"ltp":2.98,"tv":0.03,"id":424679},{"batb":[[0,1.81,10],[1,1.8,46.2],[2,1.44,7.71]],"ltp":1.5,"tv":83.77,"id":5995}]}]}
{"op":"mcm","clk":"11760584314","pt":1722503901923,"mc":[{"id":"1.231284093","rc":[{"batb":[[0,2.14,32.42],[1,1.44,6.1],[2,1.43,116.28]],"ltp":2.98,"tv":0.03,"id":424679},{"batb":[[0,1.8,46.2],[1,1.44,7.71],[2,1.43,116.28]],"ltp":1.5,"tv":83.77,"id":5995}]}]}
{"op":"mcm","clk":"11760584428","pt":1722503904537,"mc":[{"id":"1.231284093","rc":[{"batb":[[0,2.16,10],[1,2.14,32.42],[2,1.44,6.1]],"ltp":2.98,"tv":0.03,"id":424679},{"batb":[[0,1.81,10],[1,1.8,46.2],[2,1.44,7.71]],"ltp":1.5,"tv":83.77,"id":5995}]}]}
{"op":"mcm","clk":"11760584613","pt":1722503907837,"mc":[{"id":"1.231284093","rc":[{"batb":[[0,2.14,32.42],[1,1.44,6.1],[2,1.43,116.28]],"ltp":2.98,"tv":0.03,"id":424679},{"batb":[[0,1.8,46.2],[1,1.44,7.71],[2,1.43,116.28]],"ltp":1.5,"tv":83.77,"id":5995}]}]}
{"op":"mcm","clk":"11760584813","pt":1722503911370,"mc":[{"id":"1.231284093","rc":[{"batb":[[0,2.16,10],[1,2.14,32.42],[2,1.44,6.1]],"ltp":2.98,"tv":0.03,"id":424679},{"batb":[[0,1.81,10],[1,1.8,46.2],[2,1.44,7.71]],"ltp":1.5,"tv":83.77,"id":5995}]}]}
{"op":"mcm","clk":"11760585036","pt":1722503914650,"mc":[{"id":"1.231284093","rc":[{"batb":[[0,2.14,32.42],[1,1.44,6.1],[2,1.43,116.28]],"ltp":2.98,"tv":0.03,"id":424679},{"batb":[[0,1.8,46.2],[1,1.44,7.71],[2,1.43,116.28]],"ltp":1.5,"tv":83.77,"id":5995}]}]}
{"op":"mcm","clk":"11760585220","pt":1722503917643,"mc":[{"id":"1.231284093","rc":[{"batb":[[0,2.16,10],[1,2.14,32.42],[2,1.44,6.1]],"ltp":2.98,"tv":0.03,"id":424679},{"batb":[[0,1.81,10],[1,1.8,46.2],[2,1.44,7.71]],"ltp":1.5,"tv":83.77,"id":5995}]}]}
{"op":"mcm","clk":"11760585315","pt":1722503919031,"mc":[{"id":"1.231284093","rc":[{"trd":[[1.81,0.12]],"batb":[[0,1.81,9.94]],"ltp":1.81,"tv":83.88,"id":5995}],"tv":83.92}]}
{"op":"mcm","clk":"11760585442","pt":1722503920947,"mc":[{"id":"1.231284093","rc":[{"batb":[[0,2.14,32.42],[1,1.44,6.1],[2,1.43,116.28]],"ltp":2.98,"tv":0.03,"id":424679},{"batb":[[0,1.8,46.2],[1,1.44,7.71],[2,1.43,116.28]],"ltp":1.81,"tv":83.88,"id":5995}]}]}
{"op":"mcm","clk":"11760631181","pt":1722504756391,"mc":[{"id":"1.231284093","rc":[{"batl":[[0,1.87,15]],"ltp":1.81,"tv":83.88,"id":5995}]}]}
{"op":"mcm","clk":"11760669196","pt":1722505490913,"mc":[{"id":"1.231284093","rc":[{"batb":[[1,1.43,116.28],[2,1.38,131.58]],"ltp":2.98,"tv":0.03,"id":424679},{"batb":[[1,1.43,116.28],[2,1.38,131.58]],"ltp":1.81,"tv":83.88,"id":5995}]}]}
{"op":"mcm","clk":"11760752312","pt":1722506921782,"mc":[{"id":"1.231284093","rc":[{"trd":[[1.8,110]],"batb":[[0,1.8,33.05]],"ltp":1.8,"tv":110.18,"id":5995}],"tv":110.22}]}
{"op":"mcm","clk":"11760752563","pt":1722506926484,"mc":[{"id":"1.231284093","rc":[{"batb":[[0,1.8,46.2]],"ltp":1.8,"tv":110.18,"id":5995}]}]}
{"op":"mcm","clk":"11761014318","pt":1722511150367,"mc":[{"id":"1.231284093","rc":[{"trd":[[1.8,109.97]],"batb":[[1,1.75,29],[2,1.43,116.28]],"ltp":1.8,"tv":110.16,"id":5995}],"tv":110.19}]}
{"op":"mcm","clk":"11761014824","pt":1722511158153,"mc":[{"id":"1.231284093","rc":[{"batl":[[1,1.9,21.75]],"ltp":1.8,"tv":110.16,"id":5995}]}]}
{"op":"mcm","clk":"11761037584","pt":1722511532845,"mc":[{"id":"1.231284093","rc":[{"batb":[[1,1.74,17.32],[2,1.43,116.28]],"ltp":2.98,"tv":0.03,"id":424679},{"batb":[[2,1.74,17.32]],"ltp":1.8,"tv":110.16,"id":5995}]}]}
{"op":"mcm","clk":"11761161957","pt":1722513748809,"mc":[{"id":"1.231284093","rc":[{"trd":[[1.8,109.96]],"ltp":1.8,"tv":110.14,"id":5995}],"tv":110.18}]}
{"op":"mcm","clk":"11761211473","pt":1722514452305,"mc":[{"id":"1.231284093","rc":[{"batb":[[0,1.74,17.32],[1,1.43,116.28],[2,1.38,131.58]],"ltp":2.98,"tv":0.03,"id":424679},{"batb":[[0,1.75,29],[1,1.74,17.32],[2,1.7,13.76]],"ltp":1.8,"tv":110.14,"id":5995}]}]}
{"op":"mcm","clk":"11761336943","pt":1722516615420,"mc":[{"id":"1.231284093","rc":[{"batl":[[0,1.86,3],[1,1.87,15],[2,1.9,21.75]],"ltp":1.8,"tv":110.14,"id":5995}]}]}
{"op":"mcm","clk":"11761381935","pt":1722517410433,"mc":[{"id":"1.231284093","rc":[{"batb":[[0,2.14,32.42],[1,1.74,17.32],[2,1.43,116.28]],"ltp":2.98,"tv":0.03,"id":424679},{"trd":[[1.8,109.94]],"batb":[[0,1.8,46.2],[1,1.75,29],[2,1.74,17.32]],"ltp":1.8,"tv":110.13,"id":5995}],"tv":110.16}]}
{"op":"mcm","clk":"11761651656","pt":1722522109990,"mc":[{"id":"1.231284093","rc":[{"batb":[[0,2.14,37.86]],"ltp":2.98,"tv":0.03,"id":424679},{"trd":[[1.8,109.93]],"batb":[[0,1.8,53.95]],"ltp":1.8,"tv":110.11,"id":5995}],"tv":110.15}]}
{"op":"mcm","clk":"11761774164","pt":1722523863160,"mc":[{"id":"1.231284093","rc":[{"trd":[[1.8,113.93]],"batb":[[0,1.8,51.95]],"ltp":1.8,"tv":114.11,"id":5995}],"tv":114.15}]}
{"op":"mcm","clk":"11761774520","pt":1722523868284,"mc":[{"id":"1.231284093","rc":[{"batb":[[0,1.8,53.95]],"ltp":1.8,"tv":114.11,"id":5995}]}]}
{"op":"mcm","clk":"11761888897","pt":1722525174981,"mc":[{"id":"1.231284093","rc":[{"trd":[[1.8,113.96]],"ltp":1.8,"tv":114.14,"id":5995}],"tv":114.18}]}
{"op":"mcm","clk":"11762214472","pt":1722528369782,"mc":[{"id":"1.231284093","rc":[{"trd":[[1.8,114.12]],"batb":[[0,1.8,53.88]],"ltp":1.8,"tv":114.31,"id":5995}],"tv":114.34}]}
{"op":"mcm","clk":"11762214890","pt":1722528372780,"mc":[{"id":"1.231284093","rc":[{"batb":[[0,1.8,53.95]],"ltp":1.8,"tv":114.31,"id":5995}]}]}
{"op":"mcm","clk":"11762492939","pt":1722530514138,"mc":[{"id":"1.231284093","rc":[{"batb":[[0,1.82,313.23],[1,1.8,53.95],[2,1.75,29]],"ltp":1.8,"tv":114.31,"id":5995}]}]}
{"op":"mcm","clk":"11762493620","pt":1722530520325,"mc":[{"id":"1.231284093","rc":[{"batb":[[0,1.8,53.95],[1,1.75,29],[2,1.74,17.32]],"ltp":1.8,"tv":114.31,"id":5995}]}]}
{"op":"mcm","clk":"11762531981","pt":1722530770786,"mc":[{"id":"1.231284093","rc":[{"trd":[[1.8,114.26]],"batb":[[0,1.8,53.88]],"ltp":1.8,"tv":114.45,"id":5995}],"tv":114.48}]}
{"op":"mcm","clk":"11762532205","pt":1722530772797,"mc":[{"id":"1.231284093","rc":[{"batb":[[0,1.8,53.95]],"ltp":1.8,"tv":114.45,"id":5995}]}]}
{"op":"mcm","clk":"11762629742","pt":1722531752154,"mc":[{"id":"1.231284093","rc":[{"batb":[[0,2.2,227.4],[1,2.14,37.86],[2,1.74,17.32]],"ltp":2.98,"tv":0.03,"id":424679},{"trd":[[1.8,114.28]],"ltp":1.8,"tv":114.46,"id":5995}],"tv":114.5}]}
{"op":"mcm","clk":"11762630649","pt":1722531760497,"mc":[{"id":"1.231284093","rc":[{"trd":[[2.2,454.79]],"batb":[[0,2.14,37.86],[1,1.74,17.32],[2,1.43,116.28]],"ltp":2.2,"tv":454.83,"id":424679}],"tv":569.29}]}
{"op":"mcm","clk":"11762633159","pt":1722531784913,"mc":[{"id":"1.231284093","rc":[{"batb":[[0,2.2,431.27],[1,2.14,37.86],[2,1.74,17.32]],"ltp":2.2,"tv":454.83,"id":424679}]}]}
{"op":"mcm","clk":"11762634291","pt":1722531794734,"mc":[{"id":"1.231284093","rc":[{"trd":[[2.2,1317.34]],"batb":[[0,2.14,37.86],[1,1.74,17.32],[2,1.43,116.28]],"ltp":2.2,"tv":1317.37,"id":424679}],"tv":1431.84}]}
{"op":"mcm","clk":"11762639961","pt":1722531844878,"mc":[{"id":"1.231284093","rc":[{"batb":[[0,2.2,431.27],[1,2.14,37.86],[2,1.74,17.32]],"ltp":2.2,"tv":1317.37,"id":424679}]}]}
{"op":"mcm","clk":"11762640621","pt":1722531849907,"mc":[{"id":"1.231284093","rc":[{"trd":[[2.2,2179.88]],"batb":[[0,2.14,37.86],[1,1.74,17.32],[2,1.43,116.28]],"ltp":2.2,"tv":2179.91,"id":424679}],"tv":2294.38}]}
{"op":"mcm","clk":"11762641662","pt":1722531858108,"mc":[{"id":"1.231284093","rc":[{"batb":[[0,2.2,431.27],[1,2.14,37.86],[2,1.74,17.32]],"ltp":2.2,"tv":2179.91,"id":424679}]}]}
{"op":"mcm","clk":"11762642050","pt":1722531861410,"mc":[{"id":"1.231284093","rc":[{"trd":[[2.2,3042.42]],"batb":[[0,2.14,37.86],[1,1.74,17.32],[2,1.43,116.28]],"ltp":2.2,"tv":3042.45,"id":424679}],"tv":3156.92}]}
{"op":"mcm","clk":"11762642894","pt":1722531868694,"mc":[{"id":"1.231284093","rc":[{"batb":[[0,2.2,431.27],[1,2.14,37.86],[2,1.74,17.32]],"ltp":2.2,"tv":3042.45,"id":424679}]}]}
{"op":"mcm","clk":"11762643375","pt":1722531872497,"mc":[{"id":"1.231284093","rc":[{"trd":[[2.2,3904.96]],"batb":[[0,2.14,37.86],[1,1.74,17.32],[2,1.43,116.28]],"ltp":2.2,"tv":3904.99,"id":424679}],"tv":4019.46}]}
{"op":"mcm","clk":"11762644582","pt":1722531881707,"mc":[{"id":"1.231284093","rc":[{"batb":[[0,2.2,431.27],[1,2.14,37.86],[2,1.74,17.32]],"ltp":2.2,"tv":3904.99,"id":424679}]}]}
{"op":"mcm","clk":"11762644983","pt":1722531885038,"mc":[{"id":"1.231284093","rc":[{"trd":[[2.2,4767.51]],"batb":[[0,2.14,37.86],[1,1.74,17.32],[2,1.43,116.28]],"ltp":2.2,"tv":4767.54,"id":424679}],"tv":4882.0}]}
{"op":"mcm","clk":"11762645829","pt":1722531891818,"mc":[{"id":"1.231284093","rc":[{"batb":[[0,2.2,431.27],[1,2.14,37.86],[2,1.74,17.32]],"ltp":2.2,"tv":4767.54,"id":424679}]}]}
{"op":"mcm","clk":"11762646302","pt":1722531895651,"mc":[{"id":"1.231284093","rc":[{"trd":[[2.2,5630.05]],"batb":[[0,2.14,37.86],[1,1.74,17.32],[2,1.43,116.28]],"ltp":2.2,"tv":5630.08,"id":424679}],"tv":5744.55}]}
{"op":"mcm","clk":"11762647096","pt":1722531902060,"mc":[{"id":"1.231284093","rc":[{"batb":[[0,2.2,431.27],[1,2.14,37.86],[2,1.74,17.32]],"ltp":2.2,"tv":5630.08,"id":424679}]}]}
{"op":"mcm","clk":"11762647273","pt":1722531903345,"mc":[{"id":"1.231284093","rc":[{"batb":[[0,2.22,4],[1,2.2,435.27],[2,2.14,37.86]],"ltp":2.2,"tv":5630.08,"id":424679},{"batl":[[0,1.84,4],[1,1.86,3],[2,1.87,15]],"ltp":1.8,"tv":114.46,"id":5995}]}]}
{"op":"mcm","clk":"11762647505","pt":1722531905235,"mc":[{"id":"1.231284093","rc":[{"trd":[[2.2,6484.59],[2.22,8]],"batb":[[0,2.2,8],[1,2.14,37.86],[2,1.74,17.32]],"ltp":2.2,"tv":6492.62,"id":424679}],"tv":6607.09}]}
{"op":"mcm","clk":"11762647620","pt":1722531906066,"mc":[{"id":"1.231284093","rc":[{"batb":[[0,2.2,4]],"ltp":2.2,"tv":6492.62,"id":424679},{"batl":[[0,1.86,3],[1,1.87,15],[2,1.9,21.75]],"ltp":1.8,"tv":114.46,"id":5995}]}]}
{"op":"mcm","clk":"11762648469","pt":1722531912441,"mc":[{"id":"1.231284093","rc":[{"trd":[[2.2,6492.43]],"batb":[[0,2.14,37.94],[1,1.74,17.32],[2,1.43,116.28]],"ltp":2.2,"tv":6500.46,"id":424679}],"tv":6614.93}]}
{"op":"mcm","clk":"11762649230","pt":1722531918680,"mc":[{"id":"1.231284093","rc":[{"batb":[[0,2.16,4.08],[1,2.14,37.86],[2,1.74,17.32]],"batl":[[0,2.24,4],[1,2.26,4]],"ltp":2.2,"tv":6500.46,"id":424679},{"batb":[[0,1.81,4],[1,1.8,57.95],[2,1.75,29]],"batl":[[0,1.86,7]],"ltp":1.8,"tv":114.46,"id":5995}]}]}
{"op":"mcm","clk":"11762649622","pt":1722531921392,"mc":[{"id":"1.231284093","rc":[{"batb":[[0,2.2,431.35],[1,2.16,4],[2,2.14,37.86]],"ltp":2.2,"tv":6500.46,"id":424679},{"batb":[[0,1.8,53.95],[1,1.75,29],[2,1.74,17.32]],"ltp":1.8,"tv":114.46,"id":5995}]}]}
{"op":"mcm","clk":"11762650379","pt":1722531926614,"mc":[{"id":"1.231284093","rc":[{"trd":[[2.2,7354.82]],"batb":[[0,2.16,4.08],[1,2.14,37.86],[2,1.74,17.32]],"ltp":2.2,"tv":7362.85,"id":424679}],"tv":7477.32}]}
{"op":"mcm","clk":"11762650924","pt":1722531931296,"mc":[{"id":"1.231284093","rc":[{"batb":[[0,2.16,4]],"ltp":2.2,"tv":7362.85,"id":424679}]}]}
{"op":"mcm","clk":"11762651256","pt":1722531933887,"mc":[{"id":"1.231284093","rc":[{"batl":[[0,2.24,4],[1,2.26,4]],"ltp":2.2,"tv":7362.85,"id":424679},{"batb":[[0,1.81,4],[1,1.8,57.95],[2,1.75,29]],"ltp":1.8,"tv":114.46,"id":5995}]}]}
{"op":"mcm","clk":"11762651502","pt":1722531935397,"mc":[{"id":"1.231284093","rc":[{"batb":[[0,2.22,431.27],[1,2.16,4],[2,2.14,37.86]],"ltp":2.2,"tv":7362.85,"id":424679}]}]}
{"op":"mcm","clk":"11762651544","pt":1722531935684,"mc":[{"id":"1.231284093","rc":[{"batb":[[0,1.8,53.95],[1,1.75,29],[2,1.74,17.32]],"ltp":1.8,"tv":114.46,"id":5995}]}]}
{"op":"mcm","clk":"11762652001","pt":1722531938804,"mc":[{"id":"1.231284093","rc":[{"trd":[[2.22,870.54]],"batb":[[0,2.16,4],[1,2.14,37.86],[2,1.74,17.32]],"ltp":2.22,"tv":8225.39,"id":424679}],"tv":8339.86}]}
{"op":"mcm","clk":"11762652704","pt":1722531944002,"mc":[{"id":"1.231284093","rc":[{"batb":[[0,2.22,431.27],[1,2.16,4],[2,2.14,37.86]],"ltp":2.22,"tv":8225.39,"id":424679}]}]}
{"op":"mcm","clk":"11762653168","pt":1722531947699,"mc":[{"id":"1.231284093","rc":[{"trd":[[2.22,1733.08]],"batb":[[0,2.16,4],[1,2.14,37.86],[2,1.74,17.32]],"ltp":2.22,"tv":9087.93,"id":424679}],"tv":9202.4}]}
{"op":"mcm","clk":"11762653352","pt":1722531949112,"mc":[{"id":"1.231284093","rc":[{"batl":[[0,2.24,4],[1,2.26,4]],"ltp":2.22,"tv":9087.93,"id":424679},{"batb":[[0,1.81,4],[1,1.8,57.95],[2,1.75,29]],"ltp":1.8,"tv":114.46,"id":5995}]}]}
{"op":"mcm","clk":"11762654060","pt":1722531954197,"mc":[{"id":"1.231284093","rc":[{"batb":[[0,2.22,431.27],[1,2.16,4],[2,2.14,37.86]],"ltp":2.22,"tv":9087.93,"id":424679},{"batb":[[0,1.8,53.95],[1,1.75,29],[2,1.74,17.32]],"ltp":1.8,"tv":114.46,"id":5995}]}]}
{"op":"mcm","clk":"11762654305","pt":1722531956099,"mc":[{"id":"1.231284093","rc":[{"trd":[[1.8,114.42]],"batb":[[0,1.8,53.88]],"ltp":1.8,"tv":114.6,"id":5995}],"tv":9202.54}]}
{"op":"mcm","clk":"11762654348","pt":1722531956409,"mc":[{"id":"1.231284093","rc":[{"trd":[[2.22,2595.63]],"batb":[[0,2.16,4],[1,2.14,37.86],[2,1.74,17.32]],"ltp":2.22,"tv":9950.47,"id":424679}],"tv":10065.08}]}
{"op":"mcm","clk":"11762654483","pt":1722531957516,"mc":[{"id":"1.231284093","rc":[{"batb":[[0,1.8,53.95]],"ltp":1.8,"tv":114.6,"id":5995}]}]}
{"op":"mcm","clk":"11762654996","pt":1722531961684,"mc":[{"id":"1.231284093","rc":[{"batb":[[0,2.22,431.27],[1,2.16,4],[2,2.14,37.86]],"ltp":2.22,"tv":9950.47,"id":424679}]}]}
{"op":"mcm","clk":"11762655324","pt":1722531964325,"mc":[{"id":"1.231284093","rc":[{"batb":[[0,2.22,435.27]],"ltp":2.22,"tv":9950.47,"id":424679},{"batl":[[0,1.82,4],[1,1.86,7],[2,1.87,15]],"ltp":1.8,"tv":114.6,"id":5995}]}]}
{"op":"mcm","clk":"11762655452","pt":1722531965326,"mc":[{"id":"1.231284093","rc":[{"trd":[[2.22,3458.17]],"batb":[[0,2.22,4]],"ltp":2.22,"tv":10813.02,"id":424679}],"tv":10927.63}]}
{"op":"mcm","clk":"11762655497","pt":1722531965591,"mc":[{"id":"1.231284093","rc":[{"batb":[[0,2.14,37.86],[1,1.74,17.32],[2,1.43,116.28]],"ltp":2.22,"tv":10813.02,"id":424679},{"batl":[[0,1.86,7],[1,1.87,15],[2,1.9,21.75]],"ltp":1.8,"tv":114.6,"id":5995}]}]}
{"op":"mcm","clk":"11762656285","pt":1722531971132,"mc":[{"id":"1.231284093","rc":[{"batb":[[0,2.22,431.27],[1,2.14,37.86],[2,1.74,17.32]],"ltp":2.22,"tv":10813.02,"id":424679}]}]}
{"op":"mcm","clk":"11762656750","pt":1722531974336,"mc":[{"id":"1.231284093","rc":[{"trd":[[2.22,4320.71]],"batb":[[0,2.14,37.86],[1,1.74,17.32],[2,1.43,116.28]],"ltp":2.22,"tv":11675.56,"id":424679}],"tv":11790.17}]}
{"op":"mcm","clk":"11762657538","pt":1722531979734,"mc":[{"id":"1.231284093","rc":[{"batb":[[0,2.18,10],[1,2.16,4],[2,2.14,37.86]],"batl":[[0,2.24,4],[1,2.26,4]],"ltp":2.22,"tv":11675.56,"id":424679},{"batb":[[0,1.81,4],[1,1.8,57.95],[2,1.75,29]],"ltp":1.8,"tv":114.6,"id":5995}]}]}
{"op":"mcm","clk":"11762657738","pt":1722531981108,"mc":[{"id":"1.231284093","rc":[{"batb":[[0,2.22,431.27],[1,2.18,10],[2,2.16,4]],"ltp":2.22,"tv":11675.56,"id":424679}]}]}
{"op":"mcm","clk":"11762657829","pt":1722531981837,"mc":[{"id":"1.231284093","rc":[{"batb":[[0,1.8,53.95],[1,1.75,29],[2,1.74,17.32]],"ltp":1.8,"tv":114.6,"id":5995}]}]}
{"op":"mcm","clk":"11762657987","pt":1722531982941,"mc":[{"id":"1.231284093","rc":[{"batb":[[1,2.16,4],[2,2.14,37.86]],"ltp":2.22,"tv":11675.56,"id":424679}]}]}
{"op":"mcm","clk":"11762658217","pt":1722531984744,"mc":[{"id":"1.231284093","rc":[{"trd":[[2.22,5183.25]],"batb":[[0,2.16,4],[1,2.14,37.86],[2,1.74,17.32]],"ltp":2.22,"tv":12538.1,"id":424679}],"tv":12652.71}]}
{"op":"mcm","clk":"11762659148","pt":1722531991540,"mc":[{"id":"1.231284093","rc":[{"batb":[[0,2.22,431.27],[1,2.16,4],[2,2.14,37.86]],"ltp":2.22,"tv":12538.1,"id":424679}]}]}
{"op":"mcm","clk":"11762659682","pt":1722531995358,"mc":[{"id":"1.231284093","rc":[{"trd":[[2.22,6045.79]],"batb":[[0,2.14,37.86],[1,1.74,17.32],[2,1.43,116.28]],"ltp":2.22,"tv":13400.64,"id":424679},{"batl":[[0,1.82,4],[1,1.86,7],[2,1.87,15]],"ltp":1.8,"tv":114.6,"id":5995}],"tv":13515.25}]}
{"op":"mcm","clk":"11762659760","pt":1722531995942,"mc":[{"id":"1.231284093","rc":[{"batl":[[0,1.86,7],[1,1.87,15],[2,1.9,21.75]],"ltp":1.8,"tv":114.6,"id":5995}]}]}
{"op":"mcm","clk":"11762660296","pt":1722532000061,"mc":[{"id":"1.231284093","rc":[{"batb":[[0,2.22,431.27],[1,2.14,37.86],[2,1.74,17.32]],"ltp":2.22,"tv":13400.64,"id":424679}]}]}
{"op":"mcm","clk":"11762660790","pt":1722532003558,"mc":[{"id":"1.231284093","rc":[{"trd":[[2.22,6908.34]],"batb":[[0,2.14,37.86],[1,1.74,17.32],[2,1.43,116.28]],"ltp":2.22,"tv":14263.18,"id":424679}],"tv":14377.79}]}
{"op":"mcm","clk":"11762661644","pt":1722532009959,"mc":[{"id":"1.231284093","rc":[{"batb":[[0,2.22,431.27],[1,2.16,4],[2,2.14,37.86]],"batl":[[0,2.24,4],[1,2.26,4]],"ltp":2.22,"tv":14263.18,"id":424679},{"batb":[[0,1.81,4],[1,1.8,57.95],[2,1.75,29]],"ltp":1.8,"tv":114.6,"id":5995}]}]}
{"op":"mcm","clk":"11762661715","pt":1722532010468,"mc":[{"id":"1.231284093","rc":[{"batb":[[0,1.8,53.95],[1,1.75,29],[2,1.74,17.32]],"ltp":1.8,"tv":114.6,"id":5995}]}]}
{"op":"mcm","clk":"11762662028","pt":1722532012639,"mc":[{"id":"1.231284093","rc":[{"trd":[[2.22,7770.88]],"batb":[[0,2.16,4],[1,2.14,37.86],[2,1.74,17.32]],"ltp":2.22,"tv":15125.73,"id":424679}],"tv":15240.34}]}
{"op":"mcm","clk":"11762663095","pt":1722532020398,"mc":[{"id":"1.231284093","rc":[{"batb":[[0,2.22,431.27],[1,2.16,4],[2,2.14,37.86]],"ltp":2.22,"tv":15125.73,"id":424679}]}]}
{"op":"mcm","clk":"11762663644","pt":1722532024188,"mc":[{"id":"1.231284093","rc":[{"trd":[[2.22,8633.42]],"batb":[[0,2.16,4],[1,2.14,37.86],[2,1.74,17.32]],"ltp":2.22,"tv":15988.27,"id":424679}],"tv":16102.88}]}
{"op":"mcm","clk":"11762663788","pt":1722532025181,"mc":[{"id":"1.231284093","rc":[{"batb":[[0,2.18,10],[1,2.16,4],[2,2.14,37.86]],"batl":[[0,2.24,4],[1,2.26,4]],"ltp":2.22,"tv":15988.27,"id":424679},{"batb":[[0,1.81,4],[1,1.8,57.95],[2,1.75,29]],"ltp":1.8,"tv":114.6,"id":5995}]}]}
{"op":"mcm","clk":"11762664242","pt":1722532028498,"mc":[{"id":"1.231284093","rc":[{"batb":[[0,2.16,4],[1,2.14,37.86],[2,1.74,17.32]],"ltp":2.22,"tv":15988.27,"id":424679}]}]}
{"op":"mcm","clk":"11762664775","pt":1722532032396,"mc":[{"id":"1.231284093","rc":[{"batb":[[0,2.22,431.27],[1,2.16,4],[2,2.14,37.86]],"ltp":2.22,"tv":15988.27,"id":424679}]}]}
{"op":"mcm","clk":"11762664826","pt":1722532032785,"mc":[{"id":"1.231284093","rc":[{"batb":[[2,1.74,17.32]],"ltp":2.22,"tv":15988.27,"id":424679},{"batb":[[0,1.75,29],[1,1.74,17.32],[2,1.7,13.81]],"ltp":1.8,"tv":114.6,"id":5995}]}]}
{"op":"mcm","clk":"11762665239","pt":1722532035683,"mc":[{"id":"1.231284093","rc":[{"trd":[[2.22,9495.96]],"batb":[[0,2.16,4],[1,1.74,17.32],[2,1.43,116.28]],"ltp":2.22,"tv":16850.81,"id":424679}],"tv":16965.42}]}
{"op":"mcm","clk":"11762665576","pt":1722532038008,"mc":[{"id":"1.231284093","rc":[{"batb":[[1,2.14,37.86],[2,1.74,17.32]],"ltp":2.22,"tv":16850.81,"id":424679},{"batb":[[0,1.8,53.95],[1,1.75,29],[2,1.74,17.32]],"ltp":1.8,"tv":114.6,"id":5995}]}]}
{"op":"mcm","clk":"11762665902","pt":1722532040366,"mc":[{"id":"1.231284093","rc":[{"batl":[[0,2.24,4],[1,2.26,4]],"ltp":2.22,"tv":16850.81,"id":424679},{"batb":[[0,1.81,4],[1,1.8,57.95],[2,1.75,29]],"ltp":1.8,"tv":114.6,"id":5995}]}]}
{"op":"mcm","clk":"11762666286","pt":1722532043377,"mc":[{"id":"1.231284093","rc":[{"batb":[[0,2.22,431.27],[1,2.16,4],[2,2.14,37.86]],"ltp":2.22,"tv":16850.81,"id":424679},{"batb":[[0,1.8,53.95],[1,1.75,29],[2,1.74,17.32]],"ltp":1.8,"tv":114.6,"id":5995}]}]}
{"op":"mcm","clk":"11762666671","pt":1722532046291,"mc":[{"id":"1.231284093","rc":[{"trd":[[2.22,10358.5]],"batb":[[0,2.16,4],[1,2.14,37.86],[2,1.74,17.32]],"ltp":2.22,"tv":17713.35,"id":424679}],"tv":17827.96}]}
{"op":"mcm","clk":"11762667962","pt":1722532055501,"mc":[{"id":"1.231284093","rc":[{"batl":[[0,2.24,4],[1,2.26,4]],"ltp":2.22,"tv":17713.35,"id":424679},{"batb":[[0,1.81,4],[1,1.8,57.95],[2,1.75,29]],"ltp":1.8,"tv":114.6,"id":5995}]}]}
{"op":"mcm","clk":"11762668511","pt":1722532059918,"mc":[{"id":"1.231284093","rc":[{"batb":[[0,2.22,431.27],[1,2.16,4],[2,2.14,37.86]],"ltp":2.22,"tv":17713.35,"id":424679}]}]}
{"op":"mcm","clk":"11762668636","pt":1722532060918,"mc":[{"id":"1.231284093","rc":[{"batb":[[0,1.8,53.95],[1,1.75,29],[2,1.74,17.32]],"ltp":1.8,"tv":114.6,"id":5995}]}]}
{"op":"mcm","clk":"11762668848","pt":1722532062727,"mc":[{"id":"1.231284093","rc":[{"trd":[[2.22,11221.05]],"batb":[[0,2.16,4],[1,2.14,37.86],[2,1.74,17.32]],"ltp":2.22,"tv":18575.9,"id":424679}],"tv":18690.5}]}
{"op":"mcm","clk":"11762669796","pt":1722532069529,"mc":[{"id":"1.231284093","rc":[{"batb":[[0,2.22,431.27],[1,2.16,4],[2,2.14,37.86]],"ltp":2.22,"tv":18575.9,"id":424679}]}]}
{"op":"mcm","clk":"11762669996","pt":1722532070744,"mc":[{"id":"1.231284093","rc":[{"batb":[[0,2.22,435.27]],"ltp":2.22,"tv":18575.9,"id":424679},{"batl":[[0,1.82,4],[1,1.86,7],[2,1.87,15]],"ltp":1.8,"tv":114.6,"id":5995}]}]}
{"op":"mcm","clk":"11762670309","pt":1722532073236,"mc":[{"id":"1.231284093","rc":[{"trd":[[2.22,12083.59]],"batb":[[0,2.22,4]],"ltp":2.22,"tv":19438.44,"id":424679}],"tv":19553.05}]}
{"op":"mcm","clk":"11762670344","pt":1722532073549,"mc":[{"id":"1.231284093","rc":[{"batb":[[0,2.14,37.86],[1,1.74,17.32],[2,1.43,116.28]],"ltp":2.22,"tv":19438.44,"id":424679},{"batl":[[0,1.86,7],[1,1.87,15],[2,1.9,21.75]],"ltp":1.8,"tv":114.6,"id":5995}]}]}
{"op":"mcm","clk":"11762671592","pt":1722532082897,"mc":[{"id":"1.231284093","rc":[{"batb":[[0,2.22,431.27],[1,2.14,37.86],[2,1.74,17.32]],"ltp":2.22,"tv":19438.44,"id":424679}]}]}
{"op":"mcm","clk":"11762672020","pt":1722532086009,"mc":[{"id":"1.231284093","rc":[{"batb":[[0,2.22,435.27]],"ltp":2.22,"tv":19438.44,"id":424679},{"batl":[[0,1.82,4],[1,1.86,7],[2,1.87,15]],"ltp":1.8,"tv":114.6,"id":5995}]}]}
{"op":"mcm","clk":"11762672123","pt":1722532086819,"mc":[{"id":"1.231284093","rc":[{"trd":[[2.22,12946.13]],"batb":[[0,2.14,37.86],[1,1.74,17.32],[2,1.43,116.28]],"ltp":2.22,"tv":20300.98,"id":424679},{"batl":[[0,1.86,7],[1,1.87,15],[2,1.9,21.75]],"ltp":1.8,"tv":114.6,"id":5995}],"tv":20415.59}]}
{"op":"mcm","clk":"11762673280","pt":1722532095228,"mc":[{"id":"1.231284093","rc":[{"batb":[[0,2.22,431.27],[1,2.14,37.86],[2,1.74,17.32]],"ltp":2.22,"tv":20300.98,"id":424679}]}]}
{"op":"mcm","clk":"11762673405","pt":1722532096228,"mc":[{"id":"1.231284093","rc":[{"batb":[[0,2.22,433.6]],"ltp":2.22,"tv":20300.98,"id":424679}]}]}
{"op":"mcm","clk":"11762673822","pt":1722532099337,"mc":[{"id":"1.231284093","rc":[{"trd":[[2.22,13808.67]],"batb":[[0,2.14,37.86],[1,1.74,17.32],[2,1.43,116.28]],"ltp":2.22,"tv":21163.52,"id":424679},{"batl":[[0,1.86,3]],"ltp":1.8,"tv":114.6,"id":5995}],"tv":21278.13}]}
{"op":"mcm","clk":"11762674092","pt":1722532101300,"mc":[{"id":"1.231284093","rc":[{"batb":[[0,2.18,10],[1,2.16,4],[2,2.14,37.86]],"batl":[[0,2.24,4],[1,2.26,4]],"ltp":2.22,"tv":21163.52,"id":424679},{"batb":[[0,1.81,4],[1,1.8,57.95],[2,1.75,29]],"batl":[[0,1.86,7]],"ltp":1.8,"tv":114.6,"id":5995}]}]}
{"op":"mcm","clk":"11762674109","pt":1722532101432,"mc":[{"id":"1.231284093","rc":[{"batl":[[2,2.28,1.48]],"ltp":2.22,"tv":21163.52,"id":424679}]}]}
{"op":"mcm","clk":"11762674515","pt":1722532104536,"mc":[{"id":"1.231284093","rc":[{"batb":[[0,2.16,4],[1,2.14,37.86],[2,1.74,17.32]],"ltp":2.22,"tv":21163.52,"id":424679}]}]}
{"op":"mcm","clk":"11762675420","pt":1722532111323,"mc":[{"id":"1.231284093","rc":[{"batb":[[0,2.22,433.6],[1,2.16,4],[2,2.14,37.86]],"ltp":2.22,"tv":21163.52,"id":424679},{"batb":[[0,1.8,53.95],[1,1.75,29],[2,1.74,17.32]],"ltp":1.8,"tv":114.6,"id":5995}]}]}
{"op":"mcm","clk":"11762675748","pt":1722532113848,"mc":[{"id":"1.231284093","rc":[{"trd":[[2.22,14671.22]],"batb":[[0,2.16,4],[1,2.14,37.86],[2,1.74,17.32]],"ltp":2.22,"tv":22026.06,"id":424679}],"tv":22140.67}]}
{"op":"mcm","clk":"11762676085","pt":1722532116321,"mc":[{"id":"1.231284093","rc":[{"batl":[[0,2.24,4],[1,2.26,4]],"ltp":2.22,"tv":22026.06,"id":424679},{"batb":[[0,1.81,4],[1,1.8,57.95],[2,1.75,29]],"ltp":1.8,"tv":114.6,"id":5995}]}]}
{"op":"mcm","clk":"11762677172","pt":1722532123844,"mc":[{"id":"1.231284093","rc":[{"batb":[[0,2.22,431.27],[1,2.16,4],[2,2.14,37.86]],"ltp":2.22,"tv":22026.06,"id":424679},{"batb":[[0,1.8,53.95],[1,1.75,29],[2,1.74,17.32]],"ltp":1.8,"tv":114.6,"id":5995}]}]}
{"op":"mcm","clk":"11762677657","pt":1722532127051,"mc":[{"id":"1.231284093","rc":[{"trd":[[2.22,15533.76]],"batb":[[0,2.16,4],[1,2.14,37.86],[2,1.74,17.32]],"ltp":2.22,"tv":22888.61,"id":424679}],"tv":23003.22}]}
{"op":"mcm","clk":"11762678302","pt":1722532131550,"mc":[{"id":"1.231284093","rc":[{"batl":[[0,2.24,4],[1,2.26,4]],"ltp":2.22,"tv":22888.61,"id":424679},{"batb":[[0,1.81,4],[1,1.8,57.95],[2,1.75,29]],"ltp":1.8,"tv":114.6,"id":5995}]}]}
{"op":"mcm","clk":"11762678518","pt":1722532133076,"mc":[{"id":"1.231284093","rc":[{"batb":[[0,2.22,431.27],[1,2.16,4],[2,2.14,37.86]],"ltp":2.22,"tv":22888.61,"id":424679},{"batb":[[0,1.8,53.95],[1,1.75,29],[2,1.74,17.32]],"ltp":1.8,"tv":114.6,"id":5995}]}]}
{"op":"mcm","clk":"11762678871","pt":1722532135462,"mc":[{"id":"1.231284093","rc":[{"trd":[[2.22,16396.3]],"batb":[[0,2.16,4],[1,2.14,37.86],[2,1.74,17.32]],"ltp":2.22,"tv":23751.15,"id":424679}],"tv":23865.76}]}
{"op":"mcm","clk":"11762679636","pt":1722532141085,"mc":[{"id":"1.231284093","rc":[{"batb":[[0,2.22,431.27],[1,2.16,4],[2,2.14,37.86]],"ltp":2.22,"tv":23751.15,"id":424679}]}]}
{"op":"mcm","clk":"11762680129","pt":1722532144377,"mc":[{"id":"1.231284093","rc":[{"trd":[[2.22,17258.84]],"batb":[[0,2.16,4],[1,2.14,37.86],[2,1.74,17.32]],"ltp":2.22,"tv":24613.69,"id":424679}],"tv":24728.3}]}
{"op":"mcm","clk":"11762680505","pt":1722532146782,"mc":[{"id":"1.231284093","rc":[{"batl":[[0,2.24,4],[1,2.26,4]],"ltp":2.22,"tv":24613.69,"id":424679},{"batb":[[0,1.81,4],[1,1.8,57.95],[2,1.75,29]],"ltp":1.8,"tv":114.6,"id":5995}]}]}
{"op":"mcm","clk":"11762681132","pt":1722532151181,"mc":[{"id":"1.231284093","rc":[{"batb":[[0,2.22,431.27],[1,2.16,4],[2,2.14,37.86]],"ltp":2.22,"tv":24613.69,"id":424679},{"batb":[[0,1.8,53.95],[1,1.75,29],[2,1.74,17.32]],"ltp":1.8,"tv":114.6,"id":5995}]}]}
{"op":"mcm","clk":"11762681507","pt":1722532153772,"mc":[{"id":"1.231284093","rc":[{"trd":[[2.22,18121.38]],"batb":[[0,2.16,4],[1,2.14,37.86],[2,1.74,17.32]],"ltp":2.22,"tv":25476.23,"id":424679}],"tv":25590.84}]}
{"op":"mcm","clk":"11762682386","pt":1722532159589,"mc":[{"id":"1.231284093","rc":[{"batb":[[0,2.22,431.27],[1,2.16,4],[2,2.14,37.86]],"ltp":2.22,"tv":25476.23,"id":424679}]}]}
{"op":"mcm","clk":"11762682684","pt":1722532161894,"mc":[{"id":"1.231284093","rc":[{"batb":[[0,2.22,435.27]],"ltp":2.22,"tv":25476.23,"id":424679},{"batl":[[0,1.82,4],[1,1.86,7],[2,1.87,15]],"ltp":1.8,"tv":114.6,"id":5995}]}]}
{"op":"mcm","clk":"11762682844","pt":1722532163104,"mc":[{"id":"1.231284093","rc":[{"trd":[[2.22,18983.93]],"batb":[[0,2.22,4]],"ltp":2.22,"tv":26338.77,"id":424679}],"tv":26453.38}]}
{"op":"mcm","clk":"11762682929","pt":1722532163804,"mc":[{"id":"1.231284093","rc":[{"batb":[[0,2.14,37.86],[1,1.74,17.32],[2,1.43,116.28]],"ltp":2.22,"tv":26338.77,"id":424679},{"batl":[[0,1.86,7],[1,1.87,15],[2,1.9,21.75]],"ltp":1.8,"tv":114.6,"id":5995}]}]}
{"op":"mcm","clk":"11762684680","pt":1722532177000,"mc":[{"id":"1.231284093","rc":[{"batb":[[0,2.16,4],[1,2.14,37.86],[2,1.74,17.32]],"batl":[[0,2.24,4],[1,2.26,4]],"ltp":2.22,"tv":26338.77,"id":424679},{"batb":[[0,1.81,4],[1,1.8,57.95],[2,1.75,29]],"ltp":1.8,"tv":114.6,"id":5995}]}]}
{"op":"mcm","clk":"11762685279","pt":1722532181319,"mc":[{"id":"1.231284093","rc":[{"batb":[[0,2.22,431.27],[1,2.16,4],[2,2.14,37.86]],"batl":[[0,2.28,1.48],[1,2.26,0]],"ltp":2.22,"tv":26338.77,"id":424679},{"batb":[[0,1.8,53.95],[1,1.75,29],[2,1.74,17.32]],"ltp":1.8,"tv":114.6,"id":5995}]}]}
{"op":"mcm","clk":"11762685699","pt":1722532184234,"mc":[{"id":"1.231284093","rc":[{"trd":[[2.22,19846.47]],"batb":[[0,2.16,4],[1,2.14,37.86],[2,1.74,17.32]],"ltp":2.22,"tv":27201.32,"id":424679}],"tv":27315.93}]}
{"op":"mcm","clk":"11762686854","pt":1722532192341,"mc":[{"id":"1.231284093","rc":[{"batb":[[0,2.22,431.27],[1,2.16,4],[2,2.14,37.86]],"batl":[[0,2.24,4],[1,2.26,4],[2,2.28,1.48]],"ltp":2.22,"tv":27201.32,"id":424679},{"batb":[[0,1.81,4],[1,1.8,57.95],[2,1.75,29]],"ltp":1.8,"tv":114.6,"id":5995}]}]}
{"op":"mcm","clk":"11762686989","pt":1722532193134,"mc":[{"id":"1.231284093","rc":[{"batb":[[0,1.8,53.95],[1,1.75,29],[2,1.74,17.32]],"ltp":1.8,"tv":114.6,"id":5995}]}]}
{"op":"mcm","clk":"11762687300","pt":1722532195238,"mc":[{"id":"1.231284093","rc":[{"trd":[[2.22,20709.01]],"batb":[[0,2.16,4],[1,2.14,37.86],[2,1.74,17.32]],"ltp":2.22,"tv":28063.86,"id":424679}],"tv":28178.47}]}
{"op":"mcm","clk":"11762688101","pt":1722532201038,"mc":[{"id":"1.231284093","rc":[{"batb":[[0,2.22,431.27],[1,2.16,4],[2,2.14,37.86]],"ltp":2.22,"tv":28063.86,"id":424679}]}]}
{"op":"mcm","clk":"11762688541","pt":1722532204256,"mc":[{"id":"1.231284093","rc":[{"trd":[[2.22,21571.55]],"batb":[[0,2.16,4],[1,2.14,37.86],[2,1.74,17.32]],"ltp":2.22,"tv":28926.4,"id":424679}],"tv":29041.01}]}
{"op":"mcm","clk":"11762688942","pt":1722532207451,"mc":[{"id":"1.231284093","rc":[{"batl":[[0,2.24,4],[1,2.26,4]],"ltp":2.22,"tv":28926.4,"id":424679},{"batb":[[0,1.81,4],[1,1.8,57.95],[2,1.75,29]],"ltp":1.8,"tv":114.6,"id":5995}]}]}
{"op":"mcm","clk":"11762689488","pt":1722532211254,"mc":[{"id":"1.231284093","rc":[{"batb":[[0,2.22,431.27],[1,2.16,4],[2,2.14,37.86]],"batl":[[0,2.28,1.48],[1,2.26,0]],"ltp":2.22,"tv":28926.4,"id":424679},{"batb":[[0,1.8,53.95],[1,1.75,29],[2,1.74,17.32]],"ltp":1.8,"tv":114.6,"id":5995}]}]}
{"op":"mcm","clk":"11762689856","pt":1722532213762,"mc":[{"id":"1.231284093","rc":[{"trd":[[2.22,22434.09]],"batb":[[0,2.16,4],[1,2.14,37.86],[2,1.74,17.32]],"ltp":2.22,"tv":29788.94,"id":424679}],"tv":29903.55}]}
{"op":"mcm","clk":"11762690808","pt":1722532220323,"mc":[{"id":"1.231284093","rc":[{"batb":[[0,2.22,431.27],[1,2.16,4],[2,2.14,37.86]],"ltp":2.22,"tv":29788.94,"id":424679}]}]}
{"op":"mcm","clk":"11762691258","pt":1722532223398,"mc":[{"id":"1.231284093","rc":[{"trd":[[2.22,23296.64]],"batb":[[0,2.22,4]],"ltp":2.22,"tv":30651.49,"id":424679},{"batl":[[0,1.82,4],[1,1.86,7],[2,1.87,15]],"ltp":1.8,"tv":114.6,"id":5995}],"tv":30766.09}]}
{"op":"mcm","clk":"11762691312","pt":1722532223769,"mc":[{"id":"1.231284093","rc":[{"batb":[[0,2.14,37.86],[1,1.74,17.32],[2,1.43,116.28]],"ltp":2.22,"tv":30651.49,"id":424679},{"batl":[[0,1.86,7],[1,1.87,15],[2,1.9,21.75]],"ltp":1.8,"tv":114.6,"id":5995}]}]}
{"op":"mcm","clk":"11762692939","pt":1722532234886,"mc":[{"id":"1.231284093","rc":[{"batb":[[0,2.22,431.27],[1,2.14,37.86],[2,1.74,17.32]],"ltp":2.22,"tv":30651.49,"id":424679}]}]}
{"op":"mcm","clk":"11762693453","pt":1722532238287,"mc":[{"id":"1.231284093","rc":[{"trd":[[2.22,24159.18]],"batb":[[0,2.22,4]],"ltp":2.22,"tv":31514.03,"id":424679},{"batl":[[0,1.82,4],[1,1.86,7],[2,1.87,15]],"ltp":1.8,"tv":114.6,"id":5995}],"tv":31628.64}]}
{"op":"mcm","clk":"11762693607","pt":1722532239214,"mc":[{"id":"1.231284093","rc":[{"batb":[[0,2.14,37.86],[1,1.74,17.32],[2,1.43,116.28]],"ltp":2.22,"tv":31514.03,"id":424679},{"batl":[[0,1.86,7],[1,1.87,15],[2,1.9,21.75]],"ltp":1.8,"tv":114.6,"id":5995}]}]}
{"op":"mcm","clk":"11762694705","pt":1722532246311,"mc":[{"id":"1.231284093","rc":[{"batb":[[0,2.22,431.27],[1,2.14,37.86],[2,1.74,17.32]],"ltp":2.22,"tv":31514.03,"id":424679}]}]}
{"op":"mcm","clk":"11762695349","pt":1722532250388,"mc":[{"id":"1.231284093","rc":[{"trd":[[2.22,25021.72]],"batb":[[0,2.14,37.86],[1,1.74,17.32],[2,1.43,116.28]],"ltp":2.22,"tv":32376.57,"id":424679}],"tv":32491.18}]}
{"op":"mcm","clk":"11762695748","pt":1722532253145,"mc":[{"id":"1.231284093","rc":[{"batb":[[0,2.16,4],[1,2.14,37.86],[2,1.74,17.32]],"batl":[[0,2.24,4],[1,2.26,4]],"ltp":2.22,"tv":32376.57,"id":424679},{"batb":[[0,1.81,4],[1,1.8,57.95],[2,1.75,29]],"ltp":1.8,"tv":114.6,"id":5995}]}]}
{"op":"mcm","clk":"11762696228","pt":1722532256289,"mc":[{"id":"1.231284093","rc":[{"batb":[[0,2.22,431.27],[1,2.16,4],[2,2.14,37.86]],"ltp":2.22,"tv":32376.57,"id":424679}]}]}
{"op":"mcm","clk":"11762696326","pt":1722532257022,"mc":[{"id":"1.231284093","rc":[{"batb":[[0,1.8,53.95],[1,1.75,29],[2,1.74,17.32]],"ltp":1.8,"tv":114.6,"id":5995}]}]}
{"op":"mcm","clk":"11762696680","pt":1722532259399,"mc":[{"id":"1.231284093","rc":[{"trd":[[2.22,25884.26]],"batb":[[0,2.16,4],[1,2.14,37.86],[2,1.74,17.32]],"ltp":2.22,"tv":33239.11,"id":424679}],"tv":33353.72}]}
{"op":"mcm","clk":"11762697763","pt":1722532266491,"mc":[{"id":"1.231284093","rc":[{"batb":[[0,2.22,431.27],[1,2.16,4],[2,2.14,37.86]],"ltp":2.22,"tv":33239.11,"id":424679}]}]}
{"op":"mcm","clk":"11762698035","pt":1722532268325,"mc":[{"id":"1.231284093","rc":[{"batb":[[0,2.22,435.27]],"ltp":2.22,"tv":33239.11,"id":424679},{"batl":[[0,1.82,4],[1,1.86,7],[2,1.87,15]],"ltp":1.8,"tv":114.6,"id":5995}]}]}
{"op":"mcm","clk":"11762698295","pt":1722532270120,"mc":[{"id":"1.231284093","rc":[{"trd":[[2.22,26746.81]],"batb":[[0,2.14,37.86],[1,1.74,17.32],[2,1.43,116.28]],"ltp":2.22,"tv":34101.65,"id":424679},{"batl":[[0,1.86,7],[1,1.87,15],[2,1.9,21.75]],"ltp":1.8,"tv":114.6,"id":5995}],"tv":34216.26}]}
{"op":"mcm","clk":"11762699400","pt":1722532277718,"mc":[{"id":"1.231284093","rc":[{"batb":[[0,2.22,431.27],[1,2.14,37.86],[2,1.74,17.32]],"ltp":2.22,"tv":34101.65,"id":424679}]}]}
{"op":"mcm","clk":"11762699817","pt":1722532281130,"mc":[{"id":"1.231284093","rc":[{"trd":[[2.22,27609.35]],"batb":[[0,2.14,37.86],[1,1.74,17.32],[2,1.43,116.28]],"ltp":2.22,"tv":34964.2,"id":424679}],"tv":35078.81}]}
{"op":"mcm","clk":"11762700132","pt":1722532283546,"mc":[{"id":"1.231284093","rc":[{"batb":[[0,2.16,4],[1,2.14,37.86],[2,1.74,17.32]],"batl":[[0,2.24,4],[1,2.26,4]],"ltp":2.22,"tv":34964.2,"id":424679},{"batb":[[0,1.81,4],[1,1.8,57.95],[2,1.75,29]],"ltp":1.8,"tv":114.6,"id":5995}]}]}
{"op":"mcm","clk":"11762700892","pt":1722532289234,"mc":[{"id":"1.231284093","rc":[{"batb":[[0,2.22,431.27],[1,2.16,4],[2,2.14,37.86]],"ltp":2.22,"tv":34964.2,"id":424679},{"batb":[[0,1.8,53.95],[1,1.75,29],[2,1.74,17.32]],"ltp":1.8,"tv":114.6,"id":5995}]}]}
{"op":"mcm","clk":"11762701240","pt":1722532292128,"mc":[{"id":"1.231284093","rc":[{"trd":[[2.22,28471.89]],"batb":[[0,2.16,4],[1,2.14,37.86],[2,1.74,17.32]],"ltp":2.22,"tv":35826.74,"id":424679}],"tv":35941.35}]}
{"op":"mcm","clk":"11762702027","pt":1722532298578,"mc":[{"id":"1.231284093","rc":[{"batl":[[0,2.24,4],[1,2.26,4]],"ltp":2.22,"tv":35826.74,"id":424679},{"batb":[[0,1.81,4],[1,1.8,57.95],[2,1.75,29]],"ltp":1.8,"tv":114.6,"id":5995}]}]}
{"op":"mcm","clk":"11762702562","pt":1722532302306,"mc":[{"id":"1.231284093","rc":[{"batb":[[0,2.22,431.27],[1,2.16,4],[2,2.14,37.86]],"batl":[[0,2.28,1.48],[1,2.26,0]],"ltp":2.22,"tv":35826.74,"id":424679},{"batb":[[0,1.8,53.95],[1,1.75,29],[2,1.74,17.32]],"ltp":1.8,"tv":114.6,"id":5995}]}]}
{"op":"mcm","clk":"11762702944","pt":1722532305050,"mc":[{"id":"1.231284093","rc":[{"trd":[[2.22,29334.43]],"batb":[[0,2.16,4],[1,2.14,37.86],[2,1.74,17.32]],"ltp":2.22,"tv":36689.28,"id":424679}],"tv":36803.89}]}
{"op":"mcm","clk":"11762704028","pt":1722532313294,"mc":[{"id":"1.231284093","rc":[{"batb":[[0,2.22,431.27],[1,2.16,4],[2,2.14,37.86]],"ltp":2.22,"tv":36689.28,"id":424679}]}]}
{"op":"mcm","clk":"11762704168","pt":1722532314375,"mc":[{"id":"1.231284093","rc":[{"batl":[[0,2.28,1.48]],"ltp":2.22,"tv":36689.28,"id":424679}]}]}
{"op":"mcm","clk":"11762704505","pt":1722532317096,"mc":[{"id":"1.231284093","rc":[{"trd":[[2.22,30196.97]],"batb":[[0,2.16,4],[1,2.14,37.86],[2,1.74,17.32]],"ltp":2.22,"tv":37551.82,"id":424679}],"tv":37666.43}]}
{"op":"mcm","clk":"11762705612","pt":1722532325104,"mc":[{"id":"1.231284093","rc":[{"batb":[[0,2.22,431.27],[1,2.16,4],[2,2.14,37.86]],"ltp":2.22,"tv":37551.82,"id":424679}]}]}
{"op":"mcm","clk":"11762706105","pt":1722532328313,"mc":[{"id":"1.231284093","rc":[{"trd":[[2.22,31059.52]],"batb":[[0,2.16,4],[1,2.14,37.86],[2,1.74,17.32]],"ltp":2.22,"tv":38414.36,"id":424679}],"tv":38528.97}]}
{"op":"mcm","clk":"11762706230","pt":1722532329101,"mc":[{"id":"1.231284093","rc":[{"batl":[[0,2.24,4],[1,2.26,4]],"ltp":2.22,"tv":38414.36,"id":424679},{"batb":[[0,1.81,4],[1,1.8,57.95],[2,1.75,29]],"ltp":1.8,"tv":114.6,"id":5995}]}]}
{"op":"mcm","clk":"11762707147","pt":1722532335295,"mc":[{"id":"1.231284093","rc":[{"batb":[[0,2.22,431.27],[1,2.16,4],[2,2.14,37.86]],"batl":[[0,2.28,1.48],[1,2.26,0]],"ltp":2.22,"tv":38414.36,"id":424679},{"batb":[[0,1.8,53.95],[1,1.75,29],[2,1.74,17.32]],"ltp":1.8,"tv":114.6,"id":5995}]}]}
{"op":"mcm","clk":"11762707602","pt":1722532338523,"mc":[{"id":"1.231284093","rc":[{"trd":[[2.22,31922.06]],"batb":[[0,2.16,4],[1,2.14,37.86],[2,1.74,17.32]],"ltp":2.22,"tv":39276.91,"id":424679}],"tv":39391.52}]}
{"op":"mcm","clk":"11762708449","pt":1722532344329,"mc":[{"id":"1.231284093","rc":[{"batb":[[0,1.81,4],[1,1.8,57.95],[2,1.75,29]],"ltp":1.8,"tv":114.6,"id":5995}]}]}
{"op":"mcm","clk":"11762708465","pt":1722532344430,"mc":[{"id":"1.231284093","rc":[{"batl":[[0,2.24,4],[1,2.26,4]],"ltp":2.22,"tv":39276.91,"id":424679}]}]}
{"op":"mcm","clk":"11762708891","pt":1722532347304,"mc":[{"id":"1.231284093","rc":[{"batb":[[0,2.22,431.27],[1,2.16,4],[2,2.14,37.86]],"ltp":2.22,"tv":39276.91,"id":424679}]}]}
{"op":"mcm","clk":"11762709013","pt":1722532348128,"mc":[{"id":"1.231284093","rc":[{"batb":[[0,1.8,53.95],[1,1.75,29],[2,1.74,17.32]],"ltp":1.8,"tv":114.6,"id":5995}]}]}
{"op":"mcm","clk":"11762709528","pt":1722532351808,"mc":[{"id":"1.231284093","rc":[{"trd":[[2.22,32784.6]],"batb":[[0,2.16,4],[1,2.14,37.86],[2,1.74,17.32]],"ltp":2.22,"tv":40139.45,"id":424679}],"tv":40254.06}]}
{"op":"mcm","clk":"11762710492","pt":1722532358714,"mc":[{"id":"1.231284093","rc":[{"batb":[[0,2.22,431.27],[1,2.16,4],[2,2.14,37.86]],"ltp":2.22,"tv":40139.45,"id":424679}]}]}
{"op":"mcm","clk":"11762710610","pt":1722532359552,"mc":[{"id":"1.231284093","rc":[{"batb":[[0,2.22,435.27]],"ltp":2.22,"tv":40139.45,"id":424679},{"batl":[[0,1.82,4],[1,1.86,7],[2,1.87,15]],"ltp":1.8,"tv":114.6,"id":5995}]}]}
{"op":"mcm","clk":"11762711144","pt":1722532363220,"mc":[{"id":"1.231284093","rc":[{"trd":[[2.22,33647.14]],"batb":[[0,2.22,4]],"ltp":2.22,"tv":41001.99,"id":424679}],"tv":41116.6}]}
{"op":"mcm","clk":"11762711188","pt":1722532363535,"mc":[{"id":"1.231284093","rc":[{"batb":[[0,2.14,37.86],[1,1.74,17.32],[2,1.43,116.28]],"ltp":2.22,"tv":41001.99,"id":424679},{"batl":[[0,1.86,7],[1,1.87,15],[2,1.9,21.75]],"ltp":1.8,"tv":114.6,"id":5995}]}]}
{"op":"mcm","clk":"11762712332","pt":1722532371831,"mc":[{"id":"1.231284093","rc":[{"batb":[[0,2.22,431.27],[1,2.14,37.86],[2,1.74,17.32]],"ltp":2.22,"tv":41001.99,"id":424679}]}]}
{"op":"mcm","clk":"11762712866","pt":1722532375262,"mc":[{"id":"1.231284093","rc":[{"trd":[[2.22,34509.68]],"batb":[[0,2.14,37.86],[1,1.74,17.32],[2,1.43,116.28]],"ltp":2.22,"tv":41864.53,"id":424679},{"batl":[[0,1.82,4],[1,1.86,7],[2,1.87,15]],"ltp":1.8,"tv":114.6,"id":5995}],"tv":41979.14}]}
{"op":"mcm","clk":"11762712947","pt":1722532375750,"mc":[{"id":"1.231284093","rc":[{"batl":[[0,1.86,7],[1,1.87,15],[2,1.9,21.75]],"ltp":1.8,"tv":114.6,"id":5995}]}]}
{"op":"mcm","clk":"11762714050","pt":1722532383162,"mc":[{"id":"1.231284093","rc":[{"batb":[[0,2.22,431.27],[1,2.14,37.86],[2,1.74,17.32]],"ltp":2.22,"tv":41864.53,"id":424679}]}]}
{"op":"mcm","clk":"11762714664","pt":1722532387268,"mc":[{"id":"1.231284093","rc":[{"trd":[[2.22,35372.23]],"batb":[[0,2.14,37.86],[1,1.74,17.32],[2,1.43,116.28]],"ltp":2.22,"tv":42727.08,"id":424679}],"tv":42841.68}]}
{"op":"mcm","clk":"11762715067","pt":1722532389879,"mc":[{"id":"1.231284093","rc":[{"batb":[[0,2.16,4],[1,2.14,37.86],[2,1.74,17.32]],"batl":[[0,2.24,4],[1,2.26,4]],"ltp":2.22,"tv":42727.08,"id":424679},{"batb":[[0,1.81,4],[1,1.8,57.95],[2,1.75,29]],"ltp":1.8,"tv":114.6,"id":5995}]}]}
{"op":"mcm","clk":"11762717918","pt":1722532408330,"mc":[{"id":"1.231284093","rc":[{"batb":[[0,2.16,10]],"ltp":2.22,"tv":42727.08,"id":424679},{"batb":[[0,1.84,470.48],[1,1.81,4],[2,1.8,57.95]],"batl":[[0,1.86,3]],"ltp":1.8,"tv":114.6,"id":5995}]}]}
{"op":"mcm","clk":"11762718083","pt":1722532409320,"mc":[{"id":"1.231284093","rc":[{"batb":[[1,1.74,17.32],[2,1.43,116.28]],"ltp":2.22,"tv":42727.08,"id":424679},{"batb":[[2,1.8,4]],"ltp":1.8,"tv":114.6,"id":5995}]}]}
{"op":"mcm","clk":"11762718411","pt":1722532411391,"mc":[{"id":"1.231284093","rc":[{"trd":[[1.84,940.96]],"batb":[[0,1.81,4],[1,1.8,4],[2,1.75,29]],"ltp":1.84,"tv":1055.56,"id":5995}],"tv":43782.64}]}
{"op":"mcm","clk":"11762718458","pt":1722532411723,"mc":[{"id":"1.231284093","rc":[{"batb":[[0,1.74,17.32],[1,1.43,116.28],[2,1.38,131.58]],"ltp":2.22,"tv":42727.08,"id":424679},{"batb":[[0,1.75,29],[1,1.74,17.32],[2,1.7,13.81]],"ltp":1.84,"tv":1055.56,"id":5995}]}]}
{"op":"mcm","clk":"11762718871","pt":1722532414308,"mc":[{"id":"1.231284093","rc":[{"batb":[[0,2.14,37.86],[1,1.74,17.32],[2,1.43,116.28]],"ltp":2.22,"tv":42727.08,"id":424679},{"batb":[[0,1.8,53.95],[1,1.75,29],[2,1.74,17.32]],"ltp":1.84,"tv":1055.56,"id":5995}]}]}
{"op":"mcm","clk":"11762719510","pt":1722532418501,"mc":[{"id":"1.231284093","rc":[{"batb":[[0,1.84,470.48],[1,1.8,53.95],[2,1.75,29]],"ltp":1.84,"tv":1055.56,"id":5995}]}]}
{"op":"mcm","clk":"11762719802","pt":1722532420410,"mc":[{"id":"1.231284093","rc":[{"batl":[[0,2.18,4],[1,2.2,4]],"ltp":2.22,"tv":42727.08,"id":424679},{"batb":[[0,1.85,4],[1,1.84,474.48],[2,1.8,53.95]],"ltp":1.84,"tv":1055.56,"id":5995}]}]}
{"op":"mcm","clk":"11762720087","pt":1722532422212,"mc":[{"id":"1.231284093","rc":[{"trd":[[1.84,1873.91],[1.85,8]],"batb":[[0,1.84,8],[1,1.8,53.95],[2,1.75,29]],"ltp":1.84,"tv":1996.52,"id":5995}],"tv":44723.6}]}
{"op":"mcm","clk":"11762720162","pt":1722532422720,"mc":[{"id":"1.231284093","rc":[{"batb":[[0,1.84,4]],"ltp":1.84,"tv":1996.52,"id":5995}]}]}
{"op":"mcm","clk":"11762722025","pt":1722532435550,"mc":[{"id":"1.231284093","rc":[{"batb":[[0,2.16,4],[1,2.14,37.86],[2,1.74,17.32]],"ltp":2.22,"tv":42727.08,"id":424679},{"batl":[[0,1.86,7]],"ltp":1.84,"tv":1996.52,"id":5995}]}]}
{"op":"mcm","clk":"11762722275","pt":1722532437247,"mc":[{"id":"1.231284093","rc":[{"trd":[[1.84,1881.75]],"batb":[[0,1.8,54.03],[1,1.75,29],[2,1.74,17.32]],"ltp":1.84,"tv":2004.36,"id":5995}],"tv":44731.44}]}
{"op":"mcm","clk":"11762722747","pt":1722532440718,"mc":[{"id":"1.231284093","rc":[{"batb":[[0,1.8,53.95]],"ltp":1.84,"tv":2004.36,"id":5995}]}]}
{"op":"mcm","clk":"11762723707","pt":1722532447289,"mc":[{"id":"1.231284093","rc":[{"batb":[[0,2.14,37.86],[1,1.74,17.32],[2,1.43,116.28]],"ltp":2.22,"tv":42727.08,"id":424679},{"batb":[[0,1.84,470.48],[1,1.8,53.95],[2,1.75,29]],"batl":[[0,1.86,3]],"ltp":1.84,"tv":2004.36,"id":5995}]}]}
{"op":"mcm","clk":"11762724198","pt":1722532450681,"mc":[{"id":"1.231284093","rc":[{"batl":[[0,2.18,4],[1,2.2,4]],"ltp":2.22,"tv":42727.08,"id":424679},{"trd":[[1.84,2822.71]],"batb":[[0,1.84,4]],"ltp":1.84,"tv":2945.31,"id":5995}],"tv":45672.39}]}
{"op":"mcm","clk":"11762725504","pt":1722532459787,"mc":[{"id":"1.231284093","rc":[{"batb":[[0,1.85,470.48],[1,1.84,4],[2,1.8,53.95]],"ltp":1.84,"tv":2945.31,"id":5995}]}]}
{"op":"mcm","clk":"11762726088","pt":1722532464392,"mc":[{"id":"1.231284093","rc":[{"trd":[[1.85,948.95]],"batb":[[0,1.8,53.95],[1,1.75,29],[2,1.74,17.32]],"ltp":1.85,"tv":3886.27,"id":5995}],"tv":46613.35}]}
{"op":"mcm","clk":"11762726313","pt":1722532465986,"mc":[{"id":"1.231284093","rc":[{"batb":[[0,2.16,4],[1,2.14,37.86],[2,1.74,17.32]],"batl":[[0,2.24,4],[1,2.26,4]],"ltp":2.22,"tv":42727.08,"id":424679},{"batb":[[0,1.8,57.95]],"batl":[[0,1.86,7]],"ltp":1.85,"tv":3886.27,"id":5995}]}]}
{"op":"mcm","clk":"11762726878","pt":1722532470188,"mc":[{"id":"1.231284093","rc":[{"batb":[[0,1.85,470.48],[1,1.8,57.95],[2,1.75,29]],"ltp":1.85,"tv":3886.27,"id":5995}]}]}
{"op":"mcm","clk":"11762727008","pt":1722532471195,"mc":[{"id":"1.231284093","rc":[{"batb":[[0,2.16,10]],"ltp":2.22,"tv":42727.08,"id":424679},{"batl":[[0,1.86,3]],"ltp":1.85,"tv":3886.27,"id":5995}]}]}
{"op":"mcm","clk":"11762727351","pt":1722532474319,"mc":[{"id":"1.231284093","rc":[{"trd":[[1.85,1889.91]],"batb":[[0,1.8,57.95],[1,1.75,29],[2,1.74,17.32]],"ltp":1.85,"tv":4827.22,"id":5995}],"tv":47554.3}]}
{"op":"mcm","clk":"11762727394","pt":1722532474690,"mc":[{"id":"1.231284093","rc":[{"batb":[[0,2.14,37.86],[1,1.74,17.32],[2,1.43,116.28]],"ltp":2.22,"tv":42727.08,"id":424679}]}]}
{"op":"mcm","clk":"11762728143","pt":1722532481096,"mc":[{"id":"1.231284093","rc":[{"batb":[[0,2.16,10],[1,2.14,37.86],[2,1.74,17.32]],"batl":[[0,2.18,4],[1,2.24,4],[2,2.26,4]],"ltp":2.22,"tv":42727.08,"id":424679},{"batb":[[0,1.85,474.48],[1,1.8,57.95],[2,1.75,29]],"ltp":1.85,"tv":4827.22,"id":5995}]}]}
{"op":"mcm","clk":"11762728567","pt":1722532484197,"mc":[{"id":"1.231284093","rc":[{"batb":[[0,2.14,37.86],[1,1.74,17.32],[2,1.43,116.28]],"ltp":2.22,"tv":42727.08,"id":424679},{"trd":[[1.85,2830.86]],"batb":[[0,1.85,4]],"ltp":1.85,"tv":5768.18,"id":5995}],"tv":48495.26}]}
{"op":"mcm","clk":"11762728624","pt":1722532484620,"mc":[{"id":"1.231284093","rc":[{"batl":[[0,2.24,4],[1,2.26,4],[2,2.26,0]],"ltp":2.22,"tv":42727.08,"id":424679},{"batb":[[0,1.8,57.95],[1,1.75,29],[2,1.74,17.32]],"ltp":1.85,"tv":5768.18,"id":5995}]}]}
{"op":"mcm","clk":"11762728974","pt":1722532487129,"mc":[{"id":"1.231284093","rc":[{"batb":[[0,2.16,10],[1,2.14,37.86],[2,1.74,17.32]],"ltp":2.22,"tv":42727.08,"id":424679}]}]}
{"op":"mcm","clk":"11762729439","pt":1722532490430,"mc":[{"id":"1.231284093","rc":[{"batb":[[0,2.14,37.86],[1,1.74,17.32],[2,1.43,116.28]],"ltp":2.22,"tv":42727.08,"id":424679}]}]}
{"op":"mcm","clk":"11762729845","pt":1722532493548,"mc":[{"id":"1.231284093","rc":[{"batb":[[0,2.16,10],[1,2.14,37.86],[2,1.74,17.32]],"ltp":2.22,"tv":42727.08,"id":424679},{"batb":[[0,1.85,470.48],[1,1.8,57.95],[2,1.75,29]],"ltp":1.85,"tv":5768.18,"id":5995}]}]}
{"op":"mcm","clk":"11762729991","pt":1722532494699,"mc":[{"id":"1.231284093","rc":[{"batb":[[1,1.74,17.32],[2,1.43,116.28]],"ltp":2.22,"tv":42727.08,"id":424679},{"batb":[[1,1.8,4]],"ltp":1.85,"tv":5768.18,"id":5995}]}]}
{"op":"mcm","clk":"11762730288","pt":1722532496933,"mc":[{"id":"1.231284093","rc":[{"batb":[[0,1.74,17.32],[1,1.43,116.28],[2,1.38,131.58]],"ltp":2.22,"tv":42727.08,"id":424679},{"trd":[[1.85,3771.82]],"batb":[[0,1.75,29],[1,1.74,17.32],[2,1.7,13.81]],"ltp":1.85,"tv":6709.13,"id":5995}],"tv":49436.21}]}
{"op":"mcm","clk":"11762730618","pt":1722532499627,"mc":[{"id":"1.231284093","rc":[{"batb":[[0,2.14,37.86],[1,1.74,17.32],[2,1.43,116.28]],"ltp":2.22,"tv":42727.08,"id":424679},{"batb":[[0,1.8,53.95],[1,1.75,29],[2,1.74,17.32]],"ltp":1.85,"tv":6709.13,"id":5995}]}]}
{"op":"mcm","clk":"11762731464","pt":1722532506424,"mc":[{"id":"1.231284093","rc":[{"batb":[[0,1.85,470.48],[1,1.8,53.95],[2,1.75,29]],"ltp":1.85,"tv":6709.13,"id":5995}]}]}
{"op":"mcm","clk":"11762731985","pt":1722532510024,"mc":[{"id":"1.231284093","rc":[{"trd":[[1.85,4712.77]],"batb":[[0,1.8,53.95],[1,1.75,29],[2,1.74,17.32]],"ltp":1.85,"tv":7650.09,"id":5995}],"tv":50377.17}]}
{"op":"mcm","clk":"11762732210","pt":1722532511719,"mc":[{"id":"1.231284093","rc":[{"batb":[[0,2.16,4],[1,2.14,37.86],[2,1.74,17.32]],"batl":[[0,2.24,4],[1,2.26,4]],"ltp":2.22,"tv":42727.08,"id":424679},{"batb":[[0,1.8,57.95]],"batl":[[0,1.86,7]],"ltp":1.85,"tv":7650.09,"id":5995}]}]}
{"op":"mcm","clk":"11762732772","pt":1722532516251,"mc":[{"id":"1.231284093","rc":[{"batb":[[0,2.14,37.86],[1,1.74,17.32],[2,1.43,116.28]],"ltp":2.22,"tv":42727.08,"id":424679},{"batb":[[0,1.85,470.48],[1,1.8,57.95],[2,1.75,29]],"batl":[[0,1.86,3]],"ltp":1.85,"tv":7650.09,"id":5995}]}]}
{"op":"mcm","clk":"11762732795","pt":1722532516417,"mc":[{"id":"1.231284093","rc":[{"batb":[[0,2.16,10],[1,2.14,37.86],[2,1.74,17.32]],"ltp":2.22,"tv":42727.08,"id":424679}]}]}
{"op":"mcm","clk":"11762733268","pt":1722532520341,"mc":[{"id":"1.231284093","rc":[{"batb":[[0,1.74,17.32],[1,1.43,116.28],[2,1.38,131.58]],"ltp":2.22,"tv":42727.08,"id":424679},{"trd":[[1.85,5653.73]],"batb":[[0,1.75,29],[1,1.74,17.32],[2,1.7,13.81]],"ltp":1.85,"tv":8591.04,"id":5995}],"tv":51318.12}]}
{"op":"mcm","clk":"11762733773","pt":1722532524753,"mc":[{"id":"1.231284093","rc":[{"batb":[[0,2.14,37.86],[1,1.74,17.32],[2,1.43,116.28]],"ltp":2.22,"tv":42727.08,"id":424679},{"batb":[[0,1.8,53.95],[1,1.75,29],[2,1.74,17.32]],"ltp":1.85,"tv":8591.04,"id":5995}]}]}
{"op":"mcm","clk":"11762734060","pt":1722532527099,"mc":[{"id":"1.231284093","rc":[{"batb":[[0,2.16,4],[1,2.14,37.86],[2,1.74,17.32]],"batl":[[0,2.24,4],[1,2.26,4]],"ltp":2.22,"tv":42727.08,"id":424679},{"batb":[[0,1.85,470.48],[1,1.8,57.95],[2,1.75,29]],"batl":[[0,1.86,7]],"ltp":1.85,"tv":8591.04,"id":5995}]}]}
{"op":"mcm","clk":"11762734184","pt":1722532527850,"mc":[{"id":"1.231284093","rc":[{"batb":[[0,2.16,10]],"ltp":2.22,"tv":42727.08,"id":424679},{"batl":[[0,1.86,3]],"ltp":1.85,"tv":8591.04,"id":5995}]}]}
{"op":"mcm","clk":"11762734462","pt":1722532530290,"mc":[{"id":"1.231284093","rc":[{"batb":[[1,1.74,17.32],[2,1.43,116.28]],"ltp":2.22,"tv":42727.08,"id":424679},{"trd":[[1.85,6594.68]],"batb":[[0,1.8,4],[1,1.75,29],[2,1.74,17.32]],"ltp":1.85,"tv":9532.0,"id":5995}],"tv":52259.08}]}
{"op":"mcm","clk":"11762734565","pt":1722532531286,"mc":[{"id":"1.231284093","rc":[{"batb":[[0,1.74,17.32],[1,1.43,116.28],[2,1.38,131.58]],"ltp":2.22,"tv":42727.08,"id":424679},{"batb":[[0,1.75,29],[1,1.74,17.32],[2,1.7,13.81]],"ltp":1.85,"tv":9532.0,"id":5995}]}]}
{"op":"mcm","clk":"11762734921","pt":1722532534777,"mc":[{"id":"1.231284093","rc":[{"batb":[[0,2.14,37.86],[1,1.74,17.32],[2,1.43,116.28]],"ltp":2.22,"tv":42727.08,"id":424679},{"batb":[[0,1.8,53.95],[1,1.75,29],[2,1.74,17.32]],"ltp":1.85,"tv":9532.0,"id":5995}]}]}
{"op":"mcm","clk":"11762735020","pt":1722532535710,"mc":[{"id":"1.231284093","rc":[{"batb":[[0,1.85,470.48],[1,1.8,53.95],[2,1.75,29]],"ltp":1.85,"tv":9532.0,"id":5995}]}]}
{"op":"mcm","clk":"11762735382","pt":1722532538967,"mc":[{"id":"1.231284093","rc":[{"trd":[[1.85,7535.64]],"batb":[[0,1.8,53.95],[1,1.75,29],[2,1.74,17.32]],"ltp":1.85,"tv":10472.95,"id":5995}],"tv":53200.03}]}
{"op":"mcm","clk":"11762735732","pt":1722532542292,"mc":[{"id":"1.231284093","rc":[{"batb":[[0,2.16,4],[1,2.14,37.86],[2,1.74,17.32]],"batl":[[0,2.24,4],[1,2.26,4]],"ltp":2.22,"tv":42727.08,"id":424679},{"batb":[[0,1.8,57.95]],"batl":[[0,1.86,7]],"ltp":1.85,"tv":10472.95,"id":5995}]}]}
{"op":"mcm","clk":"11762736073","pt":1722532545193,"mc":[{"id":"1.231284093","rc":[{"batb":[[0,2.16,10]],"ltp":2.22,"tv":42727.08,"id":424679},{"batb":[[0,1.85,470.48],[1,1.8,57.95],[2,1.75,29]],"batl":[[0,1.86,3]],"ltp":1.85,"tv":10472.95,"id":5995}]}]}
{"op":"mcm","clk":"11762736388","pt":1722532548101,"mc":[{"id":"1.231284093","rc":[{"trd":[[1.85,8476.59]],"batb":[[0,1.8,57.95],[1,1.75,29],[2,1.74,17.32]],"ltp":1.85,"tv":11413.91,"id":5995}],"tv":54140.99}]}
{"op":"mcm","clk":"11762736428","pt":1722532548419,"mc":[{"id":"1.231284093","rc":[{"batb":[[0,2.14,37.86],[1,1.74,17.32],[2,1.43,116.28]],"ltp":2.22,"tv":42727.08,"id":424679}]}]}
{"op":"mcm","clk":"11762736963","pt":1722532553218,"mc":[{"id":"1.231284093","rc":[{"batb":[[0,2.16,10],[1,2.14,37.86],[2,1.74,17.32]],"ltp":2.22,"tv":42727.08,"id":424679}]}]}
{"op":"mcm","clk":"11762737034","pt":1722532553807,"mc":[{"id":"1.231284093","rc":[{"batb":[[0,1.85,470.48],[1,1.8,57.95],[2,1.75,29]],"ltp":1.85,"tv":11413.91,"id":5995}]}]}
{"op":"mcm","clk":"11762737174","pt":1722532554918,"mc":[{"id":"1.231284093","rc":[{"batb":[[1,1.74,17.32],[2,1.43,116.28]],"ltp":2.22,"tv":42727.08,"id":424679},{"batb":[[1,1.8,4]],"ltp":1.85,"tv":11413.91,"id":5995}]}]}
{"op":"mcm","clk":"11762737407","pt":1722532557099,"mc":[{"id":"1.231284093","rc":[{"batb":[[0,1.74,17.32],[1,1.43,116.28],[2,1.38,131.58]],"ltp":2.22,"tv":42727.08,"id":424679},{"trd":[[1.85,9417.55]],"batb":[[0,1.8,4],[1,1.75,29],[2,1.74,17.32]],"ltp":1.85,"tv":12354.86,"id":5995}],"tv":55081.94}]}
{"op":"mcm","clk":"11762737502","pt":1722532557881,"mc":[{"id":"1.231284093","rc":[{"batl":[[0,2.18,4],[1,2.26,0]],"ltp":2.22,"tv":42727.08,"id":424679},{"batb":[[0,1.85,4]],"ltp":1.85,"tv":12354.86,"id":5995}]}]}
{"op":"mcm","clk":"11762737720","pt":1722532559832,"mc":[{"id":"1.231284093","rc":[{"batb":[[0,2.14,37.86],[1,1.74,17.32],[2,1.43,116.28]],"ltp":2.22,"tv":42727.08,"id":424679},{"batb":[[1,1.8,53.95],[2,1.75,29]],"ltp":1.85,"tv":12354.86,"id":5995}]}]}
{"op":"mcm","clk":"11762737790","pt":1722532560411,"mc":[{"id":"1.231284093","rc":[{"batb":[[0,1.8,53.95],[1,1.75,29],[2,1.74,17.32]],"ltp":1.85,"tv":12354.86,"id":5995}]}]}
{"op":"mcm","clk":"11762738390","pt":1722532565407,"mc":[{"id":"1.231284093","rc":[{"batb":[[0,1.85,470.48],[1,1.8,53.95],[2,1.75,29]],"ltp":1.85,"tv":12354.86,"id":5995}]}]}
{"op":"mcm","clk":"11762738879","pt":1722532569207,"mc":[{"id":"1.231284093","rc":[{"trd":[[1.85,10358.5]],"batb":[[0,1.8,53.95],[1,1.75,29],[2,1.74,17.32]],"ltp":1.85,"tv":13295.82,"id":5995}],"tv":56022.9}]}
{"op":"mcm","clk":"11762739334","pt":1722532572815,"mc":[{"id":"1.231284093","rc":[{"batb":[[0,2.16,4],[1,2.14,37.86],[2,1.74,17.32]],"batl":[[0,2.24,4],[1,2.26,4]],"ltp":2.22,"tv":42727.08,"id":424679},{"batb":[[0,1.8,57.95]],"batl":[[0,1.86,7]],"ltp":1.85,"tv":13295.82,"id":5995}]}]}
{"op":"mcm","clk":"11762739626","pt":1722532575040,"mc":[{"id":"1.231284093","rc":[{"batb":[[0,1.85,470.48],[1,1.8,57.95],[2,1.75,29]],"ltp":1.85,"tv":13295.82,"id":5995}]}]}
{"op":"mcm","clk":"11762739709","pt":1722532575651,"mc":[{"id":"1.231284093","rc":[{"batb":[[0,2.16,10]],"ltp":2.22,"tv":42727.08,"id":424679},{"batl":[[0,1.86,3]],"ltp":1.85,"tv":13295.82,"id":5995}]}]}
{"op":"mcm","clk":"11762739988","pt":1722532578241,"mc":[{"id":"1.231284093","rc":[{"trd":[[1.85,11299.46]],"batb":[[0,1.8,57.95],[1,1.75,29],[2,1.74,17.32]],"ltp":1.85,"tv":14236.77,"id":5995}],"tv":56963.85}]}
{"op":"mcm","clk":"11762740077","pt":1722532578928,"mc":[{"id":"1.231284093","rc":[{"batb":[[0,2.14,37.86],[1,1.74,17.32],[2,1.43,116.28]],"ltp":2.22,"tv":42727.08,"id":424679}]}]}
{"op":"mcm","clk":"11762740864","pt":1722532585331,"mc":[{"id":"1.231284093","rc":[{"batb":[[0,2.16,10]],"ltp":2.22,"tv":42727.08,"id":424679},{"batb":[[0,1.85,470.48],[1,1.8,4],[2,1.75,29]],"ltp":1.85,"tv":14236.77,"id":5995}]}]}
{"op":"mcm","clk":"11762741191","pt":1722532588218,"mc":[{"id":"1.231284093","rc":[{"batb":[[0,1.74,17.32],[1,1.43,116.28],[2,1.38,131.58]],"batl":[[0,2.18,4],[1,2.24,4],[2,2.26,4]],"ltp":2.22,"tv":42727.08,"id":424679},{"batb":[[0,1.85,474.48]],"ltp":1.85,"tv":14236.77,"id":5995}]}]}
{"op":"mcm","clk":"11762741318","pt":1722532589238,"mc":[{"id":"1.231284093","rc":[{"trd":[[1.85,12240.41]],"batb":[[0,1.85,4]],"ltp":1.85,"tv":15177.73,"id":5995}],"tv":57904.81}]}
{"op":"mcm","clk":"11762741439","pt":1722532590256,"mc":[{"id":"1.231284093","rc":[{"batb":[[0,2.14,37.86],[1,1.74,17.32],[2,1.43,116.28]],"ltp":2.22,"tv":42727.08,"id":424679},{"batb":[[0,1.8,53.95],[1,1.75,29],[2,1.74,17.32]],"ltp":1.85,"tv":15177.73,"id":5995}]}]}
{"op":"mcm","clk":"11762742079","pt":1722532595546,"mc":[{"id":"1.231284093","rc":[{"batb":[[0,1.85,470.48],[1,1.8,53.95],[2,1.75,29]],"ltp":1.85,"tv":15177.73,"id":5995}]}]}
{"op":"mcm","clk":"11762742526","pt":1722532599048,"mc":[{"id":"1.231284093","rc":[{"trd":[[1.85,13181.37]],"batb":[[0,1.8,53.95],[1,1.75,29],[2,1.74,17.32]],"ltp":1.85,"tv":16118.68,"id":5995}],"tv":58845.76}]}
{"op":"mcm","clk":"11762743035","pt":1722532603323,"mc":[{"id":"1.231284093","rc":[{"batb":[[0,2.16,4],[1,2.14,37.86],[2,1.74,17.32]],"batl":[[0,2.24,4],[1,2.26,4]],"ltp":2.22,"tv":42727.08,"id":424679},{"batb":[[0,1.8,57.95]],"batl":[[0,1.86,7]],"ltp":1.85,"tv":16118.68,"id":5995}]}]}
{"op":"mcm","clk":"11762743216","pt":1722532604951,"mc":[{"id":"1.231284093","rc":[{"batb":[[0,1.85,470.48],[1,1.8,57.95],[2,1.75,29]],"ltp":1.85,"tv":16118.68,"id":5995}]}]}
{"op":"mcm","clk":"11762743282","pt":1722532605639,"mc":[{"id":"1.231284093","rc":[{"batb":[[0,2.16,10]],"ltp":2.22,"tv":42727.08,"id":424679},{"batl":[[0,1.86,3]],"ltp":1.85,"tv":16118.68,"id":5995}]}]}
{"op":"mcm","clk":"11762743680","pt":1722532608972,"mc":[{"id":"1.231284093","rc":[{"batb":[[0,2.14,37.86],[1,1.74,17.32],[2,1.43,116.28]],"ltp":2.22,"tv":42727.08,"id":424679},{"trd":[[1.85,14122.33]],"batb":[[0,1.8,57.95],[1,1.75,29],[2,1.74,17.32]],"ltp":1.85,"tv":17059.64,"id":5995}],"tv":59786.72}]}
{"op":"mcm","clk":"11762744030","pt":1722532612162,"mc":[{"id":"1.231284093","rc":[{"batb":[[0,2.16,10],[1,2.14,37.86],[2,1.74,17.32]],"ltp":2.22,"tv":42727.08,"id":424679}]}]}
{"op":"mcm","clk":"11762744303","pt":1722532614460,"mc":[{"id":"1.231284093","rc":[{"batb":[[0,1.85,470.48],[1,1.8,57.95],[2,1.75,29]],"ltp":1.85,"tv":17059.64,"id":5995}]}]}
{"op":"mcm","clk":"11762744430","pt":1722532615464,"mc":[{"id":"1.231284093","rc":[{"batb":[[0,1.74,17.32],[1,1.43,116.28],[2,1.38,131.58]],"ltp":2.22,"tv":42727.08,"id":424679},{"batb":[[1,1.8,4]],"ltp":1.85,"tv":17059.64,"id":5995}]}]}
{"op":"mcm","clk":"11762744900","pt":1722532619346,"mc":[{"id":"1.231284093","rc":[{"batb":[[0,1.75,10],[1,1.74,17.32],[2,1.43,116.28]],"ltp":2.22,"tv":42727.08,"id":424679},{"trd":[[1.85,15063.28]],"batb":[[0,1.85,4],[1,1.75,29],[2,1.74,17.32]],"ltp":1.85,"tv":18000.59,"id":5995}],"tv":60727.67}]}
{"op":"mcm","clk":"11762745027","pt":1722532620388,"mc":[{"id":"1.231284093","rc":[{"batb":[[0,2.14,37.86],[1,1.75,10],[2,1.74,17.32]],"ltp":2.22,"tv":42727.08,"id":424679},{"batb":[[0,1.8,53.95]],"ltp":1.85,"tv":18000.59,"id":5995}]}]}
{"op":"mcm","clk":"11762745237","pt":1722532621862,"mc":[{"id":"1.231284093","rc":[{"batb":[[1,1.74,17.32],[2,1.43,116.28]],"ltp":2.22,"tv":42727.08,"id":424679}]}]}
{"op":"mcm","clk":"11762745492","pt":1722532623714,"mc":[{"id":"1.231284093","rc":[{"batb":[[0,1.85,470.48],[1,1.8,53.95],[2,1.75,29]],"ltp":1.85,"tv":18000.59,"id":5995}]}]}
{"op":"mcm","clk":"11762745933","pt":1722532627174,"mc":[{"id":"1.231284093","rc":[{"trd":[[1.85,16004.24]],"batb":[[0,1.8,53.95],[1,1.75,29],[2,1.74,17.32]],"ltp":1.85,"tv":18941.55,"id":5995}],"tv":61668.63}]}
{"op":"mcm","clk":"11762746567","pt":1722532632570,"mc":[{"id":"1.231284093","rc":[{"batb":[[0,1.85,470.48],[1,1.8,53.95],[2,1.75,29]],"ltp":1.85,"tv":18941.55,"id":5995}]}]}
{"op":"mcm","clk":"11762746723","pt":1722532633786,"mc":[{"id":"1.231284093","rc":[{"batl":[[0,2.18,4]],"ltp":2.22,"tv":42727.08,"id":424679},{"batb":[[0,1.85,474.48]],"ltp":1.85,"tv":18941.55,"id":5995}]}]}
{"op":"mcm","clk":"11762746986","pt":1722532635990,"mc":[{"id":"1.231284093","rc":[{"trd":[[1.85,16945.19]],"batb":[[0,1.85,4]],"ltp":1.85,"tv":19882.5,"id":5995}],"tv":62609.58}]}
{"op":"mcm","clk":"11762747061","pt":1722532636572,"mc":[{"id":"1.231284093","rc":[{"batb":[[0,1.8,53.95],[1,1.75,29],[2,1.74,17.32]],"ltp":1.85,"tv":19882.5,"id":5995}]}]}
{"op":"mcm","clk":"11762747854","pt":1722532642583,"mc":[{"id":"1.231284093","rc":[{"batb":[[0,1.85,470.48],[1,1.8,53.95],[2,1.75,29]],"ltp":1.85,"tv":19882.5,"id":5995}]}]}
{"op":"mcm","clk":"11762748335","pt":1722532646252,"mc":[{"id":"1.231284093","rc":[{"trd":[[1.85,17886.15]],"batb":[[0,1.8,53.95],[1,1.75,29],[2,1.74,17.32]],"ltp":1.85,"tv":20823.46,"id":5995}],"tv":63550.54}]}
{"op":"mcm","clk":"11762748656","pt":1722532649009,"mc":[{"id":"1.231284093","rc":[{"batb":[[0,2.16,4],[1,2.14,37.86],[2,1.74,17.32]],"batl":[[0,2.24,4],[1,2.26,4]],"ltp":2.22,"tv":42727.08,"id":424679},{"batb":[[0,1.8,57.95]],"batl":[[0,1.86,7]],"ltp":1.85,"tv":20823.46,"id":5995}]}]}
{"op":"mcm","clk":"11762749022","pt":1722532652207,"mc":[{"id":"1.231284093","rc":[{"batb":[[0,2.14,37.86],[1,1.74,17.32],[2,1.43,116.28]],"ltp":2.22,"tv":42727.08,"id":424679},{"batb":[[0,1.85,470.48],[1,1.8,57.95],[2,1.75,29]],"batl":[[0,1.86,3]],"ltp":1.85,"tv":20823.46,"id":5995}]}]}
{"op":"mcm","clk":"11762749046","pt":1722532652410,"mc":[{"id":"1.231284093","rc":[{"batb":[[0,2.16,10],[1,2.14,37.86],[2,1.74,17.32]],"ltp":2.22,"tv":42727.08,"id":424679}]}]}
{"op":"mcm","clk":"11762749516","pt":1722532656191,"mc":[{"id":"1.231284093","rc":[{"batb":[[0,1.74,17.32],[1,1.43,116.28],[2,1.38,131.58]],"ltp":2.22,"tv":42727.08,"id":424679},{"trd":[[1.85,18827.1]],"batb":[[0,1.75,29],[1,1.74,17.32],[2,1.7,13.81]],"ltp":1.85,"tv":21764.41,"id":5995}],"tv":64491.49}]}
{"op":"mcm","clk":"11762750055","pt":1722532660586,"mc":[{"id":"1.231284093","rc":[{"batb":[[0,2.14,37.86],[1,1.74,17.32],[2,1.43,116.28]],"ltp":2.22,"tv":42727.08,"id":424679},{"batb":[[0,1.8,53.95],[1,1.75,29],[2,1.74,17.32]],"ltp":1.85,"tv":21764.41,"id":5995}]}]}
{"op":"mcm","clk":"11762750509","pt":1722532664213,"mc":[{"id":"1.231284093","rc":[{"batb":[[0,2.16,4],[1,2.14,37.86],[2,1.74,17.32]],"batl":[[0,2.24,4],[1,2.26,4]],"ltp":2.22,"tv":42727.08,"id":424679},{"batb":[[0,1.85,470.48],[1,1.8,57.95],[2,1.75,29]],"batl":[[0,1.86,7]],"ltp":1.85,"tv":21764.41,"id":5995}]}]}
{"op":"mcm","clk":"11762750601","pt":1722532664976,"mc":[{"id":"1.231284093","rc":[{"batb":[[0,2.16,10]],"ltp":2.22,"tv":42727.08,"id":424679},{"batl":[[0,1.86,3]],"ltp":1.85,"tv":21764.41,"id":5995}]}]}
{"op":"mcm","clk":"11762750698","pt":1722532665711,"mc":[{"id":"1.231284093","rc":[{"batb":[[1,1.74,17.32],[2,1.43,116.28]],"ltp":2.22,"tv":42727.08,"id":424679},{"batb":[[1,1.8,4]],"ltp":1.85,"tv":21764.41,"id":5995}]}]}
{"op":"mcm","clk":"11762750891","pt":1722532667332,"mc":[{"id":"1.231284093","rc":[{"trd":[[1.85,19768.06]],"batb":[[0,1.75,29],[1,1.74,17.32],[2,1.7,13.81]],"ltp":1.85,"tv":22705.37,"id":5995}],"tv":65432.45}]}
{"op":"mcm","clk":"11762751004","pt":1722532668278,"mc":[{"id":"1.231284093","rc":[{"batb":[[0,1.74,17.32],[1,1.43,116.28],[2,1.38,131.58]],"ltp":2.22,"tv":42727.08,"id":424679}]}]}
{"op":"mcm","clk":"11762751275","pt":1722532670600,"mc":[{"id":"1.231284093","rc":[{"batb":[[0,2.14,37.86],[1,1.74,17.32],[2,1.43,116.28]],"ltp":2.22,"tv":42727.08,"id":424679},{"batb":[[0,1.8,53.95],[1,1.75,29],[2,1.74,17.32]],"ltp":1.85,"tv":22705.37,"id":5995}]}]}
{"op":"mcm","clk":"11762751649","pt":1722532673816,"mc":[{"id":"1.231284093","rc":[{"batb":[[0,1.85,470.48],[1,1.8,53.95],[2,1.75,29]],"ltp":1.85,"tv":22705.37,"id":5995}]}]}
{"op":"mcm","clk":"11762752103","pt":1722532677513,"mc":[{"id":"1.231284093","rc":[{"trd":[[1.85,20709.01]],"batb":[[0,1.8,53.95],[1,1.75,29],[2,1.74,17.32]],"ltp":1.85,"tv":23646.32,"id":5995}],"tv":66373.4}]}
{"op":"mcm","clk":"11762752372","pt":1722532679413,"mc":[{"id":"1.231284093","rc":[{"batb":[[0,2.16,4],[1,2.14,37.86],[2,1.74,17.32]],"batl":[[0,2.24,4],[1,2.26,4]],"ltp":2.22,"tv":42727.08,"id":424679},{"batb":[[0,1.8,57.95]],"batl":[[0,1.86,7]],"ltp":1.85,"tv":23646.32,"id":5995}]}]}
{"op":"mcm","clk":"11762752954","pt":1722532683903,"mc":[{"id":"1.231284093","rc":[{"batb":[[0,1.85,470.48],[1,1.8,57.95],[2,1.75,29]],"ltp":1.85,"tv":23646.32,"id":5995}]}]}
{"op":"mcm","clk":"11762753062","pt":1722532684713,"mc":[{"id":"1.231284093","rc":[{"batb":[[0,2.16,10]],"ltp":2.22,"tv":42727.08,"id":424679},{"batl":[[0,1.86,3]],"ltp":1.85,"tv":23646.32,"id":5995}]}]}
{"op":"mcm","clk":"11762753190","pt":1722532685725,"mc":[{"id":"1.231284093","rc":[{"batb":[[1,1.74,17.32],[2,1.43,116.28]],"ltp":2.22,"tv":42727.08,"id":424679},{"batb":[[1,1.8,4]],"ltp":1.85,"tv":23646.32,"id":5995}]}]}
{"op":"mcm","clk":"11762753490","pt":1722532688395,"mc":[{"id":"1.231284093","rc":[{"batb":[[0,1.74,17.32],[1,1.43,116.28],[2,1.38,131.58]],"ltp":2.22,"tv":42727.08,"id":424679},{"trd":[[1.85,21649.97]],"batb":[[0,1.8,4],[1,1.75,29],[2,1.74,17.32]],"ltp":1.85,"tv":24587.28,"id":5995}],"tv":67314.36}]}
{"op":"mcm","clk":"11762753502","pt":1722532688498,"mc":[{"id":"1.231284093","rc":[{"batb":[[0,1.75,29],[1,1.74,17.32],[2,1.7,13.81]],"ltp":1.85,"tv":24587.28,"id":5995}]}]}
{"op":"mcm","clk":"11762753773","pt":1722532690719,"mc":[{"id":"1.231284093","rc":[{"batb":[[0,2.14,37.86],[1,1.74,17.32],[2,1.43,116.28]],"ltp":2.22,"tv":42727.08,"id":424679},{"batb":[[0,1.8,53.95],[1,1.75,29],[2,1.74,17.32]],"ltp":1.85,"tv":24587.28,"id":5995}]}]}
{"op":"mcm","clk":"11762754182","pt":1722532694033,"mc":[{"id":"1.231284093","rc":[{"batb":[[0,1.85,470.48],[1,1.8,53.95],[2,1.75,29]],"ltp":1.85,"tv":24587.28,"id":5995}]}]}
{"op":"mcm","clk":"11762754241","pt":1722532694516,"mc":[{"id":"1.231284093","rc":[{"batl":[[0,2.18,4]],"ltp":2.22,"tv":42727.08,"id":424679},{"batb":[[0,1.85,474.48]],"ltp":1.85,"tv":24587.28,"id":5995}]}]}
{"op":"mcm","clk":"11762754630","pt":1722532697941,"mc":[{"id":"1.231284093","rc":[{"trd":[[1.85,22590.92]],"batb":[[0,1.8,53.95],[1,1.75,29],[2,1.74,17.32]],"ltp":1.85,"tv":25528.23,"id":5995}],"tv":68255.31}]}
{"op":"mcm","clk":"11762755397","pt":1722532704834,"mc":[{"id":"1.231284093","rc":[{"batb":[[0,1.85,470.48],[1,1.8,53.95],[2,1.75,29]],"ltp":1.85,"tv":25528.23,"id":5995}]}]}
{"op":"mcm","clk":"11762755929","pt":1722532708936,"mc":[{"id":"1.231284093","rc":[{"trd":[[1.85,23531.88]],"batb":[[0,1.8,53.95],[1,1.75,29],[2,1.74,17.32]],"ltp":1.85,"tv":26469.19,"id":5995}],"tv":69196.27}]}
{"op":"mcm","clk":"11762756024","pt":1722532709736,"mc":[{"id":"1.231284093","rc":[{"batb":[[0,2.16,4],[1,2.14,37.86],[2,1.74,17.32]],"batl":[[0,2.24,4],[1,2.26,4]],"ltp":2.22,"tv":42727.08,"id":424679},{"batb":[[0,1.8,57.95]],"batl":[[0,1.86,7]],"ltp":1.85,"tv":26469.19,"id":5995}]}]}
{"op":"mcm","clk":"11762756675","pt":1722532715376,"mc":[{"id":"1.231284093","rc":[{"batb":[[0,2.16,10]],"ltp":2.22,"tv":42727.08,"id":424679},{"batb":[[0,1.85,470.48],[1,1.8,57.95],[2,1.75,29]],"batl":[[0,1.86,3]],"ltp":1.85,"tv":26469.19,"id":5995}]}]}
{"op":"mcm","clk":"11762756734","pt":1722532715849,"mc":[{"id":"1.231284093","rc":[{"batb":[[1,1.74,17.32],[2,1.43,116.28]],"ltp":2.22,"tv":42727.08,"id":424679},{"batb":[[1,1.8,4]],"ltp":1.85,"tv":26469.19,"id":5995}]}]}
{"op":"mcm","clk":"11762757012","pt":1722532718157,"mc":[{"id":"1.231284093","rc":[{"trd":[[1.85,24472.83]],"batb":[[0,1.8,4],[1,1.75,29],[2,1.74,17.32]],"ltp":1.85,"tv":27410.14,"id":5995}],"tv":70137.22}]}
{"op":"mcm","clk":"11762757071","pt":1722532718625,"mc":[{"id":"1.231284093","rc":[{"batb":[[0,1.74,17.32],[1,1.43,116.28],[2,1.38,131.58]],"ltp":2.22,"tv":42727.08,"id":424679},{"batb":[[0,1.75,29],[1,1.74,17.32],[2,1.7,13.81]],"ltp":1.85,"tv":27410.14,"id":5995}]}]}
{"op":"mcm","clk":"11762757343","pt":1722532720871,"mc":[{"id":"1.231284093","rc":[{"batb":[[0,2.14,37.86],[1,1.74,17.32],[2,1.43,116.28]],"ltp":2.22,"tv":42727.08,"id":424679},{"batb":[[0,1.8,53.95],[1,1.75,29],[2,1.74,17.32]],"ltp":1.85,"tv":27410.14,"id":5995}]}]}
{"op":"mcm","clk":"11762757958","pt":1722532725239,"mc":[{"id":"1.231284093","rc":[{"batb":[[0,2.16,4],[1,2.14,37.86],[2,1.74,17.32]],"batl":[[0,2.24,4],[1,2.26,4]],"ltp":2.22,"tv":42727.08,"id":424679},{"batb":[[0,1.85,470.48],[1,1.8,57.95],[2,1.75,29]],"batl":[[0,1.86,7]],"ltp":1.85,"tv":27410.14,"id":5995}]}]}
{"op":"mcm","clk":"11762758034","pt":1722532725753,"mc":[{"id":"1.231284093","rc":[{"batb":[[0,2.16,10]],"ltp":2.22,"tv":42727.08,"id":424679},{"batl":[[0,1.86,3]],"ltp":1.85,"tv":27410.14,"id":5995}]}]}
{"op":"mcm","clk":"11762758499","pt":1722532729162,"mc":[{"id":"1.231284093","rc":[{"batb":[[0,2.14,37.86],[1,1.74,17.32],[2,1.43,116.28]],"ltp":2.22,"tv":42727.08,"id":424679},{"trd":[[1.85,25413.79]],"batb":[[0,1.8,57.95],[1,1.75,29],[2,1.74,17.32]],"ltp":1.85,"tv":28351.1,"id":5995}],"tv":71078.18}]}
{"op":"mcm","clk":"11762759425","pt":1722532736281,"mc":[{"id":"1.231284093","rc":[{"batb":[[0,2.16,10],[1,2.14,37.86],[2,1.74,17.32]],"ltp":2.22,"tv":42727.08,"id":424679},{"batb":[[0,1.85,470.48],[1,1.8,57.95],[2,1.75,29]],"ltp":1.85,"tv":28351.1,"id":5995}]}]}
{"op":"mcm","clk":"11762759940","pt":1722532740395,"mc":[{"id":"1.231284093","rc":[{"batb":[[0,2.14,37.86],[1,1.74,17.32],[2,1.43,116.28]],"batl":[[0,2.18,4],[1,2.24,4],[2,2.26,4]],"ltp":2.22,"tv":42727.08,"id":424679},{"trd":[[1.85,26354.74]],"batb":[[0,1.85,4]],"ltp":1.85,"tv":29292.05,"id":5995}],"tv":72019.13}]}
{"op":"mcm","clk":"11762760019","pt":1722532740979,"mc":[{"id":"1.231284093","rc":[{"batl":[[0,2.24,4],[1,2.26,4],[2,2.26,0]],"ltp":2.22,"tv":42727.08,"id":424679},{"batb":[[0,1.8,57.95],[1,1.75,29],[2,1.74,17.32]],"ltp":1.85,"tv":29292.05,"id":5995}]}]}
{"op":"mcm","clk":"11762760552","pt":1722532745089,"mc":[{"id":"1.231284093","rc":[{"batb":[[0,2.16,10],[1,2.14,37.86],[2,1.74,17.32]],"ltp":2.22,"tv":42727.08,"id":424679}]}]}
{"op":"mcm","clk":"11762760733","pt":1722532746505,"mc":[{"id":"1.231284093","rc":[{"batb":[[0,1.85,470.48],[1,1.8,57.95],[2,1.75,29]],"ltp":1.85,"tv":29292.05,"id":5995}]}]}
{"op":"mcm","clk":"11762760974","pt":1722532748498,"mc":[{"id":"1.231284093","rc":[{"batb":[[0,2.14,37.86],[1,1.74,17.32],[2,1.43,116.28]],"ltp":2.22,"tv":42727.08,"id":424679}]}]}
{"op":"mcm","clk":"11762761192","pt":1722532750099,"mc":[{"id":"1.231284093","rc":[{"trd":[[1.85,27295.7]],"batb":[[0,1.8,57.95],[1,1.75,29],[2,1.74,17.32]],"ltp":1.85,"tv":30233.01,"id":5995}],"tv":72960.09}]}
{"op":"mcm","clk":"11762761626","pt":1722532753473,"mc":[{"id":"1.231284093","rc":[{"batb":[[0,2.16,10],[1,2.14,37.86],[2,1.74,17.32]],"ltp":2.22,"tv":42727.08,"id":424679}]}]}
{"op":"mcm","clk":"11762761937","pt":1722532755995,"mc":[{"id":"1.231284093","rc":[{"batb":[[0,2.16,14]],"ltp":2.22,"tv":42727.08,"id":424679},{"batb":[[0,1.85,470.48],[1,1.8,57.95],[2,1.75,29]],"batl":[[0,1.86,7]],"ltp":1.85,"tv":30233.01,"id":5995}]}]}
{"op":"mcm","clk":"11762762060","pt":1722532756897,"mc":[{"id":"1.231284093","rc":[{"batb":[[0,2.14,37.86],[1,1.74,17.32],[2,1.43,116.28]],"ltp":2.22,"tv":42727.08,"id":424679},{"batl":[[0,1.86,3]],"ltp":1.85,"tv":30233.01,"id":5995}]}]}
{"op":"mcm","clk":"11762762495","pt":1722532759947,"mc":[{"id":"1.231284093","rc":[{"batb":[[0,2.16,10],[1,2.14,37.86],[2,1.74,17.32]],"ltp":2.22,"tv":42727.08,"id":424679},{"trd":[[1.85,28236.65]],"batb":[[0,1.8,57.95],[1,1.75,29],[2,1.74,17.32]],"ltp":1.85,"tv":31173.96,"id":5995}],"tv":73901.04}]}
{"op":"mcm","clk":"11762763024","pt":1722532763290,"mc":[{"id":"1.231284093","rc":[{"batb":[[0,2.14,37.86],[1,1.74,17.32],[2,1.43,116.28]],"ltp":2.22,"tv":42727.08,"id":424679}]}]}
{"op":"mcm","clk":"11762763672","pt":1722532768017,"mc":[{"id":"1.231284093","rc":[{"batb":[[0,2.16,10],[1,2.14,37.86],[2,1.74,17.32]],"ltp":2.22,"tv":42727.08,"id":424679},{"batb":[[0,1.85,470.48],[1,1.8,57.95],[2,1.75,29]],"ltp":1.85,"tv":31173.96,"id":5995}]}]}
{"op":"mcm","clk":"11762764059","pt":1722532771334,"mc":[{"id":"1.231284093","rc":[{"batb":[[0,1.74,17.32],[1,1.43,116.28],[2,1.38,131.58]],"batl":[[0,2.18,4],[1,2.24,4],[2,2.26,4]],"ltp":2.22,"tv":42727.08,"id":424679},{"trd":[[1.85,29177.61]],"batb":[[0,1.85,4],[1,1.8,4]],"ltp":1.85,"tv":32114.92,"id":5995}],"tv":74842.0}]}
{"op":"mcm","clk":"11762764101","pt":1722532771596,"mc":[{"id":"1.231284093","rc":[{"batb":[[0,1.75,29],[1,1.74,17.32],[2,1.7,13.81]],"ltp":1.85,"tv":32114.92,"id":5995}]}]}
{"op":"mcm","clk":"11762764658","pt":1722532775990,"mc":[{"id":"1.231284093","rc":[{"batb":[[0,2.14,37.86],[1,1.74,17.32],[2,1.43,116.28]],"ltp":2.22,"tv":42727.08,"id":424679},{"batb":[[0,1.8,53.95],[1,1.75,29],[2,1.74,17.32]],"ltp":1.85,"tv":32114.92,"id":5995}]}]}
{"op":"mcm","clk":"11762764802","pt":1722532777096,"mc":[{"id":"1.231284093","rc":[{"batb":[[0,1.85,470.48],[1,1.8,53.95],[2,1.75,29]],"ltp":1.85,"tv":32114.92,"id":5995}]}]}
{"op":"mcm","clk":"11762765233","pt":1722532780400,"mc":[{"id":"1.231284093","rc":[{"trd":[[1.85,30118.56]],"batb":[[0,1.8,53.95],[1,1.75,29],[2,1.74,17.32]],"ltp":1.85,"tv":33055.87,"id":5995}],"tv":75782.95}]}
{"op":"mcm","clk":"11762765912","pt":1722532785820,"mc":[{"id":"1.231284093","rc":[{"batb":[[0,2.16,4],[1,2.14,37.86],[2,1.74,17.32]],"batl":[[0,2.24,4],[1,2.26,4]],"ltp":2.22,"tv":42727.08,"id":424679},{"batb":[[0,1.8,57.95]],"batl":[[0,1.86,7]],"ltp":1.85,"tv":33055.87,"id":5995}]}]}
{"op":"mcm","clk":"11762766093","pt":1722532787355,"mc":[{"id":"1.231284093","rc":[{"batb":[[0,2.16,10]],"ltp":2.22,"tv":42727.08,"id":424679},{"batb":[[0,1.85,470.48],[1,1.8,57.95],[2,1.75,29]],"batl":[[0,1.86,3]],"ltp":1.85,"tv":33055.87,"id":5995}]}]}
{"op":"mcm","clk":"11762766397","pt":1722532790148,"mc":[{"id":"1.231284093","rc":[{"trd":[[1.85,31059.52]],"batb":[[0,1.8,57.95],[1,1.75,29],[2,1.74,17.32]],"ltp":1.85,"tv":33996.83,"id":5995}],"tv":76723.91}]}
{"op":"mcm","clk":"11762766458","pt":1722532790619,"mc":[{"id":"1.231284093","rc":[{"batb":[[0,2.14,37.86],[1,1.74,17.32],[2,1.43,116.28]],"ltp":2.22,"tv":42727.08,"id":424679}]}]}
{"op":"mcm","clk":"11762767283","pt":1722532797315,"mc":[{"id":"1.231284093","rc":[{"batb":[[0,2.16,10],[1,2.14,37.86],[2,1.74,17.32]],"ltp":2.22,"tv":42727.08,"id":424679},{"batb":[[0,1.85,470.48],[1,1.8,57.95],[2,1.75,29]],"ltp":1.85,"tv":33996.83,"id":5995}]}]}
{"op":"mcm","clk":"11762767738","pt":1722532801044,"mc":[{"id":"1.231284093","rc":[{"batb":[[0,2.14,37.86],[1,1.74,17.32],[2,1.43,116.28]],"batl":[[0,2.18,4],[1,2.24,4],[2,2.26,4]],"ltp":2.22,"tv":42727.08,"id":424679},{"batb":[[0,1.85,474.48]],"ltp":1.85,"tv":33996.83,"id":5995}]}]}
{"op":"mcm","clk":"11762767916","pt":1722532802369,"mc":[{"id":"1.231284093","rc":[{"batl":[[0,2.24,4],[1,2.26,4],[2,2.26,0]],"ltp":2.22,"tv":42727.08,"id":424679},{"trd":[[1.85,32000.47]],"batb":[[0,1.8,57.95],[1,1.75,29],[2,1.74,17.32]],"ltp":1.85,"tv":34937.78,"id":5995}],"tv":77664.86}]}
{"op":"mcm","clk":"11762768806","pt":1722532809620,"mc":[{"id":"1.231284093","rc":[{"batb":[[0,2.16,10],[1,2.14,37.86],[2,1.74,17.32]],"ltp":2.22,"tv":42727.08,"id":424679},{"batb":[[0,1.85,470.48],[1,1.8,57.95],[2,1.75,29]],"ltp":1.85,"tv":34937.78,"id":5995}]}]}
{"op":"mcm","clk":"11762769003","pt":1722532811244,"mc":[{"id":"1.231284093","rc":[{"batb":[[1,1.74,17.32],[2,1.43,116.28]],"ltp":2.22,"tv":42727.08,"id":424679},{"batb":[[1,1.8,4]],"ltp":1.85,"tv":34937.78,"id":5995}]}]}
{"op":"mcm","clk":"11762769220","pt":1722532813159,"mc":[{"id":"1.231284093","rc":[{"batb":[[0,1.74,17.32],[1,1.43,116.28],[2,1.38,131.58]],"ltp":2.22,"tv":42727.08,"id":424679},{"trd":[[1.85,32941.43]],"batb":[[0,1.75,29],[1,1.74,17.32],[2,1.7,13.81]],"ltp":1.85,"tv":35878.74,"id":5995}],"tv":78605.82}]}
{"op":"mcm","clk":"11762769601","pt":1722532816218,"mc":[{"id":"1.231284093","rc":[{"batb":[[0,2.14,37.86],[1,1.74,17.32],[2,1.43,116.28]],"ltp":2.22,"tv":42727.08,"id":424679},{"batb":[[0,1.8,53.95],[1,1.75,29],[2,1.74,17.32]],"ltp":1.85,"tv":35878.74,"id":5995}]}]}
{"op":"mcm","clk":"11762769925","pt":1722532818929,"mc":[{"id":"1.231284093","rc":[{"batb":[[0,1.85,470.48],[1,1.8,53.95],[2,1.75,29]],"ltp":1.85,"tv":35878.74,"id":5995}]}]}
{"op":"mcm","clk":"11762770380","pt":1722532822449,"mc":[{"id":"1.231284093","rc":[{"trd":[[1.85,33882.38]],"batb":[[0,1.8,53.95],[1,1.75,29],[2,1.74,17.32]],"ltp":1.85,"tv":36819.69,"id":5995}],"tv":79546.77}]}
{"op":"mcm","clk":"11762771251","pt":1722532829031,"mc":[{"id":"1.231284093","rc":[{"batb":[[0,1.85,470.48],[1,1.8,53.95],[2,1.75,29]],"ltp":1.85,"tv":36819.69,"id":5995}]}]}
{"op":"mcm","clk":"11762771524","pt":1722532831369,"mc":[{"id":"1.231284093","rc":[{"batl":[[0,2.18,4]],"ltp":2.22,"tv":42727.08,"id":424679},{"batb":[[0,1.85,474.48]],"ltp":1.85,"tv":36819.69,"id":5995}]}]}
{"op":"mcm","clk":"11762771761","pt":1722532833258,"mc":[{"id":"1.231284093","rc":[{"trd":[[1.85,34823.34]],"batb":[[0,1.8,53.95],[1,1.75,29],[2,1.74,17.32]],"ltp":1.85,"tv":37760.65,"id":5995}],"tv":80487.73}]}
{"op":"mcm","clk":"11762772389","pt":1722532838263,"mc":[{"id":"1.231284093","rc":[{"batb":[[0,1.85,470.48],[1,1.8,53.95],[2,1.75,29]],"ltp":1.85,"tv":37760.65,"id":5995}]}]}
{"op":"mcm","clk":"11762772828","pt":1722532841654,"mc":[{"id":"1.231284093","rc":[{"trd":[[1.85,35764.29]],"batb":[[0,1.8,53.95],[1,1.75,29],[2,1.74,17.32]],"ltp":1.85,"tv":38701.6,"id":5995}],"tv":81428.68}]}
{"op":"mcm","clk":"11762773557","pt":1722532847393,"mc":[{"id":"1.231284093","rc":[{"batl":[[0,2.24,4],[1,2.26,4]],"ltp":2.22,"tv":42727.08,"id":424679},{"batb":[[0,1.85,470.48],[1,1.8,57.95],[2,1.75,29]],"ltp":1.85,"tv":38701.6,"id":5995}]}]}
{"op":"mcm","clk":"11762773582","pt":1722532847559,"mc":[{"id":"1.231284093","rc":[{"batb":[[0,2.16,10],[1,2.14,37.86],[2,1.74,17.32]],"ltp":2.22,"tv":42727.08,"id":424679}]}]}
{"op":"mcm","clk":"11762774013","pt":1722532850867,"mc":[{"id":"1.231284093","rc":[{"batb":[[0,2.14,37.86],[1,1.74,17.32],[2,1.43,116.28]],"ltp":2.22,"tv":42727.08,"id":424679},{"trd":[[1.85,36705.25]],"batb":[[0,1.8,57.95],[1,1.75,29],[2,1.74,17.32]],"ltp":1.85,"tv":39642.56,"id":5995}],"tv":82369.64}]}
{"op":"mcm","clk":"11762774310","pt":1722532853290,"mc":[{"id":"1.231284093","rc":[{"batb":[[0,2.16,10],[1,2.14,37.86],[2,1.74,17.32]],"ltp":2.22,"tv":42727.08,"id":424679}]}]}
{"op":"mcm","clk":"11762774742","pt":1722532856600,"mc":[{"id":"1.231284093","rc":[{"batb":[[0,2.14,37.86],[1,1.74,17.32],[2,1.43,116.28]],"ltp":2.22,"tv":42727.08,"id":424679},{"batb":[[0,1.85,470.48],[1,1.8,57.95],[2,1.75,29]],"ltp":1.85,"tv":39642.56,"id":5995}]}]}
{"op":"mcm","clk":"11762775054","pt":1722532859068,"mc":[{"id":"1.231284093","rc":[{"batb":[[0,2.16,10],[1,2.14,37.86],[2,1.74,17.32]],"ltp":2.22,"tv":42727.08,"id":424679}]}]}
{"op":"mcm","clk":"11762775187","pt":1722532860116,"mc":[{"id":"1.231284093","rc":[{"trd":[[1.85,37646.2]],"batb":[[0,1.8,57.95],[1,1.75,29],[2,1.74,17.32]],"ltp":1.85,"tv":40583.51,"id":5995}],"tv":83310.59}]}
{"op":"mcm","clk":"11762775435","pt":1722532861821,"mc":[{"id":"1.231284093","rc":[{"batb":[[0,2.16,14]],"ltp":2.22,"tv":42727.08,"id":424679},{"batl":[[0,1.86,7]],"ltp":1.85,"tv":40583.51,"id":5995}]}]}
{"op":"mcm","clk":"11762775540","pt":1722532862517,"mc":[{"id":"1.231284093","rc":[{"batb":[[0,2.16,4]],"ltp":2.22,"tv":42727.08,"id":424679}]}]}
{"op":"mcm","clk":"11762776031","pt":1722532866102,"mc":[{"id":"1.231284093","rc":[{"batb":[[0,1.85,470.48],[1,1.8,57.95],[2,1.75,29]],"ltp":1.85,"tv":40583.51,"id":5995}]}]}
{"op":"mcm","clk":"11762776150","pt":1722532866996,"mc":[{"id":"1.231284093","rc":[{"batb":[[0,2.16,10]],"ltp":2.22,"tv":42727.08,"id":424679},{"batl":[[0,1.86,3]],"ltp":1.85,"tv":40583.51,"id":5995}]}]}
{"op":"mcm","clk":"11762776614","pt":1722532870208,"mc":[{"id":"1.231284093","rc":[{"batb":[[0,2.14,37.86],[1,1.74,17.32],[2,1.43,116.28]],"ltp":2.22,"tv":42727.08,"id":424679},{"trd":[[1.85,38587.16]],"batb":[[0,1.8,57.95],[1,1.75,29],[2,1.74,17.32]],"ltp":1.85,"tv":41524.47,"id":5995}],"tv":84251.55}]}
{"op":"mcm","clk":"11762777494","pt":1722532876977,"mc":[{"id":"1.231284093","rc":[{"batb":[[0,2.16,4],[1,2.14,37.86],[2,1.74,17.32]],"ltp":2.22,"tv":42727.08,"id":424679},{"batl":[[0,1.86,7]],"ltp":1.85,"tv":41524.47,"id":5995}]}]}
{"op":"mcm","clk":"11762777669","pt":1722532878293,"mc":[{"id":"1.231284093","rc":[{"batb":[[0,1.85,470.48],[1,1.8,57.95],[2,1.75,29]],"ltp":1.85,"tv":41524.47,"id":5995}]}]}
{"op":"mcm","clk":"11762777781","pt":1722532879130,"mc":[{"id":"1.231284093","rc":[{"batb":[[0,2.16,10]],"ltp":2.22,"tv":42727.08,"id":424679},{"batl":[[0,1.86,3]],"ltp":1.85,"tv":41524.47,"id":5995}]}]}
{"op":"mcm","clk":"11762778225","pt":1722532882397,"mc":[{"id":"1.231284093","rc":[{"batb":[[1,1.74,17.32],[2,1.43,116.28]],"ltp":2.22,"tv":42727.08,"id":424679},{"trd":[[1.85,39528.11]],"batb":[[0,1.8,4],[1,1.75,29],[2,1.74,17.32]],"ltp":1.85,"tv":42465.42,"id":5995}],"tv":85192.51}]}
{"op":"mcm","clk":"11762778299","pt":1722532883030,"mc":[{"id":"1.231284093","rc":[{"batb":[[0,1.74,17.32],[1,1.43,116.28],[2,1.38,131.58]],"ltp":2.22,"tv":42727.08,"id":424679},{"batb":[[0,1.75,29],[1,1.74,17.32],[2,1.7,13.81]],"ltp":1.85,"tv":42465.42,"id":5995}]}]}
{"op":"mcm","clk":"11762778779","pt":1722532886549,"mc":[{"id":"1.231284093","rc":[{"batb":[[0,2.14,37.86],[1,1.74,17.32],[2,1.43,116.28]],"ltp":2.22,"tv":42727.08,"id":424679},{"batb":[[0,1.8,53.95],[1,1.75,29],[2,1.74,17.32]],"ltp":1.85,"tv":42465.42,"id":5995}]}]}
{"op":"mcm","clk":"11762779062","pt":1722532888430,"mc":[{"id":"1.231284093","rc":[{"batb":[[0,1.85,470.48],[1,1.8,53.95],[2,1.75,29]],"ltp":1.85,"tv":42465.42,"id":5995}]}]}
{"op":"mcm","clk":"11762779512","pt":1722532892114,"mc":[{"id":"1.231284093","rc":[{"batl":[[0,2.18,4]],"ltp":2.22,"tv":42727.08,"id":424679},{"batb":[[0,1.85,474.48]],"ltp":1.85,"tv":42465.42,"id":5995}]}]}
{"op":"mcm","clk":"11762779628","pt":1722532893012,"mc":[{"id":"1.231284093","rc":[{"trd":[[1.85,40469.07]],"batb":[[0,1.85,4]],"ltp":1.85,"tv":43406.38,"id":5995}],"tv":86133.46}]}
{"op":"mcm","clk":"11762779689","pt":1722532893538,"mc":[{"id":"1.231284093","rc":[{"batb":[[0,1.8,53.95],[1,1.75,29],[2,1.74,17.32]],"ltp":1.85,"tv":43406.38,"id":5995}]}]}
{"op":"mcm","clk":"11762781504","pt":1722532907313,"mc":[{"id":"1.231284093","rc":[{"batb":[[0,2.16,4],[1,2.14,37.86],[2,1.74,17.32]],"batl":[[0,2.24,4],[1,2.26,4]],"ltp":2.22,"tv":42727.08,"id":424679},{"batb":[[0,1.8,57.95]],"batl":[[0,1.86,7]],"ltp":1.85,"tv":43406.38,"id":5995}]}]}
{"op":"mcm","clk":"11762781684","pt":1722532908738,"mc":[{"id":"1.231284093","rc":[{"batb":[[0,1.81,4.73],[1,1.8,57.95],[2,1.75,29]],"ltp":1.85,"tv":43406.38,"id":5995}]}]}
{"op":"mcm","clk":"11762782949","pt":1722532918833,"mc":[{"id":"1.231284093","rc":[{"batl":[[0,1.85,240.73],[1,1.86,7],[2,1.87,15]],"ltp":1.85,"tv":43406.38,"id":5995}]}]}
{"op":"mcm","clk":"11762783471","pt":1722532922556,"mc":[{"id":"1.231284093","rc":[{"batb":[[0,1.81,8.73]],"batl":[[0,1.84,4],[1,1.85,244.73],[2,1.86,7]],"ltp":1.85,"tv":43406.38,"id":5995}]}]}
{"op":"mcm","clk":"11762785286","pt":1722532935369,"mc":[{"id":"1.231284093","rc":[{"trd":[[1.84,2830.71],[1.85,40958.52],[1.86,9.67]],"batl":[[0,1.86,2.17],[1,1.87,15],[2,1.9,21.75]],"ltp":1.86,"tv":43913.5,"id":5995}],"tv":86640.58}]}
{"op":"mcm","clk":"11762788757","pt":1722532961384,"mc":[{"id":"1.231284093","rc":[{"batl":[[0,1.85,13.33],[1,1.86,2.17],[2,1.87,15]],"ltp":1.86,"tv":43913.5,"id":5995}]}]}
{"op":"mcm","clk":"11762789649","pt":1722532967878,"mc":[{"id":"1.231284093","rc":[{"batl":[[0,1.85,17.33]],"ltp":1.86,"tv":43913.5,"id":5995}]}]}
{"op":"mcm","clk":"11762790139","pt":1722532971601,"mc":[{"id":"1.231284093","rc":[{"batl":[[0,1.85,4]],"ltp":1.86,"tv":43913.5,"id":5995}]}]}
{"op":"mcm","clk":"11762790244","pt":1722532972405,"mc":[{"id":"1.231284093","rc":[{"batl":[[0,1.86,2.17],[1,1.87,15],[2,1.9,21.75]],"ltp":1.86,"tv":43913.5,"id":5995}]}]}
{"op":"mcm","clk":"11762790470","pt":1722532974094,"mc":[{"id":"1.231284093","rc":[{"batb":[[0,2.16,8.27]],"ltp":2.22,"tv":42727.08,"id":424679}]}]}
{"op":"mcm","clk":"11762790803","pt":1722532976499,"mc":[{"id":"1.231284093","rc":[{"batb":[[0,2.16,4]],"ltp":2.22,"tv":42727.08,"id":424679}]}]}
{"op":"mcm","clk":"11762793855","pt":1722532998245,"mc":[{"id":"1.231284093","rc":[{"trd":[[1.8,124.92],[1.81,17.57]],"batb":[[0,1.81,4],[1,1.8,52.7]],"batl":[[0,1.86,6.77]],"ltp":1.8,"tv":43941.45,"id":5995}],"tv":86668.53}]}
{"op":"mcm","clk":"11762794425","pt":1722533002146,"mc":[{"id":"1.231284093","rc":[{"batb":[[1,1.8,57.95]],"ltp":1.8,"tv":43941.45,"id":5995}]}]}
{"op":"mcm","clk":"11762794687","pt":1722533003951,"mc":[{"id":"1.231284093","rc":[{"batl":[[0,2.24,8.31]],"ltp":2.22,"tv":42727.08,"id":424679}]}]}
{"op":"mcm","clk":"11762794950","pt":1722533005841,"mc":[{"id":"1.231284093","rc":[{"batl":[[0,2.24,4]],"ltp":2.22,"tv":42727.08,"id":424679}]}]}
{"op":"mcm","clk":"11762801554","pt":1722533053561,"mc":[{"id":"1.231284093","rc":[{"batl":[[0,2.24,8.31]],"ltp":2.22,"tv":42727.08,"id":424679}]}]}
{"op":"mcm","clk":"11762801920","pt":1722533056048,"mc":[{"id":"1.231284093","rc":[{"batl":[[0,2.24,4]],"ltp":2.22,"tv":42727.08,"id":424679}]}]}
{"op":"mcm","clk":"11762808012","pt":1722533104218,"mc":[{"id":"1.231284093","rc":[{"batl":[[0,2.24,8.31]],"ltp":2.22,"tv":42727.08,"id":424679}]}]}
{"op":"mcm","clk":"11762808331","pt":1722533106335,"mc":[{"id":"1.231284093","rc":[{"batl":[[0,2.24,4]],"ltp":2.22,"tv":42727.08,"id":424679}]}]}
{"op":"mcm","clk":"11762815011","pt":1722533154314,"mc":[{"id":"1.231284093","rc":[{"batl":[[0,2.24,8.31]],"ltp":2.22,"tv":42727.08,"id":424679}]}]}
{"op":"mcm","clk":"11762815273","pt":1722533156311,"mc":[{"id":"1.231284093","rc":[{"batl":[[0,2.24,4]],"ltp":2.22,"tv":42727.08,"id":424679}]}]}
{"op":"mcm","clk":"11762822299","pt":1722533205289,"mc":[{"id":"1.231284093","rc":[{"batl":[[0,2.24,8.31]],"ltp":2.22,"tv":42727.08,"id":424679}]}]}
{"op":"mcm","clk":"11762822686","pt":1722533207992,"mc":[{"id":"1.231284093","rc":[{"batl":[[0,2.24,4]],"ltp":2.22,"tv":42727.08,"id":424679}]}]}
{"op":"mcm","clk":"11762829291","pt":1722533254941,"mc":[{"id":"1.231284093","rc":[{"batl":[[0,2.24,8.31]],"ltp":2.22,"tv":42727.08,"id":424679}]}]}
{"op":"mcm","clk":"11762829610","pt":1722533257107,"mc":[{"id":"1.231284093","rc":[{"batl":[[0,2.24,4]],"ltp":2.22,"tv":42727.08,"id":424679}]}]}
{"op":"mcm","clk":"11762836761","pt":1722533303881,"mc":[{"id":"1.231284093","rc":[{"batl":[[0,2.24,8.31]],"ltp":2.22,"tv":42727.08,"id":424679}]}]}
{"op":"mcm","clk":"11762837204","pt":1722533306679,"mc":[{"id":"1.231284093","rc":[{"batl":[[0,2.24,4]],"ltp":2.22,"tv":42727.08,"id":424679}]}]}
{"op":"mcm","clk":"11762844323","pt":1722533354029,"mc":[{"id":"1.231284093","rc":[{"batl":[[0,2.24,8.31]],"ltp":2.22,"tv":42727.08,"id":424679}]}]}
{"op":"mcm","clk":"11762844708","pt":1722533356544,"mc":[{"id":"1.231284093","rc":[{"batl":[[0,2.24,4]],"ltp":2.22,"tv":42727.08,"id":424679}]}]}
{"op":"mcm","clk":"11762851642","pt":1722533404905,"mc":[{"id":"1.231284093","rc":[{"batl":[[0,2.24,8.31]],"ltp":2.22,"tv":42727.08,"id":424679}]}]}
{"op":"mcm","clk":"11762851905","pt":1722533406979,"mc":[{"id":"1.231284093","rc":[{"batl":[[0,2.24,4]],"ltp":2.22,"tv":42727.08,"id":424679}]}]}
{"op":"mcm","clk":"11762858950","pt":1722533454676,"mc":[{"id":"1.231284093","rc":[{"batl":[[0,2.24,8.31]],"ltp":2.22,"tv":42727.08,"id":424679}]}]}
{"op":"mcm","clk":"11762859330","pt":1722533457274,"mc":[{"id":"1.231284093","rc":[{"batl":[[0,2.24,4]],"ltp":2.22,"tv":42727.08,"id":424679}]}]}
{"op":"mcm","clk":"11762866532","pt":1722533504846,"mc":[{"id":"1.231284093","rc":[{"batl":[[0,2.24,8.31]],"ltp":2.22,"tv":42727.08,"id":424679}]}]}
{"op":"mcm","clk":"11762866880","pt":1722533507319,"mc":[{"id":"1.231284093","rc":[{"batl":[[0,2.24,4]],"ltp":2.22,"tv":42727.08,"id":424679}]}]}
{"op":"mcm","clk":"11762873490","pt":1722533554102,"mc":[{"id":"1.231284093","rc":[{"batl":[[0,2.24,8.31]],"ltp":2.22,"tv":42727.08,"id":424679}]}]}
{"op":"mcm","clk":"11762873834","pt":1722533556409,"mc":[{"id":"1.231284093","rc":[{"batl":[[0,2.24,4]],"ltp":2.22,"tv":42727.08,"id":424679}]}]}
{"op":"mcm","clk":"11762881039","pt":1722533604322,"mc":[{"id":"1.231284093","rc":[{"batl":[[0,2.24,8.31]],"ltp":2.22,"tv":42727.08,"id":424679}]}]}
{"op":"mcm","clk":"11762881469","pt":1722533606847,"mc":[{"id":"1.231284093","rc":[{"batl":[[0,2.24,4]],"ltp":2.22,"tv":42727.08,"id":424679}]}]}
{"op":"mcm","clk":"11762888610","pt":1722533653543,"mc":[{"id":"1.231284093","rc":[{"batl":[[0,2.24,8.31]],"ltp":2.22,"tv":42727.08,"id":424679}]}]}
{"op":"mcm","clk":"11762888888","pt":1722533655637,"mc":[{"id":"1.231284093","rc":[{"batl":[[0,2.24,4]],"ltp":2.22,"tv":42727.08,"id":424679}]}]}
{"op":"mcm","clk":"11762896038","pt":1722533704012,"mc":[{"id":"1.231284093","rc":[{"batl":[[0,2.24,8.31]],"ltp":2.22,"tv":42727.08,"id":424679}]}]}
{"op":"mcm","clk":"11762896367","pt":1722533706230,"mc":[{"id":"1.231284093","rc":[{"batl":[[0,2.24,4]],"ltp":2.22,"tv":42727.08,"id":424679}]}]}
{"op":"mcm","clk":"11762903858","pt":1722533754924,"mc":[{"id":"1.231284093","rc":[{"batl":[[0,2.24,8.31]],"ltp":2.22,"tv":42727.08,"id":424679}]}]}
{"op":"mcm","clk":"11762904244","pt":1722533757208,"mc":[{"id":"1.231284093","rc":[{"batl":[[0,2.24,4]],"ltp":2.22,"tv":42727.08,"id":424679}]}]}
{"op":"mcm","clk":"11762911448","pt":1722533803302,"mc":[{"id":"1.231284093","rc":[{"batl":[[0,2.24,8.31]],"ltp":2.22,"tv":42727.08,"id":424679}]}]}
{"op":"mcm","clk":"11762911837","pt":1722533805659,"mc":[{"id":"1.231284093","rc":[{"batl":[[0,2.24,4]],"ltp":2.22,"tv":42727.08,"id":424679}]}]}
{"op":"mcm","clk":"11762918940","pt":1722533851813,"mc":[{"id":"1.231284093","rc":[{"batl":[[0,2.24,8.31]],"ltp":2.22,"tv":42727.08,"id":424679}]}]}
{"op":"mcm","clk":"11762919344","pt":1722533854311,"mc":[{"id":"1.231284093","rc":[{"batl":[[0,2.24,4]],"ltp":2.22,"tv":42727.08,"id":424679}]}]}
{"op":"mcm","clk":"11762926270","pt":1722533901363,"mc":[{"id":"1.231284093","rc":[{"batl":[[0,2.24,8.31]],"ltp":2.22,"tv":42727.08,"id":424679}]}]}
{"op":"mcm","clk":"11762926611","pt":1722533903854,"mc":[{"id":"1.231284093","rc":[{"batl":[[0,2.24,4]],"ltp":2.22,"tv":42727.08,"id":424679}]}]}
{"op":"mcm","clk":"11762933563","pt":1722533949918,"mc":[{"id":"1.231284093","rc":[{"batl":[[0,2.24,8.31]],"ltp":2.22,"tv":42727.08,"id":424679}]}]}
{"op":"mcm","clk":"11762933966","pt":1722533952527,"mc":[{"id":"1.231284093","rc":[{"batl":[[0,2.24,4]],"ltp":2.22,"tv":42727.08,"id":424679}]}]}
{"op":"mcm","clk":"11762941036","pt":1722533999781,"mc":[{"id":"1.231284093","rc":[{"batl":[[0,2.24,8.31]],"ltp":2.22,"tv":42727.08,"id":424679}]}]}
{"op":"mcm","clk":"11762941432","pt":1722534002367,"mc":[{"id":"1.231284093","rc":[{"batl":[[0,2.24,4]],"ltp":2.22,"tv":42727.08,"id":424679}]}]}
{"op":"mcm","clk":"11762948498","pt":1722534049118,"mc":[{"id":"1.231284093","rc":[{"batl":[[0,2.24,8.31]],"ltp":2.22,"tv":42727.08,"id":424679}]}]}
{"op":"mcm","clk":"11762948833","pt":1722534051338,"mc":[{"id":"1.231284093","rc":[{"batl":[[0,2.24,4]],"ltp":2.22,"tv":42727.08,"id":424679}]}]}
{"op":"mcm","clk":"11762956388","pt":1722534099357,"mc":[{"id":"1.231284093","rc":[{"batl":[[0,2.24,8.31]],"ltp":2.22,"tv":42727.08,"id":424679}]}]}
{"op":"mcm","clk":"11762956728","pt":1722534101681,"mc":[{"id":"1.231284093","rc":[{"batl":[[0,2.24,4]],"ltp":2.22,"tv":42727.08,"id":424679}]}]}
{"op":"mcm","clk":"11762963387","pt":1722534147972,"mc":[{"id":"1.231284093","rc":[{"batl":[[0,2.24,8.31]],"ltp":2.22,"tv":42727.08,"id":424679}]}]}
{"op":"mcm","clk":"11762963736","pt":1722534150251,"mc":[{"id":"1.231284093","rc":[{"batl":[[0,2.24,4]],"ltp":2.22,"tv":42727.08,"id":424679}]}]}
{"op":"mcm","clk":"11762970836","pt":1722534195870,"mc":[{"id":"1.231284093","rc":[{"batl":[[0,2.24,8.31]],"ltp":2.22,"tv":42727.08,"id":424679}]}]}
{"op":"mcm","clk":"11762971277","pt":1722534198313,"mc":[{"id":"1.231284093","rc":[{"batl":[[0,2.24,4]],"ltp":2.22,"tv":42727.08,"id":424679}]}]}
{"op":"mcm","clk":"11762979064","pt":1722534245429,"mc":[{"id":"1.231284093","rc":[{"batl":[[0,2.24,8.31]],"ltp":2.22,"tv":42727.08,"id":424679}]}]}
{"op":"mcm","clk":"11762979483","pt":1722534247622,"mc":[{"id":"1.231284093","rc":[{"batl":[[0,2.24,4]],"ltp":2.22,"tv":42727.08,"id":424679}]}]}
{"op":"mcm","clk":"11762986927","pt":1722534294895,"mc":[{"id":"1.231284093","rc":[{"batl":[[0,2.24,8.31]],"ltp":2.22,"tv":42727.08,"id":424679}]}]}
{"op":"mcm","clk":"11762987312","pt":1722534297404,"mc":[{"id":"1.231284093","rc":[{"batl":[[0,2.24,4]],"ltp":2.22,"tv":42727.08,"id":424679}]}]}
{"op":"mcm","clk":"11762994891","pt":1722534344036,"mc":[{"id":"1.231284093","rc":[{"batl":[[0,2.24,8.31]],"ltp":2.22,"tv":42727.08,"id":424679}]}]}
{"op":"mcm","clk":"11762995243","pt":1722534346159,"mc":[{"id":"1.231284093","rc":[{"batl":[[0,2.24,4]],"ltp":2.22,"tv":42727.08,"id":424679}]}]}
{"op":"mcm","clk":"11763002794","pt":1722534392799,"mc":[{"id":"1.231284093","rc":[{"batl":[[0,2.24,8.31]],"ltp":2.22,"tv":42727.08,"id":424679}]}]}
{"op":"mcm","clk":"11763003135","pt":1722534395019,"mc":[{"id":"1.231284093","rc":[{"batl":[[0,2.24,4]],"ltp":2.22,"tv":42727.08,"id":424679}]}]}
{"op":"mcm","clk":"11763012017","pt":1722534452707,"mc":[{"id":"1.231284093","rc":[{"batl":[[0,2.24,8.31]],"ltp":2.22,"tv":42727.08,"id":424679}]}]}
{"op":"mcm","clk":"11763012506","pt":1722534455964,"mc":[{"id":"1.231284093","rc":[{"batl":[[0,2.24,4]],"ltp":2.22,"tv":42727.08,"id":424679}]}]}
{"op":"mcm","clk":"11763019344","pt":1722534500725,"mc":[{"id":"1.231284093","rc":[{"batl":[[0,2.24,8.31]],"ltp":2.22,"tv":42727.08,"id":424679}]}]}
{"op":"mcm","clk":"11763019782","pt":1722534503611,"mc":[{"id":"1.231284093","rc":[{"batl":[[0,2.24,4]],"ltp":2.22,"tv":42727.08,"id":424679}]}]}
{"op":"mcm","clk":"11763025571","pt":1722534549601,"mc":[{"id":"1.231284093","rc":[{"batl":[[0,2.24,8.31]],"ltp":2.22,"tv":42727.08,"id":424679}]}]}
{"op":"mcm","clk":"11763025909","pt":1722534552168,"mc":[{"id":"1.231284093","rc":[{"batl":[[0,2.24,4]],"ltp":2.22,"tv":42727.08,"id":424679}]}]}
{"op":"mcm","clk":"11763031502","pt":1722534598647,"mc":[{"id":"1.231284093","rc":[{"batl":[[0,2.24,8.31]],"ltp":2.22,"tv":42727.08,"id":424679}]}]}
{"op":"mcm","clk":"11763031782","pt":1722534601055,"mc":[{"id":"1.231284093","rc":[{"batl":[[0,2.24,4]],"ltp":2.22,"tv":42727.08,"id":424679}]}]}
{"op":"mcm","clk":"11763037664","pt":1722534647787,"mc":[{"id":"1.231284093","rc":[{"batl":[[0,2.24,8.31]],"ltp":2.22,"tv":42727.08,"id":424679}]}]}
{"op":"mcm","clk":"11763037888","pt":1722534649663,"mc":[{"id":"1.231284093","rc":[{"batl":[[0,2.24,4]],"ltp":2.22,"tv":42727.08,"id":424679}]}]}
{"op":"mcm","clk":"11763043416","pt":1722534695227,"mc":[{"id":"1.231284093","rc":[{"batl":[[0,2.24,8.31]],"ltp":2.22,"tv":42727.08,"id":424679}]}]}
{"op":"mcm","clk":"11763043730","pt":1722534697935,"mc":[{"id":"1.231284093","rc":[{"batl":[[0,2.24,4]],"ltp":2.22,"tv":42727.08,"id":424679}]}]}
{"op":"mcm","clk":"11763048801","pt":1722534743005,"mc":[{"id":"1.231284093","rc":[{"batl":[[0,2.24,8.31]],"ltp":2.22,"tv":42727.08,"id":424679}]}]}
{"op":"mcm","clk":"11763049036","pt":1722534745511,"mc":[{"id":"1.231284093","rc":[{"batl":[[0,2.24,4]],"ltp":2.22,"tv":42727.08,"id":424679}]}]}
{"op":"mcm","clk":"11763053829","pt":1722534791116,"mc":[{"id":"1.231284093","rc":[{"batl":[[0,2.24,8.31]],"ltp":2.22,"tv":42727.08,"id":424679}]}]}
{"op":"mcm","clk":"11763054062","pt":1722534793454,"mc":[{"id":"1.231284093","rc":[{"batl":[[0,2.24,4]],"ltp":2.22,"tv":42727.08,"id":424679}]}]}
{"op":"mcm","clk":"11763057995","pt":1722534839006,"mc":[{"id":"1.231284093","rc":[{"batl":[[0,2.24,8.31]],"ltp":2.22,"tv":42727.08,"id":424679}]}]}
{"op":"mcm","clk":"11763058210","pt":1722534841517,"mc":[{"id":"1.231284093","rc":[{"batl":[[0,2.24,4]],"ltp":2.22,"tv":42727.08,"id":424679}]}]}
{"op":"mcm","clk":"11763062721","pt":1722534887662,"mc":[{"id":"1.231284093","rc":[{"batl":[[0,2.24,8.31]],"ltp":2.22,"tv":42727.08,"id":424679}]}]}
{"op":"mcm","clk":"11763062914","pt":1722534890067,"mc":[{"id":"1.231284093","rc":[{"batl":[[0,2.24,4]],"ltp":2.22,"tv":42727.08,"id":424679}]}]}
{"op":"mcm","clk":"11763067419","pt":1722534935592,"mc":[{"id":"1.231284093","rc":[{"batl":[[0,2.24,8.31]],"ltp":2.22,"tv":42727.08,"id":424679}]}]}
{"op":"mcm","clk":"11763067627","pt":1722534937789,"mc":[{"id":"1.231284093","rc":[{"batl":[[0,2.24,4]],"ltp":2.22,"tv":42727.08,"id":424679}]}]}
{"op":"mcm","clk":"11763072051","pt":1722534984171,"mc":[{"id":"1.231284093","rc":[{"batl":[[0,2.24,8.31]],"ltp":2.22,"tv":42727.08,"id":424679}]}]}
{"op":"mcm","clk":"11763072317","pt":1722534986980,"mc":[{"id":"1.231284093","rc":[{"batl":[[0,2.24,4]],"ltp":2.22,"tv":42727.08,"id":424679}]}]}
{"op":"mcm","clk":"11763077178","pt":1722535032414,"mc":[{"id":"1.231284093","rc":[{"batl":[[0,2.24,8.31]],"ltp":2.22,"tv":42727.08,"id":424679}]}]}
{"op":"mcm","clk":"11763077439","pt":1722535034811,"mc":[{"id":"1.231284093","rc":[{"batl":[[0,2.24,4]],"ltp":2.22,"tv":42727.08,"id":424679}]}]}
{"op":"mcm","clk":"11763082420","pt":1722535080956,"mc":[{"id":"1.231284093","rc":[{"batl":[[0,2.24,8.31]],"ltp":2.22,"tv":42727.08,"id":424679}]}]}
{"op":"mcm","clk":"11763082681","pt":1722535083145,"mc":[{"id":"1.231284093","rc":[{"batl":[[0,2.24,4]],"ltp":2.22,"tv":42727.08,"id":424679}]}]}
{"op":"mcm","clk":"11763087861","pt":1722535128195,"mc":[{"id":"1.231284093","rc":[{"batl":[[0,2.24,8.31]],"ltp":2.22,"tv":42727.08,"id":424679}]}]}
{"op":"mcm","clk":"11763088147","pt":1722535130510,"mc":[{"id":"1.231284093","rc":[{"batl":[[0,2.24,4]],"ltp":2.22,"tv":42727.08,"id":424679}]}]}
{"op":"mcm","clk":"11763093233","pt":1722535175331,"mc":[{"id":"1.231284093","rc":[{"batl":[[0,2.24,8.31]],"ltp":2.22,"tv":42727.08,"id":424679}]}]}
{"op":"mcm","clk":"11763093497","pt":1722535177526,"mc":[{"id":"1.231284093","rc":[{"batl":[[0,2.24,4]],"ltp":2.22,"tv":42727.08,"id":424679}]}]}
{"op":"mcm","clk":"11763097660","pt":1722535211595,"mc":[{"id":"1.231284093","rc":[{"trd":[[2.2,7358.28],[2.22,35388.87]],"batl":[[0,2.24,8.31]],"ltp":2.22,"tv":42747.19,"id":424679},{"trd":[[1.8,124.93],[1.81,17.58],[1.84,2832.04],[1.85,40977.8],[1.86,9.67]],"batl":[[0,1.86,6.78]],"ltp":1.8,"tv":43962.08,"id":5995}],"tv":86709.27}]}
{"op":"mcm","clk":"11763098108","pt":1722535214580,"mc":[{"id":"1.231284093","rc":[{"batl":[[0,2.24,4]],"ltp":2.22,"tv":42747.19,"id":424679}]}]}
{"op":"mcm","clk":"11763105011","pt":1722535265794,"mc":[{"id":"1.231284093","rc":[{"batl":[[0,2.24,8.31]],"ltp":2.22,"tv":42747.19,"id":424679}]}]}
{"op":"mcm","clk":"11763105401","pt":1722535267542,"mc":[{"id":"1.231284093","rc":[{"batl":[[0,2.24,4]],"ltp":2.22,"tv":42747.19,"id":424679}]}]}
{"op":"mcm","clk":"11763111363","pt":1722535307848,"mc":[{"id":"1.231284093","rc":[{"batl":[[0,2.24,8.31]],"ltp":2.22,"tv":42747.19,"id":424679}]}]}
{"op":"mcm","clk":"11763111678","pt":1722535310022,"mc":[{"id":"1.231284093","rc":[{"batl":[[0,2.24,4]],"ltp":2.22,"tv":42747.19,"id":424679}]}]}
{"op":"mcm","clk":"11763117057","pt":1722535345798,"mc":[{"id":"1.231284093","rc":[{"batl":[[0,2.24,8.31]],"ltp":2.22,"tv":42747.19,"id":424679}]}]}
{"op":"mcm","clk":"11763117424","pt":1722535347901,"mc":[{"id":"1.231284093","rc":[{"batl":[[0,2.24,4]],"ltp":2.22,"tv":42747.19,"id":424679}]}]}
{"op":"mcm","clk":"11763123714","pt":1722535388027,"mc":[{"id":"1.231284093","rc":[{"batl":[[0,2.24,8.31]],"ltp":2.22,"tv":42747.19,"id":424679}]}]}
{"op":"mcm","clk":"11763124148","pt":1722535390729,"mc":[{"id":"1.231284093","rc":[{"batl":[[0,2.24,4]],"ltp":2.22,"tv":42747.19,"id":424679}]}]}
{"op":"mcm","clk":"11763131496","pt":1722535437105,"mc":[{"id":"1.231284093","rc":[{"batl":[[0,2.24,8.31]],"ltp":2.22,"tv":42747.19,"id":424679}]}]}
{"op":"mcm","clk":"11763131893","pt":1722535439588,"mc":[{"id":"1.231284093","rc":[{"batl":[[0,2.24,4]],"ltp":2.22,"tv":42747.19,"id":424679}]}]}
{"op":"mcm","clk":"11763138655","pt":1722535482052,"mc":[{"id":"1.231284093","rc":[{"batl":[[0,2.24,8.31]],"ltp":2.22,"tv":42747.19,"id":424679}]}]}
{"op":"mcm","clk":"11763138953","pt":1722535483961,"mc":[{"id":"1.231284093","rc":[{"batl":[[0,2.24,4]],"ltp":2.22,"tv":42747.19,"id":424679}]}]}
{"op":"mcm","clk":"11763146022","pt":1722535525594,"mc":[{"id":"1.231284093","rc":[{"batl":[[0,2.24,8.31]],"ltp":2.22,"tv":42747.19,"id":424679}]}]}
{"op":"mcm","clk":"11763146336","pt":1722535527702,"mc":[{"id":"1.231284093","rc":[{"batl":[[0,2.24,4]],"ltp":2.22,"tv":42747.19,"id":424679}]}]}
{"op":"mcm","clk":"11763153110","pt":1722535569291,"mc":[{"id":"1.231284093","rc":[{"batl":[[0,2.24,8.31]],"ltp":2.22,"tv":42747.19,"id":424679}]}]}
{"op":"mcm","clk":"11763153572","pt":1722535572012,"mc":[{"id":"1.231284093","rc":[{"batl":[[0,2.24,4]],"ltp":2.22,"tv":42747.19,"id":424679}]}]}
{"op":"mcm","clk":"11763160868","pt":1722535615053,"mc":[{"id":"1.231284093","rc":[{"batl":[[0,2.24,8.31]],"ltp":2.22,"tv":42747.19,"id":424679}]}]}
{"op":"mcm","clk":"11763161253","pt":1722535617437,"mc":[{"id":"1.231284093","rc":[{"batl":[[0,2.24,4]],"ltp":2.22,"tv":42747.19,"id":424679}]}]}
{"op":"mcm","clk":"11763167736","pt":1722535658804,"mc":[{"id":"1.231284093","rc":[{"batl":[[0,2.24,8.31]],"ltp":2.22,"tv":42747.19,"id":424679}]}]}
{"op":"mcm","clk":"11763168089","pt":1722535661076,"mc":[{"id":"1.231284093","rc":[{"batl":[[0,2.24,4]],"ltp":2.22,"tv":42747.19,"id":424679}]}]}
{"op":"mcm","clk":"11763173665","pt":1722535695083,"mc":[{"id":"1.231284093","rc":[{"trd":[[1.81,21.65]],"batb":[[0,1.81,1.97]],"ltp":1.81,"tv":43966.14,"id":5995}],"tv":86713.33}]}
{"op":"mcm","clk":"11763231074","pt":1722535988019,"mc":[{"id":"1.231284093","rc":[{"batb":[[0,1.81,9.28]],"ltp":1.81,"tv":43966.14,"id":5995}]}]}
{"op":"mcm","clk":"11763655884","pt":1722538749815,"mc":[{"id":"1.231284093","rc":[{"trd":[[1.81,36.26]],"batb":[[0,1.81,1.97]],"ltp":1.81,"tv":43980.76,"id":5995}],"tv":86727.95}]}
{"op":"mcm","clk":"11763656744","pt":1722538756131,"mc":[{"id":"1.231284093","rc":[{"batb":[[0,1.81,5.97]],"ltp":1.81,"tv":43980.76,"id":5995}]}]}
{"op":"mcm","clk":"11763771174","pt":1722539495156,"mc":[{"id":"1.231284093","rc":[{"trd":[[2.2,7366.95],[2.22,35430.56]],"ltp":2.22,"tv":42797.54,"id":424679},{"trd":[[1.8,124.95],[1.81,38.16],[1.84,2835.37],[1.85,41026.06],[1.86,9.68]],"batb":[[0,1.81,5.04]],"batl":[[0,1.86,6.78]],"ltp":1.81,"tv":44034.28,"id":5995}],"tv":86831.83}]}
{"op":"mcm","clk":"11763771369","pt":1722539496357,"mc":[{"id":"1.231284093","rc":[{"batl":[[0,2.24,8.37]],"ltp":2.22,"tv":42797.54,"id":424679}]}]}
{"op":"mcm","clk":"11763771716","pt":1722539498363,"mc":[{"id":"1.231284093","rc":[{"batl":[[0,2.24,4]],"ltp":2.22,"tv":42797.54,"id":424679}]}]}
{"op":"mcm","clk":"11763779771","pt":1722539542514,"mc":[{"id":"1.231284093","rc":[{"batl":[[0,2.24,8.37]],"ltp":2.22,"tv":42797.54,"id":424679}]}]}
{"op":"mcm","clk":"11763780182","pt":1722539544630,"mc":[{"id":"1.231284093","rc":[{"batl":[[0,2.24,4]],"ltp":2.22,"tv":42797.54,"id":424679}]}]}
{"op":"mcm","clk":"11763787951","pt":1722539588752,"mc":[{"id":"1.231284093","rc":[{"batl":[[0,2.24,8.37]],"ltp":2.22,"tv":42797.54,"id":424679}]}]}
{"op":"mcm","clk":"11763788299","pt":1722539590771,"mc":[{"id":"1.231284093","rc":[{"batl":[[0,2.24,4]],"ltp":2.22,"tv":42797.54,"id":424679}]}]}
{"op":"mcm","clk":"11763796161","pt":1722539638475,"mc":[{"id":"1.231284093","rc":[{"batl":[[0,2.24,8.37]],"ltp":2.22,"tv":42797.54,"id":424679}]}]}
{"op":"mcm","clk":"11763796527","pt":1722539640708,"mc":[{"id":"1.231284093","rc":[{"batl":[[0,2.24,4]],"ltp":2.22,"tv":42797.54,"id":424679}]}]}
{"op":"mcm","clk":"11763804344","pt":1722539687441,"mc":[{"id":"1.231284093","rc":[{"batl":[[0,2.24,8.37]],"ltp":2.22,"tv":42797.54,"id":424679}]}]}
{"op":"mcm","clk":"11763804649","pt":1722539689357,"mc":[{"id":"1.231284093","rc":[{"batl":[[0,2.24,4]],"ltp":2.22,"tv":42797.54,"id":424679}]}]}
{"op":"mcm","clk":"11763812349","pt":1722539735982,"mc":[{"id":"1.231284093","rc":[{"batl":[[0,2.24,8.37]],"ltp":2.22,"tv":42797.54,"id":424679}]}]}
{"op":"mcm","clk":"11763812678","pt":1722539738265,"mc":[{"id":"1.231284093","rc":[{"batl":[[0,2.24,4]],"ltp":2.22,"tv":42797.54,"id":424679}]}]}
{"op":"mcm","clk":"11763820018","pt":1722539784756,"mc":[{"id":"1.231284093","rc":[{"batl":[[0,2.24,8.37]],"ltp":2.22,"tv":42797.54,"id":424679}]}]}
{"op":"mcm","clk":"11763820290","pt":1722539786682,"mc":[{"id":"1.231284093","rc":[{"batl":[[0,2.24,4]],"ltp":2.22,"tv":42797.54,"id":424679}]}]}
{"op":"mcm","clk":"11763827098","pt":1722539832407,"mc":[{"id":"1.231284093","rc":[{"batl":[[0,2.24,8.37]],"ltp":2.22,"tv":42797.54,"id":424679}]}]}
{"op":"mcm","clk":"11763827413","pt":1722539834296,"mc":[{"id":"1.231284093","rc":[{"batl":[[0,2.24,4]],"ltp":2.22,"tv":42797.54,"id":424679}]}]}
{"op":"mcm","clk":"11763834590","pt":1722539881974,"mc":[{"id":"1.231284093","rc":[{"batl":[[0,2.24,8.37]],"ltp":2.22,"tv":42797.54,"id":424679}]}]}
{"op":"mcm","clk":"11763834943","pt":1722539884194,"mc":[{"id":"1.231284093","rc":[{"batl":[[0,2.24,4]],"ltp":2.22,"tv":42797.54,"id":424679}]}]}
{"op":"mcm","clk":"11763841990","pt":1722539931025,"mc":[{"id":"1.231284093","rc":[{"batl":[[0,2.24,8.37]],"ltp":2.22,"tv":42797.54,"id":424679}]}]}
{"op":"mcm","clk":"11763842269","pt":1722539932973,"mc":[{"id":"1.231284093","rc":[{"batl":[[0,2.24,4]],"ltp":2.22,"tv":42797.54,"id":424679}]}]}
{"op":"mcm","clk":"11763848755","pt":1722539980400,"mc":[{"id":"1.231284093","rc":[{"batl":[[0,2.24,8.37]],"ltp":2.22,"tv":42797.54,"id":424679}]}]}
{"op":"mcm","clk":"11763849019","pt":1722539982731,"mc":[{"id":"1.231284093","rc":[{"batl":[[0,2.24,4]],"ltp":2.22,"tv":42797.54,"id":424679}]}]}
{"op":"mcm","clk":"11763855046","pt":1722540029788,"mc":[{"id":"1.231284093","rc":[{"batl":[[0,2.24,8.37]],"ltp":2.22,"tv":42797.54,"id":424679}]}]}
{"op":"mcm","clk":"11763855338","pt":1722540032177,"mc":[{"id":"1.231284093","rc":[{"batl":[[0,2.24,4]],"ltp":2.22,"tv":42797.54,"id":424679}]}]}
{"op":"mcm","clk":"11763861898","pt":1722540079270,"mc":[{"id":"1.231284093","rc":[{"batl":[[0,2.24,8.37]],"ltp":2.22,"tv":42797.54,"id":424679}]}]}
{"op":"mcm","clk":"11763862403","pt":1722540082143,"mc":[{"id":"1.231284093","rc":[{"batl":[[0,2.24,4]],"ltp":2.22,"tv":42797.54,"id":424679},{"trd":[[1.81,48.24]],"batb":[[0,1.8,57.95],[1,1.75,29],[2,1.74,17.32]],"batl":[[0,1.81,2.28],[1,1.86,6.78],[2,1.87,15]],"ltp":1.81,"tv":44044.36,"id":5995}],"tv":86841.91}]}
{"op":"mcm","clk":"11764052814","pt":1722541532070,"mc":[{"id":"1.231284093","rc":[{"batb":[[1,1.74,17.32],[2,1.43,116.28]],"ltp":2.22,"tv":42797.54,"id":424679},{"batb":[[0,1.75,29],[1,1.74,17.32],[2,1.43,116.28]],"ltp":1.81,"tv":44044.36,"id":5995}]}]}
{"op":"mcm","clk":"11764052880","pt":1722541532590,"mc":[{"id":"1.231284093","rc":[{"batl":[[1,1.86,4.61]],"ltp":1.81,"tv":44044.36,"id":5995}]}]}
{"op":"mcm","clk":"11764053137","pt":1722541534278,"mc":[{"id":"1.231284093","rc":[{"batb":[[1,2.14,37.86],[2,1.74,17.32]],"ltp":2.22,"tv":42797.54,"id":424679},{"batb":[[0,1.8,53.95],[1,1.75,29],[2,1.74,17.32]],"ltp":1.81,"tv":44044.36,"id":5995}]}]}
{"op":"mcm","clk":"11764053915","pt":1722541537589,"mc":[{"id":"1.231284093","rc":[{"batl":[[0,2.24,4],[1,2.26,4]],"ltp":2.22,"tv":42797.54,"id":424679},{"batb":[[0,1.8,57.95]],"ltp":1.81,"tv":44044.36,"id":5995}]}]}
{"op":"mcm","clk":"11764058526","pt":1722541569252,"mc":[{"id":"1.231284093","rc":[{"trd":[[1.8,125.09]],"batb":[[0,1.8,57.88]],"ltp":1.8,"tv":44044.5,"id":5995}],"tv":86842.05}]}
{"op":"mcm","clk":"11764058575","pt":1722541569530,"mc":[{"id":"1.231284093","rc":[{"batb":[[0,1.8,57.95]],"ltp":1.8,"tv":44044.5,"id":5995}]}]}
{"op":"mcm","clk":"11764141015","pt":1722542434709,"mc":[{"id":"1.231284093","rc":[{"trd":[[2.2,7361.17],[2.22,35402.76]],"ltp":2.22,"tv":42763.96,"id":424679},{"trd":[[1.8,125.07],[1.81,50.21],[1.84,2833.15],[1.85,40993.87],[1.86,9.67]],"batl":[[0,1.81,1.28],[1,1.86,4.61]],"ltp":1.81,"tv":44012.04,"id":5995}],"tv":86776.0}]}
{"op":"mcm","clk":"11764144849","pt":1722542475017,"mc":[{"id":"1.231284093","rc":[{"batl":[[1,1.86,5.61]],"ltp":1.81,"tv":44012.04,"id":5995}]}]}
{"op":"mcm","clk":"11764174434","pt":1722542751532,"mc":[{"id":"1.231284093","rc":[{"trd":[[1.8,125.21]],"batb":[[0,1.8,57.88]],"ltp":1.8,"tv":44012.18,"id":5995}],"tv":86776.14}]}
{"op":"mcm","clk":"11764213610","pt":1722543123078,"mc":[{"id":"1.231284093","rc":[{"batl":[[2,1.87,36.75]],"ltp":1.8,"tv":44012.18,"id":5995}]}]}
{"op":"mcm","clk":"11764213720","pt":1722543124112,"mc":[{"id":"1.231284093","rc":[{"batb":[[0,2.16,9.26]],"ltp":2.22,"tv":42763.96,"id":424679}]}]}
{"op":"mcm","clk":"11764240537","pt":1722543404586,"mc":[{"id":"1.231284093","rc":[{"trd":[[1.8,129.19]],"batb":[[0,1.8,55.89]],"ltp":1.8,"tv":44016.16,"id":5995}],"tv":86780.12}]}
{"op":"mcm","clk":"11764277910","pt":1722543753758,"mc":[{"id":"1.231284093","rc":[{"trd":[[1.8,131.18]],"batb":[[0,1.8,54.9]],"ltp":1.8,"tv":44018.14,"id":5995}],"tv":86782.11}]}
{"op":"mcm","clk":"11764285881","pt":1722543831628,"mc":[{"id":"1.231284093","rc":[{"trd":[[1.81,52.21]],"batl":[[0,1.86,5.88],[1,1.87,36.75],[2,1.87,0]],"ltp":1.81,"tv":44020.14,"id":5995}],"tv":86784.11}]}
{"op":"mcm","clk":"11764286222","pt":1722543835342,"mc":[{"id":"1.231284093","rc":[{"batl":[[0,1.86,9.88]],"ltp":1.81,"tv":44020.14,"id":5995}]}]}
{"op":"mcm","clk":"11764291695","pt":1722543893195,"mc":[{"id":"1.231284093","rc":[{"batb":[[0,2.18,36.57],[1,2.16,9.26]],"ltp":2.22,"tv":42763.96,"id":424679},{"batb":[[0,1.78,56.28]],"ltp":1.81,"tv":44020.14,"id":5995}]}]}
{"op":"mcm","clk":"11764291752","pt":1722543893706,"mc":[{"id":"1.231284093","rc":[{"batb":[[0,1.78,55.33]],"ltp":1.81,"tv":44020.14,"id":5995}]}]}
{"op":"mcm","clk":"11764291826","pt":1722543894586,"mc":[{"id":"1.231284093","rc":[{"batb":[[1,2.16,4]],"ltp":2.22,"tv":42763.96,"id":424679},{"batl":[[0,1.84,4.93],[1,1.86,5],[2,1.87,36.75]],"ltp":1.81,"tv":44020.14,"id":5995}]}]}
{"op":"mcm","clk":"11764291984","pt":1722543896289,"mc":[{"id":"1.231284093","rc":[{"batb":[[0,2.2,10],[1,2.18,40.57],[2,2.16,4]],"batl":[[0,2.28,4],[1,2.3,4]],"ltp":2.22,"tv":42763.96,"id":424679},{"batb":[[0,1.78,59.33]],"batl":[[0,1.84,8.93]],"ltp":1.81,"tv":44020.14,"id":5995}]}]}
{"op":"mcm","clk":"11764292006","pt":1722543896500,"mc":[{"id":"1.231284093","rc":[{"batl":[[2,2.32,1.47]],"ltp":2.22,"tv":42763.96,"id":424679}]}]}
{"op":"mcm","clk":"11764292336","pt":1722543899793,"mc":[{"id":"1.231284093","rc":[{"batb":[[0,2.18,40.57],[1,2.16,4],[2,1.74,17.32]],"ltp":2.22,"tv":42763.96,"id":424679}]}]}
{"op":"mcm","clk":"11764292572","pt":1722543902176,"mc":[{"id":"1.231284093","rc":[{"batb":[[0,2.2,10],[1,2.18,40.57],[2,2.16,4]],"ltp":2.22,"tv":42763.96,"id":424679}]}]}
{"op":"mcm","clk":"11764292889","pt":1722543905484,"mc":[{"id":"1.231284093","rc":[{"batb":[[0,2.18,40.57],[1,2.16,4],[2,1.74,17.32]],"ltp":2.22,"tv":42763.96,"id":424679}]}]}
{"op":"mcm","clk":"11764293276","pt":1722543909104,"mc":[{"id":"1.231284093","rc":[{"batb":[[0,2.2,10],[1,2.18,40.57],[2,2.16,4]],"ltp":2.22,"tv":42763.96,"id":424679}]}]}
{"op":"mcm","clk":"11764293481","pt":1722543911079,"mc":[{"id":"1.231284093","rc":[{"batb":[[0,2.2,14]],"ltp":2.22,"tv":42763.96,"id":424679}]}]}
{"op":"mcm","clk":"11764293630","pt":1722543912478,"mc":[{"id":"1.231284093","rc":[{"batb":[[0,2.2,4]],"ltp":2.22,"tv":42763.96,"id":424679}]}]}
{"op":"mcm","clk":"11764380603","pt":1722544942894,"mc":[{"id":"1.231284093","rc":[{"batb":[[0,1.8,4],[1,1.78,59.33],[2,1.75,29]],"ltp":1.81,"tv":44020.14,"id":5995}]}]}
{"op":"mcm","clk":"11764381555","pt":1722544953678,"mc":[{"id":"1.231284093","rc":[{"batl":[[0,1.83,4.28],[1,1.84,8.66],[2,1.86,5]],"ltp":1.81,"tv":44020.14,"id":5995}]}]}
{"op":"mcm","clk":"11764383287","pt":1722544975341,"mc":[{"id":"1.231284093","rc":[{"batl":[[0,2.28,8.28]],"ltp":2.22,"tv":42763.96,"id":424679}]}]}
{"op":"mcm","clk":"11764383584","pt":1722544978598,"mc":[{"id":"1.231284093","rc":[{"batl":[[0,2.28,4]],"ltp":2.22,"tv":42763.96,"id":424679}]}]}
{"op":"mcm","clk":"11764388257","pt":1722545035368,"mc":[{"id":"1.231284093","rc":[{"batl":[[0,2.28,8.28]],"ltp":2.22,"tv":42763.96,"id":424679}]}]}
{"op":"mcm","clk":"11764388488","pt":1722545038258,"mc":[{"id":"1.231284093","rc":[{"batl":[[0,2.28,4]],"ltp":2.22,"tv":42763.96,"id":424679}]}]}
{"op":"mcm","clk":"11764393761","pt":1722545097990,"mc":[{"id":"1.231284093","rc":[{"batl":[[0,2.28,8.28]],"ltp":2.22,"tv":42763.96,"id":424679}]}]}
{"op":"mcm","clk":"11764393995","pt":1722545100199,"mc":[{"id":"1.231284093","rc":[{"batl":[[0,2.28,4]],"ltp":2.22,"tv":42763.96,"id":424679}]}]}
{"op":"mcm","clk":"11764398651","pt":1722545151350,"mc":[{"id":"1.231284093","rc":[{"trd":[[1.8,131.32]],"batb":[[0,1.8,3.93]],"ltp":1.8,"tv":44020.28,"id":5995}],"tv":86784.25}]}
{"op":"mcm","clk":"11764399439","pt":1722545159494,"mc":[{"id":"1.231284093","rc":[{"batl":[[0,2.28,8.28]],"ltp":2.22,"tv":42763.96,"id":424679}]}]}
{"op":"mcm","clk":"11764399654","pt":1722545161873,"mc":[{"id":"1.231284093","rc":[{"batl":[[0,2.28,4]],"ltp":2.22,"tv":42763.96,"id":424679}]}]}
{"op":"mcm","clk":"11764403839","pt":1722545220942,"mc":[{"id":"1.231284093","rc":[{"batl":[[0,2.28,8.28]],"ltp":2.22,"tv":42763.96,"id":424679}]}]}
{"op":"mcm","clk":"11764403979","pt":1722545223149,"mc":[{"id":"1.231284093","rc":[{"batl":[[0,2.28,4]],"ltp":2.22,"tv":42763.96,"id":424679}]}]}
{"op":"mcm","clk":"11764407693","pt":1722545281687,"mc":[{"id":"1.231284093","rc":[{"batl":[[0,2.28,8.28]],"ltp":2.22,"tv":42763.96,"id":424679}]}]}
{"op":"mcm","clk":"11764407869","pt":1722545283695,"mc":[{"id":"1.231284093","rc":[{"batl":[[0,2.28,4]],"ltp":2.22,"tv":42763.96,"id":424679}]}]}
{"op":"mcm","clk":"11764411844","pt":1722545344188,"mc":[{"id":"1.231284093","rc":[{"batl":[[0,2.28,8.28]],"ltp":2.22,"tv":42763.96,"id":424679}]}]}
{"op":"mcm","clk":"11764411978","pt":1722545346298,"mc":[{"id":"1.231284093","rc":[{"batl":[[0,2.28,4]],"ltp":2.22,"tv":42763.96,"id":424679}]}]}
{"op":"mcm","clk":"11764415727","pt":1722545404767,"mc":[{"id":"1.231284093","rc":[{"batl":[[0,2.28,8.28]],"ltp":2.22,"tv":42763.96,"id":424679}]}]}
{"op":"mcm","clk":"11764415931","pt":1722545407263,"mc":[{"id":"1.231284093","rc":[{"batl":[[0,2.28,4]],"ltp":2.22,"tv":42763.96,"id":424679}]}]}
{"op":"mcm","clk":"11764419698","pt":1722545465510,"mc":[{"id":"1.231284093","rc":[{"batl":[[0,2.28,8.28]],"ltp":2.22,"tv":42763.96,"id":424679}]}]}
{"op":"mcm","clk":"11764419806","pt":1722545467408,"mc":[{"id":"1.231284093","rc":[{"batl":[[0,2.28,4]],"ltp":2.22,"tv":42763.96,"id":424679}]}]}
{"op":"mcm","clk":"11764423706","pt":1722545527598,"mc":[{"id":"1.231284093","rc":[{"batl":[[0,2.28,8.28]],"ltp":2.22,"tv":42763.96,"id":424679}]}]}
{"op":"mcm","clk":"11764423815","pt":1722545529703,"mc":[{"id":"1.231284093","rc":[{"batl":[[0,2.28,4]],"ltp":2.22,"tv":42763.96,"id":424679}]}]}
{"op":"mcm","clk":"11764427202","pt":1722545589255,"mc":[{"id":"1.231284093","rc":[{"batl":[[0,2.28,8.28]],"ltp":2.22,"tv":42763.96,"id":424679}]}]}
{"op":"mcm","clk":"11764427324","pt":1722545591558,"mc":[{"id":"1.231284093","rc":[{"batl":[[0,2.28,4]],"ltp":2.22,"tv":42763.96,"id":424679}]}]}
{"op":"mcm","clk":"11764430236","pt":1722545649640,"mc":[{"id":"1.231284093","rc":[{"batl":[[0,2.28,8.28]],"ltp":2.22,"tv":42763.96,"id":424679}]}]}
{"op":"mcm","clk":"11764430336","pt":1722545651638,"mc":[{"id":"1.231284093","rc":[{"batl":[[0,2.28,4]],"ltp":2.22,"tv":42763.96,"id":424679}]}]}
{"op":"mcm","clk":"11764432885","pt":1722545710128,"mc":[{"id":"1.231284093","rc":[{"batl":[[0,2.28,8.28]],"ltp":2.22,"tv":42763.96,"id":424679}]}]}
{"op":"mcm","clk":"11764432954","pt":1722545712229,"mc":[{"id":"1.231284093","rc":[{"batl":[[0,2.28,4]],"ltp":2.22,"tv":42763.96,"id":424679}]}]}
{"op":"mcm","clk":"11764435642","pt":1722545771188,"mc":[{"id":"1.231284093","rc":[{"batl":[[0,2.28,8.28]],"ltp":2.22,"tv":42763.96,"id":424679}]}]}
{"op":"mcm","clk":"11764435758","pt":1722545773597,"mc":[{"id":"1.231284093","rc":[{"batl":[[0,2.28,4]],"ltp":2.22,"tv":42763.96,"id":424679}]}]}
{"op":"mcm","clk":"11764438430","pt":1722545831148,"mc":[{"id":"1.231284093","rc":[{"batl":[[0,2.28,8.28]],"ltp":2.22,"tv":42763.96,"id":424679}]}]}
{"op":"mcm","clk":"11764438540","pt":1722545833633,"mc":[{"id":"1.231284093","rc":[{"batl":[[0,2.28,4]],"ltp":2.22,"tv":42763.96,"id":424679}]}]}
{"op":"mcm","clk":"11764441047","pt":1722545891998,"mc":[{"id":"1.231284093","rc":[{"batl":[[0,2.28,8.28]],"ltp":2.22,"tv":42763.96,"id":424679}]}]}
{"op":"mcm","clk":"11764441156","pt":1722545894305,"mc":[{"id":"1.231284093","rc":[{"batl":[[0,2.28,4]],"ltp":2.22,"tv":42763.96,"id":424679}]}]}
{"op":"mcm","clk":"11764443796","pt":1722545951406,"mc":[{"id":"1.231284093","rc":[{"batl":[[0,2.28,8.28]],"ltp":2.22,"tv":42763.96,"id":424679}]}]}
{"op":"mcm","clk":"11764443963","pt":1722545953563,"mc":[{"id":"1.231284093","rc":[{"batl":[[0,2.28,4]],"ltp":2.22,"tv":42763.96,"id":424679}]}]}
{"op":"mcm","clk":"11764446936","pt":1722546015570,"mc":[{"id":"1.231284093","rc":[{"trd":[[2.2,7362.9],[2.22,35411.1]],"batl":[[0,2.28,8.29]],"ltp":2.22,"tv":42774.03,"id":424679},{"trd":[[1.8,131.32],[1.81,52.22],[1.84,2833.81],[1.85,41003.53],[1.86,9.67]],"batl":[[1,1.84,8.66]],"ltp":1.8,"tv":44030.62,"id":5995}],"tv":86804.65}]}
{"op":"mcm","clk":"11764447102","pt":1722546019438,"mc":[{"id":"1.231284093","rc":[{"batl":[[0,2.28,4]],"ltp":2.22,"tv":42774.03,"id":424679}]}]}
{"op":"mcm","clk":"11764449770","pt":1722546068698,"mc":[{"id":"1.231284093","rc":[{"batl":[[0,2.28,8.29]],"ltp":2.22,"tv":42774.03,"id":424679}]}]}
{"op":"mcm","clk":"11764449945","pt":1722546071931,"mc":[{"id":"1.231284093","rc":[{"batl":[[0,2.28,4]],"ltp":2.22,"tv":42774.03,"id":424679}]}]}
{"op":"mcm","clk":"11764452812","pt":1722546128872,"mc":[{"id":"1.231284093","rc":[{"batl":[[0,2.28,8.29]],"ltp":2.22,"tv":42774.03,"id":424679}]}]}
{"op":"mcm","clk":"11764453076","pt":1722546131898,"mc":[{"id":"1.231284093","rc":[{"batl":[[0,2.28,4]],"ltp":2.22,"tv":42774.03,"id":424679}]}]}
{"op":"mcm","clk":"11764455828","pt":1722546183135,"mc":[{"id":"1.231284093","rc":[{"batl":[[0,2.28,8.29]],"ltp":2.22,"tv":42774.03,"id":424679}]}]}
{"op":"mcm","clk":"11764455956","pt":1722546185399,"mc":[{"id":"1.231284093","rc":[{"batl":[[0,2.28,4]],"ltp":2.22,"tv":42774.03,"id":424679}]}]}
{"op":"mcm","clk":"11764458620","pt":1722546235475,"mc":[{"id":"1.231284093","rc":[{"batl":[[0,2.28,8.29]],"ltp":2.22,"tv":42774.03,"id":424679}]}]}
{"op":"mcm","clk":"11764458726","pt":1722546237479,"mc":[{"id":"1.231284093","rc":[{"batl":[[0,2.28,4]],"ltp":2.22,"tv":42774.03,"id":424679}]}]}
{"op":"mcm","clk":"11764461193","pt":1722546286707,"mc":[{"id":"1.231284093","rc":[{"batl":[[0,2.28,8.29]],"ltp":2.22,"tv":42774.03,"id":424679}]}]}
{"op":"mcm","clk":"11764461295","pt":1722546289410,"mc":[{"id":"1.231284093","rc":[{"batl":[[0,2.28,4]],"ltp":2.22,"tv":42774.03,"id":424679}]}]}
{"op":"mcm","clk":"11764463232","pt":1722546334071,"mc":[{"id":"1.231284093","rc":[{"batl":[[0,2.28,8.29]],"ltp":2.22,"tv":42774.03,"id":424679}]}]}
{"op":"mcm","clk":"11764463318","pt":1722546336068,"mc":[{"id":"1.231284093","rc":[{"batl":[[0,2.28,4]],"ltp":2.22,"tv":42774.03,"id":424679}]}]}
{"op":"mcm","clk":"11764464009","pt":1722546351287,"mc":[{"id":"1.231284093","rc":[{"trd":[[1.8,131.46]],"batb":[[0,1.8,3.86]],"ltp":1.8,"tv":44030.76,"id":5995}],"tv":86804.79}]}
{"op":"mcm","clk":"11764465373","pt":1722546383409,"mc":[{"id":"1.231284093","rc":[{"batl":[[0,2.28,8.28]],"ltp":2.22,"tv":42774.03,"id":424679}]}]}
