{"op":"mcm","clk":"11780498858","pt":1722763363309,"mc":[{"id":"1.231431354","marketDefinition":{"bspMarket":false,"turnInPlayEnabled":true,"persistenceEnabled":true,"marketBaseRate":5.0,"eventId":"33467056","eventTypeId":"4","numberOfWinners":1,"bettingType":"ODDS","marketType":"MATCH_ODDS","marketTime":"2024-08-07T10:00:00.000Z","suspendTime":"2024-08-07T10:00:00.000Z","bspReconciled":false,"complete":true,"inPlay":false,"crossMatching":false,"runnersVoidable":false,"numberOfActiveRunners":2,"betDelay":0,"status":"OPEN","runners":[{"status":"ACTIVE","sortPriority":1,"id":31372,"name":"Worcestershire"},{"status":"ACTIVE","sortPriority":2,"id":5901,"name":"Kent"}],"regulators":["MR_INT"],"countryCode":"GB","discountAllowed":false,"timezone":"GMT","openDate":"2024-08-07T10:00:00.000Z","version":6056049237,"name":"Match Odds","eventName":"Worcestershire v Kent"},"rc":[{"batb":[[0,1.03,200],[1,1.02,200],[2,1.01,220]],"ltp":0.0,"tv":0.0,"id":5901},{"batb":[[0,1.03,200],[1,1.02,200],[2,1.01,220]],"ltp":0.0,"tv":0.0,"id":31372}]}]}
{"op":"mcm","clk":"11780499030","pt":1722763365529,"mc":[{"id":"1.231431354","marketDefinition":{"bspMarket":false,"turnInPlayEnabled":true,"persistenceEnabled":true,"marketBaseRate":5.0,"eventId":"33467056","eventTypeId":"4","numberOfWinners":1,"bettingType":"ODDS","marketType":"MATCH_ODDS","marketTime":"2024-08-07T10:00:00.000Z","suspendTime":"2024-08-07T10:00:00.000Z","bspReconciled":false,"complete":true,"inPlay":false,"crossMatching":false,"runnersVoidable":false,"numberOfActiveRunners":2,"betDelay":0,"status":"OPEN","runners":[{"status":"ACTIVE","sortPriority":1,"id":31372,"name":"Worcestershire"},{"status":"ACTIVE","sortPriority":2,"id":5901,"name":"Kent"}],"regulators":["MR_INT"],"countryCode":"GB","discountAllowed":true,"timezone":"GMT","openDate":"2024-08-07T10:00:00.000Z","version":6056049237,"name":"Match Odds","eventName":"Worcestershire v Kent"}}]}
{"op":"mcm","clk":"11780917407","pt":1722767444057,"mc":[{"id":"1.231431354","rc":[{"batb":[[2,1.01,478.41]],"ltp":0.0,"tv":0.0,"id":5901},{"batb":[[2,1.01,478.41]],"ltp":0.0,"tv":0.0,"id":31372}]}]}
{"op":"mcm","clk":"11780991169","pt":1722768150480,"mc":[{"id":"1.231431354","rc":[{"batb":[[2,1.01,486.22]],"ltp":0.0,"tv":0.0,"id":5901},{"batb":[[2,1.01,486.22]],"ltp":0.0,"tv":0.0,"id":31372}]}]}
{"op":"mcm","clk":"11780991649","pt":1722768155439,"mc":[{"id":"1.231431354","marketDefinition":{"bspMarket":false,"turnInPlayEnabled":true,"persistenceEnabled":true,"marketBaseRate":5.0,"eventId":"33467056","eventTypeId":"4","numberOfWinners":1,"bettingType":"ODDS","marketType":"MATCH_ODDS","marketTime":"2024-08-07T10:00:00.000Z","suspendTime":"2024-08-07T10:00:00.000Z","bspReconciled":false,"complete":true,"inPlay":false,"crossMatching":true,"runnersVoidable":false,"numberOfActiveRunners":2,"betDelay":0,"status":"OPEN","runners":[{"status":"ACTIVE","sortPriority":1,"id":31372,"name":"Worcestershire"},{"status":"ACTIVE","sortPriority":2,"id":5901,"name":"Kent"}],"regulators":["MR_INT"],"countryCode":"GB","discountAllowed":true,"timezone":"GMT","openDate":"2024-08-07T10:00:00.000Z","version":6056049237,"name":"Match Odds","eventName":"Worcestershire v Kent"}}]}
{"op":"mcm","clk":"11780992273","pt":1722768162117,"mc":[{"id":"1.231431354","rc":[{"batb":[[1,1.02,207.81]],"ltp":0.0,"tv":0.0,"id":5901},{"batb":[[1,1.02,207.81]],"ltp":0.0,"tv":0.0,"id":31372}]}]}
{"op":"mcm","clk":"11781002052","pt":1722768176605,"mc":[{"id":"1.231431354","rc":[{"batb":[[1,1.02,246.85]],"ltp":0.0,"tv":0.0,"id":5901},{"batb":[[1,1.02,246.85]],"ltp":0.0,"tv":0.0,"id":31372}]}]}
{"op":"mcm","clk":"11781003331","pt":1722768189316,"mc":[{"id":"1.231431354","rc":[{"batb":[[0,1.03,207.81]],"ltp":0.0,"tv":0.0,"id":5901},{"batb":[[0,1.03,207.81]],"ltp":0.0,"tv":0.0,"id":31372}]}]}
{"op":"mcm","clk":"11781004513","pt":1722768200439,"mc":[{"id":"1.231431354","rc":[{"batb":[[0,1.04,7.81],[1,1.03,207.81],[2,1.02,246.85]],"ltp":0.0,"tv":0.0,"id":5901},{"batb":[[0,1.04,7.81],[1,1.03,207.81],[2,1.02,246.85]],"ltp":0.0,"tv":0.0,"id":31372}]}]}
{"op":"mcm","clk":"11781005649","pt":1722768211640,"mc":[{"id":"1.231431354","rc":[{"batb":[[0,1.05,7.81],[1,1.04,7.81],[2,1.03,207.81]],"ltp":0.0,"tv":0.0,"id":5901},{"batb":[[0,1.05,7.81],[1,1.04,7.81],[2,1.03,207.81]],"ltp":0.0,"tv":0.0,"id":31372}]}]}
{"op":"mcm","clk":"11781006904","pt":1722768224663,"mc":[{"id":"1.231431354","rc":[{"batb":[[0,1.06,7.81],[1,1.05,7.81],[2,1.04,7.81]],"ltp":0.0,"tv":0.0,"id":5901},{"batb":[[0,1.06,7.81],[1,1.05,7.81],[2,1.04,7.81]],"ltp":0.0,"tv":0.0,"id":31372}]}]}
{"op":"mcm","clk":"11781008473","pt":1722768239963,"mc":[{"id":"1.231431354","rc":[{"batb":[[0,1.07,7.81],[1,1.06,7.81],[2,1.05,7.81]],"ltp":0.0,"tv":0.0,"id":5901},{"batb":[[0,1.07,7.81],[1,1.06,7.81],[2,1.05,7.81]],"ltp":0.0,"tv":0.0,"id":31372}]}]}
{"op":"mcm","clk":"11781010553","pt":1722768258980,"mc":[{"id":"1.231431354","rc":[{"batb":[[0,1.08,7.81],[1,1.07,7.81],[2,1.06,7.81]],"ltp":0.0,"tv":0.0,"id":5901},{"batb":[[0,1.08,7.81],[1,1.07,7.81],[2,1.06,7.81]],"ltp":0.0,"tv":0.0,"id":31372}]}]}
{"op":"mcm","clk":"11781019960","pt":1722768346200,"mc":[{"id":"1.231431354","rc":[{"batb":[[0,1.09,95.17],[1,1.08,7.81],[2,1.07,7.81]],"ltp":0.0,"tv":0.0,"id":5901},{"batb":[[0,1.09,95.17],[1,1.08,7.81],[2,1.07,7.81]],"ltp":0.0,"tv":0.0,"id":31372}]}]}
{"op":"mcm","clk":"11781192435","pt":1722770146463,"mc":[{"id":"1.231431354","rc":[{"batb":[[0,1.08,7.81],[1,1.07,7.81],[2,1.06,7.81]],"ltp":0.0,"tv":0.0,"id":31372}]}]}
{"op":"mcm","clk":"11781192448","pt":1722770146568,"mc":[{"id":"1.231431354","rc":[{"batb":[[0,1.08,7.81],[1,1.07,7.81],[2,1.06,7.81]],"ltp":0.0,"tv":0.0,"id":5901}]}]}
{"op":"mcm","clk":"11781194918","pt":1722770171059,"mc":[{"id":"1.231431354","rc":[{"batb":[[0,1.09,95.17],[1,1.08,7.81],[2,1.07,7.81]],"ltp":0.0,"tv":0.0,"id":5901},{"batb":[[0,1.09,95.17],[1,1.08,7.81],[2,1.07,7.81]],"ltp":0.0,"tv":0.0,"id":31372}]}]}
{"op":"mcm","clk":"11781376314","pt":1722771971403,"mc":[{"id":"1.231431354","rc":[{"batb":[[0,1.08,7.81],[1,1.07,7.81],[2,1.06,7.81]],"ltp":0.0,"tv":0.0,"id":5901}]}]}
{"op":"mcm","clk":"11781376347","pt":1722771971666,"mc":[{"id":"1.231431354","rc":[{"batb":[[0,1.08,7.81],[1,1.07,7.81],[2,1.06,7.81]],"ltp":0.0,"tv":0.0,"id":31372}]}]}
{"op":"mcm","clk":"11781378095","pt":1722771988414,"mc":[{"id":"1.231431354","rc":[{"batb":[[0,1.09,95.17],[1,1.08,7.81],[2,1.07,7.81]],"ltp":0.0,"tv":0.0,"id":5901},{"batb":[[0,1.09,95.17],[1,1.08,7.81],[2,1.07,7.81]],"ltp":0.0,"tv":0.0,"id":31372}]}]}
{"op":"mcm","clk":"11781569676","pt":1722773788812,"mc":[{"id":"1.231431354","rc":[{"batb":[[0,1.08,7.81],[1,1.07,7.81],[2,1.06,7.81]],"ltp":0.0,"tv":0.0,"id":5901},{"batb":[[0,1.08,7.81],[1,1.07,7.81],[2,1.06,7.81]],"ltp":0.0,"tv":0.0,"id":31372}]}]}
{"op":"mcm","clk":"11781570952","pt":1722773801488,"mc":[{"id":"1.231431354","rc":[{"batb":[[0,1.09,95.17],[1,1.08,7.81],[2,1.07,7.81]],"ltp":0.0,"tv":0.0,"id":31372}]}]}
{"op":"mcm","clk":"11781570964","pt":1722773801586,"mc":[{"id":"1.231431354","rc":[{"batb":[[0,1.09,95.17],[1,1.08,7.81],[2,1.07,7.81]],"ltp":0.0,"tv":0.0,"id":5901}]}]}
{"op":"mcm","clk":"11781777316","pt":1722775601805,"mc":[{"id":"1.231431354","rc":[{"batb":[[0,1.08,7.81],[1,1.07,7.81],[2,1.06,7.81]],"ltp":0.0,"tv":0.0,"id":5901},{"batb":[[0,1.08,7.81],[1,1.07,7.81],[2,1.06,7.81]],"ltp":0.0,"tv":0.0,"id":31372}]}]}
{"op":"mcm","clk":"11781777776","pt":1722775605638,"mc":[{"id":"1.231431354","rc":[{"batb":[[0,1.09,95.17],[1,1.08,7.81],[2,1.07,7.81]],"ltp":0.0,"tv":0.0,"id":5901},{"batb":[[0,1.09,95.17],[1,1.08,7.81],[2,1.07,7.81]],"ltp":0.0,"tv":0.0,"id":31372}]}]}
{"op":"mcm","clk":"11781998400","pt":1722777406025,"mc":[{"id":"1.231431354","rc":[{"batb":[[0,1.08,7.81],[1,1.07,7.81],[2,1.06,7.81]],"ltp":0.0,"tv":0.0,"id":5901},{"batb":[[0,1.08,7.81],[1,1.07,7.81],[2,1.06,7.81]],"ltp":0.0,"tv":0.0,"id":31372}]}]}
{"op":"mcm","clk":"11782014399","pt":1722777512846,"mc":[{"id":"1.231431354","rc":[{"batb":[[0,1.09,95.17],[1,1.08,7.81],[2,1.07,7.81]],"ltp":0.0,"tv":0.0,"id":5901},{"batb":[[0,1.09,95.17],[1,1.08,7.81],[2,1.07,7.81]],"ltp":0.0,"tv":0.0,"id":31372}]}]}
{"op":"mcm","clk":"11782266511","pt":1722779313312,"mc":[{"id":"1.231431354","rc":[{"batb":[[0,1.08,7.81],[1,1.07,7.81],[2,1.06,7.81]],"ltp":0.0,"tv":0.0,"id":5901},{"batb":[[0,1.08,7.81],[1,1.07,7.81],[2,1.06,7.81]],"ltp":0.0,"tv":0.0,"id":31372}]}]}
{"op":"mcm","clk":"11782273896","pt":1722779379564,"mc":[{"id":"1.231431354","rc":[{"batb":[[0,1.09,95.17],[1,1.08,7.81],[2,1.07,7.81]],"ltp":0.0,"tv":0.0,"id":5901},{"batb":[[0,1.09,95.17],[1,1.08,7.81],[2,1.07,7.81]],"ltp":0.0,"tv":0.0,"id":31372}]}]}
{"op":"mcm","clk":"11782530091","pt":1722781180136,"mc":[{"id":"1.231431354","rc":[{"batb":[[0,1.08,7.81],[1,1.07,7.81],[2,1.06,7.81]],"ltp":0.0,"tv":0.0,"id":5901},{"batb":[[0,1.08,7.81],[1,1.07,7.81],[2,1.06,7.81]],"ltp":0.0,"tv":0.0,"id":31372}]}]}
{"op":"mcm","clk":"11782533650","pt":1722781205365,"mc":[{"id":"1.231431354","rc":[{"batb":[[0,1.09,95.17],[1,1.08,7.81],[2,1.07,7.81]],"ltp":0.0,"tv":0.0,"id":5901},{"batb":[[0,1.09,95.17],[1,1.08,7.81],[2,1.07,7.81]],"ltp":0.0,"tv":0.0,"id":31372}]}]}
{"op":"mcm","clk":"11782809069","pt":1722783005656,"mc":[{"id":"1.231431354","rc":[{"batb":[[0,1.08,7.81],[1,1.07,7.81],[2,1.06,7.81]],"ltp":0.0,"tv":0.0,"id":5901},{"batb":[[0,1.08,7.81],[1,1.07,7.81],[2,1.06,7.81]],"ltp":0.0,"tv":0.0,"id":31372}]}]}
{"op":"mcm","clk":"11782821849","pt":1722783105763,"mc":[{"id":"1.231431354","rc":[{"batb":[[0,1.09,95.17],[1,1.08,7.81],[2,1.07,7.81]],"ltp":0.0,"tv":0.0,"id":5901},{"batb":[[0,1.09,95.17],[1,1.08,7.81],[2,1.07,7.81]],"ltp":0.0,"tv":0.0,"id":31372}]}]}
{"op":"mcm","clk":"11783105681","pt":1722784906203,"mc":[{"id":"1.231431354","rc":[{"batb":[[0,1.08,7.81],[1,1.07,7.81],[2,1.06,7.81]],"ltp":0.0,"tv":0.0,"id":5901},{"batb":[[0,1.08,7.81],[1,1.07,7.81],[2,1.06,7.81]],"ltp":0.0,"tv":0.0,"id":31372}]}]}
{"op":"mcm","clk":"11783110849","pt":1722784936642,"mc":[{"id":"1.231431354","rc":[{"batb":[[0,1.09,95.17],[1,1.08,7.81],[2,1.07,7.81]],"ltp":0.0,"tv":0.0,"id":5901},{"batb":[[0,1.09,95.17],[1,1.08,7.81],[2,1.07,7.81]],"ltp":0.0,"tv":0.0,"id":31372}]}]}
{"op":"mcm","clk":"11783433023","pt":1722786736982,"mc":[{"id":"1.231431354","rc":[{"batb":[[0,1.08,7.81],[1,1.07,7.81],[2,1.06,7.81]],"ltp":0.0,"tv":0.0,"id":5901},{"batb":[[0,1.08,7.81],[1,1.07,7.81],[2,1.06,7.81]],"ltp":0.0,"tv":0.0,"id":31372}]}]}
{"op":"mcm","clk":"11783451721","pt":1722786853933,"mc":[{"id":"1.231431354","rc":[{"batb":[[0,1.09,95.17],[1,1.08,7.81],[2,1.07,7.81]],"ltp":0.0,"tv":0.0,"id":5901},{"batb":[[0,1.09,95.17],[1,1.08,7.81],[2,1.07,7.81]],"ltp":0.0,"tv":0.0,"id":31372}]}]}
{"op":"mcm","clk":"11783765321","pt":1722788654340,"mc":[{"id":"1.231431354","rc":[{"batb":[[0,1.08,7.81],[1,1.07,7.81],[2,1.06,7.81]],"ltp":0.0,"tv":0.0,"id":5901},{"batb":[[0,1.08,7.81],[1,1.07,7.81],[2,1.06,7.81]],"ltp":0.0,"tv":0.0,"id":31372}]}]}
{"op":"mcm","clk":"11783775557","pt":1722788717305,"mc":[{"id":"1.231431354","rc":[{"batb":[[0,1.09,95.17],[1,1.08,7.81],[2,1.07,7.81]],"ltp":0.0,"tv":0.0,"id":5901},{"batb":[[0,1.09,95.17],[1,1.08,7.81],[2,1.07,7.81]],"ltp":0.0,"tv":0.0,"id":31372}]}]}
{"op":"mcm","clk":"11784056861","pt":1722790517795,"mc":[{"id":"1.231431354","rc":[{"batb":[[0,1.08,7.81],[1,1.07,7.81],[2,1.06,7.81]],"ltp":0.0,"tv":0.0,"id":5901},{"batb":[[0,1.08,7.81],[1,1.07,7.81],[2,1.06,7.81]],"ltp":0.0,"tv":0.0,"id":31372}]}]}
{"op":"mcm","clk":"11784059720","pt":1722790536387,"mc":[{"id":"1.231431354","rc":[{"batb":[[0,1.09,95.17],[1,1.08,7.81],[2,1.07,7.81]],"ltp":0.0,"tv":0.0,"id":5901},{"batb":[[0,1.09,95.17],[1,1.08,7.81],[2,1.07,7.81]],"ltp":0.0,"tv":0.0,"id":31372}]}]}
{"op":"mcm","clk":"11784248539","pt":1722791737323,"mc":[{"id":"1.231431354","rc":[{"batb":[[0,2.04,4.26],[1,1.09,95.17],[2,1.08,7.81]],"ltp":0.0,"tv":0.0,"id":5901},{"batb":[[0,1.88,5.03],[1,1.09,95.17],[2,1.08,7.81]],"ltp":0.0,"tv":0.0,"id":31372}]}]}
{"op":"mcm","clk":"11784344487","pt":1722792336793,"mc":[{"id":"1.231431354","rc":[{"batb":[[1,1.08,7.81],[2,1.07,7.81]],"ltp":0.0,"tv":0.0,"id":5901},{"batb":[[1,1.08,7.81],[2,1.07,7.81]],"ltp":0.0,"tv":0.0,"id":31372}]}]}
{"op":"mcm","clk":"11784540143","pt":1722793617499,"mc":[{"id":"1.231431354","rc":[{"batb":[[1,1.18,277.78],[2,1.13,384.62]],"ltp":0.0,"tv":0.0,"id":5901},{"batb":[[1,1.13,384.62],[2,1.08,7.81]],"ltp":0.0,"tv":0.0,"id":31372}]}]}
{"op":"mcm","clk":"11784540219","pt":1722793617877,"mc":[{"id":"1.231431354","rc":[{"batb":[[1,1.38,131.58],[2,1.33,151.52]],"ltp":0.0,"tv":0.0,"id":5901},{"batb":[[1,1.38,131.58],[2,1.33,151.52]],"ltp":0.0,"tv":0.0,"id":31372}]}]}
{"op":"mcm","clk":"11785011020","pt":1722796756923,"mc":[{"id":"1.231431354","rc":[{"batb":[[1,1.8,37.5],[2,1.38,131.58]],"ltp":0.0,"tv":0.0,"id":31372}]}]}
{"op":"mcm","clk":"11785011824","pt":1722796762331,"mc":[{"id":"1.231431354","rc":[{"batl":[[0,2,30]],"ltp":0.0,"tv":0.0,"id":31372}]}]}
{"op":"mcm","clk":"11785663692","pt":1722800862560,"mc":[{"id":"1.231431354","rc":[{"batb":[[1,1.38,131.58],[2,1.33,151.52]],"ltp":0.0,"tv":0.0,"id":31372}]}]}
{"op":"mcm","clk":"11786744422","pt":1722813126589,"mc":[{"id":"1.231431354","rc":[{"batb":[[1,1.66,267],[2,1.38,131.58]],"ltp":0.0,"tv":0.0,"id":31372}]}]}
{"op":"mcm","clk":"11786745365","pt":1722813145303,"mc":[{"id":"1.231431354","rc":[{"batb":[[1,1.5,252],[2,1.38,131.58]],"ltp":0.0,"tv":0.0,"id":5901}]}]}
{"op":"mcm","clk":"11786807917","pt":1722814457462,"mc":[{"id":"1.231431354","rc":[{"batl":[[0,2.5,8.86]],"ltp":0.0,"tv":0.0,"id":5901},{"batb":[[1,1.67,13.36],[2,1.66,267]],"ltp":0.0,"tv":0.0,"id":31372}]}]}
{"op":"mcm","clk":"11786808584","pt":1722814471200,"mc":[{"id":"1.231431354","rc":[{"batb":[[1,1.51,12.58],[2,1.5,252]],"ltp":0.0,"tv":0.0,"id":5901},{"batl":[[0,2.98,6.4]],"ltp":0.0,"tv":0.0,"id":31372}]}]}
{"op":"mcm","clk":"11786821403","pt":1722814760323,"mc":[{"id":"1.231431354","rc":[{"batb":[[1,1.52,252],[2,1.51,12.58]],"ltp":0.0,"tv":0.0,"id":5901},{"batb":[[1,1.68,267],[2,1.67,13.36]],"ltp":0.0,"tv":0.0,"id":31372}]}]}
{"op":"mcm","clk":"11786821452","pt":1722814761506,"mc":[{"id":"1.231431354","rc":[{"batb":[[2,1.38,131.58]],"ltp":0.0,"tv":0.0,"id":5901},{"batb":[[2,1.38,131.58]],"ltp":0.0,"tv":0.0,"id":31372}]}]}
{"op":"mcm","clk":"11786869473","pt":1722816082613,"mc":[{"id":"1.231431354","rc":[{"batb":[[1,1.53,12.58],[2,1.52,252]],"batl":[[0,2.46,9.09]],"ltp":0.0,"tv":0.0,"id":5901},{"batb":[[1,1.69,13.36],[2,1.68,267]],"batl":[[0,2.92,6.61]],"ltp":0.0,"tv":0.0,"id":31372}]}]}
{"op":"mcm","clk":"11787066309","pt":1722822174887,"mc":[{"id":"1.231431354","rc":[{"batb":[[1,1.53,12.6]],"batl":[[0,2.46,9.1]],"ltp":0.0,"tv":0.0,"id":5901},{"batb":[[1,1.69,13.37]],"batl":[[0,2.92,6.62]],"ltp":0.0,"tv":0.0,"id":31372}]}]}
{"op":"mcm","clk":"11787097470","pt":1722823170108,"mc":[{"id":"1.231431354","rc":[{"batb":[[0,1.53,12.6],[1,1.52,252],[2,1.38,131.58]],"ltp":0.0,"tv":0.0,"id":5901},{"batb":[[0,1.69,13.37],[1,1.68,267],[2,1.38,131.58]],"ltp":0.0,"tv":0.0,"id":31372}]}]}
{"op":"mcm","clk":"11787098019","pt":1722823193322,"mc":[{"id":"1.231431354","rc":[{"batb":[[0,1.54,15.89],[1,1.53,12.6],[2,1.52,252]],"ltp":0.0,"tv":0.0,"id":5901},{"batb":[[0,1.7,12.26],[1,1.69,13.37],[2,1.68,267]],"ltp":0.0,"tv":0.0,"id":31372}]}]}
{"op":"mcm","clk":"11787098044","pt":1722823194533,"mc":[{"id":"1.231431354","rc":[{"batb":[[1,1.52,252],[2,1.38,131.58]],"ltp":0.0,"tv":0.0,"id":5901},{"batb":[[1,1.68,267],[2,1.38,131.58]],"ltp":0.0,"tv":0.0,"id":31372}]}]}
{"op":"mcm","clk":"11787098353","pt":1722823208324,"mc":[{"id":"1.231431354","rc":[{"batb":[[0,1.54,15.89]],"ltp":0.0,"tv":0.0,"id":5901},{"batb":[[0,1.7,12.26]],"ltp":0.0,"tv":0.0,"id":31372}]}]}
{"op":"mcm","clk":"11787098375","pt":1722823209505,"mc":[{"id":"1.231431354","rc":[{"batl":[[0,2.46,8.88]],"ltp":0.0,"tv":0.0,"id":5901}]}]}
{"op":"mcm","clk":"11787135839","pt":1722824505504,"mc":[{"id":"1.231431354","rc":[{"batb":[[1,1.69,7.43],[2,1.68,267]],"ltp":0.0,"tv":0.0,"id":31372}]}]}
{"op":"mcm","clk":"11787135850","pt":1722824505709,"mc":[{"id":"1.231431354","rc":[{"batb":[[1,1.53,7.38],[2,1.52,252]],"ltp":0.0,"tv":0.0,"id":5901}]}]}
{"op":"mcm","clk":"11787151299","pt":1722824994501,"mc":[{"id":"1.231431354","rc":[{"batb":[[0,1.53,20.12],[1,1.52,252],[2,1.38,131.58]],"ltp":0.0,"tv":0.0,"id":5901},{"batb":[[0,1.69,21.54],[1,1.68,267],[2,1.38,131.58]],"batl":[[0,2.92,6.59]],"ltp":0.0,"tv":0.0,"id":31372}]}]}
{"op":"mcm","clk":"11787152812","pt":1722825042686,"mc":[{"id":"1.231431354","rc":[{"batb":[[0,1.54,15.89],[1,1.53,20.12],[2,1.52,252]],"ltp":0.0,"tv":0.0,"id":5901},{"batb":[[0,1.7,12.26],[1,1.69,21.54],[2,1.68,267]],"ltp":0.0,"tv":0.0,"id":31372}]}]}
{"op":"mcm","clk":"11787161268","pt":1722825361215,"mc":[{"id":"1.231431354","rc":[{"batb":[[0,2.04,4.26],[1,1.54,15.89],[2,1.53,20.12]],"ltp":0.0,"tv":0.0,"id":5901},{"batb":[[0,1.88,5.03],[1,1.7,12.26],[2,1.69,21.54]],"ltp":0.0,"tv":0.0,"id":31372}]}]}
{"op":"mcm","clk":"11787161345","pt":1722825362909,"mc":[{"id":"1.231431354","rc":[{"batb":[[2,1.53,7.38]],"ltp":0.0,"tv":0.0,"id":5901},{"batb":[[2,1.69,7.43]],"ltp":0.0,"tv":0.0,"id":31372}]}]}
{"op":"mcm","clk":"11787184111","pt":1722826038283,"mc":[{"id":"1.231431354","rc":[{"batb":[[2,1.52,252]],"ltp":0.0,"tv":0.0,"id":5901},{"batb":[[2,1.68,267]],"ltp":0.0,"tv":0.0,"id":31372}]}]}
{"op":"mcm","clk":"11787204136","pt":1722826843476,"mc":[{"id":"1.231431354","rc":[{"batb":[[1,1.53,12.58]],"batl":[[0,2.46,9.1]],"ltp":0.0,"tv":0.0,"id":5901},{"batb":[[1,1.69,13.36]],"batl":[[0,2.92,6.61]],"ltp":0.0,"tv":0.0,"id":31372}]}]}
{"op":"mcm","clk":"11787336344","pt":1722832974897,"mc":[{"id":"1.231431354","rc":[{"batb":[[1,1.53,12.59]],"batl":[[0,2.46,9.1]],"ltp":0.0,"tv":0.0,"id":5901},{"batb":[[1,1.69,13.37]],"batl":[[0,2.92,6.62]],"ltp":0.0,"tv":0.0,"id":31372}]}]}
{"op":"mcm","clk":"11787430036","pt":1722838374863,"mc":[{"id":"1.231431354","rc":[{"batb":[[1,1.53,12.61]],"batl":[[0,2.46,9.12]],"ltp":0.0,"tv":0.0,"id":5901},{"batb":[[1,1.69,13.39]],"batl":[[0,2.92,6.63]],"ltp":0.0,"tv":0.0,"id":31372}]}]}
{"op":"mcm","clk":"11787566344","pt":1722843774918,"mc":[{"id":"1.231431354","rc":[{"batb":[[1,1.53,12.62]],"batl":[[0,2.46,9.12]],"ltp":0.0,"tv":0.0,"id":5901},{"batb":[[1,1.69,13.4]],"batl":[[0,2.92,6.63]],"ltp":0.0,"tv":0.0,"id":31372}]}]}
{"op":"mcm","clk":"11787777238","pt":1722849174880,"mc":[{"id":"1.231431354","rc":[{"batb":[[1,1.53,12.65]],"batl":[[0,2.46,9.15]],"ltp":0.0,"tv":0.0,"id":5901},{"batb":[[1,1.69,13.43]],"batl":[[0,2.92,6.65]],"ltp":0.0,"tv":0.0,"id":31372}]}]}
{"op":"mcm","clk":"11787938598","pt":1722852002379,"mc":[{"id":"1.231431354","rc":[{"batb":[[0,2.04,42.64]],"ltp":0.0,"tv":0.0,"id":5901},{"batb":[[0,1.88,50.39]],"ltp":0.0,"tv":0.0,"id":31372}]}]}
{"op":"mcm","clk":"11787938770","pt":1722852004450,"mc":[{"id":"1.231431354","rc":[{"batb":[[1,1.52,252],[2,1.38,131.58]],"ltp":0.0,"tv":0.0,"id":5901},{"batb":[[1,1.68,267],[2,1.38,131.58]],"ltp":0.0,"tv":0.0,"id":31372}]}]}
{"op":"mcm","clk":"11788958272","pt":1722867709707,"mc":[{"id":"1.231431354","rc":[{"batb":[[0,2.04,36.91]],"ltp":0.0,"tv":0.0,"id":5901},{"batb":[[0,1.88,43.62]],"ltp":0.0,"tv":0.0,"id":31372}]}]}
{"op":"mcm","clk":"11790622181","pt":1722884020109,"mc":[{"id":"1.231431354","rc":[{"batb":[[1,1.74,17.32],[2,1.52,252]],"ltp":0.0,"tv":0.0,"id":5901},{"batb":[[1,1.74,17.32],[2,1.68,267]],"ltp":0.0,"tv":0.0,"id":31372}]}]}
{"op":"mcm","clk":"11790632740","pt":1722884118832,"mc":[{"id":"1.231431354","rc":[{"batb":[[1,1.8,37.5],[2,1.74,17.32]],"ltp":0.0,"tv":0.0,"id":31372}]}]}
{"op":"mcm","clk":"11790633521","pt":1722884126053,"mc":[{"id":"1.231431354","rc":[{"batl":[[0,1.97,30]],"ltp":0.0,"tv":0.0,"id":31372}]}]}
{"op":"mcm","clk":"11790720562","pt":1722885022204,"mc":[{"id":"1.231431354","rc":[{"trd":[[1.88,27.38]],"batb":[[0,1.88,29.93]],"ltp":1.88,"tv":27.37,"id":31372}],"tv":27.37}]}
{"op":"mcm","clk":"11790720667","pt":1722885023297,"mc":[{"id":"1.231431354","rc":[{"batb":[[0,1.88,43.62]],"ltp":1.88,"tv":27.37,"id":31372}]}]}
{"op":"mcm","clk":"11791232611","pt":1722892374855,"mc":[{"id":"1.231431354","rc":[{"trd":[[1.88,27.36]],"ltp":1.88,"tv":27.35,"id":31372}],"tv":27.35}]}
{"op":"mcm","clk":"11791412378","pt":1722897774872,"mc":[{"id":"1.231431354","rc":[{"trd":[[1.88,27.36]],"ltp":1.88,"tv":27.36,"id":31372}],"tv":27.36}]}
{"op":"mcm","clk":"11791632156","pt":1722903174901,"mc":[{"id":"1.231431354","rc":[{"trd":[[1.88,27.34]],"ltp":1.88,"tv":27.33,"id":31372}],"tv":27.33}]}
{"op":"mcm","clk":"11791909479","pt":1722908574884,"mc":[{"id":"1.231431354","rc":[{"trd":[[1.88,27.33]],"ltp":1.88,"tv":27.32,"id":31372}],"tv":27.32}]}
{"op":"mcm","clk":"11792131737","pt":1722913974920,"mc":[{"id":"1.231431354","rc":[{"trd":[[1.88,27.34]],"ltp":1.88,"tv":27.34,"id":31372}],"tv":27.34}]}
{"op":"mcm","clk":"11792312141","pt":1722919374894,"mc":[{"id":"1.231431354","rc":[{"trd":[[1.88,27.34]],"ltp":1.88,"tv":27.34,"id":31372}],"tv":27.34}]}
{"op":"mcm","clk":"11792444321","pt":1722924774880,"mc":[{"id":"1.231431354","rc":[{"trd":[[1.88,27.36]],"ltp":1.88,"tv":27.35,"id":31372}],"tv":27.35}]}
{"op":"mcm","clk":"11792581579","pt":1722930174913,"mc":[{"id":"1.231431354","rc":[{"trd":[[1.88,27.37]],"ltp":1.88,"tv":27.37,"id":31372}],"tv":27.37}]}
{"op":"mcm","clk":"11792759027","pt":1722935574889,"mc":[{"id":"1.231431354","rc":[{"trd":[[1.88,27.4]],"ltp":1.88,"tv":27.39,"id":31372}],"tv":27.39}]}
{"op":"mcm","clk":"11792945746","pt":1722939089824,"mc":[{"id":"1.231431354","rc":[{"batb":[[0,1.74,17.32],[1,1.52,252],[2,1.25,100]],"ltp":0.0,"tv":0.0,"id":5901},{"trd":[[1.88,27.42]],"batb":[[0,1.8,37.5],[1,1.74,17.32],[2,1.68,267]],"ltp":1.88,"tv":27.42,"id":31372}],"tv":27.42}]}
{"op":"mcm","clk":"11793090619","pt":1722941071427,"mc":[{"id":"1.231431354","rc":[{"batb":[[0,2.04,36.91],[1,1.74,17.32],[2,1.52,252]],"ltp":0.0,"tv":0.0,"id":5901},{"batb":[[0,1.88,43.62],[1,1.8,37.5],[2,1.74,17.32]],"ltp":1.88,"tv":27.42,"id":31372}]}]}
{"op":"mcm","clk":"11793479596","pt":1722946374872,"mc":[{"id":"1.231431354","rc":[{"trd":[[1.88,27.44]],"ltp":1.88,"tv":27.43,"id":31372}],"tv":27.43}]}
{"op":"mcm","clk":"11793489249","pt":1722946471979,"mc":[{"id":"1.231431354","rc":[{"batb":[[2,1.25,100]],"ltp":0.0,"tv":0.0,"id":5901}]}]}
{"op":"mcm","clk":"11793788150","pt":1722951774881,"mc":[{"id":"1.231431354","rc":[{"trd":[[1.88,27.46]],"ltp":1.88,"tv":27.45,"id":31372}],"tv":27.45}]}
{"op":"mcm","clk":"11793895005","pt":1722954111374,"mc":[{"id":"1.231431354","rc":[{"batb":[[0,2.04,36.36]],"ltp":0.0,"tv":0.0,"id":5901},{"trd":[[1.88,27.43]],"batb":[[0,1.88,42.98]],"ltp":1.88,"tv":27.43,"id":31372}],"tv":27.43}]}
{"op":"mcm","clk":"11794042977","pt":1722957174865,"mc":[{"id":"1.231431354","rc":[{"trd":[[1.88,27.42]],"ltp":1.88,"tv":27.41,"id":31372}],"tv":27.41}]}
{"op":"mcm","clk":"11794276950","pt":1722960943351,"mc":[{"id":"1.231431354","rc":[{"batb":[[2,1.08,7.88]],"ltp":0.0,"tv":0.0,"id":5901},{"trd":[[1.88,27.44]],"ltp":1.88,"tv":27.43,"id":31372}],"tv":27.43}]}
{"op":"mcm","clk":"11794287138","pt":1722961083466,"mc":[{"id":"1.231431354","rc":[{"batb":[[2,1.23,217.39]],"ltp":0.0,"tv":0.0,"id":5901}]}]}
{"op":"mcm","clk":"11794287175","pt":1722961083833,"mc":[{"id":"1.231431354","rc":[{"batb":[[2,1.48,104.17]],"ltp":0.0,"tv":0.0,"id":5901}]}]}
{"op":"mcm","clk":"11794652404","pt":1722966159987,"mc":[{"id":"1.231431354","rc":[{"trd":[[1.88,27.42]],"batb":[[0,1.93,82.1],[1,1.88,42.98],[2,1.8,37.5]],"ltp":1.88,"tv":27.42,"id":31372}],"tv":27.42}]}
{"op":"mcm","clk":"11794654562","pt":1722966187108,"mc":[{"id":"1.231431354","rc":[{"trd":[[2.04,72.26]],"batb":[[0,1.74,17.55],[1,1.48,104.17],[2,1.43,116.28]],"ltp":2.04,"tv":72.26,"id":5901},{"batb":[[0,1.88,42.98],[1,1.8,37.5],[2,1.74,17.32]],"ltp":1.88,"tv":27.42,"id":31372}],"tv":99.68}]}
{"op":"mcm","clk":"11794654650","pt":1722966188107,"mc":[{"id":"1.231431354","rc":[{"trd":[[1.97,59.68]],"batl":[[0,1.97,0.16]],"ltp":1.97,"tv":87.1,"id":31372}],"tv":159.36}]}
{"op":"mcm","clk":"11794654904","pt":1722966191230,"mc":[{"id":"1.231431354","rc":[{"batb":[[0,1.99,10],[1,1.98,38.59],[2,1.74,17.32]],"batl":[[0,2.1,24.84]],"ltp":2.04,"tv":72.26,"id":5901}]}]}
{"op":"mcm","clk":"11794655167","pt":1722966194523,"mc":[{"id":"1.231431354","rc":[{"batb":[[0,1.98,38.59],[1,1.74,17.32],[2,1.48,104.17]],"ltp":2.04,"tv":72.26,"id":5901}]}]}
{"op":"mcm","clk":"11794789183","pt":1722967680686,"mc":[{"id":"1.231431354","rc":[{"batb":[[0,1.99,10],[1,1.98,38.59],[2,1.74,17.32]],"ltp":2.04,"tv":72.26,"id":5901},{"trd":[[1.88,27.44]],"ltp":1.97,"tv":87.11,"id":31372}],"tv":159.37}]}
{"op":"mcm","clk":"11794789627","pt":1722967684392,"mc":[{"id":"1.231431354","rc":[{"batb":[[0,1.98,38.59],[1,1.74,17.32],[2,1.48,104.17]],"ltp":2.04,"tv":72.26,"id":5901}]}]}
{"op":"mcm","clk":"11794898852","pt":1722968657277,"mc":[{"id":"1.231431354","rc":[{"batb":[[0,1.99,10],[1,1.98,38.59],[2,1.74,17.32]],"ltp":2.04,"tv":72.26,"id":5901}]}]}
{"op":"mcm","clk":"11794899146","pt":1722968660612,"mc":[{"id":"1.231431354","rc":[{"batb":[[0,1.98,38.59],[1,1.74,17.32],[2,1.48,104.17]],"ltp":2.04,"tv":72.26,"id":5901}]}]}
{"op":"mcm","clk":"11794902904","pt":1722968703829,"mc":[{"id":"1.231431354","rc":[{"batb":[[0,1.99,10],[1,1.98,38.59],[2,1.74,17.32]],"ltp":2.04,"tv":72.26,"id":5901}]}]}
{"op":"mcm","clk":"11794903227","pt":1722968707138,"mc":[{"id":"1.231431354","rc":[{"batb":[[0,1.98,38.59],[1,1.74,17.32],[2,1.48,104.17]],"ltp":2.04,"tv":72.26,"id":5901}]}]}
{"op":"mcm","clk":"11795060618","pt":1722970221161,"mc":[{"id":"1.231431354","rc":[{"batb":[[1,1.84,37.5]],"ltp":1.97,"tv":87.11,"id":31372}]}]}
{"op":"mcm","clk":"11795061023","pt":1722970225882,"mc":[{"id":"1.231431354","rc":[{"batb":[[1,1.84,68]],"ltp":1.97,"tv":87.11,"id":31372}]}]}
{"op":"mcm","clk":"11795365049","pt":1722973374899,"mc":[{"id":"1.231431354","rc":[{"trd":[[1.88,27.43]],"ltp":1.97,"tv":87.11,"id":31372}],"tv":159.37}]}
{"op":"mcm","clk":"11795737176","pt":1722978774888,"mc":[{"id":"1.231431354","rc":[{"trd":[[1.88,27.44]],"ltp":1.97,"tv":87.11,"id":31372}],"tv":159.37}]}
{"op":"mcm","clk":"11795779386","pt":1722979616849,"mc":[{"id":"1.231431354","rc":[{"batb":[[0,2.08,35.02]],"batl":[[0,2.16,32]],"ltp":2.04,"tv":72.26,"id":5901},{"batb":[[0,1.85,44.49]],"ltp":1.97,"tv":87.11,"id":31372}]}]}
{"op":"mcm","clk":"11795969281","pt":1722984174905,"mc":[{"id":"1.231431354","rc":[{"trd":[[1.88,27.43]],"ltp":1.97,"tv":87.11,"id":31372}],"tv":159.37}]}
{"op":"mcm","clk":"11796012293","pt":1722985327628,"mc":[{"id":"1.231431354","rc":[{"trd":[[2.08,69.88]],"batb":[[0,1.74,17.4],[1,1.48,104.17],[2,1.43,116.28]],"ltp":2.08,"tv":142.14,"id":5901},{"trd":[[1.88,27.44]],"ltp":1.97,"tv":87.11,"id":31372}],"tv":229.25}]}
{"op":"mcm","clk":"11796012381","pt":1722985330359,"mc":[{"id":"1.231431354","rc":[{"batb":[[0,1.75,10.08],[1,1.74,17.32],[2,1.48,104.17]],"batl":[[0,2.16,5.8]],"ltp":2.08,"tv":142.14,"id":5901}]}]}
{"op":"mcm","clk":"11796012469","pt":1722985332158,"mc":[{"id":"1.231431354","rc":[{"batb":[[0,2,37.82],[1,1.75,10],[2,1.74,17.32]],"ltp":2.08,"tv":142.14,"id":5901}]}]}
{"op":"mcm","clk":"11796012535","pt":1722985333541,"mc":[{"id":"1.231431354","rc":[{"batb":[[1,1.74,17.32],[2,1.48,104.17]],"ltp":2.08,"tv":142.14,"id":5901}]}]}
{"op":"mcm","clk":"11796102980","pt":1722987332900,"mc":[{"id":"1.231431354","rc":[{"trd":[[1.85,2.88]],"batb":[[0,1.85,43.05]],"ltp":1.85,"tv":89.99,"id":31372}],"tv":232.13}]}
{"op":"mcm","clk":"11796103147","pt":1722987337299,"mc":[{"id":"1.231431354","rc":[{"batb":[[0,1.85,44.49]],"ltp":1.85,"tv":89.99,"id":31372}]}]}
{"op":"mcm","clk":"11796110312","pt":1722987490997,"mc":[{"id":"1.231431354","rc":[{"batl":[[0,1.99,4.74]],"ltp":1.85,"tv":89.99,"id":31372}]}]}
{"op":"mcm","clk":"11796111174","pt":1722987508984,"mc":[{"id":"1.231431354","rc":[{"batl":[[1,2.26,4.58]],"ltp":1.85,"tv":89.99,"id":31372}]}]}
{"op":"mcm","clk":"11796111894","pt":1722987523991,"mc":[{"id":"1.231431354","rc":[{"batb":[[2,1.77,4.58]],"ltp":1.85,"tv":89.99,"id":31372}]}]}
{"op":"mcm","clk":"11796214330","pt":1722989574943,"mc":[{"id":"1.231431354","rc":[{"trd":[[1.88,27.45]],"batb":[[2,1.77,4.58]],"batl":[[0,1.99,4.74],[1,2.26,4.58]],"ltp":1.85,"tv":90.0,"id":31372}],"tv":232.14}]}
{"op":"mcm","clk":"11796436639","pt":1722994974979,"mc":[{"id":"1.231431354","rc":[{"trd":[[1.88,27.42]],"batb":[[2,1.77,4.58]],"batl":[[0,1.99,4.74],[1,2.26,4.58]],"ltp":1.85,"tv":89.98,"id":31372}],"tv":232.12}]}
{"op":"mcm","clk":"11796615584","pt":1723000374952,"mc":[{"id":"1.231431354","rc":[{"trd":[[1.88,27.42]],"batb":[[2,1.77,4.57]],"batl":[[0,1.99,4.73],[1,2.26,4.57]],"ltp":1.85,"tv":89.97,"id":31372}],"tv":232.11}]}
{"op":"mcm","clk":"11796635127","pt":1723001172005,"mc":[{"id":"1.231431354","rc":[{"batb":[[0,2.02,1],[1,2,37.82],[2,1.74,17.32]],"ltp":2.08,"tv":142.14,"id":5901},{"batb":[[0,1.86,1.09],[1,1.85,44.49],[2,1.84,68]],"ltp":1.85,"tv":89.97,"id":31372}]}]}
{"op":"mcm","clk":"11796721544","pt":1723005774958,"mc":[{"id":"1.231431354","rc":[{"trd":[[1.88,27.41]],"batl":[[0,1.99,4.73],[1,2.26,4.57]],"ltp":1.85,"tv":89.96,"id":31372}],"tv":232.1}]}
{"op":"mcm","clk":"11796786058","pt":1723008546973,"mc":[{"id":"1.231431354","rc":[{"trd":[[1.88,27.42]],"ltp":1.85,"tv":89.97,"id":31372}],"tv":232.11}]}
{"op":"mcm","clk":"11796832385","pt":1723010856075,"mc":[{"id":"1.231431354","rc":[{"trd":[[1.88,27.42]],"batl":[[0,1.99,4.74],[1,2.26,4.58]],"ltp":1.85,"tv":89.98,"id":31372}],"tv":232.12}]}
{"op":"mcm","clk":"11796853856","pt":1723011536002,"mc":[{"id":"1.231431354","rc":[{"trd":[[1.86,2.18]],"batb":[[0,1.85,44.49],[1,1.84,68],[2,1.77,4.58]],"batl":[[0,1.86,3.91],[1,1.99,4.74],[2,2.26,4.58]],"ltp":1.86,"tv":92.16,"id":31372}],"tv":234.3}]}
{"op":"mcm","clk":"11796854749","pt":1723011572131,"mc":[{"id":"1.231431354","rc":[{"trd":[[1.85,10.7]],"batb":[[0,1.85,40.58]],"batl":[[0,1.99,4.74],[1,2.26,4.58],[2,2.26,0]],"ltp":1.85,"tv":99.98,"id":31372}],"tv":242.12}]}
{"op":"mcm","clk":"11796854854","pt":1723011577259,"mc":[{"id":"1.231431354","rc":[{"batb":[[0,1.85,44.49]],"ltp":1.85,"tv":99.98,"id":31372}]}]}
{"op":"mcm","clk":"11796860318","pt":1723011778969,"mc":[{"id":"1.231431354","rc":[{"batl":[[0,1.98,2.9],[1,1.99,4.58],[2,2.26,4.58]],"ltp":1.85,"tv":99.98,"id":31372}]}]}
{"op":"mcm","clk":"11796860679","pt":1723011794186,"mc":[{"id":"1.231431354","rc":[{"batb":[[0,1.86,2.74],[1,1.85,44.49],[2,1.84,68]],"ltp":1.85,"tv":99.98,"id":31372}]}]}
{"op":"mcm","clk":"11796874843","pt":1723012453211,"mc":[{"id":"1.231431354","rc":[{"trd":[[2.02,1.28]],"batb":[[0,2,38.18],[1,1.74,17.32],[2,1.48,104.17]],"ltp":2.02,"tv":143.42,"id":5901}],"tv":243.4}]}
{"op":"mcm","clk":"11796875941","pt":1723012508665,"mc":[{"id":"1.231431354","rc":[{"batl":[[0,1.87,1.11],[1,1.98,2.9],[2,1.99,4.58]],"ltp":1.85,"tv":99.98,"id":31372}]}]}
{"op":"mcm","clk":"11796876657","pt":1723012542638,"mc":[{"id":"1.231431354","rc":[{"batl":[[0,1.98,2.9],[1,1.99,4.58],[2,2.26,4.58]],"ltp":1.85,"tv":99.98,"id":31372}]}]}
{"op":"mcm","clk":"11796876981","pt":1723012561139,"mc":[{"id":"1.231431354","rc":[{"trd":[[1.97,60]],"batb":[[0,1.86,3.7]],"batl":[[0,1.98,2.74]],"ltp":1.97,"tv":100.3,"id":31372}],"tv":243.72}]}
{"op":"mcm","clk":"11796877297","pt":1723012569368,"mc":[{"id":"1.231431354","rc":[{"batb":[[0,1.86,2.74]],"ltp":1.97,"tv":100.3,"id":31372}]}]}
{"op":"mcm","clk":"11796877524","pt":1723012579487,"mc":[{"id":"1.231431354","rc":[{"batb":[[0,1.97,1.11],[1,1.86,2.74],[2,1.85,44.49]],"ltp":1.97,"tv":100.3,"id":31372}]}]}
{"op":"mcm","clk":"11796877789","pt":1723012592765,"mc":[{"id":"1.231431354","rc":[{"batb":[[0,1.86,2.74],[1,1.85,44.49],[2,1.84,68]],"ltp":1.97,"tv":100.3,"id":31372}]}]}
{"op":"mcm","clk":"11796877964","pt":1723012602506,"mc":[{"id":"1.231431354","rc":[{"batl":[[0,1.87,1.11],[1,1.98,2.74],[2,1.99,4.58]],"ltp":1.97,"tv":100.3,"id":31372}]}]}
{"op":"mcm","clk":"11796878157","pt":1723012609590,"mc":[{"id":"1.231431354","rc":[{"trd":[[1.87,2]],"batl":[[0,1.98,2.86],[1,1.99,4.58],[2,2.26,4.58]],"ltp":1.87,"tv":102.3,"id":31372}],"tv":245.72}]}
{"op":"mcm","clk":"11796878296","pt":1723012617278,"mc":[{"id":"1.231431354","rc":[{"trd":[[1.87,2.22]],"batb":[[0,1.87,49.89],[1,1.86,2.74],[2,1.85,44.49]],"batl":[[0,1.98,2.74]],"ltp":1.87,"tv":102.52,"id":31372}],"tv":245.94}]}
{"op":"mcm","clk":"11796878541","pt":1723012631628,"mc":[{"id":"1.231431354","rc":[{"trd":[[2.02,2.51]],"batb":[[0,2,37.82]],"ltp":2.02,"tv":144.65,"id":5901},{"trd":[[1.98,0.52]],"batl":[[0,1.98,2.22]],"ltp":1.98,"tv":103.04,"id":31372}],"tv":247.7}]}
{"op":"mcm","clk":"11796878865","pt":1723012645710,"mc":[{"id":"1.231431354","rc":[{"batl":[[0,1.88,1.11],[1,1.98,2.22],[2,1.99,4.58]],"ltp":1.98,"tv":103.04,"id":31372}]}]}
{"op":"mcm","clk":"11796879114","pt":1723012658650,"mc":[{"id":"1.231431354","rc":[{"batl":[[0,1.98,2.22],[1,1.99,4.58],[2,2.26,4.58]],"ltp":1.98,"tv":103.04,"id":31372}]}]}
{"op":"mcm","clk":"11796879379","pt":1723012670036,"mc":[{"id":"1.231431354","rc":[{"batb":[[0,1.96,1.11],[1,1.87,49.89],[2,1.86,2.74]],"ltp":1.98,"tv":103.04,"id":31372}]}]}
{"op":"mcm","clk":"11796879618","pt":1723012680691,"mc":[{"id":"1.231431354","rc":[{"batb":[[0,1.87,49.89],[1,1.86,2.74],[2,1.85,44.49]],"ltp":1.98,"tv":103.04,"id":31372}]}]}
{"op":"mcm","clk":"11796879837","pt":1723012689902,"mc":[{"id":"1.231431354","rc":[{"batl":[[0,1.88,1.11],[1,1.98,2.22],[2,1.99,4.58]],"ltp":1.98,"tv":103.04,"id":31372}]}]}
{"op":"mcm","clk":"11796880048","pt":1723012700594,"mc":[{"id":"1.231431354","rc":[{"batl":[[0,1.98,2.22],[1,1.99,4.58],[2,2.26,4.58]],"ltp":1.98,"tv":103.04,"id":31372}]}]}
{"op":"mcm","clk":"11796880316","pt":1723012714496,"mc":[{"id":"1.231431354","rc":[{"batb":[[0,1.96,1.11],[1,1.87,49.89],[2,1.86,2.74]],"ltp":1.98,"tv":103.04,"id":31372}]}]}
{"op":"mcm","clk":"11796880498","pt":1723012725030,"mc":[{"id":"1.231431354","rc":[{"batb":[[0,1.87,49.89],[1,1.86,2.74],[2,1.85,44.49]],"ltp":1.98,"tv":103.04,"id":31372}]}]}
{"op":"mcm","clk":"11796880771","pt":1723012740117,"mc":[{"id":"1.231431354","rc":[{"batl":[[0,1.88,1.11],[1,1.98,2.22],[2,1.99,4.58]],"ltp":1.98,"tv":103.04,"id":31372}]}]}
{"op":"mcm","clk":"11796880986","pt":1723012750951,"mc":[{"id":"1.231431354","rc":[{"batl":[[0,1.98,2.22],[1,1.99,4.58],[2,2.26,4.58]],"ltp":1.98,"tv":103.04,"id":31372}]}]}
{"op":"mcm","clk":"11796882849","pt":1723012847544,"mc":[{"id":"1.231431354","rc":[{"batb":[[0,1.96,1.11],[1,1.87,49.89],[2,1.86,2.74]],"ltp":1.98,"tv":103.04,"id":31372}]}]}
{"op":"mcm","clk":"11796883150","pt":1723012861848,"mc":[{"id":"1.231431354","rc":[{"batb":[[0,1.87,49.89],[1,1.86,2.74],[2,1.85,44.49]],"ltp":1.98,"tv":103.04,"id":31372}]}]}
{"op":"mcm","clk":"11796883399","pt":1723012874745,"mc":[{"id":"1.231431354","rc":[{"batl":[[0,1.88,1.11],[1,1.98,2.22],[2,1.99,4.58]],"ltp":1.98,"tv":103.04,"id":31372}]}]}
{"op":"mcm","clk":"11796883903","pt":1723012898073,"mc":[{"id":"1.231431354","rc":[{"batl":[[0,1.98,2.22],[1,1.99,4.58],[2,2.26,4.58]],"ltp":1.98,"tv":103.04,"id":31372}]}]}
{"op":"mcm","clk":"11796884373","pt":1723012921135,"mc":[{"id":"1.231431354","rc":[{"batb":[[0,1.97,1.11],[1,1.87,49.89],[2,1.86,2.74]],"ltp":1.98,"tv":103.04,"id":31372}]}]}
{"op":"mcm","clk":"11796884720","pt":1723012935916,"mc":[{"id":"1.231431354","rc":[{"batb":[[0,1.87,49.89],[1,1.86,2.74],[2,1.85,44.49]],"ltp":1.98,"tv":103.04,"id":31372}]}]}
{"op":"mcm","clk":"11796885109","pt":1723012954033,"mc":[{"id":"1.231431354","rc":[{"batl":[[0,1.88,1.11],[1,1.98,2.22],[2,1.99,4.58]],"ltp":1.98,"tv":103.04,"id":31372}]}]}
{"op":"mcm","clk":"11796885345","pt":1723012967557,"mc":[{"id":"1.231431354","rc":[{"batl":[[0,1.98,2.22],[1,1.99,4.58],[2,2.26,4.58]],"ltp":1.98,"tv":103.04,"id":31372}]}]}
{"op":"mcm","clk":"11796885534","pt":1723012974472,"mc":[{"id":"1.231431354","rc":[{"batb":[[0,1.97,1.11],[1,1.87,49.89],[2,1.86,2.74]],"ltp":1.98,"tv":103.04,"id":31372}]}]}
{"op":"mcm","clk":"11796885774","pt":1723012985760,"mc":[{"id":"1.231431354","rc":[{"batb":[[0,1.87,49.89],[1,1.86,2.74],[2,1.85,44.49]],"ltp":1.98,"tv":103.04,"id":31372}]}]}
{"op":"mcm","clk":"11796886003","pt":1723012993760,"mc":[{"id":"1.231431354","rc":[{"batb":[[0,1.97,1.11],[1,1.87,49.89],[2,1.86,2.74]],"ltp":1.98,"tv":103.04,"id":31372}]}]}
{"op":"mcm","clk":"11796886361","pt":1723013009906,"mc":[{"id":"1.231431354","rc":[{"batb":[[0,1.87,49.89],[1,1.86,2.74],[2,1.85,44.49]],"ltp":1.98,"tv":103.04,"id":31372}]}]}
{"op":"mcm","clk":"11796886730","pt":1723013028000,"mc":[{"id":"1.231431354","rc":[{"batl":[[0,1.88,1.11],[1,1.98,2.22],[2,1.99,4.58]],"ltp":1.98,"tv":103.04,"id":31372}]}]}
{"op":"mcm","clk":"11796887002","pt":1723013043413,"mc":[{"id":"1.231431354","rc":[{"batl":[[0,1.98,2.22],[1,1.99,4.58],[2,2.26,4.58]],"ltp":1.98,"tv":103.04,"id":31372}]}]}
{"op":"mcm","clk":"11796887162","pt":1723013052251,"mc":[{"id":"1.231431354","rc":[{"batb":[[0,1.97,1.11],[1,1.87,49.89],[2,1.86,2.74]],"ltp":1.98,"tv":103.04,"id":31372}]}]}
{"op":"mcm","clk":"11796887372","pt":1723013065564,"mc":[{"id":"1.231431354","rc":[{"batb":[[0,1.87,49.89],[1,1.86,2.74],[2,1.85,44.49]],"ltp":1.98,"tv":103.04,"id":31372}]}]}
{"op":"mcm","clk":"11796888052","pt":1723013095115,"mc":[{"id":"1.231431354","rc":[{"batl":[[0,1.88,1.11],[1,1.98,2.22],[2,1.99,4.58]],"ltp":1.98,"tv":103.04,"id":31372}]}]}
{"op":"mcm","clk":"11796888352","pt":1723013110348,"mc":[{"id":"1.231431354","rc":[{"batl":[[0,1.98,2.22],[1,1.99,4.58],[2,2.26,4.58]],"ltp":1.98,"tv":103.04,"id":31372}]}]}
{"op":"mcm","clk":"11796888376","pt":1723013111939,"mc":[{"id":"1.231431354","rc":[{"batb":[[0,1.88,1.57],[1,1.87,49.89],[2,1.86,2.74]],"ltp":1.98,"tv":103.04,"id":31372}]}]}
{"op":"mcm","clk":"11796888409","pt":1723013113537,"mc":[{"id":"1.231431354","rc":[{"batb":[[0,1.87,49.89],[1,1.86,2.74],[2,1.85,44.49]],"ltp":1.98,"tv":103.04,"id":31372}]}]}
{"op":"mcm","clk":"11796888590","pt":1723013122150,"mc":[{"id":"1.231431354","rc":[{"batb":[[0,1.97,1.11],[1,1.87,49.89],[2,1.86,2.74]],"ltp":1.98,"tv":103.04,"id":31372}]}]}
{"op":"mcm","clk":"11796888624","pt":1723013124355,"mc":[{"id":"1.231431354","rc":[{"trd":[[1.97,61.57]],"batb":[[0,1.87,50.22],[1,1.86,2.74],[2,1.85,44.49]],"ltp":1.97,"tv":104.62,"id":31372}],"tv":249.27}]}
{"op":"mcm","clk":"11796888704","pt":1723013128249,"mc":[{"id":"1.231431354","rc":[{"batb":[[0,1.88,1.11],[1,1.87,49.89],[2,1.86,2.74]],"ltp":1.97,"tv":104.62,"id":31372}]}]}
{"op":"mcm","clk":"11796888833","pt":1723013135468,"mc":[{"id":"1.231431354","rc":[{"batb":[[0,1.87,50.68],[1,1.86,2.74],[2,1.85,44.49]],"ltp":1.97,"tv":104.62,"id":31372}]}]}
{"op":"mcm","clk":"11796889534","pt":1723013170579,"mc":[{"id":"1.231431354","rc":[{"trd":[[1.87,2.3],[1.88,29]],"batb":[[0,1.87,49.85]],"ltp":1.87,"tv":106.27,"id":31372}],"tv":250.92}]}
{"op":"mcm","clk":"11796889850","pt":1723013182403,"mc":[{"id":"1.231431354","rc":[{"batb":[[0,1.87,49.89]],"batl":[[0,1.89,1.11],[1,1.98,2.22],[2,1.99,4.58]],"ltp":1.87,"tv":106.27,"id":31372}]}]}
{"op":"mcm","clk":"11796890125","pt":1723013195113,"mc":[{"id":"1.231431354","rc":[{"batl":[[0,1.98,2.22],[1,1.99,4.58],[2,2.26,4.58]],"ltp":1.87,"tv":106.27,"id":31372}]}]}
{"op":"mcm","clk":"11796890783","pt":1723013224830,"mc":[{"id":"1.231431354","rc":[{"batb":[[0,1.96,1.11],[1,1.87,49.89],[2,1.86,2.74]],"ltp":1.87,"tv":106.27,"id":31372}]}]}
{"op":"mcm","clk":"11796891006","pt":1723013238256,"mc":[{"id":"1.231431354","rc":[{"batb":[[0,1.87,49.89],[1,1.86,2.74],[2,1.85,44.49]],"ltp":1.87,"tv":106.27,"id":31372}]}]}
{"op":"mcm","clk":"11796891396","pt":1723013256513,"mc":[{"id":"1.231431354","rc":[{"batl":[[0,1.89,1.11],[1,1.98,2.22],[2,1.99,4.58]],"ltp":1.87,"tv":106.27,"id":31372}]}]}
{"op":"mcm","clk":"11796891736","pt":1723013270304,"mc":[{"id":"1.231431354","rc":[{"batl":[[0,1.98,2.22],[1,1.99,4.58],[2,2.26,4.58]],"ltp":1.87,"tv":106.27,"id":31372}]}]}
{"op":"mcm","clk":"11796892037","pt":1723013281718,"mc":[{"id":"1.231431354","rc":[{"batb":[[0,1.96,1.11],[1,1.87,49.89],[2,1.86,2.74]],"ltp":1.87,"tv":106.27,"id":31372}]}]}
{"op":"mcm","clk":"11796892328","pt":1723013294943,"mc":[{"id":"1.231431354","rc":[{"batb":[[0,1.87,49.89],[1,1.86,2.74],[2,1.85,44.49]],"ltp":1.87,"tv":106.27,"id":31372}]}]}
{"op":"mcm","clk":"11796892749","pt":1723013313662,"mc":[{"id":"1.231431354","rc":[{"batl":[[0,1.89,1.11],[1,1.98,2.22],[2,1.99,4.58]],"ltp":1.87,"tv":106.27,"id":31372}]}]}
{"op":"mcm","clk":"11796893015","pt":1723013325285,"mc":[{"id":"1.231431354","rc":[{"batl":[[0,1.98,2.22],[1,1.99,4.58],[2,2.26,4.58]],"ltp":1.87,"tv":106.27,"id":31372}]}]}
{"op":"mcm","clk":"11796904695","pt":1723013801963,"mc":[{"id":"1.231431354","rc":[{"batl":[[1,1.99,9.58]],"ltp":1.87,"tv":106.27,"id":31372}]}]}
{"op":"mcm","clk":"11796955235","pt":1723015373702,"mc":[{"id":"1.231431354","rc":[{"trd":[[2.02,2.51]],"ltp":2.02,"tv":144.65,"id":5901},{"trd":[[1.88,29.06],[1.97,61.57]],"batb":[[0,1.87,49.85],[1,1.86,2.74]],"batl":[[0,1.88,1.07],[1,1.98,2.22],[2,1.99,9.57]],"ltp":1.88,"tv":106.33,"id":31372}],"tv":250.99}]}
{"op":"mcm","clk":"11796955828","pt":1723015390610,"mc":[{"id":"1.231431354","rc":[{"batl":[[0,1.98,2.22],[1,1.99,9.57],[2,2.26,4.57]],"ltp":1.88,"tv":106.33,"id":31372}]}]}
{"op":"mcm","clk":"11796957765","pt":1723015440091,"mc":[{"id":"1.231431354","rc":[{"batb":[[0,1.97,1.11],[1,1.87,49.85],[2,1.86,2.74]],"ltp":1.88,"tv":106.33,"id":31372}]}]}
{"op":"mcm","clk":"11796958503","pt":1723015459008,"mc":[{"id":"1.231431354","rc":[{"batb":[[0,1.87,49.85],[1,1.86,2.74],[2,1.85,44.49]],"ltp":1.88,"tv":106.33,"id":31372}]}]}
{"op":"mcm","clk":"11796959443","pt":1723015485820,"mc":[{"id":"1.231431354","rc":[{"batl":[[0,1.88,1.11],[1,1.98,2.22],[2,1.99,9.57]],"ltp":1.88,"tv":106.33,"id":31372}]}]}
{"op":"mcm","clk":"11796959846","pt":1723015497466,"mc":[{"id":"1.231431354","rc":[{"batl":[[0,1.88,101.11]],"ltp":1.88,"tv":106.33,"id":31372}]}]}
{"op":"mcm","clk":"11796959856","pt":1723015497672,"mc":[{"id":"1.231431354","rc":[{"batl":[[0,1.88,100]],"ltp":1.88,"tv":106.33,"id":31372}]}]}
{"op":"mcm","clk":"11796989596","pt":1723016315580,"mc":[{"id":"1.231431354","rc":[{"batl":[[2,1.99,5]],"ltp":1.88,"tv":106.33,"id":31372}]}]}
{"op":"mcm","clk":"11797043306","pt":1723017607310,"mc":[{"id":"1.231431354","rc":[{"trd":[[2.02,2.51]],"batb":[[0,2.1,16.42],[1,2,37.82],[2,1.74,17.32]],"ltp":2.02,"tv":144.65,"id":5901},{"trd":[[1.87,2.3],[1.88,29.09],[1.97,61.58]],"batb":[[1,1.86,23.75]],"batl":[[1,1.98,2.22]],"ltp":1.88,"tv":106.36,"id":31372}],"tv":251.02}]}
{"op":"mcm","clk":"11797049095","pt":1723017738844,"mc":[{"id":"1.231431354","rc":[{"trd":[[1.85,63.48],[1.86,49.69],[1.87,102]],"batb":[[0,1.85,18.1],[1,1.84,68],[2,1.74,17.32]],"ltp":1.85,"tv":306.35,"id":31372}],"tv":451.01}]}
{"op":"mcm","clk":"11797049129","pt":1723017739882,"mc":[{"id":"1.231431354","rc":[{"batb":[[1,1.84,89.51]],"ltp":1.85,"tv":306.35,"id":31372}]}]}
{"op":"mcm","clk":"11797049309","pt":1723017744079,"mc":[{"id":"1.231431354","rc":[{"batb":[[0,1.85,44.49]],"ltp":1.85,"tv":306.35,"id":31372}]}]}
{"op":"mcm","clk":"11797054297","pt":1723017872417,"mc":[{"id":"1.231431354","rc":[{"trd":[[2.12,88]],"batb":[[0,2,55.88],[1,1.74,17.32],[2,1.48,104.17]],"ltp":2.12,"tv":232.65,"id":5901},{"trd":[[1.88,128.32]],"batl":[[0,1.98,2.99],[1,1.99,5],[2,2.36,4.64]],"ltp":1.88,"tv":405.58,"id":31372}],"tv":638.24}]}
{"op":"mcm","clk":"11797058220","pt":1723017963324,"mc":[{"id":"1.231431354","rc":[{"batl":[[0,1.96,5.27],[1,1.98,2.22],[2,1.99,5]],"ltp":1.88,"tv":405.58,"id":31372}]}]}
{"op":"mcm","clk":"11797058662","pt":1723017975240,"mc":[{"id":"1.231431354","rc":[{"batb":[[2,1.8,4.5]],"ltp":1.88,"tv":405.58,"id":31372}]}]}
{"op":"mcm","clk":"11797059168","pt":1723017987067,"mc":[{"id":"1.231431354","rc":[{"trd":[[1.88,129.86]],"batb":[[0,1.88,49.23],[1,1.85,44.49],[2,1.84,89.51]],"batl":[[0,1.96,4.5]],"ltp":1.88,"tv":407.12,"id":31372}],"tv":639.78}]}
{"op":"mcm","clk":"11797059194","pt":1723017987531,"mc":[{"id":"1.231431354","rc":[{"batb":[[1,1.85,65.75]],"ltp":1.88,"tv":407.12,"id":31372}]}]}
{"op":"mcm","clk":"11797059254","pt":1723017988971,"mc":[{"id":"1.231431354","rc":[{"batb":[[1,1.85,68]],"ltp":1.88,"tv":407.12,"id":31372}]}]}
{"op":"mcm","clk":"11797059282","pt":1723017989537,"mc":[{"id":"1.231431354","rc":[{"batb":[[1,1.87,20.77],[2,1.85,68]],"ltp":1.88,"tv":407.12,"id":31372}]}]}
{"op":"mcm","clk":"11797059734","pt":1723017999758,"mc":[{"id":"1.231431354","rc":[{"batb":[[1,1.95,4.5],[2,1.74,17.32]],"ltp":2.12,"tv":232.65,"id":5901}]}]}
{"op":"mcm","clk":"11797070922","pt":1723018294145,"mc":[{"id":"1.231431354","rc":[{"trd":[[1.88,132.02]],"batb":[[0,1.88,48.15]],"ltp":1.88,"tv":409.28,"id":31372}],"tv":641.94}]}
{"op":"mcm","clk":"11797075073","pt":1723018418479,"mc":[{"id":"1.231431354","rc":[{"batl":[[0,1.95,18.04],[1,1.96,4.5],[2,1.98,2.22]],"ltp":1.88,"tv":409.28,"id":31372}]}]}
{"op":"mcm","clk":"11797075135","pt":1723018420785,"mc":[{"id":"1.231431354","rc":[{"batb":[[0,2.02,17.71],[1,2,55.88],[2,1.95,4.5]],"ltp":2.12,"tv":232.65,"id":5901}]}]}
{"op":"mcm","clk":"11797099890","pt":1723019115302,"mc":[{"id":"1.231431354","rc":[{"trd":[[1.88,228.32]],"batb":[[0,1.87,20.77],[1,1.85,68],[2,1.84,89.51]],"batl":[[0,1.88,201.85],[1,1.95,18.04],[2,1.96,4.5]],"ltp":1.88,"tv":505.58,"id":31372}],"tv":738.24}]}
{"op":"mcm","clk":"11797099937","pt":1723019116330,"mc":[{"id":"1.231431354","rc":[{"batb":[[0,2.04,17.37],[1,2.02,17.71],[2,2,55.88]],"ltp":2.12,"tv":232.65,"id":5901},{"batb":[[0,1.85,46.74],[1,1.84,89.51],[2,1.8,4.5]],"ltp":1.88,"tv":505.58,"id":31372}]}]}
{"op":"mcm","clk":"11797099978","pt":1723019117320,"mc":[{"id":"1.231431354","rc":[{"batb":[[0,2.1,16.42],[1,2.04,17.37],[2,2.02,17.71]],"ltp":2.12,"tv":232.65,"id":5901}]}]}
{"op":"mcm","clk":"11797103793","pt":1723019219511,"mc":[{"id":"1.231431354","rc":[{"trd":[[1.85,65.14]],"batb":[[0,1.85,45.91]],"ltp":1.85,"tv":507.24,"id":31372}],"tv":739.9}]}
{"op":"mcm","clk":"11797103995","pt":1723019224222,"mc":[{"id":"1.231431354","rc":[{"batb":[[0,1.85,46.74]],"ltp":1.85,"tv":507.24,"id":31372}]}]}
{"op":"mcm","clk":"11797104554","pt":1723019238131,"mc":[{"id":"1.231431354","rc":[{"trd":[[1.88,229.98]],"batl":[[0,1.88,201.02]],"ltp":1.88,"tv":508.9,"id":31372}],"tv":741.56}]}
{"op":"mcm","clk":"11797126453","pt":1723019693169,"mc":[{"id":"1.231431354","rc":[{"trd":[[1.85,158.62]],"batb":[[0,1.84,89.51],[1,1.8,4.5],[2,1.74,17.32]],"batl":[[0,1.88,201.28]],"ltp":1.85,"tv":602.38,"id":31372}],"tv":835.04}]}
{"op":"mcm","clk":"11797126608","pt":1723019696209,"mc":[{"id":"1.231431354","rc":[{"batb":[[1,1.81,46.69],[2,1.8,4.5]],"ltp":1.85,"tv":602.38,"id":31372}]}]}
{"op":"mcm","clk":"11797127054","pt":1723019705637,"mc":[{"id":"1.231431354","rc":[{"batl":[[0,1.88,201.02]],"ltp":1.85,"tv":602.38,"id":31372}]}]}
{"op":"mcm","clk":"11797127308","pt":1723019710258,"mc":[{"id":"1.231431354","rc":[{"batb":[[0,2.04,17.37],[1,2.02,17.71],[2,2,55.88]],"ltp":2.12,"tv":232.65,"id":5901},{"batl":[[0,1.95,18.04],[1,1.96,4.5],[2,1.98,2.22]],"ltp":1.85,"tv":602.38,"id":31372}]}]}
{"op":"mcm","clk":"11797127830","pt":1723019720642,"mc":[{"id":"1.231431354","rc":[{"batb":[[0,1.85,34],[1,1.84,89.51],[2,1.81,46.69]],"ltp":1.85,"tv":602.38,"id":31372}]}]}
{"op":"mcm","clk":"11797137504","pt":1723019929673,"mc":[{"id":"1.231431354","rc":[{"batb":[[0,1.84,89.51],[1,1.81,46.69],[2,1.8,4.5]],"ltp":1.85,"tv":602.38,"id":31372}]}]}
{"op":"mcm","clk":"11797138320","pt":1723019946398,"mc":[{"id":"1.231431354","rc":[{"batl":[[0,1.88,29.28],[1,1.95,18.04],[2,1.96,4.5]],"ltp":1.85,"tv":602.38,"id":31372}]}]}
{"op":"mcm","clk":"11797138350","pt":1723019946907,"mc":[{"id":"1.231431354","rc":[{"batb":[[0,1.84,68],[1,1.83,21.76],[2,1.81,46.69]],"ltp":1.85,"tv":602.38,"id":31372}]}]}
{"op":"mcm","clk":"11797138412","pt":1723019948905,"mc":[{"id":"1.231431354","rc":[{"batb":[[0,2.1,16.42],[1,2.04,17.37],[2,2.02,17.71]],"ltp":2.12,"tv":232.65,"id":5901}]}]}
{"op":"mcm","clk":"11797149329","pt":1723020191069,"mc":[{"id":"1.231431354","rc":[{"trd":[[1.84,136]],"batb":[[0,1.83,21.76],[1,1.81,46.69],[2,1.8,4.5]],"batl":[[0,1.84,1],[1,1.88,29.28],[2,1.95,18.04]],"ltp":1.84,"tv":738.38,"id":31372}],"tv":971.04}]}
{"op":"mcm","clk":"11797149362","pt":1723020192102,"mc":[{"id":"1.231431354","rc":[{"batb":[[0,1.81,46.69],[1,1.8,27.08],[2,1.74,17.32]],"ltp":1.84,"tv":738.38,"id":31372}]}]}
{"op":"mcm","clk":"11797149443","pt":1723020193807,"mc":[{"id":"1.231431354","rc":[{"batl":[[0,1.88,29.28],[1,1.95,18.04],[2,1.96,4.5]],"ltp":1.84,"tv":738.38,"id":31372}]}]}
{"op":"mcm","clk":"11797149878","pt":1723020204499,"mc":[{"id":"1.231431354","rc":[{"batl":[[0,1.95,18.04],[1,1.96,4.5],[2,1.98,2.22]],"ltp":1.84,"tv":738.38,"id":31372}]}]}
{"op":"mcm","clk":"11797149906","pt":1723020205119,"mc":[{"id":"1.231431354","rc":[{"batb":[[0,2.04,17.37],[1,2.02,17.71],[2,2,55.88]],"ltp":2.12,"tv":232.65,"id":5901}]}]}
{"op":"mcm","clk":"11797150971","pt":1723020229046,"mc":[{"id":"1.231431354","rc":[{"batl":[[0,1.86,86.28],[1,1.95,18.04],[2,1.96,4.5]],"ltp":1.84,"tv":738.38,"id":31372}]}]}
{"op":"mcm","clk":"11797151078","pt":1723020231146,"mc":[{"id":"1.231431354","rc":[{"batb":[[0,2.14,15.85],[1,2.04,17.37],[2,2.02,17.71]],"ltp":2.12,"tv":232.65,"id":5901}]}]}
{"op":"mcm","clk":"11797160839","pt":1723020438496,"mc":[{"id":"1.231431354","rc":[{"trd":[[2.16,74]],"ltp":2.16,"tv":306.65,"id":5901},{"trd":[[1.86,135.63]],"batl":[[0,1.95,18.38],[1,1.96,4.5],[2,1.98,2.22]],"ltp":1.86,"tv":824.32,"id":31372}],"tv":1130.98}]}
{"op":"mcm","clk":"11797160856","pt":1723020438805,"mc":[{"id":"1.231431354","rc":[{"batb":[[0,2.04,17.37],[1,2.02,17.71],[2,2,55.88]],"ltp":2.16,"tv":306.65,"id":5901}]}]}
{"op":"mcm","clk":"11797166718","pt":1723020544622,"mc":[{"id":"1.231431354","rc":[{"trd":[[1.81,4]],"batb":[[0,1.81,44.69]],"ltp":1.81,"tv":828.32,"id":31372}],"tv":1134.98}]}
{"op":"mcm","clk":"11797166834","pt":1723020546829,"mc":[{"id":"1.231431354","rc":[{"batb":[[0,1.81,46.69]],"ltp":1.81,"tv":828.32,"id":31372}]}]}
{"op":"mcm","clk":"11797169718","pt":1723020598863,"mc":[{"id":"1.231431354","rc":[{"batl":[[0,1.83,1.58],[1,1.95,18.38],[2,1.96,4.5]],"ltp":1.81,"tv":828.32,"id":31372}]}]}
{"op":"mcm","clk":"11797170487","pt":1723020611389,"mc":[{"id":"1.231431354","rc":[{"batl":[[0,1.95,18.38],[1,1.96,4.5],[2,1.98,2.22]],"ltp":1.81,"tv":828.32,"id":31372}]}]}
{"op":"mcm","clk":"11797172011","pt":1723020639429,"mc":[{"id":"1.231431354","rc":[{"batb":[[0,2.02,17.71],[1,2,55.88],[2,1.95,4.5]],"ltp":2.16,"tv":306.65,"id":5901},{"trd":[[1.86,136.31]],"batb":[[0,1.92,1.24],[1,1.81,69],[2,1.8,27.08]],"batl":[[0,1.95,18.04]],"ltp":1.86,"tv":829.0,"id":31372}],"tv":1135.66}]}
{"op":"mcm","clk":"11797172136","pt":1723020641433,"mc":[{"id":"1.231431354","rc":[{"batb":[[0,2.04,17.37],[1,2.02,17.71],[2,2,55.88]],"ltp":2.16,"tv":306.65,"id":5901},{"batl":[[0,1.94,10],[1,1.95,18.04],[2,1.96,4.5]],"ltp":1.86,"tv":829.0,"id":31372}]}]}
{"op":"mcm","clk":"11797172349","pt":1723020644821,"mc":[{"id":"1.231431354","rc":[{"batb":[[0,1.81,69],[1,1.8,27.08],[2,1.74,17.32]],"ltp":1.86,"tv":829.0,"id":31372}]}]}
{"op":"mcm","clk":"11797173539","pt":1723020665065,"mc":[{"id":"1.231431354","rc":[{"batb":[[0,2.06,10],[1,2.04,17.37],[2,2.02,17.71]],"batl":[[0,2.22,9]],"ltp":2.16,"tv":306.65,"id":5901}]}]}
{"op":"mcm","clk":"11797173773","pt":1723020668252,"mc":[{"id":"1.231431354","rc":[{"batb":[[0,2.04,17.37],[1,2.02,17.71],[2,2,55.88]],"ltp":2.16,"tv":306.65,"id":5901}]}]}
{"op":"mcm","clk":"11797174390","pt":1723020677587,"mc":[{"id":"1.231431354","rc":[{"batb":[[0,2.06,10],[1,2.04,17.37],[2,2.02,17.71]],"ltp":2.16,"tv":306.65,"id":5901}]}]}
{"op":"mcm","clk":"11797174608","pt":1723020680873,"mc":[{"id":"1.231431354","rc":[{"batb":[[0,2.04,17.37],[1,2.02,17.71],[2,2,55.88]],"ltp":2.16,"tv":306.65,"id":5901}]}]}
{"op":"mcm","clk":"11797174908","pt":1723020685298,"mc":[{"id":"1.231431354","rc":[{"batb":[[0,2.06,10],[1,2.04,17.37],[2,2.02,17.71]],"ltp":2.16,"tv":306.65,"id":5901}]}]}
{"op":"mcm","clk":"11797174932","pt":1723020685663,"mc":[{"id":"1.231431354","rc":[{"trd":[[2.22,0.56]],"batl":[[0,2.22,8.72]],"ltp":2.22,"tv":307.21,"id":5901}],"tv":1136.22}]}
{"op":"mcm","clk":"11797175115","pt":1723020688582,"mc":[{"id":"1.231431354","rc":[{"batb":[[0,2.04,17.37],[1,2.02,17.71],[2,2,55.88]],"ltp":2.22,"tv":307.21,"id":5901}]}]}
{"op":"mcm","clk":"11797175364","pt":1723020692289,"mc":[{"id":"1.231431354","rc":[{"batb":[[0,2.06,10],[1,2.04,17.37],[2,2.02,17.71]],"ltp":2.22,"tv":307.21,"id":5901}]}]}
{"op":"mcm","clk":"11797175556","pt":1723020695681,"mc":[{"id":"1.231431354","rc":[{"batb":[[0,2.04,17.37],[1,2.02,17.71],[2,2,55.88]],"ltp":2.22,"tv":307.21,"id":5901}]}]}
{"op":"mcm","clk":"11797175744","pt":1723020698509,"mc":[{"id":"1.231431354","rc":[{"batb":[[0,2.06,10],[1,2.04,17.37],[2,2.02,17.71]],"ltp":2.22,"tv":307.21,"id":5901}]}]}
{"op":"mcm","clk":"11797175964","pt":1723020701812,"mc":[{"id":"1.231431354","rc":[{"batb":[[0,2.04,17.37],[1,2.02,17.71],[2,2,55.88]],"ltp":2.22,"tv":307.21,"id":5901}]}]}
{"op":"mcm","clk":"11797176138","pt":1723020704703,"mc":[{"id":"1.231431354","rc":[{"batb":[[0,2.06,10],[1,2.04,17.37],[2,2.02,17.71]],"ltp":2.22,"tv":307.21,"id":5901},{"batl":[[0,1.9,2.25],[1,1.94,10],[2,1.95,18.04]],"ltp":1.86,"tv":829.0,"id":31372}]}]}
{"op":"mcm","clk":"11797176235","pt":1723020706415,"mc":[{"id":"1.231431354","rc":[{"batb":[[0,2.06,27.04]],"ltp":2.22,"tv":307.21,"id":5901}]}]}
{"op":"mcm","clk":"11797176376","pt":1723020708523,"mc":[{"id":"1.231431354","rc":[{"batb":[[0,2.04,17.37],[1,2.02,17.71],[2,2,55.88]],"ltp":2.22,"tv":307.21,"id":5901}]}]}
{"op":"mcm","clk":"11797176572","pt":1723020711822,"mc":[{"id":"1.231431354","rc":[{"batb":[[0,2.06,10],[1,2.04,17.37],[2,2.02,17.71]],"ltp":2.22,"tv":307.21,"id":5901}]}]}
{"op":"mcm","clk":"11797176763","pt":1723020714408,"mc":[{"id":"1.231431354","rc":[{"batb":[[0,2.06,27.04]],"ltp":2.22,"tv":307.21,"id":5901}]}]}
{"op":"mcm","clk":"11797176844","pt":1723020715494,"mc":[{"id":"1.231431354","rc":[{"batb":[[0,2.04,17.37],[1,2.02,17.71],[2,2,55.88]],"ltp":2.22,"tv":307.21,"id":5901}]}]}
{"op":"mcm","clk":"11797176988","pt":1723020717613,"mc":[{"id":"1.231431354","rc":[{"batb":[[0,2.06,10],[1,2.04,17.37],[2,2.02,17.71]],"ltp":2.22,"tv":307.21,"id":5901}]}]}
{"op":"mcm","clk":"11797177106","pt":1723020719414,"mc":[{"id":"1.231431354","rc":[{"batb":[[0,2.06,27.04]],"ltp":2.22,"tv":307.21,"id":5901}]}]}
{"op":"mcm","clk":"11797177251","pt":1723020721511,"mc":[{"id":"1.231431354","rc":[{"batb":[[0,2.04,17.37],[1,2.02,17.71],[2,2,55.88]],"ltp":2.22,"tv":307.21,"id":5901}]}]}
{"op":"mcm","clk":"11797177682","pt":1723020728322,"mc":[{"id":"1.231431354","rc":[{"batb":[[0,2.06,10],[1,2.04,17.37],[2,2.02,17.71]],"ltp":2.22,"tv":307.21,"id":5901}]}]}
{"op":"mcm","clk":"11797177792","pt":1723020730446,"mc":[{"id":"1.231431354","rc":[{"batb":[[0,2.06,27.04]],"ltp":2.22,"tv":307.21,"id":5901}]}]}
{"op":"mcm","clk":"11797177879","pt":1723020732038,"mc":[{"id":"1.231431354","rc":[{"batb":[[0,2.04,17.37],[1,2.02,17.71],[2,2,55.88]],"ltp":2.22,"tv":307.21,"id":5901}]}]}
{"op":"mcm","clk":"11797178181","pt":1723020736542,"mc":[{"id":"1.231431354","rc":[{"batb":[[0,2.06,10],[1,2.04,17.37],[2,2.02,17.71]],"ltp":2.22,"tv":307.21,"id":5901}]}]}
{"op":"mcm","clk":"11797178286","pt":1723020738446,"mc":[{"id":"1.231431354","rc":[{"batb":[[0,2.06,27.04]],"ltp":2.22,"tv":307.21,"id":5901}]}]}
{"op":"mcm","clk":"11797178395","pt":1723020740459,"mc":[{"id":"1.231431354","rc":[{"batb":[[0,2.04,17.37],[1,2.02,17.71],[2,2,55.88]],"ltp":2.22,"tv":307.21,"id":5901},{"batb":[[0,1.81,46.69]],"batl":[[0,1.82,1.58],[1,1.9,2.25],[2,1.94,10]],"ltp":1.86,"tv":829.0,"id":31372}]}]}
{"op":"mcm","clk":"11797178567","pt":1723020743448,"mc":[{"id":"1.231431354","rc":[{"batb":[[0,2.06,10],[1,2.04,17.37],[2,2.02,17.71]],"ltp":2.22,"tv":307.21,"id":5901},{"batl":[[0,1.9,2.25],[1,1.94,10],[2,1.95,18.04]],"ltp":1.86,"tv":829.0,"id":31372}]}]}
{"op":"mcm","clk":"11797178667","pt":1723020745461,"mc":[{"id":"1.231431354","rc":[{"batb":[[0,2.06,27.04]],"ltp":2.22,"tv":307.21,"id":5901}]}]}
{"op":"mcm","clk":"11797178747","pt":1723020747050,"mc":[{"id":"1.231431354","rc":[{"batb":[[0,2.04,17.37],[1,2.02,17.71],[2,2,55.88]],"ltp":2.22,"tv":307.21,"id":5901}]}]}
{"op":"mcm","clk":"11797178898","pt":1723020749262,"mc":[{"id":"1.231431354","rc":[{"batb":[[0,2.06,10],[1,2.04,17.37],[2,2.02,17.71]],"ltp":2.22,"tv":307.21,"id":5901}]}]}
{"op":"mcm","clk":"11797179007","pt":1723020751441,"mc":[{"id":"1.231431354","rc":[{"batb":[[0,2.06,27.04]],"ltp":2.22,"tv":307.21,"id":5901}]}]}
{"op":"mcm","clk":"11797179080","pt":1723020753038,"mc":[{"id":"1.231431354","rc":[{"batb":[[0,2.04,17.37],[1,2.02,17.71],[2,2,55.88]],"ltp":2.22,"tv":307.21,"id":5901}]}]}
{"op":"mcm","clk":"11797179188","pt":1723020755244,"mc":[{"id":"1.231431354","rc":[{"batb":[[0,2.06,10],[1,2.04,17.37],[2,2.02,17.71]],"ltp":2.22,"tv":307.21,"id":5901}]}]}
{"op":"mcm","clk":"11797179313","pt":1723020757454,"mc":[{"id":"1.231431354","rc":[{"batb":[[0,2.06,27.04]],"ltp":2.22,"tv":307.21,"id":5901}]}]}
{"op":"mcm","clk":"11797179409","pt":1723020758946,"mc":[{"id":"1.231431354","rc":[{"batb":[[0,2.04,17.37],[1,2.02,17.71],[2,2,55.88]],"ltp":2.22,"tv":307.21,"id":5901}]}]}
{"op":"mcm","clk":"11797179641","pt":1723020763049,"mc":[{"id":"1.231431354","rc":[{"batb":[[0,2.06,10],[1,2.04,17.37],[2,2.02,17.71]],"ltp":2.22,"tv":307.21,"id":5901}]}]}
{"op":"mcm","clk":"11797179753","pt":1723020764948,"mc":[{"id":"1.231431354","rc":[{"batb":[[0,2.06,27.04]],"ltp":2.22,"tv":307.21,"id":5901}]}]}
{"op":"mcm","clk":"11797179845","pt":1723020766454,"mc":[{"id":"1.231431354","rc":[{"batb":[[0,2.06,17.04]],"ltp":2.22,"tv":307.21,"id":5901}]}]}
{"op":"mcm","clk":"11797179871","pt":1723020766970,"mc":[{"id":"1.231431354","rc":[{"batb":[[0,2.04,17.37],[1,2.02,17.71],[2,2,55.88]],"ltp":2.22,"tv":307.21,"id":5901}]}]}
{"op":"mcm","clk":"11797180001","pt":1723020769087,"mc":[{"id":"1.231431354","rc":[{"batb":[[0,2.06,10],[1,2.04,17.37],[2,2.02,17.71]],"ltp":2.22,"tv":307.21,"id":5901}]}]}
{"op":"mcm","clk":"11797180117","pt":1723020770989,"mc":[{"id":"1.231431354","rc":[{"batb":[[0,2.06,27.04]],"ltp":2.22,"tv":307.21,"id":5901}]}]}
{"op":"mcm","clk":"11797180209","pt":1723020772377,"mc":[{"id":"1.231431354","rc":[{"batb":[[0,2.06,17.04]],"ltp":2.22,"tv":307.21,"id":5901}]}]}
{"op":"mcm","clk":"11797180261","pt":1723020773093,"mc":[{"id":"1.231431354","rc":[{"batb":[[0,2.04,17.37],[1,2.02,17.71],[2,2,55.88]],"ltp":2.22,"tv":307.21,"id":5901}]}]}
{"op":"mcm","clk":"11797180376","pt":1723020774897,"mc":[{"id":"1.231431354","rc":[{"batb":[[0,2.06,10],[1,2.04,17.37],[2,2.02,17.71]],"ltp":2.22,"tv":307.21,"id":5901}]}]}
{"op":"mcm","clk":"11797180441","pt":1723020775978,"mc":[{"id":"1.231431354","rc":[{"batb":[[0,1.88,1.58],[1,1.81,69],[2,1.8,27.08]],"ltp":1.86,"tv":829.0,"id":31372}]}]}
{"op":"mcm","clk":"11797180511","pt":1723020777008,"mc":[{"id":"1.231431354","rc":[{"batb":[[0,2.06,27.04]],"ltp":2.22,"tv":307.21,"id":5901}]}]}
{"op":"mcm","clk":"11797180596","pt":1723020778191,"mc":[{"id":"1.231431354","rc":[{"batb":[[0,2.06,17.04]],"ltp":2.22,"tv":307.21,"id":5901}]}]}
{"op":"mcm","clk":"11797180666","pt":1723020779471,"mc":[{"id":"1.231431354","rc":[{"batb":[[0,2.04,17.37],[1,2.02,17.71],[2,2,55.88]],"ltp":2.22,"tv":307.21,"id":5901},{"batb":[[0,1.81,69],[1,1.8,27.08],[2,1.74,17.32]],"ltp":1.86,"tv":829.0,"id":31372}]}]}
{"op":"mcm","clk":"11797180783","pt":1723020781270,"mc":[{"id":"1.231431354","rc":[{"batb":[[0,2.06,10],[1,2.04,17.37],[2,2.02,17.71]],"ltp":2.22,"tv":307.21,"id":5901}]}]}
{"op":"mcm","clk":"11797180871","pt":1723020782976,"mc":[{"id":"1.231431354","rc":[{"batb":[[0,2.06,27.04]],"ltp":2.22,"tv":307.21,"id":5901}]}]}
{"op":"mcm","clk":"11797180967","pt":1723020784513,"mc":[{"id":"1.231431354","rc":[{"batb":[[0,2.06,17.04]],"ltp":2.22,"tv":307.21,"id":5901}]}]}
{"op":"mcm","clk":"11797181006","pt":1723020785078,"mc":[{"id":"1.231431354","rc":[{"batb":[[0,2.04,17.37],[1,2.02,17.71],[2,2,55.88]],"ltp":2.22,"tv":307.21,"id":5901}]}]}
{"op":"mcm","clk":"11797181320","pt":1723020790107,"mc":[{"id":"1.231431354","rc":[{"batb":[[0,2.06,10],[1,2.04,17.37],[2,2.02,17.71]],"ltp":2.22,"tv":307.21,"id":5901}]}]}
{"op":"mcm","clk":"11797181421","pt":1723020792004,"mc":[{"id":"1.231431354","rc":[{"batb":[[0,2.06,27.04]],"ltp":2.22,"tv":307.21,"id":5901}]}]}
{"op":"mcm","clk":"11797181507","pt":1723020793502,"mc":[{"id":"1.231431354","rc":[{"batb":[[0,2.06,17.04]],"ltp":2.22,"tv":307.21,"id":5901}]}]}
{"op":"mcm","clk":"11797181543","pt":1723020794014,"mc":[{"id":"1.231431354","rc":[{"batb":[[0,2.04,17.37],[1,2.02,17.71],[2,2,55.88]],"ltp":2.22,"tv":307.21,"id":5901}]}]}
{"op":"mcm","clk":"11797182047","pt":1723020802420,"mc":[{"id":"1.231431354","rc":[{"batb":[[0,2.06,10],[1,2.04,17.37],[2,2.02,17.71]],"batl":[[0,2.2,9.02],[1,2.22,8.72]],"ltp":2.22,"tv":307.21,"id":5901}]}]}
{"op":"mcm","clk":"11797182153","pt":1723020804012,"mc":[{"id":"1.231431354","rc":[{"batb":[[0,2.06,27.04]],"ltp":2.22,"tv":307.21,"id":5901}]}]}
{"op":"mcm","clk":"11797182233","pt":1723020805196,"mc":[{"id":"1.231431354","rc":[{"batb":[[0,2.06,17.04]],"ltp":2.22,"tv":307.21,"id":5901}]}]}
{"op":"mcm","clk":"11797182260","pt":1723020805605,"mc":[{"id":"1.231431354","rc":[{"batb":[[0,2.04,17.37],[1,2.02,17.71],[2,2,55.88]],"ltp":2.22,"tv":307.21,"id":5901}]}]}
{"op":"mcm","clk":"11797182581","pt":1723020809703,"mc":[{"id":"1.231431354","rc":[{"batb":[[0,2.06,10],[1,2.04,17.37],[2,2.02,17.71]],"ltp":2.22,"tv":307.21,"id":5901}]}]}
{"op":"mcm","clk":"11797182731","pt":1723020812013,"mc":[{"id":"1.231431354","rc":[{"batb":[[0,2.06,27.04]],"ltp":2.22,"tv":307.21,"id":5901}]}]}
{"op":"mcm","clk":"11797182798","pt":1723020812941,"mc":[{"id":"1.231431354","rc":[{"batb":[[0,2.06,17.04]],"ltp":2.22,"tv":307.21,"id":5901}]}]}
{"op":"mcm","clk":"11797182844","pt":1723020813609,"mc":[{"id":"1.231431354","rc":[{"batb":[[0,2.04,17.37],[1,2.02,17.71],[2,2,55.88]],"ltp":2.22,"tv":307.21,"id":5901}]}]}
{"op":"mcm","clk":"11797183080","pt":1723020817731,"mc":[{"id":"1.231431354","rc":[{"batb":[[0,2.06,10],[1,2.04,17.37],[2,2.02,17.71]],"ltp":2.22,"tv":307.21,"id":5901}]}]}
{"op":"mcm","clk":"11797183205","pt":1723020820041,"mc":[{"id":"1.231431354","rc":[{"batb":[[0,2.06,27.04]],"ltp":2.22,"tv":307.21,"id":5901}]}]}
{"op":"mcm","clk":"11797183260","pt":1723020820916,"mc":[{"id":"1.231431354","rc":[{"batb":[[0,2.06,17.04]],"ltp":2.22,"tv":307.21,"id":5901}]}]}
{"op":"mcm","clk":"11797183300","pt":1723020821536,"mc":[{"id":"1.231431354","rc":[{"batb":[[0,2.04,17.37],[1,2.02,17.71],[2,2,55.88]],"ltp":2.22,"tv":307.21,"id":5901}]}]}
{"op":"mcm","clk":"11797183514","pt":1723020825135,"mc":[{"id":"1.231431354","rc":[{"batb":[[0,2.06,10],[1,2.04,17.37],[2,2.02,17.71]],"ltp":2.22,"tv":307.21,"id":5901}]}]}
{"op":"mcm","clk":"11797183622","pt":1723020827031,"mc":[{"id":"1.231431354","rc":[{"batb":[[0,2.06,27.04]],"ltp":2.22,"tv":307.21,"id":5901}]}]}
{"op":"mcm","clk":"11797183703","pt":1723020828417,"mc":[{"id":"1.231431354","rc":[{"batb":[[0,2.06,17.04]],"ltp":2.22,"tv":307.21,"id":5901}]}]}
{"op":"mcm","clk":"11797183743","pt":1723020829032,"mc":[{"id":"1.231431354","rc":[{"batb":[[0,2.04,17.37],[1,2.02,17.71],[2,2,55.88]],"ltp":2.22,"tv":307.21,"id":5901}]}]}
{"op":"mcm","clk":"11797183939","pt":1723020832461,"mc":[{"id":"1.231431354","rc":[{"batb":[[0,2.06,10],[1,2.04,17.37],[2,2.02,17.71]],"ltp":2.22,"tv":307.21,"id":5901}]}]}
{"op":"mcm","clk":"11797184103","pt":1723020835029,"mc":[{"id":"1.231431354","rc":[{"batb":[[0,2.06,27.04]],"ltp":2.22,"tv":307.21,"id":5901}]}]}
{"op":"mcm","clk":"11797184169","pt":1723020836077,"mc":[{"id":"1.231431354","rc":[{"batb":[[0,2.04,17.37],[1,2.02,17.71],[2,2,55.88]],"ltp":2.22,"tv":307.21,"id":5901}]}]}
{"op":"mcm","clk":"11797184404","pt":1723020840092,"mc":[{"id":"1.231431354","rc":[{"batb":[[0,2.06,10],[1,2.04,17.37],[2,2.02,17.71]],"ltp":2.22,"tv":307.21,"id":5901}]}]}
{"op":"mcm","clk":"11797184531","pt":1723020842053,"mc":[{"id":"1.231431354","rc":[{"batb":[[0,2.06,27.04]],"ltp":2.22,"tv":307.21,"id":5901}]}]}
{"op":"mcm","clk":"11797184604","pt":1723020843239,"mc":[{"id":"1.231431354","rc":[{"batb":[[0,2.06,17.04]],"ltp":2.22,"tv":307.21,"id":5901}]}]}
{"op":"mcm","clk":"11797184625","pt":1723020843547,"mc":[{"id":"1.231431354","rc":[{"batb":[[0,2.04,17.37],[1,2.02,17.71],[2,2,55.88]],"ltp":2.22,"tv":307.21,"id":5901}]}]}
{"op":"mcm","clk":"11797184849","pt":1723020847154,"mc":[{"id":"1.231431354","rc":[{"batb":[[0,2.06,10],[1,2.04,17.37],[2,2.02,17.71]],"ltp":2.22,"tv":307.21,"id":5901}]}]}
{"op":"mcm","clk":"11797184976","pt":1723020849054,"mc":[{"id":"1.231431354","rc":[{"batb":[[0,2.06,27.04]],"ltp":2.22,"tv":307.21,"id":5901}]}]}
{"op":"mcm","clk":"11797185079","pt":1723020851159,"mc":[{"id":"1.231431354","rc":[{"batb":[[0,2.04,17.37],[1,2.02,17.71],[2,2,55.88]],"ltp":2.22,"tv":307.21,"id":5901}]}]}
{"op":"mcm","clk":"11797185205","pt":1723020853282,"mc":[{"id":"1.231431354","rc":[{"batb":[[0,2.06,10],[1,2.04,17.37],[2,2.02,17.71]],"ltp":2.22,"tv":307.21,"id":5901}]}]}
{"op":"mcm","clk":"11797185320","pt":1723020855046,"mc":[{"id":"1.231431354","rc":[{"batb":[[0,2.06,27.04]],"ltp":2.22,"tv":307.21,"id":5901}]}]}
{"op":"mcm","clk":"11797185394","pt":1723020856386,"mc":[{"id":"1.231431354","rc":[{"batb":[[0,2.06,17.04]],"ltp":2.22,"tv":307.21,"id":5901}]}]}
{"op":"mcm","clk":"11797185413","pt":1723020856644,"mc":[{"id":"1.231431354","rc":[{"batb":[[0,2.04,17.37],[1,2.02,17.71],[2,2,55.88]],"ltp":2.22,"tv":307.21,"id":5901}]}]}
{"op":"mcm","clk":"11797185555","pt":1723020859366,"mc":[{"id":"1.231431354","rc":[{"batb":[[0,2.06,10],[1,2.04,17.37],[2,2.02,17.71]],"ltp":2.22,"tv":307.21,"id":5901}]}]}
{"op":"mcm","clk":"11797185674","pt":1723020861577,"mc":[{"id":"1.231431354","rc":[{"batb":[[0,2.06,27.04]],"ltp":2.22,"tv":307.21,"id":5901}]}]}
{"op":"mcm","clk":"11797185772","pt":1723020863172,"mc":[{"id":"1.231431354","rc":[{"batb":[[0,2.04,17.37],[1,2.02,17.71],[2,2,55.88]],"ltp":2.22,"tv":307.21,"id":5901}]}]}
{"op":"mcm","clk":"11797185971","pt":1723020866576,"mc":[{"id":"1.231431354","rc":[{"batb":[[0,2.06,10],[1,2.04,17.37],[2,2.02,17.71]],"ltp":2.22,"tv":307.21,"id":5901}]}]}
{"op":"mcm","clk":"11797186084","pt":1723020868588,"mc":[{"id":"1.231431354","rc":[{"batb":[[0,2.06,27.04]],"ltp":2.22,"tv":307.21,"id":5901}]}]}
{"op":"mcm","clk":"11797186150","pt":1723020869973,"mc":[{"id":"1.231431354","rc":[{"batb":[[0,2.06,17.04]],"ltp":2.22,"tv":307.21,"id":5901}]}]}
{"op":"mcm","clk":"11797186184","pt":1723020870589,"mc":[{"id":"1.231431354","rc":[{"batb":[[0,2.04,17.37],[1,2.02,17.71],[2,2,55.88]],"ltp":2.22,"tv":307.21,"id":5901}]}]}
{"op":"mcm","clk":"11797186352","pt":1723020873582,"mc":[{"id":"1.231431354","rc":[{"batb":[[0,2.06,10],[1,2.04,17.37],[2,2.02,17.71]],"ltp":2.22,"tv":307.21,"id":5901}]}]}
{"op":"mcm","clk":"11797186477","pt":1723020875592,"mc":[{"id":"1.231431354","rc":[{"batb":[[0,2.06,27.04]],"ltp":2.22,"tv":307.21,"id":5901}]}]}
{"op":"mcm","clk":"11797186573","pt":1723020877085,"mc":[{"id":"1.231431354","rc":[{"batb":[[0,2.04,17.37],[1,2.02,17.71],[2,2,55.88]],"ltp":2.22,"tv":307.21,"id":5901}]}]}
{"op":"mcm","clk":"11797186737","pt":1723020880176,"mc":[{"id":"1.231431354","rc":[{"batb":[[0,2.06,10],[1,2.04,17.37],[2,2.02,17.71]],"ltp":2.22,"tv":307.21,"id":5901}]}]}
{"op":"mcm","clk":"11797186850","pt":1723020882084,"mc":[{"id":"1.231431354","rc":[{"batb":[[0,2.06,27.04]],"ltp":2.22,"tv":307.21,"id":5901}]}]}
{"op":"mcm","clk":"11797186918","pt":1723020883372,"mc":[{"id":"1.231431354","rc":[{"batb":[[0,2.06,17.04]],"ltp":2.22,"tv":307.21,"id":5901}]}]}
{"op":"mcm","clk":"11797186935","pt":1723020883678,"mc":[{"id":"1.231431354","rc":[{"batb":[[0,2.04,17.37],[1,2.02,17.71],[2,2,55.88]],"ltp":2.22,"tv":307.21,"id":5901}]}]}
{"op":"mcm","clk":"11797187190","pt":1723020888102,"mc":[{"id":"1.231431354","rc":[{"batb":[[0,2.06,10],[1,2.04,17.37],[2,2.02,17.71]],"ltp":2.22,"tv":307.21,"id":5901}]}]}
{"op":"mcm","clk":"11797187302","pt":1723020890108,"mc":[{"id":"1.231431354","rc":[{"batb":[[0,2.06,27.04]],"ltp":2.22,"tv":307.21,"id":5901}]}]}
{"op":"mcm","clk":"11797187362","pt":1723020891395,"mc":[{"id":"1.231431354","rc":[{"batb":[[0,2.06,17.04]],"ltp":2.22,"tv":307.21,"id":5901}]}]}
{"op":"mcm","clk":"11797187374","pt":1723020891701,"mc":[{"id":"1.231431354","rc":[{"batb":[[0,2.04,17.37],[1,2.02,17.71],[2,2,55.88]],"ltp":2.22,"tv":307.21,"id":5901}]}]}
{"op":"mcm","clk":"11797187599","pt":1723020895609,"mc":[{"id":"1.231431354","rc":[{"batb":[[0,2.06,10],[1,2.04,17.37],[2,2.02,17.71]],"ltp":2.22,"tv":307.21,"id":5901}]}]}
{"op":"mcm","clk":"11797187733","pt":1723020898135,"mc":[{"id":"1.231431354","rc":[{"batb":[[0,2.06,27.04]],"ltp":2.22,"tv":307.21,"id":5901}]}]}
{"op":"mcm","clk":"11797187795","pt":1723020899109,"mc":[{"id":"1.231431354","rc":[{"batb":[[0,2.04,17.37],[1,2.02,17.71],[2,2,55.88]],"ltp":2.22,"tv":307.21,"id":5901}]}]}
{"op":"mcm","clk":"11797188094","pt":1723020904191,"mc":[{"id":"1.231431354","rc":[{"batb":[[0,2.06,10],[1,2.04,17.37],[2,2.02,17.71]],"ltp":2.22,"tv":307.21,"id":5901}]}]}
{"op":"mcm","clk":"11797188219","pt":1723020906102,"mc":[{"id":"1.231431354","rc":[{"batb":[[0,2.06,27.04]],"ltp":2.22,"tv":307.21,"id":5901}]}]}
{"op":"mcm","clk":"11797188335","pt":1723020908110,"mc":[{"id":"1.231431354","rc":[{"batb":[[0,2.04,17.37],[1,2.02,17.71],[2,2,55.88]],"ltp":2.22,"tv":307.21,"id":5901}]}]}
{"op":"mcm","clk":"11797188688","pt":1723020914504,"mc":[{"id":"1.231431354","rc":[{"batb":[[0,2.06,10],[1,2.04,17.37],[2,2.02,17.71]],"ltp":2.22,"tv":307.21,"id":5901}]}]}
{"op":"mcm","clk":"11797188822","pt":1723020916612,"mc":[{"id":"1.231431354","rc":[{"batb":[[0,2.06,27.04]],"ltp":2.22,"tv":307.21,"id":5901}]}]}
{"op":"mcm","clk":"11797188922","pt":1723020918207,"mc":[{"id":"1.231431354","rc":[{"batb":[[0,2.04,17.37],[1,2.02,17.71],[2,2,55.88]],"ltp":2.22,"tv":307.21,"id":5901}]}]}
{"op":"mcm","clk":"11797190384","pt":1723020942819,"mc":[{"id":"1.231431354","rc":[{"batb":[[0,2.06,10],[1,2.04,17.37],[2,2.02,17.71]],"ltp":2.22,"tv":307.21,"id":5901}]}]}
{"op":"mcm","clk":"11797190524","pt":1723020945128,"mc":[{"id":"1.231431354","rc":[{"batb":[[0,2.06,27.04]],"ltp":2.22,"tv":307.21,"id":5901}]}]}
{"op":"mcm","clk":"11797190579","pt":1723020946253,"mc":[{"id":"1.231431354","rc":[{"batb":[[0,2.06,17.04]],"ltp":2.22,"tv":307.21,"id":5901}]}]}
{"op":"mcm","clk":"11797190613","pt":1723020946716,"mc":[{"id":"1.231431354","rc":[{"batb":[[0,2.04,17.37],[1,2.02,17.71],[2,2,55.88]],"ltp":2.22,"tv":307.21,"id":5901}]}]}
{"op":"mcm","clk":"11797190768","pt":1723020949434,"mc":[{"id":"1.231431354","rc":[{"batb":[[0,2.06,10],[1,2.04,17.37],[2,2.02,17.71]],"ltp":2.22,"tv":307.21,"id":5901}]}]}
{"op":"mcm","clk":"11797190876","pt":1723020951225,"mc":[{"id":"1.231431354","rc":[{"batb":[[0,2.06,27.04]],"ltp":2.22,"tv":307.21,"id":5901}]}]}
{"op":"mcm","clk":"11797190995","pt":1723020953227,"mc":[{"id":"1.231431354","rc":[{"batb":[[0,2.04,17.37],[1,2.02,17.71],[2,2,55.88]],"ltp":2.22,"tv":307.21,"id":5901}]}]}
{"op":"mcm","clk":"11797191354","pt":1723020958471,"mc":[{"id":"1.231431354","rc":[{"batb":[[0,2.06,10],[1,2.04,17.37],[2,2.02,17.71]],"ltp":2.22,"tv":307.21,"id":5901}]}]}
{"op":"mcm","clk":"11797191451","pt":1723020960162,"mc":[{"id":"1.231431354","rc":[{"batb":[[0,2.06,27.04]],"ltp":2.22,"tv":307.21,"id":5901}]}]}
{"op":"mcm","clk":"11797191574","pt":1723020962254,"mc":[{"id":"1.231431354","rc":[{"batb":[[0,2.04,17.37],[1,2.02,17.71],[2,2,55.88]],"ltp":2.22,"tv":307.21,"id":5901}]}]}
{"op":"mcm","clk":"11797191702","pt":1723020964562,"mc":[{"id":"1.231431354","rc":[{"batb":[[0,2.06,10],[1,2.04,17.37],[2,2.02,17.71]],"ltp":2.22,"tv":307.21,"id":5901}]}]}
{"op":"mcm","clk":"11797191844","pt":1723020967135,"mc":[{"id":"1.231431354","rc":[{"batb":[[0,2.06,27.04]],"ltp":2.22,"tv":307.21,"id":5901}]}]}
{"op":"mcm","clk":"11797191911","pt":1723020968365,"mc":[{"id":"1.231431354","rc":[{"batb":[[0,2.04,17.37],[1,2.02,17.71],[2,2,55.88]],"ltp":2.22,"tv":307.21,"id":5901}]}]}
{"op":"mcm","clk":"11797192306","pt":1723020976457,"mc":[{"id":"1.231431354","rc":[{"batb":[[0,2.06,10],[1,2.04,17.37],[2,2.02,17.71]],"ltp":2.22,"tv":307.21,"id":5901}]}]}
{"op":"mcm","clk":"11797192409","pt":1723020978659,"mc":[{"id":"1.231431354","rc":[{"batb":[[0,2.06,27.04]],"ltp":2.22,"tv":307.21,"id":5901}]}]}
{"op":"mcm","clk":"11797192489","pt":1723020980301,"mc":[{"id":"1.231431354","rc":[{"batb":[[0,2.04,17.37],[1,2.02,17.71],[2,2,55.88]],"ltp":2.22,"tv":307.21,"id":5901}]}]}
{"op":"mcm","clk":"11797192614","pt":1723020982352,"mc":[{"id":"1.231431354","rc":[{"batb":[[0,2.06,10],[1,2.04,17.37],[2,2.02,17.71]],"ltp":2.22,"tv":307.21,"id":5901}]}]}
{"op":"mcm","clk":"11797192724","pt":1723020984760,"mc":[{"id":"1.231431354","rc":[{"batb":[[0,2.06,27.04]],"ltp":2.22,"tv":307.21,"id":5901}]}]}
{"op":"mcm","clk":"11797192796","pt":1723020986294,"mc":[{"id":"1.231431354","rc":[{"batb":[[0,2.04,17.37],[1,2.02,17.71],[2,2,55.88]],"ltp":2.22,"tv":307.21,"id":5901}]}]}
{"op":"mcm","clk":"11797192909","pt":1723020989264,"mc":[{"id":"1.231431354","rc":[{"batb":[[0,2.06,10],[1,2.04,17.37],[2,2.02,17.71]],"ltp":2.22,"tv":307.21,"id":5901}]}]}
{"op":"mcm","clk":"11797193055","pt":1723020991676,"mc":[{"id":"1.231431354","rc":[{"batb":[[0,2.06,27.04]],"ltp":2.22,"tv":307.21,"id":5901}]}]}
{"op":"mcm","clk":"11797193120","pt":1723020992805,"mc":[{"id":"1.231431354","rc":[{"batb":[[0,2.04,17.37],[1,2.02,17.71],[2,2,55.88]],"ltp":2.22,"tv":307.21,"id":5901}]}]}
{"op":"mcm","clk":"11797193280","pt":1723020995484,"mc":[{"id":"1.231431354","rc":[{"batb":[[0,2.06,10],[1,2.04,17.37],[2,2.02,17.71]],"ltp":2.22,"tv":307.21,"id":5901}]}]}
{"op":"mcm","clk":"11797193427","pt":1723020997704,"mc":[{"id":"1.231431354","rc":[{"batb":[[0,2.06,27.04]],"ltp":2.22,"tv":307.21,"id":5901}]}]}
{"op":"mcm","clk":"11797193508","pt":1723020999176,"mc":[{"id":"1.231431354","rc":[{"batb":[[0,2.04,17.37],[1,2.02,17.71],[2,2,55.88]],"ltp":2.22,"tv":307.21,"id":5901}]}]}
{"op":"mcm","clk":"11797193873","pt":1723021006122,"mc":[{"id":"1.231431354","rc":[{"batb":[[0,2.06,10],[1,2.04,17.37],[2,2.02,17.71]],"ltp":2.22,"tv":307.21,"id":5901}]}]}
{"op":"mcm","clk":"11797193959","pt":1723021007718,"mc":[{"id":"1.231431354","rc":[{"batb":[[0,2.06,27.04]],"ltp":2.22,"tv":307.21,"id":5901}]}]}
{"op":"mcm","clk":"11797194086","pt":1723021010332,"mc":[{"id":"1.231431354","rc":[{"batb":[[0,2.04,17.37],[1,2.02,17.71],[2,2,55.88]],"ltp":2.22,"tv":307.21,"id":5901}]}]}
{"op":"mcm","clk":"11797194180","pt":1723021012022,"mc":[{"id":"1.231431354","rc":[{"batb":[[0,2.06,10],[1,2.04,17.37],[2,2.02,17.71]],"ltp":2.22,"tv":307.21,"id":5901}]}]}
{"op":"mcm","clk":"11797194324","pt":1723021014226,"mc":[{"id":"1.231431354","rc":[{"batb":[[0,2.06,27.04]],"ltp":2.22,"tv":307.21,"id":5901}]}]}
{"op":"mcm","clk":"11797194385","pt":1723021015199,"mc":[{"id":"1.231431354","rc":[{"batb":[[0,2.06,17.04]],"ltp":2.22,"tv":307.21,"id":5901}]}]}
{"op":"mcm","clk":"11797194425","pt":1723021015812,"mc":[{"id":"1.231431354","rc":[{"batb":[[0,2.04,17.37],[1,2.02,17.71],[2,2,55.88]],"ltp":2.22,"tv":307.21,"id":5901}]}]}
{"op":"mcm","clk":"11797194617","pt":1723021019120,"mc":[{"id":"1.231431354","rc":[{"batb":[[0,2.06,10],[1,2.04,17.37],[2,2.02,17.71]],"ltp":2.22,"tv":307.21,"id":5901}]}]}
{"op":"mcm","clk":"11797194737","pt":1723021021224,"mc":[{"id":"1.231431354","rc":[{"batb":[[0,2.06,27.04]],"ltp":2.22,"tv":307.21,"id":5901}]}]}
{"op":"mcm","clk":"11797194860","pt":1723021023334,"mc":[{"id":"1.231431354","rc":[{"batb":[[0,2.04,17.37],[1,2.02,17.71],[2,2,55.88]],"ltp":2.22,"tv":307.21,"id":5901}]}]}
{"op":"mcm","clk":"11797195848","pt":1723021040972,"mc":[{"id":"1.231431354","rc":[{"batb":[[0,2.06,10],[1,2.04,17.37],[2,2.02,17.71]],"ltp":2.22,"tv":307.21,"id":5901}]}]}
{"op":"mcm","clk":"11797195939","pt":1723021042723,"mc":[{"id":"1.231431354","rc":[{"batb":[[0,2.06,27.04]],"ltp":2.22,"tv":307.21,"id":5901}]}]}
{"op":"mcm","clk":"11797196008","pt":1723021044257,"mc":[{"id":"1.231431354","rc":[{"batb":[[0,2.06,17.04]],"ltp":2.22,"tv":307.21,"id":5901}]}]}
{"op":"mcm","clk":"11797196029","pt":1723021044772,"mc":[{"id":"1.231431354","rc":[{"batb":[[0,2.04,17.37],[1,2.02,17.71],[2,2,55.88]],"ltp":2.22,"tv":307.21,"id":5901}]}]}
{"op":"mcm","clk":"11797196150","pt":1723021047032,"mc":[{"id":"1.231431354","rc":[{"batb":[[0,2.06,10],[1,2.04,17.37],[2,2.02,17.71]],"ltp":2.22,"tv":307.21,"id":5901}]}]}
{"op":"mcm","clk":"11797196256","pt":1723021048775,"mc":[{"id":"1.231431354","rc":[{"batb":[[0,2.06,27.04]],"ltp":2.22,"tv":307.21,"id":5901}]}]}
{"op":"mcm","clk":"11797196348","pt":1723021050268,"mc":[{"id":"1.231431354","rc":[{"batb":[[0,2.06,17.04]],"ltp":2.22,"tv":307.21,"id":5901}]}]}
{"op":"mcm","clk":"11797196374","pt":1723021050733,"mc":[{"id":"1.231431354","rc":[{"batb":[[0,2.04,17.37],[1,2.02,17.71],[2,2,55.88]],"ltp":2.22,"tv":307.21,"id":5901}]}]}
{"op":"mcm","clk":"11797197407","pt":1723021068883,"mc":[{"id":"1.231431354","rc":[{"batb":[[0,2.06,10],[1,2.04,17.37],[2,2.02,17.71]],"ltp":2.22,"tv":307.21,"id":5901}]}]}
{"op":"mcm","clk":"11797197522","pt":1723021070784,"mc":[{"id":"1.231431354","rc":[{"batb":[[0,2.06,27.04]],"ltp":2.22,"tv":307.21,"id":5901}]}]}
{"op":"mcm","clk":"11797197610","pt":1723021072381,"mc":[{"id":"1.231431354","rc":[{"batb":[[0,2.04,17.37],[1,2.02,17.71],[2,2,55.88]],"ltp":2.22,"tv":307.21,"id":5901}]}]}
{"op":"mcm","clk":"11797201030","pt":1723021125952,"mc":[{"id":"1.231431354","rc":[{"batb":[[0,2.06,10],[1,2.04,17.37],[2,2.02,17.71]],"ltp":2.22,"tv":307.21,"id":5901}]}]}
{"op":"mcm","clk":"11797201156","pt":1723021127819,"mc":[{"id":"1.231431354","rc":[{"batb":[[0,2.06,27.04]],"ltp":2.22,"tv":307.21,"id":5901}]}]}
{"op":"mcm","clk":"11797201260","pt":1723021129458,"mc":[{"id":"1.231431354","rc":[{"batb":[[0,2.04,17.37],[1,2.02,17.71],[2,2,55.88]],"ltp":2.22,"tv":307.21,"id":5901}]}]}
{"op":"mcm","clk":"11797202380","pt":1723021148557,"mc":[{"id":"1.231431354","rc":[{"batb":[[0,2.06,10],[1,2.04,17.37],[2,2.02,17.71]],"ltp":2.22,"tv":307.21,"id":5901}]}]}
{"op":"mcm","clk":"11797202480","pt":1723021150358,"mc":[{"id":"1.231431354","rc":[{"batb":[[0,2.06,27.04]],"ltp":2.22,"tv":307.21,"id":5901}]}]}
{"op":"mcm","clk":"11797202598","pt":1723021152457,"mc":[{"id":"1.231431354","rc":[{"batb":[[0,2.04,17.37],[1,2.02,17.71],[2,2,55.88]],"ltp":2.22,"tv":307.21,"id":5901}]}]}
{"op":"mcm","clk":"11797203157","pt":1723021162067,"mc":[{"id":"1.231431354","rc":[{"batb":[[0,2.06,10],[1,2.04,17.37],[2,2.02,17.71]],"ltp":2.22,"tv":307.21,"id":5901}]}]}
{"op":"mcm","clk":"11797203263","pt":1723021163867,"mc":[{"id":"1.231431354","rc":[{"batb":[[0,2.06,27.04]],"ltp":2.22,"tv":307.21,"id":5901}]}]}
{"op":"mcm","clk":"11797203346","pt":1723021165257,"mc":[{"id":"1.231431354","rc":[{"batb":[[0,2.06,17.04]],"ltp":2.22,"tv":307.21,"id":5901}]}]}
{"op":"mcm","clk":"11797203386","pt":1723021165875,"mc":[{"id":"1.231431354","rc":[{"batb":[[0,2.04,17.37],[1,2.02,17.71],[2,2,55.88]],"ltp":2.22,"tv":307.21,"id":5901}]}]}
{"op":"mcm","clk":"11797205768","pt":1723021202505,"mc":[{"id":"1.231431354","rc":[{"batb":[[2,2,18.06]],"ltp":2.22,"tv":307.21,"id":5901},{"batb":[[0,1.81,22.31]],"ltp":1.86,"tv":829.0,"id":31372}]}]}
{"op":"mcm","clk":"11797205806","pt":1723021202918,"mc":[{"id":"1.231431354","rc":[{"batb":[[0,2.06,10],[1,2.04,17.37],[2,2.02,17.71]],"ltp":2.22,"tv":307.21,"id":5901},{"batb":[[0,1.8,4.5],[1,1.74,41.73],[2,1.51,7.73]],"ltp":1.86,"tv":829.0,"id":31372}]}]}
{"op":"mcm","clk":"11797205987","pt":1723021204906,"mc":[{"id":"1.231431354","rc":[{"batb":[[0,2.06,27.03],[1,2.04,17.36],[2,2.02,17.7]],"ltp":2.22,"tv":307.21,"id":5901},{"trd":[[1.86,136.29],[1.88,229.97]],"batb":[[1,1.74,41.72],[2,1.51,7.74]],"ltp":1.86,"tv":828.98,"id":31372}],"tv":1136.2}]}
{"op":"mcm","clk":"11797206122","pt":1723021206413,"mc":[{"id":"1.231431354","rc":[{"batb":[[0,2.04,17.36],[1,2.02,17.7],[2,2,18.05]],"ltp":2.22,"tv":307.21,"id":5901}]}]}
{"op":"mcm","clk":"11797207057","pt":1723021217213,"mc":[{"id":"1.231431354","rc":[{"batb":[[0,2.06,10],[1,2.04,17.36],[2,2.02,17.7]],"ltp":2.22,"tv":307.21,"id":5901},{"batl":[[2,1.96,4.5]],"ltp":1.86,"tv":828.98,"id":31372}]}]}
{"op":"mcm","clk":"11797207248","pt":1723021219440,"mc":[{"id":"1.231431354","rc":[{"batb":[[0,2.06,27.03]],"ltp":2.22,"tv":307.21,"id":5901}]}]}
{"op":"mcm","clk":"11797207333","pt":1723021220430,"mc":[{"id":"1.231431354","rc":[{"batb":[[0,2.06,17.03]],"ltp":2.22,"tv":307.21,"id":5901}]}]}
{"op":"mcm","clk":"11797207369","pt":1723021220947,"mc":[{"id":"1.231431354","rc":[{"batb":[[0,2,18.05],[1,1.95,4.5],[2,1.74,17.32]],"ltp":2.22,"tv":307.21,"id":5901}]}]}
{"op":"mcm","clk":"11797207517","pt":1723021222752,"mc":[{"id":"1.231431354","rc":[{"batb":[[0,2.02,10],[1,2,23.05],[2,1.95,4.5]],"ltp":2.22,"tv":307.21,"id":5901}]}]}
{"op":"mcm","clk":"11797207752","pt":1723021225440,"mc":[{"id":"1.231431354","rc":[{"batb":[[0,2.02,27.7]],"ltp":2.22,"tv":307.21,"id":5901}]}]}
{"op":"mcm","clk":"11797207839","pt":1723021226426,"mc":[{"id":"1.231431354","rc":[{"batb":[[0,2,23.05],[1,1.95,4.5],[2,1.74,17.32]],"ltp":2.22,"tv":307.21,"id":5901}]}]}
{"op":"mcm","clk":"11797210028","pt":1723021260462,"mc":[{"id":"1.231431354","rc":[{"trd":[[2.2,1.18]],"batb":[[0,2.02,10],[1,2,23.05],[2,1.95,4.5]],"batl":[[0,2.2,8.43]],"ltp":2.2,"tv":308.39,"id":5901}],"tv":1137.37}]}
{"op":"mcm","clk":"11797210157","pt":1723021262476,"mc":[{"id":"1.231431354","rc":[{"batb":[[0,2.02,27.7]],"ltp":2.2,"tv":308.39,"id":5901}]}]}
{"op":"mcm","clk":"11797210192","pt":1723021262993,"mc":[{"id":"1.231431354","rc":[{"batb":[[1,2,18.05]],"ltp":2.2,"tv":308.39,"id":5901}]}]}
{"op":"mcm","clk":"11797210282","pt":1723021264492,"mc":[{"id":"1.231431354","rc":[{"batb":[[0,2,18.05],[1,1.95,4.5],[2,1.74,17.32]],"ltp":2.2,"tv":308.39,"id":5901}]}]}
{"op":"mcm","clk":"11797210539","pt":1723021268289,"mc":[{"id":"1.231431354","rc":[{"batb":[[0,2.02,10],[1,2,23.05],[2,1.95,4.5]],"ltp":2.2,"tv":308.39,"id":5901}]}]}
{"op":"mcm","clk":"11797210706","pt":1723021270506,"mc":[{"id":"1.231431354","rc":[{"batb":[[0,2.02,27.7]],"ltp":2.2,"tv":308.39,"id":5901}]}]}
{"op":"mcm","clk":"11797210808","pt":1723021272001,"mc":[{"id":"1.231431354","rc":[{"batb":[[0,2,23.05],[1,1.95,4.5],[2,1.74,17.32]],"ltp":2.2,"tv":308.39,"id":5901}]}]}
{"op":"mcm","clk":"11797221180","pt":1723021418095,"mc":[{"id":"1.231431354","rc":[{"batb":[[0,2.12,9.02],[1,2,23.05],[2,1.95,4.5]],"ltp":2.2,"tv":308.39,"id":5901}]}]}
{"op":"mcm","clk":"11797221342","pt":1723021420558,"mc":[{"id":"1.231431354","rc":[{"batb":[[1,2.06,17.03],[2,2,23.05]],"ltp":2.2,"tv":308.39,"id":5901}]}]}
{"op":"mcm","clk":"11797221576","pt":1723021424266,"mc":[{"id":"1.231431354","rc":[{"batb":[[2,2,18.05]],"ltp":2.2,"tv":308.39,"id":5901}]}]}
{"op":"mcm","clk":"11797222289","pt":1723021436098,"mc":[{"id":"1.231431354","rc":[{"batl":[[0,1.9,70.25]],"ltp":1.86,"tv":828.98,"id":31372}]}]}
{"op":"mcm","clk":"11797222474","pt":1723021438613,"mc":[{"id":"1.231431354","rc":[{"batb":[[1,2.1,16.41],[2,2.06,17.03]],"ltp":2.2,"tv":308.39,"id":5901}]}]}
{"op":"mcm","clk":"11797222744","pt":1723021442792,"mc":[{"id":"1.231431354","rc":[{"batl":[[0,1.9,68.25]],"ltp":1.86,"tv":828.98,"id":31372}]}]}
{"op":"mcm","clk":"11797223831","pt":1723021460734,"mc":[{"id":"1.231431354","rc":[{"batl":[[2,4.3,0.24]],"ltp":2.2,"tv":308.39,"id":5901}]}]}
{"op":"mcm","clk":"11797227067","pt":1723021511692,"mc":[{"id":"1.231431354","rc":[{"batl":[[0,1.88,9.02],[1,1.9,68.25],[2,1.94,10]],"ltp":1.86,"tv":828.98,"id":31372}]}]}
{"op":"mcm","clk":"11797244202","pt":1723021826036,"mc":[{"id":"1.231431354","rc":[{"batb":[[0,1.74,41.72],[1,1.51,7.74],[2,1.48,104.17]],"ltp":1.86,"tv":828.98,"id":31372}]}]}
{"op":"mcm","clk":"11797244853","pt":1723021836272,"mc":[{"id":"1.231431354","rc":[{"batl":[[0,1.87,2.25],[1,1.88,9.02],[2,1.9,68.25]],"ltp":1.86,"tv":828.98,"id":31372}]}]}
{"op":"mcm","clk":"11797245088","pt":1723021839581,"mc":[{"id":"1.231431354","rc":[{"batl":[[2,1.9,66]],"ltp":1.86,"tv":828.98,"id":31372}]}]}
{"op":"mcm","clk":"11797261835","pt":1723022003969,"mc":[{"id":"1.231431354","rc":[{"trd":[[2.14,0.46]],"ltp":2.14,"tv":308.85,"id":5901},{"trd":[[1.87,102.52]],"batl":[[0,1.87,1.73]],"ltp":1.87,"tv":829.5,"id":31372}],"tv":1138.35}]}
{"op":"mcm","clk":"11797262782","pt":1723022019996,"mc":[{"id":"1.231431354","rc":[{"batl":[[2,4.3,0.69]],"ltp":2.14,"tv":308.85,"id":5901}]}]}
{"op":"mcm","clk":"11797263427","pt":1723022033214,"mc":[{"id":"1.231431354","rc":[{"batl":[[2,3,1.37]],"ltp":2.14,"tv":308.85,"id":5901}]}]}
{"op":"mcm","clk":"11797277399","pt":1723022274765,"mc":[{"id":"1.231431354","rc":[{"batl":[[0,1.88,9.76],[1,1.9,66],[2,1.94,10]],"ltp":1.87,"tv":829.5,"id":31372}]}]}
{"op":"mcm","clk":"11797288096","pt":1723022475841,"mc":[{"id":"1.231431354","rc":[{"batl":[[2,1.92,50]],"ltp":1.87,"tv":829.5,"id":31372}]}]}
{"op":"mcm","clk":"11797289707","pt":1723022502464,"mc":[{"id":"1.231431354","rc":[{"batl":[[1,1.92,50],[2,1.94,10]],"ltp":1.87,"tv":829.5,"id":31372}]}]}
{"op":"mcm","clk":"11797289715","pt":1723022502563,"mc":[{"id":"1.231431354","rc":[{"batl":[[0,1.88,75.76]],"ltp":1.87,"tv":829.5,"id":31372}]}]}
{"op":"mcm","clk":"11797291390","pt":1723022526486,"mc":[{"id":"1.231431354","rc":[{"trd":[[2.12,171.37],[2.14,1.11]],"batb":[[0,2.1,16.41],[1,2.06,17.03],[2,2,18.05]],"ltp":2.12,"tv":392.87,"id":5901},{"trd":[[1.87,103.26],[1.88,303.64]],"batl":[[0,1.88,1.35]],"ltp":1.88,"tv":903.91,"id":31372}],"tv":1296.78}]}
{"op":"mcm","clk":"11797291425","pt":1723022527098,"mc":[{"id":"1.231431354","rc":[{"batb":[[0,2.12,10]],"ltp":2.12,"tv":392.87,"id":5901}]}]}
{"op":"mcm","clk":"11797291458","pt":1723022527565,"mc":[{"id":"1.231431354","rc":[{"batb":[[1,2.08,16.71],[2,2.06,17.03]],"ltp":2.12,"tv":392.87,"id":5901}]}]}
{"op":"mcm","clk":"11797291615","pt":1723022529789,"mc":[{"id":"1.231431354","rc":[{"batb":[[0,2.08,16.71],[1,2.06,17.03],[2,2,18.05]],"ltp":2.12,"tv":392.87,"id":5901}]}]}
{"op":"mcm","clk":"11797292333","pt":1723022541206,"mc":[{"id":"1.231431354","rc":[{"batb":[[0,2.1,10],[1,2.08,16.71],[2,2.06,17.03]],"ltp":2.12,"tv":392.87,"id":5901}]}]}
{"op":"mcm","clk":"11797292555","pt":1723022544513,"mc":[{"id":"1.231431354","rc":[{"batb":[[0,2.08,16.71],[1,2.06,17.03],[2,2,18.05]],"ltp":2.12,"tv":392.87,"id":5901}]}]}
{"op":"mcm","clk":"11797294391","pt":1723022575649,"mc":[{"id":"1.231431354","rc":[{"batb":[[0,2.1,10],[1,2.08,16.71],[2,2.06,17.03]],"ltp":2.12,"tv":392.87,"id":5901}]}]}
{"op":"mcm","clk":"11797294600","pt":1723022578949,"mc":[{"id":"1.231431354","rc":[{"batb":[[0,2.08,16.71],[1,2.06,17.03],[2,2,18.05]],"ltp":2.12,"tv":392.87,"id":5901}]}]}
{"op":"mcm","clk":"11797301016","pt":1723022678547,"mc":[{"id":"1.231431354","rc":[{"batb":[[0,2.1,10],[1,2.08,16.71],[2,2.06,17.03]],"ltp":2.12,"tv":392.87,"id":5901}]}]}
{"op":"mcm","clk":"11797301257","pt":1723022681869,"mc":[{"id":"1.231431354","rc":[{"batb":[[0,2.08,16.71],[1,2.06,17.03],[2,2,18.05]],"ltp":2.12,"tv":392.87,"id":5901}]}]}
{"op":"mcm","clk":"11797301653","pt":1723022687765,"mc":[{"id":"1.231431354","rc":[{"batb":[[0,2.1,10],[1,2.08,16.71],[2,2.06,17.03]],"ltp":2.12,"tv":392.87,"id":5901}]}]}
{"op":"mcm","clk":"11797301845","pt":1723022690972,"mc":[{"id":"1.231431354","rc":[{"batb":[[0,2.08,16.71],[1,2.06,17.03],[2,2,18.05]],"ltp":2.12,"tv":392.87,"id":5901}]}]}
{"op":"mcm","clk":"11797306201","pt":1723022749620,"mc":[{"id":"1.231431354","rc":[{"batb":[[0,2.1,10],[1,2.08,16.71],[2,2.06,17.03]],"ltp":2.12,"tv":392.87,"id":5901}]}]}
{"op":"mcm","clk":"11797306475","pt":1723022752847,"mc":[{"id":"1.231431354","rc":[{"batb":[[0,2.08,16.71],[1,2.06,17.03],[2,2,18.05]],"ltp":2.12,"tv":392.87,"id":5901}]}]}
{"op":"mcm","clk":"11797307064","pt":1723022760849,"mc":[{"id":"1.231431354","rc":[{"batb":[[0,2.1,10],[1,2.08,16.71],[2,2.06,17.03]],"ltp":2.12,"tv":392.87,"id":5901}]}]}
{"op":"mcm","clk":"11797307338","pt":1723022764165,"mc":[{"id":"1.231431354","rc":[{"batb":[[0,2.08,16.71],[1,2.06,17.03],[2,2,18.05]],"ltp":2.12,"tv":392.87,"id":5901}]}]}
{"op":"mcm","clk":"11797310241","pt":1723022807888,"mc":[{"id":"1.231431354","rc":[{"batb":[[0,2.1,10],[1,2.08,16.71],[2,2.06,17.03]],"ltp":2.12,"tv":392.87,"id":5901},{"batb":[[2,1.2,11]],"ltp":1.88,"tv":903.91,"id":31372}]}]}
{"op":"mcm","clk":"11797310412","pt":1723022811245,"mc":[{"id":"1.231431354","rc":[{"batb":[[0,2.08,16.71],[1,2.06,17.03],[2,2,18.05]],"ltp":2.12,"tv":392.87,"id":5901}]}]}
{"op":"mcm","clk":"11797314783","pt":1723022880496,"mc":[{"id":"1.231431354","rc":[{"batb":[[0,2.1,10],[1,2.08,16.71],[2,2.06,17.03]],"ltp":2.12,"tv":392.87,"id":5901},{"batl":[[1,1.92,75.81]],"ltp":1.88,"tv":903.91,"id":31372}]}]}
{"op":"mcm","clk":"11797314984","pt":1723022883681,"mc":[{"id":"1.231431354","rc":[{"batb":[[0,2.08,16.71],[1,2.06,17.03],[2,2,18.05]],"ltp":2.12,"tv":392.87,"id":5901}]}]}
{"op":"mcm","clk":"11797316084","pt":1723022901996,"mc":[{"id":"1.231431354","rc":[{"batb":[[0,2.1,10],[1,2.08,16.71],[2,2.06,17.03]],"ltp":2.12,"tv":392.87,"id":5901}]}]}
{"op":"mcm","clk":"11797316270","pt":1723022905317,"mc":[{"id":"1.231431354","rc":[{"batb":[[0,2.08,16.71],[1,2.06,17.03],[2,2,18.05]],"ltp":2.12,"tv":392.87,"id":5901}]}]}
{"op":"mcm","clk":"11797317019","pt":1723022917349,"mc":[{"id":"1.231431354","rc":[{"batb":[[0,2.1,10],[1,2.08,16.71],[2,2.06,17.03]],"ltp":2.12,"tv":392.87,"id":5901}]}]}
{"op":"mcm","clk":"11797317231","pt":1723022920633,"mc":[{"id":"1.231431354","rc":[{"batb":[[0,2.08,16.71],[1,2.06,17.03],[2,2,18.05]],"ltp":2.12,"tv":392.87,"id":5901}]}]}
{"op":"mcm","clk":"11797319236","pt":1723022950656,"mc":[{"id":"1.231431354","rc":[{"batb":[[0,2.1,10],[1,2.08,16.71],[2,2.06,17.03]],"ltp":2.12,"tv":392.87,"id":5901}]}]}
{"op":"mcm","clk":"11797319502","pt":1723022953961,"mc":[{"id":"1.231431354","rc":[{"batb":[[0,2.08,16.71],[1,2.06,17.03],[2,2,18.05]],"ltp":2.12,"tv":392.87,"id":5901}]}]}
{"op":"mcm","clk":"11797319686","pt":1723022956483,"mc":[{"id":"1.231431354","rc":[{"batb":[[0,2.1,10],[1,2.08,16.71],[2,2.06,17.03]],"ltp":2.12,"tv":392.87,"id":5901},{"batb":[[2,1.48,104.17]],"ltp":1.88,"tv":903.91,"id":31372}]}]}
{"op":"mcm","clk":"11797319864","pt":1723022959374,"mc":[{"id":"1.231431354","rc":[{"batb":[[0,2.08,16.71],[1,2.06,17.03],[2,2,18.05]],"ltp":2.12,"tv":392.87,"id":5901}]}]}
{"op":"mcm","clk":"11797321256","pt":1723022979820,"mc":[{"id":"1.231431354","rc":[{"batb":[[0,2.1,10],[1,2.08,16.71],[2,2.06,17.03]],"ltp":2.12,"tv":392.87,"id":5901},{"batb":[[1,1.48,104.17],[2,1.43,116.28]],"ltp":1.88,"tv":903.91,"id":31372}]}]}
{"op":"mcm","clk":"11797321515","pt":1723022983098,"mc":[{"id":"1.231431354","rc":[{"batb":[[0,2.08,16.71],[1,2.06,17.03],[2,2,18.05]],"ltp":2.12,"tv":392.87,"id":5901}]}]}
{"op":"mcm","clk":"11797322160","pt":1723022991015,"mc":[{"id":"1.231431354","rc":[{"batb":[[0,2.1,10],[1,2.08,16.71],[2,2.06,17.03]],"ltp":2.12,"tv":392.87,"id":5901},{"batb":[[1,1.48,111.91]],"ltp":1.88,"tv":903.91,"id":31372}]}]}
{"op":"mcm","clk":"11797322426","pt":1723022994318,"mc":[{"id":"1.231431354","rc":[{"batb":[[0,2.08,16.71],[1,2.06,17.03],[2,2,18.05]],"ltp":2.12,"tv":392.87,"id":5901}]}]}
{"op":"mcm","clk":"11797322748","pt":1723022998496,"mc":[{"id":"1.231431354","rc":[{"batb":[[0,2.1,10],[1,2.08,16.71],[2,2.06,17.03]],"ltp":2.12,"tv":392.87,"id":5901},{"batb":[[1,1.5,7.74],[2,1.48,104.17]],"ltp":1.88,"tv":903.91,"id":31372}]}]}
{"op":"mcm","clk":"11797323027","pt":1723023001729,"mc":[{"id":"1.231431354","rc":[{"batb":[[0,2.08,16.71],[1,2.06,17.03],[2,2,18.05]],"ltp":2.12,"tv":392.87,"id":5901}]}]}
{"op":"mcm","clk":"11797324150","pt":1723023014239,"mc":[{"id":"1.231431354","rc":[{"batb":[[0,2.1,10],[1,2.08,16.71],[2,2.06,17.03]],"ltp":2.12,"tv":392.87,"id":5901},{"batb":[[1,1.53,102.08]],"ltp":1.88,"tv":903.91,"id":31372}]}]}
{"op":"mcm","clk":"11797324415","pt":1723023017139,"mc":[{"id":"1.231431354","rc":[{"batb":[[0,2.08,16.71],[1,2.06,17.03],[2,2,18.05]],"ltp":2.12,"tv":392.87,"id":5901}]}]}
{"op":"mcm","clk":"11797329113","pt":1723023074457,"mc":[{"id":"1.231431354","rc":[{"batb":[[0,2.1,10],[1,2.08,16.71],[2,2.06,17.03]],"ltp":2.12,"tv":392.87,"id":5901},{"batl":[[0,1.87,333],[1,1.88,1.35],[2,1.92,75.81]],"ltp":1.88,"tv":903.91,"id":31372}]}]}
{"op":"mcm","clk":"11797329255","pt":1723023076175,"mc":[{"id":"1.231431354","rc":[{"trd":[[2.2,9.61]],"batl":[[0,2.22,8.72],[1,3,1.37],[2,6.6,1.7]],"ltp":2.2,"tv":401.3,"id":5901},{"trd":[[1.83,10.13]],"batl":[[0,1.83,322.87],[1,1.87,333],[2,1.88,1.35]],"ltp":1.83,"tv":914.04,"id":31372}],"tv":1315.34}]}
{"op":"mcm","clk":"11797329338","pt":1723023077149,"mc":[{"id":"1.231431354","rc":[{"batb":[[0,2.14,15.83],[1,2.1,10],[2,2.08,16.71]],"ltp":2.2,"tv":401.3,"id":5901},{"batb":[[0,1.74,17.32],[1,1.53,136.14]],"batl":[[0,1.87,333],[1,1.88,1.35],[2,1.92,75.81]],"ltp":1.83,"tv":914.04,"id":31372}]}]}
{"op":"mcm","clk":"11797329395","pt":1723023077973,"mc":[{"id":"1.231431354","rc":[{"batb":[[0,2.12,16.12],[1,2.08,16.71],[2,2.06,17.03]],"ltp":2.2,"tv":401.3,"id":5901}]}]}
{"op":"mcm","clk":"11797331617","pt":1723023104414,"mc":[{"id":"1.231431354","rc":[{"batb":[[0,2.14,10],[1,2.12,16.12],[2,2.08,16.71]],"ltp":2.2,"tv":401.3,"id":5901}]}]}
{"op":"mcm","clk":"11797331907","pt":1723023107798,"mc":[{"id":"1.231431354","rc":[{"batb":[[0,2.12,16.12],[1,2.08,16.71],[2,2.06,17.03]],"ltp":2.2,"tv":401.3,"id":5901}]}]}
{"op":"mcm","clk":"11797333665","pt":1723023128006,"mc":[{"id":"1.231431354","rc":[{"batb":[[0,2.14,10],[1,2.12,16.12],[2,2.08,16.71]],"ltp":2.2,"tv":401.3,"id":5901}]}]}
{"op":"mcm","clk":"11797333913","pt":1723023131410,"mc":[{"id":"1.231431354","rc":[{"batb":[[0,2.12,16.12],[1,2.08,16.71],[2,2.06,17.03]],"ltp":2.2,"tv":401.3,"id":5901}]}]}
{"op":"mcm","clk":"11797334204","pt":1723023135145,"mc":[{"id":"1.231431354","rc":[{"batb":[[0,2.14,10],[1,2.12,16.12],[2,2.08,16.71]],"ltp":2.2,"tv":401.3,"id":5901}]}]}
{"op":"mcm","clk":"11797334466","pt":1723023138353,"mc":[{"id":"1.231431354","rc":[{"batb":[[0,2.12,16.12],[1,2.08,16.71],[2,2.06,17.03]],"ltp":2.2,"tv":401.3,"id":5901}]}]}
{"op":"mcm","clk":"11797334941","pt":1723023145121,"mc":[{"id":"1.231431354","rc":[{"batb":[[0,2.14,10],[1,2.12,16.12],[2,2.08,16.71]],"ltp":2.2,"tv":401.3,"id":5901},{"batl":[[0,1.86,2.22],[1,1.87,333],[2,1.88,1.35]],"ltp":1.83,"tv":914.04,"id":31372}]}]}
{"op":"mcm","clk":"11797334999","pt":1723023146050,"mc":[{"id":"1.231431354","rc":[{"batb":[[0,2.14,25.83]],"ltp":2.2,"tv":401.3,"id":5901}]}]}
{"op":"mcm","clk":"11797335163","pt":1723023148362,"mc":[{"id":"1.231431354","rc":[{"batb":[[0,2.14,15.83]],"ltp":2.2,"tv":401.3,"id":5901}]}]}
{"op":"mcm","clk":"11797342862","pt":1723023257909,"mc":[{"id":"1.231431354","rc":[{"batl":[[0,1.85,18.04],[1,1.86,2.22],[2,1.87,333]],"ltp":1.83,"tv":914.04,"id":31372}]}]}
{"op":"mcm","clk":"11797343657","pt":1723023269903,"mc":[{"id":"1.231431354","rc":[{"batl":[[0,1.86,2.22],[1,1.87,333],[2,1.88,1.35]],"ltp":1.83,"tv":914.04,"id":31372}]}]}
{"op":"mcm","clk":"11797350986","pt":1723023376766,"mc":[{"id":"1.231431354","rc":[{"trd":[[2.14,35.03],[2.16,75.91]],"batb":[[0,2.14,10]],"ltp":2.14,"tv":437.13,"id":5901},{"trd":[[1.86,138.51],[1.87,105.85]],"batl":[[0,1.87,330.41],[1,1.88,1.35],[2,1.92,75.81]],"ltp":1.87,"tv":918.85,"id":31372}],"tv":1355.98}]}
{"op":"mcm","clk":"11797351229","pt":1723023380149,"mc":[{"id":"1.231431354","rc":[{"batb":[[0,2.12,16.12],[1,2.08,16.71],[2,2.06,17.03]],"ltp":2.14,"tv":437.13,"id":5901}]}]}
{"op":"mcm","clk":"11797351567","pt":1723023384268,"mc":[{"id":"1.231431354","rc":[{"batb":[[0,2.14,10],[1,2.12,16.12],[2,2.08,16.71]],"ltp":2.14,"tv":437.13,"id":5901},{"batb":[[1,1.55,11.02],[2,1.53,136.14]],"ltp":1.87,"tv":918.85,"id":31372}]}]}
{"op":"mcm","clk":"11797351616","pt":1723023384850,"mc":[{"id":"1.231431354","rc":[{"batb":[[1,1.55,18.77],[2,1.53,128.4]],"ltp":1.87,"tv":918.85,"id":31372}]}]}
{"op":"mcm","clk":"11797351730","pt":1723023386390,"mc":[{"id":"1.231431354","rc":[{"batb":[[1,1.55,51.59]],"ltp":1.87,"tv":918.85,"id":31372}]}]}
{"op":"mcm","clk":"11797351811","pt":1723023387532,"mc":[{"id":"1.231431354","rc":[{"batb":[[0,2.12,16.12],[1,2.08,16.71],[2,2.06,17.03]],"ltp":2.14,"tv":437.13,"id":5901}]}]}
{"op":"mcm","clk":"11797354164","pt":1723023422303,"mc":[{"id":"1.231431354","rc":[{"batb":[[0,2.14,10],[1,2.12,16.12],[2,2.08,16.71]],"ltp":2.14,"tv":437.13,"id":5901}]}]}
{"op":"mcm","clk":"11797354408","pt":1723023425618,"mc":[{"id":"1.231431354","rc":[{"batb":[[0,2.12,16.12],[1,2.08,16.71],[2,2.06,17.03]],"ltp":2.14,"tv":437.13,"id":5901}]}]}
{"op":"mcm","clk":"11797357000","pt":1723023461950,"mc":[{"id":"1.231431354","rc":[{"batb":[[0,2.14,10],[1,2.12,16.12],[2,2.1,9.02]],"ltp":2.14,"tv":437.13,"id":5901}]}]}
{"op":"mcm","clk":"11797357229","pt":1723023465254,"mc":[{"id":"1.231431354","rc":[{"batb":[[0,2.12,16.12],[1,2.1,9.02],[2,2.08,16.71]],"ltp":2.14,"tv":437.13,"id":5901}]}]}
{"op":"mcm","clk":"11797360208","pt":1723023510388,"mc":[{"id":"1.231431354","rc":[{"batb":[[0,2.14,10],[1,2.12,16.12],[2,2.1,9.02]],"ltp":2.14,"tv":437.13,"id":5901},{"batl":[[0,1.84,283.06],[1,1.87,330.41],[2,1.88,1.35]],"ltp":1.87,"tv":918.85,"id":31372}]}]}
{"op":"mcm","clk":"11797360343","pt":1723023512203,"mc":[{"id":"1.231431354","rc":[{"batb":[[0,2.14,25.83]],"ltp":2.14,"tv":437.13,"id":5901}]}]}
{"op":"mcm","clk":"11797360375","pt":1723023512575,"mc":[{"id":"1.231431354","rc":[{"batb":[[0,2.16,15.56],[1,2.14,25.83],[2,2.12,16.12]],"ltp":2.14,"tv":437.13,"id":5901}]}]}
{"op":"mcm","clk":"11797360453","pt":1723023513602,"mc":[{"id":"1.231431354","rc":[{"batb":[[1,2.14,15.83]],"ltp":2.14,"tv":437.13,"id":5901}]}]}
{"op":"mcm","clk":"11797361403","pt":1723023528501,"mc":[{"id":"1.231431354","rc":[{"batl":[[0,1.83,1.35],[1,1.84,283.06],[2,1.87,330.41]],"ltp":1.87,"tv":918.85,"id":31372}]}]}
{"op":"mcm","clk":"11797361479","pt":1723023529587,"mc":[{"id":"1.231431354","rc":[{"batb":[[0,2.18,15.3],[1,2.16,15.56],[2,2.14,15.83]],"ltp":2.14,"tv":437.13,"id":5901}]}]}
{"op":"mcm","clk":"11797361719","pt":1723023533699,"mc":[{"id":"1.231431354","rc":[{"batl":[[0,1.83,5.35]],"ltp":1.87,"tv":918.85,"id":31372}]}]}
{"op":"mcm","clk":"11797364531","pt":1723023578382,"mc":[{"id":"1.231431354","rc":[{"trd":[[2.22,0.95]],"batl":[[0,2.22,8.33]],"ltp":2.22,"tv":437.52,"id":5901},{"trd":[[1.81,4.47]],"ltp":1.81,"tv":919.32,"id":31372}],"tv":1356.85}]}
{"op":"mcm","clk":"11797366022","pt":1723023600855,"mc":[{"id":"1.231431354","rc":[{"batb":[[0,1.81,93.39],[1,1.74,17.32],[2,1.55,51.59]],"ltp":1.81,"tv":919.32,"id":31372}]}]}
{"op":"mcm","clk":"11797366180","pt":1723023603279,"mc":[{"id":"1.231431354","rc":[{"batb":[[1,1.8,22.57],[2,1.74,17.32]],"ltp":1.81,"tv":919.32,"id":31372}]}]}
{"op":"mcm","clk":"11797366793","pt":1723023612567,"mc":[{"id":"1.231431354","rc":[{"trd":[[1.81,4.67]],"batb":[[0,1.81,93.29]],"ltp":1.81,"tv":919.52,"id":31372}],"tv":1357.05}]}
{"op":"mcm","clk":"11797367038","pt":1723023615972,"mc":[{"id":"1.231431354","rc":[{"batb":[[0,1.81,93.39]],"ltp":1.81,"tv":919.52,"id":31372}]}]}
{"op":"mcm","clk":"11797368565","pt":1723023636404,"mc":[{"id":"1.231431354","rc":[{"trd":[[1.81,6.12]],"batb":[[0,1.81,92.67]],"ltp":1.81,"tv":920.96,"id":31372}],"tv":1358.49}]}
{"op":"mcm","clk":"11797368902","pt":1723023641025,"mc":[{"id":"1.231431354","rc":[{"batb":[[0,1.81,93.39]],"ltp":1.81,"tv":920.96,"id":31372}]}]}
{"op":"mcm","clk":"11797373228","pt":1723023704998,"mc":[{"id":"1.231431354","rc":[{"batl":[[2,3.4,1.46]],"ltp":2.22,"tv":437.52,"id":5901}]}]}
{"op":"mcm","clk":"11797373814","pt":1723023713413,"mc":[{"id":"1.231431354","rc":[{"trd":[[1.83,20.83],[1.84,198.04]],"batl":[[0,1.84,252.04],[1,1.87,330.41],[2,1.92,75.81]],"ltp":1.84,"tv":993.69,"id":31372}],"tv":1431.22}]}
{"op":"mcm","clk":"11797376310","pt":1723023748843,"mc":[{"id":"1.231431354","rc":[{"trd":[[2.18,0.2]],"batb":[[0,2.18,15.2]],"ltp":2.18,"tv":437.73,"id":5901}],"tv":1431.43}]}
{"op":"mcm","clk":"11797380801","pt":1723023814710,"mc":[{"id":"1.231431354","rc":[{"trd":[[2.22,8.17]],"batl":[[0,2.22,4.72]],"ltp":2.22,"tv":444.95,"id":5901}],"tv":1438.65}]}
{"op":"mcm","clk":"11797382309","pt":1723023838458,"mc":[{"id":"1.231431354","rc":[{"trd":[[1.81,8.1]],"batb":[[0,1.81,92.4]],"ltp":1.81,"tv":995.67,"id":31372}],"tv":1440.63}]}
{"op":"mcm","clk":"11797382561","pt":1723023842066,"mc":[{"id":"1.231431354","rc":[{"batb":[[0,1.81,93.39]],"ltp":1.81,"tv":995.67,"id":31372}]}]}
{"op":"mcm","clk":"11797383214","pt":1723023851054,"mc":[{"id":"1.231431354","rc":[{"trd":[[2.18,215.4]],"batb":[[0,2.16,15.56],[1,2.14,15.83],[2,2.12,16.12]],"ltp":2.18,"tv":660.14,"id":5901},{"trd":[[1.84,416.99]],"batl":[[0,1.84,33.09]],"ltp":1.84,"tv":1214.62,"id":31372}],"tv":1874.77}]}
{"op":"mcm","clk":"11797384154","pt":1723023865469,"mc":[{"id":"1.231431354","rc":[{"trd":[[2.22,8.58]],"batl":[[0,2.22,4.52]],"ltp":2.22,"tv":660.55,"id":5901}],"tv":1875.18}]}
{"op":"mcm","clk":"11797387029","pt":1723023908074,"mc":[{"id":"1.231431354","rc":[{"trd":[[2.18,224.42]],"ltp":2.18,"tv":669.57,"id":5901},{"trd":[[1.84,427.68]],"batl":[[0,1.84,22.4]],"ltp":1.84,"tv":1225.31,"id":31372}],"tv":1894.89}]}
{"op":"mcm","clk":"11797388477","pt":1723023929279,"mc":[{"id":"1.231431354","rc":[{"batb":[[0,2.14,15.83],[1,2.12,16.12],[2,2.1,9.02]],"ltp":2.18,"tv":669.57,"id":5901},{"trd":[[1.84,472.48]],"batb":[[0,1.85,77.6],[1,1.81,115.68],[2,1.8,22.57]],"batl":[[0,1.87,330.41],[1,1.92,75.81],[2,1.94,10]],"ltp":1.84,"tv":1270.11,"id":31372}],"tv":1939.69}]}
{"op":"mcm","clk":"11797388515","pt":1723023929800,"mc":[{"id":"1.231431354","rc":[{"batb":[[0,2.12,16.12],[1,2.1,9.02],[2,2,75.64]],"ltp":2.18,"tv":669.57,"id":5901}]}]}
{"op":"mcm","clk":"11797388625","pt":1723023931193,"mc":[{"id":"1.231431354","rc":[{"batb":[[1,1.84,21.49],[2,1.81,115.68]],"ltp":1.84,"tv":1270.11,"id":31372}]}]}
{"op":"mcm","clk":"11797388712","pt":1723023932480,"mc":[{"id":"1.231431354","rc":[{"batb":[[1,1.84,221.49]],"ltp":1.84,"tv":1270.11,"id":31372}]}]}
{"op":"mcm","clk":"11797388947","pt":1723023935687,"mc":[{"id":"1.231431354","rc":[{"batb":[[2,1.83,300]],"ltp":1.84,"tv":1270.11,"id":31372}]}]}
{"op":"mcm","clk":"11797390161","pt":1723023953505,"mc":[{"id":"1.231431354","rc":[{"batb":[[0,2.14,10],[1,2.12,16.12],[2,2.1,9.02]],"ltp":2.18,"tv":669.57,"id":5901}]}]}
{"op":"mcm","clk":"11797390338","pt":1723023956700,"mc":[{"id":"1.231431354","rc":[{"batb":[[0,2.12,16.12],[1,2.1,9.02],[2,2,75.64]],"ltp":2.18,"tv":669.57,"id":5901}]}]}
{"op":"mcm","clk":"11797394146","pt":1723024016411,"mc":[{"id":"1.231431354","rc":[{"trd":[[1.85,158.82]],"batb":[[0,1.85,77.5]],"ltp":1.85,"tv":1270.32,"id":31372}],"tv":1939.89}]}
{"op":"mcm","clk":"11797394158","pt":1723024016568,"mc":[{"id":"1.231431354","rc":[{"batb":[[0,2.14,10],[1,2.12,16.12],[2,2.1,9.02]],"ltp":2.18,"tv":669.57,"id":5901}]}]}
{"op":"mcm","clk":"11797394378","pt":1723024019782,"mc":[{"id":"1.231431354","rc":[{"batb":[[0,2.12,16.12],[1,2.1,9.02],[2,1.74,17.32]],"ltp":2.18,"tv":669.57,"id":5901}]}]}
{"op":"mcm","clk":"11797394599","pt":1723024023096,"mc":[{"id":"1.231431354","rc":[{"batb":[[0,2.14,10],[1,2.12,16.12],[2,2.1,9.02]],"ltp":2.18,"tv":669.57,"id":5901}]}]}
{"op":"mcm","clk":"11797394872","pt":1723024026417,"mc":[{"id":"1.231431354","rc":[{"batb":[[0,2.12,16.12],[1,2.1,9.02],[2,2,75.64]],"ltp":2.18,"tv":669.57,"id":5901}]}]}
{"op":"mcm","clk":"11797396000","pt":1723024041917,"mc":[{"id":"1.231431354","rc":[{"batb":[[0,2.14,10],[1,2.12,16.12],[2,2.1,9.02]],"ltp":2.18,"tv":669.57,"id":5901},{"trd":[[1.85,258.82]],"batb":[[0,1.85,27.5]],"ltp":1.85,"tv":1370.32,"id":31372}],"tv":2039.89}]}
{"op":"mcm","clk":"11797396251","pt":1723024045324,"mc":[{"id":"1.231431354","rc":[{"batb":[[0,2.12,16.12],[1,2.1,9.02],[2,1.74,17.32]],"ltp":2.18,"tv":669.57,"id":5901}]}]}
{"op":"mcm","clk":"11797396446","pt":1723024048231,"mc":[{"id":"1.231431354","rc":[{"batb":[[0,2.14,10],[1,2.12,16.12],[2,2.1,9.02]],"ltp":2.18,"tv":669.57,"id":5901}]}]}
{"op":"mcm","clk":"11797396509","pt":1723024049260,"mc":[{"id":"1.231431354","rc":[{"trd":[[1.85,308.82]],"batb":[[0,1.85,2.5]],"ltp":1.85,"tv":1420.32,"id":31372}],"tv":2089.89}]}
{"op":"mcm","clk":"11797396690","pt":1723024051540,"mc":[{"id":"1.231431354","rc":[{"batb":[[0,2.12,16.12],[1,2.1,9.02],[2,2,75.64]],"ltp":2.18,"tv":669.57,"id":5901}]}]}
{"op":"mcm","clk":"11797397154","pt":1723024057337,"mc":[{"id":"1.231431354","rc":[{"batb":[[0,2.14,25.83],[1,2.12,16.12],[2,2.1,9.02]],"ltp":2.18,"tv":669.57,"id":5901},{"trd":[[1.85,313.82]],"batb":[[0,1.84,200],[1,1.83,321.75],[2,1.82,400]],"batl":[[0,1.85,47.5],[1,1.87,330.41],[2,1.92,75.81]],"ltp":1.85,"tv":1425.32,"id":31372}],"tv":2094.89}]}
{"op":"mcm","clk":"11797397358","pt":1723024060152,"mc":[{"id":"1.231431354","rc":[{"batb":[[0,2.14,15.83]],"ltp":2.18,"tv":669.57,"id":5901}]}]}
{"op":"mcm","clk":"11797403681","pt":1723024154537,"mc":[{"id":"1.231431354","rc":[{"trd":[[1.84,512.48]],"batb":[[0,1.84,180]],"ltp":1.84,"tv":1465.32,"id":31372}],"tv":2134.89}]}
{"op":"mcm","clk":"11797405332","pt":1723024179985,"mc":[{"id":"1.231431354","rc":[{"trd":[[1.85,314.38]],"batl":[[0,1.85,47.22]],"ltp":1.85,"tv":1465.88,"id":31372}],"tv":2135.45}]}
{"op":"mcm","clk":"11797407092","pt":1723024204623,"mc":[{"id":"1.231431354","rc":[{"trd":[[1.84,532.48]],"batb":[[0,1.84,170]],"ltp":1.84,"tv":1485.88,"id":31372}],"tv":2155.45}]}
{"op":"mcm","clk":"11797410484","pt":1723024252059,"mc":[{"id":"1.231431354","rc":[{"trd":[[2.16,76.36]],"ltp":2.16,"tv":670.02,"id":5901},{"trd":[[1.85,314.91]],"batl":[[0,1.85,46.69]],"ltp":1.85,"tv":1486.41,"id":31372}],"tv":2156.43}]}
{"op":"mcm","clk":"11797419561","pt":1723024379414,"mc":[{"id":"1.231431354","rc":[{"trd":[[1.84,542.48]],"batb":[[0,1.84,165]],"ltp":1.84,"tv":1496.41,"id":31372}],"tv":2166.43}]}
{"op":"mcm","clk":"11797421266","pt":1723024403356,"mc":[{"id":"1.231431354","rc":[{"trd":[[1.84,542.5]],"batb":[[0,1.84,164.99]],"ltp":1.84,"tv":1496.43,"id":31372}],"tv":2166.45}]}
{"op":"mcm","clk":"11797423720","pt":1723024436990,"mc":[{"id":"1.231431354","rc":[{"trd":[[1.84,546.16]],"batb":[[0,1.84,163.16]],"ltp":1.84,"tv":1500.09,"id":31372}],"tv":2170.11}]}
{"op":"mcm","clk":"11797424086","pt":1723024441425,"mc":[{"id":"1.231431354","rc":[{"trd":[[1.84,568.66]],"batb":[[0,1.84,151.91]],"ltp":1.84,"tv":1522.59,"id":31372}],"tv":2192.61}]}
{"op":"mcm","clk":"11797430342","pt":1723024514991,"mc":[{"id":"1.231431354","rc":[{"trd":[[1.84,568.86]],"batb":[[0,1.84,151.81]],"ltp":1.84,"tv":1522.79,"id":31372}],"tv":2192.81}]}
{"op":"mcm","clk":"11797433991","pt":1723024553293,"mc":[{"id":"1.231431354","rc":[{"batl":[[1,1.92,75.81],[2,1.94,10]],"ltp":1.84,"tv":1522.79,"id":31372}]}]}
{"op":"mcm","clk":"11797438260","pt":1723024598930,"mc":[{"id":"1.231431354","rc":[{"trd":[[1.84,576.18]],"batb":[[0,1.84,148.15]],"ltp":1.84,"tv":1530.11,"id":31372}],"tv":2200.13}]}
{"op":"mcm","clk":"11797442404","pt":1723024642828,"mc":[{"id":"1.231431354","rc":[{"trd":[[2.16,76.49]],"ltp":2.16,"tv":670.15,"id":5901},{"trd":[[1.85,315.06]],"batl":[[0,1.85,46.54]],"ltp":1.85,"tv":1530.26,"id":31372}],"tv":2200.41}]}
{"op":"mcm","clk":"11797451072","pt":1723024728731,"mc":[{"id":"1.231431354","rc":[{"trd":[[1.84,580.68]],"batb":[[0,1.84,145.9]],"ltp":1.84,"tv":1534.76,"id":31372}],"tv":2204.91}]}
{"op":"mcm","clk":"11797452730","pt":1723024745589,"mc":[{"id":"1.231431354","rc":[{"batl":[[0,2.18,200],[1,2.22,4.52],[2,3,1.37]],"ltp":2.16,"tv":670.15,"id":5901}]}]}
{"op":"mcm","clk":"11797454256","pt":1723024761816,"mc":[{"id":"1.231431354","rc":[{"batb":[[0,1.84,235.95]],"ltp":1.84,"tv":1534.76,"id":31372}]}]}
{"op":"mcm","clk":"11797454400","pt":1723024763421,"mc":[{"id":"1.231431354","rc":[{"trd":[[1.84,581.05]],"batb":[[0,1.84,235.76]],"ltp":1.84,"tv":1535.14,"id":31372}],"tv":2205.29}]}
{"op":"mcm","clk":"11797456152","pt":1723024782146,"mc":[{"id":"1.231431354","rc":[{"trd":[[2.14,50.87]],"batb":[[0,2.1,9.02],[1,2.08,16.71],[2,2.04,9.71]],"ltp":2.14,"tv":685.98,"id":5901},{"trd":[[1.85,408.14],[1.88,321.66]],"batb":[[0,1.88,435.44],[1,1.84,257.25],[2,1.83,321.75]],"batl":[[0,1.92,75.81],[1,1.94,10],[2,1.99,5]],"ltp":1.88,"tv":1646.24,"id":31372}],"tv":2332.22}]}
{"op":"mcm","clk":"11797456319","pt":1723024784128,"mc":[{"id":"1.231431354","rc":[{"batb":[[1,1.87,20.75],[2,1.84,257.25]],"ltp":1.88,"tv":1646.24,"id":31372}]}]}
{"op":"mcm","clk":"11797456452","pt":1723024785451,"mc":[{"id":"1.231431354","rc":[{"batb":[[0,1.87,20.75],[1,1.84,257.25],[2,1.83,321.75]],"ltp":1.88,"tv":1646.24,"id":31372}]}]}
{"op":"mcm","clk":"11797456474","pt":1723024785765,"mc":[{"id":"1.231431354","rc":[{"batb":[[0,1.84,257.25],[1,1.83,321.75],[2,1.82,400]],"ltp":1.88,"tv":1646.24,"id":31372}]}]}
{"op":"mcm","clk":"11797456640","pt":1723024787468,"mc":[{"id":"1.231431354","rc":[{"batl":[[0,1.91,50.57],[1,1.92,75.81],[2,1.94,10]],"ltp":1.88,"tv":1646.24,"id":31372}]}]}
{"op":"mcm","clk":"11797457245","pt":1723024793737,"mc":[{"id":"1.231431354","rc":[{"batb":[[0,2.1,8.12]],"ltp":2.14,"tv":685.98,"id":5901},{"batb":[[0,1.84,111.54],[1,1.83,21.75],[2,1.81,22.29]],"ltp":1.88,"tv":1646.24,"id":31372}]}]}
{"op":"mcm","clk":"11797457582","pt":1723024797041,"mc":[{"id":"1.231431354","rc":[{"trd":[[1.9,168.1]],"batb":[[0,1.84,21.49]],"ltp":1.9,"tv":1814.34,"id":31372}],"tv":2500.32}]}
{"op":"mcm","clk":"11797457663","pt":1723024797966,"mc":[{"id":"1.231431354","rc":[{"trd":[[2.1,3.66]],"batb":[[0,2.1,6.29]],"ltp":2.1,"tv":689.64,"id":5901}],"tv":2503.98}]}
{"op":"mcm","clk":"11797458078","pt":1723024802165,"mc":[{"id":"1.231431354","marketDefinition":{"bspMarket":false,"turnInPlayEnabled":true,"persistenceEnabled":true,"marketBaseRate":5.0,"eventId":"33467056","eventTypeId":"4","numberOfWinners":1,"bettingType":"ODDS","marketType":"MATCH_ODDS","marketTime":"2024-08-07T10:00:00.000Z","suspendTime":"2024-08-07T10:00:00.000Z","bspReconciled":false,"complete":true,"inPlay":false,"crossMatching":true,"runnersVoidable":false,"numberOfActiveRunners":2,"betDelay":0,"status":"SUSPENDED","runners":[{"status":"ACTIVE","sortPriority":1,"id":31372,"name":"Worcestershire"},{"status":"ACTIVE","sortPriority":2,"id":5901,"name":"Kent"}],"regulators":["MR_INT"],"countryCode":"GB","discountAllowed":true,"timezone":"GMT","openDate":"2024-08-07T10:00:00.000Z","version":6060491003,"name":"Match Odds","eventName":"Worcestershire v Kent"},"rc":[{"batb":[[1,2.04,9.71],[2,2,75.64]],"ltp":2.1,"tv":689.64,"id":5901},{"batb":[[0,1.75,11.31],[1,1.74,17.32],[2,1.62,3.94]],"ltp":1.9,"tv":1814.34,"id":31372}]}]}
{"op":"mcm","clk":"11797458254","pt":1723024803468,"mc":[{"id":"1.231431354","rc":[{"trd":[[2.1,3.66]],"batl":[[2,3,1.37]],"ltp":2.1,"tv":689.64,"id":5901},{"trd":[[1.84,581.05],[1.86,138.51],[1.88,321.65],[1.97,61.57]],"batb":[[2,1.62,3.93]],"batl":[[1,1.92,75.84]],"ltp":1.9,"tv":1814.31,"id":31372}],"tv":2503.96}]}
{"op":"mcm","clk":"11797458683","pt":1723024807059,"mc":[{"id":"1.231431354","rc":[{"trd":[[2.14,50.83],[2.18,224.41]],"batb":[[2,1.74,17.32]],"ltp":2.1,"tv":689.59,"id":5901},{"trd":[[1.83,20.82],[1.84,581.01],[1.86,138.49]],"ltp":1.9,"tv":1814.25,"id":31372}],"tv":2503.84}]}
{"op":"mcm","clk":"11797460055","pt":1723024819174,"mc":[{"id":"1.231431354","marketDefinition":{"bspMarket":false,"turnInPlayEnabled":true,"persistenceEnabled":true,"marketBaseRate":5.0,"eventId":"33467056","eventTypeId":"4","numberOfWinners":1,"bettingType":"ODDS","marketType":"MATCH_ODDS","marketTime":"2024-08-07T10:00:00.000Z","suspendTime":"2024-08-07T10:00:00.000Z","bspReconciled":false,"complete":true,"inPlay":true,"crossMatching":true,"runnersVoidable":false,"numberOfActiveRunners":2,"betDelay":5,"status":"OPEN","runners":[{"status":"ACTIVE","sortPriority":1,"id":31372,"name":"Worcestershire"},{"status":"ACTIVE","sortPriority":2,"id":5901,"name":"Kent"}],"regulators":["MR_INT"],"countryCode":"GB","discountAllowed":true,"timezone":"GMT","openDate":"2024-08-07T10:00:00.000Z","version":6060491593,"name":"Match Odds","eventName":"Worcestershire v Kent"},"rc":[{"batb":[[0,1.74,17.32],[1,1.66,6.29],[2,1.65,40]],"batl":[[0,2.22,4.52],[1,3,1.37],[2,6.6,1.7]],"ltp":2.1,"tv":689.59,"id":5901},{"batb":[[0,1.74,17.32],[1,1.62,3.93],[2,1.55,13.93]],"batl":[[0,1.92,75.84],[1,1.94,10],[2,2,26.75]],"ltp":1.9,"tv":1814.25,"id":31372}]}]}
{"op":"mcm","clk":"11797460727","pt":1723024824953,"mc":[{"id":"1.231431354","rc":[{"batl":[[0,1.86,500],[1,1.92,75.84],[2,1.94,10]],"ltp":1.9,"tv":1814.25,"id":31372}]}]}
{"op":"mcm","clk":"11797460920","pt":1723024826779,"mc":[{"id":"1.231431354","rc":[{"trd":[[2.22,13.1]],"batl":[[0,3,1.37],[1,6.6,1.7],[2,10,1.19]],"ltp":2.22,"tv":694.11,"id":5901},{"trd":[[1.81,13.63]],"batl":[[0,1.81,494.46],[1,1.86,500],[2,1.92,75.84]],"ltp":1.81,"tv":1819.79,"id":31372}],"tv":2513.9}]}
{"op":"mcm","clk":"11797461117","pt":1723024828478,"mc":[{"id":"1.231431354","rc":[{"trd":[[1.74,34.64]],"batb":[[0,1.62,3.93],[1,1.55,13.93],[2,1.53,94.34]],"batl":[[0,1.74,482.68]],"ltp":1.74,"tv":1854.43,"id":31372}],"tv":2548.54}]}
{"op":"mcm","clk":"11797461229","pt":1723024829581,"mc":[{"id":"1.231431354","rc":[{"batl":[[0,1.86,500],[1,1.92,75.84],[2,1.94,10]],"ltp":1.74,"tv":1854.43,"id":31372}]}]}
{"op":"mcm","clk":"11797461705","pt":1723024833786,"mc":[{"id":"1.231431354","rc":[{"batb":[[0,2.38,8.37],[1,1.74,17.32],[2,1.66,6.29]],"ltp":2.22,"tv":694.11,"id":5901}]}]}
{"op":"mcm","clk":"11797462219","pt":1723024838510,"mc":[{"id":"1.231431354","rc":[{"batl":[[0,1.92,75.84],[1,1.94,10],[2,2,26.75]],"ltp":1.74,"tv":1854.43,"id":31372}]}]}
{"op":"mcm","clk":"11797462567","pt":1723024841698,"mc":[{"id":"1.231431354","rc":[{"batl":[[0,1.72,32.81],[1,1.92,75.84],[2,1.94,10]],"ltp":1.74,"tv":1854.43,"id":31372}]}]}
{"op":"mcm","clk":"11797463646","pt":1723024852502,"mc":[{"id":"1.231431354","rc":[{"batb":[[0,1.55,13.93],[1,1.53,94.34],[2,1.48,104.17]],"ltp":1.74,"tv":1854.43,"id":31372}]}]}
{"op":"mcm","clk":"11797463850","pt":1723024854522,"mc":[{"id":"1.231431354","rc":[{"batb":[[0,1.55,8.42]],"ltp":1.74,"tv":1854.43,"id":31372}]}]}
{"op":"mcm","clk":"11797465035","pt":1723024864128,"mc":[{"id":"1.231431354","rc":[{"trd":[[2.38,0.28]],"batb":[[0,2.38,8.23]],"ltp":2.38,"tv":694.39,"id":5901}],"tv":2548.82}]}
{"op":"mcm","clk":"11797466272","pt":1723024875043,"mc":[{"id":"1.231431354","rc":[{"batb":[[0,1.55,5.51]],"ltp":1.74,"tv":1854.43,"id":31372}]}]}
{"op":"mcm","clk":"11797466855","pt":1723024880241,"mc":[{"id":"1.231431354","rc":[{"batb":[[0,1.57,2.91],[1,1.55,5.51],[2,1.53,94.34]],"ltp":1.74,"tv":1854.43,"id":31372}]}]}
{"op":"mcm","clk":"11797467849","pt":1723024889541,"mc":[{"id":"1.231431354","rc":[{"batb":[[2,1.48,104.17]],"ltp":1.74,"tv":1854.43,"id":31372}]}]}
{"op":"mcm","clk":"11797467985","pt":1723024891146,"mc":[{"id":"1.231431354","rc":[{"batb":[[2,1.44,8.65]],"ltp":1.74,"tv":1854.43,"id":31372}]}]}
{"op":"mcm","clk":"11797468058","pt":1723024891861,"mc":[{"id":"1.231431354","rc":[{"batl":[[0,2.52,100.46],[1,4,1.19],[2,6.6,1.43]],"ltp":2.38,"tv":694.39,"id":5901}]}]}
{"op":"mcm","clk":"11797468421","pt":1723024895319,"mc":[{"id":"1.231431354","rc":[{"batl":[[1,2.66,7.21],[2,4,1.19]],"ltp":2.38,"tv":694.39,"id":5901}]}]}
{"op":"mcm","clk":"11797468936","pt":1723024900261,"mc":[{"id":"1.231431354","rc":[{"batb":[[0,1.55,5.51],[1,1.44,8.65],[2,1.4,85.87]],"ltp":1.74,"tv":1854.43,"id":31372}]}]}
{"op":"mcm","clk":"11797469490","pt":1723024905296,"mc":[{"id":"1.231431354","rc":[{"batb":[[1,1.44,8.74]],"ltp":1.74,"tv":1854.43,"id":31372}]}]}
{"op":"mcm","clk":"11797470260","pt":1723024912974,"mc":[{"id":"1.231431354","rc":[{"batl":[[0,1.72,50.85]],"ltp":1.74,"tv":1854.43,"id":31372}]}]}
{"op":"mcm","clk":"11797470740","pt":1723024917984,"mc":[{"id":"1.231431354","rc":[{"trd":[[1.72,0.2]],"batl":[[0,1.72,50.75]],"ltp":1.72,"tv":1854.63,"id":31372}],"tv":2549.02}]}
{"op":"mcm","clk":"11797471277","pt":1723024923467,"mc":[{"id":"1.231431354","rc":[{"batl":[[0,1.72,32.71]],"ltp":1.72,"tv":1854.63,"id":31372}]}]}
{"op":"mcm","clk":"11797471897","pt":1723024929793,"mc":[{"id":"1.231431354","rc":[{"batl":[[1,1.8,236.03],[2,1.92,75.84]],"ltp":1.72,"tv":1854.63,"id":31372}]}]}
{"op":"mcm","clk":"11797472333","pt":1723024933978,"mc":[{"id":"1.231431354","rc":[{"batb":[[0,1.74,17.32],[1,1.66,6.29],[2,1.65,40]],"ltp":2.38,"tv":694.39,"id":5901}]}]}
{"op":"mcm","clk":"11797472659","pt":1723024937090,"mc":[{"id":"1.231431354","rc":[{"trd":[[2.38,0.73]],"ltp":2.38,"tv":694.84,"id":5901},{"trd":[[1.72,0.82]],"batl":[[0,1.72,32.09]],"ltp":1.72,"tv":1855.25,"id":31372}],"tv":2550.09}]}
{"op":"mcm","clk":"11797473817","pt":1723024948223,"mc":[{"id":"1.231431354","rc":[{"batl":[[0,2.5,1.37],[1,2.52,100],[2,2.66,7.21]],"ltp":2.38,"tv":694.84,"id":5901}]}]}
{"op":"mcm","clk":"11797474313","pt":1723024952644,"mc":[{"id":"1.231431354","rc":[{"batl":[[1,1.75,2],[2,1.8,236.03]],"ltp":1.72,"tv":1855.25,"id":31372}]}]}
{"op":"mcm","clk":"11797474772","pt":1723024957041,"mc":[{"id":"1.231431354","rc":[{"batl":[[0,2.52,100.46],[1,2.66,7.21],[2,4,1.19]],"ltp":2.38,"tv":694.84,"id":5901},{"batb":[[2,1.42,8.27]],"ltp":1.72,"tv":1855.25,"id":31372}]}]}
{"op":"mcm","clk":"11797475023","pt":1723024959431,"mc":[{"id":"1.231431354","rc":[{"batb":[[0,2.2,5.86],[1,1.74,17.32],[2,1.66,6.29]],"ltp":2.38,"tv":694.84,"id":5901},{"batb":[[2,1.4,85.87]],"ltp":1.72,"tv":1855.25,"id":31372}]}]}
{"op":"mcm","clk":"11797475468","pt":1723024963810,"mc":[{"id":"1.231431354","rc":[{"batb":[[1,1.5,8.27],[2,1.44,8.74]],"ltp":1.72,"tv":1855.25,"id":31372}]}]}
{"op":"mcm","clk":"11797476310","pt":1723024971824,"mc":[{"id":"1.231431354","rc":[{"batb":[[1,1.44,8.74],[2,1.4,85.87]],"ltp":1.72,"tv":1855.25,"id":31372}]}]}
{"op":"mcm","clk":"11797476492","pt":1723024973679,"mc":[{"id":"1.231431354","rc":[{"batb":[[0,1.74,17.32],[1,1.66,6.29],[2,1.65,40]],"ltp":2.38,"tv":694.84,"id":5901}]}]}
{"op":"mcm","clk":"11797477754","pt":1723024986021,"mc":[{"id":"1.231431354","rc":[{"batl":[[0,2.5,160.46],[1,2.52,100],[2,2.66,7.21]],"ltp":2.38,"tv":694.84,"id":5901},{"batb":[[2,1.41,8.79]],"ltp":1.72,"tv":1855.25,"id":31372}]}]}
{"op":"mcm","clk":"11797477981","pt":1723024988206,"mc":[{"id":"1.231431354","rc":[{"batb":[[2,1.4,85.87]],"ltp":1.72,"tv":1855.25,"id":31372}]}]}
{"op":"mcm","clk":"11797478079","pt":1723024989141,"mc":[{"id":"1.231431354","rc":[{"batb":[[0,2.2,6.31],[1,1.74,17.32],[2,1.66,6.29]],"ltp":2.38,"tv":694.84,"id":5901}]}]}
{"op":"mcm","clk":"11797478493","pt":1723024993306,"mc":[{"id":"1.231431354","rc":[{"batb":[[1,1.5,8.79],[2,1.44,8.74]],"ltp":1.72,"tv":1855.25,"id":31372}]}]}
{"op":"mcm","clk":"11797478748","pt":1723024995808,"mc":[{"id":"1.231431354","rc":[{"batb":[[1,1.44,8.74],[2,1.4,85.87]],"ltp":1.72,"tv":1855.25,"id":31372}]}]}
{"op":"mcm","clk":"11797479113","pt":1723024999712,"mc":[{"id":"1.231431354","rc":[{"trd":[[2.38,0.83]],"ltp":2.38,"tv":694.94,"id":5901},{"trd":[[1.72,0.96]],"batl":[[0,1.72,31.95]],"ltp":1.72,"tv":1855.39,"id":31372}],"tv":2550.33}]}
{"op":"mcm","clk":"11797481028","pt":1723025020057,"mc":[{"id":"1.231431354","rc":[{"batb":[[0,2.4,8.25],[1,2.2,6.31],[2,1.74,17.32]],"ltp":2.38,"tv":694.94,"id":5901}]}]}
{"op":"mcm","clk":"11797481296","pt":1723025023171,"mc":[{"id":"1.231431354","rc":[{"batl":[[0,2.52,100.46],[1,2.66,7.21],[2,4,1.19]],"ltp":2.38,"tv":694.94,"id":5901},{"batb":[[2,1.41,8.79]],"ltp":1.72,"tv":1855.39,"id":31372}]}]}
{"op":"mcm","clk":"11797481485","pt":1723025025254,"mc":[{"id":"1.231431354","rc":[{"batb":[[2,1.4,85.87]],"ltp":1.72,"tv":1855.39,"id":31372}]}]}
{"op":"mcm","clk":"11797481976","pt":1723025030410,"mc":[{"id":"1.231431354","rc":[{"batb":[[1,1.5,8.79],[2,1.44,8.74]],"ltp":1.72,"tv":1855.39,"id":31372}]}]}
{"op":"mcm","clk":"11797484753","pt":1723025058132,"mc":[{"id":"1.231431354","rc":[{"trd":[[1.72,1.16]],"batl":[[0,1.72,31.85]],"ltp":1.72,"tv":1855.59,"id":31372}],"tv":2550.54}]}
{"op":"mcm","clk":"11797484850","pt":1723025059125,"mc":[{"id":"1.231431354","rc":[{"batb":[[1,1.44,8.74],[2,1.4,85.87]],"ltp":1.72,"tv":1855.59,"id":31372}]}]}
{"op":"mcm","clk":"11797485560","pt":1723025066416,"mc":[{"id":"1.231431354","rc":[{"trd":[[2.5,0.46],[2.52,1.02]],"batl":[[0,2.52,98.98]],"ltp":2.52,"tv":696.42,"id":5901},{"trd":[[1.65,1.56],[1.66,0.69]],"ltp":1.65,"tv":1857.84,"id":31372}],"tv":2554.26}]}
{"op":"mcm","clk":"11797486753","pt":1723025079319,"mc":[{"id":"1.231431354","rc":[{"trd":[[2.52,1.06]],"batl":[[0,2.52,98.96]],"ltp":2.52,"tv":696.46,"id":5901}],"tv":2554.3}]}
{"op":"mcm","clk":"11797486908","pt":1723025081257,"mc":[{"id":"1.231431354","rc":[{"batl":[[0,1.72,32.36]],"ltp":1.65,"tv":1857.84,"id":31372}]}]}
{"op":"mcm","clk":"11797488154","pt":1723025095347,"mc":[{"id":"1.231431354","rc":[{"batl":[[0,1.7,4.5],[1,1.72,32.36],[2,1.75,2]],"ltp":1.65,"tv":1857.84,"id":31372}]}]}
{"op":"mcm","clk":"11797488172","pt":1723025095582,"mc":[{"id":"1.231431354","rc":[{"batb":[[0,2.2,6.31],[1,1.74,17.32],[2,1.66,6.29]],"ltp":2.52,"tv":696.46,"id":5901}]}]}
{"op":"mcm","clk":"11797488662","pt":1723025100563,"mc":[{"id":"1.231431354","rc":[{"batb":[[0,2.44,8.25],[1,2.2,6.31],[2,1.74,17.32]],"ltp":2.52,"tv":696.46,"id":5901}]}]}
{"op":"mcm","clk":"11797489310","pt":1723025106899,"mc":[{"id":"1.231431354","rc":[{"batl":[[0,1.7,6.75]],"ltp":1.65,"tv":1857.84,"id":31372}]}]}
{"op":"mcm","clk":"11797489529","pt":1723025108998,"mc":[{"id":"1.231431354","rc":[{"batb":[[2,1.41,8.79]],"ltp":1.65,"tv":1857.84,"id":31372}]}]}
{"op":"mcm","clk":"11797489745","pt":1723025111492,"mc":[{"id":"1.231431354","rc":[{"batb":[[2,1.4,85.87]],"ltp":1.65,"tv":1857.84,"id":31372}]}]}
{"op":"mcm","clk":"11797490067","pt":1723025114999,"mc":[{"id":"1.231431354","rc":[{"trd":[[1.7,0.2]],"batl":[[0,1.7,6.65]],"ltp":1.7,"tv":1858.04,"id":31372}],"tv":2554.5}]}
{"op":"mcm","clk":"11797490586","pt":1723025120414,"mc":[{"id":"1.231431354","rc":[{"trd":[[2.52,5.48]],"batb":[[0,2.2,6.31],[1,1.74,17.32],[2,1.66,6.29]],"batl":[[0,2.52,94.54]],"ltp":2.52,"tv":700.88,"id":5901},{"trd":[[1.65,8.31]],"ltp":1.65,"tv":1864.79,"id":31372}],"tv":2565.67}]}
{"op":"mcm","clk":"11797491661","pt":1723025132732,"mc":[{"id":"1.231431354","rc":[{"batb":[[0,2.44,8.02],[1,2.2,6.31],[2,1.74,17.32]],"ltp":2.52,"tv":700.88,"id":5901}]}]}
{"op":"mcm","clk":"11797491943","pt":1723025135711,"mc":[{"id":"1.231431354","rc":[{"batb":[[2,1.41,8.79]],"ltp":1.65,"tv":1864.79,"id":31372}]}]}
{"op":"mcm","clk":"11797492152","pt":1723025137902,"mc":[{"id":"1.231431354","rc":[{"batb":[[2,1.4,85.87]],"ltp":1.65,"tv":1864.79,"id":31372}]}]}
{"op":"mcm","clk":"11797493845","pt":1723025158446,"mc":[{"id":"1.231431354","rc":[{"trd":[[2.52,5.55]],"batl":[[0,2.52,94.47]],"ltp":2.52,"tv":700.95,"id":5901},{"trd":[[1.65,8.41]],"ltp":1.65,"tv":1864.89,"id":31372}],"tv":2565.84}]}
{"op":"mcm","clk":"11797494444","pt":1723025165155,"mc":[{"id":"1.231431354","rc":[{"batb":[[0,1.65,3.61],[1,1.55,5.51],[2,1.44,8.74]],"ltp":1.65,"tv":1864.89,"id":31372}]}]}
{"op":"mcm","clk":"11797494543","pt":1723025166243,"mc":[{"id":"1.231431354","rc":[{"trd":[[1.7,0.34]],"batl":[[0,1.7,6.58]],"ltp":1.7,"tv":1865.03,"id":31372}],"tv":2565.98}]}
{"op":"mcm","clk":"11797495513","pt":1723025178168,"mc":[{"id":"1.231431354","rc":[{"batl":[[1,1.72,31.85]],"ltp":1.7,"tv":1865.03,"id":31372}]}]}
{"op":"mcm","clk":"11797496382","pt":1723025188876,"mc":[{"id":"1.231431354","rc":[{"trd":[[2.44,8.02]],"batb":[[0,2.2,6.31],[1,1.74,17.32],[2,1.66,6.29]],"ltp":2.44,"tv":708.97,"id":5901},{"trd":[[1.7,25.01]],"batb":[[0,1.7,481.91],[1,1.65,3.61],[2,1.55,5.51]],"batl":[[0,1.72,31.85],[1,1.75,2],[2,1.8,236.03]],"ltp":1.7,"tv":1889.7,"id":31372}],"tv":2598.67}]}
{"op":"mcm","clk":"11797496686","pt":1723025192066,"mc":[{"id":"1.231431354","rc":[{"batb":[[0,1.65,3.61],[1,1.55,5.51],[2,1.44,8.74]],"ltp":1.7,"tv":1889.7,"id":31372}]}]}
{"op":"mcm","clk":"11797496775","pt":1723025193200,"mc":[{"id":"1.231431354","rc":[{"batl":[[0,2.52,94.6]],"ltp":2.44,"tv":708.97,"id":5901}]}]}
{"op":"mcm","clk":"11797497581","pt":1723025202906,"mc":[{"id":"1.231431354","rc":[{"trd":[[2.44,8.28]],"batb":[[0,2.44,8.89],[1,2.2,6.31],[2,1.74,17.32]],"batl":[[0,2.52,94.47]],"ltp":2.44,"tv":709.23,"id":5901}],"tv":2598.94}]}
{"op":"mcm","clk":"11797497653","pt":1723025203792,"mc":[{"id":"1.231431354","rc":[{"batb":[[0,1.66,200],[1,1.65,3.61],[2,1.55,5.51]],"ltp":1.7,"tv":1889.7,"id":31372}]}]}
{"op":"mcm","clk":"11797498864","pt":1723025219025,"mc":[{"id":"1.231431354","rc":[{"batb":[[0,2.44,7.09]],"ltp":2.44,"tv":709.23,"id":5901}]}]}
{"op":"mcm","clk":"11797499332","pt":1723025224625,"mc":[{"id":"1.231431354","rc":[{"batb":[[0,2.46,7.91],[1,2.44,7.09],[2,2.2,6.31]],"ltp":2.44,"tv":709.23,"id":5901}]}]}
{"op":"mcm","clk":"11797499928","pt":1723025231543,"mc":[{"id":"1.231431354","rc":[{"trd":[[2.46,0.2]],"batb":[[0,2.46,7.81]],"ltp":2.46,"tv":709.43,"id":5901}],"tv":2599.14}]}
{"op":"mcm","clk":"11797500851","pt":1723025242954,"mc":[{"id":"1.231431354","rc":[{"trd":[[2.46,0.46]],"batb":[[0,2.46,7.68]],"ltp":2.46,"tv":709.69,"id":5901}],"tv":2599.39}]}
{"op":"mcm","clk":"11797502288","pt":1723025259646,"mc":[{"id":"1.231431354","rc":[{"trd":[[2.46,15.81]],"batb":[[0,2.44,7.09],[1,2.2,6.31],[2,1.74,17.32]],"ltp":2.46,"tv":725.04,"id":5901}],"tv":2614.75}]}
{"op":"mcm","clk":"11797503063","pt":1723025269370,"mc":[{"id":"1.231431354","rc":[{"trd":[[2.44,15.37]],"batb":[[0,2.2,6.31],[1,1.74,17.32],[2,1.66,6.29]],"ltp":2.44,"tv":732.13,"id":5901},{"trd":[[1.7,35.19]],"batb":[[0,1.71,489.82],[1,1.66,200],[2,1.65,3.61]],"ltp":1.7,"tv":1899.88,"id":31372}],"tv":2632.02}]}
{"op":"mcm","clk":"11797503134","pt":1723025270356,"mc":[{"id":"1.231431354","rc":[{"batb":[[0,1.66,200],[1,1.65,3.61],[2,1.55,5.51]],"ltp":1.7,"tv":1899.88,"id":31372}]}]}
{"op":"mcm","clk":"11797506917","pt":1723025317729,"mc":[{"id":"1.231431354","rc":[{"batl":[[0,2.66,7.21],[1,4,1.19],[2,5,3.51]],"ltp":2.44,"tv":732.13,"id":5901}]}]}
{"op":"mcm","clk":"11797507231","pt":1723025322258,"mc":[{"id":"1.231431354","rc":[{"trd":[[2.52,10.96]],"ltp":2.52,"tv":737.54,"id":5901},{"trd":[[1.66,8.9]],"batb":[[0,1.66,191.79]],"ltp":1.66,"tv":1908.09,"id":31372}],"tv":2645.64}]}
{"op":"mcm","clk":"11797507272","pt":1723025322839,"mc":[{"id":"1.231431354","rc":[{"batl":[[0,2.42,94.47],[1,2.66,7.21],[2,4,1.19]],"ltp":2.52,"tv":737.54,"id":5901}]}]}
{"op":"mcm","clk":"11797507375","pt":1723025324246,"mc":[{"id":"1.231431354","rc":[{"trd":[[1.72,1.36]],"batl":[[0,1.72,31.75]],"ltp":1.72,"tv":1908.29,"id":31372}],"tv":2645.84}]}
{"op":"mcm","clk":"11797507754","pt":1723025329552,"mc":[{"id":"1.231431354","rc":[{"batb":[[0,2.4,8.25],[1,2.2,6.31],[2,1.74,17.32]],"ltp":2.52,"tv":737.54,"id":5901}]}]}
{"op":"mcm","clk":"11797509804","pt":1723025354602,"mc":[{"id":"1.231431354","rc":[{"trd":[[2.4,8.25]],"batb":[[0,2.2,6.31],[1,1.74,17.32],[2,1.66,6.29]],"ltp":2.4,"tv":745.79,"id":5901},{"trd":[[1.72,76.37]],"batb":[[0,1.72,14.27],[1,1.66,191.79],[2,1.65,3.61]],"batl":[[0,1.75,2],[1,1.8,236.03],[2,1.92,76.35]],"ltp":1.72,"tv":1983.3,"id":31372}],"tv":2729.1}]}
{"op":"mcm","clk":"11797510057","pt":1723025358306,"mc":[{"id":"1.231431354","rc":[{"batl":[[0,2.4,4.5],[1,2.42,94.47],[2,2.66,7.21]],"ltp":2.4,"tv":745.79,"id":5901}]}]}
{"op":"mcm","clk":"11797510638","pt":1723025364212,"mc":[{"id":"1.231431354","rc":[{"batl":[[1,1.77,27.15],[2,1.8,236.03]],"ltp":1.72,"tv":1983.3,"id":31372}]}]}
{"op":"mcm","clk":"11797510826","pt":1723025366400,"mc":[{"id":"1.231431354","rc":[{"batb":[[1,1.65,3.61],[2,1.55,5.51]],"ltp":1.72,"tv":1983.3,"id":31372}]}]}
{"op":"mcm","clk":"11797515250","pt":1723025413823,"mc":[{"id":"1.231431354","rc":[{"batb":[[0,2.36,8.49],[1,2.2,6.31],[2,1.74,17.32]],"ltp":2.4,"tv":745.79,"id":5901}]}]}
{"op":"mcm","clk":"11797515992","pt":1723025422838,"mc":[{"id":"1.231431354","rc":[{"batl":[[1,2.66,7.21],[2,4,1.19]],"ltp":2.4,"tv":745.79,"id":5901}]}]}
{"op":"mcm","clk":"11797516425","pt":1723025427970,"mc":[{"id":"1.231431354","rc":[{"trd":[[2.36,16.98]],"batb":[[0,2.2,6.31],[1,1.74,17.32],[2,1.66,6.29]],"batl":[[0,2.36,85.98],[1,2.4,4.5],[2,2.66,7.21]],"ltp":2.36,"tv":762.77,"id":5901}],"tv":2746.08}]}
{"op":"mcm","clk":"11797517234","pt":1723025437786,"mc":[{"id":"1.231431354","rc":[{"batl":[[0,1.75,2.9]],"ltp":1.72,"tv":1983.3,"id":31372}]}]}
{"op":"mcm","clk":"11797518423","pt":1723025451774,"mc":[{"id":"1.231431354","rc":[{"trd":[[2.36,17.94]],"batl":[[0,2.36,85.02]],"ltp":2.36,"tv":763.73,"id":5901},{"trd":[[1.73,1.31]],"ltp":1.73,"tv":1984.61,"id":31372}],"tv":2748.35}]}
{"op":"mcm","clk":"11797519653","pt":1723025465001,"mc":[{"id":"1.231431354","rc":[{"trd":[[2.4,12.75]],"batl":[[0,2.66,7.21],[1,4,1.19],[2,5,3.51]],"ltp":2.4,"tv":768.23,"id":5901},{"trd":[[1.71,6.32]],"batb":[[0,1.65,3.61],[1,1.55,5.51],[2,1.46,6.38]],"batl":[[0,1.7,4487.53],[1,1.75,2.9],[2,1.77,27.15]],"ltp":1.71,"tv":1990.93,"id":31372}],"tv":2759.17}]}
{"op":"mcm","clk":"11797520561","pt":1723025475533,"mc":[{"id":"1.231431354","rc":[{"trd":[[1.7,85.69]],"batl":[[0,1.7,4462.28]],"ltp":1.7,"tv":2041.44,"id":31372}],"tv":2809.67}]}
{"op":"mcm","clk":"11797520720","pt":1723025477205,"mc":[{"id":"1.231431354","rc":[{"trd":[[2.42,0.1]],"ltp":2.42,"tv":768.33,"id":5901},{"trd":[[1.7,85.83]],"batl":[[0,1.7,4462.14]],"ltp":1.7,"tv":2041.58,"id":31372}],"tv":2809.92}]}
{"op":"mcm","clk":"11797521007","pt":1723025480597,"mc":[{"id":"1.231431354","rc":[{"trd":[[2.42,100.1]],"ltp":2.42,"tv":868.33,"id":5901},{"trd":[[1.7,228.18]],"batl":[[0,1.7,4319.79]],"ltp":1.7,"tv":2183.93,"id":31372}],"tv":3052.27}]}
{"op":"mcm","clk":"11797521286","pt":1723025483507,"mc":[{"id":"1.231431354","rc":[{"trd":[[2.42,109.82],[2.44,31.41]],"ltp":2.42,"tv":894.09,"id":5901},{"trd":[[1.7,242.02]],"batl":[[0,1.7,4305.95]],"ltp":1.7,"tv":2197.77,"id":31372}],"tv":3091.87}]}
{"op":"mcm","clk":"11797522000","pt":1723025491922,"mc":[{"id":"1.231431354","rc":[{"trd":[[1.7,444.07]],"batl":[[0,1.7,4204.93]],"ltp":1.7,"tv":2399.81,"id":31372}],"tv":3293.91}]}
{"op":"mcm","clk":"11797522084","pt":1723025492707,"mc":[{"id":"1.231431354","rc":[{"trd":[[2.42,259.82]],"ltp":2.42,"tv":1044.09,"id":5901},{"trd":[[1.7,657.6]],"batl":[[0,1.7,3991.4]],"ltp":1.7,"tv":2613.34,"id":31372}],"tv":3657.44}]}
{"op":"mcm","clk":"11797523638","pt":1723025511034,"mc":[{"id":"1.231431354","rc":[{"batb":[[1,1.56,7.24],[2,1.55,5.51]],"ltp":1.7,"tv":2613.34,"id":31372}]}]}
{"op":"mcm","clk":"11797523726","pt":1723025512127,"mc":[{"id":"1.231431354","rc":[{"batb":[[1,1.55,5.51],[2,1.46,6.38]],"ltp":1.7,"tv":2613.34,"id":31372}]}]}
{"op":"mcm","clk":"11797523801","pt":1723025513071,"mc":[{"id":"1.231431354","rc":[{"batl":[[0,1.7,3766.4]],"ltp":1.7,"tv":2613.34,"id":31372}]}]}
{"op":"mcm","clk":"11797524611","pt":1723025522359,"mc":[{"id":"1.231431354","rc":[{"batb":[[0,2.44,8.02],[1,2.2,6.31],[2,1.74,17.32]],"ltp":2.42,"tv":1044.09,"id":5901}]}]}
{"op":"mcm","clk":"11797524882","pt":1723025525376,"mc":[{"id":"1.231431354","rc":[{"batb":[[1,1.56,7.24],[2,1.55,5.51]],"ltp":1.7,"tv":2613.34,"id":31372}]}]}
{"op":"mcm","clk":"11797525175","pt":1723025528548,"mc":[{"id":"1.231431354","rc":[{"batb":[[1,1.55,5.51],[2,1.46,6.38]],"ltp":1.7,"tv":2613.34,"id":31372}]}]}
{"op":"mcm","clk":"11797525441","pt":1723025531459,"mc":[{"id":"1.231431354","rc":[{"batl":[[0,1.7,3541.4]],"ltp":1.7,"tv":2613.34,"id":31372}]}]}
{"op":"mcm","clk":"11797525617","pt":1723025533453,"mc":[{"id":"1.231431354","rc":[{"batl":[[0,1.7,3488.29]],"ltp":1.7,"tv":2613.34,"id":31372}]}]}
{"op":"mcm","clk":"11797526644","pt":1723025546191,"mc":[{"id":"1.231431354","rc":[{"batb":[[1,1.56,7.24],[2,1.55,5.51]],"ltp":1.7,"tv":2613.34,"id":31372}]}]}
{"op":"mcm","clk":"11797526862","pt":1723025549294,"mc":[{"id":"1.231431354","rc":[{"batb":[[1,1.55,5.51],[2,1.46,6.38]],"ltp":1.7,"tv":2613.34,"id":31372}]}]}
{"op":"mcm","clk":"11797526911","pt":1723025549868,"mc":[{"id":"1.231431354","rc":[{"batl":[[0,1.7,3263.29]],"ltp":1.7,"tv":2613.34,"id":31372}]}]}
{"op":"mcm","clk":"11797527443","pt":1723025557273,"mc":[{"id":"1.231431354","rc":[{"trd":[[1.7,657.8]],"batl":[[0,1.7,3263.19]],"ltp":1.7,"tv":2613.54,"id":31372}],"tv":3657.64}]}
{"op":"mcm","clk":"11797529420","pt":1723025580395,"mc":[{"id":"1.231431354","rc":[{"trd":[[2.66,7.21]],"batb":[[0,2.2,6.31],[1,1.74,17.32],[2,1.66,6.29]],"batl":[[0,4,1.19],[1,5,3.51],[2,8,1.19]],"ltp":2.66,"tv":1051.3,"id":5901},{"trd":[[1.6,11.99],[1.65,15.63]],"batb":[[0,1.55,5.51],[1,1.46,6.38],[2,1.44,8.65]],"batl":[[0,1.59,488.01],[1,1.61,496.39],[2,1.7,3263.19]],"ltp":1.6,"tv":2632.75,"id":31372}],"tv":3684.06}]}
{"op":"mcm","clk":"11797529587","pt":1723025582227,"mc":[{"id":"1.231431354","rc":[{"batl":[[2,1.69,500]],"ltp":1.6,"tv":2632.75,"id":31372}]}]}
{"op":"mcm","clk":"11797529722","pt":1723025583594,"mc":[{"id":"1.231431354","rc":[{"batl":[[1,1.6,100],[2,1.61,496.39]],"ltp":1.6,"tv":2632.75,"id":31372}]}]}
{"op":"mcm","clk":"11797529889","pt":1723025585306,"mc":[{"id":"1.231431354","rc":[{"trd":[[1.55,11.02]],"batb":[[0,1.46,6.38],[1,1.44,8.65],[2,1.4,85.87]],"batl":[[0,1.55,494.49],[1,1.59,488.01],[2,1.6,100]],"ltp":1.55,"tv":2643.77,"id":31372}],"tv":3695.08}]}
{"op":"mcm","clk":"11797529960","pt":1723025586094,"mc":[{"id":"1.231431354","rc":[{"batl":[[0,1.59,488.01],[1,1.6,322],[2,1.61,496.39]],"ltp":1.55,"tv":2643.77,"id":31372}]}]}
{"op":"mcm","clk":"11797530082","pt":1723025587406,"mc":[{"id":"1.231431354","rc":[{"batl":[[0,1.6,322],[1,1.61,496.39],[2,1.69,500]],"ltp":1.55,"tv":2643.77,"id":31372}]}]}
{"op":"mcm","clk":"11797530373","pt":1723025590234,"mc":[{"id":"1.231431354","rc":[{"batb":[[0,2.84,8.02],[1,2.2,6.31],[2,1.74,17.32]],"ltp":2.66,"tv":1051.3,"id":5901},{"batl":[[0,1.6,100],[1,1.69,500],[2,1.7,3263.19]],"ltp":1.55,"tv":2643.77,"id":31372}]}]}
{"op":"mcm","clk":"11797530494","pt":1723025591443,"mc":[{"id":"1.231431354","rc":[{"trd":[[3,0.91]],"batb":[[0,2.2,6.31],[1,1.74,17.32],[2,1.66,6.29]],"batl":[[0,5,3.79],[1,8,1.19],[2,13,1.1]],"ltp":3.0,"tv":1052.22,"id":5901},{"trd":[[1.5,1.83]],"batl":[[0,1.5,18.17],[1,1.6,100],[2,1.69,500]],"ltp":1.5,"tv":2645.6,"id":31372}],"tv":3697.82}]}
{"op":"mcm","clk":"11797530745","pt":1723025594241,"mc":[{"id":"1.231431354","rc":[{"batl":[[1,1.59,500],[2,1.6,100]],"ltp":1.5,"tv":2645.6,"id":31372}]}]}
{"op":"mcm","clk":"11797530885","pt":1723025595308,"mc":[{"id":"1.231431354","rc":[{"batl":[[0,1.57,222],[2,1.7,3263.19]],"ltp":1.5,"tv":2645.6,"id":31372}]}]}
{"op":"mcm","clk":"11797530988","pt":1723025596308,"mc":[{"id":"1.231431354","rc":[{"trd":[[3.05,0.04]],"batb":[[0,3.05,7.98],[1,2.86,4],[2,2.2,6.31]],"ltp":3.05,"tv":1052.26,"id":5901},{"trd":[[1.49,0.09]],"batb":[[0,1.46,6.29]],"ltp":1.49,"tv":2645.68,"id":31372}],"tv":3697.95}]}
{"op":"mcm","clk":"11797531080","pt":1723025597061,"mc":[{"id":"1.231431354","rc":[{"batl":[[0,1.51,3],[1,1.57,222],[2,1.59,500]],"ltp":1.49,"tv":2645.68,"id":31372}]}]}
{"op":"mcm","clk":"11797531253","pt":1723025598447,"mc":[{"id":"1.231431354","rc":[{"batb":[[1,2.2,6.31],[2,1.74,17.32]],"ltp":3.05,"tv":1052.26,"id":5901}]}]}
{"op":"mcm","clk":"11797531272","pt":1723025598617,"mc":[{"id":"1.231431354","rc":[{"batl":[[2,1.7,3263.19]],"ltp":1.49,"tv":2645.68,"id":31372}]}]}
{"op":"mcm","clk":"11797531776","pt":1723025604344,"mc":[{"id":"1.231431354","rc":[{"batb":[[2,1.41,9.44]],"ltp":1.49,"tv":2645.68,"id":31372}]}]}
{"op":"mcm","clk":"11797532242","pt":1723025609459,"mc":[{"id":"1.231431354","rc":[{"batb":[[0,2.2,6.31],[1,1.74,17.32],[2,1.66,6.29]],"ltp":3.05,"tv":1052.26,"id":5901},{"trd":[[1.41,18.88],[1.44,17.3],[1.46,12.58]],"batb":[[0,1.34,85.87],[1,1.33,151.52],[2,1.32,17.31]],"batl":[[0,1.4,61.12],[1,1.51,3],[2,1.54,22]],"ltp":1.41,"tv":2694.45,"id":31372}],"tv":3746.72}]}
{"op":"mcm","clk":"11797532251","pt":1723025609566,"mc":[{"id":"1.231431354","rc":[{"batb":[[0,3.1,4],[1,2.2,6.31],[2,1.74,17.32]],"ltp":3.05,"tv":1052.26,"id":5901}]}]}
{"op":"mcm","clk":"11797532514","pt":1723025612356,"mc":[{"id":"1.231431354","rc":[{"batb":[[0,2.2,6.31],[1,1.74,17.32],[2,1.66,6.29]],"ltp":3.05,"tv":1052.26,"id":5901},{"batb":[[0,1.33,151.52],[1,1.32,17.31],[2,1.3,85.87]],"ltp":1.41,"tv":2694.45,"id":31372}]}]}
{"op":"mcm","clk":"11797532676","pt":1723025614368,"mc":[{"id":"1.231431354","rc":[{"batb":[[0,3.55,7.98],[1,2.2,6.31],[2,1.74,17.32]],"ltp":3.05,"tv":1052.26,"id":5901},{"batb":[[2,1.28,178.57]],"ltp":1.41,"tv":2694.45,"id":31372}]}]}
{"op":"mcm","clk":"11797533062","pt":1723025618461,"mc":[{"id":"1.231431354","rc":[{"batb":[[1,2.94,6.86],[2,2.2,6.31]],"ltp":3.05,"tv":1052.26,"id":5901},{"batb":[[0,1.38,14.61],[1,1.33,151.52],[2,1.32,17.31]],"ltp":1.41,"tv":2694.45,"id":31372}]}]}
{"op":"mcm","clk":"11797533153","pt":1723025619336,"mc":[{"id":"1.231431354","rc":[{"batb":[[1,2.2,6.31],[2,1.74,17.32]],"ltp":3.05,"tv":1052.26,"id":5901},{"trd":[[1.4,53.5]],"batl":[[0,1.4,34.37]],"ltp":1.4,"tv":2747.95,"id":31372}],"tv":3800.22}]}
{"op":"mcm","clk":"11797533252","pt":1723025620432,"mc":[{"id":"1.231431354","rc":[{"batb":[[0,1.33,151.52],[1,1.32,17.31],[2,1.28,178.57]],"ltp":1.4,"tv":2747.95,"id":31372}]}]}
{"op":"mcm","clk":"11797533368","pt":1723025621647,"mc":[{"id":"1.231431354","rc":[{"batl":[[0,1.4,25.35]],"ltp":1.4,"tv":2747.95,"id":31372}]}]}
{"op":"mcm","clk":"11797533452","pt":1723025622528,"mc":[{"id":"1.231431354","rc":[{"batb":[[0,2.2,6.31],[1,1.74,17.32],[2,1.66,6.29]],"ltp":3.05,"tv":1052.26,"id":5901}]}]}
{"op":"mcm","clk":"11797533608","pt":1723025624370,"mc":[{"id":"1.231431354","rc":[{"batb":[[0,2.9,6.96],[1,2.2,6.31],[2,1.74,17.32]],"ltp":3.05,"tv":1052.26,"id":5901},{"batl":[[0,1.39,10.34],[1,1.4,25.35],[2,1.51,3]],"ltp":1.4,"tv":2747.95,"id":31372}]}]}
{"op":"mcm","clk":"11797533696","pt":1723025625455,"mc":[{"id":"1.231431354","rc":[{"batb":[[0,2.2,6.31],[1,1.74,17.32],[2,1.66,6.29]],"ltp":3.05,"tv":1052.26,"id":5901},{"batb":[[0,1.37,450.81],[1,1.35,33],[2,1.33,151.52]],"ltp":1.4,"tv":2747.95,"id":31372}]}]}
{"op":"mcm","clk":"11797533772","pt":1723025626339,"mc":[{"id":"1.231431354","rc":[{"trd":[[1.39,20.68],[1.4,104.2]],"batb":[[0,1.4,357.7],[1,1.37,450.81],[2,1.35,33]],"batl":[[0,1.51,3],[1,1.54,22],[2,1.57,222]],"ltp":1.4,"tv":2819.33,"id":31372}],"tv":3871.59}]}
{"op":"mcm","clk":"11797533981","pt":1723025628439,"mc":[{"id":"1.231431354","rc":[{"batb":[[2,1.33,151.52]],"ltp":1.4,"tv":2819.33,"id":31372}]}]}
{"op":"mcm","clk":"11797534148","pt":1723025630262,"mc":[{"id":"1.231431354","rc":[{"batb":[[0,2.86,7.06],[1,2.2,6.31],[2,1.74,17.32]],"ltp":3.05,"tv":1052.26,"id":5901},{"batb":[[0,1.4,372.11]],"ltp":1.4,"tv":2819.33,"id":31372}]}]}
{"op":"mcm","clk":"11797534219","pt":1723025631137,"mc":[{"id":"1.231431354","rc":[{"batb":[[0,2.2,6.31],[1,1.74,17.32],[2,1.66,6.29]],"ltp":3.05,"tv":1052.26,"id":5901},{"batb":[[0,1.4,357.7],[2,1.35,14.16]],"ltp":1.4,"tv":2819.33,"id":31372}]}]}
{"op":"mcm","clk":"11797534511","pt":1723025634310,"mc":[{"id":"1.231431354","rc":[{"batb":[[1,1.37,450.91]],"batl":[[2,1.75,2]],"ltp":1.4,"tv":2819.33,"id":31372}]}]}
{"op":"mcm","clk":"11797534697","pt":1723025636139,"mc":[{"id":"1.231431354","rc":[{"batb":[[0,2.76,7.29],[1,2.2,6.31],[2,1.74,17.32]],"ltp":3.05,"tv":1052.26,"id":5901},{"batb":[[0,1.42,14.18],[1,1.4,357.7],[2,1.37,450.91]],"ltp":1.4,"tv":2819.33,"id":31372}]}]}
{"op":"mcm","clk":"11797534948","pt":1723025638941,"mc":[{"id":"1.231431354","rc":[{"batb":[[1,1.41,18.88],[2,1.4,357.7]],"ltp":1.4,"tv":2819.33,"id":31372}]}]}
{"op":"mcm","clk":"11797535267","pt":1723025642335,"mc":[{"id":"1.231431354","rc":[{"batl":[[0,1.51,3.75],[1,1.53,6.29],[2,1.54,22]],"ltp":1.4,"tv":2819.33,"id":31372}]}]}
{"op":"mcm","clk":"11797535440","pt":1723025644267,"mc":[{"id":"1.231431354","rc":[{"batb":[[0,2.2,6.31],[1,1.74,17.32],[2,1.66,6.29]],"ltp":3.05,"tv":1052.26,"id":5901},{"batb":[[0,1.41,14.16],[1,1.4,357.7],[2,1.35,14.26]],"batl":[[2,1.75,2]],"ltp":1.4,"tv":2819.33,"id":31372}]}]}
{"op":"mcm","clk":"11797536450","pt":1723025654386,"mc":[{"id":"1.231431354","rc":[{"batb":[[0,2.76,7.29],[1,2.2,6.31],[2,1.74,17.32]],"ltp":3.05,"tv":1052.26,"id":5901},{"batb":[[0,1.42,14.18],[1,1.41,14.16],[2,1.4,357.7]],"ltp":1.4,"tv":2819.33,"id":31372}]}]}
{"op":"mcm","clk":"11797536534","pt":1723025655276,"mc":[{"id":"1.231431354","rc":[{"batl":[[0,3.55,2.71],[1,5,3.79],[2,8,1.19]],"ltp":3.05,"tv":1052.26,"id":5901}]}]}
{"op":"mcm","clk":"11797536635","pt":1723025656160,"mc":[{"id":"1.231431354","rc":[{"batb":[[0,2.2,6.31],[1,1.74,17.32],[2,1.66,6.29]],"ltp":3.05,"tv":1052.26,"id":5901},{"batb":[[0,1.41,14.16],[1,1.4,357.7],[2,1.35,14.26]],"ltp":1.4,"tv":2819.33,"id":31372}]}]}
{"op":"mcm","clk":"11797536737","pt":1723025657041,"mc":[{"id":"1.231431354","rc":[{"batb":[[2,1.35,14.16]],"ltp":1.4,"tv":2819.33,"id":31372}]}]}
{"op":"mcm","clk":"11797536947","pt":1723025659439,"mc":[{"id":"1.231431354","rc":[{"batl":[[0,1.51,3]],"ltp":1.4,"tv":2819.33,"id":31372}]}]}
{"op":"mcm","clk":"11797537222","pt":1723025662461,"mc":[{"id":"1.231431354","rc":[{"batb":[[0,2.68,7.54],[1,2.2,6.31],[2,1.74,17.32]],"ltp":3.05,"tv":1052.26,"id":5901},{"batb":[[0,1.45,13.93],[1,1.41,14.16],[2,1.4,357.7]],"ltp":1.4,"tv":2819.33,"id":31372}]}]}
{"op":"mcm","clk":"11797538423","pt":1723025674866,"mc":[{"id":"1.231431354","rc":[{"batb":[[0,2.2,6.31],[1,1.74,17.32],[2,1.66,6.29]],"ltp":3.05,"tv":1052.26,"id":5901}]}]}
{"op":"mcm","clk":"11797538849","pt":1723025679768,"mc":[{"id":"1.231431354","rc":[{"batb":[[0,2.64,7.64],[1,2.2,6.31],[2,1.74,17.32]],"ltp":3.05,"tv":1052.26,"id":5901}]}]}
{"op":"mcm","clk":"11797539011","pt":1723025681600,"mc":[{"id":"1.231431354","rc":[{"trd":[[1.45,0.2]],"batb":[[0,1.45,13.82]],"ltp":1.45,"tv":2819.54,"id":31372}],"tv":3871.8}]}
{"op":"mcm","clk":"11797540454","pt":1723025698109,"mc":[{"id":"1.231431354","rc":[{"batl":[[0,3.55,2.25]],"ltp":3.05,"tv":1052.26,"id":5901}]}]}
{"op":"mcm","clk":"11797540519","pt":1723025698793,"mc":[{"id":"1.231431354","rc":[{"trd":[[1.45,0.41]],"batb":[[0,1.45,13.72]],"ltp":1.45,"tv":2819.74,"id":31372}],"tv":3872.0}]}
{"op":"mcm","clk":"11797540965","pt":1723025703036,"mc":[{"id":"1.231431354","rc":[{"trd":[[1.51,0.2]],"batl":[[0,1.51,2.9]],"ltp":1.51,"tv":2819.94,"id":31372}],"tv":3872.2}]}
{"op":"mcm","clk":"11797541219","pt":1723025705427,"mc":[{"id":"1.231431354","rc":[{"batl":[[2,1.6,6.29]],"ltp":1.51,"tv":2819.94,"id":31372}]}]}
{"op":"mcm","clk":"11797541614","pt":1723025709715,"mc":[{"id":"1.231431354","rc":[{"batb":[[0,2.2,6.31],[1,1.74,17.32],[2,1.66,6.29]],"ltp":3.05,"tv":1052.26,"id":5901}]}]}
{"op":"mcm","clk":"11797541953","pt":1723025713258,"mc":[{"id":"1.231431354","rc":[{"batb":[[0,2.98,5.83],[1,2.2,6.31],[2,1.74,17.32]],"ltp":3.05,"tv":1052.26,"id":5901}]}]}
{"op":"mcm","clk":"11797542129","pt":1723025715231,"mc":[{"id":"1.231431354","rc":[{"batb":[[1,2.68,7.54],[2,2.2,6.31]],"ltp":3.05,"tv":1052.26,"id":5901},{"batb":[[2,1.35,14.59]],"ltp":1.51,"tv":2819.94,"id":31372}]}]}
{"op":"mcm","clk":"11797542203","pt":1723025716011,"mc":[{"id":"1.231431354","rc":[{"batb":[[2,1.4,17.05]],"ltp":1.51,"tv":2819.94,"id":31372}]}]}
{"op":"mcm","clk":"11797543476","pt":1723025729852,"mc":[{"id":"1.231431354","rc":[{"batb":[[2,1.35,14.59]],"ltp":1.51,"tv":2819.94,"id":31372}]}]}
{"op":"mcm","clk":"11797545395","pt":1723025751538,"mc":[{"id":"1.231431354","rc":[{"batb":[[2,1.4,8.79]],"ltp":1.51,"tv":2819.94,"id":31372}]}]}
{"op":"mcm","clk":"11797545613","pt":1723025753871,"mc":[{"id":"1.231431354","rc":[{"trd":[[2.98,2.34]],"batb":[[0,2.98,4.66]],"ltp":2.98,"tv":1054.6,"id":5901}],"tv":3874.54}]}
{"op":"mcm","clk":"11797546538","pt":1723025763552,"mc":[{"id":"1.231431354","rc":[{"batb":[[2,1.35,14.59]],"ltp":1.51,"tv":2819.94,"id":31372}]}]}
{"op":"mcm","clk":"11797546799","pt":1723025766770,"mc":[{"id":"1.231431354","rc":[{"trd":[[2.98,2.82]],"batb":[[0,2.98,4.18]],"batl":[[1,6.6,1.7],[2,10,1.19]],"ltp":2.98,"tv":1055.08,"id":5901},{"trd":[[1.51,1.14]],"batl":[[0,1.53,6.29],[1,1.6,6.29],[2,1.62,50]],"ltp":1.51,"tv":2820.88,"id":31372}],"tv":3875.97}]}
{"op":"mcm","clk":"11797546897","pt":1723025767764,"mc":[{"id":"1.231431354","rc":[{"batb":[[1,1.41,9.44]],"ltp":1.51,"tv":2820.88,"id":31372}]}]}
{"op":"mcm","clk":"11797547640","pt":1723025775379,"mc":[{"id":"1.231431354","rc":[{"trd":[[1.45,26.41]],"batb":[[0,1.41,10.16],[1,1.35,14.59],[2,1.32,17.31]],"ltp":1.45,"tv":2846.89,"id":31372}],"tv":3901.97}]}
{"op":"mcm","clk":"11797547738","pt":1723025776400,"mc":[{"id":"1.231431354","rc":[{"batl":[[0,1.5,3.93],[1,1.53,6.29],[2,1.6,6.29]],"ltp":1.45,"tv":2846.89,"id":31372}]}]}
{"op":"mcm","clk":"11797547765","pt":1723025776692,"mc":[{"id":"1.231431354","rc":[{"batb":[[0,2.68,7.54],[1,2.2,6.31],[2,1.74,17.32]],"ltp":2.98,"tv":1055.08,"id":5901}]}]}
{"op":"mcm","clk":"11797548327","pt":1723025782509,"mc":[{"id":"1.231431354","rc":[{"batb":[[0,3.05,4.18]],"ltp":2.98,"tv":1055.08,"id":5901}]}]}
{"op":"mcm","clk":"11797548371","pt":1723025782885,"mc":[{"id":"1.231431354","rc":[{"batb":[[0,1.44,14],[1,1.41,9.44],[2,1.35,14.59]],"ltp":1.45,"tv":2846.89,"id":31372}]}]}
{"op":"mcm","clk":"11797548551","pt":1723025784809,"mc":[{"id":"1.231431354","rc":[{"batb":[[0,1.41,9.44],[1,1.35,14.59],[2,1.32,17.31]],"ltp":1.45,"tv":2846.89,"id":31372}]}]}
{"op":"mcm","clk":"11797549094","pt":1723025790300,"mc":[{"id":"1.231431354","rc":[{"batb":[[0,3.1,5.5],[1,3.05,4.18],[2,2.2,6.31]],"ltp":2.98,"tv":1055.08,"id":5901}]}]}
{"op":"mcm","clk":"11797549133","pt":1723025790716,"mc":[{"id":"1.231431354","rc":[{"batb":[[1,2.2,6.31],[2,1.74,17.32]],"ltp":2.98,"tv":1055.08,"id":5901}]}]}
{"op":"mcm","clk":"11797549229","pt":1723025791809,"mc":[{"id":"1.231431354","rc":[{"batb":[[2,2.16,12.59]],"ltp":2.98,"tv":1055.08,"id":5901}]}]}
{"op":"mcm","clk":"11797549386","pt":1723025793322,"mc":[{"id":"1.231431354","rc":[{"batb":[[1,1.39,8.79],[2,1.35,14.59]],"ltp":1.45,"tv":2846.89,"id":31372}]}]}
{"op":"mcm","clk":"11797549499","pt":1723025794415,"mc":[{"id":"1.231431354","rc":[{"batb":[[1,2.7,7.47],[2,2.2,6.31]],"ltp":2.98,"tv":1055.08,"id":5901},{"batb":[[0,1.44,14],[1,1.41,9.44],[2,1.39,8.79]],"ltp":1.45,"tv":2846.89,"id":31372}]}]}
{"op":"mcm","clk":"11797549604","pt":1723025795517,"mc":[{"id":"1.231431354","rc":[{"batb":[[1,2.2,6.31],[2,2.16,12.59]],"ltp":2.98,"tv":1055.08,"id":5901},{"batb":[[0,1.41,9.44],[1,1.39,8.79],[2,1.35,14.59]],"ltp":1.45,"tv":2846.89,"id":31372}]}]}
{"op":"mcm","clk":"11797549624","pt":1723025795728,"mc":[{"id":"1.231431354","rc":[{"batb":[[0,3.15,4.18],[1,3.1,5.5],[2,2.2,6.31]],"ltp":2.98,"tv":1055.08,"id":5901}]}]}
{"op":"mcm","clk":"11797550007","pt":1723025799934,"mc":[{"id":"1.231431354","rc":[{"batl":[[0,1.5,4.69]],"ltp":1.45,"tv":2846.89,"id":31372}]}]}
{"op":"mcm","clk":"11797550173","pt":1723025801609,"mc":[{"id":"1.231431354","rc":[{"batb":[[2,2.72,7.43]],"ltp":2.98,"tv":1055.08,"id":5901},{"batb":[[0,1.44,14.04],[1,1.41,9.44],[2,1.39,8.79]],"ltp":1.45,"tv":2846.89,"id":31372}]}]}
{"op":"mcm","clk":"11797550311","pt":1723025803120,"mc":[{"id":"1.231431354","rc":[{"batb":[[2,1.35,14.59]],"ltp":1.45,"tv":2846.89,"id":31372}]}]}
{"op":"mcm","clk":"11797550347","pt":1723025803536,"mc":[{"id":"1.231431354","rc":[{"batb":[[2,2.2,6.31]],"ltp":2.98,"tv":1055.08,"id":5901},{"batb":[[0,1.41,9.44],[1,1.35,14.59],[2,1.32,17.31]],"ltp":1.45,"tv":2846.89,"id":31372}]}]}
{"op":"mcm","clk":"11797550524","pt":1723025805507,"mc":[{"id":"1.231431354","rc":[{"batb":[[1,2.2,6.31],[2,2.16,12.59]],"ltp":2.98,"tv":1055.08,"id":5901}]}]}
{"op":"mcm","clk":"11797550553","pt":1723025805816,"mc":[{"id":"1.231431354","rc":[{"trd":[[3.15,0.05]],"batb":[[0,3.15,4.13]],"ltp":3.15,"tv":1055.13,"id":5901},{"trd":[[1.47,0.1]],"ltp":1.47,"tv":2846.99,"id":31372}],"tv":3902.12}]}
{"op":"mcm","clk":"11797550987","pt":1723025810520,"mc":[{"id":"1.231431354","rc":[{"batb":[[0,3.2,5.5],[1,3.15,4.13],[2,2.2,6.31]],"ltp":3.15,"tv":1055.13,"id":5901}]}]}
{"op":"mcm","clk":"11797551254","pt":1723025813445,"mc":[{"id":"1.231431354","rc":[{"batb":[[1,2.2,6.31],[2,2.16,12.59]],"ltp":3.15,"tv":1055.13,"id":5901}]}]}
{"op":"mcm","clk":"11797551857","pt":1723025819731,"mc":[{"id":"1.231431354","rc":[{"batl":[[0,1.45,2],[1,1.5,4.69],[2,1.53,6.29]],"ltp":1.47,"tv":2846.99,"id":31372}]}]}
{"op":"mcm","clk":"11797551982","pt":1723025820937,"mc":[{"id":"1.231431354","rc":[{"trd":[[3.2,0.2]],"batb":[[0,3.2,5.4]],"ltp":3.2,"tv":1055.33,"id":5901}],"tv":3902.32}]}
{"op":"mcm","clk":"11797552096","pt":1723025821938,"mc":[{"id":"1.231431354","rc":[{"trd":[[3.2,1.72]],"batb":[[0,3.2,4.64]],"ltp":3.2,"tv":1056.85,"id":5901}],"tv":3903.84}]}
{"op":"mcm","clk":"11797553063","pt":1723025831259,"mc":[{"id":"1.231431354","rc":[{"batb":[[1,1.39,8.79],[2,1.35,14.59]],"ltp":1.47,"tv":2846.99,"id":31372}]}]}
{"op":"mcm","clk":"11797554581","pt":1723025846254,"mc":[{"id":"1.231431354","rc":[{"trd":[[3.2,5.32]],"batb":[[0,3.2,2.84]],"ltp":3.2,"tv":1060.45,"id":5901}],"tv":3907.44}]}
{"op":"mcm","clk":"11797554803","pt":1723025848241,"mc":[{"id":"1.231431354","rc":[{"batb":[[1,1.35,14.59],[2,1.32,17.31]],"ltp":1.47,"tv":2846.99,"id":31372}]}]}
{"op":"mcm","clk":"11797554884","pt":1723025848966,"mc":[{"id":"1.231431354","rc":[{"trd":[[3.2,5.68]],"batb":[[0,3.2,2.66]],"ltp":3.2,"tv":1060.81,"id":5901}],"tv":3907.8}]}
{"op":"mcm","clk":"11797555269","pt":1723025852942,"mc":[{"id":"1.231431354","rc":[{"trd":[[3.2,6.24]],"batb":[[0,3.2,2.38]],"ltp":3.2,"tv":1061.37,"id":5901}],"tv":3908.36}]}
{"op":"mcm","clk":"11797556582","pt":1723025865672,"mc":[{"id":"1.231431354","rc":[{"batb":[[0,3.25,5.13]],"ltp":3.2,"tv":1061.37,"id":5901}]}]}
{"op":"mcm","clk":"11797557119","pt":1723025871078,"mc":[{"id":"1.231431354","rc":[{"batb":[[0,3.3,2.38],[1,3.25,5.13],[2,2.2,6.31]],"ltp":3.2,"tv":1061.37,"id":5901}]}]}
{"op":"mcm","clk":"11797557684","pt":1723025876198,"mc":[{"id":"1.231431354","rc":[{"batb":[[2,1.33,10.85]],"ltp":1.47,"tv":2846.99,"id":31372}]}]}
{"op":"mcm","clk":"11797558195","pt":1723025881110,"mc":[{"id":"1.231431354","rc":[{"batb":[[1,2.2,6.31],[2,2.16,12.59]],"ltp":3.2,"tv":1061.37,"id":5901},{"batb":[[2,1.32,17.31]],"ltp":1.47,"tv":2846.99,"id":31372}]}]}
{"op":"mcm","clk":"11797558339","pt":1723025882315,"mc":[{"id":"1.231431354","rc":[{"trd":[[3.3,1.96]],"batb":[[0,2.2,6.73],[1,2.16,12.59],[2,1.74,17.32]],"ltp":3.3,"tv":1063.33,"id":5901},{"trd":[[1.44,21.8]],"ltp":1.44,"tv":2851.49,"id":31372}],"tv":3914.82}]}
{"op":"mcm","clk":"11797558568","pt":1723025884305,"mc":[{"id":"1.231431354","rc":[{"trd":[[3.3,2.38]],"batb":[[0,2.2,6.31]],"ltp":3.3,"tv":1063.75,"id":5901},{"trd":[[1.44,22.76]],"batb":[[0,1.41,9.83]],"ltp":1.44,"tv":2852.45,"id":31372}],"tv":3916.2}]}
{"op":"mcm","clk":"11797558724","pt":1723025885981,"mc":[{"id":"1.231431354","rc":[{"trd":[[3.3,2.55]],"batb":[[0,3.35,4.96],[1,2.2,6.31],[2,2.16,12.59]],"ltp":3.3,"tv":1063.92,"id":5901},{"trd":[[1.44,23.15]],"batb":[[0,1.41,9.44]],"ltp":1.44,"tv":2852.84,"id":31372}],"tv":3916.76}]}
{"op":"mcm","clk":"11797558935","pt":1723025888110,"mc":[{"id":"1.231431354","rc":[{"batb":[[1,2.76,7.29],[2,2.2,6.31]],"ltp":3.3,"tv":1063.92,"id":5901},{"batb":[[0,1.42,14.18],[1,1.41,9.44],[2,1.35,14.59]],"ltp":1.44,"tv":2852.84,"id":31372}]}]}
{"op":"mcm","clk":"11797559033","pt":1723025888999,"mc":[{"id":"1.231431354","rc":[{"batb":[[1,2.2,6.31],[2,2.16,12.59]],"ltp":3.3,"tv":1063.92,"id":5901},{"batb":[[0,1.41,9.44],[1,1.35,14.59],[2,1.32,17.31]],"ltp":1.44,"tv":2852.84,"id":31372}]}]}
{"op":"mcm","clk":"11797559227","pt":1723025890823,"mc":[{"id":"1.231431354","rc":[{"batl":[[0,1.5,4.69],[1,1.53,6.29],[2,1.6,6.29]],"ltp":1.44,"tv":2852.84,"id":31372}]}]}
{"op":"mcm","clk":"11797560489","pt":1723025902906,"mc":[{"id":"1.231431354","rc":[{"trd":[[3.35,1.92]],"batb":[[0,3.35,3.04]],"ltp":3.35,"tv":1065.84,"id":5901},{"trd":[[1.43,4.5]],"ltp":1.43,"tv":2857.34,"id":31372}],"tv":3923.18}]}
{"op":"mcm","clk":"11797561727","pt":1723025916312,"mc":[{"id":"1.231431354","rc":[{"trd":[[1.41,37.76]],"batb":[[0,1.35,14.59],[1,1.32,17.31],[2,1.24,235.08]],"batl":[[0,1.41,13.06],[1,1.5,4.69],[2,1.53,6.29]],"ltp":1.41,"tv":2876.22,"id":31372}],"tv":3942.06}]}
{"op":"mcm","clk":"11797561762","pt":1723025916624,"mc":[{"id":"1.231431354","rc":[{"batb":[[0,2.2,6.31],[1,2.16,12.59],[2,1.74,17.32]],"ltp":3.35,"tv":1065.84,"id":5901}]}]}
{"op":"mcm","clk":"11797561957","pt":1723025918858,"mc":[{"id":"1.231431354","rc":[{"trd":[[1.41,47.2]],"batl":[[0,1.41,8.34]],"ltp":1.41,"tv":2885.66,"id":31372}],"tv":3951.51}]}
{"op":"mcm","clk":"11797562184","pt":1723025921526,"mc":[{"id":"1.231431354","rc":[{"batb":[[0,3.5,3.04],[1,2.2,6.31],[2,2.16,12.59]],"ltp":3.35,"tv":1065.84,"id":5901}]}]}
{"op":"mcm","clk":"11797562282","pt":1723025922614,"mc":[{"id":"1.231431354","rc":[{"batb":[[1,2.88,7.02],[2,2.2,6.31]],"ltp":3.35,"tv":1065.84,"id":5901}]}]}
{"op":"mcm","clk":"11797562404","pt":1723025924024,"mc":[{"id":"1.231431354","rc":[{"trd":[[3.5,1.89]],"batb":[[0,3.5,1.15]],"ltp":3.5,"tv":1067.73,"id":5901},{"trd":[[1.4,108.92]],"ltp":1.4,"tv":2890.38,"id":31372}],"tv":3958.12}]}
{"op":"mcm","clk":"11797562966","pt":1723025930622,"mc":[{"id":"1.231431354","rc":[{"batb":[[1,2.2,6.31],[2,2.16,12.59]],"ltp":3.5,"tv":1067.73,"id":5901}]}]}
{"op":"mcm","clk":"11797563081","pt":1723025932060,"mc":[{"id":"1.231431354","rc":[{"trd":[[3.5,3.04]],"batb":[[0,2.2,6.31],[1,2.16,12.59],[2,1.74,17.32]],"ltp":3.5,"tv":1068.88,"id":5901},{"trd":[[1.4,111.8]],"batb":[[0,1.41,46.31],[1,1.35,14.59],[2,1.32,17.31]],"batl":[[0,1.5,4.69],[1,1.53,6.29],[2,1.6,6.29]],"ltp":1.4,"tv":2893.26,"id":31372}],"tv":3962.15}]}
{"op":"mcm","clk":"11797563207","pt":1723025933559,"mc":[{"id":"1.231431354","rc":[{"batb":[[1,1.4,81],[2,1.35,14.59]],"ltp":1.4,"tv":2893.26,"id":31372}]}]}
{"op":"mcm","clk":"11797563516","pt":1723025937441,"mc":[{"id":"1.231431354","rc":[{"batb":[[1,1.35,14.59],[2,1.32,17.31]],"ltp":1.4,"tv":2893.26,"id":31372}]}]}
{"op":"mcm","clk":"11797563579","pt":1723025938163,"mc":[{"id":"1.231431354","rc":[{"batb":[[0,2.8,7.19],[1,2.2,6.31],[2,2.16,12.59]],"ltp":3.5,"tv":1068.88,"id":5901},{"batb":[[0,1.41,60.59],[1,1.4,13.53],[2,1.35,14.59]],"ltp":1.4,"tv":2893.26,"id":31372}]}]}
{"op":"mcm","clk":"11797563975","pt":1723025942242,"mc":[{"id":"1.231431354","rc":[{"batb":[[0,2.2,6.31],[1,2.16,12.59],[2,1.74,17.32]],"ltp":3.5,"tv":1068.88,"id":5901}]}]}
{"op":"mcm","clk":"11797564143","pt":1723025944058,"mc":[{"id":"1.231431354","rc":[{"batl":[[0,1.48,1.57],[1,1.5,4.69],[2,1.53,6.29]],"ltp":1.4,"tv":2893.26,"id":31372}]}]}
{"op":"mcm","clk":"11797564353","pt":1723025946750,"mc":[{"id":"1.231431354","rc":[{"batb":[[0,2.84,7.12],[1,2.2,6.31],[2,2.16,12.59]],"ltp":3.5,"tv":1068.88,"id":5901}]}]}
{"op":"mcm","clk":"11797565265","pt":1723025957374,"mc":[{"id":"1.231431354","rc":[{"batb":[[0,2.2,6.31],[1,2.16,12.59],[2,1.74,17.32]],"ltp":3.5,"tv":1068.88,"id":5901},{"batb":[[0,1.41,46.31],[1,1.35,14.59],[2,1.32,17.31]],"ltp":1.4,"tv":2893.26,"id":31372}]}]}
{"op":"mcm","clk":"11797565635","pt":1723025961786,"mc":[{"id":"1.231431354","rc":[{"trd":[[3.05,0.23]],"ltp":3.05,"tv":1069.07,"id":5901},{"trd":[[1.48,0.39]],"batl":[[0,1.48,1.19]],"ltp":1.48,"tv":2893.64,"id":31372}],"tv":3962.72}]}
{"op":"mcm","clk":"11797565724","pt":1723025962677,"mc":[{"id":"1.231431354","rc":[{"batb":[[0,3.15,5.37],[1,2.2,6.31],[2,2.16,12.59]],"ltp":3.05,"tv":1069.07,"id":5901}]}]}
{"op":"mcm","clk":"11797566242","pt":1723025968354,"mc":[{"id":"1.231431354","rc":[{"batb":[[1,2.64,7.64],[2,2.2,6.31]],"ltp":3.05,"tv":1069.07,"id":5901},{"batb":[[0,1.46,13.82],[1,1.41,46.31],[2,1.35,14.59]],"ltp":1.48,"tv":2893.64,"id":31372}]}]}
{"op":"mcm","clk":"11797566324","pt":1723025969182,"mc":[{"id":"1.231431354","rc":[{"batb":[[1,2.2,6.31],[2,2.16,12.59]],"ltp":3.05,"tv":1069.07,"id":5901},{"batb":[[0,1.41,46.31],[1,1.35,14.59],[2,1.32,17.31]],"ltp":1.48,"tv":2893.64,"id":31372}]}]}
{"op":"mcm","clk":"11797566719","pt":1723025973491,"mc":[{"id":"1.231431354","rc":[{"batb":[[2,1.32,11.01]],"ltp":1.48,"tv":2893.64,"id":31372}]}]}
{"op":"mcm","clk":"11797566762","pt":1723025973860,"mc":[{"id":"1.231431354","rc":[{"trd":[[3.15,0.43]],"batb":[[0,3.15,5.18]],"ltp":3.15,"tv":1069.45,"id":5901}],"tv":3963.1}]}
{"op":"mcm","clk":"11797566894","pt":1723025975376,"mc":[{"id":"1.231431354","rc":[{"batb":[[1,2.74,7.36],[2,2.2,6.31]],"ltp":3.15,"tv":1069.45,"id":5901},{"batb":[[0,1.43,14.11],[1,1.41,46.31],[2,1.35,6.72]],"ltp":1.48,"tv":2893.64,"id":31372}]}]}
{"op":"mcm","clk":"11797566958","pt":1723025976206,"mc":[{"id":"1.231431354","rc":[{"batb":[[1,2.2,6.31],[2,2.16,12.59]],"ltp":3.15,"tv":1069.45,"id":5901},{"batb":[[0,1.41,46.31],[1,1.35,6.72],[2,1.32,11.01]],"ltp":1.48,"tv":2893.64,"id":31372}]}]}
{"op":"mcm","clk":"11797567489","pt":1723025982287,"mc":[{"id":"1.231431354","rc":[{"batb":[[1,2.76,7.32],[2,2.2,6.31]],"ltp":3.15,"tv":1069.45,"id":5901},{"batb":[[0,1.43,14.14],[1,1.41,46.31],[2,1.35,6.72]],"ltp":1.48,"tv":2893.64,"id":31372}]}]}
{"op":"mcm","clk":"11797567567","pt":1723025983175,"mc":[{"id":"1.231431354","rc":[{"trd":[[3.15,10.79]],"batb":[[0,2.2,6.31],[1,2.16,12.59],[2,1.74,17.32]],"batl":[[0,3.15,31.38],[1,3.55,2.25],[2,6.6,1.7]],"ltp":3.15,"tv":1079.81,"id":5901},{"batb":[[0,1.41,46.31],[1,1.35,6.72],[2,1.32,11.01]],"ltp":1.48,"tv":2893.64,"id":31372}],"tv":3973.46}]}
{"op":"mcm","clk":"11797567820","pt":1723025986177,"mc":[{"id":"1.231431354","rc":[{"batb":[[0,1.42,45],[1,1.41,46.31],[2,1.35,6.72]],"ltp":1.48,"tv":2893.64,"id":31372}]}]}
{"op":"mcm","clk":"11797567954","pt":1723025987882,"mc":[{"id":"1.231431354","rc":[{"batb":[[0,1.47,9.02],[1,1.42,45],[2,1.41,46.31]],"ltp":1.48,"tv":2893.64,"id":31372}]}]}
{"op":"mcm","clk":"11797568230","pt":1723025990898,"mc":[{"id":"1.231431354","rc":[{"batl":[[0,3.15,31.57]],"ltp":3.15,"tv":1079.81,"id":5901}]}]}
{"op":"mcm","clk":"11797568412","pt":1723025993037,"mc":[{"id":"1.231431354","rc":[{"trd":[[1.48,2.76]],"batl":[[0,1.5,4.69],[1,1.53,6.29],[2,1.6,6.29]],"ltp":1.48,"tv":2896.02,"id":31372}],"tv":3975.84}]}
{"op":"mcm","clk":"11797568744","pt":1723025996680,"mc":[{"id":"1.231431354","rc":[{"batb":[[0,2.26,6.29],[1,2.2,6.31],[2,2.16,12.59]],"ltp":3.15,"tv":1079.81,"id":5901},{"batb":[[0,1.42,45],[1,1.41,46.31],[2,1.35,6.72]],"ltp":1.48,"tv":2896.02,"id":31372}]}]}
{"op":"mcm","clk":"11797570018","pt":1723026009478,"mc":[{"id":"1.231431354","rc":[{"trd":[[3,1.81]],"ltp":3.0,"tv":1080.71,"id":5901},{"trd":[[1.5,3.63]],"batl":[[0,1.5,2.89]],"ltp":1.5,"tv":2897.82,"id":31372}],"tv":3978.54}]}
{"op":"mcm","clk":"11797570080","pt":1723026010162,"mc":[{"id":"1.231431354","rc":[{"trd":[[1.5,9.4]],"batb":[[0,1.5,6.14],[1,1.42,45],[2,1.41,46.31]],"batl":[[0,1.53,6.29],[1,1.6,6.29],[2,1.62,50]],"ltp":1.5,"tv":2903.59,"id":31372}],"tv":3984.31}]}
{"op":"mcm","clk":"11797570588","pt":1723026015585,"mc":[{"id":"1.231431354","rc":[{"batb":[[0,2.68,7.54],[1,2.26,6.29],[2,2.2,6.31]],"ltp":3.0,"tv":1080.71,"id":5901},{"batb":[[0,1.45,13.93]],"ltp":1.5,"tv":2903.59,"id":31372}]}]}
{"op":"mcm","clk":"11797571100","pt":1723026021459,"mc":[{"id":"1.231431354","rc":[{"batb":[[0,2.9,6.08],[1,2.68,7.54],[2,2.26,6.29]],"batl":[[0,3.15,31.38]],"ltp":3.0,"tv":1080.71,"id":5901},{"trd":[[1.53,0.2]],"batl":[[0,1.53,6.19]],"ltp":1.53,"tv":2903.79,"id":31372}],"tv":3984.51}]}
{"op":"mcm","clk":"11797571148","pt":1723026022036,"mc":[{"id":"1.231431354","rc":[{"batl":[[0,3.55,2.25],[1,6.6,1.7],[2,10,1.19]],"ltp":3.0,"tv":1080.71,"id":5901}]}]}
{"op":"mcm","clk":"11797572857","pt":1723026040019,"mc":[{"id":"1.231431354","rc":[{"trd":[[2.9,12.16]],"batb":[[0,2.68,7.54],[1,2.26,6.29],[2,2.2,6.31]],"batl":[[0,2.9,25],[1,3.55,2.25],[2,6.6,1.7]],"ltp":2.9,"tv":1092.87,"id":5901}],"tv":3996.67}]}
{"op":"mcm","clk":"11797572917","pt":1723026040602,"mc":[{"id":"1.231431354","rc":[{"batb":[[0,2.26,6.29],[1,2.2,6.31],[2,2.16,12.59]],"ltp":2.9,"tv":1092.87,"id":5901},{"batb":[[0,1.42,45],[1,1.41,46.31],[2,1.35,6.72]],"ltp":1.53,"tv":2903.79,"id":31372}]}]}
{"op":"mcm","clk":"11797574004","pt":1723026052287,"mc":[{"id":"1.231431354","rc":[{"batb":[[0,1.41,46.31],[1,1.35,6.72],[2,1.32,11.01]],"ltp":1.53,"tv":2903.79,"id":31372}]}]}
{"op":"mcm","clk":"11797574666","pt":1723026059437,"mc":[{"id":"1.231431354","rc":[{"trd":[[1.53,12.59]],"batb":[[0,1.53,1.93],[1,1.41,46.31],[2,1.35,6.72]],"batl":[[0,1.6,6.29],[1,1.62,50],[2,1.75,2]],"ltp":1.53,"tv":2916.18,"id":31372}],"tv":4009.05}]}
{"op":"mcm","clk":"11797574830","pt":1723026061260,"mc":[{"id":"1.231431354","rc":[{"batl":[[0,2.9,25.38]],"ltp":2.9,"tv":1092.87,"id":5901}]}]}
{"op":"mcm","clk":"11797575329","pt":1723026066386,"mc":[{"id":"1.231431354","rc":[{"batb":[[0,2.66,7.57],[1,2.26,6.29],[2,2.2,6.31]],"batl":[[0,3.55,2.63],[1,6.6,1.7],[2,10,1.19]],"ltp":2.9,"tv":1092.87,"id":5901},{"batb":[[1,1.45,13.89],[2,1.41,46.31]],"ltp":1.53,"tv":2916.18,"id":31372}]}]}
{"op":"mcm","clk":"11797575768","pt":1723026071473,"mc":[{"id":"1.231431354","rc":[{"batb":[[0,2.26,6.29],[1,2.2,6.31],[2,2.16,12.59]],"ltp":2.9,"tv":1092.87,"id":5901}]}]}
{"op":"mcm","clk":"11797576224","pt":1723026076479,"mc":[{"id":"1.231431354","rc":[{"batb":[[0,2.7,7.47],[1,2.26,6.29],[2,2.2,6.31]],"ltp":2.9,"tv":1092.87,"id":5901}]}]}
{"op":"mcm","clk":"11797576484","pt":1723026079452,"mc":[{"id":"1.231431354","rc":[{"batl":[[0,3.55,2.25]],"ltp":2.9,"tv":1092.87,"id":5901},{"batb":[[0,1.45,13.89],[1,1.41,46.31],[2,1.35,6.72]],"ltp":1.53,"tv":2916.18,"id":31372}]}]}
{"op":"mcm","clk":"11797576562","pt":1723026080380,"mc":[{"id":"1.231431354","rc":[{"batl":[[2,1.74,6.72]],"ltp":1.53,"tv":2916.18,"id":31372}]}]}
{"op":"mcm","clk":"11797576727","pt":1723026082208,"mc":[{"id":"1.231431354","rc":[{"trd":[[2.7,0.57]],"batb":[[0,2.7,7.19]],"ltp":2.7,"tv":1093.44,"id":5901},{"batl":[[2,1.75,2]],"ltp":1.53,"tv":2916.18,"id":31372}],"tv":4009.62}]}
{"op":"mcm","clk":"11797576893","pt":1723026083988,"mc":[{"id":"1.231431354","rc":[{"trd":[[2.66,11],[2.7,14.94]],"batb":[[0,2.26,6.29],[1,2.2,6.31],[2,2.16,12.59]],"batl":[[0,2.66,14.33],[1,3.55,2.25],[2,6.6,1.7]],"ltp":2.66,"tv":1111.6,"id":5901},{"trd":[[1.6,18.28]],"batl":[[0,1.62,50],[1,1.75,2],[2,1.77,27.15]],"ltp":1.6,"tv":2922.47,"id":31372}],"tv":4034.07}]}
{"op":"mcm","clk":"11797576992","pt":1723026084968,"mc":[{"id":"1.231431354","rc":[{"batb":[[0,1.41,46.97],[1,1.35,6.72],[2,1.32,11.01]],"ltp":1.6,"tv":2922.47,"id":31372}]}]}
{"op":"mcm","clk":"11797577427","pt":1723026089775,"mc":[{"id":"1.231431354","rc":[{"batb":[[0,1.47,2.23],[1,1.41,46.31],[2,1.35,6.72]],"ltp":1.6,"tv":2922.47,"id":31372}]}]}
{"op":"mcm","clk":"11797577631","pt":1723026091981,"mc":[{"id":"1.231431354","rc":[{"batb":[[0,1.51,1.57],[1,1.49,2.23],[2,1.47,1.57]],"ltp":1.6,"tv":2922.47,"id":31372}]}]}
{"op":"mcm","clk":"11797577756","pt":1723026093496,"mc":[{"id":"1.231431354","rc":[{"batb":[[0,1.56,1.57],[1,1.51,1.57],[2,1.49,2.23]],"ltp":1.6,"tv":2922.47,"id":31372}]}]}
{"op":"mcm","clk":"11797577817","pt":1723026094271,"mc":[{"id":"1.231431354","rc":[{"trd":[[2.66,14.78]],"batl":[[0,2.66,10.54]],"ltp":2.66,"tv":1115.38,"id":5901},{"trd":[[1.6,24.58]],"batb":[[0,1.58,1.57],[1,1.56,1.57],[2,1.51,1.57]],"ltp":1.6,"tv":2928.76,"id":31372}],"tv":4044.15}]}
{"op":"mcm","clk":"11797577877","pt":1723026095100,"mc":[{"id":"1.231431354","rc":[{"batb":[[0,1.59,1.57],[1,1.58,1.57],[2,1.56,1.57]],"ltp":1.6,"tv":2928.76,"id":31372}]}]}
{"op":"mcm","clk":"11797577973","pt":1723026096198,"mc":[{"id":"1.231431354","rc":[{"trd":[[1.62,9.02]],"batl":[[0,1.62,45.49]],"ltp":1.62,"tv":2937.78,"id":31372}],"tv":4053.17}]}
{"op":"mcm","clk":"11797578514","pt":1723026102015,"mc":[{"id":"1.231431354","rc":[{"batl":[[0,3.55,2.25],[1,6.6,1.7],[2,10,1.19]],"ltp":2.66,"tv":1115.38,"id":5901}]}]}
{"op":"mcm","clk":"11797578924","pt":1723026106938,"mc":[{"id":"1.231431354","rc":[{"batl":[[0,1.62,45.77]],"ltp":1.62,"tv":2937.78,"id":31372}]}]}
{"op":"mcm","clk":"11797579058","pt":1723026108322,"mc":[{"id":"1.231431354","rc":[{"trd":[[2.66,14.88]],"ltp":2.66,"tv":1115.48,"id":5901},{"trd":[[1.6,24.75]],"batl":[[0,1.62,45.61]],"ltp":1.6,"tv":2937.95,"id":31372}],"tv":4053.44}]}
{"op":"mcm","clk":"11797579398","pt":1723026112319,"mc":[{"id":"1.231431354","rc":[{"trd":[[2.64,0.01]],"batb":[[0,2.64,7.03],[1,2.26,6.29],[2,2.2,6.31]],"ltp":2.64,"tv":1115.49,"id":5901},{"trd":[[1.61,0.02]],"batl":[[0,1.62,45.49]],"ltp":1.61,"tv":2937.97,"id":31372}],"tv":4053.47}]}
{"op":"mcm","clk":"11797579426","pt":1723026112632,"mc":[{"id":"1.231431354","rc":[{"trd":[[2.64,0.56]],"batb":[[0,2.64,6.48]],"ltp":2.64,"tv":1116.04,"id":5901},{"trd":[[1.61,0.92]],"ltp":1.61,"tv":2938.87,"id":31372}],"tv":4054.92}]}
{"op":"mcm","clk":"11797579562","pt":1723026114427,"mc":[{"id":"1.231431354","rc":[{"batl":[[0,1.6,8.22],[1,1.62,45.49],[2,1.75,2]],"ltp":1.61,"tv":2938.87,"id":31372}]}]}
{"op":"mcm","clk":"11797579633","pt":1723026115256,"mc":[{"id":"1.231431354","rc":[{"trd":[[2.7,15.87],[2.74,0.91],[2.8,0.88]],"batb":[[0,2.82,4.44],[1,2.64,6.48],[2,2.26,6.29]],"ltp":2.8,"tv":1118.76,"id":5901},{"trd":[[1.56,1.57],[1.58,1.57],[1.59,1.57]],"batb":[[0,1.51,1.57],[1,1.49,2.23],[2,1.47,1.57]],"batl":[[2,1.74,6.72]],"ltp":1.56,"tv":2943.59,"id":31372}],"tv":4062.35}]}
{"op":"mcm","clk":"11797579898","pt":1723026118427,"mc":[{"id":"1.231431354","rc":[{"batb":[[0,2.64,6.48],[1,2.26,6.29],[2,2.2,6.31]],"ltp":2.8,"tv":1118.76,"id":5901}]}]}
{"op":"mcm","clk":"11797580094","pt":1723026121141,"mc":[{"id":"1.231431354","rc":[{"batb":[[0,2.82,2.71],[1,2.64,6.48],[2,2.26,6.29]],"ltp":2.8,"tv":1118.76,"id":5901}]}]}
{"op":"mcm","clk":"11797580223","pt":1723026122455,"mc":[{"id":"1.231431354","rc":[{"batb":[[0,2.64,6.48],[1,2.26,6.29],[2,2.2,6.31]],"ltp":2.8,"tv":1118.76,"id":5901},{"batl":[[0,1.6,3163.9]],"ltp":1.56,"tv":2943.59,"id":31372}]}]}
{"op":"mcm","clk":"11797580611","pt":1723026127163,"mc":[{"id":"1.231431354","rc":[{"batb":[[0,2.26,6.29],[1,2.2,6.31],[2,2.16,12.59]],"ltp":2.8,"tv":1118.76,"id":5901},{"batb":[[0,1.55,27.05],[1,1.51,1.57],[2,1.49,2.23]],"ltp":1.56,"tv":2943.59,"id":31372}]}]}
{"op":"mcm","clk":"11797580992","pt":1723026131864,"mc":[{"id":"1.231431354","rc":[{"batb":[[0,2.68,6.48],[1,2.26,6.29],[2,2.2,6.31]],"ltp":2.8,"tv":1118.76,"id":5901}]}]}
{"op":"mcm","clk":"11797581171","pt":1723026134227,"mc":[{"id":"1.231431354","rc":[{"batb":[[0,2.26,6.29],[1,2.2,6.31],[2,2.16,12.59]],"ltp":2.8,"tv":1118.76,"id":5901},{"batb":[[0,1.56,1.57],[1,1.55,27.05],[2,1.51,1.57]],"batl":[[0,1.58,6.29],[1,1.6,3163.9],[2,1.62,45.49]],"ltp":1.56,"tv":2943.59,"id":31372}]}]}
{"op":"mcm","clk":"11797581254","pt":1723026135265,"mc":[{"id":"1.231431354","rc":[{"trd":[[1.58,7.87]],"batl":[[0,1.58,3.15]],"ltp":1.58,"tv":2949.88,"id":31372}],"tv":4068.65}]}
{"op":"mcm","clk":"11797581362","pt":1723026136468,"mc":[{"id":"1.231431354","rc":[{"trd":[[1.58,14.17],[1.6,32.83]],"batl":[[0,1.6,3159.86],[1,1.62,45.49],[2,1.74,6.72]],"ltp":1.6,"tv":2964.27,"id":31372}],"tv":4083.03}]}
{"op":"mcm","clk":"11797581392","pt":1723026136746,"mc":[{"id":"1.231431354","rc":[{"trd":[[1.6,39.12]],"batl":[[0,1.6,3156.72]],"ltp":1.6,"tv":2970.55,"id":31372}],"tv":4089.31}]}
{"op":"mcm","clk":"11797581513","pt":1723026138269,"mc":[{"id":"1.231431354","rc":[{"trd":[[1.6,54.85]],"batl":[[0,1.6,3148.86]],"ltp":1.6,"tv":2986.28,"id":31372}],"tv":4105.04}]}
{"op":"mcm","clk":"11797581576","pt":1723026138990,"mc":[{"id":"1.231431354","rc":[{"batb":[[0,2.74,6.48],[1,2.26,6.29],[2,2.2,6.31]],"ltp":2.8,"tv":1118.76,"id":5901}]}]}
{"op":"mcm","clk":"11797581670","pt":1723026139978,"mc":[{"id":"1.231431354","rc":[{"batl":[[0,2.82,10.54],[1,3.55,2.25],[2,6.6,1.7]],"ltp":2.8,"tv":1118.76,"id":5901}]}]}
{"op":"mcm","clk":"11797582558","pt":1723026150087,"mc":[{"id":"1.231431354","rc":[{"batl":[[2,1.75,2]],"ltp":1.6,"tv":2986.28,"id":31372}]}]}
{"op":"mcm","clk":"11797582588","pt":1723026150557,"mc":[{"id":"1.231431354","rc":[{"trd":[[2.74,3.51]],"batb":[[0,2.74,3.88]],"ltp":2.74,"tv":1121.36,"id":5901},{"trd":[[1.58,18.68]],"ltp":1.58,"tv":2990.79,"id":31372}],"tv":4112.15}]}
{"op":"mcm","clk":"11797582869","pt":1723026154360,"mc":[{"id":"1.231431354","rc":[{"trd":[[1.56,1.78]],"batb":[[0,1.56,1.47]],"ltp":1.56,"tv":2990.99,"id":31372}],"tv":4112.35}]}
{"op":"mcm","clk":"11797583057","pt":1723026156512,"mc":[{"id":"1.231431354","rc":[{"batb":[[0,1.57,7.87],[1,1.56,1.47],[2,1.55,27.05]],"ltp":1.56,"tv":2990.99,"id":31372}]}]}
{"op":"mcm","clk":"11797583160","pt":1723026157922,"mc":[{"id":"1.231431354","rc":[{"trd":[[2.74,7.39]],"batb":[[0,2.26,6.29],[1,2.2,6.31],[2,2.16,12.59]],"ltp":2.74,"tv":1125.24,"id":5901},{"trd":[[1.58,25.4]],"batb":[[0,1.59,7.87],[1,1.58,1.14],[2,1.57,7.87]],"ltp":1.58,"tv":2997.72,"id":31372}],"tv":4122.96}]}
{"op":"mcm","clk":"11797583325","pt":1723026160099,"mc":[{"id":"1.231431354","rc":[{"trd":[[1.6,290.88]],"batl":[[0,1.6,3030.84]],"ltp":1.6,"tv":3233.76,"id":31372}],"tv":4359.0}]}
{"op":"mcm","clk":"11797583558","pt":1723026163171,"mc":[{"id":"1.231431354","rc":[{"trd":[[1.59,17.31]],"batb":[[0,1.58,1.14],[1,1.57,7.87],[2,1.56,1.47]],"ltp":1.59,"tv":3249.5,"id":31372}],"tv":4374.74}]}
{"op":"mcm","clk":"11797584005","pt":1723026168134,"mc":[{"id":"1.231431354","rc":[{"batl":[[2,1.74,6.72]],"ltp":1.59,"tv":3249.5,"id":31372}]}]}
{"op":"mcm","clk":"11797584160","pt":1723026169856,"mc":[{"id":"1.231431354","rc":[{"batl":[[2,1.75,2]],"ltp":1.59,"tv":3249.5,"id":31372}]}]}
{"op":"mcm","clk":"11797584522","pt":1723026173853,"mc":[{"id":"1.231431354","rc":[{"trd":[[2.66,14.9]],"ltp":2.66,"tv":1125.26,"id":5901},{"trd":[[1.6,290.91]],"batl":[[0,1.6,3030.81]],"ltp":1.6,"tv":3249.53,"id":31372}],"tv":4374.79}]}
{"op":"mcm","clk":"11797584621","pt":1723026174941,"mc":[{"id":"1.231431354","rc":[{"batb":[[1,1.56,1.47],[2,1.51,1.57]],"ltp":1.6,"tv":3249.53,"id":31372}]}]}
{"op":"mcm","clk":"11797585399","pt":1723026184378,"mc":[{"id":"1.231431354","rc":[{"trd":[[1.6,297.2]],"batl":[[0,1.6,3027.67]],"ltp":1.6,"tv":3255.81,"id":31372}],"tv":4381.07}]}
{"op":"mcm","clk":"11797585490","pt":1723026185478,"mc":[{"id":"1.231431354","rc":[{"trd":[[1.6,316.06]],"batl":[[0,1.6,3018.25]],"ltp":1.6,"tv":3274.67,"id":31372}],"tv":4399.94}]}
{"op":"mcm","clk":"11797585581","pt":1723026186470,"mc":[{"id":"1.231431354","rc":[{"batl":[[0,3.55,2.25],[1,6.6,1.7],[2,10,1.19]],"ltp":2.66,"tv":1125.26,"id":5901},{"trd":[[1.6,338.07]],"batl":[[0,1.6,3007.26]],"ltp":1.6,"tv":3296.68,"id":31372}],"tv":4421.94}]}
{"op":"mcm","clk":"11797585597","pt":1723026186681,"mc":[{"id":"1.231431354","rc":[{"trd":[[1.6,341.21]],"batl":[[0,1.6,3005.69]],"ltp":1.6,"tv":3299.82,"id":31372}],"tv":4425.08}]}
{"op":"mcm","clk":"11797585751","pt":1723026188486,"mc":[{"id":"1.231431354","rc":[{"trd":[[1.6,353.78]],"batl":[[0,1.6,2999.41]],"ltp":1.6,"tv":3312.4,"id":31372}],"tv":4437.66}]}
{"op":"mcm","clk":"11797585818","pt":1723026189178,"mc":[{"id":"1.231431354","rc":[{"batl":[[0,1.6,2974.61]],"ltp":1.6,"tv":3312.4,"id":31372}]}]}
{"op":"mcm","clk":"11797585888","pt":1723026189991,"mc":[{"id":"1.231431354","rc":[{"trd":[[1.6,360.07]],"batl":[[0,1.6,2971.47]],"ltp":1.6,"tv":3318.68,"id":31372}],"tv":4443.95}]}
{"op":"mcm","clk":"11797586050","pt":1723026192076,"mc":[{"id":"1.231431354","rc":[{"batb":[[0,2.6,7.75],[1,2.26,6.29],[2,2.2,6.31]],"ltp":2.66,"tv":1125.26,"id":5901}]}]}
{"op":"mcm","clk":"11797586670","pt":1723026199497,"mc":[{"id":"1.231431354","rc":[{"batb":[[2,1.41,46.97]],"ltp":1.6,"tv":3318.68,"id":31372}]}]}
{"op":"mcm","clk":"11797586737","pt":1723026200374,"mc":[{"id":"1.231431354","rc":[{"trd":[[2.66,25.45]],"batb":[[0,2.68,6.87],[1,2.6,7.75],[2,2.26,6.29]],"ltp":2.66,"tv":1135.8,"id":5901},{"trd":[[1.6,377.6]],"batl":[[0,1.6,2953.94]],"ltp":1.6,"tv":3336.21,"id":31372}],"tv":4472.02}]}
{"op":"mcm","clk":"11797586896","pt":1723026202296,"mc":[{"id":"1.231431354","rc":[{"batb":[[1,2.26,6.29],[2,2.2,6.31]],"ltp":2.66,"tv":1135.8,"id":5901}]}]}
{"op":"mcm","clk":"11797587077","pt":1723026204373,"mc":[{"id":"1.231431354","rc":[{"trd":[[1.6,380.74]],"batl":[[0,1.6,2952.37]],"ltp":1.6,"tv":3339.36,"id":31372}],"tv":4475.16}]}
{"op":"mcm","clk":"11797587135","pt":1723026204939,"mc":[{"id":"1.231431354","rc":[{"trd":[[1.6,383.89]],"batb":[[2,1.47,14.37]],"batl":[[0,1.6,2950.8]],"ltp":1.6,"tv":3342.5,"id":31372}],"tv":4478.3}]}
{"op":"mcm","clk":"11797587653","pt":1723026211072,"mc":[{"id":"1.231431354","rc":[{"batb":[[1,2.62,7.72],[2,2.26,6.29]],"ltp":2.66,"tv":1135.8,"id":5901},{"batl":[[0,1.6,2949.9]],"ltp":1.6,"tv":3342.5,"id":31372}]}]}
{"op":"mcm","clk":"11797588386","pt":1723026220309,"mc":[{"id":"1.231431354","rc":[{"trd":[[1.58,27.68]],"batb":[[0,1.56,1.47],[1,1.47,14.37],[2,1.41,46.31]],"batl":[[0,1.58,392.25],[1,1.6,2949.9],[2,1.62,45.49]],"ltp":1.58,"tv":3344.78,"id":31372}],"tv":4480.59}]}
{"op":"mcm","clk":"11797588414","pt":1723026220670,"mc":[{"id":"1.231431354","rc":[{"batb":[[0,2.62,7.72],[1,2.26,6.29],[2,2.2,6.31]],"ltp":2.66,"tv":1135.8,"id":5901}]}]}
{"op":"mcm","clk":"11797588787","pt":1723026225617,"mc":[{"id":"1.231431354","rc":[{"batb":[[0,2.74,6.87],[1,2.62,7.72],[2,2.26,6.29]],"ltp":2.66,"tv":1135.8,"id":5901}]}]}
{"op":"mcm","clk":"11797592666","pt":1723026271821,"mc":[{"id":"1.231431354","rc":[{"batl":[[0,1.6,2949.9],[1,1.62,45.49],[2,1.75,2]],"ltp":1.58,"tv":3344.78,"id":31372}]}]}
{"op":"mcm","clk":"11797593597","pt":1723026283348,"mc":[{"id":"1.231431354","rc":[{"batb":[[1,2.26,6.29],[2,2.2,6.31]],"ltp":2.66,"tv":1135.8,"id":5901},{"batb":[[1,1.41,46.97],[2,1.35,6.72]],"ltp":1.58,"tv":3344.78,"id":31372}]}]}
{"op":"mcm","clk":"11797593777","pt":1723026285358,"mc":[{"id":"1.231431354","rc":[{"batb":[[0,2.76,6.56]],"ltp":2.66,"tv":1135.8,"id":5901}]}]}
{"op":"mcm","clk":"11797593815","pt":1723026285900,"mc":[{"id":"1.231431354","rc":[{"batl":[[0,1.62,45.49],[1,1.75,2],[2,1.77,27.15]],"ltp":1.58,"tv":3344.78,"id":31372}]}]}
{"op":"mcm","clk":"11797593928","pt":1723026287165,"mc":[{"id":"1.231431354","rc":[{"trd":[[1.56,4.72]],"batb":[[0,1.41,46.97],[1,1.35,6.72],[2,1.32,11.01]],"batl":[[0,1.56,35.51],[1,1.62,45.49],[2,1.75,2]],"ltp":1.56,"tv":3347.73,"id":31372}],"tv":4483.53}]}
{"op":"mcm","clk":"11797594187","pt":1723026290357,"mc":[{"id":"1.231431354","rc":[{"batb":[[0,2.78,6.87],[1,2.76,6.56],[2,2.26,6.29]],"ltp":2.66,"tv":1135.8,"id":5901}]}]}
{"op":"mcm","clk":"11797594415","pt":1723026293277,"mc":[{"id":"1.231431354","rc":[{"batb":[[2,2.64,7.64]],"ltp":2.66,"tv":1135.8,"id":5901},{"batb":[[0,1.46,14.48],[1,1.41,46.31],[2,1.35,6.72]],"ltp":1.56,"tv":3347.73,"id":31372}]}]}
{"op":"mcm","clk":"11797594458","pt":1723026293898,"mc":[{"id":"1.231431354","rc":[{"batb":[[2,2.26,6.29]],"ltp":2.66,"tv":1135.8,"id":5901},{"batb":[[0,1.41,46.97],[1,1.35,6.72],[2,1.32,11.01]],"ltp":1.56,"tv":3347.73,"id":31372}]}]}
{"op":"mcm","clk":"11797594878","pt":1723026298863,"mc":[{"id":"1.231431354","rc":[{"batb":[[0,1.41,46.31]],"ltp":1.56,"tv":3347.73,"id":31372}]}]}
{"op":"mcm","clk":"11797595059","pt":1723026300328,"mc":[{"id":"1.231431354","rc":[{"batb":[[1,2.26,6.29],[2,2.2,6.31]],"ltp":2.66,"tv":1135.8,"id":5901}]}]}
{"op":"mcm","clk":"11797595112","pt":1723026300820,"mc":[{"id":"1.231431354","rc":[{"batb":[[0,2.26,6.29],[1,2.2,6.31],[2,2.16,12.59]],"ltp":2.66,"tv":1135.8,"id":5901}]}]}
{"op":"mcm","clk":"11797595557","pt":1723026305304,"mc":[{"id":"1.231431354","rc":[{"batb":[[0,2.8,6.56],[1,2.26,6.29],[2,2.2,6.31]],"ltp":2.66,"tv":1135.8,"id":5901}]}]}
{"op":"mcm","clk":"11797595844","pt":1723026308285,"mc":[{"id":"1.231431354","rc":[{"trd":[[1.56,4.92]],"batl":[[0,1.56,35.41]],"ltp":1.56,"tv":3347.93,"id":31372}],"tv":4483.73}]}
{"op":"mcm","clk":"11797596635","pt":1723026317016,"mc":[{"id":"1.231431354","rc":[{"trd":[[2.8,1.79]],"batb":[[0,2.8,6.1]],"ltp":2.8,"tv":1136.72,"id":5901}],"tv":4484.65}]}
{"op":"mcm","clk":"11797596838","pt":1723026319392,"mc":[{"id":"1.231431354","rc":[{"trd":[[1.41,62.94]],"batb":[[0,1.41,38.44]],"ltp":1.41,"tv":3363.67,"id":31372}],"tv":4500.39}]}
{"op":"mcm","clk":"11797596855","pt":1723026319594,"mc":[{"id":"1.231431354","rc":[{"trd":[[1.41,78.68]],"batb":[[0,1.41,30.57]],"ltp":1.41,"tv":3379.4,"id":31372}],"tv":4516.13}]}
{"op":"mcm","clk":"11797597094","pt":1723026322471,"mc":[{"id":"1.231431354","rc":[{"batb":[[0,2.26,6.29],[1,2.2,6.31],[2,2.16,12.59]],"ltp":2.8,"tv":1136.72,"id":5901},{"batl":[[0,1.52,7.87],[1,1.53,15.74],[2,1.54,15.74]],"ltp":1.41,"tv":3379.4,"id":31372}]}]}
{"op":"mcm","clk":"11797597115","pt":1723026322696,"mc":[{"id":"1.231431354","rc":[{"batl":[[0,1.52,15.74]],"ltp":1.41,"tv":3379.4,"id":31372}]}]}
{"op":"mcm","clk":"11797597273","pt":1723026324505,"mc":[{"id":"1.231431354","rc":[{"batb":[[0,1.41,31.32]],"batl":[[0,1.5,23.6],[1,1.51,23.6],[2,1.52,15.74]],"ltp":1.41,"tv":3379.4,"id":31372}]}]}
{"op":"mcm","clk":"11797597337","pt":1723026325177,"mc":[{"id":"1.231431354","rc":[{"trd":[[3,1.92]],"ltp":3.0,"tv":1136.82,"id":5901},{"trd":[[1.49,0.29]],"batl":[[0,1.48,15.74],[1,1.49,23.4],[2,1.5,23.6]],"ltp":1.49,"tv":3379.61,"id":31372}],"tv":4516.43}]}
{"op":"mcm","clk":"11797597886","pt":1723026331406,"mc":[{"id":"1.231431354","rc":[{"batl":[[0,1.49,23.4],[1,1.5,23.6],[2,1.51,23.6]],"ltp":1.49,"tv":3379.61,"id":31372}]}]}
{"op":"mcm","clk":"11797597979","pt":1723026332388,"mc":[{"id":"1.231431354","rc":[{"batb":[[0,3.15,6.1],[1,2.26,6.29],[2,2.2,6.31]],"ltp":3.0,"tv":1136.82,"id":5901},{"batb":[[0,1.42,16.49],[1,1.41,30.57],[2,1.35,6.72]],"batl":[[0,1.5,23.6],[1,1.51,23.6],[2,1.52,15.74]],"ltp":1.49,"tv":3379.61,"id":31372}]}]}
{"op":"mcm","clk":"11797598026","pt":1723026333024,"mc":[{"id":"1.231431354","rc":[{"batb":[[1,2.7,7.47],[2,2.26,6.29]],"ltp":3.0,"tv":1136.82,"id":5901},{"batb":[[0,1.44,14.75],[1,1.42,15.74],[2,1.41,30.57]],"ltp":1.49,"tv":3379.61,"id":31372}]}]}
{"op":"mcm","clk":"11797598116","pt":1723026333910,"mc":[{"id":"1.231431354","rc":[{"batb":[[1,2.26,6.29],[2,2.2,6.31]],"ltp":3.0,"tv":1136.82,"id":5901},{"batb":[[0,1.42,16.49],[1,1.41,30.57],[2,1.35,6.72]],"ltp":1.49,"tv":3379.61,"id":31372}]}]}
{"op":"mcm","clk":"11797598254","pt":1723026335523,"mc":[{"id":"1.231431354","rc":[{"batl":[[0,1.51,23.6],[1,1.52,15.74],[2,1.53,15.74]],"ltp":1.49,"tv":3379.61,"id":31372}]}]}
{"op":"mcm","clk":"11797598420","pt":1723026337404,"mc":[{"id":"1.231431354","rc":[{"batb":[[0,1.46,205],[1,1.42,16.49],[2,1.41,30.57]],"ltp":1.49,"tv":3379.61,"id":31372}]}]}
{"op":"mcm","clk":"11797598472","pt":1723026338029,"mc":[{"id":"1.231431354","rc":[{"batl":[[0,1.52,15.74],[1,1.53,15.74],[2,1.54,15.74]],"ltp":1.49,"tv":3379.61,"id":31372}]}]}
{"op":"mcm","clk":"11797598581","pt":1723026339335,"mc":[{"id":"1.231431354","rc":[{"batl":[[0,1.53,15.74],[1,1.54,15.74],[2,1.56,35.41]],"ltp":1.49,"tv":3379.61,"id":31372}]}]}
{"op":"mcm","clk":"11797599259","pt":1723026347241,"mc":[{"id":"1.231431354","rc":[{"batb":[[0,1.42,16.49],[1,1.41,30.57],[2,1.35,6.72]],"ltp":1.49,"tv":3379.61,"id":31372}]}]}
{"op":"mcm","clk":"11797599493","pt":1723026349921,"mc":[{"id":"1.231431354","rc":[{"trd":[[3.15,13.36]],"batb":[[0,3.15,3.53]],"ltp":3.15,"tv":1139.39,"id":5901},{"trd":[[1.47,5.61]],"ltp":1.47,"tv":3385.12,"id":31372}],"tv":4524.51}]}
{"op":"mcm","clk":"11797599716","pt":1723026352344,"mc":[{"id":"1.231431354","rc":[{"batb":[[0,1.45,205],[1,1.42,16.49],[2,1.41,30.57]],"ltp":1.47,"tv":3385.12,"id":31372}]}]}
{"op":"mcm","clk":"11797599858","pt":1723026354316,"mc":[{"id":"1.231431354","rc":[{"trd":[[3.15,13.92]],"batb":[[0,3.15,3.25]],"ltp":3.15,"tv":1139.95,"id":5901},{"batl":[[0,1.52,5.51],[1,1.53,15.74],[2,1.54,15.74]],"ltp":1.47,"tv":3385.12,"id":31372}],"tv":4525.07}]}
{"op":"mcm","clk":"11797600530","pt":1723026362258,"mc":[{"id":"1.231431354","rc":[{"batl":[[1,1.54,15.74],[2,1.56,35.41]],"ltp":1.47,"tv":3385.12,"id":31372}]}]}
{"op":"mcm","clk":"11797600561","pt":1723026362571,"mc":[{"id":"1.231431354","rc":[{"batl":[[1,1.56,35.41],[2,1.62,45.49]],"ltp":1.47,"tv":3385.12,"id":31372}]}]}
{"op":"mcm","clk":"11797600726","pt":1723026364554,"mc":[{"id":"1.231431354","rc":[{"trd":[[3.15,17.17]],"batb":[[0,2.26,6.29],[1,2.2,6.31],[2,2.16,12.59]],"ltp":3.15,"tv":1143.2,"id":5901},{"trd":[[1.47,12.57]],"batb":[[0,1.47,353.69],[1,1.45,205],[2,1.42,16.49]],"ltp":1.47,"tv":3392.08,"id":31372}],"tv":4535.28}]}
{"op":"mcm","clk":"11797601047","pt":1723026368565,"mc":[{"id":"1.231431354","rc":[{"batl":[[0,3.55,2.53]],"ltp":3.15,"tv":1143.2,"id":5901}]}]}
{"op":"mcm","clk":"11797601431","pt":1723026373155,"mc":[{"id":"1.231431354","rc":[{"batb":[[1,1.42,16.49],[2,1.41,30.57]],"ltp":1.47,"tv":3392.08,"id":31372}]}]}
{"op":"mcm","clk":"11797601493","pt":1723026373943,"mc":[{"id":"1.231431354","rc":[{"batb":[[0,1.47,349.19]],"ltp":1.47,"tv":3392.08,"id":31372}]}]}
{"op":"mcm","clk":"11797601615","pt":1723026375347,"mc":[{"id":"1.231431354","rc":[{"batb":[[0,1.42,16.49],[1,1.41,30.57],[2,1.35,6.72]],"ltp":1.47,"tv":3392.08,"id":31372}]}]}
{"op":"mcm","clk":"11797601838","pt":1723026378227,"mc":[{"id":"1.231431354","rc":[{"batb":[[2,1.35,16.54]],"ltp":1.47,"tv":3392.08,"id":31372}]}]}
{"op":"mcm","clk":"11797601931","pt":1723026379267,"mc":[{"id":"1.231431354","rc":[{"batl":[[0,3.55,2.25]],"ltp":3.15,"tv":1143.2,"id":5901},{"batb":[[2,1.35,6.72]],"ltp":1.47,"tv":3392.08,"id":31372}]}]}
{"op":"mcm","clk":"11797602040","pt":1723026380567,"mc":[{"id":"1.231431354","rc":[{"batl":[[0,1.5,3606.49],[1,1.52,5.51],[2,1.56,35.41]],"ltp":1.47,"tv":3392.08,"id":31372}]}]}
{"op":"mcm","clk":"11797603030","pt":1723026392141,"mc":[{"id":"1.231431354","rc":[{"trd":[[3,2.01]],"ltp":3.0,"tv":1143.29,"id":5901},{"trd":[[1.5,9.58]],"batl":[[0,1.5,3606.31]],"ltp":1.5,"tv":3392.26,"id":31372}],"tv":4535.55}]}
{"op":"mcm","clk":"11797603300","pt":1723026395640,"mc":[{"id":"1.231431354","rc":[{"trd":[[3,5.15]],"ltp":3.0,"tv":1146.44,"id":5901},{"trd":[[1.5,15.87]],"batl":[[0,1.5,3600.02]],"ltp":1.5,"tv":3398.55,"id":31372}],"tv":4544.99}]}
{"op":"mcm","clk":"11797603498","pt":1723026398143,"mc":[{"id":"1.231431354","rc":[{"trd":[[3,8.3]],"ltp":3.0,"tv":1149.58,"id":5901},{"trd":[[1.5,22.16]],"batl":[[0,1.5,3593.73]],"ltp":1.5,"tv":3404.84,"id":31372}],"tv":4554.43}]}
{"op":"mcm","clk":"11797603701","pt":1723026400651,"mc":[{"id":"1.231431354","rc":[{"batb":[[0,1.44,400.75],[1,1.42,15.74],[2,1.41,30.57]],"ltp":1.5,"tv":3404.84,"id":31372}]}]}
{"op":"mcm","clk":"11797604277","pt":1723026407468,"mc":[{"id":"1.231431354","rc":[{"batb":[[0,1.45,1.57],[1,1.44,400.75],[2,1.42,15.74]],"ltp":1.5,"tv":3404.84,"id":31372}]}]}
{"op":"mcm","clk":"11797604538","pt":1723026410392,"mc":[{"id":"1.231431354","rc":[{"batb":[[0,3.05,5.63],[1,2.26,6.29],[2,2.2,6.31]],"ltp":3.0,"tv":1149.58,"id":5901}]}]}
{"op":"mcm","clk":"11797604596","pt":1723026410972,"mc":[{"id":"1.231431354","rc":[{"trd":[[1.44,334.72]],"batb":[[0,1.44,244.97],[1,1.42,15.74],[2,1.41,30.57]],"ltp":1.44,"tv":3716.4,"id":31372}],"tv":4865.99}]}
{"op":"mcm","clk":"11797605208","pt":1723026417888,"mc":[{"id":"1.231431354","rc":[{"trd":[[3.05,5.86]],"batb":[[0,2.26,6.29],[1,2.2,6.31],[2,2.16,12.59]],"ltp":3.05,"tv":1155.21,"id":5901},{"trd":[[1.49,11.81]],"batl":[[0,1.5,3589.95]],"ltp":1.49,"tv":3727.92,"id":31372}],"tv":4883.14}]}
{"op":"mcm","clk":"11797605808","pt":1723026425382,"mc":[{"id":"1.231431354","rc":[{"trd":[[1.5,85.11]],"batl":[[0,1.5,3558.47]],"ltp":1.5,"tv":3790.88,"id":31372}],"tv":4946.1}]}
{"op":"mcm","clk":"11797605904","pt":1723026426473,"mc":[{"id":"1.231431354","rc":[{"batl":[[0,3.55,2.53]],"ltp":3.05,"tv":1155.21,"id":5901},{"trd":[[1.5,195.27]],"batl":[[0,1.5,3503.38]],"ltp":1.5,"tv":3901.04,"id":31372}],"tv":5056.26}]}
{"op":"mcm","clk":"11797605934","pt":1723026426788,"mc":[{"id":"1.231431354","rc":[{"trd":[[1.5,226.75]],"batl":[[0,1.5,3487.64]],"ltp":1.5,"tv":3932.52,"id":31372}],"tv":5087.74}]}
{"op":"mcm","clk":"11797606085","pt":1723026428404,"mc":[{"id":"1.231431354","rc":[{"trd":[[1.5,289.7]],"batl":[[0,1.5,3456.16]],"ltp":1.5,"tv":3995.47,"id":31372}],"tv":5150.69}]}
{"op":"mcm","clk":"11797606241","pt":1723026430190,"mc":[{"id":"1.231431354","rc":[{"batl":[[0,3.55,2.25]],"ltp":3.05,"tv":1155.21,"id":5901}]}]}
{"op":"mcm","clk":"11797606648","pt":1723026435312,"mc":[{"id":"1.231431354","rc":[{"trd":[[1.5,299.13]],"batl":[[0,1.5,3451.45]],"ltp":1.5,"tv":4004.9,"id":31372}],"tv":5160.12}]}
{"op":"mcm","clk":"11797606830","pt":1723026437406,"mc":[{"id":"1.231431354","rc":[{"batb":[[0,1.42,15.74],[1,1.41,30.57],[2,1.35,6.72]],"ltp":1.5,"tv":4004.9,"id":31372}]}]}
{"op":"mcm","clk":"11797607076","pt":1723026440212,"mc":[{"id":"1.231431354","rc":[{"batb":[[0,1.45,1.8],[1,1.42,15.74],[2,1.41,30.57]],"ltp":1.5,"tv":4004.9,"id":31372}]}]}
{"op":"mcm","clk":"11797609546","pt":1723026472154,"mc":[{"id":"1.231431354","rc":[{"batb":[[0,2.64,7.64],[1,2.26,6.29],[2,2.2,6.31]],"ltp":3.05,"tv":1155.21,"id":5901},{"batb":[[0,1.46,13.82],[1,1.45,1.8],[2,1.42,15.74]],"ltp":1.5,"tv":4004.9,"id":31372}]}]}
{"op":"mcm","clk":"11797609613","pt":1723026472935,"mc":[{"id":"1.231431354","rc":[{"batb":[[0,2.26,6.29],[1,2.2,6.31],[2,2.16,12.59]],"ltp":3.05,"tv":1155.21,"id":5901},{"batb":[[0,1.45,1.8],[1,1.42,15.74],[2,1.41,30.57]],"ltp":1.5,"tv":4004.9,"id":31372}]}]}
{"op":"mcm","clk":"11797610111","pt":1723026479420,"mc":[{"id":"1.231431354","rc":[{"batb":[[0,2.6,7.75],[1,2.26,6.29],[2,2.2,6.31]],"ltp":3.05,"tv":1155.21,"id":5901},{"batb":[[0,1.47,13.71],[1,1.45,251.8],[2,1.42,15.74]],"ltp":1.5,"tv":4004.9,"id":31372}]}]}
{"op":"mcm","clk":"11797610158","pt":1723026480047,"mc":[{"id":"1.231431354","rc":[{"batb":[[0,2.26,6.29],[1,2.2,6.31],[2,2.16,12.59]],"ltp":3.05,"tv":1155.21,"id":5901},{"batb":[[0,1.45,251.8],[1,1.42,15.74],[2,1.41,30.57]],"ltp":1.5,"tv":4004.9,"id":31372}]}]}
{"op":"mcm","clk":"11797610752","pt":1723026486172,"mc":[{"id":"1.231431354","rc":[{"batb":[[0,2.6,7.75],[1,2.26,6.29],[2,2.2,6.31]],"ltp":3.05,"tv":1155.21,"id":5901}]}]}
{"op":"mcm","clk":"11797611426","pt":1723026494040,"mc":[{"id":"1.231431354","rc":[{"batb":[[0,1.46,18.04],[1,1.45,251.8],[2,1.42,15.74]],"ltp":1.5,"tv":4004.9,"id":31372}]}]}
{"op":"mcm","clk":"11797611514","pt":1723026495079,"mc":[{"id":"1.231431354","rc":[{"batb":[[0,2.26,6.29],[1,2.2,6.31],[2,2.16,12.59]],"ltp":3.05,"tv":1155.21,"id":5901}]}]}
{"op":"mcm","clk":"11797612296","pt":1723026504465,"mc":[{"id":"1.231431354","rc":[{"batb":[[1,1.45,250]],"ltp":1.5,"tv":4004.9,"id":31372}]}]}
{"op":"mcm","clk":"11797612835","pt":1723026510481,"mc":[{"id":"1.231431354","rc":[{"batb":[[1,1.42,15.74],[2,1.41,30.57]],"ltp":1.5,"tv":4004.9,"id":31372}]}]}
{"op":"mcm","clk":"11797612957","pt":1723026511985,"mc":[{"id":"1.231431354","rc":[{"trd":[[3,8.39]],"ltp":3.0,"tv":1155.31,"id":5901},{"trd":[[1.5,299.31]],"batl":[[0,1.5,3451.27]],"ltp":1.5,"tv":4005.08,"id":31372}],"tv":5160.39}]}
{"op":"mcm","clk":"11797613275","pt":1723026515581,"mc":[{"id":"1.231431354","rc":[{"batb":[[0,1.46,268.04]],"ltp":1.5,"tv":4005.08,"id":31372}]}]}
{"op":"mcm","clk":"11797613834","pt":1723026522209,"mc":[{"id":"1.231431354","rc":[{"trd":[[3,8.68]],"ltp":3.0,"tv":1155.59,"id":5901},{"trd":[[1.5,299.88]],"batl":[[0,1.5,3450.7]],"ltp":1.5,"tv":4005.65,"id":31372}],"tv":5161.24}]}
{"op":"mcm","clk":"11797614904","pt":1723026533990,"mc":[{"id":"1.231431354","rc":[{"batl":[[1,5.4,1.52],[2,8,1.19]],"ltp":3.0,"tv":1155.59,"id":5901}]}]}
{"op":"mcm","clk":"11797615310","pt":1723026538503,"mc":[{"id":"1.231431354","rc":[{"trd":[[1.5,300.08]],"batl":[[0,1.5,3450.6]],"ltp":1.5,"tv":4005.85,"id":31372}],"tv":5161.44}]}
{"op":"mcm","clk":"11797615434","pt":1723026539900,"mc":[{"id":"1.231431354","rc":[{"batb":[[0,1.46,18.04]],"ltp":1.5,"tv":4005.85,"id":31372}]}]}
{"op":"mcm","clk":"11797615878","pt":1723026544229,"mc":[{"id":"1.231431354","rc":[{"trd":[[1.5,300.45]],"batl":[[0,1.5,3450.42]],"ltp":1.5,"tv":4006.21,"id":31372}],"tv":5161.81}]}
{"op":"mcm","clk":"11797617276","pt":1723026558226,"mc":[{"id":"1.231431354","rc":[{"trd":[[3,8.78]],"ltp":3.0,"tv":1155.69,"id":5901},{"trd":[[1.5,300.65]],"batl":[[0,1.5,3450.22]],"ltp":1.5,"tv":4006.41,"id":31372}],"tv":5162.11}]}
{"op":"mcm","clk":"11797617415","pt":1723026559634,"mc":[{"id":"1.231431354","rc":[{"batl":[[0,1.5,3419.66]],"ltp":1.5,"tv":4006.41,"id":31372}]}]}
{"op":"mcm","clk":"11797617950","pt":1723026565397,"mc":[{"id":"1.231431354","rc":[{"batb":[[2,1.4,125]],"ltp":1.5,"tv":4006.41,"id":31372}]}]}
{"op":"mcm","clk":"11797618268","pt":1723026568864,"mc":[{"id":"1.231431354","rc":[{"batl":[[0,1.5,3420.23]],"ltp":1.5,"tv":4006.41,"id":31372}]}]}
{"op":"mcm","clk":"11797618760","pt":1723026574059,"mc":[{"id":"1.231431354","rc":[{"batl":[[0,1.5,3419.66]],"ltp":1.5,"tv":4006.41,"id":31372}]}]}
{"op":"mcm","clk":"11797620900","pt":1723026597285,"mc":[{"id":"1.231431354","rc":[{"batb":[[0,1.46,268.04]],"ltp":1.5,"tv":4006.41,"id":31372}]}]}
{"op":"mcm","clk":"11797622392","pt":1723026611013,"mc":[{"id":"1.231431354","rc":[{"batb":[[0,1.46,18.04]],"ltp":1.5,"tv":4006.41,"id":31372}]}]}
{"op":"mcm","clk":"11797622883","pt":1723026615597,"mc":[{"id":"1.231431354","rc":[{"batl":[[0,1.5,2969.66]],"ltp":1.5,"tv":4006.41,"id":31372}]}]}
{"op":"mcm","clk":"11797623365","pt":1723026620136,"mc":[{"id":"1.231431354","rc":[{"batb":[[0,1.46,2.42]],"ltp":1.5,"tv":4006.41,"id":31372}]}]}
{"op":"mcm","clk":"11797626696","pt":1723026651221,"mc":[{"id":"1.231431354","rc":[{"trd":[[3,9.68]],"ltp":3.0,"tv":1156.59,"id":5901},{"trd":[[1.5,302.45]],"batl":[[0,1.5,2967.86]],"ltp":1.5,"tv":4008.21,"id":31372}],"tv":5164.81}]}
{"op":"mcm","clk":"11797628104","pt":1723026664972,"mc":[{"id":"1.231431354","rc":[{"batb":[[0,1.46,4.14]],"ltp":1.5,"tv":4008.21,"id":31372}]}]}
{"op":"mcm","clk":"11797628479","pt":1723026668661,"mc":[{"id":"1.231431354","rc":[{"batl":[[0,1.5,2895.86]],"ltp":1.5,"tv":4008.21,"id":31372}]}]}
{"op":"mcm","clk":"11797630468","pt":1723026689393,"mc":[{"id":"1.231431354","rc":[{"batb":[[0,1.46,254.14],[1,1.42,6.29]],"ltp":1.5,"tv":4008.21,"id":31372}]}]}
{"op":"mcm","clk":"11797630783","pt":1723026692775,"mc":[{"id":"1.231431354","rc":[{"trd":[[3,9.78]],"ltp":3.0,"tv":1156.69,"id":5901},{"trd":[[1.5,302.65]],"batl":[[0,1.5,2895.66]],"ltp":1.5,"tv":4008.41,"id":31372}],"tv":5165.11}]}
{"op":"mcm","clk":"11797631322","pt":1723026698792,"mc":[{"id":"1.231431354","rc":[{"trd":[[1.46,327.3]],"batb":[[0,1.46,96.78]],"ltp":1.46,"tv":4323.13,"id":31372}],"tv":5479.82}]}
{"op":"mcm","clk":"11797632040","pt":1723026706179,"mc":[{"id":"1.231431354","rc":[{"trd":[[1.5,318.36]],"batl":[[0,1.5,2887.81]],"ltp":1.5,"tv":4338.84,"id":31372}],"tv":5495.54}]}
{"op":"mcm","clk":"11797632164","pt":1723026707483,"mc":[{"id":"1.231431354","rc":[{"trd":[[1.5,334.08]],"batl":[[0,1.5,2879.96]],"ltp":1.5,"tv":4354.56,"id":31372}],"tv":5511.26}]}
{"op":"mcm","clk":"11797632269","pt":1723026708515,"mc":[{"id":"1.231431354","rc":[{"trd":[[1.5,343.51]],"batl":[[0,1.5,2875.25]],"ltp":1.5,"tv":4363.99,"id":31372}],"tv":5520.69}]}
{"op":"mcm","clk":"11797632362","pt":1723026709411,"mc":[{"id":"1.231431354","rc":[{"trd":[[1.5,362.37]],"batl":[[0,1.5,2865.83]],"ltp":1.5,"tv":4382.85,"id":31372}],"tv":5539.55}]}
{"op":"mcm","clk":"11797632472","pt":1723026710504,"mc":[{"id":"1.231431354","rc":[{"trd":[[1.5,365.52]],"batb":[[0,1.46,98.5]],"batl":[[0,1.5,2864.26]],"ltp":1.5,"tv":4386.0,"id":31372}],"tv":5542.69}]}
{"op":"mcm","clk":"11797632573","pt":1723026711525,"mc":[{"id":"1.231431354","rc":[{"trd":[[1.5,374.95]],"batl":[[0,1.5,2859.55]],"ltp":1.5,"tv":4395.43,"id":31372}],"tv":5552.12}]}
{"op":"mcm","clk":"11797632658","pt":1723026712411,"mc":[{"id":"1.231431354","rc":[{"trd":[[1.5,390.67]],"batl":[[0,1.5,2851.7]],"ltp":1.5,"tv":4411.15,"id":31372}],"tv":5567.84}]}
{"op":"mcm","clk":"11797632725","pt":1723026713092,"mc":[{"id":"1.231431354","rc":[{"trd":[[1.5,396.95]],"batl":[[0,1.5,2848.56]],"ltp":1.5,"tv":4417.43,"id":31372}],"tv":5574.13}]}
{"op":"mcm","clk":"11797632878","pt":1723026714496,"mc":[{"id":"1.231431354","rc":[{"trd":[[1.5,412.67]],"batl":[[0,1.5,2840.71]],"ltp":1.5,"tv":4433.15,"id":31372}],"tv":5589.85}]}
{"op":"mcm","clk":"11797632927","pt":1723026715020,"mc":[{"id":"1.231431354","rc":[{"trd":[[1.5,425.24]],"batl":[[0,1.5,2834.43]],"ltp":1.5,"tv":4445.72,"id":31372}],"tv":5602.42}]}
{"op":"mcm","clk":"11797632981","pt":1723026715528,"mc":[{"id":"1.231431354","rc":[{"trd":[[1.5,428.39]],"batl":[[0,1.5,2832.86]],"ltp":1.5,"tv":4448.87,"id":31372}],"tv":5605.56}]}
{"op":"mcm","clk":"11797633171","pt":1723026717408,"mc":[{"id":"1.231431354","rc":[{"trd":[[1.5,440.96]],"batl":[[0,1.5,2826.58]],"ltp":1.5,"tv":4461.44,"id":31372}],"tv":5618.14}]}
{"op":"mcm","clk":"11797633228","pt":1723026718043,"mc":[{"id":"1.231431354","rc":[{"trd":[[1.5,450.39]],"batl":[[0,1.5,2821.87]],"ltp":1.5,"tv":4470.87,"id":31372}],"tv":5627.57}]}
{"op":"mcm","clk":"11797633335","pt":1723026719126,"mc":[{"id":"1.231431354","rc":[{"trd":[[1.5,456.68]],"batl":[[0,1.5,2818.73]],"ltp":1.5,"tv":4477.16,"id":31372}],"tv":5633.86}]}
{"op":"mcm","clk":"11797633468","pt":1723026720224,"mc":[{"id":"1.231431354","rc":[{"trd":[[1.5,475.54]],"batl":[[0,1.5,2809.31]],"ltp":1.5,"tv":4496.02,"id":31372}],"tv":5652.72}]}
{"op":"mcm","clk":"11797633554","pt":1723026721002,"mc":[{"id":"1.231431354","rc":[{"trd":[[1.5,481.83]],"batl":[[0,1.5,2806.17]],"ltp":1.5,"tv":4502.31,"id":31372}],"tv":5659.0}]}
{"op":"mcm","clk":"11797633712","pt":1723026722426,"mc":[{"id":"1.231431354","rc":[{"trd":[[1.5,484.97]],"batl":[[0,1.5,2804.6]],"ltp":1.5,"tv":4505.45,"id":31372}],"tv":5662.15}]}
{"op":"mcm","clk":"11797633811","pt":1723026723325,"mc":[{"id":"1.231431354","rc":[{"trd":[[1.5,491.26]],"batl":[[0,1.5,2801.46]],"ltp":1.5,"tv":4511.74,"id":31372}],"tv":5668.44}]}
{"op":"mcm","clk":"11797633837","pt":1723026723534,"mc":[{"id":"1.231431354","rc":[{"trd":[[1.5,497.55]],"batl":[[0,1.5,2798.32]],"ltp":1.5,"tv":4518.03,"id":31372}],"tv":5674.72}]}
{"op":"mcm","clk":"11797634296","pt":1723026727906,"mc":[{"id":"1.231431354","rc":[{"trd":[[1.5,1497.55]],"batl":[[0,1.5,2298.32]],"ltp":1.5,"tv":5518.03,"id":31372}],"tv":6674.72}]}
{"op":"mcm","clk":"11797634402","pt":1723026728996,"mc":[{"id":"1.231431354","rc":[{"trd":[[3,9.88]],"ltp":3.0,"tv":1156.79,"id":5901},{"trd":[[1.5,1497.75]],"batl":[[0,1.5,2298.12]],"ltp":1.5,"tv":5518.23,"id":31372}],"tv":6675.02}]}
{"op":"mcm","clk":"11797635101","pt":1723026735521,"mc":[{"id":"1.231431354","rc":[{"trd":[[1.5,1513.46]],"batl":[[0,1.5,2290.27]],"ltp":1.5,"tv":5533.94,"id":31372}],"tv":6690.74}]}
{"op":"mcm","clk":"11797635193","pt":1723026736330,"mc":[{"id":"1.231431354","rc":[{"trd":[[1.5,1526.04]],"batl":[[0,1.5,2283.99]],"ltp":1.5,"tv":5546.52,"id":31372}],"tv":6703.32}]}
{"op":"mcm","clk":"11797635654","pt":1723026740949,"mc":[{"id":"1.231431354","rc":[{"trd":[[1.5,1826.04]],"batl":[[0,1.5,2133.99]],"ltp":1.5,"tv":5846.52,"id":31372}],"tv":7003.32}]}
{"op":"mcm","clk":"11797636313","pt":1723026747436,"mc":[{"id":"1.231431354","rc":[{"trd":[[1.5,1844.9]],"batl":[[0,1.5,2124.57]],"ltp":1.5,"tv":5865.38,"id":31372}],"tv":7022.18}]}
{"op":"mcm","clk":"11797636426","pt":1723026748435,"mc":[{"id":"1.231431354","rc":[{"trd":[[1.5,1863.76]],"batl":[[0,1.5,2115.15]],"ltp":1.5,"tv":5884.24,"id":31372}],"tv":7041.04}]}
{"op":"mcm","clk":"11797636535","pt":1723026749525,"mc":[{"id":"1.231431354","rc":[{"trd":[[1.5,1885.77]],"batl":[[0,1.5,2104.16]],"ltp":1.5,"tv":5906.25,"id":31372}],"tv":7063.04}]}
{"op":"mcm","clk":"11797636577","pt":1723026750046,"mc":[{"id":"1.231431354","rc":[{"trd":[[1.5,1888.91]],"batl":[[0,1.5,2102.59]],"ltp":1.5,"tv":5909.39,"id":31372}],"tv":7066.19}]}
{"op":"mcm","clk":"11797636779","pt":1723026752139,"mc":[{"id":"1.231431354","rc":[{"trd":[[1.5,1892.05]],"batl":[[0,1.5,2101.02]],"ltp":1.5,"tv":5912.53,"id":31372}],"tv":7069.33}]}
{"op":"mcm","clk":"11797639971","pt":1723026782979,"mc":[{"id":"1.231431354","rc":[{"trd":[[1.5,1924.96]],"batl":[[0,1.5,2084.57]],"ltp":1.5,"tv":5945.44,"id":31372}],"tv":7102.23}]}
{"op":"mcm","clk":"11797640068","pt":1723026783966,"mc":[{"id":"1.231431354","rc":[{"trd":[[3,309.88]],"ltp":3.0,"tv":1456.79,"id":5901},{"trd":[[1.5,2524.96]],"batl":[[0,1.5,1484.57]],"ltp":1.5,"tv":6545.44,"id":31372}],"tv":8002.23}]}
{"op":"mcm","clk":"11797640872","pt":1723026791472,"mc":[{"id":"1.231431354","rc":[{"trd":[[1.4,285.7],[1.42,12.59],[1.46,524.29]],"batb":[[0,1.4,38.05],[1,1.35,149.58],[2,1.32,11.01]],"ltp":1.4,"tv":6928.92,"id":31372}],"tv":8385.71}]}
{"op":"mcm","clk":"11797641794","pt":1723026799999,"mc":[{"id":"1.231431354","rc":[{"batb":[[0,1.41,16.45],[1,1.4,38.05],[2,1.37,8.6]],"ltp":1.4,"tv":6928.92,"id":31372}]}]}
{"op":"mcm","clk":"11797642247","pt":1723026804214,"mc":[{"id":"1.231431354","rc":[{"batb":[[2,1.37,17.2]],"ltp":1.4,"tv":6928.92,"id":31372}]}]}
{"op":"mcm","clk":"11797642592","pt":1723026807099,"mc":[{"id":"1.231431354","rc":[{"batb":[[2,1.35,149.58]],"batl":[[0,1.49,6.29],[1,1.5,1484.57],[2,1.52,5.51]],"ltp":1.4,"tv":6928.92,"id":31372}]}]}
{"op":"mcm","clk":"11797643250","pt":1723026812830,"mc":[{"id":"1.231431354","rc":[{"trd":[[1.49,12.71]],"batl":[[0,1.49,5.85]],"ltp":1.49,"tv":6929.81,"id":31372}],"tv":8386.61}]}
{"op":"mcm","clk":"11797643967","pt":1723026819337,"mc":[{"id":"1.231431354","rc":[{"batb":[[0,1.41,18.17]],"ltp":1.49,"tv":6929.81,"id":31372}]}]}
{"op":"mcm","clk":"11797644013","pt":1723026819837,"mc":[{"id":"1.231431354","rc":[{"batl":[[0,1.49,87.55]],"ltp":1.49,"tv":6929.81,"id":31372}]}]}
{"op":"mcm","clk":"11797644578","pt":1723026824947,"mc":[{"id":"1.231431354","rc":[{"batb":[[0,1.42,433],[1,1.41,18.17],[2,1.4,38.05]],"ltp":1.49,"tv":6929.81,"id":31372}]}]}
{"op":"mcm","clk":"11797645213","pt":1723026831049,"mc":[{"id":"1.231431354","rc":[{"batb":[[1,1.41,1.72]],"ltp":1.49,"tv":6929.81,"id":31372}]}]}
{"op":"mcm","clk":"11797645713","pt":1723026836158,"mc":[{"id":"1.231431354","rc":[{"batb":[[0,1.44,16.45],[1,1.42,433],[2,1.41,1.72]],"ltp":1.49,"tv":6929.81,"id":31372}]}]}
{"op":"mcm","clk":"11797647525","pt":1723026852642,"mc":[{"id":"1.231431354","rc":[{"batb":[[0,2.7,7.47],[1,2.26,6.29],[2,2.2,6.31]],"ltp":3.0,"tv":1456.79,"id":5901}]}]}
{"op":"mcm","clk":"11797647649","pt":1723026854043,"mc":[{"id":"1.231431354","rc":[{"batb":[[2,1.4,38.05]],"ltp":1.49,"tv":6929.81,"id":31372}]}]}
{"op":"mcm","clk":"11797647922","pt":1723026856850,"mc":[{"id":"1.231431354","rc":[{"trd":[[1.49,12.91]],"batl":[[0,1.49,87.44]],"ltp":1.49,"tv":6930.02,"id":31372}],"tv":8386.81}]}
{"op":"mcm","clk":"11797648134","pt":1723026859147,"mc":[{"id":"1.231431354","rc":[{"batb":[[0,1.44,18.17]],"ltp":1.49,"tv":6930.02,"id":31372}]}]}
{"op":"mcm","clk":"11797648209","pt":1723026860088,"mc":[{"id":"1.231431354","rc":[{"batb":[[0,1.44,1.72]],"ltp":1.49,"tv":6930.02,"id":31372}]}]}
{"op":"mcm","clk":"11797648669","pt":1723026865180,"mc":[{"id":"1.231431354","rc":[{"batb":[[0,1.45,16.45]],"ltp":1.49,"tv":6930.02,"id":31372}]}]}
{"op":"mcm","clk":"11797648841","pt":1723026866996,"mc":[{"id":"1.231431354","rc":[{"batb":[[0,2.26,6.29],[1,2.2,6.31],[2,2.16,12.59]],"ltp":3.0,"tv":1456.79,"id":5901},{"batb":[[1,1.44,14],[2,1.42,433]],"ltp":1.49,"tv":6930.02,"id":31372}]}]}
{"op":"mcm","clk":"11797648938","pt":1723026868094,"mc":[{"id":"1.231431354","rc":[{"batb":[[1,1.42,433],[2,1.4,38.05]],"ltp":1.49,"tv":6930.02,"id":31372}]}]}
{"op":"mcm","clk":"11797649110","pt":1723026870008,"mc":[{"id":"1.231431354","rc":[{"batb":[[1,1.42,434.72]],"ltp":1.49,"tv":6930.02,"id":31372}]}]}
{"op":"mcm","clk":"11797649325","pt":1723026872298,"mc":[{"id":"1.231431354","rc":[{"batb":[[1,1.42,433]],"ltp":1.49,"tv":6930.02,"id":31372}]}]}
{"op":"mcm","clk":"11797650747","pt":1723026888281,"mc":[{"id":"1.231431354","rc":[{"batb":[[0,1.42,433],[1,1.4,38.05],[2,1.35,149.58]],"ltp":1.49,"tv":6930.02,"id":31372}]}]}
{"op":"mcm","clk":"11797651147","pt":1723026893378,"mc":[{"id":"1.231431354","rc":[{"batb":[[0,1.46,16.45],[1,1.42,433],[2,1.4,38.05]],"ltp":1.49,"tv":6930.02,"id":31372}]}]}
{"op":"mcm","clk":"11797651220","pt":1723026894312,"mc":[{"id":"1.231431354","rc":[{"batb":[[0,2.7,7.47],[1,2.26,6.29],[2,2.2,6.31]],"ltp":3.0,"tv":1456.79,"id":5901},{"batb":[[1,1.44,14],[2,1.42,433]],"ltp":1.49,"tv":6930.02,"id":31372}]}]}
{"op":"mcm","clk":"11797651321","pt":1723026895515,"mc":[{"id":"1.231431354","rc":[{"batb":[[0,2.26,6.29],[1,2.2,6.31],[2,2.16,12.59]],"ltp":3.0,"tv":1456.79,"id":5901},{"batb":[[1,1.42,433],[2,1.4,38.05]],"ltp":1.49,"tv":6930.02,"id":31372}]}]}
{"op":"mcm","clk":"11797651748","pt":1723026900197,"mc":[{"id":"1.231431354","rc":[{"batb":[[1,1.42,434.72]],"ltp":1.49,"tv":6930.02,"id":31372}]}]}
{"op":"mcm","clk":"11797652087","pt":1723026903519,"mc":[{"id":"1.231431354","rc":[{"batb":[[0,1.42,433],[1,1.4,38.05],[2,1.35,149.58]],"ltp":1.49,"tv":6930.02,"id":31372}]}]}
{"op":"mcm","clk":"11797652550","pt":1723026908224,"mc":[{"id":"1.231431354","rc":[{"batb":[[0,1.47,16.45],[1,1.42,433],[2,1.4,38.05]],"ltp":1.49,"tv":6930.02,"id":31372}]}]}
{"op":"mcm","clk":"11797652742","pt":1723026910090,"mc":[{"id":"1.231431354","rc":[{"batb":[[0,2.7,7.47],[1,2.26,6.29],[2,2.2,6.31]],"ltp":3.0,"tv":1456.79,"id":5901},{"batb":[[1,1.44,14],[2,1.42,433]],"ltp":1.49,"tv":6930.02,"id":31372}]}]}
