{"op":"mcm","clk":"11883320458","pt":1723738370555,"mc":[{"id":"1.231851789","marketDefinition":{"bspMarket":false,"turnInPlayEnabled":true,"persistenceEnabled":true,"marketBaseRate":5.0,"eventId":"33497939","eventTypeId":"4","numberOfWinners":1,"bettingType":"ODDS","marketType":"MATCH_ODDS","marketTime":"2024-08-22T10:00:00.000Z","suspendTime":"2024-08-22T10:00:00.000Z","bspReconciled":false,"complete":true,"inPlay":false,"crossMatching":false,"runnersVoidable":false,"numberOfActiveRunners":3,"betDelay":0,"status":"OPEN","runners":[{"status":"ACTIVE","sortPriority":1,"id":31374,"name":"Durham"},{"status":"ACTIVE","sortPriority":2,"id":2780,"name":"Nottinghamshire"},{"status":"ACTIVE","sortPriority":3,"id":60443,"name":"The Draw"}],"regulators":["MR_INT"],"countryCode":"GB","discountAllowed":false,"timezone":"GMT","openDate":"2024-08-22T10:00:00.000Z","version":6075698885,"name":"Match Odds","eventName":"Durham v Nottinghamshire"},"rc":[{"batb":[[0,1.03,200],[1,1.02,200],[2,1.01,220]],"ltp":0.0,"tv":0.0,"id":2780},{"batb":[[0,1.03,200],[1,1.02,200],[2,1.01,220]],"ltp":0.0,"tv":0.0,"id":60443},{"batb":[[0,1.03,200],[1,1.02,200],[2,1.01,220]],"ltp":0.0,"tv":0.0,"id":31374}]}]}
{"op":"mcm","clk":"11883320660","pt":1723738372306,"mc":[{"id":"1.231851789","marketDefinition":{"bspMarket":false,"turnInPlayEnabled":true,"persistenceEnabled":true,"marketBaseRate":5.0,"eventId":"33497939","eventTypeId":"4","numberOfWinners":1,"bettingType":"ODDS","marketType":"MATCH_ODDS","marketTime":"2024-08-22T10:00:00.000Z","suspendTime":"2024-08-22T10:00:00.000Z","bspReconciled":false,"complete":true,"inPlay":false,"crossMatching":false,"runnersVoidable":false,"numberOfActiveRunners":3,"betDelay":0,"status":"OPEN","runners":[{"status":"ACTIVE","sortPriority":1,"id":31374,"name":"Durham"},{"status":"ACTIVE","sortPriority":2,"id":2780,"name":"Nottinghamshire"},{"status":"ACTIVE","sortPriority":3,"id":60443,"name":"The Draw"}],"regulators":["MR_INT"],"countryCode":"GB","discountAllowed":true,"timezone":"GMT","openDate":"2024-08-22T10:00:00.000Z","version":6075698885,"name":"Match Odds","eventName":"Durham v Nottinghamshire"}}]}
{"op":"mcm","clk":"11883471335","pt":1723739494885,"mc":[{"id":"1.231851789","rc":[{"batb":[[2,1.01,478.85]],"ltp":0.0,"tv":0.0,"id":2780},{"batb":[[2,1.01,478.85]],"ltp":0.0,"tv":0.0,"id":60443},{"batb":[[2,1.01,478.85]],"ltp":0.0,"tv":0.0,"id":31374}]}]}
{"op":"mcm","clk":"11883827562","pt":1723741975056,"mc":[{"id":"1.231851789","rc":[{"batb":[[2,1.01,478.59]],"ltp":0.0,"tv":0.0,"id":2780},{"batb":[[2,1.01,478.59]],"ltp":0.0,"tv":0.0,"id":60443},{"batb":[[2,1.01,478.59]],"ltp":0.0,"tv":0.0,"id":31374}]}]}
{"op":"mcm","clk":"11884937190","pt":1723747375090,"mc":[{"id":"1.231851789","rc":[{"batb":[[2,1.01,478.24]],"ltp":0.0,"tv":0.0,"id":2780},{"batb":[[2,1.01,478.24]],"ltp":0.0,"tv":0.0,"id":60443},{"batb":[[2,1.01,478.24]],"ltp":0.0,"tv":0.0,"id":31374}]}]}
{"op":"mcm","clk":"11885936932","pt":1723752775078,"mc":[{"id":"1.231851789","rc":[{"batb":[[2,1.01,478.38]],"ltp":0.0,"tv":0.0,"id":2780},{"batb":[[2,1.01,478.38]],"ltp":0.0,"tv":0.0,"id":60443},{"batb":[[2,1.01,478.38]],"ltp":0.0,"tv":0.0,"id":31374}]}]}
{"op":"mcm","clk":"11886190501","pt":1723754649278,"mc":[{"id":"1.231851789","rc":[{"batl":[[0,95,5],[1,990,5]],"ltp":0.0,"tv":0.0,"id":2780},{"batl":[[0,95,5],[1,990,5]],"ltp":0.0,"tv":0.0,"id":60443},{"batl":[[0,95,5],[1,990,5]],"ltp":0.0,"tv":0.0,"id":31374}]}]}
{"op":"mcm","clk":"11886193364","pt":1723754671238,"mc":[{"id":"1.231851789","rc":[{"batb":[[0,1.04,125],[1,1.03,200],[2,1.02,200]],"ltp":0.0,"tv":0.0,"id":31374}]}]}
{"op":"mcm","clk":"11886193666","pt":1723754673416,"mc":[{"id":"1.231851789","rc":[{"batb":[[0,1.04,125],[1,1.03,200],[2,1.02,200]],"ltp":0.0,"tv":0.0,"id":2780}]}]}
{"op":"mcm","clk":"11886193807","pt":1723754674498,"mc":[{"id":"1.231851789","rc":[{"batb":[[0,1.04,125],[1,1.03,200],[2,1.02,200]],"ltp":0.0,"tv":0.0,"id":60443}]}]}
{"op":"mcm","clk":"11886194475","pt":1723754679962,"mc":[{"id":"1.231851789","marketDefinition":{"bspMarket":false,"turnInPlayEnabled":true,"persistenceEnabled":true,"marketBaseRate":5.0,"eventId":"33497939","eventTypeId":"4","numberOfWinners":1,"bettingType":"ODDS","marketType":"MATCH_ODDS","marketTime":"2024-08-22T10:00:00.000Z","suspendTime":"2024-08-22T10:00:00.000Z","bspReconciled":false,"complete":true,"inPlay":false,"crossMatching":true,"runnersVoidable":false,"numberOfActiveRunners":3,"betDelay":0,"status":"OPEN","runners":[{"status":"ACTIVE","sortPriority":1,"id":31374,"name":"Durham"},{"status":"ACTIVE","sortPriority":2,"id":2780,"name":"Nottinghamshire"},{"status":"ACTIVE","sortPriority":3,"id":60443,"name":"The Draw"}],"regulators":["MR_INT"],"countryCode":"GB","discountAllowed":true,"timezone":"GMT","openDate":"2024-08-22T10:00:00.000Z","version":6075698885,"name":"Match Odds","eventName":"Durham v Nottinghamshire"}}]}
{"op":"mcm","clk":"11887898753","pt":1723787790123,"mc":[{"id":"1.231851789","marketDefinition":{"bspMarket":false,"turnInPlayEnabled":true,"persistenceEnabled":true,"marketBaseRate":5.0,"eventId":"33497939","eventTypeId":"4","numberOfWinners":1,"bettingType":"ODDS","marketType":"MATCH_ODDS","marketTime":"2024-08-22T10:00:00.000Z","suspendTime":"2024-08-22T10:00:00.000Z","bspReconciled":false,"complete":true,"inPlay":false,"crossMatching":true,"runnersVoidable":false,"numberOfActiveRunners":3,"betDelay":0,"status":"OPEN","runners":[{"status":"ACTIVE","sortPriority":1,"id":31374,"name":"Durham"},{"status":"ACTIVE","sortPriority":2,"id":2780,"name":"Nottinghamshire"},{"status":"ACTIVE","sortPriority":3,"id":60443,"name":"The Draw"}],"regulators":["MR_INT"],"countryCode":"GB","discountAllowed":true,"timezone":"GMT","openDate":"2024-08-22T10:00:00.000Z","version":6076529057,"name":"Match Odds","eventName":"Durham v Nottinghamshire"}}]}
{"op":"mcm","clk":"11888562019","pt":1723800423808,"mc":[{"id":"1.231851789","rc":[{"batb":[[0,1.03,200],[1,1.02,200],[2,1.01,478.42]],"ltp":0.0,"tv":0.0,"id":2780},{"batb":[[0,1.03,200],[1,1.02,200],[2,1.01,478.42]],"ltp":0.0,"tv":0.0,"id":60443},{"batb":[[0,1.03,200],[1,1.02,200],[2,1.01,478.42]],"ltp":0.0,"tv":0.0,"id":31374}]}]}
{"op":"mcm","clk":"11888566498","pt":1723800475764,"mc":[{"id":"1.231851789","rc":[{"batb":[[0,1.04,500],[1,1.03,200],[2,1.02,200]],"ltp":0.0,"tv":0.0,"id":31374}]}]}
{"op":"mcm","clk":"11888566791","pt":1723800479078,"mc":[{"id":"1.231851789","rc":[{"batb":[[0,1.04,500],[1,1.03,200],[2,1.02,200]],"ltp":0.0,"tv":0.0,"id":2780}]}]}
{"op":"mcm","clk":"11888567060","pt":1723800482391,"mc":[{"id":"1.231851789","rc":[{"batb":[[0,1.04,500],[1,1.03,200],[2,1.02,200]],"ltp":0.0,"tv":0.0,"id":60443}]}]}
{"op":"mcm","clk":"11891357912","pt":1723827599096,"mc":[{"id":"1.231851789","rc":[{"batl":[[0,95,5.95]],"ltp":0.0,"tv":0.0,"id":60443}]}]}
{"op":"mcm","clk":"11891359805","pt":1723827610138,"mc":[{"id":"1.231851789","rc":[{"batl":[[0,95,5.95]],"ltp":0.0,"tv":0.0,"id":2780},{"batl":[[0,95,5.95]],"ltp":0.0,"tv":0.0,"id":60443}]}]}
{"op":"mcm","clk":"11891361406","pt":1723827621142,"mc":[{"id":"1.231851789","rc":[{"batl":[[0,95,5.95]],"ltp":0.0,"tv":0.0,"id":31374}]}]}
{"op":"mcm","clk":"11891376151","pt":1723827727709,"mc":[{"id":"1.231851789","rc":[{"batb":[[0,1.14,61.15],[1,1.04,500],[2,1.03,200]],"ltp":0.0,"tv":0.0,"id":2780},{"batb":[[0,1.14,61.15],[1,1.04,500],[2,1.03,200]],"ltp":0.0,"tv":0.0,"id":60443},{"batb":[[0,1.14,61.15],[1,1.04,500],[2,1.03,200]],"ltp":0.0,"tv":0.0,"id":31374}]}]}
{"op":"mcm","clk":"11891701140","pt":1723829532907,"mc":[{"id":"1.231851789","rc":[{"batb":[[0,1.04,500],[1,1.03,200],[2,1.02,200]],"ltp":0.0,"tv":0.0,"id":2780},{"batb":[[0,1.04,500],[1,1.03,200],[2,1.02,200]],"ltp":0.0,"tv":0.0,"id":60443},{"batb":[[0,1.04,500],[1,1.03,200],[2,1.02,200]],"ltp":0.0,"tv":0.0,"id":31374}]}]}
{"op":"mcm","clk":"11891723914","pt":1723829653080,"mc":[{"id":"1.231851789","rc":[{"batb":[[0,1.14,61.15],[1,1.04,500],[2,1.03,200]],"ltp":0.0,"tv":0.0,"id":2780},{"batb":[[0,1.14,61.15],[1,1.04,500],[2,1.03,200]],"ltp":0.0,"tv":0.0,"id":60443},{"batb":[[0,1.14,61.15],[1,1.04,500],[2,1.03,200]],"ltp":0.0,"tv":0.0,"id":31374}]}]}
{"op":"mcm","clk":"11891922205","pt":1723830726959,"mc":[{"id":"1.231851789","rc":[{"batb":[[1,1.03,200],[2,1.02,200]],"ltp":0.0,"tv":0.0,"id":60443}]}]}
{"op":"mcm","clk":"11891922603","pt":1723830729168,"mc":[{"id":"1.231851789","rc":[{"batb":[[1,1.03,200],[2,1.02,200]],"ltp":0.0,"tv":0.0,"id":2780},{"batb":[[1,1.03,200],[2,1.02,200]],"ltp":0.0,"tv":0.0,"id":31374}]}]}
{"op":"mcm","clk":"11891923006","pt":1723830731480,"mc":[{"id":"1.231851789","rc":[{"batb":[[0,1.15,133.33],[1,1.14,61.15],[2,1.03,200]],"ltp":0.0,"tv":0.0,"id":31374}]}]}
{"op":"mcm","clk":"11891923219","pt":1723830732817,"mc":[{"id":"1.231851789","rc":[{"batb":[[0,1.15,133.33],[1,1.14,61.15],[2,1.03,200]],"ltp":0.0,"tv":0.0,"id":2780}]}]}
{"op":"mcm","clk":"11891924007","pt":1723830738299,"mc":[{"id":"1.231851789","rc":[{"batb":[[0,1.15,133.33],[1,1.14,61.15],[2,1.03,200]],"ltp":0.0,"tv":0.0,"id":60443}]}]}
{"op":"mcm","clk":"11892046024","pt":1723831453291,"mc":[{"id":"1.231851789","rc":[{"batb":[[1,1.03,200],[2,1.02,200]],"ltp":0.0,"tv":0.0,"id":2780},{"batb":[[1,1.14,61.16]],"ltp":0.0,"tv":0.0,"id":60443},{"batb":[[1,1.14,61.16]],"ltp":0.0,"tv":0.0,"id":31374}]}]}
{"op":"mcm","clk":"11892046121","pt":1723831453702,"mc":[{"id":"1.231851789","rc":[{"batb":[[1,1.03,200],[2,1.02,200]],"ltp":0.0,"tv":0.0,"id":60443},{"batb":[[1,1.03,200],[2,1.02,200]],"ltp":0.0,"tv":0.0,"id":31374}]}]}
{"op":"mcm","clk":"11892068530","pt":1723831561603,"mc":[{"id":"1.231851789","rc":[{"batb":[[0,1.16,53.51],[1,1.15,133.33],[2,1.03,200]],"ltp":0.0,"tv":0.0,"id":2780},{"batb":[[0,1.16,53.51],[1,1.15,133.33],[2,1.03,200]],"ltp":0.0,"tv":0.0,"id":60443},{"batb":[[0,1.16,53.51],[1,1.15,133.33],[2,1.03,200]],"ltp":0.0,"tv":0.0,"id":31374}]}]}
{"op":"mcm","clk":"11892471502","pt":1723833361947,"mc":[{"id":"1.231851789","rc":[{"batb":[[0,1.15,133.33],[1,1.03,200],[2,1.02,200]],"ltp":0.0,"tv":0.0,"id":2780},{"batb":[[0,1.15,133.33],[1,1.03,200],[2,1.02,200]],"ltp":0.0,"tv":0.0,"id":60443},{"batb":[[0,1.15,133.33],[1,1.03,200],[2,1.02,200]],"ltp":0.0,"tv":0.0,"id":31374}]}]}
{"op":"mcm","clk":"11892484331","pt":1723833418614,"mc":[{"id":"1.231851789","rc":[{"batb":[[0,1.16,53.51],[1,1.15,133.33],[2,1.03,200]],"ltp":0.0,"tv":0.0,"id":2780},{"batb":[[0,1.16,53.51],[1,1.15,133.33],[2,1.03,200]],"ltp":0.0,"tv":0.0,"id":60443},{"batb":[[0,1.16,53.51],[1,1.15,133.33],[2,1.03,200]],"ltp":0.0,"tv":0.0,"id":31374}]}]}
{"op":"mcm","clk":"11892844170","pt":1723835219172,"mc":[{"id":"1.231851789","rc":[{"batb":[[0,1.16,53.5]],"ltp":0.0,"tv":0.0,"id":2780},{"batb":[[0,1.15,133.33],[1,1.03,200],[2,1.02,200]],"ltp":0.0,"tv":0.0,"id":60443},{"batb":[[0,1.15,133.33],[1,1.03,200],[2,1.02,200]],"ltp":0.0,"tv":0.0,"id":31374}]}]}
{"op":"mcm","clk":"11892844215","pt":1723835219452,"mc":[{"id":"1.231851789","rc":[{"batb":[[0,1.15,133.33],[1,1.03,200],[2,1.02,200]],"ltp":0.0,"tv":0.0,"id":2780}]}]}
{"op":"mcm","clk":"11892850567","pt":1723835253888,"mc":[{"id":"1.231851789","rc":[{"batb":[[0,1.16,53.5],[1,1.15,133.33],[2,1.03,200]],"ltp":0.0,"tv":0.0,"id":2780},{"batb":[[0,1.16,53.5],[1,1.15,133.33],[2,1.03,200]],"ltp":0.0,"tv":0.0,"id":60443},{"batb":[[0,1.16,53.5],[1,1.15,133.33],[2,1.03,200]],"ltp":0.0,"tv":0.0,"id":31374}]}]}
{"op":"mcm","clk":"11893154190","pt":1723837054155,"mc":[{"id":"1.231851789","rc":[{"batb":[[0,1.15,133.33],[1,1.03,200],[2,1.02,200]],"ltp":0.0,"tv":0.0,"id":60443}]}]}
{"op":"mcm","clk":"11893154261","pt":1723837054623,"mc":[{"id":"1.231851789","rc":[{"batb":[[0,1.15,133.33],[1,1.03,200],[2,1.02,200]],"ltp":0.0,"tv":0.0,"id":2780},{"batb":[[0,1.15,133.33],[1,1.03,200],[2,1.02,200]],"ltp":0.0,"tv":0.0,"id":31374}]}]}
{"op":"mcm","clk":"11893163302","pt":1723837118817,"mc":[{"id":"1.231851789","rc":[{"batb":[[0,1.16,53.5],[1,1.15,133.33],[2,1.03,200]],"ltp":0.0,"tv":0.0,"id":2780},{"batb":[[0,1.16,53.5],[1,1.15,133.33],[2,1.03,200]],"ltp":0.0,"tv":0.0,"id":60443},{"batb":[[0,1.16,53.5],[1,1.15,133.33],[2,1.03,200]],"ltp":0.0,"tv":0.0,"id":31374}]}]}
{"op":"mcm","clk":"11893392686","pt":1723838919247,"mc":[{"id":"1.231851789","rc":[{"batb":[[0,1.16,53.51]],"ltp":0.0,"tv":0.0,"id":2780},{"batb":[[0,1.15,133.33],[1,1.03,200],[2,1.02,200]],"ltp":0.0,"tv":0.0,"id":60443},{"batb":[[0,1.15,133.33],[1,1.03,200],[2,1.02,200]],"ltp":0.0,"tv":0.0,"id":31374}]}]}
{"op":"mcm","clk":"11893392705","pt":1723838919451,"mc":[{"id":"1.231851789","rc":[{"batb":[[0,1.15,133.33],[1,1.03,200],[2,1.02,200]],"ltp":0.0,"tv":0.0,"id":2780}]}]}
{"op":"mcm","clk":"11893392838","pt":1723838920607,"mc":[{"id":"1.231851789","rc":[{"batb":[[0,1.16,53.51],[1,1.15,133.33],[2,1.03,200]],"ltp":0.0,"tv":0.0,"id":2780},{"batb":[[0,1.16,53.51],[1,1.15,133.33],[2,1.03,200]],"ltp":0.0,"tv":0.0,"id":60443},{"batb":[[0,1.16,53.51],[1,1.15,133.33],[2,1.03,200]],"ltp":0.0,"tv":0.0,"id":31374}]}]}
{"op":"mcm","clk":"11893576775","pt":1723840721278,"mc":[{"id":"1.231851789","rc":[{"batb":[[0,1.15,133.33],[1,1.03,200],[2,1.02,200]],"ltp":0.0,"tv":0.0,"id":2780},{"batb":[[0,1.15,133.33],[1,1.03,200],[2,1.02,200]],"ltp":0.0,"tv":0.0,"id":60443},{"batb":[[0,1.15,133.33],[1,1.03,200],[2,1.02,200]],"ltp":0.0,"tv":0.0,"id":31374}]}]}
{"op":"mcm","clk":"11893590889","pt":1723840919082,"mc":[{"id":"1.231851789","rc":[{"batb":[[0,1.16,53.51],[1,1.15,133.33],[2,1.03,200]],"ltp":0.0,"tv":0.0,"id":2780},{"batb":[[0,1.16,53.51],[1,1.15,133.33],[2,1.03,200]],"ltp":0.0,"tv":0.0,"id":60443},{"batb":[[0,1.16,53.51],[1,1.15,133.33],[2,1.03,200]],"ltp":0.0,"tv":0.0,"id":31374}]}]}
{"op":"mcm","clk":"11893691113","pt":1723842719275,"mc":[{"id":"1.231851789","rc":[{"batb":[[0,1.15,133.33],[1,1.03,200],[2,1.02,200]],"ltp":0.0,"tv":0.0,"id":2780},{"batb":[[0,1.16,53.53]],"ltp":0.0,"tv":0.0,"id":60443},{"batb":[[0,1.16,53.53]],"ltp":0.0,"tv":0.0,"id":31374}]}]}
{"op":"mcm","clk":"11893691129","pt":1723842719634,"mc":[{"id":"1.231851789","rc":[{"batb":[[0,1.15,133.33],[1,1.03,200],[2,1.02,200]],"ltp":0.0,"tv":0.0,"id":60443},{"batb":[[0,1.15,133.33],[1,1.03,200],[2,1.02,200]],"ltp":0.0,"tv":0.0,"id":31374}]}]}
{"op":"mcm","clk":"11893699109","pt":1723842869997,"mc":[{"id":"1.231851789","rc":[{"batb":[[0,1.16,53.53],[1,1.15,133.33],[2,1.03,200]],"ltp":0.0,"tv":0.0,"id":2780},{"batb":[[0,1.16,53.53],[1,1.15,133.33],[2,1.03,200]],"ltp":0.0,"tv":0.0,"id":60443},{"batb":[[0,1.16,53.53],[1,1.15,133.33],[2,1.03,200]],"ltp":0.0,"tv":0.0,"id":31374}]}]}
{"op":"mcm","clk":"11893792099","pt":1723844670153,"mc":[{"id":"1.231851789","rc":[{"batb":[[0,1.15,133.33],[1,1.03,200],[2,1.02,200]],"ltp":0.0,"tv":0.0,"id":2780}]}]}
{"op":"mcm","clk":"11893792119","pt":1723844670608,"mc":[{"id":"1.231851789","rc":[{"batb":[[0,1.15,133.33],[1,1.03,200],[2,1.02,200]],"ltp":0.0,"tv":0.0,"id":60443},{"batb":[[0,1.15,133.33],[1,1.03,200],[2,1.02,200]],"ltp":0.0,"tv":0.0,"id":31374}]}]}
{"op":"mcm","clk":"11893797468","pt":1723844794253,"mc":[{"id":"1.231851789","rc":[{"batb":[[0,1.16,53.53],[1,1.15,133.33],[2,1.03,200]],"ltp":0.0,"tv":0.0,"id":2780},{"batb":[[0,1.16,53.53],[1,1.15,133.33],[2,1.03,200]],"ltp":0.0,"tv":0.0,"id":60443},{"batb":[[0,1.16,53.53],[1,1.15,133.33],[2,1.03,200]],"ltp":0.0,"tv":0.0,"id":31374}]}]}
{"op":"mcm","clk":"11893878565","pt":1723846594937,"mc":[{"id":"1.231851789","rc":[{"batb":[[0,1.15,133.33],[1,1.03,200],[2,1.02,200]],"ltp":0.0,"tv":0.0,"id":2780},{"batb":[[0,1.15,133.33],[1,1.03,200],[2,1.02,200]],"ltp":0.0,"tv":0.0,"id":60443},{"batb":[[0,1.15,133.33],[1,1.03,200],[2,1.02,200]],"ltp":0.0,"tv":0.0,"id":31374}]}]}
{"op":"mcm","clk":"11893883356","pt":1723846702616,"mc":[{"id":"1.231851789","rc":[{"batb":[[0,1.16,53.5],[1,1.15,133.33],[2,1.03,200]],"ltp":0.0,"tv":0.0,"id":2780},{"batb":[[0,1.16,53.5],[1,1.15,133.33],[2,1.03,200]],"ltp":0.0,"tv":0.0,"id":60443},{"batb":[[0,1.16,53.5],[1,1.15,133.33],[2,1.03,200]],"ltp":0.0,"tv":0.0,"id":31374}]}]}
{"op":"mcm","clk":"11893952642","pt":1723848503070,"mc":[{"id":"1.231851789","rc":[{"batb":[[0,1.15,133.33],[1,1.03,200],[2,1.02,200]],"ltp":0.0,"tv":0.0,"id":2780},{"batb":[[0,1.15,133.33],[1,1.03,200],[2,1.02,200]],"ltp":0.0,"tv":0.0,"id":60443},{"batb":[[0,1.15,133.33],[1,1.03,200],[2,1.02,200]],"ltp":0.0,"tv":0.0,"id":31374}]}]}
{"op":"mcm","clk":"11893956859","pt":1723848606838,"mc":[{"id":"1.231851789","rc":[{"batb":[[0,1.16,53.5],[1,1.15,133.33],[2,1.03,200]],"ltp":0.0,"tv":0.0,"id":2780},{"batb":[[0,1.16,53.5],[1,1.15,133.33],[2,1.03,200]],"ltp":0.0,"tv":0.0,"id":60443},{"batb":[[0,1.16,53.5],[1,1.15,133.33],[2,1.03,200]],"ltp":0.0,"tv":0.0,"id":31374}]}]}
{"op":"mcm","clk":"11894057014","pt":1723850407289,"mc":[{"id":"1.231851789","rc":[{"batb":[[0,1.15,133.33],[1,1.03,200],[2,1.02,200]],"ltp":0.0,"tv":0.0,"id":2780},{"batb":[[0,1.15,133.33],[1,1.03,200],[2,1.02,200]],"ltp":0.0,"tv":0.0,"id":60443}]}]}
{"op":"mcm","clk":"11894057020","pt":1723850407496,"mc":[{"id":"1.231851789","rc":[{"batb":[[0,1.15,133.33],[1,1.03,200],[2,1.02,200]],"ltp":0.0,"tv":0.0,"id":31374}]}]}
{"op":"mcm","clk":"11894061560","pt":1723850499384,"mc":[{"id":"1.231851789","rc":[{"batb":[[0,1.16,53.5],[1,1.15,133.33],[2,1.03,200]],"ltp":0.0,"tv":0.0,"id":2780},{"batb":[[0,1.16,53.5],[1,1.15,133.33],[2,1.03,200]],"ltp":0.0,"tv":0.0,"id":60443},{"batb":[[0,1.16,53.5],[1,1.15,133.33],[2,1.03,200]],"ltp":0.0,"tv":0.0,"id":31374}]}]}
{"op":"mcm","clk":"11894168257","pt":1723852300059,"mc":[{"id":"1.231851789","rc":[{"batb":[[0,1.15,133.33],[1,1.03,200],[2,1.02,200]],"ltp":0.0,"tv":0.0,"id":2780},{"batb":[[0,1.15,133.33],[1,1.03,200],[2,1.02,200]],"ltp":0.0,"tv":0.0,"id":60443},{"batb":[[0,1.15,133.33],[1,1.03,200],[2,1.02,200]],"ltp":0.0,"tv":0.0,"id":31374}]}]}
{"op":"mcm","clk":"11894172859","pt":1723852384568,"mc":[{"id":"1.231851789","rc":[{"batb":[[0,1.16,53.5],[1,1.15,133.33],[2,1.03,200]],"ltp":0.0,"tv":0.0,"id":2780},{"batb":[[0,1.16,53.5],[1,1.15,133.33],[2,1.03,200]],"ltp":0.0,"tv":0.0,"id":60443},{"batb":[[0,1.16,53.5],[1,1.15,133.33],[2,1.03,200]],"ltp":0.0,"tv":0.0,"id":31374}]}]}
{"op":"mcm","clk":"11894283223","pt":1723854184994,"mc":[{"id":"1.231851789","rc":[{"batb":[[0,1.15,133.33],[1,1.03,200],[2,1.02,200]],"ltp":0.0,"tv":0.0,"id":2780},{"batb":[[0,1.15,133.33],[1,1.03,200],[2,1.02,200]],"ltp":0.0,"tv":0.0,"id":60443},{"batb":[[0,1.15,133.33],[1,1.03,200],[2,1.02,200]],"ltp":0.0,"tv":0.0,"id":31374}]}]}
{"op":"mcm","clk":"11894287980","pt":1723854258262,"mc":[{"id":"1.231851789","rc":[{"batb":[[0,1.16,53.5],[1,1.15,133.33],[2,1.03,200]],"ltp":0.0,"tv":0.0,"id":2780},{"batb":[[0,1.16,53.5],[1,1.15,133.33],[2,1.03,200]],"ltp":0.0,"tv":0.0,"id":60443},{"batb":[[0,1.16,53.5],[1,1.15,133.33],[2,1.03,200]],"ltp":0.0,"tv":0.0,"id":31374}]}]}
{"op":"mcm","clk":"11894428688","pt":1723856058775,"mc":[{"id":"1.231851789","rc":[{"batb":[[0,1.15,133.33],[1,1.03,200],[2,1.02,200]],"ltp":0.0,"tv":0.0,"id":2780},{"batb":[[0,1.15,133.33],[1,1.03,200],[2,1.02,200]],"ltp":0.0,"tv":0.0,"id":60443},{"batb":[[0,1.15,133.33],[1,1.03,200],[2,1.02,200]],"ltp":0.0,"tv":0.0,"id":31374}]}]}
{"op":"mcm","clk":"11894433041","pt":1723856126732,"mc":[{"id":"1.231851789","rc":[{"batb":[[0,1.16,53.5],[1,1.15,133.33],[2,1.03,200]],"ltp":0.0,"tv":0.0,"id":2780},{"batb":[[0,1.16,53.5],[1,1.15,133.33],[2,1.03,200]],"ltp":0.0,"tv":0.0,"id":60443},{"batb":[[0,1.16,53.5],[1,1.15,133.33],[2,1.03,200]],"ltp":0.0,"tv":0.0,"id":31374}]}]}
{"op":"mcm","clk":"11894553882","pt":1723857927154,"mc":[{"id":"1.231851789","rc":[{"batb":[[0,1.15,133.33],[1,1.03,200],[2,1.02,200]],"ltp":0.0,"tv":0.0,"id":60443},{"batb":[[0,1.15,133.33],[1,1.03,200],[2,1.02,200]],"ltp":0.0,"tv":0.0,"id":31374}]}]}
{"op":"mcm","clk":"11894553897","pt":1723857927360,"mc":[{"id":"1.231851789","rc":[{"batb":[[0,1.15,133.33],[1,1.03,200],[2,1.02,200]],"ltp":0.0,"tv":0.0,"id":2780}]}]}
{"op":"mcm","clk":"11894557682","pt":1723857987706,"mc":[{"id":"1.231851789","rc":[{"batb":[[0,1.16,53.5],[1,1.15,133.33],[2,1.03,200]],"ltp":0.0,"tv":0.0,"id":2780},{"batb":[[0,1.16,53.5],[1,1.15,133.33],[2,1.03,200]],"ltp":0.0,"tv":0.0,"id":60443},{"batb":[[0,1.16,53.5],[1,1.15,133.33],[2,1.03,200]],"ltp":0.0,"tv":0.0,"id":31374}]}]}
{"op":"mcm","clk":"11894662700","pt":1723859788156,"mc":[{"id":"1.231851789","rc":[{"batb":[[0,1.15,133.33],[1,1.03,200],[2,1.02,200]],"ltp":0.0,"tv":0.0,"id":60443},{"batb":[[0,1.15,133.33],[1,1.03,200],[2,1.02,200]],"ltp":0.0,"tv":0.0,"id":31374}]}]}
{"op":"mcm","clk":"11894662709","pt":1723859788360,"mc":[{"id":"1.231851789","rc":[{"batb":[[0,1.15,133.33],[1,1.03,200],[2,1.02,200]],"ltp":0.0,"tv":0.0,"id":2780}]}]}
{"op":"mcm","clk":"11894664725","pt":1723859839384,"mc":[{"id":"1.231851789","rc":[{"batb":[[0,1.16,53.5],[1,1.15,133.33],[2,1.03,200]],"ltp":0.0,"tv":0.0,"id":2780},{"batb":[[0,1.16,53.5],[1,1.15,133.33],[2,1.03,200]],"ltp":0.0,"tv":0.0,"id":60443},{"batb":[[0,1.16,53.5],[1,1.15,133.33],[2,1.03,200]],"ltp":0.0,"tv":0.0,"id":31374}]}]}
{"op":"mcm","clk":"11894776938","pt":1723861639898,"mc":[{"id":"1.231851789","rc":[{"batb":[[0,1.15,133.33],[1,1.03,200],[2,1.02,200]],"ltp":0.0,"tv":0.0,"id":2780},{"batb":[[0,1.15,133.33],[1,1.03,200],[2,1.02,200]],"ltp":0.0,"tv":0.0,"id":60443},{"batb":[[0,1.15,133.33],[1,1.03,200],[2,1.02,200]],"ltp":0.0,"tv":0.0,"id":31374}]}]}
{"op":"mcm","clk":"11894779004","pt":1723861676520,"mc":[{"id":"1.231851789","rc":[{"batb":[[0,1.16,53.5],[1,1.15,133.33],[2,1.03,200]],"ltp":0.0,"tv":0.0,"id":2780},{"batb":[[0,1.16,53.5],[1,1.15,133.33],[2,1.03,200]],"ltp":0.0,"tv":0.0,"id":60443},{"batb":[[0,1.16,53.5],[1,1.15,133.33],[2,1.03,200]],"ltp":0.0,"tv":0.0,"id":31374}]}]}
{"op":"mcm","clk":"11894865861","pt":1723863477033,"mc":[{"id":"1.231851789","rc":[{"batb":[[0,1.15,133.33],[1,1.03,200],[2,1.02,200]],"ltp":0.0,"tv":0.0,"id":2780},{"batb":[[0,1.15,133.33],[1,1.03,200],[2,1.02,200]],"ltp":0.0,"tv":0.0,"id":60443},{"batb":[[0,1.15,133.33],[1,1.03,200],[2,1.02,200]],"ltp":0.0,"tv":0.0,"id":31374}]}]}
{"op":"mcm","clk":"11894866594","pt":1723863497247,"mc":[{"id":"1.231851789","rc":[{"batb":[[0,1.16,53.5],[1,1.15,133.33],[2,1.03,200]],"ltp":0.0,"tv":0.0,"id":2780},{"batb":[[0,1.16,53.5],[1,1.15,133.33],[2,1.03,200]],"ltp":0.0,"tv":0.0,"id":60443},{"batb":[[0,1.16,53.5],[1,1.15,133.33],[2,1.03,200]],"ltp":0.0,"tv":0.0,"id":31374}]}]}
{"op":"mcm","clk":"11894935652","pt":1723865297882,"mc":[{"id":"1.231851789","rc":[{"batb":[[0,1.15,133.33],[1,1.03,200],[2,1.02,200]],"ltp":0.0,"tv":0.0,"id":2780},{"batb":[[0,1.15,133.33],[1,1.03,200],[2,1.02,200]],"ltp":0.0,"tv":0.0,"id":60443},{"batb":[[0,1.15,133.33],[1,1.03,200],[2,1.02,200]],"ltp":0.0,"tv":0.0,"id":31374}]}]}
{"op":"mcm","clk":"11894935752","pt":1723865300281,"mc":[{"id":"1.231851789","rc":[{"batb":[[0,1.16,53.5],[1,1.15,133.33],[2,1.03,200]],"ltp":0.0,"tv":0.0,"id":2780},{"batb":[[0,1.16,53.5],[1,1.15,133.33],[2,1.03,200]],"ltp":0.0,"tv":0.0,"id":60443},{"batb":[[0,1.16,53.5],[1,1.15,133.33],[2,1.03,200]],"ltp":0.0,"tv":0.0,"id":31374}]}]}
{"op":"mcm","clk":"11895012122","pt":1723867100898,"mc":[{"id":"1.231851789","rc":[{"batb":[[0,1.15,133.33],[1,1.03,200],[2,1.02,200]],"ltp":0.0,"tv":0.0,"id":2780},{"batb":[[0,1.15,133.33],[1,1.03,200],[2,1.02,200]],"ltp":0.0,"tv":0.0,"id":60443},{"batb":[[0,1.15,133.33],[1,1.03,200],[2,1.02,200]],"ltp":0.0,"tv":0.0,"id":31374}]}]}
{"op":"mcm","clk":"11895027990","pt":1723867318055,"mc":[{"id":"1.231851789","rc":[{"batb":[[0,1.16,53.5],[1,1.15,133.33],[2,1.03,200]],"ltp":0.0,"tv":0.0,"id":2780},{"batb":[[0,1.16,53.5],[1,1.15,133.33],[2,1.03,200]],"ltp":0.0,"tv":0.0,"id":60443},{"batb":[[0,1.16,53.5],[1,1.15,133.33],[2,1.03,200]],"ltp":0.0,"tv":0.0,"id":31374}]}]}
{"op":"mcm","clk":"11895103792","pt":1723869118235,"mc":[{"id":"1.231851789","rc":[{"batb":[[0,1.15,133.33],[1,1.03,200],[2,1.02,200]],"ltp":0.0,"tv":0.0,"id":2780}]}]}
{"op":"mcm","clk":"11895103807","pt":1723869118641,"mc":[{"id":"1.231851789","rc":[{"batb":[[0,1.15,133.33],[1,1.03,200],[2,1.02,200]],"ltp":0.0,"tv":0.0,"id":60443},{"batb":[[0,1.15,133.33],[1,1.03,200],[2,1.02,200]],"ltp":0.0,"tv":0.0,"id":31374}]}]}
{"op":"mcm","clk":"11895113794","pt":1723869321227,"mc":[{"id":"1.231851789","rc":[{"batb":[[0,1.16,53.5],[1,1.15,133.33],[2,1.03,200]],"ltp":0.0,"tv":0.0,"id":2780},{"batb":[[0,1.16,53.5],[1,1.15,133.33],[2,1.03,200]],"ltp":0.0,"tv":0.0,"id":60443},{"batb":[[0,1.16,53.5],[1,1.15,133.33],[2,1.03,200]],"ltp":0.0,"tv":0.0,"id":31374}]}]}
{"op":"mcm","clk":"11895175251","pt":1723871121754,"mc":[{"id":"1.231851789","rc":[{"batb":[[0,1.15,133.33],[1,1.03,200],[2,1.02,200]],"ltp":0.0,"tv":0.0,"id":2780},{"batb":[[0,1.15,133.33],[1,1.03,200],[2,1.02,200]],"ltp":0.0,"tv":0.0,"id":60443},{"batb":[[0,1.15,133.33],[1,1.03,200],[2,1.02,200]],"ltp":0.0,"tv":0.0,"id":31374}]}]}
{"op":"mcm","clk":"11895181714","pt":1723871319081,"mc":[{"id":"1.231851789","rc":[{"batb":[[0,1.16,53.5],[1,1.15,133.33],[2,1.03,200]],"ltp":0.0,"tv":0.0,"id":2780},{"batb":[[0,1.16,53.5],[1,1.15,133.33],[2,1.03,200]],"ltp":0.0,"tv":0.0,"id":60443},{"batb":[[0,1.16,53.5],[1,1.15,133.33],[2,1.03,200]],"ltp":0.0,"tv":0.0,"id":31374}]}]}
{"op":"mcm","clk":"11895256825","pt":1723873119778,"mc":[{"id":"1.231851789","rc":[{"batb":[[0,1.15,133.33],[1,1.03,200],[2,1.02,200]],"ltp":0.0,"tv":0.0,"id":2780},{"batb":[[0,1.15,133.33],[1,1.03,200],[2,1.02,200]],"ltp":0.0,"tv":0.0,"id":60443},{"batb":[[0,1.15,133.33],[1,1.03,200],[2,1.02,200]],"ltp":0.0,"tv":0.0,"id":31374}]}]}
{"op":"mcm","clk":"11895261768","pt":1723873304156,"mc":[{"id":"1.231851789","rc":[{"batb":[[0,1.16,53.5],[1,1.15,133.33],[2,1.03,200]],"ltp":0.0,"tv":0.0,"id":2780},{"batb":[[0,1.16,53.5],[1,1.15,133.33],[2,1.03,200]],"ltp":0.0,"tv":0.0,"id":60443},{"batb":[[0,1.16,53.5],[1,1.15,133.33],[2,1.03,200]],"ltp":0.0,"tv":0.0,"id":31374}]}]}
{"op":"mcm","clk":"11895333498","pt":1723875104882,"mc":[{"id":"1.231851789","rc":[{"batb":[[0,1.15,133.33],[1,1.03,200],[2,1.02,200]],"ltp":0.0,"tv":0.0,"id":2780},{"batb":[[0,1.15,133.33],[1,1.03,200],[2,1.02,200]],"ltp":0.0,"tv":0.0,"id":60443},{"batb":[[0,1.15,133.33],[1,1.03,200],[2,1.02,200]],"ltp":0.0,"tv":0.0,"id":31374}]}]}
{"op":"mcm","clk":"11895339969","pt":1723875291025,"mc":[{"id":"1.231851789","rc":[{"batb":[[0,1.16,53.5],[1,1.15,133.33],[2,1.03,200]],"ltp":0.0,"tv":0.0,"id":2780},{"batb":[[0,1.16,53.5],[1,1.15,133.33],[2,1.03,200]],"ltp":0.0,"tv":0.0,"id":60443},{"batb":[[0,1.16,53.5],[1,1.15,133.33],[2,1.03,200]],"ltp":0.0,"tv":0.0,"id":31374}]}]}
{"op":"mcm","clk":"11895427249","pt":1723877091270,"mc":[{"id":"1.231851789","rc":[{"batb":[[0,1.15,133.33],[1,1.03,200],[2,1.02,200]],"ltp":0.0,"tv":0.0,"id":2780},{"batb":[[0,1.15,133.33],[1,1.03,200],[2,1.02,200]],"ltp":0.0,"tv":0.0,"id":31374}]}]}
{"op":"mcm","clk":"11895427257","pt":1723877091476,"mc":[{"id":"1.231851789","rc":[{"batb":[[0,1.15,133.33],[1,1.03,200],[2,1.02,200]],"ltp":0.0,"tv":0.0,"id":60443}]}]}
{"op":"mcm","clk":"11895434962","pt":1723877278174,"mc":[{"id":"1.231851789","rc":[{"batb":[[0,1.16,53.5],[1,1.15,133.33],[2,1.03,200]],"ltp":0.0,"tv":0.0,"id":2780},{"batb":[[0,1.16,53.5],[1,1.15,133.33],[2,1.03,200]],"ltp":0.0,"tv":0.0,"id":60443},{"batb":[[0,1.16,53.5],[1,1.15,133.33],[2,1.03,200]],"ltp":0.0,"tv":0.0,"id":31374}]}]}
{"op":"mcm","clk":"11895538039","pt":1723879078688,"mc":[{"id":"1.231851789","rc":[{"batb":[[0,1.15,133.33],[1,1.03,200],[2,1.02,200]],"ltp":0.0,"tv":0.0,"id":2780},{"batb":[[0,1.15,133.33],[1,1.03,200],[2,1.02,200]],"ltp":0.0,"tv":0.0,"id":60443},{"batb":[[0,1.15,133.33],[1,1.03,200],[2,1.02,200]],"ltp":0.0,"tv":0.0,"id":31374}]}]}
{"op":"mcm","clk":"11895547848","pt":1723879257506,"mc":[{"id":"1.231851789","rc":[{"batb":[[0,1.16,53.5],[1,1.15,133.33],[2,1.03,200]],"ltp":0.0,"tv":0.0,"id":2780},{"batb":[[0,1.16,53.5],[1,1.15,133.33],[2,1.03,200]],"ltp":0.0,"tv":0.0,"id":60443},{"batb":[[0,1.16,53.5],[1,1.15,133.33],[2,1.03,200]],"ltp":0.0,"tv":0.0,"id":31374}]}]}
{"op":"mcm","clk":"11895660635","pt":1723881058172,"mc":[{"id":"1.231851789","rc":[{"batb":[[0,1.15,133.33],[1,1.03,200],[2,1.02,200]],"ltp":0.0,"tv":0.0,"id":2780},{"batb":[[0,1.15,133.33],[1,1.03,200],[2,1.02,200]],"ltp":0.0,"tv":0.0,"id":60443},{"batb":[[0,1.15,133.33],[1,1.03,200],[2,1.02,200]],"ltp":0.0,"tv":0.0,"id":31374}]}]}
{"op":"mcm","clk":"11895671757","pt":1723881236356,"mc":[{"id":"1.231851789","rc":[{"batb":[[0,1.16,53.5],[1,1.15,133.33],[2,1.03,200]],"ltp":0.0,"tv":0.0,"id":2780},{"batb":[[0,1.16,53.5],[1,1.15,133.33],[2,1.03,200]],"ltp":0.0,"tv":0.0,"id":60443},{"batb":[[0,1.16,53.5],[1,1.15,133.33],[2,1.03,200]],"ltp":0.0,"tv":0.0,"id":31374}]}]}
{"op":"mcm","clk":"11895827337","pt":1723883036859,"mc":[{"id":"1.231851789","rc":[{"batb":[[0,1.15,133.33],[1,1.03,200],[2,1.02,200]],"ltp":0.0,"tv":0.0,"id":2780},{"batb":[[0,1.15,133.33],[1,1.03,200],[2,1.02,200]],"ltp":0.0,"tv":0.0,"id":60443},{"batb":[[0,1.15,133.33],[1,1.03,200],[2,1.02,200]],"ltp":0.0,"tv":0.0,"id":31374}]}]}
{"op":"mcm","clk":"11895841812","pt":1723883216166,"mc":[{"id":"1.231851789","rc":[{"batb":[[0,1.16,53.5],[1,1.15,133.33],[2,1.03,200]],"ltp":0.0,"tv":0.0,"id":2780},{"batb":[[0,1.16,53.5],[1,1.15,133.33],[2,1.03,200]],"ltp":0.0,"tv":0.0,"id":60443},{"batb":[[0,1.16,53.5],[1,1.15,133.33],[2,1.03,200]],"ltp":0.0,"tv":0.0,"id":31374}]}]}
{"op":"mcm","clk":"11895999665","pt":1723885016301,"mc":[{"id":"1.231851789","rc":[{"batb":[[0,1.15,133.33],[1,1.03,200],[2,1.02,200]],"ltp":0.0,"tv":0.0,"id":2780}]}]}
{"op":"mcm","clk":"11895999688","pt":1723885016506,"mc":[{"id":"1.231851789","rc":[{"batb":[[0,1.15,133.33],[1,1.03,200],[2,1.02,200]],"ltp":0.0,"tv":0.0,"id":60443},{"batb":[[0,1.15,133.33],[1,1.03,200],[2,1.02,200]],"ltp":0.0,"tv":0.0,"id":31374}]}]}
{"op":"mcm","clk":"11896016728","pt":1723885195434,"mc":[{"id":"1.231851789","rc":[{"batb":[[0,1.16,53.5],[1,1.15,133.33],[2,1.03,200]],"ltp":0.0,"tv":0.0,"id":2780},{"batb":[[0,1.16,53.5],[1,1.15,133.33],[2,1.03,200]],"ltp":0.0,"tv":0.0,"id":60443},{"batb":[[0,1.16,53.5],[1,1.15,133.33],[2,1.03,200]],"ltp":0.0,"tv":0.0,"id":31374}]}]}
{"op":"mcm","clk":"11896220102","pt":1723886995911,"mc":[{"id":"1.231851789","rc":[{"batb":[[0,1.15,133.33],[1,1.03,200],[2,1.02,200]],"ltp":0.0,"tv":0.0,"id":2780},{"batb":[[0,1.15,133.33],[1,1.03,200],[2,1.02,200]],"ltp":0.0,"tv":0.0,"id":60443},{"batb":[[0,1.15,133.33],[1,1.03,200],[2,1.02,200]],"ltp":0.0,"tv":0.0,"id":31374}]}]}
{"op":"mcm","clk":"11896245771","pt":1723887175904,"mc":[{"id":"1.231851789","rc":[{"batb":[[0,1.16,53.5],[1,1.15,133.33],[2,1.03,200]],"ltp":0.0,"tv":0.0,"id":2780},{"batb":[[0,1.16,53.5],[1,1.15,133.33],[2,1.03,200]],"ltp":0.0,"tv":0.0,"id":60443},{"batb":[[0,1.16,53.5],[1,1.15,133.33],[2,1.03,200]],"ltp":0.0,"tv":0.0,"id":31374}]}]}
{"op":"mcm","clk":"11896487026","pt":1723888976168,"mc":[{"id":"1.231851789","rc":[{"batb":[[0,1.15,133.33],[1,1.03,200],[2,1.02,200]],"ltp":0.0,"tv":0.0,"id":60443},{"batb":[[0,1.15,133.33],[1,1.03,200],[2,1.02,200]],"ltp":0.0,"tv":0.0,"id":31374}]}]}
{"op":"mcm","clk":"11896487057","pt":1723888976374,"mc":[{"id":"1.231851789","rc":[{"batb":[[0,1.15,133.33],[1,1.03,200],[2,1.02,200]],"ltp":0.0,"tv":0.0,"id":2780}]}]}
{"op":"mcm","clk":"11896517112","pt":1723889146025,"mc":[{"id":"1.231851789","rc":[{"batb":[[0,1.16,53.5],[1,1.15,133.33],[2,1.03,200]],"ltp":0.0,"tv":0.0,"id":2780},{"batb":[[0,1.16,53.5],[1,1.15,133.33],[2,1.03,200]],"ltp":0.0,"tv":0.0,"id":60443},{"batb":[[0,1.16,53.5],[1,1.15,133.33],[2,1.03,200]],"ltp":0.0,"tv":0.0,"id":31374}]}]}
{"op":"mcm","clk":"11896837070","pt":1723890946156,"mc":[{"id":"1.231851789","rc":[{"batb":[[0,1.15,133.33],[1,1.03,200],[2,1.02,200]],"ltp":0.0,"tv":0.0,"id":31374}]}]}
{"op":"mcm","clk":"11896837150","pt":1723890946573,"mc":[{"id":"1.231851789","rc":[{"batb":[[0,1.15,133.33],[1,1.03,200],[2,1.02,200]],"ltp":0.0,"tv":0.0,"id":2780},{"batb":[[0,1.15,133.33],[1,1.03,200],[2,1.02,200]],"ltp":0.0,"tv":0.0,"id":60443}]}]}
{"op":"mcm","clk":"11896867571","pt":1723891104842,"mc":[{"id":"1.231851789","rc":[{"batb":[[0,1.16,53.5],[1,1.15,133.33],[2,1.03,200]],"ltp":0.0,"tv":0.0,"id":2780},{"batb":[[0,1.16,53.5],[1,1.15,133.33],[2,1.03,200]],"ltp":0.0,"tv":0.0,"id":60443},{"batb":[[0,1.16,53.5],[1,1.15,133.33],[2,1.03,200]],"ltp":0.0,"tv":0.0,"id":31374}]}]}
{"op":"mcm","clk":"11897154447","pt":1723892905101,"mc":[{"id":"1.231851789","rc":[{"batb":[[0,1.15,133.33],[1,1.03,200],[2,1.02,200]],"ltp":0.0,"tv":0.0,"id":60443}]}]}
{"op":"mcm","clk":"11897154524","pt":1723892905511,"mc":[{"id":"1.231851789","rc":[{"batb":[[0,1.15,133.33],[1,1.03,200],[2,1.02,200]],"ltp":0.0,"tv":0.0,"id":2780},{"batb":[[0,1.15,133.33],[1,1.03,200],[2,1.02,200]],"ltp":0.0,"tv":0.0,"id":31374}]}]}
{"op":"mcm","clk":"11897183606","pt":1723893057076,"mc":[{"id":"1.231851789","rc":[{"batb":[[0,1.16,53.5],[1,1.15,133.33],[2,1.03,200]],"ltp":0.0,"tv":0.0,"id":2780},{"batb":[[0,1.16,53.5],[1,1.15,133.33],[2,1.03,200]],"ltp":0.0,"tv":0.0,"id":60443},{"batb":[[0,1.16,53.5],[1,1.15,133.33],[2,1.03,200]],"ltp":0.0,"tv":0.0,"id":31374}]}]}
{"op":"mcm","clk":"11897569259","pt":1723894857770,"mc":[{"id":"1.231851789","rc":[{"batb":[[0,1.15,133.33],[1,1.03,200],[2,1.02,200]],"ltp":0.0,"tv":0.0,"id":2780},{"batb":[[0,1.15,133.33],[1,1.03,200],[2,1.02,200]],"ltp":0.0,"tv":0.0,"id":60443},{"batb":[[0,1.15,133.33],[1,1.03,200],[2,1.02,200]],"ltp":0.0,"tv":0.0,"id":31374}]}]}
{"op":"mcm","clk":"11897597614","pt":1723894990637,"mc":[{"id":"1.231851789","rc":[{"batb":[[0,1.16,53.5],[1,1.15,133.33],[2,1.03,200]],"ltp":0.0,"tv":0.0,"id":2780},{"batb":[[0,1.16,53.5],[1,1.15,133.33],[2,1.03,200]],"ltp":0.0,"tv":0.0,"id":60443},{"batb":[[0,1.16,53.5],[1,1.15,133.33],[2,1.03,200]],"ltp":0.0,"tv":0.0,"id":31374}]}]}
{"op":"mcm","clk":"11897913533","pt":1723896791176,"mc":[{"id":"1.231851789","rc":[{"batb":[[0,1.15,133.33],[1,1.03,200],[2,1.02,200]],"ltp":0.0,"tv":0.0,"id":2780},{"batb":[[0,1.15,133.33],[1,1.03,200],[2,1.02,200]],"ltp":0.0,"tv":0.0,"id":31374}]}]}
{"op":"mcm","clk":"11897913570","pt":1723896791381,"mc":[{"id":"1.231851789","rc":[{"batb":[[0,1.15,133.33],[1,1.03,200],[2,1.02,200]],"ltp":0.0,"tv":0.0,"id":60443}]}]}
{"op":"mcm","clk":"11897930556","pt":1723896895714,"mc":[{"id":"1.231851789","rc":[{"batb":[[0,1.16,53.5],[1,1.15,133.33],[2,1.03,200]],"ltp":0.0,"tv":0.0,"id":2780},{"batb":[[0,1.16,53.5],[1,1.15,133.33],[2,1.03,200]],"ltp":0.0,"tv":0.0,"id":60443},{"batb":[[0,1.16,53.5],[1,1.15,133.33],[2,1.03,200]],"ltp":0.0,"tv":0.0,"id":31374}]}]}
{"op":"mcm","clk":"11898224887","pt":1723898696074,"mc":[{"id":"1.231851789","rc":[{"batb":[[0,1.15,133.33],[1,1.03,200],[2,1.02,200]],"ltp":0.0,"tv":0.0,"id":2780},{"batb":[[0,1.15,133.33],[1,1.03,200],[2,1.02,200]],"ltp":0.0,"tv":0.0,"id":60443},{"batb":[[0,1.15,133.33],[1,1.03,200],[2,1.02,200]],"ltp":0.0,"tv":0.0,"id":31374}]}]}
{"op":"mcm","clk":"11898236293","pt":1723898761338,"mc":[{"id":"1.231851789","rc":[{"batb":[[0,1.16,53.5],[1,1.15,133.33],[2,1.03,200]],"ltp":0.0,"tv":0.0,"id":2780},{"batb":[[0,1.16,53.5],[1,1.15,133.33],[2,1.03,200]],"ltp":0.0,"tv":0.0,"id":60443},{"batb":[[0,1.16,53.5],[1,1.15,133.33],[2,1.03,200]],"ltp":0.0,"tv":0.0,"id":31374}]}]}
{"op":"mcm","clk":"11898463631","pt":1723900132270,"mc":[{"id":"1.231851789","rc":[{"batb":[[0,1.17,19.59],[1,1.16,53.5],[2,1.15,133.33]],"batl":[[0,90,1.79],[1,95,5],[2,990,5]],"ltp":0.0,"tv":0.0,"id":2780},{"batb":[[0,1.17,19.59],[1,1.16,53.5],[2,1.15,133.33]],"batl":[[0,90,1.79],[1,95,5],[2,990,5]],"ltp":0.0,"tv":0.0,"id":60443},{"batb":[[0,1.17,19.59],[1,1.16,53.5],[2,1.15,133.33]],"batl":[[0,90,1.79],[1,95,5],[2,990,5]],"ltp":0.0,"tv":0.0,"id":31374}]}]}
{"op":"mcm","clk":"11898540991","pt":1723900561764,"mc":[{"id":"1.231851789","rc":[{"batb":[[1,1.15,133.33],[2,1.03,200]],"ltp":0.0,"tv":0.0,"id":2780},{"batb":[[1,1.15,133.33],[2,1.03,200]],"ltp":0.0,"tv":0.0,"id":60443},{"batb":[[1,1.15,133.33],[2,1.03,200]],"ltp":0.0,"tv":0.0,"id":31374}]}]}
{"op":"mcm","clk":"11898547798","pt":1723900600198,"mc":[{"id":"1.231851789","rc":[{"batb":[[0,1.18,47.55],[1,1.17,19.59],[2,1.15,133.33]],"ltp":0.0,"tv":0.0,"id":2780},{"batb":[[0,1.18,47.55],[1,1.17,19.59],[2,1.15,133.33]],"ltp":0.0,"tv":0.0,"id":60443},{"batb":[[0,1.18,47.55],[1,1.17,19.59],[2,1.15,133.33]],"ltp":0.0,"tv":0.0,"id":31374}]}]}
{"op":"mcm","clk":"11898834809","pt":1723902400860,"mc":[{"id":"1.231851789","rc":[{"batb":[[0,1.17,19.59],[1,1.15,133.33],[2,1.03,200]],"ltp":0.0,"tv":0.0,"id":2780},{"batb":[[0,1.17,19.59],[1,1.15,133.33],[2,1.03,200]],"ltp":0.0,"tv":0.0,"id":60443},{"batb":[[0,1.17,19.59],[1,1.15,133.33],[2,1.03,200]],"ltp":0.0,"tv":0.0,"id":31374}]}]}
{"op":"mcm","clk":"11898835092","pt":1723902402970,"mc":[{"id":"1.231851789","rc":[{"batb":[[0,1.18,47.55],[1,1.17,19.59],[2,1.15,133.33]],"ltp":0.0,"tv":0.0,"id":2780},{"batb":[[0,1.18,47.55],[1,1.17,19.59],[2,1.15,133.33]],"ltp":0.0,"tv":0.0,"id":60443},{"batb":[[0,1.18,47.55],[1,1.17,19.59],[2,1.15,133.33]],"ltp":0.0,"tv":0.0,"id":31374}]}]}
{"op":"mcm","clk":"11899229315","pt":1723904203260,"mc":[{"id":"1.231851789","rc":[{"batb":[[0,1.17,19.59],[1,1.15,133.33],[2,1.03,200]],"ltp":0.0,"tv":0.0,"id":2780}]}]}
{"op":"mcm","clk":"11899229422","pt":1723904203638,"mc":[{"id":"1.231851789","rc":[{"batb":[[0,1.17,19.59],[1,1.15,133.33],[2,1.03,200]],"ltp":0.0,"tv":0.0,"id":60443},{"batb":[[0,1.17,19.59],[1,1.15,133.33],[2,1.03,200]],"ltp":0.0,"tv":0.0,"id":31374}]}]}
{"op":"mcm","clk":"11899272807","pt":1723904351975,"mc":[{"id":"1.231851789","rc":[{"batb":[[0,1.18,47.55],[1,1.17,19.59],[2,1.15,133.33]],"ltp":0.0,"tv":0.0,"id":2780},{"batb":[[0,1.18,47.55],[1,1.17,19.59],[2,1.15,133.33]],"ltp":0.0,"tv":0.0,"id":60443},{"batb":[[0,1.18,47.55],[1,1.17,19.59],[2,1.15,133.33]],"ltp":0.0,"tv":0.0,"id":31374}]}]}
{"op":"mcm","clk":"11899310874","pt":1723904489255,"mc":[{"id":"1.231851789","rc":[{"batl":[[0,1.2,1.54],[1,90,1.79],[2,95,5]],"ltp":0.0,"tv":0.0,"id":31374}]}]}
{"op":"mcm","clk":"11899315287","pt":1723904504664,"mc":[{"id":"1.231851789","rc":[{"batl":[[0,90,1.79],[1,95,5],[2,990,5]],"ltp":0.0,"tv":0.0,"id":31374}]}]}
{"op":"mcm","clk":"11899758590","pt":1723906152271,"mc":[{"id":"1.231851789","rc":[{"batb":[[0,1.17,19.59],[1,1.15,133.33],[2,1.03,200]],"ltp":0.0,"tv":0.0,"id":2780},{"batb":[[0,1.17,19.59],[1,1.15,133.33],[2,1.03,200]],"ltp":0.0,"tv":0.0,"id":31374}]}]}
{"op":"mcm","clk":"11899758639","pt":1723906152469,"mc":[{"id":"1.231851789","rc":[{"batb":[[0,1.17,19.59],[1,1.15,133.33],[2,1.03,200]],"ltp":0.0,"tv":0.0,"id":60443}]}]}
{"op":"mcm","clk":"11899785388","pt":1723906279249,"mc":[{"id":"1.231851789","rc":[{"batb":[[0,1.18,47.55],[1,1.17,19.59],[2,1.15,133.33]],"ltp":0.0,"tv":0.0,"id":2780},{"batb":[[0,1.18,47.55],[1,1.17,19.59],[2,1.15,133.33]],"ltp":0.0,"tv":0.0,"id":60443},{"batb":[[0,1.18,47.55],[1,1.17,19.59],[2,1.15,133.33]],"ltp":0.0,"tv":0.0,"id":31374}]}]}
{"op":"mcm","clk":"11900199375","pt":1723908079940,"mc":[{"id":"1.231851789","rc":[{"batb":[[0,1.17,19.59],[1,1.15,133.33],[2,1.03,200]],"ltp":0.0,"tv":0.0,"id":2780},{"batb":[[0,1.17,19.59],[1,1.15,133.33],[2,1.03,200]],"ltp":0.0,"tv":0.0,"id":60443},{"batb":[[0,1.17,19.59],[1,1.15,133.33],[2,1.03,200]],"ltp":0.0,"tv":0.0,"id":31374}]}]}
{"op":"mcm","clk":"11900219324","pt":1723908157807,"mc":[{"id":"1.231851789","rc":[{"batb":[[0,1.18,47.55],[1,1.17,19.59],[2,1.15,133.33]],"ltp":0.0,"tv":0.0,"id":2780},{"batb":[[0,1.18,47.55],[1,1.17,19.59],[2,1.15,133.33]],"ltp":0.0,"tv":0.0,"id":60443},{"batb":[[0,1.18,47.55],[1,1.17,19.59],[2,1.15,133.33]],"ltp":0.0,"tv":0.0,"id":31374}]}]}
{"op":"mcm","clk":"11900468190","pt":1723909160486,"mc":[{"id":"1.231851789","rc":[{"batl":[[0,95,5.85],[1,990,5],[2,990,0]],"ltp":0.0,"tv":0.0,"id":2780},{"batl":[[0,95,5.85],[1,990,5],[2,990,0]],"ltp":0.0,"tv":0.0,"id":60443},{"batl":[[0,95,5.85],[1,990,5],[2,990,0]],"ltp":0.0,"tv":0.0,"id":31374}]}]}
{"op":"mcm","clk":"11900538289","pt":1723909389591,"mc":[{"id":"1.231851789","rc":[{"batb":[[0,1.19,19.59],[1,1.18,47.55]],"ltp":0.0,"tv":0.0,"id":2780},{"batb":[[0,1.19,19.59],[1,1.18,47.55]],"ltp":0.0,"tv":0.0,"id":60443},{"batb":[[0,1.19,19.59],[1,1.18,47.55]],"ltp":0.0,"tv":0.0,"id":31374}]}]}
{"op":"mcm","clk":"11900660622","pt":1723909958216,"mc":[{"id":"1.231851789","rc":[{"batb":[[1,1.15,133.33],[2,1.03,200]],"ltp":0.0,"tv":0.0,"id":2780},{"batb":[[1,1.15,133.33],[2,1.03,200]],"ltp":0.0,"tv":0.0,"id":31374}]}]}
{"op":"mcm","clk":"11900660652","pt":1723909958413,"mc":[{"id":"1.231851789","rc":[{"batb":[[1,1.15,133.33],[2,1.03,200]],"ltp":0.0,"tv":0.0,"id":60443}]}]}
{"op":"mcm","clk":"11900667926","pt":1723910001956,"mc":[{"id":"1.231851789","rc":[{"batb":[[0,1.2,42.8],[1,1.19,19.59],[2,1.15,133.33]],"ltp":0.0,"tv":0.0,"id":2780},{"batb":[[0,1.2,42.8],[1,1.19,19.59],[2,1.15,133.33]],"ltp":0.0,"tv":0.0,"id":60443},{"batb":[[0,1.2,42.8],[1,1.19,19.59],[2,1.15,133.33]],"ltp":0.0,"tv":0.0,"id":31374}]}]}
{"op":"mcm","clk":"11900984989","pt":1723911802213,"mc":[{"id":"1.231851789","rc":[{"batb":[[0,1.19,19.59],[1,1.15,133.33],[2,1.03,200]],"ltp":0.0,"tv":0.0,"id":31374}]}]}
{"op":"mcm","clk":"11900985076","pt":1723911802797,"mc":[{"id":"1.231851789","rc":[{"batb":[[0,1.19,19.59],[1,1.15,133.33],[2,1.03,200]],"ltp":0.0,"tv":0.0,"id":2780},{"batb":[[0,1.19,19.59],[1,1.15,133.33],[2,1.03,200]],"ltp":0.0,"tv":0.0,"id":60443}]}]}
{"op":"mcm","clk":"11900988625","pt":1723911822834,"mc":[{"id":"1.231851789","rc":[{"batb":[[0,1.2,42.8],[1,1.19,19.59],[2,1.15,133.33]],"ltp":0.0,"tv":0.0,"id":2780},{"batb":[[0,1.2,42.8],[1,1.19,19.59],[2,1.15,133.33]],"ltp":0.0,"tv":0.0,"id":60443},{"batb":[[0,1.2,42.8],[1,1.19,19.59],[2,1.15,133.33]],"ltp":0.0,"tv":0.0,"id":31374}]}]}
{"op":"mcm","clk":"11901264583","pt":1723913342092,"mc":[{"id":"1.231851789","rc":[{"batb":[[0,1.21,5.94],[1,1.2,42.8],[2,1.19,19.59]],"ltp":0.0,"tv":0.0,"id":2780},{"batb":[[0,1.21,6.08],[1,1.2,42.8],[2,1.19,19.59]],"ltp":0.0,"tv":0.0,"id":31374}]}]}
{"op":"mcm","clk":"11901264633","pt":1723913342407,"mc":[{"id":"1.231851789","rc":[{"batb":[[0,1.21,6.79],[1,1.2,42.8],[2,1.19,19.59]],"ltp":0.0,"tv":0.0,"id":60443}]}]}
{"op":"mcm","clk":"11901312262","pt":1723913623213,"mc":[{"id":"1.231851789","rc":[{"batb":[[1,1.19,19.59],[2,1.15,133.33]],"ltp":0.0,"tv":0.0,"id":2780},{"batb":[[1,1.19,19.59],[2,1.15,133.33]],"ltp":0.0,"tv":0.0,"id":60443}]}]}
{"op":"mcm","clk":"11901312297","pt":1723913623421,"mc":[{"id":"1.231851789","rc":[{"batb":[[1,1.19,19.59],[2,1.15,133.33]],"ltp":0.0,"tv":0.0,"id":31374}]}]}
{"op":"mcm","clk":"11901328452","pt":1723913721538,"mc":[{"id":"1.231851789","rc":[{"batb":[[0,1.22,38.91],[1,1.21,5.94],[2,1.19,19.59]],"ltp":0.0,"tv":0.0,"id":2780},{"batb":[[0,1.22,38.91],[1,1.21,6.79],[2,1.19,19.59]],"ltp":0.0,"tv":0.0,"id":60443},{"batb":[[0,1.22,38.91],[1,1.21,6.08],[2,1.19,19.59]],"ltp":0.0,"tv":0.0,"id":31374}]}]}
{"op":"mcm","clk":"11901652602","pt":1723915522259,"mc":[{"id":"1.231851789","rc":[{"batb":[[0,1.21,5.94],[1,1.19,19.59],[2,1.15,133.33]],"ltp":0.0,"tv":0.0,"id":2780},{"batb":[[0,1.21,6.79],[1,1.19,19.59],[2,1.15,133.33]],"ltp":0.0,"tv":0.0,"id":60443},{"batb":[[0,1.21,6.08],[1,1.19,19.59],[2,1.15,133.33]],"ltp":0.0,"tv":0.0,"id":31374}]}]}
{"op":"mcm","clk":"11901657320","pt":1723915552317,"mc":[{"id":"1.231851789","rc":[{"batb":[[0,1.22,38.91],[1,1.21,5.94],[2,1.19,19.59]],"ltp":0.0,"tv":0.0,"id":2780},{"batb":[[0,1.22,38.91],[1,1.21,6.79],[2,1.19,19.59]],"ltp":0.0,"tv":0.0,"id":60443},{"batb":[[0,1.22,38.91],[1,1.21,6.08],[2,1.19,19.59]],"ltp":0.0,"tv":0.0,"id":31374}]}]}
{"op":"mcm","clk":"11901922799","pt":1723917053010,"mc":[{"id":"1.231851789","rc":[{"batb":[[0,1.23,5.94],[1,1.22,38.91]],"ltp":0.0,"tv":0.0,"id":2780},{"batb":[[0,1.23,6.08],[1,1.22,38.91]],"ltp":0.0,"tv":0.0,"id":31374}]}]}
{"op":"mcm","clk":"11901922871","pt":1723917053492,"mc":[{"id":"1.231851789","rc":[{"batb":[[0,1.23,6.79],[1,1.22,38.91]],"ltp":0.0,"tv":0.0,"id":60443}]}]}
{"op":"mcm","clk":"11901973596","pt":1723917353191,"mc":[{"id":"1.231851789","rc":[{"batb":[[1,1.19,19.59],[2,1.15,133.33]],"ltp":0.0,"tv":0.0,"id":2780},{"batb":[[1,1.19,19.59],[2,1.15,133.33]],"ltp":0.0,"tv":0.0,"id":60443},{"batb":[[1,1.19,19.59],[2,1.15,133.33]],"ltp":0.0,"tv":0.0,"id":31374}]}]}
{"op":"mcm","clk":"11901993723","pt":1723917481387,"mc":[{"id":"1.231851789","rc":[{"batb":[[0,1.24,35.66],[1,1.23,5.94],[2,1.19,19.59]],"ltp":0.0,"tv":0.0,"id":2780},{"batb":[[0,1.24,35.66],[1,1.23,6.79],[2,1.19,19.59]],"ltp":0.0,"tv":0.0,"id":60443},{"batb":[[0,1.24,35.66],[1,1.23,6.08],[2,1.19,19.59]],"ltp":0.0,"tv":0.0,"id":31374}]}]}
{"op":"mcm","clk":"11902363131","pt":1723919282065,"mc":[{"id":"1.231851789","rc":[{"batb":[[0,1.23,5.94],[1,1.19,19.59],[2,1.15,133.33]],"ltp":0.0,"tv":0.0,"id":2780},{"batb":[[0,1.23,6.79],[1,1.19,19.59],[2,1.15,133.33]],"ltp":0.0,"tv":0.0,"id":60443},{"batb":[[0,1.23,6.08],[1,1.19,19.59],[2,1.15,133.33]],"ltp":0.0,"tv":0.0,"id":31374}]}]}
{"op":"mcm","clk":"11902378427","pt":1723919349781,"mc":[{"id":"1.231851789","rc":[{"batb":[[0,1.24,35.66],[1,1.23,5.94],[2,1.19,19.59]],"ltp":0.0,"tv":0.0,"id":2780},{"batb":[[0,1.24,35.66],[1,1.23,6.79],[2,1.19,19.59]],"ltp":0.0,"tv":0.0,"id":60443},{"batb":[[0,1.24,35.66],[1,1.23,6.08],[2,1.19,19.59]],"ltp":0.0,"tv":0.0,"id":31374}]}]}
{"op":"mcm","clk":"11902655374","pt":1723920549083,"mc":[{"id":"1.231851789","rc":[{"batb":[[1,1.19,19.59],[2,1.15,133.33]],"ltp":0.0,"tv":0.0,"id":31374}]}]}
{"op":"mcm","clk":"11902655489","pt":1723920549732,"mc":[{"id":"1.231851789","rc":[{"batb":[[1,1.19,19.59],[2,1.15,133.33]],"ltp":0.0,"tv":0.0,"id":2780},{"batb":[[1,1.19,19.59],[2,1.15,133.33]],"ltp":0.0,"tv":0.0,"id":60443}]}]}
{"op":"mcm","clk":"11902768568","pt":1723921113353,"mc":[{"id":"1.231851789","rc":[{"batb":[[2,1.03,200]],"ltp":0.0,"tv":0.0,"id":60443}]}]}
{"op":"mcm","clk":"11902768779","pt":1723921114473,"mc":[{"id":"1.231851789","rc":[{"batb":[[2,1.03,200]],"ltp":0.0,"tv":0.0,"id":2780}]}]}
{"op":"mcm","clk":"11902769120","pt":1723921116389,"mc":[{"id":"1.231851789","rc":[{"batb":[[2,1.03,200]],"ltp":0.0,"tv":0.0,"id":31374}]}]}
{"op":"mcm","clk":"11902769288","pt":1723921117487,"mc":[{"id":"1.231851789","rc":[{"batb":[[0,1.25,80],[1,1.24,35.66],[2,1.19,19.59]],"ltp":0.0,"tv":0.0,"id":31374}]}]}
{"op":"mcm","clk":"11902769443","pt":1723921118384,"mc":[{"id":"1.231851789","rc":[{"batb":[[0,1.25,80],[1,1.24,35.66],[2,1.19,19.59]],"ltp":0.0,"tv":0.0,"id":2780}]}]}
{"op":"mcm","clk":"11902769635","pt":1723921119565,"mc":[{"id":"1.231851789","rc":[{"batb":[[0,1.25,80],[1,1.24,35.66],[2,1.19,19.59]],"ltp":0.0,"tv":0.0,"id":60443}]}]}
{"op":"mcm","clk":"11902775477","pt":1723921150285,"mc":[{"id":"1.231851789","rc":[{"batb":[[1,1.19,19.59],[2,1.03,200]],"ltp":0.0,"tv":0.0,"id":2780},{"batb":[[1,1.19,19.59],[2,1.03,200]],"ltp":0.0,"tv":0.0,"id":31374}]}]}
{"op":"mcm","clk":"11902775517","pt":1723921150503,"mc":[{"id":"1.231851789","rc":[{"batb":[[1,1.19,19.59],[2,1.03,200]],"ltp":0.0,"tv":0.0,"id":60443}]}]}
{"op":"mcm","clk":"11902777154","pt":1723921159336,"mc":[{"id":"1.231851789","rc":[{"batb":[[0,1.26,32.92],[1,1.25,80],[2,1.19,19.59]],"ltp":0.0,"tv":0.0,"id":2780},{"batb":[[0,1.26,32.92],[1,1.25,80],[2,1.19,19.59]],"ltp":0.0,"tv":0.0,"id":60443},{"batb":[[0,1.26,32.92],[1,1.25,80],[2,1.19,19.59]],"ltp":0.0,"tv":0.0,"id":31374}]}]}
{"op":"mcm","clk":"11903161791","pt":1723922960044,"mc":[{"id":"1.231851789","rc":[{"batb":[[0,1.25,80],[1,1.19,19.59],[2,1.03,200]],"ltp":0.0,"tv":0.0,"id":2780},{"batb":[[0,1.25,80],[1,1.19,19.59],[2,1.03,200]],"ltp":0.0,"tv":0.0,"id":60443},{"batb":[[0,1.25,80],[1,1.19,19.59],[2,1.03,200]],"ltp":0.0,"tv":0.0,"id":31374}]}]}
{"op":"mcm","clk":"11903182694","pt":1723923061026,"mc":[{"id":"1.231851789","rc":[{"batb":[[0,1.26,32.92],[1,1.25,80],[2,1.19,19.59]],"ltp":0.0,"tv":0.0,"id":2780},{"batb":[[0,1.26,32.92],[1,1.25,80],[2,1.19,19.59]],"ltp":0.0,"tv":0.0,"id":60443},{"batb":[[0,1.26,32.92],[1,1.25,80],[2,1.19,19.59]],"ltp":0.0,"tv":0.0,"id":31374}]}]}
{"op":"mcm","clk":"11903374169","pt":1723924027196,"mc":[{"id":"1.231851789","rc":[{"batb":[[0,1.27,6.57],[1,1.26,32.92],[2,1.25,80]],"ltp":0.0,"tv":0.0,"id":31374}]}]}
{"op":"mcm","clk":"11903374260","pt":1723924027786,"mc":[{"id":"1.231851789","rc":[{"batb":[[0,1.27,6.23],[1,1.26,32.92],[2,1.25,80]],"ltp":0.0,"tv":0.0,"id":2780},{"batb":[[0,1.27,6.58],[1,1.26,32.92],[2,1.25,80]],"ltp":0.0,"tv":0.0,"id":60443}]}]}
{"op":"mcm","clk":"11903517993","pt":1723924861720,"mc":[{"id":"1.231851789","rc":[{"batb":[[1,1.25,80],[2,1.19,19.59]],"ltp":0.0,"tv":0.0,"id":2780},{"batb":[[1,1.25,80],[2,1.19,19.59]],"ltp":0.0,"tv":0.0,"id":60443},{"batb":[[1,1.25,80],[2,1.19,19.59]],"ltp":0.0,"tv":0.0,"id":31374}]}]}
{"op":"mcm","clk":"11903528918","pt":1723924920363,"mc":[{"id":"1.231851789","rc":[{"batb":[[0,1.28,30.57],[1,1.27,6.23],[2,1.25,80]],"ltp":0.0,"tv":0.0,"id":2780},{"batb":[[0,1.28,30.57],[1,1.27,6.58],[2,1.25,80]],"ltp":0.0,"tv":0.0,"id":60443},{"batb":[[0,1.28,30.57],[1,1.27,6.57],[2,1.25,80]],"ltp":0.0,"tv":0.0,"id":31374}]}]}
{"op":"mcm","clk":"11903841011","pt":1723926720892,"mc":[{"id":"1.231851789","rc":[{"batb":[[0,1.27,6.23],[1,1.25,80],[2,1.19,19.59]],"ltp":0.0,"tv":0.0,"id":2780},{"batb":[[0,1.27,6.58],[1,1.25,80],[2,1.19,19.59]],"ltp":0.0,"tv":0.0,"id":60443},{"batb":[[0,1.27,6.57],[1,1.25,80],[2,1.19,19.59]],"ltp":0.0,"tv":0.0,"id":31374}]}]}
{"op":"mcm","clk":"11903856137","pt":1723926818265,"mc":[{"id":"1.231851789","rc":[{"batb":[[0,1.28,30.57],[1,1.27,6.57],[2,1.25,80]],"ltp":0.0,"tv":0.0,"id":31374}]}]}
{"op":"mcm","clk":"11903856155","pt":1723926818357,"mc":[{"id":"1.231851789","rc":[{"batb":[[0,1.28,30.57],[1,1.27,6.23],[2,1.25,80]],"ltp":0.0,"tv":0.0,"id":2780},{"batb":[[0,1.28,30.57],[1,1.27,6.58],[2,1.25,80]],"ltp":0.0,"tv":0.0,"id":60443}]}]}
{"op":"mcm","clk":"11903917878","pt":1723927252213,"mc":[{"id":"1.231851789","rc":[{"batb":[[0,1.29,6.57],[1,1.28,30.57]],"ltp":0.0,"tv":0.0,"id":31374}]}]}
{"op":"mcm","clk":"11903918029","pt":1723927253255,"mc":[{"id":"1.231851789","rc":[{"batb":[[0,1.29,6.23],[1,1.28,30.57]],"ltp":0.0,"tv":0.0,"id":2780},{"batb":[[0,1.29,6.58],[1,1.28,30.57]],"ltp":0.0,"tv":0.0,"id":60443}]}]}
{"op":"mcm","clk":"11904053495","pt":1723928618999,"mc":[{"id":"1.231851789","rc":[{"batb":[[1,1.25,80],[2,1.19,19.59]],"ltp":0.0,"tv":0.0,"id":2780},{"batb":[[1,1.25,80],[2,1.19,19.59]],"ltp":0.0,"tv":0.0,"id":60443},{"batb":[[1,1.25,80],[2,1.19,19.59]],"ltp":0.0,"tv":0.0,"id":31374}]}]}
{"op":"mcm","clk":"11904055136","pt":1723928639448,"mc":[{"id":"1.231851789","rc":[{"batb":[[0,1.3,28.53],[1,1.29,6.23],[2,1.25,80]],"ltp":0.0,"tv":0.0,"id":2780},{"batb":[[0,1.3,28.53],[1,1.29,6.58],[2,1.25,80]],"ltp":0.0,"tv":0.0,"id":60443},{"batb":[[0,1.3,28.53],[1,1.29,6.57],[2,1.25,80]],"ltp":0.0,"tv":0.0,"id":31374}]}]}
{"op":"mcm","clk":"11904215208","pt":1723930440170,"mc":[{"id":"1.231851789","rc":[{"batb":[[0,1.29,6.23],[1,1.25,80],[2,1.19,19.59]],"ltp":0.0,"tv":0.0,"id":2780},{"batb":[[0,1.29,6.58],[1,1.25,80],[2,1.19,19.59]],"ltp":0.0,"tv":0.0,"id":60443},{"batb":[[0,1.29,6.57],[1,1.25,80],[2,1.19,19.59]],"ltp":0.0,"tv":0.0,"id":31374}]}]}
{"op":"mcm","clk":"11904218938","pt":1723930481487,"mc":[{"id":"1.231851789","rc":[{"batb":[[0,1.3,28.53],[1,1.29,6.23],[2,1.25,80]],"ltp":0.0,"tv":0.0,"id":2780},{"batb":[[0,1.3,28.53],[1,1.29,6.58],[2,1.25,80]],"ltp":0.0,"tv":0.0,"id":60443},{"batb":[[0,1.3,28.53],[1,1.29,6.57],[2,1.25,80]],"ltp":0.0,"tv":0.0,"id":31374}]}]}
{"op":"mcm","clk":"11904223707","pt":1723930530258,"mc":[{"id":"1.231851789","rc":[{"batb":[[0,1.31,6.23],[1,1.3,28.53]],"ltp":0.0,"tv":0.0,"id":2780},{"batb":[[1,1.25,80],[2,1.19,19.59]],"ltp":0.0,"tv":0.0,"id":60443},{"batb":[[0,1.31,6.57],[1,1.3,28.53]],"ltp":0.0,"tv":0.0,"id":31374}]}]}
{"op":"mcm","clk":"11904223718","pt":1723930530360,"mc":[{"id":"1.231851789","rc":[{"batb":[[0,1.31,6.58],[1,1.3,28.53],[2,1.25,80]],"ltp":0.0,"tv":0.0,"id":60443}]}]}
{"op":"mcm","clk":"11904386477","pt":1723932282069,"mc":[{"id":"1.231851789","rc":[{"batb":[[1,1.25,80],[2,1.19,19.59]],"ltp":0.0,"tv":0.0,"id":2780},{"batb":[[1,1.25,80],[2,1.19,19.59]],"ltp":0.0,"tv":0.0,"id":60443},{"batb":[[1,1.25,80],[2,1.19,19.59]],"ltp":0.0,"tv":0.0,"id":31374}]}]}
{"op":"mcm","clk":"11904386944","pt":1723932288299,"mc":[{"id":"1.231851789","rc":[{"batb":[[0,1.32,26.75],[1,1.31,6.23],[2,1.25,80]],"ltp":0.0,"tv":0.0,"id":2780},{"batb":[[0,1.32,26.75],[1,1.31,6.58],[2,1.25,80]],"ltp":0.0,"tv":0.0,"id":60443},{"batb":[[0,1.32,26.75],[1,1.31,6.57],[2,1.25,80]],"ltp":0.0,"tv":0.0,"id":31374}]}]}
{"op":"mcm","clk":"11904499459","pt":1723933818215,"mc":[{"id":"1.231851789","rc":[{"batb":[[1,1.25,80],[2,1.19,19.59]],"ltp":0.0,"tv":0.0,"id":2780},{"batb":[[0,1.33,6.57],[1,1.32,26.75]],"ltp":0.0,"tv":0.0,"id":31374}]}]}
{"op":"mcm","clk":"11904499501","pt":1723933818682,"mc":[{"id":"1.231851789","rc":[{"batb":[[0,1.33,6.23],[1,1.32,26.75],[2,1.25,80]],"ltp":0.0,"tv":0.0,"id":2780},{"batb":[[0,1.33,6.58],[1,1.32,26.75]],"ltp":0.0,"tv":0.0,"id":60443}]}]}
{"op":"mcm","clk":"11904519695","pt":1723934088892,"mc":[{"id":"1.231851789","rc":[{"batb":[[1,1.25,80],[2,1.19,19.59]],"ltp":0.0,"tv":0.0,"id":2780},{"batb":[[1,1.25,80],[2,1.19,19.59]],"ltp":0.0,"tv":0.0,"id":60443},{"batb":[[1,1.25,80],[2,1.19,19.59]],"ltp":0.0,"tv":0.0,"id":31374}]}]}
{"op":"mcm","clk":"11904526021","pt":1723934173153,"mc":[{"id":"1.231851789","rc":[{"batb":[[0,1.34,25.18],[1,1.33,6.23],[2,1.25,80]],"ltp":0.0,"tv":0.0,"id":2780},{"batb":[[0,1.34,25.18],[1,1.33,6.58],[2,1.25,80]],"ltp":0.0,"tv":0.0,"id":60443},{"batb":[[0,1.34,25.18],[1,1.33,6.57],[2,1.25,80]],"ltp":0.0,"tv":0.0,"id":31374}]}]}
{"op":"mcm","clk":"11904659804","pt":1723935973814,"mc":[{"id":"1.231851789","rc":[{"batb":[[0,1.33,6.23],[1,1.25,80],[2,1.19,19.59]],"ltp":0.0,"tv":0.0,"id":2780},{"batb":[[0,1.33,6.58],[1,1.25,80],[2,1.19,19.59]],"ltp":0.0,"tv":0.0,"id":60443},{"batb":[[0,1.33,6.57],[1,1.25,80],[2,1.19,19.59]],"ltp":0.0,"tv":0.0,"id":31374}]}]}
{"op":"mcm","clk":"11904664212","pt":1723936031689,"mc":[{"id":"1.231851789","rc":[{"batb":[[0,1.34,25.18],[1,1.33,6.23],[2,1.25,80]],"ltp":0.0,"tv":0.0,"id":2780},{"batb":[[0,1.34,25.18],[1,1.33,6.58],[2,1.25,80]],"ltp":0.0,"tv":0.0,"id":60443},{"batb":[[0,1.34,25.18],[1,1.33,6.57],[2,1.25,80]],"ltp":0.0,"tv":0.0,"id":31374}]}]}
{"op":"mcm","clk":"11904764714","pt":1723937190035,"mc":[{"id":"1.231851789","rc":[{"batb":[[0,1.35,6.23],[1,1.34,25.18]],"ltp":0.0,"tv":0.0,"id":2780},{"batb":[[0,1.35,6.57],[1,1.34,25.18]],"ltp":0.0,"tv":0.0,"id":31374}]}]}
{"op":"mcm","clk":"11904764756","pt":1723937190507,"mc":[{"id":"1.231851789","rc":[{"batb":[[0,1.35,6.58],[1,1.34,25.18]],"ltp":0.0,"tv":0.0,"id":60443}]}]}
{"op":"mcm","clk":"11904809924","pt":1723937832255,"mc":[{"id":"1.231851789","rc":[{"batb":[[1,1.25,80],[2,1.19,19.59]],"ltp":0.0,"tv":0.0,"id":2780},{"batb":[[1,1.25,80],[2,1.19,19.59]],"ltp":0.0,"tv":0.0,"id":60443},{"batb":[[1,1.25,80],[2,1.19,19.59]],"ltp":0.0,"tv":0.0,"id":31374}]}]}
{"op":"mcm","clk":"11904821983","pt":1723938010487,"mc":[{"id":"1.231851789","rc":[{"batb":[[0,1.36,23.78],[1,1.35,6.23],[2,1.25,80]],"ltp":0.0,"tv":0.0,"id":2780},{"batb":[[0,1.36,23.78],[1,1.35,6.58],[2,1.25,80]],"ltp":0.0,"tv":0.0,"id":60443},{"batb":[[0,1.36,23.78],[1,1.35,6.57],[2,1.25,80]],"ltp":0.0,"tv":0.0,"id":31374}]}]}
{"op":"mcm","clk":"11904949754","pt":1723939811158,"mc":[{"id":"1.231851789","rc":[{"batb":[[0,1.35,6.23],[1,1.25,80],[2,1.19,19.59]],"ltp":0.0,"tv":0.0,"id":2780},{"batb":[[0,1.35,6.58],[1,1.25,80],[2,1.19,19.59]],"ltp":0.0,"tv":0.0,"id":60443},{"batb":[[0,1.35,6.57],[1,1.25,80],[2,1.19,19.59]],"ltp":0.0,"tv":0.0,"id":31374}]}]}
{"op":"mcm","clk":"11904959383","pt":1723939920932,"mc":[{"id":"1.231851789","rc":[{"batb":[[0,1.36,23.78],[1,1.35,6.23],[2,1.25,80]],"ltp":0.0,"tv":0.0,"id":2780},{"batb":[[0,1.36,23.78],[1,1.35,6.58],[2,1.25,80]],"ltp":0.0,"tv":0.0,"id":60443},{"batb":[[0,1.36,23.78],[1,1.35,6.57],[2,1.25,80]],"ltp":0.0,"tv":0.0,"id":31374}]}]}
{"op":"mcm","clk":"11904986695","pt":1723940218074,"mc":[{"id":"1.231851789","rc":[{"batb":[[1,1.26,6.57]],"ltp":0.0,"tv":0.0,"id":31374}]}]}
{"op":"mcm","clk":"11904986778","pt":1723940219063,"mc":[{"id":"1.231851789","rc":[{"batb":[[1,1.26,6.23]],"ltp":0.0,"tv":0.0,"id":2780},{"batb":[[1,1.26,6.58]],"ltp":0.0,"tv":0.0,"id":60443}]}]}
{"op":"mcm","clk":"11905123201","pt":1723941721187,"mc":[{"id":"1.231851789","rc":[{"batb":[[0,1.26,6.58],[1,1.25,80],[2,1.19,19.59]],"ltp":0.0,"tv":0.0,"id":60443},{"batb":[[0,1.26,6.57],[1,1.25,80],[2,1.19,19.59]],"ltp":0.0,"tv":0.0,"id":31374}]}]}
{"op":"mcm","clk":"11905123215","pt":1723941721391,"mc":[{"id":"1.231851789","rc":[{"batb":[[0,1.26,6.23],[1,1.25,80],[2,1.19,19.59]],"ltp":0.0,"tv":0.0,"id":2780}]}]}
{"op":"mcm","clk":"11905143064","pt":1723941821657,"mc":[{"id":"1.231851789","rc":[{"batb":[[0,1.27,31.7],[1,1.26,6.23],[2,1.25,80]],"ltp":0.0,"tv":0.0,"id":2780},{"batb":[[0,1.27,31.7],[1,1.26,6.58],[2,1.25,80]],"ltp":0.0,"tv":0.0,"id":60443},{"batb":[[0,1.27,31.7],[1,1.26,6.57],[2,1.25,80]],"ltp":0.0,"tv":0.0,"id":31374}]}]}
{"op":"mcm","clk":"11905266311","pt":1723943567249,"mc":[{"id":"1.231851789","rc":[{"batb":[[0,1.28,6.23],[1,1.27,31.7]],"ltp":0.0,"tv":0.0,"id":2780},{"batb":[[1,1.25,80],[2,1.19,19.59]],"ltp":0.0,"tv":0.0,"id":60443},{"batb":[[0,1.28,6.57],[1,1.27,31.7]],"ltp":0.0,"tv":0.0,"id":31374}]}]}
{"op":"mcm","clk":"11905266316","pt":1723943567348,"mc":[{"id":"1.231851789","rc":[{"batb":[[0,1.28,6.58],[1,1.27,31.7],[2,1.25,80]],"ltp":0.0,"tv":0.0,"id":60443}]}]}
{"op":"mcm","clk":"11905270270","pt":1723943622126,"mc":[{"id":"1.231851789","rc":[{"batb":[[1,1.25,80],[2,1.19,19.59]],"ltp":0.0,"tv":0.0,"id":2780},{"batb":[[1,1.25,80],[2,1.19,19.59]],"ltp":0.0,"tv":0.0,"id":31374}]}]}
{"op":"mcm","clk":"11905270285","pt":1723943622334,"mc":[{"id":"1.231851789","rc":[{"batb":[[1,1.25,80],[2,1.19,19.59]],"ltp":0.0,"tv":0.0,"id":60443}]}]}
{"op":"mcm","clk":"11905276422","pt":1723943709508,"mc":[{"id":"1.231851789","rc":[{"batb":[[0,1.29,29.52],[1,1.28,6.23],[2,1.25,80]],"ltp":0.0,"tv":0.0,"id":2780},{"batb":[[0,1.29,29.52],[1,1.28,6.58],[2,1.25,80]],"ltp":0.0,"tv":0.0,"id":60443},{"batb":[[0,1.29,29.52],[1,1.28,6.57],[2,1.25,80]],"ltp":0.0,"tv":0.0,"id":31374}]}]}
{"op":"mcm","clk":"11905402441","pt":1723945510125,"mc":[{"id":"1.231851789","rc":[{"batb":[[0,1.28,6.23],[1,1.25,80],[2,1.19,19.59]],"ltp":0.0,"tv":0.0,"id":2780},{"batb":[[0,1.28,6.58],[1,1.25,80],[2,1.19,19.59]],"ltp":0.0,"tv":0.0,"id":60443},{"batb":[[0,1.28,6.57],[1,1.25,80],[2,1.19,19.59]],"ltp":0.0,"tv":0.0,"id":31374}]}]}
{"op":"mcm","clk":"11905406350","pt":1723945571364,"mc":[{"id":"1.231851789","rc":[{"batb":[[0,1.29,29.52],[1,1.28,6.23],[2,1.25,80]],"ltp":0.0,"tv":0.0,"id":2780},{"batb":[[0,1.29,29.52],[1,1.28,6.58],[2,1.25,80]],"ltp":0.0,"tv":0.0,"id":60443},{"batb":[[0,1.29,29.52],[1,1.28,6.57],[2,1.25,80]],"ltp":0.0,"tv":0.0,"id":31374}]}]}
{"op":"mcm","clk":"11905456509","pt":1723946576170,"mc":[{"id":"1.231851789","rc":[{"batb":[[0,1.3,6.23],[1,1.29,29.52]],"ltp":0.0,"tv":0.0,"id":2780},{"batb":[[0,1.3,6.57],[1,1.29,29.52]],"ltp":0.0,"tv":0.0,"id":31374}]}]}
{"op":"mcm","clk":"11905456520","pt":1723946576580,"mc":[{"id":"1.231851789","rc":[{"batb":[[0,1.3,6.58],[1,1.29,29.52]],"ltp":0.0,"tv":0.0,"id":60443}]}]}
{"op":"mcm","clk":"11905507096","pt":1723947371850,"mc":[{"id":"1.231851789","rc":[{"batb":[[1,1.25,80],[2,1.19,19.59]],"ltp":0.0,"tv":0.0,"id":2780},{"batb":[[1,1.25,80],[2,1.19,19.59]],"ltp":0.0,"tv":0.0,"id":60443},{"batb":[[1,1.25,80],[2,1.19,19.59]],"ltp":0.0,"tv":0.0,"id":31374}]}]}
{"op":"mcm","clk":"11905508180","pt":1723947393741,"mc":[{"id":"1.231851789","rc":[{"batb":[[0,1.31,27.61],[1,1.3,6.23],[2,1.25,80]],"ltp":0.0,"tv":0.0,"id":2780},{"batb":[[0,1.31,27.61],[1,1.3,6.58],[2,1.25,80]],"ltp":0.0,"tv":0.0,"id":60443},{"batb":[[0,1.31,27.61],[1,1.3,6.57],[2,1.25,80]],"ltp":0.0,"tv":0.0,"id":31374}]}]}
{"op":"mcm","clk":"11905600930","pt":1723949194226,"mc":[{"id":"1.231851789","rc":[{"batb":[[0,1.3,6.23],[1,1.25,80],[2,1.19,19.59]],"ltp":0.0,"tv":0.0,"id":2780},{"batb":[[0,1.3,6.58],[1,1.25,80],[2,1.19,19.59]],"ltp":0.0,"tv":0.0,"id":60443},{"batb":[[0,1.3,6.57],[1,1.25,80],[2,1.19,19.59]],"ltp":0.0,"tv":0.0,"id":31374}]}]}
{"op":"mcm","clk":"11905611002","pt":1723949359614,"mc":[{"id":"1.231851789","rc":[{"batb":[[0,1.31,27.61],[1,1.3,6.23],[2,1.25,80]],"ltp":0.0,"tv":0.0,"id":2780},{"batb":[[0,1.31,27.61],[1,1.3,6.58],[2,1.25,80]],"ltp":0.0,"tv":0.0,"id":60443},{"batb":[[0,1.31,27.61],[1,1.3,6.57],[2,1.25,80]],"ltp":0.0,"tv":0.0,"id":31374}]}]}
{"op":"mcm","clk":"11905632222","pt":1723949719052,"mc":[{"id":"1.231851789","rc":[{"batb":[[0,1.32,6.23],[1,1.31,27.61]],"ltp":0.0,"tv":0.0,"id":2780},{"batb":[[0,1.32,6.57],[1,1.31,27.61]],"ltp":0.0,"tv":0.0,"id":31374}]}]}
{"op":"mcm","clk":"11905632242","pt":1723949719419,"mc":[{"id":"1.231851789","rc":[{"batb":[[0,1.32,6.58],[1,1.31,27.61]],"ltp":0.0,"tv":0.0,"id":60443}]}]}
{"op":"mcm","clk":"11905716415","pt":1723951160275,"mc":[{"id":"1.231851789","rc":[{"batb":[[1,1.25,80],[2,1.19,19.59]],"ltp":0.0,"tv":0.0,"id":2780},{"batb":[[1,1.25,80],[2,1.19,19.59]],"ltp":0.0,"tv":0.0,"id":60443},{"batb":[[1,1.25,80],[2,1.19,19.59]],"ltp":0.0,"tv":0.0,"id":31374}]}]}
{"op":"mcm","clk":"11905724468","pt":1723951305014,"mc":[{"id":"1.231851789","rc":[{"batb":[[0,1.33,25.94],[1,1.32,6.23],[2,1.25,80]],"ltp":0.0,"tv":0.0,"id":2780},{"batb":[[0,1.33,25.94],[1,1.32,6.58],[2,1.25,80]],"ltp":0.0,"tv":0.0,"id":60443},{"batb":[[0,1.33,25.94],[1,1.32,6.57],[2,1.25,80]],"ltp":0.0,"tv":0.0,"id":31374}]}]}
{"op":"mcm","clk":"11905814106","pt":1723952820286,"mc":[{"id":"1.231851789","rc":[{"batb":[[0,1.34,6.57],[1,1.33,25.94]],"ltp":0.0,"tv":0.0,"id":31374}]}]}
{"op":"mcm","clk":"11905814149","pt":1723952821113,"mc":[{"id":"1.231851789","rc":[{"batb":[[0,1.34,6.23],[1,1.33,25.94]],"ltp":0.0,"tv":0.0,"id":2780},{"batb":[[0,1.34,6.58],[1,1.33,25.94]],"ltp":0.0,"tv":0.0,"id":60443}]}]}
{"op":"mcm","clk":"11905827662","pt":1723953105247,"mc":[{"id":"1.231851789","rc":[{"batb":[[1,1.25,80],[2,1.19,19.59]],"ltp":0.0,"tv":0.0,"id":60443}]}]}
{"op":"mcm","clk":"11905827692","pt":1723953105659,"mc":[{"id":"1.231851789","rc":[{"batb":[[1,1.25,80],[2,1.19,19.59]],"ltp":0.0,"tv":0.0,"id":2780},{"batb":[[1,1.25,80],[2,1.19,19.59]],"ltp":0.0,"tv":0.0,"id":31374}]}]}
{"op":"mcm","clk":"11905833252","pt":1723953224144,"mc":[{"id":"1.231851789","rc":[{"batb":[[0,1.35,24.46],[1,1.34,6.23],[2,1.25,80]],"ltp":0.0,"tv":0.0,"id":2780},{"batb":[[0,1.35,24.46],[1,1.34,6.58],[2,1.25,80]],"ltp":0.0,"tv":0.0,"id":60443},{"batb":[[0,1.35,24.46],[1,1.34,6.57],[2,1.25,80]],"ltp":0.0,"tv":0.0,"id":31374}]}]}
{"op":"mcm","clk":"11905923658","pt":1723955024749,"mc":[{"id":"1.231851789","rc":[{"batb":[[0,1.34,6.23],[1,1.25,80],[2,1.19,19.59]],"ltp":0.0,"tv":0.0,"id":2780},{"batb":[[0,1.34,6.58],[1,1.25,80],[2,1.19,19.59]],"ltp":0.0,"tv":0.0,"id":60443},{"batb":[[0,1.34,6.57],[1,1.25,80],[2,1.19,19.59]],"ltp":0.0,"tv":0.0,"id":31374}]}]}
{"op":"mcm","clk":"11905927457","pt":1723955126551,"mc":[{"id":"1.231851789","rc":[{"batb":[[0,1.35,24.46],[1,1.34,6.23],[2,1.25,80]],"ltp":0.0,"tv":0.0,"id":2780},{"batb":[[0,1.35,24.46],[1,1.34,6.58],[2,1.25,80]],"ltp":0.0,"tv":0.0,"id":60443},{"batb":[[0,1.35,24.46],[1,1.34,6.57],[2,1.25,80]],"ltp":0.0,"tv":0.0,"id":31374}]}]}
{"op":"mcm","clk":"11905954158","pt":1723955835270,"mc":[{"id":"1.231851789","rc":[{"batb":[[1,1.25,80],[2,1.19,19.59]],"ltp":0.0,"tv":0.0,"id":31374}]}]}
{"op":"mcm","clk":"11905954196","pt":1723955836189,"mc":[{"id":"1.231851789","rc":[{"batb":[[1,1.26,6.23]],"ltp":0.0,"tv":0.0,"id":2780},{"batb":[[1,1.26,6.58]],"ltp":0.0,"tv":0.0,"id":60443},{"batb":[[1,1.26,6.57],[2,1.25,80]],"ltp":0.0,"tv":0.0,"id":31374}]}]}
{"op":"mcm","clk":"11906001958","pt":1723956927163,"mc":[{"id":"1.231851789","rc":[{"batb":[[0,1.26,6.23],[1,1.25,80],[2,1.19,19.59]],"ltp":0.0,"tv":0.0,"id":2780},{"batb":[[0,1.26,6.58],[1,1.25,80],[2,1.19,19.59]],"ltp":0.0,"tv":0.0,"id":60443},{"batb":[[0,1.26,6.57],[1,1.25,80],[2,1.19,19.59]],"ltp":0.0,"tv":0.0,"id":31374}]}]}
{"op":"mcm","clk":"11906004893","pt":1723957015143,"mc":[{"id":"1.231851789","rc":[{"batb":[[0,1.27,31.7],[1,1.26,6.23],[2,1.25,80]],"ltp":0.0,"tv":0.0,"id":2780},{"batb":[[0,1.27,31.7],[1,1.26,6.58],[2,1.25,80]],"ltp":0.0,"tv":0.0,"id":60443},{"batb":[[0,1.27,31.7],[1,1.26,6.57],[2,1.25,80]],"ltp":0.0,"tv":0.0,"id":31374}]}]}
{"op":"mcm","clk":"11906019272","pt":1723957447387,"mc":[{"id":"1.231851789","rc":[{"batb":[[0,1.28,19.59],[1,1.27,31.7],[2,1.26,6.23]],"ltp":0.0,"tv":0.0,"id":2780},{"batb":[[0,1.28,19.59],[1,1.27,31.7],[2,1.26,6.58]],"ltp":0.0,"tv":0.0,"id":60443},{"batb":[[0,1.28,19.59],[1,1.27,31.7],[2,1.26,6.57]],"ltp":0.0,"tv":0.0,"id":31374}]}]}
{"op":"mcm","clk":"11906096739","pt":1723958815757,"mc":[{"id":"1.231851789","rc":[{"batb":[[1,1.26,6.23],[2,1.25,80]],"ltp":0.0,"tv":0.0,"id":2780},{"batb":[[1,1.26,6.58],[2,1.25,80]],"ltp":0.0,"tv":0.0,"id":60443},{"batb":[[1,1.26,6.57],[2,1.25,80]],"ltp":0.0,"tv":0.0,"id":31374}]}]}
{"op":"mcm","clk":"11906098209","pt":1723958850152,"mc":[{"id":"1.231851789","rc":[{"batb":[[1,1.25,80],[2,1.03,200]],"ltp":0.0,"tv":0.0,"id":31374}]}]}
{"op":"mcm","clk":"11906098228","pt":1723958850865,"mc":[{"id":"1.231851789","rc":[{"batb":[[1,1.25,80],[2,1.03,200]],"ltp":0.0,"tv":0.0,"id":2780},{"batb":[[1,1.25,80],[2,1.03,200]],"ltp":0.0,"tv":0.0,"id":60443}]}]}
{"op":"mcm","clk":"11906100362","pt":1723958898317,"mc":[{"id":"1.231851789","rc":[{"batb":[[0,1.29,29.52],[1,1.28,19.59],[2,1.25,80]],"ltp":0.0,"tv":0.0,"id":2780},{"batb":[[0,1.29,29.52],[1,1.28,19.59],[2,1.25,80]],"ltp":0.0,"tv":0.0,"id":60443},{"batb":[[0,1.29,29.52],[1,1.28,19.59],[2,1.25,80]],"ltp":0.0,"tv":0.0,"id":31374}]}]}
{"op":"mcm","clk":"11906176140","pt":1723960699212,"mc":[{"id":"1.231851789","rc":[{"batb":[[0,1.28,19.59],[1,1.25,80],[2,1.03,200]],"ltp":0.0,"tv":0.0,"id":2780},{"batb":[[0,1.28,19.59],[1,1.25,80],[2,1.03,200]],"ltp":0.0,"tv":0.0,"id":60443},{"batb":[[0,1.28,19.59],[1,1.25,80],[2,1.03,200]],"ltp":0.0,"tv":0.0,"id":31374}]}]}
{"op":"mcm","clk":"11906179549","pt":1723960773700,"mc":[{"id":"1.231851789","rc":[{"batb":[[0,1.29,29.52],[1,1.28,19.59],[2,1.25,80]],"ltp":0.0,"tv":0.0,"id":2780},{"batb":[[0,1.29,29.52],[1,1.28,19.59],[2,1.25,80]],"ltp":0.0,"tv":0.0,"id":60443},{"batb":[[0,1.29,29.52],[1,1.28,19.59],[2,1.25,80]],"ltp":0.0,"tv":0.0,"id":31374}]}]}
{"op":"mcm","clk":"11906229983","pt":1723961864840,"mc":[{"id":"1.231851789","rc":[{"batb":[[0,1.3,7.15],[1,1.29,29.52],[2,1.28,19.59]],"ltp":0.0,"tv":0.0,"id":2780},{"batb":[[0,1.3,7.31],[1,1.29,29.52],[2,1.28,19.59]],"ltp":0.0,"tv":0.0,"id":60443},{"batb":[[0,1.3,7.7],[1,1.29,29.52],[2,1.28,19.59]],"ltp":0.0,"tv":0.0,"id":31374}]}]}
{"op":"mcm","clk":"11906258397","pt":1723962574230,"mc":[{"id":"1.231851789","rc":[{"batb":[[1,1.28,19.59],[2,1.25,80]],"ltp":0.0,"tv":0.0,"id":60443},{"batb":[[1,1.28,19.59],[2,1.25,80]],"ltp":0.0,"tv":0.0,"id":31374}]}]}
{"op":"mcm","clk":"11906258404","pt":1723962574437,"mc":[{"id":"1.231851789","rc":[{"batb":[[1,1.28,19.59],[2,1.25,80]],"ltp":0.0,"tv":0.0,"id":2780}]}]}
{"op":"mcm","clk":"11906262217","pt":1723962652332,"mc":[{"id":"1.231851789","rc":[{"batb":[[0,1.31,27.61],[1,1.3,7.15],[2,1.28,19.59]],"ltp":0.0,"tv":0.0,"id":2780},{"batb":[[0,1.31,27.61],[1,1.3,7.31],[2,1.28,19.59]],"ltp":0.0,"tv":0.0,"id":60443},{"batb":[[0,1.31,27.61],[1,1.3,7.7],[2,1.28,19.59]],"ltp":0.0,"tv":0.0,"id":31374}]}]}
{"op":"mcm","clk":"11906362400","pt":1723964452978,"mc":[{"id":"1.231851789","rc":[{"batb":[[0,1.3,7.15],[1,1.28,19.59],[2,1.25,80]],"ltp":0.0,"tv":0.0,"id":2780},{"batb":[[0,1.3,7.31],[1,1.28,19.59],[2,1.25,80]],"ltp":0.0,"tv":0.0,"id":60443},{"batb":[[0,1.3,7.7],[1,1.28,19.59],[2,1.25,80]],"ltp":0.0,"tv":0.0,"id":31374}]}]}
{"op":"mcm","clk":"11906365642","pt":1723964523268,"mc":[{"id":"1.231851789","rc":[{"batb":[[0,1.31,27.61],[1,1.3,7.15],[2,1.28,19.59]],"ltp":0.0,"tv":0.0,"id":2780},{"batb":[[0,1.31,27.61],[1,1.3,7.31],[2,1.28,19.59]],"ltp":0.0,"tv":0.0,"id":60443},{"batb":[[0,1.31,27.61],[1,1.3,7.7],[2,1.28,19.59]],"ltp":0.0,"tv":0.0,"id":31374}]}]}
{"op":"mcm","clk":"11906379712","pt":1723964819289,"mc":[{"id":"1.231851789","rc":[{"batb":[[0,1.32,7.15],[1,1.31,27.61]],"ltp":0.0,"tv":0.0,"id":2780},{"batb":[[1,1.28,19.59],[2,1.25,80]],"ltp":0.0,"tv":0.0,"id":60443},{"batb":[[0,1.32,7.7],[1,1.31,27.61]],"ltp":0.0,"tv":0.0,"id":31374}]}]}
{"op":"mcm","clk":"11906379720","pt":1723964819408,"mc":[{"id":"1.231851789","rc":[{"batb":[[0,1.32,7.31],[1,1.31,27.61],[2,1.28,19.59]],"ltp":0.0,"tv":0.0,"id":60443}]}]}
{"op":"mcm","clk":"11906470026","pt":1723966323866,"mc":[{"id":"1.231851789","rc":[{"batb":[[1,1.28,19.59],[2,1.25,80]],"ltp":0.0,"tv":0.0,"id":2780},{"batb":[[1,1.28,19.59],[2,1.25,80]],"ltp":0.0,"tv":0.0,"id":60443},{"batb":[[1,1.28,19.59],[2,1.25,80]],"ltp":0.0,"tv":0.0,"id":31374}]}]}
{"op":"mcm","clk":"11906474998","pt":1723966396655,"mc":[{"id":"1.231851789","rc":[{"batb":[[0,1.33,25.94],[1,1.32,7.15],[2,1.28,19.59]],"ltp":0.0,"tv":0.0,"id":2780},{"batb":[[0,1.33,25.94],[1,1.32,7.31],[2,1.28,19.59]],"ltp":0.0,"tv":0.0,"id":60443},{"batb":[[0,1.33,25.94],[1,1.32,7.7],[2,1.28,19.59]],"ltp":0.0,"tv":0.0,"id":31374}]}]}
{"op":"mcm","clk":"11906573429","pt":1723967809304,"mc":[{"id":"1.231851789","rc":[{"batb":[[1,1.28,19.59],[2,1.25,80]],"ltp":0.0,"tv":0.0,"id":31374}]}]}
{"op":"mcm","clk":"11906573517","pt":1723967810289,"mc":[{"id":"1.231851789","rc":[{"batb":[[0,1.34,7.15],[1,1.33,25.94]],"ltp":0.0,"tv":0.0,"id":2780},{"batb":[[0,1.34,7.31],[1,1.33,25.94]],"ltp":0.0,"tv":0.0,"id":60443},{"batb":[[0,1.34,7.7],[1,1.33,25.94],[2,1.28,19.59]],"ltp":0.0,"tv":0.0,"id":31374}]}]}
{"op":"mcm","clk":"11906606335","pt":1723968197289,"mc":[{"id":"1.231851789","rc":[{"batb":[[1,1.28,19.59],[2,1.25,80]],"ltp":0.0,"tv":0.0,"id":2780},{"batb":[[1,1.28,19.59],[2,1.25,80]],"ltp":0.0,"tv":0.0,"id":60443},{"batb":[[1,1.28,19.59],[2,1.25,80]],"ltp":0.0,"tv":0.0,"id":31374}]}]}
{"op":"mcm","clk":"11906621478","pt":1723968375695,"mc":[{"id":"1.231851789","rc":[{"batb":[[0,1.35,24.46],[1,1.34,7.15],[2,1.28,19.59]],"ltp":0.0,"tv":0.0,"id":2780},{"batb":[[0,1.35,24.46],[1,1.34,7.31],[2,1.28,19.59]],"ltp":0.0,"tv":0.0,"id":60443},{"batb":[[0,1.35,24.46],[1,1.34,7.7],[2,1.28,19.59]],"ltp":0.0,"tv":0.0,"id":31374}]}]}
{"op":"mcm","clk":"11906703809","pt":1723969269081,"mc":[{"id":"1.231851789","rc":[{"batb":[[0,1.36,19.59],[1,1.35,24.46],[2,1.34,7.15]],"ltp":0.0,"tv":0.0,"id":2780},{"batb":[[0,1.36,19.59],[1,1.35,24.46],[2,1.34,7.31]],"ltp":0.0,"tv":0.0,"id":60443},{"batb":[[0,1.36,19.59],[1,1.35,24.46],[2,1.34,7.7]],"ltp":0.0,"tv":0.0,"id":31374}]}]}
{"op":"mcm","clk":"11906704323","pt":1723969275788,"mc":[{"id":"1.231851789","rc":[{"batb":[[0,1.36,9.37]],"ltp":0.0,"tv":0.0,"id":2780},{"batb":[[0,1.36,9.37]],"ltp":0.0,"tv":0.0,"id":31374}]}]}
{"op":"mcm","clk":"11906785681","pt":1723970176135,"mc":[{"id":"1.231851789","rc":[{"batb":[[1,1.34,7.31],[2,1.25,80]],"ltp":0.0,"tv":0.0,"id":60443},{"batb":[[1,1.34,7.7],[2,1.25,80]],"ltp":0.0,"tv":0.0,"id":31374}]}]}
{"op":"mcm","clk":"11906785707","pt":1723970176443,"mc":[{"id":"1.231851789","rc":[{"batb":[[1,1.34,7.15],[2,1.25,80]],"ltp":0.0,"tv":0.0,"id":2780}]}]}
{"op":"mcm","clk":"11906787178","pt":1723970191379,"mc":[{"id":"1.231851789","rc":[{"batb":[[0,1.37,23.13],[1,1.36,9.37],[2,1.34,7.15]],"ltp":0.0,"tv":0.0,"id":2780},{"batb":[[0,1.37,23.13],[1,1.36,19.59],[2,1.34,7.31]],"ltp":0.0,"tv":0.0,"id":60443},{"batb":[[0,1.37,23.13],[1,1.36,9.37],[2,1.34,7.7]],"ltp":0.0,"tv":0.0,"id":31374}]}]}
{"op":"mcm","clk":"11906846605","pt":1723970824293,"mc":[{"id":"1.231851789","rc":[{"batb":[[2,1.25,80]],"ltp":0.0,"tv":0.0,"id":2780},{"batb":[[2,1.26,7.7]],"ltp":0.0,"tv":0.0,"id":31374}]}]}
{"op":"mcm","clk":"11906846649","pt":1723970824802,"mc":[{"id":"1.231851789","rc":[{"batb":[[2,1.26,7.15]],"ltp":0.0,"tv":0.0,"id":2780},{"batb":[[2,1.26,7.31]],"ltp":0.0,"tv":0.0,"id":60443}]}]}
{"op":"mcm","clk":"11906969532","pt":1723971991862,"mc":[{"id":"1.231851789","rc":[{"batb":[[0,1.36,9.37],[1,1.26,7.15],[2,1.25,80]],"ltp":0.0,"tv":0.0,"id":2780},{"batb":[[0,1.36,19.59],[1,1.26,7.31],[2,1.25,80]],"ltp":0.0,"tv":0.0,"id":60443},{"batb":[[0,1.36,9.37],[1,1.26,7.7],[2,1.25,80]],"ltp":0.0,"tv":0.0,"id":31374}]}]}
{"op":"mcm","clk":"11906970941","pt":1723972003570,"mc":[{"id":"1.231851789","rc":[{"batb":[[0,1.37,23.13],[1,1.36,9.37],[2,1.26,7.15]],"ltp":0.0,"tv":0.0,"id":2780},{"batb":[[0,1.37,23.13],[1,1.36,19.59],[2,1.26,7.31]],"ltp":0.0,"tv":0.0,"id":60443},{"batb":[[0,1.37,23.13],[1,1.36,9.37],[2,1.26,7.7]],"ltp":0.0,"tv":0.0,"id":31374}]}]}
{"op":"mcm","clk":"11907164952","pt":1723973594226,"mc":[{"id":"1.231851789","rc":[{"batb":[[0,1.5,20],[1,1.37,23.13],[2,1.36,9.37]],"ltp":0.0,"tv":0.0,"id":31374}]}]}
{"op":"mcm","clk":"11907166083","pt":1723973603285,"mc":[{"id":"1.231851789","rc":[{"batb":[[0,1.5,20],[1,1.37,23.13],[2,1.36,9.37]],"ltp":0.0,"tv":0.0,"id":2780}]}]}
{"op":"mcm","clk":"11907167084","pt":1723973611667,"mc":[{"id":"1.231851789","rc":[{"batb":[[2,1.3,20]],"ltp":0.0,"tv":0.0,"id":60443}]}]}
{"op":"mcm","clk":"11907192234","pt":1723973804120,"mc":[{"id":"1.231851789","rc":[{"batb":[[1,1.36,9.37],[2,1.25,80]],"ltp":0.0,"tv":0.0,"id":2780},{"batb":[[0,1.36,19.59],[1,1.3,20],[2,1.25,80]],"ltp":0.0,"tv":0.0,"id":60443},{"batb":[[1,1.36,9.37],[2,1.25,80]],"ltp":0.0,"tv":0.0,"id":31374}]}]}
{"op":"mcm","clk":"11907192684","pt":1723973807589,"mc":[{"id":"1.231851789","rc":[{"batb":[[0,1.51,16.78],[1,1.5,20],[2,1.36,9.37]],"ltp":0.0,"tv":0.0,"id":2780},{"batb":[[0,1.37,23.13],[1,1.36,19.59],[2,1.3,20]],"ltp":0.0,"tv":0.0,"id":60443},{"batb":[[0,1.51,16.78],[1,1.5,20],[2,1.36,9.37]],"ltp":0.0,"tv":0.0,"id":31374}]}]}
{"op":"mcm","clk":"11907422620","pt":1723975608085,"mc":[{"id":"1.231851789","rc":[{"batb":[[0,1.5,20],[1,1.36,9.37],[2,1.25,80]],"ltp":0.0,"tv":0.0,"id":2780},{"batb":[[0,1.5,20],[1,1.36,9.37],[2,1.25,80]],"ltp":0.0,"tv":0.0,"id":31374}]}]}
{"op":"mcm","clk":"11907422652","pt":1723975608396,"mc":[{"id":"1.231851789","rc":[{"batb":[[0,1.36,19.59],[1,1.3,20],[2,1.25,80]],"ltp":0.0,"tv":0.0,"id":60443}]}]}
{"op":"mcm","clk":"11907444738","pt":1723975781568,"mc":[{"id":"1.231851789","rc":[{"batb":[[0,1.51,16.78],[1,1.5,20],[2,1.36,9.37]],"ltp":0.0,"tv":0.0,"id":2780},{"batb":[[0,1.37,23.13],[1,1.36,19.59],[2,1.3,20]],"ltp":0.0,"tv":0.0,"id":60443},{"batb":[[0,1.51,16.78],[1,1.5,20],[2,1.36,9.37]],"ltp":0.0,"tv":0.0,"id":31374}]}]}
{"op":"mcm","clk":"11907675825","pt":1723977582137,"mc":[{"id":"1.231851789","rc":[{"batb":[[0,1.5,20],[1,1.36,9.37],[2,1.25,80]],"ltp":0.0,"tv":0.0,"id":2780},{"batb":[[0,1.36,19.59],[1,1.3,20],[2,1.25,80]],"ltp":0.0,"tv":0.0,"id":60443},{"batb":[[0,1.5,20],[1,1.36,9.37],[2,1.25,80]],"ltp":0.0,"tv":0.0,"id":31374}]}]}
{"op":"mcm","clk":"11907694415","pt":1723977730504,"mc":[{"id":"1.231851789","rc":[{"batb":[[0,1.51,16.78],[1,1.5,20],[2,1.36,9.37]],"ltp":0.0,"tv":0.0,"id":2780},{"batb":[[0,1.37,23.13],[1,1.36,19.59],[2,1.3,20]],"ltp":0.0,"tv":0.0,"id":60443},{"batb":[[0,1.51,16.78],[1,1.5,20],[2,1.36,9.37]],"ltp":0.0,"tv":0.0,"id":31374}]}]}
{"op":"mcm","clk":"11907915017","pt":1723979531022,"mc":[{"id":"1.231851789","rc":[{"batb":[[0,1.5,20],[1,1.36,9.37],[2,1.25,80]],"ltp":0.0,"tv":0.0,"id":2780},{"batb":[[0,1.36,19.59],[1,1.3,20],[2,1.25,80]],"ltp":0.0,"tv":0.0,"id":60443},{"batb":[[0,1.5,20],[1,1.36,9.37],[2,1.25,80]],"ltp":0.0,"tv":0.0,"id":31374}]}]}
{"op":"mcm","clk":"11907939836","pt":1723979650070,"mc":[{"id":"1.231851789","rc":[{"batb":[[0,1.51,16.78],[1,1.5,20],[2,1.36,9.37]],"ltp":0.0,"tv":0.0,"id":2780},{"batb":[[0,1.37,23.13],[1,1.36,19.59],[2,1.3,20]],"ltp":0.0,"tv":0.0,"id":60443},{"batb":[[0,1.51,16.78],[1,1.5,20],[2,1.36,9.37]],"ltp":0.0,"tv":0.0,"id":31374}]}]}
{"op":"mcm","clk":"11908174030","pt":1723981450282,"mc":[{"id":"1.231851789","rc":[{"batb":[[0,1.36,19.59],[1,1.3,20],[2,1.25,80]],"ltp":0.0,"tv":0.0,"id":60443}]}]}
{"op":"mcm","clk":"11908174075","pt":1723981450699,"mc":[{"id":"1.231851789","rc":[{"batb":[[0,1.5,20],[1,1.36,9.37],[2,1.25,80]],"ltp":0.0,"tv":0.0,"id":2780},{"batb":[[0,1.5,20],[1,1.36,9.37],[2,1.25,80]],"ltp":0.0,"tv":0.0,"id":31374}]}]}
{"op":"mcm","clk":"11908185746","pt":1723981542165,"mc":[{"id":"1.231851789","rc":[{"batb":[[0,1.51,16.78],[1,1.5,20],[2,1.36,9.37]],"ltp":0.0,"tv":0.0,"id":2780},{"batb":[[0,1.37,23.13],[1,1.36,19.59],[2,1.3,20]],"ltp":0.0,"tv":0.0,"id":60443},{"batb":[[0,1.51,16.78],[1,1.5,20],[2,1.36,9.37]],"ltp":0.0,"tv":0.0,"id":31374}]}]}
{"op":"mcm","clk":"11908415413","pt":1723983342282,"mc":[{"id":"1.231851789","rc":[{"batb":[[0,1.36,19.59],[1,1.3,20],[2,1.25,80]],"ltp":0.0,"tv":0.0,"id":60443}]}]}
{"op":"mcm","clk":"11908415512","pt":1723983342815,"mc":[{"id":"1.231851789","rc":[{"batb":[[0,1.5,20],[1,1.36,9.37],[2,1.25,80]],"ltp":0.0,"tv":0.0,"id":2780},{"batb":[[0,1.5,20],[1,1.36,9.37],[2,1.25,80]],"ltp":0.0,"tv":0.0,"id":31374}]}]}
{"op":"mcm","clk":"11908427044","pt":1723983413817,"mc":[{"id":"1.231851789","rc":[{"batb":[[0,1.51,16.78],[1,1.5,20],[2,1.36,9.37]],"ltp":0.0,"tv":0.0,"id":2780},{"batb":[[0,1.37,23.13],[1,1.36,19.59],[2,1.3,20]],"ltp":0.0,"tv":0.0,"id":60443},{"batb":[[0,1.51,16.78],[1,1.5,20],[2,1.36,9.37]],"ltp":0.0,"tv":0.0,"id":31374}]}]}
{"op":"mcm","clk":"11908721577","pt":1723985214187,"mc":[{"id":"1.231851789","rc":[{"batb":[[0,1.36,19.59],[1,1.3,20],[2,1.25,80]],"ltp":0.0,"tv":0.0,"id":60443},{"batb":[[0,1.5,20],[1,1.36,9.37],[2,1.25,80]],"ltp":0.0,"tv":0.0,"id":31374}]}]}
{"op":"mcm","clk":"11908721608","pt":1723985214398,"mc":[{"id":"1.231851789","rc":[{"batb":[[0,1.5,20],[1,1.36,9.37],[2,1.25,80]],"ltp":0.0,"tv":0.0,"id":2780}]}]}
{"op":"mcm","clk":"11908729420","pt":1723985265767,"mc":[{"id":"1.231851789","rc":[{"batb":[[0,1.51,16.78],[1,1.5,20],[2,1.36,9.37]],"ltp":0.0,"tv":0.0,"id":2780},{"batb":[[0,1.37,23.13],[1,1.36,19.59],[2,1.3,20]],"ltp":0.0,"tv":0.0,"id":60443},{"batb":[[0,1.51,16.78],[1,1.5,20],[2,1.36,9.37]],"ltp":0.0,"tv":0.0,"id":31374}]}]}
{"op":"mcm","clk":"11908975900","pt":1723987066101,"mc":[{"id":"1.231851789","rc":[{"batb":[[0,1.5,20],[1,1.36,9.37],[2,1.25,80]],"ltp":0.0,"tv":0.0,"id":2780},{"batb":[[0,1.5,20],[1,1.36,9.37],[2,1.25,80]],"ltp":0.0,"tv":0.0,"id":31374}]}]}
{"op":"mcm","clk":"11908975939","pt":1723987066313,"mc":[{"id":"1.231851789","rc":[{"batb":[[0,1.36,19.59],[1,1.3,20],[2,1.25,80]],"ltp":0.0,"tv":0.0,"id":60443}]}]}
{"op":"mcm","clk":"11908978584","pt":1723987082625,"mc":[{"id":"1.231851789","rc":[{"batb":[[0,1.51,16.78],[1,1.5,20],[2,1.36,9.37]],"ltp":0.0,"tv":0.0,"id":2780},{"batb":[[0,1.37,23.13],[1,1.36,19.59],[2,1.3,20]],"ltp":0.0,"tv":0.0,"id":60443},{"batb":[[0,1.51,16.78],[1,1.5,20],[2,1.36,9.37]],"ltp":0.0,"tv":0.0,"id":31374}]}]}
{"op":"mcm","clk":"11909190192","pt":1723988407888,"mc":[{"id":"1.231851789","rc":[{"batb":[[2,1.25,80]],"ltp":0.0,"tv":0.0,"id":2780},{"batb":[[0,1.38,19.59],[1,1.37,23.13]],"ltp":0.0,"tv":0.0,"id":60443},{"batb":[[2,1.25,80]],"ltp":0.0,"tv":0.0,"id":31374}]}]}
{"op":"mcm","clk":"11909273485","pt":1723988883116,"mc":[{"id":"1.231851789","rc":[{"batb":[[0,1.5,20],[1,1.25,80],[2,1.03,200]],"ltp":0.0,"tv":0.0,"id":2780},{"batb":[[1,1.3,20],[2,1.25,80]],"ltp":0.0,"tv":0.0,"id":60443},{"batb":[[0,1.5,20],[1,1.25,80],[2,1.03,200]],"ltp":0.0,"tv":0.0,"id":31374}]}]}
{"op":"mcm","clk":"11909294444","pt":1723989024527,"mc":[{"id":"1.231851789","rc":[{"batb":[[0,1.51,16.78],[1,1.5,20],[2,1.25,80]],"ltp":0.0,"tv":0.0,"id":2780},{"batb":[[0,1.39,21.95],[1,1.38,19.59],[2,1.3,20]],"ltp":0.0,"tv":0.0,"id":60443},{"batb":[[0,1.51,16.78],[1,1.5,20],[2,1.25,80]],"ltp":0.0,"tv":0.0,"id":31374}]}]}
{"op":"mcm","clk":"11909551350","pt":1723990825256,"mc":[{"id":"1.231851789","rc":[{"batb":[[0,1.5,20],[1,1.25,80],[2,1.03,200]],"ltp":0.0,"tv":0.0,"id":2780},{"batb":[[0,1.38,19.59],[1,1.3,20],[2,1.25,80]],"ltp":0.0,"tv":0.0,"id":60443},{"batb":[[0,1.5,20],[1,1.25,80],[2,1.03,200]],"ltp":0.0,"tv":0.0,"id":31374}]}]}
{"op":"mcm","clk":"11909563454","pt":1723990908029,"mc":[{"id":"1.231851789","rc":[{"batb":[[0,1.51,16.78],[1,1.5,20],[2,1.25,80]],"ltp":0.0,"tv":0.0,"id":2780},{"batb":[[0,1.39,21.95],[1,1.38,19.59],[2,1.3,20]],"ltp":0.0,"tv":0.0,"id":60443},{"batb":[[0,1.51,16.78],[1,1.5,20],[2,1.25,80]],"ltp":0.0,"tv":0.0,"id":31374}]}]}
{"op":"mcm","clk":"11909855115","pt":1723992708279,"mc":[{"id":"1.231851789","rc":[{"batb":[[0,1.5,20],[1,1.25,80],[2,1.03,200]],"ltp":0.0,"tv":0.0,"id":31374}]}]}
{"op":"mcm","clk":"11909855165","pt":1723992708595,"mc":[{"id":"1.231851789","rc":[{"batb":[[0,1.5,20],[1,1.25,80],[2,1.03,200]],"ltp":0.0,"tv":0.0,"id":2780},{"batb":[[0,1.38,19.59],[1,1.3,20],[2,1.25,80]],"ltp":0.0,"tv":0.0,"id":60443}]}]}
{"op":"mcm","clk":"11909874154","pt":1723992838514,"mc":[{"id":"1.231851789","rc":[{"batb":[[0,1.51,16.78],[1,1.5,20],[2,1.25,80]],"ltp":0.0,"tv":0.0,"id":2780},{"batb":[[0,1.39,21.95],[1,1.38,19.59],[2,1.3,20]],"ltp":0.0,"tv":0.0,"id":60443},{"batb":[[0,1.51,16.78],[1,1.5,20],[2,1.25,80]],"ltp":0.0,"tv":0.0,"id":31374}]}]}
{"op":"mcm","clk":"11910197069","pt":1723994639105,"mc":[{"id":"1.231851789","rc":[{"batb":[[0,1.5,20],[1,1.25,80],[2,1.03,200]],"ltp":0.0,"tv":0.0,"id":2780},{"batb":[[0,1.38,19.59],[1,1.3,20],[2,1.25,80]],"ltp":0.0,"tv":0.0,"id":60443},{"batb":[[0,1.5,20],[1,1.25,80],[2,1.03,200]],"ltp":0.0,"tv":0.0,"id":31374}]}]}
{"op":"mcm","clk":"11910211252","pt":1723994718047,"mc":[{"id":"1.231851789","rc":[{"batb":[[0,1.51,16.78],[1,1.5,20],[2,1.25,80]],"ltp":0.0,"tv":0.0,"id":2780},{"batb":[[0,1.39,21.95],[1,1.38,19.59],[2,1.3,20]],"ltp":0.0,"tv":0.0,"id":60443},{"batb":[[0,1.51,16.78],[1,1.5,20],[2,1.25,80]],"ltp":0.0,"tv":0.0,"id":31374}]}]}
{"op":"mcm","clk":"11910575942","pt":1723996518274,"mc":[{"id":"1.231851789","rc":[{"batb":[[0,1.5,20],[1,1.25,80],[2,1.03,200]],"ltp":0.0,"tv":0.0,"id":2780},{"batb":[[0,1.5,20],[1,1.25,80],[2,1.03,200]],"ltp":0.0,"tv":0.0,"id":31374}]}]}
{"op":"mcm","clk":"11910575963","pt":1723996518426,"mc":[{"id":"1.231851789","rc":[{"batb":[[0,1.38,19.59],[1,1.3,20],[2,1.25,80]],"ltp":0.0,"tv":0.0,"id":60443}]}]}
{"op":"mcm","clk":"11910587837","pt":1723996588608,"mc":[{"id":"1.231851789","rc":[{"batb":[[0,1.51,16.78],[1,1.5,20],[2,1.25,80]],"ltp":0.0,"tv":0.0,"id":2780},{"batb":[[0,1.39,21.95],[1,1.38,19.59],[2,1.3,20]],"ltp":0.0,"tv":0.0,"id":60443},{"batb":[[0,1.51,16.78],[1,1.5,20],[2,1.25,80]],"ltp":0.0,"tv":0.0,"id":31374}]}]}
{"op":"mcm","clk":"11910940811","pt":1723998388942,"mc":[{"id":"1.231851789","rc":[{"batb":[[0,1.5,20],[1,1.25,80],[2,1.03,200]],"ltp":0.0,"tv":0.0,"id":2780},{"batb":[[0,1.38,19.59],[1,1.3,20],[2,1.25,80]],"ltp":0.0,"tv":0.0,"id":60443},{"batb":[[0,1.5,20],[1,1.25,80],[2,1.03,200]],"ltp":0.0,"tv":0.0,"id":31374}]}]}
{"op":"mcm","clk":"11910942909","pt":1723998400232,"mc":[{"id":"1.231851789","rc":[{"batb":[[0,1.51,16.78],[1,1.5,20],[2,1.25,80]],"ltp":0.0,"tv":0.0,"id":2780},{"batb":[[0,1.39,21.95],[1,1.38,19.59],[2,1.3,20]],"ltp":0.0,"tv":0.0,"id":60443},{"batb":[[0,1.51,16.78],[1,1.5,20],[2,1.25,80]],"ltp":0.0,"tv":0.0,"id":31374}]}]}
{"op":"mcm","clk":"11911282602","pt":1724000200900,"mc":[{"id":"1.231851789","rc":[{"batb":[[0,1.5,20],[1,1.25,80],[2,1.03,200]],"ltp":0.0,"tv":0.0,"id":2780},{"batb":[[0,1.38,19.59],[1,1.3,20],[2,1.25,80]],"ltp":0.0,"tv":0.0,"id":60443},{"batb":[[0,1.5,20],[1,1.25,80],[2,1.03,200]],"ltp":0.0,"tv":0.0,"id":31374}]}]}
{"op":"mcm","clk":"11911300342","pt":1724000324145,"mc":[{"id":"1.231851789","rc":[{"batb":[[0,1.51,16.78],[1,1.5,20],[2,1.25,80]],"ltp":0.0,"tv":0.0,"id":2780},{"batb":[[0,1.39,21.95],[1,1.38,19.59],[2,1.3,20]],"ltp":0.0,"tv":0.0,"id":60443},{"batb":[[0,1.51,16.78],[1,1.5,20],[2,1.25,80]],"ltp":0.0,"tv":0.0,"id":31374}]}]}
{"op":"mcm","clk":"11911574298","pt":1724002124770,"mc":[{"id":"1.231851789","rc":[{"batb":[[0,1.5,20],[1,1.25,80],[2,1.03,200]],"ltp":0.0,"tv":0.0,"id":2780},{"batb":[[0,1.38,19.59],[1,1.3,20],[2,1.25,80]],"ltp":0.0,"tv":0.0,"id":60443},{"batb":[[0,1.5,20],[1,1.25,80],[2,1.03,200]],"ltp":0.0,"tv":0.0,"id":31374}]}]}
{"op":"mcm","clk":"11911575027","pt":1724002130692,"mc":[{"id":"1.231851789","rc":[{"batb":[[0,1.51,16.78],[1,1.5,20],[2,1.25,80]],"ltp":0.0,"tv":0.0,"id":2780},{"batb":[[0,1.39,21.95],[1,1.38,19.59],[2,1.3,20]],"ltp":0.0,"tv":0.0,"id":60443},{"batb":[[0,1.51,16.78],[1,1.5,20],[2,1.25,80]],"ltp":0.0,"tv":0.0,"id":31374}]}]}
{"op":"mcm","clk":"11911817072","pt":1724003931043,"mc":[{"id":"1.231851789","rc":[{"batb":[[0,1.5,20],[1,1.25,80],[2,1.03,200]],"ltp":0.0,"tv":0.0,"id":2780},{"batb":[[0,1.38,19.59],[1,1.3,20],[2,1.25,80]],"ltp":0.0,"tv":0.0,"id":60443},{"batb":[[0,1.5,20],[1,1.25,80],[2,1.03,200]],"ltp":0.0,"tv":0.0,"id":31374}]}]}
{"op":"mcm","clk":"11911826708","pt":1724004010795,"mc":[{"id":"1.231851789","rc":[{"batb":[[0,1.51,16.78],[1,1.5,20],[2,1.25,80]],"ltp":0.0,"tv":0.0,"id":2780},{"batb":[[0,1.39,21.95],[1,1.38,19.59],[2,1.3,20]],"ltp":0.0,"tv":0.0,"id":60443},{"batb":[[0,1.51,16.78],[1,1.5,20],[2,1.25,80]],"ltp":0.0,"tv":0.0,"id":31374}]}]}
{"op":"mcm","clk":"11912139398","pt":1724005811233,"mc":[{"id":"1.231851789","rc":[{"batb":[[0,1.5,20],[1,1.25,80],[2,1.03,200]],"ltp":0.0,"tv":0.0,"id":2780},{"batb":[[0,1.5,20],[1,1.25,80],[2,1.03,200]],"ltp":0.0,"tv":0.0,"id":31374}]}]}
{"op":"mcm","clk":"11912139619","pt":1724005812203,"mc":[{"id":"1.231851789","rc":[{"batb":[[0,1.51,16.78],[1,1.5,20],[2,1.25,80]],"ltp":0.0,"tv":0.0,"id":2780},{"batb":[[0,1.51,16.78],[1,1.5,20],[2,1.25,80]],"ltp":0.0,"tv":0.0,"id":31374}]}]}
{"op":"mcm","clk":"11912478286","pt":1724007612878,"mc":[{"id":"1.231851789","rc":[{"batb":[[0,1.5,20],[1,1.25,80],[2,1.03,200]],"ltp":0.0,"tv":0.0,"id":2780},{"batb":[[0,1.38,19.59],[1,1.3,20],[2,1.25,80]],"ltp":0.0,"tv":0.0,"id":60443},{"batb":[[0,1.5,20],[1,1.25,80],[2,1.03,200]],"ltp":0.0,"tv":0.0,"id":31374}]}]}
{"op":"mcm","clk":"11912488997","pt":1724007674061,"mc":[{"id":"1.231851789","rc":[{"batb":[[0,1.51,16.78],[1,1.5,20],[2,1.25,80]],"ltp":0.0,"tv":0.0,"id":2780},{"batb":[[0,1.39,21.95],[1,1.38,19.59],[2,1.3,20]],"ltp":0.0,"tv":0.0,"id":60443},{"batb":[[0,1.51,16.78],[1,1.5,20],[2,1.25,80]],"ltp":0.0,"tv":0.0,"id":31374}]}]}
{"op":"mcm","clk":"11912621595","pt":1724008399408,"mc":[{"id":"1.231851789","rc":[{"batb":[[2,1.03,200]],"ltp":0.0,"tv":0.0,"id":2780}]}]}
{"op":"mcm","clk":"11912621828","pt":1724008400624,"mc":[{"id":"1.231851789","rc":[{"batb":[[2,1.03,200]],"ltp":0.0,"tv":0.0,"id":31374}]}]}
{"op":"mcm","clk":"11912622085","pt":1724008402002,"mc":[{"id":"1.231851789","rc":[{"batb":[[2,1.1,200]],"ltp":0.0,"tv":0.0,"id":31374}]}]}
{"op":"mcm","clk":"11912622267","pt":1724008403005,"mc":[{"id":"1.231851789","rc":[{"batb":[[2,1.1,200]],"ltp":0.0,"tv":0.0,"id":2780}]}]}
{"op":"mcm","clk":"11912823658","pt":1724009474294,"mc":[{"id":"1.231851789","rc":[{"batb":[[0,1.5,20],[1,1.1,200],[2,1.03,200]],"ltp":0.0,"tv":0.0,"id":2780}]}]}
{"op":"mcm","clk":"11912823728","pt":1724009474706,"mc":[{"id":"1.231851789","rc":[{"batb":[[0,1.38,19.59],[1,1.3,20],[2,1.1,200]],"ltp":0.0,"tv":0.0,"id":60443},{"batb":[[0,1.5,20],[1,1.1,200],[2,1.03,200]],"ltp":0.0,"tv":0.0,"id":31374}]}]}
{"op":"mcm","clk":"11912839457","pt":1724009560179,"mc":[{"id":"1.231851789","rc":[{"batb":[[0,1.51,16.78],[1,1.5,20],[2,1.1,200]],"ltp":0.0,"tv":0.0,"id":2780},{"batb":[[0,1.39,21.95],[1,1.38,19.59],[2,1.3,20]],"ltp":0.0,"tv":0.0,"id":60443},{"batb":[[0,1.51,16.78],[1,1.5,20],[2,1.1,200]],"ltp":0.0,"tv":0.0,"id":31374}]}]}
{"op":"mcm","clk":"11913135596","pt":1724011360743,"mc":[{"id":"1.231851789","rc":[{"batb":[[0,1.5,20],[1,1.1,200],[2,1.03,200]],"batl":[[0,95,5.85]],"ltp":0.0,"tv":0.0,"id":2780},{"batb":[[0,1.38,19.62],[1,1.3,20],[2,1.1,200]],"batl":[[0,95,5.85]],"ltp":0.0,"tv":0.0,"id":60443},{"batb":[[0,1.5,20],[1,1.1,200],[2,1.03,200]],"batl":[[0,95,5.85]],"ltp":0.0,"tv":0.0,"id":31374}]}]}
{"op":"mcm","clk":"11913140383","pt":1724011399295,"mc":[{"id":"1.231851789","rc":[{"batb":[[0,1.51,16.81],[1,1.5,20],[2,1.1,200]],"ltp":0.0,"tv":0.0,"id":2780},{"batb":[[0,1.39,21.99],[1,1.38,19.62],[2,1.3,20]],"ltp":0.0,"tv":0.0,"id":60443},{"batb":[[0,1.51,16.81],[1,1.5,20],[2,1.1,200]],"ltp":0.0,"tv":0.0,"id":31374}]}]}
{"op":"mcm","clk":"11913388187","pt":1724013200107,"mc":[{"id":"1.231851789","rc":[{"batb":[[0,1.5,20],[1,1.1,200],[2,1.03,200]],"ltp":0.0,"tv":0.0,"id":2780},{"batb":[[0,1.38,19.62],[1,1.3,20],[2,1.1,200]],"ltp":0.0,"tv":0.0,"id":60443},{"batb":[[0,1.5,20],[1,1.1,200],[2,1.03,200]],"ltp":0.0,"tv":0.0,"id":31374}]}]}
{"op":"mcm","clk":"11913401420","pt":1724013308046,"mc":[{"id":"1.231851789","rc":[{"batb":[[0,1.51,16.81],[1,1.5,20],[2,1.1,200]],"ltp":0.0,"tv":0.0,"id":2780},{"batb":[[0,1.39,21.99],[1,1.38,19.62],[2,1.3,20]],"ltp":0.0,"tv":0.0,"id":60443},{"batb":[[0,1.51,16.81],[1,1.5,20],[2,1.1,200]],"ltp":0.0,"tv":0.0,"id":31374}]}]}
{"op":"mcm","clk":"11913564538","pt":1724015108837,"mc":[{"id":"1.231851789","rc":[{"batb":[[0,1.5,20],[1,1.1,200],[2,1.03,200]],"ltp":0.0,"tv":0.0,"id":2780},{"batb":[[0,1.38,19.61],[1,1.3,20],[2,1.1,200]],"ltp":0.0,"tv":0.0,"id":60443},{"batb":[[0,1.5,20],[1,1.1,200],[2,1.03,200]],"ltp":0.0,"tv":0.0,"id":31374}]}]}
{"op":"mcm","clk":"11913569447","pt":1724015177090,"mc":[{"id":"1.231851789","rc":[{"batb":[[0,1.51,16.8],[1,1.5,20],[2,1.1,200]],"ltp":0.0,"tv":0.0,"id":2780},{"batb":[[0,1.39,21.97],[1,1.38,19.61],[2,1.3,20]],"ltp":0.0,"tv":0.0,"id":60443},{"batb":[[0,1.51,16.8],[1,1.5,20],[2,1.1,200]],"ltp":0.0,"tv":0.0,"id":31374}]}]}
{"op":"mcm","clk":"11913683627","pt":1724016977780,"mc":[{"id":"1.231851789","rc":[{"batb":[[0,1.5,20],[1,1.1,200],[2,1.03,200]],"ltp":0.0,"tv":0.0,"id":2780},{"batb":[[0,1.38,19.61],[1,1.3,20],[2,1.1,200]],"ltp":0.0,"tv":0.0,"id":60443},{"batb":[[0,1.5,20],[1,1.1,200],[2,1.03,200]],"ltp":0.0,"tv":0.0,"id":31374}]}]}
{"op":"mcm","clk":"11913689288","pt":1724017064578,"mc":[{"id":"1.231851789","rc":[{"batb":[[0,1.51,16.8],[1,1.5,20],[2,1.1,200]],"ltp":0.0,"tv":0.0,"id":2780},{"batb":[[0,1.39,21.97],[1,1.38,19.61],[2,1.3,20]],"ltp":0.0,"tv":0.0,"id":60443},{"batb":[[0,1.51,16.8],[1,1.5,20],[2,1.1,200]],"ltp":0.0,"tv":0.0,"id":31374}]}]}
{"op":"mcm","clk":"11913817647","pt":1724018865234,"mc":[{"id":"1.231851789","rc":[{"batb":[[0,1.5,20],[1,1.1,200],[2,1.03,200]],"ltp":0.0,"tv":0.0,"id":2780},{"batb":[[0,1.38,19.59],[1,1.3,20],[2,1.1,200]],"ltp":0.0,"tv":0.0,"id":60443},{"batb":[[0,1.5,20],[1,1.1,200],[2,1.03,200]],"ltp":0.0,"tv":0.0,"id":31374}]}]}
{"op":"mcm","clk":"11913820165","pt":1724018908459,"mc":[{"id":"1.231851789","rc":[{"batb":[[0,1.51,16.79],[1,1.5,20],[2,1.1,200]],"ltp":0.0,"tv":0.0,"id":2780},{"batb":[[0,1.39,21.96],[1,1.38,19.59],[2,1.3,20]],"ltp":0.0,"tv":0.0,"id":60443},{"batb":[[0,1.51,16.79],[1,1.5,20],[2,1.1,200]],"ltp":0.0,"tv":0.0,"id":31374}]}]}
{"op":"mcm","clk":"11913919055","pt":1724020709006,"mc":[{"id":"1.231851789","rc":[{"batb":[[0,1.5,20],[1,1.1,200],[2,1.03,200]],"ltp":0.0,"tv":0.0,"id":2780},{"batb":[[0,1.38,19.59],[1,1.3,20],[2,1.1,200]],"ltp":0.0,"tv":0.0,"id":60443},{"batb":[[0,1.5,20],[1,1.1,200],[2,1.03,200]],"ltp":0.0,"tv":0.0,"id":31374}]}]}
{"op":"mcm","clk":"11913920817","pt":1724020731213,"mc":[{"id":"1.231851789","rc":[{"batb":[[0,1.51,16.79],[1,1.5,20],[2,1.1,200]],"ltp":0.0,"tv":0.0,"id":2780},{"batb":[[0,1.39,21.96],[1,1.38,19.59],[2,1.3,20]],"ltp":0.0,"tv":0.0,"id":60443},{"batb":[[0,1.51,16.79],[1,1.5,20],[2,1.1,200]],"ltp":0.0,"tv":0.0,"id":31374}]}]}
{"op":"mcm","clk":"11914008597","pt":1724022531772,"mc":[{"id":"1.231851789","rc":[{"batb":[[0,1.5,20],[1,1.1,200],[2,1.03,200]],"ltp":0.0,"tv":0.0,"id":2780},{"batb":[[0,1.38,19.59],[1,1.3,20],[2,1.1,200]],"ltp":0.0,"tv":0.0,"id":60443},{"batb":[[0,1.5,20],[1,1.1,200],[2,1.03,200]],"ltp":0.0,"tv":0.0,"id":31374}]}]}
{"op":"mcm","clk":"11914014275","pt":1724022652530,"mc":[{"id":"1.231851789","rc":[{"batb":[[0,1.51,16.79],[1,1.5,20],[2,1.1,200]],"ltp":0.0,"tv":0.0,"id":2780},{"batb":[[0,1.39,21.96],[1,1.38,19.59],[2,1.3,20]],"ltp":0.0,"tv":0.0,"id":60443},{"batb":[[0,1.51,16.79],[1,1.5,20],[2,1.1,200]],"ltp":0.0,"tv":0.0,"id":31374}]}]}
{"op":"mcm","clk":"11914120228","pt":1724024453086,"mc":[{"id":"1.231851789","rc":[{"batb":[[0,1.5,20],[1,1.1,200],[2,1.03,200]],"ltp":0.0,"tv":0.0,"id":2780},{"batb":[[0,1.38,19.59],[1,1.3,20],[2,1.1,200]],"ltp":0.0,"tv":0.0,"id":60443},{"batb":[[0,1.5,20],[1,1.1,200],[2,1.03,200]],"ltp":0.0,"tv":0.0,"id":31374}]}]}
{"op":"mcm","clk":"11914124455","pt":1724024532674,"mc":[{"id":"1.231851789","rc":[{"batb":[[0,1.51,16.79],[1,1.5,20],[2,1.1,200]],"ltp":0.0,"tv":0.0,"id":2780},{"batb":[[0,1.39,21.96],[1,1.38,19.59],[2,1.3,20]],"ltp":0.0,"tv":0.0,"id":60443},{"batb":[[0,1.51,16.79],[1,1.5,20],[2,1.1,200]],"ltp":0.0,"tv":0.0,"id":31374}]}]}
{"op":"mcm","clk":"11914212765","pt":1724026333234,"mc":[{"id":"1.231851789","rc":[{"batb":[[0,1.5,20],[1,1.1,200],[2,1.03,200]],"ltp":0.0,"tv":0.0,"id":2780},{"batb":[[0,1.38,19.59],[1,1.3,20],[2,1.1,200]],"ltp":0.0,"tv":0.0,"id":60443},{"batb":[[0,1.5,20],[1,1.1,200],[2,1.03,200]],"ltp":0.0,"tv":0.0,"id":31374}]}]}
{"op":"mcm","clk":"11914214774","pt":1724026381154,"mc":[{"id":"1.231851789","rc":[{"batb":[[0,1.51,16.79],[1,1.5,20],[2,1.1,200]],"ltp":0.0,"tv":0.0,"id":2780},{"batb":[[0,1.39,21.95],[1,1.38,19.59],[2,1.3,20]],"ltp":0.0,"tv":0.0,"id":60443},{"batb":[[0,1.51,16.79],[1,1.5,20],[2,1.1,200]],"ltp":0.0,"tv":0.0,"id":31374}]}]}
{"op":"mcm","clk":"11914305226","pt":1724028181735,"mc":[{"id":"1.231851789","rc":[{"batb":[[0,1.5,20],[1,1.1,200],[2,1.03,200]],"ltp":0.0,"tv":0.0,"id":2780},{"batb":[[0,1.38,19.59],[1,1.3,20],[2,1.1,200]],"ltp":0.0,"tv":0.0,"id":60443},{"batb":[[0,1.5,20],[1,1.1,200],[2,1.03,200]],"ltp":0.0,"tv":0.0,"id":31374}]}]}
{"op":"mcm","clk":"11914306548","pt":1724028212476,"mc":[{"id":"1.231851789","rc":[{"batb":[[0,1.51,16.79],[1,1.5,20],[2,1.1,200]],"ltp":0.0,"tv":0.0,"id":2780},{"batb":[[0,1.39,21.95],[1,1.38,19.59],[2,1.3,20]],"ltp":0.0,"tv":0.0,"id":60443},{"batb":[[0,1.51,16.79],[1,1.5,20],[2,1.1,200]],"ltp":0.0,"tv":0.0,"id":31374}]}]}
{"op":"mcm","clk":"11914384316","pt":1724030013131,"mc":[{"id":"1.231851789","rc":[{"batb":[[0,1.5,20],[1,1.1,200],[2,1.03,200]],"ltp":0.0,"tv":0.0,"id":2780},{"batb":[[0,1.38,19.6],[1,1.3,20],[2,1.1,200]],"ltp":0.0,"tv":0.0,"id":60443},{"batb":[[0,1.5,20],[1,1.1,200],[2,1.03,200]],"ltp":0.0,"tv":0.0,"id":31374}]}]}
{"op":"mcm","clk":"11914384672","pt":1724030027064,"mc":[{"id":"1.231851789","rc":[{"batb":[[0,1.51,16.8],[1,1.5,20],[2,1.1,200]],"ltp":0.0,"tv":0.0,"id":2780},{"batb":[[0,1.39,21.96],[1,1.38,19.6],[2,1.3,20]],"ltp":0.0,"tv":0.0,"id":60443},{"batb":[[0,1.51,16.8],[1,1.5,20],[2,1.1,200]],"ltp":0.0,"tv":0.0,"id":31374}]}]}
{"op":"mcm","clk":"11914426911","pt":1724031827166,"mc":[{"id":"1.231851789","rc":[{"batb":[[0,1.5,20],[1,1.1,200],[2,1.03,200]],"ltp":0.0,"tv":0.0,"id":31374}]}]}
{"op":"mcm","clk":"11914426921","pt":1724031827578,"mc":[{"id":"1.231851789","rc":[{"batb":[[0,1.5,20],[1,1.1,200],[2,1.03,200]],"ltp":0.0,"tv":0.0,"id":2780},{"batb":[[0,1.38,19.6],[1,1.3,20],[2,1.1,200]],"ltp":0.0,"tv":0.0,"id":60443}]}]}
{"op":"mcm","clk":"11914429407","pt":1724031933686,"mc":[{"id":"1.231851789","rc":[{"batb":[[0,1.51,16.8],[1,1.5,20],[2,1.1,200]],"ltp":0.0,"tv":0.0,"id":2780},{"batb":[[0,1.39,21.96],[1,1.38,19.6],[2,1.3,20]],"ltp":0.0,"tv":0.0,"id":60443},{"batb":[[0,1.51,16.8],[1,1.5,20],[2,1.1,200]],"ltp":0.0,"tv":0.0,"id":31374}]}]}
{"op":"mcm","clk":"11914480817","pt":1724033575019,"mc":[{"id":"1.231851789","rc":[{"batb":[[0,1.51,16.79]],"ltp":0.0,"tv":0.0,"id":2780},{"batb":[[0,1.39,21.95],[1,1.38,19.59]],"ltp":0.0,"tv":0.0,"id":60443},{"batb":[[0,1.51,16.79]],"ltp":0.0,"tv":0.0,"id":31374}]}]}
{"op":"mcm","clk":"11914490094","pt":1724033734222,"mc":[{"id":"1.231851789","rc":[{"batb":[[0,1.5,20],[1,1.1,200],[2,1.03,200]],"ltp":0.0,"tv":0.0,"id":2780},{"batb":[[0,1.38,19.59],[1,1.3,20],[2,1.1,200]],"ltp":0.0,"tv":0.0,"id":60443}]}]}
{"op":"mcm","clk":"11914490107","pt":1724033734426,"mc":[{"id":"1.231851789","rc":[{"batb":[[0,1.5,20],[1,1.1,200],[2,1.03,200]],"ltp":0.0,"tv":0.0,"id":31374}]}]}
{"op":"mcm","clk":"11914493136","pt":1724033828043,"mc":[{"id":"1.231851789","rc":[{"batb":[[0,1.51,16.79],[1,1.5,20],[2,1.1,200]],"ltp":0.0,"tv":0.0,"id":2780},{"batb":[[0,1.39,21.95],[1,1.38,19.59],[2,1.3,20]],"ltp":0.0,"tv":0.0,"id":60443},{"batb":[[0,1.51,16.79],[1,1.5,20],[2,1.1,200]],"ltp":0.0,"tv":0.0,"id":31374}]}]}
{"op":"mcm","clk":"11914546823","pt":1724035628293,"mc":[{"id":"1.231851789","rc":[{"batb":[[0,1.5,20],[1,1.1,200],[2,1.03,200]],"ltp":0.0,"tv":0.0,"id":2780}]}]}
{"op":"mcm","clk":"11914546834","pt":1724035628702,"mc":[{"id":"1.231851789","rc":[{"batb":[[0,1.38,19.59],[1,1.3,20],[2,1.1,200]],"ltp":0.0,"tv":0.0,"id":60443},{"batb":[[0,1.5,20],[1,1.1,200],[2,1.03,200]],"ltp":0.0,"tv":0.0,"id":31374}]}]}
{"op":"mcm","clk":"11914549412","pt":1724035719116,"mc":[{"id":"1.231851789","rc":[{"batb":[[0,1.51,16.79],[1,1.5,20],[2,1.1,200]],"ltp":0.0,"tv":0.0,"id":2780},{"batb":[[0,1.39,21.95],[1,1.38,19.59],[2,1.3,20]],"ltp":0.0,"tv":0.0,"id":60443},{"batb":[[0,1.51,16.79],[1,1.5,20],[2,1.1,200]],"ltp":0.0,"tv":0.0,"id":31374}]}]}
{"op":"mcm","clk":"11914599819","pt":1724037519868,"mc":[{"id":"1.231851789","rc":[{"batb":[[0,1.5,20],[1,1.1,200],[2,1.03,200]],"ltp":0.0,"tv":0.0,"id":2780},{"batb":[[0,1.38,19.59],[1,1.3,20],[2,1.1,200]],"ltp":0.0,"tv":0.0,"id":60443},{"batb":[[0,1.5,20],[1,1.1,200],[2,1.03,200]],"ltp":0.0,"tv":0.0,"id":31374}]}]}
{"op":"mcm","clk":"11914602740","pt":1724037592746,"mc":[{"id":"1.231851789","rc":[{"batb":[[0,1.51,16.78],[1,1.5,20],[2,1.1,200]],"ltp":0.0,"tv":0.0,"id":2780},{"batb":[[0,1.39,21.95],[1,1.38,19.59],[2,1.3,20]],"ltp":0.0,"tv":0.0,"id":60443},{"batb":[[0,1.51,16.78],[1,1.5,20],[2,1.1,200]],"ltp":0.0,"tv":0.0,"id":31374}]}]}
{"op":"mcm","clk":"11914660742","pt":1724039393170,"mc":[{"id":"1.231851789","rc":[{"batb":[[0,1.5,20],[1,1.1,200],[2,1.03,200]],"ltp":0.0,"tv":0.0,"id":2780},{"batb":[[0,1.5,20],[1,1.1,200],[2,1.03,200]],"ltp":0.0,"tv":0.0,"id":31374}]}]}
{"op":"mcm","clk":"11914660751","pt":1724039393374,"mc":[{"id":"1.231851789","rc":[{"batb":[[0,1.38,19.59],[1,1.3,20],[2,1.1,200]],"ltp":0.0,"tv":0.0,"id":60443}]}]}
{"op":"mcm","clk":"11914662515","pt":1724039455542,"mc":[{"id":"1.231851789","rc":[{"batb":[[0,1.51,16.78],[1,1.5,20],[2,1.1,200]],"ltp":0.0,"tv":0.0,"id":2780},{"batb":[[0,1.39,21.95],[1,1.38,19.59],[2,1.3,20]],"ltp":0.0,"tv":0.0,"id":60443},{"batb":[[0,1.51,16.78],[1,1.5,20],[2,1.1,200]],"ltp":0.0,"tv":0.0,"id":31374}]}]}
{"op":"mcm","clk":"11914709672","pt":1724041256155,"mc":[{"id":"1.231851789","rc":[{"batb":[[0,1.5,20],[1,1.1,200],[2,1.03,200]],"ltp":0.0,"tv":0.0,"id":2780},{"batb":[[0,1.38,19.6],[1,1.3,20],[2,1.1,200]],"ltp":0.0,"tv":0.0,"id":60443},{"batb":[[0,1.5,20],[1,1.1,200],[2,1.03,200]],"ltp":0.0,"tv":0.0,"id":31374}]}]}
{"op":"mcm","clk":"11914711109","pt":1724041313907,"mc":[{"id":"1.231851789","rc":[{"batb":[[0,1.51,16.8],[1,1.5,20],[2,1.1,200]],"ltp":0.0,"tv":0.0,"id":2780},{"batb":[[0,1.39,21.96],[1,1.38,19.6],[2,1.3,20]],"ltp":0.0,"tv":0.0,"id":60443},{"batb":[[0,1.51,16.8],[1,1.5,20],[2,1.1,200]],"ltp":0.0,"tv":0.0,"id":31374}]}]}
{"op":"mcm","clk":"11914763764","pt":1724043114262,"mc":[{"id":"1.231851789","rc":[{"batb":[[0,1.5,20],[1,1.1,200],[2,1.03,200]],"ltp":0.0,"tv":0.0,"id":2780},{"batb":[[0,1.38,19.6],[1,1.3,20],[2,1.1,200]],"ltp":0.0,"tv":0.0,"id":60443}]}]}
{"op":"mcm","clk":"11914763769","pt":1724043114365,"mc":[{"id":"1.231851789","rc":[{"batb":[[0,1.5,20],[1,1.1,200],[2,1.03,200]],"ltp":0.0,"tv":0.0,"id":31374}]}]}
{"op":"mcm","clk":"11914765625","pt":1724043162082,"mc":[{"id":"1.231851789","rc":[{"batb":[[0,1.51,16.8],[1,1.5,20],[2,1.1,200]],"ltp":0.0,"tv":0.0,"id":2780},{"batb":[[0,1.39,21.96],[1,1.38,19.6],[2,1.3,20]],"ltp":0.0,"tv":0.0,"id":60443},{"batb":[[0,1.51,16.8],[1,1.5,20],[2,1.1,200]],"ltp":0.0,"tv":0.0,"id":31374}]}]}
{"op":"mcm","clk":"11914821555","pt":1724044374998,"mc":[{"id":"1.231851789","rc":[{"batb":[[0,1.51,16.8]],"ltp":0.0,"tv":0.0,"id":2780},{"batb":[[0,1.39,21.97],[1,1.38,19.6]],"ltp":0.0,"tv":0.0,"id":60443},{"batb":[[0,1.51,16.8]],"ltp":0.0,"tv":0.0,"id":31374}]}]}
{"op":"mcm","clk":"11914850111","pt":1724044962805,"mc":[{"id":"1.231851789","rc":[{"batb":[[0,1.5,20],[1,1.1,200],[2,1.03,200]],"ltp":0.0,"tv":0.0,"id":2780},{"batb":[[0,1.38,19.6],[1,1.3,20],[2,1.1,200]],"ltp":0.0,"tv":0.0,"id":60443},{"batb":[[0,1.5,20],[1,1.1,200],[2,1.03,200]],"ltp":0.0,"tv":0.0,"id":31374}]}]}
{"op":"mcm","clk":"11914851950","pt":1724045005444,"mc":[{"id":"1.231851789","rc":[{"batb":[[0,1.51,16.8],[1,1.5,20],[2,1.1,200]],"ltp":0.0,"tv":0.0,"id":2780},{"batb":[[0,1.39,21.97],[1,1.38,19.6],[2,1.3,20]],"ltp":0.0,"tv":0.0,"id":60443},{"batb":[[0,1.51,16.8],[1,1.5,20],[2,1.1,200]],"ltp":0.0,"tv":0.0,"id":31374}]}]}
{"op":"mcm","clk":"11914928638","pt":1724046805849,"mc":[{"id":"1.231851789","rc":[{"batb":[[0,1.5,20],[1,1.1,200],[2,1.03,200]],"ltp":0.0,"tv":0.0,"id":2780},{"batb":[[0,1.38,19.6],[1,1.3,20],[2,1.1,200]],"ltp":0.0,"tv":0.0,"id":60443},{"batb":[[0,1.5,20],[1,1.1,200],[2,1.03,200]],"ltp":0.0,"tv":0.0,"id":31374}]}]}
{"op":"mcm","clk":"11914930349","pt":1724046846310,"mc":[{"id":"1.231851789","rc":[{"batb":[[0,1.51,16.8],[1,1.5,20],[2,1.1,200]],"ltp":0.0,"tv":0.0,"id":2780},{"batb":[[0,1.39,21.97],[1,1.38,19.6],[2,1.3,20]],"ltp":0.0,"tv":0.0,"id":60443},{"batb":[[0,1.51,16.8],[1,1.5,20],[2,1.1,200]],"ltp":0.0,"tv":0.0,"id":31374}]}]}
{"op":"mcm","clk":"11915005836","pt":1724048646893,"mc":[{"id":"1.231851789","rc":[{"batb":[[0,1.5,20],[1,1.1,200],[2,1.03,200]],"ltp":0.0,"tv":0.0,"id":2780},{"batb":[[0,1.38,19.6],[1,1.3,20],[2,1.1,200]],"ltp":0.0,"tv":0.0,"id":60443},{"batb":[[0,1.5,20],[1,1.1,200],[2,1.03,200]],"ltp":0.0,"tv":0.0,"id":31374}]}]}
{"op":"mcm","clk":"11915007803","pt":1724048686493,"mc":[{"id":"1.231851789","rc":[{"batb":[[0,1.51,16.8],[1,1.5,20],[2,1.1,200]],"ltp":0.0,"tv":0.0,"id":2780},{"batb":[[0,1.39,21.97],[1,1.38,19.6],[2,1.3,20]],"ltp":0.0,"tv":0.0,"id":60443},{"batb":[[0,1.51,16.8],[1,1.5,20],[2,1.1,200]],"ltp":0.0,"tv":0.0,"id":31374}]}]}
{"op":"mcm","clk":"11915105900","pt":1724050487031,"mc":[{"id":"1.231851789","rc":[{"batb":[[0,1.5,20],[1,1.1,200],[2,1.03,200]],"ltp":0.0,"tv":0.0,"id":2780},{"batb":[[0,1.38,19.6],[1,1.3,20],[2,1.1,200]],"ltp":0.0,"tv":0.0,"id":60443},{"batb":[[0,1.5,20],[1,1.1,200],[2,1.03,200]],"ltp":0.0,"tv":0.0,"id":31374}]}]}
{"op":"mcm","clk":"11915107579","pt":1724050519758,"mc":[{"id":"1.231851789","rc":[{"batb":[[0,1.51,16.8],[1,1.5,20],[2,1.1,200]],"ltp":0.0,"tv":0.0,"id":2780},{"batb":[[0,1.39,21.97],[1,1.38,19.6],[2,1.3,20]],"ltp":0.0,"tv":0.0,"id":60443},{"batb":[[0,1.51,16.8],[1,1.5,20],[2,1.1,200]],"ltp":0.0,"tv":0.0,"id":31374}]}]}
{"op":"mcm","clk":"11915190267","pt":1724052320268,"mc":[{"id":"1.231851789","rc":[{"batb":[[0,1.5,20],[1,1.1,200],[2,1.03,200]],"ltp":0.0,"tv":0.0,"id":2780},{"batb":[[0,1.38,19.59],[1,1.3,20],[2,1.1,200]],"ltp":0.0,"tv":0.0,"id":60443},{"batb":[[0,1.5,20],[1,1.1,200],[2,1.03,200]],"ltp":0.0,"tv":0.0,"id":31374}]}]}
{"op":"mcm","clk":"11915191719","pt":1724052350803,"mc":[{"id":"1.231851789","rc":[{"batb":[[0,1.51,16.79],[1,1.5,20],[2,1.1,200]],"ltp":0.0,"tv":0.0,"id":2780},{"batb":[[0,1.39,21.96],[1,1.38,19.59],[2,1.3,20]],"ltp":0.0,"tv":0.0,"id":60443},{"batb":[[0,1.51,16.79],[1,1.5,20],[2,1.1,200]],"ltp":0.0,"tv":0.0,"id":31374}]}]}
{"op":"mcm","clk":"11915270667","pt":1724054151302,"mc":[{"id":"1.231851789","rc":[{"batb":[[0,1.38,19.59],[1,1.3,20],[2,1.1,200]],"ltp":0.0,"tv":0.0,"id":60443},{"batb":[[0,1.5,20],[1,1.1,200],[2,1.03,200]],"ltp":0.0,"tv":0.0,"id":31374}]}]}
{"op":"mcm","clk":"11915270677","pt":1724054151505,"mc":[{"id":"1.231851789","rc":[{"batb":[[0,1.5,20],[1,1.1,200],[2,1.03,200]],"ltp":0.0,"tv":0.0,"id":2780}]}]}
{"op":"mcm","clk":"11915272038","pt":1724054181826,"mc":[{"id":"1.231851789","rc":[{"batb":[[0,1.51,16.79],[1,1.5,20],[2,1.1,200]],"ltp":0.0,"tv":0.0,"id":2780},{"batb":[[0,1.39,21.96],[1,1.38,19.59],[2,1.3,20]],"ltp":0.0,"tv":0.0,"id":60443},{"batb":[[0,1.51,16.79],[1,1.5,20],[2,1.1,200]],"ltp":0.0,"tv":0.0,"id":31374}]}]}
{"op":"mcm","clk":"11915321580","pt":1724055175016,"mc":[{"id":"1.231851789","rc":[{"batb":[[0,1.39,21.95]],"ltp":0.0,"tv":0.0,"id":60443}]}]}
{"op":"mcm","clk":"11915362380","pt":1724055982227,"mc":[{"id":"1.231851789","rc":[{"batb":[[0,1.5,20],[1,1.1,200],[2,1.03,200]],"ltp":0.0,"tv":0.0,"id":2780},{"batb":[[0,1.5,20],[1,1.1,200],[2,1.03,200]],"ltp":0.0,"tv":0.0,"id":31374}]}]}
{"op":"mcm","clk":"11915362393","pt":1724055982433,"mc":[{"id":"1.231851789","rc":[{"batb":[[0,1.38,19.59],[1,1.3,20],[2,1.1,200]],"ltp":0.0,"tv":0.0,"id":60443}]}]}
{"op":"mcm","clk":"11915363511","pt":1724056004314,"mc":[{"id":"1.231851789","rc":[{"batb":[[0,1.51,16.79],[1,1.5,20],[2,1.1,200]],"ltp":0.0,"tv":0.0,"id":2780},{"batb":[[0,1.39,21.95],[1,1.38,19.59],[2,1.3,20]],"ltp":0.0,"tv":0.0,"id":60443},{"batb":[[0,1.51,16.79],[1,1.5,20],[2,1.1,200]],"ltp":0.0,"tv":0.0,"id":31374}]}]}
{"op":"mcm","clk":"11915443246","pt":1724057804964,"mc":[{"id":"1.231851789","rc":[{"batb":[[0,1.5,20],[1,1.1,200],[2,1.03,200]],"ltp":0.0,"tv":0.0,"id":2780},{"batb":[[0,1.38,19.59],[1,1.3,20],[2,1.1,200]],"ltp":0.0,"tv":0.0,"id":60443},{"batb":[[0,1.5,20],[1,1.1,200],[2,1.03,200]],"ltp":0.0,"tv":0.0,"id":31374}]}]}
{"op":"mcm","clk":"11915443716","pt":1724057818579,"mc":[{"id":"1.231851789","rc":[{"batb":[[0,1.51,16.79],[1,1.5,20],[2,1.1,200]],"ltp":0.0,"tv":0.0,"id":2780},{"batb":[[0,1.39,21.95],[1,1.38,19.59],[2,1.3,20]],"ltp":0.0,"tv":0.0,"id":60443},{"batb":[[0,1.51,16.79],[1,1.5,20],[2,1.1,200]],"ltp":0.0,"tv":0.0,"id":31374}]}]}
{"op":"mcm","clk":"11915445385","pt":1724057865838,"mc":[{"id":"1.231851789","rc":[{"batb":[[0,1.4,40],[1,1.39,21.95],[2,1.38,19.59]],"ltp":0.0,"tv":0.0,"id":60443}]}]}
{"op":"mcm","clk":"11915512954","pt":1724059619208,"mc":[{"id":"1.231851789","rc":[{"batb":[[0,1.5,20],[1,1.1,200],[2,1.03,200]],"ltp":0.0,"tv":0.0,"id":2780},{"batb":[[1,1.38,19.57],[2,1.3,20]],"ltp":0.0,"tv":0.0,"id":60443},{"batb":[[0,1.5,20],[1,1.1,200],[2,1.03,200]],"ltp":0.0,"tv":0.0,"id":31374}]}]}
{"op":"mcm","clk":"11915513320","pt":1724059633020,"mc":[{"id":"1.231851789","rc":[{"batb":[[0,1.51,16.77],[1,1.5,20],[2,1.1,200]],"ltp":0.0,"tv":0.0,"id":2780},{"batb":[[0,1.41,20.86],[1,1.4,40],[2,1.38,19.57]],"ltp":0.0,"tv":0.0,"id":60443},{"batb":[[0,1.51,16.77],[1,1.5,20],[2,1.1,200]],"ltp":0.0,"tv":0.0,"id":31374}]}]}
{"op":"mcm","clk":"11915587295","pt":1724061433569,"mc":[{"id":"1.231851789","rc":[{"batb":[[0,1.5,20],[1,1.1,200],[2,1.03,200]],"ltp":0.0,"tv":0.0,"id":2780},{"batb":[[0,1.4,40],[1,1.38,19.57],[2,1.3,20]],"ltp":0.0,"tv":0.0,"id":60443},{"batb":[[0,1.5,20],[1,1.1,200],[2,1.03,200]],"ltp":0.0,"tv":0.0,"id":31374}]}]}
{"op":"mcm","clk":"11915587510","pt":1724061438590,"mc":[{"id":"1.231851789","rc":[{"batb":[[0,1.51,16.77],[1,1.5,20],[2,1.1,200]],"ltp":0.0,"tv":0.0,"id":2780},{"batb":[[0,1.41,20.86],[1,1.4,40],[2,1.38,19.57]],"ltp":0.0,"tv":0.0,"id":60443},{"batb":[[0,1.51,16.77],[1,1.5,20],[2,1.1,200]],"ltp":0.0,"tv":0.0,"id":31374}]}]}
{"op":"mcm","clk":"11915663994","pt":1724063239109,"mc":[{"id":"1.231851789","rc":[{"batb":[[0,1.5,20],[1,1.1,200],[2,1.03,200]],"ltp":0.0,"tv":0.0,"id":2780},{"batb":[[0,1.4,40],[1,1.38,19.58],[2,1.3,20]],"ltp":0.0,"tv":0.0,"id":60443},{"batb":[[0,1.5,20],[1,1.1,200],[2,1.03,200]],"ltp":0.0,"tv":0.0,"id":31374}]}]}
{"op":"mcm","clk":"11915667701","pt":1724063341592,"mc":[{"id":"1.231851789","rc":[{"batb":[[0,1.51,16.78],[1,1.5,20],[2,1.1,200]],"ltp":0.0,"tv":0.0,"id":2780},{"batb":[[0,1.41,20.87],[1,1.4,40],[2,1.38,19.58]],"ltp":0.0,"tv":0.0,"id":60443},{"batb":[[0,1.51,16.78],[1,1.5,20],[2,1.1,200]],"ltp":0.0,"tv":0.0,"id":31374}]}]}
{"op":"mcm","clk":"11915737526","pt":1724065030277,"mc":[{"id":"1.231851789","rc":[{"batl":[[0,1.45,1.54],[1,95,5.85],[2,990,5]],"ltp":0.0,"tv":0.0,"id":60443}]}]}
{"op":"mcm","clk":"11915737884","pt":1724065038990,"mc":[{"id":"1.231851789","rc":[{"batl":[[0,95,5.85],[1,990,5],[2,990,0]],"ltp":0.0,"tv":0.0,"id":60443}]}]}
{"op":"mcm","clk":"11915738450","pt":1724065052629,"mc":[{"id":"1.231851789","rc":[{"batl":[[0,1.45,1.54],[1,95,5.85],[2,990,5]],"ltp":0.0,"tv":0.0,"id":60443}]}]}
{"op":"mcm","clk":"11915738780","pt":1724065060743,"mc":[{"id":"1.231851789","rc":[{"batl":[[0,95,5.85],[1,990,5],[2,990,0]],"ltp":0.0,"tv":0.0,"id":60443}]}]}
{"op":"mcm","clk":"11915741772","pt":1724065142101,"mc":[{"id":"1.231851789","rc":[{"batb":[[0,1.5,20],[1,1.1,200],[2,1.03,200]],"ltp":0.0,"tv":0.0,"id":2780},{"batb":[[0,1.5,20],[1,1.1,200],[2,1.03,200]],"ltp":0.0,"tv":0.0,"id":31374}]}]}
{"op":"mcm","clk":"11915741781","pt":1724065142306,"mc":[{"id":"1.231851789","rc":[{"batb":[[0,1.4,40],[1,1.38,19.58],[2,1.3,20]],"ltp":0.0,"tv":0.0,"id":60443}]}]}
{"op":"mcm","clk":"11915747326","pt":1724065267757,"mc":[{"id":"1.231851789","rc":[{"batb":[[0,1.51,16.8],[1,1.5,20],[2,1.1,200]],"batl":[[0,95,5.85]],"ltp":0.0,"tv":0.0,"id":2780},{"batb":[[0,1.41,20.89],[1,1.4,40],[2,1.38,19.6]],"batl":[[0,95,5.85]],"ltp":0.0,"tv":0.0,"id":60443},{"batb":[[0,1.51,16.8],[1,1.5,20],[2,1.1,200]],"batl":[[0,95,5.85]],"ltp":0.0,"tv":0.0,"id":31374}]}]}
{"op":"mcm","clk":"11915750762","pt":1724065363420,"mc":[{"id":"1.231851789","rc":[{"batl":[[0,1.45,2.32],[1,95,5.85],[2,990,5]],"ltp":0.0,"tv":0.0,"id":60443}]}]}
{"op":"mcm","clk":"11915751132","pt":1724065370883,"mc":[{"id":"1.231851789","rc":[{"batl":[[0,95,5.85],[1,990,5],[2,990,0]],"ltp":0.0,"tv":0.0,"id":60443}]}]}
{"op":"mcm","clk":"11915751495","pt":1724065380858,"mc":[{"id":"1.231851789","rc":[{"batl":[[0,1.45,3.09],[1,95,5.85],[2,990,5]],"ltp":0.0,"tv":0.0,"id":60443}]}]}
{"op":"mcm","clk":"11915751679","pt":1724065386473,"mc":[{"id":"1.231851789","rc":[{"batl":[[0,95,5.85],[1,990,5],[2,990,0]],"ltp":0.0,"tv":0.0,"id":60443}]}]}
{"op":"mcm","clk":"11915755747","pt":1724065495593,"mc":[{"id":"1.231851789","rc":[{"batb":[[0,2,1.54],[1,1.41,20.89],[2,1.4,40]],"ltp":0.0,"tv":0.0,"id":60443}]}]}
{"op":"mcm","clk":"11915756062","pt":1724065502815,"mc":[{"id":"1.231851789","rc":[{"batb":[[0,1.41,20.89],[1,1.4,40],[2,1.38,19.6]],"ltp":0.0,"tv":0.0,"id":60443}]}]}
{"op":"mcm","clk":"11915756617","pt":1724065514885,"mc":[{"id":"1.231851789","rc":[{"batl":[[0,1.48,1.54],[1,95,5.85],[2,990,5]],"ltp":0.0,"tv":0.0,"id":60443}]}]}
{"op":"mcm","clk":"11915757228","pt":1724065530447,"mc":[{"id":"1.231851789","rc":[{"batl":[[0,95,5.85],[1,990,5],[2,990,0]],"ltp":0.0,"tv":0.0,"id":60443}]}]}
{"op":"mcm","clk":"11915822259","pt":1724067068171,"mc":[{"id":"1.231851789","rc":[{"batb":[[0,1.5,20],[1,1.1,200],[2,1.03,200]],"ltp":0.0,"tv":0.0,"id":2780},{"batb":[[0,1.5,20],[1,1.1,200],[2,1.03,200]],"ltp":0.0,"tv":0.0,"id":31374}]}]}
{"op":"mcm","clk":"11915822269","pt":1724067068374,"mc":[{"id":"1.231851789","rc":[{"batb":[[0,1.4,40],[1,1.38,19.6],[2,1.3,20]],"ltp":0.0,"tv":0.0,"id":60443}]}]}
{"op":"mcm","clk":"11915823442","pt":1724067103617,"mc":[{"id":"1.231851789","rc":[{"batb":[[0,1.51,16.8],[1,1.5,20],[2,1.1,200]],"ltp":0.0,"tv":0.0,"id":2780},{"batb":[[0,1.41,20.89],[1,1.4,40],[2,1.38,19.6]],"ltp":0.0,"tv":0.0,"id":60443},{"batb":[[0,1.51,16.8],[1,1.5,20],[2,1.1,200]],"ltp":0.0,"tv":0.0,"id":31374}]}]}
{"op":"mcm","clk":"11915874605","pt":1724068612945,"mc":[{"id":"1.231851789","rc":[{"trd":[[1.41,0.1]],"batb":[[0,1.41,20.85]],"ltp":1.41,"tv":0.09,"id":60443}],"tv":0.09}]}
{"op":"mcm","clk":"11915880740","pt":1724068767102,"mc":[{"id":"1.231851789","rc":[{"trd":[[1.41,2.08]],"batb":[[0,1.41,19.85]],"ltp":1.41,"tv":2.08,"id":60443}],"tv":2.08}]}
{"op":"mcm","clk":"11915886479","pt":1724068904160,"mc":[{"id":"1.231851789","rc":[{"batb":[[0,1.5,20],[1,1.1,200],[2,1.03,200]],"ltp":0.0,"tv":0.0,"id":2780},{"batb":[[0,1.4,40],[1,1.38,19.6],[2,1.3,20]],"ltp":1.41,"tv":2.08,"id":60443},{"batb":[[0,1.5,20],[1,1.1,200],[2,1.03,200]],"ltp":0.0,"tv":0.0,"id":31374}]}]}
{"op":"mcm","clk":"11915887928","pt":1724068937867,"mc":[{"id":"1.231851789","rc":[{"batb":[[0,1.51,16.8],[1,1.5,20],[2,1.1,200]],"ltp":0.0,"tv":0.0,"id":2780},{"batb":[[0,1.51,16.8],[1,1.5,20],[2,1.1,200]],"ltp":0.0,"tv":0.0,"id":31374}]}]}
{"op":"mcm","clk":"11915982673","pt":1724070738127,"mc":[{"id":"1.231851789","rc":[{"batb":[[0,1.5,20],[1,1.1,200],[2,1.03,200]],"ltp":0.0,"tv":0.0,"id":2780}]}]}
{"op":"mcm","clk":"11915982688","pt":1724070738332,"mc":[{"id":"1.231851789","rc":[{"batb":[[0,1.5,20],[1,1.1,200],[2,1.03,200]],"ltp":0.0,"tv":0.0,"id":31374}]}]}
{"op":"mcm","clk":"11915984316","pt":1724070764869,"mc":[{"id":"1.231851789","rc":[{"batb":[[0,1.51,16.8],[1,1.5,20],[2,1.1,200]],"ltp":0.0,"tv":0.0,"id":2780},{"batb":[[0,1.51,16.8],[1,1.5,20],[2,1.1,200]],"ltp":0.0,"tv":0.0,"id":31374}]}]}
{"op":"mcm","clk":"11916002258","pt":1724071087956,"mc":[{"id":"1.231851789","rc":[{"batb":[[0,1.8,277],[1,1.51,16.8],[2,1.5,20]],"ltp":0.0,"tv":0.0,"id":2780}]}]}
{"op":"mcm","clk":"11916043472","pt":1724071639968,"mc":[{"id":"1.231851789","rc":[{"batb":[[0,1.81,6.26],[1,1.8,277],[2,1.51,16.8]],"ltp":0.0,"tv":0.0,"id":2780}]}]}
{"op":"mcm","clk":"11916087520","pt":1724072565232,"mc":[{"id":"1.231851789","rc":[{"batb":[[0,1.81,6.26],[2,1.5,20]],"ltp":0.0,"tv":0.0,"id":2780},{"batb":[[0,1.5,20],[1,1.1,200],[2,1.03,200]],"ltp":0.0,"tv":0.0,"id":31374}]}]}
{"op":"mcm","clk":"11916088819","pt":1724072589251,"mc":[{"id":"1.231851789","rc":[{"batb":[[0,1.82,10.45],[1,1.81,6.26],[2,1.8,277]],"ltp":0.0,"tv":0.0,"id":2780},{"batb":[[0,1.51,16.8],[1,1.5,20],[2,1.1,200]],"ltp":0.0,"tv":0.0,"id":31374}]}]}
{"op":"mcm","clk":"11916209207","pt":1724074389542,"mc":[{"id":"1.231851789","rc":[{"batb":[[0,1.81,6.26],[1,1.8,277],[2,1.5,20]],"ltp":0.0,"tv":0.0,"id":2780},{"batb":[[0,1.5,20],[1,1.1,200],[2,1.03,200]],"ltp":0.0,"tv":0.0,"id":31374}]}]}
{"op":"mcm","clk":"11916210467","pt":1724074408728,"mc":[{"id":"1.231851789","rc":[{"batb":[[0,1.82,10.45],[1,1.81,6.26],[2,1.8,277]],"ltp":0.0,"tv":0.0,"id":2780},{"batb":[[0,1.51,16.8],[1,1.5,20],[2,1.1,200]],"ltp":0.0,"tv":0.0,"id":31374}]}]}
{"op":"mcm","clk":"11916254812","pt":1724075080875,"mc":[{"id":"1.231851789","rc":[{"batb":[[0,1.4,40.9]],"ltp":1.41,"tv":2.08,"id":60443}]}]}
{"op":"mcm","clk":"11916324972","pt":1724076209048,"mc":[{"id":"1.231851789","rc":[{"batb":[[0,1.81,6.26],[1,1.8,277],[2,1.5,20]],"ltp":0.0,"tv":0.0,"id":2780},{"batb":[[1,1.38,19.6]],"ltp":1.41,"tv":2.07,"id":60443},{"batb":[[0,1.5,20],[1,1.1,200],[2,1.03,200]],"ltp":0.0,"tv":0.0,"id":31374}]}]}
{"op":"mcm","clk":"11916325907","pt":1724076228663,"mc":[{"id":"1.231851789","rc":[{"batb":[[0,1.82,10.44],[1,1.81,6.26],[2,1.8,277]],"ltp":0.0,"tv":0.0,"id":2780},{"batb":[[0,1.51,16.79],[1,1.5,20],[2,1.1,200]],"ltp":0.0,"tv":0.0,"id":31374}]}]}
{"op":"mcm","clk":"11916442357","pt":1724078029000,"mc":[{"id":"1.231851789","rc":[{"batb":[[0,1.81,6.26],[1,1.8,277],[2,1.5,20]],"ltp":0.0,"tv":0.0,"id":2780},{"batb":[[0,1.5,20],[1,1.1,200],[2,1.03,200]],"ltp":0.0,"tv":0.0,"id":31374}]}]}
{"op":"mcm","clk":"11916442435","pt":1724078030503,"mc":[{"id":"1.231851789","rc":[{"batb":[[0,1.82,10.44],[1,1.81,6.26],[2,1.8,277]],"ltp":0.0,"tv":0.0,"id":2780},{"batb":[[0,1.51,16.79],[1,1.5,20],[2,1.1,200]],"ltp":0.0,"tv":0.0,"id":31374}]}]}
{"op":"mcm","clk":"11916566968","pt":1724079830864,"mc":[{"id":"1.231851789","rc":[{"batb":[[0,1.81,6.25],[1,1.8,277],[2,1.5,20]],"ltp":0.0,"tv":0.0,"id":2780},{"trd":[[1.41,2.08]],"batb":[[0,1.4,40.9]],"ltp":1.41,"tv":2.07,"id":60443},{"batb":[[0,1.5,20],[1,1.1,200],[2,1.03,200]],"ltp":0.0,"tv":0.0,"id":31374}],"tv":2.07}]}
{"op":"mcm","clk":"11916567010","pt":1724079831372,"mc":[{"id":"1.231851789","rc":[{"batb":[[0,1.82,10.44],[1,1.81,6.25],[2,1.8,277]],"ltp":0.0,"tv":0.0,"id":2780},{"batb":[[0,1.51,16.79],[1,1.5,20],[2,1.1,200]],"ltp":0.0,"tv":0.0,"id":31374}]}]}
{"op":"mcm","clk":"11916656133","pt":1724080783487,"mc":[{"id":"1.231851789","rc":[{"batb":[[0,1.41,20.49],[1,1.4,40]],"ltp":1.41,"tv":2.07,"id":60443}]}]}
{"op":"mcm","clk":"11916750123","pt":1724081631660,"mc":[{"id":"1.231851789","rc":[{"batb":[[0,1.81,6.25],[1,1.8,277],[2,1.5,20]],"ltp":0.0,"tv":0.0,"id":2780},{"batb":[[0,1.5,20],[1,1.1,200],[2,1.03,200]],"ltp":0.0,"tv":0.0,"id":31374}]}]}
{"op":"mcm","clk":"11916763846","pt":1724081778499,"mc":[{"id":"1.231851789","rc":[{"batb":[[0,1.82,10.44],[1,1.81,6.25],[2,1.8,277]],"ltp":0.0,"tv":0.0,"id":2780},{"batb":[[0,1.51,16.79],[1,1.5,20],[2,1.1,200]],"ltp":0.0,"tv":0.0,"id":31374}]}]}
{"op":"mcm","clk":"11916954519","pt":1724083578740,"mc":[{"id":"1.231851789","rc":[{"batb":[[0,1.81,6.25],[1,1.8,277],[2,1.5,20]],"ltp":0.0,"tv":0.0,"id":2780},{"trd":[[1.41,2.08]],"batb":[[0,1.41,20.51]],"ltp":1.41,"tv":2.07,"id":60443},{"batb":[[0,1.5,20],[1,1.1,200],[2,1.03,200]],"ltp":0.0,"tv":0.0,"id":31374}],"tv":2.07}]}
{"op":"mcm","clk":"11916957827","pt":1724083602826,"mc":[{"id":"1.231851789","rc":[{"batb":[[0,1.82,10.45],[1,1.81,6.25],[2,1.8,277]],"ltp":0.0,"tv":0.0,"id":2780},{"batb":[[0,1.51,16.8],[1,1.5,20],[2,1.1,200]],"ltp":0.0,"tv":0.0,"id":31374}]}]}
{"op":"mcm","clk":"11917204080","pt":1724085403206,"mc":[{"id":"1.231851789","rc":[{"batb":[[0,1.81,6.25],[1,1.8,277],[2,1.5,20]],"ltp":0.0,"tv":0.0,"id":2780},{"batb":[[0,1.5,20],[1,1.1,200],[2,1.03,200]],"ltp":0.0,"tv":0.0,"id":31374}]}]}
{"op":"mcm","clk":"11917210575","pt":1724085447634,"mc":[{"id":"1.231851789","rc":[{"batb":[[0,1.82,10.45],[1,1.81,6.25],[2,1.8,277]],"ltp":0.0,"tv":0.0,"id":2780},{"batb":[[0,1.51,16.8],[1,1.5,20],[2,1.1,200]],"ltp":0.0,"tv":0.0,"id":31374}]}]}
{"op":"mcm","clk":"11917434235","pt":1724087248078,"mc":[{"id":"1.231851789","rc":[{"batb":[[0,1.81,6.25],[1,1.8,277],[2,1.5,20]],"ltp":0.0,"tv":0.0,"id":2780},{"batb":[[0,1.41,20.52]],"ltp":1.41,"tv":2.07,"id":60443},{"batb":[[0,1.5,20],[1,1.1,200],[2,1.03,200]],"ltp":0.0,"tv":0.0,"id":31374}]}]}
{"op":"mcm","clk":"11917438195","pt":1724087272168,"mc":[{"id":"1.231851789","rc":[{"batb":[[0,1.82,10.45],[1,1.81,6.25],[2,1.8,277]],"ltp":0.0,"tv":0.0,"id":2780},{"batb":[[0,1.51,16.81],[1,1.5,20],[2,1.1,200]],"ltp":0.0,"tv":0.0,"id":31374}]}]}
{"op":"mcm","clk":"11917966705","pt":1724090873120,"mc":[{"id":"1.231851789","rc":[{"batb":[[0,1.82,10.45],[1,1.81,6.24]],"ltp":0.0,"tv":0.0,"id":2780},{"batb":[[0,1.41,20.51]],"ltp":1.41,"tv":2.07,"id":60443},{"batb":[[0,1.5,20],[1,1.1,200],[2,1.03,200]],"ltp":0.0,"tv":0.0,"id":31374}]}]}
{"op":"mcm","clk":"11917966741","pt":1724090873328,"mc":[{"id":"1.231851789","rc":[{"batb":[[0,1.81,6.24],[1,1.8,277],[2,1.5,20]],"ltp":0.0,"tv":0.0,"id":2780}]}]}
{"op":"mcm","clk":"11917986127","pt":1724091015758,"mc":[{"id":"1.231851789","rc":[{"batb":[[0,1.82,10.45],[1,1.81,6.24],[2,1.8,277]],"ltp":0.0,"tv":0.0,"id":2780},{"batb":[[0,1.51,16.8],[1,1.5,20],[2,1.1,200]],"ltp":0.0,"tv":0.0,"id":31374}]}]}
{"op":"mcm","clk":"11918272588","pt":1724092816122,"mc":[{"id":"1.231851789","rc":[{"batb":[[0,1.81,6.24],[1,1.8,277],[2,1.5,20]],"ltp":0.0,"tv":0.0,"id":2780},{"batb":[[0,1.5,20],[1,1.1,200],[2,1.03,200]],"ltp":0.0,"tv":0.0,"id":31374}]}]}
{"op":"mcm","clk":"11918289701","pt":1724092915259,"mc":[{"id":"1.231851789","rc":[{"batb":[[0,1.82,10.45],[1,1.81,6.24],[2,1.8,277]],"ltp":0.0,"tv":0.0,"id":2780},{"batb":[[0,1.51,16.8],[1,1.5,20],[2,1.1,200]],"ltp":0.0,"tv":0.0,"id":31374}]}]}
{"op":"mcm","clk":"11918555074","pt":1724094715537,"mc":[{"id":"1.231851789","rc":[{"batb":[[0,1.81,6.24],[1,1.8,277],[2,1.5,20]],"ltp":0.0,"tv":0.0,"id":2780},{"batb":[[0,1.41,20.51]],"ltp":1.41,"tv":2.07,"id":60443},{"batb":[[0,1.5,20],[1,1.1,200],[2,1.03,200]],"ltp":0.0,"tv":0.0,"id":31374}]}]}
{"op":"mcm","clk":"11918564242","pt":1724094779503,"mc":[{"id":"1.231851789","rc":[{"batb":[[0,1.82,10.45],[1,1.81,6.24],[2,1.8,277]],"ltp":0.0,"tv":0.0,"id":2780},{"batb":[[0,1.51,16.81],[1,1.5,20],[2,1.1,200]],"ltp":0.0,"tv":0.0,"id":31374}]}]}
{"op":"mcm","clk":"11918725999","pt":1724095909105,"mc":[{"id":"1.231851789","rc":[{"batb":[[2,1.5,20]],"ltp":0.0,"tv":0.0,"id":2780}]}]}
{"op":"mcm","clk":"11918818501","pt":1724096580041,"mc":[{"id":"1.231851789","rc":[{"batb":[[0,1.81,6.24],[1,1.5,20],[2,1.1,200]],"ltp":0.0,"tv":0.0,"id":2780},{"batb":[[0,1.5,20],[1,1.1,200],[2,1.03,200]],"ltp":0.0,"tv":0.0,"id":31374}]}]}
{"op":"mcm","clk":"11918829985","pt":1724096658574,"mc":[{"id":"1.231851789","rc":[{"batb":[[0,1.82,10.45],[1,1.81,6.24],[2,1.5,20]],"ltp":0.0,"tv":0.0,"id":2780},{"batb":[[0,1.51,16.81],[1,1.5,20],[2,1.1,200]],"ltp":0.0,"tv":0.0,"id":31374}]}]}
{"op":"mcm","clk":"11919008714","pt":1724098256670,"mc":[{"id":"1.231851789","rc":[{"batb":[[0,1.82,10.46],[1,1.5,20],[2,1.1,200]],"ltp":0.0,"tv":0.0,"id":2780},{"batb":[[0,1.41,20.52]],"ltp":1.41,"tv":2.07,"id":60443},{"batb":[[0,1.51,16.81]],"ltp":0.0,"tv":0.0,"id":31374}]}]}
{"op":"mcm","clk":"11919035651","pt":1724098458910,"mc":[{"id":"1.231851789","rc":[{"batb":[[0,1.5,20],[1,1.1,200],[2,1.03,200]],"ltp":0.0,"tv":0.0,"id":2780},{"batb":[[0,1.5,20],[1,1.1,200],[2,1.03,200]],"ltp":0.0,"tv":0.0,"id":31374}]}]}
{"op":"mcm","clk":"11919042607","pt":1724098537804,"mc":[{"id":"1.231851789","rc":[{"batb":[[0,1.51,16.81],[1,1.5,20],[2,1.1,200]],"ltp":0.0,"tv":0.0,"id":2780},{"batb":[[0,1.51,16.81],[1,1.5,20],[2,1.1,200]],"ltp":0.0,"tv":0.0,"id":31374}]}]}
{"op":"mcm","clk":"11919197863","pt":1724100338188,"mc":[{"id":"1.231851789","rc":[{"batb":[[0,1.5,20],[1,1.1,200],[2,1.03,200]],"ltp":0.0,"tv":0.0,"id":2780},{"batb":[[0,1.5,20],[1,1.1,200],[2,1.03,200]],"ltp":0.0,"tv":0.0,"id":31374}]}]}
{"op":"mcm","clk":"11919199932","pt":1724100368950,"mc":[{"id":"1.231851789","rc":[{"batb":[[0,1.51,16.81],[1,1.5,20],[2,1.1,200]],"ltp":0.0,"tv":0.0,"id":2780},{"batb":[[0,1.51,16.81],[1,1.5,20],[2,1.1,200]],"ltp":0.0,"tv":0.0,"id":31374}]}]}
{"op":"mcm","clk":"11919299930","pt":1724102169188,"mc":[{"id":"1.231851789","rc":[{"batb":[[0,1.5,20],[1,1.1,200],[2,1.03,200]],"ltp":0.0,"tv":0.0,"id":2780},{"batb":[[0,1.51,16.82]],"ltp":0.0,"tv":0.0,"id":31374}]}]}
{"op":"mcm","clk":"11919299942","pt":1724102169343,"mc":[{"id":"1.231851789","rc":[{"batb":[[0,1.5,20],[1,1.1,200],[2,1.03,200]],"ltp":0.0,"tv":0.0,"id":31374}]}]}
{"op":"mcm","clk":"11919305729","pt":1724102314521,"mc":[{"id":"1.231851789","rc":[{"batb":[[0,1.51,16.82],[1,1.5,20],[2,1.1,200]],"ltp":0.0,"tv":0.0,"id":2780},{"batb":[[0,1.51,16.82],[1,1.5,20],[2,1.1,200]],"ltp":0.0,"tv":0.0,"id":31374}]}]}
{"op":"mcm","clk":"11919384368","pt":1724104114909,"mc":[{"id":"1.231851789","rc":[{"batb":[[0,1.5,20],[1,1.1,200],[2,1.03,200]],"ltp":0.0,"tv":0.0,"id":2780},{"batb":[[0,1.5,20],[1,1.1,200],[2,1.03,200]],"ltp":0.0,"tv":0.0,"id":31374}]}]}
{"op":"mcm","clk":"11919389275","pt":1724104235319,"mc":[{"id":"1.231851789","rc":[{"batb":[[0,1.51,16.82],[1,1.5,20],[2,1.1,200]],"ltp":0.0,"tv":0.0,"id":2780},{"batb":[[0,1.51,16.82],[1,1.5,20],[2,1.1,200]],"ltp":0.0,"tv":0.0,"id":31374}]}]}
{"op":"mcm","clk":"11919466976","pt":1724106035756,"mc":[{"id":"1.231851789","rc":[{"batb":[[0,1.5,20],[1,1.1,200],[2,1.03,200]],"ltp":0.0,"tv":0.0,"id":2780},{"batb":[[0,1.41,20.52]],"ltp":1.41,"tv":2.07,"id":60443},{"batb":[[0,1.5,20],[1,1.1,200],[2,1.03,200]],"ltp":0.0,"tv":0.0,"id":31374}]}]}
{"op":"mcm","clk":"11919471010","pt":1724106132067,"mc":[{"id":"1.231851789","rc":[{"batb":[[0,1.51,16.82],[1,1.5,20],[2,1.1,200]],"ltp":0.0,"tv":0.0,"id":2780},{"batb":[[0,1.51,16.82],[1,1.5,20],[2,1.1,200]],"ltp":0.0,"tv":0.0,"id":31374}]}]}
{"op":"mcm","clk":"11919565762","pt":1724107932551,"mc":[{"id":"1.231851789","rc":[{"batb":[[0,1.5,20],[1,1.1,200],[2,1.03,200]],"ltp":0.0,"tv":0.0,"id":2780},{"batb":[[0,1.5,20],[1,1.1,200],[2,1.03,200]],"ltp":0.0,"tv":0.0,"id":31374}]}]}
{"op":"mcm","clk":"11919569867","pt":1724108013538,"mc":[{"id":"1.231851789","rc":[{"batb":[[0,1.51,16.82],[1,1.5,20],[2,1.1,200]],"ltp":0.0,"tv":0.0,"id":2780},{"batb":[[0,1.51,16.82],[1,1.5,20],[2,1.1,200]],"ltp":0.0,"tv":0.0,"id":31374}]}]}
{"op":"mcm","clk":"11919633101","pt":1724109174959,"mc":[{"id":"1.231851789","rc":[{"batb":[[0,1.41,20.52]],"ltp":1.41,"tv":2.07,"id":60443}]}]}
{"op":"mcm","clk":"11919669330","pt":1724109814092,"mc":[{"id":"1.231851789","rc":[{"batb":[[0,1.5,20],[1,1.1,200],[2,1.03,200]],"ltp":0.0,"tv":0.0,"id":2780},{"batb":[[0,1.5,20],[1,1.1,200],[2,1.03,200]],"ltp":0.0,"tv":0.0,"id":31374}]}]}
{"op":"mcm","clk":"11919673107","pt":1724109886489,"mc":[{"id":"1.231851789","rc":[{"batb":[[0,1.51,16.82],[1,1.5,20],[2,1.1,200]],"ltp":0.0,"tv":0.0,"id":2780},{"batb":[[0,1.51,16.82],[1,1.5,20],[2,1.1,200]],"ltp":0.0,"tv":0.0,"id":31374}]}]}
{"op":"mcm","clk":"11919769283","pt":1724111686969,"mc":[{"id":"1.231851789","rc":[{"batb":[[0,1.5,20],[1,1.1,200],[2,1.03,200]],"ltp":0.0,"tv":0.0,"id":2780},{"batb":[[0,1.5,20],[1,1.1,200],[2,1.03,200]],"ltp":0.0,"tv":0.0,"id":31374}]}]}
{"op":"mcm","clk":"11919772428","pt":1724111740317,"mc":[{"id":"1.231851789","rc":[{"batb":[[0,1.51,16.82],[1,1.5,20],[2,1.1,200]],"ltp":0.0,"tv":0.0,"id":2780},{"batb":[[0,1.51,16.82],[1,1.5,20],[2,1.1,200]],"ltp":0.0,"tv":0.0,"id":31374}]}]}
{"op":"mcm","clk":"11919871445","pt":1724113540734,"mc":[{"id":"1.231851789","rc":[{"batb":[[0,1.5,20],[1,1.1,200],[2,1.03,200]],"ltp":0.0,"tv":0.0,"id":2780},{"batb":[[0,1.5,20],[1,1.1,200],[2,1.03,200]],"ltp":0.0,"tv":0.0,"id":31374}]}]}
{"op":"mcm","clk":"11919872875","pt":1724113570284,"mc":[{"id":"1.231851789","rc":[{"batb":[[0,1.51,16.82],[1,1.5,20],[2,1.1,200]],"ltp":0.0,"tv":0.0,"id":2780},{"batb":[[0,1.51,16.82],[1,1.5,20],[2,1.1,200]],"ltp":0.0,"tv":0.0,"id":31374}]}]}
{"op":"mcm","clk":"11919964820","pt":1724115370683,"mc":[{"id":"1.231851789","rc":[{"batb":[[0,1.5,20],[1,1.1,200],[2,1.03,200]],"ltp":0.0,"tv":0.0,"id":2780},{"batb":[[0,1.5,20],[1,1.1,200],[2,1.03,200]],"ltp":0.0,"tv":0.0,"id":31374}]}]}
{"op":"mcm","clk":"11919965071","pt":1724115376737,"mc":[{"id":"1.231851789","rc":[{"batb":[[0,1.51,16.82],[1,1.5,20],[2,1.1,200]],"ltp":0.0,"tv":0.0,"id":2780},{"batb":[[0,1.51,16.82],[1,1.5,20],[2,1.1,200]],"ltp":0.0,"tv":0.0,"id":31374}]}]}
{"op":"mcm","clk":"11920050173","pt":1724117177134,"mc":[{"id":"1.231851789","rc":[{"batb":[[0,1.5,20],[1,1.1,200],[2,1.03,200]],"ltp":0.0,"tv":0.0,"id":2780},{"batb":[[0,1.5,20],[1,1.1,200],[2,1.03,200]],"ltp":0.0,"tv":0.0,"id":31374}]}]}
{"op":"mcm","clk":"11920056091","pt":1724117300986,"mc":[{"id":"1.231851789","rc":[{"batb":[[0,1.51,16.82],[1,1.5,20],[2,1.1,200]],"ltp":0.0,"tv":0.0,"id":2780},{"batb":[[0,1.51,16.82],[1,1.5,20],[2,1.1,200]],"ltp":0.0,"tv":0.0,"id":31374}]}]}
{"op":"mcm","clk":"11920148338","pt":1724119101221,"mc":[{"id":"1.231851789","rc":[{"batb":[[0,1.5,20],[1,1.1,200],[2,1.03,200]],"ltp":0.0,"tv":0.0,"id":31374}]}]}
{"op":"mcm","clk":"11920148350","pt":1724119101430,"mc":[{"id":"1.231851789","rc":[{"batb":[[0,1.5,20],[1,1.1,200],[2,1.03,200]],"ltp":0.0,"tv":0.0,"id":2780}]}]}
{"op":"mcm","clk":"11920152689","pt":1724119183154,"mc":[{"id":"1.231851789","rc":[{"batb":[[0,1.51,16.82],[1,1.5,20],[2,1.1,200]],"ltp":0.0,"tv":0.0,"id":2780},{"batb":[[0,1.51,16.82],[1,1.5,20],[2,1.1,200]],"ltp":0.0,"tv":0.0,"id":31374}]}]}
{"op":"mcm","clk":"11920194319","pt":1724119975005,"mc":[{"id":"1.231851789","rc":[{"batb":[[0,1.51,16.82]],"ltp":0.0,"tv":0.0,"id":2780},{"batb":[[0,1.41,20.53]],"ltp":1.41,"tv":2.08,"id":60443},{"batb":[[0,1.51,16.82]],"ltp":0.0,"tv":0.0,"id":31374}]}]}
{"op":"mcm","clk":"11920236639","pt":1724120983511,"mc":[{"id":"1.231851789","rc":[{"batb":[[0,1.5,20],[1,1.1,200],[2,1.03,200]],"ltp":0.0,"tv":0.0,"id":2780},{"batb":[[0,1.5,20],[1,1.1,200],[2,1.03,200]],"ltp":0.0,"tv":0.0,"id":31374}]}]}
{"op":"mcm","clk":"11920238519","pt":1724121043061,"mc":[{"id":"1.231851789","rc":[{"batb":[[0,1.51,16.82],[1,1.5,20],[2,1.1,200]],"ltp":0.0,"tv":0.0,"id":2780},{"batb":[[0,1.51,16.82],[1,1.5,20],[2,1.1,200]],"ltp":0.0,"tv":0.0,"id":31374}]}]}
{"op":"mcm","clk":"11920330815","pt":1724123615109,"mc":[{"id":"1.231851789","rc":[{"batb":[[0,1.5,20],[1,1.1,200],[2,1.03,200]],"ltp":0.0,"tv":0.0,"id":2780},{"batb":[[0,1.41,20.52]],"ltp":1.41,"tv":2.08,"id":60443},{"batb":[[0,1.51,16.82]],"ltp":0.0,"tv":0.0,"id":31374}]}]}
{"op":"mcm","clk":"11920330826","pt":1724123615415,"mc":[{"id":"1.231851789","rc":[{"batb":[[0,1.5,20],[1,1.1,200],[2,1.03,200]],"ltp":0.0,"tv":0.0,"id":31374}]}]}
{"op":"mcm","clk":"11920334399","pt":1724123738877,"mc":[{"id":"1.231851789","rc":[{"batb":[[0,1.51,16.82],[1,1.5,20],[2,1.1,200]],"ltp":0.0,"tv":0.0,"id":2780},{"batb":[[0,1.51,16.82],[1,1.5,20],[2,1.1,200]],"ltp":0.0,"tv":0.0,"id":31374}]}]}
{"op":"mcm","clk":"11920394517","pt":1724125539078,"mc":[{"id":"1.231851789","rc":[{"batb":[[0,1.5,20],[1,1.1,200],[2,1.03,200]],"ltp":0.0,"tv":0.0,"id":31374}]}]}
{"op":"mcm","clk":"11920394528","pt":1724125539792,"mc":[{"id":"1.231851789","rc":[{"batb":[[0,1.5,20],[1,1.1,200],[2,1.03,200]],"ltp":0.0,"tv":0.0,"id":2780}]}]}
{"op":"mcm","clk":"11920394951","pt":1724125556123,"mc":[{"id":"1.231851789","rc":[{"batb":[[0,1.51,16.82],[1,1.5,20],[2,1.1,200]],"ltp":0.0,"tv":0.0,"id":2780},{"batb":[[0,1.51,16.82],[1,1.5,20],[2,1.1,200]],"ltp":0.0,"tv":0.0,"id":31374}]}]}
{"op":"mcm","clk":"11920451321","pt":1724127356525,"mc":[{"id":"1.231851789","rc":[{"batb":[[0,1.5,20],[1,1.1,200],[2,1.03,200]],"ltp":0.0,"tv":0.0,"id":2780},{"batb":[[0,1.5,20],[1,1.1,200],[2,1.03,200]],"ltp":0.0,"tv":0.0,"id":31374}]}]}
{"op":"mcm","clk":"11920451468","pt":1724127361844,"mc":[{"id":"1.231851789","rc":[{"batb":[[0,1.51,16.82],[1,1.5,20],[2,1.1,200]],"ltp":0.0,"tv":0.0,"id":2780},{"batb":[[0,1.51,16.82],[1,1.5,20],[2,1.1,200]],"ltp":0.0,"tv":0.0,"id":31374}]}]}
{"op":"mcm","clk":"11920511144","pt":1724129163066,"mc":[{"id":"1.231851789","rc":[{"batb":[[0,1.5,20],[1,1.1,200],[2,1.03,200]],"ltp":0.0,"tv":0.0,"id":2780},{"batb":[[0,1.5,20],[1,1.1,200],[2,1.03,200]],"ltp":0.0,"tv":0.0,"id":31374}]}]}
{"op":"mcm","clk":"11920515778","pt":1724129312412,"mc":[{"id":"1.231851789","rc":[{"batb":[[0,1.51,16.82],[1,1.5,20],[2,1.1,200]],"ltp":0.0,"tv":0.0,"id":2780},{"batb":[[0,1.51,16.82],[1,1.5,20],[2,1.1,200]],"ltp":0.0,"tv":0.0,"id":31374}]}]}
{"op":"mcm","clk":"11920593968","pt":1724131112783,"mc":[{"id":"1.231851789","rc":[{"batb":[[0,1.5,20],[1,1.1,200],[2,1.03,200]],"ltp":0.0,"tv":0.0,"id":2780},{"batb":[[0,1.5,20],[1,1.1,200],[2,1.03,200]],"ltp":0.0,"tv":0.0,"id":31374}]}]}
{"op":"mcm","clk":"11920595816","pt":1724131179241,"mc":[{"id":"1.231851789","rc":[{"batb":[[0,1.51,16.82],[1,1.5,20],[2,1.1,200]],"ltp":0.0,"tv":0.0,"id":31374}]}]}
{"op":"mcm","clk":"11920595819","pt":1724131179342,"mc":[{"id":"1.231851789","rc":[{"batb":[[0,1.51,16.82],[1,1.5,20],[2,1.1,200]],"ltp":0.0,"tv":0.0,"id":2780}]}]}
{"op":"mcm","clk":"11920659911","pt":1724132979559,"mc":[{"id":"1.231851789","rc":[{"batb":[[0,1.5,20],[1,1.1,200],[2,1.03,200]],"ltp":0.0,"tv":0.0,"id":2780},{"batb":[[0,1.5,20],[1,1.1,200],[2,1.03,200]],"ltp":0.0,"tv":0.0,"id":31374}]}]}
{"op":"mcm","clk":"11920663077","pt":1724133046031,"mc":[{"id":"1.231851789","rc":[{"batb":[[0,1.51,16.82],[1,1.5,20],[2,1.1,200]],"ltp":0.0,"tv":0.0,"id":2780},{"batb":[[0,1.51,16.82],[1,1.5,20],[2,1.1,200]],"ltp":0.0,"tv":0.0,"id":31374}]}]}
{"op":"mcm","clk":"11920716988","pt":1724134846214,"mc":[{"id":"1.231851789","rc":[{"batb":[[0,1.51,16.82]],"ltp":0.0,"tv":0.0,"id":2780},{"batb":[[0,1.41,20.52]],"ltp":1.41,"tv":2.08,"id":60443},{"batb":[[0,1.5,20],[1,1.1,200],[2,1.03,200]],"ltp":0.0,"tv":0.0,"id":31374}]}]}
{"op":"mcm","clk":"11920716994","pt":1724134846419,"mc":[{"id":"1.231851789","rc":[{"batb":[[0,1.5,20],[1,1.1,200],[2,1.03,200]],"ltp":0.0,"tv":0.0,"id":2780}]}]}
{"op":"mcm","clk":"11920718695","pt":1724134911591,"mc":[{"id":"1.231851789","rc":[{"batb":[[0,1.51,16.82],[1,1.5,20],[2,1.1,200]],"ltp":0.0,"tv":0.0,"id":2780},{"batb":[[0,1.51,16.82],[1,1.5,20],[2,1.1,200]],"ltp":0.0,"tv":0.0,"id":31374}]}]}
{"op":"mcm","clk":"11920783432","pt":1724136712228,"mc":[{"id":"1.231851789","rc":[{"batb":[[0,1.5,20],[1,1.1,200],[2,1.03,200]],"ltp":0.0,"tv":0.0,"id":2780},{"batb":[[0,1.5,20],[1,1.1,200],[2,1.03,200]],"ltp":0.0,"tv":0.0,"id":31374}]}]}
{"op":"mcm","clk":"11920785240","pt":1724136775804,"mc":[{"id":"1.231851789","rc":[{"batb":[[0,1.51,16.82],[1,1.5,20],[2,1.1,200]],"ltp":0.0,"tv":0.0,"id":2780},{"batb":[[0,1.51,16.82],[1,1.5,20],[2,1.1,200]],"ltp":0.0,"tv":0.0,"id":31374}]}]}
{"op":"mcm","clk":"11920846317","pt":1724138576004,"mc":[{"id":"1.231851789","rc":[{"batb":[[0,1.51,16.81]],"ltp":0.0,"tv":0.0,"id":2780},{"trd":[[1.41,2.08]],"batb":[[0,1.41,20.51]],"ltp":1.41,"tv":2.07,"id":60443},{"batb":[[0,1.5,20],[1,1.1,200],[2,1.03,200]],"ltp":0.0,"tv":0.0,"id":31374}],"tv":2.07}]}
{"op":"mcm","clk":"11920846333","pt":1724138576619,"mc":[{"id":"1.231851789","rc":[{"batb":[[0,1.5,20],[1,1.1,200],[2,1.03,200]],"ltp":0.0,"tv":0.0,"id":2780}]}]}
{"op":"mcm","clk":"11920848367","pt":1724138638663,"mc":[{"id":"1.231851789","rc":[{"batb":[[0,1.51,16.81],[1,1.5,20],[2,1.1,200]],"ltp":0.0,"tv":0.0,"id":2780},{"batb":[[0,1.51,16.81],[1,1.5,20],[2,1.1,200]],"ltp":0.0,"tv":0.0,"id":31374}]}]}
{"op":"mcm","clk":"11920902613","pt":1724140438896,"mc":[{"id":"1.231851789","rc":[{"batb":[[0,1.5,20],[1,1.1,200],[2,1.03,200]],"ltp":0.0,"tv":0.0,"id":2780},{"batb":[[0,1.5,20],[1,1.1,200],[2,1.03,200]],"ltp":0.0,"tv":0.0,"id":31374}]}]}
{"op":"mcm","clk":"11920904865","pt":1724140502884,"mc":[{"id":"1.231851789","rc":[{"batb":[[0,1.51,16.81],[1,1.5,20],[2,1.1,200]],"ltp":0.0,"tv":0.0,"id":2780},{"batb":[[0,1.51,16.81],[1,1.5,20],[2,1.1,200]],"ltp":0.0,"tv":0.0,"id":31374}]}]}
{"op":"mcm","clk":"11920941575","pt":1724141575013,"mc":[{"id":"1.231851789","rc":[{"batb":[[0,1.51,16.8]],"ltp":0.0,"tv":0.0,"id":2780},{"batb":[[0,1.41,20.51]],"ltp":1.41,"tv":2.07,"id":60443},{"batb":[[0,1.51,16.8]],"ltp":0.0,"tv":0.0,"id":31374}]}]}
{"op":"mcm","clk":"11920965881","pt":1724142303140,"mc":[{"id":"1.231851789","rc":[{"batb":[[0,1.5,20],[1,1.1,200],[2,1.03,200]],"ltp":0.0,"tv":0.0,"id":2780},{"batb":[[0,1.5,20],[1,1.1,200],[2,1.03,200]],"ltp":0.0,"tv":0.0,"id":31374}]}]}
{"op":"mcm","clk":"11920969924","pt":1724142440096,"mc":[{"id":"1.231851789","rc":[{"batb":[[0,1.51,16.8],[1,1.5,20],[2,1.1,200]],"ltp":0.0,"tv":0.0,"id":2780},{"batb":[[0,1.51,16.8],[1,1.5,20],[2,1.1,200]],"ltp":0.0,"tv":0.0,"id":31374}]}]}
{"op":"mcm","clk":"11921033611","pt":1724144240202,"mc":[{"id":"1.231851789","rc":[{"batb":[[0,1.5,20],[1,1.1,200],[2,1.03,200]],"ltp":0.0,"tv":0.0,"id":2780}]}]}
{"op":"mcm","clk":"11921033625","pt":1724144240356,"mc":[{"id":"1.231851789","rc":[{"batb":[[0,1.5,20],[1,1.1,200],[2,1.03,200]],"ltp":0.0,"tv":0.0,"id":31374}]}]}
{"op":"mcm","clk":"11921034857","pt":1724144283820,"mc":[{"id":"1.231851789","rc":[{"batb":[[0,1.51,16.8],[1,1.5,20],[2,1.1,200]],"ltp":0.0,"tv":0.0,"id":2780},{"batb":[[0,1.51,16.8],[1,1.5,20],[2,1.1,200]],"ltp":0.0,"tv":0.0,"id":31374}]}]}
{"op":"mcm","clk":"11921099859","pt":1724146084090,"mc":[{"id":"1.231851789","rc":[{"batb":[[0,1.5,20],[1,1.1,200],[2,1.03,200]],"ltp":0.0,"tv":0.0,"id":2780},{"batb":[[0,1.41,20.5]],"ltp":1.41,"tv":2.07,"id":60443},{"batb":[[0,1.5,20],[1,1.1,200],[2,1.03,200]],"ltp":0.0,"tv":0.0,"id":31374}]}]}
{"op":"mcm","clk":"11921101349","pt":1724146121128,"mc":[{"id":"1.231851789","rc":[{"batb":[[0,1.51,16.8],[1,1.5,20],[2,1.1,200]],"ltp":0.0,"tv":0.0,"id":2780},{"batb":[[0,1.51,16.8],[1,1.5,20],[2,1.1,200]],"ltp":0.0,"tv":0.0,"id":31374}]}]}
{"op":"mcm","clk":"11921185698","pt":1724147921925,"mc":[{"id":"1.231851789","rc":[{"batb":[[0,1.5,20],[1,1.1,200],[2,1.03,200]],"ltp":0.0,"tv":0.0,"id":2780},{"batb":[[0,1.5,20],[1,1.1,200],[2,1.03,200]],"ltp":0.0,"tv":0.0,"id":31374}]}]}
{"op":"mcm","clk":"11921186823","pt":1724147952967,"mc":[{"id":"1.231851789","rc":[{"batb":[[0,1.51,16.8],[1,1.5,20],[2,1.1,200]],"ltp":0.0,"tv":0.0,"id":2780},{"batb":[[0,1.51,16.8],[1,1.5,20],[2,1.1,200]],"ltp":0.0,"tv":0.0,"id":31374}]}]}
{"op":"mcm","clk":"11921271003","pt":1724149753170,"mc":[{"id":"1.231851789","rc":[{"batb":[[0,1.51,16.79]],"ltp":0.0,"tv":0.0,"id":2780},{"batb":[[0,1.41,20.49]],"ltp":1.41,"tv":2.07,"id":60443},{"batb":[[0,1.5,20],[1,1.1,200],[2,1.03,200]],"ltp":0.0,"tv":0.0,"id":31374}]}]}
{"op":"mcm","clk":"11921271009","pt":1724149753375,"mc":[{"id":"1.231851789","rc":[{"batb":[[0,1.5,20],[1,1.1,200],[2,1.03,200]],"ltp":0.0,"tv":0.0,"id":2780}]}]}
{"op":"mcm","clk":"11921272365","pt":1724149784811,"mc":[{"id":"1.231851789","rc":[{"batb":[[0,1.51,16.79],[1,1.5,20],[2,1.1,200]],"ltp":0.0,"tv":0.0,"id":2780},{"batb":[[0,1.51,16.79],[1,1.5,20],[2,1.1,200]],"ltp":0.0,"tv":0.0,"id":31374}]}]}
{"op":"mcm","clk":"11921349544","pt":1724151584999,"mc":[{"id":"1.231851789","rc":[{"batb":[[0,1.5,20],[1,1.1,200],[2,1.04,1.53]],"ltp":0.0,"tv":0.0,"id":2780}]}]}
{"op":"mcm","clk":"11921349557","pt":1724151585306,"mc":[{"id":"1.231851789","rc":[{"batb":[[0,1.5,20],[1,1.1,200],[2,1.04,1.53]],"ltp":0.0,"tv":0.0,"id":31374}]}]}
{"op":"mcm","clk":"11921350319","pt":1724151600937,"mc":[{"id":"1.231851789","rc":[{"batb":[[0,1.51,16.79],[1,1.5,20],[2,1.1,200]],"ltp":0.0,"tv":0.0,"id":2780},{"batb":[[0,1.51,16.79],[1,1.5,20],[2,1.1,200]],"ltp":0.0,"tv":0.0,"id":31374}]}]}
{"op":"mcm","clk":"11921389467","pt":1724152374962,"mc":[{"id":"1.231851789","rc":[{"batb":[[0,1.51,16.79]],"ltp":0.0,"tv":0.0,"id":2780},{"batb":[[0,1.41,20.5]],"ltp":1.41,"tv":2.07,"id":60443},{"batb":[[0,1.51,16.79]],"ltp":0.0,"tv":0.0,"id":31374}]}]}
{"op":"mcm","clk":"11921438130","pt":1724153401162,"mc":[{"id":"1.231851789","rc":[{"batb":[[0,1.5,20],[1,1.1,200],[2,1.04,1.53]],"ltp":0.0,"tv":0.0,"id":2780},{"batb":[[0,1.5,20],[1,1.1,200],[2,1.04,1.53]],"ltp":0.0,"tv":0.0,"id":31374}]}]}
{"op":"mcm","clk":"11921438236","pt":1724153402936,"mc":[{"id":"1.231851789","rc":[{"batb":[[0,1.51,16.79],[1,1.5,20],[2,1.1,200]],"ltp":0.0,"tv":0.0,"id":2780},{"batb":[[0,1.51,16.79],[1,1.5,20],[2,1.1,200]],"ltp":0.0,"tv":0.0,"id":31374}]}]}
{"op":"mcm","clk":"11921517247","pt":1724155206584,"mc":[{"id":"1.231851789","rc":[{"batb":[[0,1.5,20],[1,1.1,200],[2,1.04,1.53]],"ltp":0.0,"tv":0.0,"id":2780},{"trd":[[1.41,2.08]],"batb":[[0,1.41,20.48]],"ltp":1.41,"tv":2.07,"id":60443},{"batb":[[0,1.5,20],[1,1.1,200],[2,1.04,1.53]],"ltp":0.0,"tv":0.0,"id":31374}],"tv":2.07}]}
{"op":"mcm","clk":"11921523914","pt":1724155343720,"mc":[{"id":"1.231851789","rc":[{"batb":[[0,1.51,16.78],[1,1.5,20],[2,1.1,200]],"ltp":0.0,"tv":0.0,"id":2780},{"batb":[[0,1.51,16.78],[1,1.5,20],[2,1.1,200]],"ltp":0.0,"tv":0.0,"id":31374}]}]}
{"op":"mcm","clk":"11921611612","pt":1724157144032,"mc":[{"id":"1.231851789","rc":[{"batb":[[0,1.5,20],[1,1.1,200],[2,1.04,1.53]],"ltp":0.0,"tv":0.0,"id":2780},{"batb":[[0,1.5,20],[1,1.1,200],[2,1.04,1.53]],"ltp":0.0,"tv":0.0,"id":31374}]}]}
{"op":"mcm","clk":"11921613366","pt":1724157178784,"mc":[{"id":"1.231851789","rc":[{"batb":[[0,1.51,16.78],[1,1.5,20],[2,1.1,200]],"ltp":0.0,"tv":0.0,"id":2780},{"batb":[[0,1.51,16.78],[1,1.5,20],[2,1.1,200]],"ltp":0.0,"tv":0.0,"id":31374}]}]}
{"op":"mcm","clk":"11921641693","pt":1724157699773,"mc":[{"id":"1.231851789","rc":[{"batb":[[0,1.42,40.89],[1,1.41,19.59]],"ltp":1.41,"tv":2.07,"id":60443}]}]}
{"op":"mcm","clk":"11921644177","pt":1724157751559,"mc":[{"id":"1.231851789","rc":[{"batl":[[0,14,6],[1,95,5.85],[2,990,5]],"ltp":0.0,"tv":0.0,"id":2780},{"batl":[[0,12.5,8],[1,95,5.85],[2,990,5]],"ltp":0.0,"tv":0.0,"id":31374}]}]}
{"op":"mcm","clk":"11921714366","pt":1724158979058,"mc":[{"id":"1.231851789","rc":[{"trd":[[1.41,2.07]],"batb":[[0,1.42,40.89],[1,1.41,19.59]],"ltp":1.41,"tv":2.07,"id":60443},{"batb":[[0,1.5,20],[1,1.1,200],[2,1.04,1.53]],"ltp":0.0,"tv":0.0,"id":31374}],"tv":2.07}]}
{"op":"mcm","clk":"11921714392","pt":1724158979625,"mc":[{"id":"1.231851789","rc":[{"batb":[[0,1.5,20],[1,1.1,200],[2,1.04,1.53]],"ltp":0.0,"tv":0.0,"id":2780}]}]}
{"op":"mcm","clk":"11921715540","pt":1724159001457,"mc":[{"id":"1.231851789","rc":[{"batb":[[0,1.51,16.79],[1,1.5,20],[2,1.1,200]],"ltp":0.0,"tv":0.0,"id":2780},{"batb":[[0,1.51,16.79],[1,1.5,20],[2,1.1,200]],"ltp":0.0,"tv":0.0,"id":31374}]}]}
{"op":"mcm","clk":"11921815643","pt":1724160801663,"mc":[{"id":"1.231851789","rc":[{"batb":[[0,1.5,20],[1,1.1,200],[2,1.04,1.53]],"ltp":0.0,"tv":0.0,"id":2780},{"batb":[[0,1.5,20],[1,1.1,200],[2,1.04,1.53]],"ltp":0.0,"tv":0.0,"id":31374}]}]}
{"op":"mcm","clk":"11921816210","pt":1724160813010,"mc":[{"id":"1.231851789","rc":[{"batb":[[0,1.51,16.79],[1,1.5,20],[2,1.1,200]],"ltp":0.0,"tv":0.0,"id":2780},{"batb":[[0,1.51,16.79],[1,1.5,20],[2,1.1,200]],"ltp":0.0,"tv":0.0,"id":31374}]}]}
{"op":"mcm","clk":"11921851934","pt":1724161517746,"mc":[{"id":"1.231851789","rc":[{"batl":[[0,1.9,1.5],[1,12.5,8],[2,95,5.85]],"ltp":0.0,"tv":0.0,"id":31374}]}]}
{"op":"mcm","clk":"11921857326","pt":1724161626958,"mc":[{"id":"1.231851789","rc":[{"batl":[[0,1.8,1.5]],"ltp":0.0,"tv":0.0,"id":31374}]}]}
{"op":"mcm","clk":"11921911875","pt":1724162613157,"mc":[{"id":"1.231851789","rc":[{"batb":[[0,1.51,16.79]],"ltp":0.0,"tv":0.0,"id":2780},{"batb":[[1,1.41,19.6]],"ltp":1.41,"tv":2.07,"id":60443},{"batb":[[0,1.5,20],[1,1.1,200],[2,1.04,1.53]],"ltp":0.0,"tv":0.0,"id":31374}]}]}
{"op":"mcm","clk":"11921911905","pt":1724162613569,"mc":[{"id":"1.231851789","rc":[{"batb":[[0,1.5,20],[1,1.1,200],[2,1.04,1.53]],"ltp":0.0,"tv":0.0,"id":2780}]}]}
{"op":"mcm","clk":"11921912089","pt":1724162616973,"mc":[{"id":"1.231851789","rc":[{"batb":[[0,1.51,16.79],[1,1.5,20],[2,1.1,200]],"ltp":0.0,"tv":0.0,"id":2780},{"batb":[[0,1.51,16.79],[1,1.5,20],[2,1.1,200]],"ltp":0.0,"tv":0.0,"id":31374}]}]}
{"op":"mcm","clk":"11921913360","pt":1724162637385,"mc":[{"id":"1.231851789","rc":[{"batl":[[1,1.9,1],[2,12.5,8]],"ltp":0.0,"tv":0.0,"id":31374}]}]}
{"op":"mcm","clk":"11921917468","pt":1724162707787,"mc":[{"id":"1.231851789","rc":[{"batl":[[0,1.8,2.5],[1,12.5,8],[2,95,5.85]],"ltp":0.0,"tv":0.0,"id":31374}]}]}
{"op":"mcm","clk":"11921964382","pt":1724163350922,"mc":[{"id":"1.231851789","rc":[{"batb":[[0,1.42,40]],"ltp":1.41,"tv":2.07,"id":60443}]}]}
{"op":"mcm","clk":"11921965129","pt":1724163366431,"mc":[{"id":"1.231851789","rc":[{"trd":[[1.8,1.78]],"batl":[[0,1.8,1.61]],"ltp":1.8,"tv":1.78,"id":31374}],"tv":3.85}]}
{"op":"mcm","clk":"11921970155","pt":1724163468267,"mc":[{"id":"1.231851789","rc":[{"batl":[[0,1.7,1],[1,12.5,8.61]],"ltp":1.8,"tv":1.78,"id":31374}]}]}
{"op":"mcm","clk":"11921973537","pt":1724163540843,"mc":[{"id":"1.231851789","rc":[{"trd":[[1.7,1.78]],"batl":[[0,12.5,8.72],[1,95,5.85],[2,990,5]],"ltp":1.7,"tv":3.56,"id":31374}],"tv":5.64}]}
{"op":"mcm","clk":"11922017331","pt":1724164308349,"mc":[{"id":"1.231851789","rc":[{"batl":[[0,1.9,1.72],[1,12.5,8],[2,95,5.85]],"ltp":1.7,"tv":3.56,"id":31374}]}]}
{"op":"mcm","clk":"11922019506","pt":1724164348093,"mc":[{"id":"1.231851789","rc":[{"batl":[[0,1.8,1.72]],"ltp":1.7,"tv":3.56,"id":31374}]}]}
{"op":"mcm","clk":"11922023517","pt":1724164417161,"mc":[{"id":"1.231851789","rc":[{"batb":[[0,1.5,20],[1,1.1,200],[2,1.04,1.53]],"ltp":0.0,"tv":0.0,"id":2780}]}]}
{"op":"mcm","clk":"11922023525","pt":1724164417365,"mc":[{"id":"1.231851789","rc":[{"batb":[[0,1.5,20],[1,1.1,200],[2,1.04,1.53]],"ltp":1.7,"tv":3.56,"id":31374}]}]}
{"op":"mcm","clk":"11922032961","pt":1724164574669,"mc":[{"id":"1.231851789","rc":[{"batb":[[0,1.51,16.79],[1,1.5,20],[2,1.1,200]],"ltp":0.0,"tv":0.0,"id":2780},{"batb":[[0,1.51,16.79],[1,1.5,20],[2,1.1,200]],"ltp":1.7,"tv":3.56,"id":31374}]}]}
{"op":"mcm","clk":"11922124247","pt":1724166220855,"mc":[{"id":"1.231851789","rc":[{"batb":[[0,1.51,16.8]],"ltp":0.0,"tv":0.0,"id":2780},{"batb":[[1,1.41,19.61]],"ltp":1.41,"tv":2.07,"id":60443},{"trd":[[1.7,2],[1.8,5]],"batb":[[0,1.51,16.8]],"batl":[[0,12.5,8],[1,95,5.85],[2,990,5]],"ltp":1.8,"tv":7.0,"id":31374}],"tv":9.07}]}
{"op":"mcm","clk":"11922125366","pt":1724166234883,"mc":[{"id":"1.231851789","rc":[{"batl":[[0,12.5,8.97]],"ltp":1.8,"tv":7.0,"id":31374}]}]}
{"op":"mcm","clk":"11922130609","pt":1724166308073,"mc":[{"id":"1.231851789","rc":[{"batl":[[2,1000,0.85]],"ltp":1.41,"tv":2.07,"id":60443}]}]}
{"op":"mcm","clk":"11922130698","pt":1724166308999,"mc":[{"id":"1.231851789","rc":[{"batl":[[1,90,1.02],[2,95,5]],"ltp":0.0,"tv":0.0,"id":2780},{"batl":[[0,90,1.02],[1,95,5],[2,990,5]],"ltp":1.41,"tv":2.07,"id":60443},{"batl":[[1,90,1.02],[2,95,5]],"ltp":1.8,"tv":7.0,"id":31374}]}]}
{"op":"mcm","clk":"11922135818","pt":1724166374949,"mc":[{"id":"1.231851789","rc":[{"batb":[[0,1.5,20],[1,1.1,200],[2,1.04,1.53]],"ltp":0.0,"tv":0.0,"id":2780},{"batb":[[0,1.5,20],[1,1.1,200],[2,1.04,1.53]],"ltp":1.8,"tv":7.0,"id":31374}]}]}
{"op":"mcm","clk":"11922136951","pt":1724166390561,"mc":[{"id":"1.231851789","rc":[{"batl":[[2,990,5.17]],"ltp":1.41,"tv":2.07,"id":60443}]}]}
{"op":"mcm","clk":"11922137500","pt":1724166398166,"mc":[{"id":"1.231851789","rc":[{"batl":[[2,990,5.34]],"ltp":1.41,"tv":2.07,"id":60443}]}]}
{"op":"mcm","clk":"11922143136","pt":1724166479247,"mc":[{"id":"1.231851789","rc":[{"batl":[[2,990,5.51]],"ltp":1.41,"tv":2.07,"id":60443}]}]}
{"op":"mcm","clk":"11922145730","pt":1724166514772,"mc":[{"id":"1.231851789","rc":[{"batb":[[0,1.56,15.3],[1,1.5,20],[2,1.1,200]],"ltp":0.0,"tv":0.0,"id":2780},{"batb":[[0,1.51,16.8],[1,1.5,20],[2,1.1,200]],"ltp":1.8,"tv":7.0,"id":31374}]}]}
{"op":"mcm","clk":"11922261018","pt":1724168074476,"mc":[{"id":"1.231851789","rc":[{"batl":[[0,10,1.42],[1,12.5,8],[2,90,1.02]],"ltp":1.8,"tv":7.0,"id":31374}]}]}
{"op":"mcm","clk":"11922262102","pt":1724168088587,"mc":[{"id":"1.231851789","rc":[{"batl":[[0,8,1.42]],"ltp":1.8,"tv":7.0,"id":31374}]}]}
{"op":"mcm","clk":"11922263118","pt":1724168101138,"mc":[{"id":"1.231851789","rc":[{"batl":[[0,8,1.33]],"ltp":1.8,"tv":7.0,"id":31374}]}]}
{"op":"mcm","clk":"11922264757","pt":1724168121045,"mc":[{"id":"1.231851789","rc":[{"batl":[[0,8,1.24]],"ltp":1.8,"tv":7.0,"id":31374}]}]}
{"op":"mcm","clk":"11922266296","pt":1724168139578,"mc":[{"id":"1.231851789","rc":[{"batl":[[0,7,1.15],[1,12.5,8.27]],"ltp":1.8,"tv":7.0,"id":31374}]}]}
{"op":"mcm","clk":"11922281225","pt":1724168315225,"mc":[{"id":"1.231851789","rc":[{"batb":[[0,1.5,20],[1,1.1,200],[2,1.04,1.53]],"ltp":0.0,"tv":0.0,"id":2780},{"batb":[[0,1.5,20],[1,1.1,200],[2,1.04,1.53]],"ltp":1.8,"tv":7.0,"id":31374}]}]}
{"op":"mcm","clk":"11922292484","pt":1724168435883,"mc":[{"id":"1.231851789","rc":[{"batb":[[0,1.5,20.89]],"ltp":0.0,"tv":0.0,"id":2780}]}]}
{"op":"mcm","clk":"11922293366","pt":1724168444897,"mc":[{"id":"1.231851789","rc":[{"batb":[[0,1.56,16.2],[1,1.5,20],[2,1.1,200]],"ltp":0.0,"tv":0.0,"id":2780},{"batb":[[0,1.51,16.8],[1,1.5,20],[2,1.1,200]],"ltp":1.8,"tv":7.0,"id":31374}]}]}
{"op":"mcm","clk":"11922294414","pt":1724168455909,"mc":[{"id":"1.231851789","rc":[{"batb":[[0,1.42,40.89]],"ltp":1.41,"tv":2.07,"id":60443}]}]}
{"op":"mcm","clk":"11922472803","pt":1724170245161,"mc":[{"id":"1.231851789","rc":[{"batb":[[1,1.41,19.61]],"ltp":1.41,"tv":2.07,"id":60443},{"trd":[[1.8,5]],"batb":[[0,1.5,20],[1,1.1,200],[2,1.04,1.53]],"ltp":1.8,"tv":7.0,"id":31374}],"tv":9.07}]}
{"op":"mcm","clk":"11922472840","pt":1724170245417,"mc":[{"id":"1.231851789","rc":[{"batb":[[0,1.5,20.89],[1,1.1,200],[2,1.04,1.53]],"ltp":0.0,"tv":0.0,"id":2780}]}]}
{"op":"mcm","clk":"11922485664","pt":1724170362394,"mc":[{"id":"1.231851789","rc":[{"batb":[[0,1.56,16.2],[1,1.5,20],[2,1.1,200]],"ltp":0.0,"tv":0.0,"id":2780},{"batb":[[0,1.51,16.8],[1,1.5,20],[2,1.1,200]],"ltp":1.8,"tv":7.0,"id":31374}]}]}
{"op":"mcm","clk":"11922681873","pt":1724172162902,"mc":[{"id":"1.231851789","rc":[{"batb":[[0,1.5,20.89],[1,1.1,200],[2,1.04,1.53]],"ltp":0.0,"tv":0.0,"id":2780},{"batb":[[0,1.5,20],[1,1.1,200],[2,1.04,1.53]],"ltp":1.8,"tv":7.0,"id":31374}]}]}
{"op":"mcm","clk":"11922691560","pt":1724172256009,"mc":[{"id":"1.231851789","rc":[{"batb":[[0,1.56,16.2],[1,1.5,20],[2,1.1,200]],"ltp":0.0,"tv":0.0,"id":2780},{"batb":[[0,1.51,16.8],[1,1.5,20],[2,1.1,200]],"ltp":1.8,"tv":7.0,"id":31374}]}]}
{"op":"mcm","clk":"11922879277","pt":1724173974963,"mc":[{"id":"1.231851789","rc":[{"batb":[[0,1.56,16.21]],"ltp":0.0,"tv":0.0,"id":2780},{"batb":[[1,1.41,19.63]],"ltp":1.41,"tv":2.07,"id":60443},{"batb":[[0,1.51,16.82]],"ltp":1.8,"tv":7.0,"id":31374}]}]}
{"op":"mcm","clk":"11922892456","pt":1724174056234,"mc":[{"id":"1.231851789","rc":[{"batb":[[0,1.5,20],[1,1.1,200],[2,1.04,1.53]],"ltp":1.8,"tv":7.0,"id":31374}]}]}
{"op":"mcm","clk":"11922892476","pt":1724174056545,"mc":[{"id":"1.231851789","rc":[{"batb":[[0,1.5,20.89],[1,1.1,200],[2,1.04,1.53]],"ltp":0.0,"tv":0.0,"id":2780}]}]}
{"op":"mcm","clk":"11922901096","pt":1724174127208,"mc":[{"id":"1.231851789","rc":[{"batb":[[0,1.56,16.21],[1,1.5,20],[2,1.1,200]],"ltp":0.0,"tv":0.0,"id":2780},{"batb":[[0,1.51,16.82],[1,1.5,20],[2,1.1,200]],"ltp":1.8,"tv":7.0,"id":31374}]}]}
{"op":"mcm","clk":"11923103593","pt":1724175927563,"mc":[{"id":"1.231851789","rc":[{"batb":[[0,1.5,20.89],[1,1.1,200],[2,1.04,1.53]],"ltp":0.0,"tv":0.0,"id":2780},{"batb":[[0,1.5,20],[1,1.1,200],[2,1.04,1.53]],"ltp":1.8,"tv":7.0,"id":31374}]}]}
{"op":"mcm","clk":"11923107959","pt":1724175963197,"mc":[{"id":"1.231851789","rc":[{"batb":[[0,1.56,16.21],[1,1.5,20],[2,1.1,200]],"ltp":0.0,"tv":0.0,"id":2780},{"batb":[[0,1.51,16.82],[1,1.5,20],[2,1.1,200]],"ltp":1.8,"tv":7.0,"id":31374}]}]}
{"op":"mcm","clk":"11923205973","pt":1724176939682,"mc":[{"id":"1.231851789","rc":[{"batb":[[0,1.56,16.22]],"ltp":0.0,"tv":0.0,"id":2780},{"batb":[[1,1.41,19.63]],"ltp":1.41,"tv":2.07,"id":60443},{"trd":[[1.8,5]],"batb":[[0,1.51,16.83]],"batl":[[0,6.8,1.98],[1,12.5,8.45]],"ltp":1.8,"tv":7.0,"id":31374}],"tv":9.08}]}
{"op":"mcm","clk":"11923223584","pt":1724177083730,"mc":[{"id":"1.231851789","rc":[{"batl":[[0,85,1.17],[1,95,5.85]],"ltp":1.41,"tv":2.07,"id":60443}]}]}
{"op":"mcm","clk":"11923224287","pt":1724177089242,"mc":[{"id":"1.231851789","rc":[{"batl":[[0,13.5,1],[1,14,6],[2,90,1.02]],"ltp":0.0,"tv":0.0,"id":2780}]}]}
{"op":"mcm","clk":"11923319439","pt":1724177764018,"mc":[{"id":"1.231851789","rc":[{"batb":[[0,1.5,20.89],[1,1.1,200],[2,1.04,1.53]],"ltp":0.0,"tv":0.0,"id":2780},{"batb":[[0,1.5,20],[1,1.1,200],[2,1.04,1.53]],"ltp":1.8,"tv":7.0,"id":31374}]}]}
{"op":"mcm","clk":"11923320482","pt":1724177771419,"mc":[{"id":"1.231851789","rc":[{"batb":[[0,1.56,16.22],[1,1.5,20],[2,1.1,200]],"ltp":0.0,"tv":0.0,"id":2780},{"batb":[[0,1.51,16.83],[1,1.5,20],[2,1.1,200]],"ltp":1.8,"tv":7.0,"id":31374}]}]}
{"op":"mcm","clk":"11923575847","pt":1724179571627,"mc":[{"id":"1.231851789","rc":[{"batb":[[0,1.5,20.89],[1,1.1,200],[2,1.04,1.53]],"ltp":0.0,"tv":0.0,"id":2780},{"batb":[[0,1.5,20],[1,1.1,200],[2,1.04,1.53]],"ltp":1.8,"tv":7.0,"id":31374}]}]}
{"op":"mcm","clk":"11923593683","pt":1724179676326,"mc":[{"id":"1.231851789","rc":[{"batb":[[0,1.56,16.22],[1,1.5,20],[2,1.1,200]],"ltp":0.0,"tv":0.0,"id":2780},{"batb":[[0,1.51,16.83],[1,1.5,20],[2,1.1,200]],"ltp":1.8,"tv":7.0,"id":31374}]}]}
{"op":"mcm","clk":"11923888893","pt":1724181476892,"mc":[{"id":"1.231851789","rc":[{"batb":[[0,1.5,20.89],[1,1.1,200],[2,1.04,1.53]],"ltp":0.0,"tv":0.0,"id":2780},{"trd":[[1.41,2.08]],"batb":[[1,1.41,19.63]],"ltp":1.41,"tv":2.07,"id":60443},{"trd":[[1.8,5]],"batb":[[0,1.5,20],[1,1.1,200],[2,1.04,1.53]],"ltp":1.8,"tv":7.0,"id":31374}],"tv":9.07}]}
{"op":"mcm","clk":"11923899527","pt":1724181536973,"mc":[{"id":"1.231851789","rc":[{"batb":[[0,1.56,16.21],[1,1.5,20],[2,1.1,200]],"ltp":0.0,"tv":0.0,"id":2780},{"batb":[[0,1.51,16.82],[1,1.5,20],[2,1.1,200]],"ltp":1.8,"tv":7.0,"id":31374}]}]}
{"op":"mcm","clk":"11924158714","pt":1724183337282,"mc":[{"id":"1.231851789","rc":[{"batb":[[0,1.5,20.89],[1,1.1,200],[2,1.04,1.53]],"ltp":0.0,"tv":0.0,"id":2780},{"batb":[[0,1.5,20],[1,1.1,200],[2,1.04,1.53]],"ltp":1.8,"tv":7.0,"id":31374}]}]}
{"op":"mcm","clk":"11924164308","pt":1724183377089,"mc":[{"id":"1.231851789","rc":[{"batb":[[0,1.56,16.21],[1,1.5,20],[2,1.1,200]],"ltp":0.0,"tv":0.0,"id":2780},{"batb":[[0,1.51,16.82],[1,1.5,20],[2,1.1,200]],"ltp":1.8,"tv":7.0,"id":31374}]}]}
{"op":"mcm","clk":"11924351225","pt":1724184774973,"mc":[{"id":"1.231851789","rc":[{"batb":[[0,1.56,16.21]],"ltp":0.0,"tv":0.0,"id":2780},{"batb":[[1,1.41,19.63]],"ltp":1.41,"tv":2.07,"id":60443},{"batb":[[0,1.51,16.82]],"ltp":1.8,"tv":7.0,"id":31374}]}]}
{"op":"mcm","clk":"11924367676","pt":1724184892284,"mc":[{"id":"1.231851789","rc":[{"batb":[[0,1.8,37],[1,1.56,16.21],[2,1.5,20]],"ltp":0.0,"tv":0.0,"id":2780}]}]}
{"op":"mcm","clk":"11924369501","pt":1724184908383,"mc":[{"id":"1.231851789","rc":[{"batb":[[0,1.6,36],[1,1.51,16.82],[2,1.5,20]],"ltp":1.8,"tv":7.0,"id":31374}]}]}
{"op":"mcm","clk":"11924394684","pt":1724185115206,"mc":[{"id":"1.231851789","rc":[{"batb":[[0,1.56,16.21],[1,1.5,20],[2,1.1,200]],"ltp":0.0,"tv":0.0,"id":2780},{"batb":[[0,1.51,16.82],[1,1.5,20],[2,1.1,200]],"ltp":1.8,"tv":7.0,"id":31374}]}]}
{"op":"mcm","clk":"11924401996","pt":1724185177567,"mc":[{"id":"1.231851789","rc":[{"batb":[[0,1.5,20.89],[1,1.1,200],[2,1.04,1.53]],"ltp":0.0,"tv":0.0,"id":2780},{"batb":[[0,1.5,20],[1,1.1,200],[2,1.04,1.53]],"ltp":1.8,"tv":7.0,"id":31374}]}]}
{"op":"mcm","clk":"11924417421","pt":1724185305709,"mc":[{"id":"1.231851789","rc":[{"batb":[[0,1.56,16.21],[1,1.5,20],[2,1.1,200]],"ltp":0.0,"tv":0.0,"id":2780},{"batb":[[0,1.51,16.82],[1,1.5,20],[2,1.1,200]],"ltp":1.8,"tv":7.0,"id":31374}]}]}
{"op":"mcm","clk":"11924563014","pt":1724187106150,"mc":[{"id":"1.231851789","rc":[{"batb":[[0,1.5,20.89],[1,1.1,200],[2,1.04,1.53]],"ltp":0.0,"tv":0.0,"id":2780},{"batb":[[0,1.5,20],[1,1.1,200],[2,1.04,1.53]],"ltp":1.8,"tv":7.0,"id":31374}]}]}
{"op":"mcm","clk":"11924565169","pt":1724187165296,"mc":[{"id":"1.231851789","rc":[{"batb":[[0,1.56,16.21],[1,1.5,20],[2,1.1,200]],"ltp":0.0,"tv":0.0,"id":2780},{"batb":[[0,1.51,16.82],[1,1.5,20],[2,1.1,200]],"ltp":1.8,"tv":7.0,"id":31374}]}]}
{"op":"mcm","clk":"11924634942","pt":1724188965737,"mc":[{"id":"1.231851789","rc":[{"batb":[[0,1.5,20.89],[1,1.1,200],[2,1.04,1.53]],"ltp":0.0,"tv":0.0,"id":2780},{"batb":[[1,1.41,19.64]],"ltp":1.41,"tv":2.07,"id":60443},{"batb":[[0,1.5,20],[1,1.1,200],[2,1.04,1.53]],"ltp":1.8,"tv":7.0,"id":31374}]}]}
{"op":"mcm","clk":"11924638168","pt":1724189056652,"mc":[{"id":"1.231851789","rc":[{"batb":[[0,1.56,16.22],[1,1.5,20],[2,1.1,200]],"ltp":0.0,"tv":0.0,"id":2780},{"batb":[[0,1.51,16.83],[1,1.5,20],[2,1.1,200]],"ltp":1.8,"tv":7.0,"id":31374}]}]}
{"op":"mcm","clk":"11924681786","pt":1724190047485,"mc":[{"id":"1.231851789","rc":[{"trd":[[13.5,0.14]],"batl":[[0,14,6.86],[1,90,1.02],[2,95,5]],"ltp":13.5,"tv":0.14,"id":2780},{"trd":[[1.69,1.11],[1.75,1.78]],"batb":[[0,1.42,40]],"ltp":1.69,"tv":4.96,"id":60443},{"trd":[[2.98,0.63]],"batl":[[0,6.8,1.34]],"ltp":2.98,"tv":7.63,"id":31374}],"tv":12.74}]}
{"op":"mcm","clk":"11924682022","pt":1724190053068,"mc":[{"id":"1.231851789","rc":[{"batb":[[0,1.57,2.09],[1,1.56,15.33],[2,1.5,20]],"ltp":13.5,"tv":0.14,"id":2780}]}]}
{"op":"mcm","clk":"11924683051","pt":1724190074993,"mc":[{"id":"1.231851789","rc":[{"batl":[[0,1.7,2],[1,85,1.17],[2,95,5.85]],"ltp":1.69,"tv":4.96,"id":60443}]}]}
{"op":"mcm","clk":"11924683070","pt":1724190075401,"mc":[{"id":"1.231851789","rc":[{"batb":[[0,1.56,16.22],[1,1.5,20],[2,1.1,200]],"ltp":13.5,"tv":0.14,"id":2780},{"batl":[[1,90,1.02],[2,95,5]],"ltp":1.69,"tv":4.96,"id":60443}]}]}
{"op":"mcm","clk":"11924683299","pt":1724190081029,"mc":[{"id":"1.231851789","rc":[{"batb":[[0,1.61,1.17],[1,1.56,16.22],[2,1.5,20]],"ltp":13.5,"tv":0.14,"id":2780}]}]}
{"op":"mcm","clk":"11924730045","pt":1724190857143,"mc":[{"id":"1.231851789","rc":[{"batb":[[1,1.5,20.89],[2,1.1,200]],"ltp":13.5,"tv":0.14,"id":2780},{"batb":[[0,1.5,20],[1,1.1,200],[2,1.04,1.53]],"ltp":2.98,"tv":7.63,"id":31374}]}]}
{"op":"mcm","clk":"11924732346","pt":1724190908989,"mc":[{"id":"1.231851789","rc":[{"batb":[[0,1.62,13.84],[1,1.61,1.17],[2,1.5,20.89]],"ltp":13.5,"tv":0.14,"id":2780},{"batb":[[0,1.51,16.83],[1,1.5,20],[2,1.1,200]],"ltp":2.98,"tv":7.63,"id":31374}]}]}
{"op":"mcm","clk":"11924732421","pt":1724190910687,"mc":[{"id":"1.231851789","rc":[{"batb":[[1,1.5,20.89],[2,1.1,200]],"ltp":13.5,"tv":0.14,"id":2780}]}]}
{"op":"mcm","clk":"11924732649","pt":1724190916219,"mc":[{"id":"1.231851789","rc":[{"batb":[[0,1.63,1.16],[1,1.62,13.84],[2,1.5,20.89]],"ltp":13.5,"tv":0.14,"id":2780}]}]}
{"op":"mcm","clk":"11924833347","pt":1724192709564,"mc":[{"id":"1.231851789","rc":[{"batb":[[1,1.5,20.89],[2,1.1,200]],"ltp":13.5,"tv":0.14,"id":2780},{"batb":[[0,1.5,20],[1,1.1,200],[2,1.04,1.53]],"ltp":2.98,"tv":7.63,"id":31374}]}]}
{"op":"mcm","clk":"11924835221","pt":1724192747841,"mc":[{"id":"1.231851789","rc":[{"batb":[[0,1.64,13.41],[1,1.63,1.16],[2,1.5,20.89]],"ltp":13.5,"tv":0.14,"id":2780},{"batb":[[0,1.51,16.83],[1,1.5,20],[2,1.1,200]],"ltp":2.98,"tv":7.63,"id":31374}]}]}
{"op":"mcm","clk":"11924835462","pt":1724192753632,"mc":[{"id":"1.231851789","rc":[{"batb":[[1,1.5,20.89],[2,1.1,200]],"ltp":13.5,"tv":0.14,"id":2780}]}]}
{"op":"mcm","clk":"11924835676","pt":1724192759160,"mc":[{"id":"1.231851789","rc":[{"batb":[[0,1.65,1.15],[1,1.64,13.41],[2,1.5,20.89]],"ltp":13.5,"tv":0.14,"id":2780}]}]}
{"op":"mcm","clk":"11924940224","pt":1724194548132,"mc":[{"id":"1.231851789","rc":[{"batb":[[1,1.5,20.89],[2,1.1,200]],"ltp":13.5,"tv":0.14,"id":2780}]}]}
{"op":"mcm","clk":"11924940239","pt":1724194548436,"mc":[{"id":"1.231851789","rc":[{"batb":[[0,1.5,20],[1,1.1,200],[2,1.04,1.53]],"ltp":2.98,"tv":7.63,"id":31374}]}]}
{"op":"mcm","clk":"11924941294","pt":1724194570058,"mc":[{"id":"1.231851789","rc":[{"batb":[[0,1.66,13],[1,1.65,1.15],[2,1.5,20.89]],"ltp":13.5,"tv":0.14,"id":2780},{"batb":[[0,1.51,16.83],[1,1.5,20],[2,1.1,200]],"ltp":2.98,"tv":7.63,"id":31374}]}]}
{"op":"mcm","clk":"11924941563","pt":1724194574382,"mc":[{"id":"1.231851789","rc":[{"batb":[[1,1.5,20.89],[2,1.1,200]],"ltp":13.5,"tv":0.14,"id":2780}]}]}
{"op":"mcm","clk":"11924941857","pt":1724194579969,"mc":[{"id":"1.231851789","rc":[{"batb":[[0,1.67,1.13],[1,1.66,13],[2,1.5,20.89]],"ltp":13.5,"tv":0.14,"id":2780}]}]}
{"op":"mcm","clk":"11924995026","pt":1724195575041,"mc":[{"id":"1.231851789","rc":[{"batb":[[1,1.66,13.01]],"ltp":13.5,"tv":0.14,"id":2780},{"batb":[[1,1.41,19.64]],"ltp":1.69,"tv":4.96,"id":60443},{"batb":[[0,1.51,16.83]],"ltp":2.98,"tv":7.63,"id":31374}]}]}
{"op":"mcm","clk":"11925040426","pt":1724196370262,"mc":[{"id":"1.231851789","rc":[{"batb":[[1,1.5,20.89],[2,1.1,200]],"ltp":13.5,"tv":0.14,"id":2780}]}]}
{"op":"mcm","clk":"11925040439","pt":1724196370466,"mc":[{"id":"1.231851789","rc":[{"batb":[[0,1.5,20],[1,1.1,200],[2,1.04,1.53]],"ltp":2.98,"tv":7.63,"id":31374}]}]}
{"op":"mcm","clk":"11925047497","pt":1724196488754,"mc":[{"id":"1.231851789","rc":[{"batb":[[0,1.68,12.62],[1,1.67,1.13],[2,1.5,20.89]],"ltp":13.5,"tv":0.14,"id":2780},{"batb":[[0,1.51,16.83],[1,1.5,20],[2,1.1,200]],"ltp":2.98,"tv":7.63,"id":31374}]}]}
{"op":"mcm","clk":"11925047565","pt":1724196489739,"mc":[{"id":"1.231851789","rc":[{"batb":[[1,1.5,20.89],[2,1.1,200]],"ltp":13.5,"tv":0.14,"id":2780}]}]}
{"op":"mcm","clk":"11925047892","pt":1724196495238,"mc":[{"id":"1.231851789","rc":[{"batb":[[0,1.69,1.12],[1,1.68,12.62],[2,1.5,20.89]],"ltp":13.5,"tv":0.14,"id":2780}]}]}
{"op":"mcm","clk":"11925135639","pt":1724198289144,"mc":[{"id":"1.231851789","rc":[{"batb":[[1,1.5,20.89],[2,1.1,200]],"ltp":13.5,"tv":0.14,"id":2780},{"batb":[[0,1.5,20],[1,1.1,200],[2,1.04,1.53]],"ltp":2.98,"tv":7.63,"id":31374}]}]}
{"op":"mcm","clk":"11925140502","pt":1724198384949,"mc":[{"id":"1.231851789","rc":[{"batb":[[0,1.7,12.26],[1,1.69,1.12],[2,1.5,20.89]],"ltp":13.5,"tv":0.14,"id":2780},{"batb":[[0,1.51,16.83],[1,1.5,20],[2,1.1,200]],"ltp":2.98,"tv":7.63,"id":31374}]}]}
{"op":"mcm","clk":"11925140667","pt":1724198388149,"mc":[{"id":"1.231851789","rc":[{"batb":[[1,1.5,20.89],[2,1.1,200]],"ltp":13.5,"tv":0.14,"id":2780}]}]}
{"op":"mcm","clk":"11925140950","pt":1724198393805,"mc":[{"id":"1.231851789","rc":[{"batb":[[0,1.71,1.11],[1,1.7,12.26],[2,1.5,20.89]],"ltp":13.5,"tv":0.14,"id":2780}]}]}
{"op":"mcm","clk":"11925232352","pt":1724200185174,"mc":[{"id":"1.231851789","rc":[{"batb":[[1,1.7,12.26]],"ltp":13.5,"tv":0.14,"id":2780},{"batb":[[1,1.41,19.64]],"ltp":1.69,"tv":4.96,"id":60443},{"batb":[[0,1.5,20],[1,1.1,200],[2,1.04,1.53]],"ltp":2.98,"tv":7.63,"id":31374}],"tv":12.74}]}
{"op":"mcm","clk":"11925232368","pt":1724200185388,"mc":[{"id":"1.231851789","rc":[{"batb":[[1,1.5,20.89],[2,1.1,200]],"ltp":13.5,"tv":0.14,"id":2780}]}]}
{"op":"mcm","clk":"11925236157","pt":1724200241807,"mc":[{"id":"1.231851789","rc":[{"batb":[[0,1.72,11.92],[1,1.71,1.11],[2,1.5,20.89]],"ltp":13.5,"tv":0.14,"id":2780},{"batb":[[0,1.51,16.83],[1,1.5,20],[2,1.1,200]],"ltp":2.98,"tv":7.63,"id":31374}]}]}
{"op":"mcm","clk":"11925236221","pt":1724200242479,"mc":[{"id":"1.231851789","rc":[{"batb":[[1,1.5,20.89],[2,1.1,200]],"ltp":13.5,"tv":0.14,"id":2780}]}]}
{"op":"mcm","clk":"11925236594","pt":1724200247980,"mc":[{"id":"1.231851789","rc":[{"batb":[[0,1.73,1.09],[1,1.72,11.92],[2,1.5,20.89]],"ltp":13.5,"tv":0.14,"id":2780}]}]}
{"op":"mcm","clk":"11925358198","pt":1724201765832,"mc":[{"id":"1.231851789","rc":[{"trd":[[13.5,0.25]],"batl":[[0,14,6.75]],"ltp":13.5,"tv":0.25,"id":2780},{"trd":[[1.7,0.87]],"batl":[[0,1.7,1.13]],"ltp":1.7,"tv":5.83,"id":60443},{"trd":[[2.96,0.5]],"ltp":2.96,"tv":8.13,"id":31374}],"tv":14.21}]}
{"op":"mcm","clk":"11925358428","pt":1724201769940,"mc":[{"id":"1.231851789","rc":[{"batl":[[0,6.8,1]],"ltp":2.96,"tv":8.13,"id":31374}]}]}
{"op":"mcm","clk":"11925359287","pt":1724201782442,"mc":[{"id":"1.231851789","rc":[{"batb":[[0,1.51,17.76]],"ltp":2.96,"tv":8.13,"id":31374}]}]}
{"op":"mcm","clk":"11925360684","pt":1724201802581,"mc":[{"id":"1.231851789","rc":[{"batb":[[0,1.51,16.83]],"ltp":2.96,"tv":8.13,"id":31374}]}]}
{"op":"mcm","clk":"11925377541","pt":1724202042221,"mc":[{"id":"1.231851789","rc":[{"batb":[[1,1.5,20.89],[2,1.1,200]],"ltp":13.5,"tv":0.25,"id":2780},{"batb":[[1,1.41,19.63]],"ltp":1.7,"tv":5.83,"id":60443},{"batb":[[0,1.5,20],[1,1.1,200],[2,1.04,1.53]],"ltp":2.96,"tv":8.13,"id":31374}]}]}
{"op":"mcm","clk":"11925379797","pt":1724202073959,"mc":[{"id":"1.231851789","rc":[{"batb":[[1,1.61,14.07],[2,1.5,20.89]],"ltp":13.5,"tv":0.25,"id":2780},{"batb":[[0,1.51,16.82],[1,1.5,20],[2,1.1,200]],"ltp":2.96,"tv":8.13,"id":31374}]}]}
{"op":"mcm","clk":"11925496851","pt":1724203874197,"mc":[{"id":"1.231851789","rc":[{"batb":[[0,1.5,20],[1,1.1,200],[2,1.04,1.53]],"ltp":2.96,"tv":8.13,"id":31374}]}]}
{"op":"mcm","clk":"11925496861","pt":1724203874348,"mc":[{"id":"1.231851789","rc":[{"batb":[[1,1.5,20.89],[2,1.1,200]],"ltp":13.5,"tv":0.25,"id":2780}]}]}
{"op":"mcm","clk":"11925497452","pt":1724203883771,"mc":[{"id":"1.231851789","rc":[{"batb":[[1,1.61,14.07],[2,1.5,20.89]],"ltp":13.5,"tv":0.25,"id":2780},{"batb":[[0,1.51,16.82],[1,1.5,20],[2,1.1,200]],"ltp":2.96,"tv":8.13,"id":31374}]}]}
{"op":"mcm","clk":"11925624816","pt":1724205552505,"mc":[{"id":"1.231851789","rc":[{"batb":[[0,1.51,17.76]],"ltp":2.96,"tv":8.13,"id":31374}]}]}
{"op":"mcm","clk":"11925625592","pt":1724205564618,"mc":[{"id":"1.231851789","rc":[{"batb":[[0,1.8,1.62],[1,1.51,16.82],[2,1.5,20]],"ltp":2.96,"tv":8.13,"id":31374}]}]}
{"op":"mcm","clk":"11925634801","pt":1724205684258,"mc":[{"id":"1.231851789","rc":[{"batb":[[1,1.5,20.89],[2,1.1,200]],"ltp":13.5,"tv":0.25,"id":2780},{"batb":[[1,1.41,19.64]],"ltp":1.7,"tv":5.83,"id":60443},{"batb":[[1,1.5,20],[2,1.1,200]],"ltp":2.96,"tv":8.13,"id":31374}],"tv":14.22}]}
{"op":"mcm","clk":"11925642873","pt":1724205781368,"mc":[{"id":"1.231851789","rc":[{"batb":[[1,1.61,14.07],[2,1.5,20.89]],"ltp":13.5,"tv":0.25,"id":2780},{"batb":[[0,1.81,10.59],[1,1.8,1.62],[2,1.5,20]],"ltp":2.96,"tv":8.13,"id":31374}]}]}
{"op":"mcm","clk":"11925724746","pt":1724206806576,"mc":[{"id":"1.231851789","rc":[{"batb":[[0,1.81,12.21],[1,1.5,20],[2,1.1,200]],"ltp":2.96,"tv":8.13,"id":31374}]}]}
{"op":"mcm","clk":"11925760484","pt":1724207581815,"mc":[{"id":"1.231851789","rc":[{"batb":[[1,1.5,20.89],[2,1.1,200]],"ltp":13.5,"tv":0.25,"id":2780},{"batb":[[0,1.81,1.62]],"ltp":2.96,"tv":8.13,"id":31374}]}]}
{"op":"mcm","clk":"11925763312","pt":1724207650286,"mc":[{"id":"1.231851789","rc":[{"batb":[[1,1.61,14.07],[2,1.5,20.89]],"ltp":13.5,"tv":0.25,"id":2780},{"batb":[[0,1.82,10.47],[1,1.81,1.62],[2,1.5,20]],"ltp":2.96,"tv":8.13,"id":31374}]}]}
{"op":"mcm","clk":"11925802543","pt":1724208625671,"mc":[{"id":"1.231851789","rc":[{"batb":[[0,1.82,12.08],[1,1.5,20],[2,1.1,200]],"ltp":2.96,"tv":8.13,"id":31374}]}]}
{"op":"mcm","clk":"11925840170","pt":1724209450659,"mc":[{"id":"1.231851789","rc":[{"batb":[[1,1.5,20.89],[2,1.1,200]],"ltp":13.5,"tv":0.25,"id":2780},{"batb":[[1,1.41,19.64]],"ltp":1.7,"tv":5.83,"id":60443},{"batb":[[0,1.82,1.62]],"ltp":2.96,"tv":8.13,"id":31374}]}]}
{"op":"mcm","clk":"11925841645","pt":1724209487957,"mc":[{"id":"1.231851789","rc":[{"batb":[[1,1.61,14.07],[2,1.5,20.89]],"ltp":13.5,"tv":0.25,"id":2780},{"batb":[[0,1.83,10.34],[1,1.82,1.62],[2,1.5,20]],"ltp":2.96,"tv":8.13,"id":31374}]}]}
{"op":"mcm","clk":"11925906325","pt":1724211288165,"mc":[{"id":"1.231851789","rc":[{"batb":[[0,1.82,1.62],[1,1.5,20],[2,1.1,200]],"ltp":2.96,"tv":8.13,"id":31374}]}]}
{"op":"mcm","clk":"11925906332","pt":1724211288370,"mc":[{"id":"1.231851789","rc":[{"batb":[[1,1.5,20.89],[2,1.1,200]],"ltp":13.5,"tv":0.25,"id":2780}]}]}
{"op":"mcm","clk":"11925907048","pt":1724211310889,"mc":[{"id":"1.231851789","rc":[{"batb":[[1,1.61,14.07],[2,1.5,20.89]],"ltp":13.5,"tv":0.25,"id":2780},{"batb":[[0,1.83,10.34],[1,1.82,1.62],[2,1.5,20]],"ltp":2.96,"tv":8.13,"id":31374}]}]}
{"op":"mcm","clk":"11925977580","pt":1724213111148,"mc":[{"id":"1.231851789","rc":[{"batb":[[1,1.61,14.06]],"ltp":13.5,"tv":0.25,"id":2780},{"batb":[[1,1.41,19.63]],"ltp":1.7,"tv":5.83,"id":60443},{"batb":[[0,1.82,1.62],[1,1.5,20],[2,1.1,200]],"ltp":2.96,"tv":8.13,"id":31374}],"tv":14.22}]}
{"op":"mcm","clk":"11925977588","pt":1724213111353,"mc":[{"id":"1.231851789","rc":[{"batb":[[1,1.5,20.89],[2,1.1,200]],"ltp":13.5,"tv":0.25,"id":2780}]}]}
{"op":"mcm","clk":"11925978105","pt":1724213124953,"mc":[{"id":"1.231851789","rc":[{"batb":[[1,1.61,14.06],[2,1.5,20.89]],"ltp":13.5,"tv":0.25,"id":2780},{"batb":[[0,1.83,10.34],[1,1.82,1.62],[2,1.5,20]],"ltp":2.96,"tv":8.13,"id":31374}]}]}
{"op":"mcm","clk":"11926033072","pt":1724214925248,"mc":[{"id":"1.231851789","rc":[{"batb":[[1,1.5,20.89],[2,1.1,200]],"ltp":13.5,"tv":0.25,"id":2780}]}]}
{"op":"mcm","clk":"11926033077","pt":1724214925453,"mc":[{"id":"1.231851789","rc":[{"batb":[[0,1.82,1.62],[1,1.5,20],[2,1.1,200]],"ltp":2.96,"tv":8.13,"id":31374}]}]}
{"op":"mcm","clk":"11926033773","pt":1724214946883,"mc":[{"id":"1.231851789","rc":[{"trd":[[1.7,3.13]],"batl":[[0,90,1.02],[1,95,5],[2,990,5.51]],"ltp":1.7,"tv":8.09,"id":60443}],"tv":16.48}]}
{"op":"mcm","clk":"11926033807","pt":1724214947760,"mc":[{"id":"1.231851789","rc":[{"batl":[[0,85,1.17],[1,95,5.85]],"ltp":1.7,"tv":8.09,"id":60443}]}]}
{"op":"mcm","clk":"11926034991","pt":1724214987424,"mc":[{"id":"1.231851789","rc":[{"batl":[[0,85,1.82]],"ltp":1.7,"tv":8.09,"id":60443}]}]}
{"op":"mcm","clk":"11926035112","pt":1724214992352,"mc":[{"id":"1.231851789","rc":[{"batb":[[0,1.5,20.89],[1,1.1,200],[2,1.04,1.53]],"ltp":13.5,"tv":0.25,"id":2780}]}]}
{"op":"mcm","clk":"11926035147","pt":1724214993734,"mc":[{"id":"1.231851789","rc":[{"batl":[[0,85,1.81]],"ltp":1.7,"tv":8.09,"id":60443}]}]}
{"op":"mcm","clk":"11926035254","pt":1724214997827,"mc":[{"id":"1.231851789","rc":[{"batb":[[0,1.89,1.79],[1,1.5,20.89],[2,1.1,200]],"ltp":13.5,"tv":0.25,"id":2780}]}]}
{"op":"mcm","clk":"11926035886","pt":1724215020063,"mc":[{"id":"1.231851789","rc":[{"batb":[[0,1.9,9.53],[1,1.89,1.79],[2,1.5,20.89]],"ltp":13.5,"tv":0.25,"id":2780},{"batb":[[1,1.66,13],[2,1.5,20]],"ltp":2.96,"tv":8.13,"id":31374}]}]}
{"op":"mcm","clk":"11926036107","pt":1724215025737,"mc":[{"id":"1.231851789","rc":[{"batb":[[1,1.5,20.89],[2,1.1,200]],"ltp":13.5,"tv":0.25,"id":2780}]}]}
{"op":"mcm","clk":"11926036258","pt":1724215031263,"mc":[{"id":"1.231851789","rc":[{"batb":[[0,1.91,1.77],[1,1.9,9.53],[2,1.5,20.89]],"ltp":13.5,"tv":0.25,"id":2780}]}]}
{"op":"mcm","clk":"11926112391","pt":1724216820432,"mc":[{"id":"1.231851789","rc":[{"batb":[[1,1.5,20.89],[2,1.1,200]],"ltp":13.5,"tv":0.25,"id":2780},{"batb":[[1,1.5,20],[2,1.1,200]],"ltp":2.96,"tv":8.13,"id":31374}],"tv":16.47}]}
{"op":"mcm","clk":"11926116542","pt":1724216905373,"mc":[{"id":"1.231851789","rc":[{"batb":[[0,1.92,9.32],[1,1.91,1.77],[2,1.5,20.89]],"ltp":13.5,"tv":0.25,"id":2780},{"batb":[[1,1.66,13],[2,1.5,20]],"ltp":2.96,"tv":8.13,"id":31374}]}]}
{"op":"mcm","clk":"11926116650","pt":1724216907698,"mc":[{"id":"1.231851789","rc":[{"batb":[[1,1.5,20.89],[2,1.1,200]],"ltp":13.5,"tv":0.25,"id":2780}]}]}
{"op":"mcm","clk":"11926116877","pt":1724216913326,"mc":[{"id":"1.231851789","rc":[{"batb":[[0,1.93,1.75],[1,1.92,9.32],[2,1.5,20.89]],"ltp":13.5,"tv":0.25,"id":2780}]}]}
{"op":"mcm","clk":"11926199609","pt":1724218705848,"mc":[{"id":"1.231851789","rc":[{"batb":[[1,1.5,20.89],[2,1.1,200]],"ltp":13.5,"tv":0.25,"id":2780},{"batb":[[1,1.5,20],[2,1.1,200]],"ltp":2.96,"tv":8.13,"id":31374}]}]}
{"op":"mcm","clk":"11926202596","pt":1724218784467,"mc":[{"id":"1.231851789","rc":[{"batb":[[0,1.94,9.13],[1,1.93,1.75],[2,1.5,20.89]],"ltp":13.5,"tv":0.25,"id":2780},{"batb":[[1,1.66,13],[2,1.5,20]],"ltp":2.96,"tv":8.13,"id":31374}]}]}
{"op":"mcm","clk":"11926202789","pt":1724218789862,"mc":[{"id":"1.231851789","rc":[{"batb":[[1,1.5,20.89],[2,1.1,200]],"ltp":13.5,"tv":0.25,"id":2780}]}]}
{"op":"mcm","clk":"11926203010","pt":1724218795490,"mc":[{"id":"1.231851789","rc":[{"batb":[[0,1.95,1.73],[1,1.94,9.13],[2,1.5,20.89]],"ltp":13.5,"tv":0.25,"id":2780}]}]}
{"op":"mcm","clk":"11926242573","pt":1724219697427,"mc":[{"id":"1.231851789","rc":[{"batb":[[0,1.95,2.27]],"ltp":13.5,"tv":0.25,"id":2780}]}]}
{"op":"mcm","clk":"11926243054","pt":1724219707829,"mc":[{"id":"1.231851789","rc":[{"batb":[[0,1.82,2.15]],"ltp":2.96,"tv":8.13,"id":31374}]}]}
{"op":"mcm","clk":"11926278186","pt":1724220584931,"mc":[{"id":"1.231851789","rc":[{"batb":[[1,1.5,20.89],[2,1.1,200]],"ltp":13.5,"tv":0.25,"id":2780},{"batb":[[1,1.41,19.64]],"ltp":1.7,"tv":8.09,"id":60443},{"trd":[[1.8,5]],"batb":[[0,1.82,2.15],[1,1.5,20],[2,1.1,200]],"ltp":2.96,"tv":8.13,"id":31374}],"tv":16.48}]}
{"op":"mcm","clk":"11926281224","pt":1724220659425,"mc":[{"id":"1.231851789","rc":[{"batb":[[0,1.96,9.47],[1,1.95,1.73],[2,1.5,20.89]],"ltp":13.5,"tv":0.25,"id":2780},{"batb":[[0,1.83,10.88],[1,1.82,1.62],[2,1.5,20]],"ltp":2.96,"tv":8.13,"id":31374}]}]}
{"op":"mcm","clk":"11926281296","pt":1724220661015,"mc":[{"id":"1.231851789","rc":[{"batb":[[1,1.5,20.89],[2,1.1,200]],"ltp":13.5,"tv":0.25,"id":2780}]}]}
{"op":"mcm","clk":"11926281557","pt":1724220667322,"mc":[{"id":"1.231851789","rc":[{"batb":[[0,1.97,2.25],[1,1.96,8.94],[2,1.5,20.89]],"ltp":13.5,"tv":0.25,"id":2780}]}]}
{"op":"mcm","clk":"11926354328","pt":1724222459731,"mc":[{"id":"1.231851789","rc":[{"batb":[[1,1.5,20.89],[2,1.1,200]],"ltp":13.5,"tv":0.25,"id":2780},{"batb":[[0,1.82,2.15],[1,1.5,20],[2,1.1,200]],"ltp":2.96,"tv":8.13,"id":31374}]}]}
{"op":"mcm","clk":"11926357161","pt":1724222530255,"mc":[{"id":"1.231851789","rc":[{"batb":[[0,1.98,9.29],[1,1.97,1.71],[2,1.5,20.89]],"ltp":13.5,"tv":0.25,"id":2780},{"batb":[[0,1.83,10.88],[1,1.82,1.62],[2,1.5,20]],"ltp":2.96,"tv":8.13,"id":31374}]}]}
{"op":"mcm","clk":"11926357300","pt":1724222532407,"mc":[{"id":"1.231851789","rc":[{"batb":[[1,1.5,20.89],[2,1.1,200]],"ltp":13.5,"tv":0.25,"id":2780}]}]}
{"op":"mcm","clk":"11926357534","pt":1724222537953,"mc":[{"id":"1.231851789","rc":[{"batb":[[0,1.99,2.24],[1,1.98,8.76],[2,1.5,20.89]],"ltp":13.5,"tv":0.25,"id":2780}]}]}
{"op":"mcm","clk":"11926441341","pt":1724224330687,"mc":[{"id":"1.231851789","rc":[{"batb":[[1,1.5,20.89],[2,1.1,200]],"ltp":13.5,"tv":0.25,"id":2780},{"batb":[[1,1.41,19.64]],"ltp":1.7,"tv":8.1,"id":60443},{"batb":[[0,1.82,2.15],[1,1.5,20],[2,1.1,200]],"ltp":2.96,"tv":8.13,"id":31374}],"tv":16.48}]}
{"op":"mcm","clk":"11926443973","pt":1724224397802,"mc":[{"id":"1.231851789","rc":[{"batb":[[0,2,9.12],[1,1.99,1.7],[2,1.5,20.89]],"ltp":13.5,"tv":0.25,"id":2780},{"batb":[[0,1.83,10.88],[1,1.82,1.62],[2,1.5,20]],"ltp":2.96,"tv":8.13,"id":31374}]}]}
{"op":"mcm","clk":"11926444188","pt":1724224403513,"mc":[{"id":"1.231851789","rc":[{"batb":[[1,1.5,20.89],[2,1.1,200]],"ltp":13.5,"tv":0.25,"id":2780}]}]}
{"op":"mcm","clk":"11926444376","pt":1724224409066,"mc":[{"id":"1.231851789","rc":[{"batb":[[0,2.02,1.67],[1,2,9.12],[2,1.5,20.89]],"ltp":13.5,"tv":0.25,"id":2780}]}]}
{"op":"mcm","clk":"11926472396","pt":1724225180940,"mc":[{"id":"1.231851789","rc":[{"batb":[[1,2,8.58]],"ltp":13.5,"tv":0.25,"id":2780}]}]}
{"op":"mcm","clk":"11926472574","pt":1724225184530,"mc":[{"id":"1.231851789","rc":[{"batb":[[0,1.83,10.34]],"ltp":2.96,"tv":8.13,"id":31374}]}]}
{"op":"mcm","clk":"11926510626","pt":1724226198181,"mc":[{"id":"1.231851789","rc":[{"batb":[[1,1.5,20.89],[2,1.1,200]],"ltp":13.5,"tv":0.25,"id":2780},{"batb":[[0,1.82,1.62],[1,1.5,20],[2,1.1,200]],"ltp":2.96,"tv":8.13,"id":31374}]}]}
{"op":"mcm","clk":"11926513219","pt":1724226257973,"mc":[{"id":"1.231851789","rc":[{"batb":[[1,1.89,9.64],[2,1.5,20.89]],"ltp":13.5,"tv":0.25,"id":2780},{"batb":[[1,1.66,13.01],[2,1.5,20]],"ltp":2.96,"tv":8.13,"id":31374}]}]}
{"op":"mcm","clk":"11926600784","pt":1724227974974,"mc":[{"id":"1.231851789","rc":[{"batb":[[1,1.41,19.64]],"ltp":1.7,"tv":8.1,"id":60443}]}]}
{"op":"mcm","clk":"11926608089","pt":1724228058171,"mc":[{"id":"1.231851789","rc":[{"batb":[[1,1.5,20.89],[2,1.1,200]],"ltp":13.5,"tv":0.25,"id":2780}]}]}
{"op":"mcm","clk":"11926608096","pt":1724228058374,"mc":[{"id":"1.231851789","rc":[{"batb":[[1,1.5,20],[2,1.1,200]],"ltp":2.96,"tv":8.13,"id":31374}]}]}
{"op":"mcm","clk":"11926611382","pt":1724228124024,"mc":[{"id":"1.231851789","rc":[{"batb":[[1,1.89,9.64],[2,1.5,20.89]],"ltp":13.5,"tv":0.25,"id":2780},{"batb":[[1,1.66,13],[2,1.5,20]],"ltp":2.96,"tv":8.13,"id":31374}]}]}
{"op":"mcm","clk":"11926703434","pt":1724229924202,"mc":[{"id":"1.231851789","rc":[{"batb":[[1,1.5,20],[2,1.1,200]],"ltp":2.96,"tv":8.13,"id":31374}]}]}
{"op":"mcm","clk":"11926703441","pt":1724229924319,"mc":[{"id":"1.231851789","rc":[{"batb":[[1,1.5,20.89],[2,1.1,200]],"ltp":13.5,"tv":0.25,"id":2780}]}]}
{"op":"mcm","clk":"11926710144","pt":1724230044468,"mc":[{"id":"1.231851789","rc":[{"batb":[[1,1.89,9.64],[2,1.5,20.89]],"ltp":13.5,"tv":0.25,"id":2780},{"batb":[[1,1.66,13],[2,1.5,20]],"ltp":2.96,"tv":8.13,"id":31374}]}]}
{"op":"mcm","clk":"11926805288","pt":1724231844819,"mc":[{"id":"1.231851789","rc":[{"batb":[[1,1.5,20.89],[2,1.1,200]],"ltp":13.5,"tv":0.25,"id":2780},{"batb":[[1,1.41,19.65]],"ltp":1.7,"tv":8.1,"id":60443},{"batb":[[1,1.5,20],[2,1.1,200]],"ltp":2.96,"tv":8.13,"id":31374}]}]}
{"op":"mcm","clk":"11926808260","pt":1724231892548,"mc":[{"id":"1.231851789","rc":[{"batb":[[1,1.89,9.65],[2,1.5,20.89]],"ltp":13.5,"tv":0.25,"id":2780},{"batb":[[1,1.66,13.01],[2,1.5,20]],"ltp":2.96,"tv":8.13,"id":31374}]}]}
{"op":"mcm","clk":"11926875558","pt":1724232952401,"mc":[{"id":"1.231851789","rc":[{"batl":[[2,870,0.51]],"ltp":13.5,"tv":0.25,"id":2780},{"batl":[[1,180,1.03],[2,870,0.34]],"ltp":1.7,"tv":8.1,"id":60443}]}]}
{"op":"mcm","clk":"11926876979","pt":1724232972045,"mc":[{"id":"1.231851789","rc":[{"batl":[[2,95,5]],"ltp":13.5,"tv":0.25,"id":2780},{"batl":[[1,95,5.85],[2,990,5.51]],"ltp":1.7,"tv":8.1,"id":60443}]}]}
{"op":"mcm","clk":"11926936079","pt":1724233693020,"mc":[{"id":"1.231851789","rc":[{"batb":[[1,1.5,20.89],[2,1.08,31.25]],"ltp":13.5,"tv":0.25,"id":2780},{"batb":[[1,1.5,20],[2,1.08,31.25]],"ltp":2.96,"tv":8.13,"id":31374}]}]}
{"op":"mcm","clk":"11926939088","pt":1724233738180,"mc":[{"id":"1.231851789","rc":[{"batb":[[1,1.89,9.65],[2,1.5,20.89]],"ltp":13.5,"tv":0.25,"id":2780},{"batb":[[1,1.66,13.01],[2,1.5,20]],"ltp":2.96,"tv":8.13,"id":31374}]}]}
{"op":"mcm","clk":"11927095552","pt":1724235538541,"mc":[{"id":"1.231851789","rc":[{"batb":[[1,1.89,9.64]],"batl":[[1,90,1.02]],"ltp":13.5,"tv":0.25,"id":2780},{"trd":[[1.41,2.08],[1.7,3.13]],"batb":[[1,1.41,19.63]],"ltp":1.7,"tv":8.09,"id":60443},{"trd":[[1.7,2],[1.8,5]],"batb":[[0,1.82,1.62],[1,1.5,20],[2,1.08,31.25]],"batl":[[2,90,1.02]],"ltp":2.96,"tv":8.13,"id":31374}],"tv":16.47}]}
{"op":"mcm","clk":"11927095719","pt":1724235540244,"mc":[{"id":"1.231851789","rc":[{"batb":[[1,1.5,20.89],[2,1.08,31.25]],"ltp":13.5,"tv":0.25,"id":2780}]}]}
{"op":"mcm","clk":"11927098868","pt":1724235572226,"mc":[{"id":"1.231851789","rc":[{"batb":[[1,1.89,9.64],[2,1.5,20.89]],"ltp":13.5,"tv":0.25,"id":2780},{"batb":[[1,1.66,13],[2,1.5,20]],"ltp":2.96,"tv":8.13,"id":31374}]}]}
{"op":"mcm","clk":"11927274797","pt":1724237373094,"mc":[{"id":"1.231851789","rc":[{"batb":[[1,1.5,20.89],[2,1.08,31.25]],"ltp":13.5,"tv":0.25,"id":2780},{"batb":[[1,1.5,20],[2,1.08,31.25]],"ltp":2.96,"tv":8.13,"id":31374}]}]}
{"op":"mcm","clk":"11927277386","pt":1724237400030,"mc":[{"id":"1.231851789","rc":[{"batb":[[1,1.89,9.64],[2,1.5,20.89]],"ltp":13.5,"tv":0.25,"id":2780},{"batb":[[1,1.66,13],[2,1.5,20]],"ltp":2.96,"tv":8.13,"id":31374}]}]}
{"op":"mcm","clk":"11927404197","pt":1724238774986,"mc":[{"id":"1.231851789","rc":[{"batb":[[1,1.89,9.63],[2,1.5,20.89]],"ltp":13.5,"tv":0.25,"id":2780},{"trd":[[1.41,2.07],[1.7,3.13],[1.75,1.78]],"batb":[[1,1.41,19.62]],"ltp":1.7,"tv":8.09,"id":60443},{"trd":[[1.7,2],[1.8,5]],"batb":[[0,1.82,1.61],[1,1.66,12.99]],"ltp":2.96,"tv":8.12,"id":31374}],"tv":16.46}]}
{"op":"mcm","clk":"11927453086","pt":1724239201900,"mc":[{"id":"1.231851789","rc":[{"batb":[[1,1.5,20.89],[2,1.08,31.25]],"ltp":13.5,"tv":0.25,"id":2780},{"batb":[[1,1.5,20],[2,1.08,31.25]],"ltp":2.96,"tv":8.12,"id":31374}]}]}
{"op":"mcm","clk":"11927456080","pt":1724239230662,"mc":[{"id":"1.231851789","rc":[{"batb":[[1,1.89,9.63],[2,1.5,20.89]],"ltp":13.5,"tv":0.25,"id":2780},{"batb":[[1,1.66,12.99],[2,1.5,20]],"ltp":2.96,"tv":8.12,"id":31374}]}]}
{"op":"mcm","clk":"11927622717","pt":1724241030922,"mc":[{"id":"1.231851789","rc":[{"batb":[[1,1.5,20.89],[2,1.08,31.25]],"ltp":13.5,"tv":0.25,"id":2780},{"batb":[[1,1.5,20],[2,1.08,31.25]],"ltp":2.96,"tv":8.12,"id":31374}]}]}
{"op":"mcm","clk":"11927630244","pt":1724241134080,"mc":[{"id":"1.231851789","rc":[{"batb":[[1,1.89,9.63],[2,1.5,20.89]],"ltp":13.5,"tv":0.25,"id":2780},{"batb":[[1,1.66,12.99],[2,1.5,20]],"ltp":2.96,"tv":8.12,"id":31374}]}]}
{"op":"mcm","clk":"11927757779","pt":1724242934302,"mc":[{"id":"1.231851789","rc":[{"batb":[[1,1.5,20.89],[2,1.08,31.25]],"ltp":13.5,"tv":0.25,"id":2780},{"trd":[[1.8,5]],"batb":[[0,1.82,1.62]],"ltp":2.96,"tv":8.12,"id":31374}],"tv":16.47}]}
{"op":"mcm","clk":"11927757799","pt":1724242934472,"mc":[{"id":"1.231851789","rc":[{"batb":[[1,1.5,20],[2,1.08,31.25]],"ltp":2.96,"tv":8.12,"id":31374}]}]}
{"op":"mcm","clk":"11927763950","pt":1724243014061,"mc":[{"id":"1.231851789","rc":[{"batb":[[1,1.89,9.63],[2,1.5,20.89]],"ltp":13.5,"tv":0.25,"id":2780},{"batb":[[1,1.66,12.99],[2,1.5,20]],"ltp":2.96,"tv":8.12,"id":31374}]}]}
{"op":"mcm","clk":"11927882396","pt":1724244814245,"mc":[{"id":"1.231851789","rc":[{"batb":[[1,1.5,20],[2,1.08,31.25]],"ltp":2.96,"tv":8.12,"id":31374}]}]}
{"op":"mcm","clk":"11927882436","pt":1724244814958,"mc":[{"id":"1.231851789","rc":[{"batb":[[1,1.5,20.89],[2,1.08,31.25]],"ltp":13.5,"tv":0.25,"id":2780}]}]}
{"op":"mcm","clk":"11927886228","pt":1724244870525,"mc":[{"id":"1.231851789","rc":[{"batb":[[1,1.89,9.63],[2,1.5,20.89]],"ltp":13.5,"tv":0.25,"id":2780},{"batb":[[1,1.66,12.99],[2,1.5,20]],"ltp":2.96,"tv":8.12,"id":31374}]}]}
{"op":"mcm","clk":"11928010256","pt":1724246670969,"mc":[{"id":"1.231851789","rc":[{"batb":[[1,1.5,20.89],[2,1.08,31.25]],"ltp":13.5,"tv":0.25,"id":2780},{"trd":[[1.41,2.07],[1.7,3.13]],"batb":[[1,1.41,19.61]],"ltp":1.7,"tv":8.09,"id":60443},{"trd":[[1.8,5]],"batb":[[0,1.82,1.61],[1,1.5,20],[2,1.08,31.25]],"ltp":2.96,"tv":8.12,"id":31374}],"tv":16.46}]}
{"op":"mcm","clk":"11928013057","pt":1724246714608,"mc":[{"id":"1.231851789","rc":[{"batb":[[1,1.89,9.63],[2,1.5,20.89]],"ltp":13.5,"tv":0.25,"id":2780},{"batb":[[1,1.66,12.99],[2,1.5,20]],"ltp":2.96,"tv":8.12,"id":31374}]}]}
{"op":"mcm","clk":"11928129591","pt":1724248515122,"mc":[{"id":"1.231851789","rc":[{"batb":[[1,1.5,20],[2,1.08,31.25]],"ltp":2.96,"tv":8.12,"id":31374}]}]}
{"op":"mcm","clk":"11928129671","pt":1724248516215,"mc":[{"id":"1.231851789","rc":[{"batb":[[1,1.5,20.89],[2,1.08,31.25]],"ltp":13.5,"tv":0.25,"id":2780}]}]}
{"op":"mcm","clk":"11928130914","pt":1724248545348,"mc":[{"id":"1.231851789","rc":[{"batb":[[1,1.89,9.63],[2,1.5,20.89]],"ltp":13.5,"tv":0.25,"id":2780},{"batb":[[1,1.66,12.99],[2,1.5,20]],"ltp":2.96,"tv":8.12,"id":31374}]}]}
{"op":"mcm","clk":"11928199335","pt":1724249574974,"mc":[{"id":"1.231851789","rc":[{"batb":[[1,1.89,9.62]],"batl":[[1,90,1.02]],"ltp":13.5,"tv":0.25,"id":2780},{"trd":[[1.41,2.07]],"batb":[[1,1.41,19.59]],"ltp":1.7,"tv":8.08,"id":60443},{"batb":[[1,1.66,12.97]],"batl":[[2,90,1.02]],"ltp":2.96,"tv":8.12,"id":31374}],"tv":16.46}]}
{"op":"mcm","clk":"11928251174","pt":1724250345799,"mc":[{"id":"1.231851789","rc":[{"batb":[[1,1.5,20.89],[2,1.08,31.25]],"ltp":13.5,"tv":0.25,"id":2780},{"batb":[[1,1.5,20],[2,1.08,31.25]],"ltp":2.96,"tv":8.12,"id":31374}]}]}
{"op":"mcm","clk":"11928252418","pt":1724250363512,"mc":[{"id":"1.231851789","rc":[{"batb":[[1,1.89,9.62],[2,1.5,20.89]],"ltp":13.5,"tv":0.25,"id":2780},{"batb":[[1,1.66,12.97],[2,1.5,20]],"ltp":2.96,"tv":8.12,"id":31374}]}]}
{"op":"mcm","clk":"11928335739","pt":1724251825510,"mc":[{"id":"1.231851789","rc":[{"batb":[[0,1.42,40.89]],"ltp":1.7,"tv":8.08,"id":60443}]}]}
{"op":"mcm","clk":"11928336670","pt":1724251842022,"mc":[{"id":"1.231851789","rc":[{"batl":[[0,6.8,1.18],[1,12.5,8.27]],"ltp":2.96,"tv":8.12,"id":31374}]}]}
{"op":"mcm","clk":"11928337490","pt":1724251855667,"mc":[{"id":"1.231851789","rc":[{"batl":[[0,6.8,1.45],[1,12.5,8]],"ltp":2.96,"tv":8.12,"id":31374}]}]}
{"op":"mcm","clk":"11928355753","pt":1724252164092,"mc":[{"id":"1.231851789","rc":[{"batb":[[1,1.5,20.89],[2,1.08,31.25]],"ltp":13.5,"tv":0.25,"id":2780},{"batb":[[1,1.5,20],[2,1.08,31.25]],"ltp":2.96,"tv":8.12,"id":31374}]}]}
{"op":"mcm","clk":"11928363279","pt":1724252294430,"mc":[{"id":"1.231851789","rc":[{"batb":[[0,2.04,8.23],[1,2.02,1.67],[2,1.5,20.89]],"ltp":13.5,"tv":0.25,"id":2780},{"batb":[[1,1.66,12.97],[2,1.5,20]],"ltp":2.96,"tv":8.12,"id":31374}]}]}
{"op":"mcm","clk":"11928363486","pt":1724252297825,"mc":[{"id":"1.231851789","rc":[{"batb":[[1,1.5,20.89],[2,1.08,31.25]],"ltp":13.5,"tv":0.25,"id":2780}]}]}
{"op":"mcm","clk":"11928363851","pt":1724252303357,"mc":[{"id":"1.231851789","rc":[{"batb":[[0,2.06,1.64],[1,2.04,8.23],[2,1.5,20.89]],"ltp":13.5,"tv":0.25,"id":2780}]}]}
{"op":"mcm","clk":"11928538941","pt":1724254094863,"mc":[{"id":"1.231851789","rc":[{"batb":[[1,1.5,20.89],[2,1.08,31.25]],"ltp":13.5,"tv":0.25,"id":2780},{"trd":[[1.41,2.07],[1.7,3.12]],"batb":[[1,1.41,19.59]],"ltp":1.7,"tv":8.08,"id":60443},{"trd":[[1.7,2],[1.8,4.99]],"batb":[[0,1.82,1.61],[1,1.5,20],[2,1.08,31.25]],"ltp":2.96,"tv":8.11,"id":31374}],"tv":16.45}]}
{"op":"mcm","clk":"11928555381","pt":1724254262488,"mc":[{"id":"1.231851789","rc":[{"batb":[[0,2.08,7.93],[1,2.06,1.64],[2,1.5,20.89]],"ltp":13.5,"tv":0.25,"id":2780},{"batb":[[1,1.66,12.97],[2,1.5,20]],"ltp":2.96,"tv":8.11,"id":31374}]}]}
{"op":"mcm","clk":"11928555481","pt":1724254263430,"mc":[{"id":"1.231851789","rc":[{"batb":[[1,1.5,20.89],[2,1.08,31.25]],"ltp":13.5,"tv":0.25,"id":2780}]}]}
{"op":"mcm","clk":"11928556068","pt":1724254268906,"mc":[{"id":"1.231851789","rc":[{"batb":[[0,2.1,1.61],[1,2.08,7.93],[2,1.5,20.89]],"ltp":13.5,"tv":0.25,"id":2780}]}]}
{"op":"mcm","clk":"11928787074","pt":1724256051808,"mc":[{"id":"1.231851789","marketDefinition":{"bspMarket":false,"turnInPlayEnabled":true,"persistenceEnabled":true,"marketBaseRate":5.0,"eventId":"33497939","eventTypeId":"4","numberOfWinners":1,"bettingType":"ODDS","marketType":"MATCH_ODDS","marketTime":"2024-08-22T10:00:00.000Z","suspendTime":"2024-08-22T10:00:00.000Z","bspReconciled":false,"complete":true,"inPlay":false,"crossMatching":true,"runnersVoidable":false,"numberOfActiveRunners":3,"betDelay":0,"status":"OPEN","runners":[{"status":"ACTIVE","sortPriority":1,"id":31374,"name":"Durham"},{"status":"ACTIVE","sortPriority":2,"id":2780,"name":"Nottinghamshire"},{"status":"ACTIVE","sortPriority":3,"id":60443,"name":"The Draw"}],"regulators":["MR_INT"],"countryCode":"GB","discountAllowed":true,"timezone":"GMT","openDate":"2024-08-22T10:00:00.000Z","version":6089294947,"name":"Match Odds","eventName":"Durham v Nottinghamshire"}}]}
{"op":"mcm","clk":"11928788484","pt":1724256062949,"mc":[{"id":"1.231851789","rc":[{"batb":[[1,1.5,20.89],[2,1.08,31.25]],"ltp":13.5,"tv":0.25,"id":2780},{"trd":[[1.41,2.07],[1.7,3.12],[1.75,1.78]],"batb":[[0,1.42,40.89],[1,1.41,19.6]],"ltp":1.7,"tv":8.08,"id":60443},{"trd":[[1.7,2],[1.8,4.99]],"batb":[[0,1.82,1.61],[1,1.66,12.97]],"ltp":2.96,"tv":8.11,"id":31374}],"tv":16.44}]}
{"op":"mcm","clk":"11928788551","pt":1724256063527,"mc":[{"id":"1.231851789","rc":[{"batb":[[1,1.5,20],[2,1.08,31.25]],"ltp":2.96,"tv":8.11,"id":31374}]}]}
{"op":"mcm","clk":"11928811013","pt":1724256226768,"mc":[{"id":"1.231851789","rc":[{"batb":[[0,2.12,7.64],[1,2.1,1.61],[2,1.5,20.89]],"ltp":13.5,"tv":0.25,"id":2780},{"batb":[[1,1.7,12.23],[2,1.5,20]],"ltp":2.96,"tv":8.11,"id":31374}]}]}
{"op":"mcm","clk":"11928811336","pt":1724256229239,"mc":[{"id":"1.231851789","rc":[{"batb":[[1,1.5,20.89],[2,1.08,31.25]],"ltp":13.5,"tv":0.25,"id":2780}]}]}
{"op":"mcm","clk":"11928812160","pt":1724256234772,"mc":[{"id":"1.231851789","rc":[{"batb":[[0,2.14,1.58],[1,2.12,7.64],[2,1.5,20.89]],"ltp":13.5,"tv":0.25,"id":2780}]}]}
{"op":"mcm","clk":"11929065736","pt":1724258027224,"mc":[{"id":"1.231851789","rc":[{"batb":[[1,1.5,20.89],[2,1.08,31.25]],"ltp":13.5,"tv":0.25,"id":2780},{"batb":[[1,1.5,20],[2,1.08,31.25]],"ltp":2.96,"tv":8.11,"id":31374}]}]}
{"op":"mcm","clk":"11929089504","pt":1724258171915,"mc":[{"id":"1.231851789","rc":[{"batb":[[0,2.16,7.38],[1,2.14,1.58],[2,1.5,20.89]],"ltp":13.5,"tv":0.25,"id":2780},{"batb":[[1,1.7,12.23],[2,1.5,20]],"ltp":2.96,"tv":8.11,"id":31374}]}]}
{"op":"mcm","clk":"11929089627","pt":1724258172756,"mc":[{"id":"1.231851789","rc":[{"batb":[[1,1.5,20.89],[2,1.08,31.25]],"ltp":13.5,"tv":0.25,"id":2780}]}]}
{"op":"mcm","clk":"11929090618","pt":1724258178344,"mc":[{"id":"1.231851789","rc":[{"batb":[[0,2.18,1.55],[1,2.16,7.38],[2,1.5,20.89]],"ltp":13.5,"tv":0.25,"id":2780}]}]}
{"op":"mcm","clk":"11929381006","pt":1724259978143,"mc":[{"id":"1.231851789","rc":[{"batb":[[1,1.5,20.89],[2,1.08,31.25]],"ltp":13.5,"tv":0.25,"id":2780},{"trd":[[1.41,2.07]],"batb":[[1,1.41,19.58]],"ltp":1.7,"tv":8.07,"id":60443},{"trd":[[1.8,4.99]],"batb":[[0,1.82,1.61],[1,1.5,20],[2,1.08,31.25]],"ltp":2.96,"tv":8.1,"id":31374}],"tv":16.43}]}
{"op":"mcm","clk":"11929408171","pt":1724260129096,"mc":[{"id":"1.231851789","rc":[{"batb":[[1,2.16,7.38],[2,1.5,20.89]],"ltp":13.5,"tv":0.25,"id":2780},{"batb":[[1,1.7,12.22],[2,1.5,20]],"ltp":2.96,"tv":8.1,"id":31374}]}]}
{"op":"mcm","clk":"11929714691","pt":1724261929902,"mc":[{"id":"1.231851789","rc":[{"batb":[[1,1.5,20.89],[2,1.08,31.25]],"ltp":13.5,"tv":0.25,"id":2780},{"batb":[[1,1.5,20],[2,1.08,31.25]],"ltp":2.96,"tv":8.1,"id":31374}]}]}
{"op":"mcm","clk":"11929733685","pt":1724262041914,"mc":[{"id":"1.231851789","rc":[{"batb":[[1,2.16,7.38],[2,1.5,20.89]],"ltp":13.5,"tv":0.25,"id":2780},{"batb":[[1,1.7,12.22],[2,1.5,20]],"ltp":2.96,"tv":8.1,"id":31374}]}]}
{"op":"mcm","clk":"11930006905","pt":1724263842209,"mc":[{"id":"1.231851789","rc":[{"batb":[[1,2.16,7.38]],"ltp":13.5,"tv":0.25,"id":2780},{"batb":[[1,1.41,19.59]],"ltp":1.7,"tv":8.07,"id":60443},{"trd":[[1.8,4.99]],"batb":[[1,1.5,20],[2,1.08,31.25]],"ltp":2.96,"tv":8.1,"id":31374}],"tv":16.43}]}
{"op":"mcm","clk":"11930006940","pt":1724263842372,"mc":[{"id":"1.231851789","rc":[{"batb":[[1,1.5,20.89],[2,1.08,31.25]],"ltp":13.5,"tv":0.25,"id":2780}]}]}
{"op":"mcm","clk":"11930016825","pt":1724263898172,"mc":[{"id":"1.231851789","rc":[{"batb":[[1,2.16,7.38],[2,1.5,20.89]],"ltp":13.5,"tv":0.25,"id":2780},{"batb":[[1,1.7,12.23],[2,1.5,20]],"ltp":2.96,"tv":8.1,"id":31374}]}]}
{"op":"mcm","clk":"11930326728","pt":1724265698584,"mc":[{"id":"1.231851789","rc":[{"batb":[[1,1.5,20.89],[2,1.08,31.25]],"ltp":13.5,"tv":0.25,"id":2780},{"batb":[[1,1.5,20],[2,1.08,31.25]],"ltp":2.96,"tv":8.1,"id":31374}]}]}
{"op":"mcm","clk":"11930331196","pt":1724265725585,"mc":[{"id":"1.231851789","rc":[{"batb":[[1,2.16,7.38],[2,1.5,20.89]],"ltp":13.5,"tv":0.25,"id":2780},{"batb":[[1,1.7,12.23],[2,1.5,20]],"ltp":2.96,"tv":8.1,"id":31374}]}]}
{"op":"mcm","clk":"11930556415","pt":1724267299208,"mc":[{"id":"1.231851789","marketDefinition":{"bspMarket":false,"turnInPlayEnabled":true,"persistenceEnabled":true,"marketBaseRate":5.0,"eventId":"33497939","eventTypeId":"4","numberOfWinners":1,"bettingType":"ODDS","marketType":"MATCH_ODDS","marketTime":"2024-08-22T10:00:00.000Z","suspendTime":"2024-08-22T10:00:00.000Z","bspReconciled":false,"complete":true,"inPlay":false,"crossMatching":true,"runnersVoidable":false,"numberOfActiveRunners":3,"betDelay":0,"status":"OPEN","runners":[{"status":"ACTIVE","sortPriority":1,"id":31374,"name":"Durham"},{"status":"ACTIVE","sortPriority":2,"id":2780,"name":"Nottinghamshire"},{"status":"ACTIVE","sortPriority":3,"id":60443,"name":"The Draw"}],"regulators":["MR_INT"],"countryCode":"GB","discountAllowed":true,"timezone":"GMT","openDate":"2024-08-22T10:00:00.000Z","version":6089833848,"name":"Match Odds","eventName":"Durham v Nottinghamshire"}}]}
{"op":"mcm","clk":"11930585466","pt":1724267526069,"mc":[{"id":"1.231851789","rc":[{"batb":[[1,1.5,20.89],[2,1.08,31.25]],"ltp":13.5,"tv":0.25,"id":2780},{"batb":[[1,1.41,19.59]],"ltp":1.7,"tv":8.07,"id":60443},{"trd":[[1.8,4.98]],"batb":[[1,1.5,20],[2,1.08,31.25]],"ltp":2.96,"tv":8.1,"id":31374}],"tv":16.42}]}
{"op":"mcm","clk":"11930607966","pt":1724267695808,"mc":[{"id":"1.231851789","rc":[{"batb":[[1,2.16,7.38],[2,1.5,20.89]],"ltp":13.5,"tv":0.25,"id":2780},{"batb":[[1,1.7,12.22],[2,1.5,20]],"ltp":2.96,"tv":8.1,"id":31374}]}]}
{"op":"mcm","clk":"11930824038","pt":1724269496228,"mc":[{"id":"1.231851789","rc":[{"batb":[[1,1.5,20.89],[2,1.08,31.25]],"ltp":13.5,"tv":0.25,"id":2780},{"batb":[[1,1.5,20],[2,1.08,31.25]],"ltp":2.96,"tv":8.1,"id":31374}]}]}
{"op":"mcm","clk":"11930837779","pt":1724269623454,"mc":[{"id":"1.231851789","rc":[{"batb":[[1,2.16,7.38],[2,1.5,20.89]],"ltp":13.5,"tv":0.25,"id":2780},{"batb":[[1,1.7,12.22],[2,1.5,20]],"ltp":2.96,"tv":8.1,"id":31374}]}]}
{"op":"mcm","clk":"11931000931","pt":1724271175034,"mc":[{"id":"1.231851789","rc":[{"batb":[[1,2.16,7.38]],"ltp":13.5,"tv":0.25,"id":2780},{"trd":[[1.41,2.07],[1.7,3.12]],"batb":[[1,1.41,19.6]],"ltp":1.7,"tv":8.07,"id":60443},{"trd":[[1.7,2],[1.8,4.99]],"batb":[[0,1.82,1.61],[1,1.7,12.23]],"ltp":2.96,"tv":8.1,"id":31374}],"tv":16.43}]}
{"op":"mcm","clk":"11931027978","pt":1724271423848,"mc":[{"id":"1.231851789","rc":[{"batb":[[1,1.5,20.89],[2,1.08,31.25]],"ltp":13.5,"tv":0.25,"id":2780},{"batb":[[1,1.5,20],[2,1.08,31.25]],"ltp":2.96,"tv":8.1,"id":31374}]}]}
{"op":"mcm","clk":"11931040106","pt":1724271547787,"mc":[{"id":"1.231851789","rc":[{"batb":[[1,2.16,7.38],[2,1.5,20.89]],"ltp":13.5,"tv":0.25,"id":2780},{"batb":[[1,1.7,12.23],[2,1.5,20]],"ltp":2.96,"tv":8.1,"id":31374}]}]}
{"op":"mcm","clk":"11931198464","pt":1724273348265,"mc":[{"id":"1.231851789","rc":[{"batb":[[1,1.5,20.89],[2,1.08,31.25]],"ltp":13.5,"tv":0.25,"id":2780},{"batb":[[1,1.5,20],[2,1.08,31.25]],"ltp":2.96,"tv":8.1,"id":31374}]}]}
{"op":"mcm","clk":"11931202737","pt":1724273407930,"mc":[{"id":"1.231851789","rc":[{"batb":[[1,2.16,7.38],[2,1.5,20.89]],"ltp":13.5,"tv":0.25,"id":2780},{"batb":[[1,1.7,12.23],[2,1.5,20]],"ltp":2.96,"tv":8.1,"id":31374}]}]}
{"op":"mcm","clk":"11931345291","pt":1724275208929,"mc":[{"id":"1.231851789","rc":[{"batb":[[1,1.5,20.89],[2,1.08,31.25]],"ltp":13.5,"tv":0.25,"id":2780},{"batb":[[1,1.41,19.59]],"ltp":1.7,"tv":8.07,"id":60443},{"batb":[[1,1.5,20],[2,1.08,31.25]],"ltp":2.96,"tv":8.1,"id":31374}]}]}
{"op":"mcm","clk":"11931346726","pt":1724275227266,"mc":[{"id":"1.231851789","rc":[{"batb":[[1,1.7,12.23],[2,1.5,20]],"ltp":2.96,"tv":8.1,"id":31374}]}]}
{"op":"mcm","clk":"11931346735","pt":1724275227366,"mc":[{"id":"1.231851789","rc":[{"batb":[[1,2.16,7.38],[2,1.5,20.89]],"ltp":13.5,"tv":0.25,"id":2780}]}]}
{"op":"mcm","clk":"11931489525","pt":1724277027977,"mc":[{"id":"1.231851789","rc":[{"batb":[[1,1.5,20.89],[2,1.08,31.25]],"ltp":13.5,"tv":0.25,"id":2780},{"batb":[[1,1.5,20],[2,1.08,31.25]],"ltp":2.96,"tv":8.1,"id":31374}]}]}
{"op":"mcm","clk":"11931502411","pt":1724277203992,"mc":[{"id":"1.231851789","rc":[{"batb":[[1,2.16,7.38],[2,1.5,20.89]],"ltp":13.5,"tv":0.25,"id":2780},{"batb":[[1,1.7,12.23],[2,1.5,20]],"ltp":2.96,"tv":8.1,"id":31374}]}]}
{"op":"mcm","clk":"11931619174","pt":1724279004263,"mc":[{"id":"1.231851789","rc":[{"batb":[[1,1.5,20.89],[2,1.08,31.25]],"ltp":13.5,"tv":0.25,"id":2780},{"batb":[[1,1.41,19.58]],"ltp":1.7,"tv":8.07,"id":60443},{"batb":[[1,1.7,12.22]],"ltp":2.96,"tv":8.1,"id":31374}]}]}
{"op":"mcm","clk":"11931619183","pt":1724279004416,"mc":[{"id":"1.231851789","rc":[{"batb":[[1,1.5,20],[2,1.08,31.25]],"ltp":2.96,"tv":8.1,"id":31374}]}]}
{"op":"mcm","clk":"11931626728","pt":1724279140990,"mc":[{"id":"1.231851789","rc":[{"batb":[[1,2.16,7.38],[2,1.5,20.89]],"ltp":13.5,"tv":0.25,"id":2780},{"batb":[[1,1.7,12.22],[2,1.5,20]],"ltp":2.96,"tv":8.1,"id":31374}]}]}
{"op":"mcm","clk":"11931736966","pt":1724280941269,"mc":[{"id":"1.231851789","rc":[{"batb":[[1,1.5,20.89],[2,1.08,31.25]],"ltp":13.5,"tv":0.25,"id":2780},{"batb":[[1,1.5,20],[2,1.08,31.25]],"ltp":2.96,"tv":8.1,"id":31374}]}]}
{"op":"mcm","clk":"11931743741","pt":1724281058022,"mc":[{"id":"1.231851789","rc":[{"batb":[[1,2.16,7.38],[2,1.5,20.89]],"ltp":13.5,"tv":0.25,"id":2780},{"batb":[[1,1.7,12.22],[2,1.5,20]],"ltp":2.96,"tv":8.1,"id":31374}]}]}
{"op":"mcm","clk":"11931815542","pt":1724281975054,"mc":[{"id":"1.231851789","rc":[{"batb":[[1,2.16,7.38]],"ltp":13.5,"tv":0.25,"id":2780},{"batb":[[1,1.41,19.6]],"ltp":1.7,"tv":8.07,"id":60443},{"batb":[[1,1.7,12.23]],"ltp":2.96,"tv":8.1,"id":31374}]}]}
{"op":"mcm","clk":"11931893390","pt":1724282858204,"mc":[{"id":"1.231851789","rc":[{"batb":[[1,1.5,20],[2,1.08,31.25]],"ltp":2.96,"tv":8.1,"id":31374}]}]}
{"op":"mcm","clk":"11931893409","pt":1724282858409,"mc":[{"id":"1.231851789","rc":[{"batb":[[1,1.5,20.89],[2,1.08,31.25]],"ltp":13.5,"tv":0.25,"id":2780}]}]}
{"op":"mcm","clk":"11931901329","pt":1724282951522,"mc":[{"id":"1.231851789","rc":[{"batb":[[1,2.16,7.38],[2,1.5,20.89]],"ltp":13.5,"tv":0.25,"id":2780},{"batb":[[1,1.7,12.23],[2,1.5,20]],"ltp":2.96,"tv":8.1,"id":31374}]}]}
{"op":"mcm","clk":"11932051656","pt":1724284751872,"mc":[{"id":"1.231851789","rc":[{"batb":[[1,1.5,20.89],[2,1.08,31.25]],"ltp":13.5,"tv":0.25,"id":2780},{"batb":[[1,1.5,20],[2,1.08,31.25]],"ltp":2.96,"tv":8.1,"id":31374}]}]}
{"op":"mcm","clk":"11932057252","pt":1724284827186,"mc":[{"id":"1.231851789","rc":[{"batb":[[1,2.16,7.38],[2,1.5,20.89]],"ltp":13.5,"tv":0.25,"id":2780},{"batb":[[1,1.41,19.59]],"ltp":1.7,"tv":8.07,"id":60443},{"batb":[[1,1.7,12.23],[2,1.5,20]],"ltp":2.96,"tv":8.1,"id":31374}]}]}
{"op":"mcm","clk":"11932195442","pt":1724286627460,"mc":[{"id":"1.231851789","rc":[{"batb":[[1,1.5,20.89],[2,1.08,31.25]],"ltp":13.5,"tv":0.25,"id":2780},{"batb":[[1,1.5,20],[2,1.08,31.25]],"ltp":2.96,"tv":8.1,"id":31374}]}]}
{"op":"mcm","clk":"11932199256","pt":1724286677984,"mc":[{"id":"1.231851789","rc":[{"batb":[[1,2.16,7.38],[2,1.5,20.89]],"ltp":13.5,"tv":0.25,"id":2780},{"batb":[[1,1.7,12.23],[2,1.5,20]],"ltp":2.96,"tv":8.1,"id":31374}]}]}
{"op":"mcm","clk":"11932354258","pt":1724288478212,"mc":[{"id":"1.231851789","rc":[{"batb":[[1,2.16,7.38]],"ltp":13.5,"tv":0.25,"id":2780},{"batb":[[1,1.41,19.59]],"ltp":1.7,"tv":8.07,"id":60443},{"batb":[[1,1.5,20],[2,1.08,31.25]],"ltp":2.96,"tv":8.1,"id":31374}],"tv":16.43}]}
{"op":"mcm","clk":"11932354274","pt":1724288478421,"mc":[{"id":"1.231851789","rc":[{"batb":[[1,1.5,20.89],[2,1.08,31.25]],"ltp":13.5,"tv":0.25,"id":2780}]}]}
{"op":"mcm","clk":"11932356436","pt":1724288510883,"mc":[{"id":"1.231851789","rc":[{"batb":[[1,2.16,7.38],[2,1.5,20.89]],"ltp":13.5,"tv":0.25,"id":2780},{"batb":[[1,1.7,12.22],[2,1.5,20]],"ltp":2.96,"tv":8.1,"id":31374}]}]}
{"op":"mcm","clk":"11932477196","pt":1724290311066,"mc":[{"id":"1.231851789","rc":[{"batb":[[1,1.5,20.89],[2,1.08,31.25]],"ltp":13.5,"tv":0.25,"id":2780}]}]}
{"op":"mcm","clk":"11932477233","pt":1724290311680,"mc":[{"id":"1.231851789","rc":[{"batb":[[1,1.5,20],[2,1.08,31.25]],"ltp":2.96,"tv":8.1,"id":31374}]}]}
{"op":"mcm","clk":"11932477839","pt":1724290322264,"mc":[{"id":"1.231851789","rc":[{"batb":[[1,2.16,7.38],[2,1.5,20.89]],"ltp":13.5,"tv":0.25,"id":2780},{"batb":[[1,1.7,12.22],[2,1.5,20]],"ltp":2.96,"tv":8.1,"id":31374}]}]}
{"op":"mcm","clk":"11932587815","pt":1724292122670,"mc":[{"id":"1.231851789","rc":[{"batb":[[1,1.5,20.89],[2,1.08,31.25]],"ltp":13.5,"tv":0.25,"id":2780},{"batb":[[1,1.5,20],[2,1.08,31.25]],"ltp":2.96,"tv":8.1,"id":31374}],"tv":16.44}]}
{"op":"mcm","clk":"11932597874","pt":1724292280149,"mc":[{"id":"1.231851789","rc":[{"batb":[[1,2.16,7.38],[2,1.5,20.89]],"ltp":13.5,"tv":0.25,"id":2780},{"batb":[[1,1.7,12.22],[2,1.5,20]],"ltp":2.96,"tv":8.1,"id":31374}]}]}
{"op":"mcm","clk":"11932715128","pt":1724294080550,"mc":[{"id":"1.231851789","rc":[{"batb":[[1,1.5,20.89],[2,1.08,31.25]],"ltp":13.5,"tv":0.25,"id":2780},{"batb":[[1,1.5,20],[2,1.08,31.25]],"ltp":2.96,"tv":8.1,"id":31374}]}]}
{"op":"mcm","clk":"11932720995","pt":1724294215071,"mc":[{"id":"1.231851789","rc":[{"batb":[[1,2.16,7.38],[2,1.5,20.89]],"ltp":13.5,"tv":0.25,"id":2780},{"batb":[[1,1.7,12.22],[2,1.5,20]],"ltp":2.96,"tv":8.1,"id":31374}]}]}
{"op":"mcm","clk":"11932812110","pt":1724296015161,"mc":[{"id":"1.231851789","rc":[{"batb":[[1,1.5,20],[2,1.08,31.25]],"ltp":2.96,"tv":8.1,"id":31374}],"tv":16.43}]}
{"op":"mcm","clk":"11932812125","pt":1724296015366,"mc":[{"id":"1.231851789","rc":[{"batb":[[1,1.5,20.89],[2,1.08,31.25]],"ltp":13.5,"tv":0.25,"id":2780}]}]}
{"op":"mcm","clk":"11932816977","pt":1724296125073,"mc":[{"id":"1.231851789","rc":[{"batb":[[1,2.16,7.38],[2,1.5,20.89]],"ltp":13.5,"tv":0.25,"id":2780},{"batb":[[1,1.7,12.22],[2,1.5,20]],"ltp":2.96,"tv":8.1,"id":31374}]}]}
{"op":"mcm","clk":"11932910970","pt":1724297925299,"mc":[{"id":"1.231851789","rc":[{"batb":[[1,1.5,20],[2,1.08,31.25]],"ltp":2.96,"tv":8.1,"id":31374}]}]}
{"op":"mcm","clk":"11932910982","pt":1724297925452,"mc":[{"id":"1.231851789","rc":[{"batb":[[1,1.5,20.89],[2,1.08,31.25]],"ltp":13.5,"tv":0.25,"id":2780}]}]}
{"op":"mcm","clk":"11932916624","pt":1724298023473,"mc":[{"id":"1.231851789","rc":[{"batb":[[1,2.16,7.38],[2,1.5,20.89]],"ltp":13.5,"tv":0.25,"id":2780},{"batb":[[1,1.7,12.22],[2,1.5,20]],"ltp":2.96,"tv":8.1,"id":31374}]}]}
{"op":"mcm","clk":"11933023072","pt":1724299823963,"mc":[{"id":"1.231851789","rc":[{"batb":[[1,1.5,20.89],[2,1.08,31.25]],"ltp":13.5,"tv":0.25,"id":2780},{"batb":[[1,1.41,19.59]],"ltp":1.7,"tv":8.07,"id":60443},{"batb":[[1,1.5,20],[2,1.08,31.25]],"ltp":2.96,"tv":8.1,"id":31374}]}]}
{"op":"mcm","clk":"11933028434","pt":1724299911668,"mc":[{"id":"1.231851789","rc":[{"batb":[[1,2.16,7.38],[2,1.5,20.89]],"ltp":13.5,"tv":0.25,"id":2780},{"batb":[[1,1.7,12.23],[2,1.5,20]],"ltp":2.96,"tv":8.1,"id":31374}]}]}
{"op":"mcm","clk":"11933119761","pt":1724301712117,"mc":[{"id":"1.231851789","rc":[{"batb":[[1,1.5,20.89],[2,1.08,31.25]],"ltp":13.5,"tv":0.25,"id":2780},{"batb":[[1,1.5,20],[2,1.08,31.25]],"ltp":2.96,"tv":8.1,"id":31374}]}]}
{"op":"mcm","clk":"11933123620","pt":1724301786619,"mc":[{"id":"1.231851789","rc":[{"batb":[[1,2.16,7.38],[2,1.5,20.89]],"ltp":13.5,"tv":0.25,"id":2780},{"batb":[[1,1.7,12.23],[2,1.5,20]],"ltp":2.96,"tv":8.1,"id":31374}]}]}
{"op":"mcm","clk":"11933231814","pt":1724303575025,"mc":[{"id":"1.231851789","rc":[{"batb":[[1,1.41,19.59]],"ltp":1.7,"tv":8.08,"id":60443},{"batb":[[1,1.7,12.23]],"ltp":2.96,"tv":8.1,"id":31374}],"tv":16.44}]}
{"op":"mcm","clk":"11933236029","pt":1724303587077,"mc":[{"id":"1.231851789","rc":[{"batb":[[1,1.5,20.89],[2,1.08,31.25]],"ltp":13.5,"tv":0.25,"id":2780},{"batb":[[1,1.5,20],[2,1.08,31.25]],"ltp":2.96,"tv":8.1,"id":31374}]}]}
{"op":"mcm","clk":"11933238934","pt":1724303663020,"mc":[{"id":"1.231851789","rc":[{"batb":[[1,2.16,7.38],[2,1.5,20.89]],"ltp":13.5,"tv":0.25,"id":2780},{"batb":[[1,1.7,12.23],[2,1.5,20]],"ltp":2.96,"tv":8.1,"id":31374}]}]}
{"op":"mcm","clk":"11933304274","pt":1724304878110,"mc":[{"id":"1.231851789","rc":[{"batl":[[0,55,1.57],[1,85,1],[2,95,5.85]],"ltp":1.7,"tv":8.08,"id":60443}]}]}
{"op":"mcm","clk":"11933304334","pt":1724304878984,"mc":[{"id":"1.231851789","rc":[{"batl":[[1,95,5.85],[2,990,5.51]],"ltp":1.7,"tv":8.08,"id":60443}]}]}
{"op":"mcm","clk":"11933304652","pt":1724304884626,"mc":[{"id":"1.231851789","rc":[{"batl":[[0,50,1.81],[1,90,1.62],[2,95,5]],"ltp":1.7,"tv":8.08,"id":60443}]}]}
{"op":"mcm","clk":"11933304703","pt":1724304885500,"mc":[{"id":"1.231851789","rc":[{"batl":[[0,46,1.4],[1,50,1.17],[2,95,5.85]],"ltp":1.7,"tv":8.08,"id":60443}]}]}
