{"op":"mcm","clk":"11876643920","pt":1724078118822,"mc":[{"id":"1.232018919","marketDefinition":{"bspMarket":false,"turnInPlayEnabled":true,"persistenceEnabled":true,"marketBaseRate":5.0,"eventId":"33508296","eventTypeId":"4","numberOfWinners":1,"bettingType":"ODDS","marketType":"MATCH_ODDS","marketTime":"2024-08-20T16:00:00.000Z","suspendTime":"2024-08-20T16:00:00.000Z","bspReconciled":false,"complete":true,"inPlay":false,"crossMatching":true,"runnersVoidable":false,"numberOfActiveRunners":2,"betDelay":0,"status":"OPEN","runners":[{"status":"ACTIVE","sortPriority":1,"id":72857115,"name":"Miami Lions"},{"status":"ACTIVE","sortPriority":2,"id":72857116,"name":"Grand Cayman Stingrays"}],"regulators":["MR_INT"],"countryCode":"GB","discountAllowed":true,"timezone":"GMT","openDate":"2024-08-20T16:00:00.000Z","version":6086446828,"name":"Match Odds","eventName":"Miami Lions v Grand Cayman Stingrays"},"rc":[{"batb":[[0,1.03,200],[1,1.02,200],[2,1.01,220]],"ltp":0.0,"tv":0.0,"id":72857115},{"batb":[[0,1.03,200],[1,1.02,200],[2,1.01,220]],"ltp":0.0,"tv":0.0,"id":72857116}]}]}
{"op":"mcm","clk":"11876916826","pt":1724081447799,"mc":[{"id":"1.232018919","rc":[{"batb":[[2,1.01,480.89]],"ltp":0.0,"tv":0.0,"id":72857115}]}]}
{"op":"mcm","clk":"11876916856","pt":1724081448062,"mc":[{"id":"1.232018919","rc":[{"batb":[[2,1.01,480.89]],"ltp":0.0,"tv":0.0,"id":72857116}]}]}
{"op":"mcm","clk":"11876968428","pt":1724082039694,"mc":[{"id":"1.232018919","rc":[{"batb":[[0,1.11,24.82],[1,1.03,200],[2,1.02,200]],"ltp":0.0,"tv":0.0,"id":72857115}]}]}
{"op":"mcm","clk":"11876969646","pt":1724082052905,"mc":[{"id":"1.232018919","rc":[{"batb":[[0,1.11,24.82],[1,1.03,200],[2,1.02,200]],"ltp":0.0,"tv":0.0,"id":72857116}]}]}
{"op":"mcm","clk":"11876971656","pt":1724082075045,"mc":[{"id":"1.232018919","rc":[{"batb":[[0,1.12,71.37],[1,1.11,24.82],[2,1.03,200]],"ltp":0.0,"tv":0.0,"id":72857115},{"batb":[[0,1.12,71.37],[1,1.11,24.82],[2,1.03,200]],"ltp":0.0,"tv":0.0,"id":72857116}]}]}
{"op":"mcm","clk":"11877049445","pt":1724082941373,"mc":[{"id":"1.232018919","rc":[{"batb":[[0,1.2,250],[1,1.12,71.37],[2,1.11,24.82]],"ltp":0.0,"tv":0.0,"id":72857115}]}]}
{"op":"mcm","clk":"11877049529","pt":1724082942142,"mc":[{"id":"1.232018919","rc":[{"batb":[[0,1.2,250],[1,1.12,71.37],[2,1.11,24.82]],"ltp":0.0,"tv":0.0,"id":72857116}]}]}
{"op":"mcm","clk":"11877134755","pt":1724083876219,"mc":[{"id":"1.232018919","rc":[{"batb":[[1,1.11,24.83],[2,1.03,200]],"ltp":0.0,"tv":0.0,"id":72857115},{"batb":[[1,1.11,24.83],[2,1.03,200]],"ltp":0.0,"tv":0.0,"id":72857116}]}]}
{"op":"mcm","clk":"11877138187","pt":1724083913864,"mc":[{"id":"1.232018919","rc":[{"batb":[[0,1.21,40.81],[1,1.2,250],[2,1.11,24.83]],"ltp":0.0,"tv":0.0,"id":72857115},{"batb":[[0,1.21,40.81],[1,1.2,250],[2,1.11,24.83]],"ltp":0.0,"tv":0.0,"id":72857116}]}]}
{"op":"mcm","clk":"11877155690","pt":1724083996426,"mc":[{"id":"1.232018919","rc":[{"batb":[[0,1.22,5.99],[1,1.21,40.81],[2,1.2,250]],"ltp":0.0,"tv":0.0,"id":72857115}]}]}
{"op":"mcm","clk":"11877155731","pt":1724083996849,"mc":[{"id":"1.232018919","rc":[{"batb":[[0,1.22,7.15],[1,1.21,40.81],[2,1.2,250]],"ltp":0.0,"tv":0.0,"id":72857116}]}]}
{"op":"mcm","clk":"11877170862","pt":1724084166513,"mc":[{"id":"1.232018919","rc":[{"batb":[[0,1.22,6.53]],"ltp":0.0,"tv":0.0,"id":72857115}]}]}
{"op":"mcm","clk":"11877171878","pt":1724084176840,"mc":[{"id":"1.232018919","rc":[{"batb":[[0,1.22,7.69]],"ltp":0.0,"tv":0.0,"id":72857116}]}]}
{"op":"mcm","clk":"11877314204","pt":1724085714822,"mc":[{"id":"1.232018919","rc":[{"batb":[[1,1.2,250],[2,1.11,24.83]],"ltp":0.0,"tv":0.0,"id":72857116}]}]}
{"op":"mcm","clk":"11877314224","pt":1724085715027,"mc":[{"id":"1.232018919","rc":[{"batb":[[1,1.2,250],[2,1.11,24.83]],"ltp":0.0,"tv":0.0,"id":72857115}]}]}
{"op":"mcm","clk":"11877318079","pt":1724085755731,"mc":[{"id":"1.232018919","rc":[{"batb":[[0,1.23,37.8],[1,1.22,5.99],[2,1.2,250]],"ltp":0.0,"tv":0.0,"id":72857115},{"batb":[[0,1.23,37.8],[1,1.22,7.15],[2,1.2,250]],"ltp":0.0,"tv":0.0,"id":72857116}]}]}
{"op":"mcm","clk":"11877403991","pt":1724086748501,"mc":[{"id":"1.232018919","rc":[{"batb":[[0,1.24,6.53],[1,1.23,37.26]],"ltp":0.0,"tv":0.0,"id":72857115},{"batb":[[0,1.24,7.69],[1,1.23,37.26]],"ltp":0.0,"tv":0.0,"id":72857116}]}]}
{"op":"mcm","clk":"11877493498","pt":1724087556388,"mc":[{"id":"1.232018919","rc":[{"batb":[[1,1.2,250],[2,1.11,24.84]],"ltp":0.0,"tv":0.0,"id":72857115},{"batb":[[1,1.2,250],[2,1.11,24.84]],"ltp":0.0,"tv":0.0,"id":72857116}]}]}
{"op":"mcm","clk":"11877495775","pt":1724087576118,"mc":[{"id":"1.232018919","rc":[{"batb":[[0,1.25,34.83],[1,1.24,5.99],[2,1.2,250]],"ltp":0.0,"tv":0.0,"id":72857115},{"batb":[[0,1.25,34.83],[1,1.24,7.15],[2,1.2,250]],"ltp":0.0,"tv":0.0,"id":72857116}]}]}
{"op":"mcm","clk":"11877541774","pt":1724087982459,"mc":[{"id":"1.232018919","rc":[{"batb":[[0,1.26,2.06],[1,1.25,34.29],[2,1.24,5.99]],"ltp":0.0,"tv":0.0,"id":72857115}]}]}
{"op":"mcm","clk":"11877542165","pt":1724087986077,"mc":[{"id":"1.232018919","rc":[{"trd":[[1.26,3.05],[1.4,1.08]],"batb":[[0,1.25,34.29],[1,1.24,5.99],[2,1.2,250]],"batl":[[0,1.26,0.25]],"ltp":1.26,"tv":4.12,"id":72857115}],"tv":4.12}]}
{"op":"mcm","clk":"11877544357","pt":1724088005475,"mc":[{"id":"1.232018919","rc":[{"batb":[[0,1.26,7.7],[1,1.25,34.29],[2,1.24,7.15]],"ltp":0.0,"tv":0.0,"id":72857116}]}]}
{"op":"mcm","clk":"11877545020","pt":1724088010898,"mc":[{"id":"1.232018919","rc":[{"trd":[[1.26,14.33],[1.4,1.08]],"batb":[[0,1.25,34.29],[1,1.24,7.15],[2,1.2,250]],"batl":[[0,1.26,0.77]],"ltp":1.26,"tv":15.4,"id":72857116}],"tv":19.52}]}
{"op":"mcm","clk":"11877546853","pt":1724088027889,"mc":[{"id":"1.232018919","rc":[{"batb":[[0,1.26,26.87],[1,1.25,34.29],[2,1.24,5.99]],"ltp":1.26,"tv":4.12,"id":72857115}]}]}
{"op":"mcm","clk":"11877547420","pt":1724088033017,"mc":[{"id":"1.232018919","rc":[{"trd":[[1.26,56.78]],"batb":[[0,1.25,34.29],[1,1.24,5.99],[2,1.2,250]],"batl":[[0,1.26,0.09]],"ltp":1.26,"tv":57.85,"id":72857115}],"tv":73.26}]}
{"op":"mcm","clk":"11877549601","pt":1724088051543,"mc":[{"id":"1.232018919","rc":[{"batb":[[0,1.26,98.51],[1,1.25,34.29],[2,1.24,7.15]],"ltp":1.26,"tv":15.4,"id":72857116}]}]}
{"op":"mcm","clk":"11877550187","pt":1724088056325,"mc":[{"id":"1.232018919","rc":[{"trd":[[1.26,211.34]],"batb":[[0,1.25,34.29],[1,1.24,7.15],[2,1.2,250]],"batl":[[0,1.26,0.09]],"ltp":1.26,"tv":212.41,"id":72857116}],"tv":270.27}]}
{"op":"mcm","clk":"11877551346","pt":1724088065840,"mc":[{"id":"1.232018919","rc":[{"batb":[[0,1.25,34.83]],"ltp":1.26,"tv":212.41,"id":72857116}]}]}
{"op":"mcm","clk":"11877552545","pt":1724088075887,"mc":[{"id":"1.232018919","rc":[{"batb":[[0,1.25,34.83]],"ltp":1.26,"tv":57.85,"id":72857115}]}]}
{"op":"mcm","clk":"11877553552","pt":1724088083951,"mc":[{"id":"1.232018919","rc":[{"batb":[[0,1.26,376.66],[1,1.25,34.29],[2,1.24,5.99]],"ltp":1.26,"tv":57.85,"id":72857115}]}]}
{"op":"mcm","clk":"11877554538","pt":1724088092173,"mc":[{"id":"1.232018919","rc":[{"trd":[[1.26,809.02],[1.4,2.15]],"batb":[[0,1.25,34.29],[1,1.24,5.99],[2,1.2,250]],"batl":[[0,1.26,0.02]],"ltp":1.26,"tv":811.17,"id":72857115}],"tv":1023.59}]}
{"op":"mcm","clk":"11877555896","pt":1724088103467,"mc":[{"id":"1.232018919","rc":[{"batb":[[0,1.25,34.83]],"ltp":1.26,"tv":811.17,"id":72857115}]}]}
{"op":"mcm","clk":"11877558900","pt":1724088129548,"mc":[{"id":"1.232018919","rc":[{"batb":[[0,1.26,394.57],[1,1.25,34.29],[2,1.24,7.15]],"ltp":1.26,"tv":212.41,"id":72857116}]}]}
{"op":"mcm","clk":"11877559728","pt":1724088137220,"mc":[{"id":"1.232018919","rc":[{"trd":[[1.26,999.4],[1.4,2.15]],"batb":[[0,1.25,34.29],[1,1.24,7.15],[2,1.2,250]],"batl":[[0,1.26,0.59]],"ltp":1.26,"tv":1001.55,"id":72857116}],"tv":1812.73}]}
{"op":"mcm","clk":"11877563722","pt":1724088171908,"mc":[{"id":"1.232018919","rc":[{"batb":[[0,1.26,97.25],[1,1.25,34.29],[2,1.24,5.99]],"ltp":1.26,"tv":811.17,"id":72857115}]}]}
{"op":"mcm","clk":"11877564468","pt":1724088178505,"mc":[{"id":"1.232018919","rc":[{"trd":[[1.26,1002.06],[1.4,3.23]],"batb":[[0,1.25,34.49],[1,1.24,5.99],[2,1.2,250]],"ltp":1.26,"tv":1005.28,"id":72857115}],"tv":2006.84}]}
{"op":"mcm","clk":"11877565427","pt":1724088186501,"mc":[{"id":"1.232018919","rc":[{"batb":[[0,1.25,34.83]],"ltp":1.26,"tv":1001.55,"id":72857116}]}]}
{"op":"mcm","clk":"11877566615","pt":1724088196804,"mc":[{"id":"1.232018919","rc":[{"batb":[[0,1.25,35.03]],"ltp":1.26,"tv":1005.28,"id":72857115}]}]}
{"op":"mcm","clk":"11877567130","pt":1724088201036,"mc":[{"id":"1.232018919","rc":[{"batb":[[0,1.25,34.83]],"ltp":1.26,"tv":1005.28,"id":72857115}]}]}
{"op":"mcm","clk":"11877648178","pt":1724088932302,"mc":[{"id":"1.232018919","rc":[{"batb":[[0,1.4,2.08],[1,1.25,34.29],[2,1.24,7.15]],"ltp":1.26,"tv":1001.55,"id":72857116}]}]}
{"op":"mcm","clk":"11877648587","pt":1724088936000,"mc":[{"id":"1.232018919","rc":[{"batb":[[0,1.25,34.83],[1,1.24,7.15],[2,1.2,250]],"ltp":1.26,"tv":1001.55,"id":72857116}]}]}
{"op":"mcm","clk":"11877652203","pt":1724088968429,"mc":[{"id":"1.232018919","rc":[{"batl":[[0,1.5,1.54]],"ltp":1.26,"tv":1001.55,"id":72857116}]}]}
{"op":"mcm","clk":"11877653871","pt":1724088983084,"mc":[{"id":"1.232018919","rc":[{"batb":[[0,1.5,1.54],[1,1.25,34.83],[2,1.24,7.15]],"ltp":1.26,"tv":1001.55,"id":72857116}]}]}
{"op":"mcm","clk":"11877654154","pt":1724088985334,"mc":[{"id":"1.232018919","rc":[{"batb":[[0,1.25,34.83],[1,1.24,7.15],[2,1.2,250]],"ltp":1.26,"tv":1001.55,"id":72857116}]}]}
{"op":"mcm","clk":"11877660355","pt":1724089037996,"mc":[{"id":"1.232018919","rc":[{"batb":[[0,1.5,1.54],[1,1.25,34.83],[2,1.24,7.15]],"ltp":1.26,"tv":1001.55,"id":72857116}]}]}
{"op":"mcm","clk":"11877660466","pt":1724089039035,"mc":[{"id":"1.232018919","rc":[{"trd":[[1.5,3.08]],"batb":[[0,1.25,34.83],[1,1.24,7.15],[2,1.2,250]],"ltp":1.5,"tv":1004.63,"id":72857116}],"tv":2009.92}]}
{"op":"mcm","clk":"11877664759","pt":1724089074775,"mc":[{"id":"1.232018919","rc":[{"trd":[[1.5,6.16]],"ltp":1.5,"tv":1007.71,"id":72857116}],"tv":2013.0}]}
{"op":"mcm","clk":"11877667092","pt":1724089093591,"mc":[{"id":"1.232018919","rc":[{"batb":[[0,1.26,14.54],[1,1.25,34.29],[2,1.24,5.99]],"batl":[[0,3.5,35.82]],"ltp":1.26,"tv":1005.28,"id":72857115}]}]}
{"op":"mcm","clk":"11877667364","pt":1724089095871,"mc":[{"id":"1.232018919","rc":[{"batb":[[0,1.26,10.54]],"ltp":1.26,"tv":1005.28,"id":72857115}]}]}
{"op":"mcm","clk":"11877667482","pt":1724089096878,"mc":[{"id":"1.232018919","rc":[{"batb":[[0,1.25,34.83],[1,1.24,5.99],[2,1.2,250]],"ltp":1.26,"tv":1005.28,"id":72857115}]}]}
{"op":"mcm","clk":"11877667782","pt":1724089099599,"mc":[{"id":"1.232018919","rc":[{"batb":[[0,1.26,14.54],[1,1.25,34.29],[2,1.24,5.99]],"ltp":1.26,"tv":1005.28,"id":72857115}]}]}
{"op":"mcm","clk":"11877668154","pt":1724089102302,"mc":[{"id":"1.232018919","rc":[{"batb":[[0,1.26,10.54]],"ltp":1.26,"tv":1005.28,"id":72857115}]}]}
{"op":"mcm","clk":"11877668286","pt":1724089103306,"mc":[{"id":"1.232018919","rc":[{"batb":[[0,1.25,34.83],[1,1.24,5.99],[2,1.2,250]],"ltp":1.26,"tv":1005.28,"id":72857115}]}]}
{"op":"mcm","clk":"11877670126","pt":1724089115117,"mc":[{"id":"1.232018919","rc":[{"batb":[[0,1.26,14.54],[1,1.25,34.29],[2,1.24,5.99]],"ltp":1.26,"tv":1005.28,"id":72857115}]}]}
{"op":"mcm","clk":"11877670567","pt":1724089118632,"mc":[{"id":"1.232018919","rc":[{"batb":[[0,1.25,34.83],[1,1.24,5.99],[2,1.2,250]],"ltp":1.26,"tv":1005.28,"id":72857115}]}]}
{"op":"mcm","clk":"11877671072","pt":1724089122529,"mc":[{"id":"1.232018919","rc":[{"batb":[[0,1.26,14.54],[1,1.25,34.29],[2,1.24,5.99]],"ltp":1.26,"tv":1005.28,"id":72857115}]}]}
{"op":"mcm","clk":"11877671447","pt":1724089125321,"mc":[{"id":"1.232018919","rc":[{"batb":[[0,1.26,10.54]],"ltp":1.26,"tv":1005.28,"id":72857115}]}]}
{"op":"mcm","clk":"11877671566","pt":1724089126319,"mc":[{"id":"1.232018919","rc":[{"batb":[[0,1.25,34.83],[1,1.24,5.99],[2,1.2,250]],"ltp":1.26,"tv":1005.28,"id":72857115}]}]}
{"op":"mcm","clk":"11877671828","pt":1724089128330,"mc":[{"id":"1.232018919","rc":[{"batb":[[0,1.26,4.54],[1,1.25,34.29],[2,1.24,5.99]],"ltp":1.26,"tv":1005.28,"id":72857115}]}]}
{"op":"mcm","clk":"11877671899","pt":1724089128938,"mc":[{"id":"1.232018919","rc":[{"batb":[[0,1.27,10.54],[1,1.26,4],[2,1.25,34.29]],"ltp":1.26,"tv":1005.28,"id":72857115}]}]}
{"op":"mcm","clk":"11877672180","pt":1724089131237,"mc":[{"id":"1.232018919","rc":[{"batb":[[1,1.25,34.29],[2,1.24,5.99]],"ltp":1.26,"tv":1005.28,"id":72857115}]}]}
{"op":"mcm","clk":"11877672321","pt":1724089132436,"mc":[{"id":"1.232018919","rc":[{"batb":[[0,1.25,34.83],[1,1.24,5.99],[2,1.2,250]],"ltp":1.26,"tv":1005.28,"id":72857115}]}]}
{"op":"mcm","clk":"11877672571","pt":1724089134447,"mc":[{"id":"1.232018919","rc":[{"batb":[[0,1.26,4.54],[1,1.25,34.29],[2,1.24,5.99]],"ltp":1.26,"tv":1005.28,"id":72857115}]}]}
{"op":"mcm","clk":"11877672794","pt":1724089136235,"mc":[{"id":"1.232018919","rc":[{"batb":[[0,1.27,10.54],[1,1.26,4],[2,1.25,34.29]],"ltp":1.26,"tv":1005.28,"id":72857115},{"trd":[[1.5,529.96]],"ltp":1.5,"tv":1531.51,"id":72857116}],"tv":2536.8}]}
{"op":"mcm","clk":"11877672909","pt":1724089137030,"mc":[{"id":"1.232018919","rc":[{"batb":[[1,1.25,34.29],[2,1.24,5.99]],"ltp":1.26,"tv":1005.28,"id":72857115}]}]}
{"op":"mcm","clk":"11877673230","pt":1724089139530,"mc":[{"id":"1.232018919","rc":[{"batb":[[0,1.26,4.54]],"ltp":1.26,"tv":1005.28,"id":72857115}]}]}
{"op":"mcm","clk":"11877673551","pt":1724089142049,"mc":[{"id":"1.232018919","rc":[{"batb":[[0,1.27,10.54]],"ltp":1.26,"tv":1005.28,"id":72857115}]}]}
{"op":"mcm","clk":"11877674028","pt":1724089145570,"mc":[{"id":"1.232018919","rc":[{"batb":[[0,1.25,34.83],[1,1.24,5.99],[2,1.2,250]],"ltp":1.26,"tv":1005.28,"id":72857115}]}]}
{"op":"mcm","clk":"11877674069","pt":1724089145840,"mc":[{"id":"1.232018919","rc":[{"batb":[[0,1.26,4.54],[1,1.25,34.29],[2,1.24,5.99]],"ltp":1.26,"tv":1005.28,"id":72857115}]}]}
{"op":"mcm","clk":"11877674396","pt":1724089148565,"mc":[{"id":"1.232018919","rc":[{"batb":[[0,1.26,10.54]],"ltp":1.26,"tv":1005.28,"id":72857115}]}]}
{"op":"mcm","clk":"11877674834","pt":1724089152242,"mc":[{"id":"1.232018919","rc":[{"batb":[[0,1.26,4.54]],"ltp":1.26,"tv":1005.28,"id":72857115}]}]}
{"op":"mcm","clk":"11877675131","pt":1724089154462,"mc":[{"id":"1.232018919","rc":[{"batb":[[0,1.27,10.54]],"ltp":1.26,"tv":1005.28,"id":72857115}]}]}
{"op":"mcm","clk":"11877675394","pt":1724089156656,"mc":[{"id":"1.232018919","rc":[{"batb":[[0,1.28,4.54],[1,1.27,10],[2,1.25,34.29]],"ltp":1.26,"tv":1005.28,"id":72857115},{"batb":[[0,1.26,14.54],[1,1.25,34.29],[2,1.24,7.15]],"batl":[[0,3.4,35.82]],"ltp":1.5,"tv":1531.51,"id":72857116}]}]}
{"op":"mcm","clk":"11877675575","pt":1724089158175,"mc":[{"id":"1.232018919","rc":[{"batb":[[1,1.25,34.29],[2,1.24,5.99]],"ltp":1.26,"tv":1005.28,"id":72857115}]}]}
{"op":"mcm","clk":"11877675674","pt":1724089158966,"mc":[{"id":"1.232018919","rc":[{"batb":[[0,1.25,34.83],[1,1.24,5.99],[2,1.2,250]],"ltp":1.26,"tv":1005.28,"id":72857115},{"batb":[[0,1.26,10.54]],"ltp":1.5,"tv":1531.51,"id":72857116}]}]}
{"op":"mcm","clk":"11877675889","pt":1724089160665,"mc":[{"id":"1.232018919","rc":[{"batb":[[0,1.26,10.54],[1,1.25,34.29],[2,1.24,5.99]],"ltp":1.26,"tv":1005.28,"id":72857115},{"trd":[[1.5,1053.77]],"batb":[[0,1.25,34.83],[1,1.24,7.15],[2,1.2,250]],"ltp":1.5,"tv":2055.32,"id":72857116}],"tv":3060.6}]}
{"op":"mcm","clk":"11877676170","pt":1724089163168,"mc":[{"id":"1.232018919","rc":[{"batb":[[0,1.27,4.54],[1,1.26,10],[2,1.25,34.29]],"ltp":1.26,"tv":1005.28,"id":72857115},{"batb":[[0,1.26,14.54],[1,1.25,34.29],[2,1.24,7.15]],"ltp":1.5,"tv":2055.32,"id":72857116}]}]}
{"op":"mcm","clk":"11877676283","pt":1724089164065,"mc":[{"id":"1.232018919","rc":[{"batb":[[1,1.25,34.29],[2,1.24,5.99]],"ltp":1.26,"tv":1005.28,"id":72857115}]}]}
{"op":"mcm","clk":"11877676497","pt":1724089165959,"mc":[{"id":"1.232018919","rc":[{"batb":[[0,1.25,34.83],[1,1.24,5.99],[2,1.2,250]],"ltp":1.26,"tv":1005.28,"id":72857115},{"batb":[[0,1.26,10.54]],"ltp":1.5,"tv":2055.32,"id":72857116}]}]}
{"op":"mcm","clk":"11877676670","pt":1724089167158,"mc":[{"id":"1.232018919","rc":[{"batb":[[0,1.26,10.54],[1,1.25,34.29],[2,1.24,5.99]],"ltp":1.26,"tv":1005.28,"id":72857115},{"batb":[[0,1.25,34.83],[1,1.24,7.15],[2,1.2,250]],"ltp":1.5,"tv":2055.32,"id":72857116}]}]}
{"op":"mcm","clk":"11877676858","pt":1724089168684,"mc":[{"id":"1.232018919","rc":[{"batb":[[0,1.27,4.54],[1,1.26,10],[2,1.25,34.29]],"ltp":1.26,"tv":1005.28,"id":72857115},{"batb":[[0,1.26,4.54],[1,1.25,34.29],[2,1.24,7.15]],"ltp":1.5,"tv":2055.32,"id":72857116}]}]}
{"op":"mcm","clk":"11877677107","pt":1724089170792,"mc":[{"id":"1.232018919","rc":[{"batb":[[1,1.25,34.29],[2,1.24,5.99]],"ltp":1.26,"tv":1005.28,"id":72857115},{"batb":[[0,1.27,10.54],[1,1.26,4],[2,1.25,34.29]],"ltp":1.5,"tv":2055.32,"id":72857116}]}]}
{"op":"mcm","clk":"11877677131","pt":1724089170951,"mc":[{"id":"1.232018919","rc":[{"batb":[[0,1.25,34.83],[1,1.24,5.99],[2,1.2,250]],"ltp":1.26,"tv":1005.28,"id":72857115},{"batb":[[1,1.25,34.29],[2,1.24,7.15]],"ltp":1.5,"tv":2055.32,"id":72857116}]}]}
{"op":"mcm","clk":"11877677466","pt":1724089173469,"mc":[{"id":"1.232018919","rc":[{"batb":[[0,1.26,14.54],[1,1.25,34.29],[2,1.24,5.99]],"ltp":1.26,"tv":1005.28,"id":72857115},{"batb":[[0,1.28,4.54],[1,1.27,10],[2,1.25,34.29]],"ltp":1.5,"tv":2055.32,"id":72857116}]}]}
{"op":"mcm","clk":"11877677547","pt":1724089173996,"mc":[{"id":"1.232018919","rc":[{"batb":[[1,1.25,34.29],[2,1.24,7.15]],"ltp":1.5,"tv":2055.32,"id":72857116}]}]}
{"op":"mcm","clk":"11877677768","pt":1724089175788,"mc":[{"id":"1.232018919","rc":[{"batb":[[0,1.26,10.54]],"ltp":1.26,"tv":1005.28,"id":72857115},{"batb":[[0,1.25,34.83],[1,1.24,7.15],[2,1.2,250]],"ltp":1.5,"tv":2055.32,"id":72857116}]}]}
{"op":"mcm","clk":"11877677934","pt":1724089177051,"mc":[{"id":"1.232018919","rc":[{"batb":[[0,1.25,34.83],[1,1.24,5.99],[2,1.2,250]],"ltp":1.26,"tv":1005.28,"id":72857115},{"batb":[[0,1.26,10.54],[1,1.25,34.29],[2,1.24,7.15]],"ltp":1.5,"tv":2055.32,"id":72857116}]}]}
{"op":"mcm","clk":"11877678124","pt":1724089178499,"mc":[{"id":"1.232018919","rc":[{"batb":[[0,1.26,4.54],[1,1.25,34.29],[2,1.24,5.99]],"ltp":1.26,"tv":1005.28,"id":72857115},{"batb":[[0,1.27,4.54],[1,1.26,10],[2,1.25,34.29]],"ltp":1.5,"tv":2055.32,"id":72857116}]}]}
{"op":"mcm","clk":"11877678389","pt":1724089180679,"mc":[{"id":"1.232018919","rc":[{"batb":[[0,1.27,10.54]],"batl":[[0,3,35.82]],"ltp":1.26,"tv":1005.28,"id":72857115},{"batb":[[0,1.25,34.83],[1,1.24,7.15],[2,1.2,250]],"ltp":1.5,"tv":2055.32,"id":72857116}]}]}
{"op":"mcm","clk":"11877678724","pt":1724089183566,"mc":[{"id":"1.232018919","rc":[{"batb":[[0,1.25,34.83],[1,1.24,5.99],[2,1.2,250]],"ltp":1.26,"tv":1005.28,"id":72857115}]}]}
{"op":"mcm","clk":"11877678781","pt":1724089183998,"mc":[{"id":"1.232018919","rc":[{"batb":[[0,1.26,4.54],[1,1.25,34.29],[2,1.24,5.99]],"ltp":1.26,"tv":1005.28,"id":72857115},{"batb":[[0,1.26,14.54],[1,1.25,34.29],[2,1.24,7.15]],"ltp":1.5,"tv":2055.32,"id":72857116}]}]}
{"op":"mcm","clk":"11877679092","pt":1724089186782,"mc":[{"id":"1.232018919","rc":[{"batb":[[0,1.26,10.54]],"ltp":1.26,"tv":1005.28,"id":72857115},{"batb":[[0,1.26,10.54]],"ltp":1.5,"tv":2055.32,"id":72857116}]}]}
{"op":"mcm","clk":"11877679170","pt":1724089187515,"mc":[{"id":"1.232018919","rc":[{"batb":[[0,1.25,34.83],[1,1.24,7.15],[2,1.2,250]],"ltp":1.5,"tv":2055.32,"id":72857116}]}]}
{"op":"mcm","clk":"11877679324","pt":1724089188779,"mc":[{"id":"1.232018919","rc":[{"batb":[[0,1.27,4.54],[1,1.26,10],[2,1.25,34.29]],"ltp":1.26,"tv":1005.28,"id":72857115},{"batb":[[0,1.26,4.54],[1,1.25,34.29],[2,1.24,7.15]],"batl":[[0,3,35.82]],"ltp":1.5,"tv":2055.32,"id":72857116}]}]}
{"op":"mcm","clk":"11877679502","pt":1724089190296,"mc":[{"id":"1.232018919","rc":[{"batb":[[1,1.25,34.29],[2,1.24,5.99]],"ltp":1.26,"tv":1005.28,"id":72857115},{"batb":[[0,1.27,10.54],[1,1.26,4],[2,1.25,34.29]],"ltp":1.5,"tv":2055.32,"id":72857116}]}]}
{"op":"mcm","clk":"11877679635","pt":1724089191313,"mc":[{"id":"1.232018919","rc":[{"batb":[[0,1.25,34.83],[1,1.24,5.99],[2,1.2,250]],"ltp":1.26,"tv":1005.28,"id":72857115},{"batb":[[1,1.25,34.29],[2,1.24,7.15]],"ltp":1.5,"tv":2055.32,"id":72857116}]}]}
{"op":"mcm","clk":"11877679975","pt":1724089193796,"mc":[{"id":"1.232018919","rc":[{"batb":[[0,1.26,10.54],[1,1.25,34.29],[2,1.24,5.99]],"ltp":1.26,"tv":1005.28,"id":72857115},{"batb":[[0,1.25,34.83],[1,1.24,7.15],[2,1.2,250]],"ltp":1.5,"tv":2055.32,"id":72857116}]}]}
{"op":"mcm","clk":"11877680029","pt":1724089194219,"mc":[{"id":"1.232018919","rc":[{"batb":[[0,1.27,4.54],[1,1.26,10],[2,1.25,34.29]],"ltp":1.26,"tv":1005.28,"id":72857115},{"batb":[[0,1.26,4.54],[1,1.25,34.29],[2,1.24,7.15]],"ltp":1.5,"tv":2055.32,"id":72857116}]}]}
{"op":"mcm","clk":"11877680228","pt":1724089195627,"mc":[{"id":"1.232018919","rc":[{"batb":[[0,1.6,1.54],[1,1.26,4.54],[2,1.25,34.29]],"ltp":1.5,"tv":2055.32,"id":72857116}]}]}
{"op":"mcm","clk":"11877680359","pt":1724089196714,"mc":[{"id":"1.232018919","rc":[{"batb":[[0,1.25,34.83],[1,1.24,5.99],[2,1.2,250]],"ltp":1.26,"tv":1005.28,"id":72857115},{"batb":[[1,1.25,34.83],[2,1.24,7.15]],"ltp":1.5,"tv":2055.32,"id":72857116}]}]}
{"op":"mcm","clk":"11877680598","pt":1724089198609,"mc":[{"id":"1.232018919","rc":[{"batb":[[0,1.26,4.54],[1,1.25,34.29],[2,1.24,5.99]],"ltp":1.26,"tv":1005.28,"id":72857115},{"batb":[[0,1.26,10.54],[1,1.25,34.29]],"ltp":1.5,"tv":2055.32,"id":72857116}]}]}
{"op":"mcm","clk":"11877680964","pt":1724089201532,"mc":[{"id":"1.232018919","rc":[{"batb":[[0,1.26,10.54]],"ltp":1.26,"tv":1005.28,"id":72857115},{"batb":[[0,1.27,4.54],[1,1.26,10],[2,1.25,34.29]],"ltp":1.5,"tv":2055.32,"id":72857116}]}]}
{"op":"mcm","clk":"11877681036","pt":1724089202019,"mc":[{"id":"1.232018919","rc":[{"batb":[[1,1.25,34.29],[2,1.24,7.15]],"ltp":1.5,"tv":2055.32,"id":72857116}]}]}
{"op":"mcm","clk":"11877681383","pt":1724089204769,"mc":[{"id":"1.232018919","rc":[{"batb":[[0,1.27,4.54],[1,1.26,10],[2,1.25,34.29]],"ltp":1.26,"tv":1005.28,"id":72857115},{"batb":[[0,1.26,10.54]],"batl":[[0,1.6,1.54],[1,3,35.82]],"ltp":1.5,"tv":2055.32,"id":72857116}]}]}
{"op":"mcm","clk":"11877681409","pt":1724089204982,"mc":[{"id":"1.232018919","rc":[{"batb":[[1,1.25,34.29],[2,1.24,5.99]],"ltp":1.26,"tv":1005.28,"id":72857115}]}]}
{"op":"mcm","clk":"11877681609","pt":1724089206562,"mc":[{"id":"1.232018919","rc":[{"batb":[[0,1.25,34.83],[1,1.24,5.99],[2,1.2,250]],"ltp":1.26,"tv":1005.28,"id":72857115}]}]}
{"op":"mcm","clk":"11877681733","pt":1724089207564,"mc":[{"id":"1.232018919","rc":[{"batb":[[0,1.26,10.54],[1,1.25,34.29],[2,1.24,5.99]],"ltp":1.26,"tv":1005.28,"id":72857115},{"batb":[[0,1.27,4.54]],"batl":[[0,3,35.82],[1,3,0]],"ltp":1.5,"tv":2055.32,"id":72857116}]}]}
{"op":"mcm","clk":"11877681959","pt":1724089209455,"mc":[{"id":"1.232018919","rc":[{"batb":[[0,1.27,4.54],[1,1.26,10],[2,1.25,34.29]],"ltp":1.26,"tv":1005.28,"id":72857115},{"batb":[[0,1.25,34.83],[1,1.24,7.15],[2,1.2,250]],"ltp":1.5,"tv":2055.32,"id":72857116}]}]}
{"op":"mcm","clk":"11877682147","pt":1724089210762,"mc":[{"id":"1.232018919","rc":[{"batb":[[1,1.25,34.29],[2,1.24,5.99]],"ltp":1.26,"tv":1005.28,"id":72857115},{"batb":[[0,1.26,10.54],[1,1.25,34.29],[2,1.24,7.15]],"ltp":1.5,"tv":2055.32,"id":72857116}]}]}
{"op":"mcm","clk":"11877682343","pt":1724089212291,"mc":[{"id":"1.232018919","rc":[{"batb":[[0,1.25,34.83],[1,1.24,5.99],[2,1.2,250]],"ltp":1.26,"tv":1005.28,"id":72857115},{"batb":[[0,1.27,4.54],[1,1.26,10],[2,1.25,34.29]],"ltp":1.5,"tv":2055.32,"id":72857116}]}]}
{"op":"mcm","clk":"11877682632","pt":1724089214558,"mc":[{"id":"1.232018919","rc":[{"batb":[[0,1.26,14.54],[1,1.25,34.29],[2,1.24,5.99]],"ltp":1.26,"tv":1005.28,"id":72857115},{"batb":[[0,1.25,34.83],[1,1.24,7.15],[2,1.2,250]],"ltp":1.5,"tv":2055.32,"id":72857116}]}]}
{"op":"mcm","clk":"11877682993","pt":1724089217292,"mc":[{"id":"1.232018919","rc":[{"batb":[[0,1.26,10.54]],"ltp":1.26,"tv":1005.28,"id":72857115},{"batb":[[0,1.26,14.54],[1,1.25,34.29],[2,1.24,7.15]],"ltp":1.5,"tv":2055.32,"id":72857116}]}]}
{"op":"mcm","clk":"11877683084","pt":1724089217978,"mc":[{"id":"1.232018919","rc":[{"batb":[[0,1.25,34.83],[1,1.24,5.99],[2,1.2,250]],"ltp":1.26,"tv":1005.28,"id":72857115}]}]}
{"op":"mcm","clk":"11877683285","pt":1724089219555,"mc":[{"id":"1.232018919","rc":[{"batb":[[0,1.26,4.54],[1,1.25,34.29],[2,1.24,5.99]],"batl":[[0,2.74,180.32],[1,3,35.82]],"ltp":1.26,"tv":1005.28,"id":72857115},{"batb":[[0,1.26,10.54]],"ltp":1.5,"tv":2055.32,"id":72857116}]}]}
{"op":"mcm","clk":"11877683440","pt":1724089220768,"mc":[{"id":"1.232018919","rc":[{"batb":[[0,1.27,10.54],[1,1.26,4],[2,1.25,34.29]],"ltp":1.26,"tv":1005.28,"id":72857115},{"batb":[[0,1.25,34.83],[1,1.24,7.15],[2,1.2,250]],"ltp":1.5,"tv":2055.32,"id":72857116}]}]}
{"op":"mcm","clk":"11877683616","pt":1724089222075,"mc":[{"id":"1.232018919","rc":[{"batb":[[1,1.25,34.29],[2,1.24,5.99]],"ltp":1.26,"tv":1005.28,"id":72857115},{"batb":[[0,1.26,4.54],[1,1.25,34.29],[2,1.24,7.15]],"ltp":1.5,"tv":2055.32,"id":72857116}]}]}
{"op":"mcm","clk":"11877683798","pt":1724089223371,"mc":[{"id":"1.232018919","rc":[{"batb":[[0,1.27,10.54],[1,1.26,4],[2,1.25,34.29]],"ltp":1.5,"tv":2055.32,"id":72857116}]}]}
{"op":"mcm","clk":"11877683933","pt":1724089224367,"mc":[{"id":"1.232018919","rc":[{"batb":[[0,1.26,4.54]],"ltp":1.26,"tv":1005.28,"id":72857115},{"batb":[[1,1.25,34.29],[2,1.24,7.15]],"ltp":1.5,"tv":2055.32,"id":72857116}]}]}
{"op":"mcm","clk":"11877684203","pt":1724089226675,"mc":[{"id":"1.232018919","rc":[{"batb":[[0,1.27,10.54]],"ltp":1.26,"tv":1005.28,"id":72857115},{"batb":[[0,1.28,4.54],[1,1.27,10],[2,1.25,34.29]],"ltp":1.5,"tv":2055.32,"id":72857116}]}]}
{"op":"mcm","clk":"11877684252","pt":1724089227088,"mc":[{"id":"1.232018919","rc":[{"batb":[[1,1.25,34.29],[2,1.24,7.15]],"ltp":1.5,"tv":2055.32,"id":72857116}]}]}
{"op":"mcm","clk":"11877684581","pt":1724089229393,"mc":[{"id":"1.232018919","rc":[{"batb":[[0,1.28,4.54],[1,1.27,10],[2,1.25,34.29]],"ltp":1.26,"tv":1005.28,"id":72857115},{"batb":[[0,1.26,10.54]],"ltp":1.5,"tv":2055.32,"id":72857116}]}]}
{"op":"mcm","clk":"11877684642","pt":1724089229906,"mc":[{"id":"1.232018919","rc":[{"batb":[[1,1.25,34.29],[2,1.24,5.99]],"ltp":1.26,"tv":1005.28,"id":72857115},{"batl":[[0,2.72,180.32],[1,3,35.82]],"ltp":1.5,"tv":2055.32,"id":72857116}]}]}
{"op":"mcm","clk":"11877684856","pt":1724089231485,"mc":[{"id":"1.232018919","rc":[{"batb":[[0,1.25,34.83],[1,1.24,5.99],[2,1.2,250]],"ltp":1.26,"tv":1005.28,"id":72857115},{"batb":[[0,1.27,4.54],[1,1.26,10],[2,1.25,34.29]],"ltp":1.5,"tv":2055.32,"id":72857116}]}]}
{"op":"mcm","clk":"11877685006","pt":1724089232791,"mc":[{"id":"1.232018919","rc":[{"batb":[[0,1.26,10.54],[1,1.25,34.29],[2,1.24,5.99]],"ltp":1.26,"tv":1005.28,"id":72857115},{"batb":[[1,1.25,34.29],[2,1.24,7.15]],"ltp":1.5,"tv":2055.32,"id":72857116}]}]}
{"op":"mcm","clk":"11877685148","pt":1724089233792,"mc":[{"id":"1.232018919","rc":[{"batb":[[0,1.27,4.54],[1,1.26,10],[2,1.25,34.29]],"ltp":1.26,"tv":1005.28,"id":72857115},{"batb":[[0,1.25,34.83],[1,1.24,7.15],[2,1.2,250]],"ltp":1.5,"tv":2055.32,"id":72857116}]}]}
{"op":"mcm","clk":"11877685520","pt":1724089236484,"mc":[{"id":"1.232018919","rc":[{"batb":[[0,1.25,34.83],[1,1.24,5.99],[2,1.2,250]],"ltp":1.26,"tv":1005.28,"id":72857115},{"batb":[[0,1.26,14.54],[1,1.25,34.29],[2,1.24,7.15]],"ltp":1.5,"tv":2055.32,"id":72857116}]}]}
{"op":"mcm","clk":"11877685731","pt":1724089238379,"mc":[{"id":"1.232018919","rc":[{"batb":[[0,1.26,4.54],[1,1.25,34.29],[2,1.24,5.99]],"ltp":1.26,"tv":1005.28,"id":72857115},{"batb":[[0,1.26,10.54]],"ltp":1.5,"tv":2055.32,"id":72857116}]}]}
{"op":"mcm","clk":"11877685863","pt":1724089239468,"mc":[{"id":"1.232018919","rc":[{"batb":[[0,1.27,10.54],[1,1.26,4],[2,1.25,34.29]],"ltp":1.26,"tv":1005.28,"id":72857115},{"batb":[[0,1.25,34.83],[1,1.24,7.15],[2,1.2,250]],"ltp":1.5,"tv":2055.32,"id":72857116}]}]}
{"op":"mcm","clk":"11877686025","pt":1724089240680,"mc":[{"id":"1.232018919","rc":[{"batb":[[1,1.25,34.29],[2,1.24,5.99]],"ltp":1.26,"tv":1005.28,"id":72857115}]}]}
{"op":"mcm","clk":"11877686049","pt":1724089240886,"mc":[{"id":"1.232018919","rc":[{"batb":[[0,1.26,4.54],[1,1.25,34.29],[2,1.24,7.15]],"ltp":1.5,"tv":2055.32,"id":72857116}]}]}
{"op":"mcm","clk":"11877686342","pt":1724089243310,"mc":[{"id":"1.232018919","rc":[{"batb":[[0,1.26,4.54]],"ltp":1.26,"tv":1005.28,"id":72857115},{"batb":[[0,1.27,10.54]],"ltp":1.5,"tv":2055.32,"id":72857116}]}]}
{"op":"mcm","clk":"11877686684","pt":1724089245607,"mc":[{"id":"1.232018919","rc":[{"batb":[[0,1.26,10.54]],"ltp":1.26,"tv":1005.28,"id":72857115},{"batb":[[0,1.28,4.54],[1,1.27,10],[2,1.25,34.29]],"ltp":1.5,"tv":2055.32,"id":72857116}]}]}
{"op":"mcm","clk":"11877686798","pt":1724089246630,"mc":[{"id":"1.232018919","rc":[{"batb":[[1,1.25,34.29],[2,1.24,7.15]],"ltp":1.5,"tv":2055.32,"id":72857116}]}]}
{"op":"mcm","clk":"11877686963","pt":1724089247822,"mc":[{"id":"1.232018919","rc":[{"batb":[[0,1.25,34.83],[1,1.24,7.15],[2,1.2,250]],"ltp":1.5,"tv":2055.32,"id":72857116}]}]}
{"op":"mcm","clk":"11877687086","pt":1724089248812,"mc":[{"id":"1.232018919","rc":[{"batb":[[0,1.27,4.54]],"ltp":1.26,"tv":1005.28,"id":72857115}]}]}
{"op":"mcm","clk":"11877687109","pt":1724089249022,"mc":[{"id":"1.232018919","rc":[{"batb":[[0,1.26,10.54],[1,1.25,34.29],[2,1.24,7.15]],"ltp":1.5,"tv":2055.32,"id":72857116}]}]}
{"op":"mcm","clk":"11877687309","pt":1724089250496,"mc":[{"id":"1.232018919","rc":[{"batb":[[0,1.25,34.83],[1,1.24,5.99],[2,1.2,250]],"ltp":1.26,"tv":1005.28,"id":72857115},{"batb":[[0,1.27,4.54],[1,1.26,10],[2,1.25,34.29]],"ltp":1.5,"tv":2055.32,"id":72857116}]}]}
{"op":"mcm","clk":"11877687452","pt":1724089251698,"mc":[{"id":"1.232018919","rc":[{"batb":[[0,1.26,10.54],[1,1.25,34.29],[2,1.24,5.99]],"ltp":1.26,"tv":1005.28,"id":72857115}]}]}
{"op":"mcm","clk":"11877687609","pt":1724089252800,"mc":[{"id":"1.232018919","rc":[{"batb":[[0,1.27,4.54],[1,1.26,10],[2,1.25,34.29]],"ltp":1.26,"tv":1005.28,"id":72857115},{"batb":[[0,1.25,34.83],[1,1.24,7.15],[2,1.2,250]],"ltp":1.5,"tv":2055.32,"id":72857116}]}]}
{"op":"mcm","clk":"11877687934","pt":1724089255531,"mc":[{"id":"1.232018919","rc":[{"batb":[[0,1.25,34.83],[1,1.24,5.99],[2,1.2,250]],"ltp":1.26,"tv":1005.28,"id":72857115},{"batb":[[0,1.26,14.54],[1,1.25,34.29],[2,1.24,7.15]],"ltp":1.5,"tv":2055.32,"id":72857116}]}]}
{"op":"mcm","clk":"11877688313","pt":1724089258403,"mc":[{"id":"1.232018919","rc":[{"batb":[[0,1.26,14.54],[1,1.25,34.29],[2,1.24,5.99]],"ltp":1.26,"tv":1005.28,"id":72857115},{"batb":[[0,1.26,10.54]],"ltp":1.5,"tv":2055.32,"id":72857116}]}]}
{"op":"mcm","clk":"11877688448","pt":1724089259501,"mc":[{"id":"1.232018919","rc":[{"batb":[[0,1.25,34.83],[1,1.24,7.15],[2,1.2,250]],"ltp":1.5,"tv":2055.32,"id":72857116}]}]}
{"op":"mcm","clk":"11877688613","pt":1724089260810,"mc":[{"id":"1.232018919","rc":[{"batb":[[0,1.26,10.54]],"ltp":1.26,"tv":1005.28,"id":72857115}]}]}
{"op":"mcm","clk":"11877688743","pt":1724089261810,"mc":[{"id":"1.232018919","rc":[{"batb":[[0,1.25,34.83],[1,1.24,5.99],[2,1.2,250]],"ltp":1.26,"tv":1005.28,"id":72857115},{"batb":[[0,1.27,10.54],[1,1.26,4],[2,1.25,34.29]],"ltp":1.5,"tv":2055.32,"id":72857116}]}]}
{"op":"mcm","clk":"11877688893","pt":1724089263122,"mc":[{"id":"1.232018919","rc":[{"batb":[[0,1.26,4.54],[1,1.25,34.29],[2,1.24,5.99]],"ltp":1.26,"tv":1005.28,"id":72857115},{"batb":[[1,1.25,34.29],[2,1.24,7.15]],"ltp":1.5,"tv":2055.32,"id":72857116}]}]}
{"op":"mcm","clk":"11877689199","pt":1724089265524,"mc":[{"id":"1.232018919","rc":[{"batb":[[0,1.27,10.54]],"ltp":1.26,"tv":1005.28,"id":72857115},{"batb":[[0,1.26,4.54]],"ltp":1.5,"tv":2055.32,"id":72857116}]}]}
{"op":"mcm","clk":"11877689500","pt":1724089268203,"mc":[{"id":"1.232018919","rc":[{"batb":[[0,1.28,4.54],[1,1.27,10],[2,1.25,34.29]],"ltp":1.26,"tv":1005.28,"id":72857115},{"batb":[[0,1.26,10.54]],"ltp":1.5,"tv":2055.32,"id":72857116}]}]}
{"op":"mcm","clk":"11877689582","pt":1724089268927,"mc":[{"id":"1.232018919","rc":[{"batb":[[1,1.25,34.29],[2,1.24,5.99]],"ltp":1.26,"tv":1005.28,"id":72857115}]}]}
{"op":"mcm","clk":"11877689770","pt":1724089270609,"mc":[{"id":"1.232018919","rc":[{"batb":[[0,1.25,34.83],[1,1.24,5.99],[2,1.2,250]],"ltp":1.26,"tv":1005.28,"id":72857115},{"batb":[[0,1.27,4.54],[1,1.26,10],[2,1.25,34.29]],"ltp":1.5,"tv":2055.32,"id":72857116}]}]}
{"op":"mcm","clk":"11877689932","pt":1724089271816,"mc":[{"id":"1.232018919","rc":[{"batb":[[0,1.26,10.54],[1,1.25,34.29],[2,1.24,5.99]],"ltp":1.26,"tv":1005.28,"id":72857115},{"batb":[[1,1.25,34.29],[2,1.24,7.15]],"ltp":1.5,"tv":2055.32,"id":72857116}]}]}
{"op":"mcm","clk":"11877690049","pt":1724089272814,"mc":[{"id":"1.232018919","rc":[{"batb":[[0,1.25,34.83],[1,1.24,7.15],[2,1.2,250]],"ltp":1.5,"tv":2055.32,"id":72857116}]}]}
{"op":"mcm","clk":"11877690060","pt":1724089272919,"mc":[{"id":"1.232018919","rc":[{"batb":[[0,1.27,4.54],[1,1.26,10],[2,1.25,34.29]],"ltp":1.26,"tv":1005.28,"id":72857115}]}]}
{"op":"mcm","clk":"11877690437","pt":1724089275410,"mc":[{"id":"1.232018919","rc":[{"batb":[[0,1.25,34.83],[1,1.24,5.99],[2,1.2,250]],"ltp":1.26,"tv":1005.28,"id":72857115},{"batb":[[0,1.26,14.54],[1,1.25,34.29],[2,1.24,7.15]],"ltp":1.5,"tv":2055.32,"id":72857116}]}]}
{"op":"mcm","clk":"11877690770","pt":1724089278123,"mc":[{"id":"1.232018919","rc":[{"batb":[[0,1.26,14.54],[1,1.25,34.29],[2,1.24,5.99]],"ltp":1.26,"tv":1005.28,"id":72857115},{"batb":[[0,1.26,10.54]],"ltp":1.5,"tv":2055.32,"id":72857116}]}]}
{"op":"mcm","clk":"11877690863","pt":1724089278967,"mc":[{"id":"1.232018919","rc":[{"batb":[[0,1.25,34.83],[1,1.24,7.15],[2,1.2,250]],"ltp":1.5,"tv":2055.32,"id":72857116}]}]}
{"op":"mcm","clk":"11877691063","pt":1724089280549,"mc":[{"id":"1.232018919","rc":[{"batb":[[0,1.26,10.54]],"ltp":1.26,"tv":1005.28,"id":72857115},{"batb":[[0,1.26,4.54],[1,1.25,34.29],[2,1.24,7.15]],"ltp":1.5,"tv":2055.32,"id":72857116}]}]}
{"op":"mcm","clk":"11877691199","pt":1724089281652,"mc":[{"id":"1.232018919","rc":[{"batb":[[0,1.25,34.83],[1,1.24,5.99],[2,1.2,250]],"ltp":1.26,"tv":1005.28,"id":72857115},{"batb":[[0,1.27,10.54],[1,1.26,4],[2,1.25,34.29]],"ltp":1.5,"tv":2055.32,"id":72857116}]}]}
{"op":"mcm","clk":"11877691336","pt":1724089282977,"mc":[{"id":"1.232018919","rc":[{"batb":[[0,1.26,4.54],[1,1.25,34.29],[2,1.24,5.99]],"ltp":1.26,"tv":1005.28,"id":72857115},{"batb":[[1,1.25,34.29],[2,1.24,7.15]],"ltp":1.5,"tv":2055.32,"id":72857116}]}]}
{"op":"mcm","clk":"11877691631","pt":1724089285465,"mc":[{"id":"1.232018919","rc":[{"batb":[[0,1.26,10.54]],"ltp":1.26,"tv":1005.28,"id":72857115},{"batb":[[0,1.26,4.54]],"ltp":1.5,"tv":2055.32,"id":72857116}]}]}
{"op":"mcm","clk":"11877692053","pt":1724089288818,"mc":[{"id":"1.232018919","rc":[{"batb":[[0,1.27,4.54]],"ltp":1.26,"tv":1005.28,"id":72857115},{"batb":[[0,1.26,10.54]],"ltp":1.5,"tv":2055.32,"id":72857116}]}]}
{"op":"mcm","clk":"11877692243","pt":1724089290355,"mc":[{"id":"1.232018919","rc":[{"batb":[[0,1.25,34.83],[1,1.24,5.99],[2,1.2,250]],"ltp":1.26,"tv":1005.28,"id":72857115},{"batb":[[0,1.27,4.54],[1,1.26,10],[2,1.25,34.29]],"ltp":1.5,"tv":2055.32,"id":72857116}]}]}
{"op":"mcm","clk":"11877692416","pt":1724089291731,"mc":[{"id":"1.232018919","rc":[{"batb":[[0,1.26,10.54],[1,1.25,34.29],[2,1.24,5.99]],"ltp":1.26,"tv":1005.28,"id":72857115},{"batb":[[1,1.25,34.29],[2,1.24,7.15]],"ltp":1.5,"tv":2055.32,"id":72857116}]}]}
{"op":"mcm","clk":"11877692511","pt":1724089292536,"mc":[{"id":"1.232018919","rc":[{"batb":[[0,1.25,34.83],[1,1.24,7.15],[2,1.2,250]],"ltp":1.5,"tv":2055.32,"id":72857116}]}]}
{"op":"mcm","clk":"11877692817","pt":1724089295270,"mc":[{"id":"1.232018919","rc":[{"batb":[[0,1.26,4.54]],"ltp":1.26,"tv":1005.28,"id":72857115},{"batb":[[0,1.26,14.54],[1,1.25,34.29],[2,1.24,7.15]],"ltp":1.5,"tv":2055.32,"id":72857116}]}]}
{"op":"mcm","clk":"11877693102","pt":1724089297733,"mc":[{"id":"1.232018919","rc":[{"batb":[[0,1.26,10.54]],"ltp":1.26,"tv":1005.28,"id":72857115},{"batb":[[0,1.26,10.54]],"ltp":1.5,"tv":2055.32,"id":72857116}]}]}
{"op":"mcm","clk":"11877693218","pt":1724089298681,"mc":[{"id":"1.232018919","rc":[{"batb":[[0,1.25,34.83],[1,1.24,7.15],[2,1.2,250]],"ltp":1.5,"tv":2055.32,"id":72857116}]}]}
{"op":"mcm","clk":"11877693509","pt":1724089301256,"mc":[{"id":"1.232018919","rc":[{"batb":[[0,1.26,4.54]],"ltp":1.26,"tv":1005.28,"id":72857115},{"batb":[[0,1.26,14.54],[1,1.25,34.29],[2,1.24,7.15]],"ltp":1.5,"tv":2055.32,"id":72857116}]}]}
{"op":"mcm","clk":"11877693794","pt":1724089303669,"mc":[{"id":"1.232018919","rc":[{"batb":[[0,1.26,10.54]],"ltp":1.26,"tv":1005.28,"id":72857115},{"batb":[[0,1.26,10.54]],"ltp":1.5,"tv":2055.32,"id":72857116}]}]}
{"op":"mcm","clk":"11877693896","pt":1724089304559,"mc":[{"id":"1.232018919","rc":[{"batb":[[0,1.25,34.83],[1,1.24,7.15],[2,1.2,250]],"ltp":1.5,"tv":2055.32,"id":72857116}]}]}
{"op":"mcm","clk":"11877694267","pt":1724089307307,"mc":[{"id":"1.232018919","rc":[{"batb":[[0,1.26,4.54]],"ltp":1.26,"tv":1005.28,"id":72857115},{"batb":[[0,1.26,14.54],[1,1.25,34.29],[2,1.24,7.15]],"ltp":1.5,"tv":2055.32,"id":72857116}]}]}
{"op":"mcm","clk":"11877694593","pt":1724089309667,"mc":[{"id":"1.232018919","rc":[{"batb":[[0,1.25,34.83],[1,1.24,5.99],[2,1.2,250]],"ltp":1.26,"tv":1005.28,"id":72857115},{"batb":[[0,1.26,10.54]],"ltp":1.5,"tv":2055.32,"id":72857116}]}]}
{"op":"mcm","clk":"11877694702","pt":1724089310560,"mc":[{"id":"1.232018919","rc":[{"batb":[[0,1.26,10.54],[1,1.25,34.29],[2,1.24,5.99]],"ltp":1.26,"tv":1005.28,"id":72857115},{"batb":[[0,1.25,34.83],[1,1.24,7.15],[2,1.2,250]],"ltp":1.5,"tv":2055.32,"id":72857116}]}]}
{"op":"mcm","clk":"11877695071","pt":1724089313189,"mc":[{"id":"1.232018919","rc":[{"batb":[[0,1.27,4.54]],"ltp":1.26,"tv":1005.28,"id":72857115},{"batb":[[0,1.26,14.54],[1,1.25,34.29],[2,1.24,7.15]],"ltp":1.5,"tv":2055.32,"id":72857116}]}]}
{"op":"mcm","clk":"11877695417","pt":1724089315776,"mc":[{"id":"1.232018919","rc":[{"batb":[[0,1.26,10.54]],"ltp":1.26,"tv":1005.28,"id":72857115},{"batb":[[0,1.26,10.54]],"ltp":1.5,"tv":2055.32,"id":72857116}]}]}
{"op":"mcm","clk":"11877695462","pt":1724089316186,"mc":[{"id":"1.232018919","rc":[{"batb":[[0,1.25,34.83],[1,1.24,7.15],[2,1.2,250]],"ltp":1.5,"tv":2055.32,"id":72857116}]}]}
{"op":"mcm","clk":"11877695873","pt":1724089319480,"mc":[{"id":"1.232018919","rc":[{"batb":[[0,1.26,4.54]],"ltp":1.26,"tv":1005.28,"id":72857115},{"batb":[[0,1.26,14.54],[1,1.25,34.29],[2,1.24,7.15]],"ltp":1.5,"tv":2055.32,"id":72857116}]}]}
{"op":"mcm","clk":"11877696170","pt":1724089321796,"mc":[{"id":"1.232018919","rc":[{"batb":[[0,1.25,34.83],[1,1.24,5.99],[2,1.2,250]],"ltp":1.26,"tv":1005.28,"id":72857115},{"batb":[[0,1.26,10.54]],"ltp":1.5,"tv":2055.32,"id":72857116}]}]}
{"op":"mcm","clk":"11877696288","pt":1724089322706,"mc":[{"id":"1.232018919","rc":[{"batb":[[0,1.27,10.54],[1,1.25,34.29],[2,1.24,5.99]],"ltp":1.26,"tv":1005.28,"id":72857115},{"batb":[[0,1.25,34.83],[1,1.24,7.15],[2,1.2,250]],"ltp":1.5,"tv":2055.32,"id":72857116}]}]}
{"op":"mcm","clk":"11877696686","pt":1724089325816,"mc":[{"id":"1.232018919","rc":[{"batb":[[0,1.26,4.54]],"ltp":1.26,"tv":1005.28,"id":72857115},{"batb":[[0,1.26,14.54],[1,1.25,34.29],[2,1.24,7.15]],"ltp":1.5,"tv":2055.32,"id":72857116}]}]}
{"op":"mcm","clk":"11877697009","pt":1724089328313,"mc":[{"id":"1.232018919","rc":[{"batb":[[0,1.26,10.54]],"ltp":1.26,"tv":1005.28,"id":72857115},{"batb":[[0,1.26,10.54]],"ltp":1.5,"tv":2055.32,"id":72857116}]}]}
{"op":"mcm","clk":"11877697113","pt":1724089329107,"mc":[{"id":"1.232018919","rc":[{"batb":[[0,1.25,34.83],[1,1.24,7.15],[2,1.2,250]],"ltp":1.5,"tv":2055.32,"id":72857116}]}]}
{"op":"mcm","clk":"11877697463","pt":1724089331726,"mc":[{"id":"1.232018919","rc":[{"batb":[[0,1.26,4.54]],"ltp":1.26,"tv":1005.28,"id":72857115},{"batb":[[0,1.26,14.54],[1,1.25,34.29],[2,1.24,7.15]],"ltp":1.5,"tv":2055.32,"id":72857116}]}]}
{"op":"mcm","clk":"11877697750","pt":1724089334200,"mc":[{"id":"1.232018919","rc":[{"batb":[[0,1.26,10.54]],"ltp":1.26,"tv":1005.28,"id":72857115},{"batb":[[0,1.26,10.54]],"ltp":1.5,"tv":2055.32,"id":72857116}]}]}
{"op":"mcm","clk":"11877697872","pt":1724089335215,"mc":[{"id":"1.232018919","rc":[{"batb":[[0,1.25,34.83],[1,1.24,7.15],[2,1.2,250]],"ltp":1.5,"tv":2055.32,"id":72857116}]}]}
{"op":"mcm","clk":"11877698089","pt":1724089336691,"mc":[{"id":"1.232018919","rc":[{"batb":[[0,1.27,4.54],[1,1.26,10],[2,1.25,34.29]],"ltp":1.26,"tv":1005.28,"id":72857115},{"batb":[[0,1.26,4.54],[1,1.25,34.29],[2,1.24,7.15]],"ltp":1.5,"tv":2055.32,"id":72857116}]}]}
{"op":"mcm","clk":"11877698209","pt":1724089337630,"mc":[{"id":"1.232018919","rc":[{"batb":[[1,1.25,34.29],[2,1.24,5.99]],"ltp":1.26,"tv":1005.28,"id":72857115}]}]}
{"op":"mcm","clk":"11877698237","pt":1724089337839,"mc":[{"id":"1.232018919","rc":[{"batb":[[0,1.27,10.54],[1,1.26,4],[2,1.25,34.29]],"ltp":1.5,"tv":2055.32,"id":72857116}]}]}
{"op":"mcm","clk":"11877698447","pt":1724089339401,"mc":[{"id":"1.232018919","rc":[{"batb":[[0,1.25,34.83],[1,1.24,5.99],[2,1.2,250]],"ltp":1.26,"tv":1005.28,"id":72857115},{"batb":[[1,1.25,34.29],[2,1.24,7.15]],"ltp":1.5,"tv":2055.32,"id":72857116}]}]}
{"op":"mcm","clk":"11877698761","pt":1724089341633,"mc":[{"id":"1.232018919","rc":[{"batb":[[0,1.27,4.54],[1,1.26,10],[2,1.25,34.29]],"ltp":1.26,"tv":1005.28,"id":72857115},{"batb":[[0,1.26,4.54]],"ltp":1.5,"tv":2055.32,"id":72857116}]}]}
{"op":"mcm","clk":"11877699085","pt":1724089344101,"mc":[{"id":"1.232018919","rc":[{"batb":[[0,1.26,10.54],[1,1.25,34.29],[2,1.24,5.99]],"ltp":1.26,"tv":1005.28,"id":72857115},{"batb":[[0,1.26,10.54]],"ltp":1.5,"tv":2055.32,"id":72857116}]}]}
{"op":"mcm","clk":"11877699173","pt":1724089344833,"mc":[{"id":"1.232018919","rc":[{"batb":[[0,1.25,34.83],[1,1.24,5.99],[2,1.2,250]],"ltp":1.26,"tv":1005.28,"id":72857115}]}]}
{"op":"mcm","clk":"11877699563","pt":1724089347439,"mc":[{"id":"1.232018919","rc":[{"batb":[[0,1.26,14.54],[1,1.25,34.29],[2,1.24,5.99]],"ltp":1.26,"tv":1005.28,"id":72857115},{"batb":[[0,1.26,4.54]],"ltp":1.5,"tv":2055.32,"id":72857116}]}]}
{"op":"mcm","clk":"11877700018","pt":1724089350807,"mc":[{"id":"1.232018919","rc":[{"batb":[[0,1.25,34.83],[1,1.24,5.99],[2,1.2,250]],"ltp":1.26,"tv":1005.28,"id":72857115},{"batb":[[0,1.27,10.54]],"ltp":1.5,"tv":2055.32,"id":72857116}]}]}
{"op":"mcm","clk":"11877700402","pt":1724089353648,"mc":[{"id":"1.232018919","rc":[{"batb":[[0,1.26,14.54],[1,1.25,34.29],[2,1.24,5.99]],"ltp":1.26,"tv":1005.28,"id":72857115},{"batb":[[0,1.26,4.54]],"ltp":1.5,"tv":2055.32,"id":72857116}]}]}
{"op":"mcm","clk":"11877700697","pt":1724089356127,"mc":[{"id":"1.232018919","rc":[{"batb":[[0,1.26,10.54]],"ltp":1.26,"tv":1005.28,"id":72857115},{"batb":[[0,1.26,10.54]],"ltp":1.5,"tv":2055.32,"id":72857116}]}]}
{"op":"mcm","clk":"11877700816","pt":1724089357125,"mc":[{"id":"1.232018919","rc":[{"batb":[[0,1.25,34.83],[1,1.24,5.99],[2,1.2,250]],"ltp":1.26,"tv":1005.28,"id":72857115}]}]}
{"op":"mcm","clk":"11877701126","pt":1724089359632,"mc":[{"id":"1.232018919","rc":[{"batb":[[0,1.26,14.54],[1,1.25,34.29],[2,1.24,5.99]],"ltp":1.26,"tv":1005.28,"id":72857115},{"batb":[[0,1.27,4.54]],"ltp":1.5,"tv":2055.32,"id":72857116}]}]}
{"op":"mcm","clk":"11877701520","pt":1724089362325,"mc":[{"id":"1.232018919","rc":[{"batb":[[0,1.26,10.54]],"ltp":1.26,"tv":1005.28,"id":72857115},{"batb":[[0,1.26,10.54]],"ltp":1.5,"tv":2055.32,"id":72857116}]}]}
{"op":"mcm","clk":"11877701606","pt":1724089363051,"mc":[{"id":"1.232018919","rc":[{"batb":[[0,1.25,34.83],[1,1.24,5.99],[2,1.2,250]],"ltp":1.26,"tv":1005.28,"id":72857115}]}]}
{"op":"mcm","clk":"11877701955","pt":1724089365631,"mc":[{"id":"1.232018919","rc":[{"batb":[[0,1.26,14.54],[1,1.25,34.29],[2,1.24,5.99]],"ltp":1.26,"tv":1005.28,"id":72857115},{"batb":[[0,1.27,4.54]],"ltp":1.5,"tv":2055.32,"id":72857116}]}]}
{"op":"mcm","clk":"11877702280","pt":1724089368253,"mc":[{"id":"1.232018919","rc":[{"batb":[[0,1.26,10.54]],"ltp":1.26,"tv":1005.28,"id":72857115},{"batb":[[0,1.26,10.54]],"ltp":1.5,"tv":2055.32,"id":72857116}]}]}
{"op":"mcm","clk":"11877702415","pt":1724089369256,"mc":[{"id":"1.232018919","rc":[{"batb":[[0,1.25,34.83],[1,1.24,5.99],[2,1.2,250]],"ltp":1.26,"tv":1005.28,"id":72857115}]}]}
{"op":"mcm","clk":"11877702731","pt":1724089371649,"mc":[{"id":"1.232018919","rc":[{"batb":[[0,1.26,14.54],[1,1.25,34.29],[2,1.24,5.99]],"ltp":1.26,"tv":1005.28,"id":72857115},{"batb":[[0,1.26,4.54]],"ltp":1.5,"tv":2055.32,"id":72857116}]}]}
{"op":"mcm","clk":"11877702982","pt":1724089373965,"mc":[{"id":"1.232018919","rc":[{"batb":[[0,1.26,10.54]],"ltp":1.26,"tv":1005.28,"id":72857115},{"batb":[[0,1.26,10.54]],"ltp":1.5,"tv":2055.32,"id":72857116}]}]}
{"op":"mcm","clk":"11877712924","pt":1724089375081,"mc":[{"id":"1.232018919","rc":[{"batb":[[0,1.25,34.83],[1,1.24,5.99],[2,1.2,250]],"ltp":1.26,"tv":1005.28,"id":72857115}]}]}
{"op":"mcm","clk":"11877713123","pt":1724089376556,"mc":[{"id":"1.232018919","rc":[{"batb":[[0,1.26,4.54]],"ltp":1.26,"tv":1005.28,"id":72857115},{"batb":[[0,1.27,4.54],[1,1.26,10]],"ltp":1.5,"tv":2055.32,"id":72857116}]}]}
{"op":"mcm","clk":"11877713230","pt":1724089377536,"mc":[{"id":"1.232018919","rc":[{"batb":[[0,1.27,10.54],[1,1.26,4],[2,1.24,5.99]],"ltp":1.26,"tv":1005.28,"id":72857115},{"batb":[[1,1.24,7.15],[2,1.2,250]],"ltp":1.5,"tv":2055.32,"id":72857116}]}]}
{"op":"mcm","clk":"11877713368","pt":1724089378942,"mc":[{"id":"1.232018919","rc":[{"batb":[[1,1.24,5.99],[2,1.2,250]],"ltp":1.26,"tv":1005.28,"id":72857115},{"batb":[[0,1.24,7.69],[1,1.2,250],[2,1.11,24.84]],"ltp":1.5,"tv":2055.32,"id":72857116}]}]}
{"op":"mcm","clk":"11877713643","pt":1724089381168,"mc":[{"id":"1.232018919","rc":[{"batb":[[0,1.25,4.54]],"ltp":1.26,"tv":1005.28,"id":72857115},{"batb":[[0,1.25,14.54],[1,1.24,7.15],[2,1.2,250]],"ltp":1.5,"tv":2055.32,"id":72857116}]}]}
{"op":"mcm","clk":"11877713976","pt":1724089383772,"mc":[{"id":"1.232018919","rc":[{"batb":[[0,1.25,10.54]],"ltp":1.26,"tv":1005.28,"id":72857115},{"batb":[[0,1.25,10.54]],"ltp":1.5,"tv":2055.32,"id":72857116}]}]}
{"op":"mcm","clk":"11877714051","pt":1724089384452,"mc":[{"id":"1.232018919","rc":[{"batb":[[0,1.24,7.69],[1,1.2,250],[2,1.11,24.84]],"ltp":1.5,"tv":2055.32,"id":72857116}]}]}
{"op":"mcm","clk":"11877714388","pt":1724089387371,"mc":[{"id":"1.232018919","rc":[{"batb":[[0,1.25,4.54]],"ltp":1.26,"tv":1005.28,"id":72857115},{"batb":[[0,1.25,14.54],[1,1.24,7.15],[2,1.2,250]],"ltp":1.5,"tv":2055.32,"id":72857116}]}]}
{"op":"mcm","clk":"11877714666","pt":1724089389776,"mc":[{"id":"1.232018919","rc":[{"batb":[[0,1.25,10.54]],"ltp":1.26,"tv":1005.28,"id":72857115},{"batb":[[0,1.25,10.54]],"ltp":1.5,"tv":2055.32,"id":72857116}]}]}
{"op":"mcm","clk":"11877714775","pt":1724089390566,"mc":[{"id":"1.232018919","rc":[{"batb":[[0,1.24,7.69],[1,1.2,250],[2,1.11,24.84]],"ltp":1.5,"tv":2055.32,"id":72857116}]}]}
{"op":"mcm","clk":"11877715083","pt":1724089393173,"mc":[{"id":"1.232018919","rc":[{"batb":[[0,1.25,4.54]],"ltp":1.26,"tv":1005.28,"id":72857115},{"batb":[[0,1.25,14.54],[1,1.24,7.15],[2,1.2,250]],"ltp":1.5,"tv":2055.32,"id":72857116}]}]}
{"op":"mcm","clk":"11877715397","pt":1724089395745,"mc":[{"id":"1.232018919","rc":[{"batb":[[0,1.25,10.54]],"ltp":1.26,"tv":1005.28,"id":72857115},{"batb":[[0,1.25,10.54]],"ltp":1.5,"tv":2055.32,"id":72857116}]}]}
{"op":"mcm","clk":"11877715473","pt":1724089396473,"mc":[{"id":"1.232018919","rc":[{"batb":[[0,1.24,7.69],[1,1.2,250],[2,1.11,24.84]],"ltp":1.5,"tv":2055.32,"id":72857116}]}]}
{"op":"mcm","clk":"11877715814","pt":1724089399361,"mc":[{"id":"1.232018919","rc":[{"batb":[[0,1.25,4.54]],"ltp":1.26,"tv":1005.28,"id":72857115},{"batb":[[0,1.25,14.54],[1,1.24,7.15],[2,1.2,250]],"ltp":1.5,"tv":2055.32,"id":72857116}]}]}
{"op":"mcm","clk":"11877716091","pt":1724089401665,"mc":[{"id":"1.232018919","rc":[{"batb":[[0,1.24,6.53],[1,1.2,250],[2,1.11,24.84]],"ltp":1.26,"tv":1005.28,"id":72857115},{"batb":[[0,1.25,10.54]],"ltp":1.5,"tv":2055.32,"id":72857116}]}]}
{"op":"mcm","clk":"11877716196","pt":1724089402658,"mc":[{"id":"1.232018919","rc":[{"batb":[[0,1.25,10.54],[1,1.24,5.99],[2,1.2,250]],"ltp":1.26,"tv":1005.28,"id":72857115},{"batb":[[0,1.24,7.69],[1,1.2,250],[2,1.11,24.84]],"ltp":1.5,"tv":2055.32,"id":72857116}]}]}
{"op":"mcm","clk":"11877716514","pt":1724089405263,"mc":[{"id":"1.232018919","rc":[{"batb":[[0,1.25,4.54]],"ltp":1.26,"tv":1005.28,"id":72857115},{"batb":[[0,1.25,14.54],[1,1.24,7.15],[2,1.2,250]],"ltp":1.5,"tv":2055.32,"id":72857116}]}]}
{"op":"mcm","clk":"11877716775","pt":1724089407570,"mc":[{"id":"1.232018919","rc":[{"batb":[[0,1.25,10.54]],"ltp":1.26,"tv":1005.28,"id":72857115},{"batb":[[0,1.25,10.54]],"ltp":1.5,"tv":2055.32,"id":72857116}]}]}
{"op":"mcm","clk":"11877716893","pt":1724089408555,"mc":[{"id":"1.232018919","rc":[{"batb":[[0,1.24,7.69],[1,1.2,250],[2,1.11,24.84]],"ltp":1.5,"tv":2055.32,"id":72857116}]}]}
{"op":"mcm","clk":"11877717302","pt":1724089411164,"mc":[{"id":"1.232018919","rc":[{"batb":[[0,1.25,4.54]],"ltp":1.26,"tv":1005.28,"id":72857115},{"batb":[[0,1.25,14.54],[1,1.24,7.15],[2,1.2,250]],"ltp":1.5,"tv":2055.32,"id":72857116}]}]}
{"op":"mcm","clk":"11877717645","pt":1724089413786,"mc":[{"id":"1.232018919","rc":[{"batb":[[0,1.25,10.54]],"ltp":1.26,"tv":1005.28,"id":72857115},{"batb":[[0,1.25,10.54]],"ltp":1.5,"tv":2055.32,"id":72857116}]}]}
{"op":"mcm","clk":"11877717718","pt":1724089414469,"mc":[{"id":"1.232018919","rc":[{"batb":[[0,1.24,7.69],[1,1.2,250],[2,1.11,24.84]],"ltp":1.5,"tv":2055.32,"id":72857116}]}]}
{"op":"mcm","clk":"11877718034","pt":1724089417183,"mc":[{"id":"1.232018919","rc":[{"batb":[[0,1.25,4.54]],"ltp":1.26,"tv":1005.28,"id":72857115},{"batb":[[0,1.25,14.54],[1,1.24,7.15],[2,1.2,250]],"ltp":1.5,"tv":2055.32,"id":72857116}]}]}
{"op":"mcm","clk":"11877718317","pt":1724089419585,"mc":[{"id":"1.232018919","rc":[{"batb":[[0,1.25,10.54]],"ltp":1.26,"tv":1005.28,"id":72857115},{"batb":[[0,1.25,10.54]],"ltp":1.5,"tv":2055.32,"id":72857116}]}]}
{"op":"mcm","clk":"11877718452","pt":1724089420580,"mc":[{"id":"1.232018919","rc":[{"batb":[[0,1.24,7.69],[1,1.2,250],[2,1.11,24.84]],"ltp":1.5,"tv":2055.32,"id":72857116}]}]}
{"op":"mcm","clk":"11877718603","pt":1724089421784,"mc":[{"id":"1.232018919","rc":[{"batb":[[0,1.26,4.54],[1,1.25,10],[2,1.24,5.99]],"ltp":1.26,"tv":1005.28,"id":72857115},{"batb":[[0,1.25,4.54],[1,1.24,7.15],[2,1.2,250]],"ltp":1.5,"tv":2055.32,"id":72857116}]}]}
{"op":"mcm","clk":"11877718759","pt":1724089422989,"mc":[{"id":"1.232018919","rc":[{"batb":[[1,1.24,5.99],[2,1.2,250]],"ltp":1.26,"tv":1005.28,"id":72857115},{"batb":[[0,1.26,10.54],[1,1.25,4],[2,1.24,7.15]],"ltp":1.5,"tv":2055.32,"id":72857116}]}]}
{"op":"mcm","clk":"11877718907","pt":1724089424317,"mc":[{"id":"1.232018919","rc":[{"batb":[[0,1.24,6.53],[1,1.2,250],[2,1.11,24.84]],"ltp":1.26,"tv":1005.28,"id":72857115},{"batb":[[1,1.24,7.15],[2,1.2,250]],"ltp":1.5,"tv":2055.32,"id":72857116}]}]}
{"op":"mcm","clk":"11877719175","pt":1724089426620,"mc":[{"id":"1.232018919","rc":[{"batb":[[0,1.26,4.54],[1,1.25,10],[2,1.24,5.99]],"ltp":1.26,"tv":1005.28,"id":72857115},{"batb":[[0,1.25,4.54]],"ltp":1.5,"tv":2055.32,"id":72857116}]}]}
{"op":"mcm","clk":"11877719567","pt":1724089429706,"mc":[{"id":"1.232018919","rc":[{"batb":[[0,1.24,6.53],[1,1.2,250],[2,1.11,24.84]],"ltp":1.26,"tv":1005.28,"id":72857115},{"batb":[[0,1.25,10.54]],"ltp":1.5,"tv":2055.32,"id":72857116}]}]}
{"op":"mcm","clk":"11877719926","pt":1724089432408,"mc":[{"id":"1.232018919","rc":[{"batb":[[0,1.25,14.54],[1,1.24,5.99],[2,1.2,250]],"ltp":1.26,"tv":1005.28,"id":72857115},{"batb":[[0,1.25,4.54]],"ltp":1.5,"tv":2055.32,"id":72857116}]}]}
{"op":"mcm","clk":"11877720218","pt":1724089434817,"mc":[{"id":"1.232018919","rc":[{"batb":[[0,1.25,10.54]],"ltp":1.26,"tv":1005.28,"id":72857115},{"batb":[[0,1.24,7.69],[1,1.2,250],[2,1.11,24.84]],"ltp":1.5,"tv":2055.32,"id":72857116}]}]}
{"op":"mcm","clk":"11877720334","pt":1724089435807,"mc":[{"id":"1.232018919","rc":[{"batb":[[0,1.24,6.53],[1,1.2,250],[2,1.11,24.84]],"ltp":1.26,"tv":1005.28,"id":72857115},{"batb":[[0,1.25,10.54],[1,1.24,7.15],[2,1.2,250]],"ltp":1.5,"tv":2055.32,"id":72857116}]}]}
{"op":"mcm","clk":"11877720641","pt":1724089438415,"mc":[{"id":"1.232018919","rc":[{"batb":[[0,1.25,14.54],[1,1.24,5.99],[2,1.2,250]],"ltp":1.26,"tv":1005.28,"id":72857115},{"batb":[[0,1.25,4.54]],"ltp":1.5,"tv":2055.32,"id":72857116}]}]}
{"op":"mcm","clk":"11877720939","pt":1724089441044,"mc":[{"id":"1.232018919","rc":[{"batb":[[0,1.25,10.54]],"ltp":1.26,"tv":1005.28,"id":72857115},{"batb":[[0,1.25,10.54]],"ltp":1.5,"tv":2055.32,"id":72857116}]}]}
{"op":"mcm","clk":"11877721042","pt":1724089441833,"mc":[{"id":"1.232018919","rc":[{"batb":[[0,1.24,6.53],[1,1.2,250],[2,1.11,24.84]],"ltp":1.26,"tv":1005.28,"id":72857115}]}]}
{"op":"mcm","clk":"11877721353","pt":1724089444408,"mc":[{"id":"1.232018919","rc":[{"batb":[[0,1.25,14.54],[1,1.24,5.99],[2,1.2,250]],"ltp":1.26,"tv":1005.28,"id":72857115},{"batb":[[0,1.25,4.54]],"ltp":1.5,"tv":2055.32,"id":72857116}]}]}
{"op":"mcm","clk":"11877721650","pt":1724089446614,"mc":[{"id":"1.232018919","rc":[{"batb":[[0,1.25,10.54]],"ltp":1.26,"tv":1005.28,"id":72857115},{"batb":[[0,1.26,10.54]],"ltp":1.5,"tv":2055.32,"id":72857116}]}]}
{"op":"mcm","clk":"11877721785","pt":1724089447722,"mc":[{"id":"1.232018919","rc":[{"batb":[[0,1.24,6.53],[1,1.2,250],[2,1.11,24.84]],"ltp":1.26,"tv":1005.28,"id":72857115}]}]}
{"op":"mcm","clk":"11877722107","pt":1724089450547,"mc":[{"id":"1.232018919","rc":[{"batb":[[0,1.25,14.54],[1,1.24,5.99],[2,1.2,250]],"ltp":1.26,"tv":1005.28,"id":72857115},{"batb":[[0,1.25,4.54]],"ltp":1.5,"tv":2055.32,"id":72857116}]}]}
{"op":"mcm","clk":"11877722450","pt":1724089453121,"mc":[{"id":"1.232018919","rc":[{"batb":[[0,1.25,10.54]],"ltp":1.26,"tv":1005.28,"id":72857115},{"batb":[[0,1.25,10.54]],"ltp":1.5,"tv":2055.32,"id":72857116}]}]}
{"op":"mcm","clk":"11877722549","pt":1724089453946,"mc":[{"id":"1.232018919","rc":[{"batb":[[0,1.24,6.53],[1,1.2,250],[2,1.11,24.84]],"ltp":1.26,"tv":1005.28,"id":72857115}]}]}
{"op":"mcm","clk":"11877722903","pt":1724089456743,"mc":[{"id":"1.232018919","rc":[{"batb":[[0,1.59,5.99],[1,1.25,14.54],[2,1.2,250]],"ltp":1.26,"tv":1005.28,"id":72857115},{"batb":[[0,1.25,4.54]],"ltp":1.5,"tv":2055.32,"id":72857116}]}]}
{"op":"mcm","clk":"11877722960","pt":1724089457124,"mc":[{"id":"1.232018919","rc":[{"batb":[[0,1.58,7.15],[1,1.25,4.54]],"ltp":1.5,"tv":2055.32,"id":72857116}]}]}
{"op":"mcm","clk":"11877723207","pt":1724089459142,"mc":[{"id":"1.232018919","rc":[{"batb":[[1,1.25,10.54]],"ltp":1.26,"tv":1005.28,"id":72857115},{"batb":[[0,1.59,10],[1,1.58,7.15],[2,1.2,250.54]],"ltp":1.5,"tv":2055.32,"id":72857116}]}]}
{"op":"mcm","clk":"11877723304","pt":1724089459945,"mc":[{"id":"1.232018919","rc":[{"batb":[[1,1.2,250.54],[2,1.11,24.84]],"ltp":1.26,"tv":1005.28,"id":72857115}]}]}
{"op":"mcm","clk":"11877723531","pt":1724089461632,"mc":[{"id":"1.232018919","rc":[{"batb":[[0,1.6,4],[1,1.59,5.99],[2,1.2,250.54]],"ltp":1.26,"tv":1005.28,"id":72857115},{"batb":[[0,1.6,4],[1,1.59,10],[2,1.58,7.15]],"ltp":1.5,"tv":2055.32,"id":72857116}]}]}
{"op":"mcm","clk":"11877723665","pt":1724089462805,"mc":[{"id":"1.232018919","rc":[{"batb":[[0,1.61,10],[1,1.6,4],[2,1.59,5.99]],"ltp":1.26,"tv":1005.28,"id":72857115},{"batb":[[1,1.58,7.15],[2,1.2,250.54]],"ltp":1.5,"tv":2055.32,"id":72857116}]}]}
{"op":"mcm","clk":"11877723803","pt":1724089463958,"mc":[{"id":"1.232018919","rc":[{"batb":[[1,1.59,5.99],[2,1.2,250.54]],"ltp":1.26,"tv":1005.28,"id":72857115},{"batb":[[0,1.58,7.15],[1,1.2,250.54],[2,1.11,24.84]],"ltp":1.5,"tv":2055.32,"id":72857116}]}]}
{"op":"mcm","clk":"11877723971","pt":1724089465167,"mc":[{"id":"1.232018919","rc":[{"batb":[[0,1.59,10],[1,1.58,7.15],[2,1.2,250.54]],"ltp":1.5,"tv":2055.32,"id":72857116}]}]}
{"op":"mcm","clk":"11877724112","pt":1724089466161,"mc":[{"id":"1.232018919","rc":[{"batb":[[0,1.6,4]],"ltp":1.26,"tv":1005.28,"id":72857115},{"batb":[[0,1.6,4],[1,1.59,10],[2,1.58,7.15]],"ltp":1.5,"tv":2055.32,"id":72857116}]}]}
{"op":"mcm","clk":"11877724394","pt":1724089468667,"mc":[{"id":"1.232018919","rc":[{"batb":[[0,1.6,10]],"ltp":1.26,"tv":1005.28,"id":72857115},{"batb":[[0,1.58,7.15],[1,1.2,250.54],[2,1.11,24.84]],"ltp":1.5,"tv":2055.32,"id":72857116}]}]}
{"op":"mcm","clk":"11877724816","pt":1724089472063,"mc":[{"id":"1.232018919","rc":[{"batb":[[0,1.6,4]],"ltp":1.26,"tv":1005.28,"id":72857115},{"batb":[[0,1.59,14],[1,1.58,7.15],[2,1.2,250.54]],"ltp":1.5,"tv":2055.32,"id":72857116}]}]}
{"op":"mcm","clk":"11877725143","pt":1724089474677,"mc":[{"id":"1.232018919","rc":[{"batb":[[0,1.6,10]],"ltp":1.26,"tv":1005.28,"id":72857115},{"batb":[[0,1.59,10]],"ltp":1.5,"tv":2055.32,"id":72857116}]}]}
{"op":"mcm","clk":"11877725245","pt":1724089475464,"mc":[{"id":"1.232018919","rc":[{"batb":[[0,1.58,7.15],[1,1.2,250.54],[2,1.11,24.84]],"ltp":1.5,"tv":2055.32,"id":72857116}]}]}
{"op":"mcm","clk":"11877725591","pt":1724089478277,"mc":[{"id":"1.232018919","rc":[{"batb":[[0,1.6,4]],"ltp":1.26,"tv":1005.28,"id":72857115},{"batb":[[0,1.59,14],[1,1.58,7.15],[2,1.2,250.54]],"ltp":1.5,"tv":2055.32,"id":72857116}]}]}
{"op":"mcm","clk":"11877725871","pt":1724089480779,"mc":[{"id":"1.232018919","rc":[{"batb":[[0,1.61,10]],"ltp":1.26,"tv":1005.28,"id":72857115},{"batb":[[0,1.59,10]],"ltp":1.5,"tv":2055.32,"id":72857116}]}]}
{"op":"mcm","clk":"11877725965","pt":1724089481467,"mc":[{"id":"1.232018919","rc":[{"batb":[[0,1.58,7.15],[1,1.2,250.54],[2,1.11,24.84]],"ltp":1.5,"tv":2055.32,"id":72857116}]}]}
{"op":"mcm","clk":"11877726307","pt":1724089484391,"mc":[{"id":"1.232018919","rc":[{"batb":[[0,1.62,4]],"ltp":1.26,"tv":1005.28,"id":72857115},{"batb":[[0,1.59,14],[1,1.58,7.15],[2,1.2,250.54]],"ltp":1.5,"tv":2055.32,"id":72857116}]}]}
{"op":"mcm","clk":"11877726665","pt":1724089487281,"mc":[{"id":"1.232018919","rc":[{"batb":[[0,1.63,10]],"ltp":1.26,"tv":1005.28,"id":72857115},{"batb":[[0,1.58,7.15],[1,1.2,250.54],[2,1.11,24.84]],"ltp":1.5,"tv":2055.32,"id":72857116}]}]}
{"op":"mcm","clk":"11877727200","pt":1724089491089,"mc":[{"id":"1.232018919","rc":[{"batb":[[0,1.59,5.99],[1,1.2,250.54],[2,1.11,24.84]],"ltp":1.26,"tv":1005.28,"id":72857115}]}]}
{"op":"mcm","clk":"11877727481","pt":1724089493311,"mc":[{"id":"1.232018919","rc":[{"batb":[[0,1.64,14],[1,1.59,5.99],[2,1.2,250.54]],"ltp":1.26,"tv":1005.28,"id":72857115},{"batb":[[0,1.59,14],[1,1.58,7.15],[2,1.2,250.54]],"ltp":1.5,"tv":2055.32,"id":72857116}]}]}
{"op":"mcm","clk":"11877728193","pt":1724089498513,"mc":[{"id":"1.232018919","rc":[{"batb":[[0,1.64,10]],"ltp":1.26,"tv":1005.28,"id":72857115},{"batb":[[0,1.59,10]],"ltp":1.5,"tv":2055.32,"id":72857116}]}]}
{"op":"mcm","clk":"11877728289","pt":1724089499404,"mc":[{"id":"1.232018919","rc":[{"batb":[[0,1.59,5.99],[1,1.2,250.54],[2,1.11,24.84]],"ltp":1.26,"tv":1005.28,"id":72857115},{"batb":[[0,1.58,7.15],[1,1.2,250.54],[2,1.11,24.84]],"ltp":1.5,"tv":2055.32,"id":72857116}]}]}
{"op":"mcm","clk":"11877728769","pt":1724089502626,"mc":[{"id":"1.232018919","rc":[{"batb":[[0,1.6,14],[1,1.59,5.99],[2,1.2,250.54]],"ltp":1.26,"tv":1005.28,"id":72857115},{"batb":[[0,1.59,14],[1,1.58,7.15],[2,1.2,250.54]],"ltp":1.5,"tv":2055.32,"id":72857116}]}]}
{"op":"mcm","clk":"11877729114","pt":1724089504903,"mc":[{"id":"1.232018919","rc":[{"batb":[[0,1.6,10]],"ltp":1.26,"tv":1005.28,"id":72857115},{"batb":[[0,1.59,10]],"ltp":1.5,"tv":2055.32,"id":72857116}]}]}
{"op":"mcm","clk":"11877729244","pt":1724089506016,"mc":[{"id":"1.232018919","rc":[{"batb":[[0,1.59,5.99],[1,1.2,250.54],[2,1.11,24.84]],"ltp":1.26,"tv":1005.28,"id":72857115},{"batb":[[0,1.58,7.15],[1,1.2,250.54],[2,1.11,24.84]],"ltp":1.5,"tv":2055.32,"id":72857116}]}]}
{"op":"mcm","clk":"11877729434","pt":1724089507597,"mc":[{"id":"1.232018919","rc":[{"batb":[[0,1.6,4],[1,1.59,5.99],[2,1.2,250.54]],"ltp":1.26,"tv":1005.28,"id":72857115},{"batb":[[0,1.59,4],[1,1.58,7.15],[2,1.2,250.54]],"ltp":1.5,"tv":2055.32,"id":72857116}]}]}
{"op":"mcm","clk":"11877729754","pt":1724089509898,"mc":[{"id":"1.232018919","rc":[{"batb":[[0,1.61,10]],"ltp":1.26,"tv":1005.28,"id":72857115},{"batb":[[0,1.6,10]],"ltp":1.5,"tv":2055.32,"id":72857116}]}]}
{"op":"mcm","clk":"11877730179","pt":1724089513508,"mc":[{"id":"1.232018919","rc":[{"batb":[[0,1.6,4]],"ltp":1.26,"tv":1005.28,"id":72857115},{"batb":[[0,1.59,4]],"ltp":1.5,"tv":2055.32,"id":72857116}]}]}
{"op":"mcm","clk":"11877730434","pt":1724089515912,"mc":[{"id":"1.232018919","rc":[{"batb":[[0,1.61,10]],"ltp":1.26,"tv":1005.28,"id":72857115},{"batb":[[0,1.6,10]],"ltp":1.5,"tv":2055.32,"id":72857116}]}]}
{"op":"mcm","clk":"11877730680","pt":1724089518212,"mc":[{"id":"1.232018919","rc":[{"batb":[[0,1.62,4],[1,1.61,10],[2,1.59,5.99]],"ltp":1.26,"tv":1005.28,"id":72857115},{"batb":[[0,1.61,4],[1,1.6,10],[2,1.58,7.15]],"ltp":1.5,"tv":2055.32,"id":72857116}]}]}
{"op":"mcm","clk":"11877730814","pt":1724089519307,"mc":[{"id":"1.232018919","rc":[{"batb":[[1,1.59,5.99],[2,1.2,250.54]],"ltp":1.26,"tv":1005.28,"id":72857115},{"batb":[[1,1.58,7.15],[2,1.2,250.54]],"ltp":1.5,"tv":2055.32,"id":72857116}]}]}
{"op":"mcm","clk":"11877731016","pt":1724089520822,"mc":[{"id":"1.232018919","rc":[{"batb":[[0,1.59,5.99],[1,1.2,250.54],[2,1.11,24.84]],"ltp":1.26,"tv":1005.28,"id":72857115},{"batb":[[0,1.58,7.15],[1,1.2,250.54],[2,1.11,24.84]],"ltp":1.5,"tv":2055.32,"id":72857116}]}]}
{"op":"mcm","clk":"11877731246","pt":1724089522703,"mc":[{"id":"1.232018919","rc":[{"batb":[[0,1.6,10],[1,1.59,5.99],[2,1.2,250.54]],"ltp":1.26,"tv":1005.28,"id":72857115},{"batb":[[0,1.59,10],[1,1.58,7.15],[2,1.2,250.54]],"ltp":1.5,"tv":2055.32,"id":72857116}]}]}
{"op":"mcm","clk":"11877731299","pt":1724089523223,"mc":[{"id":"1.232018919","rc":[{"batb":[[0,1.61,4],[1,1.6,10],[2,1.59,5.99]],"ltp":1.26,"tv":1005.28,"id":72857115},{"batb":[[0,1.6,4],[1,1.59,10],[2,1.58,7.15]],"ltp":1.5,"tv":2055.32,"id":72857116}]}]}
{"op":"mcm","clk":"11877731554","pt":1724089525522,"mc":[{"id":"1.232018919","rc":[{"batb":[[0,1.6,10],[1,1.59,5.99],[2,1.2,250.54]],"ltp":1.26,"tv":1005.28,"id":72857115},{"batb":[[0,1.59,10],[1,1.58,7.15],[2,1.2,250.54]],"ltp":1.5,"tv":2055.32,"id":72857116}]}]}
{"op":"mcm","clk":"11877731652","pt":1724089526418,"mc":[{"id":"1.232018919","rc":[{"batb":[[0,1.59,5.99],[1,1.2,250.54],[2,1.11,24.84]],"ltp":1.26,"tv":1005.28,"id":72857115},{"batb":[[0,1.58,7.15],[1,1.2,250.54],[2,1.11,24.84]],"ltp":1.5,"tv":2055.32,"id":72857116}]}]}
{"op":"mcm","clk":"11877731905","pt":1724089528812,"mc":[{"id":"1.232018919","rc":[{"batb":[[0,1.6,14],[1,1.59,5.99],[2,1.2,250.54]],"ltp":1.26,"tv":1005.28,"id":72857115},{"batb":[[0,1.59,14],[1,1.58,7.15],[2,1.2,250.54]],"ltp":1.5,"tv":2055.32,"id":72857116}]}]}
{"op":"mcm","clk":"11877732215","pt":1724089531425,"mc":[{"id":"1.232018919","rc":[{"batb":[[0,1.6,10]],"ltp":1.26,"tv":1005.28,"id":72857115},{"batb":[[0,1.59,10]],"ltp":1.5,"tv":2055.32,"id":72857116}]}]}
{"op":"mcm","clk":"11877732344","pt":1724089532318,"mc":[{"id":"1.232018919","rc":[{"batb":[[0,1.59,5.99],[1,1.2,250.54],[2,1.11,24.84]],"ltp":1.26,"tv":1005.28,"id":72857115},{"batb":[[0,1.58,7.15],[1,1.2,250.54],[2,1.11,24.84]],"ltp":1.5,"tv":2055.32,"id":72857116}]}]}
{"op":"mcm","clk":"11877732572","pt":1724089534504,"mc":[{"id":"1.232018919","rc":[{"batb":[[0,1.61,10],[1,1.6,4],[2,1.59,5.99]],"ltp":1.26,"tv":1005.28,"id":72857115},{"batb":[[0,1.6,10],[1,1.59,4],[2,1.58,7.15]],"ltp":1.5,"tv":2055.32,"id":72857116}]}]}
{"op":"mcm","clk":"11877732783","pt":1724089536539,"mc":[{"id":"1.232018919","rc":[{"batb":[[1,1.59,5.99],[2,1.2,250.54]],"ltp":1.26,"tv":1005.28,"id":72857115},{"batb":[[1,1.58,7.15],[2,1.2,250.54]],"ltp":1.5,"tv":2055.32,"id":72857116}]}]}
{"op":"mcm","clk":"11877732845","pt":1724089537118,"mc":[{"id":"1.232018919","rc":[{"batb":[[0,1.62,13.83],[1,1.61,10],[2,1.59,5.99]],"ltp":1.26,"tv":1005.28,"id":72857115},{"batb":[[0,1.61,14.05],[1,1.6,10],[2,1.58,7.15]],"ltp":1.5,"tv":2055.32,"id":72857116}]}]}
{"op":"mcm","clk":"11877732934","pt":1724089537949,"mc":[{"id":"1.232018919","rc":[{"batb":[[1,1.59,5.99],[2,1.2,250.54]],"ltp":1.26,"tv":1005.28,"id":72857115},{"batb":[[1,1.58,7.15],[2,1.2,250.54]],"ltp":1.5,"tv":2055.32,"id":72857116}]}]}
{"op":"mcm","clk":"11877733201","pt":1724089540333,"mc":[{"id":"1.232018919","rc":[{"batb":[[0,1.64,10],[1,1.63,4],[2,1.62,13.83]],"ltp":1.26,"tv":1005.28,"id":72857115},{"batb":[[0,1.63,10],[1,1.62,4],[2,1.61,14.05]],"ltp":1.5,"tv":2055.32,"id":72857116}]}]}
{"op":"mcm","clk":"11877733346","pt":1724089541643,"mc":[{"id":"1.232018919","rc":[{"batb":[[0,1.63,10.54]],"ltp":1.5,"tv":2055.32,"id":72857116}]}]}
{"op":"mcm","clk":"11877733387","pt":1724089542056,"mc":[{"id":"1.232018919","rc":[{"batb":[[1,1.62,13.83],[2,1.59,5.99]],"ltp":1.26,"tv":1005.28,"id":72857115},{"batb":[[1,1.61,14.05],[2,1.58,7.15]],"ltp":1.5,"tv":2055.32,"id":72857116}]}]}
{"op":"mcm","clk":"11877733572","pt":1724089543676,"mc":[{"id":"1.232018919","rc":[{"batb":[[0,1.62,13.83],[1,1.59,5.99],[2,1.2,250.54]],"ltp":1.26,"tv":1005.28,"id":72857115},{"batb":[[0,1.61,14.59],[1,1.58,7.15],[2,1.2,250]],"ltp":1.5,"tv":2055.32,"id":72857116}]}]}
{"op":"mcm","clk":"11877734309","pt":1724089549447,"mc":[{"id":"1.232018919","rc":[{"batb":[[0,1.63,14],[1,1.62,13.83],[2,1.59,5.99]],"ltp":1.26,"tv":1005.28,"id":72857115},{"batb":[[0,1.62,14.54],[1,1.61,14.05],[2,1.58,7.15]],"ltp":1.5,"tv":2055.32,"id":72857116}]}]}
{"op":"mcm","clk":"11877734651","pt":1724089552238,"mc":[{"id":"1.232018919","rc":[{"batb":[[0,1.63,10]],"ltp":1.26,"tv":1005.28,"id":72857115},{"batb":[[0,1.62,10.54]],"ltp":1.5,"tv":2055.32,"id":72857116}]}]}
{"op":"mcm","clk":"11877734749","pt":1724089552853,"mc":[{"id":"1.232018919","rc":[{"batb":[[0,1.62,13.83],[1,1.59,5.99],[2,1.2,250.54]],"ltp":1.26,"tv":1005.28,"id":72857115},{"batb":[[0,1.61,14.59],[1,1.58,7.15],[2,1.2,250]],"ltp":1.5,"tv":2055.32,"id":72857116}]}]}
{"op":"mcm","clk":"11877734950","pt":1724089554470,"mc":[{"id":"1.232018919","rc":[{"batb":[[0,1.63,4],[1,1.62,13.83],[2,1.59,5.99]],"ltp":1.26,"tv":1005.28,"id":72857115},{"batb":[[0,1.62,4.54],[1,1.61,14.05],[2,1.58,7.15]],"ltp":1.5,"tv":2055.32,"id":72857116}]}]}
{"op":"mcm","clk":"11877735081","pt":1724089555663,"mc":[{"id":"1.232018919","rc":[{"batb":[[0,1.64,10],[1,1.63,4],[2,1.62,13.83]],"ltp":1.26,"tv":1005.28,"id":72857115},{"batb":[[0,1.63,10.54],[1,1.62,4],[2,1.61,14.05]],"ltp":1.5,"tv":2055.32,"id":72857116}]}]}
{"op":"mcm","clk":"11877735216","pt":1724089556871,"mc":[{"id":"1.232018919","rc":[{"batb":[[1,1.62,13.83],[2,1.59,5.99]],"ltp":1.26,"tv":1005.28,"id":72857115},{"batb":[[1,1.61,14.05],[2,1.58,7.15]],"ltp":1.5,"tv":2055.32,"id":72857116}]}]}
{"op":"mcm","clk":"11877735476","pt":1724089559163,"mc":[{"id":"1.232018919","rc":[{"batb":[[0,1.65,4]],"ltp":1.26,"tv":1005.28,"id":72857115},{"batb":[[0,1.64,4.54]],"ltp":1.5,"tv":2055.32,"id":72857116}]}]}
{"op":"mcm","clk":"11877735740","pt":1724089561574,"mc":[{"id":"1.232018919","rc":[{"batb":[[0,1.63,10]],"ltp":1.26,"tv":1005.28,"id":72857115},{"batb":[[0,1.62,10.54]],"ltp":1.5,"tv":2055.32,"id":72857116}]}]}
{"op":"mcm","clk":"11877736085","pt":1724089564771,"mc":[{"id":"1.232018919","rc":[{"batb":[[0,1.61,14.59],[1,1.58,7.15],[2,1.2,250]],"ltp":1.5,"tv":2055.32,"id":72857116}]}]}
{"op":"mcm","clk":"11877736098","pt":1724089564877,"mc":[{"id":"1.232018919","rc":[{"batb":[[0,1.64,4]],"ltp":1.26,"tv":1005.28,"id":72857115},{"batb":[[0,1.62,4.54],[1,1.61,14.05],[2,1.58,7.15]],"ltp":1.5,"tv":2055.32,"id":72857116}]}]}
{"op":"mcm","clk":"11877736383","pt":1724089567275,"mc":[{"id":"1.232018919","rc":[{"batb":[[0,1.63,10]],"ltp":1.26,"tv":1005.28,"id":72857115},{"batb":[[0,1.62,10.54]],"ltp":1.5,"tv":2055.32,"id":72857116}]}]}
{"op":"mcm","clk":"11877736627","pt":1724089569479,"mc":[{"id":"1.232018919","rc":[{"batb":[[0,1.64,4],[1,1.63,10],[2,1.62,13.83]],"ltp":1.26,"tv":1005.28,"id":72857115},{"batb":[[0,1.63,4.54],[1,1.62,10],[2,1.61,14.05]],"ltp":1.5,"tv":2055.32,"id":72857116}]}]}
{"op":"mcm","clk":"11877736742","pt":1724089570472,"mc":[{"id":"1.232018919","rc":[{"batb":[[1,1.62,13.83],[2,1.59,5.99]],"ltp":1.26,"tv":1005.28,"id":72857115},{"batb":[[1,1.61,14.05],[2,1.58,7.15]],"ltp":1.5,"tv":2055.32,"id":72857116}]}]}
{"op":"mcm","clk":"11877736929","pt":1724089572202,"mc":[{"id":"1.232018919","rc":[{"batb":[[0,1.62,13.83],[1,1.59,5.99],[2,1.2,250.54]],"ltp":1.26,"tv":1005.28,"id":72857115},{"batb":[[0,1.61,14.59],[1,1.58,7.15],[2,1.2,250]],"ltp":1.5,"tv":2055.32,"id":72857116}]}]}
{"op":"mcm","clk":"11877737355","pt":1724089575705,"mc":[{"id":"1.232018919","rc":[{"batb":[[0,1.63,14],[1,1.62,13.83],[2,1.59,5.99]],"ltp":1.26,"tv":1005.28,"id":72857115},{"batb":[[0,1.62,14.54],[1,1.61,14.05],[2,1.58,7.15]],"ltp":1.5,"tv":2055.32,"id":72857116}]}]}
{"op":"mcm","clk":"11877737581","pt":1724089577890,"mc":[{"id":"1.232018919","rc":[{"batb":[[0,1.63,10]],"ltp":1.26,"tv":1005.28,"id":72857115},{"batb":[[0,1.62,10.54]],"ltp":1.5,"tv":2055.32,"id":72857116}]}]}
{"op":"mcm","clk":"11877737670","pt":1724089579002,"mc":[{"id":"1.232018919","rc":[{"batb":[[0,1.62,13.83],[1,1.59,5.99],[2,1.2,250]],"ltp":1.26,"tv":1005.28,"id":72857115},{"batb":[[0,1.61,14.59],[1,1.58,7.15],[2,1.2,250]],"ltp":1.5,"tv":2055.32,"id":72857116}]}]}
{"op":"mcm","clk":"11877738039","pt":1724089582728,"mc":[{"id":"1.232018919","rc":[{"batb":[[0,1.63,14],[1,1.62,13.83],[2,1.59,5.99]],"ltp":1.26,"tv":1005.28,"id":72857115},{"batb":[[0,1.62,14.54],[1,1.61,14.05],[2,1.58,7.15]],"ltp":1.5,"tv":2055.32,"id":72857116}]}]}
{"op":"mcm","clk":"11877738283","pt":1724089584925,"mc":[{"id":"1.232018919","rc":[{"batb":[[0,1.63,10]],"ltp":1.26,"tv":1005.28,"id":72857115},{"batb":[[0,1.62,10.54]],"ltp":1.5,"tv":2055.32,"id":72857116}]}]}
{"op":"mcm","clk":"11877738383","pt":1724089585916,"mc":[{"id":"1.232018919","rc":[{"batb":[[0,1.62,13.83],[1,1.59,5.99],[2,1.2,250]],"ltp":1.26,"tv":1005.28,"id":72857115},{"batb":[[0,1.61,14.59],[1,1.58,7.15],[2,1.2,250]],"ltp":1.5,"tv":2055.32,"id":72857116}]}]}
{"op":"mcm","clk":"11877738554","pt":1724089587426,"mc":[{"id":"1.232018919","rc":[{"batb":[[0,1.63,4],[1,1.62,13.83],[2,1.59,5.99]],"ltp":1.26,"tv":1005.28,"id":72857115},{"batb":[[0,1.62,4.54],[1,1.61,14.05],[2,1.58,7.15]],"ltp":1.5,"tv":2055.32,"id":72857116}]}]}
{"op":"mcm","clk":"11877738624","pt":1724089588103,"mc":[{"id":"1.232018919","rc":[{"batb":[[0,1.64,10],[1,1.63,4],[2,1.62,13.83]],"ltp":1.26,"tv":1005.28,"id":72857115},{"batb":[[0,1.63,10.54],[1,1.62,4],[2,1.61,14.05]],"ltp":1.5,"tv":2055.32,"id":72857116}]}]}
{"op":"mcm","clk":"11877738848","pt":1724089590038,"mc":[{"id":"1.232018919","rc":[{"batb":[[1,1.62,13.83],[2,1.59,5.99]],"ltp":1.26,"tv":1005.28,"id":72857115},{"batb":[[1,1.61,14.05],[2,1.58,7.15]],"ltp":1.5,"tv":2055.32,"id":72857116}]}]}
{"op":"mcm","clk":"11877739036","pt":1724089591606,"mc":[{"id":"1.232018919","rc":[{"batb":[[0,1.62,13.83],[1,1.59,5.99],[2,1.2,250]],"ltp":1.26,"tv":1005.28,"id":72857115},{"batb":[[0,1.61,14.59],[1,1.58,7.15],[2,1.2,250]],"ltp":1.5,"tv":2055.32,"id":72857116}]}]}
{"op":"mcm","clk":"11877739283","pt":1724089593895,"mc":[{"id":"1.232018919","rc":[{"batb":[[0,1.63,14],[1,1.62,13.83],[2,1.59,5.99]],"ltp":1.26,"tv":1005.28,"id":72857115},{"batb":[[0,1.62,14.54],[1,1.61,14.05],[2,1.58,7.15]],"ltp":1.5,"tv":2055.32,"id":72857116}]}]}
{"op":"mcm","clk":"11877739615","pt":1724089596723,"mc":[{"id":"1.232018919","rc":[{"batb":[[0,1.63,10]],"ltp":1.26,"tv":1005.28,"id":72857115},{"batb":[[0,1.62,10.54]],"ltp":1.5,"tv":2055.32,"id":72857116}]}]}
{"op":"mcm","clk":"11877739678","pt":1724089597248,"mc":[{"id":"1.232018919","rc":[{"batb":[[0,1.62,13.83],[1,1.59,5.99],[2,1.2,250]],"ltp":1.26,"tv":1005.28,"id":72857115},{"batb":[[0,1.61,14.59],[1,1.58,7.15],[2,1.2,250]],"ltp":1.5,"tv":2055.32,"id":72857116}]}]}
{"op":"mcm","clk":"11877739889","pt":1724089598714,"mc":[{"id":"1.232018919","rc":[{"batb":[[0,1.63,4],[1,1.62,13.83],[2,1.59,5.99]],"ltp":1.26,"tv":1005.28,"id":72857115}]}]}
{"op":"mcm","clk":"11877739915","pt":1724089598923,"mc":[{"id":"1.232018919","rc":[{"batb":[[0,1.62,4.54],[1,1.61,14.05],[2,1.58,7.15]],"ltp":1.5,"tv":2055.32,"id":72857116}]}]}
{"op":"mcm","clk":"11877740184","pt":1724089601213,"mc":[{"id":"1.232018919","rc":[{"batb":[[0,1.64,10]],"ltp":1.26,"tv":1005.28,"id":72857115},{"batb":[[0,1.63,10.54]],"ltp":1.5,"tv":2055.32,"id":72857116}]}]}
{"op":"mcm","clk":"11877740579","pt":1724089604430,"mc":[{"id":"1.232018919","rc":[{"batb":[[0,1.63,4]],"ltp":1.26,"tv":1005.28,"id":72857115},{"batb":[[0,1.64,4.54]],"ltp":1.5,"tv":2055.32,"id":72857116}]}]}
{"op":"mcm","clk":"11877740868","pt":1724089606756,"mc":[{"id":"1.232018919","rc":[{"batb":[[0,1.62,13.83],[1,1.59,5.99],[2,1.2,250]],"ltp":1.26,"tv":1005.28,"id":72857115}]}]}
{"op":"mcm","clk":"11877740951","pt":1724089607431,"mc":[{"id":"1.232018919","rc":[{"batb":[[0,1.63,10],[1,1.62,13.83],[2,1.59,5.99]],"batl":[[2,4,0.77]],"ltp":1.26,"tv":1005.28,"id":72857115},{"batb":[[0,1.65,10.54]],"batl":[[2,4,0.77]],"ltp":1.5,"tv":2055.32,"id":72857116}]}]}
{"op":"mcm","clk":"11877741246","pt":1724089610082,"mc":[{"id":"1.232018919","rc":[{"batb":[[0,1.64,4]],"ltp":1.26,"tv":1005.28,"id":72857115},{"batb":[[0,1.66,4],[1,1.61,14.59]],"ltp":1.5,"tv":2055.32,"id":72857116}]}]}
{"op":"mcm","clk":"11877741559","pt":1724089612774,"mc":[{"id":"1.232018919","rc":[{"batb":[[0,1.63,10]],"ltp":1.26,"tv":1005.28,"id":72857115},{"batb":[[0,1.62,10.54],[1,1.61,14.05]],"ltp":1.5,"tv":2055.32,"id":72857116}]}]}
{"op":"mcm","clk":"11877741851","pt":1724089615174,"mc":[{"id":"1.232018919","rc":[{"batb":[[0,1.64,4],[1,1.63,10],[2,1.62,13.83]],"batl":[[2,5,1.54]],"ltp":1.26,"tv":1005.28,"id":72857115},{"batb":[[0,1.63,4.54],[1,1.62,10],[2,1.61,14.05]],"batl":[[2,5,1.54]],"ltp":1.5,"tv":2055.32,"id":72857116}]}]}
{"op":"mcm","clk":"11877741956","pt":1724089616046,"mc":[{"id":"1.232018919","rc":[{"batb":[[1,1.62,13.83],[2,1.59,5.99]],"ltp":1.26,"tv":1005.28,"id":72857115},{"batb":[[1,1.61,14.05],[2,1.58,7.15]],"ltp":1.5,"tv":2055.32,"id":72857116}]}]}
{"op":"mcm","clk":"11877742129","pt":1724089617460,"mc":[{"id":"1.232018919","rc":[{"batb":[[0,1.62,13.83],[1,1.59,5.99],[2,1.2,250]],"ltp":1.26,"tv":1005.28,"id":72857115},{"batb":[[0,1.61,14.59],[1,1.58,7.15],[2,1.2,250]],"ltp":1.5,"tv":2055.32,"id":72857116}]}]}
{"op":"mcm","clk":"11877742308","pt":1724089618962,"mc":[{"id":"1.232018919","rc":[{"batb":[[0,1.63,10],[1,1.62,13.83],[2,1.59,5.99]],"ltp":1.26,"tv":1005.28,"id":72857115},{"batb":[[0,1.62,10.54],[1,1.61,14.05],[2,1.58,7.15]],"ltp":1.5,"tv":2055.32,"id":72857116}]}]}
{"op":"mcm","clk":"11877742431","pt":1724089620099,"mc":[{"id":"1.232018919","rc":[{"batb":[[0,1.64,4],[1,1.63,10],[2,1.62,13.83]],"ltp":1.26,"tv":1005.28,"id":72857115},{"batb":[[0,1.63,4.54],[1,1.62,10],[2,1.61,14.05]],"ltp":1.5,"tv":2055.32,"id":72857116}]}]}
{"op":"mcm","clk":"11877742756","pt":1724089622778,"mc":[{"id":"1.232018919","rc":[{"batb":[[0,1.62,13.83],[1,1.59,5.99],[2,1.2,250]],"ltp":1.26,"tv":1005.28,"id":72857115},{"batb":[[0,1.61,14.59],[1,1.58,7.15],[2,1.2,250]],"ltp":1.5,"tv":2055.32,"id":72857116}]}]}
{"op":"mcm","clk":"11877743456","pt":1724089628867,"mc":[{"id":"1.232018919","rc":[{"batb":[[0,1.63,14],[1,1.62,13.83],[2,1.59,5.99]],"ltp":1.26,"tv":1005.28,"id":72857115},{"batb":[[0,1.62,14.54],[1,1.61,14.05],[2,1.58,7.15]],"ltp":1.5,"tv":2055.32,"id":72857116}]}]}
{"op":"mcm","clk":"11877743708","pt":1724089631108,"mc":[{"id":"1.232018919","rc":[{"batb":[[0,1.63,10]],"ltp":1.26,"tv":1005.28,"id":72857115},{"batb":[[0,1.62,10.54]],"ltp":1.5,"tv":2055.32,"id":72857116}]}]}
{"op":"mcm","clk":"11877743825","pt":1724089632191,"mc":[{"id":"1.232018919","rc":[{"batb":[[0,1.62,13.83],[1,1.59,5.99],[2,1.2,250]],"ltp":1.26,"tv":1005.28,"id":72857115},{"batb":[[0,1.61,14.59],[1,1.58,7.15],[2,1.2,250]],"ltp":1.5,"tv":2055.32,"id":72857116}]}]}
{"op":"mcm","clk":"11877743960","pt":1724089633284,"mc":[{"id":"1.232018919","rc":[{"batb":[[0,1.63,4],[1,1.62,13.83],[2,1.59,5.99]],"ltp":1.26,"tv":1005.28,"id":72857115},{"batb":[[0,1.62,4.54],[1,1.61,14.05],[2,1.58,7.15]],"ltp":1.5,"tv":2055.32,"id":72857116}]}]}
{"op":"mcm","clk":"11877744245","pt":1724089635577,"mc":[{"id":"1.232018919","rc":[{"batb":[[0,1.63,10]],"ltp":1.26,"tv":1005.28,"id":72857115},{"batb":[[0,1.62,10.54]],"ltp":1.5,"tv":2055.32,"id":72857116}]}]}
{"op":"mcm","clk":"11877744630","pt":1724089638797,"mc":[{"id":"1.232018919","rc":[{"batb":[[0,1.62,13.83],[1,1.59,5.99],[2,1.2,250]],"ltp":1.26,"tv":1005.28,"id":72857115},{"batb":[[0,1.61,14.59],[1,1.58,7.15],[2,1.2,250]],"ltp":1.5,"tv":2055.32,"id":72857116}]}]}
{"op":"mcm","clk":"11877744665","pt":1724089639112,"mc":[{"id":"1.232018919","rc":[{"batb":[[0,1.63,4],[1,1.62,13.83],[2,1.59,5.99]],"ltp":1.26,"tv":1005.28,"id":72857115},{"batb":[[0,1.62,4.54],[1,1.61,14.05],[2,1.58,7.15]],"ltp":1.5,"tv":2055.32,"id":72857116}]}]}
{"op":"mcm","clk":"11877744949","pt":1724089641399,"mc":[{"id":"1.232018919","rc":[{"batb":[[0,1.63,10]],"ltp":1.26,"tv":1005.28,"id":72857115},{"batb":[[0,1.63,10.54]],"ltp":1.5,"tv":2055.32,"id":72857116}]}]}
{"op":"mcm","clk":"11877745356","pt":1724089644679,"mc":[{"id":"1.232018919","rc":[{"batb":[[0,1.62,13.83],[1,1.59,5.99],[2,1.2,250]],"ltp":1.26,"tv":1005.28,"id":72857115},{"batb":[[0,1.61,14.59],[1,1.58,7.15],[2,1.2,250]],"ltp":1.5,"tv":2055.32,"id":72857116}]}]}
{"op":"mcm","clk":"11877745364","pt":1724089644829,"mc":[{"id":"1.232018919","rc":[{"batb":[[0,1.63,4],[1,1.62,13.83],[2,1.59,5.99]],"ltp":1.26,"tv":1005.28,"id":72857115},{"batb":[[0,1.62,4.54],[1,1.61,14.05],[2,1.58,7.15]],"ltp":1.5,"tv":2055.32,"id":72857116}]}]}
{"op":"mcm","clk":"11877745702","pt":1724089647388,"mc":[{"id":"1.232018919","rc":[{"batb":[[0,1.63,10]],"ltp":1.26,"tv":1005.28,"id":72857115},{"batb":[[0,1.62,10.54]],"ltp":1.5,"tv":2055.32,"id":72857116}]}]}
{"op":"mcm","clk":"11877746075","pt":1724089650815,"mc":[{"id":"1.232018919","rc":[{"batb":[[0,1.63,4]],"ltp":1.26,"tv":1005.28,"id":72857115},{"batb":[[0,1.62,4.54]],"ltp":1.5,"tv":2055.32,"id":72857116}]}]}
{"op":"mcm","clk":"11877746319","pt":1724089653230,"mc":[{"id":"1.232018919","rc":[{"batb":[[0,1.64,10]],"ltp":1.26,"tv":1005.28,"id":72857115},{"batb":[[0,1.63,10.54]],"ltp":1.5,"tv":2055.32,"id":72857116}]}]}
{"op":"mcm","clk":"11877746729","pt":1724089656714,"mc":[{"id":"1.232018919","rc":[{"batb":[[0,1.63,4]],"ltp":1.26,"tv":1005.28,"id":72857115},{"batb":[[0,1.62,4.54]],"ltp":1.5,"tv":2055.32,"id":72857116}]}]}
{"op":"mcm","clk":"11877746958","pt":1724089658641,"mc":[{"id":"1.232018919","rc":[{"batb":[[0,1.64,10],[1,1.63,4],[2,1.62,13.83]],"ltp":1.26,"tv":1005.28,"id":72857115},{"batb":[[0,1.63,10.54],[1,1.62,4],[2,1.61,14.05]],"ltp":1.5,"tv":2055.32,"id":72857116}]}]}
{"op":"mcm","clk":"11877747008","pt":1724089659006,"mc":[{"id":"1.232018919","rc":[{"batb":[[1,1.62,13.83],[2,1.59,5.99]],"ltp":1.26,"tv":1005.28,"id":72857115},{"batb":[[1,1.61,14.05],[2,1.58,7.15]],"ltp":1.5,"tv":2055.32,"id":72857116}]}]}
{"op":"mcm","clk":"11877747414","pt":1724089662026,"mc":[{"id":"1.232018919","rc":[{"batb":[[0,1.65,4]],"ltp":1.26,"tv":1005.28,"id":72857115},{"batb":[[0,1.64,4.54]],"ltp":1.5,"tv":2055.32,"id":72857116}]}]}
{"op":"mcm","clk":"11877747920","pt":1724089665198,"mc":[{"id":"1.232018919","rc":[{"batb":[[0,1.66,10]],"ltp":1.26,"tv":1005.28,"id":72857115},{"batb":[[0,1.65,10.54]],"ltp":1.5,"tv":2055.32,"id":72857116}]}]}
{"op":"mcm","clk":"11877748744","pt":1724089667552,"mc":[{"id":"1.232018919","rc":[{"batb":[[0,1.67,4],[1,1.66,10],[2,1.62,13.83]],"ltp":1.26,"tv":1005.28,"id":72857115},{"batb":[[0,1.66,4.54],[1,1.65,10],[2,1.61,14.05]],"ltp":1.5,"tv":2055.32,"id":72857116}]}]}
{"op":"mcm","clk":"11877749427","pt":1724089669728,"mc":[{"id":"1.232018919","rc":[{"batb":[[0,1.62,13.83],[1,1.59,5.99],[2,1.2,250]],"ltp":1.26,"tv":1005.28,"id":72857115},{"batb":[[0,1.61,14.59],[1,1.58,7.15],[2,1.2,250]],"ltp":1.5,"tv":2055.32,"id":72857116}]}]}
{"op":"mcm","clk":"11877749845","pt":1724089671114,"mc":[{"id":"1.232018919","rc":[{"batb":[[0,1.63,10],[1,1.62,13.83],[2,1.59,5.99]],"ltp":1.26,"tv":1005.28,"id":72857115},{"batb":[[0,1.62,10.54],[1,1.61,14.05],[2,1.58,7.15]],"ltp":1.5,"tv":2055.32,"id":72857116}]}]}
{"op":"mcm","clk":"11877750127","pt":1724089672328,"mc":[{"id":"1.232018919","rc":[{"batb":[[0,1.64,4],[1,1.63,10],[2,1.62,13.83]],"ltp":1.26,"tv":1005.28,"id":72857115},{"batb":[[0,1.63,4.54],[1,1.62,10],[2,1.61,14.05]],"ltp":1.5,"tv":2055.32,"id":72857116}]}]}
{"op":"mcm","clk":"11877750572","pt":1724089674524,"mc":[{"id":"1.232018919","rc":[{"batb":[[0,1.62,13.83],[1,1.59,5.99],[2,1.2,250]],"ltp":1.26,"tv":1005.28,"id":72857115},{"batb":[[0,1.61,14.59],[1,1.58,7.15],[2,1.2,250]],"ltp":1.5,"tv":2055.32,"id":72857116}]}]}
{"op":"mcm","clk":"11877750976","pt":1724089676834,"mc":[{"id":"1.232018919","rc":[{"batb":[[0,1.63,14],[1,1.62,13.83],[2,1.59,5.99]],"ltp":1.26,"tv":1005.28,"id":72857115},{"batb":[[0,1.62,14.54],[1,1.61,14.05],[2,1.58,7.15]],"ltp":1.5,"tv":2055.32,"id":72857116}]}]}
{"op":"mcm","clk":"11877751421","pt":1724089679457,"mc":[{"id":"1.232018919","rc":[{"batb":[[0,1.63,10]],"ltp":1.26,"tv":1005.28,"id":72857115},{"batb":[[0,1.62,10.54]],"ltp":1.5,"tv":2055.32,"id":72857116}]}]}
{"op":"mcm","clk":"11877751579","pt":1724089680461,"mc":[{"id":"1.232018919","rc":[{"batb":[[0,1.62,13.83],[1,1.59,5.99],[2,1.2,250]],"ltp":1.26,"tv":1005.28,"id":72857115},{"batb":[[0,1.61,14.59],[1,1.58,7.15],[2,1.2,250]],"ltp":1.5,"tv":2055.32,"id":72857116}]}]}
{"op":"mcm","clk":"11877751943","pt":1724089682647,"mc":[{"id":"1.232018919","rc":[{"batb":[[0,1.63,14],[1,1.62,13.83],[2,1.59,5.99]],"ltp":1.26,"tv":1005.28,"id":72857115},{"batb":[[0,1.62,14.54],[1,1.61,14.05],[2,1.58,7.15]],"ltp":1.5,"tv":2055.32,"id":72857116}]}]}
{"op":"mcm","clk":"11877752268","pt":1724089684850,"mc":[{"id":"1.232018919","rc":[{"batb":[[0,1.63,10]],"ltp":1.26,"tv":1005.28,"id":72857115},{"batb":[[0,1.62,10.54]],"ltp":1.5,"tv":2055.32,"id":72857116}]}]}
{"op":"mcm","clk":"11877752427","pt":1724089685978,"mc":[{"id":"1.232018919","rc":[{"batb":[[0,1.62,13.83],[1,1.59,5.99],[2,1.2,250]],"ltp":1.26,"tv":1005.28,"id":72857115},{"batb":[[0,1.61,14.59],[1,1.58,7.15],[2,1.2,250]],"ltp":1.5,"tv":2055.32,"id":72857116}]}]}
{"op":"mcm","clk":"11877752941","pt":1724089689623,"mc":[{"id":"1.232018919","rc":[{"batb":[[0,1.63,14],[1,1.62,13.83],[2,1.59,5.99]],"ltp":1.26,"tv":1005.28,"id":72857115},{"batb":[[0,1.62,14.54],[1,1.61,14.05],[2,1.58,7.15]],"ltp":1.5,"tv":2055.32,"id":72857116}]}]}
{"op":"mcm","clk":"11877753262","pt":1724089692067,"mc":[{"id":"1.232018919","rc":[{"batb":[[0,1.63,10]],"ltp":1.26,"tv":1005.28,"id":72857115},{"batb":[[0,1.62,10.54]],"ltp":1.5,"tv":2055.32,"id":72857116}]}]}
{"op":"mcm","clk":"11877753360","pt":1724089692846,"mc":[{"id":"1.232018919","rc":[{"batb":[[0,1.62,13.83],[1,1.59,5.99],[2,1.2,250]],"ltp":1.26,"tv":1005.28,"id":72857115},{"batb":[[0,1.61,14.59],[1,1.58,7.15],[2,1.2,250]],"ltp":1.5,"tv":2055.32,"id":72857116}]}]}
{"op":"mcm","clk":"11877754077","pt":1724089698062,"mc":[{"id":"1.232018919","rc":[{"batb":[[0,1.63,14],[1,1.62,13.83],[2,1.59,5.99]],"ltp":1.26,"tv":1005.28,"id":72857115},{"batb":[[0,1.62,14.54],[1,1.61,14.05],[2,1.58,7.15]],"ltp":1.5,"tv":2055.32,"id":72857116}]}]}
{"op":"mcm","clk":"11877754422","pt":1724089700732,"mc":[{"id":"1.232018919","rc":[{"batb":[[0,1.63,10]],"ltp":1.26,"tv":1005.28,"id":72857115},{"batb":[[0,1.62,10.54]],"ltp":1.5,"tv":2055.32,"id":72857116}]}]}
{"op":"mcm","clk":"11877754539","pt":1724089701673,"mc":[{"id":"1.232018919","rc":[{"batb":[[0,1.62,13.83],[1,1.59,5.99],[2,1.2,250]],"ltp":1.26,"tv":1005.28,"id":72857115},{"batb":[[0,1.61,14.59],[1,1.58,7.15],[2,1.2,250]],"ltp":1.5,"tv":2055.32,"id":72857116}]}]}
{"op":"mcm","clk":"11877754812","pt":1724089703859,"mc":[{"id":"1.232018919","rc":[{"batb":[[0,1.63,14],[1,1.62,13.83],[2,1.59,5.99]],"ltp":1.26,"tv":1005.28,"id":72857115},{"batb":[[0,1.62,14.54],[1,1.61,14.05],[2,1.58,7.15]],"ltp":1.5,"tv":2055.32,"id":72857116}]}]}
{"op":"mcm","clk":"11877755103","pt":1724089706371,"mc":[{"id":"1.232018919","rc":[{"batb":[[0,1.63,10]],"ltp":1.26,"tv":1005.28,"id":72857115},{"batb":[[0,1.62,10.54]],"ltp":1.5,"tv":2055.32,"id":72857116}]}]}
{"op":"mcm","clk":"11877755209","pt":1724089707254,"mc":[{"id":"1.232018919","rc":[{"batb":[[0,1.62,13.83],[1,1.59,5.99],[2,1.2,250]],"ltp":1.26,"tv":1005.28,"id":72857115},{"batb":[[0,1.61,14.59],[1,1.58,7.15],[2,1.2,250]],"ltp":1.5,"tv":2055.32,"id":72857116}]}]}
{"op":"mcm","clk":"11877755480","pt":1724089708975,"mc":[{"id":"1.232018919","rc":[{"batb":[[0,1.63,4],[1,1.62,13.83],[2,1.59,5.99]],"ltp":1.26,"tv":1005.28,"id":72857115},{"batb":[[0,1.62,4.54],[1,1.61,14.05],[2,1.58,7.15]],"ltp":1.5,"tv":2055.32,"id":72857116}]}]}
{"op":"mcm","clk":"11877755626","pt":1724089710161,"mc":[{"id":"1.232018919","rc":[{"batb":[[0,1.64,10],[1,1.63,4],[2,1.62,13.83]],"ltp":1.26,"tv":1005.28,"id":72857115},{"batb":[[0,1.63,10.54],[1,1.62,4],[2,1.61,14.05]],"ltp":1.5,"tv":2055.32,"id":72857116}]}]}
{"op":"mcm","clk":"11877755854","pt":1724089711778,"mc":[{"id":"1.232018919","rc":[{"batb":[[1,1.62,13.83],[2,1.59,5.99]],"ltp":1.26,"tv":1005.28,"id":72857115},{"batb":[[1,1.61,14.05],[2,1.58,7.15]],"ltp":1.5,"tv":2055.32,"id":72857116}]}]}
{"op":"mcm","clk":"11877756064","pt":1724089713489,"mc":[{"id":"1.232018919","rc":[{"batb":[[0,1.62,13.83],[1,1.59,5.99],[2,1.2,250]],"ltp":1.26,"tv":1005.28,"id":72857115},{"batb":[[0,1.61,14.59],[1,1.58,7.15],[2,1.2,250]],"ltp":1.5,"tv":2055.32,"id":72857116}]}]}
{"op":"mcm","clk":"11877756305","pt":1724089715356,"mc":[{"id":"1.232018919","rc":[{"batb":[[0,1.63,4],[1,1.62,13.83],[2,1.59,5.99]],"ltp":1.26,"tv":1005.28,"id":72857115},{"batb":[[0,1.62,4.54],[1,1.61,14.05],[2,1.58,7.15]],"ltp":1.5,"tv":2055.32,"id":72857116}]}]}
{"op":"mcm","clk":"11877756441","pt":1724089716558,"mc":[{"id":"1.232018919","rc":[{"batb":[[0,1.64,10],[1,1.63,4],[2,1.62,13.83]],"ltp":1.26,"tv":1005.28,"id":72857115},{"batb":[[0,1.63,10.54],[1,1.62,4],[2,1.61,14.05]],"ltp":1.5,"tv":2055.32,"id":72857116}]}]}
{"op":"mcm","clk":"11877756580","pt":1724089717599,"mc":[{"id":"1.232018919","rc":[{"batb":[[1,1.62,13.83],[2,1.59,5.99]],"ltp":1.26,"tv":1005.28,"id":72857115},{"batb":[[1,1.61,14.05],[2,1.58,7.15]],"ltp":1.5,"tv":2055.32,"id":72857116}]}]}
{"op":"mcm","clk":"11877756916","pt":1724089720257,"mc":[{"id":"1.232018919","rc":[{"batb":[[0,1.65,4]],"ltp":1.26,"tv":1005.28,"id":72857115},{"batb":[[0,1.64,4.54]],"ltp":1.5,"tv":2055.32,"id":72857116}]}]}
{"op":"mcm","clk":"11877757221","pt":1724089722565,"mc":[{"id":"1.232018919","rc":[{"batb":[[0,1.66,10]],"ltp":1.26,"tv":1005.28,"id":72857115},{"batb":[[0,1.65,10.54]],"ltp":1.5,"tv":2055.32,"id":72857116}]}]}
{"op":"mcm","clk":"11877757681","pt":1724089726314,"mc":[{"id":"1.232018919","rc":[{"batb":[[0,1.63,4]],"ltp":1.26,"tv":1005.28,"id":72857115},{"batb":[[0,1.62,4.54]],"ltp":1.5,"tv":2055.32,"id":72857116}]}]}
{"op":"mcm","clk":"11877757913","pt":1724089728385,"mc":[{"id":"1.232018919","rc":[{"batb":[[0,1.64,10],[1,1.63,4],[2,1.62,13.83]],"ltp":1.26,"tv":1005.28,"id":72857115},{"batb":[[0,1.63,10.54],[1,1.62,4],[2,1.61,14.05]],"ltp":1.5,"tv":2055.32,"id":72857116}]}]}
{"op":"mcm","clk":"11877757978","pt":1724089728902,"mc":[{"id":"1.232018919","rc":[{"batb":[[1,1.62,13.83],[2,1.59,5.99]],"ltp":1.26,"tv":1005.28,"id":72857115},{"batb":[[1,1.61,14.05],[2,1.58,7.15]],"ltp":1.5,"tv":2055.32,"id":72857116}]}]}
{"op":"mcm","clk":"11877758349","pt":1724089732074,"mc":[{"id":"1.232018919","rc":[{"batb":[[0,1.63,4]],"ltp":1.26,"tv":1005.28,"id":72857115},{"batb":[[0,1.62,4.54]],"ltp":1.5,"tv":2055.32,"id":72857116}]}]}
{"op":"mcm","clk":"11877758694","pt":1724089734784,"mc":[{"id":"1.232018919","rc":[{"batb":[[0,1.64,10]],"ltp":1.26,"tv":1005.28,"id":72857115},{"batb":[[0,1.63,10.54]],"ltp":1.5,"tv":2055.32,"id":72857116}]}]}
{"op":"mcm","clk":"11877758984","pt":1724089737683,"mc":[{"id":"1.232018919","rc":[{"batb":[[0,1.65,4],[1,1.64,10],[2,1.62,13.83]],"ltp":1.26,"tv":1005.28,"id":72857115},{"batb":[[0,1.64,4.54],[1,1.63,10],[2,1.61,14.05]],"ltp":1.5,"tv":2055.32,"id":72857116}]}]}
{"op":"mcm","clk":"11877759085","pt":1724089738407,"mc":[{"id":"1.232018919","rc":[{"batb":[[1,1.62,13.83],[2,1.59,5.99]],"ltp":1.26,"tv":1005.28,"id":72857115},{"batb":[[1,1.61,14.05],[2,1.58,7.15]],"ltp":1.5,"tv":2055.32,"id":72857116}]}]}
{"op":"mcm","clk":"11877759243","pt":1724089739909,"mc":[{"id":"1.232018919","rc":[{"batb":[[0,1.62,13.83],[1,1.59,5.99],[2,1.2,250]],"ltp":1.26,"tv":1005.28,"id":72857115},{"batb":[[0,1.61,14.59],[1,1.58,7.15],[2,1.2,250]],"ltp":1.5,"tv":2055.32,"id":72857116}]}]}
{"op":"mcm","clk":"11877759380","pt":1724089741105,"mc":[{"id":"1.232018919","rc":[{"batb":[[0,1.63,10],[1,1.62,13.83],[2,1.59,5.99]],"ltp":1.26,"tv":1005.28,"id":72857115},{"batb":[[0,1.62,10.54],[1,1.61,14.05],[2,1.58,7.15]],"ltp":1.5,"tv":2055.32,"id":72857116}]}]}
{"op":"mcm","clk":"11877759774","pt":1724089744495,"mc":[{"id":"1.232018919","rc":[{"batb":[[0,1.63,4]],"ltp":1.26,"tv":1005.28,"id":72857115},{"batb":[[0,1.62,4.54]],"ltp":1.5,"tv":2055.32,"id":72857116}]}]}
{"op":"mcm","clk":"11877760033","pt":1724089746779,"mc":[{"id":"1.232018919","rc":[{"batb":[[0,1.64,10]],"ltp":1.26,"tv":1005.28,"id":72857115},{"batb":[[0,1.63,10.54]],"ltp":1.5,"tv":2055.32,"id":72857116}]}]}
{"op":"mcm","clk":"11877760306","pt":1724089749124,"mc":[{"id":"1.232018919","rc":[{"batb":[[0,1.65,4],[1,1.64,10],[2,1.62,13.83]],"ltp":1.26,"tv":1005.28,"id":72857115},{"batb":[[0,1.64,4.54],[1,1.63,10],[2,1.61,14.05]],"ltp":1.5,"tv":2055.32,"id":72857116}]}]}
{"op":"mcm","clk":"11877760430","pt":1724089750220,"mc":[{"id":"1.232018919","rc":[{"batb":[[1,1.62,13.83],[2,1.59,5.99]],"ltp":1.26,"tv":1005.28,"id":72857115},{"batb":[[1,1.61,14.05],[2,1.58,7.15]],"ltp":1.5,"tv":2055.32,"id":72857116}]}]}
{"op":"mcm","clk":"11877760562","pt":1724089751411,"mc":[{"id":"1.232018919","rc":[{"batb":[[0,1.62,13.83],[1,1.59,5.99],[2,1.2,250]],"ltp":1.26,"tv":1005.28,"id":72857115},{"batb":[[0,1.61,14.59],[1,1.58,7.15],[2,1.2,250]],"ltp":1.5,"tv":2055.32,"id":72857116}]}]}
{"op":"mcm","clk":"11877760705","pt":1724089752813,"mc":[{"id":"1.232018919","rc":[{"batb":[[0,1.63,10],[1,1.62,13.83],[2,1.59,5.99]],"ltp":1.26,"tv":1005.28,"id":72857115},{"batb":[[0,1.62,10.54],[1,1.61,14.05],[2,1.58,7.15]],"ltp":1.5,"tv":2055.32,"id":72857116}]}]}
{"op":"mcm","clk":"11877760960","pt":1724089754897,"mc":[{"id":"1.232018919","rc":[{"batb":[[0,1.64,4],[1,1.63,10],[2,1.62,13.83]],"ltp":1.26,"tv":1005.28,"id":72857115},{"batb":[[0,1.63,4.54],[1,1.62,10],[2,1.61,14.05]],"ltp":1.5,"tv":2055.32,"id":72857116}]}]}
{"op":"mcm","clk":"11877761116","pt":1724089756200,"mc":[{"id":"1.232018919","rc":[{"batb":[[1,1.62,13.83],[2,1.59,5.99]],"ltp":1.26,"tv":1005.28,"id":72857115},{"batb":[[1,1.61,14.05],[2,1.58,7.15]],"ltp":1.5,"tv":2055.32,"id":72857116}]}]}
{"op":"mcm","clk":"11877761272","pt":1724089757396,"mc":[{"id":"1.232018919","rc":[{"batb":[[0,1.62,13.83],[1,1.59,5.99],[2,1.2,250]],"ltp":1.26,"tv":1005.28,"id":72857115},{"batb":[[0,1.61,14.59],[1,1.58,7.15],[2,1.2,250]],"ltp":1.5,"tv":2055.32,"id":72857116}]}]}
{"op":"mcm","clk":"11877761542","pt":1724089759737,"mc":[{"id":"1.232018919","rc":[{"batb":[[0,1.63,14],[1,1.62,13.83],[2,1.59,5.99]],"ltp":1.26,"tv":1005.28,"id":72857115},{"batb":[[0,1.62,14.54],[1,1.61,14.05],[2,1.58,7.15]],"ltp":1.5,"tv":2055.32,"id":72857116}]}]}
{"op":"mcm","clk":"11877761818","pt":1724089762017,"mc":[{"id":"1.232018919","rc":[{"batb":[[0,1.63,10]],"ltp":1.26,"tv":1005.28,"id":72857115},{"batb":[[0,1.62,10.54]],"ltp":1.5,"tv":2055.32,"id":72857116}]}]}
{"op":"mcm","clk":"11877761921","pt":1724089762908,"mc":[{"id":"1.232018919","rc":[{"batb":[[0,1.62,13.83],[1,1.59,5.99],[2,1.2,250]],"ltp":1.26,"tv":1005.28,"id":72857115},{"batb":[[0,1.61,14.59],[1,1.58,7.15],[2,1.2,250]],"ltp":1.5,"tv":2055.32,"id":72857116}]}]}
{"op":"mcm","clk":"11877762368","pt":1724089766702,"mc":[{"id":"1.232018919","rc":[{"batb":[[0,1.63,14],[1,1.62,13.83],[2,1.59,5.99]],"ltp":1.26,"tv":1005.28,"id":72857115},{"batb":[[0,1.62,14.54],[1,1.61,14.05],[2,1.58,7.15]],"ltp":1.5,"tv":2055.32,"id":72857116}]}]}
{"op":"mcm","clk":"11877762686","pt":1724089769559,"mc":[{"id":"1.232018919","rc":[{"batb":[[0,1.63,10]],"ltp":1.26,"tv":1005.28,"id":72857115},{"batb":[[0,1.62,10.54]],"ltp":1.5,"tv":2055.32,"id":72857116}]}]}
{"op":"mcm","clk":"11877762747","pt":1724089770033,"mc":[{"id":"1.232018919","rc":[{"batb":[[0,1.62,13.83],[1,1.59,5.99],[2,1.2,250]],"ltp":1.26,"tv":1005.28,"id":72857115},{"batb":[[0,1.61,14.59],[1,1.58,7.15],[2,1.2,250]],"ltp":1.5,"tv":2055.32,"id":72857116}]}]}
{"op":"mcm","clk":"11877763140","pt":1724089773271,"mc":[{"id":"1.232018919","rc":[{"batb":[[0,1.63,14],[1,1.62,13.83],[2,1.59,5.99]],"ltp":1.26,"tv":1005.28,"id":72857115},{"batb":[[0,1.62,14.54],[1,1.61,14.05],[2,1.58,7.15]],"ltp":1.5,"tv":2055.32,"id":72857116}]}]}
{"op":"mcm","clk":"11877763430","pt":1724089775839,"mc":[{"id":"1.232018919","rc":[{"batb":[[0,1.63,10]],"ltp":1.26,"tv":1005.28,"id":72857115},{"batb":[[0,1.62,10.54]],"ltp":1.5,"tv":2055.32,"id":72857116}]}]}
{"op":"mcm","clk":"11877763536","pt":1724089776854,"mc":[{"id":"1.232018919","rc":[{"batb":[[0,1.62,13.83],[1,1.59,5.99],[2,1.2,250]],"ltp":1.26,"tv":1005.28,"id":72857115},{"batb":[[0,1.61,14.59],[1,1.58,7.15],[2,1.2,250]],"ltp":1.5,"tv":2055.32,"id":72857116}]}]}
{"op":"mcm","clk":"11877763684","pt":1724089778238,"mc":[{"id":"1.232018919","rc":[{"batb":[[0,1.63,4],[1,1.62,13.83],[2,1.59,5.99]],"ltp":1.26,"tv":1005.28,"id":72857115},{"batb":[[0,1.62,4.54],[1,1.61,14.05],[2,1.58,7.15]],"ltp":1.5,"tv":2055.32,"id":72857116}]}]}
{"op":"mcm","clk":"11877763854","pt":1724089779541,"mc":[{"id":"1.232018919","rc":[{"batb":[[0,1.64,10],[1,1.63,4],[2,1.62,13.83]],"ltp":1.26,"tv":1005.28,"id":72857115},{"batb":[[0,1.63,10.54],[1,1.62,4],[2,1.61,14.05]],"ltp":1.5,"tv":2055.32,"id":72857116}]}]}
{"op":"mcm","clk":"11877763971","pt":1724089780562,"mc":[{"id":"1.232018919","rc":[{"batb":[[1,1.62,13.83],[2,1.59,5.99]],"ltp":1.26,"tv":1005.28,"id":72857115},{"batb":[[1,1.61,14.05],[2,1.58,7.15]],"ltp":1.5,"tv":2055.32,"id":72857116}]}]}
{"op":"mcm","clk":"11877764188","pt":1724089782737,"mc":[{"id":"1.232018919","rc":[{"batb":[[0,1.65,4],[1,1.64,10],[2,1.62,13.83]],"ltp":1.26,"tv":1005.28,"id":72857115},{"batb":[[0,1.64,4.54],[1,1.63,10],[2,1.61,14.05]],"ltp":1.5,"tv":2055.32,"id":72857116}]}]}
{"op":"mcm","clk":"11877764218","pt":1724089783049,"mc":[{"id":"1.232018919","rc":[{"batb":[[1,1.62,13.83],[2,1.59,5.99]],"ltp":1.26,"tv":1005.28,"id":72857115},{"batb":[[1,1.61,14.05],[2,1.58,7.15]],"ltp":1.5,"tv":2055.32,"id":72857116}]}]}
{"op":"mcm","clk":"11877764471","pt":1724089785266,"mc":[{"id":"1.232018919","rc":[{"batb":[[0,1.63,10]],"ltp":1.26,"tv":1005.28,"id":72857115},{"batb":[[0,1.62,10.54]],"ltp":1.5,"tv":2055.32,"id":72857116}]}]}
{"op":"mcm","clk":"11877764750","pt":1724089787748,"mc":[{"id":"1.232018919","rc":[{"batb":[[0,1.64,4],[1,1.63,10],[2,1.62,13.83]],"ltp":1.26,"tv":1005.28,"id":72857115},{"batb":[[0,1.63,4.54],[1,1.62,10],[2,1.61,14.05]],"ltp":1.5,"tv":2055.32,"id":72857116}]}]}
{"op":"mcm","clk":"11877764825","pt":1724089788470,"mc":[{"id":"1.232018919","rc":[{"batb":[[1,1.62,13.83],[2,1.59,5.99]],"ltp":1.26,"tv":1005.28,"id":72857115},{"batb":[[1,1.61,14.05],[2,1.58,7.15]],"ltp":1.5,"tv":2055.32,"id":72857116}]}]}
{"op":"mcm","clk":"11877765012","pt":1724089790077,"mc":[{"id":"1.232018919","rc":[{"batb":[[0,1.62,13.83],[1,1.59,5.99],[2,1.2,250]],"ltp":1.26,"tv":1005.28,"id":72857115},{"batb":[[0,1.61,14.59],[1,1.58,7.15],[2,1.2,250]],"ltp":1.5,"tv":2055.32,"id":72857116}]}]}
{"op":"mcm","clk":"11877765148","pt":1724089791374,"mc":[{"id":"1.232018919","rc":[{"batb":[[0,1.63,10],[1,1.62,13.83],[2,1.59,5.99]],"ltp":1.26,"tv":1005.28,"id":72857115},{"batb":[[0,1.62,10.54],[1,1.61,14.05],[2,1.58,7.15]],"ltp":1.5,"tv":2055.32,"id":72857116}]}]}
{"op":"mcm","clk":"11877765374","pt":1724089793544,"mc":[{"id":"1.232018919","rc":[{"batb":[[0,1.64,4],[1,1.63,10],[2,1.62,13.83]],"ltp":1.26,"tv":1005.28,"id":72857115},{"batb":[[0,1.63,4.54],[1,1.62,10],[2,1.61,14.05]],"ltp":1.5,"tv":2055.32,"id":72857116}]}]}
{"op":"mcm","clk":"11877765506","pt":1724089794680,"mc":[{"id":"1.232018919","rc":[{"batb":[[1,1.62,13.83],[2,1.59,5.99]],"ltp":1.26,"tv":1005.28,"id":72857115},{"batb":[[1,1.61,14.05],[2,1.58,7.15]],"ltp":1.5,"tv":2055.32,"id":72857116}]}]}
{"op":"mcm","clk":"11877765729","pt":1724089796760,"mc":[{"id":"1.232018919","rc":[{"batb":[[0,1.62,13.83],[1,1.59,5.99],[2,1.2,250]],"ltp":1.26,"tv":1005.28,"id":72857115},{"batb":[[0,1.61,14.59],[1,1.58,7.15],[2,1.2,250]],"ltp":1.5,"tv":2055.32,"id":72857116}]}]}
{"op":"mcm","clk":"11877765747","pt":1724089796961,"mc":[{"id":"1.232018919","rc":[{"batb":[[0,1.63,10],[1,1.62,13.83],[2,1.59,5.99]],"ltp":1.26,"tv":1005.28,"id":72857115},{"batb":[[0,1.62,10.54],[1,1.61,14.05],[2,1.58,7.15]],"ltp":1.5,"tv":2055.32,"id":72857116}]}]}
{"op":"mcm","clk":"11877765957","pt":1724089798979,"mc":[{"id":"1.232018919","rc":[{"batb":[[0,1.64,4],[1,1.63,10],[2,1.62,13.83]],"ltp":1.26,"tv":1005.28,"id":72857115},{"batb":[[0,1.63,4.54],[1,1.62,10],[2,1.61,14.05]],"ltp":1.5,"tv":2055.32,"id":72857116}]}]}
{"op":"mcm","clk":"11877766103","pt":1724089800379,"mc":[{"id":"1.232018919","rc":[{"batb":[[1,1.62,13.83],[2,1.59,5.99]],"ltp":1.26,"tv":1005.28,"id":72857115},{"batb":[[1,1.61,14.05],[2,1.58,7.15]],"ltp":1.5,"tv":2055.32,"id":72857116}]}]}
{"op":"mcm","clk":"11877766218","pt":1724089801367,"mc":[{"id":"1.232018919","rc":[{"batb":[[0,1.62,13.83],[1,1.59,5.99],[2,1.2,250]],"ltp":1.26,"tv":1005.28,"id":72857115},{"batb":[[0,1.61,14.59],[1,1.58,7.15],[2,1.2,250]],"ltp":1.5,"tv":2055.32,"id":72857116}]}]}
{"op":"mcm","clk":"11877766367","pt":1724089802695,"mc":[{"id":"1.232018919","rc":[{"batb":[[0,1.63,10],[1,1.62,13.83],[2,1.59,5.99]],"ltp":1.26,"tv":1005.28,"id":72857115},{"batb":[[0,1.62,10.54],[1,1.61,14.05],[2,1.58,7.15]],"ltp":1.5,"tv":2055.32,"id":72857116}]}]}
{"op":"mcm","clk":"11877766569","pt":1724089804268,"mc":[{"id":"1.232018919","rc":[{"batb":[[0,1.64,4],[1,1.63,10],[2,1.62,13.83]],"ltp":1.26,"tv":1005.28,"id":72857115},{"batb":[[0,1.63,4.54],[1,1.62,10],[2,1.61,14.05]],"ltp":1.5,"tv":2055.32,"id":72857116}]}]}
{"op":"mcm","clk":"11877766824","pt":1724089806591,"mc":[{"id":"1.232018919","rc":[{"batb":[[0,1.62,13.83],[1,1.59,5.99],[2,1.2,250]],"ltp":1.26,"tv":1005.28,"id":72857115},{"batb":[[0,1.61,14.59],[1,1.58,7.15],[2,1.2,250]],"ltp":1.5,"tv":2055.32,"id":72857116}]}]}
{"op":"mcm","clk":"11877767213","pt":1724089809912,"mc":[{"id":"1.232018919","rc":[{"batb":[[0,1.63,14],[1,1.62,13.83],[2,1.59,5.99]],"ltp":1.26,"tv":1005.28,"id":72857115},{"batb":[[0,1.62,14.54],[1,1.61,14.05],[2,1.58,7.15]],"ltp":1.5,"tv":2055.32,"id":72857116}]}]}
{"op":"mcm","clk":"11877767534","pt":1724089812611,"mc":[{"id":"1.232018919","rc":[{"batb":[[0,1.63,10]],"ltp":1.26,"tv":1005.28,"id":72857115},{"batb":[[0,1.62,10.54]],"ltp":1.5,"tv":2055.32,"id":72857116}]}]}
{"op":"mcm","clk":"11877767648","pt":1724089813611,"mc":[{"id":"1.232018919","rc":[{"batb":[[0,1.62,13.83],[1,1.59,5.99],[2,1.2,250]],"ltp":1.26,"tv":1005.28,"id":72857115},{"batb":[[0,1.61,14.59],[1,1.58,7.15],[2,1.2,250]],"ltp":1.5,"tv":2055.32,"id":72857116}]}]}
{"op":"mcm","clk":"11877767884","pt":1724089815697,"mc":[{"id":"1.232018919","rc":[{"batb":[[0,1.63,4],[1,1.62,13.83],[2,1.59,5.99]],"ltp":1.26,"tv":1005.28,"id":72857115},{"batb":[[0,1.62,4.54],[1,1.61,14.05],[2,1.58,7.15]],"ltp":1.5,"tv":2055.32,"id":72857116}]}]}
{"op":"mcm","clk":"11877767908","pt":1724089815902,"mc":[{"id":"1.232018919","rc":[{"batb":[[0,1.64,10],[1,1.63,4],[2,1.62,13.83]],"ltp":1.26,"tv":1005.28,"id":72857115},{"batb":[[0,1.63,10.54],[1,1.62,4],[2,1.61,14.05]],"ltp":1.5,"tv":2055.32,"id":72857116}]}]}
{"op":"mcm","clk":"11877768126","pt":1724089818081,"mc":[{"id":"1.232018919","rc":[{"batb":[[1,1.62,13.83],[2,1.59,5.99]],"ltp":1.26,"tv":1005.28,"id":72857115},{"batb":[[1,1.61,14.05],[2,1.58,7.15]],"ltp":1.5,"tv":2055.32,"id":72857116}]}]}
{"op":"mcm","clk":"11877768272","pt":1724089819594,"mc":[{"id":"1.232018919","rc":[{"batb":[[0,1.62,13.83],[1,1.59,5.99],[2,1.2,250]],"ltp":1.26,"tv":1005.28,"id":72857115},{"batb":[[0,1.61,14.59],[1,1.58,7.15],[2,1.2,250]],"ltp":1.5,"tv":2055.32,"id":72857116}]}]}
{"op":"mcm","clk":"11877768651","pt":1724089822938,"mc":[{"id":"1.232018919","rc":[{"batb":[[0,1.63,14],[1,1.62,13.83],[2,1.59,5.99]],"ltp":1.26,"tv":1005.28,"id":72857115},{"batb":[[0,1.62,14.54],[1,1.61,14.05],[2,1.58,7.15]],"ltp":1.5,"tv":2055.32,"id":72857116}]}]}
{"op":"mcm","clk":"11877768934","pt":1724089825406,"mc":[{"id":"1.232018919","rc":[{"batb":[[0,1.63,10]],"ltp":1.26,"tv":1005.28,"id":72857115},{"batb":[[0,1.62,10.54]],"ltp":1.5,"tv":2055.32,"id":72857116}]}]}
{"op":"mcm","clk":"11877769049","pt":1724089826429,"mc":[{"id":"1.232018919","rc":[{"batb":[[0,1.62,13.83],[1,1.59,5.99],[2,1.2,250]],"ltp":1.26,"tv":1005.28,"id":72857115},{"batb":[[0,1.61,14.59],[1,1.58,7.15],[2,1.2,250]],"ltp":1.5,"tv":2055.32,"id":72857116}]}]}
{"op":"mcm","clk":"11877769270","pt":1724089828724,"mc":[{"id":"1.232018919","rc":[{"batb":[[0,1.63,14],[1,1.62,13.83],[2,1.59,5.99]],"ltp":1.26,"tv":1005.28,"id":72857115},{"batb":[[0,1.62,14.54],[1,1.61,14.05],[2,1.58,7.15]],"ltp":1.5,"tv":2055.32,"id":72857116}]}]}
{"op":"mcm","clk":"11877769572","pt":1724089831317,"mc":[{"id":"1.232018919","rc":[{"batb":[[0,1.63,10]],"ltp":1.26,"tv":1005.28,"id":72857115},{"batb":[[0,1.62,10.54]],"ltp":1.5,"tv":2055.32,"id":72857116}]}]}
{"op":"mcm","clk":"11877769655","pt":1724089832319,"mc":[{"id":"1.232018919","rc":[{"batb":[[0,1.62,13.83],[1,1.59,5.99],[2,1.2,250]],"ltp":1.26,"tv":1005.28,"id":72857115},{"batb":[[0,1.61,14.59],[1,1.58,7.15],[2,1.2,250]],"ltp":1.5,"tv":2055.32,"id":72857116}]}]}
{"op":"mcm","clk":"11877769879","pt":1724089834518,"mc":[{"id":"1.232018919","rc":[{"batb":[[0,1.64,10],[1,1.63,4],[2,1.62,13.83]],"ltp":1.26,"tv":1005.28,"id":72857115},{"batb":[[0,1.63,10.54],[1,1.62,4],[2,1.61,14.05]],"ltp":1.5,"tv":2055.32,"id":72857116}]}]}
{"op":"mcm","clk":"11877770111","pt":1724089836633,"mc":[{"id":"1.232018919","rc":[{"batb":[[1,1.62,13.83],[2,1.59,5.99]],"ltp":1.26,"tv":1005.28,"id":72857115},{"batb":[[1,1.61,14.05],[2,1.58,7.15]],"ltp":1.5,"tv":2055.32,"id":72857116}]}]}
{"op":"mcm","clk":"11877770218","pt":1724089837824,"mc":[{"id":"1.232018919","rc":[{"batb":[[0,1.62,13.83],[1,1.59,5.99],[2,1.2,250]],"ltp":1.26,"tv":1005.28,"id":72857115},{"batb":[[0,1.61,14.59],[1,1.58,7.15],[2,1.2,250]],"ltp":1.5,"tv":2055.32,"id":72857116}]}]}
{"op":"mcm","clk":"11877770524","pt":1724089840737,"mc":[{"id":"1.232018919","rc":[{"batb":[[0,1.63,14],[1,1.62,13.83],[2,1.59,5.99]],"ltp":1.26,"tv":1005.28,"id":72857115},{"batb":[[0,1.62,14.54],[1,1.61,14.05],[2,1.58,7.15]],"ltp":1.5,"tv":2055.32,"id":72857116}]}]}
{"op":"mcm","clk":"11877770771","pt":1724089842926,"mc":[{"id":"1.232018919","rc":[{"batb":[[0,1.63,10]],"ltp":1.26,"tv":1005.28,"id":72857115},{"batb":[[0,1.62,10.54]],"ltp":1.5,"tv":2055.32,"id":72857116}]}]}
{"op":"mcm","clk":"11877770915","pt":1724089844132,"mc":[{"id":"1.232018919","rc":[{"batb":[[0,1.62,13.83],[1,1.59,5.99],[2,1.2,250]],"ltp":1.26,"tv":1005.28,"id":72857115},{"batb":[[0,1.61,14.59],[1,1.58,7.15],[2,1.2,250]],"ltp":1.5,"tv":2055.32,"id":72857116}]}]}
{"op":"mcm","clk":"11877771261","pt":1724089847237,"mc":[{"id":"1.232018919","rc":[{"batb":[[0,1.63,14],[1,1.62,13.83],[2,1.59,5.99]],"ltp":1.26,"tv":1005.28,"id":72857115},{"batb":[[0,1.62,14.54],[1,1.61,14.05],[2,1.58,7.15]],"ltp":1.5,"tv":2055.32,"id":72857116}]}]}
{"op":"mcm","clk":"11877771532","pt":1724089849628,"mc":[{"id":"1.232018919","rc":[{"batb":[[0,1.63,10]],"ltp":1.26,"tv":1005.28,"id":72857115},{"batb":[[0,1.62,10.54]],"ltp":1.5,"tv":2055.32,"id":72857116}]}]}
{"op":"mcm","clk":"11877771647","pt":1724089850614,"mc":[{"id":"1.232018919","rc":[{"batb":[[0,1.62,13.83],[1,1.59,5.99],[2,1.2,250]],"ltp":1.26,"tv":1005.28,"id":72857115},{"batb":[[0,1.61,14.59],[1,1.58,7.15],[2,1.2,250]],"ltp":1.5,"tv":2055.32,"id":72857116}]}]}
{"op":"mcm","clk":"11877771785","pt":1724089851911,"mc":[{"id":"1.232018919","rc":[{"batb":[[0,1.63,4],[1,1.62,13.83],[2,1.59,5.99]],"ltp":1.26,"tv":1005.28,"id":72857115},{"batb":[[0,1.62,4.54],[1,1.61,14.05],[2,1.58,7.15]],"ltp":1.5,"tv":2055.32,"id":72857116}]}]}
{"op":"mcm","clk":"11877772069","pt":1724089854713,"mc":[{"id":"1.232018919","rc":[{"batb":[[0,1.63,10]],"ltp":1.26,"tv":1005.28,"id":72857115},{"batb":[[0,1.62,10.54]],"ltp":1.5,"tv":2055.32,"id":72857116}]}]}
{"op":"mcm","clk":"11877772289","pt":1724089856842,"mc":[{"id":"1.232018919","rc":[{"batb":[[0,1.64,4],[1,1.63,10],[2,1.62,13.83]],"ltp":1.26,"tv":1005.28,"id":72857115},{"batb":[[0,1.63,4.54],[1,1.62,10],[2,1.61,14.05]],"ltp":1.5,"tv":2055.32,"id":72857116}]}]}
{"op":"mcm","clk":"11877772469","pt":1724089858251,"mc":[{"id":"1.232018919","rc":[{"batb":[[1,1.62,13.83],[2,1.59,5.99]],"ltp":1.26,"tv":1005.28,"id":72857115},{"batb":[[1,1.61,14.05],[2,1.58,7.15]],"ltp":1.5,"tv":2055.32,"id":72857116}]}]}
{"op":"mcm","clk":"11877772581","pt":1724089859330,"mc":[{"id":"1.232018919","rc":[{"batb":[[0,1.62,13.83],[1,1.59,5.99],[2,1.2,250]],"ltp":1.26,"tv":1005.28,"id":72857115},{"batb":[[0,1.61,14.59],[1,1.58,7.15],[2,1.2,250]],"ltp":1.5,"tv":2055.32,"id":72857116}]}]}
{"op":"mcm","clk":"11877773336","pt":1724089865370,"mc":[{"id":"1.232018919","rc":[{"batb":[[0,1.63,14],[1,1.62,13.83],[2,1.59,5.99]],"ltp":1.26,"tv":1005.28,"id":72857115},{"batb":[[0,1.62,14.54],[1,1.61,14.05],[2,1.58,7.15]],"ltp":1.5,"tv":2055.32,"id":72857116}]}]}
{"op":"mcm","clk":"11877773593","pt":1724089867975,"mc":[{"id":"1.232018919","rc":[{"batb":[[0,1.63,10]],"ltp":1.26,"tv":1005.28,"id":72857115},{"batb":[[0,1.62,10.54]],"ltp":1.5,"tv":2055.32,"id":72857116}]}]}
{"op":"mcm","clk":"11877773703","pt":1724089868900,"mc":[{"id":"1.232018919","rc":[{"batb":[[0,1.62,13.83],[1,1.59,5.99],[2,1.2,250]],"ltp":1.26,"tv":1005.28,"id":72857115},{"batb":[[0,1.61,14.59],[1,1.58,7.15],[2,1.2,250]],"ltp":1.5,"tv":2055.32,"id":72857116}]}]}
{"op":"mcm","clk":"11877773976","pt":1724089870491,"mc":[{"id":"1.232018919","rc":[{"batb":[[0,1.63,4],[1,1.62,13.83],[2,1.59,5.99]],"ltp":1.26,"tv":1005.28,"id":72857115},{"batb":[[0,1.62,4.54],[1,1.61,14.05],[2,1.58,7.15]],"ltp":1.5,"tv":2055.32,"id":72857116}]}]}
{"op":"mcm","clk":"11877774374","pt":1724089872780,"mc":[{"id":"1.232018919","rc":[{"batb":[[0,1.62,13.83],[1,1.59,5.99],[2,1.2,250]],"ltp":1.26,"tv":1005.28,"id":72857115},{"batb":[[0,1.61,14.59],[1,1.58,7.15],[2,1.2,250]],"ltp":1.5,"tv":2055.32,"id":72857116}]}]}
{"op":"mcm","clk":"11877774408","pt":1724089872984,"mc":[{"id":"1.232018919","rc":[{"batb":[[0,1.63,10],[1,1.62,13.83],[2,1.59,5.99]],"ltp":1.26,"tv":1005.28,"id":72857115},{"batb":[[0,1.62,10.54],[1,1.61,14.05],[2,1.58,7.15]],"ltp":1.5,"tv":2055.32,"id":72857116}]}]}
{"op":"mcm","clk":"11877774852","pt":1724089876485,"mc":[{"id":"1.232018919","rc":[{"batb":[[0,1.63,4]],"ltp":1.26,"tv":1005.28,"id":72857115},{"batb":[[0,1.62,4.54]],"ltp":1.5,"tv":2055.32,"id":72857116}]}]}
{"op":"mcm","clk":"11877775157","pt":1724089878674,"mc":[{"id":"1.232018919","rc":[{"batb":[[0,1.62,13.83],[1,1.59,5.99],[2,1.2,250]],"ltp":1.26,"tv":1005.28,"id":72857115},{"batb":[[0,1.61,14.59],[1,1.58,7.15],[2,1.2,250]],"ltp":1.5,"tv":2055.32,"id":72857116}]}]}
{"op":"mcm","clk":"11877775209","pt":1724089879188,"mc":[{"id":"1.232018919","rc":[{"batb":[[0,1.63,10],[1,1.62,13.83],[2,1.59,5.99]],"ltp":1.26,"tv":1005.28,"id":72857115},{"batb":[[0,1.62,10.54],[1,1.61,14.05],[2,1.58,7.15]],"ltp":1.5,"tv":2055.32,"id":72857116}]}]}
{"op":"mcm","clk":"11877775640","pt":1724089882684,"mc":[{"id":"1.232018919","rc":[{"batb":[[0,1.63,4]],"ltp":1.26,"tv":1005.28,"id":72857115},{"batb":[[0,1.62,4.54]],"ltp":1.5,"tv":2055.32,"id":72857116}]}]}
{"op":"mcm","clk":"11877775955","pt":1724089885182,"mc":[{"id":"1.232018919","rc":[{"batb":[[0,1.63,10]],"ltp":1.26,"tv":1005.28,"id":72857115},{"batb":[[0,1.62,10.54]],"ltp":1.5,"tv":2055.32,"id":72857116}]}]}
{"op":"mcm","clk":"11877776218","pt":1724089887770,"mc":[{"id":"1.232018919","rc":[{"trd":[[2.44,0.37]],"batb":[[0,2.54,2.05],[1,1.63,10],[2,1.62,13.83]],"ltp":2.44,"tv":1005.66,"id":72857115},{"trd":[[1.7,0.54]],"batb":[[0,1.62,10]],"ltp":1.7,"tv":2055.85,"id":72857116}],"tv":3061.52}]}
{"op":"mcm","clk":"11877776306","pt":1724089888503,"mc":[{"id":"1.232018919","rc":[{"batb":[[0,2.56,4],[1,2.54,2.05]],"ltp":2.44,"tv":1005.66,"id":72857115},{"batb":[[0,1.63,4]],"ltp":1.7,"tv":2055.85,"id":72857116}]}]}
{"op":"mcm","clk":"11877776542","pt":1724089890395,"mc":[{"id":"1.232018919","rc":[{"batb":[[0,2.54,2.05],[1,1.62,13.83],[2,1.59,5.99]],"ltp":2.44,"tv":1005.66,"id":72857115},{"batb":[[0,1.61,14.05],[1,1.58,7.15],[2,1.2,250]],"ltp":1.7,"tv":2055.85,"id":72857116}]}]}
{"op":"mcm","clk":"11877776674","pt":1724089891618,"mc":[{"id":"1.232018919","rc":[{"batb":[[0,1.62,10],[1,1.61,14.05],[2,1.58,7.15]],"ltp":1.7,"tv":2055.85,"id":72857116}]}]}
{"op":"mcm","clk":"11877776857","pt":1724089893299,"mc":[{"id":"1.232018919","rc":[{"batb":[[0,2.58,10],[1,2.56,4],[2,2.54,2.05]],"ltp":2.44,"tv":1005.66,"id":72857115},{"batb":[[0,1.63,8],[1,1.62,14],[2,1.61,14.05]],"ltp":1.7,"tv":2055.85,"id":72857116}]}]}
{"op":"mcm","clk":"11877777135","pt":1724089895701,"mc":[{"id":"1.232018919","rc":[{"batb":[[1,2.54,2.05],[2,1.62,13.83]],"ltp":2.44,"tv":1005.66,"id":72857115},{"batb":[[0,1.62,4],[1,1.61,14.05],[2,1.58,7.15]],"ltp":1.7,"tv":2055.85,"id":72857116}]}]}
{"op":"mcm","clk":"11877777271","pt":1724089896594,"mc":[{"id":"1.232018919","rc":[{"batb":[[0,2.54,2.05],[1,1.62,13.83],[2,1.59,5.99]],"ltp":2.44,"tv":1005.66,"id":72857115}]}]}
{"op":"mcm","clk":"11877777509","pt":1724089898614,"mc":[{"id":"1.232018919","rc":[{"trd":[[2.54,6.05]],"batb":[[0,1.62,13.83],[1,1.59,5.99],[2,1.2,250]],"ltp":2.54,"tv":1011.71,"id":72857115},{"trd":[[1.65,9.31]],"batb":[[0,1.65,4.69],[1,1.64,17.91],[2,1.62,4]],"ltp":1.65,"tv":2065.16,"id":72857116}],"tv":3076.87}]}
{"op":"mcm","clk":"11877777535","pt":1724089898825,"mc":[{"id":"1.232018919","rc":[{"batb":[[0,1.63,10],[1,1.62,13.83],[2,1.59,5.99]],"ltp":2.54,"tv":1011.71,"id":72857115}]}]}
{"op":"mcm","clk":"11877777805","pt":1724089900999,"mc":[{"id":"1.232018919","rc":[{"batb":[[0,1.64,4],[1,1.63,10],[2,1.62,13.83]],"ltp":2.54,"tv":1011.71,"id":72857115},{"batb":[[0,1.64,18.6],[1,1.62,4],[2,1.61,14.05]],"ltp":1.65,"tv":2065.16,"id":72857116}]}]}
{"op":"mcm","clk":"11877777929","pt":1724089902198,"mc":[{"id":"1.232018919","rc":[{"batb":[[1,1.62,13.83],[2,1.59,5.99]],"ltp":2.54,"tv":1011.71,"id":72857115},{"batb":[[0,1.64,17.91]],"ltp":1.65,"tv":2065.16,"id":72857116}]}]}
{"op":"mcm","clk":"11877778111","pt":1724089903712,"mc":[{"id":"1.232018919","rc":[{"batb":[[0,1.62,13.83],[1,1.59,5.99],[2,1.2,250]],"ltp":2.54,"tv":1011.71,"id":72857115},{"batb":[[0,1.65,4],[1,1.64,17.91]],"ltp":1.65,"tv":2065.16,"id":72857116}]}]}
{"op":"mcm","clk":"11877778222","pt":1724089904532,"mc":[{"id":"1.232018919","rc":[{"batb":[[0,1.63,10],[1,1.62,13.83],[2,1.59,5.99]],"ltp":2.54,"tv":1011.71,"id":72857115},{"batb":[[0,1.66,10],[1,1.65,4],[2,1.64,17.91]],"ltp":1.65,"tv":2065.16,"id":72857116}]}]}
{"op":"mcm","clk":"11877778381","pt":1724089906350,"mc":[{"id":"1.232018919","rc":[{"batb":[[0,1.64,4],[1,1.63,10],[2,1.62,13.83]],"ltp":2.54,"tv":1011.71,"id":72857115},{"batb":[[1,1.64,17.91],[2,1.61,14.05]],"ltp":1.65,"tv":2065.16,"id":72857116}]}]}
{"op":"mcm","clk":"11877778541","pt":1724089907701,"mc":[{"id":"1.232018919","rc":[{"batb":[[1,1.62,13.83],[2,1.59,5.99]],"ltp":2.54,"tv":1011.71,"id":72857115},{"batb":[[0,1.64,17.91],[1,1.61,14.05],[2,1.58,7.15]],"ltp":1.65,"tv":2065.16,"id":72857116}]}]}
{"op":"mcm","clk":"11877778686","pt":1724089909006,"mc":[{"id":"1.232018919","rc":[{"batb":[[0,1.62,13.83],[1,1.59,5.99],[2,1.2,250]],"ltp":2.54,"tv":1011.71,"id":72857115},{"batb":[[0,1.65,4],[1,1.64,17.91],[2,1.61,14.05]],"ltp":1.65,"tv":2065.16,"id":72857116}]}]}
{"op":"mcm","clk":"11877778827","pt":1724089910217,"mc":[{"id":"1.232018919","rc":[{"batb":[[0,1.63,10],[1,1.62,13.83],[2,1.59,5.99]],"ltp":2.54,"tv":1011.71,"id":72857115},{"batb":[[0,1.66,10],[1,1.65,4],[2,1.64,17.91]],"ltp":1.65,"tv":2065.16,"id":72857116}]}]}
{"op":"mcm","clk":"11877778964","pt":1724089911416,"mc":[{"id":"1.232018919","rc":[{"batb":[[0,1.64,4],[1,1.63,10],[2,1.62,13.83]],"ltp":2.54,"tv":1011.71,"id":72857115},{"batb":[[1,1.64,17.91],[2,1.61,14.05]],"ltp":1.65,"tv":2065.16,"id":72857116}]}]}
{"op":"mcm","clk":"11877779192","pt":1724089913733,"mc":[{"id":"1.232018919","rc":[{"batb":[[0,1.62,13.83],[1,1.59,5.99],[2,1.2,250]],"ltp":2.54,"tv":1011.71,"id":72857115},{"batb":[[0,1.65,4]],"ltp":1.65,"tv":2065.16,"id":72857116}]}]}
{"op":"mcm","clk":"11877779310","pt":1724089914614,"mc":[{"id":"1.232018919","rc":[{"batb":[[1,1.61,14.05],[2,1.58,7.15]],"ltp":1.65,"tv":2065.16,"id":72857116}]}]}
{"op":"mcm","clk":"11877779466","pt":1724089916226,"mc":[{"id":"1.232018919","rc":[{"batb":[[0,1.63,14],[1,1.62,13.83],[2,1.59,5.99]],"ltp":2.54,"tv":1011.71,"id":72857115},{"batb":[[0,1.62,10]],"ltp":1.65,"tv":2065.16,"id":72857116}]}]}
{"op":"mcm","clk":"11877779705","pt":1724089918634,"mc":[{"id":"1.232018919","rc":[{"batb":[[0,1.63,10]],"ltp":2.54,"tv":1011.71,"id":72857115},{"batb":[[0,1.63,4],[1,1.62,10],[2,1.61,14.05]],"ltp":1.65,"tv":2065.16,"id":72857116}]}]}
{"op":"mcm","clk":"11877779811","pt":1724089919630,"mc":[{"id":"1.232018919","rc":[{"batb":[[0,1.62,13.83],[1,1.59,5.99],[2,1.2,250]],"ltp":2.54,"tv":1011.71,"id":72857115},{"batb":[[1,1.61,14.05],[2,1.58,7.15]],"ltp":1.65,"tv":2065.16,"id":72857116}]}]}
{"op":"mcm","clk":"11877779993","pt":1724089921142,"mc":[{"id":"1.232018919","rc":[{"batb":[[0,1.63,4],[1,1.62,13.83],[2,1.59,5.99]],"ltp":2.54,"tv":1011.71,"id":72857115},{"batb":[[0,1.61,14.05],[1,1.58,7.15],[2,1.2,250]],"ltp":1.65,"tv":2065.16,"id":72857116}]}]}
{"op":"mcm","clk":"11877780132","pt":1724089922450,"mc":[{"id":"1.232018919","rc":[{"batb":[[0,1.64,10],[1,1.63,4],[2,1.62,13.83]],"ltp":2.54,"tv":1011.71,"id":72857115},{"batb":[[0,1.62,10],[1,1.61,14.05],[2,1.58,7.15]],"ltp":1.65,"tv":2065.16,"id":72857116}]}]}
{"op":"mcm","clk":"11877780254","pt":1724089923546,"mc":[{"id":"1.232018919","rc":[{"batb":[[1,1.62,13.83],[2,1.59,5.99]],"ltp":2.54,"tv":1011.71,"id":72857115},{"batb":[[0,1.63,4],[1,1.62,10],[2,1.61,14.05]],"ltp":1.65,"tv":2065.16,"id":72857116}]}]}
{"op":"mcm","clk":"11877780458","pt":1724089925646,"mc":[{"id":"1.232018919","rc":[{"batb":[[0,1.62,13.83],[1,1.59,5.99],[2,1.2,250]],"ltp":2.54,"tv":1011.71,"id":72857115},{"batb":[[1,1.61,14.05],[2,1.58,7.15]],"ltp":1.65,"tv":2065.16,"id":72857116}]}]}
{"op":"mcm","clk":"11877780479","pt":1724089925854,"mc":[{"id":"1.232018919","rc":[{"batb":[[0,1.63,4],[1,1.62,13.83],[2,1.59,5.99]],"ltp":2.54,"tv":1011.71,"id":72857115},{"batb":[[0,1.61,14.05],[1,1.58,7.15],[2,1.2,250]],"ltp":1.65,"tv":2065.16,"id":72857116}]}]}
{"op":"mcm","clk":"11877780717","pt":1724089928250,"mc":[{"id":"1.232018919","rc":[{"batb":[[0,1.64,10]],"ltp":2.54,"tv":1011.71,"id":72857115},{"batb":[[0,1.62,14],[1,1.61,14.05],[2,1.58,7.15]],"ltp":1.65,"tv":2065.16,"id":72857116}]}]}
{"op":"mcm","clk":"11877780944","pt":1724089930433,"mc":[{"id":"1.232018919","rc":[{"batb":[[0,1.65,4],[1,1.64,10],[2,1.62,13.83]],"ltp":2.54,"tv":1011.71,"id":72857115},{"batb":[[0,1.62,10]],"ltp":1.65,"tv":2065.16,"id":72857116}]}]}
{"op":"mcm","clk":"11877781045","pt":1724089931357,"mc":[{"id":"1.232018919","rc":[{"batb":[[1,1.62,13.83],[2,1.59,5.99]],"ltp":2.54,"tv":1011.71,"id":72857115},{"batb":[[0,1.61,14.05],[1,1.58,7.15],[2,1.2,250]],"ltp":1.65,"tv":2065.16,"id":72857116}]}]}
{"op":"mcm","clk":"11877781216","pt":1724089932755,"mc":[{"id":"1.232018919","rc":[{"batb":[[0,1.62,13.83],[1,1.59,5.99],[2,1.2,250]],"ltp":2.54,"tv":1011.71,"id":72857115},{"batb":[[0,1.62,4],[1,1.61,14.05],[2,1.58,7.15]],"ltp":1.65,"tv":2065.16,"id":72857116}]}]}
{"op":"mcm","clk":"11877781410","pt":1724089934465,"mc":[{"id":"1.232018919","rc":[{"batb":[[0,1.63,10.54],[1,1.62,13.83],[2,1.59,5.99]],"ltp":2.54,"tv":1011.71,"id":72857115},{"batb":[[0,1.63,10],[1,1.62,4],[2,1.61,14.05]],"ltp":1.65,"tv":2065.16,"id":72857116}]}]}
{"op":"mcm","clk":"11877781491","pt":1724089935252,"mc":[{"id":"1.232018919","rc":[{"batb":[[0,1.64,4.54],[1,1.63,10],[2,1.62,13.83]],"ltp":2.54,"tv":1011.71,"id":72857115},{"batb":[[1,1.61,14.05],[2,1.58,7.15]],"ltp":1.65,"tv":2065.16,"id":72857116}]}]}
{"op":"mcm","clk":"11877781725","pt":1724089937371,"mc":[{"id":"1.232018919","rc":[{"batb":[[0,1.62,14.36],[1,1.59,5.99],[2,1.2,250]],"ltp":2.54,"tv":1011.71,"id":72857115},{"batb":[[0,1.62,4]],"ltp":1.65,"tv":2065.16,"id":72857116}]}]}
{"op":"mcm","clk":"11877781968","pt":1724089939767,"mc":[{"id":"1.232018919","rc":[{"batb":[[0,1.63,14.54],[1,1.62,13.83],[2,1.59,5.99]],"ltp":2.54,"tv":1011.71,"id":72857115},{"batb":[[0,1.63,10]],"ltp":1.65,"tv":2065.16,"id":72857116}]}]}
{"op":"mcm","clk":"11877782247","pt":1724089942259,"mc":[{"id":"1.232018919","rc":[{"batb":[[0,1.63,10.54]],"ltp":2.54,"tv":1011.71,"id":72857115},{"batb":[[0,1.64,4],[1,1.63,10],[2,1.61,14.05]],"ltp":1.65,"tv":2065.16,"id":72857116}]}]}
{"op":"mcm","clk":"11877782316","pt":1724089942982,"mc":[{"id":"1.232018919","rc":[{"batb":[[0,1.62,14.36],[1,1.59,5.99],[2,1.2,250]],"ltp":2.54,"tv":1011.71,"id":72857115},{"batb":[[1,1.61,14.05],[2,1.58,7.15]],"ltp":1.65,"tv":2065.16,"id":72857116}]}]}
{"op":"mcm","clk":"11877782530","pt":1724089944693,"mc":[{"id":"1.232018919","rc":[{"batb":[[0,1.61,14.05],[1,1.58,7.15],[2,1.2,250]],"ltp":1.65,"tv":2065.16,"id":72857116}]}]}
{"op":"mcm","clk":"11877782596","pt":1724089945166,"mc":[{"id":"1.232018919","rc":[{"batb":[[0,1.64,10.54],[1,1.63,4],[2,1.62,13.83]],"ltp":2.54,"tv":1011.71,"id":72857115},{"batb":[[0,1.62,10],[1,1.61,14.05],[2,1.58,7.15]],"ltp":1.65,"tv":2065.16,"id":72857116}]}]}
{"op":"mcm","clk":"11877782841","pt":1724089947320,"mc":[{"id":"1.232018919","rc":[{"batb":[[1,1.62,13.83],[2,1.59,5.99]],"ltp":2.54,"tv":1011.71,"id":72857115},{"batb":[[0,1.63,4],[1,1.62,10],[2,1.61,14.05]],"ltp":1.65,"tv":2065.16,"id":72857116}]}]}
{"op":"mcm","clk":"11877782983","pt":1724089948673,"mc":[{"id":"1.232018919","rc":[{"batb":[[0,1.62,14.36],[1,1.59,5.99],[2,1.2,250]],"ltp":2.54,"tv":1011.71,"id":72857115},{"batb":[[1,1.61,14.05],[2,1.58,7.15]],"ltp":1.65,"tv":2065.16,"id":72857116}]}]}
{"op":"mcm","clk":"11877783112","pt":1724089949808,"mc":[{"id":"1.232018919","rc":[{"batb":[[0,1.63,4.54],[1,1.62,13.83],[2,1.59,5.99]],"ltp":2.54,"tv":1011.71,"id":72857115},{"batb":[[0,1.61,14.05],[1,1.58,7.15],[2,1.2,250]],"ltp":1.65,"tv":2065.16,"id":72857116}]}]}
{"op":"mcm","clk":"11877783303","pt":1724089951579,"mc":[{"id":"1.232018919","rc":[{"batb":[[0,1.64,10.54],[1,1.63,4],[2,1.62,13.83]],"ltp":2.54,"tv":1011.71,"id":72857115},{"batb":[[0,1.62,10],[1,1.61,14.05],[2,1.58,7.15]],"ltp":1.65,"tv":2065.16,"id":72857116}]}]}
{"op":"mcm","clk":"11877783370","pt":1724089952078,"mc":[{"id":"1.232018919","rc":[{"batb":[[1,1.62,13.83],[2,1.59,5.99]],"ltp":2.54,"tv":1011.71,"id":72857115},{"batb":[[0,1.63,4],[1,1.62,10],[2,1.61,14.05]],"ltp":1.65,"tv":2065.16,"id":72857116}]}]}
{"op":"mcm","clk":"11877783589","pt":1724089954409,"mc":[{"id":"1.232018919","rc":[{"batb":[[0,1.65,4.54],[1,1.64,10],[2,1.62,13.83]],"ltp":2.54,"tv":1011.71,"id":72857115},{"batb":[[0,1.62,10],[1,1.61,14.05],[2,1.58,7.15]],"ltp":1.65,"tv":2065.16,"id":72857116}]}]}
{"op":"mcm","clk":"11877783650","pt":1724089954879,"mc":[{"id":"1.232018919","rc":[{"batb":[[1,1.62,13.83],[2,1.59,5.99]],"ltp":2.54,"tv":1011.71,"id":72857115},{"batb":[[0,1.61,14.05],[1,1.58,7.15],[2,1.2,250]],"ltp":1.65,"tv":2065.16,"id":72857116}]}]}
{"op":"mcm","clk":"11877783851","pt":1724089956696,"mc":[{"id":"1.232018919","rc":[{"batb":[[0,1.62,14.36],[1,1.59,5.99],[2,1.2,250]],"ltp":2.54,"tv":1011.71,"id":72857115}]}]}
{"op":"mcm","clk":"11877783876","pt":1724089956901,"mc":[{"id":"1.232018919","rc":[{"batb":[[0,1.62,4],[1,1.61,14.05],[2,1.58,7.15]],"ltp":1.65,"tv":2065.16,"id":72857116}]}]}
{"op":"mcm","clk":"11877784026","pt":1724089958518,"mc":[{"id":"1.232018919","rc":[{"batb":[[0,1.63,10.54],[1,1.62,13.83],[2,1.59,5.99]],"ltp":2.54,"tv":1011.71,"id":72857115},{"batb":[[0,1.63,10],[1,1.62,4],[2,1.61,14.05]],"ltp":1.65,"tv":2065.16,"id":72857116}]}]}
{"op":"mcm","clk":"11877784104","pt":1724089959404,"mc":[{"id":"1.232018919","rc":[{"batb":[[0,1.64,4.54],[1,1.63,10],[2,1.62,13.83]],"ltp":2.54,"tv":1011.71,"id":72857115},{"batb":[[1,1.61,14.05],[2,1.58,7.15]],"ltp":1.65,"tv":2065.16,"id":72857116}]}]}
{"op":"mcm","clk":"11877784374","pt":1724089961797,"mc":[{"id":"1.232018919","rc":[{"batb":[[0,1.62,14.36],[1,1.59,5.99],[2,1.2,250]],"ltp":2.54,"tv":1011.71,"id":72857115},{"batb":[[0,1.64,4]],"ltp":1.65,"tv":2065.16,"id":72857116}]}]}
{"op":"mcm","clk":"11877784640","pt":1724089964111,"mc":[{"id":"1.232018919","rc":[{"batb":[[0,1.63,14.54],[1,1.62,13.83],[2,1.59,5.99]],"ltp":2.54,"tv":1011.71,"id":72857115},{"batb":[[0,1.62,10]],"ltp":1.65,"tv":2065.16,"id":72857116}]}]}
{"op":"mcm","clk":"11877784921","pt":1724089966796,"mc":[{"id":"1.232018919","rc":[{"batb":[[0,1.63,10.54]],"ltp":2.54,"tv":1011.71,"id":72857115},{"batb":[[0,1.63,4],[1,1.62,10],[2,1.61,14.05]],"ltp":1.65,"tv":2065.16,"id":72857116}]}]}
{"op":"mcm","clk":"11877784995","pt":1724089967526,"mc":[{"id":"1.232018919","rc":[{"batb":[[0,1.62,14.36],[1,1.59,5.99],[2,1.2,250]],"ltp":2.54,"tv":1011.71,"id":72857115},{"batb":[[1,1.61,14.05],[2,1.58,7.15]],"ltp":1.65,"tv":2065.16,"id":72857116}]}]}
{"op":"mcm","clk":"11877785146","pt":1724089968724,"mc":[{"id":"1.232018919","rc":[{"batb":[[0,1.63,4.54],[1,1.62,13.83],[2,1.59,5.99]],"ltp":2.54,"tv":1011.71,"id":72857115}]}]}
{"op":"mcm","clk":"11877785198","pt":1724089969196,"mc":[{"id":"1.232018919","rc":[{"batb":[[0,1.61,14.05],[1,1.58,7.15],[2,1.2,250]],"ltp":1.65,"tv":2065.16,"id":72857116}]}]}
{"op":"mcm","clk":"11877785336","pt":1724089970287,"mc":[{"id":"1.232018919","rc":[{"batb":[[0,1.64,10.54],[1,1.63,4],[2,1.62,13.83]],"ltp":2.54,"tv":1011.71,"id":72857115},{"batb":[[0,1.62,10],[1,1.61,14.05],[2,1.58,7.15]],"ltp":1.65,"tv":2065.16,"id":72857116}]}]}
{"op":"mcm","clk":"11877785467","pt":1724089971392,"mc":[{"id":"1.232018919","rc":[{"batb":[[1,1.62,13.83],[2,1.59,5.99]],"ltp":2.54,"tv":1011.71,"id":72857115},{"batb":[[0,1.63,4],[1,1.62,10],[2,1.61,14.05]],"ltp":1.65,"tv":2065.16,"id":72857116}]}]}
{"op":"mcm","clk":"11877785743","pt":1724089973688,"mc":[{"id":"1.232018919","rc":[{"batb":[[0,1.65,4.54]],"ltp":2.54,"tv":1011.71,"id":72857115},{"batb":[[0,1.61,14.05],[1,1.58,7.15],[2,1.2,250]],"ltp":1.65,"tv":2065.16,"id":72857116}]}]}
{"op":"mcm","clk":"11877786013","pt":1724089976160,"mc":[{"id":"1.232018919","rc":[{"batb":[[0,1.66,10.54]],"ltp":2.54,"tv":1011.71,"id":72857115},{"batb":[[0,1.62,14],[1,1.61,14.05],[2,1.58,7.15]],"ltp":1.65,"tv":2065.16,"id":72857116}]}]}
{"op":"mcm","clk":"11877786275","pt":1724089978507,"mc":[{"id":"1.232018919","rc":[{"batb":[[0,1.67,4.54],[1,1.66,10],[2,1.62,13.83]],"ltp":2.54,"tv":1011.71,"id":72857115},{"batb":[[0,1.62,10]],"ltp":1.65,"tv":2065.16,"id":72857116}]}]}
{"op":"mcm","clk":"11877786410","pt":1724089979707,"mc":[{"id":"1.232018919","rc":[{"batb":[[1,1.62,13.83],[2,1.59,5.99]],"ltp":2.54,"tv":1011.71,"id":72857115},{"batb":[[0,1.61,14.05],[1,1.58,7.15],[2,1.2,250]],"ltp":1.65,"tv":2065.16,"id":72857116}]}]}
{"op":"mcm","clk":"11877786515","pt":1724089980713,"mc":[{"id":"1.232018919","rc":[{"batb":[[0,1.62,14.36],[1,1.59,5.99],[2,1.2,250]],"ltp":2.54,"tv":1011.71,"id":72857115}]}]}
{"op":"mcm","clk":"11877786532","pt":1724089980913,"mc":[{"id":"1.232018919","rc":[{"batb":[[0,1.62,4],[1,1.61,14.05],[2,1.58,7.15]],"ltp":1.65,"tv":2065.16,"id":72857116}]}]}
{"op":"mcm","clk":"11877786725","pt":1724089982719,"mc":[{"id":"1.232018919","rc":[{"batb":[[0,1.63,10.54],[1,1.62,13.83],[2,1.59,5.99]],"ltp":2.54,"tv":1011.71,"id":72857115},{"batb":[[0,1.63,10],[1,1.62,4],[2,1.61,14.05]],"ltp":1.65,"tv":2065.16,"id":72857116}]}]}
{"op":"mcm","clk":"11877786843","pt":1724089983647,"mc":[{"id":"1.232018919","rc":[{"batb":[[0,1.64,4.54],[1,1.63,10],[2,1.62,13.83]],"ltp":2.54,"tv":1011.71,"id":72857115},{"batb":[[1,1.61,14.05],[2,1.58,7.15]],"ltp":1.65,"tv":2065.16,"id":72857116}]}]}
{"op":"mcm","clk":"11877787057","pt":1724089985548,"mc":[{"id":"1.232018919","rc":[{"batb":[[0,1.63,10.54],[1,1.62,13.83],[2,1.59,5.99]],"ltp":2.54,"tv":1011.71,"id":72857115}]}]}
{"op":"mcm","clk":"11877787136","pt":1724089986317,"mc":[{"id":"1.232018919","rc":[{"batb":[[0,1.62,14.36],[1,1.59,5.99],[2,1.2,250]],"ltp":2.54,"tv":1011.71,"id":72857115},{"batb":[[0,1.62,4]],"ltp":1.65,"tv":2065.16,"id":72857116}]}]}
{"op":"mcm","clk":"11877787431","pt":1724089988738,"mc":[{"id":"1.232018919","rc":[{"batb":[[0,1.63,10.54],[1,1.62,13.83],[2,1.59,5.99]],"ltp":2.54,"tv":1011.71,"id":72857115},{"batb":[[0,1.62,10]],"ltp":1.65,"tv":2065.16,"id":72857116}]}]}
{"op":"mcm","clk":"11877787439","pt":1724089988834,"mc":[{"id":"1.232018919","rc":[{"batb":[[0,1.63,14.54]],"ltp":2.54,"tv":1011.71,"id":72857115}]}]}
{"op":"mcm","clk":"11877787761","pt":1724089991333,"mc":[{"id":"1.232018919","rc":[{"batb":[[0,1.63,10.54]],"ltp":2.54,"tv":1011.71,"id":72857115},{"batb":[[0,1.63,4],[1,1.62,10],[2,1.61,14.05]],"ltp":1.65,"tv":2065.16,"id":72857116}]}]}
{"op":"mcm","clk":"11877787856","pt":1724089992131,"mc":[{"id":"1.232018919","rc":[{"batb":[[0,1.62,14.36],[1,1.59,5.99],[2,1.2,250]],"ltp":2.54,"tv":1011.71,"id":72857115},{"batb":[[1,1.61,14.05],[2,1.58,7.15]],"ltp":1.65,"tv":2065.16,"id":72857116}]}]}
{"op":"mcm","clk":"11877787984","pt":1724089993631,"mc":[{"id":"1.232018919","rc":[{"batb":[[0,1.61,14.05],[1,1.58,7.15],[2,1.2,250]],"ltp":1.65,"tv":2065.16,"id":72857116}]}]}
{"op":"mcm","clk":"11877788003","pt":1724089993841,"mc":[{"id":"1.232018919","rc":[{"batb":[[0,1.63,4.54],[1,1.62,13.83],[2,1.59,5.99]],"ltp":2.54,"tv":1011.71,"id":72857115}]}]}
{"op":"mcm","clk":"11877788212","pt":1724089995729,"mc":[{"id":"1.232018919","rc":[{"batb":[[0,1.64,10],[1,1.63,4],[2,1.62,13.83]],"ltp":2.54,"tv":1011.71,"id":72857115},{"batb":[[0,1.62,10],[1,1.61,14.05],[2,1.58,7.15]],"ltp":1.65,"tv":2065.16,"id":72857116}]}]}
{"op":"mcm","clk":"11877788257","pt":1724089996262,"mc":[{"id":"1.232018919","rc":[{"batb":[[1,1.62,13.83],[2,1.59,5.99]],"ltp":2.54,"tv":1011.71,"id":72857115},{"batb":[[0,1.63,4],[1,1.62,10],[2,1.61,14.05]],"ltp":1.65,"tv":2065.16,"id":72857116}]}]}
{"op":"mcm","clk":"11877788494","pt":1724089998566,"mc":[{"id":"1.232018919","rc":[{"batb":[[0,1.65,4],[1,1.64,10],[2,1.62,13.83]],"ltp":2.54,"tv":1011.71,"id":72857115},{"batb":[[0,1.62,10],[1,1.61,14.05],[2,1.58,7.15]],"ltp":1.65,"tv":2065.16,"id":72857116}]}]}
{"op":"mcm","clk":"11877788547","pt":1724089999073,"mc":[{"id":"1.232018919","rc":[{"batb":[[1,1.62,13.83],[2,1.59,5.99]],"ltp":2.54,"tv":1011.71,"id":72857115},{"batb":[[0,1.61,14.05],[1,1.58,7.15],[2,1.2,250]],"ltp":1.65,"tv":2065.16,"id":72857116}]}]}
{"op":"mcm","clk":"11877788630","pt":1724089999877,"mc":[{"id":"1.232018919","rc":[{"batb":[[0,2,2.42],[1,1.61,14.05],[2,1.58,7.15]],"ltp":1.65,"tv":2065.16,"id":72857116}]}]}
{"op":"mcm","clk":"11877788766","pt":1724090001077,"mc":[{"id":"1.232018919","rc":[{"batb":[[0,1.62,13.83],[1,1.59,5.99],[2,1.2,250]],"ltp":2.54,"tv":1011.71,"id":72857115},{"batb":[[0,2.02,4],[1,2,2.42],[2,1.61,14.05]],"ltp":1.65,"tv":2065.16,"id":72857116}]}]}
{"op":"mcm","clk":"11877788854","pt":1724090001863,"mc":[{"id":"1.232018919","rc":[{"batb":[[0,1.63,10],[1,1.62,13.83],[2,1.59,5.99]],"ltp":2.54,"tv":1011.71,"id":72857115},{"batb":[[0,2.04,10],[1,2.02,4],[2,2,2.42]],"ltp":1.65,"tv":2065.16,"id":72857116}]}]}
{"op":"mcm","clk":"11877789057","pt":1724090003680,"mc":[{"id":"1.232018919","rc":[{"batb":[[0,1.64,4],[1,1.63,10],[2,1.62,13.83]],"ltp":2.54,"tv":1011.71,"id":72857115},{"batb":[[1,2,2.42],[2,1.61,14.05]],"ltp":1.65,"tv":2065.16,"id":72857116}]}]}
{"op":"mcm","clk":"11877789263","pt":1724090005470,"mc":[{"id":"1.232018919","rc":[{"batb":[[0,1.62,13.83],[1,1.59,5.99],[2,1.2,250]],"ltp":2.54,"tv":1011.71,"id":72857115},{"batb":[[0,2,2.42],[1,1.61,14.05],[2,1.58,7.15]],"ltp":1.65,"tv":2065.16,"id":72857116}]}]}
{"op":"mcm","clk":"11877789560","pt":1724090007574,"mc":[{"id":"1.232018919","rc":[{"batb":[[0,1.63,10],[1,1.62,13.83],[2,1.59,5.99]],"ltp":2.54,"tv":1011.71,"id":72857115},{"batb":[[0,2.02,4],[1,2,2.42],[2,1.61,14.05]],"ltp":1.65,"tv":2065.16,"id":72857116}]}]}
{"op":"mcm","clk":"11877789658","pt":1724090008062,"mc":[{"id":"1.232018919","rc":[{"batb":[[0,1.64,4],[1,1.63,10],[2,1.62,13.83]],"ltp":2.54,"tv":1011.71,"id":72857115},{"batb":[[0,2.04,10],[1,2.02,4]],"ltp":1.65,"tv":2065.16,"id":72857116}]}]}
{"op":"mcm","clk":"11877790019","pt":1724090010779,"mc":[{"id":"1.232018919","rc":[{"batb":[[0,1.63,10],[1,1.62,13.83],[2,1.59,5.99]],"ltp":2.54,"tv":1011.71,"id":72857115},{"batb":[[1,1.61,14.05],[2,1.58,7.15]],"ltp":1.65,"tv":2065.16,"id":72857116}]}]}
{"op":"mcm","clk":"11877790104","pt":1724090011563,"mc":[{"id":"1.232018919","rc":[{"batb":[[0,1.62,13.83],[1,1.59,5.99],[2,1.2,250]],"ltp":2.54,"tv":1011.71,"id":72857115}]}]}
{"op":"mcm","clk":"11877790220","pt":1724090011957,"mc":[{"id":"1.232018919","rc":[{"batb":[[0,1.61,14.05],[1,1.58,7.15],[2,1.2,250]],"ltp":1.65,"tv":2065.16,"id":72857116}]}]}
{"op":"mcm","clk":"11877790660","pt":1724090014284,"mc":[{"id":"1.232018919","rc":[{"batb":[[0,1.63,14],[1,1.62,13.83],[2,1.59,5.99]],"ltp":2.54,"tv":1011.71,"id":72857115},{"batb":[[0,1.63,10],[1,1.62,4],[2,1.61,14.05]],"ltp":1.65,"tv":2065.16,"id":72857116}]}]}
{"op":"mcm","clk":"11877790932","pt":1724090016617,"mc":[{"id":"1.232018919","rc":[{"batb":[[0,1.63,10]],"ltp":2.54,"tv":1011.71,"id":72857115},{"batb":[[1,1.61,14.05],[2,1.58,7.15]],"ltp":1.65,"tv":2065.16,"id":72857116}]}]}
{"op":"mcm","clk":"11877791067","pt":1724090017711,"mc":[{"id":"1.232018919","rc":[{"batb":[[0,1.62,13.83],[1,1.59,5.99],[2,1.2,250]],"ltp":2.54,"tv":1011.71,"id":72857115}]}]}
{"op":"mcm","clk":"11877791088","pt":1724090017975,"mc":[{"id":"1.232018919","rc":[{"batb":[[0,1.61,14.05],[1,1.58,7.15],[2,1.2,250]],"ltp":1.65,"tv":2065.16,"id":72857116}]}]}
{"op":"mcm","clk":"11877791302","pt":1724090019793,"mc":[{"id":"1.232018919","rc":[{"batb":[[0,1.63,4],[1,1.62,13.83],[2,1.59,5.99]],"ltp":2.54,"tv":1011.71,"id":72857115},{"batb":[[0,1.62,4],[1,1.61,14.05],[2,1.58,7.15]],"ltp":1.65,"tv":2065.16,"id":72857116}]}]}
{"op":"mcm","clk":"11877791313","pt":1724090019902,"mc":[{"id":"1.232018919","rc":[{"batb":[[0,1.64,10],[1,1.63,4],[2,1.62,13.83]],"ltp":2.54,"tv":1011.71,"id":72857115}]}]}
{"op":"mcm","clk":"11877791433","pt":1724090021043,"mc":[{"id":"1.232018919","rc":[{"batb":[[0,1.63,10],[1,1.62,4],[2,1.61,14.05]],"ltp":1.65,"tv":2065.16,"id":72857116}]}]}
{"op":"mcm","clk":"11877791545","pt":1724090022181,"mc":[{"id":"1.232018919","rc":[{"batb":[[1,1.62,13.83],[2,1.59,5.99]],"ltp":2.54,"tv":1011.71,"id":72857115},{"batb":[[1,1.61,14.05],[2,1.58,7.15]],"ltp":1.65,"tv":2065.16,"id":72857116}]}]}
{"op":"mcm","clk":"11877791683","pt":1724090023434,"mc":[{"id":"1.232018919","rc":[{"batb":[[0,2.06,2.42],[1,1.63,10],[2,1.61,14.05]],"ltp":1.65,"tv":2065.16,"id":72857116}]}]}
{"op":"mcm","clk":"11877791807","pt":1724090024408,"mc":[{"id":"1.232018919","rc":[{"batb":[[0,1.62,13.83],[1,1.59,5.99],[2,1.2,250]],"ltp":2.54,"tv":1011.71,"id":72857115},{"batb":[[1,1.61,14.05],[2,1.58,7.15]],"ltp":1.65,"tv":2065.16,"id":72857116}]}]}
{"op":"mcm","clk":"11877792489","pt":1724090031095,"mc":[{"id":"1.232018919","rc":[{"batb":[[0,1.61,14.05],[1,1.58,7.15],[2,1.2,250]],"ltp":1.65,"tv":2065.16,"id":72857116}]}]}
{"op":"mcm","clk":"11877806852","pt":1724090161165,"mc":[{"id":"1.232018919","rc":[{"batb":[[0,2,2.42],[1,1.61,14.05],[2,1.58,7.15]],"ltp":1.65,"tv":2065.16,"id":72857116}]}]}
{"op":"mcm","clk":"11877808425","pt":1724090175099,"mc":[{"id":"1.232018919","rc":[{"batb":[[0,1.61,14.05],[1,1.58,7.15],[2,1.2,250]],"ltp":1.65,"tv":2065.16,"id":72857116}]}]}
{"op":"mcm","clk":"11877809733","pt":1724090187624,"mc":[{"id":"1.232018919","rc":[{"batb":[[0,2,1.14],[1,1.61,14.05],[2,1.58,7.15]],"ltp":1.65,"tv":2065.16,"id":72857116}]}]}
{"op":"mcm","clk":"11877810135","pt":1724090191511,"mc":[{"id":"1.232018919","rc":[{"batl":[[1,5,1.54],[2,6,0.77]],"ltp":1.65,"tv":2065.16,"id":72857116}]}]}
{"op":"mcm","clk":"11877810538","pt":1724090195790,"mc":[{"id":"1.232018919","rc":[{"batb":[[0,1.61,14.05],[1,1.58,7.15],[2,1.2,250]],"ltp":1.65,"tv":2065.16,"id":72857116}]}]}
{"op":"mcm","clk":"11877811696","pt":1724090205907,"mc":[{"id":"1.232018919","rc":[{"batb":[[0,2,4.28],[1,1.61,14.05],[2,1.58,7.15]],"ltp":1.65,"tv":2065.16,"id":72857116}]}]}
{"op":"mcm","clk":"11877812769","pt":1724090215736,"mc":[{"id":"1.232018919","rc":[{"batb":[[0,1.61,14.05],[1,1.58,7.15],[2,1.2,250]],"ltp":1.65,"tv":2065.16,"id":72857116}]}]}
{"op":"mcm","clk":"11877814545","pt":1724090230340,"mc":[{"id":"1.232018919","rc":[{"trd":[[1.62,7.55]],"batb":[[0,1.62,10.05]],"ltp":1.62,"tv":1019.26,"id":72857115}],"tv":3084.43}]}
{"op":"mcm","clk":"11877815375","pt":1724090237638,"mc":[{"id":"1.232018919","rc":[{"batl":[[0,2.7,8.85],[1,2.72,180.32],[2,5,1.54]],"ltp":1.65,"tv":2065.16,"id":72857116}]}]}
{"op":"mcm","clk":"11877815800","pt":1724090241480,"mc":[{"id":"1.232018919","rc":[{"batl":[[1,5,1.54],[2,6,0.77]],"ltp":1.62,"tv":1019.26,"id":72857115}]}]}
{"op":"mcm","clk":"11877828257","pt":1724090350872,"mc":[{"id":"1.232018919","rc":[{"batl":[[1,5,1.54],[2,6,0.77]],"ltp":1.65,"tv":2065.16,"id":72857116}]}]}
{"op":"mcm","clk":"11877828445","pt":1724090352666,"mc":[{"id":"1.232018919","rc":[{"batl":[[0,5,1.54],[1,6,0.77],[2,6,0]],"ltp":1.65,"tv":2065.16,"id":72857116}]}]}
{"op":"mcm","clk":"11877828470","pt":1724090352879,"mc":[{"id":"1.232018919","rc":[{"batl":[[0,5,1.54],[1,6,0.77],[2,6,0]],"ltp":1.62,"tv":1019.26,"id":72857115}]}]}
{"op":"mcm","clk":"11877833564","pt":1724090400828,"mc":[{"id":"1.232018919","rc":[{"batb":[[0,1.63,10],[1,1.62,10.05],[2,1.59,5.99]],"ltp":1.62,"tv":1019.26,"id":72857115},{"batb":[[0,1.62,10],[1,1.61,14.05],[2,1.58,7.15]],"ltp":1.65,"tv":2065.16,"id":72857116}]}]}
{"op":"mcm","clk":"11877834059","pt":1724090404433,"mc":[{"id":"1.232018919","rc":[{"trd":[[1.26,1001.52],[1.4,3.23],[1.62,7.56],[2.44,0.37],[2.54,6.06]],"batb":[[0,1.62,10.05],[1,1.59,5.99],[2,1.2,250]],"ltp":1.62,"tv":1018.73,"id":72857115},{"trd":[[1.26,998.87],[1.4,2.15],[1.5,1053.2]],"batb":[[0,1.61,14.05],[1,1.58,7.14],[2,1.2,250]],"ltp":1.65,"tv":2064.06,"id":72857116}],"tv":3082.8}]}
{"op":"mcm","clk":"11877834740","pt":1724090409749,"mc":[{"id":"1.232018919","rc":[{"batb":[[0,1.63,10],[1,1.62,10.05],[2,1.59,5.99]],"ltp":1.62,"tv":1018.73,"id":72857115},{"batb":[[0,1.62,10],[1,1.61,14.05],[2,1.58,7.14]],"ltp":1.65,"tv":2064.06,"id":72857116}]}]}
{"op":"mcm","clk":"11877835203","pt":1724090413471,"mc":[{"id":"1.232018919","rc":[{"batb":[[0,1.62,10.05],[1,1.59,5.99],[2,1.2,250]],"ltp":1.62,"tv":1018.73,"id":72857115},{"batb":[[0,1.61,14.05],[1,1.58,7.14],[2,1.2,250]],"ltp":1.65,"tv":2064.06,"id":72857116}]}]}
{"op":"mcm","clk":"11877835680","pt":1724090416953,"mc":[{"id":"1.232018919","rc":[{"batb":[[0,1.63,10],[1,1.62,10.05],[2,1.59,5.99]],"ltp":1.62,"tv":1018.73,"id":72857115},{"batb":[[0,1.62,10],[1,1.61,14.05],[2,1.58,7.14]],"ltp":1.65,"tv":2064.06,"id":72857116}]}]}
{"op":"mcm","clk":"11877836142","pt":1724090420342,"mc":[{"id":"1.232018919","rc":[{"batb":[[0,1.62,10.05],[1,1.59,5.99],[2,1.2,250]],"ltp":1.62,"tv":1018.73,"id":72857115},{"batb":[[0,1.61,14.05],[1,1.58,7.14],[2,1.2,250]],"ltp":1.65,"tv":2064.06,"id":72857116}]}]}
{"op":"mcm","clk":"11877836805","pt":1724090425766,"mc":[{"id":"1.232018919","rc":[{"batb":[[0,1.63,10],[1,1.62,10.05],[2,1.59,5.99]],"ltp":1.62,"tv":1018.73,"id":72857115},{"batb":[[0,1.62,10],[1,1.61,14.05],[2,1.58,7.14]],"ltp":1.65,"tv":2064.06,"id":72857116}]}]}
{"op":"mcm","clk":"11877837224","pt":1724090429156,"mc":[{"id":"1.232018919","rc":[{"batb":[[0,1.62,10.05],[1,1.59,5.99],[2,1.2,250]],"ltp":1.62,"tv":1018.73,"id":72857115},{"batb":[[0,1.61,14.05],[1,1.58,7.14],[2,1.2,250]],"ltp":1.65,"tv":2064.06,"id":72857116}]}]}
{"op":"mcm","clk":"11877837737","pt":1724090433468,"mc":[{"id":"1.232018919","rc":[{"batb":[[0,1.63,10],[1,1.62,10.05],[2,1.59,5.99]],"ltp":1.62,"tv":1018.73,"id":72857115},{"batb":[[0,1.62,10],[1,1.61,14.05],[2,1.58,7.14]],"ltp":1.65,"tv":2064.06,"id":72857116}]}]}
{"op":"mcm","clk":"11877838190","pt":1724090437260,"mc":[{"id":"1.232018919","rc":[{"batb":[[0,1.62,10.05],[1,1.59,5.99],[2,1.2,250]],"ltp":1.62,"tv":1018.73,"id":72857115},{"batb":[[0,1.61,14.05],[1,1.58,7.14],[2,1.2,250]],"ltp":1.65,"tv":2064.06,"id":72857116}]}]}
{"op":"mcm","clk":"11877838643","pt":1724090440952,"mc":[{"id":"1.232018919","rc":[{"batb":[[0,1.63,10],[1,1.62,10.05],[2,1.59,5.99]],"ltp":1.62,"tv":1018.73,"id":72857115},{"batb":[[0,1.62,10],[1,1.61,14.05],[2,1.58,7.14]],"ltp":1.65,"tv":2064.06,"id":72857116}]}]}
{"op":"mcm","clk":"11877839123","pt":1724090444584,"mc":[{"id":"1.232018919","rc":[{"batb":[[0,1.62,10.05],[1,1.59,5.99],[2,1.2,250]],"ltp":1.62,"tv":1018.73,"id":72857115},{"batb":[[0,1.61,14.05],[1,1.58,7.14],[2,1.2,250]],"ltp":1.65,"tv":2064.06,"id":72857116}]}]}
{"op":"mcm","clk":"11877839395","pt":1724090446868,"mc":[{"id":"1.232018919","rc":[{"batb":[[0,1.63,10],[1,1.62,10.05],[2,1.59,5.99]],"ltp":1.62,"tv":1018.73,"id":72857115},{"batb":[[0,1.62,10],[1,1.61,14.05],[2,1.58,7.14]],"ltp":1.65,"tv":2064.06,"id":72857116}]}]}
{"op":"mcm","clk":"11877839808","pt":1724090450394,"mc":[{"id":"1.232018919","rc":[{"batb":[[0,1.62,10.05],[1,1.59,5.99],[2,1.2,250]],"ltp":1.62,"tv":1018.73,"id":72857115},{"batb":[[0,1.61,14.05],[1,1.58,7.14],[2,1.2,250]],"ltp":1.65,"tv":2064.06,"id":72857116}]}]}
{"op":"mcm","clk":"11877840111","pt":1724090452787,"mc":[{"id":"1.232018919","rc":[{"batb":[[0,1.63,10],[1,1.62,10.05],[2,1.59,5.99]],"ltp":1.62,"tv":1018.73,"id":72857115},{"batb":[[0,1.62,10],[1,1.61,14.05],[2,1.58,7.14]],"ltp":1.65,"tv":2064.06,"id":72857116}]}]}
{"op":"mcm","clk":"11877840548","pt":1724090456264,"mc":[{"id":"1.232018919","rc":[{"batb":[[0,1.62,10.05],[1,1.59,5.99],[2,1.2,250]],"ltp":1.62,"tv":1018.73,"id":72857115},{"batb":[[0,1.61,14.05],[1,1.58,7.14],[2,1.2,250]],"ltp":1.65,"tv":2064.06,"id":72857116}]}]}
{"op":"mcm","clk":"11877840934","pt":1724090459675,"mc":[{"id":"1.232018919","rc":[{"batb":[[0,1.63,10],[1,1.62,10.05],[2,1.59,5.99]],"ltp":1.62,"tv":1018.73,"id":72857115},{"batb":[[0,1.62,10],[1,1.61,14.05],[2,1.58,7.14]],"ltp":1.65,"tv":2064.06,"id":72857116}]}]}
{"op":"mcm","clk":"11877841372","pt":1724090463284,"mc":[{"id":"1.232018919","rc":[{"batb":[[0,1.62,10.05],[1,1.59,5.99],[2,1.2,250]],"ltp":1.62,"tv":1018.73,"id":72857115},{"batb":[[0,1.61,14.05],[1,1.58,7.14],[2,1.2,250]],"ltp":1.65,"tv":2064.06,"id":72857116}]}]}
{"op":"mcm","clk":"11877841709","pt":1724090465792,"mc":[{"id":"1.232018919","rc":[{"batb":[[0,1.63,10],[1,1.62,10.05],[2,1.59,5.99]],"ltp":1.62,"tv":1018.73,"id":72857115},{"batb":[[0,1.62,10],[1,1.61,14.05],[2,1.58,7.14]],"ltp":1.65,"tv":2064.06,"id":72857116}]}]}
{"op":"mcm","clk":"11877842217","pt":1724090469333,"mc":[{"id":"1.232018919","rc":[{"batb":[[0,1.62,10.05],[1,1.59,5.99],[2,1.2,250]],"ltp":1.62,"tv":1018.73,"id":72857115},{"batb":[[0,1.61,14.05],[1,1.58,7.14],[2,1.2,250]],"ltp":1.65,"tv":2064.06,"id":72857116}]}]}
{"op":"mcm","clk":"11877842597","pt":1724090472043,"mc":[{"id":"1.232018919","rc":[{"batb":[[0,1.63,10],[1,1.62,10.05],[2,1.59,5.99]],"ltp":1.62,"tv":1018.73,"id":72857115},{"batb":[[0,1.62,10],[1,1.61,14.05],[2,1.58,7.14]],"ltp":1.65,"tv":2064.06,"id":72857116}]}]}
{"op":"mcm","clk":"11877843154","pt":1724090475473,"mc":[{"id":"1.232018919","rc":[{"batb":[[0,1.62,10.05],[1,1.59,5.99],[2,1.2,250]],"ltp":1.62,"tv":1018.73,"id":72857115},{"batb":[[0,1.61,14.05],[1,1.58,7.14],[2,1.2,250]],"ltp":1.65,"tv":2064.06,"id":72857116}]}]}
{"op":"mcm","clk":"11877843460","pt":1724090478015,"mc":[{"id":"1.232018919","rc":[{"batb":[[0,1.63,10],[1,1.62,10.05],[2,1.59,5.99]],"ltp":1.62,"tv":1018.73,"id":72857115},{"batb":[[0,1.62,10],[1,1.61,14.05],[2,1.58,7.14]],"ltp":1.65,"tv":2064.06,"id":72857116}]}]}
{"op":"mcm","clk":"11877843953","pt":1724090481607,"mc":[{"id":"1.232018919","rc":[{"batb":[[0,1.62,10.05],[1,1.59,5.99],[2,1.2,250]],"ltp":1.62,"tv":1018.73,"id":72857115},{"batb":[[0,1.61,14.05],[1,1.58,7.14],[2,1.2,250]],"ltp":1.65,"tv":2064.06,"id":72857116}]}]}
{"op":"mcm","clk":"11877844413","pt":1724090484894,"mc":[{"id":"1.232018919","rc":[{"batb":[[0,1.63,10],[1,1.62,10.05],[2,1.59,5.99]],"ltp":1.62,"tv":1018.73,"id":72857115},{"batb":[[0,1.62,10],[1,1.61,14.05],[2,1.58,7.14]],"ltp":1.65,"tv":2064.06,"id":72857116}]}]}
{"op":"mcm","clk":"11877844888","pt":1724090488300,"mc":[{"id":"1.232018919","rc":[{"batb":[[0,1.62,10.05],[1,1.59,5.99],[2,1.2,250]],"ltp":1.62,"tv":1018.73,"id":72857115},{"batb":[[0,1.61,14.05],[1,1.58,7.14],[2,1.2,250]],"ltp":1.65,"tv":2064.06,"id":72857116}]}]}
{"op":"mcm","clk":"11877845361","pt":1724090491812,"mc":[{"id":"1.232018919","rc":[{"batb":[[0,1.63,10],[1,1.62,10.05],[2,1.59,5.99]],"ltp":1.62,"tv":1018.73,"id":72857115},{"batb":[[0,1.62,10],[1,1.61,14.05],[2,1.58,7.14]],"ltp":1.65,"tv":2064.06,"id":72857116}]}]}
{"op":"mcm","clk":"11877845831","pt":1724090495319,"mc":[{"id":"1.232018919","rc":[{"batb":[[0,1.62,10.05],[1,1.59,5.99],[2,1.2,250]],"ltp":1.62,"tv":1018.73,"id":72857115},{"batb":[[0,1.61,14.05],[1,1.58,7.14],[2,1.2,250]],"ltp":1.65,"tv":2064.06,"id":72857116}]}]}
{"op":"mcm","clk":"11877846184","pt":1724090498141,"mc":[{"id":"1.232018919","rc":[{"batb":[[0,1.63,10],[1,1.62,10.05],[2,1.59,5.99]],"ltp":1.62,"tv":1018.73,"id":72857115},{"batb":[[0,1.62,10],[1,1.61,14.05],[2,1.58,7.14]],"ltp":1.65,"tv":2064.06,"id":72857116}]}]}
{"op":"mcm","clk":"11877846663","pt":1724090501733,"mc":[{"id":"1.232018919","rc":[{"batb":[[0,1.62,10.05],[1,1.59,5.99],[2,1.2,250]],"ltp":1.62,"tv":1018.73,"id":72857115},{"batb":[[0,1.61,14.05],[1,1.58,7.14],[2,1.2,250]],"ltp":1.65,"tv":2064.06,"id":72857116}]}]}
{"op":"mcm","clk":"11877847035","pt":1724090504823,"mc":[{"id":"1.232018919","rc":[{"batb":[[0,1.63,10],[1,1.62,10.05],[2,1.59,5.99]],"ltp":1.62,"tv":1018.73,"id":72857115},{"batb":[[0,1.62,10],[1,1.61,14.05],[2,1.58,7.14]],"ltp":1.65,"tv":2064.06,"id":72857116}]}]}
{"op":"mcm","clk":"11877847443","pt":1724090508150,"mc":[{"id":"1.232018919","rc":[{"batb":[[0,1.62,10.05],[1,1.59,5.99],[2,1.2,250]],"ltp":1.62,"tv":1018.73,"id":72857115},{"batb":[[0,1.61,14.05],[1,1.58,7.14],[2,1.2,250]],"ltp":1.65,"tv":2064.06,"id":72857116}]}]}
{"op":"mcm","clk":"11877847834","pt":1724090511330,"mc":[{"id":"1.232018919","rc":[{"batb":[[0,1.63,10],[1,1.62,10.05],[2,1.59,5.99]],"ltp":1.62,"tv":1018.73,"id":72857115},{"batb":[[0,1.62,10],[1,1.61,14.05],[2,1.58,7.14]],"ltp":1.65,"tv":2064.06,"id":72857116}]}]}
{"op":"mcm","clk":"11877848330","pt":1724090515032,"mc":[{"id":"1.232018919","rc":[{"batb":[[0,1.62,10.05],[1,1.59,5.99],[2,1.2,250]],"ltp":1.62,"tv":1018.73,"id":72857115},{"batb":[[0,1.61,14.05],[1,1.58,7.14],[2,1.2,250]],"ltp":1.65,"tv":2064.06,"id":72857116}]}]}
{"op":"mcm","clk":"11877848943","pt":1724090519922,"mc":[{"id":"1.232018919","rc":[{"batb":[[0,1.63,10],[1,1.62,10.05],[2,1.59,5.99]],"ltp":1.62,"tv":1018.73,"id":72857115},{"batb":[[0,1.62,10],[1,1.61,14.05],[2,1.58,7.14]],"ltp":1.65,"tv":2064.06,"id":72857116}]}]}
{"op":"mcm","clk":"11877849345","pt":1724090523258,"mc":[{"id":"1.232018919","rc":[{"batb":[[0,1.62,10.05],[1,1.59,5.99],[2,1.2,250]],"ltp":1.62,"tv":1018.73,"id":72857115},{"batb":[[0,1.61,14.05],[1,1.58,7.14],[2,1.2,250]],"ltp":1.65,"tv":2064.06,"id":72857116}]}]}
{"op":"mcm","clk":"11877849710","pt":1724090526044,"mc":[{"id":"1.232018919","rc":[{"batb":[[0,1.63,10],[1,1.62,10.05],[2,1.59,5.99]],"ltp":1.62,"tv":1018.73,"id":72857115},{"batb":[[0,1.62,10],[1,1.61,14.05],[2,1.58,7.14]],"ltp":1.65,"tv":2064.06,"id":72857116}]}]}
{"op":"mcm","clk":"11877850187","pt":1724090529583,"mc":[{"id":"1.232018919","rc":[{"batb":[[0,1.62,10.05],[1,1.59,5.99],[2,1.2,250]],"ltp":1.62,"tv":1018.73,"id":72857115},{"batb":[[0,1.61,14.05],[1,1.58,7.14],[2,1.2,250]],"ltp":1.65,"tv":2064.06,"id":72857116}]}]}
{"op":"mcm","clk":"11877850629","pt":1724090533046,"mc":[{"id":"1.232018919","rc":[{"batb":[[0,1.63,10],[1,1.62,10.05],[2,1.59,5.99]],"ltp":1.62,"tv":1018.73,"id":72857115},{"batb":[[0,1.62,10],[1,1.61,14.05],[2,1.58,7.14]],"ltp":1.65,"tv":2064.06,"id":72857116}]}]}
{"op":"mcm","clk":"11877851081","pt":1724090536481,"mc":[{"id":"1.232018919","rc":[{"batb":[[0,1.62,10.05],[1,1.59,5.99],[2,1.2,250]],"ltp":1.62,"tv":1018.73,"id":72857115},{"batb":[[0,1.61,14.05],[1,1.58,7.14],[2,1.2,250]],"ltp":1.65,"tv":2064.06,"id":72857116}]}]}
{"op":"mcm","clk":"11877851444","pt":1724090539308,"mc":[{"id":"1.232018919","rc":[{"batb":[[0,1.63,10],[1,1.62,10.05],[2,1.59,5.99]],"ltp":1.62,"tv":1018.73,"id":72857115},{"batb":[[0,1.62,10],[1,1.61,14.05],[2,1.58,7.14]],"ltp":1.65,"tv":2064.06,"id":72857116}]}]}
{"op":"mcm","clk":"11877851909","pt":1724090542478,"mc":[{"id":"1.232018919","rc":[{"batb":[[0,1.62,10.05],[1,1.59,5.99],[2,1.2,250]],"ltp":1.62,"tv":1018.73,"id":72857115},{"batb":[[0,1.61,14.05],[1,1.58,7.14],[2,1.2,250]],"ltp":1.65,"tv":2064.06,"id":72857116}]}]}
{"op":"mcm","clk":"11877852296","pt":1724090545571,"mc":[{"id":"1.232018919","rc":[{"batb":[[0,1.63,10],[1,1.62,10.05],[2,1.59,5.99]],"ltp":1.62,"tv":1018.73,"id":72857115},{"batb":[[0,1.62,10],[1,1.61,14.05],[2,1.58,7.14]],"ltp":1.65,"tv":2064.06,"id":72857116}]}]}
{"op":"mcm","clk":"11877852732","pt":1724090549162,"mc":[{"id":"1.232018919","rc":[{"batb":[[0,1.62,10.05],[1,1.59,5.99],[2,1.2,250]],"ltp":1.62,"tv":1018.73,"id":72857115},{"batb":[[0,1.61,14.05],[1,1.58,7.14],[2,1.2,250]],"ltp":1.65,"tv":2064.06,"id":72857116}]}]}
{"op":"mcm","clk":"11877853159","pt":1724090552599,"mc":[{"id":"1.232018919","rc":[{"batb":[[0,1.63,10],[1,1.62,10.05],[2,1.59,5.99]],"ltp":1.62,"tv":1018.73,"id":72857115},{"batb":[[0,1.62,10],[1,1.61,14.05],[2,1.58,7.14]],"ltp":1.65,"tv":2064.06,"id":72857116}]}]}
{"op":"mcm","clk":"11877853612","pt":1724090555993,"mc":[{"id":"1.232018919","rc":[{"batb":[[0,1.62,10.05],[1,1.59,5.99],[2,1.2,250]],"ltp":1.62,"tv":1018.73,"id":72857115},{"batb":[[0,1.61,14.05],[1,1.58,7.14],[2,1.2,250]],"ltp":1.65,"tv":2064.06,"id":72857116}]}]}
{"op":"mcm","clk":"11877854015","pt":1724090559092,"mc":[{"id":"1.232018919","rc":[{"batb":[[0,1.63,10],[1,1.62,10.05],[2,1.59,5.99]],"ltp":1.62,"tv":1018.73,"id":72857115},{"batb":[[0,1.62,10],[1,1.61,14.05],[2,1.58,7.14]],"ltp":1.65,"tv":2064.06,"id":72857116}]}]}
{"op":"mcm","clk":"11877854508","pt":1724090562796,"mc":[{"id":"1.232018919","rc":[{"batb":[[0,1.62,10.05],[1,1.59,5.99],[2,1.2,250]],"ltp":1.62,"tv":1018.73,"id":72857115},{"batb":[[0,1.61,14.05],[1,1.58,7.14],[2,1.2,250]],"ltp":1.65,"tv":2064.06,"id":72857116}]}]}
{"op":"mcm","clk":"11877854878","pt":1724090565410,"mc":[{"id":"1.232018919","rc":[{"batb":[[0,1.63,10],[1,1.62,10.05],[2,1.59,5.99]],"ltp":1.62,"tv":1018.73,"id":72857115},{"batb":[[0,1.62,10],[1,1.61,14.05],[2,1.58,7.14]],"ltp":1.65,"tv":2064.06,"id":72857116}]}]}
{"op":"mcm","clk":"11877855324","pt":1724090568807,"mc":[{"id":"1.232018919","rc":[{"batb":[[0,1.62,10.05],[1,1.59,5.99],[2,1.2,250]],"ltp":1.62,"tv":1018.73,"id":72857115},{"batb":[[0,1.61,14.05],[1,1.58,7.14],[2,1.2,250]],"ltp":1.65,"tv":2064.06,"id":72857116}]}]}
{"op":"mcm","clk":"11877855659","pt":1724090571793,"mc":[{"id":"1.232018919","rc":[{"batb":[[0,1.63,10],[1,1.62,10.05],[2,1.59,5.99]],"ltp":1.62,"tv":1018.73,"id":72857115},{"batb":[[0,1.62,10],[1,1.61,14.05],[2,1.58,7.14]],"ltp":1.65,"tv":2064.06,"id":72857116}]}]}
{"op":"mcm","clk":"11877856044","pt":1724090575222,"mc":[{"id":"1.232018919","rc":[{"batb":[[0,1.62,10.05],[1,1.59,5.99],[2,1.2,250]],"ltp":1.62,"tv":1018.73,"id":72857115},{"batb":[[0,1.61,14.05],[1,1.58,7.14],[2,1.2,250]],"ltp":1.65,"tv":2064.06,"id":72857116}]}]}
{"op":"mcm","clk":"11877856330","pt":1724090577624,"mc":[{"id":"1.232018919","rc":[{"batb":[[0,1.63,10],[1,1.62,10.05],[2,1.59,5.99]],"ltp":1.62,"tv":1018.73,"id":72857115},{"batb":[[0,1.62,10],[1,1.61,14.05],[2,1.58,7.14]],"ltp":1.65,"tv":2064.06,"id":72857116}]}]}
{"op":"mcm","clk":"11877856786","pt":1724090581017,"mc":[{"id":"1.232018919","rc":[{"batb":[[0,1.62,10.05],[1,1.59,5.99],[2,1.2,250]],"ltp":1.62,"tv":1018.73,"id":72857115},{"batb":[[0,1.61,14.05],[1,1.58,7.14],[2,1.2,250]],"ltp":1.65,"tv":2064.06,"id":72857116}]}]}
{"op":"mcm","clk":"11877857147","pt":1724090583832,"mc":[{"id":"1.232018919","rc":[{"batb":[[0,1.63,10],[1,1.62,10.05],[2,1.59,5.99]],"ltp":1.62,"tv":1018.73,"id":72857115},{"batb":[[0,1.62,10],[1,1.61,14.05],[2,1.58,7.14]],"ltp":1.65,"tv":2064.06,"id":72857116}]}]}
{"op":"mcm","clk":"11877857597","pt":1724090587417,"mc":[{"id":"1.232018919","rc":[{"batb":[[0,1.62,10.05],[1,1.59,5.99],[2,1.2,250]],"ltp":1.62,"tv":1018.73,"id":72857115},{"batb":[[0,1.61,14.05],[1,1.58,7.14],[2,1.2,250]],"ltp":1.65,"tv":2064.06,"id":72857116}]}]}
{"op":"mcm","clk":"11877857959","pt":1724090590023,"mc":[{"id":"1.232018919","rc":[{"batb":[[0,1.63,10],[1,1.62,10.05],[2,1.59,5.99]],"ltp":1.62,"tv":1018.73,"id":72857115},{"batb":[[0,1.62,10],[1,1.61,14.05],[2,1.58,7.14]],"ltp":1.65,"tv":2064.06,"id":72857116}]}]}
{"op":"mcm","clk":"11877858405","pt":1724090593818,"mc":[{"id":"1.232018919","rc":[{"batb":[[0,1.62,10.05],[1,1.59,5.99],[2,1.2,250]],"ltp":1.62,"tv":1018.73,"id":72857115},{"batb":[[0,1.61,14.05],[1,1.58,7.14],[2,1.2,250]],"ltp":1.65,"tv":2064.06,"id":72857116}]}]}
{"op":"mcm","clk":"11877859332","pt":1724090601229,"mc":[{"id":"1.232018919","rc":[{"batb":[[0,1.63,10],[1,1.62,10.05],[2,1.59,5.99]],"ltp":1.62,"tv":1018.73,"id":72857115},{"batb":[[0,1.62,10],[1,1.61,14.05],[2,1.58,7.14]],"ltp":1.65,"tv":2064.06,"id":72857116}]}]}
{"op":"mcm","clk":"11877859782","pt":1724090604921,"mc":[{"id":"1.232018919","rc":[{"batb":[[0,1.62,10.05],[1,1.59,5.99],[2,1.2,250]],"ltp":1.62,"tv":1018.73,"id":72857115},{"batb":[[0,1.61,14.05],[1,1.58,7.14],[2,1.2,250]],"ltp":1.65,"tv":2064.06,"id":72857116}]}]}
{"op":"mcm","clk":"11877860121","pt":1724090607637,"mc":[{"id":"1.232018919","rc":[{"batb":[[0,1.63,10],[1,1.62,10.05],[2,1.59,5.99]],"ltp":1.62,"tv":1018.73,"id":72857115},{"batb":[[0,1.62,10],[1,1.61,14.05],[2,1.58,7.14]],"ltp":1.65,"tv":2064.06,"id":72857116}]}]}
{"op":"mcm","clk":"11877860569","pt":1724090611242,"mc":[{"id":"1.232018919","rc":[{"batb":[[0,1.62,10.05],[1,1.59,5.99],[2,1.2,250]],"ltp":1.62,"tv":1018.73,"id":72857115},{"batb":[[0,1.61,14.05],[1,1.58,7.14],[2,1.2,250]],"ltp":1.65,"tv":2064.06,"id":72857116}]}]}
{"op":"mcm","clk":"11877860883","pt":1724090613899,"mc":[{"id":"1.232018919","rc":[{"batb":[[0,1.63,10],[1,1.62,10.05],[2,1.59,5.99]],"ltp":1.62,"tv":1018.73,"id":72857115},{"batb":[[0,1.62,10],[1,1.61,14.05],[2,1.58,7.14]],"ltp":1.65,"tv":2064.06,"id":72857116}]}]}
{"op":"mcm","clk":"11877861334","pt":1724090617492,"mc":[{"id":"1.232018919","rc":[{"batb":[[0,1.62,10.05],[1,1.59,5.99],[2,1.2,250]],"ltp":1.62,"tv":1018.73,"id":72857115},{"batb":[[0,1.61,14.05],[1,1.58,7.14],[2,1.2,250]],"ltp":1.65,"tv":2064.06,"id":72857116}]}]}
{"op":"mcm","clk":"11877861782","pt":1724090621303,"mc":[{"id":"1.232018919","rc":[{"batb":[[0,1.63,10],[1,1.62,10.05],[2,1.59,5.99]],"ltp":1.62,"tv":1018.73,"id":72857115},{"batb":[[0,1.62,10],[1,1.61,14.05],[2,1.58,7.14]],"ltp":1.65,"tv":2064.06,"id":72857116}]}]}
{"op":"mcm","clk":"11877862264","pt":1724090624858,"mc":[{"id":"1.232018919","rc":[{"batb":[[0,1.62,10.05],[1,1.59,5.99],[2,1.2,250]],"ltp":1.62,"tv":1018.73,"id":72857115},{"batb":[[0,1.61,14.05],[1,1.58,7.14],[2,1.2,250]],"ltp":1.65,"tv":2064.06,"id":72857116}]}]}
{"op":"mcm","clk":"11877862573","pt":1724090627360,"mc":[{"id":"1.232018919","rc":[{"batb":[[0,1.63,10],[1,1.62,10.05],[2,1.59,5.99]],"ltp":1.62,"tv":1018.73,"id":72857115},{"batb":[[0,1.62,10],[1,1.61,14.05],[2,1.58,7.14]],"ltp":1.65,"tv":2064.06,"id":72857116}]}]}
{"op":"mcm","clk":"11877862966","pt":1724090630956,"mc":[{"id":"1.232018919","rc":[{"batb":[[0,1.62,10.05],[1,1.59,5.99],[2,1.2,250]],"ltp":1.62,"tv":1018.73,"id":72857115},{"batb":[[0,1.61,14.05],[1,1.58,7.14],[2,1.2,250]],"ltp":1.65,"tv":2064.06,"id":72857116}]}]}
{"op":"mcm","clk":"11877863298","pt":1724090633290,"mc":[{"id":"1.232018919","rc":[{"batb":[[0,1.63,10],[1,1.62,10.05],[2,1.59,5.99]],"ltp":1.62,"tv":1018.73,"id":72857115},{"batb":[[0,1.62,10],[1,1.61,14.05],[2,1.58,7.14]],"ltp":1.65,"tv":2064.06,"id":72857116}]}]}
{"op":"mcm","clk":"11877863740","pt":1724090636874,"mc":[{"id":"1.232018919","rc":[{"batb":[[0,1.62,10.05],[1,1.59,5.99],[2,1.2,250]],"ltp":1.62,"tv":1018.73,"id":72857115},{"batb":[[0,1.61,14.05],[1,1.58,7.14],[2,1.2,250]],"ltp":1.65,"tv":2064.06,"id":72857116}]}]}
{"op":"mcm","clk":"11877864243","pt":1724090640286,"mc":[{"id":"1.232018919","rc":[{"batb":[[0,1.63,10],[1,1.62,10.05],[2,1.59,5.99]],"ltp":1.62,"tv":1018.73,"id":72857115},{"batb":[[0,1.62,10],[1,1.61,14.05],[2,1.58,7.14]],"ltp":1.65,"tv":2064.06,"id":72857116}]}]}
{"op":"mcm","clk":"11877864750","pt":1724090643807,"mc":[{"id":"1.232018919","rc":[{"batb":[[0,1.62,10.05],[1,1.59,5.99],[2,1.2,250]],"ltp":1.62,"tv":1018.73,"id":72857115},{"batb":[[0,1.61,14.05],[1,1.58,7.14],[2,1.2,250]],"ltp":1.65,"tv":2064.06,"id":72857116}]}]}
{"op":"mcm","clk":"11877865258","pt":1724090647570,"mc":[{"id":"1.232018919","rc":[{"batb":[[0,1.63,10],[1,1.62,10.05],[2,1.59,5.99]],"ltp":1.62,"tv":1018.73,"id":72857115},{"batb":[[0,1.62,10],[1,1.61,14.05],[2,1.58,7.14]],"ltp":1.65,"tv":2064.06,"id":72857116}]}]}
{"op":"mcm","clk":"11877865884","pt":1724090651503,"mc":[{"id":"1.232018919","rc":[{"batb":[[0,1.62,10.05],[1,1.59,5.99],[2,1.2,250]],"ltp":1.62,"tv":1018.73,"id":72857115},{"batb":[[0,1.61,14.58],[1,1.58,7.14],[2,1.2,250]],"ltp":1.65,"tv":2064.06,"id":72857116}]}]}
{"op":"mcm","clk":"11877866958","pt":1724090659403,"mc":[{"id":"1.232018919","rc":[{"batb":[[0,1.63,10],[1,1.62,10.05],[2,1.59,5.99]],"ltp":1.62,"tv":1018.73,"id":72857115},{"batb":[[0,1.62,10.54],[1,1.61,14.05],[2,1.58,7.14]],"ltp":1.65,"tv":2064.06,"id":72857116}]}]}
{"op":"mcm","clk":"11877867251","pt":1724090661485,"mc":[{"id":"1.232018919","rc":[{"batb":[[0,1.63,10.54]],"ltp":1.62,"tv":1018.73,"id":72857115}]}]}
{"op":"mcm","clk":"11877867493","pt":1724090663209,"mc":[{"id":"1.232018919","rc":[{"batb":[[0,1.62,10.58],[1,1.59,5.99],[2,1.2,250]],"ltp":1.62,"tv":1018.73,"id":72857115},{"batb":[[0,1.61,14.58],[1,1.58,7.14],[2,1.2,250]],"ltp":1.65,"tv":2064.06,"id":72857116}]}]}
{"op":"mcm","clk":"11877867971","pt":1724090666633,"mc":[{"id":"1.232018919","rc":[{"batb":[[0,1.63,10.54],[1,1.62,10.05],[2,1.59,5.99]],"ltp":1.62,"tv":1018.73,"id":72857115},{"batb":[[0,1.62,10.54],[1,1.61,14.05],[2,1.58,7.14]],"ltp":1.65,"tv":2064.06,"id":72857116}]}]}
{"op":"mcm","clk":"11877868494","pt":1724090670389,"mc":[{"id":"1.232018919","rc":[{"batb":[[0,1.62,10.58],[1,1.59,5.99],[2,1.2,250]],"ltp":1.62,"tv":1018.73,"id":72857115},{"batb":[[0,1.61,14.58],[1,1.58,7.14],[2,1.2,250]],"ltp":1.65,"tv":2064.06,"id":72857116}]}]}
{"op":"mcm","clk":"11877869005","pt":1724090673819,"mc":[{"id":"1.232018919","rc":[{"batb":[[0,1.63,10.54],[1,1.62,10.05],[2,1.59,5.99]],"ltp":1.62,"tv":1018.73,"id":72857115},{"batb":[[0,1.62,10.54],[1,1.61,14.05],[2,1.58,7.14]],"ltp":1.65,"tv":2064.06,"id":72857116}]}]}
{"op":"mcm","clk":"11877869464","pt":1724090677214,"mc":[{"id":"1.232018919","rc":[{"batb":[[0,1.62,10.58],[1,1.59,5.99],[2,1.2,250]],"ltp":1.62,"tv":1018.73,"id":72857115},{"batb":[[0,1.61,14.58],[1,1.58,7.14],[2,1.2,250]],"ltp":1.65,"tv":2064.06,"id":72857116}]}]}
{"op":"mcm","clk":"11877869930","pt":1724090680539,"mc":[{"id":"1.232018919","rc":[{"batb":[[0,1.63,10.54],[1,1.62,10.05],[2,1.59,5.99]],"ltp":1.62,"tv":1018.73,"id":72857115},{"batb":[[0,1.62,10.54],[1,1.61,14.05],[2,1.58,7.14]],"ltp":1.65,"tv":2064.06,"id":72857116}]}]}
{"op":"mcm","clk":"11877870412","pt":1724090684131,"mc":[{"id":"1.232018919","rc":[{"batb":[[0,1.62,10.58],[1,1.59,5.99],[2,1.2,250]],"ltp":1.62,"tv":1018.73,"id":72857115},{"batb":[[0,1.61,14.58],[1,1.58,7.14],[2,1.2,250]],"ltp":1.65,"tv":2064.06,"id":72857116}]}]}
{"op":"mcm","clk":"11877871115","pt":1724090689128,"mc":[{"id":"1.232018919","rc":[{"batb":[[0,1.63,10.54],[1,1.62,10.05],[2,1.59,5.99]],"ltp":1.62,"tv":1018.73,"id":72857115},{"batb":[[0,1.62,10.54],[1,1.61,14.05],[2,1.58,7.14]],"ltp":1.65,"tv":2064.06,"id":72857116}]}]}
{"op":"mcm","clk":"11877871651","pt":1724090692795,"mc":[{"id":"1.232018919","rc":[{"batb":[[0,1.62,10.58],[1,1.59,5.99],[2,1.2,250]],"ltp":1.62,"tv":1018.73,"id":72857115},{"batb":[[0,1.61,14.58],[1,1.58,7.14],[2,1.2,250]],"ltp":1.65,"tv":2064.06,"id":72857116}]}]}
{"op":"mcm","clk":"11877872346","pt":1724090697357,"mc":[{"id":"1.232018919","rc":[{"batb":[[0,1.63,10.54],[1,1.62,10.05],[2,1.59,5.99]],"ltp":1.62,"tv":1018.73,"id":72857115},{"batb":[[0,1.62,10.54],[1,1.61,14.05],[2,1.58,7.14]],"ltp":1.65,"tv":2064.06,"id":72857116}]}]}
{"op":"mcm","clk":"11877872891","pt":1724090701093,"mc":[{"id":"1.232018919","rc":[{"batb":[[0,1.62,10.58],[1,1.59,5.99],[2,1.2,250]],"ltp":1.62,"tv":1018.73,"id":72857115},{"batb":[[0,1.61,14.58],[1,1.58,7.14],[2,1.2,250]],"ltp":1.65,"tv":2064.06,"id":72857116}]}]}
{"op":"mcm","clk":"11877873452","pt":1724090704410,"mc":[{"id":"1.232018919","rc":[{"batb":[[0,1.63,10.54],[1,1.62,10.05],[2,1.59,5.99]],"ltp":1.62,"tv":1018.73,"id":72857115},{"batb":[[0,1.62,10.54],[1,1.61,14.05],[2,1.58,7.14]],"ltp":1.65,"tv":2064.06,"id":72857116}]}]}
{"op":"mcm","clk":"11877873989","pt":1724090708074,"mc":[{"id":"1.232018919","rc":[{"batb":[[0,1.62,10.58],[1,1.59,5.99],[2,1.2,250]],"ltp":1.62,"tv":1018.73,"id":72857115},{"batb":[[0,1.61,14.58],[1,1.58,7.14],[2,1.2,250]],"ltp":1.65,"tv":2064.06,"id":72857116}]}]}
{"op":"mcm","clk":"11877874409","pt":1724090710977,"mc":[{"id":"1.232018919","rc":[{"batb":[[0,1.63,10.54],[1,1.62,10.05],[2,1.59,5.99]],"ltp":1.62,"tv":1018.73,"id":72857115},{"batb":[[0,1.62,10.54],[1,1.61,14.05],[2,1.58,7.14]],"ltp":1.65,"tv":2064.06,"id":72857116}]}]}
{"op":"mcm","clk":"11877874975","pt":1724090714693,"mc":[{"id":"1.232018919","rc":[{"batb":[[0,1.62,10.58],[1,1.59,5.99],[2,1.2,250]],"ltp":1.62,"tv":1018.73,"id":72857115},{"batb":[[0,1.61,14.58],[1,1.58,7.14],[2,1.2,250]],"ltp":1.65,"tv":2064.06,"id":72857116}]}]}
{"op":"mcm","clk":"11877875333","pt":1724090717390,"mc":[{"id":"1.232018919","rc":[{"batb":[[0,1.63,10.54],[1,1.62,10.05],[2,1.59,5.99]],"ltp":1.62,"tv":1018.73,"id":72857115},{"batb":[[0,1.62,10.54],[1,1.61,14.05],[2,1.58,7.14]],"ltp":1.65,"tv":2064.06,"id":72857116}]}]}
{"op":"mcm","clk":"11877875851","pt":1724090720788,"mc":[{"id":"1.232018919","rc":[{"batb":[[0,1.62,10.58],[1,1.59,5.99],[2,1.2,250]],"ltp":1.62,"tv":1018.73,"id":72857115},{"batb":[[0,1.61,14.58],[1,1.58,7.14],[2,1.2,250]],"ltp":1.65,"tv":2064.06,"id":72857116}]}]}
{"op":"mcm","clk":"11877876265","pt":1724090723618,"mc":[{"id":"1.232018919","rc":[{"batb":[[0,1.63,10.54],[1,1.62,10.05],[2,1.59,5.99]],"ltp":1.62,"tv":1018.73,"id":72857115},{"batb":[[0,1.62,10.54],[1,1.61,14.05],[2,1.58,7.14]],"ltp":1.65,"tv":2064.06,"id":72857116}]}]}
{"op":"mcm","clk":"11877876803","pt":1724090727201,"mc":[{"id":"1.232018919","rc":[{"batb":[[0,1.62,10.58],[1,1.59,5.99],[2,1.2,250]],"ltp":1.62,"tv":1018.73,"id":72857115},{"batb":[[0,1.61,14.58],[1,1.58,7.14],[2,1.2,250]],"ltp":1.65,"tv":2064.06,"id":72857116}]}]}
{"op":"mcm","clk":"11877877146","pt":1724090729799,"mc":[{"id":"1.232018919","rc":[{"batb":[[0,1.63,10.54],[1,1.62,10.05],[2,1.59,5.99]],"ltp":1.62,"tv":1018.73,"id":72857115},{"batb":[[0,1.62,10.54],[1,1.61,14.05],[2,1.58,7.14]],"ltp":1.65,"tv":2064.06,"id":72857116}]}]}
{"op":"mcm","clk":"11877877670","pt":1724090733513,"mc":[{"id":"1.232018919","rc":[{"batb":[[0,1.62,10.58],[1,1.59,5.99],[2,1.2,250]],"ltp":1.62,"tv":1018.73,"id":72857115},{"batb":[[0,1.61,14.58],[1,1.58,7.14],[2,1.2,250]],"ltp":1.65,"tv":2064.06,"id":72857116}]}]}
{"op":"mcm","clk":"11877878035","pt":1724090735931,"mc":[{"id":"1.232018919","rc":[{"batb":[[0,1.63,10.54],[1,1.62,10.05],[2,1.59,5.99]],"ltp":1.62,"tv":1018.73,"id":72857115},{"batb":[[0,1.62,10.54],[1,1.61,14.05],[2,1.58,7.14]],"ltp":1.65,"tv":2064.06,"id":72857116}]}]}
{"op":"mcm","clk":"11877878604","pt":1724090739613,"mc":[{"id":"1.232018919","rc":[{"batb":[[0,1.62,10.58],[1,1.59,5.99],[2,1.2,250]],"ltp":1.62,"tv":1018.73,"id":72857115},{"batb":[[0,1.61,14.58],[1,1.58,7.14],[2,1.2,250]],"ltp":1.65,"tv":2064.06,"id":72857116}]}]}
{"op":"mcm","clk":"11877879151","pt":1724090743017,"mc":[{"id":"1.232018919","rc":[{"batb":[[0,1.63,10.54],[1,1.62,10.05],[2,1.59,5.99]],"ltp":1.62,"tv":1018.73,"id":72857115},{"batb":[[0,1.62,10.54],[1,1.61,14.05],[2,1.58,7.14]],"ltp":1.65,"tv":2064.06,"id":72857116}]}]}
{"op":"mcm","clk":"11877879704","pt":1724090746866,"mc":[{"id":"1.232018919","rc":[{"batb":[[0,1.62,10.58],[1,1.59,5.99],[2,1.2,250]],"ltp":1.62,"tv":1018.73,"id":72857115},{"batb":[[0,1.61,14.58],[1,1.58,7.14],[2,1.2,250]],"ltp":1.65,"tv":2064.06,"id":72857116}]}]}
{"op":"mcm","clk":"11877880382","pt":1724090751002,"mc":[{"id":"1.232018919","rc":[{"batb":[[0,1.63,10.54],[1,1.62,10.05],[2,1.59,5.99]],"ltp":1.62,"tv":1018.73,"id":72857115},{"batb":[[0,1.62,10.54],[1,1.61,14.05],[2,1.58,7.14]],"ltp":1.65,"tv":2064.06,"id":72857116}]}]}
{"op":"mcm","clk":"11877880982","pt":1724090754628,"mc":[{"id":"1.232018919","rc":[{"batb":[[0,1.62,10.58],[1,1.59,5.99],[2,1.2,250]],"ltp":1.62,"tv":1018.73,"id":72857115},{"batb":[[0,1.61,14.58],[1,1.58,7.14],[2,1.2,250]],"ltp":1.65,"tv":2064.06,"id":72857116}]}]}
{"op":"mcm","clk":"11877881598","pt":1724090758227,"mc":[{"id":"1.232018919","rc":[{"batb":[[0,1.63,10.54],[1,1.62,10.05],[2,1.59,5.99]],"ltp":1.62,"tv":1018.73,"id":72857115},{"batb":[[0,1.62,10.54],[1,1.61,14.05],[2,1.58,7.14]],"ltp":1.65,"tv":2064.06,"id":72857116}]}]}
{"op":"mcm","clk":"11877882161","pt":1724090761847,"mc":[{"id":"1.232018919","rc":[{"batb":[[0,1.62,10.58],[1,1.59,5.99],[2,1.2,250]],"ltp":1.62,"tv":1018.73,"id":72857115},{"batb":[[0,1.61,14.58],[1,1.58,7.14],[2,1.2,250]],"ltp":1.65,"tv":2064.06,"id":72857116}]}]}
{"op":"mcm","clk":"11877882756","pt":1724090765217,"mc":[{"id":"1.232018919","rc":[{"batb":[[0,1.63,10.54],[1,1.62,10.05],[2,1.59,5.99]],"ltp":1.62,"tv":1018.73,"id":72857115},{"batb":[[0,1.62,10.54],[1,1.61,14.05],[2,1.58,7.14]],"ltp":1.65,"tv":2064.06,"id":72857116}]}]}
{"op":"mcm","clk":"11877883324","pt":1724090768624,"mc":[{"id":"1.232018919","rc":[{"batb":[[0,1.62,10.58],[1,1.59,5.99],[2,1.2,250]],"ltp":1.62,"tv":1018.73,"id":72857115},{"batb":[[0,1.61,14.58],[1,1.58,7.14],[2,1.2,250]],"ltp":1.65,"tv":2064.06,"id":72857116}]}]}
{"op":"mcm","clk":"11877883707","pt":1724090771138,"mc":[{"id":"1.232018919","rc":[{"batb":[[0,1.63,10.54],[1,1.62,10.05],[2,1.59,5.99]],"ltp":1.62,"tv":1018.73,"id":72857115},{"batb":[[0,1.62,10.54],[1,1.61,14.05],[2,1.58,7.14]],"ltp":1.65,"tv":2064.06,"id":72857116}]}]}
{"op":"mcm","clk":"11877884304","pt":1724090774758,"mc":[{"id":"1.232018919","rc":[{"batb":[[0,1.62,10.58],[1,1.59,5.99],[2,1.2,250]],"ltp":1.62,"tv":1018.73,"id":72857115},{"batb":[[0,1.61,14.58],[1,1.58,7.14],[2,1.2,250]],"ltp":1.65,"tv":2064.06,"id":72857116}]}]}
{"op":"mcm","clk":"11877884919","pt":1724090778665,"mc":[{"id":"1.232018919","rc":[{"batb":[[0,1.63,10.54],[1,1.62,10.05],[2,1.59,5.99]],"ltp":1.62,"tv":1018.73,"id":72857115},{"batb":[[0,1.62,10.54],[1,1.61,14.05],[2,1.58,7.14]],"ltp":1.65,"tv":2064.06,"id":72857116}]}]}
{"op":"mcm","clk":"11877885450","pt":1724090782246,"mc":[{"id":"1.232018919","rc":[{"batb":[[0,1.62,10.58],[1,1.59,5.99],[2,1.2,250]],"ltp":1.62,"tv":1018.73,"id":72857115},{"batb":[[0,1.61,14.58],[1,1.58,7.14],[2,1.2,250]],"ltp":1.65,"tv":2064.06,"id":72857116}]}]}
{"op":"mcm","clk":"11877885788","pt":1724090784661,"mc":[{"id":"1.232018919","rc":[{"batb":[[0,1.63,10.54],[1,1.62,10.05],[2,1.59,5.99]],"ltp":1.62,"tv":1018.73,"id":72857115},{"batb":[[0,1.62,10.54],[1,1.61,14.05],[2,1.58,7.14]],"ltp":1.65,"tv":2064.06,"id":72857116}]}]}
{"op":"mcm","clk":"11877886296","pt":1724090788290,"mc":[{"id":"1.232018919","rc":[{"batb":[[0,1.62,10.58],[1,1.59,5.99],[2,1.2,250]],"ltp":1.62,"tv":1018.73,"id":72857115},{"batb":[[0,1.61,14.58],[1,1.58,7.14],[2,1.2,250]],"ltp":1.65,"tv":2064.06,"id":72857116}]}]}
{"op":"mcm","clk":"11877886772","pt":1724090791463,"mc":[{"id":"1.232018919","rc":[{"batb":[[0,1.63,10.54],[1,1.62,10.05],[2,1.59,5.99]],"ltp":1.62,"tv":1018.73,"id":72857115},{"batb":[[0,1.62,10.54],[1,1.61,14.05],[2,1.58,7.14]],"ltp":1.65,"tv":2064.06,"id":72857116}]}]}
{"op":"mcm","clk":"11877887337","pt":1724090795075,"mc":[{"id":"1.232018919","rc":[{"batb":[[0,1.62,10.58],[1,1.59,5.99],[2,1.2,250]],"ltp":1.62,"tv":1018.73,"id":72857115},{"batb":[[0,1.61,14.58],[1,1.58,7.14],[2,1.2,250]],"ltp":1.65,"tv":2064.06,"id":72857116}]}]}
{"op":"mcm","clk":"11877887786","pt":1724090797991,"mc":[{"id":"1.232018919","rc":[{"batb":[[0,1.63,10.54],[1,1.62,10.05],[2,1.59,5.99]],"ltp":1.62,"tv":1018.73,"id":72857115},{"batb":[[0,1.62,10.54],[1,1.61,14.05],[2,1.58,7.14]],"ltp":1.65,"tv":2064.06,"id":72857116}]}]}
{"op":"mcm","clk":"11877888297","pt":1724090801598,"mc":[{"id":"1.232018919","rc":[{"batb":[[0,1.62,10.58],[1,1.59,5.99],[2,1.2,250]],"ltp":1.62,"tv":1018.73,"id":72857115},{"batb":[[0,1.61,14.58],[1,1.58,7.14],[2,1.2,250]],"ltp":1.65,"tv":2064.06,"id":72857116}]}]}
{"op":"mcm","clk":"11877888824","pt":1724090804893,"mc":[{"id":"1.232018919","rc":[{"batb":[[0,1.63,10.54],[1,1.62,10.05],[2,1.59,5.99]],"ltp":1.62,"tv":1018.73,"id":72857115},{"batb":[[0,1.62,10.54],[1,1.61,14.05],[2,1.58,7.14]],"ltp":1.65,"tv":2064.06,"id":72857116}]}]}
{"op":"mcm","clk":"11877889357","pt":1724090808601,"mc":[{"id":"1.232018919","rc":[{"batb":[[0,1.62,10.58],[1,1.59,5.99],[2,1.2,250]],"ltp":1.62,"tv":1018.73,"id":72857115},{"batb":[[0,1.61,14.58],[1,1.58,7.14],[2,1.2,250]],"ltp":1.65,"tv":2064.06,"id":72857116}]}]}
{"op":"mcm","clk":"11877889569","pt":1724090810172,"mc":[{"id":"1.232018919","rc":[{"batb":[[0,1.63,4.54],[1,1.62,10.05],[2,1.59,5.99]],"batl":[[0,2.62,1.67],[1,5,1.54],[2,6,0.77]],"ltp":1.62,"tv":1018.73,"id":72857115}]}]}
{"op":"mcm","clk":"11877889757","pt":1724090811377,"mc":[{"id":"1.232018919","rc":[{"batb":[[0,1.64,10.54],[1,1.63,4],[2,1.62,10.05]],"ltp":1.62,"tv":1018.73,"id":72857115},{"batb":[[0,1.62,10.54],[1,1.61,14.05],[2,1.58,7.14]],"ltp":1.65,"tv":2064.06,"id":72857116}]}]}
{"op":"mcm","clk":"11877889883","pt":1724090812412,"mc":[{"id":"1.232018919","rc":[{"batb":[[1,1.62,10.05],[2,1.59,5.99]],"ltp":1.62,"tv":1018.73,"id":72857115}]}]}
{"op":"mcm","clk":"11877890210","pt":1724090814599,"mc":[{"id":"1.232018919","rc":[{"batb":[[0,1.65,4.54],[1,1.64,10],[2,1.62,10.05]],"ltp":1.62,"tv":1018.73,"id":72857115}]}]}
{"op":"mcm","clk":"11877890260","pt":1724090814909,"mc":[{"id":"1.232018919","rc":[{"batb":[[1,1.62,10.05],[2,1.59,5.99]],"ltp":1.62,"tv":1018.73,"id":72857115},{"batb":[[0,1.61,14.58],[1,1.58,7.14],[2,1.2,250]],"ltp":1.65,"tv":2064.06,"id":72857116}]}]}
{"op":"mcm","clk":"11877890623","pt":1724090817304,"mc":[{"id":"1.232018919","rc":[{"batb":[[0,1.63,10.54]],"ltp":1.62,"tv":1018.73,"id":72857115},{"batb":[[0,1.62,10.54],[1,1.61,14.05],[2,1.58,7.14]],"ltp":1.65,"tv":2064.06,"id":72857116}]}]}
{"op":"mcm","clk":"11877891115","pt":1724090820621,"mc":[{"id":"1.232018919","rc":[{"batb":[[0,1.64,4.54]],"ltp":1.62,"tv":1018.73,"id":72857115},{"batb":[[0,1.61,14.58],[1,1.58,7.14],[2,1.2,250]],"ltp":1.65,"tv":2064.06,"id":72857116}]}]}
{"op":"mcm","clk":"11877891440","pt":1724090822705,"mc":[{"id":"1.232018919","rc":[{"batb":[[0,1.62,10.58],[1,1.59,5.99],[2,1.2,250]],"ltp":1.62,"tv":1018.73,"id":72857115}]}]}
{"op":"mcm","clk":"11877891491","pt":1724090823020,"mc":[{"id":"1.232018919","rc":[{"batb":[[0,1.63,10.54],[1,1.62,10.05],[2,1.59,5.99]],"ltp":1.62,"tv":1018.73,"id":72857115},{"batb":[[0,1.62,10.54],[1,1.61,14.05],[2,1.58,7.14]],"ltp":1.65,"tv":2064.06,"id":72857116}]}]}
{"op":"mcm","clk":"11877891982","pt":1724090826417,"mc":[{"id":"1.232018919","rc":[{"batb":[[0,1.64,4.54]],"ltp":1.62,"tv":1018.73,"id":72857115},{"batb":[[0,1.61,14.58],[1,1.58,7.14],[2,1.2,250]],"ltp":1.65,"tv":2064.06,"id":72857116}]}]}
{"op":"mcm","clk":"11877892329","pt":1724090828620,"mc":[{"id":"1.232018919","rc":[{"batb":[[0,1.65,10.54],[1,1.64,4],[2,1.62,10.05]],"ltp":1.62,"tv":1018.73,"id":72857115},{"batb":[[0,1.62,10.54],[1,1.61,14.05],[2,1.58,7.14]],"batl":[[0,2.58,1.67],[1,5,1.54],[2,6,0.77]],"ltp":1.65,"tv":2064.06,"id":72857116}]}]}
{"op":"mcm","clk":"11877892378","pt":1724090828930,"mc":[{"id":"1.232018919","rc":[{"batb":[[1,1.62,10.05],[2,1.59,5.99]],"ltp":1.62,"tv":1018.73,"id":72857115}]}]}
{"op":"mcm","clk":"11877892735","pt":1724090831330,"mc":[{"id":"1.232018919","rc":[{"batb":[[0,1.66,4.54],[1,1.65,10],[2,1.62,10.05]],"ltp":1.62,"tv":1018.73,"id":72857115}]}]}
{"op":"mcm","clk":"11877892842","pt":1724090832113,"mc":[{"id":"1.232018919","rc":[{"batb":[[1,1.62,10.05],[2,1.59,5.99]],"ltp":1.62,"tv":1018.73,"id":72857115},{"batb":[[0,1.61,14.58],[1,1.58,7.14],[2,1.2,250]],"ltp":1.65,"tv":2064.06,"id":72857116}]}]}
{"op":"mcm","clk":"11877893125","pt":1724090833628,"mc":[{"id":"1.232018919","rc":[{"batb":[[0,1.62,10.58],[1,1.59,5.99],[2,1.2,250]],"ltp":1.62,"tv":1018.73,"id":72857115}]}]}
{"op":"mcm","clk":"11877893483","pt":1724090836142,"mc":[{"id":"1.232018919","rc":[{"batb":[[0,1.63,14.54],[1,1.62,10.05],[2,1.59,5.99]],"batl":[[0,5,1.54],[1,6,0.77],[2,6,0]],"ltp":1.62,"tv":1018.73,"id":72857115},{"batb":[[0,1.62,10.54],[1,1.61,14.05],[2,1.58,7.14]],"batl":[[0,5,1.54],[1,6,0.77],[2,6,0]],"ltp":1.65,"tv":2064.06,"id":72857116}]}]}
{"op":"mcm","clk":"11877893795","pt":1724090838237,"mc":[{"id":"1.232018919","rc":[{"batb":[[0,1.63,10.54]],"ltp":1.62,"tv":1018.73,"id":72857115}]}]}
{"op":"mcm","clk":"11877893938","pt":1724090839338,"mc":[{"id":"1.232018919","rc":[{"batb":[[0,1.62,10.58],[1,1.59,5.99],[2,1.2,250]],"ltp":1.62,"tv":1018.73,"id":72857115},{"batb":[[0,1.61,14.58],[1,1.58,7.14],[2,1.2,250]],"ltp":1.65,"tv":2064.06,"id":72857116}]}]}
{"op":"mcm","clk":"11877894912","pt":1724090845627,"mc":[{"id":"1.232018919","rc":[{"batb":[[0,1.63,10.54],[1,1.62,10.05],[2,1.59,5.99]],"ltp":1.62,"tv":1018.73,"id":72857115},{"batb":[[0,1.62,10.54],[1,1.61,14.05],[2,1.58,7.14]],"ltp":1.65,"tv":2064.06,"id":72857116}]}]}
{"op":"mcm","clk":"11877895461","pt":1724090849349,"mc":[{"id":"1.232018919","rc":[{"batb":[[0,1.62,10.58],[1,1.59,5.99],[2,1.2,250]],"ltp":1.62,"tv":1018.73,"id":72857115},{"batb":[[0,1.61,14.58],[1,1.58,7.14],[2,1.2,250]],"ltp":1.65,"tv":2064.06,"id":72857116}]}]}
{"op":"mcm","clk":"11877895880","pt":1724090852367,"mc":[{"id":"1.232018919","rc":[{"batb":[[0,1.63,10.54],[1,1.62,10.05],[2,1.59,5.99]],"ltp":1.62,"tv":1018.73,"id":72857115},{"batb":[[0,1.62,10.54],[1,1.61,14.05],[2,1.58,7.14]],"ltp":1.65,"tv":2064.06,"id":72857116}]}]}
{"op":"mcm","clk":"11877896479","pt":1724090856042,"mc":[{"id":"1.232018919","rc":[{"batb":[[0,1.62,10.58],[1,1.59,5.99],[2,1.2,250]],"ltp":1.62,"tv":1018.73,"id":72857115},{"batb":[[0,1.61,14.58],[1,1.58,7.14],[2,1.2,250]],"ltp":1.65,"tv":2064.06,"id":72857116}]}]}
{"op":"mcm","clk":"11877896985","pt":1724090859608,"mc":[{"id":"1.232018919","rc":[{"batb":[[0,1.63,10.54],[1,1.62,10.05],[2,1.59,5.99]],"ltp":1.62,"tv":1018.73,"id":72857115},{"batb":[[0,1.62,10.54],[1,1.61,14.05],[2,1.58,7.14]],"ltp":1.65,"tv":2064.06,"id":72857116}]}]}
{"op":"mcm","clk":"11877897462","pt":1724090863053,"mc":[{"id":"1.232018919","rc":[{"batb":[[0,1.62,10.58],[1,1.59,5.99],[2,1.2,250]],"ltp":1.62,"tv":1018.73,"id":72857115},{"batb":[[0,1.61,14.58],[1,1.58,7.14],[2,1.2,250]],"ltp":1.65,"tv":2064.06,"id":72857116}]}]}
{"op":"mcm","clk":"11877897775","pt":1724090865247,"mc":[{"id":"1.232018919","rc":[{"batb":[[0,1.63,10.54],[1,1.62,10.05],[2,1.59,5.99]],"ltp":1.62,"tv":1018.73,"id":72857115},{"batb":[[0,1.62,10.54],[1,1.61,14.05],[2,1.58,7.14]],"ltp":1.65,"tv":2064.06,"id":72857116}]}]}
{"op":"mcm","clk":"11877898197","pt":1724090868451,"mc":[{"id":"1.232018919","rc":[{"batb":[[0,1.7,1.46]],"ltp":1.62,"tv":1018.73,"id":72857115},{"batb":[[0,1.61,14.58],[1,1.58,7.14],[2,1.2,250]],"ltp":1.65,"tv":2064.06,"id":72857116}]}]}
{"op":"mcm","clk":"11877898687","pt":1724090871354,"mc":[{"id":"1.232018919","rc":[{"batb":[[0,1.62,10.54],[1,1.61,14.05],[2,1.58,7.14]],"ltp":1.65,"tv":2064.06,"id":72857116}]}]}
{"op":"mcm","clk":"11877899185","pt":1724090874864,"mc":[{"id":"1.232018919","rc":[{"batb":[[0,1.61,14.58],[1,1.58,7.14],[2,1.2,250]],"ltp":1.65,"tv":2064.06,"id":72857116}]}]}
{"op":"mcm","clk":"11877899647","pt":1724090877897,"mc":[{"id":"1.232018919","rc":[{"batb":[[0,1.62,10.54],[1,1.61,14.05],[2,1.58,7.14]],"ltp":1.65,"tv":2064.06,"id":72857116}]}]}
{"op":"mcm","clk":"11877900189","pt":1724090881464,"mc":[{"id":"1.232018919","rc":[{"batb":[[0,1.64,1.38]],"ltp":1.65,"tv":2064.06,"id":72857116}]}]}
{"op":"mcm","clk":"11877909263","pt":1724090938423,"mc":[{"id":"1.232018919","rc":[{"batb":[[0,1.7,1.97]],"ltp":1.62,"tv":1018.73,"id":72857115}]}]}
{"op":"mcm","clk":"11877915757","pt":1724090981177,"mc":[{"id":"1.232018919","rc":[{"batb":[[0,1.7,1.43]],"ltp":1.62,"tv":1018.73,"id":72857115},{"batb":[[0,1.62,10.84]],"ltp":1.65,"tv":2064.06,"id":72857116}]}]}
{"op":"mcm","clk":"11877916239","pt":1724090984544,"mc":[{"id":"1.232018919","rc":[{"batb":[[0,1.61,14.89],[1,1.58,7.14],[2,1.2,250]],"ltp":1.65,"tv":2064.06,"id":72857116}]}]}
{"op":"mcm","clk":"11877917005","pt":1724090989578,"mc":[{"id":"1.232018919","rc":[{"batb":[[0,1.62,10.84],[1,1.61,14.05],[2,1.58,7.14]],"ltp":1.65,"tv":2064.06,"id":72857116}]}]}
{"op":"mcm","clk":"11877917528","pt":1724090993194,"mc":[{"id":"1.232018919","rc":[{"batb":[[0,1.61,14.89],[1,1.58,7.14],[2,1.2,250]],"ltp":1.65,"tv":2064.06,"id":72857116}]}]}
{"op":"mcm","clk":"11877917895","pt":1724090995456,"mc":[{"id":"1.232018919","rc":[{"batb":[[0,1.62,10.84],[1,1.61,14.05],[2,1.58,7.14]],"ltp":1.65,"tv":2064.06,"id":72857116}]}]}
{"op":"mcm","clk":"11877918421","pt":1724090998865,"mc":[{"id":"1.232018919","rc":[{"batb":[[0,1.61,14.89],[1,1.58,7.14],[2,1.2,250]],"ltp":1.65,"tv":2064.06,"id":72857116}]}]}
{"op":"mcm","clk":"11877919343","pt":1724091004367,"mc":[{"id":"1.232018919","rc":[{"batb":[[0,1.62,10.84],[1,1.61,14.05],[2,1.58,7.14]],"ltp":1.65,"tv":2064.06,"id":72857116}]}]}
{"op":"mcm","clk":"11877919973","pt":1724091008086,"mc":[{"id":"1.232018919","rc":[{"batb":[[0,1.61,14.89],[1,1.58,7.14],[2,1.2,250]],"ltp":1.65,"tv":2064.06,"id":72857116}]}]}
{"op":"mcm","clk":"11877920531","pt":1724091011173,"mc":[{"id":"1.232018919","rc":[{"batb":[[0,1.62,10.84],[1,1.61,14.05],[2,1.58,7.14]],"ltp":1.65,"tv":2064.06,"id":72857116}]}]}
{"op":"mcm","clk":"11877921095","pt":1724091014595,"mc":[{"id":"1.232018919","rc":[{"batb":[[0,1.61,14.89],[1,1.58,7.14],[2,1.2,250]],"ltp":1.65,"tv":2064.06,"id":72857116}]}]}
{"op":"mcm","clk":"11877921556","pt":1724091017429,"mc":[{"id":"1.232018919","rc":[{"batb":[[0,1.62,10.84],[1,1.61,14.05],[2,1.58,7.14]],"ltp":1.65,"tv":2064.06,"id":72857116}]}]}
{"op":"mcm","clk":"11877922111","pt":1724091020796,"mc":[{"id":"1.232018919","rc":[{"batb":[[0,1.61,14.89],[1,1.58,7.14],[2,1.2,250]],"ltp":1.65,"tv":2064.06,"id":72857116}]}]}
{"op":"mcm","clk":"11877922871","pt":1724091025413,"mc":[{"id":"1.232018919","rc":[{"batb":[[0,1.62,10.84],[1,1.61,14.05],[2,1.58,7.14]],"ltp":1.65,"tv":2064.06,"id":72857116}]}]}
{"op":"mcm","clk":"11877923397","pt":1724091028916,"mc":[{"id":"1.232018919","rc":[{"batb":[[0,1.61,14.89],[1,1.58,7.14],[2,1.2,250]],"ltp":1.65,"tv":2064.06,"id":72857116}]}]}
{"op":"mcm","clk":"11877924168","pt":1724091033806,"mc":[{"id":"1.232018919","rc":[{"batb":[[0,1.62,10.84],[1,1.61,14.05],[2,1.58,7.14]],"ltp":1.65,"tv":2064.06,"id":72857116}]}]}
{"op":"mcm","clk":"11877924741","pt":1724091037825,"mc":[{"id":"1.232018919","rc":[{"batb":[[0,1.61,14.89],[1,1.58,7.14],[2,1.2,250]],"ltp":1.65,"tv":2064.06,"id":72857116}]}]}
{"op":"mcm","clk":"11877925537","pt":1724091043231,"mc":[{"id":"1.232018919","rc":[{"batb":[[0,1.62,10.84],[1,1.61,14.05],[2,1.58,7.14]],"ltp":1.65,"tv":2064.06,"id":72857116}]}]}
{"op":"mcm","clk":"11877926106","pt":1724091046839,"mc":[{"id":"1.232018919","rc":[{"batb":[[0,1.61,14.89],[1,1.58,7.14],[2,1.2,250]],"ltp":1.65,"tv":2064.06,"id":72857116}]}]}
{"op":"mcm","clk":"11877929039","pt":1724091066459,"mc":[{"id":"1.232018919","rc":[{"batb":[[0,1.62,10.84],[1,1.61,14.05],[2,1.58,7.14]],"ltp":1.65,"tv":2064.06,"id":72857116}]}]}
{"op":"mcm","clk":"11877929696","pt":1724091070134,"mc":[{"id":"1.232018919","rc":[{"batb":[[0,1.61,14.89],[1,1.58,7.14],[2,1.2,250]],"ltp":1.65,"tv":2064.06,"id":72857116}]}]}
{"op":"mcm","clk":"11877931677","pt":1724091083183,"mc":[{"id":"1.232018919","rc":[{"batb":[[0,1.62,10.84],[1,1.61,14.05],[2,1.58,7.14]],"ltp":1.65,"tv":2064.06,"id":72857116}]}]}
{"op":"mcm","clk":"11877932249","pt":1724091086975,"mc":[{"id":"1.232018919","rc":[{"batb":[[0,1.61,14.89],[1,1.58,7.14],[2,1.2,250]],"ltp":1.65,"tv":2064.06,"id":72857116}]}]}
{"op":"mcm","clk":"11877932590","pt":1724091089181,"mc":[{"id":"1.232018919","rc":[{"batb":[[0,1.62,10.84],[1,1.61,14.05],[2,1.58,7.14]],"ltp":1.65,"tv":2064.06,"id":72857116}]}]}
{"op":"mcm","clk":"11877933113","pt":1724091092805,"mc":[{"id":"1.232018919","rc":[{"batb":[[0,1.61,14.89],[1,1.58,7.14],[2,1.2,250]],"ltp":1.65,"tv":2064.06,"id":72857116}]}]}
{"op":"mcm","clk":"11877934718","pt":1724091103470,"mc":[{"id":"1.232018919","rc":[{"batb":[[0,1.62,10.84],[1,1.61,14.05],[2,1.58,7.14]],"ltp":1.65,"tv":2064.06,"id":72857116}]}]}
{"op":"mcm","clk":"11877935310","pt":1724091107383,"mc":[{"id":"1.232018919","rc":[{"batb":[[0,1.61,14.89],[1,1.58,7.14],[2,1.2,250]],"ltp":1.65,"tv":2064.06,"id":72857116}]}]}
{"op":"mcm","clk":"11877937904","pt":1724091124126,"mc":[{"id":"1.232018919","rc":[{"batb":[[0,1.62,10.84],[1,1.61,14.05],[2,1.58,7.14]],"ltp":1.65,"tv":2064.06,"id":72857116}]}]}
{"op":"mcm","clk":"11877938471","pt":1724091127640,"mc":[{"id":"1.232018919","rc":[{"batb":[[0,1.61,14.89],[1,1.58,7.14],[2,1.2,250]],"ltp":1.65,"tv":2064.06,"id":72857116}]}]}
{"op":"mcm","clk":"11877939090","pt":1724091131622,"mc":[{"id":"1.232018919","rc":[{"batb":[[0,1.62,10.84],[1,1.61,14.05],[2,1.58,7.14]],"ltp":1.65,"tv":2064.06,"id":72857116}]}]}
{"op":"mcm","clk":"11877939692","pt":1724091135547,"mc":[{"id":"1.232018919","rc":[{"batb":[[0,1.61,14.89],[1,1.58,7.14],[2,1.2,250]],"ltp":1.65,"tv":2064.06,"id":72857116}]}]}
{"op":"mcm","clk":"11877941191","pt":1724091145036,"mc":[{"id":"1.232018919","rc":[{"batb":[[0,1.62,10.84],[1,1.61,14.05],[2,1.58,7.14]],"ltp":1.65,"tv":2064.06,"id":72857116}]}]}
{"op":"mcm","clk":"11877941754","pt":1724091148856,"mc":[{"id":"1.232018919","rc":[{"batb":[[0,1.61,14.89],[1,1.58,7.14],[2,1.2,250]],"ltp":1.65,"tv":2064.06,"id":72857116}]}]}
{"op":"mcm","clk":"11877942103","pt":1724091151140,"mc":[{"id":"1.232018919","rc":[{"batb":[[0,1.62,10.84],[1,1.61,14.05],[2,1.58,7.14]],"ltp":1.65,"tv":2064.06,"id":72857116}]}]}
{"op":"mcm","clk":"11877942626","pt":1724091154543,"mc":[{"id":"1.232018919","rc":[{"batb":[[0,1.61,14.89],[1,1.58,7.14],[2,1.2,250]],"ltp":1.65,"tv":2064.06,"id":72857116}]}]}
{"op":"mcm","clk":"11877943070","pt":1724091157059,"mc":[{"id":"1.232018919","rc":[{"batb":[[0,1.62,10.84],[1,1.61,14.05],[2,1.58,7.14]],"ltp":1.65,"tv":2064.06,"id":72857116}]}]}
{"op":"mcm","clk":"11877943624","pt":1724091160553,"mc":[{"id":"1.232018919","rc":[{"batb":[[0,1.61,14.89],[1,1.58,7.14],[2,1.2,250]],"ltp":1.65,"tv":2064.06,"id":72857116}]}]}
{"op":"mcm","clk":"11877944192","pt":1724091164169,"mc":[{"id":"1.232018919","rc":[{"batb":[[0,1.62,10.84],[1,1.61,14.05],[2,1.58,7.14]],"ltp":1.65,"tv":2064.06,"id":72857116}]}]}
{"op":"mcm","clk":"11877944778","pt":1724091167769,"mc":[{"id":"1.232018919","rc":[{"batb":[[0,1.61,14.89],[1,1.58,7.14],[2,1.2,250]],"ltp":1.65,"tv":2064.06,"id":72857116}]}]}
{"op":"mcm","clk":"11877945521","pt":1724091172586,"mc":[{"id":"1.232018919","rc":[{"batb":[[0,1.62,10.84],[1,1.61,14.05],[2,1.58,7.14]],"ltp":1.65,"tv":2064.06,"id":72857116}]}]}
{"op":"mcm","clk":"11877946135","pt":1724091176303,"mc":[{"id":"1.232018919","rc":[{"batb":[[0,1.61,14.89],[1,1.58,7.14],[2,1.2,250]],"ltp":1.65,"tv":2064.06,"id":72857116}]}]}
{"op":"mcm","clk":"11877946623","pt":1724091179497,"mc":[{"id":"1.232018919","rc":[{"batb":[[0,1.62,10.84],[1,1.61,14.05],[2,1.58,7.14]],"ltp":1.65,"tv":2064.06,"id":72857116}]}]}
{"op":"mcm","clk":"11877947241","pt":1724091183407,"mc":[{"id":"1.232018919","rc":[{"batb":[[0,1.61,14.89],[1,1.58,7.14],[2,1.2,250]],"ltp":1.65,"tv":2064.06,"id":72857116}]}]}
{"op":"mcm","clk":"11877949460","pt":1724091197097,"mc":[{"id":"1.232018919","rc":[{"batb":[[0,1.62,10.84],[1,1.61,14.05],[2,1.58,7.14]],"ltp":1.65,"tv":2064.06,"id":72857116}]}]}
{"op":"mcm","clk":"11877950040","pt":1724091200808,"mc":[{"id":"1.232018919","rc":[{"batb":[[0,1.61,14.89],[1,1.58,7.14],[2,1.2,250]],"ltp":1.65,"tv":2064.06,"id":72857116}]}]}
{"op":"mcm","clk":"11877951563","pt":1724091209350,"mc":[{"id":"1.232018919","rc":[{"batb":[[0,1.62,10.84],[1,1.61,14.05],[2,1.58,7.14]],"ltp":1.65,"tv":2064.06,"id":72857116}]}]}
{"op":"mcm","clk":"11877952421","pt":1724091212933,"mc":[{"id":"1.232018919","rc":[{"batb":[[0,1.61,14.89],[1,1.58,7.14],[2,1.2,250]],"ltp":1.65,"tv":2064.06,"id":72857116}]}]}
{"op":"mcm","clk":"11877952933","pt":1724091215857,"mc":[{"id":"1.232018919","rc":[{"batb":[[0,1.62,10.84],[1,1.61,14.05],[2,1.58,7.14]],"ltp":1.65,"tv":2064.06,"id":72857116}]}]}
{"op":"mcm","clk":"11877953532","pt":1724091219540,"mc":[{"id":"1.232018919","rc":[{"batb":[[0,1.61,14.89],[1,1.58,7.14],[2,1.2,250]],"ltp":1.65,"tv":2064.06,"id":72857116}]}]}
{"op":"mcm","clk":"11877955336","pt":1724091230788,"mc":[{"id":"1.232018919","rc":[{"batb":[[0,1.62,10.84],[1,1.61,14.05],[2,1.58,7.14]],"ltp":1.65,"tv":2064.06,"id":72857116}]}]}
{"op":"mcm","clk":"11877955892","pt":1724091234278,"mc":[{"id":"1.232018919","rc":[{"batb":[[0,1.61,14.89],[1,1.58,7.14],[2,1.2,250]],"ltp":1.65,"tv":2064.06,"id":72857116}]}]}
{"op":"mcm","clk":"11877956401","pt":1724091237508,"mc":[{"id":"1.232018919","rc":[{"batb":[[0,1.62,10.84],[1,1.61,14.05],[2,1.58,7.14]],"ltp":1.65,"tv":2064.06,"id":72857116}]}]}
{"op":"mcm","clk":"11877956996","pt":1724091241296,"mc":[{"id":"1.232018919","rc":[{"batb":[[0,1.61,14.89],[1,1.58,7.14],[2,1.2,250]],"ltp":1.65,"tv":2064.06,"id":72857116}]}]}
{"op":"mcm","clk":"11877957463","pt":1724091243902,"mc":[{"id":"1.232018919","rc":[{"batb":[[0,1.62,10.84],[1,1.61,14.05],[2,1.58,7.14]],"ltp":1.65,"tv":2064.06,"id":72857116}]}]}
{"op":"mcm","clk":"11877958099","pt":1724091247626,"mc":[{"id":"1.232018919","rc":[{"batb":[[0,1.61,14.89],[1,1.58,7.14],[2,1.2,250]],"ltp":1.65,"tv":2064.06,"id":72857116}]}]}
{"op":"mcm","clk":"11877958666","pt":1724091251037,"mc":[{"id":"1.232018919","rc":[{"batb":[[0,1.62,10.84],[1,1.61,14.05],[2,1.58,7.14]],"ltp":1.65,"tv":2064.06,"id":72857116}]}]}
{"op":"mcm","clk":"11877959273","pt":1724091254834,"mc":[{"id":"1.232018919","rc":[{"batb":[[0,1.61,14.89],[1,1.58,7.14],[2,1.2,250]],"ltp":1.65,"tv":2064.06,"id":72857116}]}]}
{"op":"mcm","clk":"11877960782","pt":1724091264153,"mc":[{"id":"1.232018919","rc":[{"batb":[[0,1.62,10.84],[1,1.61,14.05],[2,1.58,7.14]],"ltp":1.65,"tv":2064.06,"id":72857116}]}]}
{"op":"mcm","clk":"11877961395","pt":1724091267745,"mc":[{"id":"1.232018919","rc":[{"batb":[[0,1.61,14.89],[1,1.58,7.14],[2,1.2,250]],"ltp":1.65,"tv":2064.06,"id":72857116}]}]}
{"op":"mcm","clk":"11877961812","pt":1724091270363,"mc":[{"id":"1.232018919","rc":[{"batb":[[0,1.62,10.84],[1,1.61,14.05],[2,1.58,7.14]],"ltp":1.65,"tv":2064.06,"id":72857116}]}]}
{"op":"mcm","clk":"11877962388","pt":1724091274139,"mc":[{"id":"1.232018919","rc":[{"batb":[[0,1.61,14.89],[1,1.58,7.14],[2,1.2,250]],"ltp":1.65,"tv":2064.06,"id":72857116}]}]}
{"op":"mcm","clk":"11877964597","pt":1724091288098,"mc":[{"id":"1.232018919","rc":[{"batb":[[0,1.62,10.84],[1,1.61,14.05],[2,1.58,7.14]],"ltp":1.65,"tv":2064.06,"id":72857116}]}]}
{"op":"mcm","clk":"11877965099","pt":1724091291566,"mc":[{"id":"1.232018919","rc":[{"batb":[[0,1.61,14.89],[1,1.58,7.14],[2,1.2,250]],"ltp":1.65,"tv":2064.06,"id":72857116}]}]}
{"op":"mcm","clk":"11877965661","pt":1724091295180,"mc":[{"id":"1.232018919","rc":[{"batb":[[0,1.62,10.84],[1,1.61,14.05],[2,1.58,7.14]],"ltp":1.65,"tv":2064.06,"id":72857116}]}]}
{"op":"mcm","clk":"11877966219","pt":1724091298760,"mc":[{"id":"1.232018919","rc":[{"batb":[[0,1.61,14.89],[1,1.58,7.14],[2,1.2,250]],"ltp":1.65,"tv":2064.06,"id":72857116}]}]}
{"op":"mcm","clk":"11877966836","pt":1724091302194,"mc":[{"id":"1.232018919","rc":[{"batb":[[0,1.62,10.84],[1,1.61,14.05],[2,1.58,7.14]],"ltp":1.65,"tv":2064.06,"id":72857116}]}]}
{"op":"mcm","clk":"11877967486","pt":1724091305927,"mc":[{"id":"1.232018919","rc":[{"batb":[[0,1.61,14.89],[1,1.58,7.14],[2,1.2,250]],"ltp":1.65,"tv":2064.06,"id":72857116}]}]}
{"op":"mcm","clk":"11877968213","pt":1724091310192,"mc":[{"id":"1.232018919","rc":[{"batb":[[0,1.62,10.84],[1,1.61,14.05],[2,1.58,7.14]],"ltp":1.65,"tv":2064.06,"id":72857116}]}]}
{"op":"mcm","clk":"11877968822","pt":1724091313913,"mc":[{"id":"1.232018919","rc":[{"batb":[[0,1.61,14.89],[1,1.58,7.14],[2,1.2,250]],"ltp":1.65,"tv":2064.06,"id":72857116}]}]}
{"op":"mcm","clk":"11877969495","pt":1724091317809,"mc":[{"id":"1.232018919","rc":[{"batb":[[0,1.62,10.84],[1,1.61,14.05],[2,1.58,7.14]],"ltp":1.65,"tv":2064.06,"id":72857116}]}]}
{"op":"mcm","clk":"11877970063","pt":1724091321185,"mc":[{"id":"1.232018919","rc":[{"batb":[[0,1.61,14.89],[1,1.58,7.14],[2,1.2,250]],"ltp":1.65,"tv":2064.06,"id":72857116}]}]}
{"op":"mcm","clk":"11877970515","pt":1724091323808,"mc":[{"id":"1.232018919","rc":[{"batb":[[0,1.62,10.84],[1,1.61,14.05],[2,1.58,7.14]],"ltp":1.65,"tv":2064.06,"id":72857116}]}]}
{"op":"mcm","clk":"11877971106","pt":1724091327431,"mc":[{"id":"1.232018919","rc":[{"batb":[[0,1.61,14.89],[1,1.58,7.14],[2,1.2,250]],"ltp":1.65,"tv":2064.06,"id":72857116}]}]}
{"op":"mcm","clk":"11877972607","pt":1724091336386,"mc":[{"id":"1.232018919","rc":[{"batb":[[0,1.62,10.84],[1,1.61,14.05],[2,1.58,7.14]],"ltp":1.65,"tv":2064.06,"id":72857116}]}]}
{"op":"mcm","clk":"11877972791","pt":1724091337445,"mc":[{"id":"1.232018919","rc":[{"batb":[[1,1.59,5.99],[2,1.2,250]],"ltp":1.62,"tv":1018.73,"id":72857115},{"batb":[[1,1.58,7.14],[2,1.2,250]],"ltp":1.65,"tv":2064.06,"id":72857116}]}]}
{"op":"mcm","clk":"11877973234","pt":1724091340026,"mc":[{"id":"1.232018919","rc":[{"batb":[[0,1.58,7.98],[1,1.2,250],[2,1.11,24.84]],"ltp":1.65,"tv":2064.06,"id":72857116}]}]}
{"op":"mcm","clk":"11877974658","pt":1724091348232,"mc":[{"id":"1.232018919","rc":[{"batb":[[0,1.59,10.84],[1,1.58,7.14],[2,1.2,250]],"ltp":1.65,"tv":2064.06,"id":72857116}]}]}
{"op":"mcm","clk":"11877975331","pt":1724091352149,"mc":[{"id":"1.232018919","rc":[{"batb":[[0,1.58,7.98],[1,1.2,250],[2,1.11,24.84]],"ltp":1.65,"tv":2064.06,"id":72857116}]}]}
{"op":"mcm","clk":"11877975979","pt":1724091355535,"mc":[{"id":"1.232018919","rc":[{"batb":[[0,1.59,10.84],[1,1.58,7.14],[2,1.2,250]],"ltp":1.65,"tv":2064.06,"id":72857116}]}]}
{"op":"mcm","clk":"11877976616","pt":1724091359315,"mc":[{"id":"1.232018919","rc":[{"batb":[[0,1.58,7.98],[1,1.2,250],[2,1.11,24.84]],"ltp":1.65,"tv":2064.06,"id":72857116}]}]}
{"op":"mcm","clk":"11877977084","pt":1724091362258,"mc":[{"id":"1.232018919","rc":[{"batb":[[0,1.59,10.84],[1,1.58,7.14],[2,1.2,250]],"ltp":1.65,"tv":2064.06,"id":72857116}]}]}
{"op":"mcm","clk":"11877977715","pt":1724091365846,"mc":[{"id":"1.232018919","rc":[{"batb":[[0,1.58,7.98],[1,1.2,250],[2,1.11,24.84]],"ltp":1.65,"tv":2064.06,"id":72857116}]}]}
{"op":"mcm","clk":"11877978262","pt":1724091369170,"mc":[{"id":"1.232018919","rc":[{"batb":[[0,1.59,10.84],[1,1.58,7.14],[2,1.2,250]],"batl":[[1,5.9,4.27],[2,6,0.77]],"ltp":1.65,"tv":2064.06,"id":72857116}]}]}
{"op":"mcm","clk":"11877978566","pt":1724091371096,"mc":[{"id":"1.232018919","rc":[{"batl":[[1,6,0.77],[2,6,0]],"ltp":1.65,"tv":2064.06,"id":72857116}]}]}
{"op":"mcm","clk":"11877978834","pt":1724091372662,"mc":[{"id":"1.232018919","rc":[{"batb":[[0,1.58,7.98],[1,1.2,250],[2,1.11,24.84]],"ltp":1.65,"tv":2064.06,"id":72857116}]}]}
{"op":"mcm","clk":"11877979360","pt":1724091375768,"mc":[{"id":"1.232018919","rc":[{"batl":[[1,5.9,4.28],[2,6,0.77]],"ltp":1.62,"tv":1018.73,"id":72857115},{"batb":[[0,1.59,10.84],[1,1.58,7.14],[2,1.2,250]],"ltp":1.65,"tv":2064.06,"id":72857116}]}]}
{"op":"mcm","clk":"11877979820","pt":1724091378551,"mc":[{"id":"1.232018919","rc":[{"batl":[[1,6,0.77],[2,6,0]],"ltp":1.62,"tv":1018.73,"id":72857115}]}]}
{"op":"mcm","clk":"11877979919","pt":1724091379173,"mc":[{"id":"1.232018919","rc":[{"batb":[[0,1.58,7.98],[1,1.2,250],[2,1.11,24.84]],"ltp":1.65,"tv":2064.06,"id":72857116}]}]}
{"op":"mcm","clk":"11877981271","pt":1724091387173,"mc":[{"id":"1.232018919","rc":[{"batb":[[0,1.59,10.84],[1,1.58,7.14],[2,1.2,250]],"ltp":1.65,"tv":2064.06,"id":72857116}]}]}
{"op":"mcm","clk":"11877981904","pt":1724091390737,"mc":[{"id":"1.232018919","rc":[{"batb":[[0,1.58,7.98],[1,1.2,250],[2,1.11,24.84]],"ltp":1.65,"tv":2064.06,"id":72857116}]}]}
{"op":"mcm","clk":"11877982735","pt":1724091395551,"mc":[{"id":"1.232018919","rc":[{"batb":[[0,1.59,10.84],[1,1.58,7.14],[2,1.2,250]],"ltp":1.65,"tv":2064.06,"id":72857116}]}]}
{"op":"mcm","clk":"11877983300","pt":1724091399179,"mc":[{"id":"1.232018919","rc":[{"batb":[[0,1.58,7.98],[1,1.2,250],[2,1.11,24.84]],"ltp":1.65,"tv":2064.06,"id":72857116}]}]}
{"op":"mcm","clk":"11877984064","pt":1724091403852,"mc":[{"id":"1.232018919","rc":[{"batb":[[0,1.59,10.84],[1,1.58,7.14],[2,1.2,250]],"ltp":1.65,"tv":2064.06,"id":72857116}]}]}
{"op":"mcm","clk":"11877984594","pt":1724091407259,"mc":[{"id":"1.232018919","rc":[{"batb":[[0,1.58,7.98],[1,1.2,250],[2,1.11,24.84]],"ltp":1.65,"tv":2064.06,"id":72857116}]}]}
{"op":"mcm","clk":"11877984987","pt":1724091409741,"mc":[{"id":"1.232018919","rc":[{"batb":[[0,1.59,10.84],[1,1.58,7.14],[2,1.2,250]],"ltp":1.65,"tv":2064.06,"id":72857116}]}]}
{"op":"mcm","clk":"11877985558","pt":1724091413381,"mc":[{"id":"1.232018919","rc":[{"batb":[[0,1.58,7.98],[1,1.2,250],[2,1.11,24.84]],"ltp":1.65,"tv":2064.06,"id":72857116}]}]}
{"op":"mcm","clk":"11877986600","pt":1724091419990,"mc":[{"id":"1.232018919","rc":[{"batb":[[0,1.59,10.84],[1,1.58,7.14],[2,1.2,250]],"batl":[[1,5.9,4.27],[2,6,0.77]],"ltp":1.65,"tv":2064.06,"id":72857116}]}]}
{"op":"mcm","clk":"11877986877","pt":1724091421679,"mc":[{"id":"1.232018919","rc":[{"batl":[[1,6,0.77],[2,6,0]],"ltp":1.65,"tv":2064.06,"id":72857116}]}]}
{"op":"mcm","clk":"11877987223","pt":1724091423358,"mc":[{"id":"1.232018919","rc":[{"batb":[[0,1.58,7.98],[1,1.2,250],[2,1.11,24.84]],"ltp":1.65,"tv":2064.06,"id":72857116}]}]}
{"op":"mcm","clk":"11877987635","pt":1724091425875,"mc":[{"id":"1.232018919","rc":[{"batb":[[0,1.59,10.84],[1,1.58,7.14],[2,1.2,250]],"ltp":1.65,"tv":2064.06,"id":72857116}]}]}
{"op":"mcm","clk":"11877988236","pt":1724091429695,"mc":[{"id":"1.232018919","rc":[{"batb":[[0,1.58,7.98],[1,1.2,250],[2,1.11,24.84]],"ltp":1.65,"tv":2064.06,"id":72857116}]}]}
{"op":"mcm","clk":"11877988423","pt":1724091430957,"mc":[{"id":"1.232018919","rc":[{"batl":[[1,5.9,4.28],[2,6,0.77]],"ltp":1.62,"tv":1018.73,"id":72857115}]}]}
{"op":"mcm","clk":"11877988767","pt":1724091433209,"mc":[{"id":"1.232018919","rc":[{"batb":[[0,1.59,10.84],[1,1.58,7.14],[2,1.2,250]],"ltp":1.65,"tv":2064.06,"id":72857116}]}]}
{"op":"mcm","clk":"11877988967","pt":1724091434483,"mc":[{"id":"1.232018919","rc":[{"batl":[[1,6,0.77],[2,6,0]],"ltp":1.62,"tv":1018.73,"id":72857115}]}]}
{"op":"mcm","clk":"11877989337","pt":1724091436699,"mc":[{"id":"1.232018919","rc":[{"batb":[[0,1.58,7.98],[1,1.2,250],[2,1.11,24.84]],"ltp":1.65,"tv":2064.06,"id":72857116}]}]}
{"op":"mcm","clk":"11877989899","pt":1724091440008,"mc":[{"id":"1.232018919","rc":[{"batb":[[0,1.59,10.84],[1,1.58,7.14],[2,1.2,250]],"ltp":1.65,"tv":2064.06,"id":72857116}]}]}
{"op":"mcm","clk":"11877990495","pt":1724091443516,"mc":[{"id":"1.232018919","rc":[{"batb":[[0,1.58,7.98],[1,1.2,250],[2,1.11,24.84]],"ltp":1.65,"tv":2064.06,"id":72857116}]}]}
{"op":"mcm","clk":"11877992530","pt":1724091455502,"mc":[{"id":"1.232018919","rc":[{"batb":[[0,1.59,10.84],[1,1.58,7.14],[2,1.2,250]],"ltp":1.65,"tv":2064.06,"id":72857116}]}]}
{"op":"mcm","clk":"11877992698","pt":1724091456503,"mc":[{"id":"1.232018919","rc":[{"batb":[[0,1.64,1.38],[1,1.59,10],[2,1.58,7.14]],"ltp":1.65,"tv":2064.06,"id":72857116}]}]}
{"op":"mcm","clk":"11877993069","pt":1724091458796,"mc":[{"id":"1.232018919","rc":[{"batb":[[1,1.58,7.14],[2,1.2,250]],"ltp":1.65,"tv":2064.06,"id":72857116}]}]}
{"op":"mcm","clk":"11877994621","pt":1724091469068,"mc":[{"id":"1.232018919","rc":[{"batb":[[1,1.59,14.52],[2,1.58,7.14]],"ltp":1.65,"tv":2064.06,"id":72857116}]}]}
{"op":"mcm","clk":"11877994842","pt":1724091470436,"mc":[{"id":"1.232018919","rc":[{"batl":[[1,5.9,4.27],[2,6,0.77]],"ltp":1.65,"tv":2064.06,"id":72857116}]}]}
{"op":"mcm","clk":"11877995484","pt":1724091474004,"mc":[{"id":"1.232018919","rc":[{"batl":[[1,6,0.77],[2,6,0]],"ltp":1.65,"tv":2064.06,"id":72857116}]}]}
{"op":"mcm","clk":"11877998033","pt":1724091489745,"mc":[{"id":"1.232018919","rc":[{"batb":[[0,1.6,10.84]],"ltp":1.65,"tv":2064.06,"id":72857116}]}]}
{"op":"mcm","clk":"11877998548","pt":1724091492938,"mc":[{"id":"1.232018919","rc":[{"batb":[[0,1.59,15.36],[1,1.58,7.14],[2,1.2,250]],"ltp":1.65,"tv":2064.06,"id":72857116}]}]}
{"op":"mcm","clk":"11877999070","pt":1724091496066,"mc":[{"id":"1.232018919","rc":[{"batb":[[0,1.6,10.84],[1,1.59,14.52],[2,1.58,7.14]],"ltp":1.65,"tv":2064.06,"id":72857116}]}]}
{"op":"mcm","clk":"11877999644","pt":1724091499375,"mc":[{"id":"1.232018919","rc":[{"batb":[[0,1.59,15.36],[1,1.58,7.14],[2,1.2,250]],"ltp":1.65,"tv":2064.06,"id":72857116}]}]}
{"op":"mcm","clk":"11878000092","pt":1724091502390,"mc":[{"id":"1.232018919","rc":[{"batb":[[0,1.6,10.84],[1,1.59,14.52],[2,1.58,7.14]],"ltp":1.65,"tv":2064.06,"id":72857116}]}]}
{"op":"mcm","clk":"11878000648","pt":1724091506004,"mc":[{"id":"1.232018919","rc":[{"batb":[[0,1.59,15.36],[1,1.58,7.14],[2,1.2,250]],"ltp":1.65,"tv":2064.06,"id":72857116}]}]}
{"op":"mcm","clk":"11878001385","pt":1724091509672,"mc":[{"id":"1.232018919","rc":[{"batb":[[0,1.6,10.84],[1,1.59,14.52],[2,1.58,7.14]],"ltp":1.65,"tv":2064.06,"id":72857116}]}]}
{"op":"mcm","clk":"11878002071","pt":1724091513301,"mc":[{"id":"1.232018919","rc":[{"batb":[[0,1.59,15.36],[1,1.58,7.14],[2,1.2,250]],"ltp":1.65,"tv":2064.06,"id":72857116}]}]}
{"op":"mcm","clk":"11878003211","pt":1724091520192,"mc":[{"id":"1.232018919","rc":[{"batb":[[0,1.6,10.84],[1,1.59,14.52],[2,1.58,7.14]],"batl":[[1,5.9,4.27],[2,6,0.77]],"ltp":1.65,"tv":2064.06,"id":72857116}]}]}
{"op":"mcm","clk":"11878003739","pt":1724091523393,"mc":[{"id":"1.232018919","rc":[{"batb":[[0,1.59,15.36],[1,1.58,7.14],[2,1.2,250]],"ltp":1.65,"tv":2064.06,"id":72857116}]}]}
{"op":"mcm","clk":"11878003815","pt":1724091523906,"mc":[{"id":"1.232018919","rc":[{"batl":[[1,6,0.77],[2,6,0]],"ltp":1.65,"tv":2064.06,"id":72857116}]}]}
{"op":"mcm","clk":"11878004349","pt":1724091527419,"mc":[{"id":"1.232018919","rc":[{"batb":[[0,1.6,10.84],[1,1.59,14.52],[2,1.58,7.14]],"ltp":1.65,"tv":2064.06,"id":72857116}]}]}
{"op":"mcm","clk":"11878004888","pt":1724091531083,"mc":[{"id":"1.232018919","rc":[{"batb":[[0,1.59,15.36],[1,1.58,7.14],[2,1.2,250]],"ltp":1.65,"tv":2064.06,"id":72857116}]}]}
{"op":"mcm","clk":"11878005623","pt":1724091536002,"mc":[{"id":"1.232018919","rc":[{"batb":[[0,1.6,10.84],[1,1.59,14.52],[2,1.58,7.14]],"ltp":1.65,"tv":2064.06,"id":72857116}]}]}
{"op":"mcm","clk":"11878006165","pt":1724091539566,"mc":[{"id":"1.232018919","rc":[{"batb":[[0,1.59,15.36],[1,1.58,7.14],[2,1.2,250]],"ltp":1.65,"tv":2064.06,"id":72857116}]}]}
{"op":"mcm","clk":"11878006555","pt":1724091541939,"mc":[{"id":"1.232018919","rc":[{"batb":[[0,1.6,10.84],[1,1.59,14.52],[2,1.58,7.14]],"ltp":1.65,"tv":2064.06,"id":72857116}]}]}
{"op":"mcm","clk":"11878007161","pt":1724091545707,"mc":[{"id":"1.232018919","rc":[{"batb":[[0,1.59,15.36],[1,1.58,7.14],[2,1.2,250]],"ltp":1.65,"tv":2064.06,"id":72857116}]}]}
{"op":"mcm","clk":"11878008833","pt":1724091556364,"mc":[{"id":"1.232018919","rc":[{"batb":[[0,1.6,10.84],[1,1.59,14.52],[2,1.58,7.14]],"ltp":1.65,"tv":2064.06,"id":72857116}]}]}
{"op":"mcm","clk":"11878009430","pt":1724091559937,"mc":[{"id":"1.232018919","rc":[{"batb":[[0,1.59,15.36],[1,1.58,7.14],[2,1.2,250]],"ltp":1.65,"tv":2064.06,"id":72857116}]}]}
{"op":"mcm","clk":"11878009891","pt":1724091562968,"mc":[{"id":"1.232018919","rc":[{"batb":[[0,1.6,10.84],[1,1.59,14.52],[2,1.58,7.14]],"ltp":1.65,"tv":2064.06,"id":72857116}]}]}
{"op":"mcm","clk":"11878010427","pt":1724091566246,"mc":[{"id":"1.232018919","rc":[{"batb":[[0,1.59,15.36],[1,1.58,7.14],[2,1.2,250]],"ltp":1.65,"tv":2064.06,"id":72857116}]}]}
{"op":"mcm","clk":"11878011193","pt":1724091571129,"mc":[{"id":"1.232018919","rc":[{"batb":[[0,1.6,10.84],[1,1.59,14.52],[2,1.58,7.14]],"batl":[[1,5.9,4.27],[2,6,0.77]],"ltp":1.65,"tv":2064.06,"id":72857116}]}]}
{"op":"mcm","clk":"11878011752","pt":1724091574539,"mc":[{"id":"1.232018919","rc":[{"batb":[[0,1.59,15.36],[1,1.58,7.14],[2,1.2,250]],"batl":[[1,6,0.77],[2,6,0]],"ltp":1.65,"tv":2064.06,"id":72857116}]}]}
{"op":"mcm","clk":"11878012249","pt":1724091577432,"mc":[{"id":"1.232018919","rc":[{"batb":[[0,1.6,10.84],[1,1.59,14.52],[2,1.58,7.14]],"ltp":1.65,"tv":2064.06,"id":72857116}]}]}
{"op":"mcm","clk":"11878012817","pt":1724091581072,"mc":[{"id":"1.232018919","rc":[{"batb":[[0,1.59,15.36],[1,1.58,7.14],[2,1.2,250]],"ltp":1.65,"tv":2064.06,"id":72857116}]}]}
{"op":"mcm","clk":"11878013820","pt":1724091587674,"mc":[{"id":"1.232018919","rc":[{"batb":[[0,1.6,10.84],[1,1.59,14.52],[2,1.58,7.14]],"ltp":1.65,"tv":2064.06,"id":72857116}]}]}
{"op":"mcm","clk":"11878014389","pt":1724091591380,"mc":[{"id":"1.232018919","rc":[{"batb":[[0,1.59,15.36],[1,1.58,7.14],[2,1.2,250]],"ltp":1.65,"tv":2064.06,"id":72857116}]}]}
{"op":"mcm","clk":"11878018123","pt":1724091614480,"mc":[{"id":"1.232018919","rc":[{"batb":[[0,1.6,10.84],[1,1.59,14.52],[2,1.58,7.14]],"ltp":1.65,"tv":2064.06,"id":72857116}]}]}
{"op":"mcm","clk":"11878018700","pt":1724091618094,"mc":[{"id":"1.232018919","rc":[{"batb":[[0,1.59,15.36],[1,1.58,7.14],[2,1.2,250]],"ltp":1.65,"tv":2064.06,"id":72857116}]}]}
{"op":"mcm","clk":"11878019106","pt":1724091620680,"mc":[{"id":"1.232018919","rc":[{"batb":[[0,1.6,10.84],[1,1.59,14.52],[2,1.58,7.14]],"ltp":1.65,"tv":2064.06,"id":72857116}]}]}
{"op":"mcm","clk":"11878019184","pt":1724091621196,"mc":[{"id":"1.232018919","rc":[{"batl":[[1,5.9,4.27],[2,6,0.77]],"ltp":1.65,"tv":2064.06,"id":72857116}]}]}
{"op":"mcm","clk":"11878019644","pt":1724091624090,"mc":[{"id":"1.232018919","rc":[{"batb":[[0,1.59,15.36],[1,1.58,7.14],[2,1.2,250]],"ltp":1.65,"tv":2064.06,"id":72857116}]}]}
{"op":"mcm","clk":"11878019783","pt":1724091624985,"mc":[{"id":"1.232018919","rc":[{"batl":[[1,6,0.77],[2,6,0]],"ltp":1.65,"tv":2064.06,"id":72857116}]}]}
{"op":"mcm","clk":"11878020057","pt":1724091626880,"mc":[{"id":"1.232018919","rc":[{"batb":[[0,1.6,10.84],[1,1.59,14.52],[2,1.58,7.14]],"ltp":1.65,"tv":2064.06,"id":72857116}]}]}
{"op":"mcm","clk":"11878020645","pt":1724091630511,"mc":[{"id":"1.232018919","rc":[{"batb":[[0,1.59,15.36],[1,1.58,7.14],[2,1.2,250]],"ltp":1.65,"tv":2064.06,"id":72857116}]}]}
{"op":"mcm","clk":"11878021237","pt":1724091634204,"mc":[{"id":"1.232018919","rc":[{"batb":[[0,1.6,10.84],[1,1.59,14.52],[2,1.58,7.14]],"ltp":1.65,"tv":2064.06,"id":72857116}]}]}
{"op":"mcm","clk":"11878021818","pt":1724091637491,"mc":[{"id":"1.232018919","rc":[{"batb":[[0,1.59,15.36],[1,1.58,7.14],[2,1.2,250]],"ltp":1.65,"tv":2064.06,"id":72857116}]}]}
{"op":"mcm","clk":"11878022183","pt":1724091639700,"mc":[{"id":"1.232018919","rc":[{"batb":[[0,1.6,10.84],[1,1.59,14.52],[2,1.58,7.14]],"ltp":1.65,"tv":2064.06,"id":72857116}]}]}
{"op":"mcm","clk":"11878022745","pt":1724091643221,"mc":[{"id":"1.232018919","rc":[{"batb":[[0,1.59,15.36],[1,1.58,7.14],[2,1.2,250]],"ltp":1.65,"tv":2064.06,"id":72857116}]}]}
{"op":"mcm","clk":"11878023310","pt":1724091646608,"mc":[{"id":"1.232018919","rc":[{"batb":[[0,1.6,10.84],[1,1.59,14.52],[2,1.58,7.14]],"ltp":1.65,"tv":2064.06,"id":72857116}]}]}
{"op":"mcm","clk":"11878023864","pt":1724091650015,"mc":[{"id":"1.232018919","rc":[{"batb":[[0,1.59,15.36],[1,1.58,7.14],[2,1.2,250]],"ltp":1.65,"tv":2064.06,"id":72857116}]}]}
{"op":"mcm","clk":"11878024423","pt":1724091653422,"mc":[{"id":"1.232018919","rc":[{"batb":[[0,1.6,10.84],[1,1.59,14.52],[2,1.58,7.14]],"ltp":1.65,"tv":2064.06,"id":72857116}]}]}
{"op":"mcm","clk":"11878024970","pt":1724091656829,"mc":[{"id":"1.232018919","rc":[{"batb":[[0,1.59,15.36],[1,1.58,7.14],[2,1.2,250]],"ltp":1.65,"tv":2064.06,"id":72857116}]}]}
{"op":"mcm","clk":"11878025545","pt":1724091660940,"mc":[{"id":"1.232018919","rc":[{"batb":[[0,1.6,10.84],[1,1.59,14.52],[2,1.58,7.14]],"ltp":1.65,"tv":2064.06,"id":72857116}]}]}
