{"op":"mcm","clk":"11749081170","pt":1722332107428,"mc":[{"id":"1.231242812","marketDefinition":{"bspMarket":false,"turnInPlayEnabled":true,"persistenceEnabled":true,"marketBaseRate":5.0,"eventId":"33455059","eventTypeId":"4","numberOfWinners":1,"bettingType":"ODDS","marketType":"MATCH_ODDS","marketTime":"2024-08-02T10:00:00.000Z","suspendTime":"2024-08-02T10:00:00.000Z","bspReconciled":false,"complete":true,"inPlay":false,"crossMatching":false,"runnersVoidable":false,"numberOfActiveRunners":2,"betDelay":0,"status":"OPEN","runners":[{"status":"ACTIVE","sortPriority":1,"id":2120,"name":"Warwickshire"},{"status":"ACTIVE","sortPriority":2,"id":424676,"name":"Surrey"}],"regulators":["MR_INT"],"countryCode":"GB","discountAllowed":false,"timezone":"GMT","openDate":"2024-08-02T10:00:00.000Z","version":6047208078,"name":"Match Odds","eventName":"Warwickshire v Surrey"},"rc":[{"batb":[[0,1.03,200],[1,1.02,200],[2,1.01,220]],"ltp":0.0,"tv":0.0,"id":424676},{"batb":[[0,1.03,200],[1,1.02,200],[2,1.01,220]],"ltp":0.0,"tv":0.0,"id":2120}]}]}
{"op":"mcm","clk":"11749081282","pt":1722332111293,"mc":[{"id":"1.231242812","marketDefinition":{"bspMarket":false,"turnInPlayEnabled":true,"persistenceEnabled":true,"marketBaseRate":5.0,"eventId":"33455059","eventTypeId":"4","numberOfWinners":1,"bettingType":"ODDS","marketType":"MATCH_ODDS","marketTime":"2024-08-02T10:00:00.000Z","suspendTime":"2024-08-02T10:00:00.000Z","bspReconciled":false,"complete":true,"inPlay":false,"crossMatching":false,"runnersVoidable":false,"numberOfActiveRunners":2,"betDelay":0,"status":"OPEN","runners":[{"status":"ACTIVE","sortPriority":1,"id":2120,"name":"Warwickshire"},{"status":"ACTIVE","sortPriority":2,"id":424676,"name":"Surrey"}],"regulators":["MR_INT"],"countryCode":"GB","discountAllowed":true,"timezone":"GMT","openDate":"2024-08-02T10:00:00.000Z","version":6047208078,"name":"Match Odds","eventName":"Warwickshire v Surrey"}}]}
{"op":"mcm","clk":"11749251175","pt":1722336349592,"mc":[{"id":"1.231242812","rc":[{"batb":[[2,1.01,471.93]],"ltp":0.0,"tv":0.0,"id":424676},{"batb":[[2,1.01,471.93]],"ltp":0.0,"tv":0.0,"id":2120}]}]}
{"op":"mcm","clk":"11749399879","pt":1722340218978,"mc":[{"id":"1.231242812","rc":[{"batb":[[0,1.3,1000],[1,1.03,200],[2,1.02,200]],"ltp":0.0,"tv":0.0,"id":424676},{"batb":[[0,1.3,1000],[1,1.03,200],[2,1.02,200]],"ltp":0.0,"tv":0.0,"id":2120}]}]}
{"op":"mcm","clk":"11749400468","pt":1722340235490,"mc":[{"id":"1.231242812","marketDefinition":{"bspMarket":false,"turnInPlayEnabled":true,"persistenceEnabled":true,"marketBaseRate":5.0,"eventId":"33455059","eventTypeId":"4","numberOfWinners":1,"bettingType":"ODDS","marketType":"MATCH_ODDS","marketTime":"2024-08-02T10:00:00.000Z","suspendTime":"2024-08-02T10:00:00.000Z","bspReconciled":false,"complete":true,"inPlay":false,"crossMatching":true,"runnersVoidable":false,"numberOfActiveRunners":2,"betDelay":0,"status":"OPEN","runners":[{"status":"ACTIVE","sortPriority":1,"id":2120,"name":"Warwickshire"},{"status":"ACTIVE","sortPriority":2,"id":424676,"name":"Surrey"}],"regulators":["MR_INT"],"countryCode":"GB","discountAllowed":true,"timezone":"GMT","openDate":"2024-08-02T10:00:00.000Z","version":6047208078,"name":"Match Odds","eventName":"Warwickshire v Surrey"}}]}
{"op":"mcm","clk":"11749401245","pt":1722340255630,"mc":[{"id":"1.231242812","rc":[{"batb":[[0,1.31,6.25],[1,1.3,1000],[2,1.03,200]],"ltp":0.0,"tv":0.0,"id":424676},{"batb":[[0,1.31,5.84],[1,1.3,1000],[2,1.03,200]],"ltp":0.0,"tv":0.0,"id":2120}]}]}
{"op":"mcm","clk":"11749461627","pt":1722341574835,"mc":[{"id":"1.231242812","rc":[{"batb":[[0,1.31,6.26]],"ltp":0.0,"tv":0.0,"id":424676},{"batb":[[0,1.31,5.85]],"ltp":0.0,"tv":0.0,"id":2120}]}]}
{"op":"mcm","clk":"11749714953","pt":1722346250251,"mc":[{"id":"1.231242812","rc":[{"batb":[[0,1.31,6.27],[1,1.03,200],[2,1.02,200]],"ltp":0.0,"tv":0.0,"id":424676},{"batb":[[0,1.31,5.85],[1,1.03,200],[2,1.02,200]],"ltp":0.0,"tv":0.0,"id":2120}]}]}
{"op":"mcm","clk":"11749815866","pt":1722347727123,"mc":[{"id":"1.231242812","rc":[{"batb":[[0,1.03,200],[1,1.02,200],[2,1.01,472.33]],"ltp":0.0,"tv":0.0,"id":424676},{"batb":[[0,1.03,200],[1,1.02,200],[2,1.01,472.33]],"ltp":0.0,"tv":0.0,"id":2120}]}]}
{"op":"mcm","clk":"11750136767","pt":1722352374861,"mc":[{"id":"1.231242812","rc":[{"batb":[[2,1.01,472.77]],"ltp":0.0,"tv":0.0,"id":424676},{"batb":[[2,1.01,472.77]],"ltp":0.0,"tv":0.0,"id":2120}]}]}
{"op":"mcm","clk":"11750639401","pt":1722357774848,"mc":[{"id":"1.231242812","rc":[{"batb":[[2,1.01,472.84]],"ltp":0.0,"tv":0.0,"id":424676},{"batb":[[2,1.01,472.84]],"ltp":0.0,"tv":0.0,"id":2120}]}]}
{"op":"mcm","clk":"11750759415","pt":1722359061272,"mc":[{"id":"1.231242812","rc":[{"batb":[[0,1.23,217.39],[1,1.18,277.78],[2,1.13,384.62]],"ltp":0.0,"tv":0.0,"id":424676},{"batb":[[0,1.23,217.39],[1,1.18,277.78],[2,1.13,384.62]],"ltp":0.0,"tv":0.0,"id":2120}]}]}
{"op":"mcm","clk":"11750759495","pt":1722359061975,"mc":[{"id":"1.231242812","rc":[{"batb":[[0,1.43,116.28],[1,1.38,131.58],[2,1.33,151.52]],"ltp":0.0,"tv":0.0,"id":424676},{"batb":[[0,1.43,116.28],[1,1.38,131.58],[2,1.33,151.52]],"ltp":0.0,"tv":0.0,"id":2120}]}]}
{"op":"mcm","clk":"11750866586","pt":1722360146156,"mc":[{"id":"1.231242812","rc":[{"batb":[[0,1.44,6.02],[1,1.43,116.28],[2,1.38,131.58]],"ltp":0.0,"tv":0.0,"id":424676},{"batb":[[0,1.44,5.97],[1,1.43,116.28],[2,1.38,131.58]],"ltp":0.0,"tv":0.0,"id":2120}]}]}
{"op":"mcm","clk":"11750893043","pt":1722360391072,"mc":[{"id":"1.231242812","rc":[{"batb":[[0,1.44,12.03]],"ltp":0.0,"tv":0.0,"id":424676},{"batb":[[0,1.44,11.97]],"ltp":0.0,"tv":0.0,"id":2120}]}]}
{"op":"mcm","clk":"11751184361","pt":1722363174855,"mc":[{"id":"1.231242812","rc":[{"batb":[[0,1.44,12.03]],"ltp":0.0,"tv":0.0,"id":424676},{"batb":[[0,1.44,11.97]],"ltp":0.0,"tv":0.0,"id":2120}]}]}
{"op":"mcm","clk":"11751380179","pt":1722364624387,"mc":[{"id":"1.231242812","rc":[{"batb":[[0,2.26,3.46],[1,1.44,12.03],[2,1.43,116.28]],"ltp":0.0,"tv":0.0,"id":424676},{"batb":[[0,1.73,5.97],[1,1.44,11.97],[2,1.43,116.28]],"ltp":0.0,"tv":0.0,"id":2120}]}]}
{"op":"mcm","clk":"11751682774","pt":1722366440137,"mc":[{"id":"1.231242812","rc":[{"batb":[[1,1.44,6.01]],"ltp":0.0,"tv":0.0,"id":424676},{"batb":[[1,1.44,6]],"ltp":0.0,"tv":0.0,"id":2120}]}]}
{"op":"mcm","clk":"11753636190","pt":1722395574851,"mc":[{"id":"1.231242812","rc":[{"batb":[[1,1.44,6.01]],"ltp":0.0,"tv":0.0,"id":424676},{"batb":[[1,1.44,6]],"ltp":0.0,"tv":0.0,"id":2120}]}]}
{"op":"mcm","clk":"11753753015","pt":1722398859437,"mc":[{"id":"1.231242812","rc":[{"batb":[[0,1.44,6.01],[1,1.43,116.28],[2,1.38,131.58]],"ltp":0.0,"tv":0.0,"id":424676},{"batb":[[0,1.44,6],[1,1.43,116.28],[2,1.38,131.58]],"ltp":0.0,"tv":0.0,"id":2120}]}]}
{"op":"mcm","clk":"11753753450","pt":1722398862621,"mc":[{"id":"1.231242812","rc":[{"batb":[[0,2.26,3.46],[1,1.44,6.01],[2,1.43,116.28]],"ltp":0.0,"tv":0.0,"id":424676},{"batb":[[0,1.73,5.97],[1,1.44,6],[2,1.43,116.28]],"ltp":0.0,"tv":0.0,"id":2120}]}]}
{"op":"mcm","clk":"11753790532","pt":1722400234458,"mc":[{"id":"1.231242812","rc":[{"batb":[[0,1.44,6.01],[1,1.43,116.28],[2,1.38,131.58]],"ltp":0.0,"tv":0.0,"id":424676},{"batb":[[0,1.44,6],[1,1.43,116.28],[2,1.38,131.58]],"ltp":0.0,"tv":0.0,"id":2120}]}]}
{"op":"mcm","clk":"11753790984","pt":1722400237812,"mc":[{"id":"1.231242812","rc":[{"batb":[[0,2.26,3.46],[1,1.44,6.01],[2,1.43,116.28]],"ltp":0.0,"tv":0.0,"id":424676},{"batb":[[0,1.73,5.97],[1,1.44,6],[2,1.43,116.28]],"ltp":0.0,"tv":0.0,"id":2120}]}]}
{"op":"mcm","clk":"11753801556","pt":1722400617444,"mc":[{"id":"1.231242812","rc":[{"batb":[[0,1.44,6.01],[1,1.43,116.28],[2,1.38,131.58]],"ltp":0.0,"tv":0.0,"id":424676},{"batb":[[0,1.44,6],[1,1.43,116.28],[2,1.38,131.58]],"ltp":0.0,"tv":0.0,"id":2120}]}]}
{"op":"mcm","clk":"11753801734","pt":1722400619148,"mc":[{"id":"1.231242812","rc":[{"batb":[[0,2.26,3.46],[1,1.44,6.01],[2,1.43,116.28]],"ltp":0.0,"tv":0.0,"id":424676},{"batb":[[0,1.73,5.97],[1,1.44,6],[2,1.43,116.28]],"ltp":0.0,"tv":0.0,"id":2120}]}]}
{"op":"mcm","clk":"11753838976","pt":1722401937564,"mc":[{"id":"1.231242812","rc":[{"batb":[[0,1.44,6.01],[1,1.43,116.28],[2,1.38,131.58]],"ltp":0.0,"tv":0.0,"id":424676},{"batb":[[0,1.44,6],[1,1.43,116.28],[2,1.38,131.58]],"ltp":0.0,"tv":0.0,"id":2120}]}]}
{"op":"mcm","clk":"11753839118","pt":1722401939406,"mc":[{"id":"1.231242812","rc":[{"batb":[[0,2.26,3.46],[1,1.44,6.01],[2,1.43,116.28]],"ltp":0.0,"tv":0.0,"id":424676},{"batb":[[0,1.73,5.97],[1,1.44,6],[2,1.43,116.28]],"ltp":0.0,"tv":0.0,"id":2120}]}]}
{"op":"mcm","clk":"11753847105","pt":1722402214851,"mc":[{"id":"1.231242812","rc":[{"batb":[[0,1.44,6.01],[1,1.43,116.28],[2,1.38,131.58]],"ltp":0.0,"tv":0.0,"id":424676},{"batb":[[0,1.44,6],[1,1.43,116.28],[2,1.38,131.58]],"ltp":0.0,"tv":0.0,"id":2120}]}]}
{"op":"mcm","clk":"11753847170","pt":1722402215796,"mc":[{"id":"1.231242812","rc":[{"batb":[[0,2.26,3.46],[1,1.44,6.01],[2,1.43,116.28]],"ltp":0.0,"tv":0.0,"id":424676},{"batb":[[0,1.73,5.97],[1,1.44,6],[2,1.43,116.28]],"ltp":0.0,"tv":0.0,"id":2120}]}]}
{"op":"mcm","clk":"11753873785","pt":1722403478190,"mc":[{"id":"1.231242812","rc":[{"batb":[[0,1.44,6.01],[1,1.43,116.28],[2,1.38,131.58]],"ltp":0.0,"tv":0.0,"id":424676},{"batb":[[0,1.44,6],[1,1.43,116.28],[2,1.38,131.58]],"ltp":0.0,"tv":0.0,"id":2120}]}]}
{"op":"mcm","clk":"11753874127","pt":1722403481586,"mc":[{"id":"1.231242812","rc":[{"batb":[[0,2.26,3.46],[1,1.44,6.01],[2,1.43,116.28]],"ltp":0.0,"tv":0.0,"id":424676},{"batb":[[0,1.73,5.97],[1,1.44,6],[2,1.43,116.28]],"ltp":0.0,"tv":0.0,"id":2120}]}]}
{"op":"mcm","clk":"11753881581","pt":1722403756679,"mc":[{"id":"1.231242812","rc":[{"batb":[[0,1.44,6.01],[1,1.43,116.28],[2,1.38,131.58]],"ltp":0.0,"tv":0.0,"id":424676},{"batb":[[0,1.44,6],[1,1.43,116.28],[2,1.38,131.58]],"ltp":0.0,"tv":0.0,"id":2120}]}]}
{"op":"mcm","clk":"11753881685","pt":1722403757454,"mc":[{"id":"1.231242812","rc":[{"batb":[[0,2.26,3.46],[1,1.44,6.01],[2,1.43,116.28]],"ltp":0.0,"tv":0.0,"id":424676},{"batb":[[0,1.73,5.97],[1,1.44,6],[2,1.43,116.28]],"ltp":0.0,"tv":0.0,"id":2120}]}]}
{"op":"mcm","clk":"11753911271","pt":1722405183023,"mc":[{"id":"1.231242812","rc":[{"batb":[[0,1.44,6.01],[1,1.43,116.28],[2,1.38,131.58]],"ltp":0.0,"tv":0.0,"id":424676},{"batb":[[0,1.44,6],[1,1.43,116.28],[2,1.38,131.58]],"ltp":0.0,"tv":0.0,"id":2120}]}]}
{"op":"mcm","clk":"11753911323","pt":1722405183663,"mc":[{"id":"1.231242812","rc":[{"batb":[[0,2.26,3.46],[1,1.44,6.01],[2,1.43,116.28]],"ltp":0.0,"tv":0.0,"id":424676},{"batb":[[0,1.73,5.97],[1,1.44,6],[2,1.43,116.28]],"ltp":0.0,"tv":0.0,"id":2120}]}]}
{"op":"mcm","clk":"11754056844","pt":1722411774897,"mc":[{"id":"1.231242812","rc":[{"batb":[[1,1.44,6.01]],"ltp":0.0,"tv":0.0,"id":424676},{"batb":[[1,1.44,6]],"ltp":0.0,"tv":0.0,"id":2120}]}]}
{"op":"mcm","clk":"11754233276","pt":1722417174887,"mc":[{"id":"1.231242812","rc":[{"batb":[[1,1.44,6.02]],"ltp":0.0,"tv":0.0,"id":424676},{"batb":[[1,1.44,6.01]],"ltp":0.0,"tv":0.0,"id":2120}]}]}
{"op":"mcm","clk":"11754356628","pt":1722419309953,"mc":[{"id":"1.231242812","rc":[{"trd":[[2.26,2]],"batb":[[0,2.26,2.46]],"ltp":2.26,"tv":2.0,"id":424676}],"tv":2.0}]}
{"op":"mcm","clk":"11754356693","pt":1722419311462,"mc":[{"id":"1.231242812","rc":[{"batb":[[0,2.26,3.46]],"ltp":2.26,"tv":2.0,"id":424676}]}]}
{"op":"mcm","clk":"11754401047","pt":1722419935148,"mc":[{"id":"1.231242812","rc":[{"batb":[[2,1.2,11]],"ltp":2.26,"tv":2.0,"id":424676},{"batb":[[2,1.2,11]],"ltp":0.0,"tv":0.0,"id":2120}]}]}
{"op":"mcm","clk":"11754401146","pt":1722419936285,"mc":[{"id":"1.231242812","rc":[{"batb":[[1,1.2,11],[2,1.1,11]],"ltp":2.26,"tv":2.0,"id":424676},{"batb":[[1,1.2,11],[2,1.1,11]],"ltp":0.0,"tv":0.0,"id":2120}]}]}
{"op":"mcm","clk":"11754401636","pt":1722419942076,"mc":[{"id":"1.231242812","rc":[{"batb":[[1,1.25,100],[2,1.2,11]],"ltp":2.26,"tv":2.0,"id":424676},{"batb":[[1,1.25,100],[2,1.2,11]],"ltp":0.0,"tv":0.0,"id":2120}]}]}
{"op":"mcm","clk":"11754407202","pt":1722420004887,"mc":[{"id":"1.231242812","rc":[{"batb":[[0,2.26,34.61]],"ltp":2.26,"tv":2.0,"id":424676},{"batb":[[0,1.73,59.74]],"ltp":0.0,"tv":0.0,"id":2120}]}]}
{"op":"mcm","clk":"11754427647","pt":1722420261150,"mc":[{"id":"1.231242812","rc":[{"trd":[[1.73,2.6]],"batb":[[0,1.73,58.44]],"ltp":1.73,"tv":2.6,"id":2120}],"tv":4.6}]}
{"op":"mcm","clk":"11754427984","pt":1722420265953,"mc":[{"id":"1.231242812","rc":[{"batb":[[0,1.73,59.74]],"ltp":1.73,"tv":2.6,"id":2120}]}]}
{"op":"mcm","clk":"11754641910","pt":1722422851097,"mc":[{"id":"1.231242812","rc":[{"trd":[[2.26,36.61]],"batb":[[0,2.18,36.95]],"ltp":2.26,"tv":36.61,"id":424676},{"trd":[[1.8,43.45]],"batb":[[0,1.8,106.55],[1,1.73,59.74],[2,1.25,100]],"ltp":1.8,"tv":46.05,"id":2120}],"tv":82.66}]}
{"op":"mcm","clk":"11754642158","pt":1722422854470,"mc":[{"id":"1.231242812","rc":[{"trd":[[2.18,36.95]],"batb":[[0,1.25,100],[1,1.2,11],[2,1.1,11]],"ltp":2.18,"tv":73.56,"id":424676},{"trd":[[1.85,43.54]],"batb":[[0,1.85,156.46],[1,1.8,106.55],[2,1.73,59.74]],"ltp":1.85,"tv":89.59,"id":2120}],"tv":163.15}]}
{"op":"mcm","clk":"11754648933","pt":1722422943196,"mc":[{"id":"1.231242812","rc":[{"batb":[[0,1.26,32.61],[1,1.25,100],[2,1.2,11]],"ltp":2.18,"tv":73.56,"id":424676},{"batb":[[0,1.86,9.86],[1,1.85,156.46],[2,1.8,106.55]],"ltp":1.85,"tv":89.59,"id":2120}]}]}
{"op":"mcm","clk":"11754659414","pt":1722423060102,"mc":[{"id":"1.231242812","rc":[{"batl":[[0,2.02,100]],"ltp":2.18,"tv":73.56,"id":424676}]}]}
{"op":"mcm","clk":"11754659454","pt":1722423060514,"mc":[{"id":"1.231242812","rc":[{"batb":[[0,1.27,10],[1,1.26,32.61],[2,1.25,100]],"ltp":2.18,"tv":73.56,"id":424676}]}]}
{"op":"mcm","clk":"11754659540","pt":1722423061343,"mc":[{"id":"1.231242812","rc":[{"batl":[[0,1.94,100],[1,2.02,100]],"ltp":2.18,"tv":73.56,"id":424676}]}]}
{"op":"mcm","clk":"11754659670","pt":1722423062598,"mc":[{"id":"1.231242812","rc":[{"trd":[[1.87,59.62]],"batl":[[0,1.87,70.19],[1,1.94,100],[2,2.02,100]],"ltp":1.87,"tv":133.18,"id":424676}],"tv":222.77}]}
{"op":"mcm","clk":"11754659796","pt":1722423064104,"mc":[{"id":"1.231242812","rc":[{"batb":[[0,1.26,32.61],[1,1.25,100],[2,1.2,11]],"batl":[[0,1.83,100],[1,1.87,70.19],[2,1.89,100]],"ltp":1.87,"tv":133.18,"id":424676}]}]}
{"op":"mcm","clk":"11754660190","pt":1722423068126,"mc":[{"id":"1.231242812","rc":[{"trd":[[1.83,60.3]],"batl":[[0,1.83,69.85]],"ltp":1.83,"tv":193.48,"id":424676}],"tv":283.07}]}
{"op":"mcm","clk":"11754661144","pt":1722423078359,"mc":[{"id":"1.231242812","rc":[{"trd":[[1.83,120.36]],"batl":[[0,1.83,39.82]],"ltp":1.83,"tv":253.54,"id":424676}],"tv":343.13}]}
{"op":"mcm","clk":"11754661600","pt":1722423083149,"mc":[{"id":"1.231242812","rc":[{"trd":[[1.77,3.96]],"batl":[[0,1.77,2.02],[1,1.83,39.82],[2,1.87,70.19]],"ltp":1.77,"tv":257.5,"id":424676}],"tv":347.09}]}
{"op":"mcm","clk":"11754661666","pt":1722423084178,"mc":[{"id":"1.231242812","rc":[{"trd":[[1.77,7.92]],"batl":[[0,1.83,39.86],[1,1.87,70.19],[2,1.89,100]],"ltp":1.77,"tv":261.46,"id":424676}],"tv":351.05}]}
{"op":"mcm","clk":"11754661753","pt":1722423085159,"mc":[{"id":"1.231242812","rc":[{"trd":[[1.73,3.9]],"batl":[[0,1.79,2.09],[1,1.83,39.82],[2,1.87,70.19]],"ltp":1.73,"tv":265.36,"id":424676}],"tv":354.95}]}
{"op":"mcm","clk":"11754661853","pt":1722423086246,"mc":[{"id":"1.231242812","rc":[{"trd":[[1.73,4],[1.76,3.96]],"batl":[[0,1.77,2.06],[1,1.79,2],[2,1.81,2]],"ltp":1.76,"tv":269.42,"id":424676}],"tv":359.01}]}
{"op":"mcm","clk":"11754661926","pt":1722423087171,"mc":[{"id":"1.231242812","rc":[{"trd":[[1.76,4],[1.77,11.94]],"batl":[[0,1.79,2.03],[1,1.81,2],[2,1.83,41.82]],"ltp":1.77,"tv":273.48,"id":424676}],"tv":363.07}]}
{"op":"mcm","clk":"11754662009","pt":1722423088147,"mc":[{"id":"1.231242812","rc":[{"trd":[[1.72,7.9]],"batl":[[0,1.74,4.05],[1,1.77,4.03],[2,1.79,2]],"ltp":1.72,"tv":281.38,"id":424676}],"tv":370.97}]}
{"op":"mcm","clk":"11754662025","pt":1722423088357,"mc":[{"id":"1.231242812","rc":[{"batl":[[2,1.79,4]],"ltp":1.72,"tv":281.38,"id":424676}]}]}
{"op":"mcm","clk":"11754662280","pt":1722423091193,"mc":[{"id":"1.231242812","rc":[{"batl":[[0,1.71,40],[1,1.74,24.05],[2,1.76,20]],"ltp":1.72,"tv":281.38,"id":424676}]}]}
{"op":"mcm","clk":"11754662527","pt":1722423094090,"mc":[{"id":"1.231242812","rc":[{"trd":[[1.71,56.2],[1.72,8],[1.74,47.94]],"batb":[[0,1.71,16.34],[1,1.26,32.61],[2,1.25,100]],"batl":[[0,1.76,20.03],[1,1.77,4.03],[2,1.78,20]],"ltp":1.74,"tv":385.62,"id":424676},{"trd":[[2.4,16.96]],"ltp":2.4,"tv":106.55,"id":2120}],"tv":492.17}]}
{"op":"mcm","clk":"11754662629","pt":1722423095021,"mc":[{"id":"1.231242812","rc":[{"trd":[[1.74,48],[1.76,15.9]],"batl":[[0,1.76,14.05]],"ltp":1.76,"tv":397.58,"id":424676}],"tv":504.13}]}
{"op":"mcm","clk":"11754662970","pt":1722423099007,"mc":[{"id":"1.231242812","rc":[{"trd":[[1.76,43.86]],"batl":[[0,1.77,4.1],[1,1.78,20],[2,1.79,4]],"ltp":1.76,"tv":425.54,"id":424676}],"tv":532.09}]}
{"op":"mcm","clk":"11754663037","pt":1722423099791,"mc":[{"id":"1.231242812","rc":[{"trd":[[1.76,44],[1.77,19.76]],"batl":[[0,1.78,20.12],[1,1.79,4],[2,1.81,2]],"ltp":1.77,"tv":433.5,"id":424676}],"tv":540.05}]}
{"op":"mcm","clk":"11754663139","pt":1722423100789,"mc":[{"id":"1.231242812","rc":[{"trd":[[1.77,20],[1.78,24.08]],"batl":[[0,1.78,7.96]],"ltp":1.78,"tv":457.82,"id":424676}],"tv":564.37}]}
{"op":"mcm","clk":"11754663915","pt":1722423109314,"mc":[{"id":"1.231242812","rc":[{"trd":[[1.78,39.86]],"batl":[[0,1.79,4.07],[1,1.81,2],[2,1.83,41.82]],"ltp":1.78,"tv":473.6,"id":424676}],"tv":580.15}]}
{"op":"mcm","clk":"11754664046","pt":1722423110713,"mc":[{"id":"1.231242812","rc":[{"trd":[[1.78,40],[1.79,7.82]],"batl":[[0,1.81,2.09],[1,1.83,41.82],[2,1.84,2]],"ltp":1.79,"tv":481.56,"id":424676}],"tv":588.11}]}
{"op":"mcm","clk":"11754664154","pt":1722423111797,"mc":[{"id":"1.231242812","rc":[{"trd":[[1.79,8],[1.81,3.98]],"batl":[[0,1.83,41.83],[1,1.84,2],[2,1.86,2]],"ltp":1.81,"tv":485.71,"id":424676}],"tv":592.27}]}
{"op":"mcm","clk":"11754667014","pt":1722423144255,"mc":[{"id":"1.231242812","rc":[{"trd":[[1.81,3.99],[1.83,162.18]],"batl":[[0,1.84,2],[1,1.86,2],[2,1.87,70.19]],"ltp":1.83,"tv":527.55,"id":424676},{"trd":[[2.2,34.79],[2.22,0.01]],"batb":[[0,1.87,10],[1,1.86,9.86],[2,1.85,156.46]],"batl":[[0,2.2,0.2]],"ltp":2.2,"tv":141.35,"id":2120}],"tv":668.9}]}
{"op":"mcm","clk":"11754667131","pt":1722423145549,"mc":[{"id":"1.231242812","rc":[{"batb":[[0,1.83,4.21],[1,1.71,16.34],[2,1.26,32.61]],"ltp":1.83,"tv":527.55,"id":424676}]}]}
{"op":"mcm","clk":"11754667326","pt":1722423147533,"mc":[{"id":"1.231242812","rc":[{"batb":[[0,1.86,9.86],[1,1.85,156.46],[2,1.8,106.55]],"ltp":2.2,"tv":141.35,"id":2120}]}]}
{"op":"mcm","clk":"11754667823","pt":1722423153233,"mc":[{"id":"1.231242812","rc":[{"trd":[[1.84,4],[1.86,4],[1.87,60.04]],"batb":[[0,1.71,16.34],[1,1.26,32.61],[2,1.25,100]],"batl":[[0,1.87,69.98],[1,1.89,100],[2,1.91,100]],"ltp":1.87,"tv":535.97,"id":424676}],"tv":677.32}]}
{"op":"mcm","clk":"11754667835","pt":1722423153335,"mc":[{"id":"1.231242812","rc":[{"batb":[[0,1.87,10],[1,1.86,9.86],[2,1.85,156.46]],"ltp":2.2,"tv":141.35,"id":2120}]}]}
{"op":"mcm","clk":"11754668184","pt":1722423156965,"mc":[{"id":"1.231242812","rc":[{"batb":[[0,1.86,9.86],[1,1.85,156.46],[2,1.8,106.55]],"ltp":2.2,"tv":141.35,"id":2120}]}]}
{"op":"mcm","clk":"11754668536","pt":1722423160649,"mc":[{"id":"1.231242812","rc":[{"batb":[[0,1.87,10],[1,1.86,9.86],[2,1.85,156.46]],"ltp":2.2,"tv":141.35,"id":2120}]}]}
{"op":"mcm","clk":"11754668847","pt":1722423164169,"mc":[{"id":"1.231242812","rc":[{"batb":[[0,1.86,9.86],[1,1.85,156.46],[2,1.8,106.55]],"ltp":2.2,"tv":141.35,"id":2120}]}]}
{"op":"mcm","clk":"11754668880","pt":1722423164481,"mc":[{"id":"1.231242812","rc":[{"trd":[[1.87,130.02]],"batl":[[0,1.89,100],[1,1.91,100],[2,1.92,100]],"ltp":1.87,"tv":605.95,"id":424676},{"trd":[[2.14,61.15]],"batl":[[0,2.14,23.22],[1,2.2,0.2]],"ltp":2.14,"tv":202.49,"id":2120}],"tv":808.45}]}
{"op":"mcm","clk":"11754669119","pt":1722423167373,"mc":[{"id":"1.231242812","rc":[{"batb":[[0,1.87,10],[1,1.86,9.86],[2,1.85,156.46]],"ltp":2.14,"tv":202.49,"id":2120}]}]}
{"op":"mcm","clk":"11754669394","pt":1722423170780,"mc":[{"id":"1.231242812","rc":[{"batb":[[0,1.86,9.86],[1,1.85,156.46],[2,1.8,106.55]],"ltp":2.14,"tv":202.49,"id":2120}]}]}
{"op":"mcm","clk":"11754669663","pt":1722423173871,"mc":[{"id":"1.231242812","rc":[{"trd":[[1.89,26.04]],"batl":[[0,1.89,73.96]],"ltp":1.89,"tv":631.99,"id":424676},{"trd":[[2.12,23.22]],"batb":[[0,1.87,10],[1,1.86,9.86],[2,1.85,156.46]],"batl":[[0,2.2,0.2],[1,2.2,0]],"ltp":2.12,"tv":225.71,"id":2120}],"tv":857.7}]}
{"op":"mcm","clk":"11754669949","pt":1722423177382,"mc":[{"id":"1.231242812","rc":[{"batb":[[0,1.86,9.86],[1,1.85,156.46],[2,1.8,106.55]],"ltp":2.12,"tv":225.71,"id":2120}]}]}
{"op":"mcm","clk":"11754670582","pt":1722423184463,"mc":[{"id":"1.231242812","rc":[{"trd":[[1.89,73.36]],"batl":[[0,1.89,26.64]],"ltp":1.89,"tv":679.31,"id":424676},{"trd":[[2.12,65.4]],"ltp":2.12,"tv":267.9,"id":2120}],"tv":947.21}]}
{"op":"mcm","clk":"11754672980","pt":1722423213204,"mc":[{"id":"1.231242812","rc":[{"trd":[[1.89,84.82]],"batl":[[0,1.89,20.91]],"ltp":1.89,"tv":690.77,"id":424676}],"tv":958.67}]}
{"op":"mcm","clk":"11754673110","pt":1722423214716,"mc":[{"id":"1.231242812","rc":[{"trd":[[1.89,105.73]],"batl":[[0,1.91,100],[1,1.92,100],[2,1.94,100]],"ltp":1.89,"tv":711.68,"id":424676},{"trd":[[2.12,84.04]],"batb":[[0,1.87,10],[1,1.86,9.86],[2,1.85,156.46]],"batl":[[0,2.12,15.06]],"ltp":2.12,"tv":286.54,"id":2120}],"tv":998.22}]}
{"op":"mcm","clk":"11754673419","pt":1722423218032,"mc":[{"id":"1.231242812","rc":[{"batb":[[0,1.71,16.55]],"ltp":1.89,"tv":711.68,"id":424676},{"batb":[[0,1.86,9.86],[1,1.85,156.46],[2,1.8,106.55]],"ltp":2.12,"tv":286.54,"id":2120}]}]}
{"op":"mcm","clk":"11754673897","pt":1722423222929,"mc":[{"id":"1.231242812","rc":[{"trd":[[1.91,0.42]],"batb":[[0,1.71,16.34]],"batl":[[0,1.91,99.79]],"ltp":1.91,"tv":712.1,"id":424676},{"batb":[[0,1.87,10],[1,1.86,9.86],[2,1.85,156.46]],"ltp":2.12,"tv":286.54,"id":2120}],"tv":998.64}]}
{"op":"mcm","clk":"11754674233","pt":1722423226346,"mc":[{"id":"1.231242812","rc":[{"batb":[[0,1.86,9.86],[1,1.85,156.46],[2,1.8,106.55]],"ltp":2.12,"tv":286.54,"id":2120}]}]}
{"op":"mcm","clk":"11754675046","pt":1722423236048,"mc":[{"id":"1.231242812","rc":[{"batl":[[0,1.9,88.47],[1,1.91,99.79],[2,1.92,100]],"ltp":1.91,"tv":712.1,"id":424676},{"batb":[[0,1.87,10],[1,1.86,9.86],[2,1.85,156.46]],"ltp":2.12,"tv":286.54,"id":2120}]}]}
{"op":"mcm","clk":"11754675311","pt":1722423239365,"mc":[{"id":"1.231242812","rc":[{"batb":[[0,1.86,9.86],[1,1.85,156.46],[2,1.8,106.55]],"ltp":2.12,"tv":286.54,"id":2120}]}]}
{"op":"mcm","clk":"11754675728","pt":1722423243752,"mc":[{"id":"1.231242812","rc":[{"batb":[[0,1.87,10],[1,1.86,9.86],[2,1.85,156.46]],"ltp":2.12,"tv":286.54,"id":2120}]}]}
{"op":"mcm","clk":"11754676035","pt":1722423247170,"mc":[{"id":"1.231242812","rc":[{"batb":[[0,1.86,9.86],[1,1.85,156.46],[2,1.8,106.55]],"ltp":2.12,"tv":286.54,"id":2120}]}]}
{"op":"mcm","clk":"11754677396","pt":1722423261795,"mc":[{"id":"1.231242812","rc":[{"batl":[[0,1.9,87.96]],"ltp":1.91,"tv":712.1,"id":424676},{"batb":[[0,1.87,10],[1,1.86,9.86],[2,1.85,156.46]],"ltp":2.12,"tv":286.54,"id":2120}]}]}
{"op":"mcm","clk":"11754677661","pt":1722423265185,"mc":[{"id":"1.231242812","rc":[{"batb":[[0,1.86,9.86],[1,1.85,156.46],[2,1.8,106.55]],"ltp":2.12,"tv":286.54,"id":2120}]}]}
{"op":"mcm","clk":"11754678644","pt":1722423275898,"mc":[{"id":"1.231242812","rc":[{"batl":[[0,1.9,87.12]],"ltp":1.91,"tv":712.1,"id":424676},{"batb":[[0,1.87,10],[1,1.86,9.86],[2,1.85,156.46]],"ltp":2.12,"tv":286.54,"id":2120}]}]}
{"op":"mcm","clk":"11754678937","pt":1722423279201,"mc":[{"id":"1.231242812","rc":[{"batb":[[0,1.86,9.86],[1,1.85,156.46],[2,1.8,106.55]],"ltp":2.12,"tv":286.54,"id":2120}]}]}
{"op":"mcm","clk":"11754679243","pt":1722423282518,"mc":[{"id":"1.231242812","rc":[{"batb":[[0,1.87,10],[1,1.86,9.86],[2,1.85,156.46]],"ltp":2.12,"tv":286.54,"id":2120}]}]}
{"op":"mcm","clk":"11754679569","pt":1722423285886,"mc":[{"id":"1.231242812","rc":[{"batb":[[0,1.86,9.86],[1,1.85,156.46],[2,1.8,106.55]],"ltp":2.12,"tv":286.54,"id":2120}]}]}
{"op":"mcm","clk":"11754681443","pt":1722423305716,"mc":[{"id":"1.231242812","rc":[{"batb":[[0,1.87,10],[1,1.86,9.86],[2,1.85,156.46]],"batl":[[0,2.18,337.47]],"ltp":2.12,"tv":286.54,"id":2120}]}]}
{"op":"mcm","clk":"11754681719","pt":1722423309044,"mc":[{"id":"1.231242812","rc":[{"batb":[[0,1.86,9.86],[1,1.85,156.46],[2,1.8,106.55]],"ltp":2.12,"tv":286.54,"id":2120}]}]}
{"op":"mcm","clk":"11754682325","pt":1722423315640,"mc":[{"id":"1.231242812","rc":[{"trd":[[1.9,87.12],[1.91,100.21],[1.92,100],[1.94,100]],"batl":[[0,1.95,100],[1,1.97,100],[2,1.99,100]],"ltp":1.94,"tv":1099.01,"id":424676},{"trd":[[2.06,94.18],[2.08,183.94],[2.1,78.82]],"batb":[[0,1.87,10],[1,1.86,9.86],[2,1.85,156.46]],"batl":[[0,2.06,486.73],[1,2.18,337.47]],"ltp":2.06,"tv":643.48,"id":2120}],"tv":1742.49}]}
{"op":"mcm","clk":"11754682601","pt":1722423318750,"mc":[{"id":"1.231242812","rc":[{"batb":[[0,1.86,9.86],[1,1.85,156.46],[2,1.8,106.55]],"ltp":2.06,"tv":643.48,"id":2120}]}]}
{"op":"mcm","clk":"11754682895","pt":1722423321752,"mc":[{"id":"1.231242812","rc":[{"trd":[[1.95,100]],"batl":[[0,1.97,100],[1,1.99,100],[2,2.02,200]],"ltp":1.95,"tv":1199.01,"id":424676},{"trd":[[2.04,95.59]],"batb":[[0,1.87,10],[1,1.86,9.86],[2,1.85,156.46]],"batl":[[0,2.04,1591.75],[1,2.06,486.73],[2,2.18,337.47]],"ltp":2.04,"tv":739.06,"id":2120}],"tv":1938.07}]}
{"op":"mcm","clk":"11754683185","pt":1722423325171,"mc":[{"id":"1.231242812","rc":[{"batb":[[0,1.86,9.86],[1,1.85,156.46],[2,1.8,106.55]],"ltp":2.04,"tv":739.06,"id":2120}]}]}
{"op":"mcm","clk":"11754683787","pt":1722423332044,"mc":[{"id":"1.231242812","rc":[{"trd":[[1.97,100]],"batl":[[0,1.99,100],[1,2.02,200],[2,2.02,0]],"ltp":1.97,"tv":1299.01,"id":424676},{"trd":[[2.02,97.53]],"batb":[[0,1.87,10],[1,1.86,9.86],[2,1.85,156.46]],"batl":[[0,2.02,746.14],[1,2.04,1591.75],[2,2.06,486.73]],"ltp":2.02,"tv":836.59,"id":2120}],"tv":2135.6}]}
{"op":"mcm","clk":"11754684113","pt":1722423335467,"mc":[{"id":"1.231242812","rc":[{"batb":[[0,1.86,9.86],[1,1.85,156.46],[2,1.8,106.55]],"ltp":2.02,"tv":836.59,"id":2120}]}]}
{"op":"mcm","clk":"11754685206","pt":1722423347964,"mc":[{"id":"1.231242812","rc":[{"batb":[[0,1.87,10],[1,1.86,9.86],[2,1.85,156.46]],"ltp":2.02,"tv":836.59,"id":2120}]}]}
{"op":"mcm","clk":"11754685514","pt":1722423351278,"mc":[{"id":"1.231242812","rc":[{"batb":[[0,1.86,9.86],[1,1.85,156.46],[2,1.8,106.55]],"ltp":2.02,"tv":836.59,"id":2120}]}]}
{"op":"mcm","clk":"11754686003","pt":1722423357100,"mc":[{"id":"1.231242812","rc":[{"batb":[[0,1.87,10],[1,1.86,9.86],[2,1.85,156.46]],"ltp":2.02,"tv":836.59,"id":2120}]}]}
{"op":"mcm","clk":"11754686284","pt":1722423360617,"mc":[{"id":"1.231242812","rc":[{"batb":[[0,1.86,9.86],[1,1.85,156.46],[2,1.8,106.55]],"ltp":2.02,"tv":836.59,"id":2120}]}]}
{"op":"mcm","clk":"11754686501","pt":1722423363184,"mc":[{"id":"1.231242812","rc":[{"batb":[[0,1.87,10],[1,1.86,9.86],[2,1.85,156.46]],"ltp":2.02,"tv":836.59,"id":2120}]}]}
{"op":"mcm","clk":"11754686802","pt":1722423366495,"mc":[{"id":"1.231242812","rc":[{"batb":[[0,1.86,9.86],[1,1.85,156.46],[2,1.8,106.55]],"ltp":2.02,"tv":836.59,"id":2120}]}]}
{"op":"mcm","clk":"11754686923","pt":1722423367993,"mc":[{"id":"1.231242812","rc":[{"trd":[[1.99,100]],"batb":[[0,1.72,10],[1,1.71,16.34],[2,1.26,32.61]],"batl":[[0,2.02,200],[1,2.02,0]],"ltp":1.99,"tv":1399.01,"id":424676},{"trd":[[2,99.5]],"batl":[[0,2.02,746.64]],"ltp":2.0,"tv":936.09,"id":2120}],"tv":2335.1}]}
{"op":"mcm","clk":"11754687211","pt":1722423371201,"mc":[{"id":"1.231242812","rc":[{"batb":[[0,1.71,16.34],[1,1.26,32.61],[2,1.25,100]],"ltp":1.99,"tv":1399.01,"id":424676}]}]}
{"op":"mcm","clk":"11754687257","pt":1722423371717,"mc":[{"id":"1.231242812","rc":[{"trd":[[2.02,200]],"ltp":2.02,"tv":1599.01,"id":424676},{"trd":[[1.98,204.04]],"batb":[[0,1.87,10],[1,1.86,9.86],[2,1.85,156.46]],"batl":[[0,1.98,17.96],[1,2.02,746.64],[2,2.04,1591.75]],"ltp":1.98,"tv":1140.13,"id":2120}],"tv":2739.14}]}
{"op":"mcm","clk":"11754687438","pt":1722423373603,"mc":[{"id":"1.231242812","rc":[{"batb":[[0,2.02,530],[1,1.71,16.34],[2,1.26,32.61]],"ltp":2.02,"tv":1599.01,"id":424676},{"batl":[[0,2.02,746.64],[1,2.04,1591.75],[2,2.06,486.73]],"ltp":1.98,"tv":1140.13,"id":2120}]}]}
{"op":"mcm","clk":"11754687529","pt":1722423374583,"mc":[{"id":"1.231242812","rc":[{"batb":[[0,1.86,9.86],[1,1.85,156.46],[2,1.8,106.55]],"ltp":1.98,"tv":1140.13,"id":2120}]}]}
{"op":"mcm","clk":"11754687768","pt":1722423377109,"mc":[{"id":"1.231242812","rc":[{"batb":[[0,1.87,10],[1,1.86,9.86],[2,1.85,156.46]],"batl":[[0,2.02,746.14]],"ltp":1.98,"tv":1140.13,"id":2120}]}]}
{"op":"mcm","clk":"11754688126","pt":1722423381033,"mc":[{"id":"1.231242812","rc":[{"batb":[[0,1.86,9.86],[1,1.85,156.46],[2,1.8,106.55]],"batl":[[0,1.98,100],[1,2.02,746.14],[2,2.04,1591.75]],"ltp":1.98,"tv":1140.13,"id":2120}]}]}
{"op":"mcm","clk":"11754689082","pt":1722423392252,"mc":[{"id":"1.231242812","rc":[{"batb":[[0,2.02,554.03]],"ltp":2.02,"tv":1599.01,"id":424676}]}]}
{"op":"mcm","clk":"11754689594","pt":1722423398261,"mc":[{"id":"1.231242812","rc":[{"batl":[[0,2.12,534.04]],"ltp":2.02,"tv":1599.01,"id":424676}]}]}
{"op":"mcm","clk":"11754689631","pt":1722423398629,"mc":[{"id":"1.231242812","rc":[{"batb":[[0,2.04,10],[1,2.02,554.03],[2,1.71,16.34]],"ltp":2.02,"tv":1599.01,"id":424676}]}]}
{"op":"mcm","clk":"11754689907","pt":1722423401834,"mc":[{"id":"1.231242812","rc":[{"batb":[[0,2.02,554.03],[1,1.71,16.34],[2,1.26,32.61]],"ltp":2.02,"tv":1599.01,"id":424676}]}]}
{"op":"mcm","clk":"11754690220","pt":1722423405764,"mc":[{"id":"1.231242812","rc":[{"batb":[[0,2.04,10],[1,2.02,24.03],[2,1.71,16.34]],"ltp":2.02,"tv":1599.01,"id":424676}]}]}
{"op":"mcm","clk":"11754690502","pt":1722423409224,"mc":[{"id":"1.231242812","rc":[{"batb":[[0,2.02,24.03],[1,1.71,16.34],[2,1.26,32.61]],"ltp":2.02,"tv":1599.01,"id":424676},{"batl":[[0,1.98,222]],"ltp":1.98,"tv":1140.13,"id":2120}]}]}
{"op":"mcm","clk":"11754690756","pt":1722423412034,"mc":[{"id":"1.231242812","rc":[{"trd":[[1.98,476.26]],"batl":[[0,1.98,85.89]],"ltp":1.98,"tv":1412.35,"id":2120}],"tv":3011.36}]}
{"op":"mcm","clk":"11754690787","pt":1722423412445,"mc":[{"id":"1.231242812","rc":[{"batb":[[0,2.04,10],[1,2.02,24.03],[2,1.71,16.34]],"ltp":2.02,"tv":1599.01,"id":424676}]}]}
{"op":"mcm","clk":"11754691098","pt":1722423416059,"mc":[{"id":"1.231242812","rc":[{"batb":[[0,2.02,24.03],[1,1.71,16.34],[2,1.26,32.61]],"ltp":2.02,"tv":1599.01,"id":424676},{"trd":[[1.98,476.28]],"batl":[[0,1.98,85.88]],"ltp":1.98,"tv":1412.37,"id":2120}],"tv":3011.38}]}
{"op":"mcm","clk":"11754691724","pt":1722423423551,"mc":[{"id":"1.231242812","rc":[{"batb":[[0,2.04,10],[1,2.02,24.03],[2,1.71,16.34]],"ltp":2.02,"tv":1599.01,"id":424676}]}]}
{"op":"mcm","clk":"11754692002","pt":1722423426864,"mc":[{"id":"1.231242812","rc":[{"batb":[[0,2.02,24.03],[1,1.71,16.34],[2,1.26,32.61]],"ltp":2.02,"tv":1599.01,"id":424676}]}]}
{"op":"mcm","clk":"11754692188","pt":1722423429254,"mc":[{"id":"1.231242812","rc":[{"batb":[[0,2.04,10],[1,2.02,24.03],[2,1.71,16.34]],"ltp":2.02,"tv":1599.01,"id":424676},{"batb":[[0,1.87,10],[1,1.86,9.86],[2,1.85,156.46]],"batl":[[0,1.99,85.88]],"ltp":1.98,"tv":1412.37,"id":2120}]}]}
{"op":"mcm","clk":"11754692446","pt":1722423432268,"mc":[{"id":"1.231242812","rc":[{"batb":[[0,1.86,9.86],[1,1.85,156.46],[2,1.8,106.55]],"ltp":1.98,"tv":1412.37,"id":2120}]}]}
{"op":"mcm","clk":"11754692466","pt":1722423432575,"mc":[{"id":"1.231242812","rc":[{"batb":[[0,2.02,24.03],[1,1.71,16.34],[2,1.26,32.61]],"ltp":2.02,"tv":1599.01,"id":424676}]}]}
{"op":"mcm","clk":"11754692801","pt":1722423436455,"mc":[{"id":"1.231242812","rc":[{"batb":[[0,2.04,10],[1,2.02,24.03],[2,1.71,16.34]],"ltp":2.02,"tv":1599.01,"id":424676},{"batb":[[0,1.87,10],[1,1.86,9.86],[2,1.85,156.46]],"batl":[[0,2,85.88]],"ltp":1.98,"tv":1412.37,"id":2120}]}]}
{"op":"mcm","clk":"11754693094","pt":1722423439768,"mc":[{"id":"1.231242812","rc":[{"batb":[[0,2.02,24.03],[1,1.71,16.34],[2,1.26,32.61]],"ltp":2.02,"tv":1599.01,"id":424676},{"batb":[[0,1.86,9.86],[1,1.85,156.46],[2,1.8,106.55]],"ltp":1.98,"tv":1412.37,"id":2120}]}]}
{"op":"mcm","clk":"11754694885","pt":1722423460221,"mc":[{"id":"1.231242812","rc":[{"batb":[[0,2.04,10],[1,2.02,24.03],[2,1.71,16.34]],"ltp":2.02,"tv":1599.01,"id":424676},{"batb":[[0,1.87,10],[1,1.86,9.86],[2,1.85,156.46]],"ltp":1.98,"tv":1412.37,"id":2120}]}]}
{"op":"mcm","clk":"11754695226","pt":1722423463860,"mc":[{"id":"1.231242812","rc":[{"batb":[[0,2.02,24.03],[1,1.71,16.34],[2,1.26,32.61]],"ltp":2.02,"tv":1599.01,"id":424676},{"batb":[[0,1.86,9.86],[1,1.85,156.46],[2,1.8,106.55]],"ltp":1.98,"tv":1412.37,"id":2120}]}]}
{"op":"mcm","clk":"11754695514","pt":1722423466931,"mc":[{"id":"1.231242812","rc":[{"batb":[[0,2.04,10],[1,2.02,24.03],[2,1.71,16.34]],"ltp":2.02,"tv":1599.01,"id":424676},{"batb":[[0,1.87,10],[1,1.86,9.86],[2,1.85,156.46]],"ltp":1.98,"tv":1412.37,"id":2120}]}]}
{"op":"mcm","clk":"11754695813","pt":1722423470450,"mc":[{"id":"1.231242812","rc":[{"batb":[[0,2.02,24.03],[1,1.71,16.34],[2,1.26,32.61]],"ltp":2.02,"tv":1599.01,"id":424676},{"batb":[[0,1.86,9.86],[1,1.85,156.46],[2,1.8,106.55]],"ltp":1.98,"tv":1412.37,"id":2120}]}]}
{"op":"mcm","clk":"11754696145","pt":1722423474247,"mc":[{"id":"1.231242812","rc":[{"batb":[[0,2.04,10],[1,2.02,24.03],[2,1.71,16.34]],"ltp":2.02,"tv":1599.01,"id":424676},{"batb":[[0,1.87,10],[1,1.86,9.86],[2,1.85,156.46]],"ltp":1.98,"tv":1412.37,"id":2120}]}]}
{"op":"mcm","clk":"11754696465","pt":1722423478044,"mc":[{"id":"1.231242812","rc":[{"batb":[[0,2.02,24.03],[1,1.71,16.34],[2,1.26,32.61]],"ltp":2.02,"tv":1599.01,"id":424676},{"batb":[[0,1.86,9.86],[1,1.85,156.46],[2,1.8,106.55]],"ltp":1.98,"tv":1412.37,"id":2120}]}]}
{"op":"mcm","clk":"11754698984","pt":1722423509787,"mc":[{"id":"1.231242812","rc":[{"batb":[[0,2.04,10],[1,2.02,24.03],[2,1.71,16.34]],"ltp":2.02,"tv":1599.01,"id":424676},{"batb":[[0,1.87,10],[1,1.86,9.86],[2,1.85,156.46]],"ltp":1.98,"tv":1412.37,"id":2120}]}]}
{"op":"mcm","clk":"11754699300","pt":1722423513563,"mc":[{"id":"1.231242812","rc":[{"batb":[[0,2.02,24.03],[1,1.71,16.34],[2,1.26,32.61]],"ltp":2.02,"tv":1599.01,"id":424676},{"batb":[[0,1.86,9.86],[1,1.85,156.46],[2,1.8,106.55]],"ltp":1.98,"tv":1412.37,"id":2120}]}]}
{"op":"mcm","clk":"11754700240","pt":1722423523887,"mc":[{"id":"1.231242812","rc":[{"batb":[[0,2.04,10],[1,2.02,24.03],[2,2,520]],"ltp":2.02,"tv":1599.01,"id":424676},{"batb":[[0,1.87,10],[1,1.86,9.86],[2,1.85,156.46]],"ltp":1.98,"tv":1412.37,"id":2120}]}]}
{"op":"mcm","clk":"11754700516","pt":1722423527309,"mc":[{"id":"1.231242812","rc":[{"batb":[[0,2.02,24.03],[1,2,520],[2,1.71,16.34]],"ltp":2.02,"tv":1599.01,"id":424676},{"batb":[[0,1.86,9.86],[1,1.85,156.46],[2,1.8,106.55]],"ltp":1.98,"tv":1412.37,"id":2120}]}]}
{"op":"mcm","clk":"11754700798","pt":1722423530616,"mc":[{"id":"1.231242812","rc":[{"batb":[[0,2.04,10],[1,2.02,24.03],[2,2,520]],"ltp":2.02,"tv":1599.01,"id":424676},{"batb":[[0,1.87,10],[1,1.86,9.86],[2,1.85,156.46]],"ltp":1.98,"tv":1412.37,"id":2120}]}]}
{"op":"mcm","clk":"11754700865","pt":1722423531388,"mc":[{"id":"1.231242812","rc":[{"batl":[[2,2.04,655.53]],"ltp":1.98,"tv":1412.37,"id":2120}]}]}
{"op":"mcm","clk":"11754701056","pt":1722423534004,"mc":[{"id":"1.231242812","rc":[{"batb":[[0,2.02,24.03],[1,2,520],[2,1.71,16.34]],"ltp":2.02,"tv":1599.01,"id":424676},{"batb":[[0,1.86,9.86],[1,1.85,156.46],[2,1.8,106.55]],"ltp":1.98,"tv":1412.37,"id":2120}]}]}
{"op":"mcm","clk":"11754701334","pt":1722423537207,"mc":[{"id":"1.231242812","rc":[{"batb":[[0,2.02,544.03],[1,1.71,16.34],[2,1.26,32.61]],"ltp":2.02,"tv":1599.01,"id":424676}]}]}
{"op":"mcm","clk":"11754701352","pt":1722423537414,"mc":[{"id":"1.231242812","rc":[{"batb":[[0,2.04,10],[1,2.02,544.03],[2,1.71,16.34]],"ltp":2.02,"tv":1599.01,"id":424676},{"batb":[[0,1.87,10],[1,1.86,9.86],[2,1.85,156.46]],"ltp":1.98,"tv":1412.37,"id":2120}]}]}
{"op":"mcm","clk":"11754701674","pt":1722423540845,"mc":[{"id":"1.231242812","rc":[{"batb":[[0,2.02,544.03],[1,1.71,16.34],[2,1.26,32.61]],"ltp":2.02,"tv":1599.01,"id":424676},{"batb":[[0,1.86,9.86],[1,1.85,156.46],[2,1.8,106.55]],"ltp":1.98,"tv":1412.37,"id":2120}]}]}
{"op":"mcm","clk":"11754702176","pt":1722423547126,"mc":[{"id":"1.231242812","rc":[{"batb":[[0,2.04,10],[1,2.02,544.03],[2,1.71,16.34]],"ltp":2.02,"tv":1599.01,"id":424676},{"batb":[[0,1.87,10],[1,1.86,9.86],[2,1.85,156.46]],"ltp":1.98,"tv":1412.37,"id":2120}]}]}
{"op":"mcm","clk":"11754702405","pt":1722423550536,"mc":[{"id":"1.231242812","rc":[{"batb":[[0,2.02,544.03],[1,1.71,16.34],[2,1.26,32.61]],"ltp":2.02,"tv":1599.01,"id":424676},{"batb":[[0,1.86,9.86],[1,1.85,156.46],[2,1.8,106.55]],"ltp":1.98,"tv":1412.37,"id":2120}]}]}
{"op":"mcm","clk":"11754702607","pt":1722423553113,"mc":[{"id":"1.231242812","rc":[{"batb":[[0,2.04,10],[1,2.02,544.03],[2,1.71,16.34]],"ltp":2.02,"tv":1599.01,"id":424676},{"batb":[[0,1.87,10],[1,1.86,9.86],[2,1.85,156.46]],"batl":[[0,1.98,85.88]],"ltp":1.98,"tv":1412.37,"id":2120}]}]}
{"op":"mcm","clk":"11754702847","pt":1722423556111,"mc":[{"id":"1.231242812","rc":[{"batb":[[0,2.02,544.03],[1,1.71,16.34],[2,1.26,32.61]],"ltp":2.02,"tv":1599.01,"id":424676},{"batb":[[0,1.86,9.86],[1,1.85,156.46],[2,1.8,106.55]],"ltp":1.98,"tv":1412.37,"id":2120}]}]}
{"op":"mcm","clk":"11754703167","pt":1722423560013,"mc":[{"id":"1.231242812","rc":[{"batl":[[0,2.08,3.17],[1,2.12,534.04]],"ltp":2.02,"tv":1599.01,"id":424676}]}]}
{"op":"mcm","clk":"11754709487","pt":1722423628610,"mc":[{"id":"1.231242812","rc":[{"trd":[[1.84,4],[1.86,4],[1.89,105.72],[1.9,87.06]],"batb":[[0,2.04,16.67],[1,2.02,544.02],[2,1.71,16.34]],"batl":[[0,2.08,3.17]],"ltp":2.02,"tv":1598.94,"id":424676},{"trd":[[2.12,84.03]],"ltp":1.98,"tv":1412.36,"id":2120}],"tv":3011.3}]}
{"op":"mcm","clk":"11754710689","pt":1722423640698,"mc":[{"id":"1.231242812","rc":[{"batl":[[1,2.1,16.91],[2,2.12,534.04]],"ltp":2.02,"tv":1598.94,"id":424676},{"batb":[[0,1.9,16.91],[1,1.86,9.86],[2,1.85,156.46]],"ltp":1.98,"tv":1412.36,"id":2120}]}]}
{"op":"mcm","clk":"11754711392","pt":1722423648212,"mc":[{"id":"1.231242812","rc":[{"batl":[[1,2.1,550.95],[2,2.12,0]],"ltp":2.02,"tv":1598.94,"id":424676}]}]}
{"op":"mcm","clk":"11754711769","pt":1722423652089,"mc":[{"id":"1.231242812","rc":[{"batb":[[0,2.04,33.22]],"ltp":2.02,"tv":1598.94,"id":424676}]}]}
{"op":"mcm","clk":"11754714646","pt":1722423680252,"mc":[{"id":"1.231242812","rc":[{"batl":[[0,2.08,20.04]],"ltp":2.02,"tv":1598.94,"id":424676},{"batb":[[0,1.91,16.87],[1,1.9,16.91],[2,1.86,9.86]],"ltp":1.98,"tv":1412.36,"id":2120}]}]}
{"op":"mcm","clk":"11754714685","pt":1722423680768,"mc":[{"id":"1.231242812","rc":[{"batl":[[1,2.1,534.04]],"ltp":2.02,"tv":1598.94,"id":424676},{"batb":[[1,1.86,9.86],[2,1.85,156.46]],"ltp":1.98,"tv":1412.36,"id":2120}]}]}
{"op":"mcm","clk":"11754714870","pt":1722423682649,"mc":[{"id":"1.231242812","rc":[{"batb":[[0,1.86,9.86],[1,1.85,156.46],[2,1.8,106.55]],"ltp":1.98,"tv":1412.36,"id":2120}]}]}
{"op":"mcm","clk":"11754761941","pt":1722424272079,"mc":[{"id":"1.231242812","rc":[{"batb":[[1,2.02,24.02]],"ltp":2.02,"tv":1598.94,"id":424676}]}]}
{"op":"mcm","clk":"11754769741","pt":1722424365467,"mc":[{"id":"1.231242812","rc":[{"trd":[[2.08,40.08],[2.1,969.92]],"batl":[[0,2.1,49.08],[1,2.1,0]],"ltp":2.1,"tv":2608.93,"id":424676}],"tv":4021.29}]}
{"op":"mcm","clk":"11754769859","pt":1722424366660,"mc":[{"id":"1.231242812","rc":[{"batb":[[0,2.04,41.34]],"ltp":2.1,"tv":2608.93,"id":424676}]}]}
{"op":"mcm","clk":"11754771449","pt":1722424385014,"mc":[{"id":"1.231242812","rc":[{"trd":[[2.1,987.46]],"batl":[[0,2.1,40.31]],"ltp":2.1,"tv":2626.48,"id":424676}],"tv":4038.84}]}
{"op":"mcm","clk":"11754801859","pt":1722424743436,"mc":[{"id":"1.231242812","rc":[{"batb":[[0,1.85,156.46],[1,1.8,106.55],[2,1.73,59.74]],"ltp":1.98,"tv":1412.36,"id":2120}]}]}
{"op":"mcm","clk":"11754809237","pt":1722424830200,"mc":[{"id":"1.231242812","rc":[{"trd":[[2.1,991]],"batl":[[0,2.1,38.54]],"ltp":2.1,"tv":2630.02,"id":424676}],"tv":4042.38}]}
{"op":"mcm","clk":"11754895730","pt":1722425861642,"mc":[{"id":"1.231242812","rc":[{"batb":[[0,2.04,147.9]],"ltp":2.1,"tv":2630.02,"id":424676}]}]}
{"op":"mcm","clk":"11754898480","pt":1722425895786,"mc":[{"id":"1.231242812","rc":[{"batl":[[0,1.96,11.5],[1,1.98,85.88],[2,2.02,746.14]],"ltp":1.98,"tv":1412.36,"id":2120}]}]}
{"op":"mcm","clk":"11754914901","pt":1722426104258,"mc":[{"id":"1.231242812","rc":[{"batl":[[0,1.96,19.02]],"ltp":1.98,"tv":1412.36,"id":2120}]}]}
{"op":"mcm","clk":"11754956872","pt":1722426639219,"mc":[{"id":"1.231242812","rc":[{"trd":[[2.1,1008.77]],"batl":[[0,2.1,29.65]],"ltp":2.1,"tv":2647.79,"id":424676}],"tv":4060.15}]}
{"op":"mcm","clk":"11754960041","pt":1722426676079,"mc":[{"id":"1.231242812","rc":[{"batb":[[0,2.08,8.88],[1,2.04,147.9],[2,2.02,24.02]],"ltp":2.1,"tv":2647.79,"id":424676}]}]}
{"op":"mcm","clk":"11754960756","pt":1722426684752,"mc":[{"id":"1.231242812","rc":[{"trd":[[2.1,1026.54]],"batb":[[0,2.04,147.9],[1,2.02,24.02],[2,1.71,16.34]],"batl":[[0,2.1,20.77]],"ltp":2.1,"tv":2665.55,"id":424676}],"tv":4077.91}]}
{"op":"mcm","clk":"11754965363","pt":1722426741924,"mc":[{"id":"1.231242812","rc":[{"batl":[[2,2.02,468.24]],"ltp":1.98,"tv":1412.36,"id":2120}]}]}
{"op":"mcm","clk":"11754989784","pt":1722427019391,"mc":[{"id":"1.231242812","rc":[{"trd":[[2.1,1030.12]],"batl":[[0,2.1,18.98]],"ltp":2.1,"tv":2669.13,"id":424676}],"tv":4081.49}]}
{"op":"mcm","clk":"11755072035","pt":1722427974886,"mc":[{"id":"1.231242812","rc":[{"trd":[[1.9,87.06],[2.08,40.07],[2.1,1030.01]],"batb":[[0,2.04,148.03],[1,2.02,24.05]],"batl":[[0,2.1,18.98]],"ltp":2.1,"tv":2669.03,"id":424676},{"trd":[[1.98,476.24],[2.02,97.5],[2.04,95.56],[2.06,94.15],[2.08,183.89],[2.1,78.8],[2.12,84.01],[2.14,61.13]],"batl":[[0,1.96,19.01],[2,2.02,468.12]],"ltp":1.98,"tv":1412.15,"id":2120}],"tv":4081.18}]}
{"op":"mcm","clk":"11755170562","pt":1722429153970,"mc":[{"id":"1.231242812","rc":[{"trd":[[2.1,1067.97]],"batb":[[0,2.1,71.42],[1,2.04,148.03],[2,2.02,24.05]],"ltp":2.1,"tv":2706.99,"id":424676}],"tv":4119.14}]}
{"op":"mcm","clk":"11755170631","pt":1722429154745,"mc":[{"id":"1.231242812","rc":[{"batb":[[1,2.04,131.36]],"ltp":2.1,"tv":2706.99,"id":424676},{"batl":[[0,1.96,11.5]],"ltp":1.98,"tv":1412.15,"id":2120}]}]}
{"op":"mcm","clk":"11755170800","pt":1722429157062,"mc":[{"id":"1.231242812","rc":[{"batb":[[0,2.12,16.55],[1,2.1,71.42],[2,2.04,106.7]],"ltp":2.1,"tv":2706.99,"id":424676},{"batl":[[0,1.98,85.88],[1,2.02,468.12],[2,2.04,468.12]],"ltp":1.98,"tv":1412.15,"id":2120}]}]}
{"op":"mcm","clk":"11755173118","pt":1722429187589,"mc":[{"id":"1.231242812","rc":[{"batb":[[0,2.12,21.91]],"ltp":2.1,"tv":2706.99,"id":424676},{"batb":[[0,1.86,11.75],[1,1.85,156.46],[2,1.8,106.55]],"ltp":1.98,"tv":1412.15,"id":2120}]}]}
{"op":"mcm","clk":"11755178727","pt":1722429265579,"mc":[{"id":"1.231242812","rc":[{"trd":[[2.12,6.48]],"batb":[[0,2.12,18.67]],"ltp":2.12,"tv":2713.46,"id":424676}],"tv":4125.62}]}
{"op":"mcm","clk":"11755189302","pt":1722429403782,"mc":[{"id":"1.231242812","rc":[{"batl":[[0,2.16,7.01]],"ltp":2.12,"tv":2713.46,"id":424676},{"batb":[[0,1.86,19.43]],"ltp":1.98,"tv":1412.15,"id":2120}]}]}
{"op":"mcm","clk":"11755206297","pt":1722429603736,"mc":[{"id":"1.231242812","rc":[{"batl":[[1,2.12,26.3],[2,2.04,0]],"ltp":1.98,"tv":1412.15,"id":2120}]}]}
{"op":"mcm","clk":"11755206652","pt":1722429608040,"mc":[{"id":"1.231242812","rc":[{"trd":[[2.12,18.41]],"batb":[[0,2.12,12.71]],"ltp":2.12,"tv":2725.39,"id":424676}],"tv":4137.55}]}
{"op":"mcm","clk":"11755206786","pt":1722429609836,"mc":[{"id":"1.231242812","rc":[{"batl":[[0,1.9,5.9],[1,1.98,85.88],[2,2.12,26.3]],"ltp":1.98,"tv":1412.15,"id":2120}]}]}
{"op":"mcm","clk":"11755304967","pt":1722430978771,"mc":[{"id":"1.231242812","rc":[{"trd":[[1.84,4],[1.86,4],[1.89,105.72],[1.9,87.02],[2.08,40.08],[2.1,1068.28],[2.12,18.41]],"batb":[[0,2.12,12.72],[2,2.04,106.94]],"batl":[[0,2.16,7.01]],"ltp":2.12,"tv":2725.67,"id":424676},{"trd":[[1.98,476.31],[2.02,97.55],[2.04,95.61],[2.06,94.2],[2.08,183.98],[2.1,78.84],[2.12,84.04],[2.14,61.16]],"batb":[[0,1.86,19.44]],"batl":[[0,1.9,5.9],[2,2.12,26.29]],"ltp":1.98,"tv":1412.55,"id":2120}],"tv":4138.22}]}
{"op":"mcm","clk":"11755908970","pt":1722438774863,"mc":[{"id":"1.231242812","rc":[{"trd":[[1.89,105.72],[1.9,87.04],[2.08,40.05],[2.1,1067.35],[2.12,18.39]],"batb":[[0,2.12,12.69],[2,2.04,107.06]],"batl":[[0,2.16,7]],"ltp":2.12,"tv":2724.7,"id":424676},{"trd":[[1.98,476.07],[2.02,97.38],[2.04,95.44],[2.06,94.04],[2.08,183.66],[2.1,78.7],[2.12,83.93],[2.14,61.06]],"batb":[[0,1.86,19.41]],"batl":[[0,1.9,5.89],[2,2.12,26.3]],"ltp":1.98,"tv":1411.12,"id":2120}],"tv":4135.83}]}
{"op":"mcm","clk":"11756577310","pt":1722444174869,"mc":[{"id":"1.231242812","rc":[{"trd":[[1.89,105.72],[1.9,87.06],[2.08,40.06],[2.1,1067.72],[2.12,18.4]],"batb":[[0,2.12,12.7],[2,2.04,107.13]],"batl":[[0,2.16,7]],"ltp":2.12,"tv":2725.12,"id":424676},{"trd":[[1.98,476.16],[2.02,97.45],[2.04,95.51],[2.06,94.1],[2.08,183.78],[2.1,78.76],[2.12,83.97],[2.14,61.1]],"batb":[[0,1.86,19.42]],"batl":[[0,1.9,5.89],[2,2.12,26.3]],"ltp":1.98,"tv":1411.67,"id":2120}],"tv":4136.8}]}
{"op":"mcm","clk":"11756785979","pt":1722446035190,"mc":[{"id":"1.231242812","rc":[{"trd":[[1.89,105.73],[1.9,87.08],[2.08,40.05],[2.1,1067.18],[2.12,18.38]],"batb":[[0,2.12,12.69],[2,2.04,107.13]],"batl":[[0,2.16,7]],"ltp":2.12,"tv":2724.58,"id":424676},{"trd":[[1.98,476.03],[2.02,97.35],[2.04,95.41],[2.06,94],[2.08,183.6],[2.1,78.68],[2.12,83.91],[2.14,61.04]],"batb":[[0,1.86,19.4]],"batl":[[0,1.9,5.89],[2,2.12,26.31]],"ltp":1.98,"tv":1410.85,"id":2120}],"tv":4135.44}]}
{"op":"mcm","clk":"11756956725","pt":1722447521244,"mc":[{"id":"1.231242812","rc":[{"trd":[[2.16,4.65]],"batl":[[0,2.16,2.35]],"ltp":2.16,"tv":2729.22,"id":424676},{"trd":[[1.86,44.2]],"batb":[[0,1.85,156.46],[1,1.8,106.55],[2,1.71,500]],"batl":[[0,1.89,7.55],[1,1.9,5.89],[2,1.98,85.88]],"ltp":1.86,"tv":1455.06,"id":2120}],"tv":4184.29}]}
{"op":"mcm","clk":"11756956734","pt":1722447521343,"mc":[{"id":"1.231242812","rc":[{"batb":[[0,2.12,45.69]],"ltp":2.16,"tv":2729.22,"id":424676},{"batb":[[1,1.82,45.07],[2,1.8,106.55]],"ltp":1.86,"tv":1455.06,"id":2120}]}]}
{"op":"mcm","clk":"11756957493","pt":1722447529151,"mc":[{"id":"1.231242812","rc":[{"trd":[[2.16,6.74]],"batl":[[0,2.16,0.26]],"ltp":2.16,"tv":2731.31,"id":424676},{"trd":[[1.86,46.63]],"ltp":1.86,"tv":1457.49,"id":2120}],"tv":4188.8}]}
{"op":"mcm","clk":"11756957819","pt":1722447532160,"mc":[{"id":"1.231242812","rc":[{"batb":[[0,2.14,6.8],[1,2.12,45.69],[2,2.1,71.42]],"ltp":2.16,"tv":2731.31,"id":424676}]}]}
{"op":"mcm","clk":"11756958311","pt":1722447536546,"mc":[{"id":"1.231242812","rc":[{"batb":[[1,2.12,12.69]],"ltp":2.16,"tv":2731.31,"id":424676},{"batb":[[1,1.8,106.55],[2,1.71,500]],"ltp":1.86,"tv":1457.49,"id":2120}]}]}
{"op":"mcm","clk":"11756958979","pt":1722447542778,"mc":[{"id":"1.231242812","rc":[{"trd":[[1.85,133.7]],"batb":[[0,1.85,111.38]],"ltp":1.85,"tv":1547.65,"id":2120}],"tv":4278.96}]}
{"op":"mcm","clk":"11757194462","pt":1722449574917,"mc":[{"id":"1.231242812","rc":[{"trd":[[1.9,87.07],[2.08,40.06],[2.1,1067.49],[2.12,18.39],[2.16,6.74]],"batb":[[0,2.14,6.8],[1,2.12,12.7]],"ltp":2.16,"tv":2731.63,"id":424676},{"trd":[[1.86,46.64],[1.98,476.11],[2.02,97.4],[2.04,95.47],[2.06,94.06],[2.08,183.7],[2.1,78.72],[2.12,83.95],[2.14,61.07]],"batl":[[0,1.89,7.55],[1,1.9,5.89]],"ltp":1.85,"tv":1548.13,"id":2120}],"tv":4279.77}]}
{"op":"mcm","clk":"11757217045","pt":1722449705950,"mc":[{"id":"1.231242812","rc":[{"trd":[[1.85,355.7]],"batb":[[0,1.8,106.93],[1,1.71,500],[2,1.43,116.28]],"ltp":1.85,"tv":1770.13,"id":2120}],"tv":4501.77}]}
{"op":"mcm","clk":"11757217588","pt":1722449710231,"mc":[{"id":"1.231242812","rc":[{"batb":[[1,2.12,45.7]],"ltp":2.16,"tv":2731.63,"id":424676},{"batb":[[0,1.82,45.45],[1,1.8,106.55],[2,1.71,500]],"ltp":1.85,"tv":1770.13,"id":2120}]}]}
{"op":"mcm","clk":"11757314587","pt":1722450464119,"mc":[{"id":"1.231242812","rc":[{"trd":[[1.85,356.46]],"batb":[[0,1.82,45.07]],"batl":[[0,1.85,49.62],[1,1.89,7.55],[2,1.9,5.89]],"ltp":1.85,"tv":1770.89,"id":2120}],"tv":4502.53}]}
{"op":"mcm","clk":"11757314683","pt":1722450464823,"mc":[{"id":"1.231242812","rc":[{"batb":[[0,2.18,6.68]],"ltp":2.16,"tv":2731.63,"id":424676},{"batl":[[0,1.84,7.76],[1,1.85,49.62]],"ltp":1.85,"tv":1770.89,"id":2120}]}]}
{"op":"mcm","clk":"11757314787","pt":1722450465610,"mc":[{"id":"1.231242812","rc":[{"batb":[[0,2.18,13.82],[1,2.12,33]],"ltp":2.16,"tv":2731.63,"id":424676},{"batl":[[0,1.84,19.62],[2,1.98,85.88]],"ltp":1.85,"tv":1770.89,"id":2120}]}]}
{"op":"mcm","clk":"11757318753","pt":1722450497142,"mc":[{"id":"1.231242812","rc":[{"batl":[[0,1.84,24.57]],"ltp":1.85,"tv":1770.89,"id":2120}]}]}
{"op":"mcm","clk":"11757436515","pt":1722451364602,"mc":[{"id":"1.231242812","rc":[{"trd":[[2.18,64.94]],"batb":[[0,2.12,33],[1,2.1,71.42],[2,2.04,107.1]],"ltp":2.18,"tv":2759.62,"id":424676},{"trd":[[1.84,0.41]],"batl":[[0,1.84,24.16]],"ltp":1.84,"tv":1771.31,"id":2120}],"tv":4530.93}]}
{"op":"mcm","clk":"11757436796","pt":1722451366807,"mc":[{"id":"1.231242812","rc":[{"batl":[[0,1.84,19.21]],"ltp":1.84,"tv":1771.31,"id":2120}]}]}
{"op":"mcm","clk":"11757505367","pt":1722451869490,"mc":[{"id":"1.231242812","rc":[{"trd":[[1.84,38.83],[1.85,455.7]],"batb":[[0,1.85,231.17],[1,1.82,45.07],[2,1.8,106.55]],"batl":[[0,1.98,85.88],[1,2.12,26.31],[2,1.98,0]],"ltp":1.85,"tv":1908.97,"id":2120}],"tv":4668.59}]}
{"op":"mcm","clk":"11757505460","pt":1722451870320,"mc":[{"id":"1.231242812","rc":[{"batl":[[0,2.16,9.57]],"ltp":2.18,"tv":2759.62,"id":424676}]}]}
{"op":"mcm","clk":"11757505846","pt":1722451873100,"mc":[{"id":"1.231242812","rc":[{"trd":[[2.12,51.39]],"batb":[[0,2.1,71.42],[1,2.04,107.1],[2,2.02,24.14]],"ltp":2.12,"tv":2792.62,"id":424676},{"trd":[[1.9,36.82]],"batb":[[0,1.9,163.18],[1,1.85,231.17],[2,1.82,45.07]],"ltp":1.9,"tv":1945.79,"id":2120}],"tv":4738.41}]}
{"op":"mcm","clk":"11757505923","pt":1722451873720,"mc":[{"id":"1.231242812","rc":[{"batb":[[2,1.8,106.55]],"ltp":1.9,"tv":1945.79,"id":2120}]}]}
{"op":"mcm","clk":"11757506316","pt":1722451877109,"mc":[{"id":"1.231242812","rc":[{"trd":[[2.04,214.2],[2.1,1210.33]],"batb":[[0,2.02,24.14],[1,1.71,16.34],[2,1.43,116.28]],"batl":[[0,2.04,221.48]],"ltp":2.04,"tv":3149.66,"id":424676}],"tv":5095.45}]}
{"op":"mcm","clk":"11757506491","pt":1722451878526,"mc":[{"id":"1.231242812","rc":[{"batb":[[2,1.82,45.07]],"ltp":1.9,"tv":1945.79,"id":2120}]}]}
{"op":"mcm","clk":"11757510635","pt":1722451911991,"mc":[{"id":"1.231242812","rc":[{"trd":[[2.02,332.46]],"batb":[[0,1.72,10]],"batl":[[0,2.02,291.68],[1,2.04,221.48]],"ltp":2.02,"tv":3282.12,"id":424676},{"trd":[[1.98,561.99]],"batb":[[0,1.91,10],[1,1.9,163.18],[2,1.85,231.17]],"batl":[[0,2.12,26.31],[1,2.12,0]],"ltp":1.98,"tv":2031.67,"id":2120}],"tv":5313.79}]}
{"op":"mcm","clk":"11757511042","pt":1722451915160,"mc":[{"id":"1.231242812","rc":[{"batb":[[0,1.71,16.34],[1,1.43,116.28],[2,1.38,131.58]],"ltp":2.02,"tv":3282.12,"id":424676},{"batb":[[0,1.9,163.18],[1,1.85,231.17],[2,1.82,45.07]],"ltp":1.98,"tv":2031.67,"id":2120}]}]}
{"op":"mcm","clk":"11757514588","pt":1722451943172,"mc":[{"id":"1.231242812","rc":[{"batl":[[0,2,16.33],[1,2.02,291.68],[2,2.04,221.48]],"ltp":2.02,"tv":3282.12,"id":424676},{"batb":[[0,1.99,16.73],[1,1.9,163.18],[2,1.85,231.17]],"ltp":1.98,"tv":2031.67,"id":2120}]}]}
{"op":"mcm","clk":"11757514612","pt":1722451943364,"mc":[{"id":"1.231242812","rc":[{"batb":[[0,1.72,10],[1,1.71,16.34],[2,1.43,116.28]],"ltp":2.02,"tv":3282.12,"id":424676},{"batb":[[0,2,10],[1,1.99,16.73],[2,1.9,163.18]],"ltp":1.98,"tv":2031.67,"id":2120}]}]}
{"op":"mcm","clk":"11757514797","pt":1722451944784,"mc":[{"id":"1.231242812","rc":[{"batb":[[1,1.9,163.18],[2,1.85,231.17]],"ltp":1.98,"tv":2031.67,"id":2120}]}]}
{"op":"mcm","clk":"11757515064","pt":1722451946765,"mc":[{"id":"1.231242812","rc":[{"batb":[[0,1.71,16.34],[1,1.43,116.28],[2,1.38,131.58]],"ltp":2.02,"tv":3282.12,"id":424676},{"batb":[[0,1.9,163.18],[1,1.85,231.17],[2,1.82,45.07]],"ltp":1.98,"tv":2031.67,"id":2120}]}]}
{"op":"mcm","clk":"11757519187","pt":1722451978510,"mc":[{"id":"1.231242812","rc":[{"batb":[[0,1.72,10],[1,1.71,16.34],[2,1.43,116.28]],"ltp":2.02,"tv":3282.12,"id":424676},{"batb":[[0,1.91,10],[1,1.9,163.18],[2,1.85,231.17]],"ltp":1.98,"tv":2031.67,"id":2120}]}]}
{"op":"mcm","clk":"11757519638","pt":1722451981802,"mc":[{"id":"1.231242812","rc":[{"batb":[[0,1.71,16.34],[1,1.43,116.28],[2,1.38,131.58]],"ltp":2.02,"tv":3282.12,"id":424676},{"batb":[[0,1.9,163.18],[1,1.85,231.17],[2,1.82,45.07]],"ltp":1.98,"tv":2031.67,"id":2120}]}]}
{"op":"mcm","clk":"11757520057","pt":1722451984910,"mc":[{"id":"1.231242812","rc":[{"batb":[[0,1.72,10],[1,1.71,16.34],[2,1.43,116.28]],"ltp":2.02,"tv":3282.12,"id":424676},{"batb":[[0,2,10],[1,1.99,16.73],[2,1.9,163.18]],"ltp":1.98,"tv":2031.67,"id":2120}]}]}
{"op":"mcm","clk":"11757520360","pt":1722451987023,"mc":[{"id":"1.231242812","rc":[{"batb":[[1,1.9,163.18],[2,1.85,231.17]],"ltp":1.98,"tv":2031.67,"id":2120}]}]}
{"op":"mcm","clk":"11757520562","pt":1722451988427,"mc":[{"id":"1.231242812","rc":[{"batb":[[0,1.71,16.34],[1,1.43,116.28],[2,1.38,131.58]],"ltp":2.02,"tv":3282.12,"id":424676},{"batb":[[0,1.9,163.18],[1,1.85,231.17],[2,1.82,45.07]],"ltp":1.98,"tv":2031.67,"id":2120}]}]}
{"op":"mcm","clk":"11757521201","pt":1722451993437,"mc":[{"id":"1.231242812","rc":[{"batb":[[0,1.72,10],[1,1.71,16.34],[2,1.43,116.28]],"ltp":2.02,"tv":3282.12,"id":424676},{"batb":[[0,1.91,10],[1,1.9,163.18],[2,1.85,231.17]],"ltp":1.98,"tv":2031.67,"id":2120}]}]}
{"op":"mcm","clk":"11757521679","pt":1722451996906,"mc":[{"id":"1.231242812","rc":[{"batb":[[0,1.71,16.34],[1,1.43,116.28],[2,1.38,131.58]],"ltp":2.02,"tv":3282.12,"id":424676},{"batb":[[0,1.9,163.18],[1,1.85,231.17],[2,1.82,45.07]],"ltp":1.98,"tv":2031.67,"id":2120}]}]}
{"op":"mcm","clk":"11757522070","pt":1722452000137,"mc":[{"id":"1.231242812","rc":[{"batb":[[0,1.72,10],[1,1.71,16.34],[2,1.43,116.28]],"ltp":2.02,"tv":3282.12,"id":424676},{"batb":[[0,1.91,10],[1,1.9,163.18],[2,1.85,231.17]],"ltp":1.98,"tv":2031.67,"id":2120}]}]}
{"op":"mcm","clk":"11757522496","pt":1722452003547,"mc":[{"id":"1.231242812","rc":[{"batb":[[0,1.71,16.34],[1,1.43,116.28],[2,1.38,131.58]],"ltp":2.02,"tv":3282.12,"id":424676},{"batb":[[0,1.9,163.18],[1,1.85,231.17],[2,1.82,45.07]],"ltp":1.98,"tv":2031.67,"id":2120}]}]}
{"op":"mcm","clk":"11757525115","pt":1722452023075,"mc":[{"id":"1.231242812","rc":[{"batb":[[0,1.72,10],[1,1.71,16.34],[2,1.43,116.28]],"ltp":2.02,"tv":3282.12,"id":424676},{"batb":[[0,1.91,10],[1,1.9,163.18],[2,1.85,231.17]],"ltp":1.98,"tv":2031.67,"id":2120}]}]}
{"op":"mcm","clk":"11757525538","pt":1722452026836,"mc":[{"id":"1.231242812","rc":[{"batb":[[0,1.71,16.34],[1,1.43,116.28],[2,1.38,131.58]],"ltp":2.02,"tv":3282.12,"id":424676},{"batb":[[0,1.99,16.73]],"ltp":1.98,"tv":2031.67,"id":2120}]}]}
{"op":"mcm","clk":"11757525922","pt":1722452030143,"mc":[{"id":"1.231242812","rc":[{"batb":[[0,1.72,10],[1,1.71,16.34],[2,1.43,116.28]],"ltp":2.02,"tv":3282.12,"id":424676},{"batb":[[0,2,10],[1,1.99,16.73],[2,1.9,163.18]],"ltp":1.98,"tv":2031.67,"id":2120}]}]}
{"op":"mcm","clk":"11757526000","pt":1722452030872,"mc":[{"id":"1.231242812","rc":[{"batb":[[1,1.9,163.18],[2,1.85,231.17]],"ltp":1.98,"tv":2031.67,"id":2120}]}]}
{"op":"mcm","clk":"11757526294","pt":1722452033458,"mc":[{"id":"1.231242812","rc":[{"batb":[[0,1.71,16.34],[1,1.43,116.28],[2,1.38,131.58]],"ltp":2.02,"tv":3282.12,"id":424676},{"batb":[[0,1.9,163.18],[1,1.85,231.17],[2,1.82,45.07]],"ltp":1.98,"tv":2031.67,"id":2120}]}]}
{"op":"mcm","clk":"11757526884","pt":1722452037973,"mc":[{"id":"1.231242812","rc":[{"batb":[[0,1.72,10],[1,1.71,16.34],[2,1.43,116.28]],"ltp":2.02,"tv":3282.12,"id":424676},{"batb":[[0,1.91,10],[1,1.9,163.18],[2,1.85,231.17]],"ltp":1.98,"tv":2031.67,"id":2120}]}]}
{"op":"mcm","clk":"11757527324","pt":1722452041585,"mc":[{"id":"1.231242812","rc":[{"batb":[[0,1.71,16.34],[1,1.43,116.28],[2,1.38,131.58]],"ltp":2.02,"tv":3282.12,"id":424676},{"batb":[[0,1.9,163.18],[1,1.85,231.17],[2,1.82,45.07]],"ltp":1.98,"tv":2031.67,"id":2120}]}]}
{"op":"mcm","clk":"11757529604","pt":1722452059080,"mc":[{"id":"1.231242812","rc":[{"batb":[[0,1.72,10],[1,1.71,16.34],[2,1.43,116.28]],"ltp":2.02,"tv":3282.12,"id":424676},{"batb":[[0,1.91,10],[1,1.9,163.18],[2,1.85,231.17]],"ltp":1.98,"tv":2031.67,"id":2120}]}]}
{"op":"mcm","clk":"11757530038","pt":1722452062602,"mc":[{"id":"1.231242812","rc":[{"batb":[[0,1.71,16.34],[1,1.43,116.28],[2,1.38,131.58]],"ltp":2.02,"tv":3282.12,"id":424676},{"batb":[[0,1.9,163.18],[1,1.85,231.17],[2,1.82,45.07]],"ltp":1.98,"tv":2031.67,"id":2120}]}]}
{"op":"mcm","clk":"11757530914","pt":1722452069174,"mc":[{"id":"1.231242812","rc":[{"batb":[[0,1.99,16.73],[1,1.9,163.18],[2,1.85,231.17]],"ltp":1.98,"tv":2031.67,"id":2120}]}]}
{"op":"mcm","clk":"11757530937","pt":1722452069385,"mc":[{"id":"1.231242812","rc":[{"batb":[[0,1.72,10],[1,1.71,16.34],[2,1.43,116.28]],"ltp":2.02,"tv":3282.12,"id":424676},{"batb":[[0,2,10],[1,1.99,16.73],[2,1.9,163.18]],"ltp":1.98,"tv":2031.67,"id":2120}]}]}
{"op":"mcm","clk":"11757531204","pt":1722452071479,"mc":[{"id":"1.231242812","rc":[{"batb":[[1,1.9,163.18],[2,1.85,231.17]],"ltp":1.98,"tv":2031.67,"id":2120}]}]}
{"op":"mcm","clk":"11757531370","pt":1722452072709,"mc":[{"id":"1.231242812","rc":[{"batb":[[0,1.71,16.34],[1,1.43,116.28],[2,1.38,131.58]],"ltp":2.02,"tv":3282.12,"id":424676},{"batb":[[0,1.9,163.18],[1,1.85,231.17],[2,1.82,45.07]],"ltp":1.98,"tv":2031.67,"id":2120}]}]}
{"op":"mcm","clk":"11757533154","pt":1722452086217,"mc":[{"id":"1.231242812","rc":[{"batb":[[0,1.72,10],[1,1.71,16.34],[2,1.43,116.28]],"ltp":2.02,"tv":3282.12,"id":424676},{"batb":[[0,1.91,10],[1,1.9,163.18],[2,1.85,231.17]],"ltp":1.98,"tv":2031.67,"id":2120}]}]}
{"op":"mcm","clk":"11757533591","pt":1722452089410,"mc":[{"id":"1.231242812","rc":[{"batb":[[0,1.71,16.34],[1,1.43,116.28],[2,1.38,131.58]],"ltp":2.02,"tv":3282.12,"id":424676},{"batb":[[0,1.9,163.18],[1,1.85,231.17],[2,1.82,45.07]],"ltp":1.98,"tv":2031.67,"id":2120}]}]}
{"op":"mcm","clk":"11757535499","pt":1722452103901,"mc":[{"id":"1.231242812","rc":[{"batb":[[0,1.72,10],[1,1.71,16.34],[2,1.43,116.28]],"ltp":2.02,"tv":3282.12,"id":424676},{"batb":[[0,1.91,10],[1,1.9,163.18],[2,1.85,231.17]],"ltp":1.98,"tv":2031.67,"id":2120}]}]}
{"op":"mcm","clk":"11757535977","pt":1722452107335,"mc":[{"id":"1.231242812","rc":[{"batb":[[0,1.71,16.34],[1,1.43,116.28],[2,1.38,131.58]],"ltp":2.02,"tv":3282.12,"id":424676},{"batb":[[0,1.9,163.18],[1,1.85,231.17],[2,1.82,45.07]],"ltp":1.98,"tv":2031.67,"id":2120}]}]}
{"op":"mcm","clk":"11757536442","pt":1722452110832,"mc":[{"id":"1.231242812","rc":[{"batb":[[0,1.72,10],[1,1.71,16.34],[2,1.43,116.28]],"ltp":2.02,"tv":3282.12,"id":424676},{"batb":[[0,2,10],[1,1.99,16.73],[2,1.9,163.18]],"ltp":1.98,"tv":2031.67,"id":2120}]}]}
{"op":"mcm","clk":"11757536719","pt":1722452112839,"mc":[{"id":"1.231242812","rc":[{"batb":[[1,1.9,163.18],[2,1.85,231.17]],"ltp":1.98,"tv":2031.67,"id":2120}]}]}
{"op":"mcm","clk":"11757536935","pt":1722452114256,"mc":[{"id":"1.231242812","rc":[{"batb":[[0,1.71,16.34],[1,1.43,116.28],[2,1.38,131.58]],"ltp":2.02,"tv":3282.12,"id":424676},{"batb":[[0,1.9,163.18],[1,1.85,231.17],[2,1.82,45.07]],"ltp":1.98,"tv":2031.67,"id":2120}]}]}
{"op":"mcm","clk":"11757542325","pt":1722452153665,"mc":[{"id":"1.231242812","rc":[{"batb":[[0,1.72,10],[1,1.71,16.34],[2,1.43,116.28]],"ltp":2.02,"tv":3282.12,"id":424676},{"batb":[[0,2,10],[1,1.99,16.73],[2,1.9,163.18]],"ltp":1.98,"tv":2031.67,"id":2120}]}]}
{"op":"mcm","clk":"11757542588","pt":1722452155892,"mc":[{"id":"1.231242812","rc":[{"batb":[[1,1.9,163.18],[2,1.85,231.17]],"ltp":1.98,"tv":2031.67,"id":2120}]}]}
{"op":"mcm","clk":"11757542727","pt":1722452156998,"mc":[{"id":"1.231242812","rc":[{"batb":[[0,1.71,16.34],[1,1.43,116.28],[2,1.38,131.58]],"ltp":2.02,"tv":3282.12,"id":424676},{"batb":[[0,1.9,163.18],[1,1.85,231.17],[2,1.82,45.07]],"ltp":1.98,"tv":2031.67,"id":2120}]}]}
{"op":"mcm","clk":"11757543771","pt":1722452165099,"mc":[{"id":"1.231242812","rc":[{"batl":[[0,2,30.59]],"ltp":2.02,"tv":3282.12,"id":424676},{"batb":[[0,1.99,14.53],[1,1.9,163.18],[2,1.85,231.17]],"ltp":1.98,"tv":2031.67,"id":2120}]}]}
{"op":"mcm","clk":"11757543954","pt":1722452166504,"mc":[{"id":"1.231242812","rc":[{"batb":[[0,1.9,163.18],[1,1.85,231.17],[2,1.82,45.07]],"ltp":1.98,"tv":2031.67,"id":2120}]}]}
{"op":"mcm","clk":"11757544293","pt":1722452169081,"mc":[{"id":"1.231242812","rc":[{"batb":[[0,1.72,10],[1,1.71,16.34],[2,1.43,116.28]],"ltp":2.02,"tv":3282.12,"id":424676},{"batb":[[0,2,10],[1,1.9,163.18],[2,1.85,231.17]],"ltp":1.98,"tv":2031.67,"id":2120}]}]}
{"op":"mcm","clk":"11757544871","pt":1722452173592,"mc":[{"id":"1.231242812","rc":[{"batb":[[0,1.71,16.34],[1,1.43,116.28],[2,1.38,131.58]],"ltp":2.02,"tv":3282.12,"id":424676},{"batb":[[0,1.9,163.18],[1,1.85,231.17],[2,1.82,45.07]],"ltp":1.98,"tv":2031.67,"id":2120}]}]}
{"op":"mcm","clk":"11757549784","pt":1722452215032,"mc":[{"id":"1.231242812","rc":[{"trd":[[2,61.19]],"batb":[[0,2,117.9],[1,1.71,16.34],[2,1.43,116.28]],"batl":[[0,2.02,291.68],[1,2.04,221.48],[2,2.04,0]],"ltp":2.0,"tv":3343.32,"id":424676},{"batb":[[0,1.91,10],[1,1.9,163.18],[2,1.85,231.17]],"ltp":1.98,"tv":2031.67,"id":2120}],"tv":5374.99}]}
{"op":"mcm","clk":"11757549899","pt":1722452216126,"mc":[{"id":"1.231242812","rc":[{"batb":[[0,2,132.16]],"ltp":2.0,"tv":3343.32,"id":424676}]}]}
{"op":"mcm","clk":"11757549962","pt":1722452216746,"mc":[{"id":"1.231242812","rc":[{"batb":[[0,2,148.49]],"ltp":2.0,"tv":3343.32,"id":424676}]}]}
{"op":"mcm","clk":"11757550159","pt":1722452218424,"mc":[{"id":"1.231242812","rc":[{"batb":[[0,1.9,163.18],[1,1.85,231.17],[2,1.82,45.07]],"ltp":1.98,"tv":2031.67,"id":2120}]}]}
{"op":"mcm","clk":"11757550912","pt":1722452224840,"mc":[{"id":"1.231242812","rc":[{"trd":[[2,358.17]],"batb":[[0,1.72,10]],"batl":[[0,2,451.51],[1,2.02,291.68],[2,2.04,221.48]],"ltp":2.0,"tv":3640.29,"id":424676},{"batb":[[0,1.91,10],[1,1.9,163.18],[2,1.85,231.17]],"ltp":1.98,"tv":2031.67,"id":2120}],"tv":5671.97}]}
{"op":"mcm","clk":"11757551328","pt":1722452228270,"mc":[{"id":"1.231242812","rc":[{"batb":[[0,1.71,16.34],[1,1.43,116.28],[2,1.38,131.58]],"ltp":2.0,"tv":3640.29,"id":424676},{"batb":[[0,1.9,163.18],[1,1.85,231.17],[2,1.82,45.07]],"ltp":1.98,"tv":2031.67,"id":2120}]}]}
{"op":"mcm","clk":"11757553029","pt":1722452242172,"mc":[{"id":"1.231242812","rc":[{"trd":[[2,403.17]],"batb":[[0,1.72,10],[1,1.71,16.34],[2,1.43,116.28]],"batl":[[0,2,429.01]],"ltp":2.0,"tv":3685.29,"id":424676},{"batb":[[0,1.91,10],[1,1.9,163.18],[2,1.85,231.17]],"ltp":1.98,"tv":2031.67,"id":2120}],"tv":5716.97}]}
{"op":"mcm","clk":"11757553387","pt":1722452245667,"mc":[{"id":"1.231242812","rc":[{"batb":[[0,1.71,16.34],[1,1.43,116.28],[2,1.38,131.58]],"ltp":2.0,"tv":3685.29,"id":424676},{"batb":[[0,1.9,163.18],[1,1.85,231.17],[2,1.82,45.07]],"ltp":1.98,"tv":2031.67,"id":2120}]}]}
{"op":"mcm","clk":"11757554658","pt":1722452256126,"mc":[{"id":"1.231242812","rc":[{"batl":[[0,1.99,16.33],[1,2,429.01],[2,2.02,291.68]],"ltp":2.0,"tv":3685.29,"id":424676},{"batb":[[0,2.02,16.73],[1,1.9,163.18],[2,1.85,231.17]],"ltp":1.98,"tv":2031.67,"id":2120}]}]}
{"op":"mcm","clk":"11757554681","pt":1722452256333,"mc":[{"id":"1.231242812","rc":[{"batb":[[0,2.04,10],[1,2.02,16.73],[2,1.9,163.18]],"ltp":1.98,"tv":2031.67,"id":2120}]}]}
{"op":"mcm","clk":"11757554944","pt":1722452258837,"mc":[{"id":"1.231242812","rc":[{"batb":[[1,1.9,163.18],[2,1.85,231.17]],"ltp":1.98,"tv":2031.67,"id":2120}]}]}
{"op":"mcm","clk":"11757555044","pt":1722452259631,"mc":[{"id":"1.231242812","rc":[{"batb":[[0,1.9,163.18],[1,1.85,231.17],[2,1.82,45.07]],"ltp":1.98,"tv":2031.67,"id":2120}]}]}
{"op":"mcm","clk":"11757559537","pt":1722452296009,"mc":[{"id":"1.231242812","rc":[{"trd":[[1.99,104.5]],"batl":[[0,1.99,14.08]],"ltp":1.99,"tv":3689.79,"id":424676},{"batb":[[0,1.91,10],[1,1.9,163.18],[2,1.85,231.17]],"ltp":1.98,"tv":2031.67,"id":2120}],"tv":5721.46}]}
{"op":"mcm","clk":"11757559681","pt":1722452297288,"mc":[{"id":"1.231242812","rc":[{"batb":[[0,2.02,16.73],[1,1.91,10],[2,1.9,163.18]],"ltp":1.98,"tv":2031.67,"id":2120}]}]}
{"op":"mcm","clk":"11757559931","pt":1722452299406,"mc":[{"id":"1.231242812","rc":[{"batb":[[1,1.9,163.18],[2,1.85,231.17]],"ltp":1.98,"tv":2031.67,"id":2120}]}]}
{"op":"mcm","clk":"11757581577","pt":1722452469538,"mc":[{"id":"1.231242812","rc":[{"trd":[[1.84,4],[1.86,4],[1.89,105.72],[1.9,86.95],[1.99,104.5],[2,403.14],[2.02,332.48],[2.04,214.31],[2.08,40.05],[2.1,1210.08],[2.12,51.38],[2.16,6.74],[2.18,64.93]],"batl":[[0,1.99,14.07]],"ltp":1.99,"tv":3689.48,"id":424676},{"trd":[[1.84,38.82],[1.86,46.63],[1.98,561.92],[2.02,97.36],[2.04,95.42],[2.06,94.01],[2.08,183.61],[2.1,78.68],[2.12,83.89],[2.14,61.04]],"batb":[[0,2.04,10],[1,2.02,16.72],[2,1.9,163.18]],"batl":[[0,2.12,26.27]],"ltp":1.98,"tv":2031.21,"id":2120}],"tv":5720.7}]}
{"op":"mcm","clk":"11757582115","pt":1722452473046,"mc":[{"id":"1.231242812","rc":[{"batb":[[0,2.02,16.72],[1,1.9,163.18],[2,1.85,231.17]],"ltp":1.98,"tv":2031.21,"id":2120}]}]}
{"op":"mcm","clk":"11757585283","pt":1722452497186,"mc":[{"id":"1.231242812","rc":[{"batb":[[0,2.02,33.47]],"ltp":1.98,"tv":2031.21,"id":2120}]}]}
{"op":"mcm","clk":"11757585301","pt":1722452497293,"mc":[{"id":"1.231242812","rc":[{"batb":[[0,2.04,10],[1,2.02,33.47],[2,1.9,163.18]],"ltp":1.98,"tv":2031.21,"id":2120}]}]}
{"op":"mcm","clk":"11757585713","pt":1722452500799,"mc":[{"id":"1.231242812","rc":[{"batb":[[0,2.02,33.47],[1,1.9,163.18],[2,1.85,231.17]],"ltp":1.98,"tv":2031.21,"id":2120}]}]}
{"op":"mcm","clk":"11757684179","pt":1722453241430,"mc":[{"id":"1.231242812","rc":[{"batb":[[0,2.04,10],[1,2.02,33.47],[2,1.9,163.18]],"ltp":1.98,"tv":2031.21,"id":2120}]}]}
{"op":"mcm","clk":"11757684692","pt":1722453244845,"mc":[{"id":"1.231242812","rc":[{"batb":[[0,2.02,33.47],[1,1.9,163.18],[2,1.85,231.17]],"ltp":1.98,"tv":2031.21,"id":2120}]}]}
{"op":"mcm","clk":"11757787205","pt":1722453981761,"mc":[{"id":"1.231242812","rc":[{"trd":[[1.99,166.61]],"batb":[[0,1.99,137.41],[1,1.71,16.34],[2,1.43,116.28]],"batl":[[0,2,429.01],[1,2.02,291.68],[2,2.04,221.48]],"ltp":1.99,"tv":3751.59,"id":424676},{"trd":[[2.02,130.82]],"batb":[[0,1.91,10]],"ltp":2.02,"tv":2064.68,"id":2120}],"tv":5816.28}]}
{"op":"mcm","clk":"11757787378","pt":1722453983270,"mc":[{"id":"1.231242812","rc":[{"batb":[[0,1.99,153.73]],"ltp":1.99,"tv":3751.59,"id":424676},{"batl":[[0,2.02,16.72],[1,2.12,26.27]],"ltp":2.02,"tv":2064.68,"id":2120}]}]}
{"op":"mcm","clk":"11757787390","pt":1722453983377,"mc":[{"id":"1.231242812","rc":[{"batl":[[0,2.02,33.47]],"ltp":2.02,"tv":2064.68,"id":2120}]}]}
{"op":"mcm","clk":"11757787623","pt":1722453985171,"mc":[{"id":"1.231242812","rc":[{"batb":[[0,1.9,163.18],[1,1.85,231.17],[2,1.8,106.55]],"ltp":2.02,"tv":2064.68,"id":2120}]}]}
{"op":"mcm","clk":"11757787988","pt":1722453988160,"mc":[{"id":"1.231242812","rc":[{"batb":[[0,1.99,16.32]],"ltp":1.99,"tv":3751.59,"id":424676},{"batb":[[0,1.91,10],[1,1.9,163.18],[2,1.85,231.17]],"ltp":2.02,"tv":2064.68,"id":2120}]}]}
{"op":"mcm","clk":"11757788461","pt":1722453991478,"mc":[{"id":"1.231242812","rc":[{"batb":[[0,1.9,163.18],[1,1.85,231.17],[2,1.8,106.55]],"ltp":2.02,"tv":2064.68,"id":2120}]}]}
{"op":"mcm","clk":"11757788760","pt":1722453993368,"mc":[{"id":"1.231242812","rc":[{"trd":[[2,677.96]],"batl":[[0,2,291.6]],"ltp":2.0,"tv":4026.41,"id":424676}],"tv":6091.1}]}
{"op":"mcm","clk":"11757810255","pt":1722454135954,"mc":[{"id":"1.231242812","rc":[{"batb":[[0,1.91,10],[1,1.9,163.18],[2,1.85,231.17]],"ltp":2.02,"tv":2064.68,"id":2120}]}]}
{"op":"mcm","clk":"11757810678","pt":1722454138839,"mc":[{"id":"1.231242812","rc":[{"trd":[[2,1037.96]],"batl":[[0,2,111.6]],"ltp":2.0,"tv":4386.41,"id":424676}],"tv":6451.1}]}
{"op":"mcm","clk":"11757810771","pt":1722454139529,"mc":[{"id":"1.231242812","rc":[{"batb":[[0,1.9,163.18],[1,1.85,231.17],[2,1.8,106.55]],"ltp":2.02,"tv":2064.68,"id":2120}]}]}
{"op":"mcm","clk":"11757821388","pt":1722454211282,"mc":[{"id":"1.231242812","rc":[{"trd":[[2,1054.3]],"batl":[[0,2,103.43]],"ltp":2.0,"tv":4402.75,"id":424676},{"batb":[[0,1.91,10],[1,1.9,163.18],[2,1.85,231.17]],"ltp":2.02,"tv":2064.68,"id":2120}],"tv":6467.44}]}
{"op":"mcm","clk":"11757821940","pt":1722454214807,"mc":[{"id":"1.231242812","rc":[{"batb":[[0,1.9,163.18],[1,1.85,231.17],[2,1.8,106.55]],"ltp":2.02,"tv":2064.68,"id":2120}]}]}
{"op":"mcm","clk":"11757836108","pt":1722454309546,"mc":[{"id":"1.231242812","rc":[{"batb":[[0,1.91,10],[1,1.9,163.18],[2,1.85,231.17]],"ltp":2.02,"tv":2064.68,"id":2120}]}]}
{"op":"mcm","clk":"11757836602","pt":1722454313032,"mc":[{"id":"1.231242812","rc":[{"batb":[[0,1.9,163.18],[1,1.85,231.17],[2,1.8,106.55]],"ltp":2.02,"tv":2064.68,"id":2120}]}]}
{"op":"mcm","clk":"11757844043","pt":1722454365999,"mc":[{"id":"1.231242812","rc":[{"trd":[[1.99,199.25]],"batb":[[0,1.71,16.34],[1,1.43,116.28],[2,1.38,131.58]],"batl":[[0,1.99,283.68],[1,2,103.43],[2,2.02,291.68]],"ltp":1.99,"tv":4435.4,"id":424676},{"batb":[[0,1.91,10],[1,1.9,163.18],[2,1.85,231.17]],"batl":[[0,2.02,16.75]],"ltp":2.02,"tv":2064.68,"id":2120}],"tv":6500.08}]}
{"op":"mcm","clk":"11757844191","pt":1722454367005,"mc":[{"id":"1.231242812","rc":[{"batl":[[0,2.1,16.11]],"ltp":2.02,"tv":2064.68,"id":2120}]}]}
{"op":"mcm","clk":"11757844334","pt":1722454368099,"mc":[{"id":"1.231242812","rc":[{"batl":[[0,2.1,32.2]],"ltp":2.02,"tv":2064.68,"id":2120}]}]}
{"op":"mcm","clk":"11757844436","pt":1722454368887,"mc":[{"id":"1.231242812","rc":[{"batl":[[0,1.98,300],[1,1.99,283.68],[2,2,103.43]],"ltp":1.99,"tv":4435.4,"id":424676},{"batb":[[0,1.9,163.18],[1,1.85,231.17],[2,1.8,106.55]],"ltp":2.02,"tv":2064.68,"id":2120}]}]}
{"op":"mcm","clk":"11757849104","pt":1722454401950,"mc":[{"id":"1.231242812","rc":[{"batl":[[0,1.97,16.32],[1,1.98,300],[2,1.99,283.68]],"ltp":1.99,"tv":4435.4,"id":424676},{"batb":[[0,1.91,10],[1,1.9,163.18],[2,1.85,231.17]],"ltp":2.02,"tv":2064.68,"id":2120}]}]}
{"op":"mcm","clk":"11757849557","pt":1722454405242,"mc":[{"id":"1.231242812","rc":[{"batb":[[0,1.9,163.18],[1,1.85,231.17],[2,1.8,106.55]],"ltp":2.02,"tv":2064.68,"id":2120}]}]}
{"op":"mcm","clk":"11757869579","pt":1722454550623,"mc":[{"id":"1.231242812","rc":[{"batl":[[0,1.97,30.98]],"ltp":1.99,"tv":4435.4,"id":424676},{"batb":[[0,1.91,10],[1,1.9,163.18],[2,1.85,231.17]],"ltp":2.02,"tv":2064.68,"id":2120}]}]}
{"op":"mcm","clk":"11757870038","pt":1722454553924,"mc":[{"id":"1.231242812","rc":[{"batb":[[0,1.9,163.18],[1,1.85,231.17],[2,1.8,106.55]],"ltp":2.02,"tv":2064.68,"id":2120}]}]}
{"op":"mcm","clk":"11757883347","pt":1722454650619,"mc":[{"id":"1.231242812","rc":[{"batb":[[0,1.91,10],[1,1.9,163.18],[2,1.85,231.17]],"ltp":2.02,"tv":2064.68,"id":2120}]}]}
{"op":"mcm","clk":"11757883762","pt":1722454653925,"mc":[{"id":"1.231242812","rc":[{"batb":[[0,1.9,163.18],[1,1.85,231.17],[2,1.8,106.55]],"ltp":2.02,"tv":2064.68,"id":2120}]}]}
{"op":"mcm","clk":"11757888552","pt":1722454689959,"mc":[{"id":"1.231242812","rc":[{"batb":[[2,1.82,45.07]],"ltp":2.02,"tv":2064.68,"id":2120}]}]}
{"op":"mcm","clk":"11757888611","pt":1722454690374,"mc":[{"id":"1.231242812","rc":[{"batb":[[0,1.91,10],[1,1.9,163.18],[2,1.85,231.17]],"ltp":2.02,"tv":2064.68,"id":2120}]}]}
{"op":"mcm","clk":"11757889179","pt":1722454693753,"mc":[{"id":"1.231242812","rc":[{"batb":[[0,1.9,163.18],[1,1.85,231.17],[2,1.82,45.07]],"ltp":2.02,"tv":2064.68,"id":2120}]}]}
{"op":"mcm","clk":"11757943182","pt":1722455037221,"mc":[{"id":"1.231242812","rc":[{"trd":[[1.97,130.98],[1.98,173.21]],"batb":[[0,1.91,15.13],[1,1.71,16.34],[2,1.43,116.28]],"batl":[[0,1.98,126.79],[1,1.99,283.68],[2,2,103.43]],"ltp":1.98,"tv":4639.59,"id":424676},{"trd":[[2.02,330.82]],"batb":[[0,1.91,10],[1,1.9,163.18],[2,1.85,231.17]],"ltp":2.02,"tv":2264.68,"id":2120}],"tv":6904.28}]}
{"op":"mcm","clk":"11757943297","pt":1722455038133,"mc":[{"id":"1.231242812","rc":[{"batb":[[0,1.91,31.96]],"ltp":1.98,"tv":4639.59,"id":424676}]}]}
{"op":"mcm","clk":"11757943533","pt":1722455039930,"mc":[{"id":"1.231242812","rc":[{"batb":[[0,1.9,163.18],[1,1.85,231.17],[2,1.82,45.07]],"ltp":2.02,"tv":2264.68,"id":2120}]}]}
{"op":"mcm","clk":"11757951535","pt":1722455103219,"mc":[{"id":"1.231242812","rc":[{"trd":[[1.98,275.23]],"batl":[[0,1.98,24.77]],"ltp":1.98,"tv":4741.61,"id":424676},{"trd":[[2.02,430.82]],"batb":[[0,1.91,10],[1,1.9,163.18],[2,1.85,231.17]],"ltp":2.02,"tv":2364.68,"id":2120}],"tv":7106.3}]}
{"op":"mcm","clk":"11757951995","pt":1722455106499,"mc":[{"id":"1.231242812","rc":[{"batb":[[0,1.9,163.18],[1,1.85,231.17],[2,1.82,45.07]],"ltp":2.02,"tv":2364.68,"id":2120}]}]}
{"op":"mcm","clk":"11757966082","pt":1722455212075,"mc":[{"id":"1.231242812","rc":[{"trd":[[1.91,164.14]],"batb":[[0,1.71,16.34],[1,1.43,116.28],[2,1.38,131.58]],"batl":[[0,1.91,268.03],[1,1.98,24.77],[2,1.99,283.68]],"ltp":1.91,"tv":4805.54,"id":424676},{"batb":[[0,1.91,10],[1,1.9,163.18],[2,1.85,231.17]],"ltp":2.02,"tv":2364.68,"id":2120}],"tv":7170.23}]}
{"op":"mcm","clk":"11757966537","pt":1722455215279,"mc":[{"id":"1.231242812","rc":[{"trd":[[1.9,122.54]],"batl":[[0,1.9,164.41],[1,1.91,268.03],[2,1.98,24.77]],"ltp":1.9,"tv":4841.13,"id":424676},{"trd":[[2.1,110.88]],"batb":[[0,1.9,163.18],[1,1.85,231.17],[2,1.82,45.07]],"batl":[[0,2.12,26.27],[1,2.12,0]],"ltp":2.1,"tv":2396.88,"id":2120}],"tv":7238.01}]}
{"op":"mcm","clk":"11757975295","pt":1722455283580,"mc":[{"id":"1.231242812","rc":[{"trd":[[1.9,286.95]],"batl":[[0,1.91,268.03],[1,1.98,24.77],[2,1.99,283.68]],"ltp":1.9,"tv":5005.54,"id":424676},{"trd":[[2.1,259.63]],"batb":[[0,1.91,10],[1,1.9,163.18],[2,1.85,231.17]],"batl":[[0,2.1,1.25],[1,2.12,26.27]],"ltp":2.1,"tv":2545.63,"id":2120}],"tv":7551.17}]}
{"op":"mcm","clk":"11757975663","pt":1722455286946,"mc":[{"id":"1.231242812","rc":[{"batb":[[0,1.9,163.18],[1,1.85,231.17],[2,1.82,45.07]],"ltp":2.1,"tv":2545.63,"id":2120}]}]}
{"op":"mcm","clk":"11757988295","pt":1722455401675,"mc":[{"id":"1.231242812","rc":[{"trd":[[1.91,381.94]],"batl":[[0,1.91,50.23]],"ltp":1.91,"tv":5223.34,"id":424676},{"trd":[[2.08,383.61]],"batb":[[0,1.91,10],[1,1.9,163.18],[2,1.85,231.17]],"ltp":2.08,"tv":2745.63,"id":2120}],"tv":7968.97}]}
{"op":"mcm","clk":"11757988693","pt":1722455404976,"mc":[{"id":"1.231242812","rc":[{"batb":[[0,1.9,163.18],[1,1.85,231.17],[2,1.82,45.07]],"ltp":2.08,"tv":2745.63,"id":2120}]}]}
{"op":"mcm","clk":"11757991138","pt":1722455428122,"mc":[{"id":"1.231242812","rc":[{"trd":[[1.91,387.5]],"batl":[[0,1.91,47.45]],"ltp":1.91,"tv":5228.9,"id":424676},{"batb":[[0,1.91,10],[1,1.9,163.18],[2,1.85,231.17]],"ltp":2.08,"tv":2745.63,"id":2120}],"tv":7974.53}]}
{"op":"mcm","clk":"11757991539","pt":1722455431565,"mc":[{"id":"1.231242812","rc":[{"batb":[[0,1.9,163.18],[1,1.85,231.17],[2,1.82,45.07]],"ltp":2.08,"tv":2745.63,"id":2120}]}]}
{"op":"mcm","clk":"11758042585","pt":1722455908241,"mc":[{"id":"1.231242812","rc":[{"batb":[[0,1.91,10],[1,1.9,163.18],[2,1.85,231.17]],"ltp":2.08,"tv":2745.63,"id":2120}]}]}
{"op":"mcm","clk":"11758042980","pt":1722455911926,"mc":[{"id":"1.231242812","rc":[{"batb":[[0,1.9,163.18],[1,1.85,231.17],[2,1.82,45.07]],"ltp":2.08,"tv":2745.63,"id":2120}]}]}
{"op":"mcm","clk":"11758061140","pt":1722456083711,"mc":[{"id":"1.231242812","rc":[{"trd":[[1.9,286.94],[1.91,393.49],[1.97,130.98],[1.99,199.24],[2,1054.28],[2.02,332.46],[2.04,214.2],[2.08,40.04],[2.1,1209.93],[2.12,51.38],[2.16,6.74],[2.18,64.93]],"batl":[[0,1.91,44.45]],"ltp":1.91,"tv":5234.54,"id":424676},{"trd":[[1.84,38.82],[1.86,46.63],[1.98,561.88],[2.02,430.79],[2.04,95.39],[2.06,93.99],[2.08,383.56],[2.1,259.6],[2.12,83.87],[2.14,61.03]],"batb":[[0,1.91,10],[1,1.9,163.18],[2,1.85,231.17]],"batl":[[1,2.12,26.27]],"ltp":2.08,"tv":2745.39,"id":2120}],"tv":7979.94}]}
{"op":"mcm","clk":"11758061518","pt":1722456087131,"mc":[{"id":"1.231242812","rc":[{"batb":[[0,1.9,163.18],[1,1.85,231.17],[2,1.82,45.07]],"ltp":2.08,"tv":2745.39,"id":2120}]}]}
{"op":"mcm","clk":"11758117225","pt":1722456673879,"mc":[{"id":"1.231242812","rc":[{"batb":[[0,1.91,10],[1,1.9,163.18],[2,1.85,231.17]],"ltp":2.08,"tv":2745.39,"id":2120}]}]}
{"op":"mcm","clk":"11758117520","pt":1722456677366,"mc":[{"id":"1.231242812","rc":[{"batb":[[0,1.9,163.18],[1,1.85,231.17],[2,1.82,45.07]],"ltp":2.08,"tv":2745.39,"id":2120}]}]}
{"op":"mcm","clk":"11758119426","pt":1722456700005,"mc":[{"id":"1.231242812","rc":[{"batb":[[0,1.91,10],[1,1.9,163.18],[2,1.85,231.17]],"ltp":2.08,"tv":2745.39,"id":2120}]}]}
{"op":"mcm","clk":"11758119711","pt":1722456703324,"mc":[{"id":"1.231242812","rc":[{"batb":[[0,1.9,163.18],[1,1.85,231.17],[2,1.82,45.07]],"ltp":2.08,"tv":2745.39,"id":2120}]}]}
{"op":"mcm","clk":"11758121198","pt":1722456724296,"mc":[{"id":"1.231242812","rc":[{"batb":[[0,1.91,10],[1,1.9,163.18],[2,1.85,231.17]],"ltp":2.08,"tv":2745.39,"id":2120}]}]}
{"op":"mcm","clk":"11758121482","pt":1722456726635,"mc":[{"id":"1.231242812","rc":[{"batb":[[0,1.9,163.18],[1,1.85,231.17],[2,1.82,45.07]],"ltp":2.08,"tv":2745.39,"id":2120}]}]}
{"op":"mcm","clk":"11758122000","pt":1722456734349,"mc":[{"id":"1.231242812","rc":[{"batb":[[0,1.91,10],[1,1.9,163.18],[2,1.85,231.17]],"ltp":2.08,"tv":2745.39,"id":2120}]}]}
{"op":"mcm","clk":"11758122316","pt":1722456737998,"mc":[{"id":"1.231242812","rc":[{"batb":[[0,1.9,163.18],[1,1.85,231.17],[2,1.82,45.07]],"ltp":2.08,"tv":2745.39,"id":2120}]}]}
{"op":"mcm","clk":"11758145794","pt":1722457021879,"mc":[{"id":"1.231242812","rc":[{"batb":[[0,1.91,10],[1,1.9,163.18],[2,1.85,231.17]],"ltp":2.08,"tv":2745.39,"id":2120}]}]}
{"op":"mcm","clk":"11758146105","pt":1722457025506,"mc":[{"id":"1.231242812","rc":[{"batb":[[0,1.9,163.18],[1,1.85,231.17],[2,1.82,45.07]],"ltp":2.08,"tv":2745.39,"id":2120}]}]}
{"op":"mcm","clk":"11758148610","pt":1722457054012,"mc":[{"id":"1.231242812","rc":[{"batb":[[0,1.91,10],[1,1.9,163.18],[2,1.85,231.17]],"ltp":2.08,"tv":2745.39,"id":2120}]}]}
{"op":"mcm","clk":"11758148907","pt":1722457057315,"mc":[{"id":"1.231242812","rc":[{"batb":[[0,1.9,163.18],[1,1.85,231.17],[2,1.82,45.07]],"ltp":2.08,"tv":2745.39,"id":2120}]}]}
{"op":"mcm","clk":"11758155867","pt":1722457131994,"mc":[{"id":"1.231242812","rc":[{"batb":[[0,1.91,10],[1,1.9,163.18],[2,1.85,231.17]],"ltp":2.08,"tv":2745.39,"id":2120}]}]}
{"op":"mcm","clk":"11758156193","pt":1722457135421,"mc":[{"id":"1.231242812","rc":[{"batb":[[0,1.9,163.18],[1,1.85,231.17],[2,1.82,45.07]],"ltp":2.08,"tv":2745.39,"id":2120}]}]}
{"op":"mcm","clk":"11758159806","pt":1722457172129,"mc":[{"id":"1.231242812","rc":[{"batb":[[0,1.91,10],[1,1.9,163.18],[2,1.85,231.17]],"ltp":2.08,"tv":2745.39,"id":2120}]}]}
{"op":"mcm","clk":"11758160117","pt":1722457175659,"mc":[{"id":"1.231242812","rc":[{"batb":[[0,1.9,163.18],[1,1.85,231.17],[2,1.82,45.07]],"ltp":2.08,"tv":2745.39,"id":2120}]}]}
{"op":"mcm","clk":"11758162094","pt":1722457195376,"mc":[{"id":"1.231242812","rc":[{"batb":[[0,1.91,10],[1,1.9,163.18],[2,1.85,231.17]],"ltp":2.08,"tv":2745.39,"id":2120}]}]}
{"op":"mcm","clk":"11758162426","pt":1722457198700,"mc":[{"id":"1.231242812","rc":[{"batb":[[0,1.9,163.18],[1,1.85,231.17],[2,1.82,45.07]],"ltp":2.08,"tv":2745.39,"id":2120}]}]}
{"op":"mcm","clk":"11758171939","pt":1722457298593,"mc":[{"id":"1.231242812","rc":[{"batb":[[0,1.91,10],[1,1.9,163.18],[2,1.85,231.17]],"ltp":2.08,"tv":2745.39,"id":2120}]}]}
{"op":"mcm","clk":"11758172300","pt":1722457301973,"mc":[{"id":"1.231242812","rc":[{"batb":[[0,1.9,163.18],[1,1.85,231.17],[2,1.82,45.07]],"ltp":2.08,"tv":2745.39,"id":2120}]}]}
{"op":"mcm","clk":"11758173305","pt":1722457311584,"mc":[{"id":"1.231242812","rc":[{"batb":[[0,1.91,10],[1,1.9,163.18],[2,1.85,231.17]],"ltp":2.08,"tv":2745.39,"id":2120}]}]}
{"op":"mcm","clk":"11758173656","pt":1722457314901,"mc":[{"id":"1.231242812","rc":[{"batb":[[0,1.9,163.18],[1,1.85,231.17],[2,1.82,45.07]],"ltp":2.08,"tv":2745.39,"id":2120}]}]}
{"op":"mcm","clk":"11758175661","pt":1722457336238,"mc":[{"id":"1.231242812","rc":[{"trd":[[1.91,416.15]],"batl":[[0,1.91,33.12]],"ltp":1.91,"tv":5257.2,"id":424676},{"batb":[[0,1.91,10],[1,1.9,163.18],[2,1.85,231.17]],"ltp":2.08,"tv":2745.39,"id":2120}],"tv":8002.6}]}
{"op":"mcm","clk":"11758175950","pt":1722457339662,"mc":[{"id":"1.231242812","rc":[{"batb":[[0,1.9,163.18],[1,1.85,231.17],[2,1.82,45.07]],"ltp":2.08,"tv":2745.39,"id":2120}]}]}
{"op":"mcm","clk":"11758204294","pt":1722457663320,"mc":[{"id":"1.231242812","rc":[{"batb":[[0,1.91,10],[1,1.9,163.18],[2,1.85,231.17]],"ltp":2.08,"tv":2745.39,"id":2120}]}]}
{"op":"mcm","clk":"11758204603","pt":1722457666890,"mc":[{"id":"1.231242812","rc":[{"batb":[[0,1.9,163.18],[1,1.85,231.17],[2,1.82,45.07]],"ltp":2.08,"tv":2745.39,"id":2120}]}]}
{"op":"mcm","clk":"11758218161","pt":1722457838388,"mc":[{"id":"1.231242812","rc":[{"batb":[[0,1.91,10],[1,1.9,163.18],[2,1.85,231.17]],"ltp":2.08,"tv":2745.39,"id":2120}]}]}
{"op":"mcm","clk":"11758218410","pt":1722457841795,"mc":[{"id":"1.231242812","rc":[{"batb":[[0,1.9,163.18],[1,1.85,231.17],[2,1.82,45.07]],"ltp":2.08,"tv":2745.39,"id":2120}]}]}
{"op":"mcm","clk":"11758220302","pt":1722457864923,"mc":[{"id":"1.231242812","rc":[{"batb":[[0,1.91,10],[1,1.9,163.18],[2,1.85,231.17]],"ltp":2.08,"tv":2745.39,"id":2120}]}]}
{"op":"mcm","clk":"11758220624","pt":1722457868954,"mc":[{"id":"1.231242812","rc":[{"trd":[[1.91,420.85]],"batl":[[0,1.91,30.77]],"ltp":1.91,"tv":5261.9,"id":424676},{"batb":[[0,1.9,163.18],[1,1.85,231.17],[2,1.82,45.07]],"ltp":2.08,"tv":2745.39,"id":2120}],"tv":8007.3}]}
{"op":"mcm","clk":"11758224280","pt":1722457915707,"mc":[{"id":"1.231242812","rc":[{"trd":[[1.91,482.39]],"batb":[[0,1.92,420.04],[1,1.71,16.34],[2,1.43,116.28]],"batl":[[0,1.98,24.77],[1,1.99,283.68],[2,2,103.43]],"ltp":1.91,"tv":5323.44,"id":424676},{"batb":[[0,1.91,10],[1,1.9,163.18],[2,1.85,231.17]],"ltp":2.08,"tv":2745.39,"id":2120}],"tv":8068.84}]}
{"op":"mcm","clk":"11758224547","pt":1722457919109,"mc":[{"id":"1.231242812","rc":[{"batb":[[0,1.9,163.18],[1,1.85,231.17],[2,1.82,45.07]],"ltp":2.08,"tv":2745.39,"id":2120}]}]}
{"op":"mcm","clk":"11758226590","pt":1722457946528,"mc":[{"id":"1.231242812","rc":[{"batb":[[0,1.93,16.83],[1,1.92,420.04],[2,1.71,16.34]],"ltp":1.91,"tv":5323.44,"id":424676},{"batb":[[0,1.91,10],[1,1.9,163.18],[2,1.85,231.17]],"batl":[[0,2.08,16.84],[1,2.1,1.25],[2,2.12,26.27]],"ltp":2.08,"tv":2745.39,"id":2120}]}]}
{"op":"mcm","clk":"11758226863","pt":1722457950036,"mc":[{"id":"1.231242812","rc":[{"batb":[[0,1.9,163.18],[1,1.85,231.17],[2,1.82,45.07]],"ltp":2.08,"tv":2745.39,"id":2120}]}]}
{"op":"mcm","clk":"11758229866","pt":1722457992003,"mc":[{"id":"1.231242812","rc":[{"batb":[[0,1.91,10],[1,1.9,163.18],[2,1.85,231.17]],"ltp":2.08,"tv":2745.39,"id":2120}]}]}
{"op":"mcm","clk":"11758230110","pt":1722457995575,"mc":[{"id":"1.231242812","rc":[{"batb":[[0,1.9,163.18],[1,1.85,231.17],[2,1.82,45.07]],"ltp":2.08,"tv":2745.39,"id":2120}]}]}
{"op":"mcm","clk":"11758234633","pt":1722458052655,"mc":[{"id":"1.231242812","rc":[{"batb":[[0,1.91,10],[1,1.9,163.18],[2,1.85,231.17]],"ltp":2.08,"tv":2745.39,"id":2120}]}]}
{"op":"mcm","clk":"11758235109","pt":1722458058256,"mc":[{"id":"1.231242812","rc":[{"batb":[[0,1.9,163.18],[1,1.85,231.17],[2,1.82,45.07]],"ltp":2.08,"tv":2745.39,"id":2120}]}]}
{"op":"mcm","clk":"11758239016","pt":1722458106512,"mc":[{"id":"1.231242812","rc":[{"batb":[[1,1.71,16.34],[2,1.43,116.28]],"ltp":1.91,"tv":5323.44,"id":424676},{"batb":[[0,1.91,10],[1,1.9,163.18],[2,1.85,231.17]],"ltp":2.08,"tv":2745.39,"id":2120}]}]}
{"op":"mcm","clk":"11758239098","pt":1722458107508,"mc":[{"id":"1.231242812","rc":[{"batb":[[0,1.71,16.34],[1,1.43,116.28],[2,1.38,131.58]],"ltp":1.91,"tv":5323.44,"id":424676},{"batl":[[0,2.1,1.25],[1,2.12,26.27],[2,2.12,0]],"ltp":2.08,"tv":2745.39,"id":2120}]}]}
{"op":"mcm","clk":"11758239289","pt":1722458109818,"mc":[{"id":"1.231242812","rc":[{"batb":[[0,1.9,163.18],[1,1.85,231.17],[2,1.82,45.07]],"ltp":2.08,"tv":2745.39,"id":2120}]}]}
{"op":"mcm","clk":"11758244254","pt":1722458175581,"mc":[{"id":"1.231242812","rc":[{"batb":[[0,1.91,10],[1,1.9,163.18],[2,1.85,231.17]],"ltp":2.08,"tv":2745.39,"id":2120}]}]}
{"op":"mcm","clk":"11758244528","pt":1722458179102,"mc":[{"id":"1.231242812","rc":[{"batb":[[0,1.9,163.18],[1,1.85,231.17],[2,1.82,45.07]],"ltp":2.08,"tv":2745.39,"id":2120}]}]}
{"op":"mcm","clk":"11758247785","pt":1722458221762,"mc":[{"id":"1.231242812","rc":[{"batb":[[0,1.91,10],[1,1.9,163.18],[2,1.85,231.17]],"ltp":2.08,"tv":2745.39,"id":2120}]}]}
{"op":"mcm","clk":"11758248146","pt":1722458225562,"mc":[{"id":"1.231242812","rc":[{"batb":[[0,1.9,163.18],[1,1.85,231.17],[2,1.82,45.07]],"ltp":2.08,"tv":2745.39,"id":2120}]}]}
{"op":"mcm","clk":"11758249244","pt":1722458239976,"mc":[{"id":"1.231242812","rc":[{"batb":[[0,1.91,10],[1,1.9,163.18],[2,1.85,231.17]],"ltp":2.08,"tv":2745.39,"id":2120}]}]}
{"op":"mcm","clk":"11758249500","pt":1722458243593,"mc":[{"id":"1.231242812","rc":[{"batb":[[0,1.9,163.18],[1,1.85,231.17],[2,1.82,45.07]],"ltp":2.08,"tv":2745.39,"id":2120}]}]}
{"op":"mcm","clk":"11758252305","pt":1722458281387,"mc":[{"id":"1.231242812","rc":[{"batb":[[0,1.91,10],[1,1.9,163.18],[2,1.85,231.17]],"ltp":2.08,"tv":2745.39,"id":2120}]}]}
{"op":"mcm","clk":"11758252580","pt":1722458284889,"mc":[{"id":"1.231242812","rc":[{"batb":[[0,1.9,163.18],[1,1.85,231.17],[2,1.82,45.07]],"ltp":2.08,"tv":2745.39,"id":2120}]}]}
{"op":"mcm","clk":"11758254221","pt":1722458308110,"mc":[{"id":"1.231242812","rc":[{"batb":[[0,1.91,10],[1,1.9,163.18],[2,1.85,231.17]],"ltp":2.08,"tv":2745.39,"id":2120}]}]}
{"op":"mcm","clk":"11758254523","pt":1722458311824,"mc":[{"id":"1.231242812","rc":[{"batb":[[0,1.9,163.18],[1,1.85,231.17],[2,1.82,45.07]],"ltp":2.08,"tv":2745.39,"id":2120}]}]}
{"op":"mcm","clk":"11758255438","pt":1722458326366,"mc":[{"id":"1.231242812","rc":[{"batb":[[0,1.91,10],[1,1.9,163.18],[2,1.85,231.17]],"ltp":2.08,"tv":2745.39,"id":2120}]}]}
{"op":"mcm","clk":"11758255665","pt":1722458329971,"mc":[{"id":"1.231242812","rc":[{"batb":[[0,1.9,163.18],[1,1.85,231.17],[2,1.82,45.07]],"ltp":2.08,"tv":2745.39,"id":2120}]}]}
{"op":"mcm","clk":"11758255843","pt":1722458332954,"mc":[{"id":"1.231242812","rc":[{"batb":[[0,1.91,10],[1,1.9,163.18],[2,1.85,231.17]],"ltp":2.08,"tv":2745.39,"id":2120}]}]}
{"op":"mcm","clk":"11758256034","pt":1722458336250,"mc":[{"id":"1.231242812","rc":[{"batb":[[0,1.9,163.18],[1,1.85,231.17],[2,1.82,45.07]],"ltp":2.08,"tv":2745.39,"id":2120}]}]}
{"op":"mcm","clk":"11758256471","pt":1722458343954,"mc":[{"id":"1.231242812","rc":[{"batb":[[0,1.91,10],[1,1.9,163.18],[2,1.85,231.17]],"ltp":2.08,"tv":2745.39,"id":2120}]}]}
{"op":"mcm","clk":"11758256688","pt":1722458347360,"mc":[{"id":"1.231242812","rc":[{"batb":[[0,1.9,163.18],[1,1.85,231.17],[2,1.82,45.07]],"ltp":2.08,"tv":2745.39,"id":2120}]}]}
{"op":"mcm","clk":"11758258255","pt":1722458372794,"mc":[{"id":"1.231242812","rc":[{"batb":[[0,1.91,10],[1,1.9,163.18],[2,1.85,231.17]],"ltp":2.08,"tv":2745.39,"id":2120}]}]}
{"op":"mcm","clk":"11758258447","pt":1722458376096,"mc":[{"id":"1.231242812","rc":[{"batb":[[0,1.9,163.18],[1,1.85,231.17],[2,1.82,45.07]],"ltp":2.08,"tv":2745.39,"id":2120}]}]}
{"op":"mcm","clk":"11758260068","pt":1722458402627,"mc":[{"id":"1.231242812","rc":[{"batb":[[0,1.91,10],[1,1.9,163.18],[2,1.85,231.17]],"ltp":2.08,"tv":2745.39,"id":2120}]}]}
{"op":"mcm","clk":"11758260297","pt":1722458406134,"mc":[{"id":"1.231242812","rc":[{"batb":[[0,1.9,163.18],[1,1.85,231.17],[2,1.82,45.07]],"ltp":2.08,"tv":2745.39,"id":2120}]}]}
{"op":"mcm","clk":"11758260549","pt":1722458410051,"mc":[{"id":"1.231242812","rc":[{"batb":[[0,1.91,10],[1,1.9,163.18],[2,1.85,231.17]],"ltp":2.08,"tv":2745.39,"id":2120}]}]}
{"op":"mcm","clk":"11758260805","pt":1722458413456,"mc":[{"id":"1.231242812","rc":[{"batb":[[0,1.9,163.18],[1,1.85,231.17],[2,1.82,45.07]],"ltp":2.08,"tv":2745.39,"id":2120}]}]}
{"op":"mcm","clk":"11758261879","pt":1722458428741,"mc":[{"id":"1.231242812","rc":[{"batb":[[0,1.91,10],[1,1.9,163.18],[2,1.85,231.17]],"ltp":2.08,"tv":2745.39,"id":2120}]}]}
{"op":"mcm","clk":"11758262090","pt":1722458432246,"mc":[{"id":"1.231242812","rc":[{"batb":[[0,1.9,163.18],[1,1.85,231.17],[2,1.82,45.07]],"ltp":2.08,"tv":2745.39,"id":2120}]}]}
{"op":"mcm","clk":"11758262253","pt":1722458434876,"mc":[{"id":"1.231242812","rc":[{"batb":[[0,1.91,10],[1,1.9,163.18],[2,1.85,231.17]],"ltp":2.08,"tv":2745.39,"id":2120}]}]}
{"op":"mcm","clk":"11758262489","pt":1722458438255,"mc":[{"id":"1.231242812","rc":[{"batb":[[0,1.9,163.18],[1,1.85,231.17],[2,1.82,45.07]],"ltp":2.08,"tv":2745.39,"id":2120}]}]}
{"op":"mcm","clk":"11758263065","pt":1722458446455,"mc":[{"id":"1.231242812","rc":[{"batb":[[0,1.91,10],[1,1.9,163.18],[2,1.85,231.17]],"ltp":2.08,"tv":2745.39,"id":2120}]}]}
{"op":"mcm","clk":"11758263295","pt":1722458450066,"mc":[{"id":"1.231242812","rc":[{"batb":[[0,1.9,163.18],[1,1.85,231.17],[2,1.82,45.07]],"ltp":2.08,"tv":2745.39,"id":2120}]}]}
{"op":"mcm","clk":"11758264996","pt":1722458476292,"mc":[{"id":"1.231242812","rc":[{"batb":[[0,1.91,10],[1,1.9,163.18],[2,1.85,231.17]],"ltp":2.08,"tv":2745.39,"id":2120}]}]}
{"op":"mcm","clk":"11758265228","pt":1722458479597,"mc":[{"id":"1.231242812","rc":[{"batb":[[0,1.9,163.18],[1,1.85,231.17],[2,1.82,45.07]],"ltp":2.08,"tv":2745.39,"id":2120}]}]}
{"op":"mcm","clk":"11758265651","pt":1722458486106,"mc":[{"id":"1.231242812","rc":[{"batb":[[0,1.91,10],[1,1.9,163.18],[2,1.85,231.17]],"ltp":2.08,"tv":2745.39,"id":2120}]}]}
{"op":"mcm","clk":"11758265842","pt":1722458489612,"mc":[{"id":"1.231242812","rc":[{"batb":[[0,1.9,163.18],[1,1.85,231.17],[2,1.82,45.07]],"ltp":2.08,"tv":2745.39,"id":2120}]}]}
{"op":"mcm","clk":"11758266281","pt":1722458496492,"mc":[{"id":"1.231242812","rc":[{"batb":[[0,1.91,10],[1,1.9,163.18],[2,1.85,231.17]],"ltp":2.08,"tv":2745.39,"id":2120}]}]}
{"op":"mcm","clk":"11758266478","pt":1722458499798,"mc":[{"id":"1.231242812","rc":[{"batb":[[0,1.9,163.18],[1,1.85,231.17],[2,1.82,45.07]],"ltp":2.08,"tv":2745.39,"id":2120}]}]}
{"op":"mcm","clk":"11758296041","pt":1722458967858,"mc":[{"id":"1.231242812","rc":[{"batb":[[0,1.91,10],[1,1.9,163.18],[2,1.85,231.17]],"ltp":2.08,"tv":2745.39,"id":2120}]}]}
{"op":"mcm","clk":"11758296285","pt":1722458971200,"mc":[{"id":"1.231242812","rc":[{"batb":[[0,1.9,163.18],[1,1.85,231.17],[2,1.82,45.07]],"ltp":2.08,"tv":2745.39,"id":2120}]}]}
{"op":"mcm","clk":"11758302523","pt":1722459071350,"mc":[{"id":"1.231242812","rc":[{"batb":[[0,1.91,10],[1,1.9,163.18],[2,1.85,231.17]],"ltp":2.08,"tv":2745.39,"id":2120}]}]}
{"op":"mcm","clk":"11758302741","pt":1722459074895,"mc":[{"id":"1.231242812","rc":[{"batb":[[0,1.9,163.18],[1,1.85,231.17],[2,1.82,45.07]],"ltp":2.08,"tv":2745.39,"id":2120}]}]}
{"op":"mcm","clk":"11758303805","pt":1722459094705,"mc":[{"id":"1.231242812","rc":[{"batb":[[0,1.91,10],[1,1.9,163.18],[2,1.85,231.17]],"ltp":2.08,"tv":2745.39,"id":2120}]}]}
{"op":"mcm","clk":"11758303975","pt":1722459098106,"mc":[{"id":"1.231242812","rc":[{"batb":[[0,1.9,163.18],[1,1.85,231.17],[2,1.82,45.07]],"ltp":2.08,"tv":2745.39,"id":2120}]}]}
{"op":"mcm","clk":"11758304158","pt":1722459101586,"mc":[{"id":"1.231242812","rc":[{"batb":[[0,1.91,10],[1,1.9,163.18],[2,1.85,231.17]],"ltp":2.08,"tv":2745.39,"id":2120}]}]}
{"op":"mcm","clk":"11758304357","pt":1722459104873,"mc":[{"id":"1.231242812","rc":[{"batb":[[0,1.9,163.18],[1,1.85,231.17],[2,1.82,45.07]],"ltp":2.08,"tv":2745.39,"id":2120}]}]}
{"op":"mcm","clk":"11758304529","pt":1722459107907,"mc":[{"id":"1.231242812","rc":[{"batb":[[0,1.91,10],[1,1.9,163.18],[2,1.85,231.17]],"ltp":2.08,"tv":2745.39,"id":2120}]}]}
{"op":"mcm","clk":"11758304755","pt":1722459111299,"mc":[{"id":"1.231242812","rc":[{"batb":[[0,1.9,163.18],[1,1.85,231.17],[2,1.82,45.07]],"ltp":2.08,"tv":2745.39,"id":2120}]}]}
{"op":"mcm","clk":"11758305171","pt":1722459118432,"mc":[{"id":"1.231242812","rc":[{"batb":[[0,1.91,10],[1,1.9,163.18],[2,1.85,231.17]],"ltp":2.08,"tv":2745.39,"id":2120}]}]}
{"op":"mcm","clk":"11758305326","pt":1722459121820,"mc":[{"id":"1.231242812","rc":[{"batb":[[0,1.9,163.18],[1,1.85,231.17],[2,1.82,45.07]],"ltp":2.08,"tv":2745.39,"id":2120}]}]}
{"op":"mcm","clk":"11758305476","pt":1722459124231,"mc":[{"id":"1.231242812","rc":[{"batb":[[0,1.91,10],[1,1.9,163.18],[2,1.85,231.17]],"ltp":2.08,"tv":2745.39,"id":2120}]}]}
{"op":"mcm","clk":"11758305657","pt":1722459127617,"mc":[{"id":"1.231242812","rc":[{"batb":[[0,1.9,163.18],[1,1.85,231.17],[2,1.82,45.07]],"ltp":2.08,"tv":2745.39,"id":2120}]}]}
{"op":"mcm","clk":"11758305881","pt":1722459131529,"mc":[{"id":"1.231242812","rc":[{"batb":[[0,1.91,10],[1,1.9,163.18],[2,1.85,231.17]],"ltp":2.08,"tv":2745.39,"id":2120}]}]}
{"op":"mcm","clk":"11758306161","pt":1722459136049,"mc":[{"id":"1.231242812","rc":[{"batb":[[0,1.9,163.18],[1,1.85,231.17],[2,1.82,45.07]],"ltp":2.08,"tv":2745.39,"id":2120}]}]}
{"op":"mcm","clk":"11758306458","pt":1722459141336,"mc":[{"id":"1.231242812","rc":[{"batb":[[0,1.91,10],[1,1.9,163.18],[2,1.85,231.17]],"ltp":2.08,"tv":2745.39,"id":2120}]}]}
{"op":"mcm","clk":"11758306673","pt":1722459144933,"mc":[{"id":"1.231242812","rc":[{"batb":[[0,1.9,163.18],[1,1.85,231.17],[2,1.82,45.07]],"ltp":2.08,"tv":2745.39,"id":2120}]}]}
{"op":"mcm","clk":"11758308677","pt":1722459178177,"mc":[{"id":"1.231242812","rc":[{"batb":[[0,1.91,10],[1,1.9,163.18],[2,1.85,231.17]],"ltp":2.08,"tv":2745.39,"id":2120}]}]}
{"op":"mcm","clk":"11758308873","pt":1722459181817,"mc":[{"id":"1.231242812","rc":[{"batb":[[0,1.9,163.18],[1,1.85,231.17],[2,1.82,45.07]],"ltp":2.08,"tv":2745.39,"id":2120}]}]}
{"op":"mcm","clk":"11758309380","pt":1722459190084,"mc":[{"id":"1.231242812","rc":[{"batb":[[0,1.91,10],[1,1.9,163.18],[2,1.85,231.17]],"ltp":2.08,"tv":2745.39,"id":2120}]}]}
{"op":"mcm","clk":"11758309587","pt":1722459193689,"mc":[{"id":"1.231242812","rc":[{"batb":[[0,1.9,163.18],[1,1.85,231.17],[2,1.82,45.07]],"ltp":2.08,"tv":2745.39,"id":2120}]}]}
{"op":"mcm","clk":"11758309805","pt":1722459196817,"mc":[{"id":"1.231242812","rc":[{"batb":[[0,1.91,10],[1,1.9,163.18],[2,1.85,231.17]],"ltp":2.08,"tv":2745.39,"id":2120}]}]}
{"op":"mcm","clk":"11758310020","pt":1722459200434,"mc":[{"id":"1.231242812","rc":[{"batb":[[0,1.9,163.18],[1,1.85,231.17],[2,1.82,45.07]],"ltp":2.08,"tv":2745.39,"id":2120}]}]}
{"op":"mcm","clk":"11758310865","pt":1722459214235,"mc":[{"id":"1.231242812","rc":[{"batb":[[0,1.91,10],[1,1.9,163.18],[2,1.85,231.17]],"ltp":2.08,"tv":2745.39,"id":2120}]}]}
{"op":"mcm","clk":"11758311075","pt":1722459217823,"mc":[{"id":"1.231242812","rc":[{"batb":[[0,1.9,163.18],[1,1.85,231.17],[2,1.82,45.07]],"ltp":2.08,"tv":2745.39,"id":2120}]}]}
{"op":"mcm","clk":"11758311306","pt":1722459221522,"mc":[{"id":"1.231242812","rc":[{"batb":[[0,1.91,10],[1,1.9,163.18],[2,1.85,231.17]],"ltp":2.08,"tv":2745.39,"id":2120}]}]}
{"op":"mcm","clk":"11758311512","pt":1722459225115,"mc":[{"id":"1.231242812","rc":[{"batb":[[0,1.9,163.18],[1,1.85,231.17],[2,1.82,45.07]],"ltp":2.08,"tv":2745.39,"id":2120}]}]}
{"op":"mcm","clk":"11758312227","pt":1722459236448,"mc":[{"id":"1.231242812","rc":[{"batb":[[0,1.91,10],[1,1.9,163.18],[2,1.85,231.17]],"ltp":2.08,"tv":2745.39,"id":2120}]}]}
{"op":"mcm","clk":"11758312445","pt":1722459239839,"mc":[{"id":"1.231242812","rc":[{"batb":[[0,1.9,163.18],[1,1.85,231.17],[2,1.82,45.07]],"ltp":2.08,"tv":2745.39,"id":2120}]}]}
{"op":"mcm","clk":"11758314430","pt":1722459270385,"mc":[{"id":"1.231242812","rc":[{"batb":[[0,1.91,10],[1,1.9,163.18],[2,1.85,231.17]],"ltp":2.08,"tv":2745.39,"id":2120}]}]}
{"op":"mcm","clk":"11758314592","pt":1722459273664,"mc":[{"id":"1.231242812","rc":[{"batb":[[0,1.9,163.18],[1,1.85,231.17],[2,1.82,45.07]],"ltp":2.08,"tv":2745.39,"id":2120}]}]}
{"op":"mcm","clk":"11758315217","pt":1722459283807,"mc":[{"id":"1.231242812","rc":[{"batb":[[0,1.91,10],[1,1.9,163.18],[2,1.85,231.17]],"ltp":2.08,"tv":2745.39,"id":2120}]}]}
{"op":"mcm","clk":"11758315441","pt":1722459287469,"mc":[{"id":"1.231242812","rc":[{"batb":[[0,1.9,163.18],[1,1.85,231.17],[2,1.82,45.07]],"ltp":2.08,"tv":2745.39,"id":2120}]}]}
{"op":"mcm","clk":"11758316118","pt":1722459299477,"mc":[{"id":"1.231242812","rc":[{"batb":[[0,1.91,10],[1,1.9,163.18],[2,1.85,231.17]],"ltp":2.08,"tv":2745.39,"id":2120}]}]}
{"op":"mcm","clk":"11758316311","pt":1722459303123,"mc":[{"id":"1.231242812","rc":[{"batb":[[0,1.9,163.18],[1,1.85,231.17],[2,1.82,45.07]],"ltp":2.08,"tv":2745.39,"id":2120}]}]}
{"op":"mcm","clk":"11758317189","pt":1722459318845,"mc":[{"id":"1.231242812","rc":[{"batb":[[0,1.91,10],[1,1.9,163.18],[2,1.85,231.17]],"ltp":2.08,"tv":2745.39,"id":2120}]}]}
{"op":"mcm","clk":"11758317374","pt":1722459322219,"mc":[{"id":"1.231242812","rc":[{"batb":[[0,1.9,163.18],[1,1.85,231.17],[2,1.82,45.07]],"ltp":2.08,"tv":2745.39,"id":2120}]}]}
{"op":"mcm","clk":"11758317625","pt":1722459326934,"mc":[{"id":"1.231242812","rc":[{"batb":[[0,1.91,10],[1,1.9,163.18],[2,1.85,231.17]],"ltp":2.08,"tv":2745.39,"id":2120}]}]}
{"op":"mcm","clk":"11758317895","pt":1722459331715,"mc":[{"id":"1.231242812","rc":[{"batb":[[0,1.9,163.18],[1,1.85,231.17],[2,1.82,45.07]],"ltp":2.08,"tv":2745.39,"id":2120}]}]}
{"op":"mcm","clk":"11758320123","pt":1722459372283,"mc":[{"id":"1.231242812","rc":[{"trd":[[1.9,288.32]],"batl":[[0,1.9,198.62],[1,1.98,24.77],[2,1.99,283.68]],"ltp":1.9,"tv":5324.82,"id":424676},{"trd":[[2.1,260.85]],"batl":[[0,2.12,26.27],[1,2.12,0]],"ltp":2.1,"tv":2746.64,"id":2120}],"tv":8071.47}]}
{"op":"mcm","clk":"11758320129","pt":1722459372386,"mc":[{"id":"1.231242812","rc":[{"batb":[[0,1.91,10],[1,1.9,163.18],[2,1.85,231.17]],"ltp":2.1,"tv":2746.64,"id":2120}]}]}
{"op":"mcm","clk":"11758320323","pt":1722459375684,"mc":[{"id":"1.231242812","rc":[{"trd":[[1.89,135.18]],"batl":[[0,1.89,270.54],[1,1.9,198.62],[2,1.98,24.77]],"ltp":1.89,"tv":5354.28,"id":424676},{"trd":[[2.12,110.14]],"batb":[[0,1.9,163.18],[1,1.85,231.17],[2,1.82,45.07]],"ltp":2.12,"tv":2772.91,"id":2120}],"tv":8127.19}]}
{"op":"mcm","clk":"11758321694","pt":1722459406388,"mc":[{"id":"1.231242812","rc":[{"batl":[[0,1.83,200],[1,1.88,16.83],[2,1.89,270.54]],"ltp":1.89,"tv":5354.28,"id":424676},{"batb":[[0,2.14,15.04],[1,1.9,163.18],[2,1.85,231.17]],"ltp":2.12,"tv":2772.91,"id":2120}]}]}
{"op":"mcm","clk":"11758321753","pt":1722459407620,"mc":[{"id":"1.231242812","rc":[{"batl":[[1,1.89,270.54],[2,1.9,198.62]],"ltp":1.89,"tv":5354.28,"id":424676},{"batb":[[0,1.9,163.18],[1,1.85,231.17],[2,1.82,45.07]],"ltp":2.12,"tv":2772.91,"id":2120}]}]}
{"op":"mcm","clk":"11758322074","pt":1722459412810,"mc":[{"id":"1.231242812","rc":[{"batl":[[1,1.86,350],[2,1.89,270.54]],"ltp":1.89,"tv":5354.28,"id":424676}]}]}
{"op":"mcm","clk":"11758322424","pt":1722459420031,"mc":[{"id":"1.231242812","rc":[{"batl":[[0,1.8,300],[1,1.83,200],[2,1.86,350]],"ltp":1.89,"tv":5354.28,"id":424676}]}]}
{"op":"mcm","clk":"11758323902","pt":1722459450938,"mc":[{"id":"1.231242812","rc":[{"batl":[[0,1.79,16.83],[1,1.8,300],[2,1.83,200]],"ltp":1.89,"tv":5354.28,"id":424676},{"batb":[[0,2.26,13.58],[1,1.9,163.18],[2,1.85,231.17]],"ltp":2.12,"tv":2772.91,"id":2120}]}]}
{"op":"mcm","clk":"11758324380","pt":1722459460864,"mc":[{"id":"1.231242812","rc":[{"trd":[[1.79,41.66],[1.8,565.82]],"batl":[[0,1.8,17.09],[1,1.83,200],[2,1.86,350]],"ltp":1.8,"tv":5953.76,"id":424676}],"tv":8726.67}]}
{"op":"mcm","clk":"11758324437","pt":1722459461994,"mc":[{"id":"1.231242812","rc":[{"batb":[[0,1.9,163.18],[1,1.85,231.17],[2,1.82,45.07]],"ltp":2.12,"tv":2772.91,"id":2120}]}]}
{"op":"mcm","clk":"11758324861","pt":1722459471190,"mc":[{"id":"1.231242812","rc":[{"trd":[[1.8,599.5]],"batl":[[0,1.83,200.25],[1,1.86,350],[2,1.89,270.54]],"ltp":1.8,"tv":5987.44,"id":424676}],"tv":8760.35}]}
{"op":"mcm","clk":"11758326427","pt":1722459503091,"mc":[{"id":"1.231242812","rc":[{"batb":[[0,2.22,12.51],[1,1.9,163.18],[2,1.85,231.17]],"ltp":2.12,"tv":2772.91,"id":2120}]}]}
{"op":"mcm","clk":"11758326832","pt":1722459511191,"mc":[{"id":"1.231242812","rc":[{"trd":[[1.8,600],[1.82,15.26],[1.83,249.16]],"batl":[[0,1.83,156.51]],"ltp":1.83,"tv":6090.18,"id":424676},{"trd":[[2.22,12.52]],"batb":[[0,1.9,163.18],[1,1.85,231.17],[2,1.82,45.07]],"ltp":2.22,"tv":2785.42,"id":2120}],"tv":8875.6}]}
{"op":"mcm","clk":"11758329411","pt":1722459563949,"mc":[{"id":"1.231242812","rc":[{"batb":[[0,1.72,15.12],[1,1.71,16.34],[2,1.43,116.28]],"ltp":1.83,"tv":6090.18,"id":424676}]}]}
{"op":"mcm","clk":"11758329485","pt":1722459565484,"mc":[{"id":"1.231242812","rc":[{"batb":[[0,1.72,32.64]],"ltp":1.83,"tv":6090.18,"id":424676},{"batb":[[0,1.91,10],[1,1.9,163.18],[2,1.85,231.17]],"batl":[[0,2.4,11.57]],"ltp":2.22,"tv":2785.42,"id":2120}]}]}
{"op":"mcm","clk":"11758329621","pt":1722459569085,"mc":[{"id":"1.231242812","rc":[{"batb":[[0,1.9,163.18],[1,1.85,231.17],[2,1.82,45.07]],"ltp":2.22,"tv":2785.42,"id":2120}]}]}
{"op":"mcm","clk":"11758329682","pt":1722459570058,"mc":[{"id":"1.231242812","rc":[{"trd":[[1.83,315.16]],"batl":[[0,1.83,123.51]],"ltp":1.83,"tv":6156.18,"id":424676}],"tv":8941.6}]}
{"op":"mcm","clk":"11758330047","pt":1722459576583,"mc":[{"id":"1.231242812","rc":[{"batb":[[0,1.91,10],[1,1.9,163.18],[2,1.85,231.17]],"ltp":2.22,"tv":2785.42,"id":2120}]}]}
{"op":"mcm","clk":"11758330226","pt":1722459580067,"mc":[{"id":"1.231242812","rc":[{"batb":[[0,1.9,163.18],[1,1.85,231.17],[2,1.82,45.07]],"ltp":2.22,"tv":2785.42,"id":2120}]}]}
{"op":"mcm","clk":"11758330415","pt":1722459583399,"mc":[{"id":"1.231242812","rc":[{"batb":[[0,1.91,10],[1,1.9,163.18],[2,1.85,231.17]],"ltp":2.22,"tv":2785.42,"id":2120}]}]}
{"op":"mcm","clk":"11758330617","pt":1722459586889,"mc":[{"id":"1.231242812","rc":[{"batb":[[0,1.9,163.18],[1,1.85,231.17],[2,1.82,45.07]],"ltp":2.22,"tv":2785.42,"id":2120}]}]}
{"op":"mcm","clk":"11758330927","pt":1722459592284,"mc":[{"id":"1.231242812","rc":[{"batb":[[0,1.91,10],[1,1.9,163.18],[2,1.85,231.17]],"ltp":2.22,"tv":2785.42,"id":2120}]}]}
{"op":"mcm","clk":"11758331092","pt":1722459595820,"mc":[{"id":"1.231242812","rc":[{"batb":[[0,1.9,163.18],[1,1.85,231.17],[2,1.82,45.07]],"ltp":2.22,"tv":2785.42,"id":2120}]}]}
{"op":"mcm","clk":"11758331273","pt":1722459599621,"mc":[{"id":"1.231242812","rc":[{"batb":[[0,1.91,10],[1,1.9,163.18],[2,1.85,231.17]],"batl":[[0,2.22,104],[1,2.4,11.57]],"ltp":2.22,"tv":2785.42,"id":2120}]}]}
{"op":"mcm","clk":"11758331418","pt":1722459601903,"mc":[{"id":"1.231242812","rc":[{"batb":[[0,1.82,16.55],[1,1.72,15.12],[2,1.71,16.34]],"ltp":1.83,"tv":6156.18,"id":424676},{"batl":[[0,2.22,116.51],[1,2.4,0]],"ltp":2.22,"tv":2785.42,"id":2120}]}]}
{"op":"mcm","clk":"11758331504","pt":1722459603133,"mc":[{"id":"1.231242812","rc":[{"trd":[[1.79,41.67],[1.8,600.07],[1.9,288.32],[1.91,482.42],[1.97,130.98],[1.99,199.25],[2,1054.3],[2.02,332.47],[2.04,214.23],[2.08,40.04],[2.1,1210.07],[2.12,51.38],[2.16,6.74],[2.18,64.93]],"batb":[[0,1.82,16.56],[1,1.72,15.15]],"ltp":1.83,"tv":6156.52,"id":424676},{"trd":[[1.84,38.82],[1.86,46.63],[1.98,561.92],[2.02,430.82],[2.04,95.42],[2.06,94.01],[2.08,383.61],[2.1,260.88],[2.12,110.16],[2.14,61.04],[2.22,12.52]],"batb":[[0,1.9,163.18],[1,1.85,231.17],[2,1.82,45.07]],"batl":[[0,2.22,116.51]],"ltp":2.22,"tv":2785.66,"id":2120}],"tv":8942.18}]}
{"op":"mcm","clk":"11758332364","pt":1722459619140,"mc":[{"id":"1.231242812","rc":[{"batb":[[0,1.91,10],[1,1.9,163.18],[2,1.85,231.17]],"ltp":2.22,"tv":2785.66,"id":2120}]}]}
{"op":"mcm","clk":"11758332532","pt":1722459622635,"mc":[{"id":"1.231242812","rc":[{"batb":[[0,1.9,163.18],[1,1.85,231.17],[2,1.82,45.07]],"ltp":2.22,"tv":2785.66,"id":2120}]}]}
{"op":"mcm","clk":"11758332770","pt":1722459628029,"mc":[{"id":"1.231242812","rc":[{"batb":[[0,1.91,10],[1,1.9,163.18],[2,1.85,231.17]],"ltp":2.22,"tv":2785.66,"id":2120}]}]}
{"op":"mcm","clk":"11758332923","pt":1722459631527,"mc":[{"id":"1.231242812","rc":[{"batb":[[0,1.9,163.18],[1,1.85,231.17],[2,1.82,45.07]],"ltp":2.22,"tv":2785.66,"id":2120}]}]}
{"op":"mcm","clk":"11758333234","pt":1722459637939,"mc":[{"id":"1.231242812","rc":[{"batb":[[0,1.91,10],[1,1.9,163.18],[2,1.85,231.17]],"ltp":2.22,"tv":2785.66,"id":2120}]}]}
{"op":"mcm","clk":"11758333436","pt":1722459641440,"mc":[{"id":"1.231242812","rc":[{"batb":[[0,1.9,163.18],[1,1.85,231.17],[2,1.82,45.07]],"ltp":2.22,"tv":2785.66,"id":2120}]}]}
{"op":"mcm","clk":"11758333815","pt":1722459648925,"mc":[{"id":"1.231242812","rc":[{"batb":[[0,1.91,10],[1,1.9,163.18],[2,1.85,231.17]],"ltp":2.22,"tv":2785.66,"id":2120}]}]}
{"op":"mcm","clk":"11758333980","pt":1722459652530,"mc":[{"id":"1.231242812","rc":[{"batb":[[0,1.9,163.18],[1,1.85,231.17],[2,1.82,45.07]],"ltp":2.22,"tv":2785.66,"id":2120}]}]}
{"op":"mcm","clk":"11758335050","pt":1722459672865,"mc":[{"id":"1.231242812","rc":[{"trd":[[1.83,438.67]],"batl":[[0,1.86,350],[1,1.89,270.54],[2,1.9,198.62]],"ltp":1.83,"tv":6280.03,"id":424676},{"trd":[[2.2,137.53]],"batb":[[0,1.91,10],[1,1.9,163.18],[2,1.85,231.17]],"batl":[[0,2.2,1.26],[1,2.22,12.51]],"ltp":2.2,"tv":2888.4,"id":2120}],"tv":9168.43}]}
{"op":"mcm","clk":"11758335125","pt":1722459674564,"mc":[{"id":"1.231242812","rc":[{"batl":[[1,2.22,0]],"ltp":2.2,"tv":2888.4,"id":2120}]}]}
{"op":"mcm","clk":"11758335214","pt":1722459676165,"mc":[{"id":"1.231242812","rc":[{"batb":[[0,1.9,163.18],[1,1.85,231.17],[2,1.82,45.07]],"ltp":2.2,"tv":2888.4,"id":2120}]}]}
{"op":"mcm","clk":"11758335235","pt":1722459676559,"mc":[{"id":"1.231242812","rc":[{"batb":[[0,1.72,32.67],[1,1.71,16.34],[2,1.43,116.28]],"ltp":1.83,"tv":6280.03,"id":424676}]}]}
{"op":"mcm","clk":"11758335385","pt":1722459679076,"mc":[{"id":"1.231242812","rc":[{"batb":[[0,1.91,10],[1,1.9,163.18],[2,1.85,231.17]],"batl":[[1,2.38,11.67]],"ltp":2.2,"tv":2888.4,"id":2120}]}]}
{"op":"mcm","clk":"11758335551","pt":1722459682478,"mc":[{"id":"1.231242812","rc":[{"batb":[[0,1.9,163.18],[1,1.85,231.17],[2,1.82,45.07]],"ltp":2.2,"tv":2888.4,"id":2120}]}]}
{"op":"mcm","clk":"11758336365","pt":1722459698106,"mc":[{"id":"1.231242812","rc":[{"batb":[[0,1.72,17.53]],"ltp":1.83,"tv":6280.03,"id":424676},{"batb":[[0,1.91,10],[1,1.9,163.18],[2,1.85,231.17]],"ltp":2.2,"tv":2888.4,"id":2120}]}]}
{"op":"mcm","clk":"11758336467","pt":1722459699903,"mc":[{"id":"1.231242812","rc":[{"batl":[[1,2.4,11.57]],"ltp":2.2,"tv":2888.4,"id":2120}]}]}
{"op":"mcm","clk":"11758336541","pt":1722459701596,"mc":[{"id":"1.231242812","rc":[{"batb":[[0,1.9,163.18],[1,1.85,231.17],[2,1.82,45.07]],"ltp":2.2,"tv":2888.4,"id":2120}]}]}
{"op":"mcm","clk":"11758339107","pt":1722459751090,"mc":[{"id":"1.231242812","rc":[{"batb":[[0,1.91,10],[1,1.9,163.18],[2,1.85,231.17]],"batl":[[0,2.4,11.57],[1,2.4,0]],"ltp":2.2,"tv":2888.4,"id":2120}]}]}
{"op":"mcm","clk":"11758339300","pt":1722459754485,"mc":[{"id":"1.231242812","rc":[{"batb":[[0,1.9,163.18],[1,1.85,231.17],[2,1.82,45.07]],"ltp":2.2,"tv":2888.4,"id":2120}]}]}
{"op":"mcm","clk":"11758339650","pt":1722459761570,"mc":[{"id":"1.231242812","rc":[{"trd":[[1.86,100]],"batl":[[0,1.86,302]],"ltp":1.86,"tv":6376.03,"id":424676},{"batb":[[0,1.91,10],[1,1.9,163.18],[2,1.85,231.17]],"ltp":2.2,"tv":2888.4,"id":2120}],"tv":9264.43}]}
{"op":"mcm","clk":"11758339807","pt":1722459764963,"mc":[{"id":"1.231242812","rc":[{"batb":[[0,1.9,163.18],[1,1.85,231.17],[2,1.82,45.07]],"ltp":2.2,"tv":2888.4,"id":2120}]}]}
{"op":"mcm","clk":"11758340775","pt":1722459784620,"mc":[{"id":"1.231242812","rc":[{"batb":[[0,1.91,10],[1,1.9,163.18],[2,1.85,231.17]],"ltp":2.2,"tv":2888.4,"id":2120}]}]}
{"op":"mcm","clk":"11758340939","pt":1722459788008,"mc":[{"id":"1.231242812","rc":[{"batb":[[0,1.9,163.18],[1,1.85,231.17],[2,1.82,45.07]],"ltp":2.2,"tv":2888.4,"id":2120}]}]}
{"op":"mcm","clk":"11758341342","pt":1722459797090,"mc":[{"id":"1.231242812","rc":[{"batb":[[0,1.91,10],[1,1.9,163.18],[2,1.85,231.17]],"ltp":2.2,"tv":2888.4,"id":2120}]}]}
{"op":"mcm","clk":"11758341465","pt":1722459800629,"mc":[{"id":"1.231242812","rc":[{"batb":[[0,1.9,163.18],[1,1.85,231.17],[2,1.82,45.07]],"ltp":2.2,"tv":2888.4,"id":2120}]}]}
{"op":"mcm","clk":"11758341916","pt":1722459808945,"mc":[{"id":"1.231242812","rc":[{"batb":[[0,1.91,10],[1,1.9,163.18],[2,1.85,231.17]],"ltp":2.2,"tv":2888.4,"id":2120}]}]}
{"op":"mcm","clk":"11758342069","pt":1722459812432,"mc":[{"id":"1.231242812","rc":[{"batb":[[0,1.9,163.18],[1,1.85,231.17],[2,1.82,45.07]],"ltp":2.2,"tv":2888.4,"id":2120}]}]}
{"op":"mcm","clk":"11758342137","pt":1722459813717,"mc":[{"id":"1.231242812","rc":[{"trd":[[1.86,117.56]],"batl":[[0,1.86,293.22]],"ltp":1.86,"tv":6393.59,"id":424676}],"tv":9282.0}]}
{"op":"mcm","clk":"11758343048","pt":1722459834478,"mc":[{"id":"1.231242812","rc":[{"batb":[[0,1.91,10],[1,1.9,163.18],[2,1.85,231.17]],"ltp":2.2,"tv":2888.4,"id":2120}]}]}
{"op":"mcm","clk":"11758343195","pt":1722459837968,"mc":[{"id":"1.231242812","rc":[{"batb":[[0,1.9,163.18],[1,1.85,231.17],[2,1.82,45.07]],"ltp":2.2,"tv":2888.4,"id":2120}]}]}
{"op":"mcm","clk":"11758343590","pt":1722459844955,"mc":[{"id":"1.231242812","rc":[{"batb":[[0,1.91,10],[1,1.9,163.18],[2,1.85,231.17]],"ltp":2.2,"tv":2888.4,"id":2120}]}]}
{"op":"mcm","clk":"11758343763","pt":1722459848293,"mc":[{"id":"1.231242812","rc":[{"batb":[[0,1.9,163.18],[1,1.85,231.17],[2,1.82,45.07]],"ltp":2.2,"tv":2888.4,"id":2120}]}]}
{"op":"mcm","clk":"11758343988","pt":1722459854974,"mc":[{"id":"1.231242812","rc":[{"batb":[[0,1.91,10],[1,1.9,163.18],[2,1.85,231.17]],"ltp":2.2,"tv":2888.4,"id":2120}]}]}
{"op":"mcm","clk":"11758344113","pt":1722459858363,"mc":[{"id":"1.231242812","rc":[{"batb":[[0,1.9,163.18],[1,1.85,231.17],[2,1.82,45.07]],"ltp":2.2,"tv":2888.4,"id":2120}]}]}
{"op":"mcm","clk":"11758344360","pt":1722459863564,"mc":[{"id":"1.231242812","rc":[{"batl":[[0,1.85,14.4],[1,1.86,293.22],[2,1.89,270.54]],"ltp":1.86,"tv":6393.59,"id":424676},{"batb":[[0,1.91,10],[1,1.9,163.18],[2,1.85,231.17]],"ltp":2.2,"tv":2888.4,"id":2120}]}]}
{"op":"mcm","clk":"11758344498","pt":1722459866901,"mc":[{"id":"1.231242812","rc":[{"batb":[[0,1.9,163.18],[1,1.85,231.17],[2,1.82,45.07]],"ltp":2.2,"tv":2888.4,"id":2120}]}]}
{"op":"mcm","clk":"11758345179","pt":1722459883899,"mc":[{"id":"1.231242812","rc":[{"trd":[[1.85,8.7]],"batl":[[0,1.85,10.05]],"ltp":1.85,"tv":6402.3,"id":424676},{"batb":[[0,1.91,10],[1,1.9,163.18],[2,1.85,231.17]],"ltp":2.2,"tv":2888.4,"id":2120}],"tv":9290.7}]}
{"op":"mcm","clk":"11758345350","pt":1722459887232,"mc":[{"id":"1.231242812","rc":[{"batb":[[0,1.9,163.18],[1,1.85,231.17],[2,1.82,45.07]],"ltp":2.2,"tv":2888.4,"id":2120}]}]}
{"op":"mcm","clk":"11758345477","pt":1722459890419,"mc":[{"id":"1.231242812","rc":[{"batb":[[0,1.91,10],[1,1.9,163.18],[2,1.85,231.17]],"ltp":2.2,"tv":2888.4,"id":2120}]}]}
{"op":"mcm","clk":"11758345614","pt":1722459893712,"mc":[{"id":"1.231242812","rc":[{"batb":[[0,1.9,163.18],[1,1.85,231.17],[2,1.82,45.07]],"ltp":2.2,"tv":2888.4,"id":2120}]}]}
{"op":"mcm","clk":"11758346489","pt":1722459914037,"mc":[{"id":"1.231242812","rc":[{"batb":[[0,2.2,10],[1,2.18,12.82],[2,1.9,163.18]],"ltp":2.2,"tv":2888.4,"id":2120}]}]}
{"op":"mcm","clk":"11758346564","pt":1722459915837,"mc":[{"id":"1.231242812","rc":[{"batb":[[1,1.9,163.18],[2,1.85,231.17]],"ltp":2.2,"tv":2888.4,"id":2120}]}]}
{"op":"mcm","clk":"11758346627","pt":1722459917329,"mc":[{"id":"1.231242812","rc":[{"batb":[[0,1.9,163.18],[1,1.85,231.17],[2,1.82,45.07]],"ltp":2.2,"tv":2888.4,"id":2120}]}]}
{"op":"mcm","clk":"11758347493","pt":1722459935285,"mc":[{"id":"1.231242812","rc":[{"trd":[[1.85,26.54]],"batl":[[0,1.85,1.13]],"ltp":1.85,"tv":6420.13,"id":424676},{"batb":[[0,1.91,10],[1,1.9,163.18],[2,1.85,231.17]],"ltp":2.2,"tv":2888.4,"id":2120}],"tv":9308.54}]}
{"op":"mcm","clk":"11758347646","pt":1722459938593,"mc":[{"id":"1.231242812","rc":[{"batb":[[0,1.9,163.18],[1,1.85,231.17],[2,1.82,45.07]],"ltp":2.2,"tv":2888.4,"id":2120}]}]}
{"op":"mcm","clk":"11758348162","pt":1722459950481,"mc":[{"id":"1.231242812","rc":[{"trd":[[1.85,28.8]],"batb":[[0,1.85,16.64],[1,1.72,17.53],[2,1.71,16.34]],"batl":[[0,1.86,293.22],[1,1.89,270.54],[2,1.9,198.62]],"ltp":1.85,"tv":6422.39,"id":424676},{"batb":[[0,1.91,10],[1,1.9,163.18],[2,1.85,231.17]],"ltp":2.2,"tv":2888.4,"id":2120}],"tv":9310.79}]}
{"op":"mcm","clk":"11758348250","pt":1722459952274,"mc":[{"id":"1.231242812","rc":[{"batb":[[1,1.73,15.4],[2,1.72,17.53]],"ltp":1.85,"tv":6422.39,"id":424676}]}]}
{"op":"mcm","clk":"11758348318","pt":1722459953809,"mc":[{"id":"1.231242812","rc":[{"batb":[[0,1.9,163.18],[1,1.85,231.17],[2,1.82,45.07]],"ltp":2.2,"tv":2888.4,"id":2120}]}]}
{"op":"mcm","clk":"11758348364","pt":1722459954682,"mc":[{"id":"1.231242812","rc":[{"batb":[[2,1.71,16.34]],"ltp":1.85,"tv":6422.39,"id":424676}]}]}
{"op":"mcm","clk":"11758348412","pt":1722459955908,"mc":[{"id":"1.231242812","rc":[{"batb":[[1,1.71,16.34],[2,1.43,116.28]],"ltp":1.85,"tv":6422.39,"id":424676}]}]}
{"op":"mcm","clk":"11758348755","pt":1722459964902,"mc":[{"id":"1.231242812","rc":[{"batb":[[0,1.71,16.34],[1,1.43,116.28],[2,1.38,131.58]],"ltp":1.85,"tv":6422.39,"id":424676}]}]}
{"op":"mcm","clk":"11758348940","pt":1722459971097,"mc":[{"id":"1.231242812","rc":[{"batb":[[1,1.44,18.5],[2,1.43,116.28]],"ltp":1.85,"tv":6422.39,"id":424676}]}]}
{"op":"mcm","clk":"11758349487","pt":1722459984822,"mc":[{"id":"1.231242812","rc":[{"trd":[[1.86,126.26]],"batl":[[0,1.86,288.87]],"ltp":1.86,"tv":6431.09,"id":424676}],"tv":9319.49}]}
{"op":"mcm","clk":"11758349858","pt":1722459994260,"mc":[{"id":"1.231242812","rc":[{"trd":[[1.86,159.56]],"batl":[[0,1.86,272.22]],"ltp":1.86,"tv":6464.39,"id":424676}],"tv":9352.79}]}
{"op":"mcm","clk":"11758350023","pt":1722459998951,"mc":[{"id":"1.231242812","rc":[{"trd":[[1.86,177.4]],"batl":[[0,1.86,263.3]],"ltp":1.86,"tv":6482.23,"id":424676}],"tv":9370.63}]}
{"op":"mcm","clk":"11758350309","pt":1722460008140,"mc":[{"id":"1.231242812","rc":[{"batb":[[0,2.18,11.13],[1,1.9,163.18],[2,1.85,231.17]],"ltp":2.2,"tv":2888.4,"id":2120}]}]}
{"op":"mcm","clk":"11758351632","pt":1722460041098,"mc":[{"id":"1.231242812","rc":[{"trd":[[2.18,14.92]],"batb":[[0,2.18,3.67]],"ltp":2.18,"tv":2903.32,"id":2120}],"tv":9385.55}]}
{"op":"mcm","clk":"11758352071","pt":1722460052730,"mc":[{"id":"1.231242812","rc":[{"batb":[[0,1.8,2.05],[1,1.71,16.34],[2,1.44,18.5]],"ltp":1.86,"tv":6482.23,"id":424676}]}]}
{"op":"mcm","clk":"11758352143","pt":1722460054116,"mc":[{"id":"1.231242812","rc":[{"batb":[[1,1.72,33.02],[2,1.71,16.34]],"ltp":1.86,"tv":6482.23,"id":424676}]}]}
{"op":"mcm","clk":"11758352223","pt":1722460056130,"mc":[{"id":"1.231242812","rc":[{"batb":[[0,2.2,10],[1,2.18,3.67],[2,1.9,163.18]],"batl":[[0,2.38,11.67]],"ltp":2.18,"tv":2903.32,"id":2120}]}]}
{"op":"mcm","clk":"11758352247","pt":1722460056734,"mc":[{"id":"1.231242812","rc":[{"batb":[[1,1.9,163.18],[2,1.85,231.17]],"ltp":2.18,"tv":2903.32,"id":2120}]}]}
{"op":"mcm","clk":"11758352328","pt":1722460058734,"mc":[{"id":"1.231242812","rc":[{"batb":[[0,1.81,2.05]],"ltp":1.86,"tv":6482.23,"id":424676},{"batl":[[0,2.38,18.51]],"ltp":2.18,"tv":2903.32,"id":2120}]}]}
{"op":"mcm","clk":"11758352358","pt":1722460059306,"mc":[{"id":"1.231242812","rc":[{"batb":[[0,1.9,163.18],[1,1.85,231.17],[2,1.82,45.07]],"ltp":2.18,"tv":2903.32,"id":2120}]}]}
{"op":"mcm","clk":"11758352520","pt":1722460063615,"mc":[{"id":"1.231242812","rc":[{"batb":[[0,1.82,2.05]],"ltp":1.86,"tv":6482.23,"id":424676},{"batb":[[0,1.91,10],[1,1.9,163.18],[2,1.85,231.17]],"ltp":2.18,"tv":2903.32,"id":2120}]}]}
{"op":"mcm","clk":"11758352643","pt":1722460067149,"mc":[{"id":"1.231242812","rc":[{"batb":[[0,1.9,163.18],[1,1.85,231.17],[2,1.82,45.07]],"ltp":2.18,"tv":2903.32,"id":2120}]}]}
{"op":"mcm","clk":"11758352761","pt":1722460070638,"mc":[{"id":"1.231242812","rc":[{"batb":[[0,1.83,2.05]],"ltp":1.86,"tv":6482.23,"id":424676},{"batb":[[0,1.91,10],[1,1.9,163.18],[2,1.85,231.17]],"ltp":2.18,"tv":2903.32,"id":2120}]}]}
{"op":"mcm","clk":"11758352853","pt":1722460073925,"mc":[{"id":"1.231242812","rc":[{"batb":[[0,1.9,163.18],[1,1.85,231.17],[2,1.82,45.07]],"ltp":2.18,"tv":2903.32,"id":2120}]}]}
{"op":"mcm","clk":"11758353020","pt":1722460079262,"mc":[{"id":"1.231242812","rc":[{"batb":[[0,1.84,2.05]],"ltp":1.86,"tv":6482.23,"id":424676},{"batb":[[0,1.91,10],[1,1.9,163.18],[2,1.85,231.17]],"ltp":2.18,"tv":2903.32,"id":2120}]}]}
{"op":"mcm","clk":"11758353099","pt":1722460082557,"mc":[{"id":"1.231242812","rc":[{"batb":[[0,1.9,163.18],[1,1.85,231.17],[2,1.82,45.07]],"ltp":2.18,"tv":2903.32,"id":2120}]}]}
{"op":"mcm","clk":"11758353267","pt":1722460089757,"mc":[{"id":"1.231242812","rc":[{"batb":[[0,1.85,2.05]],"ltp":1.86,"tv":6482.23,"id":424676},{"batb":[[0,1.91,10],[1,1.9,163.18],[2,1.85,231.17]],"ltp":2.18,"tv":2903.32,"id":2120}]}]}
{"op":"mcm","clk":"11758353346","pt":1722460093149,"mc":[{"id":"1.231242812","rc":[{"batb":[[0,1.9,163.18],[1,1.85,231.17],[2,1.82,45.07]],"ltp":2.18,"tv":2903.32,"id":2120}]}]}
{"op":"mcm","clk":"11758353514","pt":1722460098946,"mc":[{"id":"1.231242812","rc":[{"batb":[[0,1.91,10],[1,1.9,163.18],[2,1.85,231.17]],"ltp":2.18,"tv":2903.32,"id":2120}]}]}
{"op":"mcm","clk":"11758353588","pt":1722460101259,"mc":[{"id":"1.231242812","rc":[{"trd":[[1.86,704]],"batb":[[0,1.86,47.86],[1,1.85,2.05],[2,1.72,15.5]],"batl":[[0,1.89,270.54],[1,1.9,198.62],[2,1.98,24.77]],"ltp":1.86,"tv":7008.83,"id":424676},{"batl":[[0,2.38,6.84]],"ltp":2.18,"tv":2903.32,"id":2120}],"tv":9912.15}]}
{"op":"mcm","clk":"11758353604","pt":1722460101670,"mc":[{"id":"1.231242812","rc":[{"batb":[[0,1.87,30.37],[1,1.86,47.86],[2,1.85,2.05]],"ltp":1.86,"tv":7008.83,"id":424676},{"batl":[[0,2.16,20.39]],"ltp":2.18,"tv":2903.32,"id":2120}]}]}
{"op":"mcm","clk":"11758353632","pt":1722460102390,"mc":[{"id":"1.231242812","rc":[{"batb":[[0,1.9,163.18],[1,1.85,231.17],[2,1.82,45.07]],"ltp":2.18,"tv":2903.32,"id":2120}]}]}
{"op":"mcm","clk":"11758353668","pt":1722460103469,"mc":[{"id":"1.231242812","rc":[{"batb":[[1,1.86,70.68]],"ltp":1.86,"tv":7008.83,"id":424676}]}]}
{"op":"mcm","clk":"11758353851","pt":1722460110191,"mc":[{"id":"1.231242812","rc":[{"batb":[[1,1.86,88.44]],"ltp":1.86,"tv":7008.83,"id":424676},{"batb":[[0,1.91,10],[1,1.9,163.18],[2,1.85,231.17]],"ltp":2.18,"tv":2903.32,"id":2120}]}]}
{"op":"mcm","clk":"11758353877","pt":1722460111782,"mc":[{"id":"1.231242812","rc":[{"batb":[[1,1.86,40.58]],"ltp":1.86,"tv":7008.83,"id":424676}]}]}
{"op":"mcm","clk":"11758353905","pt":1722460112962,"mc":[{"id":"1.231242812","rc":[{"batb":[[0,1.9,163.18],[1,1.85,231.17],[2,1.82,45.07]],"ltp":2.18,"tv":2903.32,"id":2120}]}]}
{"op":"mcm","clk":"11758354033","pt":1722460116094,"mc":[{"id":"1.231242812","rc":[{"batb":[[0,1.91,10],[1,1.9,163.18],[2,1.85,231.17]],"ltp":2.18,"tv":2903.32,"id":2120}]}]}
{"op":"mcm","clk":"11758354138","pt":1722460119584,"mc":[{"id":"1.231242812","rc":[{"batb":[[0,1.9,163.18],[1,1.85,231.17],[2,1.82,45.07]],"ltp":2.18,"tv":2903.32,"id":2120}]}]}
{"op":"mcm","clk":"11758354209","pt":1722460122197,"mc":[{"id":"1.231242812","rc":[{"trd":[[1.89,139.28]],"batb":[[2,1.71,16.34]],"batl":[[0,1.89,268.49]],"ltp":1.89,"tv":7012.93,"id":424676},{"batb":[[0,1.91,10],[1,1.9,163.18],[2,1.85,231.17]],"ltp":2.18,"tv":2903.32,"id":2120}],"tv":9916.25}]}
{"op":"mcm","clk":"11758354319","pt":1722460125802,"mc":[{"id":"1.231242812","rc":[{"batb":[[0,1.9,163.18],[1,1.85,231.17],[2,1.82,45.07]],"ltp":2.18,"tv":2903.32,"id":2120}]}]}
{"op":"mcm","clk":"11758354561","pt":1722460133906,"mc":[{"id":"1.231242812","rc":[{"batb":[[0,1.87,35.19]],"ltp":1.89,"tv":7012.93,"id":424676},{"batb":[[0,1.91,10],[1,1.9,163.18],[2,1.85,231.17]],"ltp":2.18,"tv":2903.32,"id":2120}]}]}
{"op":"mcm","clk":"11758354695","pt":1722460137234,"mc":[{"id":"1.231242812","rc":[{"batb":[[1,1.86,17.77]],"ltp":1.89,"tv":7012.93,"id":424676},{"batb":[[0,1.9,163.18],[1,1.85,231.17],[2,1.82,45.07]],"ltp":2.18,"tv":2903.32,"id":2120}]}]}
{"op":"mcm","clk":"11758354699","pt":1722460137289,"mc":[{"id":"1.231242812","rc":[{"batb":[[0,1.87,58.63]],"ltp":1.89,"tv":7012.93,"id":424676}]}]}
{"op":"mcm","clk":"11758354937","pt":1722460143296,"mc":[{"id":"1.231242812","rc":[{"batb":[[0,1.91,10],[1,1.9,163.18],[2,1.85,231.17]],"ltp":2.18,"tv":2903.32,"id":2120}]}]}
{"op":"mcm","clk":"11758355055","pt":1722460146537,"mc":[{"id":"1.231242812","rc":[{"batb":[[0,1.9,163.18],[1,1.85,231.17],[2,1.82,45.07]],"ltp":2.18,"tv":2903.32,"id":2120}]}]}
{"op":"mcm","clk":"11758355186","pt":1722460150134,"mc":[{"id":"1.231242812","rc":[{"batb":[[0,1.91,10],[1,1.9,163.18],[2,1.85,231.17]],"ltp":2.18,"tv":2903.32,"id":2120}]}]}
{"op":"mcm","clk":"11758355342","pt":1722460153248,"mc":[{"id":"1.231242812","rc":[{"batb":[[0,1.87,35.19]],"ltp":1.89,"tv":7012.93,"id":424676}]}]}
{"op":"mcm","clk":"11758355366","pt":1722460153669,"mc":[{"id":"1.231242812","rc":[{"batb":[[0,1.87,57.89]],"ltp":1.89,"tv":7012.93,"id":424676},{"batb":[[0,1.9,163.18],[1,1.85,231.17],[2,1.82,45.07]],"ltp":2.18,"tv":2903.32,"id":2120}]}]}
{"op":"mcm","clk":"11758355498","pt":1722460156530,"mc":[{"id":"1.231242812","rc":[{"batb":[[0,1.91,10],[1,1.9,163.18],[2,1.85,231.17]],"ltp":2.18,"tv":2903.32,"id":2120}]}]}
{"op":"mcm","clk":"11758355634","pt":1722460159876,"mc":[{"id":"1.231242812","rc":[{"batb":[[0,1.9,163.18],[1,1.85,231.17],[2,1.82,45.07]],"ltp":2.18,"tv":2903.32,"id":2120}]}]}
{"op":"mcm","clk":"11758355896","pt":1722460164758,"mc":[{"id":"1.231242812","rc":[{"batb":[[1,1.71,16.34],[2,1.43,116.28]],"ltp":1.89,"tv":7012.93,"id":424676},{"batb":[[0,1.91,10],[1,1.9,163.18],[2,1.85,231.17]],"ltp":2.18,"tv":2903.32,"id":2120}]}]}
{"op":"mcm","clk":"11758355987","pt":1722460166351,"mc":[{"id":"1.231242812","rc":[{"batb":[[0,1.87,53.06]],"ltp":1.89,"tv":7012.93,"id":424676}]}]}
{"op":"mcm","clk":"11758356066","pt":1722460168146,"mc":[{"id":"1.231242812","rc":[{"batb":[[0,1.9,163.18],[1,1.85,231.17],[2,1.82,45.07]],"ltp":2.18,"tv":2903.32,"id":2120}]}]}
{"op":"mcm","clk":"11758356654","pt":1722460186283,"mc":[{"id":"1.231242812","rc":[{"trd":[[1.89,156.42]],"batl":[[0,1.89,251.35]],"ltp":1.89,"tv":7030.07,"id":424676},{"trd":[[2.12,125.44]],"ltp":2.12,"tv":2918.61,"id":2120}],"tv":9948.68}]}
{"op":"mcm","clk":"11758356660","pt":1722460186385,"mc":[{"id":"1.231242812","rc":[{"batb":[[0,1.91,10],[1,1.9,163.18],[2,1.85,231.17]],"ltp":2.12,"tv":2918.61,"id":2120}]}]}
{"op":"mcm","clk":"11758356764","pt":1722460189673,"mc":[{"id":"1.231242812","rc":[{"batb":[[0,1.9,163.18],[1,1.85,231.17],[2,1.82,45.07]],"ltp":2.12,"tv":2918.61,"id":2120}]}]}
{"op":"mcm","clk":"11758356785","pt":1722460190292,"mc":[{"id":"1.231242812","rc":[{"batb":[[2,1.66,544.54]],"ltp":1.89,"tv":7030.07,"id":424676}]}]}
{"op":"mcm","clk":"11758357898","pt":1722460223357,"mc":[{"id":"1.231242812","rc":[{"batb":[[0,1.91,10],[1,1.9,163.18],[2,1.85,231.17]],"ltp":2.12,"tv":2918.61,"id":2120}]}]}
{"op":"mcm","clk":"11758357933","pt":1722460224407,"mc":[{"id":"1.231242812","rc":[{"trd":[[1.89,160.5]],"batl":[[0,1.89,249.31]],"ltp":1.89,"tv":7034.15,"id":424676}],"tv":9952.76}]}
{"op":"mcm","clk":"11758357996","pt":1722460226610,"mc":[{"id":"1.231242812","rc":[{"batb":[[0,1.9,163.18],[1,1.85,231.17],[2,1.82,45.07]],"ltp":2.12,"tv":2918.61,"id":2120}]}]}
{"op":"mcm","clk":"11758358707","pt":1722460247145,"mc":[{"id":"1.231242812","rc":[{"batb":[[0,1.91,10],[1,1.9,163.18],[2,1.85,231.17]],"ltp":2.12,"tv":2918.61,"id":2120}]}]}
{"op":"mcm","clk":"11758358717","pt":1722460247452,"mc":[{"id":"1.231242812","rc":[{"trd":[[1.89,205.38]],"batb":[[0,1.87,30.37]],"batl":[[0,1.89,226.87]],"ltp":1.89,"tv":7079.03,"id":424676}],"tv":9997.64}]}
{"op":"mcm","clk":"11758358814","pt":1722460250737,"mc":[{"id":"1.231242812","rc":[{"batb":[[0,1.9,163.18],[1,1.85,231.17],[2,1.82,45.07]],"ltp":2.12,"tv":2918.61,"id":2120}]}]}
{"op":"mcm","clk":"11758359236","pt":1722460265173,"mc":[{"id":"1.231242812","rc":[{"batb":[[0,1.91,10],[1,1.9,163.18],[2,1.85,231.17]],"ltp":2.12,"tv":2918.61,"id":2120}]}]}
{"op":"mcm","clk":"11758359379","pt":1722460268578,"mc":[{"id":"1.231242812","rc":[{"batb":[[0,1.9,163.18],[1,1.85,231.17],[2,1.82,45.07]],"ltp":2.12,"tv":2918.61,"id":2120}]}]}
{"op":"mcm","clk":"11758359710","pt":1722460278901,"mc":[{"id":"1.231242812","rc":[{"batb":[[0,1.91,10],[1,1.9,163.18],[2,1.85,231.17]],"ltp":2.12,"tv":2918.61,"id":2120}]}]}
{"op":"mcm","clk":"11758359804","pt":1722460282293,"mc":[{"id":"1.231242812","rc":[{"batb":[[0,1.9,163.18],[1,1.85,231.17],[2,1.82,45.07]],"ltp":2.12,"tv":2918.61,"id":2120}]}]}
{"op":"mcm","clk":"11758360498","pt":1722460309727,"mc":[{"id":"1.231242812","rc":[{"batb":[[0,1.91,10],[1,1.9,163.18],[2,1.85,231.17]],"ltp":2.12,"tv":2918.61,"id":2120}]}]}
{"op":"mcm","clk":"11758360615","pt":1722460313305,"mc":[{"id":"1.231242812","rc":[{"batb":[[0,1.9,163.18],[1,1.85,231.17],[2,1.82,45.07]],"ltp":2.12,"tv":2918.61,"id":2120}]}]}
{"op":"mcm","clk":"11758360731","pt":1722460316645,"mc":[{"id":"1.231242812","rc":[{"batb":[[0,1.91,10],[1,1.9,163.18],[2,1.85,231.17]],"ltp":2.12,"tv":2918.61,"id":2120}]}]}
{"op":"mcm","clk":"11758360838","pt":1722460320135,"mc":[{"id":"1.231242812","rc":[{"batb":[[0,1.9,163.18],[1,1.85,231.17],[2,1.82,45.07]],"ltp":2.12,"tv":2918.61,"id":2120}]}]}
{"op":"mcm","clk":"11758360970","pt":1722460324209,"mc":[{"id":"1.231242812","rc":[{"trd":[[1.87,130.22]],"batb":[[0,1.87,30.27]],"ltp":1.87,"tv":7079.23,"id":424676}],"tv":9997.84}]}
{"op":"mcm","clk":"11758360974","pt":1722460324314,"mc":[{"id":"1.231242812","rc":[{"batb":[[0,1.91,10],[1,1.9,163.18],[2,1.85,231.17]],"ltp":2.12,"tv":2918.61,"id":2120}]}]}
{"op":"mcm","clk":"11758361072","pt":1722460327652,"mc":[{"id":"1.231242812","rc":[{"batb":[[0,1.9,163.18],[1,1.85,231.17],[2,1.82,45.07]],"ltp":2.12,"tv":2918.61,"id":2120}]}]}
{"op":"mcm","clk":"11758361372","pt":1722460339349,"mc":[{"id":"1.231242812","rc":[{"batb":[[0,1.91,10],[1,1.9,163.18],[2,1.85,231.17]],"ltp":2.12,"tv":2918.61,"id":2120}]}]}
{"op":"mcm","clk":"11758361513","pt":1722460343253,"mc":[{"id":"1.231242812","rc":[{"batb":[[0,1.9,163.18],[1,1.85,231.17],[2,1.82,45.07]],"ltp":2.12,"tv":2918.61,"id":2120}]}]}
{"op":"mcm","clk":"11758361623","pt":1722460346743,"mc":[{"id":"1.231242812","rc":[{"batb":[[0,1.91,10],[1,1.9,163.18],[2,1.85,231.17]],"ltp":2.12,"tv":2918.61,"id":2120}]}]}
{"op":"mcm","clk":"11758361695","pt":1722460350380,"mc":[{"id":"1.231242812","rc":[{"batb":[[0,1.9,163.18],[1,1.85,231.17],[2,1.82,45.07]],"ltp":2.12,"tv":2918.61,"id":2120}]}]}
{"op":"mcm","clk":"11758361785","pt":1722460353565,"mc":[{"id":"1.231242812","rc":[{"batb":[[0,1.91,10],[1,1.9,163.18],[2,1.85,231.17]],"ltp":2.12,"tv":2918.61,"id":2120}]}]}
{"op":"mcm","clk":"11758361876","pt":1722460357050,"mc":[{"id":"1.231242812","rc":[{"batb":[[0,1.9,163.18],[1,1.85,231.17],[2,1.82,45.07]],"ltp":2.12,"tv":2918.61,"id":2120}]}]}
{"op":"mcm","clk":"11758371844","pt":1722460448656,"mc":[{"id":"1.231242812","rc":[{"batb":[[0,1.87,34.72],[1,1.86,35.62],[2,1.71,16.34]],"ltp":1.87,"tv":7079.23,"id":424676},{"batb":[[0,2.12,31.04],[1,1.9,163.18],[2,1.85,231.17]],"ltp":2.12,"tv":2918.61,"id":2120}]}]}
{"op":"mcm","clk":"11758388121","pt":1722461049439,"mc":[{"id":"1.231242812","rc":[{"trd":[[1.89,213.8]],"batl":[[0,1.89,222.66]],"ltp":1.89,"tv":7087.65,"id":424676}],"tv":10006.26}]}
{"op":"mcm","clk":"11758391280","pt":1722461152843,"mc":[{"id":"1.231242812","rc":[{"trd":[[1.89,433.06]],"batl":[[0,1.89,113.03]],"ltp":1.89,"tv":7306.91,"id":424676}],"tv":10225.52}]}
{"op":"mcm","clk":"11758392171","pt":1722461183106,"mc":[{"id":"1.231242812","rc":[{"trd":[[1.89,454.98]],"batl":[[0,1.89,102.07]],"ltp":1.89,"tv":7328.83,"id":424676}],"tv":10247.44}]}
{"op":"mcm","clk":"11758392798","pt":1722461205414,"mc":[{"id":"1.231242812","rc":[{"trd":[[1.89,476.9]],"batl":[[0,1.89,91.11]],"ltp":1.89,"tv":7350.75,"id":424676}],"tv":10269.36}]}
{"op":"mcm","clk":"11758407798","pt":1722461739964,"mc":[{"id":"1.231242812","rc":[{"trd":[[1.89,659.12]],"batb":[[0,1.89,47.3],[1,1.87,34.72],[2,1.86,35.62]],"batl":[[0,1.9,198.62],[1,1.98,24.77],[2,1.99,283.68]],"ltp":1.89,"tv":7532.97,"id":424676}],"tv":10451.58}]}
{"op":"mcm","clk":"11758407840","pt":1722461741246,"mc":[{"id":"1.231242812","rc":[{"batb":[[1,1.87,20.47]],"ltp":1.89,"tv":7532.97,"id":424676},{"batl":[[0,2.16,12.86]],"ltp":2.12,"tv":2918.61,"id":2120}]}]}
{"op":"mcm","clk":"11758407845","pt":1722461741450,"mc":[{"id":"1.231242812","rc":[{"batb":[[0,1.89,77.25],[1,1.86,35.62],[2,1.71,16.34]],"ltp":1.89,"tv":7532.97,"id":424676},{"batl":[[0,2.14,7.6],[1,2.16,12.86]],"ltp":2.12,"tv":2918.61,"id":2120}]}]}
{"op":"mcm","clk":"11758408623","pt":1722461767189,"mc":[{"id":"1.231242812","rc":[{"batb":[[1,1.71,16.34],[2,1.66,544.54]],"ltp":1.89,"tv":7532.97,"id":424676},{"batb":[[0,1.9,163.18],[1,1.85,231.17],[2,1.8,106.55]],"ltp":2.12,"tv":2918.61,"id":2120}]}]}
{"op":"mcm","clk":"11758408641","pt":1722461768272,"mc":[{"id":"1.231242812","rc":[{"batb":[[1,1.87,35.62],[2,1.71,16.34]],"ltp":1.89,"tv":7532.97,"id":424676},{"batb":[[0,2.1,31.55],[1,1.91,10],[2,1.9,163.18]],"batl":[[0,2.12,13.1],[1,2.14,7.6]],"ltp":2.12,"tv":2918.61,"id":2120}]}]}
{"op":"mcm","clk":"11758408703","pt":1722461770688,"mc":[{"id":"1.231242812","rc":[{"batb":[[1,1.9,163.18],[2,1.85,231.17]],"ltp":2.12,"tv":2918.61,"id":2120}]}]}
{"op":"mcm","clk":"11758410824","pt":1722461843259,"mc":[{"id":"1.231242812","rc":[{"batb":[[0,1.89,112.36],[1,1.71,16.34],[2,1.66,544.54]],"ltp":1.89,"tv":7532.97,"id":424676}]}]}
{"op":"mcm","clk":"11758413550","pt":1722461946730,"mc":[{"id":"1.231242812","rc":[{"trd":[[2.1,276.68]],"batb":[[0,2.1,23.65]],"ltp":2.1,"tv":2934.41,"id":2120}],"tv":10467.38}]}
{"op":"mcm","clk":"11758419110","pt":1722462141704,"mc":[{"id":"1.231242812","rc":[{"trd":[[1.9,468.28]],"batl":[[0,1.9,108.64]],"ltp":1.9,"tv":7712.93,"id":424676}],"tv":10647.34}]}
{"op":"mcm","clk":"11758421578","pt":1722462233499,"mc":[{"id":"1.231242812","rc":[{"trd":[[1.9,558.44]],"batl":[[0,1.9,63.56]],"ltp":1.9,"tv":7803.09,"id":424676}],"tv":10737.5}]}
{"op":"mcm","clk":"11758421936","pt":1722462245026,"mc":[{"id":"1.231242812","rc":[{"trd":[[1.9,672.94]],"batl":[[0,1.9,6.31]],"ltp":1.9,"tv":7917.59,"id":424676}],"tv":10852.0}]}
{"op":"mcm","clk":"11758421961","pt":1722462245696,"mc":[{"id":"1.231242812","rc":[{"batb":[[0,2.02,24.42],[1,1.91,10],[2,1.9,163.18]],"ltp":2.1,"tv":2934.41,"id":2120}]}]}
{"op":"mcm","clk":"11758421984","pt":1722462246313,"mc":[{"id":"1.231242812","rc":[{"batb":[[1,1.85,14.4],[2,1.71,16.34]],"ltp":1.9,"tv":7917.59,"id":424676},{"batl":[[2,2.18,7.46]],"ltp":2.1,"tv":2934.41,"id":2120}]}]}
{"op":"mcm","clk":"11758422039","pt":1722462247908,"mc":[{"id":"1.231242812","rc":[{"batb":[[1,1.71,16.34],[2,1.66,544.54]],"ltp":1.9,"tv":7917.59,"id":424676},{"batl":[[2,2.18,0]],"ltp":2.1,"tv":2934.41,"id":2120}]}]}
{"op":"mcm","clk":"11758422066","pt":1722462248988,"mc":[{"id":"1.231242812","rc":[{"batb":[[1,1.9,163.18],[2,1.89,41.53]],"ltp":2.1,"tv":2934.41,"id":2120}]}]}
{"op":"mcm","clk":"11758422151","pt":1722462252217,"mc":[{"id":"1.231242812","rc":[{"trd":[[1.9,685.56]],"batb":[[0,1.9,2.71],[1,1.89,112.36],[2,1.71,16.34]],"batl":[[0,1.98,24.77],[1,1.99,283.68],[2,2,153.43]],"ltp":1.9,"tv":7930.21,"id":424676}],"tv":10864.62}]}
{"op":"mcm","clk":"11758422155","pt":1722462252319,"mc":[{"id":"1.231242812","rc":[{"batb":[[0,2.04,10],[1,2.02,24.42],[2,1.9,163.18]],"ltp":2.1,"tv":2934.41,"id":2120}]}]}
{"op":"mcm","clk":"11758422247","pt":1722462255606,"mc":[{"id":"1.231242812","rc":[{"batb":[[0,2.02,24.42],[1,1.9,163.18],[2,1.89,41.53]],"ltp":2.1,"tv":2934.41,"id":2120}]}]}
{"op":"mcm","clk":"11758422295","pt":1722462257302,"mc":[{"id":"1.231242812","rc":[{"batb":[[0,1.89,112.36],[1,1.71,16.34],[2,1.66,544.54]],"ltp":1.9,"tv":7930.21,"id":424676}]}]}
{"op":"mcm","clk":"11758422505","pt":1722462263517,"mc":[{"id":"1.231242812","rc":[{"batb":[[0,2.04,10],[1,2.02,24.42],[2,1.9,163.18]],"ltp":2.1,"tv":2934.41,"id":2120}]}]}
{"op":"mcm","clk":"11758422591","pt":1722462266904,"mc":[{"id":"1.231242812","rc":[{"batb":[[0,2.02,24.42],[1,1.9,163.18],[2,1.89,41.53]],"ltp":2.1,"tv":2934.41,"id":2120}]}]}
{"op":"mcm","clk":"11758422669","pt":1722462270640,"mc":[{"id":"1.231242812","rc":[{"batb":[[0,2.04,10],[1,2.02,24.42],[2,1.9,163.18]],"ltp":2.1,"tv":2934.41,"id":2120}]}]}
{"op":"mcm","clk":"11758422738","pt":1722462273821,"mc":[{"id":"1.231242812","rc":[{"batb":[[0,2.02,24.42],[1,1.9,163.18],[2,1.89,41.53]],"ltp":2.1,"tv":2934.41,"id":2120}]}]}
{"op":"mcm","clk":"11758422874","pt":1722462277743,"mc":[{"id":"1.231242812","rc":[{"batb":[[0,1.9,8.35],[1,1.89,112.36],[2,1.71,16.34]],"ltp":1.9,"tv":7930.21,"id":424676},{"batb":[[0,2.04,10],[1,2.02,24.42],[2,1.9,163.18]],"batl":[[0,2.12,21.13]],"ltp":2.1,"tv":2934.41,"id":2120}]}]}
{"op":"mcm","clk":"11758422897","pt":1722462279028,"mc":[{"id":"1.231242812","rc":[{"batl":[[1,2.14,0]],"ltp":2.1,"tv":2934.41,"id":2120}]}]}
{"op":"mcm","clk":"11758422948","pt":1722462280928,"mc":[{"id":"1.231242812","rc":[{"batb":[[0,2.02,24.42],[1,1.9,163.18],[2,1.89,41.53]],"ltp":2.1,"tv":2934.41,"id":2120}]}]}
{"op":"mcm","clk":"11758423080","pt":1722462285868,"mc":[{"id":"1.231242812","rc":[{"batb":[[0,2.04,10],[1,2.02,24.42],[2,1.9,163.18]],"ltp":2.1,"tv":2934.41,"id":2120}]}]}
{"op":"mcm","clk":"11758423205","pt":1722462289157,"mc":[{"id":"1.231242812","rc":[{"batb":[[0,2.02,24.42],[1,1.9,163.18],[2,1.89,41.53]],"ltp":2.1,"tv":2934.41,"id":2120}]}]}
{"op":"mcm","clk":"11758423297","pt":1722462291951,"mc":[{"id":"1.231242812","rc":[{"batb":[[0,2.04,10],[1,2.02,24.42],[2,1.9,163.18]],"ltp":2.1,"tv":2934.41,"id":2120}]}]}
{"op":"mcm","clk":"11758423389","pt":1722462295236,"mc":[{"id":"1.231242812","rc":[{"batb":[[0,2.02,24.42],[1,1.9,163.18],[2,1.89,41.53]],"ltp":2.1,"tv":2934.41,"id":2120}]}]}
{"op":"mcm","clk":"11758423490","pt":1722462298166,"mc":[{"id":"1.231242812","rc":[{"batb":[[0,2.04,10],[1,2.02,24.42],[2,1.9,163.18]],"ltp":2.1,"tv":2934.41,"id":2120}]}]}
{"op":"mcm","clk":"11758423614","pt":1722462301668,"mc":[{"id":"1.231242812","rc":[{"batb":[[0,2.02,24.42],[1,1.9,163.18],[2,1.89,41.53]],"ltp":2.1,"tv":2934.41,"id":2120}]}]}
{"op":"mcm","clk":"11758423698","pt":1722462304143,"mc":[{"id":"1.231242812","rc":[{"batb":[[0,2.04,10],[1,2.02,24.42],[2,1.9,163.18]],"ltp":2.1,"tv":2934.41,"id":2120}]}]}
{"op":"mcm","clk":"11758423827","pt":1722462307682,"mc":[{"id":"1.231242812","rc":[{"batb":[[0,2.02,24.42],[1,1.9,163.18],[2,1.89,41.53]],"ltp":2.1,"tv":2934.41,"id":2120}]}]}
{"op":"mcm","clk":"11758423899","pt":1722462310354,"mc":[{"id":"1.231242812","rc":[{"batb":[[0,2.04,10],[1,2.02,24.42],[2,1.9,163.18]],"ltp":2.1,"tv":2934.41,"id":2120}]}]}
{"op":"mcm","clk":"11758424024","pt":1722462313999,"mc":[{"id":"1.231242812","rc":[{"batb":[[0,2.02,24.42],[1,1.9,163.18],[2,1.89,41.53]],"ltp":2.1,"tv":2934.41,"id":2120}]}]}
{"op":"mcm","clk":"11758424120","pt":1722462316363,"mc":[{"id":"1.231242812","rc":[{"batb":[[0,2.04,10],[1,2.02,24.42],[2,1.9,163.18]],"ltp":2.1,"tv":2934.41,"id":2120}]}]}
{"op":"mcm","clk":"11758424195","pt":1722462318164,"mc":[{"id":"1.231242812","rc":[{"batb":[[1,1.89,77.25]],"ltp":1.9,"tv":7930.21,"id":424676}]}]}
{"op":"mcm","clk":"11758424200","pt":1722462318366,"mc":[{"id":"1.231242812","rc":[{"batb":[[2,1.71,55.01]],"ltp":1.9,"tv":7930.21,"id":424676}]}]}
{"op":"mcm","clk":"11758424286","pt":1722462320265,"mc":[{"id":"1.231242812","rc":[{"batb":[[0,1.9,53.43]],"ltp":1.9,"tv":7930.21,"id":424676},{"batb":[[0,2.02,24.42],[1,1.9,163.18],[2,1.89,41.53]],"ltp":2.1,"tv":2934.41,"id":2120}]}]}
{"op":"mcm","clk":"11758424343","pt":1722462321903,"mc":[{"id":"1.231242812","rc":[{"batb":[[1,1.89,47.3]],"ltp":1.9,"tv":7930.21,"id":424676},{"batb":[[0,2.04,10],[1,2.02,24.42],[2,1.9,163.18]],"ltp":2.1,"tv":2934.41,"id":2120}]}]}
{"op":"mcm","clk":"11758424434","pt":1722462325190,"mc":[{"id":"1.231242812","rc":[{"batb":[[0,2.02,24.42],[1,1.9,163.18],[2,1.89,41.53]],"ltp":2.1,"tv":2934.41,"id":2120}]}]}
{"op":"mcm","clk":"11758424494","pt":1722462327811,"mc":[{"id":"1.231242812","rc":[{"batb":[[2,1.85,14.4]],"ltp":1.9,"tv":7930.21,"id":424676},{"batb":[[0,2.04,10],[1,2.02,24.42],[2,1.9,163.18]],"batl":[[1,2.18,7.46]],"ltp":2.1,"tv":2934.41,"id":2120}]}]}
{"op":"mcm","clk":"11758424546","pt":1722462329812,"mc":[{"id":"1.231242812","rc":[{"batb":[[0,1.91,13.95],[1,1.9,53.43],[2,1.89,47.3]],"ltp":1.9,"tv":7930.21,"id":424676},{"batl":[[0,2.1,7.75],[1,2.12,21.13]],"ltp":2.1,"tv":2934.41,"id":2120}]}]}
{"op":"mcm","clk":"11758424590","pt":1722462331200,"mc":[{"id":"1.231242812","rc":[{"batb":[[0,2.02,24.42],[1,1.9,163.18],[2,1.89,41.53]],"batl":[[0,2.08,13.36],[1,2.1,7.75],[2,2.12,8.03]],"ltp":2.1,"tv":2934.41,"id":2120}]}]}
{"op":"mcm","clk":"11758424591","pt":1722462331303,"mc":[{"id":"1.231242812","rc":[{"batb":[[0,1.9,53.43],[1,1.89,47.3],[2,1.71,55.01]],"ltp":1.9,"tv":7930.21,"id":424676}]}]}
{"op":"mcm","clk":"11758424636","pt":1722462332997,"mc":[{"id":"1.231242812","rc":[{"batl":[[0,2.1,7.75],[1,2.12,8.03],[2,2.12,0]],"ltp":2.1,"tv":2934.41,"id":2120}]}]}
{"op":"mcm","clk":"11758424669","pt":1722462334179,"mc":[{"id":"1.231242812","rc":[{"batb":[[0,2.04,10],[1,2.02,24.42],[2,1.9,163.18]],"batl":[[0,2.12,8.03],[1,2.12,0]],"ltp":2.1,"tv":2934.41,"id":2120}]}]}
{"op":"mcm","clk":"11758424765","pt":1722462337413,"mc":[{"id":"1.231242812","rc":[{"batb":[[0,2.02,24.42],[1,1.9,163.18],[2,1.89,41.53]],"ltp":2.1,"tv":2934.41,"id":2120}]}]}
{"op":"mcm","clk":"11758424952","pt":1722462344293,"mc":[{"id":"1.231242812","rc":[{"batb":[[0,2.04,10],[1,2.02,24.42],[2,1.9,163.18]],"ltp":2.1,"tv":2934.41,"id":2120}]}]}
{"op":"mcm","clk":"11758425067","pt":1722462347493,"mc":[{"id":"1.231242812","rc":[{"batb":[[0,2.02,24.42],[1,1.9,163.18],[2,1.89,41.53]],"ltp":2.1,"tv":2934.41,"id":2120}]}]}
{"op":"mcm","clk":"11758425629","pt":1722462363312,"mc":[{"id":"1.231242812","rc":[{"batb":[[0,2.04,10],[1,2.02,24.42],[2,1.9,163.18]],"ltp":2.1,"tv":2934.41,"id":2120}]}]}
{"op":"mcm","clk":"11758425752","pt":1722462366718,"mc":[{"id":"1.231242812","rc":[{"batb":[[0,2.02,24.42],[1,1.9,163.18],[2,1.89,41.53]],"ltp":2.1,"tv":2934.41,"id":2120}]}]}
{"op":"mcm","clk":"11758425874","pt":1722462369831,"mc":[{"id":"1.231242812","rc":[{"batb":[[0,2.04,10],[1,2.02,24.42],[2,1.9,163.18]],"ltp":2.1,"tv":2934.41,"id":2120}]}]}
{"op":"mcm","clk":"11758425994","pt":1722462373229,"mc":[{"id":"1.231242812","rc":[{"batb":[[0,2.02,24.42],[1,1.9,163.18],[2,1.89,41.53]],"ltp":2.1,"tv":2934.41,"id":2120}]}]}
{"op":"mcm","clk":"11758426099","pt":1722462375748,"mc":[{"id":"1.231242812","rc":[{"batb":[[0,2.04,10],[1,2.02,24.42],[2,1.9,163.18]],"ltp":2.1,"tv":2934.41,"id":2120}]}]}
{"op":"mcm","clk":"11758426208","pt":1722462379035,"mc":[{"id":"1.231242812","rc":[{"batb":[[0,2.02,24.42],[1,1.9,163.18],[2,1.89,41.53]],"ltp":2.1,"tv":2934.41,"id":2120}]}]}
{"op":"mcm","clk":"11758426427","pt":1722462386344,"mc":[{"id":"1.231242812","rc":[{"batb":[[0,2.04,10],[1,2.02,24.42],[2,1.9,163.18]],"ltp":2.1,"tv":2934.41,"id":2120}]}]}
{"op":"mcm","clk":"11758426539","pt":1722462390242,"mc":[{"id":"1.231242812","rc":[{"batb":[[0,1.9,88.04],[2,1.71,16.34]],"ltp":1.9,"tv":7930.21,"id":424676},{"batb":[[0,2.02,24.42],[1,1.9,163.18],[2,1.89,41.53]],"ltp":2.1,"tv":2934.41,"id":2120}]}]}
{"op":"mcm","clk":"11758426936","pt":1722462400887,"mc":[{"id":"1.231242812","rc":[{"batb":[[0,2.04,10],[1,2.02,24.42],[2,1.9,163.18]],"ltp":2.1,"tv":2934.41,"id":2120}]}]}
{"op":"mcm","clk":"11758427076","pt":1722462404072,"mc":[{"id":"1.231242812","rc":[{"batb":[[0,2.02,24.42],[1,1.9,163.18],[2,1.89,41.53]],"ltp":2.1,"tv":2934.41,"id":2120}]}]}
{"op":"mcm","clk":"11758427294","pt":1722462410861,"mc":[{"id":"1.231242812","rc":[{"batb":[[2,1.85,14.4]],"ltp":1.9,"tv":7930.21,"id":424676},{"batb":[[0,2.04,10],[1,2.02,24.42],[2,1.9,163.18]],"batl":[[1,2.18,7.46]],"ltp":2.1,"tv":2934.41,"id":2120}]}]}
{"op":"mcm","clk":"11758427352","pt":1722462412871,"mc":[{"id":"1.231242812","rc":[{"batb":[[0,1.91,13.95],[1,1.9,88.04],[2,1.89,47.3]],"ltp":1.9,"tv":7930.21,"id":424676},{"batl":[[0,2.1,7.75],[1,2.12,8.03]],"ltp":2.1,"tv":2934.41,"id":2120}]}]}
{"op":"mcm","clk":"11758427418","pt":1722462414896,"mc":[{"id":"1.231242812","rc":[{"batb":[[0,2.02,24.42],[1,1.9,163.18],[2,1.89,41.53]],"batl":[[0,2.08,13.36],[1,2.1,7.75],[2,2.12,8.03]],"ltp":2.1,"tv":2934.41,"id":2120}]}]}
{"op":"mcm","clk":"11758427476","pt":1722462416800,"mc":[{"id":"1.231242812","rc":[{"batb":[[0,1.92,15.6],[1,1.91,13.95],[2,1.9,88.04]],"ltp":1.9,"tv":7930.21,"id":424676}]}]}
{"op":"mcm","clk":"11758427490","pt":1722462417364,"mc":[{"id":"1.231242812","rc":[{"batb":[[1,1.9,88.04],[2,1.89,47.3]],"ltp":1.9,"tv":7930.21,"id":424676}]}]}
{"op":"mcm","clk":"11758427886","pt":1722462430108,"mc":[{"id":"1.231242812","rc":[{"batb":[[0,1.93,13.8],[1,1.92,15.6],[2,1.9,88.04]],"ltp":1.9,"tv":7930.21,"id":424676}]}]}
{"op":"mcm","clk":"11758427903","pt":1722462430876,"mc":[{"id":"1.231242812","rc":[{"batl":[[2,2.12,0]],"ltp":2.1,"tv":2934.41,"id":2120}]}]}
{"op":"mcm","clk":"11758427927","pt":1722462431900,"mc":[{"id":"1.231242812","rc":[{"batl":[[0,2.06,7.9],[1,2.08,13.36]],"ltp":2.1,"tv":2934.41,"id":2120}]}]}
{"op":"mcm","clk":"11758427945","pt":1722462433027,"mc":[{"id":"1.231242812","rc":[{"batb":[[0,1.94,15.44],[1,1.93,13.8],[2,1.92,15.6]],"ltp":1.9,"tv":7930.21,"id":424676}]}]}
{"op":"mcm","clk":"11758428000","pt":1722462435212,"mc":[{"id":"1.231242812","rc":[{"batb":[[0,1.92,15.6],[1,1.9,79.68],[2,1.89,47.3]],"ltp":1.9,"tv":7930.21,"id":424676}]}]}
{"op":"mcm","clk":"11758429034","pt":1722462472930,"mc":[{"id":"1.231242812","rc":[{"batb":[[0,2,24.93],[1,1.91,10],[2,1.9,163.18]],"ltp":2.1,"tv":2934.41,"id":2120}]}]}
{"op":"mcm","clk":"11758429132","pt":1722462476224,"mc":[{"id":"1.231242812","rc":[{"batb":[[1,1.9,163.18],[2,1.89,41.53]],"ltp":2.1,"tv":2934.41,"id":2120}]}]}
{"op":"mcm","clk":"11758430100","pt":1722462512697,"mc":[{"id":"1.231242812","rc":[{"batb":[[0,1.93,13.8],[1,1.92,15.6],[2,1.9,79.68]],"ltp":1.9,"tv":7930.21,"id":424676}]}]}
{"op":"mcm","clk":"11758430147","pt":1722462514594,"mc":[{"id":"1.231242812","rc":[{"batb":[[0,1.94,15.44],[1,1.93,13.8],[2,1.92,15.6]],"ltp":1.9,"tv":7930.21,"id":424676}]}]}
{"op":"mcm","clk":"11758430183","pt":1722462515773,"mc":[{"id":"1.231242812","rc":[{"batb":[[1,1.92,15.6],[2,1.9,79.68]],"ltp":1.9,"tv":7930.21,"id":424676}]}]}
{"op":"mcm","clk":"11758430214","pt":1722462516503,"mc":[{"id":"1.231242812","rc":[{"batb":[[0,1.92,15.6],[1,1.9,79.68],[2,1.89,47.3]],"ltp":1.9,"tv":7930.21,"id":424676}]}]}
{"op":"mcm","clk":"11758432395","pt":1722462595771,"mc":[{"id":"1.231242812","rc":[{"batb":[[0,1.93,13.8],[1,1.92,15.6],[2,1.9,79.68]],"ltp":1.9,"tv":7930.21,"id":424676}]}]}
{"op":"mcm","clk":"11758432435","pt":1722462596693,"mc":[{"id":"1.231242812","rc":[{"batb":[[0,1.94,15.44],[1,1.93,13.8],[2,1.92,15.6]],"ltp":1.9,"tv":7930.21,"id":424676}]}]}
{"op":"mcm","clk":"11758432462","pt":1722462597359,"mc":[{"id":"1.231242812","rc":[{"batb":[[1,1.92,15.6],[2,1.9,79.68]],"ltp":1.9,"tv":7930.21,"id":424676}]}]}
{"op":"mcm","clk":"11758432495","pt":1722462598693,"mc":[{"id":"1.231242812","rc":[{"batb":[[0,1.92,15.6],[1,1.9,79.68],[2,1.89,47.3]],"ltp":1.9,"tv":7930.21,"id":424676}]}]}
{"op":"mcm","clk":"11758434895","pt":1722462676984,"mc":[{"id":"1.231242812","rc":[{"batb":[[0,1.93,13.8],[1,1.92,15.6],[2,1.9,79.68]],"ltp":1.9,"tv":7930.21,"id":424676}]}]}
{"op":"mcm","clk":"11758434949","pt":1722462679188,"mc":[{"id":"1.231242812","rc":[{"batb":[[0,1.94,15.44],[1,1.93,13.8],[2,1.92,15.6]],"ltp":1.9,"tv":7930.21,"id":424676}]}]}
{"op":"mcm","clk":"11758434970","pt":1722462679702,"mc":[{"id":"1.231242812","rc":[{"batb":[[1,1.92,15.6],[2,1.9,79.68]],"ltp":1.9,"tv":7930.21,"id":424676}]}]}
{"op":"mcm","clk":"11758435031","pt":1722462681293,"mc":[{"id":"1.231242812","rc":[{"batb":[[0,1.92,15.6],[1,1.9,79.68],[2,1.89,47.3]],"ltp":1.9,"tv":7930.21,"id":424676}]}]}
{"op":"mcm","clk":"11758437036","pt":1722462759682,"mc":[{"id":"1.231242812","rc":[{"batb":[[0,1.93,13.8],[1,1.92,15.6],[2,1.9,79.68]],"ltp":1.9,"tv":7930.21,"id":424676}]}]}
{"op":"mcm","clk":"11758437071","pt":1722462761578,"mc":[{"id":"1.231242812","rc":[{"batb":[[0,1.94,15.44],[1,1.93,13.8],[2,1.92,15.6]],"ltp":1.9,"tv":7930.21,"id":424676}]}]}
{"op":"mcm","clk":"11758437110","pt":1722462762865,"mc":[{"id":"1.231242812","rc":[{"batb":[[1,1.92,15.6],[2,1.9,79.68]],"ltp":1.9,"tv":7930.21,"id":424676}]}]}
{"op":"mcm","clk":"11758437139","pt":1722462763892,"mc":[{"id":"1.231242812","rc":[{"batb":[[0,1.92,15.6],[1,1.9,79.68],[2,1.89,47.3]],"ltp":1.9,"tv":7930.21,"id":424676}]}]}
{"op":"mcm","clk":"11758439254","pt":1722462841454,"mc":[{"id":"1.231242812","rc":[{"batb":[[0,1.93,13.8],[1,1.92,15.6],[2,1.9,79.68]],"ltp":1.9,"tv":7930.21,"id":424676}]}]}
{"op":"mcm","clk":"11758439289","pt":1722462842603,"mc":[{"id":"1.231242812","rc":[{"batb":[[0,1.94,15.44],[1,1.93,13.8],[2,1.92,15.6]],"ltp":1.9,"tv":7930.21,"id":424676}]}]}
{"op":"mcm","clk":"11758439318","pt":1722462843479,"mc":[{"id":"1.231242812","rc":[{"batb":[[1,1.92,15.6],[2,1.9,79.68]],"ltp":1.9,"tv":7930.21,"id":424676}]}]}
{"op":"mcm","clk":"11758439360","pt":1722462844562,"mc":[{"id":"1.231242812","rc":[{"batb":[[0,1.92,15.6],[1,1.9,79.68],[2,1.89,47.3]],"ltp":1.9,"tv":7930.21,"id":424676}]}]}
{"op":"mcm","clk":"11758441825","pt":1722462922933,"mc":[{"id":"1.231242812","rc":[{"batb":[[0,1.93,13.8],[1,1.92,15.6],[2,1.9,79.68]],"ltp":1.9,"tv":7930.21,"id":424676}]}]}
{"op":"mcm","clk":"11758441867","pt":1722462923962,"mc":[{"id":"1.231242812","rc":[{"batb":[[0,1.94,15.44],[1,1.93,13.8],[2,1.92,15.6]],"ltp":1.9,"tv":7930.21,"id":424676}]}]}
{"op":"mcm","clk":"11758441899","pt":1722462925043,"mc":[{"id":"1.231242812","rc":[{"batb":[[1,1.92,15.6],[2,1.9,79.68]],"ltp":1.9,"tv":7930.21,"id":424676}]}]}
{"op":"mcm","clk":"11758441930","pt":1722462926065,"mc":[{"id":"1.231242812","rc":[{"batb":[[0,1.92,15.6],[1,1.9,79.68],[2,1.89,47.3]],"ltp":1.9,"tv":7930.21,"id":424676}]}]}
{"op":"mcm","clk":"11758444025","pt":1722463005227,"mc":[{"id":"1.231242812","rc":[{"batb":[[0,1.93,13.8],[1,1.92,15.6],[2,1.9,79.68]],"ltp":1.9,"tv":7930.21,"id":424676}]}]}
{"op":"mcm","clk":"11758444052","pt":1722463007125,"mc":[{"id":"1.231242812","rc":[{"batb":[[0,1.94,15.44]],"ltp":1.9,"tv":7930.21,"id":424676}]}]}
{"op":"mcm","clk":"11758444102","pt":1722463009127,"mc":[{"id":"1.231242812","rc":[{"batb":[[0,1.92,15.6],[1,1.9,79.68],[2,1.89,47.3]],"ltp":1.9,"tv":7930.21,"id":424676}]}]}
{"op":"mcm","clk":"11758444887","pt":1722463036986,"mc":[{"id":"1.231242812","rc":[{"trd":[[1.94,107.67]],"ltp":1.94,"tv":7937.88,"id":424676},{"trd":[[2.06,101.24]],"batl":[[0,2.08,14.03],[1,2.08,0]],"ltp":2.06,"tv":2941.63,"id":2120}],"tv":10879.52}]}
{"op":"mcm","clk":"11758444926","pt":1722463037758,"mc":[{"id":"1.231242812","rc":[{"batb":[[1,1.91,15.68],[2,1.9,79.68]],"ltp":1.94,"tv":7937.88,"id":424676},{"batl":[[0,2.1,18.59]],"ltp":2.06,"tv":2941.63,"id":2120}]}]}
{"op":"mcm","clk":"11758444952","pt":1722463038680,"mc":[{"id":"1.231242812","rc":[{"batb":[[0,2.02,10],[1,2,24.93],[2,1.9,163.18]],"ltp":2.06,"tv":2941.63,"id":2120}]}]}
{"op":"mcm","clk":"11758444980","pt":1722463039553,"mc":[{"id":"1.231242812","rc":[{"batb":[[0,1.92,13.88],[1,1.91,23.21]],"ltp":1.94,"tv":7937.88,"id":424676}]}]}
{"op":"mcm","clk":"11758445068","pt":1722463042269,"mc":[{"id":"1.231242812","rc":[{"batb":[[0,2,24.93],[1,1.9,163.18],[2,1.89,41.53]],"ltp":2.06,"tv":2941.63,"id":2120}]}]}
{"op":"mcm","clk":"11758445430","pt":1722463059198,"mc":[{"id":"1.231242812","rc":[{"batb":[[0,1.93,45.08],[1,1.92,13.88],[2,1.91,23.21]],"ltp":1.94,"tv":7937.88,"id":424676}]}]}
{"op":"mcm","clk":"11758445450","pt":1722463059810,"mc":[{"id":"1.231242812","rc":[{"batb":[[0,1.94,15.44],[1,1.93,45.08],[2,1.92,13.88]],"ltp":1.94,"tv":7937.88,"id":424676},{"batb":[[0,2.02,10],[1,2,24.93],[2,1.9,163.18]],"batl":[[0,2.06,13.48]],"ltp":2.06,"tv":2941.63,"id":2120}]}]}
{"op":"mcm","clk":"11758445483","pt":1722463060789,"mc":[{"id":"1.231242812","rc":[{"batb":[[0,1.95,13.67],[1,1.94,15.44],[2,1.93,45.08]],"ltp":1.94,"tv":7937.88,"id":424676}]}]}
{"op":"mcm","clk":"11758445583","pt":1722463063402,"mc":[{"id":"1.231242812","rc":[{"batb":[[0,2,24.93],[1,1.9,163.18],[2,1.85,231.17]],"ltp":2.06,"tv":2941.63,"id":2120}]}]}
{"op":"mcm","clk":"11758445684","pt":1722463066586,"mc":[{"id":"1.231242812","rc":[{"batb":[[2,1.89,41.53]],"ltp":2.06,"tv":2941.63,"id":2120}]}]}
{"op":"mcm","clk":"11758445765","pt":1722463070322,"mc":[{"id":"1.231242812","rc":[{"trd":[[1.95,124.52]],"batb":[[0,1.95,1.41]],"ltp":1.95,"tv":7962.4,"id":424676}],"tv":10904.04}]}
{"op":"mcm","clk":"11758445955","pt":1722463078434,"mc":[{"id":"1.231242812","rc":[{"trd":[[1.95,127.05]],"batb":[[0,1.94,15.58],[1,1.93,45.08],[2,1.9,79.68]],"ltp":1.95,"tv":7964.92,"id":424676}],"tv":10906.56}]}
{"op":"mcm","clk":"11758446012","pt":1722463081003,"mc":[{"id":"1.231242812","rc":[{"batb":[[0,1.94,15.44]],"ltp":1.95,"tv":7964.92,"id":424676}]}]}
{"op":"mcm","clk":"11758446314","pt":1722463093327,"mc":[{"id":"1.231242812","rc":[{"batl":[[0,2.06,17.7]],"ltp":2.06,"tv":2941.63,"id":2120}]}]}
{"op":"mcm","clk":"11758446435","pt":1722463097844,"mc":[{"id":"1.231242812","rc":[{"batb":[[1,1.93,79.17],[2,1.9,45.08]],"ltp":1.95,"tv":7964.92,"id":424676}]}]}
{"op":"mcm","clk":"11758446812","pt":1722463112945,"mc":[{"id":"1.231242812","rc":[{"batb":[[0,1.95,30.65],[1,1.94,15.44],[2,1.93,79.17]],"ltp":1.95,"tv":7964.92,"id":424676}]}]}
{"op":"mcm","clk":"11758446863","pt":1722463114539,"mc":[{"id":"1.231242812","rc":[{"batb":[[0,1.96,15.28],[1,1.95,30.65],[2,1.94,15.44]],"ltp":1.95,"tv":7964.92,"id":424676}]}]}
{"op":"mcm","clk":"11758447120","pt":1722463124028,"mc":[{"id":"1.231242812","rc":[{"trd":[[1.96,27.96]],"batb":[[0,1.96,1.3]],"ltp":1.96,"tv":7992.89,"id":424676}],"tv":10934.52}]}
{"op":"mcm","clk":"11758447358","pt":1722463132539,"mc":[{"id":"1.231242812","rc":[{"trd":[[1.96,30.3]],"batb":[[0,1.95,30.78],[1,1.94,15.44],[2,1.93,79.17]],"ltp":1.96,"tv":7995.23,"id":424676}],"tv":10936.87}]}
{"op":"mcm","clk":"11758447414","pt":1722463134845,"mc":[{"id":"1.231242812","rc":[{"batb":[[0,1.95,30.65]],"ltp":1.96,"tv":7995.23,"id":424676}]}]}
{"op":"mcm","clk":"11758448412","pt":1722463167771,"mc":[{"id":"1.231242812","rc":[{"batb":[[1,1.94,49.53],[2,1.93,45.08]],"ltp":1.96,"tv":7995.23,"id":424676}]}]}
{"op":"mcm","clk":"11758448440","pt":1722463169207,"mc":[{"id":"1.231242812","rc":[{"batb":[[2,1.9,45.08]],"ltp":1.96,"tv":7995.23,"id":424676}]}]}
{"op":"mcm","clk":"11758448605","pt":1722463174896,"mc":[{"id":"1.231242812","rc":[{"batb":[[0,1.94,49.53],[1,1.9,45.08],[2,1.89,47.3]],"ltp":1.96,"tv":7995.23,"id":424676}]}]}
{"op":"mcm","clk":"11758448659","pt":1722463176686,"mc":[{"id":"1.231242812","rc":[{"batl":[[0,2.06,4.22]],"ltp":2.06,"tv":2941.63,"id":2120}]}]}
{"op":"mcm","clk":"11758448718","pt":1722463178632,"mc":[{"id":"1.231242812","rc":[{"batb":[[0,1.94,34.09]],"ltp":1.96,"tv":7995.23,"id":424676}]}]}
{"op":"mcm","clk":"11758450714","pt":1722463235246,"mc":[{"id":"1.231242812","rc":[{"trd":[[1.79,41.66],[1.8,600.02],[1.85,28.79],[1.86,703.87],[1.89,659.11],[1.9,685.54],[1.91,482.39],[1.95,127.04],[1.96,30.3],[1.97,130.98],[1.99,199.25],[2,1054.29],[2.08,40.04],[2.1,1209.98],[2.12,51.38],[2.16,6.74],[2.18,64.93]],"batl":[[0,1.98,28.77]],"ltp":1.96,"tv":7994.85,"id":424676},{"trd":[[1.84,38.82],[1.86,46.63],[1.98,561.89],[2.02,430.8],[2.04,95.4],[2.06,101.22],[2.08,383.58],[2.1,276.66],[2.12,125.39],[2.14,61.03],[2.18,14.92],[2.22,12.52]],"ltp":2.06,"tv":2941.43,"id":2120}],"tv":10936.28}]}
{"op":"mcm","clk":"11758450745","pt":1722463236066,"mc":[{"id":"1.231242812","rc":[{"batb":[[0,1.9,45.08],[1,1.89,82.41],[2,1.71,16.34]],"ltp":1.96,"tv":7994.85,"id":424676}]}]}
{"op":"mcm","clk":"11758450824","pt":1722463238174,"mc":[{"id":"1.231242812","rc":[{"batb":[[0,2.02,10],[1,2,24.93],[2,1.9,163.18]],"batl":[[0,2.1,13.22]],"ltp":2.06,"tv":2941.43,"id":2120}]}]}
{"op":"mcm","clk":"11758450939","pt":1722463241464,"mc":[{"id":"1.231242812","rc":[{"batb":[[0,2,24.93],[1,1.9,163.18],[2,1.89,41.53]],"ltp":2.06,"tv":2941.43,"id":2120}]}]}
{"op":"mcm","clk":"11758451053","pt":1722463244779,"mc":[{"id":"1.231242812","rc":[{"batb":[[0,2.02,10],[1,2,24.93],[2,1.9,163.18]],"ltp":2.06,"tv":2941.43,"id":2120}]}]}
{"op":"mcm","clk":"11758451188","pt":1722463248171,"mc":[{"id":"1.231242812","rc":[{"batb":[[0,2,24.93],[1,1.9,163.18],[2,1.89,41.53]],"ltp":2.06,"tv":2941.43,"id":2120}]}]}
{"op":"mcm","clk":"11758451244","pt":1722463249707,"mc":[{"id":"1.231242812","rc":[{"batb":[[0,2.04,4],[1,2.02,4],[2,2,24.93]],"ltp":2.06,"tv":2941.43,"id":2120}]}]}
{"op":"mcm","clk":"11758451823","pt":1722463264777,"mc":[{"id":"1.231242812","rc":[{"batl":[[0,2.1,17.22]],"ltp":2.06,"tv":2941.43,"id":2120}]}]}
{"op":"mcm","clk":"11758452791","pt":1722463290737,"mc":[{"id":"1.231242812","rc":[{"batb":[[0,1.89,82.41],[1,1.71,16.34],[2,1.66,544.37]],"ltp":1.96,"tv":7994.85,"id":424676},{"batl":[[0,2.1,13.22]],"ltp":2.06,"tv":2941.43,"id":2120}]}]}
{"op":"mcm","clk":"11758452827","pt":1722463291617,"mc":[{"id":"1.231242812","rc":[{"batl":[[0,2.12,13.1]],"ltp":2.06,"tv":2941.43,"id":2120}]}]}
{"op":"mcm","clk":"11758453408","pt":1722463305034,"mc":[{"id":"1.231242812","rc":[{"batb":[[0,1.89,47.3],[1,1.71,55.01]],"ltp":1.96,"tv":7994.85,"id":424676},{"batb":[[1,2.02,28.42],[2,1.9,163.18]],"ltp":2.06,"tv":2941.43,"id":2120}]}]}
{"op":"mcm","clk":"11758575669","pt":1722466104174,"mc":[{"id":"1.231242812","rc":[{"batb":[[0,1.95,36.74],[1,1.89,47.3],[2,1.71,55.01]],"ltp":1.96,"tv":7994.85,"id":424676},{"batb":[[0,2.02,28.42],[1,1.98,37.71]],"batl":[[0,2.04,13.62]],"ltp":2.06,"tv":2941.43,"id":2120}]}]}
{"op":"mcm","clk":"11758575674","pt":1722466104378,"mc":[{"id":"1.231242812","rc":[{"trd":[[2.04,115.41]],"batl":[[0,2.04,3.61]],"ltp":2.04,"tv":2961.43,"id":2120}],"tv":10956.28}]}
{"op":"mcm","clk":"11758576211","pt":1722466118176,"mc":[{"id":"1.231242812","rc":[{"batb":[[1,1.89,82.41],[2,1.71,16.34]],"ltp":1.96,"tv":7994.85,"id":424676}]}]}
{"op":"mcm","clk":"11758749284","pt":1722469367039,"mc":[{"id":"1.231242812","rc":[{"trd":[[1.79,41.66],[1.8,599.97],[1.85,28.79],[1.86,703.91],[1.89,659.16],[1.9,685.55],[1.91,482.39],[1.95,127.04],[1.96,30.3],[1.97,130.97],[1.99,199.24],[2,1054.28],[2.02,332.48],[2.04,214.28],[2.08,40.04],[2.1,1209.9],[2.12,51.38],[2.16,6.74],[2.18,64.93]],"batb":[[1,1.89,82.45]],"ltp":1.96,"tv":7994.83,"id":424676},{"trd":[[1.84,38.82],[1.86,46.63],[1.98,561.87],[2.02,430.78],[2.04,115.39],[2.06,101.2],[2.08,383.55],[2.1,276.65],[2.12,125.39],[2.14,61.02],[2.18,14.92],[2.22,12.52]],"batb":[[0,2.02,28.44]],"ltp":2.04,"tv":2961.29,"id":2120}],"tv":10956.12}]}
{"op":"mcm","clk":"11758872192","pt":1722471174854,"mc":[{"id":"1.231242812","rc":[{"trd":[[1.79,41.67],[1.8,600.1],[1.85,28.8],[1.86,704.02],[1.89,659.21],[1.9,685.58],[1.91,482.41],[1.95,127.05],[1.96,30.3],[1.97,130.99],[1.99,199.26],[2,1054.31],[2.02,332.49],[2.04,214.33],[2.08,40.05],[2.1,1210.13],[2.12,51.38],[2.16,6.74],[2.18,64.93]],"batb":[[1,1.89,82.49]],"ltp":1.96,"tv":7995.58,"id":424676},{"trd":[[1.84,38.83],[1.86,46.64],[1.98,561.93],[2.02,430.83],[2.04,115.43],[2.06,101.25],[2.08,383.63],[2.1,276.7],[2.12,125.43],[2.14,61.05],[2.18,14.92],[2.22,12.53]],"batb":[[0,2.02,28.45]],"batl":[[0,2.04,3.61]],"ltp":2.04,"tv":2961.72,"id":2120}],"tv":10957.31}]}
{"op":"mcm","clk":"11759271583","pt":1722476574879,"mc":[{"id":"1.231242812","rc":[{"trd":[[1.79,41.68],[1.8,600.15],[1.85,28.8],[1.86,704.01],[1.89,659.1],[1.9,685.56],[1.91,482.41],[1.95,127.05],[1.96,30.3],[1.97,130.99],[1.99,199.26],[2,1054.32],[2.02,332.46],[2.04,214.2],[2.08,40.05],[2.1,1210.2],[2.12,51.39],[2.16,6.74],[2.18,64.94]],"batb":[[1,1.89,82.38]],"ltp":1.96,"tv":7995.44,"id":424676},{"trd":[[1.84,38.83],[1.86,46.64],[1.98,561.95],[2.02,430.86],[2.04,115.45],[2.06,101.26],[2.08,383.66],[2.1,276.71],[2.12,125.44],[2.14,61.06],[2.18,14.93],[2.22,12.53]],"batb":[[0,2.02,28.42]],"ltp":2.04,"tv":2961.86,"id":2120}],"tv":10957.3}]}
{"op":"mcm","clk":"11759369872","pt":1722477793170,"mc":[{"id":"1.231242812","rc":[{"trd":[[1.79,41.68],[1.8,600.12],[1.85,28.8],[1.86,704],[1.89,659.02],[1.9,685.57],[1.91,482.41],[1.95,127.05],[1.96,30.3],[1.97,130.99],[1.98,277.21],[1.99,199.26],[2,1054.31],[2.02,332.44],[2.04,214.1],[2.08,40.05],[2.1,1210.14],[2.12,51.38],[2.18,64.93]],"batb":[[0,1.96,4],[1,1.95,36.74],[2,1.89,82.31]],"batl":[[0,1.98,26.79]],"ltp":1.98,"tv":7997.11,"id":424676},{"trd":[[1.84,38.83],[1.86,46.64],[1.98,561.94],[2.02,489.58],[2.04,115.44],[2.06,101.26],[2.08,383.64],[2.1,276.69],[2.12,125.43],[2.14,61.05],[2.18,14.93],[2.22,12.53]],"batb":[[0,2.02,4]],"ltp":2.02,"tv":3020.51,"id":2120}],"tv":11017.62}]}
{"op":"mcm","clk":"11759370673","pt":1722477807184,"mc":[{"id":"1.231242812","rc":[{"trd":[[1.98,304],[1.99,482.94],[2,1166.47]],"batb":[[0,1.95,36.74],[1,1.89,82.31],[2,1.71,16.34]],"batl":[[0,2,41.27],[1,2.02,291.68],[2,2.04,221.48]],"ltp":2.0,"tv":8419.74,"id":424676},{"trd":[[2,493.93],[2.02,523.84]],"batb":[[0,1.98,37.71],[1,1.9,163.18],[2,1.85,231.17]],"ltp":2.0,"tv":3449.19,"id":2120}],"tv":11868.94}]}
{"op":"mcm","clk":"11759370742","pt":1722477808274,"mc":[{"id":"1.231242812","rc":[{"batb":[[0,1.96,10],[1,1.95,36.74],[2,1.89,82.31]],"batl":[[0,2,45.27]],"ltp":2.0,"tv":8419.74,"id":424676},{"batb":[[0,2,4],[1,1.98,37.71],[2,1.9,163.18]],"ltp":2.0,"tv":3449.19,"id":2120}]}]}
{"op":"mcm","clk":"11759370900","pt":1722477810554,"mc":[{"id":"1.231242812","rc":[{"batb":[[0,1.95,36.74],[1,1.89,82.31],[2,1.71,16.34]],"ltp":2.0,"tv":8419.74,"id":424676}]}]}
{"op":"mcm","clk":"11759371044","pt":1722477812874,"mc":[{"id":"1.231242812","rc":[{"batb":[[0,1.96,10],[1,1.95,36.74],[2,1.89,82.31]],"ltp":2.0,"tv":8419.74,"id":424676}]}]}
{"op":"mcm","clk":"11759371244","pt":1722477816371,"mc":[{"id":"1.231242812","rc":[{"batb":[[0,1.95,36.74],[1,1.89,82.31],[2,1.71,16.34]],"ltp":2.0,"tv":8419.74,"id":424676}]}]}
{"op":"mcm","clk":"11759371375","pt":1722477818679,"mc":[{"id":"1.231242812","rc":[{"batb":[[0,1.96,10],[1,1.95,36.74],[2,1.89,82.31]],"ltp":2.0,"tv":8419.74,"id":424676}]}]}
{"op":"mcm","clk":"11759371559","pt":1722477821981,"mc":[{"id":"1.231242812","rc":[{"batb":[[0,1.95,36.74],[1,1.89,82.31],[2,1.71,16.34]],"ltp":2.0,"tv":8419.74,"id":424676}]}]}
{"op":"mcm","clk":"11759371708","pt":1722477824565,"mc":[{"id":"1.231242812","rc":[{"batb":[[0,1.96,10],[1,1.95,36.74],[2,1.89,82.31]],"ltp":2.0,"tv":8419.74,"id":424676}]}]}
{"op":"mcm","clk":"11759371906","pt":1722477827970,"mc":[{"id":"1.231242812","rc":[{"batb":[[0,1.95,36.74],[1,1.89,82.31],[2,1.71,16.34]],"ltp":2.0,"tv":8419.74,"id":424676}]}]}
{"op":"mcm","clk":"11759372000","pt":1722477830292,"mc":[{"id":"1.231242812","rc":[{"batb":[[0,1.96,10],[1,1.95,36.74],[2,1.89,82.31]],"ltp":2.0,"tv":8419.74,"id":424676}]}]}
{"op":"mcm","clk":"11759372154","pt":1722477833781,"mc":[{"id":"1.231242812","rc":[{"batb":[[0,1.95,36.74],[1,1.89,82.31],[2,1.71,16.34]],"ltp":2.0,"tv":8419.74,"id":424676}]}]}
{"op":"mcm","clk":"11759372240","pt":1722477836091,"mc":[{"id":"1.231242812","rc":[{"batb":[[0,1.96,10],[1,1.95,36.74],[2,1.89,82.31]],"ltp":2.0,"tv":8419.74,"id":424676}]}]}
{"op":"mcm","clk":"11759372449","pt":1722477839606,"mc":[{"id":"1.231242812","rc":[{"batb":[[0,1.95,36.74],[1,1.89,82.31],[2,1.71,16.34]],"ltp":2.0,"tv":8419.74,"id":424676}]}]}
{"op":"mcm","clk":"11759372550","pt":1722477841916,"mc":[{"id":"1.231242812","rc":[{"batb":[[0,1.96,10],[1,1.95,36.74],[2,1.89,82.31]],"ltp":2.0,"tv":8419.74,"id":424676}]}]}
{"op":"mcm","clk":"11759372707","pt":1722477845309,"mc":[{"id":"1.231242812","rc":[{"batb":[[0,1.95,36.74],[1,1.89,82.31],[2,1.71,16.34]],"ltp":2.0,"tv":8419.74,"id":424676}]}]}
{"op":"mcm","clk":"11759372825","pt":1722477847623,"mc":[{"id":"1.231242812","rc":[{"batb":[[0,1.96,10],[1,1.95,36.74],[2,1.89,82.31]],"ltp":2.0,"tv":8419.74,"id":424676}]}]}
{"op":"mcm","clk":"11759372994","pt":1722477850810,"mc":[{"id":"1.231242812","rc":[{"trd":[[2,1207.97]],"batb":[[0,1.95,36.74],[1,1.89,82.31],[2,1.71,16.34]],"batl":[[0,2,3.77]],"ltp":2.0,"tv":8461.24,"id":424676},{"trd":[[2,543.43]],"batb":[[0,1.98,37.71],[1,1.9,163.18],[2,1.85,231.17]],"ltp":2.0,"tv":3498.69,"id":2120}],"tv":11959.94}]}
{"op":"mcm","clk":"11759373160","pt":1722477854102,"mc":[{"id":"1.231242812","rc":[{"batb":[[0,1.96,10],[1,1.95,36.74],[2,1.89,82.31]],"ltp":2.0,"tv":8461.24,"id":424676}]}]}
{"op":"mcm","clk":"11759373290","pt":1722477857432,"mc":[{"id":"1.231242812","rc":[{"batb":[[0,1.95,36.74],[1,1.89,82.31],[2,1.71,16.34]],"ltp":2.0,"tv":8461.24,"id":424676}]}]}
{"op":"mcm","clk":"11759373443","pt":1722477859814,"mc":[{"id":"1.231242812","rc":[{"batb":[[0,1.96,10],[1,1.95,36.74],[2,1.89,82.31]],"ltp":2.0,"tv":8461.24,"id":424676}]}]}
{"op":"mcm","clk":"11759373647","pt":1722477863103,"mc":[{"id":"1.231242812","rc":[{"batb":[[0,1.95,36.74],[1,1.89,82.31],[2,1.71,16.34]],"ltp":2.0,"tv":8461.24,"id":424676}]}]}
{"op":"mcm","clk":"11759373913","pt":1722477867031,"mc":[{"id":"1.231242812","rc":[{"batb":[[0,1.96,10],[1,1.95,36.74],[2,1.89,82.31]],"ltp":2.0,"tv":8461.24,"id":424676}]}]}
{"op":"mcm","clk":"11759374127","pt":1722477870829,"mc":[{"id":"1.231242812","rc":[{"batb":[[0,1.95,36.74],[1,1.89,82.31],[2,1.71,16.34]],"ltp":2.0,"tv":8461.24,"id":424676}]}]}
{"op":"mcm","clk":"11759374239","pt":1722477872938,"mc":[{"id":"1.231242812","rc":[{"batb":[[0,1.96,10],[1,1.95,36.74],[2,1.89,82.31]],"ltp":2.0,"tv":8461.24,"id":424676}]}]}
{"op":"mcm","clk":"11759374294","pt":1722477873923,"mc":[{"id":"1.231242812","rc":[{"trd":[[2,1211.74],[2.02,470.19]],"batl":[[0,2.02,153.93],[1,2.04,221.48],[2,2.04,0]],"ltp":2.02,"tv":8602.76,"id":424676},{"trd":[[1.98,777.89],[2,547.2]],"batb":[[0,1.91,10]],"ltp":1.98,"tv":3718.41,"id":2120}],"tv":12321.18}]}
{"op":"mcm","clk":"11759374336","pt":1722477874640,"mc":[{"id":"1.231242812","rc":[{"batb":[[1,1.95,38.9]],"ltp":2.02,"tv":8602.76,"id":424676},{"batb":[[0,1.94,39.32],[1,1.91,10],[2,1.9,163.18]],"ltp":1.98,"tv":3718.41,"id":2120}]}]}
{"op":"mcm","clk":"11759374409","pt":1722477876234,"mc":[{"id":"1.231242812","rc":[{"batb":[[0,1.95,38.9],[1,1.89,82.31],[2,1.71,16.34]],"ltp":2.02,"tv":8602.76,"id":424676}]}]}
{"op":"mcm","clk":"11759374472","pt":1722477877323,"mc":[{"id":"1.231242812","rc":[{"batb":[[1,1.9,163.18],[2,1.85,231.17]],"ltp":1.98,"tv":3718.41,"id":2120}]}]}
{"op":"mcm","clk":"11759374522","pt":1722477878448,"mc":[{"id":"1.231242812","rc":[{"batb":[[0,1.96,10],[1,1.95,38.9],[2,1.89,82.31]],"ltp":2.02,"tv":8602.76,"id":424676}]}]}
{"op":"mcm","clk":"11759374649","pt":1722477880356,"mc":[{"id":"1.231242812","rc":[{"batb":[[0,1.95,10],[1,1.94,39.32],[2,1.9,163.18]],"ltp":1.98,"tv":3718.41,"id":2120}]}]}
{"op":"mcm","clk":"11759374743","pt":1722477881748,"mc":[{"id":"1.231242812","rc":[{"batb":[[0,1.95,38.9],[1,1.89,82.31],[2,1.71,16.34]],"ltp":2.02,"tv":8602.76,"id":424676}]}]}
{"op":"mcm","clk":"11759374782","pt":1722477882417,"mc":[{"id":"1.231242812","rc":[{"batl":[[0,2,9.96],[1,2.02,153.93],[2,2.04,221.48]],"ltp":2.02,"tv":8602.76,"id":424676}]}]}
{"op":"mcm","clk":"11759374848","pt":1722477883650,"mc":[{"id":"1.231242812","rc":[{"batb":[[0,1.96,4],[1,1.95,38.9],[2,1.89,82.31]],"batl":[[0,2,13.96]],"ltp":2.02,"tv":8602.76,"id":424676},{"batb":[[0,2,4]],"batl":[[0,2.04,7.61]],"ltp":1.98,"tv":3718.41,"id":2120}]}]}
{"op":"mcm","clk":"11759377774","pt":1722477932978,"mc":[{"id":"1.231242812","rc":[{"trd":[[2,1225.71]],"batb":[[0,1.97,10],[1,1.96,4],[2,1.95,38.9]],"batl":[[0,2.02,153.93],[1,2.04,221.48],[2,2.04,0]],"ltp":2.0,"tv":8616.73,"id":424676},{"trd":[[2,569.16]],"batb":[[0,1.95,10]],"batl":[[0,2.04,7.85]],"ltp":2.0,"tv":3740.38,"id":2120}],"tv":12357.11}]}
{"op":"mcm","clk":"11759377823","pt":1722477933907,"mc":[{"id":"1.231242812","rc":[{"batb":[[1,1.95,38.9],[2,1.89,47.24]],"ltp":2.0,"tv":8616.73,"id":424676},{"batl":[[0,2.04,3.85]],"ltp":2.0,"tv":3740.38,"id":2120}]}]}
{"op":"mcm","clk":"11759377848","pt":1722477934471,"mc":[{"id":"1.231242812","rc":[{"batb":[[1,1.96,10.3],[2,1.95,38.9]],"ltp":2.0,"tv":8616.73,"id":424676}]}]}
{"op":"mcm","clk":"11759377956","pt":1722477936367,"mc":[{"id":"1.231242812","rc":[{"batb":[[0,1.96,10.3],[1,1.95,38.9],[2,1.89,47.24]],"ltp":2.0,"tv":8616.73,"id":424676},{"batb":[[0,1.94,39.32],[1,1.9,163.18],[2,1.85,231.17]],"ltp":2.0,"tv":3740.38,"id":2120}]}]}
{"op":"mcm","clk":"11759378085","pt":1722477938684,"mc":[{"id":"1.231242812","rc":[{"batb":[[0,1.97,10],[1,1.96,10.3],[2,1.95,38.9]],"ltp":2.0,"tv":8616.73,"id":424676},{"batb":[[0,1.95,10],[1,1.94,39.32],[2,1.9,163.18]],"ltp":2.0,"tv":3740.38,"id":2120}]}]}
{"op":"mcm","clk":"11759378285","pt":1722477941986,"mc":[{"id":"1.231242812","rc":[{"batb":[[0,1.96,10.3],[1,1.95,38.9],[2,1.89,47.24]],"ltp":2.0,"tv":8616.73,"id":424676},{"batb":[[0,1.94,39.32],[1,1.9,163.18],[2,1.85,231.17]],"ltp":2.0,"tv":3740.38,"id":2120}]}]}
{"op":"mcm","clk":"11759378399","pt":1722477944093,"mc":[{"id":"1.231242812","rc":[{"batb":[[0,1.97,10],[1,1.96,10.3],[2,1.95,38.9]],"batl":[[0,2.02,157.93]],"ltp":2.0,"tv":8616.73,"id":424676},{"batb":[[0,1.98,4],[1,1.94,39.32],[2,1.9,163.18]],"ltp":2.0,"tv":3740.38,"id":2120}]}]}
{"op":"mcm","clk":"11759378576","pt":1722477947486,"mc":[{"id":"1.231242812","rc":[{"batb":[[0,1.96,10.3],[1,1.95,38.9],[2,1.89,47.24]],"ltp":2.0,"tv":8616.73,"id":424676}]}]}
{"op":"mcm","clk":"11759378708","pt":1722477949588,"mc":[{"id":"1.231242812","rc":[{"batb":[[0,1.97,10],[1,1.96,10.3],[2,1.95,38.9]],"ltp":2.0,"tv":8616.73,"id":424676}]}]}
{"op":"mcm","clk":"11759378879","pt":1722477952982,"mc":[{"id":"1.231242812","rc":[{"batb":[[0,1.96,10.3],[1,1.95,38.9],[2,1.89,47.24]],"ltp":2.0,"tv":8616.73,"id":424676}]}]}
{"op":"mcm","clk":"11759379003","pt":1722477955267,"mc":[{"id":"1.231242812","rc":[{"batb":[[0,1.97,10],[1,1.96,10.3],[2,1.95,38.9]],"ltp":2.0,"tv":8616.73,"id":424676}]}]}
{"op":"mcm","clk":"11759379190","pt":1722477958521,"mc":[{"id":"1.231242812","rc":[{"batb":[[0,1.96,10.3],[1,1.95,38.9],[2,1.89,47.24]],"ltp":2.0,"tv":8616.73,"id":424676}]}]}
{"op":"mcm","clk":"11759379351","pt":1722477960902,"mc":[{"id":"1.231242812","rc":[{"batb":[[0,1.97,10],[1,1.96,10.3],[2,1.95,38.9]],"ltp":2.0,"tv":8616.73,"id":424676}]}]}
{"op":"mcm","clk":"11759379537","pt":1722477964309,"mc":[{"id":"1.231242812","rc":[{"batb":[[0,1.96,10.3],[1,1.95,38.9],[2,1.89,47.24]],"ltp":2.0,"tv":8616.73,"id":424676}]}]}
{"op":"mcm","clk":"11759379650","pt":1722477966683,"mc":[{"id":"1.231242812","rc":[{"batb":[[0,1.97,10],[1,1.96,10.3],[2,1.95,38.9]],"ltp":2.0,"tv":8616.73,"id":424676}]}]}
{"op":"mcm","clk":"11759379832","pt":1722477970031,"mc":[{"id":"1.231242812","rc":[{"batb":[[0,1.96,10.3],[1,1.95,38.9],[2,1.89,47.24]],"ltp":2.0,"tv":8616.73,"id":424676}]}]}
{"op":"mcm","clk":"11759379937","pt":1722477972506,"mc":[{"id":"1.231242812","rc":[{"batb":[[0,1.97,10],[1,1.96,10.3],[2,1.95,38.9]],"ltp":2.0,"tv":8616.73,"id":424676}]}]}
{"op":"mcm","clk":"11759380130","pt":1722477975910,"mc":[{"id":"1.231242812","rc":[{"batb":[[0,1.96,10.3],[1,1.95,38.9],[2,1.89,47.24]],"ltp":2.0,"tv":8616.73,"id":424676}]}]}
{"op":"mcm","clk":"11759380255","pt":1722477978330,"mc":[{"id":"1.231242812","rc":[{"batb":[[0,1.97,10],[1,1.96,10.3],[2,1.95,38.9]],"ltp":2.0,"tv":8616.73,"id":424676}]}]}
{"op":"mcm","clk":"11759380444","pt":1722477981740,"mc":[{"id":"1.231242812","rc":[{"batb":[[0,1.96,10.3],[1,1.95,38.9],[2,1.89,47.24]],"ltp":2.0,"tv":8616.73,"id":424676}]}]}
{"op":"mcm","clk":"11759380592","pt":1722477983906,"mc":[{"id":"1.231242812","rc":[{"batb":[[0,1.97,10],[1,1.96,10.3],[2,1.95,38.9]],"ltp":2.0,"tv":8616.73,"id":424676},{"batl":[[0,2,45.74],[1,2.04,3.61]],"ltp":2.0,"tv":3740.38,"id":2120}]}]}
{"op":"mcm","clk":"11759380624","pt":1722477984525,"mc":[{"id":"1.231242812","rc":[{"batb":[[0,2,10.09],[1,1.97,10]],"ltp":2.0,"tv":8616.73,"id":424676},{"batl":[[0,1.99,3.7],[1,2,45.74]],"ltp":2.0,"tv":3740.38,"id":2120}]}]}
{"op":"mcm","clk":"11759380783","pt":1722477987205,"mc":[{"id":"1.231242812","rc":[{"batb":[[1,1.95,38.9],[2,1.89,47.24]],"ltp":2.0,"tv":8616.73,"id":424676}]}]}
{"op":"mcm","clk":"11759382082","pt":1722478006264,"mc":[{"id":"1.231242812","rc":[{"batb":[[1,1.95,72.95]],"ltp":2.0,"tv":8616.73,"id":424676}]}]}
{"op":"mcm","clk":"11759413525","pt":1722478456017,"mc":[{"id":"1.231242812","rc":[{"trd":[[2.02,510.87]],"batl":[[0,2.02,117.25]],"ltp":2.02,"tv":8657.41,"id":424676},{"trd":[[1.98,827.39]],"batb":[[0,1.94,39.32],[1,1.9,163.18],[2,1.85,231.17]],"batl":[[1,2,0.24]],"ltp":1.98,"tv":3789.88,"id":2120}],"tv":12447.29}]}
{"op":"mcm","clk":"11759413600","pt":1722478457009,"mc":[{"id":"1.231242812","rc":[{"batb":[[0,1.98,4],[1,1.94,39.32],[2,1.9,163.18]],"ltp":1.98,"tv":3789.88,"id":2120}]}]}
{"op":"mcm","clk":"11759413687","pt":1722478457902,"mc":[{"id":"1.231242812","rc":[{"trd":[[2,1225.94]],"batb":[[0,1.96,20.3]],"batl":[[0,2,5.04],[1,2.02,117.25],[2,2.04,221.48]],"ltp":2.0,"tv":8657.64,"id":424676},{"trd":[[2,569.4]],"batb":[[0,1.99,5.48],[1,1.98,4],[2,1.94,39.32]],"batl":[[0,2.04,3.61],[1,2,0]],"ltp":2.0,"tv":3790.12,"id":2120}],"tv":12447.77}]}
{"op":"mcm","clk":"11759413942","pt":1722478460798,"mc":[{"id":"1.231242812","rc":[{"batb":[[0,1.96,10.3]],"ltp":2.0,"tv":8657.64,"id":424676}]}]}
{"op":"mcm","clk":"11759414848","pt":1722478472137,"mc":[{"id":"1.231242812","rc":[{"batb":[[0,1.97,4],[1,1.96,14.3],[2,1.95,72.95]],"batl":[[0,2,9.04]],"ltp":2.0,"tv":8657.64,"id":424676},{"batl":[[0,2.04,7.61]],"ltp":2.0,"tv":3790.12,"id":2120}]}]}
{"op":"mcm","clk":"11759416031","pt":1722478487160,"mc":[{"id":"1.231242812","rc":[{"batb":[[0,2,4],[1,1.99,5.48],[2,1.98,4]],"ltp":2.0,"tv":3790.12,"id":2120}]}]}
{"op":"mcm","clk":"11759416054","pt":1722478487420,"mc":[{"id":"1.231242812","rc":[{"batb":[[1,1.96,19.78]],"ltp":2.0,"tv":8657.64,"id":424676}]}]}
{"op":"mcm","clk":"11759416254","pt":1722478489648,"mc":[{"id":"1.231242812","rc":[{"batl":[[0,2.04,14.21]],"ltp":2.0,"tv":3790.12,"id":2120}]}]}
{"op":"mcm","clk":"11759416590","pt":1722478494236,"mc":[{"id":"1.231242812","rc":[{"batb":[[1,1.96,53.32],[2,1.95,38.9]],"ltp":2.0,"tv":8657.64,"id":424676}]}]}
{"op":"mcm","clk":"11759552309","pt":1722480346796,"mc":[{"id":"1.231242812","rc":[{"trd":[[1.97,138.99]],"batb":[[0,1.96,53.32],[1,1.95,38.9],[2,1.89,47.24]],"batl":[[0,2,9.55]],"ltp":1.97,"tv":8665.64,"id":424676}],"tv":12455.77}]}
{"op":"mcm","clk":"11759552397","pt":1722480348186,"mc":[{"id":"1.231242812","rc":[{"batl":[[0,2.04,18.5]],"ltp":2.0,"tv":3790.12,"id":2120}]}]}
{"op":"mcm","clk":"11759553117","pt":1722480358119,"mc":[{"id":"1.231242812","rc":[{"trd":[[1.97,140.01]],"batb":[[0,1.97,3.49],[1,1.96,53.32],[2,1.95,38.9]],"batl":[[0,2,9.04]],"ltp":1.97,"tv":8666.66,"id":424676},{"batl":[[0,2.04,14.21]],"ltp":2.0,"tv":3790.12,"id":2120}],"tv":12456.79}]}
{"op":"mcm","clk":"11759566350","pt":1722480561249,"mc":[{"id":"1.231242812","rc":[{"trd":[[1.97,146.99]],"batb":[[0,1.96,53.32],[1,1.95,38.9],[2,1.89,47.24]],"batl":[[0,1.97,1.02],[1,2,9.04],[2,2.02,117.25]],"ltp":1.97,"tv":8673.64,"id":424676}],"tv":12463.77}]}
{"op":"mcm","clk":"11759566399","pt":1722480562024,"mc":[{"id":"1.231242812","rc":[{"batl":[[0,2.04,18.5]],"ltp":2.0,"tv":3790.12,"id":2120}]}]}
{"op":"mcm","clk":"11759566607","pt":1722480565418,"mc":[{"id":"1.231242812","rc":[{"batl":[[0,2,9.04],[1,2.02,117.25],[2,2.04,221.48]],"ltp":1.97,"tv":8673.64,"id":424676}]}]}
{"op":"mcm","clk":"11759566799","pt":1722480568651,"mc":[{"id":"1.231242812","rc":[{"batb":[[0,1.97,4],[1,1.96,53.32],[2,1.95,38.9]],"ltp":1.97,"tv":8673.64,"id":424676}]}]}
{"op":"mcm","clk":"11759566883","pt":1722480570248,"mc":[{"id":"1.231242812","rc":[{"batl":[[0,2.04,14.21]],"ltp":2.0,"tv":3790.12,"id":2120}]}]}
{"op":"mcm","clk":"11759568024","pt":1722480587253,"mc":[{"id":"1.231242812","rc":[{"trd":[[1.97,154.99]],"batb":[[0,1.96,53.32],[1,1.95,38.9],[2,1.89,47.24]],"batl":[[0,2,9.55]],"ltp":1.97,"tv":8681.64,"id":424676}],"tv":12471.77}]}
{"op":"mcm","clk":"11759568424","pt":1722480592757,"mc":[{"id":"1.231242812","rc":[{"batl":[[0,2,9.04]],"ltp":1.97,"tv":8681.64,"id":424676}]}]}
{"op":"mcm","clk":"11759568786","pt":1722480598766,"mc":[{"id":"1.231242812","rc":[{"batb":[[0,1.97,4],[1,1.96,53.32],[2,1.95,38.9]],"ltp":1.97,"tv":8681.64,"id":424676}]}]}
{"op":"mcm","clk":"11759654379","pt":1722481974882,"mc":[{"id":"1.231242812","rc":[{"trd":[[1.86,704.04],[1.89,659.08],[1.9,685.58],[1.91,482.41],[2.02,510.88],[2.04,214.17],[2.1,1210.15]],"batb":[[1,1.96,53.34]],"ltp":1.97,"tv":8681.86,"id":424676},{"trd":[[1.98,827.43],[2,569.47],[2.02,523.86],[2.1,276.7],[2.12,125.44]],"ltp":2.0,"tv":3790.26,"id":2120}],"tv":12472.12}]}
{"op":"mcm","clk":"11759688033","pt":1722482527995,"mc":[{"id":"1.231242812","rc":[{"trd":[[1.97,162.99]],"batb":[[0,1.96,53.34],[1,1.95,38.9],[2,1.89,47.27]],"batl":[[0,2,9.55]],"ltp":1.97,"tv":8689.86,"id":424676}],"tv":12480.12}]}
{"op":"mcm","clk":"11759688061","pt":1722482528302,"mc":[{"id":"1.231242812","rc":[{"batl":[[0,2.04,18.5]],"ltp":2.0,"tv":3790.26,"id":2120}]}]}
{"op":"mcm","clk":"11759688779","pt":1722482543834,"mc":[{"id":"1.231242812","rc":[{"batl":[[0,2,9.04]],"ltp":1.97,"tv":8689.86,"id":424676}]}]}
{"op":"mcm","clk":"11759690750","pt":1722482591048,"mc":[{"id":"1.231242812","rc":[{"batb":[[0,1.96,98.42]],"ltp":1.97,"tv":8689.86,"id":424676}]}]}
{"op":"mcm","clk":"11759692006","pt":1722482621083,"mc":[{"id":"1.231242812","rc":[{"batb":[[0,1.96,53.34]],"ltp":1.97,"tv":8689.86,"id":424676}]}]}
{"op":"mcm","clk":"11759694401","pt":1722482667096,"mc":[{"id":"1.231242812","rc":[{"batb":[[0,1.97,9.02],[1,1.96,53.34],[2,1.95,38.9]],"ltp":1.97,"tv":8689.86,"id":424676}]}]}
{"op":"mcm","clk":"11759694467","pt":1722482668329,"mc":[{"id":"1.231242812","rc":[{"batl":[[0,2.04,14.21]],"ltp":2.0,"tv":3790.26,"id":2120}]}]}
{"op":"mcm","clk":"11759695034","pt":1722482679716,"mc":[{"id":"1.231242812","rc":[{"batb":[[0,1.97,13.02]],"batl":[[0,1.99,4],[1,2,9.04],[2,2.02,117.25]],"ltp":1.97,"tv":8689.86,"id":424676}]}]}
{"op":"mcm","clk":"11759695098","pt":1722482681052,"mc":[{"id":"1.231242812","rc":[{"batb":[[1,1.98,4],[2,1.94,39.32]],"ltp":2.0,"tv":3790.26,"id":2120}]}]}
{"op":"mcm","clk":"11759696014","pt":1722482697754,"mc":[{"id":"1.231242812","rc":[{"batb":[[0,1.97,4]],"ltp":1.97,"tv":8689.86,"id":424676}]}]}
{"op":"mcm","clk":"11759697612","pt":1722482728900,"mc":[{"id":"1.231242812","rc":[{"trd":[[1.96,103.44],[1.97,170.99]],"batb":[[0,1.96,16.78],[1,1.95,38.9],[2,1.89,47.27]],"ltp":1.96,"tv":8770.99,"id":424676}],"tv":12561.26}]}
{"op":"mcm","clk":"11759697645","pt":1722482729471,"mc":[{"id":"1.231242812","rc":[{"batl":[[0,1.99,9.4]],"ltp":1.96,"tv":8770.99,"id":424676},{"batl":[[0,2.04,10.6]],"ltp":2.0,"tv":3790.26,"id":2120}]}]}
{"op":"mcm","clk":"11759698023","pt":1722482736366,"mc":[{"id":"1.231242812","rc":[{"batb":[[0,1.95,38.9],[1,1.89,65.07],[2,1.71,16.34]],"ltp":1.96,"tv":8770.99,"id":424676}]}]}
{"op":"mcm","clk":"11759698226","pt":1722482740173,"mc":[{"id":"1.231242812","rc":[{"batb":[[0,1.96,4],[1,1.95,38.9],[2,1.89,65.07]],"ltp":1.96,"tv":8770.99,"id":424676}]}]}
{"op":"mcm","clk":"11759720162","pt":1722483147169,"mc":[{"id":"1.231242812","rc":[{"trd":[[1.96,121.15]],"batb":[[0,1.95,38.9],[1,1.89,65.07],[2,1.71,16.34]],"ltp":1.96,"tv":8788.7,"id":424676},{"trd":[[2.04,124.77]],"batl":[[0,2.04,1.26]],"ltp":2.04,"tv":3799.59,"id":2120}],"tv":12588.3}]}
{"op":"mcm","clk":"11759720195","pt":1722483147894,"mc":[{"id":"1.231242812","rc":[{"batb":[[0,1.96,4],[1,1.95,38.9],[2,1.89,65.07]],"ltp":1.96,"tv":8788.7,"id":424676},{"batl":[[0,2.04,4]],"ltp":2.04,"tv":3799.59,"id":2120}]}]}
{"op":"mcm","clk":"11759720308","pt":1722483150061,"mc":[{"id":"1.231242812","rc":[{"batb":[[0,2.02,1.74],[1,2,4],[2,1.98,4]],"ltp":2.04,"tv":3799.59,"id":2120}]}]}
{"op":"mcm","clk":"11759751317","pt":1722483811815,"mc":[{"id":"1.231242812","rc":[{"trd":[[2.04,126.77]],"batl":[[0,2.04,3]],"ltp":2.04,"tv":3801.59,"id":2120}],"tv":12590.3}]}
{"op":"mcm","clk":"11759751537","pt":1722483819530,"mc":[{"id":"1.231242812","rc":[{"trd":[[2.02,525.86]],"batb":[[0,2,4.73],[1,1.98,4],[2,1.94,39.32]],"ltp":2.02,"tv":3803.6,"id":2120}],"tv":12592.3}]}
{"op":"mcm","clk":"11759751618","pt":1722483822099,"mc":[{"id":"1.231242812","rc":[{"batb":[[0,2,4]],"ltp":2.02,"tv":3803.6,"id":2120}]}]}
{"op":"mcm","clk":"11759855181","pt":1722487374868,"mc":[{"id":"1.231242812","rc":[{"trd":[[1.79,41.7],[1.8,600.3],[1.85,28.82],[1.86,704.06],[1.89,658.95],[1.9,685.58],[1.91,482.43],[1.95,127.06],[1.96,121.14],[1.97,171.01],[1.99,482.96],[2,1225.98],[2.02,510.85],[2.04,214.02],[2.08,40.06],[2.1,1210.44],[2.12,51.39],[2.16,6.74],[2.18,64.94]],"batb":[[2,1.89,64.98]],"batl":[[0,1.99,9.4],[1,2,9.04]],"ltp":1.96,"tv":8789.04,"id":424676},{"trd":[[1.84,38.84],[1.86,46.65],[1.98,827.5],[2,569.46],[2.02,525.91],[2.04,126.84],[2.06,101.31],[2.08,383.75],[2.1,276.75],[2.12,125.48],[2.14,61.09],[2.18,14.93],[2.22,12.53]],"ltp":2.02,"tv":3804.11,"id":2120}],"tv":12593.15}]}
{"op":"mcm","clk":"11760037797","pt":1722492774853,"mc":[{"id":"1.231242812","rc":[{"trd":[[1.79,41.69],[1.8,600.25],[1.85,28.81],[1.86,704.15],[1.89,659.09],[1.9,685.6],[1.91,482.43],[1.95,127.05],[1.96,121.16],[1.97,171],[1.99,482.95],[2,1225.97],[2.02,510.88],[2.04,214.17],[2.08,40.06],[2.1,1210.37],[2.12,51.39],[2.16,6.74],[2.18,64.94]],"batb":[[2,1.89,65.07]],"ltp":1.96,"tv":8789.34,"id":424676},{"trd":[[1.84,38.84],[1.86,46.65],[1.98,827.54],[2,569.6],[2.02,525.94],[2.04,126.82],[2.06,101.3],[2.08,383.72],[2.1,276.75],[2.12,125.49],[2.14,61.08],[2.18,14.93],[2.22,12.53]],"ltp":2.02,"tv":3804.23,"id":2120}],"tv":12593.58}]}
{"op":"mcm","clk":"11760046217","pt":1722492851752,"mc":[{"id":"1.231242812","rc":[{"trd":[[2,572.3]],"batb":[[0,2,2.65]],"ltp":2.0,"tv":3806.93,"id":2120}],"tv":12596.28}]}
{"op":"mcm","clk":"11760046238","pt":1722492852468,"mc":[{"id":"1.231242812","rc":[{"batl":[[0,1.99,5.4]],"ltp":1.96,"tv":8789.34,"id":424676}]}]}
{"op":"mcm","clk":"11760046508","pt":1722492859648,"mc":[{"id":"1.231242812","rc":[{"batl":[[0,1.99,9.4]],"ltp":1.96,"tv":8789.34,"id":424676}]}]}
{"op":"mcm","clk":"11760046537","pt":1722492860672,"mc":[{"id":"1.231242812","rc":[{"batl":[[1,2,14.41]],"ltp":1.96,"tv":8789.34,"id":424676}]}]}
{"op":"mcm","clk":"11760096203","pt":1722494332757,"mc":[{"id":"1.231242812","rc":[{"batb":[[2,1.9,180]],"ltp":1.96,"tv":8789.34,"id":424676}]}]}
{"op":"mcm","clk":"11760098568","pt":1722494400130,"mc":[{"id":"1.231242812","rc":[{"batb":[[1,1.95,55.68]],"ltp":1.96,"tv":8789.34,"id":424676}]}]}
{"op":"mcm","clk":"11760263469","pt":1722498174839,"mc":[{"id":"1.231242812","rc":[{"trd":[[1.79,41.76],[1.8,600.91],[1.84,4],[1.85,28.88],[1.86,705.25],[1.87,130.22],[1.89,659.4],[1.9,685.88],[1.91,482.54],[1.95,127.08],[1.96,121.27],[1.97,171.07],[1.99,483.02],[2,1226.13],[2.02,510.94],[2.04,214.42],[2.08,40.1],[2.1,1211.59],[2.12,51.42],[2.16,6.76],[2.18,64.97]],"batb":[[1,1.95,55.72]],"batl":[[0,1.99,9.41],[1,2,14.43]],"ltp":1.96,"tv":8794.02,"id":424676},{"trd":[[1.84,38.88],[1.86,46.69],[1.98,828.54],[2,573.75],[2.02,526.47],[2.04,127.06],[2.06,101.52],[2.08,384.12],[2.1,277.04],[2.12,125.82],[2.14,61.21],[2.18,14.96],[2.22,12.56]],"ltp":2.0,"tv":3811.68,"id":2120}],"tv":12605.7}]}
{"op":"mcm","clk":"11760332151","pt":1722499460843,"mc":[{"id":"1.231242812","rc":[{"trd":[[1.79,41.76],[1.8,600.88],[1.84,4.01],[1.85,28.89],[1.86,705.6],[1.89,659.46],[1.9,685.99],[1.91,482.56],[1.95,127.08],[1.96,121.27],[1.97,171.07],[1.99,483.02],[2,1226.12],[2.02,510.94],[2.04,214.45],[2.08,40.11],[2.1,1211.55],[2.12,51.42],[2.18,64.97]],"batb":[[1,1.95,55.73],[2,1.92,180]],"ltp":1.96,"tv":8794.52,"id":424676},{"trd":[[1.84,38.88],[1.86,46.69],[1.98,828.83],[2,574.36],[2.02,526.55],[2.04,127.05],[2.06,101.51],[2.08,384.11],[2.1,277.04],[2.12,125.89],[2.14,61.21],[2.18,14.96],[2.22,12.56]],"ltp":2.0,"tv":3812.68,"id":2120}],"tv":12607.21}]}
{"op":"mcm","clk":"11760333045","pt":1722499475570,"mc":[{"id":"1.231242812","rc":[{"trd":[[2,578.36]],"batb":[[0,1.98,4.65],[1,1.94,39.32],[2,1.9,163.18]],"ltp":2.0,"tv":3816.68,"id":2120}],"tv":12611.21}]}
{"op":"mcm","clk":"11760457167","pt":1722501731488,"mc":[{"id":"1.231242812","rc":[{"batb":[[1,1.95,16.83]],"ltp":1.96,"tv":8794.52,"id":424676},{"batb":[[1,1.9,163.18],[2,1.85,231.17]],"ltp":2.0,"tv":3816.68,"id":2120}]}]}
{"op":"mcm","clk":"11760458123","pt":1722501746077,"mc":[{"id":"1.231242812","rc":[{"batb":[[0,1.92,180],[1,1.9,180],[2,1.89,47.39]],"ltp":1.96,"tv":8794.52,"id":424676}]}]}
{"op":"mcm","clk":"11760458558","pt":1722501754188,"mc":[{"id":"1.231242812","rc":[{"batl":[[0,2.08,4],[1,2.1,4]],"ltp":2.0,"tv":3816.68,"id":2120}]}]}
{"op":"mcm","clk":"11760459918","pt":1722501778025,"mc":[{"id":"1.231242812","rc":[{"batl":[[0,2.08,15.64]],"ltp":2.0,"tv":3816.68,"id":2120}]}]}
{"op":"mcm","clk":"11760462910","pt":1722501840934,"mc":[{"id":"1.231242812","rc":[{"batb":[[0,1.92,197.34]],"ltp":1.96,"tv":8794.52,"id":424676}]}]}
{"op":"mcm","clk":"11760467618","pt":1722501927527,"mc":[{"id":"1.231242812","rc":[{"batb":[[0,1.93,10.52],[1,1.92,197.34],[2,1.9,180]],"ltp":1.96,"tv":8794.52,"id":424676}]}]}
{"op":"mcm","clk":"11760468065","pt":1722501935803,"mc":[{"id":"1.231242812","rc":[{"batb":[[0,1.93,14.52]],"ltp":1.96,"tv":8794.52,"id":424676}]}]}
{"op":"mcm","clk":"11760516479","pt":1722502800966,"mc":[{"id":"1.231242812","rc":[{"batb":[[0,1.99,10.65],[1,1.98,4],[2,1.9,163.18]],"ltp":2.0,"tv":3816.68,"id":2120}]}]}
{"op":"mcm","clk":"11760516696","pt":1722502804437,"mc":[{"id":"1.231242812","rc":[{"batb":[[0,1.98,4.65],[1,1.9,163.18],[2,1.85,231.17]],"ltp":2.0,"tv":3816.68,"id":2120}]}]}
{"op":"mcm","clk":"11760516841","pt":1722502806754,"mc":[{"id":"1.231242812","rc":[{"trd":[[1.79,41.73],[1.8,600.63],[1.84,4.01],[1.85,28.87],[1.86,705.76],[1.89,659.48],[1.9,686.04],[1.91,482.53],[1.95,127.07],[1.96,121.25],[1.97,171.04],[1.99,482.99],[2,1226.06],[2.02,510.95],[2.04,214.46],[2.08,40.09],[2.1,1211.1],[2.12,51.41],[2.16,6.75],[2.18,64.96]],"batb":[[0,1.93,14.51],[1,1.92,197.34]],"batl":[[0,1.99,9.41],[1,2,14.42]],"ltp":1.96,"tv":8793.8,"id":424676},{"trd":[[1.84,38.86],[1.86,46.67],[1.98,828.83],[2,578.61],[2.02,526.47],[2.04,126.96],[2.06,101.43],[2.08,383.95],[2.1,276.95],[2.12,125.87],[2.14,61.15],[2.18,14.95],[2.22,12.55]],"batb":[[0,1.99,10.65],[1,1.98,4],[2,1.9,163.18]],"batl":[[0,2.08,15.64]],"ltp":2.0,"tv":3816.31,"id":2120}],"tv":12610.11}]}
{"op":"mcm","clk":"11760517099","pt":1722502810151,"mc":[{"id":"1.231242812","rc":[{"batb":[[0,1.98,4.65],[1,1.9,163.18],[2,1.85,231.17]],"ltp":2.0,"tv":3816.31,"id":2120}]}]}
{"op":"mcm","clk":"11760517244","pt":1722502812572,"mc":[{"id":"1.231242812","rc":[{"batb":[[0,1.99,10.65],[1,1.98,4],[2,1.9,163.18]],"ltp":2.0,"tv":3816.31,"id":2120}]}]}
{"op":"mcm","clk":"11760517441","pt":1722502815766,"mc":[{"id":"1.231242812","rc":[{"batb":[[0,1.98,4.65],[1,1.9,163.18],[2,1.85,231.17]],"ltp":2.0,"tv":3816.31,"id":2120}]}]}
{"op":"mcm","clk":"11760517607","pt":1722502818486,"mc":[{"id":"1.231242812","rc":[{"batb":[[0,1.99,10.65],[1,1.98,4],[2,1.9,163.18]],"ltp":2.0,"tv":3816.31,"id":2120}]}]}
{"op":"mcm","clk":"11760517927","pt":1722502823994,"mc":[{"id":"1.231242812","rc":[{"batb":[[0,1.98,4.65],[1,1.9,163.18],[2,1.85,231.17]],"ltp":2.0,"tv":3816.31,"id":2120}]}]}
{"op":"mcm","clk":"11760518041","pt":1722502826356,"mc":[{"id":"1.231242812","rc":[{"batb":[[0,1.99,10.65],[1,1.98,4],[2,1.9,163.18]],"ltp":2.0,"tv":3816.31,"id":2120}]}]}
{"op":"mcm","clk":"11760518219","pt":1722502829796,"mc":[{"id":"1.231242812","rc":[{"batb":[[0,1.98,4.65],[1,1.9,163.18],[2,1.85,231.17]],"ltp":2.0,"tv":3816.31,"id":2120}]}]}
{"op":"mcm","clk":"11760518319","pt":1722502832258,"mc":[{"id":"1.231242812","rc":[{"batb":[[0,1.99,10.65],[1,1.98,4],[2,1.9,163.18]],"ltp":2.0,"tv":3816.31,"id":2120}]}]}
{"op":"mcm","clk":"11760518487","pt":1722502835699,"mc":[{"id":"1.231242812","rc":[{"batb":[[0,1.98,4.65],[1,1.9,163.18],[2,1.85,231.17]],"ltp":2.0,"tv":3816.31,"id":2120}]}]}
{"op":"mcm","clk":"11760518659","pt":1722502838298,"mc":[{"id":"1.231242812","rc":[{"batb":[[0,1.99,10.65],[1,1.98,4],[2,1.9,163.18]],"ltp":2.0,"tv":3816.31,"id":2120}]}]}
{"op":"mcm","clk":"11760518849","pt":1722502841514,"mc":[{"id":"1.231242812","rc":[{"batb":[[0,1.98,4.65],[1,1.9,163.18],[2,1.85,231.17]],"ltp":2.0,"tv":3816.31,"id":2120}]}]}
{"op":"mcm","clk":"11760518978","pt":1722502843688,"mc":[{"id":"1.231242812","rc":[{"batb":[[0,1.99,10.65],[1,1.98,4],[2,1.9,163.18]],"ltp":2.0,"tv":3816.31,"id":2120}]}]}
{"op":"mcm","clk":"11760519224","pt":1722502848223,"mc":[{"id":"1.231242812","rc":[{"batb":[[0,1.98,4.65],[1,1.9,163.18],[2,1.85,231.17]],"ltp":2.0,"tv":3816.31,"id":2120}]}]}
{"op":"mcm","clk":"11760519439","pt":1722502852128,"mc":[{"id":"1.231242812","rc":[{"batb":[[0,1.99,10.65],[1,1.98,4],[2,1.9,163.18]],"ltp":2.0,"tv":3816.31,"id":2120}]}]}
{"op":"mcm","clk":"11760519604","pt":1722502855418,"mc":[{"id":"1.231242812","rc":[{"batb":[[0,1.98,4.65],[1,1.9,163.18],[2,1.85,231.17]],"ltp":2.0,"tv":3816.31,"id":2120}]}]}
{"op":"mcm","clk":"11760519718","pt":1722502857833,"mc":[{"id":"1.231242812","rc":[{"batb":[[0,1.99,10.65],[1,1.98,4],[2,1.9,163.18]],"ltp":2.0,"tv":3816.31,"id":2120}]}]}
{"op":"mcm","clk":"11760519880","pt":1722502861032,"mc":[{"id":"1.231242812","rc":[{"batb":[[0,1.98,4.65],[1,1.9,163.18],[2,1.85,231.17]],"ltp":2.0,"tv":3816.31,"id":2120}]}]}
{"op":"mcm","clk":"11760520021","pt":1722502863412,"mc":[{"id":"1.231242812","rc":[{"batb":[[0,1.99,10.65],[1,1.98,4],[2,1.9,163.18]],"ltp":2.0,"tv":3816.31,"id":2120}]}]}
{"op":"mcm","clk":"11760520322","pt":1722502869020,"mc":[{"id":"1.231242812","rc":[{"batb":[[0,1.98,4.65],[1,1.9,163.18],[2,1.85,231.17]],"ltp":2.0,"tv":3816.31,"id":2120}]}]}
{"op":"mcm","clk":"11760520453","pt":1722502871328,"mc":[{"id":"1.231242812","rc":[{"batb":[[0,1.99,10.65],[1,1.98,4],[2,1.9,163.18]],"ltp":2.0,"tv":3816.31,"id":2120}]}]}
{"op":"mcm","clk":"11760520652","pt":1722502874829,"mc":[{"id":"1.231242812","rc":[{"batb":[[0,1.98,4.65],[1,1.9,163.18],[2,1.85,231.17]],"ltp":2.0,"tv":3816.31,"id":2120}]}]}
{"op":"mcm","clk":"11760520789","pt":1722502877247,"mc":[{"id":"1.231242812","rc":[{"batb":[[0,1.99,10.65],[1,1.98,4],[2,1.9,163.18]],"ltp":2.0,"tv":3816.31,"id":2120}]}]}
{"op":"mcm","clk":"11760520969","pt":1722502880545,"mc":[{"id":"1.231242812","rc":[{"batb":[[0,1.98,4.65],[1,1.9,163.18],[2,1.85,231.17]],"ltp":2.0,"tv":3816.31,"id":2120}]}]}
{"op":"mcm","clk":"11760521072","pt":1722502882751,"mc":[{"id":"1.231242812","rc":[{"batb":[[0,1.99,10.65],[1,1.98,4],[2,1.9,163.18]],"ltp":2.0,"tv":3816.31,"id":2120}]}]}
{"op":"mcm","clk":"11760521214","pt":1722502886043,"mc":[{"id":"1.231242812","rc":[{"batb":[[0,1.98,4.65],[1,1.9,163.18],[2,1.85,231.17]],"ltp":2.0,"tv":3816.31,"id":2120}]}]}
{"op":"mcm","clk":"11760521383","pt":1722502889637,"mc":[{"id":"1.231242812","rc":[{"batb":[[0,1.99,10.65],[1,1.98,4],[2,1.9,163.18]],"ltp":2.0,"tv":3816.31,"id":2120}]}]}
{"op":"mcm","clk":"11760521573","pt":1722502892926,"mc":[{"id":"1.231242812","rc":[{"batb":[[0,1.98,4.65],[1,1.9,163.18],[2,1.85,231.17]],"ltp":2.0,"tv":3816.31,"id":2120}]}]}
{"op":"mcm","clk":"11760521688","pt":1722502895342,"mc":[{"id":"1.231242812","rc":[{"batb":[[0,1.99,10.65],[1,1.98,4],[2,1.9,163.18]],"ltp":2.0,"tv":3816.31,"id":2120}]}]}
{"op":"mcm","clk":"11760521852","pt":1722502898753,"mc":[{"id":"1.231242812","rc":[{"batb":[[0,1.98,4.65],[1,1.9,163.18],[2,1.85,231.17]],"ltp":2.0,"tv":3816.31,"id":2120}]}]}
{"op":"mcm","clk":"11760521960","pt":1722502901058,"mc":[{"id":"1.231242812","rc":[{"batb":[[0,1.99,10.65],[1,1.98,4],[2,1.9,163.18]],"ltp":2.0,"tv":3816.31,"id":2120}]}]}
{"op":"mcm","clk":"11760522104","pt":1722502904163,"mc":[{"id":"1.231242812","rc":[{"batb":[[0,1.98,4.65],[1,1.9,163.18],[2,1.85,231.17]],"ltp":2.0,"tv":3816.31,"id":2120}]}]}
{"op":"mcm","clk":"11760522244","pt":1722502906842,"mc":[{"id":"1.231242812","rc":[{"batb":[[0,1.99,10.65],[1,1.98,4],[2,1.9,163.18]],"ltp":2.0,"tv":3816.31,"id":2120}]}]}
{"op":"mcm","clk":"11760522432","pt":1722502910250,"mc":[{"id":"1.231242812","rc":[{"batb":[[0,1.98,4.65],[1,1.9,163.18],[2,1.85,231.17]],"ltp":2.0,"tv":3816.31,"id":2120}]}]}
{"op":"mcm","clk":"11760522570","pt":1722502912769,"mc":[{"id":"1.231242812","rc":[{"batb":[[0,1.99,10.65],[1,1.98,4],[2,1.9,163.18]],"ltp":2.0,"tv":3816.31,"id":2120}]}]}
{"op":"mcm","clk":"11760522696","pt":1722502916049,"mc":[{"id":"1.231242812","rc":[{"batb":[[0,1.98,4.65],[1,1.9,163.18],[2,1.85,231.17]],"ltp":2.0,"tv":3816.31,"id":2120}]}]}
{"op":"mcm","clk":"11760522799","pt":1722502918356,"mc":[{"id":"1.231242812","rc":[{"batb":[[0,1.99,10.65],[1,1.98,4],[2,1.9,163.18]],"ltp":2.0,"tv":3816.31,"id":2120}]}]}
{"op":"mcm","clk":"11760523002","pt":1722502922170,"mc":[{"id":"1.231242812","rc":[{"batb":[[0,1.98,4.65],[1,1.9,163.18],[2,1.85,231.17]],"ltp":2.0,"tv":3816.31,"id":2120}]}]}
{"op":"mcm","clk":"11760523227","pt":1722502925874,"mc":[{"id":"1.231242812","rc":[{"batb":[[0,1.99,10.65],[1,1.98,4],[2,1.9,163.18]],"ltp":2.0,"tv":3816.31,"id":2120}]}]}
{"op":"mcm","clk":"11760523535","pt":1722502930771,"mc":[{"id":"1.231242812","rc":[{"batb":[[0,1.98,4.65],[1,1.9,163.18],[2,1.85,231.17]],"ltp":2.0,"tv":3816.31,"id":2120}]}]}
{"op":"mcm","clk":"11760523708","pt":1722502934672,"mc":[{"id":"1.231242812","rc":[{"batb":[[0,1.99,10.65],[1,1.98,4],[2,1.9,163.18]],"ltp":2.0,"tv":3816.31,"id":2120}]}]}
{"op":"mcm","clk":"11760523863","pt":1722502938076,"mc":[{"id":"1.231242812","rc":[{"batb":[[0,1.98,4.65],[1,1.9,163.18],[2,1.85,231.17]],"ltp":2.0,"tv":3816.31,"id":2120}]}]}
{"op":"mcm","clk":"11760524010","pt":1722502941106,"mc":[{"id":"1.231242812","rc":[{"batb":[[0,1.99,10.65],[1,1.98,4],[2,1.9,163.18]],"ltp":2.0,"tv":3816.31,"id":2120}]}]}
{"op":"mcm","clk":"11760524168","pt":1722502944298,"mc":[{"id":"1.231242812","rc":[{"batb":[[0,1.98,4.65],[1,1.9,163.18],[2,1.85,231.17]],"ltp":2.0,"tv":3816.31,"id":2120}]}]}
{"op":"mcm","clk":"11760524323","pt":1722502947895,"mc":[{"id":"1.231242812","rc":[{"batb":[[0,1.99,10.65],[1,1.98,4],[2,1.9,163.18]],"ltp":2.0,"tv":3816.31,"id":2120}]}]}
{"op":"mcm","clk":"11760524523","pt":1722502952612,"mc":[{"id":"1.231242812","rc":[{"batb":[[0,1.98,4.65],[1,1.9,163.18],[2,1.85,231.17]],"ltp":2.0,"tv":3816.31,"id":2120}]}]}
{"op":"mcm","clk":"11760524666","pt":1722502955898,"mc":[{"id":"1.231242812","rc":[{"batb":[[0,1.99,10.65],[1,1.98,4],[2,1.9,163.18]],"ltp":2.0,"tv":3816.31,"id":2120}]}]}
{"op":"mcm","clk":"11760524800","pt":1722502959238,"mc":[{"id":"1.231242812","rc":[{"batb":[[0,1.98,4.65],[1,1.9,163.18],[2,1.85,231.17]],"ltp":2.0,"tv":3816.31,"id":2120}]}]}
{"op":"mcm","clk":"11760524956","pt":1722502962426,"mc":[{"id":"1.231242812","rc":[{"batb":[[0,1.99,10.65],[1,1.98,4],[2,1.9,163.18]],"ltp":2.0,"tv":3816.31,"id":2120}]}]}
{"op":"mcm","clk":"11760525134","pt":1722502965829,"mc":[{"id":"1.231242812","rc":[{"batb":[[0,1.98,4.65],[1,1.9,163.18],[2,1.85,231.17]],"ltp":2.0,"tv":3816.31,"id":2120}]}]}
{"op":"mcm","clk":"11760525242","pt":1722502968154,"mc":[{"id":"1.231242812","rc":[{"batb":[[0,1.99,10.65],[1,1.98,4],[2,1.9,163.18]],"ltp":2.0,"tv":3816.31,"id":2120}]}]}
{"op":"mcm","clk":"11760525405","pt":1722502971635,"mc":[{"id":"1.231242812","rc":[{"batb":[[0,1.98,4.65],[1,1.9,163.18],[2,1.85,231.17]],"ltp":2.0,"tv":3816.31,"id":2120}]}]}
{"op":"mcm","clk":"11760525505","pt":1722502973838,"mc":[{"id":"1.231242812","rc":[{"batb":[[0,1.99,10.65],[1,1.98,4],[2,1.9,163.18]],"ltp":2.0,"tv":3816.31,"id":2120}]}]}
{"op":"mcm","clk":"11760525662","pt":1722502977355,"mc":[{"id":"1.231242812","rc":[{"batb":[[0,1.98,4.65],[1,1.9,163.18],[2,1.85,231.17]],"ltp":2.0,"tv":3816.31,"id":2120}]}]}
{"op":"mcm","clk":"11760525772","pt":1722502979528,"mc":[{"id":"1.231242812","rc":[{"batb":[[0,1.99,10.65],[1,1.98,4],[2,1.9,163.18]],"ltp":2.0,"tv":3816.31,"id":2120}]}]}
{"op":"mcm","clk":"11760525944","pt":1722502982823,"mc":[{"id":"1.231242812","rc":[{"batb":[[0,1.98,4.65],[1,1.9,163.18],[2,1.85,231.17]],"ltp":2.0,"tv":3816.31,"id":2120}]}]}
{"op":"mcm","clk":"11760526060","pt":1722502985242,"mc":[{"id":"1.231242812","rc":[{"batb":[[0,1.99,10.65],[1,1.98,4],[2,1.9,163.18]],"ltp":2.0,"tv":3816.31,"id":2120}]}]}
{"op":"mcm","clk":"11760526298","pt":1722502989238,"mc":[{"id":"1.231242812","rc":[{"trd":[[1.99,501.31]],"batl":[[0,2,14.67],[1,2.02,117.25],[2,2.04,221.48]],"ltp":1.99,"tv":8812.11,"id":424676},{"batb":[[0,1.98,4.65],[1,1.9,163.18],[2,1.85,231.17]],"ltp":2.0,"tv":3816.31,"id":2120}],"tv":12628.43}]}
{"op":"mcm","clk":"11760526312","pt":1722502989550,"mc":[{"id":"1.231242812","rc":[{"batb":[[0,1.93,29.43]],"ltp":1.99,"tv":8812.11,"id":424676},{"batb":[[0,1.99,9.93],[1,1.98,4],[2,1.9,163.18]],"ltp":2.0,"tv":3816.31,"id":2120}]}]}
{"op":"mcm","clk":"11760526393","pt":1722502990842,"mc":[{"id":"1.231242812","rc":[{"batb":[[0,1.94,10],[1,1.93,29.43],[2,1.92,197.34]],"ltp":1.99,"tv":8812.11,"id":424676},{"batb":[[0,2,10.65],[1,1.99,9.28],[2,1.98,4]],"ltp":2.0,"tv":3816.31,"id":2120}]}]}
{"op":"mcm","clk":"11760526446","pt":1722502992139,"mc":[{"id":"1.231242812","rc":[{"batb":[[1,1.98,4],[2,1.9,163.18]],"ltp":2.0,"tv":3816.31,"id":2120}]}]}
{"op":"mcm","clk":"11760526566","pt":1722502994146,"mc":[{"id":"1.231242812","rc":[{"trd":[[1.99,509.55]],"batb":[[0,1.94,14]],"batl":[[0,2,14.55]],"ltp":1.99,"tv":8820.35,"id":424676}],"tv":12636.67}]}
{"op":"mcm","clk":"11760526605","pt":1722502994763,"mc":[{"id":"1.231242812","rc":[{"batb":[[0,1.94,4]],"ltp":1.99,"tv":8820.35,"id":424676}]}]}
{"op":"mcm","clk":"11760526638","pt":1722502995457,"mc":[{"id":"1.231242812","rc":[{"batb":[[0,1.98,4.65],[1,1.9,163.18],[2,1.85,231.17]],"ltp":2.0,"tv":3816.31,"id":2120}]}]}
{"op":"mcm","clk":"11760526720","pt":1722502996972,"mc":[{"id":"1.231242812","rc":[{"batb":[[0,1.95,10],[1,1.94,4],[2,1.93,29.43]],"ltp":1.99,"tv":8820.35,"id":424676},{"batb":[[0,1.99,6.13],[1,1.98,4],[2,1.9,163.18]],"ltp":2.0,"tv":3816.31,"id":2120}]}]}
{"op":"mcm","clk":"11760526768","pt":1722502997748,"mc":[{"id":"1.231242812","rc":[{"batb":[[1,1.93,25.43],[2,1.92,197.34]],"ltp":1.99,"tv":8820.35,"id":424676},{"batb":[[0,2,10.65],[1,1.99,5.48],[2,1.98,4]],"ltp":2.0,"tv":3816.31,"id":2120}]}]}
{"op":"mcm","clk":"11760526811","pt":1722502998772,"mc":[{"id":"1.231242812","rc":[{"batb":[[1,1.98,4],[2,1.9,163.18]],"ltp":2.0,"tv":3816.31,"id":2120}]}]}
{"op":"mcm","clk":"11760526873","pt":1722503000166,"mc":[{"id":"1.231242812","rc":[{"batb":[[0,1.93,25.43],[1,1.92,197.34],[2,1.9,180]],"ltp":1.99,"tv":8820.35,"id":424676}]}]}
{"op":"mcm","clk":"11760526917","pt":1722503001142,"mc":[{"id":"1.231242812","rc":[{"batb":[[0,1.98,4.65],[1,1.9,163.18],[2,1.85,231.17]],"ltp":2.0,"tv":3816.31,"id":2120}]}]}
{"op":"mcm","clk":"11760526985","pt":1722503002478,"mc":[{"id":"1.231242812","rc":[{"batb":[[0,1.94,10],[1,1.93,25.43],[2,1.92,197.34]],"ltp":1.99,"tv":8820.35,"id":424676}]}]}
{"op":"mcm","clk":"11760527100","pt":1722503004788,"mc":[{"id":"1.231242812","rc":[{"batb":[[0,1.99,10.65],[1,1.98,4],[2,1.9,163.18]],"ltp":2.0,"tv":3816.31,"id":2120}]}]}
{"op":"mcm","clk":"11760527261","pt":1722503007669,"mc":[{"id":"1.231242812","rc":[{"batb":[[0,1.93,25.43],[1,1.92,197.34],[2,1.9,180]],"ltp":1.99,"tv":8820.35,"id":424676}]}]}
{"op":"mcm","clk":"11760527310","pt":1722503008961,"mc":[{"id":"1.231242812","rc":[{"batb":[[0,1.98,4.65],[1,1.9,163.18],[2,1.85,231.17]],"ltp":2.0,"tv":3816.31,"id":2120}]}]}
{"op":"mcm","clk":"11760527348","pt":1722503009882,"mc":[{"id":"1.231242812","rc":[{"batb":[[0,1.94,10],[1,1.93,25.43],[2,1.92,197.34]],"ltp":1.99,"tv":8820.35,"id":424676}]}]}
{"op":"mcm","clk":"11760527403","pt":1722503011274,"mc":[{"id":"1.231242812","rc":[{"batb":[[0,1.99,10.65],[1,1.98,4],[2,1.9,163.18]],"ltp":2.0,"tv":3816.31,"id":2120}]}]}
{"op":"mcm","clk":"11760527517","pt":1722503013492,"mc":[{"id":"1.231242812","rc":[{"batb":[[0,1.93,25.43],[1,1.92,197.34],[2,1.9,180]],"ltp":1.99,"tv":8820.35,"id":424676}]}]}
{"op":"mcm","clk":"11760527559","pt":1722503014469,"mc":[{"id":"1.231242812","rc":[{"batb":[[0,1.98,4.65],[1,1.9,163.18],[2,1.85,231.17]],"ltp":2.0,"tv":3816.31,"id":2120}]}]}
{"op":"mcm","clk":"11760527668","pt":1722503017086,"mc":[{"id":"1.231242812","rc":[{"batb":[[0,1.94,10],[1,1.93,25.43],[2,1.92,197.34]],"ltp":1.99,"tv":8820.35,"id":424676},{"batb":[[0,1.99,10.65],[1,1.98,4],[2,1.9,163.18]],"ltp":2.0,"tv":3816.31,"id":2120}]}]}
{"op":"mcm","clk":"11760527842","pt":1722503020335,"mc":[{"id":"1.231242812","rc":[{"batb":[[0,1.93,25.43],[1,1.92,197.34],[2,1.9,180]],"ltp":1.99,"tv":8820.35,"id":424676},{"batb":[[0,1.98,4.65],[1,1.9,163.18],[2,1.85,231.17]],"ltp":2.0,"tv":3816.31,"id":2120}]}]}
{"op":"mcm","clk":"11760528004","pt":1722503023508,"mc":[{"id":"1.231242812","rc":[{"batb":[[0,1.94,10],[1,1.93,25.43],[2,1.92,197.34]],"ltp":1.99,"tv":8820.35,"id":424676},{"batb":[[0,1.99,10.65],[1,1.98,4],[2,1.9,163.18]],"ltp":2.0,"tv":3816.31,"id":2120}]}]}
{"op":"mcm","clk":"11760528065","pt":1722503024595,"mc":[{"id":"1.231242812","rc":[{"trd":[[1.99,517.57]],"batb":[[0,1.94,14]],"batl":[[0,2,14.54]],"ltp":1.99,"tv":8828.37,"id":424676}],"tv":12644.69}]}
{"op":"mcm","clk":"11760528191","pt":1722503026810,"mc":[{"id":"1.231242812","rc":[{"batb":[[0,1.94,4]],"ltp":1.99,"tv":8828.37,"id":424676},{"batb":[[0,1.98,4.65],[1,1.9,163.18],[2,1.85,231.17]],"ltp":2.0,"tv":3816.31,"id":2120}]}]}
{"op":"mcm","clk":"11760528301","pt":1722503029213,"mc":[{"id":"1.231242812","rc":[{"batb":[[0,1.95,10],[1,1.94,4],[2,1.93,25.43]],"ltp":1.99,"tv":8828.37,"id":424676},{"batb":[[0,1.99,10.65],[1,1.98,4],[2,1.9,163.18]],"ltp":2.0,"tv":3816.31,"id":2120}]}]}
{"op":"mcm","clk":"11760528318","pt":1722503029577,"mc":[{"id":"1.231242812","rc":[{"batb":[[1,1.93,25.43],[2,1.92,197.34]],"ltp":1.99,"tv":8828.37,"id":424676}]}]}
{"op":"mcm","clk":"11760528466","pt":1722503032621,"mc":[{"id":"1.231242812","rc":[{"batb":[[0,1.93,25.43],[1,1.92,197.34],[2,1.9,180]],"ltp":1.99,"tv":8828.37,"id":424676},{"batb":[[0,1.98,4.65],[1,1.9,163.18],[2,1.85,231.17]],"ltp":2.0,"tv":3816.31,"id":2120}]}]}
{"op":"mcm","clk":"11760528591","pt":1722503034797,"mc":[{"id":"1.231242812","rc":[{"batb":[[0,1.96,10],[1,1.93,25.43],[2,1.92,197.34]],"ltp":1.99,"tv":8828.37,"id":424676},{"batb":[[0,2,10.65],[1,1.98,4],[2,1.9,163.18]],"ltp":2.0,"tv":3816.31,"id":2120}]}]}
{"op":"mcm","clk":"11760528801","pt":1722503039240,"mc":[{"id":"1.231242812","rc":[{"batb":[[0,1.93,25.43],[1,1.92,197.34],[2,1.9,180]],"ltp":1.99,"tv":8828.37,"id":424676},{"batb":[[0,1.98,4.65],[1,1.9,163.18],[2,1.85,231.17]],"ltp":2.0,"tv":3816.31,"id":2120}]}]}
{"op":"mcm","clk":"11760528852","pt":1722503040110,"mc":[{"id":"1.231242812","rc":[{"trd":[[1.99,525.57]],"ltp":1.99,"tv":8836.37,"id":424676},{"batl":[[0,2.06,4],[1,2.08,15.64],[2,2.1,4]],"ltp":2.0,"tv":3816.31,"id":2120}],"tv":12652.69}]}
{"op":"mcm","clk":"11760528971","pt":1722503042406,"mc":[{"id":"1.231242812","rc":[{"batb":[[0,1.94,10],[1,1.93,25.43],[2,1.92,197.34]],"ltp":1.99,"tv":8836.37,"id":424676},{"batb":[[0,1.99,10.65],[1,1.98,4],[2,1.9,163.18]],"ltp":2.0,"tv":3816.31,"id":2120}]}]}
{"op":"mcm","clk":"11760529127","pt":1722503045916,"mc":[{"id":"1.231242812","rc":[{"batb":[[0,1.93,25.43],[1,1.92,197.34],[2,1.9,180]],"ltp":1.99,"tv":8836.37,"id":424676},{"batb":[[0,1.98,4.65],[1,1.9,163.18],[2,1.85,231.17]],"ltp":2.0,"tv":3816.31,"id":2120}]}]}
{"op":"mcm","clk":"11760529175","pt":1722503046901,"mc":[{"id":"1.231242812","rc":[{"batb":[[0,1.99,9.93],[1,1.98,4],[2,1.9,163.18]],"ltp":2.0,"tv":3816.31,"id":2120}]}]}
{"op":"mcm","clk":"11760529239","pt":1722503048158,"mc":[{"id":"1.231242812","rc":[{"batb":[[0,1.94,10],[1,1.93,25.43],[2,1.92,197.34]],"ltp":1.99,"tv":8836.37,"id":424676}]}]}
{"op":"mcm","clk":"11760529416","pt":1722503051520,"mc":[{"id":"1.231242812","rc":[{"batb":[[0,1.93,25.43],[1,1.92,197.34],[2,1.9,180]],"ltp":1.99,"tv":8836.37,"id":424676}]}]}
{"op":"mcm","clk":"11760529617","pt":1722503055131,"mc":[{"id":"1.231242812","rc":[{"trd":[[1.99,533.57]],"batb":[[0,1.94,4],[1,1.93,25.43],[2,1.92,197.34]],"ltp":1.99,"tv":8844.37,"id":424676},{"batb":[[0,1.98,4.65],[1,1.9,163.18],[2,1.85,231.17]],"ltp":2.0,"tv":3816.31,"id":2120}],"tv":12660.69}]}
{"op":"mcm","clk":"11760529649","pt":1722503055759,"mc":[{"id":"1.231242812","rc":[{"batb":[[0,1.94,14]],"ltp":1.99,"tv":8844.37,"id":424676}]}]}
{"op":"mcm","clk":"11760529721","pt":1722503057111,"mc":[{"id":"1.231242812","rc":[{"batb":[[1,1.93,14.92]],"ltp":1.99,"tv":8844.37,"id":424676},{"batb":[[0,1.99,10.65],[1,1.98,4],[2,1.9,163.18]],"ltp":2.0,"tv":3816.31,"id":2120}]}]}
{"op":"mcm","clk":"11760529749","pt":1722503057628,"mc":[{"id":"1.231242812","rc":[{"batb":[[1,1.92,197.34],[2,1.9,180]],"ltp":1.99,"tv":8844.37,"id":424676}]}]}
{"op":"mcm","clk":"11760529905","pt":1722503060614,"mc":[{"id":"1.231242812","rc":[{"batb":[[0,1.94,4]],"ltp":1.99,"tv":8844.37,"id":424676}]}]}
{"op":"mcm","clk":"11760530002","pt":1722503062233,"mc":[{"id":"1.231242812","rc":[{"batb":[[0,1.93,25.97]],"ltp":1.99,"tv":8844.37,"id":424676},{"batb":[[0,1.98,4.65],[1,1.9,163.18],[2,1.85,231.17]],"ltp":2.0,"tv":3816.31,"id":2120}]}]}
