{"op":"mcm","clk":"11934290379","pt":1724327330224,"mc":[{"id":"1.232135506","marketDefinition":{"bspMarket":false,"turnInPlayEnabled":true,"persistenceEnabled":true,"marketBaseRate":5.0,"eventId":"33516557","eventTypeId":"4","numberOfWinners":1,"bettingType":"ODDS","marketType":"MATCH_ODDS","marketTime":"2024-08-22T23:00:00.000Z","suspendTime":"2024-08-22T23:00:00.000Z","bspReconciled":false,"complete":true,"inPlay":false,"crossMatching":true,"runnersVoidable":false,"numberOfActiveRunners":2,"betDelay":0,"status":"OPEN","runners":[{"status":"ACTIVE","sortPriority":1,"id":72963954,"name":"Trinidad Knight Riders W"},{"status":"ACTIVE","sortPriority":2,"id":47674067,"name":"Barbados Royals W"}],"regulators":["MR_INT"],"countryCode":"GB","discountAllowed":false,"timezone":"GMT","openDate":"2024-08-22T23:00:00.000Z","version":6090771174,"name":"Match Odds","eventName":"Trinidad Knight Riders W v Barbados Royals W"},"rc":[{"batb":[[0,1.03,200],[1,1.02,200],[2,1.01,220]],"ltp":0.0,"tv":0.0,"id":47674067},{"batb":[[0,1.03,200],[1,1.02,200],[2,1.01,220]],"ltp":0.0,"tv":0.0,"id":72963954}]}]}
{"op":"mcm","clk":"11934290521","pt":1724327332773,"mc":[{"id":"1.232135506","marketDefinition":{"bspMarket":false,"turnInPlayEnabled":true,"persistenceEnabled":true,"marketBaseRate":5.0,"eventId":"33516557","eventTypeId":"4","numberOfWinners":1,"bettingType":"ODDS","marketType":"MATCH_ODDS","marketTime":"2024-08-22T23:00:00.000Z","suspendTime":"2024-08-22T23:00:00.000Z","bspReconciled":false,"complete":true,"inPlay":false,"crossMatching":true,"runnersVoidable":false,"numberOfActiveRunners":2,"betDelay":0,"status":"OPEN","runners":[{"status":"ACTIVE","sortPriority":1,"id":72963954,"name":"Trinidad Knight Riders W"},{"status":"ACTIVE","sortPriority":2,"id":47674067,"name":"Barbados Royals W"}],"regulators":["MR_INT"],"countryCode":"GB","discountAllowed":true,"timezone":"GMT","openDate":"2024-08-22T23:00:00.000Z","version":6090771174,"name":"Match Odds","eventName":"Trinidad Knight Riders W v Barbados Royals W"}}]}
{"op":"mcm","clk":"11934307537","pt":1724327673753,"mc":[{"id":"1.232135506","rc":[{"batb":[[0,1.05,200],[1,1.04,250],[2,1.03,533.33]],"ltp":0.0,"tv":0.0,"id":47674067},{"batb":[[0,1.05,200],[1,1.04,250],[2,1.03,533.33]],"ltp":0.0,"tv":0.0,"id":72963954}]}]}
{"op":"mcm","clk":"11934323224","pt":1724327943045,"mc":[{"id":"1.232135506","rc":[{"batb":[[1,1.04,251.53]],"ltp":0.0,"tv":0.0,"id":47674067},{"batb":[[1,1.04,251.53]],"ltp":0.0,"tv":0.0,"id":72963954}]}]}
{"op":"mcm","clk":"11934426208","pt":1724329910734,"mc":[{"id":"1.232135506","rc":[{"batl":[[0,10,95.66]],"ltp":0.0,"tv":0.0,"id":72963954}]}]}
{"op":"mcm","clk":"11934480169","pt":1724330821173,"mc":[{"id":"1.232135506","rc":[{"batb":[[0,1.51,755.03],[1,1.05,200],[2,1.04,251.53]],"ltp":0.0,"tv":0.0,"id":47674067}]}]}
{"op":"mcm","clk":"11934494732","pt":1724331125812,"mc":[{"id":"1.232135506","rc":[{"batl":[[0,3,10]],"ltp":0.0,"tv":0.0,"id":47674067}]}]}
{"op":"mcm","clk":"11934495051","pt":1724331134336,"mc":[{"id":"1.232135506","rc":[{"batl":[[0,2.96,10]],"ltp":0.0,"tv":0.0,"id":47674067}]}]}
{"op":"mcm","clk":"11934501751","pt":1724331291829,"mc":[{"id":"1.232135506","rc":[{"batb":[[0,1.77,6.16],[1,1.05,200],[2,1.04,251.53]],"batl":[[0,2.96,4.11],[1,2.98,4.11]],"ltp":0.0,"tv":0.0,"id":72963954}]}]}
{"op":"mcm","clk":"11934512748","pt":1724331514396,"mc":[{"id":"1.232135506","rc":[{"batb":[[1,1.21,82.85],[2,1.05,200]],"ltp":0.0,"tv":0.0,"id":72963954}]}]}
{"op":"mcm","clk":"11934513281","pt":1724331526529,"mc":[{"id":"1.232135506","rc":[{"batb":[[1,1.21,82.85],[2,1.05,200]],"ltp":0.0,"tv":0.0,"id":47674067}]}]}
{"op":"mcm","clk":"11934545909","pt":1724332116009,"mc":[{"id":"1.232135506","rc":[{"batb":[[0,1.54,112.92],[1,1.51,754.63],[2,1.21,82.92]],"ltp":0.0,"tv":0.0,"id":47674067},{"batb":[[1,1.21,82.92]],"ltp":0.0,"tv":0.0,"id":72963954}]}]}
{"op":"mcm","clk":"11934565965","pt":1724332529772,"mc":[{"id":"1.232135506","rc":[{"batb":[[0,1.55,6.13],[1,1.54,112.92],[2,1.51,754.63]],"ltp":0.0,"tv":0.0,"id":47674067}]}]}
{"op":"mcm","clk":"11934578130","pt":1724332716715,"mc":[{"id":"1.232135506","rc":[{"batl":[[0,2,3.54],[1,2.96,10]],"ltp":0.0,"tv":0.0,"id":47674067}]}]}
{"op":"mcm","clk":"11934580471","pt":1724332759889,"mc":[{"id":"1.232135506","rc":[{"batl":[[0,1.99,5.31]],"ltp":0.0,"tv":0.0,"id":47674067}]}]}
{"op":"mcm","clk":"11934600434","pt":1724333083910,"mc":[{"id":"1.232135506","rc":[{"batb":[[0,1.6,21],[1,1.55,6.13],[2,1.54,112.92]],"ltp":0.0,"tv":0.0,"id":47674067}]}]}
{"op":"mcm","clk":"11934700409","pt":1724334410270,"mc":[{"id":"1.232135506","rc":[{"batb":[[0,1.61,34.27],[1,1.6,21],[2,1.55,6.13]],"ltp":0.0,"tv":0.0,"id":47674067}]}]}
{"op":"mcm","clk":"11934701089","pt":1724334418682,"mc":[{"id":"1.232135506","rc":[{"batb":[[0,1.6,21],[1,1.55,6.13],[2,1.54,112.92]],"ltp":0.0,"tv":0.0,"id":47674067}]}]}
{"op":"mcm","clk":"11934743565","pt":1724335052821,"mc":[{"id":"1.232135506","rc":[{"batl":[[0,1.62,1.14],[1,1.99,5.31],[2,2.96,10]],"ltp":0.0,"tv":0.0,"id":47674067}]}]}
{"op":"mcm","clk":"11934743717","pt":1724335055469,"mc":[{"id":"1.232135506","rc":[{"batl":[[0,1.99,5.31],[1,2.96,10],[2,2.96,0]],"ltp":0.0,"tv":0.0,"id":47674067}]}]}
{"op":"mcm","clk":"11934744546","pt":1724335068170,"mc":[{"id":"1.232135506","rc":[{"batb":[[0,1.97,1.14],[1,1.6,21],[2,1.55,6.13]],"ltp":0.0,"tv":0.0,"id":47674067}]}]}
{"op":"mcm","clk":"11934744665","pt":1724335069925,"mc":[{"id":"1.232135506","rc":[{"batb":[[0,1.6,21],[1,1.55,6.13],[2,1.54,112.92]],"ltp":0.0,"tv":0.0,"id":47674067}]}]}
{"op":"mcm","clk":"11934745485","pt":1724335082171,"mc":[{"id":"1.232135506","rc":[{"batl":[[0,1.62,1.14],[1,1.99,5.31],[2,2.96,10]],"ltp":0.0,"tv":0.0,"id":47674067}]}]}
{"op":"mcm","clk":"11934745623","pt":1724335084271,"mc":[{"id":"1.232135506","rc":[{"batl":[[0,1.99,5.31],[1,2.96,10],[2,2.96,0]],"ltp":0.0,"tv":0.0,"id":47674067}]}]}
{"op":"mcm","clk":"11934747601","pt":1724335112903,"mc":[{"id":"1.232135506","rc":[{"batb":[[0,1.97,1.14],[1,1.6,21],[2,1.55,6.13]],"ltp":0.0,"tv":0.0,"id":47674067}]}]}
{"op":"mcm","clk":"11934747740","pt":1724335115119,"mc":[{"id":"1.232135506","rc":[{"batb":[[0,1.6,21],[1,1.55,6.13],[2,1.54,112.92]],"ltp":0.0,"tv":0.0,"id":47674067}]}]}
{"op":"mcm","clk":"11934749259","pt":1724335139664,"mc":[{"id":"1.232135506","rc":[{"batl":[[0,1.62,1.14],[1,1.99,5.31],[2,2.96,10]],"ltp":0.0,"tv":0.0,"id":47674067}]}]}
{"op":"mcm","clk":"11934749369","pt":1724335141576,"mc":[{"id":"1.232135506","rc":[{"batl":[[0,1.99,5.31],[1,2.96,10],[2,2.96,0]],"ltp":0.0,"tv":0.0,"id":47674067}]}]}
{"op":"mcm","clk":"11934750385","pt":1724335157397,"mc":[{"id":"1.232135506","rc":[{"batb":[[0,1.97,1.14],[1,1.6,21],[2,1.55,6.13]],"ltp":0.0,"tv":0.0,"id":47674067}]}]}
{"op":"mcm","clk":"11934750583","pt":1724335159769,"mc":[{"id":"1.232135506","rc":[{"batb":[[0,1.6,21],[1,1.55,6.13],[2,1.54,112.92]],"ltp":0.0,"tv":0.0,"id":47674067}]}]}
{"op":"mcm","clk":"11934751969","pt":1724335182873,"mc":[{"id":"1.232135506","rc":[{"batl":[[0,1.62,1.14],[1,1.99,5.31],[2,2.96,10]],"ltp":0.0,"tv":0.0,"id":47674067}]}]}
{"op":"mcm","clk":"11934752128","pt":1724335184999,"mc":[{"id":"1.232135506","rc":[{"batl":[[0,1.99,5.31],[1,2.96,10],[2,2.96,0]],"ltp":0.0,"tv":0.0,"id":47674067}]}]}
{"op":"mcm","clk":"11934753210","pt":1724335201306,"mc":[{"id":"1.232135506","rc":[{"batb":[[0,1.97,1.14],[1,1.6,21],[2,1.55,6.13]],"ltp":0.0,"tv":0.0,"id":47674067}]}]}
{"op":"mcm","clk":"11934753384","pt":1724335203337,"mc":[{"id":"1.232135506","rc":[{"batb":[[0,1.6,21],[1,1.55,6.14],[2,1.54,112.77]],"batl":[[0,1.99,5.32]],"ltp":0.0,"tv":0.0,"id":47674067},{"batb":[[0,1.77,6.15]],"batl":[[0,2.96,4.1],[1,2.98,4.1]],"ltp":0.0,"tv":0.0,"id":72963954}]}]}
{"op":"mcm","clk":"11934755043","pt":1724335226742,"mc":[{"id":"1.232135506","rc":[{"batl":[[0,1.62,1.14],[1,1.99,5.32],[2,2.96,10]],"ltp":0.0,"tv":0.0,"id":47674067},{"batb":[[1,1.21,82.81]],"ltp":0.0,"tv":0.0,"id":72963954}]}]}
{"op":"mcm","clk":"11934755172","pt":1724335228845,"mc":[{"id":"1.232135506","rc":[{"batl":[[0,1.99,5.32],[1,2.96,10],[2,2.96,0]],"ltp":0.0,"tv":0.0,"id":47674067}]}]}
{"op":"mcm","clk":"11934756374","pt":1724335245559,"mc":[{"id":"1.232135506","rc":[{"batb":[[0,1.97,1.14],[1,1.6,21],[2,1.55,6.14]],"ltp":0.0,"tv":0.0,"id":47674067}]}]}
{"op":"mcm","clk":"11934756542","pt":1724335247593,"mc":[{"id":"1.232135506","rc":[{"batb":[[0,1.6,21],[1,1.55,6.14],[2,1.54,112.77]],"ltp":0.0,"tv":0.0,"id":47674067}]}]}
{"op":"mcm","clk":"11934758595","pt":1724335275616,"mc":[{"id":"1.232135506","rc":[{"batl":[[0,1.62,1.14],[1,1.99,5.32],[2,2.96,10]],"ltp":0.0,"tv":0.0,"id":47674067}]}]}
{"op":"mcm","clk":"11934758745","pt":1724335277811,"mc":[{"id":"1.232135506","rc":[{"batl":[[0,1.99,5.32],[1,2.96,10],[2,2.96,0]],"ltp":0.0,"tv":0.0,"id":47674067}]}]}
{"op":"mcm","clk":"11934759834","pt":1724335294234,"mc":[{"id":"1.232135506","rc":[{"batb":[[0,1.97,1.14],[1,1.6,21],[2,1.55,6.14]],"ltp":0.0,"tv":0.0,"id":47674067}]}]}
{"op":"mcm","clk":"11934760017","pt":1724335296857,"mc":[{"id":"1.232135506","rc":[{"batb":[[0,1.6,21],[1,1.55,6.14],[2,1.54,112.77]],"ltp":0.0,"tv":0.0,"id":47674067}]}]}
{"op":"mcm","clk":"11934761367","pt":1724335318767,"mc":[{"id":"1.232135506","rc":[{"batl":[[0,1.62,1.14],[1,1.99,5.32],[2,2.96,10]],"ltp":0.0,"tv":0.0,"id":47674067}]}]}
{"op":"mcm","clk":"11934761495","pt":1724335320679,"mc":[{"id":"1.232135506","rc":[{"batl":[[0,1.99,5.32],[1,2.96,10],[2,2.96,0]],"ltp":0.0,"tv":0.0,"id":47674067}]}]}
{"op":"mcm","clk":"11934762630","pt":1724335336584,"mc":[{"id":"1.232135506","rc":[{"batb":[[0,1.97,1.14],[1,1.6,21],[2,1.55,6.14]],"ltp":0.0,"tv":0.0,"id":47674067}]}]}
{"op":"mcm","clk":"11934762782","pt":1724335338709,"mc":[{"id":"1.232135506","rc":[{"batb":[[0,1.6,21],[1,1.55,6.14],[2,1.54,112.77]],"ltp":0.0,"tv":0.0,"id":47674067}]}]}
{"op":"mcm","clk":"11934765513","pt":1724335355122,"mc":[{"id":"1.232135506","rc":[{"batl":[[0,1.62,1.14],[1,1.99,5.32],[2,2.96,10]],"ltp":0.0,"tv":0.0,"id":47674067}]}]}
{"op":"mcm","clk":"11934765662","pt":1724335357596,"mc":[{"id":"1.232135506","rc":[{"batl":[[0,1.99,5.32],[1,2.96,10],[2,2.96,0]],"ltp":0.0,"tv":0.0,"id":47674067}]}]}
{"op":"mcm","clk":"11934766830","pt":1724335373923,"mc":[{"id":"1.232135506","rc":[{"batb":[[0,1.97,1.14],[1,1.6,21],[2,1.55,6.14]],"ltp":0.0,"tv":0.0,"id":47674067}]}]}
{"op":"mcm","clk":"11934766938","pt":1724335375633,"mc":[{"id":"1.232135506","rc":[{"batb":[[0,1.6,21],[1,1.55,6.14],[2,1.54,112.77]],"ltp":0.0,"tv":0.0,"id":47674067}]}]}
{"op":"mcm","clk":"11934773084","pt":1724335453810,"mc":[{"id":"1.232135506","rc":[{"batl":[[0,1.62,1.14],[1,1.99,5.32],[2,2.96,10]],"ltp":0.0,"tv":0.0,"id":47674067}]}]}
{"op":"mcm","clk":"11934773219","pt":1724335456034,"mc":[{"id":"1.232135506","rc":[{"batl":[[0,1.99,5.32],[1,2.96,10],[2,2.96,0]],"ltp":0.0,"tv":0.0,"id":47674067}]}]}
{"op":"mcm","clk":"11934789359","pt":1724335661298,"mc":[{"id":"1.232135506","rc":[{"batb":[[2,1.04,1.53]],"ltp":0.0,"tv":0.0,"id":72963954}]}]}
{"op":"mcm","clk":"11934798059","pt":1724335779633,"mc":[{"id":"1.232135506","rc":[{"batb":[[0,1.61,43.93],[1,1.6,21],[2,1.55,6.14]],"ltp":0.0,"tv":0.0,"id":47674067}]}]}
{"op":"mcm","clk":"11934798937","pt":1724335790737,"mc":[{"id":"1.232135506","rc":[{"trd":[[1.61,87.86]],"batb":[[0,1.6,21],[1,1.55,6.14],[2,1.54,112.77]],"batl":[[0,1.99,6.06]],"ltp":1.61,"tv":87.86,"id":47674067}],"tv":87.86}]}
{"op":"mcm","clk":"11934799184","pt":1724335793747,"mc":[{"id":"1.232135506","rc":[{"batl":[[0,1.99,5.32]],"ltp":1.61,"tv":87.86,"id":47674067}]}]}
{"op":"mcm","clk":"11934802094","pt":1724335828770,"mc":[{"id":"1.232135506","rc":[{"batl":[[0,1.98,35.69],[1,1.99,5.32],[2,2.96,10]],"ltp":1.61,"tv":87.86,"id":47674067}]}]}
{"op":"mcm","clk":"11934803275","pt":1724335843686,"mc":[{"id":"1.232135506","rc":[{"trd":[[1.98,71.39]],"batb":[[0,1.6,21.85]],"batl":[[0,1.99,5.32],[1,2.96,10],[2,2.96,0]],"ltp":1.98,"tv":159.25,"id":47674067}],"tv":159.25}]}
{"op":"mcm","clk":"11934803635","pt":1724335847680,"mc":[{"id":"1.232135506","rc":[{"batb":[[0,1.6,21]],"ltp":1.98,"tv":159.25,"id":47674067}]}]}
{"op":"mcm","clk":"11934808235","pt":1724335905865,"mc":[{"id":"1.232135506","rc":[{"trd":[[1.99,0.08]],"batl":[[0,1.99,5.28]],"ltp":1.99,"tv":159.33,"id":47674067}],"tv":159.33}]}
{"op":"mcm","clk":"11934810199","pt":1724335930580,"mc":[{"id":"1.232135506","rc":[{"batb":[[0,1.65,969.31],[1,1.6,21],[2,1.55,6.14]],"ltp":1.99,"tv":159.33,"id":47674067}]}]}
{"op":"mcm","clk":"11934842583","pt":1724336209228,"mc":[{"id":"1.232135506","rc":[{"batb":[[0,1.69,104],[1,1.65,969.31],[2,1.6,21]],"ltp":1.99,"tv":159.33,"id":47674067}]}]}
{"op":"mcm","clk":"11934849982","pt":1724336302555,"mc":[{"id":"1.232135506","rc":[{"batl":[[2,18,0.51]],"ltp":1.99,"tv":159.33,"id":47674067},{"batl":[[2,18,0.51]],"ltp":0.0,"tv":0.0,"id":72963954}]}]}
{"op":"mcm","clk":"11934853870","pt":1724336353604,"mc":[{"id":"1.232135506","rc":[{"batl":[[2,19,1.03]],"ltp":1.99,"tv":159.33,"id":47674067},{"batl":[[2,19,1.03]],"ltp":0.0,"tv":0.0,"id":72963954}]}]}
{"op":"mcm","clk":"11934904891","pt":1724337017196,"mc":[{"id":"1.232135506","rc":[{"batb":[[0,1.7,5.11],[1,1.69,104],[2,1.65,969.31]],"ltp":1.99,"tv":159.33,"id":47674067}]}]}
{"op":"mcm","clk":"11934920589","pt":1724337228025,"mc":[{"id":"1.232135506","rc":[{"batb":[[0,1.7,11.24]],"ltp":1.99,"tv":159.33,"id":47674067}]}]}
{"op":"mcm","clk":"11934982361","pt":1724337963853,"mc":[{"id":"1.232135506","rc":[{"batl":[[2,18,1.03]],"ltp":1.99,"tv":159.33,"id":47674067},{"batl":[[2,18,1.03]],"ltp":0.0,"tv":0.0,"id":72963954}]}]}
{"op":"mcm","clk":"11934987644","pt":1724338042436,"mc":[{"id":"1.232135506","rc":[{"batb":[[1,1.76,534.27],[2,1.21,82.81]],"ltp":0.0,"tv":0.0,"id":72963954}]}]}
{"op":"mcm","clk":"11934991386","pt":1724338091671,"mc":[{"id":"1.232135506","rc":[{"batl":[[2,8.4,1.03]],"ltp":1.99,"tv":159.33,"id":47674067},{"batl":[[2,8.4,1.03]],"ltp":0.0,"tv":0.0,"id":72963954}]}]}
{"op":"mcm","clk":"11934993427","pt":1724338122719,"mc":[{"id":"1.232135506","rc":[{"batb":[[0,1.7,21.88]],"ltp":1.99,"tv":159.33,"id":47674067}]}]}
{"op":"mcm","clk":"11934999720","pt":1724338216553,"mc":[{"id":"1.232135506","rc":[{"batl":[[2,5,1.03]],"ltp":1.99,"tv":159.33,"id":47674067},{"batl":[[2,5,1.03]],"ltp":0.0,"tv":0.0,"id":72963954}]}]}
{"op":"mcm","clk":"11935006043","pt":1724338309723,"mc":[{"id":"1.232135506","rc":[{"batl":[[0,2.96,10],[1,5,1.03],[2,18,1.03]],"ltp":1.99,"tv":159.33,"id":47674067}]}]}
{"op":"mcm","clk":"11935007901","pt":1724338335659,"mc":[{"id":"1.232135506","rc":[{"batl":[[0,1.98,9.75],[1,2.96,10],[2,5,1.03]],"ltp":1.99,"tv":159.33,"id":47674067}]}]}
{"op":"mcm","clk":"11935009562","pt":1724338352755,"mc":[{"id":"1.232135506","rc":[{"batl":[[0,2.96,10],[1,5,1.03],[2,18,1.03]],"ltp":1.99,"tv":159.33,"id":47674067}]}]}
{"op":"mcm","clk":"11935009571","pt":1724338352862,"mc":[{"id":"1.232135506","rc":[{"batl":[[0,1.95,9.75],[1,2.96,10],[2,5,1.03]],"ltp":1.99,"tv":159.33,"id":47674067}]}]}
{"op":"mcm","clk":"11935028952","pt":1724338596681,"mc":[{"id":"1.232135506","rc":[{"batl":[[0,2.96,10],[1,5,1.03],[2,8.4,1.03]],"ltp":1.99,"tv":159.33,"id":47674067}]}]}
{"op":"mcm","clk":"11935028960","pt":1724338596787,"mc":[{"id":"1.232135506","rc":[{"batl":[[0,1.85,9.75],[1,2.96,10],[2,5,1.03]],"ltp":1.99,"tv":159.33,"id":47674067}]}]}
{"op":"mcm","clk":"11935031920","pt":1724338634728,"mc":[{"id":"1.232135506","rc":[{"batl":[[0,2.96,10],[1,5,1.03],[2,6.6,1.03]],"ltp":1.99,"tv":159.33,"id":47674067}]}]}
{"op":"mcm","clk":"11935031939","pt":1724338634934,"mc":[{"id":"1.232135506","rc":[{"batl":[[0,1.91,9.75],[1,2.96,10],[2,5,1.03]],"ltp":1.99,"tv":159.33,"id":47674067}]}]}
{"op":"mcm","clk":"11935035980","pt":1724338693686,"mc":[{"id":"1.232135506","rc":[{"batb":[[0,1.7,11.24]],"ltp":1.99,"tv":159.33,"id":47674067}]}]}
{"op":"mcm","clk":"11935044639","pt":1724338805740,"mc":[{"id":"1.232135506","rc":[{"trd":[[1.61,87.84],[1.98,71.37]],"batb":[[0,1.7,11.24]],"batl":[[0,1.91,9.75]],"ltp":1.99,"tv":159.28,"id":47674067},{"batb":[[0,1.77,6.15],[1,1.76,534.15],[2,1.21,82.79]],"batl":[[0,2.96,4.1],[1,2.98,4.1]],"ltp":0.0,"tv":0.0,"id":72963954}],"tv":159.28}]}
{"op":"mcm","clk":"11935065892","pt":1724339029243,"mc":[{"id":"1.232135506","rc":[{"batb":[[0,1.71,14],[1,1.7,6.14],[2,1.69,104]],"batl":[[0,1.95,9.75]],"ltp":1.99,"tv":159.28,"id":47674067}]}]}
{"op":"mcm","clk":"11935066012","pt":1724339031034,"mc":[{"id":"1.232135506","rc":[{"batb":[[0,1.71,10]],"ltp":1.99,"tv":159.28,"id":47674067}]}]}
{"op":"mcm","clk":"11935066073","pt":1724339032059,"mc":[{"id":"1.232135506","rc":[{"batb":[[0,1.7,6.14],[1,1.69,104],[2,1.65,969.31]],"ltp":1.99,"tv":159.28,"id":47674067}]}]}
{"op":"mcm","clk":"11935066466","pt":1724339036970,"mc":[{"id":"1.232135506","rc":[{"batb":[[0,1.71,14],[1,1.7,6.14],[2,1.69,104]],"batl":[[0,1.96,9.75]],"ltp":1.99,"tv":159.28,"id":47674067}]}]}
{"op":"mcm","clk":"11935066639","pt":1724339039042,"mc":[{"id":"1.232135506","rc":[{"batb":[[0,1.71,10]],"ltp":1.99,"tv":159.28,"id":47674067}]}]}
{"op":"mcm","clk":"11935066716","pt":1724339040278,"mc":[{"id":"1.232135506","rc":[{"batb":[[0,1.7,6.14],[1,1.69,104],[2,1.65,969.31]],"ltp":1.99,"tv":159.28,"id":47674067}]}]}
{"op":"mcm","clk":"11935077510","pt":1724339145438,"mc":[{"id":"1.232135506","rc":[{"batb":[[2,1.6,21]],"ltp":1.99,"tv":159.28,"id":47674067}]}]}
{"op":"mcm","clk":"11935083570","pt":1724339190171,"mc":[{"id":"1.232135506","rc":[{"batb":[[2,1.6,29.54]],"ltp":1.99,"tv":159.28,"id":47674067},{"batb":[[2,1.6,8.54]],"ltp":0.0,"tv":0.0,"id":72963954}]}]}
{"op":"mcm","clk":"11935089087","pt":1724339246449,"mc":[{"id":"1.232135506","rc":[{"batb":[[0,1.7,13.46]],"ltp":1.99,"tv":159.28,"id":47674067},{"batb":[[2,1.7,7.32]],"ltp":0.0,"tv":0.0,"id":72963954}]}]}
{"op":"mcm","clk":"11935093400","pt":1724339288811,"mc":[{"id":"1.232135506","rc":[{"batb":[[0,1.7,18.56]],"ltp":1.99,"tv":159.28,"id":47674067}]}]}
{"op":"mcm","clk":"11935095155","pt":1724339304124,"mc":[{"id":"1.232135506","rc":[{"batb":[[0,2.4,1.07],[1,1.77,6.15],[2,1.76,534.15]],"ltp":0.0,"tv":0.0,"id":72963954}]}]}
{"op":"mcm","clk":"11935095380","pt":1724339306399,"mc":[{"id":"1.232135506","rc":[{"batb":[[0,1.77,6.15],[1,1.76,534.15],[2,1.7,7.32]],"ltp":0.0,"tv":0.0,"id":72963954}]}]}
{"op":"mcm","clk":"11935096267","pt":1724339314129,"mc":[{"id":"1.232135506","rc":[{"batb":[[0,2.4,1.07],[1,1.77,6.15],[2,1.76,534.15]],"ltp":0.0,"tv":0.0,"id":72963954}]}]}
{"op":"mcm","clk":"11935096375","pt":1724339315124,"mc":[{"id":"1.232135506","rc":[{"batb":[[1,1.8,6.41],[2,1.77,6.15]],"ltp":0.0,"tv":0.0,"id":72963954}]}]}
{"op":"mcm","clk":"11935096562","pt":1724339316731,"mc":[{"id":"1.232135506","rc":[{"batb":[[0,1.8,12.56],[1,1.76,534.15],[2,1.7,7.32]],"ltp":0.0,"tv":0.0,"id":72963954}]}]}
{"op":"mcm","clk":"11935097113","pt":1724339321832,"mc":[{"id":"1.232135506","rc":[{"batb":[[0,2.4,1.53],[1,1.8,12.56],[2,1.76,534.15]],"ltp":0.0,"tv":0.0,"id":72963954}]}]}
{"op":"mcm","clk":"11935097552","pt":1724339326061,"mc":[{"id":"1.232135506","rc":[{"batb":[[0,1.8,12.56],[1,1.76,534.15],[2,1.7,7.32]],"ltp":0.0,"tv":0.0,"id":72963954}]}]}
{"op":"mcm","clk":"11935098509","pt":1724339335676,"mc":[{"id":"1.232135506","rc":[{"batl":[[0,2.08,1.07],[1,2.96,4.1],[2,2.98,4.1]],"ltp":0.0,"tv":0.0,"id":72963954}]}]}
{"op":"mcm","clk":"11935098846","pt":1724339339066,"mc":[{"id":"1.232135506","rc":[{"batl":[[0,2.96,4.1],[1,2.98,4.1],[2,5,1.02]],"ltp":0.0,"tv":0.0,"id":72963954}]}]}
{"op":"mcm","clk":"11935100086","pt":1724339350699,"mc":[{"id":"1.232135506","rc":[{"batb":[[0,1.89,1.07],[1,1.7,18.56],[2,1.69,104]],"ltp":1.99,"tv":159.28,"id":47674067}]}]}
{"op":"mcm","clk":"11935101012","pt":1724339361006,"mc":[{"id":"1.232135506","rc":[{"batb":[[0,1.9,5.69],[1,1.8,12.56],[2,1.76,534.15]],"ltp":0.0,"tv":0.0,"id":72963954}]}]}
{"op":"mcm","clk":"11935101138","pt":1724339362436,"mc":[{"id":"1.232135506","rc":[{"batb":[[0,1.7,18.56],[1,1.69,104],[2,1.6,29.54]],"ltp":1.99,"tv":159.28,"id":47674067},{"batb":[[0,1.9,11.84],[1,1.8,6.41]],"ltp":0.0,"tv":0.0,"id":72963954}]}]}
{"op":"mcm","clk":"11935103352","pt":1724339385036,"mc":[{"id":"1.232135506","rc":[{"batb":[[0,1.85,1.07],[1,1.7,18.56],[2,1.69,104]],"ltp":1.99,"tv":159.28,"id":47674067}]}]}
{"op":"mcm","clk":"11935104354","pt":1724339395521,"mc":[{"id":"1.232135506","rc":[{"batb":[[0,1.7,18.56],[1,1.69,104],[2,1.6,29.54]],"ltp":1.99,"tv":159.28,"id":47674067}]}]}
{"op":"mcm","clk":"11935105096","pt":1724339403650,"mc":[{"id":"1.232135506","rc":[{"batb":[[0,1.85,3.82],[1,1.7,18.56],[2,1.69,104]],"ltp":1.99,"tv":159.28,"id":47674067}]}]}
{"op":"mcm","clk":"11935106592","pt":1724339417864,"mc":[{"id":"1.232135506","rc":[{"batb":[[0,1.7,18.56],[1,1.69,104],[2,1.6,29.54]],"ltp":1.99,"tv":159.28,"id":47674067}]}]}
{"op":"mcm","clk":"11935111781","pt":1724339471632,"mc":[{"id":"1.232135506","rc":[{"batb":[[0,1.88,1.07],[1,1.7,18.56],[2,1.69,104]],"ltp":1.99,"tv":159.28,"id":47674067}]}]}
{"op":"mcm","clk":"11935112282","pt":1724339476750,"mc":[{"id":"1.232135506","rc":[{"batl":[[0,2.96,10],[1,5,1.02],[2,6,1.02]],"ltp":1.99,"tv":159.28,"id":47674067}]}]}
{"op":"mcm","clk":"11935112324","pt":1724339477063,"mc":[{"id":"1.232135506","rc":[{"trd":[[1.88,11.49],[1.89,8]],"batb":[[0,1.9,5.32]],"ltp":1.88,"tv":178.78,"id":47674067}],"tv":178.78}]}
{"op":"mcm","clk":"11935112710","pt":1724339480752,"mc":[{"id":"1.232135506","rc":[{"batb":[[0,1.71,4]],"ltp":1.88,"tv":178.78,"id":47674067}]}]}
{"op":"mcm","clk":"11935112946","pt":1724339483129,"mc":[{"id":"1.232135506","rc":[{"batb":[[0,1.71,10]],"ltp":1.88,"tv":178.78,"id":47674067}]}]}
{"op":"mcm","clk":"11935113299","pt":1724339486443,"mc":[{"id":"1.232135506","rc":[{"batb":[[0,1.71,4]],"ltp":1.88,"tv":178.78,"id":47674067}]}]}
{"op":"mcm","clk":"11935113660","pt":1724339488756,"mc":[{"id":"1.232135506","rc":[{"batb":[[0,1.71,10]],"ltp":1.88,"tv":178.78,"id":47674067}]}]}
{"op":"mcm","clk":"11935114227","pt":1724339492361,"mc":[{"id":"1.232135506","rc":[{"batb":[[0,1.71,4]],"ltp":1.88,"tv":178.78,"id":47674067}]}]}
{"op":"mcm","clk":"11935114520","pt":1724339494654,"mc":[{"id":"1.232135506","rc":[{"batb":[[0,1.71,10]],"ltp":1.88,"tv":178.78,"id":47674067},{"batb":[[0,2.36,1.07],[1,1.9,11.84],[2,1.8,6.41]],"ltp":0.0,"tv":0.0,"id":72963954}]}]}
{"op":"mcm","clk":"11935114841","pt":1724339497651,"mc":[{"id":"1.232135506","rc":[{"batb":[[0,1.72,4],[1,1.71,10],[2,1.7,18.56]],"ltp":1.88,"tv":178.78,"id":47674067},{"batb":[[0,1.9,11.84],[1,1.8,6.41],[2,1.76,534.15]],"ltp":0.0,"tv":0.0,"id":72963954}]}]}
{"op":"mcm","clk":"11935114856","pt":1724339497857,"mc":[{"id":"1.232135506","rc":[{"batb":[[1,1.7,18.56],[2,1.69,104]],"ltp":1.88,"tv":178.78,"id":47674067}]}]}
{"op":"mcm","clk":"11935115094","pt":1724339500078,"mc":[{"id":"1.232135506","rc":[{"batb":[[0,1.71,10]],"ltp":1.88,"tv":178.78,"id":47674067}]}]}
{"op":"mcm","clk":"11935115503","pt":1724339503457,"mc":[{"id":"1.232135506","rc":[{"batb":[[0,1.71,4]],"ltp":1.88,"tv":178.78,"id":47674067}]}]}
{"op":"mcm","clk":"11935115741","pt":1724339505669,"mc":[{"id":"1.232135506","rc":[{"batb":[[0,1.7,18.56],[1,1.69,104],[2,1.6,29.54]],"ltp":1.88,"tv":178.78,"id":47674067}]}]}
{"op":"mcm","clk":"11935115760","pt":1724339505876,"mc":[{"id":"1.232135506","rc":[{"batb":[[0,1.71,10],[1,1.7,18.56],[2,1.69,104]],"ltp":1.88,"tv":178.78,"id":47674067}]}]}
{"op":"mcm","clk":"11935116096","pt":1724339508468,"mc":[{"id":"1.232135506","rc":[{"trd":[[1.71,1.17]],"batb":[[0,1.72,4],[1,1.71,8.83],[2,1.7,18.56]],"ltp":1.71,"tv":179.95,"id":47674067},{"trd":[[2.42,0.82]],"batb":[[0,1.91,14],[1,1.9,11.84],[2,1.8,6.41]],"ltp":2.42,"tv":0.82,"id":72963954}],"tv":180.77}]}
{"op":"mcm","clk":"11935116186","pt":1724339509293,"mc":[{"id":"1.232135506","rc":[{"batb":[[1,1.7,18.56],[2,1.69,104]],"ltp":1.71,"tv":179.95,"id":47674067},{"batb":[[0,1.91,20.15],[1,1.9,5.69]],"ltp":2.42,"tv":0.82,"id":72963954}]}]}
{"op":"mcm","clk":"11935116337","pt":1724339510695,"mc":[{"id":"1.232135506","rc":[{"batb":[[0,1.7,18.56],[1,1.69,104],[2,1.6,29.54]],"ltp":1.71,"tv":179.95,"id":47674067},{"batb":[[0,1.91,16.15]],"ltp":2.42,"tv":0.82,"id":72963954}]}]}
{"op":"mcm","clk":"11935116438","pt":1724339511674,"mc":[{"id":"1.232135506","rc":[{"batb":[[0,1.91,6.15]],"ltp":2.42,"tv":0.82,"id":72963954}]}]}
{"op":"mcm","clk":"11935116454","pt":1724339511874,"mc":[{"id":"1.232135506","rc":[{"batb":[[0,1.71,10],[1,1.7,18.56],[2,1.69,104]],"ltp":1.71,"tv":179.95,"id":47674067}]}]}
{"op":"mcm","clk":"11935116664","pt":1724339514161,"mc":[{"id":"1.232135506","rc":[{"batb":[[0,1.72,4],[1,1.71,10],[2,1.7,18.56]],"ltp":1.71,"tv":179.95,"id":47674067},{"batb":[[0,1.93,10],[1,1.92,10.15],[2,1.9,5.69]],"ltp":2.42,"tv":0.82,"id":72963954}]}]}
{"op":"mcm","clk":"11935116785","pt":1724339515609,"mc":[{"id":"1.232135506","rc":[{"batb":[[1,1.7,18.56],[2,1.69,104]],"ltp":1.71,"tv":179.95,"id":47674067},{"batb":[[0,1.93,16.15],[1,1.92,4]],"ltp":2.42,"tv":0.82,"id":72963954}]}]}
{"op":"mcm","clk":"11935116857","pt":1724339516389,"mc":[{"id":"1.232135506","rc":[{"batb":[[0,1.7,18.56],[1,1.69,104],[2,1.6,29.54]],"ltp":1.71,"tv":179.95,"id":47674067},{"batb":[[1,1.9,5.69],[2,1.8,6.41]],"ltp":2.42,"tv":0.82,"id":72963954}]}]}
{"op":"mcm","clk":"11935116981","pt":1724339517688,"mc":[{"id":"1.232135506","rc":[{"batb":[[0,1.71,10],[1,1.7,18.56],[2,1.69,104]],"ltp":1.71,"tv":179.95,"id":47674067},{"batb":[[0,1.93,6.15]],"ltp":2.42,"tv":0.82,"id":72963954}]}]}
{"op":"mcm","clk":"11935117305","pt":1724339521111,"mc":[{"id":"1.232135506","rc":[{"batb":[[0,1.71,4]],"ltp":1.71,"tv":179.95,"id":47674067},{"batb":[[0,1.94,14],[1,1.93,6.15],[2,1.9,5.69]],"ltp":2.42,"tv":0.82,"id":72963954}]}]}
{"op":"mcm","clk":"11935117699","pt":1724339524694,"mc":[{"id":"1.232135506","rc":[{"batb":[[0,1.71,10]],"batl":[[0,1.94,7.93],[1,2.96,10],[2,5,1.02]],"ltp":1.71,"tv":179.95,"id":47674067},{"batb":[[0,1.93,6.15],[1,1.9,5.69],[2,1.8,6.41]],"ltp":2.42,"tv":0.82,"id":72963954}]}]}
{"op":"mcm","clk":"11935117971","pt":1724339527393,"mc":[{"id":"1.232135506","rc":[{"batb":[[0,1.7,18.56],[1,1.69,104],[2,1.6,29.54]],"ltp":1.71,"tv":179.95,"id":47674067},{"batb":[[0,1.94,14],[1,1.93,6.15],[2,1.9,5.69]],"ltp":2.42,"tv":0.82,"id":72963954}]}]}
{"op":"mcm","clk":"11935118173","pt":1724339529816,"mc":[{"id":"1.232135506","rc":[{"batb":[[0,1.94,10]],"ltp":2.42,"tv":0.82,"id":72963954}]}]}
{"op":"mcm","clk":"11935118287","pt":1724339530804,"mc":[{"id":"1.232135506","rc":[{"batb":[[0,1.93,6.15],[1,1.9,5.69],[2,1.8,6.41]],"ltp":2.42,"tv":0.82,"id":72963954}]}]}
{"op":"mcm","clk":"11935120389","pt":1724339551548,"mc":[{"id":"1.232135506","rc":[{"batb":[[0,2.28,1.07],[1,1.94,14],[2,1.93,6.15]],"ltp":2.42,"tv":0.82,"id":72963954}]}]}
{"op":"mcm","clk":"11935120608","pt":1724339553670,"mc":[{"id":"1.232135506","rc":[{"batb":[[1,1.94,10]],"ltp":2.42,"tv":0.82,"id":72963954}]}]}
{"op":"mcm","clk":"11935120736","pt":1724339554763,"mc":[{"id":"1.232135506","rc":[{"batb":[[1,1.93,6.15],[2,1.9,5.69]],"ltp":2.42,"tv":0.82,"id":72963954}]}]}
{"op":"mcm","clk":"11935121388","pt":1724339561751,"mc":[{"id":"1.232135506","rc":[{"batb":[[0,1.93,6.15],[1,1.9,5.69],[2,1.8,6.41]],"ltp":2.42,"tv":0.82,"id":72963954}]}]}
{"op":"mcm","clk":"11935121400","pt":1724339561855,"mc":[{"id":"1.232135506","rc":[{"batb":[[0,1.94,14],[1,1.93,6.15],[2,1.9,5.69]],"ltp":2.42,"tv":0.82,"id":72963954}]}]}
{"op":"mcm","clk":"11935121594","pt":1724339564083,"mc":[{"id":"1.232135506","rc":[{"batb":[[0,1.94,10]],"ltp":2.42,"tv":0.82,"id":72963954}]}]}
{"op":"mcm","clk":"11935121687","pt":1724339565081,"mc":[{"id":"1.232135506","rc":[{"batb":[[0,1.93,6.15],[1,1.9,5.69],[2,1.8,6.41]],"ltp":2.42,"tv":0.82,"id":72963954}]}]}
{"op":"mcm","clk":"11935121981","pt":1724339567586,"mc":[{"id":"1.232135506","rc":[{"batb":[[0,1.95,10],[1,1.94,4],[2,1.93,6.15]],"ltp":2.42,"tv":0.82,"id":72963954}]}]}
{"op":"mcm","clk":"11935122239","pt":1724339569672,"mc":[{"id":"1.232135506","rc":[{"batb":[[1,1.93,6.15],[2,1.9,5.69]],"ltp":2.42,"tv":0.82,"id":72963954}]}]}
{"op":"mcm","clk":"11935122357","pt":1724339570964,"mc":[{"id":"1.232135506","rc":[{"batb":[[0,1.93,6.15],[1,1.9,5.69],[2,1.8,6.41]],"ltp":2.42,"tv":0.82,"id":72963954}]}]}
{"op":"mcm","clk":"11935122574","pt":1724339573300,"mc":[{"id":"1.232135506","rc":[{"batb":[[0,1.94,14],[1,1.93,6.15],[2,1.9,5.69]],"ltp":2.42,"tv":0.82,"id":72963954}]}]}
{"op":"mcm","clk":"11935122937","pt":1724339576692,"mc":[{"id":"1.232135506","rc":[{"batb":[[0,1.93,6.15],[1,1.9,5.69],[2,1.8,6.41]],"ltp":2.42,"tv":0.82,"id":72963954}]}]}
{"op":"mcm","clk":"11935123121","pt":1724339578396,"mc":[{"id":"1.232135506","rc":[{"batb":[[0,1.94,4],[1,1.93,6.15],[2,1.9,5.69]],"ltp":2.42,"tv":0.82,"id":72963954}]}]}
{"op":"mcm","clk":"11935123383","pt":1724339581006,"mc":[{"id":"1.232135506","rc":[{"batb":[[0,1.94,10]],"ltp":2.42,"tv":0.82,"id":72963954}]}]}
{"op":"mcm","clk":"11935123743","pt":1724339584327,"mc":[{"id":"1.232135506","rc":[{"batb":[[0,1.94,4]],"ltp":2.42,"tv":0.82,"id":72963954}]}]}
{"op":"mcm","clk":"11935123991","pt":1724339586715,"mc":[{"id":"1.232135506","rc":[{"batb":[[0,1.94,10]],"ltp":2.42,"tv":0.82,"id":72963954}]}]}
{"op":"mcm","clk":"11935124354","pt":1724339590199,"mc":[{"id":"1.232135506","rc":[{"batb":[[0,1.94,4]],"ltp":2.42,"tv":0.82,"id":72963954}]}]}
{"op":"mcm","clk":"11935124658","pt":1724339592598,"mc":[{"id":"1.232135506","rc":[{"batb":[[0,1.94,10]],"ltp":2.42,"tv":0.82,"id":72963954}]}]}
{"op":"mcm","clk":"11935125087","pt":1724339596217,"mc":[{"id":"1.232135506","rc":[{"batb":[[0,1.94,4]],"ltp":2.42,"tv":0.82,"id":72963954}]}]}
{"op":"mcm","clk":"11935125295","pt":1724339598444,"mc":[{"id":"1.232135506","rc":[{"batb":[[0,1.95,10],[1,1.94,4],[2,1.93,6.15]],"ltp":2.42,"tv":0.82,"id":72963954}]}]}
{"op":"mcm","clk":"11935125341","pt":1724339598803,"mc":[{"id":"1.232135506","rc":[{"batb":[[1,1.93,6.15],[2,1.9,5.69]],"ltp":2.42,"tv":0.82,"id":72963954}]}]}
{"op":"mcm","clk":"11935125670","pt":1724339601918,"mc":[{"id":"1.232135506","rc":[{"batb":[[0,1.94,4]],"ltp":2.42,"tv":0.82,"id":72963954}]}]}
{"op":"mcm","clk":"11935125939","pt":1724339604515,"mc":[{"id":"1.232135506","rc":[{"batb":[[0,1.94,10]],"ltp":2.42,"tv":0.82,"id":72963954}]}]}
{"op":"mcm","clk":"11935126279","pt":1724339608028,"mc":[{"id":"1.232135506","rc":[{"batb":[[0,1.94,4]],"ltp":2.42,"tv":0.82,"id":72963954}]}]}
{"op":"mcm","clk":"11935126465","pt":1724339610406,"mc":[{"id":"1.232135506","rc":[{"batb":[[0,1.94,10]],"ltp":2.42,"tv":0.82,"id":72963954}]}]}
{"op":"mcm","clk":"11935126808","pt":1724339613653,"mc":[{"id":"1.232135506","rc":[{"batb":[[0,1.93,6.15],[1,1.9,5.69],[2,1.8,6.41]],"ltp":2.42,"tv":0.82,"id":72963954}]}]}
{"op":"mcm","clk":"11935126868","pt":1724339614021,"mc":[{"id":"1.232135506","rc":[{"batb":[[0,1.94,4],[1,1.93,6.15],[2,1.9,5.69]],"ltp":2.42,"tv":0.82,"id":72963954}]}]}
{"op":"mcm","clk":"11935127117","pt":1724339616461,"mc":[{"id":"1.232135506","rc":[{"batb":[[0,1.94,10]],"ltp":2.42,"tv":0.82,"id":72963954}]}]}
{"op":"mcm","clk":"11935127314","pt":1724339618538,"mc":[{"id":"1.232135506","rc":[{"batb":[[0,1.95,4],[1,1.94,10],[2,1.93,6.15]],"ltp":2.42,"tv":0.82,"id":72963954}]}]}
{"op":"mcm","clk":"11935127435","pt":1724339619734,"mc":[{"id":"1.232135506","rc":[{"batb":[[1,1.93,6.15],[2,1.9,5.69]],"ltp":2.42,"tv":0.82,"id":72963954}]}]}
{"op":"mcm","clk":"11935127592","pt":1724339621251,"mc":[{"id":"1.232135506","rc":[{"batb":[[0,1.93,6.15],[1,1.9,5.69],[2,1.8,6.41]],"ltp":2.42,"tv":0.82,"id":72963954}]}]}
{"op":"mcm","clk":"11935127827","pt":1724339623555,"mc":[{"id":"1.232135506","rc":[{"batb":[[0,1.94,14],[1,1.93,6.15],[2,1.9,5.69]],"ltp":2.42,"tv":0.82,"id":72963954}]}]}
{"op":"mcm","clk":"11935128047","pt":1724339625855,"mc":[{"id":"1.232135506","rc":[{"batb":[[0,1.94,10]],"ltp":2.42,"tv":0.82,"id":72963954}]}]}
{"op":"mcm","clk":"11935128163","pt":1724339626952,"mc":[{"id":"1.232135506","rc":[{"batb":[[0,1.93,6.15],[1,1.9,5.69],[2,1.8,6.41]],"ltp":2.42,"tv":0.82,"id":72963954}]}]}
{"op":"mcm","clk":"11935128542","pt":1724339631061,"mc":[{"id":"1.232135506","rc":[{"batb":[[0,1.94,14],[1,1.93,6.15],[2,1.9,5.69]],"ltp":2.42,"tv":0.82,"id":72963954}]}]}
{"op":"mcm","clk":"11935128782","pt":1724339633665,"mc":[{"id":"1.232135506","rc":[{"batb":[[0,1.94,10]],"ltp":2.42,"tv":0.82,"id":72963954}]}]}
{"op":"mcm","clk":"11935128862","pt":1724339634652,"mc":[{"id":"1.232135506","rc":[{"batb":[[0,1.93,6.15],[1,1.9,5.69],[2,1.8,6.41]],"ltp":2.42,"tv":0.82,"id":72963954}]}]}
{"op":"mcm","clk":"11935129312","pt":1724339640060,"mc":[{"id":"1.232135506","rc":[{"batb":[[0,1.94,14],[1,1.93,6.15],[2,1.9,5.69]],"ltp":2.42,"tv":0.82,"id":72963954}]}]}
{"op":"mcm","clk":"11935129567","pt":1724339642464,"mc":[{"id":"1.232135506","rc":[{"batb":[[0,1.94,10]],"ltp":2.42,"tv":0.82,"id":72963954}]}]}
{"op":"mcm","clk":"11935129679","pt":1724339643568,"mc":[{"id":"1.232135506","rc":[{"batb":[[0,1.93,6.15],[1,1.9,5.69],[2,1.8,6.41]],"ltp":2.42,"tv":0.82,"id":72963954}]}]}
{"op":"mcm","clk":"11935132180","pt":1724339667926,"mc":[{"id":"1.232135506","rc":[{"batb":[[0,1.94,14],[1,1.93,6.15],[2,1.9,5.69]],"ltp":2.42,"tv":0.82,"id":72963954}]}]}
{"op":"mcm","clk":"11935132389","pt":1724339670223,"mc":[{"id":"1.232135506","rc":[{"batb":[[0,1.94,10]],"ltp":2.42,"tv":0.82,"id":72963954}]}]}
{"op":"mcm","clk":"11935132471","pt":1724339671224,"mc":[{"id":"1.232135506","rc":[{"batb":[[0,1.93,6.15],[1,1.9,5.69],[2,1.8,6.41]],"ltp":2.42,"tv":0.82,"id":72963954}]}]}
{"op":"mcm","clk":"11935133472","pt":1724339681624,"mc":[{"id":"1.232135506","rc":[{"batb":[[0,1.94,14],[1,1.93,6.15],[2,1.9,5.69]],"ltp":2.42,"tv":0.82,"id":72963954}]}]}
{"op":"mcm","clk":"11935133700","pt":1724339684112,"mc":[{"id":"1.232135506","rc":[{"batb":[[0,1.94,10]],"ltp":2.42,"tv":0.82,"id":72963954}]}]}
{"op":"mcm","clk":"11935133829","pt":1724339685240,"mc":[{"id":"1.232135506","rc":[{"batb":[[0,1.93,6.15],[1,1.9,5.69],[2,1.8,6.41]],"ltp":2.42,"tv":0.82,"id":72963954}]}]}
{"op":"mcm","clk":"11935134093","pt":1724339687720,"mc":[{"id":"1.232135506","rc":[{"batb":[[0,1.94,14],[1,1.93,6.15],[2,1.9,5.69]],"ltp":2.42,"tv":0.82,"id":72963954}]}]}
{"op":"mcm","clk":"11935134316","pt":1724339690241,"mc":[{"id":"1.232135506","rc":[{"batb":[[0,1.94,10]],"ltp":2.42,"tv":0.82,"id":72963954}]}]}
{"op":"mcm","clk":"11935134427","pt":1724339691226,"mc":[{"id":"1.232135506","rc":[{"batb":[[0,1.93,6.15],[1,1.9,5.69],[2,1.8,6.41]],"ltp":2.42,"tv":0.82,"id":72963954}]}]}
{"op":"mcm","clk":"11935135872","pt":1724339705235,"mc":[{"id":"1.232135506","rc":[{"batb":[[0,1.94,14],[1,1.93,6.15],[2,1.9,5.69]],"ltp":2.42,"tv":0.82,"id":72963954}]}]}
{"op":"mcm","clk":"11935136161","pt":1724339707851,"mc":[{"id":"1.232135506","rc":[{"batb":[[0,1.94,10]],"ltp":2.42,"tv":0.82,"id":72963954}]}]}
{"op":"mcm","clk":"11935136256","pt":1724339708846,"mc":[{"id":"1.232135506","rc":[{"batb":[[0,1.93,6.15],[1,1.9,5.69],[2,1.8,6.41]],"ltp":2.42,"tv":0.82,"id":72963954}]}]}
{"op":"mcm","clk":"11935137249","pt":1724339716852,"mc":[{"id":"1.232135506","rc":[{"batb":[[0,1.94,14],[1,1.93,6.15],[2,1.9,5.69]],"ltp":2.42,"tv":0.82,"id":72963954}]}]}
{"op":"mcm","clk":"11935137494","pt":1724339719485,"mc":[{"id":"1.232135506","rc":[{"batb":[[0,1.94,10]],"ltp":2.42,"tv":0.82,"id":72963954}]}]}
{"op":"mcm","clk":"11935137598","pt":1724339720397,"mc":[{"id":"1.232135506","rc":[{"batb":[[0,1.93,6.15],[1,1.9,5.69],[2,1.8,6.41]],"ltp":2.42,"tv":0.82,"id":72963954}]}]}
{"op":"mcm","clk":"11935138554","pt":1724339729471,"mc":[{"id":"1.232135506","rc":[{"batb":[[0,1.94,14],[1,1.93,6.15],[2,1.9,5.69]],"ltp":2.42,"tv":0.82,"id":72963954}]}]}
{"op":"mcm","clk":"11935138905","pt":1724339732690,"mc":[{"id":"1.232135506","rc":[{"batb":[[0,1.93,6.15],[1,1.9,5.69],[2,1.8,6.41]],"ltp":2.42,"tv":0.82,"id":72963954}]}]}
{"op":"mcm","clk":"11935140001","pt":1724339741816,"mc":[{"id":"1.232135506","rc":[{"batb":[[0,1.94,14],[1,1.93,6.15],[2,1.9,5.69]],"ltp":2.42,"tv":0.82,"id":72963954}]}]}
{"op":"mcm","clk":"11935140305","pt":1724339744302,"mc":[{"id":"1.232135506","rc":[{"batb":[[0,1.94,10]],"ltp":2.42,"tv":0.82,"id":72963954}]}]}
{"op":"mcm","clk":"11935140422","pt":1724339745290,"mc":[{"id":"1.232135506","rc":[{"batb":[[0,1.93,6.15],[1,1.9,5.69],[2,1.8,6.41]],"ltp":2.42,"tv":0.82,"id":72963954}]}]}
{"op":"mcm","clk":"11935141311","pt":1724339753105,"mc":[{"id":"1.232135506","rc":[{"batb":[[0,1.94,14],[1,1.93,6.15],[2,1.9,5.69]],"ltp":2.42,"tv":0.82,"id":72963954}]}]}
{"op":"mcm","clk":"11935141580","pt":1724339755524,"mc":[{"id":"1.232135506","rc":[{"batb":[[0,1.94,10]],"ltp":2.42,"tv":0.82,"id":72963954}]}]}
{"op":"mcm","clk":"11935141695","pt":1724339756616,"mc":[{"id":"1.232135506","rc":[{"batb":[[0,1.93,6.15],[1,1.9,5.69],[2,1.8,6.41]],"ltp":2.42,"tv":0.82,"id":72963954}]}]}
{"op":"mcm","clk":"11935143162","pt":1724339770036,"mc":[{"id":"1.232135506","rc":[{"batb":[[0,1.94,14],[1,1.93,6.15],[2,1.9,5.69]],"ltp":2.42,"tv":0.82,"id":72963954}]}]}
{"op":"mcm","clk":"11935143415","pt":1724339772437,"mc":[{"id":"1.232135506","rc":[{"batb":[[0,1.94,10]],"ltp":2.42,"tv":0.82,"id":72963954}]}]}
{"op":"mcm","clk":"11935143498","pt":1724339773351,"mc":[{"id":"1.232135506","rc":[{"batb":[[0,1.93,6.15],[1,1.9,5.69],[2,1.8,6.41]],"ltp":2.42,"tv":0.82,"id":72963954}]}]}
{"op":"mcm","clk":"11935144391","pt":1724339781658,"mc":[{"id":"1.232135506","rc":[{"batb":[[0,1.71,9.79],[1,1.7,18.56],[2,1.69,104]],"ltp":1.71,"tv":179.95,"id":47674067}]}]}
{"op":"mcm","clk":"11935144405","pt":1724339781859,"mc":[{"id":"1.232135506","rc":[{"batb":[[0,1.94,14],[1,1.93,6.15],[2,1.9,5.69]],"ltp":2.42,"tv":0.82,"id":72963954}]}]}
{"op":"mcm","clk":"11935144605","pt":1724339784043,"mc":[{"id":"1.232135506","rc":[{"batb":[[0,1.94,10]],"ltp":2.42,"tv":0.82,"id":72963954}]}]}
{"op":"mcm","clk":"11935144697","pt":1724339785065,"mc":[{"id":"1.232135506","rc":[{"batb":[[0,1.93,6.15],[1,1.9,5.69],[2,1.8,6.41]],"ltp":2.42,"tv":0.82,"id":72963954}]}]}
{"op":"mcm","clk":"11935145715","pt":1724339795688,"mc":[{"id":"1.232135506","rc":[{"batb":[[0,1.94,14],[1,1.93,6.15],[2,1.9,5.69]],"ltp":2.42,"tv":0.82,"id":72963954}]}]}
{"op":"mcm","clk":"11935145922","pt":1724339798169,"mc":[{"id":"1.232135506","rc":[{"batb":[[0,1.94,10]],"ltp":2.42,"tv":0.82,"id":72963954}]}]}
{"op":"mcm","clk":"11935146016","pt":1724339799199,"mc":[{"id":"1.232135506","rc":[{"batb":[[0,1.93,6.15],[1,1.9,5.69],[2,1.8,6.41]],"ltp":2.42,"tv":0.82,"id":72963954}]}]}
{"op":"mcm","clk":"11935146354","pt":1724339802762,"mc":[{"id":"1.232135506","rc":[{"batb":[[0,1.94,14],[1,1.93,6.15],[2,1.9,5.69]],"ltp":2.42,"tv":0.82,"id":72963954}]}]}
{"op":"mcm","clk":"11935146614","pt":1724339805288,"mc":[{"id":"1.232135506","rc":[{"batb":[[0,1.94,10]],"ltp":2.42,"tv":0.82,"id":72963954}]}]}
{"op":"mcm","clk":"11935146676","pt":1724339806064,"mc":[{"id":"1.232135506","rc":[{"batb":[[0,1.93,6.15],[1,1.9,5.69],[2,1.8,6.41]],"ltp":2.42,"tv":0.82,"id":72963954}]}]}
{"op":"mcm","clk":"11935147408","pt":1724339813675,"mc":[{"id":"1.232135506","rc":[{"batb":[[0,1.94,14],[1,1.93,6.15],[2,1.9,5.69]],"ltp":2.42,"tv":0.82,"id":72963954}]}]}
{"op":"mcm","clk":"11935147609","pt":1724339816312,"mc":[{"id":"1.232135506","rc":[{"batb":[[0,1.94,10]],"ltp":2.42,"tv":0.82,"id":72963954}]}]}
{"op":"mcm","clk":"11935147725","pt":1724339817508,"mc":[{"id":"1.232135506","rc":[{"batb":[[0,1.93,6.15],[1,1.9,5.69],[2,1.8,6.41]],"ltp":2.42,"tv":0.82,"id":72963954}]}]}
{"op":"mcm","clk":"11935147854","pt":1724339819101,"mc":[{"id":"1.232135506","rc":[{"batb":[[0,1.94,4],[1,1.93,6.15],[2,1.9,5.69]],"ltp":2.42,"tv":0.82,"id":72963954}]}]}
{"op":"mcm","clk":"11935148114","pt":1724339821509,"mc":[{"id":"1.232135506","rc":[{"batb":[[0,1.94,10]],"ltp":2.42,"tv":0.82,"id":72963954}]}]}
{"op":"mcm","clk":"11935148495","pt":1724339825099,"mc":[{"id":"1.232135506","rc":[{"batb":[[0,1.94,4]],"ltp":2.42,"tv":0.82,"id":72963954}]}]}
{"op":"mcm","clk":"11935148742","pt":1724339827396,"mc":[{"id":"1.232135506","rc":[{"batb":[[0,1.94,10]],"ltp":2.42,"tv":0.82,"id":72963954}]}]}
{"op":"mcm","clk":"11935149119","pt":1724339830714,"mc":[{"id":"1.232135506","rc":[{"batb":[[0,1.93,6.15],[1,1.9,5.69],[2,1.8,6.41]],"ltp":2.42,"tv":0.82,"id":72963954}]}]}
{"op":"mcm","clk":"11935149137","pt":1724339830823,"mc":[{"id":"1.232135506","rc":[{"batb":[[0,1.94,4],[1,1.93,6.15],[2,1.9,5.69]],"ltp":2.42,"tv":0.82,"id":72963954}]}]}
{"op":"mcm","clk":"11935149403","pt":1724339833302,"mc":[{"id":"1.232135506","rc":[{"batb":[[0,1.94,10]],"ltp":2.42,"tv":0.82,"id":72963954}]}]}
{"op":"mcm","clk":"11935149795","pt":1724339836711,"mc":[{"id":"1.232135506","rc":[{"batb":[[0,1.94,4]],"ltp":2.42,"tv":0.82,"id":72963954}]}]}
{"op":"mcm","clk":"11935150114","pt":1724339839312,"mc":[{"id":"1.232135506","rc":[{"batb":[[0,1.94,10]],"ltp":2.42,"tv":0.82,"id":72963954}]}]}
{"op":"mcm","clk":"11935150481","pt":1724339842630,"mc":[{"id":"1.232135506","rc":[{"batb":[[0,1.94,4]],"ltp":2.42,"tv":0.82,"id":72963954}]}]}
{"op":"mcm","clk":"11935150799","pt":1724339845119,"mc":[{"id":"1.232135506","rc":[{"batb":[[0,1.94,10]],"ltp":2.42,"tv":0.82,"id":72963954}]}]}
{"op":"mcm","clk":"11935151199","pt":1724339848743,"mc":[{"id":"1.232135506","rc":[{"batb":[[0,1.94,4]],"ltp":2.42,"tv":0.82,"id":72963954}]}]}
{"op":"mcm","clk":"11935151456","pt":1724339851126,"mc":[{"id":"1.232135506","rc":[{"batb":[[0,1.94,10]],"ltp":2.42,"tv":0.82,"id":72963954}]}]}
{"op":"mcm","clk":"11935151853","pt":1724339854644,"mc":[{"id":"1.232135506","rc":[{"batb":[[0,1.94,4]],"ltp":2.42,"tv":0.82,"id":72963954}]}]}
{"op":"mcm","clk":"11935152130","pt":1724339857147,"mc":[{"id":"1.232135506","rc":[{"batb":[[0,1.94,10]],"ltp":2.42,"tv":0.82,"id":72963954}]}]}
{"op":"mcm","clk":"11935152523","pt":1724339860635,"mc":[{"id":"1.232135506","rc":[{"batb":[[0,1.94,4]],"ltp":2.42,"tv":0.82,"id":72963954}]}]}
{"op":"mcm","clk":"11935152802","pt":1724339863159,"mc":[{"id":"1.232135506","rc":[{"batb":[[0,1.94,10]],"ltp":2.42,"tv":0.82,"id":72963954}]}]}
{"op":"mcm","clk":"11935153303","pt":1724339866539,"mc":[{"id":"1.232135506","rc":[{"batb":[[0,1.94,4]],"ltp":2.42,"tv":0.82,"id":72963954}]}]}
{"op":"mcm","clk":"11935153598","pt":1724339868969,"mc":[{"id":"1.232135506","rc":[{"batb":[[0,1.94,10]],"ltp":2.42,"tv":0.82,"id":72963954}]}]}
{"op":"mcm","clk":"11935153969","pt":1724339872347,"mc":[{"id":"1.232135506","rc":[{"batb":[[0,1.94,4]],"ltp":2.42,"tv":0.82,"id":72963954}]}]}
{"op":"mcm","clk":"11935154219","pt":1724339874682,"mc":[{"id":"1.232135506","rc":[{"batb":[[0,1.94,10]],"ltp":2.42,"tv":0.82,"id":72963954}]}]}
{"op":"mcm","clk":"11935154518","pt":1724339877283,"mc":[{"id":"1.232135506","rc":[{"batb":[[0,1.95,4],[1,1.94,10],[2,1.93,6.15]],"ltp":2.42,"tv":0.82,"id":72963954}]}]}
{"op":"mcm","clk":"11935154611","pt":1724339878065,"mc":[{"id":"1.232135506","rc":[{"batb":[[1,1.93,6.15],[2,1.9,5.69]],"ltp":2.42,"tv":0.82,"id":72963954}]}]}
{"op":"mcm","clk":"11935154783","pt":1724339879671,"mc":[{"id":"1.232135506","rc":[{"batb":[[0,1.93,6.15],[1,1.9,5.69],[2,1.8,6.41]],"ltp":2.42,"tv":0.82,"id":72963954}]}]}
{"op":"mcm","clk":"11935155683","pt":1724339886785,"mc":[{"id":"1.232135506","rc":[{"batb":[[0,1.94,14],[1,1.93,6.15],[2,1.9,5.69]],"ltp":2.42,"tv":0.82,"id":72963954}]}]}
{"op":"mcm","clk":"11935155985","pt":1724339889191,"mc":[{"id":"1.232135506","rc":[{"batb":[[0,1.94,10]],"ltp":2.42,"tv":0.82,"id":72963954}]}]}
{"op":"mcm","clk":"11935156093","pt":1724339890088,"mc":[{"id":"1.232135506","rc":[{"batb":[[0,1.93,6.15],[1,1.9,5.69],[2,1.8,6.41]],"ltp":2.42,"tv":0.82,"id":72963954}]}]}
{"op":"mcm","clk":"11935156358","pt":1724339892168,"mc":[{"id":"1.232135506","rc":[{"batb":[[0,1.94,14],[1,1.93,6.15],[2,1.9,5.69]],"ltp":2.42,"tv":0.82,"id":72963954}]}]}
{"op":"mcm","clk":"11935156627","pt":1724339894480,"mc":[{"id":"1.232135506","rc":[{"batb":[[0,1.94,10]],"ltp":2.42,"tv":0.82,"id":72963954}]}]}
{"op":"mcm","clk":"11935156752","pt":1724339895400,"mc":[{"id":"1.232135506","rc":[{"batb":[[0,1.93,6.15],[1,1.9,5.69],[2,1.8,6.41]],"ltp":2.42,"tv":0.82,"id":72963954}]}]}
{"op":"mcm","clk":"11935159034","pt":1724339916509,"mc":[{"id":"1.232135506","rc":[{"batb":[[0,1.94,14],[1,1.93,6.15],[2,1.9,5.69]],"ltp":2.42,"tv":0.82,"id":72963954}]}]}
{"op":"mcm","clk":"11935159356","pt":1724339919153,"mc":[{"id":"1.232135506","rc":[{"batb":[[0,1.94,10]],"ltp":2.42,"tv":0.82,"id":72963954}]}]}
{"op":"mcm","clk":"11935159479","pt":1724339920137,"mc":[{"id":"1.232135506","rc":[{"batb":[[0,1.93,6.15],[1,1.9,5.69],[2,1.8,6.41]],"ltp":2.42,"tv":0.82,"id":72963954}]}]}
{"op":"mcm","clk":"11935160687","pt":1724339930245,"mc":[{"id":"1.232135506","rc":[{"batb":[[0,1.94,14],[1,1.93,6.15],[2,1.9,5.69]],"ltp":2.42,"tv":0.82,"id":72963954}]}]}
{"op":"mcm","clk":"11935160943","pt":1724339932633,"mc":[{"id":"1.232135506","rc":[{"batb":[[0,1.94,10]],"ltp":2.42,"tv":0.82,"id":72963954}]}]}
{"op":"mcm","clk":"11935161107","pt":1724339933561,"mc":[{"id":"1.232135506","rc":[{"batb":[[0,1.93,6.15],[1,1.9,5.69],[2,1.8,6.41]],"ltp":2.42,"tv":0.82,"id":72963954}]}]}
{"op":"mcm","clk":"11935161580","pt":1724339937663,"mc":[{"id":"1.232135506","rc":[{"batb":[[0,1.94,14],[1,1.93,6.15],[2,1.9,5.69]],"ltp":2.42,"tv":0.82,"id":72963954}]}]}
{"op":"mcm","clk":"11935161838","pt":1724339939948,"mc":[{"id":"1.232135506","rc":[{"batb":[[0,1.94,10]],"ltp":2.42,"tv":0.82,"id":72963954}]}]}
{"op":"mcm","clk":"11935161956","pt":1724339940944,"mc":[{"id":"1.232135506","rc":[{"batb":[[0,1.93,6.15],[1,1.9,5.69],[2,1.8,6.41]],"ltp":2.42,"tv":0.82,"id":72963954}]}]}
{"op":"mcm","clk":"11935163992","pt":1724339957490,"mc":[{"id":"1.232135506","rc":[{"batb":[[0,1.94,14],[1,1.93,6.15],[2,1.9,5.69]],"ltp":2.42,"tv":0.82,"id":72963954}]}]}
{"op":"mcm","clk":"11935164231","pt":1724339960026,"mc":[{"id":"1.232135506","rc":[{"batb":[[0,1.94,10]],"ltp":2.42,"tv":0.82,"id":72963954}]}]}
{"op":"mcm","clk":"11935164368","pt":1724339961124,"mc":[{"id":"1.232135506","rc":[{"batb":[[0,1.93,6.15],[1,1.9,5.69],[2,1.8,6.41]],"ltp":2.42,"tv":0.82,"id":72963954}]}]}
{"op":"mcm","clk":"11935165287","pt":1724339970408,"mc":[{"id":"1.232135506","rc":[{"batb":[[0,1.94,14],[1,1.93,6.15],[2,1.9,5.69]],"ltp":2.42,"tv":0.82,"id":72963954}]}]}
{"op":"mcm","clk":"11935165571","pt":1724339972915,"mc":[{"id":"1.232135506","rc":[{"batb":[[0,1.94,10]],"ltp":2.42,"tv":0.82,"id":72963954}]}]}
{"op":"mcm","clk":"11935165706","pt":1724339974036,"mc":[{"id":"1.232135506","rc":[{"batb":[[0,1.93,6.15],[1,1.9,5.69],[2,1.8,6.41]],"ltp":2.42,"tv":0.82,"id":72963954}]}]}
{"op":"mcm","clk":"11935166179","pt":1724339978545,"mc":[{"id":"1.232135506","rc":[{"batb":[[0,1.94,14],[1,1.93,6.15],[2,1.9,5.69]],"ltp":2.42,"tv":0.82,"id":72963954}]}]}
{"op":"mcm","clk":"11935166441","pt":1724339980844,"mc":[{"id":"1.232135506","rc":[{"batb":[[0,1.94,10]],"ltp":2.42,"tv":0.82,"id":72963954}]}]}
{"op":"mcm","clk":"11935166575","pt":1724339981840,"mc":[{"id":"1.232135506","rc":[{"batb":[[0,1.93,6.15],[1,1.9,5.69],[2,1.8,6.41]],"ltp":2.42,"tv":0.82,"id":72963954}]}]}
{"op":"mcm","clk":"11935168621","pt":1724339999740,"mc":[{"id":"1.232135506","rc":[{"batb":[[0,1.94,14],[1,1.93,6.15],[2,1.9,5.69]],"ltp":2.42,"tv":0.82,"id":72963954}]}]}
{"op":"mcm","clk":"11935168911","pt":1724340002377,"mc":[{"id":"1.232135506","rc":[{"batb":[[0,1.94,10]],"ltp":2.42,"tv":0.82,"id":72963954}]}]}
{"op":"mcm","clk":"11935169047","pt":1724340003471,"mc":[{"id":"1.232135506","rc":[{"batb":[[0,1.93,6.15],[1,1.9,5.69],[2,1.8,6.41]],"ltp":2.42,"tv":0.82,"id":72963954}]}]}
{"op":"mcm","clk":"11935169461","pt":1724340007382,"mc":[{"id":"1.232135506","rc":[{"batb":[[0,1.94,14],[1,1.93,6.15],[2,1.9,5.69]],"ltp":2.42,"tv":0.82,"id":72963954}]}]}
{"op":"mcm","clk":"11935169769","pt":1724340010088,"mc":[{"id":"1.232135506","rc":[{"batb":[[0,1.94,10]],"ltp":2.42,"tv":0.82,"id":72963954}]}]}
{"op":"mcm","clk":"11935169870","pt":1724340010877,"mc":[{"id":"1.232135506","rc":[{"batb":[[0,1.93,6.15],[1,1.9,5.69],[2,1.8,6.41]],"ltp":2.42,"tv":0.82,"id":72963954}]}]}
{"op":"mcm","clk":"11935170107","pt":1724340013168,"mc":[{"id":"1.232135506","rc":[{"batb":[[0,1.94,14],[1,1.93,6.15],[2,1.9,5.69]],"ltp":2.42,"tv":0.82,"id":72963954}]}]}
{"op":"mcm","clk":"11935170405","pt":1724340015790,"mc":[{"id":"1.232135506","rc":[{"batb":[[0,1.94,10]],"ltp":2.42,"tv":0.82,"id":72963954}]}]}
{"op":"mcm","clk":"11935170521","pt":1724340016776,"mc":[{"id":"1.232135506","rc":[{"batb":[[0,1.93,6.15],[1,1.9,5.69],[2,1.8,6.41]],"ltp":2.42,"tv":0.82,"id":72963954}]}]}
{"op":"mcm","clk":"11935171187","pt":1724340022386,"mc":[{"id":"1.232135506","rc":[{"batb":[[0,1.94,14],[1,1.93,6.15],[2,1.9,5.69]],"ltp":2.42,"tv":0.82,"id":72963954}]}]}
{"op":"mcm","clk":"11935171462","pt":1724340024990,"mc":[{"id":"1.232135506","rc":[{"batb":[[0,1.94,10]],"ltp":2.42,"tv":0.82,"id":72963954}]}]}
{"op":"mcm","clk":"11935171570","pt":1724340025890,"mc":[{"id":"1.232135506","rc":[{"batb":[[0,1.93,6.15],[1,1.9,5.69],[2,1.8,6.41]],"ltp":2.42,"tv":0.82,"id":72963954}]}]}
{"op":"mcm","clk":"11935172946","pt":1724340037635,"mc":[{"id":"1.232135506","rc":[{"batb":[[0,1.94,14],[1,1.93,6.15],[2,1.9,5.69]],"ltp":2.42,"tv":0.82,"id":72963954}]}]}
{"op":"mcm","clk":"11935173252","pt":1724340040094,"mc":[{"id":"1.232135506","rc":[{"batb":[[0,1.94,10]],"ltp":2.42,"tv":0.82,"id":72963954}]}]}
{"op":"mcm","clk":"11935173378","pt":1724340041097,"mc":[{"id":"1.232135506","rc":[{"batb":[[0,1.93,6.15],[1,1.9,5.69],[2,1.8,6.41]],"ltp":2.42,"tv":0.82,"id":72963954}]}]}
{"op":"mcm","clk":"11935175387","pt":1724340058853,"mc":[{"id":"1.232135506","rc":[{"batb":[[0,1.94,14],[1,1.93,6.15],[2,1.9,5.69]],"ltp":2.42,"tv":0.82,"id":72963954}]}]}
{"op":"mcm","clk":"11935175781","pt":1724340062077,"mc":[{"id":"1.232135506","rc":[{"batb":[[0,1.94,10]],"ltp":2.42,"tv":0.82,"id":72963954}]}]}
{"op":"mcm","clk":"11935175879","pt":1724340062896,"mc":[{"id":"1.232135506","rc":[{"batb":[[0,1.93,6.15],[1,1.9,5.69],[2,1.8,6.41]],"ltp":2.42,"tv":0.82,"id":72963954}]}]}
{"op":"mcm","clk":"11935176095","pt":1724340064425,"mc":[{"id":"1.232135506","rc":[{"batb":[[0,1.94,4],[1,1.93,6.15],[2,1.9,5.69]],"ltp":2.42,"tv":0.82,"id":72963954}]}]}
{"op":"mcm","clk":"11935176157","pt":1724340064948,"mc":[{"id":"1.232135506","rc":[{"batb":[[0,1.95,10],[1,1.94,4],[2,1.93,6.15]],"ltp":2.42,"tv":0.82,"id":72963954}]}]}
{"op":"mcm","clk":"11935176404","pt":1724340067041,"mc":[{"id":"1.232135506","rc":[{"batb":[[1,1.93,6.15],[2,1.9,5.69]],"ltp":2.42,"tv":0.82,"id":72963954}]}]}
{"op":"mcm","clk":"11935176573","pt":1724340068340,"mc":[{"id":"1.232135506","rc":[{"batb":[[0,1.93,6.15],[1,1.9,5.69],[2,1.8,6.41]],"ltp":2.42,"tv":0.82,"id":72963954}]}]}
{"op":"mcm","clk":"11935178571","pt":1724340086552,"mc":[{"id":"1.232135506","rc":[{"trd":[[1.94,1.92]],"batl":[[0,1.94,6.97]],"ltp":1.94,"tv":181.87,"id":47674067},{"batb":[[0,1.94,14],[1,1.93,6.15],[2,1.9,5.69]],"ltp":2.42,"tv":0.82,"id":72963954}],"tv":182.69}]}
{"op":"mcm","clk":"11935178825","pt":1724340088953,"mc":[{"id":"1.232135506","rc":[{"batb":[[0,1.94,10]],"ltp":2.42,"tv":0.82,"id":72963954}]}]}
{"op":"mcm","clk":"11935178920","pt":1724340089891,"mc":[{"id":"1.232135506","rc":[{"batb":[[0,1.93,6.15],[1,1.9,5.69],[2,1.8,6.41]],"ltp":2.42,"tv":0.82,"id":72963954}]}]}
{"op":"mcm","clk":"11935179771","pt":1724340097688,"mc":[{"id":"1.232135506","rc":[{"batb":[[0,1.94,14],[1,1.93,6.15],[2,1.9,5.69]],"ltp":2.42,"tv":0.82,"id":72963954}]}]}
{"op":"mcm","clk":"11935180083","pt":1724340100194,"mc":[{"id":"1.232135506","rc":[{"batb":[[0,1.94,10]],"ltp":2.42,"tv":0.82,"id":72963954}]}]}
{"op":"mcm","clk":"11935180205","pt":1724340101082,"mc":[{"id":"1.232135506","rc":[{"batb":[[0,1.93,6.15],[1,1.9,5.69],[2,1.8,6.41]],"ltp":2.42,"tv":0.82,"id":72963954}]}]}
{"op":"mcm","clk":"11935180465","pt":1724340103356,"mc":[{"id":"1.232135506","rc":[{"batb":[[0,1.95,10],[1,1.94,4],[2,1.93,6.15]],"ltp":2.42,"tv":0.82,"id":72963954}]}]}
{"op":"mcm","clk":"11935180652","pt":1724340105309,"mc":[{"id":"1.232135506","rc":[{"batb":[[1,1.93,6.15],[2,1.9,5.69]],"ltp":2.42,"tv":0.82,"id":72963954}]}]}
{"op":"mcm","clk":"11935180813","pt":1724340106663,"mc":[{"id":"1.232135506","rc":[{"batb":[[0,1.93,6.15],[1,1.9,5.69],[2,1.8,6.41]],"ltp":2.42,"tv":0.82,"id":72963954}]}]}
{"op":"mcm","clk":"11935183060","pt":1724340126919,"mc":[{"id":"1.232135506","rc":[{"batb":[[0,1.94,14],[1,1.93,6.15],[2,1.9,5.69]],"ltp":2.42,"tv":0.82,"id":72963954}]}]}
{"op":"mcm","clk":"11935183334","pt":1724340129419,"mc":[{"id":"1.232135506","rc":[{"batb":[[0,1.94,10]],"ltp":2.42,"tv":0.82,"id":72963954}]}]}
{"op":"mcm","clk":"11935183447","pt":1724340130516,"mc":[{"id":"1.232135506","rc":[{"batb":[[0,1.93,6.15],[1,1.9,5.69],[2,1.8,6.41]],"ltp":2.42,"tv":0.82,"id":72963954}]}]}
{"op":"mcm","clk":"11935183849","pt":1724340134540,"mc":[{"id":"1.232135506","rc":[{"batb":[[0,1.94,14],[1,1.93,6.15],[2,1.9,5.69]],"ltp":2.42,"tv":0.82,"id":72963954}]}]}
{"op":"mcm","clk":"11935184061","pt":1724340136925,"mc":[{"id":"1.232135506","rc":[{"batb":[[0,1.94,10]],"ltp":2.42,"tv":0.82,"id":72963954}]}]}
{"op":"mcm","clk":"11935184181","pt":1724340138021,"mc":[{"id":"1.232135506","rc":[{"batb":[[0,1.93,6.15],[1,1.9,5.69],[2,1.8,6.41]],"ltp":2.42,"tv":0.82,"id":72963954}]}]}
{"op":"mcm","clk":"11935184582","pt":1724340143248,"mc":[{"id":"1.232135506","rc":[{"batb":[[0,1.94,14],[1,1.93,6.15],[2,1.9,5.69]],"ltp":2.42,"tv":0.82,"id":72963954}]}]}
{"op":"mcm","clk":"11935184839","pt":1724340145744,"mc":[{"id":"1.232135506","rc":[{"batb":[[0,1.94,10]],"ltp":2.42,"tv":0.82,"id":72963954}]}]}
{"op":"mcm","clk":"11935184925","pt":1724340146750,"mc":[{"id":"1.232135506","rc":[{"batb":[[0,1.93,6.15],[1,1.9,5.69],[2,1.8,6.41]],"ltp":2.42,"tv":0.82,"id":72963954}]}]}
{"op":"mcm","clk":"11935185069","pt":1724340148534,"mc":[{"id":"1.232135506","rc":[{"batb":[[0,1.94,4],[1,1.93,6.15],[2,1.9,5.69]],"ltp":2.42,"tv":0.82,"id":72963954}]}]}
{"op":"mcm","clk":"11935185309","pt":1724340151328,"mc":[{"id":"1.232135506","rc":[{"batb":[[0,1.94,10]],"ltp":2.42,"tv":0.82,"id":72963954}]}]}
{"op":"mcm","clk":"11935185586","pt":1724340154639,"mc":[{"id":"1.232135506","rc":[{"batb":[[0,1.93,6.15],[1,1.9,5.69],[2,1.8,6.41]],"ltp":2.42,"tv":0.82,"id":72963954}]}]}
{"op":"mcm","clk":"11935185601","pt":1724340154846,"mc":[{"id":"1.232135506","rc":[{"batb":[[0,1.94,4],[1,1.93,6.15],[2,1.9,5.69]],"ltp":2.42,"tv":0.82,"id":72963954}]}]}
{"op":"mcm","clk":"11935185831","pt":1724340157271,"mc":[{"id":"1.232135506","rc":[{"batb":[[0,1.94,10]],"ltp":2.42,"tv":0.82,"id":72963954}]}]}
{"op":"mcm","clk":"11935186095","pt":1724340159739,"mc":[{"id":"1.232135506","rc":[{"batb":[[0,1.95,4],[1,1.94,10],[2,1.93,6.15]],"ltp":2.42,"tv":0.82,"id":72963954}]}]}
{"op":"mcm","clk":"11935186178","pt":1724340160462,"mc":[{"id":"1.232135506","rc":[{"batb":[[1,1.93,6.15],[2,1.9,5.69]],"ltp":2.42,"tv":0.82,"id":72963954}]}]}
{"op":"mcm","clk":"11935186337","pt":1724340162169,"mc":[{"id":"1.232135506","rc":[{"batb":[[0,1.93,6.15],[1,1.9,5.69],[2,1.8,6.41]],"ltp":2.42,"tv":0.82,"id":72963954}]}]}
{"op":"mcm","clk":"11935186689","pt":1724340165968,"mc":[{"id":"1.232135506","rc":[{"batb":[[0,1.94,14],[1,1.93,6.15],[2,1.9,5.69]],"ltp":2.42,"tv":0.82,"id":72963954}]}]}
{"op":"mcm","clk":"11935186928","pt":1724340168366,"mc":[{"id":"1.232135506","rc":[{"batb":[[0,1.94,10]],"ltp":2.42,"tv":0.82,"id":72963954}]}]}
{"op":"mcm","clk":"11935187041","pt":1724340169581,"mc":[{"id":"1.232135506","rc":[{"batb":[[0,1.93,6.15],[1,1.9,5.69],[2,1.8,6.41]],"ltp":2.42,"tv":0.82,"id":72963954}]}]}
{"op":"mcm","clk":"11935187231","pt":1724340171971,"mc":[{"id":"1.232135506","rc":[{"batb":[[0,1.95,10],[1,1.94,4],[2,1.93,6.15]],"ltp":2.42,"tv":0.82,"id":72963954}]}]}
{"op":"mcm","clk":"11935187493","pt":1724340173989,"mc":[{"id":"1.232135506","rc":[{"batb":[[1,1.93,6.15],[2,1.9,5.69]],"ltp":2.42,"tv":0.82,"id":72963954}]}]}
{"op":"mcm","clk":"11935187601","pt":1724340175185,"mc":[{"id":"1.232135506","rc":[{"batb":[[0,1.93,6.15],[1,1.9,5.69],[2,1.8,6.41]],"ltp":2.42,"tv":0.82,"id":72963954}]}]}
{"op":"mcm","clk":"11935188121","pt":1724340180491,"mc":[{"id":"1.232135506","rc":[{"batb":[[0,1.94,14],[1,1.93,6.15],[2,1.9,5.69]],"ltp":2.42,"tv":0.82,"id":72963954}]}]}
{"op":"mcm","clk":"11935188376","pt":1724340183011,"mc":[{"id":"1.232135506","rc":[{"batb":[[0,1.94,10]],"ltp":2.42,"tv":0.82,"id":72963954}]}]}
{"op":"mcm","clk":"11935188461","pt":1724340183896,"mc":[{"id":"1.232135506","rc":[{"batb":[[0,1.93,6.15],[1,1.9,5.69],[2,1.8,6.41]],"ltp":2.42,"tv":0.82,"id":72963954}]}]}
{"op":"mcm","clk":"11935189570","pt":1724340194708,"mc":[{"id":"1.232135506","rc":[{"batb":[[0,1.94,14],[1,1.93,6.15],[2,1.9,5.69]],"ltp":2.42,"tv":0.82,"id":72963954}]}]}
{"op":"mcm","clk":"11935189823","pt":1724340197526,"mc":[{"id":"1.232135506","rc":[{"batb":[[0,1.94,10]],"ltp":2.42,"tv":0.82,"id":72963954}]}]}
{"op":"mcm","clk":"11935189939","pt":1724340198430,"mc":[{"id":"1.232135506","rc":[{"batb":[[0,1.93,6.15],[1,1.9,5.69],[2,1.8,6.41]],"ltp":2.42,"tv":0.82,"id":72963954}]}]}
{"op":"mcm","clk":"11935191903","pt":1724340219638,"mc":[{"id":"1.232135506","rc":[{"batb":[[0,1.94,14],[1,1.93,6.15],[2,1.9,5.69]],"ltp":2.42,"tv":0.82,"id":72963954}]}]}
{"op":"mcm","clk":"11935192122","pt":1724340222043,"mc":[{"id":"1.232135506","rc":[{"batb":[[0,1.94,10]],"ltp":2.42,"tv":0.82,"id":72963954}]}]}
{"op":"mcm","clk":"11935192225","pt":1724340223064,"mc":[{"id":"1.232135506","rc":[{"batb":[[0,1.93,6.15],[1,1.9,5.69],[2,1.8,6.41]],"ltp":2.42,"tv":0.82,"id":72963954}]}]}
{"op":"mcm","clk":"11935192468","pt":1724340225452,"mc":[{"id":"1.232135506","rc":[{"batb":[[0,1.94,14],[1,1.93,6.15],[2,1.9,5.69]],"ltp":2.42,"tv":0.82,"id":72963954}]}]}
{"op":"mcm","clk":"11935192688","pt":1724340228055,"mc":[{"id":"1.232135506","rc":[{"batb":[[0,1.94,10]],"ltp":2.42,"tv":0.82,"id":72963954}]}]}
{"op":"mcm","clk":"11935192781","pt":1724340228944,"mc":[{"id":"1.232135506","rc":[{"batb":[[0,1.93,6.15],[1,1.9,5.69],[2,1.8,6.41]],"ltp":2.42,"tv":0.82,"id":72963954}]}]}
{"op":"mcm","clk":"11935193143","pt":1724340232650,"mc":[{"id":"1.232135506","rc":[{"batb":[[0,1.94,14],[1,1.93,6.15],[2,1.9,5.69]],"ltp":2.42,"tv":0.82,"id":72963954}]}]}
{"op":"mcm","clk":"11935193378","pt":1724340235284,"mc":[{"id":"1.232135506","rc":[{"batb":[[0,1.94,10]],"ltp":2.42,"tv":0.82,"id":72963954}]}]}
{"op":"mcm","clk":"11935193475","pt":1724340236275,"mc":[{"id":"1.232135506","rc":[{"batb":[[0,1.93,6.15],[1,1.9,5.69],[2,1.8,6.41]],"ltp":2.42,"tv":0.82,"id":72963954}]}]}
{"op":"mcm","clk":"11935193818","pt":1724340240075,"mc":[{"id":"1.232135506","rc":[{"batb":[[0,1.94,14],[1,1.93,6.15],[2,1.9,5.69]],"ltp":2.42,"tv":0.82,"id":72963954}]}]}
{"op":"mcm","clk":"11935194053","pt":1724340242691,"mc":[{"id":"1.232135506","rc":[{"batb":[[0,1.94,10]],"ltp":2.42,"tv":0.82,"id":72963954}]}]}
{"op":"mcm","clk":"11935194160","pt":1724340243685,"mc":[{"id":"1.232135506","rc":[{"batb":[[0,1.93,6.15],[1,1.9,5.69],[2,1.8,6.41]],"ltp":2.42,"tv":0.82,"id":72963954}]}]}
{"op":"mcm","clk":"11935194852","pt":1724340250392,"mc":[{"id":"1.232135506","rc":[{"batb":[[0,1.71,10.92]],"ltp":1.94,"tv":181.87,"id":47674067},{"batb":[[0,1.96,10],[1,1.95,4],[2,1.94,1]],"ltp":2.42,"tv":0.82,"id":72963954}]}]}
{"op":"mcm","clk":"11935195064","pt":1724340252592,"mc":[{"id":"1.232135506","rc":[{"batb":[[1,1.94,1],[2,1.93,6.15]],"ltp":2.42,"tv":0.82,"id":72963954}]}]}
{"op":"mcm","clk":"11935195140","pt":1724340253587,"mc":[{"id":"1.232135506","rc":[{"batb":[[0,1.94,1],[1,1.93,6.15],[2,1.9,5.69]],"ltp":2.42,"tv":0.82,"id":72963954}]}]}
{"op":"mcm","clk":"11935195447","pt":1724340257195,"mc":[{"id":"1.232135506","rc":[{"batb":[[0,1.95,4],[1,1.94,1],[2,1.93,6.15]],"ltp":2.42,"tv":0.82,"id":72963954}]}]}
{"op":"mcm","clk":"11935195525","pt":1724340257797,"mc":[{"id":"1.232135506","rc":[{"batb":[[0,1.96,10],[1,1.95,4],[2,1.94,1]],"ltp":2.42,"tv":0.82,"id":72963954}]}]}
{"op":"mcm","clk":"11935195699","pt":1724340259692,"mc":[{"id":"1.232135506","rc":[{"batb":[[1,1.94,1],[2,1.93,6.15]],"ltp":2.42,"tv":0.82,"id":72963954}]}]}
{"op":"mcm","clk":"11935195854","pt":1724340261099,"mc":[{"id":"1.232135506","rc":[{"batb":[[0,1.94,1],[1,1.93,6.15],[2,1.9,5.69]],"ltp":2.42,"tv":0.82,"id":72963954}]}]}
{"op":"mcm","clk":"11935196749","pt":1724340270510,"mc":[{"id":"1.232135506","rc":[{"batb":[[0,1.96,10],[1,1.95,4],[2,1.94,1]],"ltp":2.42,"tv":0.82,"id":72963954}]}]}
{"op":"mcm","clk":"11935196974","pt":1724340272606,"mc":[{"id":"1.232135506","rc":[{"batb":[[1,1.94,1],[2,1.93,6.15]],"ltp":2.42,"tv":0.82,"id":72963954}]}]}
{"op":"mcm","clk":"11935197100","pt":1724340273830,"mc":[{"id":"1.232135506","rc":[{"batb":[[0,1.94,1],[1,1.93,6.15],[2,1.9,5.69]],"ltp":2.42,"tv":0.82,"id":72963954}]}]}
{"op":"mcm","clk":"11935197848","pt":1724340281430,"mc":[{"id":"1.232135506","rc":[{"batb":[[0,1.96,10],[1,1.95,4],[2,1.94,1]],"ltp":2.42,"tv":0.82,"id":72963954}]}]}
{"op":"mcm","clk":"11935198054","pt":1724340283540,"mc":[{"id":"1.232135506","rc":[{"batb":[[1,1.94,1],[2,1.93,6.15]],"ltp":2.42,"tv":0.82,"id":72963954}]}]}
{"op":"mcm","clk":"11935198182","pt":1724340284929,"mc":[{"id":"1.232135506","rc":[{"batb":[[0,1.94,1],[1,1.93,6.15],[2,1.9,5.69]],"ltp":2.42,"tv":0.82,"id":72963954}]}]}
{"op":"mcm","clk":"11935199619","pt":1724340298748,"mc":[{"id":"1.232135506","rc":[{"batb":[[0,1.95,4],[1,1.94,1],[2,1.93,6.15]],"ltp":2.42,"tv":0.82,"id":72963954}]}]}
{"op":"mcm","clk":"11935199670","pt":1724340299265,"mc":[{"id":"1.232135506","rc":[{"batb":[[0,1.96,10],[1,1.95,4],[2,1.94,1]],"ltp":2.42,"tv":0.82,"id":72963954}]}]}
{"op":"mcm","clk":"11935199881","pt":1724340301265,"mc":[{"id":"1.232135506","rc":[{"batb":[[1,1.94,1],[2,1.93,6.15]],"ltp":2.42,"tv":0.82,"id":72963954}]}]}
{"op":"mcm","clk":"11935200092","pt":1724340302978,"mc":[{"id":"1.232135506","rc":[{"batb":[[0,1.94,1],[1,1.93,6.15],[2,1.9,5.69]],"ltp":2.42,"tv":0.82,"id":72963954}]}]}
{"op":"mcm","clk":"11935201579","pt":1724340317397,"mc":[{"id":"1.232135506","rc":[{"batb":[[0,1.96,10],[1,1.95,4],[2,1.94,1]],"ltp":2.42,"tv":0.82,"id":72963954}]}]}
{"op":"mcm","clk":"11935201824","pt":1724340319594,"mc":[{"id":"1.232135506","rc":[{"batb":[[1,1.94,1],[2,1.93,6.15]],"ltp":2.42,"tv":0.82,"id":72963954}]}]}
{"op":"mcm","clk":"11935202079","pt":1724340321676,"mc":[{"id":"1.232135506","rc":[{"batb":[[0,1.71,1.13]],"ltp":1.94,"tv":181.87,"id":47674067},{"batb":[[0,1.94,1],[1,1.93,6.15],[2,1.9,5.69]],"ltp":2.42,"tv":0.82,"id":72963954}]}]}
{"op":"mcm","clk":"11935202091","pt":1724340321885,"mc":[{"id":"1.232135506","rc":[{"batb":[[0,1.95,4],[1,1.94,1],[2,1.93,6.15]],"ltp":2.42,"tv":0.82,"id":72963954}]}]}
{"op":"mcm","clk":"11935202313","pt":1724340324192,"mc":[{"id":"1.232135506","rc":[{"batb":[[0,1.94,1],[1,1.93,6.15],[2,1.9,5.69]],"ltp":2.42,"tv":0.82,"id":72963954}]}]}
{"op":"mcm","clk":"11935204082","pt":1724340342701,"mc":[{"id":"1.232135506","rc":[{"batb":[[0,1.72,10.75],[1,1.71,1.13],[2,1.7,18.56]],"ltp":1.94,"tv":181.87,"id":47674067}]}]}
{"op":"mcm","clk":"11935204108","pt":1724340343008,"mc":[{"id":"1.232135506","rc":[{"batb":[[0,1.96,10],[1,1.95,4],[2,1.94,1]],"ltp":2.42,"tv":0.82,"id":72963954}]}]}
{"op":"mcm","clk":"11935204294","pt":1724340344980,"mc":[{"id":"1.232135506","rc":[{"batb":[[1,1.94,1],[2,1.93,6.15]],"ltp":2.42,"tv":0.82,"id":72963954}]}]}
{"op":"mcm","clk":"11935204406","pt":1724340346174,"mc":[{"id":"1.232135506","rc":[{"batb":[[0,1.94,1],[1,1.93,6.15],[2,1.9,5.69]],"ltp":2.42,"tv":0.82,"id":72963954}]}]}
{"op":"mcm","clk":"11935205686","pt":1724340359735,"mc":[{"id":"1.232135506","rc":[{"batb":[[0,1.95,4],[1,1.94,1],[2,1.93,6.15]],"ltp":2.42,"tv":0.82,"id":72963954}]}]}
{"op":"mcm","clk":"11935205722","pt":1724340360060,"mc":[{"id":"1.232135506","rc":[{"batb":[[0,1.96,10],[1,1.95,4],[2,1.94,1]],"ltp":2.42,"tv":0.82,"id":72963954}]}]}
{"op":"mcm","clk":"11935205932","pt":1724340361929,"mc":[{"id":"1.232135506","rc":[{"batb":[[1,1.94,1],[2,1.93,6.15]],"ltp":2.42,"tv":0.82,"id":72963954}]}]}
{"op":"mcm","clk":"11935206065","pt":1724340363291,"mc":[{"id":"1.232135506","rc":[{"batb":[[0,1.94,1],[1,1.93,6.15],[2,1.9,5.69]],"ltp":2.42,"tv":0.82,"id":72963954}]}]}
{"op":"mcm","clk":"11935206437","pt":1724340367211,"mc":[{"id":"1.232135506","rc":[{"batb":[[0,1.96,10],[1,1.95,4],[2,1.94,1]],"ltp":2.42,"tv":0.82,"id":72963954}]}]}
{"op":"mcm","clk":"11935206675","pt":1724340369407,"mc":[{"id":"1.232135506","rc":[{"batb":[[1,1.94,1],[2,1.93,6.15]],"ltp":2.42,"tv":0.82,"id":72963954}]}]}
{"op":"mcm","clk":"11935206789","pt":1724340370494,"mc":[{"id":"1.232135506","rc":[{"batb":[[0,1.94,1],[1,1.93,6.15],[2,1.9,5.69]],"ltp":2.42,"tv":0.82,"id":72963954}]}]}
{"op":"mcm","clk":"11935210273","pt":1724340404999,"mc":[{"id":"1.232135506","rc":[{"batb":[[0,1.96,10],[1,1.95,4],[2,1.94,1]],"ltp":2.42,"tv":0.82,"id":72963954}]}]}
{"op":"mcm","clk":"11935210525","pt":1724340407185,"mc":[{"id":"1.232135506","rc":[{"batb":[[1,1.94,1],[2,1.93,6.15]],"ltp":2.42,"tv":0.82,"id":72963954}]}]}
{"op":"mcm","clk":"11935210670","pt":1724340408626,"mc":[{"id":"1.232135506","rc":[{"batb":[[0,1.94,1],[1,1.93,6.15],[2,1.9,5.69]],"ltp":2.42,"tv":0.82,"id":72963954}]}]}
{"op":"mcm","clk":"11935213079","pt":1724340430756,"mc":[{"id":"1.232135506","rc":[{"batb":[[0,1.96,10],[1,1.95,4],[2,1.94,1]],"ltp":2.42,"tv":0.82,"id":72963954}]}]}
{"op":"mcm","clk":"11935213301","pt":1724340432931,"mc":[{"id":"1.232135506","rc":[{"batb":[[1,1.94,1],[2,1.93,6.15]],"ltp":2.42,"tv":0.82,"id":72963954}]}]}
{"op":"mcm","clk":"11935213451","pt":1724340434434,"mc":[{"id":"1.232135506","rc":[{"batb":[[0,1.94,1],[1,1.93,6.15],[2,1.9,5.69]],"ltp":2.42,"tv":0.82,"id":72963954}]}]}
{"op":"mcm","clk":"11935214260","pt":1724340442152,"mc":[{"id":"1.232135506","rc":[{"batb":[[0,1.96,10],[1,1.95,4],[2,1.94,1]],"ltp":2.42,"tv":0.82,"id":72963954}]}]}
{"op":"mcm","clk":"11935214499","pt":1724340444334,"mc":[{"id":"1.232135506","rc":[{"batb":[[1,1.94,1],[2,1.93,6.15]],"ltp":2.42,"tv":0.82,"id":72963954}]}]}
{"op":"mcm","clk":"11935214632","pt":1724340445389,"mc":[{"id":"1.232135506","rc":[{"batb":[[0,1.94,1],[1,1.93,6.15],[2,1.9,5.69]],"ltp":2.42,"tv":0.82,"id":72963954}]}]}
{"op":"mcm","clk":"11935218015","pt":1724340478706,"mc":[{"id":"1.232135506","rc":[{"batb":[[0,1.95,4],[1,1.94,1],[2,1.93,6.15]],"ltp":2.42,"tv":0.82,"id":72963954}]}]}
{"op":"mcm","clk":"11935218036","pt":1724340479009,"mc":[{"id":"1.232135506","rc":[{"batb":[[0,1.96,10],[1,1.95,4],[2,1.94,1]],"ltp":2.42,"tv":0.82,"id":72963954}]}]}
{"op":"mcm","clk":"11935218207","pt":1724340480902,"mc":[{"id":"1.232135506","rc":[{"batb":[[1,1.94,1],[2,1.93,6.15]],"ltp":2.42,"tv":0.82,"id":72963954}]}]}
{"op":"mcm","clk":"11935218341","pt":1724340482403,"mc":[{"id":"1.232135506","rc":[{"batb":[[0,1.94,1],[1,1.93,6.15],[2,1.9,5.69]],"ltp":2.42,"tv":0.82,"id":72963954}]}]}
{"op":"mcm","clk":"11935220366","pt":1724340501128,"mc":[{"id":"1.232135506","rc":[{"batb":[[0,1.96,10],[1,1.95,4],[2,1.94,1]],"ltp":2.42,"tv":0.82,"id":72963954}]}]}
{"op":"mcm","clk":"11935220595","pt":1724340503454,"mc":[{"id":"1.232135506","rc":[{"batb":[[1,1.94,1],[2,1.93,6.15]],"ltp":2.42,"tv":0.82,"id":72963954}]}]}
{"op":"mcm","clk":"11935220700","pt":1724340504644,"mc":[{"id":"1.232135506","rc":[{"batb":[[0,1.94,1],[1,1.93,6.15],[2,1.9,5.69]],"ltp":2.42,"tv":0.82,"id":72963954}]}]}
{"op":"mcm","clk":"11935220810","pt":1724340505834,"mc":[{"id":"1.232135506","rc":[{"batb":[[0,1.95,4],[1,1.94,1],[2,1.93,6.15]],"ltp":2.42,"tv":0.82,"id":72963954}]}]}
{"op":"mcm","clk":"11935221023","pt":1724340508156,"mc":[{"id":"1.232135506","rc":[{"batb":[[0,1.94,1],[1,1.93,6.15],[2,1.9,5.69]],"ltp":2.42,"tv":0.82,"id":72963954}]}]}
{"op":"mcm","clk":"11935221836","pt":1724340516620,"mc":[{"id":"1.232135506","rc":[{"batb":[[0,1.96,10],[1,1.95,4],[2,1.94,1]],"ltp":2.42,"tv":0.82,"id":72963954}]}]}
{"op":"mcm","clk":"11935222008","pt":1724340518568,"mc":[{"id":"1.232135506","rc":[{"batb":[[1,1.94,1],[2,1.93,6.15]],"ltp":2.42,"tv":0.82,"id":72963954}]}]}
{"op":"mcm","clk":"11935222143","pt":1724340519965,"mc":[{"id":"1.232135506","rc":[{"batb":[[0,1.94,1],[1,1.93,6.15],[2,1.9,5.69]],"ltp":2.42,"tv":0.82,"id":72963954}]}]}
{"op":"mcm","clk":"11935223711","pt":1724340537465,"mc":[{"id":"1.232135506","rc":[{"batb":[[0,1.96,10],[1,1.95,4],[2,1.94,1]],"ltp":2.42,"tv":0.82,"id":72963954}]}]}
{"op":"mcm","clk":"11935223936","pt":1724340539631,"mc":[{"id":"1.232135506","rc":[{"batb":[[1,1.94,1],[2,1.93,6.15]],"ltp":2.42,"tv":0.82,"id":72963954}]}]}
{"op":"mcm","clk":"11935224044","pt":1724340540675,"mc":[{"id":"1.232135506","rc":[{"batb":[[0,1.94,1],[1,1.93,6.15],[2,1.9,5.69]],"ltp":2.42,"tv":0.82,"id":72963954}]}]}
{"op":"mcm","clk":"11935224800","pt":1724340548283,"mc":[{"id":"1.232135506","rc":[{"batb":[[0,1.96,10],[1,1.95,4],[2,1.94,1]],"ltp":2.42,"tv":0.82,"id":72963954}]}]}
{"op":"mcm","clk":"11935225023","pt":1724340550377,"mc":[{"id":"1.232135506","rc":[{"batb":[[1,1.94,1],[2,1.93,6.15]],"ltp":2.42,"tv":0.82,"id":72963954}]}]}
{"op":"mcm","clk":"11935225148","pt":1724340551570,"mc":[{"id":"1.232135506","rc":[{"batb":[[0,1.94,1],[1,1.93,6.15],[2,1.9,5.69]],"ltp":2.42,"tv":0.82,"id":72963954}]}]}
{"op":"mcm","clk":"11935227841","pt":1724340581206,"mc":[{"id":"1.232135506","rc":[{"batb":[[0,1.96,10],[1,1.95,4],[2,1.94,1]],"ltp":2.42,"tv":0.82,"id":72963954}]}]}
{"op":"mcm","clk":"11935228052","pt":1724340583231,"mc":[{"id":"1.232135506","rc":[{"batb":[[1,1.94,1],[2,1.93,6.15]],"ltp":2.42,"tv":0.82,"id":72963954}]}]}
{"op":"mcm","clk":"11935228192","pt":1724340584437,"mc":[{"id":"1.232135506","rc":[{"batb":[[0,1.94,1],[1,1.93,6.15],[2,1.9,5.69]],"ltp":2.42,"tv":0.82,"id":72963954}]}]}
{"op":"mcm","clk":"11935229190","pt":1724340595649,"mc":[{"id":"1.232135506","rc":[{"batb":[[0,1.96,10],[1,1.95,4],[2,1.94,1]],"ltp":2.42,"tv":0.82,"id":72963954}]}]}
{"op":"mcm","clk":"11935229381","pt":1724340597847,"mc":[{"id":"1.232135506","rc":[{"batb":[[1,1.94,1],[2,1.93,6.15]],"ltp":2.42,"tv":0.82,"id":72963954}]}]}
{"op":"mcm","clk":"11935229516","pt":1724340599136,"mc":[{"id":"1.232135506","rc":[{"batb":[[0,1.94,1],[1,1.93,6.15],[2,1.9,5.69]],"ltp":2.42,"tv":0.82,"id":72963954}]}]}
{"op":"mcm","clk":"11935232980","pt":1724340630695,"mc":[{"id":"1.232135506","rc":[{"batb":[[0,1.95,4],[1,1.94,1],[2,1.93,6.15]],"ltp":2.42,"tv":0.82,"id":72963954}]}]}
{"op":"mcm","clk":"11935232991","pt":1724340630800,"mc":[{"id":"1.232135506","rc":[{"batb":[[0,1.96,10],[1,1.95,4],[2,1.94,1]],"ltp":2.42,"tv":0.82,"id":72963954}]}]}
{"op":"mcm","clk":"11935233222","pt":1724340632893,"mc":[{"id":"1.232135506","rc":[{"batb":[[1,1.94,1],[2,1.93,6.15]],"ltp":2.42,"tv":0.82,"id":72963954}]}]}
{"op":"mcm","clk":"11935233400","pt":1724340634382,"mc":[{"id":"1.232135506","rc":[{"batb":[[0,1.94,1],[1,1.93,6.15],[2,1.9,5.69]],"ltp":2.42,"tv":0.82,"id":72963954}]}]}
{"op":"mcm","clk":"11935234635","pt":1724340647320,"mc":[{"id":"1.232135506","rc":[{"batb":[[0,1.96,10],[1,1.95,4],[2,1.94,1]],"ltp":2.42,"tv":0.82,"id":72963954}]}]}
{"op":"mcm","clk":"11935234835","pt":1724340649235,"mc":[{"id":"1.232135506","rc":[{"batb":[[1,1.94,1],[2,1.93,6.15]],"ltp":2.42,"tv":0.82,"id":72963954}]}]}
{"op":"mcm","clk":"11935234974","pt":1724340650525,"mc":[{"id":"1.232135506","rc":[{"batb":[[0,1.94,1],[1,1.93,6.15],[2,1.9,5.69]],"ltp":2.42,"tv":0.82,"id":72963954}]}]}
{"op":"mcm","clk":"11935235254","pt":1724340653423,"mc":[{"id":"1.232135506","rc":[{"batb":[[0,1.96,10],[1,1.95,4],[2,1.94,1]],"ltp":2.42,"tv":0.82,"id":72963954}]}]}
{"op":"mcm","clk":"11935235428","pt":1724340655498,"mc":[{"id":"1.232135506","rc":[{"batb":[[1,1.94,1],[2,1.93,6.15]],"ltp":2.42,"tv":0.82,"id":72963954}]}]}
{"op":"mcm","clk":"11935235533","pt":1724340656695,"mc":[{"id":"1.232135506","rc":[{"batb":[[0,1.94,1],[1,1.93,6.15],[2,1.9,5.69]],"ltp":2.42,"tv":0.82,"id":72963954}]}]}
{"op":"mcm","clk":"11935237885","pt":1724340679448,"mc":[{"id":"1.232135506","rc":[{"batb":[[0,1.95,4],[1,1.94,1],[2,1.93,6.15]],"ltp":2.42,"tv":0.82,"id":72963954}]}]}
{"op":"mcm","clk":"11935237919","pt":1724340679864,"mc":[{"id":"1.232135506","rc":[{"batb":[[0,1.96,10],[1,1.95,4],[2,1.94,1]],"ltp":2.42,"tv":0.82,"id":72963954}]}]}
{"op":"mcm","clk":"11935238116","pt":1724340681851,"mc":[{"id":"1.232135506","rc":[{"batb":[[1,1.94,1],[2,1.93,6.15]],"ltp":2.42,"tv":0.82,"id":72963954}]}]}
{"op":"mcm","clk":"11935238255","pt":1724340683158,"mc":[{"id":"1.232135506","rc":[{"batb":[[0,1.94,1],[1,1.93,6.15],[2,1.9,5.69]],"ltp":2.42,"tv":0.82,"id":72963954}]}]}
{"op":"mcm","clk":"11935239947","pt":1724340699253,"mc":[{"id":"1.232135506","rc":[{"batb":[[0,1.96,10],[1,1.95,4],[2,1.94,1]],"ltp":2.42,"tv":0.82,"id":72963954}]}]}
{"op":"mcm","clk":"11935240137","pt":1724340701158,"mc":[{"id":"1.232135506","rc":[{"batb":[[1,1.94,1],[2,1.93,6.15]],"ltp":2.42,"tv":0.82,"id":72963954}]}]}
{"op":"mcm","clk":"11935240309","pt":1724340702780,"mc":[{"id":"1.232135506","rc":[{"batb":[[0,1.94,1],[1,1.93,6.15],[2,1.9,5.69]],"ltp":2.42,"tv":0.82,"id":72963954}]}]}
{"op":"mcm","clk":"11935242864","pt":1724340727308,"mc":[{"id":"1.232135506","rc":[{"batb":[[0,1.96,10],[1,1.95,4],[2,1.94,1]],"ltp":2.42,"tv":0.82,"id":72963954}]}]}
{"op":"mcm","clk":"11935243089","pt":1724340729398,"mc":[{"id":"1.232135506","rc":[{"batb":[[1,1.94,1],[2,1.93,6.15]],"ltp":2.42,"tv":0.82,"id":72963954}]}]}
{"op":"mcm","clk":"11935243226","pt":1724340730603,"mc":[{"id":"1.232135506","rc":[{"batb":[[0,1.94,1],[1,1.93,6.15],[2,1.9,5.69]],"ltp":2.42,"tv":0.82,"id":72963954}]}]}
{"op":"mcm","clk":"11935244085","pt":1724340738625,"mc":[{"id":"1.232135506","rc":[{"batb":[[0,1.96,10],[1,1.95,4],[2,1.94,1]],"ltp":2.42,"tv":0.82,"id":72963954}]}]}
{"op":"mcm","clk":"11935244325","pt":1724340741117,"mc":[{"id":"1.232135506","rc":[{"batb":[[1,1.94,1],[2,1.93,6.15]],"ltp":2.42,"tv":0.82,"id":72963954}]}]}
{"op":"mcm","clk":"11935244421","pt":1724340741900,"mc":[{"id":"1.232135506","rc":[{"batb":[[0,1.94,1],[1,1.93,6.15],[2,1.9,5.69]],"ltp":2.42,"tv":0.82,"id":72963954}]}]}
{"op":"mcm","clk":"11935245380","pt":1724340750702,"mc":[{"id":"1.232135506","rc":[{"batb":[[0,1.95,4],[1,1.94,1],[2,1.93,6.15]],"ltp":2.42,"tv":0.82,"id":72963954}]}]}
{"op":"mcm","clk":"11935245396","pt":1724340750906,"mc":[{"id":"1.232135506","rc":[{"batb":[[0,1.96,10],[1,1.95,4],[2,1.94,1]],"ltp":2.42,"tv":0.82,"id":72963954}]}]}
{"op":"mcm","clk":"11935245614","pt":1724340753000,"mc":[{"id":"1.232135506","rc":[{"batb":[[1,1.94,1],[2,1.93,6.15]],"ltp":2.42,"tv":0.82,"id":72963954}]}]}
{"op":"mcm","clk":"11935245751","pt":1724340754309,"mc":[{"id":"1.232135506","rc":[{"batb":[[0,1.94,1],[1,1.93,6.15],[2,1.9,5.69]],"ltp":2.42,"tv":0.82,"id":72963954}]}]}
{"op":"mcm","clk":"11935245959","pt":1724340756236,"mc":[{"id":"1.232135506","rc":[{"batb":[[0,1.95,4],[1,1.94,1],[2,1.93,6.15]],"ltp":2.42,"tv":0.82,"id":72963954}]}]}
{"op":"mcm","clk":"11935246200","pt":1724340758520,"mc":[{"id":"1.232135506","rc":[{"batb":[[0,1.94,1],[1,1.93,6.15],[2,1.9,5.69]],"ltp":2.42,"tv":0.82,"id":72963954}]}]}
{"op":"mcm","clk":"11935249767","pt":1724340791280,"mc":[{"id":"1.232135506","rc":[{"batb":[[0,1.96,10],[1,1.95,4],[2,1.94,1]],"ltp":2.42,"tv":0.82,"id":72963954}]}]}
{"op":"mcm","clk":"11935249975","pt":1724340793349,"mc":[{"id":"1.232135506","rc":[{"batb":[[1,1.94,1],[2,1.93,6.15]],"ltp":2.42,"tv":0.82,"id":72963954}]}]}
{"op":"mcm","clk":"11935250121","pt":1724340794544,"mc":[{"id":"1.232135506","rc":[{"batb":[[0,1.94,1],[1,1.93,6.15],[2,1.9,5.69]],"ltp":2.42,"tv":0.82,"id":72963954}]}]}
{"op":"mcm","clk":"11935250385","pt":1724340797483,"mc":[{"id":"1.232135506","rc":[{"batb":[[0,1.96,10],[1,1.95,4],[2,1.94,1]],"ltp":2.42,"tv":0.82,"id":72963954}]}]}
{"op":"mcm","clk":"11935250609","pt":1724340799664,"mc":[{"id":"1.232135506","rc":[{"trd":[[1.69,208],[1.7,37.13],[1.71,3.43],[1.72,21.49]],"batb":[[0,1.6,29.54],[1,1.54,112.74],[2,1.51,755.44]],"batl":[[0,1.69,15.18],[1,1.94,6.97],[2,2.96,10]],"ltp":1.69,"tv":450.75,"id":47674067},{"batb":[[1,1.94,1],[2,1.93,6.15]],"ltp":2.42,"tv":0.82,"id":72963954}],"tv":451.57}]}
{"op":"mcm","clk":"11935250734","pt":1724340800757,"mc":[{"id":"1.232135506","rc":[{"batb":[[0,1.94,1],[1,1.93,6.15],[2,1.9,5.69]],"ltp":2.42,"tv":0.82,"id":72963954}]}]}
{"op":"mcm","clk":"11935250760","pt":1724340800961,"mc":[{"id":"1.232135506","rc":[{"batl":[[2,2.06,4.22]],"ltp":1.69,"tv":450.75,"id":47674067}]}]}
{"op":"mcm","clk":"11935252248","pt":1724340816682,"mc":[{"id":"1.232135506","rc":[{"batl":[[1,2.06,4.22],[2,2.96,10]],"ltp":1.69,"tv":450.75,"id":47674067}]}]}
{"op":"mcm","clk":"11935252266","pt":1724340816891,"mc":[{"id":"1.232135506","rc":[{"batb":[[0,1.96,10],[1,1.95,4],[2,1.94,1]],"ltp":2.42,"tv":0.82,"id":72963954}]}]}
{"op":"mcm","clk":"11935252504","pt":1724340818983,"mc":[{"id":"1.232135506","rc":[{"batb":[[1,1.94,1],[2,1.93,6.15]],"ltp":2.42,"tv":0.82,"id":72963954}]}]}
{"op":"mcm","clk":"11935252636","pt":1724340820180,"mc":[{"id":"1.232135506","rc":[{"batb":[[0,1.94,1],[1,1.93,6.15],[2,1.9,5.69]],"ltp":2.42,"tv":0.82,"id":72963954}]}]}
{"op":"mcm","clk":"11935253869","pt":1724340832696,"mc":[{"id":"1.232135506","rc":[{"trd":[[1.69,210.16]],"batl":[[0,1.69,14.1]],"ltp":1.69,"tv":452.91,"id":47674067}],"tv":453.73}]}
{"op":"mcm","clk":"11935253896","pt":1724340832903,"mc":[{"id":"1.232135506","rc":[{"batb":[[0,1.96,10],[1,1.95,4],[2,1.94,1]],"ltp":2.42,"tv":0.82,"id":72963954}]}]}
{"op":"mcm","clk":"11935254126","pt":1724340835090,"mc":[{"id":"1.232135506","rc":[{"batb":[[1,1.94,1],[2,1.93,6.15]],"ltp":2.42,"tv":0.82,"id":72963954}]}]}
{"op":"mcm","clk":"11935254236","pt":1724340836124,"mc":[{"id":"1.232135506","rc":[{"batb":[[0,1.94,1],[1,1.93,6.15],[2,1.9,5.69]],"ltp":2.42,"tv":0.82,"id":72963954}]}]}
{"op":"mcm","clk":"11935255876","pt":1724340852437,"mc":[{"id":"1.232135506","rc":[{"batb":[[0,1.95,4],[1,1.94,1],[2,1.93,6.15]],"ltp":2.42,"tv":0.82,"id":72963954}]}]}
{"op":"mcm","clk":"11935255932","pt":1724340852912,"mc":[{"id":"1.232135506","rc":[{"batb":[[0,1.96,10],[1,1.95,4],[2,1.94,1]],"ltp":2.42,"tv":0.82,"id":72963954}]}]}
{"op":"mcm","clk":"11935256111","pt":1724340854736,"mc":[{"id":"1.232135506","rc":[{"batb":[[1,1.94,1],[2,1.93,6.15]],"ltp":2.42,"tv":0.82,"id":72963954}]}]}
{"op":"mcm","clk":"11935256465","pt":1724340857554,"mc":[{"id":"1.232135506","rc":[{"batb":[[0,1.95,4]],"ltp":2.42,"tv":0.82,"id":72963954}]}]}
{"op":"mcm","clk":"11935256671","pt":1724340859733,"mc":[{"id":"1.232135506","rc":[{"batb":[[0,1.94,1],[1,1.93,6.15],[2,1.9,5.69]],"ltp":2.42,"tv":0.82,"id":72963954}]}]}
{"op":"mcm","clk":"11935257074","pt":1724340864556,"mc":[{"id":"1.232135506","rc":[{"batb":[[0,1.63,3.4],[1,1.6,29.54],[2,1.54,112.74]],"ltp":1.69,"tv":452.91,"id":47674067}]}]}
{"op":"mcm","clk":"11935257101","pt":1724340864866,"mc":[{"id":"1.232135506","rc":[{"batb":[[0,1.96,10],[1,1.95,4],[2,1.94,1]],"ltp":2.42,"tv":0.82,"id":72963954}]}]}
{"op":"mcm","clk":"11935257280","pt":1724340867041,"mc":[{"id":"1.232135506","rc":[{"batb":[[1,1.94,1],[2,1.93,6.15]],"ltp":2.42,"tv":0.82,"id":72963954}]}]}
{"op":"mcm","clk":"11935257395","pt":1724340868089,"mc":[{"id":"1.232135506","rc":[{"batb":[[0,1.94,1],[1,1.93,6.15],[2,1.9,5.69]],"ltp":2.42,"tv":0.82,"id":72963954}]}]}
{"op":"mcm","clk":"11935257557","pt":1724340869576,"mc":[{"id":"1.232135506","rc":[{"batb":[[0,1.65,3.4]],"ltp":1.69,"tv":452.91,"id":47674067},{"batb":[[0,1.95,4],[1,1.94,1],[2,1.93,6.15]],"ltp":2.42,"tv":0.82,"id":72963954}]}]}
{"op":"mcm","clk":"11935257782","pt":1724340871963,"mc":[{"id":"1.232135506","rc":[{"batb":[[0,1.94,1],[1,1.93,6.15],[2,1.9,5.69]],"ltp":2.42,"tv":0.82,"id":72963954}]}]}
{"op":"mcm","clk":"11935257934","pt":1724340873707,"mc":[{"id":"1.232135506","rc":[{"batb":[[0,1.6,29.54],[1,1.54,112.74],[2,1.51,755.44]],"ltp":1.69,"tv":452.91,"id":47674067}]}]}
{"op":"mcm","clk":"11935259716","pt":1724340893476,"mc":[{"id":"1.232135506","rc":[{"batb":[[0,1.96,10],[1,1.95,4],[2,1.94,1]],"ltp":2.42,"tv":0.82,"id":72963954}]}]}
{"op":"mcm","clk":"11935259895","pt":1724340895596,"mc":[{"id":"1.232135506","rc":[{"batb":[[1,1.94,1],[2,1.93,6.15]],"ltp":2.42,"tv":0.82,"id":72963954}]}]}
{"op":"mcm","clk":"11935260013","pt":1724340896681,"mc":[{"id":"1.232135506","rc":[{"batb":[[0,1.94,1],[1,1.93,6.15],[2,1.9,5.69]],"ltp":2.42,"tv":0.82,"id":72963954}]}]}
{"op":"mcm","clk":"11935260713","pt":1724340903588,"mc":[{"id":"1.232135506","rc":[{"batb":[[0,1.96,10],[1,1.95,4],[2,1.94,1]],"ltp":2.42,"tv":0.82,"id":72963954}]}]}
{"op":"mcm","clk":"11935260938","pt":1724340905720,"mc":[{"id":"1.232135506","rc":[{"batb":[[1,1.94,1],[2,1.93,6.15]],"ltp":2.42,"tv":0.82,"id":72963954}]}]}
{"op":"mcm","clk":"11935261036","pt":1724340906702,"mc":[{"id":"1.232135506","rc":[{"batb":[[0,1.62,30.26],[1,1.6,29.54],[2,1.54,112.74]],"ltp":1.69,"tv":452.91,"id":47674067}]}]}
{"op":"mcm","clk":"11935261046","pt":1724340906806,"mc":[{"id":"1.232135506","rc":[{"batb":[[0,1.94,1],[1,1.93,6.15],[2,1.9,5.69]],"ltp":2.42,"tv":0.82,"id":72963954}]}]}
{"op":"mcm","clk":"11935261260","pt":1724340909000,"mc":[{"id":"1.232135506","rc":[{"batb":[[0,1.96,10],[1,1.95,4],[2,1.94,1]],"ltp":2.42,"tv":0.82,"id":72963954}]}]}
{"op":"mcm","clk":"11935261455","pt":1724340911026,"mc":[{"id":"1.232135506","rc":[{"batb":[[1,1.94,1],[2,1.93,6.15]],"ltp":2.42,"tv":0.82,"id":72963954}]}]}
{"op":"mcm","clk":"11935261593","pt":1724340912215,"mc":[{"id":"1.232135506","rc":[{"batb":[[0,1.94,1],[1,1.93,6.15],[2,1.9,5.69]],"ltp":2.42,"tv":0.82,"id":72963954}]}]}
{"op":"mcm","clk":"11935261840","pt":1724340914730,"mc":[{"id":"1.232135506","rc":[{"batb":[[2,1.55,755.44]],"ltp":1.69,"tv":452.91,"id":47674067},{"batb":[[0,1.96,10],[1,1.95,4],[2,1.94,1]],"ltp":2.42,"tv":0.82,"id":72963954}]}]}
{"op":"mcm","clk":"11935262068","pt":1724340917011,"mc":[{"id":"1.232135506","rc":[{"batb":[[1,1.94,1],[2,1.93,6.15]],"ltp":2.42,"tv":0.82,"id":72963954}]}]}
{"op":"mcm","clk":"11935262177","pt":1724340918036,"mc":[{"id":"1.232135506","rc":[{"batb":[[0,1.94,1],[1,1.93,6.15],[2,1.9,5.69]],"ltp":2.42,"tv":0.82,"id":72963954}]}]}
{"op":"mcm","clk":"11935263953","pt":1724340936121,"mc":[{"id":"1.232135506","rc":[{"batb":[[0,1.61,30.82]],"ltp":1.69,"tv":452.91,"id":47674067},{"batb":[[0,1.96,10],[1,1.95,4],[2,1.94,1]],"ltp":2.42,"tv":0.82,"id":72963954}]}]}
{"op":"mcm","clk":"11935264247","pt":1724340938454,"mc":[{"id":"1.232135506","rc":[{"batb":[[1,1.94,1],[2,1.93,6.15]],"ltp":2.42,"tv":0.82,"id":72963954}]}]}
{"op":"mcm","clk":"11935264358","pt":1724340939450,"mc":[{"id":"1.232135506","rc":[{"batb":[[0,1.94,1],[1,1.93,6.15],[2,1.9,5.69]],"ltp":2.42,"tv":0.82,"id":72963954}]}]}
{"op":"mcm","clk":"11935264488","pt":1724340940859,"mc":[{"id":"1.232135506","rc":[{"batb":[[0,1.95,4],[1,1.94,1],[2,1.93,6.15]],"ltp":2.42,"tv":0.82,"id":72963954}]}]}
{"op":"mcm","clk":"11935264735","pt":1724340943351,"mc":[{"id":"1.232135506","rc":[{"batb":[[0,1.94,1],[1,1.93,6.15],[2,1.9,5.69]],"ltp":2.42,"tv":0.82,"id":72963954}]}]}
{"op":"mcm","clk":"11935265415","pt":1724340950755,"mc":[{"id":"1.232135506","rc":[{"batb":[[0,1.95,4],[1,1.94,1],[2,1.93,6.15]],"ltp":2.42,"tv":0.82,"id":72963954}]}]}
{"op":"mcm","clk":"11935265443","pt":1724340951163,"mc":[{"id":"1.232135506","rc":[{"batb":[[0,1.96,10],[1,1.95,4],[2,1.94,1]],"ltp":2.42,"tv":0.82,"id":72963954}]}]}
{"op":"mcm","clk":"11935265666","pt":1724340953234,"mc":[{"id":"1.232135506","rc":[{"batb":[[1,1.94,1],[2,1.93,6.15]],"ltp":2.42,"tv":0.82,"id":72963954}]}]}
{"op":"mcm","clk":"11935265810","pt":1724340954631,"mc":[{"id":"1.232135506","rc":[{"batb":[[0,1.94,1],[1,1.93,6.15],[2,1.9,5.69]],"ltp":2.42,"tv":0.82,"id":72963954}]}]}
{"op":"mcm","clk":"11935266749","pt":1724340964410,"mc":[{"id":"1.232135506","rc":[{"batb":[[0,1.95,4],[1,1.94,1],[2,1.93,6.15]],"ltp":2.42,"tv":0.82,"id":72963954}]}]}
{"op":"mcm","clk":"11935266799","pt":1724340964852,"mc":[{"id":"1.232135506","rc":[{"batb":[[0,1.96,10],[1,1.95,4],[2,1.94,1]],"ltp":2.42,"tv":0.82,"id":72963954}]}]}
{"op":"mcm","clk":"11935267024","pt":1724340966973,"mc":[{"id":"1.232135506","rc":[{"batb":[[1,1.94,1],[2,1.93,6.15]],"ltp":2.42,"tv":0.82,"id":72963954}]}]}
{"op":"mcm","clk":"11935267149","pt":1724340968098,"mc":[{"id":"1.232135506","rc":[{"batb":[[0,1.94,1],[1,1.93,6.15],[2,1.9,5.69]],"ltp":2.42,"tv":0.82,"id":72963954}]}]}
{"op":"mcm","clk":"11935268292","pt":1724340979079,"mc":[{"id":"1.232135506","rc":[{"batb":[[0,1.96,10],[1,1.95,4],[2,1.94,1]],"ltp":2.42,"tv":0.82,"id":72963954}]}]}
{"op":"mcm","clk":"11935268516","pt":1724340981302,"mc":[{"id":"1.232135506","rc":[{"batb":[[1,1.94,1],[2,1.93,6.15]],"ltp":2.42,"tv":0.82,"id":72963954}]}]}
{"op":"mcm","clk":"11935268639","pt":1724340982702,"mc":[{"id":"1.232135506","rc":[{"batb":[[0,1.94,1],[1,1.93,6.15],[2,1.9,5.69]],"ltp":2.42,"tv":0.82,"id":72963954}]}]}
{"op":"mcm","clk":"11935269469","pt":1724340991529,"mc":[{"id":"1.232135506","rc":[{"batb":[[0,1.96,10],[1,1.95,4],[2,1.94,1]],"ltp":2.42,"tv":0.82,"id":72963954}]}]}
{"op":"mcm","clk":"11935269655","pt":1724340993415,"mc":[{"id":"1.232135506","rc":[{"batb":[[1,1.94,1],[2,1.93,6.15]],"ltp":2.42,"tv":0.82,"id":72963954}]}]}
{"op":"mcm","clk":"11935269713","pt":1724340993989,"mc":[{"id":"1.232135506","rc":[{"batb":[[0,1.62,8.27],[1,1.61,30.82],[2,1.6,29.54]],"ltp":1.69,"tv":452.91,"id":47674067}]}]}
{"op":"mcm","clk":"11935269855","pt":1724340995128,"mc":[{"id":"1.232135506","rc":[{"batb":[[0,1.94,1],[1,1.93,6.15],[2,1.9,5.69]],"ltp":2.42,"tv":0.82,"id":72963954}]}]}
{"op":"mcm","clk":"11935270946","pt":1724341004930,"mc":[{"id":"1.232135506","rc":[{"batb":[[0,1.96,10],[1,1.95,4],[2,1.94,1]],"ltp":2.42,"tv":0.82,"id":72963954}]}]}
{"op":"mcm","clk":"11935271188","pt":1724341007108,"mc":[{"id":"1.232135506","rc":[{"batb":[[1,1.94,1],[2,1.93,6.15]],"ltp":2.42,"tv":0.82,"id":72963954}]}]}
{"op":"mcm","clk":"11935271327","pt":1724341008505,"mc":[{"id":"1.232135506","rc":[{"batb":[[0,1.94,1],[1,1.93,6.15],[2,1.9,5.69]],"ltp":2.42,"tv":0.82,"id":72963954}]}]}
{"op":"mcm","clk":"11935274580","pt":1724341038276,"mc":[{"id":"1.232135506","rc":[{"batb":[[0,1.96,10],[1,1.95,4],[2,1.94,1]],"ltp":2.42,"tv":0.82,"id":72963954}]}]}
{"op":"mcm","clk":"11935274832","pt":1724341040463,"mc":[{"id":"1.232135506","rc":[{"batb":[[1,1.94,1],[2,1.93,6.15]],"ltp":2.42,"tv":0.82,"id":72963954}]}]}
{"op":"mcm","clk":"11935274983","pt":1724341041868,"mc":[{"id":"1.232135506","rc":[{"batb":[[0,1.94,1],[1,1.93,6.15],[2,1.9,5.69]],"ltp":2.42,"tv":0.82,"id":72963954}]}]}
{"op":"mcm","clk":"11935276108","pt":1724341052300,"mc":[{"id":"1.232135506","rc":[{"batb":[[0,1.96,10],[1,1.95,4],[2,1.94,1]],"ltp":2.42,"tv":0.82,"id":72963954}]}]}
{"op":"mcm","clk":"11935276355","pt":1724341054588,"mc":[{"id":"1.232135506","rc":[{"batb":[[1,1.94,1],[2,1.93,6.15]],"ltp":2.42,"tv":0.82,"id":72963954}]}]}
{"op":"mcm","clk":"11935276480","pt":1724341055682,"mc":[{"id":"1.232135506","rc":[{"batb":[[0,1.94,1],[1,1.93,6.15],[2,1.9,5.69]],"ltp":2.42,"tv":0.82,"id":72963954}]}]}
{"op":"mcm","clk":"11935278211","pt":1724341072699,"mc":[{"id":"1.232135506","rc":[{"batb":[[1,1.6,29.54],[2,1.55,755.44]],"ltp":1.69,"tv":452.91,"id":47674067}]}]}
{"op":"mcm","clk":"11935278256","pt":1724341073073,"mc":[{"id":"1.232135506","rc":[{"batb":[[0,1.62,38.58]],"ltp":1.69,"tv":452.91,"id":47674067},{"batb":[[0,1.96,10],[1,1.95,4],[2,1.94,1]],"ltp":2.42,"tv":0.82,"id":72963954}]}]}
{"op":"mcm","clk":"11935278466","pt":1724341075036,"mc":[{"id":"1.232135506","rc":[{"batb":[[1,1.94,1],[2,1.93,6.15]],"ltp":2.42,"tv":0.82,"id":72963954}]}]}
{"op":"mcm","clk":"11935278608","pt":1724341076531,"mc":[{"id":"1.232135506","rc":[{"batb":[[0,1.94,1],[1,1.93,6.15],[2,1.9,5.69]],"ltp":2.42,"tv":0.82,"id":72963954}]}]}
{"op":"mcm","clk":"11935278987","pt":1724341080215,"mc":[{"id":"1.232135506","rc":[{"batb":[[0,1.96,10],[1,1.95,4],[2,1.94,1]],"ltp":2.42,"tv":0.82,"id":72963954}]}]}
{"op":"mcm","clk":"11935279263","pt":1724341082356,"mc":[{"id":"1.232135506","rc":[{"batb":[[1,1.94,1],[2,1.93,6.15]],"ltp":2.42,"tv":0.82,"id":72963954}]}]}
{"op":"mcm","clk":"11935279422","pt":1724341083750,"mc":[{"id":"1.232135506","rc":[{"batb":[[0,1.94,1],[1,1.93,6.15],[2,1.9,5.69]],"ltp":2.42,"tv":0.82,"id":72963954}]}]}
{"op":"mcm","clk":"11935279531","pt":1724341084733,"mc":[{"id":"1.232135506","rc":[{"batb":[[0,1.95,4],[1,1.94,1],[2,1.93,6.15]],"ltp":2.42,"tv":0.82,"id":72963954}]}]}
{"op":"mcm","clk":"11935279788","pt":1724341087017,"mc":[{"id":"1.232135506","rc":[{"batb":[[0,1.94,1],[1,1.93,6.15],[2,1.9,5.69]],"ltp":2.42,"tv":0.82,"id":72963954}]}]}
{"op":"mcm","clk":"11935282697","pt":1724341116179,"mc":[{"id":"1.232135506","rc":[{"batb":[[0,1.96,10],[1,1.95,4],[2,1.94,1]],"ltp":2.42,"tv":0.82,"id":72963954}]}]}
{"op":"mcm","clk":"11935282899","pt":1724341118145,"mc":[{"id":"1.232135506","rc":[{"batb":[[1,1.94,1],[2,1.93,6.15]],"ltp":2.42,"tv":0.82,"id":72963954}]}]}
{"op":"mcm","clk":"11935283068","pt":1724341119692,"mc":[{"id":"1.232135506","rc":[{"batb":[[0,1.94,1],[1,1.93,6.15],[2,1.9,5.69]],"ltp":2.42,"tv":0.82,"id":72963954}]}]}
{"op":"mcm","clk":"11935286789","pt":1724341153725,"mc":[{"id":"1.232135506","rc":[{"batb":[[0,1.95,4],[1,1.94,1],[2,1.93,6.15]],"ltp":2.42,"tv":0.82,"id":72963954}]}]}
{"op":"mcm","clk":"11935286808","pt":1724341153882,"mc":[{"id":"1.232135506","rc":[{"batb":[[0,1.96,10],[1,1.95,4],[2,1.94,1]],"ltp":2.42,"tv":0.82,"id":72963954}]}]}
{"op":"mcm","clk":"11935287025","pt":1724341156105,"mc":[{"id":"1.232135506","rc":[{"batb":[[1,1.94,1],[2,1.93,6.15]],"ltp":2.42,"tv":0.82,"id":72963954}]}]}
{"op":"mcm","clk":"11935287122","pt":1724341157138,"mc":[{"id":"1.232135506","rc":[{"batb":[[0,1.94,1],[1,1.93,6.15],[2,1.9,5.69]],"ltp":2.42,"tv":0.82,"id":72963954}]}]}
{"op":"mcm","clk":"11935287431","pt":1724341160094,"mc":[{"id":"1.232135506","rc":[{"batb":[[1,1.6,8.54]],"ltp":1.69,"tv":452.91,"id":47674067},{"batb":[[0,1.96,10],[1,1.95,4],[2,1.94,1]],"ltp":2.42,"tv":0.82,"id":72963954}]}]}
{"op":"mcm","clk":"11935287668","pt":1724341162424,"mc":[{"id":"1.232135506","rc":[{"batb":[[1,1.94,1],[2,1.93,6.15]],"ltp":2.42,"tv":0.82,"id":72963954}]}]}
{"op":"mcm","clk":"11935287774","pt":1724341163512,"mc":[{"id":"1.232135506","rc":[{"batb":[[0,1.94,1],[1,1.93,6.15],[2,1.9,5.69]],"ltp":2.42,"tv":0.82,"id":72963954}]}]}
{"op":"mcm","clk":"11935288796","pt":1724341173351,"mc":[{"id":"1.232135506","rc":[{"batb":[[0,1.96,10],[1,1.95,4],[2,1.94,1]],"ltp":2.42,"tv":0.82,"id":72963954}]}]}
{"op":"mcm","clk":"11935288988","pt":1724341175315,"mc":[{"id":"1.232135506","rc":[{"batb":[[1,1.94,1],[2,1.93,6.15]],"ltp":2.42,"tv":0.82,"id":72963954}]}]}
{"op":"mcm","clk":"11935289071","pt":1724341176510,"mc":[{"id":"1.232135506","rc":[{"batb":[[0,1.94,1],[1,1.93,6.15],[2,1.9,5.69]],"ltp":2.42,"tv":0.82,"id":72963954}]}]}
{"op":"mcm","clk":"11935289339","pt":1724341179213,"mc":[{"id":"1.232135506","rc":[{"batb":[[0,1.96,10],[1,1.95,4],[2,1.94,1]],"ltp":2.42,"tv":0.82,"id":72963954}]}]}
{"op":"mcm","clk":"11935289589","pt":1724341181448,"mc":[{"id":"1.232135506","rc":[{"batb":[[1,1.94,1],[2,1.93,6.15]],"ltp":2.42,"tv":0.82,"id":72963954}]}]}
{"op":"mcm","clk":"11935289741","pt":1724341182643,"mc":[{"id":"1.232135506","rc":[{"batb":[[0,1.94,1],[1,1.93,6.15],[2,1.9,5.69]],"ltp":2.42,"tv":0.82,"id":72963954}]}]}
{"op":"mcm","clk":"11935291671","pt":1724341199754,"mc":[{"id":"1.232135506","rc":[{"batb":[[0,1.96,10],[1,1.95,4],[2,1.94,1]],"ltp":2.42,"tv":0.82,"id":72963954}]}]}
{"op":"mcm","clk":"11935292032","pt":1724341202683,"mc":[{"id":"1.232135506","rc":[{"batb":[[1,1.94,1],[2,1.93,6.15]],"ltp":2.42,"tv":0.82,"id":72963954}]}]}
{"op":"mcm","clk":"11935292065","pt":1724341202943,"mc":[{"id":"1.232135506","rc":[{"batb":[[0,1.94,1],[1,1.93,6.15],[2,1.9,5.69]],"ltp":2.42,"tv":0.82,"id":72963954}]}]}
{"op":"mcm","clk":"11935292657","pt":1724341207477,"mc":[{"id":"1.232135506","rc":[{"batb":[[0,1.96,10],[1,1.95,4],[2,1.94,1]],"ltp":2.42,"tv":0.82,"id":72963954}]}]}
{"op":"mcm","clk":"11935292693","pt":1724341207787,"mc":[{"id":"1.232135506","rc":[{"batb":[[0,1.62,8.27]],"ltp":1.69,"tv":452.91,"id":47674067}]}]}
{"op":"mcm","clk":"11935292944","pt":1724341209761,"mc":[{"id":"1.232135506","rc":[{"batb":[[1,1.94,1],[2,1.93,6.15]],"ltp":2.42,"tv":0.82,"id":72963954}]}]}
{"op":"mcm","clk":"11935293078","pt":1724341210955,"mc":[{"id":"1.232135506","rc":[{"batb":[[0,1.94,1],[1,1.93,6.15],[2,1.9,5.69]],"ltp":2.42,"tv":0.82,"id":72963954}]}]}
{"op":"mcm","clk":"11935294044","pt":1724341218956,"mc":[{"id":"1.232135506","rc":[{"batl":[[0,1.69,11.55]],"ltp":1.69,"tv":452.91,"id":47674067},{"batb":[[0,1.96,10],[1,1.95,4],[2,1.94,1]],"ltp":2.42,"tv":0.82,"id":72963954}]}]}
{"op":"mcm","clk":"11935294293","pt":1724341221093,"mc":[{"id":"1.232135506","rc":[{"batb":[[1,1.94,1],[2,1.93,6.15]],"ltp":2.42,"tv":0.82,"id":72963954}]}]}
{"op":"mcm","clk":"11935294436","pt":1724341222297,"mc":[{"id":"1.232135506","rc":[{"batb":[[0,1.94,1],[1,1.93,6.15],[2,1.9,5.69]],"ltp":2.42,"tv":0.82,"id":72963954}]}]}
{"op":"mcm","clk":"11935295489","pt":1724341230580,"mc":[{"id":"1.232135506","rc":[{"batb":[[0,1.96,10],[1,1.95,4],[2,1.94,1]],"ltp":2.42,"tv":0.82,"id":72963954}]}]}
{"op":"mcm","clk":"11935295746","pt":1724341232703,"mc":[{"id":"1.232135506","rc":[{"batb":[[1,1.94,1],[2,1.93,6.15]],"ltp":2.42,"tv":0.82,"id":72963954}]}]}
{"op":"mcm","clk":"11935295904","pt":1724341234004,"mc":[{"id":"1.232135506","rc":[{"batb":[[0,1.94,1],[1,1.93,6.15],[2,1.9,5.69]],"ltp":2.42,"tv":0.82,"id":72963954}]}]}
{"op":"mcm","clk":"11935296557","pt":1724341239410,"mc":[{"id":"1.232135506","rc":[{"batb":[[0,1.96,10],[1,1.95,4],[2,1.94,1]],"ltp":2.42,"tv":0.82,"id":72963954}]}]}
{"op":"mcm","clk":"11935296828","pt":1724341241712,"mc":[{"id":"1.232135506","rc":[{"batb":[[1,1.94,1],[2,1.93,6.15]],"ltp":2.42,"tv":0.82,"id":72963954}]}]}
{"op":"mcm","clk":"11935296941","pt":1724341242898,"mc":[{"id":"1.232135506","rc":[{"batb":[[0,1.94,1],[1,1.93,6.15],[2,1.9,5.69]],"ltp":2.42,"tv":0.82,"id":72963954}]}]}
{"op":"mcm","clk":"11935297334","pt":1724341246713,"mc":[{"id":"1.232135506","rc":[{"batb":[[0,1.96,10],[1,1.95,4],[2,1.94,1]],"ltp":2.42,"tv":0.82,"id":72963954}]}]}
{"op":"mcm","clk":"11935297568","pt":1724341249109,"mc":[{"id":"1.232135506","rc":[{"batb":[[1,1.94,1],[2,1.93,6.15]],"ltp":2.42,"tv":0.82,"id":72963954}]}]}
{"op":"mcm","clk":"11935297706","pt":1724341250255,"mc":[{"id":"1.232135506","rc":[{"batb":[[0,1.94,1],[1,1.93,6.15],[2,1.9,5.69]],"ltp":2.42,"tv":0.82,"id":72963954}]}]}
{"op":"mcm","clk":"11935297978","pt":1724341252712,"mc":[{"id":"1.232135506","rc":[{"batl":[[1,1.9,18.8],[2,2.06,4.22]],"ltp":1.69,"tv":452.91,"id":47674067}]}]}
{"op":"mcm","clk":"11935298018","pt":1724341253127,"mc":[{"id":"1.232135506","rc":[{"batb":[[0,1.96,10],[1,1.95,4],[2,1.94,1]],"ltp":2.42,"tv":0.82,"id":72963954}]}]}
{"op":"mcm","clk":"11935298181","pt":1724341254626,"mc":[{"id":"1.232135506","rc":[{"batl":[[1,1.89,4.59],[2,1.9,18.8]],"ltp":1.69,"tv":452.91,"id":47674067}]}]}
{"op":"mcm","clk":"11935298255","pt":1724341255356,"mc":[{"id":"1.232135506","rc":[{"batb":[[1,1.94,1],[2,1.93,6.15]],"ltp":2.42,"tv":0.82,"id":72963954}]}]}
{"op":"mcm","clk":"11935298387","pt":1724341256401,"mc":[{"id":"1.232135506","rc":[{"batb":[[0,1.94,1],[1,1.93,6.15],[2,1.9,5.69]],"ltp":2.42,"tv":0.82,"id":72963954}]}]}
{"op":"mcm","clk":"11935299331","pt":1724341264212,"mc":[{"id":"1.232135506","rc":[{"batl":[[0,1.69,8.88]],"ltp":1.69,"tv":452.91,"id":47674067},{"batb":[[0,1.96,10],[1,1.95,4],[2,1.94,1]],"ltp":2.42,"tv":0.82,"id":72963954}]}]}
{"op":"mcm","clk":"11935299556","pt":1724341266345,"mc":[{"id":"1.232135506","rc":[{"batb":[[1,1.94,1],[2,1.93,6.15]],"ltp":2.42,"tv":0.82,"id":72963954}]}]}
{"op":"mcm","clk":"11935299673","pt":1724341267546,"mc":[{"id":"1.232135506","rc":[{"batb":[[0,1.94,1],[1,1.93,6.15],[2,1.9,5.69]],"ltp":2.42,"tv":0.82,"id":72963954}]}]}
{"op":"mcm","clk":"11935301754","pt":1724341288646,"mc":[{"id":"1.232135506","rc":[{"batb":[[0,1.96,10],[1,1.95,4],[2,1.94,1]],"ltp":2.42,"tv":0.82,"id":72963954}]}]}
{"op":"mcm","clk":"11935301954","pt":1724341290661,"mc":[{"id":"1.232135506","rc":[{"batb":[[1,1.94,1],[2,1.93,6.15]],"ltp":2.42,"tv":0.82,"id":72963954}]}]}
{"op":"mcm","clk":"11935302082","pt":1724341291956,"mc":[{"id":"1.232135506","rc":[{"batb":[[0,1.94,1],[1,1.93,6.15],[2,1.9,5.69]],"ltp":2.42,"tv":0.82,"id":72963954}]}]}
{"op":"mcm","clk":"11935302270","pt":1724341293969,"mc":[{"id":"1.232135506","rc":[{"batb":[[0,1.95,4],[1,1.94,1],[2,1.93,6.15]],"ltp":2.42,"tv":0.82,"id":72963954}]}]}
{"op":"mcm","clk":"11935302527","pt":1724341296358,"mc":[{"id":"1.232135506","rc":[{"batb":[[0,1.94,1],[1,1.93,6.15],[2,1.9,5.69]],"ltp":2.42,"tv":0.82,"id":72963954}]}]}
{"op":"mcm","clk":"11935303511","pt":1724341305475,"mc":[{"id":"1.232135506","rc":[{"batb":[[0,1.96,10],[1,1.95,4],[2,1.94,1]],"ltp":2.42,"tv":0.82,"id":72963954}]}]}
{"op":"mcm","clk":"11935303732","pt":1724341307571,"mc":[{"id":"1.232135506","rc":[{"batb":[[1,1.94,1],[2,1.93,6.15]],"ltp":2.42,"tv":0.82,"id":72963954}]}]}
{"op":"mcm","clk":"11935303842","pt":1724341308761,"mc":[{"id":"1.232135506","rc":[{"batb":[[0,1.94,1],[1,1.93,6.15],[2,1.9,5.69]],"ltp":2.42,"tv":0.82,"id":72963954}]}]}
{"op":"mcm","clk":"11935306001","pt":1724341329913,"mc":[{"id":"1.232135506","rc":[{"batb":[[0,1.96,10],[1,1.95,4],[2,1.94,1]],"ltp":2.42,"tv":0.82,"id":72963954}]}]}
{"op":"mcm","clk":"11935306211","pt":1724341332298,"mc":[{"id":"1.232135506","rc":[{"batb":[[1,1.94,1],[2,1.93,6.15]],"ltp":2.42,"tv":0.82,"id":72963954}]}]}
{"op":"mcm","clk":"11935306311","pt":1724341333495,"mc":[{"id":"1.232135506","rc":[{"batb":[[0,1.94,1],[1,1.93,6.15],[2,1.9,5.69]],"ltp":2.42,"tv":0.82,"id":72963954}]}]}
{"op":"mcm","clk":"11935307008","pt":1724341341597,"mc":[{"id":"1.232135506","rc":[{"batb":[[0,1.96,10],[1,1.95,4],[2,1.94,1]],"ltp":2.42,"tv":0.82,"id":72963954}]}]}
{"op":"mcm","clk":"11935307220","pt":1724341343925,"mc":[{"id":"1.232135506","rc":[{"batb":[[1,1.94,1],[2,1.93,6.15]],"ltp":2.42,"tv":0.82,"id":72963954}]}]}
{"op":"mcm","clk":"11935307304","pt":1724341344915,"mc":[{"id":"1.232135506","rc":[{"batb":[[0,1.94,1],[1,1.93,6.15],[2,1.9,5.69]],"ltp":2.42,"tv":0.82,"id":72963954}]}]}
{"op":"mcm","clk":"11935309881","pt":1724341372224,"mc":[{"id":"1.232135506","rc":[{"batb":[[0,1.96,10],[1,1.95,4],[2,1.94,1]],"ltp":2.42,"tv":0.82,"id":72963954}]}]}
{"op":"mcm","clk":"11935310095","pt":1724341374566,"mc":[{"id":"1.232135506","rc":[{"batb":[[1,1.94,1],[2,1.93,6.15]],"ltp":2.42,"tv":0.82,"id":72963954}]}]}
{"op":"mcm","clk":"11935322319","pt":1724341375736,"mc":[{"id":"1.232135506","rc":[{"batb":[[0,1.94,1],[1,1.93,6.15],[2,1.9,5.69]],"ltp":2.42,"tv":0.82,"id":72963954}]}]}
{"op":"mcm","clk":"11935325022","pt":1724341402391,"mc":[{"id":"1.232135506","rc":[{"batb":[[0,1.96,10],[1,1.95,4],[2,1.94,1]],"ltp":2.42,"tv":0.82,"id":72963954}]}]}
{"op":"mcm","clk":"11935325237","pt":1724341404473,"mc":[{"id":"1.232135506","rc":[{"batb":[[1,1.94,1],[2,1.93,6.15]],"ltp":2.42,"tv":0.82,"id":72963954}]}]}
{"op":"mcm","clk":"11935325380","pt":1724341405871,"mc":[{"id":"1.232135506","rc":[{"batb":[[0,1.94,1],[1,1.93,6.15],[2,1.9,5.69]],"ltp":2.42,"tv":0.82,"id":72963954}]}]}
{"op":"mcm","clk":"11935325596","pt":1724341407860,"mc":[{"id":"1.232135506","rc":[{"batb":[[0,1.95,4],[1,1.94,1],[2,1.93,6.15]],"ltp":2.42,"tv":0.82,"id":72963954}]}]}
{"op":"mcm","clk":"11935325846","pt":1724341410195,"mc":[{"id":"1.232135506","rc":[{"batb":[[0,1.94,1],[1,1.93,6.15],[2,1.9,5.69]],"ltp":2.42,"tv":0.82,"id":72963954}]}]}
{"op":"mcm","clk":"11935326354","pt":1724341414576,"mc":[{"id":"1.232135506","rc":[{"batb":[[0,1.96,10],[1,1.95,4],[2,1.94,1]],"ltp":2.42,"tv":0.82,"id":72963954}]}]}
{"op":"mcm","clk":"11935326593","pt":1724341416578,"mc":[{"id":"1.232135506","rc":[{"batb":[[1,1.94,1],[2,1.93,6.15]],"ltp":2.42,"tv":0.82,"id":72963954}]}]}
{"op":"mcm","clk":"11935326768","pt":1724341417980,"mc":[{"id":"1.232135506","rc":[{"batb":[[0,1.94,1],[1,1.93,6.15],[2,1.9,5.69]],"ltp":2.42,"tv":0.82,"id":72963954}]}]}
{"op":"mcm","clk":"11935328598","pt":1724341435520,"mc":[{"id":"1.232135506","rc":[{"batb":[[0,1.96,10],[1,1.95,4],[2,1.94,1]],"ltp":2.42,"tv":0.82,"id":72963954}]}]}
{"op":"mcm","clk":"11935328810","pt":1724341437507,"mc":[{"id":"1.232135506","rc":[{"batb":[[1,1.94,1],[2,1.93,6.15]],"ltp":2.42,"tv":0.82,"id":72963954}]}]}
{"op":"mcm","clk":"11935328917","pt":1724341438703,"mc":[{"id":"1.232135506","rc":[{"batb":[[0,1.94,1],[1,1.93,6.15],[2,1.9,5.69]],"ltp":2.42,"tv":0.82,"id":72963954}]}]}
{"op":"mcm","clk":"11935331318","pt":1724341459622,"mc":[{"id":"1.232135506","rc":[{"batb":[[0,1.96,10],[1,1.95,4],[2,1.94,1]],"ltp":2.42,"tv":0.82,"id":72963954}]}]}
{"op":"mcm","clk":"11935331541","pt":1724341461818,"mc":[{"id":"1.232135506","rc":[{"batb":[[1,1.94,1],[2,1.93,6.15]],"ltp":2.42,"tv":0.82,"id":72963954}]}]}
{"op":"mcm","clk":"11935331702","pt":1724341463521,"mc":[{"id":"1.232135506","rc":[{"batb":[[0,1.94,1],[1,1.93,6.15],[2,1.9,5.69]],"ltp":2.42,"tv":0.82,"id":72963954}]}]}
{"op":"mcm","clk":"11935332087","pt":1724341467195,"mc":[{"id":"1.232135506","rc":[{"batb":[[0,1.96,10],[1,1.95,4],[2,1.94,1]],"ltp":2.42,"tv":0.82,"id":72963954}]}]}
{"op":"mcm","clk":"11935332343","pt":1724341469639,"mc":[{"id":"1.232135506","rc":[{"batb":[[1,1.94,1],[2,1.93,6.15]],"ltp":2.42,"tv":0.82,"id":72963954}]}]}
{"op":"mcm","clk":"11935332430","pt":1724341470439,"mc":[{"id":"1.232135506","rc":[{"batb":[[0,1.94,1],[1,1.93,6.15],[2,1.9,5.69]],"ltp":2.42,"tv":0.82,"id":72963954}]}]}
{"op":"mcm","clk":"11935333381","pt":1724341478749,"mc":[{"id":"1.232135506","rc":[{"batb":[[0,1.96,10],[1,1.95,4],[2,1.94,1]],"ltp":2.42,"tv":0.82,"id":72963954}]}]}
{"op":"mcm","clk":"11935333619","pt":1724341481066,"mc":[{"id":"1.232135506","rc":[{"batb":[[1,1.94,1],[2,1.93,6.15]],"ltp":2.42,"tv":0.82,"id":72963954}]}]}
{"op":"mcm","clk":"11935333733","pt":1724341482163,"mc":[{"id":"1.232135506","rc":[{"batb":[[0,1.94,1],[1,1.93,6.15],[2,1.9,5.69]],"ltp":2.42,"tv":0.82,"id":72963954}]}]}
{"op":"mcm","clk":"11935334618","pt":1724341490370,"mc":[{"id":"1.232135506","rc":[{"batb":[[0,1.96,10],[1,1.95,4],[2,1.94,1]],"ltp":2.42,"tv":0.82,"id":72963954}]}]}
{"op":"mcm","clk":"11935334826","pt":1724341492586,"mc":[{"id":"1.232135506","rc":[{"batb":[[1,1.94,1],[2,1.93,6.15]],"ltp":2.42,"tv":0.82,"id":72963954}]}]}
{"op":"mcm","clk":"11935334943","pt":1724341493575,"mc":[{"id":"1.232135506","rc":[{"batb":[[0,1.94,1],[1,1.93,6.15],[2,1.9,5.69]],"ltp":2.42,"tv":0.82,"id":72963954}]}]}
{"op":"mcm","clk":"11935336057","pt":1724341504274,"mc":[{"id":"1.232135506","rc":[{"batb":[[0,1.96,10],[1,1.95,4],[2,1.94,1]],"ltp":2.42,"tv":0.82,"id":72963954}]}]}
{"op":"mcm","clk":"11935336340","pt":1724341506598,"mc":[{"id":"1.232135506","rc":[{"batb":[[1,1.94,1],[2,1.93,6.15]],"ltp":2.42,"tv":0.82,"id":72963954}]}]}
{"op":"mcm","clk":"11935336498","pt":1724341507866,"mc":[{"id":"1.232135506","rc":[{"batb":[[0,1.94,1],[1,1.93,6.15],[2,1.9,5.69]],"ltp":2.42,"tv":0.82,"id":72963954}]}]}
{"op":"mcm","clk":"11935336696","pt":1724341509583,"mc":[{"id":"1.232135506","rc":[{"batb":[[0,1.95,4],[1,1.94,1],[2,1.93,6.15]],"ltp":2.42,"tv":0.82,"id":72963954}]}]}
{"op":"mcm","clk":"11935336969","pt":1724341511780,"mc":[{"id":"1.232135506","rc":[{"batb":[[0,1.94,1],[1,1.93,6.15],[2,1.9,5.69]],"ltp":2.42,"tv":0.82,"id":72963954}]}]}
{"op":"mcm","clk":"11935337507","pt":1724341516673,"mc":[{"id":"1.232135506","rc":[{"batb":[[0,1.95,4],[1,1.94,1],[2,1.93,6.15]],"ltp":2.42,"tv":0.82,"id":72963954}]}]}
{"op":"mcm","clk":"11935337537","pt":1724341516871,"mc":[{"id":"1.232135506","rc":[{"batb":[[0,1.96,10],[1,1.95,4],[2,1.94,1]],"ltp":2.42,"tv":0.82,"id":72963954}]}]}
{"op":"mcm","clk":"11935337768","pt":1724341519107,"mc":[{"id":"1.232135506","rc":[{"batb":[[1,1.94,1],[2,1.93,6.15]],"ltp":2.42,"tv":0.82,"id":72963954}]}]}
{"op":"mcm","clk":"11935337903","pt":1724341520099,"mc":[{"id":"1.232135506","rc":[{"batb":[[0,1.94,1],[1,1.93,6.15],[2,1.9,5.69]],"ltp":2.42,"tv":0.82,"id":72963954}]}]}
{"op":"mcm","clk":"11935338426","pt":1724341525704,"mc":[{"id":"1.232135506","rc":[{"batb":[[0,1.95,4],[1,1.94,1],[2,1.93,6.15]],"ltp":2.42,"tv":0.82,"id":72963954}]}]}
{"op":"mcm","clk":"11935338456","pt":1724341525911,"mc":[{"id":"1.232135506","rc":[{"batb":[[0,1.96,10],[1,1.95,4],[2,1.94,1]],"ltp":2.42,"tv":0.82,"id":72963954}]}]}
{"op":"mcm","clk":"11935338655","pt":1724341527983,"mc":[{"id":"1.232135506","rc":[{"batb":[[1,1.94,1],[2,1.93,6.15]],"ltp":2.42,"tv":0.82,"id":72963954}]}]}
{"op":"mcm","clk":"11935338739","pt":1724341529095,"mc":[{"id":"1.232135506","rc":[{"batb":[[0,1.94,1],[1,1.93,6.15],[2,1.9,5.69]],"ltp":2.42,"tv":0.82,"id":72963954}]}]}
{"op":"mcm","clk":"11935340556","pt":1724341548618,"mc":[{"id":"1.232135506","rc":[{"batb":[[0,1.96,10],[1,1.95,4],[2,1.94,1]],"ltp":2.42,"tv":0.82,"id":72963954}]}]}
{"op":"mcm","clk":"11935340770","pt":1724341550913,"mc":[{"id":"1.232135506","rc":[{"batb":[[1,1.94,1],[2,1.93,6.15]],"ltp":2.42,"tv":0.82,"id":72963954}]}]}
{"op":"mcm","clk":"11935340862","pt":1724341551962,"mc":[{"id":"1.232135506","rc":[{"batb":[[0,1.94,1],[1,1.93,6.15],[2,1.9,5.69]],"ltp":2.42,"tv":0.82,"id":72963954}]}]}
{"op":"mcm","clk":"11935341276","pt":1724341556437,"mc":[{"id":"1.232135506","rc":[{"batb":[[0,1.96,10],[1,1.95,4],[2,1.94,1]],"ltp":2.42,"tv":0.82,"id":72963954}]}]}
{"op":"mcm","clk":"11935341479","pt":1724341558517,"mc":[{"id":"1.232135506","rc":[{"batb":[[1,1.94,1],[2,1.93,6.15]],"ltp":2.42,"tv":0.82,"id":72963954}]}]}
{"op":"mcm","clk":"11935341604","pt":1724341559820,"mc":[{"id":"1.232135506","rc":[{"batb":[[0,1.94,1],[1,1.93,6.15],[2,1.9,5.69]],"ltp":2.42,"tv":0.82,"id":72963954}]}]}
{"op":"mcm","clk":"11935342601","pt":1724341569633,"mc":[{"id":"1.232135506","rc":[{"batb":[[0,1.96,10],[1,1.95,4],[2,1.94,1]],"ltp":2.42,"tv":0.82,"id":72963954}]}]}
{"op":"mcm","clk":"11935342843","pt":1724341571745,"mc":[{"id":"1.232135506","rc":[{"batb":[[1,1.94,1],[2,1.93,6.15]],"ltp":2.42,"tv":0.82,"id":72963954}]}]}
{"op":"mcm","clk":"11935342963","pt":1724341573054,"mc":[{"id":"1.232135506","rc":[{"batb":[[0,1.94,1],[1,1.93,6.15],[2,1.9,5.69]],"ltp":2.42,"tv":0.82,"id":72963954}]}]}
{"op":"mcm","clk":"11935346970","pt":1724341614518,"mc":[{"id":"1.232135506","rc":[{"batb":[[0,1.96,10],[1,1.95,4],[2,1.94,1]],"ltp":2.42,"tv":0.82,"id":72963954}]}]}
{"op":"mcm","clk":"11935347149","pt":1724341616818,"mc":[{"id":"1.232135506","rc":[{"batb":[[1,1.94,1],[2,1.93,6.15]],"ltp":2.42,"tv":0.82,"id":72963954}]}]}
{"op":"mcm","clk":"11935347270","pt":1724341617922,"mc":[{"id":"1.232135506","rc":[{"batb":[[0,1.94,1],[1,1.93,6.15],[2,1.9,5.69]],"ltp":2.42,"tv":0.82,"id":72963954}]}]}
{"op":"mcm","clk":"11935348077","pt":1724341626305,"mc":[{"id":"1.232135506","rc":[{"batb":[[0,1.96,10],[1,1.95,4],[2,1.94,1]],"ltp":2.42,"tv":0.82,"id":72963954}]}]}
{"op":"mcm","clk":"11935348244","pt":1724341628448,"mc":[{"id":"1.232135506","rc":[{"batb":[[1,1.94,1],[2,1.93,6.15]],"ltp":2.42,"tv":0.82,"id":72963954}]}]}
{"op":"mcm","clk":"11935348326","pt":1724341629642,"mc":[{"id":"1.232135506","rc":[{"batb":[[0,1.94,1],[1,1.93,6.15],[2,1.9,5.69]],"ltp":2.42,"tv":0.82,"id":72963954}]}]}
{"op":"mcm","clk":"11935348646","pt":1724341632724,"mc":[{"id":"1.232135506","rc":[{"batb":[[0,1.96,10],[1,1.95,4],[2,1.94,1]],"ltp":2.42,"tv":0.82,"id":72963954}]}]}
{"op":"mcm","clk":"11935348874","pt":1724341634857,"mc":[{"id":"1.232135506","rc":[{"batb":[[1,1.94,1],[2,1.93,6.15]],"ltp":2.42,"tv":0.82,"id":72963954}]}]}
{"op":"mcm","clk":"11935348967","pt":1724341636151,"mc":[{"id":"1.232135506","rc":[{"batb":[[0,1.94,1],[1,1.93,6.15],[2,1.9,5.69]],"ltp":2.42,"tv":0.82,"id":72963954}]}]}
{"op":"mcm","clk":"11935349991","pt":1724341647739,"mc":[{"id":"1.232135506","rc":[{"batb":[[0,1.95,4],[1,1.94,1],[2,1.93,6.15]],"ltp":2.42,"tv":0.82,"id":72963954}]}]}
{"op":"mcm","clk":"11935350012","pt":1724341647948,"mc":[{"id":"1.232135506","rc":[{"batb":[[0,1.96,10],[1,1.95,4],[2,1.94,1]],"ltp":2.42,"tv":0.82,"id":72963954}]}]}
{"op":"mcm","clk":"11935350207","pt":1724341650148,"mc":[{"id":"1.232135506","rc":[{"batb":[[1,1.94,1],[2,1.93,6.15]],"ltp":2.42,"tv":0.82,"id":72963954}]}]}
{"op":"mcm","clk":"11935350343","pt":1724341651497,"mc":[{"id":"1.232135506","rc":[{"batb":[[0,1.94,1],[1,1.93,6.15],[2,1.9,5.69]],"ltp":2.42,"tv":0.82,"id":72963954}]}]}
{"op":"mcm","clk":"11935350623","pt":1724341654026,"mc":[{"id":"1.232135506","rc":[{"batb":[[0,1.96,10],[1,1.95,4],[2,1.94,1]],"ltp":2.42,"tv":0.82,"id":72963954}]}]}
{"op":"mcm","clk":"11935350817","pt":1724341656034,"mc":[{"id":"1.232135506","rc":[{"batb":[[1,1.94,1],[2,1.93,6.15]],"ltp":2.42,"tv":0.82,"id":72963954}]}]}
{"op":"mcm","clk":"11935350943","pt":1724341657429,"mc":[{"id":"1.232135506","rc":[{"batb":[[0,1.94,1],[1,1.93,6.15],[2,1.9,5.69]],"ltp":2.42,"tv":0.82,"id":72963954}]}]}
{"op":"mcm","clk":"11935351389","pt":1724341662171,"mc":[{"id":"1.232135506","rc":[{"batb":[[0,1.96,10],[1,1.95,4],[2,1.94,1]],"ltp":2.42,"tv":0.82,"id":72963954}]}]}
{"op":"mcm","clk":"11935351597","pt":1724341664557,"mc":[{"id":"1.232135506","rc":[{"batb":[[1,1.94,1],[2,1.93,6.15]],"ltp":2.42,"tv":0.82,"id":72963954}]}]}
{"op":"mcm","clk":"11935351735","pt":1724341665745,"mc":[{"id":"1.232135506","rc":[{"batb":[[0,1.94,1],[1,1.93,6.15],[2,1.9,5.69]],"ltp":2.42,"tv":0.82,"id":72963954}]}]}
{"op":"mcm","clk":"11935352688","pt":1724341676674,"mc":[{"id":"1.232135506","rc":[{"batb":[[0,1.95,4],[1,1.94,1],[2,1.93,6.15]],"ltp":2.42,"tv":0.82,"id":72963954}]}]}
{"op":"mcm","clk":"11935352703","pt":1724341676775,"mc":[{"id":"1.232135506","rc":[{"batb":[[0,1.96,10],[1,1.95,4],[2,1.94,1]],"ltp":2.42,"tv":0.82,"id":72963954}]}]}
{"op":"mcm","clk":"11935352910","pt":1724341679060,"mc":[{"id":"1.232135506","rc":[{"batb":[[1,1.94,1],[2,1.93,6.15]],"ltp":2.42,"tv":0.82,"id":72963954}]}]}
{"op":"mcm","clk":"11935353036","pt":1724341680362,"mc":[{"id":"1.232135506","rc":[{"batb":[[0,1.94,1],[1,1.93,6.15],[2,1.9,5.69]],"ltp":2.42,"tv":0.82,"id":72963954}]}]}
{"op":"mcm","clk":"11935353650","pt":1724341685695,"mc":[{"id":"1.232135506","rc":[{"batb":[[0,1.96,10],[1,1.95,4],[2,1.94,1]],"ltp":2.42,"tv":0.82,"id":72963954}]}]}
{"op":"mcm","clk":"11935353875","pt":1724341687678,"mc":[{"id":"1.232135506","rc":[{"batb":[[1,1.94,1],[2,1.93,6.15]],"ltp":2.42,"tv":0.82,"id":72963954}]}]}
{"op":"mcm","clk":"11935354016","pt":1724341688970,"mc":[{"id":"1.232135506","rc":[{"batb":[[0,1.94,1],[1,1.93,6.15],[2,1.9,5.69]],"ltp":2.42,"tv":0.82,"id":72963954}]}]}
{"op":"mcm","clk":"11935354521","pt":1724341693597,"mc":[{"id":"1.232135506","rc":[{"batb":[[0,1.96,10],[1,1.95,4],[2,1.94,1]],"ltp":2.42,"tv":0.82,"id":72963954}]}]}
{"op":"mcm","clk":"11935354732","pt":1724341695790,"mc":[{"id":"1.232135506","rc":[{"batb":[[1,1.94,1],[2,1.93,6.15]],"ltp":2.42,"tv":0.82,"id":72963954}]}]}
{"op":"mcm","clk":"11935354871","pt":1724341697091,"mc":[{"id":"1.232135506","rc":[{"batb":[[0,1.94,1],[1,1.93,6.15],[2,1.9,5.69]],"ltp":2.42,"tv":0.82,"id":72963954}]}]}
{"op":"mcm","clk":"11935355317","pt":1724341701204,"mc":[{"id":"1.232135506","rc":[{"batb":[[0,1.96,10],[1,1.95,4],[2,1.94,1]],"ltp":2.42,"tv":0.82,"id":72963954}]}]}
{"op":"mcm","clk":"11935355540","pt":1724341703295,"mc":[{"id":"1.232135506","rc":[{"batb":[[1,1.94,1],[2,1.93,6.15]],"ltp":2.42,"tv":0.82,"id":72963954}]}]}
{"op":"mcm","clk":"11935355660","pt":1724341704480,"mc":[{"id":"1.232135506","rc":[{"batb":[[0,1.94,1],[1,1.93,6.15],[2,1.9,5.69]],"ltp":2.42,"tv":0.82,"id":72963954}]}]}
{"op":"mcm","clk":"11935356197","pt":1724341710003,"mc":[{"id":"1.232135506","rc":[{"batb":[[0,1.96,10],[1,1.95,4],[2,1.94,1]],"ltp":2.42,"tv":0.82,"id":72963954}]}]}
{"op":"mcm","clk":"11935356417","pt":1724341712195,"mc":[{"id":"1.232135506","rc":[{"batb":[[1,1.94,1],[2,1.93,6.15]],"ltp":2.42,"tv":0.82,"id":72963954}]}]}
{"op":"mcm","clk":"11935356543","pt":1724341713398,"mc":[{"id":"1.232135506","rc":[{"batb":[[0,1.94,1],[1,1.93,6.15],[2,1.9,5.69]],"ltp":2.42,"tv":0.82,"id":72963954}]}]}
{"op":"mcm","clk":"11935357681","pt":1724341725115,"mc":[{"id":"1.232135506","rc":[{"batb":[[0,1.96,10],[1,1.95,4],[2,1.94,1]],"ltp":2.42,"tv":0.82,"id":72963954}]}]}
{"op":"mcm","clk":"11935357880","pt":1724341727237,"mc":[{"id":"1.232135506","rc":[{"batb":[[1,1.94,1],[2,1.93,6.15]],"ltp":2.42,"tv":0.82,"id":72963954}]}]}
{"op":"mcm","clk":"11935358031","pt":1724341728637,"mc":[{"id":"1.232135506","rc":[{"batb":[[0,1.94,1],[1,1.93,6.15],[2,1.9,5.69]],"ltp":2.42,"tv":0.82,"id":72963954}]}]}
{"op":"mcm","clk":"11935358477","pt":1724341733427,"mc":[{"id":"1.232135506","rc":[{"batb":[[0,1.95,4],[1,1.94,1],[2,1.93,6.15]],"ltp":2.42,"tv":0.82,"id":72963954}]}]}
{"op":"mcm","clk":"11935358514","pt":1724341733845,"mc":[{"id":"1.232135506","rc":[{"batb":[[0,1.96,10],[1,1.95,4],[2,1.94,1]],"ltp":2.42,"tv":0.82,"id":72963954}]}]}
{"op":"mcm","clk":"11935358702","pt":1724341735726,"mc":[{"id":"1.232135506","rc":[{"batb":[[1,1.94,1],[2,1.93,6.15]],"ltp":2.42,"tv":0.82,"id":72963954}]}]}
{"op":"mcm","clk":"11935358869","pt":1724341737233,"mc":[{"id":"1.232135506","rc":[{"batb":[[0,1.94,1],[1,1.93,6.15],[2,1.9,5.69]],"ltp":2.42,"tv":0.82,"id":72963954}]}]}
{"op":"mcm","clk":"11935359136","pt":1724341739631,"mc":[{"id":"1.232135506","rc":[{"batb":[[0,1.95,4],[1,1.94,1],[2,1.93,6.15]],"ltp":2.42,"tv":0.82,"id":72963954}]}]}
{"op":"mcm","clk":"11935359168","pt":1724341739944,"mc":[{"id":"1.232135506","rc":[{"batb":[[0,1.96,10],[1,1.95,4],[2,1.94,1]],"ltp":2.42,"tv":0.82,"id":72963954}]}]}
{"op":"mcm","clk":"11935359393","pt":1724341742241,"mc":[{"id":"1.232135506","rc":[{"batb":[[1,1.94,1],[2,1.93,6.15]],"ltp":2.42,"tv":0.82,"id":72963954}]}]}
{"op":"mcm","clk":"11935359501","pt":1724341743236,"mc":[{"id":"1.232135506","rc":[{"batb":[[0,1.94,1],[1,1.93,6.15],[2,1.9,5.69]],"ltp":2.42,"tv":0.82,"id":72963954}]}]}
{"op":"mcm","clk":"11935359688","pt":1724341744726,"mc":[{"id":"1.232135506","rc":[{"batb":[[0,1.95,4],[1,1.94,1],[2,1.93,6.15]],"ltp":2.42,"tv":0.82,"id":72963954}]}]}
{"op":"mcm","clk":"11935359948","pt":1724341747076,"mc":[{"id":"1.232135506","rc":[{"batb":[[0,1.94,1],[1,1.93,6.15],[2,1.9,5.69]],"ltp":2.42,"tv":0.82,"id":72963954}]}]}
{"op":"mcm","clk":"11935360863","pt":1724341755450,"mc":[{"id":"1.232135506","rc":[{"batb":[[0,1.96,10],[1,1.95,4],[2,1.94,1]],"ltp":2.42,"tv":0.82,"id":72963954}]}]}
{"op":"mcm","clk":"11935361065","pt":1724341757685,"mc":[{"id":"1.232135506","rc":[{"batb":[[1,1.94,1],[2,1.93,6.15]],"ltp":2.42,"tv":0.82,"id":72963954}]}]}
{"op":"mcm","clk":"11935361184","pt":1724341758671,"mc":[{"id":"1.232135506","rc":[{"batb":[[0,1.94,1],[1,1.93,6.15],[2,1.9,5.69]],"ltp":2.42,"tv":0.82,"id":72963954}]}]}
{"op":"mcm","clk":"11935361573","pt":1724341762562,"mc":[{"id":"1.232135506","rc":[{"batb":[[0,1.96,10],[1,1.95,4],[2,1.94,1]],"ltp":2.42,"tv":0.82,"id":72963954}]}]}
{"op":"mcm","clk":"11935361821","pt":1724341764582,"mc":[{"id":"1.232135506","rc":[{"batb":[[1,1.94,1],[2,1.93,6.15]],"ltp":2.42,"tv":0.82,"id":72963954}]}]}
{"op":"mcm","clk":"11935361945","pt":1724341765776,"mc":[{"id":"1.232135506","rc":[{"batb":[[0,1.94,1],[1,1.93,6.15],[2,1.9,5.69]],"ltp":2.42,"tv":0.82,"id":72963954}]}]}
{"op":"mcm","clk":"11935362198","pt":1724341768163,"mc":[{"id":"1.232135506","rc":[{"batb":[[0,1.96,10],[1,1.95,4],[2,1.94,1]],"ltp":2.42,"tv":0.82,"id":72963954}]}]}
{"op":"mcm","clk":"11935362414","pt":1724341770389,"mc":[{"id":"1.232135506","rc":[{"batb":[[1,1.94,1],[2,1.93,6.15]],"ltp":2.42,"tv":0.82,"id":72963954}]}]}
{"op":"mcm","clk":"11935362554","pt":1724341771897,"mc":[{"id":"1.232135506","rc":[{"batb":[[0,1.94,1],[1,1.93,6.15],[2,1.9,5.69]],"ltp":2.42,"tv":0.82,"id":72963954}]}]}
{"op":"mcm","clk":"11935362897","pt":1724341775283,"mc":[{"id":"1.232135506","rc":[{"batb":[[0,1.96,10],[1,1.95,4],[2,1.94,1]],"ltp":2.42,"tv":0.82,"id":72963954}]}]}
{"op":"mcm","clk":"11935363124","pt":1724341777365,"mc":[{"id":"1.232135506","rc":[{"batb":[[1,1.94,1],[2,1.93,6.15]],"ltp":2.42,"tv":0.82,"id":72963954}]}]}
{"op":"mcm","clk":"11935363267","pt":1724341778707,"mc":[{"id":"1.232135506","rc":[{"batb":[[0,1.94,1],[1,1.93,6.15],[2,1.9,5.69]],"ltp":2.42,"tv":0.82,"id":72963954}]}]}
{"op":"mcm","clk":"11935363483","pt":1724341780679,"mc":[{"id":"1.232135506","rc":[{"batb":[[0,1.95,4],[1,1.94,1],[2,1.93,6.15]],"ltp":2.42,"tv":0.82,"id":72963954}]}]}
{"op":"mcm","clk":"11935363683","pt":1724341783020,"mc":[{"id":"1.232135506","rc":[{"batb":[[0,1.94,1],[1,1.93,6.15],[2,1.9,5.69]],"ltp":2.42,"tv":0.82,"id":72963954}]}]}
{"op":"mcm","clk":"11935364253","pt":1724341788896,"mc":[{"id":"1.232135506","rc":[{"batb":[[0,1.96,10],[1,1.95,4],[2,1.94,1]],"ltp":2.42,"tv":0.82,"id":72963954}]}]}
{"op":"mcm","clk":"11935364496","pt":1724341791091,"mc":[{"id":"1.232135506","rc":[{"batb":[[1,1.94,1],[2,1.93,6.15]],"ltp":2.42,"tv":0.82,"id":72963954}]}]}
{"op":"mcm","clk":"11935364631","pt":1724341792290,"mc":[{"id":"1.232135506","rc":[{"batb":[[0,1.94,1],[1,1.93,6.15],[2,1.9,5.69]],"ltp":2.42,"tv":0.82,"id":72963954}]}]}
{"op":"mcm","clk":"11935365591","pt":1724341801506,"mc":[{"id":"1.232135506","rc":[{"batb":[[0,1.96,10],[1,1.95,4],[2,1.94,1]],"ltp":2.42,"tv":0.82,"id":72963954}]}]}
{"op":"mcm","clk":"11935365857","pt":1724341803543,"mc":[{"id":"1.232135506","rc":[{"batb":[[1,1.94,1],[2,1.93,6.15]],"ltp":2.42,"tv":0.82,"id":72963954}]}]}
{"op":"mcm","clk":"11935366017","pt":1724341804846,"mc":[{"id":"1.232135506","rc":[{"batb":[[0,1.94,1],[1,1.93,6.15],[2,1.9,5.69]],"ltp":2.42,"tv":0.82,"id":72963954}]}]}
{"op":"mcm","clk":"11935367493","pt":1724341818345,"mc":[{"id":"1.232135506","rc":[{"batb":[[0,1.96,10],[1,1.95,4],[2,1.94,1]],"ltp":2.42,"tv":0.82,"id":72963954}]}]}
{"op":"mcm","clk":"11935367735","pt":1724341820321,"mc":[{"id":"1.232135506","rc":[{"batb":[[1,1.94,1],[2,1.93,6.15]],"ltp":2.42,"tv":0.82,"id":72963954}]}]}
{"op":"mcm","clk":"11935367899","pt":1724341821743,"mc":[{"id":"1.232135506","rc":[{"trd":[[1.69,210.19]],"batl":[[0,1.69,8.85]],"ltp":1.69,"tv":452.93,"id":47674067},{"trd":[[2.44,0.02]],"batb":[[0,1.94,1],[1,1.93,6.15],[2,1.9,5.69]],"ltp":2.44,"tv":0.84,"id":72963954}],"tv":453.78}]}
{"op":"mcm","clk":"11935368700","pt":1724341829161,"mc":[{"id":"1.232135506","rc":[{"batb":[[0,1.96,10],[1,1.95,4],[2,1.94,1]],"ltp":2.44,"tv":0.84,"id":72963954}]}]}
{"op":"mcm","clk":"11935368864","pt":1724341830669,"mc":[{"id":"1.232135506","rc":[{"trd":[[1.69,210.22]],"batl":[[0,1.69,8.82]],"ltp":1.69,"tv":452.96,"id":47674067},{"trd":[[2.44,0.04]],"ltp":2.44,"tv":0.86,"id":72963954}],"tv":453.83}]}
{"op":"mcm","clk":"11935368941","pt":1724341831350,"mc":[{"id":"1.232135506","rc":[{"batb":[[1,1.94,1],[2,1.93,6.15]],"ltp":2.44,"tv":0.86,"id":72963954}]}]}
{"op":"mcm","clk":"11935369043","pt":1724341832348,"mc":[{"id":"1.232135506","rc":[{"batb":[[0,1.94,1],[1,1.93,6.15],[2,1.9,5.69]],"ltp":2.44,"tv":0.86,"id":72963954}]}]}
{"op":"mcm","clk":"11935369465","pt":1724341836150,"mc":[{"id":"1.232135506","rc":[{"batb":[[0,1.96,10],[1,1.95,4],[2,1.94,1]],"ltp":2.44,"tv":0.86,"id":72963954}]}]}
{"op":"mcm","clk":"11935369689","pt":1724341838391,"mc":[{"id":"1.232135506","rc":[{"batb":[[1,1.94,1],[2,1.93,6.15]],"ltp":2.44,"tv":0.86,"id":72963954}]}]}
{"op":"mcm","clk":"11935369839","pt":1724341839595,"mc":[{"id":"1.232135506","rc":[{"batb":[[0,1.94,1],[1,1.93,6.15],[2,1.9,5.69]],"ltp":2.44,"tv":0.86,"id":72963954}]}]}
{"op":"mcm","clk":"11935370068","pt":1724341841673,"mc":[{"id":"1.232135506","rc":[{"batb":[[0,1.95,4],[1,1.94,1],[2,1.93,6.15]],"ltp":2.44,"tv":0.86,"id":72963954}]}]}
{"op":"mcm","clk":"11935370266","pt":1724341843385,"mc":[{"id":"1.232135506","rc":[{"batb":[[0,1.94,1],[1,1.93,6.15],[2,1.9,5.69]],"ltp":2.44,"tv":0.86,"id":72963954}]}]}
{"op":"mcm","clk":"11935371933","pt":1724341858687,"mc":[{"id":"1.232135506","rc":[{"batb":[[0,1.95,4],[1,1.94,1],[2,1.93,6.15]],"ltp":2.44,"tv":0.86,"id":72963954}]}]}
{"op":"mcm","clk":"11935371988","pt":1724341859102,"mc":[{"id":"1.232135506","rc":[{"batb":[[0,1.96,10],[1,1.95,4],[2,1.94,1]],"ltp":2.44,"tv":0.86,"id":72963954}]}]}
{"op":"mcm","clk":"11935372224","pt":1724341861078,"mc":[{"id":"1.232135506","rc":[{"batb":[[1,1.94,1],[2,1.93,6.15]],"ltp":2.44,"tv":0.86,"id":72963954}]}]}
{"op":"mcm","clk":"11935372379","pt":1724341862515,"mc":[{"id":"1.232135506","rc":[{"batb":[[0,1.94,1],[1,1.93,6.15],[2,1.9,5.69]],"ltp":2.44,"tv":0.86,"id":72963954}]}]}
{"op":"mcm","clk":"11935373907","pt":1724341875195,"mc":[{"id":"1.232135506","rc":[{"batb":[[0,1.96,10],[1,1.95,4],[2,1.94,1]],"ltp":2.44,"tv":0.86,"id":72963954}]}]}
{"op":"mcm","clk":"11935374168","pt":1724341877433,"mc":[{"id":"1.232135506","rc":[{"batb":[[1,1.94,1],[2,1.93,6.15]],"ltp":2.44,"tv":0.86,"id":72963954}]}]}
{"op":"mcm","clk":"11935374292","pt":1724341878528,"mc":[{"id":"1.232135506","rc":[{"batb":[[0,1.94,1],[1,1.93,6.15],[2,1.9,5.69]],"ltp":2.44,"tv":0.86,"id":72963954}]}]}
{"op":"mcm","clk":"11935376370","pt":1724341896724,"mc":[{"id":"1.232135506","rc":[{"batb":[[0,1.96,10],[1,1.95,4],[2,1.94,1]],"ltp":2.44,"tv":0.86,"id":72963954}]}]}
{"op":"mcm","clk":"11935376642","pt":1724341899032,"mc":[{"id":"1.232135506","rc":[{"batb":[[1,1.94,1],[2,1.93,6.15]],"ltp":2.44,"tv":0.86,"id":72963954}]}]}
{"op":"mcm","clk":"11935376768","pt":1724341900125,"mc":[{"id":"1.232135506","rc":[{"batb":[[0,1.94,1],[1,1.93,6.15],[2,1.9,5.69]],"ltp":2.44,"tv":0.86,"id":72963954}]}]}
{"op":"mcm","clk":"11935377081","pt":1724341902730,"mc":[{"id":"1.232135506","rc":[{"batl":[[2,2.96,10]],"ltp":1.69,"tv":452.96,"id":47674067},{"batb":[[0,1.95,4],[1,1.94,1],[2,1.93,6.15]],"ltp":2.44,"tv":0.86,"id":72963954}]}]}
{"op":"mcm","clk":"11935377091","pt":1724341902833,"mc":[{"id":"1.232135506","rc":[{"batb":[[0,1.96,10],[1,1.95,4],[2,1.94,1]],"ltp":2.44,"tv":0.86,"id":72963954}]}]}
{"op":"mcm","clk":"11935377433","pt":1724341905747,"mc":[{"id":"1.232135506","rc":[{"batl":[[1,2.96,10],[2,5,1.02]],"ltp":1.69,"tv":452.96,"id":47674067},{"batb":[[1,1.94,1],[2,1.93,6.15]],"ltp":2.44,"tv":0.86,"id":72963954}]}]}
{"op":"mcm","clk":"11935377499","pt":1724341906268,"mc":[{"id":"1.232135506","rc":[{"batl":[[1,2.04,4.25],[2,2.96,10]],"ltp":1.69,"tv":452.96,"id":47674067},{"batb":[[0,1.94,1],[1,1.93,6.15],[2,1.9,5.69]],"ltp":2.44,"tv":0.86,"id":72963954}]}]}
{"op":"mcm","clk":"11935377733","pt":1724341908149,"mc":[{"id":"1.232135506","rc":[{"batb":[[0,1.95,4],[1,1.94,1],[2,1.93,6.15]],"ltp":2.44,"tv":0.86,"id":72963954}]}]}
{"op":"mcm","clk":"11935377865","pt":1724341909241,"mc":[{"id":"1.232135506","rc":[{"batl":[[1,2.06,4.22]],"ltp":1.69,"tv":452.96,"id":47674067},{"batb":[[0,1.96,10],[1,1.95,4],[2,1.94,1]],"ltp":2.44,"tv":0.86,"id":72963954}]}]}
{"op":"mcm","clk":"11935378002","pt":1724341910334,"mc":[{"id":"1.232135506","rc":[{"batb":[[1,1.94,1],[2,1.93,6.15]],"ltp":2.44,"tv":0.86,"id":72963954}]}]}
{"op":"mcm","clk":"11935378259","pt":1724341912568,"mc":[{"id":"1.232135506","rc":[{"batb":[[0,1.94,1],[1,1.93,6.15],[2,1.9,5.69]],"ltp":2.44,"tv":0.86,"id":72963954}]}]}
{"op":"mcm","clk":"11935378288","pt":1724341912774,"mc":[{"id":"1.232135506","rc":[{"batb":[[0,1.95,4],[1,1.94,1],[2,1.93,6.15]],"ltp":2.44,"tv":0.86,"id":72963954}]}]}
{"op":"mcm","clk":"11935378572","pt":1724341915058,"mc":[{"id":"1.232135506","rc":[{"batb":[[0,1.94,1],[1,1.93,6.15],[2,1.9,5.69]],"ltp":2.44,"tv":0.86,"id":72963954}]}]}
{"op":"mcm","clk":"11935379099","pt":1724341919680,"mc":[{"id":"1.232135506","rc":[{"trd":[[1.69,227.85]],"batl":[[0,2.06,4.22],[1,2.96,10],[2,5,1.02]],"ltp":1.69,"tv":470.6,"id":47674067}],"tv":471.46}]}
{"op":"mcm","clk":"11935379137","pt":1724341919943,"mc":[{"id":"1.232135506","rc":[{"batb":[[0,1.63,10],[1,1.62,8.27],[2,1.6,8.54]],"ltp":1.69,"tv":470.6,"id":47674067},{"batb":[[0,1.96,10],[1,1.95,4],[2,1.94,1]],"ltp":2.44,"tv":0.86,"id":72963954}]}]}
{"op":"mcm","clk":"11935379407","pt":1724341922050,"mc":[{"id":"1.232135506","rc":[{"batb":[[1,1.94,1],[2,1.93,6.15]],"ltp":2.44,"tv":0.86,"id":72963954}]}]}
{"op":"mcm","clk":"11935379556","pt":1724341923256,"mc":[{"id":"1.232135506","rc":[{"batb":[[0,1.64,4]],"batl":[[0,2.96,10.01],[1,5,1.02],[2,6,1.02]],"ltp":1.69,"tv":470.6,"id":47674067},{"batb":[[0,1.94,1],[1,1.93,6.15],[2,1.9,5.69]],"ltp":2.44,"tv":0.86,"id":72963954}]}]}
{"op":"mcm","clk":"11935379869","pt":1724341925756,"mc":[{"id":"1.232135506","rc":[{"batb":[[0,1.63,10]],"ltp":1.69,"tv":470.6,"id":47674067},{"batb":[[0,1.95,4],[1,1.94,1],[2,1.93,6.15]],"ltp":2.44,"tv":0.86,"id":72963954}]}]}
{"op":"mcm","clk":"11935379882","pt":1724341925863,"mc":[{"id":"1.232135506","rc":[{"batb":[[0,1.96,10],[1,1.95,4],[2,1.94,1]],"ltp":2.44,"tv":0.86,"id":72963954}]}]}
{"op":"mcm","clk":"11935380198","pt":1724341928383,"mc":[{"id":"1.232135506","rc":[{"batb":[[0,1.64,4],[1,1.63,10],[2,1.62,8.27]],"ltp":1.69,"tv":470.6,"id":47674067},{"batb":[[1,1.94,1],[2,1.93,6.15]],"ltp":2.44,"tv":0.86,"id":72963954}]}]}
{"op":"mcm","clk":"11935380344","pt":1724341929678,"mc":[{"id":"1.232135506","rc":[{"batb":[[1,1.62,8.27],[2,1.6,8.54]],"ltp":1.69,"tv":470.6,"id":47674067},{"batb":[[0,1.94,1],[1,1.93,6.15],[2,1.9,5.69]],"batl":[[0,2.94,4.1]],"ltp":2.44,"tv":0.86,"id":72963954}]}]}
{"op":"mcm","clk":"11935380493","pt":1724341930671,"mc":[{"id":"1.232135506","rc":[{"batb":[[0,1.62,8.27],[1,1.6,8.54],[2,1.55,755.44]],"ltp":1.69,"tv":470.6,"id":47674067}]}]}
{"op":"mcm","clk":"11935380511","pt":1724341930771,"mc":[{"id":"1.232135506","rc":[{"batb":[[0,1.95,4],[1,1.94,1],[2,1.93,6.15]],"ltp":2.44,"tv":0.86,"id":72963954}]}]}
{"op":"mcm","clk":"11935380857","pt":1724341933280,"mc":[{"id":"1.232135506","rc":[{"batb":[[0,1.63,14],[1,1.62,8.27],[2,1.6,8.54]],"ltp":1.69,"tv":470.6,"id":47674067},{"batb":[[0,1.94,1],[1,1.93,6.15],[2,1.9,5.69]],"ltp":2.44,"tv":0.86,"id":72963954}]}]}
{"op":"mcm","clk":"11935381114","pt":1724341935677,"mc":[{"id":"1.232135506","rc":[{"batb":[[0,1.63,10]],"ltp":1.69,"tv":470.6,"id":47674067}]}]}
{"op":"mcm","clk":"11935381199","pt":1724341936617,"mc":[{"id":"1.232135506","rc":[{"batb":[[0,1.62,8.27],[1,1.6,8.54],[2,1.55,755.44]],"ltp":1.69,"tv":470.6,"id":47674067},{"batb":[[0,1.96,10],[1,1.95,4],[2,1.94,1]],"ltp":2.44,"tv":0.86,"id":72963954}]}]}
{"op":"mcm","clk":"11935381436","pt":1724341938603,"mc":[{"id":"1.232135506","rc":[{"batb":[[0,1.63,4],[1,1.62,8.27],[2,1.6,8.54]],"batl":[[0,2.1,4.14],[1,2.96,10],[2,5,1.02]],"ltp":1.69,"tv":470.6,"id":47674067},{"batb":[[1,1.94,1],[2,1.93,6.15]],"ltp":2.44,"tv":0.86,"id":72963954}]}]}
{"op":"mcm","clk":"11935381547","pt":1724341939491,"mc":[{"id":"1.232135506","rc":[{"batb":[[0,1.64,10],[1,1.63,4],[2,1.62,8.27]],"ltp":1.69,"tv":470.6,"id":47674067},{"batb":[[0,1.94,1],[1,1.93,6.15],[2,1.9,5.69]],"ltp":2.44,"tv":0.86,"id":72963954}]}]}
{"op":"mcm","clk":"11935381681","pt":1724341940587,"mc":[{"id":"1.232135506","rc":[{"batb":[[1,1.62,8.27],[2,1.6,8.54]],"ltp":1.69,"tv":470.6,"id":47674067}]}]}
{"op":"mcm","clk":"11935381747","pt":1724341940794,"mc":[{"id":"1.232135506","rc":[{"batb":[[0,1.95,4],[1,1.94,1],[2,1.93,6.15]],"ltp":2.44,"tv":0.86,"id":72963954}]}]}
{"op":"mcm","clk":"11935381891","pt":1724341942108,"mc":[{"id":"1.232135506","rc":[{"batb":[[0,1.62,8.27],[1,1.6,8.54],[2,1.55,755.44]],"ltp":1.69,"tv":470.6,"id":47674067},{"batb":[[0,1.96,10],[1,1.95,4],[2,1.94,1]],"ltp":2.44,"tv":0.86,"id":72963954}]}]}
{"op":"mcm","clk":"11935382001","pt":1724341943095,"mc":[{"id":"1.232135506","rc":[{"batb":[[1,1.94,1],[2,1.93,6.15]],"ltp":2.44,"tv":0.86,"id":72963954}]}]}
{"op":"mcm","clk":"11935382254","pt":1724341945392,"mc":[{"id":"1.232135506","rc":[{"batb":[[0,1.63,14],[1,1.62,8.27],[2,1.6,8.54]],"batl":[[0,2.96,10.01],[1,5,1.02],[2,6,1.02]],"ltp":1.69,"tv":470.6,"id":47674067},{"batb":[[0,1.95,4]],"ltp":2.44,"tv":0.86,"id":72963954}]}]}
{"op":"mcm","clk":"11935382520","pt":1724341947698,"mc":[{"id":"1.232135506","rc":[{"batb":[[0,1.63,10]],"ltp":1.69,"tv":470.6,"id":47674067},{"batb":[[0,1.96,10]],"ltp":2.44,"tv":0.86,"id":72963954}]}]}
{"op":"mcm","clk":"11935382587","pt":1724341948219,"mc":[{"id":"1.232135506","rc":[{"batb":[[0,1.62,8.27],[1,1.6,8.54],[2,1.55,755.44]],"ltp":1.69,"tv":470.6,"id":47674067}]}]}
{"op":"mcm","clk":"11935382850","pt":1724341950729,"mc":[{"id":"1.232135506","rc":[{"batb":[[0,1.94,1],[1,1.93,6.15],[2,1.9,5.69]],"ltp":2.44,"tv":0.86,"id":72963954}]}]}
{"op":"mcm","clk":"11935382958","pt":1724341951725,"mc":[{"id":"1.232135506","rc":[{"batb":[[0,1.63,14],[1,1.62,8.27],[2,1.6,8.54]],"batl":[[0,2.02,35.45],[1,2.96,10],[2,5,1.02]],"ltp":1.69,"tv":470.6,"id":47674067},{"batb":[[0,1.95,4],[1,1.94,1],[2,1.93,6.15]],"ltp":2.44,"tv":0.86,"id":72963954}]}]}
{"op":"mcm","clk":"11935383122","pt":1724341953198,"mc":[{"id":"1.232135506","rc":[{"batb":[[0,1.63,10]],"ltp":1.69,"tv":470.6,"id":47674067},{"batb":[[0,1.94,1],[1,1.93,6.15],[2,1.9,5.69]],"ltp":2.44,"tv":0.86,"id":72963954}]}]}
{"op":"mcm","clk":"11935383235","pt":1724341954192,"mc":[{"id":"1.232135506","rc":[{"batb":[[0,1.62,8.27],[1,1.6,8.54],[2,1.55,755.44]],"ltp":1.69,"tv":470.6,"id":47674067}]}]}
{"op":"mcm","clk":"11935383974","pt":1724341960712,"mc":[{"id":"1.232135506","rc":[{"batl":[[0,1.95,26.9],[1,2.02,35.44],[2,2.96,10]],"ltp":1.69,"tv":470.6,"id":47674067}]}]}
{"op":"mcm","clk":"11935384031","pt":1724341961230,"mc":[{"id":"1.232135506","rc":[{"batb":[[0,1.63,10],[1,1.62,8.27],[2,1.6,8.54]],"ltp":1.69,"tv":470.6,"id":47674067},{"batb":[[0,1.96,10],[1,1.95,4],[2,1.94,1]],"ltp":2.44,"tv":0.86,"id":72963954}]}]}
{"op":"mcm","clk":"11935384279","pt":1724341963325,"mc":[{"id":"1.232135506","rc":[{"batb":[[1,1.94,1],[2,1.93,6.15]],"ltp":2.44,"tv":0.86,"id":72963954}]}]}
{"op":"mcm","clk":"11935384418","pt":1724341964625,"mc":[{"id":"1.232135506","rc":[{"batb":[[0,1.62,8.27],[1,1.6,8.54],[2,1.55,755.44]],"ltp":1.69,"tv":470.6,"id":47674067},{"batb":[[0,1.94,1],[1,1.93,6.15],[2,1.9,5.69]],"ltp":2.44,"tv":0.86,"id":72963954}]}]}
{"op":"mcm","clk":"11935384590","pt":1724341966135,"mc":[{"id":"1.232135506","rc":[{"batb":[[0,1.95,4],[1,1.94,1],[2,1.93,6.15]],"ltp":2.44,"tv":0.86,"id":72963954}]}]}
{"op":"mcm","clk":"11935384870","pt":1724341968629,"mc":[{"id":"1.232135506","rc":[{"batb":[[0,1.94,1],[1,1.93,6.15],[2,1.9,5.69]],"ltp":2.44,"tv":0.86,"id":72963954}]}]}
{"op":"mcm","clk":"11935385179","pt":1724341971537,"mc":[{"id":"1.232135506","rc":[{"batl":[[0,1.94,4.48],[1,1.95,26.89],[2,2.02,35.44]],"ltp":1.69,"tv":470.6,"id":47674067},{"batb":[[0,1.96,10],[1,1.95,4],[2,1.94,1]],"ltp":2.44,"tv":0.86,"id":72963954}]}]}
{"op":"mcm","clk":"11935385421","pt":1724341973467,"mc":[{"id":"1.232135506","rc":[{"batb":[[1,1.94,1],[2,1.93,6.15]],"ltp":2.44,"tv":0.86,"id":72963954}]}]}
{"op":"mcm","clk":"11935385592","pt":1724341974980,"mc":[{"id":"1.232135506","rc":[{"batb":[[0,1.94,1],[1,1.93,6.15],[2,1.9,5.69]],"ltp":2.44,"tv":0.86,"id":72963954}]}]}
{"op":"mcm","clk":"11935385714","pt":1724341975956,"mc":[{"id":"1.232135506","rc":[{"batl":[[0,1.93,26.9],[1,1.94,4.47]],"ltp":1.69,"tv":470.6,"id":47674067},{"batb":[[0,1.95,4],[1,1.94,1],[2,1.93,6.15]],"ltp":2.44,"tv":0.86,"id":72963954}]}]}
{"op":"mcm","clk":"11935385897","pt":1724341977273,"mc":[{"id":"1.232135506","rc":[{"batl":[[1,2.02,35.44],[2,2.96,10]],"ltp":1.69,"tv":470.6,"id":47674067},{"batb":[[0,1.96,10],[1,1.95,4],[2,1.94,1]],"ltp":2.44,"tv":0.86,"id":72963954}]}]}
{"op":"mcm","clk":"11935386013","pt":1724341978248,"mc":[{"id":"1.232135506","rc":[{"batb":[[1,1.94,1],[2,1.93,6.15]],"ltp":2.44,"tv":0.86,"id":72963954}]}]}
{"op":"mcm","clk":"11935386292","pt":1724341980670,"mc":[{"id":"1.232135506","rc":[{"batb":[[0,1.95,4]],"ltp":2.44,"tv":0.86,"id":72963954}]}]}
{"op":"mcm","clk":"11935386578","pt":1724341982879,"mc":[{"id":"1.232135506","rc":[{"batb":[[0,1.94,1],[1,1.93,6.15],[2,1.9,5.69]],"ltp":2.44,"tv":0.86,"id":72963954}]}]}
{"op":"mcm","clk":"11935388033","pt":1724341995370,"mc":[{"id":"1.232135506","rc":[{"batb":[[0,1.96,10],[1,1.95,4],[2,1.94,1]],"ltp":2.44,"tv":0.86,"id":72963954}]}]}
{"op":"mcm","clk":"11935388429","pt":1724341998758,"mc":[{"id":"1.232135506","rc":[{"batb":[[0,1.94,1],[1,1.93,6.15],[2,1.9,5.69]],"ltp":2.44,"tv":0.86,"id":72963954}]}]}
{"op":"mcm","clk":"11935389046","pt":1724342004491,"mc":[{"id":"1.232135506","rc":[{"batl":[[0,1.92,4.53],[1,1.93,26.89],[2,2.02,35.44]],"ltp":1.69,"tv":470.6,"id":47674067},{"batb":[[0,1.96,10],[1,1.95,4],[2,1.94,1]],"ltp":2.44,"tv":0.86,"id":72963954}]}]}
{"op":"mcm","clk":"11935389264","pt":1724342006367,"mc":[{"id":"1.232135506","rc":[{"batb":[[1,1.94,1],[2,1.93,6.15]],"ltp":2.44,"tv":0.86,"id":72963954}]}]}
{"op":"mcm","clk":"11935389453","pt":1724342007869,"mc":[{"id":"1.232135506","rc":[{"batb":[[0,1.94,1],[1,1.93,6.15],[2,1.9,5.69]],"ltp":2.44,"tv":0.86,"id":72963954}]}]}
{"op":"mcm","clk":"11935391134","pt":1724342022513,"mc":[{"id":"1.232135506","rc":[{"batb":[[0,1.95,4],[1,1.94,1],[2,1.93,6.15]],"ltp":2.44,"tv":0.86,"id":72963954}]}]}
{"op":"mcm","clk":"11935391167","pt":1724342022777,"mc":[{"id":"1.232135506","rc":[{"batb":[[0,1.96,10],[1,1.95,4],[2,1.94,1]],"ltp":2.44,"tv":0.86,"id":72963954}]}]}
{"op":"mcm","clk":"11935391270","pt":1724342023919,"mc":[{"id":"1.232135506","rc":[{"batl":[[0,1.91,27.62],[1,1.92,4.52]],"ltp":1.69,"tv":470.6,"id":47674067}]}]}
{"op":"mcm","clk":"11935391348","pt":1724342024804,"mc":[{"id":"1.232135506","rc":[{"batb":[[1,1.94,1],[2,1.93,6.15]],"ltp":2.44,"tv":0.86,"id":72963954}]}]}
{"op":"mcm","clk":"11935391518","pt":1724342026318,"mc":[{"id":"1.232135506","rc":[{"batl":[[1,2.02,35.44],[2,2.96,10]],"ltp":1.69,"tv":470.6,"id":47674067},{"batb":[[0,1.94,1],[1,1.93,6.15],[2,1.9,5.69]],"ltp":2.44,"tv":0.86,"id":72963954}]}]}
{"op":"mcm","clk":"11935391865","pt":1724342029632,"mc":[{"id":"1.232135506","rc":[{"batb":[[0,1.95,4],[1,1.94,1],[2,1.93,6.15]],"ltp":2.44,"tv":0.86,"id":72963954}]}]}
{"op":"mcm","clk":"11935391892","pt":1724342029933,"mc":[{"id":"1.232135506","rc":[{"batb":[[0,1.96,10],[1,1.95,4],[2,1.94,1]],"ltp":2.44,"tv":0.86,"id":72963954}]}]}
{"op":"mcm","clk":"11935392111","pt":1724342032198,"mc":[{"id":"1.232135506","rc":[{"batb":[[1,1.94,1],[2,1.93,6.15]],"ltp":2.44,"tv":0.86,"id":72963954}]}]}
{"op":"mcm","clk":"11935392208","pt":1724342033138,"mc":[{"id":"1.232135506","rc":[{"batb":[[0,1.94,1],[1,1.93,6.15],[2,1.9,5.69]],"ltp":2.44,"tv":0.86,"id":72963954}]}]}
{"op":"mcm","clk":"11935392545","pt":1724342036341,"mc":[{"id":"1.232135506","rc":[{"batl":[[0,1.9,4.57],[1,1.91,27.61],[2,2.02,35.44]],"ltp":1.69,"tv":470.6,"id":47674067},{"batb":[[0,1.96,10],[1,1.95,4],[2,1.94,1]],"ltp":2.44,"tv":0.86,"id":72963954}]}]}
{"op":"mcm","clk":"11935392758","pt":1724342038426,"mc":[{"id":"1.232135506","rc":[{"batb":[[1,1.94,1],[2,1.93,6.15]],"ltp":2.44,"tv":0.86,"id":72963954}]}]}
{"op":"mcm","clk":"11935392871","pt":1724342039657,"mc":[{"id":"1.232135506","rc":[{"batb":[[0,1.94,1],[1,1.93,6.15],[2,1.9,5.69]],"ltp":2.44,"tv":0.86,"id":72963954}]}]}
{"op":"mcm","clk":"11935393160","pt":1724342042230,"mc":[{"id":"1.232135506","rc":[{"batl":[[0,1.89,27.62],[1,1.9,4.56]],"ltp":1.69,"tv":470.6,"id":47674067},{"batb":[[0,1.96,10],[1,1.95,4],[2,1.94,1]],"ltp":2.44,"tv":0.86,"id":72963954}]}]}
{"op":"mcm","clk":"11935393403","pt":1724342044356,"mc":[{"id":"1.232135506","rc":[{"batl":[[1,2.02,35.44],[2,2.96,10]],"ltp":1.69,"tv":470.6,"id":47674067},{"batb":[[1,1.94,1],[2,1.93,6.15]],"ltp":2.44,"tv":0.86,"id":72963954}]}]}
{"op":"mcm","clk":"11935393548","pt":1724342045654,"mc":[{"id":"1.232135506","rc":[{"batb":[[0,1.94,1],[1,1.93,6.15],[2,1.9,5.69]],"ltp":2.44,"tv":0.86,"id":72963954}]}]}
{"op":"mcm","clk":"11935394513","pt":1724342053750,"mc":[{"id":"1.232135506","rc":[{"batb":[[0,1.95,4],[1,1.94,1],[2,1.93,6.15]],"ltp":2.44,"tv":0.86,"id":72963954}]}]}
{"op":"mcm","clk":"11935394528","pt":1724342053856,"mc":[{"id":"1.232135506","rc":[{"batb":[[0,1.96,10],[1,1.95,4],[2,1.94,1]],"ltp":2.44,"tv":0.86,"id":72963954}]}]}
{"op":"mcm","clk":"11935394768","pt":1724342055981,"mc":[{"id":"1.232135506","rc":[{"batb":[[1,1.94,1],[2,1.93,6.15]],"ltp":2.44,"tv":0.86,"id":72963954}]}]}
{"op":"mcm","clk":"11935394918","pt":1724342057247,"mc":[{"id":"1.232135506","rc":[{"batb":[[0,1.94,1],[1,1.93,6.15],[2,1.9,5.69]],"ltp":2.44,"tv":0.86,"id":72963954}]}]}
{"op":"mcm","clk":"11935396000","pt":1724342066690,"mc":[{"id":"1.232135506","rc":[{"batb":[[0,1.96,10],[1,1.95,4],[2,1.94,1]],"ltp":2.44,"tv":0.86,"id":72963954}]}]}
{"op":"mcm","clk":"11935396231","pt":1724342068564,"mc":[{"id":"1.232135506","rc":[{"batl":[[0,1.88,4.62],[1,1.89,27.61],[2,2.02,35.44]],"ltp":1.69,"tv":470.6,"id":47674067},{"batb":[[1,1.94,1],[2,1.93,6.15]],"ltp":2.44,"tv":0.86,"id":72963954}]}]}
{"op":"mcm","clk":"11935396428","pt":1724342070066,"mc":[{"id":"1.232135506","rc":[{"batb":[[0,1.94,1],[1,1.93,6.15],[2,1.9,5.69]],"ltp":2.44,"tv":0.86,"id":72963954}]}]}
{"op":"mcm","clk":"11935396720","pt":1724342072291,"mc":[{"id":"1.232135506","rc":[{"batb":[[0,1.96,10],[1,1.95,4],[2,1.94,1]],"ltp":2.44,"tv":0.86,"id":72963954}]}]}
{"op":"mcm","clk":"11935397000","pt":1724342074382,"mc":[{"id":"1.232135506","rc":[{"batb":[[1,1.94,1],[2,1.93,6.15]],"ltp":2.44,"tv":0.86,"id":72963954}]}]}
{"op":"mcm","clk":"11935397139","pt":1724342075672,"mc":[{"id":"1.232135506","rc":[{"batb":[[0,1.94,1],[1,1.93,6.15],[2,1.9,5.69]],"ltp":2.44,"tv":0.86,"id":72963954}]}]}
{"op":"mcm","clk":"11935398134","pt":1724342084708,"mc":[{"id":"1.232135506","rc":[{"batb":[[0,1.96,10],[1,1.95,4],[2,1.94,1]],"ltp":2.44,"tv":0.86,"id":72963954}]}]}
{"op":"mcm","clk":"11935398370","pt":1724342086904,"mc":[{"id":"1.232135506","rc":[{"batb":[[1,1.94,1],[2,1.93,6.15]],"ltp":2.44,"tv":0.86,"id":72963954}]}]}
{"op":"mcm","clk":"11935398527","pt":1724342088407,"mc":[{"id":"1.232135506","rc":[{"batb":[[0,1.94,1],[1,1.93,6.15],[2,1.9,5.69]],"ltp":2.44,"tv":0.86,"id":72963954}]}]}
{"op":"mcm","clk":"11935399588","pt":1724342097722,"mc":[{"id":"1.232135506","rc":[{"batl":[[1,2.02,35.44],[2,2.96,10]],"ltp":1.69,"tv":470.6,"id":47674067}]}]}
{"op":"mcm","clk":"11935399696","pt":1724342098710,"mc":[{"id":"1.232135506","rc":[{"batl":[[0,1.87,27.62]],"ltp":1.69,"tv":470.6,"id":47674067},{"batb":[[0,1.96,10],[1,1.95,4],[2,1.94,1]],"ltp":2.44,"tv":0.86,"id":72963954}]}]}
{"op":"mcm","clk":"11935399713","pt":1724342098817,"mc":[{"id":"1.232135506","rc":[{"batl":[[0,1.86,4.67],[1,1.87,27.61],[2,2.02,35.44]],"ltp":1.69,"tv":470.6,"id":47674067}]}]}
{"op":"mcm","clk":"11935399846","pt":1724342100115,"mc":[{"id":"1.232135506","rc":[{"batb":[[1,1.94,1],[2,1.93,6.15]],"ltp":2.44,"tv":0.86,"id":72963954}]}]}
{"op":"mcm","clk":"11935399975","pt":1724342101214,"mc":[{"id":"1.232135506","rc":[{"batb":[[0,1.94,1],[1,1.93,6.15],[2,1.9,5.69]],"ltp":2.44,"tv":0.86,"id":72963954}]}]}
{"op":"mcm","clk":"11935400238","pt":1724342103423,"mc":[{"id":"1.232135506","rc":[{"batb":[[0,1.95,4],[1,1.94,1],[2,1.93,6.15]],"ltp":2.44,"tv":0.86,"id":72963954}]}]}
{"op":"mcm","clk":"11935400299","pt":1724342103820,"mc":[{"id":"1.232135506","rc":[{"batb":[[0,1.96,10],[1,1.95,4],[2,1.94,1]],"ltp":2.44,"tv":0.86,"id":72963954}]}]}
{"op":"mcm","clk":"11935400582","pt":1724342105704,"mc":[{"id":"1.232135506","rc":[{"batl":[[1,2.02,35.44],[2,2.96,10]],"ltp":1.69,"tv":470.6,"id":47674067}]}]}
{"op":"mcm","clk":"11935400668","pt":1724342106388,"mc":[{"id":"1.232135506","rc":[{"batl":[[0,1.85,27.62]],"ltp":1.69,"tv":470.6,"id":47674067},{"batb":[[1,1.94,1],[2,1.93,6.15]],"ltp":2.44,"tv":0.86,"id":72963954}]}]}
{"op":"mcm","clk":"11935400772","pt":1724342107220,"mc":[{"id":"1.232135506","rc":[{"batb":[[0,1.94,1],[1,1.93,6.15],[2,1.9,5.69]],"ltp":2.44,"tv":0.86,"id":72963954}]}]}
{"op":"mcm","clk":"11935402731","pt":1724342123226,"mc":[{"id":"1.232135506","rc":[{"batb":[[2,1.55,756.37]],"ltp":1.69,"tv":470.6,"id":47674067},{"batb":[[0,1.96,10],[1,1.95,4],[2,1.94,1]],"ltp":2.44,"tv":0.86,"id":72963954}]}]}
{"op":"mcm","clk":"11935403034","pt":1724342125555,"mc":[{"id":"1.232135506","rc":[{"batb":[[1,1.94,1],[2,1.93,6.15]],"ltp":2.44,"tv":0.86,"id":72963954}]}]}
{"op":"mcm","clk":"11935403151","pt":1724342126641,"mc":[{"id":"1.232135506","rc":[{"batb":[[0,1.94,1],[1,1.93,6.15],[2,1.9,5.69]],"ltp":2.44,"tv":0.86,"id":72963954}]}]}
{"op":"mcm","clk":"11935403782","pt":1724342131736,"mc":[{"id":"1.232135506","rc":[{"batl":[[0,1.84,4.72],[1,1.85,27.61],[2,2.02,35.44]],"ltp":1.69,"tv":470.6,"id":47674067},{"batb":[[0,1.95,4],[1,1.94,1],[2,1.93,6.15]],"ltp":2.44,"tv":0.86,"id":72963954}]}]}
{"op":"mcm","clk":"11935403810","pt":1724342131966,"mc":[{"id":"1.232135506","rc":[{"batb":[[0,1.96,10],[1,1.95,4],[2,1.94,1]],"ltp":2.44,"tv":0.86,"id":72963954}]}]}
{"op":"mcm","clk":"11935404109","pt":1724342134159,"mc":[{"id":"1.232135506","rc":[{"batb":[[1,1.94,1],[2,1.93,6.15]],"ltp":2.44,"tv":0.86,"id":72963954}]}]}
{"op":"mcm","clk":"11935404309","pt":1724342135664,"mc":[{"id":"1.232135506","rc":[{"batb":[[0,1.94,1],[1,1.93,6.15],[2,1.9,5.69]],"ltp":2.44,"tv":0.86,"id":72963954}]}]}
{"op":"mcm","clk":"11935404608","pt":1724342138359,"mc":[{"id":"1.232135506","rc":[{"batb":[[0,1.96,10],[1,1.95,4],[2,1.94,1]],"ltp":2.44,"tv":0.86,"id":72963954}]}]}
{"op":"mcm","clk":"11935404917","pt":1724342140581,"mc":[{"id":"1.232135506","rc":[{"batb":[[1,1.94,1],[2,1.93,6.15]],"ltp":2.44,"tv":0.86,"id":72963954}]}]}
{"op":"mcm","clk":"11935405091","pt":1724342141979,"mc":[{"id":"1.232135506","rc":[{"batb":[[0,1.94,1],[1,1.93,6.15],[2,1.9,5.69]],"ltp":2.44,"tv":0.86,"id":72963954}]}]}
{"op":"mcm","clk":"11935405188","pt":1724342142875,"mc":[{"id":"1.232135506","rc":[{"batl":[[0,1.83,27.62],[1,1.84,4.72]],"ltp":1.69,"tv":470.6,"id":47674067},{"batb":[[0,1.95,4],[1,1.94,1],[2,1.93,6.15]],"ltp":2.44,"tv":0.86,"id":72963954}]}]}
{"op":"mcm","clk":"11935405441","pt":1724342145191,"mc":[{"id":"1.232135506","rc":[{"batb":[[0,1.94,1],[1,1.93,6.15],[2,1.9,5.69]],"ltp":2.44,"tv":0.86,"id":72963954}]}]}
{"op":"mcm","clk":"11935405523","pt":1724342145775,"mc":[{"id":"1.232135506","rc":[{"batl":[[1,2.02,35.44],[2,2.96,10]],"ltp":1.69,"tv":470.6,"id":47674067}]}]}
{"op":"mcm","clk":"11935405869","pt":1724342148689,"mc":[{"id":"1.232135506","rc":[{"batb":[[0,1.96,10],[1,1.95,4],[2,1.94,1]],"ltp":2.44,"tv":0.86,"id":72963954}]}]}
{"op":"mcm","clk":"11935406103","pt":1724342150672,"mc":[{"id":"1.232135506","rc":[{"batb":[[1,1.94,1],[2,1.93,6.15]],"ltp":2.44,"tv":0.86,"id":72963954}]}]}
{"op":"mcm","clk":"11935406276","pt":1724342151980,"mc":[{"id":"1.232135506","rc":[{"batb":[[0,1.94,1],[1,1.93,6.15],[2,1.9,5.69]],"ltp":2.44,"tv":0.86,"id":72963954}]}]}
{"op":"mcm","clk":"11935406422","pt":1724342153386,"mc":[{"id":"1.232135506","rc":[{"batb":[[0,1.95,4],[1,1.94,1],[2,1.93,6.15]],"ltp":2.44,"tv":0.86,"id":72963954}]}]}
{"op":"mcm","clk":"11935406699","pt":1724342155668,"mc":[{"id":"1.232135506","rc":[{"batb":[[0,1.96,10]],"ltp":2.44,"tv":0.86,"id":72963954}]}]}
{"op":"mcm","clk":"11935407053","pt":1724342158716,"mc":[{"id":"1.232135506","rc":[{"batb":[[0,1.94,1],[1,1.93,6.15],[2,1.9,5.69]],"ltp":2.44,"tv":0.86,"id":72963954}]}]}
{"op":"mcm","clk":"11935407085","pt":1724342158983,"mc":[{"id":"1.232135506","rc":[{"batb":[[0,1.95,4],[1,1.94,1],[2,1.93,6.15]],"ltp":2.44,"tv":0.86,"id":72963954}]}]}
{"op":"mcm","clk":"11935407354","pt":1724342161377,"mc":[{"id":"1.232135506","rc":[{"batb":[[0,1.94,1],[1,1.93,6.15],[2,1.9,5.69]],"ltp":2.44,"tv":0.86,"id":72963954}]}]}
{"op":"mcm","clk":"11935407424","pt":1724342161998,"mc":[{"id":"1.232135506","rc":[{"batl":[[0,1.82,4.77],[1,1.83,27.61],[2,2.02,35.44]],"ltp":1.69,"tv":470.6,"id":47674067}]}]}
{"op":"mcm","clk":"11935407692","pt":1724342164597,"mc":[{"id":"1.232135506","rc":[{"batb":[[0,1.96,10],[1,1.95,4],[2,1.94,1]],"ltp":2.44,"tv":0.86,"id":72963954}]}]}
{"op":"mcm","clk":"11935407952","pt":1724342166640,"mc":[{"id":"1.232135506","rc":[{"batb":[[1,1.94,1],[2,1.93,6.15]],"ltp":2.44,"tv":0.86,"id":72963954}]}]}
{"op":"mcm","clk":"11935408089","pt":1724342167788,"mc":[{"id":"1.232135506","rc":[{"batb":[[0,1.94,1],[1,1.93,6.15],[2,1.9,5.69]],"ltp":2.44,"tv":0.86,"id":72963954}]}]}
{"op":"mcm","clk":"11935408415","pt":1724342170693,"mc":[{"id":"1.232135506","rc":[{"batl":[[1,2.02,35.44],[2,2.96,10]],"ltp":1.69,"tv":470.6,"id":47674067}]}]}
{"op":"mcm","clk":"11935408469","pt":1724342171207,"mc":[{"id":"1.232135506","rc":[{"batl":[[0,1.81,27.62],[1,1.82,4.77],[2,2.02,35.44]],"ltp":1.69,"tv":470.6,"id":47674067},{"batb":[[0,1.96,10],[1,1.95,4],[2,1.94,1]],"ltp":2.44,"tv":0.86,"id":72963954}]}]}
{"op":"mcm","clk":"11935408709","pt":1724342173439,"mc":[{"id":"1.232135506","rc":[{"batl":[[1,2.02,35.44],[2,2.96,10]],"ltp":1.69,"tv":470.6,"id":47674067},{"batb":[[1,1.94,1],[2,1.93,6.15]],"ltp":2.44,"tv":0.86,"id":72963954}]}]}
{"op":"mcm","clk":"11935408847","pt":1724342174526,"mc":[{"id":"1.232135506","rc":[{"batb":[[0,1.94,1],[1,1.93,6.15],[2,1.9,5.69]],"ltp":2.44,"tv":0.86,"id":72963954}]}]}
{"op":"mcm","clk":"11935409012","pt":1724342175926,"mc":[{"id":"1.232135506","rc":[{"batb":[[0,1.95,4],[1,1.94,1],[2,1.93,6.15]],"ltp":2.44,"tv":0.86,"id":72963954}]}]}
{"op":"mcm","clk":"11935409276","pt":1724342178216,"mc":[{"id":"1.232135506","rc":[{"batb":[[0,1.94,1],[1,1.93,6.15],[2,1.9,5.69]],"ltp":2.44,"tv":0.86,"id":72963954}]}]}
{"op":"mcm","clk":"11935410323","pt":1724342186709,"mc":[{"id":"1.232135506","rc":[{"batb":[[2,1.55,757.29]],"ltp":1.69,"tv":470.6,"id":47674067},{"batb":[[0,1.96,10],[1,1.95,4],[2,1.94,1]],"ltp":2.44,"tv":0.86,"id":72963954}]}]}
{"op":"mcm","clk":"11935410535","pt":1724342188744,"mc":[{"id":"1.232135506","rc":[{"batb":[[1,1.94,1],[2,1.93,6.15]],"ltp":2.44,"tv":0.86,"id":72963954}]}]}
{"op":"mcm","clk":"11935410711","pt":1724342190136,"mc":[{"id":"1.232135506","rc":[{"batb":[[0,1.94,1],[1,1.93,6.15],[2,1.9,5.69]],"ltp":2.44,"tv":0.86,"id":72963954}]}]}
{"op":"mcm","clk":"11935411180","pt":1724342193669,"mc":[{"id":"1.232135506","rc":[{"batl":[[0,1.8,4.82],[1,1.81,27.61],[2,2.02,35.44]],"ltp":1.69,"tv":470.6,"id":47674067},{"batb":[[0,1.95,4],[1,1.94,1],[2,1.93,6.15]],"ltp":2.44,"tv":0.86,"id":72963954}]}]}
{"op":"mcm","clk":"11935411209","pt":1724342193834,"mc":[{"id":"1.232135506","rc":[{"batb":[[0,1.96,10],[1,1.95,4],[2,1.94,1]],"ltp":2.44,"tv":0.86,"id":72963954}]}]}
{"op":"mcm","clk":"11935411463","pt":1724342195869,"mc":[{"id":"1.232135506","rc":[{"batb":[[1,1.94,1],[2,1.93,6.15]],"ltp":2.44,"tv":0.86,"id":72963954}]}]}
{"op":"mcm","clk":"11935411596","pt":1724342197065,"mc":[{"id":"1.232135506","rc":[{"batb":[[0,1.94,1],[1,1.93,6.15],[2,1.9,5.69]],"ltp":2.44,"tv":0.86,"id":72963954}]}]}
{"op":"mcm","clk":"11935412252","pt":1724342202359,"mc":[{"id":"1.232135506","rc":[{"batb":[[0,1.96,10],[1,1.95,4],[2,1.94,1]],"ltp":2.44,"tv":0.86,"id":72963954}]}]}
{"op":"mcm","clk":"11935412530","pt":1724342204592,"mc":[{"id":"1.232135506","rc":[{"batb":[[1,1.94,1],[2,1.93,6.15]],"ltp":2.44,"tv":0.86,"id":72963954}]}]}
{"op":"mcm","clk":"11935412651","pt":1724342205577,"mc":[{"id":"1.232135506","rc":[{"batb":[[0,1.94,1],[1,1.93,6.15],[2,1.9,5.69]],"ltp":2.44,"tv":0.86,"id":72963954}]}]}
{"op":"mcm","clk":"11935412836","pt":1724342207080,"mc":[{"id":"1.232135506","rc":[{"batb":[[0,1.95,4],[1,1.94,1],[2,1.93,6.15]],"ltp":2.44,"tv":0.86,"id":72963954}]}]}
{"op":"mcm","clk":"11935413116","pt":1724342209720,"mc":[{"id":"1.232135506","rc":[{"batl":[[1,2.02,35.44],[2,2.96,10]],"ltp":1.69,"tv":470.6,"id":47674067},{"batb":[[0,1.94,1],[1,1.93,6.15],[2,1.9,5.69]],"ltp":2.44,"tv":0.86,"id":72963954}]}]}
{"op":"mcm","clk":"11935413410","pt":1724342212522,"mc":[{"id":"1.232135506","rc":[{"batb":[[0,1.63,10],[1,1.62,8.27],[2,1.6,8.54]],"batl":[[0,2.02,35.45],[1,2.96,10],[2,5,1.02]],"ltp":1.69,"tv":470.6,"id":47674067},{"batb":[[0,1.96,10],[1,1.95,4],[2,1.94,1]],"ltp":2.44,"tv":0.86,"id":72963954}]}]}
{"op":"mcm","clk":"11935413574","pt":1724342214183,"mc":[{"id":"1.232135506","rc":[{"batb":[[1,1.94,1],[2,1.93,6.15]],"ltp":2.44,"tv":0.86,"id":72963954}]}]}
{"op":"mcm","clk":"11935413655","pt":1724342215115,"mc":[{"id":"1.232135506","rc":[{"batb":[[0,1.62,8.27],[1,1.6,8.54],[2,1.55,757.29]],"ltp":1.69,"tv":470.6,"id":47674067}]}]}
{"op":"mcm","clk":"11935413719","pt":1724342215791,"mc":[{"id":"1.232135506","rc":[{"batb":[[0,1.94,1],[1,1.93,6.15],[2,1.9,5.69]],"ltp":2.44,"tv":0.86,"id":72963954}]}]}
{"op":"mcm","clk":"11935414020","pt":1724342218704,"mc":[{"id":"1.232135506","rc":[{"batb":[[0,1.63,10],[1,1.62,8.27],[2,1.6,8.54]],"ltp":1.69,"tv":470.6,"id":47674067},{"batb":[[0,1.96,10],[1,1.95,4],[2,1.94,1]],"ltp":2.44,"tv":0.86,"id":72963954}]}]}
{"op":"mcm","clk":"11935414246","pt":1724342220839,"mc":[{"id":"1.232135506","rc":[{"batb":[[1,1.94,1],[2,1.93,6.15]],"ltp":2.44,"tv":0.86,"id":72963954}]}]}
{"op":"mcm","clk":"11935414409","pt":1724342222246,"mc":[{"id":"1.232135506","rc":[{"batb":[[0,1.63,24.62]],"ltp":1.69,"tv":470.6,"id":47674067},{"batb":[[0,1.94,1],[1,1.93,6.15],[2,1.9,5.69]],"ltp":2.44,"tv":0.86,"id":72963954}]}]}
{"op":"mcm","clk":"11935414800","pt":1724342225520,"mc":[{"id":"1.232135506","rc":[{"batb":[[0,1.64,10],[1,1.63,32.75],[2,1.62,8.27]],"ltp":1.69,"tv":470.6,"id":47674067},{"batb":[[0,1.96,10],[1,1.95,4],[2,1.94,1]],"ltp":2.44,"tv":0.86,"id":72963954}]}]}
{"op":"mcm","clk":"11935414869","pt":1724342226144,"mc":[{"id":"1.232135506","rc":[{"batl":[[0,2,4.35],[1,2.02,35.44],[2,2.96,10]],"ltp":1.69,"tv":470.6,"id":47674067}]}]}
{"op":"mcm","clk":"11935415054","pt":1724342227645,"mc":[{"id":"1.232135506","rc":[{"batb":[[1,1.94,1],[2,1.93,6.15]],"ltp":2.44,"tv":0.86,"id":72963954}]}]}
{"op":"mcm","clk":"11935415195","pt":1724342228849,"mc":[{"id":"1.232135506","rc":[{"batb":[[0,1.63,32.75],[1,1.62,8.27],[2,1.6,8.54]],"ltp":1.69,"tv":470.6,"id":47674067},{"batb":[[0,1.94,1],[1,1.93,6.15],[2,1.9,5.69]],"ltp":2.44,"tv":0.86,"id":72963954}]}]}
{"op":"mcm","clk":"11935416216","pt":1724342238145,"mc":[{"id":"1.232135506","rc":[{"batb":[[0,1.64,10],[1,1.63,32.75],[2,1.62,8.27]],"ltp":1.69,"tv":470.6,"id":47674067},{"batb":[[0,1.95,4],[1,1.94,1],[2,1.93,6.15]],"ltp":2.44,"tv":0.86,"id":72963954}]}]}
{"op":"mcm","clk":"11935416372","pt":1724342239650,"mc":[{"id":"1.232135506","rc":[{"batl":[[0,1.98,27.47],[1,2,4.34],[2,2.02,35.44]],"ltp":1.69,"tv":470.6,"id":47674067},{"batb":[[0,1.96,10],[1,1.95,4],[2,1.94,1]],"ltp":2.44,"tv":0.86,"id":72963954}]}]}
{"op":"mcm","clk":"11935416415","pt":1724342240165,"mc":[{"id":"1.232135506","rc":[{"batb":[[0,1.65,7.63],[1,1.64,10],[2,1.63,32.75]],"ltp":1.69,"tv":470.6,"id":47674067}]}]}
{"op":"mcm","clk":"11935416507","pt":1724342240945,"mc":[{"id":"1.232135506","rc":[{"batl":[[1,2.02,35.44],[2,2.96,10]],"ltp":1.69,"tv":470.6,"id":47674067},{"batb":[[1,1.94,1],[2,1.93,6.15]],"ltp":2.44,"tv":0.86,"id":72963954}]}]}
{"op":"mcm","clk":"11935416666","pt":1724342242355,"mc":[{"id":"1.232135506","rc":[{"batb":[[0,1.66,7.63],[1,1.65,7.63]],"ltp":1.69,"tv":470.6,"id":47674067},{"batb":[[0,1.94,1],[1,1.93,6.15],[2,1.9,5.69]],"ltp":2.44,"tv":0.86,"id":72963954}]}]}
{"op":"mcm","clk":"11935416782","pt":1724342243638,"mc":[{"id":"1.232135506","rc":[{"batb":[[0,1.68,7.63],[1,1.67,7.63],[2,1.66,7.63]],"ltp":1.69,"tv":470.6,"id":47674067},{"batb":[[0,1.95,4],[1,1.94,1],[2,1.93,6.15]],"ltp":2.44,"tv":0.86,"id":72963954}]}]}
{"op":"mcm","clk":"11935416973","pt":1724342245457,"mc":[{"id":"1.232135506","rc":[{"batb":[[0,1.94,1],[1,1.93,6.15],[2,1.9,5.69]],"ltp":2.44,"tv":0.86,"id":72963954}]}]}
{"op":"mcm","clk":"11935418108","pt":1724342256654,"mc":[{"id":"1.232135506","rc":[{"batl":[[0,1.97,4.41],[1,1.98,27.47],[2,2.02,35.44]],"ltp":1.69,"tv":470.6,"id":47674067},{"batb":[[0,1.96,10],[1,1.95,4],[2,1.94,1]],"ltp":2.44,"tv":0.86,"id":72963954}]}]}
{"op":"mcm","clk":"11935418374","pt":1724342258887,"mc":[{"id":"1.232135506","rc":[{"batb":[[1,1.94,1],[2,1.93,6.15]],"ltp":2.44,"tv":0.86,"id":72963954}]}]}
{"op":"mcm","clk":"11935418479","pt":1724342259977,"mc":[{"id":"1.232135506","rc":[{"batb":[[0,1.94,1],[1,1.93,6.15],[2,1.9,5.69]],"ltp":2.44,"tv":0.86,"id":72963954}]}]}
{"op":"mcm","clk":"11935418755","pt":1724342262566,"mc":[{"id":"1.232135506","rc":[{"batb":[[0,1.95,4],[1,1.94,1],[2,1.93,6.15]],"ltp":2.44,"tv":0.86,"id":72963954}]}]}
{"op":"mcm","clk":"11935418892","pt":1724342263660,"mc":[{"id":"1.232135506","rc":[{"batl":[[1,2.02,35.44],[2,2.96,10]],"ltp":1.69,"tv":470.6,"id":47674067},{"batb":[[0,1.96,10],[1,1.95,4],[2,1.94,1]],"ltp":2.44,"tv":0.86,"id":72963954}]}]}
{"op":"mcm","clk":"11935418941","pt":1724342264075,"mc":[{"id":"1.232135506","rc":[{"batl":[[0,1.96,27.47]],"ltp":1.69,"tv":470.6,"id":47674067}]}]}
{"op":"mcm","clk":"11935419078","pt":1724342265162,"mc":[{"id":"1.232135506","rc":[{"batb":[[1,1.94,1],[2,1.93,6.15]],"ltp":2.44,"tv":0.86,"id":72963954}]}]}
{"op":"mcm","clk":"11935419184","pt":1724342266195,"mc":[{"id":"1.232135506","rc":[{"batb":[[0,1.94,1],[1,1.93,6.15],[2,1.9,5.69]],"ltp":2.44,"tv":0.86,"id":72963954}]}]}
{"op":"mcm","clk":"11935419541","pt":1724342269259,"mc":[{"id":"1.232135506","rc":[{"batb":[[0,1.96,10],[1,1.95,4],[2,1.94,1]],"ltp":2.44,"tv":0.86,"id":72963954}]}]}
{"op":"mcm","clk":"11935419774","pt":1724342271696,"mc":[{"id":"1.232135506","rc":[{"batb":[[1,1.94,1],[2,1.93,6.15]],"ltp":2.44,"tv":0.86,"id":72963954}]}]}
{"op":"mcm","clk":"11935419921","pt":1724342272965,"mc":[{"id":"1.232135506","rc":[{"batb":[[0,1.94,1],[1,1.93,6.15],[2,1.9,5.69]],"ltp":2.44,"tv":0.86,"id":72963954}]}]}
{"op":"mcm","clk":"11935420350","pt":1724342277214,"mc":[{"id":"1.232135506","rc":[{"batb":[[0,1.96,10],[1,1.95,4],[2,1.94,1]],"ltp":2.44,"tv":0.86,"id":72963954}]}]}
{"op":"mcm","clk":"11935420571","pt":1724342279390,"mc":[{"id":"1.232135506","rc":[{"batb":[[1,1.94,1],[2,1.93,6.15]],"ltp":2.44,"tv":0.86,"id":72963954}]}]}
{"op":"mcm","clk":"11935420688","pt":1724342280493,"mc":[{"id":"1.232135506","rc":[{"batb":[[0,1.94,1],[1,1.93,6.15],[2,1.9,5.69]],"ltp":2.44,"tv":0.86,"id":72963954}]}]}
{"op":"mcm","clk":"11935420913","pt":1724342282581,"mc":[{"id":"1.232135506","rc":[{"batb":[[0,1.95,4],[1,1.94,1],[2,1.93,6.15]],"ltp":2.44,"tv":0.86,"id":72963954}]}]}
{"op":"mcm","clk":"11935420947","pt":1724342282894,"mc":[{"id":"1.232135506","rc":[{"batb":[[0,1.96,10],[1,1.95,4],[2,1.94,1]],"ltp":2.44,"tv":0.86,"id":72963954}]}]}
{"op":"mcm","clk":"11935421202","pt":1724342284923,"mc":[{"id":"1.232135506","rc":[{"batb":[[1,1.94,1],[2,1.93,6.15]],"ltp":2.44,"tv":0.86,"id":72963954}]}]}
{"op":"mcm","clk":"11935421379","pt":1724342286384,"mc":[{"id":"1.232135506","rc":[{"batb":[[0,1.94,1],[1,1.93,6.15],[2,1.9,5.69]],"ltp":2.44,"tv":0.86,"id":72963954}]}]}
{"op":"mcm","clk":"11935421731","pt":1724342289505,"mc":[{"id":"1.232135506","rc":[{"batb":[[0,1.96,10],[1,1.95,4],[2,1.94,1]],"ltp":2.44,"tv":0.86,"id":72963954}]}]}
{"op":"mcm","clk":"11935421800","pt":1724342290023,"mc":[{"id":"1.232135506","rc":[{"batl":[[0,1.95,4.46],[1,1.96,27.47],[2,2.02,35.44]],"ltp":1.69,"tv":470.6,"id":47674067}]}]}
{"op":"mcm","clk":"11935421983","pt":1724342291530,"mc":[{"id":"1.232135506","rc":[{"batb":[[1,1.94,1],[2,1.93,6.15]],"ltp":2.44,"tv":0.86,"id":72963954}]}]}
{"op":"mcm","clk":"11935422130","pt":1724342292879,"mc":[{"id":"1.232135506","rc":[{"batb":[[0,1.94,1],[1,1.93,6.15],[2,1.9,5.69]],"ltp":2.44,"tv":0.86,"id":72963954}]}]}
{"op":"mcm","clk":"11935422320","pt":1724342294589,"mc":[{"id":"1.232135506","rc":[{"batb":[[0,1.95,4],[1,1.94,1],[2,1.93,6.15]],"ltp":2.44,"tv":0.86,"id":72963954}]}]}
{"op":"mcm","clk":"11935422464","pt":1724342295908,"mc":[{"id":"1.232135506","rc":[{"batb":[[0,1.96,10],[1,1.95,4],[2,1.94,1]],"ltp":2.44,"tv":0.86,"id":72963954}]}]}
{"op":"mcm","clk":"11935422578","pt":1724342296898,"mc":[{"id":"1.232135506","rc":[{"batb":[[1,1.94,1],[2,1.93,6.15]],"ltp":2.44,"tv":0.86,"id":72963954}]}]}
{"op":"mcm","clk":"11935422857","pt":1724342299391,"mc":[{"id":"1.232135506","rc":[{"batb":[[0,1.95,4]],"ltp":2.44,"tv":0.86,"id":72963954}]}]}
{"op":"mcm","clk":"11935423088","pt":1724342301620,"mc":[{"id":"1.232135506","rc":[{"batb":[[0,1.94,1],[1,1.93,6.15],[2,1.9,5.69]],"ltp":2.44,"tv":0.86,"id":72963954}]}]}
{"op":"mcm","clk":"11935423252","pt":1724342302917,"mc":[{"id":"1.232135506","rc":[{"batl":[[0,1.94,27.47],[1,1.95,4.45]],"ltp":1.69,"tv":470.6,"id":47674067}]}]}
{"op":"mcm","clk":"11935423500","pt":1724342305103,"mc":[{"id":"1.232135506","rc":[{"batl":[[1,2.02,35.44],[2,2.96,10]],"ltp":1.69,"tv":470.6,"id":47674067},{"batb":[[0,1.96,10],[1,1.95,4],[2,1.94,1]],"ltp":2.44,"tv":0.86,"id":72963954}]}]}
{"op":"mcm","clk":"11935423787","pt":1724342307496,"mc":[{"id":"1.232135506","rc":[{"batb":[[1,1.94,1],[2,1.93,6.15]],"ltp":2.44,"tv":0.86,"id":72963954}]}]}
{"op":"mcm","clk":"11935423899","pt":1724342308533,"mc":[{"id":"1.232135506","rc":[{"batb":[[0,1.94,1],[1,1.93,6.15],[2,1.9,5.69]],"ltp":2.44,"tv":0.86,"id":72963954}]}]}
{"op":"mcm","clk":"11935424313","pt":1724342312413,"mc":[{"id":"1.232135506","rc":[{"batb":[[0,1.95,4],[1,1.94,1],[2,1.93,6.15]],"ltp":2.44,"tv":0.86,"id":72963954}]}]}
{"op":"mcm","clk":"11935424370","pt":1724342312825,"mc":[{"id":"1.232135506","rc":[{"batb":[[0,1.96,10],[1,1.95,4],[2,1.94,1]],"ltp":2.44,"tv":0.86,"id":72963954}]}]}
{"op":"mcm","clk":"11935424642","pt":1724342314910,"mc":[{"id":"1.232135506","rc":[{"batb":[[1,1.94,1],[2,1.93,6.15]],"ltp":2.44,"tv":0.86,"id":72963954}]}]}
{"op":"mcm","clk":"11935424772","pt":1724342316168,"mc":[{"id":"1.232135506","rc":[{"batb":[[0,1.94,1],[1,1.93,6.15],[2,1.9,5.69]],"ltp":2.44,"tv":0.86,"id":72963954}]}]}
{"op":"mcm","clk":"11935424910","pt":1724342317357,"mc":[{"id":"1.232135506","rc":[{"batb":[[0,1.95,4],[1,1.94,1],[2,1.93,6.15]],"ltp":2.44,"tv":0.86,"id":72963954}]}]}
{"op":"mcm","clk":"11935425171","pt":1724342319549,"mc":[{"id":"1.232135506","rc":[{"batb":[[0,1.94,1],[1,1.93,6.15],[2,1.9,5.69]],"ltp":2.44,"tv":0.86,"id":72963954}]}]}
{"op":"mcm","clk":"11935425281","pt":1724342320430,"mc":[{"id":"1.232135506","rc":[{"batl":[[0,1.93,4.5],[1,1.94,27.47],[2,2.02,35.44]],"ltp":1.69,"tv":470.6,"id":47674067}]}]}
{"op":"mcm","clk":"11935426067","pt":1724342327039,"mc":[{"id":"1.232135506","rc":[{"batl":[[0,1.92,27.47],[1,1.93,4.5]],"ltp":1.69,"tv":470.6,"id":47674067},{"batb":[[0,1.96,10],[1,1.95,4],[2,1.94,1]],"ltp":2.44,"tv":0.86,"id":72963954}]}]}
{"op":"mcm","clk":"11935426245","pt":1724342328454,"mc":[{"id":"1.232135506","rc":[{"batl":[[1,2.02,35.44],[2,2.96,10]],"ltp":1.69,"tv":470.6,"id":47674067}]}]}
{"op":"mcm","clk":"11935426347","pt":1724342329363,"mc":[{"id":"1.232135506","rc":[{"batb":[[1,1.94,1],[2,1.93,6.15]],"ltp":2.44,"tv":0.86,"id":72963954}]}]}
{"op":"mcm","clk":"11935426486","pt":1724342330446,"mc":[{"id":"1.232135506","rc":[{"batb":[[0,1.94,1],[1,1.93,6.15],[2,1.9,5.69]],"ltp":2.44,"tv":0.86,"id":72963954}]}]}
{"op":"mcm","clk":"11935427292","pt":1724342337640,"mc":[{"id":"1.232135506","rc":[{"batb":[[0,1.96,10],[1,1.95,4],[2,1.94,1]],"ltp":2.44,"tv":0.86,"id":72963954}]}]}
{"op":"mcm","clk":"11935427516","pt":1724342339990,"mc":[{"id":"1.232135506","rc":[{"batb":[[1,1.94,1],[2,1.93,6.15]],"ltp":2.44,"tv":0.86,"id":72963954}]}]}
{"op":"mcm","clk":"11935427616","pt":1724342340936,"mc":[{"id":"1.232135506","rc":[{"batb":[[0,1.94,1],[1,1.93,6.15],[2,1.9,5.69]],"ltp":2.44,"tv":0.86,"id":72963954}]}]}
{"op":"mcm","clk":"11935427926","pt":1724342343367,"mc":[{"id":"1.232135506","rc":[{"batb":[[0,1.96,10],[1,1.95,4],[2,1.94,1]],"ltp":2.44,"tv":0.86,"id":72963954}]}]}
{"op":"mcm","clk":"11935428207","pt":1724342345552,"mc":[{"id":"1.232135506","rc":[{"batb":[[1,1.94,1],[2,1.93,6.15]],"ltp":2.44,"tv":0.86,"id":72963954}]}]}
{"op":"mcm","clk":"11935428338","pt":1724342346753,"mc":[{"id":"1.232135506","rc":[{"batb":[[0,1.94,1],[1,1.93,6.15],[2,1.9,5.69]],"ltp":2.44,"tv":0.86,"id":72963954}]}]}
{"op":"mcm","clk":"11935429006","pt":1724342352297,"mc":[{"id":"1.232135506","rc":[{"batl":[[0,1.91,4.55],[1,1.92,27.47],[2,2.02,35.44]],"ltp":1.69,"tv":470.6,"id":47674067},{"batb":[[0,1.96,10],[1,1.95,4],[2,1.94,1]],"ltp":2.44,"tv":0.86,"id":72963954}]}]}
{"op":"mcm","clk":"11935429251","pt":1724342354066,"mc":[{"id":"1.232135506","rc":[{"batb":[[1,1.94,1],[2,1.93,6.15]],"ltp":2.44,"tv":0.86,"id":72963954}]}]}
{"op":"mcm","clk":"11935429409","pt":1724342355373,"mc":[{"id":"1.232135506","rc":[{"batb":[[0,1.94,1],[1,1.93,6.15],[2,1.9,5.69]],"ltp":2.44,"tv":0.86,"id":72963954}]}]}
{"op":"mcm","clk":"11935429529","pt":1724342356573,"mc":[{"id":"1.232135506","rc":[{"batb":[[0,1.95,4],[1,1.94,1],[2,1.93,6.15]],"ltp":2.44,"tv":0.86,"id":72963954}]}]}
{"op":"mcm","clk":"11935429675","pt":1724342357776,"mc":[{"id":"1.232135506","rc":[{"batb":[[0,1.96,10],[1,1.95,4],[2,1.94,1]],"ltp":2.44,"tv":0.86,"id":72963954}]}]}
{"op":"mcm","clk":"11935429819","pt":1724342358871,"mc":[{"id":"1.232135506","rc":[{"batb":[[1,1.94,1],[2,1.93,6.15]],"ltp":2.44,"tv":0.86,"id":72963954}]}]}
{"op":"mcm","clk":"11935430117","pt":1724342361385,"mc":[{"id":"1.232135506","rc":[{"batb":[[0,1.95,4]],"ltp":2.44,"tv":0.86,"id":72963954}]}]}
{"op":"mcm","clk":"11935430414","pt":1724342363906,"mc":[{"id":"1.232135506","rc":[{"batb":[[0,1.94,1],[1,1.93,6.15],[2,1.9,5.69]],"ltp":2.44,"tv":0.86,"id":72963954}]}]}
{"op":"mcm","clk":"11935430818","pt":1724342367706,"mc":[{"id":"1.232135506","rc":[{"batb":[[0,1.67,7.63],[1,1.66,7.63],[2,1.65,7.63]],"ltp":1.69,"tv":470.6,"id":47674067},{"batb":[[0,1.96,10],[1,1.95,4],[2,1.94,1]],"ltp":2.44,"tv":0.86,"id":72963954}]}]}
{"op":"mcm","clk":"11935430881","pt":1724342368383,"mc":[{"id":"1.232135506","rc":[{"batb":[[0,1.65,7.63],[1,1.63,8.13],[2,1.62,8.27]],"ltp":1.69,"tv":470.6,"id":47674067}]}]}
{"op":"mcm","clk":"11935431076","pt":1724342370386,"mc":[{"id":"1.232135506","rc":[{"batb":[[0,1.63,8.13],[1,1.62,8.27],[2,1.6,8.54]],"ltp":1.69,"tv":470.6,"id":47674067},{"batb":[[1,1.94,1],[2,1.93,6.15]],"ltp":2.44,"tv":0.86,"id":72963954}]}]}
{"op":"mcm","clk":"11935431134","pt":1724342371013,"mc":[{"id":"1.232135506","rc":[{"batb":[[0,1.94,1],[1,1.93,6.15],[2,1.9,5.69]],"ltp":2.44,"tv":0.86,"id":72963954}]}]}
{"op":"mcm","clk":"11935431435","pt":1724342374511,"mc":[{"id":"1.232135506","rc":[{"batb":[[0,1.65,7.63],[1,1.64,7.63],[2,1.63,8.13]],"ltp":1.69,"tv":470.6,"id":47674067},{"batb":[[0,1.96,10],[1,1.95,4],[2,1.94,1]],"ltp":2.44,"tv":0.86,"id":72963954}]}]}
{"op":"mcm","clk":"11935431557","pt":1724342375710,"mc":[{"id":"1.232135506","rc":[{"batb":[[0,1.68,7.63],[1,1.67,7.63],[2,1.65,7.63]],"ltp":1.69,"tv":470.6,"id":47674067}]}]}
{"op":"mcm","clk":"11935431637","pt":1724342376596,"mc":[{"id":"1.232135506","rc":[{"batb":[[1,1.94,1],[2,1.93,6.15]],"ltp":2.44,"tv":0.86,"id":72963954}]}]}
{"op":"mcm","clk":"11935431751","pt":1724342377688,"mc":[{"id":"1.232135506","rc":[{"batb":[[0,1.94,1],[1,1.93,6.15],[2,1.9,5.69]],"ltp":2.44,"tv":0.86,"id":72963954}]}]}
{"op":"mcm","clk":"11935431997","pt":1724342380239,"mc":[{"id":"1.232135506","rc":[{"batb":[[2,1.66,7.63]],"ltp":1.69,"tv":470.6,"id":47674067},{"batb":[[0,1.96,10],[1,1.95,4],[2,1.94,1]],"ltp":2.44,"tv":0.86,"id":72963954}]}]}
{"op":"mcm","clk":"11935432186","pt":1724342382222,"mc":[{"id":"1.232135506","rc":[{"batb":[[1,1.94,1],[2,1.93,6.15]],"ltp":2.44,"tv":0.86,"id":72963954}]}]}
{"op":"mcm","clk":"11935432326","pt":1724342383536,"mc":[{"id":"1.232135506","rc":[{"batb":[[0,1.94,1],[1,1.93,6.15],[2,1.9,5.69]],"ltp":2.44,"tv":0.86,"id":72963954}]}]}
{"op":"mcm","clk":"11935432505","pt":1724342385204,"mc":[{"id":"1.232135506","rc":[{"batb":[[0,1.95,4],[1,1.94,1],[2,1.93,6.15]],"ltp":2.44,"tv":0.86,"id":72963954}]}]}
{"op":"mcm","clk":"11935432766","pt":1724342387697,"mc":[{"id":"1.232135506","rc":[{"batb":[[0,1.94,1],[1,1.93,6.15],[2,1.9,5.69]],"ltp":2.44,"tv":0.86,"id":72963954}]}]}
{"op":"mcm","clk":"11935433496","pt":1724342395102,"mc":[{"id":"1.232135506","rc":[{"batb":[[0,1.96,10],[1,1.95,4],[2,1.94,1]],"ltp":2.44,"tv":0.86,"id":72963954}]}]}
{"op":"mcm","clk":"11935433684","pt":1724342397132,"mc":[{"id":"1.232135506","rc":[{"batb":[[1,1.94,1],[2,1.93,6.15]],"ltp":2.44,"tv":0.86,"id":72963954}]}]}
{"op":"mcm","clk":"11935433842","pt":1724342398600,"mc":[{"id":"1.232135506","rc":[{"batb":[[0,1.94,1],[1,1.93,6.15],[2,1.9,5.69]],"ltp":2.44,"tv":0.86,"id":72963954}]}]}
{"op":"mcm","clk":"11935434494","pt":1724342403433,"mc":[{"id":"1.232135506","rc":[{"trd":[[1.61,87.92],[1.69,227.96],[1.7,37.15],[1.71,3.43],[1.72,21.51],[1.88,11.5],[1.89,8],[1.98,71.43]],"batb":[[0,1.68,7.64],[1,1.67,7.64],[2,1.66,7.64]],"batl":[[0,1.91,4.56],[1,1.92,27.49],[2,2.02,35.47]],"ltp":1.69,"tv":470.91,"id":47674067},{"batb":[[0,1.96,10],[1,1.95,4],[2,1.94,1]],"batl":[[0,2.94,4.1],[1,2.98,4.1]],"ltp":2.44,"tv":0.86,"id":72963954}],"tv":471.77}]}
{"op":"mcm","clk":"11935434749","pt":1724342405435,"mc":[{"id":"1.232135506","rc":[{"batb":[[1,1.94,1],[2,1.93,6.15]],"ltp":2.44,"tv":0.86,"id":72963954}]}]}
{"op":"mcm","clk":"11935434894","pt":1724342407080,"mc":[{"id":"1.232135506","rc":[{"batb":[[0,1.94,1],[1,1.93,6.15],[2,1.9,5.69]],"ltp":2.44,"tv":0.86,"id":72963954}]}]}
{"op":"mcm","clk":"11935435094","pt":1724342408916,"mc":[{"id":"1.232135506","rc":[{"batb":[[0,1.95,4],[1,1.94,1],[2,1.93,6.15]],"ltp":2.44,"tv":0.86,"id":72963954}]}]}
{"op":"mcm","clk":"11935435368","pt":1724342411232,"mc":[{"id":"1.232135506","rc":[{"batb":[[0,1.94,1],[1,1.93,6.15],[2,1.9,5.69]],"ltp":2.44,"tv":0.86,"id":72963954}]}]}
{"op":"mcm","clk":"11935435605","pt":1724342413643,"mc":[{"id":"1.232135506","rc":[{"batb":[[0,1.95,4],[1,1.94,1],[2,1.93,6.15]],"ltp":2.44,"tv":0.86,"id":72963954}]}]}
{"op":"mcm","clk":"11935435640","pt":1724342413956,"mc":[{"id":"1.232135506","rc":[{"batb":[[0,1.96,10],[1,1.95,4],[2,1.94,1]],"ltp":2.44,"tv":0.86,"id":72963954}]}]}
{"op":"mcm","clk":"11935435878","pt":1724342416053,"mc":[{"id":"1.232135506","rc":[{"batb":[[1,1.94,1],[2,1.93,6.15]],"ltp":2.44,"tv":0.86,"id":72963954}]}]}
{"op":"mcm","clk":"11935436004","pt":1724342417370,"mc":[{"id":"1.232135506","rc":[{"batb":[[0,1.94,1],[1,1.93,6.15],[2,1.9,5.69]],"ltp":2.44,"tv":0.86,"id":72963954}]}]}
{"op":"mcm","clk":"11935436921","pt":1724342425430,"mc":[{"id":"1.232135506","rc":[{"batb":[[0,1.95,4],[1,1.94,1],[2,1.93,6.15]],"ltp":2.44,"tv":0.86,"id":72963954}]}]}
{"op":"mcm","clk":"11935437005","pt":1724342426049,"mc":[{"id":"1.232135506","rc":[{"batb":[[0,1.96,10],[1,1.95,4],[2,1.94,1]],"ltp":2.44,"tv":0.86,"id":72963954}]}]}
{"op":"mcm","clk":"11935437215","pt":1724342427981,"mc":[{"id":"1.232135506","rc":[{"batb":[[1,1.94,1],[2,1.93,6.15]],"ltp":2.44,"tv":0.86,"id":72963954}]}]}
{"op":"mcm","clk":"11935437399","pt":1724342429490,"mc":[{"id":"1.232135506","rc":[{"batb":[[0,1.94,1],[1,1.93,6.15],[2,1.9,5.69]],"ltp":2.44,"tv":0.86,"id":72963954}]}]}
{"op":"mcm","clk":"11935437815","pt":1724342433249,"mc":[{"id":"1.232135506","rc":[{"batb":[[0,1.96,10],[1,1.95,4],[2,1.94,1]],"ltp":2.44,"tv":0.86,"id":72963954}]}]}
{"op":"mcm","clk":"11935438036","pt":1724342435490,"mc":[{"id":"1.232135506","rc":[{"batb":[[1,1.94,1],[2,1.93,6.15]],"ltp":2.44,"tv":0.86,"id":72963954}]}]}
{"op":"mcm","clk":"11935438151","pt":1724342436484,"mc":[{"id":"1.232135506","rc":[{"batb":[[0,1.94,1],[1,1.93,6.15],[2,1.9,5.69]],"ltp":2.44,"tv":0.86,"id":72963954}]}]}
{"op":"mcm","clk":"11935438308","pt":1724342437998,"mc":[{"id":"1.232135506","rc":[{"batb":[[0,1.95,4],[1,1.94,1],[2,1.93,6.15]],"ltp":2.44,"tv":0.86,"id":72963954}]}]}
{"op":"mcm","clk":"11935438448","pt":1724342439220,"mc":[{"id":"1.232135506","rc":[{"batb":[[0,1.96,10],[1,1.95,4],[2,1.94,1]],"ltp":2.44,"tv":0.86,"id":72963954}]}]}
{"op":"mcm","clk":"11935438581","pt":1724342440361,"mc":[{"id":"1.232135506","rc":[{"batb":[[1,1.94,1],[2,1.93,6.15]],"ltp":2.44,"tv":0.86,"id":72963954}]}]}
{"op":"mcm","clk":"11935438852","pt":1724342442665,"mc":[{"id":"1.232135506","rc":[{"batb":[[0,1.95,4]],"ltp":2.44,"tv":0.86,"id":72963954}]}]}
{"op":"mcm","clk":"11935439117","pt":1724342445082,"mc":[{"id":"1.232135506","rc":[{"batb":[[0,1.94,1],[1,1.93,6.15],[2,1.9,5.69]],"ltp":2.44,"tv":0.86,"id":72963954}]}]}
{"op":"mcm","clk":"11935440211","pt":1724342454105,"mc":[{"id":"1.232135506","rc":[{"batl":[[0,1.9,27.5],[1,1.91,4.55]],"ltp":1.69,"tv":470.91,"id":47674067},{"batb":[[0,1.96,10],[1,1.95,4],[2,1.94,1]],"ltp":2.44,"tv":0.86,"id":72963954}]}]}
{"op":"mcm","clk":"11935440319","pt":1724342454992,"mc":[{"id":"1.232135506","rc":[{"batl":[[0,1.89,4.6],[1,1.9,27.49]],"ltp":1.69,"tv":470.91,"id":47674067}]}]}
{"op":"mcm","clk":"11935440441","pt":1724342456304,"mc":[{"id":"1.232135506","rc":[{"batb":[[1,1.94,1],[2,1.93,6.15]],"ltp":2.44,"tv":0.86,"id":72963954}]}]}
{"op":"mcm","clk":"11935440543","pt":1724342457290,"mc":[{"id":"1.232135506","rc":[{"batb":[[0,1.94,1],[1,1.93,6.15],[2,1.9,5.69]],"ltp":2.44,"tv":0.86,"id":72963954}]}]}
{"op":"mcm","clk":"11935441160","pt":1724342462384,"mc":[{"id":"1.232135506","rc":[{"batl":[[0,1.88,27.5],[1,1.89,4.59]],"ltp":1.69,"tv":470.91,"id":47674067},{"batb":[[0,1.96,10],[1,1.95,4],[2,1.94,1]],"ltp":2.44,"tv":0.86,"id":72963954}]}]}
{"op":"mcm","clk":"11935441217","pt":1724342462918,"mc":[{"id":"1.232135506","rc":[{"batl":[[1,2.02,35.47],[2,2.96,10]],"ltp":1.69,"tv":470.91,"id":47674067}]}]}
{"op":"mcm","clk":"11935441431","pt":1724342464600,"mc":[{"id":"1.232135506","rc":[{"batb":[[1,1.94,1],[2,1.93,6.15]],"ltp":2.44,"tv":0.86,"id":72963954}]}]}
{"op":"mcm","clk":"11935441542","pt":1724342465694,"mc":[{"id":"1.232135506","rc":[{"batb":[[0,1.94,1],[1,1.93,6.15],[2,1.9,5.69]],"ltp":2.44,"tv":0.86,"id":72963954}]}]}
{"op":"mcm","clk":"11935441669","pt":1724342466890,"mc":[{"id":"1.232135506","rc":[{"batb":[[0,1.95,4],[1,1.94,1],[2,1.93,6.15]],"ltp":2.44,"tv":0.86,"id":72963954}]}]}
{"op":"mcm","clk":"11935441940","pt":1724342469412,"mc":[{"id":"1.232135506","rc":[{"batb":[[0,1.96,10]],"ltp":2.44,"tv":0.86,"id":72963954}]}]}
{"op":"mcm","clk":"11935442373","pt":1724342472698,"mc":[{"id":"1.232135506","rc":[{"batb":[[0,1.95,4]],"ltp":2.44,"tv":0.86,"id":72963954}]}]}
{"op":"mcm","clk":"11935442632","pt":1724342475116,"mc":[{"id":"1.232135506","rc":[{"batb":[[0,1.94,1],[1,1.93,6.15],[2,1.9,5.69]],"ltp":2.44,"tv":0.86,"id":72963954}]}]}
{"op":"mcm","clk":"11935442730","pt":1724342476001,"mc":[{"id":"1.232135506","rc":[{"batl":[[0,1.87,4.65],[1,1.88,27.49],[2,2.02,35.47]],"ltp":1.69,"tv":470.91,"id":47674067}]}]}
{"op":"mcm","clk":"11935446172","pt":1724342506725,"mc":[{"id":"1.232135506","rc":[{"batl":[[1,2.02,35.47],[2,2.96,10]],"ltp":1.69,"tv":470.91,"id":47674067}]}]}
{"op":"mcm","clk":"11935446199","pt":1724342507044,"mc":[{"id":"1.232135506","rc":[{"batl":[[0,1.86,27.65],[1,1.87,4.64],[2,2.02,35.47]],"ltp":1.69,"tv":470.91,"id":47674067},{"batb":[[0,1.96,10],[1,1.95,4],[2,1.94,1]],"ltp":2.44,"tv":0.86,"id":72963954}]}]}
{"op":"mcm","clk":"11935446454","pt":1724342509366,"mc":[{"id":"1.232135506","rc":[{"batl":[[0,1.85,4.7],[1,1.86,27.64]],"ltp":1.69,"tv":470.91,"id":47674067},{"batb":[[1,1.94,1],[2,1.93,6.15]],"ltp":2.44,"tv":0.86,"id":72963954}]}]}
{"op":"mcm","clk":"11935446580","pt":1724342510362,"mc":[{"id":"1.232135506","rc":[{"batb":[[0,1.94,1],[1,1.93,6.15],[2,1.9,5.69]],"ltp":2.44,"tv":0.86,"id":72963954}]}]}
{"op":"mcm","clk":"11935447463","pt":1724342517746,"mc":[{"id":"1.232135506","rc":[{"batl":[[1,2.02,35.47],[2,2.96,10]],"ltp":1.69,"tv":470.91,"id":47674067}]}]}
{"op":"mcm","clk":"11935447529","pt":1724342518271,"mc":[{"id":"1.232135506","rc":[{"batl":[[0,1.84,27.65],[1,1.85,4.69],[2,2.02,35.47]],"ltp":1.69,"tv":470.91,"id":47674067},{"batb":[[0,1.96,10],[1,1.95,4],[2,1.94,1]],"ltp":2.44,"tv":0.86,"id":72963954}]}]}
{"op":"mcm","clk":"11935447740","pt":1724342520149,"mc":[{"id":"1.232135506","rc":[{"batl":[[1,2.02,35.47],[2,2.96,10]],"ltp":1.69,"tv":470.91,"id":47674067},{"batb":[[1,1.94,1],[2,1.93,6.15]],"ltp":2.44,"tv":0.86,"id":72963954}]}]}
{"op":"mcm","clk":"11935447911","pt":1724342521477,"mc":[{"id":"1.232135506","rc":[{"batb":[[0,1.94,1],[1,1.93,6.15],[2,1.9,5.69]],"ltp":2.44,"tv":0.86,"id":72963954}]}]}
{"op":"mcm","clk":"11935449764","pt":1724342536380,"mc":[{"id":"1.232135506","rc":[{"batl":[[0,1.83,4.75],[1,1.84,27.64],[2,2.02,35.47]],"ltp":1.69,"tv":470.91,"id":47674067},{"batb":[[0,1.96,10],[1,1.95,4],[2,1.94,1]],"ltp":2.44,"tv":0.86,"id":72963954}]}]}
{"op":"mcm","clk":"11935449967","pt":1724342538316,"mc":[{"id":"1.232135506","rc":[{"batb":[[1,1.94,1],[2,1.93,6.15]],"ltp":2.44,"tv":0.86,"id":72963954}]}]}
{"op":"mcm","clk":"11935450135","pt":1724342539779,"mc":[{"id":"1.232135506","rc":[{"batb":[[0,1.94,1],[1,1.93,6.15],[2,1.9,5.69]],"ltp":2.44,"tv":0.86,"id":72963954}]}]}
{"op":"mcm","clk":"11935451060","pt":1724342547112,"mc":[{"id":"1.232135506","rc":[{"batl":[[1,1.9,27.64]],"ltp":1.69,"tv":470.91,"id":47674067},{"batb":[[0,1.96,10],[1,1.95,4],[2,1.94,1]],"ltp":2.44,"tv":0.86,"id":72963954}]}]}
{"op":"mcm","clk":"11935451311","pt":1724342549216,"mc":[{"id":"1.232135506","rc":[{"batl":[[0,1.9,27.65],[1,2.02,35.47],[2,2.96,10]],"ltp":1.69,"tv":470.91,"id":47674067},{"batb":[[1,1.94,1],[2,1.93,6.15]],"ltp":2.44,"tv":0.86,"id":72963954}]}]}
{"op":"mcm","clk":"11935451425","pt":1724342550419,"mc":[{"id":"1.232135506","rc":[{"batb":[[0,1.94,1],[1,1.93,6.15],[2,1.9,5.69]],"ltp":2.44,"tv":0.86,"id":72963954}]}]}
{"op":"mcm","clk":"11935452289","pt":1724342557693,"mc":[{"id":"1.232135506","rc":[{"batb":[[0,1.95,4],[1,1.94,1],[2,1.93,6.15]],"ltp":2.44,"tv":0.86,"id":72963954}]}]}
{"op":"mcm","clk":"11935452319","pt":1724342557901,"mc":[{"id":"1.232135506","rc":[{"batb":[[0,1.96,10],[1,1.95,4],[2,1.94,1]],"ltp":2.44,"tv":0.86,"id":72963954}]}]}
{"op":"mcm","clk":"11935452553","pt":1724342560014,"mc":[{"id":"1.232135506","rc":[{"batb":[[1,1.94,1],[2,1.93,6.15]],"ltp":2.44,"tv":0.86,"id":72963954}]}]}
{"op":"mcm","clk":"11935452692","pt":1724342561222,"mc":[{"id":"1.232135506","rc":[{"batb":[[0,1.94,1],[1,1.93,6.15],[2,1.9,5.69]],"ltp":2.44,"tv":0.86,"id":72963954}]}]}
{"op":"mcm","clk":"11935452791","pt":1724342562001,"mc":[{"id":"1.232135506","rc":[{"trd":[[1.69,227.98]],"batb":[[0,1.69,9.99],[1,1.68,7.64],[2,1.67,7.64]],"batl":[[0,1.95,27.64]],"ltp":1.69,"tv":470.93,"id":47674067}],"tv":471.79}]}
{"op":"mcm","clk":"11935452960","pt":1724342563729,"mc":[{"id":"1.232135506","rc":[{"batl":[[0,1.94,4.59],[1,1.95,27.64],[2,2.02,35.47]],"ltp":1.69,"tv":470.93,"id":47674067},{"batb":[[0,1.95,4],[1,1.94,1],[2,1.93,6.15]],"ltp":2.44,"tv":0.86,"id":72963954}]}]}
{"op":"mcm","clk":"11935452976","pt":1724342563834,"mc":[{"id":"1.232135506","rc":[{"batb":[[0,1.96,10],[1,1.95,4],[2,1.94,1]],"ltp":2.44,"tv":0.86,"id":72963954}]}]}
{"op":"mcm","clk":"11935453136","pt":1724342565341,"mc":[{"id":"1.232135506","rc":[{"batb":[[0,1.68,7.64],[1,1.67,7.64],[2,1.66,7.64]],"ltp":1.69,"tv":470.93,"id":47674067},{"batb":[[1,1.94,1],[2,1.93,6.15]],"ltp":2.44,"tv":0.86,"id":72963954}]}]}
{"op":"mcm","clk":"11935453327","pt":1724342567227,"mc":[{"id":"1.232135506","rc":[{"batb":[[0,1.94,1],[1,1.93,6.15],[2,1.9,5.69]],"ltp":2.44,"tv":0.86,"id":72963954}]}]}
{"op":"mcm","clk":"11935453511","pt":1724342568746,"mc":[{"id":"1.232135506","rc":[{"batl":[[1,2.02,35.47],[2,2.96,10]],"ltp":1.69,"tv":470.93,"id":47674067}]}]}
{"op":"mcm","clk":"11935453556","pt":1724342569088,"mc":[{"id":"1.232135506","rc":[{"batl":[[0,1.94,32.23]],"ltp":1.69,"tv":470.93,"id":47674067},{"batb":[[0,1.95,4],[1,1.94,1],[2,1.93,6.15]],"ltp":2.44,"tv":0.86,"id":72963954}]}]}
{"op":"mcm","clk":"11935453910","pt":1724342571413,"mc":[{"id":"1.232135506","rc":[{"batb":[[0,1.94,1],[1,1.93,6.15],[2,1.9,5.69]],"ltp":2.44,"tv":0.86,"id":72963954}]}]}
{"op":"mcm","clk":"11935454445","pt":1724342575532,"mc":[{"id":"1.232135506","rc":[{"batb":[[0,1.96,10],[1,1.95,4],[2,1.94,1]],"ltp":2.44,"tv":0.86,"id":72963954}]}]}
{"op":"mcm","clk":"11935454669","pt":1724342577723,"mc":[{"id":"1.232135506","rc":[{"batb":[[1,1.94,1],[2,1.93,6.15]],"batl":[[0,2.94,4.21]],"ltp":2.44,"tv":0.86,"id":72963954}]}]}
{"op":"mcm","clk":"11935454811","pt":1724342578922,"mc":[{"id":"1.232135506","rc":[{"batb":[[0,1.94,1],[1,1.93,6.15],[2,1.9,5.69]],"ltp":2.44,"tv":0.86,"id":72963954}]}]}
{"op":"mcm","clk":"11935455905","pt":1724342587563,"mc":[{"id":"1.232135506","rc":[{"batb":[[0,1.96,10],[1,1.95,4],[2,1.94,1]],"ltp":2.44,"tv":0.86,"id":72963954}]}]}
{"op":"mcm","clk":"11935456149","pt":1724342589547,"mc":[{"id":"1.232135506","rc":[{"batb":[[1,1.94,1],[2,1.93,6.15]],"ltp":2.44,"tv":0.86,"id":72963954}]}]}
{"op":"mcm","clk":"11935456326","pt":1724342590756,"mc":[{"id":"1.232135506","rc":[{"batb":[[0,1.94,1],[1,1.93,6.15],[2,1.9,5.69]],"ltp":2.44,"tv":0.86,"id":72963954}]}]}
{"op":"mcm","clk":"11935457584","pt":1724342600551,"mc":[{"id":"1.232135506","rc":[{"batb":[[0,1.96,10],[1,1.95,4],[2,1.94,1]],"ltp":2.44,"tv":0.86,"id":72963954}]}]}
{"op":"mcm","clk":"11935457850","pt":1724342602789,"mc":[{"id":"1.232135506","rc":[{"batb":[[1,1.94,1],[2,1.93,6.15]],"ltp":2.44,"tv":0.86,"id":72963954}]}]}
{"op":"mcm","clk":"11935458022","pt":1724342604187,"mc":[{"id":"1.232135506","rc":[{"batb":[[0,1.94,1],[1,1.93,6.15],[2,1.9,5.69]],"ltp":2.44,"tv":0.86,"id":72963954}]}]}
{"op":"mcm","clk":"11935458247","pt":1724342605912,"mc":[{"id":"1.232135506","rc":[{"batb":[[0,1.95,4],[1,1.94,1],[2,1.93,6.15]],"ltp":2.44,"tv":0.86,"id":72963954}]}]}
{"op":"mcm","clk":"11935458593","pt":1724342608379,"mc":[{"id":"1.232135506","rc":[{"batb":[[0,1.94,1],[1,1.93,6.15],[2,1.9,5.69]],"ltp":2.44,"tv":0.86,"id":72963954}]}]}
{"op":"mcm","clk":"11935459464","pt":1724342615165,"mc":[{"id":"1.232135506","rc":[{"batb":[[0,1.96,10],[1,1.95,4],[2,1.94,1]],"ltp":2.44,"tv":0.86,"id":72963954}]}]}
{"op":"mcm","clk":"11935459701","pt":1724342617303,"mc":[{"id":"1.232135506","rc":[{"batb":[[1,1.94,1],[2,1.93,6.15]],"ltp":2.44,"tv":0.86,"id":72963954}]}]}
{"op":"mcm","clk":"11935459859","pt":1724342618612,"mc":[{"id":"1.232135506","rc":[{"batb":[[0,1.94,1],[1,1.93,6.15],[2,1.9,5.69]],"ltp":2.44,"tv":0.86,"id":72963954}]}]}
{"op":"mcm","clk":"11935460039","pt":1724342620016,"mc":[{"id":"1.232135506","rc":[{"batb":[[0,1.95,4],[1,1.94,1],[2,1.93,6.15]],"ltp":2.44,"tv":0.86,"id":72963954}]}]}
{"op":"mcm","clk":"11935460339","pt":1724342622736,"mc":[{"id":"1.232135506","rc":[{"batb":[[0,1.94,1],[1,1.93,6.15],[2,1.9,5.69]],"ltp":2.44,"tv":0.86,"id":72963954}]}]}
{"op":"mcm","clk":"11935460907","pt":1724342627468,"mc":[{"id":"1.232135506","rc":[{"batb":[[0,1.95,4],[1,1.94,1],[2,1.93,6.15]],"ltp":2.44,"tv":0.86,"id":72963954}]}]}
{"op":"mcm","clk":"11935460973","pt":1724342627986,"mc":[{"id":"1.232135506","rc":[{"batb":[[0,1.96,10],[1,1.95,4],[2,1.94,1]],"ltp":2.44,"tv":0.86,"id":72963954}]}]}
{"op":"mcm","clk":"11935461178","pt":1724342629979,"mc":[{"id":"1.232135506","rc":[{"batb":[[1,1.94,1],[2,1.93,6.15]],"ltp":2.44,"tv":0.86,"id":72963954}]}]}
{"op":"mcm","clk":"11935461300","pt":1724342631186,"mc":[{"id":"1.232135506","rc":[{"batb":[[0,1.94,1],[1,1.93,6.15],[2,1.9,5.69]],"ltp":2.44,"tv":0.86,"id":72963954}]}]}
{"op":"mcm","clk":"11935461814","pt":1724342635371,"mc":[{"id":"1.232135506","rc":[{"batb":[[0,1.96,10],[1,1.95,4],[2,1.94,1]],"ltp":2.44,"tv":0.86,"id":72963954}]}]}
{"op":"mcm","clk":"11935462088","pt":1724342637796,"mc":[{"id":"1.232135506","rc":[{"batb":[[1,1.94,1],[2,1.93,6.15]],"ltp":2.44,"tv":0.86,"id":72963954}]}]}
{"op":"mcm","clk":"11935462221","pt":1724342638884,"mc":[{"id":"1.232135506","rc":[{"batb":[[0,1.94,1],[1,1.93,6.15],[2,1.9,5.69]],"ltp":2.44,"tv":0.86,"id":72963954}]}]}
{"op":"mcm","clk":"11935463366","pt":1724342648402,"mc":[{"id":"1.232135506","rc":[{"batb":[[0,1.96,10],[1,1.95,4],[2,1.94,1]],"ltp":2.44,"tv":0.86,"id":72963954}]}]}
{"op":"mcm","clk":"11935463606","pt":1724342650513,"mc":[{"id":"1.232135506","rc":[{"batb":[[1,1.94,1],[2,1.93,6.15]],"ltp":2.44,"tv":0.86,"id":72963954}]}]}
{"op":"mcm","clk":"11935463768","pt":1724342651916,"mc":[{"id":"1.232135506","rc":[{"batb":[[0,1.94,1],[1,1.93,6.15],[2,1.9,5.69]],"ltp":2.44,"tv":0.86,"id":72963954}]}]}
{"op":"mcm","clk":"11935463923","pt":1724342653393,"mc":[{"id":"1.232135506","rc":[{"batb":[[0,1.95,4],[1,1.94,1],[2,1.93,6.15]],"ltp":2.44,"tv":0.86,"id":72963954}]}]}
{"op":"mcm","clk":"11935464222","pt":1724342655709,"mc":[{"id":"1.232135506","rc":[{"batb":[[0,1.94,1],[1,1.93,6.15],[2,1.9,5.69]],"ltp":2.44,"tv":0.86,"id":72963954}]}]}
{"op":"mcm","clk":"11935464554","pt":1724342658422,"mc":[{"id":"1.232135506","rc":[{"batb":[[0,1.96,10],[1,1.95,4],[2,1.94,1]],"ltp":2.44,"tv":0.86,"id":72963954}]}]}
{"op":"mcm","clk":"11935464814","pt":1724342660722,"mc":[{"id":"1.232135506","rc":[{"batb":[[1,1.94,1],[2,1.93,6.15]],"ltp":2.44,"tv":0.86,"id":72963954}]}]}
{"op":"mcm","clk":"11935464961","pt":1724342661992,"mc":[{"id":"1.232135506","rc":[{"batb":[[0,1.94,1],[1,1.93,6.15],[2,1.9,5.69]],"ltp":2.44,"tv":0.86,"id":72963954}]}]}
{"op":"mcm","clk":"11935465235","pt":1724342664308,"mc":[{"id":"1.232135506","rc":[{"batb":[[0,1.96,10],[1,1.95,4],[2,1.94,1]],"ltp":2.44,"tv":0.86,"id":72963954}]}]}
{"op":"mcm","clk":"11935465433","pt":1724342666217,"mc":[{"id":"1.232135506","rc":[{"batb":[[1,1.94,1],[2,1.93,6.15]],"ltp":2.44,"tv":0.86,"id":72963954}]}]}
{"op":"mcm","clk":"11935465600","pt":1724342667660,"mc":[{"id":"1.232135506","rc":[{"batb":[[0,1.94,1],[1,1.93,6.15],[2,1.9,5.69]],"ltp":2.44,"tv":0.86,"id":72963954}]}]}
{"op":"mcm","clk":"11935469070","pt":1724342696356,"mc":[{"id":"1.232135506","rc":[{"batb":[[0,1.96,10],[1,1.95,4],[2,1.94,1]],"ltp":2.44,"tv":0.86,"id":72963954}]}]}
{"op":"mcm","clk":"11935469360","pt":1724342698737,"mc":[{"id":"1.232135506","rc":[{"batb":[[1,1.94,1],[2,1.93,6.15]],"ltp":2.44,"tv":0.86,"id":72963954}]}]}
{"op":"mcm","clk":"11935469489","pt":1724342699736,"mc":[{"id":"1.232135506","rc":[{"batb":[[0,1.94,1],[1,1.93,6.15],[2,1.9,5.69]],"ltp":2.44,"tv":0.86,"id":72963954}]}]}
{"op":"mcm","clk":"11935470516","pt":1724342707270,"mc":[{"id":"1.232135506","rc":[{"batb":[[0,1.96,10],[1,1.95,4],[2,1.94,1]],"ltp":2.44,"tv":0.86,"id":72963954}]}]}
{"op":"mcm","clk":"11935470846","pt":1724342709348,"mc":[{"id":"1.232135506","rc":[{"batb":[[1,1.94,1],[2,1.93,6.15]],"ltp":2.44,"tv":0.86,"id":72963954}]}]}
{"op":"mcm","clk":"11935471031","pt":1724342710659,"mc":[{"id":"1.232135506","rc":[{"batb":[[0,1.94,1],[1,1.93,6.15],[2,1.9,5.69]],"ltp":2.44,"tv":0.86,"id":72963954}]}]}
{"op":"mcm","clk":"11935471770","pt":1724342716182,"mc":[{"id":"1.232135506","rc":[{"batb":[[0,1.96,10],[1,1.95,4],[2,1.94,1]],"ltp":2.44,"tv":0.86,"id":72963954}]}]}
{"op":"mcm","clk":"11935471998","pt":1724342718274,"mc":[{"id":"1.232135506","rc":[{"batb":[[1,1.94,1],[2,1.93,6.15]],"ltp":2.44,"tv":0.86,"id":72963954}]}]}
{"op":"mcm","clk":"11935472202","pt":1724342719693,"mc":[{"id":"1.232135506","rc":[{"batb":[[0,1.94,1],[1,1.93,6.15],[2,1.9,5.69]],"ltp":2.44,"tv":0.86,"id":72963954}]}]}
{"op":"mcm","clk":"11935473347","pt":1724342728104,"mc":[{"id":"1.232135506","rc":[{"batb":[[0,1.96,10],[1,1.95,4],[2,1.94,1]],"ltp":2.44,"tv":0.86,"id":72963954}]}]}
{"op":"mcm","clk":"11935473662","pt":1724342730358,"mc":[{"id":"1.232135506","rc":[{"batb":[[1,1.94,1],[2,1.93,6.15]],"ltp":2.44,"tv":0.86,"id":72963954}]}]}
{"op":"mcm","clk":"11935473822","pt":1724342731582,"mc":[{"id":"1.232135506","rc":[{"batb":[[0,1.94,1],[1,1.93,6.15],[2,1.9,5.69]],"ltp":2.44,"tv":0.86,"id":72963954}]}]}
{"op":"mcm","clk":"11935474441","pt":1724342736496,"mc":[{"id":"1.232135506","rc":[{"batb":[[0,1.96,10],[1,1.95,4],[2,1.94,1]],"ltp":2.44,"tv":0.86,"id":72963954}]}]}
{"op":"mcm","clk":"11935474735","pt":1724342738720,"mc":[{"id":"1.232135506","rc":[{"batb":[[1,1.94,1],[2,1.93,6.15]],"ltp":2.44,"tv":0.86,"id":72963954}]}]}
{"op":"mcm","clk":"11935474852","pt":1724342739814,"mc":[{"id":"1.232135506","rc":[{"batb":[[0,1.94,1],[1,1.93,6.15],[2,1.9,5.69]],"ltp":2.44,"tv":0.86,"id":72963954}]}]}
{"op":"mcm","clk":"11935475024","pt":1724342741004,"mc":[{"id":"1.232135506","rc":[{"batb":[[0,1.95,4],[1,1.94,1],[2,1.93,6.15]],"ltp":2.44,"tv":0.86,"id":72963954}]}]}
{"op":"mcm","clk":"11935475340","pt":1724342743502,"mc":[{"id":"1.232135506","rc":[{"batb":[[0,1.96,10]],"ltp":2.44,"tv":0.86,"id":72963954}]}]}
{"op":"mcm","clk":"11935475680","pt":1724342746001,"mc":[{"id":"1.232135506","rc":[{"batb":[[0,1.97,4],[1,1.96,10],[2,1.94,1]],"ltp":2.44,"tv":0.86,"id":72963954}]}]}
{"op":"mcm","clk":"11935475800","pt":1724342747014,"mc":[{"id":"1.232135506","rc":[{"batb":[[1,1.94,1],[2,1.93,6.15]],"ltp":2.44,"tv":0.86,"id":72963954}]}]}
{"op":"mcm","clk":"11935476002","pt":1724342748633,"mc":[{"id":"1.232135506","rc":[{"batb":[[0,1.94,1],[1,1.93,6.15],[2,1.9,5.69]],"ltp":2.44,"tv":0.86,"id":72963954}]}]}
{"op":"mcm","clk":"11935476804","pt":1724342755328,"mc":[{"id":"1.232135506","rc":[{"batb":[[0,2.1,10],[1,2.08,6.74],[2,1.95,4]],"ltp":2.44,"tv":0.86,"id":72963954}]}]}
{"op":"mcm","clk":"11935477034","pt":1724342757337,"mc":[{"id":"1.232135506","rc":[{"batb":[[2,1.94,1]],"ltp":2.44,"tv":0.86,"id":72963954}]}]}
{"op":"mcm","clk":"11935477176","pt":1724342758537,"mc":[{"id":"1.232135506","rc":[{"batb":[[0,2.08,6.74],[1,1.94,1],[2,1.93,6.15]],"ltp":2.44,"tv":0.86,"id":72963954}]}]}
{"op":"mcm","clk":"11935477599","pt":1724342762015,"mc":[{"id":"1.232135506","rc":[{"batb":[[0,2.1,14],[1,2.08,6.74],[2,1.94,1]],"ltp":2.44,"tv":0.86,"id":72963954}]}]}
{"op":"mcm","clk":"11935477940","pt":1724342764343,"mc":[{"id":"1.232135506","rc":[{"batb":[[0,2.1,10]],"ltp":2.44,"tv":0.86,"id":72963954}]}]}
{"op":"mcm","clk":"11935478056","pt":1724342765337,"mc":[{"id":"1.232135506","rc":[{"batb":[[0,2.08,6.74],[1,1.94,1],[2,1.93,6.15]],"ltp":2.44,"tv":0.86,"id":72963954}]}]}
{"op":"mcm","clk":"11935478775","pt":1724342770342,"mc":[{"id":"1.232135506","rc":[{"batb":[[0,2.1,14],[1,2.08,6.74],[2,1.94,1]],"ltp":2.44,"tv":0.86,"id":72963954}]}]}
{"op":"mcm","clk":"11935479141","pt":1724342773004,"mc":[{"id":"1.232135506","rc":[{"batb":[[0,2.1,10]],"ltp":2.44,"tv":0.86,"id":72963954}]}]}
{"op":"mcm","clk":"11935479341","pt":1724342773865,"mc":[{"id":"1.232135506","rc":[{"batb":[[0,2.08,6.74],[1,1.94,1],[2,1.93,6.15]],"ltp":2.44,"tv":0.86,"id":72963954}]}]}
{"op":"mcm","clk":"11935480319","pt":1724342780457,"mc":[{"id":"1.232135506","rc":[{"batb":[[0,2.1,14],[1,2.08,6.74],[2,1.94,1]],"ltp":2.44,"tv":0.86,"id":72963954}]}]}
{"op":"mcm","clk":"11935480617","pt":1724342782963,"mc":[{"id":"1.232135506","rc":[{"batl":[[0,1.92,27.76],[1,1.94,4.47],[2,2.02,35.47]],"ltp":1.69,"tv":470.93,"id":47674067},{"batb":[[0,2.1,10]],"ltp":2.44,"tv":0.86,"id":72963954}]}]}
{"op":"mcm","clk":"11935480763","pt":1724342784031,"mc":[{"id":"1.232135506","rc":[{"batb":[[0,2.08,6.74],[1,1.94,1],[2,1.93,6.15]],"ltp":2.44,"tv":0.86,"id":72963954}]}]}
{"op":"mcm","clk":"11935481253","pt":1724342787969,"mc":[{"id":"1.232135506","rc":[{"batl":[[0,1.91,4.66],[1,1.92,27.64]],"ltp":1.69,"tv":470.93,"id":47674067},{"batb":[[0,2.1,14],[1,2.08,6.74],[2,1.94,1]],"ltp":2.44,"tv":0.86,"id":72963954}]}]}
{"op":"mcm","clk":"11935481520","pt":1724342790161,"mc":[{"id":"1.232135506","rc":[{"batb":[[0,2.1,10]],"ltp":2.44,"tv":0.86,"id":72963954}]}]}
{"op":"mcm","clk":"11935481655","pt":1724342791162,"mc":[{"id":"1.232135506","rc":[{"batb":[[0,2.08,6.74],[1,1.94,1],[2,1.93,6.15]],"ltp":2.44,"tv":0.86,"id":72963954}]}]}
{"op":"mcm","clk":"11935482214","pt":1724342795661,"mc":[{"id":"1.232135506","rc":[{"batl":[[1,2.02,35.47],[2,2.96,10]],"ltp":1.69,"tv":470.93,"id":47674067}]}]}
{"op":"mcm","clk":"11935482233","pt":1724342795884,"mc":[{"id":"1.232135506","rc":[{"batl":[[0,1.91,32.3]],"ltp":1.69,"tv":470.93,"id":47674067},{"batb":[[0,2.1,14],[1,2.08,6.74],[2,1.94,1]],"ltp":2.44,"tv":0.86,"id":72963954}]}]}
{"op":"mcm","clk":"11935482518","pt":1724342798282,"mc":[{"id":"1.232135506","rc":[{"batb":[[0,2.1,10]],"ltp":2.44,"tv":0.86,"id":72963954}]}]}
{"op":"mcm","clk":"11935482632","pt":1724342799282,"mc":[{"id":"1.232135506","rc":[{"batb":[[0,2.08,6.74],[1,1.94,1],[2,1.93,6.15]],"ltp":2.44,"tv":0.86,"id":72963954}]}]}
{"op":"mcm","clk":"11935484662","pt":1724342815771,"mc":[{"id":"1.232135506","rc":[{"batb":[[0,2.1,14],[1,2.08,6.74],[2,1.94,1]],"ltp":2.44,"tv":0.86,"id":72963954}]}]}
{"op":"mcm","clk":"11935485029","pt":1724342818437,"mc":[{"id":"1.232135506","rc":[{"batb":[[0,2.1,10]],"ltp":2.44,"tv":0.86,"id":72963954}]}]}
{"op":"mcm","clk":"11935485130","pt":1724342819162,"mc":[{"id":"1.232135506","rc":[{"batb":[[0,2.08,6.74],[1,1.94,1],[2,1.93,6.15]],"ltp":2.44,"tv":0.86,"id":72963954}]}]}
{"op":"mcm","clk":"11935485876","pt":1724342825046,"mc":[{"id":"1.232135506","rc":[{"batb":[[0,2.1,14],[1,2.08,6.74],[2,1.94,1]],"ltp":2.44,"tv":0.86,"id":72963954}]}]}
{"op":"mcm","clk":"11935486203","pt":1724342827376,"mc":[{"id":"1.232135506","rc":[{"batb":[[0,2.1,10]],"ltp":2.44,"tv":0.86,"id":72963954}]}]}
{"op":"mcm","clk":"11935486368","pt":1724342828520,"mc":[{"id":"1.232135506","rc":[{"batb":[[0,2.08,6.74],[1,1.94,1],[2,1.93,6.15]],"ltp":2.44,"tv":0.86,"id":72963954}]}]}
{"op":"mcm","clk":"11935489554","pt":1724342853516,"mc":[{"id":"1.232135506","rc":[{"batb":[[0,2.1,14],[1,2.08,6.74],[2,1.94,1]],"ltp":2.44,"tv":0.86,"id":72963954}]}]}
{"op":"mcm","clk":"11935489858","pt":1724342855753,"mc":[{"id":"1.232135506","rc":[{"batb":[[0,2.1,10]],"ltp":2.44,"tv":0.86,"id":72963954}]}]}
{"op":"mcm","clk":"11935489990","pt":1724342856945,"mc":[{"id":"1.232135506","rc":[{"batb":[[0,2.08,6.74],[1,1.94,1],[2,1.93,6.15]],"ltp":2.44,"tv":0.86,"id":72963954}]}]}
{"op":"mcm","clk":"11935490977","pt":1724342866262,"mc":[{"id":"1.232135506","rc":[{"batb":[[0,2.1,14],[1,2.08,6.74],[2,1.94,1]],"ltp":2.44,"tv":0.86,"id":72963954}]}]}
{"op":"mcm","clk":"11935491237","pt":1724342868667,"mc":[{"id":"1.232135506","rc":[{"batb":[[0,2.1,10]],"ltp":2.44,"tv":0.86,"id":72963954}]}]}
{"op":"mcm","clk":"11935491356","pt":1724342869614,"mc":[{"id":"1.232135506","rc":[{"batb":[[0,2.08,6.74],[1,1.94,1],[2,1.93,6.15]],"ltp":2.44,"tv":0.86,"id":72963954}]}]}
{"op":"mcm","clk":"11935492537","pt":1724342879480,"mc":[{"id":"1.232135506","rc":[{"batb":[[0,2.1,14],[1,2.08,6.74],[2,1.94,1]],"ltp":2.44,"tv":0.86,"id":72963954}]}]}
{"op":"mcm","clk":"11935492811","pt":1724342881780,"mc":[{"id":"1.232135506","rc":[{"batb":[[0,2.1,10]],"ltp":2.44,"tv":0.86,"id":72963954}]}]}
{"op":"mcm","clk":"11935492960","pt":1724342882878,"mc":[{"id":"1.232135506","rc":[{"batb":[[0,2.08,6.74],[1,1.94,1],[2,1.93,6.15]],"ltp":2.44,"tv":0.86,"id":72963954}]}]}
{"op":"mcm","clk":"11935493897","pt":1724342890184,"mc":[{"id":"1.232135506","rc":[{"batl":[[0,1.9,67.52],[1,1.91,32.3],[2,2.02,35.47]],"ltp":1.69,"tv":470.93,"id":47674067},{"batb":[[0,2.1,14],[1,2.08,6.74],[2,1.94,1]],"ltp":2.44,"tv":0.86,"id":72963954}]}]}
{"op":"mcm","clk":"11935494225","pt":1724342892376,"mc":[{"id":"1.232135506","rc":[{"batl":[[0,1.89,4.59],[1,1.9,67.52],[2,1.91,27.76]],"ltp":1.69,"tv":470.93,"id":47674067},{"batb":[[0,2.1,10]],"ltp":2.44,"tv":0.86,"id":72963954}]}]}
{"op":"mcm","clk":"11935494342","pt":1724342893363,"mc":[{"id":"1.232135506","rc":[{"batb":[[0,2.08,6.74],[1,1.94,1],[2,1.93,6.15]],"ltp":2.44,"tv":0.86,"id":72963954}]}]}
{"op":"mcm","clk":"11935494773","pt":1724342896869,"mc":[{"id":"1.232135506","rc":[{"batl":[[0,1.89,32.23],[2,2.02,35.59]],"ltp":1.69,"tv":470.93,"id":47674067},{"batb":[[0,2.1,14],[1,2.08,6.74],[2,1.94,1]],"ltp":2.44,"tv":0.86,"id":72963954}]}]}
{"op":"mcm","clk":"11935495046","pt":1724342899176,"mc":[{"id":"1.232135506","rc":[{"batb":[[0,2.1,10]],"ltp":2.44,"tv":0.86,"id":72963954}]}]}
{"op":"mcm","clk":"11935495168","pt":1724342900063,"mc":[{"id":"1.232135506","rc":[{"batb":[[0,2.08,6.74],[1,1.94,1],[2,1.93,6.15]],"ltp":2.44,"tv":0.86,"id":72963954}]}]}
{"op":"mcm","clk":"11935495718","pt":1724342904610,"mc":[{"id":"1.232135506","rc":[{"batb":[[0,2.1,14],[1,2.08,6.74],[2,1.94,1]],"ltp":2.44,"tv":0.86,"id":72963954}]}]}
{"op":"mcm","clk":"11935496004","pt":1724342906705,"mc":[{"id":"1.232135506","rc":[{"batl":[[0,1.88,67.52],[1,1.89,32.23],[2,1.9,67.52]],"ltp":1.69,"tv":470.93,"id":47674067}]}]}
{"op":"mcm","clk":"11935496091","pt":1724342907397,"mc":[{"id":"1.232135506","rc":[{"batb":[[0,2.1,10]],"ltp":2.44,"tv":0.86,"id":72963954}]}]}
{"op":"mcm","clk":"11935496189","pt":1724342908218,"mc":[{"id":"1.232135506","rc":[{"batb":[[0,2.08,6.74],[1,1.94,1],[2,1.93,6.15]],"ltp":2.44,"tv":0.86,"id":72963954}]}]}
{"op":"mcm","clk":"11935496307","pt":1724342909194,"mc":[{"id":"1.232135506","rc":[{"batl":[[0,1.87,4.64],[1,1.88,67.52],[2,1.89,27.64]],"ltp":1.69,"tv":470.93,"id":47674067}]}]}
{"op":"mcm","clk":"11935496515","pt":1724342911119,"mc":[{"id":"1.232135506","rc":[{"batb":[[0,2.1,14],[1,2.08,6.74],[2,1.94,1]],"ltp":2.44,"tv":0.86,"id":72963954}]}]}
{"op":"mcm","clk":"11935496786","pt":1724342913487,"mc":[{"id":"1.232135506","rc":[{"batb":[[0,2.1,10]],"ltp":2.44,"tv":0.86,"id":72963954}]}]}
{"op":"mcm","clk":"11935496914","pt":1724342914598,"mc":[{"id":"1.232135506","rc":[{"batb":[[0,2.08,6.74],[1,1.94,1],[2,1.93,6.15]],"ltp":2.44,"tv":0.86,"id":72963954}]}]}
{"op":"mcm","clk":"11935497087","pt":1724342916225,"mc":[{"id":"1.232135506","rc":[{"batb":[[0,2.1,4],[1,2.08,6.74],[2,1.94,1]],"ltp":2.44,"tv":0.86,"id":72963954}]}]}
{"op":"mcm","clk":"11935497241","pt":1724342917390,"mc":[{"id":"1.232135506","rc":[{"batb":[[0,2.12,10],[1,2.1,4],[2,2.08,6.74]],"ltp":2.44,"tv":0.86,"id":72963954}]}]}
{"op":"mcm","clk":"11935497390","pt":1724342918710,"mc":[{"id":"1.232135506","rc":[{"batb":[[1,2.08,6.74],[2,1.94,1]],"ltp":2.44,"tv":0.86,"id":72963954}]}]}
{"op":"mcm","clk":"11935497695","pt":1724342921320,"mc":[{"id":"1.232135506","rc":[{"batb":[[0,2.1,4]],"ltp":2.44,"tv":0.86,"id":72963954}]}]}
{"op":"mcm","clk":"11935497799","pt":1724342922110,"mc":[{"id":"1.232135506","rc":[{"batl":[[0,1.82,67.52],[1,1.87,4.64],[2,1.88,67.52]],"ltp":1.69,"tv":470.93,"id":47674067}]}]}
{"op":"mcm","clk":"11935497957","pt":1724342923410,"mc":[{"id":"1.232135506","rc":[{"batl":[[1,1.88,67.52],[2,1.89,27.64]],"ltp":1.69,"tv":470.93,"id":47674067},{"batb":[[0,2.12,10],[1,2.1,4],[2,2.08,6.74]],"ltp":2.44,"tv":0.86,"id":72963954}]}]}
{"op":"mcm","clk":"11935497994","pt":1724342923825,"mc":[{"id":"1.232135506","rc":[{"batb":[[1,2.08,6.74],[2,1.94,1]],"ltp":2.44,"tv":0.86,"id":72963954}]}]}
{"op":"mcm","clk":"11935498111","pt":1724342924917,"mc":[{"id":"1.232135506","rc":[{"batl":[[1,1.89,27.64],[2,2.02,35.59]],"ltp":1.69,"tv":470.93,"id":47674067}]}]}
{"op":"mcm","clk":"11935498346","pt":1724342927009,"mc":[{"id":"1.232135506","rc":[{"batb":[[0,2.1,4]],"ltp":2.44,"tv":0.86,"id":72963954}]}]}
{"op":"mcm","clk":"11935498541","pt":1724342928718,"mc":[{"id":"1.232135506","rc":[{"batl":[[1,2.02,35.59],[2,2.96,10]],"ltp":1.69,"tv":470.93,"id":47674067}]}]}
{"op":"mcm","clk":"11935498647","pt":1724342929501,"mc":[{"id":"1.232135506","rc":[{"batb":[[0,2.1,10]],"ltp":2.44,"tv":0.86,"id":72963954}]}]}
{"op":"mcm","clk":"11935499018","pt":1724342932946,"mc":[{"id":"1.232135506","rc":[{"batb":[[0,2.1,4]],"ltp":2.44,"tv":0.86,"id":72963954}]}]}
{"op":"mcm","clk":"11935499253","pt":1724342935342,"mc":[{"id":"1.232135506","rc":[{"batb":[[0,2.1,10]],"ltp":2.44,"tv":0.86,"id":72963954}]}]}
{"op":"mcm","clk":"11935499502","pt":1724342937444,"mc":[{"id":"1.232135506","rc":[{"batl":[[0,1.81,4.8],[1,1.82,67.52],[2,2.02,35.59]],"ltp":1.69,"tv":470.93,"id":47674067},{"batb":[[0,2.12,4],[1,2.1,10],[2,2.08,6.74]],"ltp":2.44,"tv":0.86,"id":72963954}]}]}
{"op":"mcm","clk":"11935499625","pt":1724342938509,"mc":[{"id":"1.232135506","rc":[{"batb":[[1,2.08,6.74],[2,1.94,1]],"ltp":2.44,"tv":0.86,"id":72963954}]}]}
{"op":"mcm","clk":"11935499745","pt":1724342939712,"mc":[{"id":"1.232135506","rc":[{"batb":[[0,2.08,6.74],[1,1.94,1],[2,1.93,6.15]],"ltp":2.44,"tv":0.86,"id":72963954}]}]}
{"op":"mcm","clk":"11935500186","pt":1724342943440,"mc":[{"id":"1.232135506","rc":[{"batb":[[0,2.1,14],[1,2.08,6.74],[2,1.94,1]],"ltp":2.44,"tv":0.86,"id":72963954}]}]}
{"op":"mcm","clk":"11935500510","pt":1724342945755,"mc":[{"id":"1.232135506","rc":[{"batb":[[0,2.1,10]],"ltp":2.44,"tv":0.86,"id":72963954}]}]}
{"op":"mcm","clk":"11935500653","pt":1724342946967,"mc":[{"id":"1.232135506","rc":[{"batb":[[0,2.08,6.74],[1,1.94,1],[2,1.93,6.15]],"ltp":2.44,"tv":0.86,"id":72963954}]}]}
{"op":"mcm","clk":"11935500836","pt":1724342948385,"mc":[{"id":"1.232135506","rc":[{"batb":[[0,2.1,4],[1,2.08,6.74],[2,1.94,1]],"ltp":2.44,"tv":0.86,"id":72963954}]}]}
{"op":"mcm","clk":"11935501120","pt":1724342950946,"mc":[{"id":"1.232135506","rc":[{"batb":[[0,2.1,10]],"ltp":2.44,"tv":0.86,"id":72963954}]}]}
{"op":"mcm","clk":"11935501491","pt":1724342954296,"mc":[{"id":"1.232135506","rc":[{"batb":[[0,2.1,4]],"ltp":2.44,"tv":0.86,"id":72963954}]}]}
{"op":"mcm","clk":"11935501721","pt":1724342956687,"mc":[{"id":"1.232135506","rc":[{"batb":[[0,2.08,6.74],[1,1.94,1],[2,1.93,6.15]],"ltp":2.44,"tv":0.86,"id":72963954}]}]}
{"op":"mcm","clk":"11935501743","pt":1724342956851,"mc":[{"id":"1.232135506","rc":[{"batb":[[0,2.1,10],[1,2.08,6.74],[2,1.94,1]],"ltp":2.44,"tv":0.86,"id":72963954}]}]}
{"op":"mcm","clk":"11935502110","pt":1724342960302,"mc":[{"id":"1.232135506","rc":[{"batb":[[0,2.1,4]],"ltp":2.44,"tv":0.86,"id":72963954}]}]}
{"op":"mcm","clk":"11935502418","pt":1724342962724,"mc":[{"id":"1.232135506","rc":[{"batb":[[0,2.1,10]],"ltp":2.44,"tv":0.86,"id":72963954}]}]}
{"op":"mcm","clk":"11935502857","pt":1724342966304,"mc":[{"id":"1.232135506","rc":[{"batb":[[0,2.1,4]],"ltp":2.44,"tv":0.86,"id":72963954}]}]}
{"op":"mcm","clk":"11935503131","pt":1724342968585,"mc":[{"id":"1.232135506","rc":[{"batb":[[0,2.1,10]],"ltp":2.44,"tv":0.86,"id":72963954}]}]}
{"op":"mcm","clk":"11935503574","pt":1724342972174,"mc":[{"id":"1.232135506","rc":[{"batb":[[0,2.1,4]],"ltp":2.44,"tv":0.86,"id":72963954}]}]}
{"op":"mcm","clk":"11935503849","pt":1724342974609,"mc":[{"id":"1.232135506","rc":[{"batb":[[0,2.1,10]],"ltp":2.44,"tv":0.86,"id":72963954}]}]}
{"op":"mcm","clk":"11935504117","pt":1724342976981,"mc":[{"id":"1.232135506","rc":[{"batb":[[0,2.12,4],[1,2.1,10],[2,2.08,6.74]],"ltp":2.44,"tv":0.86,"id":72963954}]}]}
{"op":"mcm","clk":"11935504290","pt":1724342978294,"mc":[{"id":"1.232135506","rc":[{"batl":[[0,1.8,67.52],[1,1.81,4.8],[2,1.82,67.52]],"ltp":1.69,"tv":470.93,"id":47674067},{"batb":[[1,2.08,6.74],[2,1.94,1]],"ltp":2.44,"tv":0.86,"id":72963954}]}]}
{"op":"mcm","clk":"11935504414","pt":1724342979395,"mc":[{"id":"1.232135506","rc":[{"batl":[[0,1.79,4.85],[1,1.8,67.52]],"ltp":1.69,"tv":470.93,"id":47674067},{"batb":[[0,2.08,6.74],[1,1.94,1],[2,1.93,6.15]],"ltp":2.44,"tv":0.86,"id":72963954}]}]}
{"op":"mcm","clk":"11935504541","pt":1724342980394,"mc":[{"id":"1.232135506","rc":[{"batl":[[2,2.02,35.59]],"ltp":1.69,"tv":470.93,"id":47674067},{"batb":[[0,2.1,10],[1,2.08,6.74],[2,1.94,1]],"ltp":2.44,"tv":0.86,"id":72963954}]}]}
{"op":"mcm","clk":"11935504962","pt":1724342983626,"mc":[{"id":"1.232135506","rc":[{"batb":[[0,2.08,6.74],[1,1.94,1],[2,1.93,6.15]],"ltp":2.44,"tv":0.86,"id":72963954}]}]}
{"op":"mcm","clk":"11935504987","pt":1724342983833,"mc":[{"id":"1.232135506","rc":[{"batb":[[0,2.1,4],[1,2.08,6.74],[2,1.94,1]],"ltp":2.44,"tv":0.86,"id":72963954}]}]}
{"op":"mcm","clk":"11935505316","pt":1724342986194,"mc":[{"id":"1.232135506","rc":[{"batb":[[0,2.1,10]],"ltp":2.44,"tv":0.86,"id":72963954}]}]}
{"op":"mcm","clk":"11935505533","pt":1724342987922,"mc":[{"id":"1.232135506","rc":[{"batl":[[1,2.02,35.59],[2,2.96,10]],"ltp":1.69,"tv":470.93,"id":47674067}]}]}
{"op":"mcm","clk":"11935505761","pt":1724342989618,"mc":[{"id":"1.232135506","rc":[{"batb":[[0,1.69,10],[1,1.68,7.64],[2,1.67,7.64]],"batl":[[0,2,4.46],[1,2.02,35.47]],"ltp":1.69,"tv":470.93,"id":47674067},{"batb":[[0,2.12,4]],"ltp":2.44,"tv":0.86,"id":72963954}]}]}
{"op":"mcm","clk":"11935506127","pt":1724342992030,"mc":[{"id":"1.232135506","rc":[{"batb":[[0,2.1,10]],"ltp":2.44,"tv":0.86,"id":72963954}]}]}
{"op":"mcm","clk":"11935506248","pt":1724342993043,"mc":[{"id":"1.232135506","rc":[{"batb":[[0,1.68,7.64],[1,1.67,7.64],[2,1.66,7.64]],"ltp":1.69,"tv":470.93,"id":47674067}]}]}
{"op":"mcm","clk":"11935506684","pt":1724342996231,"mc":[{"id":"1.232135506","rc":[{"batb":[[0,1.69,10],[1,1.68,7.64],[2,1.67,7.64]],"ltp":1.69,"tv":470.93,"id":47674067},{"batb":[[0,2.12,4]],"ltp":2.44,"tv":0.86,"id":72963954}]}]}
{"op":"mcm","clk":"11935507088","pt":1724342998734,"mc":[{"id":"1.232135506","rc":[{"batl":[[0,1.88,2.77],[1,2,4.46],[2,2.02,35.47]],"ltp":1.69,"tv":470.93,"id":47674067},{"batb":[[0,2.14,10],[1,2.12,4],[2,2.08,6.74]],"ltp":2.44,"tv":0.86,"id":72963954}]}]}
{"op":"mcm","clk":"11935507180","pt":1724342999626,"mc":[{"id":"1.232135506","rc":[{"batb":[[0,1.68,7.64],[1,1.67,7.64],[2,1.66,7.64]],"ltp":1.69,"tv":470.93,"id":47674067},{"batb":[[1,2.08,6.74],[2,1.94,1]],"ltp":2.44,"tv":0.86,"id":72963954}]}]}
{"op":"mcm","clk":"11935507372","pt":1724343001048,"mc":[{"id":"1.232135506","rc":[{"batl":[[0,1.85,67.52],[1,1.88,2.77],[2,2,4.46]],"ltp":1.69,"tv":470.93,"id":47674067},{"batb":[[0,2.16,4],[1,2.14,10],[2,2.08,6.74]],"ltp":2.44,"tv":0.86,"id":72963954}]}]}
{"op":"mcm","clk":"11935507527","pt":1724343002151,"mc":[{"id":"1.232135506","rc":[{"batb":[[1,2.08,6.74],[2,1.94,1]],"ltp":2.44,"tv":0.86,"id":72963954}]}]}
{"op":"mcm","clk":"11935507736","pt":1724343003680,"mc":[{"id":"1.232135506","rc":[{"batl":[[0,1.84,4.72],[1,1.85,67.52],[2,1.88,2.77]],"ltp":1.69,"tv":470.93,"id":47674067},{"batb":[[0,2.08,6.74],[1,1.94,1],[2,1.93,6.15]],"ltp":2.44,"tv":0.86,"id":72963954}]}]}
