{"op":"mcm","clk":"11918258682","pt":1724583322999,"mc":[{"id":"1.232260815","marketDefinition":{"bspMarket":false,"turnInPlayEnabled":true,"persistenceEnabled":true,"marketBaseRate":5.0,"eventId":"33525729","eventTypeId":"4","numberOfWinners":1,"bettingType":"ODDS","marketType":"MATCH_ODDS","marketTime":"2024-08-27T14:30:00.000Z","suspendTime":"2024-08-27T14:30:00.000Z","bspReconciled":false,"complete":true,"inPlay":false,"crossMatching":false,"runnersVoidable":false,"numberOfActiveRunners":2,"betDelay":0,"status":"OPEN","runners":[{"status":"ACTIVE","sortPriority":1,"id":60971788,"name":"Czechia"},{"status":"ACTIVE","sortPriority":2,"id":60971786,"name":"Greece"}],"regulators":["MR_INT"],"countryCode":"GB","discountAllowed":false,"timezone":"GMT","openDate":"2024-08-27T14:30:00.000Z","version":6098410788,"name":"Match Odds","eventName":"Czechia v Greece"},"rc":[{"batb":[[0,1.03,200],[1,1.02,200],[2,1.01,220]],"ltp":0.0,"tv":0.0,"id":60971788},{"batb":[[0,1.03,200],[1,1.02,200],[2,1.01,220]],"ltp":0.0,"tv":0.0,"id":60971786}]}]}
{"op":"mcm","clk":"11918258877","pt":1724583324329,"mc":[{"id":"1.232260815","marketDefinition":{"bspMarket":false,"turnInPlayEnabled":true,"persistenceEnabled":true,"marketBaseRate":5.0,"eventId":"33525729","eventTypeId":"4","numberOfWinners":1,"bettingType":"ODDS","marketType":"MATCH_ODDS","marketTime":"2024-08-27T14:30:00.000Z","suspendTime":"2024-08-27T14:30:00.000Z","bspReconciled":false,"complete":true,"inPlay":false,"crossMatching":false,"runnersVoidable":false,"numberOfActiveRunners":2,"betDelay":0,"status":"OPEN","runners":[{"status":"ACTIVE","sortPriority":1,"id":60971788,"name":"Czechia"},{"status":"ACTIVE","sortPriority":2,"id":60971786,"name":"Greece"}],"regulators":["MR_INT"],"countryCode":"GB","discountAllowed":true,"timezone":"GMT","openDate":"2024-08-27T14:30:00.000Z","version":6098410788,"name":"Match Odds","eventName":"Czechia v Greece"}}]}
{"op":"mcm","clk":"11918336800","pt":1724583910280,"mc":[{"id":"1.232260815","rc":[{"batb":[[2,1.01,220.76]],"ltp":0.0,"tv":0.0,"id":60971788},{"batb":[[2,1.01,220.76]],"ltp":0.0,"tv":0.0,"id":60971786}]}]}
{"op":"mcm","clk":"11918532570","pt":1724585255024,"mc":[{"id":"1.232260815","rc":[{"batb":[[2,1.01,221.51]],"ltp":0.0,"tv":0.0,"id":60971788},{"batb":[[2,1.01,221.51]],"ltp":0.0,"tv":0.0,"id":60971786}]}]}
{"op":"mcm","clk":"11918533284","pt":1724585260042,"mc":[{"id":"1.232260815","marketDefinition":{"bspMarket":false,"turnInPlayEnabled":true,"persistenceEnabled":true,"marketBaseRate":5.0,"eventId":"33525729","eventTypeId":"4","numberOfWinners":1,"bettingType":"ODDS","marketType":"MATCH_ODDS","marketTime":"2024-08-27T14:30:00.000Z","suspendTime":"2024-08-27T14:30:00.000Z","bspReconciled":false,"complete":true,"inPlay":false,"crossMatching":true,"runnersVoidable":false,"numberOfActiveRunners":2,"betDelay":0,"status":"OPEN","runners":[{"status":"ACTIVE","sortPriority":1,"id":60971788,"name":"Czechia"},{"status":"ACTIVE","sortPriority":2,"id":60971786,"name":"Greece"}],"regulators":["MR_INT"],"countryCode":"GB","discountAllowed":true,"timezone":"GMT","openDate":"2024-08-27T14:30:00.000Z","version":6098410788,"name":"Match Odds","eventName":"Czechia v Greece"}}]}
{"op":"mcm","clk":"11918899574","pt":1724588017708,"mc":[{"id":"1.232260815","rc":[{"batb":[[0,1.05,200],[1,1.04,250],[2,1.03,533.33]],"ltp":0.0,"tv":0.0,"id":60971788},{"batb":[[0,1.05,200],[1,1.04,250],[2,1.03,533.33]],"ltp":0.0,"tv":0.0,"id":60971786}]}]}
{"op":"mcm","clk":"11919281088","pt":1724590681206,"mc":[{"id":"1.232260815","rc":[{"batl":[[0,14,0.76]],"ltp":0.0,"tv":0.0,"id":60971788},{"batl":[[0,14,0.76]],"ltp":0.0,"tv":0.0,"id":60971786}]}]}
{"op":"mcm","clk":"11919282471","pt":1724590691244,"mc":[{"id":"1.232260815","rc":[{"batl":[[0,24,1.51]],"ltp":0.0,"tv":0.0,"id":60971788},{"batl":[[0,24,1.51]],"ltp":0.0,"tv":0.0,"id":60971786}]}]}
{"op":"mcm","clk":"11920406783","pt":1724597772973,"mc":[{"id":"1.232260815","rc":[{"batl":[[0,14,1.68],[1,24,0.76]],"ltp":0.0,"tv":0.0,"id":60971786}]}]}
{"op":"mcm","clk":"11920408360","pt":1724597785727,"mc":[{"id":"1.232260815","rc":[{"batl":[[0,14,1.68],[1,24,0.76]],"ltp":0.0,"tv":0.0,"id":60971788}]}]}
{"op":"mcm","clk":"11920419948","pt":1724597881730,"mc":[{"id":"1.232260815","rc":[{"batb":[[0,1.11,5.48],[1,1.05,200],[2,1.04,250]],"ltp":0.0,"tv":0.0,"id":60971786}]}]}
{"op":"mcm","clk":"11922571218","pt":1724611851752,"mc":[{"id":"1.232260815","rc":[{"batb":[[0,1.57,67.44],[1,1.05,200],[2,1.04,250]],"ltp":0.0,"tv":0.0,"id":60971788},{"batb":[[0,2.62,23.73],[1,1.11,5.48],[2,1.05,200]],"ltp":0.0,"tv":0.0,"id":60971786}]}]}
{"op":"mcm","clk":"11923703498","pt":1724618574825,"mc":[{"id":"1.232260815","rc":[{"batl":[[0,14,1.68],[1,24,0.76]],"ltp":0.0,"tv":0.0,"id":60971788},{"batl":[[0,14,1.68],[1,24,0.76]],"ltp":0.0,"tv":0.0,"id":60971786}]}]}
{"op":"mcm","clk":"11924158684","pt":1724623108016,"mc":[{"id":"1.232260815","rc":[{"batl":[[0,24,1.51],[1,24,0]],"ltp":0.0,"tv":0.0,"id":60971788},{"batb":[[1,1.05,200],[2,1.04,250]],"batl":[[0,24,1.51],[1,24,0]],"ltp":0.0,"tv":0.0,"id":60971786}]}]}
{"op":"mcm","clk":"11925406228","pt":1724645574826,"mc":[{"id":"1.232260815","rc":[{"batl":[[0,24,1.51]],"ltp":0.0,"tv":0.0,"id":60971788},{"batl":[[0,24,1.51]],"ltp":0.0,"tv":0.0,"id":60971786}]}]}
{"op":"mcm","clk":"11926238981","pt":1724663354024,"mc":[{"id":"1.232260815","rc":[{"batl":[[0,17,594.59],[1,24,0.76]],"ltp":0.0,"tv":0.0,"id":60971788}]}]}
{"op":"mcm","clk":"11926350940","pt":1724666058025,"mc":[{"id":"1.232260815","rc":[{"batl":[[0,24,1.52],[1,24,0]],"ltp":0.0,"tv":0.0,"id":60971788}]}]}
{"op":"mcm","clk":"11926618000","pt":1724671502963,"mc":[{"id":"1.232260815","rc":[{"batb":[[1,1.53,10.26],[2,1.05,200]],"ltp":0.0,"tv":0.0,"id":60971788}]}]}
{"op":"mcm","clk":"11927143649","pt":1724679313066,"mc":[{"id":"1.232260815","rc":[{"batb":[[0,1.57,71.6]],"ltp":0.0,"tv":0.0,"id":60971788},{"batb":[[0,2.62,25.19]],"ltp":0.0,"tv":0.0,"id":60971786}]}]}
{"op":"mcm","clk":"11927258454","pt":1724680435543,"mc":[{"id":"1.232260815","rc":[{"batb":[[2,1.04,251.05]],"ltp":0.0,"tv":0.0,"id":60971786}]}]}
{"op":"mcm","clk":"11927797084","pt":1724683374832,"mc":[{"id":"1.232260815","rc":[{"batl":[[0,24,1.52]],"ltp":0.0,"tv":0.0,"id":60971788},{"batl":[[0,24,1.52]],"ltp":0.0,"tv":0.0,"id":60971786}]}]}
{"op":"mcm","clk":"11928374550","pt":1724686659324,"mc":[{"id":"1.232260815","rc":[{"batb":[[2,1.13,384.62]],"ltp":0.0,"tv":0.0,"id":60971788},{"batb":[[1,1.09,277.78],[2,1.07,357.14]],"ltp":0.0,"tv":0.0,"id":60971786}]}]}
{"op":"mcm","clk":"11928374621","pt":1724686659698,"mc":[{"id":"1.232260815","rc":[{"batb":[[2,1.28,178.57]],"ltp":0.0,"tv":0.0,"id":60971788},{"batb":[[1,1.28,178.57],[2,1.23,217.39]],"ltp":0.0,"tv":0.0,"id":60971786}]}]}
{"op":"mcm","clk":"11929343242","pt":1724694174840,"mc":[{"id":"1.232260815","rc":[{"batl":[[0,24,1.52]],"ltp":0.0,"tv":0.0,"id":60971788},{"batl":[[0,24,1.52]],"ltp":0.0,"tv":0.0,"id":60971786}]}]}
{"op":"mcm","clk":"11930033052","pt":1724699574847,"mc":[{"id":"1.232260815","rc":[{"batl":[[0,24,1.52]],"ltp":0.0,"tv":0.0,"id":60971788},{"batl":[[0,24,1.52]],"ltp":0.0,"tv":0.0,"id":60971786}]}]}
{"op":"mcm","clk":"11930339903","pt":1724702311683,"mc":[{"id":"1.232260815","rc":[{"trd":[[1.57,17.58]],"batb":[[0,1.57,54.02]],"ltp":1.57,"tv":17.58,"id":60971788},{"trd":[[2.76,10]],"ltp":2.76,"tv":10.0,"id":60971786}],"tv":27.58}]}
{"op":"mcm","clk":"11930340105","pt":1724702314293,"mc":[{"id":"1.232260815","rc":[{"batb":[[0,1.57,125.62]],"ltp":1.57,"tv":17.58,"id":60971788}]}]}
{"op":"mcm","clk":"11930340112","pt":1724702314375,"mc":[{"id":"1.232260815","rc":[{"batb":[[0,1.57,71.6]],"ltp":1.57,"tv":17.58,"id":60971788}]}]}
{"op":"mcm","clk":"11931082513","pt":1724713432634,"mc":[{"id":"1.232260815","rc":[{"batb":[[0,1.54,75.58]],"ltp":1.57,"tv":17.58,"id":60971788},{"batb":[[0,2.7,24]],"ltp":2.76,"tv":10.0,"id":60971786}]}]}
{"op":"mcm","clk":"11931905552","pt":1724729758652,"mc":[{"id":"1.232260815","rc":[{"trd":[[1.54,0.18]],"batb":[[0,1.54,75.49]],"ltp":1.54,"tv":17.75,"id":60971788}],"tv":27.75}]}
{"op":"mcm","clk":"11931905636","pt":1724729761573,"mc":[{"id":"1.232260815","rc":[{"batb":[[0,1.54,75.58]],"ltp":1.54,"tv":17.75,"id":60971788}]}]}
{"op":"mcm","clk":"11931905676","pt":1724729762753,"mc":[{"id":"1.232260815","rc":[{"trd":[[1.59,0.09]],"ltp":1.59,"tv":17.84,"id":60971788},{"trd":[[2.7,0.05]],"batb":[[0,2.7,23.95]],"ltp":2.7,"tv":10.05,"id":60971786}],"tv":27.89}]}
{"op":"mcm","clk":"11931905792","pt":1724729766734,"mc":[{"id":"1.232260815","rc":[{"batb":[[0,2.7,24]],"ltp":2.7,"tv":10.05,"id":60971786}]}]}
{"op":"mcm","clk":"11932005618","pt":1724732307661,"mc":[{"id":"1.232260815","rc":[{"trd":[[2.7,0.23]],"batb":[[0,2.7,23.91]],"ltp":2.7,"tv":10.22,"id":60971786}],"tv":28.07}]}
{"op":"mcm","clk":"11932005684","pt":1724732309760,"mc":[{"id":"1.232260815","rc":[{"batb":[[0,2.7,24]],"ltp":2.7,"tv":10.22,"id":60971786}]}]}
{"op":"mcm","clk":"11932005809","pt":1724732313645,"mc":[{"id":"1.232260815","rc":[{"trd":[[1.54,0.34]],"batb":[[0,1.54,75.42]],"ltp":1.54,"tv":18.0,"id":60971788},{"trd":[[2.86,0.09]],"ltp":2.86,"tv":10.31,"id":60971786}],"tv":28.32}]}
{"op":"mcm","clk":"11932005839","pt":1724732314769,"mc":[{"id":"1.232260815","rc":[{"batb":[[0,1.54,75.58]],"ltp":1.54,"tv":18.0,"id":60971788}]}]}
{"op":"mcm","clk":"11932213663","pt":1724737764641,"mc":[{"id":"1.232260815","rc":[{"trd":[[2.7,10.23]],"batb":[[0,2.7,19]],"ltp":2.7,"tv":20.31,"id":60971786}],"tv":38.32}]}
{"op":"mcm","clk":"11932213764","pt":1724737766747,"mc":[{"id":"1.232260815","rc":[{"batb":[[0,2.7,24]],"ltp":2.7,"tv":20.31,"id":60971786}]}]}
{"op":"mcm","clk":"11932249773","pt":1724738775668,"mc":[{"id":"1.232260815","rc":[{"trd":[[1.54,2.1]],"batb":[[0,1.54,74.7]],"ltp":1.54,"tv":19.76,"id":60971788}],"tv":40.08}]}
{"op":"mcm","clk":"11932249895","pt":1724738779782,"mc":[{"id":"1.232260815","rc":[{"batb":[[0,1.54,75.58]],"ltp":1.54,"tv":19.76,"id":60971788}]}]}
{"op":"mcm","clk":"11932331435","pt":1724740946881,"mc":[{"id":"1.232260815","rc":[{"trd":[[1.54,44.41]],"batb":[[0,1.55,5],[1,1.54,33.27],[2,1.53,10.26]],"ltp":1.54,"tv":62.07,"id":60971788},{"trd":[[2.86,22.87]],"batb":[[0,2.72,5],[1,2.7,24],[2,1.28,178.57]],"ltp":2.86,"tv":43.09,"id":60971786}],"tv":105.17}]}
{"op":"mcm","clk":"11932331519","pt":1724740950315,"mc":[{"id":"1.232260815","rc":[{"batb":[[0,1.54,33.27],[1,1.53,10.26],[2,1.28,178.57]],"ltp":1.54,"tv":62.07,"id":60971788},{"batb":[[0,2.7,24],[1,1.28,178.57],[2,1.23,217.39]],"ltp":2.86,"tv":43.09,"id":60971786}]}]}
{"op":"mcm","clk":"11932331573","pt":1724740951692,"mc":[{"id":"1.232260815","rc":[{"batb":[[0,1.54,75.58]],"ltp":1.54,"tv":62.07,"id":60971788}]}]}
{"op":"mcm","clk":"11932331619","pt":1724740952822,"mc":[{"id":"1.232260815","rc":[{"batb":[[0,1.55,5],[1,1.54,75.58],[2,1.53,10.26]],"ltp":1.54,"tv":62.07,"id":60971788},{"batb":[[0,2.72,5],[1,2.7,24],[2,1.28,178.57]],"ltp":2.86,"tv":43.09,"id":60971786}]}]}
{"op":"mcm","clk":"11932331710","pt":1724740956219,"mc":[{"id":"1.232260815","rc":[{"batb":[[0,1.54,75.58],[1,1.53,10.26],[2,1.28,178.57]],"ltp":1.54,"tv":62.07,"id":60971788},{"batb":[[0,2.7,24],[1,1.28,178.57],[2,1.23,217.39]],"ltp":2.86,"tv":43.09,"id":60971786}]}]}
{"op":"mcm","clk":"11932331761","pt":1724740958418,"mc":[{"id":"1.232260815","rc":[{"batb":[[0,1.55,5],[1,1.54,75.58],[2,1.53,10.26]],"ltp":1.54,"tv":62.07,"id":60971788},{"batb":[[0,2.72,5],[1,2.7,24],[2,1.28,178.57]],"ltp":2.86,"tv":43.09,"id":60971786}]}]}
{"op":"mcm","clk":"11932331873","pt":1724740961813,"mc":[{"id":"1.232260815","rc":[{"batb":[[0,1.54,75.58],[1,1.53,10.26],[2,1.28,178.57]],"ltp":1.54,"tv":62.07,"id":60971788},{"batb":[[0,2.7,24],[1,1.28,178.57],[2,1.23,217.39]],"ltp":2.86,"tv":43.09,"id":60971786}]}]}
{"op":"mcm","clk":"11932331969","pt":1724740964021,"mc":[{"id":"1.232260815","rc":[{"batb":[[0,1.55,5],[1,1.54,75.58],[2,1.53,10.26]],"ltp":1.54,"tv":62.07,"id":60971788},{"batb":[[0,2.72,5],[1,2.7,24],[2,1.28,178.57]],"ltp":2.86,"tv":43.09,"id":60971786}]}]}
{"op":"mcm","clk":"11932332052","pt":1724740967446,"mc":[{"id":"1.232260815","rc":[{"batb":[[0,1.54,75.58],[1,1.53,10.26],[2,1.28,178.57]],"ltp":1.54,"tv":62.07,"id":60971788},{"batb":[[0,2.7,24],[1,1.28,178.57],[2,1.23,217.39]],"ltp":2.86,"tv":43.09,"id":60971786}]}]}
{"op":"mcm","clk":"11932332105","pt":1724740969648,"mc":[{"id":"1.232260815","rc":[{"batb":[[0,1.55,5],[1,1.54,75.58],[2,1.53,10.26]],"ltp":1.54,"tv":62.07,"id":60971788},{"batb":[[0,2.72,5],[1,2.7,24],[2,1.28,178.57]],"ltp":2.86,"tv":43.09,"id":60971786}]}]}
{"op":"mcm","clk":"11932332182","pt":1724740972925,"mc":[{"id":"1.232260815","rc":[{"batb":[[0,1.54,75.58],[1,1.53,10.26],[2,1.28,178.57]],"ltp":1.54,"tv":62.07,"id":60971788},{"batb":[[0,2.7,24],[1,1.28,178.57],[2,1.23,217.39]],"ltp":2.86,"tv":43.09,"id":60971786}]}]}
{"op":"mcm","clk":"11932332264","pt":1724740975836,"mc":[{"id":"1.232260815","rc":[{"batb":[[0,1.55,5],[1,1.54,75.58],[2,1.53,10.26]],"ltp":1.54,"tv":62.07,"id":60971788},{"batb":[[0,2.72,5],[1,2.7,24],[2,1.28,178.57]],"ltp":2.86,"tv":43.09,"id":60971786}]}]}
{"op":"mcm","clk":"11932332356","pt":1724740979365,"mc":[{"id":"1.232260815","rc":[{"batb":[[0,1.54,75.58],[1,1.53,10.26],[2,1.28,178.57]],"ltp":1.54,"tv":62.07,"id":60971788},{"batb":[[0,2.7,24],[1,1.28,178.57],[2,1.23,217.39]],"ltp":2.86,"tv":43.09,"id":60971786}]}]}
{"op":"mcm","clk":"11932332443","pt":1724740982237,"mc":[{"id":"1.232260815","rc":[{"batb":[[0,1.55,5],[1,1.54,75.58],[2,1.53,10.26]],"ltp":1.54,"tv":62.07,"id":60971788},{"batb":[[0,2.72,5],[1,2.7,24],[2,1.28,178.57]],"ltp":2.86,"tv":43.09,"id":60971786}]}]}
{"op":"mcm","clk":"11932332570","pt":1724740985657,"mc":[{"id":"1.232260815","rc":[{"batb":[[0,1.54,75.58],[1,1.53,10.26],[2,1.28,178.57]],"ltp":1.54,"tv":62.07,"id":60971788},{"batb":[[0,2.7,24],[1,1.28,178.57],[2,1.23,217.39]],"ltp":2.86,"tv":43.09,"id":60971786}]}]}
{"op":"mcm","clk":"11932332643","pt":1724740987851,"mc":[{"id":"1.232260815","rc":[{"batb":[[0,1.55,5],[1,1.54,75.58],[2,1.53,10.26]],"ltp":1.54,"tv":62.07,"id":60971788},{"batb":[[0,2.72,5],[1,2.7,24],[2,1.28,178.57]],"ltp":2.86,"tv":43.09,"id":60971786}]}]}
{"op":"mcm","clk":"11932332738","pt":1724740991170,"mc":[{"id":"1.232260815","rc":[{"batb":[[0,1.54,75.58],[1,1.53,10.26],[2,1.28,178.57]],"ltp":1.54,"tv":62.07,"id":60971788},{"batb":[[0,2.7,24],[1,1.28,178.57],[2,1.23,217.39]],"ltp":2.86,"tv":43.09,"id":60971786}]}]}
{"op":"mcm","clk":"11932332812","pt":1724740993354,"mc":[{"id":"1.232260815","rc":[{"batb":[[0,1.55,5],[1,1.54,75.58],[2,1.53,10.26]],"ltp":1.54,"tv":62.07,"id":60971788},{"batb":[[0,2.72,5],[1,2.7,24],[2,1.28,178.57]],"ltp":2.86,"tv":43.09,"id":60971786}]}]}
{"op":"mcm","clk":"11932332923","pt":1724740996985,"mc":[{"id":"1.232260815","rc":[{"batb":[[0,1.54,75.58],[1,1.53,10.26],[2,1.28,178.57]],"ltp":1.54,"tv":62.07,"id":60971788},{"batb":[[0,2.7,24],[1,1.28,178.57],[2,1.23,217.39]],"ltp":2.86,"tv":43.09,"id":60971786}]}]}
{"op":"mcm","clk":"11932333010","pt":1724740999956,"mc":[{"id":"1.232260815","rc":[{"batb":[[0,1.55,5],[1,1.54,75.58],[2,1.53,10.26]],"ltp":1.54,"tv":62.07,"id":60971788},{"batb":[[0,2.72,5],[1,2.7,24],[2,1.28,178.57]],"ltp":2.86,"tv":43.09,"id":60971786}]}]}
{"op":"mcm","clk":"11932333119","pt":1724741003387,"mc":[{"id":"1.232260815","rc":[{"batb":[[0,1.54,75.58],[1,1.53,10.26],[2,1.28,178.57]],"ltp":1.54,"tv":62.07,"id":60971788},{"batb":[[0,2.7,24],[1,1.28,178.57],[2,1.23,217.39]],"ltp":2.86,"tv":43.09,"id":60971786}]}]}
{"op":"mcm","clk":"11932333172","pt":1724741005590,"mc":[{"id":"1.232260815","rc":[{"batb":[[0,1.55,5],[1,1.54,75.58],[2,1.53,10.26]],"ltp":1.54,"tv":62.07,"id":60971788},{"batb":[[0,2.72,5],[1,2.7,24],[2,1.28,178.57]],"ltp":2.86,"tv":43.09,"id":60971786}]}]}
{"op":"mcm","clk":"11932333252","pt":1724741008872,"mc":[{"id":"1.232260815","rc":[{"batb":[[0,1.54,75.58],[1,1.53,10.26],[2,1.28,178.57]],"ltp":1.54,"tv":62.07,"id":60971788},{"batb":[[0,2.7,24],[1,1.28,178.57],[2,1.23,217.39]],"ltp":2.86,"tv":43.09,"id":60971786}]}]}
{"op":"mcm","clk":"11932333351","pt":1724741012503,"mc":[{"id":"1.232260815","rc":[{"batb":[[0,1.55,5],[1,1.54,75.58],[2,1.53,10.26]],"ltp":1.54,"tv":62.07,"id":60971788},{"batb":[[0,2.72,5],[1,2.7,24],[2,1.28,178.57]],"ltp":2.86,"tv":43.09,"id":60971786}]}]}
{"op":"mcm","clk":"11932333452","pt":1724741015881,"mc":[{"id":"1.232260815","rc":[{"batb":[[0,1.54,75.58],[1,1.53,10.26],[2,1.28,178.57]],"ltp":1.54,"tv":62.07,"id":60971788},{"batb":[[0,2.7,24],[1,1.28,178.57],[2,1.23,217.39]],"ltp":2.86,"tv":43.09,"id":60971786}]}]}
{"op":"mcm","clk":"11932333530","pt":1724741018381,"mc":[{"id":"1.232260815","rc":[{"batb":[[0,1.55,5],[1,1.54,75.58],[2,1.53,10.26]],"ltp":1.54,"tv":62.07,"id":60971788},{"batb":[[0,2.72,5],[1,2.7,24],[2,1.28,178.57]],"ltp":2.86,"tv":43.09,"id":60971786}]}]}
{"op":"mcm","clk":"11932333639","pt":1724741021815,"mc":[{"id":"1.232260815","rc":[{"batb":[[0,1.54,75.58],[1,1.53,10.26],[2,1.28,178.57]],"ltp":1.54,"tv":62.07,"id":60971788},{"batb":[[0,2.7,24],[1,1.28,178.57],[2,1.23,217.39]],"ltp":2.86,"tv":43.09,"id":60971786}]}]}
{"op":"mcm","clk":"11932333725","pt":1724741024232,"mc":[{"id":"1.232260815","rc":[{"batb":[[0,1.55,5],[1,1.54,75.58],[2,1.53,10.26]],"ltp":1.54,"tv":62.07,"id":60971788},{"batb":[[0,2.72,5],[1,2.7,24],[2,1.28,178.57]],"ltp":2.86,"tv":43.09,"id":60971786}]}]}
{"op":"mcm","clk":"11932333835","pt":1724741027711,"mc":[{"id":"1.232260815","rc":[{"batb":[[0,1.54,75.58],[1,1.53,10.26],[2,1.28,178.57]],"ltp":1.54,"tv":62.07,"id":60971788},{"batb":[[0,2.7,24],[1,1.28,178.57],[2,1.23,217.39]],"ltp":2.86,"tv":43.09,"id":60971786}]}]}
{"op":"mcm","clk":"11932333908","pt":1724741030324,"mc":[{"id":"1.232260815","rc":[{"batb":[[0,1.55,5],[1,1.54,75.58],[2,1.53,10.26]],"ltp":1.54,"tv":62.07,"id":60971788},{"batb":[[0,2.72,5],[1,2.7,24],[2,1.28,178.57]],"ltp":2.86,"tv":43.09,"id":60971786}]}]}
{"op":"mcm","clk":"11932333996","pt":1724741033648,"mc":[{"id":"1.232260815","rc":[{"batb":[[0,1.54,75.58],[1,1.53,10.26],[2,1.28,178.57]],"ltp":1.54,"tv":62.07,"id":60971788},{"batb":[[0,2.7,24],[1,1.28,178.57],[2,1.23,217.39]],"ltp":2.86,"tv":43.09,"id":60971786}]}]}
{"op":"mcm","clk":"11932334070","pt":1724741035851,"mc":[{"id":"1.232260815","rc":[{"batb":[[0,1.55,5],[1,1.54,75.58],[2,1.53,10.26]],"ltp":1.54,"tv":62.07,"id":60971788},{"batb":[[0,2.72,5],[1,2.7,24],[2,1.28,178.57]],"ltp":2.86,"tv":43.09,"id":60971786}]}]}
{"op":"mcm","clk":"11932334167","pt":1724741039133,"mc":[{"id":"1.232260815","rc":[{"batb":[[0,1.54,75.58],[1,1.53,10.26],[2,1.28,178.57]],"ltp":1.54,"tv":62.07,"id":60971788},{"batb":[[0,2.7,24],[1,1.28,178.57],[2,1.23,217.39]],"ltp":2.86,"tv":43.09,"id":60971786}]}]}
{"op":"mcm","clk":"11932334221","pt":1724741041325,"mc":[{"id":"1.232260815","rc":[{"batb":[[0,1.55,5],[1,1.54,75.58],[2,1.53,10.26]],"ltp":1.54,"tv":62.07,"id":60971788},{"batb":[[0,2.72,5],[1,2.7,24],[2,1.28,178.57]],"ltp":2.86,"tv":43.09,"id":60971786}]}]}
{"op":"mcm","clk":"11932334342","pt":1724741044773,"mc":[{"id":"1.232260815","rc":[{"batb":[[0,1.54,75.58],[1,1.53,10.26],[2,1.28,178.57]],"ltp":1.54,"tv":62.07,"id":60971788},{"batb":[[0,2.7,24],[1,1.28,178.57],[2,1.23,217.39]],"ltp":2.86,"tv":43.09,"id":60971786}]}]}
{"op":"mcm","clk":"11932334426","pt":1724741047533,"mc":[{"id":"1.232260815","rc":[{"batb":[[0,1.55,5],[1,1.54,75.58],[2,1.53,10.26]],"ltp":1.54,"tv":62.07,"id":60971788},{"batb":[[0,2.72,5],[1,2.7,24],[2,1.28,178.57]],"ltp":2.86,"tv":43.09,"id":60971786}]}]}
{"op":"mcm","clk":"11932334577","pt":1724741051073,"mc":[{"id":"1.232260815","rc":[{"batb":[[0,1.54,75.58],[1,1.53,10.26],[2,1.28,178.57]],"ltp":1.54,"tv":62.07,"id":60971788},{"batb":[[0,2.7,24],[1,1.28,178.57],[2,1.23,217.39]],"ltp":2.86,"tv":43.09,"id":60971786}]}]}
{"op":"mcm","clk":"11932334689","pt":1724741053682,"mc":[{"id":"1.232260815","rc":[{"batb":[[0,1.55,5],[1,1.54,75.58],[2,1.53,10.26]],"ltp":1.54,"tv":62.07,"id":60971788},{"batb":[[0,2.72,5],[1,2.7,24],[2,1.28,178.57]],"ltp":2.86,"tv":43.09,"id":60971786}]}]}
{"op":"mcm","clk":"11932334793","pt":1724741056961,"mc":[{"id":"1.232260815","rc":[{"batb":[[0,1.54,75.58],[1,1.53,10.26],[2,1.28,178.57]],"ltp":1.54,"tv":62.07,"id":60971788},{"batb":[[0,2.7,24],[1,1.28,178.57],[2,1.23,217.39]],"ltp":2.86,"tv":43.09,"id":60971786}]}]}
{"op":"mcm","clk":"11932334901","pt":1724741060860,"mc":[{"id":"1.232260815","rc":[{"batb":[[0,1.55,5],[1,1.54,75.58],[2,1.53,10.26]],"ltp":1.54,"tv":62.07,"id":60971788},{"batb":[[0,2.72,5],[1,2.7,24],[2,1.28,178.57]],"ltp":2.86,"tv":43.09,"id":60971786}]}]}
{"op":"mcm","clk":"11932335017","pt":1724741064284,"mc":[{"id":"1.232260815","rc":[{"batb":[[0,1.54,75.58],[1,1.53,10.26],[2,1.28,178.57]],"ltp":1.54,"tv":62.07,"id":60971788},{"batb":[[0,2.7,24],[1,1.28,178.57],[2,1.23,217.39]],"ltp":2.86,"tv":43.09,"id":60971786}]}]}
{"op":"mcm","clk":"11932335108","pt":1724741066482,"mc":[{"id":"1.232260815","rc":[{"batb":[[0,1.55,5],[1,1.54,75.58],[2,1.53,10.26]],"ltp":1.54,"tv":62.07,"id":60971788},{"batb":[[0,2.72,5],[1,2.7,24],[2,1.28,178.57]],"ltp":2.86,"tv":43.09,"id":60971786}]}]}
{"op":"mcm","clk":"11932335227","pt":1724741069766,"mc":[{"id":"1.232260815","rc":[{"batb":[[0,1.54,75.58],[1,1.53,10.26],[2,1.28,178.57]],"ltp":1.54,"tv":62.07,"id":60971788},{"batb":[[0,2.7,24],[1,1.28,178.57],[2,1.23,217.39]],"ltp":2.86,"tv":43.09,"id":60971786}]}]}
{"op":"mcm","clk":"11932335314","pt":1724741072082,"mc":[{"id":"1.232260815","rc":[{"batb":[[0,1.55,5],[1,1.54,75.58],[2,1.53,10.26]],"ltp":1.54,"tv":62.07,"id":60971788},{"batb":[[0,2.72,5],[1,2.7,24],[2,1.28,178.57]],"ltp":2.86,"tv":43.09,"id":60971786}]}]}
{"op":"mcm","clk":"11932335415","pt":1724741075304,"mc":[{"id":"1.232260815","rc":[{"batb":[[0,1.54,75.58],[1,1.53,10.26],[2,1.28,178.57]],"ltp":1.54,"tv":62.07,"id":60971788}]}]}
{"op":"mcm","clk":"11932335421","pt":1724741075409,"mc":[{"id":"1.232260815","rc":[{"batb":[[0,2.7,24],[1,1.28,178.57],[2,1.23,217.39]],"ltp":2.86,"tv":43.09,"id":60971786}]}]}
{"op":"mcm","clk":"11932335456","pt":1724741077606,"mc":[{"id":"1.232260815","rc":[{"batb":[[0,1.55,5],[1,1.54,75.58],[2,1.53,10.26]],"ltp":1.54,"tv":62.07,"id":60971788},{"batb":[[0,2.72,5],[1,2.7,24],[2,1.28,178.57]],"ltp":2.86,"tv":43.09,"id":60971786}]}]}
{"op":"mcm","clk":"11932335519","pt":1724741081088,"mc":[{"id":"1.232260815","rc":[{"batb":[[0,1.54,75.58],[1,1.53,10.26],[2,1.28,178.57]],"ltp":1.54,"tv":62.07,"id":60971788},{"batb":[[0,2.7,24],[1,1.28,178.57],[2,1.23,217.39]],"ltp":2.86,"tv":43.09,"id":60971786}]}]}
{"op":"mcm","clk":"11932335603","pt":1724741083696,"mc":[{"id":"1.232260815","rc":[{"batb":[[0,1.55,5],[1,1.54,75.58],[2,1.53,10.26]],"ltp":1.54,"tv":62.07,"id":60971788},{"batb":[[0,2.72,5],[1,2.7,24],[2,1.28,178.57]],"ltp":2.86,"tv":43.09,"id":60971786}]}]}
{"op":"mcm","clk":"11932335709","pt":1724741087222,"mc":[{"id":"1.232260815","rc":[{"batb":[[0,1.54,75.58],[1,1.53,10.26],[2,1.28,178.57]],"ltp":1.54,"tv":62.07,"id":60971788},{"batb":[[0,2.7,24],[1,1.28,178.57],[2,1.23,217.39]],"ltp":2.86,"tv":43.09,"id":60971786}]}]}
{"op":"mcm","clk":"11932335788","pt":1724741089319,"mc":[{"id":"1.232260815","rc":[{"batb":[[0,1.55,5],[1,1.54,75.58],[2,1.53,10.26]],"ltp":1.54,"tv":62.07,"id":60971788},{"batb":[[0,2.72,5],[1,2.7,24],[2,1.28,178.57]],"ltp":2.86,"tv":43.09,"id":60971786}]}]}
{"op":"mcm","clk":"11932335922","pt":1724741092599,"mc":[{"id":"1.232260815","rc":[{"batb":[[0,1.54,75.58],[1,1.53,10.26],[2,1.28,178.57]],"ltp":1.54,"tv":62.07,"id":60971788},{"batb":[[0,2.7,24],[1,1.28,178.57],[2,1.23,217.39]],"ltp":2.86,"tv":43.09,"id":60971786}]}]}
{"op":"mcm","clk":"11932335987","pt":1724741094798,"mc":[{"id":"1.232260815","rc":[{"batb":[[0,1.55,5],[1,1.54,75.58],[2,1.53,10.26]],"ltp":1.54,"tv":62.07,"id":60971788},{"batb":[[0,2.72,5],[1,2.7,24],[2,1.28,178.57]],"ltp":2.86,"tv":43.09,"id":60971786}]}]}
{"op":"mcm","clk":"11932336076","pt":1724741098118,"mc":[{"id":"1.232260815","rc":[{"batb":[[0,1.54,75.58],[1,1.53,10.26],[2,1.28,178.57]],"ltp":1.54,"tv":62.07,"id":60971788},{"batb":[[0,2.7,24],[1,1.28,178.57],[2,1.23,217.39]],"ltp":2.86,"tv":43.09,"id":60971786}]}]}
{"op":"mcm","clk":"11932336136","pt":1724741100527,"mc":[{"id":"1.232260815","rc":[{"batb":[[0,1.55,5],[1,1.54,75.58],[2,1.53,10.26]],"ltp":1.54,"tv":62.07,"id":60971788},{"batb":[[0,2.72,5],[1,2.7,24],[2,1.28,178.57]],"ltp":2.86,"tv":43.09,"id":60971786}]}]}
{"op":"mcm","clk":"11932336277","pt":1724741103974,"mc":[{"id":"1.232260815","rc":[{"batb":[[0,1.54,75.58],[1,1.53,10.26],[2,1.28,178.57]],"ltp":1.54,"tv":62.07,"id":60971788},{"batb":[[0,2.7,24],[1,1.28,178.57],[2,1.23,217.39]],"ltp":2.86,"tv":43.09,"id":60971786}]}]}
{"op":"mcm","clk":"11932336362","pt":1724741106137,"mc":[{"id":"1.232260815","rc":[{"batb":[[0,1.55,5],[1,1.54,75.58],[2,1.53,10.26]],"ltp":1.54,"tv":62.07,"id":60971788},{"batb":[[0,2.72,5],[1,2.7,24],[2,1.28,178.57]],"ltp":2.86,"tv":43.09,"id":60971786}]}]}
{"op":"mcm","clk":"11932336473","pt":1724741109459,"mc":[{"id":"1.232260815","rc":[{"batb":[[0,1.54,75.58],[1,1.53,10.26],[2,1.28,178.57]],"ltp":1.54,"tv":62.07,"id":60971788},{"batb":[[0,2.7,24],[1,1.28,178.57],[2,1.23,217.39]],"ltp":2.86,"tv":43.09,"id":60971786}]}]}
{"op":"mcm","clk":"11932336543","pt":1724741111554,"mc":[{"id":"1.232260815","rc":[{"batb":[[0,1.55,5],[1,1.54,75.58],[2,1.53,10.26]],"ltp":1.54,"tv":62.07,"id":60971788},{"batb":[[0,2.72,5],[1,2.7,24],[2,1.28,178.57]],"ltp":2.86,"tv":43.09,"id":60971786}]}]}
{"op":"mcm","clk":"11932336672","pt":1724741114989,"mc":[{"id":"1.232260815","rc":[{"batb":[[0,1.54,75.58],[1,1.53,10.26],[2,1.28,178.57]],"ltp":1.54,"tv":62.07,"id":60971788},{"batb":[[0,2.7,24],[1,1.28,178.57],[2,1.23,217.39]],"ltp":2.86,"tv":43.09,"id":60971786}]}]}
{"op":"mcm","clk":"11932336726","pt":1724741117058,"mc":[{"id":"1.232260815","rc":[{"batb":[[0,1.55,5],[1,1.54,75.58],[2,1.53,10.26]],"ltp":1.54,"tv":62.07,"id":60971788},{"batb":[[0,2.72,5],[1,2.7,24],[2,1.28,178.57]],"ltp":2.86,"tv":43.09,"id":60971786}]}]}
{"op":"mcm","clk":"11932336854","pt":1724741120381,"mc":[{"id":"1.232260815","rc":[{"batb":[[0,1.54,75.58],[1,1.53,10.26],[2,1.28,178.57]],"ltp":1.54,"tv":62.07,"id":60971788},{"batb":[[0,2.7,24],[1,1.28,178.57],[2,1.23,217.39]],"ltp":2.86,"tv":43.09,"id":60971786}]}]}
{"op":"mcm","clk":"11932336953","pt":1724741123860,"mc":[{"id":"1.232260815","rc":[{"batb":[[0,1.55,5],[1,1.54,75.58],[2,1.53,10.26]],"ltp":1.54,"tv":62.07,"id":60971788},{"batb":[[0,2.72,5],[1,2.7,24],[2,1.28,178.57]],"ltp":2.86,"tv":43.09,"id":60971786}]}]}
{"op":"mcm","clk":"11932337049","pt":1724741127182,"mc":[{"id":"1.232260815","rc":[{"batb":[[0,1.54,75.58],[1,1.53,10.26],[2,1.28,178.57]],"ltp":1.54,"tv":62.07,"id":60971788},{"batb":[[0,2.7,24],[1,1.28,178.57],[2,1.23,217.39]],"ltp":2.86,"tv":43.09,"id":60971786}]}]}
{"op":"mcm","clk":"11932337122","pt":1724741129281,"mc":[{"id":"1.232260815","rc":[{"batb":[[0,1.55,5],[1,1.54,75.58],[2,1.53,10.26]],"ltp":1.54,"tv":62.07,"id":60971788},{"batb":[[0,2.72,5],[1,2.7,24],[2,1.28,178.57]],"ltp":2.86,"tv":43.09,"id":60971786}]}]}
{"op":"mcm","clk":"11932337225","pt":1724741132511,"mc":[{"id":"1.232260815","rc":[{"batb":[[0,1.54,75.58],[1,1.53,10.26],[2,1.28,178.57]],"ltp":1.54,"tv":62.07,"id":60971788},{"batb":[[0,2.7,24],[1,1.28,178.57],[2,1.23,217.39]],"ltp":2.86,"tv":43.09,"id":60971786}]}]}
{"op":"mcm","clk":"11932337317","pt":1724741134875,"mc":[{"id":"1.232260815","rc":[{"batb":[[0,1.55,5],[1,1.54,75.58],[2,1.53,10.26]],"ltp":1.54,"tv":62.07,"id":60971788},{"batb":[[0,2.72,5],[1,2.7,24],[2,1.28,178.57]],"ltp":2.86,"tv":43.09,"id":60971786}]}]}
{"op":"mcm","clk":"11932337443","pt":1724741138201,"mc":[{"id":"1.232260815","rc":[{"batb":[[0,1.54,75.58],[1,1.53,10.26],[2,1.28,178.57]],"ltp":1.54,"tv":62.07,"id":60971788},{"batb":[[0,2.7,24],[1,1.28,178.57],[2,1.23,217.39]],"ltp":2.86,"tv":43.09,"id":60971786}]}]}
{"op":"mcm","clk":"11932337711","pt":1724741145211,"mc":[{"id":"1.232260815","rc":[{"batb":[[0,1.55,5],[1,1.54,75.58],[2,1.53,10.26]],"ltp":1.54,"tv":62.07,"id":60971788},{"batb":[[0,2.72,5],[1,2.7,24],[2,1.28,178.57]],"ltp":2.86,"tv":43.09,"id":60971786}]}]}
{"op":"mcm","clk":"11932337831","pt":1724741148698,"mc":[{"id":"1.232260815","rc":[{"batb":[[0,1.54,75.58],[1,1.53,10.26],[2,1.28,178.57]],"ltp":1.54,"tv":62.07,"id":60971788},{"batb":[[0,2.7,24],[1,1.28,178.57],[2,1.23,217.39]],"ltp":2.86,"tv":43.09,"id":60971786}]}]}
{"op":"mcm","clk":"11932338044","pt":1724741153208,"mc":[{"id":"1.232260815","rc":[{"batb":[[0,1.55,5],[1,1.54,75.58],[2,1.53,10.26]],"ltp":1.54,"tv":62.07,"id":60971788},{"batb":[[0,2.72,5],[1,2.7,24],[2,1.28,178.57]],"ltp":2.86,"tv":43.09,"id":60971786}]}]}
{"op":"mcm","clk":"11932338166","pt":1724741156530,"mc":[{"id":"1.232260815","rc":[{"batb":[[0,1.54,75.58],[1,1.53,10.26],[2,1.28,178.57]],"ltp":1.54,"tv":62.07,"id":60971788},{"batb":[[0,2.7,24],[1,1.28,178.57],[2,1.23,217.39]],"ltp":2.86,"tv":43.09,"id":60971786}]}]}
{"op":"mcm","clk":"11932338246","pt":1724741159342,"mc":[{"id":"1.232260815","rc":[{"batb":[[0,1.55,5],[1,1.54,75.58],[2,1.53,10.26]],"ltp":1.54,"tv":62.07,"id":60971788},{"batb":[[0,2.72,5],[1,2.7,24],[2,1.28,178.57]],"ltp":2.86,"tv":43.09,"id":60971786}]}]}
{"op":"mcm","clk":"11932338354","pt":1724741162741,"mc":[{"id":"1.232260815","rc":[{"batb":[[0,1.54,75.58],[1,1.53,10.26],[2,1.28,178.57]],"ltp":1.54,"tv":62.07,"id":60971788},{"batb":[[0,2.7,24],[1,1.28,178.57],[2,1.23,217.39]],"ltp":2.86,"tv":43.09,"id":60971786}]}]}
{"op":"mcm","clk":"11932338483","pt":1724741164924,"mc":[{"id":"1.232260815","rc":[{"batb":[[0,1.55,5],[1,1.54,75.58],[2,1.53,10.26]],"ltp":1.54,"tv":62.07,"id":60971788},{"batb":[[0,2.72,5],[1,2.7,24],[2,1.28,178.57]],"ltp":2.86,"tv":43.09,"id":60971786}]}]}
{"op":"mcm","clk":"11932338629","pt":1724741168428,"mc":[{"id":"1.232260815","rc":[{"batb":[[0,1.54,75.58],[1,1.53,10.26],[2,1.28,178.57]],"ltp":1.54,"tv":62.07,"id":60971788},{"batb":[[0,2.7,24],[1,1.28,178.57],[2,1.23,217.39]],"ltp":2.86,"tv":43.09,"id":60971786}]}]}
{"op":"mcm","clk":"11932338780","pt":1724741171662,"mc":[{"id":"1.232260815","rc":[{"batb":[[0,1.55,5],[1,1.54,75.58],[2,1.53,10.26]],"ltp":1.54,"tv":62.07,"id":60971788},{"batb":[[0,2.72,5],[1,2.7,24],[2,1.28,178.57]],"ltp":2.86,"tv":43.09,"id":60971786}]}]}
{"op":"mcm","clk":"11932338928","pt":1724741175061,"mc":[{"id":"1.232260815","rc":[{"batb":[[0,1.54,75.58],[1,1.53,10.26],[2,1.28,178.57]],"ltp":1.54,"tv":62.07,"id":60971788},{"batb":[[0,2.7,24],[1,1.28,178.57],[2,1.23,217.39]],"ltp":2.86,"tv":43.09,"id":60971786}]}]}
{"op":"mcm","clk":"11932339009","pt":1724741177346,"mc":[{"id":"1.232260815","rc":[{"batb":[[0,1.55,5],[1,1.54,75.58],[2,1.53,10.26]],"ltp":1.54,"tv":62.07,"id":60971788},{"batb":[[0,2.72,5],[1,2.7,24],[2,1.28,178.57]],"ltp":2.86,"tv":43.09,"id":60971786}]}]}
{"op":"mcm","clk":"11932339141","pt":1724741180633,"mc":[{"id":"1.232260815","rc":[{"batb":[[0,1.54,75.58],[1,1.53,10.26],[2,1.28,178.57]],"ltp":1.54,"tv":62.07,"id":60971788},{"batb":[[0,2.7,24],[1,1.28,178.57],[2,1.23,217.39]],"ltp":2.86,"tv":43.09,"id":60971786}]}]}
{"op":"mcm","clk":"11932339265","pt":1724741183053,"mc":[{"id":"1.232260815","rc":[{"trd":[[1.54,118.7]],"batb":[[0,1.55,5],[1,1.54,1.29],[2,1.53,10.26]],"ltp":1.54,"tv":136.36,"id":60971788},{"trd":[[2.86,62.87]],"batb":[[0,2.72,5],[1,2.7,24],[2,1.28,178.57]],"ltp":2.86,"tv":83.09,"id":60971786}],"tv":219.46}]}
{"op":"mcm","clk":"11932339381","pt":1724741186250,"mc":[{"id":"1.232260815","rc":[{"batb":[[0,1.54,1.29],[1,1.53,10.26],[2,1.28,178.57]],"ltp":1.54,"tv":136.36,"id":60971788},{"batb":[[0,2.7,24],[1,1.28,178.57],[2,1.23,217.39]],"ltp":2.86,"tv":83.09,"id":60971786}]}]}
{"op":"mcm","clk":"11932339425","pt":1724741187374,"mc":[{"id":"1.232260815","rc":[{"batb":[[0,1.53,10.26],[1,1.5,81.63]],"ltp":1.54,"tv":136.36,"id":60971788}]}]}
{"op":"mcm","clk":"11932339473","pt":1724741188660,"mc":[{"id":"1.232260815","rc":[{"batb":[[0,1.54,5],[1,1.53,10.26],[2,1.5,81.63]],"ltp":1.54,"tv":136.36,"id":60971788},{"batb":[[0,2.72,5],[1,2.7,24],[2,1.28,178.57]],"ltp":2.86,"tv":83.09,"id":60971786}]}]}
{"op":"mcm","clk":"11932339580","pt":1724741192046,"mc":[{"id":"1.232260815","rc":[{"batb":[[0,1.53,10.26],[1,1.5,81.63],[2,1.28,178.57]],"ltp":1.54,"tv":136.36,"id":60971788},{"batb":[[0,2.7,24],[1,1.28,178.57],[2,1.23,217.39]],"ltp":2.86,"tv":83.09,"id":60971786}]}]}
{"op":"mcm","clk":"11932339670","pt":1724741194252,"mc":[{"id":"1.232260815","rc":[{"batb":[[0,1.54,5],[1,1.53,10.26],[2,1.5,81.63]],"ltp":1.54,"tv":136.36,"id":60971788},{"batb":[[0,2.72,5],[1,2.7,24],[2,1.28,178.57]],"ltp":2.86,"tv":83.09,"id":60971786}]}]}
{"op":"mcm","clk":"11932339819","pt":1724741197792,"mc":[{"id":"1.232260815","rc":[{"batb":[[0,1.53,10.26],[1,1.5,81.63],[2,1.28,178.57]],"ltp":1.54,"tv":136.36,"id":60971788},{"batb":[[0,2.7,24],[1,1.28,178.57],[2,1.23,217.39]],"ltp":2.86,"tv":83.09,"id":60971786}]}]}
{"op":"mcm","clk":"11932339930","pt":1724741200050,"mc":[{"id":"1.232260815","rc":[{"batb":[[0,1.54,5],[1,1.53,10.26],[2,1.5,81.63]],"ltp":1.54,"tv":136.36,"id":60971788},{"batb":[[0,2.72,5],[1,2.7,24],[2,1.28,178.57]],"ltp":2.86,"tv":83.09,"id":60971786}]}]}
{"op":"mcm","clk":"11932340090","pt":1724741203391,"mc":[{"id":"1.232260815","rc":[{"batb":[[0,1.53,10.26],[1,1.5,81.63],[2,1.28,178.57]],"ltp":1.54,"tv":136.36,"id":60971788},{"batb":[[0,2.7,24],[1,1.28,178.57],[2,1.23,217.39]],"ltp":2.86,"tv":83.09,"id":60971786}]}]}
{"op":"mcm","clk":"11932340238","pt":1724741206481,"mc":[{"id":"1.232260815","rc":[{"batb":[[0,1.54,5],[1,1.53,10.26],[2,1.5,81.63]],"ltp":1.54,"tv":136.36,"id":60971788},{"batb":[[0,2.72,5],[1,2.7,24],[2,1.28,178.57]],"ltp":2.86,"tv":83.09,"id":60971786}]}]}
{"op":"mcm","clk":"11932340363","pt":1724741209691,"mc":[{"id":"1.232260815","rc":[{"batb":[[0,1.53,10.26],[1,1.5,81.63],[2,1.28,178.57]],"ltp":1.54,"tv":136.36,"id":60971788},{"batb":[[0,2.7,24],[1,1.28,178.57],[2,1.23,217.39]],"ltp":2.86,"tv":83.09,"id":60971786}]}]}
{"op":"mcm","clk":"11932340504","pt":1724741212713,"mc":[{"id":"1.232260815","rc":[{"batb":[[0,1.54,5],[1,1.53,10.26],[2,1.5,81.63]],"ltp":1.54,"tv":136.36,"id":60971788},{"batb":[[0,2.72,5],[1,2.7,24],[2,1.28,178.57]],"ltp":2.86,"tv":83.09,"id":60971786}]}]}
{"op":"mcm","clk":"11932340664","pt":1724741216108,"mc":[{"id":"1.232260815","rc":[{"batb":[[0,1.53,10.26],[1,1.5,81.63],[2,1.28,178.57]],"ltp":1.54,"tv":136.36,"id":60971788},{"batb":[[0,2.7,24],[1,1.28,178.57],[2,1.23,217.39]],"ltp":2.86,"tv":83.09,"id":60971786}]}]}
{"op":"mcm","clk":"11932340789","pt":1724741218426,"mc":[{"id":"1.232260815","rc":[{"batb":[[0,1.54,5],[1,1.53,10.26],[2,1.5,81.63]],"ltp":1.54,"tv":136.36,"id":60971788},{"batb":[[0,2.72,5],[1,2.7,24],[2,1.28,178.57]],"ltp":2.86,"tv":83.09,"id":60971786}]}]}
{"op":"mcm","clk":"11932340932","pt":1724741221824,"mc":[{"id":"1.232260815","rc":[{"batb":[[0,1.53,10.26],[1,1.5,81.63],[2,1.28,178.57]],"ltp":1.54,"tv":136.36,"id":60971788},{"batb":[[0,2.7,24],[1,1.28,178.57],[2,1.23,217.39]],"ltp":2.86,"tv":83.09,"id":60971786}]}]}
{"op":"mcm","clk":"11932341017","pt":1724741224189,"mc":[{"id":"1.232260815","rc":[{"batb":[[0,1.54,5],[1,1.53,10.26],[2,1.5,81.63]],"ltp":1.54,"tv":136.36,"id":60971788},{"batb":[[0,2.72,5],[1,2.7,24],[2,1.28,178.57]],"ltp":2.86,"tv":83.09,"id":60971786}]}]}
{"op":"mcm","clk":"11932341142","pt":1724741226821,"mc":[{"id":"1.232260815","rc":[{"trd":[[1.53,4.38],[1.54,123.7]],"batb":[[0,1.53,5.88],[1,1.5,81.63],[2,1.28,178.57]],"ltp":1.53,"tv":145.74,"id":60971788},{"trd":[[2.86,65.56],[2.9,2.31]],"ltp":2.9,"tv":88.09,"id":60971786}],"tv":233.84}]}
{"op":"mcm","clk":"11932341185","pt":1724741227497,"mc":[{"id":"1.232260815","rc":[{"batb":[[0,2.7,24],[1,1.28,178.57],[2,1.23,217.39]],"ltp":2.9,"tv":88.09,"id":60971786}]}]}
{"op":"mcm","clk":"11932341276","pt":1724741229802,"mc":[{"id":"1.232260815","rc":[{"batb":[[0,1.54,5],[1,1.53,5.88],[2,1.5,81.63]],"ltp":1.53,"tv":145.74,"id":60971788},{"batb":[[0,2.72,5],[1,2.7,24],[2,1.28,178.57]],"ltp":2.9,"tv":88.09,"id":60971786}]}]}
{"op":"mcm","clk":"11932341433","pt":1724741233127,"mc":[{"id":"1.232260815","rc":[{"trd":[[1.53,10.26],[1.54,128.7]],"batb":[[0,1.5,81.63],[1,1.28,178.57],[2,1.23,217.39]],"ltp":1.53,"tv":156.62,"id":60971788},{"trd":[[2.86,68.25],[2.9,5.41]],"batb":[[0,2.9,4.21]],"ltp":2.9,"tv":93.88,"id":60971786}],"tv":250.51}]}
{"op":"mcm","clk":"11932341530","pt":1724741235551,"mc":[{"id":"1.232260815","rc":[{"batb":[[0,1.51,5],[1,1.5,81.63],[2,1.28,178.57]],"ltp":1.53,"tv":156.62,"id":60971788},{"batb":[[0,2.92,5],[1,2.9,4.21],[2,2.7,24]],"ltp":2.9,"tv":93.88,"id":60971786}]}]}
{"op":"mcm","clk":"11932341615","pt":1724741237622,"mc":[{"id":"1.232260815","rc":[{"batb":[[1,1.28,178.57],[2,1.23,217.39]],"ltp":1.53,"tv":156.62,"id":60971788},{"batb":[[2,1.28,178.57]],"ltp":2.9,"tv":93.88,"id":60971786}]}]}
{"op":"mcm","clk":"11932341678","pt":1724741239217,"mc":[{"id":"1.232260815","rc":[{"batb":[[0,1.31,143.33]],"ltp":1.53,"tv":156.62,"id":60971788},{"batb":[[0,2.9,4.21],[1,1.28,178.57],[2,1.23,217.39]],"ltp":2.9,"tv":93.88,"id":60971786}]}]}
{"op":"mcm","clk":"11932341804","pt":1724741242249,"mc":[{"id":"1.232260815","rc":[{"batb":[[0,1.32,5],[1,1.31,143.33],[2,1.28,178.57]],"ltp":1.53,"tv":156.62,"id":60971788},{"batb":[[0,2.92,5]],"ltp":2.9,"tv":93.88,"id":60971786}]}]}
{"op":"mcm","clk":"11932341826","pt":1724741242513,"mc":[{"id":"1.232260815","rc":[{"trd":[[1.5,8.42]],"batb":[[0,1.5,73.21],[1,1.32,5],[2,1.31,143.33]],"ltp":1.5,"tv":165.04,"id":60971788},{"trd":[[3,4.21]],"batb":[[1,2.7,24],[2,1.28,178.57]],"ltp":3.0,"tv":98.09,"id":60971786}],"tv":263.14}]}
{"op":"mcm","clk":"11932341906","pt":1724741244822,"mc":[{"id":"1.232260815","rc":[{"batb":[[1,1.31,143.33],[2,1.28,178.57]],"ltp":1.5,"tv":165.04,"id":60971788},{"batb":[[0,2.7,24],[1,1.28,178.57],[2,1.23,217.39]],"ltp":3.0,"tv":98.09,"id":60971786}]}]}
{"op":"mcm","clk":"11932342004","pt":1724741247238,"mc":[{"id":"1.232260815","rc":[{"batb":[[0,1.51,5],[1,1.5,73.21],[2,1.31,143.33]],"ltp":1.5,"tv":165.04,"id":60971788},{"batb":[[0,2.72,5],[1,2.7,24],[2,1.28,178.57]],"ltp":3.0,"tv":98.09,"id":60971786}]}]}
{"op":"mcm","clk":"11932342023","pt":1724741247545,"mc":[{"id":"1.232260815","rc":[{"batb":[[1,1.5,81.63]],"ltp":1.5,"tv":165.04,"id":60971788}]}]}
{"op":"mcm","clk":"11932342147","pt":1724741250527,"mc":[{"id":"1.232260815","rc":[{"batb":[[0,1.5,81.63],[1,1.31,143.33],[2,1.28,178.57]],"ltp":1.5,"tv":165.04,"id":60971788},{"batb":[[0,2.7,24],[1,1.28,178.57],[2,1.23,217.39]],"ltp":3.0,"tv":98.09,"id":60971786}]}]}
{"op":"mcm","clk":"11932342270","pt":1724741254222,"mc":[{"id":"1.232260815","rc":[{"trd":[[1.5,75.36],[1.51,5]],"batb":[[0,1.5,14.69],[1,1.28,178.57],[2,1.23,217.39]],"ltp":1.5,"tv":236.98,"id":60971788},{"trd":[[2.98,2.53],[3,37.68]],"batb":[[0,2.72,5],[1,2.7,24],[2,1.28,178.57]],"ltp":3.0,"tv":134.09,"id":60971786}],"tv":371.08}]}
{"op":"mcm","clk":"11932342377","pt":1724741257143,"mc":[{"id":"1.232260815","rc":[{"batb":[[0,1.51,5],[1,1.5,14.69],[2,1.28,178.57]],"ltp":1.5,"tv":236.98,"id":60971788},{"batb":[[0,2.7,24],[1,1.28,178.57],[2,1.23,217.39]],"ltp":3.0,"tv":134.09,"id":60971786}]}]}
{"op":"mcm","clk":"11932342393","pt":1724741257687,"mc":[{"id":"1.232260815","rc":[{"batb":[[1,1.28,178.57],[2,1.23,217.39]],"ltp":1.5,"tv":236.98,"id":60971788}]}]}
{"op":"mcm","clk":"11932342492","pt":1724741260277,"mc":[{"id":"1.232260815","rc":[{"batb":[[0,1.28,178.57],[1,1.23,217.39],[2,1.18,277.78]],"ltp":1.5,"tv":236.98,"id":60971788},{"batb":[[0,2.72,5],[1,2.7,24],[2,1.28,178.57]],"ltp":3.0,"tv":134.09,"id":60971786}]}]}
{"op":"mcm","clk":"11932342500","pt":1724741260471,"mc":[{"id":"1.232260815","rc":[{"batb":[[0,1.3,144.45],[1,1.28,178.57],[2,1.23,217.39]],"ltp":1.5,"tv":236.98,"id":60971788}]}]}
{"op":"mcm","clk":"11932342582","pt":1724741262052,"mc":[{"id":"1.232260815","rc":[{"batb":[[0,2.86,11.19],[1,2.72,5],[2,2.7,24]],"ltp":3.0,"tv":134.09,"id":60971786}]}]}
{"op":"mcm","clk":"11932342642","pt":1724741263237,"mc":[{"id":"1.232260815","rc":[{"batb":[[1,2.7,24],[2,1.28,178.57]],"ltp":3.0,"tv":134.09,"id":60971786}]}]}
{"op":"mcm","clk":"11932342647","pt":1724741263437,"mc":[{"id":"1.232260815","rc":[{"batb":[[0,1.31,5],[1,1.3,144.45],[2,1.28,178.57]],"ltp":1.5,"tv":236.98,"id":60971788}]}]}
{"op":"mcm","clk":"11932342753","pt":1724741265757,"mc":[{"id":"1.232260815","rc":[{"batb":[[0,2.88,5],[1,2.86,11.19],[2,2.7,24]],"ltp":3.0,"tv":134.09,"id":60971786}]}]}
{"op":"mcm","clk":"11932342800","pt":1724741266740,"mc":[{"id":"1.232260815","rc":[{"batb":[[0,1.3,144.45],[1,1.28,178.57],[2,1.23,217.39]],"ltp":1.5,"tv":236.98,"id":60971788},{"batb":[[0,2.98,11],[1,2.88,5],[2,2.86,11.19]],"ltp":3.0,"tv":134.09,"id":60971786}]}]}
{"op":"mcm","clk":"11932342904","pt":1724741269059,"mc":[{"id":"1.232260815","rc":[{"batb":[[0,1.31,5],[1,1.3,144.45],[2,1.28,178.57]],"ltp":1.5,"tv":236.98,"id":60971788},{"batb":[[1,2.86,11.19],[2,2.7,24]],"ltp":3.0,"tv":134.09,"id":60971786}]}]}
{"op":"mcm","clk":"11932343076","pt":1724741272284,"mc":[{"id":"1.232260815","rc":[{"batb":[[0,1.3,144.45],[1,1.28,178.57],[2,1.23,217.39]],"ltp":1.5,"tv":236.98,"id":60971788},{"batb":[[0,3,5],[1,2.98,11]],"ltp":3.0,"tv":134.09,"id":60971786}]}]}
{"op":"mcm","clk":"11932343192","pt":1724741274686,"mc":[{"id":"1.232260815","rc":[{"batb":[[0,1.31,5],[1,1.3,144.45],[2,1.28,178.57]],"ltp":1.5,"tv":236.98,"id":60971788},{"batb":[[0,2.98,11],[1,2.7,24],[2,1.28,178.57]],"ltp":3.0,"tv":134.09,"id":60971786}]}]}
{"op":"mcm","clk":"11932343300","pt":1724741277094,"mc":[{"id":"1.232260815","rc":[{"batb":[[0,3,5],[1,2.98,11],[2,2.7,24]],"ltp":3.0,"tv":134.09,"id":60971786}]}]}
{"op":"mcm","clk":"11932343370","pt":1724741277965,"mc":[{"id":"1.232260815","rc":[{"batb":[[0,1.3,144.45],[1,1.28,178.57],[2,1.23,217.39]],"ltp":1.5,"tv":236.98,"id":60971788}]}]}
{"op":"mcm","clk":"11932343412","pt":1724741278878,"mc":[{"id":"1.232260815","rc":[{"batb":[[0,3,16],[1,2.7,24],[2,1.28,178.57]],"ltp":3.0,"tv":134.09,"id":60971786}]}]}
{"op":"mcm","clk":"11932343499","pt":1724741280572,"mc":[{"id":"1.232260815","rc":[{"batb":[[0,1.31,5],[1,1.3,144.45],[2,1.28,178.57]],"ltp":1.5,"tv":236.98,"id":60971788},{"batb":[[0,3,11]],"ltp":3.0,"tv":134.09,"id":60971786}]}]}
{"op":"mcm","clk":"11932343635","pt":1724741283848,"mc":[{"id":"1.232260815","rc":[{"batb":[[0,1.3,144.45],[1,1.28,178.57],[2,1.23,217.39]],"ltp":1.5,"tv":236.98,"id":60971788},{"batb":[[0,3.05,5],[1,3,11],[2,2.7,24]],"ltp":3.0,"tv":134.09,"id":60971786}]}]}
{"op":"mcm","clk":"11932343764","pt":1724741286873,"mc":[{"id":"1.232260815","rc":[{"batb":[[0,1.31,5],[1,1.3,144.45],[2,1.28,178.57]],"ltp":1.5,"tv":236.98,"id":60971788},{"batb":[[0,3,11],[1,2.7,24],[2,1.28,178.57]],"ltp":3.0,"tv":134.09,"id":60971786}]}]}
{"op":"mcm","clk":"11932343871","pt":1724741289077,"mc":[{"id":"1.232260815","rc":[{"batb":[[0,3.05,5],[1,3,11],[2,2.7,24]],"ltp":3.0,"tv":134.09,"id":60971786}]}]}
{"op":"mcm","clk":"11932343924","pt":1724741290099,"mc":[{"id":"1.232260815","rc":[{"batb":[[0,1.3,144.45],[1,1.28,178.57],[2,1.23,217.39]],"ltp":1.5,"tv":236.98,"id":60971788}]}]}
{"op":"mcm","clk":"11932344050","pt":1724741292806,"mc":[{"id":"1.232260815","rc":[{"batb":[[0,1.31,5],[1,1.3,144.45],[2,1.28,178.57]],"ltp":1.5,"tv":236.98,"id":60971788},{"batb":[[0,3,11],[1,2.7,24],[2,1.28,178.57]],"ltp":3.0,"tv":134.09,"id":60971786}]}]}
{"op":"mcm","clk":"11932344232","pt":1724741295978,"mc":[{"id":"1.232260815","rc":[{"batb":[[0,1.3,144.45],[1,1.28,178.57],[2,1.23,217.39]],"ltp":1.5,"tv":236.98,"id":60971788},{"batb":[[0,3.05,5],[1,3,11],[2,2.7,24]],"ltp":3.0,"tv":134.09,"id":60971786}]}]}
{"op":"mcm","clk":"11932344258","pt":1724741296695,"mc":[{"id":"1.232260815","rc":[{"batb":[[0,1.33,88.04],[1,1.3,144.45],[2,1.28,178.57]],"ltp":1.5,"tv":236.98,"id":60971788}]}]}
{"op":"mcm","clk":"11932344352","pt":1724741298998,"mc":[{"id":"1.232260815","rc":[{"batb":[[0,1.34,5],[1,1.33,88.04],[2,1.3,144.45]],"ltp":1.5,"tv":236.98,"id":60971788},{"batb":[[0,2.7,24],[1,1.28,178.57],[2,1.23,217.39]],"ltp":3.0,"tv":134.09,"id":60971786}]}]}
{"op":"mcm","clk":"11932344459","pt":1724741301308,"mc":[{"id":"1.232260815","rc":[{"batb":[[0,2.72,5],[1,2.7,24],[2,1.28,178.57]],"ltp":3.0,"tv":134.09,"id":60971786}]}]}
{"op":"mcm","clk":"11932344501","pt":1724741302024,"mc":[{"id":"1.232260815","rc":[{"batb":[[0,1.33,88.04],[1,1.3,144.45],[2,1.28,178.57]],"ltp":1.5,"tv":236.98,"id":60971788}]}]}
{"op":"mcm","clk":"11932344625","pt":1724741304731,"mc":[{"id":"1.232260815","rc":[{"batb":[[0,1.34,5],[1,1.33,88.04],[2,1.3,144.45]],"ltp":1.5,"tv":236.98,"id":60971788},{"batb":[[0,2.7,24],[1,1.28,178.57],[2,1.23,217.39]],"ltp":3.0,"tv":134.09,"id":60971786}]}]}
{"op":"mcm","clk":"11932344732","pt":1724741307299,"mc":[{"id":"1.232260815","rc":[{"batb":[[0,1.36,137.98],[1,1.34,5],[2,1.33,88.04]],"ltp":1.5,"tv":236.98,"id":60971788},{"batb":[[0,2.72,5],[1,2.7,24],[2,1.28,178.57]],"ltp":3.0,"tv":134.09,"id":60971786}]}]}
{"op":"mcm","clk":"11932344757","pt":1724741307915,"mc":[{"id":"1.232260815","rc":[{"batb":[[1,1.33,88.04],[2,1.28,178.57]],"ltp":1.5,"tv":236.98,"id":60971788}]}]}
{"op":"mcm","clk":"11932344873","pt":1724741310221,"mc":[{"id":"1.232260815","rc":[{"batb":[[0,1.37,5],[1,1.36,137.98],[2,1.33,88.04]],"ltp":1.5,"tv":236.98,"id":60971788}]}]}
{"op":"mcm","clk":"11932344912","pt":1724741311038,"mc":[{"id":"1.232260815","rc":[{"batb":[[0,2.7,24],[1,1.28,178.57],[2,1.23,217.39]],"ltp":3.0,"tv":134.09,"id":60971786}]}]}
{"op":"mcm","clk":"11932345012","pt":1724741313702,"mc":[{"id":"1.232260815","rc":[{"batb":[[0,1.36,137.98],[1,1.33,88.04],[2,1.28,178.57]],"ltp":1.5,"tv":236.98,"id":60971788},{"batb":[[0,2.72,5],[1,2.7,24],[2,1.28,178.57]],"ltp":3.0,"tv":134.09,"id":60971786}]}]}
{"op":"mcm","clk":"11932345150","pt":1724741317233,"mc":[{"id":"1.232260815","rc":[{"batb":[[0,1.37,5],[1,1.36,137.98],[2,1.33,88.04]],"ltp":1.5,"tv":236.98,"id":60971788},{"batb":[[0,2.7,24],[1,1.28,178.57],[2,1.23,217.39]],"ltp":3.0,"tv":134.09,"id":60971786}]}]}
{"op":"mcm","clk":"11932345248","pt":1724741319534,"mc":[{"id":"1.232260815","rc":[{"batb":[[0,2.72,5],[1,2.7,24],[2,1.28,178.57]],"ltp":3.0,"tv":134.09,"id":60971786}]}]}
{"op":"mcm","clk":"11932345280","pt":1724741320614,"mc":[{"id":"1.232260815","rc":[{"batb":[[0,1.36,137.98],[1,1.33,88.04],[2,1.28,178.57]],"ltp":1.5,"tv":236.98,"id":60971788}]}]}
{"op":"mcm","clk":"11932345366","pt":1724741322960,"mc":[{"id":"1.232260815","rc":[{"batb":[[0,1.37,5],[1,1.36,137.98],[2,1.33,88.04]],"ltp":1.5,"tv":236.98,"id":60971788},{"batb":[[0,2.7,24],[1,1.28,178.57],[2,1.23,217.39]],"ltp":3.0,"tv":134.09,"id":60971786}]}]}
{"op":"mcm","clk":"11932345408","pt":1724741323735,"mc":[{"id":"1.232260815","rc":[{"batb":[[0,2.72,4],[1,2.7,24],[2,1.28,178.57]],"batl":[[0,3.65,35.21],[1,24,1.52]],"ltp":3.0,"tv":134.09,"id":60971786}]}]}
{"op":"mcm","clk":"11932345510","pt":1724741326134,"mc":[{"id":"1.232260815","rc":[{"batb":[[0,1.36,137.98],[1,1.33,88.04],[2,1.28,178.57]],"ltp":1.5,"tv":236.98,"id":60971788},{"batb":[[0,2.7,24],[1,1.28,178.57],[2,1.23,217.39]],"ltp":3.0,"tv":134.09,"id":60971786}]}]}
{"op":"mcm","clk":"11932345524","pt":1724741326643,"mc":[{"id":"1.232260815","rc":[{"batb":[[0,2.74,5],[1,2.7,24],[2,1.28,178.57]],"ltp":3.0,"tv":134.09,"id":60971786}]}]}
{"op":"mcm","clk":"11932345668","pt":1724741330059,"mc":[{"id":"1.232260815","rc":[{"batb":[[0,1.37,5],[1,1.36,137.98],[2,1.33,88.04]],"ltp":1.5,"tv":236.98,"id":60971788},{"batb":[[0,2.76,4]],"ltp":3.0,"tv":134.09,"id":60971786}]}]}
{"op":"mcm","clk":"11932345729","pt":1724741331645,"mc":[{"id":"1.232260815","rc":[{"batb":[[0,2.7,24],[1,1.28,178.57],[2,1.23,217.39]],"ltp":3.0,"tv":134.09,"id":60971786}]}]}
{"op":"mcm","clk":"11932345768","pt":1724741332770,"mc":[{"id":"1.232260815","rc":[{"batb":[[0,1.36,137.98],[1,1.33,88.04],[2,1.28,178.57]],"ltp":1.5,"tv":236.98,"id":60971788},{"batb":[[0,2.72,5],[1,2.7,24],[2,1.28,178.57]],"ltp":3.0,"tv":134.09,"id":60971786}]}]}
{"op":"mcm","clk":"11932345840","pt":1724741334255,"mc":[{"id":"1.232260815","rc":[{"batb":[[0,1.33,88.04],[1,1.28,178.57],[2,1.23,217.39]],"ltp":1.5,"tv":236.98,"id":60971788},{"batb":[[0,2.74,4],[1,2.72,5],[2,2.7,24]],"batl":[[0,3.4,55.16],[1,3.65,35.21],[2,24,1.52]],"ltp":3.0,"tv":134.09,"id":60971786}]}]}
{"op":"mcm","clk":"11932345924","pt":1724741336148,"mc":[{"id":"1.232260815","rc":[{"batb":[[0,1.34,5],[1,1.33,88.04],[2,1.28,178.57]],"ltp":1.5,"tv":236.98,"id":60971788},{"batb":[[0,2.7,24],[1,1.28,178.57],[2,1.23,217.39]],"ltp":3.0,"tv":134.09,"id":60971786}]}]}
{"op":"mcm","clk":"11932346033","pt":1724741338868,"mc":[{"id":"1.232260815","rc":[{"batb":[[0,1.33,88.04],[1,1.28,178.57],[2,1.23,217.39]],"ltp":1.5,"tv":236.98,"id":60971788},{"batb":[[0,2.72,9],[1,2.7,24],[2,1.28,178.57]],"ltp":3.0,"tv":134.09,"id":60971786}]}]}
{"op":"mcm","clk":"11932346119","pt":1724741340672,"mc":[{"id":"1.232260815","rc":[{"batb":[[0,2.72,5]],"ltp":3.0,"tv":134.09,"id":60971786}]}]}
{"op":"mcm","clk":"11932346187","pt":1724741341862,"mc":[{"id":"1.232260815","rc":[{"batb":[[0,1.34,5],[1,1.33,88.04],[2,1.28,178.57]],"ltp":1.5,"tv":236.98,"id":60971788},{"batb":[[0,2.7,24],[1,1.28,178.57],[2,1.23,217.39]],"ltp":3.0,"tv":134.09,"id":60971786}]}]}
{"op":"mcm","clk":"11932346261","pt":1724741343045,"mc":[{"id":"1.232260815","rc":[{"batb":[[0,2.72,4],[1,2.7,24],[2,1.28,178.57]],"ltp":3.0,"tv":134.09,"id":60971786}]}]}
{"op":"mcm","clk":"11932346319","pt":1724741344170,"mc":[{"id":"1.232260815","rc":[{"batb":[[0,2.74,5],[1,2.72,4],[2,2.7,24]],"ltp":3.0,"tv":134.09,"id":60971786}]}]}
{"op":"mcm","clk":"11932346362","pt":1724741345142,"mc":[{"id":"1.232260815","rc":[{"batb":[[0,1.33,88.04],[1,1.28,178.57],[2,1.23,217.39]],"ltp":1.5,"tv":236.98,"id":60971788}]}]}
{"op":"mcm","clk":"11932346372","pt":1724741345346,"mc":[{"id":"1.232260815","rc":[{"batb":[[1,2.7,24],[2,1.28,178.57]],"ltp":3.0,"tv":134.09,"id":60971786}]}]}
{"op":"mcm","clk":"11932346509","pt":1724741347670,"mc":[{"id":"1.232260815","rc":[{"batb":[[0,1.34,5],[1,1.33,88.04],[2,1.28,178.57]],"ltp":1.5,"tv":236.98,"id":60971788},{"batb":[[0,2.72,4]],"ltp":3.0,"tv":134.09,"id":60971786}]}]}
{"op":"mcm","clk":"11932346646","pt":1724741350185,"mc":[{"id":"1.232260815","rc":[{"batb":[[0,2.72,5]],"ltp":3.0,"tv":134.09,"id":60971786}]}]}
{"op":"mcm","clk":"11932346695","pt":1724741351161,"mc":[{"id":"1.232260815","rc":[{"batb":[[0,1.33,88.04],[1,1.28,178.57],[2,1.23,217.39]],"ltp":1.5,"tv":236.98,"id":60971788}]}]}
{"op":"mcm","clk":"11932346774","pt":1724741352386,"mc":[{"id":"1.232260815","rc":[{"batb":[[0,2.74,4],[1,2.72,5],[2,2.7,24]],"ltp":3.0,"tv":134.09,"id":60971786}]}]}
{"op":"mcm","clk":"11932346828","pt":1724741353467,"mc":[{"id":"1.232260815","rc":[{"batb":[[0,1.34,5],[1,1.33,88.04],[2,1.28,178.57]],"ltp":1.5,"tv":236.98,"id":60971788},{"batb":[[1,2.7,24],[2,1.28,178.57]],"ltp":3.0,"tv":134.09,"id":60971786}]}]}
{"op":"mcm","clk":"11932346882","pt":1724741354788,"mc":[{"id":"1.232260815","rc":[{"batb":[[0,2.7,24],[1,1.28,178.57],[2,1.23,217.39]],"ltp":3.0,"tv":134.09,"id":60971786}]}]}
{"op":"mcm","clk":"11932346942","pt":1724741356075,"mc":[{"id":"1.232260815","rc":[{"batb":[[0,2.72,5],[1,2.7,24],[2,1.28,178.57]],"ltp":3.0,"tv":134.09,"id":60971786}]}]}
{"op":"mcm","clk":"11932346982","pt":1724741356992,"mc":[{"id":"1.232260815","rc":[{"batb":[[0,1.33,88.04],[1,1.28,178.57],[2,1.23,217.39]],"ltp":1.5,"tv":236.98,"id":60971788},{"batb":[[0,2.74,4],[1,2.72,5],[2,2.7,24]],"ltp":3.0,"tv":134.09,"id":60971786}]}]}
{"op":"mcm","clk":"11932347073","pt":1724741359189,"mc":[{"id":"1.232260815","rc":[{"batb":[[0,1.34,5],[1,1.33,88.04],[2,1.28,178.57]],"ltp":1.5,"tv":236.98,"id":60971788}]}]}
{"op":"mcm","clk":"11932347088","pt":1724741359394,"mc":[{"id":"1.232260815","rc":[{"batb":[[0,2.7,24],[1,1.28,178.57],[2,1.23,217.39]],"ltp":3.0,"tv":134.09,"id":60971786}]}]}
{"op":"mcm","clk":"11932347183","pt":1724741361697,"mc":[{"id":"1.232260815","rc":[{"batb":[[0,2.72,9],[1,2.7,24],[2,1.28,178.57]],"ltp":3.0,"tv":134.09,"id":60971786}]}]}
{"op":"mcm","clk":"11932347220","pt":1724741362470,"mc":[{"id":"1.232260815","rc":[{"batb":[[0,1.33,88.04],[1,1.28,178.57],[2,1.23,217.39]],"ltp":1.5,"tv":236.98,"id":60971788}]}]}
{"op":"mcm","clk":"11932347303","pt":1724741364258,"mc":[{"id":"1.232260815","rc":[{"batb":[[0,2.72,5]],"ltp":3.0,"tv":134.09,"id":60971786}]}]}
{"op":"mcm","clk":"11932347349","pt":1724741365180,"mc":[{"id":"1.232260815","rc":[{"batb":[[0,2.7,24],[1,1.28,178.57],[2,1.23,217.39]],"ltp":3.0,"tv":134.09,"id":60971786}]}]}
{"op":"mcm","clk":"11932347364","pt":1724741365387,"mc":[{"id":"1.232260815","rc":[{"batb":[[0,1.34,5],[1,1.33,88.04],[2,1.28,178.57]],"ltp":1.5,"tv":236.98,"id":60971788}]}]}
{"op":"mcm","clk":"11932347435","pt":1724741366668,"mc":[{"id":"1.232260815","rc":[{"batb":[[0,2.72,4],[1,2.7,24],[2,1.28,178.57]],"ltp":3.0,"tv":134.09,"id":60971786}]}]}
{"op":"mcm","clk":"11932347489","pt":1724741367803,"mc":[{"id":"1.232260815","rc":[{"batb":[[0,2.74,5],[1,2.72,4],[2,2.7,24]],"ltp":3.0,"tv":134.09,"id":60971786}]}]}
{"op":"mcm","clk":"11932347544","pt":1724741369185,"mc":[{"id":"1.232260815","rc":[{"batb":[[0,1.33,88.04],[1,1.28,178.57],[2,1.23,217.39]],"ltp":1.5,"tv":236.98,"id":60971788},{"batb":[[1,2.7,24],[2,1.28,178.57]],"ltp":3.0,"tv":134.09,"id":60971786}]}]}
{"op":"mcm","clk":"11932347634","pt":1724741371188,"mc":[{"id":"1.232260815","rc":[{"batb":[[0,1.34,5],[1,1.33,88.04],[2,1.28,178.57]],"ltp":1.5,"tv":236.98,"id":60971788},{"batb":[[0,2.7,24],[1,1.28,178.57],[2,1.23,217.39]],"ltp":3.0,"tv":134.09,"id":60971786}]}]}
{"op":"mcm","clk":"11932347641","pt":1724741371392,"mc":[{"id":"1.232260815","rc":[{"batb":[[0,2.72,4],[1,2.7,24],[2,1.28,178.57]],"ltp":3.0,"tv":134.09,"id":60971786}]}]}
{"op":"mcm","clk":"11932347823","pt":1724741374275,"mc":[{"id":"1.232260815","rc":[{"batb":[[0,1.33,88.04],[1,1.28,178.57],[2,1.23,217.39]],"ltp":1.5,"tv":236.98,"id":60971788},{"batb":[[0,2.72,5]],"ltp":3.0,"tv":134.09,"id":60971786}]}]}
{"op":"mcm","clk":"11932348005","pt":1724741377206,"mc":[{"id":"1.232260815","rc":[{"batb":[[0,1.34,5],[1,1.33,88.04],[2,1.28,178.57]],"ltp":1.5,"tv":236.98,"id":60971788},{"batb":[[0,2.74,4]],"ltp":3.0,"tv":134.09,"id":60971786}]}]}
{"op":"mcm","clk":"11932348135","pt":1724741379510,"mc":[{"id":"1.232260815","rc":[{"batb":[[0,2.76,5]],"ltp":3.0,"tv":134.09,"id":60971786}]}]}
{"op":"mcm","clk":"11932348212","pt":1724741380495,"mc":[{"id":"1.232260815","rc":[{"batb":[[0,1.33,88.04],[1,1.28,178.57],[2,1.23,217.39]],"ltp":1.5,"tv":236.98,"id":60971788}]}]}
{"op":"mcm","clk":"11932348309","pt":1724741381677,"mc":[{"id":"1.232260815","rc":[{"batb":[[0,2.78,4],[1,2.76,5],[2,2.7,24]],"ltp":3.0,"tv":134.09,"id":60971786}]}]}
{"op":"mcm","clk":"11932348404","pt":1724741383020,"mc":[{"id":"1.232260815","rc":[{"batb":[[0,1.34,5],[1,1.33,88.04],[2,1.28,178.57]],"ltp":1.5,"tv":236.98,"id":60971788},{"batb":[[1,2.7,24],[2,1.28,178.57]],"ltp":3.0,"tv":134.09,"id":60971786}]}]}
{"op":"mcm","clk":"11932348464","pt":1724741383897,"mc":[{"id":"1.232260815","rc":[{"batb":[[0,2.7,24],[1,1.28,178.57],[2,1.23,217.39]],"ltp":3.0,"tv":134.09,"id":60971786}]}]}
{"op":"mcm","clk":"11932348611","pt":1724741386201,"mc":[{"id":"1.232260815","rc":[{"batb":[[0,1.33,88.04],[1,1.28,178.57],[2,1.23,217.39]],"ltp":1.5,"tv":236.98,"id":60971788},{"batb":[[0,2.72,9],[1,2.7,24],[2,1.28,178.57]],"ltp":3.0,"tv":134.09,"id":60971786}]}]}
{"op":"mcm","clk":"11932348750","pt":1724741388309,"mc":[{"id":"1.232260815","rc":[{"batb":[[0,1.34,5],[1,1.33,88.04],[2,1.28,178.57]],"ltp":1.5,"tv":236.98,"id":60971788}]}]}
{"op":"mcm","clk":"11932348764","pt":1724741388416,"mc":[{"id":"1.232260815","rc":[{"batb":[[0,2.72,5]],"ltp":3.0,"tv":134.09,"id":60971786}]}]}
{"op":"mcm","clk":"11932348870","pt":1724741389602,"mc":[{"id":"1.232260815","rc":[{"batb":[[0,2.7,24],[1,1.28,178.57],[2,1.23,217.39]],"ltp":3.0,"tv":134.09,"id":60971786}]}]}
{"op":"mcm","clk":"11932348939","pt":1724741390725,"mc":[{"id":"1.232260815","rc":[{"batb":[[0,2.72,4],[1,2.7,24],[2,1.28,178.57]],"ltp":3.0,"tv":134.09,"id":60971786}]}]}
{"op":"mcm","clk":"11932348995","pt":1724741391705,"mc":[{"id":"1.232260815","rc":[{"batb":[[0,1.33,88.04],[1,1.28,178.57],[2,1.23,217.39]],"ltp":1.5,"tv":236.98,"id":60971788},{"batb":[[0,2.74,5],[1,2.72,4],[2,2.7,24]],"ltp":3.0,"tv":134.09,"id":60971786}]}]}
{"op":"mcm","clk":"11932349064","pt":1724741393134,"mc":[{"id":"1.232260815","rc":[{"batb":[[1,2.7,24],[2,1.28,178.57]],"ltp":3.0,"tv":134.09,"id":60971786}]}]}
{"op":"mcm","clk":"11932349175","pt":1724741395232,"mc":[{"id":"1.232260815","rc":[{"batb":[[0,1.34,5],[1,1.33,88.04],[2,1.28,178.57]],"ltp":1.5,"tv":236.98,"id":60971788},{"batb":[[0,2.7,24],[1,1.28,178.57],[2,1.23,217.39]],"ltp":3.0,"tv":134.09,"id":60971786}]}]}
{"op":"mcm","clk":"11932349183","pt":1724741395335,"mc":[{"id":"1.232260815","rc":[{"batb":[[0,2.72,4],[1,2.7,24],[2,1.28,178.57]],"ltp":3.0,"tv":134.09,"id":60971786}]}]}
{"op":"mcm","clk":"11932349315","pt":1724741397743,"mc":[{"id":"1.232260815","rc":[{"batb":[[0,2.74,5]],"ltp":3.0,"tv":134.09,"id":60971786}]}]}
{"op":"mcm","clk":"11932349348","pt":1724741398414,"mc":[{"id":"1.232260815","rc":[{"batb":[[0,1.33,88.04],[1,1.28,178.57],[2,1.23,217.39]],"ltp":1.5,"tv":236.98,"id":60971788}]}]}
{"op":"mcm","clk":"11932349449","pt":1724741399808,"mc":[{"id":"1.232260815","rc":[{"batb":[[0,2.76,4],[1,2.74,5],[2,2.7,24]],"batl":[[1,24,1.52],[2,24,0]],"ltp":3.0,"tv":134.09,"id":60971786}]}]}
{"op":"mcm","clk":"11932349517","pt":1724741401003,"mc":[{"id":"1.232260815","rc":[{"batb":[[0,1.34,5],[1,1.33,88.04],[2,1.28,178.57]],"ltp":1.5,"tv":236.98,"id":60971788},{"batb":[[1,2.7,24],[2,1.28,178.57]],"ltp":3.0,"tv":134.09,"id":60971786}]}]}
{"op":"mcm","clk":"11932349591","pt":1724741402240,"mc":[{"id":"1.232260815","rc":[{"batb":[[0,2.7,24],[1,1.28,178.57],[2,1.23,217.39]],"ltp":3.0,"tv":134.09,"id":60971786}]}]}
{"op":"mcm","clk":"11932349657","pt":1724741403317,"mc":[{"id":"1.232260815","rc":[{"batb":[[0,2.72,5],[1,2.7,24],[2,1.28,178.57]],"ltp":3.0,"tv":134.09,"id":60971786}]}]}
{"op":"mcm","clk":"11932349696","pt":1724741404242,"mc":[{"id":"1.232260815","rc":[{"batb":[[0,1.33,88.04],[1,1.28,178.57],[2,1.23,217.39]],"ltp":1.5,"tv":236.98,"id":60971788}]}]}
{"op":"mcm","clk":"11932349760","pt":1724741405323,"mc":[{"id":"1.232260815","rc":[{"batb":[[0,2.74,4],[1,2.72,5],[2,2.7,24]],"ltp":3.0,"tv":134.09,"id":60971786}]}]}
{"op":"mcm","clk":"11932349846","pt":1724741406810,"mc":[{"id":"1.232260815","rc":[{"batb":[[0,1.34,5],[1,1.33,88.04],[2,1.28,178.57]],"ltp":1.5,"tv":236.98,"id":60971788},{"batb":[[1,2.7,24],[2,1.28,178.57]],"ltp":3.0,"tv":134.09,"id":60971786}]}]}
{"op":"mcm","clk":"11932349874","pt":1724741407630,"mc":[{"id":"1.232260815","rc":[{"batb":[[0,2.7,24],[1,1.28,178.57],[2,1.23,217.39]],"ltp":3.0,"tv":134.09,"id":60971786}]}]}
{"op":"mcm","clk":"11932349997","pt":1724741410031,"mc":[{"id":"1.232260815","rc":[{"batb":[[0,1.33,88.04],[1,1.28,178.57],[2,1.23,217.39]],"ltp":1.5,"tv":236.98,"id":60971788},{"batb":[[0,2.72,9],[1,2.7,24],[2,1.28,178.57]],"ltp":3.0,"tv":134.09,"id":60971786}]}]}
{"op":"mcm","clk":"11932350104","pt":1724741412133,"mc":[{"id":"1.232260815","rc":[{"batb":[[0,1.34,5],[1,1.33,88.04],[2,1.28,178.57]],"ltp":1.5,"tv":236.98,"id":60971788}]}]}
{"op":"mcm","clk":"11932350113","pt":1724741412335,"mc":[{"id":"1.232260815","rc":[{"batb":[[0,2.72,5]],"ltp":3.0,"tv":134.09,"id":60971786}]}]}
{"op":"mcm","clk":"11932350172","pt":1724741413358,"mc":[{"id":"1.232260815","rc":[{"batb":[[0,2.7,24],[1,1.28,178.57],[2,1.23,217.39]],"ltp":3.0,"tv":134.09,"id":60971786}]}]}
{"op":"mcm","clk":"11932350306","pt":1724741415625,"mc":[{"id":"1.232260815","rc":[{"batb":[[0,1.33,88.04],[1,1.28,178.57],[2,1.23,217.39]],"ltp":1.5,"tv":236.98,"id":60971788},{"batb":[[0,2.72,9],[1,2.7,24],[2,1.28,178.57]],"ltp":3.0,"tv":134.09,"id":60971786}]}]}
{"op":"mcm","clk":"11932350411","pt":1724741417946,"mc":[{"id":"1.232260815","rc":[{"batb":[[0,1.34,5],[1,1.33,88.04],[2,1.28,178.57]],"ltp":1.5,"tv":236.98,"id":60971788},{"batb":[[0,2.72,5]],"ltp":3.0,"tv":134.09,"id":60971786}]}]}
{"op":"mcm","clk":"11932350447","pt":1724741418863,"mc":[{"id":"1.232260815","rc":[{"batb":[[0,2.7,24],[1,1.28,178.57],[2,1.23,217.39]],"ltp":3.0,"tv":134.09,"id":60971786}]}]}
{"op":"mcm","clk":"11932350555","pt":1724741421220,"mc":[{"id":"1.232260815","rc":[{"batb":[[0,1.33,88.04],[1,1.28,178.57],[2,1.23,217.39]],"ltp":1.5,"tv":236.98,"id":60971788},{"batb":[[0,2.74,5],[1,2.72,4],[2,2.7,24]],"ltp":3.0,"tv":134.09,"id":60971786}]}]}
{"op":"mcm","clk":"11932350629","pt":1724741422751,"mc":[{"id":"1.232260815","rc":[{"batb":[[1,2.7,24],[2,1.28,178.57]],"ltp":3.0,"tv":134.09,"id":60971786}]}]}
{"op":"mcm","clk":"11932350721","pt":1724741425062,"mc":[{"id":"1.232260815","rc":[{"batb":[[0,1.34,5],[1,1.33,88.04],[2,1.28,178.57]],"ltp":1.5,"tv":236.98,"id":60971788},{"batb":[[0,2.72,4]],"ltp":3.0,"tv":134.09,"id":60971786}]}]}
{"op":"mcm","clk":"11932350859","pt":1724741428237,"mc":[{"id":"1.232260815","rc":[{"batb":[[0,1.33,88.04],[1,1.28,178.57],[2,1.23,217.39]],"ltp":1.5,"tv":236.98,"id":60971788},{"batb":[[0,2.72,5]],"ltp":3.0,"tv":134.09,"id":60971786}]}]}
{"op":"mcm","clk":"11932350982","pt":1724741430756,"mc":[{"id":"1.232260815","rc":[{"batb":[[0,1.34,5],[1,1.33,88.04],[2,1.28,178.57]],"ltp":1.5,"tv":236.98,"id":60971788},{"batb":[[0,2.74,4]],"ltp":3.0,"tv":134.09,"id":60971786}]}]}
{"op":"mcm","clk":"11932351084","pt":1724741432933,"mc":[{"id":"1.232260815","rc":[{"batb":[[0,2.72,5]],"ltp":3.0,"tv":134.09,"id":60971786}]}]}
{"op":"mcm","clk":"11932351140","pt":1724741433858,"mc":[{"id":"1.232260815","rc":[{"batb":[[0,1.33,88.04],[1,1.28,178.57],[2,1.23,217.39]],"ltp":1.5,"tv":236.98,"id":60971788}]}]}
{"op":"mcm","clk":"11932351197","pt":1724741435038,"mc":[{"id":"1.232260815","rc":[{"batb":[[0,2.74,4],[1,2.72,5],[2,2.7,24]],"ltp":3.0,"tv":134.09,"id":60971786}]}]}
{"op":"mcm","clk":"11932351262","pt":1724741436162,"mc":[{"id":"1.232260815","rc":[{"batb":[[1,2.7,24],[2,1.28,178.57]],"ltp":3.0,"tv":134.09,"id":60971786}]}]}
{"op":"mcm","clk":"11932351313","pt":1724741437080,"mc":[{"id":"1.232260815","rc":[{"batb":[[0,1.34,5],[1,1.33,88.04],[2,1.28,178.57]],"ltp":1.5,"tv":236.98,"id":60971788}]}]}
{"op":"mcm","clk":"11932351329","pt":1724741437341,"mc":[{"id":"1.232260815","rc":[{"batb":[[0,2.7,24],[1,1.28,178.57],[2,1.23,217.39]],"ltp":3.0,"tv":134.09,"id":60971786}]}]}
{"op":"mcm","clk":"11932351409","pt":1724741438980,"mc":[{"id":"1.232260815","rc":[{"batb":[[0,2.72,5],[1,2.7,24],[2,1.28,178.57]],"ltp":3.0,"tv":134.09,"id":60971786}]}]}
{"op":"mcm","clk":"11932351503","pt":1724741440673,"mc":[{"id":"1.232260815","rc":[{"batb":[[0,1.33,88.04],[1,1.28,178.57],[2,1.23,217.39]],"ltp":1.5,"tv":236.98,"id":60971788},{"batb":[[0,2.74,4],[1,2.72,5],[2,2.7,24]],"ltp":3.0,"tv":134.09,"id":60971786}]}]}
{"op":"mcm","clk":"11932351579","pt":1724741442259,"mc":[{"id":"1.232260815","rc":[{"batb":[[1,2.7,24],[2,1.28,178.57]],"ltp":3.0,"tv":134.09,"id":60971786}]}]}
{"op":"mcm","clk":"11932351626","pt":1724741443084,"mc":[{"id":"1.232260815","rc":[{"batb":[[0,1.34,5],[1,1.33,88.04],[2,1.28,178.57]],"ltp":1.5,"tv":236.98,"id":60971788},{"batb":[[0,2.7,24],[1,1.28,178.57],[2,1.23,217.39]],"ltp":3.0,"tv":134.09,"id":60971786}]}]}
{"op":"mcm","clk":"11932351729","pt":1724741445087,"mc":[{"id":"1.232260815","rc":[{"batb":[[0,2.74,4],[1,2.72,5],[2,2.7,24]],"ltp":3.0,"tv":134.09,"id":60971786}]}]}
{"op":"mcm","clk":"11932351797","pt":1724741446273,"mc":[{"id":"1.232260815","rc":[{"batb":[[0,1.33,88.04],[1,1.28,178.57],[2,1.23,217.39]],"ltp":1.5,"tv":236.98,"id":60971788}]}]}
{"op":"mcm","clk":"11932351888","pt":1724741448169,"mc":[{"id":"1.232260815","rc":[{"batb":[[0,2.7,24],[1,1.28,178.57],[2,1.23,217.39]],"ltp":3.0,"tv":134.09,"id":60971786}]}]}
{"op":"mcm","clk":"11932351937","pt":1724741449392,"mc":[{"id":"1.232260815","rc":[{"batb":[[0,1.34,5],[1,1.33,88.04],[2,1.28,178.57]],"ltp":1.5,"tv":236.98,"id":60971788}]}]}
{"op":"mcm","clk":"11932351990","pt":1724741450476,"mc":[{"id":"1.232260815","rc":[{"batb":[[0,2.72,9],[1,2.7,24],[2,1.28,178.57]],"ltp":3.0,"tv":134.09,"id":60971786}]}]}
{"op":"mcm","clk":"11932352098","pt":1724741452676,"mc":[{"id":"1.232260815","rc":[{"batb":[[0,1.33,88.04],[1,1.28,178.57],[2,1.23,217.39]],"ltp":1.5,"tv":236.98,"id":60971788},{"batb":[[0,2.72,5]],"ltp":3.0,"tv":134.09,"id":60971786}]}]}
{"op":"mcm","clk":"11932352156","pt":1724741453867,"mc":[{"id":"1.232260815","rc":[{"batb":[[0,2.7,24],[1,1.28,178.57],[2,1.23,217.39]],"ltp":3.0,"tv":134.09,"id":60971786}]}]}
{"op":"mcm","clk":"11932352213","pt":1724741455090,"mc":[{"id":"1.232260815","rc":[{"batb":[[0,1.34,5],[1,1.33,88.04],[2,1.28,178.57]],"ltp":1.5,"tv":236.98,"id":60971788},{"batb":[[0,2.72,4],[1,2.7,24],[2,1.28,178.57]],"ltp":3.0,"tv":134.09,"id":60971786}]}]}
{"op":"mcm","clk":"11932352266","pt":1724741456167,"mc":[{"id":"1.232260815","rc":[{"batb":[[0,2.74,5],[1,2.72,4],[2,2.7,24]],"ltp":3.0,"tv":134.09,"id":60971786}]}]}
{"op":"mcm","clk":"11932352330","pt":1724741457393,"mc":[{"id":"1.232260815","rc":[{"batb":[[1,2.7,24],[2,1.28,178.57]],"ltp":3.0,"tv":134.09,"id":60971786}]}]}
{"op":"mcm","clk":"11932352393","pt":1724741458471,"mc":[{"id":"1.232260815","rc":[{"batb":[[0,1.33,88.04],[1,1.28,178.57],[2,1.23,217.39]],"ltp":1.5,"tv":236.98,"id":60971788}]}]}
{"op":"mcm","clk":"11932352448","pt":1724741459595,"mc":[{"id":"1.232260815","rc":[{"batb":[[0,2.72,4]],"ltp":3.0,"tv":134.09,"id":60971786}]}]}
{"op":"mcm","clk":"11932352494","pt":1724741460671,"mc":[{"id":"1.232260815","rc":[{"batb":[[0,1.34,5],[1,1.33,88.04],[2,1.28,178.57]],"ltp":1.5,"tv":236.98,"id":60971788}]}]}
{"op":"mcm","clk":"11932352539","pt":1724741461757,"mc":[{"id":"1.232260815","rc":[{"batb":[[0,2.74,5]],"ltp":3.0,"tv":134.09,"id":60971786}]}]}
{"op":"mcm","clk":"11932352630","pt":1724741463956,"mc":[{"id":"1.232260815","rc":[{"batb":[[0,1.33,88.04],[1,1.28,178.57],[2,1.23,217.39]],"ltp":1.5,"tv":236.98,"id":60971788},{"batb":[[0,2.76,4],[1,2.74,5],[2,2.7,24]],"ltp":3.0,"tv":134.09,"id":60971786}]}]}
{"op":"mcm","clk":"11932352684","pt":1724741464979,"mc":[{"id":"1.232260815","rc":[{"batb":[[1,2.7,24],[2,1.28,178.57]],"ltp":3.0,"tv":134.09,"id":60971786}]}]}
{"op":"mcm","clk":"11932352734","pt":1724741466205,"mc":[{"id":"1.232260815","rc":[{"batb":[[0,1.34,5],[1,1.33,88.04],[2,1.28,178.57]],"ltp":1.5,"tv":236.98,"id":60971788},{"batb":[[0,2.7,24],[1,1.28,178.57],[2,1.23,217.39]],"ltp":3.0,"tv":134.09,"id":60971786}]}]}
{"op":"mcm","clk":"11932352817","pt":1724741467901,"mc":[{"id":"1.232260815","rc":[{"batb":[[0,2.72,5],[1,2.7,24],[2,1.28,178.57]],"ltp":3.0,"tv":134.09,"id":60971786}]}]}
{"op":"mcm","clk":"11932352884","pt":1724741469078,"mc":[{"id":"1.232260815","rc":[{"batb":[[0,2.74,4],[1,2.72,5],[2,2.7,24]],"ltp":3.0,"tv":134.09,"id":60971786}]}]}
{"op":"mcm","clk":"11932352901","pt":1724741469385,"mc":[{"id":"1.232260815","rc":[{"batb":[[0,1.33,88.04],[1,1.28,178.57],[2,1.23,217.39]],"ltp":1.5,"tv":236.98,"id":60971788}]}]}
{"op":"mcm","clk":"11932352987","pt":1724741471271,"mc":[{"id":"1.232260815","rc":[{"batb":[[1,2.7,24],[2,1.28,178.57]],"ltp":3.0,"tv":134.09,"id":60971786}]}]}
{"op":"mcm","clk":"11932353002","pt":1724741471578,"mc":[{"id":"1.232260815","rc":[{"batb":[[0,1.34,5],[1,1.33,88.04],[2,1.28,178.57]],"ltp":1.5,"tv":236.98,"id":60971788},{"batb":[[0,2.7,24],[1,1.28,178.57],[2,1.23,217.39]],"ltp":3.0,"tv":134.09,"id":60971786}]}]}
{"op":"mcm","clk":"11932353120","pt":1724741473779,"mc":[{"id":"1.232260815","rc":[{"batb":[[0,2.72,9],[1,2.7,24],[2,1.28,178.57]],"ltp":3.0,"tv":134.09,"id":60971786}]}]}
{"op":"mcm","clk":"11932353180","pt":1724741475001,"mc":[{"id":"1.232260815","rc":[{"batb":[[0,1.33,88.04],[1,1.28,178.57],[2,1.23,217.39]],"ltp":1.5,"tv":236.98,"id":60971788}]}]}
{"op":"mcm","clk":"11932353237","pt":1724741475982,"mc":[{"id":"1.232260815","rc":[{"batb":[[0,2.72,5]],"ltp":3.0,"tv":134.09,"id":60971786}]}]}
{"op":"mcm","clk":"11932353280","pt":1724741477062,"mc":[{"id":"1.232260815","rc":[{"batb":[[0,1.34,5],[1,1.33,88.04],[2,1.28,178.57]],"ltp":1.5,"tv":236.98,"id":60971788},{"batb":[[0,2.7,24],[1,1.28,178.57],[2,1.23,217.39]],"ltp":3.0,"tv":134.09,"id":60971786}]}]}
{"op":"mcm","clk":"11932353366","pt":1724741478802,"mc":[{"id":"1.232260815","rc":[{"batb":[[0,2.72,4],[1,2.7,24],[2,1.28,178.57]],"ltp":3.0,"tv":134.09,"id":60971786}]}]}
{"op":"mcm","clk":"11932353456","pt":1724741480287,"mc":[{"id":"1.232260815","rc":[{"batb":[[0,1.33,88.04],[1,1.28,178.57],[2,1.23,217.39]],"ltp":1.5,"tv":236.98,"id":60971788},{"batb":[[0,2.74,5],[1,2.72,4],[2,2.7,24]],"ltp":3.0,"tv":134.09,"id":60971786}]}]}
{"op":"mcm","clk":"11932353510","pt":1724741481309,"mc":[{"id":"1.232260815","rc":[{"batb":[[1,2.7,24],[2,1.28,178.57]],"ltp":3.0,"tv":134.09,"id":60971786}]}]}
{"op":"mcm","clk":"11932353630","pt":1724741483206,"mc":[{"id":"1.232260815","rc":[{"batb":[[0,1.34,5],[1,1.33,88.04],[2,1.28,178.57]],"ltp":1.5,"tv":236.98,"id":60971788},{"batb":[[0,2.7,24],[1,1.28,178.57],[2,1.23,217.39]],"ltp":3.0,"tv":134.09,"id":60971786}]}]}
{"op":"mcm","clk":"11932353693","pt":1724741484395,"mc":[{"id":"1.232260815","rc":[{"batb":[[0,2.72,4],[1,2.7,24],[2,1.28,178.57]],"ltp":3.0,"tv":134.09,"id":60971786}]}]}
{"op":"mcm","clk":"11932353750","pt":1724741485617,"mc":[{"id":"1.232260815","rc":[{"batb":[[0,1.33,88.04],[1,1.28,178.57],[2,1.23,217.39]],"ltp":1.5,"tv":236.98,"id":60971788},{"batb":[[0,2.74,5],[1,2.72,4],[2,2.7,24]],"ltp":3.0,"tv":134.09,"id":60971786}]}]}
{"op":"mcm","clk":"11932353806","pt":1724741486587,"mc":[{"id":"1.232260815","rc":[{"batb":[[1,2.7,24],[2,1.28,178.57]],"ltp":3.0,"tv":134.09,"id":60971786}]}]}
{"op":"mcm","clk":"11932353863","pt":1724741487711,"mc":[{"id":"1.232260815","rc":[{"batb":[[0,1.34,5],[1,1.33,88.04],[2,1.28,178.57]],"ltp":1.5,"tv":236.98,"id":60971788}]}]}
{"op":"mcm","clk":"11932353920","pt":1724741488896,"mc":[{"id":"1.232260815","rc":[{"batb":[[0,2.76,4]],"ltp":3.0,"tv":134.09,"id":60971786}]}]}
{"op":"mcm","clk":"11932354015","pt":1724741490988,"mc":[{"id":"1.232260815","rc":[{"batb":[[0,1.33,88.04],[1,1.28,178.57],[2,1.23,217.39]],"ltp":1.5,"tv":236.98,"id":60971788},{"batb":[[0,2.78,5]],"ltp":3.0,"tv":134.09,"id":60971786}]}]}
{"op":"mcm","clk":"11932354136","pt":1724741493335,"mc":[{"id":"1.232260815","rc":[{"batb":[[0,1.34,5],[1,1.33,88.04],[2,1.28,178.57]],"ltp":1.5,"tv":236.98,"id":60971788},{"batb":[[0,2.8,4],[1,2.78,5],[2,2.7,24]],"ltp":3.0,"tv":134.09,"id":60971786}]}]}
{"op":"mcm","clk":"11932354184","pt":1724741494412,"mc":[{"id":"1.232260815","rc":[{"batb":[[1,2.7,24],[2,1.28,178.57]],"ltp":3.0,"tv":134.09,"id":60971786}]}]}
{"op":"mcm","clk":"11932354236","pt":1724741495532,"mc":[{"id":"1.232260815","rc":[{"batb":[[0,2.7,24],[1,1.28,178.57],[2,1.23,217.39]],"ltp":3.0,"tv":134.09,"id":60971786}]}]}
{"op":"mcm","clk":"11932354292","pt":1724741496707,"mc":[{"id":"1.232260815","rc":[{"batb":[[0,1.33,88.04],[1,1.28,178.57],[2,1.23,217.39]],"ltp":1.5,"tv":236.98,"id":60971788},{"batb":[[0,2.72,5],[1,2.7,24],[2,1.28,178.57]],"ltp":3.0,"tv":134.09,"id":60971786}]}]}
{"op":"mcm","clk":"11932354330","pt":1724741497836,"mc":[{"id":"1.232260815","rc":[{"batb":[[0,2.74,4],[1,2.72,5],[2,2.7,24]],"ltp":3.0,"tv":134.09,"id":60971786}]}]}
{"op":"mcm","clk":"11932354378","pt":1724741499013,"mc":[{"id":"1.232260815","rc":[{"batb":[[0,1.34,5],[1,1.33,88.04],[2,1.28,178.57]],"ltp":1.5,"tv":236.98,"id":60971788}]}]}
{"op":"mcm","clk":"11932354432","pt":1724741500133,"mc":[{"id":"1.232260815","rc":[{"batb":[[0,2.7,24],[1,1.28,178.57],[2,1.23,217.39]],"ltp":3.0,"tv":134.09,"id":60971786}]}]}
{"op":"mcm","clk":"11932354531","pt":1724741502240,"mc":[{"id":"1.232260815","rc":[{"batb":[[0,1.33,88.04],[1,1.28,178.57],[2,1.23,217.39]],"ltp":1.5,"tv":236.98,"id":60971788}]}]}
{"op":"mcm","clk":"11932354536","pt":1724741502341,"mc":[{"id":"1.232260815","rc":[{"batb":[[0,2.72,9],[1,2.7,24],[2,1.28,178.57]],"ltp":3.0,"tv":134.09,"id":60971786}]}]}
{"op":"mcm","clk":"11932354644","pt":1724741504602,"mc":[{"id":"1.232260815","rc":[{"batb":[[0,1.34,5],[1,1.33,88.04],[2,1.28,178.57]],"ltp":1.5,"tv":236.98,"id":60971788},{"batb":[[0,2.72,5]],"ltp":3.0,"tv":134.09,"id":60971786}]}]}
{"op":"mcm","clk":"11932354699","pt":1724741505634,"mc":[{"id":"1.232260815","rc":[{"batb":[[0,2.7,24],[1,1.28,178.57],[2,1.23,217.39]],"ltp":3.0,"tv":134.09,"id":60971786}]}]}
{"op":"mcm","clk":"11932354773","pt":1724741506811,"mc":[{"id":"1.232260815","rc":[{"batb":[[0,2.72,4],[1,2.7,24],[2,1.28,178.57]],"ltp":3.0,"tv":134.09,"id":60971786}]}]}
{"op":"mcm","clk":"11932354837","pt":1724741508043,"mc":[{"id":"1.232260815","rc":[{"batb":[[0,1.33,88.04],[1,1.28,178.57],[2,1.23,217.39]],"ltp":1.5,"tv":236.98,"id":60971788},{"batb":[[0,2.74,5],[1,2.72,4],[2,2.7,24]],"ltp":3.0,"tv":134.09,"id":60971786}]}]}
{"op":"mcm","clk":"11932354891","pt":1724741509320,"mc":[{"id":"1.232260815","rc":[{"batb":[[1,2.7,24],[2,1.28,178.57]],"ltp":3.0,"tv":134.09,"id":60971786}]}]}
{"op":"mcm","clk":"11932354960","pt":1724741511316,"mc":[{"id":"1.232260815","rc":[{"batb":[[0,1.34,5],[1,1.33,88.04],[2,1.28,178.57]],"ltp":1.5,"tv":236.98,"id":60971788},{"batb":[[0,2.7,24],[1,1.28,178.57],[2,1.23,217.39]],"ltp":3.0,"tv":134.09,"id":60971786}]}]}
{"op":"mcm","clk":"11932354964","pt":1724741511417,"mc":[{"id":"1.232260815","rc":[{"batb":[[0,2.72,4],[1,2.7,24],[2,1.28,178.57]],"ltp":3.0,"tv":134.09,"id":60971786}]}]}
{"op":"mcm","clk":"11932355067","pt":1724741513822,"mc":[{"id":"1.232260815","rc":[{"batb":[[0,1.33,88.04],[1,1.28,178.57],[2,1.23,217.39]],"ltp":1.5,"tv":236.98,"id":60971788},{"batb":[[0,2.74,5]],"ltp":3.0,"tv":134.09,"id":60971786}]}]}
{"op":"mcm","clk":"11932355168","pt":1724741516316,"mc":[{"id":"1.232260815","rc":[{"batb":[[0,1.34,5],[1,1.33,88.04],[2,1.28,178.57]],"ltp":1.5,"tv":236.98,"id":60971788},{"batb":[[0,2.76,4],[1,2.74,5],[2,2.7,24]],"ltp":3.0,"tv":134.09,"id":60971786}]}]}
{"op":"mcm","clk":"11932355182","pt":1724741516825,"mc":[{"id":"1.232260815","rc":[{"batb":[[1,2.7,24],[2,1.28,178.57]],"ltp":3.0,"tv":134.09,"id":60971786}]}]}
{"op":"mcm","clk":"11932355280","pt":1724741518830,"mc":[{"id":"1.232260815","rc":[{"batb":[[0,2.7,24],[1,1.28,178.57],[2,1.23,217.39]],"ltp":3.0,"tv":134.09,"id":60971786}]}]}
{"op":"mcm","clk":"11932355307","pt":1724741519643,"mc":[{"id":"1.232260815","rc":[{"batb":[[0,1.33,88.04],[1,1.28,178.57],[2,1.23,217.39]],"ltp":1.5,"tv":236.98,"id":60971788},{"batb":[[0,2.72,5],[1,2.7,24],[2,1.28,178.57]],"ltp":3.0,"tv":134.09,"id":60971786}]}]}
{"op":"mcm","clk":"11932355445","pt":1724741522933,"mc":[{"id":"1.232260815","rc":[{"batb":[[0,1.34,5],[1,1.33,88.04],[2,1.28,178.57]],"ltp":1.5,"tv":236.98,"id":60971788},{"batb":[[0,2.74,4]],"ltp":3.0,"tv":134.09,"id":60971786}]}]}
{"op":"mcm","clk":"11932355543","pt":1724741525241,"mc":[{"id":"1.232260815","rc":[{"batb":[[0,2.72,5]],"ltp":3.0,"tv":134.09,"id":60971786}]}]}
{"op":"mcm","clk":"11932355582","pt":1724741526160,"mc":[{"id":"1.232260815","rc":[{"batb":[[0,1.33,88.04],[1,1.28,178.57],[2,1.23,217.39]],"ltp":1.5,"tv":236.98,"id":60971788}]}]}
{"op":"mcm","clk":"11932355630","pt":1724741527341,"mc":[{"id":"1.232260815","rc":[{"batb":[[0,2.74,4],[1,2.72,5],[2,2.7,24]],"ltp":3.0,"tv":134.09,"id":60971786}]}]}
{"op":"mcm","clk":"11932355687","pt":1724741528566,"mc":[{"id":"1.232260815","rc":[{"batb":[[0,1.34,5],[1,1.33,88.04],[2,1.28,178.57]],"ltp":1.5,"tv":236.98,"id":60971788},{"batb":[[1,2.7,24],[2,1.28,178.57]],"ltp":3.0,"tv":134.09,"id":60971786}]}]}
{"op":"mcm","clk":"11932355746","pt":1724741529745,"mc":[{"id":"1.232260815","rc":[{"batb":[[0,2.7,24],[1,1.28,178.57],[2,1.23,217.39]],"ltp":3.0,"tv":134.09,"id":60971786}]}]}
{"op":"mcm","clk":"11932355844","pt":1724741531842,"mc":[{"id":"1.232260815","rc":[{"batb":[[0,1.33,88.04],[1,1.28,178.57],[2,1.23,217.39]],"ltp":1.5,"tv":236.98,"id":60971788},{"batb":[[0,2.74,4],[1,2.72,5],[2,2.7,24]],"ltp":3.0,"tv":134.09,"id":60971786}]}]}
{"op":"mcm","clk":"11932355968","pt":1724741534148,"mc":[{"id":"1.232260815","rc":[{"batb":[[0,1.34,5],[1,1.33,88.04],[2,1.28,178.57]],"ltp":1.5,"tv":236.98,"id":60971788},{"batb":[[0,2.72,5],[1,2.7,24],[2,1.28,178.57]],"ltp":3.0,"tv":134.09,"id":60971786}]}]}
{"op":"mcm","clk":"11932356010","pt":1724741535069,"mc":[{"id":"1.232260815","rc":[{"batb":[[0,2.7,24],[1,1.28,178.57],[2,1.23,217.39]],"ltp":3.0,"tv":134.09,"id":60971786}]}]}
{"op":"mcm","clk":"11932356122","pt":1724741537576,"mc":[{"id":"1.232260815","rc":[{"batb":[[0,1.33,88.04],[1,1.28,178.57],[2,1.23,217.39]],"ltp":1.5,"tv":236.98,"id":60971788},{"batb":[[0,2.72,9],[1,2.7,24],[2,1.28,178.57]],"ltp":3.0,"tv":134.09,"id":60971786}]}]}
{"op":"mcm","clk":"11932356219","pt":1724741540080,"mc":[{"id":"1.232260815","rc":[{"batb":[[0,1.34,5],[1,1.33,88.04],[2,1.28,178.57]],"ltp":1.5,"tv":236.98,"id":60971788},{"batb":[[0,2.72,5]],"ltp":3.0,"tv":134.09,"id":60971786}]}]}
{"op":"mcm","clk":"11932356252","pt":1724741540850,"mc":[{"id":"1.232260815","rc":[{"batb":[[0,2.7,24],[1,1.28,178.57],[2,1.23,217.39]],"ltp":3.0,"tv":134.09,"id":60971786}]}]}
{"op":"mcm","clk":"11932356350","pt":1724741543269,"mc":[{"id":"1.232260815","rc":[{"batb":[[0,1.33,88.04],[1,1.28,178.57],[2,1.23,217.39]],"ltp":1.5,"tv":236.98,"id":60971788}]}]}
{"op":"mcm","clk":"11932356364","pt":1724741543475,"mc":[{"id":"1.232260815","rc":[{"batb":[[0,2.72,9],[1,2.7,24],[2,1.28,178.57]],"ltp":3.0,"tv":134.09,"id":60971786}]}]}
{"op":"mcm","clk":"11932356491","pt":1724741545771,"mc":[{"id":"1.232260815","rc":[{"batb":[[0,1.34,5],[1,1.33,88.04],[2,1.28,178.57]],"ltp":1.5,"tv":236.98,"id":60971788},{"batb":[[0,2.72,5]],"ltp":3.0,"tv":134.09,"id":60971786}]}]}
{"op":"mcm","clk":"11932356528","pt":1724741546642,"mc":[{"id":"1.232260815","rc":[{"batb":[[0,2.7,24],[1,1.28,178.57],[2,1.23,217.39]],"ltp":3.0,"tv":134.09,"id":60971786}]}]}
{"op":"mcm","clk":"11932356619","pt":1724741548940,"mc":[{"id":"1.232260815","rc":[{"batb":[[0,1.33,88.04],[1,1.28,178.57],[2,1.23,217.39]],"ltp":1.5,"tv":236.98,"id":60971788},{"batb":[[0,2.74,5],[1,2.72,4],[2,2.7,24]],"ltp":3.0,"tv":134.09,"id":60971786}]}]}
{"op":"mcm","clk":"11932356709","pt":1724741551594,"mc":[{"id":"1.232260815","rc":[{"batb":[[0,1.34,5],[1,1.33,88.04],[2,1.28,178.57]],"ltp":1.5,"tv":236.98,"id":60971788},{"batb":[[1,2.7,24],[2,1.28,178.57]],"ltp":3.0,"tv":134.09,"id":60971786}]}]}
{"op":"mcm","clk":"11932356740","pt":1724741552359,"mc":[{"id":"1.232260815","rc":[{"batb":[[0,2.7,24],[1,1.28,178.57],[2,1.23,217.39]],"ltp":3.0,"tv":134.09,"id":60971786}]}]}
{"op":"mcm","clk":"11932356830","pt":1724741554968,"mc":[{"id":"1.232260815","rc":[{"batb":[[0,1.33,88.04],[1,1.28,178.57],[2,1.23,217.39]],"ltp":1.5,"tv":236.98,"id":60971788},{"batb":[[0,2.74,5],[1,2.72,4],[2,2.7,24]],"ltp":3.0,"tv":134.09,"id":60971786}]}]}
{"op":"mcm","clk":"11932356919","pt":1724741556756,"mc":[{"id":"1.232260815","rc":[{"batb":[[1,2.7,24],[2,1.28,178.57]],"ltp":3.0,"tv":134.09,"id":60971786}]}]}
{"op":"mcm","clk":"11932356983","pt":1724741557987,"mc":[{"id":"1.232260815","rc":[{"batb":[[0,1.34,5],[1,1.33,88.04],[2,1.28,178.57]],"ltp":1.5,"tv":236.98,"id":60971788},{"batb":[[0,2.7,24],[1,1.28,178.57],[2,1.23,217.39]],"ltp":3.0,"tv":134.09,"id":60971786}]}]}
{"op":"mcm","clk":"11932357078","pt":1724741559870,"mc":[{"id":"1.232260815","rc":[{"batb":[[0,2.72,4],[1,2.7,24],[2,1.28,178.57]],"ltp":3.0,"tv":134.09,"id":60971786}]}]}
{"op":"mcm","clk":"11932357136","pt":1724741561153,"mc":[{"id":"1.232260815","rc":[{"batb":[[0,1.33,88.04],[1,1.28,178.57],[2,1.23,217.39]],"ltp":1.5,"tv":236.98,"id":60971788},{"batb":[[0,2.74,5],[1,2.72,4],[2,2.7,24]],"ltp":3.0,"tv":134.09,"id":60971786}]}]}
{"op":"mcm","clk":"11932357216","pt":1724741562950,"mc":[{"id":"1.232260815","rc":[{"batb":[[1,2.7,24],[2,1.28,178.57]],"ltp":3.0,"tv":134.09,"id":60971786}]}]}
{"op":"mcm","clk":"11932357271","pt":1724741564583,"mc":[{"id":"1.232260815","rc":[{"batb":[[0,1.34,5],[1,1.33,88.04],[2,1.28,178.57]],"ltp":1.5,"tv":236.98,"id":60971788},{"batb":[[0,2.7,24],[1,1.28,178.57],[2,1.23,217.39]],"ltp":3.0,"tv":134.09,"id":60971786}]}]}
{"op":"mcm","clk":"11932357333","pt":1724741565871,"mc":[{"id":"1.232260815","rc":[{"batb":[[0,2.72,4],[1,2.7,24],[2,1.28,178.57]],"ltp":3.0,"tv":134.09,"id":60971786}]}]}
{"op":"mcm","clk":"11932357372","pt":1724741567096,"mc":[{"id":"1.232260815","rc":[{"batb":[[0,2.74,5],[1,2.72,4],[2,2.7,24]],"ltp":3.0,"tv":134.09,"id":60971786}]}]}
{"op":"mcm","clk":"11932357420","pt":1724741568170,"mc":[{"id":"1.232260815","rc":[{"batb":[[0,1.33,88.04],[1,1.28,178.57],[2,1.23,217.39]],"ltp":1.5,"tv":236.98,"id":60971788},{"batb":[[1,2.7,24],[2,1.28,178.57]],"ltp":3.0,"tv":134.09,"id":60971786}]}]}
{"op":"mcm","clk":"11932357490","pt":1724741570311,"mc":[{"id":"1.232260815","rc":[{"batb":[[0,2.7,24],[1,1.28,178.57],[2,1.23,217.39]],"ltp":3.0,"tv":134.09,"id":60971786}]}]}
{"op":"mcm","clk":"11932357501","pt":1724741570516,"mc":[{"id":"1.232260815","rc":[{"batb":[[0,1.34,5],[1,1.33,88.04],[2,1.28,178.57]],"ltp":1.5,"tv":236.98,"id":60971788},{"batb":[[0,2.72,4],[1,2.7,24],[2,1.28,178.57]],"ltp":3.0,"tv":134.09,"id":60971786}]}]}
{"op":"mcm","clk":"11932357603","pt":1724741572767,"mc":[{"id":"1.232260815","rc":[{"batb":[[0,2.74,5]],"ltp":3.0,"tv":134.09,"id":60971786}]}]}
{"op":"mcm","clk":"11932357641","pt":1724741573686,"mc":[{"id":"1.232260815","rc":[{"batb":[[0,1.33,88.04],[1,1.28,178.57],[2,1.23,217.39]],"ltp":1.5,"tv":236.98,"id":60971788}]}]}
{"op":"mcm","clk":"11932357701","pt":1724741575168,"mc":[{"id":"1.232260815","rc":[{"batb":[[0,2.76,4],[1,2.74,5],[2,2.7,24]],"ltp":3.0,"tv":134.09,"id":60971786}]}]}
{"op":"mcm","clk":"11932357741","pt":1724741576190,"mc":[{"id":"1.232260815","rc":[{"batb":[[0,1.34,5],[1,1.33,88.04],[2,1.28,178.57]],"ltp":1.5,"tv":236.98,"id":60971788},{"batb":[[1,2.7,24],[2,1.28,178.57]],"ltp":3.0,"tv":134.09,"id":60971786}]}]}
{"op":"mcm","clk":"11932357780","pt":1724741577415,"mc":[{"id":"1.232260815","rc":[{"batb":[[0,2.7,24],[1,1.28,178.57],[2,1.23,217.39]],"ltp":3.0,"tv":134.09,"id":60971786}]}]}
{"op":"mcm","clk":"11932357825","pt":1724741578591,"mc":[{"id":"1.232260815","rc":[{"batb":[[0,2.72,5],[1,2.7,24],[2,1.28,178.57]],"ltp":3.0,"tv":134.09,"id":60971786}]}]}
{"op":"mcm","clk":"11932357863","pt":1724741579710,"mc":[{"id":"1.232260815","rc":[{"batb":[[0,1.33,88.04],[1,1.28,178.57],[2,1.23,217.39]],"ltp":1.5,"tv":236.98,"id":60971788},{"batb":[[0,2.74,4],[1,2.72,5],[2,2.7,24]],"ltp":3.0,"tv":134.09,"id":60971786}]}]}
{"op":"mcm","clk":"11932357938","pt":1724741581914,"mc":[{"id":"1.232260815","rc":[{"batb":[[0,1.34,5],[1,1.33,88.04],[2,1.28,178.57]],"ltp":1.5,"tv":236.98,"id":60971788},{"batb":[[0,2.7,24],[1,1.28,178.57],[2,1.23,217.39]],"ltp":3.0,"tv":134.09,"id":60971786}]}]}
{"op":"mcm","clk":"11932358046","pt":1724741584222,"mc":[{"id":"1.232260815","rc":[{"batb":[[0,2.72,9],[1,2.7,24],[2,1.28,178.57]],"ltp":3.0,"tv":134.09,"id":60971786}]}]}
{"op":"mcm","clk":"11932358087","pt":1724741585097,"mc":[{"id":"1.232260815","rc":[{"batb":[[0,1.33,88.04],[1,1.28,178.57],[2,1.23,217.39]],"ltp":1.5,"tv":236.98,"id":60971788}]}]}
{"op":"mcm","clk":"11932358146","pt":1724741586381,"mc":[{"id":"1.232260815","rc":[{"batb":[[0,2.72,5]],"ltp":3.0,"tv":134.09,"id":60971786}]}]}
{"op":"mcm","clk":"11932358214","pt":1724741587826,"mc":[{"id":"1.232260815","rc":[{"batb":[[0,1.34,5],[1,1.33,88.04],[2,1.28,178.57]],"ltp":1.5,"tv":236.98,"id":60971788},{"batb":[[0,2.7,24],[1,1.28,178.57],[2,1.23,217.39]],"ltp":3.0,"tv":134.09,"id":60971786}]}]}
{"op":"mcm","clk":"11932358278","pt":1724741589003,"mc":[{"id":"1.232260815","rc":[{"batb":[[0,2.72,4],[1,2.7,24],[2,1.28,178.57]],"ltp":3.0,"tv":134.09,"id":60971786}]}]}
{"op":"mcm","clk":"11932358385","pt":1724741591203,"mc":[{"id":"1.232260815","rc":[{"batb":[[0,1.33,88.04],[1,1.28,178.57],[2,1.23,217.39]],"ltp":1.5,"tv":236.98,"id":60971788},{"batb":[[0,2.7,24],[1,1.28,178.57],[2,1.23,217.39]],"ltp":3.0,"tv":134.09,"id":60971786}]}]}
{"op":"mcm","clk":"11932358393","pt":1724741591408,"mc":[{"id":"1.232260815","rc":[{"batb":[[0,2.74,5],[1,2.7,24],[2,1.28,178.57]],"ltp":3.0,"tv":134.09,"id":60971786}]}]}
{"op":"mcm","clk":"11932358511","pt":1724741593619,"mc":[{"id":"1.232260815","rc":[{"batb":[[0,1.34,5],[1,1.33,88.04],[2,1.28,178.57]],"ltp":1.5,"tv":236.98,"id":60971788},{"batb":[[0,2.76,4],[1,2.74,5],[2,2.7,24]],"ltp":3.0,"tv":134.09,"id":60971786}]}]}
{"op":"mcm","clk":"11932358576","pt":1724741594739,"mc":[{"id":"1.232260815","rc":[{"batb":[[1,2.7,24],[2,1.28,178.57]],"ltp":3.0,"tv":134.09,"id":60971786}]}]}
{"op":"mcm","clk":"11932358627","pt":1724741595920,"mc":[{"id":"1.232260815","rc":[{"batb":[[0,2.7,24],[1,1.28,178.57],[2,1.23,217.39]],"ltp":3.0,"tv":134.09,"id":60971786}]}]}
{"op":"mcm","clk":"11932358669","pt":1724741596939,"mc":[{"id":"1.232260815","rc":[{"batb":[[0,1.33,88.04],[1,1.28,178.57],[2,1.23,217.39]],"ltp":1.5,"tv":236.98,"id":60971788},{"batb":[[0,2.72,5],[1,2.7,24],[2,1.28,178.57]],"ltp":3.0,"tv":134.09,"id":60971786}]}]}
{"op":"mcm","clk":"11932358716","pt":1724741598012,"mc":[{"id":"1.232260815","rc":[{"batb":[[0,2.74,4],[1,2.72,5],[2,2.7,24]],"ltp":3.0,"tv":134.09,"id":60971786}]}]}
{"op":"mcm","clk":"11932358765","pt":1724741599243,"mc":[{"id":"1.232260815","rc":[{"batb":[[0,1.34,5],[1,1.33,88.04],[2,1.28,178.57]],"ltp":1.5,"tv":236.98,"id":60971788}]}]}
{"op":"mcm","clk":"11932358837","pt":1724741600321,"mc":[{"id":"1.232260815","rc":[{"batb":[[0,2.7,24],[1,1.28,178.57],[2,1.23,217.39]],"ltp":3.0,"tv":134.09,"id":60971786}]}]}
{"op":"mcm","clk":"11932358972","pt":1724741602730,"mc":[{"id":"1.232260815","rc":[{"batb":[[0,1.33,88.04],[1,1.28,178.57],[2,1.23,217.39]],"ltp":1.5,"tv":236.98,"id":60971788},{"batb":[[0,2.72,9],[1,2.7,24],[2,1.28,178.57]],"ltp":3.0,"tv":134.09,"id":60971786}]}]}
{"op":"mcm","clk":"11932359081","pt":1724741605030,"mc":[{"id":"1.232260815","rc":[{"batb":[[0,1.34,5],[1,1.33,88.04],[2,1.28,178.57]],"ltp":1.5,"tv":236.98,"id":60971788},{"batb":[[0,2.72,5]],"ltp":3.0,"tv":134.09,"id":60971786}]}]}
{"op":"mcm","clk":"11932359122","pt":1724741605901,"mc":[{"id":"1.232260815","rc":[{"batb":[[0,2.7,24],[1,1.28,178.57],[2,1.23,217.39]],"ltp":3.0,"tv":134.09,"id":60971786}]}]}
{"op":"mcm","clk":"11932359208","pt":1724741608004,"mc":[{"id":"1.232260815","rc":[{"batb":[[0,1.33,88.04],[1,1.28,178.57],[2,1.23,217.39]],"ltp":1.5,"tv":236.98,"id":60971788}]}]}
{"op":"mcm","clk":"11932359254","pt":1724741608826,"mc":[{"id":"1.232260815","rc":[{"batb":[[0,2.72,9],[1,2.7,24],[2,1.28,178.57]],"ltp":3.0,"tv":134.09,"id":60971786}]}]}
{"op":"mcm","clk":"11932359360","pt":1724741611135,"mc":[{"id":"1.232260815","rc":[{"batb":[[0,1.34,5],[1,1.33,88.04],[2,1.28,178.57]],"ltp":1.5,"tv":236.98,"id":60971788},{"batb":[[0,2.72,5]],"ltp":3.0,"tv":134.09,"id":60971786}]}]}
{"op":"mcm","clk":"11932359416","pt":1724741612017,"mc":[{"id":"1.232260815","rc":[{"batb":[[0,2.7,24],[1,1.28,178.57],[2,1.23,217.39]],"ltp":3.0,"tv":134.09,"id":60971786}]}]}
{"op":"mcm","clk":"11932359508","pt":1724741614320,"mc":[{"id":"1.232260815","rc":[{"batb":[[0,1.33,88.04],[1,1.28,178.57],[2,1.23,217.39]],"ltp":1.5,"tv":236.98,"id":60971788},{"batb":[[0,2.72,9],[1,2.7,24],[2,1.28,178.57]],"ltp":3.0,"tv":134.09,"id":60971786}]}]}
{"op":"mcm","clk":"11932359623","pt":1724741616721,"mc":[{"id":"1.232260815","rc":[{"batb":[[0,1.34,5],[1,1.33,88.04],[2,1.28,178.57]],"ltp":1.5,"tv":236.98,"id":60971788},{"batb":[[0,2.72,5]],"ltp":3.0,"tv":134.09,"id":60971786}]}]}
{"op":"mcm","clk":"11932359656","pt":1724741617648,"mc":[{"id":"1.232260815","rc":[{"batb":[[0,2.7,24],[1,1.28,178.57],[2,1.23,217.39]],"ltp":3.0,"tv":134.09,"id":60971786}]}]}
{"op":"mcm","clk":"11932359706","pt":1724741618821,"mc":[{"id":"1.232260815","rc":[{"batb":[[0,2.72,4],[1,2.7,24],[2,1.28,178.57]],"ltp":3.0,"tv":134.09,"id":60971786}]}]}
{"op":"mcm","clk":"11932359768","pt":1724741620052,"mc":[{"id":"1.232260815","rc":[{"batb":[[0,1.33,88.04],[1,1.28,178.57],[2,1.23,217.39]],"ltp":1.5,"tv":236.98,"id":60971788},{"batb":[[0,2.74,5],[1,2.72,4],[2,2.7,24]],"ltp":3.0,"tv":134.09,"id":60971786}]}]}
{"op":"mcm","clk":"11932359815","pt":1724741621229,"mc":[{"id":"1.232260815","rc":[{"batb":[[1,2.7,24],[2,1.28,178.57]],"ltp":3.0,"tv":134.09,"id":60971786}]}]}
{"op":"mcm","clk":"11932359904","pt":1724741623225,"mc":[{"id":"1.232260815","rc":[{"batb":[[0,1.34,5],[1,1.33,88.04],[2,1.28,178.57]],"ltp":1.5,"tv":236.98,"id":60971788},{"batb":[[0,2.7,24],[1,1.28,178.57],[2,1.23,217.39]],"ltp":3.0,"tv":134.09,"id":60971786}]}]}
{"op":"mcm","clk":"11932359961","pt":1724741624351,"mc":[{"id":"1.232260815","rc":[{"batb":[[0,2.72,4],[1,2.7,24],[2,1.28,178.57]],"ltp":3.0,"tv":134.09,"id":60971786}]}]}
{"op":"mcm","clk":"11932360030","pt":1724741625939,"mc":[{"id":"1.232260815","rc":[{"batb":[[0,2.74,5],[1,2.72,4],[2,2.7,24]],"ltp":3.0,"tv":134.09,"id":60971786}]}]}
{"op":"mcm","clk":"11932360059","pt":1724741626552,"mc":[{"id":"1.232260815","rc":[{"batb":[[0,1.33,88.04],[1,1.28,178.57],[2,1.23,217.39]],"ltp":1.5,"tv":236.98,"id":60971788},{"batb":[[1,2.7,24],[2,1.28,178.57]],"ltp":3.0,"tv":134.09,"id":60971786}]}]}
{"op":"mcm","clk":"11932360165","pt":1724741629065,"mc":[{"id":"1.232260815","rc":[{"batb":[[0,1.34,5],[1,1.33,88.04],[2,1.28,178.57]],"ltp":1.5,"tv":236.98,"id":60971788},{"batb":[[0,2.76,4],[1,2.74,5],[2,2.7,24]],"ltp":3.0,"tv":134.09,"id":60971786}]}]}
{"op":"mcm","clk":"11932360207","pt":1724741630245,"mc":[{"id":"1.232260815","rc":[{"batb":[[1,2.7,24],[2,1.28,178.57]],"ltp":3.0,"tv":134.09,"id":60971786}]}]}
{"op":"mcm","clk":"11932360239","pt":1724741631375,"mc":[{"id":"1.232260815","rc":[{"batb":[[0,2.7,24],[1,1.28,178.57],[2,1.23,217.39]],"ltp":3.0,"tv":134.09,"id":60971786}]}]}
{"op":"mcm","clk":"11932360296","pt":1724741632556,"mc":[{"id":"1.232260815","rc":[{"batb":[[0,1.33,88.04],[1,1.28,178.57],[2,1.23,217.39]],"ltp":1.5,"tv":236.98,"id":60971788},{"batb":[[0,2.72,5],[1,2.7,24],[2,1.28,178.57]],"ltp":3.0,"tv":134.09,"id":60971786}]}]}
{"op":"mcm","clk":"11932360420","pt":1724741634720,"mc":[{"id":"1.232260815","rc":[{"batb":[[0,1.34,5],[1,1.33,88.04],[2,1.28,178.57]],"ltp":1.5,"tv":236.98,"id":60971788},{"batb":[[0,2.74,4],[1,2.72,5],[2,2.7,24]],"ltp":3.0,"tv":134.09,"id":60971786}]}]}
{"op":"mcm","clk":"11932360457","pt":1724741635645,"mc":[{"id":"1.232260815","rc":[{"batb":[[1,2.7,24],[2,1.28,178.57]],"ltp":3.0,"tv":134.09,"id":60971786}]}]}
{"op":"mcm","clk":"11932360518","pt":1724741636923,"mc":[{"id":"1.232260815","rc":[{"batb":[[0,2.7,24],[1,1.28,178.57],[2,1.23,217.39]],"ltp":3.0,"tv":134.09,"id":60971786}]}]}
{"op":"mcm","clk":"11932360580","pt":1724741638151,"mc":[{"id":"1.232260815","rc":[{"batb":[[0,1.33,88.04],[1,1.28,178.57],[2,1.23,217.39]],"ltp":1.5,"tv":236.98,"id":60971788},{"batb":[[0,2.72,5],[1,2.7,24],[2,1.28,178.57]],"ltp":3.0,"tv":134.09,"id":60971786}]}]}
{"op":"mcm","clk":"11932360626","pt":1724741639225,"mc":[{"id":"1.232260815","rc":[{"batb":[[0,2.74,4],[1,2.72,5],[2,2.7,24]],"ltp":3.0,"tv":134.09,"id":60971786}]}]}
{"op":"mcm","clk":"11932360704","pt":1724741641233,"mc":[{"id":"1.232260815","rc":[{"batb":[[1,2.7,24],[2,1.28,178.57]],"ltp":3.0,"tv":134.09,"id":60971786}]}]}
{"op":"mcm","clk":"11932360714","pt":1724741641439,"mc":[{"id":"1.232260815","rc":[{"batb":[[0,1.34,5],[1,1.33,88.04],[2,1.28,178.57]],"ltp":1.5,"tv":236.98,"id":60971788},{"batb":[[0,2.7,24],[1,1.28,178.57],[2,1.23,217.39]],"ltp":3.0,"tv":134.09,"id":60971786}]}]}
{"op":"mcm","clk":"11932360836","pt":1724741643704,"mc":[{"id":"1.232260815","rc":[{"batb":[[0,2.72,9],[1,2.7,24],[2,1.28,178.57]],"ltp":3.0,"tv":134.09,"id":60971786}]}]}
{"op":"mcm","clk":"11932360877","pt":1724741644685,"mc":[{"id":"1.232260815","rc":[{"batb":[[0,1.33,88.04],[1,1.28,178.57],[2,1.23,217.39]],"ltp":1.5,"tv":236.98,"id":60971788}]}]}
{"op":"mcm","clk":"11932360938","pt":1724741646073,"mc":[{"id":"1.232260815","rc":[{"batb":[[0,2.72,5]],"ltp":3.0,"tv":134.09,"id":60971786}]}]}
{"op":"mcm","clk":"11932361001","pt":1724741647196,"mc":[{"id":"1.232260815","rc":[{"batb":[[0,1.34,5],[1,1.33,88.04],[2,1.28,178.57]],"ltp":1.5,"tv":236.98,"id":60971788},{"batb":[[0,2.7,24],[1,1.28,178.57],[2,1.23,217.39]],"ltp":3.0,"tv":134.09,"id":60971786}]}]}
{"op":"mcm","clk":"11932361053","pt":1724741648271,"mc":[{"id":"1.232260815","rc":[{"batb":[[0,2.72,4],[1,2.7,24],[2,1.28,178.57]],"ltp":3.0,"tv":134.09,"id":60971786}]}]}
{"op":"mcm","clk":"11932361103","pt":1724741649394,"mc":[{"id":"1.232260815","rc":[{"batb":[[0,2.74,5],[1,2.72,4],[2,2.7,24]],"ltp":3.0,"tv":134.09,"id":60971786}]}]}
{"op":"mcm","clk":"11932361163","pt":1724741650685,"mc":[{"id":"1.232260815","rc":[{"batb":[[0,1.33,88.04],[1,1.28,178.57],[2,1.23,217.39]],"ltp":1.5,"tv":236.98,"id":60971788},{"batb":[[1,2.7,24],[2,1.28,178.57]],"ltp":3.0,"tv":134.09,"id":60971786}]}]}
{"op":"mcm","clk":"11932361283","pt":1724741652890,"mc":[{"id":"1.232260815","rc":[{"batb":[[0,1.34,5],[1,1.33,88.04],[2,1.28,178.57]],"ltp":1.5,"tv":236.98,"id":60971788},{"batb":[[0,2.76,4]],"ltp":3.0,"tv":134.09,"id":60971786}]}]}
{"op":"mcm","clk":"11932361400","pt":1724741655200,"mc":[{"id":"1.232260815","rc":[{"batb":[[0,2.7,24],[1,1.28,178.57],[2,1.23,217.39]],"ltp":3.0,"tv":134.09,"id":60971786}]}]}
{"op":"mcm","clk":"11932361441","pt":1724741656117,"mc":[{"id":"1.232260815","rc":[{"batb":[[0,1.33,88.04],[1,1.28,178.57],[2,1.23,217.39]],"ltp":1.5,"tv":236.98,"id":60971788},{"batb":[[0,2.72,5],[1,2.7,24],[2,1.28,178.57]],"ltp":3.0,"tv":134.09,"id":60971786}]}]}
{"op":"mcm","clk":"11932361553","pt":1724741658688,"mc":[{"id":"1.232260815","rc":[{"batb":[[0,1.34,5],[1,1.33,88.04],[2,1.28,178.57]],"ltp":1.5,"tv":236.98,"id":60971788},{"batb":[[0,2.72,4]],"ltp":3.0,"tv":134.09,"id":60971786}]}]}
{"op":"mcm","clk":"11932361648","pt":1724741661038,"mc":[{"id":"1.232260815","rc":[{"batb":[[0,2.74,5]],"ltp":3.0,"tv":134.09,"id":60971786}]}]}
{"op":"mcm","clk":"11932361690","pt":1724741661916,"mc":[{"id":"1.232260815","rc":[{"batb":[[0,1.33,88.04],[1,1.28,178.57],[2,1.23,217.39]],"ltp":1.5,"tv":236.98,"id":60971788}]}]}
{"op":"mcm","clk":"11932361790","pt":1724741664317,"mc":[{"id":"1.232260815","rc":[{"batb":[[0,2.7,24],[1,1.28,178.57],[2,1.23,217.39]],"ltp":3.0,"tv":134.09,"id":60971786}]}]}
{"op":"mcm","clk":"11932361794","pt":1724741664418,"mc":[{"id":"1.232260815","rc":[{"batb":[[0,1.34,5],[1,1.33,88.04],[2,1.28,178.57]],"ltp":1.5,"tv":236.98,"id":60971788},{"batb":[[0,2.72,4],[1,2.7,24],[2,1.28,178.57]],"ltp":3.0,"tv":134.09,"id":60971786}]}]}
{"op":"mcm","clk":"11932361884","pt":1724741666819,"mc":[{"id":"1.232260815","rc":[{"batb":[[0,2.74,5]],"ltp":3.0,"tv":134.09,"id":60971786}]}]}
{"op":"mcm","clk":"11932361917","pt":1724741667789,"mc":[{"id":"1.232260815","rc":[{"batb":[[0,1.33,88.04],[1,1.28,178.57],[2,1.23,217.39]],"ltp":1.5,"tv":236.98,"id":60971788}]}]}
{"op":"mcm","clk":"11932362006","pt":1724741670091,"mc":[{"id":"1.232260815","rc":[{"batb":[[0,1.34,5],[1,1.33,88.04],[2,1.28,178.57]],"ltp":1.5,"tv":236.98,"id":60971788},{"batb":[[0,2.76,4]],"ltp":3.0,"tv":134.09,"id":60971786}]}]}
{"op":"mcm","clk":"11932362079","pt":1724741672291,"mc":[{"id":"1.232260815","rc":[{"batb":[[0,2.7,24],[1,1.28,178.57],[2,1.23,217.39]],"ltp":3.0,"tv":134.09,"id":60971786}]}]}
{"op":"mcm","clk":"11932362088","pt":1724741672496,"mc":[{"id":"1.232260815","rc":[{"batb":[[0,2.72,5],[1,2.7,24],[2,1.28,178.57]],"ltp":3.0,"tv":134.09,"id":60971786}]}]}
{"op":"mcm","clk":"11932362124","pt":1724741673520,"mc":[{"id":"1.232260815","rc":[{"batb":[[0,1.33,88.04],[1,1.28,178.57],[2,1.23,217.39]],"ltp":1.5,"tv":236.98,"id":60971788}]}]}
{"op":"mcm","clk":"11932362161","pt":1724741674594,"mc":[{"id":"1.232260815","rc":[{"batb":[[0,2.74,4],[1,2.72,5],[2,2.7,24]],"ltp":3.0,"tv":134.09,"id":60971786}]}]}
{"op":"mcm","clk":"11932362225","pt":1724741675917,"mc":[{"id":"1.232260815","rc":[{"batb":[[0,1.34,5],[1,1.33,88.04],[2,1.28,178.57]],"ltp":1.5,"tv":236.98,"id":60971788},{"batb":[[1,2.7,24],[2,1.28,178.57]],"ltp":3.0,"tv":134.09,"id":60971786}]}]}
{"op":"mcm","clk":"11932362261","pt":1724741676936,"mc":[{"id":"1.232260815","rc":[{"batb":[[0,2.7,24],[1,1.28,178.57],[2,1.23,217.39]],"ltp":3.0,"tv":134.09,"id":60971786}]}]}
{"op":"mcm","clk":"11932362312","pt":1724741678009,"mc":[{"id":"1.232260815","rc":[{"batb":[[0,2.72,5],[1,2.7,24],[2,1.28,178.57]],"ltp":3.0,"tv":134.09,"id":60971786}]}]}
{"op":"mcm","clk":"11932362381","pt":1724741679240,"mc":[{"id":"1.232260815","rc":[{"batb":[[0,1.33,88.04],[1,1.28,178.57],[2,1.23,217.39]],"ltp":1.5,"tv":236.98,"id":60971788},{"batb":[[0,2.74,4],[1,2.72,5],[2,2.7,24]],"ltp":3.0,"tv":134.09,"id":60971786}]}]}
{"op":"mcm","clk":"11932362488","pt":1724741681440,"mc":[{"id":"1.232260815","rc":[{"batb":[[0,1.34,5],[1,1.33,88.04],[2,1.28,178.57]],"ltp":1.5,"tv":236.98,"id":60971788},{"batb":[[0,2.7,24],[1,1.28,178.57],[2,1.23,217.39]],"ltp":3.0,"tv":134.09,"id":60971786}]}]}
{"op":"mcm","clk":"11932362581","pt":1724741684144,"mc":[{"id":"1.232260815","rc":[{"batb":[[0,2.72,9],[1,2.7,24],[2,1.28,178.57]],"ltp":3.0,"tv":134.09,"id":60971786}]}]}
{"op":"mcm","clk":"11932362608","pt":1724741684910,"mc":[{"id":"1.232260815","rc":[{"batb":[[0,1.33,88.04],[1,1.28,178.57],[2,1.23,217.39]],"ltp":1.5,"tv":236.98,"id":60971788}]}]}
{"op":"mcm","clk":"11932362669","pt":1724741686545,"mc":[{"id":"1.232260815","rc":[{"batb":[[0,2.72,5]],"ltp":3.0,"tv":134.09,"id":60971786}]}]}
{"op":"mcm","clk":"11932362721","pt":1724741687616,"mc":[{"id":"1.232260815","rc":[{"batb":[[0,1.34,5],[1,1.33,88.04],[2,1.28,178.57]],"ltp":1.5,"tv":236.98,"id":60971788},{"batb":[[0,2.7,24],[1,1.28,178.57],[2,1.23,217.39]],"ltp":3.0,"tv":134.09,"id":60971786}]}]}
{"op":"mcm","clk":"11932362756","pt":1724741688734,"mc":[{"id":"1.232260815","rc":[{"batb":[[0,2.72,4],[1,2.7,24],[2,1.28,178.57]],"ltp":3.0,"tv":134.09,"id":60971786}]}]}
{"op":"mcm","clk":"11932362791","pt":1724741689909,"mc":[{"id":"1.232260815","rc":[{"batb":[[0,2.74,5],[1,2.72,4],[2,2.7,24]],"ltp":3.0,"tv":134.09,"id":60971786}]}]}
{"op":"mcm","clk":"11932362827","pt":1724741690930,"mc":[{"id":"1.232260815","rc":[{"batb":[[0,1.33,88.04],[1,1.28,178.57],[2,1.23,217.39]],"ltp":1.5,"tv":236.98,"id":60971788},{"batb":[[1,2.7,24],[2,1.28,178.57]],"ltp":3.0,"tv":134.09,"id":60971786}]}]}
{"op":"mcm","clk":"11932362936","pt":1724741693238,"mc":[{"id":"1.232260815","rc":[{"batb":[[0,1.34,5],[1,1.33,88.04],[2,1.28,178.57]],"ltp":1.5,"tv":236.98,"id":60971788},{"batb":[[0,2.76,4]],"ltp":3.0,"tv":134.09,"id":60971786}]}]}
{"op":"mcm","clk":"11932363034","pt":1724741695437,"mc":[{"id":"1.232260815","rc":[{"batb":[[0,2.78,5]],"ltp":3.0,"tv":134.09,"id":60971786}]}]}
{"op":"mcm","clk":"11932363066","pt":1724741696406,"mc":[{"id":"1.232260815","rc":[{"batb":[[0,1.33,88.04],[1,1.28,178.57],[2,1.23,217.39]],"ltp":1.5,"tv":236.98,"id":60971788}]}]}
{"op":"mcm","clk":"11932363106","pt":1724741697536,"mc":[{"id":"1.232260815","rc":[{"batb":[[0,2.8,4],[1,2.78,5],[2,2.7,24]],"ltp":3.0,"tv":134.09,"id":60971786}]}]}
{"op":"mcm","clk":"11932363165","pt":1724741699116,"mc":[{"id":"1.232260815","rc":[{"batb":[[0,1.34,5],[1,1.33,88.04],[2,1.28,178.57]],"ltp":1.5,"tv":236.98,"id":60971788},{"batb":[[1,2.7,24],[2,1.28,178.57]],"ltp":3.0,"tv":134.09,"id":60971786}]}]}
{"op":"mcm","clk":"11932363206","pt":1724741699934,"mc":[{"id":"1.232260815","rc":[{"batb":[[0,2.7,24],[1,1.28,178.57],[2,1.23,217.39]],"ltp":3.0,"tv":134.09,"id":60971786}]}]}
{"op":"mcm","clk":"11932363286","pt":1724741701933,"mc":[{"id":"1.232260815","rc":[{"batb":[[0,2.72,5],[1,2.7,24],[2,1.28,178.57]],"ltp":3.0,"tv":134.09,"id":60971786}]}]}
{"op":"mcm","clk":"11932363310","pt":1724741702551,"mc":[{"id":"1.232260815","rc":[{"batb":[[0,1.33,88.04],[1,1.28,178.57],[2,1.23,217.39]],"ltp":1.5,"tv":236.98,"id":60971788},{"batb":[[0,2.74,4],[1,2.72,5],[2,2.7,24]],"ltp":3.0,"tv":134.09,"id":60971786}]}]}
{"op":"mcm","clk":"11932363407","pt":1724741705260,"mc":[{"id":"1.232260815","rc":[{"batb":[[0,1.34,5],[1,1.33,88.04],[2,1.28,178.57]],"ltp":1.5,"tv":236.98,"id":60971788},{"batb":[[0,2.7,24],[1,1.28,178.57],[2,1.23,217.39]],"ltp":3.0,"tv":134.09,"id":60971786}]}]}
{"op":"mcm","clk":"11932363563","pt":1724741708137,"mc":[{"id":"1.232260815","rc":[{"batb":[[0,1.33,88.04],[1,1.28,178.57],[2,1.23,217.39]],"ltp":1.5,"tv":236.98,"id":60971788},{"batb":[[0,2.72,9],[1,2.7,24],[2,1.28,178.57]],"ltp":3.0,"tv":134.09,"id":60971786}]}]}
{"op":"mcm","clk":"11932363639","pt":1724741710433,"mc":[{"id":"1.232260815","rc":[{"batb":[[0,1.34,5],[1,1.33,88.04],[2,1.28,178.57]],"ltp":1.5,"tv":236.98,"id":60971788},{"batb":[[0,2.72,5]],"ltp":3.0,"tv":134.09,"id":60971786}]}]}
{"op":"mcm","clk":"11932363677","pt":1724741711355,"mc":[{"id":"1.232260815","rc":[{"batb":[[0,2.7,24],[1,1.28,178.57],[2,1.23,217.39]],"ltp":3.0,"tv":134.09,"id":60971786}]}]}
{"op":"mcm","clk":"11932363804","pt":1724741713769,"mc":[{"id":"1.232260815","rc":[{"batb":[[0,1.33,88.04],[1,1.28,178.57],[2,1.23,217.39]],"ltp":1.5,"tv":236.98,"id":60971788},{"batb":[[0,2.72,9],[1,2.7,24],[2,1.28,178.57]],"ltp":3.0,"tv":134.09,"id":60971786}]}]}
{"op":"mcm","clk":"11932363888","pt":1724741716167,"mc":[{"id":"1.232260815","rc":[{"batb":[[0,1.34,5],[1,1.33,88.04],[2,1.28,178.57]],"ltp":1.5,"tv":236.98,"id":60971788},{"batb":[[0,2.72,5]],"ltp":3.0,"tv":134.09,"id":60971786}]}]}
{"op":"mcm","clk":"11932363910","pt":1724741716929,"mc":[{"id":"1.232260815","rc":[{"batb":[[0,2.7,24],[1,1.28,178.57],[2,1.23,217.39]],"ltp":3.0,"tv":134.09,"id":60971786}]}]}
{"op":"mcm","clk":"11932364003","pt":1724741719432,"mc":[{"id":"1.232260815","rc":[{"batb":[[0,1.33,88.04],[1,1.28,178.57],[2,1.23,217.39]],"ltp":1.5,"tv":236.98,"id":60971788},{"batb":[[0,2.72,9],[1,2.7,24],[2,1.28,178.57]],"ltp":3.0,"tv":134.09,"id":60971786}]}]}
{"op":"mcm","clk":"11932364098","pt":1724741721879,"mc":[{"id":"1.232260815","rc":[{"batb":[[0,1.34,5],[1,1.33,88.04],[2,1.28,178.57]],"ltp":1.5,"tv":236.98,"id":60971788},{"batb":[[0,2.72,5]],"ltp":3.0,"tv":134.09,"id":60971786}]}]}
{"op":"mcm","clk":"11932364141","pt":1724741722850,"mc":[{"id":"1.232260815","rc":[{"batb":[[0,2.7,24],[1,1.28,178.57],[2,1.23,217.39]],"ltp":3.0,"tv":134.09,"id":60971786}]}]}
{"op":"mcm","clk":"11932364204","pt":1724741725156,"mc":[{"id":"1.232260815","rc":[{"batb":[[0,1.33,88.04],[1,1.28,178.57],[2,1.23,217.39]],"ltp":1.5,"tv":236.98,"id":60971788},{"batb":[[0,2.74,5],[1,2.72,4],[2,2.7,24]],"ltp":3.0,"tv":134.09,"id":60971786}]}]}
{"op":"mcm","clk":"11932364283","pt":1724741727261,"mc":[{"id":"1.232260815","rc":[{"batb":[[1,2.7,24],[2,1.28,178.57]],"ltp":3.0,"tv":134.09,"id":60971786}]}]}
{"op":"mcm","clk":"11932364290","pt":1724741727463,"mc":[{"id":"1.232260815","rc":[{"batb":[[0,1.34,5],[1,1.33,88.04],[2,1.28,178.57]],"ltp":1.5,"tv":236.98,"id":60971788}]}]}
{"op":"mcm","clk":"11932364321","pt":1724741728385,"mc":[{"id":"1.232260815","rc":[{"batb":[[0,2.7,24],[1,1.28,178.57],[2,1.23,217.39]],"ltp":3.0,"tv":134.09,"id":60971786}]}]}
{"op":"mcm","clk":"11932364367","pt":1724741729464,"mc":[{"id":"1.232260815","rc":[{"batb":[[0,2.72,4],[1,2.7,24],[2,1.28,178.57]],"ltp":3.0,"tv":134.09,"id":60971786}]}]}
{"op":"mcm","clk":"11932364413","pt":1724741730789,"mc":[{"id":"1.232260815","rc":[{"batb":[[0,1.33,88.04],[1,1.28,178.57],[2,1.23,217.39]],"ltp":1.5,"tv":236.98,"id":60971788},{"batb":[[0,2.74,5],[1,2.72,4],[2,2.7,24]],"ltp":3.0,"tv":134.09,"id":60971786}]}]}
{"op":"mcm","clk":"11932364451","pt":1724741731658,"mc":[{"id":"1.232260815","rc":[{"batb":[[1,2.7,24],[2,1.28,178.57]],"ltp":3.0,"tv":134.09,"id":60971786}]}]}
{"op":"mcm","clk":"11932364548","pt":1724741734273,"mc":[{"id":"1.232260815","rc":[{"batb":[[0,1.34,5],[1,1.33,88.04],[2,1.28,178.57]],"ltp":1.5,"tv":236.98,"id":60971788},{"batb":[[0,2.72,4]],"ltp":3.0,"tv":134.09,"id":60971786}]}]}
{"op":"mcm","clk":"11932364640","pt":1724741736677,"mc":[{"id":"1.232260815","rc":[{"batb":[[0,2.7,24],[1,1.28,178.57],[2,1.23,217.39]],"ltp":3.0,"tv":134.09,"id":60971786}]}]}
{"op":"mcm","clk":"11932364680","pt":1724741737697,"mc":[{"id":"1.232260815","rc":[{"batb":[[0,1.33,88.04],[1,1.28,178.57],[2,1.23,217.39]],"ltp":1.5,"tv":236.98,"id":60971788}]}]}
{"op":"mcm","clk":"11932375057","pt":1724742000968,"mc":[{"id":"1.232260815","rc":[{"batb":[[0,1.34,5],[1,1.33,88.04],[2,1.28,178.57]],"ltp":1.5,"tv":236.98,"id":60971788},{"batb":[[0,2.72,9],[1,2.7,24],[2,1.28,178.57]],"ltp":3.0,"tv":134.09,"id":60971786}]}]}
{"op":"mcm","clk":"11932375281","pt":1724742004313,"mc":[{"id":"1.232260815","rc":[{"batb":[[1,1.33,88.05]],"ltp":1.5,"tv":236.98,"id":60971788},{"batb":[[0,2.7,24],[1,1.28,178.57],[2,1.23,217.39]],"ltp":3.0,"tv":134.09,"id":60971786}]}]}
{"op":"mcm","clk":"11932375289","pt":1724742004366,"mc":[{"id":"1.232260815","rc":[{"batb":[[0,1.33,88.05],[1,1.28,178.57],[2,1.23,217.39]],"ltp":1.5,"tv":236.98,"id":60971788}]}]}
{"op":"mcm","clk":"11932375396","pt":1724742006592,"mc":[{"id":"1.232260815","rc":[{"batb":[[0,1.34,5],[1,1.33,88.05],[2,1.28,178.57]],"ltp":1.5,"tv":236.98,"id":60971788},{"batb":[[0,2.72,9],[1,2.7,24],[2,1.28,178.57]],"ltp":3.0,"tv":134.09,"id":60971786}]}]}
{"op":"mcm","clk":"11932375513","pt":1724742008913,"mc":[{"id":"1.232260815","rc":[{"batb":[[0,2.72,5]],"ltp":3.0,"tv":134.09,"id":60971786}]}]}
{"op":"mcm","clk":"11932375567","pt":1724742009889,"mc":[{"id":"1.232260815","rc":[{"batb":[[0,1.33,88.05],[1,1.28,178.57],[2,1.23,217.39]],"ltp":1.5,"tv":236.98,"id":60971788},{"batb":[[0,2.7,24],[1,1.28,178.57],[2,1.23,217.39]],"ltp":3.0,"tv":134.09,"id":60971786}]}]}
{"op":"mcm","clk":"11932375628","pt":1724742011181,"mc":[{"id":"1.232260815","rc":[{"batb":[[0,2.72,4],[1,2.7,24],[2,1.28,178.57]],"ltp":3.0,"tv":134.09,"id":60971786}]}]}
{"op":"mcm","clk":"11932375687","pt":1724742012310,"mc":[{"id":"1.232260815","rc":[{"batb":[[0,1.34,5],[1,1.33,88.05],[2,1.28,178.57]],"ltp":1.5,"tv":236.98,"id":60971788},{"batb":[[0,2.74,5],[1,2.72,4],[2,2.7,24]],"ltp":3.0,"tv":134.09,"id":60971786}]}]}
{"op":"mcm","clk":"11932375759","pt":1724742013496,"mc":[{"id":"1.232260815","rc":[{"batb":[[1,2.7,24],[2,1.28,178.57]],"ltp":3.0,"tv":134.09,"id":60971786}]}]}
{"op":"mcm","clk":"11932375879","pt":1724742016013,"mc":[{"id":"1.232260815","rc":[{"batb":[[0,1.33,88.05],[1,1.28,178.57],[2,1.23,217.39]],"ltp":1.5,"tv":236.98,"id":60971788},{"batb":[[0,2.72,4]],"ltp":3.0,"tv":134.09,"id":60971786}]}]}
{"op":"mcm","clk":"11932375994","pt":1724742018130,"mc":[{"id":"1.232260815","rc":[{"batb":[[0,1.34,5],[1,1.33,88.05],[2,1.28,178.57]],"ltp":1.5,"tv":236.98,"id":60971788},{"batb":[[0,2.74,5],[1,2.72,4],[2,2.7,24]],"ltp":3.0,"tv":134.09,"id":60971786}]}]}
{"op":"mcm","clk":"11932376007","pt":1724742018334,"mc":[{"id":"1.232260815","rc":[{"batb":[[1,2.7,24],[2,1.28,178.57]],"ltp":3.0,"tv":134.09,"id":60971786}]}]}
{"op":"mcm","clk":"11932376143","pt":1724742020740,"mc":[{"id":"1.232260815","rc":[{"batb":[[0,2.76,4],[1,2.74,5],[2,2.7,24]],"ltp":3.0,"tv":134.09,"id":60971786}]}]}
{"op":"mcm","clk":"11932376182","pt":1724742021514,"mc":[{"id":"1.232260815","rc":[{"batb":[[0,1.33,88.05],[1,1.28,178.57],[2,1.23,217.39]],"ltp":1.5,"tv":236.98,"id":60971788},{"batb":[[1,2.7,24],[2,1.28,178.57]],"ltp":3.0,"tv":134.09,"id":60971786}]}]}
{"op":"mcm","clk":"11932376254","pt":1724742023056,"mc":[{"id":"1.232260815","rc":[{"batb":[[0,2.7,24],[1,1.28,178.57],[2,1.23,217.39]],"ltp":3.0,"tv":134.09,"id":60971786}]}]}
{"op":"mcm","clk":"11932376300","pt":1724742024240,"mc":[{"id":"1.232260815","rc":[{"batb":[[0,1.34,5],[1,1.33,88.05],[2,1.28,178.57]],"ltp":1.5,"tv":236.98,"id":60971788},{"batb":[[0,2.72,5],[1,2.7,24],[2,1.28,178.57]],"ltp":3.0,"tv":134.09,"id":60971786}]}]}
{"op":"mcm","clk":"11932376339","pt":1724742025317,"mc":[{"id":"1.232260815","rc":[{"batb":[[0,2.74,4],[1,2.72,5],[2,2.7,24]],"ltp":3.0,"tv":134.09,"id":60971786}]}]}
{"op":"mcm","clk":"11932376441","pt":1724742027622,"mc":[{"id":"1.232260815","rc":[{"batb":[[0,1.33,88.05],[1,1.28,178.57],[2,1.23,217.39]],"ltp":1.5,"tv":236.98,"id":60971788},{"batb":[[0,2.7,24],[1,1.28,178.57],[2,1.23,217.39]],"ltp":3.0,"tv":134.09,"id":60971786}]}]}
{"op":"mcm","clk":"11932376551","pt":1724742029830,"mc":[{"id":"1.232260815","rc":[{"batb":[[0,1.34,5],[1,1.33,88.05],[2,1.28,178.57]],"ltp":1.5,"tv":236.98,"id":60971788},{"batb":[[0,2.72,9],[1,2.7,24],[2,1.28,178.57]],"ltp":3.0,"tv":134.09,"id":60971786}]}]}
{"op":"mcm","clk":"11932376667","pt":1724742032040,"mc":[{"id":"1.232260815","rc":[{"batb":[[0,2.72,5]],"ltp":3.0,"tv":134.09,"id":60971786}]}]}
{"op":"mcm","clk":"11932376727","pt":1724742033270,"mc":[{"id":"1.232260815","rc":[{"batb":[[0,1.33,88.05],[1,1.28,178.57],[2,1.23,217.39]],"ltp":1.5,"tv":236.98,"id":60971788},{"batb":[[0,2.7,24],[1,1.28,178.57],[2,1.23,217.39]],"ltp":3.0,"tv":134.09,"id":60971786}]}]}
{"op":"mcm","clk":"11932376791","pt":1724742034349,"mc":[{"id":"1.232260815","rc":[{"batb":[[0,2.72,4],[1,2.7,24],[2,1.28,178.57]],"ltp":3.0,"tv":134.09,"id":60971786}]}]}
{"op":"mcm","clk":"11932376845","pt":1724742035433,"mc":[{"id":"1.232260815","rc":[{"batb":[[0,1.34,5],[1,1.33,88.05],[2,1.28,178.57]],"ltp":1.5,"tv":236.98,"id":60971788},{"batb":[[0,2.74,5],[1,2.72,4],[2,2.7,24]],"ltp":3.0,"tv":134.09,"id":60971786}]}]}
{"op":"mcm","clk":"11932376887","pt":1724742036571,"mc":[{"id":"1.232260815","rc":[{"batb":[[1,2.7,24],[2,1.28,178.57]],"ltp":3.0,"tv":134.09,"id":60971786}]}]}
{"op":"mcm","clk":"11932377005","pt":1724742038875,"mc":[{"id":"1.232260815","rc":[{"batb":[[0,1.33,88.05],[1,1.28,178.57],[2,1.23,217.39]],"ltp":1.5,"tv":236.98,"id":60971788},{"batb":[[0,2.76,4]],"ltp":3.0,"tv":134.09,"id":60971786}]}]}
{"op":"mcm","clk":"11932377109","pt":1724742041179,"mc":[{"id":"1.232260815","rc":[{"batb":[[0,1.34,5],[1,1.33,88.05],[2,1.28,178.57]],"ltp":1.5,"tv":236.98,"id":60971788},{"batb":[[0,2.72,5]],"ltp":3.0,"tv":134.09,"id":60971786}]}]}
{"op":"mcm","clk":"11932377215","pt":1724742043329,"mc":[{"id":"1.232260815","rc":[{"batb":[[0,2.74,4],[1,2.72,5],[2,2.7,24]],"ltp":3.0,"tv":134.09,"id":60971786}]}]}
{"op":"mcm","clk":"11932377270","pt":1724742044559,"mc":[{"id":"1.232260815","rc":[{"batb":[[0,1.33,88.05],[1,1.28,178.57],[2,1.23,217.39]],"ltp":1.5,"tv":236.98,"id":60971788},{"batb":[[1,2.7,24],[2,1.28,178.57]],"ltp":3.0,"tv":134.09,"id":60971786}]}]}
{"op":"mcm","clk":"11932377334","pt":1724742045849,"mc":[{"id":"1.232260815","rc":[{"batb":[[0,2.7,24],[1,1.28,178.57],[2,1.23,217.39]],"ltp":3.0,"tv":134.09,"id":60971786}]}]}
{"op":"mcm","clk":"11932377387","pt":1724742046973,"mc":[{"id":"1.232260815","rc":[{"batb":[[0,1.34,5],[1,1.33,88.05],[2,1.28,178.57]],"ltp":1.5,"tv":236.98,"id":60971788},{"batb":[[0,2.72,5],[1,2.7,24],[2,1.28,178.57]],"ltp":3.0,"tv":134.09,"id":60971786}]}]}
{"op":"mcm","clk":"11932377449","pt":1724742048053,"mc":[{"id":"1.232260815","rc":[{"batb":[[0,2.74,4],[1,2.72,5],[2,2.7,24]],"ltp":3.0,"tv":134.09,"id":60971786}]}]}
{"op":"mcm","clk":"11932377555","pt":1724742050452,"mc":[{"id":"1.232260815","rc":[{"batb":[[0,1.33,88.05],[1,1.28,178.57],[2,1.23,217.39]],"ltp":1.5,"tv":236.98,"id":60971788},{"batb":[[0,2.7,24],[1,1.28,178.57],[2,1.23,217.39]],"ltp":3.0,"tv":134.09,"id":60971786}]}]}
{"op":"mcm","clk":"11932377681","pt":1724742053779,"mc":[{"id":"1.232260815","rc":[{"batb":[[0,1.34,5],[1,1.33,88.05],[2,1.28,178.57]],"ltp":1.5,"tv":236.98,"id":60971788},{"batb":[[0,2.72,9],[1,2.7,24],[2,1.28,178.57]],"ltp":3.0,"tv":134.09,"id":60971786}]}]}
{"op":"mcm","clk":"11932377773","pt":1724742056081,"mc":[{"id":"1.232260815","rc":[{"batb":[[0,2.72,5]],"ltp":3.0,"tv":134.09,"id":60971786}]}]}
{"op":"mcm","clk":"11932377817","pt":1724742057050,"mc":[{"id":"1.232260815","rc":[{"batb":[[0,1.33,88.05],[1,1.28,178.57],[2,1.23,217.39]],"ltp":1.5,"tv":236.98,"id":60971788},{"batb":[[0,2.7,24],[1,1.28,178.57],[2,1.23,217.39]],"ltp":3.0,"tv":134.09,"id":60971786}]}]}
{"op":"mcm","clk":"11932377875","pt":1724742058179,"mc":[{"id":"1.232260815","rc":[{"batb":[[0,2.72,4],[1,2.7,24],[2,1.28,178.57]],"ltp":3.0,"tv":134.09,"id":60971786}]}]}
{"op":"mcm","clk":"11932377956","pt":1724742059409,"mc":[{"id":"1.232260815","rc":[{"batb":[[0,1.34,5],[1,1.33,88.05],[2,1.28,178.57]],"ltp":1.5,"tv":236.98,"id":60971788},{"batb":[[0,2.74,5],[1,2.72,4],[2,2.7,24]],"ltp":3.0,"tv":134.09,"id":60971786}]}]}
{"op":"mcm","clk":"11932378031","pt":1724742060587,"mc":[{"id":"1.232260815","rc":[{"batb":[[1,2.7,24],[2,1.28,178.57]],"ltp":3.0,"tv":134.09,"id":60971786}]}]}
{"op":"mcm","clk":"11932378171","pt":1724742062753,"mc":[{"id":"1.232260815","rc":[{"batb":[[0,1.33,88.05],[1,1.28,178.57],[2,1.23,217.39]],"ltp":1.5,"tv":236.98,"id":60971788},{"batb":[[0,2.72,4]],"ltp":3.0,"tv":134.09,"id":60971786}]}]}
{"op":"mcm","clk":"11932378285","pt":1724742065166,"mc":[{"id":"1.232260815","rc":[{"batb":[[0,1.34,5],[1,1.33,88.05],[2,1.28,178.57]],"ltp":1.5,"tv":236.98,"id":60971788},{"batb":[[0,2.74,5]],"ltp":3.0,"tv":134.09,"id":60971786}]}]}
{"op":"mcm","clk":"11932378442","pt":1724742068397,"mc":[{"id":"1.232260815","rc":[{"batb":[[0,1.33,88.05],[1,1.28,178.57],[2,1.23,217.39]],"ltp":1.5,"tv":236.98,"id":60971788},{"batb":[[0,2.76,4]],"ltp":3.0,"tv":134.09,"id":60971786}]}]}
{"op":"mcm","clk":"11932378559","pt":1724742070807,"mc":[{"id":"1.232260815","rc":[{"batb":[[0,1.34,5],[1,1.33,88.05],[2,1.28,178.57]],"ltp":1.5,"tv":236.98,"id":60971788},{"batb":[[0,2.78,5]],"ltp":3.0,"tv":134.09,"id":60971786}]}]}
{"op":"mcm","clk":"11932378684","pt":1724742072971,"mc":[{"id":"1.232260815","rc":[{"batb":[[0,2.8,4],[1,2.78,5],[2,2.7,24]],"ltp":3.0,"tv":134.09,"id":60971786}]}]}
{"op":"mcm","clk":"11932378762","pt":1724742074201,"mc":[{"id":"1.232260815","rc":[{"batb":[[0,1.33,88.05],[1,1.28,178.57],[2,1.23,217.39]],"ltp":1.5,"tv":236.98,"id":60971788},{"batb":[[1,2.7,24],[2,1.28,178.57]],"ltp":3.0,"tv":134.09,"id":60971786}]}]}
{"op":"mcm","clk":"11932378816","pt":1724742075275,"mc":[{"id":"1.232260815","rc":[{"batb":[[0,2.7,24],[1,1.28,178.57],[2,1.23,217.39]],"ltp":3.0,"tv":134.09,"id":60971786}]}]}
{"op":"mcm","clk":"11932378867","pt":1724742076402,"mc":[{"id":"1.232260815","rc":[{"batb":[[0,1.34,5],[1,1.33,88.05],[2,1.28,178.57]],"ltp":1.5,"tv":236.98,"id":60971788},{"batb":[[0,2.72,5],[1,2.7,24],[2,1.28,178.57]],"ltp":3.0,"tv":134.09,"id":60971786}]}]}
{"op":"mcm","clk":"11932378915","pt":1724742077474,"mc":[{"id":"1.232260815","rc":[{"batb":[[0,2.74,4],[1,2.72,5],[2,2.7,24]],"ltp":3.0,"tv":134.09,"id":60971786}]}]}
{"op":"mcm","clk":"11932379022","pt":1724742079883,"mc":[{"id":"1.232260815","rc":[{"batb":[[0,1.33,88.05],[1,1.28,178.57],[2,1.23,217.39]],"ltp":1.5,"tv":236.98,"id":60971788},{"batb":[[0,2.7,24],[1,1.28,178.57],[2,1.23,217.39]],"ltp":3.0,"tv":134.09,"id":60971786}]}]}
{"op":"mcm","clk":"11932379166","pt":1724742082793,"mc":[{"id":"1.232260815","rc":[{"batb":[[0,1.34,5],[1,1.33,88.05],[2,1.28,178.57]],"ltp":1.5,"tv":236.98,"id":60971788},{"batb":[[0,2.72,9],[1,2.7,24],[2,1.28,178.57]],"ltp":3.0,"tv":134.09,"id":60971786}]}]}
{"op":"mcm","clk":"11932379269","pt":1724742085095,"mc":[{"id":"1.232260815","rc":[{"batb":[[0,2.72,5]],"ltp":3.0,"tv":134.09,"id":60971786}]}]}
{"op":"mcm","clk":"11932379310","pt":1724742086021,"mc":[{"id":"1.232260815","rc":[{"batb":[[0,1.33,88.05],[1,1.28,178.57],[2,1.23,217.39]],"ltp":1.5,"tv":236.98,"id":60971788},{"batb":[[0,2.7,24],[1,1.28,178.57],[2,1.23,217.39]],"ltp":3.0,"tv":134.09,"id":60971786}]}]}
{"op":"mcm","clk":"11932379347","pt":1724742086793,"mc":[{"id":"1.232260815","rc":[{"batb":[[0,1.42,6.53],[1,1.33,88.05],[2,1.28,178.57]],"ltp":1.5,"tv":236.98,"id":60971788}]}]}
{"op":"mcm","clk":"11932379394","pt":1724742087917,"mc":[{"id":"1.232260815","rc":[{"batb":[[0,2.72,4],[1,2.7,24],[2,1.28,178.57]],"ltp":3.0,"tv":134.09,"id":60971786}]}]}
{"op":"mcm","clk":"11932379449","pt":1724742089091,"mc":[{"id":"1.232260815","rc":[{"batb":[[0,1.43,5],[1,1.42,6.53],[2,1.33,88.05]],"ltp":1.5,"tv":236.98,"id":60971788},{"batb":[[0,2.74,5],[1,2.72,4],[2,2.7,24]],"ltp":3.0,"tv":134.09,"id":60971786}]}]}
{"op":"mcm","clk":"11932379521","pt":1724742090424,"mc":[{"id":"1.232260815","rc":[{"batb":[[1,2.7,24],[2,1.28,178.57]],"ltp":3.0,"tv":134.09,"id":60971786}]}]}
{"op":"mcm","clk":"11932379644","pt":1724742092628,"mc":[{"id":"1.232260815","rc":[{"batb":[[0,1.42,6.53],[1,1.33,88.05],[2,1.28,178.57]],"ltp":1.5,"tv":236.98,"id":60971788},{"batb":[[0,2.72,4]],"ltp":3.0,"tv":134.09,"id":60971786}]}]}
{"op":"mcm","clk":"11932379748","pt":1724742094930,"mc":[{"id":"1.232260815","rc":[{"batb":[[0,1.43,5],[1,1.42,6.53],[2,1.33,88.05]],"ltp":1.5,"tv":236.98,"id":60971788},{"batb":[[0,2.74,5]],"ltp":3.0,"tv":134.09,"id":60971786}]}]}
{"op":"mcm","clk":"11932379851","pt":1724742097125,"mc":[{"id":"1.232260815","rc":[{"batb":[[0,2.76,4],[1,2.74,5],[2,2.7,24]],"ltp":3.0,"tv":134.09,"id":60971786}]}]}
{"op":"mcm","clk":"11932379918","pt":1724742098201,"mc":[{"id":"1.232260815","rc":[{"batb":[[0,1.44,130.21]],"ltp":1.5,"tv":236.98,"id":60971788},{"batb":[[1,2.7,24],[2,1.28,178.57]],"batl":[[0,24,1.52],[1,24,0]],"ltp":3.0,"tv":134.09,"id":60971786}]}]}
{"op":"mcm","clk":"11932380000","pt":1724742099429,"mc":[{"id":"1.232260815","rc":[{"batb":[[0,2.7,24],[1,1.28,178.57],[2,1.23,217.39]],"ltp":3.0,"tv":134.09,"id":60971786}]}]}
{"op":"mcm","clk":"11932380086","pt":1724742101016,"mc":[{"id":"1.232260815","rc":[{"batb":[[0,1.45,5],[1,1.44,130.21]],"ltp":1.5,"tv":236.98,"id":60971788},{"batb":[[0,2.72,5],[1,2.7,24],[2,1.28,178.57]],"ltp":3.0,"tv":134.09,"id":60971786}]}]}
{"op":"mcm","clk":"11932380233","pt":1724742104048,"mc":[{"id":"1.232260815","rc":[{"batb":[[0,1.44,130.21],[1,1.33,88.05],[2,1.28,178.57]],"ltp":1.5,"tv":236.98,"id":60971788},{"batb":[[0,2.7,24],[1,1.28,178.57],[2,1.23,217.39]],"ltp":3.0,"tv":134.09,"id":60971786}]}]}
{"op":"mcm","clk":"11932380345","pt":1724742106303,"mc":[{"id":"1.232260815","rc":[{"batb":[[0,1.45,5],[1,1.44,130.21],[2,1.33,88.05]],"ltp":1.5,"tv":236.98,"id":60971788},{"batb":[[0,2.72,5],[1,2.7,24],[2,1.28,178.57]],"ltp":3.0,"tv":134.09,"id":60971786}]}]}
{"op":"mcm","clk":"11932380502","pt":1724742109625,"mc":[{"id":"1.232260815","rc":[{"batb":[[0,1.44,130.21],[1,1.33,88.05],[2,1.28,178.57]],"ltp":1.5,"tv":236.98,"id":60971788},{"batb":[[0,2.7,24],[1,1.28,178.57],[2,1.23,217.39]],"ltp":3.0,"tv":134.09,"id":60971786}]}]}
{"op":"mcm","clk":"11932380614","pt":1724742111929,"mc":[{"id":"1.232260815","rc":[{"batb":[[0,1.45,5],[1,1.44,130.21],[2,1.33,88.05]],"ltp":1.5,"tv":236.98,"id":60971788},{"batb":[[0,2.72,5],[1,2.7,24],[2,1.28,178.57]],"ltp":3.0,"tv":134.09,"id":60971786}]}]}
{"op":"mcm","clk":"11932380778","pt":1724742115263,"mc":[{"id":"1.232260815","rc":[{"batb":[[0,1.44,130.21],[1,1.33,88.05],[2,1.28,178.57]],"ltp":1.5,"tv":236.98,"id":60971788},{"batb":[[0,2.7,24],[1,1.28,178.57],[2,1.23,217.39]],"ltp":3.0,"tv":134.09,"id":60971786}]}]}
{"op":"mcm","clk":"11932380899","pt":1724742117561,"mc":[{"id":"1.232260815","rc":[{"batb":[[0,1.45,5],[1,1.44,130.21],[2,1.33,88.05]],"ltp":1.5,"tv":236.98,"id":60971788},{"batb":[[0,2.72,5],[1,2.7,24],[2,1.28,178.57]],"ltp":3.0,"tv":134.09,"id":60971786}]}]}
{"op":"mcm","clk":"11932381061","pt":1724742121045,"mc":[{"id":"1.232260815","rc":[{"batb":[[0,1.44,130.21],[1,1.33,88.05],[2,1.28,178.57]],"ltp":1.5,"tv":236.98,"id":60971788},{"batb":[[0,2.7,24],[1,1.28,178.57],[2,1.23,217.39]],"ltp":3.0,"tv":134.09,"id":60971786}]}]}
{"op":"mcm","clk":"11932381182","pt":1724742123259,"mc":[{"id":"1.232260815","rc":[{"batb":[[0,1.45,5],[1,1.44,130.21],[2,1.33,88.05]],"ltp":1.5,"tv":236.98,"id":60971788},{"batb":[[0,2.72,5],[1,2.7,24],[2,1.28,178.57]],"ltp":3.0,"tv":134.09,"id":60971786}]}]}
{"op":"mcm","clk":"11932381344","pt":1724742126661,"mc":[{"id":"1.232260815","rc":[{"batb":[[0,1.44,130.21],[1,1.33,88.05],[2,1.28,178.57]],"ltp":1.5,"tv":236.98,"id":60971788},{"batb":[[0,2.7,24],[1,1.28,178.57],[2,1.23,217.39]],"ltp":3.0,"tv":134.09,"id":60971786}]}]}
{"op":"mcm","clk":"11932381472","pt":1724742128965,"mc":[{"id":"1.232260815","rc":[{"batb":[[0,1.45,5],[1,1.44,130.21],[2,1.33,88.05]],"ltp":1.5,"tv":236.98,"id":60971788},{"batb":[[0,2.72,5],[1,2.7,24],[2,1.28,178.57]],"ltp":3.0,"tv":134.09,"id":60971786}]}]}
{"op":"mcm","clk":"11932381646","pt":1724742132461,"mc":[{"id":"1.232260815","rc":[{"batb":[[0,1.44,130.21],[1,1.33,88.05],[2,1.28,178.57]],"ltp":1.5,"tv":236.98,"id":60971788},{"batb":[[0,2.7,24],[1,1.28,178.57],[2,1.23,217.39]],"ltp":3.0,"tv":134.09,"id":60971786}]}]}
{"op":"mcm","clk":"11932381756","pt":1724742134864,"mc":[{"id":"1.232260815","rc":[{"batb":[[0,1.45,5],[1,1.44,130.21],[2,1.33,88.05]],"ltp":1.5,"tv":236.98,"id":60971788},{"batb":[[0,2.72,5],[1,2.7,24],[2,1.28,178.57]],"ltp":3.0,"tv":134.09,"id":60971786}]}]}
{"op":"mcm","clk":"11932381940","pt":1724742138353,"mc":[{"id":"1.232260815","rc":[{"batb":[[0,1.44,130.21],[1,1.33,88.05],[2,1.28,178.57]],"ltp":1.5,"tv":236.98,"id":60971788},{"batb":[[0,2.7,24],[1,1.28,178.57],[2,1.23,217.39]],"ltp":3.0,"tv":134.09,"id":60971786}]}]}
{"op":"mcm","clk":"11932382113","pt":1724742141178,"mc":[{"id":"1.232260815","rc":[{"batb":[[0,1.45,5],[1,1.44,130.21],[2,1.33,88.05]],"ltp":1.5,"tv":236.98,"id":60971788},{"batb":[[0,2.72,5],[1,2.7,24],[2,1.28,178.57]],"ltp":3.0,"tv":134.09,"id":60971786}]}]}
{"op":"mcm","clk":"11932382250","pt":1724742144297,"mc":[{"id":"1.232260815","rc":[{"batb":[[0,1.44,130.21],[1,1.33,88.05],[2,1.28,178.57]],"ltp":1.5,"tv":236.98,"id":60971788}]}]}
{"op":"mcm","clk":"11932382254","pt":1724742144400,"mc":[{"id":"1.232260815","rc":[{"batb":[[0,2.7,24],[1,1.28,178.57],[2,1.23,217.39]],"ltp":3.0,"tv":134.09,"id":60971786}]}]}
{"op":"mcm","clk":"11932382369","pt":1724742146599,"mc":[{"id":"1.232260815","rc":[{"batb":[[0,1.45,5],[1,1.44,130.21],[2,1.33,88.05]],"ltp":1.5,"tv":236.98,"id":60971788},{"batb":[[0,2.72,5],[1,2.7,24],[2,1.28,178.57]],"ltp":3.0,"tv":134.09,"id":60971786}]}]}
{"op":"mcm","clk":"11932382518","pt":1724742149881,"mc":[{"id":"1.232260815","rc":[{"batb":[[0,1.44,130.21],[1,1.33,88.05],[2,1.28,178.57]],"ltp":1.5,"tv":236.98,"id":60971788},{"batb":[[0,2.7,24],[1,1.28,178.57],[2,1.23,217.39]],"ltp":3.0,"tv":134.09,"id":60971786}]}]}
{"op":"mcm","clk":"11932382687","pt":1724742152603,"mc":[{"id":"1.232260815","rc":[{"batb":[[0,1.45,5],[1,1.44,130.21],[2,1.33,88.05]],"ltp":1.5,"tv":236.98,"id":60971788},{"batb":[[0,2.72,5],[1,2.7,24],[2,1.28,178.57]],"ltp":3.0,"tv":134.09,"id":60971786}]}]}
{"op":"mcm","clk":"11932382881","pt":1724742155989,"mc":[{"id":"1.232260815","rc":[{"batb":[[0,1.44,130.21],[1,1.33,88.05],[2,1.28,178.57]],"ltp":1.5,"tv":236.98,"id":60971788},{"batb":[[0,2.7,24],[1,1.28,178.57],[2,1.23,217.39]],"ltp":3.0,"tv":134.09,"id":60971786}]}]}
{"op":"mcm","clk":"11932382998","pt":1724742158294,"mc":[{"id":"1.232260815","rc":[{"batb":[[0,1.45,5],[1,1.44,130.21],[2,1.33,88.05]],"ltp":1.5,"tv":236.98,"id":60971788},{"batb":[[0,2.72,5],[1,2.7,24],[2,1.28,178.57]],"ltp":3.0,"tv":134.09,"id":60971786}]}]}
{"op":"mcm","clk":"11932383173","pt":1724742161521,"mc":[{"id":"1.232260815","rc":[{"batb":[[0,1.44,130.21],[1,1.33,88.05],[2,1.28,178.57]],"ltp":1.5,"tv":236.98,"id":60971788},{"batb":[[0,2.7,24],[1,1.28,178.57],[2,1.23,217.39]],"ltp":3.0,"tv":134.09,"id":60971786}]}]}
{"op":"mcm","clk":"11932383269","pt":1724742163578,"mc":[{"id":"1.232260815","rc":[{"batb":[[0,1.45,5],[1,1.44,130.21],[2,1.33,88.05]],"ltp":1.5,"tv":236.98,"id":60971788},{"batb":[[0,2.72,5],[1,2.7,24],[2,1.28,178.57]],"ltp":3.0,"tv":134.09,"id":60971786}]}]}
{"op":"mcm","clk":"11932383440","pt":1724742167014,"mc":[{"id":"1.232260815","rc":[{"batb":[[0,1.44,130.21],[1,1.33,88.05],[2,1.28,178.57]],"ltp":1.5,"tv":236.98,"id":60971788},{"batb":[[0,2.7,24],[1,1.28,178.57],[2,1.23,217.39]],"ltp":3.0,"tv":134.09,"id":60971786}]}]}
{"op":"mcm","clk":"11932383544","pt":1724742169224,"mc":[{"id":"1.232260815","rc":[{"batb":[[0,1.45,5],[1,1.44,130.21],[2,1.33,88.05]],"ltp":1.5,"tv":236.98,"id":60971788},{"batb":[[0,2.72,5],[1,2.7,24],[2,1.28,178.57]],"ltp":3.0,"tv":134.09,"id":60971786}]}]}
{"op":"mcm","clk":"11932383724","pt":1724742172715,"mc":[{"id":"1.232260815","rc":[{"batb":[[0,1.44,130.21],[1,1.33,88.05],[2,1.28,178.57]],"ltp":1.5,"tv":236.98,"id":60971788},{"batb":[[0,2.7,24],[1,1.28,178.57],[2,1.23,217.39]],"ltp":3.0,"tv":134.09,"id":60971786}]}]}
{"op":"mcm","clk":"11932383830","pt":1724742174931,"mc":[{"id":"1.232260815","rc":[{"batb":[[0,1.45,5],[1,1.44,130.21],[2,1.33,88.05]],"ltp":1.5,"tv":236.98,"id":60971788},{"batb":[[0,2.72,5],[1,2.7,24],[2,1.28,178.57]],"ltp":3.0,"tv":134.09,"id":60971786}]}]}
{"op":"mcm","clk":"11932383983","pt":1724742178111,"mc":[{"id":"1.232260815","rc":[{"batb":[[0,1.44,130.21],[1,1.33,88.05],[2,1.28,178.57]],"ltp":1.5,"tv":236.98,"id":60971788},{"batb":[[0,2.7,24],[1,1.28,178.57],[2,1.23,217.39]],"ltp":3.0,"tv":134.09,"id":60971786}]}]}
{"op":"mcm","clk":"11932384084","pt":1724742180216,"mc":[{"id":"1.232260815","rc":[{"batb":[[0,1.45,5],[1,1.44,130.21],[2,1.33,88.05]],"ltp":1.5,"tv":236.98,"id":60971788},{"batb":[[0,2.72,5],[1,2.7,24],[2,1.28,178.57]],"ltp":3.0,"tv":134.09,"id":60971786}]}]}
{"op":"mcm","clk":"11932384261","pt":1724742183513,"mc":[{"id":"1.232260815","rc":[{"batb":[[0,1.44,130.21],[1,1.33,88.05],[2,1.28,178.57]],"ltp":1.5,"tv":236.98,"id":60971788},{"batb":[[0,2.7,24],[1,1.28,178.57],[2,1.23,217.39]],"ltp":3.0,"tv":134.09,"id":60971786}]}]}
{"op":"mcm","clk":"11932384447","pt":1724742187107,"mc":[{"id":"1.232260815","rc":[{"batb":[[0,1.45,5],[1,1.44,130.21],[2,1.33,88.05]],"ltp":1.5,"tv":236.98,"id":60971788},{"batb":[[0,2.72,5],[1,2.7,24],[2,1.28,178.57]],"ltp":3.0,"tv":134.09,"id":60971786}]}]}
{"op":"mcm","clk":"11932384599","pt":1724742190543,"mc":[{"id":"1.232260815","rc":[{"batb":[[0,1.44,130.21],[1,1.33,88.05],[2,1.28,178.57]],"ltp":1.5,"tv":236.98,"id":60971788},{"batb":[[0,2.7,24],[1,1.28,178.57],[2,1.23,217.39]],"ltp":3.0,"tv":134.09,"id":60971786}]}]}
{"op":"mcm","clk":"11932384689","pt":1724742192748,"mc":[{"id":"1.232260815","rc":[{"batb":[[0,1.45,5],[1,1.44,130.21],[2,1.33,88.05]],"ltp":1.5,"tv":236.98,"id":60971788},{"batb":[[0,2.72,5],[1,2.7,24],[2,1.28,178.57]],"ltp":3.0,"tv":134.09,"id":60971786}]}]}
{"op":"mcm","clk":"11932384859","pt":1724742196046,"mc":[{"id":"1.232260815","rc":[{"batb":[[0,1.44,130.21],[1,1.33,88.05],[2,1.28,178.57]],"ltp":1.5,"tv":236.98,"id":60971788},{"batb":[[0,2.7,24],[1,1.28,178.57],[2,1.23,217.39]],"ltp":3.0,"tv":134.09,"id":60971786}]}]}
{"op":"mcm","clk":"11932385020","pt":1724742199723,"mc":[{"id":"1.232260815","rc":[{"batb":[[0,1.45,5],[1,1.44,130.21],[2,1.33,88.05]],"ltp":1.5,"tv":236.98,"id":60971788},{"batb":[[0,2.72,5],[1,2.7,24],[2,1.28,178.57]],"ltp":3.0,"tv":134.09,"id":60971786}]}]}
{"op":"mcm","clk":"11932385187","pt":1724742203129,"mc":[{"id":"1.232260815","rc":[{"batb":[[0,1.44,130.21],[1,1.33,88.05],[2,1.28,178.57]],"ltp":1.5,"tv":236.98,"id":60971788},{"batb":[[0,2.7,24],[1,1.28,178.57],[2,1.23,217.39]],"ltp":3.0,"tv":134.09,"id":60971786}]}]}
{"op":"mcm","clk":"11932385300","pt":1724742205335,"mc":[{"id":"1.232260815","rc":[{"batb":[[0,1.45,5],[1,1.44,130.21],[2,1.33,88.05]],"ltp":1.5,"tv":236.98,"id":60971788},{"batb":[[0,2.72,5],[1,2.7,24],[2,1.28,178.57]],"ltp":3.0,"tv":134.09,"id":60971786}]}]}
{"op":"mcm","clk":"11932385455","pt":1724742208762,"mc":[{"id":"1.232260815","rc":[{"batb":[[0,1.44,130.21],[1,1.33,88.05],[2,1.28,178.57]],"ltp":1.5,"tv":236.98,"id":60971788},{"batb":[[0,2.7,24],[1,1.28,178.57],[2,1.23,217.39]],"ltp":3.0,"tv":134.09,"id":60971786}]}]}
{"op":"mcm","clk":"11932385537","pt":1724742210868,"mc":[{"id":"1.232260815","rc":[{"batb":[[0,1.45,5],[1,1.44,130.21],[2,1.33,88.05]],"ltp":1.5,"tv":236.98,"id":60971788},{"batb":[[0,2.72,5],[1,2.7,24],[2,1.28,178.57]],"ltp":3.0,"tv":134.09,"id":60971786}]}]}
{"op":"mcm","clk":"11932385700","pt":1724742214258,"mc":[{"id":"1.232260815","rc":[{"batb":[[0,1.44,130.21],[1,1.33,88.05],[2,1.28,178.57]],"ltp":1.5,"tv":236.98,"id":60971788},{"batb":[[0,2.7,24],[1,1.28,178.57],[2,1.23,217.39]],"ltp":3.0,"tv":134.09,"id":60971786}]}]}
{"op":"mcm","clk":"11932385834","pt":1724742217584,"mc":[{"id":"1.232260815","rc":[{"batb":[[0,1.45,5],[1,1.44,130.21],[2,1.33,88.05]],"ltp":1.5,"tv":236.98,"id":60971788},{"batb":[[0,2.72,5],[1,2.7,24],[2,1.28,178.57]],"ltp":3.0,"tv":134.09,"id":60971786}]}]}
{"op":"mcm","clk":"11932385965","pt":1724742220868,"mc":[{"id":"1.232260815","rc":[{"batb":[[0,1.44,130.21],[1,1.33,88.05],[2,1.28,178.57]],"ltp":1.5,"tv":236.98,"id":60971788},{"batb":[[0,2.7,24],[1,1.28,178.57],[2,1.23,217.39]],"ltp":3.0,"tv":134.09,"id":60971786}]}]}
{"op":"mcm","clk":"11932386088","pt":1724742224002,"mc":[{"id":"1.232260815","rc":[{"batb":[[0,1.45,5],[1,1.44,130.21],[2,1.33,88.05]],"ltp":1.5,"tv":236.98,"id":60971788},{"batb":[[0,2.72,5],[1,2.7,24],[2,1.28,178.57]],"ltp":3.0,"tv":134.09,"id":60971786}]}]}
{"op":"mcm","clk":"11932386204","pt":1724742227409,"mc":[{"id":"1.232260815","rc":[{"batb":[[0,1.44,130.21],[1,1.33,88.05],[2,1.28,178.57]],"ltp":1.5,"tv":236.98,"id":60971788},{"batb":[[0,2.7,24],[1,1.28,178.57],[2,1.23,217.39]],"ltp":3.0,"tv":134.09,"id":60971786}]}]}
{"op":"mcm","clk":"11932386291","pt":1724742229704,"mc":[{"id":"1.232260815","rc":[{"batb":[[0,1.45,5],[1,1.44,130.21],[2,1.33,88.05]],"ltp":1.5,"tv":236.98,"id":60971788},{"batb":[[0,2.72,5],[1,2.7,24],[2,1.28,178.57]],"ltp":3.0,"tv":134.09,"id":60971786}]}]}
{"op":"mcm","clk":"11932386390","pt":1724742233081,"mc":[{"id":"1.232260815","rc":[{"batb":[[0,1.44,130.21],[1,1.33,88.05],[2,1.28,178.57]],"ltp":1.5,"tv":236.98,"id":60971788},{"batb":[[0,2.7,24],[1,1.28,178.57],[2,1.23,217.39]],"ltp":3.0,"tv":134.09,"id":60971786}]}]}
{"op":"mcm","clk":"11932386473","pt":1724742235295,"mc":[{"id":"1.232260815","rc":[{"batb":[[0,1.45,5],[1,1.44,130.21],[2,1.33,88.05]],"ltp":1.5,"tv":236.98,"id":60971788},{"batb":[[0,2.72,5],[1,2.7,24],[2,1.28,178.57]],"ltp":3.0,"tv":134.09,"id":60971786}]}]}
{"op":"mcm","clk":"11932386591","pt":1724742238821,"mc":[{"id":"1.232260815","rc":[{"batb":[[0,1.44,130.21],[1,1.33,88.05],[2,1.28,178.57]],"ltp":1.5,"tv":236.98,"id":60971788},{"batb":[[0,2.7,24],[1,1.28,178.57],[2,1.23,217.39]],"ltp":3.0,"tv":134.09,"id":60971786}]}]}
{"op":"mcm","clk":"11932386675","pt":1724742241087,"mc":[{"id":"1.232260815","rc":[{"batb":[[0,1.45,5],[1,1.44,130.21],[2,1.33,88.05]],"ltp":1.5,"tv":236.98,"id":60971788},{"batb":[[0,2.72,5],[1,2.7,24],[2,1.28,178.57]],"ltp":3.0,"tv":134.09,"id":60971786}]}]}
{"op":"mcm","clk":"11932386792","pt":1724742244322,"mc":[{"id":"1.232260815","rc":[{"batb":[[0,1.44,130.21],[1,1.33,88.05],[2,1.28,178.57]],"ltp":1.5,"tv":236.98,"id":60971788},{"batb":[[0,2.7,24],[1,1.28,178.57],[2,1.23,217.39]],"ltp":3.0,"tv":134.09,"id":60971786}]}]}
{"op":"mcm","clk":"11932386909","pt":1724742247295,"mc":[{"id":"1.232260815","rc":[{"batb":[[0,1.45,5],[1,1.44,130.21],[2,1.33,88.05]],"ltp":1.5,"tv":236.98,"id":60971788},{"batb":[[0,2.72,5],[1,2.7,24],[2,1.28,178.57]],"ltp":3.0,"tv":134.09,"id":60971786}]}]}
{"op":"mcm","clk":"11932387052","pt":1724742250726,"mc":[{"id":"1.232260815","rc":[{"batb":[[0,1.44,130.21],[1,1.33,88.05],[2,1.28,178.57]],"ltp":1.5,"tv":236.98,"id":60971788},{"batb":[[0,2.7,24],[1,1.28,178.57],[2,1.23,217.39]],"ltp":3.0,"tv":134.09,"id":60971786}]}]}
{"op":"mcm","clk":"11932387132","pt":1724742253035,"mc":[{"id":"1.232260815","rc":[{"batb":[[0,1.45,5],[1,1.44,130.21],[2,1.33,88.05]],"ltp":1.5,"tv":236.98,"id":60971788},{"batb":[[0,2.72,5],[1,2.7,24],[2,1.28,178.57]],"ltp":3.0,"tv":134.09,"id":60971786}]}]}
{"op":"mcm","clk":"11932387280","pt":1724742256527,"mc":[{"id":"1.232260815","rc":[{"batb":[[0,1.44,130.21],[1,1.33,88.05],[2,1.28,178.57]],"ltp":1.5,"tv":236.98,"id":60971788},{"batb":[[0,2.7,24],[1,1.28,178.57],[2,1.23,217.39]],"ltp":3.0,"tv":134.09,"id":60971786}]}]}
{"op":"mcm","clk":"11932387404","pt":1724742259453,"mc":[{"id":"1.232260815","rc":[{"batb":[[0,1.45,5],[1,1.44,130.21],[2,1.33,88.05]],"ltp":1.5,"tv":236.98,"id":60971788},{"batb":[[0,2.72,5],[1,2.7,24],[2,1.28,178.57]],"ltp":3.0,"tv":134.09,"id":60971786}]}]}
{"op":"mcm","clk":"11932387531","pt":1724742262943,"mc":[{"id":"1.232260815","rc":[{"batb":[[0,1.44,130.21],[1,1.33,88.05],[2,1.28,178.57]],"ltp":1.5,"tv":236.98,"id":60971788},{"batb":[[0,2.7,24],[1,1.28,178.57],[2,1.23,217.39]],"ltp":3.0,"tv":134.09,"id":60971786}]}]}
{"op":"mcm","clk":"11932387619","pt":1724742265454,"mc":[{"id":"1.232260815","rc":[{"batb":[[0,1.45,5],[1,1.44,130.21],[2,1.33,88.05]],"ltp":1.5,"tv":236.98,"id":60971788},{"batb":[[0,2.72,5],[1,2.7,24],[2,1.28,178.57]],"ltp":3.0,"tv":134.09,"id":60971786}]}]}
{"op":"mcm","clk":"11932387776","pt":1724742268842,"mc":[{"id":"1.232260815","rc":[{"batb":[[0,1.44,130.21],[1,1.33,88.05],[2,1.28,178.57]],"ltp":1.5,"tv":236.98,"id":60971788},{"batb":[[0,2.7,24],[1,1.28,178.57],[2,1.23,217.39]],"ltp":3.0,"tv":134.09,"id":60971786}]}]}
{"op":"mcm","clk":"11932387871","pt":1724742271146,"mc":[{"id":"1.232260815","rc":[{"batb":[[0,1.45,5],[1,1.44,130.21],[2,1.33,88.05]],"ltp":1.5,"tv":236.98,"id":60971788},{"batb":[[0,2.72,5],[1,2.7,24],[2,1.28,178.57]],"ltp":3.0,"tv":134.09,"id":60971786}]}]}
{"op":"mcm","clk":"11932387984","pt":1724742274628,"mc":[{"id":"1.232260815","rc":[{"batb":[[0,1.44,130.21],[1,1.33,88.05],[2,1.28,178.57]],"ltp":1.5,"tv":236.98,"id":60971788},{"batb":[[0,2.7,24],[1,1.28,178.57],[2,1.23,217.39]],"ltp":3.0,"tv":134.09,"id":60971786}]}]}
{"op":"mcm","clk":"11932388092","pt":1724742276829,"mc":[{"id":"1.232260815","rc":[{"batb":[[0,1.45,5],[1,1.44,130.21],[2,1.33,88.05]],"ltp":1.5,"tv":236.98,"id":60971788},{"batb":[[0,2.72,5],[1,2.7,24],[2,1.28,178.57]],"ltp":3.0,"tv":134.09,"id":60971786}]}]}
{"op":"mcm","clk":"11932388231","pt":1724742280173,"mc":[{"id":"1.232260815","rc":[{"batb":[[0,1.44,130.21],[1,1.33,88.05],[2,1.28,178.57]],"ltp":1.5,"tv":236.98,"id":60971788},{"batb":[[0,2.7,24],[1,1.28,178.57],[2,1.23,217.39]],"ltp":3.0,"tv":134.09,"id":60971786}]}]}
{"op":"mcm","clk":"11932388328","pt":1724742282437,"mc":[{"id":"1.232260815","rc":[{"batb":[[0,1.45,5],[1,1.44,130.21],[2,1.33,88.05]],"ltp":1.5,"tv":236.98,"id":60971788},{"batb":[[0,2.72,5],[1,2.7,24],[2,1.28,178.57]],"ltp":3.0,"tv":134.09,"id":60971786}]}]}
{"op":"mcm","clk":"11932388496","pt":1724742285774,"mc":[{"id":"1.232260815","rc":[{"batb":[[0,1.44,130.21],[1,1.33,88.05],[2,1.28,178.57]],"ltp":1.5,"tv":236.98,"id":60971788},{"batb":[[0,2.7,24],[1,1.28,178.57],[2,1.23,217.39]],"ltp":3.0,"tv":134.09,"id":60971786}]}]}
{"op":"mcm","clk":"11932388593","pt":1724742288181,"mc":[{"id":"1.232260815","rc":[{"batb":[[0,1.45,5],[1,1.44,130.21],[2,1.33,88.05]],"ltp":1.5,"tv":236.98,"id":60971788},{"batb":[[0,2.72,5],[1,2.7,24],[2,1.28,178.57]],"ltp":3.0,"tv":134.09,"id":60971786}]}]}
{"op":"mcm","clk":"11932388719","pt":1724742291361,"mc":[{"id":"1.232260815","rc":[{"batb":[[0,1.44,130.21],[1,1.33,88.05],[2,1.28,178.57]],"ltp":1.5,"tv":236.98,"id":60971788},{"batb":[[0,2.7,24],[1,1.28,178.57],[2,1.23,217.39]],"ltp":3.0,"tv":134.09,"id":60971786}]}]}
{"op":"mcm","clk":"11932388814","pt":1724742293561,"mc":[{"id":"1.232260815","rc":[{"batb":[[0,1.45,5],[1,1.44,130.21],[2,1.33,88.05]],"ltp":1.5,"tv":236.98,"id":60971788},{"batb":[[0,2.72,5],[1,2.7,24],[2,1.28,178.57]],"ltp":3.0,"tv":134.09,"id":60971786}]}]}
{"op":"mcm","clk":"11932388957","pt":1724742296888,"mc":[{"id":"1.232260815","rc":[{"batb":[[0,1.44,130.21],[1,1.33,88.05],[2,1.28,178.57]],"ltp":1.5,"tv":236.98,"id":60971788},{"batb":[[0,2.7,24],[1,1.28,178.57],[2,1.23,217.39]],"ltp":3.0,"tv":134.09,"id":60971786}]}]}
{"op":"mcm","clk":"11932389026","pt":1724742299091,"mc":[{"id":"1.232260815","rc":[{"batb":[[0,1.45,5],[1,1.44,130.21],[2,1.33,88.05]],"ltp":1.5,"tv":236.98,"id":60971788},{"batb":[[0,2.72,5],[1,2.7,24],[2,1.28,178.57]],"ltp":3.0,"tv":134.09,"id":60971786}]}]}
{"op":"mcm","clk":"11932389179","pt":1724742302298,"mc":[{"id":"1.232260815","rc":[{"batb":[[0,1.44,130.21],[1,1.33,88.05],[2,1.28,178.57]],"ltp":1.5,"tv":236.98,"id":60971788}]}]}
{"op":"mcm","clk":"11932389183","pt":1724742302400,"mc":[{"id":"1.232260815","rc":[{"batb":[[0,2.7,24],[1,1.28,178.57],[2,1.23,217.39]],"ltp":3.0,"tv":134.09,"id":60971786}]}]}
{"op":"mcm","clk":"11932389299","pt":1724742304706,"mc":[{"id":"1.232260815","rc":[{"batb":[[0,1.45,5],[1,1.44,130.21],[2,1.33,88.05]],"ltp":1.5,"tv":236.98,"id":60971788},{"batb":[[0,2.72,5],[1,2.7,24],[2,1.28,178.57]],"ltp":3.0,"tv":134.09,"id":60971786}]}]}
{"op":"mcm","clk":"11932389414","pt":1724742308091,"mc":[{"id":"1.232260815","rc":[{"batb":[[0,1.44,130.21],[1,1.33,88.05],[2,1.28,178.57]],"ltp":1.5,"tv":236.98,"id":60971788},{"batb":[[0,2.7,24],[1,1.28,178.57],[2,1.23,217.39]],"ltp":3.0,"tv":134.09,"id":60971786}]}]}
{"op":"mcm","clk":"11932389505","pt":1724742310294,"mc":[{"id":"1.232260815","rc":[{"batb":[[0,1.45,5],[1,1.44,130.21],[2,1.33,88.05]],"ltp":1.5,"tv":236.98,"id":60971788},{"batb":[[0,2.72,5],[1,2.7,24],[2,1.28,178.57]],"ltp":3.0,"tv":134.09,"id":60971786}]}]}
{"op":"mcm","clk":"11932389626","pt":1724742313718,"mc":[{"id":"1.232260815","rc":[{"batb":[[0,1.44,130.21],[1,1.33,88.05],[2,1.28,178.57]],"ltp":1.5,"tv":236.98,"id":60971788},{"batb":[[0,2.7,24],[1,1.28,178.57],[2,1.23,217.39]],"ltp":3.0,"tv":134.09,"id":60971786}]}]}
{"op":"mcm","clk":"11932389771","pt":1724742317096,"mc":[{"id":"1.232260815","rc":[{"batb":[[0,1.45,5],[1,1.44,130.21],[2,1.33,88.05]],"ltp":1.5,"tv":236.98,"id":60971788},{"batb":[[0,2.72,5],[1,2.7,24],[2,1.28,178.57]],"ltp":3.0,"tv":134.09,"id":60971786}]}]}
{"op":"mcm","clk":"11932389951","pt":1724742320688,"mc":[{"id":"1.232260815","rc":[{"batb":[[0,1.44,130.21],[1,1.33,88.05],[2,1.28,178.57]],"ltp":1.5,"tv":236.98,"id":60971788},{"batb":[[0,2.7,24],[1,1.28,178.57],[2,1.23,217.39]],"ltp":3.0,"tv":134.09,"id":60971786}]}]}
{"op":"mcm","clk":"11932390063","pt":1724742323090,"mc":[{"id":"1.232260815","rc":[{"batb":[[0,1.45,5],[1,1.44,130.21],[2,1.33,88.05]],"ltp":1.5,"tv":236.98,"id":60971788},{"batb":[[0,2.72,5],[1,2.7,24],[2,1.28,178.57]],"ltp":3.0,"tv":134.09,"id":60971786}]}]}
{"op":"mcm","clk":"11932390219","pt":1724742326623,"mc":[{"id":"1.232260815","rc":[{"batb":[[0,1.44,130.21],[1,1.33,88.05],[2,1.28,178.57]],"ltp":1.5,"tv":236.98,"id":60971788},{"batb":[[0,2.7,24],[1,1.28,178.57],[2,1.23,217.39]],"ltp":3.0,"tv":134.09,"id":60971786}]}]}
{"op":"mcm","clk":"11932390384","pt":1724742330416,"mc":[{"id":"1.232260815","rc":[{"batb":[[0,1.45,5],[1,1.44,130.21],[2,1.33,88.05]],"ltp":1.5,"tv":236.98,"id":60971788},{"batb":[[0,2.72,5],[1,2.7,24],[2,1.28,178.57]],"ltp":3.0,"tv":134.09,"id":60971786}]}]}
{"op":"mcm","clk":"11932390502","pt":1724742333703,"mc":[{"id":"1.232260815","rc":[{"batb":[[0,1.44,130.21],[1,1.33,88.05],[2,1.28,178.57]],"ltp":1.5,"tv":236.98,"id":60971788},{"batb":[[0,2.7,24],[1,1.28,178.57],[2,1.23,217.39]],"ltp":3.0,"tv":134.09,"id":60971786}]}]}
{"op":"mcm","clk":"11932390597","pt":1724742336125,"mc":[{"id":"1.232260815","rc":[{"batb":[[0,1.45,5],[1,1.44,130.21],[2,1.33,88.05]],"ltp":1.5,"tv":236.98,"id":60971788},{"batb":[[0,2.72,5],[1,2.7,24],[2,1.28,178.57]],"ltp":3.0,"tv":134.09,"id":60971786}]}]}
{"op":"mcm","clk":"11932390755","pt":1724742339502,"mc":[{"id":"1.232260815","rc":[{"batb":[[0,1.44,130.21],[1,1.33,88.05],[2,1.28,178.57]],"ltp":1.5,"tv":236.98,"id":60971788},{"batb":[[0,2.7,24],[1,1.28,178.57],[2,1.23,217.39]],"ltp":3.0,"tv":134.09,"id":60971786}]}]}
{"op":"mcm","clk":"11932390893","pt":1724742342531,"mc":[{"id":"1.232260815","rc":[{"batb":[[0,1.45,5],[1,1.44,130.21],[2,1.33,88.05]],"ltp":1.5,"tv":236.98,"id":60971788},{"batb":[[0,2.72,5],[1,2.7,24],[2,1.28,178.57]],"ltp":3.0,"tv":134.09,"id":60971786}]}]}
{"op":"mcm","clk":"11932391029","pt":1724742346018,"mc":[{"id":"1.232260815","rc":[{"batb":[[0,1.44,130.21],[1,1.33,88.05],[2,1.28,178.57]],"ltp":1.5,"tv":236.98,"id":60971788},{"batb":[[0,2.7,24],[1,1.28,178.57],[2,1.23,217.39]],"ltp":3.0,"tv":134.09,"id":60971786}]}]}
{"op":"mcm","clk":"11932391119","pt":1724742348217,"mc":[{"id":"1.232260815","rc":[{"batb":[[0,1.45,5],[1,1.44,130.21],[2,1.33,88.05]],"ltp":1.5,"tv":236.98,"id":60971788},{"batb":[[0,2.72,5],[1,2.7,24],[2,1.28,178.57]],"ltp":3.0,"tv":134.09,"id":60971786}]}]}
{"op":"mcm","clk":"11932391281","pt":1724742351648,"mc":[{"id":"1.232260815","rc":[{"batb":[[0,1.44,130.21],[1,1.33,88.05],[2,1.28,178.57]],"ltp":1.5,"tv":236.98,"id":60971788},{"batb":[[0,2.7,24],[1,1.28,178.57],[2,1.23,217.39]],"ltp":3.0,"tv":134.09,"id":60971786}]}]}
{"op":"mcm","clk":"11932391373","pt":1724742353953,"mc":[{"id":"1.232260815","rc":[{"batb":[[0,1.45,5],[1,1.44,130.21],[2,1.33,88.05]],"ltp":1.5,"tv":236.98,"id":60971788},{"batb":[[0,2.72,5],[1,2.7,24],[2,1.28,178.57]],"ltp":3.0,"tv":134.09,"id":60971786}]}]}
{"op":"mcm","clk":"11932391506","pt":1724742357342,"mc":[{"id":"1.232260815","rc":[{"batb":[[0,1.44,130.21],[1,1.33,88.05],[2,1.28,178.57]],"ltp":1.5,"tv":236.98,"id":60971788},{"batb":[[0,2.7,24],[1,1.28,178.57],[2,1.23,217.39]],"ltp":3.0,"tv":134.09,"id":60971786}]}]}
{"op":"mcm","clk":"11932391574","pt":1724742359641,"mc":[{"id":"1.232260815","rc":[{"batb":[[0,1.45,5],[1,1.44,130.21],[2,1.33,88.05]],"ltp":1.5,"tv":236.98,"id":60971788},{"batb":[[0,2.72,5],[1,2.7,24],[2,1.28,178.57]],"ltp":3.0,"tv":134.09,"id":60971786}]}]}
{"op":"mcm","clk":"11932391712","pt":1724742363093,"mc":[{"id":"1.232260815","rc":[{"batb":[[0,1.44,130.21],[1,1.33,88.05],[2,1.28,178.57]],"batl":[[0,1.58,2],[1,24,1.52]],"ltp":1.5,"tv":236.98,"id":60971788},{"batb":[[0,2.7,24],[1,1.28,178.57],[2,1.23,217.39]],"ltp":3.0,"tv":134.09,"id":60971786}]}]}
{"op":"mcm","clk":"11932391802","pt":1724742365354,"mc":[{"id":"1.232260815","rc":[{"batb":[[0,2.72,5],[1,2.7,24],[2,1.28,178.57]],"ltp":3.0,"tv":134.09,"id":60971786}]}]}
{"op":"mcm","clk":"11932391915","pt":1724742368583,"mc":[{"id":"1.232260815","rc":[{"batb":[[0,2.7,24],[1,1.28,178.57],[2,1.23,217.39]],"ltp":3.0,"tv":134.09,"id":60971786}]}]}
{"op":"mcm","clk":"11932391998","pt":1724742370740,"mc":[{"id":"1.232260815","rc":[{"batb":[[0,2.72,5],[1,2.7,24],[2,1.28,178.57]],"ltp":3.0,"tv":134.09,"id":60971786}]}]}
{"op":"mcm","clk":"11932392120","pt":1724742374078,"mc":[{"id":"1.232260815","rc":[{"batb":[[0,2.7,24],[1,1.28,178.57],[2,1.23,217.39]],"ltp":3.0,"tv":134.09,"id":60971786}]}]}
{"op":"mcm","clk":"11932392194","pt":1724742376286,"mc":[{"id":"1.232260815","rc":[{"batb":[[0,2.72,5],[1,2.7,24],[2,1.28,178.57]],"ltp":3.0,"tv":134.09,"id":60971786}]}]}
{"op":"mcm","clk":"11932392325","pt":1724742379769,"mc":[{"id":"1.232260815","rc":[{"batb":[[0,2.7,24],[1,1.28,178.57],[2,1.23,217.39]],"ltp":3.0,"tv":134.09,"id":60971786}]}]}
{"op":"mcm","clk":"11932392406","pt":1724742381983,"mc":[{"id":"1.232260815","rc":[{"batb":[[0,2.72,5],[1,2.7,24],[2,1.28,178.57]],"ltp":3.0,"tv":134.09,"id":60971786}]}]}
{"op":"mcm","clk":"11932392515","pt":1724742385162,"mc":[{"id":"1.232260815","rc":[{"batb":[[0,2.7,24],[1,1.28,178.57],[2,1.23,217.39]],"ltp":3.0,"tv":134.09,"id":60971786}]}]}
{"op":"mcm","clk":"11932392606","pt":1724742387480,"mc":[{"id":"1.232260815","rc":[{"batb":[[0,2.72,5],[1,2.7,24],[2,1.28,178.57]],"ltp":3.0,"tv":134.09,"id":60971786}]}]}
{"op":"mcm","clk":"11932392737","pt":1724742390868,"mc":[{"id":"1.232260815","rc":[{"batb":[[0,2.7,24],[1,1.28,178.57],[2,1.23,217.39]],"ltp":3.0,"tv":134.09,"id":60971786}]}]}
{"op":"mcm","clk":"11932392837","pt":1724742393889,"mc":[{"id":"1.232260815","rc":[{"batb":[[0,2.72,5],[1,2.7,24],[2,1.28,178.57]],"ltp":3.0,"tv":134.09,"id":60971786}]}]}
{"op":"mcm","clk":"11932392974","pt":1724742397395,"mc":[{"id":"1.232260815","rc":[{"batb":[[0,2.7,24],[1,1.28,178.57],[2,1.23,217.39]],"ltp":3.0,"tv":134.09,"id":60971786}]}]}
{"op":"mcm","clk":"11932393210","pt":1724742403289,"mc":[{"id":"1.232260815","rc":[{"batb":[[0,2.72,5],[1,2.7,24],[2,1.28,178.57]],"ltp":3.0,"tv":134.09,"id":60971786}]}]}
{"op":"mcm","clk":"11932393323","pt":1724742406536,"mc":[{"id":"1.232260815","rc":[{"batb":[[0,2.7,24],[1,1.28,178.57],[2,1.23,217.39]],"ltp":3.0,"tv":134.09,"id":60971786}]}]}
{"op":"mcm","clk":"11932393431","pt":1724742409021,"mc":[{"id":"1.232260815","rc":[{"batb":[[0,2.72,5],[1,2.7,24],[2,1.28,178.57]],"ltp":3.0,"tv":134.09,"id":60971786}]}]}
{"op":"mcm","clk":"11932393587","pt":1724742412521,"mc":[{"id":"1.232260815","rc":[{"batb":[[0,2.7,24],[1,1.28,178.57],[2,1.23,217.39]],"ltp":3.0,"tv":134.09,"id":60971786}]}]}
{"op":"mcm","clk":"11932393846","pt":1724742417717,"mc":[{"id":"1.232260815","rc":[{"batb":[[0,2.72,5],[1,2.7,24],[2,1.28,178.57]],"ltp":3.0,"tv":134.09,"id":60971786}]}]}
{"op":"mcm","clk":"11932393981","pt":1724742421116,"mc":[{"id":"1.232260815","rc":[{"batb":[[0,2.7,24],[1,1.28,178.57],[2,1.23,217.39]],"ltp":3.0,"tv":134.09,"id":60971786}]}]}
{"op":"mcm","clk":"11932394066","pt":1724742423233,"mc":[{"id":"1.232260815","rc":[{"batb":[[0,2.72,5],[1,2.7,24],[2,1.28,178.57]],"ltp":3.0,"tv":134.09,"id":60971786}]}]}
{"op":"mcm","clk":"11932394193","pt":1724742426339,"mc":[{"id":"1.232260815","rc":[{"batb":[[0,2.7,24],[1,1.28,178.57],[2,1.23,217.39]],"ltp":3.0,"tv":134.09,"id":60971786}]}]}
{"op":"mcm","clk":"11932394279","pt":1724742428651,"mc":[{"id":"1.232260815","rc":[{"batb":[[0,2.72,5],[1,2.7,24],[2,1.28,178.57]],"ltp":3.0,"tv":134.09,"id":60971786}]}]}
{"op":"mcm","clk":"11932394420","pt":1724742431849,"mc":[{"id":"1.232260815","rc":[{"batb":[[0,2.7,24],[1,1.28,178.57],[2,1.23,217.39]],"ltp":3.0,"tv":134.09,"id":60971786}]}]}
{"op":"mcm","clk":"11932394532","pt":1724742434260,"mc":[{"id":"1.232260815","rc":[{"batb":[[0,2.72,5],[1,2.7,24],[2,1.28,178.57]],"ltp":3.0,"tv":134.09,"id":60971786}]}]}
{"op":"mcm","clk":"11932394696","pt":1724742437557,"mc":[{"id":"1.232260815","rc":[{"batb":[[0,2.7,24],[1,1.28,178.57],[2,1.23,217.39]],"ltp":3.0,"tv":134.09,"id":60971786}]}]}
{"op":"mcm","clk":"11932394810","pt":1724742439822,"mc":[{"id":"1.232260815","rc":[{"batb":[[0,2.72,5],[1,2.7,24],[2,1.28,178.57]],"ltp":3.0,"tv":134.09,"id":60971786}]}]}
{"op":"mcm","clk":"11932394975","pt":1724742443029,"mc":[{"id":"1.232260815","rc":[{"batb":[[0,2.7,24],[1,1.28,178.57],[2,1.23,217.39]],"ltp":3.0,"tv":134.09,"id":60971786}]}]}
{"op":"mcm","clk":"11932395068","pt":1724742445350,"mc":[{"id":"1.232260815","rc":[{"batb":[[0,2.72,5],[1,2.7,24],[2,1.28,178.57]],"ltp":3.0,"tv":134.09,"id":60971786}]}]}
{"op":"mcm","clk":"11932395211","pt":1724742448679,"mc":[{"id":"1.232260815","rc":[{"batb":[[0,2.7,24],[1,1.28,178.57],[2,1.23,217.39]],"ltp":3.0,"tv":134.09,"id":60971786}]}]}
{"op":"mcm","clk":"11932395289","pt":1724742450974,"mc":[{"id":"1.232260815","rc":[{"batb":[[0,2.72,5],[1,2.7,24],[2,1.28,178.57]],"ltp":3.0,"tv":134.09,"id":60971786}]}]}
{"op":"mcm","clk":"11932395428","pt":1724742454370,"mc":[{"id":"1.232260815","rc":[{"batb":[[0,2.7,24],[1,1.28,178.57],[2,1.23,217.39]],"ltp":3.0,"tv":134.09,"id":60971786}]}]}
{"op":"mcm","clk":"11932395550","pt":1724742457486,"mc":[{"id":"1.232260815","rc":[{"batb":[[0,2.72,5],[1,2.7,24],[2,1.28,178.57]],"ltp":3.0,"tv":134.09,"id":60971786}]}]}
{"op":"mcm","clk":"11932395662","pt":1724742460766,"mc":[{"id":"1.232260815","rc":[{"batb":[[0,2.7,24],[1,1.28,178.57],[2,1.23,217.39]],"ltp":3.0,"tv":134.09,"id":60971786}]}]}
{"op":"mcm","clk":"11932395775","pt":1724742463171,"mc":[{"id":"1.232260815","rc":[{"batb":[[0,2.72,5],[1,2.7,24],[2,1.28,178.57]],"ltp":3.0,"tv":134.09,"id":60971786}]}]}
{"op":"mcm","clk":"11932395884","pt":1724742466587,"mc":[{"id":"1.232260815","rc":[{"batb":[[0,2.7,24],[1,1.28,178.57],[2,1.23,217.39]],"ltp":3.0,"tv":134.09,"id":60971786}]}]}
{"op":"mcm","clk":"11932395994","pt":1724742469702,"mc":[{"id":"1.232260815","rc":[{"batb":[[0,2.72,5],[1,2.7,24],[2,1.28,178.57]],"ltp":3.0,"tv":134.09,"id":60971786}]}]}
{"op":"mcm","clk":"11932396105","pt":1724742472981,"mc":[{"id":"1.232260815","rc":[{"batb":[[0,2.7,24],[1,1.28,178.57],[2,1.23,217.39]],"ltp":3.0,"tv":134.09,"id":60971786}]}]}
{"op":"mcm","clk":"11932396195","pt":1724742475404,"mc":[{"id":"1.232260815","rc":[{"batb":[[0,2.72,5],[1,2.7,24],[2,1.28,178.57]],"ltp":3.0,"tv":134.09,"id":60971786}]}]}
{"op":"mcm","clk":"11932396324","pt":1724742478716,"mc":[{"id":"1.232260815","rc":[{"batb":[[0,2.7,24],[1,1.28,178.57],[2,1.23,217.39]],"ltp":3.0,"tv":134.09,"id":60971786}]}]}
{"op":"mcm","clk":"11932396414","pt":1724742481181,"mc":[{"id":"1.232260815","rc":[{"batb":[[0,2.72,5],[1,2.7,24],[2,1.28,178.57]],"ltp":3.0,"tv":134.09,"id":60971786}]}]}
{"op":"mcm","clk":"11932396544","pt":1724742484507,"mc":[{"id":"1.232260815","rc":[{"batb":[[0,2.7,24],[1,1.28,178.57],[2,1.23,217.39]],"ltp":3.0,"tv":134.09,"id":60971786}]}]}
{"op":"mcm","clk":"11932396634","pt":1724742486901,"mc":[{"id":"1.232260815","rc":[{"batb":[[0,2.72,5],[1,2.7,24],[2,1.28,178.57]],"ltp":3.0,"tv":134.09,"id":60971786}]}]}
{"op":"mcm","clk":"11932396765","pt":1724742490521,"mc":[{"id":"1.232260815","rc":[{"batb":[[0,2.7,24],[1,1.28,178.57],[2,1.23,217.39]],"ltp":3.0,"tv":134.09,"id":60971786}]}]}
{"op":"mcm","clk":"11932396867","pt":1724742493339,"mc":[{"id":"1.232260815","rc":[{"batb":[[0,2.72,5],[1,2.7,24],[2,1.28,178.57]],"ltp":3.0,"tv":134.09,"id":60971786}]}]}
{"op":"mcm","clk":"11932396979","pt":1724742496719,"mc":[{"id":"1.232260815","rc":[{"batb":[[0,2.7,24],[1,1.28,178.57],[2,1.23,217.39]],"ltp":3.0,"tv":134.09,"id":60971786}]}]}
{"op":"mcm","clk":"11932397091","pt":1724742499930,"mc":[{"id":"1.232260815","rc":[{"batb":[[0,2.72,5],[1,2.7,24],[2,1.28,178.57]],"ltp":3.0,"tv":134.09,"id":60971786}]}]}
{"op":"mcm","clk":"11932397217","pt":1724742503259,"mc":[{"id":"1.232260815","rc":[{"batb":[[0,2.7,24],[1,1.28,178.57],[2,1.23,217.39]],"ltp":3.0,"tv":134.09,"id":60971786}]}]}
{"op":"mcm","clk":"11932397318","pt":1724742505531,"mc":[{"id":"1.232260815","rc":[{"batb":[[0,2.72,5],[1,2.7,24],[2,1.28,178.57]],"ltp":3.0,"tv":134.09,"id":60971786}]}]}
{"op":"mcm","clk":"11932397473","pt":1724742509026,"mc":[{"id":"1.232260815","rc":[{"batb":[[0,2.7,24],[1,1.28,178.57],[2,1.23,217.39]],"ltp":3.0,"tv":134.09,"id":60971786}]}]}
{"op":"mcm","clk":"11932397579","pt":1724742511326,"mc":[{"id":"1.232260815","rc":[{"batb":[[0,2.72,5],[1,2.7,24],[2,1.28,178.57]],"ltp":3.0,"tv":134.09,"id":60971786}]}]}
{"op":"mcm","clk":"11932397743","pt":1724742514562,"mc":[{"id":"1.232260815","rc":[{"batb":[[0,2.7,24],[1,1.28,178.57],[2,1.23,217.39]],"ltp":3.0,"tv":134.09,"id":60971786}]}]}
{"op":"mcm","clk":"11932397869","pt":1724742516970,"mc":[{"id":"1.232260815","rc":[{"batb":[[0,2.72,5],[1,2.7,24],[2,1.28,178.57]],"ltp":3.0,"tv":134.09,"id":60971786}]}]}
{"op":"mcm","clk":"11932398006","pt":1724742520347,"mc":[{"id":"1.232260815","rc":[{"batb":[[0,2.7,24],[1,1.28,178.57],[2,1.23,217.39]],"ltp":3.0,"tv":134.09,"id":60971786}]}]}
{"op":"mcm","clk":"11932398092","pt":1724742522652,"mc":[{"id":"1.232260815","rc":[{"batb":[[0,2.72,5],[1,2.7,24],[2,1.28,178.57]],"ltp":3.0,"tv":134.09,"id":60971786}]}]}
{"op":"mcm","clk":"11932398250","pt":1724742525976,"mc":[{"id":"1.232260815","rc":[{"batb":[[0,2.7,24],[1,1.28,178.57],[2,1.23,217.39]],"ltp":3.0,"tv":134.09,"id":60971786}]}]}
{"op":"mcm","clk":"11932398360","pt":1724742528175,"mc":[{"id":"1.232260815","rc":[{"batb":[[0,2.72,5],[1,2.7,24],[2,1.28,178.57]],"ltp":3.0,"tv":134.09,"id":60971786}]}]}
{"op":"mcm","clk":"11932398487","pt":1724742531449,"mc":[{"id":"1.232260815","rc":[{"batb":[[0,2.7,24],[1,1.28,178.57],[2,1.23,217.39]],"ltp":3.0,"tv":134.09,"id":60971786}]}]}
{"op":"mcm","clk":"11932398585","pt":1724742533750,"mc":[{"id":"1.232260815","rc":[{"batb":[[0,2.72,5],[1,2.7,24],[2,1.28,178.57]],"ltp":3.0,"tv":134.09,"id":60971786}]}]}
{"op":"mcm","clk":"11932398728","pt":1724742537276,"mc":[{"id":"1.232260815","rc":[{"batb":[[0,2.7,24],[1,1.28,178.57],[2,1.23,217.39]],"ltp":3.0,"tv":134.09,"id":60971786}]}]}
{"op":"mcm","clk":"11932398831","pt":1724742539494,"mc":[{"id":"1.232260815","rc":[{"batb":[[0,2.72,5],[1,2.7,24],[2,1.28,178.57]],"ltp":3.0,"tv":134.09,"id":60971786}]}]}
{"op":"mcm","clk":"11932398981","pt":1724742542788,"mc":[{"id":"1.232260815","rc":[{"batb":[[0,2.7,24],[1,1.28,178.57],[2,1.23,217.39]],"ltp":3.0,"tv":134.09,"id":60971786}]}]}
{"op":"mcm","clk":"11932399078","pt":1724742545093,"mc":[{"id":"1.232260815","rc":[{"batb":[[0,2.72,5],[1,2.7,24],[2,1.28,178.57]],"ltp":3.0,"tv":134.09,"id":60971786}]}]}
{"op":"mcm","clk":"11932399233","pt":1724742548477,"mc":[{"id":"1.232260815","rc":[{"batb":[[0,2.7,24],[1,1.28,178.57],[2,1.23,217.39]],"ltp":3.0,"tv":134.09,"id":60971786}]}]}
{"op":"mcm","clk":"11932399341","pt":1724742550883,"mc":[{"id":"1.232260815","rc":[{"batb":[[0,2.72,5],[1,2.7,24],[2,1.28,178.57]],"ltp":3.0,"tv":134.09,"id":60971786}]}]}
{"op":"mcm","clk":"11932399478","pt":1724742554072,"mc":[{"id":"1.232260815","rc":[{"batb":[[0,2.7,24],[1,1.28,178.57],[2,1.23,217.39]],"ltp":3.0,"tv":134.09,"id":60971786}]}]}
{"op":"mcm","clk":"11932399583","pt":1724742556785,"mc":[{"id":"1.232260815","rc":[{"batb":[[0,2.72,5],[1,2.7,24],[2,1.28,178.57]],"ltp":3.0,"tv":134.09,"id":60971786}]}]}
{"op":"mcm","clk":"11932399709","pt":1724742559986,"mc":[{"id":"1.232260815","rc":[{"batb":[[0,2.7,24],[1,1.28,178.57],[2,1.23,217.39]],"ltp":3.0,"tv":134.09,"id":60971786}]}]}
{"op":"mcm","clk":"11932399799","pt":1724742562142,"mc":[{"id":"1.232260815","rc":[{"batb":[[0,2.72,5],[1,2.7,24],[2,1.28,178.57]],"ltp":3.0,"tv":134.09,"id":60971786}]}]}
{"op":"mcm","clk":"11932399947","pt":1724742565418,"mc":[{"id":"1.232260815","rc":[{"batb":[[0,2.7,24],[1,1.28,178.57],[2,1.23,217.39]],"ltp":3.0,"tv":134.09,"id":60971786}]}]}
{"op":"mcm","clk":"11932400033","pt":1724742567616,"mc":[{"id":"1.232260815","rc":[{"batb":[[0,2.72,5],[1,2.7,24],[2,1.28,178.57]],"ltp":3.0,"tv":134.09,"id":60971786}]}]}
{"op":"mcm","clk":"11932400167","pt":1724742571053,"mc":[{"id":"1.232260815","rc":[{"batb":[[0,2.7,24],[1,1.28,178.57],[2,1.23,217.39]],"ltp":3.0,"tv":134.09,"id":60971786}]}]}
{"op":"mcm","clk":"11932400247","pt":1724742573267,"mc":[{"id":"1.232260815","rc":[{"batb":[[0,2.72,5],[1,2.7,24],[2,1.28,178.57]],"ltp":3.0,"tv":134.09,"id":60971786}]}]}
{"op":"mcm","clk":"11932400375","pt":1724742576660,"mc":[{"id":"1.232260815","rc":[{"batb":[[0,2.7,24],[1,1.28,178.57],[2,1.23,217.39]],"ltp":3.0,"tv":134.09,"id":60971786}]}]}
{"op":"mcm","clk":"11932400440","pt":1724742578864,"mc":[{"id":"1.232260815","rc":[{"batb":[[0,2.72,5],[1,2.7,24],[2,1.28,178.57]],"ltp":3.0,"tv":134.09,"id":60971786}]}]}
{"op":"mcm","clk":"11932400583","pt":1724742582159,"mc":[{"id":"1.232260815","rc":[{"batb":[[0,2.7,24],[1,1.28,178.57],[2,1.23,217.39]],"ltp":3.0,"tv":134.09,"id":60971786}]}]}
{"op":"mcm","clk":"11932400696","pt":1724742584571,"mc":[{"id":"1.232260815","rc":[{"batb":[[0,2.72,5],[1,2.7,24],[2,1.28,178.57]],"ltp":3.0,"tv":134.09,"id":60971786}]}]}
{"op":"mcm","clk":"11932400825","pt":1724742587751,"mc":[{"id":"1.232260815","rc":[{"batb":[[0,2.7,24],[1,1.28,178.57],[2,1.23,217.39]],"ltp":3.0,"tv":134.09,"id":60971786}]}]}
{"op":"mcm","clk":"11932400915","pt":1724742590159,"mc":[{"id":"1.232260815","rc":[{"batb":[[0,2.72,5],[1,2.7,24],[2,1.28,178.57]],"ltp":3.0,"tv":134.09,"id":60971786}]}]}
{"op":"mcm","clk":"11932401054","pt":1724742593668,"mc":[{"id":"1.232260815","rc":[{"batb":[[0,2.7,24],[1,1.28,178.57],[2,1.23,217.39]],"ltp":3.0,"tv":134.09,"id":60971786}]}]}
{"op":"mcm","clk":"11932401165","pt":1724742596643,"mc":[{"id":"1.232260815","rc":[{"batb":[[0,2.72,5],[1,2.7,24],[2,1.28,178.57]],"ltp":3.0,"tv":134.09,"id":60971786}]}]}
{"op":"mcm","clk":"11932401302","pt":1724742600080,"mc":[{"id":"1.232260815","rc":[{"batb":[[0,2.7,24],[1,1.28,178.57],[2,1.23,217.39]],"ltp":3.0,"tv":134.09,"id":60971786}]}]}
{"op":"mcm","clk":"11932401399","pt":1724742602294,"mc":[{"id":"1.232260815","rc":[{"batb":[[0,2.72,5],[1,2.7,24],[2,1.28,178.57]],"ltp":3.0,"tv":134.09,"id":60971786}]}]}
{"op":"mcm","clk":"11932401526","pt":1724742605685,"mc":[{"id":"1.232260815","rc":[{"batb":[[0,2.7,24],[1,1.28,178.57],[2,1.23,217.39]],"ltp":3.0,"tv":134.09,"id":60971786}]}]}
{"op":"mcm","clk":"11932401648","pt":1724742608768,"mc":[{"id":"1.232260815","rc":[{"batb":[[0,2.72,5],[1,2.7,24],[2,1.28,178.57]],"ltp":3.0,"tv":134.09,"id":60971786}]}]}
{"op":"mcm","clk":"11932401778","pt":1724742612095,"mc":[{"id":"1.232260815","rc":[{"batb":[[0,2.7,24],[1,1.28,178.57],[2,1.23,217.39]],"ltp":3.0,"tv":134.09,"id":60971786}]}]}
{"op":"mcm","clk":"11932401872","pt":1724742614398,"mc":[{"id":"1.232260815","rc":[{"batb":[[0,2.72,5],[1,2.7,24],[2,1.28,178.57]],"ltp":3.0,"tv":134.09,"id":60971786}]}]}
{"op":"mcm","clk":"11932401984","pt":1724742617776,"mc":[{"id":"1.232260815","rc":[{"batb":[[0,2.7,24],[1,1.28,178.57],[2,1.23,217.39]],"ltp":3.0,"tv":134.09,"id":60971786}]}]}
{"op":"mcm","clk":"11932402105","pt":1724742621111,"mc":[{"id":"1.232260815","rc":[{"batb":[[0,2.72,5],[1,2.7,24],[2,1.28,178.57]],"ltp":3.0,"tv":134.09,"id":60971786}]}]}
{"op":"mcm","clk":"11932402214","pt":1724742624284,"mc":[{"id":"1.232260815","rc":[{"batb":[[0,2.7,24],[1,1.28,178.57],[2,1.23,217.39]],"ltp":3.0,"tv":134.09,"id":60971786}]}]}
{"op":"mcm","clk":"11932402302","pt":1724742626602,"mc":[{"id":"1.232260815","rc":[{"batb":[[0,2.72,5],[1,2.7,24],[2,1.28,178.57]],"ltp":3.0,"tv":134.09,"id":60971786}]}]}
{"op":"mcm","clk":"11932402439","pt":1724742629933,"mc":[{"id":"1.232260815","rc":[{"batb":[[0,2.7,24],[1,1.28,178.57],[2,1.23,217.39]],"ltp":3.0,"tv":134.09,"id":60971786}]}]}
{"op":"mcm","clk":"11932402534","pt":1724742632193,"mc":[{"id":"1.232260815","rc":[{"batb":[[0,2.72,5],[1,2.7,24],[2,1.28,178.57]],"ltp":3.0,"tv":134.09,"id":60971786}]}]}
{"op":"mcm","clk":"11932402656","pt":1724742635520,"mc":[{"id":"1.232260815","rc":[{"batb":[[0,2.7,24],[1,1.28,178.57],[2,1.23,217.39]],"ltp":3.0,"tv":134.09,"id":60971786}]}]}
{"op":"mcm","clk":"11932402736","pt":1724742637836,"mc":[{"id":"1.232260815","rc":[{"batb":[[0,2.72,5],[1,2.7,24],[2,1.28,178.57]],"ltp":3.0,"tv":134.09,"id":60971786}]}]}
{"op":"mcm","clk":"11932402865","pt":1724742641116,"mc":[{"id":"1.232260815","rc":[{"batb":[[0,2.7,24],[1,1.28,178.57],[2,1.23,217.39]],"ltp":3.0,"tv":134.09,"id":60971786}]}]}
{"op":"mcm","clk":"11932402989","pt":1724742644451,"mc":[{"id":"1.232260815","rc":[{"batb":[[0,2.72,5],[1,2.7,24],[2,1.28,178.57]],"ltp":3.0,"tv":134.09,"id":60971786}]}]}
{"op":"mcm","clk":"11932403146","pt":1724742647746,"mc":[{"id":"1.232260815","rc":[{"batb":[[0,2.7,24],[1,1.28,178.57],[2,1.23,217.39]],"ltp":3.0,"tv":134.09,"id":60971786}]}]}
{"op":"mcm","clk":"11932403228","pt":1724742650054,"mc":[{"id":"1.232260815","rc":[{"batb":[[0,2.72,5],[1,2.7,24],[2,1.28,178.57]],"ltp":3.0,"tv":134.09,"id":60971786}]}]}
{"op":"mcm","clk":"11932403370","pt":1724742653458,"mc":[{"id":"1.232260815","rc":[{"batb":[[0,2.7,24],[1,1.28,178.57],[2,1.23,217.39]],"ltp":3.0,"tv":134.09,"id":60971786}]}]}
{"op":"mcm","clk":"11932403459","pt":1724742655763,"mc":[{"id":"1.232260815","rc":[{"batb":[[0,2.72,5],[1,2.7,24],[2,1.28,178.57]],"ltp":3.0,"tv":134.09,"id":60971786}]}]}
{"op":"mcm","clk":"11932403585","pt":1724742659252,"mc":[{"id":"1.232260815","rc":[{"batb":[[0,2.7,24],[1,1.28,178.57],[2,1.23,217.39]],"ltp":3.0,"tv":134.09,"id":60971786}]}]}
{"op":"mcm","clk":"11932403664","pt":1724742661572,"mc":[{"id":"1.232260815","rc":[{"batb":[[0,2.72,5],[1,2.7,24],[2,1.28,178.57]],"ltp":3.0,"tv":134.09,"id":60971786}]}]}
{"op":"mcm","clk":"11932403808","pt":1724742665069,"mc":[{"id":"1.232260815","rc":[{"batb":[[0,2.7,24],[1,1.28,178.57],[2,1.23,217.39]],"ltp":3.0,"tv":134.09,"id":60971786}]}]}
{"op":"mcm","clk":"11932403907","pt":1724742667329,"mc":[{"id":"1.232260815","rc":[{"batb":[[0,2.72,5],[1,2.7,24],[2,1.28,178.57]],"ltp":3.0,"tv":134.09,"id":60971786}]}]}
{"op":"mcm","clk":"11932404036","pt":1724742670680,"mc":[{"id":"1.232260815","rc":[{"batb":[[0,2.7,24],[1,1.28,178.57],[2,1.23,217.39]],"ltp":3.0,"tv":134.09,"id":60971786}]}]}
{"op":"mcm","clk":"11932404127","pt":1724742672980,"mc":[{"id":"1.232260815","rc":[{"batb":[[0,2.72,5],[1,2.7,24],[2,1.28,178.57]],"ltp":3.0,"tv":134.09,"id":60971786}]}]}
{"op":"mcm","clk":"11932404257","pt":1724742676160,"mc":[{"id":"1.232260815","rc":[{"batb":[[0,2.7,24],[1,1.28,178.57],[2,1.23,217.39]],"ltp":3.0,"tv":134.09,"id":60971786}]}]}
{"op":"mcm","clk":"11932404344","pt":1724742678472,"mc":[{"id":"1.232260815","rc":[{"batb":[[0,2.72,5],[1,2.7,24],[2,1.28,178.57]],"ltp":3.0,"tv":134.09,"id":60971786}]}]}
{"op":"mcm","clk":"11932404479","pt":1724742681765,"mc":[{"id":"1.232260815","rc":[{"batb":[[0,2.7,24],[1,1.28,178.57],[2,1.23,217.39]],"ltp":3.0,"tv":134.09,"id":60971786}]}]}
{"op":"mcm","clk":"11932404590","pt":1724742684689,"mc":[{"id":"1.232260815","rc":[{"batb":[[0,2.72,5],[1,2.7,24],[2,1.28,178.57]],"ltp":3.0,"tv":134.09,"id":60971786}]}]}
{"op":"mcm","clk":"11932404729","pt":1724742687864,"mc":[{"id":"1.232260815","rc":[{"batb":[[0,2.7,24],[1,1.28,178.57],[2,1.23,217.39]],"ltp":3.0,"tv":134.09,"id":60971786}]}]}
{"op":"mcm","clk":"11932404807","pt":1724742690012,"mc":[{"id":"1.232260815","rc":[{"batb":[[0,2.72,5],[1,2.7,24],[2,1.28,178.57]],"ltp":3.0,"tv":134.09,"id":60971786}]}]}
{"op":"mcm","clk":"11932404967","pt":1724742693292,"mc":[{"id":"1.232260815","rc":[{"batb":[[0,2.7,24],[1,1.28,178.57],[2,1.23,217.39]],"ltp":3.0,"tv":134.09,"id":60971786}]}]}
{"op":"mcm","clk":"11932405052","pt":1724742695485,"mc":[{"id":"1.232260815","rc":[{"batb":[[0,2.72,5],[1,2.7,24],[2,1.28,178.57]],"ltp":3.0,"tv":134.09,"id":60971786}]}]}
{"op":"mcm","clk":"11932405154","pt":1724742698709,"mc":[{"id":"1.232260815","rc":[{"batb":[[0,2.7,24],[1,1.28,178.57],[2,1.23,217.39]],"ltp":3.0,"tv":134.09,"id":60971786}]}]}
{"op":"mcm","clk":"11932405234","pt":1724742700816,"mc":[{"id":"1.232260815","rc":[{"batb":[[0,2.72,5],[1,2.7,24],[2,1.28,178.57]],"ltp":3.0,"tv":134.09,"id":60971786}]}]}
{"op":"mcm","clk":"11932405368","pt":1724742703998,"mc":[{"id":"1.232260815","rc":[{"batb":[[0,2.7,24],[1,1.28,178.57],[2,1.23,217.39]],"ltp":3.0,"tv":134.09,"id":60971786}]}]}
{"op":"mcm","clk":"11932405462","pt":1724742706508,"mc":[{"id":"1.232260815","rc":[{"batb":[[0,2.72,5],[1,2.7,24],[2,1.28,178.57]],"ltp":3.0,"tv":134.09,"id":60971786}]}]}
{"op":"mcm","clk":"11932405551","pt":1724742709787,"mc":[{"id":"1.232260815","rc":[{"batb":[[0,2.7,24],[1,1.28,178.57],[2,1.23,217.39]],"ltp":3.0,"tv":134.09,"id":60971786}]}]}
{"op":"mcm","clk":"11932405640","pt":1724742712192,"mc":[{"id":"1.232260815","rc":[{"batb":[[0,2.72,5],[1,2.7,24],[2,1.28,178.57]],"ltp":3.0,"tv":134.09,"id":60971786}]}]}
{"op":"mcm","clk":"11932405753","pt":1724742715518,"mc":[{"id":"1.232260815","rc":[{"batb":[[0,2.7,24],[1,1.28,178.57],[2,1.23,217.39]],"ltp":3.0,"tv":134.09,"id":60971786}]}]}
{"op":"mcm","clk":"11932405825","pt":1724742717833,"mc":[{"id":"1.232260815","rc":[{"batb":[[0,2.72,5],[1,2.7,24],[2,1.28,178.57]],"ltp":3.0,"tv":134.09,"id":60971786}]}]}
{"op":"mcm","clk":"11932405942","pt":1724742721222,"mc":[{"id":"1.232260815","rc":[{"batb":[[0,2.7,24],[1,1.28,178.57],[2,1.23,217.39]],"ltp":3.0,"tv":134.09,"id":60971786}]}]}
{"op":"mcm","clk":"11932406030","pt":1724742724247,"mc":[{"id":"1.232260815","rc":[{"batb":[[0,2.72,5],[1,2.7,24],[2,1.28,178.57]],"ltp":3.0,"tv":134.09,"id":60971786}]}]}
{"op":"mcm","clk":"11932406158","pt":1724742727535,"mc":[{"id":"1.232260815","rc":[{"batb":[[0,2.7,24],[1,1.28,178.57],[2,1.23,217.39]],"ltp":3.0,"tv":134.09,"id":60971786}]}]}
{"op":"mcm","clk":"11932406251","pt":1724742729723,"mc":[{"id":"1.232260815","rc":[{"batb":[[0,2.72,5],[1,2.7,24],[2,1.28,178.57]],"ltp":3.0,"tv":134.09,"id":60971786}]}]}
{"op":"mcm","clk":"11932406372","pt":1724742733150,"mc":[{"id":"1.232260815","rc":[{"batb":[[0,2.7,24],[1,1.28,178.57],[2,1.23,217.39]],"ltp":3.0,"tv":134.09,"id":60971786}]}]}
{"op":"mcm","clk":"11932406480","pt":1724742735362,"mc":[{"id":"1.232260815","rc":[{"batb":[[0,2.72,5],[1,2.7,24],[2,1.28,178.57]],"ltp":3.0,"tv":134.09,"id":60971786}]}]}
{"op":"mcm","clk":"11932406612","pt":1724742738745,"mc":[{"id":"1.232260815","rc":[{"batb":[[0,2.7,24],[1,1.28,178.57],[2,1.23,217.39]],"ltp":3.0,"tv":134.09,"id":60971786}]}]}
{"op":"mcm","clk":"11932406711","pt":1724742740941,"mc":[{"id":"1.232260815","rc":[{"batb":[[0,2.72,5],[1,2.7,24],[2,1.28,178.57]],"ltp":3.0,"tv":134.09,"id":60971786}]}]}
{"op":"mcm","clk":"11932406905","pt":1724742745292,"mc":[{"id":"1.232260815","rc":[{"batb":[[0,2.7,24],[1,1.28,178.57],[2,1.23,217.39]],"ltp":3.0,"tv":134.09,"id":60971786}]}]}
{"op":"mcm","clk":"11932407024","pt":1724742747856,"mc":[{"id":"1.232260815","rc":[{"batb":[[0,2.72,5],[1,2.7,24],[2,1.28,178.57]],"ltp":3.0,"tv":134.09,"id":60971786}]}]}
{"op":"mcm","clk":"11932407136","pt":1724742751183,"mc":[{"id":"1.232260815","rc":[{"batb":[[0,2.7,24],[1,1.28,178.57],[2,1.23,217.39]],"ltp":3.0,"tv":134.09,"id":60971786}]}]}
{"op":"mcm","clk":"11932407247","pt":1724742754260,"mc":[{"id":"1.232260815","rc":[{"batb":[[0,2.72,5],[1,2.7,24],[2,1.28,178.57]],"ltp":3.0,"tv":134.09,"id":60971786}]}]}
{"op":"mcm","clk":"11932407415","pt":1724742757712,"mc":[{"id":"1.232260815","rc":[{"batb":[[0,2.7,24],[1,1.28,178.57],[2,1.23,217.39]],"ltp":3.0,"tv":134.09,"id":60971786}]}]}
{"op":"mcm","clk":"11932407540","pt":1724742760592,"mc":[{"id":"1.232260815","rc":[{"batb":[[0,2.72,5],[1,2.7,24],[2,1.28,178.57]],"ltp":3.0,"tv":134.09,"id":60971786}]}]}
{"op":"mcm","clk":"11932407665","pt":1724742763977,"mc":[{"id":"1.232260815","rc":[{"batb":[[0,2.7,24],[1,1.28,178.57],[2,1.23,217.39]],"ltp":3.0,"tv":134.09,"id":60971786}]}]}
{"op":"mcm","clk":"11932407738","pt":1724742766083,"mc":[{"id":"1.232260815","rc":[{"batb":[[0,2.72,5],[1,2.7,24],[2,1.28,178.57]],"ltp":3.0,"tv":134.09,"id":60971786}]}]}
{"op":"mcm","clk":"11932407843","pt":1724742769367,"mc":[{"id":"1.232260815","rc":[{"batb":[[0,2.7,24],[1,1.28,178.57],[2,1.23,217.39]],"ltp":3.0,"tv":134.09,"id":60971786}]}]}
{"op":"mcm","clk":"11932407897","pt":1724742770694,"mc":[{"id":"1.232260815","rc":[{"batl":[[0,1.58,2.93]],"ltp":1.5,"tv":236.98,"id":60971788}]}]}
{"op":"mcm","clk":"11932407934","pt":1724742771822,"mc":[{"id":"1.232260815","rc":[{"batb":[[0,2.72,5],[1,2.7,24],[2,1.28,178.57]],"ltp":3.0,"tv":134.09,"id":60971786}]}]}
{"op":"mcm","clk":"11932418395","pt":1724742775096,"mc":[{"id":"1.232260815","rc":[{"batb":[[0,2.7,24],[1,1.28,178.57],[2,1.23,217.39]],"ltp":3.0,"tv":134.09,"id":60971786}]}]}
{"op":"mcm","clk":"11932418476","pt":1724742777609,"mc":[{"id":"1.232260815","rc":[{"batb":[[0,2.72,5],[1,2.7,24],[2,1.28,178.57]],"ltp":3.0,"tv":134.09,"id":60971786}]}]}
{"op":"mcm","clk":"11932418611","pt":1724742780836,"mc":[{"id":"1.232260815","rc":[{"batb":[[0,2.7,24],[1,1.28,178.57],[2,1.23,217.39]],"ltp":3.0,"tv":134.09,"id":60971786}]}]}
{"op":"mcm","clk":"11932418709","pt":1724742783039,"mc":[{"id":"1.232260815","rc":[{"batb":[[0,2.72,5],[1,2.7,24],[2,1.28,178.57]],"ltp":3.0,"tv":134.09,"id":60971786}]}]}
{"op":"mcm","clk":"11932418868","pt":1724742786232,"mc":[{"id":"1.232260815","rc":[{"batb":[[0,2.7,24],[1,1.28,178.57],[2,1.23,217.39]],"ltp":3.0,"tv":134.09,"id":60971786}]}]}
{"op":"mcm","clk":"11932418970","pt":1724742788539,"mc":[{"id":"1.232260815","rc":[{"batb":[[0,2.72,5],[1,2.7,24],[2,1.28,178.57]],"ltp":3.0,"tv":134.09,"id":60971786}]}]}
{"op":"mcm","clk":"11932419074","pt":1724742791962,"mc":[{"id":"1.232260815","rc":[{"batb":[[0,2.7,24],[1,1.28,178.57],[2,1.23,217.39]],"ltp":3.0,"tv":134.09,"id":60971786}]}]}
{"op":"mcm","clk":"11932419193","pt":1724742794264,"mc":[{"id":"1.232260815","rc":[{"batb":[[0,2.72,5],[1,2.7,24],[2,1.28,178.57]],"ltp":3.0,"tv":134.09,"id":60971786}]}]}
{"op":"mcm","clk":"11932419335","pt":1724742797438,"mc":[{"id":"1.232260815","rc":[{"batb":[[0,2.7,24],[1,1.28,178.57],[2,1.23,217.39]],"ltp":3.0,"tv":134.09,"id":60971786}]}]}
{"op":"mcm","clk":"11932419434","pt":1724742799843,"mc":[{"id":"1.232260815","rc":[{"batb":[[0,2.72,5],[1,2.7,24],[2,1.28,178.57]],"ltp":3.0,"tv":134.09,"id":60971786}]}]}
{"op":"mcm","clk":"11932419559","pt":1724742803266,"mc":[{"id":"1.232260815","rc":[{"batb":[[0,2.7,24],[1,1.28,178.57],[2,1.23,217.39]],"ltp":3.0,"tv":134.09,"id":60971786}]}]}
{"op":"mcm","clk":"11932419672","pt":1724742805878,"mc":[{"id":"1.232260815","rc":[{"batb":[[0,2.72,5],[1,2.7,24],[2,1.28,178.57]],"ltp":3.0,"tv":134.09,"id":60971786}]}]}
{"op":"mcm","clk":"11932419776","pt":1724742809262,"mc":[{"id":"1.232260815","rc":[{"batb":[[0,2.7,24],[1,1.28,178.57],[2,1.23,217.39]],"ltp":3.0,"tv":134.09,"id":60971786}]}]}
{"op":"mcm","clk":"11932419856","pt":1724742811658,"mc":[{"id":"1.232260815","rc":[{"batb":[[0,2.72,5],[1,2.7,24],[2,1.28,178.57]],"ltp":3.0,"tv":134.09,"id":60971786}]}]}
{"op":"mcm","clk":"11932419968","pt":1724742814982,"mc":[{"id":"1.232260815","rc":[{"batb":[[0,2.7,24],[1,1.28,178.57],[2,1.23,217.39]],"ltp":3.0,"tv":134.09,"id":60971786}]}]}
{"op":"mcm","clk":"11932420090","pt":1724742818192,"mc":[{"id":"1.232260815","rc":[{"batb":[[0,2.72,5],[1,2.7,24],[2,1.28,178.57]],"ltp":3.0,"tv":134.09,"id":60971786}]}]}
{"op":"mcm","clk":"11932420193","pt":1724742821467,"mc":[{"id":"1.232260815","rc":[{"batb":[[0,2.7,24],[1,1.28,178.57],[2,1.23,217.39]],"ltp":3.0,"tv":134.09,"id":60971786}]}]}
{"op":"mcm","clk":"11932420269","pt":1724742823571,"mc":[{"id":"1.232260815","rc":[{"batb":[[0,2.72,5],[1,2.7,24],[2,1.28,178.57]],"ltp":3.0,"tv":134.09,"id":60971786}]}]}
{"op":"mcm","clk":"11932420390","pt":1724742826797,"mc":[{"id":"1.232260815","rc":[{"batb":[[0,2.7,24],[1,1.28,178.57],[2,1.23,217.39]],"ltp":3.0,"tv":134.09,"id":60971786}]}]}
{"op":"mcm","clk":"11932420468","pt":1724742829104,"mc":[{"id":"1.232260815","rc":[{"batb":[[0,2.72,5],[1,2.7,24],[2,1.28,178.57]],"ltp":3.0,"tv":134.09,"id":60971786}]}]}
{"op":"mcm","clk":"11932420576","pt":1724742832297,"mc":[{"id":"1.232260815","rc":[{"batb":[[0,2.7,24],[1,1.28,178.57],[2,1.23,217.39]],"ltp":3.0,"tv":134.09,"id":60971786}]}]}
{"op":"mcm","clk":"11932420664","pt":1724742834505,"mc":[{"id":"1.232260815","rc":[{"batb":[[0,2.72,5],[1,2.7,24],[2,1.28,178.57]],"ltp":3.0,"tv":134.09,"id":60971786}]}]}
{"op":"mcm","clk":"11932420772","pt":1724742837683,"mc":[{"id":"1.232260815","rc":[{"batb":[[0,2.7,24],[1,1.28,178.57],[2,1.23,217.39]],"ltp":3.0,"tv":134.09,"id":60971786}]}]}
{"op":"mcm","clk":"11932420823","pt":1724742839886,"mc":[{"id":"1.232260815","rc":[{"batb":[[0,2.72,5],[1,2.7,24],[2,1.28,178.57]],"ltp":3.0,"tv":134.09,"id":60971786}]}]}
{"op":"mcm","clk":"11932420933","pt":1724742843078,"mc":[{"id":"1.232260815","rc":[{"batb":[[0,2.7,24],[1,1.28,178.57],[2,1.23,217.39]],"ltp":3.0,"tv":134.09,"id":60971786}]}]}
{"op":"mcm","clk":"11932421012","pt":1724742846512,"mc":[{"id":"1.232260815","rc":[{"batb":[[0,2.72,5],[1,2.7,24],[2,1.28,178.57]],"ltp":3.0,"tv":134.09,"id":60971786}]}]}
{"op":"mcm","clk":"11932421116","pt":1724742849785,"mc":[{"id":"1.232260815","rc":[{"batb":[[0,2.7,24],[1,1.28,178.57],[2,1.23,217.39]],"ltp":3.0,"tv":134.09,"id":60971786}]}]}
{"op":"mcm","clk":"11932421198","pt":1724742852090,"mc":[{"id":"1.232260815","rc":[{"batb":[[0,2.72,5],[1,2.7,24],[2,1.28,178.57]],"ltp":3.0,"tv":134.09,"id":60971786}]}]}
{"op":"mcm","clk":"11932421337","pt":1724742855522,"mc":[{"id":"1.232260815","rc":[{"batb":[[0,2.7,24],[1,1.28,178.57],[2,1.23,217.39]],"ltp":3.0,"tv":134.09,"id":60971786}]}]}
{"op":"mcm","clk":"11932421417","pt":1724742857725,"mc":[{"id":"1.232260815","rc":[{"batb":[[0,2.72,5],[1,2.7,24],[2,1.28,178.57]],"ltp":3.0,"tv":134.09,"id":60971786}]}]}
{"op":"mcm","clk":"11932421521","pt":1724742861120,"mc":[{"id":"1.232260815","rc":[{"batb":[[0,2.7,24],[1,1.28,178.57],[2,1.23,217.39]],"ltp":3.0,"tv":134.09,"id":60971786}]}]}
{"op":"mcm","clk":"11932421590","pt":1724742863319,"mc":[{"id":"1.232260815","rc":[{"batb":[[0,2.72,5],[1,2.7,24],[2,1.28,178.57]],"ltp":3.0,"tv":134.09,"id":60971786}]}]}
{"op":"mcm","clk":"11932421694","pt":1724742866746,"mc":[{"id":"1.232260815","rc":[{"batb":[[0,2.7,24],[1,1.28,178.57],[2,1.23,217.39]],"ltp":3.0,"tv":134.09,"id":60971786}]}]}
{"op":"mcm","clk":"11932421781","pt":1724742869065,"mc":[{"id":"1.232260815","rc":[{"batb":[[0,2.72,5],[1,2.7,24],[2,1.28,178.57]],"ltp":3.0,"tv":134.09,"id":60971786}]}]}
{"op":"mcm","clk":"11932421893","pt":1724742872337,"mc":[{"id":"1.232260815","rc":[{"batb":[[0,2.7,24],[1,1.28,178.57],[2,1.23,217.39]],"ltp":3.0,"tv":134.09,"id":60971786}]}]}
{"op":"mcm","clk":"11932421991","pt":1724742874751,"mc":[{"id":"1.232260815","rc":[{"batb":[[0,2.72,5],[1,2.7,24],[2,1.28,178.57]],"ltp":3.0,"tv":134.09,"id":60971786}]}]}
{"op":"mcm","clk":"11932422127","pt":1724742879053,"mc":[{"id":"1.232260815","rc":[{"batb":[[0,2.7,24],[1,1.28,178.57],[2,1.23,217.39]],"ltp":3.0,"tv":134.09,"id":60971786}]}]}
{"op":"mcm","clk":"11932422218","pt":1724742882070,"mc":[{"id":"1.232260815","rc":[{"batb":[[0,1.45,6.4],[1,1.44,130.21],[2,1.33,88.05]],"ltp":1.5,"tv":236.98,"id":60971788},{"batb":[[0,2.72,5],[1,2.7,24],[2,1.28,178.57]],"ltp":3.0,"tv":134.09,"id":60971786}]}]}
{"op":"mcm","clk":"11932422314","pt":1724742885460,"mc":[{"id":"1.232260815","rc":[{"batb":[[0,2.7,24],[1,1.28,178.57],[2,1.23,217.39]],"ltp":3.0,"tv":134.09,"id":60971786}]}]}
{"op":"mcm","clk":"11932422381","pt":1724742889400,"mc":[{"id":"1.232260815","rc":[{"batb":[[0,2.72,5],[1,2.7,24],[2,1.28,178.57]],"ltp":3.0,"tv":134.09,"id":60971786}]}]}
{"op":"mcm","clk":"11932422505","pt":1724742893295,"mc":[{"id":"1.232260815","rc":[{"batb":[[0,1.46,128.4],[1,1.33,88.05],[2,1.28,178.57]],"ltp":1.5,"tv":236.98,"id":60971788},{"batb":[[0,2.7,24],[1,1.28,178.57],[2,1.23,217.39]],"ltp":3.0,"tv":134.09,"id":60971786}]}]}
{"op":"mcm","clk":"11932422579","pt":1724742895905,"mc":[{"id":"1.232260815","rc":[{"batb":[[0,2.72,5],[1,2.7,24],[2,1.28,178.57]],"ltp":3.0,"tv":134.09,"id":60971786}]}]}
{"op":"mcm","clk":"11932422717","pt":1724742899394,"mc":[{"id":"1.232260815","rc":[{"batb":[[0,2.7,24],[1,1.28,178.57],[2,1.23,217.39]],"ltp":3.0,"tv":134.09,"id":60971786}]}]}
{"op":"mcm","clk":"11932422769","pt":1724742901597,"mc":[{"id":"1.232260815","rc":[{"batb":[[0,2.72,5],[1,2.7,24],[2,1.28,178.57]],"ltp":3.0,"tv":134.09,"id":60971786}]}]}
{"op":"mcm","clk":"11932422851","pt":1724742904889,"mc":[{"id":"1.232260815","rc":[{"batb":[[0,2.7,24],[1,1.28,178.57],[2,1.23,217.39]],"ltp":3.0,"tv":134.09,"id":60971786}]}]}
{"op":"mcm","clk":"11932422928","pt":1724742907189,"mc":[{"id":"1.232260815","rc":[{"batb":[[0,2.72,5],[1,2.7,24],[2,1.28,178.57]],"ltp":3.0,"tv":134.09,"id":60971786}]}]}
{"op":"mcm","clk":"11932423030","pt":1724742910630,"mc":[{"id":"1.232260815","rc":[{"batb":[[0,2.7,24],[1,1.28,178.57],[2,1.23,217.39]],"ltp":3.0,"tv":134.09,"id":60971786}]}]}
{"op":"mcm","clk":"11932423146","pt":1724742913910,"mc":[{"id":"1.232260815","rc":[{"batb":[[0,2.72,5],[1,2.7,24],[2,1.28,178.57]],"ltp":3.0,"tv":134.09,"id":60971786}]}]}
{"op":"mcm","clk":"11932423245","pt":1724742917231,"mc":[{"id":"1.232260815","rc":[{"batb":[[0,2.7,24],[1,1.28,178.57],[2,1.23,217.39]],"ltp":3.0,"tv":134.09,"id":60971786}]}]}
{"op":"mcm","clk":"11932423272","pt":1724742918209,"mc":[{"id":"1.232260815","rc":[{"batb":[[0,1.52,78.49],[1,1.46,128.4],[2,1.33,88.05]],"ltp":1.5,"tv":236.98,"id":60971788},{"batb":[[0,2.78,22.93]],"ltp":3.0,"tv":134.09,"id":60971786}]}]}
{"op":"mcm","clk":"11932423338","pt":1724742920507,"mc":[{"id":"1.232260815","rc":[{"batb":[[0,2.8,5],[1,2.78,22.93],[2,1.28,178.57]],"ltp":3.0,"tv":134.09,"id":60971786}]}]}
{"op":"mcm","clk":"11932423432","pt":1724742923825,"mc":[{"id":"1.232260815","rc":[{"batb":[[0,2.78,22.93],[1,1.28,178.57],[2,1.23,217.39]],"ltp":3.0,"tv":134.09,"id":60971786}]}]}
{"op":"mcm","clk":"11932423483","pt":1724742926122,"mc":[{"id":"1.232260815","rc":[{"batb":[[0,2.8,5],[1,2.78,22.93],[2,1.28,178.57]],"ltp":3.0,"tv":134.09,"id":60971786}]}]}
{"op":"mcm","clk":"11932423551","pt":1724742929511,"mc":[{"id":"1.232260815","rc":[{"batb":[[1,1.33,88.05],[2,1.28,178.57]],"ltp":1.5,"tv":236.98,"id":60971788},{"batb":[[0,2.78,22.93],[1,1.28,178.57],[2,1.23,217.39]],"ltp":3.0,"tv":134.09,"id":60971786}]}]}
{"op":"mcm","clk":"11932423628","pt":1724742931818,"mc":[{"id":"1.232260815","rc":[{"batb":[[0,2.8,5],[1,2.78,22.93],[2,1.28,178.57]],"ltp":3.0,"tv":134.09,"id":60971786}]}]}
{"op":"mcm","clk":"11932423742","pt":1724742935041,"mc":[{"id":"1.232260815","rc":[{"batb":[[0,2.78,22.93],[1,1.28,178.57],[2,1.23,217.39]],"ltp":3.0,"tv":134.09,"id":60971786}]}]}
{"op":"mcm","clk":"11932423797","pt":1724742937345,"mc":[{"id":"1.232260815","rc":[{"batb":[[0,2.8,5],[1,2.78,22.93],[2,1.28,178.57]],"ltp":3.0,"tv":134.09,"id":60971786}]}]}
{"op":"mcm","clk":"11932423887","pt":1724742940562,"mc":[{"id":"1.232260815","rc":[{"batb":[[0,2.78,22.93],[1,1.28,178.57],[2,1.23,217.39]],"ltp":3.0,"tv":134.09,"id":60971786}]}]}
{"op":"mcm","clk":"11932423932","pt":1724742942821,"mc":[{"id":"1.232260815","rc":[{"batb":[[0,2.8,5],[1,2.78,22.93],[2,1.28,178.57]],"ltp":3.0,"tv":134.09,"id":60971786}]}]}
{"op":"mcm","clk":"11932423996","pt":1724742946148,"mc":[{"id":"1.232260815","rc":[{"batb":[[0,2.78,22.93],[1,1.28,178.57],[2,1.23,217.39]],"ltp":3.0,"tv":134.09,"id":60971786}]}]}
{"op":"mcm","clk":"11932424049","pt":1724742948453,"mc":[{"id":"1.232260815","rc":[{"batb":[[0,2.8,5],[1,2.78,22.93],[2,1.28,178.57]],"ltp":3.0,"tv":134.09,"id":60971786}]}]}
{"op":"mcm","clk":"11932424133","pt":1724742951875,"mc":[{"id":"1.232260815","rc":[{"batb":[[0,2.78,22.93],[1,1.28,178.57],[2,1.23,217.39]],"ltp":3.0,"tv":134.09,"id":60971786}]}]}
{"op":"mcm","clk":"11932424294","pt":1724742956639,"mc":[{"id":"1.232260815","rc":[{"batb":[[0,2.8,5],[1,2.78,22.93],[2,1.28,178.57]],"ltp":3.0,"tv":134.09,"id":60971786}]}]}
{"op":"mcm","clk":"11932424393","pt":1724742960164,"mc":[{"id":"1.232260815","rc":[{"batb":[[0,2.78,22.93],[1,1.28,178.57],[2,1.23,217.39]],"ltp":3.0,"tv":134.09,"id":60971786}]}]}
{"op":"mcm","clk":"11932424486","pt":1724742962882,"mc":[{"id":"1.232260815","rc":[{"batb":[[0,2.8,5],[1,2.78,22.93],[2,1.28,178.57]],"ltp":3.0,"tv":134.09,"id":60971786}]}]}
{"op":"mcm","clk":"11932424594","pt":1724742966261,"mc":[{"id":"1.232260815","rc":[{"batb":[[0,2.78,22.93],[1,1.28,178.57],[2,1.23,217.39]],"ltp":3.0,"tv":134.09,"id":60971786}]}]}
{"op":"mcm","clk":"11932424669","pt":1724742968472,"mc":[{"id":"1.232260815","rc":[{"batb":[[0,2.8,5],[1,2.78,22.93],[2,1.28,178.57]],"ltp":3.0,"tv":134.09,"id":60971786}]}]}
{"op":"mcm","clk":"11932424772","pt":1724742971804,"mc":[{"id":"1.232260815","rc":[{"batb":[[0,2.78,22.93],[1,1.28,178.57],[2,1.23,217.39]],"ltp":3.0,"tv":134.09,"id":60971786}]}]}
{"op":"mcm","clk":"11932424885","pt":1724742974367,"mc":[{"id":"1.232260815","rc":[{"batb":[[0,2.8,5],[1,2.78,22.93],[2,1.28,178.57]],"ltp":3.0,"tv":134.09,"id":60971786}]}]}
{"op":"mcm","clk":"11932425006","pt":1724742977693,"mc":[{"id":"1.232260815","rc":[{"batb":[[0,2.78,22.93],[1,1.28,178.57],[2,1.23,217.39]],"ltp":3.0,"tv":134.09,"id":60971786}]}]}
{"op":"mcm","clk":"11932425120","pt":1724742980775,"mc":[{"id":"1.232260815","rc":[{"batb":[[0,2.8,5],[1,2.78,22.93],[2,1.28,178.57]],"ltp":3.0,"tv":134.09,"id":60971786}]}]}
{"op":"mcm","clk":"11932425228","pt":1724742984410,"mc":[{"id":"1.232260815","rc":[{"batb":[[0,2.78,22.93],[1,1.28,178.57],[2,1.23,217.39]],"ltp":3.0,"tv":134.09,"id":60971786}]}]}
{"op":"mcm","clk":"11932425292","pt":1724742986569,"mc":[{"id":"1.232260815","rc":[{"batb":[[0,2.8,5],[1,2.78,22.93],[2,1.28,178.57]],"ltp":3.0,"tv":134.09,"id":60971786}]}]}
{"op":"mcm","clk":"11932425394","pt":1724742990011,"mc":[{"id":"1.232260815","rc":[{"batb":[[0,2.78,22.93],[1,1.28,178.57],[2,1.23,217.39]],"ltp":3.0,"tv":134.09,"id":60971786}]}]}
{"op":"mcm","clk":"11932425446","pt":1724742992315,"mc":[{"id":"1.232260815","rc":[{"batb":[[0,2.8,5],[1,2.78,22.93],[2,1.28,178.57]],"ltp":3.0,"tv":134.09,"id":60971786}]}]}
{"op":"mcm","clk":"11932425536","pt":1724742995602,"mc":[{"id":"1.232260815","rc":[{"batb":[[0,2.78,22.93],[1,1.28,178.57],[2,1.23,217.39]],"ltp":3.0,"tv":134.09,"id":60971786}]}]}
{"op":"mcm","clk":"11932425613","pt":1724742997914,"mc":[{"id":"1.232260815","rc":[{"batb":[[0,2.8,5],[1,2.78,22.93],[2,1.28,178.57]],"ltp":3.0,"tv":134.09,"id":60971786}]}]}
{"op":"mcm","clk":"11932425705","pt":1724743001348,"mc":[{"id":"1.232260815","rc":[{"batb":[[0,2.78,22.93],[1,1.28,178.57],[2,1.23,217.39]],"ltp":3.0,"tv":134.09,"id":60971786}]}]}
{"op":"mcm","clk":"11932425774","pt":1724743003708,"mc":[{"id":"1.232260815","rc":[{"batb":[[0,2.8,5],[1,2.78,22.93],[2,1.28,178.57]],"ltp":3.0,"tv":134.09,"id":60971786}]}]}
{"op":"mcm","clk":"11932425862","pt":1724743006937,"mc":[{"id":"1.232260815","rc":[{"batb":[[0,2.78,22.93],[1,1.28,178.57],[2,1.23,217.39]],"ltp":3.0,"tv":134.09,"id":60971786}]}]}
{"op":"mcm","clk":"11932425942","pt":1724743009300,"mc":[{"id":"1.232260815","rc":[{"batb":[[0,2.8,5],[1,2.78,22.93],[2,1.28,178.57]],"ltp":3.0,"tv":134.09,"id":60971786}]}]}
{"op":"mcm","clk":"11932426041","pt":1724743012729,"mc":[{"id":"1.232260815","rc":[{"batb":[[0,2.78,22.93],[1,1.28,178.57],[2,1.23,217.39]],"ltp":3.0,"tv":134.09,"id":60971786}]}]}
{"op":"mcm","clk":"11932426105","pt":1724743015027,"mc":[{"id":"1.232260815","rc":[{"batb":[[0,2.8,5],[1,2.78,22.93],[2,1.28,178.57]],"ltp":3.0,"tv":134.09,"id":60971786}]}]}
{"op":"mcm","clk":"11932426208","pt":1724743018455,"mc":[{"id":"1.232260815","rc":[{"batb":[[0,2.78,22.93],[1,1.28,178.57],[2,1.23,217.39]],"ltp":3.0,"tv":134.09,"id":60971786}]}]}
{"op":"mcm","clk":"11932426259","pt":1724743020553,"mc":[{"id":"1.232260815","rc":[{"batb":[[0,2.8,5],[1,2.78,22.93],[2,1.28,178.57]],"ltp":3.0,"tv":134.09,"id":60971786}]}]}
{"op":"mcm","clk":"11932426353","pt":1724743023934,"mc":[{"id":"1.232260815","rc":[{"batb":[[0,2.78,22.93],[1,1.28,178.57],[2,1.23,217.39]],"ltp":3.0,"tv":134.09,"id":60971786}]}]}
{"op":"mcm","clk":"11932426433","pt":1724743026446,"mc":[{"id":"1.232260815","rc":[{"batb":[[0,2.8,5],[1,2.78,22.93],[2,1.28,178.57]],"ltp":3.0,"tv":134.09,"id":60971786}]}]}
{"op":"mcm","clk":"11932426534","pt":1724743029831,"mc":[{"id":"1.232260815","rc":[{"batb":[[0,2.78,22.93],[1,1.28,178.57],[2,1.23,217.39]],"ltp":3.0,"tv":134.09,"id":60971786}]}]}
{"op":"mcm","clk":"11932426649","pt":1724743033564,"mc":[{"id":"1.232260815","rc":[{"batb":[[0,2.8,5],[1,2.78,22.93],[2,1.28,178.57]],"ltp":3.0,"tv":134.09,"id":60971786}]}]}
{"op":"mcm","clk":"11932426766","pt":1724743038339,"mc":[{"id":"1.232260815","rc":[{"batb":[[0,2.78,22.93],[1,1.28,178.57],[2,1.23,217.39]],"ltp":3.0,"tv":134.09,"id":60971786}]}]}
{"op":"mcm","clk":"11932426844","pt":1724743040589,"mc":[{"id":"1.232260815","rc":[{"batb":[[0,2.8,5],[1,2.78,22.93],[2,1.28,178.57]],"ltp":3.0,"tv":134.09,"id":60971786}]}]}
{"op":"mcm","clk":"11932426932","pt":1724743043878,"mc":[{"id":"1.232260815","rc":[{"batb":[[0,2.78,22.93],[1,1.28,178.57],[2,1.23,217.39]],"ltp":3.0,"tv":134.09,"id":60971786}]}]}
{"op":"mcm","clk":"11932426988","pt":1724743046080,"mc":[{"id":"1.232260815","rc":[{"batb":[[0,2.8,5],[1,2.78,22.93],[2,1.28,178.57]],"ltp":3.0,"tv":134.09,"id":60971786}]}]}
{"op":"mcm","clk":"11932427097","pt":1724743049360,"mc":[{"id":"1.232260815","rc":[{"batb":[[0,2.78,22.93],[1,1.28,178.57],[2,1.23,217.39]],"ltp":3.0,"tv":134.09,"id":60971786}]}]}
{"op":"mcm","clk":"11932427155","pt":1724743051474,"mc":[{"id":"1.232260815","rc":[{"batb":[[0,2.8,5],[1,2.78,22.93],[2,1.28,178.57]],"ltp":3.0,"tv":134.09,"id":60971786}]}]}
{"op":"mcm","clk":"11932427229","pt":1724743054804,"mc":[{"id":"1.232260815","rc":[{"batb":[[0,2.78,22.93],[1,1.28,178.57],[2,1.23,217.39]],"ltp":3.0,"tv":134.09,"id":60971786}]}]}
{"op":"mcm","clk":"11932427327","pt":1724743058387,"mc":[{"id":"1.232260815","rc":[{"batb":[[0,2.8,5],[1,2.78,22.93],[2,1.28,178.57]],"ltp":3.0,"tv":134.09,"id":60971786}]}]}
{"op":"mcm","clk":"11932427450","pt":1724743061878,"mc":[{"id":"1.232260815","rc":[{"batb":[[0,2.78,22.93],[1,1.28,178.57],[2,1.23,217.39]],"ltp":3.0,"tv":134.09,"id":60971786}]}]}
{"op":"mcm","clk":"11932427560","pt":1724743064392,"mc":[{"id":"1.232260815","rc":[{"batb":[[0,2.8,5],[1,2.78,22.93],[2,1.28,178.57]],"ltp":3.0,"tv":134.09,"id":60971786}]}]}
{"op":"mcm","clk":"11932427633","pt":1724743067818,"mc":[{"id":"1.232260815","rc":[{"batb":[[0,2.78,22.93],[1,1.28,178.57],[2,1.23,217.39]],"ltp":3.0,"tv":134.09,"id":60971786}]}]}
{"op":"mcm","clk":"11932427757","pt":1724743071098,"mc":[{"id":"1.232260815","rc":[{"batb":[[0,2.8,5],[1,2.78,22.93],[2,1.28,178.57]],"ltp":3.0,"tv":134.09,"id":60971786}]}]}
{"op":"mcm","clk":"11932427859","pt":1724743074536,"mc":[{"id":"1.232260815","rc":[{"batb":[[0,2.78,22.93],[1,1.28,178.57],[2,1.23,217.39]],"ltp":3.0,"tv":134.09,"id":60971786}]}]}
{"op":"mcm","clk":"11932427916","pt":1724743076693,"mc":[{"id":"1.232260815","rc":[{"batb":[[0,2.8,5],[1,2.78,22.93],[2,1.28,178.57]],"ltp":3.0,"tv":134.09,"id":60971786}]}]}
{"op":"mcm","clk":"11932427991","pt":1724743080025,"mc":[{"id":"1.232260815","rc":[{"batb":[[0,2.78,22.93],[1,1.28,178.57],[2,1.23,217.39]],"ltp":3.0,"tv":134.09,"id":60971786}]}]}
{"op":"mcm","clk":"11932428075","pt":1724743083314,"mc":[{"id":"1.232260815","rc":[{"batb":[[0,2.8,5],[1,2.78,22.93],[2,1.28,178.57]],"ltp":3.0,"tv":134.09,"id":60971786}]}]}
{"op":"mcm","clk":"11932428175","pt":1724743086640,"mc":[{"id":"1.232260815","rc":[{"batb":[[0,2.78,22.93],[1,1.28,178.57],[2,1.23,217.39]],"ltp":3.0,"tv":134.09,"id":60971786}]}]}
{"op":"mcm","clk":"11932428319","pt":1724743090434,"mc":[{"id":"1.232260815","rc":[{"batb":[[0,2.8,5],[1,2.78,22.93],[2,1.28,178.57]],"ltp":3.0,"tv":134.09,"id":60971786}]}]}
{"op":"mcm","clk":"11932428444","pt":1724743093714,"mc":[{"id":"1.232260815","rc":[{"batb":[[0,2.78,22.93],[1,1.28,178.57],[2,1.23,217.39]],"ltp":3.0,"tv":134.09,"id":60971786}]}]}
{"op":"mcm","clk":"11932428519","pt":1724743096023,"mc":[{"id":"1.232260815","rc":[{"batb":[[0,2.8,5],[1,2.78,22.93],[2,1.28,178.57]],"ltp":3.0,"tv":134.09,"id":60971786}]}]}
{"op":"mcm","clk":"11932428623","pt":1724743099357,"mc":[{"id":"1.232260815","rc":[{"batb":[[0,2.78,22.93],[1,1.28,178.57],[2,1.23,217.39]],"ltp":3.0,"tv":134.09,"id":60971786}]}]}
{"op":"mcm","clk":"11932428721","pt":1724743102745,"mc":[{"id":"1.232260815","rc":[{"batb":[[0,2.8,5],[1,2.78,22.93],[2,1.28,178.57]],"ltp":3.0,"tv":134.09,"id":60971786}]}]}
{"op":"mcm","clk":"11932428846","pt":1724743106229,"mc":[{"id":"1.232260815","rc":[{"batb":[[0,2.78,22.93],[1,1.28,178.57],[2,1.23,217.39]],"ltp":3.0,"tv":134.09,"id":60971786}]}]}
{"op":"mcm","clk":"11932428923","pt":1724743109147,"mc":[{"id":"1.232260815","rc":[{"batb":[[0,2.8,5],[1,2.78,22.93],[2,1.28,178.57]],"ltp":3.0,"tv":134.09,"id":60971786}]}]}
{"op":"mcm","clk":"11932429002","pt":1724743112468,"mc":[{"id":"1.232260815","rc":[{"batb":[[0,2.78,22.93],[1,1.28,178.57],[2,1.23,217.39]],"ltp":3.0,"tv":134.09,"id":60971786}]}]}
{"op":"mcm","clk":"11932429091","pt":1724743114666,"mc":[{"id":"1.232260815","rc":[{"batb":[[0,2.8,5],[1,2.78,22.93],[2,1.28,178.57]],"ltp":3.0,"tv":134.09,"id":60971786}]}]}
{"op":"mcm","clk":"11932429206","pt":1724743117946,"mc":[{"id":"1.232260815","rc":[{"batb":[[0,2.78,22.93],[1,1.28,178.57],[2,1.23,217.39]],"ltp":3.0,"tv":134.09,"id":60971786}]}]}
{"op":"mcm","clk":"11932429274","pt":1724743120162,"mc":[{"id":"1.232260815","rc":[{"batb":[[0,2.8,5],[1,2.78,22.93],[2,1.28,178.57]],"ltp":3.0,"tv":134.09,"id":60971786}]}]}
{"op":"mcm","clk":"11932429376","pt":1724743123541,"mc":[{"id":"1.232260815","rc":[{"batb":[[0,2.78,22.93],[1,1.28,178.57],[2,1.23,217.39]],"ltp":3.0,"tv":134.09,"id":60971786}]}]}
{"op":"mcm","clk":"11932429439","pt":1724743126674,"mc":[{"id":"1.232260815","rc":[{"batb":[[0,2.8,5],[1,2.78,22.93],[2,1.28,178.57]],"ltp":3.0,"tv":134.09,"id":60971786}]}]}
{"op":"mcm","clk":"11932429502","pt":1724743129964,"mc":[{"id":"1.232260815","rc":[{"batb":[[0,2.78,22.93],[1,1.28,178.57],[2,1.23,217.39]],"ltp":3.0,"tv":134.09,"id":60971786}]}]}
{"op":"mcm","clk":"11932429587","pt":1724743132275,"mc":[{"id":"1.232260815","rc":[{"batb":[[0,2.8,5],[1,2.78,22.93],[2,1.28,178.57]],"ltp":3.0,"tv":134.09,"id":60971786}]}]}
{"op":"mcm","clk":"11932429689","pt":1724743135553,"mc":[{"id":"1.232260815","rc":[{"batb":[[0,2.78,22.93],[1,1.28,178.57],[2,1.23,217.39]],"ltp":3.0,"tv":134.09,"id":60971786}]}]}
{"op":"mcm","clk":"11932429787","pt":1724743138171,"mc":[{"id":"1.232260815","rc":[{"batb":[[0,2.8,5],[1,2.78,22.93],[2,1.28,178.57]],"ltp":3.0,"tv":134.09,"id":60971786}]}]}
{"op":"mcm","clk":"11932429898","pt":1724743141571,"mc":[{"id":"1.232260815","rc":[{"batb":[[0,2.78,22.93],[1,1.28,178.57],[2,1.23,217.39]],"ltp":3.0,"tv":134.09,"id":60971786}]}]}
{"op":"mcm","clk":"11932429985","pt":1724743143880,"mc":[{"id":"1.232260815","rc":[{"batb":[[0,2.8,5],[1,2.78,22.93],[2,1.28,178.57]],"ltp":3.0,"tv":134.09,"id":60971786}]}]}
{"op":"mcm","clk":"11932430095","pt":1724743147256,"mc":[{"id":"1.232260815","rc":[{"batb":[[0,2.78,22.93],[1,1.28,178.57],[2,1.23,217.39]],"ltp":3.0,"tv":134.09,"id":60971786}]}]}
{"op":"mcm","clk":"11932430174","pt":1724743149665,"mc":[{"id":"1.232260815","rc":[{"batb":[[0,2.8,5],[1,2.78,22.93],[2,1.28,178.57]],"ltp":3.0,"tv":134.09,"id":60971786}]}]}
{"op":"mcm","clk":"11932430262","pt":1724743153079,"mc":[{"id":"1.232260815","rc":[{"batb":[[0,2.78,22.93],[1,1.28,178.57],[2,1.23,217.39]],"ltp":3.0,"tv":134.09,"id":60971786}]}]}
{"op":"mcm","clk":"11932430350","pt":1724743155487,"mc":[{"id":"1.232260815","rc":[{"batb":[[0,2.8,5],[1,2.78,22.93],[2,1.28,178.57]],"ltp":3.0,"tv":134.09,"id":60971786}]}]}
{"op":"mcm","clk":"11932430475","pt":1724743158871,"mc":[{"id":"1.232260815","rc":[{"batb":[[0,2.78,22.93],[1,1.28,178.57],[2,1.23,217.39]],"ltp":3.0,"tv":134.09,"id":60971786}]}]}
{"op":"mcm","clk":"11932430600","pt":1724743161885,"mc":[{"id":"1.232260815","rc":[{"batb":[[0,2.8,5],[1,2.78,22.93],[2,1.28,178.57]],"ltp":3.0,"tv":134.09,"id":60971786}]}]}
{"op":"mcm","clk":"11932430711","pt":1724743165304,"mc":[{"id":"1.232260815","rc":[{"batb":[[0,2.78,22.93],[1,1.28,178.57],[2,1.23,217.39]],"ltp":3.0,"tv":134.09,"id":60971786}]}]}
{"op":"mcm","clk":"11932430788","pt":1724743167706,"mc":[{"id":"1.232260815","rc":[{"batb":[[0,2.8,5],[1,2.78,22.93],[2,1.28,178.57]],"ltp":3.0,"tv":134.09,"id":60971786}]}]}
{"op":"mcm","clk":"11932430911","pt":1724743171093,"mc":[{"id":"1.232260815","rc":[{"batb":[[0,2.78,22.93],[1,1.28,178.57],[2,1.23,217.39]],"ltp":3.0,"tv":134.09,"id":60971786}]}]}
{"op":"mcm","clk":"11932430960","pt":1724743173384,"mc":[{"id":"1.232260815","rc":[{"batb":[[0,2.8,5],[1,2.78,22.93],[2,1.28,178.57]],"ltp":3.0,"tv":134.09,"id":60971786}]}]}
{"op":"mcm","clk":"11932431071","pt":1724743176810,"mc":[{"id":"1.232260815","rc":[{"batb":[[0,2.78,22.93],[1,1.28,178.57],[2,1.23,217.39]],"ltp":3.0,"tv":134.09,"id":60971786}]}]}
{"op":"mcm","clk":"11932431150","pt":1724743179925,"mc":[{"id":"1.232260815","rc":[{"batb":[[0,2.8,5],[1,2.78,22.93],[2,1.28,178.57]],"ltp":3.0,"tv":134.09,"id":60971786}]}]}
{"op":"mcm","clk":"11932431294","pt":1724743183160,"mc":[{"id":"1.232260815","rc":[{"batb":[[0,2.78,22.93],[1,1.28,178.57],[2,1.23,217.39]],"ltp":3.0,"tv":134.09,"id":60971786}]}]}
{"op":"mcm","clk":"11932431400","pt":1724743185715,"mc":[{"id":"1.232260815","rc":[{"batb":[[0,2.8,5],[1,2.78,22.93],[2,1.28,178.57]],"ltp":3.0,"tv":134.09,"id":60971786}]}]}
{"op":"mcm","clk":"11932431530","pt":1724743188936,"mc":[{"id":"1.232260815","rc":[{"batb":[[0,2.78,22.93],[1,1.28,178.57],[2,1.23,217.39]],"ltp":3.0,"tv":134.09,"id":60971786}]}]}
{"op":"mcm","clk":"11932431625","pt":1724743191400,"mc":[{"id":"1.232260815","rc":[{"batb":[[0,2.8,5],[1,2.78,22.93],[2,1.28,178.57]],"ltp":3.0,"tv":134.09,"id":60971786}]}]}
{"op":"mcm","clk":"11932431766","pt":1724743194725,"mc":[{"id":"1.232260815","rc":[{"batb":[[0,2.78,22.93],[1,1.28,178.57],[2,1.23,217.39]],"ltp":3.0,"tv":134.09,"id":60971786}]}]}
{"op":"mcm","clk":"11932431847","pt":1724743197025,"mc":[{"id":"1.232260815","rc":[{"batb":[[0,2.8,5],[1,2.78,22.93],[2,1.28,178.57]],"ltp":3.0,"tv":134.09,"id":60971786}]}]}
{"op":"mcm","clk":"11932431944","pt":1724743200568,"mc":[{"id":"1.232260815","rc":[{"batb":[[0,2.78,22.93],[1,1.28,178.57],[2,1.23,217.39]],"ltp":3.0,"tv":134.09,"id":60971786}]}]}
{"op":"mcm","clk":"11932432043","pt":1724743203643,"mc":[{"id":"1.232260815","rc":[{"batb":[[0,2.8,5],[1,2.78,22.93],[2,1.28,178.57]],"ltp":3.0,"tv":134.09,"id":60971786}]}]}
{"op":"mcm","clk":"11932432151","pt":1724743207067,"mc":[{"id":"1.232260815","rc":[{"batb":[[0,2.78,22.93],[1,1.28,178.57],[2,1.23,217.39]],"ltp":3.0,"tv":134.09,"id":60971786}]}]}
{"op":"mcm","clk":"11932432253","pt":1724743210032,"mc":[{"id":"1.232260815","rc":[{"batb":[[0,2.8,5],[1,2.78,22.93],[2,1.28,178.57]],"ltp":3.0,"tv":134.09,"id":60971786}]}]}
{"op":"mcm","clk":"11932432343","pt":1724743213453,"mc":[{"id":"1.232260815","rc":[{"batb":[[0,2.78,22.93],[1,1.28,178.57],[2,1.23,217.39]],"ltp":3.0,"tv":134.09,"id":60971786}]}]}
{"op":"mcm","clk":"11932432410","pt":1724743215759,"mc":[{"id":"1.232260815","rc":[{"batb":[[0,2.8,5],[1,2.78,22.93],[2,1.28,178.57]],"ltp":3.0,"tv":134.09,"id":60971786}]}]}
{"op":"mcm","clk":"11932432505","pt":1724743219084,"mc":[{"id":"1.232260815","rc":[{"batb":[[0,2.78,22.93],[1,1.28,178.57],[2,1.23,217.39]],"ltp":3.0,"tv":134.09,"id":60971786}]}]}
{"op":"mcm","clk":"11932432574","pt":1724743221449,"mc":[{"id":"1.232260815","rc":[{"batb":[[0,2.8,5],[1,2.78,22.93],[2,1.28,178.57]],"ltp":3.0,"tv":134.09,"id":60971786}]}]}
{"op":"mcm","clk":"11932432643","pt":1724743224670,"mc":[{"id":"1.232260815","rc":[{"batb":[[0,2.78,22.93],[1,1.28,178.57],[2,1.23,217.39]],"ltp":3.0,"tv":134.09,"id":60971786}]}]}
{"op":"mcm","clk":"11932432696","pt":1724743227077,"mc":[{"id":"1.232260815","rc":[{"batb":[[0,2.8,5],[1,2.78,22.93],[2,1.28,178.57]],"ltp":3.0,"tv":134.09,"id":60971786}]}]}
{"op":"mcm","clk":"11932432782","pt":1724743230400,"mc":[{"id":"1.232260815","rc":[{"batb":[[0,2.78,22.93],[1,1.28,178.57],[2,1.23,217.39]],"ltp":3.0,"tv":134.09,"id":60971786}]}]}
{"op":"mcm","clk":"11932432848","pt":1724743232701,"mc":[{"id":"1.232260815","rc":[{"batb":[[0,2.8,5],[1,2.78,22.93],[2,1.28,178.57]],"ltp":3.0,"tv":134.09,"id":60971786}]}]}
{"op":"mcm","clk":"11932432930","pt":1724743235971,"mc":[{"id":"1.232260815","rc":[{"batb":[[0,2.78,22.93],[1,1.28,178.57],[2,1.23,217.39]],"ltp":3.0,"tv":134.09,"id":60971786}]}]}
{"op":"mcm","clk":"11932432987","pt":1724743238486,"mc":[{"id":"1.232260815","rc":[{"batb":[[0,2.8,5],[1,2.78,22.93],[2,1.28,178.57]],"ltp":3.0,"tv":134.09,"id":60971786}]}]}
{"op":"mcm","clk":"11932433085","pt":1724743241776,"mc":[{"id":"1.232260815","rc":[{"batb":[[0,2.78,22.93],[1,1.28,178.57],[2,1.23,217.39]],"ltp":3.0,"tv":134.09,"id":60971786}]}]}
{"op":"mcm","clk":"11932433143","pt":1724743243980,"mc":[{"id":"1.232260815","rc":[{"batb":[[0,2.8,5],[1,2.78,22.93],[2,1.28,178.57]],"ltp":3.0,"tv":134.09,"id":60971786}]}]}
{"op":"mcm","clk":"11932433233","pt":1724743247406,"mc":[{"id":"1.232260815","rc":[{"batb":[[0,2.78,22.93],[1,1.28,178.57],[2,1.23,217.39]],"ltp":3.0,"tv":134.09,"id":60971786}]}]}
{"op":"mcm","clk":"11932433302","pt":1724743250483,"mc":[{"id":"1.232260815","rc":[{"batb":[[0,2.8,5],[1,2.78,22.93],[2,1.28,178.57]],"ltp":3.0,"tv":134.09,"id":60971786}]}]}
{"op":"mcm","clk":"11932433398","pt":1724743253913,"mc":[{"id":"1.232260815","rc":[{"batb":[[0,2.78,22.93],[1,1.28,178.57],[2,1.23,217.39]],"ltp":3.0,"tv":134.09,"id":60971786}]}]}
{"op":"mcm","clk":"11932433454","pt":1724743256114,"mc":[{"id":"1.232260815","rc":[{"batb":[[0,2.8,5],[1,2.78,22.93],[2,1.28,178.57]],"ltp":3.0,"tv":134.09,"id":60971786}]}]}
{"op":"mcm","clk":"11932433526","pt":1724743259647,"mc":[{"id":"1.232260815","rc":[{"batb":[[0,2.78,22.93],[1,1.28,178.57],[2,1.23,217.39]],"ltp":3.0,"tv":134.09,"id":60971786}]}]}
{"op":"mcm","clk":"11932433644","pt":1724743262827,"mc":[{"id":"1.232260815","rc":[{"batb":[[0,2.8,5],[1,2.78,22.93],[2,1.28,178.57]],"ltp":3.0,"tv":134.09,"id":60971786}]}]}
{"op":"mcm","clk":"11932433750","pt":1724743266205,"mc":[{"id":"1.232260815","rc":[{"batb":[[0,2.78,22.93],[1,1.28,178.57],[2,1.23,217.39]],"ltp":3.0,"tv":134.09,"id":60971786}]}]}
{"op":"mcm","clk":"11932433822","pt":1724743268519,"mc":[{"id":"1.232260815","rc":[{"batb":[[0,2.8,5],[1,2.78,22.93],[2,1.28,178.57]],"ltp":3.0,"tv":134.09,"id":60971786}]}]}
{"op":"mcm","clk":"11932434011","pt":1724743271813,"mc":[{"id":"1.232260815","rc":[{"batb":[[0,2.78,22.93],[1,1.28,178.57],[2,1.23,217.39]],"ltp":3.0,"tv":134.09,"id":60971786}]}]}
{"op":"mcm","clk":"11932434100","pt":1724743274225,"mc":[{"id":"1.232260815","rc":[{"batb":[[0,2.8,5],[1,2.78,22.93],[2,1.28,178.57]],"ltp":3.0,"tv":134.09,"id":60971786}]}]}
{"op":"mcm","clk":"11932434104","pt":1724743274330,"mc":[{"id":"1.232260815","rc":[{"trd":[[1.52,42.4]],"batb":[[0,1.52,36.09]],"ltp":1.52,"tv":279.38,"id":60971788},{"trd":[[2.94,21.92]],"ltp":2.94,"tv":156.01,"id":60971786}],"tv":435.4}]}
{"op":"mcm","clk":"11932434209","pt":1724743277555,"mc":[{"id":"1.232260815","rc":[{"batb":[[0,2.78,22.93],[1,1.28,178.57],[2,1.23,217.39]],"ltp":2.94,"tv":156.01,"id":60971786}]}]}
{"op":"mcm","clk":"11932434270","pt":1724743279244,"mc":[{"id":"1.232260815","rc":[{"batb":[[0,1.52,66.3]],"ltp":1.52,"tv":279.38,"id":60971788}]}]}
{"op":"mcm","clk":"11932434318","pt":1724743280370,"mc":[{"id":"1.232260815","rc":[{"batb":[[0,2.8,5],[1,2.78,22.93],[2,1.28,178.57]],"ltp":2.94,"tv":156.01,"id":60971786}]}]}
{"op":"mcm","clk":"11932434538","pt":1724743283583,"mc":[{"id":"1.232260815","rc":[{"batb":[[0,2.78,22.93],[1,1.28,178.57],[2,1.23,217.39]],"ltp":2.94,"tv":156.01,"id":60971786}]}]}
{"op":"mcm","clk":"11932434650","pt":1724743285850,"mc":[{"id":"1.232260815","rc":[{"batb":[[0,2.8,5],[1,2.78,22.93],[2,1.28,178.57]],"ltp":2.94,"tv":156.01,"id":60971786}]}]}
{"op":"mcm","clk":"11932434830","pt":1724743289169,"mc":[{"id":"1.232260815","rc":[{"batb":[[0,2.78,22.93],[1,1.28,178.57],[2,1.23,217.39]],"ltp":2.94,"tv":156.01,"id":60971786}]}]}
{"op":"mcm","clk":"11932434944","pt":1724743291476,"mc":[{"id":"1.232260815","rc":[{"batb":[[0,2.8,5],[1,2.78,22.93],[2,1.28,178.57]],"ltp":2.94,"tv":156.01,"id":60971786}]}]}
{"op":"mcm","clk":"11932435084","pt":1724743294763,"mc":[{"id":"1.232260815","rc":[{"batb":[[0,2.78,22.93],[1,1.28,178.57],[2,1.23,217.39]],"ltp":2.94,"tv":156.01,"id":60971786}]}]}
{"op":"mcm","clk":"11932435253","pt":1724743297091,"mc":[{"id":"1.232260815","rc":[{"batb":[[0,2.8,5],[1,2.78,22.93],[2,1.28,178.57]],"ltp":2.94,"tv":156.01,"id":60971786}]}]}
{"op":"mcm","clk":"11932435456","pt":1724743300471,"mc":[{"id":"1.232260815","rc":[{"batb":[[0,2.78,22.93],[1,1.28,178.57],[2,1.23,217.39]],"ltp":2.94,"tv":156.01,"id":60971786}]}]}
{"op":"mcm","clk":"11932435592","pt":1724743302785,"mc":[{"id":"1.232260815","rc":[{"batb":[[0,2.8,5],[1,2.78,22.93],[2,1.28,178.57]],"ltp":2.94,"tv":156.01,"id":60971786}]}]}
{"op":"mcm","clk":"11932435752","pt":1724743305971,"mc":[{"id":"1.232260815","rc":[{"batb":[[0,2.78,22.93],[1,1.28,178.57],[2,1.23,217.39]],"ltp":2.94,"tv":156.01,"id":60971786}]}]}
{"op":"mcm","clk":"11932435888","pt":1724743309196,"mc":[{"id":"1.232260815","rc":[{"batb":[[0,2.8,5],[1,2.78,22.93],[2,1.28,178.57]],"ltp":2.94,"tv":156.01,"id":60971786}]}]}
{"op":"mcm","clk":"11932436009","pt":1724743312512,"mc":[{"id":"1.232260815","rc":[{"batb":[[0,2.78,22.93],[1,1.28,178.57],[2,1.23,217.39]],"ltp":2.94,"tv":156.01,"id":60971786}]}]}
{"op":"mcm","clk":"11932436120","pt":1724743314821,"mc":[{"id":"1.232260815","rc":[{"batb":[[0,2.8,5],[1,2.78,22.93],[2,1.28,178.57]],"ltp":2.94,"tv":156.01,"id":60971786}]}]}
{"op":"mcm","clk":"11932436267","pt":1724743317997,"mc":[{"id":"1.232260815","rc":[{"batb":[[0,2.78,22.93],[1,1.28,178.57],[2,1.23,217.39]],"ltp":2.94,"tv":156.01,"id":60971786}]}]}
{"op":"mcm","clk":"11932436354","pt":1724743320605,"mc":[{"id":"1.232260815","rc":[{"batb":[[0,2.8,5],[1,2.78,22.93],[2,1.28,178.57]],"ltp":2.94,"tv":156.01,"id":60971786}]}]}
{"op":"mcm","clk":"11932436482","pt":1724743324002,"mc":[{"id":"1.232260815","rc":[{"batb":[[0,2.78,22.93],[1,1.28,178.57],[2,1.23,217.39]],"ltp":2.94,"tv":156.01,"id":60971786}]}]}
{"op":"mcm","clk":"11932436559","pt":1724743326308,"mc":[{"id":"1.232260815","rc":[{"batb":[[0,2.8,5],[1,2.78,22.93],[2,1.28,178.57]],"ltp":2.94,"tv":156.01,"id":60971786}]}]}
{"op":"mcm","clk":"11932436682","pt":1724743329638,"mc":[{"id":"1.232260815","rc":[{"batb":[[0,2.78,22.93],[1,1.28,178.57],[2,1.23,217.39]],"ltp":2.94,"tv":156.01,"id":60971786}]}]}
{"op":"mcm","clk":"11932436744","pt":1724743331948,"mc":[{"id":"1.232260815","rc":[{"batb":[[0,2.8,5],[1,2.78,22.93],[2,1.28,178.57]],"ltp":2.94,"tv":156.01,"id":60971786}]}]}
{"op":"mcm","clk":"11932436866","pt":1724743335223,"mc":[{"id":"1.232260815","rc":[{"batb":[[0,2.78,22.93],[1,1.28,178.57],[2,1.23,217.39]],"ltp":2.94,"tv":156.01,"id":60971786}]}]}
{"op":"mcm","clk":"11932436931","pt":1724743337533,"mc":[{"id":"1.232260815","rc":[{"batb":[[0,2.8,5],[1,2.78,22.93],[2,1.28,178.57]],"ltp":2.94,"tv":156.01,"id":60971786}]}]}
{"op":"mcm","clk":"11932437063","pt":1724743340861,"mc":[{"id":"1.232260815","rc":[{"batb":[[0,2.78,22.93],[1,1.28,178.57],[2,1.23,217.39]],"ltp":2.94,"tv":156.01,"id":60971786}]}]}
