{"op":"mcm","clk":"11848710166","pt":1723294204306,"mc":[{"id":"1.231659753","marketDefinition":{"bspMarket":false,"turnInPlayEnabled":true,"persistenceEnabled":true,"marketBaseRate":5.0,"eventId":"33483335","eventTypeId":"4","numberOfWinners":1,"bettingType":"ODDS","marketType":"MATCH_ODDS","marketTime":"2024-08-14T14:00:00.000Z","suspendTime":"2024-08-14T14:00:00.000Z","bspReconciled":false,"complete":true,"inPlay":false,"crossMatching":true,"runnersVoidable":false,"numberOfActiveRunners":2,"betDelay":0,"status":"OPEN","runners":[{"status":"ACTIVE","sortPriority":1,"id":26354926,"name":"Southern Brave"},{"status":"ACTIVE","sortPriority":2,"id":26354927,"name":"Welsh Fire"}],"regulators":["MR_INT"],"countryCode":"GB","discountAllowed":false,"timezone":"GMT","openDate":"2024-08-14T14:00:00.000Z","version":6065805000,"name":"Match Odds","eventName":"Southern Brave v Welsh Fire"},"rc":[{"batb":[[0,1.06,100],[1,1.05,100],[2,1.04,100]],"ltp":0.0,"tv":0.0,"id":26354927},{"batb":[[0,1.06,100],[1,1.05,100],[2,1.04,100]],"ltp":0.0,"tv":0.0,"id":26354926}]}]}
{"op":"mcm","clk":"11848710449","pt":1723294205919,"mc":[{"id":"1.231659753","marketDefinition":{"bspMarket":false,"turnInPlayEnabled":true,"persistenceEnabled":true,"marketBaseRate":5.0,"eventId":"33483335","eventTypeId":"4","numberOfWinners":1,"bettingType":"ODDS","marketType":"MATCH_ODDS","marketTime":"2024-08-14T14:00:00.000Z","suspendTime":"2024-08-14T14:00:00.000Z","bspReconciled":false,"complete":true,"inPlay":false,"crossMatching":true,"runnersVoidable":false,"numberOfActiveRunners":2,"betDelay":0,"status":"OPEN","runners":[{"status":"ACTIVE","sortPriority":1,"id":26354926,"name":"Southern Brave"},{"status":"ACTIVE","sortPriority":2,"id":26354927,"name":"Welsh Fire"}],"regulators":["MR_INT"],"countryCode":"GB","discountAllowed":true,"timezone":"GMT","openDate":"2024-08-14T14:00:00.000Z","version":6065805000,"name":"Match Odds","eventName":"Southern Brave v Welsh Fire"}}]}
{"op":"mcm","clk":"11848775267","pt":1723294672709,"mc":[{"id":"1.231659753","rc":[{"batb":[[0,1.1,25000],[1,1.09,25000],[2,1.08,25000]],"ltp":0.0,"tv":0.0,"id":26354927},{"batb":[[0,1.1,25000],[1,1.09,25000],[2,1.08,25000]],"ltp":0.0,"tv":0.0,"id":26354926}]}]}
{"op":"mcm","clk":"11848776686","pt":1723294682745,"mc":[{"id":"1.231659753","rc":[{"batb":[[0,1.09,25000],[1,1.08,25000],[2,1.07,25000]],"ltp":0.0,"tv":0.0,"id":26354926}]}]}
{"op":"mcm","clk":"11848776858","pt":1723294683864,"mc":[{"id":"1.231659753","rc":[{"batb":[[0,1.06,25100],[1,1.05,25100],[2,1.04,25100]],"ltp":0.0,"tv":0.0,"id":26354926}]}]}
{"op":"mcm","clk":"11848778237","pt":1723294692860,"mc":[{"id":"1.231659753","rc":[{"batb":[[0,1.08,25000],[1,1.07,25000],[2,1.06,25100]],"ltp":0.0,"tv":0.0,"id":26354927}]}]}
{"op":"mcm","clk":"11848778391","pt":1723294693892,"mc":[{"id":"1.231659753","rc":[{"batb":[[0,1.07,25000],[1,1.06,25100],[2,1.05,25100]],"ltp":0.0,"tv":0.0,"id":26354927}]}]}
{"op":"mcm","clk":"11848778512","pt":1723294694794,"mc":[{"id":"1.231659753","rc":[{"batb":[[0,1.06,25100],[1,1.05,25100],[2,1.04,25100]],"ltp":0.0,"tv":0.0,"id":26354927}]}]}
{"op":"mcm","clk":"11851598370","pt":1723307655893,"mc":[{"id":"1.231659753","rc":[{"batb":[[2,1.04,40103]],"ltp":0.0,"tv":0.0,"id":26354926}]}]}
{"op":"mcm","clk":"11851599376","pt":1723307660911,"mc":[{"id":"1.231659753","rc":[{"batb":[[2,1.04,40103]],"ltp":0.0,"tv":0.0,"id":26354927}]}]}
{"op":"mcm","clk":"11851961126","pt":1723309461954,"mc":[{"id":"1.231659753","rc":[{"batl":[[0,1.08,2.85]],"ltp":0.0,"tv":0.0,"id":26354926}]}]}
{"op":"mcm","clk":"11851967485","pt":1723309495582,"mc":[{"id":"1.231659753","rc":[{"batl":[[0,1.1,7.13]],"ltp":0.0,"tv":0.0,"id":26354926}]}]}
{"op":"mcm","clk":"11851977255","pt":1723309546648,"mc":[{"id":"1.231659753","rc":[{"batl":[[0,1.1,7.13]],"ltp":0.0,"tv":0.0,"id":26354927}]}]}
{"op":"mcm","clk":"11851982219","pt":1723309570355,"mc":[{"id":"1.231659753","rc":[{"trd":[[1.1,14.26]],"batb":[[0,1.1,11.11],[1,1.06,25100],[2,1.05,25100]],"ltp":1.1,"tv":14.26,"id":26354927}],"tv":14.26}]}
{"op":"mcm","clk":"11851983282","pt":1723309575463,"mc":[{"id":"1.231659753","rc":[{"batb":[[0,1.06,25100],[1,1.05,25100],[2,1.04,40103]],"ltp":1.1,"tv":14.26,"id":26354927}]}]}
{"op":"mcm","clk":"11854279429","pt":1723322926159,"mc":[{"id":"1.231659753","rc":[{"batb":[[0,2.38,2.82],[1,1.06,25100],[2,1.05,25100]],"ltp":1.1,"tv":14.26,"id":26354927},{"batb":[[0,1.66,5.91],[1,1.06,25100],[2,1.05,25100]],"ltp":0.0,"tv":0.0,"id":26354926}]}]}
{"op":"mcm","clk":"11854321674","pt":1723323336771,"mc":[{"id":"1.231659753","rc":[{"batb":[[1,1.25,100],[2,1.06,25100]],"ltp":1.1,"tv":14.26,"id":26354927},{"batb":[[1,1.25,100],[2,1.06,25100]],"ltp":0.0,"tv":0.0,"id":26354926}]}]}
{"op":"mcm","clk":"11856230980","pt":1723352358413,"mc":[{"id":"1.231659753","rc":[{"trd":[[2.38,2.65]],"batb":[[0,1.25,100.17],[1,1.06,25100],[2,1.05,25100]],"ltp":2.38,"tv":16.91,"id":26354927},{"trd":[[1.73,3.65]],"ltp":1.73,"tv":3.64,"id":26354926}],"tv":20.56}]}
{"op":"mcm","clk":"11856231143","pt":1723352363578,"mc":[{"id":"1.231659753","rc":[{"batb":[[0,2.3,3],[1,1.25,100],[2,1.06,25100]],"ltp":2.38,"tv":16.91,"id":26354927}]}]}
{"op":"mcm","clk":"11856231661","pt":1723352378391,"mc":[{"id":"1.231659753","rc":[{"trd":[[2.3,0.7]],"batb":[[0,2.3,2.3]],"ltp":2.3,"tv":17.61,"id":26354927},{"trd":[[1.77,0.91]],"ltp":1.77,"tv":4.56,"id":26354926}],"tv":22.17}]}
{"op":"mcm","clk":"11856231916","pt":1723352383508,"mc":[{"id":"1.231659753","rc":[{"batb":[[0,2.3,3]],"ltp":2.3,"tv":17.61,"id":26354927}]}]}
{"op":"mcm","clk":"11859247685","pt":1723382755651,"mc":[{"id":"1.231659753","rc":[{"batl":[[0,1.76,70.83]],"ltp":1.77,"tv":4.56,"id":26354926}]}]}
{"op":"mcm","clk":"11859270312","pt":1723382967258,"mc":[{"id":"1.231659753","rc":[{"batb":[[0,1.67,212.5],[1,1.66,5.91],[2,1.25,100]],"ltp":1.77,"tv":4.56,"id":26354926}]}]}
{"op":"mcm","clk":"11859272291","pt":1723382985091,"mc":[{"id":"1.231659753","rc":[{"batb":[[0,1.66,5.91],[1,1.25,100],[2,1.06,25100]],"ltp":1.77,"tv":4.56,"id":26354926}]}]}
{"op":"mcm","clk":"11859749885","pt":1723386110883,"mc":[{"id":"1.231659753","rc":[{"batb":[[0,2.3,3.09]],"ltp":2.3,"tv":17.61,"id":26354927},{"batb":[[0,1.66,6.1]],"ltp":1.77,"tv":4.56,"id":26354926}]}]}
{"op":"mcm","clk":"11863038716","pt":1723404980504,"mc":[{"id":"1.231659753","rc":[{"batb":[[0,2.3,3.8]],"ltp":2.3,"tv":17.61,"id":26354927}]}]}
{"op":"mcm","clk":"11863039785","pt":1723404985228,"mc":[{"id":"1.231659753","rc":[{"batb":[[0,2.3,3.09]],"ltp":2.3,"tv":17.61,"id":26354927}]}]}
{"op":"mcm","clk":"11863042153","pt":1723404996612,"mc":[{"id":"1.231659753","rc":[{"batb":[[0,2.3,4.09]],"ltp":2.3,"tv":17.61,"id":26354927}]}]}
{"op":"mcm","clk":"11863042699","pt":1723404998935,"mc":[{"id":"1.231659753","rc":[{"batb":[[0,2.3,3.09]],"ltp":2.3,"tv":17.61,"id":26354927}]}]}
{"op":"mcm","clk":"11863044581","pt":1723405007840,"mc":[{"id":"1.231659753","rc":[{"batb":[[0,2.48,1.28],[1,2.3,3.09],[2,1.25,100]],"ltp":2.3,"tv":17.61,"id":26354927}]}]}
{"op":"mcm","clk":"11863045079","pt":1723405010117,"mc":[{"id":"1.231659753","rc":[{"batb":[[0,2.3,3.09],[1,1.25,100],[2,1.06,25100]],"ltp":2.3,"tv":17.61,"id":26354927}]}]}
{"op":"mcm","clk":"11863955853","pt":1723411135636,"mc":[{"id":"1.231659753","rc":[{"trd":[[1.1,14.25]],"ltp":2.3,"tv":17.59,"id":26354927},{"trd":[[1.73,3.64],[1.77,0.91]],"ltp":1.77,"tv":4.54,"id":26354926}],"tv":22.14}]}
{"op":"mcm","clk":"11864141445","pt":1723412808956,"mc":[{"id":"1.231659753","rc":[{"batb":[[1,1.4,25],[2,1.25,100]],"ltp":1.77,"tv":4.54,"id":26354926}]}]}
{"op":"mcm","clk":"11864540233","pt":1723417974912,"mc":[{"id":"1.231659753","rc":[{"trd":[[1.1,14.25]],"ltp":2.3,"tv":17.6,"id":26354927},{"trd":[[1.73,3.64]],"ltp":1.77,"tv":4.55,"id":26354926}],"tv":22.15}]}
{"op":"mcm","clk":"11864820079","pt":1723423374970,"mc":[{"id":"1.231659753","rc":[{"trd":[[1.1,14.24]],"ltp":2.3,"tv":17.59,"id":26354927}],"tv":22.14}]}
{"op":"mcm","clk":"11864996793","pt":1723428774964,"mc":[{"id":"1.231659753","rc":[{"trd":[[1.1,14.23]],"ltp":2.3,"tv":17.58,"id":26354927},{"trd":[[1.73,3.64]],"ltp":1.77,"tv":4.55,"id":26354926}],"tv":22.13}]}
{"op":"mcm","clk":"11865160022","pt":1723434174964,"mc":[{"id":"1.231659753","rc":[{"trd":[[1.1,14.23]],"ltp":2.3,"tv":17.58,"id":26354927}],"tv":22.13}]}
{"op":"mcm","clk":"11865388724","pt":1723441443304,"mc":[{"id":"1.231659753","rc":[{"batl":[[0,1.76,10]],"ltp":1.77,"tv":4.54,"id":26354926}]}]}
{"op":"mcm","clk":"11865501813","pt":1723444974905,"mc":[{"id":"1.231659753","rc":[{"trd":[[1.1,14.22]],"ltp":2.3,"tv":17.57,"id":26354927},{"trd":[[1.73,3.64]],"ltp":1.77,"tv":4.54,"id":26354926}],"tv":22.12}]}
{"op":"mcm","clk":"11865519781","pt":1723445506534,"mc":[{"id":"1.231659753","rc":[{"batb":[[1,1.59,276.92],[2,1.4,25]],"ltp":1.77,"tv":4.54,"id":26354926}]}]}
{"op":"mcm","clk":"11865538839","pt":1723446242225,"mc":[{"id":"1.231659753","rc":[{"trd":[[1.1,14.22]],"batl":[[0,2.68,8.2]],"ltp":2.3,"tv":17.57,"id":26354927},{"batb":[[1,1.6,13.9],[2,1.59,276.92]],"ltp":1.77,"tv":4.54,"id":26354926}],"tv":22.11}]}
{"op":"mcm","clk":"11865655466","pt":1723450375010,"mc":[{"id":"1.231659753","rc":[{"batb":[[1,1.6,13.9]],"ltp":1.77,"tv":4.54,"id":26354926}],"tv":22.11}]}
{"op":"mcm","clk":"11865898232","pt":1723455774914,"mc":[{"id":"1.231659753","rc":[{"trd":[[1.1,14.23]],"batl":[[0,2.68,8.2]],"ltp":2.3,"tv":17.57,"id":26354927},{"trd":[[1.73,3.64]],"batb":[[1,1.6,13.9]],"ltp":1.77,"tv":4.54,"id":26354926}],"tv":22.12}]}
{"op":"mcm","clk":"11865918856","pt":1723456101565,"mc":[{"id":"1.231659753","rc":[{"batb":[[0,1.25,100],[1,1.06,25100],[2,1.05,25100]],"ltp":2.3,"tv":17.57,"id":26354927},{"batb":[[0,1.6,13.9],[1,1.59,276.92],[2,1.4,25]],"ltp":1.77,"tv":4.54,"id":26354926}]}]}
{"op":"mcm","clk":"11865955428","pt":1723456762436,"mc":[{"id":"1.231659753","rc":[{"batb":[[0,1.6,21.69]],"ltp":1.77,"tv":4.54,"id":26354926}]}]}
{"op":"mcm","clk":"11865961464","pt":1723456853541,"mc":[{"id":"1.231659753","rc":[{"trd":[[1.1,14.24]],"batl":[[0,2.68,8.21]],"ltp":2.3,"tv":17.58,"id":26354927},{"trd":[[1.73,3.64]],"batb":[[0,1.6,21.71],[1,1.4,25],[2,1.25,100]],"ltp":1.77,"tv":4.55,"id":26354926}],"tv":22.13}]}
{"op":"mcm","clk":"11865961568","pt":1723456855342,"mc":[{"id":"1.231659753","rc":[{"batb":[[0,1.6,7.79]],"ltp":1.77,"tv":4.55,"id":26354926}]}]}
{"op":"mcm","clk":"11865997143","pt":1723457464759,"mc":[{"id":"1.231659753","rc":[{"batb":[[0,2.38,2.94],[1,1.25,100],[2,1.06,25100]],"ltp":2.3,"tv":17.58,"id":26354927},{"batb":[[0,1.66,6.15],[1,1.6,7.79],[2,1.4,25]],"ltp":1.77,"tv":4.55,"id":26354926}]}]}
{"op":"mcm","clk":"11866051460","pt":1723458415083,"mc":[{"id":"1.231659753","rc":[{"batb":[[1,1.4,25],[2,1.25,100]],"ltp":1.77,"tv":4.55,"id":26354926}]}]}
{"op":"mcm","clk":"11866199873","pt":1723461095574,"mc":[{"id":"1.231659753","rc":[{"trd":[[1.1,14.23]],"ltp":2.3,"tv":17.58,"id":26354927},{"batb":[[1,1.55,276.92],[2,1.4,25]],"ltp":1.77,"tv":4.55,"id":26354926}],"tv":22.13}]}
{"op":"mcm","clk":"11866200006","pt":1723461097788,"mc":[{"id":"1.231659753","rc":[{"batb":[[1,1.4,25],[2,1.25,100]],"ltp":1.77,"tv":4.55,"id":26354926}]}]}
{"op":"mcm","clk":"11866510851","pt":1723466575008,"mc":[{"id":"1.231659753","rc":[{"trd":[[1.1,14.23]],"ltp":2.3,"tv":17.57,"id":26354927},{"trd":[[1.73,3.64]],"ltp":1.77,"tv":4.54,"id":26354926}],"tv":22.12}]}
{"op":"mcm","clk":"11866550934","pt":1723467421763,"mc":[{"id":"1.231659753","rc":[{"trd":[[1.66,1.02]],"batb":[[0,1.66,5.13]],"ltp":1.66,"tv":5.56,"id":26354926}],"tv":23.14}]}
{"op":"mcm","clk":"11866550960","pt":1723467422325,"mc":[{"id":"1.231659753","rc":[{"batb":[[0,1.66,6.15]],"ltp":1.66,"tv":5.56,"id":26354926}]}]}
{"op":"mcm","clk":"11866681570","pt":1723469715460,"mc":[{"id":"1.231659753","rc":[{"trd":[[1.1,14.26]],"batb":[[0,2.38,2.8]],"ltp":2.3,"tv":17.6,"id":26354927},{"trd":[[1.73,3.64]],"batb":[[0,1.66,5.87]],"ltp":1.66,"tv":5.57,"id":26354926}],"tv":23.17}]}
{"op":"mcm","clk":"11866768123","pt":1723471200357,"mc":[{"id":"1.231659753","rc":[{"batb":[[0,2.38,28.07]],"ltp":2.3,"tv":17.6,"id":26354927},{"batb":[[0,1.66,58.7]],"ltp":1.66,"tv":5.57,"id":26354926}]}]}
{"op":"mcm","clk":"11866816162","pt":1723471974893,"mc":[{"id":"1.231659753","rc":[{"trd":[[1.1,14.24]],"ltp":2.3,"tv":17.58,"id":26354927}],"tv":23.16}]}
{"op":"mcm","clk":"11867177539","pt":1723477374904,"mc":[{"id":"1.231659753","rc":[{"trd":[[1.73,3.64],[1.77,0.91]],"ltp":1.66,"tv":5.56,"id":26354926}],"tv":23.15}]}
{"op":"mcm","clk":"11867542636","pt":1723482265095,"mc":[{"id":"1.231659753","rc":[{"trd":[[1.1,14.25]],"ltp":2.3,"tv":17.6,"id":26354927},{"trd":[[1.73,3.64],[1.77,0.91]],"batl":[[0,1.76,10.71]],"ltp":1.66,"tv":5.57,"id":26354926}],"tv":23.17}]}
{"op":"mcm","clk":"11867543781","pt":1723482278299,"mc":[{"id":"1.231659753","rc":[{"batl":[[0,1.76,10]],"ltp":1.66,"tv":5.57,"id":26354926}]}]}
{"op":"mcm","clk":"11867546596","pt":1723482310572,"mc":[{"id":"1.231659753","rc":[{"batl":[[0,1.67,1.43],[1,1.76,10]],"ltp":1.66,"tv":5.57,"id":26354926}]}]}
{"op":"mcm","clk":"11867547915","pt":1723482325766,"mc":[{"id":"1.231659753","rc":[{"batl":[[0,1.76,10],[1,1.76,0]],"ltp":1.66,"tv":5.57,"id":26354926}]}]}
{"op":"mcm","clk":"11867550358","pt":1723482354898,"mc":[{"id":"1.231659753","rc":[{"batb":[[0,1.72,1.43],[1,1.66,58.7],[2,1.4,25]],"ltp":1.66,"tv":5.57,"id":26354926}]}]}
{"op":"mcm","clk":"11867551241","pt":1723482364017,"mc":[{"id":"1.231659753","rc":[{"batb":[[0,1.66,58.7],[1,1.4,25],[2,1.25,100]],"ltp":1.66,"tv":5.57,"id":26354926}]}]}
{"op":"mcm","clk":"11867552739","pt":1723482380630,"mc":[{"id":"1.231659753","rc":[{"batb":[[0,1.72,2.14],[1,1.66,58.7],[2,1.4,25]],"ltp":1.66,"tv":5.57,"id":26354926}]}]}
{"op":"mcm","clk":"11867553777","pt":1723482392849,"mc":[{"id":"1.231659753","rc":[{"batb":[[0,1.66,58.7],[1,1.4,25],[2,1.25,100]],"ltp":1.66,"tv":5.57,"id":26354926}]}]}
{"op":"mcm","clk":"11867560335","pt":1723482466123,"mc":[{"id":"1.231659753","rc":[{"batb":[[0,1.72,2.14],[1,1.66,58.7],[2,1.4,25]],"ltp":1.66,"tv":5.57,"id":26354926}]}]}
{"op":"mcm","clk":"11867561380","pt":1723482479155,"mc":[{"id":"1.231659753","rc":[{"batb":[[0,1.66,58.7],[1,1.4,25],[2,1.25,100]],"ltp":1.66,"tv":5.57,"id":26354926}]}]}
{"op":"mcm","clk":"11867562493","pt":1723482492939,"mc":[{"id":"1.231659753","rc":[{"batb":[[0,1.72,2.85],[1,1.66,58.7],[2,1.4,25]],"ltp":1.66,"tv":5.57,"id":26354926}]}]}
{"op":"mcm","clk":"11867564804","pt":1723482520695,"mc":[{"id":"1.231659753","rc":[{"batb":[[0,1.66,58.7],[1,1.4,25],[2,1.25,100]],"ltp":1.66,"tv":5.57,"id":26354926}]}]}
{"op":"mcm","clk":"11867566734","pt":1723482542645,"mc":[{"id":"1.231659753","rc":[{"batl":[[0,1.67,1.43],[1,1.76,10]],"ltp":1.66,"tv":5.57,"id":26354926}]}]}
{"op":"mcm","clk":"11867569387","pt":1723482572657,"mc":[{"id":"1.231659753","rc":[{"batl":[[0,1.76,10],[1,1.76,0]],"ltp":1.66,"tv":5.57,"id":26354926}]}]}
{"op":"mcm","clk":"11867574026","pt":1723482625307,"mc":[{"id":"1.231659753","rc":[{"batl":[[0,1.67,1.43],[1,1.76,10]],"ltp":1.66,"tv":5.57,"id":26354926}]}]}
{"op":"mcm","clk":"11867576440","pt":1723482651353,"mc":[{"id":"1.231659753","rc":[{"trd":[[1.66,3.88]],"batb":[[0,1.66,57.27]],"batl":[[0,1.76,10],[1,1.76,0]],"ltp":1.66,"tv":8.43,"id":26354926}],"tv":26.03}]}
{"op":"mcm","clk":"11867576567","pt":1723482652943,"mc":[{"id":"1.231659753","rc":[{"batb":[[0,1.66,58.7]],"ltp":1.66,"tv":8.43,"id":26354926}]}]}
{"op":"mcm","clk":"11867609447","pt":1723482942122,"mc":[{"id":"1.231659753","rc":[{"batb":[[0,1.66,58.99]],"ltp":1.66,"tv":8.43,"id":26354926}]}]}
{"op":"mcm","clk":"11867610081","pt":1723482949242,"mc":[{"id":"1.231659753","rc":[{"trd":[[2.38,2.86]],"batb":[[0,2.38,27.86]],"ltp":2.38,"tv":17.81,"id":26354927},{"trd":[[1.73,3.93]],"batb":[[0,1.66,58.7]],"ltp":1.73,"tv":8.71,"id":26354926}],"tv":26.53}]}
{"op":"mcm","clk":"11867610447","pt":1723482953853,"mc":[{"id":"1.231659753","rc":[{"batb":[[0,2.38,28.07]],"ltp":2.38,"tv":17.81,"id":26354927}]}]}
{"op":"mcm","clk":"11867611318","pt":1723482964150,"mc":[{"id":"1.231659753","rc":[{"trd":[[2.38,3.07]],"batb":[[0,2.38,27.86]],"ltp":2.38,"tv":18.02,"id":26354927},{"trd":[[1.73,4.21]],"ltp":1.73,"tv":9.0,"id":26354926}],"tv":27.02}]}
{"op":"mcm","clk":"11867611708","pt":1723482968865,"mc":[{"id":"1.231659753","rc":[{"batb":[[0,2.38,55.93]],"ltp":2.38,"tv":18.02,"id":26354927}]}]}
{"op":"mcm","clk":"11867611718","pt":1723482968963,"mc":[{"id":"1.231659753","rc":[{"batb":[[0,2.38,28.07]],"ltp":2.38,"tv":18.02,"id":26354927}]}]}
{"op":"mcm","clk":"11867612048","pt":1723482972465,"mc":[{"id":"1.231659753","rc":[{"trd":[[2.38,3.28]],"batb":[[0,2.38,27.86]],"ltp":2.38,"tv":18.23,"id":26354927},{"trd":[[1.73,4.5]],"ltp":1.73,"tv":9.28,"id":26354926}],"tv":27.52}]}
{"op":"mcm","clk":"11867612171","pt":1723482973845,"mc":[{"id":"1.231659753","rc":[{"batb":[[0,2.38,28.07]],"ltp":2.38,"tv":18.23,"id":26354927}]}]}
{"op":"mcm","clk":"11867612800","pt":1723482980588,"mc":[{"id":"1.231659753","rc":[{"trd":[[2.38,3.49]],"batb":[[0,2.38,27.86]],"ltp":2.38,"tv":18.44,"id":26354927},{"trd":[[1.73,4.78]],"ltp":1.73,"tv":9.57,"id":26354926}],"tv":28.01}]}
{"op":"mcm","clk":"11867613104","pt":1723482984075,"mc":[{"id":"1.231659753","rc":[{"batb":[[0,2.38,28.07]],"ltp":2.38,"tv":18.44,"id":26354927}]}]}
{"op":"mcm","clk":"11868059268","pt":1723488174912,"mc":[{"id":"1.231659753","rc":[{"trd":[[1.1,14.23]],"ltp":2.38,"tv":18.42,"id":26354927},{"trd":[[1.66,3.87],[1.73,4.78]],"ltp":1.73,"tv":9.56,"id":26354926}],"tv":27.98}]}
{"op":"mcm","clk":"11868267778","pt":1723490804782,"mc":[{"id":"1.231659753","rc":[{"trd":[[1.1,14.24]],"batb":[[0,2.5,1.17],[1,2.38,28.07],[2,1.25,100]],"ltp":2.38,"tv":18.42,"id":26354927},{"trd":[[1.66,3.87]],"ltp":1.73,"tv":9.56,"id":26354926}],"tv":27.99}]}
{"op":"mcm","clk":"11868271742","pt":1723490851451,"mc":[{"id":"1.231659753","rc":[{"batb":[[0,2.38,28.07],[1,1.25,100],[2,1.06,25100]],"ltp":2.38,"tv":18.42,"id":26354927}]}]}
{"op":"mcm","clk":"11868465711","pt":1723493574897,"mc":[{"id":"1.231659753","rc":[{"trd":[[1.1,14.24]],"ltp":2.38,"tv":18.43,"id":26354927},{"trd":[[1.73,4.78]],"ltp":1.73,"tv":9.56,"id":26354926}],"tv":27.99}]}
{"op":"mcm","clk":"11868483698","pt":1723493810882,"mc":[{"id":"1.231659753","rc":[{"batb":[[1,1.36,25]],"ltp":1.73,"tv":9.56,"id":26354926}]}]}
{"op":"mcm","clk":"11868485649","pt":1723493841446,"mc":[{"id":"1.231659753","rc":[{"batl":[[0,1.72,10]],"ltp":1.73,"tv":9.56,"id":26354926}]}]}
{"op":"mcm","clk":"11868526673","pt":1723494515479,"mc":[{"id":"1.231659753","rc":[{"batl":[[1,1.81,1]],"ltp":1.73,"tv":9.56,"id":26354926}]}]}
{"op":"mcm","clk":"11868527079","pt":1723494524084,"mc":[{"id":"1.231659753","rc":[{"batl":[[2,1.89,1]],"ltp":1.73,"tv":9.56,"id":26354926}]}]}
{"op":"mcm","clk":"11868538205","pt":1723494737295,"mc":[{"id":"1.231659753","rc":[{"batb":[[0,1.71,1.17],[1,1.66,58.7],[2,1.36,25]],"ltp":1.73,"tv":9.56,"id":26354926}]}]}
{"op":"mcm","clk":"11868541541","pt":1723494804134,"mc":[{"id":"1.231659753","rc":[{"batb":[[0,1.66,58.7],[1,1.36,25],[2,1.25,100]],"ltp":1.73,"tv":9.56,"id":26354926}]}]}
{"op":"mcm","clk":"11868740282","pt":1723498974887,"mc":[{"id":"1.231659753","rc":[{"trd":[[1.1,14.25]],"ltp":2.38,"tv":18.43,"id":26354927}],"tv":28.0}]}
{"op":"mcm","clk":"11868986212","pt":1723504374900,"mc":[{"id":"1.231659753","rc":[{"trd":[[1.1,14.25]],"ltp":2.38,"tv":18.43,"id":26354927}],"tv":28.0}]}
{"op":"mcm","clk":"11869284948","pt":1723509774913,"mc":[{"id":"1.231659753","rc":[{"trd":[[1.1,14.25]],"ltp":2.38,"tv":18.43,"id":26354927},{"trd":[[1.73,4.78]],"ltp":1.73,"tv":9.56,"id":26354926}],"tv":28.0}]}
{"op":"mcm","clk":"11869547435","pt":1723515174985,"mc":[{"id":"1.231659753","rc":[{"trd":[[1.1,14.24]],"ltp":2.38,"tv":18.43,"id":26354927},{"trd":[[1.66,3.87],[1.73,4.78]],"ltp":1.73,"tv":9.56,"id":26354926}],"tv":27.99}]}
{"op":"mcm","clk":"11869761179","pt":1723520574980,"mc":[{"id":"1.231659753","rc":[{"trd":[[1.1,14.24]],"ltp":2.38,"tv":18.43,"id":26354927},{"trd":[[1.73,4.78]],"ltp":1.73,"tv":9.56,"id":26354926}],"tv":27.99}]}
{"op":"mcm","clk":"11869955265","pt":1723525974982,"mc":[{"id":"1.231659753","rc":[{"trd":[[1.1,14.24]],"ltp":2.38,"tv":18.43,"id":26354927},{"trd":[[1.73,4.78]],"ltp":1.73,"tv":9.56,"id":26354926}],"tv":27.99}]}
{"op":"mcm","clk":"11869960842","pt":1723526085755,"mc":[{"id":"1.231659753","rc":[{"batb":[[1,1.6,276.92],[2,1.36,25]],"ltp":1.73,"tv":9.56,"id":26354926}]}]}
{"op":"mcm","clk":"11869977419","pt":1723526656448,"mc":[{"id":"1.231659753","rc":[{"trd":[[1.66,10.21]],"ltp":1.66,"tv":15.9,"id":26354926}],"tv":34.33}]}
{"op":"mcm","clk":"11869996481","pt":1723527394381,"mc":[{"id":"1.231659753","rc":[{"trd":[[1.66,16.72]],"batb":[[0,1.66,55.45]],"ltp":1.66,"tv":22.4,"id":26354926}],"tv":40.83}]}
{"op":"mcm","clk":"11869996594","pt":1723527399201,"mc":[{"id":"1.231659753","rc":[{"batb":[[0,1.66,58.7]],"ltp":1.66,"tv":22.4,"id":26354926}]}]}
{"op":"mcm","clk":"11870021638","pt":1723528547999,"mc":[{"id":"1.231659753","rc":[{"batb":[[1,1.36,25],[2,1.25,100]],"ltp":1.66,"tv":22.4,"id":26354926}]}]}
{"op":"mcm","clk":"11870063614","pt":1723530275208,"mc":[{"id":"1.231659753","rc":[{"batb":[[0,1.67,2],[1,1.66,58.7],[2,1.36,25]],"ltp":1.66,"tv":22.4,"id":26354926}]}]}
{"op":"mcm","clk":"11870200066","pt":1723535216120,"mc":[{"id":"1.231659753","rc":[{"trd":[[1.1,14.21]],"ltp":2.38,"tv":18.4,"id":26354927},{"trd":[[1.66,16.7],[1.67,2],[1.73,4.77],[1.77,0.91]],"batb":[[0,1.67,1]],"ltp":1.67,"tv":24.37,"id":26354926}],"tv":42.77}]}
{"op":"mcm","clk":"11870240348","pt":1723536775005,"mc":[{"id":"1.231659753","rc":[{"trd":[[1.1,14.2]],"ltp":2.38,"tv":18.39,"id":26354927},{"trd":[[1.66,16.69],[1.73,4.77]],"ltp":1.67,"tv":24.36,"id":26354926}],"tv":42.75}]}
{"op":"mcm","clk":"11870255026","pt":1723537296416,"mc":[{"id":"1.231659753","rc":[{"trd":[[1.67,4]],"batb":[[0,1.66,58.7],[1,1.36,25],[2,1.25,100]],"ltp":1.67,"tv":26.36,"id":26354926}],"tv":44.75}]}
{"op":"mcm","clk":"11870419910","pt":1723542175022,"mc":[{"id":"1.231659753","rc":[{"trd":[[1.1,14.22]],"ltp":2.38,"tv":18.4,"id":26354927},{"trd":[[1.66,16.69],[1.73,4.77]],"ltp":1.67,"tv":26.37,"id":26354926}],"tv":44.78}]}
{"op":"mcm","clk":"11870608222","pt":1723546476685,"mc":[{"id":"1.231659753","rc":[{"trd":[[1.1,14.22]],"batl":[[0,2.54,1]],"ltp":2.38,"tv":18.41,"id":26354927},{"trd":[[1.66,16.7],[1.73,4.77]],"ltp":1.67,"tv":26.37,"id":26354926}],"tv":44.78}]}
{"op":"mcm","clk":"11870654287","pt":1723547491250,"mc":[{"id":"1.231659753","rc":[{"trd":[[1.1,14.23]],"ltp":2.38,"tv":18.42,"id":26354927},{"trd":[[1.66,16.7],[1.73,4.78]],"batb":[[1,1.57,950],[2,1.36,25]],"ltp":1.67,"tv":26.38,"id":26354926}],"tv":44.81}]}
{"op":"mcm","clk":"11870654986","pt":1723547508349,"mc":[{"id":"1.231659753","rc":[{"batl":[[2,1.82,900]],"ltp":1.67,"tv":26.38,"id":26354926}]}]}
{"op":"mcm","clk":"11870900007","pt":1723552975007,"mc":[{"id":"1.231659753","rc":[{"trd":[[1.1,14.22]],"ltp":2.38,"tv":18.41,"id":26354927},{"trd":[[1.73,4.77]],"ltp":1.67,"tv":26.38,"id":26354926}],"tv":44.79}]}
{"op":"mcm","clk":"11870943748","pt":1723553987594,"mc":[{"id":"1.231659753","rc":[{"batl":[[0,1.71,2],[1,1.72,10],[2,1.81,1]],"ltp":1.67,"tv":26.38,"id":26354926}]}]}
{"op":"mcm","clk":"11871031664","pt":1723556115966,"mc":[{"id":"1.231659753","rc":[{"trd":[[1.1,14.21]],"batb":[[0,2.38,27.49]],"ltp":2.38,"tv":18.4,"id":26354927},{"trd":[[1.66,16.7],[1.73,4.77],[1.77,0.91]],"batb":[[0,1.66,57.48]],"ltp":1.67,"tv":26.37,"id":26354926}],"tv":44.78}]}
{"op":"mcm","clk":"11871155661","pt":1723558375019,"mc":[{"id":"1.231659753","rc":[{"trd":[[1.1,14.19]],"ltp":2.38,"tv":18.38,"id":26354927},{"trd":[[1.66,16.7],[1.73,4.76]],"ltp":1.67,"tv":26.37,"id":26354926}],"tv":44.75}]}
{"op":"mcm","clk":"11871485041","pt":1723563775004,"mc":[{"id":"1.231659753","rc":[{"trd":[[1.1,14.2]],"ltp":2.38,"tv":18.38,"id":26354927},{"trd":[[1.66,16.7]],"ltp":1.67,"tv":26.37,"id":26354926}],"tv":44.75}]}
{"op":"mcm","clk":"11871550813","pt":1723564732372,"mc":[{"id":"1.231659753","rc":[{"trd":[[1.66,26.12]],"batb":[[0,1.66,52.77]],"ltp":1.66,"tv":35.78,"id":26354926}],"tv":54.17}]}
{"op":"mcm","clk":"11871551093","pt":1723564736269,"mc":[{"id":"1.231659753","rc":[{"batb":[[0,1.66,57.48]],"ltp":1.66,"tv":35.78,"id":26354926}]}]}
{"op":"mcm","clk":"11871614309","pt":1723565458107,"mc":[{"id":"1.231659753","rc":[{"trd":[[1.1,14.19]],"batb":[[0,2.4,10],[1,2.38,27.49],[2,1.25,100]],"ltp":2.38,"tv":18.38,"id":26354927},{"trd":[[1.66,26.11],[1.73,4.76]],"ltp":1.66,"tv":35.78,"id":26354926}],"tv":54.16}]}
{"op":"mcm","clk":"11871614812","pt":1723565463134,"mc":[{"id":"1.231659753","rc":[{"batb":[[0,2.38,27.49],[1,1.25,100],[2,1.06,25100]],"ltp":2.38,"tv":18.38,"id":26354927}]}]}
{"op":"mcm","clk":"11871670130","pt":1723566085901,"mc":[{"id":"1.231659753","rc":[{"batb":[[0,2.4,10],[1,2.38,27.49],[2,1.25,100]],"ltp":2.38,"tv":18.38,"id":26354927}]}]}
{"op":"mcm","clk":"11871670556","pt":1723566090406,"mc":[{"id":"1.231659753","rc":[{"batb":[[0,2.38,27.49],[1,1.25,100],[2,1.06,25100]],"ltp":2.38,"tv":18.38,"id":26354927}]}]}
{"op":"mcm","clk":"11871670839","pt":1723566093826,"mc":[{"id":"1.231659753","rc":[{"batb":[[0,2.4,10],[1,2.38,27.49],[2,1.25,100]],"ltp":2.38,"tv":18.38,"id":26354927}]}]}
{"op":"mcm","clk":"11871671252","pt":1723566099614,"mc":[{"id":"1.231659753","rc":[{"batb":[[0,2.38,27.49],[1,1.25,100],[2,1.06,25100]],"ltp":2.38,"tv":18.38,"id":26354927}]}]}
{"op":"mcm","clk":"11871671426","pt":1723566101944,"mc":[{"id":"1.231659753","rc":[{"batb":[[0,2.4,10],[1,2.38,27.49],[2,1.25,100]],"ltp":2.38,"tv":18.38,"id":26354927}]}]}
{"op":"mcm","clk":"11871671868","pt":1723566107616,"mc":[{"id":"1.231659753","rc":[{"batb":[[0,2.38,27.49],[1,1.25,100],[2,1.06,25100]],"ltp":2.38,"tv":18.38,"id":26354927}]}]}
{"op":"mcm","clk":"11871672048","pt":1723566110159,"mc":[{"id":"1.231659753","rc":[{"batb":[[0,2.4,10],[1,2.38,27.49],[2,1.25,100]],"ltp":2.38,"tv":18.38,"id":26354927}]}]}
{"op":"mcm","clk":"11871672424","pt":1723566114920,"mc":[{"id":"1.231659753","rc":[{"batb":[[0,2.38,27.49],[1,1.25,100],[2,1.06,25100]],"ltp":2.38,"tv":18.38,"id":26354927}]}]}
{"op":"mcm","clk":"11871699480","pt":1723566466905,"mc":[{"id":"1.231659753","rc":[{"batb":[[1,1.62,13],[2,1.57,950]],"ltp":1.66,"tv":35.78,"id":26354926}]}]}
{"op":"mcm","clk":"11871699491","pt":1723566467012,"mc":[{"id":"1.231659753","rc":[{"batb":[[0,2.4,10],[1,2.38,27.49],[2,1.25,100]],"ltp":2.38,"tv":18.38,"id":26354927}]}]}
{"op":"mcm","clk":"11871699780","pt":1723566470425,"mc":[{"id":"1.231659753","rc":[{"batb":[[0,2.38,27.49],[1,1.25,100],[2,1.06,25100]],"ltp":2.38,"tv":18.38,"id":26354927}]}]}
{"op":"mcm","clk":"11871700193","pt":1723566474843,"mc":[{"id":"1.231659753","rc":[{"batb":[[0,2.4,10],[1,2.38,27.49],[2,1.25,100]],"ltp":2.38,"tv":18.38,"id":26354927},{"batl":[[2,1.74,8.06]],"ltp":1.66,"tv":35.78,"id":26354926}]}]}
{"op":"mcm","clk":"11871700491","pt":1723566478126,"mc":[{"id":"1.231659753","rc":[{"batb":[[0,2.38,27.49],[1,1.25,100],[2,1.06,25100]],"ltp":2.38,"tv":18.38,"id":26354927}]}]}
{"op":"mcm","clk":"11871711015","pt":1723566593255,"mc":[{"id":"1.231659753","rc":[{"batb":[[0,2.4,10],[1,2.38,27.49],[2,1.25,100]],"ltp":2.38,"tv":18.38,"id":26354927}]}]}
{"op":"mcm","clk":"11871711444","pt":1723566597950,"mc":[{"id":"1.231659753","rc":[{"batb":[[0,2.38,27.49],[1,1.25,100],[2,1.06,25100]],"ltp":2.38,"tv":18.38,"id":26354927}]}]}
{"op":"mcm","clk":"11871711804","pt":1723566601542,"mc":[{"id":"1.231659753","rc":[{"batb":[[0,2.4,10],[1,2.38,27.49],[2,1.25,100]],"ltp":2.38,"tv":18.38,"id":26354927}]}]}
{"op":"mcm","clk":"11871712597","pt":1723566609760,"mc":[{"id":"1.231659753","rc":[{"batb":[[0,2.38,27.49],[1,1.25,100],[2,1.06,25100]],"ltp":2.38,"tv":18.38,"id":26354927}]}]}
{"op":"mcm","clk":"11871712942","pt":1723566613069,"mc":[{"id":"1.231659753","rc":[{"batb":[[0,2.4,10],[1,2.38,27.49],[2,1.25,100]],"ltp":2.38,"tv":18.38,"id":26354927}]}]}
{"op":"mcm","clk":"11871714015","pt":1723566620297,"mc":[{"id":"1.231659753","rc":[{"batb":[[0,2.38,27.49],[1,1.25,100],[2,1.06,25100]],"ltp":2.38,"tv":18.38,"id":26354927}]}]}
{"op":"mcm","clk":"11871714502","pt":1723566624100,"mc":[{"id":"1.231659753","rc":[{"batb":[[0,2.4,10],[1,2.38,27.49],[2,1.25,100]],"ltp":2.38,"tv":18.38,"id":26354927}]}]}
{"op":"mcm","clk":"11871715358","pt":1723566630987,"mc":[{"id":"1.231659753","rc":[{"batb":[[0,2.38,27.49],[1,1.25,100],[2,1.06,25100]],"ltp":2.38,"tv":18.38,"id":26354927}]}]}
{"op":"mcm","clk":"11871715696","pt":1723566633900,"mc":[{"id":"1.231659753","rc":[{"batb":[[0,2.4,10],[1,2.38,27.49],[2,1.25,100]],"ltp":2.38,"tv":18.38,"id":26354927}]}]}
{"op":"mcm","clk":"11871716442","pt":1723566640666,"mc":[{"id":"1.231659753","rc":[{"batb":[[0,2.38,27.49],[1,1.25,100],[2,1.06,25100]],"ltp":2.38,"tv":18.38,"id":26354927}]}]}
{"op":"mcm","clk":"11871716837","pt":1723566643245,"mc":[{"id":"1.231659753","rc":[{"batb":[[0,2.4,10],[1,2.38,27.49],[2,1.25,100]],"ltp":2.38,"tv":18.38,"id":26354927}]}]}
{"op":"mcm","clk":"11871717459","pt":1723566648847,"mc":[{"id":"1.231659753","rc":[{"batb":[[0,2.38,27.49],[1,1.25,100],[2,1.06,25100]],"ltp":2.38,"tv":18.38,"id":26354927}]}]}
{"op":"mcm","clk":"11871763441","pt":1723567232751,"mc":[{"id":"1.231659753","rc":[{"batb":[[2,1.57,1226.92]],"ltp":1.66,"tv":35.78,"id":26354926}]}]}
{"op":"mcm","clk":"11871938450","pt":1723569175025,"mc":[{"id":"1.231659753","rc":[{"trd":[[1.1,14.19]],"ltp":2.38,"tv":18.38,"id":26354927},{"trd":[[1.66,26.12],[1.73,4.76],[1.77,0.91]],"ltp":1.66,"tv":35.78,"id":26354926}],"tv":54.16}]}
{"op":"mcm","clk":"11871961068","pt":1723569379631,"mc":[{"id":"1.231659753","rc":[{"batb":[[0,2.4,10],[1,2.38,27.49],[2,1.25,100]],"ltp":2.38,"tv":18.38,"id":26354927}]}]}
{"op":"mcm","clk":"11871961541","pt":1723569383747,"mc":[{"id":"1.231659753","rc":[{"batb":[[0,2.38,27.49],[1,1.25,100],[2,1.06,25100]],"ltp":2.38,"tv":18.38,"id":26354927}]}]}
{"op":"mcm","clk":"11871961948","pt":1723569387430,"mc":[{"id":"1.231659753","rc":[{"batb":[[0,2.4,10],[1,2.38,27.49],[2,1.25,100]],"ltp":2.38,"tv":18.38,"id":26354927}]}]}
{"op":"mcm","clk":"11871963007","pt":1723569398531,"mc":[{"id":"1.231659753","rc":[{"batb":[[0,2.38,27.49],[1,1.25,100],[2,1.06,25100]],"ltp":2.38,"tv":18.38,"id":26354927}]}]}
{"op":"mcm","clk":"11871963580","pt":1723569404666,"mc":[{"id":"1.231659753","rc":[{"batb":[[0,2.4,10],[1,2.38,27.49],[2,1.25,100]],"ltp":2.38,"tv":18.38,"id":26354927}]}]}
{"op":"mcm","clk":"11871964354","pt":1723569412465,"mc":[{"id":"1.231659753","rc":[{"batb":[[0,2.38,27.49],[1,1.25,100],[2,1.06,25100]],"ltp":2.38,"tv":18.38,"id":26354927}]}]}
{"op":"mcm","clk":"11871964853","pt":1723569416584,"mc":[{"id":"1.231659753","rc":[{"batb":[[0,2.4,10],[1,2.38,27.49],[2,1.25,100]],"ltp":2.38,"tv":18.38,"id":26354927}]}]}
{"op":"mcm","clk":"11871965665","pt":1723569424993,"mc":[{"id":"1.231659753","rc":[{"batb":[[0,2.38,27.49],[1,1.25,100],[2,1.06,25100]],"ltp":2.38,"tv":18.38,"id":26354927}]}]}
{"op":"mcm","clk":"11871966132","pt":1723569429720,"mc":[{"id":"1.231659753","rc":[{"batb":[[0,2.4,10],[1,2.38,27.49],[2,1.25,100]],"ltp":2.38,"tv":18.38,"id":26354927}]}]}
{"op":"mcm","clk":"11871966809","pt":1723569436402,"mc":[{"id":"1.231659753","rc":[{"batb":[[0,2.38,27.49],[1,1.25,100],[2,1.06,25100]],"ltp":2.38,"tv":18.38,"id":26354927}]}]}
{"op":"mcm","clk":"11871967160","pt":1723569440098,"mc":[{"id":"1.231659753","rc":[{"batb":[[0,2.4,10],[1,2.38,27.49],[2,1.25,100]],"ltp":2.38,"tv":18.38,"id":26354927}]}]}
{"op":"mcm","clk":"11871967807","pt":1723569446519,"mc":[{"id":"1.231659753","rc":[{"batb":[[0,2.38,27.49],[1,1.25,100],[2,1.06,25100]],"ltp":2.38,"tv":18.38,"id":26354927}]}]}
{"op":"mcm","clk":"11871968192","pt":1723569450108,"mc":[{"id":"1.231659753","rc":[{"batb":[[0,2.4,10],[1,2.38,27.49],[2,1.25,100]],"ltp":2.38,"tv":18.38,"id":26354927}]}]}
{"op":"mcm","clk":"11871968958","pt":1723569457024,"mc":[{"id":"1.231659753","rc":[{"batb":[[0,2.38,27.49],[1,1.25,100],[2,1.06,25100]],"ltp":2.38,"tv":18.38,"id":26354927}]}]}
{"op":"mcm","clk":"11871969322","pt":1723569460517,"mc":[{"id":"1.231659753","rc":[{"batb":[[0,2.4,10],[1,2.38,27.49],[2,1.25,100]],"ltp":2.38,"tv":18.38,"id":26354927}]}]}
{"op":"mcm","clk":"11871970033","pt":1723569466935,"mc":[{"id":"1.231659753","rc":[{"batb":[[0,2.38,27.49],[1,1.25,100],[2,1.06,25100]],"ltp":2.38,"tv":18.38,"id":26354927}]}]}
{"op":"mcm","clk":"11871970371","pt":1723569470414,"mc":[{"id":"1.231659753","rc":[{"batb":[[0,2.4,10],[1,2.38,27.49],[2,1.25,100]],"ltp":2.38,"tv":18.38,"id":26354927}]}]}
{"op":"mcm","clk":"11871970983","pt":1723569477065,"mc":[{"id":"1.231659753","rc":[{"batb":[[0,2.38,27.49],[1,1.25,100],[2,1.06,25100]],"ltp":2.38,"tv":18.38,"id":26354927}]}]}
{"op":"mcm","clk":"11872020740","pt":1723569966139,"mc":[{"id":"1.231659753","rc":[{"trd":[[2.54,1]],"ltp":2.54,"tv":19.38,"id":26354927},{"trd":[[1.62,26],[1.64,1.55],[1.65,3.53],[1.66,141.08]],"batb":[[0,1.57,1226.92],[1,1.36,25],[2,1.25,100]],"batl":[[0,1.61,74.44],[1,1.71,2],[2,1.72,10]],"ltp":1.62,"tv":181.82,"id":26354926}],"tv":201.2}]}
{"op":"mcm","clk":"11872024051","pt":1723570003795,"mc":[{"id":"1.231659753","rc":[{"batl":[[0,1.63,74.44]],"ltp":1.62,"tv":181.82,"id":26354926}]}]}
{"op":"mcm","clk":"11872024281","pt":1723570006634,"mc":[{"id":"1.231659753","rc":[{"batb":[[0,1.62,61.19],[1,1.57,1226.92],[2,1.36,25]],"ltp":1.62,"tv":181.82,"id":26354926}]}]}
{"op":"mcm","clk":"11872029930","pt":1723570072201,"mc":[{"id":"1.231659753","rc":[{"trd":[[1.63,5.92]],"batl":[[0,1.63,71.48]],"ltp":1.63,"tv":187.74,"id":26354926}],"tv":207.12}]}
{"op":"mcm","clk":"11872032581","pt":1723570102126,"mc":[{"id":"1.231659753","rc":[{"trd":[[1.63,11.84]],"batl":[[0,1.63,68.52]],"ltp":1.63,"tv":193.66,"id":26354926}],"tv":213.04}]}
{"op":"mcm","clk":"11872038456","pt":1723570160124,"mc":[{"id":"1.231659753","rc":[{"batl":[[1,1.67,21.06],[2,1.71,2]],"ltp":1.63,"tv":193.66,"id":26354926}]}]}
{"op":"mcm","clk":"11872039122","pt":1723570166693,"mc":[{"id":"1.231659753","rc":[{"batl":[[1,1.7,21.06]],"ltp":1.63,"tv":193.66,"id":26354926}]}]}
{"op":"mcm","clk":"11872080636","pt":1723570562999,"mc":[{"id":"1.231659753","rc":[{"batb":[[1,1.6,66],[2,1.57,1226.92]],"ltp":1.63,"tv":193.66,"id":26354926}]}]}
{"op":"mcm","clk":"11872202547","pt":1723571754463,"mc":[{"id":"1.231659753","rc":[{"trd":[[1.63,31.34]],"batl":[[0,1.63,58.77]],"ltp":1.63,"tv":213.16,"id":26354926}],"tv":232.54}]}
{"op":"mcm","clk":"11872393647","pt":1723573218699,"mc":[{"id":"1.231659753","rc":[{"trd":[[1.63,31.33],[1.66,141.09],[1.73,4.76]],"ltp":1.63,"tv":213.16,"id":26354926}],"tv":232.54}]}
{"op":"mcm","clk":"11872496937","pt":1723573917858,"mc":[{"id":"1.231659753","rc":[{"batb":[[2,1.57,276.92]],"ltp":1.63,"tv":213.16,"id":26354926}]}]}
{"op":"mcm","clk":"11872512569","pt":1723574020930,"mc":[{"id":"1.231659753","rc":[{"batb":[[0,2.46,25.98]],"ltp":2.54,"tv":19.38,"id":26354927}]}]}
{"op":"mcm","clk":"11872513297","pt":1723574027032,"mc":[{"id":"1.231659753","rc":[{"trd":[[2.58,37.13]],"batb":[[0,2.48,10],[1,2.46,25.98],[2,1.25,100]],"batl":[[0,2.58,10171.2]],"ltp":2.58,"tv":56.51,"id":26354927},{"trd":[[1.63,90.1]],"batl":[[0,1.7,21.06],[1,1.71,2],[2,1.72,10]],"ltp":1.63,"tv":271.93,"id":26354926}],"tv":328.44}]}
{"op":"mcm","clk":"11872513738","pt":1723574030426,"mc":[{"id":"1.231659753","rc":[{"batb":[[0,2.46,25.98],[1,1.25,100],[2,1.06,25100]],"ltp":2.58,"tv":56.51,"id":26354927}]}]}
{"op":"mcm","clk":"11872807941","pt":1723575643330,"mc":[{"id":"1.231659753","rc":[{"trd":[[1.1,14.19]],"ltp":2.58,"tv":56.5,"id":26354927},{"trd":[[1.62,28.88],[1.63,90.1],[1.66,141.09],[1.73,4.75],[1.77,0.9]],"batb":[[0,1.62,59.75]],"ltp":1.62,"tv":274.8,"id":26354926}],"tv":331.31}]}
{"op":"mcm","clk":"11872808600","pt":1723575647205,"mc":[{"id":"1.231659753","rc":[{"batb":[[0,1.62,61.19]],"ltp":1.62,"tv":274.8,"id":26354926}]}]}
{"op":"mcm","clk":"11873107963","pt":1723577258724,"mc":[{"id":"1.231659753","rc":[{"trd":[[2.46,0.35]],"ltp":2.46,"tv":56.85,"id":26354927},{"trd":[[1.69,0.51]],"ltp":1.69,"tv":275.31,"id":26354926}],"tv":332.17}]}
{"op":"mcm","clk":"11873110877","pt":1723577274246,"mc":[{"id":"1.231659753","rc":[{"batl":[[0,1.68,10],[1,1.7,21.06],[2,1.71,2]],"ltp":1.69,"tv":275.31,"id":26354926}]}]}
{"op":"mcm","clk":"11873248819","pt":1723578134046,"mc":[{"id":"1.231659753","rc":[{"trd":[[1.62,34.88]],"batb":[[0,1.62,58.19]],"ltp":1.62,"tv":281.31,"id":26354926}],"tv":338.17}]}
{"op":"mcm","clk":"11873249224","pt":1723578136948,"mc":[{"id":"1.231659753","rc":[{"batb":[[0,1.62,61.19]],"ltp":1.62,"tv":281.31,"id":26354926}]}]}
{"op":"mcm","clk":"11873261210","pt":1723578219344,"mc":[{"id":"1.231659753","rc":[{"trd":[[1.62,54.88]],"batb":[[0,1.62,51.19]],"ltp":1.62,"tv":301.31,"id":26354926}],"tv":358.17}]}
{"op":"mcm","clk":"11873261585","pt":1723578222343,"mc":[{"id":"1.231659753","rc":[{"batb":[[0,1.62,61.19]],"ltp":1.62,"tv":301.31,"id":26354926}]}]}
{"op":"mcm","clk":"11873291535","pt":1723578428255,"mc":[{"id":"1.231659753","rc":[{"batb":[[1,1.6,69.35]],"ltp":1.62,"tv":301.31,"id":26354926}]}]}
{"op":"mcm","clk":"11873291775","pt":1723578429821,"mc":[{"id":"1.231659753","rc":[{"batb":[[1,1.6,66]],"ltp":1.62,"tv":301.31,"id":26354926}]}]}
{"op":"mcm","clk":"11873295293","pt":1723578452855,"mc":[{"id":"1.231659753","rc":[{"trd":[[1.62,177.26]],"batb":[[0,1.6,66],[1,1.57,276.92],[2,1.54,950]],"batl":[[0,1.62,5246.42],[1,1.68,10],[2,1.7,21.06]],"ltp":1.62,"tv":423.69,"id":26354926}],"tv":480.55}]}
{"op":"mcm","clk":"11873295349","pt":1723578453269,"mc":[{"id":"1.231659753","rc":[{"batb":[[1,1.58,65.41],[2,1.57,276.92]],"ltp":1.62,"tv":423.69,"id":26354926}]}]}
{"op":"mcm","clk":"11873322651","pt":1723578619201,"mc":[{"id":"1.231659753","rc":[{"batl":[[0,1.61,250],[1,1.62,5246.42],[2,1.68,10]],"ltp":1.62,"tv":423.69,"id":26354926}]}]}
{"op":"mcm","clk":"11873325697","pt":1723578636376,"mc":[{"id":"1.231659753","rc":[{"trd":[[1.6,132]],"batb":[[0,1.58,65.41],[1,1.57,276.92],[2,1.54,950]],"batl":[[0,1.6,5241.61],[1,1.61,250],[2,1.62,5246.42]],"ltp":1.6,"tv":555.69,"id":26354926}],"tv":612.55}]}
{"op":"mcm","clk":"11873328012","pt":1723578649512,"mc":[{"id":"1.231659753","rc":[{"batl":[[0,1.61,250],[1,1.62,5246.42],[2,1.68,10]],"ltp":1.6,"tv":555.69,"id":26354926}]}]}
{"op":"mcm","clk":"11873328337","pt":1723578651304,"mc":[{"id":"1.231659753","rc":[{"batl":[[1,1.68,10],[2,1.7,21.06]],"ltp":1.6,"tv":555.69,"id":26354926}]}]}
{"op":"mcm","clk":"11873330951","pt":1723578666127,"mc":[{"id":"1.231659753","rc":[{"batb":[[0,1.59,66],[1,1.58,65.41],[2,1.57,276.92]],"ltp":1.6,"tv":555.69,"id":26354926}]}]}
{"op":"mcm","clk":"11873343659","pt":1723578737800,"mc":[{"id":"1.231659753","rc":[{"trd":[[1.61,500]],"batb":[[0,1.61,651.62],[1,1.59,66],[2,1.58,65.41]],"batl":[[0,1.67,302.53]],"ltp":1.61,"tv":1055.69,"id":26354926}],"tv":1112.55}]}
{"op":"mcm","clk":"11873343849","pt":1723578738898,"mc":[{"id":"1.231659753","rc":[{"batl":[[0,1.68,10],[1,1.7,21.06],[2,1.71,2]],"ltp":1.61,"tv":1055.69,"id":26354926}]}]}
{"op":"mcm","clk":"11873347420","pt":1723578759221,"mc":[{"id":"1.231659753","rc":[{"trd":[[1.61,1803.24]],"batb":[[0,1.59,66],[1,1.58,65.41],[2,1.57,276.92]],"batl":[[0,1.61,4655.99],[1,1.68,10],[2,1.7,21.06]],"ltp":1.61,"tv":2358.93,"id":26354926}],"tv":2415.79}]}
{"op":"mcm","clk":"11873348413","pt":1723578764755,"mc":[{"id":"1.231659753","rc":[{"batb":[[0,2.6,23.71]],"ltp":2.46,"tv":56.85,"id":26354927},{"batb":[[1,1.57,343.48],[2,1.54,950]],"ltp":1.61,"tv":2358.93,"id":26354926}]}]}
{"op":"mcm","clk":"11873349503","pt":1723578771147,"mc":[{"id":"1.231659753","rc":[{"batl":[[0,1.68,10],[1,1.7,21.06],[2,1.71,2]],"ltp":1.61,"tv":2358.93,"id":26354926}]}]}
{"op":"mcm","clk":"11873351074","pt":1723578780241,"mc":[{"id":"1.231659753","rc":[{"batb":[[0,1.58,66]],"ltp":1.61,"tv":2358.93,"id":26354926}]}]}
{"op":"mcm","clk":"11873354124","pt":1723578797731,"mc":[{"id":"1.231659753","rc":[{"batb":[[0,1.57,409.48],[1,1.54,950],[2,1.46,1400]],"ltp":1.61,"tv":2358.93,"id":26354926}]}]}
{"op":"mcm","clk":"11873356776","pt":1723578813083,"mc":[{"id":"1.231659753","rc":[{"batb":[[0,1.58,66],[1,1.57,343.48],[2,1.54,950]],"ltp":1.61,"tv":2358.93,"id":26354926}]}]}
{"op":"mcm","clk":"11873360221","pt":1723578834124,"mc":[{"id":"1.231659753","rc":[{"batl":[[0,1.63,66],[1,1.68,10],[2,1.7,21.06]],"ltp":1.61,"tv":2358.93,"id":26354926}]}]}
{"op":"mcm","clk":"11873374425","pt":1723578917620,"mc":[{"id":"1.231659753","rc":[{"batl":[[0,1.62,66]],"ltp":1.61,"tv":2358.93,"id":26354926}]}]}
{"op":"mcm","clk":"11873380009","pt":1723578950665,"mc":[{"id":"1.231659753","rc":[{"batl":[[1,1.67,21.06],[2,1.68,10]],"ltp":1.61,"tv":2358.93,"id":26354926}]}]}
{"op":"mcm","clk":"11873402809","pt":1723579096564,"mc":[{"id":"1.231659753","rc":[{"batb":[[0,1.58,451.1]],"ltp":1.61,"tv":2358.93,"id":26354926}]}]}
{"op":"mcm","clk":"11873412580","pt":1723579158725,"mc":[{"id":"1.231659753","rc":[{"batb":[[2,1.06,31766.66]],"ltp":2.46,"tv":56.85,"id":26354927}]}]}
{"op":"mcm","clk":"11873412765","pt":1723579159837,"mc":[{"id":"1.231659753","rc":[{"batb":[[2,1.07,5714.28]],"ltp":2.46,"tv":56.85,"id":26354927}]}]}
{"op":"mcm","clk":"11873412913","pt":1723579160637,"mc":[{"id":"1.231659753","rc":[{"batb":[[2,1.08,9999.98]],"ltp":2.46,"tv":56.85,"id":26354927}]}]}
{"op":"mcm","clk":"11873420308","pt":1723579209684,"mc":[{"id":"1.231659753","rc":[{"trd":[[1.1,14.2]],"ltp":2.46,"tv":56.86,"id":26354927},{"trd":[[1.62,214.82],[1.63,90.1],[1.66,141.1],[1.73,4.76]],"batb":[[0,1.59,5],[1,1.58,450.88],[2,1.57,343.48]],"batl":[[0,1.62,47.22]],"ltp":1.62,"tv":2396.5,"id":26354926}],"tv":2453.37}]}
{"op":"mcm","clk":"11873421130","pt":1723579215102,"mc":[{"id":"1.231659753","rc":[{"trd":[[1.62,229.36]],"batl":[[0,1.62,39.95]],"ltp":1.62,"tv":2411.04,"id":26354926}],"tv":2467.91}]}
{"op":"mcm","clk":"11873421934","pt":1723579220517,"mc":[{"id":"1.231659753","rc":[{"trd":[[2.6,19.06]],"batb":[[0,2.6,4.65]],"ltp":2.6,"tv":75.92,"id":26354927},{"trd":[[1.62,309.26],[1.63,120.5]],"batb":[[0,1.59,13]],"batl":[[0,1.67,21.06],[1,1.68,10],[2,1.71,2]],"ltp":1.63,"tv":2521.34,"id":26354926}],"tv":2597.27}]}
{"op":"mcm","clk":"11873422125","pt":1723579221798,"mc":[{"id":"1.231659753","rc":[{"batb":[[0,2.5,25.29]],"ltp":2.6,"tv":75.92,"id":26354927},{"batb":[[0,1.62,61.19],[1,1.61,25],[2,1.6,148.88]],"ltp":1.63,"tv":2521.34,"id":26354926}]}]}
{"op":"mcm","clk":"11873422278","pt":1723579222900,"mc":[{"id":"1.231659753","rc":[{"batb":[[2,1.58,450.88]],"ltp":1.63,"tv":2521.34,"id":26354926}]}]}
{"op":"mcm","clk":"11873422332","pt":1723579223213,"mc":[{"id":"1.231659753","rc":[{"batb":[[1,1.59,25]],"ltp":1.63,"tv":2521.34,"id":26354926}]}]}
{"op":"mcm","clk":"11873431995","pt":1723579291858,"mc":[{"id":"1.231659753","rc":[{"trd":[[1.62,798.88]],"batb":[[0,1.59,25],[1,1.58,516.29],[2,1.57,276.92]],"batl":[[0,1.62,5062.8],[1,1.67,21.06],[2,1.68,10]],"ltp":1.62,"tv":3010.96,"id":26354926}],"tv":3086.89}]}
{"op":"mcm","clk":"11873432062","pt":1723579292485,"mc":[{"id":"1.231659753","rc":[{"trd":[[1.62,835.96]],"batl":[[0,1.62,5044.26]],"ltp":1.62,"tv":3048.04,"id":26354926}],"tv":3123.97}]}
{"op":"mcm","clk":"11873432626","pt":1723579296884,"mc":[{"id":"1.231659753","rc":[{"batb":[[0,2.6,23.71]],"ltp":2.6,"tv":75.92,"id":26354927}]}]}
{"op":"mcm","clk":"11873432678","pt":1723579297371,"mc":[{"id":"1.231659753","rc":[{"batb":[[1,1.58,548.29],[2,1.57,304.92]],"ltp":1.62,"tv":3048.04,"id":26354926}]}]}
{"op":"mcm","clk":"11873433492","pt":1723579303773,"mc":[{"id":"1.231659753","rc":[{"trd":[[1.62,1737.58]],"batl":[[0,1.62,4593.45]],"ltp":1.62,"tv":3949.66,"id":26354926}],"tv":4025.59}]}
{"op":"mcm","clk":"11873433568","pt":1723579304399,"mc":[{"id":"1.231659753","rc":[{"batb":[[0,1.59,1527.13]],"ltp":1.62,"tv":3949.66,"id":26354926}]}]}
{"op":"mcm","clk":"11873434025","pt":1723579307911,"mc":[{"id":"1.231659753","rc":[{"batb":[[1,1.58,482.29]],"ltp":1.62,"tv":3949.66,"id":26354926}]}]}
{"op":"mcm","clk":"11873434873","pt":1723579313819,"mc":[{"id":"1.231659753","rc":[{"trd":[[1.62,5885.06]],"batl":[[0,1.62,2519.71]],"ltp":1.62,"tv":8097.14,"id":26354926}],"tv":8173.07}]}
{"op":"mcm","clk":"11873436350","pt":1723579324548,"mc":[{"id":"1.231659753","rc":[{"batb":[[0,2.62,4],[1,2.6,27.71],[2,1.25,100]],"batl":[[0,2.7,4]],"ltp":2.6,"tv":75.92,"id":26354927},{"batb":[[0,1.59,1531.13]],"batl":[[0,1.62,2523.71]],"ltp":1.62,"tv":8097.14,"id":26354926}]}]}
{"op":"mcm","clk":"11873436523","pt":1723579325831,"mc":[{"id":"1.231659753","rc":[{"trd":[[2.64,2.92]],"batb":[[0,2.64,1.08],[1,2.62,4],[2,2.6,27.71]],"batl":[[0,2.72,1.2]],"ltp":2.64,"tv":78.84,"id":26354927},{"trd":[[1.61,1808.04],[1.62,6029.32]],"batb":[[0,1.59,29],[1,1.58,469.29],[2,1.57,276.92]],"batl":[[0,1.62,2451.58]],"ltp":1.61,"tv":8246.2,"id":26354926}],"tv":8325.05}]}
{"op":"mcm","clk":"11873436802","pt":1723579327737,"mc":[{"id":"1.231659753","rc":[{"batb":[[0,2.62,4],[1,2.6,27.71],[2,1.25,100]],"ltp":2.64,"tv":78.84,"id":26354927}]}]}
{"op":"mcm","clk":"11873436864","pt":1723579328261,"mc":[{"id":"1.231659753","rc":[{"batb":[[0,1.59,741.87],[1,1.58,481.29],[2,1.57,303.92]],"ltp":1.61,"tv":8246.2,"id":26354926}]}]}
{"op":"mcm","clk":"11873437028","pt":1723579329638,"mc":[{"id":"1.231659753","rc":[{"batb":[[0,1.59,1146.25],[1,1.58,469.29],[2,1.57,276.92]],"ltp":1.61,"tv":8246.2,"id":26354926}]}]}
{"op":"mcm","clk":"11873437091","pt":1723579330141,"mc":[{"id":"1.231659753","rc":[{"batb":[[1,1.58,481.29],[2,1.57,304.92]],"ltp":1.61,"tv":8246.2,"id":26354926}]}]}
{"op":"mcm","clk":"11873438332","pt":1723579339652,"mc":[{"id":"1.231659753","rc":[{"batl":[[0,2.7,4]],"ltp":2.64,"tv":78.84,"id":26354927}]}]}
{"op":"mcm","clk":"11873438495","pt":1723579340860,"mc":[{"id":"1.231659753","rc":[{"trd":[[2.64,5.84]],"batb":[[0,2.64,1.08],[1,2.62,4],[2,2.6,27.71]],"batl":[[0,2.72,1.2]],"ltp":2.64,"tv":81.76,"id":26354927},{"trd":[[1.61,1812.84]],"batb":[[0,1.59,29],[1,1.58,469.29],[2,1.57,276.92]],"ltp":1.61,"tv":8251.0,"id":26354926}],"tv":8332.77}]}
{"op":"mcm","clk":"11873438729","pt":1723579342728,"mc":[{"id":"1.231659753","rc":[{"batb":[[0,2.62,4],[1,2.6,27.71],[2,1.25,100]],"ltp":2.64,"tv":81.76,"id":26354927}]}]}
{"op":"mcm","clk":"11873438796","pt":1723579343343,"mc":[{"id":"1.231659753","rc":[{"batb":[[0,1.59,1216.1],[1,1.58,481.29],[2,1.57,299.92]],"ltp":1.61,"tv":8251.0,"id":26354926}]}]}
{"op":"mcm","clk":"11873440360","pt":1723579354749,"mc":[{"id":"1.231659753","rc":[{"batl":[[0,2.7,4]],"ltp":2.64,"tv":81.76,"id":26354927}]}]}
{"op":"mcm","clk":"11873440483","pt":1723579355749,"mc":[{"id":"1.231659753","rc":[{"trd":[[2.64,7.3]],"batb":[[0,2.64,2.54],[1,2.62,4],[2,2.6,27.71]],"batl":[[0,2.72,1.2]],"ltp":2.64,"tv":83.22,"id":26354927},{"trd":[[1.61,1815.24]],"batb":[[0,1.59,29],[1,1.58,469.29],[2,1.57,276.92]],"ltp":1.61,"tv":8253.4,"id":26354926}],"tv":8336.63}]}
{"op":"mcm","clk":"11873440767","pt":1723579357863,"mc":[{"id":"1.231659753","rc":[{"batb":[[0,2.62,4],[1,2.6,27.71],[2,1.25,100]],"ltp":2.64,"tv":83.22,"id":26354927},{"batb":[[0,1.59,1228.75],[1,1.58,481.29],[2,1.57,298.92]],"ltp":1.61,"tv":8253.4,"id":26354926}]}]}
{"op":"mcm","clk":"11873441156","pt":1723579360656,"mc":[{"id":"1.231659753","rc":[{"trd":[[1.62,6031.32]],"batl":[[0,1.62,2450.58]],"ltp":1.62,"tv":8255.4,"id":26354926}],"tv":8338.63}]}
{"op":"mcm","clk":"11873442338","pt":1723579369894,"mc":[{"id":"1.231659753","rc":[{"batl":[[0,2.7,4]],"ltp":2.64,"tv":83.22,"id":26354927}]}]}
{"op":"mcm","clk":"11873442442","pt":1723579370581,"mc":[{"id":"1.231659753","rc":[{"trd":[[2.64,10.22]],"batb":[[0,2.64,1.08],[1,2.62,4],[2,2.6,27.71]],"batl":[[1,2.72,1.2]],"ltp":2.64,"tv":86.14,"id":26354927},{"trd":[[1.61,1820.04]],"batb":[[0,1.59,29],[1,1.58,469.29],[2,1.57,276.92]],"ltp":1.61,"tv":8260.2,"id":26354926}],"tv":8346.35}]}
{"op":"mcm","clk":"11873442741","pt":1723579372869,"mc":[{"id":"1.231659753","rc":[{"batb":[[0,2.62,4],[1,2.6,27.71],[2,1.25,100]],"ltp":2.64,"tv":86.14,"id":26354927},{"batb":[[1,1.58,481.29],[2,1.57,298.92]],"ltp":1.61,"tv":8260.2,"id":26354926}]}]}
{"op":"mcm","clk":"11873442771","pt":1723579373072,"mc":[{"id":"1.231659753","rc":[{"batb":[[0,1.59,1182.6]],"ltp":1.61,"tv":8260.2,"id":26354926}]}]}
{"op":"mcm","clk":"11873443662","pt":1723579379697,"mc":[{"id":"1.231659753","rc":[{"trd":[[1.62,9637.82]],"batl":[[0,1.62,647.33]],"ltp":1.62,"tv":11866.7,"id":26354926}],"tv":11952.85}]}
{"op":"mcm","clk":"11873444070","pt":1723579382802,"mc":[{"id":"1.231659753","rc":[{"batb":[[0,1.6,1],[1,1.59,1182.6],[2,1.58,481.29]],"ltp":1.62,"tv":11866.7,"id":26354926}]}]}
{"op":"mcm","clk":"11873444474","pt":1723579385816,"mc":[{"id":"1.231659753","rc":[{"trd":[[2.64,14.22]],"batl":[[0,2.7,4]],"ltp":2.64,"tv":90.14,"id":26354927},{"trd":[[1.61,1826.6]],"batb":[[0,1.6,5],[1,1.59,29]],"ltp":1.61,"tv":11873.26,"id":26354926}],"tv":11963.41}]}
{"op":"mcm","clk":"11873444502","pt":1723579385979,"mc":[{"id":"1.231659753","rc":[{"batb":[[2,1.58,450.29]],"ltp":1.61,"tv":11873.26,"id":26354926}]}]}
{"op":"mcm","clk":"11873444740","pt":1723579387706,"mc":[{"id":"1.231659753","rc":[{"batb":[[1,2.6,4]],"ltp":2.64,"tv":90.14,"id":26354927},{"batb":[[1,1.59,12],[2,1.58,384.88]],"ltp":1.61,"tv":11873.26,"id":26354926}]}]}
{"op":"mcm","clk":"11873444875","pt":1723579388813,"mc":[{"id":"1.231659753","rc":[{"trd":[[2.64,18.22]],"ltp":2.64,"tv":94.14,"id":26354927},{"trd":[[1.61,1833.16]],"batb":[[0,1.6,1]],"ltp":1.61,"tv":11879.82,"id":26354926}],"tv":11973.97}]}
{"op":"mcm","clk":"11873445348","pt":1723579392424,"mc":[{"id":"1.231659753","rc":[{"batb":[[1,2.6,27.71]],"ltp":2.64,"tv":94.14,"id":26354927},{"batb":[[1,1.59,24],[2,1.58,450.29]],"ltp":1.61,"tv":11879.82,"id":26354926}]}]}
{"op":"mcm","clk":"11873446363","pt":1723579400103,"mc":[{"id":"1.231659753","rc":[{"batl":[[0,2.7,4]],"ltp":2.64,"tv":94.14,"id":26354927},{"batb":[[0,1.6,5]],"ltp":1.61,"tv":11879.82,"id":26354926}]}]}
{"op":"mcm","clk":"11873446500","pt":1723579401304,"mc":[{"id":"1.231659753","rc":[{"trd":[[2.64,22.22]],"batl":[[1,2.72,1.2]],"ltp":2.64,"tv":98.14,"id":26354927},{"trd":[[1.61,1839.72]],"ltp":1.61,"tv":11886.38,"id":26354926}],"tv":11984.53}]}
{"op":"mcm","clk":"11873446671","pt":1723579402628,"mc":[{"id":"1.231659753","rc":[{"trd":[[2.64,32.22]],"batb":[[1,2.6,4]],"ltp":2.64,"tv":108.14,"id":26354927},{"trd":[[1.61,1856.12]],"batb":[[1,1.59,12],[2,1.58,384.88]],"ltp":1.61,"tv":11902.78,"id":26354926}],"tv":12010.93}]}
{"op":"mcm","clk":"11873446741","pt":1723579403100,"mc":[{"id":"1.231659753","rc":[{"batb":[[0,1.6,1]],"ltp":1.61,"tv":11902.78,"id":26354926}]}]}
{"op":"mcm","clk":"11873447419","pt":1723579407634,"mc":[{"id":"1.231659753","rc":[{"batb":[[1,2.6,27.71]],"ltp":2.64,"tv":108.14,"id":26354927},{"batb":[[1,1.59,24],[2,1.58,450.29]],"ltp":1.61,"tv":11902.78,"id":26354926}]}]}
{"op":"mcm","clk":"11873448611","pt":1723579415733,"mc":[{"id":"1.231659753","rc":[{"trd":[[2.64,36.22]],"batl":[[0,2.7,4],[1,2.72,1.2]],"ltp":2.64,"tv":112.14,"id":26354927},{"trd":[[1.61,1862.68]],"batb":[[0,1.6,5]],"ltp":1.61,"tv":11909.34,"id":26354926}],"tv":12021.49}]}
{"op":"mcm","clk":"11873448792","pt":1723579416853,"mc":[{"id":"1.231659753","rc":[{"trd":[[2.64,46.22]],"ltp":2.64,"tv":122.14,"id":26354927},{"trd":[[1.61,1879.08]],"ltp":1.61,"tv":11925.74,"id":26354926}],"tv":12047.89}]}
{"op":"mcm","clk":"11873448935","pt":1723579417634,"mc":[{"id":"1.231659753","rc":[{"batb":[[1,2.6,4]],"ltp":2.64,"tv":122.14,"id":26354927},{"batb":[[1,1.59,12],[2,1.58,384.88]],"ltp":1.61,"tv":11925.74,"id":26354926}]}]}
{"op":"mcm","clk":"11873449025","pt":1723579418216,"mc":[{"id":"1.231659753","rc":[{"batb":[[0,1.6,1]],"ltp":1.61,"tv":11925.74,"id":26354926}]}]}
{"op":"mcm","clk":"11873449623","pt":1723579422637,"mc":[{"id":"1.231659753","rc":[{"batb":[[1,2.6,27.71]],"ltp":2.64,"tv":122.14,"id":26354927},{"batb":[[1,1.59,25],[2,1.58,450.29]],"ltp":1.61,"tv":11925.74,"id":26354926}]}]}
{"op":"mcm","clk":"11873450691","pt":1723579430436,"mc":[{"id":"1.231659753","rc":[{"batl":[[0,2.7,4]],"ltp":2.64,"tv":122.14,"id":26354927},{"batb":[[0,1.6,5]],"ltp":1.61,"tv":11925.74,"id":26354926}]}]}
{"op":"mcm","clk":"11873450899","pt":1723579431860,"mc":[{"id":"1.231659753","rc":[{"trd":[[2.64,50.22]],"ltp":2.64,"tv":126.14,"id":26354927},{"trd":[[1.61,1885.64]],"ltp":1.61,"tv":11932.3,"id":26354926}],"tv":12058.45}]}
{"op":"mcm","clk":"11873451034","pt":1723579432858,"mc":[{"id":"1.231659753","rc":[{"trd":[[2.64,60.22]],"batb":[[1,2.6,4]],"ltp":2.64,"tv":136.14,"id":26354927},{"trd":[[1.61,1902.04]],"batb":[[1,1.59,13],[2,1.58,384.88]],"ltp":1.61,"tv":11948.7,"id":26354926}],"tv":12084.85}]}
{"op":"mcm","clk":"11873451078","pt":1723579433123,"mc":[{"id":"1.231659753","rc":[{"batb":[[0,1.6,1]],"ltp":1.61,"tv":11948.7,"id":26354926}]}]}
{"op":"mcm","clk":"11873451759","pt":1723579437763,"mc":[{"id":"1.231659753","rc":[{"batb":[[1,2.6,27.71]],"ltp":2.64,"tv":136.14,"id":26354927},{"batb":[[1,1.59,25],[2,1.58,450.29]],"ltp":1.61,"tv":11948.7,"id":26354926}]}]}
{"op":"mcm","clk":"11873452649","pt":1723579444460,"mc":[{"id":"1.231659753","rc":[{"trd":[[1.58,748],[1.59,50],[1.6,134]],"batb":[[0,1.59,20],[1,1.58,1591.44],[2,1.57,276.92]],"ltp":1.58,"tv":12748.7,"id":26354926}],"tv":12884.85}]}
{"op":"mcm","clk":"11873452833","pt":1723579445881,"mc":[{"id":"1.231659753","rc":[{"batb":[[0,2.64,4],[1,2.62,4],[2,2.6,27.71]],"batl":[[0,2.7,4]],"ltp":2.64,"tv":136.14,"id":26354927},{"batb":[[0,1.59,24],[1,1.58,1610.44]],"batl":[[0,1.61,4],[1,1.62,647.33],[2,1.67,21.06]],"ltp":1.58,"tv":12748.7,"id":26354926}]}]}
{"op":"mcm","clk":"11873452904","pt":1723579446456,"mc":[{"id":"1.231659753","rc":[{"batl":[[1,2.72,1.2]],"ltp":2.64,"tv":136.14,"id":26354927},{"trd":[[1.61,1910.04]],"batl":[[0,1.62,647.33],[1,1.67,21.06],[2,1.68,10]],"ltp":1.61,"tv":12756.7,"id":26354926}],"tv":12892.85}]}
{"op":"mcm","clk":"11873453200","pt":1723579448368,"mc":[{"id":"1.231659753","rc":[{"batb":[[0,2.62,4],[1,2.6,27.71],[2,1.25,100]],"ltp":2.64,"tv":136.14,"id":26354927}]}]}
{"op":"mcm","clk":"11873454226","pt":1723579455898,"mc":[{"id":"1.231659753","rc":[{"trd":[[2.64,63.14]],"batb":[[0,2.64,1.08],[1,2.62,4],[2,2.6,27.71]],"ltp":2.64,"tv":139.06,"id":26354927},{"trd":[[1.61,1914.84]],"batb":[[1,1.58,76.29]],"ltp":1.61,"tv":12761.5,"id":26354926}],"tv":12900.57}]}
{"op":"mcm","clk":"11873454588","pt":1723579458595,"mc":[{"id":"1.231659753","rc":[{"batb":[[0,2.62,4],[1,2.6,27.71],[2,1.25,100]],"ltp":2.64,"tv":139.06,"id":26354927},{"batb":[[0,1.59,1096.57],[1,1.58,98.29]],"ltp":1.61,"tv":12761.5,"id":26354926}]}]}
{"op":"mcm","clk":"11873454877","pt":1723579460906,"mc":[{"id":"1.231659753","rc":[{"batl":[[0,2.7,4]],"ltp":2.64,"tv":139.06,"id":26354927},{"batb":[[0,1.6,4],[1,1.59,1096.57],[2,1.58,98.29]],"ltp":1.61,"tv":12761.5,"id":26354926}]}]}
{"op":"mcm","clk":"11873454976","pt":1723579461597,"mc":[{"id":"1.231659753","rc":[{"trd":[[2.64,67.14]],"ltp":2.64,"tv":143.06,"id":26354927},{"trd":[[1.61,1921.4]],"batb":[[1,1.59,24],[2,1.58,76.29]],"ltp":1.61,"tv":12768.06,"id":26354926}],"tv":12911.13}]}
{"op":"mcm","clk":"11873455090","pt":1723579462387,"mc":[{"id":"1.231659753","rc":[{"batb":[[0,1.59,396.61],[1,1.58,99.29],[2,1.57,276.92]],"ltp":1.61,"tv":12768.06,"id":26354926}]}]}
{"op":"mcm","clk":"11873456911","pt":1723579476787,"mc":[{"id":"1.231659753","rc":[{"trd":[[2.64,70.06]],"batb":[[0,2.64,1.08],[1,2.62,4],[2,2.6,27.71]],"batl":[[0,2.7,4],[1,2.72,1.2]],"ltp":2.64,"tv":145.98,"id":26354927},{"trd":[[1.61,1926.2]],"batb":[[0,1.59,24],[1,1.58,76.29]],"ltp":1.61,"tv":12772.86,"id":26354926}],"tv":12918.85}]}
{"op":"mcm","clk":"11873457154","pt":1723579478817,"mc":[{"id":"1.231659753","rc":[{"batb":[[0,2.62,4],[1,2.6,27.71],[2,1.25,100]],"ltp":2.64,"tv":145.98,"id":26354927}]}]}
{"op":"mcm","clk":"11873457249","pt":1723579479299,"mc":[{"id":"1.231659753","rc":[{"batb":[[0,1.59,1162.28],[1,1.58,98.29]],"ltp":1.61,"tv":12772.86,"id":26354926}]}]}
{"op":"mcm","clk":"11873457924","pt":1723579484493,"mc":[{"id":"1.231659753","rc":[{"trd":[[1.61,1951.8]],"batb":[[0,1.59,382.68],[1,1.58,76.29]],"batl":[[0,1.61,4.37],[1,1.62,647.33],[2,1.67,21.06]],"ltp":1.61,"tv":12798.47,"id":26354926}],"tv":12944.45}]}
{"op":"mcm","clk":"11873458012","pt":1723579485224,"mc":[{"id":"1.231659753","rc":[{"batb":[[1,1.58,98.29]],"ltp":1.61,"tv":12798.47,"id":26354926}]}]}
{"op":"mcm","clk":"11873458900","pt":1723579491896,"mc":[{"id":"1.231659753","rc":[{"batb":[[0,2.64,4],[1,2.62,4],[2,2.6,27.71]],"batl":[[0,2.7,4]],"ltp":2.64,"tv":145.98,"id":26354927},{"trd":[[1.61,1968.54]],"batb":[[0,1.6,4],[1,1.59,382.68],[2,1.58,76.29]],"batl":[[0,1.62,647.33],[1,1.67,21.06],[2,1.68,10]],"ltp":1.61,"tv":12815.2,"id":26354926}],"tv":12961.19}]}
{"op":"mcm","clk":"11873459070","pt":1723579492809,"mc":[{"id":"1.231659753","rc":[{"trd":[[2.64,74.06]],"batb":[[0,2.62,4],[1,2.6,27.71],[2,1.25,100]],"ltp":2.64,"tv":149.98,"id":26354927},{"trd":[[1.61,1975.1]],"batb":[[0,1.59,378.68],[1,1.58,98.29],[2,1.57,276.92]],"ltp":1.61,"tv":12821.76,"id":26354926}],"tv":12971.75}]}
{"op":"mcm","clk":"11873459197","pt":1723579493496,"mc":[{"id":"1.231659753","rc":[{"batb":[[0,1.6,17.27],[1,1.59,378.68],[2,1.58,76.29]],"ltp":1.61,"tv":12821.76,"id":26354926}]}]}
{"op":"mcm","clk":"11873459779","pt":1723579497691,"mc":[{"id":"1.231659753","rc":[{"batb":[[1,2.6,4]],"ltp":2.64,"tv":149.98,"id":26354927},{"batb":[[2,1.58,10.88]],"ltp":1.61,"tv":12821.76,"id":26354926}]}]}
{"op":"mcm","clk":"11873459820","pt":1723579498109,"mc":[{"id":"1.231659753","rc":[{"batb":[[1,1.59,20]],"ltp":1.61,"tv":12821.76,"id":26354926}]}]}
{"op":"mcm","clk":"11873465179","pt":1723579543134,"mc":[{"id":"1.231659753","rc":[{"batb":[[0,1.6,18.27]],"ltp":1.61,"tv":12821.76,"id":26354926}]}]}
{"op":"mcm","clk":"11873487474","pt":1723579722129,"mc":[{"id":"1.231659753","rc":[{"trd":[[1.62,9691.92]],"batl":[[0,1.62,620.28]],"ltp":1.62,"tv":12875.86,"id":26354926}],"tv":13025.85}]}
{"op":"mcm","clk":"11873488122","pt":1723579727326,"mc":[{"id":"1.231659753","rc":[{"batb":[[0,1.6,17.27]],"ltp":1.62,"tv":12875.86,"id":26354926}]}]}
{"op":"mcm","clk":"11873504988","pt":1723579853290,"mc":[{"id":"1.231659753","rc":[{"batl":[[0,1.62,300.28]],"ltp":1.62,"tv":12875.86,"id":26354926}]}]}
{"op":"mcm","clk":"11873509003","pt":1723579883836,"mc":[{"id":"1.231659753","rc":[{"batb":[[0,2.6,4],[1,1.25,100],[2,1.08,9999.98]],"ltp":2.64,"tv":149.98,"id":26354927},{"batb":[[0,1.61,812],[1,1.6,17.27]],"ltp":1.62,"tv":12875.86,"id":26354926}]}]}
{"op":"mcm","clk":"11873509131","pt":1723579884825,"mc":[{"id":"1.231659753","rc":[{"batb":[[0,2.6,27.71]],"ltp":2.64,"tv":149.98,"id":26354927},{"batb":[[0,1.61,817.17],[1,1.59,26],[2,1.58,76.29]],"ltp":1.62,"tv":12875.86,"id":26354926}]}]}
{"op":"mcm","clk":"11873509216","pt":1723579885452,"mc":[{"id":"1.231659753","rc":[{"batb":[[0,2.62,4],[1,2.6,27.71],[2,1.25,100]],"batl":[[0,2.64,4]],"ltp":2.64,"tv":149.98,"id":26354927},{"batb":[[0,1.61,821.17]],"ltp":1.62,"tv":12875.86,"id":26354926}]}]}
{"op":"mcm","clk":"11873509496","pt":1723579887759,"mc":[{"id":"1.231659753","rc":[{"batb":[[0,2.6,27.71],[1,1.25,100],[2,1.08,9999.98]],"ltp":2.64,"tv":149.98,"id":26354927}]}]}
{"op":"mcm","clk":"11873510100","pt":1723579892437,"mc":[{"id":"1.231659753","rc":[{"batb":[[0,2.62,4],[1,2.6,27.71],[2,1.25,100]],"ltp":2.64,"tv":149.98,"id":26354927}]}]}
{"op":"mcm","clk":"11873510400","pt":1723579894743,"mc":[{"id":"1.231659753","rc":[{"batb":[[1,2.6,4]],"ltp":2.64,"tv":149.98,"id":26354927},{"batb":[[1,1.59,10],[2,1.58,10.88]],"ltp":1.62,"tv":12875.86,"id":26354926}]}]}
{"op":"mcm","clk":"11873510445","pt":1723579895060,"mc":[{"id":"1.231659753","rc":[{"batb":[[0,2.6,4],[1,1.25,100],[2,1.08,9999.98]],"ltp":2.64,"tv":149.98,"id":26354927}]}]}
{"op":"mcm","clk":"11873510963","pt":1723579898755,"mc":[{"id":"1.231659753","rc":[{"batb":[[0,2.62,4],[1,2.6,4],[2,1.25,100]],"ltp":2.64,"tv":149.98,"id":26354927}]}]}
{"op":"mcm","clk":"11873511331","pt":1723579901345,"mc":[{"id":"1.231659753","rc":[{"batb":[[0,2.6,4],[1,1.25,100],[2,1.08,9999.98]],"ltp":2.64,"tv":149.98,"id":26354927}]}]}
{"op":"mcm","clk":"11873511835","pt":1723579904450,"mc":[{"id":"1.231659753","rc":[{"batb":[[0,2.62,4]],"ltp":2.64,"tv":149.98,"id":26354927},{"batb":[[1,1.59,826],[2,1.58,30.88]],"batl":[[0,1.62,296.28]],"ltp":1.62,"tv":12875.86,"id":26354926}]}]}
{"op":"mcm","clk":"11873512195","pt":1723579906756,"mc":[{"id":"1.231659753","rc":[{"batb":[[0,1.26,10]],"ltp":2.64,"tv":149.98,"id":26354927}]}]}
{"op":"mcm","clk":"11873512630","pt":1723579909766,"mc":[{"id":"1.231659753","rc":[{"batb":[[0,2.6,23.71],[1,1.27,4],[2,1.26,10]],"ltp":2.64,"tv":149.98,"id":26354927},{"trd":[[1.62,9755.92]],"batb":[[2,1.58,96.29]],"batl":[[0,1.62,264.28]],"ltp":1.62,"tv":12939.86,"id":26354926}],"tv":13089.85}]}
{"op":"mcm","clk":"11873512677","pt":1723579910080,"mc":[{"id":"1.231659753","rc":[{"batb":[[2,1.25,100]],"ltp":2.64,"tv":149.98,"id":26354927}]}]}
{"op":"mcm","clk":"11873512908","pt":1723579911650,"mc":[{"id":"1.231659753","rc":[{"batb":[[1,1.25,100],[2,1.08,9999.98]],"ltp":2.64,"tv":149.98,"id":26354927}]}]}
{"op":"mcm","clk":"11873513631","pt":1723579917253,"mc":[{"id":"1.231659753","rc":[{"batb":[[0,2.62,4],[1,2.6,23.71],[2,1.25,100]],"ltp":2.64,"tv":149.98,"id":26354927}]}]}
{"op":"mcm","clk":"11873513991","pt":1723579920054,"mc":[{"id":"1.231659753","rc":[{"batb":[[0,2.6,23.71],[1,1.25,100],[2,1.08,9999.98]],"ltp":2.64,"tv":149.98,"id":26354927}]}]}
{"op":"mcm","clk":"11873514422","pt":1723579923576,"mc":[{"id":"1.231659753","rc":[{"batb":[[0,2.62,4],[1,2.6,23.71],[2,1.25,100]],"ltp":2.64,"tv":149.98,"id":26354927}]}]}
{"op":"mcm","clk":"11873514785","pt":1723579926376,"mc":[{"id":"1.231659753","rc":[{"batb":[[0,2.6,23.71],[1,1.25,100],[2,1.08,9999.98]],"ltp":2.64,"tv":149.98,"id":26354927}]}]}
{"op":"mcm","clk":"11873515236","pt":1723579929675,"mc":[{"id":"1.231659753","rc":[{"batb":[[0,2.62,4],[1,2.6,23.71],[2,1.25,100]],"ltp":2.64,"tv":149.98,"id":26354927}]}]}
{"op":"mcm","clk":"11873515604","pt":1723579932194,"mc":[{"id":"1.231659753","rc":[{"batb":[[0,2.6,23.71],[1,1.25,100],[2,1.08,9999.98]],"ltp":2.64,"tv":149.98,"id":26354927}]}]}
{"op":"mcm","clk":"11873515956","pt":1723579934874,"mc":[{"id":"1.231659753","rc":[{"batb":[[0,2.62,4],[1,2.6,23.71],[2,1.25,100]],"ltp":2.64,"tv":149.98,"id":26354927}]}]}
{"op":"mcm","clk":"11873516284","pt":1723579937279,"mc":[{"id":"1.231659753","rc":[{"batb":[[0,2.6,23.71],[1,1.25,100],[2,1.08,9999.98]],"ltp":2.64,"tv":149.98,"id":26354927}]}]}
{"op":"mcm","clk":"11873516980","pt":1723579942469,"mc":[{"id":"1.231659753","rc":[{"batb":[[0,2.62,4],[1,2.6,23.71],[2,1.25,100]],"ltp":2.64,"tv":149.98,"id":26354927}]}]}
{"op":"mcm","clk":"11873517309","pt":1723579945084,"mc":[{"id":"1.231659753","rc":[{"batb":[[0,2.6,23.71],[1,1.25,100],[2,1.08,9999.98]],"ltp":2.64,"tv":149.98,"id":26354927}]}]}
{"op":"mcm","clk":"11873517536","pt":1723579946796,"mc":[{"id":"1.231659753","rc":[{"batl":[[0,1.62,221.61]],"ltp":1.62,"tv":12939.86,"id":26354926}]}]}
{"op":"mcm","clk":"11873517920","pt":1723579949792,"mc":[{"id":"1.231659753","rc":[{"batb":[[0,2.62,4],[1,2.6,23.71],[2,1.25,100]],"ltp":2.64,"tv":149.98,"id":26354927}]}]}
{"op":"mcm","clk":"11873518310","pt":1723579952502,"mc":[{"id":"1.231659753","rc":[{"batb":[[0,2.6,23.71],[1,1.25,100],[2,1.08,9999.98]],"ltp":2.64,"tv":149.98,"id":26354927}]}]}
{"op":"mcm","clk":"11873518841","pt":1723579956594,"mc":[{"id":"1.231659753","rc":[{"batb":[[0,2.62,4],[1,2.6,23.71],[2,1.25,100]],"ltp":2.64,"tv":149.98,"id":26354927}]}]}
{"op":"mcm","clk":"11873519302","pt":1723579959819,"mc":[{"id":"1.231659753","rc":[{"batb":[[0,2.6,23.71],[1,1.25,100],[2,1.08,9999.98]],"ltp":2.64,"tv":149.98,"id":26354927}]}]}
{"op":"mcm","clk":"11873519773","pt":1723579963121,"mc":[{"id":"1.231659753","rc":[{"batb":[[0,2.62,4],[1,2.6,23.71],[2,1.25,100]],"ltp":2.64,"tv":149.98,"id":26354927}]}]}
{"op":"mcm","clk":"11873520138","pt":1723579965691,"mc":[{"id":"1.231659753","rc":[{"batb":[[0,2.6,23.71],[1,1.25,100],[2,1.08,9999.98]],"ltp":2.64,"tv":149.98,"id":26354927}]}]}
{"op":"mcm","clk":"11873520821","pt":1723579970711,"mc":[{"id":"1.231659753","rc":[{"batb":[[0,2.62,4],[1,2.6,23.71],[2,1.25,100]],"ltp":2.64,"tv":149.98,"id":26354927},{"batl":[[0,1.62,200.28]],"ltp":1.62,"tv":12939.86,"id":26354926}]}]}
{"op":"mcm","clk":"11873521218","pt":1723579973238,"mc":[{"id":"1.231659753","rc":[{"batb":[[0,2.6,23.71],[1,1.25,100],[2,1.08,9999.98]],"ltp":2.64,"tv":149.98,"id":26354927}]}]}
{"op":"mcm","clk":"11873530459","pt":1723579975525,"mc":[{"id":"1.231659753","rc":[{"batb":[[0,2.62,4],[1,2.6,23.71],[2,1.25,100]],"ltp":2.64,"tv":149.98,"id":26354927}]}]}
{"op":"mcm","clk":"11873530788","pt":1723579977922,"mc":[{"id":"1.231659753","rc":[{"batb":[[0,2.6,23.71],[1,1.25,100],[2,1.08,9999.98]],"ltp":2.64,"tv":149.98,"id":26354927}]}]}
{"op":"mcm","clk":"11873531094","pt":1723579980117,"mc":[{"id":"1.231659753","rc":[{"batb":[[0,2.62,4],[1,2.6,23.71],[2,1.25,100]],"ltp":2.64,"tv":149.98,"id":26354927}]}]}
{"op":"mcm","clk":"11873531464","pt":1723579982736,"mc":[{"id":"1.231659753","rc":[{"batb":[[0,2.6,23.71],[1,1.25,100],[2,1.08,9999.98]],"ltp":2.64,"tv":149.98,"id":26354927}]}]}
{"op":"mcm","clk":"11873532043","pt":1723579986818,"mc":[{"id":"1.231659753","rc":[{"batb":[[0,2.62,4],[1,2.6,23.71],[2,1.25,100]],"ltp":2.64,"tv":149.98,"id":26354927}]}]}
{"op":"mcm","clk":"11873532407","pt":1723579989494,"mc":[{"id":"1.231659753","rc":[{"batb":[[0,2.6,23.71],[1,1.25,100],[2,1.08,9999.98]],"ltp":2.64,"tv":149.98,"id":26354927}]}]}
{"op":"mcm","clk":"11873532880","pt":1723579993125,"mc":[{"id":"1.231659753","rc":[{"batb":[[0,2.62,4],[1,2.6,23.71],[2,1.25,100]],"ltp":2.64,"tv":149.98,"id":26354927}]}]}
{"op":"mcm","clk":"11873533223","pt":1723579995633,"mc":[{"id":"1.231659753","rc":[{"batb":[[0,2.6,23.71],[1,1.25,100],[2,1.08,9999.98]],"ltp":2.64,"tv":149.98,"id":26354927}]}]}
{"op":"mcm","clk":"11873533704","pt":1723579998734,"mc":[{"id":"1.231659753","rc":[{"batb":[[0,2.62,4],[1,2.6,23.71],[2,1.25,100]],"ltp":2.64,"tv":149.98,"id":26354927},{"batb":[[2,1.58,76.29]],"batl":[[0,1.62,40.28]],"ltp":1.62,"tv":12939.86,"id":26354926}]}]}
{"op":"mcm","clk":"11873533872","pt":1723579999736,"mc":[{"id":"1.231659753","rc":[{"batl":[[0,1.62,18.95]],"ltp":1.62,"tv":12939.86,"id":26354926}]}]}
{"op":"mcm","clk":"11873534118","pt":1723580001214,"mc":[{"id":"1.231659753","rc":[{"batb":[[0,2.6,23.71],[1,1.25,100],[2,1.08,9999.98]],"ltp":2.64,"tv":149.98,"id":26354927}]}]}
{"op":"mcm","clk":"11873534541","pt":1723580004360,"mc":[{"id":"1.231659753","rc":[{"batb":[[0,2.62,4],[1,2.6,23.71],[2,1.25,100]],"ltp":2.64,"tv":149.98,"id":26354927}]}]}
{"op":"mcm","clk":"11873534893","pt":1723580006636,"mc":[{"id":"1.231659753","rc":[{"batb":[[0,2.6,23.71],[1,1.25,100],[2,1.08,9999.98]],"ltp":2.64,"tv":149.98,"id":26354927}]}]}
{"op":"mcm","clk":"11873535652","pt":1723580011772,"mc":[{"id":"1.231659753","rc":[{"batb":[[0,2.62,4],[1,2.6,23.71],[2,1.25,100]],"ltp":2.64,"tv":149.98,"id":26354927}]}]}
{"op":"mcm","clk":"11873535780","pt":1723580012592,"mc":[{"id":"1.231659753","rc":[{"trd":[[2.62,1.47]],"batb":[[0,2.62,2.53]],"ltp":2.62,"tv":151.45,"id":26354927},{"trd":[[1.62,9758.3]],"batl":[[0,1.67,21.06],[1,1.68,10],[2,1.73,900]],"ltp":1.62,"tv":12942.24,"id":26354926}],"tv":13093.7}]}
{"op":"mcm","clk":"11873536119","pt":1723580014892,"mc":[{"id":"1.231659753","rc":[{"batb":[[0,2.6,23.71],[1,1.25,100],[2,1.08,9999.98]],"ltp":2.62,"tv":151.45,"id":26354927},{"batb":[[0,1.62,19],[1,1.61,821.17],[2,1.59,800]],"ltp":1.62,"tv":12942.24,"id":26354926}]}]}
{"op":"mcm","clk":"11873536336","pt":1723580016217,"mc":[{"id":"1.231659753","rc":[{"batb":[[0,1.62,36.06],[1,1.61,804]],"ltp":1.62,"tv":12942.24,"id":26354926}]}]}
{"op":"mcm","clk":"11873571463","pt":1723580252684,"mc":[{"id":"1.231659753","rc":[{"trd":[[2.6,66.48]],"batb":[[0,1.25,100],[1,1.08,9999.98],[2,1.07,11428.56]],"batl":[[0,2.6,1.29],[1,2.64,4]],"ltp":2.6,"tv":198.87,"id":26354927}],"tv":13141.12}]}
{"op":"mcm","clk":"11873571529","pt":1723580253110,"mc":[{"id":"1.231659753","rc":[{"batb":[[0,1.26,14],[1,1.25,100],[2,1.08,9999.98]],"ltp":2.6,"tv":198.87,"id":26354927}]}]}
{"op":"mcm","clk":"11873571967","pt":1723580255822,"mc":[{"id":"1.231659753","rc":[{"batb":[[0,2.5,25.29],[1,1.26,10],[2,1.25,100]],"ltp":2.6,"tv":198.87,"id":26354927},{"batb":[[0,1.62,97.25],[1,1.61,806]],"ltp":1.62,"tv":12942.24,"id":26354926}]}]}
{"op":"mcm","clk":"11873572096","pt":1723580256817,"mc":[{"id":"1.231659753","rc":[{"batb":[[1,1.25,100],[2,1.08,9999.98]],"batl":[[0,2.64,4],[1,2.64,0]],"ltp":2.6,"tv":198.87,"id":26354927}]}]}
{"op":"mcm","clk":"11873572289","pt":1723580258224,"mc":[{"id":"1.231659753","rc":[{"batb":[[0,2.52,4],[1,2.5,25.29],[2,1.25,100]],"ltp":2.6,"tv":198.87,"id":26354927},{"batb":[[1,1.61,804]],"ltp":1.62,"tv":12942.24,"id":26354926}]}]}
{"op":"mcm","clk":"11873572614","pt":1723580260836,"mc":[{"id":"1.231659753","rc":[{"batb":[[0,2.5,25.29],[1,1.25,100],[2,1.08,9999.98]],"ltp":2.6,"tv":198.87,"id":26354927}]}]}
{"op":"mcm","clk":"11873572713","pt":1723580261524,"mc":[{"id":"1.231659753","rc":[{"batb":[[0,2.52,10],[1,2.5,25.29],[2,1.25,100]],"ltp":2.6,"tv":198.87,"id":26354927},{"batl":[[0,1.65,19.2],[1,1.67,21.06],[2,1.68,10]],"ltp":1.62,"tv":12942.24,"id":26354926}]}]}
{"op":"mcm","clk":"11873573039","pt":1723580263610,"mc":[{"id":"1.231659753","rc":[{"batl":[[0,2.62,4],[1,2.64,4]],"ltp":2.6,"tv":198.87,"id":26354927},{"batb":[[0,1.63,4],[1,1.62,101.25],[2,1.61,804]],"ltp":1.62,"tv":12942.24,"id":26354926}]}]}
{"op":"mcm","clk":"11873573148","pt":1723580264507,"mc":[{"id":"1.231659753","rc":[{"batb":[[0,2.54,4]],"batl":[[2,2.66,1.25]],"ltp":2.6,"tv":198.87,"id":26354927}]}]}
{"op":"mcm","clk":"11873573356","pt":1723580266303,"mc":[{"id":"1.231659753","rc":[{"batb":[[0,2.5,25.29],[1,1.25,100],[2,1.08,9999.98]],"ltp":2.6,"tv":198.87,"id":26354927}]}]}
{"op":"mcm","clk":"11873573449","pt":1723580267027,"mc":[{"id":"1.231659753","rc":[{"batb":[[0,2.52,10],[1,2.5,25.29],[2,1.25,100]],"ltp":2.6,"tv":198.87,"id":26354927}]}]}
{"op":"mcm","clk":"11873573757","pt":1723580269727,"mc":[{"id":"1.231659753","rc":[{"batb":[[0,2.54,4],[1,2.52,10],[2,2.5,25.29]],"batl":[[0,2.62,32.43]],"ltp":2.6,"tv":198.87,"id":26354927}]}]}
{"op":"mcm","clk":"11873573842","pt":1723580270610,"mc":[{"id":"1.231659753","rc":[{"batb":[[1,2.5,25.29],[2,1.25,100]],"ltp":2.6,"tv":198.87,"id":26354927}]}]}
{"op":"mcm","clk":"11873574058","pt":1723580272225,"mc":[{"id":"1.231659753","rc":[{"batb":[[0,2.52,30.44],[1,2.5,51.3]],"ltp":2.6,"tv":198.87,"id":26354927}]}]}
{"op":"mcm","clk":"11873574374","pt":1723580274743,"mc":[{"id":"1.231659753","rc":[{"batb":[[0,2.54,14],[1,2.52,30.44],[2,2.5,51.3]],"ltp":2.6,"tv":198.87,"id":26354927}]}]}
{"op":"mcm","clk":"11873574679","pt":1723580277145,"mc":[{"id":"1.231659753","rc":[{"batb":[[0,2.54,10]],"ltp":2.6,"tv":198.87,"id":26354927}]}]}
{"op":"mcm","clk":"11873574896","pt":1723580278815,"mc":[{"id":"1.231659753","rc":[{"batb":[[0,2.52,30.44],[1,2.5,51.3],[2,1.25,100]],"batl":[[0,2.6,4],[1,2.62,32.43],[2,2.64,4]],"ltp":2.6,"tv":198.87,"id":26354927}]}]}
{"op":"mcm","clk":"11873575246","pt":1723580281426,"mc":[{"id":"1.231659753","rc":[{"batb":[[0,2.54,4],[1,2.52,30.44],[2,2.5,51.3]],"ltp":2.6,"tv":198.87,"id":26354927}]}]}
{"op":"mcm","clk":"11873575563","pt":1723580283826,"mc":[{"id":"1.231659753","rc":[{"batb":[[0,2.52,30.44],[1,2.5,51.3],[2,1.25,100]],"ltp":2.6,"tv":198.87,"id":26354927}]}]}
{"op":"mcm","clk":"11873575864","pt":1723580286267,"mc":[{"id":"1.231659753","rc":[{"batb":[[0,2.54,4],[1,2.52,30.44],[2,2.5,51.3]],"ltp":2.6,"tv":198.87,"id":26354927}]}]}
{"op":"mcm","clk":"11873576212","pt":1723580289033,"mc":[{"id":"1.231659753","rc":[{"batb":[[0,2.52,30.44],[1,2.5,51.3],[2,1.25,100]],"ltp":2.6,"tv":198.87,"id":26354927}]}]}
{"op":"mcm","clk":"11873576505","pt":1723580291233,"mc":[{"id":"1.231659753","rc":[{"batb":[[0,2.54,4],[1,2.52,30.44],[2,2.5,51.3]],"ltp":2.6,"tv":198.87,"id":26354927}]}]}
{"op":"mcm","clk":"11873576804","pt":1723580293630,"mc":[{"id":"1.231659753","rc":[{"batb":[[0,2.52,30.44],[1,2.5,51.3],[2,1.25,100]],"ltp":2.6,"tv":198.87,"id":26354927}]}]}
{"op":"mcm","clk":"11873577169","pt":1723580296139,"mc":[{"id":"1.231659753","rc":[{"batb":[[0,2.54,4],[1,2.52,30.44],[2,2.5,51.3]],"ltp":2.6,"tv":198.87,"id":26354927}]}]}
{"op":"mcm","clk":"11873577370","pt":1723580297644,"mc":[{"id":"1.231659753","rc":[{"batb":[[0,1.63,12.38]],"ltp":1.62,"tv":12942.24,"id":26354926}]}]}
{"op":"mcm","clk":"11873577509","pt":1723580298628,"mc":[{"id":"1.231659753","rc":[{"batb":[[0,2.52,30.44],[1,2.5,51.3],[2,1.25,100]],"ltp":2.6,"tv":198.87,"id":26354927}]}]}
{"op":"mcm","clk":"11873577796","pt":1723580301184,"mc":[{"id":"1.231659753","rc":[{"batb":[[0,2.54,4],[1,2.52,30.44],[2,2.5,51.3]],"ltp":2.6,"tv":198.87,"id":26354927}]}]}
{"op":"mcm","clk":"11873578171","pt":1723580303942,"mc":[{"id":"1.231659753","rc":[{"batb":[[0,2.52,30.44],[1,2.5,51.3],[2,1.25,100]],"ltp":2.6,"tv":198.87,"id":26354927}]}]}
{"op":"mcm","clk":"11873578518","pt":1723580306772,"mc":[{"id":"1.231659753","rc":[{"batb":[[0,2.54,4],[1,2.52,30.44],[2,2.5,51.3]],"ltp":2.6,"tv":198.87,"id":26354927}]}]}
{"op":"mcm","clk":"11873578852","pt":1723580309480,"mc":[{"id":"1.231659753","rc":[{"batb":[[0,2.52,30.44],[1,2.5,51.3],[2,1.25,100]],"ltp":2.6,"tv":198.87,"id":26354927}]}]}
{"op":"mcm","clk":"11873579161","pt":1723580311895,"mc":[{"id":"1.231659753","rc":[{"batb":[[0,2.54,4],[1,2.52,30.44],[2,2.5,51.3]],"ltp":2.6,"tv":198.87,"id":26354927},{"batl":[[0,1.64,1],[1,1.65,19.2],[2,1.67,21.06]],"ltp":1.62,"tv":12942.24,"id":26354926}]}]}
{"op":"mcm","clk":"11873579522","pt":1723580314459,"mc":[{"id":"1.231659753","rc":[{"batb":[[0,2.52,30.44],[1,2.5,51.3],[2,1.25,100]],"ltp":2.6,"tv":198.87,"id":26354927}]}]}
{"op":"mcm","clk":"11873579889","pt":1723580317589,"mc":[{"id":"1.231659753","rc":[{"batb":[[0,2.54,4],[1,2.52,30.44],[2,2.5,51.3]],"ltp":2.6,"tv":198.87,"id":26354927}]}]}
{"op":"mcm","clk":"11873580253","pt":1723580320395,"mc":[{"id":"1.231659753","rc":[{"batb":[[0,2.52,30.44],[1,2.5,51.3],[2,1.25,100]],"ltp":2.6,"tv":198.87,"id":26354927}]}]}
{"op":"mcm","clk":"11873580714","pt":1723580323793,"mc":[{"id":"1.231659753","rc":[{"batb":[[0,2.54,4],[1,2.52,30.44],[2,2.5,51.3]],"ltp":2.6,"tv":198.87,"id":26354927}]}]}
{"op":"mcm","clk":"11873581141","pt":1723580326882,"mc":[{"id":"1.231659753","rc":[{"batb":[[0,2.52,30.44],[1,2.5,51.3],[2,1.25,100]],"ltp":2.6,"tv":198.87,"id":26354927}]}]}
{"op":"mcm","clk":"11873581437","pt":1723580329062,"mc":[{"id":"1.231659753","rc":[{"batb":[[0,2.54,4],[1,2.52,30.44],[2,2.5,51.3]],"ltp":2.6,"tv":198.87,"id":26354927}]}]}
{"op":"mcm","clk":"11873581749","pt":1723580331572,"mc":[{"id":"1.231659753","rc":[{"batb":[[0,2.52,30.44],[1,2.5,51.3],[2,1.25,100]],"ltp":2.6,"tv":198.87,"id":26354927}]}]}
{"op":"mcm","clk":"11873582044","pt":1723580333802,"mc":[{"id":"1.231659753","rc":[{"batb":[[0,2.54,4],[1,2.52,30.44],[2,2.5,51.3]],"ltp":2.6,"tv":198.87,"id":26354927}]}]}
{"op":"mcm","clk":"11873582357","pt":1723580336312,"mc":[{"id":"1.231659753","rc":[{"batb":[[0,2.52,30.44],[1,2.5,51.3],[2,1.25,100]],"ltp":2.6,"tv":198.87,"id":26354927}]}]}
{"op":"mcm","clk":"11873582701","pt":1723580338914,"mc":[{"id":"1.231659753","rc":[{"batb":[[0,2.54,4],[1,2.52,30.44],[2,2.5,51.3]],"ltp":2.6,"tv":198.87,"id":26354927}]}]}
{"op":"mcm","clk":"11873583013","pt":1723580341204,"mc":[{"id":"1.231659753","rc":[{"batb":[[0,2.52,30.44],[1,2.5,51.3],[2,1.25,100]],"ltp":2.6,"tv":198.87,"id":26354927}]}]}
{"op":"mcm","clk":"11873583659","pt":1723580346211,"mc":[{"id":"1.231659753","rc":[{"batb":[[0,2.54,4],[1,2.52,30.44],[2,2.5,51.3]],"ltp":2.6,"tv":198.87,"id":26354927}]}]}
{"op":"mcm","clk":"11873584021","pt":1723580348837,"mc":[{"id":"1.231659753","rc":[{"batb":[[0,2.52,30.44],[1,2.5,51.3],[2,1.25,100]],"ltp":2.6,"tv":198.87,"id":26354927}]}]}
{"op":"mcm","clk":"11873584381","pt":1723580351603,"mc":[{"id":"1.231659753","rc":[{"batb":[[0,2.54,4],[1,2.52,30.44],[2,2.5,51.3]],"ltp":2.6,"tv":198.87,"id":26354927}]}]}
{"op":"mcm","clk":"11873584720","pt":1723580354334,"mc":[{"id":"1.231659753","rc":[{"batb":[[0,2.52,30.44],[1,2.5,51.3],[2,1.25,100]],"ltp":2.6,"tv":198.87,"id":26354927}]}]}
{"op":"mcm","clk":"11873585162","pt":1723580357528,"mc":[{"id":"1.231659753","rc":[{"batb":[[0,2.54,4],[1,2.52,30.44],[2,2.5,51.3]],"ltp":2.6,"tv":198.87,"id":26354927}]}]}
{"op":"mcm","clk":"11873585446","pt":1723580359821,"mc":[{"id":"1.231659753","rc":[{"batb":[[0,2.52,30.44],[1,2.5,51.3],[2,1.25,100]],"ltp":2.6,"tv":198.87,"id":26354927}]}]}
{"op":"mcm","clk":"11873585924","pt":1723580363812,"mc":[{"id":"1.231659753","rc":[{"batb":[[0,2.54,4],[1,2.52,30.44],[2,2.5,51.3]],"ltp":2.6,"tv":198.87,"id":26354927}]}]}
{"op":"mcm","clk":"11873586225","pt":1723580366314,"mc":[{"id":"1.231659753","rc":[{"batb":[[0,2.52,30.44],[1,2.5,51.3],[2,1.25,100]],"ltp":2.6,"tv":198.87,"id":26354927}]}]}
{"op":"mcm","clk":"11873586593","pt":1723580369239,"mc":[{"id":"1.231659753","rc":[{"batb":[[0,2.54,4],[1,2.52,30.44],[2,2.5,51.3]],"ltp":2.6,"tv":198.87,"id":26354927}]}]}
{"op":"mcm","clk":"11873586872","pt":1723580371636,"mc":[{"id":"1.231659753","rc":[{"batb":[[0,2.52,30.44],[1,2.5,51.3],[2,1.25,100]],"ltp":2.6,"tv":198.87,"id":26354927}]}]}
{"op":"mcm","clk":"11873587510","pt":1723580376331,"mc":[{"id":"1.231659753","rc":[{"batb":[[0,2.54,4],[1,2.52,30.44],[2,2.5,51.3]],"ltp":2.6,"tv":198.87,"id":26354927}]}]}
{"op":"mcm","clk":"11873587875","pt":1723580379242,"mc":[{"id":"1.231659753","rc":[{"batb":[[0,2.52,30.44],[1,2.5,51.3],[2,1.25,100]],"ltp":2.6,"tv":198.87,"id":26354927}]}]}
{"op":"mcm","clk":"11873588256","pt":1723580382228,"mc":[{"id":"1.231659753","rc":[{"batb":[[0,2.54,4],[1,2.52,30.44],[2,2.5,51.3]],"ltp":2.6,"tv":198.87,"id":26354927}]}]}
{"op":"mcm","clk":"11873588613","pt":1723580385041,"mc":[{"id":"1.231659753","rc":[{"batb":[[0,2.52,30.44],[1,2.5,51.3],[2,1.25,100]],"ltp":2.6,"tv":198.87,"id":26354927}]}]}
{"op":"mcm","clk":"11873589252","pt":1723580389433,"mc":[{"id":"1.231659753","rc":[{"batb":[[0,2.54,4],[1,2.52,30.44],[2,2.5,51.3]],"ltp":2.6,"tv":198.87,"id":26354927}]}]}
{"op":"mcm","clk":"11873589658","pt":1723580392761,"mc":[{"id":"1.231659753","rc":[{"batb":[[0,2.52,30.44],[1,2.5,51.3],[2,1.25,100]],"ltp":2.6,"tv":198.87,"id":26354927}]}]}
{"op":"mcm","clk":"11873589996","pt":1723580395574,"mc":[{"id":"1.231659753","rc":[{"batb":[[0,2.54,4],[1,2.52,30.44],[2,2.5,51.3]],"ltp":2.6,"tv":198.87,"id":26354927}]}]}
{"op":"mcm","clk":"11873590295","pt":1723580398178,"mc":[{"id":"1.231659753","rc":[{"batb":[[0,2.52,30.44],[1,2.5,51.3],[2,1.25,100]],"ltp":2.6,"tv":198.87,"id":26354927}]}]}
{"op":"mcm","clk":"11873590709","pt":1723580400964,"mc":[{"id":"1.231659753","rc":[{"batb":[[0,2.54,4],[1,2.52,30.44],[2,2.5,51.3]],"ltp":2.6,"tv":198.87,"id":26354927}]}]}
{"op":"mcm","clk":"11873591068","pt":1723580403855,"mc":[{"id":"1.231659753","rc":[{"batb":[[0,2.52,30.44],[1,2.5,51.3],[2,1.25,100]],"ltp":2.6,"tv":198.87,"id":26354927}]}]}
{"op":"mcm","clk":"11873591585","pt":1723580408176,"mc":[{"id":"1.231659753","rc":[{"batb":[[0,2.54,4],[1,2.52,30.44],[2,2.5,51.3]],"ltp":2.6,"tv":198.87,"id":26354927}]}]}
{"op":"mcm","clk":"11873591888","pt":1723580410687,"mc":[{"id":"1.231659753","rc":[{"batb":[[0,2.52,30.44],[1,2.5,51.3],[2,1.25,100]],"ltp":2.6,"tv":198.87,"id":26354927}]}]}
{"op":"mcm","clk":"11873592337","pt":1723580414458,"mc":[{"id":"1.231659753","rc":[{"batb":[[0,2.54,4],[1,2.52,30.44],[2,2.5,51.3]],"ltp":2.6,"tv":198.87,"id":26354927}]}]}
{"op":"mcm","clk":"11873592674","pt":1723580417393,"mc":[{"id":"1.231659753","rc":[{"batb":[[0,2.52,30.44],[1,2.5,51.3],[2,1.25,100]],"ltp":2.6,"tv":198.87,"id":26354927}]}]}
{"op":"mcm","clk":"11873593014","pt":1723580420364,"mc":[{"id":"1.231659753","rc":[{"batb":[[0,2.54,4],[1,2.52,30.44],[2,2.5,51.3]],"ltp":2.6,"tv":198.87,"id":26354927}]}]}
{"op":"mcm","clk":"11873593362","pt":1723580423389,"mc":[{"id":"1.231659753","rc":[{"batb":[[0,2.52,30.44],[1,2.5,51.3],[2,1.25,100]],"ltp":2.6,"tv":198.87,"id":26354927}]}]}
{"op":"mcm","clk":"11873593854","pt":1723580427290,"mc":[{"id":"1.231659753","rc":[{"batb":[[0,2.54,4],[1,2.52,30.44],[2,2.5,51.3]],"ltp":2.6,"tv":198.87,"id":26354927}]}]}
{"op":"mcm","clk":"11873594173","pt":1723580430003,"mc":[{"id":"1.231659753","rc":[{"batb":[[0,2.52,30.44],[1,2.5,51.3],[2,1.25,100]],"ltp":2.6,"tv":198.87,"id":26354927}]}]}
{"op":"mcm","clk":"11873594714","pt":1723580434288,"mc":[{"id":"1.231659753","rc":[{"batb":[[0,2.54,4],[1,2.52,30.44],[2,2.5,51.3]],"ltp":2.6,"tv":198.87,"id":26354927}]}]}
{"op":"mcm","clk":"11873595087","pt":1723580437202,"mc":[{"id":"1.231659753","rc":[{"batb":[[0,2.52,30.44],[1,2.5,51.3],[2,1.25,100]],"ltp":2.6,"tv":198.87,"id":26354927}]}]}
{"op":"mcm","clk":"11873595397","pt":1723580439908,"mc":[{"id":"1.231659753","rc":[{"batb":[[0,2.54,4],[1,2.52,30.44],[2,2.5,51.3]],"ltp":2.6,"tv":198.87,"id":26354927}]}]}
{"op":"mcm","clk":"11873595722","pt":1723580442721,"mc":[{"id":"1.231659753","rc":[{"batb":[[0,2.52,30.44],[1,2.5,51.3],[2,1.25,100]],"ltp":2.6,"tv":198.87,"id":26354927}]}]}
{"op":"mcm","clk":"11873596160","pt":1723580446436,"mc":[{"id":"1.231659753","rc":[{"batb":[[0,2.54,4],[1,2.52,30.44],[2,2.5,51.3]],"ltp":2.6,"tv":198.87,"id":26354927}]}]}
{"op":"mcm","clk":"11873596522","pt":1723580449201,"mc":[{"id":"1.231659753","rc":[{"batb":[[0,2.52,30.44],[1,2.5,51.3],[2,1.25,100]],"ltp":2.6,"tv":198.87,"id":26354927}]}]}
{"op":"mcm","clk":"11873597157","pt":1723580453904,"mc":[{"id":"1.231659753","rc":[{"trd":[[1.64,3.55]],"batb":[[0,1.64,26.05],[1,1.63,12.38],[2,1.62,101.25]],"batl":[[0,1.65,19.2],[1,1.67,21.06],[2,1.68,10]],"ltp":1.64,"tv":12944.24,"id":26354926}],"tv":13143.12}]}
{"op":"mcm","clk":"11873597237","pt":1723580454634,"mc":[{"id":"1.231659753","rc":[{"batb":[[0,2.54,4],[1,2.52,30.44],[2,2.5,51.3]],"ltp":2.6,"tv":198.87,"id":26354927},{"batb":[[0,1.64,62.9],[2,1.62,65.19]],"ltp":1.64,"tv":12944.24,"id":26354926}]}]}
{"op":"mcm","clk":"11873597368","pt":1723580455622,"mc":[{"id":"1.231659753","rc":[{"batb":[[0,1.64,42.9],[1,1.63,26]],"ltp":1.64,"tv":12944.24,"id":26354926}]}]}
{"op":"mcm","clk":"11873597520","pt":1723580456826,"mc":[{"id":"1.231659753","rc":[{"batb":[[0,2.52,30.44],[1,2.5,26.01],[2,1.25,100]],"ltp":2.6,"tv":198.87,"id":26354927},{"batb":[[2,1.62,4]],"ltp":1.64,"tv":12944.24,"id":26354926}]}]}
{"op":"mcm","clk":"11873597598","pt":1723580457444,"mc":[{"id":"1.231659753","rc":[{"batb":[[0,1.28,52.43],[1,1.27,10],[2,1.26,53.26]],"ltp":2.6,"tv":198.87,"id":26354927},{"batb":[[1,1.63,13]],"ltp":1.64,"tv":12944.24,"id":26354926}]}]}
{"op":"mcm","clk":"11873598027","pt":1723580460652,"mc":[{"id":"1.231659753","rc":[{"batb":[[0,2.54,4],[1,2.52,4],[2,1.29,4]],"batl":[[0,2.58,4],[1,2.6,4],[2,2.62,32.43]],"ltp":2.6,"tv":198.87,"id":26354927},{"batb":[[0,1.64,4]],"batl":[[0,1.65,23.2]],"ltp":1.64,"tv":12944.24,"id":26354926}]}]}
{"op":"mcm","clk":"11873598175","pt":1723580461852,"mc":[{"id":"1.231659753","rc":[{"batb":[[2,2.5,25.29]],"batl":[[0,2.6,4],[1,2.62,32.43],[2,2.64,4]],"ltp":2.6,"tv":198.87,"id":26354927},{"batb":[[2,1.62,65.19]],"ltp":1.64,"tv":12944.24,"id":26354926}]}]}
{"op":"mcm","clk":"11873598316","pt":1723580462819,"mc":[{"id":"1.231659753","rc":[{"batb":[[0,1.63,31.38],[1,1.62,65.19],[2,1.61,804]],"batl":[[0,1.65,19.2]],"ltp":1.64,"tv":12944.24,"id":26354926}]}]}
{"op":"mcm","clk":"11873598391","pt":1723580463543,"mc":[{"id":"1.231659753","rc":[{"batb":[[0,2.52,10],[1,2.5,51.3],[2,1.28,52.43]],"ltp":2.6,"tv":198.87,"id":26354927}]}]}
{"op":"mcm","clk":"11873598586","pt":1723580465148,"mc":[{"id":"1.231659753","rc":[{"batb":[[0,2.54,4],[1,2.52,10],[2,2.5,51.3]],"ltp":2.6,"tv":198.87,"id":26354927}]}]}
{"op":"mcm","clk":"11873598783","pt":1723580466612,"mc":[{"id":"1.231659753","rc":[{"trd":[[2.54,5]],"batb":[[0,2.52,10],[1,2.5,51.3],[2,1.28,52.43]],"batl":[[0,2.6,31.44]],"ltp":2.54,"tv":202.87,"id":26354927},{"trd":[[1.65,48.09]],"batb":[[0,1.65,1.69],[1,1.63,17.38],[2,1.62,65.19]],"batl":[[0,1.67,63.09],[1,1.68,10],[2,1.69,480]],"ltp":1.65,"tv":12988.8,"id":26354926}],"tv":13191.68}]}
{"op":"mcm","clk":"11873598834","pt":1723580467031,"mc":[{"id":"1.231659753","rc":[{"batb":[[0,2.5,51.3],[1,1.28,52.43],[2,1.26,53.26]],"ltp":2.54,"tv":202.87,"id":26354927},{"batb":[[1,1.63,34.38]],"ltp":1.65,"tv":12988.8,"id":26354926}]}]}
{"op":"mcm","clk":"11873599264","pt":1723580470318,"mc":[{"id":"1.231659753","rc":[{"batb":[[0,2.52,14],[1,2.5,51.3],[2,1.28,52.43]],"ltp":2.54,"tv":202.87,"id":26354927},{"batb":[[1,1.63,19.38]],"ltp":1.65,"tv":12988.8,"id":26354926}]}]}
{"op":"mcm","clk":"11873599523","pt":1723580472457,"mc":[{"id":"1.231659753","rc":[{"batb":[[0,2.52,10]],"ltp":2.54,"tv":202.87,"id":26354927}]}]}
{"op":"mcm","clk":"11873599653","pt":1723580473650,"mc":[{"id":"1.231659753","rc":[{"batb":[[0,2.5,51.3],[1,1.28,52.43],[2,1.26,53.26]],"ltp":2.54,"tv":202.87,"id":26354927},{"batb":[[1,1.63,30.38],[2,1.62,74.19]],"batl":[[1,1.68,170]],"ltp":1.65,"tv":12988.8,"id":26354926}]}]}
{"op":"mcm","clk":"11873599866","pt":1723580475448,"mc":[{"id":"1.231659753","rc":[{"trd":[[2.52,8]],"batb":[[0,2.5,55.3]],"ltp":2.52,"tv":210.87,"id":26354927},{"trd":[[1.66,153.24]],"batb":[[2,1.62,61.19]],"batl":[[0,1.67,67.09]],"ltp":1.66,"tv":13000.94,"id":26354926}],"tv":13211.82}]}
{"op":"mcm","clk":"11873600015","pt":1723580476644,"mc":[{"id":"1.231659753","rc":[{"trd":[[2.52,18]],"ltp":2.52,"tv":220.87,"id":26354927},{"trd":[[1.66,168.42]],"ltp":1.66,"tv":13016.12,"id":26354926}],"tv":13237.0}]}
{"op":"mcm","clk":"11873600081","pt":1723580477165,"mc":[{"id":"1.231659753","rc":[{"batb":[[2,1.62,75.19]],"ltp":1.66,"tv":13016.12,"id":26354926}]}]}
{"op":"mcm","clk":"11873600339","pt":1723580479364,"mc":[{"id":"1.231659753","rc":[{"trd":[[2.52,22]],"ltp":2.52,"tv":224.87,"id":26354927},{"trd":[[1.66,174.49]],"batb":[[2,1.62,61.19]],"ltp":1.66,"tv":13022.19,"id":26354926}],"tv":13247.07}]}
{"op":"mcm","clk":"11873600510","pt":1723580480777,"mc":[{"id":"1.231659753","rc":[{"batb":[[0,2.52,10],[1,2.5,51.3],[2,1.28,52.43]],"ltp":2.52,"tv":224.87,"id":26354927},{"batb":[[0,1.63,94.76],[1,1.62,75.19],[2,1.61,800]],"ltp":1.66,"tv":13022.19,"id":26354926}]}]}
{"op":"mcm","clk":"11873601012","pt":1723580484644,"mc":[{"id":"1.231659753","rc":[{"batb":[[0,2.54,4]],"ltp":2.52,"tv":224.87,"id":26354927}]}]}
{"op":"mcm","clk":"11873601048","pt":1723580484954,"mc":[{"id":"1.231659753","rc":[{"batb":[[0,1.63,86.12]],"ltp":1.66,"tv":13022.19,"id":26354926}]}]}
{"op":"mcm","clk":"11873601341","pt":1723580487766,"mc":[{"id":"1.231659753","rc":[{"batb":[[0,2.52,10]],"ltp":2.52,"tv":224.87,"id":26354927}]}]}
{"op":"mcm","clk":"11873601693","pt":1723580490677,"mc":[{"id":"1.231659753","rc":[{"batl":[[0,2.58,4],[1,2.6,31.44],[2,2.62,32.43]],"ltp":2.52,"tv":224.87,"id":26354927},{"batb":[[0,1.64,4],[1,1.63,90.12],[2,1.62,75.19]],"batl":[[0,1.66,4],[1,1.67,67.09],[2,1.68,170]],"ltp":1.66,"tv":13022.19,"id":26354926}]}]}
{"op":"mcm","clk":"11873601795","pt":1723580491465,"mc":[{"id":"1.231659753","rc":[{"batb":[[0,2.5,51.3],[1,1.28,52.43],[2,1.26,53.26]],"ltp":2.52,"tv":224.87,"id":26354927}]}]}
{"op":"mcm","clk":"11873602566","pt":1723580498156,"mc":[{"id":"1.231659753","rc":[{"batl":[[0,1.66,15.11]],"ltp":1.66,"tv":13022.19,"id":26354926}]}]}
{"op":"mcm","clk":"11873603456","pt":1723580505668,"mc":[{"id":"1.231659753","rc":[{"batb":[[0,2.5,55.3]],"ltp":2.52,"tv":224.87,"id":26354927}]}]}
{"op":"mcm","clk":"11873608738","pt":1723580545852,"mc":[{"id":"1.231659753","rc":[{"batb":[[0,1.65,25],[1,1.64,26.85],[2,1.63,65.12]],"ltp":1.66,"tv":13022.19,"id":26354926}]}]}
{"op":"mcm","clk":"11873608872","pt":1723580546746,"mc":[{"id":"1.231659753","rc":[{"batb":[[0,2.5,30.01]],"batl":[[0,2.58,27.5]],"ltp":2.52,"tv":224.87,"id":26354927},{"trd":[[1.66,204.71]],"batb":[[1,1.64,22.85],[2,1.63,61.12]],"batl":[[0,1.67,67.09],[1,1.68,170],[2,1.69,480]],"ltp":1.66,"tv":13052.41,"id":26354926}],"tv":13277.29}]}
{"op":"mcm","clk":"11873609014","pt":1723580547846,"mc":[{"id":"1.231659753","rc":[{"batb":[[0,1.66,11.11],[1,1.65,25],[2,1.64,6]],"ltp":1.66,"tv":13052.41,"id":26354926}]}]}
{"op":"mcm","clk":"11873609156","pt":1723580548880,"mc":[{"id":"1.231659753","rc":[{"trd":[[2.5,30.01]],"batb":[[0,1.3,81.96],[1,1.29,92.6]],"ltp":2.5,"tv":254.88,"id":26354927},{"trd":[[1.67,242.93]],"batb":[[1,1.64,25],[2,1.63,75.12]],"batl":[[0,1.67,33.89]],"ltp":1.67,"tv":13291.34,"id":26354926}],"tv":13546.23}]}
{"op":"mcm","clk":"11873609356","pt":1723580550350,"mc":[{"id":"1.231659753","rc":[{"batb":[[0,1.64,25],[1,1.63,75.12],[2,1.61,800]],"ltp":1.67,"tv":13291.34,"id":26354926}]}]}
{"op":"mcm","clk":"11873609539","pt":1723580551652,"mc":[{"id":"1.231659753","rc":[{"batb":[[0,2.5,25.29],[1,2.48,37.67],[2,1.3,81.96]],"ltp":2.5,"tv":254.88,"id":26354927},{"batb":[[2,1.62,61.19]],"batl":[[0,1.67,37.89]],"ltp":1.67,"tv":13291.34,"id":26354926}]}]}
{"op":"mcm","clk":"11873610591","pt":1723580560053,"mc":[{"id":"1.231659753","rc":[{"batb":[[0,1.65,11.18],[1,1.64,25],[2,1.63,75.12]],"ltp":1.67,"tv":13291.34,"id":26354926}]}]}
{"op":"mcm","clk":"11873610786","pt":1723580561769,"mc":[{"id":"1.231659753","rc":[{"batb":[[0,2.48,37.67],[1,1.3,81.96],[2,1.29,82.6]],"ltp":2.5,"tv":254.88,"id":26354927}]}]}
{"op":"mcm","clk":"11873610831","pt":1723580562079,"mc":[{"id":"1.231659753","rc":[{"batb":[[0,2.5,10],[1,2.48,37.67],[2,1.3,81.96]],"ltp":2.5,"tv":254.88,"id":26354927},{"batb":[[2,1.63,64.12]],"ltp":1.67,"tv":13291.34,"id":26354926}]}]}
{"op":"mcm","clk":"11873611307","pt":1723580565479,"mc":[{"id":"1.231659753","rc":[{"batb":[[0,2.48,37.67],[1,1.3,81.96],[2,1.29,82.6]],"ltp":2.5,"tv":254.88,"id":26354927},{"batb":[[0,1.65,27.93]],"ltp":1.67,"tv":13291.34,"id":26354926}]}]}
{"op":"mcm","clk":"11873611426","pt":1723580566370,"mc":[{"id":"1.231659753","rc":[{"batl":[[0,2.54,4],[1,2.58,27.5],[2,2.6,31.44]],"ltp":2.5,"tv":254.88,"id":26354927},{"batb":[[0,1.66,25],[1,1.65,30.93],[2,1.63,55.74]],"ltp":1.67,"tv":13291.34,"id":26354926}]}]}
{"op":"mcm","clk":"11873611525","pt":1723580567254,"mc":[{"id":"1.231659753","rc":[{"batb":[[1,1.65,14.18]],"ltp":1.67,"tv":13291.34,"id":26354926}]}]}
{"op":"mcm","clk":"11873613793","pt":1723580584611,"mc":[{"id":"1.231659753","rc":[{"trd":[[1.67,257.67]],"batb":[[0,1.66,41.65],[1,1.65,11.18]],"batl":[[0,1.67,30.52]],"ltp":1.67,"tv":13306.08,"id":26354926}],"tv":13560.97}]}
{"op":"mcm","clk":"11873640495","pt":1723580825842,"mc":[{"id":"1.231659753","rc":[{"trd":[[1.66,288.01]],"batb":[[0,1.64,11.25],[1,1.62,54.1],[2,1.61,800]],"batl":[[0,1.66,33.35],[1,1.67,30.52],[2,1.68,170]],"ltp":1.66,"tv":13389.38,"id":26354926}],"tv":13644.27}]}
{"op":"mcm","clk":"11873640508","pt":1723580825948,"mc":[{"id":"1.231659753","rc":[{"batb":[[1,1.63,61.77],[2,1.62,54.1]],"ltp":1.66,"tv":13389.38,"id":26354926}]}]}
{"op":"mcm","clk":"11873640720","pt":1723580827825,"mc":[{"id":"1.231659753","rc":[{"batb":[[0,2.5,52.32],[1,2.48,37.67],[2,1.3,81.96]],"ltp":2.5,"tv":254.88,"id":26354927},{"batb":[[0,1.64,54.53],[2,1.62,115.29]],"ltp":1.66,"tv":13389.38,"id":26354926}]}]}
{"op":"mcm","clk":"11873641215","pt":1723580832770,"mc":[{"id":"1.231659753","rc":[{"batb":[[0,2.5,27.03]],"ltp":2.5,"tv":254.88,"id":26354927},{"batb":[[2,1.62,54.1]],"ltp":1.66,"tv":13389.38,"id":26354926}]}]}
{"op":"mcm","clk":"11873641253","pt":1723580833031,"mc":[{"id":"1.231659753","rc":[{"batb":[[0,2.48,37.67],[1,1.3,81.96],[2,1.29,82.6]],"ltp":2.5,"tv":254.88,"id":26354927},{"trd":[[1.64,11.55]],"batb":[[0,1.64,50.53]],"ltp":1.64,"tv":13397.38,"id":26354926}],"tv":13652.27}]}
{"op":"mcm","clk":"11873641726","pt":1723580837762,"mc":[{"id":"1.231659753","rc":[{"batb":[[0,2.5,25.29],[1,2.48,37.67],[2,1.3,81.96]],"ltp":2.5,"tv":254.88,"id":26354927},{"batb":[[1,1.62,115.29],[2,1.61,800]],"ltp":1.64,"tv":13397.38,"id":26354926}]}]}
{"op":"mcm","clk":"11873641821","pt":1723580838746,"mc":[{"id":"1.231659753","rc":[{"trd":[[2.52,35.18]],"batb":[[0,2.52,20.24],[1,2.5,56.32],[2,2.48,37.67]],"batl":[[0,2.58,4],[1,2.6,2]],"ltp":2.52,"tv":268.06,"id":26354927},{"batb":[[0,1.64,54.53]],"batl":[[0,1.66,96.81]],"ltp":1.64,"tv":13397.38,"id":26354926}],"tv":13665.45}]}
{"op":"mcm","clk":"11873641896","pt":1723580839374,"mc":[{"id":"1.231659753","rc":[{"batl":[[2,2.62,1.27]],"ltp":2.52,"tv":268.06,"id":26354927}]}]}
{"op":"mcm","clk":"11873642240","pt":1723580842874,"mc":[{"id":"1.231659753","rc":[{"batb":[[1,2.5,31.03]],"ltp":2.52,"tv":268.06,"id":26354927},{"batb":[[1,1.62,54.1]],"ltp":1.64,"tv":13397.38,"id":26354926}]}]}
{"op":"mcm","clk":"11873643398","pt":1723580853782,"mc":[{"id":"1.231659753","rc":[{"batb":[[0,2.52,24.24]],"batl":[[0,2.56,6],[1,2.58,4]],"ltp":2.52,"tv":268.06,"id":26354927}]}]}
{"op":"mcm","clk":"11873643450","pt":1723580854153,"mc":[{"id":"1.231659753","rc":[{"batl":[[2,2.6,1.27]],"ltp":2.52,"tv":268.06,"id":26354927}]}]}
{"op":"mcm","clk":"11873645535","pt":1723580875991,"mc":[{"id":"1.231659753","rc":[{"batl":[[0,1.66,63.46]],"ltp":1.64,"tv":13397.38,"id":26354926}]}]}
{"op":"mcm","clk":"11873646455","pt":1723580885818,"mc":[{"id":"1.231659753","rc":[{"batl":[[0,2.6,2],[1,2.58,0],[2,2.6,0]],"ltp":2.52,"tv":268.06,"id":26354927},{"trd":[[1.64,78.25]],"batb":[[0,1.62,54.1],[1,1.61,800],[2,1.59,800]],"ltp":1.64,"tv":13464.08,"id":26354926}],"tv":13732.15}]}
{"op":"mcm","clk":"11873646513","pt":1723580886392,"mc":[{"id":"1.231659753","rc":[{"batb":[[0,2.54,4],[1,2.52,24.24],[2,2.5,31.03]],"batl":[[0,2.56,2],[1,2.58,33.43],[2,2.64,1.25]],"ltp":2.52,"tv":268.06,"id":26354927},{"batl":[[0,1.65,4.61],[1,1.66,4],[2,1.67,30.52]],"ltp":1.64,"tv":13464.08,"id":26354926}]}]}
{"op":"mcm","clk":"11873646649","pt":1723580887902,"mc":[{"id":"1.231659753","rc":[{"batb":[[2,2.5,56.32]],"ltp":2.52,"tv":268.06,"id":26354927},{"batb":[[0,1.62,115.29]],"ltp":1.64,"tv":13464.08,"id":26354926}]}]}
{"op":"mcm","clk":"11873646687","pt":1723580888314,"mc":[{"id":"1.231659753","rc":[{"batb":[[0,2.52,24.24],[1,2.5,56.32],[2,2.48,37.67]],"batl":[[2,2.6,1.25]],"ltp":2.52,"tv":268.06,"id":26354927}]}]}
{"op":"mcm","clk":"11873647714","pt":1723580899009,"mc":[{"id":"1.231659753","rc":[{"batl":[[0,2.56,6]],"ltp":2.52,"tv":268.06,"id":26354927},{"batl":[[0,1.65,8.61]],"ltp":1.64,"tv":13464.08,"id":26354926}]}]}
{"op":"mcm","clk":"11873649358","pt":1723580914243,"mc":[{"id":"1.231659753","rc":[{"batb":[[0,1.64,4],[1,1.62,115.29],[2,1.61,800]],"ltp":1.64,"tv":13464.08,"id":26354926}]}]}
{"op":"mcm","clk":"11873708282","pt":1723581633848,"mc":[{"id":"1.231659753","rc":[{"trd":[[2.52,89.3]],"batb":[[0,2.5,25.29],[1,1.3,81.96],[2,1.29,82.6]],"batl":[[0,2.52,10180.45],[1,2.56,4],[2,2.58,33.43]],"ltp":2.52,"tv":322.18,"id":26354927},{"trd":[[1.65,56.7]],"batb":[[0,1.65,112.09],[1,1.64,4],[2,1.62,115.29]],"batl":[[0,1.66,4.59],[1,1.68,170],[2,1.69,480]],"ltp":1.65,"tv":13472.69,"id":26354926}],"tv":13794.88}]}
{"op":"mcm","clk":"11873708437","pt":1723581636271,"mc":[{"id":"1.231659753","rc":[{"batl":[[0,1.68,170],[1,1.69,480],[2,1.73,900]],"ltp":1.65,"tv":13472.69,"id":26354926}]}]}
{"op":"mcm","clk":"11873708856","pt":1723581643067,"mc":[{"id":"1.231659753","rc":[{"batl":[[0,2.52,10184.45]],"ltp":2.52,"tv":322.18,"id":26354927},{"batb":[[0,1.66,4],[1,1.65,116.09],[2,1.64,4]],"ltp":1.65,"tv":13472.69,"id":26354926}]}]}
{"op":"mcm","clk":"11873713701","pt":1723581728870,"mc":[{"id":"1.231659753","rc":[{"trd":[[1.66,290.01]],"batb":[[0,1.66,3]],"ltp":1.66,"tv":13474.69,"id":26354926}],"tv":13796.88}]}
{"op":"mcm","clk":"11873729366","pt":1723581999312,"mc":[{"id":"1.231659753","rc":[{"trd":[[2.5,33.71]],"batb":[[0,2.5,23.44]],"ltp":2.5,"tv":325.88,"id":26354927}],"tv":13800.58}]}
{"op":"mcm","clk":"11873729501","pt":1723582001826,"mc":[{"id":"1.231659753","rc":[{"batb":[[0,2.5,25.29]],"ltp":2.5,"tv":325.88,"id":26354927}]}]}
{"op":"mcm","clk":"11873739142","pt":1723582166197,"mc":[{"id":"1.231659753","rc":[{"batl":[[0,1.67,200],[1,1.68,170],[2,1.69,480]],"ltp":1.66,"tv":13474.69,"id":26354926}]}]}
{"op":"mcm","clk":"11873740524","pt":1723582192924,"mc":[{"id":"1.231659753","rc":[{"trd":[[1.67,269.67]],"batl":[[0,1.67,194]],"ltp":1.67,"tv":13486.69,"id":26354926}],"tv":13812.58}]}
{"op":"mcm","clk":"11873772956","pt":1723582810453,"mc":[{"id":"1.231659753","rc":[{"trd":[[1.1,14.19]],"batb":[[1,2.46,27.33],[2,1.3,81.96]],"ltp":2.5,"tv":325.88,"id":26354927},{"trd":[[1.58,747.93],[1.63,120.5],[1.66,290]],"batb":[[1,1.65,156.83]],"ltp":1.67,"tv":13486.62,"id":26354926}],"tv":13812.5}]}
{"op":"mcm","clk":"11873788814","pt":1723583104391,"mc":[{"id":"1.231659753","rc":[{"trd":[[2.5,84.29]],"batb":[[0,2.46,27.33],[1,1.3,81.96],[2,1.29,82.6]],"batl":[[0,2.52,10184.95]],"ltp":2.5,"tv":376.46,"id":26354927}],"tv":13863.08}]}
{"op":"mcm","clk":"11873788856","pt":1723583105363,"mc":[{"id":"1.231659753","rc":[{"batb":[[1,2.42,26.71],[2,1.3,81.96]],"ltp":2.5,"tv":376.46,"id":26354927}]}]}
{"op":"mcm","clk":"11873789122","pt":1723583110179,"mc":[{"id":"1.231659753","rc":[{"trd":[[2.48,25.79]],"ltp":2.48,"tv":402.25,"id":26354927},{"trd":[[1.67,307.96]],"batl":[[0,1.67,155.71]],"ltp":1.67,"tv":13524.91,"id":26354926}],"tv":13927.16}]}
{"op":"mcm","clk":"11873789246","pt":1723583112073,"mc":[{"id":"1.231659753","rc":[{"batl":[[0,2.5,4.5],[1,2.52,10184.45],[2,2.56,4]],"ltp":2.48,"tv":402.25,"id":26354927}]}]}
{"op":"mcm","clk":"11873789358","pt":1723583113865,"mc":[{"id":"1.231659753","rc":[{"batl":[[0,2.5,4]],"ltp":2.48,"tv":402.25,"id":26354927}]}]}
{"op":"mcm","clk":"11873789363","pt":1723583113968,"mc":[{"id":"1.231659753","rc":[{"trd":[[2.48,26.28]],"ltp":2.48,"tv":402.74,"id":26354927},{"trd":[[1.67,308.7]],"batl":[[0,1.67,154.97]],"ltp":1.67,"tv":13525.65,"id":26354926}],"tv":13928.39}]}
{"op":"mcm","clk":"11873880921","pt":1723584869447,"mc":[{"id":"1.231659753","rc":[{"trd":[[1.66,290.76]],"batb":[[0,1.66,2.62]],"ltp":1.66,"tv":13526.41,"id":26354926}],"tv":13929.15}]}
{"op":"mcm","clk":"11873884353","pt":1723584940422,"mc":[{"id":"1.231659753","rc":[{"batl":[[0,1.67,508.8]],"ltp":1.66,"tv":13526.41,"id":26354926}]}]}
{"op":"mcm","clk":"11873886121","pt":1723584973427,"mc":[{"id":"1.231659753","rc":[{"batb":[[0,2.48,26.82],[1,2.44,63.16],[2,2.42,26.71]],"batl":[[1,2.52,10185.75]],"ltp":2.48,"tv":402.74,"id":26354927}]}]}
{"op":"mcm","clk":"11873886315","pt":1723584976956,"mc":[{"id":"1.231659753","rc":[{"batb":[[2,1.3,81.96]],"ltp":2.48,"tv":402.74,"id":26354927}]}]}
{"op":"mcm","clk":"11873889696","pt":1723585039628,"mc":[{"id":"1.231659753","rc":[{"trd":[[2.5,92.29],[2.52,131.3]],"batl":[[0,2.52,10164.75],[1,2.56,4],[2,2.58,33.43]],"ltp":2.52,"tv":452.74,"id":26354927}],"tv":13979.15}]}
{"op":"mcm","clk":"11873890158","pt":1723585049504,"mc":[{"id":"1.231659753","rc":[{"batl":[[0,2.5,4],[1,2.52,10164.75],[2,2.56,4]],"ltp":2.52,"tv":452.74,"id":26354927}]}]}
{"op":"mcm","clk":"11873899973","pt":1723585230088,"mc":[{"id":"1.231659753","rc":[{"trd":[[2.5,96.27]],"batl":[[0,2.52,10164.77],[1,2.56,4],[2,2.58,33.43]],"ltp":2.5,"tv":456.72,"id":26354927},{"trd":[[1.66,302]],"batb":[[0,1.65,156.83],[1,1.64,4],[2,1.63,800]],"ltp":1.66,"tv":13537.64,"id":26354926}],"tv":13994.37}]}
{"op":"mcm","clk":"11873900010","pt":1723585231212,"mc":[{"id":"1.231659753","rc":[{"batl":[[0,2.5,4.02],[1,2.52,10164.75],[2,2.56,4]],"ltp":2.5,"tv":456.72,"id":26354927},{"batb":[[0,1.66,4],[1,1.65,156.83],[2,1.64,4]],"ltp":1.66,"tv":13537.64,"id":26354926}]}]}
{"op":"mcm","clk":"11873900207","pt":1723585235407,"mc":[{"id":"1.231659753","rc":[{"batb":[[1,1.3,81.96],[2,1.29,82.6]],"ltp":2.5,"tv":456.72,"id":26354927},{"batl":[[0,1.67,154.97]],"ltp":1.66,"tv":13537.64,"id":26354926}]}]}
{"op":"mcm","clk":"11873900603","pt":1723585242721,"mc":[{"id":"1.231659753","rc":[{"trd":[[2.5,100.27]],"batl":[[0,2.52,10164.77],[1,2.56,4],[2,2.58,33.43]],"ltp":2.5,"tv":460.72,"id":26354927},{"trd":[[1.66,316.03]],"batb":[[0,1.65,156.83],[1,1.64,4],[2,1.63,800]],"ltp":1.66,"tv":13551.67,"id":26354926}],"tv":14012.4}]}
{"op":"mcm","clk":"11873900784","pt":1723585246423,"mc":[{"id":"1.231659753","rc":[{"batl":[[0,2.5,4.02],[1,2.52,10164.75],[2,2.56,4]],"ltp":2.5,"tv":460.72,"id":26354927},{"batb":[[0,1.66,4],[1,1.65,156.83],[2,1.64,4]],"ltp":1.66,"tv":13551.67,"id":26354926}]}]}
{"op":"mcm","clk":"11873901045","pt":1723585252707,"mc":[{"id":"1.231659753","rc":[{"batb":[[0,2.46,27.33],[1,2.42,26.71],[2,1.27,82.64]],"ltp":2.5,"tv":460.72,"id":26354927}]}]}
{"op":"mcm","clk":"11873901610","pt":1723585265747,"mc":[{"id":"1.231659753","rc":[{"trd":[[2.5,104.27]],"batl":[[0,2.52,10164.77],[1,2.56,4],[2,2.58,33.43]],"ltp":2.5,"tv":464.72,"id":26354927},{"trd":[[1.66,330.06]],"batb":[[0,1.65,156.83],[1,1.64,4],[2,1.63,800]],"ltp":1.66,"tv":13565.7,"id":26354926}],"tv":14030.43}]}
{"op":"mcm","clk":"11873902136","pt":1723585276767,"mc":[{"id":"1.231659753","rc":[{"batb":[[0,1.66,4],[1,1.65,156.83],[2,1.64,4]],"ltp":1.66,"tv":13565.7,"id":26354926}]}]}
{"op":"mcm","clk":"11873902284","pt":1723585281565,"mc":[{"id":"1.231659753","rc":[{"trd":[[2.5,104.28]],"batl":[[0,2.52,10164.76]],"ltp":2.5,"tv":464.73,"id":26354927},{"trd":[[1.66,338.07]],"batb":[[0,1.65,156.83],[1,1.64,4],[2,1.63,800]],"ltp":1.66,"tv":13573.71,"id":26354926}],"tv":14038.45}]}
{"op":"mcm","clk":"11873902767","pt":1723585291854,"mc":[{"id":"1.231659753","rc":[{"batb":[[0,1.66,4],[1,1.65,156.83],[2,1.64,4]],"ltp":1.66,"tv":13573.71,"id":26354926}]}]}
{"op":"mcm","clk":"11873903301","pt":1723585301899,"mc":[{"id":"1.231659753","rc":[{"trd":[[2.5,104.29]],"batl":[[0,2.52,10164.75]],"ltp":2.5,"tv":464.74,"id":26354927},{"trd":[[1.66,346.08]],"batb":[[0,1.65,156.83],[1,1.64,4],[2,1.63,800]],"ltp":1.66,"tv":13581.73,"id":26354926}],"tv":14046.47}]}
{"op":"mcm","clk":"11873906080","pt":1723585361760,"mc":[{"id":"1.231659753","rc":[{"batb":[[0,2.46,88.83]],"ltp":2.5,"tv":464.74,"id":26354927},{"batb":[[0,1.65,153.83],[1,1.64,7]],"batl":[[0,1.66,319.21],[1,1.67,154.97],[2,1.68,170]],"ltp":1.66,"tv":13581.73,"id":26354926}]}]}
{"op":"mcm","clk":"11873915073","pt":1723585376277,"mc":[{"id":"1.231659753","rc":[{"batb":[[0,2.48,26.82],[1,2.44,59.94],[2,2.42,26.71]],"ltp":2.5,"tv":464.74,"id":26354927}]}]}
{"op":"mcm","clk":"11873915185","pt":1723585378174,"mc":[{"id":"1.231659753","rc":[{"batb":[[2,1.27,82.64]],"ltp":2.5,"tv":464.74,"id":26354927}]}]}
{"op":"mcm","clk":"11873937162","pt":1723585785904,"mc":[{"id":"1.231659753","rc":[{"batl":[[0,1.67,154.97],[1,1.68,170],[2,1.69,480]],"ltp":1.66,"tv":13581.73,"id":26354926}]}]}
{"op":"mcm","clk":"11873937181","pt":1723585786311,"mc":[{"id":"1.231659753","rc":[{"trd":[[2.52,551.84]],"batb":[[1,1.27,82.64],[2,1.26,83.3]],"batl":[[0,2.52,9954.48]],"ltp":2.52,"tv":885.28,"id":26354927},{"batb":[[0,1.66,3],[1,1.65,153.83],[2,1.64,4]],"ltp":1.66,"tv":13581.73,"id":26354926}],"tv":14467.01}]}
{"op":"mcm","clk":"11873938811","pt":1723585815360,"mc":[{"id":"1.231659753","rc":[{"batb":[[0,2.46,27.33],[1,1.26,83.3],[2,1.25,100]],"ltp":2.52,"tv":885.28,"id":26354927}]}]}
{"op":"mcm","clk":"11873939132","pt":1723585819770,"mc":[{"id":"1.231659753","rc":[{"batb":[[1,2.42,26.71],[2,1.26,83.3]],"ltp":2.52,"tv":885.28,"id":26354927}]}]}
{"op":"mcm","clk":"11873978136","pt":1723586543114,"mc":[{"id":"1.231659753","rc":[{"trd":[[2.48,26.27],[2.5,104.28],[2.52,551.73]],"batb":[[0,2.46,27.33]],"ltp":2.52,"tv":885.15,"id":26354927},{"trd":[[1.58,747.72],[1.63,120.5],[1.66,352.06]],"batb":[[0,1.65,153.82],[1,1.64,4],[2,1.63,800]],"batl":[[0,1.66,4.72],[1,1.67,154.97],[2,1.68,170]],"ltp":1.66,"tv":13587.5,"id":26354926}],"tv":14472.66}]}
{"op":"mcm","clk":"11874000558","pt":1723586893435,"mc":[{"id":"1.231659753","rc":[{"trd":[[2.5,107.41]],"batl":[[0,2.52,9955.35]],"ltp":2.5,"tv":888.28,"id":26354927},{"trd":[[1.66,356.78]],"batl":[[0,1.67,154.97],[1,1.68,170],[2,1.69,480]],"ltp":1.66,"tv":13592.22,"id":26354926}],"tv":14480.51}]}
{"op":"mcm","clk":"11874067679","pt":1723587843552,"mc":[{"id":"1.231659753","rc":[{"batl":[[0,2.52,9953.35]],"ltp":2.5,"tv":888.28,"id":26354927}]}]}
{"op":"mcm","clk":"11874295202","pt":1723590775005,"mc":[{"id":"1.231659753","rc":[{"trd":[[1.1,14.19],[2.48,26.28],[2.5,107.42],[2.52,551.87]],"batb":[[0,2.46,27.34]],"ltp":2.5,"tv":888.44,"id":26354927},{"trd":[[1.58,747.98],[1.61,1975.1],[1.63,120.5],[1.64,78.25],[1.65,56.71],[1.66,356.81],[1.73,4.75]],"batb":[[0,1.65,153.83]],"ltp":1.66,"tv":13592.52,"id":26354926}],"tv":14480.97}]}
{"op":"mcm","clk":"11874349520","pt":1723591368225,"mc":[{"id":"1.231659753","rc":[{"trd":[[2.5,108.29]],"batl":[[0,2.52,9952.48]],"ltp":2.5,"tv":889.31,"id":26354927},{"trd":[[1.66,370.92]],"batl":[[0,1.66,10.33],[1,1.67,154.97],[2,1.68,170]],"ltp":1.66,"tv":13606.63,"id":26354926}],"tv":14495.95}]}
{"op":"mcm","clk":"11874350316","pt":1723591379292,"mc":[{"id":"1.231659753","rc":[{"batl":[[0,1.67,154.97],[1,1.68,170],[2,1.69,480]],"ltp":1.66,"tv":13606.63,"id":26354926}]}]}
{"op":"mcm","clk":"11874408323","pt":1723592117430,"mc":[{"id":"1.231659753","rc":[{"trd":[[1.65,59.33]],"batb":[[0,1.65,152.52]],"ltp":1.65,"tv":13609.25,"id":26354926}],"tv":14498.57}]}
{"op":"mcm","clk":"11874419783","pt":1723592263492,"mc":[{"id":"1.231659753","rc":[{"batb":[[2,1.62,61.19]],"ltp":1.65,"tv":13609.25,"id":26354926}]}]}
{"op":"mcm","clk":"11874443183","pt":1723592552106,"mc":[{"id":"1.231659753","rc":[{"trd":[[1.65,259.33]],"batb":[[0,1.65,52.52]],"ltp":1.65,"tv":13809.25,"id":26354926}],"tv":14698.57}]}
{"op":"mcm","clk":"11874481871","pt":1723593037399,"mc":[{"id":"1.231659753","rc":[{"batb":[[0,1.65,53.52]],"ltp":1.65,"tv":13809.25,"id":26354926}]}]}
{"op":"mcm","clk":"11874649431","pt":1723595729512,"mc":[{"id":"1.231659753","rc":[{"trd":[[2.48,26.29],[2.5,108.3],[2.52,551.83]],"batb":[[0,2.46,27.34]],"ltp":2.5,"tv":889.28,"id":26354927},{"trd":[[1.58,747.9],[1.61,1975.1],[1.64,78.25],[1.66,370.91]],"batb":[[0,1.65,53.54]],"batl":[[0,1.67,156.78]],"ltp":1.65,"tv":13809.14,"id":26354926}],"tv":14698.42}]}
{"op":"mcm","clk":"11874672380","pt":1723596161119,"mc":[{"id":"1.231659753","rc":[{"batb":[[0,1.65,154.85]],"ltp":1.65,"tv":13809.14,"id":26354926}]}]}
{"op":"mcm","clk":"11874672623","pt":1723596165301,"mc":[{"id":"1.231659753","rc":[{"batb":[[0,2.46,100.51]],"ltp":2.5,"tv":889.28,"id":26354927},{"batl":[[2,1.69,1033.85]],"ltp":1.65,"tv":13809.14,"id":26354926}]}]}
{"op":"mcm","clk":"11874672827","pt":1723596169006,"mc":[{"id":"1.231659753","rc":[{"batl":[[1,1.68,723.85]],"ltp":1.65,"tv":13809.14,"id":26354926}]}]}
{"op":"mcm","clk":"11874683991","pt":1723596227206,"mc":[{"id":"1.231659753","rc":[{"trd":[[1.65,303.33]],"batb":[[0,1.65,132.85]],"ltp":1.65,"tv":13853.14,"id":26354926}],"tv":14742.42}]}
{"op":"mcm","clk":"11874684434","pt":1723596235404,"mc":[{"id":"1.231659753","rc":[{"batb":[[0,1.65,136.85]],"ltp":1.65,"tv":13853.14,"id":26354926}]}]}
{"op":"mcm","clk":"11874687179","pt":1723596294656,"mc":[{"id":"1.231659753","rc":[{"batb":[[1,1.64,26]],"ltp":1.65,"tv":13853.14,"id":26354926}]}]}
{"op":"mcm","clk":"11874843777","pt":1723599881172,"mc":[{"id":"1.231659753","rc":[{"trd":[[1.1,14.19],[2.48,26.31],[2.5,108.32],[2.52,551.76]],"batb":[[0,2.46,100.53]],"ltp":2.5,"tv":889.26,"id":26354927},{"trd":[[1.58,747.79],[1.61,1975.1],[1.63,120.5],[1.64,78.25],[1.65,303.33],[1.66,370.9],[1.73,4.75]],"batb":[[0,1.65,136.87]],"batl":[[0,1.67,156.78],[1,1.68,170]],"ltp":1.65,"tv":13853.02,"id":26354926}],"tv":14742.28}]}
{"op":"mcm","clk":"11874844052","pt":1723599886980,"mc":[{"id":"1.231659753","rc":[{"batl":[[1,1.68,446.92]],"ltp":1.65,"tv":13853.02,"id":26354926}]}]}
{"op":"mcm","clk":"11874927158","pt":1723601575010,"mc":[{"id":"1.231659753","rc":[{"trd":[[1.1,14.19],[2.48,26.3],[2.5,108.3],[2.52,551.67]],"batb":[[0,2.46,100.52]],"ltp":2.5,"tv":889.14,"id":26354927},{"trd":[[1.58,747.62],[1.63,120.5],[1.65,303.33],[1.66,370.88]],"batb":[[0,1.65,136.85]],"ltp":1.65,"tv":13852.83,"id":26354926}],"tv":14741.97}]}
{"op":"mcm","clk":"11875008331","pt":1723603489063,"mc":[{"id":"1.231659753","rc":[{"trd":[[1.65,463.33]],"batb":[[0,1.65,56.85]],"ltp":1.65,"tv":14012.83,"id":26354926}],"tv":14901.98}]}
{"op":"mcm","clk":"11875038156","pt":1723604374239,"mc":[{"id":"1.231659753","rc":[{"trd":[[1.65,494.43]],"batb":[[0,1.65,41.3]],"ltp":1.65,"tv":14043.93,"id":26354926}],"tv":14933.07}]}
{"op":"mcm","clk":"11875049769","pt":1723604694822,"mc":[{"id":"1.231659753","rc":[{"trd":[[1.1,14.2],[2.48,26.27],[2.5,108.28],[2.52,551.57]],"batb":[[0,2.46,100.49]],"ltp":2.5,"tv":889.0,"id":26354927},{"trd":[[1.58,747.45],[1.61,1975.1],[1.63,120.5],[1.64,78.25],[1.65,494.39],[1.66,370.87],[1.73,4.76]],"batl":[[0,1.67,156.77],[1,1.68,170],[2,1.69,480]],"ltp":1.65,"tv":14043.75,"id":26354926}],"tv":14932.75}]}
{"op":"mcm","clk":"11875049782","pt":1723604695129,"mc":[{"id":"1.231659753","rc":[{"batb":[[0,2.46,27.32],[1,2.42,70.81]],"ltp":2.5,"tv":889.0,"id":26354927}]}]}
{"op":"mcm","clk":"11875078960","pt":1723605442615,"mc":[{"id":"1.231659753","rc":[{"trd":[[1.67,622.24]],"batb":[[0,1.67,56.56],[1,1.65,41.3],[2,1.64,26]],"batl":[[0,1.68,170],[1,1.69,480],[2,1.74,25.25]],"ltp":1.67,"tv":14357.29,"id":26354926}],"tv":15246.29}]}
{"op":"mcm","clk":"11875079002","pt":1723605443895,"mc":[{"id":"1.231659753","rc":[{"batl":[[0,2.5,2],[1,2.52,9952.48],[2,2.56,4]],"ltp":2.5,"tv":889.0,"id":26354927}]}]}
{"op":"mcm","clk":"11875079137","pt":1723605447326,"mc":[{"id":"1.231659753","rc":[{"batb":[[1,2.42,44.1]],"ltp":2.5,"tv":889.0,"id":26354927}]}]}
{"op":"mcm","clk":"11875079288","pt":1723605451834,"mc":[{"id":"1.231659753","rc":[{"batl":[[0,2.5,6]],"ltp":2.5,"tv":889.0,"id":26354927}]}]}
{"op":"mcm","clk":"11875080289","pt":1723605483277,"mc":[{"id":"1.231659753","rc":[{"batl":[[2,1.71,553.85]],"ltp":1.67,"tv":14357.29,"id":26354926}]}]}
{"op":"mcm","clk":"11875080406","pt":1723605486458,"mc":[{"id":"1.231659753","rc":[{"batl":[[2,1.7,553.85]],"ltp":1.67,"tv":14357.29,"id":26354926}]}]}
{"op":"mcm","clk":"11875080488","pt":1723605489471,"mc":[{"id":"1.231659753","rc":[{"batl":[[1,1.69,1033.85]],"ltp":1.67,"tv":14357.29,"id":26354926}]}]}
{"op":"mcm","clk":"11875080571","pt":1723605491983,"mc":[{"id":"1.231659753","rc":[{"batl":[[0,1.68,723.85]],"ltp":1.67,"tv":14357.29,"id":26354926}]}]}
{"op":"mcm","clk":"11875116613","pt":1723606522024,"mc":[{"id":"1.231659753","rc":[{"batb":[[0,2.46,100.49]],"ltp":2.5,"tv":889.0,"id":26354927},{"batl":[[0,1.68,1567.49]],"ltp":1.67,"tv":14357.29,"id":26354926}]}]}
{"op":"mcm","clk":"11875122649","pt":1723606751270,"mc":[{"id":"1.231659753","rc":[{"trd":[[1.67,679.84]],"batb":[[0,1.67,27.76]],"ltp":1.67,"tv":14414.89,"id":26354926}],"tv":15303.89}]}
{"op":"mcm","clk":"11875125424","pt":1723606854201,"mc":[{"id":"1.231659753","rc":[{"batb":[[2,1.26,87.36]],"ltp":2.5,"tv":889.0,"id":26354927}]}]}
{"op":"mcm","clk":"11875138619","pt":1723607039384,"mc":[{"id":"1.231659753","rc":[{"trd":[[1.67,693.14]],"batb":[[0,1.67,14.46]],"ltp":1.67,"tv":14428.19,"id":26354926}],"tv":15317.19}]}
{"op":"mcm","clk":"11875139603","pt":1723607071010,"mc":[{"id":"1.231659753","rc":[{"batb":[[0,2.48,11.71],[1,2.46,100.49],[2,2.42,44.1]],"batl":[[0,2.5,23.1]],"ltp":2.5,"tv":889.0,"id":26354927}]}]}
{"op":"mcm","clk":"11875144904","pt":1723607224665,"mc":[{"id":"1.231659753","rc":[{"batl":[[0,1.68,723.85]],"ltp":1.67,"tv":14428.19,"id":26354926}]}]}
{"op":"mcm","clk":"11875173219","pt":1723608294805,"mc":[{"id":"1.231659753","rc":[{"trd":[[2.48,26.26],[2.5,108.27],[2.52,551.56]],"batb":[[0,2.48,11.71],[1,2.46,27.31]],"batl":[[0,2.5,23.1]],"ltp":2.5,"tv":888.96,"id":26354927},{"trd":[[1.58,747.42],[1.61,1975.1],[1.64,78.25],[1.65,494.38],[1.66,370.87]],"batb":[[0,1.67,4014.46]],"batl":[[0,1.68,890.85]],"ltp":1.67,"tv":14428.14,"id":26354926}],"tv":15317.1}]}
{"op":"mcm","clk":"11875173251","pt":1723608296099,"mc":[{"id":"1.231659753","rc":[{"batb":[[0,2.46,27.31],[1,2.42,44.1],[2,1.26,87.36]],"ltp":2.5,"tv":888.96,"id":26354927}]}]}
{"op":"mcm","clk":"11875173631","pt":1723608306630,"mc":[{"id":"1.231659753","rc":[{"batb":[[0,1.67,4018.46]],"ltp":1.67,"tv":14428.14,"id":26354926}]}]}
{"op":"mcm","clk":"11875174688","pt":1723608337341,"mc":[{"id":"1.231659753","rc":[{"batb":[[0,2.44,101.08],[1,1.27,59.08]],"ltp":2.5,"tv":888.96,"id":26354927}]}]}
{"op":"mcm","clk":"11875175531","pt":1723608362001,"mc":[{"id":"1.231659753","rc":[{"batl":[[0,1.68,337]],"ltp":1.67,"tv":14428.14,"id":26354926}]}]}
{"op":"mcm","clk":"11875212206","pt":1723609576404,"mc":[{"id":"1.231659753","rc":[{"trd":[[1.67,730.06]],"batb":[[0,1.66,71.35]],"batl":[[0,1.68,257]],"ltp":1.67,"tv":14465.06,"id":26354926}],"tv":15354.02}]}
{"op":"mcm","clk":"11875212234","pt":1723609577729,"mc":[{"id":"1.231659753","rc":[{"batb":[[0,2.48,11.71],[1,2.44,101.08],[2,1.27,59.08]],"ltp":2.5,"tv":888.96,"id":26354927}]}]}
{"op":"mcm","clk":"11875212537","pt":1723609590844,"mc":[{"id":"1.231659753","rc":[{"batb":[[0,1.66,75.35]],"ltp":1.67,"tv":14465.06,"id":26354926}]}]}
{"op":"mcm","clk":"11875213152","pt":1723609617359,"mc":[{"id":"1.231659753","rc":[{"batb":[[1,2.46,27.31],[2,2.44,73.77]],"ltp":2.5,"tv":888.96,"id":26354927}]}]}
{"op":"mcm","clk":"11875221004","pt":1723609901821,"mc":[{"id":"1.231659753","rc":[{"batl":[[0,1.68,949.85]],"ltp":1.67,"tv":14465.06,"id":26354926}]}]}
{"op":"mcm","clk":"11875221008","pt":1723609901922,"mc":[{"id":"1.231659753","rc":[{"batl":[[0,1.68,862.85]],"ltp":1.67,"tv":14465.06,"id":26354926}]}]}
{"op":"mcm","clk":"11875235105","pt":1723610340033,"mc":[{"id":"1.231659753","rc":[{"batb":[[0,1.66,5052.38]],"ltp":1.67,"tv":14465.06,"id":26354926}]}]}
{"op":"mcm","clk":"11875235712","pt":1723610357228,"mc":[{"id":"1.231659753","rc":[{"batb":[[1,2.44,101.08],[2,1.27,59.08]],"ltp":2.5,"tv":888.96,"id":26354927}]}]}
{"op":"mcm","clk":"11875238268","pt":1723610451744,"mc":[{"id":"1.231659753","rc":[{"batl":[[0,1.68,309]],"ltp":1.67,"tv":14465.06,"id":26354926}]}]}
{"op":"mcm","clk":"11875239755","pt":1723610515151,"mc":[{"id":"1.231659753","rc":[{"batb":[[0,1.66,10061.35]],"ltp":1.67,"tv":14465.06,"id":26354926}]}]}
{"op":"mcm","clk":"11875239974","pt":1723610522488,"mc":[{"id":"1.231659753","rc":[{"batb":[[0,1.66,5084.32]],"ltp":1.67,"tv":14465.06,"id":26354926}]}]}
{"op":"mcm","clk":"11875247182","pt":1723610804634,"mc":[{"id":"1.231659753","rc":[{"batb":[[0,1.66,75.35]],"batl":[[0,1.68,260]],"ltp":1.67,"tv":14465.06,"id":26354926}]}]}
{"op":"mcm","clk":"11875247525","pt":1723610816487,"mc":[{"id":"1.231659753","rc":[{"batb":[[1,2.46,27.31],[2,2.44,73.77]],"ltp":2.5,"tv":888.96,"id":26354927}]}]}
{"op":"mcm","clk":"11875255748","pt":1723611080198,"mc":[{"id":"1.231659753","rc":[{"trd":[[2.48,28.43]],"batb":[[0,2.48,10.62]],"ltp":2.48,"tv":891.13,"id":26354927}],"tv":15356.19}]}
{"op":"mcm","clk":"11875291459","pt":1723612312906,"mc":[{"id":"1.231659753","rc":[{"trd":[[1.1,14.2],[2.48,28.42],[2.5,108.26],[2.52,551.61]],"batb":[[1,2.46,27.3]],"batl":[[0,2.5,23.1]],"ltp":2.48,"tv":891.17,"id":26354927},{"trd":[[1.58,747.52],[1.61,1975.1],[1.63,120.5],[1.64,78.25],[1.65,494.37],[1.66,370.88]],"batl":[[0,1.68,281.33]],"ltp":1.67,"tv":14465.16,"id":26354926}],"tv":15356.33}]}
{"op":"mcm","clk":"11875291926","pt":1723612329303,"mc":[{"id":"1.231659753","rc":[{"batl":[[0,1.68,260]],"ltp":1.67,"tv":14465.16,"id":26354926}]}]}
{"op":"mcm","clk":"11875305122","pt":1723612500426,"mc":[{"id":"1.231659753","rc":[{"batb":[[2,1.64,92]],"ltp":1.67,"tv":14465.16,"id":26354926}]}]}
{"op":"mcm","clk":"11875317032","pt":1723612836807,"mc":[{"id":"1.231659753","rc":[{"trd":[[2.5,131.36]],"batb":[[0,2.48,22.34]],"batl":[[0,2.52,9952.48],[1,2.56,4],[2,2.58,33.43]],"ltp":2.5,"tv":914.27,"id":26354927},{"trd":[[1.66,667.08]],"batb":[[0,1.66,53.07]],"batl":[[0,1.67,3.94],[1,1.68,199],[2,1.69,1033.85]],"ltp":1.66,"tv":14761.36,"id":26354926}],"tv":15675.63}]}
{"op":"mcm","clk":"11875317053","pt":1723612837266,"mc":[{"id":"1.231659753","rc":[{"batb":[[0,1.66,57.07]],"ltp":1.66,"tv":14761.36,"id":26354926}]}]}
{"op":"mcm","clk":"11875317254","pt":1723612842177,"mc":[{"id":"1.231659753","rc":[{"trd":[[1.66,674.96]],"batb":[[0,1.66,53.13]],"ltp":1.66,"tv":14769.24,"id":26354926}],"tv":15683.51}]}
{"op":"mcm","clk":"11875318183","pt":1723612865438,"mc":[{"id":"1.231659753","rc":[{"batb":[[1,2.44,101.07],[2,1.27,59.08]],"ltp":2.5,"tv":914.27,"id":26354927}]}]}
{"op":"mcm","clk":"11875319321","pt":1723612892652,"mc":[{"id":"1.231659753","rc":[{"batl":[[0,1.68,199],[1,1.69,1033.85],[2,1.7,553.85]],"ltp":1.66,"tv":14769.24,"id":26354926}]}]}
{"op":"mcm","clk":"11875319587","pt":1723612898981,"mc":[{"id":"1.231659753","rc":[{"trd":[[1.66,682.84]],"batb":[[0,1.66,49.19]],"ltp":1.66,"tv":14777.12,"id":26354926}],"tv":15691.39}]}
{"op":"mcm","clk":"11875324080","pt":1723613006770,"mc":[{"id":"1.231659753","rc":[{"trd":[[2.52,561.28]],"batb":[[0,2.48,94.92],[2,1.26,4.06]],"batl":[[0,2.52,9942.81]],"ltp":2.52,"tv":923.94,"id":26354927},{"trd":[[1.65,591.74],[1.66,781.22]],"batb":[[0,1.66,2.58],[1,1.65,2.6]],"batl":[[0,1.68,306.14]],"ltp":1.65,"tv":14972.87,"id":26354926}],"tv":15896.81}]}
{"op":"mcm","clk":"11875324191","pt":1723613010285,"mc":[{"id":"1.231659753","rc":[{"batb":[[1,2.46,27.3],[2,2.44,73.77]],"ltp":2.52,"tv":923.94,"id":26354927},{"batb":[[0,1.65,2.6],[1,1.64,92],[2,1.63,553.85]],"ltp":1.65,"tv":14972.87,"id":26354926}]}]}
{"op":"mcm","clk":"11875324360","pt":1723613015295,"mc":[{"id":"1.231659753","rc":[{"batb":[[2,2.44,100.11]],"ltp":2.52,"tv":923.94,"id":26354927},{"batb":[[1,1.64,151.28]],"ltp":1.65,"tv":14972.87,"id":26354926}]}]}
{"op":"mcm","clk":"11875324471","pt":1723613018889,"mc":[{"id":"1.231659753","rc":[{"batb":[[0,1.65,6.6]],"ltp":1.65,"tv":14972.87,"id":26354926}]}]}
{"op":"mcm","clk":"11875324475","pt":1723613018991,"mc":[{"id":"1.231659753","rc":[{"batb":[[0,1.66,2.58],[1,1.65,6.6],[2,1.64,151.28]],"ltp":1.65,"tv":14972.87,"id":26354926}]}]}
{"op":"mcm","clk":"11875324520","pt":1723613020421,"mc":[{"id":"1.231659753","rc":[{"batb":[[2,2.44,73.77]],"ltp":2.52,"tv":923.94,"id":26354927},{"batb":[[2,1.64,92]],"ltp":1.65,"tv":14972.87,"id":26354926}]}]}
{"op":"mcm","clk":"11875324984","pt":1723613034007,"mc":[{"id":"1.231659753","rc":[{"batb":[[0,1.66,6.58]],"ltp":1.65,"tv":14972.87,"id":26354926}]}]}
{"op":"mcm","clk":"11875325214","pt":1723613039637,"mc":[{"id":"1.231659753","rc":[{"batb":[[0,1.66,23.68]],"batl":[[0,1.67,17.1],[1,1.68,306.14],[2,1.69,1033.85]],"ltp":1.65,"tv":14972.87,"id":26354926}]}]}
{"op":"mcm","clk":"11875330404","pt":1723613188525,"mc":[{"id":"1.231659753","rc":[{"batl":[[2,2.58,0]],"ltp":2.52,"tv":923.94,"id":26354927},{"trd":[[1.66,817.3]],"batb":[[0,1.66,5.63],[1,1.65,4]],"ltp":1.66,"tv":15008.95,"id":26354926}],"tv":15932.9}]}
{"op":"mcm","clk":"11875330576","pt":1723613194218,"mc":[{"id":"1.231659753","rc":[{"batb":[[0,1.66,3211.35]],"ltp":1.66,"tv":15008.95,"id":26354926}]}]}
{"op":"mcm","clk":"11875330620","pt":1723613196004,"mc":[{"id":"1.231659753","rc":[{"batl":[[0,1.68,306.14],[1,1.69,1033.85],[2,1.7,553.85]],"ltp":1.66,"tv":15008.95,"id":26354926}]}]}
{"op":"mcm","clk":"11875330743","pt":1723613200134,"mc":[{"id":"1.231659753","rc":[{"batb":[[0,1.66,3215.35]],"ltp":1.66,"tv":15008.95,"id":26354926}]}]}
{"op":"mcm","clk":"11875349585","pt":1723613785123,"mc":[{"id":"1.231659753","rc":[{"trd":[[2.48,30.42]],"batb":[[0,2.48,93.92]],"ltp":2.48,"tv":925.94,"id":26354927}],"tv":15934.9}]}
{"op":"mcm","clk":"11875355893","pt":1723613971588,"mc":[{"id":"1.231659753","rc":[{"trd":[[1.66,857.31]],"batb":[[0,1.66,3195.35]],"ltp":1.66,"tv":15048.95,"id":26354926}],"tv":15974.9}]}
{"op":"mcm","clk":"11875355910","pt":1723613972457,"mc":[{"id":"1.231659753","rc":[{"batl":[[0,1.67,16.99],[1,1.68,306.14],[2,1.69,1033.85]],"ltp":1.66,"tv":15048.95,"id":26354926}]}]}
{"op":"mcm","clk":"11875357456","pt":1723614025331,"mc":[{"id":"1.231659753","rc":[{"trd":[[1.66,865.31]],"batb":[[0,1.66,3191.35]],"ltp":1.66,"tv":15056.95,"id":26354926}],"tv":15982.9}]}
{"op":"mcm","clk":"11875367438","pt":1723614391960,"mc":[{"id":"1.231659753","rc":[{"trd":[[1.66,875.31]],"batb":[[0,1.66,3186.35]],"ltp":1.66,"tv":15066.95,"id":26354926}],"tv":15992.9}]}
{"op":"mcm","clk":"11875374524","pt":1723614652246,"mc":[{"id":"1.231659753","rc":[{"batl":[[0,1.67,39.54]],"ltp":1.66,"tv":15066.95,"id":26354926}]}]}
{"op":"mcm","clk":"11875376203","pt":1723614709789,"mc":[{"id":"1.231659753","rc":[{"trd":[[1.66,894.01]],"batb":[[0,1.66,3177]],"ltp":1.66,"tv":15085.65,"id":26354926}],"tv":16011.6}]}
{"op":"mcm","clk":"11875385553","pt":1723615061455,"mc":[{"id":"1.231659753","rc":[{"trd":[[1.66,904.01]],"batb":[[0,1.66,3172]],"ltp":1.66,"tv":15095.65,"id":26354926}],"tv":16021.6}]}
{"op":"mcm","clk":"11875399114","pt":1723615458179,"mc":[{"id":"1.231659753","rc":[{"trd":[[2.48,30.48],[2.5,131.42],[2.52,561.28]],"batb":[[0,2.48,93.92],[1,2.46,27.36]],"ltp":2.48,"tv":926.05,"id":26354927},{"trd":[[1.58,747.52],[1.61,1975.1],[1.64,78.25],[1.65,591.83],[1.66,944],[1.67,730.07]],"batb":[[0,1.66,3152]],"batl":[[0,1.67,39.54]],"ltp":1.66,"tv":15135.74,"id":26354926}],"tv":16061.79}]}
{"op":"mcm","clk":"11875415828","pt":1723616079071,"mc":[{"id":"1.231659753","rc":[{"trd":[[2.48,50.48]],"batb":[[0,2.48,83.91]],"ltp":2.48,"tv":946.05,"id":26354927}],"tv":16081.79}]}
{"op":"mcm","clk":"11875416486","pt":1723616108520,"mc":[{"id":"1.231659753","rc":[{"trd":[[1.66,7248]],"batb":[[0,1.65,4],[1,1.64,92],[2,1.63,553.85]],"batl":[[0,1.66,3079.25],[1,1.67,39.54],[2,1.68,306.14]],"ltp":1.66,"tv":21439.74,"id":26354926}],"tv":22385.79}]}
{"op":"mcm","clk":"11875416572","pt":1723616111231,"mc":[{"id":"1.231659753","rc":[{"batb":[[2,2.44,100.11]],"ltp":2.48,"tv":946.05,"id":26354927},{"batb":[[1,1.64,151.28]],"ltp":1.66,"tv":21439.74,"id":26354926}]}]}
{"op":"mcm","clk":"11875417205","pt":1723616138338,"mc":[{"id":"1.231659753","rc":[{"batb":[[0,2.48,110.76],[1,2.44,100.11],[2,1.26,4.07]],"ltp":2.48,"tv":946.05,"id":26354927}]}]}
{"op":"mcm","clk":"11875419734","pt":1723616248757,"mc":[{"id":"1.231659753","rc":[{"batl":[[0,1.66,3279.25]],"ltp":1.66,"tv":21439.74,"id":26354926}]}]}
{"op":"mcm","clk":"11875419881","pt":1723616256286,"mc":[{"id":"1.231659753","rc":[{"trd":[[2.52,689.61]],"batl":[[0,2.52,9814.48]],"ltp":2.52,"tv":1074.38,"id":26354927},{"trd":[[1.65,795.83]],"batb":[[0,1.64,151.28],[1,1.63,553.85],[2,1.62,553.85]],"batl":[[0,1.66,3079.25]],"ltp":1.65,"tv":21643.74,"id":26354926}],"tv":22718.12}]}
{"op":"mcm","clk":"11875420211","pt":1723616269402,"mc":[{"id":"1.231659753","rc":[{"batb":[[0,1.65,4],[1,1.64,151.28],[2,1.63,553.85]],"ltp":1.65,"tv":21643.74,"id":26354926}]}]}
{"op":"mcm","clk":"11875429420","pt":1723616686242,"mc":[{"id":"1.231659753","rc":[{"batb":[[0,2.5,1073.79],[1,2.48,110.76],[2,2.44,26.34]],"ltp":2.52,"tv":1074.38,"id":26354927},{"batl":[[0,1.66,3108.25],[2,1.68,277.14]],"ltp":1.65,"tv":21643.74,"id":26354926}]}]}
{"op":"mcm","clk":"11875429480","pt":1723616688841,"mc":[{"id":"1.231659753","rc":[{"batb":[[2,1.26,4.07]],"ltp":2.52,"tv":1074.38,"id":26354927},{"batb":[[1,1.64,92]],"ltp":1.65,"tv":21643.74,"id":26354926}]}]}
{"op":"mcm","clk":"11875429854","pt":1723616707359,"mc":[{"id":"1.231659753","rc":[{"batl":[[1,1.67,1442.01]],"ltp":1.65,"tv":21643.74,"id":26354926}]}]}
{"op":"mcm","clk":"11875430037","pt":1723616715353,"mc":[{"id":"1.231659753","rc":[{"batl":[[1,1.67,1419.46]],"ltp":1.65,"tv":21643.74,"id":26354926}]}]}
{"op":"mcm","clk":"11875431464","pt":1723616771257,"mc":[{"id":"1.231659753","rc":[{"trd":[[2.52,739.37]],"batl":[[0,2.52,9764.72]],"ltp":2.52,"tv":1124.14,"id":26354927},{"trd":[[1.65,879.83]],"batb":[[0,1.64,92],[1,1.63,553.85],[2,1.62,553.85]],"ltp":1.65,"tv":21727.74,"id":26354926}],"tv":22851.88}]}
{"op":"mcm","clk":"11875431706","pt":1723616778652,"mc":[{"id":"1.231659753","rc":[{"trd":[[2.52,739.51]],"batl":[[0,2.52,9764.58]],"ltp":2.52,"tv":1124.28,"id":26354927},{"trd":[[1.65,880.04]],"ltp":1.65,"tv":21727.95,"id":26354926}],"tv":22852.23}]}
{"op":"mcm","clk":"11875431734","pt":1723616779671,"mc":[{"id":"1.231659753","rc":[{"trd":[[1.66,7248.44]],"batl":[[0,1.66,3108.03]],"ltp":1.66,"tv":21728.38,"id":26354926}],"tv":22852.67}]}
{"op":"mcm","clk":"11875431847","pt":1723616782733,"mc":[{"id":"1.231659753","rc":[{"batb":[[0,1.65,4],[1,1.64,92],[2,1.63,553.85]],"ltp":1.66,"tv":21728.38,"id":26354926}]}]}
{"op":"mcm","clk":"11875435754","pt":1723616938935,"mc":[{"id":"1.231659753","rc":[{"trd":[[2.5,135.42]],"batb":[[0,2.5,1071.79]],"ltp":2.5,"tv":1128.28,"id":26354927}],"tv":22856.67}]}
{"op":"mcm","clk":"11875439977","pt":1723617088015,"mc":[{"id":"1.231659753","rc":[{"trd":[[2.52,749.99]],"batl":[[0,2.52,9754.1]],"ltp":2.52,"tv":1138.76,"id":26354927},{"trd":[[1.65,904.04]],"batb":[[0,1.64,92],[1,1.63,553.85],[2,1.62,553.85]],"ltp":1.65,"tv":21752.38,"id":26354926}],"tv":22891.15}]}
{"op":"mcm","clk":"11875440301","pt":1723617099716,"mc":[{"id":"1.231659753","rc":[{"batb":[[0,1.65,4],[1,1.64,92],[2,1.63,553.85]],"ltp":1.65,"tv":21752.38,"id":26354926}]}]}
{"op":"mcm","clk":"11875445791","pt":1723617304035,"mc":[{"id":"1.231659753","rc":[{"trd":[[2.52,780.11]],"batl":[[0,2.52,9723.98]],"ltp":2.52,"tv":1168.88,"id":26354927},{"trd":[[1.65,958.04]],"batb":[[0,1.64,92],[1,1.63,553.85],[2,1.62,553.85]],"ltp":1.65,"tv":21806.38,"id":26354926}],"tv":22975.27}]}
{"op":"mcm","clk":"11875448111","pt":1723617385410,"mc":[{"id":"1.231659753","rc":[{"trd":[[2.52,783.38]],"batl":[[0,2.52,9720.71]],"ltp":2.52,"tv":1172.15,"id":26354927},{"trd":[[1.65,963.04]],"ltp":1.65,"tv":21811.38,"id":26354926}],"tv":22983.54}]}
{"op":"mcm","clk":"11875450515","pt":1723617470017,"mc":[{"id":"1.231659753","rc":[{"trd":[[1.66,12648.44]],"batl":[[0,1.66,408.03]],"ltp":1.66,"tv":27211.38,"id":26354926}],"tv":28383.54}]}
{"op":"mcm","clk":"11875450690","pt":1723617475913,"mc":[{"id":"1.231659753","rc":[{"trd":[[2.52,783.53]],"batl":[[0,2.52,9720.56]],"ltp":2.52,"tv":1172.3,"id":26354927},{"trd":[[1.65,963.27]],"ltp":1.65,"tv":27211.62,"id":26354926}],"tv":28383.92}]}
{"op":"mcm","clk":"11875450706","pt":1723617476520,"mc":[{"id":"1.231659753","rc":[{"trd":[[1.66,12648.92]],"batl":[[0,1.66,407.79]],"ltp":1.66,"tv":27212.1,"id":26354926}],"tv":28384.4}]}
{"op":"mcm","clk":"11875453460","pt":1723617557284,"mc":[{"id":"1.231659753","rc":[{"batb":[[0,2.5,999.79]],"ltp":2.52,"tv":1172.3,"id":26354927},{"trd":[[1.66,13464.5]],"batb":[[0,1.66,2797.93],[1,1.64,92],[2,1.63,553.85]],"batl":[[0,1.67,1527.24],[1,1.68,277.14],[2,1.69,480]],"ltp":1.66,"tv":28027.68,"id":26354926}],"tv":29199.98}]}
{"op":"mcm","clk":"11875453670","pt":1723617562712,"mc":[{"id":"1.231659753","rc":[{"trd":[[1.66,13464.61]],"batb":[[0,1.66,2797.88]],"ltp":1.66,"tv":28027.78,"id":26354926}],"tv":29200.09}]}
{"op":"mcm","clk":"11875453728","pt":1723617564610,"mc":[{"id":"1.231659753","rc":[{"trd":[[1.67,730.19]],"batl":[[0,1.67,1527.18]],"ltp":1.67,"tv":28027.91,"id":26354926}],"tv":29200.21}]}
{"op":"mcm","clk":"11875453841","pt":1723617568030,"mc":[{"id":"1.231659753","rc":[{"batl":[[0,1.67,1419.4]],"ltp":1.67,"tv":28027.91,"id":26354926}]}]}
{"op":"mcm","clk":"11875454909","pt":1723617605743,"mc":[{"id":"1.231659753","rc":[{"batb":[[0,2.48,38.18],[1,1.26,4.07],[2,1.25,100]],"ltp":2.52,"tv":1172.3,"id":26354927},{"batl":[[1,1.68,170]],"ltp":1.67,"tv":28027.91,"id":26354926}]}]}
{"op":"mcm","clk":"11875455651","pt":1723617634379,"mc":[{"id":"1.231659753","rc":[{"batb":[[0,2.48,11.33],[1,2.46,27.36],[2,1.26,4.07]],"ltp":2.52,"tv":1172.3,"id":26354927}]}]}
{"op":"mcm","clk":"11875456157","pt":1723617655137,"mc":[{"id":"1.231659753","rc":[{"batb":[[0,2.48,1013.12]],"ltp":2.52,"tv":1172.3,"id":26354927}]}]}
{"op":"mcm","clk":"11875480040","pt":1723618290242,"mc":[{"id":"1.231659753","rc":[{"batl":[[1,1.68,481.54]],"ltp":1.67,"tv":28027.91,"id":26354926}]}]}
{"op":"mcm","clk":"11875480136","pt":1723618294227,"mc":[{"id":"1.231659753","rc":[{"batl":[[0,1.67,1450.55]],"ltp":1.67,"tv":28027.91,"id":26354926}]}]}
{"op":"mcm","clk":"11875480221","pt":1723618298217,"mc":[{"id":"1.231659753","rc":[{"batl":[[0,1.67,1481.7]],"ltp":1.67,"tv":28027.91,"id":26354926}]}]}
{"op":"mcm","clk":"11875480535","pt":1723618313430,"mc":[{"id":"1.231659753","rc":[{"batl":[[2,1.69,511.15]],"ltp":1.67,"tv":28027.91,"id":26354926}]}]}
{"op":"mcm","clk":"11875480848","pt":1723618329028,"mc":[{"id":"1.231659753","rc":[{"trd":[[1.66,13526.91]],"batb":[[0,1.66,2766.73]],"ltp":1.66,"tv":28090.21,"id":26354926}],"tv":29262.51}]}
{"op":"mcm","clk":"11875481069","pt":1723618339180,"mc":[{"id":"1.231659753","rc":[{"batl":[[0,1.67,1589.48]],"ltp":1.66,"tv":28090.21,"id":26354926}]}]}
{"op":"mcm","clk":"11875482143","pt":1723618387400,"mc":[{"id":"1.231659753","rc":[{"batl":[[1,1.68,170]],"ltp":1.66,"tv":28090.21,"id":26354926}]}]}
{"op":"mcm","clk":"11875482233","pt":1723618391393,"mc":[{"id":"1.231659753","rc":[{"batl":[[0,1.67,1558.33]],"ltp":1.66,"tv":28090.21,"id":26354926}]}]}
{"op":"mcm","clk":"11875486690","pt":1723618597802,"mc":[{"id":"1.231659753","rc":[{"trd":[[1.66,13806.91]],"batb":[[0,1.66,2626.73]],"ltp":1.66,"tv":28370.21,"id":26354926}],"tv":29542.51}]}
{"op":"mcm","clk":"11875492818","pt":1723618827393,"mc":[{"id":"1.231659753","rc":[{"trd":[[1.1,14.22],[2.48,50.55],[2.5,135.49],[2.52,784.49]],"batb":[[0,2.5,72],[1,2.48,1013.15],[2,2.46,27.4]],"batl":[[0,2.52,9720.56]],"ltp":2.52,"tv":1173.43,"id":26354927},{"trd":[[1.58,749.22],[1.61,1975.15],[1.62,9758.31],[1.63,120.51],[1.64,78.29],[1.65,963.37],[1.66,13807.22],[1.67,779.17],[1.73,4.76],[1.77,0.91]],"batl":[[0,1.67,1533.89]],"ltp":1.67,"tv":28421.41,"id":26354926}],"tv":29594.84}]}
{"op":"mcm","clk":"11875493073","pt":1723618835705,"mc":[{"id":"1.231659753","rc":[{"batb":[[2,1.26,4.07]],"ltp":2.52,"tv":1173.43,"id":26354927},{"batl":[[0,1.67,1426.11]],"ltp":1.67,"tv":28421.41,"id":26354926}]}]}
{"op":"mcm","clk":"11875493714","pt":1723618857208,"mc":[{"id":"1.231659753","rc":[{"batl":[[1,1.68,160]],"ltp":1.67,"tv":28421.41,"id":26354926}]}]}
{"op":"mcm","clk":"11875499447","pt":1723619067474,"mc":[{"id":"1.231659753","rc":[{"trd":[[2.48,52.55],[2.5,279.49]],"batb":[[0,2.48,1084.73],[1,1.26,4.07],[2,1.25,100]],"ltp":2.48,"tv":1319.43,"id":26354927},{"batb":[[0,1.66,2735.16]],"ltp":1.67,"tv":28421.41,"id":26354926}],"tv":29740.84}]}
{"op":"mcm","clk":"11875499680","pt":1723619077073,"mc":[{"id":"1.231659753","rc":[{"batb":[[1,2.46,27.4],[2,1.26,4.07]],"ltp":2.48,"tv":1319.43,"id":26354927}]}]}
{"op":"mcm","clk":"11875500227","pt":1723619095708,"mc":[{"id":"1.231659753","rc":[{"trd":[[2.48,72.55]],"batb":[[0,2.48,1074.73]],"ltp":2.48,"tv":1339.43,"id":26354927}],"tv":29760.84}]}
{"op":"mcm","clk":"11875500273","pt":1723619097199,"mc":[{"id":"1.231659753","rc":[{"batb":[[0,2.48,1074.37]],"ltp":2.48,"tv":1339.43,"id":26354927}]}]}
{"op":"mcm","clk":"11875500334","pt":1723619099718,"mc":[{"id":"1.231659753","rc":[{"batl":[[0,2.5,5.79],[1,2.52,9720.56],[2,2.56,4]],"ltp":2.48,"tv":1339.43,"id":26354927}]}]}
{"op":"mcm","clk":"11875500642","pt":1723619109740,"mc":[{"id":"1.231659753","rc":[{"batl":[[0,1.67,2427.9]],"ltp":1.67,"tv":28421.41,"id":26354926}]}]}
{"op":"mcm","clk":"11875501002","pt":1723619122740,"mc":[{"id":"1.231659753","rc":[{"batb":[[0,2.48,1078.37]],"ltp":2.48,"tv":1339.43,"id":26354927}]}]}
{"op":"mcm","clk":"11875501051","pt":1723619124326,"mc":[{"id":"1.231659753","rc":[{"batb":[[0,2.48,1105.25],[1,1.26,4.07],[2,1.25,100]],"ltp":2.48,"tv":1339.43,"id":26354927}]}]}
{"op":"mcm","clk":"11875508365","pt":1723619340768,"mc":[{"id":"1.231659753","rc":[{"batl":[[0,1.67,2435.9],[1,1.68,168]],"ltp":1.67,"tv":28421.41,"id":26354926}]}]}
{"op":"mcm","clk":"11875508382","pt":1723619341180,"mc":[{"id":"1.231659753","rc":[{"batl":[[2,1.69,519.15]],"ltp":1.67,"tv":28421.41,"id":26354926}]}]}
{"op":"mcm","clk":"11875509331","pt":1723619369460,"mc":[{"id":"1.231659753","rc":[{"batl":[[1,1.68,168.98]],"ltp":1.67,"tv":28421.41,"id":26354926}]}]}
{"op":"mcm","clk":"11875509478","pt":1723619374103,"mc":[{"id":"1.231659753","rc":[{"batl":[[1,1.68,168]],"ltp":1.67,"tv":28421.41,"id":26354926}]}]}
{"op":"mcm","clk":"11875523695","pt":1723619793291,"mc":[{"id":"1.231659753","rc":[{"batb":[[1,2.46,9.67],[2,1.26,4.07]],"ltp":2.48,"tv":1339.43,"id":26354927},{"batb":[[1,1.65,15.51],[2,1.64,92]],"ltp":1.67,"tv":28421.41,"id":26354926}]}]}
{"op":"mcm","clk":"11875527701","pt":1723619914514,"mc":[{"id":"1.231659753","rc":[{"trd":[[1.66,13817.22]],"batb":[[0,1.66,2730.16]],"ltp":1.66,"tv":28431.41,"id":26354926}],"tv":29770.84}]}
{"op":"mcm","clk":"11875528074","pt":1723619926222,"mc":[{"id":"1.231659753","rc":[{"trd":[[1.67,881.53]],"batl":[[0,1.67,2384.72]],"ltp":1.67,"tv":28533.77,"id":26354926}],"tv":29873.21}]}
{"op":"mcm","clk":"11875536012","pt":1723620167822,"mc":[{"id":"1.231659753","rc":[{"trd":[[1.66,13818.92]],"batb":[[0,1.66,2729.31]],"ltp":1.66,"tv":28535.47,"id":26354926}],"tv":29874.91}]}
{"op":"mcm","clk":"11875542108","pt":1723620424608,"mc":[{"id":"1.231659753","rc":[{"trd":[[1.67,883.19]],"batl":[[0,1.67,2383.89]],"ltp":1.67,"tv":28537.13,"id":26354926}],"tv":29876.57}]}
{"op":"mcm","clk":"11875548014","pt":1723620694533,"mc":[{"id":"1.231659753","rc":[{"batb":[[0,2.48,1032.67]],"batl":[[0,2.5,77.79]],"ltp":2.48,"tv":1339.43,"id":26354927},{"trd":[[1.67,5588.67]],"batb":[[0,1.67,1616.11],[1,1.66,2729.31],[2,1.65,15.51]],"batl":[[0,1.68,275.14],[1,1.69,519.15],[2,1.7,31.15]],"ltp":1.67,"tv":33242.61,"id":26354926}],"tv":34582.05}]}
{"op":"mcm","clk":"11875548042","pt":1723620695816,"mc":[{"id":"1.231659753","rc":[{"batb":[[0,2.48,1028.67]],"ltp":2.48,"tv":1339.43,"id":26354927},{"batb":[[1,1.66,2737.36]],"ltp":1.67,"tv":33242.61,"id":26354926}]}]}
{"op":"mcm","clk":"11875548166","pt":1723620701755,"mc":[{"id":"1.231659753","rc":[{"trd":[[1.67,5588.78]],"batb":[[0,1.67,1616.06]],"ltp":1.67,"tv":33242.71,"id":26354926}],"tv":34582.15}]}
{"op":"mcm","clk":"11875548228","pt":1723620703654,"mc":[{"id":"1.231659753","rc":[{"trd":[[1.68,0.12]],"batl":[[0,1.68,275.08]],"ltp":1.68,"tv":33242.83,"id":26354926}],"tv":34582.27}]}
{"op":"mcm","clk":"11875548365","pt":1723620709540,"mc":[{"id":"1.231659753","rc":[{"batl":[[0,2.5,81.79]],"ltp":2.48,"tv":1339.43,"id":26354927}]}]}
{"op":"mcm","clk":"11875548688","pt":1723620721671,"mc":[{"id":"1.231659753","rc":[{"trd":[[1.67,8293.64]],"batb":[[0,1.67,263.63]],"ltp":1.67,"tv":35947.69,"id":26354926}],"tv":37287.13}]}
{"op":"mcm","clk":"11875548851","pt":1723620727885,"mc":[{"id":"1.231659753","rc":[{"trd":[[1.67,8293.74]],"batb":[[0,1.67,263.58]],"ltp":1.67,"tv":35947.8,"id":26354926}],"tv":37287.24}]}
{"op":"mcm","clk":"11875548880","pt":1723620728864,"mc":[{"id":"1.231659753","rc":[{"trd":[[1.68,0.24]],"batl":[[0,1.68,275.02]],"ltp":1.68,"tv":35947.92,"id":26354926}],"tv":37287.36}]}
{"op":"mcm","clk":"11875549192","pt":1723620740777,"mc":[{"id":"1.231659753","rc":[{"trd":[[1.67,8311.78]],"batb":[[0,1.67,254.56]],"ltp":1.67,"tv":35965.96,"id":26354926}],"tv":37305.4}]}
{"op":"mcm","clk":"11875549214","pt":1723620741190,"mc":[{"id":"1.231659753","rc":[{"batl":[[0,2.5,77.79]],"ltp":2.48,"tv":1339.43,"id":26354927}]}]}
{"op":"mcm","clk":"11875549362","pt":1723620747901,"mc":[{"id":"1.231659753","rc":[{"batb":[[0,2.48,26.88]],"ltp":2.48,"tv":1339.43,"id":26354927}]}]}
{"op":"mcm","clk":"11875549365","pt":1723620748004,"mc":[{"id":"1.231659753","rc":[{"batb":[[0,1.67,362.34],[1,1.66,116.48]],"batl":[[0,1.68,167.88]],"ltp":1.67,"tv":35965.96,"id":26354926}]}]}
{"op":"mcm","clk":"11875549550","pt":1723620754972,"mc":[{"id":"1.231659753","rc":[{"batl":[[0,2.5,81.79]],"ltp":2.48,"tv":1339.43,"id":26354927}]}]}
{"op":"mcm","clk":"11875550459","pt":1723620793319,"mc":[{"id":"1.231659753","rc":[{"batb":[[0,2.46,9.67],[1,2.44,27.4]],"ltp":2.48,"tv":1339.43,"id":26354927}]}]}
{"op":"mcm","clk":"11875553016","pt":1723620900466,"mc":[{"id":"1.231659753","rc":[{"batl":[[0,1.68,189.21]],"ltp":1.67,"tv":35965.96,"id":26354926}]}]}
{"op":"mcm","clk":"11875555813","pt":1723621010867,"mc":[{"id":"1.231659753","rc":[{"batl":[[0,1.68,289.21]],"ltp":1.67,"tv":35965.96,"id":26354926}]}]}
{"op":"mcm","clk":"11875556481","pt":1723621036292,"mc":[{"id":"1.231659753","rc":[{"batb":[[0,2.46,37.07],[1,1.26,4.07],[2,1.25,100]],"ltp":2.48,"tv":1339.43,"id":26354927}]}]}
{"op":"mcm","clk":"11875558230","pt":1723621107217,"mc":[{"id":"1.231659753","rc":[{"trd":[[1.67,8311.98],[1.68,0.44]],"batb":[[0,1.67,362.24]],"batl":[[0,1.68,289.11]],"ltp":1.68,"tv":35966.36,"id":26354926}],"tv":37305.8}]}
{"op":"mcm","clk":"11875560407","pt":1723621194111,"mc":[{"id":"1.231659753","rc":[{"trd":[[1.67,8462.18]],"batb":[[0,1.67,287.14]],"ltp":1.67,"tv":36116.56,"id":26354926}],"tv":37456.0}]}
{"op":"mcm","clk":"11875573598","pt":1723621706883,"mc":[{"id":"1.231659753","rc":[{"trd":[[1.67,8470.18]],"batb":[[0,1.67,283.14]],"ltp":1.67,"tv":36124.56,"id":26354926}],"tv":37464.0}]}
{"op":"mcm","clk":"11875576542","pt":1723621811130,"mc":[{"id":"1.231659753","rc":[{"trd":[[1.67,8480.18]],"batb":[[0,1.67,278.14]],"ltp":1.67,"tv":36134.56,"id":26354926}],"tv":37474.0}]}
{"op":"mcm","clk":"11875576756","pt":1723621819343,"mc":[{"id":"1.231659753","rc":[{"batl":[[0,1.68,292.11]],"ltp":1.67,"tv":36134.56,"id":26354926}]}]}
{"op":"mcm","clk":"11875578406","pt":1723621879216,"mc":[{"id":"1.231659753","rc":[{"trd":[[1.67,8500.18]],"batb":[[0,1.67,268.14]],"ltp":1.67,"tv":36154.56,"id":26354926}],"tv":37494.0}]}
{"op":"mcm","clk":"11875579596","pt":1723621916521,"mc":[{"id":"1.231659753","rc":[{"batb":[[1,1.66,216.48]],"ltp":1.67,"tv":36154.56,"id":26354926}]}]}
{"op":"mcm","clk":"11875579677","pt":1723621919527,"mc":[{"id":"1.231659753","rc":[{"trd":[[1.67,8700.18]],"batb":[[0,1.67,168.14]],"batl":[[0,1.68,192.11]],"ltp":1.67,"tv":36354.56,"id":26354926}],"tv":37694.0}]}
{"op":"mcm","clk":"11875581069","pt":1723621973706,"mc":[{"id":"1.231659753","rc":[{"batl":[[0,1.68,1193.9]],"ltp":1.67,"tv":36354.56,"id":26354926}]}]}
{"op":"mcm","clk":"11875581560","pt":1723621994830,"mc":[{"id":"1.231659753","rc":[{"batb":[[0,2.46,487.88]],"ltp":2.48,"tv":1339.43,"id":26354927},{"batb":[[0,1.67,60.36]],"ltp":1.67,"tv":36354.56,"id":26354926}]}]}
{"op":"mcm","clk":"11875589775","pt":1723622312817,"mc":[{"id":"1.231659753","rc":[{"batl":[[0,2.5,5.79]],"ltp":2.48,"tv":1339.43,"id":26354927},{"batb":[[0,1.66,216.48],[1,1.65,15.51],[2,1.64,92]],"batl":[[0,1.67,4653.58],[1,1.68,1193.9],[2,1.69,519.15]],"ltp":1.67,"tv":36354.56,"id":26354926}]}]}
{"op":"mcm","clk":"11875589917","pt":1723622318643,"mc":[{"id":"1.231659753","rc":[{"batb":[[0,2.48,4],[1,2.46,487.88],[2,1.26,4.07]],"ltp":2.48,"tv":1339.43,"id":26354927},{"batb":[[0,1.66,108.05]],"batl":[[0,1.67,4657.58]],"ltp":1.67,"tv":36354.56,"id":26354926}]}]}
{"op":"mcm","clk":"11875590134","pt":1723622327229,"mc":[{"id":"1.231659753","rc":[{"batb":[[0,2.48,30.88],[1,2.46,460.48]],"ltp":2.48,"tv":1339.43,"id":26354927}]}]}
{"op":"mcm","clk":"11875590999","pt":1723622358537,"mc":[{"id":"1.231659753","rc":[{"batb":[[1,2.46,9.67]],"ltp":2.48,"tv":1339.43,"id":26354927},{"batl":[[1,1.68,192.11]],"ltp":1.67,"tv":36354.56,"id":26354926}]}]}
{"op":"mcm","clk":"11875592678","pt":1723622418418,"mc":[{"id":"1.231659753","rc":[{"trd":[[1.1,14.21],[2.48,72.55],[2.5,279.48],[2.52,784.43]],"batb":[[0,2.48,30.87],[1,2.46,9.67],[2,1.26,4.07]],"batl":[[0,2.5,5.8]],"ltp":2.48,"tv":1339.35,"id":26354927},{"trd":[[1.58,749.12],[1.61,1975.15],[1.63,120.51],[1.64,78.3],[1.65,963.34],[1.66,13818.92],[1.67,8700.15],[1.73,4.76]],"batb":[[1,1.65,15.52]],"ltp":1.67,"tv":36354.41,"id":26354926}],"tv":37693.76}]}
{"op":"mcm","clk":"11875607838","pt":1723622902788,"mc":[{"id":"1.231659753","rc":[{"trd":[[1.66,13903.92]],"batb":[[0,1.66,65.55]],"ltp":1.66,"tv":36439.41,"id":26354926}],"tv":37778.76}]}
{"op":"mcm","clk":"11875608907","pt":1723622931557,"mc":[{"id":"1.231659753","rc":[{"batb":[[0,1.66,108.05]],"ltp":1.66,"tv":36439.41,"id":26354926}]}]}
{"op":"mcm","clk":"11875609803","pt":1723622954655,"mc":[{"id":"1.231659753","rc":[{"trd":[[1.67,8785.15]],"batb":[[0,1.66,65.55]],"batl":[[0,1.67,4615.08]],"ltp":1.67,"tv":36524.41,"id":26354926}],"tv":37863.76}]}
{"op":"mcm","clk":"11875627775","pt":1723623236242,"mc":[{"id":"1.231659753","rc":[{"trd":[[1.66,13907.92]],"batb":[[0,1.66,63.55]],"ltp":1.66,"tv":36528.41,"id":26354926}],"tv":37867.76}]}
{"op":"mcm","clk":"11875633440","pt":1723623376829,"mc":[{"id":"1.231659753","rc":[{"batb":[[0,2.48,1032.66]],"ltp":2.48,"tv":1339.35,"id":26354927}]}]}
{"op":"mcm","clk":"11875641060","pt":1723623591641,"mc":[{"id":"1.231659753","rc":[{"batl":[[1,1.68,32.33]],"ltp":1.66,"tv":36528.41,"id":26354926}]}]}
{"op":"mcm","clk":"11875641458","pt":1723623603669,"mc":[{"id":"1.231659753","rc":[{"trd":[[2.5,285.28]],"batb":[[0,2.5,72],[1,2.48,1032.66],[2,2.46,9.67]],"batl":[[0,2.52,9720.56],[1,2.56,4],[2,2.56,0]],"ltp":2.5,"tv":1345.14,"id":26354927},{"trd":[[1.66,14043.75]],"batb":[[0,1.65,124.61],[1,1.64,92],[2,1.63,160]],"batl":[[0,1.66,82.73],[1,1.67,4615.08],[2,1.68,32.33]],"ltp":1.66,"tv":36664.23,"id":26354926}],"tv":38009.38}]}
{"op":"mcm","clk":"11875641934","pt":1723623610241,"mc":[{"id":"1.231659753","rc":[{"trd":[[1.66,14057.45]],"batb":[[0,1.65,118.52]],"batl":[[0,1.66,75.88]],"ltp":1.66,"tv":36677.93,"id":26354926}],"tv":38023.08}]}
{"op":"mcm","clk":"11875643337","pt":1723623622267,"mc":[{"id":"1.231659753","rc":[{"batb":[[1,2.48,30.87]],"ltp":2.5,"tv":1345.14,"id":26354927}]}]}
{"op":"mcm","clk":"11875646656","pt":1723623668604,"mc":[{"id":"1.231659753","rc":[{"batl":[[2,1.68,192.33]],"ltp":1.66,"tv":36677.93,"id":26354926}]}]}
{"op":"mcm","clk":"11875646915","pt":1723623671425,"mc":[{"id":"1.231659753","rc":[{"trd":[[1.65,963.6]],"batb":[[0,1.65,118.39]],"ltp":1.65,"tv":36678.19,"id":26354926}],"tv":38023.34}]}
{"op":"mcm","clk":"11875647094","pt":1723623673330,"mc":[{"id":"1.231659753","rc":[{"batl":[[0,1.66,101.72]],"ltp":1.65,"tv":36678.19,"id":26354926}]}]}
{"op":"mcm","clk":"11875649432","pt":1723623696873,"mc":[{"id":"1.231659753","rc":[{"trd":[[2.5,289.28]],"batb":[[0,2.5,70]],"ltp":2.5,"tv":1349.14,"id":26354927}],"tv":38027.34}]}
{"op":"mcm","clk":"11875655235","pt":1723623861730,"mc":[{"id":"1.231659753","rc":[{"batl":[[1,1.67,4623.08]],"ltp":1.65,"tv":36678.19,"id":26354926}]}]}
{"op":"mcm","clk":"11875655287","pt":1723623862758,"mc":[{"id":"1.231659753","rc":[{"batl":[[0,1.66,109.72]],"ltp":1.65,"tv":36678.19,"id":26354926}]}]}
{"op":"mcm","clk":"11875655583","pt":1723623869876,"mc":[{"id":"1.231659753","rc":[{"trd":[[1.65,979.6]],"batb":[[0,1.65,110.39],[1,1.64,100.05]],"ltp":1.65,"tv":36694.19,"id":26354926}],"tv":38043.34}]}
{"op":"mcm","clk":"11875655601","pt":1723623870345,"mc":[{"id":"1.231659753","rc":[{"batb":[[0,1.65,109.09]],"ltp":1.65,"tv":36694.19,"id":26354926}]}]}
{"op":"mcm","clk":"11875666815","pt":1723624210058,"mc":[{"id":"1.231659753","rc":[{"batb":[[0,2.5,77.79],[2,1.26,4.07]],"ltp":2.5,"tv":1349.14,"id":26354927}]}]}
{"op":"mcm","clk":"11875667865","pt":1723624244194,"mc":[{"id":"1.231659753","rc":[{"batl":[[0,1.66,309.72]],"ltp":1.65,"tv":36694.19,"id":26354926}]}]}
{"op":"mcm","clk":"11875671614","pt":1723624335272,"mc":[{"id":"1.231659753","rc":[{"trd":[[1.66,14057.89]],"batl":[[0,1.66,309.49]],"ltp":1.66,"tv":36694.63,"id":26354926}],"tv":38043.78}]}
{"op":"mcm","clk":"11875673447","pt":1723624377018,"mc":[{"id":"1.231659753","rc":[{"trd":[[2.5,297.28]],"batb":[[0,2.5,73.79]],"ltp":2.5,"tv":1357.14,"id":26354927}],"tv":38051.78}]}
{"op":"mcm","clk":"11875674795","pt":1723624409497,"mc":[{"id":"1.231659753","rc":[{"batl":[[2,3,1]],"ltp":2.5,"tv":1357.14,"id":26354927}]}]}
{"op":"mcm","clk":"11875675763","pt":1723624430011,"mc":[{"id":"1.231659753","rc":[{"batb":[[0,1.65,1511.56]],"ltp":1.66,"tv":36694.63,"id":26354926}]}]}
{"op":"mcm","clk":"11875690117","pt":1723624770306,"mc":[{"id":"1.231659753","rc":[{"trd":[[1.66,14089.89]],"batl":[[0,1.66,293.49]],"ltp":1.66,"tv":36726.64,"id":26354926}],"tv":38083.78}]}
{"op":"mcm","clk":"11875699417","pt":1723624962326,"mc":[{"id":"1.231659753","rc":[{"batl":[[2,1.68,171]],"ltp":1.66,"tv":36726.64,"id":26354926}]}]}
{"op":"mcm","clk":"11875710907","pt":1723625184426,"mc":[{"id":"1.231659753","rc":[{"trd":[[1.65,1079.6]],"batb":[[0,1.65,1461.56]],"ltp":1.65,"tv":36826.64,"id":26354926}],"tv":38183.78}]}
{"op":"mcm","clk":"11875714769","pt":1723625266408,"mc":[{"id":"1.231659753","rc":[{"trd":[[1.66,14163.45]],"batl":[[0,1.66,256.71]],"ltp":1.66,"tv":36900.19,"id":26354926}],"tv":38257.34}]}
{"op":"mcm","clk":"11875721068","pt":1723625414193,"mc":[{"id":"1.231659753","rc":[{"trd":[[1.65,1183.46]],"batb":[[0,1.65,1418.72]],"ltp":1.65,"tv":37004.05,"id":26354926}],"tv":38361.2}]}
{"op":"mcm","clk":"11875723153","pt":1723625468243,"mc":[{"id":"1.231659753","rc":[{"trd":[[1.65,1233.46]],"batb":[[0,1.65,1393.72]],"ltp":1.65,"tv":37054.05,"id":26354926}],"tv":38411.2}]}
{"op":"mcm","clk":"11875724204","pt":1723625495988,"mc":[{"id":"1.231659753","rc":[{"trd":[[1.65,1283.46]],"batb":[[0,1.65,1368.72]],"ltp":1.65,"tv":37104.05,"id":26354926}],"tv":38461.2}]}
{"op":"mcm","clk":"11875726949","pt":1723625561384,"mc":[{"id":"1.231659753","rc":[{"trd":[[1.65,1333.46]],"batb":[[0,1.65,1343.72]],"ltp":1.65,"tv":37154.05,"id":26354926}],"tv":38511.2}]}
{"op":"mcm","clk":"11875727107","pt":1723625564580,"mc":[{"id":"1.231659753","rc":[{"trd":[[1.65,1333.88]],"batb":[[0,1.65,1343.51]],"ltp":1.65,"tv":37154.47,"id":26354926}],"tv":38511.62}]}
{"op":"mcm","clk":"11875727172","pt":1723625565860,"mc":[{"id":"1.231659753","rc":[{"trd":[[1.66,14163.88]],"batl":[[0,1.66,256.5]],"ltp":1.66,"tv":37154.91,"id":26354926}],"tv":38512.06}]}
{"op":"mcm","clk":"11875728990","pt":1723625611608,"mc":[{"id":"1.231659753","rc":[{"trd":[[1.65,1383.88]],"batb":[[0,1.65,1318.51]],"ltp":1.65,"tv":37204.91,"id":26354926}],"tv":38562.06}]}
{"op":"mcm","clk":"11875731991","pt":1723625683598,"mc":[{"id":"1.231659753","rc":[{"trd":[[1.65,1515.88]],"batb":[[0,1.65,1252.51]],"ltp":1.65,"tv":37336.91,"id":26354926}],"tv":38694.06}]}
{"op":"mcm","clk":"11875734303","pt":1723625732962,"mc":[{"id":"1.231659753","rc":[{"trd":[[1.65,1555.88]],"batb":[[0,1.65,1232.51]],"ltp":1.65,"tv":37376.91,"id":26354926}],"tv":38734.06}]}
{"op":"mcm","clk":"11875736156","pt":1723625772336,"mc":[{"id":"1.231659753","rc":[{"trd":[[2.52,1013.45]],"batl":[[0,2.52,9606.05]],"ltp":2.52,"tv":1586.16,"id":26354927}],"tv":38963.08}]}
{"op":"mcm","clk":"11875736365","pt":1723625776709,"mc":[{"id":"1.231659753","rc":[{"trd":[[1.65,1556.3]],"batb":[[0,1.65,1232.3]],"ltp":1.65,"tv":37377.33,"id":26354926}],"tv":38963.5}]}
{"op":"mcm","clk":"11875736416","pt":1723625777833,"mc":[{"id":"1.231659753","rc":[{"trd":[[1.66,14164.32]],"batl":[[0,1.66,256.28]],"ltp":1.66,"tv":37377.76,"id":26354926}],"tv":38963.93}]}
{"op":"mcm","clk":"11875740381","pt":1723625871852,"mc":[{"id":"1.231659753","rc":[{"trd":[[2.5,309.28]],"batb":[[0,2.5,67.79]],"ltp":2.5,"tv":1598.16,"id":26354927}],"tv":38975.93}]}
{"op":"mcm","clk":"11875740385","pt":1723625871958,"mc":[{"id":"1.231659753","rc":[{"batb":[[0,1.65,1241.4]],"ltp":1.66,"tv":37377.76,"id":26354926}]}]}
{"op":"mcm","clk":"11875746155","pt":1723626009172,"mc":[{"id":"1.231659753","rc":[{"trd":[[2.48,72.54],[2.5,309.28],[2.52,1013.94]],"batb":[[0,2.5,67.8],[1,2.48,30.85],[2,1.26,4.07]],"ltp":2.5,"tv":1598.65,"id":26354927},{"trd":[[1.58,749.99],[1.61,1975.17],[1.64,78.31],[1.65,1607.89],[1.66,14164.35],[1.67,8785.13]],"batb":[[0,1.65,1215.59]],"batl":[[0,1.66,256.24]],"ltp":1.65,"tv":37430.26,"id":26354926}],"tv":39028.92}]}
{"op":"mcm","clk":"11875747801","pt":1723626041503,"mc":[{"id":"1.231659753","rc":[{"batb":[[1,2.48,97.85]],"ltp":2.5,"tv":1598.65,"id":26354927}]}]}
{"op":"mcm","clk":"11875759934","pt":1723626280575,"mc":[{"id":"1.231659753","rc":[{"batl":[[0,1.66,307.87]],"ltp":1.65,"tv":37430.26,"id":26354926}]}]}
{"op":"mcm","clk":"11875763030","pt":1723626340058,"mc":[{"id":"1.231659753","rc":[{"trd":[[1.65,1613.05]],"batb":[[0,1.65,1213.01]],"ltp":1.65,"tv":37435.42,"id":26354926}],"tv":39034.08}]}
{"op":"mcm","clk":"11875764392","pt":1723626367765,"mc":[{"id":"1.231659753","rc":[{"trd":[[2.52,1068.04]],"batl":[[0,2.52,9579]],"ltp":2.52,"tv":1652.75,"id":26354927}],"tv":39088.18}]}
{"op":"mcm","clk":"11875764790","pt":1723626377470,"mc":[{"id":"1.231659753","rc":[{"trd":[[1.65,1623.05]],"batb":[[0,1.65,1208.01]],"ltp":1.65,"tv":37445.42,"id":26354926}],"tv":39098.18}]}
{"op":"mcm","clk":"11875767037","pt":1723626419720,"mc":[{"id":"1.231659753","rc":[{"batb":[[0,2.5,1069.59]],"ltp":2.52,"tv":1652.75,"id":26354927}]}]}
{"op":"mcm","clk":"11875781330","pt":1723626750114,"mc":[{"id":"1.231659753","rc":[{"trd":[[2.52,1107.66]],"batl":[[0,2.52,9559.19]],"ltp":2.52,"tv":1692.37,"id":26354927}],"tv":39137.8}]}
{"op":"mcm","clk":"11875781404","pt":1723626752117,"mc":[{"id":"1.231659753","rc":[{"trd":[[2.52,1164.08]],"batl":[[0,2.52,9530.98]],"ltp":2.52,"tv":1748.79,"id":26354927}],"tv":39194.22}]}
{"op":"mcm","clk":"11875786492","pt":1723626891548,"mc":[{"id":"1.231659753","rc":[{"trd":[[1.65,1929.95]],"batb":[[0,1.65,1054.56]],"ltp":1.65,"tv":37752.32,"id":26354926}],"tv":39501.12}]}
{"op":"mcm","clk":"11875786696","pt":1723626897525,"mc":[{"id":"1.231659753","rc":[{"trd":[[1.65,1930.06]],"batb":[[0,1.65,1054.51]],"ltp":1.65,"tv":37752.43,"id":26354926}],"tv":39501.22}]}
{"op":"mcm","clk":"11875786746","pt":1723626898562,"mc":[{"id":"1.231659753","rc":[{"trd":[[1.66,14164.47]],"batl":[[0,1.66,307.8]],"ltp":1.66,"tv":37752.55,"id":26354926}],"tv":39501.35}]}
{"op":"mcm","clk":"11875787857","pt":1723626923160,"mc":[{"id":"1.231659753","rc":[{"trd":[[2.52,1364.42]],"batl":[[0,2.52,9430.81]],"ltp":2.52,"tv":1949.13,"id":26354927}],"tv":39701.69}]}
{"op":"mcm","clk":"11875788284","pt":1723626933195,"mc":[{"id":"1.231659753","rc":[{"batb":[[0,2.5,67.8]],"ltp":2.52,"tv":1949.13,"id":26354927}]}]}
{"op":"mcm","clk":"11875795522","pt":1723627108887,"mc":[{"id":"1.231659753","rc":[{"trd":[[2.52,2977.46]],"batl":[[0,2.52,8624.29]],"ltp":2.52,"tv":3562.17,"id":26354927}],"tv":41314.73}]}
{"op":"mcm","clk":"11875795690","pt":1723627112603,"mc":[{"id":"1.231659753","rc":[{"trd":[[1.65,1930.16]],"batb":[[0,1.65,1054.46]],"ltp":1.65,"tv":37752.66,"id":26354926}],"tv":41314.83}]}
{"op":"mcm","clk":"11875795739","pt":1723627113477,"mc":[{"id":"1.231659753","rc":[{"trd":[[1.66,14164.59]],"batl":[[0,1.66,307.74]],"ltp":1.66,"tv":37752.78,"id":26354926}],"tv":41314.96}]}
{"op":"mcm","clk":"11875810584","pt":1723627439449,"mc":[{"id":"1.231659753","rc":[{"trd":[[1.65,2033.42]],"batb":[[0,1.65,1002.83]],"batl":[[0,1.66,256.12]],"ltp":1.65,"tv":37856.04,"id":26354926}],"tv":41418.21}]}
{"op":"mcm","clk":"11875811424","pt":1723627460311,"mc":[{"id":"1.231659753","rc":[{"trd":[[2.52,3040.56]],"batl":[[0,2.52,8592.74]],"ltp":2.52,"tv":3625.27,"id":26354927}],"tv":41481.31}]}
{"op":"mcm","clk":"11875823544","pt":1723627832208,"mc":[{"id":"1.231659753","rc":[{"trd":[[2.5,310.72]],"batb":[[0,2.5,67.08]],"ltp":2.5,"tv":3626.71,"id":26354927}],"tv":41482.76}]}
{"op":"mcm","clk":"11875826206","pt":1723627911370,"mc":[{"id":"1.231659753","rc":[{"trd":[[1.65,2038.4]],"batb":[[0,1.65,1000.34]],"ltp":1.65,"tv":37861.02,"id":26354926}],"tv":41487.73}]}
{"op":"mcm","clk":"11875865610","pt":1723628711325,"mc":[{"id":"1.231659753","rc":[{"trd":[[1.65,2438.4]],"batb":[[0,1.65,800.34]],"batl":[[0,1.66,56.12]],"ltp":1.65,"tv":38261.02,"id":26354926}],"tv":41887.73}]}
{"op":"mcm","clk":"11875870978","pt":1723628833755,"mc":[{"id":"1.231659753","rc":[{"batb":[[0,2.5,517.89]],"ltp":2.5,"tv":3626.71,"id":26354927}]}]}
{"op":"mcm","clk":"11875887957","pt":1723629267923,"mc":[{"id":"1.231659753","rc":[{"trd":[[2.5,320.72]],"batb":[[0,2.5,512.89]],"ltp":2.5,"tv":3636.71,"id":26354927}],"tv":41897.73}]}
{"op":"mcm","clk":"11875897865","pt":1723629504202,"mc":[{"id":"1.231659753","rc":[{"batl":[[0,1.66,61.12]],"ltp":1.65,"tv":38261.02,"id":26354926}]}]}
{"op":"mcm","clk":"11875898146","pt":1723629509314,"mc":[{"id":"1.231659753","rc":[{"batb":[[0,1.65,802.34]],"ltp":1.65,"tv":38261.02,"id":26354926}]}]}
{"op":"mcm","clk":"11875900500","pt":1723629562563,"mc":[{"id":"1.231659753","rc":[{"trd":[[1.65,2649.98]],"batb":[[0,1.65,696.55]],"ltp":1.65,"tv":38472.6,"id":26354926}],"tv":42109.31}]}
{"op":"mcm","clk":"11875902586","pt":1723629608653,"mc":[{"id":"1.231659753","rc":[{"trd":[[1.1,14.21],[2.48,72.54],[2.5,320.72],[2.52,3040.82]],"batb":[[1,2.48,97.85]],"ltp":2.5,"tv":3636.96,"id":26354927},{"trd":[[1.58,750.63],[1.61,1975.17],[1.63,120.5],[1.64,78.31],[1.65,2649.97],[1.66,14188.65],[1.67,8785.13],[1.73,4.76]],"batl":[[0,1.66,49.12]],"ltp":1.66,"tv":38497.27,"id":26354926}],"tv":42134.24}]}
{"op":"mcm","clk":"11875902844","pt":1723629614270,"mc":[{"id":"1.231659753","rc":[{"trd":[[2.5,344.72]],"batb":[[0,2.5,500.89]],"ltp":2.5,"tv":3660.96,"id":26354927}],"tv":42158.24}]}
{"op":"mcm","clk":"11875911049","pt":1723629783698,"mc":[{"id":"1.231659753","rc":[{"batl":[[0,1.66,178.12]],"ltp":1.66,"tv":38497.27,"id":26354926}]}]}
{"op":"mcm","clk":"11875920285","pt":1723629976408,"mc":[{"id":"1.231659753","rc":[{"trd":[[1.65,2659.97]],"batb":[[0,1.65,691.55]],"ltp":1.65,"tv":38507.27,"id":26354926}],"tv":42168.24}]}
{"op":"mcm","clk":"11875925174","pt":1723630084600,"mc":[{"id":"1.231659753","rc":[{"trd":[[1.65,2669.97]],"batb":[[0,1.65,686.55]],"ltp":1.65,"tv":38517.27,"id":26354926}],"tv":42178.24}]}
{"op":"mcm","clk":"11875941149","pt":1723630412155,"mc":[{"id":"1.231659753","rc":[{"trd":[[1.65,2671.97]],"batb":[[0,1.65,685.55]],"ltp":1.65,"tv":38519.27,"id":26354926}],"tv":42180.24}]}
{"op":"mcm","clk":"11875955186","pt":1723630678384,"mc":[{"id":"1.231659753","rc":[{"batb":[[0,1.65,2488.8]],"ltp":1.65,"tv":38519.27,"id":26354926}]}]}
{"op":"mcm","clk":"11875956641","pt":1723630701072,"mc":[{"id":"1.231659753","rc":[{"batb":[[1,1.64,3305.77]],"ltp":1.65,"tv":38519.27,"id":26354926}]}]}
{"op":"mcm","clk":"11875957148","pt":1723630709077,"mc":[{"id":"1.231659753","rc":[{"trd":[[1.66,14212.65]],"batl":[[0,1.66,166.13]],"ltp":1.66,"tv":38543.27,"id":26354926}],"tv":42204.23}]}
{"op":"mcm","clk":"11875957622","pt":1723630717515,"mc":[{"id":"1.231659753","rc":[{"trd":[[1.66,14236.64]],"batl":[[0,1.66,154.13]],"ltp":1.66,"tv":38567.27,"id":26354926}],"tv":42228.23}]}
{"op":"mcm","clk":"11875960812","pt":1723630779354,"mc":[{"id":"1.231659753","rc":[{"batb":[[0,2.5,458.61],[1,2.48,93.85]],"batl":[[0,2.52,8622.22]],"ltp":2.5,"tv":3660.96,"id":26354927},{"batl":[[1,1.67,8]],"ltp":1.66,"tv":38567.27,"id":26354926}]}]}
{"op":"mcm","clk":"11875961012","pt":1723630783169,"mc":[{"id":"1.231659753","rc":[{"trd":[[2.5,344.74]],"batb":[[0,2.5,458.6]],"ltp":2.5,"tv":3660.98,"id":26354927}],"tv":42228.25}]}
{"op":"mcm","clk":"11875964414","pt":1723630844838,"mc":[{"id":"1.231659753","rc":[{"trd":[[1.66,14260.64]],"batl":[[0,1.66,142.13]],"ltp":1.66,"tv":38591.26,"id":26354926}],"tv":42252.25}]}
{"op":"mcm","clk":"11875967886","pt":1723630909108,"mc":[{"id":"1.231659753","rc":[{"batb":[[0,2.5,450.81],[1,2.48,107.29]],"ltp":2.5,"tv":3660.98,"id":26354927}]}]}
{"op":"mcm","clk":"11875968813","pt":1723630927129,"mc":[{"id":"1.231659753","rc":[{"batl":[[2,1.68,192.33]],"ltp":1.66,"tv":38591.26,"id":26354926}]}]}
{"op":"mcm","clk":"11875969164","pt":1723630934136,"mc":[{"id":"1.231659753","rc":[{"trd":[[2.5,377.02]],"batb":[[0,2.5,418.53]],"ltp":2.5,"tv":3693.26,"id":26354927},{"trd":[[1.66,14544.9],[1.67,8849.45]],"batb":[[0,1.66,44.76],[1,1.65,2488.8],[2,1.64,3305.77]],"batl":[[0,1.68,299.47],[1,1.69,519.15],[2,1.7,31.15]],"ltp":1.67,"tv":38939.84,"id":26354926}],"tv":42633.11}]}
{"op":"mcm","clk":"11875972969","pt":1723631007682,"mc":[{"id":"1.231659753","rc":[{"batb":[[0,2.5,170.58]],"ltp":2.5,"tv":3693.26,"id":26354927}]}]}
{"op":"mcm","clk":"11875977502","pt":1723631095903,"mc":[{"id":"1.231659753","rc":[{"batb":[[0,2.48,107.29],[1,1.26,4.07],[2,1.1,25000]],"ltp":2.5,"tv":3693.26,"id":26354927}]}]}
{"op":"mcm","clk":"11875977512","pt":1723631096008,"mc":[{"id":"1.231659753","rc":[{"batl":[[0,2.5,29.72],[1,2.52,8622.22],[2,2.56,4]],"ltp":2.5,"tv":3693.26,"id":26354927},{"batl":[[0,1.68,192.33]],"ltp":1.67,"tv":38939.84,"id":26354926}]}]}
{"op":"mcm","clk":"11875978201","pt":1723631108892,"mc":[{"id":"1.231659753","rc":[{"trd":[[2.5,393.06]],"batl":[[0,2.5,21.7]],"ltp":2.5,"tv":3709.3,"id":26354927}],"tv":42649.15}]}
{"op":"mcm","clk":"11875978209","pt":1723631108998,"mc":[{"id":"1.231659753","rc":[{"batb":[[0,2.48,99.86]],"ltp":2.5,"tv":3709.3,"id":26354927}]}]}
{"op":"mcm","clk":"11875979063","pt":1723631125525,"mc":[{"id":"1.231659753","rc":[{"batb":[[0,2.48,73.01],[1,2.46,27.36],[2,1.26,4.07]],"ltp":2.5,"tv":3709.3,"id":26354927}]}]}
{"op":"mcm","clk":"11875979959","pt":1723631143429,"mc":[{"id":"1.231659753","rc":[{"batl":[[0,1.67,261.47],[1,1.68,192.33],[2,1.69,519.15]],"ltp":1.67,"tv":38939.84,"id":26354926}]}]}
{"op":"mcm","clk":"11875981892","pt":1723631185104,"mc":[{"id":"1.231659753","rc":[{"trd":[[2.48,132.54]],"batb":[[0,2.48,43.01]],"ltp":2.48,"tv":3769.3,"id":26354927}],"tv":42709.15}]}
{"op":"mcm","clk":"11875983043","pt":1723631209448,"mc":[{"id":"1.231659753","rc":[{"trd":[[2.5,436.46],[2.52,3056.8]],"batb":[[0,2.48,115.59]],"batl":[[0,2.52,8584.75],[1,2.56,4],[2,3,1]],"ltp":2.52,"tv":3828.68,"id":26354927},{"batb":[[0,1.65,2470.61],[1,1.64,3305.77],[2,1.63,160]],"ltp":1.67,"tv":38939.84,"id":26354926}],"tv":42768.53}]}
{"op":"mcm","clk":"11875985193","pt":1723631255647,"mc":[{"id":"1.231659753","rc":[{"batb":[[0,2.48,128.59]],"batl":[[0,2.5,13],[1,2.52,8584.75],[2,2.56,4]],"ltp":2.52,"tv":3828.68,"id":26354927}]}]}
{"op":"mcm","clk":"11875986219","pt":1723631277197,"mc":[{"id":"1.231659753","rc":[{"batb":[[0,1.66,34],[1,1.65,2470.61],[2,1.64,3305.77]],"batl":[[0,1.67,295.47]],"ltp":1.67,"tv":38939.84,"id":26354926}]}]}
{"op":"mcm","clk":"11875987869","pt":1723631313655,"mc":[{"id":"1.231659753","rc":[{"batb":[[0,2.48,155.44],[1,1.26,4.07],[2,1.1,25000]],"ltp":2.52,"tv":3828.68,"id":26354927}]}]}
{"op":"mcm","clk":"11875993293","pt":1723631447579,"mc":[{"id":"1.231659753","rc":[{"trd":[[1.66,14595.46]],"batb":[[0,1.66,8.72]],"ltp":1.66,"tv":38990.4,"id":26354926}],"tv":42819.09}]}
{"op":"mcm","clk":"11875993322","pt":1723631448194,"mc":[{"id":"1.231659753","rc":[{"trd":[[2.48,142.54]],"batb":[[0,2.48,150.44]],"ltp":2.48,"tv":3838.68,"id":26354927}],"tv":42829.09}]}
{"op":"mcm","clk":"11876000673","pt":1723631608763,"mc":[{"id":"1.231659753","rc":[{"batb":[[0,2.48,144.43]],"ltp":2.48,"tv":3838.68,"id":26354927}]}]}
{"op":"mcm","clk":"11876000682","pt":1723631608966,"mc":[{"id":"1.231659753","rc":[{"batb":[[1,2.46,11.56],[2,1.26,4.07]],"ltp":2.48,"tv":3838.68,"id":26354927},{"batb":[[1,1.65,2484.87]],"ltp":1.66,"tv":38990.4,"id":26354926}]}]}
{"op":"mcm","clk":"11876002385","pt":1723631650379,"mc":[{"id":"1.231659753","rc":[{"trd":[[1.66,14605.46]],"batb":[[0,1.66,3.72]],"ltp":1.66,"tv":39000.4,"id":26354926}],"tv":42839.09}]}
{"op":"mcm","clk":"11876009601","pt":1723631794373,"mc":[{"id":"1.231659753","rc":[{"trd":[[2.48,144.54]],"batb":[[0,2.48,143.43]],"ltp":2.48,"tv":3840.68,"id":26354927}],"tv":42841.09}]}
{"op":"mcm","clk":"11876010012","pt":1723631802596,"mc":[{"id":"1.231659753","rc":[{"batb":[[0,1.66,25.72]],"ltp":1.66,"tv":39000.4,"id":26354926}]}]}
{"op":"mcm","clk":"11876010686","pt":1723631817593,"mc":[{"id":"1.231659753","rc":[{"trd":[[2.5,462.46]],"batb":[[0,2.5,167.32],[1,2.48,143.43],[2,2.46,11.56]],"batl":[[0,2.52,8584.75],[1,2.56,4],[2,3,1]],"ltp":2.5,"tv":3866.68,"id":26354927}],"tv":42867.09}]}
{"op":"mcm","clk":"11876011415","pt":1723631834117,"mc":[{"id":"1.231659753","rc":[{"trd":[[1.66,14612.9]],"batb":[[0,1.65,2484.87],[1,1.64,3305.77],[2,1.63,160]],"batl":[[0,1.66,19.36],[1,1.67,295.47],[2,1.68,192.33]],"ltp":1.66,"tv":39007.84,"id":26354926}],"tv":42874.53}]}
{"op":"mcm","clk":"11876011534","pt":1723631836913,"mc":[{"id":"1.231659753","rc":[{"trd":[[2.5,492.46]],"batb":[[0,2.5,152.32]],"ltp":2.5,"tv":3896.68,"id":26354927}],"tv":42904.53}]}
{"op":"mcm","clk":"11876011649","pt":1723631840214,"mc":[{"id":"1.231659753","rc":[{"batl":[[0,1.67,295.47],[1,1.68,192.33],[2,1.69,519.15]],"ltp":1.66,"tv":39007.84,"id":26354926}]}]}
{"op":"mcm","clk":"11876012147","pt":1723631852418,"mc":[{"id":"1.231659753","rc":[{"batb":[[0,1.66,25.7],[1,1.65,2484.87],[2,1.64,3305.77]],"ltp":1.66,"tv":39007.84,"id":26354926}]}]}
{"op":"mcm","clk":"11876012756","pt":1723631866048,"mc":[{"id":"1.231659753","rc":[{"batb":[[1,1.65,2492.91]],"ltp":1.66,"tv":39007.84,"id":26354926}]}]}
{"op":"mcm","clk":"11876012911","pt":1723631870051,"mc":[{"id":"1.231659753","rc":[{"batb":[[0,1.66,1892.7]],"ltp":1.66,"tv":39007.84,"id":26354926}]}]}
{"op":"mcm","clk":"11876012977","pt":1723631872072,"mc":[{"id":"1.231659753","rc":[{"batb":[[0,1.66,1900.74]],"ltp":1.66,"tv":39007.84,"id":26354926}]}]}
{"op":"mcm","clk":"11876013039","pt":1723631873875,"mc":[{"id":"1.231659753","rc":[{"trd":[[1.66,14613.2]],"batb":[[0,1.66,1900.59]],"ltp":1.66,"tv":39008.14,"id":26354926}],"tv":42904.83}]}
{"op":"mcm","clk":"11876013077","pt":1723631874859,"mc":[{"id":"1.231659753","rc":[{"trd":[[1.67,8849.76]],"batl":[[0,1.67,295.31]],"ltp":1.67,"tv":39008.46,"id":26354926}],"tv":42905.14}]}
{"op":"mcm","clk":"11876013206","pt":1723631878380,"mc":[{"id":"1.231659753","rc":[{"trd":[[1.66,14643.32]],"batb":[[0,1.66,1885.53]],"ltp":1.66,"tv":39038.58,"id":26354926}],"tv":42935.26}]}
{"op":"mcm","clk":"11876013358","pt":1723631881687,"mc":[{"id":"1.231659753","rc":[{"batl":[[0,1.67,303.31]],"ltp":1.66,"tv":39038.58,"id":26354926}]}]}
{"op":"mcm","clk":"11876013457","pt":1723631883863,"mc":[{"id":"1.231659753","rc":[{"trd":[[1.66,14803.32]],"batb":[[0,1.66,1805.53]],"ltp":1.66,"tv":39198.58,"id":26354926}],"tv":43095.26}]}
{"op":"mcm","clk":"11876014211","pt":1723631900566,"mc":[{"id":"1.231659753","rc":[{"batb":[[0,2.5,156.61]],"batl":[[1,2.56,8.29]],"ltp":2.5,"tv":3896.68,"id":26354927}]}]}
{"op":"mcm","clk":"11876014613","pt":1723631909756,"mc":[{"id":"1.231659753","rc":[{"batb":[[0,2.5,4.29]],"ltp":2.5,"tv":3896.68,"id":26354927}]}]}
{"op":"mcm","clk":"11876015020","pt":1723631918494,"mc":[{"id":"1.231659753","rc":[{"batb":[[1,2.48,116.58],[2,2.46,38.93]],"ltp":2.5,"tv":3896.68,"id":26354927}]}]}
{"op":"mcm","clk":"11876018813","pt":1723631993456,"mc":[{"id":"1.231659753","rc":[{"trd":[[2.5,501.04]],"batb":[[0,2.48,116.58],[1,2.46,38.93],[2,1.26,4.07]],"batl":[[0,2.5,13.75],[1,2.52,8584.75],[2,2.56,8.29]],"ltp":2.5,"tv":3905.26,"id":26354927}],"tv":43103.84}]}
{"op":"mcm","clk":"11876019566","pt":1723632007585,"mc":[{"id":"1.231659753","rc":[{"batb":[[0,2.48,143.43],[1,2.46,11.56]],"ltp":2.5,"tv":3905.26,"id":26354927}]}]}
{"op":"mcm","clk":"11876022252","pt":1723632057864,"mc":[{"id":"1.231659753","rc":[{"trd":[[1.67,9008.8]],"batl":[[0,1.67,223.79]],"ltp":1.67,"tv":39357.62,"id":26354926}],"tv":43262.88}]}
{"op":"mcm","clk":"11876024922","pt":1723632100508,"mc":[{"id":"1.231659753","rc":[{"batb":[[0,2.48,116.58],[1,2.46,38.93]],"ltp":2.5,"tv":3905.26,"id":26354927}]}]}
{"op":"mcm","clk":"11876026082","pt":1723632119935,"mc":[{"id":"1.231659753","rc":[{"batl":[[0,1.67,196.74]],"ltp":1.67,"tv":39357.62,"id":26354926}]}]}
{"op":"mcm","clk":"11876028089","pt":1723632153263,"mc":[{"id":"1.231659753","rc":[{"batb":[[0,2.48,44],[1,2.46,112.1]],"ltp":2.5,"tv":3905.26,"id":26354927}]}]}
{"op":"mcm","clk":"11876037216","pt":1723632301630,"mc":[{"id":"1.231659753","rc":[{"trd":[[2.48,145.66]],"batb":[[0,2.48,43.44]],"ltp":2.48,"tv":3906.38,"id":26354927}],"tv":43264.0}]}
{"op":"mcm","clk":"11876043085","pt":1723632403158,"mc":[{"id":"1.231659753","rc":[{"batb":[[0,2.48,116.02]],"ltp":2.48,"tv":3906.38,"id":26354927},{"batl":[[1,1.68,1594.8]],"ltp":1.67,"tv":39357.62,"id":26354926}]}]}
{"op":"mcm","clk":"11876048634","pt":1723632507456,"mc":[{"id":"1.231659753","rc":[{"trd":[[1.67,9058.92]],"batl":[[0,1.67,171.68]],"ltp":1.67,"tv":39407.74,"id":26354926}],"tv":43314.12}]}
{"op":"mcm","clk":"11876050361","pt":1723632547420,"mc":[{"id":"1.231659753","rc":[{"trd":[[1.66,15203.32]],"batb":[[0,1.66,1605.53]],"ltp":1.66,"tv":39807.74,"id":26354926}],"tv":43714.12}]}
{"op":"mcm","clk":"11876050556","pt":1723632551815,"mc":[{"id":"1.231659753","rc":[{"trd":[[1.66,15203.62]],"batb":[[0,1.66,1605.38]],"ltp":1.66,"tv":39808.03,"id":26354926}],"tv":43714.42}]}
{"op":"mcm","clk":"11876050641","pt":1723632553621,"mc":[{"id":"1.231659753","rc":[{"trd":[[1.67,9059.24]],"batl":[[0,1.67,171.52]],"ltp":1.67,"tv":39808.35,"id":26354926}],"tv":43714.74}]}
{"op":"mcm","clk":"11876051471","pt":1723632571175,"mc":[{"id":"1.231659753","rc":[{"batb":[[2,2.3,153.97]],"ltp":2.48,"tv":3906.38,"id":26354927}]}]}
{"op":"mcm","clk":"11876053004","pt":1723632603871,"mc":[{"id":"1.231659753","rc":[{"trd":[[1.66,15221.78]],"batb":[[0,1.66,1596.3]],"ltp":1.66,"tv":39826.51,"id":26354926}],"tv":43732.9}]}
{"op":"mcm","clk":"11876085709","pt":1723633322697,"mc":[{"id":"1.231659753","rc":[{"trd":[[1.1,14.22],[2.48,145.68],[2.5,501.06],[2.52,3057.24]],"batb":[[0,2.5,6],[1,2.48,122.02],[2,2.46,112.11]],"batl":[[0,2.52,8584.75],[1,2.56,8.29],[2,3,1]],"ltp":2.48,"tv":3906.88,"id":26354927},{"trd":[[1.58,750.75],[1.61,1975.17],[1.63,120.51],[1.64,78.32],[1.65,2672.03],[1.66,15221.89],[1.67,9059.26],[1.73,4.76]],"batb":[[1,1.65,2492.91]],"ltp":1.66,"tv":39826.86,"id":26354926}],"tv":43733.74}]}
{"op":"mcm","clk":"11876085723","pt":1723633322969,"mc":[{"id":"1.231659753","rc":[{"batb":[[1,2.48,116.02]],"ltp":2.48,"tv":3906.88,"id":26354927}]}]}
{"op":"mcm","clk":"11876086146","pt":1723633329735,"mc":[{"id":"1.231659753","rc":[{"batl":[[1,1.68,192.33]],"ltp":1.66,"tv":39826.86,"id":26354926}]}]}
{"op":"mcm","clk":"11876087574","pt":1723633355246,"mc":[{"id":"1.231659753","rc":[{"trd":[[2.5,513.06]],"batb":[[0,2.48,43.44],[1,2.46,112.11],[2,2.3,154.06]],"batl":[[0,2.5,3.02],[1,2.52,8584.75],[2,2.56,8.29]],"ltp":2.5,"tv":3918.88,"id":26354927}],"tv":43745.74}]}
{"op":"mcm","clk":"11876093147","pt":1723633452784,"mc":[{"id":"1.231659753","rc":[{"batl":[[0,2.52,8584.75],[1,2.56,8.29],[2,3,1]],"ltp":2.5,"tv":3918.88,"id":26354927}]}]}
{"op":"mcm","clk":"11876100952","pt":1723633601944,"mc":[{"id":"1.231659753","rc":[{"batb":[[2,1.64,100.05]],"ltp":1.66,"tv":39826.86,"id":26354926}]}]}
{"op":"mcm","clk":"11876101221","pt":1723633607263,"mc":[{"id":"1.231659753","rc":[{"batb":[[1,1.65,689.66]],"ltp":1.66,"tv":39826.86,"id":26354926}]}]}
{"op":"mcm","clk":"11876106698","pt":1723633728118,"mc":[{"id":"1.231659753","rc":[{"trd":[[1.66,15321.89]],"batb":[[0,1.66,1546.3]],"ltp":1.66,"tv":39926.86,"id":26354926}],"tv":43845.74}]}
{"op":"mcm","clk":"11876107256","pt":1723633742713,"mc":[{"id":"1.231659753","rc":[{"trd":[[1.66,15337.89]],"batb":[[0,1.66,1538.3],[1,1.65,697.71]],"ltp":1.66,"tv":39942.86,"id":26354926}],"tv":43861.74}]}
{"op":"mcm","clk":"11876107389","pt":1723633745544,"mc":[{"id":"1.231659753","rc":[{"trd":[[1.66,15353.89]],"batb":[[0,1.66,1530.3],[1,1.65,705.76]],"ltp":1.66,"tv":39958.86,"id":26354926}],"tv":43877.74}]}
{"op":"mcm","clk":"11876110115","pt":1723633809303,"mc":[{"id":"1.231659753","rc":[{"batl":[[0,1.67,192.85]],"ltp":1.66,"tv":39958.86,"id":26354926}]}]}
{"op":"mcm","clk":"11876111611","pt":1723633843144,"mc":[{"id":"1.231659753","rc":[{"trd":[[1.66,15356.07]],"batb":[[0,1.66,1529.21]],"ltp":1.66,"tv":39961.04,"id":26354926}],"tv":43879.92}]}
{"op":"mcm","clk":"11876113547","pt":1723633886578,"mc":[{"id":"1.231659753","rc":[{"trd":[[1.66,15456.07]],"batb":[[0,1.66,1479.21]],"ltp":1.66,"tv":40061.04,"id":26354926}],"tv":43979.92}]}
{"op":"mcm","clk":"11876114882","pt":1723633917161,"mc":[{"id":"1.231659753","rc":[{"trd":[[1.66,15459.69]],"batb":[[0,1.66,1477.4]],"ltp":1.66,"tv":40064.66,"id":26354926}],"tv":43983.54}]}
{"op":"mcm","clk":"11876133921","pt":1723634150163,"mc":[{"id":"1.231659753","rc":[{"trd":[[1.66,15469.69]],"batb":[[0,1.66,1472.4]],"ltp":1.66,"tv":40074.66,"id":26354926}],"tv":43993.54}]}
{"op":"mcm","clk":"11876146087","pt":1723634385502,"mc":[{"id":"1.231659753","rc":[{"batl":[[0,1.67,89.35]],"ltp":1.66,"tv":40074.66,"id":26354926}]}]}
{"op":"mcm","clk":"11876149013","pt":1723634440965,"mc":[{"id":"1.231659753","rc":[{"trd":[[1.67,9165.92]],"batl":[[0,1.67,36.02]],"ltp":1.67,"tv":40181.32,"id":26354926}],"tv":44100.2}]}
{"op":"mcm","clk":"11876149254","pt":1723634444892,"mc":[{"id":"1.231659753","rc":[{"batb":[[0,1.66,1483.07]],"ltp":1.67,"tv":40181.32,"id":26354926}]}]}
{"op":"mcm","clk":"11876149529","pt":1723634449731,"mc":[{"id":"1.231659753","rc":[{"batb":[[1,1.65,716.43]],"ltp":1.67,"tv":40181.32,"id":26354926}]}]}
{"op":"mcm","clk":"11876150017","pt":1723634458276,"mc":[{"id":"1.231659753","rc":[{"batb":[[2,1.64,110.72]],"ltp":1.67,"tv":40181.32,"id":26354926}]}]}
{"op":"mcm","clk":"11876151230","pt":1723634481002,"mc":[{"id":"1.231659753","rc":[{"batl":[[0,1.67,40.53]],"ltp":1.67,"tv":40181.32,"id":26354926}]}]}
{"op":"mcm","clk":"11876153777","pt":1723634526133,"mc":[{"id":"1.231659753","rc":[{"trd":[[1.66,15509.69]],"batb":[[0,1.66,1463.07]],"ltp":1.66,"tv":40221.32,"id":26354926}],"tv":44140.2}]}
{"op":"mcm","clk":"11876174134","pt":1723634949000,"mc":[{"id":"1.231659753","rc":[{"trd":[[1.66,15549.69]],"batb":[[0,1.66,1443.07]],"ltp":1.66,"tv":40261.32,"id":26354926}],"tv":44180.2}]}
{"op":"mcm","clk":"11876178915","pt":1723635067669,"mc":[{"id":"1.231659753","rc":[{"batb":[[1,1.65,980.52]],"ltp":1.66,"tv":40261.32,"id":26354926}]}]}
{"op":"mcm","clk":"11876179075","pt":1723635071354,"mc":[{"id":"1.231659753","rc":[{"batb":[[1,1.65,716.43]],"ltp":1.66,"tv":40261.32,"id":26354926}]}]}
{"op":"mcm","clk":"11876182210","pt":1723635149975,"mc":[{"id":"1.231659753","rc":[{"batb":[[1,1.65,51.07]],"ltp":1.66,"tv":40261.32,"id":26354926}]}]}
{"op":"mcm","clk":"11876186463","pt":1723635242562,"mc":[{"id":"1.231659753","rc":[{"batb":[[0,2.5,72],[1,2.48,43.44],[2,2.46,112.11]],"ltp":2.5,"tv":3918.88,"id":26354927},{"trd":[[1.66,18435.83]],"batb":[[0,1.65,51.07],[1,1.64,110.72],[2,1.63,160]],"batl":[[0,1.66,7306.93],[1,1.67,40.53],[2,1.68,192.33]],"ltp":1.66,"tv":43147.46,"id":26354926}],"tv":47066.34}]}
{"op":"mcm","clk":"11876186684","pt":1723635246789,"mc":[{"id":"1.231659753","rc":[{"trd":[[1.65,2672.14]],"batb":[[0,1.65,51.02]],"ltp":1.65,"tv":43147.56,"id":26354926}],"tv":47066.45}]}
{"op":"mcm","clk":"11876186767","pt":1723635248590,"mc":[{"id":"1.231659753","rc":[{"trd":[[1.66,18435.96]],"batl":[[0,1.66,7306.87]],"ltp":1.66,"tv":43147.69,"id":26354926}],"tv":47066.57}]}
{"op":"mcm","clk":"11876186950","pt":1723635253695,"mc":[{"id":"1.231659753","rc":[{"batb":[[0,2.48,43.44],[1,2.46,112.11],[2,2.3,154.06]],"ltp":2.5,"tv":3918.88,"id":26354927},{"batl":[[0,1.67,40.53],[1,1.68,192.33],[2,1.69,519.15]],"ltp":1.66,"tv":43147.69,"id":26354926}]}]}
{"op":"mcm","clk":"11876187826","pt":1723635277340,"mc":[{"id":"1.231659753","rc":[{"batb":[[0,1.65,5059.99]],"ltp":1.66,"tv":43147.69,"id":26354926}]}]}
{"op":"mcm","clk":"11876189397","pt":1723635313240,"mc":[{"id":"1.231659753","rc":[{"batb":[[0,2.5,4.51],[1,2.48,43.44],[2,2.46,112.11]],"ltp":2.5,"tv":3918.88,"id":26354927}]}]}
{"op":"mcm","clk":"11876192804","pt":1723635390836,"mc":[{"id":"1.231659753","rc":[{"batl":[[0,1.67,36.02]],"ltp":1.66,"tv":43147.69,"id":26354926}]}]}
{"op":"mcm","clk":"11876193128","pt":1723635397782,"mc":[{"id":"1.231659753","rc":[{"batb":[[0,1.65,51.02]],"ltp":1.66,"tv":43147.69,"id":26354926}]}]}
{"op":"mcm","clk":"11876219179","pt":1723635884421,"mc":[{"id":"1.231659753","rc":[{"batl":[[0,1.67,41.29]],"ltp":1.66,"tv":43147.69,"id":26354926}]}]}
{"op":"mcm","clk":"11876224432","pt":1723635976637,"mc":[{"id":"1.231659753","rc":[{"batb":[[0,1.66,255.77],[1,1.65,51.02],[2,1.64,110.72]],"ltp":1.66,"tv":43147.69,"id":26354926}]}]}
{"op":"mcm","clk":"11876226583","pt":1723636011142,"mc":[{"id":"1.231659753","rc":[{"batl":[[2,1.69,1073]],"ltp":1.66,"tv":43147.69,"id":26354926}]}]}
{"op":"mcm","clk":"11876227127","pt":1723636019881,"mc":[{"id":"1.231659753","rc":[{"batl":[[2,1.69,519.15]],"ltp":1.66,"tv":43147.69,"id":26354926}]}]}
{"op":"mcm","clk":"11876233356","pt":1723636140617,"mc":[{"id":"1.231659753","rc":[{"batb":[[0,1.65,51.02],[1,1.64,110.72],[2,1.63,160]],"ltp":1.66,"tv":43147.69,"id":26354926}]}]}
{"op":"mcm","clk":"11876234778","pt":1723636166318,"mc":[{"id":"1.231659753","rc":[{"batb":[[2,1.63,320]],"ltp":1.66,"tv":43147.69,"id":26354926}]}]}
{"op":"mcm","clk":"11876236311","pt":1723636198779,"mc":[{"id":"1.231659753","rc":[{"trd":[[2.52,11456.64]],"batb":[[0,2.5,42.1]],"batl":[[0,2.52,185.61]],"ltp":2.52,"tv":12318.28,"id":26354927},{"trd":[[1.65,15597.59]],"batb":[[0,1.64,110.72],[1,1.63,342.58],[2,1.62,1204.52]],"batl":[[0,1.67,149.07]],"ltp":1.65,"tv":56073.14,"id":26354926}],"tv":68391.42}]}
{"op":"mcm","clk":"11876236593","pt":1723636203755,"mc":[{"id":"1.231659753","rc":[{"trd":[[2.52,11638.25]],"batb":[[0,2.52,34.13],[1,2.5,42.1],[2,2.48,43.44]],"batl":[[0,2.56,4.29],[1,3,1],[2,140,1.03]],"ltp":2.52,"tv":12499.89,"id":26354927},{"trd":[[1.65,15874.95]],"batb":[[0,1.64,106.72]],"batl":[[0,1.65,49.91],[1,1.66,12874.43],[2,1.67,149.07]],"ltp":1.65,"tv":56350.5,"id":26354926}],"tv":68850.39}]}
{"op":"mcm","clk":"11876236767","pt":1723636206788,"mc":[{"id":"1.231659753","rc":[{"batb":[[0,2.54,4],[1,2.52,34.13],[2,2.5,42.1]],"ltp":2.52,"tv":12499.89,"id":26354927}]}]}
{"op":"mcm","clk":"11876236980","pt":1723636210560,"mc":[{"id":"1.231659753","rc":[{"batb":[[1,2.52,60.99]],"ltp":2.52,"tv":12499.89,"id":26354927}]}]}
{"op":"mcm","clk":"11876237785","pt":1723636225410,"mc":[{"id":"1.231659753","rc":[{"batb":[[1,1.63,182.58]],"ltp":1.65,"tv":56350.5,"id":26354926}]}]}
{"op":"mcm","clk":"11876238097","pt":1723636232396,"mc":[{"id":"1.231659753","rc":[{"batb":[[1,1.63,22.58]],"ltp":1.65,"tv":56350.5,"id":26354926}]}]}
{"op":"mcm","clk":"11876238229","pt":1723636235077,"mc":[{"id":"1.231659753","rc":[{"batb":[[0,2.54,11.04]],"batl":[[0,2.56,9.71]],"ltp":2.52,"tv":12499.89,"id":26354927}]}]}
{"op":"mcm","clk":"11876238437","pt":1723636238706,"mc":[{"id":"1.231659753","rc":[{"trd":[[2.52,11659.41],[2.54,38.46]],"batb":[[0,2.52,50.41],[1,2.5,42.1],[2,2.48,43.44]],"ltp":2.52,"tv":12554.5,"id":26354927}],"tv":68905.01}]}
{"op":"mcm","clk":"11876238685","pt":1723636244388,"mc":[{"id":"1.231659753","rc":[{"batb":[[1,1.63,299.5]],"ltp":1.65,"tv":56350.5,"id":26354926}]}]}
{"op":"mcm","clk":"11876239034","pt":1723636251727,"mc":[{"id":"1.231659753","rc":[{"batb":[[0,2.54,4],[1,2.52,54.41],[2,2.5,42.1]],"ltp":2.52,"tv":12554.5,"id":26354927}]}]}
{"op":"mcm","clk":"11876239325","pt":1723636258601,"mc":[{"id":"1.231659753","rc":[{"batb":[[1,2.52,27.55]],"ltp":2.52,"tv":12554.5,"id":26354927}]}]}
{"op":"mcm","clk":"11876240351","pt":1723636281544,"mc":[{"id":"1.231659753","rc":[{"trd":[[1.65,15964.95]],"batl":[[0,1.65,109.09]],"ltp":1.65,"tv":56440.5,"id":26354926}],"tv":68995.01}]}
{"op":"mcm","clk":"11876240713","pt":1723636290662,"mc":[{"id":"1.231659753","rc":[{"batl":[[0,2.56,14.81]],"ltp":2.52,"tv":12554.5,"id":26354927}]}]}
{"op":"mcm","clk":"11876241528","pt":1723636306582,"mc":[{"id":"1.231659753","rc":[{"batb":[[1,2.52,54.41]],"ltp":2.52,"tv":12554.5,"id":26354927}]}]}
{"op":"mcm","clk":"11876244200","pt":1723636363512,"mc":[{"id":"1.231659753","rc":[{"trd":[[2.54,42.46]],"batb":[[0,2.52,30.86],[1,2.5,42.1],[2,2.48,43.44]],"batl":[[0,2.56,56.39]],"ltp":2.54,"tv":12558.5,"id":26354927},{"trd":[[1.65,15971.11]],"batb":[[0,1.65,68.23],[1,1.64,106.72],[2,1.63,299.5]],"batl":[[0,1.67,149.07],[1,1.68,192.33],[2,1.69,519.15]],"ltp":1.65,"tv":56446.66,"id":26354926}],"tv":69005.17}]}
{"op":"mcm","clk":"11876244319","pt":1723636365831,"mc":[{"id":"1.231659753","rc":[{"batl":[[0,2.56,51.29]],"ltp":2.54,"tv":12558.5,"id":26354927}]}]}
{"op":"mcm","clk":"11876244643","pt":1723636372539,"mc":[{"id":"1.231659753","rc":[{"batl":[[0,2.54,4],[1,2.56,51.29],[2,3,1]],"ltp":2.54,"tv":12558.5,"id":26354927}]}]}
{"op":"mcm","clk":"11876245983","pt":1723636401736,"mc":[{"id":"1.231659753","rc":[{"batb":[[0,2.5,42.1],[1,2.48,43.44],[2,2.46,11.57]],"ltp":2.54,"tv":12558.5,"id":26354927}]}]}
{"op":"mcm","clk":"11876246023","pt":1723636402762,"mc":[{"id":"1.231659753","rc":[{"batb":[[0,2.5,46.1]],"ltp":2.54,"tv":12558.5,"id":26354927},{"batl":[[0,1.66,4],[1,1.67,153.07],[2,1.68,192.33]],"ltp":1.65,"tv":56446.66,"id":26354926}]}]}
{"op":"mcm","clk":"11876246041","pt":1723636403173,"mc":[{"id":"1.231659753","rc":[{"batl":[[0,2.52,7.1],[1,2.54,4],[2,2.56,45.87]],"ltp":2.54,"tv":12558.5,"id":26354927}]}]}
{"op":"mcm","clk":"11876246794","pt":1723636422380,"mc":[{"id":"1.231659753","rc":[{"trd":[[2.52,11668.43]],"batl":[[0,2.52,2.59]],"ltp":2.52,"tv":12567.52,"id":26354927}],"tv":69014.19}]}
{"op":"mcm","clk":"11876247832","pt":1723636447612,"mc":[{"id":"1.231659753","rc":[{"batb":[[1,2.48,70.3]],"ltp":2.52,"tv":12567.52,"id":26354927}]}]}
{"op":"mcm","clk":"11876250360","pt":1723636507133,"mc":[{"id":"1.231659753","rc":[{"trd":[[1.66,18443.84]],"batl":[[0,1.67,153.13],[1,1.68,192.33],[2,1.69,519.15]],"ltp":1.66,"tv":56454.54,"id":26354926}],"tv":69022.07}]}
{"op":"mcm","clk":"11876250420","pt":1723636508465,"mc":[{"id":"1.231659753","rc":[{"batb":[[0,1.65,72.23]],"batl":[[0,1.66,4.06],[1,1.67,153.07],[2,1.68,192.33]],"ltp":1.66,"tv":56454.54,"id":26354926}]}]}
{"op":"mcm","clk":"11876254529","pt":1723636601732,"mc":[{"id":"1.231659753","rc":[{"trd":[[1.65,16071.11]],"batb":[[0,1.65,22.23]],"ltp":1.65,"tv":56554.54,"id":26354926}],"tv":69122.07}]}
{"op":"mcm","clk":"11876254586","pt":1723636602824,"mc":[{"id":"1.231659753","rc":[{"trd":[[2.52,11671.02]],"batl":[[0,2.56,45.87],[1,3,1],[2,140,1.03]],"ltp":2.52,"tv":12570.11,"id":26354927},{"trd":[[1.65,16119.53]],"batb":[[0,1.64,186.89],[1,1.63,299.5],[2,1.62,1204.52]],"batl":[[0,1.65,33.4],[1,1.67,149.07]],"ltp":1.65,"tv":56602.96,"id":26354926}],"tv":69173.08}]}
{"op":"mcm","clk":"11876254863","pt":1723636608813,"mc":[{"id":"1.231659753","rc":[{"batb":[[0,1.65,56.36],[1,1.64,186.89],[2,1.63,299.5]],"batl":[[0,1.67,149.07],[1,1.68,192.33],[2,1.69,519.15]],"ltp":1.65,"tv":56602.96,"id":26354926}]}]}
{"op":"mcm","clk":"11876254870","pt":1723636608916,"mc":[{"id":"1.231659753","rc":[{"trd":[[1.65,16186.32]],"batb":[[0,1.65,22.96]],"ltp":1.65,"tv":56669.75,"id":26354926}],"tv":69239.87}]}
{"op":"mcm","clk":"11876255134","pt":1723636614447,"mc":[{"id":"1.231659753","rc":[{"batb":[[0,2.52,4],[1,2.5,46.1],[2,2.48,70.3]],"batl":[[0,2.54,4],[1,2.56,45.87],[2,3,1]],"ltp":2.52,"tv":12570.11,"id":26354927},{"batb":[[0,1.64,186.89],[1,1.63,299.5],[2,1.62,1204.52]],"batl":[[0,1.66,4],[1,1.67,153.07],[2,1.68,192.33]],"ltp":1.65,"tv":56669.75,"id":26354926}]}]}
{"op":"mcm","clk":"11876256029","pt":1723636632762,"mc":[{"id":"1.231659753","rc":[{"batb":[[2,2.48,43.44]],"ltp":2.52,"tv":12570.11,"id":26354927}]}]}
{"op":"mcm","clk":"11876256568","pt":1723636645968,"mc":[{"id":"1.231659753","rc":[{"batb":[[0,1.65,17.17],[1,1.64,186.89],[2,1.63,299.5]],"batl":[[0,1.66,20.68]],"ltp":1.65,"tv":56669.75,"id":26354926}]}]}
{"op":"mcm","clk":"11876257849","pt":1723636678924,"mc":[{"id":"1.231659753","rc":[{"batb":[[0,2.52,8.8]],"ltp":2.52,"tv":12570.11,"id":26354927}]}]}
{"op":"mcm","clk":"11876257975","pt":1723636681517,"mc":[{"id":"1.231659753","rc":[{"batb":[[0,1.64,186.89],[1,1.63,299.5],[2,1.62,1204.52]],"ltp":1.65,"tv":56669.75,"id":26354926}]}]}
{"op":"mcm","clk":"11876259672","pt":1723636725883,"mc":[{"id":"1.231659753","rc":[{"trd":[[2.5,535.46],[2.52,11688.62]],"batb":[[0,2.5,34.9],[1,2.48,43.44],[2,2.46,11.57]],"ltp":2.5,"tv":12610.11,"id":26354927},{"batb":[[0,1.65,59.44],[1,1.64,186.89],[2,1.63,299.5]],"batl":[[0,1.66,4]],"ltp":1.65,"tv":56669.75,"id":26354926}],"tv":69279.87}]}
{"op":"mcm","clk":"11876259711","pt":1723636726563,"mc":[{"id":"1.231659753","rc":[{"batb":[[1,2.48,70.3]],"batl":[[0,2.52,4.8],[1,2.54,4],[2,2.56,45.87]],"ltp":2.5,"tv":12610.11,"id":26354927}]}]}
{"op":"mcm","clk":"11876260758","pt":1723636753989,"mc":[{"id":"1.231659753","rc":[{"trd":[[1.66,18446.54]],"batl":[[0,1.66,2.65]],"ltp":1.66,"tv":56672.45,"id":26354926}],"tv":69282.57}]}
{"op":"mcm","clk":"11876262305","pt":1723636801356,"mc":[{"id":"1.231659753","rc":[{"batb":[[1,2.48,82.48]],"ltp":2.5,"tv":12610.11,"id":26354927},{"batb":[[1,1.64,215.05]],"ltp":1.66,"tv":56672.45,"id":26354926}]}]}
{"op":"mcm","clk":"11876262891","pt":1723636812859,"mc":[{"id":"1.231659753","rc":[{"trd":[[1.1,14.21],[2.48,145.64],[2.5,535.42],[2.52,11687.98],[2.54,42.46]],"batb":[[1,2.48,82.43],[2,2.46,11.56]],"batl":[[0,2.52,4.8],[2,2.56,45.87]],"ltp":2.5,"tv":12609.36,"id":26354927},{"trd":[[1.58,750.28],[1.61,1975.17],[1.63,120.51],[1.64,78.31],[1.65,16182.34],[1.66,18446.21],[1.67,9165.85],[1.73,4.76]],"batb":[[0,1.65,58.54],[1,1.64,215.04],[2,1.63,299.49]],"ltp":1.65,"tv":56667.57,"id":26354926}],"tv":69276.94}]}
{"op":"mcm","clk":"11876263433","pt":1723636823874,"mc":[{"id":"1.231659753","rc":[{"trd":[[1.66,18451.51],[1.67,9576.53]],"batl":[[0,1.67,46.18],[1,1.68,192.33],[2,1.69,519.15]],"ltp":1.67,"tv":57083.55,"id":26354926}],"tv":69692.92}]}
{"op":"mcm","clk":"11876263516","pt":1723636825987,"mc":[{"id":"1.231659753","rc":[{"batb":[[0,1.65,62.54]],"batl":[[0,1.67,50.18]],"ltp":1.67,"tv":57083.55,"id":26354926}]}]}
{"op":"mcm","clk":"11876263864","pt":1723636834874,"mc":[{"id":"1.231659753","rc":[{"batb":[[0,1.66,21.33],[1,1.65,62.54],[2,1.64,215.04]],"ltp":1.67,"tv":57083.55,"id":26354926}]}]}
{"op":"mcm","clk":"11876263883","pt":1723636835285,"mc":[{"id":"1.231659753","rc":[{"batb":[[1,1.65,90.26]],"ltp":1.67,"tv":57083.55,"id":26354926}]}]}
{"op":"mcm","clk":"11876265900","pt":1723636880048,"mc":[{"id":"1.231659753","rc":[{"trd":[[2.5,558.94]],"batb":[[0,2.5,23.14]],"batl":[[0,2.52,7.8]],"ltp":2.5,"tv":12632.88,"id":26354927}],"tv":69716.44}]}
{"op":"mcm","clk":"11876266519","pt":1723636896254,"mc":[{"id":"1.231659753","rc":[{"trd":[[1.66,18461.77]],"batb":[[0,1.66,16.2]],"ltp":1.66,"tv":57093.81,"id":26354926}],"tv":69726.7}]}
{"op":"mcm","clk":"11876270724","pt":1723636989535,"mc":[{"id":"1.231659753","rc":[{"trd":[[2.5,578.94]],"batb":[[0,2.5,13.14],[1,2.48,70.26]],"ltp":2.5,"tv":12652.88,"id":26354927},{"batb":[[1,1.65,62.54],[2,1.64,186.89]],"ltp":1.66,"tv":57093.81,"id":26354926}],"tv":69746.7}]}
{"op":"mcm","clk":"11876270892","pt":1723636992462,"mc":[{"id":"1.231659753","rc":[{"batl":[[0,2.52,11.8]],"ltp":2.5,"tv":12652.88,"id":26354927}]}]}
{"op":"mcm","clk":"11876272309","pt":1723637021356,"mc":[{"id":"1.231659753","rc":[{"batb":[[1,2.48,82.43]],"ltp":2.5,"tv":12652.88,"id":26354927},{"batb":[[1,1.65,90.26]],"ltp":1.66,"tv":57093.81,"id":26354926}]}]}
{"op":"mcm","clk":"11876275557","pt":1723637084714,"mc":[{"id":"1.231659753","rc":[{"trd":[[2.48,159.36],[2.5,605.22]],"batb":[[0,2.5,39.8],[1,2.48,115.69]],"batl":[[0,2.52,7.8],[1,2.56,45.87],[2,3,1]],"ltp":2.48,"tv":12692.88,"id":26354927}],"tv":69786.7}]}
{"op":"mcm","clk":"11876276117","pt":1723637098359,"mc":[{"id":"1.231659753","rc":[{"batb":[[0,2.5,43.8]],"ltp":2.48,"tv":12692.88,"id":26354927}]}]}
{"op":"mcm","clk":"11876277975","pt":1723637132403,"mc":[{"id":"1.231659753","rc":[{"batb":[[0,1.65,90.26],[1,1.64,186.89],[2,1.63,299.49]],"ltp":1.66,"tv":57093.81,"id":26354926}]}]}
{"op":"mcm","clk":"11876278477","pt":1723637144777,"mc":[{"id":"1.231659753","rc":[{"trd":[[1.66,19934.43]],"batb":[[0,1.65,225.81],[1,1.64,232.89]],"batl":[[0,1.66,63.67],[1,1.67,50.18],[2,1.68,192.33]],"ltp":1.66,"tv":58566.47,"id":26354926}],"tv":71259.36}]}
{"op":"mcm","clk":"11876278566","pt":1723637146485,"mc":[{"id":"1.231659753","rc":[{"batb":[[0,1.65,198.09],[1,1.64,261.04]],"ltp":1.66,"tv":58566.47,"id":26354926}]}]}
{"op":"mcm","clk":"11876278977","pt":1723637156289,"mc":[{"id":"1.231659753","rc":[{"trd":[[1.65,16225]],"batb":[[0,1.65,176.76],[1,1.64,244.04]],"ltp":1.65,"tv":58609.13,"id":26354926}],"tv":71302.02}]}
{"op":"mcm","clk":"11876279073","pt":1723637158806,"mc":[{"id":"1.231659753","rc":[{"batb":[[0,1.65,180.76]],"ltp":1.65,"tv":58609.13,"id":26354926}]}]}
{"op":"mcm","clk":"11876279227","pt":1723637162522,"mc":[{"id":"1.231659753","rc":[{"batl":[[2,3,1.52]],"ltp":2.48,"tv":12692.88,"id":26354927}]}]}
{"op":"mcm","clk":"11876279782","pt":1723637174112,"mc":[{"id":"1.231659753","rc":[{"trd":[[1.66,20026.81]],"batb":[[1,1.64,215.04],[2,1.63,22.57]],"batl":[[0,1.66,54.33]],"ltp":1.66,"tv":58701.51,"id":26354926}],"tv":71394.4}]}
{"op":"mcm","clk":"11876280124","pt":1723637181625,"mc":[{"id":"1.231659753","rc":[{"trd":[[2.52,11695.77]],"batb":[[0,2.5,55.81]],"batl":[[0,2.56,60.42],[1,3,1.52],[2,100,1.03]],"ltp":2.52,"tv":12700.68,"id":26354927},{"trd":[[1.65,16783.89],[1.66,20090.07]],"batb":[[0,1.64,186.89],[1,1.63,51.17],[2,1.62,10.67]],"batl":[[0,1.66,22.7]],"ltp":1.66,"tv":59323.66,"id":26354926}],"tv":72024.34}]}
{"op":"mcm","clk":"11876280170","pt":1723637182499,"mc":[{"id":"1.231659753","rc":[{"batb":[[0,1.65,13],[1,1.64,215.04],[2,1.63,51.17]],"ltp":1.66,"tv":59323.66,"id":26354926}]}]}
{"op":"mcm","clk":"11876280280","pt":1723637184821,"mc":[{"id":"1.231659753","rc":[{"batb":[[0,2.52,31.94],[1,2.5,55.81],[2,2.48,115.69]],"batl":[[0,2.56,6.29],[1,2.6,66.28],[2,3,1.52]],"ltp":2.52,"tv":12700.68,"id":26354927},{"trd":[[1.66,20317.93]],"batb":[[0,1.65,42],[1,1.64,134.87]],"batl":[[0,1.66,571.05]],"ltp":1.66,"tv":59551.52,"id":26354926}],"tv":72252.2}]}
{"op":"mcm","clk":"11876280300","pt":1723637185336,"mc":[{"id":"1.231659753","rc":[{"trd":[[1.66,20350.47]],"batb":[[0,1.65,26]],"batl":[[0,1.66,554.78]],"ltp":1.66,"tv":59584.06,"id":26354926}],"tv":72284.74}]}
{"op":"mcm","clk":"11876280466","pt":1723637189142,"mc":[{"id":"1.231659753","rc":[{"batb":[[0,2.52,35.94]],"ltp":2.52,"tv":12700.68,"id":26354927},{"batl":[[0,1.66,558.78]],"ltp":1.66,"tv":59584.06,"id":26354926}]}]}
{"op":"mcm","clk":"11876280925","pt":1723637198121,"mc":[{"id":"1.231659753","rc":[{"batl":[[0,1.66,526.78]],"ltp":1.66,"tv":59584.06,"id":26354926}]}]}
{"op":"mcm","clk":"11876281006","pt":1723637199512,"mc":[{"id":"1.231659753","rc":[{"batl":[[0,2.56,61.01]],"ltp":2.52,"tv":12700.68,"id":26354927},{"batl":[[0,1.66,112.43]],"ltp":1.66,"tv":59584.06,"id":26354926}]}]}
{"op":"mcm","clk":"11876281226","pt":1723637204526,"mc":[{"id":"1.231659753","rc":[{"batb":[[1,2.5,82.63],[2,2.48,88.87]],"ltp":2.52,"tv":12700.68,"id":26354927}]}]}
{"op":"mcm","clk":"11876281276","pt":1723637205554,"mc":[{"id":"1.231659753","rc":[{"trd":[[1.65,16835.89]],"batb":[[0,1.64,204.49],[1,1.63,51.17],[2,1.62,10.67]],"batl":[[0,1.65,42],[1,1.66,112.43],[2,1.67,50.18]],"ltp":1.65,"tv":59636.06,"id":26354926}],"tv":72336.74}]}
{"op":"mcm","clk":"11876281425","pt":1723637208757,"mc":[{"id":"1.231659753","rc":[{"trd":[[1.65,16919.89]],"batb":[[0,1.65,373.38],[1,1.64,204.49],[2,1.63,51.17]],"batl":[[0,1.66,112.43],[1,1.67,50.18],[2,1.68,192.33]],"ltp":1.65,"tv":59720.06,"id":26354926}],"tv":72420.74}]}
{"op":"mcm","clk":"11876281465","pt":1723637209629,"mc":[{"id":"1.231659753","rc":[{"batb":[[0,2.5,82.63],[1,2.48,88.87],[2,2.46,11.56]],"batl":[[0,2.52,2],[1,2.54,70.86],[2,2.56,59.01]],"ltp":2.52,"tv":12700.68,"id":26354927},{"batb":[[1,1.64,232.64]],"batl":[[0,1.66,4]],"ltp":1.65,"tv":59720.06,"id":26354926}]}]}
{"op":"mcm","clk":"11876281478","pt":1723637210041,"mc":[{"id":"1.231659753","rc":[{"batb":[[0,2.5,70.62]],"ltp":2.52,"tv":12700.68,"id":26354927}]}]}
{"op":"mcm","clk":"11876281719","pt":1723637215860,"mc":[{"id":"1.231659753","rc":[{"batb":[[0,1.65,482.47]],"ltp":1.65,"tv":59720.06,"id":26354926}]}]}
{"op":"mcm","clk":"11876281822","pt":1723637218541,"mc":[{"id":"1.231659753","rc":[{"batb":[[0,1.65,477.14]],"ltp":1.65,"tv":59720.06,"id":26354926}]}]}
{"op":"mcm","clk":"11876282013","pt":1723637222547,"mc":[{"id":"1.231659753","rc":[{"trd":[[2.5,653.22]],"batb":[[0,2.5,46.62]],"ltp":2.5,"tv":12748.68,"id":26354927}],"tv":72468.74}]}
{"op":"mcm","clk":"11876282298","pt":1723637228282,"mc":[{"id":"1.231659753","rc":[{"batl":[[0,2.52,73.42],[2,2.56,4.29]],"ltp":2.5,"tv":12748.68,"id":26354927},{"batb":[[1,1.64,134.87]],"ltp":1.65,"tv":59720.06,"id":26354926}]}]}
{"op":"mcm","clk":"11876282605","pt":1723637234441,"mc":[{"id":"1.231659753","rc":[{"batl":[[0,2.52,77.42]],"ltp":2.5,"tv":12748.68,"id":26354927}]}]}
{"op":"mcm","clk":"11876283317","pt":1723637249362,"mc":[{"id":"1.231659753","rc":[{"batb":[[0,1.65,405.15]],"ltp":1.65,"tv":59720.06,"id":26354926}]}]}
{"op":"mcm","clk":"11876283535","pt":1723637253492,"mc":[{"id":"1.231659753","rc":[{"batb":[[0,2.5,19.8],[1,2.48,115.69]],"ltp":2.5,"tv":12748.68,"id":26354927}]}]}
{"op":"mcm","clk":"11876284290","pt":1723637267986,"mc":[{"id":"1.231659753","rc":[{"batl":[[0,2.52,6]],"ltp":2.5,"tv":12748.68,"id":26354927}]}]}
{"op":"mcm","clk":"11876284633","pt":1723637274681,"mc":[{"id":"1.231659753","rc":[{"trd":[[1.66,20358.47]],"batb":[[0,1.66,31.2],[1,1.65,405.15],[2,1.64,134.87]],"batl":[[0,1.67,50.18],[1,1.68,192.33],[2,1.69,519.15]],"ltp":1.66,"tv":59728.06,"id":26354926}],"tv":72476.74}]}
{"op":"mcm","clk":"11876284666","pt":1723637275507,"mc":[{"id":"1.231659753","rc":[{"batb":[[1,1.65,432.87]],"ltp":1.66,"tv":59728.06,"id":26354926}]}]}
{"op":"mcm","clk":"11876285268","pt":1723637288815,"mc":[{"id":"1.231659753","rc":[{"batb":[[0,2.5,4]],"batl":[[0,2.52,77.42]],"ltp":2.5,"tv":12748.68,"id":26354927},{"batb":[[0,1.66,328.34]],"batl":[[0,1.67,4]],"ltp":1.66,"tv":59728.06,"id":26354926}]}]}
{"op":"mcm","clk":"11876285294","pt":1723637289431,"mc":[{"id":"1.231659753","rc":[{"batb":[[0,2.48,115.69],[1,2.46,11.56],[2,2.3,153.99]],"batl":[[1,2.56,4.29],[2,3,1.52]],"ltp":2.5,"tv":12748.68,"id":26354927},{"batb":[[0,1.66,436.77]],"ltp":1.66,"tv":59728.06,"id":26354926}]}]}
{"op":"mcm","clk":"11876285399","pt":1723637292107,"mc":[{"id":"1.231659753","rc":[{"batb":[[0,2.5,38.81],[1,2.48,115.69],[2,2.46,11.56]],"ltp":2.5,"tv":12748.68,"id":26354927},{"batb":[[0,1.66,328.34],[1,1.65,136.81]],"batl":[[0,1.67,98.81]],"ltp":1.66,"tv":59728.06,"id":26354926}]}]}
{"op":"mcm","clk":"11876285518","pt":1723637294930,"mc":[{"id":"1.231659753","rc":[{"batb":[[0,1.66,332.34]],"ltp":1.66,"tv":59728.06,"id":26354926}]}]}
{"op":"mcm","clk":"11876285758","pt":1723637300162,"mc":[{"id":"1.231659753","rc":[{"batl":[[1,1.68,32.33]],"ltp":1.66,"tv":59728.06,"id":26354926}]}]}
{"op":"mcm","clk":"11876287501","pt":1723637339909,"mc":[{"id":"1.231659753","rc":[{"trd":[[1.67,9638.93]],"batl":[[0,1.67,67.61]],"ltp":1.67,"tv":59790.46,"id":26354926}],"tv":72539.14}]}
{"op":"mcm","clk":"11876287598","pt":1723637341878,"mc":[{"id":"1.231659753","rc":[{"trd":[[1.67,9644.08]],"batl":[[0,1.67,65.03]],"ltp":1.67,"tv":59795.62,"id":26354926}],"tv":72544.3}]}
{"op":"mcm","clk":"11876287608","pt":1723637342081,"mc":[{"id":"1.231659753","rc":[{"batb":[[0,1.66,301.14]],"ltp":1.67,"tv":59795.62,"id":26354926}]}]}
{"op":"mcm","clk":"11876288447","pt":1723637359421,"mc":[{"id":"1.231659753","rc":[{"batl":[[2,2.92,1.03]],"ltp":2.5,"tv":12748.68,"id":26354927}]}]}
{"op":"mcm","clk":"11876288998","pt":1723637371130,"mc":[{"id":"1.231659753","rc":[{"batb":[[0,1.66,409.57]],"batl":[[0,1.68,96.97],[1,1.69,519.15],[2,1.7,401.15]],"ltp":1.67,"tv":59795.62,"id":26354926}]}]}
{"op":"mcm","clk":"11876289182","pt":1723637375242,"mc":[{"id":"1.231659753","rc":[{"batb":[[0,2.48,115.69],[1,2.46,11.56],[2,2.3,153.99]],"ltp":2.5,"tv":12748.68,"id":26354927}]}]}
{"op":"mcm","clk":"11876289311","pt":1723637378330,"mc":[{"id":"1.231659753","rc":[{"trd":[[1.66,20445.93]],"batb":[[0,1.66,365.84]],"ltp":1.66,"tv":59883.08,"id":26354926}],"tv":72631.76}]}
{"op":"mcm","clk":"11876289683","pt":1723637385713,"mc":[{"id":"1.231659753","rc":[{"batb":[[0,2.48,119.69]],"ltp":2.5,"tv":12748.68,"id":26354927},{"batl":[[0,1.68,100.97]],"ltp":1.66,"tv":59883.08,"id":26354926}]}]}
{"op":"mcm","clk":"11876290234","pt":1723637396534,"mc":[{"id":"1.231659753","rc":[{"batb":[[0,2.48,92.87],[1,2.46,38.9]],"ltp":2.5,"tv":12748.68,"id":26354927}]}]}
{"op":"mcm","clk":"11876290451","pt":1723637400933,"mc":[{"id":"1.231659753","rc":[{"batl":[[0,2.5,4],[1,2.52,77.42],[2,2.56,4.29]],"ltp":2.5,"tv":12748.68,"id":26354927}]}]}
{"op":"mcm","clk":"11876291373","pt":1723637419637,"mc":[{"id":"1.231659753","rc":[{"trd":[[2.5,657.22]],"batb":[[0,2.5,72],[1,2.48,92.87],[2,2.46,38.9]],"batl":[[0,2.52,2],[1,2.56,4.29],[2,2.92,1.03]],"ltp":2.5,"tv":12752.68,"id":26354927},{"trd":[[1.66,20676.81]],"batb":[[0,1.65,109.09],[1,1.64,134.87],[2,1.63,51.17]],"batl":[[0,1.66,324.55],[1,1.68,100.97],[2,1.69,519.15]],"ltp":1.66,"tv":60113.96,"id":26354926}],"tv":72866.64}]}
{"op":"mcm","clk":"11876291832","pt":1723637428978,"mc":[{"id":"1.231659753","rc":[{"trd":[[1.65,16921.55]],"batb":[[0,1.65,108.26]],"ltp":1.65,"tv":60115.62,"id":26354926}],"tv":72868.3}]}
{"op":"mcm","clk":"11876291967","pt":1723637431161,"mc":[{"id":"1.231659753","rc":[{"batb":[[0,2.5,76]],"ltp":2.5,"tv":12752.68,"id":26354927},{"batl":[[0,1.66,328.55]],"ltp":1.65,"tv":60115.62,"id":26354926}]}]}
{"op":"mcm","clk":"11876292660","pt":1723637444893,"mc":[{"id":"1.231659753","rc":[{"batb":[[0,2.5,102.82],[2,2.46,11.56]],"batl":[[0,2.56,6.29],[1,2.92,1.03],[2,3,1]],"ltp":2.5,"tv":12752.68,"id":26354927},{"batb":[[0,1.64,232.61],[1,1.63,51.17],[2,1.62,564.52]],"ltp":1.65,"tv":60115.62,"id":26354926}]}]}
{"op":"mcm","clk":"11876292665","pt":1723637445016,"mc":[{"id":"1.231659753","rc":[{"batl":[[0,2.56,52.63]],"ltp":2.5,"tv":12752.68,"id":26354927}]}]}
{"op":"mcm","clk":"11876292759","pt":1723637446853,"mc":[{"id":"1.231659753","rc":[{"batl":[[0,2.56,56.63]],"ltp":2.5,"tv":12752.68,"id":26354927},{"batb":[[0,1.64,236.61]],"batl":[[0,1.65,4],[1,1.66,328.55],[2,1.68,100.97]],"ltp":1.65,"tv":60115.62,"id":26354926}]}]}
{"op":"mcm","clk":"11876292800","pt":1723637447569,"mc":[{"id":"1.231659753","rc":[{"batb":[[0,2.5,114.83]],"ltp":2.5,"tv":12752.68,"id":26354927},{"batb":[[0,1.64,208.46]],"ltp":1.65,"tv":60115.62,"id":26354926}]}]}
{"op":"mcm","clk":"11876292998","pt":1723637452187,"mc":[{"id":"1.231659753","rc":[{"trd":[[1.64,86.31]],"batb":[[0,1.64,204.46]],"batl":[[0,1.66,328.55],[1,1.68,100.97],[2,1.69,519.15]],"ltp":1.64,"tv":60123.62,"id":26354926}],"tv":72876.3}]}
{"op":"mcm","clk":"11876293590","pt":1723637465986,"mc":[{"id":"1.231659753","rc":[{"trd":[[1.64,311.31]],"batb":[[0,1.64,91.96]],"ltp":1.64,"tv":60348.62,"id":26354926}],"tv":73101.3}]}
{"op":"mcm","clk":"11876293664","pt":1723637467616,"mc":[{"id":"1.231659753","rc":[{"batl":[[0,2.56,6.29],[1,2.62,69.22],[2,3,1.52]],"ltp":2.5,"tv":12752.68,"id":26354927},{"batb":[[0,1.64,87.96],[2,1.62,10.67]],"batl":[[0,1.66,436.98]],"ltp":1.64,"tv":60348.62,"id":26354926}]}]}
{"op":"mcm","clk":"11876294075","pt":1723637476532,"mc":[{"id":"1.231659753","rc":[{"batl":[[0,1.65,4],[1,1.66,436.98],[2,1.68,100.97]],"ltp":1.64,"tv":60348.62,"id":26354926}]}]}
{"op":"mcm","clk":"11876294824","pt":1723637491618,"mc":[{"id":"1.231659753","rc":[{"batb":[[0,2.52,4],[1,2.5,114.83],[2,2.48,92.87]],"ltp":2.5,"tv":12752.68,"id":26354927},{"batb":[[0,1.64,91.96]],"ltp":1.64,"tv":60348.62,"id":26354926}]}]}
{"op":"mcm","clk":"11876295466","pt":1723637505856,"mc":[{"id":"1.231659753","rc":[{"batl":[[1,1.66,437.62]],"ltp":1.64,"tv":60348.62,"id":26354926}]}]}
{"op":"mcm","clk":"11876296788","pt":1723637536896,"mc":[{"id":"1.231659753","rc":[{"trd":[[1.65,16929.55]],"batb":[[0,1.65,3],[1,1.64,94.96],[2,1.63,51.17]],"batl":[[0,1.66,437.62],[1,1.68,100.97],[2,1.69,519.15]],"ltp":1.65,"tv":60356.62,"id":26354926}],"tv":73109.3}]}
{"op":"mcm","clk":"11876296826","pt":1723637537672,"mc":[{"id":"1.231659753","rc":[{"batb":[[1,1.64,116.11]],"ltp":1.65,"tv":60356.62,"id":26354926}]}]}
{"op":"mcm","clk":"11876297202","pt":1723637545879,"mc":[{"id":"1.231659753","rc":[{"trd":[[1.65,16935.55]],"batb":[[0,1.64,28.15],[1,1.63,51.17],[2,1.62,10.67]],"batl":[[0,1.65,898.62],[1,1.66,437.62],[2,1.68,100.97]],"ltp":1.65,"tv":60362.62,"id":26354926}],"tv":73115.3}]}
{"op":"mcm","clk":"11876297245","pt":1723637546696,"mc":[{"id":"1.231659753","rc":[{"batl":[[0,2.56,4.29],[1,2.58,2],[2,2.62,69.22]],"ltp":2.5,"tv":12752.68,"id":26354927},{"batb":[[0,1.63,22.57],[1,1.62,39.73],[2,1.61,1087.59]],"ltp":1.65,"tv":60362.62,"id":26354926}]}]}
{"op":"mcm","clk":"11876297335","pt":1723637548795,"mc":[{"id":"1.231659753","rc":[{"batb":[[0,1.64,59.28],[1,1.63,22.57],[2,1.62,39.73]],"ltp":1.65,"tv":60362.62,"id":26354926}]}]}
{"op":"mcm","clk":"11876297425","pt":1723637550673,"mc":[{"id":"1.231659753","rc":[{"batb":[[1,1.63,51.17]],"ltp":1.65,"tv":60362.62,"id":26354926}]}]}
{"op":"mcm","clk":"11876297512","pt":1723637552109,"mc":[{"id":"1.231659753","rc":[{"batl":[[0,1.65,902.62]],"ltp":1.65,"tv":60362.62,"id":26354926}]}]}
{"op":"mcm","clk":"11876298084","pt":1723637563184,"mc":[{"id":"1.231659753","rc":[{"batl":[[1,1.66,441.56]],"ltp":1.65,"tv":60362.62,"id":26354926}]}]}
{"op":"mcm","clk":"11876298212","pt":1723637566383,"mc":[{"id":"1.231659753","rc":[{"batl":[[0,2.58,2],[1,2.62,69.22],[2,3,1.52]],"ltp":2.5,"tv":12752.68,"id":26354927},{"trd":[[1.65,16948.53]],"batl":[[0,1.65,896.13]],"ltp":1.65,"tv":60375.6,"id":26354926}],"tv":73128.28}]}
{"op":"mcm","clk":"11876298809","pt":1723637578906,"mc":[{"id":"1.231659753","rc":[{"batb":[[0,2.54,4],[1,2.52,4],[2,2.5,114.83]],"batl":[[0,2.6,2]],"ltp":2.5,"tv":12752.68,"id":26354927},{"trd":[[1.63,201.95],[1.64,429.87]],"batb":[[0,1.62,10.67],[1,1.61,1117.13],[2,1.6,15530.86]],"batl":[[0,1.65,1005.22],[2,1.68,36.33]],"ltp":1.63,"tv":60575.61,"id":26354926}],"tv":73328.29}]}
{"op":"mcm","clk":"11876298848","pt":1723637579728,"mc":[{"id":"1.231659753","rc":[{"batb":[[1,2.52,26.79]],"ltp":2.5,"tv":12752.68,"id":26354927},{"batb":[[0,1.62,142.04]],"batl":[[0,1.65,1001.22],[1,1.66,437.56],[2,1.68,32.33]],"ltp":1.63,"tv":60575.61,"id":26354926}]}]}
{"op":"mcm","clk":"11876298935","pt":1723637581709,"mc":[{"id":"1.231659753","rc":[{"batb":[[0,2.54,4.29]],"batl":[[0,2.56,4.29],[1,2.6,2],[2,2.62,69.22]],"ltp":2.5,"tv":12752.68,"id":26354927},{"batb":[[0,1.62,171.1]],"ltp":1.63,"tv":60575.61,"id":26354926}]}]}
{"op":"mcm","clk":"11876298971","pt":1723637582324,"mc":[{"id":"1.231659753","rc":[{"batl":[[0,1.65,1005.22]],"ltp":1.63,"tv":60575.61,"id":26354926}]}]}
{"op":"mcm","clk":"11876299292","pt":1723637589602,"mc":[{"id":"1.231659753","rc":[{"batb":[[1,2.52,53.61],[2,2.5,88.01]],"ltp":2.5,"tv":12752.68,"id":26354927}]}]}
{"op":"mcm","clk":"11876299498","pt":1723637593825,"mc":[{"id":"1.231659753","rc":[{"batb":[[0,1.62,491.1]],"ltp":1.63,"tv":60575.61,"id":26354926}]}]}
{"op":"mcm","clk":"11876299516","pt":1723637594134,"mc":[{"id":"1.231659753","rc":[{"batb":[[0,1.63,110.42],[1,1.62,491.1],[2,1.61,1117.13]],"batl":[[0,1.65,896.13]],"ltp":1.63,"tv":60575.61,"id":26354926}]}]}
{"op":"mcm","clk":"11876299574","pt":1723637595734,"mc":[{"id":"1.231659753","rc":[{"batb":[[0,1.63,139.01]],"ltp":1.63,"tv":60575.61,"id":26354926}]}]}
{"op":"mcm","clk":"11876302455","pt":1723637668492,"mc":[{"id":"1.231659753","rc":[{"trd":[[2.54,49.37]],"batb":[[0,2.52,54.44],[1,2.5,88.01],[2,2.48,52.75]],"ltp":2.54,"tv":12759.6,"id":26354927}],"tv":73335.21}]}
{"op":"mcm","clk":"11876305115","pt":1723637744583,"mc":[{"id":"1.231659753","rc":[{"batl":[[0,2.56,6.29],[1,2.62,69.22],[2,3,1.52]],"ltp":2.54,"tv":12759.6,"id":26354927},{"batb":[[0,1.64,49.23],[1,1.63,139.01],[2,1.62,491.1]],"ltp":1.63,"tv":60575.61,"id":26354926}]}]}
{"op":"mcm","clk":"11876305280","pt":1723637748863,"mc":[{"id":"1.231659753","rc":[{"batb":[[2,1.62,768.02]],"ltp":1.63,"tv":60575.61,"id":26354926}]}]}
{"op":"mcm","clk":"11876305958","pt":1723637769073,"mc":[{"id":"1.231659753","rc":[{"trd":[[1.65,17022.53]],"batl":[[0,1.65,859.13]],"ltp":1.65,"tv":60649.61,"id":26354926}],"tv":73409.21}]}
{"op":"mcm","clk":"11876306537","pt":1723637786312,"mc":[{"id":"1.231659753","rc":[{"trd":[[1.64,437.87]],"batb":[[0,1.64,45.23]],"ltp":1.64,"tv":60657.61,"id":26354926}],"tv":73417.21}]}
{"op":"mcm","clk":"11876306639","pt":1723637788837,"mc":[{"id":"1.231659753","rc":[{"trd":[[2.56,6.29]],"batb":[[0,2.54,14.83],[1,2.52,53.61],[2,2.5,88.01]],"batl":[[0,2.6,2],[1,2.92,1.03],[2,3,1]],"ltp":2.56,"tv":12765.89,"id":26354927},{"trd":[[1.63,489.36],[1.64,538.15]],"batb":[[0,1.62,656.91],[1,1.61,1117.13],[2,1.6,15548.05]],"batl":[[0,1.63,7092.92],[1,1.65,859.13],[2,1.66,437.56]],"ltp":1.63,"tv":61045.29,"id":26354926}],"tv":73811.18}]}
{"op":"mcm","clk":"11876306667","pt":1723637789615,"mc":[{"id":"1.231659753","rc":[{"batl":[[0,2.92,1.03],[1,3,1],[2,7.2,1.03]],"ltp":2.56,"tv":12765.89,"id":26354927},{"trd":[[1.63,1115.76]],"batb":[[0,1.62,712.85],[1,1.61,1218.13],[2,1.6,15565.05]],"batl":[[0,1.63,6779.72]],"ltp":1.63,"tv":61671.69,"id":26354926}],"tv":74437.58}]}
{"op":"mcm","clk":"11876306755","pt":1723637790809,"mc":[{"id":"1.231659753","rc":[{"batb":[[0,2.56,11.55],[1,2.54,14.83],[2,2.52,53.61]],"ltp":2.56,"tv":12765.89,"id":26354927}]}]}
