{"op":"mcm","clk":"11875955951","pt":1724068132056,"mc":[{"id":"1.232011572","marketDefinition":{"bspMarket":false,"turnInPlayEnabled":true,"persistenceEnabled":true,"marketBaseRate":5.0,"eventId":"33507999","eventTypeId":"4","numberOfWinners":1,"bettingType":"ODDS","marketType":"MATCH_ODDS","marketTime":"2024-08-19T21:00:00.000Z","suspendTime":"2024-08-19T21:00:00.000Z","bspReconciled":false,"complete":true,"inPlay":false,"crossMatching":true,"runnersVoidable":false,"numberOfActiveRunners":2,"betDelay":0,"status":"OPEN","runners":[{"status":"ACTIVE","sortPriority":1,"id":72857117,"name":"Caribbean Giants"},{"status":"ACTIVE","sortPriority":2,"id":72857115,"name":"Miami Lions"}],"regulators":["MR_INT"],"countryCode":"GB","discountAllowed":false,"timezone":"GMT","openDate":"2024-08-19T21:00:00.000Z","version":6086343952,"name":"Match Odds","eventName":"Caribbean Giants v Miami Lions"},"rc":[{"batb":[[0,1.03,200],[1,1.02,200],[2,1.01,220]],"ltp":0.0,"tv":0.0,"id":72857115},{"batb":[[0,1.03,200],[1,1.02,200],[2,1.01,220]],"ltp":0.0,"tv":0.0,"id":72857117}]}]}
{"op":"mcm","clk":"11875956035","pt":1724068133782,"mc":[{"id":"1.232011572","marketDefinition":{"bspMarket":false,"turnInPlayEnabled":true,"persistenceEnabled":true,"marketBaseRate":5.0,"eventId":"33507999","eventTypeId":"4","numberOfWinners":1,"bettingType":"ODDS","marketType":"MATCH_ODDS","marketTime":"2024-08-19T21:00:00.000Z","suspendTime":"2024-08-19T21:00:00.000Z","bspReconciled":false,"complete":true,"inPlay":false,"crossMatching":true,"runnersVoidable":false,"numberOfActiveRunners":2,"betDelay":0,"status":"OPEN","runners":[{"status":"ACTIVE","sortPriority":1,"id":72857117,"name":"Caribbean Giants"},{"status":"ACTIVE","sortPriority":2,"id":72857115,"name":"Miami Lions"}],"regulators":["MR_INT"],"countryCode":"GB","discountAllowed":true,"timezone":"GMT","openDate":"2024-08-19T21:00:00.000Z","version":6086343952,"name":"Match Odds","eventName":"Caribbean Giants v Miami Lions"}}]}
{"op":"mcm","clk":"11875973837","pt":1724068428476,"mc":[{"id":"1.232011572","rc":[{"batl":[[0,13,0.94]],"ltp":0.0,"tv":0.0,"id":72857115}]}]}
{"op":"mcm","clk":"11875974366","pt":1724068436917,"mc":[{"id":"1.232011572","rc":[{"batl":[[0,13,0.94]],"ltp":0.0,"tv":0.0,"id":72857117}]}]}
{"op":"mcm","clk":"11876112611","pt":1724070646393,"mc":[{"id":"1.232011572","rc":[{"batb":[[2,1.01,479.86]],"ltp":0.0,"tv":0.0,"id":72857115},{"batb":[[2,1.01,479.86]],"ltp":0.0,"tv":0.0,"id":72857117}]}]}
{"op":"mcm","clk":"11876245537","pt":1724072826566,"mc":[{"id":"1.232011572","rc":[{"batb":[[2,1.01,736.97]],"ltp":0.0,"tv":0.0,"id":72857115},{"batb":[[2,1.01,736.97]],"ltp":0.0,"tv":0.0,"id":72857117}]}]}
{"op":"mcm","clk":"11876252695","pt":1724072930669,"mc":[{"id":"1.232011572","rc":[{"batb":[[1,1.02,294.97]],"ltp":0.0,"tv":0.0,"id":72857115},{"batb":[[1,1.02,294.97]],"ltp":0.0,"tv":0.0,"id":72857117}]}]}
{"op":"mcm","clk":"11876253283","pt":1724072938669,"mc":[{"id":"1.232011572","rc":[{"batb":[[0,1.1,1000],[1,1.03,200],[2,1.02,294.97]],"ltp":0.0,"tv":0.0,"id":72857117}]}]}
{"op":"mcm","clk":"11876253485","pt":1724072941451,"mc":[{"id":"1.232011572","rc":[{"batb":[[0,1.1,1000],[1,1.03,200],[2,1.02,294.97]],"ltp":0.0,"tv":0.0,"id":72857115}]}]}
{"op":"mcm","clk":"11876257530","pt":1724072998811,"mc":[{"id":"1.232011572","rc":[{"batb":[[0,1.65,222],[1,1.1,1000],[2,1.03,200]],"ltp":0.0,"tv":0.0,"id":72857117}]}]}
{"op":"mcm","clk":"11876288250","pt":1724073277605,"mc":[{"id":"1.232011572","rc":[{"batb":[[0,1.66,7.2],[1,1.65,222],[2,1.1,1000]],"ltp":0.0,"tv":0.0,"id":72857117}]}]}
{"op":"mcm","clk":"11876298618","pt":1724073425553,"mc":[{"id":"1.232011572","rc":[{"batb":[[0,1.12,2.4],[1,1.1,1000],[2,1.03,200]],"ltp":0.0,"tv":0.0,"id":72857115}]}]}
{"op":"mcm","clk":"11876299670","pt":1724073440839,"mc":[{"id":"1.232011572","rc":[{"batb":[[0,1.1,1000],[1,1.03,200],[2,1.02,294.97]],"ltp":0.0,"tv":0.0,"id":72857115}]}]}
{"op":"mcm","clk":"11876301102","pt":1724073464094,"mc":[{"id":"1.232011572","rc":[{"batb":[[0,1.12,2.4],[1,1.1,1000],[2,1.03,200]],"ltp":0.0,"tv":0.0,"id":72857115}]}]}
{"op":"mcm","clk":"11876302438","pt":1724073484780,"mc":[{"id":"1.232011572","rc":[{"batb":[[0,1.1,1000],[1,1.03,200],[2,1.02,294.97]],"ltp":0.0,"tv":0.0,"id":72857115}]}]}
{"op":"mcm","clk":"11876306295","pt":1724073545941,"mc":[{"id":"1.232011572","rc":[{"batl":[[0,1.13,2.4],[1,13,0.94]],"ltp":0.0,"tv":0.0,"id":72857115}]}]}
{"op":"mcm","clk":"11876306667","pt":1724073551858,"mc":[{"id":"1.232011572","rc":[{"batl":[[0,13,0.94],[1,13,0]],"ltp":0.0,"tv":0.0,"id":72857115}]}]}
{"op":"mcm","clk":"11876317744","pt":1724073712816,"mc":[{"id":"1.232011572","rc":[{"batb":[[0,2.48,2.4],[1,1.1,1000],[2,1.03,200]],"ltp":0.0,"tv":0.0,"id":72857115}]}]}
{"op":"mcm","clk":"11876318213","pt":1724073719202,"mc":[{"id":"1.232011572","rc":[{"batb":[[0,1.1,1000],[1,1.03,200],[2,1.02,294.97]],"ltp":0.0,"tv":0.0,"id":72857115}]}]}
{"op":"mcm","clk":"11876320924","pt":1724073754480,"mc":[{"id":"1.232011572","rc":[{"batl":[[0,1.13,2.4],[1,13,0.94]],"ltp":0.0,"tv":0.0,"id":72857115}]}]}
{"op":"mcm","clk":"11876321298","pt":1724073759597,"mc":[{"id":"1.232011572","rc":[{"batl":[[0,13,0.94],[1,13,0]],"ltp":0.0,"tv":0.0,"id":72857115}]}]}
{"op":"mcm","clk":"11876326080","pt":1724073826909,"mc":[{"id":"1.232011572","rc":[{"batl":[[0,1.13,2.4],[1,13,0.94]],"ltp":0.0,"tv":0.0,"id":72857115}]}]}
{"op":"mcm","clk":"11876326486","pt":1724073832808,"mc":[{"id":"1.232011572","rc":[{"batl":[[0,13,0.94],[1,13,0]],"ltp":0.0,"tv":0.0,"id":72857115}]}]}
{"op":"mcm","clk":"11876328484","pt":1724073860587,"mc":[{"id":"1.232011572","rc":[{"batb":[[0,2.48,2.4],[1,1.1,1000],[2,1.03,200]],"ltp":0.0,"tv":0.0,"id":72857115}]}]}
{"op":"mcm","clk":"11876328880","pt":1724073865871,"mc":[{"id":"1.232011572","rc":[{"batb":[[0,1.1,1000],[1,1.03,200],[2,1.02,294.97]],"ltp":0.0,"tv":0.0,"id":72857115}]}]}
{"op":"mcm","clk":"11876332727","pt":1724073918897,"mc":[{"id":"1.232011572","rc":[{"batl":[[0,1.13,2.4],[1,13,0.94]],"ltp":0.0,"tv":0.0,"id":72857115}]}]}
{"op":"mcm","clk":"11876333159","pt":1724073923939,"mc":[{"id":"1.232011572","rc":[{"batl":[[0,13,0.94],[1,13,0]],"ltp":0.0,"tv":0.0,"id":72857115}]}]}
{"op":"mcm","clk":"11876335297","pt":1724073948651,"mc":[{"id":"1.232011572","rc":[{"batl":[[0,13,1.34]],"ltp":0.0,"tv":0.0,"id":72857117}]}]}
{"op":"mcm","clk":"11876335710","pt":1724073953951,"mc":[{"id":"1.232011572","rc":[{"batl":[[0,3,2.38],[1,13,0.94]],"ltp":0.0,"tv":0.0,"id":72857117}]}]}
{"op":"mcm","clk":"11876336827","pt":1724073968070,"mc":[{"id":"1.232011572","rc":[{"batl":[[0,13,0.94],[1,13,0]],"ltp":0.0,"tv":0.0,"id":72857117}]}]}
{"op":"mcm","clk":"11876341905","pt":1724074041856,"mc":[{"id":"1.232011572","rc":[{"batb":[[1,1.1,1000],[2,1.03,200]],"ltp":0.0,"tv":0.0,"id":72857117}]}]}
{"op":"mcm","clk":"11876367090","pt":1724074365554,"mc":[{"id":"1.232011572","rc":[{"batl":[[0,1.12,2.4],[1,13,0.94]],"ltp":0.0,"tv":0.0,"id":72857115}]}]}
{"op":"mcm","clk":"11876367593","pt":1724074371459,"mc":[{"id":"1.232011572","rc":[{"trd":[[1.12,4.81]],"batb":[[0,1.12,1.18],[1,1.1,1000],[2,1.03,200]],"batl":[[0,13,0.94],[1,13,0]],"ltp":1.12,"tv":4.8,"id":72857115}],"tv":4.8}]}
{"op":"mcm","clk":"11876367994","pt":1724074375948,"mc":[{"id":"1.232011572","rc":[{"batb":[[0,1.1,1000],[1,1.03,200],[2,1.02,294.97]],"ltp":1.12,"tv":4.8,"id":72857115}]}]}
{"op":"mcm","clk":"11876425537","pt":1724075104143,"mc":[{"id":"1.232011572","rc":[{"batb":[[0,1.12,2.4],[1,1.1,1000],[2,1.03,200]],"ltp":1.12,"tv":4.8,"id":72857115}]}]}
{"op":"mcm","clk":"11876429270","pt":1724075156843,"mc":[{"id":"1.232011572","rc":[{"batb":[[0,1.16,3.93],[1,1.12,2.4],[2,1.1,1000]],"ltp":1.12,"tv":4.8,"id":72857115}]}]}
{"op":"mcm","clk":"11876474128","pt":1724075744359,"mc":[{"id":"1.232011572","rc":[{"batl":[[0,2.22,0.08]],"ltp":0.0,"tv":0.0,"id":72857117}]}]}
{"op":"mcm","clk":"11876495341","pt":1724076031379,"mc":[{"id":"1.232011572","rc":[{"trd":[[1.12,4.82]],"batb":[[0,1.16,3.93],[1,1.12,2.42]],"ltp":1.12,"tv":4.81,"id":72857115},{"batb":[[0,1.1,1000],[1,1.03,200],[2,1.02,294.91]],"ltp":0.0,"tv":0.0,"id":72857117}],"tv":4.81}]}
{"op":"mcm","clk":"11876573606","pt":1724077085095,"mc":[{"id":"1.232011572","rc":[{"batb":[[0,1.16,86.39]],"ltp":1.12,"tv":4.81,"id":72857115},{"batb":[[0,1.11,82.46],[1,1.1,1000],[2,1.03,200]],"ltp":0.0,"tv":0.0,"id":72857117}]}]}
{"op":"mcm","clk":"11876604690","pt":1724077538239,"mc":[{"id":"1.232011572","rc":[{"batb":[[0,6,1.16],[1,1.11,82.46],[2,1.1,1000]],"ltp":0.0,"tv":0.0,"id":72857117}]}]}
{"op":"mcm","clk":"11876605715","pt":1724077553357,"mc":[{"id":"1.232011572","rc":[{"batb":[[0,1.11,82.46],[1,1.1,1000],[2,1.03,200]],"ltp":0.0,"tv":0.0,"id":72857117}]}]}
{"op":"mcm","clk":"11876609439","pt":1724077605230,"mc":[{"id":"1.232011572","rc":[{"batb":[[0,6,1.16],[1,1.11,82.46],[2,1.1,1000]],"ltp":0.0,"tv":0.0,"id":72857117}]}]}
{"op":"mcm","clk":"11876609896","pt":1724077611817,"mc":[{"id":"1.232011572","rc":[{"trd":[[1.2,5.79]],"batb":[[0,1.2,12.15],[1,1.16,86.39],[2,1.12,2.42]],"ltp":1.2,"tv":10.6,"id":72857115},{"trd":[[6,1.16]],"batb":[[0,1.11,82.46],[1,1.1,1000],[2,1.03,200]],"ltp":6.0,"tv":1.15,"id":72857117}],"tv":11.76}]}
{"op":"mcm","clk":"11876610497","pt":1724077620556,"mc":[{"id":"1.232011572","rc":[{"batb":[[0,1.16,86.39],[1,1.12,2.42],[2,1.1,1000]],"ltp":1.2,"tv":10.6,"id":72857115}]}]}
{"op":"mcm","clk":"11876614180","pt":1724077674790,"mc":[{"id":"1.232011572","rc":[{"batl":[[0,1.18,1.54]],"ltp":1.2,"tv":10.6,"id":72857115}]}]}
{"op":"mcm","clk":"11876614629","pt":1724077680870,"mc":[{"id":"1.232011572","rc":[{"trd":[[1.18,3.09]],"batb":[[0,1.18,2.04],[1,1.16,86.39],[2,1.12,2.42]],"ltp":1.18,"tv":13.69,"id":72857115}],"tv":14.85}]}
{"op":"mcm","clk":"11876615229","pt":1724077689588,"mc":[{"id":"1.232011572","rc":[{"batb":[[0,1.16,86.39],[1,1.12,2.42],[2,1.1,1000]],"ltp":1.18,"tv":13.69,"id":72857115}]}]}
{"op":"mcm","clk":"11876618168","pt":1724077729348,"mc":[{"id":"1.232011572","rc":[{"batl":[[0,1.2,1.54]],"ltp":1.18,"tv":13.69,"id":72857115}]}]}
{"op":"mcm","clk":"11876618483","pt":1724077733433,"mc":[{"id":"1.232011572","rc":[{"trd":[[1.2,8.87]],"batb":[[0,1.2,2.04],[1,1.16,86.39],[2,1.12,2.42]],"ltp":1.2,"tv":16.77,"id":72857115}],"tv":17.93}]}
{"op":"mcm","clk":"11876618769","pt":1724077737050,"mc":[{"id":"1.232011572","rc":[{"batb":[[0,1.16,86.39],[1,1.12,2.42],[2,1.1,1000]],"ltp":1.2,"tv":16.77,"id":72857115}]}]}
{"op":"mcm","clk":"11876657703","pt":1724078311876,"mc":[{"id":"1.232011572","rc":[{"batb":[[0,5.9,1.16],[1,1.11,82.46],[2,1.1,1000]],"ltp":6.0,"tv":1.15,"id":72857117}]}]}
{"op":"mcm","clk":"11876658146","pt":1724078318486,"mc":[{"id":"1.232011572","rc":[{"trd":[[1.21,5.64]],"batb":[[0,1.21,12.29],[1,1.16,86.39],[2,1.12,2.42]],"ltp":1.21,"tv":22.42,"id":72857115},{"trd":[[5.9,1.16]],"batb":[[0,1.11,82.46],[1,1.1,1000],[2,1.03,200]],"ltp":5.9,"tv":2.31,"id":72857117}],"tv":24.73}]}
{"op":"mcm","clk":"11876658486","pt":1724078323479,"mc":[{"id":"1.232011572","rc":[{"batb":[[0,1.16,86.39],[1,1.12,2.42],[2,1.1,1000]],"ltp":1.21,"tv":22.42,"id":72857115}]}]}
{"op":"mcm","clk":"11876667455","pt":1724078445046,"mc":[{"id":"1.232011572","rc":[{"batb":[[0,5,1.16],[1,1.11,82.46],[2,1.1,1000]],"ltp":5.9,"tv":2.31,"id":72857117}]}]}
{"op":"mcm","clk":"11876667936","pt":1724078450822,"mc":[{"id":"1.232011572","rc":[{"trd":[[1.25,4.63]],"batb":[[0,1.25,13.3],[1,1.16,86.39],[2,1.12,2.42]],"ltp":1.25,"tv":27.05,"id":72857115},{"trd":[[5,1.16]],"batb":[[0,1.11,82.46],[1,1.1,1000],[2,1.03,200]],"ltp":5.0,"tv":3.47,"id":72857117}],"tv":30.52}]}
{"op":"mcm","clk":"11876668231","pt":1724078454525,"mc":[{"id":"1.232011572","rc":[{"batb":[[0,1.16,86.39],[1,1.12,2.42],[2,1.1,1000]],"ltp":1.25,"tv":27.05,"id":72857115}]}]}
{"op":"mcm","clk":"11876670184","pt":1724078481139,"mc":[{"id":"1.232011572","rc":[{"batb":[[0,4.3,1.16],[1,1.11,82.46],[2,1.1,1000]],"ltp":5.0,"tv":3.47,"id":72857117}]}]}
{"op":"mcm","clk":"11876670514","pt":1724078486479,"mc":[{"id":"1.232011572","rc":[{"trd":[[1.31,3.59]],"ltp":1.31,"tv":30.63,"id":72857115},{"trd":[[4.3,1.1]],"batb":[[0,1.11,82.52],[1,1.1,1000],[2,1.03,200]],"ltp":4.3,"tv":4.56,"id":72857117}],"tv":35.2}]}
{"op":"mcm","clk":"11876670729","pt":1724078489672,"mc":[{"id":"1.232011572","rc":[{"batb":[[0,1.11,82.46]],"ltp":4.3,"tv":4.56,"id":72857117}]}]}
{"op":"mcm","clk":"11876672897","pt":1724078523532,"mc":[{"id":"1.232011572","rc":[{"batl":[[0,1.32,1.16]],"ltp":1.31,"tv":30.63,"id":72857115}]}]}
{"op":"mcm","clk":"11876672998","pt":1724078525230,"mc":[{"id":"1.232011572","rc":[{"batb":[[0,1.22,3.93],[1,1.16,82.46],[2,1.12,2.42]],"ltp":1.31,"tv":30.63,"id":72857115}]}]}
{"op":"mcm","clk":"11876673070","pt":1724078526513,"mc":[{"id":"1.232011572","rc":[{"trd":[[1.32,2.31]],"batb":[[0,1.32,2.43],[1,1.22,3.93],[2,1.16,82.46]],"ltp":1.32,"tv":32.95,"id":72857115}],"tv":37.52}]}
{"op":"mcm","clk":"11876673326","pt":1724078530915,"mc":[{"id":"1.232011572","rc":[{"batb":[[0,1.22,3.93],[1,1.16,82.46],[2,1.12,2.42]],"ltp":1.32,"tv":32.95,"id":72857115}]}]}
{"op":"mcm","clk":"11876674125","pt":1724078542451,"mc":[{"id":"1.232011572","rc":[{"batb":[[0,1.22,4.88]],"ltp":1.32,"tv":32.95,"id":72857115}]}]}
{"op":"mcm","clk":"11876674703","pt":1724078550835,"mc":[{"id":"1.232011572","rc":[{"batl":[[0,6,0.94]],"ltp":1.32,"tv":32.95,"id":72857115}]}]}
{"op":"mcm","clk":"11876690450","pt":1724078637658,"mc":[{"id":"1.232011572","rc":[{"batl":[[0,6.6,0.94]],"ltp":1.32,"tv":32.95,"id":72857115}]}]}
{"op":"mcm","clk":"11876747233","pt":1724079394728,"mc":[{"id":"1.232011572","rc":[{"batl":[[0,1.37,1.54],[1,6.6,0.94]],"ltp":1.32,"tv":32.95,"id":72857115}]}]}
{"op":"mcm","clk":"11876747791","pt":1724079402425,"mc":[{"id":"1.232011572","rc":[{"trd":[[1.37,3.09]],"batb":[[0,1.37,2.04],[1,1.22,4.88],[2,1.16,82.46]],"batl":[[0,6.6,0.94],[1,6.6,0]],"ltp":1.37,"tv":36.04,"id":72857115}],"tv":40.6}]}
{"op":"mcm","clk":"11876748029","pt":1724079405862,"mc":[{"id":"1.232011572","rc":[{"batb":[[0,1.22,4.88],[1,1.16,82.46],[2,1.12,2.42]],"ltp":1.37,"tv":36.04,"id":72857115}]}]}
{"op":"mcm","clk":"11876748948","pt":1724079418166,"mc":[{"id":"1.232011572","rc":[{"batb":[[0,3,1.16],[1,1.11,82.46],[2,1.1,1000]],"ltp":4.3,"tv":4.56,"id":72857117}]}]}
{"op":"mcm","clk":"11876749178","pt":1724079420848,"mc":[{"id":"1.232011572","rc":[{"trd":[[1.5,2.31]],"batb":[[0,1.5,1.27],[1,1.22,4.88],[2,1.16,82.46]],"ltp":1.5,"tv":38.35,"id":72857115},{"trd":[[3,1.16]],"batb":[[0,1.11,82.46],[1,1.1,1000],[2,1.03,200]],"ltp":3.0,"tv":5.72,"id":72857117}],"tv":44.08}]}
{"op":"mcm","clk":"11876749377","pt":1724079423473,"mc":[{"id":"1.232011572","rc":[{"batb":[[0,1.22,4.88],[1,1.16,82.46],[2,1.12,2.42]],"ltp":1.5,"tv":38.35,"id":72857115}]}]}
{"op":"mcm","clk":"11876751437","pt":1724079449868,"mc":[{"id":"1.232011572","rc":[{"batl":[[0,1.45,1.16],[1,6.6,0.94]],"ltp":1.5,"tv":38.35,"id":72857115}]}]}
{"op":"mcm","clk":"11876751707","pt":1724079453511,"mc":[{"id":"1.232011572","rc":[{"trd":[[1.45,2.31]],"batb":[[0,1.45,2.43],[1,1.22,4.88],[2,1.16,82.46]],"batl":[[0,6.6,0.94],[1,6.6,0]],"ltp":1.45,"tv":40.67,"id":72857115}],"tv":46.39}]}
{"op":"mcm","clk":"11876752006","pt":1724079456907,"mc":[{"id":"1.232011572","rc":[{"batb":[[0,1.22,4.88],[1,1.16,82.46],[2,1.12,2.42]],"ltp":1.45,"tv":40.67,"id":72857115}]}]}
{"op":"mcm","clk":"11876754144","pt":1724079483414,"mc":[{"id":"1.232011572","rc":[{"batl":[[0,1.54,1.16],[1,6.6,0.94]],"ltp":1.45,"tv":40.67,"id":72857115}]}]}
{"op":"mcm","clk":"11876754428","pt":1724079486445,"mc":[{"id":"1.232011572","rc":[{"trd":[[1.54,2.31]],"batb":[[0,1.54,2.43],[1,1.22,4.88],[2,1.16,82.46]],"batl":[[0,6.6,0.94],[1,6.6,0]],"ltp":1.54,"tv":42.98,"id":72857115}],"tv":48.71}]}
{"op":"mcm","clk":"11876754750","pt":1724079490555,"mc":[{"id":"1.232011572","rc":[{"batb":[[0,1.22,4.88],[1,1.16,82.46],[2,1.12,2.42]],"ltp":1.54,"tv":42.98,"id":72857115}]}]}
{"op":"mcm","clk":"11876789239","pt":1724079947835,"mc":[{"id":"1.232011572","rc":[{"trd":[[1.12,4.82],[1.18,3.08],[1.2,8.86],[1.21,5.63],[1.25,4.62],[1.31,3.58],[1.32,2.31],[1.37,3.08],[1.45,2.31],[1.5,2.31],[1.54,2.31]],"batb":[[0,1.22,4.87],[1,1.16,82.81],[2,1.12,2.42]],"batl":[[0,10,2.73]],"ltp":1.54,"tv":42.9,"id":72857115},{"trd":[[3,1.16],[4.3,1.09],[5,1.16],[5.9,1.16],[6,1.16]],"batb":[[0,1.11,82.81]],"ltp":3.0,"tv":5.71,"id":72857117}],"tv":48.62}]}
{"op":"mcm","clk":"11876804473","pt":1724080148602,"mc":[{"id":"1.232011572","rc":[{"batl":[[0,6.6,0.94]],"ltp":1.54,"tv":42.9,"id":72857115}]}]}
{"op":"mcm","clk":"11876863975","pt":1724080867327,"mc":[{"id":"1.232011572","rc":[{"batb":[[2,1.1,1000]],"ltp":1.54,"tv":42.9,"id":72857115}]}]}
{"op":"mcm","clk":"11876971644","pt":1724082074840,"mc":[{"id":"1.232011572","rc":[{"batb":[[0,1.23,38.18],[1,1.22,3.92],[2,1.16,82.81]],"ltp":1.54,"tv":42.9,"id":72857115},{"batb":[[0,1.18,47.58],[1,1.11,82.81],[2,1.1,1000]],"ltp":3.0,"tv":5.71,"id":72857117}]}]}
{"op":"mcm","clk":"11877038587","pt":1724082831432,"mc":[{"id":"1.232011572","rc":[{"batl":[[0,1.2,2.31]],"ltp":3.0,"tv":5.71,"id":72857117}]}]}
{"op":"mcm","clk":"11877039699","pt":1724082843926,"mc":[{"id":"1.232011572","rc":[{"batb":[[0,1.24,10.94],[1,1.23,37.24],[2,1.22,3.92]],"ltp":1.54,"tv":42.9,"id":72857115},{"trd":[[1.2,4.62]],"batb":[[0,1.2,1.27],[1,1.18,47.58],[2,1.11,82.81]],"ltp":1.2,"tv":10.33,"id":72857117}],"tv":53.24}]}
{"op":"mcm","clk":"11877040027","pt":1724082847227,"mc":[{"id":"1.232011572","rc":[{"batb":[[0,1.23,38.18],[1,1.22,3.92],[2,1.16,82.81]],"ltp":1.54,"tv":42.9,"id":72857115}]}]}
{"op":"mcm","clk":"11877040132","pt":1724082848568,"mc":[{"id":"1.232011572","rc":[{"batb":[[0,1.18,47.58],[1,1.11,82.81],[2,1.1,1000]],"ltp":1.2,"tv":10.33,"id":72857117}]}]}
{"op":"mcm","clk":"11877042515","pt":1724082872816,"mc":[{"id":"1.232011572","rc":[{"batb":[[0,1.24,10.94],[1,1.23,37.24],[2,1.22,3.92]],"ltp":1.54,"tv":42.9,"id":72857115}]}]}
{"op":"mcm","clk":"11877042877","pt":1724082876324,"mc":[{"id":"1.232011572","rc":[{"batb":[[0,1.23,38.18],[1,1.22,3.92],[2,1.16,82.81]],"ltp":1.54,"tv":42.9,"id":72857115}]}]}
{"op":"mcm","clk":"11877043765","pt":1724082886017,"mc":[{"id":"1.232011572","rc":[{"batb":[[0,1.24,10.94],[1,1.23,37.24],[2,1.22,3.92]],"ltp":1.54,"tv":42.9,"id":72857115}]}]}
{"op":"mcm","clk":"11877044132","pt":1724082889526,"mc":[{"id":"1.232011572","rc":[{"batb":[[0,1.23,38.18],[1,1.22,3.92],[2,1.16,82.81]],"ltp":1.54,"tv":42.9,"id":72857115}]}]}
{"op":"mcm","clk":"11877044606","pt":1724082894321,"mc":[{"id":"1.232011572","rc":[{"batb":[[0,1.24,10.94],[1,1.23,37.24],[2,1.22,3.92]],"ltp":1.54,"tv":42.9,"id":72857115}]}]}
{"op":"mcm","clk":"11877044910","pt":1724082897932,"mc":[{"id":"1.232011572","rc":[{"batb":[[0,1.23,38.18],[1,1.22,3.92],[2,1.16,82.81]],"ltp":1.54,"tv":42.9,"id":72857115}]}]}
{"op":"mcm","clk":"11877045495","pt":1724082903536,"mc":[{"id":"1.232011572","rc":[{"batb":[[0,1.24,10.94],[1,1.23,37.24],[2,1.22,3.92]],"ltp":1.54,"tv":42.9,"id":72857115}]}]}
{"op":"mcm","clk":"11877045888","pt":1724082907143,"mc":[{"id":"1.232011572","rc":[{"batb":[[0,1.23,38.18],[1,1.22,3.92],[2,1.16,82.81]],"ltp":1.54,"tv":42.9,"id":72857115}]}]}
{"op":"mcm","clk":"11877047181","pt":1724082919077,"mc":[{"id":"1.232011572","rc":[{"batb":[[0,1.24,10.94],[1,1.23,37.24],[2,1.22,3.92]],"ltp":1.54,"tv":42.9,"id":72857115}]}]}
{"op":"mcm","clk":"11877047550","pt":1724082922651,"mc":[{"id":"1.232011572","rc":[{"batb":[[0,1.23,38.18],[1,1.22,3.92],[2,1.16,82.81]],"ltp":1.54,"tv":42.9,"id":72857115}]}]}
{"op":"mcm","clk":"11877048437","pt":1724082930991,"mc":[{"id":"1.232011572","rc":[{"batb":[[0,1.24,10.94],[1,1.23,37.24],[2,1.22,3.92]],"ltp":1.54,"tv":42.9,"id":72857115}]}]}
{"op":"mcm","clk":"11877048775","pt":1724082934498,"mc":[{"id":"1.232011572","rc":[{"batb":[[0,1.23,38.18],[1,1.22,3.92],[2,1.16,82.81]],"ltp":1.54,"tv":42.9,"id":72857115}]}]}
{"op":"mcm","clk":"11877053939","pt":1724082993334,"mc":[{"id":"1.232011572","rc":[{"batb":[[0,1.24,10.94],[1,1.23,37.24],[2,1.22,3.92]],"ltp":1.54,"tv":42.9,"id":72857115},{"batb":[[2,1.03,200]],"ltp":1.2,"tv":10.33,"id":72857117}]}]}
{"op":"mcm","clk":"11877054217","pt":1724082996745,"mc":[{"id":"1.232011572","rc":[{"batb":[[0,1.23,38.18],[1,1.22,3.92],[2,1.16,82.81]],"ltp":1.54,"tv":42.9,"id":72857115}]}]}
{"op":"mcm","clk":"11877054846","pt":1724083004576,"mc":[{"id":"1.232011572","rc":[{"batb":[[0,1.24,10.94],[1,1.23,37.24],[2,1.22,3.92]],"ltp":1.54,"tv":42.9,"id":72857115},{"batb":[[2,1.04,1250]],"ltp":1.2,"tv":10.33,"id":72857117}]}]}
{"op":"mcm","clk":"11877054937","pt":1724083005663,"mc":[{"id":"1.232011572","rc":[{"batb":[[1,1.23,472.02]],"ltp":1.54,"tv":42.9,"id":72857115},{"batb":[[0,1.33,151.52],[1,1.23,434.78],[2,1.19,526.32]],"ltp":1.2,"tv":10.33,"id":72857117}]}]}
{"op":"mcm","clk":"11877054954","pt":1724083005870,"mc":[{"id":"1.232011572","rc":[{"batb":[[0,1.33,152.46],[1,1.24,10],[2,1.23,472.02]],"ltp":1.54,"tv":42.9,"id":72857115}]}]}
{"op":"mcm","clk":"11877055124","pt":1724083007981,"mc":[{"id":"1.232011572","rc":[{"batb":[[1,1.23,472.02],[2,1.22,3.92]],"ltp":1.54,"tv":42.9,"id":72857115}]}]}
{"op":"mcm","clk":"11877058852","pt":1724083053821,"mc":[{"id":"1.232011572","rc":[{"batb":[[0,1.42,1.48],[1,1.33,151.52],[2,1.23,472.02]],"ltp":1.54,"tv":42.9,"id":72857115}]}]}
{"op":"mcm","clk":"11877059609","pt":1724083062441,"mc":[{"id":"1.232011572","rc":[{"batb":[[0,1.33,152.06]],"ltp":1.2,"tv":10.33,"id":72857117}]}]}
{"op":"mcm","clk":"11877076629","pt":1724083248738,"mc":[{"id":"1.232011572","rc":[{"trd":[[1.12,4.82],[1.18,3.08],[1.2,8.86],[1.21,5.64],[1.25,4.62],[1.31,3.58],[1.37,3.08],[1.5,2.31],[3,0.27]],"batb":[[0,3.95,2.04],[1,1.42,1.48],[2,1.33,151.52]],"ltp":3.0,"tv":43.2,"id":72857115},{"trd":[[1.2,4.62],[1.5,0.54]],"batb":[[0,1.33,151.52]],"ltp":1.5,"tv":10.87,"id":72857117}],"tv":54.07}]}
{"op":"mcm","clk":"11877077377","pt":1724083255831,"mc":[{"id":"1.232011572","rc":[{"trd":[[3.95,2.04]],"batb":[[0,1.42,1.48],[1,1.33,151.52],[2,1.23,472.04]],"ltp":3.95,"tv":45.24,"id":72857115},{"trd":[[1.34,6.02]],"batb":[[0,1.34,11.89],[1,1.33,151.52],[2,1.23,434.78]],"ltp":1.34,"tv":16.89,"id":72857117}],"tv":62.13}]}
{"op":"mcm","clk":"11877077690","pt":1724083259519,"mc":[{"id":"1.232011572","rc":[{"batb":[[0,1.33,151.52],[1,1.23,434.78],[2,1.19,526.32]],"ltp":1.34,"tv":16.89,"id":72857117}]}]}
{"op":"mcm","clk":"11877086329","pt":1724083344947,"mc":[{"id":"1.232011572","rc":[{"batl":[[0,1.35,2.31]],"ltp":1.34,"tv":16.89,"id":72857117}]}]}
{"op":"mcm","clk":"11877086607","pt":1724083347854,"mc":[{"id":"1.232011572","rc":[{"trd":[[1.35,4.62]],"batb":[[0,1.35,1.27],[1,1.33,151.52],[2,1.23,434.78]],"ltp":1.35,"tv":21.51,"id":72857117}],"tv":66.75}]}
{"op":"mcm","clk":"11877086963","pt":1724083351441,"mc":[{"id":"1.232011572","rc":[{"batb":[[0,1.33,151.52],[1,1.23,434.78],[2,1.19,526.32]],"ltp":1.35,"tv":21.51,"id":72857117}]}]}
{"op":"mcm","clk":"11877094225","pt":1724083427768,"mc":[{"id":"1.232011572","rc":[{"batb":[[0,2.98,1.54],[1,1.33,151.52],[2,1.23,434.78]],"ltp":1.35,"tv":21.51,"id":72857117}]}]}
{"op":"mcm","clk":"11877094666","pt":1724083432428,"mc":[{"id":"1.232011572","rc":[{"trd":[[1.51,3.04]],"batb":[[0,1.5,1.08],[1,1.33,152.46]],"ltp":1.51,"tv":48.28,"id":72857115},{"trd":[[2.98,1.54]],"batb":[[0,1.33,151.52],[1,1.23,434.78],[2,1.19,526.32]],"ltp":2.98,"tv":23.05,"id":72857117}],"tv":71.33}]}
{"op":"mcm","clk":"11877094709","pt":1724083433048,"mc":[{"id":"1.232011572","rc":[{"batb":[[0,1.51,1.08]],"ltp":1.51,"tv":48.28,"id":72857115}]}]}
{"op":"mcm","clk":"11877095156","pt":1724083437822,"mc":[{"id":"1.232011572","rc":[{"batb":[[0,1.42,1.48],[1,1.33,151.52]],"ltp":1.51,"tv":48.28,"id":72857115}]}]}
{"op":"mcm","clk":"11877100546","pt":1724083495637,"mc":[{"id":"1.232011572","rc":[{"batb":[[1,1.34,10],[2,1.33,151.52]],"ltp":1.51,"tv":48.28,"id":72857115}]}]}
{"op":"mcm","clk":"11877100884","pt":1724083498847,"mc":[{"id":"1.232011572","rc":[{"batb":[[1,1.33,151.52],[2,1.23,472.04]],"ltp":1.51,"tv":48.28,"id":72857115}]}]}
{"op":"mcm","clk":"11877112655","pt":1724083628596,"mc":[{"id":"1.232011572","rc":[{"batl":[[0,3.5,0.94]],"ltp":1.51,"tv":48.28,"id":72857115}]}]}
{"op":"mcm","clk":"11877118035","pt":1724083686447,"mc":[{"id":"1.232011572","rc":[{"batb":[[0,1.33,152.06]],"ltp":2.98,"tv":23.05,"id":72857117}]}]}
{"op":"mcm","clk":"11877134674","pt":1724083875261,"mc":[{"id":"1.232011572","rc":[{"batb":[[2,1.23,434.78]],"ltp":1.51,"tv":48.28,"id":72857115}]}]}
{"op":"mcm","clk":"11877138165","pt":1724083913647,"mc":[{"id":"1.232011572","rc":[{"batb":[[1,1.34,25.21],[2,1.33,151.52]],"ltp":1.51,"tv":48.28,"id":72857115},{"batb":[[0,1.41,21.44],[1,1.33,151.52],[2,1.23,434.78]],"ltp":2.98,"tv":23.05,"id":72857117}]}]}
{"op":"mcm","clk":"11877169780","pt":1724084155492,"mc":[{"id":"1.232011572","rc":[{"batb":[[0,1.34,25.74],[1,1.33,151.52],[2,1.23,434.78]],"ltp":1.51,"tv":48.28,"id":72857115}]}]}
{"op":"mcm","clk":"11877171627","pt":1724084174412,"mc":[{"id":"1.232011572","rc":[{"batb":[[0,1.42,4.11],[1,1.34,25.21],[2,1.33,151.52]],"ltp":1.51,"tv":48.28,"id":72857115}]}]}
{"op":"mcm","clk":"11877173725","pt":1724084196663,"mc":[{"id":"1.232011572","rc":[{"batb":[[0,1.43,14.54],[1,1.42,3.58],[2,1.34,25.21]],"batl":[[0,3.3,2.13]],"ltp":1.51,"tv":48.28,"id":72857115}]}]}
{"op":"mcm","clk":"11877173922","pt":1724084199172,"mc":[{"id":"1.232011572","rc":[{"batb":[[0,1.43,10.54]],"ltp":1.51,"tv":48.28,"id":72857115}]}]}
{"op":"mcm","clk":"11877173998","pt":1724084200053,"mc":[{"id":"1.232011572","rc":[{"batb":[[0,1.42,4.11],[1,1.34,25.21],[2,1.33,151.52]],"ltp":1.51,"tv":48.28,"id":72857115}]}]}
{"op":"mcm","clk":"11877180736","pt":1724084275148,"mc":[{"id":"1.232011572","rc":[{"batb":[[0,1.43,14.54],[1,1.42,3.58],[2,1.35,7.66]],"ltp":1.51,"tv":48.28,"id":72857115},{"batb":[[1,1.34,6.62],[2,1.33,151.52]],"ltp":2.98,"tv":23.05,"id":72857117}]}]}
{"op":"mcm","clk":"11877180914","pt":1724084277338,"mc":[{"id":"1.232011572","rc":[{"batb":[[0,1.43,10.54]],"ltp":1.51,"tv":48.28,"id":72857115}]}]}
{"op":"mcm","clk":"11877181004","pt":1724084278372,"mc":[{"id":"1.232011572","rc":[{"batb":[[0,1.42,4.11],[1,1.35,7.66],[2,1.34,25.21]],"ltp":1.51,"tv":48.28,"id":72857115}]}]}
{"op":"mcm","clk":"11877201215","pt":1724084492124,"mc":[{"id":"1.232011572","rc":[{"batb":[[0,1.43,14.54],[1,1.42,3.58],[2,1.35,7.66]],"ltp":1.51,"tv":48.28,"id":72857115}]}]}
{"op":"mcm","clk":"11877201406","pt":1724084494418,"mc":[{"id":"1.232011572","rc":[{"batb":[[0,1.43,10.54]],"ltp":1.51,"tv":48.28,"id":72857115}]}]}
{"op":"mcm","clk":"11877201487","pt":1724084495497,"mc":[{"id":"1.232011572","rc":[{"batb":[[0,1.42,4.11],[1,1.35,7.66],[2,1.34,25.21]],"ltp":1.51,"tv":48.28,"id":72857115}]}]}
{"op":"mcm","clk":"11877203866","pt":1724084520759,"mc":[{"id":"1.232011572","rc":[{"batb":[[0,1.43,14.54],[1,1.42,3.58],[2,1.35,7.66]],"ltp":1.51,"tv":48.28,"id":72857115}]}]}
{"op":"mcm","clk":"11877204148","pt":1724084523357,"mc":[{"id":"1.232011572","rc":[{"batb":[[0,1.43,10.54]],"ltp":1.51,"tv":48.28,"id":72857115}]}]}
{"op":"mcm","clk":"11877204249","pt":1724084524240,"mc":[{"id":"1.232011572","rc":[{"batb":[[0,1.42,4.11],[1,1.35,7.66],[2,1.34,25.21]],"ltp":1.51,"tv":48.28,"id":72857115}]}]}
{"op":"mcm","clk":"11877211654","pt":1724084607441,"mc":[{"id":"1.232011572","rc":[{"batb":[[0,1.43,14.54],[1,1.42,3.58],[2,1.35,7.66]],"ltp":1.51,"tv":48.28,"id":72857115}]}]}
{"op":"mcm","clk":"11877211947","pt":1724084609836,"mc":[{"id":"1.232011572","rc":[{"batb":[[0,1.43,10.54]],"ltp":1.51,"tv":48.28,"id":72857115}]}]}
{"op":"mcm","clk":"11877212100","pt":1724084610936,"mc":[{"id":"1.232011572","rc":[{"batb":[[0,1.42,4.11],[1,1.35,7.66],[2,1.34,25.21]],"ltp":1.51,"tv":48.28,"id":72857115}]}]}
{"op":"mcm","clk":"11877216504","pt":1724084660196,"mc":[{"id":"1.232011572","rc":[{"batb":[[0,1.43,14.54],[1,1.42,3.58],[2,1.35,7.66]],"ltp":1.51,"tv":48.28,"id":72857115}]}]}
{"op":"mcm","clk":"11877216703","pt":1724084662578,"mc":[{"id":"1.232011572","rc":[{"batb":[[0,1.43,10.54]],"ltp":1.51,"tv":48.28,"id":72857115}]}]}
{"op":"mcm","clk":"11877216774","pt":1724084663511,"mc":[{"id":"1.232011572","rc":[{"batb":[[0,1.42,4.11],[1,1.35,7.66],[2,1.34,25.21]],"ltp":1.51,"tv":48.28,"id":72857115}]}]}
{"op":"mcm","clk":"11877247812","pt":1724085007898,"mc":[{"id":"1.232011572","rc":[{"batb":[[0,1.43,14.54],[1,1.42,3.58],[2,1.35,7.66]],"ltp":1.51,"tv":48.28,"id":72857115}]}]}
{"op":"mcm","clk":"11877248026","pt":1724085010612,"mc":[{"id":"1.232011572","rc":[{"batb":[[0,1.43,10.54]],"ltp":1.51,"tv":48.28,"id":72857115}]}]}
{"op":"mcm","clk":"11877248096","pt":1724085011399,"mc":[{"id":"1.232011572","rc":[{"batb":[[0,1.42,4.11],[1,1.35,7.66],[2,1.34,25.21]],"ltp":1.51,"tv":48.28,"id":72857115}]}]}
{"op":"mcm","clk":"11877266193","pt":1724085209213,"mc":[{"id":"1.232011572","rc":[{"batb":[[0,1.43,14.54],[1,1.42,3.58],[2,1.35,7.66]],"ltp":1.51,"tv":48.28,"id":72857115}]}]}
{"op":"mcm","clk":"11877266586","pt":1724085211913,"mc":[{"id":"1.232011572","rc":[{"batb":[[0,1.43,10.54]],"ltp":1.51,"tv":48.28,"id":72857115}]}]}
{"op":"mcm","clk":"11877266742","pt":1724085213030,"mc":[{"id":"1.232011572","rc":[{"batb":[[0,1.42,4.11],[1,1.35,7.66],[2,1.34,25.21]],"ltp":1.51,"tv":48.28,"id":72857115}]}]}
{"op":"mcm","clk":"11877269925","pt":1724085244463,"mc":[{"id":"1.232011572","rc":[{"batb":[[0,1.43,14.54],[1,1.42,3.58],[2,1.35,7.66]],"ltp":1.51,"tv":48.28,"id":72857115}]}]}
{"op":"mcm","clk":"11877270157","pt":1724085247057,"mc":[{"id":"1.232011572","rc":[{"batb":[[0,1.43,10.54]],"ltp":1.51,"tv":48.28,"id":72857115}]}]}
{"op":"mcm","clk":"11877270243","pt":1724085247942,"mc":[{"id":"1.232011572","rc":[{"batb":[[0,1.42,4.11],[1,1.35,7.66],[2,1.34,25.21]],"ltp":1.51,"tv":48.28,"id":72857115}]}]}
{"op":"mcm","clk":"11877273649","pt":1724085287897,"mc":[{"id":"1.232011572","rc":[{"batb":[[0,1.43,14.54],[1,1.42,3.58],[2,1.35,7.66]],"ltp":1.51,"tv":48.28,"id":72857115}]}]}
{"op":"mcm","clk":"11877273846","pt":1724085290177,"mc":[{"id":"1.232011572","rc":[{"batb":[[0,1.43,10.54]],"ltp":1.51,"tv":48.28,"id":72857115}]}]}
{"op":"mcm","clk":"11877273923","pt":1724085291183,"mc":[{"id":"1.232011572","rc":[{"batb":[[0,1.42,4.11],[1,1.35,7.66],[2,1.34,25.21]],"ltp":1.51,"tv":48.28,"id":72857115}]}]}
{"op":"mcm","clk":"11877276303","pt":1724085318011,"mc":[{"id":"1.232011572","rc":[{"batb":[[0,1.43,14.54],[1,1.42,3.58],[2,1.35,7.66]],"ltp":1.51,"tv":48.28,"id":72857115}]}]}
{"op":"mcm","clk":"11877276553","pt":1724085320721,"mc":[{"id":"1.232011572","rc":[{"batb":[[0,1.43,10.54]],"ltp":1.51,"tv":48.28,"id":72857115}]}]}
{"op":"mcm","clk":"11877276642","pt":1724085321604,"mc":[{"id":"1.232011572","rc":[{"batb":[[0,1.42,4.11],[1,1.35,7.66],[2,1.34,25.21]],"ltp":1.51,"tv":48.28,"id":72857115}]}]}
{"op":"mcm","clk":"11877277997","pt":1724085336323,"mc":[{"id":"1.232011572","rc":[{"batb":[[0,1.43,14.54],[1,1.42,3.58],[2,1.35,7.66]],"ltp":1.51,"tv":48.28,"id":72857115}]}]}
{"op":"mcm","clk":"11877278274","pt":1724085339021,"mc":[{"id":"1.232011572","rc":[{"batb":[[0,1.43,10.54]],"ltp":1.51,"tv":48.28,"id":72857115}]}]}
{"op":"mcm","clk":"11877278353","pt":1724085339908,"mc":[{"id":"1.232011572","rc":[{"batb":[[0,1.42,4.11],[1,1.35,7.66],[2,1.34,25.21]],"ltp":1.51,"tv":48.28,"id":72857115}]}]}
{"op":"mcm","clk":"11877279820","pt":1724085356686,"mc":[{"id":"1.232011572","rc":[{"batb":[[0,1.43,14.54],[1,1.42,3.58],[2,1.35,7.66]],"ltp":1.51,"tv":48.28,"id":72857115}]}]}
{"op":"mcm","clk":"11877280019","pt":1724085359085,"mc":[{"id":"1.232011572","rc":[{"batb":[[0,1.43,10.54]],"ltp":1.51,"tv":48.28,"id":72857115}]}]}
{"op":"mcm","clk":"11877280099","pt":1724085359966,"mc":[{"id":"1.232011572","rc":[{"batb":[[0,1.42,4.11],[1,1.35,7.66],[2,1.34,25.21]],"ltp":1.51,"tv":48.28,"id":72857115}]}]}
{"op":"mcm","clk":"11877282502","pt":1724085384993,"mc":[{"id":"1.232011572","rc":[{"batb":[[0,1.43,14.54],[1,1.42,3.58],[2,1.35,7.66]],"ltp":1.51,"tv":48.28,"id":72857115}]}]}
{"op":"mcm","clk":"11877282731","pt":1724085387548,"mc":[{"id":"1.232011572","rc":[{"batb":[[0,1.43,10.54]],"ltp":1.51,"tv":48.28,"id":72857115}]}]}
{"op":"mcm","clk":"11877282849","pt":1724085388801,"mc":[{"id":"1.232011572","rc":[{"batb":[[0,1.42,4.11],[1,1.35,7.66],[2,1.34,25.21]],"ltp":1.51,"tv":48.28,"id":72857115}]}]}
{"op":"mcm","clk":"11877284020","pt":1724085401310,"mc":[{"id":"1.232011572","rc":[{"batb":[[0,1.43,14.54],[1,1.42,3.58],[2,1.35,7.66]],"ltp":1.51,"tv":48.28,"id":72857115}]}]}
{"op":"mcm","clk":"11877284251","pt":1724085403721,"mc":[{"id":"1.232011572","rc":[{"batb":[[0,1.43,10.54]],"ltp":1.51,"tv":48.28,"id":72857115}]}]}
{"op":"mcm","clk":"11877284330","pt":1724085404703,"mc":[{"id":"1.232011572","rc":[{"batb":[[0,1.42,4.11],[1,1.35,7.66],[2,1.34,25.21]],"ltp":1.51,"tv":48.28,"id":72857115}]}]}
{"op":"mcm","clk":"11877285892","pt":1724085420352,"mc":[{"id":"1.232011572","rc":[{"batb":[[0,1.43,14.54],[1,1.42,3.58],[2,1.35,7.66]],"ltp":1.51,"tv":48.28,"id":72857115}]}]}
{"op":"mcm","clk":"11877286193","pt":1724085423597,"mc":[{"id":"1.232011572","rc":[{"batb":[[0,1.42,4.11],[1,1.35,7.66],[2,1.34,25.21]],"ltp":1.51,"tv":48.28,"id":72857115}]}]}
{"op":"mcm","clk":"11877287237","pt":1724085435516,"mc":[{"id":"1.232011572","rc":[{"batb":[[0,1.35,8.2],[1,1.34,25.21],[2,1.33,151.52]],"ltp":1.51,"tv":48.28,"id":72857115}]}]}
{"op":"mcm","clk":"11877314143","pt":1724085714307,"mc":[{"id":"1.232011572","rc":[{"batb":[[1,1.33,151.52],[2,1.23,434.78]],"ltp":1.51,"tv":48.28,"id":72857115},{"batb":[[0,1.34,7.15],[1,1.33,151.52],[2,1.23,434.78]],"ltp":2.98,"tv":23.05,"id":72857117}]}]}
{"op":"mcm","clk":"11877318063","pt":1724085755580,"mc":[{"id":"1.232011572","rc":[{"batb":[[0,1.36,24.34],[1,1.35,7.66],[2,1.33,151.52]],"ltp":1.51,"tv":48.28,"id":72857115},{"batb":[[0,1.35,25.02],[1,1.34,6.62],[2,1.33,151.52]],"ltp":2.98,"tv":23.05,"id":72857117}]}]}
{"op":"mcm","clk":"11877337005","pt":1724085945185,"mc":[{"id":"1.232011572","rc":[{"batb":[[0,2.7,1.16],[1,1.35,25.02],[2,1.34,6.62]],"ltp":2.98,"tv":23.05,"id":72857117}]}]}
{"op":"mcm","clk":"11877337760","pt":1724085952118,"mc":[{"id":"1.232011572","rc":[{"batb":[[0,1.35,25.02],[1,1.34,6.62],[2,1.33,151.52]],"ltp":2.98,"tv":23.05,"id":72857117}]}]}
{"op":"mcm","clk":"11877340633","pt":1724085979417,"mc":[{"id":"1.232011572","rc":[{"batb":[[0,2.7,1.54],[1,1.35,25.02],[2,1.34,6.62]],"ltp":2.98,"tv":23.05,"id":72857117}]}]}
{"op":"mcm","clk":"11877341604","pt":1724085991724,"mc":[{"id":"1.232011572","rc":[{"trd":[[2.7,2]],"batb":[[0,1.35,25.02],[1,1.34,6.62],[2,1.33,151.52]],"ltp":2.7,"tv":25.05,"id":72857117}],"tv":73.33}]}
{"op":"mcm","clk":"11877346488","pt":1724086052543,"mc":[{"id":"1.232011572","rc":[{"batb":[[0,1.6,1.5],[1,1.35,25.02],[2,1.34,6.62]],"ltp":2.7,"tv":25.05,"id":72857117}]}]}
{"op":"mcm","clk":"11877359068","pt":1724086201447,"mc":[{"id":"1.232011572","rc":[{"batb":[[0,2.66,1.16],[1,1.6,1.5],[2,1.35,25.02]],"ltp":2.7,"tv":25.05,"id":72857117}]}]}
{"op":"mcm","clk":"11877360196","pt":1724086214078,"mc":[{"id":"1.232011572","rc":[{"batb":[[0,1.6,1.5],[1,1.35,25.02],[2,1.34,6.62]],"ltp":2.7,"tv":25.05,"id":72857117}]}]}
{"op":"mcm","clk":"11877362788","pt":1724086245998,"mc":[{"id":"1.232011572","rc":[{"batb":[[0,1.35,25.02],[1,1.34,6.62],[2,1.33,151.52]],"ltp":2.7,"tv":25.05,"id":72857117}]}]}
{"op":"mcm","clk":"11877367763","pt":1724086309972,"mc":[{"id":"1.232011572","rc":[{"batb":[[0,2.3,1],[1,1.36,24.34],[2,1.35,7.66]],"ltp":1.51,"tv":48.28,"id":72857115}]}]}
{"op":"mcm","clk":"11877368844","pt":1724086322488,"mc":[{"id":"1.232011572","rc":[{"trd":[[2.3,0.59]],"batb":[[0,1.36,24.75],[1,1.35,7.66],[2,1.33,151.52]],"ltp":2.3,"tv":48.87,"id":72857115},{"trd":[[1.77,0.77]],"ltp":1.77,"tv":25.82,"id":72857117}],"tv":74.7}]}
{"op":"mcm","clk":"11877368885","pt":1724086323003,"mc":[{"id":"1.232011572","rc":[{"batb":[[0,1.36,24.34]],"ltp":2.3,"tv":48.87,"id":72857115}]}]}
{"op":"mcm","clk":"11877371372","pt":1724086353728,"mc":[{"id":"1.232011572","rc":[{"batb":[[0,2.7,1],[1,1.35,25.02],[2,1.34,6.62]],"ltp":1.77,"tv":25.82,"id":72857117}]}]}
{"op":"mcm","clk":"11877371640","pt":1724086357046,"mc":[{"id":"1.232011572","rc":[{"trd":[[1.55,0.54]],"batb":[[0,1.36,23.81]],"ltp":1.55,"tv":49.41,"id":72857115},{"trd":[[2.82,0.29]],"batb":[[0,2.7,1.86]],"ltp":2.82,"tv":26.11,"id":72857117}],"tv":75.53}]}
{"op":"mcm","clk":"11877372184","pt":1724086364240,"mc":[{"id":"1.232011572","rc":[{"batb":[[0,1.5,1.4],[1,1.35,24.49]],"ltp":2.82,"tv":26.11,"id":72857117}]}]}
{"op":"mcm","clk":"11877372622","pt":1724086370024,"mc":[{"id":"1.232011572","rc":[{"trd":[[1.36,2]],"batb":[[0,1.36,22.8]],"ltp":1.36,"tv":51.41,"id":72857115}],"tv":77.53}]}
{"op":"mcm","clk":"11877373525","pt":1724086381145,"mc":[{"id":"1.232011572","rc":[{"batb":[[2,1.16,82.84]],"ltp":1.36,"tv":51.41,"id":72857115}]}]}
{"op":"mcm","clk":"11877373751","pt":1724086383663,"mc":[{"id":"1.232011572","rc":[{"trd":[[2.98,3.08]],"batb":[[0,1.35,25.12],[1,1.34,6.62],[2,1.11,82.84]],"ltp":2.98,"tv":27.65,"id":72857117}],"tv":79.07}]}
{"op":"mcm","clk":"11877373814","pt":1724086384380,"mc":[{"id":"1.232011572","rc":[{"batb":[[0,1.38,171.16],[1,1.35,24.49],[2,1.34,6.62]],"ltp":2.98,"tv":27.65,"id":72857117}]}]}
{"op":"mcm","clk":"11877373960","pt":1724086386259,"mc":[{"id":"1.232011572","rc":[{"batb":[[0,1.35,25.12],[1,1.34,6.62],[2,1.11,82.84]],"ltp":2.98,"tv":27.65,"id":72857117}]}]}
{"op":"mcm","clk":"11877374871","pt":1724086397551,"mc":[{"id":"1.232011572","rc":[{"batb":[[2,1.2,1000]],"ltp":2.98,"tv":27.65,"id":72857117}]}]}
{"op":"mcm","clk":"11877374976","pt":1724086398898,"mc":[{"id":"1.232011572","rc":[{"batb":[[2,1.3,666.67]],"ltp":2.98,"tv":27.65,"id":72857117}]}]}
{"op":"mcm","clk":"11877375090","pt":1724086400297,"mc":[{"id":"1.232011572","rc":[{"batb":[[0,1.4,500.63],[1,1.35,24.49],[2,1.34,6.62]],"ltp":2.98,"tv":27.65,"id":72857117}]}]}
{"op":"mcm","clk":"11877375527","pt":1724086405896,"mc":[{"id":"1.232011572","rc":[{"trd":[[1.51,3.23]],"batb":[[0,1.36,23.62],[2,1.2,1000]],"ltp":1.51,"tv":51.6,"id":72857115},{"trd":[[2.98,3.17]],"batb":[[0,1.4,500.54]],"ltp":2.98,"tv":27.75,"id":72857117}],"tv":79.35}]}
{"op":"mcm","clk":"11877375742","pt":1724086407291,"mc":[{"id":"1.232011572","rc":[{"batb":[[2,1.3,666.67]],"ltp":1.51,"tv":51.6,"id":72857115}]}]}
{"op":"mcm","clk":"11877375985","pt":1724086408975,"mc":[{"id":"1.232011572","rc":[{"batb":[[0,1.4,500.82],[1,1.36,22.8],[2,1.35,7.66]],"ltp":1.51,"tv":51.6,"id":72857115}]}]}
{"op":"mcm","clk":"11877376240","pt":1724086411467,"mc":[{"id":"1.232011572","rc":[{"batb":[[0,1.4,500]],"ltp":1.51,"tv":51.6,"id":72857115}]}]}
{"op":"mcm","clk":"11877376997","pt":1724086419603,"mc":[{"id":"1.232011572","rc":[{"batb":[[0,2.64,1.16],[1,1.4,500.54],[2,1.35,24.49]],"ltp":2.98,"tv":27.75,"id":72857117}]}]}
{"op":"mcm","clk":"11877377200","pt":1724086421989,"mc":[{"id":"1.232011572","rc":[{"trd":[[1.61,1]],"ltp":1.61,"tv":52.6,"id":72857115},{"trd":[[2.64,0.61]],"batb":[[0,1.5,1.08],[1,1.4,500]],"ltp":2.64,"tv":28.35,"id":72857117}],"tv":80.96}]}
{"op":"mcm","clk":"11877377404","pt":1724086424573,"mc":[{"id":"1.232011572","rc":[{"trd":[[2.64,1.71]],"batb":[[0,1.41,10.54]],"batl":[[0,2.64,0.45]],"ltp":2.64,"tv":29.45,"id":72857117}],"tv":82.05}]}
{"op":"mcm","clk":"11877377425","pt":1724086424779,"mc":[{"id":"1.232011572","rc":[{"batb":[[0,1.53,85.27],[1,1.41,10.54],[2,1.4,500]],"ltp":2.64,"tv":29.45,"id":72857117}]}]}
{"op":"mcm","clk":"11877377637","pt":1724086427974,"mc":[{"id":"1.232011572","rc":[{"batb":[[1,1.4,500.54],[2,1.35,24.49]],"ltp":2.64,"tv":29.45,"id":72857117}]}]}
{"op":"mcm","clk":"11877377871","pt":1724086431022,"mc":[{"id":"1.232011572","rc":[{"batb":[[0,1.41,85.27],[1,1.4,500],[2,1.36,22.8]],"ltp":1.61,"tv":52.6,"id":72857115}]}]}
{"op":"mcm","clk":"11877378082","pt":1724086433907,"mc":[{"id":"1.232011572","rc":[{"batb":[[1,1.52,85.27],[2,1.4,500.54]],"ltp":2.64,"tv":29.45,"id":72857117}]}]}
{"op":"mcm","clk":"11877378288","pt":1724086436335,"mc":[{"id":"1.232011572","rc":[{"batb":[[0,2.7,1],[1,1.41,85.27],[2,1.4,500]],"ltp":1.61,"tv":52.6,"id":72857115}]}]}
{"op":"mcm","clk":"11877378620","pt":1724086440736,"mc":[{"id":"1.232011572","rc":[{"batb":[[0,1.41,85.27],[1,1.4,500],[2,1.36,22.8]],"batl":[[0,2.7,1]],"ltp":1.61,"tv":52.6,"id":72857115}]}]}
{"op":"mcm","clk":"11877378639","pt":1724086440942,"mc":[{"id":"1.232011572","rc":[{"batb":[[0,1.42,14],[1,1.41,85.27],[2,1.4,500]],"ltp":1.61,"tv":52.6,"id":72857115}]}]}
{"op":"mcm","clk":"11877378837","pt":1724086443341,"mc":[{"id":"1.232011572","rc":[{"batb":[[0,1.42,10]],"ltp":1.61,"tv":52.6,"id":72857115},{"batb":[[0,1.59,85.27],[1,1.53,85.27]],"ltp":2.64,"tv":29.45,"id":72857117}]}]}
{"op":"mcm","clk":"11877378931","pt":1724086444238,"mc":[{"id":"1.232011572","rc":[{"batb":[[0,1.41,85.27],[1,1.4,500],[2,1.36,22.8]],"ltp":1.61,"tv":52.6,"id":72857115}]}]}
{"op":"mcm","clk":"11877379454","pt":1724086450334,"mc":[{"id":"1.232011572","rc":[{"batb":[[0,1.55,85.27]],"ltp":2.64,"tv":29.45,"id":72857117}]}]}
{"op":"mcm","clk":"11877379733","pt":1724086453838,"mc":[{"id":"1.232011572","rc":[{"batb":[[0,1.55,85.31]],"ltp":2.64,"tv":29.45,"id":72857117}]}]}
{"op":"mcm","clk":"11877380830","pt":1724086467450,"mc":[{"id":"1.232011572","rc":[{"batb":[[0,1.41,85.44]],"ltp":1.61,"tv":52.6,"id":72857115},{"batb":[[0,1.55,86.2]],"ltp":2.64,"tv":29.45,"id":72857117}]}]}
{"op":"mcm","clk":"11877382081","pt":1724086483487,"mc":[{"id":"1.232011572","rc":[{"batb":[[0,2.3,1],[1,1.41,85.44],[2,1.4,500]],"ltp":1.61,"tv":52.6,"id":72857115}]}]}
{"op":"mcm","clk":"11877382478","pt":1724086488781,"mc":[{"id":"1.232011572","rc":[{"trd":[[2.3,2.59]],"batb":[[0,1.41,85.44],[1,1.4,500],[2,1.36,22.8]],"ltp":2.3,"tv":54.6,"id":72857115}],"tv":84.05}]}
{"op":"mcm","clk":"11877382610","pt":1724086490498,"mc":[{"id":"1.232011572","rc":[{"batb":[[0,1.6,1.39],[1,1.55,85.27],[2,1.53,85.27]],"ltp":2.64,"tv":29.45,"id":72857117}]}]}
{"op":"mcm","clk":"11877383773","pt":1724086504001,"mc":[{"id":"1.232011572","rc":[{"trd":[[1.41,8.9],[1.57,0.34]],"batb":[[0,1.41,80.82]],"ltp":1.41,"tv":63.84,"id":72857115}],"tv":93.3}]}
{"op":"mcm","clk":"11877385243","pt":1724086519500,"mc":[{"id":"1.232011572","rc":[{"batb":[[0,1.42,10],[1,1.41,80.82],[2,1.4,500]],"batl":[[0,2.28,17.05]],"ltp":1.41,"tv":63.84,"id":72857115}]}]}
{"op":"mcm","clk":"11877385595","pt":1724086523228,"mc":[{"id":"1.232011572","rc":[{"batb":[[0,2.1,1],[1,1.44,80.82]],"ltp":1.41,"tv":63.84,"id":72857115}]}]}
{"op":"mcm","clk":"11877385924","pt":1724086526611,"mc":[{"id":"1.232011572","rc":[{"trd":[[2.1,2]],"batb":[[0,1.45,10]],"batl":[[0,2.08,16.06],[1,2.28,17.05]],"ltp":2.1,"tv":65.84,"id":72857115}],"tv":95.3}]}
{"op":"mcm","clk":"11877386106","pt":1724086528706,"mc":[{"id":"1.232011572","rc":[{"batl":[[0,2.28,17.05],[1,2.28,0]],"ltp":2.1,"tv":65.84,"id":72857115}]}]}
{"op":"mcm","clk":"11877386202","pt":1724086529833,"mc":[{"id":"1.232011572","rc":[{"batb":[[0,1.44,80.82],[1,1.4,500],[2,1.36,22.8]],"ltp":2.1,"tv":65.84,"id":72857115}]}]}
{"op":"mcm","clk":"11877386486","pt":1724086532993,"mc":[{"id":"1.232011572","rc":[{"batb":[[0,1.45,10],[1,1.44,80.82],[2,1.4,500]],"ltp":2.1,"tv":65.84,"id":72857115}]}]}
{"op":"mcm","clk":"11877386786","pt":1724086536409,"mc":[{"id":"1.232011572","rc":[{"batb":[[0,1.47,80.82],[1,1.4,500],[2,1.36,22.8]],"ltp":2.1,"tv":65.84,"id":72857115}]}]}
{"op":"mcm","clk":"11877386912","pt":1724086537962,"mc":[{"id":"1.232011572","rc":[{"trd":[[1.47,1.39]],"batb":[[0,1.47,79.43]],"ltp":1.47,"tv":67.23,"id":72857115},{"trd":[[3.15,0.65]],"ltp":3.15,"tv":30.1,"id":72857117}],"tv":97.33}]}
{"op":"mcm","clk":"11877387022","pt":1724086539516,"mc":[{"id":"1.232011572","rc":[{"batb":[[0,1.48,10],[1,1.47,79.43],[2,1.4,500]],"ltp":1.47,"tv":67.23,"id":72857115}]}]}
{"op":"mcm","clk":"11877387397","pt":1724086543612,"mc":[{"id":"1.232011572","rc":[{"batb":[[0,1.5,79.43],[1,1.4,500],[2,1.36,22.8]],"ltp":1.47,"tv":67.23,"id":72857115}]}]}
{"op":"mcm","clk":"11877387537","pt":1724086545423,"mc":[{"id":"1.232011572","rc":[{"batb":[[0,1.51,10],[1,1.5,79.43],[2,1.4,500]],"ltp":1.47,"tv":67.23,"id":72857115}]}]}
{"op":"mcm","clk":"11877387773","pt":1724086548842,"mc":[{"id":"1.232011572","rc":[{"batb":[[0,1.5,79.43],[1,1.4,500],[2,1.36,22.8]],"ltp":1.47,"tv":67.23,"id":72857115}]}]}
{"op":"mcm","clk":"11877387869","pt":1724086549930,"mc":[{"id":"1.232011572","rc":[{"batl":[[0,2.22,17.05]],"ltp":1.47,"tv":67.23,"id":72857115}]}]}
{"op":"mcm","clk":"11877388025","pt":1724086552013,"mc":[{"id":"1.232011572","rc":[{"batb":[[0,1.51,10],[1,1.5,79.43],[2,1.4,500]],"ltp":1.47,"tv":67.23,"id":72857115}]}]}
{"op":"mcm","clk":"11877388320","pt":1724086555380,"mc":[{"id":"1.232011572","rc":[{"batb":[[0,1.5,79.43],[1,1.4,500],[2,1.36,22.8]],"ltp":1.47,"tv":67.23,"id":72857115}]}]}
{"op":"mcm","clk":"11877388754","pt":1724086560462,"mc":[{"id":"1.232011572","rc":[{"batb":[[0,1.51,10],[1,1.5,79.43],[2,1.4,500]],"ltp":1.47,"tv":67.23,"id":72857115}]}]}
{"op":"mcm","clk":"11877389066","pt":1724086564107,"mc":[{"id":"1.232011572","rc":[{"batb":[[0,1.5,79.43],[1,1.4,500],[2,1.36,22.8]],"ltp":1.47,"tv":67.23,"id":72857115}]}]}
{"op":"mcm","clk":"11877389157","pt":1724086565093,"mc":[{"id":"1.232011572","rc":[{"batb":[[0,1.52,79.43]],"ltp":1.47,"tv":67.23,"id":72857115}]}]}
{"op":"mcm","clk":"11877389302","pt":1724086566602,"mc":[{"id":"1.232011572","rc":[{"batb":[[0,1.53,10],[1,1.52,79.43],[2,1.4,500]],"ltp":1.47,"tv":67.23,"id":72857115}]}]}
{"op":"mcm","clk":"11877389524","pt":1724086569092,"mc":[{"id":"1.232011572","rc":[{"batb":[[1,1.42,79.43]],"ltp":1.47,"tv":67.23,"id":72857115}]}]}
{"op":"mcm","clk":"11877389625","pt":1724086570072,"mc":[{"id":"1.232011572","rc":[{"batb":[[0,1.42,79.43],[1,1.4,500],[2,1.36,22.8]],"ltp":1.47,"tv":67.23,"id":72857115}]}]}
{"op":"mcm","clk":"11877389923","pt":1724086573684,"mc":[{"id":"1.232011572","rc":[{"batb":[[0,1.43,10],[1,1.42,79.43],[2,1.4,500]],"ltp":1.47,"tv":67.23,"id":72857115}]}]}
{"op":"mcm","clk":"11877390289","pt":1724086577500,"mc":[{"id":"1.232011572","rc":[{"batb":[[0,1.42,79.43],[1,1.4,500],[2,1.36,22.8]],"ltp":1.47,"tv":67.23,"id":72857115}]}]}
{"op":"mcm","clk":"11877390508","pt":1724086580202,"mc":[{"id":"1.232011572","rc":[{"batb":[[0,1.43,10],[1,1.42,79.43],[2,1.4,500]],"ltp":1.47,"tv":67.23,"id":72857115}]}]}
{"op":"mcm","clk":"11877390821","pt":1724086583910,"mc":[{"id":"1.232011572","rc":[{"batb":[[0,1.42,79.43],[1,1.4,500],[2,1.36,22.8]],"ltp":1.47,"tv":67.23,"id":72857115}]}]}
{"op":"mcm","clk":"11877391137","pt":1724086587319,"mc":[{"id":"1.232011572","rc":[{"batb":[[0,1.43,10],[1,1.42,79.43],[2,1.4,500]],"ltp":1.47,"tv":67.23,"id":72857115}]}]}
{"op":"mcm","clk":"11877391388","pt":1724086590684,"mc":[{"id":"1.232011572","rc":[{"batb":[[0,1.9,1]],"ltp":1.47,"tv":67.23,"id":72857115}]}]}
{"op":"mcm","clk":"11877391829","pt":1724086596298,"mc":[{"id":"1.232011572","rc":[{"trd":[[1.9,2]],"batb":[[0,1.42,79.43],[1,1.4,500],[2,1.36,22.8]],"batl":[[0,1.8,16.06],[1,2.22,17.05]],"ltp":1.9,"tv":69.23,"id":72857115}],"tv":99.33}]}
{"op":"mcm","clk":"11877392034","pt":1724086598617,"mc":[{"id":"1.232011572","rc":[{"batb":[[0,1.43,10],[1,1.42,79.43],[2,1.4,500]],"batl":[[0,2.22,17.05],[1,2.22,0]],"ltp":1.9,"tv":69.23,"id":72857115}]}]}
{"op":"mcm","clk":"11877392274","pt":1724086601849,"mc":[{"id":"1.232011572","rc":[{"batb":[[0,1.42,79.43],[1,1.4,500],[2,1.36,22.8]],"ltp":1.9,"tv":69.23,"id":72857115}]}]}
{"op":"mcm","clk":"11877393030","pt":1724086611678,"mc":[{"id":"1.232011572","rc":[{"batb":[[0,1.43,10],[1,1.42,79.43],[2,1.4,500]],"ltp":1.9,"tv":69.23,"id":72857115}]}]}
{"op":"mcm","clk":"11877393252","pt":1724086614083,"mc":[{"id":"1.232011572","rc":[{"trd":[[1.43,2.16]],"batb":[[0,1.43,8.92]],"ltp":1.43,"tv":71.39,"id":72857115}],"tv":101.49}]}
{"op":"mcm","clk":"11877393353","pt":1724086615169,"mc":[{"id":"1.232011572","rc":[{"batb":[[0,1.42,79.43],[1,1.4,500],[2,1.36,22.8]],"ltp":1.43,"tv":71.39,"id":72857115}]}]}
{"op":"mcm","clk":"11877393741","pt":1724086620068,"mc":[{"id":"1.232011572","rc":[{"batb":[[0,1.43,10],[1,1.42,79.43],[2,1.4,500]],"ltp":1.43,"tv":71.39,"id":72857115}]}]}
{"op":"mcm","clk":"11877394057","pt":1724086623661,"mc":[{"id":"1.232011572","rc":[{"batb":[[0,1.42,79.43],[1,1.4,500],[2,1.36,22.8]],"ltp":1.43,"tv":71.39,"id":72857115}]}]}
{"op":"mcm","clk":"11877394349","pt":1724086627282,"mc":[{"id":"1.232011572","rc":[{"batb":[[0,1.43,10],[1,1.42,79.43],[2,1.4,500]],"ltp":1.43,"tv":71.39,"id":72857115}]}]}
{"op":"mcm","clk":"11877394632","pt":1724086630754,"mc":[{"id":"1.232011572","rc":[{"batb":[[0,1.44,17.05]],"ltp":1.43,"tv":71.39,"id":72857115}]}]}
{"op":"mcm","clk":"11877394812","pt":1724086632968,"mc":[{"id":"1.232011572","rc":[{"batb":[[0,1.45,10],[1,1.44,17.05]],"ltp":1.43,"tv":71.39,"id":72857115}]}]}
{"op":"mcm","clk":"11877394883","pt":1724086634105,"mc":[{"id":"1.232011572","rc":[{"batb":[[2,1.42,17.05]],"ltp":1.43,"tv":71.39,"id":72857115}]}]}
{"op":"mcm","clk":"11877394989","pt":1724086635297,"mc":[{"id":"1.232011572","rc":[{"batb":[[0,1.47,17.05],[1,1.45,10],[2,1.44,17.05]],"ltp":1.43,"tv":71.39,"id":72857115}]}]}
{"op":"mcm","clk":"11877395083","pt":1724086636280,"mc":[{"id":"1.232011572","rc":[{"batb":[[1,1.44,17.05],[2,1.42,17.05]],"ltp":1.43,"tv":71.39,"id":72857115}]}]}
{"op":"mcm","clk":"11877395474","pt":1724086640979,"mc":[{"id":"1.232011572","rc":[{"batb":[[0,1.49,10],[1,1.48,259.67],[2,1.47,17.05]],"ltp":1.43,"tv":71.39,"id":72857115}]}]}
{"op":"mcm","clk":"11877395733","pt":1724086644181,"mc":[{"id":"1.232011572","rc":[{"batb":[[0,1.48,259.67],[1,1.47,17.05],[2,1.44,17.05]],"ltp":1.43,"tv":71.39,"id":72857115}]}]}
{"op":"mcm","clk":"11877396084","pt":1724086648682,"mc":[{"id":"1.232011572","rc":[{"batb":[[0,1.49,10],[1,1.48,259.67],[2,1.47,17.05]],"ltp":1.43,"tv":71.39,"id":72857115}]}]}
{"op":"mcm","clk":"11877396392","pt":1724086652390,"mc":[{"id":"1.232011572","rc":[{"batb":[[0,1.48,259.67],[1,1.47,17.05],[2,1.44,17.05]],"ltp":1.43,"tv":71.39,"id":72857115}]}]}
{"op":"mcm","clk":"11877396604","pt":1724086655225,"mc":[{"id":"1.232011572","rc":[{"batb":[[0,1.51,10],[1,1.5,17.05],[2,1.48,259.67]],"ltp":1.43,"tv":71.39,"id":72857115}]}]}
{"op":"mcm","clk":"11877396899","pt":1724086658617,"mc":[{"id":"1.232011572","rc":[{"batb":[[0,1.5,17.05],[1,1.48,259.67],[2,1.47,17.05]],"ltp":1.43,"tv":71.39,"id":72857115}]}]}
{"op":"mcm","clk":"11877397188","pt":1724086662347,"mc":[{"id":"1.232011572","rc":[{"batb":[[0,1.51,10],[1,1.5,17.05],[2,1.48,259.67]],"ltp":1.43,"tv":71.39,"id":72857115}]}]}
{"op":"mcm","clk":"11877397483","pt":1724086666007,"mc":[{"id":"1.232011572","rc":[{"batb":[[0,1.5,17.05],[1,1.48,259.67],[2,1.47,17.05]],"ltp":1.43,"tv":71.39,"id":72857115}]}]}
{"op":"mcm","clk":"11877398190","pt":1724086674765,"mc":[{"id":"1.232011572","rc":[{"batb":[[0,1.51,10],[1,1.5,17.05],[2,1.48,259.67]],"ltp":1.43,"tv":71.39,"id":72857115}]}]}
{"op":"mcm","clk":"11877398213","pt":1724086675075,"mc":[{"id":"1.232011572","rc":[{"trd":[[1.51,3.47]],"batb":[[0,1.51,9.76]],"ltp":1.51,"tv":71.63,"id":72857115},{"trd":[[2.98,3.3]],"ltp":2.98,"tv":30.22,"id":72857117}],"tv":101.85}]}
{"op":"mcm","clk":"11877398464","pt":1724086678339,"mc":[{"id":"1.232011572","rc":[{"batb":[[0,1.5,17.05],[1,1.48,259.67],[2,1.47,17.05]],"ltp":1.51,"tv":71.63,"id":72857115}]}]}
{"op":"mcm","clk":"11877399040","pt":1724086685988,"mc":[{"id":"1.232011572","rc":[{"batb":[[0,1.51,10],[1,1.5,17.05],[2,1.48,259.67]],"ltp":1.51,"tv":71.63,"id":72857115}]}]}
{"op":"mcm","clk":"11877399298","pt":1724086689191,"mc":[{"id":"1.232011572","rc":[{"batb":[[0,1.5,17.05],[1,1.48,259.67],[2,1.47,17.05]],"ltp":1.51,"tv":71.63,"id":72857115}]}]}
{"op":"mcm","clk":"11877400766","pt":1724086706713,"mc":[{"id":"1.232011572","rc":[{"batb":[[0,1.51,10],[1,1.5,17.05],[2,1.48,259.67]],"ltp":1.51,"tv":71.63,"id":72857115}]}]}
{"op":"mcm","clk":"11877401044","pt":1724086710576,"mc":[{"id":"1.232011572","rc":[{"batb":[[0,1.5,17.05],[1,1.48,259.67],[2,1.47,17.05]],"ltp":1.51,"tv":71.63,"id":72857115}]}]}
{"op":"mcm","clk":"11877402180","pt":1724086725211,"mc":[{"id":"1.232011572","rc":[{"batb":[[0,1.51,10],[1,1.5,17.05],[2,1.48,259.67]],"ltp":1.51,"tv":71.63,"id":72857115}]}]}
{"op":"mcm","clk":"11877402408","pt":1724086728602,"mc":[{"id":"1.232011572","rc":[{"batb":[[0,1.5,17.05],[1,1.48,259.67],[2,1.47,17.05]],"ltp":1.51,"tv":71.63,"id":72857115}]}]}
{"op":"mcm","clk":"11877402952","pt":1724086735924,"mc":[{"id":"1.232011572","rc":[{"batb":[[0,1.51,10],[1,1.5,17.05],[2,1.48,259.67]],"ltp":1.51,"tv":71.63,"id":72857115}]}]}
{"op":"mcm","clk":"11877403182","pt":1724086739426,"mc":[{"id":"1.232011572","rc":[{"batb":[[0,1.5,17.05],[1,1.48,259.67],[2,1.47,17.05]],"ltp":1.51,"tv":71.63,"id":72857115}]}]}
{"op":"mcm","clk":"11877408197","pt":1724086800104,"mc":[{"id":"1.232011572","rc":[{"batb":[[0,1.51,10],[1,1.5,17.05],[2,1.48,259.67]],"ltp":1.51,"tv":71.63,"id":72857115}]}]}
{"op":"mcm","clk":"11877408629","pt":1724086803603,"mc":[{"id":"1.232011572","rc":[{"trd":[[1.41,8.91]],"batb":[[0,1.5,17.06],[1,1.48,259.67],[2,1.47,17.06]],"batl":[[0,2.22,17.06]],"ltp":1.51,"tv":71.64,"id":72857115},{"batb":[[1,1.55,85.3],[2,1.53,85.3]],"ltp":2.98,"tv":30.22,"id":72857117}],"tv":101.86}]}
{"op":"mcm","clk":"11877409304","pt":1724086810107,"mc":[{"id":"1.232011572","rc":[{"batb":[[0,1.51,10],[1,1.5,17.06],[2,1.48,259.67]],"ltp":1.51,"tv":71.64,"id":72857115}]}]}
{"op":"mcm","clk":"11877409675","pt":1724086813708,"mc":[{"id":"1.232011572","rc":[{"batb":[[0,1.5,17.06],[1,1.48,259.67],[2,1.47,17.06]],"ltp":1.51,"tv":71.64,"id":72857115}]}]}
{"op":"mcm","clk":"11877409839","pt":1724086815510,"mc":[{"id":"1.232011572","rc":[{"batb":[[0,1.55,85.79],[1,1.53,85.3],[2,1.4,500]],"ltp":2.98,"tv":30.22,"id":72857117}]}]}
{"op":"mcm","clk":"11877410282","pt":1724086820207,"mc":[{"id":"1.232011572","rc":[{"batb":[[0,1.51,10],[1,1.5,17.06],[2,1.48,259.67]],"ltp":1.51,"tv":71.64,"id":72857115},{"batb":[[0,1.55,85.35]],"ltp":2.98,"tv":30.22,"id":72857117}]}]}
{"op":"mcm","clk":"11877410581","pt":1724086823583,"mc":[{"id":"1.232011572","rc":[{"batb":[[0,1.5,17.06],[1,1.48,259.67],[2,1.47,17.06]],"ltp":1.51,"tv":71.64,"id":72857115}]}]}
{"op":"mcm","clk":"11877411366","pt":1724086832432,"mc":[{"id":"1.232011572","rc":[{"batb":[[0,1.51,10],[1,1.5,17.06],[2,1.48,259.67]],"ltp":1.51,"tv":71.64,"id":72857115}]}]}
{"op":"mcm","clk":"11877411648","pt":1724086835620,"mc":[{"id":"1.232011572","rc":[{"batb":[[0,1.5,17.06],[1,1.48,259.67],[2,1.47,17.06]],"ltp":1.51,"tv":71.64,"id":72857115}]}]}
{"op":"mcm","clk":"11877412647","pt":1724086846204,"mc":[{"id":"1.232011572","rc":[{"batb":[[0,1.51,10],[1,1.5,17.06],[2,1.48,259.67]],"ltp":1.51,"tv":71.64,"id":72857115}]}]}
{"op":"mcm","clk":"11877412948","pt":1724086849837,"mc":[{"id":"1.232011572","rc":[{"batb":[[0,1.5,17.06],[1,1.48,259.67],[2,1.47,17.06]],"ltp":1.51,"tv":71.64,"id":72857115}]}]}
{"op":"mcm","clk":"11877413315","pt":1724086853949,"mc":[{"id":"1.232011572","rc":[{"batb":[[0,1.51,10],[1,1.5,17.06],[2,1.48,259.67]],"ltp":1.51,"tv":71.64,"id":72857115}]}]}
{"op":"mcm","clk":"11877413635","pt":1724086857328,"mc":[{"id":"1.232011572","rc":[{"batb":[[0,1.5,17.06],[1,1.48,259.67],[2,1.47,17.06]],"ltp":1.51,"tv":71.64,"id":72857115}]}]}
{"op":"mcm","clk":"11877414317","pt":1724086863229,"mc":[{"id":"1.232011572","rc":[{"batb":[[0,1.51,10],[1,1.5,17.06],[2,1.48,259.67]],"ltp":1.51,"tv":71.64,"id":72857115}]}]}
{"op":"mcm","clk":"11877414654","pt":1724086866766,"mc":[{"id":"1.232011572","rc":[{"batb":[[0,1.5,17.06],[1,1.48,259.67],[2,1.47,17.06]],"ltp":1.51,"tv":71.64,"id":72857115}]}]}
{"op":"mcm","clk":"11877417546","pt":1724086898365,"mc":[{"id":"1.232011572","rc":[{"batb":[[0,1.51,10],[1,1.5,17.06],[2,1.48,259.67]],"ltp":1.51,"tv":71.64,"id":72857115}]}]}
{"op":"mcm","clk":"11877417896","pt":1724086901964,"mc":[{"id":"1.232011572","rc":[{"batb":[[0,1.5,17.06],[1,1.48,259.67],[2,1.47,17.06]],"ltp":1.51,"tv":71.64,"id":72857115}]}]}
{"op":"mcm","clk":"11877419539","pt":1724086919511,"mc":[{"id":"1.232011572","rc":[{"batb":[[0,1.51,10],[1,1.5,17.06],[2,1.48,259.67]],"ltp":1.51,"tv":71.64,"id":72857115}]}]}
{"op":"mcm","clk":"11877419874","pt":1724086922886,"mc":[{"id":"1.232011572","rc":[{"batb":[[0,1.5,17.06],[1,1.48,259.67],[2,1.47,17.06]],"ltp":1.51,"tv":71.64,"id":72857115}]}]}
{"op":"mcm","clk":"11877420443","pt":1724086928337,"mc":[{"id":"1.232011572","rc":[{"batb":[[0,1.51,10],[1,1.5,17.06],[2,1.48,259.67]],"ltp":1.51,"tv":71.64,"id":72857115}]}]}
{"op":"mcm","clk":"11877420808","pt":1724086931821,"mc":[{"id":"1.232011572","rc":[{"batb":[[0,1.5,17.06],[1,1.48,259.67],[2,1.47,17.06]],"ltp":1.51,"tv":71.64,"id":72857115}]}]}
{"op":"mcm","clk":"11877421172","pt":1724086935741,"mc":[{"id":"1.232011572","rc":[{"batb":[[0,1.51,10],[1,1.5,17.06],[2,1.48,259.67]],"ltp":1.51,"tv":71.64,"id":72857115}]}]}
{"op":"mcm","clk":"11877421506","pt":1724086939022,"mc":[{"id":"1.232011572","rc":[{"batb":[[0,1.5,17.06],[1,1.48,259.67],[2,1.47,17.06]],"ltp":1.51,"tv":71.64,"id":72857115}]}]}
{"op":"mcm","clk":"11877422144","pt":1724086945212,"mc":[{"id":"1.232011572","rc":[{"batb":[[0,1.51,10],[1,1.5,17.06],[2,1.48,259.67]],"ltp":1.51,"tv":71.64,"id":72857115}]}]}
{"op":"mcm","clk":"11877422454","pt":1724086948758,"mc":[{"id":"1.232011572","rc":[{"batb":[[0,1.5,17.06],[1,1.48,259.67],[2,1.47,17.06]],"ltp":1.51,"tv":71.64,"id":72857115}]}]}
{"op":"mcm","clk":"11877422819","pt":1724086952442,"mc":[{"id":"1.232011572","rc":[{"batb":[[0,1.51,10],[1,1.5,17.06],[2,1.48,259.67]],"ltp":1.51,"tv":71.64,"id":72857115}]}]}
{"op":"mcm","clk":"11877423149","pt":1724086955929,"mc":[{"id":"1.232011572","rc":[{"batb":[[0,1.5,17.06],[1,1.48,259.67],[2,1.47,17.06]],"ltp":1.51,"tv":71.64,"id":72857115}]}]}
{"op":"mcm","clk":"11877424658","pt":1724086969654,"mc":[{"id":"1.232011572","rc":[{"batb":[[0,1.51,10],[1,1.5,17.06],[2,1.48,259.67]],"ltp":1.51,"tv":71.64,"id":72857115}]}]}
{"op":"mcm","clk":"11877425039","pt":1724086973070,"mc":[{"id":"1.232011572","rc":[{"batb":[[0,1.5,17.06],[1,1.48,259.67],[2,1.47,17.06]],"ltp":1.51,"tv":71.64,"id":72857115}]}]}
{"op":"mcm","clk":"11877425338","pt":1724086976048,"mc":[{"id":"1.232011572","rc":[{"batb":[[0,1.51,10],[1,1.5,17.06],[2,1.48,259.67]],"ltp":1.51,"tv":71.64,"id":72857115}]}]}
{"op":"mcm","clk":"11877425691","pt":1724086979540,"mc":[{"id":"1.232011572","rc":[{"batb":[[0,1.5,17.06],[1,1.48,259.67],[2,1.47,17.06]],"ltp":1.51,"tv":71.64,"id":72857115}]}]}
{"op":"mcm","clk":"11877426389","pt":1724086985852,"mc":[{"id":"1.232011572","rc":[{"batb":[[0,1.51,10],[1,1.5,17.06],[2,1.48,259.67]],"ltp":1.51,"tv":71.64,"id":72857115}]}]}
{"op":"mcm","clk":"11877426784","pt":1724086989266,"mc":[{"id":"1.232011572","rc":[{"batb":[[0,1.5,17.06],[1,1.48,259.67],[2,1.47,17.06]],"ltp":1.51,"tv":71.64,"id":72857115}]}]}
{"op":"mcm","clk":"11877427530","pt":1724086995677,"mc":[{"id":"1.232011572","rc":[{"batb":[[0,1.51,10],[1,1.5,17.06],[2,1.48,259.67]],"ltp":1.51,"tv":71.64,"id":72857115}]}]}
{"op":"mcm","clk":"11877427971","pt":1724086999389,"mc":[{"id":"1.232011572","rc":[{"batb":[[0,1.5,17.06],[1,1.48,259.67],[2,1.47,17.06]],"ltp":1.51,"tv":71.64,"id":72857115}]}]}
{"op":"mcm","clk":"11877428353","pt":1724087002596,"mc":[{"id":"1.232011572","rc":[{"batb":[[0,1.51,10],[1,1.5,17.06],[2,1.48,259.67]],"ltp":1.51,"tv":71.64,"id":72857115}]}]}
{"op":"mcm","clk":"11877428758","pt":1724087006096,"mc":[{"id":"1.232011572","rc":[{"batb":[[0,1.5,17.06],[1,1.48,259.67],[2,1.47,17.06]],"ltp":1.51,"tv":71.64,"id":72857115}]}]}
{"op":"mcm","clk":"11877429173","pt":1724087008715,"mc":[{"id":"1.232011572","rc":[{"batb":[[0,1.51,10],[1,1.5,17.06],[2,1.49,7.66]],"ltp":1.51,"tv":71.64,"id":72857115},{"batb":[[0,1.56,6.66],[1,1.55,85.3],[2,1.53,85.3]],"ltp":2.98,"tv":30.22,"id":72857117}]}]}
{"op":"mcm","clk":"11877429786","pt":1724087012219,"mc":[{"id":"1.232011572","rc":[{"batb":[[0,1.5,17.06],[1,1.49,7.66],[2,1.48,259.67]],"ltp":1.51,"tv":71.64,"id":72857115}]}]}
{"op":"mcm","clk":"11877430694","pt":1724087018010,"mc":[{"id":"1.232011572","rc":[{"batb":[[0,1.51,10],[1,1.5,17.06],[2,1.49,7.66]],"ltp":1.51,"tv":71.64,"id":72857115}]}]}
{"op":"mcm","clk":"11877431095","pt":1724087021404,"mc":[{"id":"1.232011572","rc":[{"batb":[[0,1.5,17.06],[1,1.49,7.66],[2,1.48,259.67]],"ltp":1.51,"tv":71.64,"id":72857115}]}]}
{"op":"mcm","clk":"11877431516","pt":1724087024462,"mc":[{"id":"1.232011572","rc":[{"batb":[[0,1.51,10],[1,1.5,17.06],[2,1.49,7.66]],"ltp":1.51,"tv":71.64,"id":72857115},{"batb":[[0,1.57,288.27],[1,1.56,6.62],[2,1.55,85.3]],"ltp":2.98,"tv":30.22,"id":72857117}]}]}
{"op":"mcm","clk":"11877431855","pt":1724087027576,"mc":[{"id":"1.232011572","rc":[{"batb":[[0,1.5,17.06],[1,1.49,7.66],[2,1.48,259.67]],"ltp":1.51,"tv":71.64,"id":72857115}]}]}
{"op":"mcm","clk":"11877432532","pt":1724087033276,"mc":[{"id":"1.232011572","rc":[{"batb":[[0,1.51,10],[1,1.5,17.06],[2,1.49,7.66]],"ltp":1.51,"tv":71.64,"id":72857115}]}]}
{"op":"mcm","clk":"11877432992","pt":1724087036795,"mc":[{"id":"1.232011572","rc":[{"batb":[[0,1.5,17.06],[1,1.49,7.66],[2,1.48,259.67]],"ltp":1.51,"tv":71.64,"id":72857115}]}]}
{"op":"mcm","clk":"11877433305","pt":1724087039390,"mc":[{"id":"1.232011572","rc":[{"batb":[[0,1.55,10],[1,1.54,288.23],[2,1.5,17.06]],"ltp":1.51,"tv":71.64,"id":72857115}]}]}
{"op":"mcm","clk":"11877433684","pt":1724087042878,"mc":[{"id":"1.232011572","rc":[{"batb":[[0,1.54,288.23],[1,1.5,17.06],[2,1.49,7.66]],"ltp":1.51,"tv":71.64,"id":72857115}]}]}
{"op":"mcm","clk":"11877434671","pt":1724087051770,"mc":[{"id":"1.232011572","rc":[{"batb":[[0,1.55,10],[1,1.54,288.23],[2,1.5,17.06]],"ltp":1.51,"tv":71.64,"id":72857115}]}]}
{"op":"mcm","clk":"11877435045","pt":1724087055400,"mc":[{"id":"1.232011572","rc":[{"batb":[[0,1.54,288.23],[1,1.5,17.06],[2,1.49,7.66]],"ltp":1.51,"tv":71.64,"id":72857115}]}]}
{"op":"mcm","clk":"11877444089","pt":1724087134755,"mc":[{"id":"1.232011572","rc":[{"batb":[[0,1.55,10],[1,1.54,288.23],[2,1.5,17.06]],"ltp":1.51,"tv":71.64,"id":72857115}]}]}
{"op":"mcm","clk":"11877444492","pt":1724087138165,"mc":[{"id":"1.232011572","rc":[{"batb":[[0,1.54,288.23],[1,1.5,17.06],[2,1.49,7.66]],"ltp":1.51,"tv":71.64,"id":72857115}]}]}
{"op":"mcm","clk":"11877445403","pt":1724087145872,"mc":[{"id":"1.232011572","rc":[{"batb":[[0,1.55,10],[1,1.54,288.23],[2,1.5,17.06]],"ltp":1.51,"tv":71.64,"id":72857115}]}]}
{"op":"mcm","clk":"11877445769","pt":1724087149188,"mc":[{"id":"1.232011572","rc":[{"batb":[[0,1.54,288.23],[1,1.5,17.06],[2,1.49,7.66]],"ltp":1.51,"tv":71.64,"id":72857115}]}]}
{"op":"mcm","clk":"11877446244","pt":1724087153520,"mc":[{"id":"1.232011572","rc":[{"batb":[[0,1.55,10],[1,1.54,288.23],[2,1.5,17.06]],"ltp":1.51,"tv":71.64,"id":72857115}]}]}
{"op":"mcm","clk":"11877446605","pt":1724087157122,"mc":[{"id":"1.232011572","rc":[{"batb":[[0,1.54,288.23],[1,1.5,17.06],[2,1.49,7.66]],"ltp":1.51,"tv":71.64,"id":72857115}]}]}
{"op":"mcm","clk":"11877451259","pt":1724087199006,"mc":[{"id":"1.232011572","rc":[{"batb":[[0,1.55,10],[1,1.54,288.23],[2,1.5,17.06]],"ltp":1.51,"tv":71.64,"id":72857115}]}]}
{"op":"mcm","clk":"11877451717","pt":1724087202360,"mc":[{"id":"1.232011572","rc":[{"batb":[[0,1.54,288.23],[1,1.5,17.06],[2,1.49,7.66]],"ltp":1.51,"tv":71.64,"id":72857115}]}]}
{"op":"mcm","clk":"11877452586","pt":1724087209963,"mc":[{"id":"1.232011572","rc":[{"batb":[[0,1.55,10],[1,1.54,288.23],[2,1.5,17.06]],"ltp":1.51,"tv":71.64,"id":72857115}]}]}
{"op":"mcm","clk":"11877453364","pt":1724087216459,"mc":[{"id":"1.232011572","rc":[{"batb":[[0,1.54,288.23],[1,1.5,17.06],[2,1.49,7.66]],"ltp":1.51,"tv":71.64,"id":72857115}]}]}
{"op":"mcm","clk":"11877453873","pt":1724087220863,"mc":[{"id":"1.232011572","rc":[{"batb":[[0,1.55,10],[1,1.54,288.23],[2,1.5,17.06]],"ltp":1.51,"tv":71.64,"id":72857115}]}]}
{"op":"mcm","clk":"11877454305","pt":1724087224384,"mc":[{"id":"1.232011572","rc":[{"batb":[[0,1.54,288.23],[1,1.5,17.06],[2,1.49,7.66]],"ltp":1.51,"tv":71.64,"id":72857115}]}]}
{"op":"mcm","clk":"11877456028","pt":1724087238821,"mc":[{"id":"1.232011572","rc":[{"batb":[[0,1.55,10],[1,1.54,288.23],[2,1.5,17.06]],"ltp":1.51,"tv":71.64,"id":72857115}]}]}
{"op":"mcm","clk":"11877456438","pt":1724087241993,"mc":[{"id":"1.232011572","rc":[{"batb":[[0,1.54,288.23],[1,1.5,17.06],[2,1.49,7.66]],"ltp":1.51,"tv":71.64,"id":72857115}]}]}
{"op":"mcm","clk":"11877461573","pt":1724087284163,"mc":[{"id":"1.232011572","rc":[{"batb":[[0,1.55,10],[1,1.54,288.23],[2,1.5,17.06]],"ltp":1.51,"tv":71.64,"id":72857115}]}]}
{"op":"mcm","clk":"11877462034","pt":1724087287957,"mc":[{"id":"1.232011572","rc":[{"batb":[[0,1.54,288.23],[1,1.5,17.06],[2,1.49,7.66]],"ltp":1.51,"tv":71.64,"id":72857115}]}]}
{"op":"mcm","clk":"11877467763","pt":1724087333845,"mc":[{"id":"1.232011572","rc":[{"batb":[[0,1.55,10],[1,1.54,288.23],[2,1.5,17.06]],"ltp":1.51,"tv":71.64,"id":72857115}]}]}
{"op":"mcm","clk":"11877468190","pt":1724087337518,"mc":[{"id":"1.232011572","rc":[{"batb":[[0,1.54,288.23],[1,1.5,17.06],[2,1.49,7.66]],"ltp":1.51,"tv":71.64,"id":72857115}]}]}
{"op":"mcm","clk":"11877469166","pt":1724087346125,"mc":[{"id":"1.232011572","rc":[{"batb":[[0,1.55,10],[1,1.54,288.23],[2,1.5,17.06]],"ltp":1.51,"tv":71.64,"id":72857115}]}]}
{"op":"mcm","clk":"11877469594","pt":1724087349753,"mc":[{"id":"1.232011572","rc":[{"batb":[[0,1.54,288.23],[1,1.5,17.06],[2,1.49,7.66]],"ltp":1.51,"tv":71.64,"id":72857115}]}]}
{"op":"mcm","clk":"11877470271","pt":1724087355778,"mc":[{"id":"1.232011572","rc":[{"batb":[[0,1.55,10],[1,1.54,288.23],[2,1.5,17.06]],"ltp":1.51,"tv":71.64,"id":72857115}]}]}
{"op":"mcm","clk":"11877470712","pt":1724087359578,"mc":[{"id":"1.232011572","rc":[{"batb":[[0,1.54,288.23],[1,1.5,17.06],[2,1.49,7.66]],"ltp":1.51,"tv":71.64,"id":72857115}]}]}
{"op":"mcm","clk":"11877470991","pt":1724087361892,"mc":[{"id":"1.232011572","rc":[{"batb":[[0,1.55,10],[1,1.54,288.23],[2,1.5,17.06]],"ltp":1.51,"tv":71.64,"id":72857115}]}]}
{"op":"mcm","clk":"11877471399","pt":1724087365465,"mc":[{"id":"1.232011572","rc":[{"batb":[[0,1.54,288.23],[1,1.5,17.06],[2,1.49,7.66]],"ltp":1.51,"tv":71.64,"id":72857115}]}]}
{"op":"mcm","clk":"11877473252","pt":1724087381315,"mc":[{"id":"1.232011572","rc":[{"batb":[[0,1.55,10],[1,1.54,288.23],[2,1.5,17.06]],"ltp":1.51,"tv":71.64,"id":72857115}]}]}
{"op":"mcm","clk":"11877473647","pt":1724087384724,"mc":[{"id":"1.232011572","rc":[{"batb":[[0,1.54,288.23],[1,1.5,17.06],[2,1.49,7.66]],"ltp":1.51,"tv":71.64,"id":72857115}]}]}
{"op":"mcm","clk":"11877474495","pt":1724087392615,"mc":[{"id":"1.232011572","rc":[{"batb":[[0,1.55,10],[1,1.54,288.23],[2,1.5,17.06]],"ltp":1.51,"tv":71.64,"id":72857115}]}]}
{"op":"mcm","clk":"11877474853","pt":1724087396141,"mc":[{"id":"1.232011572","rc":[{"batb":[[0,1.54,288.23],[1,1.5,17.06],[2,1.49,7.66]],"ltp":1.51,"tv":71.64,"id":72857115}]}]}
{"op":"mcm","clk":"11877475217","pt":1724087399312,"mc":[{"id":"1.232011572","rc":[{"batb":[[0,1.55,10],[1,1.54,288.23],[2,1.5,17.06]],"ltp":1.51,"tv":71.64,"id":72857115}]}]}
{"op":"mcm","clk":"11877475668","pt":1724087403033,"mc":[{"id":"1.232011572","rc":[{"batb":[[0,1.54,288.23],[1,1.5,17.06],[2,1.49,7.66]],"ltp":1.51,"tv":71.64,"id":72857115}]}]}
{"op":"mcm","clk":"11877476005","pt":1724087406050,"mc":[{"id":"1.232011572","rc":[{"batb":[[0,1.55,10],[1,1.54,288.23],[2,1.5,17.06]],"ltp":1.51,"tv":71.64,"id":72857115}]}]}
{"op":"mcm","clk":"11877476427","pt":1724087409646,"mc":[{"id":"1.232011572","rc":[{"batb":[[0,1.54,288.23],[1,1.5,17.06],[2,1.49,7.66]],"ltp":1.51,"tv":71.64,"id":72857115}]}]}
{"op":"mcm","clk":"11877476832","pt":1724087413060,"mc":[{"id":"1.232011572","rc":[{"batb":[[0,1.55,10],[1,1.54,288.23],[2,1.5,17.06]],"ltp":1.51,"tv":71.64,"id":72857115}]}]}
{"op":"mcm","clk":"11877477218","pt":1724087416584,"mc":[{"id":"1.232011572","rc":[{"batb":[[0,1.54,288.23],[1,1.5,17.06],[2,1.49,7.66]],"ltp":1.51,"tv":71.64,"id":72857115}]}]}
{"op":"mcm","clk":"11877477568","pt":1724087419779,"mc":[{"id":"1.232011572","rc":[{"batb":[[0,1.55,10],[1,1.54,288.23],[2,1.5,17.06]],"ltp":1.51,"tv":71.64,"id":72857115}]}]}
{"op":"mcm","clk":"11877477980","pt":1724087423264,"mc":[{"id":"1.232011572","rc":[{"batb":[[0,1.54,288.23],[1,1.5,17.06],[2,1.49,7.66]],"ltp":1.51,"tv":71.64,"id":72857115}]}]}
{"op":"mcm","clk":"11877478682","pt":1724087429469,"mc":[{"id":"1.232011572","rc":[{"batb":[[0,1.55,10],[1,1.54,288.23],[2,1.5,17.06]],"ltp":1.51,"tv":71.64,"id":72857115}]}]}
{"op":"mcm","clk":"11877479113","pt":1724087432999,"mc":[{"id":"1.232011572","rc":[{"batb":[[0,1.54,288.23],[1,1.5,17.06],[2,1.49,7.66]],"ltp":1.51,"tv":71.64,"id":72857115}]}]}
{"op":"mcm","clk":"11877479487","pt":1724087436366,"mc":[{"id":"1.232011572","rc":[{"batb":[[0,1.55,10],[1,1.54,288.23],[2,1.5,17.06]],"ltp":1.51,"tv":71.64,"id":72857115}]}]}
{"op":"mcm","clk":"11877479908","pt":1724087439979,"mc":[{"id":"1.232011572","rc":[{"batb":[[0,1.54,288.23],[1,1.5,17.06],[2,1.49,7.66]],"ltp":1.51,"tv":71.64,"id":72857115}]}]}
{"op":"mcm","clk":"11877480153","pt":1724087442271,"mc":[{"id":"1.232011572","rc":[{"batb":[[0,1.55,10],[1,1.54,288.23],[2,1.5,17.06]],"ltp":1.51,"tv":71.64,"id":72857115}]}]}
{"op":"mcm","clk":"11877480559","pt":1724087445806,"mc":[{"id":"1.232011572","rc":[{"batb":[[0,1.54,288.23],[1,1.5,17.06],[2,1.49,7.66]],"ltp":1.51,"tv":71.64,"id":72857115}]}]}
{"op":"mcm","clk":"11877481012","pt":1724087450013,"mc":[{"id":"1.232011572","rc":[{"batb":[[0,1.55,10],[1,1.54,288.23],[2,1.5,17.06]],"ltp":1.51,"tv":71.64,"id":72857115}]}]}
{"op":"mcm","clk":"11877481402","pt":1724087453640,"mc":[{"id":"1.232011572","rc":[{"batb":[[0,1.54,288.23],[1,1.5,17.06],[2,1.49,7.66]],"ltp":1.51,"tv":71.64,"id":72857115}]}]}
{"op":"mcm","clk":"11877481652","pt":1724087455836,"mc":[{"id":"1.232011572","rc":[{"batb":[[0,1.55,10],[1,1.54,288.23],[2,1.5,17.06]],"ltp":1.51,"tv":71.64,"id":72857115}]}]}
{"op":"mcm","clk":"11877482042","pt":1724087459234,"mc":[{"id":"1.232011572","rc":[{"batb":[[0,1.54,288.23],[1,1.5,17.06],[2,1.49,7.66]],"ltp":1.51,"tv":71.64,"id":72857115}]}]}
{"op":"mcm","clk":"11877482368","pt":1724087462420,"mc":[{"id":"1.232011572","rc":[{"batb":[[0,1.55,10],[1,1.54,288.23],[2,1.5,17.06]],"ltp":1.51,"tv":71.64,"id":72857115}]}]}
{"op":"mcm","clk":"11877482732","pt":1724087465931,"mc":[{"id":"1.232011572","rc":[{"batb":[[0,1.54,288.23],[1,1.5,17.06],[2,1.49,7.66]],"ltp":1.51,"tv":71.64,"id":72857115}]}]}
{"op":"mcm","clk":"11877483337","pt":1724087471550,"mc":[{"id":"1.232011572","rc":[{"batb":[[0,1.55,10],[1,1.54,288.23],[2,1.5,17.06]],"ltp":1.51,"tv":71.64,"id":72857115}]}]}
{"op":"mcm","clk":"11877483700","pt":1724087474960,"mc":[{"id":"1.232011572","rc":[{"batb":[[0,1.54,288.23],[1,1.5,17.06],[2,1.49,7.66]],"ltp":1.51,"tv":71.64,"id":72857115}]}]}
{"op":"mcm","clk":"11877484066","pt":1724087478455,"mc":[{"id":"1.232011572","rc":[{"batb":[[0,1.6,1.07],[1,1.55,10],[2,1.54,288.23]],"ltp":1.51,"tv":71.64,"id":72857115}]}]}
{"op":"mcm","clk":"11877484475","pt":1724087481763,"mc":[{"id":"1.232011572","rc":[{"batb":[[1,1.54,288.23],[2,1.5,17.06]],"ltp":1.51,"tv":71.64,"id":72857115}]}]}
{"op":"mcm","clk":"11877502879","pt":1724087635835,"mc":[{"id":"1.232011572","rc":[{"batb":[[0,1.6,1.74]],"ltp":1.51,"tv":71.64,"id":72857115}]}]}
{"op":"mcm","clk":"11877503472","pt":1724087640614,"mc":[{"id":"1.232011572","rc":[{"trd":[[1.61,2.33]],"batb":[[0,1.6,1.07]],"batl":[[0,2.22,17.17]],"ltp":1.61,"tv":72.96,"id":72857115}],"tv":103.19}]}
{"op":"mcm","clk":"11877503735","pt":1724087642830,"mc":[{"id":"1.232011572","rc":[{"batl":[[0,2.22,17.06]],"ltp":1.61,"tv":72.96,"id":72857115}]}]}
{"op":"mcm","clk":"11877505711","pt":1724087659843,"mc":[{"id":"1.232011572","rc":[{"batb":[[0,1.82,1.3],[1,1.57,288.23],[2,1.56,6.62]],"ltp":2.98,"tv":30.22,"id":72857117}]}]}
{"op":"mcm","clk":"11877506270","pt":1724087664677,"mc":[{"id":"1.232011572","rc":[{"trd":[[1.82,1.45],[1.9,0.09]],"batb":[[0,1.57,288.76],[1,1.56,6.62],[2,1.55,85.3]],"ltp":1.82,"tv":31.76,"id":72857117}],"tv":104.72}]}
{"op":"mcm","clk":"11877506621","pt":1724087667971,"mc":[{"id":"1.232011572","rc":[{"batb":[[0,1.57,288.23]],"ltp":1.82,"tv":31.76,"id":72857117}]}]}
{"op":"mcm","clk":"11877508998","pt":1724087689494,"mc":[{"id":"1.232011572","rc":[{"batb":[[0,1.57,288.77]],"ltp":1.82,"tv":31.76,"id":72857117}]}]}
{"op":"mcm","clk":"11877509647","pt":1724087695605,"mc":[{"id":"1.232011572","rc":[{"batb":[[0,1.57,288.23]],"ltp":1.82,"tv":31.76,"id":72857117}]}]}
{"op":"mcm","clk":"11877509748","pt":1724087696595,"mc":[{"id":"1.232011572","rc":[{"batb":[[0,1.85,1],[1,1.57,288.77],[2,1.56,6.62]],"ltp":1.82,"tv":31.76,"id":72857117}]}]}
{"op":"mcm","clk":"11877510127","pt":1724087699586,"mc":[{"id":"1.232011572","rc":[{"batb":[[1,1.57,288.23]],"ltp":1.82,"tv":31.76,"id":72857117}]}]}
{"op":"mcm","clk":"11877511808","pt":1724087714813,"mc":[{"id":"1.232011572","rc":[{"batb":[[0,1.61,1.16],[1,1.6,1.07],[2,1.54,288.23]],"ltp":1.61,"tv":72.96,"id":72857115}]}]}
{"op":"mcm","clk":"11877512163","pt":1724087718335,"mc":[{"id":"1.232011572","rc":[{"trd":[[1.61,4.65]],"batb":[[0,1.6,1.07],[1,1.54,288.23],[2,1.5,17.06]],"batl":[[0,2.22,17.44]],"ltp":1.61,"tv":75.29,"id":72857115}],"tv":107.05}]}
{"op":"mcm","clk":"11877512354","pt":1724087720329,"mc":[{"id":"1.232011572","rc":[{"batl":[[0,2.22,17.06]],"ltp":1.61,"tv":75.29,"id":72857115}]}]}
{"op":"mcm","clk":"11877514124","pt":1724087736441,"mc":[{"id":"1.232011572","rc":[{"batb":[[0,1.86,1.88],[1,1.85,1],[2,1.57,288.23]],"ltp":1.82,"tv":31.76,"id":72857117}]}]}
{"op":"mcm","clk":"11877514454","pt":1724087739158,"mc":[{"id":"1.232011572","rc":[{"batb":[[0,1.63,10],[1,1.62,17.06],[2,1.6,1.07]],"ltp":1.61,"tv":75.29,"id":72857115}]}]}
{"op":"mcm","clk":"11877514568","pt":1724087740263,"mc":[{"id":"1.232011572","rc":[{"batb":[[2,1.6,18.14]],"ltp":1.61,"tv":75.29,"id":72857115}]}]}
{"op":"mcm","clk":"11877514661","pt":1724087741142,"mc":[{"id":"1.232011572","rc":[{"batb":[[0,1.65,17.06],[1,1.63,10],[2,1.62,17.06]],"ltp":1.61,"tv":75.29,"id":72857115}]}]}
{"op":"mcm","clk":"11877514784","pt":1724087742438,"mc":[{"id":"1.232011572","rc":[{"batb":[[1,1.62,17.06],[2,1.6,18.14]],"ltp":1.61,"tv":75.29,"id":72857115},{"trd":[[1.86,3.76]],"batb":[[0,1.85,1],[1,1.57,288.23],[2,1.56,6.62]],"batl":[[0,1.86,0.43]],"ltp":1.86,"tv":35.52,"id":72857117}],"tv":110.81}]}
{"op":"mcm","clk":"11877515003","pt":1724087744676,"mc":[{"id":"1.232011572","rc":[{"batb":[[0,1.66,10],[1,1.65,17.06],[2,1.62,17.06]],"ltp":1.61,"tv":75.29,"id":72857115},{"batb":[[0,1.86,17.06],[1,1.85,1],[2,1.57,288.23]],"ltp":1.86,"tv":35.52,"id":72857117}]}]}
{"op":"mcm","clk":"11877515295","pt":1724087747857,"mc":[{"id":"1.232011572","rc":[{"batb":[[0,1.65,17.06],[1,1.62,17.06],[2,1.6,18.14]],"ltp":1.61,"tv":75.29,"id":72857115}]}]}
{"op":"mcm","clk":"11877515637","pt":1724087751045,"mc":[{"id":"1.232011572","rc":[{"batb":[[0,1.66,10],[1,1.65,17.06],[2,1.62,17.06]],"ltp":1.61,"tv":75.29,"id":72857115}]}]}
{"op":"mcm","clk":"11877516035","pt":1724087754442,"mc":[{"id":"1.232011572","rc":[{"batb":[[0,1.65,17.06],[1,1.62,17.06],[2,1.6,18.14]],"ltp":1.61,"tv":75.29,"id":72857115}]}]}
{"op":"mcm","clk":"11877516298","pt":1724087756944,"mc":[{"id":"1.232011572","rc":[{"batb":[[0,1.66,10],[1,1.65,17.06],[2,1.62,17.06]],"ltp":1.61,"tv":75.29,"id":72857115}]}]}
{"op":"mcm","clk":"11877516681","pt":1724087760177,"mc":[{"id":"1.232011572","rc":[{"batb":[[0,1.65,17.06],[1,1.62,17.06],[2,1.6,18.14]],"ltp":1.61,"tv":75.29,"id":72857115}]}]}
{"op":"mcm","clk":"11877517015","pt":1724087762863,"mc":[{"id":"1.232011572","rc":[{"batb":[[0,1.66,10],[1,1.65,17.06],[2,1.62,17.06]],"ltp":1.61,"tv":75.29,"id":72857115}]}]}
{"op":"mcm","clk":"11877517440","pt":1724087766355,"mc":[{"id":"1.232011572","rc":[{"batb":[[0,1.65,17.06],[1,1.62,17.06],[2,1.6,18.14]],"ltp":1.61,"tv":75.29,"id":72857115}]}]}
{"op":"mcm","clk":"11877517573","pt":1724087767493,"mc":[{"id":"1.232011572","rc":[{"batb":[[0,1.67,2.78],[1,1.65,17.06],[2,1.62,17.06]],"ltp":1.61,"tv":75.29,"id":72857115}]}]}
{"op":"mcm","clk":"11877518357","pt":1724087774595,"mc":[{"id":"1.232011572","rc":[{"trd":[[1.67,5.55]],"batb":[[0,1.66,10]],"batl":[[0,2.22,17.37]],"ltp":1.67,"tv":80.84,"id":72857115}],"tv":116.36}]}
{"op":"mcm","clk":"11877518745","pt":1724087778273,"mc":[{"id":"1.232011572","rc":[{"batb":[[0,1.65,17.06],[1,1.62,17.06],[2,1.6,18.14]],"batl":[[0,2.22,17.06]],"ltp":1.67,"tv":80.84,"id":72857115}]}]}
{"op":"mcm","clk":"11877518888","pt":1724087779587,"mc":[{"id":"1.232011572","rc":[{"batb":[[0,1.69,17.06],[1,1.65,17.06],[2,1.62,17.06]],"ltp":1.67,"tv":80.84,"id":72857115}]}]}
{"op":"mcm","clk":"11877519237","pt":1724087782678,"mc":[{"id":"1.232011572","rc":[{"batb":[[0,1.7,10],[1,1.69,17.06],[2,1.65,17.06]],"ltp":1.67,"tv":80.84,"id":72857115}]}]}
{"op":"mcm","clk":"11877519585","pt":1724087785994,"mc":[{"id":"1.232011572","rc":[{"batb":[[0,1.69,17.06],[1,1.65,17.06],[2,1.62,17.06]],"ltp":1.67,"tv":80.84,"id":72857115}]}]}
{"op":"mcm","clk":"11877519868","pt":1724087788705,"mc":[{"id":"1.232011572","rc":[{"batb":[[0,1.7,10],[1,1.69,17.06],[2,1.65,17.06]],"ltp":1.67,"tv":80.84,"id":72857115}]}]}
{"op":"mcm","clk":"11877520284","pt":1724087792203,"mc":[{"id":"1.232011572","rc":[{"batb":[[0,1.69,17.06],[1,1.65,17.06],[2,1.62,17.06]],"ltp":1.67,"tv":80.84,"id":72857115}]}]}
{"op":"mcm","clk":"11877520751","pt":1724087796132,"mc":[{"id":"1.232011572","rc":[{"batb":[[0,1.7,10],[1,1.69,17.06],[2,1.65,17.06]],"ltp":1.67,"tv":80.84,"id":72857115},{"batb":[[0,1.87,3.19],[1,1.86,17.06],[2,1.85,1]],"ltp":1.86,"tv":35.52,"id":72857117}]}]}
{"op":"mcm","clk":"11877521075","pt":1724087799325,"mc":[{"id":"1.232011572","rc":[{"batb":[[0,1.69,17.06],[1,1.65,17.06],[2,1.62,17.06]],"ltp":1.67,"tv":80.84,"id":72857115}]}]}
{"op":"mcm","clk":"11877521163","pt":1724087800159,"mc":[{"id":"1.232011572","rc":[{"trd":[[1.87,6.38]],"batb":[[0,1.86,17.06],[1,1.85,1],[2,1.57,288.23]],"batl":[[0,1.87,0.66]],"ltp":1.87,"tv":41.9,"id":72857117}],"tv":122.74}]}
{"op":"mcm","clk":"11877521440","pt":1724087802965,"mc":[{"id":"1.232011572","rc":[{"batb":[[0,1.7,10],[1,1.69,17.06],[2,1.65,17.06]],"ltp":1.67,"tv":80.84,"id":72857115}]}]}
{"op":"mcm","clk":"11877521794","pt":1724087806244,"mc":[{"id":"1.232011572","rc":[{"batb":[[0,1.69,17.06],[1,1.65,17.06],[2,1.62,17.06]],"ltp":1.67,"tv":80.84,"id":72857115}]}]}
{"op":"mcm","clk":"11877522087","pt":1724087808435,"mc":[{"id":"1.232011572","rc":[{"batb":[[0,1.7,10],[1,1.69,17.06],[2,1.65,17.06]],"ltp":1.67,"tv":80.84,"id":72857115}]}]}
{"op":"mcm","clk":"11877522536","pt":1724087812187,"mc":[{"id":"1.232011572","rc":[{"batb":[[0,1.69,17.06],[1,1.65,17.06],[2,1.62,17.06]],"ltp":1.67,"tv":80.84,"id":72857115}]}]}
{"op":"mcm","clk":"11877523014","pt":1724087816262,"mc":[{"id":"1.232011572","rc":[{"batb":[[0,1.7,10],[1,1.69,17.06],[2,1.65,17.06]],"ltp":1.67,"tv":80.84,"id":72857115}]}]}
{"op":"mcm","clk":"11877523445","pt":1724087819789,"mc":[{"id":"1.232011572","rc":[{"batb":[[0,1.69,17.06],[1,1.65,17.06],[2,1.62,17.06]],"ltp":1.67,"tv":80.84,"id":72857115}]}]}
{"op":"mcm","clk":"11877523736","pt":1724087822197,"mc":[{"id":"1.232011572","rc":[{"trd":[[1.69,3.89]],"batb":[[0,1.7,10],[1,1.69,15.12],[2,1.65,17.06]],"ltp":1.69,"tv":84.72,"id":72857115}],"tv":126.62}]}
{"op":"mcm","clk":"11877523940","pt":1724087823916,"mc":[{"id":"1.232011572","rc":[{"trd":[[1.86,7.2]],"batb":[[0,1.86,15.34]],"ltp":1.86,"tv":45.34,"id":72857117}],"tv":130.07}]}
{"op":"mcm","clk":"11877524144","pt":1724087825588,"mc":[{"id":"1.232011572","rc":[{"batb":[[0,1.69,15.12],[1,1.65,17.06],[2,1.62,17.06]],"ltp":1.69,"tv":84.72,"id":72857115}]}]}
{"op":"mcm","clk":"11877525259","pt":1724087835392,"mc":[{"id":"1.232011572","rc":[{"batb":[[0,1.7,10],[1,1.69,15.12],[2,1.65,17.06]],"ltp":1.69,"tv":84.72,"id":72857115}]}]}
{"op":"mcm","clk":"11877525672","pt":1724087838914,"mc":[{"id":"1.232011572","rc":[{"batb":[[0,1.69,15.12],[1,1.65,17.06],[2,1.62,17.06]],"ltp":1.69,"tv":84.72,"id":72857115}]}]}
{"op":"mcm","clk":"11877526470","pt":1724087845408,"mc":[{"id":"1.232011572","rc":[{"batb":[[0,1.7,10],[1,1.69,15.12],[2,1.65,17.06]],"ltp":1.69,"tv":84.72,"id":72857115}]}]}
{"op":"mcm","clk":"11877526887","pt":1724087849124,"mc":[{"id":"1.232011572","rc":[{"batb":[[0,1.69,15.12],[1,1.65,17.06],[2,1.62,17.06]],"ltp":1.69,"tv":84.72,"id":72857115}]}]}
{"op":"mcm","clk":"11877527183","pt":1724087851637,"mc":[{"id":"1.232011572","rc":[{"batb":[[0,1.7,10],[1,1.69,15.12],[2,1.65,17.06]],"ltp":1.69,"tv":84.72,"id":72857115}]}]}
{"op":"mcm","clk":"11877527549","pt":1724087854904,"mc":[{"id":"1.232011572","rc":[{"batb":[[0,1.69,15.12],[1,1.65,17.06],[2,1.62,17.06]],"ltp":1.69,"tv":84.72,"id":72857115}]}]}
{"op":"mcm","clk":"11877527799","pt":1724087857162,"mc":[{"id":"1.232011572","rc":[{"batb":[[0,1.7,10],[1,1.69,15.12],[2,1.65,17.06]],"ltp":1.69,"tv":84.72,"id":72857115}]}]}
{"op":"mcm","clk":"11877528171","pt":1724087860425,"mc":[{"id":"1.232011572","rc":[{"batb":[[0,1.69,15.12],[1,1.65,17.06],[2,1.62,17.06]],"ltp":1.69,"tv":84.72,"id":72857115}]}]}
{"op":"mcm","clk":"11877528729","pt":1724087865254,"mc":[{"id":"1.232011572","rc":[{"batb":[[0,1.7,10],[1,1.69,15.12],[2,1.65,17.06]],"ltp":1.69,"tv":84.72,"id":72857115}]}]}
{"op":"mcm","clk":"11877529124","pt":1724087868848,"mc":[{"id":"1.232011572","rc":[{"batb":[[0,1.69,15.12],[1,1.65,17.06],[2,1.62,17.06]],"ltp":1.69,"tv":84.72,"id":72857115}]}]}
{"op":"mcm","clk":"11877530484","pt":1724087881446,"mc":[{"id":"1.232011572","rc":[{"batb":[[0,1.7,10],[1,1.69,15.12],[2,1.65,17.06]],"ltp":1.69,"tv":84.72,"id":72857115}]}]}
{"op":"mcm","clk":"11877530906","pt":1724087885256,"mc":[{"id":"1.232011572","rc":[{"batb":[[0,1.69,15.12],[1,1.65,17.06],[2,1.62,17.06]],"ltp":1.69,"tv":84.72,"id":72857115}]}]}
{"op":"mcm","clk":"11877532032","pt":1724087895685,"mc":[{"id":"1.232011572","rc":[{"batb":[[0,1.7,10],[1,1.69,15.12],[2,1.65,17.06]],"ltp":1.69,"tv":84.72,"id":72857115}]}]}
{"op":"mcm","clk":"11877532397","pt":1724087899275,"mc":[{"id":"1.232011572","rc":[{"batb":[[0,1.69,15.12],[1,1.65,17.06],[2,1.62,17.06]],"ltp":1.69,"tv":84.72,"id":72857115}]}]}
{"op":"mcm","clk":"11877532694","pt":1724087902093,"mc":[{"id":"1.232011572","rc":[{"batb":[[0,1.7,10],[1,1.69,15.12],[2,1.65,17.06]],"ltp":1.69,"tv":84.72,"id":72857115},{"batb":[[0,1.87,14],[1,1.86,15.34],[2,1.85,1]],"batl":[[0,2.7,8.29]],"ltp":1.86,"tv":45.34,"id":72857117}]}]}
{"op":"mcm","clk":"11877533002","pt":1724087904669,"mc":[{"id":"1.232011572","rc":[{"batb":[[0,1.87,10]],"ltp":1.86,"tv":45.34,"id":72857117}]}]}
{"op":"mcm","clk":"11877533114","pt":1724087905564,"mc":[{"id":"1.232011572","rc":[{"batb":[[0,1.69,15.12],[1,1.65,17.06],[2,1.62,17.06]],"ltp":1.69,"tv":84.72,"id":72857115},{"batb":[[0,1.86,15.34],[1,1.85,1],[2,1.57,288.23]],"ltp":1.86,"tv":45.34,"id":72857117}]}]}
{"op":"mcm","clk":"11877533451","pt":1724087908683,"mc":[{"id":"1.232011572","rc":[{"batb":[[0,1.7,10],[1,1.69,15.12],[2,1.65,17.06]],"ltp":1.69,"tv":84.72,"id":72857115},{"batb":[[0,1.87,14],[1,1.86,15.34],[2,1.85,1]],"ltp":1.86,"tv":45.34,"id":72857117}]}]}
{"op":"mcm","clk":"11877533793","pt":1724087911104,"mc":[{"id":"1.232011572","rc":[{"batb":[[0,1.87,10]],"ltp":1.86,"tv":45.34,"id":72857117}]}]}
{"op":"mcm","clk":"11877533946","pt":1724087912097,"mc":[{"id":"1.232011572","rc":[{"batb":[[0,1.69,15.12],[1,1.65,17.06],[2,1.62,17.06]],"ltp":1.69,"tv":84.72,"id":72857115},{"batb":[[0,1.86,15.34],[1,1.85,1],[2,1.57,288.23]],"ltp":1.86,"tv":45.34,"id":72857117}]}]}
{"op":"mcm","clk":"11877534244","pt":1724087914313,"mc":[{"id":"1.232011572","rc":[{"batb":[[0,1.7,10],[1,1.69,15.12],[2,1.65,17.06]],"ltp":1.69,"tv":84.72,"id":72857115},{"batb":[[0,1.87,14],[1,1.86,15.34],[2,1.85,1]],"ltp":1.86,"tv":45.34,"id":72857117}]}]}
{"op":"mcm","clk":"11877534528","pt":1724087916914,"mc":[{"id":"1.232011572","rc":[{"batb":[[0,1.87,10]],"ltp":1.86,"tv":45.34,"id":72857117}]}]}
{"op":"mcm","clk":"11877534644","pt":1724087917908,"mc":[{"id":"1.232011572","rc":[{"batb":[[0,1.69,15.12],[1,1.65,17.06],[2,1.62,17.06]],"ltp":1.69,"tv":84.72,"id":72857115},{"batb":[[0,1.86,15.34],[1,1.85,1],[2,1.57,288.23]],"ltp":1.86,"tv":45.34,"id":72857117}]}]}
{"op":"mcm","clk":"11877535647","pt":1724087926777,"mc":[{"id":"1.232011572","rc":[{"batb":[[0,1.7,10],[1,1.69,15.12],[2,1.65,17.06]],"ltp":1.69,"tv":84.72,"id":72857115},{"batb":[[0,1.87,14],[1,1.86,15.34],[2,1.85,1]],"ltp":1.86,"tv":45.34,"id":72857117}]}]}
{"op":"mcm","clk":"11877535923","pt":1724087929421,"mc":[{"id":"1.232011572","rc":[{"batb":[[0,1.87,10]],"ltp":1.86,"tv":45.34,"id":72857117}]}]}
{"op":"mcm","clk":"11877536038","pt":1724087930202,"mc":[{"id":"1.232011572","rc":[{"batb":[[0,1.69,15.12],[1,1.65,17.06],[2,1.62,17.06]],"ltp":1.69,"tv":84.72,"id":72857115},{"batb":[[0,1.86,15.34],[1,1.85,1],[2,1.57,288.23]],"ltp":1.86,"tv":45.34,"id":72857117}]}]}
{"op":"mcm","clk":"11877540320","pt":1724087969765,"mc":[{"id":"1.232011572","rc":[{"batb":[[0,1.7,10],[1,1.69,15.12],[2,1.65,17.06]],"ltp":1.69,"tv":84.72,"id":72857115},{"batb":[[0,1.87,14],[1,1.86,15.34],[2,1.85,1]],"ltp":1.86,"tv":45.34,"id":72857117}]}]}
{"op":"mcm","clk":"11877540630","pt":1724087972473,"mc":[{"id":"1.232011572","rc":[{"batb":[[0,1.87,10]],"ltp":1.86,"tv":45.34,"id":72857117}]}]}
{"op":"mcm","clk":"11877540739","pt":1724087973463,"mc":[{"id":"1.232011572","rc":[{"batb":[[0,1.69,15.12],[1,1.65,17.06],[2,1.62,17.06]],"ltp":1.69,"tv":84.72,"id":72857115},{"batb":[[0,1.86,15.34],[1,1.85,1],[2,1.57,288.23]],"ltp":1.86,"tv":45.34,"id":72857117}]}]}
{"op":"mcm","clk":"11877541170","pt":1724087977252,"mc":[{"id":"1.232011572","rc":[{"batb":[[0,1.7,10],[1,1.69,15.12],[2,1.65,17.06]],"ltp":1.69,"tv":84.72,"id":72857115},{"batb":[[0,1.87,14],[1,1.86,15.34],[2,1.85,1]],"ltp":1.86,"tv":45.34,"id":72857117}]}]}
{"op":"mcm","clk":"11877541474","pt":1724087979978,"mc":[{"id":"1.232011572","rc":[{"batb":[[0,1.87,10]],"ltp":1.86,"tv":45.34,"id":72857117}]}]}
{"op":"mcm","clk":"11877541583","pt":1724087980874,"mc":[{"id":"1.232011572","rc":[{"batb":[[0,1.69,15.12],[1,1.65,17.06],[2,1.62,17.06]],"ltp":1.69,"tv":84.72,"id":72857115},{"batb":[[0,1.86,15.34],[1,1.85,1],[2,1.57,288.23]],"ltp":1.86,"tv":45.34,"id":72857117}]}]}
{"op":"mcm","clk":"11877542368","pt":1724087987789,"mc":[{"id":"1.232011572","rc":[{"batb":[[0,1.7,10],[1,1.69,15.12],[2,1.65,17.06]],"ltp":1.69,"tv":84.72,"id":72857115},{"batb":[[0,1.87,14],[1,1.86,15.34],[2,1.85,1]],"ltp":1.86,"tv":45.34,"id":72857117}]}]}
{"op":"mcm","clk":"11877542684","pt":1724087990558,"mc":[{"id":"1.232011572","rc":[{"batb":[[0,1.87,10]],"ltp":1.86,"tv":45.34,"id":72857117}]}]}
{"op":"mcm","clk":"11877542799","pt":1724087991397,"mc":[{"id":"1.232011572","rc":[{"batb":[[0,1.69,15.12],[1,1.65,17.06],[2,1.62,17.06]],"ltp":1.69,"tv":84.72,"id":72857115},{"batb":[[0,1.86,15.34],[1,1.85,1],[2,1.57,288.23]],"ltp":1.86,"tv":45.34,"id":72857117}]}]}
{"op":"mcm","clk":"11877545455","pt":1724088014716,"mc":[{"id":"1.232011572","rc":[{"batb":[[0,1.7,10],[1,1.69,15.12],[2,1.65,17.06]],"ltp":1.69,"tv":84.72,"id":72857115},{"batb":[[0,1.87,14],[1,1.86,15.34],[2,1.85,1]],"ltp":1.86,"tv":45.34,"id":72857117}]}]}
{"op":"mcm","clk":"11877545721","pt":1724088017322,"mc":[{"id":"1.232011572","rc":[{"batb":[[0,1.87,10]],"ltp":1.86,"tv":45.34,"id":72857117}]}]}
{"op":"mcm","clk":"11877545833","pt":1724088018421,"mc":[{"id":"1.232011572","rc":[{"batb":[[0,1.69,15.12],[1,1.65,17.06],[2,1.62,17.06]],"ltp":1.69,"tv":84.72,"id":72857115},{"batb":[[0,1.86,15.34],[1,1.85,1],[2,1.57,288.23]],"ltp":1.86,"tv":45.34,"id":72857117}]}]}
{"op":"mcm","clk":"11877545949","pt":1724088019618,"mc":[{"id":"1.232011572","rc":[{"batb":[[0,1.87,4],[1,1.86,15.34],[2,1.85,1]],"ltp":1.86,"tv":45.34,"id":72857117}]}]}
{"op":"mcm","clk":"11877546231","pt":1724088022221,"mc":[{"id":"1.232011572","rc":[{"batb":[[0,1.7,10],[1,1.69,15.12],[2,1.65,17.06]],"ltp":1.69,"tv":84.72,"id":72857115},{"batb":[[0,1.87,10]],"ltp":1.86,"tv":45.34,"id":72857117}]}]}
{"op":"mcm","clk":"11877546597","pt":1724088025608,"mc":[{"id":"1.232011572","rc":[{"batb":[[0,1.69,15.12],[1,1.65,17.06],[2,1.62,17.06]],"ltp":1.69,"tv":84.72,"id":72857115},{"batb":[[0,1.86,15.34],[1,1.85,1],[2,1.57,288.23]],"ltp":1.86,"tv":45.34,"id":72857117}]}]}
{"op":"mcm","clk":"11877546620","pt":1724088025811,"mc":[{"id":"1.232011572","rc":[{"batb":[[0,1.87,4],[1,1.86,15.34],[2,1.85,1]],"ltp":1.86,"tv":45.34,"id":72857117}]}]}
{"op":"mcm","clk":"11877546897","pt":1724088028214,"mc":[{"id":"1.232011572","rc":[{"batb":[[0,1.7,10],[1,1.69,15.12],[2,1.65,17.06]],"ltp":1.69,"tv":84.72,"id":72857115},{"batb":[[0,1.87,10]],"ltp":1.86,"tv":45.34,"id":72857117}]}]}
{"op":"mcm","clk":"11877547265","pt":1724088031608,"mc":[{"id":"1.232011572","rc":[{"batb":[[0,1.69,15.12],[1,1.65,17.06],[2,1.62,17.06]],"ltp":1.69,"tv":84.72,"id":72857115},{"batb":[[0,1.86,15.34],[1,1.85,1],[2,1.57,288.23]],"ltp":1.86,"tv":45.34,"id":72857117}]}]}
{"op":"mcm","clk":"11877547287","pt":1724088031808,"mc":[{"id":"1.232011572","rc":[{"batb":[[0,1.87,4],[1,1.86,15.34],[2,1.85,1]],"ltp":1.86,"tv":45.34,"id":72857117}]}]}
{"op":"mcm","clk":"11877547576","pt":1724088034209,"mc":[{"id":"1.232011572","rc":[{"batb":[[0,1.7,10],[1,1.69,15.12],[2,1.65,17.06]],"ltp":1.69,"tv":84.72,"id":72857115},{"batb":[[0,1.87,10]],"ltp":1.86,"tv":45.34,"id":72857117}]}]}
{"op":"mcm","clk":"11877547963","pt":1724088037640,"mc":[{"id":"1.232011572","rc":[{"batb":[[0,1.69,15.12],[1,1.65,17.06],[2,1.62,17.06]],"ltp":1.69,"tv":84.72,"id":72857115},{"batb":[[0,1.87,4]],"ltp":1.86,"tv":45.34,"id":72857117}]}]}
{"op":"mcm","clk":"11877548266","pt":1724088040149,"mc":[{"id":"1.232011572","rc":[{"batb":[[0,1.7,10],[1,1.69,15.12],[2,1.65,17.06]],"ltp":1.69,"tv":84.72,"id":72857115},{"batb":[[0,1.87,10]],"ltp":1.86,"tv":45.34,"id":72857117}]}]}
{"op":"mcm","clk":"11877548684","pt":1724088043639,"mc":[{"id":"1.232011572","rc":[{"batb":[[0,1.69,15.12],[1,1.65,17.06],[2,1.62,17.06]],"ltp":1.69,"tv":84.72,"id":72857115},{"batb":[[0,1.88,4]],"ltp":1.86,"tv":45.34,"id":72857117}]}]}
{"op":"mcm","clk":"11877548994","pt":1724088046254,"mc":[{"id":"1.232011572","rc":[{"batb":[[0,1.7,10],[1,1.69,15.12],[2,1.65,17.06]],"ltp":1.69,"tv":84.72,"id":72857115},{"batb":[[0,1.87,10]],"ltp":1.86,"tv":45.34,"id":72857117}]}]}
{"op":"mcm","clk":"11877549385","pt":1724088049767,"mc":[{"id":"1.232011572","rc":[{"batb":[[0,1.69,15.12],[1,1.65,17.06],[2,1.62,17.06]],"ltp":1.69,"tv":84.72,"id":72857115},{"batb":[[0,1.87,4]],"ltp":1.86,"tv":45.34,"id":72857117}]}]}
{"op":"mcm","clk":"11877549723","pt":1724088052373,"mc":[{"id":"1.232011572","rc":[{"batb":[[0,1.7,10],[1,1.69,15.12],[2,1.65,17.06]],"ltp":1.69,"tv":84.72,"id":72857115},{"batb":[[0,1.87,10]],"ltp":1.86,"tv":45.34,"id":72857117}]}]}
{"op":"mcm","clk":"11877550178","pt":1724088056131,"mc":[{"id":"1.232011572","rc":[{"batb":[[0,1.69,15.12],[1,1.65,17.06],[2,1.62,17.06]],"ltp":1.69,"tv":84.72,"id":72857115},{"batb":[[0,1.87,4]],"ltp":1.86,"tv":45.34,"id":72857117}]}]}
{"op":"mcm","clk":"11877550462","pt":1724088058639,"mc":[{"id":"1.232011572","rc":[{"batb":[[0,1.7,10],[1,1.69,15.12],[2,1.65,17.06]],"ltp":1.69,"tv":84.72,"id":72857115},{"batb":[[0,1.87,10]],"ltp":1.86,"tv":45.34,"id":72857117}]}]}
{"op":"mcm","clk":"11877550871","pt":1724088062073,"mc":[{"id":"1.232011572","rc":[{"batb":[[0,1.69,15.12],[1,1.65,17.06],[2,1.62,17.06]],"ltp":1.69,"tv":84.72,"id":72857115},{"batb":[[0,1.87,4]],"ltp":1.86,"tv":45.34,"id":72857117}]}]}
{"op":"mcm","clk":"11877551212","pt":1724088064652,"mc":[{"id":"1.232011572","rc":[{"batb":[[0,1.7,10],[1,1.69,15.12],[2,1.65,17.06]],"ltp":1.69,"tv":84.72,"id":72857115},{"batb":[[0,1.87,10]],"ltp":1.86,"tv":45.34,"id":72857117}]}]}
{"op":"mcm","clk":"11877551635","pt":1724088068253,"mc":[{"id":"1.232011572","rc":[{"batb":[[0,1.69,15.12],[1,1.65,17.06],[2,1.62,17.06]],"ltp":1.69,"tv":84.72,"id":72857115},{"batb":[[0,1.87,4]],"ltp":1.86,"tv":45.34,"id":72857117}]}]}
{"op":"mcm","clk":"11877551903","pt":1724088070547,"mc":[{"id":"1.232011572","rc":[{"batb":[[0,1.86,15.34],[1,1.85,1],[2,1.57,288.23]],"ltp":1.86,"tv":45.34,"id":72857117}]}]}
{"op":"mcm","clk":"11877551942","pt":1724088070859,"mc":[{"id":"1.232011572","rc":[{"batb":[[0,1.7,10],[1,1.69,15.12],[2,1.65,17.06]],"ltp":1.69,"tv":84.72,"id":72857115},{"batb":[[0,1.87,10],[1,1.86,15.34],[2,1.85,1]],"ltp":1.86,"tv":45.34,"id":72857117}]}]}
{"op":"mcm","clk":"11877552378","pt":1724088074471,"mc":[{"id":"1.232011572","rc":[{"batb":[[0,1.69,15.12],[1,1.65,17.06],[2,1.62,17.06]],"ltp":1.69,"tv":84.72,"id":72857115},{"batb":[[0,1.87,4]],"ltp":1.86,"tv":45.34,"id":72857117}]}]}
{"op":"mcm","clk":"11877552644","pt":1724088076662,"mc":[{"id":"1.232011572","rc":[{"batb":[[0,1.86,15.34],[1,1.85,1],[2,1.57,288.23]],"ltp":1.86,"tv":45.34,"id":72857117}]}]}
{"op":"mcm","clk":"11877552680","pt":1724088076985,"mc":[{"id":"1.232011572","rc":[{"batb":[[0,1.7,10],[1,1.69,15.12],[2,1.65,17.06]],"ltp":1.69,"tv":84.72,"id":72857115},{"batb":[[0,1.87,10],[1,1.86,15.34],[2,1.85,1]],"ltp":1.86,"tv":45.34,"id":72857117}]}]}
{"op":"mcm","clk":"11877553112","pt":1724088080490,"mc":[{"id":"1.232011572","rc":[{"batb":[[0,1.69,15.12],[1,1.65,17.06],[2,1.62,17.06]],"ltp":1.69,"tv":84.72,"id":72857115},{"batb":[[0,1.87,4]],"ltp":1.86,"tv":45.34,"id":72857117}]}]}
{"op":"mcm","clk":"11877553443","pt":1724088082972,"mc":[{"id":"1.232011572","rc":[{"batb":[[0,1.7,10],[1,1.69,15.12],[2,1.65,17.06]],"ltp":1.69,"tv":84.72,"id":72857115},{"batb":[[0,1.87,10]],"ltp":1.86,"tv":45.34,"id":72857117}]}]}
{"op":"mcm","clk":"11877553870","pt":1724088086579,"mc":[{"id":"1.232011572","rc":[{"batb":[[0,1.69,15.12],[1,1.65,17.06],[2,1.62,17.06]],"ltp":1.69,"tv":84.72,"id":72857115},{"batb":[[0,1.87,4]],"ltp":1.86,"tv":45.34,"id":72857117}]}]}
{"op":"mcm","clk":"11877554195","pt":1724088089297,"mc":[{"id":"1.232011572","rc":[{"batb":[[0,1.7,10],[1,1.69,15.12],[2,1.65,17.06]],"ltp":1.69,"tv":84.72,"id":72857115},{"batb":[[0,1.87,10]],"ltp":1.86,"tv":45.34,"id":72857117}]}]}
{"op":"mcm","clk":"11877554583","pt":1724088092489,"mc":[{"id":"1.232011572","rc":[{"batb":[[0,1.69,15.12],[1,1.65,17.06],[2,1.62,17.06]],"ltp":1.69,"tv":84.72,"id":72857115},{"batb":[[0,1.86,15.34],[1,1.85,1],[2,1.57,288.23]],"ltp":1.86,"tv":45.34,"id":72857117}]}]}
{"op":"mcm","clk":"11877554618","pt":1724088092803,"mc":[{"id":"1.232011572","rc":[{"batb":[[0,1.87,4],[1,1.86,15.34],[2,1.85,1]],"ltp":1.86,"tv":45.34,"id":72857117}]}]}
{"op":"mcm","clk":"11877554911","pt":1724088095296,"mc":[{"id":"1.232011572","rc":[{"batb":[[0,1.7,10],[1,1.69,15.12],[2,1.65,17.06]],"ltp":1.69,"tv":84.72,"id":72857115},{"batb":[[0,1.87,10]],"ltp":1.86,"tv":45.34,"id":72857117}]}]}
{"op":"mcm","clk":"11877555309","pt":1724088098720,"mc":[{"id":"1.232011572","rc":[{"batb":[[0,1.69,15.12],[1,1.65,17.06],[2,1.62,17.06]],"ltp":1.69,"tv":84.72,"id":72857115},{"batb":[[0,1.86,15.34],[1,1.85,1],[2,1.57,288.23]],"ltp":1.86,"tv":45.34,"id":72857117}]}]}
{"op":"mcm","clk":"11877555347","pt":1724088098999,"mc":[{"id":"1.232011572","rc":[{"batb":[[0,1.87,4],[1,1.86,15.34],[2,1.85,1]],"ltp":1.86,"tv":45.34,"id":72857117}]}]}
{"op":"mcm","clk":"11877555691","pt":1724088101706,"mc":[{"id":"1.232011572","rc":[{"batb":[[0,1.7,10],[1,1.69,15.12],[2,1.65,17.06]],"ltp":1.69,"tv":84.72,"id":72857115},{"batb":[[0,1.87,10]],"ltp":1.86,"tv":45.34,"id":72857117}]}]}
{"op":"mcm","clk":"11877556081","pt":1724088105097,"mc":[{"id":"1.232011572","rc":[{"batb":[[0,1.69,15.12],[1,1.65,17.06],[2,1.62,17.06]],"ltp":1.69,"tv":84.72,"id":72857115},{"batb":[[0,1.87,4]],"ltp":1.86,"tv":45.34,"id":72857117}]}]}
{"op":"mcm","clk":"11877556373","pt":1724088107604,"mc":[{"id":"1.232011572","rc":[{"batb":[[0,1.86,15.34],[1,1.85,1],[2,1.57,288.23]],"ltp":1.86,"tv":45.34,"id":72857117}]}]}
{"op":"mcm","clk":"11877556398","pt":1724088107809,"mc":[{"id":"1.232011572","rc":[{"batb":[[0,1.7,10],[1,1.69,15.12],[2,1.65,17.06]],"ltp":1.69,"tv":84.72,"id":72857115},{"batb":[[0,1.87,10],[1,1.86,15.34],[2,1.85,1]],"ltp":1.86,"tv":45.34,"id":72857117}]}]}
{"op":"mcm","clk":"11877556805","pt":1724088111303,"mc":[{"id":"1.232011572","rc":[{"batb":[[0,1.69,15.12],[1,1.65,17.06],[2,1.62,17.06]],"ltp":1.69,"tv":84.72,"id":72857115},{"batb":[[0,1.87,4]],"ltp":1.86,"tv":45.34,"id":72857117}]}]}
{"op":"mcm","clk":"11877557066","pt":1724088113500,"mc":[{"id":"1.232011572","rc":[{"batb":[[0,1.86,15.34],[1,1.85,1],[2,1.57,288.23]],"ltp":1.86,"tv":45.34,"id":72857117}]}]}
{"op":"mcm","clk":"11877557100","pt":1724088113806,"mc":[{"id":"1.232011572","rc":[{"batb":[[0,1.7,10],[1,1.69,15.12],[2,1.65,17.06]],"ltp":1.69,"tv":84.72,"id":72857115},{"batb":[[0,1.87,10],[1,1.86,15.34],[2,1.85,1]],"ltp":1.86,"tv":45.34,"id":72857117}]}]}
{"op":"mcm","clk":"11877557532","pt":1724088117316,"mc":[{"id":"1.232011572","rc":[{"batb":[[0,1.69,15.12],[1,1.65,17.06],[2,1.62,17.06]],"ltp":1.69,"tv":84.72,"id":72857115},{"batb":[[0,1.88,4]],"ltp":1.86,"tv":45.34,"id":72857117}]}]}
{"op":"mcm","clk":"11877557867","pt":1724088120146,"mc":[{"id":"1.232011572","rc":[{"batb":[[0,1.7,10],[1,1.69,15.12],[2,1.65,17.06]],"ltp":1.69,"tv":84.72,"id":72857115},{"batb":[[0,1.87,10]],"ltp":1.86,"tv":45.34,"id":72857117}]}]}
{"op":"mcm","clk":"11877558219","pt":1724088123419,"mc":[{"id":"1.232011572","rc":[{"batb":[[0,1.69,15.12],[1,1.65,17.06],[2,1.62,17.06]],"ltp":1.69,"tv":84.72,"id":72857115},{"batb":[[0,1.86,15.34],[1,1.85,1],[2,1.57,288.23]],"ltp":1.86,"tv":45.34,"id":72857117}]}]}
{"op":"mcm","clk":"11877559329","pt":1724088133657,"mc":[{"id":"1.232011572","rc":[{"batb":[[0,1.7,10],[1,1.69,15.12],[2,1.65,17.06]],"ltp":1.69,"tv":84.72,"id":72857115},{"batb":[[0,1.87,14],[1,1.86,15.34],[2,1.85,1]],"batl":[[0,2.7,16.59]],"ltp":1.86,"tv":45.34,"id":72857117}]}]}
{"op":"mcm","clk":"11877559597","pt":1724088135857,"mc":[{"id":"1.232011572","rc":[{"batb":[[0,1.87,10]],"ltp":1.86,"tv":45.34,"id":72857117}]}]}
{"op":"mcm","clk":"11877559717","pt":1724088137059,"mc":[{"id":"1.232011572","rc":[{"batb":[[0,1.69,15.12],[1,1.65,17.06],[2,1.62,17.06]],"ltp":1.69,"tv":84.72,"id":72857115},{"batb":[[0,1.86,15.34],[1,1.85,1],[2,1.57,288.23]],"ltp":1.86,"tv":45.34,"id":72857117}]}]}
{"op":"mcm","clk":"11877560498","pt":1724088144167,"mc":[{"id":"1.232011572","rc":[{"batb":[[0,1.7,10],[1,1.69,15.12],[2,1.65,17.06]],"ltp":1.69,"tv":84.72,"id":72857115},{"batb":[[0,1.87,14],[1,1.86,15.34],[2,1.85,1]],"ltp":1.86,"tv":45.34,"id":72857117}]}]}
{"op":"mcm","clk":"11877560796","pt":1724088146770,"mc":[{"id":"1.232011572","rc":[{"batb":[[0,1.87,10]],"ltp":1.86,"tv":45.34,"id":72857117}]}]}
{"op":"mcm","clk":"11877560918","pt":1724088147778,"mc":[{"id":"1.232011572","rc":[{"batb":[[0,1.69,15.12],[1,1.65,17.06],[2,1.62,17.06]],"ltp":1.69,"tv":84.72,"id":72857115},{"batb":[[0,1.86,15.34],[1,1.85,1],[2,1.57,288.23]],"ltp":1.86,"tv":45.34,"id":72857117}]}]}
{"op":"mcm","clk":"11877561371","pt":1724088152159,"mc":[{"id":"1.232011572","rc":[{"batb":[[0,1.7,10],[1,1.69,15.12],[2,1.65,17.06]],"ltp":1.69,"tv":84.72,"id":72857115},{"batb":[[0,1.87,14],[1,1.86,15.34],[2,1.85,1]],"ltp":1.86,"tv":45.34,"id":72857117}]}]}
{"op":"mcm","clk":"11877561666","pt":1724088154767,"mc":[{"id":"1.232011572","rc":[{"batb":[[0,1.87,10]],"ltp":1.86,"tv":45.34,"id":72857117}]}]}
{"op":"mcm","clk":"11877561780","pt":1724088155690,"mc":[{"id":"1.232011572","rc":[{"batb":[[0,1.69,15.12],[1,1.65,17.06],[2,1.62,17.06]],"ltp":1.69,"tv":84.72,"id":72857115},{"batb":[[0,1.86,15.34],[1,1.85,1],[2,1.57,288.23]],"ltp":1.86,"tv":45.34,"id":72857117}]}]}
{"op":"mcm","clk":"11877562696","pt":1724088163199,"mc":[{"id":"1.232011572","rc":[{"batb":[[0,1.7,10],[1,1.69,15.12],[2,1.65,17.06]],"ltp":1.69,"tv":84.72,"id":72857115},{"batb":[[0,1.87,14],[1,1.86,15.34],[2,1.85,1]],"ltp":1.86,"tv":45.34,"id":72857117}]}]}
{"op":"mcm","clk":"11877562977","pt":1724088165798,"mc":[{"id":"1.232011572","rc":[{"batb":[[0,1.87,10]],"ltp":1.86,"tv":45.34,"id":72857117}]}]}
{"op":"mcm","clk":"11877563108","pt":1724088166897,"mc":[{"id":"1.232011572","rc":[{"batb":[[0,1.69,15.12],[1,1.65,17.06],[2,1.62,17.06]],"ltp":1.69,"tv":84.72,"id":72857115},{"batb":[[0,1.86,15.34],[1,1.85,1],[2,1.57,288.23]],"ltp":1.86,"tv":45.34,"id":72857117}]}]}
{"op":"mcm","clk":"11877566901","pt":1724088199114,"mc":[{"id":"1.232011572","rc":[{"batb":[[0,1.7,10],[1,1.69,15.12],[2,1.65,17.06]],"ltp":1.69,"tv":84.72,"id":72857115},{"batb":[[0,1.87,14],[1,1.86,15.34],[2,1.85,1]],"ltp":1.86,"tv":45.34,"id":72857117}]}]}
{"op":"mcm","clk":"11877567213","pt":1724088201747,"mc":[{"id":"1.232011572","rc":[{"batb":[[0,1.87,10]],"ltp":1.86,"tv":45.34,"id":72857117}]}]}
{"op":"mcm","clk":"11877567324","pt":1724088202732,"mc":[{"id":"1.232011572","rc":[{"batb":[[0,1.69,15.12],[1,1.65,17.06],[2,1.62,17.06]],"ltp":1.69,"tv":84.72,"id":72857115},{"batb":[[0,1.86,15.34],[1,1.85,1],[2,1.57,288.23]],"ltp":1.86,"tv":45.34,"id":72857117}]}]}
{"op":"mcm","clk":"11877569667","pt":1724088218836,"mc":[{"id":"1.232011572","rc":[{"batb":[[0,1.7,10],[1,1.69,15.12],[2,1.65,17.06]],"ltp":1.69,"tv":84.72,"id":72857115},{"batb":[[0,1.87,14],[1,1.86,15.34],[2,1.85,1]],"ltp":1.86,"tv":45.34,"id":72857117}]}]}
{"op":"mcm","clk":"11877569966","pt":1724088221352,"mc":[{"id":"1.232011572","rc":[{"batb":[[0,1.87,10]],"ltp":1.86,"tv":45.34,"id":72857117}]}]}
{"op":"mcm","clk":"11877570082","pt":1724088222247,"mc":[{"id":"1.232011572","rc":[{"batb":[[0,1.69,15.12],[1,1.65,17.06],[2,1.62,17.06]],"ltp":1.69,"tv":84.72,"id":72857115},{"batb":[[0,1.86,15.34],[1,1.85,1],[2,1.57,288.23]],"ltp":1.86,"tv":45.34,"id":72857117}]}]}
{"op":"mcm","clk":"11877571040","pt":1724088230633,"mc":[{"id":"1.232011572","rc":[{"batb":[[0,2.16,2.57],[1,1.69,15.12],[2,1.65,17.06]],"ltp":1.69,"tv":84.72,"id":72857115}]}]}
{"op":"mcm","clk":"11877571088","pt":1724088231052,"mc":[{"id":"1.232011572","rc":[{"trd":[[2.16,2.57]],"batb":[[0,1.7,10]],"ltp":2.16,"tv":87.29,"id":72857115},{"trd":[[1.87,9.35]],"batb":[[0,1.88,4],[1,1.87,7.03],[2,1.86,15.34]],"ltp":1.87,"tv":48.31,"id":72857117}],"tv":135.61}]}
{"op":"mcm","clk":"11877571324","pt":1724088233243,"mc":[{"id":"1.232011572","rc":[{"batb":[[0,1.87,7.03],[1,1.86,15.34],[2,1.85,1]],"ltp":1.87,"tv":48.31,"id":72857117}]}]}
{"op":"mcm","clk":"11877571462","pt":1724088234448,"mc":[{"id":"1.232011572","rc":[{"batb":[[0,1.69,15.12],[1,1.65,17.06],[2,1.62,17.06]],"ltp":2.16,"tv":87.29,"id":72857115},{"batb":[[0,1.86,15.34],[1,1.85,1],[2,1.57,288.23]],"ltp":1.87,"tv":48.31,"id":72857117}]}]}
{"op":"mcm","clk":"11877573299","pt":1724088251266,"mc":[{"id":"1.232011572","rc":[{"batb":[[0,1.7,10],[1,1.69,15.12],[2,1.65,17.06]],"ltp":2.16,"tv":87.29,"id":72857115},{"batb":[[0,1.87,14],[1,1.86,15.34],[2,1.85,1]],"ltp":1.87,"tv":48.31,"id":72857117}]}]}
{"op":"mcm","clk":"11877573588","pt":1724088254088,"mc":[{"id":"1.232011572","rc":[{"batb":[[0,1.87,10]],"ltp":1.87,"tv":48.31,"id":72857117}]}]}
{"op":"mcm","clk":"11877573672","pt":1724088254872,"mc":[{"id":"1.232011572","rc":[{"batb":[[0,1.69,15.12],[1,1.65,17.06],[2,1.62,17.06]],"ltp":2.16,"tv":87.29,"id":72857115},{"batb":[[0,1.86,15.34],[1,1.85,1],[2,1.57,288.23]],"ltp":1.87,"tv":48.31,"id":72857117}]}]}
{"op":"mcm","clk":"11877574659","pt":1724088264883,"mc":[{"id":"1.232011572","rc":[{"batb":[[0,1.7,10],[1,1.69,15.12],[2,1.65,17.06]],"ltp":2.16,"tv":87.29,"id":72857115},{"batb":[[0,1.87,14],[1,1.86,15.34],[2,1.85,1]],"ltp":1.87,"tv":48.31,"id":72857117}]}]}
{"op":"mcm","clk":"11877574897","pt":1724088267179,"mc":[{"id":"1.232011572","rc":[{"batb":[[0,1.87,10]],"ltp":1.87,"tv":48.31,"id":72857117}]}]}
{"op":"mcm","clk":"11877574980","pt":1724088268089,"mc":[{"id":"1.232011572","rc":[{"batb":[[0,1.69,15.12],[1,1.65,17.06],[2,1.63,143.85]],"ltp":2.16,"tv":87.29,"id":72857115},{"batb":[[0,1.86,15.34],[1,1.85,1],[2,1.57,288.23]],"ltp":1.87,"tv":48.31,"id":72857117}]}]}
{"op":"mcm","clk":"11877575936","pt":1724088277393,"mc":[{"id":"1.232011572","rc":[{"batb":[[0,1.7,10],[1,1.69,15.12],[2,1.65,17.06]],"ltp":2.16,"tv":87.29,"id":72857115},{"batb":[[0,1.87,14],[1,1.86,15.34],[2,1.85,1]],"ltp":1.87,"tv":48.31,"id":72857117}]}]}
{"op":"mcm","clk":"11877576254","pt":1724088280303,"mc":[{"id":"1.232011572","rc":[{"batb":[[0,1.87,10]],"ltp":1.87,"tv":48.31,"id":72857117}]}]}
{"op":"mcm","clk":"11877576340","pt":1724088281089,"mc":[{"id":"1.232011572","rc":[{"batb":[[0,1.69,15.12],[1,1.65,17.06],[2,1.63,143.85]],"ltp":2.16,"tv":87.29,"id":72857115},{"batb":[[0,1.86,15.34],[1,1.85,1],[2,1.57,288.23]],"ltp":1.87,"tv":48.31,"id":72857117}]}]}
{"op":"mcm","clk":"11877576499","pt":1724088282902,"mc":[{"id":"1.232011572","rc":[{"batb":[[0,1.91,8.26],[1,1.69,15.12],[2,1.65,17.06]],"ltp":2.16,"tv":87.29,"id":72857115},{"batb":[[0,1.87,4],[1,1.86,15.34],[2,1.85,1]],"ltp":1.87,"tv":48.31,"id":72857117}]}]}
{"op":"mcm","clk":"11877576761","pt":1724088285421,"mc":[{"id":"1.232011572","rc":[{"batb":[[0,1.92,10],[1,1.91,8.26],[2,1.69,15.12]],"ltp":2.16,"tv":87.29,"id":72857115},{"batb":[[0,1.87,10]],"ltp":1.87,"tv":48.31,"id":72857117}]}]}
{"op":"mcm","clk":"11877577151","pt":1724088289005,"mc":[{"id":"1.232011572","rc":[{"batb":[[0,1.91,8.26],[1,1.69,15.12],[2,1.65,17.06]],"ltp":2.16,"tv":87.29,"id":72857115},{"batb":[[0,1.87,4]],"ltp":1.87,"tv":48.31,"id":72857117}]}]}
{"op":"mcm","clk":"11877577498","pt":1724088291715,"mc":[{"id":"1.232011572","rc":[{"batb":[[0,1.92,10],[1,1.91,8.26],[2,1.69,15.12]],"ltp":2.16,"tv":87.29,"id":72857115},{"batb":[[0,1.87,10]],"ltp":1.87,"tv":48.31,"id":72857117}]}]}
{"op":"mcm","clk":"11877577899","pt":1724088295123,"mc":[{"id":"1.232011572","rc":[{"batb":[[0,1.91,8.26],[1,1.69,15.12],[2,1.65,17.06]],"ltp":2.16,"tv":87.29,"id":72857115},{"batb":[[0,1.87,4]],"ltp":1.87,"tv":48.31,"id":72857117}]}]}
{"op":"mcm","clk":"11877578134","pt":1724088297523,"mc":[{"id":"1.232011572","rc":[{"batb":[[0,1.86,15.34],[1,1.85,1],[2,1.79,8.8]],"ltp":1.87,"tv":48.31,"id":72857117}]}]}
{"op":"mcm","clk":"11877578191","pt":1724088297943,"mc":[{"id":"1.232011572","rc":[{"batb":[[0,1.92,10],[1,1.91,8.26],[2,1.69,15.12]],"ltp":2.16,"tv":87.29,"id":72857115},{"batb":[[0,1.87,10],[1,1.86,15.34],[2,1.85,1]],"ltp":1.87,"tv":48.31,"id":72857117}]}]}
{"op":"mcm","clk":"11877578557","pt":1724088300740,"mc":[{"id":"1.232011572","rc":[{"batb":[[0,1.99,7.93],[1,1.92,10]],"ltp":2.16,"tv":87.29,"id":72857115},{"batb":[[0,1.88,4],[1,1.87,10],[2,1.86,15.34]],"ltp":1.87,"tv":48.31,"id":72857117}]}]}
{"op":"mcm","clk":"11877578602","pt":1724088301122,"mc":[{"id":"1.232011572","rc":[{"batb":[[1,1.69,15.12],[2,1.65,17.06]],"ltp":2.16,"tv":87.29,"id":72857115},{"batb":[[1,1.86,15.34],[2,1.85,1]],"ltp":1.87,"tv":48.31,"id":72857117}]}]}
{"op":"mcm","clk":"11877578828","pt":1724088303029,"mc":[{"id":"1.232011572","rc":[{"batb":[[0,1.86,15.34],[1,1.85,1],[2,1.73,9.13]],"ltp":1.87,"tv":48.31,"id":72857117}]}]}
{"op":"mcm","clk":"11877579761","pt":1724088310831,"mc":[{"id":"1.232011572","rc":[{"batb":[[0,2,10],[1,1.99,7.93],[2,1.69,15.12]],"ltp":2.16,"tv":87.29,"id":72857115},{"batb":[[0,1.87,14],[1,1.86,15.34],[2,1.85,1]],"ltp":1.87,"tv":48.31,"id":72857117}]}]}
{"op":"mcm","clk":"11877580081","pt":1724088313532,"mc":[{"id":"1.232011572","rc":[{"batb":[[0,1.87,10]],"ltp":1.87,"tv":48.31,"id":72857117}]}]}
{"op":"mcm","clk":"11877580196","pt":1724088314476,"mc":[{"id":"1.232011572","rc":[{"batb":[[0,1.99,7.93],[1,1.69,15.12],[2,1.65,17.06]],"ltp":2.16,"tv":87.29,"id":72857115},{"batb":[[0,1.86,15.34],[1,1.85,1],[2,1.73,9.13]],"ltp":1.87,"tv":48.31,"id":72857117}]}]}
{"op":"mcm","clk":"11877580361","pt":1724088315733,"mc":[{"id":"1.232011572","rc":[{"batb":[[0,1.87,4],[1,1.86,15.34],[2,1.85,1]],"ltp":1.87,"tv":48.31,"id":72857117}]}]}
{"op":"mcm","clk":"11877580643","pt":1724088318155,"mc":[{"id":"1.232011572","rc":[{"batb":[[0,2,10],[1,1.99,7.93],[2,1.69,15.12]],"ltp":2.16,"tv":87.29,"id":72857115},{"batb":[[0,1.87,10]],"ltp":1.87,"tv":48.31,"id":72857117}]}]}
{"op":"mcm","clk":"11877581070","pt":1724088321518,"mc":[{"id":"1.232011572","rc":[{"batb":[[0,1.99,7.93],[1,1.69,15.12],[2,1.65,17.06]],"ltp":2.16,"tv":87.29,"id":72857115},{"batb":[[0,1.87,4]],"ltp":1.87,"tv":48.31,"id":72857117}]}]}
{"op":"mcm","clk":"11877581336","pt":1724088323726,"mc":[{"id":"1.232011572","rc":[{"batb":[[0,1.86,15.34],[1,1.85,1],[2,1.71,9.2]],"ltp":1.87,"tv":48.31,"id":72857117}]}]}
{"op":"mcm","clk":"11877581350","pt":1724088323828,"mc":[{"id":"1.232011572","rc":[{"batb":[[0,2,10],[1,1.99,7.93],[2,1.69,15.12]],"ltp":2.16,"tv":87.29,"id":72857115},{"batb":[[0,1.87,10],[1,1.86,15.34],[2,1.85,1]],"ltp":1.87,"tv":48.31,"id":72857117}]}]}
{"op":"mcm","clk":"11877581728","pt":1724088327339,"mc":[{"id":"1.232011572","rc":[{"batb":[[0,1.99,7.93],[1,1.69,15.12],[2,1.65,17.06]],"ltp":2.16,"tv":87.29,"id":72857115},{"batb":[[0,1.87,4]],"ltp":1.87,"tv":48.31,"id":72857117}]}]}
{"op":"mcm","clk":"11877582007","pt":1724088329647,"mc":[{"id":"1.232011572","rc":[{"batb":[[0,2,10],[1,1.99,7.93],[2,1.69,15.12]],"ltp":2.16,"tv":87.29,"id":72857115},{"batb":[[0,1.87,10]],"ltp":1.87,"tv":48.31,"id":72857117}]}]}
{"op":"mcm","clk":"11877582425","pt":1724088333150,"mc":[{"id":"1.232011572","rc":[{"batb":[[0,1.99,7.93],[1,1.69,15.12],[2,1.65,17.06]],"ltp":2.16,"tv":87.29,"id":72857115},{"batb":[[0,1.87,4]],"ltp":1.87,"tv":48.31,"id":72857117}]}]}
{"op":"mcm","clk":"11877582684","pt":1724088335653,"mc":[{"id":"1.232011572","rc":[{"batb":[[0,2,10],[1,1.99,7.93],[2,1.69,15.12]],"ltp":2.16,"tv":87.29,"id":72857115},{"batb":[[0,1.87,10]],"ltp":1.87,"tv":48.31,"id":72857117}]}]}
{"op":"mcm","clk":"11877583040","pt":1724088338944,"mc":[{"id":"1.232011572","rc":[{"batb":[[0,1.99,7.93],[1,1.69,15.12],[2,1.65,17.06]],"ltp":2.16,"tv":87.29,"id":72857115},{"batb":[[0,1.88,4]],"ltp":1.87,"tv":48.31,"id":72857117}]}]}
{"op":"mcm","clk":"11877583338","pt":1724088341563,"mc":[{"id":"1.232011572","rc":[{"batb":[[0,2,10],[1,1.99,7.93],[2,1.69,15.12]],"ltp":2.16,"tv":87.29,"id":72857115},{"batb":[[0,1.87,10]],"ltp":1.87,"tv":48.31,"id":72857117}]}]}
{"op":"mcm","clk":"11877583750","pt":1724088345065,"mc":[{"id":"1.232011572","rc":[{"batb":[[0,1.99,7.93],[1,1.69,15.12],[2,1.65,17.06]],"ltp":2.16,"tv":87.29,"id":72857115},{"batb":[[0,1.87,4]],"ltp":1.87,"tv":48.31,"id":72857117}]}]}
{"op":"mcm","clk":"11877584029","pt":1724088347682,"mc":[{"id":"1.232011572","rc":[{"batb":[[0,2,10],[1,1.99,7.93],[2,1.69,15.12]],"ltp":2.16,"tv":87.29,"id":72857115},{"batb":[[0,1.87,10]],"ltp":1.87,"tv":48.31,"id":72857117}]}]}
{"op":"mcm","clk":"11877584462","pt":1724088351286,"mc":[{"id":"1.232011572","rc":[{"batb":[[0,1.99,7.93],[1,1.69,15.12],[2,1.65,17.06]],"ltp":2.16,"tv":87.29,"id":72857115},{"batb":[[0,1.87,4]],"ltp":1.87,"tv":48.31,"id":72857117}]}]}
{"op":"mcm","clk":"11877584768","pt":1724088353698,"mc":[{"id":"1.232011572","rc":[{"batb":[[0,1.86,15.34],[1,1.85,1],[2,1.71,9.2]],"ltp":1.87,"tv":48.31,"id":72857117}]}]}
{"op":"mcm","clk":"11877584791","pt":1724088353866,"mc":[{"id":"1.232011572","rc":[{"batb":[[0,2,10],[1,1.99,7.93],[2,1.69,15.12]],"ltp":2.16,"tv":87.29,"id":72857115},{"batb":[[0,1.87,10],[1,1.86,15.34],[2,1.85,1]],"ltp":1.87,"tv":48.31,"id":72857117}]}]}
{"op":"mcm","clk":"11877585211","pt":1724088357374,"mc":[{"id":"1.232011572","rc":[{"batb":[[0,1.99,7.93],[1,1.69,15.12],[2,1.65,17.06]],"ltp":2.16,"tv":87.29,"id":72857115},{"batb":[[0,1.87,4]],"ltp":1.87,"tv":48.31,"id":72857117}]}]}
{"op":"mcm","clk":"11877585548","pt":1724088360022,"mc":[{"id":"1.232011572","rc":[{"batb":[[0,2,10],[1,1.99,7.93],[2,1.69,15.12]],"ltp":2.16,"tv":87.29,"id":72857115},{"batb":[[0,1.87,10]],"ltp":1.87,"tv":48.31,"id":72857117}]}]}
{"op":"mcm","clk":"11877586035","pt":1724088363576,"mc":[{"id":"1.232011572","rc":[{"batb":[[0,1.99,7.93],[1,1.69,15.12],[2,1.65,17.06]],"ltp":2.16,"tv":87.29,"id":72857115},{"batb":[[0,1.87,4]],"ltp":1.87,"tv":48.31,"id":72857117}]}]}
{"op":"mcm","clk":"11877586351","pt":1724088366184,"mc":[{"id":"1.232011572","rc":[{"batb":[[0,2,10],[1,1.99,7.93],[2,1.69,15.12]],"ltp":2.16,"tv":87.29,"id":72857115},{"batb":[[0,1.87,10]],"ltp":1.87,"tv":48.31,"id":72857117}]}]}
{"op":"mcm","clk":"11877586739","pt":1724088369697,"mc":[{"id":"1.232011572","rc":[{"batb":[[0,1.99,7.93],[1,1.69,15.12],[2,1.65,17.06]],"ltp":2.16,"tv":87.29,"id":72857115},{"batb":[[0,1.87,4]],"ltp":1.87,"tv":48.31,"id":72857117}]}]}
{"op":"mcm","clk":"11877587030","pt":1724088372219,"mc":[{"id":"1.232011572","rc":[{"batb":[[0,2,10],[1,1.99,7.93],[2,1.69,15.12]],"ltp":2.16,"tv":87.29,"id":72857115},{"batb":[[0,1.87,10]],"ltp":1.87,"tv":48.31,"id":72857117}]}]}
{"op":"mcm","clk":"11877587410","pt":1724088375726,"mc":[{"id":"1.232011572","rc":[{"batb":[[0,1.99,7.93],[1,1.69,15.12],[2,1.65,17.06]],"ltp":2.16,"tv":87.29,"id":72857115},{"batb":[[0,1.87,4]],"ltp":1.87,"tv":48.31,"id":72857117}]}]}
{"op":"mcm","clk":"11877587690","pt":1724088378177,"mc":[{"id":"1.232011572","rc":[{"batb":[[0,2,10],[1,1.99,7.93],[2,1.69,15.12]],"ltp":2.16,"tv":87.29,"id":72857115},{"batb":[[0,1.87,10]],"ltp":1.87,"tv":48.31,"id":72857117}]}]}
{"op":"mcm","clk":"11877588064","pt":1724088381635,"mc":[{"id":"1.232011572","rc":[{"batb":[[0,1.99,7.93],[1,1.69,15.12],[2,1.65,17.06]],"ltp":2.16,"tv":87.29,"id":72857115},{"batb":[[0,1.86,15.34],[1,1.85,1],[2,1.71,9.2]],"ltp":1.87,"tv":48.31,"id":72857117}]}]}
{"op":"mcm","clk":"11877588102","pt":1724088381901,"mc":[{"id":"1.232011572","rc":[{"batb":[[0,1.87,4],[1,1.86,15.34],[2,1.85,1]],"ltp":1.87,"tv":48.31,"id":72857117}]}]}
{"op":"mcm","clk":"11877588371","pt":1724088384425,"mc":[{"id":"1.232011572","rc":[{"batb":[[0,2,10],[1,1.99,7.93],[2,1.69,15.12]],"ltp":2.16,"tv":87.29,"id":72857115},{"batb":[[0,1.87,10]],"ltp":1.87,"tv":48.31,"id":72857117}]}]}
{"op":"mcm","clk":"11877588776","pt":1724088388209,"mc":[{"id":"1.232011572","rc":[{"batb":[[0,1.99,7.93],[1,1.69,15.12],[2,1.65,17.06]],"ltp":2.16,"tv":87.29,"id":72857115},{"batb":[[0,1.87,4]],"ltp":1.87,"tv":48.31,"id":72857117}]}]}
{"op":"mcm","clk":"11877589032","pt":1724088390712,"mc":[{"id":"1.232011572","rc":[{"batb":[[0,1.86,15.34],[1,1.85,1],[2,1.71,9.2]],"ltp":1.87,"tv":48.31,"id":72857117}]}]}
{"op":"mcm","clk":"11877589052","pt":1724088390920,"mc":[{"id":"1.232011572","rc":[{"batb":[[0,2,10],[1,1.99,7.93],[2,1.69,15.12]],"ltp":2.16,"tv":87.29,"id":72857115},{"batb":[[0,1.87,10],[1,1.86,15.34],[2,1.85,1]],"ltp":1.87,"tv":48.31,"id":72857117}]}]}
{"op":"mcm","clk":"11877589452","pt":1724088394321,"mc":[{"id":"1.232011572","rc":[{"batb":[[0,1.99,7.93],[1,1.69,15.12],[2,1.65,17.06]],"ltp":2.16,"tv":87.29,"id":72857115},{"batb":[[0,1.87,4]],"ltp":1.87,"tv":48.31,"id":72857117}]}]}
{"op":"mcm","clk":"11877589761","pt":1724088397036,"mc":[{"id":"1.232011572","rc":[{"batb":[[0,2,10],[1,1.99,7.93],[2,1.69,15.12]],"ltp":2.16,"tv":87.29,"id":72857115},{"batb":[[0,1.87,10]],"ltp":1.87,"tv":48.31,"id":72857117}]}]}
{"op":"mcm","clk":"11877590144","pt":1724088400550,"mc":[{"id":"1.232011572","rc":[{"batb":[[0,1.99,7.93],[1,1.69,15.12],[2,1.65,17.06]],"ltp":2.16,"tv":87.29,"id":72857115},{"batb":[[0,1.87,4]],"ltp":1.87,"tv":48.31,"id":72857117}]}]}
{"op":"mcm","clk":"11877590351","pt":1724088402739,"mc":[{"id":"1.232011572","rc":[{"batb":[[0,1.86,15.34],[1,1.85,1],[2,1.71,9.2]],"ltp":1.87,"tv":48.31,"id":72857117}]}]}
{"op":"mcm","clk":"11877590368","pt":1724088402946,"mc":[{"id":"1.232011572","rc":[{"batb":[[0,2,10],[1,1.99,7.93],[2,1.69,15.12]],"ltp":2.16,"tv":87.29,"id":72857115},{"batb":[[0,1.87,10],[1,1.86,15.34],[2,1.85,1]],"ltp":1.87,"tv":48.31,"id":72857117}]}]}
{"op":"mcm","clk":"11877590776","pt":1724088406420,"mc":[{"id":"1.232011572","rc":[{"batb":[[0,1.99,7.93],[1,1.69,15.12],[2,1.65,17.06]],"ltp":2.16,"tv":87.29,"id":72857115},{"batb":[[0,1.87,4]],"ltp":1.87,"tv":48.31,"id":72857117}]}]}
{"op":"mcm","clk":"11877590996","pt":1724088408752,"mc":[{"id":"1.232011572","rc":[{"batb":[[0,1.86,15.34],[1,1.85,1],[2,1.71,9.2]],"ltp":1.87,"tv":48.31,"id":72857117}]}]}
{"op":"mcm","clk":"11877591020","pt":1724088408913,"mc":[{"id":"1.232011572","rc":[{"batb":[[0,2,10],[1,1.99,7.93],[2,1.69,15.12]],"ltp":2.16,"tv":87.29,"id":72857115},{"batb":[[0,1.87,10],[1,1.86,15.34],[2,1.85,1]],"ltp":1.87,"tv":48.31,"id":72857117}]}]}
{"op":"mcm","clk":"11877591436","pt":1724088412557,"mc":[{"id":"1.232011572","rc":[{"batb":[[0,1.99,7.93],[1,1.69,15.12],[2,1.65,17.06]],"ltp":2.16,"tv":87.29,"id":72857115},{"trd":[[1.87,17.35]],"batb":[[0,1.86,15.34],[1,1.85,1],[2,1.71,9.2]],"batl":[[0,1.87,3.47],[1,2.7,16.59]],"ltp":1.87,"tv":56.31,"id":72857117}],"tv":143.61}]}
{"op":"mcm","clk":"11877592464","pt":1724088422301,"mc":[{"id":"1.232011572","rc":[{"batb":[[0,1.7,10]],"ltp":2.16,"tv":87.29,"id":72857115},{"batb":[[2,1.57,288.23]],"ltp":1.87,"tv":56.31,"id":72857117}]}]}
{"op":"mcm","clk":"11877592815","pt":1724088425541,"mc":[{"id":"1.232011572","rc":[{"batb":[[0,1.69,15.12],[1,1.65,17.06],[2,1.63,143.85]],"ltp":2.16,"tv":87.29,"id":72857115}]}]}
{"op":"mcm","clk":"11877593461","pt":1724088431460,"mc":[{"id":"1.232011572","rc":[{"batb":[[0,1.7,10],[1,1.69,15.12],[2,1.65,17.06]],"ltp":2.16,"tv":87.29,"id":72857115},{"trd":[[1.87,24.28]],"batb":[[0,1.89,14],[1,1.88,13.6],[2,1.86,15.34]],"batl":[[0,2.7,16.59],[1,2.7,0]],"ltp":1.87,"tv":63.24,"id":72857117}],"tv":150.54}]}
{"op":"mcm","clk":"11877593705","pt":1724088433748,"mc":[{"id":"1.232011572","rc":[{"batb":[[0,1.89,10],[1,1.86,15.34],[2,1.85,1]],"ltp":1.87,"tv":63.24,"id":72857117}]}]}
{"op":"mcm","clk":"11877593808","pt":1724088434680,"mc":[{"id":"1.232011572","rc":[{"batb":[[0,1.69,15.12],[1,1.65,17.06],[2,1.63,143.85]],"ltp":2.16,"tv":87.29,"id":72857115},{"batb":[[0,1.91,13.6]],"ltp":1.87,"tv":63.24,"id":72857117}]}]}
{"op":"mcm","clk":"11877593859","pt":1724088435147,"mc":[{"id":"1.232011572","rc":[{"batb":[[0,1.86,15.34],[1,1.85,1],[2,1.57,288.23]],"ltp":1.87,"tv":63.24,"id":72857117}]}]}
{"op":"mcm","clk":"11877595534","pt":1724088450995,"mc":[{"id":"1.232011572","rc":[{"batb":[[0,1.7,10],[1,1.69,15.12],[2,1.65,17.06]],"ltp":2.16,"tv":87.29,"id":72857115},{"batb":[[0,1.87,14],[1,1.86,15.34],[2,1.85,1]],"ltp":1.87,"tv":63.24,"id":72857117}]}]}
{"op":"mcm","clk":"11877595838","pt":1724088453602,"mc":[{"id":"1.232011572","rc":[{"batb":[[0,1.87,10]],"ltp":1.87,"tv":63.24,"id":72857117}]}]}
{"op":"mcm","clk":"11877596009","pt":1724088454663,"mc":[{"id":"1.232011572","rc":[{"batb":[[0,1.86,15.34],[1,1.85,1],[2,1.57,288.23]],"ltp":1.87,"tv":63.24,"id":72857117}]}]}
{"op":"mcm","clk":"11877596022","pt":1724088454775,"mc":[{"id":"1.232011572","rc":[{"batb":[[0,1.69,15.12],[1,1.65,17.06],[2,1.63,143.85]],"ltp":2.16,"tv":87.29,"id":72857115}]}]}
{"op":"mcm","clk":"11877596320","pt":1724088457487,"mc":[{"id":"1.232011572","rc":[{"batb":[[0,1.7,10],[1,1.69,15.12],[2,1.65,17.06]],"ltp":2.16,"tv":87.29,"id":72857115},{"batb":[[0,1.88,10],[1,1.87,4],[2,1.86,15.34]],"ltp":1.87,"tv":63.24,"id":72857117}]}]}
{"op":"mcm","clk":"11877596546","pt":1724088459481,"mc":[{"id":"1.232011572","rc":[{"batb":[[1,1.86,15.34],[2,1.85,1]],"ltp":1.87,"tv":63.24,"id":72857117}]}]}
{"op":"mcm","clk":"11877596713","pt":1724088460785,"mc":[{"id":"1.232011572","rc":[{"batb":[[0,1.69,15.12],[1,1.65,17.06],[2,1.63,143.85]],"ltp":2.16,"tv":87.29,"id":72857115},{"batb":[[0,1.86,15.34],[1,1.85,1],[2,1.57,288.23]],"ltp":1.87,"tv":63.24,"id":72857117}]}]}
{"op":"mcm","clk":"11877597281","pt":1724088466008,"mc":[{"id":"1.232011572","rc":[{"batb":[[0,1.7,10],[1,1.69,15.12],[2,1.65,17.06]],"ltp":2.16,"tv":87.29,"id":72857115},{"batb":[[0,1.87,14],[1,1.86,15.34],[2,1.85,1]],"ltp":1.87,"tv":63.24,"id":72857117}]}]}
{"op":"mcm","clk":"11877597563","pt":1724088468713,"mc":[{"id":"1.232011572","rc":[{"batb":[[0,1.87,10]],"ltp":1.87,"tv":63.24,"id":72857117}]}]}
{"op":"mcm","clk":"11877597680","pt":1724088469720,"mc":[{"id":"1.232011572","rc":[{"batb":[[0,1.69,15.12],[1,1.65,17.06],[2,1.63,143.85]],"ltp":2.16,"tv":87.29,"id":72857115},{"batb":[[0,1.86,15.34],[1,1.85,1],[2,1.57,288.23]],"ltp":1.87,"tv":63.24,"id":72857117}]}]}
{"op":"mcm","clk":"11877597850","pt":1724088471417,"mc":[{"id":"1.232011572","rc":[{"batb":[[0,1.87,4],[1,1.86,15.34],[2,1.85,1]],"ltp":1.87,"tv":63.24,"id":72857117}]}]}
{"op":"mcm","clk":"11877598128","pt":1724088473620,"mc":[{"id":"1.232011572","rc":[{"batb":[[0,1.77,1.07],[1,1.7,10],[2,1.69,15.12]],"ltp":2.16,"tv":87.29,"id":72857115},{"batb":[[0,1.88,10]],"ltp":1.87,"tv":63.24,"id":72857117}]}]}
{"op":"mcm","clk":"11877598484","pt":1724088477309,"mc":[{"id":"1.232011572","rc":[{"batb":[[1,1.69,15.12],[2,1.65,17.06]],"ltp":2.16,"tv":87.29,"id":72857115},{"batb":[[0,1.87,4]],"ltp":1.87,"tv":63.24,"id":72857117}]}]}
{"op":"mcm","clk":"11877598608","pt":1724088478397,"mc":[{"id":"1.232011572","rc":[{"batb":[[0,1.9,8.27],[1,1.77,1.07],[2,1.69,15.12]],"ltp":2.16,"tv":87.29,"id":72857115}]}]}
{"op":"mcm","clk":"11877598741","pt":1724088479692,"mc":[{"id":"1.232011572","rc":[{"batb":[[0,1.86,15.34],[1,1.85,1],[2,1.79,8.79]],"ltp":1.87,"tv":63.24,"id":72857117}]}]}
{"op":"mcm","clk":"11877598764","pt":1724088479903,"mc":[{"id":"1.232011572","rc":[{"batb":[[0,1.98,7.96],[1,1.91,10],[2,1.77,1.07]],"ltp":2.16,"tv":87.29,"id":72857115},{"batb":[[0,1.87,10],[1,1.86,15.34],[2,1.85,1]],"ltp":1.87,"tv":63.24,"id":72857117}]}]}
{"op":"mcm","clk":"11877599168","pt":1724088483612,"mc":[{"id":"1.232011572","rc":[{"batb":[[1,1.77,1.07],[2,1.69,15.12]],"ltp":2.16,"tv":87.29,"id":72857115},{"batb":[[0,1.87,4]],"ltp":1.87,"tv":63.24,"id":72857117}]}]}
{"op":"mcm","clk":"11877599440","pt":1724088486123,"mc":[{"id":"1.232011572","rc":[{"batb":[[0,1.99,10],[1,1.98,7.96],[2,1.77,1.07]],"ltp":2.16,"tv":87.29,"id":72857115},{"batb":[[0,1.87,10]],"ltp":1.87,"tv":63.24,"id":72857117}]}]}
{"op":"mcm","clk":"11877599812","pt":1724088489433,"mc":[{"id":"1.232011572","rc":[{"batb":[[0,1.98,7.96],[1,1.77,1.07],[2,1.69,15.12]],"ltp":2.16,"tv":87.29,"id":72857115},{"batb":[[0,1.88,4]],"ltp":1.87,"tv":63.24,"id":72857117}]}]}
{"op":"mcm","clk":"11877600138","pt":1724088492039,"mc":[{"id":"1.232011572","rc":[{"batb":[[0,1.99,10],[1,1.98,7.96],[2,1.77,1.07]],"ltp":2.16,"tv":87.29,"id":72857115},{"batb":[[0,1.87,10]],"ltp":1.87,"tv":63.24,"id":72857117}]}]}
{"op":"mcm","clk":"11877600570","pt":1724088496126,"mc":[{"id":"1.232011572","rc":[{"batb":[[0,1.98,7.96],[1,1.77,1.07],[2,1.69,15.12]],"ltp":2.16,"tv":87.29,"id":72857115},{"batb":[[0,1.88,4]],"ltp":1.87,"tv":63.24,"id":72857117}]}]}
{"op":"mcm","clk":"11877600964","pt":1724088499252,"mc":[{"id":"1.232011572","rc":[{"batb":[[0,1.86,15.34],[1,1.85,1],[2,1.73,9.1]],"ltp":1.87,"tv":63.24,"id":72857117}]}]}
{"op":"mcm","clk":"11877601085","pt":1724088500146,"mc":[{"id":"1.232011572","rc":[{"batb":[[0,2,7.86]],"ltp":2.16,"tv":87.29,"id":72857115},{"batb":[[2,1.71,9.2]],"ltp":1.87,"tv":63.24,"id":72857117}]}]}
{"op":"mcm","clk":"11877601425","pt":1724088502732,"mc":[{"id":"1.232011572","rc":[{"batb":[[1,1.99,10],[2,1.77,1.07]],"ltp":2.16,"tv":87.29,"id":72857115},{"batb":[[0,1.89,14],[1,1.86,15.34],[2,1.85,1]],"ltp":1.87,"tv":63.24,"id":72857117}]}]}
{"op":"mcm","clk":"11877602140","pt":1724088508642,"mc":[{"id":"1.232011572","rc":[{"batb":[[0,1.89,10]],"ltp":1.87,"tv":63.24,"id":72857117}]}]}
{"op":"mcm","clk":"11877602242","pt":1724088509532,"mc":[{"id":"1.232011572","rc":[{"batb":[[1,1.77,1.07],[2,1.69,15.12]],"ltp":2.16,"tv":87.29,"id":72857115},{"batb":[[0,1.86,15.34],[1,1.85,1],[2,1.71,9.2]],"ltp":1.87,"tv":63.24,"id":72857117}]}]}
{"op":"mcm","clk":"11877602953","pt":1724088515352,"mc":[{"id":"1.232011572","rc":[{"trd":[[2,8]],"batb":[[0,2,3.86],[2,1.63,143.85]],"ltp":2.0,"tv":95.29,"id":72857115},{"batb":[[0,1.87,14],[1,1.86,15.34],[2,1.85,1]],"ltp":1.87,"tv":63.24,"id":72857117}],"tv":158.54}]}
{"op":"mcm","clk":"11877603174","pt":1724088517443,"mc":[{"id":"1.232011572","rc":[{"batb":[[0,1.87,10]],"ltp":1.87,"tv":63.24,"id":72857117}]}]}
{"op":"mcm","clk":"11877603322","pt":1724088518738,"mc":[{"id":"1.232011572","rc":[{"batb":[[0,2,7.86]],"ltp":2.0,"tv":95.29,"id":72857115},{"batb":[[0,1.86,15.34],[1,1.85,1],[2,1.71,9.2]],"ltp":1.87,"tv":63.24,"id":72857117}]}]}
{"op":"mcm","clk":"11877603385","pt":1724088519358,"mc":[{"id":"1.232011572","rc":[{"batb":[[2,1.65,170.6]],"ltp":2.0,"tv":95.29,"id":72857115}]}]}
{"op":"mcm","clk":"11877603449","pt":1724088519833,"mc":[{"id":"1.232011572","rc":[{"batb":[[0,1.87,4],[1,1.86,15.34],[2,1.85,1]],"ltp":1.87,"tv":63.24,"id":72857117}]}]}
{"op":"mcm","clk":"11877603584","pt":1724088521051,"mc":[{"id":"1.232011572","rc":[{"batb":[[0,1.88,10],[1,1.87,4],[2,1.86,15.34]],"ltp":1.87,"tv":63.24,"id":72857117}]}]}
{"op":"mcm","clk":"11877603734","pt":1724088522142,"mc":[{"id":"1.232011572","rc":[{"batb":[[1,1.86,15.34],[2,1.85,1]],"ltp":1.87,"tv":63.24,"id":72857117}]}]}
{"op":"mcm","clk":"11877604019","pt":1724088524639,"mc":[{"id":"1.232011572","rc":[{"batb":[[0,1.86,15.34],[1,1.85,1],[2,1.71,9.2]],"ltp":1.87,"tv":63.24,"id":72857117}]}]}
{"op":"mcm","clk":"11877604065","pt":1724088525060,"mc":[{"id":"1.232011572","rc":[{"batb":[[0,1.87,4],[1,1.86,15.34],[2,1.85,1]],"ltp":1.87,"tv":63.24,"id":72857117}]}]}
{"op":"mcm","clk":"11877604342","pt":1724088527666,"mc":[{"id":"1.232011572","rc":[{"batb":[[0,1.87,10]],"ltp":1.87,"tv":63.24,"id":72857117}]}]}
{"op":"mcm","clk":"11877604691","pt":1724088530557,"mc":[{"id":"1.232011572","rc":[{"batb":[[0,1.88,4],[1,1.87,10],[2,1.86,15.34]],"ltp":1.87,"tv":63.24,"id":72857117}]}]}
{"op":"mcm","clk":"11877604728","pt":1724088530968,"mc":[{"id":"1.232011572","rc":[{"batb":[[1,1.86,15.34],[2,1.85,1]],"ltp":1.87,"tv":63.24,"id":72857117}]}]}
{"op":"mcm","clk":"11877604975","pt":1724088533281,"mc":[{"id":"1.232011572","rc":[{"batb":[[0,1.87,10]],"ltp":1.87,"tv":63.24,"id":72857117}]}]}
{"op":"mcm","clk":"11877605378","pt":1724088536650,"mc":[{"id":"1.232011572","rc":[{"batb":[[0,1.86,15.34],[1,1.85,1],[2,1.71,9.2]],"ltp":1.87,"tv":63.24,"id":72857117}]}]}
{"op":"mcm","clk":"11877605443","pt":1724088537235,"mc":[{"id":"1.232011572","rc":[{"batb":[[0,1.87,4],[1,1.86,15.34],[2,1.85,1]],"ltp":1.87,"tv":63.24,"id":72857117}]}]}
{"op":"mcm","clk":"11877605704","pt":1724088539753,"mc":[{"id":"1.232011572","rc":[{"batb":[[0,1.86,15.34],[1,1.85,1],[2,1.71,9.2]],"ltp":1.87,"tv":63.24,"id":72857117}]}]}
{"op":"mcm","clk":"11877605719","pt":1724088540478,"mc":[{"id":"1.232011572","rc":[{"batb":[[0,1.87,10],[1,1.86,15.34],[2,1.85,1]],"ltp":1.87,"tv":63.24,"id":72857117}]}]}
{"op":"mcm","clk":"11877606125","pt":1724088543364,"mc":[{"id":"1.232011572","rc":[{"batb":[[0,1.87,4]],"ltp":1.87,"tv":63.24,"id":72857117}]}]}
{"op":"mcm","clk":"11877606370","pt":1724088545671,"mc":[{"id":"1.232011572","rc":[{"batb":[[0,1.86,15.34],[1,1.85,1],[2,1.71,9.2]],"ltp":1.87,"tv":63.24,"id":72857117}]}]}
{"op":"mcm","clk":"11877606382","pt":1724088545771,"mc":[{"id":"1.232011572","rc":[{"batb":[[0,1.87,10],[1,1.86,15.34],[2,1.85,1]],"ltp":1.87,"tv":63.24,"id":72857117}]}]}
{"op":"mcm","clk":"11877606662","pt":1724088548285,"mc":[{"id":"1.232011572","rc":[{"trd":[[1.87,26.78],[1.88,8]],"batb":[[0,1.87,8.75],[1,1.85,1],[2,1.71,9.2]],"ltp":1.87,"tv":73.74,"id":72857117}],"tv":169.04}]}
{"op":"mcm","clk":"11877606759","pt":1724088549277,"mc":[{"id":"1.232011572","rc":[{"batb":[[0,1.85,1],[1,1.71,9.2],[2,1.57,288.23]],"ltp":1.87,"tv":73.74,"id":72857117}]}]}
{"op":"mcm","clk":"11877607132","pt":1724088552887,"mc":[{"id":"1.232011572","rc":[{"batb":[[0,1.86,4],[1,1.85,1],[2,1.71,9.2]],"ltp":1.87,"tv":73.74,"id":72857117}]}]}
{"op":"mcm","clk":"11877607300","pt":1724088554673,"mc":[{"id":"1.232011572","rc":[{"batb":[[0,1.87,10],[1,1.86,4],[2,1.85,1]],"ltp":1.87,"tv":73.74,"id":72857117}]}]}
{"op":"mcm","clk":"11877607421","pt":1724088555970,"mc":[{"id":"1.232011572","rc":[{"batb":[[1,1.85,1],[2,1.71,9.2]],"ltp":1.87,"tv":73.74,"id":72857117}]}]}
{"op":"mcm","clk":"11877607539","pt":1724088557180,"mc":[{"id":"1.232011572","rc":[{"batb":[[0,1.85,1],[1,1.71,9.2],[2,1.59,85.3]],"ltp":1.87,"tv":73.74,"id":72857117}]}]}
{"op":"mcm","clk":"11877608162","pt":1724088562403,"mc":[{"id":"1.232011572","rc":[{"batb":[[0,1.87,10],[1,1.86,4],[2,1.85,1]],"ltp":1.87,"tv":73.74,"id":72857117}]}]}
{"op":"mcm","clk":"11877608265","pt":1724088563300,"mc":[{"id":"1.232011572","rc":[{"batb":[[0,2.08,7.57]],"ltp":2.0,"tv":95.29,"id":72857115}]}]}
{"op":"mcm","clk":"11877608388","pt":1724088564504,"mc":[{"id":"1.232011572","rc":[{"batb":[[1,1.85,1],[2,1.66,9.49]],"ltp":1.87,"tv":73.74,"id":72857117}]}]}
{"op":"mcm","clk":"11877608567","pt":1724088566082,"mc":[{"id":"1.232011572","rc":[{"batb":[[0,1.85,1],[1,1.66,9.49],[2,1.59,85.3]],"ltp":1.87,"tv":73.74,"id":72857117}]}]}
{"op":"mcm","clk":"11877608855","pt":1724088568900,"mc":[{"id":"1.232011572","rc":[{"batb":[[0,1.87,10],[1,1.86,4],[2,1.85,1]],"ltp":1.87,"tv":73.74,"id":72857117}]}]}
{"op":"mcm","clk":"11877609079","pt":1724088571104,"mc":[{"id":"1.232011572","rc":[{"batb":[[1,1.85,1],[2,1.66,9.49]],"ltp":1.87,"tv":73.74,"id":72857117}]}]}
{"op":"mcm","clk":"11877609256","pt":1724088572480,"mc":[{"id":"1.232011572","rc":[{"batb":[[0,1.85,1],[1,1.66,9.49],[2,1.59,85.3]],"ltp":1.87,"tv":73.74,"id":72857117}]}]}
{"op":"mcm","clk":"11877610060","pt":1724088579398,"mc":[{"id":"1.232011572","rc":[{"batb":[[0,2.12,7.41]],"ltp":2.0,"tv":95.29,"id":72857115},{"batb":[[0,1.87,10],[1,1.86,4],[2,1.85,1]],"ltp":1.87,"tv":73.74,"id":72857117}]}]}
{"op":"mcm","clk":"11877610332","pt":1724088581804,"mc":[{"id":"1.232011572","rc":[{"batb":[[1,1.85,1],[2,1.63,9.65]],"ltp":1.87,"tv":73.74,"id":72857117}]}]}
{"op":"mcm","clk":"11877610448","pt":1724088582801,"mc":[{"id":"1.232011572","rc":[{"batb":[[0,1.85,1],[1,1.63,9.65],[2,1.59,85.3]],"ltp":1.87,"tv":73.74,"id":72857117}]}]}
{"op":"mcm","clk":"11877611109","pt":1724088590008,"mc":[{"id":"1.232011572","rc":[{"batb":[[0,2.14,10],[1,2.12,7.41],[2,1.77,1.07]],"batl":[[0,2.44,8.96]],"ltp":2.0,"tv":95.29,"id":72857115},{"batb":[[0,1.87,10],[1,1.86,4],[2,1.85,1]],"ltp":1.87,"tv":73.74,"id":72857117}]}]}
{"op":"mcm","clk":"11877611336","pt":1724088592199,"mc":[{"id":"1.232011572","rc":[{"batb":[[1,1.85,1],[2,1.63,9.65]],"ltp":1.87,"tv":73.74,"id":72857117}]}]}
{"op":"mcm","clk":"11877611474","pt":1724088593510,"mc":[{"id":"1.232011572","rc":[{"batb":[[0,2.12,7.41],[1,1.77,1.07],[2,1.65,170.6]],"ltp":2.0,"tv":95.29,"id":72857115},{"batb":[[0,1.85,1],[1,1.63,9.65],[2,1.59,85.3]],"ltp":1.87,"tv":73.74,"id":72857117}]}]}
{"op":"mcm","clk":"11877613183","pt":1724088607729,"mc":[{"id":"1.232011572","rc":[{"batb":[[0,2.14,10],[1,2.12,7.41],[2,1.77,1.07]],"ltp":2.0,"tv":95.29,"id":72857115},{"batb":[[0,1.86,4],[1,1.85,1],[2,1.63,9.65]],"ltp":1.87,"tv":73.74,"id":72857117}]}]}
{"op":"mcm","clk":"11877613209","pt":1724088607937,"mc":[{"id":"1.232011572","rc":[{"batb":[[0,1.87,10],[1,1.86,4],[2,1.85,1]],"ltp":1.87,"tv":73.74,"id":72857117}]}]}
{"op":"mcm","clk":"11877613493","pt":1724088610009,"mc":[{"id":"1.232011572","rc":[{"batb":[[1,1.85,1],[2,1.63,9.65]],"ltp":1.87,"tv":73.74,"id":72857117}]}]}
{"op":"mcm","clk":"11877613638","pt":1724088611425,"mc":[{"id":"1.232011572","rc":[{"batb":[[0,2.12,7.41],[1,1.77,1.07],[2,1.65,170.78]],"ltp":2.0,"tv":95.29,"id":72857115},{"batb":[[0,1.85,1],[1,1.63,9.65],[2,1.59,85.3]],"ltp":1.87,"tv":73.74,"id":72857117}]}]}
{"op":"mcm","clk":"11877614571","pt":1724088620312,"mc":[{"id":"1.232011572","rc":[{"batb":[[0,2.14,10],[1,2.12,7.41],[2,1.77,1.07]],"ltp":2.0,"tv":95.29,"id":72857115},{"batb":[[0,1.86,4],[1,1.85,1],[2,1.63,9.65]],"ltp":1.87,"tv":73.74,"id":72857117}]}]}
{"op":"mcm","clk":"11877614653","pt":1724088621147,"mc":[{"id":"1.232011572","rc":[{"batb":[[0,1.87,10],[1,1.86,4],[2,1.85,1]],"ltp":1.87,"tv":73.74,"id":72857117}]}]}
{"op":"mcm","clk":"11877614846","pt":1724088623145,"mc":[{"id":"1.232011572","rc":[{"batb":[[1,1.85,1],[2,1.63,9.65]],"ltp":1.87,"tv":73.74,"id":72857117}]}]}
{"op":"mcm","clk":"11877614974","pt":1724088624457,"mc":[{"id":"1.232011572","rc":[{"batb":[[0,2.12,7.41],[1,1.77,1.07],[2,1.65,170.78]],"ltp":2.0,"tv":95.29,"id":72857115},{"batb":[[0,1.85,1],[1,1.63,9.65],[2,1.59,85.3]],"ltp":1.87,"tv":73.74,"id":72857117}]}]}
{"op":"mcm","clk":"11877615712","pt":1724088631627,"mc":[{"id":"1.232011572","rc":[{"trd":[[2.12,0.87]],"batb":[[0,2.12,6.54]],"ltp":2.12,"tv":96.16,"id":72857115},{"trd":[[1.9,1.06]],"batb":[[0,1.63,9.65],[1,1.59,85.3],[2,1.57,288.23]],"ltp":1.9,"tv":74.71,"id":72857117}],"tv":170.88}]}
{"op":"mcm","clk":"11877615736","pt":1724088631836,"mc":[{"id":"1.232011572","rc":[{"batb":[[0,2.14,10],[1,2.12,6.54],[2,1.77,1.07]],"ltp":2.12,"tv":96.16,"id":72857115},{"batb":[[0,1.64,14],[1,1.63,9.65],[2,1.59,85.3]],"ltp":1.9,"tv":74.71,"id":72857117}]}]}
{"op":"mcm","clk":"11877615983","pt":1724088634160,"mc":[{"id":"1.232011572","rc":[{"batb":[[0,1.64,10]],"ltp":1.9,"tv":74.71,"id":72857117}]}]}
{"op":"mcm","clk":"11877616084","pt":1724088635059,"mc":[{"id":"1.232011572","rc":[{"batb":[[0,2.12,7.41],[1,1.77,1.07],[2,1.65,170.78]],"ltp":2.12,"tv":96.16,"id":72857115},{"batb":[[0,1.63,9.65],[1,1.59,85.3],[2,1.57,288.23]],"ltp":1.9,"tv":74.71,"id":72857117}]}]}
{"op":"mcm","clk":"11877617263","pt":1724088646559,"mc":[{"id":"1.232011572","rc":[{"batb":[[0,2.14,10],[1,2.12,7.41],[2,1.77,1.07]],"ltp":2.12,"tv":96.16,"id":72857115},{"batb":[[0,1.64,14],[1,1.63,9.65],[2,1.59,85.3]],"ltp":1.9,"tv":74.71,"id":72857117}]}]}
{"op":"mcm","clk":"11877617584","pt":1724088649767,"mc":[{"id":"1.232011572","rc":[{"batb":[[0,2.12,7.41],[1,1.77,1.07],[2,1.65,170.78]],"ltp":2.12,"tv":96.16,"id":72857115},{"batb":[[0,1.63,9.65],[1,1.59,85.3],[2,1.57,288.23]],"ltp":1.9,"tv":74.71,"id":72857117}]}]}
{"op":"mcm","clk":"11877618193","pt":1724088655673,"mc":[{"id":"1.232011572","rc":[{"batb":[[0,2.14,10],[1,2.12,7.41],[2,1.77,1.07]],"ltp":2.12,"tv":96.16,"id":72857115},{"batb":[[0,1.64,14],[1,1.63,9.65],[2,1.59,85.3]],"ltp":1.9,"tv":74.71,"id":72857117}]}]}
{"op":"mcm","clk":"11877618508","pt":1724088658465,"mc":[{"id":"1.232011572","rc":[{"batb":[[0,1.64,10]],"ltp":1.9,"tv":74.71,"id":72857117}]}]}
{"op":"mcm","clk":"11877618599","pt":1724088659374,"mc":[{"id":"1.232011572","rc":[{"batb":[[0,2.12,7.41],[1,1.77,1.07],[2,1.65,170.78]],"ltp":2.12,"tv":96.16,"id":72857115},{"batb":[[0,1.63,9.65],[1,1.59,85.3],[2,1.57,288.23]],"ltp":1.9,"tv":74.71,"id":72857117}]}]}
{"op":"mcm","clk":"11877619319","pt":1724088665575,"mc":[{"id":"1.232011572","rc":[{"batb":[[0,2.14,10],[1,2.12,7.41],[2,1.77,1.07]],"ltp":2.12,"tv":96.16,"id":72857115},{"batb":[[0,1.64,14],[1,1.63,9.65],[2,1.59,85.3]],"ltp":1.9,"tv":74.71,"id":72857117}]}]}
{"op":"mcm","clk":"11877619593","pt":1724088668234,"mc":[{"id":"1.232011572","rc":[{"batb":[[0,1.64,10]],"ltp":1.9,"tv":74.71,"id":72857117}]}]}
{"op":"mcm","clk":"11877619718","pt":1724088669211,"mc":[{"id":"1.232011572","rc":[{"batb":[[0,2.12,7.41],[1,1.77,1.07],[2,1.65,170.78]],"ltp":2.12,"tv":96.16,"id":72857115},{"batb":[[0,1.63,9.65],[1,1.59,85.3],[2,1.57,288.23]],"ltp":1.9,"tv":74.71,"id":72857117}]}]}
{"op":"mcm","clk":"11877623745","pt":1724088707346,"mc":[{"id":"1.232011572","rc":[{"batb":[[0,2.14,10],[1,2.12,7.41],[2,1.77,1.07]],"ltp":2.12,"tv":96.16,"id":72857115},{"batb":[[0,1.64,14],[1,1.63,9.65],[2,1.59,85.3]],"ltp":1.9,"tv":74.71,"id":72857117}]}]}
{"op":"mcm","clk":"11877624047","pt":1724088710020,"mc":[{"id":"1.232011572","rc":[{"batb":[[0,1.64,10]],"ltp":1.9,"tv":74.71,"id":72857117}]}]}
{"op":"mcm","clk":"11877624136","pt":1724088710949,"mc":[{"id":"1.232011572","rc":[{"batb":[[0,2.12,7.41],[1,1.77,1.07],[2,1.65,170.78]],"ltp":2.12,"tv":96.16,"id":72857115},{"batb":[[0,1.63,9.65],[1,1.59,85.3],[2,1.57,288.23]],"ltp":1.9,"tv":74.71,"id":72857117}]}]}
{"op":"mcm","clk":"11877625159","pt":1724088720958,"mc":[{"id":"1.232011572","rc":[{"batb":[[0,2.14,10],[1,2.12,7.41],[2,1.77,1.07]],"ltp":2.12,"tv":96.16,"id":72857115},{"batb":[[0,1.64,14],[1,1.63,9.65],[2,1.59,85.3]],"ltp":1.9,"tv":74.71,"id":72857117}]}]}
{"op":"mcm","clk":"11877625440","pt":1724088723471,"mc":[{"id":"1.232011572","rc":[{"batb":[[0,1.64,10]],"ltp":1.9,"tv":74.71,"id":72857117}]}]}
{"op":"mcm","clk":"11877625605","pt":1724088724750,"mc":[{"id":"1.232011572","rc":[{"batb":[[0,2.12,7.41],[1,1.77,1.07],[2,1.65,170.78]],"ltp":2.12,"tv":96.16,"id":72857115},{"batb":[[0,1.63,9.65],[1,1.59,85.3],[2,1.57,288.23]],"ltp":1.9,"tv":74.71,"id":72857117}]}]}
{"op":"mcm","clk":"11877626082","pt":1724088729245,"mc":[{"id":"1.232011572","rc":[{"batb":[[0,2.14,10],[1,2.12,7.41],[2,1.77,1.07]],"ltp":2.12,"tv":96.16,"id":72857115},{"batb":[[0,1.64,14],[1,1.63,9.65],[2,1.59,85.3]],"ltp":1.9,"tv":74.71,"id":72857117}]}]}
{"op":"mcm","clk":"11877626371","pt":1724088731958,"mc":[{"id":"1.232011572","rc":[{"batb":[[0,1.64,10]],"ltp":1.9,"tv":74.71,"id":72857117}]}]}
{"op":"mcm","clk":"11877626476","pt":1724088732956,"mc":[{"id":"1.232011572","rc":[{"batb":[[0,2.12,7.41],[1,1.77,1.07],[2,1.65,170.78]],"ltp":2.12,"tv":96.16,"id":72857115},{"batb":[[0,1.63,9.65],[1,1.59,85.3],[2,1.57,288.23]],"ltp":1.9,"tv":74.71,"id":72857117}]}]}
{"op":"mcm","clk":"11877626644","pt":1724088734457,"mc":[{"id":"1.232011572","rc":[{"batb":[[0,1.64,4],[1,1.63,9.65],[2,1.59,85.3]],"ltp":1.9,"tv":74.71,"id":72857117}]}]}
{"op":"mcm","clk":"11877626911","pt":1724088736763,"mc":[{"id":"1.232011572","rc":[{"batb":[[0,1.63,9.65],[1,1.59,85.3],[2,1.57,288.23]],"ltp":1.9,"tv":74.71,"id":72857117}]}]}
{"op":"mcm","clk":"11877626925","pt":1724088736867,"mc":[{"id":"1.232011572","rc":[{"batb":[[0,2.14,10],[1,2.12,7.41],[2,1.77,1.07]],"ltp":2.12,"tv":96.16,"id":72857115},{"batb":[[0,1.64,10],[1,1.63,9.65],[2,1.59,85.3]],"ltp":1.9,"tv":74.71,"id":72857117}]}]}
{"op":"mcm","clk":"11877627336","pt":1724088740472,"mc":[{"id":"1.232011572","rc":[{"batb":[[0,2.12,7.41],[1,1.77,1.07],[2,1.65,170.78]],"ltp":2.12,"tv":96.16,"id":72857115},{"batb":[[0,1.64,4]],"ltp":1.9,"tv":74.71,"id":72857117}]}]}
{"op":"mcm","clk":"11877627573","pt":1724088742763,"mc":[{"id":"1.232011572","rc":[{"batb":[[0,1.63,9.65],[1,1.59,85.3],[2,1.57,288.23]],"ltp":1.9,"tv":74.71,"id":72857117}]}]}
{"op":"mcm","clk":"11877627579","pt":1724088742860,"mc":[{"id":"1.232011572","rc":[{"batb":[[0,2.14,10],[1,2.12,7.41],[2,1.77,1.07]],"ltp":2.12,"tv":96.16,"id":72857115},{"batb":[[0,1.64,10],[1,1.63,9.65],[2,1.59,85.3]],"ltp":1.9,"tv":74.71,"id":72857117}]}]}
{"op":"mcm","clk":"11877628003","pt":1724088746501,"mc":[{"id":"1.232011572","rc":[{"batb":[[0,2.12,7.41],[1,1.77,1.07],[2,1.65,170.78]],"ltp":2.12,"tv":96.16,"id":72857115},{"batb":[[0,1.64,4]],"ltp":1.9,"tv":74.71,"id":72857117}]}]}
{"op":"mcm","clk":"11877628275","pt":1724088749188,"mc":[{"id":"1.232011572","rc":[{"batb":[[0,2.14,10],[1,2.12,7.41],[2,1.77,1.07]],"ltp":2.12,"tv":96.16,"id":72857115},{"batb":[[0,1.64,10]],"ltp":1.9,"tv":74.71,"id":72857117}]}]}
{"op":"mcm","clk":"11877628618","pt":1724088752468,"mc":[{"id":"1.232011572","rc":[{"batb":[[0,2.12,7.41],[1,1.77,1.07],[2,1.65,170.78]],"ltp":2.12,"tv":96.16,"id":72857115},{"batb":[[0,1.63,9.65],[1,1.59,85.3],[2,1.57,288.23]],"ltp":1.9,"tv":74.71,"id":72857117}]}]}
{"op":"mcm","clk":"11877628644","pt":1724088752780,"mc":[{"id":"1.232011572","rc":[{"batb":[[0,1.64,4],[1,1.63,9.65],[2,1.59,85.3]],"ltp":1.9,"tv":74.71,"id":72857117}]}]}
{"op":"mcm","clk":"11877628904","pt":1724088755280,"mc":[{"id":"1.232011572","rc":[{"batb":[[0,2.14,10],[1,2.12,7.41],[2,1.77,1.07]],"ltp":2.12,"tv":96.16,"id":72857115},{"batb":[[0,1.64,10]],"ltp":1.9,"tv":74.71,"id":72857117}]}]}
{"op":"mcm","clk":"11877629255","pt":1724088758575,"mc":[{"id":"1.232011572","rc":[{"batb":[[0,2.12,7.41],[1,1.77,1.07],[2,1.65,170.78]],"ltp":2.12,"tv":96.16,"id":72857115},{"batb":[[0,1.63,9.65],[1,1.59,85.3],[2,1.57,288.23]],"ltp":1.9,"tv":74.71,"id":72857117}]}]}
{"op":"mcm","clk":"11877629281","pt":1724088758840,"mc":[{"id":"1.232011572","rc":[{"batb":[[0,1.64,4],[1,1.63,9.65],[2,1.59,85.3]],"ltp":1.9,"tv":74.71,"id":72857117}]}]}
{"op":"mcm","clk":"11877629546","pt":1724088761340,"mc":[{"id":"1.232011572","rc":[{"batb":[[0,2.14,10],[1,2.12,7.41],[2,1.77,1.07]],"ltp":2.12,"tv":96.16,"id":72857115},{"batb":[[0,1.64,10]],"ltp":1.9,"tv":74.71,"id":72857117}]}]}
{"op":"mcm","clk":"11877629910","pt":1724088764753,"mc":[{"id":"1.232011572","rc":[{"batb":[[0,2.12,7.41],[1,1.77,1.07],[2,1.65,170.78]],"ltp":2.12,"tv":96.16,"id":72857115},{"batb":[[0,1.64,4]],"ltp":1.9,"tv":74.71,"id":72857117}]}]}
{"op":"mcm","clk":"11877630198","pt":1724088766987,"mc":[{"id":"1.232011572","rc":[{"batb":[[0,2.14,10],[1,2.12,7.41],[2,1.77,1.07]],"ltp":2.12,"tv":96.16,"id":72857115},{"batb":[[0,1.64,10]],"ltp":1.9,"tv":74.71,"id":72857117}]}]}
{"op":"mcm","clk":"11877630594","pt":1724088770669,"mc":[{"id":"1.232011572","rc":[{"batb":[[0,2.12,7.41],[1,1.77,1.07],[2,1.65,170.78]],"ltp":2.12,"tv":96.16,"id":72857115},{"batb":[[0,1.64,4]],"ltp":1.9,"tv":74.71,"id":72857117}]}]}
{"op":"mcm","clk":"11877630859","pt":1724088773176,"mc":[{"id":"1.232011572","rc":[{"batb":[[0,2.14,10],[1,2.12,7.41],[2,1.77,1.07]],"ltp":2.12,"tv":96.16,"id":72857115},{"batb":[[0,1.64,10]],"ltp":1.9,"tv":74.71,"id":72857117}]}]}
{"op":"mcm","clk":"11877631228","pt":1724088776575,"mc":[{"id":"1.232011572","rc":[{"batb":[[0,2.12,7.41],[1,1.77,1.07],[2,1.65,170.78]],"ltp":2.12,"tv":96.16,"id":72857115},{"batb":[[0,1.63,9.65],[1,1.59,85.3],[2,1.57,288.23]],"ltp":1.9,"tv":74.71,"id":72857117}]}]}
{"op":"mcm","clk":"11877631252","pt":1724088776773,"mc":[{"id":"1.232011572","rc":[{"batb":[[0,1.64,4],[1,1.63,9.65],[2,1.59,85.3]],"ltp":1.9,"tv":74.71,"id":72857117}]}]}
{"op":"mcm","clk":"11877631537","pt":1724088779153,"mc":[{"id":"1.232011572","rc":[{"batb":[[0,2.14,10],[1,2.12,7.41],[2,1.77,1.07]],"ltp":2.12,"tv":96.16,"id":72857115},{"batb":[[0,1.64,10]],"ltp":1.9,"tv":74.71,"id":72857117}]}]}
{"op":"mcm","clk":"11877631954","pt":1724088782760,"mc":[{"id":"1.232011572","rc":[{"batb":[[0,2.12,7.41],[1,1.77,1.07],[2,1.65,170.78]],"ltp":2.12,"tv":96.16,"id":72857115},{"batb":[[0,1.64,4]],"ltp":1.9,"tv":74.71,"id":72857117}]}]}
{"op":"mcm","clk":"11877632274","pt":1724088785379,"mc":[{"id":"1.232011572","rc":[{"batb":[[0,2.14,10],[1,2.12,7.41],[2,1.77,1.07]],"ltp":2.12,"tv":96.16,"id":72857115},{"batb":[[0,1.64,10]],"ltp":1.9,"tv":74.71,"id":72857117}]}]}
{"op":"mcm","clk":"11877632634","pt":1724088788611,"mc":[{"id":"1.232011572","rc":[{"batb":[[0,2.12,7.41],[1,1.77,1.07],[2,1.65,170.78]],"ltp":2.12,"tv":96.16,"id":72857115},{"batb":[[0,1.63,9.65],[1,1.59,85.3],[2,1.57,288.23]],"ltp":1.9,"tv":74.71,"id":72857117}]}]}
{"op":"mcm","clk":"11877632696","pt":1724088789084,"mc":[{"id":"1.232011572","rc":[{"batb":[[0,1.64,4],[1,1.63,9.65],[2,1.59,85.3]],"ltp":1.9,"tv":74.71,"id":72857117}]}]}
{"op":"mcm","clk":"11877632997","pt":1724088791594,"mc":[{"id":"1.232011572","rc":[{"batb":[[0,2.14,10],[1,2.12,7.41],[2,1.77,1.07]],"ltp":2.12,"tv":96.16,"id":72857115},{"batb":[[0,1.64,10]],"ltp":1.9,"tv":74.71,"id":72857117}]}]}
{"op":"mcm","clk":"11877633353","pt":1724088795090,"mc":[{"id":"1.232011572","rc":[{"batb":[[0,2.12,7.41],[1,1.77,1.07],[2,1.65,170.78]],"ltp":2.12,"tv":96.16,"id":72857115},{"batb":[[0,1.64,4]],"ltp":1.9,"tv":74.71,"id":72857117}]}]}
{"op":"mcm","clk":"11877633646","pt":1724088797683,"mc":[{"id":"1.232011572","rc":[{"batb":[[0,2.14,10],[1,2.12,7.41],[2,1.77,1.07]],"ltp":2.12,"tv":96.16,"id":72857115},{"batb":[[0,1.64,10]],"ltp":1.9,"tv":74.71,"id":72857117}]}]}
{"op":"mcm","clk":"11877634048","pt":1724088801194,"mc":[{"id":"1.232011572","rc":[{"batb":[[0,2.12,7.41],[1,1.77,1.07],[2,1.65,170.78]],"ltp":2.12,"tv":96.16,"id":72857115},{"batb":[[0,1.64,4]],"ltp":1.9,"tv":74.71,"id":72857117}]}]}
{"op":"mcm","clk":"11877634312","pt":1724088803718,"mc":[{"id":"1.232011572","rc":[{"batb":[[0,2.14,10],[1,2.12,7.41],[2,1.77,1.07]],"ltp":2.12,"tv":96.16,"id":72857115},{"batb":[[0,1.64,10]],"ltp":1.9,"tv":74.71,"id":72857117}]}]}
{"op":"mcm","clk":"11877634715","pt":1724088807228,"mc":[{"id":"1.232011572","rc":[{"batb":[[0,2.12,7.41],[1,1.77,1.07],[2,1.65,170.78]],"ltp":2.12,"tv":96.16,"id":72857115},{"batb":[[0,1.64,4]],"ltp":1.9,"tv":74.71,"id":72857117}]}]}
{"op":"mcm","clk":"11877634933","pt":1724088809621,"mc":[{"id":"1.232011572","rc":[{"batb":[[0,1.63,9.65],[1,1.59,85.3],[2,1.57,288.23]],"ltp":1.9,"tv":74.71,"id":72857117}]}]}
{"op":"mcm","clk":"11877634952","pt":1724088809780,"mc":[{"id":"1.232011572","rc":[{"batb":[[0,2.14,10],[1,2.12,7.41],[2,1.77,1.07]],"ltp":2.12,"tv":96.16,"id":72857115},{"batb":[[0,1.64,10],[1,1.63,9.65],[2,1.59,85.3]],"ltp":1.9,"tv":74.71,"id":72857117}]}]}
{"op":"mcm","clk":"11877635326","pt":1724088813243,"mc":[{"id":"1.232011572","rc":[{"batb":[[0,2.12,7.41],[1,1.77,1.07],[2,1.65,170.78]],"ltp":2.12,"tv":96.16,"id":72857115},{"batb":[[0,1.64,4]],"ltp":1.9,"tv":74.71,"id":72857117}]}]}
{"op":"mcm","clk":"11877635588","pt":1724088815626,"mc":[{"id":"1.232011572","rc":[{"batb":[[0,2.14,10],[1,2.12,7.41],[2,1.77,1.07]],"ltp":2.12,"tv":96.16,"id":72857115},{"batb":[[0,1.64,10]],"ltp":1.9,"tv":74.71,"id":72857117}]}]}
{"op":"mcm","clk":"11877636030","pt":1724088819237,"mc":[{"id":"1.232011572","rc":[{"batb":[[0,2.12,7.41],[1,1.77,1.07],[2,1.65,170.78]],"ltp":2.12,"tv":96.16,"id":72857115},{"batb":[[0,1.64,4]],"ltp":1.9,"tv":74.71,"id":72857117}]}]}
{"op":"mcm","clk":"11877636299","pt":1724088821722,"mc":[{"id":"1.232011572","rc":[{"batb":[[0,2.14,10],[1,2.12,7.41],[2,1.77,1.07]],"ltp":2.12,"tv":96.16,"id":72857115},{"batb":[[0,1.64,10]],"ltp":1.9,"tv":74.71,"id":72857117}]}]}
{"op":"mcm","clk":"11877636707","pt":1724088825321,"mc":[{"id":"1.232011572","rc":[{"batb":[[0,2.12,7.41],[1,1.77,1.07],[2,1.65,170.78]],"ltp":2.12,"tv":96.16,"id":72857115},{"batb":[[0,1.64,4]],"ltp":1.9,"tv":74.71,"id":72857117}]}]}
{"op":"mcm","clk":"11877636959","pt":1724088827621,"mc":[{"id":"1.232011572","rc":[{"batb":[[0,1.63,9.65],[1,1.59,85.3],[2,1.57,288.23]],"ltp":1.9,"tv":74.71,"id":72857117}]}]}
{"op":"mcm","clk":"11877636984","pt":1724088827829,"mc":[{"id":"1.232011572","rc":[{"batb":[[0,2.14,10],[1,2.12,7.41],[2,1.77,1.07]],"ltp":2.12,"tv":96.16,"id":72857115},{"batb":[[0,1.64,10],[1,1.63,9.65],[2,1.59,85.3]],"ltp":1.9,"tv":74.71,"id":72857117}]}]}
{"op":"mcm","clk":"11877637413","pt":1724088831439,"mc":[{"id":"1.232011572","rc":[{"batb":[[0,2.12,7.41],[1,1.77,1.07],[2,1.65,170.78]],"ltp":2.12,"tv":96.16,"id":72857115},{"batb":[[0,1.64,4]],"ltp":1.9,"tv":74.71,"id":72857117}]}]}
{"op":"mcm","clk":"11877637672","pt":1724088833742,"mc":[{"id":"1.232011572","rc":[{"batb":[[0,1.63,9.65],[1,1.59,85.3],[2,1.57,288.23]],"ltp":1.9,"tv":74.71,"id":72857117}]}]}
{"op":"mcm","clk":"11877637685","pt":1724088833849,"mc":[{"id":"1.232011572","rc":[{"batb":[[0,2.14,10],[1,2.12,7.41],[2,1.77,1.07]],"ltp":2.12,"tv":96.16,"id":72857115},{"batb":[[0,1.64,10],[1,1.63,9.65],[2,1.59,85.3]],"ltp":1.9,"tv":74.71,"id":72857117}]}]}
{"op":"mcm","clk":"11877638070","pt":1724088837358,"mc":[{"id":"1.232011572","rc":[{"batb":[[0,2.12,7.41],[1,1.77,1.07],[2,1.65,170.78]],"ltp":2.12,"tv":96.16,"id":72857115},{"batb":[[0,1.64,4]],"ltp":1.9,"tv":74.71,"id":72857117}]}]}
{"op":"mcm","clk":"11877638325","pt":1724088839548,"mc":[{"id":"1.232011572","rc":[{"batb":[[0,1.63,9.65],[1,1.59,85.3],[2,1.57,288.23]],"ltp":1.9,"tv":74.71,"id":72857117}]}]}
{"op":"mcm","clk":"11877638350","pt":1724088839781,"mc":[{"id":"1.232011572","rc":[{"batb":[[0,2.14,10],[1,2.12,7.41],[2,1.77,1.07]],"ltp":2.12,"tv":96.16,"id":72857115},{"batb":[[0,1.64,10],[1,1.63,9.65],[2,1.59,85.3]],"ltp":1.9,"tv":74.71,"id":72857117}]}]}
{"op":"mcm","clk":"11877638777","pt":1724088843369,"mc":[{"id":"1.232011572","rc":[{"batb":[[0,2.12,7.41],[1,1.77,1.07],[2,1.65,170.78]],"ltp":2.12,"tv":96.16,"id":72857115},{"batb":[[0,1.64,4]],"ltp":1.9,"tv":74.71,"id":72857117}]}]}
{"op":"mcm","clk":"11877639069","pt":1724088845672,"mc":[{"id":"1.232011572","rc":[{"batb":[[0,1.63,9.65],[1,1.59,85.3],[2,1.57,288.23]],"ltp":1.9,"tv":74.71,"id":72857117}]}]}
{"op":"mcm","clk":"11877639080","pt":1724088845777,"mc":[{"id":"1.232011572","rc":[{"batb":[[0,2.14,10],[1,2.12,7.41],[2,1.77,1.07]],"ltp":2.12,"tv":96.16,"id":72857115},{"batb":[[0,1.64,10],[1,1.63,9.65],[2,1.59,85.3]],"ltp":1.9,"tv":74.71,"id":72857117}]}]}
{"op":"mcm","clk":"11877639461","pt":1724088849370,"mc":[{"id":"1.232011572","rc":[{"batb":[[0,2.12,7.41],[1,1.77,1.07],[2,1.65,170.78]],"ltp":2.12,"tv":96.16,"id":72857115},{"batb":[[0,1.64,4]],"ltp":1.9,"tv":74.71,"id":72857117}]}]}
{"op":"mcm","clk":"11877639685","pt":1724088851666,"mc":[{"id":"1.232011572","rc":[{"batb":[[0,1.63,9.65],[1,1.59,85.3],[2,1.57,288.23]],"ltp":1.9,"tv":74.71,"id":72857117}]}]}
{"op":"mcm","clk":"11877639693","pt":1724088851770,"mc":[{"id":"1.232011572","rc":[{"batb":[[0,2.14,10],[1,2.12,7.41],[2,1.77,1.07]],"ltp":2.12,"tv":96.16,"id":72857115},{"batb":[[0,1.64,10],[1,1.63,9.65],[2,1.59,85.3]],"ltp":1.9,"tv":74.71,"id":72857117}]}]}
{"op":"mcm","clk":"11877640044","pt":1724088855084,"mc":[{"id":"1.232011572","rc":[{"batb":[[0,2.12,7.41],[1,1.77,1.07],[2,1.65,170.78]],"ltp":2.12,"tv":96.16,"id":72857115},{"batb":[[0,1.65,4]],"ltp":1.9,"tv":74.71,"id":72857117}]}]}
{"op":"mcm","clk":"11877640317","pt":1724088857483,"mc":[{"id":"1.232011572","rc":[{"batb":[[0,2.14,10],[1,2.12,7.41],[2,1.77,1.07]],"ltp":2.12,"tv":96.16,"id":72857115},{"batb":[[0,1.64,10]],"ltp":1.9,"tv":74.71,"id":72857117}]}]}
{"op":"mcm","clk":"11877640671","pt":1724088861085,"mc":[{"id":"1.232011572","rc":[{"batb":[[0,2.12,7.41],[1,1.77,1.07],[2,1.65,170.78]],"ltp":2.12,"tv":96.16,"id":72857115},{"batb":[[0,1.64,4]],"ltp":1.9,"tv":74.71,"id":72857117}]}]}
{"op":"mcm","clk":"11877640930","pt":1724088863491,"mc":[{"id":"1.232011572","rc":[{"batb":[[0,1.63,9.65],[1,1.59,85.3],[2,1.57,288.23]],"ltp":1.9,"tv":74.71,"id":72857117}]}]}
{"op":"mcm","clk":"11877640985","pt":1724088864058,"mc":[{"id":"1.232011572","rc":[{"batb":[[0,2.14,10],[1,2.12,7.41],[2,1.77,1.07]],"ltp":2.12,"tv":96.16,"id":72857115},{"batb":[[0,1.65,10],[1,1.63,9.65],[2,1.59,85.3]],"ltp":1.9,"tv":74.71,"id":72857117}]}]}
{"op":"mcm","clk":"11877641231","pt":1724088866203,"mc":[{"id":"1.232011572","rc":[{"batb":[[0,1.66,4],[1,1.65,10],[2,1.63,9.65]],"ltp":1.9,"tv":74.71,"id":72857117}]}]}
{"op":"mcm","clk":"11877641509","pt":1724088868562,"mc":[{"id":"1.232011572","rc":[{"batb":[[0,2.12,7.41],[1,1.77,1.07],[2,1.65,170.78]],"ltp":2.12,"tv":96.16,"id":72857115},{"batb":[[0,1.63,9.65],[1,1.59,85.3],[2,1.57,288.23]],"ltp":1.9,"tv":74.71,"id":72857117}]}]}
{"op":"mcm","clk":"11877643297","pt":1724088886012,"mc":[{"id":"1.232011572","rc":[{"batb":[[0,1.64,14],[1,1.63,9.65],[2,1.59,85.3]],"ltp":1.9,"tv":74.71,"id":72857117}]}]}
{"op":"mcm","clk":"11877643540","pt":1724088888312,"mc":[{"id":"1.232011572","rc":[{"batb":[[0,1.64,10]],"ltp":1.9,"tv":74.71,"id":72857117}]}]}
{"op":"mcm","clk":"11877643642","pt":1724088889302,"mc":[{"id":"1.232011572","rc":[{"batb":[[0,1.63,9.65],[1,1.59,85.3],[2,1.57,288.23]],"ltp":1.9,"tv":74.71,"id":72857117}]}]}
{"op":"mcm","clk":"11877644838","pt":1724088901229,"mc":[{"id":"1.232011572","rc":[{"batb":[[0,2.16,7.28]],"ltp":2.12,"tv":96.16,"id":72857115},{"batb":[[0,1.64,14],[1,1.61,9.78],[2,1.59,85.3]],"ltp":1.9,"tv":74.71,"id":72857117}]}]}
{"op":"mcm","clk":"11877645128","pt":1724088903522,"mc":[{"id":"1.232011572","rc":[{"batb":[[0,1.64,10]],"ltp":1.9,"tv":74.71,"id":72857117}]}]}
{"op":"mcm","clk":"11877645244","pt":1724088904547,"mc":[{"id":"1.232011572","rc":[{"batb":[[0,1.61,9.78],[1,1.59,85.3],[2,1.57,288.23]],"ltp":1.9,"tv":74.71,"id":72857117}]}]}
{"op":"mcm","clk":"11877648136","pt":1724088931769,"mc":[{"id":"1.232011572","rc":[{"batb":[[0,1.62,14],[1,1.61,9.78],[2,1.59,85.3]],"ltp":1.9,"tv":74.71,"id":72857117}]}]}
{"op":"mcm","clk":"11877648407","pt":1724088934480,"mc":[{"id":"1.232011572","rc":[{"batb":[[0,1.62,10]],"ltp":1.9,"tv":74.71,"id":72857117}]}]}
{"op":"mcm","clk":"11877648510","pt":1724088935268,"mc":[{"id":"1.232011572","rc":[{"batb":[[0,1.61,9.78],[1,1.59,85.3],[2,1.57,288.23]],"ltp":1.9,"tv":74.71,"id":72857117}]}]}
{"op":"mcm","clk":"11877648994","pt":1724088939778,"mc":[{"id":"1.232011572","rc":[{"batb":[[0,1.62,14],[1,1.61,9.78],[2,1.59,85.3]],"ltp":1.9,"tv":74.71,"id":72857117}]}]}
{"op":"mcm","clk":"11877649238","pt":1724088942070,"mc":[{"id":"1.232011572","rc":[{"batb":[[0,1.62,10]],"ltp":1.9,"tv":74.71,"id":72857117}]}]}
{"op":"mcm","clk":"11877649382","pt":1724088943294,"mc":[{"id":"1.232011572","rc":[{"batb":[[0,1.61,9.78],[1,1.59,85.3],[2,1.57,288.23]],"ltp":1.9,"tv":74.71,"id":72857117}]}]}
{"op":"mcm","clk":"11877649536","pt":1724088944767,"mc":[{"id":"1.232011572","rc":[{"batb":[[0,1.62,4],[1,1.61,9.78],[2,1.59,85.3]],"ltp":1.9,"tv":74.71,"id":72857117}]}]}
{"op":"mcm","clk":"11877649655","pt":1724088945972,"mc":[{"id":"1.232011572","rc":[{"batb":[[0,1.63,10],[1,1.62,4],[2,1.61,9.78]],"ltp":1.9,"tv":74.71,"id":72857117}]}]}
{"op":"mcm","clk":"11877649764","pt":1724088947069,"mc":[{"id":"1.232011572","rc":[{"batb":[[1,1.61,9.78],[2,1.59,85.3]],"ltp":1.9,"tv":74.71,"id":72857117}]}]}
{"op":"mcm","clk":"11877650026","pt":1724088949376,"mc":[{"id":"1.232011572","rc":[{"batb":[[0,1.61,9.78],[1,1.59,85.3],[2,1.57,288.23]],"ltp":1.9,"tv":74.71,"id":72857117}]}]}
{"op":"mcm","clk":"11877650084","pt":1724088949782,"mc":[{"id":"1.232011572","rc":[{"batb":[[0,1.62,4],[1,1.61,9.78],[2,1.59,85.3]],"ltp":1.9,"tv":74.71,"id":72857117}]}]}
{"op":"mcm","clk":"11877650385","pt":1724088952300,"mc":[{"id":"1.232011572","rc":[{"batb":[[0,1.62,10]],"ltp":1.9,"tv":74.71,"id":72857117}]}]}
{"op":"mcm","clk":"11877650755","pt":1724088955902,"mc":[{"id":"1.232011572","rc":[{"batb":[[0,1.62,4]],"ltp":1.9,"tv":74.71,"id":72857117}]}]}
{"op":"mcm","clk":"11877651011","pt":1724088958197,"mc":[{"id":"1.232011572","rc":[{"batb":[[0,1.62,10]],"ltp":1.9,"tv":74.71,"id":72857117}]}]}
{"op":"mcm","clk":"11877651378","pt":1724088961712,"mc":[{"id":"1.232011572","rc":[{"batb":[[0,1.62,4]],"ltp":1.9,"tv":74.71,"id":72857117}]}]}
{"op":"mcm","clk":"11877651671","pt":1724088963999,"mc":[{"id":"1.232011572","rc":[{"batb":[[0,1.62,10]],"ltp":1.9,"tv":74.71,"id":72857117}]}]}
{"op":"mcm","clk":"11877651923","pt":1724088966087,"mc":[{"id":"1.232011572","rc":[{"batb":[[0,1.63,4],[1,1.62,10],[2,1.61,9.78]],"ltp":1.9,"tv":74.71,"id":72857117}]}]}
{"op":"mcm","clk":"11877652056","pt":1724088967183,"mc":[{"id":"1.232011572","rc":[{"batb":[[1,1.61,9.78],[2,1.59,85.3]],"ltp":1.9,"tv":74.71,"id":72857117}]}]}
{"op":"mcm","clk":"11877652227","pt":1724088968593,"mc":[{"id":"1.232011572","rc":[{"batb":[[0,1.61,9.78],[1,1.59,85.3],[2,1.57,288.23]],"ltp":1.9,"tv":74.71,"id":72857117}]}]}
{"op":"mcm","clk":"11877652693","pt":1724088972514,"mc":[{"id":"1.232011572","rc":[{"batb":[[0,1.62,14],[1,1.61,9.78],[2,1.59,85.3]],"ltp":1.9,"tv":74.71,"id":72857117}]}]}
{"op":"mcm","clk":"11877652983","pt":1724088975119,"mc":[{"id":"1.232011572","rc":[{"batb":[[0,1.62,10]],"ltp":1.9,"tv":74.71,"id":72857117}]}]}
{"op":"mcm","clk":"11877653070","pt":1724088975801,"mc":[{"id":"1.232011572","rc":[{"batb":[[0,1.61,9.78],[1,1.59,85.3],[2,1.57,288.23]],"ltp":1.9,"tv":74.71,"id":72857117}]}]}
{"op":"mcm","clk":"11877653240","pt":1724088977311,"mc":[{"id":"1.232011572","rc":[{"batb":[[0,1.62,4],[1,1.61,9.78],[2,1.59,85.3]],"ltp":1.9,"tv":74.71,"id":72857117}]}]}
{"op":"mcm","clk":"11877653496","pt":1724088979606,"mc":[{"id":"1.232011572","rc":[{"batb":[[0,1.61,9.78],[1,1.59,85.3],[2,1.57,288.23]],"ltp":1.9,"tv":74.71,"id":72857117}]}]}
{"op":"mcm","clk":"11877653521","pt":1724088979814,"mc":[{"id":"1.232011572","rc":[{"batb":[[0,1.62,10],[1,1.61,9.78],[2,1.59,85.3]],"ltp":1.9,"tv":74.71,"id":72857117}]}]}
{"op":"mcm","clk":"11877653933","pt":1724088983510,"mc":[{"id":"1.232011572","rc":[{"batb":[[0,1.62,4]],"ltp":1.9,"tv":74.71,"id":72857117}]}]}
{"op":"mcm","clk":"11877654272","pt":1724088986235,"mc":[{"id":"1.232011572","rc":[{"batb":[[0,1.62,10]],"ltp":1.9,"tv":74.71,"id":72857117}]}]}
{"op":"mcm","clk":"11877654476","pt":1724088987910,"mc":[{"id":"1.232011572","rc":[{"batb":[[1,1.65,170.78],[2,1.63,143.85]],"ltp":2.12,"tv":96.16,"id":72857115}]}]}
{"op":"mcm","clk":"11877654642","pt":1724088989607,"mc":[{"id":"1.232011572","rc":[{"batb":[[0,1.61,9.78],[1,1.59,85.3],[2,1.57,288.23]],"ltp":1.9,"tv":74.71,"id":72857117}]}]}
{"op":"mcm","clk":"11877654666","pt":1724088989809,"mc":[{"id":"1.232011572","rc":[{"batb":[[0,1.63,4],[1,1.61,9.78],[2,1.59,85.3]],"ltp":1.9,"tv":74.71,"id":72857117}]}]}
{"op":"mcm","clk":"11877654963","pt":1724088992307,"mc":[{"id":"1.232011572","rc":[{"batb":[[0,1.62,10]],"ltp":1.9,"tv":74.71,"id":72857117}]}]}
{"op":"mcm","clk":"11877655348","pt":1724088995633,"mc":[{"id":"1.232011572","rc":[{"batb":[[0,1.61,9.78],[1,1.59,85.3],[2,1.57,288.23]],"ltp":1.9,"tv":74.71,"id":72857117}]}]}
{"op":"mcm","clk":"11877655373","pt":1724088995808,"mc":[{"id":"1.232011572","rc":[{"batb":[[0,1.62,4],[1,1.61,9.78],[2,1.59,85.3]],"ltp":1.9,"tv":74.71,"id":72857117}]}]}
{"op":"mcm","clk":"11877655655","pt":1724088998226,"mc":[{"id":"1.232011572","rc":[{"batb":[[0,1.62,10]],"ltp":1.9,"tv":74.71,"id":72857117}]}]}
{"op":"mcm","clk":"11877656080","pt":1724089001640,"mc":[{"id":"1.232011572","rc":[{"batb":[[0,1.63,4]],"ltp":1.9,"tv":74.71,"id":72857117}]}]}
{"op":"mcm","clk":"11877656275","pt":1724089003150,"mc":[{"id":"1.232011572","rc":[{"batb":[[0,1.61,9.78],[1,1.59,85.3],[2,1.57,288.23]],"ltp":1.9,"tv":74.71,"id":72857117}]}]}
{"op":"mcm","clk":"11877656429","pt":1724089004564,"mc":[{"id":"1.232011572","rc":[{"batb":[[0,1.62,10],[1,1.61,9.78],[2,1.59,85.3]],"batl":[[0,2.7,17.58]],"ltp":1.9,"tv":74.71,"id":72857117}]}]}
{"op":"mcm","clk":"11877656821","pt":1724089008172,"mc":[{"id":"1.232011572","rc":[{"batb":[[0,1.62,4]],"ltp":1.9,"tv":74.71,"id":72857117}]}]}
{"op":"mcm","clk":"11877657123","pt":1724089010696,"mc":[{"id":"1.232011572","rc":[{"batb":[[0,1.62,10]],"ltp":1.9,"tv":74.71,"id":72857117}]}]}
{"op":"mcm","clk":"11877657562","pt":1724089014571,"mc":[{"id":"1.232011572","rc":[{"batb":[[0,1.62,4]],"ltp":1.9,"tv":74.71,"id":72857117}]}]}
{"op":"mcm","clk":"11877657858","pt":1724089016966,"mc":[{"id":"1.232011572","rc":[{"batb":[[0,1.62,10]],"ltp":1.9,"tv":74.71,"id":72857117}]}]}
{"op":"mcm","clk":"11877658230","pt":1724089020366,"mc":[{"id":"1.232011572","rc":[{"batb":[[0,1.63,4]],"ltp":1.9,"tv":74.71,"id":72857117}]}]}
{"op":"mcm","clk":"11877658436","pt":1724089022225,"mc":[{"id":"1.232011572","rc":[{"batb":[[0,1.61,9.78],[1,1.59,85.3],[2,1.57,288.23]],"ltp":1.9,"tv":74.71,"id":72857117}]}]}
{"op":"mcm","clk":"11877658843","pt":1724089025682,"mc":[{"id":"1.232011572","rc":[{"batb":[[0,1.62,10],[1,1.61,9.78],[2,1.59,85.3]],"ltp":1.9,"tv":74.71,"id":72857117}]}]}
{"op":"mcm","clk":"11877658862","pt":1724089025787,"mc":[{"id":"1.232011572","rc":[{"batb":[[0,1.62,14]],"ltp":1.9,"tv":74.71,"id":72857117}]}]}
{"op":"mcm","clk":"11877659147","pt":1724089028383,"mc":[{"id":"1.232011572","rc":[{"batb":[[0,1.62,10]],"ltp":1.9,"tv":74.71,"id":72857117}]}]}
{"op":"mcm","clk":"11877659231","pt":1724089029007,"mc":[{"id":"1.232011572","rc":[{"batb":[[0,1.61,9.78],[1,1.59,85.3],[2,1.57,288.23]],"ltp":1.9,"tv":74.71,"id":72857117}]}]}
{"op":"mcm","clk":"11877659713","pt":1724089032691,"mc":[{"id":"1.232011572","rc":[{"batb":[[0,1.62,4],[1,1.61,9.78],[2,1.59,85.3]],"ltp":1.9,"tv":74.71,"id":72857117}]}]}
{"op":"mcm","clk":"11877659726","pt":1724089032796,"mc":[{"id":"1.232011572","rc":[{"batb":[[0,1.62,14]],"ltp":1.9,"tv":74.71,"id":72857117}]}]}
{"op":"mcm","clk":"11877660025","pt":1724089035309,"mc":[{"id":"1.232011572","rc":[{"batb":[[0,1.62,10]],"ltp":1.9,"tv":74.71,"id":72857117}]}]}
{"op":"mcm","clk":"11877660178","pt":1724089036517,"mc":[{"id":"1.232011572","rc":[{"batb":[[0,1.61,9.78],[1,1.59,85.3],[2,1.57,288.23]],"ltp":1.9,"tv":74.71,"id":72857117}]}]}
{"op":"mcm","clk":"11877661060","pt":1724089043811,"mc":[{"id":"1.232011572","rc":[{"batb":[[0,1.62,14],[1,1.61,9.78],[2,1.59,85.3]],"ltp":1.9,"tv":74.71,"id":72857117}]}]}
{"op":"mcm","clk":"11877661378","pt":1724089046302,"mc":[{"id":"1.232011572","rc":[{"batb":[[0,1.62,10]],"ltp":1.9,"tv":74.71,"id":72857117}]}]}
{"op":"mcm","clk":"11877661474","pt":1724089047232,"mc":[{"id":"1.232011572","rc":[{"batb":[[0,1.61,9.78],[1,1.59,85.3],[2,1.57,288.23]],"ltp":1.9,"tv":74.71,"id":72857117}]}]}
{"op":"mcm","clk":"11877661728","pt":1724089049324,"mc":[{"id":"1.232011572","rc":[{"batb":[[0,1.63,10],[1,1.62,4],[2,1.61,9.78]],"ltp":1.9,"tv":74.71,"id":72857117}]}]}
{"op":"mcm","clk":"11877661980","pt":1724089051519,"mc":[{"id":"1.232011572","rc":[{"batb":[[1,1.61,9.78],[2,1.59,85.3]],"ltp":1.9,"tv":74.71,"id":72857117}]}]}
{"op":"mcm","clk":"11877662066","pt":1724089052219,"mc":[{"id":"1.232011572","rc":[{"batb":[[0,2.2,3],[1,2.16,7.28],[2,1.65,170.78]],"ltp":2.12,"tv":96.16,"id":72857115}]}]}
{"op":"mcm","clk":"11877662130","pt":1724089052830,"mc":[{"id":"1.232011572","rc":[{"batb":[[0,1.61,9.78],[1,1.59,85.3],[2,1.57,288.23]],"ltp":1.9,"tv":74.71,"id":72857117}]}]}
{"op":"mcm","clk":"11877662256","pt":1724089054130,"mc":[{"id":"1.232011572","rc":[{"batb":[[0,1.62,4],[1,1.61,9.78],[2,1.59,85.3]],"ltp":1.9,"tv":74.71,"id":72857117}]}]}
{"op":"mcm","clk":"11877662409","pt":1724089055418,"mc":[{"id":"1.232011572","rc":[{"batb":[[0,1.63,10],[1,1.62,4],[2,1.61,9.78]],"ltp":1.9,"tv":74.71,"id":72857117}]}]}
{"op":"mcm","clk":"11877662579","pt":1724089056717,"mc":[{"id":"1.232011572","rc":[{"batb":[[1,1.61,9.78],[2,1.59,85.3]],"ltp":1.9,"tv":74.71,"id":72857117}]}]}
{"op":"mcm","clk":"11877662837","pt":1724089059036,"mc":[{"id":"1.232011572","rc":[{"trd":[[2.2,6]],"batb":[[0,2.16,7.28],[1,1.65,170.78],[2,1.63,143.85]],"batl":[[0,2.2,0.58]],"ltp":2.2,"tv":102.16,"id":72857115},{"batb":[[0,1.62,4]],"ltp":1.9,"tv":74.71,"id":72857117}],"tv":176.88}]}
{"op":"mcm","clk":"11877663143","pt":1724089061446,"mc":[{"id":"1.232011572","rc":[{"batb":[[0,1.62,10]],"ltp":1.9,"tv":74.71,"id":72857117}]}]}
{"op":"mcm","clk":"11877663523","pt":1724089064737,"mc":[{"id":"1.232011572","rc":[{"batb":[[0,1.63,4]],"ltp":1.9,"tv":74.71,"id":72857117}]}]}
{"op":"mcm","clk":"11877663823","pt":1724089067245,"mc":[{"id":"1.232011572","rc":[{"batb":[[0,1.62,10]],"ltp":1.9,"tv":74.71,"id":72857117}]}]}
{"op":"mcm","clk":"11877664241","pt":1724089070638,"mc":[{"id":"1.232011572","rc":[{"batb":[[0,1.62,4]],"ltp":1.9,"tv":74.71,"id":72857117}]}]}
{"op":"mcm","clk":"11877664519","pt":1724089073040,"mc":[{"id":"1.232011572","rc":[{"batb":[[0,1.62,10]],"ltp":1.9,"tv":74.71,"id":72857117}]}]}
{"op":"mcm","clk":"11877664939","pt":1724089076252,"mc":[{"id":"1.232011572","rc":[{"batb":[[0,1.63,4]],"ltp":1.9,"tv":74.71,"id":72857117}]}]}
{"op":"mcm","clk":"11877665215","pt":1724089078766,"mc":[{"id":"1.232011572","rc":[{"batb":[[0,1.62,10]],"ltp":1.9,"tv":74.71,"id":72857117}]}]}
{"op":"mcm","clk":"11877665686","pt":1724089082370,"mc":[{"id":"1.232011572","rc":[{"batb":[[0,1.62,4]],"ltp":1.9,"tv":74.71,"id":72857117}]}]}
{"op":"mcm","clk":"11877666027","pt":1724089084967,"mc":[{"id":"1.232011572","rc":[{"batb":[[0,1.62,10]],"ltp":1.9,"tv":74.71,"id":72857117}]}]}
{"op":"mcm","clk":"11877666436","pt":1724089088369,"mc":[{"id":"1.232011572","rc":[{"batb":[[0,1.63,4]],"ltp":1.9,"tv":74.71,"id":72857117}]}]}
{"op":"mcm","clk":"11877666734","pt":1724089090650,"mc":[{"id":"1.232011572","rc":[{"batb":[[0,1.61,9.78],[1,1.59,85.3],[2,1.57,288.23]],"ltp":1.9,"tv":74.71,"id":72857117}]}]}
{"op":"mcm","clk":"11877666760","pt":1724089090859,"mc":[{"id":"1.232011572","rc":[{"batb":[[0,1.62,10],[1,1.61,9.78],[2,1.59,85.3]],"ltp":1.9,"tv":74.71,"id":72857117}]}]}
{"op":"mcm","clk":"11877667212","pt":1724089094595,"mc":[{"id":"1.232011572","rc":[{"batb":[[0,1.62,4]],"ltp":1.9,"tv":74.71,"id":72857117}]}]}
{"op":"mcm","clk":"11877667519","pt":1724089097195,"mc":[{"id":"1.232011572","rc":[{"batb":[[0,1.62,10]],"ltp":1.9,"tv":74.71,"id":72857117}]}]}
{"op":"mcm","clk":"11877667775","pt":1724089099594,"mc":[{"id":"1.232011572","rc":[{"batb":[[0,1.63,4],[1,1.62,10],[2,1.61,9.78]],"ltp":1.9,"tv":74.71,"id":72857117}]}]}
{"op":"mcm","clk":"11877667902","pt":1724089100472,"mc":[{"id":"1.232011572","rc":[{"batb":[[1,1.61,9.78],[2,1.59,85.3]],"ltp":1.9,"tv":74.71,"id":72857117}]}]}
{"op":"mcm","clk":"11877668094","pt":1724089101876,"mc":[{"id":"1.232011572","rc":[{"batb":[[0,1.61,9.78],[1,1.59,85.3],[2,1.57,288.23]],"ltp":1.9,"tv":74.71,"id":72857117}]}]}
{"op":"mcm","clk":"11877670125","pt":1724089115116,"mc":[{"id":"1.232011572","rc":[{"batb":[[0,1.62,14],[1,1.61,9.78],[2,1.59,85.3]],"ltp":1.9,"tv":74.71,"id":72857117}]}]}
{"op":"mcm","clk":"11877670408","pt":1724089117324,"mc":[{"id":"1.232011572","rc":[{"batb":[[0,1.62,10]],"ltp":1.9,"tv":74.71,"id":72857117}]}]}
{"op":"mcm","clk":"11877670541","pt":1724089118418,"mc":[{"id":"1.232011572","rc":[{"batb":[[0,1.61,9.78],[1,1.59,85.3],[2,1.57,288.23]],"ltp":1.9,"tv":74.71,"id":72857117}]}]}
{"op":"mcm","clk":"11877671070","pt":1724089122528,"mc":[{"id":"1.232011572","rc":[{"batb":[[0,1.62,14],[1,1.61,9.78],[2,1.59,85.3]],"ltp":1.9,"tv":74.71,"id":72857117}]}]}
{"op":"mcm","clk":"11877671411","pt":1724089125015,"mc":[{"id":"1.232011572","rc":[{"batb":[[0,1.62,10]],"ltp":1.9,"tv":74.71,"id":72857117}]}]}
{"op":"mcm","clk":"11877671528","pt":1724089126022,"mc":[{"id":"1.232011572","rc":[{"batb":[[0,1.61,9.78],[1,1.59,85.3],[2,1.57,288.23]],"ltp":1.9,"tv":74.71,"id":72857117}]}]}
{"op":"mcm","clk":"11877671826","pt":1724089128294,"mc":[{"id":"1.232011572","rc":[{"batb":[[0,1.62,14],[1,1.61,9.78],[2,1.59,85.3]],"ltp":1.9,"tv":74.71,"id":72857117}]}]}
{"op":"mcm","clk":"11877672138","pt":1724089130917,"mc":[{"id":"1.232011572","rc":[{"batb":[[0,1.62,10]],"ltp":1.9,"tv":74.71,"id":72857117}]}]}
{"op":"mcm","clk":"11877672272","pt":1724089132024,"mc":[{"id":"1.232011572","rc":[{"batb":[[0,1.61,9.78],[1,1.59,85.3],[2,1.57,288.23]],"ltp":1.9,"tv":74.71,"id":72857117}]}]}
{"op":"mcm","clk":"11877672568","pt":1724089134442,"mc":[{"id":"1.232011572","rc":[{"batb":[[0,1.62,14],[1,1.61,9.78],[2,1.59,85.3]],"ltp":1.9,"tv":74.71,"id":72857117}]}]}
{"op":"mcm","clk":"11877672950","pt":1724089137337,"mc":[{"id":"1.232011572","rc":[{"batb":[[0,1.62,10]],"ltp":1.9,"tv":74.71,"id":72857117}]}]}
{"op":"mcm","clk":"11877673060","pt":1724089138229,"mc":[{"id":"1.232011572","rc":[{"batb":[[0,1.61,9.78],[1,1.59,85.3],[2,1.57,288.23]],"ltp":1.9,"tv":74.71,"id":72857117}]}]}
{"op":"mcm","clk":"11877673546","pt":1724089142007,"mc":[{"id":"1.232011572","rc":[{"batb":[[0,1.62,14],[1,1.61,9.78],[2,1.59,85.3]],"ltp":1.9,"tv":74.71,"id":72857117}]}]}
{"op":"mcm","clk":"11877673916","pt":1724089144738,"mc":[{"id":"1.232011572","rc":[{"batb":[[0,1.62,10]],"ltp":1.9,"tv":74.71,"id":72857117}]}]}
{"op":"mcm","clk":"11877674025","pt":1724089145568,"mc":[{"id":"1.232011572","rc":[{"batb":[[0,1.61,9.78],[1,1.59,85.3],[2,1.57,288.23]],"ltp":1.9,"tv":74.71,"id":72857117}]}]}
{"op":"mcm","clk":"11877674275","pt":1724089147624,"mc":[{"id":"1.232011572","rc":[{"batb":[[0,1.62,4],[1,1.61,9.78],[2,1.59,85.3]],"ltp":1.9,"tv":74.71,"id":72857117}]}]}
{"op":"mcm","clk":"11877674342","pt":1724089148140,"mc":[{"id":"1.232011572","rc":[{"batb":[[0,1.63,10],[1,1.62,4],[2,1.61,9.78]],"ltp":1.9,"tv":74.71,"id":72857117}]}]}
{"op":"mcm","clk":"11877674604","pt":1724089150345,"mc":[{"id":"1.232011572","rc":[{"batb":[[1,1.61,9.78],[2,1.59,85.3]],"ltp":1.9,"tv":74.71,"id":72857117}]}]}
{"op":"mcm","clk":"11877674734","pt":1724089151438,"mc":[{"id":"1.232011572","rc":[{"batb":[[0,1.61,9.78],[1,1.59,85.3],[2,1.57,288.23]],"ltp":1.9,"tv":74.71,"id":72857117}]}]}
{"op":"mcm","clk":"11877675116","pt":1724089154344,"mc":[{"id":"1.232011572","rc":[{"batb":[[0,1.62,14],[1,1.61,9.78],[2,1.59,85.3]],"ltp":1.9,"tv":74.71,"id":72857117}]}]}
{"op":"mcm","clk":"11877675446","pt":1724089157162,"mc":[{"id":"1.232011572","rc":[{"batb":[[0,1.62,10]],"ltp":1.9,"tv":74.71,"id":72857117}]}]}
{"op":"mcm","clk":"11877675574","pt":1724089158139,"mc":[{"id":"1.232011572","rc":[{"batb":[[0,1.61,9.78],[1,1.59,85.3],[2,1.57,288.23]],"ltp":1.9,"tv":74.71,"id":72857117}]}]}
{"op":"mcm","clk":"11877676180","pt":1724089163185,"mc":[{"id":"1.232011572","rc":[{"batb":[[0,1.62,14],[1,1.61,9.78],[2,1.59,85.3]],"ltp":1.9,"tv":74.71,"id":72857117}]}]}
{"op":"mcm","clk":"11877676535","pt":1724089166170,"mc":[{"id":"1.232011572","rc":[{"batb":[[0,1.62,10]],"ltp":1.9,"tv":74.71,"id":72857117}]}]}
{"op":"mcm","clk":"11877676664","pt":1724089167063,"mc":[{"id":"1.232011572","rc":[{"batb":[[0,1.61,9.78],[1,1.59,85.3],[2,1.57,288.23]],"ltp":1.9,"tv":74.71,"id":72857117}]}]}
{"op":"mcm","clk":"11877676852","pt":1724089168579,"mc":[{"id":"1.232011572","rc":[{"batb":[[0,1.62,4],[1,1.61,9.78],[2,1.59,85.3]],"ltp":1.9,"tv":74.71,"id":72857117}]}]}
{"op":"mcm","clk":"11877677164","pt":1724089171168,"mc":[{"id":"1.232011572","rc":[{"batb":[[0,1.62,10]],"ltp":1.9,"tv":74.71,"id":72857117}]}]}
{"op":"mcm","clk":"11877677480","pt":1724089173476,"mc":[{"id":"1.232011572","rc":[{"batb":[[0,1.63,4],[1,1.62,10],[2,1.61,9.78]],"ltp":1.9,"tv":74.71,"id":72857117}]}]}
{"op":"mcm","clk":"11877677616","pt":1724089174379,"mc":[{"id":"1.232011572","rc":[{"batb":[[1,1.61,9.78],[2,1.59,85.3]],"ltp":1.9,"tv":74.71,"id":72857117}]}]}
{"op":"mcm","clk":"11877677844","pt":1724089176263,"mc":[{"id":"1.232011572","rc":[{"batb":[[0,1.61,9.78],[1,1.59,85.3],[2,1.57,288.23]],"ltp":1.9,"tv":74.71,"id":72857117}]}]}
{"op":"mcm","clk":"11877678122","pt":1724089178497,"mc":[{"id":"1.232011572","rc":[{"batb":[[0,1.62,14],[1,1.61,9.78],[2,1.59,85.3]],"ltp":1.9,"tv":74.71,"id":72857117}]}]}
{"op":"mcm","clk":"11877678421","pt":1724089180911,"mc":[{"id":"1.232011572","rc":[{"batb":[[0,1.62,10]],"ltp":1.9,"tv":74.71,"id":72857117}]}]}
{"op":"mcm","clk":"11877678556","pt":1724089181998,"mc":[{"id":"1.232011572","rc":[{"batb":[[0,1.61,9.78],[1,1.59,85.3],[2,1.57,288.23]],"ltp":1.9,"tv":74.71,"id":72857117}]}]}
{"op":"mcm","clk":"11877678978","pt":1724089185634,"mc":[{"id":"1.232011572","rc":[{"batb":[[0,1.62,14],[1,1.61,9.78],[2,1.59,85.3]],"ltp":1.9,"tv":74.71,"id":72857117}]}]}
{"op":"mcm","clk":"11877679241","pt":1724089187996,"mc":[{"id":"1.232011572","rc":[{"batb":[[0,1.62,10]],"ltp":1.9,"tv":74.71,"id":72857117}]}]}
{"op":"mcm","clk":"11877679374","pt":1724089189099,"mc":[{"id":"1.232011572","rc":[{"batb":[[0,1.61,9.78],[1,1.59,85.3],[2,1.57,288.23]],"ltp":1.9,"tv":74.71,"id":72857117}]}]}
{"op":"mcm","clk":"11877679895","pt":1724089193115,"mc":[{"id":"1.232011572","rc":[{"batb":[[0,1.62,14],[1,1.61,9.78],[2,1.59,85.3]],"ltp":1.9,"tv":74.71,"id":72857117}]}]}
{"op":"mcm","clk":"11877680253","pt":1724089195824,"mc":[{"id":"1.232011572","rc":[{"batb":[[0,1.62,10]],"ltp":1.9,"tv":74.71,"id":72857117}]}]}
{"op":"mcm","clk":"11877680393","pt":1724089196934,"mc":[{"id":"1.232011572","rc":[{"batb":[[0,1.61,9.78],[1,1.59,85.3],[2,1.57,288.23]],"ltp":1.9,"tv":74.71,"id":72857117}]}]}
{"op":"mcm","clk":"11877682578","pt":1724089214131,"mc":[{"id":"1.232011572","rc":[{"batb":[[0,1.62,14],[1,1.61,9.78],[2,1.59,85.3]],"ltp":1.9,"tv":74.71,"id":72857117}]}]}
{"op":"mcm","clk":"11877683060","pt":1724089217712,"mc":[{"id":"1.232011572","rc":[{"batb":[[0,1.61,9.78],[1,1.59,85.3],[2,1.57,288.23]],"ltp":1.9,"tv":74.71,"id":72857117}]}]}
{"op":"mcm","clk":"11877683795","pt":1724089223317,"mc":[{"id":"1.232011572","rc":[{"batb":[[0,1.62,14],[1,1.61,9.78],[2,1.59,85.3]],"ltp":1.9,"tv":74.71,"id":72857117}]}]}
{"op":"mcm","clk":"11877684082","pt":1724089225514,"mc":[{"id":"1.232011572","rc":[{"batb":[[0,1.62,10]],"ltp":1.9,"tv":74.71,"id":72857117}]}]}
{"op":"mcm","clk":"11877684217","pt":1724089226717,"mc":[{"id":"1.232011572","rc":[{"batb":[[0,1.61,9.78],[1,1.59,85.3],[2,1.57,288.23]],"ltp":1.9,"tv":74.71,"id":72857117}]}]}
{"op":"mcm","clk":"11877684481","pt":1724089228656,"mc":[{"id":"1.232011572","rc":[{"batb":[[0,1.62,4],[1,1.61,9.78],[2,1.59,85.3]],"ltp":1.9,"tv":74.71,"id":72857117}]}]}
{"op":"mcm","clk":"11877684810","pt":1724089231163,"mc":[{"id":"1.232011572","rc":[{"batb":[[0,1.62,10]],"ltp":1.9,"tv":74.71,"id":72857117}]}]}
{"op":"mcm","clk":"11877685276","pt":1724089234629,"mc":[{"id":"1.232011572","rc":[{"batb":[[0,1.62,4]],"ltp":1.9,"tv":74.71,"id":72857117}]}]}
{"op":"mcm","clk":"11877685596","pt":1724089237050,"mc":[{"id":"1.232011572","rc":[{"batb":[[0,1.62,10]],"ltp":1.9,"tv":74.71,"id":72857117}]}]}
{"op":"mcm","clk":"11877686012","pt":1724089240566,"mc":[{"id":"1.232011572","rc":[{"batb":[[0,1.62,4]],"ltp":1.9,"tv":74.71,"id":72857117}]}]}
{"op":"mcm","clk":"11877686324","pt":1724089243145,"mc":[{"id":"1.232011572","rc":[{"batb":[[0,1.62,10]],"ltp":1.9,"tv":74.71,"id":72857117}]}]}
{"op":"mcm","clk":"11877686834","pt":1724089246762,"mc":[{"id":"1.232011572","rc":[{"batb":[[0,1.62,4]],"ltp":1.9,"tv":74.71,"id":72857117}]}]}
{"op":"mcm","clk":"11877687130","pt":1724089249181,"mc":[{"id":"1.232011572","rc":[{"batb":[[0,1.62,10]],"ltp":1.9,"tv":74.71,"id":72857117}]}]}
{"op":"mcm","clk":"11877687448","pt":1724089251689,"mc":[{"id":"1.232011572","rc":[{"batb":[[0,1.63,4],[1,1.62,10],[2,1.61,9.78]],"ltp":1.9,"tv":74.71,"id":72857117}]}]}
{"op":"mcm","clk":"11877687561","pt":1724089252375,"mc":[{"id":"1.232011572","rc":[{"batb":[[1,1.61,9.78],[2,1.59,85.3]],"ltp":1.9,"tv":74.71,"id":72857117}]}]}
{"op":"mcm","clk":"11877687816","pt":1724089254575,"mc":[{"id":"1.232011572","rc":[{"batb":[[0,1.63,4.48]],"batl":[[0,1.86,17.1],[1,2.7,16.59]],"ltp":1.9,"tv":74.71,"id":72857117}]}]}
{"op":"mcm","clk":"11877695147","pt":1724089313724,"mc":[{"id":"1.232011572","rc":[{"batl":[[0,1.86,5.46]],"ltp":1.9,"tv":74.71,"id":72857117}]}]}
{"op":"mcm","clk":"11877695174","pt":1724089313931,"mc":[{"id":"1.232011572","rc":[{"batb":[[0,1.64,14],[1,1.63,4.48],[2,1.61,9.78]],"ltp":1.9,"tv":74.71,"id":72857117}]}]}
{"op":"mcm","clk":"11877695479","pt":1724089316238,"mc":[{"id":"1.232011572","rc":[{"batb":[[0,1.64,10]],"ltp":1.9,"tv":74.71,"id":72857117}]}]}
{"op":"mcm","clk":"11877695604","pt":1724089317230,"mc":[{"id":"1.232011572","rc":[{"batb":[[0,1.63,4.48],[1,1.61,9.78],[2,1.59,85.3]],"ltp":1.9,"tv":74.71,"id":72857117}]}]}
{"op":"mcm","clk":"11877697910","pt":1724089335468,"mc":[{"id":"1.232011572","rc":[{"batl":[[1,2,4.48],[2,2.7,16.59]],"ltp":1.9,"tv":74.71,"id":72857117}]}]}
{"op":"mcm","clk":"11877699578","pt":1724089347475,"mc":[{"id":"1.232011572","rc":[{"batl":[[2,2.3,4.48]],"ltp":1.9,"tv":74.71,"id":72857117}]}]}
{"op":"mcm","clk":"11877720107","pt":1724089433874,"mc":[{"id":"1.232011572","rc":[{"batb":[[0,1.65,7.16],[1,1.63,4.48],[2,1.61,9.78]],"ltp":1.9,"tv":74.71,"id":72857117}]}]}
{"op":"mcm","clk":"11877732735","pt":1724089535979,"mc":[{"id":"1.232011572","rc":[{"trd":[[2.54,1.07]],"ltp":2.54,"tv":103.23,"id":72857115},{"trd":[[1.65,1.64]],"batb":[[0,1.65,5.52]],"ltp":1.65,"tv":76.36,"id":72857117}],"tv":179.59}]}
{"op":"mcm","clk":"11877735333","pt":1724089557918,"mc":[{"id":"1.232011572","rc":[{"batb":[[0,1.66,4.48],[1,1.65,5.52],[2,1.63,4.48]],"ltp":1.65,"tv":76.36,"id":72857117}]}]}
{"op":"mcm","clk":"11877735617","pt":1724089560425,"mc":[{"id":"1.232011572","rc":[{"batl":[[0,1.82,1.47],[1,1.86,5.46],[2,2,4.48]],"ltp":1.65,"tv":76.36,"id":72857117}]}]}
{"op":"mcm","clk":"11877736917","pt":1724089572045,"mc":[{"id":"1.232011572","rc":[{"batb":[[0,1.66,10.18],[1,1.63,4.48],[2,1.61,9.78]],"ltp":1.65,"tv":76.36,"id":72857117}]}]}
{"op":"mcm","clk":"11877737432","pt":1724089576449,"mc":[{"id":"1.232011572","rc":[{"batb":[[0,2.18,10],[1,2.16,7.28],[2,1.65,170.78]],"batl":[[0,3.5,0.77]],"ltp":2.54,"tv":103.23,"id":72857115}]}]}
{"op":"mcm","clk":"11877737750","pt":1724089579863,"mc":[{"id":"1.232011572","rc":[{"batb":[[0,2.16,7.28],[1,1.65,170.78],[2,1.63,143.85]],"ltp":2.54,"tv":103.23,"id":72857115}]}]}
{"op":"mcm","clk":"11877738050","pt":1724089582739,"mc":[{"id":"1.232011572","rc":[{"batb":[[0,2.18,10],[1,2.16,7.28],[2,1.65,170.78]],"ltp":2.54,"tv":103.23,"id":72857115}]}]}
{"op":"mcm","clk":"11877738415","pt":1724089586172,"mc":[{"id":"1.232011572","rc":[{"batb":[[0,2.16,7.28],[1,1.65,170.78],[2,1.63,143.85]],"ltp":2.54,"tv":103.23,"id":72857115}]}]}
{"op":"mcm","clk":"11877738890","pt":1724089590356,"mc":[{"id":"1.232011572","rc":[{"batb":[[0,2.18,10],[1,2.16,7.28],[2,1.65,170.78]],"ltp":2.54,"tv":103.23,"id":72857115}]}]}
{"op":"mcm","clk":"11877739281","pt":1724089593855,"mc":[{"id":"1.232011572","rc":[{"batb":[[0,2.16,7.28],[1,1.65,170.78],[2,1.63,143.85]],"ltp":2.54,"tv":103.23,"id":72857115}]}]}
{"op":"mcm","clk":"11877739545","pt":1724089596158,"mc":[{"id":"1.232011572","rc":[{"batb":[[0,2.18,10],[1,2.16,7.28],[2,1.65,170.78]],"ltp":2.54,"tv":103.23,"id":72857115}]}]}
{"op":"mcm","clk":"11877739975","pt":1724089599355,"mc":[{"id":"1.232011572","rc":[{"batb":[[0,2.16,7.28],[1,1.65,170.78],[2,1.63,143.85]],"ltp":2.54,"tv":103.23,"id":72857115}]}]}
{"op":"mcm","clk":"11877740380","pt":1724089602783,"mc":[{"id":"1.232011572","rc":[{"batb":[[0,2.18,10],[1,2.16,7.28],[2,1.65,170.78]],"ltp":2.54,"tv":103.23,"id":72857115}]}]}
{"op":"mcm","clk":"11877740785","pt":1724089606509,"mc":[{"id":"1.232011572","rc":[{"batb":[[0,2.16,7.28],[1,1.65,170.78],[2,1.63,143.85]],"ltp":2.54,"tv":103.23,"id":72857115}]}]}
{"op":"mcm","clk":"11877741120","pt":1724089608902,"mc":[{"id":"1.232011572","rc":[{"batb":[[0,2.18,10],[1,2.16,7.28],[2,1.65,170.78]],"ltp":2.54,"tv":103.23,"id":72857115}]}]}
{"op":"mcm","clk":"11877741537","pt":1724089612475,"mc":[{"id":"1.232011572","rc":[{"batb":[[0,2.16,7.28],[1,1.65,170.78],[2,1.63,143.85]],"ltp":2.54,"tv":103.23,"id":72857115}]}]}
{"op":"mcm","clk":"11877742114","pt":1724089617310,"mc":[{"id":"1.232011572","rc":[{"batb":[[0,2.18,10],[1,2.16,7.28],[2,1.65,170.78]],"ltp":2.54,"tv":103.23,"id":72857115}]}]}
{"op":"mcm","clk":"11877742534","pt":1724089620793,"mc":[{"id":"1.232011572","rc":[{"batb":[[0,2.16,7.28],[1,1.65,170.78],[2,1.63,143.85]],"ltp":2.54,"tv":103.23,"id":72857115}]}]}
{"op":"mcm","clk":"11877742903","pt":1724089623929,"mc":[{"id":"1.232011572","rc":[{"batb":[[0,2.18,10],[1,2.16,7.28],[2,1.65,170.78]],"ltp":2.54,"tv":103.23,"id":72857115}]}]}
{"op":"mcm","clk":"11877743271","pt":1724089627410,"mc":[{"id":"1.232011572","rc":[{"batb":[[0,2.16,7.28],[1,1.65,170.78],[2,1.63,143.85]],"ltp":2.54,"tv":103.23,"id":72857115}]}]}
{"op":"mcm","clk":"11877743617","pt":1724089630224,"mc":[{"id":"1.232011572","rc":[{"batb":[[0,2.18,10],[1,2.16,7.28],[2,1.65,170.78]],"ltp":2.54,"tv":103.23,"id":72857115}]}]}
{"op":"mcm","clk":"11877744015","pt":1724089633709,"mc":[{"id":"1.232011572","rc":[{"batb":[[0,2.16,7.28],[1,1.65,170.78],[2,1.63,143.85]],"ltp":2.54,"tv":103.23,"id":72857115}]}]}
{"op":"mcm","clk":"11877744830","pt":1724089640364,"mc":[{"id":"1.232011572","rc":[{"batb":[[0,2.18,10],[1,2.16,7.28],[2,1.65,170.78]],"ltp":2.54,"tv":103.23,"id":72857115}]}]}
{"op":"mcm","clk":"11877745258","pt":1724089643841,"mc":[{"id":"1.232011572","rc":[{"batb":[[0,2.16,7.28],[1,1.65,170.78],[2,1.63,143.85]],"ltp":2.54,"tv":103.23,"id":72857115}]}]}
{"op":"mcm","clk":"11877745573","pt":1724089646246,"mc":[{"id":"1.232011572","rc":[{"batb":[[0,2.18,10],[1,2.16,7.28],[2,1.65,170.78]],"ltp":2.54,"tv":103.23,"id":72857115}]}]}
{"op":"mcm","clk":"11877745825","pt":1724089648426,"mc":[{"id":"1.232011572","rc":[{"trd":[[2.2,7.22]],"batl":[[0,2.2,2.37],[1,3.5,0.77]],"ltp":2.2,"tv":104.45,"id":72857115},{"trd":[[1.82,2.92]],"batl":[[0,1.86,5.46],[1,2,4.48],[2,2.3,4.48]],"ltp":1.82,"tv":77.83,"id":72857117}],"tv":182.28}]}
{"op":"mcm","clk":"11877745969","pt":1724089649761,"mc":[{"id":"1.232011572","rc":[{"batb":[[0,2.16,7.28],[1,1.65,170.78],[2,1.63,143.85]],"ltp":2.2,"tv":104.45,"id":72857115}]}]}
{"op":"mcm","clk":"11877746352","pt":1724089653547,"mc":[{"id":"1.232011572","rc":[{"batl":[[0,3.5,0.77],[1,3.5,0]],"ltp":2.2,"tv":104.45,"id":72857115}]}]}
{"op":"mcm","clk":"11877746389","pt":1724089653854,"mc":[{"id":"1.232011572","rc":[{"batb":[[0,2.18,10],[1,2.16,7.28],[2,1.65,170.78]],"ltp":2.2,"tv":104.45,"id":72857115}]}]}
{"op":"mcm","clk":"11877746780","pt":1724089657174,"mc":[{"id":"1.232011572","rc":[{"batb":[[0,2.16,7.28],[1,1.65,170.78],[2,1.63,143.85]],"ltp":2.2,"tv":104.45,"id":72857115}]}]}
{"op":"mcm","clk":"11877747429","pt":1724089662074,"mc":[{"id":"1.232011572","rc":[{"batb":[[0,2.18,10],[1,2.16,7.28],[2,1.65,170.78]],"ltp":2.2,"tv":104.45,"id":72857115}]}]}
{"op":"mcm","clk":"11877748201","pt":1724089666052,"mc":[{"id":"1.232011572","rc":[{"batb":[[0,2.16,7.28],[1,1.65,170.78],[2,1.63,143.85]],"ltp":2.2,"tv":104.45,"id":72857115}]}]}
{"op":"mcm","clk":"11877749838","pt":1724089671065,"mc":[{"id":"1.232011572","rc":[{"batb":[[0,2.18,10],[1,2.16,7.28],[2,1.65,170.78]],"ltp":2.2,"tv":104.45,"id":72857115}]}]}
{"op":"mcm","clk":"11877750533","pt":1724089674290,"mc":[{"id":"1.232011572","rc":[{"batb":[[0,2.16,7.28],[1,1.65,170.78],[2,1.63,143.85]],"ltp":2.2,"tv":104.45,"id":72857115}]}]}
{"op":"mcm","clk":"11877750994","pt":1724089676845,"mc":[{"id":"1.232011572","rc":[{"batb":[[0,2.18,10],[1,2.16,7.28],[2,1.65,170.78]],"ltp":2.2,"tv":104.45,"id":72857115}]}]}
{"op":"mcm","clk":"11877751593","pt":1724089680466,"mc":[{"id":"1.232011572","rc":[{"batb":[[0,2.16,7.28],[1,1.65,170.78],[2,1.63,143.85]],"ltp":2.2,"tv":104.45,"id":72857115}]}]}
{"op":"mcm","clk":"11877752216","pt":1724089684380,"mc":[{"id":"1.232011572","rc":[{"batb":[[0,2.18,10],[1,2.16,7.28],[2,1.65,170.78]],"ltp":2.2,"tv":104.45,"id":72857115}]}]}
{"op":"mcm","clk":"11877752696","pt":1724089687594,"mc":[{"id":"1.232011572","rc":[{"batb":[[0,2.16,7.28],[1,1.65,170.78],[2,1.63,143.85]],"ltp":2.2,"tv":104.45,"id":72857115}]}]}
{"op":"mcm","clk":"11877753260","pt":1724089691974,"mc":[{"id":"1.232011572","rc":[{"batb":[[0,2.18,10],[1,2.16,7.28],[2,1.65,170.78]],"ltp":2.2,"tv":104.45,"id":72857115}]}]}
{"op":"mcm","clk":"11877753724","pt":1724089695405,"mc":[{"id":"1.232011572","rc":[{"batb":[[0,2.16,7.28],[1,1.65,170.78],[2,1.63,143.85]],"ltp":2.2,"tv":104.45,"id":72857115}]}]}
{"op":"mcm","clk":"11877754074","pt":1724089698016,"mc":[{"id":"1.232011572","rc":[{"batb":[[0,2.18,10],[1,2.16,7.28],[2,1.65,170.78]],"ltp":2.2,"tv":104.45,"id":72857115}]}]}
{"op":"mcm","clk":"11877754537","pt":1724089701579,"mc":[{"id":"1.232011572","rc":[{"batb":[[0,2.16,7.28],[1,1.65,170.78],[2,1.63,143.85]],"ltp":2.2,"tv":104.45,"id":72857115}]}]}
{"op":"mcm","clk":"11877754828","pt":1724089703913,"mc":[{"id":"1.232011572","rc":[{"batb":[[0,2.18,10],[1,2.16,7.28],[2,1.65,170.78]],"ltp":2.2,"tv":104.45,"id":72857115}]}]}
{"op":"mcm","clk":"11877755233","pt":1724089707425,"mc":[{"id":"1.232011572","rc":[{"batb":[[0,2.16,7.28],[1,1.65,170.78],[2,1.63,143.85]],"ltp":2.2,"tv":104.45,"id":72857115}]}]}
{"op":"mcm","clk":"11877755639","pt":1724089710215,"mc":[{"id":"1.232011572","rc":[{"batb":[[0,2.18,10],[1,2.16,7.28],[2,1.65,170.78]],"ltp":2.2,"tv":104.45,"id":72857115}]}]}
{"op":"mcm","clk":"11877756122","pt":1724089713811,"mc":[{"id":"1.232011572","rc":[{"batb":[[0,2.16,7.28],[1,1.65,170.78],[2,1.63,143.85]],"ltp":2.2,"tv":104.45,"id":72857115}]}]}
{"op":"mcm","clk":"11877756438","pt":1724089716528,"mc":[{"id":"1.232011572","rc":[{"batb":[[0,2.18,10],[1,2.16,7.28],[2,1.65,170.78]],"ltp":2.2,"tv":104.45,"id":72857115}]}]}
{"op":"mcm","clk":"11877756930","pt":1724089720321,"mc":[{"id":"1.232011572","rc":[{"batb":[[0,2.16,7.28],[1,1.65,170.78],[2,1.63,143.85]],"ltp":2.2,"tv":104.45,"id":72857115}]}]}
{"op":"mcm","clk":"11877757388","pt":1724089723819,"mc":[{"id":"1.232011572","rc":[{"batb":[[0,2.18,10],[1,2.16,7.28],[2,1.65,170.78]],"ltp":2.2,"tv":104.45,"id":72857115}]}]}
{"op":"mcm","clk":"11877757798","pt":1724089727201,"mc":[{"id":"1.232011572","rc":[{"batb":[[0,2.16,7.28],[1,1.65,170.78],[2,1.63,143.85]],"ltp":2.2,"tv":104.45,"id":72857115}]}]}
{"op":"mcm","clk":"11877758140","pt":1724089730105,"mc":[{"id":"1.232011572","rc":[{"batb":[[0,2.18,10],[1,2.16,7.28],[2,1.65,170.78]],"ltp":2.2,"tv":104.45,"id":72857115}]}]}
{"op":"mcm","clk":"11877758517","pt":1724089733539,"mc":[{"id":"1.232011572","rc":[{"batb":[[0,2.16,7.28],[1,1.65,170.78],[2,1.63,143.85]],"ltp":2.2,"tv":104.45,"id":72857115}]}]}
{"op":"mcm","clk":"11877758996","pt":1724089737742,"mc":[{"id":"1.232011572","rc":[{"batb":[[0,2.18,10],[1,2.16,7.28],[2,1.65,170.78]],"ltp":2.2,"tv":104.45,"id":72857115}]}]}
{"op":"mcm","clk":"11877759393","pt":1724089741157,"mc":[{"id":"1.232011572","rc":[{"batb":[[0,2.16,7.28],[1,1.65,170.78],[2,1.63,143.85]],"ltp":2.2,"tv":104.45,"id":72857115}]}]}
{"op":"mcm","clk":"11877760017","pt":1724089746632,"mc":[{"id":"1.232011572","rc":[{"batb":[[0,2.18,10],[1,2.16,7.28],[2,1.65,170.78]],"ltp":2.2,"tv":104.45,"id":72857115}]}]}
{"op":"mcm","clk":"11877760428","pt":1724089750151,"mc":[{"id":"1.232011572","rc":[{"batb":[[0,2.16,7.28],[1,1.65,170.78],[2,1.63,143.85]],"ltp":2.2,"tv":104.45,"id":72857115}]}]}
{"op":"mcm","clk":"11877760702","pt":1724089752775,"mc":[{"id":"1.232011572","rc":[{"batb":[[0,2.18,10],[1,2.16,7.28],[2,1.65,170.78]],"ltp":2.2,"tv":104.45,"id":72857115}]}]}
{"op":"mcm","clk":"11877761088","pt":1724089755994,"mc":[{"id":"1.232011572","rc":[{"batb":[[0,2.16,7.28],[1,1.65,170.78],[2,1.63,143.85]],"ltp":2.2,"tv":104.45,"id":72857115}]}]}
{"op":"mcm","clk":"11877761556","pt":1724089759754,"mc":[{"id":"1.232011572","rc":[{"batb":[[0,2.18,10],[1,2.16,7.28],[2,1.65,170.78]],"ltp":2.2,"tv":104.45,"id":72857115}]}]}
{"op":"mcm","clk":"11877761972","pt":1724089763280,"mc":[{"id":"1.232011572","rc":[{"batb":[[0,2.16,7.28],[1,1.65,170.78],[2,1.63,143.85]],"ltp":2.2,"tv":104.45,"id":72857115}]}]}
{"op":"mcm","clk":"11877762366","pt":1724089766666,"mc":[{"id":"1.232011572","rc":[{"batb":[[0,2.18,10],[1,2.16,7.28],[2,1.65,170.78]],"ltp":2.2,"tv":104.45,"id":72857115}]}]}
{"op":"mcm","clk":"11877762790","pt":1724089770288,"mc":[{"id":"1.232011572","rc":[{"batb":[[0,2.16,7.28],[1,1.65,170.78],[2,1.63,143.85]],"ltp":2.2,"tv":104.45,"id":72857115}]}]}
{"op":"mcm","clk":"11877763157","pt":1724089773281,"mc":[{"id":"1.232011572","rc":[{"batb":[[0,2.18,10],[1,2.16,7.28],[2,1.65,170.78]],"ltp":2.2,"tv":104.45,"id":72857115}]}]}
{"op":"mcm","clk":"11877763573","pt":1724089777099,"mc":[{"id":"1.232011572","rc":[{"batb":[[0,2.16,7.28],[1,1.65,170.78],[2,1.63,143.85]],"ltp":2.2,"tv":104.45,"id":72857115}]}]}
{"op":"mcm","clk":"11877763862","pt":1724089779585,"mc":[{"id":"1.232011572","rc":[{"batb":[[0,2.18,10],[1,2.16,7.28],[2,1.65,170.78]],"ltp":2.2,"tv":104.45,"id":72857115}]}]}
{"op":"mcm","clk":"11877764235","pt":1724089783102,"mc":[{"id":"1.232011572","rc":[{"batb":[[0,2.16,7.28],[1,1.65,170.78],[2,1.63,143.85]],"ltp":2.2,"tv":104.45,"id":72857115}]}]}
{"op":"mcm","clk":"11877764614","pt":1724089786506,"mc":[{"id":"1.232011572","rc":[{"batb":[[0,2.18,10],[1,2.16,7.28],[2,1.65,170.78]],"ltp":2.2,"tv":104.45,"id":72857115}]}]}
{"op":"mcm","clk":"11877765024","pt":1724089790086,"mc":[{"id":"1.232011572","rc":[{"batb":[[0,2.16,7.28],[1,1.65,170.78],[2,1.63,143.85]],"ltp":2.2,"tv":104.45,"id":72857115}]}]}
{"op":"mcm","clk":"11877765371","pt":1724089793499,"mc":[{"id":"1.232011572","rc":[{"batb":[[0,2.18,10],[1,2.16,7.28],[2,1.65,170.78]],"ltp":2.2,"tv":104.45,"id":72857115}]}]}
{"op":"mcm","clk":"11877765831","pt":1724089797794,"mc":[{"id":"1.232011572","rc":[{"batb":[[0,2.16,7.28],[1,1.65,170.78],[2,1.63,143.85]],"ltp":2.2,"tv":104.45,"id":72857115}]}]}
{"op":"mcm","clk":"11877766379","pt":1724089802707,"mc":[{"id":"1.232011572","rc":[{"batb":[[0,2.18,10],[1,2.16,7.28],[2,1.65,170.78]],"ltp":2.2,"tv":104.45,"id":72857115}]}]}
{"op":"mcm","clk":"11877766800","pt":1724089806334,"mc":[{"id":"1.232011572","rc":[{"batb":[[0,2.16,7.28],[1,1.65,170.78],[2,1.63,143.85]],"ltp":2.2,"tv":104.45,"id":72857115}]}]}
{"op":"mcm","clk":"11877767209","pt":1724089809845,"mc":[{"id":"1.232011572","rc":[{"batb":[[0,2.18,10],[1,2.16,7.28],[2,1.65,170.78]],"ltp":2.2,"tv":104.45,"id":72857115}]}]}
{"op":"mcm","clk":"11877767620","pt":1724089813342,"mc":[{"id":"1.232011572","rc":[{"batb":[[0,2.16,7.28],[1,1.65,170.78],[2,1.63,143.85]],"ltp":2.2,"tv":104.45,"id":72857115}]}]}
{"op":"mcm","clk":"11877767893","pt":1724089815747,"mc":[{"id":"1.232011572","rc":[{"batb":[[0,2.18,10],[1,2.16,7.28],[2,1.65,170.78]],"ltp":2.2,"tv":104.45,"id":72857115}]}]}
{"op":"mcm","clk":"11877768259","pt":1724089819429,"mc":[{"id":"1.232011572","rc":[{"batb":[[0,2.16,7.28],[1,1.65,170.78],[2,1.63,143.85]],"ltp":2.2,"tv":104.45,"id":72857115}]}]}
{"op":"mcm","clk":"11877768659","pt":1724089822943,"mc":[{"id":"1.232011572","rc":[{"batb":[[0,2.18,10],[1,2.16,7.28],[2,1.65,170.78]],"ltp":2.2,"tv":104.45,"id":72857115}]}]}
{"op":"mcm","clk":"11877769055","pt":1724089826435,"mc":[{"id":"1.232011572","rc":[{"batb":[[0,2.16,7.28],[1,1.65,170.78],[2,1.63,143.85]],"ltp":2.2,"tv":104.45,"id":72857115}]}]}
{"op":"mcm","clk":"11877769282","pt":1724089828767,"mc":[{"id":"1.232011572","rc":[{"batb":[[0,2.18,10],[1,2.16,7.28],[2,1.65,170.78]],"ltp":2.2,"tv":104.45,"id":72857115}]}]}
{"op":"mcm","clk":"11877769652","pt":1724089832262,"mc":[{"id":"1.232011572","rc":[{"batb":[[0,2.16,7.28],[1,1.65,170.78],[2,1.63,143.85]],"ltp":2.2,"tv":104.45,"id":72857115}]}]}
{"op":"mcm","clk":"11877770011","pt":1724089835757,"mc":[{"id":"1.232011572","rc":[{"batb":[[0,2.18,10],[1,2.16,7.28],[2,1.65,170.78]],"ltp":2.2,"tv":104.45,"id":72857115}]}]}
{"op":"mcm","clk":"11877770404","pt":1724089839561,"mc":[{"id":"1.232011572","rc":[{"batb":[[0,2.16,7.28],[1,1.65,170.78],[2,1.63,143.85]],"ltp":2.2,"tv":104.45,"id":72857115}]}]}
{"op":"mcm","clk":"11877770666","pt":1724089841946,"mc":[{"id":"1.232011572","rc":[{"batb":[[0,2.18,10],[1,2.16,7.28],[2,1.65,170.78]],"ltp":2.2,"tv":104.45,"id":72857115}]}]}
{"op":"mcm","clk":"11877771061","pt":1724089845471,"mc":[{"id":"1.232011572","rc":[{"batb":[[0,2.16,7.28],[1,1.65,170.78],[2,1.63,143.85]],"ltp":2.2,"tv":104.45,"id":72857115}]}]}
{"op":"mcm","clk":"11877771800","pt":1724089851960,"mc":[{"id":"1.232011572","rc":[{"batb":[[0,2.18,10],[1,2.16,7.28],[2,1.65,170.78]],"ltp":2.2,"tv":104.45,"id":72857115}]}]}
{"op":"mcm","clk":"11877772171","pt":1724089855657,"mc":[{"id":"1.232011572","rc":[{"batb":[[0,2.16,7.28],[1,1.65,170.78],[2,1.63,143.85]],"ltp":2.2,"tv":104.45,"id":72857115}]}]}
{"op":"mcm","clk":"11877772463","pt":1724089858185,"mc":[{"id":"1.232011572","rc":[{"batb":[[0,2.18,10],[1,2.16,7.28],[2,1.65,170.78]],"ltp":2.2,"tv":104.45,"id":72857115}]}]}
{"op":"mcm","clk":"11877772873","pt":1724089861680,"mc":[{"id":"1.232011572","rc":[{"batb":[[0,2.16,7.28],[1,1.65,170.78],[2,1.63,143.85]],"ltp":2.2,"tv":104.45,"id":72857115}]}]}
{"op":"mcm","clk":"11877773329","pt":1724089865318,"mc":[{"id":"1.232011572","rc":[{"batb":[[0,2.18,10],[1,2.16,7.28],[2,1.65,170.78]],"ltp":2.2,"tv":104.45,"id":72857115}]}]}
{"op":"mcm","clk":"11877773698","pt":1724089868795,"mc":[{"id":"1.232011572","rc":[{"batb":[[0,2.16,7.28],[1,1.65,170.78],[2,1.63,143.85]],"ltp":2.2,"tv":104.45,"id":72857115}]}]}
{"op":"mcm","clk":"11877775109","pt":1724089878304,"mc":[{"id":"1.232011572","rc":[{"batb":[[0,2.18,10],[1,2.16,7.28],[2,1.65,170.78]],"ltp":2.2,"tv":104.45,"id":72857115}]}]}
{"op":"mcm","clk":"11877775572","pt":1724089882098,"mc":[{"id":"1.232011572","rc":[{"batb":[[0,2.16,7.28],[1,1.65,170.78],[2,1.63,143.85]],"ltp":2.2,"tv":104.45,"id":72857115}]}]}
{"op":"mcm","clk":"11877775869","pt":1724089884397,"mc":[{"id":"1.232011572","rc":[{"batb":[[0,2.18,10],[1,2.16,7.28],[2,1.65,170.78]],"ltp":2.2,"tv":104.45,"id":72857115}]}]}
{"op":"mcm","clk":"11877776247","pt":1724089888024,"mc":[{"id":"1.232011572","rc":[{"batb":[[0,2.16,7.28],[1,1.65,170.78],[2,1.63,143.85]],"ltp":2.2,"tv":104.45,"id":72857115}]}]}
{"op":"mcm","clk":"11877776682","pt":1724089891624,"mc":[{"id":"1.232011572","rc":[{"batb":[[0,2.18,10],[1,2.16,7.28],[2,1.65,170.78]],"ltp":2.2,"tv":104.45,"id":72857115}]}]}
{"op":"mcm","clk":"11877777067","pt":1724089895132,"mc":[{"id":"1.232011572","rc":[{"batb":[[0,2.16,7.28],[1,1.65,170.78],[2,1.63,143.85]],"ltp":2.2,"tv":104.45,"id":72857115}]}]}
{"op":"mcm","clk":"11877778079","pt":1724089903448,"mc":[{"id":"1.232011572","rc":[{"batb":[[0,2.18,10],[1,2.16,7.28],[2,1.65,170.78]],"ltp":2.2,"tv":104.45,"id":72857115}]}]}
{"op":"mcm","clk":"11877778495","pt":1724089907233,"mc":[{"id":"1.232011572","rc":[{"batb":[[0,2.16,7.28],[1,1.65,170.78],[2,1.63,143.85]],"ltp":2.2,"tv":104.45,"id":72857115}]}]}
{"op":"mcm","clk":"11877778840","pt":1724089910261,"mc":[{"id":"1.232011572","rc":[{"batb":[[0,2.18,10],[1,2.16,7.28],[2,1.65,170.78]],"ltp":2.2,"tv":104.45,"id":72857115}]}]}
{"op":"mcm","clk":"11877779221","pt":1724089913848,"mc":[{"id":"1.232011572","rc":[{"batb":[[0,2.16,7.28],[1,1.65,170.78],[2,1.63,143.85]],"ltp":2.2,"tv":104.45,"id":72857115}]}]}
{"op":"mcm","clk":"11877779579","pt":1724089917470,"mc":[{"id":"1.232011572","rc":[{"batb":[[0,2.18,10],[1,2.16,7.28],[2,1.65,170.78]],"ltp":2.2,"tv":104.45,"id":72857115}]}]}
{"op":"mcm","clk":"11877780013","pt":1724089921254,"mc":[{"id":"1.232011572","rc":[{"batb":[[0,2.16,7.28],[1,1.65,170.78],[2,1.63,143.85]],"ltp":2.2,"tv":104.45,"id":72857115}]}]}
{"op":"mcm","clk":"11877780368","pt":1724089924761,"mc":[{"id":"1.232011572","rc":[{"batb":[[0,2.18,10],[1,2.16,7.28],[2,1.65,170.78]],"ltp":2.2,"tv":104.45,"id":72857115}]}]}
{"op":"mcm","clk":"11877780726","pt":1724089928296,"mc":[{"id":"1.232011572","rc":[{"batb":[[0,2.16,7.28],[1,1.65,170.78],[2,1.63,143.85]],"ltp":2.2,"tv":104.45,"id":72857115}]}]}
{"op":"mcm","clk":"11877781197","pt":1724089932605,"mc":[{"id":"1.232011572","rc":[{"batb":[[0,2.18,10],[1,2.16,7.28],[2,1.65,170.78]],"ltp":2.2,"tv":104.45,"id":72857115}]}]}
{"op":"mcm","clk":"11877781635","pt":1724089936498,"mc":[{"id":"1.232011572","rc":[{"batb":[[0,2.16,7.28],[1,1.65,170.78],[2,1.63,143.85]],"ltp":2.2,"tv":104.45,"id":72857115}]}]}
{"op":"mcm","clk":"11877781980","pt":1724089939809,"mc":[{"id":"1.232011572","rc":[{"batb":[[0,2.18,10],[1,2.16,7.28],[2,1.65,170.78]],"ltp":2.2,"tv":104.45,"id":72857115}]}]}
{"op":"mcm","clk":"11877782376","pt":1724089943402,"mc":[{"id":"1.232011572","rc":[{"batb":[[0,2.16,7.28],[1,1.65,170.78],[2,1.63,143.85]],"ltp":2.2,"tv":104.45,"id":72857115}]}]}
{"op":"mcm","clk":"11877782758","pt":1724089946367,"mc":[{"id":"1.232011572","rc":[{"batb":[[0,2.18,10],[1,2.16,7.28],[2,1.65,170.78]],"ltp":2.2,"tv":104.45,"id":72857115}]}]}
{"op":"mcm","clk":"11877783162","pt":1724089950174,"mc":[{"id":"1.232011572","rc":[{"batb":[[0,2.16,7.28],[1,1.65,170.78],[2,1.63,143.85]],"ltp":2.2,"tv":104.45,"id":72857115}]}]}
{"op":"mcm","clk":"11877783797","pt":1724089956231,"mc":[{"id":"1.232011572","rc":[{"batb":[[0,2.18,10],[1,2.16,7.28],[2,1.65,170.78]],"ltp":2.2,"tv":104.45,"id":72857115}]}]}
{"op":"mcm","clk":"11877784122","pt":1724089959534,"mc":[{"id":"1.232011572","rc":[{"batb":[[0,2.16,7.28],[1,1.65,170.78],[2,1.63,143.85]],"ltp":2.2,"tv":104.45,"id":72857115}]}]}
{"op":"mcm","clk":"11877784522","pt":1724089962994,"mc":[{"id":"1.232011572","rc":[{"batb":[[0,2.18,10],[1,2.16,7.28],[2,1.65,170.78]],"ltp":2.2,"tv":104.45,"id":72857115}]}]}
{"op":"mcm","clk":"11877784898","pt":1724089966541,"mc":[{"id":"1.232011572","rc":[{"batb":[[0,2.16,7.28],[1,1.65,170.78],[2,1.63,143.85]],"ltp":2.2,"tv":104.45,"id":72857115}]}]}
{"op":"mcm","clk":"11877785156","pt":1724089968740,"mc":[{"id":"1.232011572","rc":[{"batb":[[0,2.18,10],[1,2.16,7.28],[2,1.65,170.78]],"ltp":2.2,"tv":104.45,"id":72857115}]}]}
{"op":"mcm","clk":"11877785588","pt":1724089972354,"mc":[{"id":"1.232011572","rc":[{"batb":[[0,2.16,7.28],[1,1.65,170.78],[2,1.63,143.85]],"ltp":2.2,"tv":104.45,"id":72857115}]}]}
{"op":"mcm","clk":"11877785874","pt":1724089974932,"mc":[{"id":"1.232011572","rc":[{"batb":[[0,2.18,10],[1,2.16,7.28],[2,1.65,170.78]],"ltp":2.2,"tv":104.45,"id":72857115}]}]}
{"op":"mcm","clk":"11877786293","pt":1724089978608,"mc":[{"id":"1.232011572","rc":[{"batb":[[0,2.16,7.28],[1,1.65,170.78],[2,1.63,143.85]],"ltp":2.2,"tv":104.45,"id":72857115}]}]}
{"op":"mcm","clk":"11877786542","pt":1724089980916,"mc":[{"id":"1.232011572","rc":[{"batb":[[0,2.18,10],[1,2.16,7.28],[2,1.65,170.78]],"ltp":2.2,"tv":104.45,"id":72857115}]}]}
{"op":"mcm","clk":"11877786919","pt":1724089984335,"mc":[{"id":"1.232011572","rc":[{"batb":[[0,2.16,7.28],[1,1.65,170.78],[2,1.63,143.85]],"ltp":2.2,"tv":104.45,"id":72857115}]}]}
{"op":"mcm","clk":"11877787641","pt":1724089990243,"mc":[{"id":"1.232011572","rc":[{"batb":[[0,2.18,10],[1,2.16,7.28],[2,1.65,170.78]],"ltp":2.2,"tv":104.45,"id":72857115}]}]}
{"op":"mcm","clk":"11877788012","pt":1724089993844,"mc":[{"id":"1.232011572","rc":[{"batb":[[0,2.16,7.28],[1,1.65,170.78],[2,1.63,143.85]],"ltp":2.2,"tv":104.45,"id":72857115}]}]}
{"op":"mcm","clk":"11877788777","pt":1724090001080,"mc":[{"id":"1.232011572","rc":[{"batb":[[0,2.18,10],[1,2.16,7.28],[2,1.65,170.78]],"ltp":2.2,"tv":104.45,"id":72857115}]}]}
{"op":"mcm","clk":"11877789167","pt":1724090004576,"mc":[{"id":"1.232011572","rc":[{"batb":[[0,2.16,7.28],[1,1.65,170.78],[2,1.63,143.85]],"ltp":2.2,"tv":104.45,"id":72857115}]}]}
{"op":"mcm","clk":"11877789551","pt":1724090007571,"mc":[{"id":"1.232011572","rc":[{"batb":[[0,2.18,10],[1,2.16,7.28],[2,1.65,170.78]],"ltp":2.2,"tv":104.45,"id":72857115}]}]}
{"op":"mcm","clk":"11877790079","pt":1724090011255,"mc":[{"id":"1.232011572","rc":[{"batb":[[0,2.16,7.28],[1,1.65,170.78],[2,1.63,143.85]],"ltp":2.2,"tv":104.45,"id":72857115}]}]}
{"op":"mcm","clk":"11877790625","pt":1724090013965,"mc":[{"id":"1.232011572","rc":[{"batb":[[0,2.18,10],[1,2.16,7.28],[2,1.65,170.78]],"ltp":2.2,"tv":104.45,"id":72857115}]}]}
{"op":"mcm","clk":"11877791042","pt":1724090017458,"mc":[{"id":"1.232011572","rc":[{"batb":[[0,2.16,7.28],[1,1.65,170.78],[2,1.63,143.85]],"ltp":2.2,"tv":104.45,"id":72857115}]}]}
{"op":"mcm","clk":"11877791311","pt":1724090019845,"mc":[{"id":"1.232011572","rc":[{"batb":[[0,2.18,10],[1,2.16,7.28],[2,1.65,170.78]],"ltp":2.2,"tv":104.45,"id":72857115}]}]}
{"op":"mcm","clk":"11877791727","pt":1724090023790,"mc":[{"id":"1.232011572","rc":[{"batb":[[0,2.16,7.28],[1,1.65,170.78],[2,1.63,143.85]],"ltp":2.2,"tv":104.45,"id":72857115}]}]}
{"op":"mcm","clk":"11877795790","pt":1724090064056,"mc":[{"id":"1.232011572","rc":[{"batb":[[0,1.67,5.7],[1,1.66,4.48],[2,1.63,4.48]],"ltp":1.82,"tv":77.83,"id":72857117}]}]}
{"op":"mcm","clk":"11877833579","pt":1724090400890,"mc":[{"id":"1.232011572","rc":[{"batb":[[0,2.18,10],[1,2.16,7.28],[2,1.65,170.78]],"ltp":2.2,"tv":104.45,"id":72857115}]}]}
{"op":"mcm","clk":"11877834108","pt":1724090404963,"mc":[{"id":"1.232011572","rc":[{"trd":[[1.12,4.83],[1.18,3.08],[1.2,8.86],[1.21,5.63],[1.25,4.62],[1.31,3.58],[1.32,2.31],[1.37,3.08],[1.41,8.9],[1.45,2.31],[1.5,2.31],[1.51,3.46],[1.54,2.31],[1.61,4.65],[1.67,5.55],[1.69,3.88],[2,8],[2.16,2.57],[2.2,7.21],[2.54,1.07],[3.95,2.04]],"batb":[[0,2.16,7.28],[1,1.65,170.7],[2,1.63,143.85]],"ltp":2.2,"tv":104.41,"id":72857115},{"trd":[[1.2,4.62],[1.34,6.01],[1.35,4.62],[1.82,2.91],[1.86,7.2],[1.87,26.77],[1.88,8],[2.98,3.3]],"batb":[[0,1.67,5.69],[1,1.66,4.47],[2,1.63,4.47]],"batl":[[0,1.86,5.46],[1,2,4.47],[2,2.3,4.47]],"ltp":1.82,"tv":77.79,"id":72857117}],"tv":182.21}]}
{"op":"mcm","clk":"11877834737","pt":1724090409699,"mc":[{"id":"1.232011572","rc":[{"batb":[[0,2.18,10],[1,2.16,7.28],[2,1.65,170.7]],"ltp":2.2,"tv":104.41,"id":72857115}]}]}
{"op":"mcm","clk":"11877835191","pt":1724090413307,"mc":[{"id":"1.232011572","rc":[{"batb":[[0,2.16,7.28],[1,1.65,170.7],[2,1.63,143.85]],"ltp":2.2,"tv":104.41,"id":72857115}]}]}
{"op":"mcm","clk":"11877835695","pt":1724090417007,"mc":[{"id":"1.232011572","rc":[{"batb":[[0,2.18,10],[1,2.16,7.28],[2,1.65,170.7]],"ltp":2.2,"tv":104.41,"id":72857115}]}]}
{"op":"mcm","clk":"11877836179","pt":1724090420611,"mc":[{"id":"1.232011572","rc":[{"batb":[[0,2.16,7.28],[1,1.65,170.7],[2,1.63,143.85]],"ltp":2.2,"tv":104.41,"id":72857115}]}]}
{"op":"mcm","clk":"11877836798","pt":1724090425720,"mc":[{"id":"1.232011572","rc":[{"batb":[[0,2.18,10],[1,2.16,7.28],[2,1.65,170.7]],"ltp":2.2,"tv":104.41,"id":72857115}]}]}
{"op":"mcm","clk":"11877837195","pt":1724090428909,"mc":[{"id":"1.232011572","rc":[{"batb":[[0,2.16,7.28],[1,1.65,170.7],[2,1.63,143.85]],"ltp":2.2,"tv":104.41,"id":72857115}]}]}
{"op":"mcm","clk":"11877837734","pt":1724090433423,"mc":[{"id":"1.232011572","rc":[{"batb":[[0,2.18,10],[1,2.16,7.28],[2,1.65,170.7]],"ltp":2.2,"tv":104.41,"id":72857115}]}]}
{"op":"mcm","clk":"11877838157","pt":1724090436909,"mc":[{"id":"1.232011572","rc":[{"batb":[[0,2.16,7.28],[1,1.65,170.7],[2,1.63,143.85]],"ltp":2.2,"tv":104.41,"id":72857115}]}]}
{"op":"mcm","clk":"11877838639","pt":1724090440946,"mc":[{"id":"1.232011572","rc":[{"batb":[[0,2.18,10],[1,2.16,7.28],[2,1.65,170.7]],"ltp":2.2,"tv":104.41,"id":72857115}]}]}
{"op":"mcm","clk":"11877838883","pt":1724090442824,"mc":[{"id":"1.232011572","rc":[{"trd":[[2.18,17.9]],"batb":[[0,2.18,1.05]],"ltp":2.18,"tv":122.31,"id":72857115}],"tv":200.11}]}
{"op":"mcm","clk":"11877839093","pt":1724090444329,"mc":[{"id":"1.232011572","rc":[{"batb":[[0,2.16,7.28],[1,1.65,170.7],[2,1.63,143.85]],"ltp":2.18,"tv":122.31,"id":72857115}]}]}
{"op":"mcm","clk":"11877839404","pt":1724090446925,"mc":[{"id":"1.232011572","rc":[{"batb":[[0,2.18,10],[1,2.16,7.28],[2,1.65,170.7]],"ltp":2.18,"tv":122.31,"id":72857115}]}]}
