{"op":"mcm","clk":"11754684531","pt":1722423340276,"mc":[{"id":"1.231283997","marketDefinition":{"bspMarket":false,"turnInPlayEnabled":true,"persistenceEnabled":true,"marketBaseRate":5.0,"eventId":"33458074","eventTypeId":"4","numberOfWinners":1,"bettingType":"ODDS","marketType":"MATCH_ODDS","marketTime":"2024-08-02T10:00:00.000Z","suspendTime":"2024-08-02T10:00:00.000Z","bspReconciled":false,"complete":true,"inPlay":false,"crossMatching":false,"runnersVoidable":false,"numberOfActiveRunners":2,"betDelay":0,"status":"OPEN","runners":[{"status":"ACTIVE","sortPriority":1,"id":169,"name":"Glamorgan"},{"status":"ACTIVE","sortPriority":2,"id":31379,"name":"Sussex"}],"regulators":["MR_INT"],"countryCode":"GB","discountAllowed":false,"timezone":"GMT","openDate":"2024-08-02T10:00:00.000Z","version":6048600906,"name":"Match Odds","eventName":"Glamorgan v Sussex"},"rc":[{"batb":[[0,1.03,200],[1,1.02,200],[2,1.01,220]],"ltp":0.0,"tv":0.0,"id":31379},{"batb":[[0,1.03,200],[1,1.02,200],[2,1.01,220]],"ltp":0.0,"tv":0.0,"id":169}]}]}
{"op":"mcm","clk":"11754684637","pt":1722423341400,"mc":[{"id":"1.231283997","marketDefinition":{"bspMarket":false,"turnInPlayEnabled":true,"persistenceEnabled":true,"marketBaseRate":5.0,"eventId":"33458074","eventTypeId":"4","numberOfWinners":1,"bettingType":"ODDS","marketType":"MATCH_ODDS","marketTime":"2024-08-02T10:00:00.000Z","suspendTime":"2024-08-02T10:00:00.000Z","bspReconciled":false,"complete":true,"inPlay":false,"crossMatching":false,"runnersVoidable":false,"numberOfActiveRunners":2,"betDelay":0,"status":"OPEN","runners":[{"status":"ACTIVE","sortPriority":1,"id":169,"name":"Glamorgan"},{"status":"ACTIVE","sortPriority":2,"id":31379,"name":"Sussex"}],"regulators":["MR_INT"],"countryCode":"GB","discountAllowed":true,"timezone":"GMT","openDate":"2024-08-02T10:00:00.000Z","version":6048600906,"name":"Match Odds","eventName":"Glamorgan v Sussex"}}]}
{"op":"mcm","clk":"11755673924","pt":1722436320365,"mc":[{"id":"1.231283997","rc":[{"batb":[[0,1.12,7.66],[1,1.03,200],[2,1.02,200]],"ltp":0.0,"tv":0.0,"id":169}]}]}
{"op":"mcm","clk":"11755674953","pt":1722436334359,"mc":[{"id":"1.231283997","rc":[{"batb":[[0,1.18,8.75],[1,1.03,200],[2,1.02,200]],"ltp":0.0,"tv":0.0,"id":31379}]}]}
{"op":"mcm","clk":"11756582571","pt":1722444175077,"mc":[{"id":"1.231283997","rc":[{"batb":[[0,1.18,8.75]],"ltp":0.0,"tv":0.0,"id":31379}]}]}
{"op":"mcm","clk":"11756785880","pt":1722446034294,"mc":[{"id":"1.231283997","rc":[{"batb":[[0,1.28,178.57],[1,1.23,217.39],[2,1.18,286.53]],"ltp":0.0,"tv":0.0,"id":31379},{"batb":[[0,1.33,151.52],[1,1.28,178.57],[2,1.23,217.39]],"ltp":0.0,"tv":0.0,"id":169}]}]}
{"op":"mcm","clk":"11756785923","pt":1722446034709,"mc":[{"id":"1.231283997","rc":[{"batb":[[0,1.43,116.28],[1,1.38,131.58],[2,1.33,151.52]],"ltp":0.0,"tv":0.0,"id":31379},{"batb":[[0,1.43,116.28],[1,1.38,131.58],[2,1.33,151.52]],"ltp":0.0,"tv":0.0,"id":169}]}]}
{"op":"mcm","clk":"11756787376","pt":1722446047020,"mc":[{"id":"1.231283997","marketDefinition":{"bspMarket":false,"turnInPlayEnabled":true,"persistenceEnabled":true,"marketBaseRate":5.0,"eventId":"33458074","eventTypeId":"4","numberOfWinners":1,"bettingType":"ODDS","marketType":"MATCH_ODDS","marketTime":"2024-08-02T10:00:00.000Z","suspendTime":"2024-08-02T10:00:00.000Z","bspReconciled":false,"complete":true,"inPlay":false,"crossMatching":true,"runnersVoidable":false,"numberOfActiveRunners":2,"betDelay":0,"status":"OPEN","runners":[{"status":"ACTIVE","sortPriority":1,"id":169,"name":"Glamorgan"},{"status":"ACTIVE","sortPriority":2,"id":31379,"name":"Sussex"}],"regulators":["MR_INT"],"countryCode":"GB","discountAllowed":true,"timezone":"GMT","openDate":"2024-08-02T10:00:00.000Z","version":6048600906,"name":"Match Odds","eventName":"Glamorgan v Sussex"}}]}
{"op":"mcm","clk":"11756872337","pt":1722446798767,"mc":[{"id":"1.231283997","rc":[{"batb":[[0,3,18.48],[1,1.43,116.28],[2,1.38,131.58]],"ltp":0.0,"tv":0.0,"id":31379},{"batb":[[0,1.43,202.24]],"ltp":0.0,"tv":0.0,"id":169}]}]}
{"op":"mcm","clk":"11756941766","pt":1722447385917,"mc":[{"id":"1.231283997","rc":[{"batb":[[0,1.44,9.93],[1,1.43,202.24],[2,1.38,131.58]],"ltp":0.0,"tv":0.0,"id":169}]}]}
{"op":"mcm","clk":"11757000724","pt":1722447918960,"mc":[{"id":"1.231283997","rc":[{"trd":[[3,0.04]],"batb":[[0,3,18.44]],"ltp":3.0,"tv":0.04,"id":31379},{"trd":[[1.5,0.07]],"ltp":1.5,"tv":0.07,"id":169}],"tv":0.11}]}
{"op":"mcm","clk":"11757000826","pt":1722447919863,"mc":[{"id":"1.231283997","rc":[{"batl":[[0,3.3,4.45]],"ltp":3.0,"tv":0.04,"id":31379}]}]}
{"op":"mcm","clk":"11757001238","pt":1722447923151,"mc":[{"id":"1.231283997","rc":[{"batb":[[0,3,18.48]],"ltp":3.0,"tv":0.04,"id":31379}]}]}
{"op":"mcm","clk":"11757140226","pt":1722449186126,"mc":[{"id":"1.231283997","rc":[{"batb":[[0,1.43,116.28],[1,1.38,131.58],[2,1.33,151.52]],"batl":[[0,3.3,4.46]],"ltp":3.0,"tv":0.04,"id":31379},{"batb":[[0,1.44,9.93],[1,1.43,116.28]],"ltp":1.5,"tv":0.07,"id":169}]}]}
{"op":"mcm","clk":"11757140508","pt":1722449187888,"mc":[{"id":"1.231283997","rc":[{"batb":[[0,3,18.48],[1,1.44,5.71],[2,1.43,116.28]],"ltp":3.0,"tv":0.04,"id":31379},{"batb":[[1,1.43,202.24]],"ltp":1.5,"tv":0.07,"id":169}]}]}
{"op":"mcm","clk":"11757141317","pt":1722449193294,"mc":[{"id":"1.231283997","rc":[{"batb":[[1,1.43,116.28],[2,1.38,131.58]],"batl":[[0,3.3,4.45]],"ltp":3.0,"tv":0.04,"id":31379}]}]}
{"op":"mcm","clk":"11757296972","pt":1722450327835,"mc":[{"id":"1.231283997","rc":[{"trd":[[3,0.08]],"batb":[[0,3,18.44]],"ltp":3.0,"tv":0.08,"id":31379},{"trd":[[1.5,0.14]],"ltp":1.5,"tv":0.14,"id":169}],"tv":0.22}]}
{"op":"mcm","clk":"11757297524","pt":1722450332333,"mc":[{"id":"1.231283997","rc":[{"batb":[[0,3,36.92]],"ltp":3.0,"tv":0.08,"id":31379}]}]}
{"op":"mcm","clk":"11757297538","pt":1722450332444,"mc":[{"id":"1.231283997","rc":[{"batb":[[0,3,18.48]],"ltp":3.0,"tv":0.08,"id":31379}]}]}
{"op":"mcm","clk":"11757458497","pt":1722451519662,"mc":[{"id":"1.231283997","rc":[{"trd":[[3,0.12]],"batb":[[0,3,18.44]],"ltp":3.0,"tv":0.12,"id":31379},{"trd":[[1.5,0.21]],"ltp":1.5,"tv":0.21,"id":169}],"tv":0.33}]}
{"op":"mcm","clk":"11757458839","pt":1722451522137,"mc":[{"id":"1.231283997","rc":[{"batb":[[0,3,18.48]],"ltp":3.0,"tv":0.12,"id":31379}]}]}
{"op":"mcm","clk":"11757581540","pt":1722452469374,"mc":[{"id":"1.231283997","rc":[{"batb":[[0,1.43,116.28],[1,1.38,131.58],[2,1.33,151.52]],"batl":[[0,3.3,4.45]],"ltp":3.0,"tv":0.12,"id":31379},{"batb":[[0,1.44,9.93],[1,1.43,116.28]],"ltp":1.5,"tv":0.21,"id":169}]}]}
{"op":"mcm","clk":"11757584118","pt":1722452487566,"mc":[{"id":"1.231283997","rc":[{"batb":[[0,1.44,5.71],[1,1.43,116.28],[2,1.38,131.58]],"ltp":3.0,"tv":0.12,"id":31379}]}]}
{"op":"mcm","clk":"11757744406","pt":1722453656023,"mc":[{"id":"1.231283997","rc":[{"batb":[[0,1.44,11.99]],"ltp":3.0,"tv":0.12,"id":31379},{"batb":[[0,1.44,16.03]],"ltp":1.5,"tv":0.21,"id":169}]}]}
{"op":"mcm","clk":"11757888548","pt":1722454689959,"mc":[{"id":"1.231283997","rc":[{"batb":[[0,3,18.48],[1,1.44,11.99],[2,1.43,116.28]],"ltp":3.0,"tv":0.12,"id":31379},{"batb":[[1,1.43,202.24]],"ltp":1.5,"tv":0.21,"id":169}]}]}
{"op":"mcm","clk":"11757889256","pt":1722454694371,"mc":[{"id":"1.231283997","rc":[{"batb":[[1,1.44,6.28]],"ltp":3.0,"tv":0.12,"id":31379}]}]}
{"op":"mcm","clk":"11757889270","pt":1722454694431,"mc":[{"id":"1.231283997","rc":[{"batl":[[0,3.3,4.58]],"ltp":3.0,"tv":0.12,"id":31379}]}]}
{"op":"mcm","clk":"11757955686","pt":1722455134739,"mc":[{"id":"1.231283997","rc":[{"trd":[[3,0.16]],"batb":[[0,3,18.44]],"ltp":3.0,"tv":0.16,"id":31379},{"trd":[[1.5,0.28]],"ltp":1.5,"tv":0.28,"id":169}],"tv":0.44}]}
{"op":"mcm","clk":"11757955999","pt":1722455137092,"mc":[{"id":"1.231283997","rc":[{"batb":[[0,3,18.48]],"ltp":3.0,"tv":0.16,"id":31379}]}]}
{"op":"mcm","clk":"11758011399","pt":1722455604064,"mc":[{"id":"1.231283997","rc":[{"batb":[[0,1.44,9.93]],"ltp":1.5,"tv":0.28,"id":169}]}]}
{"op":"mcm","clk":"11758011441","pt":1722455604474,"mc":[{"id":"1.231283997","rc":[{"batb":[[1,1.43,116.28],[2,1.38,131.58]],"ltp":3.0,"tv":0.16,"id":31379}]}]}
{"op":"mcm","clk":"11758280685","pt":1722458720245,"mc":[{"id":"1.231283997","rc":[{"trd":[[3,0.2]],"batl":[[0,3.3,4.58]],"ltp":3.0,"tv":0.2,"id":31379},{"trd":[[1.5,0.35]],"batb":[[0,1.44,9.93]],"ltp":1.5,"tv":0.35,"id":169}],"tv":0.55}]}
{"op":"mcm","clk":"11758346684","pt":1722459918661,"mc":[{"id":"1.231283997","rc":[{"trd":[[3,0.24]],"batb":[[0,3,18.44]],"batl":[[0,3.3,4.58]],"ltp":3.0,"tv":0.24,"id":31379},{"trd":[[1.5,0.42]],"batb":[[0,1.44,9.93]],"ltp":1.5,"tv":0.42,"id":169}],"tv":0.66}]}
{"op":"mcm","clk":"11758346736","pt":1722459919740,"mc":[{"id":"1.231283997","rc":[{"batb":[[0,3,18.48]],"ltp":3.0,"tv":0.24,"id":31379}]}]}
{"op":"mcm","clk":"11758390088","pt":1722461117625,"mc":[{"id":"1.231283997","rc":[{"trd":[[3,0.28]],"batb":[[0,3,18.44]],"ltp":3.0,"tv":0.28,"id":31379},{"trd":[[1.5,0.49]],"ltp":1.5,"tv":0.49,"id":169}],"tv":0.77}]}
{"op":"mcm","clk":"11758390139","pt":1722461119117,"mc":[{"id":"1.231283997","rc":[{"batb":[[0,3,18.48]],"ltp":3.0,"tv":0.28,"id":31379}]}]}
{"op":"mcm","clk":"11758424216","pt":1722462318774,"mc":[{"id":"1.231283997","rc":[{"trd":[[3,0.32]],"batb":[[0,3,18.44]],"ltp":3.0,"tv":0.32,"id":31379},{"trd":[[1.5,0.56]],"ltp":1.5,"tv":0.56,"id":169}],"tv":0.88}]}
{"op":"mcm","clk":"11758424397","pt":1722462323701,"mc":[{"id":"1.231283997","rc":[{"batb":[[0,3,18.48]],"ltp":3.0,"tv":0.32,"id":31379}]}]}
{"op":"mcm","clk":"11758460430","pt":1722463518583,"mc":[{"id":"1.231283997","rc":[{"trd":[[3,0.36]],"batb":[[0,3,18.44]],"ltp":3.0,"tv":0.36,"id":31379},{"trd":[[1.5,0.63]],"batb":[[0,1.44,9.93]],"ltp":1.5,"tv":0.63,"id":169}],"tv":0.99}]}
{"op":"mcm","clk":"11758460596","pt":1722463523572,"mc":[{"id":"1.231283997","rc":[{"batb":[[0,3,18.48]],"ltp":3.0,"tv":0.36,"id":31379}]}]}
{"op":"mcm","clk":"11758509292","pt":1722464719542,"mc":[{"id":"1.231283997","rc":[{"trd":[[3,0.4]],"batb":[[0,3,18.44]],"ltp":3.0,"tv":0.4,"id":31379},{"trd":[[1.5,0.7]],"ltp":1.5,"tv":0.7,"id":169}],"tv":1.1}]}
{"op":"mcm","clk":"11758509437","pt":1722464723147,"mc":[{"id":"1.231283997","rc":[{"batb":[[0,3,18.48]],"ltp":3.0,"tv":0.4,"id":31379}]}]}
{"op":"mcm","clk":"11758619107","pt":1722467128423,"mc":[{"id":"1.231283997","rc":[{"trd":[[3,0.44]],"batb":[[0,3,18.44]],"ltp":3.0,"tv":0.44,"id":31379},{"trd":[[1.5,0.77]],"batb":[[0,1.44,9.93]],"ltp":1.5,"tv":0.77,"id":169}],"tv":1.21}]}
{"op":"mcm","clk":"11758619342","pt":1722467133365,"mc":[{"id":"1.231283997","rc":[{"batb":[[0,3,18.48]],"ltp":3.0,"tv":0.44,"id":31379}]}]}
{"op":"mcm","clk":"11758684562","pt":1722468318487,"mc":[{"id":"1.231283997","rc":[{"trd":[[3,0.48]],"batb":[[0,3,18.44]],"ltp":3.0,"tv":0.48,"id":31379},{"trd":[[1.5,0.84]],"ltp":1.5,"tv":0.84,"id":169}],"tv":1.32}]}
{"op":"mcm","clk":"11758684851","pt":1722468322667,"mc":[{"id":"1.231283997","rc":[{"batb":[[0,3,18.48]],"ltp":3.0,"tv":0.48,"id":31379}]}]}
{"op":"mcm","clk":"11758758481","pt":1722469517884,"mc":[{"id":"1.231283997","rc":[{"trd":[[3,0.52]],"batb":[[0,3,18.44]],"ltp":3.0,"tv":0.52,"id":31379},{"trd":[[1.5,0.91]],"ltp":1.5,"tv":0.91,"id":169}],"tv":1.43}]}
{"op":"mcm","clk":"11758758821","pt":1722469522887,"mc":[{"id":"1.231283997","rc":[{"batb":[[0,3,18.48]],"ltp":3.0,"tv":0.52,"id":31379}]}]}
{"op":"mcm","clk":"11758836508","pt":1722470719212,"mc":[{"id":"1.231283997","rc":[{"trd":[[3,0.56]],"batb":[[0,3,18.44]],"batl":[[0,3.3,4.58]],"ltp":3.0,"tv":0.56,"id":31379},{"trd":[[1.5,0.98]],"batb":[[0,1.44,9.93]],"ltp":1.5,"tv":0.98,"id":169}],"tv":1.54}]}
{"op":"mcm","clk":"11758836717","pt":1722470722923,"mc":[{"id":"1.231283997","rc":[{"batb":[[0,3,18.48]],"ltp":3.0,"tv":0.56,"id":31379}]}]}
{"op":"mcm","clk":"11758930871","pt":1722471918991,"mc":[{"id":"1.231283997","rc":[{"trd":[[3,0.6]],"batb":[[0,3,18.44]],"ltp":3.0,"tv":0.6,"id":31379},{"trd":[[1.5,1.05]],"ltp":1.5,"tv":1.05,"id":169}],"tv":1.65}]}
{"op":"mcm","clk":"11758931057","pt":1722471922290,"mc":[{"id":"1.231283997","rc":[{"batb":[[0,3,18.48]],"ltp":3.0,"tv":0.6,"id":31379}]}]}
{"op":"mcm","clk":"11759017977","pt":1722473119425,"mc":[{"id":"1.231283997","rc":[{"trd":[[3,0.64]],"batb":[[0,3,18.44]],"ltp":3.0,"tv":0.64,"id":31379},{"trd":[[1.5,1.12]],"ltp":1.5,"tv":1.12,"id":169}],"tv":1.76}]}
{"op":"mcm","clk":"11759018215","pt":1722473122107,"mc":[{"id":"1.231283997","rc":[{"batb":[[0,3,18.48]],"ltp":3.0,"tv":0.64,"id":31379}]}]}
{"op":"mcm","clk":"11759103967","pt":1722474320087,"mc":[{"id":"1.231283997","rc":[{"trd":[[3,0.68]],"batb":[[0,3,18.44]],"ltp":3.0,"tv":0.68,"id":31379},{"trd":[[1.5,1.19]],"batb":[[0,1.44,9.93]],"ltp":1.5,"tv":1.19,"id":169}],"tv":1.87}]}
{"op":"mcm","clk":"11759104077","pt":1722474321382,"mc":[{"id":"1.231283997","rc":[{"batb":[[0,3,36.92]],"ltp":3.0,"tv":0.68,"id":31379}]}]}
{"op":"mcm","clk":"11759104085","pt":1722474321484,"mc":[{"id":"1.231283997","rc":[{"batb":[[0,3,18.48]],"ltp":3.0,"tv":0.68,"id":31379}]}]}
{"op":"mcm","clk":"11759196457","pt":1722475519656,"mc":[{"id":"1.231283997","rc":[{"trd":[[3,0.72]],"batb":[[0,3,18.44]],"ltp":3.0,"tv":0.72,"id":31379},{"trd":[[1.5,1.26]],"ltp":1.5,"tv":1.26,"id":169}],"tv":1.98}]}
{"op":"mcm","clk":"11759196522","pt":1722475520680,"mc":[{"id":"1.231283997","rc":[{"batb":[[0,3,18.48]],"ltp":3.0,"tv":0.72,"id":31379}]}]}
{"op":"mcm","clk":"11759288126","pt":1722476718934,"mc":[{"id":"1.231283997","rc":[{"trd":[[3,0.76]],"batb":[[0,3,18.44]],"ltp":3.0,"tv":0.76,"id":31379},{"trd":[[1.5,1.33]],"ltp":1.5,"tv":1.33,"id":169}],"tv":2.09}]}
{"op":"mcm","clk":"11759288220","pt":1722476720041,"mc":[{"id":"1.231283997","rc":[{"batb":[[0,3,18.48]],"ltp":3.0,"tv":0.76,"id":31379}]}]}
{"op":"mcm","clk":"11759376975","pt":1722477918762,"mc":[{"id":"1.231283997","rc":[{"trd":[[3,0.8]],"batb":[[0,3,18.44]],"ltp":3.0,"tv":0.8,"id":31379},{"trd":[[1.5,1.4]],"ltp":1.5,"tv":1.4,"id":169}],"tv":2.2}]}
{"op":"mcm","clk":"11759377030","pt":1722477919857,"mc":[{"id":"1.231283997","rc":[{"batb":[[0,3,18.48]],"ltp":3.0,"tv":0.8,"id":31379}]}]}
{"op":"mcm","clk":"11759465529","pt":1722479118601,"mc":[{"id":"1.231283997","rc":[{"trd":[[3,0.84]],"batb":[[0,3,18.44]],"ltp":3.0,"tv":0.84,"id":31379},{"trd":[[1.5,1.47]],"ltp":1.5,"tv":1.47,"id":169}],"tv":2.31}]}
{"op":"mcm","clk":"11759465633","pt":1722479119983,"mc":[{"id":"1.231283997","rc":[{"batb":[[0,3,18.48]],"ltp":3.0,"tv":0.84,"id":31379}]}]}
{"op":"mcm","clk":"11759550653","pt":1722480319173,"mc":[{"id":"1.231283997","rc":[{"trd":[[3,0.88]],"batb":[[0,3,18.44]],"ltp":3.0,"tv":0.88,"id":31379},{"trd":[[1.5,1.54]],"ltp":1.5,"tv":1.54,"id":169}],"tv":2.42}]}
{"op":"mcm","clk":"11759550726","pt":1722480320147,"mc":[{"id":"1.231283997","rc":[{"batb":[[0,3,18.48]],"ltp":3.0,"tv":0.88,"id":31379}]}]}
{"op":"mcm","clk":"11759628317","pt":1722481520752,"mc":[{"id":"1.231283997","rc":[{"trd":[[3,0.92]],"batb":[[0,3,18.44]],"ltp":3.0,"tv":0.92,"id":31379},{"trd":[[1.5,1.61]],"ltp":1.5,"tv":1.61,"id":169}],"tv":2.53}]}
{"op":"mcm","clk":"11759628537","pt":1722481524759,"mc":[{"id":"1.231283997","rc":[{"batb":[[0,3,18.48]],"ltp":3.0,"tv":0.92,"id":31379}]}]}
{"op":"mcm","clk":"11759697060","pt":1722482718583,"mc":[{"id":"1.231283997","rc":[{"trd":[[3,0.96]],"batb":[[0,3,18.44]],"ltp":3.0,"tv":0.96,"id":31379},{"trd":[[1.5,1.68]],"ltp":1.5,"tv":1.68,"id":169}],"tv":2.64}]}
{"op":"mcm","clk":"11759697150","pt":1722482720058,"mc":[{"id":"1.231283997","rc":[{"batb":[[0,3,18.48]],"ltp":3.0,"tv":0.96,"id":31379}]}]}
{"op":"mcm","clk":"11759754769","pt":1722483919208,"mc":[{"id":"1.231283997","rc":[{"trd":[[3,1]],"batb":[[0,3,18.44]],"ltp":3.0,"tv":1.0,"id":31379},{"trd":[[1.5,1.75]],"ltp":1.5,"tv":1.75,"id":169}],"tv":2.75}]}
{"op":"mcm","clk":"11759754779","pt":1722483919822,"mc":[{"id":"1.231283997","rc":[{"batb":[[0,3,18.48]],"ltp":3.0,"tv":1.0,"id":31379}]}]}
{"op":"mcm","clk":"11759791725","pt":1722485118757,"mc":[{"id":"1.231283997","rc":[{"trd":[[3,1.04]],"batb":[[0,3,18.44]],"batl":[[0,3.3,4.58]],"ltp":3.0,"tv":1.04,"id":31379},{"trd":[[1.5,1.82]],"batb":[[0,1.44,9.94]],"ltp":1.5,"tv":1.82,"id":169}],"tv":2.86}]}
{"op":"mcm","clk":"11759791790","pt":1722485120391,"mc":[{"id":"1.231283997","rc":[{"batb":[[0,3,36.92]],"ltp":3.0,"tv":1.04,"id":31379}]}]}
{"op":"mcm","clk":"11759791794","pt":1722485120493,"mc":[{"id":"1.231283997","rc":[{"batb":[[0,3,18.48]],"ltp":3.0,"tv":1.04,"id":31379}]}]}
{"op":"mcm","clk":"11759825292","pt":1722486320439,"mc":[{"id":"1.231283997","rc":[{"trd":[[3,1.08]],"batb":[[0,3,18.44]],"ltp":3.0,"tv":1.08,"id":31379},{"trd":[[1.5,1.89]],"ltp":1.5,"tv":1.89,"id":169}],"tv":2.97}]}
{"op":"mcm","clk":"11759825371","pt":1722486325310,"mc":[{"id":"1.231283997","rc":[{"batb":[[0,3,36.92]],"ltp":3.0,"tv":1.08,"id":31379}]}]}
{"op":"mcm","clk":"11759825372","pt":1722486325413,"mc":[{"id":"1.231283997","rc":[{"batb":[[0,3,18.48]],"ltp":3.0,"tv":1.08,"id":31379}]}]}
{"op":"mcm","clk":"11759864865","pt":1722487520221,"mc":[{"id":"1.231283997","rc":[{"trd":[[3,1.12]],"ltp":3.0,"tv":1.12,"id":31379},{"trd":[[1.5,1.96]],"ltp":1.5,"tv":1.96,"id":169}],"tv":3.08}]}
{"op":"mcm","clk":"11759903042","pt":1722488718444,"mc":[{"id":"1.231283997","rc":[{"trd":[[3,1.16]],"batb":[[0,3,18.44]],"batl":[[0,3.3,4.58]],"ltp":3.0,"tv":1.16,"id":31379},{"trd":[[1.5,2.03]],"batb":[[0,1.44,9.93]],"ltp":1.5,"tv":2.03,"id":169}],"tv":3.19}]}
{"op":"mcm","clk":"11759903108","pt":1722488720244,"mc":[{"id":"1.231283997","rc":[{"batb":[[0,3,18.48]],"ltp":3.0,"tv":1.16,"id":31379}]}]}
{"op":"mcm","clk":"11759940737","pt":1722489919350,"mc":[{"id":"1.231283997","rc":[{"trd":[[3,1.2]],"ltp":3.0,"tv":1.2,"id":31379},{"trd":[[1.5,2.1]],"ltp":1.5,"tv":2.1,"id":169}],"tv":3.3}]}
{"op":"mcm","clk":"11759981101","pt":1722491120450,"mc":[{"id":"1.231283997","rc":[{"trd":[[3,1.24]],"batb":[[0,3,18.44]],"ltp":3.0,"tv":1.24,"id":31379},{"trd":[[1.5,2.17]],"ltp":1.5,"tv":2.17,"id":169}],"tv":3.41}]}
{"op":"mcm","clk":"11759981215","pt":1722491123960,"mc":[{"id":"1.231283997","rc":[{"batb":[[0,3,18.48]],"ltp":3.0,"tv":1.24,"id":31379}]}]}
{"op":"mcm","clk":"11760017745","pt":1722492323113,"mc":[{"id":"1.231283997","rc":[{"trd":[[3,1.28]],"ltp":3.0,"tv":1.28,"id":31379},{"trd":[[1.5,2.24]],"batb":[[0,1.44,9.94]],"ltp":1.5,"tv":2.24,"id":169}],"tv":3.52}]}
{"op":"mcm","clk":"11760065838","pt":1722493518651,"mc":[{"id":"1.231283997","rc":[{"trd":[[3,1.32]],"batb":[[0,3,18.44]],"ltp":3.0,"tv":1.32,"id":31379},{"trd":[[1.5,2.31]],"ltp":1.5,"tv":2.31,"id":169}],"tv":3.63}]}
{"op":"mcm","clk":"11760065966","pt":1722493523519,"mc":[{"id":"1.231283997","rc":[{"batb":[[0,3,18.48]],"ltp":3.0,"tv":1.32,"id":31379}]}]}
{"op":"mcm","clk":"11760111719","pt":1722494718996,"mc":[{"id":"1.231283997","rc":[{"trd":[[3,1.36]],"batb":[[0,3,18.44]],"ltp":3.0,"tv":1.36,"id":31379},{"trd":[[1.5,2.38]],"ltp":1.5,"tv":2.38,"id":169}],"tv":3.74}]}
{"op":"mcm","clk":"11760111972","pt":1722494723983,"mc":[{"id":"1.231283997","rc":[{"batb":[[0,3,18.48]],"ltp":3.0,"tv":1.36,"id":31379}]}]}
{"op":"mcm","clk":"11760159305","pt":1722495920209,"mc":[{"id":"1.231283997","rc":[{"trd":[[3,1.4]],"batl":[[0,3.3,4.59]],"ltp":3.0,"tv":1.4,"id":31379},{"trd":[[1.5,2.45]],"batb":[[0,1.44,9.96]],"ltp":1.5,"tv":2.45,"id":169}],"tv":3.85}]}
{"op":"mcm","clk":"11760216299","pt":1722497120079,"mc":[{"id":"1.231283997","rc":[{"trd":[[3,1.44]],"batb":[[0,3,18.44]],"ltp":3.0,"tv":1.44,"id":31379},{"trd":[[1.5,2.52]],"ltp":1.5,"tv":2.52,"id":169}],"tv":3.96}]}
{"op":"mcm","clk":"11760216565","pt":1722497125267,"mc":[{"id":"1.231283997","rc":[{"batb":[[0,3,18.48]],"ltp":3.0,"tv":1.44,"id":31379}]}]}
{"op":"mcm","clk":"11760275713","pt":1722498319068,"mc":[{"id":"1.231283997","rc":[{"trd":[[3,1.48]],"batb":[[0,3,18.44]],"ltp":3.0,"tv":1.48,"id":31379},{"trd":[[1.5,2.59]],"ltp":1.5,"tv":2.59,"id":169}],"tv":4.07}]}
{"op":"mcm","clk":"11760275770","pt":1722498320093,"mc":[{"id":"1.231283997","rc":[{"batb":[[0,3,18.48]],"ltp":3.0,"tv":1.48,"id":31379}]}]}
{"op":"mcm","clk":"11760335653","pt":1722499519989,"mc":[{"id":"1.231283997","rc":[{"trd":[[3,1.52]],"batb":[[0,3,18.44]],"ltp":3.0,"tv":1.52,"id":31379},{"trd":[[1.5,2.66]],"ltp":1.5,"tv":2.66,"id":169}],"tv":4.18}]}
{"op":"mcm","clk":"11760335921","pt":1722499524909,"mc":[{"id":"1.231283997","rc":[{"batb":[[0,3,18.48]],"ltp":3.0,"tv":1.52,"id":31379}]}]}
{"op":"mcm","clk":"11760404692","pt":1722500720253,"mc":[{"id":"1.231283997","rc":[{"trd":[[3,1.56]],"batb":[[0,3,18.44]],"ltp":3.0,"tv":1.56,"id":31379},{"trd":[[1.5,2.73]],"ltp":1.5,"tv":2.73,"id":169}],"tv":4.29}]}
{"op":"mcm","clk":"11760404937","pt":1722500725272,"mc":[{"id":"1.231283997","rc":[{"batb":[[0,3,18.48]],"ltp":3.0,"tv":1.56,"id":31379}]}]}
{"op":"mcm","clk":"11760457160","pt":1722501731488,"mc":[{"id":"1.231283997","rc":[{"batb":[[0,1.43,116.28],[1,1.38,131.58],[2,1.33,151.52]],"ltp":3.0,"tv":1.56,"id":31379},{"batb":[[1,1.43,116.28]],"ltp":1.5,"tv":2.73,"id":169}]}]}
{"op":"mcm","clk":"11760457669","pt":1722501737489,"mc":[{"id":"1.231283997","rc":[{"batb":[[0,1.44,5.71],[1,1.43,116.28],[2,1.38,131.58]],"ltp":3.0,"tv":1.56,"id":31379}]}]}
{"op":"mcm","clk":"11760566764","pt":1722503575142,"mc":[{"id":"1.231283997","rc":[{"batb":[[0,1.44,5.7]],"ltp":3.0,"tv":1.56,"id":31379},{"batb":[[0,1.44,9.95]],"ltp":1.5,"tv":2.73,"id":169}]}]}
{"op":"mcm","clk":"11760567920","pt":1722503588769,"mc":[{"id":"1.231283997","rc":[{"batb":[[0,1.44,13.49]],"ltp":3.0,"tv":1.56,"id":31379},{"batb":[[0,1.44,17.04]],"ltp":1.5,"tv":2.73,"id":169}]}]}
{"op":"mcm","clk":"11760580400","pt":1722503839354,"mc":[{"id":"1.231283997","rc":[{"batb":[[0,3,18.48],[1,1.44,13.49],[2,1.43,116.28]],"ltp":3.0,"tv":1.56,"id":31379},{"batb":[[1,1.43,202.24]],"ltp":1.5,"tv":2.73,"id":169}]}]}
{"op":"mcm","clk":"11760581151","pt":1722503847866,"mc":[{"id":"1.231283997","rc":[{"batb":[[1,1.44,7.78]],"batl":[[0,3.3,4.61]],"ltp":3.0,"tv":1.56,"id":31379}]}]}
{"op":"mcm","clk":"11760605850","pt":1722504321300,"mc":[{"id":"1.231283997","rc":[{"trd":[[3,1.6]],"ltp":3.0,"tv":1.6,"id":31379},{"trd":[[1.5,2.8]],"ltp":1.5,"tv":2.8,"id":169}],"tv":4.4}]}
{"op":"mcm","clk":"11760613688","pt":1722504459791,"mc":[{"id":"1.231283997","rc":[{"batl":[[0,2.58,5.52]],"ltp":1.5,"tv":2.8,"id":169}]}]}
{"op":"mcm","clk":"11760669028","pt":1722505488023,"mc":[{"id":"1.231283997","rc":[{"batb":[[1,1.43,116.28],[2,1.38,131.58]],"ltp":3.0,"tv":1.6,"id":31379},{"batb":[[0,1.44,9.95]],"ltp":1.5,"tv":2.8,"id":169}]}]}
{"op":"mcm","clk":"11760670891","pt":1722505518789,"mc":[{"id":"1.231283997","rc":[{"trd":[[3,1.64]],"batb":[[0,3,18.44]],"ltp":3.0,"tv":1.64,"id":31379},{"trd":[[1.5,2.87]],"ltp":1.5,"tv":2.87,"id":169}],"tv":4.51}]}
{"op":"mcm","clk":"11760671036","pt":1722505521105,"mc":[{"id":"1.231283997","rc":[{"batb":[[0,3,18.48]],"ltp":3.0,"tv":1.64,"id":31379}]}]}
{"op":"mcm","clk":"11760741868","pt":1722506728405,"mc":[{"id":"1.231283997","rc":[{"trd":[[3,1.68]],"batb":[[0,3,18.44]],"batl":[[0,3.3,4.61]],"ltp":3.0,"tv":1.68,"id":31379},{"trd":[[1.5,2.94]],"batb":[[0,1.44,9.96]],"batl":[[0,2.58,5.53]],"ltp":1.5,"tv":2.94,"id":169}],"tv":4.62}]}
{"op":"mcm","clk":"11760741973","pt":1722506730673,"mc":[{"id":"1.231283997","rc":[{"batb":[[0,3,18.48]],"ltp":3.0,"tv":1.68,"id":31379}]}]}
{"op":"mcm","clk":"11760815558","pt":1722507927513,"mc":[{"id":"1.231283997","rc":[{"trd":[[3,1.72]],"batb":[[0,3,18.44]],"ltp":3.0,"tv":1.72,"id":31379},{"trd":[[1.5,3.01]],"ltp":1.5,"tv":3.01,"id":169}],"tv":4.73}]}
{"op":"mcm","clk":"11760815691","pt":1722507929903,"mc":[{"id":"1.231283997","rc":[{"batb":[[0,3,18.48]],"ltp":3.0,"tv":1.72,"id":31379}]}]}
{"op":"mcm","clk":"11760896364","pt":1722509138761,"mc":[{"id":"1.231283997","rc":[{"trd":[[3,1.76]],"batb":[[0,3,18.44]],"ltp":3.0,"tv":1.76,"id":31379},{"trd":[[1.5,3.08]],"ltp":1.5,"tv":3.08,"id":169}],"tv":4.84}]}
{"op":"mcm","clk":"11760896436","pt":1722509140057,"mc":[{"id":"1.231283997","rc":[{"batb":[[0,3,18.48]],"ltp":3.0,"tv":1.76,"id":31379}]}]}
{"op":"mcm","clk":"11760966393","pt":1722510331607,"mc":[{"id":"1.231283997","rc":[{"trd":[[3,1.8]],"batb":[[0,3,18.44]],"batl":[[0,3.3,4.61]],"ltp":3.0,"tv":1.8,"id":31379},{"trd":[[1.5,3.15]],"batb":[[0,1.44,9.95]],"ltp":1.5,"tv":3.15,"id":169}],"tv":4.95}]}
{"op":"mcm","clk":"11760966643","pt":1722510335369,"mc":[{"id":"1.231283997","rc":[{"batb":[[0,3,18.48]],"ltp":3.0,"tv":1.8,"id":31379}]}]}
{"op":"mcm","clk":"11761009924","pt":1722511082193,"mc":[{"id":"1.231283997","rc":[{"batb":[[0,1.44,58.95]],"ltp":1.5,"tv":3.15,"id":169}]}]}
{"op":"mcm","clk":"11761010599","pt":1722511092594,"mc":[{"id":"1.231283997","rc":[{"batl":[[0,1.52,21.56]],"ltp":1.5,"tv":3.15,"id":169}]}]}
{"op":"mcm","clk":"11761036906","pt":1722511520217,"mc":[{"id":"1.231283997","rc":[{"trd":[[3,1.84]],"ltp":3.0,"tv":1.84,"id":31379},{"trd":[[1.5,3.22]],"ltp":1.5,"tv":3.22,"id":169}],"tv":5.06}]}
{"op":"mcm","clk":"11761056290","pt":1722511888404,"mc":[{"id":"1.231283997","rc":[{"batb":[[0,3.25,1.57],[1,3,18.48],[2,1.43,116.28]],"ltp":3.0,"tv":1.84,"id":31379}]}]}
{"op":"mcm","clk":"11761056703","pt":1722511896226,"mc":[{"id":"1.231283997","rc":[{"batb":[[0,3,18.48],[1,1.43,116.28],[2,1.38,131.58]],"ltp":3.0,"tv":1.84,"id":31379}]}]}
{"op":"mcm","clk":"11761067198","pt":1722512084763,"mc":[{"id":"1.231283997","rc":[{"batl":[[1,2.58,6.35]],"ltp":1.5,"tv":3.22,"id":169}]}]}
{"op":"mcm","clk":"11761103536","pt":1722512721134,"mc":[{"id":"1.231283997","rc":[{"trd":[[3,1.88]],"batb":[[0,3,18.44]],"ltp":3.0,"tv":1.88,"id":31379},{"trd":[[1.5,3.29]],"ltp":1.5,"tv":3.29,"id":169}],"tv":5.17}]}
{"op":"mcm","clk":"11761103771","pt":1722512725535,"mc":[{"id":"1.231283997","rc":[{"batb":[[0,3,18.48]],"ltp":3.0,"tv":1.88,"id":31379}]}]}
{"op":"mcm","clk":"11761171056","pt":1722513919789,"mc":[{"id":"1.231283997","rc":[{"trd":[[3,1.92]],"batb":[[0,3,18.44]],"ltp":3.0,"tv":1.92,"id":31379},{"trd":[[1.5,3.36]],"batb":[[0,1.44,58.94]],"batl":[[1,2.58,6.35]],"ltp":1.5,"tv":3.36,"id":169}],"tv":5.28}]}
{"op":"mcm","clk":"11761171141","pt":1722513921256,"mc":[{"id":"1.231283997","rc":[{"batb":[[0,3,18.48]],"ltp":3.0,"tv":1.92,"id":31379}]}]}
{"op":"mcm","clk":"11761211470","pt":1722514452305,"mc":[{"id":"1.231283997","rc":[{"batb":[[0,1.43,116.28],[1,1.38,131.58],[2,1.33,151.52]],"ltp":3.0,"tv":1.92,"id":31379},{"batb":[[1,1.43,116.28]],"ltp":1.5,"tv":3.36,"id":169}]}]}
{"op":"mcm","clk":"11761381954","pt":1722517410433,"mc":[{"id":"1.231283997","rc":[{"batb":[[0,3,18.48],[1,1.43,116.28],[2,1.38,131.58]],"ltp":3.0,"tv":1.92,"id":31379},{"batb":[[0,1.44,58.94],[1,1.43,202.24]],"batl":[[1,2.58,6.34]],"ltp":1.5,"tv":3.36,"id":169}]}]}
{"op":"mcm","clk":"11761389505","pt":1722517521489,"mc":[{"id":"1.231283997","rc":[{"trd":[[3,1.96]],"batb":[[0,3,18.44]],"ltp":3.0,"tv":1.96,"id":31379},{"trd":[[1.5,3.43]],"ltp":1.5,"tv":3.43,"id":169}],"tv":5.39}]}
{"op":"mcm","clk":"11761389849","pt":1722517525867,"mc":[{"id":"1.231283997","rc":[{"batb":[[0,3,18.48]],"ltp":3.0,"tv":1.96,"id":31379}]}]}
{"op":"mcm","clk":"11761456537","pt":1722518718942,"mc":[{"id":"1.231283997","rc":[{"trd":[[3,2]],"batb":[[0,3,18.44]],"ltp":3.0,"tv":2.0,"id":31379},{"trd":[[1.5,3.5]],"ltp":1.5,"tv":3.5,"id":169}],"tv":5.5}]}
{"op":"mcm","clk":"11761456625","pt":1722518720550,"mc":[{"id":"1.231283997","rc":[{"batb":[[0,3,18.48]],"ltp":3.0,"tv":2.0,"id":31379}]}]}
{"op":"mcm","clk":"11761498995","pt":1722519539839,"mc":[{"id":"1.231283997","rc":[{"batl":[[0,1.48,2.04],[1,1.52,21.56],[2,2.58,6.34]],"ltp":1.5,"tv":3.5,"id":169}]}]}
{"op":"mcm","clk":"11761499387","pt":1722519549028,"mc":[{"id":"1.231283997","rc":[{"batl":[[0,1.48,20.44]],"ltp":1.5,"tv":3.5,"id":169}]}]}
{"op":"mcm","clk":"11761499860","pt":1722519560153,"mc":[{"id":"1.231283997","rc":[{"batl":[[1,1.49,15.33],[2,1.52,21.56]],"ltp":1.5,"tv":3.5,"id":169}]}]}
{"op":"mcm","clk":"11761500103","pt":1722519566444,"mc":[{"id":"1.231283997","rc":[{"batl":[[2,1.51,30.67]],"ltp":1.5,"tv":3.5,"id":169}]}]}
{"op":"mcm","clk":"11761604647","pt":1722521337777,"mc":[{"id":"1.231283997","rc":[{"batb":[[0,1.44,58.94]],"batl":[[0,1.48,20.44],[1,1.49,15.33],[2,1.51,30.66]],"ltp":1.5,"tv":3.5,"id":169}]}]}
{"op":"mcm","clk":"11761612220","pt":1722521466276,"mc":[{"id":"1.231283997","rc":[{"batl":[[0,3.15,226.17]],"ltp":3.0,"tv":2.0,"id":31379}]}]}
{"op":"mcm","clk":"11761612354","pt":1722521468510,"mc":[{"id":"1.231283997","rc":[{"batb":[[0,1.44,49]],"ltp":1.5,"tv":3.5,"id":169}]}]}
{"op":"mcm","clk":"11761612863","pt":1722521476590,"mc":[{"id":"1.231283997","rc":[{"trd":[[3.15,155.98]],"batl":[[0,3.15,148.18]],"ltp":3.15,"tv":157.98,"id":31379}],"tv":161.48}]}
{"op":"mcm","clk":"11761613450","pt":1722521486005,"mc":[{"id":"1.231283997","rc":[{"trd":[[3.15,249.57]],"batl":[[0,3.15,101.39]],"ltp":3.15,"tv":251.57,"id":31379}],"tv":255.07}]}
{"op":"mcm","clk":"11761614597","pt":1722521506432,"mc":[{"id":"1.231283997","rc":[{"batl":[[0,3.15,226.17]],"ltp":3.15,"tv":251.57,"id":31379}]}]}
{"op":"mcm","clk":"11761614980","pt":1722521513747,"mc":[{"id":"1.231283997","rc":[{"trd":[[3.15,701.92]],"ltp":3.15,"tv":703.91,"id":31379}],"tv":707.41}]}
{"op":"mcm","clk":"11761615612","pt":1722521524692,"mc":[{"id":"1.231283997","rc":[{"batl":[[0,3.15,226.17]],"ltp":3.15,"tv":703.91,"id":31379}]}]}
{"op":"mcm","clk":"11761616134","pt":1722521534768,"mc":[{"id":"1.231283997","rc":[{"trd":[[3.15,1154.27]],"ltp":3.15,"tv":1156.26,"id":31379}],"tv":1159.76}]}
{"op":"mcm","clk":"11761616664","pt":1722521543689,"mc":[{"id":"1.231283997","rc":[{"batl":[[0,3.15,226.17]],"ltp":3.15,"tv":1156.26,"id":31379}]}]}
{"op":"mcm","clk":"11761617170","pt":1722521551818,"mc":[{"id":"1.231283997","rc":[{"trd":[[3.15,1606.61]],"ltp":3.15,"tv":1608.61,"id":31379}],"tv":1612.11}]}
{"op":"mcm","clk":"11761617600","pt":1722521559319,"mc":[{"id":"1.231283997","rc":[{"batl":[[0,3.15,226.17]],"ltp":3.15,"tv":1608.61,"id":31379}]}]}
{"op":"mcm","clk":"11761618002","pt":1722521565702,"mc":[{"id":"1.231283997","rc":[{"trd":[[3.15,2058.96]],"ltp":3.15,"tv":2060.96,"id":31379}],"tv":2064.46}]}
{"op":"mcm","clk":"11761618472","pt":1722521575034,"mc":[{"id":"1.231283997","rc":[{"batl":[[0,3.15,226.17]],"ltp":3.15,"tv":2060.96,"id":31379}]}]}
{"op":"mcm","clk":"11761618846","pt":1722521581714,"mc":[{"id":"1.231283997","rc":[{"trd":[[3.15,2511.31]],"ltp":3.15,"tv":2513.3,"id":31379}],"tv":2516.8}]}
{"op":"mcm","clk":"11761619284","pt":1722521588666,"mc":[{"id":"1.231283997","rc":[{"batl":[[0,3.15,226.17]],"ltp":3.15,"tv":2513.3,"id":31379}]}]}
{"op":"mcm","clk":"11761619761","pt":1722521596943,"mc":[{"id":"1.231283997","rc":[{"trd":[[3.15,2963.66]],"ltp":3.15,"tv":2965.65,"id":31379}],"tv":2969.15}]}
{"op":"mcm","clk":"11761620261","pt":1722521603785,"mc":[{"id":"1.231283997","rc":[{"batl":[[0,3.15,226.17]],"ltp":3.15,"tv":2965.65,"id":31379}]}]}
{"op":"mcm","clk":"11761620832","pt":1722521611585,"mc":[{"id":"1.231283997","rc":[{"trd":[[3.15,3416]],"ltp":3.15,"tv":3418.0,"id":31379}],"tv":3421.5}]}
{"op":"mcm","clk":"11761621252","pt":1722521617889,"mc":[{"id":"1.231283997","rc":[{"batl":[[0,3.15,226.17]],"ltp":3.15,"tv":3418.0,"id":31379}]}]}
{"op":"mcm","clk":"11761621860","pt":1722521627264,"mc":[{"id":"1.231283997","rc":[{"trd":[[3.15,3868.35]],"ltp":3.15,"tv":3870.35,"id":31379}],"tv":3873.85}]}
{"op":"mcm","clk":"11761622055","pt":1722521631392,"mc":[{"id":"1.231283997","rc":[{"batb":[[0,3.05,4],[1,3,18.48],[2,1.43,116.28]],"batl":[[0,3.3,4]],"ltp":3.15,"tv":3870.35,"id":31379},{"batb":[[0,1.45,4],[1,1.44,53],[2,1.43,202.24]],"ltp":1.5,"tv":3.5,"id":169}]}]}
{"op":"mcm","clk":"11761622230","pt":1722521634804,"mc":[{"id":"1.231283997","rc":[{"batb":[[0,3,18.48],[1,1.43,116.28],[2,1.38,131.58]],"batl":[[0,3.15,226.17],[1,3.3,4]],"ltp":3.15,"tv":3870.35,"id":31379}]}]}
{"op":"mcm","clk":"11761622724","pt":1722521641893,"mc":[{"id":"1.231283997","rc":[{"trd":[[3.15,4320.7]],"batl":[[0,3.3,4],[1,3.3,0]],"ltp":3.15,"tv":4322.69,"id":31379}],"tv":4326.19}]}
{"op":"mcm","clk":"11761623009","pt":1722521646390,"mc":[{"id":"1.231283997","rc":[{"batb":[[0,3.1,4],[1,3.05,4],[2,3,18.48]],"batl":[[0,3.25,4],[1,3.3,4]],"ltp":3.15,"tv":4322.69,"id":31379},{"batl":[[0,1.48,24.44]],"ltp":1.5,"tv":3.5,"id":169}]}]}
{"op":"mcm","clk":"11761623181","pt":1722521649380,"mc":[{"id":"1.231283997","rc":[{"batb":[[0,3,18.48],[1,1.43,116.28],[2,1.38,131.58]],"batl":[[0,3.15,226.17],[1,3.25,4],[2,3.3,4]],"ltp":3.15,"tv":4322.69,"id":31379},{"batl":[[0,1.48,20.44]],"ltp":1.5,"tv":3.5,"id":169}]}]}
{"op":"mcm","clk":"11761623691","pt":1722521656826,"mc":[{"id":"1.231283997","rc":[{"trd":[[3.15,4773.05]],"batl":[[0,3.25,4],[1,3.3,4],[2,3.3,0]],"ltp":3.15,"tv":4775.04,"id":31379}],"tv":4778.54}]}
{"op":"mcm","clk":"11761624016","pt":1722521661632,"mc":[{"id":"1.231283997","rc":[{"batb":[[0,3.1,4],[1,3.05,4],[2,3,18.48]],"ltp":3.15,"tv":4775.04,"id":31379},{"batl":[[0,1.48,24.44]],"ltp":1.5,"tv":3.5,"id":169}]}]}
{"op":"mcm","clk":"11761624180","pt":1722521664315,"mc":[{"id":"1.231283997","rc":[{"batb":[[0,3,18.48],[1,1.43,116.28],[2,1.38,131.58]],"batl":[[0,3.15,226.17],[1,3.25,4],[2,3.3,4]],"ltp":3.15,"tv":4775.04,"id":31379},{"batl":[[0,1.48,20.44]],"ltp":1.5,"tv":3.5,"id":169}]}]}
{"op":"mcm","clk":"11761624512","pt":1722521670551,"mc":[{"id":"1.231283997","rc":[{"trd":[[3.15,5225.39]],"batl":[[0,3.25,4],[1,3.3,4],[2,3.3,0]],"ltp":3.15,"tv":5227.39,"id":31379}],"tv":5230.89}]}
{"op":"mcm","clk":"11761624915","pt":1722521677327,"mc":[{"id":"1.231283997","rc":[{"batl":[[0,3.15,226.17],[1,3.25,4],[2,3.3,4]],"ltp":3.15,"tv":5227.39,"id":31379}]}]}
{"op":"mcm","clk":"11761625174","pt":1722521681243,"mc":[{"id":"1.231283997","rc":[{"trd":[[3.15,5677.74]],"batl":[[0,3.25,4],[1,3.3,4],[2,3.3,0]],"ltp":3.15,"tv":5679.74,"id":31379}],"tv":5683.24}]}
{"op":"mcm","clk":"11761625839","pt":1722521691935,"mc":[{"id":"1.231283997","rc":[{"batb":[[0,3.1,4],[1,3.05,4],[2,3,18.48]],"ltp":3.15,"tv":5679.74,"id":31379},{"batl":[[0,1.48,24.44]],"ltp":1.5,"tv":3.5,"id":169}]}]}
{"op":"mcm","clk":"11761626669","pt":1722521703968,"mc":[{"id":"1.231283997","rc":[{"batb":[[0,3,18.48],[1,1.43,116.28],[2,1.38,131.58]],"batl":[[0,3.15,272.97],[1,3.25,4],[2,3.3,4]],"ltp":3.15,"tv":5679.74,"id":31379},{"batl":[[0,1.48,20.44]],"ltp":1.5,"tv":3.5,"id":169}]}]}
{"op":"mcm","clk":"11761626879","pt":1722521707265,"mc":[{"id":"1.231283997","rc":[{"batl":[[0,3.15,276.97]],"ltp":3.15,"tv":5679.74,"id":31379},{"batb":[[0,1.47,4],[1,1.46,4],[2,1.45,4]],"ltp":1.5,"tv":3.5,"id":169}]}]}
{"op":"mcm","clk":"11761627523","pt":1722521719498,"mc":[{"id":"1.231283997","rc":[{"batl":[[0,3.1,13.69],[1,3.15,276.97],[2,3.25,4]],"ltp":3.15,"tv":5679.74,"id":31379}]}]}
{"op":"mcm","clk":"11761627708","pt":1722521722398,"mc":[{"id":"1.231283997","rc":[{"batl":[[0,3.1,17.69]],"ltp":3.15,"tv":5679.74,"id":31379}]}]}
{"op":"mcm","clk":"11761627952","pt":1722521726218,"mc":[{"id":"1.231283997","rc":[{"batl":[[1,3.15,4]],"ltp":3.15,"tv":5679.74,"id":31379}]}]}
{"op":"mcm","clk":"11761628098","pt":1722521727978,"mc":[{"id":"1.231283997","rc":[{"batb":[[0,1.44,49],[1,1.43,202.24],[2,1.38,131.58]],"ltp":1.5,"tv":3.5,"id":169}]}]}
{"op":"mcm","clk":"11761628633","pt":1722521737602,"mc":[{"id":"1.231283997","rc":[{"batb":[[0,3.05,4],[1,3,18.48],[2,1.43,116.28]],"batl":[[0,3.3,4]],"ltp":3.15,"tv":5679.74,"id":31379},{"batb":[[0,1.45,4],[1,1.44,53],[2,1.43,202.24]],"ltp":1.5,"tv":3.5,"id":169}]}]}
{"op":"mcm","clk":"11761629500","pt":1722521752630,"mc":[{"id":"1.231283997","rc":[{"batb":[[0,3.1,4],[1,3.05,4],[2,3,18.48]],"batl":[[0,3.25,4],[1,3.3,4]],"ltp":3.15,"tv":5679.74,"id":31379},{"batl":[[0,1.48,24.44]],"ltp":1.5,"tv":3.5,"id":169}]}]}
{"op":"mcm","clk":"11761629614","pt":1722521755112,"mc":[{"id":"1.231283997","rc":[{"batl":[[0,3.15,253.47],[1,3.25,4],[2,3.3,4]],"ltp":3.15,"tv":5679.74,"id":31379}]}]}
{"op":"mcm","clk":"11761629640","pt":1722521755523,"mc":[{"id":"1.231283997","rc":[{"batb":[[0,3,18.48],[1,1.43,116.28],[2,1.38,131.58]],"ltp":3.15,"tv":5679.74,"id":31379},{"batl":[[0,1.48,20.44]],"ltp":1.5,"tv":3.5,"id":169}]}]}
{"op":"mcm","clk":"11761630207","pt":1722521765255,"mc":[{"id":"1.231283997","rc":[{"trd":[[3.15,6176.88]],"batl":[[0,3.15,3.9]],"ltp":3.15,"tv":6178.88,"id":31379}],"tv":6182.38}]}
{"op":"mcm","clk":"11761630398","pt":1722521767738,"mc":[{"id":"1.231283997","rc":[{"batb":[[0,3.05,4],[1,3,18.48],[2,1.43,116.28]],"batl":[[0,3.25,4],[1,3.3,4],[2,3.3,0]],"ltp":3.15,"tv":6178.88,"id":31379},{"batl":[[0,1.48,24.44]],"ltp":1.5,"tv":3.5,"id":169}]}]}
{"op":"mcm","clk":"11761631238","pt":1722521782846,"mc":[{"id":"1.231283997","rc":[{"batb":[[0,3.1,4],[1,3.05,4],[2,3,18.48]],"ltp":3.15,"tv":6178.88,"id":31379}]}]}
{"op":"mcm","clk":"11761634308","pt":1722521830106,"mc":[{"id":"1.231283997","rc":[{"batb":[[0,3,18.48],[1,1.43,116.28],[2,1.38,131.58]],"batl":[[0,3.15,249.57],[1,3.25,4],[2,3.3,4]],"ltp":3.15,"tv":6178.88,"id":31379},{"batl":[[0,1.48,20.44]],"ltp":1.5,"tv":3.5,"id":169}]}]}
{"op":"mcm","clk":"11761634529","pt":1722521834091,"mc":[{"id":"1.231283997","rc":[{"trd":[[3.15,6676.03]],"batl":[[0,3.25,4],[1,3.3,4],[2,3.3,0]],"ltp":3.15,"tv":6678.02,"id":31379}],"tv":6681.52}]}
{"op":"mcm","clk":"11761634960","pt":1722521841432,"mc":[{"id":"1.231283997","rc":[{"batl":[[0,3.15,249.57],[1,3.25,4],[2,3.3,4]],"ltp":3.15,"tv":6678.02,"id":31379}]}]}
{"op":"mcm","clk":"11761635070","pt":1722521843297,"mc":[{"id":"1.231283997","rc":[{"batl":[[0,3.15,253.57]],"ltp":3.15,"tv":6678.02,"id":31379},{"batb":[[0,1.47,4],[1,1.46,4],[2,1.45,4]],"ltp":1.5,"tv":3.5,"id":169}]}]}
{"op":"mcm","clk":"11761635310","pt":1722521847135,"mc":[{"id":"1.231283997","rc":[{"trd":[[3.15,7175.17]],"ltp":3.15,"tv":7177.16,"id":31379},{"batb":[[0,1.44,49],[1,1.43,202.24],[2,1.38,131.58]],"ltp":1.5,"tv":3.5,"id":169}],"tv":7180.66}]}
{"op":"mcm","clk":"11761635827","pt":1722521854144,"mc":[{"id":"1.231283997","rc":[{"batl":[[0,3.15,249.57]],"ltp":3.15,"tv":7177.16,"id":31379}]}]}
{"op":"mcm","clk":"11761635845","pt":1722521854559,"mc":[{"id":"1.231283997","rc":[{"batl":[[0,3.1,12.25],[1,3.15,249.57]],"ltp":3.15,"tv":7177.16,"id":31379}]}]}
{"op":"mcm","clk":"11761636078","pt":1722521858448,"mc":[{"id":"1.231283997","rc":[{"batl":[[0,3.1,16.25]],"ltp":3.15,"tv":7177.16,"id":31379},{"batb":[[0,1.47,4],[1,1.44,49],[2,1.43,202.24]],"ltp":1.5,"tv":3.5,"id":169}]}]}
{"op":"mcm","clk":"11761636280","pt":1722521861239,"mc":[{"id":"1.231283997","rc":[{"batl":[[1,3.15,0]],"ltp":3.15,"tv":7177.16,"id":31379}]}]}
{"op":"mcm","clk":"11761636435","pt":1722521863153,"mc":[{"id":"1.231283997","rc":[{"batl":[[0,3.1,4]],"ltp":3.15,"tv":7177.16,"id":31379}]}]}
{"op":"mcm","clk":"11761636470","pt":1722521863731,"mc":[{"id":"1.231283997","rc":[{"batb":[[0,1.44,49],[1,1.43,202.24],[2,1.38,131.58]],"ltp":1.5,"tv":3.5,"id":169}]}]}
{"op":"mcm","clk":"11761636988","pt":1722521871335,"mc":[{"id":"1.231283997","rc":[{"batl":[[0,3.1,249.57]],"ltp":3.15,"tv":7177.16,"id":31379}]}]}
{"op":"mcm","clk":"11761637126","pt":1722521873558,"mc":[{"id":"1.231283997","rc":[{"batl":[[0,3.1,253.57]],"ltp":3.15,"tv":7177.16,"id":31379},{"batb":[[0,1.47,4],[1,1.44,49],[2,1.43,202.24]],"ltp":1.5,"tv":3.5,"id":169}]}]}
{"op":"mcm","clk":"11761637431","pt":1722521878273,"mc":[{"id":"1.231283997","rc":[{"trd":[[3.1,499.14]],"ltp":3.1,"tv":7676.3,"id":31379},{"batb":[[0,1.44,49],[1,1.43,202.24],[2,1.38,131.58]],"ltp":1.5,"tv":3.5,"id":169}],"tv":7679.8}]}
{"op":"mcm","clk":"11761637784","pt":1722521883259,"mc":[{"id":"1.231283997","rc":[{"batl":[[0,3.1,249.57]],"ltp":3.1,"tv":7676.3,"id":31379}]}]}
{"op":"mcm","clk":"11761638174","pt":1722521887788,"mc":[{"id":"1.231283997","rc":[{"trd":[[3.1,998.28]],"ltp":3.1,"tv":8175.45,"id":31379}],"tv":8178.95}]}
{"op":"mcm","clk":"11761638256","pt":1722521888671,"mc":[{"id":"1.231283997","rc":[{"batb":[[0,3.05,4],[1,3,18.48],[2,1.43,116.28]],"batl":[[0,3.3,4]],"ltp":3.1,"tv":8175.45,"id":31379},{"batb":[[0,1.45,4],[1,1.44,53],[2,1.43,202.24]],"ltp":1.5,"tv":3.5,"id":169}]}]}
{"op":"mcm","clk":"11761638583","pt":1722521893387,"mc":[{"id":"1.231283997","rc":[{"batl":[[0,3.1,249.57],[1,3.3,4]],"ltp":3.1,"tv":8175.45,"id":31379}]}]}
{"op":"mcm","clk":"11761638607","pt":1722521893751,"mc":[{"id":"1.231283997","rc":[{"batb":[[0,3,18.48],[1,1.43,116.28],[2,1.38,131.58]],"ltp":3.1,"tv":8175.45,"id":31379}]}]}
{"op":"mcm","clk":"11761638876","pt":1722521897800,"mc":[{"id":"1.231283997","rc":[{"trd":[[3.1,1497.43]],"batl":[[0,3.3,4],[1,3.3,0]],"ltp":3.1,"tv":8674.59,"id":31379}],"tv":8678.09}]}
{"op":"mcm","clk":"11761639145","pt":1722521902367,"mc":[{"id":"1.231283997","rc":[{"batl":[[0,3.1,249.57],[1,3.3,4]],"ltp":3.1,"tv":8674.59,"id":31379}]}]}
{"op":"mcm","clk":"11761639202","pt":1722521903663,"mc":[{"id":"1.231283997","rc":[{"batl":[[0,3.1,253.57]],"ltp":3.1,"tv":8674.59,"id":31379},{"batb":[[0,1.47,4],[1,1.45,4],[2,1.44,53]],"ltp":1.5,"tv":3.5,"id":169}]}]}
{"op":"mcm","clk":"11761639502","pt":1722521908276,"mc":[{"id":"1.231283997","rc":[{"trd":[[3.1,1996.57]],"ltp":3.1,"tv":9173.73,"id":31379},{"batb":[[0,1.45,4],[1,1.44,53],[2,1.43,202.24]],"ltp":1.5,"tv":3.5,"id":169}],"tv":9177.23}]}
{"op":"mcm","clk":"11761639831","pt":1722521913109,"mc":[{"id":"1.231283997","rc":[{"batl":[[0,3.1,249.57]],"ltp":3.1,"tv":9173.73,"id":31379}]}]}
{"op":"mcm","clk":"11761640158","pt":1722521917516,"mc":[{"id":"1.231283997","rc":[{"trd":[[3.1,2495.71]],"ltp":3.1,"tv":9672.87,"id":31379}],"tv":9676.37}]}
{"op":"mcm","clk":"11761640244","pt":1722521918923,"mc":[{"id":"1.231283997","rc":[{"batb":[[0,3.1,4],[1,3.05,4],[2,3,18.48]],"batl":[[0,3.25,4]],"ltp":3.1,"tv":9672.87,"id":31379},{"batl":[[0,1.48,24.44]],"ltp":1.5,"tv":3.5,"id":169}]}]}
{"op":"mcm","clk":"11761640513","pt":1722521922204,"mc":[{"id":"1.231283997","rc":[{"trd":[[3.1,2503.71]],"batb":[[0,3.05,4],[1,3,18.48],[2,1.43,116.28]],"batl":[[0,3.1,245.57],[1,3.25,4]],"ltp":3.1,"tv":9680.87,"id":31379}],"tv":9684.37}]}
{"op":"mcm","clk":"11761640547","pt":1722521922716,"mc":[{"id":"1.231283997","rc":[{"batb":[[0,3,18.48],[1,1.43,116.28],[2,1.38,131.58]],"ltp":3.1,"tv":9680.87,"id":31379},{"batl":[[0,1.48,20.44]],"ltp":1.5,"tv":3.5,"id":169}]}]}
{"op":"mcm","clk":"11761640900","pt":1722521927793,"mc":[{"id":"1.231283997","rc":[{"trd":[[3.1,2994.85]],"batb":[[0,3.1,4],[1,3,18.48],[2,1.43,116.28]],"batl":[[0,3.25,4],[1,3.25,0]],"ltp":3.1,"tv":10172.01,"id":31379}],"tv":10175.51}]}
{"op":"mcm","clk":"11761641280","pt":1722521933920,"mc":[{"id":"1.231283997","rc":[{"batb":[[0,3.1,8]],"ltp":3.1,"tv":10172.01,"id":31379},{"batl":[[0,1.48,24.44]],"ltp":1.5,"tv":3.5,"id":169}]}]}
{"op":"mcm","clk":"11761641910","pt":1722521943426,"mc":[{"id":"1.231283997","rc":[{"batb":[[0,3.1,4]],"ltp":3.1,"tv":10172.01,"id":31379}]}]}
{"op":"mcm","clk":"11761642928","pt":1722521959350,"mc":[{"id":"1.231283997","rc":[{"batl":[[0,3.15,249.57],[1,3.25,4]],"ltp":3.1,"tv":10172.01,"id":31379}]}]}
{"op":"mcm","clk":"11761642967","pt":1722521959824,"mc":[{"id":"1.231283997","rc":[{"batb":[[0,3,18.48],[1,1.43,116.28],[2,1.38,131.58]],"ltp":3.1,"tv":10172.01,"id":31379},{"batl":[[0,1.48,20.44]],"ltp":1.5,"tv":3.5,"id":169}]}]}
{"op":"mcm","clk":"11761643215","pt":1722521964163,"mc":[{"id":"1.231283997","rc":[{"batl":[[0,3.1,4],[1,3.15,253.57],[2,3.25,4]],"ltp":3.1,"tv":10172.01,"id":31379},{"batb":[[0,1.47,4],[1,1.46,4],[2,1.45,4]],"ltp":1.5,"tv":3.5,"id":169}]}]}
{"op":"mcm","clk":"11761643284","pt":1722521965255,"mc":[{"id":"1.231283997","rc":[{"trd":[[3.1,3002.85],[3.15,7666.31]],"batl":[[0,3.15,4],[1,3.15,0],[2,3.25,0]],"ltp":3.15,"tv":10671.16,"id":31379},{"batb":[[0,1.44,49],[1,1.43,202.24],[2,1.38,131.58]],"ltp":1.5,"tv":3.5,"id":169}],"tv":10674.66}]}
{"op":"mcm","clk":"11761644070","pt":1722521979262,"mc":[{"id":"1.231283997","rc":[{"batb":[[0,3.05,4],[1,3,18.48],[2,1.43,116.28]],"ltp":3.15,"tv":10671.16,"id":31379},{"batl":[[0,1.48,24.44]],"ltp":1.5,"tv":3.5,"id":169}]}]}
{"op":"mcm","clk":"11761644769","pt":1722521990790,"mc":[{"id":"1.231283997","rc":[{"trd":[[3.15,7669.43]],"batl":[[0,3.15,2.44]],"ltp":3.15,"tv":10674.28,"id":31379}],"tv":10677.78}]}
{"op":"mcm","clk":"11761644970","pt":1722521994382,"mc":[{"id":"1.231283997","rc":[{"batl":[[0,3.3,4]],"ltp":3.15,"tv":10674.28,"id":31379},{"batb":[[0,1.45,4],[1,1.44,53],[2,1.43,202.24]],"batl":[[0,1.48,20.44]],"ltp":1.5,"tv":3.5,"id":169}]}]}
{"op":"mcm","clk":"11761645389","pt":1722522000273,"mc":[{"id":"1.231283997","rc":[{"batb":[[0,3,18.48],[1,1.43,116.28],[2,1.38,131.58]],"batl":[[0,3.1,249.57],[1,3.3,4]],"ltp":3.15,"tv":10674.28,"id":31379}]}]}
{"op":"mcm","clk":"11761645734","pt":1722522005571,"mc":[{"id":"1.231283997","rc":[{"trd":[[3.1,3501.99]],"batl":[[0,3.3,4],[1,3.3,0]],"ltp":3.1,"tv":11173.42,"id":31379}],"tv":11176.92}]}
{"op":"mcm","clk":"11761645958","pt":1722522009513,"mc":[{"id":"1.231283997","rc":[{"batb":[[0,3.1,4],[1,3.05,4],[2,3,18.48]],"batl":[[0,3.25,4],[1,3.3,4]],"ltp":3.1,"tv":11173.42,"id":31379},{"batl":[[0,1.48,24.44]],"ltp":1.5,"tv":3.5,"id":169}]}]}
{"op":"mcm","clk":"11761646051","pt":1722522011271,"mc":[{"id":"1.231283997","rc":[{"trd":[[3.1,3510]],"batb":[[0,3.05,4],[1,3,18.48],[2,1.43,116.28]],"batl":[[0,3.1,245.57],[1,3.25,4],[2,3.3,4]],"ltp":3.1,"tv":11181.42,"id":31379}],"tv":11184.92}]}
{"op":"mcm","clk":"11761646080","pt":1722522011797,"mc":[{"id":"1.231283997","rc":[{"batb":[[0,3,18.48],[1,1.43,116.28],[2,1.38,131.58]],"ltp":3.1,"tv":11181.42,"id":31379},{"batl":[[0,1.48,20.44]],"ltp":1.5,"tv":3.5,"id":169}]}]}
{"op":"mcm","clk":"11761646401","pt":1722522017678,"mc":[{"id":"1.231283997","rc":[{"trd":[[3.1,4001.14]],"batb":[[0,3.1,4],[1,3,18.48],[2,1.43,116.28]],"batl":[[0,3.25,4],[1,3.3,4],[2,3.3,0]],"ltp":3.1,"tv":11672.56,"id":31379}],"tv":11676.06}]}
{"op":"mcm","clk":"11761646848","pt":1722522024581,"mc":[{"id":"1.231283997","rc":[{"batb":[[0,3.1,8]],"ltp":3.1,"tv":11672.56,"id":31379},{"batl":[[0,1.48,24.44]],"ltp":1.5,"tv":3.5,"id":169}]}]}
{"op":"mcm","clk":"11761647111","pt":1722522028792,"mc":[{"id":"1.231283997","rc":[{"trd":[[3.1,4008.93]],"batb":[[0,3.1,4.1]],"ltp":3.1,"tv":11680.36,"id":31379}],"tv":11683.86}]}
{"op":"mcm","clk":"11761647397","pt":1722522033803,"mc":[{"id":"1.231283997","rc":[{"batb":[[0,3.1,4]],"ltp":3.1,"tv":11680.36,"id":31379}]}]}
{"op":"mcm","clk":"11761647930","pt":1722522042129,"mc":[{"id":"1.231283997","rc":[{"batl":[[0,3.15,249.57],[1,3.25,4],[2,3.3,4]],"ltp":3.1,"tv":11680.36,"id":31379}]}]}
{"op":"mcm","clk":"11761647958","pt":1722522042543,"mc":[{"id":"1.231283997","rc":[{"batb":[[0,3,18.48],[1,1.43,116.28],[2,1.38,131.58]],"ltp":3.1,"tv":11680.36,"id":31379},{"batl":[[0,1.48,20.44]],"ltp":1.5,"tv":3.5,"id":169}]}]}
{"op":"mcm","clk":"11761648453","pt":1722522051924,"mc":[{"id":"1.231283997","rc":[{"trd":[[3.15,8168.57]],"batl":[[0,3.25,4],[1,3.3,4],[2,3.3,0]],"ltp":3.15,"tv":12179.5,"id":31379}],"tv":12183.0}]}
{"op":"mcm","clk":"11761648584","pt":1722522054855,"mc":[{"id":"1.231283997","rc":[{"batb":[[0,3.05,4],[1,3,18.48],[2,1.43,116.28]],"ltp":3.15,"tv":12179.5,"id":31379},{"batl":[[0,1.48,24.44]],"ltp":1.5,"tv":3.5,"id":169}]}]}
{"op":"mcm","clk":"11761648774","pt":1722522057932,"mc":[{"id":"1.231283997","rc":[{"batl":[[0,3.15,249.57],[1,3.25,4],[2,3.3,4]],"ltp":3.15,"tv":12179.5,"id":31379}]}]}
{"op":"mcm","clk":"11761648806","pt":1722522058549,"mc":[{"id":"1.231283997","rc":[{"batb":[[0,3,18.48],[1,1.43,116.28],[2,1.38,131.58]],"ltp":3.15,"tv":12179.5,"id":31379},{"batl":[[0,1.48,20.44]],"ltp":1.5,"tv":3.5,"id":169}]}]}
{"op":"mcm","clk":"11761648977","pt":1722522062122,"mc":[{"id":"1.231283997","rc":[{"trd":[[3.15,8667.71]],"batl":[[0,3.25,4],[1,3.3,4],[2,3.3,0]],"ltp":3.15,"tv":12678.64,"id":31379}],"tv":12682.14}]}
{"op":"mcm","clk":"11761649233","pt":1722522067242,"mc":[{"id":"1.231283997","rc":[{"batl":[[0,3.15,249.57],[1,3.25,4],[2,3.3,4]],"ltp":3.15,"tv":12678.64,"id":31379}]}]}
{"op":"mcm","clk":"11761649381","pt":1722522069954,"mc":[{"id":"1.231283997","rc":[{"batl":[[0,3.1,4],[1,3.15,253.57],[2,3.25,4]],"ltp":3.15,"tv":12678.64,"id":31379},{"batb":[[0,1.47,4],[1,1.46,4],[2,1.45,4]],"ltp":1.5,"tv":3.5,"id":169}]}]}
{"op":"mcm","clk":"11761649415","pt":1722522070572,"mc":[{"id":"1.231283997","rc":[{"batl":[[0,3.1,16.74]],"ltp":3.15,"tv":12678.64,"id":31379}]}]}
{"op":"mcm","clk":"11761649492","pt":1722522071867,"mc":[{"id":"1.231283997","rc":[{"trd":[[3.1,4042.42],[3.15,9133.36]],"batl":[[0,3.15,20.74],[1,3.25,4],[2,3.3,4]],"ltp":3.15,"tv":13177.78,"id":31379}],"tv":13181.28}]}
{"op":"mcm","clk":"11761649556","pt":1722522072856,"mc":[{"id":"1.231283997","rc":[{"batb":[[0,3.05,12.95],[1,3,18.48],[2,1.43,116.28]],"ltp":3.15,"tv":13177.78,"id":31379},{"batb":[[0,1.46,4],[1,1.45,4],[2,1.44,53]],"ltp":1.5,"tv":3.5,"id":169}]}]}
{"op":"mcm","clk":"11761650317","pt":1722522085186,"mc":[{"id":"1.231283997","rc":[{"batb":[[0,3.05,16.95]],"ltp":3.15,"tv":13177.78,"id":31379},{"batl":[[0,1.48,24.44]],"ltp":1.5,"tv":3.5,"id":169}]}]}
{"op":"mcm","clk":"11761650597","pt":1722522090070,"mc":[{"id":"1.231283997","rc":[{"trd":[[3.15,9140.43]],"batl":[[0,3.25,4],[1,3.3,4],[2,3.3,0]],"ltp":3.15,"tv":13184.84,"id":31379},{"batb":[[0,1.45,4],[1,1.44,53],[2,1.43,202.24]],"ltp":1.5,"tv":3.5,"id":169}],"tv":13188.34}]}
{"op":"mcm","clk":"11761651153","pt":1722522100293,"mc":[{"id":"1.231283997","rc":[{"batb":[[0,3.1,4],[1,3.05,16.95],[2,3,18.48]],"ltp":3.15,"tv":13184.84,"id":31379}]}]}
{"op":"mcm","clk":"11761651193","pt":1722522101107,"mc":[{"id":"1.231283997","rc":[{"batb":[[0,3.05,12.95],[1,3,18.48],[2,1.43,116.28]],"batl":[[0,3.15,249.57],[1,3.25,4],[2,3.3,4]],"ltp":3.15,"tv":13184.84,"id":31379},{"batl":[[0,1.48,20.44]],"ltp":1.5,"tv":3.5,"id":169}]}]}
{"op":"mcm","clk":"11761651655","pt":1722522109990,"mc":[{"id":"1.231283997","rc":[{"batb":[[1,3,21.58]],"ltp":3.15,"tv":13184.84,"id":31379},{"batb":[[2,1.43,216.66]],"ltp":1.5,"tv":3.5,"id":169}]}]}
{"op":"mcm","clk":"11761651839","pt":1722522112724,"mc":[{"id":"1.231283997","rc":[{"trd":[[3.15,9530.38]],"batl":[[0,3.15,54.59]],"ltp":3.15,"tv":13574.8,"id":31379}],"tv":13578.3}]}
{"op":"mcm","clk":"11761652014","pt":1722522115311,"mc":[{"id":"1.231283997","rc":[{"batb":[[0,1.47,4],[1,1.46,4],[2,1.45,4]],"batl":[[0,1.48,24.44]],"ltp":1.5,"tv":3.5,"id":169}]}]}
{"op":"mcm","clk":"11761652021","pt":1722522115420,"mc":[{"id":"1.231283997","rc":[{"batb":[[0,3.05,16.95]],"batl":[[0,3.15,58.59]],"ltp":3.15,"tv":13574.8,"id":31379}]}]}
{"op":"mcm","clk":"11761654312","pt":1722522155933,"mc":[{"id":"1.231283997","rc":[{"batl":[[0,3.15,4]],"ltp":3.15,"tv":13574.8,"id":31379}]}]}
{"op":"mcm","clk":"11761654343","pt":1722522156653,"mc":[{"id":"1.231283997","rc":[{"batb":[[0,1.44,49],[1,1.43,216.66],[2,1.38,131.58]],"ltp":1.5,"tv":3.5,"id":169}]}]}
{"op":"mcm","clk":"11761654646","pt":1722522160844,"mc":[{"id":"1.231283997","rc":[{"batb":[[0,3.1,4],[1,3.05,16.95],[2,3,21.58]],"batl":[[0,3.3,4]],"ltp":3.15,"tv":13574.8,"id":31379},{"batb":[[0,1.45,4],[1,1.44,53],[2,1.43,216.66]],"ltp":1.5,"tv":3.5,"id":169}]}]}
{"op":"mcm","clk":"11761655340","pt":1722522173070,"mc":[{"id":"1.231283997","rc":[{"trd":[[3.1,4050.22]],"batb":[[0,3.05,17.05],[1,3,21.58],[2,1.43,116.28]],"ltp":3.1,"tv":13582.6,"id":31379}],"tv":13586.1}]}
{"op":"mcm","clk":"11761655497","pt":1722522175975,"mc":[{"id":"1.231283997","rc":[{"batl":[[0,3.25,4],[1,3.3,4]],"ltp":3.1,"tv":13582.6,"id":31379}]}]}
{"op":"mcm","clk":"11761656276","pt":1722522189090,"mc":[{"id":"1.231283997","rc":[{"batl":[[0,3.15,249.57],[1,3.25,4],[2,3.3,4]],"ltp":3.1,"tv":13582.6,"id":31379}]}]}
{"op":"mcm","clk":"11761656310","pt":1722522189607,"mc":[{"id":"1.231283997","rc":[{"batl":[[0,1.48,20.44]],"ltp":1.5,"tv":3.5,"id":169}]}]}
{"op":"mcm","clk":"11761656406","pt":1722522191098,"mc":[{"id":"1.231283997","rc":[{"batb":[[0,3.05,16.95]],"batl":[[0,3.1,3.9],[1,3.15,253.57],[2,3.25,4]],"ltp":3.1,"tv":13582.6,"id":31379},{"batb":[[0,1.47,4],[1,1.46,4],[2,1.45,4]],"ltp":1.5,"tv":3.5,"id":169}]}]}
{"op":"mcm","clk":"11761656842","pt":1722522199207,"mc":[{"id":"1.231283997","rc":[{"batb":[[0,1.44,49],[1,1.43,216.66],[2,1.38,131.58]],"ltp":1.5,"tv":3.5,"id":169}]}]}
{"op":"mcm","clk":"11761657243","pt":1722522206215,"mc":[{"id":"1.231283997","rc":[{"batl":[[0,3.3,4]],"ltp":3.1,"tv":13582.6,"id":31379},{"batb":[[0,1.45,4],[1,1.44,53],[2,1.43,216.66]],"batl":[[0,1.48,24.44]],"ltp":1.5,"tv":3.5,"id":169}]}]}
{"op":"mcm","clk":"11761657359","pt":1722522208232,"mc":[{"id":"1.231283997","rc":[{"batb":[[0,3.05,12.95]],"batl":[[0,3.1,249.57],[1,3.3,4]],"ltp":3.1,"tv":13582.6,"id":31379},{"batl":[[0,1.48,20.44]],"ltp":1.5,"tv":3.5,"id":169}]}]}
{"op":"mcm","clk":"11761658028","pt":1722522217816,"mc":[{"id":"1.231283997","rc":[{"trd":[[3.1,4440.18]],"batl":[[0,3.1,54.59]],"ltp":3.1,"tv":13972.55,"id":31379}],"tv":13976.05}]}
{"op":"mcm","clk":"11761658295","pt":1722522221338,"mc":[{"id":"1.231283997","rc":[{"batl":[[0,3.1,58.59]],"ltp":3.1,"tv":13972.55,"id":31379},{"batb":[[0,1.47,4],[1,1.45,4],[2,1.44,53]],"ltp":1.5,"tv":3.5,"id":169}]}]}
{"op":"mcm","clk":"11761658770","pt":1722522228653,"mc":[{"id":"1.231283997","rc":[{"trd":[[3.1,4471.37]],"batl":[[0,3.1,43]],"ltp":3.1,"tv":14003.75,"id":31379}],"tv":14007.25}]}
{"op":"mcm","clk":"11761659149","pt":1722522235136,"mc":[{"id":"1.231283997","rc":[{"batb":[[0,1.45,4],[1,1.44,53],[2,1.43,216.66]],"ltp":1.5,"tv":3.5,"id":169}]}]}
{"op":"mcm","clk":"11761659225","pt":1722522236471,"mc":[{"id":"1.231283997","rc":[{"batb":[[0,3.05,16.95]],"batl":[[0,3.25,4]],"ltp":3.1,"tv":14003.75,"id":31379},{"batl":[[0,1.48,24.44]],"ltp":1.5,"tv":3.5,"id":169}]}]}
{"op":"mcm","clk":"11761659813","pt":1722522245205,"mc":[{"id":"1.231283997","rc":[{"batb":[[0,3.05,12.95]],"batl":[[0,3.1,249.57],[1,3.25,4]],"ltp":3.1,"tv":14003.75,"id":31379},{"batl":[[0,1.48,20.44]],"ltp":1.5,"tv":3.5,"id":169}]}]}
{"op":"mcm","clk":"11761660235","pt":1722522251561,"mc":[{"id":"1.231283997","rc":[{"batl":[[0,3.1,253.57]],"ltp":3.1,"tv":14003.75,"id":31379},{"batb":[[0,1.47,4],[1,1.45,4],[2,1.44,53]],"ltp":1.5,"tv":3.5,"id":169}]}]}
{"op":"mcm","clk":"11761660948","pt":1722522263272,"mc":[{"id":"1.231283997","rc":[{"trd":[[3.1,4954.92]],"batl":[[0,3.1,7.8],[1,3.25,0]],"ltp":3.1,"tv":14487.29,"id":31379}],"tv":14490.79}]}
{"op":"mcm","clk":"11761661132","pt":1722522266686,"mc":[{"id":"1.231283997","rc":[{"batb":[[0,3.05,16.95]],"ltp":3.1,"tv":14487.29,"id":31379}]}]}
{"op":"mcm","clk":"11761661310","pt":1722522269784,"mc":[{"id":"1.231283997","rc":[{"trd":[[3.1,4962.71]],"batl":[[0,3.1,3.9]],"ltp":3.1,"tv":14495.09,"id":31379},{"batb":[[0,1.45,4],[1,1.44,53],[2,1.43,216.66]],"ltp":1.5,"tv":3.5,"id":169}],"tv":14498.59}]}
{"op":"mcm","clk":"11761662064","pt":1722522281795,"mc":[{"id":"1.231283997","rc":[{"batl":[[0,3.25,4]],"ltp":3.1,"tv":14495.09,"id":31379},{"batl":[[0,1.48,24.44]],"ltp":1.5,"tv":3.5,"id":169}]}]}
{"op":"mcm","clk":"11761663359","pt":1722522301513,"mc":[{"id":"1.231283997","rc":[{"batb":[[0,3.1,241.77],[1,3.05,16.95],[2,3,21.58]],"ltp":3.1,"tv":14495.09,"id":31379}]}]}
{"op":"mcm","clk":"11761663513","pt":1722522303908,"mc":[{"id":"1.231283997","rc":[{"batb":[[0,3.15,12.54],[1,3.1,241.77],[2,3.05,4]],"ltp":3.1,"tv":14495.09,"id":31379}]}]}
{"op":"mcm","clk":"11761664062","pt":1722522312041,"mc":[{"id":"1.231283997","rc":[{"batb":[[0,3.15,16.54]],"ltp":3.1,"tv":14495.09,"id":31379},{"batl":[[0,1.47,4],[1,1.48,24.44],[2,1.49,15.33]],"ltp":1.5,"tv":3.5,"id":169}]}]}
{"op":"mcm","clk":"11761664164","pt":1722522313646,"mc":[{"id":"1.231283997","rc":[{"trd":[[3.1,5448.15],[3.15,9563.46]],"batb":[[0,3.05,4],[1,3,21.58],[2,1.43,116.28]],"batl":[[0,3.1,12.76],[1,3.25,4]],"ltp":3.1,"tv":15013.61,"id":31379},{"trd":[[1.47,4]],"batl":[[0,1.48,24.44],[1,1.49,15.33],[2,1.51,30.66]],"ltp":1.47,"tv":7.5,"id":169}],"tv":15021.11}]}
{"op":"mcm","clk":"11761664362","pt":1722522317359,"mc":[{"id":"1.231283997","rc":[{"batl":[[0,3.25,4],[1,3.25,0]],"ltp":3.1,"tv":15013.61,"id":31379}]}]}
{"op":"mcm","clk":"11761665328","pt":1722522331555,"mc":[{"id":"1.231283997","rc":[{"batb":[[0,3.15,249.57],[1,3.05,4],[2,3,21.58]],"ltp":3.1,"tv":15013.61,"id":31379}]}]}
{"op":"mcm","clk":"11761665650","pt":1722522336569,"mc":[{"id":"1.231283997","rc":[{"trd":[[3.15,10062.61]],"batb":[[0,3.05,4],[1,3,21.58],[2,1.43,116.28]],"ltp":3.15,"tv":15512.75,"id":31379}],"tv":15520.25}]}
{"op":"mcm","clk":"11761666136","pt":1722522343957,"mc":[{"id":"1.231283997","rc":[{"batb":[[0,3.15,249.57],[1,3.05,4],[2,3,21.58]],"ltp":3.15,"tv":15512.75,"id":31379}]}]}
{"op":"mcm","clk":"11761666393","pt":1722522348458,"mc":[{"id":"1.231283997","rc":[{"trd":[[3.15,10561.75]],"batb":[[0,3.05,4],[1,3,21.58],[2,1.43,116.28]],"ltp":3.15,"tv":16011.9,"id":31379}],"tv":16019.4}]}
{"op":"mcm","clk":"11761666699","pt":1722522354145,"mc":[{"id":"1.231283997","rc":[{"batb":[[0,3.15,249.57],[1,3.05,4],[2,3,21.58]],"ltp":3.15,"tv":16011.9,"id":31379}]}]}
{"op":"mcm","clk":"11761666916","pt":1722522358279,"mc":[{"id":"1.231283997","rc":[{"trd":[[3.15,11060.89]],"batb":[[0,3,21.58],[1,1.43,116.28],[2,1.38,131.58]],"ltp":3.15,"tv":16511.04,"id":31379},{"batl":[[0,1.48,20.44]],"ltp":1.47,"tv":7.5,"id":169}],"tv":16518.54}]}
{"op":"mcm","clk":"11761667263","pt":1722522363866,"mc":[{"id":"1.231283997","rc":[{"batb":[[0,3.15,249.57],[1,3,21.58],[2,1.43,116.28]],"ltp":3.15,"tv":16511.04,"id":31379}]}]}
{"op":"mcm","clk":"11761667503","pt":1722522367684,"mc":[{"id":"1.231283997","rc":[{"trd":[[3.15,11560.03]],"batb":[[0,3,21.58],[1,1.43,116.28],[2,1.38,131.58]],"ltp":3.15,"tv":17010.18,"id":31379}],"tv":17017.68}]}
{"op":"mcm","clk":"11761667841","pt":1722522372823,"mc":[{"id":"1.231283997","rc":[{"batb":[[0,3.15,249.57],[1,3.05,4],[2,3,21.58]],"ltp":3.15,"tv":17010.18,"id":31379},{"batl":[[0,1.48,24.44]],"ltp":1.47,"tv":7.5,"id":169}]}]}
{"op":"mcm","clk":"11761668082","pt":1722522376295,"mc":[{"id":"1.231283997","rc":[{"trd":[[3.15,12059.17]],"batb":[[0,3.05,4],[1,3,21.58],[2,1.43,116.28]],"ltp":3.15,"tv":17509.32,"id":31379}],"tv":17516.82}]}
{"op":"mcm","clk":"11761668449","pt":1722522382184,"mc":[{"id":"1.231283997","rc":[{"batb":[[0,3.15,249.57],[1,3.05,4],[2,3,21.58]],"ltp":3.15,"tv":17509.32,"id":31379}]}]}
{"op":"mcm","clk":"11761668625","pt":1722522385401,"mc":[{"id":"1.231283997","rc":[{"trd":[[3.15,12558.32]],"batb":[[0,3.05,4],[1,3,21.58],[2,1.43,116.28]],"ltp":3.15,"tv":18008.46,"id":31379}],"tv":18015.96}]}
{"op":"mcm","clk":"11761669024","pt":1722522391909,"mc":[{"id":"1.231283997","rc":[{"batb":[[0,3.15,249.57],[1,3.05,4],[2,3,21.58]],"ltp":3.15,"tv":18008.46,"id":31379}]}]}
{"op":"mcm","clk":"11761669204","pt":1722522395110,"mc":[{"id":"1.231283997","rc":[{"trd":[[3.15,13057.46]],"batb":[[0,3.05,4],[1,3,21.58],[2,1.43,116.28]],"ltp":3.15,"tv":18507.61,"id":31379}],"tv":18515.11}]}
{"op":"mcm","clk":"11761669544","pt":1722522400833,"mc":[{"id":"1.231283997","rc":[{"batb":[[0,3.15,249.57],[1,3.05,4],[2,3,21.58]],"ltp":3.15,"tv":18507.61,"id":31379}]}]}
{"op":"mcm","clk":"11761669679","pt":1722522402807,"mc":[{"id":"1.231283997","rc":[{"batb":[[0,3.15,253.57]],"ltp":3.15,"tv":18507.61,"id":31379},{"batl":[[0,1.47,4],[1,1.48,24.44],[2,1.49,15.33]],"ltp":1.47,"tv":7.5,"id":169}]}]}
{"op":"mcm","clk":"11761669802","pt":1722522404819,"mc":[{"id":"1.231283997","rc":[{"trd":[[3.15,13556.6]],"batb":[[0,3,21.58],[1,1.43,116.28],[2,1.38,131.58]],"ltp":3.15,"tv":19006.75,"id":31379},{"batl":[[0,1.48,20.44],[1,1.49,15.33],[2,1.51,30.66]],"ltp":1.47,"tv":7.5,"id":169}],"tv":19014.25}]}
{"op":"mcm","clk":"11761670634","pt":1722522417827,"mc":[{"id":"1.231283997","rc":[{"batb":[[0,3.05,4],[1,3,21.58],[2,1.43,116.28]],"ltp":3.15,"tv":19006.75,"id":31379},{"batl":[[0,1.48,24.44]],"ltp":1.47,"tv":7.5,"id":169}]}]}
{"op":"mcm","clk":"11761671205","pt":1722522426367,"mc":[{"id":"1.231283997","rc":[{"batb":[[0,3.15,249.57],[1,3.05,4],[2,3,21.58]],"ltp":3.15,"tv":19006.75,"id":31379}]}]}
{"op":"mcm","clk":"11761671488","pt":1722522431173,"mc":[{"id":"1.231283997","rc":[{"trd":[[3.15,14055.74]],"batb":[[0,3.05,4],[1,3,21.58],[2,1.43,116.28]],"ltp":3.15,"tv":19505.89,"id":31379}],"tv":19513.39}]}
{"op":"mcm","clk":"11761671860","pt":1722522436970,"mc":[{"id":"1.231283997","rc":[{"batb":[[0,3.15,249.57],[1,3.05,4],[2,3,21.58]],"ltp":3.15,"tv":19505.89,"id":31379}]}]}
{"op":"mcm","clk":"11761672112","pt":1722522440385,"mc":[{"id":"1.231283997","rc":[{"trd":[[3.15,14554.88]],"batb":[[0,3.05,4],[1,3,21.58],[2,1.43,116.28]],"ltp":3.15,"tv":20005.03,"id":31379}],"tv":20012.53}]}
{"op":"mcm","clk":"11761672520","pt":1722522445666,"mc":[{"id":"1.231283997","rc":[{"batb":[[0,3.15,249.57],[1,3.05,4],[2,3,21.58]],"ltp":3.15,"tv":20005.03,"id":31379}]}]}
{"op":"mcm","clk":"11761672701","pt":1722522448060,"mc":[{"id":"1.231283997","rc":[{"batb":[[0,3.15,253.57]],"ltp":3.15,"tv":20005.03,"id":31379},{"batl":[[0,1.47,4],[1,1.48,24.44],[2,1.49,15.33]],"ltp":1.47,"tv":7.5,"id":169}]}]}
{"op":"mcm","clk":"11761672800","pt":1722522449252,"mc":[{"id":"1.231283997","rc":[{"trd":[[3.15,15054.03]],"batb":[[0,3,21.58],[1,1.43,116.28],[2,1.38,131.58]],"ltp":3.15,"tv":20504.17,"id":31379},{"batl":[[0,1.48,20.44],[1,1.49,15.33],[2,1.51,30.66]],"ltp":1.47,"tv":7.5,"id":169}],"tv":20511.67}]}
{"op":"mcm","clk":"11761673811","pt":1722522463171,"mc":[{"id":"1.231283997","rc":[{"batb":[[0,3.15,249.57],[1,3.05,4],[2,3,21.58]],"ltp":3.15,"tv":20504.17,"id":31379},{"batl":[[0,1.48,24.44]],"ltp":1.47,"tv":7.5,"id":169}]}]}
{"op":"mcm","clk":"11761674056","pt":1722522466987,"mc":[{"id":"1.231283997","rc":[{"trd":[[3.15,15553.17]],"batb":[[0,3.05,4],[1,3,21.58],[2,1.43,116.28]],"ltp":3.15,"tv":21003.32,"id":31379}],"tv":21010.82}]}
{"op":"mcm","clk":"11761674458","pt":1722522474080,"mc":[{"id":"1.231283997","rc":[{"batb":[[0,3.15,249.57],[1,3.05,4],[2,3,21.58]],"ltp":3.15,"tv":21003.32,"id":31379}]}]}
{"op":"mcm","clk":"11761674674","pt":1722522477485,"mc":[{"id":"1.231283997","rc":[{"trd":[[3.15,16052.31]],"batb":[[0,3.05,4],[1,3,21.58],[2,1.43,116.28]],"ltp":3.15,"tv":21502.46,"id":31379}],"tv":21509.96}]}
{"op":"mcm","clk":"11761675194","pt":1722522483972,"mc":[{"id":"1.231283997","rc":[{"batb":[[0,3.15,249.57],[1,3.05,4],[2,3,21.58]],"ltp":3.15,"tv":21502.46,"id":31379}]}]}
{"op":"mcm","clk":"11761675438","pt":1722522487209,"mc":[{"id":"1.231283997","rc":[{"trd":[[3.15,16551.45]],"batb":[[0,3.05,4],[1,3,21.58],[2,1.43,116.28]],"ltp":3.15,"tv":22001.6,"id":31379}],"tv":22009.1}]}
{"op":"mcm","clk":"11761675922","pt":1722522493200,"mc":[{"id":"1.231283997","rc":[{"batb":[[0,3.15,249.57],[1,3.05,4],[2,3,21.58]],"ltp":3.15,"tv":22001.6,"id":31379}]}]}
{"op":"mcm","clk":"11761676171","pt":1722522496500,"mc":[{"id":"1.231283997","rc":[{"trd":[[3.15,17050.59]],"batb":[[0,3.05,4],[1,3,21.58],[2,1.43,116.28]],"ltp":3.15,"tv":22500.74,"id":31379}],"tv":22508.24}]}
{"op":"mcm","clk":"11761676595","pt":1722522502518,"mc":[{"id":"1.231283997","rc":[{"batb":[[0,3.15,249.57],[1,3.05,4],[2,3,21.58]],"ltp":3.15,"tv":22500.74,"id":31379}]}]}
{"op":"mcm","clk":"11761676844","pt":1722522506025,"mc":[{"id":"1.231283997","rc":[{"trd":[[3.15,17549.74]],"batb":[[0,3.05,4],[1,3,21.58],[2,1.43,116.28]],"ltp":3.15,"tv":22999.89,"id":31379}],"tv":23007.39}]}
{"op":"mcm","clk":"11761677330","pt":1722522512635,"mc":[{"id":"1.231283997","rc":[{"batb":[[0,3.15,249.57],[1,3.05,4],[2,3,21.58]],"ltp":3.15,"tv":22999.89,"id":31379}]}]}
{"op":"mcm","clk":"11761677566","pt":1722522516036,"mc":[{"id":"1.231283997","rc":[{"trd":[[3.15,18048.88]],"batb":[[0,3.05,4],[1,3,21.58],[2,1.43,116.28]],"ltp":3.15,"tv":23499.03,"id":31379}],"tv":23506.53}]}
{"op":"mcm","clk":"11761677947","pt":1722522521823,"mc":[{"id":"1.231283997","rc":[{"batb":[[0,3.15,249.57],[1,3.05,4],[2,3,21.58]],"ltp":3.15,"tv":23499.03,"id":31379}]}]}
{"op":"mcm","clk":"11761678042","pt":1722522523549,"mc":[{"id":"1.231283997","rc":[{"batb":[[0,3.15,253.57]],"ltp":3.15,"tv":23499.03,"id":31379},{"batl":[[0,1.47,4],[1,1.48,24.44],[2,1.49,15.33]],"ltp":1.47,"tv":7.5,"id":169}]}]}
{"op":"mcm","clk":"11761678156","pt":1722522525349,"mc":[{"id":"1.231283997","rc":[{"trd":[[3.15,18548.02]],"batb":[[0,3.15,4]],"ltp":3.15,"tv":23998.17,"id":31379}],"tv":24005.67}]}
{"op":"mcm","clk":"11761678196","pt":1722522525824,"mc":[{"id":"1.231283997","rc":[{"batb":[[0,3,21.58],[1,1.43,116.28],[2,1.38,131.58]],"ltp":3.15,"tv":23998.17,"id":31379},{"batl":[[0,1.48,20.44],[1,1.49,15.33],[2,1.51,30.66]],"ltp":1.47,"tv":7.5,"id":169}]}]}
{"op":"mcm","clk":"11761678546","pt":1722522531533,"mc":[{"id":"1.231283997","rc":[{"batb":[[0,3.15,249.57],[1,3,21.58],[2,1.43,116.28]],"ltp":3.15,"tv":23998.17,"id":31379}]}]}
{"op":"mcm","clk":"11761678768","pt":1722522534947,"mc":[{"id":"1.231283997","rc":[{"trd":[[3.15,19047.16]],"batb":[[0,3,21.58],[1,1.43,116.28],[2,1.38,131.58]],"ltp":3.15,"tv":24497.31,"id":31379}],"tv":24504.81}]}
{"op":"mcm","clk":"11761679019","pt":1722522538654,"mc":[{"id":"1.231283997","rc":[{"batb":[[0,3.05,4],[1,3,21.58],[2,1.43,116.28]],"ltp":3.15,"tv":24497.31,"id":31379},{"batl":[[0,1.48,24.44]],"ltp":1.47,"tv":7.5,"id":169}]}]}
{"op":"mcm","clk":"11761679225","pt":1722522541457,"mc":[{"id":"1.231283997","rc":[{"batb":[[0,3.15,249.57],[1,3.05,4],[2,3,21.58]],"ltp":3.15,"tv":24497.31,"id":31379}]}]}
{"op":"mcm","clk":"11761679537","pt":1722522545650,"mc":[{"id":"1.231283997","rc":[{"trd":[[3.15,19546.31]],"batb":[[0,3.05,4],[1,3,21.58],[2,1.43,116.28]],"ltp":3.15,"tv":24996.45,"id":31379}],"tv":25003.95}]}
{"op":"mcm","clk":"11761680006","pt":1722522551967,"mc":[{"id":"1.231283997","rc":[{"batb":[[0,3.15,249.57],[1,3.05,4],[2,3,21.58]],"ltp":3.15,"tv":24996.45,"id":31379}]}]}
{"op":"mcm","clk":"11761680156","pt":1722522553874,"mc":[{"id":"1.231283997","rc":[{"batb":[[0,3.15,253.57]],"ltp":3.15,"tv":24996.45,"id":31379},{"batl":[[0,1.47,4],[1,1.48,24.44],[2,1.49,15.33]],"ltp":1.47,"tv":7.5,"id":169}]}]}
{"op":"mcm","clk":"11761680301","pt":1722522555843,"mc":[{"id":"1.231283997","rc":[{"trd":[[3.15,20045.45]],"batb":[[0,3.15,4]],"ltp":3.15,"tv":25495.6,"id":31379}],"tv":25503.1}]}
{"op":"mcm","clk":"11761680341","pt":1722522556457,"mc":[{"id":"1.231283997","rc":[{"batb":[[0,3,21.58],[1,1.43,116.28],[2,1.38,131.58]],"ltp":3.15,"tv":25495.6,"id":31379},{"batl":[[0,1.48,20.44],[1,1.49,15.33],[2,1.51,30.66]],"ltp":1.47,"tv":7.5,"id":169}]}]}
{"op":"mcm","clk":"11761680668","pt":1722522561159,"mc":[{"id":"1.231283997","rc":[{"batb":[[0,3.15,249.57],[1,3,21.58],[2,1.43,116.28]],"ltp":3.15,"tv":25495.6,"id":31379}]}]}
{"op":"mcm","clk":"11761681008","pt":1722522565748,"mc":[{"id":"1.231283997","rc":[{"trd":[[3.15,20544.59]],"batb":[[0,3,21.58],[1,1.43,116.28],[2,1.38,131.58]],"ltp":3.15,"tv":25994.74,"id":31379}],"tv":26002.24}]}
{"op":"mcm","clk":"11761681265","pt":1722522568851,"mc":[{"id":"1.231283997","rc":[{"batb":[[0,3.05,4],[1,3,21.58],[2,1.43,116.28]],"ltp":3.15,"tv":25994.74,"id":31379},{"batl":[[0,1.48,24.44]],"ltp":1.47,"tv":7.5,"id":169}]}]}
{"op":"mcm","clk":"11761681526","pt":1722522572172,"mc":[{"id":"1.231283997","rc":[{"batb":[[0,3.15,249.57],[1,3.05,4],[2,3,21.58]],"ltp":3.15,"tv":25994.74,"id":31379}]}]}
{"op":"mcm","clk":"11761681791","pt":1722522575590,"mc":[{"id":"1.231283997","rc":[{"trd":[[3.15,21043.73]],"batb":[[0,3.05,4],[1,3,21.58],[2,1.43,116.28]],"ltp":3.15,"tv":26493.88,"id":31379}],"tv":26501.38}]}
{"op":"mcm","clk":"11761682259","pt":1722522581977,"mc":[{"id":"1.231283997","rc":[{"batb":[[0,3.15,249.57],[1,3.05,4],[2,3,21.58]],"ltp":3.15,"tv":26493.88,"id":31379}]}]}
{"op":"mcm","clk":"11761682397","pt":1722522583994,"mc":[{"id":"1.231283997","rc":[{"batb":[[0,3.15,253.57]],"ltp":3.15,"tv":26493.88,"id":31379},{"batl":[[0,1.47,4],[1,1.48,24.44],[2,1.49,15.33]],"ltp":1.47,"tv":7.5,"id":169}]}]}
{"op":"mcm","clk":"11761682462","pt":1722522585175,"mc":[{"id":"1.231283997","rc":[{"trd":[[3.15,21542.87]],"batb":[[0,3.15,4]],"ltp":3.15,"tv":26993.02,"id":31379}],"tv":27000.52}]}
{"op":"mcm","clk":"11761682481","pt":1722522585497,"mc":[{"id":"1.231283997","rc":[{"batb":[[0,3,21.58],[1,1.43,116.28],[2,1.38,131.58]],"ltp":3.15,"tv":26993.02,"id":31379},{"batl":[[0,1.48,20.44],[1,1.49,15.33],[2,1.51,30.66]],"ltp":1.47,"tv":7.5,"id":169}]}]}
{"op":"mcm","clk":"11761682820","pt":1722522591308,"mc":[{"id":"1.231283997","rc":[{"batb":[[0,3.15,249.57],[1,3,21.58],[2,1.43,116.28]],"ltp":3.15,"tv":26993.02,"id":31379}]}]}
{"op":"mcm","clk":"11761682870","pt":1722522592177,"mc":[{"id":"1.231283997","rc":[{"batb":[[0,3.2,7.77],[1,3.15,249.57]],"ltp":3.15,"tv":26993.02,"id":31379},{"batb":[[2,1.43,116.28]],"ltp":1.47,"tv":7.5,"id":169}]}]}
{"op":"mcm","clk":"11761683030","pt":1722522594820,"mc":[{"id":"1.231283997","rc":[{"trd":[[3.15,22026.48],[3.2,15.54]],"batb":[[0,3.15,7.77],[1,1.43,116.28],[2,1.38,131.58]],"ltp":3.15,"tv":27492.17,"id":31379}],"tv":27499.67}]}
{"op":"mcm","clk":"11761683180","pt":1722522597197,"mc":[{"id":"1.231283997","rc":[{"batb":[[1,3,21.58],[2,1.43,116.28]],"batl":[[0,3.25,11.65]],"ltp":3.15,"tv":27492.17,"id":31379},{"batb":[[2,1.43,216.66]],"ltp":1.47,"tv":7.5,"id":169}]}]}
{"op":"mcm","clk":"11761683595","pt":1722522602604,"mc":[{"id":"1.231283997","rc":[{"batl":[[0,3.2,7.02],[1,3.25,11.65]],"ltp":3.15,"tv":27492.17,"id":31379}]}]}
{"op":"mcm","clk":"11761684387","pt":1722522611827,"mc":[{"id":"1.231283997","rc":[{"trd":[[3.15,22040.52]],"batb":[[0,3,22.33],[1,1.43,116.28],[2,1.38,131.58]],"batl":[[0,3.25,11.65],[1,3.25,0]],"ltp":3.15,"tv":27506.2,"id":31379}],"tv":27513.7}]}
{"op":"mcm","clk":"11761684572","pt":1722522614233,"mc":[{"id":"1.231283997","rc":[{"batb":[[0,3.05,4.75],[1,3,21.58],[2,1.43,116.28]],"ltp":3.15,"tv":27506.2,"id":31379}]}]}
{"op":"mcm","clk":"11761685137","pt":1722522621928,"mc":[{"id":"1.231283997","rc":[{"batb":[[0,3.05,4]],"batl":[[0,3.15,248.82],[1,3.25,11.65]],"ltp":3.15,"tv":27506.2,"id":31379}]}]}
{"op":"mcm","clk":"11761685178","pt":1722522622547,"mc":[{"id":"1.231283997","rc":[{"batb":[[0,3,21.58],[1,1.43,116.28],[2,1.38,131.58]],"ltp":3.15,"tv":27506.2,"id":31379}]}]}
{"op":"mcm","clk":"11761685274","pt":1722522623842,"mc":[{"id":"1.231283997","rc":[{"batl":[[0,3.1,20.24],[1,3.15,248.82],[2,3.25,4]],"ltp":3.15,"tv":27506.2,"id":31379}]}]}
{"op":"mcm","clk":"11761685610","pt":1722522628044,"mc":[{"id":"1.231283997","rc":[{"trd":[[3.1,5488.64],[3.15,22499.17]],"batl":[[0,3.15,19.5],[1,3.25,4],[2,3.25,0]],"ltp":3.15,"tv":28005.34,"id":31379}],"tv":28012.84}]}
{"op":"mcm","clk":"11761685704","pt":1722522629331,"mc":[{"id":"1.231283997","rc":[{"batb":[[0,3.05,4],[1,3,21.58],[2,1.43,116.28]],"batl":[[0,3.15,23.5]],"ltp":3.15,"tv":28005.34,"id":31379},{"batb":[[0,1.46,4],[1,1.45,4],[2,1.44,53]],"batl":[[0,1.48,24.44]],"ltp":1.47,"tv":7.5,"id":169}]}]}
{"op":"mcm","clk":"11761685727","pt":1722522629625,"mc":[{"id":"1.231283997","rc":[{"batb":[[0,3.05,16.42]],"ltp":3.15,"tv":28005.34,"id":31379}]}]}
{"op":"mcm","clk":"11761686745","pt":1722522641965,"mc":[{"id":"1.231283997","rc":[{"batb":[[0,1.45,4],[1,1.44,53],[2,1.43,216.66]],"ltp":1.47,"tv":7.5,"id":169}]}]}
{"op":"mcm","clk":"11761686950","pt":1722522644448,"mc":[{"id":"1.231283997","rc":[{"batl":[[0,3.25,4]],"ltp":3.15,"tv":28005.34,"id":31379}]}]}
{"op":"mcm","clk":"11761687464","pt":1722522650871,"mc":[{"id":"1.231283997","rc":[{"batl":[[0,3.15,249.57],[1,3.25,4]],"ltp":3.15,"tv":28005.34,"id":31379}]}]}
{"op":"mcm","clk":"11761687508","pt":1722522651445,"mc":[{"id":"1.231283997","rc":[{"batl":[[0,1.48,20.44]],"ltp":1.47,"tv":7.5,"id":169}]}]}
{"op":"mcm","clk":"11761688070","pt":1722522660062,"mc":[{"id":"1.231283997","rc":[{"trd":[[3.1,5496.64],[3.15,22959.11]],"batl":[[0,3.15,23.6]],"ltp":3.15,"tv":28473.29,"id":31379},{"batb":[[0,1.47,4],[1,1.46,4],[2,1.45,4]],"ltp":1.47,"tv":7.5,"id":169}],"tv":28480.79}]}
{"op":"mcm","clk":"11761688800","pt":1722522670781,"mc":[{"id":"1.231283997","rc":[{"trd":[[3.15,22960.67]],"batl":[[0,3.15,22.82]],"ltp":3.15,"tv":28474.85,"id":31379}],"tv":28482.35}]}
{"op":"mcm","clk":"11761689105","pt":1722522674878,"mc":[{"id":"1.231283997","rc":[{"batl":[[0,3.15,4]],"ltp":3.15,"tv":28474.85,"id":31379},{"batl":[[0,1.48,24.44]],"ltp":1.47,"tv":7.5,"id":169}]}]}
{"op":"mcm","clk":"11761689142","pt":1722522675507,"mc":[{"id":"1.231283997","rc":[{"batb":[[0,1.44,49],[1,1.43,216.66],[2,1.38,131.58]],"ltp":1.47,"tv":7.5,"id":169}]}]}
{"op":"mcm","clk":"11761690201","pt":1722522689802,"mc":[{"id":"1.231283997","rc":[{"batl":[[0,3.3,4]],"ltp":3.15,"tv":28474.85,"id":31379},{"batb":[[0,1.45,4],[1,1.44,53],[2,1.43,216.66]],"ltp":1.47,"tv":7.5,"id":169}]}]}
{"op":"mcm","clk":"11761691337","pt":1722522704926,"mc":[{"id":"1.231283997","rc":[{"batb":[[0,3.15,233.97],[1,3.05,16.42],[2,3,21.58]],"batl":[[0,3.25,4],[1,3.3,4]],"ltp":3.15,"tv":28474.85,"id":31379}]}]}
{"op":"mcm","clk":"11761691395","pt":1722522705604,"mc":[{"id":"1.231283997","rc":[{"batb":[[0,3.2,19.56],[1,3.15,233.97],[2,3.05,4]],"ltp":3.15,"tv":28474.85,"id":31379}]}]}
{"op":"mcm","clk":"11761691543","pt":1722522707732,"mc":[{"id":"1.231283997","rc":[{"batb":[[2,1.43,116.28]],"ltp":1.47,"tv":7.5,"id":169}]}]}
{"op":"mcm","clk":"11761691920","pt":1722522713020,"mc":[{"id":"1.231283997","rc":[{"trd":[[3.15,23420.69],[3.2,54.66]],"batb":[[0,3.15,3.96],[1,3.05,4],[2,3,21.58]],"ltp":3.15,"tv":28973.99,"id":31379},{"batb":[[2,1.43,216.66]],"batl":[[0,1.48,20.44]],"ltp":1.47,"tv":7.5,"id":169}],"tv":28981.49}]}
{"op":"mcm","clk":"11761691990","pt":1722522714005,"mc":[{"id":"1.231283997","rc":[{"batl":[[0,3.25,11.6]],"ltp":3.15,"tv":28973.99,"id":31379}]}]}
{"op":"mcm","clk":"11761692415","pt":1722522719418,"mc":[{"id":"1.231283997","rc":[{"batl":[[0,3.2,3.9],[1,3.25,11.6],[2,3.3,4]],"ltp":3.15,"tv":28973.99,"id":31379}]}]}
{"op":"mcm","clk":"11761692878","pt":1722522725857,"mc":[{"id":"1.231283997","rc":[{"trd":[[3.15,23428.49]],"batb":[[0,3.05,4.06],[1,3,21.58],[2,1.43,116.28]],"batl":[[0,3.25,11.6],[1,3.3,4],[2,3.3,0]],"ltp":3.15,"tv":28981.78,"id":31379}],"tv":28989.28}]}
{"op":"mcm","clk":"11761693419","pt":1722522732137,"mc":[{"id":"1.231283997","rc":[{"batb":[[0,3.05,4]],"ltp":3.15,"tv":28981.78,"id":31379}]}]}
{"op":"mcm","clk":"11761693633","pt":1722522735164,"mc":[{"id":"1.231283997","rc":[{"batl":[[0,1.48,24.44]],"ltp":1.47,"tv":7.5,"id":169}]}]}
{"op":"mcm","clk":"11761694250","pt":1722522744552,"mc":[{"id":"1.231283997","rc":[{"batb":[[0,3.15,249.57],[1,3.05,4],[2,3,21.58]],"ltp":3.15,"tv":28981.78,"id":31379}]}]}
{"op":"mcm","clk":"11761694450","pt":1722522747760,"mc":[{"id":"1.231283997","rc":[{"trd":[[3.15,23927.63]],"batb":[[0,3.05,4],[1,3,21.58],[2,1.43,116.28]],"ltp":3.15,"tv":29480.93,"id":31379}],"tv":29488.43}]}
{"op":"mcm","clk":"11761694928","pt":1722522754837,"mc":[{"id":"1.231283997","rc":[{"batb":[[0,3.15,249.57],[1,3.05,4],[2,3,21.58]],"ltp":3.15,"tv":29480.93,"id":31379}]}]}
{"op":"mcm","clk":"11761695143","pt":1722522758131,"mc":[{"id":"1.231283997","rc":[{"trd":[[3.15,24426.78]],"batb":[[0,3.05,4],[1,3,21.58],[2,1.43,116.28]],"ltp":3.15,"tv":29980.07,"id":31379}],"tv":29987.57}]}
{"op":"mcm","clk":"11761695563","pt":1722522765369,"mc":[{"id":"1.231283997","rc":[{"batb":[[0,3.15,249.57],[1,3.05,4],[2,3,21.58]],"ltp":3.15,"tv":29980.07,"id":31379}]}]}
{"op":"mcm","clk":"11761695772","pt":1722522768573,"mc":[{"id":"1.231283997","rc":[{"trd":[[3.15,24925.92]],"batb":[[0,3.05,4],[1,3,21.58],[2,1.43,116.28]],"ltp":3.15,"tv":30479.21,"id":31379}],"tv":30486.71}]}
{"op":"mcm","clk":"11761696096","pt":1722522774045,"mc":[{"id":"1.231283997","rc":[{"batb":[[0,3.15,249.57],[1,3.05,4],[2,3,21.58]],"ltp":3.15,"tv":30479.21,"id":31379}]}]}
{"op":"mcm","clk":"11761696366","pt":1722522777964,"mc":[{"id":"1.231283997","rc":[{"trd":[[3.15,25425.06]],"batb":[[0,3.05,4],[1,3,21.58],[2,1.43,116.28]],"ltp":3.15,"tv":30978.35,"id":31379}],"tv":30985.85}]}
{"op":"mcm","clk":"11761696829","pt":1722522783789,"mc":[{"id":"1.231283997","rc":[{"batb":[[0,3.15,249.57],[1,3.05,4],[2,3,21.58]],"ltp":3.15,"tv":30978.35,"id":31379}]}]}
{"op":"mcm","clk":"11761697107","pt":1722522787175,"mc":[{"id":"1.231283997","rc":[{"trd":[[3.15,25924.2]],"batb":[[0,3.05,4],[1,3,21.58],[2,1.43,116.28]],"ltp":3.15,"tv":31477.5,"id":31379}],"tv":31485.0}]}
{"op":"mcm","clk":"11761697647","pt":1722522793470,"mc":[{"id":"1.231283997","rc":[{"batb":[[0,3.15,249.57],[1,3.05,4],[2,3,21.58]],"ltp":3.15,"tv":31477.5,"id":31379}]}]}
{"op":"mcm","clk":"11761697818","pt":1722522795485,"mc":[{"id":"1.231283997","rc":[{"batb":[[0,3.15,253.57]],"ltp":3.15,"tv":31477.5,"id":31379},{"batl":[[0,1.47,4],[1,1.48,24.44],[2,1.49,15.33]],"ltp":1.47,"tv":7.5,"id":169}]}]}
{"op":"mcm","clk":"11761697942","pt":1722522797000,"mc":[{"id":"1.231283997","rc":[{"trd":[[3.15,26423.34]],"batb":[[0,3.15,4]],"ltp":3.15,"tv":31976.64,"id":31379}],"tv":31984.14}]}
{"op":"mcm","clk":"11761697989","pt":1722522797613,"mc":[{"id":"1.231283997","rc":[{"batb":[[0,3,21.58],[1,1.43,116.28],[2,1.38,131.58]],"ltp":3.15,"tv":31976.64,"id":31379},{"batl":[[0,1.48,20.44],[1,1.49,15.33],[2,1.51,30.66]],"ltp":1.47,"tv":7.5,"id":169}]}]}
{"op":"mcm","clk":"11761698551","pt":1722522806113,"mc":[{"id":"1.231283997","rc":[{"batb":[[0,3.15,249.57],[1,3,21.58],[2,1.43,116.28]],"ltp":3.15,"tv":31976.64,"id":31379}]}]}
{"op":"mcm","clk":"11761698817","pt":1722522809998,"mc":[{"id":"1.231283997","rc":[{"trd":[[3.15,26922.49]],"batb":[[0,3,21.58],[1,1.43,116.28],[2,1.38,131.58]],"ltp":3.15,"tv":32475.78,"id":31379}],"tv":32483.28}]}
{"op":"mcm","clk":"11761699289","pt":1722522816219,"mc":[{"id":"1.231283997","rc":[{"batb":[[0,3.15,249.57],[1,3,21.58],[2,1.43,116.28]],"ltp":3.15,"tv":32475.78,"id":31379}]}]}
{"op":"mcm","clk":"11761699505","pt":1722522819715,"mc":[{"id":"1.231283997","rc":[{"trd":[[3.15,27421.63]],"batb":[[0,3,21.58],[1,1.43,116.28],[2,1.38,131.58]],"ltp":3.15,"tv":32974.92,"id":31379}],"tv":32982.42}]}
{"op":"mcm","clk":"11761699915","pt":1722522825722,"mc":[{"id":"1.231283997","rc":[{"batb":[[0,3.05,4],[1,3,21.58],[2,1.43,116.28]],"ltp":3.15,"tv":32974.92,"id":31379},{"batl":[[0,1.48,24.44]],"ltp":1.47,"tv":7.5,"id":169}]}]}
{"op":"mcm","clk":"11761700083","pt":1722522827731,"mc":[{"id":"1.231283997","rc":[{"batb":[[0,3.15,249.57],[1,3.05,4],[2,3,21.58]],"ltp":3.15,"tv":32974.92,"id":31379}]}]}
{"op":"mcm","clk":"11761700336","pt":1722522831250,"mc":[{"id":"1.231283997","rc":[{"trd":[[3.15,27920.77]],"batb":[[0,3.05,4],[1,3,21.58],[2,1.43,116.28]],"ltp":3.15,"tv":33474.06,"id":31379}],"tv":33481.56}]}
{"op":"mcm","clk":"11761700770","pt":1722522837519,"mc":[{"id":"1.231283997","rc":[{"batb":[[0,3.15,249.57],[1,3.05,4],[2,3,21.58]],"ltp":3.15,"tv":33474.06,"id":31379}]}]}
{"op":"mcm","clk":"11761701007","pt":1722522840841,"mc":[{"id":"1.231283997","rc":[{"batb":[[0,3.15,253.57]],"ltp":3.15,"tv":33474.06,"id":31379},{"batl":[[0,1.47,4],[1,1.48,24.44],[2,1.49,15.33]],"ltp":1.47,"tv":7.5,"id":169}]}]}
{"op":"mcm","clk":"11761701101","pt":1722522842137,"mc":[{"id":"1.231283997","rc":[{"trd":[[3.15,28419.91]],"batb":[[0,3,21.58],[1,1.43,116.28],[2,1.38,131.58]],"ltp":3.15,"tv":33973.21,"id":31379},{"batl":[[0,1.48,20.44],[1,1.49,15.33],[2,1.51,30.66]],"ltp":1.47,"tv":7.5,"id":169}],"tv":33980.71}]}
{"op":"mcm","clk":"11761701461","pt":1722522847461,"mc":[{"id":"1.231283997","rc":[{"batb":[[0,3.15,249.57],[1,3,21.58],[2,1.43,116.28]],"ltp":3.15,"tv":33973.21,"id":31379}]}]}
{"op":"mcm","clk":"11761701716","pt":1722522851051,"mc":[{"id":"1.231283997","rc":[{"trd":[[3.15,28919.06]],"batb":[[0,3,21.58],[1,1.43,116.28],[2,1.38,131.58]],"ltp":3.15,"tv":34472.35,"id":31379}],"tv":34479.85}]}
{"op":"mcm","clk":"11761702078","pt":1722522855978,"mc":[{"id":"1.231283997","rc":[{"batb":[[0,3.05,4],[1,3,21.58],[2,1.43,116.28]],"ltp":3.15,"tv":34472.35,"id":31379},{"batl":[[0,1.48,24.44]],"ltp":1.47,"tv":7.5,"id":169}]}]}
{"op":"mcm","clk":"11761702170","pt":1722522857468,"mc":[{"id":"1.231283997","rc":[{"batb":[[0,3.15,249.57],[1,3.05,4],[2,3,21.58]],"ltp":3.15,"tv":34472.35,"id":31379}]}]}
{"op":"mcm","clk":"11761702374","pt":1722522860783,"mc":[{"id":"1.231283997","rc":[{"trd":[[3.15,29418.2]],"batb":[[0,3.05,4],[1,3,21.58],[2,1.43,116.28]],"ltp":3.15,"tv":34971.49,"id":31379}],"tv":34978.99}]}
{"op":"mcm","clk":"11761702835","pt":1722522867085,"mc":[{"id":"1.231283997","rc":[{"batb":[[0,3.15,249.57],[1,3.05,4],[2,3,21.58]],"ltp":3.15,"tv":34971.49,"id":31379}]}]}
{"op":"mcm","clk":"11761703106","pt":1722522870397,"mc":[{"id":"1.231283997","rc":[{"trd":[[3.15,29917.34]],"batb":[[0,3.05,4],[1,3,21.58],[2,1.43,116.28]],"ltp":3.15,"tv":35470.63,"id":31379}],"tv":35478.13}]}
{"op":"mcm","clk":"11761703537","pt":1722522876400,"mc":[{"id":"1.231283997","rc":[{"batb":[[0,3.15,249.57],[1,3.05,4],[2,3,21.58]],"ltp":3.15,"tv":35470.63,"id":31379}]}]}
{"op":"mcm","clk":"11761703759","pt":1722522879878,"mc":[{"id":"1.231283997","rc":[{"trd":[[3.15,30416.48]],"batb":[[0,3.05,4],[1,3,21.58],[2,1.43,116.28]],"ltp":3.15,"tv":35969.77,"id":31379}],"tv":35977.27}]}
{"op":"mcm","clk":"11761704240","pt":1722522887283,"mc":[{"id":"1.231283997","rc":[{"batb":[[0,3.15,249.57],[1,3.05,4],[2,3,21.58]],"ltp":3.15,"tv":35969.77,"id":31379}]}]}
{"op":"mcm","clk":"11761704474","pt":1722522890605,"mc":[{"id":"1.231283997","rc":[{"trd":[[3.15,30915.62]],"batb":[[0,3.05,4],[1,3,21.58],[2,1.43,116.28]],"ltp":3.15,"tv":36468.92,"id":31379}],"tv":36476.42}]}
{"op":"mcm","clk":"11761704927","pt":1722522896722,"mc":[{"id":"1.231283997","rc":[{"batb":[[0,3.15,249.57],[1,3.05,4],[2,3,21.58]],"ltp":3.15,"tv":36468.92,"id":31379}]}]}
{"op":"mcm","clk":"11761705204","pt":1722522900205,"mc":[{"id":"1.231283997","rc":[{"trd":[[3.15,31414.77]],"batb":[[0,3.05,4],[1,3,21.58],[2,1.43,116.28]],"ltp":3.15,"tv":36968.06,"id":31379}],"tv":36975.56}]}
{"op":"mcm","clk":"11761705689","pt":1722522906707,"mc":[{"id":"1.231283997","rc":[{"batb":[[0,3.15,249.57],[1,3.05,4],[2,3,21.58]],"ltp":3.15,"tv":36968.06,"id":31379}]}]}
{"op":"mcm","clk":"11761705987","pt":1722522910044,"mc":[{"id":"1.231283997","rc":[{"trd":[[3.15,31913.91]],"batb":[[0,3.05,4],[1,3,21.58],[2,1.43,116.28]],"ltp":3.15,"tv":37467.2,"id":31379}],"tv":37474.7}]}
{"op":"mcm","clk":"11761706433","pt":1722522915642,"mc":[{"id":"1.231283997","rc":[{"batb":[[0,3.15,249.57],[1,3.05,4],[2,3,21.58]],"ltp":3.15,"tv":37467.2,"id":31379}]}]}
{"op":"mcm","clk":"11761706497","pt":1722522916429,"mc":[{"id":"1.231283997","rc":[{"batb":[[0,3.15,253.57]],"ltp":3.15,"tv":37467.2,"id":31379},{"batl":[[0,1.47,4],[1,1.48,24.44],[2,1.49,15.33]],"ltp":1.47,"tv":7.5,"id":169}]}]}
{"op":"mcm","clk":"11761706661","pt":1722522919037,"mc":[{"id":"1.231283997","rc":[{"trd":[[3.15,32413.05]],"batb":[[0,3.15,4]],"ltp":3.15,"tv":37966.34,"id":31379}],"tv":37973.84}]}
{"op":"mcm","clk":"11761706704","pt":1722522919611,"mc":[{"id":"1.231283997","rc":[{"batb":[[0,3,21.58],[1,1.43,116.28],[2,1.38,131.58]],"ltp":3.15,"tv":37966.34,"id":31379},{"batl":[[0,1.48,20.44],[1,1.49,15.33],[2,1.51,30.66]],"ltp":1.47,"tv":7.5,"id":169}]}]}
{"op":"mcm","clk":"11761707621","pt":1722522931559,"mc":[{"id":"1.231283997","rc":[{"batb":[[0,3.05,4],[1,3,21.58],[2,1.43,116.28]],"ltp":3.15,"tv":37966.34,"id":31379},{"batl":[[0,1.48,24.44]],"ltp":1.47,"tv":7.5,"id":169}]}]}
{"op":"mcm","clk":"11761707925","pt":1722522935031,"mc":[{"id":"1.231283997","rc":[{"batb":[[0,3.15,249.57],[1,3.05,4],[2,3,21.58]],"ltp":3.15,"tv":37966.34,"id":31379}]}]}
{"op":"mcm","clk":"11761708151","pt":1722522938434,"mc":[{"id":"1.231283997","rc":[{"trd":[[3.15,32912.19]],"batb":[[0,3.05,4],[1,3,21.58],[2,1.43,116.28]],"ltp":3.15,"tv":38465.48,"id":31379}],"tv":38472.98}]}
{"op":"mcm","clk":"11761708582","pt":1722522944431,"mc":[{"id":"1.231283997","rc":[{"batb":[[0,3.15,249.57],[1,3.05,4],[2,3,21.58]],"ltp":3.15,"tv":38465.48,"id":31379}]}]}
{"op":"mcm","clk":"11761708723","pt":1722522946661,"mc":[{"id":"1.231283997","rc":[{"batb":[[0,3.15,253.57]],"ltp":3.15,"tv":38465.48,"id":31379},{"batl":[[0,1.47,4],[1,1.48,24.44],[2,1.49,15.33]],"ltp":1.47,"tv":7.5,"id":169}]}]}
{"op":"mcm","clk":"11761708831","pt":1722522948262,"mc":[{"id":"1.231283997","rc":[{"trd":[[3.15,33411.33]],"batb":[[0,3.15,4]],"ltp":3.15,"tv":38964.63,"id":31379}],"tv":38972.13}]}
{"op":"mcm","clk":"11761708857","pt":1722522948672,"mc":[{"id":"1.231283997","rc":[{"batb":[[0,3,21.58],[1,1.43,116.28],[2,1.38,131.58]],"ltp":3.15,"tv":38964.63,"id":31379},{"batl":[[0,1.48,20.44],[1,1.49,15.33],[2,1.51,30.66]],"ltp":1.47,"tv":7.5,"id":169}]}]}
{"op":"mcm","clk":"11761709270","pt":1722522954779,"mc":[{"id":"1.231283997","rc":[{"batb":[[0,3.15,249.57],[1,3,21.58],[2,1.43,116.28]],"ltp":3.15,"tv":38964.63,"id":31379}]}]}
{"op":"mcm","clk":"11761709513","pt":1722522958081,"mc":[{"id":"1.231283997","rc":[{"trd":[[3.15,33910.48]],"batb":[[0,3,21.58],[1,1.43,116.28],[2,1.38,131.58]],"ltp":3.15,"tv":39463.77,"id":31379}],"tv":39471.27}]}
{"op":"mcm","clk":"11761709784","pt":1722522961861,"mc":[{"id":"1.231283997","rc":[{"batb":[[0,3.05,4],[1,3,21.58],[2,1.43,116.28]],"ltp":3.15,"tv":39463.77,"id":31379},{"batl":[[0,1.48,24.44]],"ltp":1.47,"tv":7.5,"id":169}]}]}
{"op":"mcm","clk":"11761709943","pt":1722522964144,"mc":[{"id":"1.231283997","rc":[{"batb":[[0,3.15,249.57],[1,3.05,4],[2,3,21.58]],"ltp":3.15,"tv":39463.77,"id":31379}]}]}
{"op":"mcm","clk":"11761710103","pt":1722522966265,"mc":[{"id":"1.231283997","rc":[{"batb":[[0,3.2,7.84],[1,3.15,249.57],[2,3.05,4]],"ltp":3.15,"tv":39463.77,"id":31379}]}]}
{"op":"mcm","clk":"11761710248","pt":1722522968174,"mc":[{"id":"1.231283997","rc":[{"trd":[[3.15,34393.94],[3.2,70.33]],"batb":[[0,3.15,7.84],[1,3.05,4],[2,3,21.58]],"ltp":3.15,"tv":39962.91,"id":31379},{"batl":[[0,1.48,20.44]],"ltp":1.47,"tv":7.5,"id":169}],"tv":39970.41}]}
{"op":"mcm","clk":"11761710282","pt":1722522968689,"mc":[{"id":"1.231283997","rc":[{"batl":[[0,3.25,19.32]],"ltp":3.15,"tv":39962.91,"id":31379}]}]}
{"op":"mcm","clk":"11761711017","pt":1722522978279,"mc":[{"id":"1.231283997","rc":[{"trd":[[3.15,34409.54]],"batb":[[0,3.05,4.04],[1,3,21.58],[2,1.43,116.28]],"ltp":3.15,"tv":39978.51,"id":31379}],"tv":39986.01}]}
{"op":"mcm","clk":"11761711510","pt":1722522984310,"mc":[{"id":"1.231283997","rc":[{"batb":[[0,3.15,249.61],[1,3.05,4],[2,3,21.58]],"ltp":3.15,"tv":39978.51,"id":31379}]}]}
{"op":"mcm","clk":"11761711767","pt":1722522987694,"mc":[{"id":"1.231283997","rc":[{"trd":[[3.15,34908.6]],"batb":[[0,3.05,4.04],[1,3,21.58],[2,1.43,116.28]],"ltp":3.15,"tv":40477.57,"id":31379}],"tv":40485.07}]}
{"op":"mcm","clk":"11761712080","pt":1722522992097,"mc":[{"id":"1.231283997","rc":[{"batl":[[0,1.48,24.44]],"ltp":1.47,"tv":7.5,"id":169}]}]}
{"op":"mcm","clk":"11761712171","pt":1722522993280,"mc":[{"id":"1.231283997","rc":[{"batb":[[0,3.15,249.61],[1,3.05,4],[2,3,21.58]],"ltp":3.15,"tv":40477.57,"id":31379}]}]}
{"op":"mcm","clk":"11761712433","pt":1722522997086,"mc":[{"id":"1.231283997","rc":[{"trd":[[3.15,35407.67]],"batb":[[0,3.05,4.04],[1,3,21.58],[2,1.43,116.28]],"ltp":3.15,"tv":40976.64,"id":31379}],"tv":40984.14}]}
{"op":"mcm","clk":"11761712875","pt":1722523003203,"mc":[{"id":"1.231283997","rc":[{"batb":[[0,3.15,249.61],[1,3.05,4],[2,3,21.58]],"ltp":3.15,"tv":40976.64,"id":31379}]}]}
{"op":"mcm","clk":"11761713099","pt":1722523006501,"mc":[{"id":"1.231283997","rc":[{"trd":[[3.15,35906.73]],"batb":[[0,3.05,4.04],[1,3,21.58],[2,1.43,116.28]],"ltp":3.15,"tv":41475.7,"id":31379}],"tv":41483.2}]}
{"op":"mcm","clk":"11761713538","pt":1722523012417,"mc":[{"id":"1.231283997","rc":[{"batb":[[0,3.15,249.61],[1,3.05,4],[2,3,21.58]],"ltp":3.15,"tv":41475.7,"id":31379}]}]}
{"op":"mcm","clk":"11761713767","pt":1722523015729,"mc":[{"id":"1.231283997","rc":[{"trd":[[3.15,36405.8]],"batb":[[0,3.05,4.04],[1,3,21.58],[2,1.43,116.28]],"ltp":3.15,"tv":41974.76,"id":31379}],"tv":41982.26}]}
{"op":"mcm","clk":"11761714496","pt":1722523026250,"mc":[{"id":"1.231283997","rc":[{"batb":[[0,3.15,249.61],[1,3.05,4],[2,3,21.58]],"ltp":3.15,"tv":41974.76,"id":31379}]}]}
{"op":"mcm","clk":"11761714722","pt":1722523029451,"mc":[{"id":"1.231283997","rc":[{"trd":[[3.15,36904.86]],"batb":[[0,3.05,4.04],[1,3,21.58],[2,1.43,116.28]],"ltp":3.15,"tv":42473.83,"id":31379}],"tv":42481.33}]}
{"op":"mcm","clk":"11761716746","pt":1722523059172,"mc":[{"id":"1.231283997","rc":[{"trd":[[3.15,36904.94]],"batb":[[0,3,21.58],[1,1.43,116.28],[2,1.38,131.58]],"batl":[[0,3.15,7.92],[1,3.25,11.6],[2,3.3,4]],"ltp":3.15,"tv":42473.91,"id":31379},{"batb":[[0,1.46,467.95],[1,1.45,4],[2,1.44,53]],"batl":[[0,1.48,20.44]],"ltp":1.47,"tv":7.5,"id":169}],"tv":42481.41}]}
{"op":"mcm","clk":"11761716828","pt":1722523060262,"mc":[{"id":"1.231283997","rc":[{"batl":[[1,3.25,4]],"ltp":3.15,"tv":42473.91,"id":31379}]}]}
{"op":"mcm","clk":"11761716846","pt":1722523060465,"mc":[{"id":"1.231283997","rc":[{"batl":[[0,3.15,15.76]],"ltp":3.15,"tv":42473.91,"id":31379}]}]}
{"op":"mcm","clk":"11761717005","pt":1722523063167,"mc":[{"id":"1.231283997","rc":[{"trd":[[1.46,935.89]],"batb":[[0,1.45,4],[1,1.44,53],[2,1.43,216.66]],"ltp":1.46,"tv":943.39,"id":169}],"tv":43417.3}]}
{"op":"mcm","clk":"11761717046","pt":1722523063782,"mc":[{"id":"1.231283997","rc":[{"batl":[[0,3.15,7.84],[1,3.25,11.68]],"ltp":3.15,"tv":42473.91,"id":31379}]}]}
{"op":"mcm","clk":"11761717088","pt":1722523064463,"mc":[{"id":"1.231283997","rc":[{"batl":[[0,3.25,11.68],[1,3.3,4],[2,3.3,0]],"ltp":3.15,"tv":42473.91,"id":31379}]}]}
{"op":"mcm","clk":"11761717244","pt":1722523066798,"mc":[{"id":"1.231283997","rc":[{"batl":[[0,3.25,19.28]],"ltp":3.15,"tv":42473.91,"id":31379},{"batb":[[0,1.45,10.26]],"ltp":1.46,"tv":943.39,"id":169}]}]}
{"op":"mcm","clk":"11761717293","pt":1722523067583,"mc":[{"id":"1.231283997","rc":[{"batb":[[0,3.05,4],[1,3,21.58],[2,1.43,116.28]],"ltp":3.15,"tv":42473.91,"id":31379}]}]}
{"op":"mcm","clk":"11761717951","pt":1722523077183,"mc":[{"id":"1.231283997","rc":[{"batb":[[0,1.46,467.95],[1,1.45,10.26],[2,1.44,53]],"ltp":1.46,"tv":943.39,"id":169}]}]}
{"op":"mcm","clk":"11761717984","pt":1722523077603,"mc":[{"id":"1.231283997","rc":[{"batb":[[0,3,21.58],[1,1.43,116.28],[2,1.38,131.58]],"ltp":3.15,"tv":42473.91,"id":31379}]}]}
{"op":"mcm","clk":"11761718111","pt":1722523079309,"mc":[{"id":"1.231283997","rc":[{"batl":[[0,3.25,11.6]],"ltp":3.15,"tv":42473.91,"id":31379},{"batb":[[1,1.45,4]],"ltp":1.46,"tv":943.39,"id":169}]}]}
{"op":"mcm","clk":"11761718131","pt":1722523079578,"mc":[{"id":"1.231283997","rc":[{"batl":[[0,3.25,4]],"ltp":3.15,"tv":42473.91,"id":31379}]}]}
{"op":"mcm","clk":"11761718278","pt":1722523081808,"mc":[{"id":"1.231283997","rc":[{"trd":[[1.46,1871.78]],"batb":[[0,1.45,4],[1,1.44,53],[2,1.43,216.66]],"ltp":1.46,"tv":1879.28,"id":169}],"tv":44353.19}]}
{"op":"mcm","clk":"11761718336","pt":1722523082698,"mc":[{"id":"1.231283997","rc":[{"batb":[[0,3.05,4],[1,3,21.58],[2,1.43,116.28]],"ltp":3.15,"tv":42473.91,"id":31379},{"batl":[[0,1.48,24.44]],"ltp":1.46,"tv":1879.28,"id":169}]}]}
{"op":"mcm","clk":"11761718703","pt":1722523089183,"mc":[{"id":"1.231283997","rc":[{"batb":[[0,3,21.58],[1,1.43,116.28],[2,1.38,131.58]],"ltp":3.15,"tv":42473.91,"id":31379},{"batb":[[0,1.46,467.95],[1,1.45,4],[2,1.44,53]],"batl":[[0,1.48,20.44]],"ltp":1.46,"tv":1879.28,"id":169}]}]}
{"op":"mcm","clk":"11761718815","pt":1722523091706,"mc":[{"id":"1.231283997","rc":[{"batl":[[0,3.15,16.04],[1,3.25,4],[2,3.3,4]],"ltp":3.15,"tv":42473.91,"id":31379}]}]}
{"op":"mcm","clk":"11761718901","pt":1722523093321,"mc":[{"id":"1.231283997","rc":[{"trd":[[1.46,2807.67]],"batb":[[0,1.45,4],[1,1.44,53],[2,1.43,216.66]],"ltp":1.46,"tv":2815.17,"id":169}],"tv":45289.08}]}
{"op":"mcm","clk":"11761719001","pt":1722523095021,"mc":[{"id":"1.231283997","rc":[{"batl":[[0,3.25,4],[1,3.3,4],[2,3.3,0]],"ltp":3.15,"tv":42473.91,"id":31379}]}]}
{"op":"mcm","clk":"11761719159","pt":1722523097823,"mc":[{"id":"1.231283997","rc":[{"batb":[[0,3.05,4],[1,3,21.58],[2,1.43,116.28]],"ltp":3.15,"tv":42473.91,"id":31379},{"batl":[[0,1.48,24.44]],"ltp":1.46,"tv":2815.17,"id":169}]}]}
{"op":"mcm","clk":"11761719345","pt":1722523101201,"mc":[{"id":"1.231283997","rc":[{"batb":[[0,1.46,467.95],[1,1.45,4],[2,1.44,53]],"ltp":1.46,"tv":2815.17,"id":169}]}]}
{"op":"mcm","clk":"11761719365","pt":1722523101613,"mc":[{"id":"1.231283997","rc":[{"batb":[[0,3,21.58],[1,1.43,116.28],[2,1.38,131.58]],"ltp":3.15,"tv":42473.91,"id":31379},{"batl":[[0,1.48,20.44]],"ltp":1.46,"tv":2815.17,"id":169}]}]}
{"op":"mcm","clk":"11761719559","pt":1722523104531,"mc":[{"id":"1.231283997","rc":[{"trd":[[1.46,3743.57]],"batb":[[0,1.45,4],[1,1.44,53],[2,1.43,216.66]],"ltp":1.46,"tv":3751.06,"id":169}],"tv":46224.98}]}
{"op":"mcm","clk":"11761719919","pt":1722523110607,"mc":[{"id":"1.231283997","rc":[{"batb":[[0,1.46,467.95],[1,1.45,4],[2,1.44,53]],"ltp":1.46,"tv":3751.06,"id":169}]}]}
{"op":"mcm","clk":"11761720063","pt":1722523112931,"mc":[{"id":"1.231283997","rc":[{"batl":[[0,3.15,4],[1,3.2,4],[2,3.25,4]],"ltp":3.15,"tv":42473.91,"id":31379},{"batb":[[0,1.47,4],[1,1.46,471.95],[2,1.45,4]],"ltp":1.46,"tv":3751.06,"id":169}]}]}
{"op":"mcm","clk":"11761720215","pt":1722523115219,"mc":[{"id":"1.231283997","rc":[{"trd":[[1.46,4671.46],[1.47,12]],"batb":[[0,1.46,8],[1,1.45,4],[2,1.44,53]],"ltp":1.46,"tv":4686.95,"id":169}],"tv":47160.87}]}
{"op":"mcm","clk":"11761720236","pt":1722523115736,"mc":[{"id":"1.231283997","rc":[{"batb":[[0,1.46,4]],"ltp":1.46,"tv":4686.95,"id":169}]}]}
{"op":"mcm","clk":"11761720557","pt":1722523120815,"mc":[{"id":"1.231283997","rc":[{"batl":[[0,1.47,3.9],[1,1.48,20.44],[2,1.49,15.33]],"ltp":1.46,"tv":4686.95,"id":169}]}]}
{"op":"mcm","clk":"11761720729","pt":1722523123723,"mc":[{"id":"1.231283997","rc":[{"batl":[[0,1.48,20.44],[1,1.49,15.33],[2,1.51,30.66]],"ltp":1.46,"tv":4686.95,"id":169}]}]}
{"op":"mcm","clk":"11761720818","pt":1722523125426,"mc":[{"id":"1.231283997","rc":[{"batl":[[0,3.25,7.68]],"ltp":3.15,"tv":42473.91,"id":31379}]}]}
{"op":"mcm","clk":"11761720963","pt":1722523128017,"mc":[{"id":"1.231283997","rc":[{"batb":[[0,3.05,4],[1,3,21.58],[2,1.43,116.28]],"batl":[[0,3.2,4],[1,3.25,7.68]],"ltp":3.15,"tv":42473.91,"id":31379},{"batl":[[0,1.48,24.44]],"ltp":1.46,"tv":4686.95,"id":169}]}]}
{"op":"mcm","clk":"11761720989","pt":1722523128428,"mc":[{"id":"1.231283997","rc":[{"batb":[[1,1.45,9.28]],"ltp":1.46,"tv":4686.95,"id":169}]}]}
{"op":"mcm","clk":"11761721104","pt":1722523130531,"mc":[{"id":"1.231283997","rc":[{"batl":[[0,3.2,11.72]],"ltp":3.15,"tv":42473.91,"id":31379}]}]}
{"op":"mcm","clk":"11761721714","pt":1722523141347,"mc":[{"id":"1.231283997","rc":[{"batb":[[0,1.47,467.95],[1,1.46,4],[2,1.45,9.28]],"ltp":1.46,"tv":4686.95,"id":169}]}]}
{"op":"mcm","clk":"11761721741","pt":1722523141767,"mc":[{"id":"1.231283997","rc":[{"batb":[[0,3,21.58],[1,1.43,116.28],[2,1.38,131.58]],"ltp":3.15,"tv":42473.91,"id":31379},{"batl":[[0,1.48,20.44]],"ltp":1.46,"tv":4686.95,"id":169}]}]}
{"op":"mcm","clk":"11761721833","pt":1722523143148,"mc":[{"id":"1.231283997","rc":[{"batl":[[0,3.1,12.05],[1,3.15,4],[2,3.2,11.72]],"ltp":3.15,"tv":42473.91,"id":31379},{"batb":[[0,1.47,471.95],[2,1.45,4]],"ltp":1.46,"tv":4686.95,"id":169}]}]}
{"op":"mcm","clk":"11761721869","pt":1722523143720,"mc":[{"id":"1.231283997","rc":[{"batl":[[0,3.1,20.01],[2,3.2,4]],"ltp":3.15,"tv":42473.91,"id":31379}]}]}
{"op":"mcm","clk":"11761722052","pt":1722523147635,"mc":[{"id":"1.231283997","rc":[{"trd":[[1.47,947.89]],"batb":[[0,1.47,4]],"ltp":1.47,"tv":5622.84,"id":169}],"tv":48096.76}]}
{"op":"mcm","clk":"11761722290","pt":1722523150325,"mc":[{"id":"1.231283997","rc":[{"batl":[[0,3.15,7.92],[1,3.15,0],[2,3.2,0]],"ltp":3.15,"tv":42473.91,"id":31379},{"batb":[[0,1.46,4],[1,1.45,4],[2,1.44,53]],"ltp":1.47,"tv":5622.84,"id":169}]}]}
{"op":"mcm","clk":"11761722661","pt":1722523155750,"mc":[{"id":"1.231283997","rc":[{"batb":[[0,1.47,467.95],[1,1.46,4],[2,1.45,4]],"ltp":1.47,"tv":5622.84,"id":169}]}]}
{"op":"mcm","clk":"11761722801","pt":1722523158273,"mc":[{"id":"1.231283997","rc":[{"batl":[[0,3.1,4],[1,3.15,4]],"ltp":3.15,"tv":42473.91,"id":31379},{"batb":[[0,1.47,471.95]],"ltp":1.47,"tv":5622.84,"id":169}]}]}
{"op":"mcm","clk":"11761722873","pt":1722523159355,"mc":[{"id":"1.231283997","rc":[{"trd":[[1.47,1883.78]],"batb":[[0,1.47,4]],"ltp":1.47,"tv":6558.73,"id":169}],"tv":49032.65}]}
{"op":"mcm","clk":"11761722949","pt":1722523160334,"mc":[{"id":"1.231283997","rc":[{"batb":[[0,1.46,4],[1,1.44,49],[2,1.43,216.66]],"ltp":1.47,"tv":6558.73,"id":169}]}]}
{"op":"mcm","clk":"11761722967","pt":1722523160543,"mc":[{"id":"1.231283997","rc":[{"batl":[[0,3.25,7.6]],"ltp":3.15,"tv":42473.91,"id":31379}]}]}
{"op":"mcm","clk":"11761723276","pt":1722523165443,"mc":[{"id":"1.231283997","rc":[{"batb":[[0,1.47,467.95],[1,1.46,4],[2,1.44,49]],"ltp":1.47,"tv":6558.73,"id":169}]}]}
{"op":"mcm","clk":"11761723476","pt":1722523168646,"mc":[{"id":"1.231283997","rc":[{"trd":[[1.47,2819.68]],"batb":[[0,1.46,4],[1,1.44,49],[2,1.43,216.66]],"ltp":1.47,"tv":7494.63,"id":169}],"tv":49968.54}]}
{"op":"mcm","clk":"11761723780","pt":1722523173381,"mc":[{"id":"1.231283997","rc":[{"batb":[[0,3.05,4],[1,3,21.58],[2,1.43,116.28]],"ltp":3.15,"tv":42473.91,"id":31379},{"batl":[[0,1.48,24.44]],"ltp":1.47,"tv":7494.63,"id":169}]}]}
{"op":"mcm","clk":"11761723847","pt":1722523174260,"mc":[{"id":"1.231283997","rc":[{"batb":[[0,1.47,467.95],[1,1.46,4],[2,1.44,49]],"batl":[[0,1.48,20.44]],"ltp":1.47,"tv":7494.63,"id":169}]}]}
{"op":"mcm","clk":"11761723885","pt":1722523174772,"mc":[{"id":"1.231283997","rc":[{"batb":[[0,3,21.58],[1,1.43,116.28],[2,1.38,131.58]],"ltp":3.15,"tv":42473.91,"id":31379}]}]}
{"op":"mcm","clk":"11761723940","pt":1722523175647,"mc":[{"id":"1.231283997","rc":[{"batl":[[0,3.1,16.4]],"ltp":3.15,"tv":42473.91,"id":31379}]}]}
{"op":"mcm","clk":"11761724083","pt":1722523177874,"mc":[{"id":"1.231283997","rc":[{"trd":[[1.47,3755.57]],"batb":[[0,1.46,4],[1,1.44,49],[2,1.43,216.66]],"ltp":1.47,"tv":8430.52,"id":169}],"tv":50904.43}]}
{"op":"mcm","clk":"11761724564","pt":1722523184899,"mc":[{"id":"1.231283997","rc":[{"batb":[[0,1.47,467.95],[1,1.46,4],[2,1.44,49]],"ltp":1.47,"tv":8430.52,"id":169}]}]}
{"op":"mcm","clk":"11761724892","pt":1722523189290,"mc":[{"id":"1.231283997","rc":[{"trd":[[1.47,4691.46]],"batb":[[0,1.47,4]],"ltp":1.47,"tv":9366.41,"id":169}],"tv":51840.32}]}
{"op":"mcm","clk":"11761724935","pt":1722523189858,"mc":[{"id":"1.231283997","rc":[{"batl":[[0,3.25,7.68]],"ltp":3.15,"tv":42473.91,"id":31379},{"batb":[[0,1.46,4],[1,1.44,49],[2,1.43,216.66]],"ltp":1.47,"tv":9366.41,"id":169}]}]}
{"op":"mcm","clk":"11761725060","pt":1722523191767,"mc":[{"id":"1.231283997","rc":[{"batb":[[1,1.45,5.28],[2,1.44,49]],"ltp":1.47,"tv":9366.41,"id":169}]}]}
{"op":"mcm","clk":"11761725288","pt":1722523195174,"mc":[{"id":"1.231283997","rc":[{"batb":[[0,1.47,467.95],[1,1.46,4],[2,1.45,5.28]],"ltp":1.47,"tv":9366.41,"id":169}]}]}
{"op":"mcm","clk":"11761725427","pt":1722523197294,"mc":[{"id":"1.231283997","rc":[{"batb":[[2,1.44,49]],"ltp":1.47,"tv":9366.41,"id":169}]}]}
{"op":"mcm","clk":"11761725540","pt":1722523198793,"mc":[{"id":"1.231283997","rc":[{"trd":[[1.47,5627.35]],"batb":[[0,1.46,4],[1,1.44,49],[2,1.43,216.66]],"ltp":1.47,"tv":10302.3,"id":169}],"tv":52776.21}]}
{"op":"mcm","clk":"11761725914","pt":1722523203915,"mc":[{"id":"1.231283997","rc":[{"batb":[[0,3.05,4],[1,3,21.58],[2,1.43,116.28]],"ltp":3.15,"tv":42473.91,"id":31379},{"batl":[[0,1.48,24.44]],"ltp":1.47,"tv":10302.3,"id":169}]}]}
{"op":"mcm","clk":"11761725995","pt":1722523205213,"mc":[{"id":"1.231283997","rc":[{"batb":[[0,1.47,467.95],[1,1.46,4],[2,1.44,49]],"ltp":1.47,"tv":10302.3,"id":169}]}]}
{"op":"mcm","clk":"11761726042","pt":1722523205786,"mc":[{"id":"1.231283997","rc":[{"batl":[[0,1.48,20.44]],"ltp":1.47,"tv":10302.3,"id":169}]}]}
{"op":"mcm","clk":"11761726085","pt":1722523206411,"mc":[{"id":"1.231283997","rc":[{"batb":[[0,3,21.58],[1,1.43,116.28],[2,1.38,131.58]],"ltp":3.15,"tv":42473.91,"id":31379}]}]}
{"op":"mcm","clk":"11761726162","pt":1722523207603,"mc":[{"id":"1.231283997","rc":[{"batl":[[0,3.1,8.05]],"ltp":3.15,"tv":42473.91,"id":31379}]}]}
{"op":"mcm","clk":"11761726238","pt":1722523208692,"mc":[{"id":"1.231283997","rc":[{"trd":[[1.47,6563.24]],"batb":[[0,1.46,4],[1,1.44,49],[2,1.43,216.66]],"ltp":1.47,"tv":11238.19,"id":169}],"tv":53712.11}]}
{"op":"mcm","clk":"11761726607","pt":1722523214431,"mc":[{"id":"1.231283997","rc":[{"batb":[[0,1.47,467.95],[1,1.46,4],[2,1.44,49]],"ltp":1.47,"tv":11238.19,"id":169}]}]}
{"op":"mcm","clk":"11761726810","pt":1722523217488,"mc":[{"id":"1.231283997","rc":[{"trd":[[1.47,7499.13]],"batb":[[0,1.46,4],[1,1.44,49],[2,1.43,216.66]],"ltp":1.47,"tv":12174.08,"id":169}],"tv":54648.0}]}
{"op":"mcm","clk":"11761726925","pt":1722523219001,"mc":[{"id":"1.231283997","rc":[{"batb":[[0,3.05,4],[1,3,21.58],[2,1.43,116.28]],"ltp":3.15,"tv":42473.91,"id":31379},{"batl":[[0,1.48,24.44]],"ltp":1.47,"tv":12174.08,"id":169}]}]}
{"op":"mcm","clk":"11761727187","pt":1722523222934,"mc":[{"id":"1.231283997","rc":[{"batb":[[0,1.47,467.95],[1,1.46,4],[2,1.44,49]],"ltp":1.47,"tv":12174.08,"id":169}]}]}
{"op":"mcm","clk":"11761727250","pt":1722523223919,"mc":[{"id":"1.231283997","rc":[{"batb":[[0,3,21.58],[1,1.43,116.28],[2,1.38,131.58]],"ltp":3.15,"tv":42473.91,"id":31379},{"batl":[[0,1.48,20.44]],"ltp":1.47,"tv":12174.08,"id":169}]}]}
{"op":"mcm","clk":"11761727421","pt":1722523226098,"mc":[{"id":"1.231283997","rc":[{"trd":[[1.47,8435.02]],"batb":[[0,1.46,4],[1,1.44,49],[2,1.43,216.66]],"ltp":1.47,"tv":13109.97,"id":169}],"tv":55583.89}]}
{"op":"mcm","clk":"11761727828","pt":1722523231852,"mc":[{"id":"1.231283997","rc":[{"batb":[[0,1.47,467.95],[1,1.46,4],[2,1.44,49]],"ltp":1.47,"tv":13109.97,"id":169}]}]}
{"op":"mcm","clk":"11761727999","pt":1722523234167,"mc":[{"id":"1.231283997","rc":[{"batl":[[0,3.1,4],[1,3.15,4]],"ltp":3.15,"tv":42473.91,"id":31379},{"batb":[[0,1.47,471.95]],"ltp":1.47,"tv":13109.97,"id":169}]}]}
{"op":"mcm","clk":"11761728055","pt":1722523235047,"mc":[{"id":"1.231283997","rc":[{"trd":[[1.47,9370.92]],"batb":[[0,1.47,4]],"ltp":1.47,"tv":14045.87,"id":169}],"tv":56519.78}]}
{"op":"mcm","clk":"11761728108","pt":1722523235827,"mc":[{"id":"1.231283997","rc":[{"batb":[[0,1.46,4],[1,1.44,49],[2,1.43,216.66]],"ltp":1.47,"tv":14045.87,"id":169}]}]}
{"op":"mcm","clk":"11761728448","pt":1722523241063,"mc":[{"id":"1.231283997","rc":[{"batl":[[0,3.1,7.96]],"ltp":3.15,"tv":42473.91,"id":31379},{"batb":[[0,1.47,467.95],[1,1.46,4],[2,1.44,49]],"ltp":1.47,"tv":14045.87,"id":169}]}]}
{"op":"mcm","clk":"11761728491","pt":1722523241532,"mc":[{"id":"1.231283997","rc":[{"batl":[[0,3.1,24.82]],"ltp":3.15,"tv":42473.91,"id":31379}]}]}
{"op":"mcm","clk":"11761728657","pt":1722523243929,"mc":[{"id":"1.231283997","rc":[{"trd":[[1.47,10306.81]],"batb":[[0,1.46,4],[1,1.44,49],[2,1.43,216.66]],"ltp":1.47,"tv":14981.76,"id":169}],"tv":57455.67}]}
{"op":"mcm","clk":"11761728816","pt":1722523246050,"mc":[{"id":"1.231283997","rc":[{"batl":[[0,3.1,16.85],[1,3.2,7.72]],"ltp":3.15,"tv":42473.91,"id":31379}]}]}
{"op":"mcm","clk":"11761728871","pt":1722523246723,"mc":[{"id":"1.231283997","rc":[{"batl":[[0,3.2,7.72],[1,3.2,0]],"ltp":3.15,"tv":42473.91,"id":31379}]}]}
{"op":"mcm","clk":"11761729047","pt":1722523249156,"mc":[{"id":"1.231283997","rc":[{"batb":[[0,3.05,4],[1,3,21.58],[2,1.43,116.28]],"ltp":3.15,"tv":42473.91,"id":31379}]}]}
{"op":"mcm","clk":"11761729105","pt":1722523250146,"mc":[{"id":"1.231283997","rc":[{"batb":[[0,1.47,467.95],[1,1.46,4],[2,1.44,49]],"batl":[[0,1.48,24.44]],"ltp":1.47,"tv":14981.76,"id":169}]}]}
{"op":"mcm","clk":"11761729148","pt":1722523250926,"mc":[{"id":"1.231283997","rc":[{"batb":[[0,3,21.58],[1,1.43,116.28],[2,1.38,131.58]],"ltp":3.15,"tv":42473.91,"id":31379},{"batl":[[0,1.48,20.44]],"ltp":1.47,"tv":14981.76,"id":169}]}]}
{"op":"mcm","clk":"11761729358","pt":1722523254249,"mc":[{"id":"1.231283997","rc":[{"batl":[[0,3.25,7.68]],"ltp":3.15,"tv":42473.91,"id":31379},{"trd":[[1.47,11242.7]],"batb":[[0,1.46,4],[1,1.44,49],[2,1.43,216.66]],"ltp":1.47,"tv":15917.65,"id":169}],"tv":58391.56}]}
{"op":"mcm","clk":"11761729545","pt":1722523256837,"mc":[{"id":"1.231283997","rc":[{"batl":[[0,3.25,15.28]],"ltp":3.15,"tv":42473.91,"id":31379},{"batb":[[1,1.45,5.28],[2,1.44,49]],"ltp":1.47,"tv":15917.65,"id":169}]}]}
{"op":"mcm","clk":"11761729698","pt":1722523259373,"mc":[{"id":"1.231283997","rc":[{"batl":[[0,3.25,7.6]],"ltp":3.15,"tv":42473.91,"id":31379},{"batb":[[0,1.47,467.95],[1,1.46,4]],"ltp":1.47,"tv":15917.65,"id":169}]}]}
{"op":"mcm","clk":"11761729881","pt":1722523261878,"mc":[{"id":"1.231283997","rc":[{"trd":[[1.47,12178.59]],"batb":[[0,1.46,4],[1,1.44,49],[2,1.43,216.66]],"ltp":1.47,"tv":16853.54,"id":169}],"tv":59327.45}]}
{"op":"mcm","clk":"11761730065","pt":1722523264311,"mc":[{"id":"1.231283997","rc":[{"batb":[[0,3.05,4],[1,3,21.58],[2,1.43,116.28]],"ltp":3.15,"tv":42473.91,"id":31379},{"batl":[[0,1.48,24.44]],"ltp":1.47,"tv":16853.54,"id":169}]}]}
{"op":"mcm","clk":"11761730364","pt":1722523268003,"mc":[{"id":"1.231283997","rc":[{"batb":[[0,1.47,467.95],[1,1.46,4],[2,1.44,49]],"batl":[[0,1.48,20.44]],"ltp":1.47,"tv":16853.54,"id":169}]}]}
{"op":"mcm","clk":"11761730448","pt":1722523268916,"mc":[{"id":"1.231283997","rc":[{"batb":[[0,3,21.58],[1,1.43,116.28],[2,1.38,131.58]],"batl":[[0,3.1,8.05]],"ltp":3.15,"tv":42473.91,"id":31379}]}]}
{"op":"mcm","clk":"11761730623","pt":1722523271402,"mc":[{"id":"1.231283997","rc":[{"trd":[[1.47,13114.48]],"batb":[[0,1.46,4],[1,1.44,49],[2,1.43,216.66]],"ltp":1.47,"tv":17789.43,"id":169}],"tv":60263.35}]}
{"op":"mcm","clk":"11761731008","pt":1722523276988,"mc":[{"id":"1.231283997","rc":[{"batb":[[0,1.47,467.95],[1,1.46,4],[2,1.44,49]],"ltp":1.47,"tv":17789.43,"id":169}]}]}
{"op":"mcm","clk":"11761731141","pt":1722523279429,"mc":[{"id":"1.231283997","rc":[{"batl":[[0,3.1,4],[1,3.15,4]],"ltp":3.15,"tv":42473.91,"id":31379},{"batb":[[0,1.47,471.95]],"ltp":1.47,"tv":17789.43,"id":169}]}]}
{"op":"mcm","clk":"11761731462","pt":1722523284121,"mc":[{"id":"1.231283997","rc":[{"trd":[[1.47,14050.37]],"batb":[[0,1.47,4]],"ltp":1.47,"tv":18725.32,"id":169}],"tv":61199.24}]}
{"op":"mcm","clk":"11761731536","pt":1722523285011,"mc":[{"id":"1.231283997","rc":[{"batb":[[0,1.46,4],[1,1.44,49],[2,1.43,216.66]],"ltp":1.47,"tv":18725.32,"id":169}]}]}
{"op":"mcm","clk":"11761732115","pt":1722523292414,"mc":[{"id":"1.231283997","rc":[{"batb":[[0,1.47,467.95],[1,1.46,4],[2,1.44,49]],"ltp":1.47,"tv":18725.32,"id":169}]}]}
{"op":"mcm","clk":"11761732250","pt":1722523294528,"mc":[{"id":"1.231283997","rc":[{"batl":[[0,3.1,4],[1,3.15,4]],"ltp":3.15,"tv":42473.91,"id":31379},{"batb":[[0,1.47,471.95]],"ltp":1.47,"tv":18725.32,"id":169}]}]}
{"op":"mcm","clk":"11761732412","pt":1722523297055,"mc":[{"id":"1.231283997","rc":[{"trd":[[1.47,14986.26]],"batb":[[0,1.47,4]],"ltp":1.47,"tv":19661.21,"id":169}],"tv":62135.13}]}
{"op":"mcm","clk":"11761732457","pt":1722523297629,"mc":[{"id":"1.231283997","rc":[{"batb":[[0,1.46,4],[1,1.44,49],[2,1.43,216.66]],"ltp":1.47,"tv":19661.21,"id":169}]}]}
{"op":"mcm","clk":"11761732789","pt":1722523302223,"mc":[{"id":"1.231283997","rc":[{"batb":[[0,1.47,467.95],[1,1.46,4],[2,1.44,49]],"ltp":1.47,"tv":19661.21,"id":169}]}]}
{"op":"mcm","clk":"11761733022","pt":1722523305534,"mc":[{"id":"1.231283997","rc":[{"batl":[[0,3.1,16.4]],"ltp":3.15,"tv":42473.91,"id":31379},{"trd":[[1.47,15922.16]],"batb":[[0,1.46,4],[1,1.44,49],[2,1.43,216.66]],"ltp":1.47,"tv":20597.11,"id":169}],"tv":63071.02}]}
{"op":"mcm","clk":"11761733335","pt":1722523309620,"mc":[{"id":"1.231283997","rc":[{"batb":[[0,3.05,4],[1,3,21.58],[2,1.43,116.28]],"ltp":3.15,"tv":42473.91,"id":31379},{"batl":[[0,1.48,24.44]],"ltp":1.47,"tv":20597.11,"id":169}]}]}
{"op":"mcm","clk":"11761733525","pt":1722523312171,"mc":[{"id":"1.231283997","rc":[{"batb":[[0,1.47,467.95],[1,1.46,4],[2,1.44,49]],"batl":[[0,1.48,20.44]],"ltp":1.47,"tv":20597.11,"id":169}]}]}
{"op":"mcm","clk":"11761733570","pt":1722523312635,"mc":[{"id":"1.231283997","rc":[{"batb":[[0,3,21.58],[1,1.43,116.28],[2,1.38,131.58]],"ltp":3.15,"tv":42473.91,"id":31379}]}]}
{"op":"mcm","clk":"11761733730","pt":1722523315070,"mc":[{"id":"1.231283997","rc":[{"trd":[[1.47,16858.05]],"batb":[[0,1.46,4],[1,1.44,49],[2,1.43,216.66]],"ltp":1.47,"tv":21533.0,"id":169}],"tv":64006.91}]}
{"op":"mcm","clk":"11761733914","pt":1722523317665,"mc":[{"id":"1.231283997","rc":[{"batl":[[0,3.25,7.68]],"ltp":3.15,"tv":42473.91,"id":31379}]}]}
{"op":"mcm","clk":"11761734056","pt":1722523320044,"mc":[{"id":"1.231283997","rc":[{"batb":[[1,1.45,5.28],[2,1.44,49]],"ltp":1.47,"tv":21533.0,"id":169}]}]}
{"op":"mcm","clk":"11761734188","pt":1722523321864,"mc":[{"id":"1.231283997","rc":[{"batb":[[0,1.47,467.95],[1,1.46,4],[2,1.45,5.28]],"ltp":1.47,"tv":21533.0,"id":169}]}]}
{"op":"mcm","clk":"11761734260","pt":1722523322851,"mc":[{"id":"1.231283997","rc":[{"batb":[[2,1.44,49]],"ltp":1.47,"tv":21533.0,"id":169}]}]}
{"op":"mcm","clk":"11761734383","pt":1722523324764,"mc":[{"id":"1.231283997","rc":[{"batl":[[0,3.1,4],[1,3.15,4]],"ltp":3.15,"tv":42473.91,"id":31379},{"batb":[[0,1.47,471.95]],"ltp":1.47,"tv":21533.0,"id":169}]}]}
{"op":"mcm","clk":"11761734488","pt":1722523326180,"mc":[{"id":"1.231283997","rc":[{"trd":[[1.47,17793.94]],"batb":[[0,1.47,4]],"ltp":1.47,"tv":22468.89,"id":169}],"tv":64942.8}]}
{"op":"mcm","clk":"11761734528","pt":1722523326652,"mc":[{"id":"1.231283997","rc":[{"batb":[[0,1.46,4],[1,1.44,49],[2,1.43,216.66]],"ltp":1.47,"tv":22468.89,"id":169}]}]}
{"op":"mcm","clk":"11761734936","pt":1722523332172,"mc":[{"id":"1.231283997","rc":[{"batb":[[0,1.47,467.95],[1,1.46,4],[2,1.44,49]],"ltp":1.47,"tv":22468.89,"id":169}]}]}
{"op":"mcm","clk":"11761734979","pt":1722523332848,"mc":[{"id":"1.231283997","rc":[{"batl":[[0,3.1,8.05]],"ltp":3.15,"tv":42473.91,"id":31379}]}]}
{"op":"mcm","clk":"11761735119","pt":1722523334877,"mc":[{"id":"1.231283997","rc":[{"batl":[[0,3.1,16.01]],"ltp":3.15,"tv":42473.91,"id":31379}]}]}
{"op":"mcm","clk":"11761735397","pt":1722523339095,"mc":[{"id":"1.231283997","rc":[{"trd":[[1.47,18729.83]],"batb":[[0,1.46,4],[1,1.44,49],[2,1.43,216.66]],"ltp":1.47,"tv":23404.78,"id":169}],"tv":65878.69}]}
{"op":"mcm","clk":"11761735482","pt":1722523340188,"mc":[{"id":"1.231283997","rc":[{"batl":[[0,3.1,11.96]],"ltp":3.15,"tv":42473.91,"id":31379},{"batb":[[0,1.47,4],[1,1.46,4],[2,1.44,49]],"ltp":1.47,"tv":23404.78,"id":169}]}]}
{"op":"mcm","clk":"11761735613","pt":1722523341800,"mc":[{"id":"1.231283997","rc":[{"batb":[[0,1.46,4],[1,1.44,49],[2,1.43,216.66]],"ltp":1.47,"tv":23404.78,"id":169}]}]}
{"op":"mcm","clk":"11761736026","pt":1722523347003,"mc":[{"id":"1.231283997","rc":[{"batb":[[0,1.47,467.95],[1,1.46,4],[2,1.44,49]],"ltp":1.47,"tv":23404.78,"id":169}]}]}
{"op":"mcm","clk":"11761736291","pt":1722523350581,"mc":[{"id":"1.231283997","rc":[{"trd":[[1.47,19665.72]],"batb":[[0,1.46,4],[1,1.44,49],[2,1.43,216.66]],"ltp":1.47,"tv":24340.67,"id":169}],"tv":66814.59}]}
{"op":"mcm","clk":"11761736422","pt":1722523352599,"mc":[{"id":"1.231283997","rc":[{"batl":[[0,3.25,7.6]],"ltp":3.15,"tv":42473.91,"id":31379}]}]}
{"op":"mcm","clk":"11761736583","pt":1722523355294,"mc":[{"id":"1.231283997","rc":[{"batb":[[0,3.05,4],[1,3,21.58],[2,1.43,116.28]],"ltp":3.15,"tv":42473.91,"id":31379},{"batl":[[0,1.48,24.44]],"ltp":1.47,"tv":24340.67,"id":169}]}]}
{"op":"mcm","clk":"11761736704","pt":1722523357204,"mc":[{"id":"1.231283997","rc":[{"batb":[[0,1.47,467.95],[1,1.46,4],[2,1.44,49]],"ltp":1.47,"tv":24340.67,"id":169}]}]}
{"op":"mcm","clk":"11761736770","pt":1722523358291,"mc":[{"id":"1.231283997","rc":[{"batl":[[0,1.48,20.44]],"ltp":1.47,"tv":24340.67,"id":169}]}]}
{"op":"mcm","clk":"11761736796","pt":1722523358713,"mc":[{"id":"1.231283997","rc":[{"batb":[[0,3,21.58],[1,1.43,116.28],[2,1.38,131.58]],"ltp":3.15,"tv":42473.91,"id":31379}]}]}
{"op":"mcm","clk":"11761736969","pt":1722523361128,"mc":[{"id":"1.231283997","rc":[{"trd":[[1.47,20601.61]],"batb":[[0,1.46,4],[1,1.44,49],[2,1.43,216.66]],"ltp":1.47,"tv":25276.56,"id":169}],"tv":67750.48}]}
{"op":"mcm","clk":"11761737343","pt":1722523366834,"mc":[{"id":"1.231283997","rc":[{"batb":[[0,1.47,467.95],[1,1.46,4],[2,1.44,49]],"ltp":1.47,"tv":25276.56,"id":169}]}]}
{"op":"mcm","clk":"11761737494","pt":1722523369218,"mc":[{"id":"1.231283997","rc":[{"batl":[[0,3.1,16.4]],"ltp":3.15,"tv":42473.91,"id":31379}]}]}
{"op":"mcm","clk":"11761737555","pt":1722523370245,"mc":[{"id":"1.231283997","rc":[{"trd":[[1.47,21537.5]],"batb":[[0,1.46,4],[1,1.44,49],[2,1.43,216.66]],"ltp":1.47,"tv":26212.45,"id":169}],"tv":68686.37}]}
{"op":"mcm","clk":"11761737588","pt":1722523370809,"mc":[{"id":"1.231283997","rc":[{"batl":[[0,3.1,20.4],[1,3.2,7.72]],"ltp":3.15,"tv":42473.91,"id":31379},{"batb":[[0,1.47,4],[1,1.46,4],[2,1.44,49]],"ltp":1.47,"tv":26212.45,"id":169}]}]}
{"op":"mcm","clk":"11761737682","pt":1722523372216,"mc":[{"id":"1.231283997","rc":[{"batl":[[0,3.2,7.72],[1,3.2,0]],"ltp":3.15,"tv":42473.91,"id":31379},{"batb":[[0,1.46,4],[1,1.44,49],[2,1.43,216.66]],"ltp":1.47,"tv":26212.45,"id":169}]}]}
{"op":"mcm","clk":"11761737912","pt":1722523376025,"mc":[{"id":"1.231283997","rc":[{"batb":[[0,1.47,467.95],[1,1.46,4],[2,1.44,49]],"ltp":1.47,"tv":26212.45,"id":169}]}]}
{"op":"mcm","clk":"11761738169","pt":1722523379546,"mc":[{"id":"1.231283997","rc":[{"trd":[[1.47,22473.4]],"batb":[[0,1.46,4],[1,1.44,49],[2,1.43,216.66]],"ltp":1.47,"tv":27148.35,"id":169}],"tv":69622.26}]}
{"op":"mcm","clk":"11761738260","pt":1722523381114,"mc":[{"id":"1.231283997","rc":[{"batl":[[0,3.25,7.68]],"ltp":3.15,"tv":42473.91,"id":31379}]}]}
{"op":"mcm","clk":"11761738459","pt":1722523383838,"mc":[{"id":"1.231283997","rc":[{"batb":[[1,1.45,5.28],[2,1.44,49]],"ltp":1.47,"tv":27148.35,"id":169}]}]}
{"op":"mcm","clk":"11761738553","pt":1722523385234,"mc":[{"id":"1.231283997","rc":[{"batb":[[0,1.47,467.95],[1,1.46,4],[2,1.45,5.28]],"ltp":1.47,"tv":27148.35,"id":169}]}]}
{"op":"mcm","clk":"11761738617","pt":1722523386332,"mc":[{"id":"1.231283997","rc":[{"batb":[[0,3.05,4],[1,3,21.58],[2,1.43,116.28]],"batl":[[0,3.2,4],[1,3.25,7.68]],"ltp":3.15,"tv":42473.91,"id":31379}]}]}
{"op":"mcm","clk":"11761738682","pt":1722523387214,"mc":[{"id":"1.231283997","rc":[{"batb":[[0,3,21.58],[1,1.43,116.28],[2,1.38,131.58]],"batl":[[0,3.1,10.72],[1,3.2,4]],"ltp":3.15,"tv":42473.91,"id":31379},{"batb":[[2,1.44,49]],"ltp":1.47,"tv":27148.35,"id":169}]}]}
{"op":"mcm","clk":"11761738775","pt":1722523388757,"mc":[{"id":"1.231283997","rc":[{"trd":[[1.47,23409.29]],"batb":[[0,1.46,4],[1,1.44,49],[2,1.43,216.66]],"ltp":1.47,"tv":28084.24,"id":169}],"tv":70558.15}]}
{"op":"mcm","clk":"11761739248","pt":1722523395727,"mc":[{"id":"1.231283997","rc":[{"batb":[[0,1.47,467.95],[1,1.46,4],[2,1.44,49]],"ltp":1.47,"tv":28084.24,"id":169}]}]}
{"op":"mcm","clk":"11761739312","pt":1722523396553,"mc":[{"id":"1.231283997","rc":[{"batl":[[0,3.1,8.05]],"ltp":3.15,"tv":42473.91,"id":31379}]}]}
{"op":"mcm","clk":"11761739535","pt":1722523400039,"mc":[{"id":"1.231283997","rc":[{"trd":[[1.47,24345.18]],"batb":[[0,1.46,4],[1,1.44,49],[2,1.43,216.66]],"ltp":1.47,"tv":29020.13,"id":169}],"tv":71494.04}]}
{"op":"mcm","clk":"11761739584","pt":1722523400657,"mc":[{"id":"1.231283997","rc":[{"batb":[[0,1.47,4],[1,1.46,4],[2,1.44,49]],"ltp":1.47,"tv":29020.13,"id":169}]}]}
{"op":"mcm","clk":"11761739708","pt":1722523402226,"mc":[{"id":"1.231283997","rc":[{"batb":[[0,1.46,4],[1,1.44,49],[2,1.43,216.66]],"ltp":1.47,"tv":29020.13,"id":169}]}]}
{"op":"mcm","clk":"11761739966","pt":1722523405861,"mc":[{"id":"1.231283997","rc":[{"batb":[[0,1.47,467.95],[1,1.46,4],[2,1.44,49]],"ltp":1.47,"tv":29020.13,"id":169}]}]}
{"op":"mcm","clk":"11761740217","pt":1722523409454,"mc":[{"id":"1.231283997","rc":[{"trd":[[1.47,25281.07]],"batb":[[0,1.46,4],[1,1.44,49],[2,1.43,216.66]],"ltp":1.47,"tv":29956.02,"id":169}],"tv":72429.93}]}
{"op":"mcm","clk":"11761740668","pt":1722523415842,"mc":[{"id":"1.231283997","rc":[{"batb":[[0,3.05,4],[1,3,21.58],[2,1.43,116.28]],"ltp":3.15,"tv":42473.91,"id":31379},{"batl":[[0,1.48,24.44]],"ltp":1.47,"tv":29956.02,"id":169}]}]}
{"op":"mcm","clk":"11761741678","pt":1722523431394,"mc":[{"id":"1.231283997","rc":[{"batb":[[0,1.47,467.95],[1,1.46,4],[2,1.44,49]],"ltp":1.47,"tv":29956.02,"id":169}]}]}
{"op":"mcm","clk":"11761741707","pt":1722523431864,"mc":[{"id":"1.231283997","rc":[{"batl":[[0,3.1,7.96]],"ltp":3.15,"tv":42473.91,"id":31379},{"batl":[[0,1.48,20.44]],"ltp":1.47,"tv":29956.02,"id":169}]}]}
{"op":"mcm","clk":"11761741882","pt":1722523434355,"mc":[{"id":"1.231283997","rc":[{"batb":[[0,3,21.58],[1,1.43,116.28],[2,1.38,131.58]],"batl":[[0,3.1,24.82]],"ltp":3.15,"tv":42473.91,"id":31379}]}]}
{"op":"mcm","clk":"11761742112","pt":1722523437265,"mc":[{"id":"1.231283997","rc":[{"trd":[[1.47,26216.96]],"batb":[[0,1.46,4],[1,1.44,49],[2,1.43,216.66]],"ltp":1.47,"tv":30891.91,"id":169}],"tv":73365.83}]}
{"op":"mcm","clk":"11761742165","pt":1722523437988,"mc":[{"id":"1.231283997","rc":[{"batl":[[0,3.1,16.85]],"ltp":3.15,"tv":42473.91,"id":31379}]}]}
{"op":"mcm","clk":"11761742561","pt":1722523443592,"mc":[{"id":"1.231283997","rc":[{"batb":[[0,1.47,467.95],[1,1.46,4],[2,1.44,49]],"ltp":1.47,"tv":30891.91,"id":169}]}]}
{"op":"mcm","clk":"11761742763","pt":1722523446191,"mc":[{"id":"1.231283997","rc":[{"batl":[[0,3.1,4],[1,3.15,4]],"ltp":3.15,"tv":42473.91,"id":31379},{"batb":[[0,1.47,471.95]],"ltp":1.47,"tv":30891.91,"id":169}]}]}
{"op":"mcm","clk":"11761742889","pt":1722523447907,"mc":[{"id":"1.231283997","rc":[{"trd":[[1.47,27152.85]],"batb":[[0,1.47,4]],"ltp":1.47,"tv":31827.8,"id":169}],"tv":74301.72}]}
{"op":"mcm","clk":"11761742979","pt":1722523449201,"mc":[{"id":"1.231283997","rc":[{"batl":[[0,3.25,15.28]],"ltp":3.15,"tv":42473.91,"id":31379},{"batb":[[0,1.46,4],[1,1.45,5.27]],"ltp":1.47,"tv":31827.8,"id":169}]}]}
{"op":"mcm","clk":"11761743266","pt":1722523453615,"mc":[{"id":"1.231283997","rc":[{"batb":[[0,1.47,467.95],[1,1.46,4],[2,1.45,5.27]],"ltp":1.47,"tv":31827.8,"id":169}]}]}
{"op":"mcm","clk":"11761743344","pt":1722523454705,"mc":[{"id":"1.231283997","rc":[{"batb":[[2,1.44,49]],"ltp":1.47,"tv":31827.8,"id":169}]}]}
{"op":"mcm","clk":"11761743521","pt":1722523457194,"mc":[{"id":"1.231283997","rc":[{"trd":[[1.47,28088.74]],"batb":[[0,1.46,4],[1,1.44,49],[2,1.43,216.66]],"ltp":1.47,"tv":32763.69,"id":169}],"tv":75237.61}]}
{"op":"mcm","clk":"11761743774","pt":1722523461188,"mc":[{"id":"1.231283997","rc":[{"batb":[[0,3.05,4],[1,3,21.58],[2,1.43,116.28]],"ltp":3.15,"tv":42473.91,"id":31379},{"batl":[[0,1.48,24.44]],"ltp":1.47,"tv":32763.69,"id":169}]}]}
{"op":"mcm","clk":"11761743876","pt":1722523462896,"mc":[{"id":"1.231283997","rc":[{"batb":[[0,1.47,467.95],[1,1.46,4],[2,1.44,49]],"batl":[[0,1.48,20.44]],"ltp":1.47,"tv":32763.69,"id":169}]}]}
{"op":"mcm","clk":"11761743913","pt":1722523463406,"mc":[{"id":"1.231283997","rc":[{"batb":[[0,3,21.58],[1,1.43,116.28],[2,1.38,131.58]],"ltp":3.15,"tv":42473.91,"id":31379}]}]}
{"op":"mcm","clk":"11761743991","pt":1722523464601,"mc":[{"id":"1.231283997","rc":[{"batl":[[0,3.1,8.05]],"ltp":3.15,"tv":42473.91,"id":31379}]}]}
{"op":"mcm","clk":"11761744097","pt":1722523466008,"mc":[{"id":"1.231283997","rc":[{"trd":[[1.47,29024.64]],"batb":[[0,1.46,4],[1,1.44,49],[2,1.43,216.66]],"ltp":1.47,"tv":33699.59,"id":169}],"tv":76173.5}]}
{"op":"mcm","clk":"11761744478","pt":1722523472040,"mc":[{"id":"1.231283997","rc":[{"batb":[[0,1.47,467.95],[1,1.46,4],[2,1.44,49]],"ltp":1.47,"tv":33699.59,"id":169}]}]}
{"op":"mcm","clk":"11761744774","pt":1722523476305,"mc":[{"id":"1.231283997","rc":[{"batb":[[0,3.05,4],[1,3,21.58],[2,1.43,116.28]],"ltp":3.15,"tv":42473.91,"id":31379},{"trd":[[1.47,29960.53]],"batb":[[0,1.46,4],[1,1.44,49],[2,1.43,216.66]],"batl":[[0,1.48,24.44]],"ltp":1.47,"tv":34635.48,"id":169}],"tv":77109.39}]}
{"op":"mcm","clk":"11761745141","pt":1722523482325,"mc":[{"id":"1.231283997","rc":[{"batl":[[0,3.1,10.72]],"ltp":3.15,"tv":42473.91,"id":31379},{"batb":[[0,1.47,467.95],[1,1.46,4],[2,1.44,49]],"batl":[[0,1.48,20.44]],"ltp":1.47,"tv":34635.48,"id":169}]}]}
{"op":"mcm","clk":"11761745154","pt":1722523482529,"mc":[{"id":"1.231283997","rc":[{"batb":[[0,3,21.58],[1,1.43,116.28],[2,1.38,131.58]],"ltp":3.15,"tv":42473.91,"id":31379}]}]}
{"op":"mcm","clk":"11761745277","pt":1722523484757,"mc":[{"id":"1.231283997","rc":[{"trd":[[1.47,30896.42]],"batb":[[0,1.46,4],[1,1.44,49],[2,1.43,216.66]],"ltp":1.47,"tv":35571.37,"id":169}],"tv":78045.28}]}
{"op":"mcm","clk":"11761745638","pt":1722523490637,"mc":[{"id":"1.231283997","rc":[{"batb":[[0,1.47,467.95],[1,1.46,4],[2,1.44,49]],"ltp":1.47,"tv":35571.37,"id":169}]}]}
{"op":"mcm","clk":"11761745690","pt":1722523491459,"mc":[{"id":"1.231283997","rc":[{"batl":[[0,3.1,4],[1,3.15,4]],"ltp":3.15,"tv":42473.91,"id":31379},{"batb":[[0,1.47,471.95]],"ltp":1.47,"tv":35571.37,"id":169}]}]}
{"op":"mcm","clk":"11761745873","pt":1722523494265,"mc":[{"id":"1.231283997","rc":[{"trd":[[1.47,31832.31]],"batb":[[0,1.47,4]],"ltp":1.47,"tv":36507.26,"id":169}],"tv":78981.17}]}
{"op":"mcm","clk":"11761745944","pt":1722523495059,"mc":[{"id":"1.231283997","rc":[{"batb":[[0,1.46,4],[1,1.44,49],[2,1.43,216.66]],"ltp":1.47,"tv":36507.26,"id":169}]}]}
{"op":"mcm","clk":"11761746349","pt":1722523500387,"mc":[{"id":"1.231283997","rc":[{"batb":[[0,1.47,467.95],[1,1.46,4],[2,1.44,49]],"ltp":1.47,"tv":36507.26,"id":169}]}]}
{"op":"mcm","clk":"11761746536","pt":1722523502864,"mc":[{"id":"1.231283997","rc":[{"batl":[[0,3.1,16.4]],"ltp":3.15,"tv":42473.91,"id":31379}]}]}
{"op":"mcm","clk":"11761746604","pt":1722523503779,"mc":[{"id":"1.231283997","rc":[{"trd":[[1.47,32768.2]],"batb":[[0,1.46,4],[1,1.44,49],[2,1.43,216.66]],"ltp":1.47,"tv":37443.15,"id":169}],"tv":79917.07}]}
{"op":"mcm","clk":"11761746829","pt":1722523506565,"mc":[{"id":"1.231283997","rc":[{"batb":[[0,3.05,4],[1,3,21.58],[2,1.43,116.28]],"ltp":3.15,"tv":42473.91,"id":31379},{"batl":[[0,1.48,24.44]],"ltp":1.47,"tv":37443.15,"id":169}]}]}
{"op":"mcm","clk":"11761747027","pt":1722523509349,"mc":[{"id":"1.231283997","rc":[{"batb":[[0,1.47,467.95],[1,1.46,4],[2,1.44,49]],"ltp":1.47,"tv":37443.15,"id":169}]}]}
{"op":"mcm","clk":"11761747078","pt":1722523510076,"mc":[{"id":"1.231283997","rc":[{"batl":[[0,1.48,20.44]],"ltp":1.47,"tv":37443.15,"id":169}]}]}
{"op":"mcm","clk":"11761747124","pt":1722523510552,"mc":[{"id":"1.231283997","rc":[{"batb":[[0,3,21.58],[1,1.43,116.28],[2,1.38,131.58]],"ltp":3.15,"tv":42473.91,"id":31379}]}]}
{"op":"mcm","clk":"11761747287","pt":1722523512670,"mc":[{"id":"1.231283997","rc":[{"trd":[[1.47,33704.09]],"batb":[[0,1.46,4],[1,1.44,49],[2,1.43,216.66]],"ltp":1.47,"tv":38379.04,"id":169}],"tv":80852.96}]}
{"op":"mcm","clk":"11761747431","pt":1722523514963,"mc":[{"id":"1.231283997","rc":[{"batl":[[0,3.25,7.68]],"ltp":3.15,"tv":42473.91,"id":31379}]}]}
{"op":"mcm","clk":"11761747592","pt":1722523517363,"mc":[{"id":"1.231283997","rc":[{"batb":[[1,1.45,5.28],[2,1.44,49]],"ltp":1.47,"tv":38379.04,"id":169}]}]}
{"op":"mcm","clk":"11761747674","pt":1722523518658,"mc":[{"id":"1.231283997","rc":[{"batb":[[0,1.47,467.95],[1,1.46,4],[2,1.45,5.28]],"ltp":1.47,"tv":38379.04,"id":169}]}]}
{"op":"mcm","clk":"11761747770","pt":1722523520379,"mc":[{"id":"1.231283997","rc":[{"batb":[[2,1.44,49]],"ltp":1.47,"tv":38379.04,"id":169}]}]}
{"op":"mcm","clk":"11761747884","pt":1722523522077,"mc":[{"id":"1.231283997","rc":[{"batl":[[0,3.1,4],[1,3.15,4]],"ltp":3.15,"tv":42473.91,"id":31379},{"trd":[[1.47,34639.98]],"batb":[[0,1.47,4]],"ltp":1.47,"tv":39314.93,"id":169}],"tv":81788.85}]}
{"op":"mcm","clk":"11761747950","pt":1722523522972,"mc":[{"id":"1.231283997","rc":[{"batb":[[0,1.46,4],[1,1.44,49],[2,1.43,216.66]],"ltp":1.47,"tv":39314.93,"id":169}]}]}
{"op":"mcm","clk":"11761748245","pt":1722523527586,"mc":[{"id":"1.231283997","rc":[{"batb":[[0,1.47,467.95],[1,1.46,4],[2,1.44,49]],"ltp":1.47,"tv":39314.93,"id":169}]}]}
{"op":"mcm","clk":"11761748414","pt":1722523529681,"mc":[{"id":"1.231283997","rc":[{"batl":[[0,3.1,16.01]],"ltp":3.15,"tv":42473.91,"id":31379}]}]}
{"op":"mcm","clk":"11761748537","pt":1722523531189,"mc":[{"id":"1.231283997","rc":[{"trd":[[1.47,35575.88]],"batb":[[0,1.46,4],[1,1.44,49],[2,1.43,216.66]],"ltp":1.47,"tv":40250.83,"id":169}],"tv":82724.74}]}
{"op":"mcm","clk":"11761748617","pt":1722523532286,"mc":[{"id":"1.231283997","rc":[{"batl":[[0,3.1,8.05]],"ltp":3.15,"tv":42473.91,"id":31379}]}]}
{"op":"mcm","clk":"11761749082","pt":1722523536995,"mc":[{"id":"1.231283997","rc":[{"batb":[[0,3.05,4],[1,3,21.58],[2,1.43,116.28]],"ltp":3.15,"tv":42473.91,"id":31379},{"batb":[[0,1.47,467.95],[1,1.46,4],[2,1.44,49]],"batl":[[0,1.48,24.44]],"ltp":1.47,"tv":40250.83,"id":169}]}]}
{"op":"mcm","clk":"11761749159","pt":1722523538089,"mc":[{"id":"1.231283997","rc":[{"batb":[[0,3,21.58],[1,1.43,116.28],[2,1.38,131.58]],"ltp":3.15,"tv":42473.91,"id":31379},{"batl":[[0,1.48,20.44]],"ltp":1.47,"tv":40250.83,"id":169}]}]}
{"op":"mcm","clk":"11761749427","pt":1722523542021,"mc":[{"id":"1.231283997","rc":[{"trd":[[1.47,36511.77]],"batb":[[0,1.46,4],[1,1.44,49],[2,1.43,216.66]],"ltp":1.47,"tv":41186.72,"id":169}],"tv":83660.63}]}
{"op":"mcm","clk":"11761749507","pt":1722523543414,"mc":[{"id":"1.231283997","rc":[{"batl":[[0,3.25,7.6]],"ltp":3.15,"tv":42473.91,"id":31379}]}]}
{"op":"mcm","clk":"11761749831","pt":1722523548499,"mc":[{"id":"1.231283997","rc":[{"batb":[[0,1.47,467.95],[1,1.46,4],[2,1.44,49]],"ltp":1.47,"tv":41186.72,"id":169}]}]}
{"op":"mcm","clk":"11761750084","pt":1722523552115,"mc":[{"id":"1.231283997","rc":[{"batl":[[0,3.1,4],[1,3.15,4]],"ltp":3.15,"tv":42473.91,"id":31379},{"trd":[[1.47,37447.66]],"batb":[[0,1.47,4]],"ltp":1.47,"tv":42122.61,"id":169}],"tv":84596.52}]}
{"op":"mcm","clk":"11761750160","pt":1722523553100,"mc":[{"id":"1.231283997","rc":[{"batb":[[0,1.46,4],[1,1.44,49],[2,1.43,216.66]],"ltp":1.47,"tv":42122.61,"id":169}]}]}
{"op":"mcm","clk":"11761751184","pt":1722523567220,"mc":[{"id":"1.231283997","rc":[{"batb":[[0,3.05,4],[1,3,21.58],[2,1.43,116.28]],"ltp":3.15,"tv":42473.91,"id":31379},{"batl":[[0,1.48,24.44]],"ltp":1.47,"tv":42122.61,"id":169}]}]}
{"op":"mcm","clk":"11761752104","pt":1722523579043,"mc":[{"id":"1.231283997","rc":[{"batl":[[0,3.25,7.68]],"ltp":3.15,"tv":42473.91,"id":31379}]}]}
{"op":"mcm","clk":"11761752272","pt":1722523581325,"mc":[{"id":"1.231283997","rc":[{"batb":[[1,1.45,5.28],[2,1.44,49]],"ltp":1.47,"tv":42122.61,"id":169}]}]}
{"op":"mcm","clk":"11761752365","pt":1722523582472,"mc":[{"id":"1.231283997","rc":[{"batl":[[0,3.2,4],[1,3.25,7.68]],"ltp":3.15,"tv":42473.91,"id":31379}]}]}
{"op":"mcm","clk":"11761753430","pt":1722523597470,"mc":[{"id":"1.231283997","rc":[{"batb":[[0,1.46,8]],"ltp":1.47,"tv":42122.61,"id":169}]}]}
{"op":"mcm","clk":"11761753591","pt":1722523599278,"mc":[{"id":"1.231283997","rc":[{"batl":[[0,3.2,11.72]],"ltp":3.15,"tv":42473.91,"id":31379}]}]}
{"op":"mcm","clk":"11761753689","pt":1722523600268,"mc":[{"id":"1.231283997","rc":[{"batb":[[0,1.47,186.01],[1,1.46,8],[2,1.45,5.28]],"ltp":1.47,"tv":42122.61,"id":169}]}]}
{"op":"mcm","clk":"11761753724","pt":1722523600571,"mc":[{"id":"1.231283997","rc":[{"batl":[[0,1.48,20.44]],"ltp":1.47,"tv":42122.61,"id":169}]}]}
{"op":"mcm","clk":"11761753896","pt":1722523602650,"mc":[{"id":"1.231283997","rc":[{"batl":[[0,3.1,18.83],[1,3.2,4]],"ltp":3.15,"tv":42473.91,"id":31379},{"batb":[[2,1.44,49]],"ltp":1.47,"tv":42122.61,"id":169}]}]}
{"op":"mcm","clk":"11761754179","pt":1722523606169,"mc":[{"id":"1.231283997","rc":[{"trd":[[3.1,5513.02]],"batl":[[0,3.1,2.46]],"ltp":3.1,"tv":42490.28,"id":31379},{"trd":[[1.47,37854.2]],"batb":[[0,1.46,4],[1,1.44,49],[2,1.43,216.66]],"ltp":1.47,"tv":42529.15,"id":169}],"tv":85019.44}]}
{"op":"mcm","clk":"11761754226","pt":1722523606681,"mc":[{"id":"1.231283997","rc":[{"batl":[[1,3.2,0]],"ltp":3.1,"tv":42490.28,"id":31379},{"batb":[[0,1.44,49],[1,1.43,216.66],[2,1.38,131.58]],"ltp":1.47,"tv":42529.15,"id":169}]}]}
{"op":"mcm","clk":"11761754368","pt":1722523608395,"mc":[{"id":"1.231283997","rc":[{"batb":[[0,3.05,10.63]],"ltp":3.1,"tv":42490.28,"id":31379}]}]}
{"op":"mcm","clk":"11761754674","pt":1722523612703,"mc":[{"id":"1.231283997","rc":[{"batl":[[0,3.25,4],[1,3.3,4]],"ltp":3.1,"tv":42490.28,"id":31379},{"batb":[[0,1.45,4],[1,1.44,53],[2,1.43,216.66]],"batl":[[0,1.48,24.44]],"ltp":1.47,"tv":42529.15,"id":169}]}]}
{"op":"mcm","clk":"11761756565","pt":1722523636408,"mc":[{"id":"1.231283997","rc":[{"batl":[[0,3.25,9.88]],"ltp":3.1,"tv":42490.28,"id":31379}]}]}
{"op":"mcm","clk":"11761757400","pt":1722523646631,"mc":[{"id":"1.231283997","rc":[{"batb":[[0,1.45,9.96]],"ltp":1.47,"tv":42529.15,"id":169}]}]}
{"op":"mcm","clk":"11761891855","pt":1722525175121,"mc":[{"id":"1.231283997","rc":[{"trd":[[3.1,5524.97],[3.15,36985.68],[3.2,70.44]],"batb":[[0,3.05,10.64]],"batl":[[0,3.25,9.89]],"ltp":3.1,"tv":42583.09,"id":31379},{"trd":[[1.46,4681.68],[1.47,37937.03]],"batb":[[0,1.45,9.96]],"batl":[[0,1.48,24.41],[1,1.49,15.31],[2,1.51,30.62]],"ltp":1.47,"tv":42622.2,"id":169}],"tv":85205.29}]}
{"op":"mcm","clk":"11762206552","pt":1722528313607,"mc":[{"id":"1.231283997","rc":[{"trd":[[3.1,5535.3],[3.15,37055.17],[3.2,70.57]],"batb":[[0,3.1,2],[1,3.05,10.65],[2,3,21.58]],"batl":[[0,3.25,9.9]],"ltp":3.1,"tv":42663.03,"id":31379},{"trd":[[1.46,4690.48],[1.47,38008.31]],"batb":[[0,1.45,9.97],[2,1.43,100.38]],"batl":[[0,1.48,24.42],[1,1.49,15.32],[2,1.51,30.64]],"ltp":1.47,"tv":42702.29,"id":169}],"tv":85365.32}]}
{"op":"mcm","clk":"11762206760","pt":1722528315098,"mc":[{"id":"1.231283997","rc":[{"batb":[[0,3.1,6]],"ltp":3.1,"tv":42663.03,"id":31379}]}]}
{"op":"mcm","clk":"11762206888","pt":1722528316003,"mc":[{"id":"1.231283997","rc":[{"batb":[[0,3.1,4]],"ltp":3.1,"tv":42663.03,"id":31379}]}]}
{"op":"mcm","clk":"11762245952","pt":1722528597835,"mc":[{"id":"1.231283997","rc":[{"batb":[[0,3.15,2],[1,3.1,4],[2,3.05,10.65]],"batl":[[2,3.35,1.04]],"ltp":3.1,"tv":42663.03,"id":31379}]}]}
{"op":"mcm","clk":"11762246267","pt":1722528600014,"mc":[{"id":"1.231283997","rc":[{"batb":[[0,3.1,4],[1,3.05,10.65],[2,3,21.58]],"ltp":3.1,"tv":42663.03,"id":31379}]}]}
{"op":"mcm","clk":"11762246824","pt":1722528604259,"mc":[{"id":"1.231283997","rc":[{"batb":[[0,3.15,2],[1,3.1,4],[2,3.05,10.65]],"ltp":3.1,"tv":42663.03,"id":31379}]}]}
{"op":"mcm","clk":"11762247147","pt":1722528606658,"mc":[{"id":"1.231283997","rc":[{"batb":[[0,3.1,4],[1,3.05,10.65],[2,3,21.58]],"ltp":3.1,"tv":42663.03,"id":31379}]}]}
{"op":"mcm","clk":"11762248887","pt":1722528619287,"mc":[{"id":"1.231283997","rc":[{"batb":[[0,3.15,2],[1,3.1,4],[2,3.05,10.65]],"ltp":3.1,"tv":42663.03,"id":31379}]}]}
{"op":"mcm","clk":"11762249279","pt":1722528622087,"mc":[{"id":"1.231283997","rc":[{"batb":[[0,3.1,4],[1,3.05,10.65],[2,3,21.58]],"ltp":3.1,"tv":42663.03,"id":31379}]}]}
{"op":"mcm","clk":"11762249783","pt":1722528625790,"mc":[{"id":"1.231283997","rc":[{"batb":[[0,3.15,2],[1,3.1,4],[2,3.05,10.65]],"ltp":3.1,"tv":42663.03,"id":31379}]}]}
{"op":"mcm","clk":"11762250036","pt":1722528627890,"mc":[{"id":"1.231283997","rc":[{"batb":[[0,3.1,4],[1,3.05,10.65],[2,3,21.58]],"ltp":3.1,"tv":42663.03,"id":31379}]}]}
{"op":"mcm","clk":"11762308941","pt":1722529063203,"mc":[{"id":"1.231283997","rc":[{"batb":[[0,3.15,2],[1,3.1,4],[2,3.05,10.65]],"ltp":3.1,"tv":42663.03,"id":31379}]}]}
{"op":"mcm","clk":"11762309265","pt":1722529065513,"mc":[{"id":"1.231283997","rc":[{"batb":[[0,3.1,4],[1,3.05,10.65],[2,3,21.58]],"ltp":3.1,"tv":42663.03,"id":31379}]}]}
{"op":"mcm","clk":"11762483483","pt":1722530441572,"mc":[{"id":"1.231283997","rc":[{"batb":[[0,3.15,2],[1,3.1,4],[2,3.05,10.65]],"ltp":3.1,"tv":42663.03,"id":31379}]}]}
{"op":"mcm","clk":"11762483843","pt":1722530443660,"mc":[{"id":"1.231283997","rc":[{"batb":[[0,3.1,4],[1,3.05,10.65],[2,3,21.58]],"ltp":3.1,"tv":42663.03,"id":31379}]}]}
{"op":"mcm","clk":"11762518779","pt":1722530654562,"mc":[{"id":"1.231283997","rc":[{"batb":[[0,3.15,2],[1,3.1,4],[2,3.05,10.65]],"ltp":3.1,"tv":42663.03,"id":31379}]}]}
{"op":"mcm","clk":"11762519009","pt":1722530656774,"mc":[{"id":"1.231283997","rc":[{"batb":[[0,3.1,4],[1,3.05,10.65],[2,3,21.58]],"ltp":3.1,"tv":42663.03,"id":31379}]}]}
{"op":"mcm","clk":"11762519253","pt":1722530659191,"mc":[{"id":"1.231283997","rc":[{"batb":[[0,3.15,2],[1,3.1,4],[2,3.05,10.65]],"ltp":3.1,"tv":42663.03,"id":31379}]}]}
{"op":"mcm","clk":"11762519324","pt":1722530659879,"mc":[{"id":"1.231283997","rc":[{"batl":[[0,1.47,4],[1,1.48,24.42],[2,1.49,15.32]],"ltp":1.47,"tv":42702.29,"id":169}]}]}
{"op":"mcm","clk":"11762519506","pt":1722530661386,"mc":[{"id":"1.231283997","rc":[{"batb":[[0,3.1,4],[1,3.05,10.65],[2,3,21.58]],"ltp":3.1,"tv":42663.03,"id":31379}]}]}
{"op":"mcm","clk":"11762519884","pt":1722530664689,"mc":[{"id":"1.231283997","rc":[{"batb":[[0,3.15,2],[1,3.1,4],[2,3.05,10.65]],"ltp":3.1,"tv":42663.03,"id":31379}]}]}
{"op":"mcm","clk":"11762520144","pt":1722530667110,"mc":[{"id":"1.231283997","rc":[{"batb":[[0,3.1,4],[1,3.05,10.65],[2,3,21.58]],"ltp":3.1,"tv":42663.03,"id":31379}]}]}
{"op":"mcm","clk":"11762520544","pt":1722530670682,"mc":[{"id":"1.231283997","rc":[{"batb":[[0,3.15,2],[1,3.1,4],[2,3.05,10.65]],"ltp":3.1,"tv":42663.03,"id":31379}]}]}
{"op":"mcm","clk":"11762520778","pt":1722530673001,"mc":[{"id":"1.231283997","rc":[{"batb":[[0,3.1,4],[1,3.05,10.65],[2,3,21.58]],"ltp":3.1,"tv":42663.03,"id":31379}]}]}
{"op":"mcm","clk":"11762521172","pt":1722530676652,"mc":[{"id":"1.231283997","rc":[{"batb":[[0,3.15,2],[1,3.1,4],[2,3.05,10.65]],"ltp":3.1,"tv":42663.03,"id":31379}]}]}
{"op":"mcm","clk":"11762521412","pt":1722530678598,"mc":[{"id":"1.231283997","rc":[{"batb":[[0,3.1,4],[1,3.05,10.65],[2,3,21.58]],"ltp":3.1,"tv":42663.03,"id":31379}]}]}
{"op":"mcm","clk":"11762522080","pt":1722530685092,"mc":[{"id":"1.231283997","rc":[{"batb":[[0,3.15,2],[1,3.1,4],[2,3.05,10.65]],"ltp":3.1,"tv":42663.03,"id":31379}]}]}
{"op":"mcm","clk":"11762522325","pt":1722530687515,"mc":[{"id":"1.231283997","rc":[{"batb":[[0,3.1,4],[1,3.05,10.65],[2,3,21.58]],"ltp":3.1,"tv":42663.03,"id":31379}]}]}
{"op":"mcm","clk":"11762522586","pt":1722530689710,"mc":[{"id":"1.231283997","rc":[{"batb":[[0,3.15,2],[1,3.1,4],[2,3.05,10.65]],"ltp":3.1,"tv":42663.03,"id":31379}]}]}
{"op":"mcm","clk":"11762522823","pt":1722530691879,"mc":[{"id":"1.231283997","rc":[{"batb":[[0,3.1,4],[1,3.05,10.65],[2,3,21.58]],"ltp":3.1,"tv":42663.03,"id":31379}]}]}
{"op":"mcm","clk":"11762523342","pt":1722530696230,"mc":[{"id":"1.231283997","rc":[{"batb":[[0,3.15,2],[1,3.1,4],[2,3.05,10.65]],"ltp":3.1,"tv":42663.03,"id":31379}]}]}
{"op":"mcm","clk":"11762523591","pt":1722530698509,"mc":[{"id":"1.231283997","rc":[{"batb":[[0,3.1,4],[1,3.05,10.65],[2,3,21.58]],"ltp":3.1,"tv":42663.03,"id":31379}]}]}
{"op":"mcm","clk":"11762523990","pt":1722530701830,"mc":[{"id":"1.231283997","rc":[{"batb":[[0,3.15,2],[1,3.1,4],[2,3.05,10.65]],"ltp":3.1,"tv":42663.03,"id":31379}]}]}
{"op":"mcm","clk":"11762524296","pt":1722530704126,"mc":[{"id":"1.231283997","rc":[{"batb":[[0,3.1,4],[1,3.05,10.65],[2,3,21.58]],"ltp":3.1,"tv":42663.03,"id":31379}]}]}
{"op":"mcm","clk":"11762524829","pt":1722530708211,"mc":[{"id":"1.231283997","rc":[{"batb":[[0,3.15,2],[1,3.1,4],[2,3.05,10.65]],"ltp":3.1,"tv":42663.03,"id":31379}]}]}
{"op":"mcm","clk":"11762525076","pt":1722530710408,"mc":[{"id":"1.231283997","rc":[{"batb":[[0,3.1,4],[1,3.05,10.65],[2,3,21.58]],"ltp":3.1,"tv":42663.03,"id":31379}]}]}
{"op":"mcm","clk":"11762525493","pt":1722530714155,"mc":[{"id":"1.231283997","rc":[{"batb":[[0,3.15,2],[1,3.1,4],[2,3.05,10.65]],"ltp":3.1,"tv":42663.03,"id":31379}]}]}
{"op":"mcm","clk":"11762525782","pt":1722530716434,"mc":[{"id":"1.231283997","rc":[{"batb":[[0,3.1,4],[1,3.05,10.65],[2,3,21.58]],"ltp":3.1,"tv":42663.03,"id":31379}]}]}
{"op":"mcm","clk":"11762526094","pt":1722530719018,"mc":[{"id":"1.231283997","rc":[{"batb":[[0,3.15,2],[1,3.1,4],[2,3.05,10.65]],"ltp":3.1,"tv":42663.03,"id":31379}]}]}
{"op":"mcm","clk":"11762526371","pt":1722530721323,"mc":[{"id":"1.231283997","rc":[{"batb":[[0,3.1,4],[1,3.05,10.65],[2,3,21.58]],"ltp":3.1,"tv":42663.03,"id":31379}]}]}
{"op":"mcm","clk":"11762526780","pt":1722530724835,"mc":[{"id":"1.231283997","rc":[{"batb":[[0,3.15,2],[1,3.1,4],[2,3.05,10.65]],"ltp":3.1,"tv":42663.03,"id":31379}]}]}
{"op":"mcm","clk":"11762527066","pt":1722530727150,"mc":[{"id":"1.231283997","rc":[{"batb":[[0,3.1,4],[1,3.05,10.65],[2,3,21.58]],"ltp":3.1,"tv":42663.03,"id":31379}]}]}
{"op":"mcm","clk":"11762527492","pt":1722530730535,"mc":[{"id":"1.231283997","rc":[{"batb":[[0,3.15,2],[1,3.1,4],[2,3.05,10.65]],"ltp":3.1,"tv":42663.03,"id":31379}]}]}
{"op":"mcm","clk":"11762527790","pt":1722530732945,"mc":[{"id":"1.231283997","rc":[{"batb":[[0,3.1,4],[1,3.05,10.65],[2,3,21.58]],"ltp":3.1,"tv":42663.03,"id":31379}]}]}
{"op":"mcm","clk":"11762528300","pt":1722530737555,"mc":[{"id":"1.231283997","rc":[{"batb":[[0,3.15,2],[1,3.1,4],[2,3.05,10.65]],"ltp":3.1,"tv":42663.03,"id":31379}]}]}
{"op":"mcm","clk":"11762528570","pt":1722530739966,"mc":[{"id":"1.231283997","rc":[{"batb":[[0,3.1,4],[1,3.05,10.65],[2,3,21.58]],"ltp":3.1,"tv":42663.03,"id":31379}]}]}
{"op":"mcm","clk":"11762528841","pt":1722530742154,"mc":[{"id":"1.231283997","rc":[{"batb":[[0,3.15,2],[1,3.1,4],[2,3.05,10.65]],"ltp":3.1,"tv":42663.03,"id":31379}]}]}
{"op":"mcm","clk":"11762529117","pt":1722530744518,"mc":[{"id":"1.231283997","rc":[{"batb":[[0,3.1,4],[1,3.05,10.65],[2,3,21.58]],"ltp":3.1,"tv":42663.03,"id":31379}]}]}
{"op":"mcm","clk":"11762529366","pt":1722530747556,"mc":[{"id":"1.231283997","rc":[{"batb":[[0,3.15,2],[1,3.1,4],[2,3.05,10.65]],"ltp":3.1,"tv":42663.03,"id":31379}]}]}
{"op":"mcm","clk":"11762529676","pt":1722530749052,"mc":[{"id":"1.231283997","rc":[{"batb":[[0,3.1,4],[1,3.05,10.65],[2,3,21.58]],"ltp":3.1,"tv":42663.03,"id":31379}]}]}
{"op":"mcm","clk":"11762529962","pt":1722530751768,"mc":[{"id":"1.231283997","rc":[{"batb":[[0,3.15,2],[1,3.1,4],[2,3.05,10.65]],"ltp":3.1,"tv":42663.03,"id":31379}]}]}
{"op":"mcm","clk":"11762530175","pt":1722530753963,"mc":[{"id":"1.231283997","rc":[{"batb":[[0,3.1,4],[1,3.05,10.65],[2,3,21.58]],"ltp":3.1,"tv":42663.03,"id":31379}]}]}
{"op":"mcm","clk":"11762530484","pt":1722530757162,"mc":[{"id":"1.231283997","rc":[{"batb":[[0,3.15,2],[1,3.1,4],[2,3.05,10.65]],"ltp":3.1,"tv":42663.03,"id":31379}]}]}
{"op":"mcm","clk":"11762530724","pt":1722530759478,"mc":[{"id":"1.231283997","rc":[{"batb":[[0,3.1,4],[1,3.05,10.65],[2,3,21.58]],"ltp":3.1,"tv":42663.03,"id":31379}]}]}
{"op":"mcm","clk":"11762530964","pt":1722530761794,"mc":[{"id":"1.231283997","rc":[{"batb":[[0,3.15,2],[1,3.1,4],[2,3.05,10.65]],"ltp":3.1,"tv":42663.03,"id":31379}]}]}
{"op":"mcm","clk":"11762531226","pt":1722530763997,"mc":[{"id":"1.231283997","rc":[{"batb":[[0,3.1,4],[1,3.05,10.65],[2,3,21.58]],"ltp":3.1,"tv":42663.03,"id":31379}]}]}
{"op":"mcm","clk":"11762531612","pt":1722530767378,"mc":[{"id":"1.231283997","rc":[{"batb":[[0,3.15,2],[1,3.1,4],[2,3.05,10.65]],"ltp":3.1,"tv":42663.03,"id":31379}]}]}
{"op":"mcm","clk":"11762531865","pt":1722530769562,"mc":[{"id":"1.231283997","rc":[{"batb":[[0,3.1,4],[1,3.05,10.65],[2,3,21.58]],"ltp":3.1,"tv":42663.03,"id":31379}]}]}
{"op":"mcm","clk":"11762532104","pt":1722530771893,"mc":[{"id":"1.231283997","rc":[{"batb":[[0,3.15,2],[1,3.1,4],[2,3.05,10.65]],"ltp":3.1,"tv":42663.03,"id":31379}]}]}
{"op":"mcm","clk":"11762532354","pt":1722530774893,"mc":[{"id":"1.231283997","rc":[{"batb":[[0,3.1,4],[1,3.05,10.65],[2,3,21.58]],"ltp":3.1,"tv":42663.03,"id":31379}]}]}
{"op":"mcm","clk":"11762532697","pt":1722530777205,"mc":[{"id":"1.231283997","rc":[{"batb":[[0,3.15,2],[1,3.1,4],[2,3.05,10.65]],"ltp":3.1,"tv":42663.03,"id":31379}]}]}
{"op":"mcm","clk":"11762532958","pt":1722530779516,"mc":[{"id":"1.231283997","rc":[{"batb":[[0,3.1,4],[1,3.05,10.65],[2,3,21.58]],"ltp":3.1,"tv":42663.03,"id":31379}]}]}
{"op":"mcm","clk":"11762533236","pt":1722530781785,"mc":[{"id":"1.231283997","rc":[{"batb":[[0,3.15,2],[1,3.1,4],[2,3.05,10.65]],"ltp":3.1,"tv":42663.03,"id":31379}]}]}
{"op":"mcm","clk":"11762533513","pt":1722530784101,"mc":[{"id":"1.231283997","rc":[{"batb":[[0,3.1,4],[1,3.05,10.65],[2,3,21.58]],"ltp":3.1,"tv":42663.03,"id":31379}]}]}
{"op":"mcm","clk":"11762533835","pt":1722530788146,"mc":[{"id":"1.231283997","rc":[{"batb":[[0,3.15,2],[1,3.1,4],[2,3.05,10.65]],"ltp":3.1,"tv":42663.03,"id":31379}]}]}
{"op":"mcm","clk":"11762534105","pt":1722530789401,"mc":[{"id":"1.231283997","rc":[{"batb":[[0,3.1,4],[1,3.05,10.65],[2,3,21.58]],"ltp":3.1,"tv":42663.03,"id":31379}]}]}
{"op":"mcm","clk":"11762534461","pt":1722530793019,"mc":[{"id":"1.231283997","rc":[{"batb":[[0,3.15,2],[1,3.1,4],[2,3.05,10.65]],"ltp":3.1,"tv":42663.03,"id":31379}]}]}
{"op":"mcm","clk":"11762534738","pt":1722530795412,"mc":[{"id":"1.231283997","rc":[{"batb":[[0,3.1,4],[1,3.05,10.65],[2,3,21.58]],"ltp":3.1,"tv":42663.03,"id":31379}]}]}
{"op":"mcm","clk":"11762535109","pt":1722530798913,"mc":[{"id":"1.231283997","rc":[{"batb":[[0,3.15,2],[1,3.1,4],[2,3.05,10.65]],"ltp":3.1,"tv":42663.03,"id":31379}]}]}
{"op":"mcm","clk":"11762535390","pt":1722530801237,"mc":[{"id":"1.231283997","rc":[{"batb":[[0,3.1,4],[1,3.05,10.65],[2,3,21.58]],"ltp":3.1,"tv":42663.03,"id":31379}]}]}
{"op":"mcm","clk":"11762535618","pt":1722530803448,"mc":[{"id":"1.231283997","rc":[{"batb":[[0,3.15,2],[1,3.1,4],[2,3.05,10.65]],"ltp":3.1,"tv":42663.03,"id":31379}]}]}
{"op":"mcm","clk":"11762535868","pt":1722530805803,"mc":[{"id":"1.231283997","rc":[{"batb":[[0,3.1,4],[1,3.05,10.65],[2,3,21.58]],"ltp":3.1,"tv":42663.03,"id":31379}]}]}
{"op":"mcm","clk":"11762536115","pt":1722530808098,"mc":[{"id":"1.231283997","rc":[{"batb":[[0,3.15,2],[1,3.1,4],[2,3.05,10.65]],"ltp":3.1,"tv":42663.03,"id":31379}]}]}
{"op":"mcm","clk":"11762536367","pt":1722530810691,"mc":[{"id":"1.231283997","rc":[{"batb":[[0,3.1,4],[1,3.05,10.65],[2,3,21.58]],"ltp":3.1,"tv":42663.03,"id":31379}]}]}
{"op":"mcm","clk":"11762536670","pt":1722530813423,"mc":[{"id":"1.231283997","rc":[{"batb":[[0,3.15,2],[1,3.1,4],[2,3.05,10.65]],"ltp":3.1,"tv":42663.03,"id":31379}]}]}
{"op":"mcm","clk":"11762536977","pt":1722530816324,"mc":[{"id":"1.231283997","rc":[{"batb":[[0,3.1,4],[1,3.05,10.65],[2,3,21.58]],"ltp":3.1,"tv":42663.03,"id":31379}]}]}
{"op":"mcm","clk":"11762537292","pt":1722530819012,"mc":[{"id":"1.231283997","rc":[{"batb":[[0,3.15,2],[1,3.1,4],[2,3.05,10.65]],"ltp":3.1,"tv":42663.03,"id":31379}]}]}
{"op":"mcm","clk":"11762537538","pt":1722530821236,"mc":[{"id":"1.231283997","rc":[{"batb":[[0,3.1,4],[1,3.05,10.65],[2,3,21.58]],"ltp":3.1,"tv":42663.03,"id":31379}]}]}
{"op":"mcm","clk":"11762537992","pt":1722530825266,"mc":[{"id":"1.231283997","rc":[{"batb":[[0,3.15,2],[1,3.1,4],[2,3.05,10.65]],"ltp":3.1,"tv":42663.03,"id":31379}]}]}
{"op":"mcm","clk":"11762538262","pt":1722530827452,"mc":[{"id":"1.231283997","rc":[{"batb":[[0,3.1,4],[1,3.05,10.65],[2,3,21.58]],"ltp":3.1,"tv":42663.03,"id":31379}]}]}
{"op":"mcm","clk":"11762538550","pt":1722530829723,"mc":[{"id":"1.231283997","rc":[{"batb":[[0,3.15,2],[1,3.1,4],[2,3.05,10.65]],"ltp":3.1,"tv":42663.03,"id":31379}]}]}
{"op":"mcm","clk":"11762538800","pt":1722530832052,"mc":[{"id":"1.231283997","rc":[{"batb":[[0,3.1,4],[1,3.05,10.65],[2,3,21.58]],"ltp":3.1,"tv":42663.03,"id":31379}]}]}
{"op":"mcm","clk":"11762539208","pt":1722530836047,"mc":[{"id":"1.231283997","rc":[{"batb":[[0,3.15,2],[1,3.1,4],[2,3.05,10.65]],"ltp":3.1,"tv":42663.03,"id":31379}]}]}
{"op":"mcm","clk":"11762539466","pt":1722530838348,"mc":[{"id":"1.231283997","rc":[{"batb":[[0,3.1,4],[1,3.05,10.65],[2,3,21.58]],"ltp":3.1,"tv":42663.03,"id":31379}]}]}
{"op":"mcm","clk":"11762539848","pt":1722530841664,"mc":[{"id":"1.231283997","rc":[{"batb":[[0,3.15,2],[1,3.1,4],[2,3.05,10.65]],"ltp":3.1,"tv":42663.03,"id":31379}]}]}
{"op":"mcm","clk":"11762540101","pt":1722530843854,"mc":[{"id":"1.231283997","rc":[{"batb":[[0,3.1,4],[1,3.05,10.65],[2,3,21.58]],"ltp":3.1,"tv":42663.03,"id":31379}]}]}
{"op":"mcm","clk":"11762540286","pt":1722530845954,"mc":[{"id":"1.231283997","rc":[{"batb":[[0,3.15,2],[1,3.1,4],[2,3.05,10.65]],"ltp":3.1,"tv":42663.03,"id":31379}]}]}
{"op":"mcm","clk":"11762540534","pt":1722530848195,"mc":[{"id":"1.231283997","rc":[{"batb":[[0,3.1,4],[1,3.05,10.65],[2,3,21.58]],"ltp":3.1,"tv":42663.03,"id":31379}]}]}
{"op":"mcm","clk":"11762540788","pt":1722530850479,"mc":[{"id":"1.231283997","rc":[{"batb":[[0,3.15,2],[1,3.1,4],[2,3.05,10.65]],"ltp":3.1,"tv":42663.03,"id":31379}]}]}
{"op":"mcm","clk":"11762541026","pt":1722530852778,"mc":[{"id":"1.231283997","rc":[{"batb":[[0,3.1,4],[1,3.05,10.65],[2,3,21.58]],"ltp":3.1,"tv":42663.03,"id":31379}]}]}
{"op":"mcm","clk":"11762541409","pt":1722530856061,"mc":[{"id":"1.231283997","rc":[{"batb":[[0,3.15,2],[1,3.1,4],[2,3.05,10.65]],"ltp":3.1,"tv":42663.03,"id":31379}]}]}
{"op":"mcm","clk":"11762541718","pt":1722530858373,"mc":[{"id":"1.231283997","rc":[{"batb":[[0,3.1,4],[1,3.05,10.65],[2,3,21.58]],"ltp":3.1,"tv":42663.03,"id":31379}]}]}
{"op":"mcm","clk":"11762542012","pt":1722530860564,"mc":[{"id":"1.231283997","rc":[{"batb":[[0,3.15,2],[1,3.1,4],[2,3.05,10.65]],"ltp":3.1,"tv":42663.03,"id":31379}]}]}
{"op":"mcm","clk":"11762542311","pt":1722530862913,"mc":[{"id":"1.231283997","rc":[{"batb":[[0,3.1,4],[1,3.05,10.65],[2,3,21.58]],"ltp":3.1,"tv":42663.03,"id":31379}]}]}
{"op":"mcm","clk":"11762542868","pt":1722530868010,"mc":[{"id":"1.231283997","rc":[{"batb":[[0,3.15,2],[1,3.1,4],[2,3.05,10.65]],"ltp":3.1,"tv":42663.03,"id":31379}]}]}
{"op":"mcm","clk":"11762543129","pt":1722530870319,"mc":[{"id":"1.231283997","rc":[{"batb":[[0,3.1,4],[1,3.05,10.65],[2,3,21.58]],"ltp":3.1,"tv":42663.03,"id":31379}]}]}
{"op":"mcm","clk":"11762543414","pt":1722530872860,"mc":[{"id":"1.231283997","rc":[{"batb":[[0,3.15,2],[1,3.1,4],[2,3.05,10.65]],"ltp":3.1,"tv":42663.03,"id":31379}]}]}
{"op":"mcm","clk":"11762543705","pt":1722530875205,"mc":[{"id":"1.231283997","rc":[{"batb":[[0,3.1,4],[1,3.05,10.65],[2,3,21.58]],"ltp":3.1,"tv":42663.03,"id":31379}]}]}
{"op":"mcm","clk":"11762544193","pt":1722530879319,"mc":[{"id":"1.231283997","rc":[{"batb":[[0,3.15,2],[1,3.1,4],[2,3.05,10.65]],"ltp":3.1,"tv":42663.03,"id":31379}]}]}
{"op":"mcm","clk":"11762544446","pt":1722530881584,"mc":[{"id":"1.231283997","rc":[{"batb":[[0,3.1,4],[1,3.05,10.65],[2,3,21.58]],"ltp":3.1,"tv":42663.03,"id":31379}]}]}
{"op":"mcm","clk":"11762544939","pt":1722530885895,"mc":[{"id":"1.231283997","rc":[{"batb":[[0,3.15,2],[1,3.1,4],[2,3.05,10.65]],"ltp":3.1,"tv":42663.03,"id":31379}]}]}
{"op":"mcm","clk":"11762545222","pt":1722530888193,"mc":[{"id":"1.231283997","rc":[{"batb":[[0,3.1,4],[1,3.05,10.65],[2,3,21.58]],"ltp":3.1,"tv":42663.03,"id":31379}]}]}
{"op":"mcm","clk":"11762545501","pt":1722530890384,"mc":[{"id":"1.231283997","rc":[{"batb":[[0,3.15,2],[1,3.1,4],[2,3.05,10.65]],"ltp":3.1,"tv":42663.03,"id":31379}]}]}
{"op":"mcm","clk":"11762545767","pt":1722530892680,"mc":[{"id":"1.231283997","rc":[{"batb":[[0,3.1,4],[1,3.05,10.65],[2,3,21.58]],"ltp":3.1,"tv":42663.03,"id":31379}]}]}
{"op":"mcm","clk":"11762546292","pt":1722530896910,"mc":[{"id":"1.231283997","rc":[{"batb":[[0,3.15,2],[1,3.1,4],[2,3.05,10.65]],"ltp":3.1,"tv":42663.03,"id":31379}]}]}
{"op":"mcm","clk":"11762546591","pt":1722530899102,"mc":[{"id":"1.231283997","rc":[{"batb":[[0,3.1,4],[1,3.05,10.65],[2,3,21.58]],"ltp":3.1,"tv":42663.03,"id":31379}]}]}
{"op":"mcm","clk":"11762546858","pt":1722530901238,"mc":[{"id":"1.231283997","rc":[{"batb":[[0,3.15,2],[1,3.1,4],[2,3.05,10.65]],"ltp":3.1,"tv":42663.03,"id":31379}]}]}
{"op":"mcm","clk":"11762547108","pt":1722530903402,"mc":[{"id":"1.231283997","rc":[{"batb":[[0,3.1,4],[1,3.05,10.65],[2,3,21.58]],"ltp":3.1,"tv":42663.03,"id":31379}]}]}
{"op":"mcm","clk":"11762547450","pt":1722530906311,"mc":[{"id":"1.231283997","rc":[{"batb":[[0,3.15,2],[1,3.1,4],[2,3.05,10.65]],"ltp":3.1,"tv":42663.03,"id":31379}]}]}
{"op":"mcm","clk":"11762547697","pt":1722530908611,"mc":[{"id":"1.231283997","rc":[{"batb":[[0,3.1,4],[1,3.05,10.65],[2,3,21.58]],"ltp":3.1,"tv":42663.03,"id":31379}]}]}
{"op":"mcm","clk":"11762548124","pt":1722530911952,"mc":[{"id":"1.231283997","rc":[{"batb":[[0,3.15,2],[1,3.1,4],[2,3.05,10.65]],"ltp":3.1,"tv":42663.03,"id":31379}]}]}
{"op":"mcm","clk":"11762548399","pt":1722530914137,"mc":[{"id":"1.231283997","rc":[{"batb":[[0,3.1,4],[1,3.05,10.65],[2,3,21.58]],"ltp":3.1,"tv":42663.03,"id":31379}]}]}
{"op":"mcm","clk":"11762548675","pt":1722530916291,"mc":[{"id":"1.231283997","rc":[{"batb":[[0,3.15,2],[1,3.1,4],[2,3.05,10.65]],"ltp":3.1,"tv":42663.03,"id":31379}]}]}
{"op":"mcm","clk":"11762548949","pt":1722530918569,"mc":[{"id":"1.231283997","rc":[{"batb":[[0,3.1,4],[1,3.05,10.65],[2,3,21.58]],"ltp":3.1,"tv":42663.03,"id":31379}]}]}
{"op":"mcm","clk":"11762549301","pt":1722530921439,"mc":[{"id":"1.231283997","rc":[{"batb":[[0,3.15,2],[1,3.1,4],[2,3.05,10.65]],"ltp":3.1,"tv":42663.03,"id":31379}]}]}
{"op":"mcm","clk":"11762549544","pt":1722530923783,"mc":[{"id":"1.231283997","rc":[{"batb":[[0,3.1,4],[1,3.05,10.65],[2,3,21.58]],"ltp":3.1,"tv":42663.03,"id":31379}]}]}
{"op":"mcm","clk":"11762549778","pt":1722530925877,"mc":[{"id":"1.231283997","rc":[{"batb":[[0,3.15,2],[1,3.1,4],[2,3.05,10.65]],"ltp":3.1,"tv":42663.03,"id":31379}]}]}
{"op":"mcm","clk":"11762550032","pt":1722530928260,"mc":[{"id":"1.231283997","rc":[{"batb":[[0,3.1,4],[1,3.05,10.65],[2,3,21.58]],"ltp":3.1,"tv":42663.03,"id":31379}]}]}
{"op":"mcm","clk":"11762550314","pt":1722530930564,"mc":[{"id":"1.231283997","rc":[{"batb":[[0,3.15,2],[1,3.1,4],[2,3.05,10.65]],"ltp":3.1,"tv":42663.03,"id":31379}]}]}
{"op":"mcm","clk":"11762550602","pt":1722530932864,"mc":[{"id":"1.231283997","rc":[{"batb":[[0,3.1,4],[1,3.05,10.65],[2,3,21.58]],"ltp":3.1,"tv":42663.03,"id":31379}]}]}
{"op":"mcm","clk":"11762550940","pt":1722530935368,"mc":[{"id":"1.231283997","rc":[{"batb":[[0,3.15,2],[1,3.1,4],[2,3.05,10.65]],"ltp":3.1,"tv":42663.03,"id":31379}]}]}
{"op":"mcm","clk":"11762551193","pt":1722530937716,"mc":[{"id":"1.231283997","rc":[{"batb":[[0,3.1,4],[1,3.05,10.65],[2,3,21.58]],"ltp":3.1,"tv":42663.03,"id":31379}]}]}
{"op":"mcm","clk":"11762551472","pt":1722530940062,"mc":[{"id":"1.231283997","rc":[{"batb":[[0,3.15,2],[1,3.1,4],[2,3.05,10.65]],"ltp":3.1,"tv":42663.03,"id":31379}]}]}
{"op":"mcm","clk":"11762551745","pt":1722530942466,"mc":[{"id":"1.231283997","rc":[{"batb":[[0,3.1,4],[1,3.05,10.65],[2,3,21.58]],"ltp":3.1,"tv":42663.03,"id":31379}]}]}
{"op":"mcm","clk":"11762552440","pt":1722530948963,"mc":[{"id":"1.231283997","rc":[{"batb":[[0,3.15,2],[1,3.1,4],[2,3.05,10.65]],"ltp":3.1,"tv":42663.03,"id":31379}]}]}
{"op":"mcm","clk":"11762552705","pt":1722530951358,"mc":[{"id":"1.231283997","rc":[{"batb":[[0,3.1,4],[1,3.05,10.65],[2,3,21.58]],"ltp":3.1,"tv":42663.03,"id":31379}]}]}
{"op":"mcm","clk":"11762553206","pt":1722530956348,"mc":[{"id":"1.231283997","rc":[{"batb":[[0,3.15,2],[1,3.1,4],[2,3.05,10.65]],"ltp":3.1,"tv":42663.03,"id":31379}]}]}
{"op":"mcm","clk":"11762553449","pt":1722530958776,"mc":[{"id":"1.231283997","rc":[{"batb":[[0,3.1,4],[1,3.05,10.65],[2,3,21.58]],"ltp":3.1,"tv":42663.03,"id":31379}]}]}
{"op":"mcm","clk":"11762553712","pt":1722530961379,"mc":[{"id":"1.231283997","rc":[{"batb":[[0,3.15,2],[1,3.1,4],[2,3.05,10.65]],"ltp":3.1,"tv":42663.03,"id":31379}]}]}
{"op":"mcm","clk":"11762553730","pt":1722530961549,"mc":[{"id":"1.231283997","rc":[{"batl":[[0,1.47,5]],"ltp":1.47,"tv":42702.29,"id":169}]}]}
{"op":"mcm","clk":"11762553910","pt":1722530963568,"mc":[{"id":"1.231283997","rc":[{"batb":[[0,3.1,4],[1,3.05,10.65],[2,3,21.58]],"ltp":3.1,"tv":42663.03,"id":31379}]}]}
{"op":"mcm","clk":"11762554225","pt":1722530967163,"mc":[{"id":"1.231283997","rc":[{"batb":[[0,3.15,2],[1,3.1,4],[2,3.05,10.65]],"ltp":3.1,"tv":42663.03,"id":31379}]}]}
{"op":"mcm","clk":"11762554405","pt":1722530969484,"mc":[{"id":"1.231283997","rc":[{"batb":[[0,3.1,4],[1,3.05,10.65],[2,3,21.58]],"ltp":3.1,"tv":42663.03,"id":31379}]}]}
{"op":"mcm","clk":"11762554607","pt":1722530971652,"mc":[{"id":"1.231283997","rc":[{"batb":[[0,3.15,2],[1,3.1,4],[2,3.05,10.65]],"ltp":3.1,"tv":42663.03,"id":31379}]}]}
{"op":"mcm","clk":"11762554782","pt":1722530973869,"mc":[{"id":"1.231283997","rc":[{"batb":[[0,3.1,4],[1,3.05,10.65],[2,3,21.58]],"ltp":3.1,"tv":42663.03,"id":31379}]}]}
{"op":"mcm","clk":"11762555530","pt":1722530981678,"mc":[{"id":"1.231283997","rc":[{"batb":[[0,3.15,2],[1,3.1,4],[2,3.05,10.65]],"ltp":3.1,"tv":42663.03,"id":31379}]}]}
{"op":"mcm","clk":"11762555773","pt":1722530983986,"mc":[{"id":"1.231283997","rc":[{"batb":[[0,3.1,4],[1,3.05,10.65],[2,3,21.58]],"ltp":3.1,"tv":42663.03,"id":31379}]}]}
{"op":"mcm","clk":"11762556125","pt":1722530987585,"mc":[{"id":"1.231283997","rc":[{"batb":[[0,3.15,2],[1,3.1,4],[2,3.05,10.65]],"ltp":3.1,"tv":42663.03,"id":31379}]}]}
{"op":"mcm","clk":"11762556343","pt":1722530989991,"mc":[{"id":"1.231283997","rc":[{"batb":[[0,3.1,4],[1,3.05,10.65],[2,3,21.58]],"ltp":3.1,"tv":42663.03,"id":31379}]}]}
{"op":"mcm","clk":"11762556658","pt":1722530993108,"mc":[{"id":"1.231283997","rc":[{"batb":[[0,3.15,2],[1,3.1,4],[2,3.05,10.65]],"ltp":3.1,"tv":42663.03,"id":31379}]}]}
{"op":"mcm","clk":"11762556890","pt":1722530995482,"mc":[{"id":"1.231283997","rc":[{"batb":[[0,3.1,4],[1,3.05,10.65],[2,3,21.58]],"ltp":3.1,"tv":42663.03,"id":31379}]}]}
{"op":"mcm","clk":"11762557092","pt":1722530997870,"mc":[{"id":"1.231283997","rc":[{"batb":[[0,3.15,2],[1,3.1,4],[2,3.05,10.65]],"ltp":3.1,"tv":42663.03,"id":31379}]}]}
{"op":"mcm","clk":"11762557313","pt":1722531000204,"mc":[{"id":"1.231283997","rc":[{"batb":[[0,3.1,4],[1,3.05,10.65],[2,3,21.58]],"ltp":3.1,"tv":42663.03,"id":31379}]}]}
{"op":"mcm","clk":"11762557643","pt":1722531003610,"mc":[{"id":"1.231283997","rc":[{"batb":[[0,3.15,2],[1,3.1,4],[2,3.05,10.65]],"ltp":3.1,"tv":42663.03,"id":31379}]}]}
{"op":"mcm","clk":"11762557882","pt":1722531005912,"mc":[{"id":"1.231283997","rc":[{"batb":[[0,3.1,4],[1,3.05,10.65],[2,3,21.58]],"ltp":3.1,"tv":42663.03,"id":31379}]}]}
{"op":"mcm","clk":"11762558099","pt":1722531008108,"mc":[{"id":"1.231283997","rc":[{"batb":[[0,3.15,2],[1,3.1,4],[2,3.05,10.65]],"ltp":3.1,"tv":42663.03,"id":31379}]}]}
{"op":"mcm","clk":"11762558321","pt":1722531010296,"mc":[{"id":"1.231283997","rc":[{"batb":[[0,3.1,4],[1,3.05,10.65],[2,3,21.58]],"ltp":3.1,"tv":42663.03,"id":31379}]}]}
{"op":"mcm","clk":"11762558506","pt":1722531012514,"mc":[{"id":"1.231283997","rc":[{"batb":[[0,3.15,2],[1,3.1,4],[2,3.05,10.65]],"ltp":3.1,"tv":42663.03,"id":31379}]}]}
{"op":"mcm","clk":"11762558673","pt":1722531014697,"mc":[{"id":"1.231283997","rc":[{"batb":[[0,3.1,4],[1,3.05,10.65],[2,3,21.58]],"ltp":3.1,"tv":42663.03,"id":31379}]}]}
{"op":"mcm","clk":"11762558993","pt":1722531018296,"mc":[{"id":"1.231283997","rc":[{"batb":[[0,3.15,2],[1,3.1,4],[2,3.05,10.65]],"ltp":3.1,"tv":42663.03,"id":31379}]}]}
{"op":"mcm","clk":"11762559169","pt":1722531020522,"mc":[{"id":"1.231283997","rc":[{"batb":[[0,3.1,4],[1,3.05,10.65],[2,3,21.58]],"ltp":3.1,"tv":42663.03,"id":31379}]}]}
{"op":"mcm","clk":"11762559688","pt":1722531025935,"mc":[{"id":"1.231283997","rc":[{"batb":[[0,3.15,2],[1,3.1,4],[2,3.05,10.65]],"ltp":3.1,"tv":42663.03,"id":31379}]}]}
{"op":"mcm","clk":"11762559925","pt":1722531028117,"mc":[{"id":"1.231283997","rc":[{"batb":[[0,3.1,4],[1,3.05,10.65],[2,3,21.58]],"ltp":3.1,"tv":42663.03,"id":31379}]}]}
{"op":"mcm","clk":"11762560189","pt":1722531030823,"mc":[{"id":"1.231283997","rc":[{"batb":[[0,3.15,2],[1,3.1,4],[2,3.05,10.65]],"ltp":3.1,"tv":42663.03,"id":31379}]}]}
{"op":"mcm","clk":"11762560380","pt":1722531033022,"mc":[{"id":"1.231283997","rc":[{"batb":[[0,3.1,4],[1,3.05,10.65],[2,3,21.58]],"ltp":3.1,"tv":42663.03,"id":31379}]}]}
{"op":"mcm","clk":"11762560563","pt":1722531035219,"mc":[{"id":"1.231283997","rc":[{"batb":[[0,3.15,2],[1,3.1,4],[2,3.05,10.65]],"ltp":3.1,"tv":42663.03,"id":31379}]}]}
{"op":"mcm","clk":"11762560752","pt":1722531037510,"mc":[{"id":"1.231283997","rc":[{"batb":[[0,3.1,4],[1,3.05,10.65],[2,3,21.58]],"ltp":3.1,"tv":42663.03,"id":31379}]}]}
{"op":"mcm","clk":"11762560927","pt":1722531039745,"mc":[{"id":"1.231283997","rc":[{"batb":[[0,3.15,2],[1,3.1,4],[2,3.05,10.65]],"ltp":3.1,"tv":42663.03,"id":31379}]}]}
{"op":"mcm","clk":"11762561133","pt":1722531042030,"mc":[{"id":"1.231283997","rc":[{"batb":[[0,3.1,4],[1,3.05,10.65],[2,3,21.58]],"ltp":3.1,"tv":42663.03,"id":31379}]}]}
{"op":"mcm","clk":"11762561332","pt":1722531044114,"mc":[{"id":"1.231283997","rc":[{"batb":[[0,3.15,2],[1,3.1,4],[2,3.05,10.65]],"ltp":3.1,"tv":42663.03,"id":31379}]}]}
{"op":"mcm","clk":"11762561520","pt":1722531046450,"mc":[{"id":"1.231283997","rc":[{"batb":[[0,3.1,4],[1,3.05,10.65],[2,3,21.58]],"ltp":3.1,"tv":42663.03,"id":31379}]}]}
{"op":"mcm","clk":"11762561701","pt":1722531048719,"mc":[{"id":"1.231283997","rc":[{"batb":[[0,3.15,2],[1,3.1,4],[2,3.05,10.65]],"ltp":3.1,"tv":42663.03,"id":31379}]}]}
{"op":"mcm","clk":"11762561922","pt":1722531050952,"mc":[{"id":"1.231283997","rc":[{"batb":[[0,3.1,4],[1,3.05,10.65],[2,3,21.58]],"ltp":3.1,"tv":42663.03,"id":31379}]}]}
{"op":"mcm","clk":"11762562112","pt":1722531053039,"mc":[{"id":"1.231283997","rc":[{"batb":[[0,3.15,2],[1,3.1,4],[2,3.05,10.65]],"ltp":3.1,"tv":42663.03,"id":31379}]}]}
{"op":"mcm","clk":"11762562334","pt":1722531055226,"mc":[{"id":"1.231283997","rc":[{"batb":[[0,3.1,4],[1,3.05,10.65],[2,3,21.58]],"ltp":3.1,"tv":42663.03,"id":31379}]}]}
{"op":"mcm","clk":"11762562549","pt":1722531057518,"mc":[{"id":"1.231283997","rc":[{"batb":[[0,3.15,2],[1,3.1,4],[2,3.05,10.65]],"ltp":3.1,"tv":42663.03,"id":31379}]}]}
{"op":"mcm","clk":"11762562773","pt":1722531059858,"mc":[{"id":"1.231283997","rc":[{"batb":[[0,3.1,4],[1,3.05,10.65],[2,3,21.58]],"ltp":3.1,"tv":42663.03,"id":31379}]}]}
{"op":"mcm","clk":"11762563027","pt":1722531062480,"mc":[{"id":"1.231283997","rc":[{"batb":[[0,3.15,2],[1,3.1,4],[2,3.05,10.65]],"ltp":3.1,"tv":42663.03,"id":31379}]}]}
{"op":"mcm","clk":"11762563223","pt":1722531064741,"mc":[{"id":"1.231283997","rc":[{"batb":[[0,3.1,4],[1,3.05,10.65],[2,3,21.58]],"ltp":3.1,"tv":42663.03,"id":31379}]}]}
{"op":"mcm","clk":"11762563641","pt":1722531069236,"mc":[{"id":"1.231283997","rc":[{"batb":[[0,3.15,2],[1,3.1,4],[2,3.05,10.65]],"ltp":3.1,"tv":42663.03,"id":31379}]}]}
{"op":"mcm","clk":"11762563816","pt":1722531071566,"mc":[{"id":"1.231283997","rc":[{"batb":[[0,3.1,4],[1,3.05,10.65],[2,3,21.58]],"ltp":3.1,"tv":42663.03,"id":31379}]}]}
{"op":"mcm","clk":"11762564067","pt":1722531074962,"mc":[{"id":"1.231283997","rc":[{"batb":[[0,3.15,2],[1,3.1,4],[2,3.05,10.65]],"ltp":3.1,"tv":42663.03,"id":31379}]}]}
{"op":"mcm","clk":"11762564272","pt":1722531077487,"mc":[{"id":"1.231283997","rc":[{"batb":[[0,3.1,4],[1,3.05,10.65],[2,3,21.58]],"ltp":3.1,"tv":42663.03,"id":31379}]}]}
{"op":"mcm","clk":"11762564556","pt":1722531080474,"mc":[{"id":"1.231283997","rc":[{"batb":[[0,3.15,2],[1,3.1,4],[2,3.05,10.65]],"ltp":3.1,"tv":42663.03,"id":31379}]}]}
{"op":"mcm","clk":"11762564791","pt":1722531082870,"mc":[{"id":"1.231283997","rc":[{"batb":[[0,3.1,4],[1,3.05,10.65],[2,3,21.58]],"ltp":3.1,"tv":42663.03,"id":31379}]}]}
{"op":"mcm","clk":"11762565074","pt":1722531085997,"mc":[{"id":"1.231283997","rc":[{"batb":[[0,3.15,2],[1,3.1,4],[2,3.05,10.65]],"ltp":3.1,"tv":42663.03,"id":31379}]}]}
{"op":"mcm","clk":"11762565288","pt":1722531088279,"mc":[{"id":"1.231283997","rc":[{"batb":[[0,3.1,4],[1,3.05,10.65],[2,3,21.58]],"ltp":3.1,"tv":42663.03,"id":31379}]}]}
{"op":"mcm","clk":"11762565496","pt":1722531090509,"mc":[{"id":"1.231283997","rc":[{"batb":[[0,3.15,2],[1,3.1,4],[2,3.05,10.65]],"ltp":3.1,"tv":42663.03,"id":31379}]}]}
{"op":"mcm","clk":"11762565674","pt":1722531092796,"mc":[{"id":"1.231283997","rc":[{"batb":[[0,3.1,4],[1,3.05,10.65],[2,3,21.58]],"ltp":3.1,"tv":42663.03,"id":31379}]}]}
{"op":"mcm","clk":"11762565987","pt":1722531096909,"mc":[{"id":"1.231283997","rc":[{"batb":[[0,3.15,2],[1,3.1,4],[2,3.05,10.65]],"ltp":3.1,"tv":42663.03,"id":31379}]}]}
{"op":"mcm","clk":"11762566198","pt":1722531099308,"mc":[{"id":"1.231283997","rc":[{"batb":[[0,3.1,4],[1,3.05,10.65],[2,3,21.58]],"ltp":3.1,"tv":42663.03,"id":31379}]}]}
{"op":"mcm","clk":"11762566568","pt":1722531104023,"mc":[{"id":"1.231283997","rc":[{"batb":[[0,3.15,2],[1,3.1,4],[2,3.05,10.65]],"ltp":3.1,"tv":42663.03,"id":31379}]}]}
{"op":"mcm","clk":"11762566755","pt":1722531106310,"mc":[{"id":"1.231283997","rc":[{"batb":[[0,3.1,4],[1,3.05,10.65],[2,3,21.58]],"ltp":3.1,"tv":42663.03,"id":31379}]}]}
{"op":"mcm","clk":"11762567075","pt":1722531109926,"mc":[{"id":"1.231283997","rc":[{"batb":[[0,3.15,2],[1,3.1,4],[2,3.05,10.65]],"ltp":3.1,"tv":42663.03,"id":31379}]}]}
{"op":"mcm","clk":"11762567295","pt":1722531112320,"mc":[{"id":"1.231283997","rc":[{"batb":[[0,3.1,4],[1,3.05,10.65],[2,3,21.58]],"ltp":3.1,"tv":42663.03,"id":31379}]}]}
{"op":"mcm","clk":"11762567671","pt":1722531116315,"mc":[{"id":"1.231283997","rc":[{"batb":[[0,3.15,2],[1,3.1,4],[2,3.05,10.65]],"ltp":3.1,"tv":42663.03,"id":31379}]}]}
{"op":"mcm","clk":"11762567893","pt":1722531118636,"mc":[{"id":"1.231283997","rc":[{"batb":[[0,3.1,4],[1,3.05,10.65],[2,3,21.58]],"ltp":3.1,"tv":42663.03,"id":31379}]}]}
{"op":"mcm","clk":"11762568262","pt":1722531122645,"mc":[{"id":"1.231283997","rc":[{"batb":[[0,3.15,2],[1,3.1,4],[2,3.05,10.65]],"ltp":3.1,"tv":42663.03,"id":31379}]}]}
{"op":"mcm","clk":"11762568472","pt":1722531124925,"mc":[{"id":"1.231283997","rc":[{"batb":[[0,3.1,4],[1,3.05,10.65],[2,3,21.58]],"ltp":3.1,"tv":42663.03,"id":31379}]}]}
{"op":"mcm","clk":"11762568715","pt":1722531127550,"mc":[{"id":"1.231283997","rc":[{"batb":[[0,3.15,2],[1,3.1,4],[2,3.05,10.65]],"ltp":3.1,"tv":42663.03,"id":31379}]}]}
{"op":"mcm","clk":"11762568943","pt":1722531129947,"mc":[{"id":"1.231283997","rc":[{"batb":[[0,3.1,4],[1,3.05,10.65],[2,3,21.58]],"ltp":3.1,"tv":42663.03,"id":31379}]}]}
{"op":"mcm","clk":"11762569317","pt":1722531134540,"mc":[{"id":"1.231283997","rc":[{"batb":[[0,3.15,2],[1,3.1,4],[2,3.05,10.65]],"ltp":3.1,"tv":42663.03,"id":31379}]}]}
{"op":"mcm","clk":"11762569518","pt":1722531136857,"mc":[{"id":"1.231283997","rc":[{"batb":[[0,3.1,4],[1,3.05,10.65],[2,3,21.58]],"ltp":3.1,"tv":42663.03,"id":31379}]}]}
{"op":"mcm","clk":"11762569756","pt":1722531139970,"mc":[{"id":"1.231283997","rc":[{"batb":[[0,3.15,2],[1,3.1,4],[2,3.05,10.65]],"ltp":3.1,"tv":42663.03,"id":31379}]}]}
{"op":"mcm","clk":"11762569952","pt":1722531142155,"mc":[{"id":"1.231283997","rc":[{"batb":[[0,3.1,4],[1,3.05,10.65],[2,3,21.58]],"ltp":3.1,"tv":42663.03,"id":31379}]}]}
{"op":"mcm","clk":"11762570173","pt":1722531144478,"mc":[{"id":"1.231283997","rc":[{"batb":[[0,3.15,2],[1,3.1,4],[2,3.05,10.65]],"ltp":3.1,"tv":42663.03,"id":31379}]}]}
{"op":"mcm","clk":"11762570365","pt":1722531146883,"mc":[{"id":"1.231283997","rc":[{"batb":[[0,3.1,4],[1,3.05,10.65],[2,3,21.58]],"ltp":3.1,"tv":42663.03,"id":31379}]}]}
{"op":"mcm","clk":"11762570659","pt":1722531149989,"mc":[{"id":"1.231283997","rc":[{"batb":[[0,3.15,2],[1,3.1,4],[2,3.05,10.65]],"ltp":3.1,"tv":42663.03,"id":31379}]}]}
{"op":"mcm","clk":"11762570860","pt":1722531152270,"mc":[{"id":"1.231283997","rc":[{"batb":[[0,3.1,4],[1,3.05,10.65],[2,3,21.58]],"ltp":3.1,"tv":42663.03,"id":31379}]}]}
{"op":"mcm","clk":"11762571319","pt":1722531156388,"mc":[{"id":"1.231283997","rc":[{"batb":[[0,3.15,2],[1,3.1,4],[2,3.05,10.65]],"ltp":3.1,"tv":42663.03,"id":31379}]}]}
{"op":"mcm","clk":"11762571535","pt":1722531158673,"mc":[{"id":"1.231283997","rc":[{"batb":[[0,3.1,4],[1,3.05,10.65],[2,3,21.58]],"ltp":3.1,"tv":42663.03,"id":31379}]}]}
{"op":"mcm","clk":"11762571799","pt":1722531161680,"mc":[{"id":"1.231283997","rc":[{"batb":[[0,3.15,2],[1,3.1,4],[2,3.05,10.65]],"ltp":3.1,"tv":42663.03,"id":31379}]}]}
{"op":"mcm","clk":"11762571999","pt":1722531164075,"mc":[{"id":"1.231283997","rc":[{"batb":[[0,3.1,4],[1,3.05,10.65],[2,3,21.58]],"ltp":3.1,"tv":42663.03,"id":31379}]}]}
{"op":"mcm","clk":"11762572189","pt":1722531166312,"mc":[{"id":"1.231283997","rc":[{"batb":[[0,3.15,2],[1,3.1,4],[2,3.05,10.65]],"ltp":3.1,"tv":42663.03,"id":31379}]}]}
{"op":"mcm","clk":"11762572397","pt":1722531168608,"mc":[{"id":"1.231283997","rc":[{"batb":[[0,3.1,4],[1,3.05,10.65],[2,3,21.58]],"ltp":3.1,"tv":42663.03,"id":31379}]}]}
{"op":"mcm","clk":"11762572626","pt":1722531171097,"mc":[{"id":"1.231283997","rc":[{"batb":[[0,3.15,2],[1,3.1,4],[2,3.05,10.65]],"ltp":3.1,"tv":42663.03,"id":31379}]}]}
{"op":"mcm","clk":"11762572801","pt":1722531173391,"mc":[{"id":"1.231283997","rc":[{"batb":[[0,3.1,4],[1,3.05,10.65],[2,3,21.58]],"ltp":3.1,"tv":42663.03,"id":31379}]}]}
{"op":"mcm","clk":"11762572983","pt":1722531175517,"mc":[{"id":"1.231283997","rc":[{"batb":[[0,3.15,2],[1,3.1,4],[2,3.05,10.65]],"ltp":3.1,"tv":42663.03,"id":31379}]}]}
{"op":"mcm","clk":"11762573167","pt":1722531178024,"mc":[{"id":"1.231283997","rc":[{"batb":[[0,3.1,4],[1,3.05,10.65],[2,3,21.58]],"ltp":3.1,"tv":42663.03,"id":31379}]}]}
{"op":"mcm","clk":"11762573438","pt":1722531181013,"mc":[{"id":"1.231283997","rc":[{"batb":[[0,3.15,2],[1,3.1,4],[2,3.05,10.65]],"ltp":3.1,"tv":42663.03,"id":31379}]}]}
{"op":"mcm","clk":"11762573665","pt":1722531183521,"mc":[{"id":"1.231283997","rc":[{"batb":[[0,3.1,4],[1,3.05,10.65],[2,3,21.58]],"ltp":3.1,"tv":42663.03,"id":31379}]}]}
{"op":"mcm","clk":"11762574019","pt":1722531187440,"mc":[{"id":"1.231283997","rc":[{"batb":[[0,3.15,2],[1,3.1,4],[2,3.05,10.65]],"ltp":3.1,"tv":42663.03,"id":31379}]}]}
{"op":"mcm","clk":"11762574242","pt":1722531189808,"mc":[{"id":"1.231283997","rc":[{"batb":[[0,3.1,4],[1,3.05,10.65],[2,3,21.58]],"ltp":3.1,"tv":42663.03,"id":31379}]}]}
{"op":"mcm","clk":"11762574463","pt":1722531192070,"mc":[{"id":"1.231283997","rc":[{"batb":[[0,3.15,2],[1,3.1,4],[2,3.05,10.65]],"ltp":3.1,"tv":42663.03,"id":31379}]}]}
{"op":"mcm","clk":"11762574678","pt":1722531194242,"mc":[{"id":"1.231283997","rc":[{"batb":[[0,3.1,4],[1,3.05,10.65],[2,3,21.58]],"ltp":3.1,"tv":42663.03,"id":31379}]}]}
{"op":"mcm","clk":"11762574901","pt":1722531196468,"mc":[{"id":"1.231283997","rc":[{"batb":[[0,3.15,2],[1,3.1,4],[2,3.05,10.65]],"ltp":3.1,"tv":42663.03,"id":31379}]}]}
{"op":"mcm","clk":"11762575126","pt":1722531198739,"mc":[{"id":"1.231283997","rc":[{"batb":[[0,3.1,4],[1,3.05,10.65],[2,3,21.58]],"ltp":3.1,"tv":42663.03,"id":31379}]}]}
{"op":"mcm","clk":"11762575351","pt":1722531201140,"mc":[{"id":"1.231283997","rc":[{"batb":[[0,3.15,2],[1,3.1,4],[2,3.05,10.65]],"ltp":3.1,"tv":42663.03,"id":31379}]}]}
{"op":"mcm","clk":"11762575544","pt":1722531203443,"mc":[{"id":"1.231283997","rc":[{"batb":[[0,3.1,4],[1,3.05,10.65],[2,3,21.58]],"ltp":3.1,"tv":42663.03,"id":31379}]}]}
{"op":"mcm","clk":"11762575754","pt":1722531205629,"mc":[{"id":"1.231283997","rc":[{"batb":[[0,3.15,2],[1,3.1,4],[2,3.05,10.65]],"ltp":3.1,"tv":42663.03,"id":31379}]}]}
{"op":"mcm","clk":"11762576005","pt":1722531207860,"mc":[{"id":"1.231283997","rc":[{"batb":[[0,3.1,4],[1,3.05,10.65],[2,3,21.58]],"ltp":3.1,"tv":42663.03,"id":31379}]}]}
{"op":"mcm","clk":"11762576268","pt":1722531210942,"mc":[{"id":"1.231283997","rc":[{"batb":[[0,3.15,2],[1,3.1,4],[2,3.05,10.65]],"ltp":3.1,"tv":42663.03,"id":31379}]}]}
{"op":"mcm","clk":"11762576453","pt":1722531213264,"mc":[{"id":"1.231283997","rc":[{"batb":[[0,3.1,4],[1,3.05,10.65],[2,3,21.58]],"ltp":3.1,"tv":42663.03,"id":31379}]}]}
{"op":"mcm","clk":"11762576648","pt":1722531215538,"mc":[{"id":"1.231283997","rc":[{"batb":[[0,3.15,2],[1,3.1,4],[2,3.05,10.65]],"ltp":3.1,"tv":42663.03,"id":31379}]}]}
{"op":"mcm","clk":"11762576856","pt":1722531217864,"mc":[{"id":"1.231283997","rc":[{"batb":[[0,3.1,4],[1,3.05,10.65],[2,3,21.58]],"ltp":3.1,"tv":42663.03,"id":31379}]}]}
{"op":"mcm","clk":"11762577073","pt":1722531219958,"mc":[{"id":"1.231283997","rc":[{"batb":[[0,3.15,2],[1,3.1,4],[2,3.05,10.65]],"ltp":3.1,"tv":42663.03,"id":31379}]}]}
{"op":"mcm","clk":"11762577329","pt":1722531222358,"mc":[{"id":"1.231283997","rc":[{"batb":[[0,3.1,4],[1,3.05,10.65],[2,3,21.58]],"ltp":3.1,"tv":42663.03,"id":31379}]}]}
{"op":"mcm","clk":"11762577548","pt":1722531225062,"mc":[{"id":"1.231283997","rc":[{"batb":[[0,3.15,2],[1,3.1,4],[2,3.05,10.65]],"ltp":3.1,"tv":42663.03,"id":31379}]}]}
{"op":"mcm","clk":"11762577718","pt":1722531227294,"mc":[{"id":"1.231283997","rc":[{"batb":[[0,3.1,4],[1,3.05,10.65],[2,3,21.58]],"ltp":3.1,"tv":42663.03,"id":31379}]}]}
{"op":"mcm","clk":"11762577977","pt":1722531229865,"mc":[{"id":"1.231283997","rc":[{"batb":[[0,3.15,2],[1,3.1,4],[2,3.05,10.65]],"ltp":3.1,"tv":42663.03,"id":31379}]}]}
{"op":"mcm","clk":"11762578172","pt":1722531232276,"mc":[{"id":"1.231283997","rc":[{"batb":[[0,3.1,4],[1,3.05,10.65],[2,3,21.58]],"ltp":3.1,"tv":42663.03,"id":31379}]}]}
{"op":"mcm","clk":"11762578456","pt":1722531235243,"mc":[{"id":"1.231283997","rc":[{"batb":[[0,3.15,2],[1,3.1,4],[2,3.05,10.65]],"ltp":3.1,"tv":42663.03,"id":31379}]}]}
{"op":"mcm","clk":"11762578653","pt":1722531237578,"mc":[{"id":"1.231283997","rc":[{"batb":[[0,3.1,4],[1,3.05,10.65],[2,3,21.58]],"ltp":3.1,"tv":42663.03,"id":31379}]}]}
{"op":"mcm","clk":"11762578851","pt":1722531239765,"mc":[{"id":"1.231283997","rc":[{"batb":[[0,3.15,2],[1,3.1,4],[2,3.05,10.65]],"ltp":3.1,"tv":42663.03,"id":31379}]}]}
{"op":"mcm","clk":"11762579039","pt":1722531242049,"mc":[{"id":"1.231283997","rc":[{"batb":[[0,3.1,4],[1,3.05,10.65],[2,3,21.58]],"ltp":3.1,"tv":42663.03,"id":31379}]}]}
{"op":"mcm","clk":"11762579282","pt":1722531244470,"mc":[{"id":"1.231283997","rc":[{"batb":[[0,3.15,2],[1,3.1,4],[2,3.05,10.65]],"ltp":3.1,"tv":42663.03,"id":31379}]}]}
{"op":"mcm","clk":"11762579506","pt":1722531246855,"mc":[{"id":"1.231283997","rc":[{"batb":[[0,3.1,4],[1,3.05,10.65],[2,3,21.58]],"ltp":3.1,"tv":42663.03,"id":31379}]}]}
{"op":"mcm","clk":"11762579688","pt":1722531248984,"mc":[{"id":"1.231283997","rc":[{"batb":[[0,3.15,2],[1,3.1,4],[2,3.05,10.65]],"ltp":3.1,"tv":42663.03,"id":31379}]}]}
{"op":"mcm","clk":"11762579889","pt":1722531251288,"mc":[{"id":"1.231283997","rc":[{"batb":[[0,3.1,4],[1,3.05,10.65],[2,3,21.58]],"ltp":3.1,"tv":42663.03,"id":31379}]}]}
{"op":"mcm","clk":"11762580077","pt":1722531253685,"mc":[{"id":"1.231283997","rc":[{"batb":[[0,3.15,2],[1,3.1,4],[2,3.05,10.65]],"ltp":3.1,"tv":42663.03,"id":31379}]}]}
{"op":"mcm","clk":"11762580267","pt":1722531255982,"mc":[{"id":"1.231283997","rc":[{"batb":[[0,3.1,4],[1,3.05,10.65],[2,3,21.58]],"ltp":3.1,"tv":42663.03,"id":31379}]}]}
{"op":"mcm","clk":"11762580431","pt":1722531258158,"mc":[{"id":"1.231283997","rc":[{"batb":[[0,3.15,2],[1,3.1,4],[2,3.05,10.65]],"ltp":3.1,"tv":42663.03,"id":31379}]}]}
{"op":"mcm","clk":"11762580589","pt":1722531260498,"mc":[{"id":"1.231283997","rc":[{"batb":[[0,3.1,4],[1,3.05,10.65],[2,3,21.58]],"ltp":3.1,"tv":42663.03,"id":31379}]}]}
{"op":"mcm","clk":"11762580769","pt":1722531262800,"mc":[{"id":"1.231283997","rc":[{"batb":[[0,3.15,2],[1,3.1,4],[2,3.05,10.65]],"ltp":3.1,"tv":42663.03,"id":31379}]}]}
{"op":"mcm","clk":"11762580998","pt":1722531265114,"mc":[{"id":"1.231283997","rc":[{"batb":[[0,3.1,4],[1,3.05,10.65],[2,3,21.58]],"ltp":3.1,"tv":42663.03,"id":31379}]}]}
{"op":"mcm","clk":"11762581216","pt":1722531267280,"mc":[{"id":"1.231283997","rc":[{"batb":[[0,3.15,2],[1,3.1,4],[2,3.05,10.65]],"ltp":3.1,"tv":42663.03,"id":31379}]}]}
{"op":"mcm","clk":"11762581389","pt":1722531269565,"mc":[{"id":"1.231283997","rc":[{"batb":[[0,3.1,4],[1,3.05,10.65],[2,3,21.58]],"ltp":3.1,"tv":42663.03,"id":31379}]}]}
{"op":"mcm","clk":"11762581593","pt":1722531272070,"mc":[{"id":"1.231283997","rc":[{"batb":[[0,3.15,2],[1,3.1,4],[2,3.05,10.65]],"ltp":3.1,"tv":42663.03,"id":31379}]}]}
{"op":"mcm","clk":"11762581782","pt":1722531274409,"mc":[{"id":"1.231283997","rc":[{"batb":[[0,3.1,4],[1,3.05,10.65],[2,3,21.58]],"ltp":3.1,"tv":42663.03,"id":31379}]}]}
{"op":"mcm","clk":"11762581978","pt":1722531276700,"mc":[{"id":"1.231283997","rc":[{"batb":[[0,3.15,2],[1,3.1,4],[2,3.05,10.65]],"ltp":3.1,"tv":42663.03,"id":31379}]}]}
{"op":"mcm","clk":"11762582161","pt":1722531278879,"mc":[{"id":"1.231283997","rc":[{"batb":[[0,3.1,4],[1,3.05,10.65],[2,3,21.58]],"ltp":3.1,"tv":42663.03,"id":31379}]}]}
{"op":"mcm","clk":"11762582420","pt":1722531281985,"mc":[{"id":"1.231283997","rc":[{"batb":[[0,3.15,2],[1,3.1,4],[2,3.05,10.65]],"ltp":3.1,"tv":42663.03,"id":31379}]}]}
{"op":"mcm","clk":"11762582622","pt":1722531284316,"mc":[{"id":"1.231283997","rc":[{"batb":[[0,3.1,4],[1,3.05,10.65],[2,3,21.58]],"ltp":3.1,"tv":42663.03,"id":31379}]}]}
{"op":"mcm","clk":"11762582812","pt":1722531286417,"mc":[{"id":"1.231283997","rc":[{"batb":[[0,3.15,2],[1,3.1,4],[2,3.05,10.65]],"ltp":3.1,"tv":42663.03,"id":31379}]}]}
{"op":"mcm","clk":"11762583017","pt":1722531288811,"mc":[{"id":"1.231283997","rc":[{"batb":[[0,3.1,4],[1,3.05,10.65],[2,3,21.58]],"ltp":3.1,"tv":42663.03,"id":31379}]}]}
{"op":"mcm","clk":"11762583209","pt":1722531291019,"mc":[{"id":"1.231283997","rc":[{"batb":[[0,3.15,2],[1,3.1,4],[2,3.05,10.65]],"ltp":3.1,"tv":42663.03,"id":31379}]}]}
{"op":"mcm","clk":"11762583416","pt":1722531293321,"mc":[{"id":"1.231283997","rc":[{"batb":[[0,3.1,4],[1,3.05,10.65],[2,3,21.58]],"ltp":3.1,"tv":42663.03,"id":31379}]}]}
{"op":"mcm","clk":"11762583698","pt":1722531296502,"mc":[{"id":"1.231283997","rc":[{"batb":[[0,3.15,2],[1,3.1,4],[2,3.05,10.65]],"ltp":3.1,"tv":42663.03,"id":31379}]}]}
{"op":"mcm","clk":"11762583894","pt":1722531298707,"mc":[{"id":"1.231283997","rc":[{"batb":[[0,3.1,4],[1,3.05,10.65],[2,3,21.58]],"ltp":3.1,"tv":42663.03,"id":31379}]}]}
{"op":"mcm","clk":"11762584102","pt":1722531301027,"mc":[{"id":"1.231283997","rc":[{"batb":[[0,3.15,2],[1,3.1,4],[2,3.05,10.65]],"ltp":3.1,"tv":42663.03,"id":31379}]}]}
{"op":"mcm","clk":"11762584319","pt":1722531303223,"mc":[{"id":"1.231283997","rc":[{"batb":[[0,3.1,4],[1,3.05,10.65],[2,3,21.58]],"ltp":3.1,"tv":42663.03,"id":31379}]}]}
{"op":"mcm","clk":"11762584611","pt":1722531305742,"mc":[{"id":"1.231283997","rc":[{"batb":[[0,3.15,2],[1,3.1,4],[2,3.05,10.65]],"ltp":3.1,"tv":42663.03,"id":31379}]}]}
{"op":"mcm","clk":"11762584847","pt":1722531308150,"mc":[{"id":"1.231283997","rc":[{"batb":[[0,3.1,4],[1,3.05,10.65],[2,3,21.58]],"ltp":3.1,"tv":42663.03,"id":31379}]}]}
{"op":"mcm","clk":"11762585172","pt":1722531311243,"mc":[{"id":"1.231283997","rc":[{"batb":[[0,3.15,2],[1,3.1,4],[2,3.05,10.65]],"ltp":3.1,"tv":42663.03,"id":31379}]}]}
{"op":"mcm","clk":"11762585380","pt":1722531313636,"mc":[{"id":"1.231283997","rc":[{"batb":[[0,3.1,4],[1,3.05,10.65],[2,3,21.58]],"ltp":3.1,"tv":42663.03,"id":31379}]}]}
{"op":"mcm","clk":"11762585675","pt":1722531316951,"mc":[{"id":"1.231283997","rc":[{"batb":[[0,3.15,2],[1,3.1,4],[2,3.05,10.65]],"ltp":3.1,"tv":42663.03,"id":31379}]}]}
{"op":"mcm","clk":"11762585856","pt":1722531319356,"mc":[{"id":"1.231283997","rc":[{"batb":[[0,3.1,4],[1,3.05,10.65],[2,3,21.58]],"ltp":3.1,"tv":42663.03,"id":31379}]}]}
{"op":"mcm","clk":"11762586164","pt":1722531323047,"mc":[{"id":"1.231283997","rc":[{"batb":[[0,3.15,2],[1,3.1,4],[2,3.05,10.65]],"ltp":3.1,"tv":42663.03,"id":31379}]}]}
{"op":"mcm","clk":"11762586369","pt":1722531325261,"mc":[{"id":"1.231283997","rc":[{"batb":[[0,3.1,4],[1,3.05,10.65],[2,3,21.58]],"ltp":3.1,"tv":42663.03,"id":31379}]}]}
{"op":"mcm","clk":"11762586658","pt":1722531328660,"mc":[{"id":"1.231283997","rc":[{"batb":[[0,3.15,2],[1,3.1,4],[2,3.05,10.65]],"ltp":3.1,"tv":42663.03,"id":31379}]}]}
{"op":"mcm","clk":"11762586898","pt":1722531331065,"mc":[{"id":"1.231283997","rc":[{"batb":[[0,3.1,4],[1,3.05,10.65],[2,3,21.58]],"ltp":3.1,"tv":42663.03,"id":31379}]}]}
{"op":"mcm","clk":"11762587313","pt":1722531334957,"mc":[{"id":"1.231283997","rc":[{"batb":[[0,3.15,2],[1,3.1,4],[2,3.05,10.65]],"ltp":3.1,"tv":42663.03,"id":31379}]}]}
{"op":"mcm","clk":"11762587553","pt":1722531337174,"mc":[{"id":"1.231283997","rc":[{"batb":[[0,3.1,4],[1,3.05,10.65],[2,3,21.58]],"ltp":3.1,"tv":42663.03,"id":31379}]}]}
{"op":"mcm","clk":"11762587815","pt":1722531339962,"mc":[{"id":"1.231283997","rc":[{"batb":[[0,3.15,2],[1,3.1,4],[2,3.05,10.65]],"ltp":3.1,"tv":42663.03,"id":31379}]}]}
{"op":"mcm","clk":"11762587993","pt":1722531342241,"mc":[{"id":"1.231283997","rc":[{"batb":[[0,3.1,4],[1,3.05,10.65],[2,3,21.58]],"ltp":3.1,"tv":42663.03,"id":31379}]}]}
{"op":"mcm","clk":"11762588286","pt":1722531345758,"mc":[{"id":"1.231283997","rc":[{"batb":[[0,3.15,2],[1,3.1,4],[2,3.05,10.65]],"ltp":3.1,"tv":42663.03,"id":31379}]}]}
{"op":"mcm","clk":"11762588459","pt":1722531348085,"mc":[{"id":"1.231283997","rc":[{"batb":[[0,3.1,4],[1,3.05,10.65],[2,3,21.58]],"ltp":3.1,"tv":42663.03,"id":31379}]}]}
{"op":"mcm","clk":"11762588626","pt":1722531350178,"mc":[{"id":"1.231283997","rc":[{"batb":[[0,3.15,2],[1,3.1,4],[2,3.05,10.65]],"ltp":3.1,"tv":42663.03,"id":31379}]}]}
{"op":"mcm","clk":"11762588813","pt":1722531352642,"mc":[{"id":"1.231283997","rc":[{"batb":[[0,3.1,4],[1,3.05,10.65],[2,3,21.58]],"ltp":3.1,"tv":42663.03,"id":31379}]}]}
{"op":"mcm","clk":"11762589006","pt":1722531354966,"mc":[{"id":"1.231283997","rc":[{"batb":[[0,3.15,2],[1,3.1,4],[2,3.05,10.65]],"ltp":3.1,"tv":42663.03,"id":31379}]}]}
{"op":"mcm","clk":"11762589167","pt":1722531357177,"mc":[{"id":"1.231283997","rc":[{"batb":[[0,3.1,4],[1,3.05,10.65],[2,3,21.58]],"ltp":3.1,"tv":42663.03,"id":31379}]}]}
{"op":"mcm","clk":"11762589326","pt":1722531359298,"mc":[{"id":"1.231283997","rc":[{"batb":[[0,3.15,2],[1,3.1,4],[2,3.05,10.65]],"ltp":3.1,"tv":42663.03,"id":31379}]}]}
{"op":"mcm","clk":"11762589529","pt":1722531361783,"mc":[{"id":"1.231283997","rc":[{"batb":[[0,3.1,4],[1,3.05,10.65],[2,3,21.58]],"ltp":3.1,"tv":42663.03,"id":31379}]}]}
{"op":"mcm","clk":"11762589712","pt":1722531364094,"mc":[{"id":"1.231283997","rc":[{"batb":[[0,3.15,2],[1,3.1,4],[2,3.05,10.65]],"ltp":3.1,"tv":42663.03,"id":31379}]}]}
{"op":"mcm","clk":"11762589944","pt":1722531366385,"mc":[{"id":"1.231283997","rc":[{"batb":[[0,3.1,4],[1,3.05,10.65],[2,3,21.58]],"ltp":3.1,"tv":42663.03,"id":31379}]}]}
{"op":"mcm","clk":"11762590238","pt":1722531369102,"mc":[{"id":"1.231283997","rc":[{"batb":[[0,3.15,2],[1,3.1,4],[2,3.05,10.65]],"ltp":3.1,"tv":42663.03,"id":31379}]}]}
{"op":"mcm","clk":"11762590490","pt":1722531371298,"mc":[{"id":"1.231283997","rc":[{"batb":[[0,3.1,4],[1,3.05,10.65],[2,3,21.58]],"ltp":3.1,"tv":42663.03,"id":31379}]}]}
{"op":"mcm","clk":"11762590791","pt":1722531374394,"mc":[{"id":"1.231283997","rc":[{"batb":[[0,3.15,2],[1,3.1,4],[2,3.05,10.65]],"ltp":3.1,"tv":42663.03,"id":31379}]}]}
{"op":"mcm","clk":"11762591022","pt":1722531376783,"mc":[{"id":"1.231283997","rc":[{"batb":[[0,3.1,4],[1,3.05,10.65],[2,3,21.58]],"ltp":3.1,"tv":42663.03,"id":31379}]}]}
{"op":"mcm","clk":"11762591243","pt":1722531379014,"mc":[{"id":"1.231283997","rc":[{"batb":[[0,3.15,2],[1,3.1,4],[2,3.05,10.65]],"ltp":3.1,"tv":42663.03,"id":31379}]}]}
{"op":"mcm","clk":"11762591462","pt":1722531381307,"mc":[{"id":"1.231283997","rc":[{"batb":[[0,3.1,4],[1,3.05,10.65],[2,3,21.58]],"ltp":3.1,"tv":42663.03,"id":31379}]}]}
{"op":"mcm","clk":"11762591813","pt":1722531384594,"mc":[{"id":"1.231283997","rc":[{"batb":[[0,3.15,2],[1,3.1,4],[2,3.05,10.65]],"ltp":3.1,"tv":42663.03,"id":31379}]}]}
{"op":"mcm","clk":"11762592052","pt":1722531386999,"mc":[{"id":"1.231283997","rc":[{"batb":[[0,3.1,4],[1,3.05,10.65],[2,3,21.58]],"ltp":3.1,"tv":42663.03,"id":31379}]}]}
{"op":"mcm","clk":"11762592363","pt":1722531390200,"mc":[{"id":"1.231283997","rc":[{"batb":[[0,3.15,2],[1,3.1,4],[2,3.05,10.65]],"ltp":3.1,"tv":42663.03,"id":31379}]}]}
{"op":"mcm","clk":"11762592601","pt":1722531392803,"mc":[{"id":"1.231283997","rc":[{"batb":[[0,3.1,4],[1,3.05,10.65],[2,3,21.58]],"ltp":3.1,"tv":42663.03,"id":31379}]}]}
{"op":"mcm","clk":"11762592908","pt":1722531396430,"mc":[{"id":"1.231283997","rc":[{"batb":[[0,3.15,2],[1,3.1,4],[2,3.05,10.65]],"ltp":3.1,"tv":42663.03,"id":31379}]}]}
{"op":"mcm","clk":"11762593156","pt":1722531398824,"mc":[{"id":"1.231283997","rc":[{"batb":[[0,3.1,4],[1,3.05,10.65],[2,3,21.58]],"ltp":3.1,"tv":42663.03,"id":31379}]}]}
{"op":"mcm","clk":"11762593449","pt":1722531402109,"mc":[{"id":"1.231283997","rc":[{"batb":[[0,3.15,2],[1,3.1,4],[2,3.05,10.65]],"ltp":3.1,"tv":42663.03,"id":31379}]}]}
{"op":"mcm","clk":"11762593664","pt":1722531404398,"mc":[{"id":"1.231283997","rc":[{"batb":[[0,3.1,4],[1,3.05,10.65],[2,3,21.58]],"ltp":3.1,"tv":42663.03,"id":31379}]}]}
{"op":"mcm","clk":"11762593994","pt":1722531407840,"mc":[{"id":"1.231283997","rc":[{"batb":[[0,3.15,2],[1,3.1,4],[2,3.05,10.65]],"ltp":3.1,"tv":42663.03,"id":31379}]}]}
{"op":"mcm","clk":"11762594239","pt":1722531410193,"mc":[{"id":"1.231283997","rc":[{"batb":[[0,3.1,4],[1,3.05,10.65],[2,3,21.58]],"ltp":3.1,"tv":42663.03,"id":31379}]}]}
{"op":"mcm","clk":"11762594609","pt":1722531414722,"mc":[{"id":"1.231283997","rc":[{"batb":[[0,3.15,2],[1,3.1,4],[2,3.05,10.65]],"ltp":3.1,"tv":42663.03,"id":31379}]}]}
{"op":"mcm","clk":"11762594831","pt":1722531416914,"mc":[{"id":"1.231283997","rc":[{"batb":[[0,3.1,4],[1,3.05,10.65],[2,3,21.58]],"ltp":3.1,"tv":42663.03,"id":31379}]}]}
{"op":"mcm","clk":"11762595065","pt":1722531419418,"mc":[{"id":"1.231283997","rc":[{"batb":[[0,3.15,2],[1,3.1,4],[2,3.05,10.65]],"ltp":3.1,"tv":42663.03,"id":31379}]}]}
{"op":"mcm","clk":"11762595353","pt":1722531421728,"mc":[{"id":"1.231283997","rc":[{"batb":[[0,3.1,4],[1,3.05,10.65],[2,3,21.58]],"ltp":3.1,"tv":42663.03,"id":31379}]}]}
{"op":"mcm","clk":"11762595597","pt":1722531424249,"mc":[{"id":"1.231283997","rc":[{"batb":[[0,3.15,2],[1,3.1,4],[2,3.05,10.65]],"ltp":3.1,"tv":42663.03,"id":31379}]}]}
{"op":"mcm","clk":"11762595853","pt":1722531426643,"mc":[{"id":"1.231283997","rc":[{"batb":[[0,3.1,4],[1,3.05,10.65],[2,3,21.58]],"ltp":3.1,"tv":42663.03,"id":31379}]}]}
{"op":"mcm","clk":"11762596045","pt":1722531428948,"mc":[{"id":"1.231283997","rc":[{"batb":[[0,3.15,2],[1,3.1,4],[2,3.05,10.65]],"ltp":3.1,"tv":42663.03,"id":31379}]}]}
{"op":"mcm","clk":"11762596255","pt":1722531431143,"mc":[{"id":"1.231283997","rc":[{"batb":[[0,3.1,4],[1,3.05,10.65],[2,3,21.58]],"ltp":3.1,"tv":42663.03,"id":31379}]}]}
{"op":"mcm","clk":"11762596600","pt":1722531434636,"mc":[{"id":"1.231283997","rc":[{"batb":[[0,3.15,2],[1,3.1,4],[2,3.05,10.65]],"ltp":3.1,"tv":42663.03,"id":31379}]}]}
{"op":"mcm","clk":"11762596808","pt":1722531436866,"mc":[{"id":"1.231283997","rc":[{"batb":[[0,3.1,4],[1,3.05,10.65],[2,3,21.58]],"ltp":3.1,"tv":42663.03,"id":31379}]}]}
{"op":"mcm","clk":"11762597129","pt":1722531440078,"mc":[{"id":"1.231283997","rc":[{"batb":[[0,3.15,2],[1,3.1,4],[2,3.05,10.65]],"ltp":3.1,"tv":42663.03,"id":31379}]}]}
{"op":"mcm","clk":"11762597342","pt":1722531442485,"mc":[{"id":"1.231283997","rc":[{"batb":[[0,3.1,4],[1,3.05,10.65],[2,3,21.58]],"ltp":3.1,"tv":42663.03,"id":31379}]}]}
{"op":"mcm","clk":"11762597723","pt":1722531446081,"mc":[{"id":"1.231283997","rc":[{"batb":[[0,3.15,2],[1,3.1,4],[2,3.05,10.65]],"ltp":3.1,"tv":42663.03,"id":31379}]}]}
{"op":"mcm","clk":"11762597918","pt":1722531448383,"mc":[{"id":"1.231283997","rc":[{"batb":[[0,3.1,4],[1,3.05,10.65],[2,3,21.58]],"ltp":3.1,"tv":42663.03,"id":31379}]}]}
{"op":"mcm","clk":"11762598210","pt":1722531451668,"mc":[{"id":"1.231283997","rc":[{"batb":[[0,3.15,2],[1,3.1,4],[2,3.05,10.65]],"ltp":3.1,"tv":42663.03,"id":31379}]}]}
{"op":"mcm","clk":"11762598402","pt":1722531453873,"mc":[{"id":"1.231283997","rc":[{"batb":[[0,3.1,4],[1,3.05,10.65],[2,3,21.58]],"ltp":3.1,"tv":42663.03,"id":31379}]}]}
{"op":"mcm","clk":"11762598752","pt":1722531457901,"mc":[{"id":"1.231283997","rc":[{"batb":[[0,3.15,2],[1,3.1,4],[2,3.05,10.65]],"ltp":3.1,"tv":42663.03,"id":31379}]}]}
{"op":"mcm","clk":"11762598948","pt":1722531460304,"mc":[{"id":"1.231283997","rc":[{"batb":[[0,3.1,4],[1,3.05,10.65],[2,3,21.58]],"ltp":3.1,"tv":42663.03,"id":31379}]}]}
{"op":"mcm","clk":"11762599136","pt":1722531462492,"mc":[{"id":"1.231283997","rc":[{"batb":[[0,3.15,2],[1,3.1,4],[2,3.05,10.65]],"ltp":3.1,"tv":42663.03,"id":31379}]}]}
{"op":"mcm","clk":"11762599326","pt":1722531464692,"mc":[{"id":"1.231283997","rc":[{"batb":[[0,3.1,4],[1,3.05,10.65],[2,3,21.58]],"ltp":3.1,"tv":42663.03,"id":31379}]}]}
{"op":"mcm","clk":"11762599813","pt":1722531470077,"mc":[{"id":"1.231283997","rc":[{"batb":[[0,3.15,2],[1,3.1,4],[2,3.05,10.65]],"ltp":3.1,"tv":42663.03,"id":31379}]}]}
{"op":"mcm","clk":"11762600007","pt":1722531472488,"mc":[{"id":"1.231283997","rc":[{"batb":[[0,3.1,4],[1,3.05,10.65],[2,3,21.58]],"ltp":3.1,"tv":42663.03,"id":31379}]}]}
{"op":"mcm","clk":"11762600400","pt":1722531477184,"mc":[{"id":"1.231283997","rc":[{"batb":[[0,3.15,2],[1,3.1,4],[2,3.05,10.65]],"ltp":3.1,"tv":42663.03,"id":31379}]}]}
{"op":"mcm","clk":"11762600599","pt":1722531479693,"mc":[{"id":"1.231283997","rc":[{"batb":[[0,3.1,4],[1,3.05,10.65],[2,3,21.58]],"ltp":3.1,"tv":42663.03,"id":31379}]}]}
{"op":"mcm","clk":"11762600781","pt":1722531481895,"mc":[{"id":"1.231283997","rc":[{"batb":[[0,3.15,2],[1,3.1,4],[2,3.05,10.65]],"ltp":3.1,"tv":42663.03,"id":31379}]}]}
{"op":"mcm","clk":"11762600962","pt":1722531484097,"mc":[{"id":"1.231283997","rc":[{"batb":[[0,3.1,4],[1,3.05,10.65],[2,3,21.58]],"ltp":3.1,"tv":42663.03,"id":31379}]}]}
{"op":"mcm","clk":"11762601314","pt":1722531487808,"mc":[{"id":"1.231283997","rc":[{"batb":[[0,3.15,2],[1,3.1,4],[2,3.05,10.65]],"ltp":3.1,"tv":42663.03,"id":31379}]}]}
{"op":"mcm","clk":"11762601573","pt":1722531490227,"mc":[{"id":"1.231283997","rc":[{"batb":[[0,3.1,4],[1,3.05,10.65],[2,3,21.58]],"ltp":3.1,"tv":42663.03,"id":31379}]}]}
{"op":"mcm","clk":"11762601994","pt":1722531494827,"mc":[{"id":"1.231283997","rc":[{"batb":[[0,3.15,2],[1,3.1,4],[2,3.05,10.65]],"ltp":3.1,"tv":42663.03,"id":31379}]}]}
{"op":"mcm","clk":"11762602189","pt":1722531497026,"mc":[{"id":"1.231283997","rc":[{"batb":[[0,3.1,4],[1,3.05,10.65],[2,3,21.58]],"ltp":3.1,"tv":42663.03,"id":31379}]}]}
{"op":"mcm","clk":"11762602552","pt":1722531500952,"mc":[{"id":"1.231283997","rc":[{"batb":[[0,3.15,2],[1,3.1,4],[2,3.05,10.65]],"ltp":3.1,"tv":42663.03,"id":31379}]}]}
{"op":"mcm","clk":"11762602808","pt":1722531503281,"mc":[{"id":"1.231283997","rc":[{"batb":[[0,3.1,4],[1,3.05,10.65],[2,3,21.58]],"ltp":3.1,"tv":42663.03,"id":31379}]}]}
{"op":"mcm","clk":"11762603052","pt":1722531505506,"mc":[{"id":"1.231283997","rc":[{"batb":[[0,3.15,2],[1,3.1,4],[2,3.05,10.65]],"ltp":3.1,"tv":42663.03,"id":31379}]}]}
{"op":"mcm","clk":"11762603251","pt":1722531507815,"mc":[{"id":"1.231283997","rc":[{"batb":[[0,3.1,4],[1,3.05,10.65],[2,3,21.58]],"ltp":3.1,"tv":42663.03,"id":31379}]}]}
{"op":"mcm","clk":"11762603564","pt":1722531510977,"mc":[{"id":"1.231283997","rc":[{"batb":[[0,3.15,2],[1,3.1,4],[2,3.05,10.65]],"ltp":3.1,"tv":42663.03,"id":31379}]}]}
{"op":"mcm","clk":"11762603796","pt":1722531513226,"mc":[{"id":"1.231283997","rc":[{"batb":[[0,3.1,4],[1,3.05,10.65],[2,3,21.58]],"ltp":3.1,"tv":42663.03,"id":31379}]}]}
{"op":"mcm","clk":"11762604000","pt":1722531515633,"mc":[{"id":"1.231283997","rc":[{"batb":[[0,3.15,2],[1,3.1,4],[2,3.05,10.65]],"ltp":3.1,"tv":42663.03,"id":31379}]}]}
{"op":"mcm","clk":"11762604218","pt":1722531518131,"mc":[{"id":"1.231283997","rc":[{"batb":[[0,3.1,4],[1,3.05,10.65],[2,3,21.58]],"ltp":3.1,"tv":42663.03,"id":31379}]}]}
{"op":"mcm","clk":"11762604531","pt":1722531521231,"mc":[{"id":"1.231283997","rc":[{"batb":[[0,3.15,2],[1,3.1,4],[2,3.05,10.65]],"ltp":3.1,"tv":42663.03,"id":31379}]}]}
{"op":"mcm","clk":"11762604755","pt":1722531523534,"mc":[{"id":"1.231283997","rc":[{"batb":[[0,3.1,4],[1,3.05,10.65],[2,3,21.58]],"ltp":3.1,"tv":42663.03,"id":31379}]}]}
{"op":"mcm","clk":"11762605169","pt":1722531527650,"mc":[{"id":"1.231283997","rc":[{"batb":[[0,3.15,2],[1,3.1,4],[2,3.05,10.65]],"ltp":3.1,"tv":42663.03,"id":31379}]}]}
{"op":"mcm","clk":"11762605403","pt":1722531529827,"mc":[{"id":"1.231283997","rc":[{"batb":[[0,3.1,4],[1,3.05,10.65],[2,3,21.58]],"ltp":3.1,"tv":42663.03,"id":31379}]}]}
{"op":"mcm","clk":"11762605646","pt":1722531532053,"mc":[{"id":"1.231283997","rc":[{"batb":[[0,3.15,2],[1,3.1,4],[2,3.05,10.65]],"ltp":3.1,"tv":42663.03,"id":31379}]}]}
{"op":"mcm","clk":"11762605897","pt":1722531534355,"mc":[{"id":"1.231283997","rc":[{"batb":[[0,3.1,4],[1,3.05,10.65],[2,3,21.58]],"ltp":3.1,"tv":42663.03,"id":31379}]}]}
{"op":"mcm","clk":"11762606427","pt":1722531540278,"mc":[{"id":"1.231283997","rc":[{"batb":[[0,3.15,2],[1,3.1,4],[2,3.05,10.65]],"ltp":3.1,"tv":42663.03,"id":31379}]}]}
{"op":"mcm","clk":"11762606702","pt":1722531542543,"mc":[{"id":"1.231283997","rc":[{"batb":[[0,3.1,4],[1,3.05,10.65],[2,3,21.58]],"ltp":3.1,"tv":42663.03,"id":31379}]}]}
{"op":"mcm","clk":"11762607092","pt":1722531545854,"mc":[{"id":"1.231283997","rc":[{"batb":[[0,3.15,2],[1,3.1,4],[2,3.05,10.65]],"ltp":3.1,"tv":42663.03,"id":31379}]}]}
{"op":"mcm","clk":"11762607328","pt":1722531548255,"mc":[{"id":"1.231283997","rc":[{"batb":[[0,3.1,4],[1,3.05,10.65],[2,3,21.58]],"ltp":3.1,"tv":42663.03,"id":31379}]}]}
{"op":"mcm","clk":"11762607563","pt":1722531550461,"mc":[{"id":"1.231283997","rc":[{"batb":[[0,3.15,2],[1,3.1,4],[2,3.05,10.65]],"ltp":3.1,"tv":42663.03,"id":31379}]}]}
{"op":"mcm","clk":"11762607793","pt":1722531552782,"mc":[{"id":"1.231283997","rc":[{"batb":[[0,3.1,4],[1,3.05,10.65],[2,3,21.58]],"ltp":3.1,"tv":42663.03,"id":31379}]}]}
{"op":"mcm","clk":"11762608050","pt":1722531555469,"mc":[{"id":"1.231283997","rc":[{"batb":[[0,3.15,2],[1,3.1,4],[2,3.05,10.65]],"ltp":3.1,"tv":42663.03,"id":31379}]}]}
{"op":"mcm","clk":"11762608292","pt":1722531557767,"mc":[{"id":"1.231283997","rc":[{"batb":[[0,3.1,4],[1,3.05,10.65],[2,3,21.58]],"ltp":3.1,"tv":42663.03,"id":31379}]}]}
{"op":"mcm","clk":"11762608562","pt":1722531560270,"mc":[{"id":"1.231283997","rc":[{"batb":[[0,3.15,2],[1,3.1,4],[2,3.05,10.65]],"ltp":3.1,"tv":42663.03,"id":31379}]}]}
{"op":"mcm","clk":"11762608799","pt":1722531562569,"mc":[{"id":"1.231283997","rc":[{"batb":[[0,3.1,4],[1,3.05,10.65],[2,3,21.58]],"ltp":3.1,"tv":42663.03,"id":31379}]}]}
{"op":"mcm","clk":"11762609036","pt":1722531564972,"mc":[{"id":"1.231283997","rc":[{"batb":[[0,3.15,2],[1,3.1,4],[2,3.05,10.65]],"ltp":3.1,"tv":42663.03,"id":31379}]}]}
{"op":"mcm","clk":"11762609253","pt":1722531567359,"mc":[{"id":"1.231283997","rc":[{"batb":[[0,3.1,4],[1,3.05,10.65],[2,3,21.58]],"ltp":3.1,"tv":42663.03,"id":31379}]}]}
{"op":"mcm","clk":"11762610167","pt":1722531576879,"mc":[{"id":"1.231283997","rc":[{"batb":[[0,3.15,2],[1,3.1,4],[2,3.05,10.65]],"ltp":3.1,"tv":42663.03,"id":31379}]}]}
{"op":"mcm","clk":"11762610439","pt":1722531579186,"mc":[{"id":"1.231283997","rc":[{"batb":[[0,3.1,4],[1,3.05,10.65],[2,3,21.58]],"ltp":3.1,"tv":42663.03,"id":31379}]}]}
{"op":"mcm","clk":"11762610848","pt":1722531582992,"mc":[{"id":"1.231283997","rc":[{"batb":[[0,3.15,2],[1,3.1,4],[2,3.05,10.65]],"ltp":3.1,"tv":42663.03,"id":31379}]}]}
{"op":"mcm","clk":"11762611066","pt":1722531585191,"mc":[{"id":"1.231283997","rc":[{"batb":[[0,3.1,4],[1,3.05,10.65],[2,3,21.58]],"ltp":3.1,"tv":42663.03,"id":31379}]}]}
{"op":"mcm","clk":"11762611290","pt":1722531587698,"mc":[{"id":"1.231283997","rc":[{"batb":[[0,3.15,2],[1,3.1,4],[2,3.05,10.65]],"ltp":3.1,"tv":42663.03,"id":31379}]}]}
{"op":"mcm","clk":"11762611491","pt":1722531589885,"mc":[{"id":"1.231283997","rc":[{"batb":[[0,3.1,4],[1,3.05,10.65],[2,3,21.58]],"ltp":3.1,"tv":42663.03,"id":31379}]}]}
{"op":"mcm","clk":"11762611959","pt":1722531594802,"mc":[{"id":"1.231283997","rc":[{"batb":[[0,3.15,2],[1,3.1,4],[2,3.05,10.65]],"ltp":3.1,"tv":42663.03,"id":31379}]}]}
{"op":"mcm","clk":"11762612208","pt":1722531597105,"mc":[{"id":"1.231283997","rc":[{"batb":[[0,3.1,4],[1,3.05,10.65],[2,3,21.58]],"ltp":3.1,"tv":42663.03,"id":31379}]}]}
{"op":"mcm","clk":"11762612445","pt":1722531599406,"mc":[{"id":"1.231283997","rc":[{"batb":[[0,3.15,2],[1,3.1,4],[2,3.05,10.65]],"ltp":3.1,"tv":42663.03,"id":31379}]}]}
{"op":"mcm","clk":"11762612740","pt":1722531601523,"mc":[{"id":"1.231283997","rc":[{"batb":[[0,3.1,4],[1,3.05,10.65],[2,3,21.58]],"ltp":3.1,"tv":42663.03,"id":31379}]}]}
{"op":"mcm","clk":"11762613105","pt":1722531604250,"mc":[{"id":"1.231283997","rc":[{"trd":[[3.1,5542.62],[3.15,37104.55],[3.2,70.65]],"batb":[[0,3.15,2],[1,3.1,4],[2,3.05,10.66]],"batl":[[0,3.25,9.9],[2,3.35,1.04]],"ltp":3.1,"tv":42719.81,"id":31379},{"trd":[[1.46,4696.73],[1.47,38058.97]],"batb":[[0,1.45,9.98]],"batl":[[1,1.48,24.42],[2,1.49,15.32]],"ltp":1.47,"tv":42759.19,"id":169}],"tv":85479.01}]}
{"op":"mcm","clk":"11762613436","pt":1722531606616,"mc":[{"id":"1.231283997","rc":[{"batb":[[0,3.1,4],[1,3.05,10.66],[2,3,21.58]],"ltp":3.1,"tv":42719.81,"id":31379}]}]}
{"op":"mcm","clk":"11762613718","pt":1722531608935,"mc":[{"id":"1.231283997","rc":[{"batb":[[0,3.15,2],[1,3.1,4],[2,3.05,10.66]],"ltp":3.1,"tv":42719.81,"id":31379}]}]}
{"op":"mcm","clk":"11762614001","pt":1722531611136,"mc":[{"id":"1.231283997","rc":[{"batb":[[0,3.1,4],[1,3.05,10.66],[2,3,21.58]],"ltp":3.1,"tv":42719.81,"id":31379}]}]}
{"op":"mcm","clk":"11762614416","pt":1722531614726,"mc":[{"id":"1.231283997","rc":[{"batb":[[0,3.15,2],[1,3.1,4],[2,3.05,10.66]],"ltp":3.1,"tv":42719.81,"id":31379}]}]}
{"op":"mcm","clk":"11762614633","pt":1722531616936,"mc":[{"id":"1.231283997","rc":[{"batb":[[0,3.1,4],[1,3.05,10.66],[2,3,21.58]],"ltp":3.1,"tv":42719.81,"id":31379}]}]}
{"op":"mcm","clk":"11762614922","pt":1722531619413,"mc":[{"id":"1.231283997","rc":[{"batb":[[0,3.15,2],[1,3.1,4],[2,3.05,10.66]],"ltp":3.1,"tv":42719.81,"id":31379}]}]}
{"op":"mcm","clk":"11762615135","pt":1722531621646,"mc":[{"id":"1.231283997","rc":[{"batb":[[0,3.1,4],[1,3.05,10.66],[2,3,21.58]],"ltp":3.1,"tv":42719.81,"id":31379}]}]}
{"op":"mcm","clk":"11762615371","pt":1722531623762,"mc":[{"id":"1.231283997","rc":[{"batb":[[0,3.15,2],[1,3.1,4],[2,3.05,10.66]],"ltp":3.1,"tv":42719.81,"id":31379}]}]}
{"op":"mcm","clk":"11762615611","pt":1722531626040,"mc":[{"id":"1.231283997","rc":[{"batb":[[0,3.1,4],[1,3.05,10.66],[2,3,21.58]],"ltp":3.1,"tv":42719.81,"id":31379}]}]}
{"op":"mcm","clk":"11762615848","pt":1722531628466,"mc":[{"id":"1.231283997","rc":[{"batb":[[0,3.15,2],[1,3.1,4],[2,3.05,10.66]],"ltp":3.1,"tv":42719.81,"id":31379}]}]}
{"op":"mcm","clk":"11762616087","pt":1722531630743,"mc":[{"id":"1.231283997","rc":[{"batb":[[0,3.1,4],[1,3.05,10.66],[2,3,21.58]],"ltp":3.1,"tv":42719.81,"id":31379}]}]}
{"op":"mcm","clk":"11762616345","pt":1722531633163,"mc":[{"id":"1.231283997","rc":[{"batb":[[0,3.15,2],[1,3.1,4],[2,3.05,10.66]],"ltp":3.1,"tv":42719.81,"id":31379}]}]}
{"op":"mcm","clk":"11762616591","pt":1722531635341,"mc":[{"id":"1.231283997","rc":[{"batb":[[0,3.1,4],[1,3.05,10.66],[2,3,21.58]],"ltp":3.1,"tv":42719.81,"id":31379}]}]}
{"op":"mcm","clk":"11762616833","pt":1722531637654,"mc":[{"id":"1.231283997","rc":[{"batb":[[0,3.15,2],[1,3.1,4],[2,3.05,10.66]],"ltp":3.1,"tv":42719.81,"id":31379}]}]}
{"op":"mcm","clk":"11762617070","pt":1722531639949,"mc":[{"id":"1.231283997","rc":[{"batb":[[0,3.1,4],[1,3.05,10.66],[2,3,21.58]],"ltp":3.1,"tv":42719.81,"id":31379}]}]}
{"op":"mcm","clk":"11762617388","pt":1722531643227,"mc":[{"id":"1.231283997","rc":[{"batb":[[0,3.15,2],[1,3.1,4],[2,3.05,10.66]],"ltp":3.1,"tv":42719.81,"id":31379}]}]}
{"op":"mcm","clk":"11762617638","pt":1722531645563,"mc":[{"id":"1.231283997","rc":[{"batb":[[0,3.1,4],[1,3.05,10.66],[2,3,21.58]],"ltp":3.1,"tv":42719.81,"id":31379}]}]}
{"op":"mcm","clk":"11762618187","pt":1722531650333,"mc":[{"id":"1.231283997","rc":[{"batb":[[0,3.15,2],[1,3.1,4],[2,3.05,10.66]],"ltp":3.1,"tv":42719.81,"id":31379}]}]}
{"op":"mcm","clk":"11762618447","pt":1722531652654,"mc":[{"id":"1.231283997","rc":[{"batb":[[0,3.1,4],[1,3.05,10.66],[2,3,21.58]],"ltp":3.1,"tv":42719.81,"id":31379}]}]}
{"op":"mcm","clk":"11762618729","pt":1722531654980,"mc":[{"id":"1.231283997","rc":[{"batb":[[0,3.15,2],[1,3.1,4],[2,3.05,10.66]],"ltp":3.1,"tv":42719.81,"id":31379}]}]}
{"op":"mcm","clk":"11762619030","pt":1722531657273,"mc":[{"id":"1.231283997","rc":[{"batb":[[0,3.1,4],[1,3.05,10.66],[2,3,21.58]],"ltp":3.1,"tv":42719.81,"id":31379}]}]}
{"op":"mcm","clk":"11762619522","pt":1722531661585,"mc":[{"id":"1.231283997","rc":[{"batb":[[0,3.15,2],[1,3.1,4],[2,3.05,10.66]],"ltp":3.1,"tv":42719.81,"id":31379}]}]}
{"op":"mcm","clk":"11762619866","pt":1722531663975,"mc":[{"id":"1.231283997","rc":[{"batb":[[0,3.1,4],[1,3.05,10.66],[2,3,21.58]],"ltp":3.1,"tv":42719.81,"id":31379}]}]}
{"op":"mcm","clk":"11762620238","pt":1722531667063,"mc":[{"id":"1.231283997","rc":[{"batb":[[0,3.15,2],[1,3.1,4],[2,3.05,10.66]],"ltp":3.1,"tv":42719.81,"id":31379}]}]}
{"op":"mcm","clk":"11762620453","pt":1722531669267,"mc":[{"id":"1.231283997","rc":[{"batb":[[0,3.1,4],[1,3.05,10.66],[2,3,21.58]],"ltp":3.1,"tv":42719.81,"id":31379}]}]}
{"op":"mcm","clk":"11762620773","pt":1722531671588,"mc":[{"id":"1.231283997","rc":[{"batb":[[0,3.15,2],[1,3.1,4],[2,3.05,10.66]],"ltp":3.1,"tv":42719.81,"id":31379}]}]}
{"op":"mcm","clk":"11762621054","pt":1722531673798,"mc":[{"id":"1.231283997","rc":[{"batb":[[0,3.1,4],[1,3.05,10.66],[2,3,21.58]],"ltp":3.1,"tv":42719.81,"id":31379}]}]}
{"op":"mcm","clk":"11762621318","pt":1722531676054,"mc":[{"id":"1.231283997","rc":[{"batb":[[0,3.15,2],[1,3.1,4],[2,3.05,10.66]],"ltp":3.1,"tv":42719.81,"id":31379}]}]}
{"op":"mcm","clk":"11762621600","pt":1722531678389,"mc":[{"id":"1.231283997","rc":[{"batb":[[0,3.1,4],[1,3.05,10.66],[2,3,21.58]],"ltp":3.1,"tv":42719.81,"id":31379}]}]}
{"op":"mcm","clk":"11762621909","pt":1722531680696,"mc":[{"id":"1.231283997","rc":[{"batb":[[0,3.15,2],[1,3.1,4],[2,3.05,10.66]],"ltp":3.1,"tv":42719.81,"id":31379}]}]}
{"op":"mcm","clk":"11762622155","pt":1722531682894,"mc":[{"id":"1.231283997","rc":[{"batb":[[0,3.1,4],[1,3.05,10.66],[2,3,21.58]],"ltp":3.1,"tv":42719.81,"id":31379}]}]}
{"op":"mcm","clk":"11762622500","pt":1722531685877,"mc":[{"id":"1.231283997","rc":[{"batb":[[0,3.15,2],[1,3.1,4],[2,3.05,10.66]],"ltp":3.1,"tv":42719.81,"id":31379}]}]}
{"op":"mcm","clk":"11762622758","pt":1722531688095,"mc":[{"id":"1.231283997","rc":[{"batb":[[0,3.1,4],[1,3.05,10.66],[2,3,21.58]],"ltp":3.1,"tv":42719.81,"id":31379}]}]}
{"op":"mcm","clk":"11762623141","pt":1722531691511,"mc":[{"id":"1.231283997","rc":[{"batb":[[0,3.15,2],[1,3.1,4],[2,3.05,10.66]],"ltp":3.1,"tv":42719.81,"id":31379}]}]}
{"op":"mcm","clk":"11762623427","pt":1722531693888,"mc":[{"id":"1.231283997","rc":[{"batb":[[0,3.1,4],[1,3.05,10.66],[2,3,21.58]],"ltp":3.1,"tv":42719.81,"id":31379}]}]}
{"op":"mcm","clk":"11762623652","pt":1722531696009,"mc":[{"id":"1.231283997","rc":[{"batb":[[0,3.15,2],[1,3.1,4],[2,3.05,10.66]],"ltp":3.1,"tv":42719.81,"id":31379}]}]}
{"op":"mcm","clk":"11762623893","pt":1722531698311,"mc":[{"id":"1.231283997","rc":[{"batb":[[0,3.1,4],[1,3.05,10.66],[2,3,21.58]],"ltp":3.1,"tv":42719.81,"id":31379}]}]}
{"op":"mcm","clk":"11762624374","pt":1722531703020,"mc":[{"id":"1.231283997","rc":[{"batb":[[0,3.15,2],[1,3.1,4],[2,3.05,10.66]],"ltp":3.1,"tv":42719.81,"id":31379}]}]}
{"op":"mcm","clk":"11762624599","pt":1722531705220,"mc":[{"id":"1.231283997","rc":[{"batb":[[0,3.1,4],[1,3.05,10.66],[2,3,21.58]],"ltp":3.1,"tv":42719.81,"id":31379}]}]}
{"op":"mcm","clk":"11762625011","pt":1722531708644,"mc":[{"id":"1.231283997","rc":[{"batb":[[0,3.15,2],[1,3.1,4],[2,3.05,10.66]],"ltp":3.1,"tv":42719.81,"id":31379}]}]}
{"op":"mcm","clk":"11762625300","pt":1722531710924,"mc":[{"id":"1.231283997","rc":[{"batb":[[0,3.1,4],[1,3.05,10.66],[2,3,21.58]],"ltp":3.1,"tv":42719.81,"id":31379}]}]}
{"op":"mcm","clk":"11762625688","pt":1722531714151,"mc":[{"id":"1.231283997","rc":[{"batb":[[0,3.15,2],[1,3.1,4],[2,3.05,10.66]],"ltp":3.1,"tv":42719.81,"id":31379}]}]}
{"op":"mcm","clk":"11762625980","pt":1722531716306,"mc":[{"id":"1.231283997","rc":[{"batb":[[0,3.1,4],[1,3.05,10.66],[2,3,21.58]],"ltp":3.1,"tv":42719.81,"id":31379}]}]}
{"op":"mcm","clk":"11762626348","pt":1722531719726,"mc":[{"id":"1.231283997","rc":[{"batb":[[0,3.15,2],[1,3.1,4],[2,3.05,10.66]],"ltp":3.1,"tv":42719.81,"id":31379}]}]}
{"op":"mcm","clk":"11762626661","pt":1722531722041,"mc":[{"id":"1.231283997","rc":[{"batb":[[0,3.1,4],[1,3.05,10.66],[2,3,21.58]],"ltp":3.1,"tv":42719.81,"id":31379}]}]}
{"op":"mcm","clk":"11762627047","pt":1722531725233,"mc":[{"id":"1.231283997","rc":[{"batb":[[0,3.15,2],[1,3.1,4],[2,3.05,10.66]],"ltp":3.1,"tv":42719.81,"id":31379}]}]}
{"op":"mcm","clk":"11762627358","pt":1722531727553,"mc":[{"id":"1.231283997","rc":[{"batb":[[0,3.1,4],[1,3.05,10.66],[2,3,21.58]],"ltp":3.1,"tv":42719.81,"id":31379}]}]}
{"op":"mcm","clk":"11762627586","pt":1722531729769,"mc":[{"id":"1.231283997","rc":[{"batb":[[0,3.15,2],[1,3.1,4],[2,3.05,10.66]],"ltp":3.1,"tv":42719.81,"id":31379}]}]}
{"op":"mcm","clk":"11762627766","pt":1722531732162,"mc":[{"id":"1.231283997","rc":[{"batb":[[0,3.1,4],[1,3.05,10.66],[2,3,21.58]],"ltp":3.1,"tv":42719.81,"id":31379}]}]}
{"op":"mcm","clk":"11762627992","pt":1722531734460,"mc":[{"id":"1.231283997","rc":[{"batb":[[0,3.15,2],[1,3.1,4],[2,3.05,10.66]],"ltp":3.1,"tv":42719.81,"id":31379}]}]}
{"op":"mcm","clk":"11762628220","pt":1722531736730,"mc":[{"id":"1.231283997","rc":[{"batb":[[0,3.1,4],[1,3.05,10.66],[2,3,21.58]],"ltp":3.1,"tv":42719.81,"id":31379}]}]}
{"op":"mcm","clk":"11762628451","pt":1722531739356,"mc":[{"id":"1.231283997","rc":[{"batb":[[0,3.15,2],[1,3.1,4],[2,3.05,10.66]],"ltp":3.1,"tv":42719.81,"id":31379}]}]}
{"op":"mcm","clk":"11762628690","pt":1722531741858,"mc":[{"id":"1.231283997","rc":[{"batb":[[0,3.1,4],[1,3.05,10.66],[2,3,21.58]],"ltp":3.1,"tv":42719.81,"id":31379}]}]}
{"op":"mcm","clk":"11762628938","pt":1722531744552,"mc":[{"id":"1.231283997","rc":[{"batb":[[0,3.15,2],[1,3.1,4],[2,3.05,10.66]],"ltp":3.1,"tv":42719.81,"id":31379}]}]}
