{"op":"mcm","clk":"11846859680","pt":1723800178719,"mc":[{"id":"1.231875383","marketDefinition":{"bspMarket":false,"turnInPlayEnabled":true,"persistenceEnabled":true,"marketBaseRate":5.0,"eventId":"33499725","eventTypeId":"4","numberOfWinners":1,"bettingType":"ODDS","marketType":"MATCH_ODDS","marketTime":"2024-08-22T10:00:00.000Z","suspendTime":"2024-08-22T10:00:00.000Z","bspReconciled":false,"complete":true,"inPlay":false,"crossMatching":false,"runnersVoidable":false,"numberOfActiveRunners":3,"betDelay":0,"status":"OPEN","runners":[{"status":"ACTIVE","sortPriority":1,"id":655,"name":"Yorkshire"},{"status":"ACTIVE","sortPriority":2,"id":31379,"name":"Sussex"},{"status":"ACTIVE","sortPriority":3,"id":60443,"name":"The Draw"}],"regulators":["MR_INT"],"countryCode":"GB","discountAllowed":false,"timezone":"GMT","openDate":"2024-08-22T10:00:00.000Z","version":6076597021,"name":"Match Odds","eventName":"Yorkshire v Sussex"},"rc":[{"batb":[[0,1.03,200],[1,1.02,200],[2,1.01,220]],"ltp":0.0,"tv":0.0,"id":31379},{"batb":[[0,1.03,200],[1,1.02,200],[2,1.01,220]],"ltp":0.0,"tv":0.0,"id":655},{"batb":[[0,1.03,200],[1,1.02,200],[2,1.01,220]],"ltp":0.0,"tv":0.0,"id":60443}]}]}
{"op":"mcm","clk":"11846859777","pt":1723800180089,"mc":[{"id":"1.231875383","marketDefinition":{"bspMarket":false,"turnInPlayEnabled":true,"persistenceEnabled":true,"marketBaseRate":5.0,"eventId":"33499725","eventTypeId":"4","numberOfWinners":1,"bettingType":"ODDS","marketType":"MATCH_ODDS","marketTime":"2024-08-22T10:00:00.000Z","suspendTime":"2024-08-22T10:00:00.000Z","bspReconciled":false,"complete":true,"inPlay":false,"crossMatching":false,"runnersVoidable":false,"numberOfActiveRunners":3,"betDelay":0,"status":"OPEN","runners":[{"status":"ACTIVE","sortPriority":1,"id":655,"name":"Yorkshire"},{"status":"ACTIVE","sortPriority":2,"id":31379,"name":"Sussex"},{"status":"ACTIVE","sortPriority":3,"id":60443,"name":"The Draw"}],"regulators":["MR_INT"],"countryCode":"GB","discountAllowed":true,"timezone":"GMT","openDate":"2024-08-22T10:00:00.000Z","version":6076597021,"name":"Match Odds","eventName":"Yorkshire v Sussex"}}]}
{"op":"mcm","clk":"11847784582","pt":1723811309227,"mc":[{"id":"1.231875383","rc":[{"batb":[[0,1.25,100],[1,1.03,200],[2,1.02,200]],"ltp":0.0,"tv":0.0,"id":31379},{"batb":[[0,1.25,100],[1,1.03,200],[2,1.02,200]],"ltp":0.0,"tv":0.0,"id":655},{"batb":[[0,1.25,100],[1,1.03,200],[2,1.02,200]],"ltp":0.0,"tv":0.0,"id":60443}]}]}
{"op":"mcm","clk":"11847787342","pt":1723811341052,"mc":[{"id":"1.231875383","rc":[{"batb":[[0,1.03,200],[1,1.02,200],[2,1.01,220]],"ltp":0.0,"tv":0.0,"id":31379},{"batb":[[0,1.03,200],[1,1.02,200],[2,1.01,220]],"ltp":0.0,"tv":0.0,"id":655},{"batb":[[0,1.03,200],[1,1.02,200],[2,1.01,220]],"ltp":0.0,"tv":0.0,"id":60443}]}]}
{"op":"mcm","clk":"11847787733","pt":1723811345773,"mc":[{"id":"1.231875383","rc":[{"batb":[[0,1.25,100],[1,1.03,200],[2,1.02,200]],"ltp":0.0,"tv":0.0,"id":31379},{"batb":[[0,1.25,100],[1,1.03,200],[2,1.02,200]],"ltp":0.0,"tv":0.0,"id":655},{"batb":[[0,1.25,100],[1,1.03,200],[2,1.02,200]],"ltp":0.0,"tv":0.0,"id":60443}]}]}
{"op":"mcm","clk":"11847788285","pt":1723811351341,"mc":[{"id":"1.231875383","rc":[{"batb":[[0,1.03,200],[1,1.02,200],[2,1.01,220]],"ltp":0.0,"tv":0.0,"id":31379},{"batb":[[0,1.03,200],[1,1.02,200],[2,1.01,220]],"ltp":0.0,"tv":0.0,"id":655},{"batb":[[0,1.03,200],[1,1.02,200],[2,1.01,220]],"ltp":0.0,"tv":0.0,"id":60443}]}]}
{"op":"mcm","clk":"11847788923","pt":1723811358075,"mc":[{"id":"1.231875383","rc":[{"batl":[[0,95,5]],"ltp":0.0,"tv":0.0,"id":31379},{"batl":[[0,95,5],[1,990,5]],"ltp":0.0,"tv":0.0,"id":655},{"batl":[[0,95,5]],"ltp":0.0,"tv":0.0,"id":60443}]}]}
{"op":"mcm","clk":"11847788934","pt":1723811358182,"mc":[{"id":"1.231875383","rc":[{"batl":[[1,990,5]],"ltp":0.0,"tv":0.0,"id":31379},{"batl":[[1,990,5]],"ltp":0.0,"tv":0.0,"id":60443}]}]}
{"op":"mcm","clk":"11847794288","pt":1723811419743,"mc":[{"id":"1.231875383","rc":[{"batb":[[0,1.04,500],[1,1.03,200],[2,1.02,200]],"ltp":0.0,"tv":0.0,"id":655}]}]}
{"op":"mcm","clk":"11847794341","pt":1723811420271,"mc":[{"id":"1.231875383","rc":[{"batb":[[0,1.04,500],[1,1.03,200],[2,1.02,200]],"ltp":0.0,"tv":0.0,"id":31379},{"batb":[[0,1.04,500],[1,1.03,200],[2,1.02,200]],"ltp":0.0,"tv":0.0,"id":60443}]}]}
{"op":"mcm","clk":"11847831463","pt":1723811838815,"mc":[{"id":"1.231875383","rc":[{"trd":[[1.04,2]],"batb":[[0,1.04,499]],"ltp":1.04,"tv":2.0,"id":31379}],"tv":2.0}]}
{"op":"mcm","clk":"11852118568","pt":1723842040144,"mc":[{"id":"1.231875383","marketDefinition":{"bspMarket":false,"turnInPlayEnabled":true,"persistenceEnabled":true,"marketBaseRate":5.0,"eventId":"33499725","eventTypeId":"4","numberOfWinners":1,"bettingType":"ODDS","marketType":"MATCH_ODDS","marketTime":"2024-08-22T10:00:00.000Z","suspendTime":"2024-08-22T10:00:00.000Z","bspReconciled":false,"complete":true,"inPlay":false,"crossMatching":true,"runnersVoidable":false,"numberOfActiveRunners":3,"betDelay":0,"status":"OPEN","runners":[{"status":"ACTIVE","sortPriority":1,"id":655,"name":"Yorkshire"},{"status":"ACTIVE","sortPriority":2,"id":31379,"name":"Sussex"},{"status":"ACTIVE","sortPriority":3,"id":60443,"name":"The Draw"}],"regulators":["MR_INT"],"countryCode":"GB","discountAllowed":true,"timezone":"GMT","openDate":"2024-08-22T10:00:00.000Z","version":6076599802,"name":"Match Odds","eventName":"Yorkshire v Sussex"}}]}
{"op":"mcm","clk":"11856031119","pt":1723892267875,"mc":[{"id":"1.231875383","rc":[{"batb":[[0,1.05,8.98],[1,1.04,500],[2,1.03,200]],"ltp":0.0,"tv":0.0,"id":655}]}]}
{"op":"mcm","clk":"11856032651","pt":1723892279460,"mc":[{"id":"1.231875383","rc":[{"batb":[[0,1.05,8.98],[1,1.04,499],[2,1.03,200]],"ltp":1.04,"tv":2.0,"id":31379}]}]}
{"op":"mcm","clk":"11856034206","pt":1723892290886,"mc":[{"id":"1.231875383","rc":[{"batb":[[0,1.05,8.98],[1,1.04,500],[2,1.03,200]],"ltp":0.0,"tv":0.0,"id":60443}]}]}
{"op":"mcm","clk":"11856054822","pt":1723892430958,"mc":[{"id":"1.231875383","rc":[{"batb":[[0,1.06,142.66],[1,1.05,8.98],[2,1.04,499]],"ltp":1.04,"tv":2.0,"id":31379},{"batb":[[0,1.06,142.66],[1,1.05,8.98],[2,1.04,500]],"ltp":0.0,"tv":0.0,"id":655},{"batb":[[0,1.06,142.66],[1,1.05,8.98],[2,1.04,500]],"ltp":0.0,"tv":0.0,"id":60443}]}]}
{"op":"mcm","clk":"11856400343","pt":1723894231461,"mc":[{"id":"1.231875383","rc":[{"batb":[[0,1.05,8.98],[1,1.04,499],[2,1.03,200]],"ltp":1.04,"tv":2.0,"id":31379},{"batb":[[0,1.05,8.98],[1,1.04,500],[2,1.03,200]],"ltp":0.0,"tv":0.0,"id":655},{"batb":[[0,1.05,8.98],[1,1.04,500],[2,1.03,200]],"ltp":0.0,"tv":0.0,"id":60443}]}]}
{"op":"mcm","clk":"11856428798","pt":1723894370593,"mc":[{"id":"1.231875383","rc":[{"batb":[[0,1.06,142.66],[1,1.05,8.98],[2,1.04,499]],"ltp":1.04,"tv":2.0,"id":31379},{"batb":[[0,1.06,142.66],[1,1.05,8.98],[2,1.04,500]],"ltp":0.0,"tv":0.0,"id":655},{"batb":[[0,1.06,142.66],[1,1.05,8.98],[2,1.04,500]],"ltp":0.0,"tv":0.0,"id":60443}]}]}
{"op":"mcm","clk":"11856779347","pt":1723896170967,"mc":[{"id":"1.231875383","rc":[{"batb":[[0,1.05,8.98],[1,1.04,500],[2,1.03,200]],"ltp":0.0,"tv":0.0,"id":655},{"batb":[[0,1.05,8.98],[1,1.04,500],[2,1.03,200]],"ltp":0.0,"tv":0.0,"id":60443}]}]}
{"op":"mcm","clk":"11856779387","pt":1723896171139,"mc":[{"id":"1.231875383","rc":[{"batb":[[0,1.05,8.98],[1,1.04,499],[2,1.03,200]],"ltp":1.04,"tv":2.0,"id":31379}]}]}
{"op":"mcm","clk":"11856801588","pt":1723896293191,"mc":[{"id":"1.231875383","rc":[{"batb":[[0,1.06,142.66],[1,1.05,8.98],[2,1.04,499]],"ltp":1.04,"tv":2.0,"id":31379},{"batb":[[0,1.06,142.66],[1,1.05,8.98],[2,1.04,500]],"ltp":0.0,"tv":0.0,"id":655},{"batb":[[0,1.06,142.66],[1,1.05,8.98],[2,1.04,500]],"ltp":0.0,"tv":0.0,"id":60443}]}]}
{"op":"mcm","clk":"11857137038","pt":1723898093853,"mc":[{"id":"1.231875383","rc":[{"batb":[[0,1.05,8.98],[1,1.04,499],[2,1.03,200]],"ltp":1.04,"tv":2.0,"id":31379},{"batb":[[0,1.05,8.98],[1,1.04,500],[2,1.03,200]],"ltp":0.0,"tv":0.0,"id":655},{"batb":[[0,1.05,8.98],[1,1.04,500],[2,1.03,200]],"ltp":0.0,"tv":0.0,"id":60443}]}]}
{"op":"mcm","clk":"11857150087","pt":1723898163805,"mc":[{"id":"1.231875383","rc":[{"batb":[[0,1.06,142.66],[1,1.05,8.98],[2,1.04,499]],"ltp":1.04,"tv":2.0,"id":31379},{"batb":[[0,1.06,142.66],[1,1.05,8.98],[2,1.04,500]],"ltp":0.0,"tv":0.0,"id":655},{"batb":[[0,1.06,142.66],[1,1.05,8.98],[2,1.04,500]],"ltp":0.0,"tv":0.0,"id":60443}]}]}
{"op":"mcm","clk":"11857479160","pt":1723899963945,"mc":[{"id":"1.231875383","rc":[{"batb":[[0,1.05,8.98],[1,1.04,499],[2,1.03,200]],"ltp":1.04,"tv":2.0,"id":31379}]}]}
{"op":"mcm","clk":"11857479252","pt":1723899964344,"mc":[{"id":"1.231875383","rc":[{"batb":[[0,1.05,8.98],[1,1.04,500],[2,1.03,200]],"ltp":0.0,"tv":0.0,"id":655},{"batb":[[0,1.05,8.98],[1,1.04,500],[2,1.03,200]],"ltp":0.0,"tv":0.0,"id":60443}]}]}
{"op":"mcm","clk":"11857489563","pt":1723900011330,"mc":[{"id":"1.231875383","rc":[{"batb":[[0,1.06,142.66],[1,1.05,8.98],[2,1.04,499]],"ltp":1.04,"tv":2.0,"id":31379},{"batb":[[0,1.06,142.66],[1,1.05,8.98],[2,1.04,500]],"ltp":0.0,"tv":0.0,"id":655},{"batb":[[0,1.06,142.66],[1,1.05,8.98],[2,1.04,500]],"ltp":0.0,"tv":0.0,"id":60443}]}]}
{"op":"mcm","clk":"11857621808","pt":1723900589597,"mc":[{"id":"1.231875383","rc":[{"batb":[[0,1.07,44.3],[1,1.06,142.66],[2,1.05,8.98]],"batl":[[0,95,5.85]],"ltp":1.04,"tv":2.0,"id":31379},{"batb":[[0,1.07,44.3],[1,1.06,142.66],[2,1.05,8.98]],"batl":[[0,95,5.85]],"ltp":0.0,"tv":0.0,"id":655},{"batb":[[0,1.07,55.37],[1,1.06,142.66],[2,1.05,8.98]],"batl":[[0,95,5.85]],"ltp":0.0,"tv":0.0,"id":60443}]}]}
{"op":"mcm","clk":"11857839692","pt":1723901813078,"mc":[{"id":"1.231875383","rc":[{"batb":[[1,1.05,8.98],[2,1.04,499]],"ltp":1.04,"tv":2.0,"id":31379},{"batb":[[1,1.05,8.98],[2,1.04,500]],"ltp":0.0,"tv":0.0,"id":655},{"batb":[[1,1.05,8.98],[2,1.04,500]],"ltp":0.0,"tv":0.0,"id":60443}]}]}
{"op":"mcm","clk":"11857842989","pt":1723901831295,"mc":[{"id":"1.231875383","rc":[{"batb":[[0,1.08,106.99],[1,1.07,44.3],[2,1.05,8.98]],"ltp":1.04,"tv":2.0,"id":31379},{"batb":[[0,1.08,106.99],[1,1.07,44.3],[2,1.05,8.98]],"ltp":0.0,"tv":0.0,"id":655},{"batb":[[0,1.08,106.99],[1,1.07,55.37],[2,1.05,8.98]],"ltp":0.0,"tv":0.0,"id":60443}]}]}
{"op":"mcm","clk":"11858201389","pt":1723903631870,"mc":[{"id":"1.231875383","rc":[{"batb":[[0,1.07,44.3],[1,1.05,8.98],[2,1.04,499]],"ltp":1.04,"tv":2.0,"id":31379},{"batb":[[0,1.07,44.3],[1,1.05,8.98],[2,1.04,500]],"ltp":0.0,"tv":0.0,"id":655},{"batb":[[0,1.07,55.37],[1,1.05,8.98],[2,1.04,500]],"ltp":0.0,"tv":0.0,"id":60443}]}]}
{"op":"mcm","clk":"11858253377","pt":1723903792698,"mc":[{"id":"1.231875383","rc":[{"batb":[[0,1.08,106.99],[1,1.07,44.3],[2,1.05,8.98]],"ltp":1.04,"tv":2.0,"id":31379},{"batb":[[0,1.08,106.99],[1,1.07,44.3],[2,1.05,8.98]],"ltp":0.0,"tv":0.0,"id":655},{"batb":[[0,1.08,106.99],[1,1.07,55.37],[2,1.05,8.98]],"ltp":0.0,"tv":0.0,"id":60443}]}]}
{"op":"mcm","clk":"11858858958","pt":1723905593678,"mc":[{"id":"1.231875383","rc":[{"batb":[[0,1.07,44.3],[1,1.05,8.98],[2,1.04,499]],"ltp":1.04,"tv":2.0,"id":31379},{"batb":[[0,1.07,44.3],[1,1.05,8.98],[2,1.04,500]],"ltp":0.0,"tv":0.0,"id":655},{"batb":[[0,1.07,55.37],[1,1.05,8.98],[2,1.04,500]],"ltp":0.0,"tv":0.0,"id":60443}]}]}
{"op":"mcm","clk":"11858904103","pt":1723905725975,"mc":[{"id":"1.231875383","rc":[{"batb":[[0,1.08,106.99],[1,1.07,44.3],[2,1.05,8.98]],"ltp":1.04,"tv":2.0,"id":31379},{"batb":[[0,1.08,106.99],[1,1.07,44.3],[2,1.05,8.98]],"ltp":0.0,"tv":0.0,"id":655},{"batb":[[0,1.08,106.99],[1,1.07,55.37],[2,1.05,8.98]],"ltp":0.0,"tv":0.0,"id":60443}]}]}
{"op":"mcm","clk":"11859405486","pt":1723907526724,"mc":[{"id":"1.231875383","rc":[{"batb":[[0,1.07,44.3],[1,1.05,8.98],[2,1.04,499]],"ltp":1.04,"tv":2.0,"id":31379},{"batb":[[0,1.07,44.3],[1,1.05,8.98],[2,1.04,500]],"ltp":0.0,"tv":0.0,"id":655},{"batb":[[0,1.07,55.37],[1,1.05,8.98],[2,1.04,500]],"ltp":0.0,"tv":0.0,"id":60443}]}]}
{"op":"mcm","clk":"11859436101","pt":1723907619465,"mc":[{"id":"1.231875383","rc":[{"batb":[[0,1.08,106.99],[1,1.07,44.3],[2,1.05,8.98]],"ltp":1.04,"tv":2.0,"id":31379},{"batb":[[0,1.08,106.99],[1,1.07,44.3],[2,1.05,8.98]],"ltp":0.0,"tv":0.0,"id":655},{"batb":[[0,1.08,106.99],[1,1.07,55.37],[2,1.05,8.98]],"ltp":0.0,"tv":0.0,"id":60443}]}]}
{"op":"mcm","clk":"11860022021","pt":1723909419910,"mc":[{"id":"1.231875383","rc":[{"batb":[[0,1.07,44.3],[1,1.05,8.98],[2,1.04,499]],"ltp":1.04,"tv":2.0,"id":31379},{"batb":[[0,1.07,55.37],[1,1.05,8.98],[2,1.04,500]],"ltp":0.0,"tv":0.0,"id":60443}]}]}
{"op":"mcm","clk":"11860022115","pt":1723909420236,"mc":[{"id":"1.231875383","rc":[{"batb":[[0,1.07,44.3],[1,1.05,8.98],[2,1.04,500]],"ltp":0.0,"tv":0.0,"id":655}]}]}
{"op":"mcm","clk":"11860037049","pt":1723909470214,"mc":[{"id":"1.231875383","rc":[{"batb":[[0,1.08,106.99],[1,1.07,44.3],[2,1.05,8.98]],"ltp":1.04,"tv":2.0,"id":31379},{"batb":[[0,1.08,106.99],[1,1.07,44.3],[2,1.05,8.98]],"ltp":0.0,"tv":0.0,"id":655},{"batb":[[0,1.08,106.99],[1,1.07,55.37],[2,1.05,8.98]],"ltp":0.0,"tv":0.0,"id":60443}]}]}
{"op":"mcm","clk":"11860069772","pt":1723909581461,"mc":[{"id":"1.231875383","rc":[{"batb":[[0,1.09,44.3],[1,1.08,106.99]],"ltp":1.04,"tv":2.0,"id":31379},{"batb":[[0,1.09,44.3],[1,1.08,106.99]],"ltp":0.0,"tv":0.0,"id":655},{"batb":[[0,1.09,55.37],[1,1.08,106.99]],"ltp":0.0,"tv":0.0,"id":60443}]}]}
{"op":"mcm","clk":"11860434930","pt":1723911270862,"mc":[{"id":"1.231875383","rc":[{"batb":[[1,1.05,8.98],[2,1.04,499]],"ltp":1.04,"tv":2.0,"id":31379},{"batb":[[1,1.05,8.98],[2,1.04,500]],"ltp":0.0,"tv":0.0,"id":655},{"batb":[[1,1.05,8.98],[2,1.04,500]],"ltp":0.0,"tv":0.0,"id":60443}]}]}
{"op":"mcm","clk":"11860454772","pt":1723911362685,"mc":[{"id":"1.231875383","rc":[{"batb":[[0,1.1,85.6],[1,1.09,44.3],[2,1.05,8.98]],"ltp":1.04,"tv":2.0,"id":31379},{"batb":[[0,1.1,85.6],[1,1.09,44.3],[2,1.05,8.98]],"ltp":0.0,"tv":0.0,"id":655},{"batb":[[0,1.1,85.6],[1,1.09,55.37],[2,1.05,8.98]],"ltp":0.0,"tv":0.0,"id":60443}]}]}
{"op":"mcm","clk":"11860808862","pt":1723913163448,"mc":[{"id":"1.231875383","rc":[{"batb":[[0,1.09,44.3],[1,1.05,8.98],[2,1.04,499]],"ltp":1.04,"tv":2.0,"id":31379},{"batb":[[0,1.09,44.3],[1,1.05,8.98],[2,1.04,500]],"ltp":0.0,"tv":0.0,"id":655},{"batb":[[0,1.09,55.37],[1,1.05,8.98],[2,1.04,500]],"ltp":0.0,"tv":0.0,"id":60443}]}]}
{"op":"mcm","clk":"11860828932","pt":1723913271781,"mc":[{"id":"1.231875383","rc":[{"batb":[[0,1.1,85.6],[1,1.09,44.3],[2,1.05,8.98]],"ltp":1.04,"tv":2.0,"id":31379},{"batb":[[0,1.1,85.6],[1,1.09,44.3],[2,1.05,8.98]],"ltp":0.0,"tv":0.0,"id":655},{"batb":[[0,1.1,85.6],[1,1.09,55.37],[2,1.05,8.98]],"ltp":0.0,"tv":0.0,"id":60443}]}]}
{"op":"mcm","clk":"11861111112","pt":1723915071995,"mc":[{"id":"1.231875383","rc":[{"batb":[[0,1.09,44.3],[1,1.05,8.98],[2,1.04,500]],"ltp":0.0,"tv":0.0,"id":655}]}]}
{"op":"mcm","clk":"11861111178","pt":1723915072522,"mc":[{"id":"1.231875383","rc":[{"batb":[[0,1.09,44.3],[1,1.05,8.98],[2,1.04,499]],"ltp":1.04,"tv":2.0,"id":31379},{"batb":[[0,1.09,55.37],[1,1.05,8.98],[2,1.04,500]],"ltp":0.0,"tv":0.0,"id":60443}]}]}
{"op":"mcm","clk":"11861117729","pt":1723915114221,"mc":[{"id":"1.231875383","rc":[{"batb":[[0,1.1,85.6],[1,1.09,44.3],[2,1.05,8.98]],"ltp":1.04,"tv":2.0,"id":31379},{"batb":[[0,1.1,85.6],[1,1.09,44.3],[2,1.05,8.98]],"ltp":0.0,"tv":0.0,"id":655},{"batb":[[0,1.1,85.6],[1,1.09,55.37],[2,1.05,8.98]],"ltp":0.0,"tv":0.0,"id":60443}]}]}
{"op":"mcm","clk":"11861437500","pt":1723916915071,"mc":[{"id":"1.231875383","rc":[{"batb":[[0,1.09,44.3],[1,1.05,8.98],[2,1.04,499]],"ltp":1.04,"tv":2.0,"id":31379},{"batb":[[0,1.09,44.3],[1,1.05,8.98],[2,1.04,500]],"ltp":0.0,"tv":0.0,"id":655},{"batb":[[0,1.09,55.37],[1,1.05,8.98],[2,1.04,500]],"ltp":0.0,"tv":0.0,"id":60443}]}]}
{"op":"mcm","clk":"11861461549","pt":1723917054850,"mc":[{"id":"1.231875383","rc":[{"batb":[[0,1.1,85.6],[1,1.09,44.3],[2,1.05,8.98]],"ltp":1.04,"tv":2.0,"id":31379},{"batb":[[0,1.1,85.6],[1,1.09,44.3],[2,1.05,8.98]],"ltp":0.0,"tv":0.0,"id":655},{"batb":[[0,1.1,85.6],[1,1.09,55.37],[2,1.05,8.98]],"ltp":0.0,"tv":0.0,"id":60443}]}]}
{"op":"mcm","clk":"11861780725","pt":1723918855832,"mc":[{"id":"1.231875383","rc":[{"batb":[[0,1.09,44.3],[1,1.05,8.98],[2,1.04,499]],"ltp":1.04,"tv":2.0,"id":31379},{"batb":[[0,1.09,44.3],[1,1.05,8.98],[2,1.04,500]],"ltp":0.0,"tv":0.0,"id":655},{"batb":[[0,1.09,55.37],[1,1.05,8.98],[2,1.04,500]],"ltp":0.0,"tv":0.0,"id":60443}]}]}
{"op":"mcm","clk":"11861797747","pt":1723918940268,"mc":[{"id":"1.231875383","rc":[{"batb":[[0,1.1,85.6],[1,1.09,44.3],[2,1.05,8.98]],"ltp":1.04,"tv":2.0,"id":31379},{"batb":[[0,1.1,85.6],[1,1.09,44.3],[2,1.05,8.98]],"ltp":0.0,"tv":0.0,"id":655},{"batb":[[0,1.1,85.6],[1,1.09,55.37],[2,1.05,8.98]],"ltp":0.0,"tv":0.0,"id":60443}]}]}
{"op":"mcm","clk":"11862150569","pt":1723920740994,"mc":[{"id":"1.231875383","rc":[{"batb":[[0,1.09,44.3],[1,1.05,8.98],[2,1.04,499]],"ltp":1.04,"tv":2.0,"id":31379},{"batb":[[0,1.09,55.37],[1,1.05,8.98],[2,1.04,500]],"ltp":0.0,"tv":0.0,"id":60443}]}]}
{"op":"mcm","clk":"11862150600","pt":1723920741166,"mc":[{"id":"1.231875383","rc":[{"batb":[[0,1.09,44.3],[1,1.05,8.98],[2,1.04,500]],"ltp":0.0,"tv":0.0,"id":655}]}]}
{"op":"mcm","clk":"11862154569","pt":1723920761352,"mc":[{"id":"1.231875383","rc":[{"batb":[[0,1.1,85.6],[1,1.09,44.3],[2,1.05,8.98]],"ltp":1.04,"tv":2.0,"id":31379},{"batb":[[0,1.1,85.6],[1,1.09,44.3],[2,1.05,8.98]],"ltp":0.0,"tv":0.0,"id":655},{"batb":[[0,1.1,85.6],[1,1.09,55.37],[2,1.05,8.98]],"ltp":0.0,"tv":0.0,"id":60443}]}]}
{"op":"mcm","clk":"11862235061","pt":1723921235404,"mc":[{"id":"1.231875383","rc":[{"batb":[[0,1.11,181.82],[1,1.1,85.6],[2,1.09,44.3]],"ltp":0.0,"tv":0.0,"id":655}]}]}
{"op":"mcm","clk":"11862235670","pt":1723921238678,"mc":[{"id":"1.231875383","rc":[{"batb":[[0,1.11,181.82],[1,1.1,85.6],[2,1.09,44.3]],"ltp":1.04,"tv":2.0,"id":31379}]}]}
{"op":"mcm","clk":"11862236649","pt":1723921244193,"mc":[{"id":"1.231875383","rc":[{"batb":[[0,1.11,181.82],[1,1.1,85.6],[2,1.09,55.37]],"ltp":0.0,"tv":0.0,"id":60443}]}]}
{"op":"mcm","clk":"11862523869","pt":1723922562077,"mc":[{"id":"1.231875383","rc":[{"batb":[[1,1.09,44.3],[2,1.05,8.98]],"ltp":1.04,"tv":2.0,"id":31379},{"batb":[[1,1.09,44.3],[2,1.05,8.98]],"ltp":0.0,"tv":0.0,"id":655},{"batb":[[1,1.09,55.37],[2,1.05,8.98]],"ltp":0.0,"tv":0.0,"id":60443}]}]}
{"op":"mcm","clk":"11862545862","pt":1723922671501,"mc":[{"id":"1.231875383","rc":[{"batb":[[0,1.12,71.33],[1,1.11,181.82],[2,1.09,44.3]],"ltp":1.04,"tv":2.0,"id":31379},{"batb":[[0,1.12,71.33],[1,1.11,181.82],[2,1.09,44.3]],"ltp":0.0,"tv":0.0,"id":655},{"batb":[[0,1.12,71.33],[1,1.11,181.82],[2,1.09,55.37]],"ltp":0.0,"tv":0.0,"id":60443}]}]}
{"op":"mcm","clk":"11862911299","pt":1723924471998,"mc":[{"id":"1.231875383","rc":[{"batb":[[0,1.11,181.82],[1,1.09,55.37],[2,1.05,8.98]],"ltp":0.0,"tv":0.0,"id":60443}]}]}
{"op":"mcm","clk":"11862911340","pt":1723924472267,"mc":[{"id":"1.231875383","rc":[{"batb":[[0,1.11,181.82],[1,1.09,44.3],[2,1.05,8.98]],"ltp":1.04,"tv":2.0,"id":31379},{"batb":[[0,1.11,181.82],[1,1.09,44.3],[2,1.05,8.98]],"ltp":0.0,"tv":0.0,"id":655}]}]}
{"op":"mcm","clk":"11862922917","pt":1723924543378,"mc":[{"id":"1.231875383","rc":[{"batb":[[0,1.12,71.33],[1,1.11,181.82],[2,1.09,44.3]],"ltp":1.04,"tv":2.0,"id":31379},{"batb":[[0,1.12,71.33],[1,1.11,181.82],[2,1.09,44.3]],"ltp":0.0,"tv":0.0,"id":655},{"batb":[[0,1.12,71.33],[1,1.11,181.82],[2,1.09,55.37]],"ltp":0.0,"tv":0.0,"id":60443}]}]}
{"op":"mcm","clk":"11863206657","pt":1723926344065,"mc":[{"id":"1.231875383","rc":[{"batb":[[0,1.11,181.82],[1,1.09,44.3],[2,1.05,8.98]],"ltp":0.0,"tv":0.0,"id":655},{"batb":[[0,1.11,181.82],[1,1.09,55.37],[2,1.05,8.98]],"ltp":0.0,"tv":0.0,"id":60443}]}]}
{"op":"mcm","clk":"11863206688","pt":1723926344267,"mc":[{"id":"1.231875383","rc":[{"batb":[[0,1.11,181.82],[1,1.09,44.3],[2,1.05,8.98]],"ltp":1.04,"tv":2.0,"id":31379}]}]}
{"op":"mcm","clk":"11863223208","pt":1723926459867,"mc":[{"id":"1.231875383","rc":[{"batb":[[0,1.12,71.33],[1,1.11,181.82],[2,1.09,44.3]],"ltp":1.04,"tv":2.0,"id":31379},{"batb":[[0,1.12,71.33],[1,1.11,181.82],[2,1.09,44.3]],"ltp":0.0,"tv":0.0,"id":655},{"batb":[[0,1.12,71.33],[1,1.11,181.82],[2,1.09,55.37]],"ltp":0.0,"tv":0.0,"id":60443}]}]}
{"op":"mcm","clk":"11863483555","pt":1723928260694,"mc":[{"id":"1.231875383","rc":[{"batb":[[0,1.11,181.82],[1,1.09,44.3],[2,1.05,8.98]],"ltp":1.04,"tv":2.0,"id":31379},{"batb":[[0,1.11,181.82],[1,1.09,44.3],[2,1.05,8.98]],"ltp":0.0,"tv":0.0,"id":655},{"batb":[[0,1.11,181.82],[1,1.09,55.37],[2,1.05,8.98]],"ltp":0.0,"tv":0.0,"id":60443}]}]}
{"op":"mcm","clk":"11863488135","pt":1723928301132,"mc":[{"id":"1.231875383","rc":[{"batb":[[0,1.12,71.33],[1,1.11,181.82],[2,1.09,44.3]],"ltp":1.04,"tv":2.0,"id":31379},{"batb":[[0,1.12,71.33],[1,1.11,181.82],[2,1.09,44.3]],"ltp":0.0,"tv":0.0,"id":655},{"batb":[[0,1.12,71.33],[1,1.11,181.82],[2,1.09,55.37]],"ltp":0.0,"tv":0.0,"id":60443}]}]}
{"op":"mcm","clk":"11863668542","pt":1723930101579,"mc":[{"id":"1.231875383","rc":[{"batb":[[0,1.11,181.82],[1,1.09,44.3],[2,1.05,8.98]],"ltp":0.0,"tv":0.0,"id":655},{"batb":[[0,1.11,181.82],[1,1.09,55.37],[2,1.05,8.98]],"ltp":0.0,"tv":0.0,"id":60443}]}]}
{"op":"mcm","clk":"11863668557","pt":1723930103582,"mc":[{"id":"1.231875383","rc":[{"batb":[[0,1.11,181.82],[1,1.09,44.3],[2,1.05,8.98]],"ltp":1.04,"tv":2.0,"id":31379}]}]}
{"op":"mcm","clk":"11863672513","pt":1723930152933,"mc":[{"id":"1.231875383","rc":[{"batb":[[0,1.12,71.33],[1,1.11,181.82],[2,1.09,44.3]],"ltp":1.04,"tv":2.0,"id":31379},{"batb":[[0,1.12,71.33],[1,1.11,181.82],[2,1.09,44.3]],"ltp":0.0,"tv":0.0,"id":655},{"batb":[[0,1.12,71.33],[1,1.11,181.82],[2,1.09,55.37]],"ltp":0.0,"tv":0.0,"id":60443}]}]}
{"op":"mcm","clk":"11863814899","pt":1723931953519,"mc":[{"id":"1.231875383","rc":[{"batb":[[0,1.11,181.82],[1,1.09,44.3],[2,1.05,8.98]],"ltp":1.04,"tv":2.0,"id":31379},{"batb":[[0,1.11,181.82],[1,1.09,44.3],[2,1.05,8.98]],"ltp":0.0,"tv":0.0,"id":655},{"batb":[[0,1.11,181.82],[1,1.09,55.37],[2,1.05,8.98]],"ltp":0.0,"tv":0.0,"id":60443}]}]}
{"op":"mcm","clk":"11863815855","pt":1723931967031,"mc":[{"id":"1.231875383","rc":[{"batb":[[0,1.12,71.33],[1,1.11,181.82],[2,1.09,44.3]],"ltp":1.04,"tv":2.0,"id":31379},{"batb":[[0,1.12,71.33],[1,1.11,181.82],[2,1.09,44.3]],"ltp":0.0,"tv":0.0,"id":655},{"batb":[[0,1.12,71.33],[1,1.11,181.82],[2,1.09,55.37]],"ltp":0.0,"tv":0.0,"id":60443}]}]}
{"op":"mcm","clk":"11863957110","pt":1723933767952,"mc":[{"id":"1.231875383","rc":[{"batb":[[0,1.11,181.82],[1,1.09,44.3],[2,1.05,8.98]],"ltp":0.0,"tv":0.0,"id":655},{"batb":[[0,1.11,181.82],[1,1.09,55.37],[2,1.05,8.98]],"ltp":0.0,"tv":0.0,"id":60443}]}]}
{"op":"mcm","clk":"11863957123","pt":1723933768157,"mc":[{"id":"1.231875383","rc":[{"batb":[[0,1.11,181.82],[1,1.09,44.3],[2,1.05,8.98]],"ltp":1.04,"tv":2.0,"id":31379}]}]}
{"op":"mcm","clk":"11863964196","pt":1723933857076,"mc":[{"id":"1.231875383","rc":[{"batb":[[0,1.12,71.33],[1,1.11,181.82],[2,1.09,44.3]],"ltp":1.04,"tv":2.0,"id":31379},{"batb":[[0,1.12,71.33],[1,1.11,181.82],[2,1.09,44.3]],"ltp":0.0,"tv":0.0,"id":655},{"batb":[[0,1.12,71.33],[1,1.11,181.82],[2,1.09,55.37]],"ltp":0.0,"tv":0.0,"id":60443}]}]}
{"op":"mcm","clk":"11864108656","pt":1723935657813,"mc":[{"id":"1.231875383","rc":[{"batb":[[0,1.11,181.82],[1,1.09,44.3],[2,1.05,8.98]],"ltp":1.04,"tv":2.0,"id":31379},{"batb":[[0,1.11,181.82],[1,1.09,44.3],[2,1.05,8.98]],"ltp":0.0,"tv":0.0,"id":655},{"batb":[[0,1.11,181.82],[1,1.09,55.37],[2,1.05,8.98]],"ltp":0.0,"tv":0.0,"id":60443}]}]}
{"op":"mcm","clk":"11864113549","pt":1723935720715,"mc":[{"id":"1.231875383","rc":[{"batb":[[0,1.12,71.33],[1,1.11,181.82],[2,1.09,44.3]],"ltp":1.04,"tv":2.0,"id":31379},{"batb":[[0,1.12,71.33],[1,1.11,181.82],[2,1.09,44.3]],"ltp":0.0,"tv":0.0,"id":655},{"batb":[[0,1.12,71.33],[1,1.11,181.82],[2,1.09,55.37]],"ltp":0.0,"tv":0.0,"id":60443}]}]}
{"op":"mcm","clk":"11864271461","pt":1723937521586,"mc":[{"id":"1.231875383","rc":[{"batb":[[0,1.11,181.82],[1,1.09,44.3],[2,1.05,8.98]],"ltp":1.04,"tv":2.0,"id":31379},{"batb":[[0,1.11,181.82],[1,1.09,44.3],[2,1.05,8.98]],"ltp":0.0,"tv":0.0,"id":655},{"batb":[[0,1.11,181.82],[1,1.09,55.37],[2,1.05,8.98]],"ltp":0.0,"tv":0.0,"id":60443}]}]}
{"op":"mcm","clk":"11864282324","pt":1723937639612,"mc":[{"id":"1.231875383","rc":[{"batb":[[0,1.12,71.33],[1,1.11,181.82],[2,1.09,44.3]],"ltp":1.04,"tv":2.0,"id":31379},{"batb":[[0,1.12,71.33],[1,1.11,181.82],[2,1.09,44.3]],"ltp":0.0,"tv":0.0,"id":655},{"batb":[[0,1.12,71.33],[1,1.11,181.82],[2,1.09,55.37]],"ltp":0.0,"tv":0.0,"id":60443}]}]}
{"op":"mcm","clk":"11864454276","pt":1723939440786,"mc":[{"id":"1.231875383","rc":[{"batb":[[0,1.11,181.82],[1,1.09,44.3],[2,1.05,8.98]],"ltp":1.04,"tv":2.0,"id":31379},{"batb":[[0,1.11,181.82],[1,1.09,44.3],[2,1.05,8.98]],"ltp":0.0,"tv":0.0,"id":655},{"batb":[[0,1.11,181.82],[1,1.09,55.37],[2,1.05,8.98]],"ltp":0.0,"tv":0.0,"id":60443}]}]}
{"op":"mcm","clk":"11864462719","pt":1723939552018,"mc":[{"id":"1.231875383","rc":[{"batb":[[0,1.12,71.33],[1,1.11,181.82],[2,1.09,44.3]],"ltp":1.04,"tv":2.0,"id":31379},{"batb":[[0,1.12,71.33],[1,1.11,181.82],[2,1.09,44.3]],"ltp":0.0,"tv":0.0,"id":655},{"batb":[[0,1.12,71.33],[1,1.11,181.82],[2,1.09,55.37]],"ltp":0.0,"tv":0.0,"id":60443}]}]}
{"op":"mcm","clk":"11864612876","pt":1723941352848,"mc":[{"id":"1.231875383","rc":[{"batb":[[0,1.11,181.82],[1,1.09,44.3],[2,1.05,8.98]],"ltp":1.04,"tv":2.0,"id":31379},{"batb":[[0,1.11,181.82],[1,1.09,44.3],[2,1.05,8.98]],"ltp":0.0,"tv":0.0,"id":655},{"batb":[[0,1.11,181.82],[1,1.09,55.37],[2,1.05,8.98]],"ltp":0.0,"tv":0.0,"id":60443}]}]}
{"op":"mcm","clk":"11864621347","pt":1723941455440,"mc":[{"id":"1.231875383","rc":[{"batb":[[0,1.12,71.33],[1,1.11,181.82],[2,1.09,44.3]],"ltp":1.04,"tv":2.0,"id":31379},{"batb":[[0,1.12,71.33],[1,1.11,181.82],[2,1.09,44.3]],"ltp":0.0,"tv":0.0,"id":655},{"batb":[[0,1.12,71.33],[1,1.11,181.82],[2,1.09,55.37]],"ltp":0.0,"tv":0.0,"id":60443}]}]}
{"op":"mcm","clk":"11864765856","pt":1723943256691,"mc":[{"id":"1.231875383","rc":[{"batb":[[0,1.11,181.82],[1,1.09,44.3],[2,1.05,8.98]],"ltp":1.04,"tv":2.0,"id":31379},{"batb":[[0,1.11,181.82],[1,1.09,44.3],[2,1.05,8.98]],"ltp":0.0,"tv":0.0,"id":655},{"batb":[[0,1.11,181.82],[1,1.09,55.37],[2,1.05,8.98]],"ltp":0.0,"tv":0.0,"id":60443}]}]}
{"op":"mcm","clk":"11864772581","pt":1723943346138,"mc":[{"id":"1.231875383","rc":[{"batb":[[0,1.12,71.33],[1,1.11,181.82],[2,1.09,44.3]],"ltp":1.04,"tv":2.0,"id":31379},{"batb":[[0,1.12,71.33],[1,1.11,181.82],[2,1.09,44.3]],"ltp":0.0,"tv":0.0,"id":655},{"batb":[[0,1.12,71.33],[1,1.11,181.82],[2,1.09,55.37]],"ltp":0.0,"tv":0.0,"id":60443}]}]}
{"op":"mcm","clk":"11864929536","pt":1723945146802,"mc":[{"id":"1.231875383","rc":[{"batb":[[0,1.11,181.82],[1,1.09,44.3],[2,1.05,8.98]],"ltp":1.04,"tv":2.0,"id":31379},{"batb":[[0,1.11,181.82],[1,1.09,44.3],[2,1.05,8.98]],"ltp":0.0,"tv":0.0,"id":655},{"batb":[[0,1.11,181.82],[1,1.09,55.37],[2,1.05,8.98]],"ltp":0.0,"tv":0.0,"id":60443}]}]}
{"op":"mcm","clk":"11864934955","pt":1723945213957,"mc":[{"id":"1.231875383","rc":[{"batb":[[0,1.12,71.33],[1,1.11,181.82],[2,1.09,44.3]],"ltp":1.04,"tv":2.0,"id":31379},{"batb":[[0,1.12,71.33],[1,1.11,181.82],[2,1.09,44.3]],"ltp":0.0,"tv":0.0,"id":655},{"batb":[[0,1.12,71.33],[1,1.11,181.82],[2,1.09,55.37]],"ltp":0.0,"tv":0.0,"id":60443}]}]}
{"op":"mcm","clk":"11865054894","pt":1723947014893,"mc":[{"id":"1.231875383","rc":[{"batb":[[0,1.11,181.82],[1,1.09,44.3],[2,1.05,8.98]],"ltp":1.04,"tv":2.0,"id":31379},{"batb":[[0,1.11,181.82],[1,1.09,44.3],[2,1.05,8.98]],"ltp":0.0,"tv":0.0,"id":655},{"batb":[[0,1.11,181.82],[1,1.09,55.37],[2,1.05,8.98]],"ltp":0.0,"tv":0.0,"id":60443}]}]}
{"op":"mcm","clk":"11865056374","pt":1723947044955,"mc":[{"id":"1.231875383","rc":[{"batb":[[0,1.12,71.33],[1,1.11,181.82],[2,1.09,44.3]],"ltp":1.04,"tv":2.0,"id":31379},{"batb":[[0,1.12,71.33],[1,1.11,181.82],[2,1.09,44.3]],"ltp":0.0,"tv":0.0,"id":655},{"batb":[[0,1.12,71.33],[1,1.11,181.82],[2,1.09,55.37]],"ltp":0.0,"tv":0.0,"id":60443}]}]}
{"op":"mcm","clk":"11865156096","pt":1723948845894,"mc":[{"id":"1.231875383","rc":[{"batb":[[0,1.11,181.82],[1,1.09,44.3],[2,1.05,8.98]],"ltp":1.04,"tv":2.0,"id":31379},{"batb":[[0,1.11,181.82],[1,1.09,44.3],[2,1.05,8.98]],"ltp":0.0,"tv":0.0,"id":655},{"batb":[[0,1.11,181.82],[1,1.09,55.37],[2,1.05,8.98]],"ltp":0.0,"tv":0.0,"id":60443}]}]}
{"op":"mcm","clk":"11865175457","pt":1723949014024,"mc":[{"id":"1.231875383","rc":[{"batb":[[0,1.12,71.33],[1,1.11,181.82],[2,1.09,44.3]],"ltp":1.04,"tv":2.0,"id":31379},{"batb":[[0,1.12,71.33],[1,1.11,181.82],[2,1.09,44.3]],"ltp":0.0,"tv":0.0,"id":655},{"batb":[[0,1.12,71.33],[1,1.11,181.82],[2,1.09,55.37]],"ltp":0.0,"tv":0.0,"id":60443}]}]}
{"op":"mcm","clk":"11865242029","pt":1723950815028,"mc":[{"id":"1.231875383","rc":[{"batb":[[0,1.11,181.82],[1,1.09,44.3],[2,1.03,200]],"ltp":1.04,"tv":2.0,"id":31379},{"batb":[[0,1.11,181.82],[1,1.09,44.3],[2,1.03,200]],"ltp":0.0,"tv":0.0,"id":655},{"batb":[[0,1.11,181.82],[1,1.09,55.37],[2,1.03,200]],"ltp":0.0,"tv":0.0,"id":60443}]}]}
{"op":"mcm","clk":"11865246684","pt":1723950966893,"mc":[{"id":"1.231875383","rc":[{"batb":[[0,1.12,71.33],[1,1.11,181.82],[2,1.09,44.3]],"ltp":1.04,"tv":2.0,"id":31379},{"batb":[[0,1.12,71.33],[1,1.11,181.82],[2,1.09,44.3]],"ltp":0.0,"tv":0.0,"id":655},{"batb":[[0,1.12,71.33],[1,1.11,181.82],[2,1.09,55.37]],"ltp":0.0,"tv":0.0,"id":60443}]}]}
{"op":"mcm","clk":"11865303598","pt":1723952767855,"mc":[{"id":"1.231875383","rc":[{"batb":[[0,1.11,181.82],[1,1.09,44.3],[2,1.03,200]],"ltp":1.04,"tv":2.0,"id":31379},{"batb":[[0,1.11,181.82],[1,1.09,44.3],[2,1.03,200]],"ltp":0.0,"tv":0.0,"id":655},{"batb":[[0,1.11,181.82],[1,1.09,55.37],[2,1.03,200]],"ltp":0.0,"tv":0.0,"id":60443}]}]}
{"op":"mcm","clk":"11865307556","pt":1723952888024,"mc":[{"id":"1.231875383","rc":[{"batb":[[0,1.12,71.33],[1,1.11,181.82],[2,1.09,44.3]],"ltp":1.04,"tv":2.0,"id":31379},{"batb":[[0,1.12,71.33],[1,1.11,181.82],[2,1.09,44.3]],"ltp":0.0,"tv":0.0,"id":655},{"batb":[[0,1.12,71.33],[1,1.11,181.82],[2,1.09,55.37]],"ltp":0.0,"tv":0.0,"id":60443}]}]}
{"op":"mcm","clk":"11865385076","pt":1723954688605,"mc":[{"id":"1.231875383","rc":[{"batb":[[0,1.11,181.82],[1,1.09,44.3],[2,1.03,200]],"ltp":1.04,"tv":2.0,"id":31379},{"batb":[[0,1.11,181.82],[1,1.09,44.3],[2,1.03,200]],"ltp":0.0,"tv":0.0,"id":655},{"batb":[[0,1.11,181.82],[1,1.09,55.37],[2,1.03,200]],"ltp":0.0,"tv":0.0,"id":60443}]}]}
{"op":"mcm","clk":"11865387765","pt":1723954793934,"mc":[{"id":"1.231875383","rc":[{"batb":[[0,1.12,71.33],[1,1.11,181.82],[2,1.09,44.3]],"ltp":1.04,"tv":2.0,"id":31379},{"batb":[[0,1.12,71.33],[1,1.11,181.82],[2,1.09,44.3]],"ltp":0.0,"tv":0.0,"id":655},{"batb":[[0,1.12,71.33],[1,1.11,181.82],[2,1.09,55.37]],"ltp":0.0,"tv":0.0,"id":60443}]}]}
{"op":"mcm","clk":"11865438418","pt":1723956594874,"mc":[{"id":"1.231875383","rc":[{"batb":[[0,1.11,181.82],[1,1.09,44.3],[2,1.03,200]],"ltp":1.04,"tv":2.0,"id":31379},{"batb":[[0,1.11,181.82],[1,1.09,44.3],[2,1.03,200]],"ltp":0.0,"tv":0.0,"id":655},{"batb":[[0,1.11,181.82],[1,1.09,55.37],[2,1.03,200]],"ltp":0.0,"tv":0.0,"id":60443}]}]}
{"op":"mcm","clk":"11865440701","pt":1723956683951,"mc":[{"id":"1.231875383","rc":[{"batb":[[0,1.12,71.33],[1,1.11,181.82],[2,1.09,44.3]],"ltp":1.04,"tv":2.0,"id":31379},{"batb":[[0,1.12,71.33],[1,1.11,181.82],[2,1.09,44.3]],"ltp":0.0,"tv":0.0,"id":655},{"batb":[[0,1.12,71.33],[1,1.11,181.82],[2,1.09,55.37]],"ltp":0.0,"tv":0.0,"id":60443}]}]}
{"op":"mcm","clk":"11865475691","pt":1723957708421,"mc":[{"id":"1.231875383","rc":[{"batb":[[0,1.13,44.3],[1,1.12,71.33],[2,1.11,181.82]],"ltp":1.04,"tv":2.0,"id":31379},{"batb":[[0,1.13,44.3],[1,1.12,71.33],[2,1.11,181.82]],"ltp":0.0,"tv":0.0,"id":655},{"batb":[[0,1.13,55.37],[1,1.12,71.33],[2,1.11,181.82]],"ltp":0.0,"tv":0.0,"id":60443}]}]}
{"op":"mcm","clk":"11865501947","pt":1723958484799,"mc":[{"id":"1.231875383","rc":[{"batb":[[1,1.11,181.82],[2,1.03,200]],"ltp":1.04,"tv":2.0,"id":31379},{"batb":[[1,1.11,181.82],[2,1.03,200]],"ltp":0.0,"tv":0.0,"id":655},{"batb":[[1,1.11,181.82],[2,1.03,200]],"ltp":0.0,"tv":0.0,"id":60443}]}]}
{"op":"mcm","clk":"11865504870","pt":1723958568232,"mc":[{"id":"1.231875383","rc":[{"batb":[[0,1.14,61.14],[1,1.13,44.3],[2,1.11,181.82]],"ltp":1.04,"tv":2.0,"id":31379},{"batb":[[0,1.14,61.14],[1,1.13,44.3],[2,1.11,181.82]],"ltp":0.0,"tv":0.0,"id":655},{"batb":[[0,1.14,61.14],[1,1.13,55.37],[2,1.11,181.82]],"ltp":0.0,"tv":0.0,"id":60443}]}]}
{"op":"mcm","clk":"11865575919","pt":1723960368992,"mc":[{"id":"1.231875383","rc":[{"batb":[[0,1.13,44.3],[1,1.11,181.82],[2,1.03,200]],"ltp":1.04,"tv":2.0,"id":31379},{"batb":[[0,1.13,44.3],[1,1.11,181.82],[2,1.03,200]],"ltp":0.0,"tv":0.0,"id":655}]}]}
{"op":"mcm","clk":"11865575925","pt":1723960369198,"mc":[{"id":"1.231875383","rc":[{"batb":[[0,1.13,55.37],[1,1.11,181.82],[2,1.03,200]],"ltp":0.0,"tv":0.0,"id":60443}]}]}
{"op":"mcm","clk":"11865578308","pt":1723960444420,"mc":[{"id":"1.231875383","rc":[{"batb":[[0,1.14,61.14],[1,1.13,44.3],[2,1.11,181.82]],"ltp":1.04,"tv":2.0,"id":31379},{"batb":[[0,1.14,61.14],[1,1.13,44.3],[2,1.11,181.82]],"ltp":0.0,"tv":0.0,"id":655},{"batb":[[0,1.14,61.14],[1,1.13,55.37],[2,1.11,181.82]],"ltp":0.0,"tv":0.0,"id":60443}]}]}
{"op":"mcm","clk":"11865648008","pt":1723962245453,"mc":[{"id":"1.231875383","rc":[{"batb":[[0,1.13,44.3],[1,1.11,181.82],[2,1.03,200]],"ltp":1.04,"tv":2.0,"id":31379},{"batb":[[0,1.13,44.3],[1,1.11,181.82],[2,1.03,200]],"ltp":0.0,"tv":0.0,"id":655},{"batb":[[0,1.13,55.37],[1,1.11,181.82],[2,1.03,200]],"ltp":0.0,"tv":0.0,"id":60443}]}]}
{"op":"mcm","clk":"11865650547","pt":1723962323252,"mc":[{"id":"1.231875383","rc":[{"batb":[[0,1.14,61.14],[1,1.13,44.3],[2,1.11,181.82]],"ltp":1.04,"tv":2.0,"id":31379},{"batb":[[0,1.14,61.14],[1,1.13,44.3],[2,1.11,181.82]],"ltp":0.0,"tv":0.0,"id":655},{"batb":[[0,1.14,61.14],[1,1.13,55.37],[2,1.11,181.82]],"ltp":0.0,"tv":0.0,"id":60443}]}]}
{"op":"mcm","clk":"11865718037","pt":1723964124061,"mc":[{"id":"1.231875383","rc":[{"batb":[[0,1.13,44.3],[1,1.11,181.82],[2,1.03,200]],"ltp":0.0,"tv":0.0,"id":655}]}]}
{"op":"mcm","clk":"11865718048","pt":1723964124267,"mc":[{"id":"1.231875383","rc":[{"batb":[[0,1.13,44.3],[1,1.11,181.82],[2,1.03,200]],"ltp":1.04,"tv":2.0,"id":31379},{"batb":[[0,1.13,55.37],[1,1.11,181.82],[2,1.03,200]],"ltp":0.0,"tv":0.0,"id":60443}]}]}
{"op":"mcm","clk":"11865721198","pt":1723964194006,"mc":[{"id":"1.231875383","rc":[{"batb":[[0,1.14,61.14],[1,1.13,44.3],[2,1.11,181.82]],"ltp":1.04,"tv":2.0,"id":31379},{"batb":[[0,1.14,61.14],[1,1.13,44.3],[2,1.11,181.82]],"ltp":0.0,"tv":0.0,"id":655},{"batb":[[0,1.14,61.14],[1,1.13,55.37],[2,1.11,181.82]],"ltp":0.0,"tv":0.0,"id":60443}]}]}
{"op":"mcm","clk":"11865824343","pt":1723965994873,"mc":[{"id":"1.231875383","rc":[{"batb":[[0,1.13,44.3],[1,1.11,181.82],[2,1.03,200]],"ltp":1.04,"tv":2.0,"id":31379},{"batb":[[0,1.13,44.3],[1,1.11,181.82],[2,1.03,200]],"ltp":0.0,"tv":0.0,"id":655},{"batb":[[0,1.13,55.37],[1,1.11,181.82],[2,1.03,200]],"ltp":0.0,"tv":0.0,"id":60443}]}]}
{"op":"mcm","clk":"11865827765","pt":1723966067375,"mc":[{"id":"1.231875383","rc":[{"batb":[[0,1.14,61.14],[1,1.13,44.3],[2,1.11,181.82]],"ltp":1.04,"tv":2.0,"id":31379},{"batb":[[0,1.14,61.14],[1,1.13,44.3],[2,1.11,181.82]],"ltp":0.0,"tv":0.0,"id":655},{"batb":[[0,1.14,61.14],[1,1.13,55.37],[2,1.11,181.82]],"ltp":0.0,"tv":0.0,"id":60443}]}]}
{"op":"mcm","clk":"11865919045","pt":1723967868016,"mc":[{"id":"1.231875383","rc":[{"batb":[[0,1.13,44.3],[1,1.11,181.82],[2,1.03,200]],"ltp":1.04,"tv":2.0,"id":31379},{"batb":[[0,1.13,44.3],[1,1.11,181.82],[2,1.03,200]],"ltp":0.0,"tv":0.0,"id":655}]}]}
{"op":"mcm","clk":"11865919048","pt":1723967868117,"mc":[{"id":"1.231875383","rc":[{"batb":[[0,1.13,55.37],[1,1.11,181.82],[2,1.03,200]],"ltp":0.0,"tv":0.0,"id":60443}]}]}
{"op":"mcm","clk":"11865926264","pt":1723968022833,"mc":[{"id":"1.231875383","rc":[{"batb":[[0,1.14,61.14],[1,1.13,44.3],[2,1.11,181.82]],"ltp":1.04,"tv":2.0,"id":31379},{"batb":[[0,1.14,61.14],[1,1.13,44.3],[2,1.11,181.82]],"ltp":0.0,"tv":0.0,"id":655},{"batb":[[0,1.14,61.14],[1,1.13,55.37],[2,1.11,181.82]],"ltp":0.0,"tv":0.0,"id":60443}]}]}
{"op":"mcm","clk":"11866038455","pt":1723969823725,"mc":[{"id":"1.231875383","rc":[{"batb":[[0,1.13,44.3],[1,1.11,181.82],[2,1.03,200]],"ltp":1.04,"tv":2.0,"id":31379},{"batb":[[0,1.13,44.3],[1,1.11,181.82],[2,1.03,200]],"ltp":0.0,"tv":0.0,"id":655},{"batb":[[0,1.13,55.37],[1,1.11,181.82],[2,1.03,200]],"ltp":0.0,"tv":0.0,"id":60443}]}]}
{"op":"mcm","clk":"11866039471","pt":1723969839464,"mc":[{"id":"1.231875383","rc":[{"batb":[[0,1.14,61.14],[1,1.13,44.3],[2,1.11,181.82]],"ltp":1.04,"tv":2.0,"id":31379},{"batb":[[0,1.14,61.14],[1,1.13,44.3],[2,1.11,181.82]],"ltp":0.0,"tv":0.0,"id":655},{"batb":[[0,1.14,61.14],[1,1.13,55.37],[2,1.11,181.82]],"ltp":0.0,"tv":0.0,"id":60443}]}]}
{"op":"mcm","clk":"11866045559","pt":1723969933314,"mc":[{"id":"1.231875383","rc":[{"batb":[[0,1.15,44.3],[1,1.14,61.14]],"ltp":1.04,"tv":2.0,"id":31379},{"batb":[[0,1.15,44.3],[1,1.14,61.14]],"ltp":0.0,"tv":0.0,"id":655},{"batb":[[0,1.15,55.37],[1,1.14,61.14]],"ltp":0.0,"tv":0.0,"id":60443}]}]}
{"op":"mcm","clk":"11866055336","pt":1723970069404,"mc":[{"id":"1.231875383","rc":[{"batb":[[0,1.16,40],[1,1.15,44.3],[2,1.14,61.14]],"ltp":1.04,"tv":2.0,"id":31379},{"batb":[[0,1.16,40],[1,1.15,44.3],[2,1.14,61.14]],"ltp":0.0,"tv":0.0,"id":655},{"batb":[[0,1.16,40],[1,1.15,55.37],[2,1.14,61.14]],"ltp":0.0,"tv":0.0,"id":60443}]}]}
{"op":"mcm","clk":"11866206568","pt":1723971640014,"mc":[{"id":"1.231875383","rc":[{"batb":[[2,1.11,181.82]],"ltp":0.0,"tv":0.0,"id":655}]}]}
{"op":"mcm","clk":"11866206613","pt":1723971640285,"mc":[{"id":"1.231875383","rc":[{"batb":[[2,1.11,181.82]],"ltp":1.04,"tv":2.0,"id":31379},{"batb":[[2,1.11,181.82]],"ltp":0.0,"tv":0.0,"id":60443}]}]}
{"op":"mcm","clk":"11866207994","pt":1723971653786,"mc":[{"id":"1.231875383","rc":[{"batb":[[0,1.17,50.35],[1,1.16,40],[2,1.15,44.3]],"ltp":1.04,"tv":2.0,"id":31379},{"batb":[[0,1.17,50.35],[1,1.16,40],[2,1.15,44.3]],"ltp":0.0,"tv":0.0,"id":655},{"batb":[[0,1.17,50.35],[1,1.16,40],[2,1.15,55.37]],"ltp":0.0,"tv":0.0,"id":60443}]}]}
{"op":"mcm","clk":"11866396230","pt":1723973454806,"mc":[{"id":"1.231875383","rc":[{"batb":[[0,1.16,40],[1,1.15,44.3],[2,1.11,181.82]],"ltp":1.04,"tv":2.0,"id":31379},{"batb":[[0,1.16,40],[1,1.15,44.3],[2,1.11,181.82]],"ltp":0.0,"tv":0.0,"id":655},{"batb":[[0,1.16,40],[1,1.15,55.37],[2,1.11,181.82]],"ltp":0.0,"tv":0.0,"id":60443}]}]}
{"op":"mcm","clk":"11866396752","pt":1723973459835,"mc":[{"id":"1.231875383","rc":[{"batb":[[0,1.17,50.35],[1,1.16,40],[2,1.15,44.3]],"ltp":1.04,"tv":2.0,"id":31379},{"batb":[[0,1.17,50.35],[1,1.16,40],[2,1.15,44.3]],"ltp":0.0,"tv":0.0,"id":655},{"batb":[[0,1.17,50.35],[1,1.16,40],[2,1.15,55.37]],"ltp":0.0,"tv":0.0,"id":60443}]}]}
{"op":"mcm","clk":"11866414211","pt":1723973631356,"mc":[{"id":"1.231875383","rc":[{"batb":[[0,1.5,20],[1,1.17,50.35],[2,1.16,40]],"ltp":0.0,"tv":0.0,"id":655}]}]}
{"op":"mcm","clk":"11866415092","pt":1723973640368,"mc":[{"id":"1.231875383","rc":[{"batb":[[0,1.5,20],[1,1.17,50.35],[2,1.16,40]],"ltp":1.04,"tv":2.0,"id":31379}]}]}
{"op":"mcm","clk":"11866415938","pt":1723973648657,"mc":[{"id":"1.231875383","rc":[{"batb":[[0,1.3,20],[1,1.17,50.35],[2,1.16,40]],"ltp":0.0,"tv":0.0,"id":60443}]}]}
{"op":"mcm","clk":"11866591034","pt":1723975260613,"mc":[{"id":"1.231875383","rc":[{"batb":[[1,1.16,40],[2,1.15,44.3]],"ltp":1.04,"tv":2.0,"id":31379},{"batb":[[1,1.16,40],[2,1.15,44.3]],"ltp":0.0,"tv":0.0,"id":655},{"batb":[[1,1.16,40],[2,1.15,55.37]],"ltp":0.0,"tv":0.0,"id":60443}]}]}
{"op":"mcm","clk":"11866612068","pt":1723975435526,"mc":[{"id":"1.231875383","rc":[{"batb":[[0,1.51,16.78],[1,1.5,20],[2,1.16,40]],"ltp":1.04,"tv":2.0,"id":31379},{"batb":[[0,1.51,16.78],[1,1.5,20],[2,1.16,40]],"ltp":0.0,"tv":0.0,"id":655},{"batb":[[0,1.31,27.61],[1,1.3,20],[2,1.16,40]],"ltp":0.0,"tv":0.0,"id":60443}]}]}
{"op":"mcm","clk":"11866866426","pt":1723977236043,"mc":[{"id":"1.231875383","rc":[{"batb":[[0,1.5,20],[1,1.16,40],[2,1.15,44.3]],"ltp":1.04,"tv":2.0,"id":31379},{"batb":[[0,1.5,20],[1,1.16,40],[2,1.15,44.3]],"ltp":0.0,"tv":0.0,"id":655}]}]}
{"op":"mcm","clk":"11866866439","pt":1723977236148,"mc":[{"id":"1.231875383","rc":[{"batb":[[0,1.3,20],[1,1.16,40],[2,1.15,55.37]],"ltp":0.0,"tv":0.0,"id":60443}]}]}
{"op":"mcm","clk":"11866886282","pt":1723977387607,"mc":[{"id":"1.231875383","rc":[{"batb":[[0,1.51,16.78],[1,1.5,20],[2,1.16,40]],"ltp":1.04,"tv":2.0,"id":31379},{"batb":[[0,1.51,16.78],[1,1.5,20],[2,1.16,40]],"ltp":0.0,"tv":0.0,"id":655},{"batb":[[0,1.31,27.61],[1,1.3,20],[2,1.16,40]],"ltp":0.0,"tv":0.0,"id":60443}]}]}
{"op":"mcm","clk":"11867119325","pt":1723979187982,"mc":[{"id":"1.231875383","rc":[{"batb":[[0,1.5,20],[1,1.16,40],[2,1.15,44.3]],"ltp":0.0,"tv":0.0,"id":655}]}]}
{"op":"mcm","clk":"11867119396","pt":1723979188353,"mc":[{"id":"1.231875383","rc":[{"batb":[[0,1.5,20],[1,1.16,40],[2,1.15,44.3]],"ltp":1.04,"tv":2.0,"id":31379},{"batb":[[0,1.3,20],[1,1.16,40],[2,1.15,55.37]],"ltp":0.0,"tv":0.0,"id":60443}]}]}
{"op":"mcm","clk":"11867138150","pt":1723979317316,"mc":[{"id":"1.231875383","rc":[{"batb":[[0,1.51,16.78],[1,1.5,20],[2,1.16,40]],"ltp":1.04,"tv":2.0,"id":31379},{"batb":[[0,1.51,16.78],[1,1.5,20],[2,1.16,40]],"ltp":0.0,"tv":0.0,"id":655},{"batb":[[0,1.31,27.61],[1,1.3,20],[2,1.16,40]],"ltp":0.0,"tv":0.0,"id":60443}]}]}
{"op":"mcm","clk":"11867418671","pt":1723981117887,"mc":[{"id":"1.231875383","rc":[{"batb":[[0,1.5,20],[1,1.16,40],[2,1.15,44.3]],"ltp":0.0,"tv":0.0,"id":655}]}]}
{"op":"mcm","clk":"11867418725","pt":1723981118197,"mc":[{"id":"1.231875383","rc":[{"batb":[[0,1.5,20],[1,1.16,40],[2,1.15,44.3]],"ltp":1.04,"tv":2.0,"id":31379},{"batb":[[0,1.3,20],[1,1.16,40],[2,1.15,55.37]],"ltp":0.0,"tv":0.0,"id":60443}]}]}
{"op":"mcm","clk":"11867432829","pt":1723981210157,"mc":[{"id":"1.231875383","rc":[{"batb":[[0,1.51,16.78],[1,1.5,20],[2,1.16,40]],"ltp":1.04,"tv":2.0,"id":31379},{"batb":[[0,1.51,16.78],[1,1.5,20],[2,1.16,40]],"ltp":0.0,"tv":0.0,"id":655},{"batb":[[0,1.31,27.61],[1,1.3,20],[2,1.16,40]],"ltp":0.0,"tv":0.0,"id":60443}]}]}
{"op":"mcm","clk":"11867702688","pt":1723983010945,"mc":[{"id":"1.231875383","rc":[{"batb":[[0,1.5,20],[1,1.16,40],[2,1.15,44.3]],"ltp":1.04,"tv":2.0,"id":31379},{"batb":[[0,1.5,20],[1,1.16,40],[2,1.15,44.3]],"ltp":0.0,"tv":0.0,"id":655},{"batb":[[0,1.3,20],[1,1.16,40],[2,1.15,55.37]],"ltp":0.0,"tv":0.0,"id":60443}]}]}
{"op":"mcm","clk":"11867714937","pt":1723983088058,"mc":[{"id":"1.231875383","rc":[{"batb":[[0,1.51,16.78],[1,1.5,20],[2,1.16,40]],"ltp":1.04,"tv":2.0,"id":31379},{"batb":[[0,1.51,16.78],[1,1.5,20],[2,1.16,40]],"ltp":0.0,"tv":0.0,"id":655},{"batb":[[0,1.31,27.61],[1,1.3,20],[2,1.16,40]],"ltp":0.0,"tv":0.0,"id":60443}]}]}
{"op":"mcm","clk":"11867993737","pt":1723984888914,"mc":[{"id":"1.231875383","rc":[{"batb":[[0,1.5,20],[1,1.16,40],[2,1.15,44.3]],"ltp":1.04,"tv":2.0,"id":31379},{"batb":[[0,1.5,20],[1,1.16,40],[2,1.15,44.3]],"ltp":0.0,"tv":0.0,"id":655},{"batb":[[0,1.3,20],[1,1.16,40],[2,1.15,55.37]],"ltp":0.0,"tv":0.0,"id":60443}]}]}
{"op":"mcm","clk":"11868002496","pt":1723984942691,"mc":[{"id":"1.231875383","rc":[{"batb":[[0,1.51,16.78],[1,1.5,20],[2,1.16,40]],"ltp":1.04,"tv":2.0,"id":31379},{"batb":[[0,1.51,16.78],[1,1.5,20],[2,1.16,40]],"ltp":0.0,"tv":0.0,"id":655},{"batb":[[0,1.31,27.61],[1,1.3,20],[2,1.16,40]],"ltp":0.0,"tv":0.0,"id":60443}]}]}
{"op":"mcm","clk":"11868285921","pt":1723986743510,"mc":[{"id":"1.231875383","rc":[{"batb":[[0,1.5,20],[1,1.16,40],[2,1.15,44.3]],"ltp":1.04,"tv":2.0,"id":31379},{"batb":[[0,1.5,20],[1,1.16,40],[2,1.15,44.3]],"ltp":0.0,"tv":0.0,"id":655},{"batb":[[0,1.3,20],[1,1.16,40],[2,1.15,55.37]],"ltp":0.0,"tv":0.0,"id":60443}]}]}
{"op":"mcm","clk":"11868290057","pt":1723986767681,"mc":[{"id":"1.231875383","rc":[{"batb":[[0,1.51,16.78],[1,1.5,20],[2,1.16,40]],"ltp":1.04,"tv":2.0,"id":31379},{"batb":[[0,1.51,16.78],[1,1.5,20],[2,1.16,40]],"ltp":0.0,"tv":0.0,"id":655},{"batb":[[0,1.31,27.61],[1,1.3,20],[2,1.16,40]],"ltp":0.0,"tv":0.0,"id":60443}]}]}
{"op":"mcm","clk":"11868587922","pt":1723988550566,"mc":[{"id":"1.231875383","rc":[{"batb":[[0,1.32,55.37],[1,1.31,27.61],[2,1.3,20]],"ltp":0.0,"tv":0.0,"id":60443}]}]}
{"op":"mcm","clk":"11868591370","pt":1723988568556,"mc":[{"id":"1.231875383","rc":[{"batb":[[0,1.5,20],[1,1.16,40],[2,1.11,181.82]],"ltp":1.04,"tv":2.0,"id":31379},{"batb":[[0,1.5,20],[1,1.16,40],[2,1.11,181.82]],"ltp":0.0,"tv":0.0,"id":655},{"batb":[[1,1.3,20],[2,1.16,40]],"ltp":0.0,"tv":0.0,"id":60443}]}]}
{"op":"mcm","clk":"11868623022","pt":1723988715002,"mc":[{"id":"1.231875383","rc":[{"batb":[[0,1.51,16.78],[1,1.5,20],[2,1.16,40]],"ltp":1.04,"tv":2.0,"id":31379},{"batb":[[0,1.51,16.78],[1,1.5,20],[2,1.16,40]],"ltp":0.0,"tv":0.0,"id":655},{"batb":[[0,1.33,25.94],[1,1.32,55.37],[2,1.3,20]],"ltp":0.0,"tv":0.0,"id":60443}]}]}
{"op":"mcm","clk":"11868938081","pt":1723990516019,"mc":[{"id":"1.231875383","rc":[{"batb":[[0,1.5,20],[1,1.16,40],[2,1.11,181.82]],"ltp":1.04,"tv":2.0,"id":31379},{"batb":[[0,1.5,20],[1,1.16,40],[2,1.11,181.82]],"ltp":0.0,"tv":0.0,"id":655},{"batb":[[0,1.32,55.37],[1,1.3,20],[2,1.16,40]],"ltp":0.0,"tv":0.0,"id":60443}]}]}
{"op":"mcm","clk":"11868958847","pt":1723990621588,"mc":[{"id":"1.231875383","rc":[{"batb":[[0,1.51,16.78],[1,1.5,20],[2,1.16,40]],"ltp":1.04,"tv":2.0,"id":31379},{"batb":[[0,1.51,16.78],[1,1.5,20],[2,1.16,40]],"ltp":0.0,"tv":0.0,"id":655},{"batb":[[0,1.33,25.94],[1,1.32,55.37],[2,1.3,20]],"ltp":0.0,"tv":0.0,"id":60443}]}]}
{"op":"mcm","clk":"11869034976","pt":1723991006540,"mc":[{"id":"1.231875383","rc":[{"batb":[[0,1.34,6.03],[1,1.33,25.94],[2,1.32,55.37]],"ltp":0.0,"tv":0.0,"id":60443}]}]}
{"op":"mcm","clk":"11869324342","pt":1723992422862,"mc":[{"id":"1.231875383","rc":[{"batb":[[0,1.5,20],[1,1.16,40],[2,1.11,181.82]],"ltp":1.04,"tv":2.0,"id":31379},{"batb":[[0,1.5,20],[1,1.16,40],[2,1.11,181.82]],"ltp":0.0,"tv":0.0,"id":655},{"batb":[[1,1.32,55.37],[2,1.3,20]],"ltp":0.0,"tv":0.0,"id":60443}]}]}
{"op":"mcm","clk":"11869344370","pt":1723992530171,"mc":[{"id":"1.231875383","rc":[{"batb":[[0,1.51,16.78],[1,1.5,20],[2,1.16,40]],"ltp":1.04,"tv":2.0,"id":31379},{"batb":[[0,1.51,16.78],[1,1.5,20],[2,1.16,40]],"ltp":0.0,"tv":0.0,"id":655},{"batb":[[0,1.35,24.46],[1,1.34,6.03],[2,1.32,55.37]],"ltp":0.0,"tv":0.0,"id":60443}]}]}
{"op":"mcm","clk":"11869514260","pt":1723993505433,"mc":[{"id":"1.231875383","rc":[{"batb":[[1,1.33,6.03]],"ltp":0.0,"tv":0.0,"id":60443}]}]}
{"op":"mcm","clk":"11869697307","pt":1723994330996,"mc":[{"id":"1.231875383","rc":[{"batb":[[0,1.5,20],[1,1.16,40],[2,1.11,181.82]],"ltp":1.04,"tv":2.0,"id":31379},{"batb":[[0,1.5,20],[1,1.16,40],[2,1.11,181.82]],"ltp":0.0,"tv":0.0,"id":655},{"batb":[[0,1.33,6.03],[1,1.32,55.37],[2,1.3,20]],"ltp":0.0,"tv":0.0,"id":60443}]}]}
{"op":"mcm","clk":"11869716163","pt":1723994414805,"mc":[{"id":"1.231875383","rc":[{"batb":[[0,1.51,16.78],[1,1.5,20],[2,1.16,40]],"ltp":1.04,"tv":2.0,"id":31379},{"batb":[[0,1.51,16.78],[1,1.5,20],[2,1.16,40]],"ltp":0.0,"tv":0.0,"id":655},{"batb":[[0,1.34,25.18],[1,1.33,6.03],[2,1.32,55.37]],"ltp":0.0,"tv":0.0,"id":60443}]}]}
{"op":"mcm","clk":"11870034660","pt":1723995984022,"mc":[{"id":"1.231875383","rc":[{"batb":[[0,1.35,6.03],[1,1.34,25.18]],"ltp":0.0,"tv":0.0,"id":60443}]}]}
{"op":"mcm","clk":"11870076829","pt":1723996216527,"mc":[{"id":"1.231875383","rc":[{"batb":[[0,1.5,20],[1,1.16,40],[2,1.11,181.82]],"ltp":1.04,"tv":2.0,"id":31379},{"batb":[[0,1.5,20],[1,1.16,40],[2,1.11,181.82]],"ltp":0.0,"tv":0.0,"id":655},{"batb":[[1,1.32,55.37],[2,1.3,20]],"ltp":0.0,"tv":0.0,"id":60443}]}]}
{"op":"mcm","clk":"11870088868","pt":1723996289550,"mc":[{"id":"1.231875383","rc":[{"batb":[[0,1.51,16.78],[1,1.5,20],[2,1.16,40]],"ltp":1.04,"tv":2.0,"id":31379},{"batb":[[0,1.51,16.78],[1,1.5,20],[2,1.16,40]],"ltp":0.0,"tv":0.0,"id":655},{"batb":[[0,1.36,23.78],[1,1.35,6.03],[2,1.32,55.37]],"ltp":0.0,"tv":0.0,"id":60443}]}]}
{"op":"mcm","clk":"11870474747","pt":1723998091080,"mc":[{"id":"1.231875383","rc":[{"batb":[[0,1.35,6.03],[1,1.32,55.37],[2,1.3,20]],"ltp":0.0,"tv":0.0,"id":60443}]}]}
{"op":"mcm","clk":"11870474854","pt":1723998091395,"mc":[{"id":"1.231875383","rc":[{"batb":[[0,1.5,20],[1,1.16,40],[2,1.11,181.82]],"ltp":1.04,"tv":2.0,"id":31379},{"batb":[[0,1.5,20],[1,1.16,40],[2,1.11,181.82]],"ltp":0.0,"tv":0.0,"id":655}]}]}
{"op":"mcm","clk":"11870479821","pt":1723998111147,"mc":[{"id":"1.231875383","rc":[{"batb":[[0,1.51,16.78],[1,1.5,20],[2,1.16,40]],"ltp":1.04,"tv":2.0,"id":31379},{"batb":[[0,1.51,16.78],[1,1.5,20],[2,1.16,40]],"ltp":0.0,"tv":0.0,"id":655},{"batb":[[0,1.36,23.78],[1,1.35,6.03],[2,1.32,55.37]],"ltp":0.0,"tv":0.0,"id":60443}]}]}
{"op":"mcm","clk":"11870538634","pt":1723998352428,"mc":[{"id":"1.231875383","rc":[{"batb":[[1,1.33,6.03]],"ltp":0.0,"tv":0.0,"id":60443}]}]}
{"op":"mcm","clk":"11870871108","pt":1723999911739,"mc":[{"id":"1.231875383","rc":[{"batb":[[0,1.5,20],[1,1.16,40],[2,1.11,181.82]],"ltp":1.04,"tv":2.0,"id":31379},{"batb":[[0,1.5,20],[1,1.16,40],[2,1.11,181.82]],"ltp":0.0,"tv":0.0,"id":655}]}]}
{"op":"mcm","clk":"11870871175","pt":1723999912117,"mc":[{"id":"1.231875383","rc":[{"batb":[[0,1.33,6.03],[1,1.32,55.37],[2,1.3,20]],"ltp":0.0,"tv":0.0,"id":60443}]}]}
{"op":"mcm","clk":"11870892861","pt":1724000043634,"mc":[{"id":"1.231875383","rc":[{"batb":[[0,1.51,16.78],[1,1.5,20],[2,1.16,40]],"ltp":1.04,"tv":2.0,"id":31379},{"batb":[[0,1.51,16.78],[1,1.5,20],[2,1.16,40]],"ltp":0.0,"tv":0.0,"id":655},{"batb":[[0,1.34,25.18],[1,1.33,6.03],[2,1.32,55.37]],"ltp":0.0,"tv":0.0,"id":60443}]}]}
{"op":"mcm","clk":"11871002951","pt":1724000737017,"mc":[{"id":"1.231875383","rc":[{"batb":[[0,1.35,6.03],[1,1.34,25.18]],"ltp":0.0,"tv":0.0,"id":60443}]}]}
{"op":"mcm","clk":"11871194127","pt":1724001844373,"mc":[{"id":"1.231875383","rc":[{"batb":[[0,1.5,20],[1,1.16,40],[2,1.11,181.82]],"ltp":1.04,"tv":2.0,"id":31379},{"batb":[[0,1.5,20],[1,1.16,40],[2,1.11,181.82]],"ltp":0.0,"tv":0.0,"id":655},{"batb":[[1,1.32,55.37],[2,1.3,20]],"ltp":0.0,"tv":0.0,"id":60443}]}]}
{"op":"mcm","clk":"11871198283","pt":1724001866697,"mc":[{"id":"1.231875383","rc":[{"batb":[[0,1.51,16.78],[1,1.5,20],[2,1.16,40]],"ltp":1.04,"tv":2.0,"id":31379},{"batb":[[0,1.51,16.78],[1,1.5,20],[2,1.16,40]],"ltp":0.0,"tv":0.0,"id":655},{"batb":[[0,1.36,23.78],[1,1.35,6.03],[2,1.32,55.37]],"ltp":0.0,"tv":0.0,"id":60443}]}]}
{"op":"mcm","clk":"11871443412","pt":1724003035299,"mc":[{"id":"1.231875383","rc":[{"batb":[[1,1.33,6.03]],"ltp":0.0,"tv":0.0,"id":60443}]}]}
{"op":"mcm","clk":"11871557501","pt":1724003668575,"mc":[{"id":"1.231875383","rc":[{"batb":[[0,1.5,20],[1,1.16,40],[2,1.11,181.82]],"ltp":1.04,"tv":2.0,"id":31379},{"batb":[[0,1.5,20],[1,1.16,40],[2,1.11,181.82]],"ltp":0.0,"tv":0.0,"id":655},{"batb":[[0,1.33,6.03],[1,1.32,55.37],[2,1.3,20]],"ltp":0.0,"tv":0.0,"id":60443}]}]}
{"op":"mcm","clk":"11871571561","pt":1724003758117,"mc":[{"id":"1.231875383","rc":[{"batb":[[0,1.51,16.78],[1,1.5,20],[2,1.16,40]],"ltp":1.04,"tv":2.0,"id":31379},{"batb":[[0,1.51,16.78],[1,1.5,20],[2,1.16,40]],"ltp":0.0,"tv":0.0,"id":655},{"batb":[[0,1.34,25.18],[1,1.33,6.03],[2,1.32,55.37]],"ltp":0.0,"tv":0.0,"id":60443}]}]}
{"op":"mcm","clk":"11871770869","pt":1724005033191,"mc":[{"id":"1.231875383","rc":[{"batb":[[0,1.35,6.03],[1,1.34,25.18]],"ltp":0.0,"tv":0.0,"id":60443}]}]}
{"op":"mcm","clk":"11871852345","pt":1724005558991,"mc":[{"id":"1.231875383","rc":[{"batb":[[0,1.5,20],[1,1.16,40],[2,1.11,181.82]],"ltp":1.04,"tv":2.0,"id":31379},{"batb":[[0,1.5,20],[1,1.16,40],[2,1.11,181.82]],"ltp":0.0,"tv":0.0,"id":655},{"batb":[[1,1.32,55.37],[2,1.3,20]],"ltp":0.0,"tv":0.0,"id":60443}]}]}
{"op":"mcm","clk":"11871853754","pt":1724005568815,"mc":[{"id":"1.231875383","rc":[{"batb":[[0,1.51,16.78],[1,1.5,20],[2,1.16,40]],"ltp":1.04,"tv":2.0,"id":31379},{"batb":[[0,1.51,16.78],[1,1.5,20],[2,1.16,40]],"ltp":0.0,"tv":0.0,"id":655},{"batb":[[0,1.36,23.78],[1,1.35,6.03],[2,1.32,55.37]],"ltp":0.0,"tv":0.0,"id":60443}]}]}
{"op":"mcm","clk":"11872093438","pt":1724007055234,"mc":[{"id":"1.231875383","rc":[{"batb":[[1,1.33,6.03]],"ltp":0.0,"tv":0.0,"id":60443}]}]}
{"op":"mcm","clk":"11872147168","pt":1724007369596,"mc":[{"id":"1.231875383","rc":[{"batb":[[0,1.5,20],[1,1.16,40],[2,1.11,181.82]],"ltp":1.04,"tv":2.0,"id":31379},{"batb":[[0,1.5,20],[1,1.16,40],[2,1.11,181.82]],"ltp":0.0,"tv":0.0,"id":655},{"batb":[[0,1.33,6.03],[1,1.32,55.37],[2,1.3,20]],"ltp":0.0,"tv":0.0,"id":60443}]}]}
{"op":"mcm","clk":"11872156378","pt":1724007426649,"mc":[{"id":"1.231875383","rc":[{"batb":[[0,1.51,16.78],[1,1.5,20],[2,1.16,40]],"ltp":1.04,"tv":2.0,"id":31379},{"batb":[[0,1.51,16.78],[1,1.5,20],[2,1.16,40]],"ltp":0.0,"tv":0.0,"id":655},{"batb":[[0,1.34,25.18],[1,1.33,6.03],[2,1.32,55.37]],"ltp":0.0,"tv":0.0,"id":60443}]}]}
{"op":"mcm","clk":"11872452225","pt":1724009058077,"mc":[{"id":"1.231875383","rc":[{"batb":[[0,1.35,6.03],[1,1.34,25.18]],"ltp":0.0,"tv":0.0,"id":60443}]}]}
{"op":"mcm","clk":"11872480709","pt":1724009227477,"mc":[{"id":"1.231875383","rc":[{"batb":[[0,1.5,20],[1,1.16,40],[2,1.09,222.22]],"ltp":1.04,"tv":2.0,"id":31379},{"batb":[[0,1.5,20],[1,1.16,40],[2,1.09,222.22]],"ltp":0.0,"tv":0.0,"id":655},{"batb":[[1,1.32,55.37],[2,1.3,20]],"ltp":0.0,"tv":0.0,"id":60443}]}]}
{"op":"mcm","clk":"11872494999","pt":1724009320822,"mc":[{"id":"1.231875383","rc":[{"batb":[[0,1.51,16.78],[1,1.5,20],[2,1.16,40]],"ltp":1.04,"tv":2.0,"id":31379},{"batb":[[0,1.51,16.78],[1,1.5,20],[2,1.16,40]],"ltp":0.0,"tv":0.0,"id":655},{"batb":[[0,1.36,23.78],[1,1.35,6.03],[2,1.32,55.37]],"ltp":0.0,"tv":0.0,"id":60443}]}]}
{"op":"mcm","clk":"11872765878","pt":1724011101548,"mc":[{"id":"1.231875383","rc":[{"batb":[[1,1.33,6.03]],"ltp":0.0,"tv":0.0,"id":60443}]}]}
{"op":"mcm","clk":"11872768811","pt":1724011121819,"mc":[{"id":"1.231875383","rc":[{"batb":[[0,1.5,20],[1,1.16,40],[2,1.09,222.22]],"ltp":1.04,"tv":2.0,"id":31379},{"batb":[[0,1.5,20],[1,1.16,40],[2,1.09,222.22]],"ltp":0.0,"tv":0.0,"id":655},{"batb":[[0,1.33,6.03],[1,1.32,55.37],[2,1.3,20]],"ltp":0.0,"tv":0.0,"id":60443}]}]}
{"op":"mcm","clk":"11872775486","pt":1724011169474,"mc":[{"id":"1.231875383","rc":[{"batb":[[0,1.51,16.78],[1,1.5,20],[2,1.16,40]],"ltp":1.04,"tv":2.0,"id":31379},{"batb":[[0,1.51,16.78],[1,1.5,20],[2,1.16,40]],"ltp":0.0,"tv":0.0,"id":655},{"batb":[[0,1.34,25.18],[1,1.33,6.03],[2,1.32,55.37]],"ltp":0.0,"tv":0.0,"id":60443}]}]}
{"op":"mcm","clk":"11873021189","pt":1724012969940,"mc":[{"id":"1.231875383","rc":[{"batb":[[0,1.51,16.81]],"batl":[[0,95,5.85]],"ltp":1.04,"tv":2.0,"id":31379},{"batb":[[0,1.51,16.81]],"batl":[[0,95,5.85]],"ltp":0.0,"tv":0.0,"id":655},{"batb":[[0,1.33,6.04],[1,1.32,55.44],[2,1.3,20]],"batl":[[0,95,5.85]],"ltp":0.0,"tv":0.0,"id":60443}]}]}
{"op":"mcm","clk":"11873021254","pt":1724012970458,"mc":[{"id":"1.231875383","rc":[{"batb":[[0,1.5,20],[1,1.16,40],[2,1.09,222.22]],"ltp":1.04,"tv":2.0,"id":31379},{"batb":[[0,1.5,20],[1,1.16,40],[2,1.09,222.22]],"ltp":0.0,"tv":0.0,"id":655}]}]}
{"op":"mcm","clk":"11873028010","pt":1724013021010,"mc":[{"id":"1.231875383","rc":[{"batb":[[0,1.51,16.81],[1,1.5,20],[2,1.16,40]],"ltp":1.04,"tv":2.0,"id":31379},{"batb":[[0,1.34,25.22],[1,1.33,6.04],[2,1.32,55.44]],"ltp":0.0,"tv":0.0,"id":60443}]}]}
{"op":"mcm","clk":"11873028019","pt":1724013021108,"mc":[{"id":"1.231875383","rc":[{"batb":[[0,1.51,16.81],[1,1.5,20],[2,1.16,40]],"ltp":0.0,"tv":0.0,"id":655}]}]}
{"op":"mcm","clk":"11873196670","pt":1724014421284,"mc":[{"id":"1.231875383","rc":[{"batb":[[0,1.35,6.04],[1,1.34,25.22]],"ltp":0.0,"tv":0.0,"id":60443}]}]}
{"op":"mcm","clk":"11873231414","pt":1724014822035,"mc":[{"id":"1.231875383","rc":[{"batb":[[0,1.5,20],[1,1.16,40],[2,1.09,222.22]],"ltp":1.04,"tv":2.0,"id":31379},{"batb":[[0,1.5,20],[1,1.16,40],[2,1.09,222.22]],"ltp":0.0,"tv":0.0,"id":655},{"batb":[[0,1.35,6.04],[1,1.32,55.41],[2,1.3,20]],"ltp":0.0,"tv":0.0,"id":60443}]}]}
{"op":"mcm","clk":"11873238867","pt":1724014908528,"mc":[{"id":"1.231875383","rc":[{"batb":[[0,1.51,16.8],[1,1.5,20],[2,1.16,40]],"ltp":1.04,"tv":2.0,"id":31379},{"batb":[[0,1.51,16.8],[1,1.5,20],[2,1.16,40]],"ltp":0.0,"tv":0.0,"id":655},{"batb":[[0,1.36,23.8],[1,1.35,6.04],[2,1.32,55.41]],"ltp":0.0,"tv":0.0,"id":60443}]}]}
{"op":"mcm","clk":"11873397194","pt":1724016708889,"mc":[{"id":"1.231875383","rc":[{"batb":[[0,1.5,20],[1,1.16,40],[2,1.09,222.22]],"ltp":1.04,"tv":2.0,"id":31379}]}]}
{"op":"mcm","clk":"11873397230","pt":1724016709321,"mc":[{"id":"1.231875383","rc":[{"batb":[[0,1.5,20],[1,1.16,40],[2,1.09,222.22]],"ltp":0.0,"tv":0.0,"id":655},{"batb":[[0,1.35,6.04],[1,1.32,55.41],[2,1.3,20]],"ltp":0.0,"tv":0.0,"id":60443}]}]}
{"op":"mcm","clk":"11873405452","pt":1724016808090,"mc":[{"id":"1.231875383","rc":[{"batb":[[0,1.51,16.8],[1,1.5,20],[2,1.16,40]],"ltp":1.04,"tv":2.0,"id":31379},{"batb":[[0,1.51,16.8],[1,1.5,20],[2,1.16,40]],"ltp":0.0,"tv":0.0,"id":655},{"batb":[[0,1.36,23.8],[1,1.35,6.04],[2,1.32,55.41]],"ltp":0.0,"tv":0.0,"id":60443}]}]}
{"op":"mcm","clk":"11873438155","pt":1724017155687,"mc":[{"id":"1.231875383","rc":[{"batb":[[1,1.33,6.04]],"ltp":0.0,"tv":0.0,"id":60443}]}]}
{"op":"mcm","clk":"11873564067","pt":1724018609030,"mc":[{"id":"1.231875383","rc":[{"batb":[[0,1.5,20],[1,1.16,40],[2,1.09,222.22]],"ltp":1.04,"tv":2.0,"id":31379},{"batb":[[0,1.5,20],[1,1.16,40],[2,1.09,222.22]],"ltp":0.0,"tv":0.0,"id":655},{"batb":[[0,1.33,6.03],[1,1.32,55.37],[2,1.3,20]],"ltp":0.0,"tv":0.0,"id":60443}]}]}
{"op":"mcm","clk":"11873567504","pt":1724018655175,"mc":[{"id":"1.231875383","rc":[{"batb":[[0,1.51,16.79],[1,1.5,20],[2,1.16,40]],"ltp":1.04,"tv":2.0,"id":31379},{"batb":[[0,1.51,16.79],[1,1.5,20],[2,1.16,40]],"ltp":0.0,"tv":0.0,"id":655},{"batb":[[0,1.34,25.19],[1,1.33,6.03],[2,1.32,55.37]],"ltp":0.0,"tv":0.0,"id":60443}]}]}
{"op":"mcm","clk":"11873675853","pt":1724019904035,"mc":[{"id":"1.231875383","rc":[{"batb":[[0,1.35,6.03],[1,1.34,25.19]],"ltp":0.0,"tv":0.0,"id":60443}]}]}
{"op":"mcm","clk":"11873714170","pt":1724020457033,"mc":[{"id":"1.231875383","rc":[{"batb":[[0,1.5,20],[1,1.16,40],[2,1.09,222.22]],"ltp":1.04,"tv":2.0,"id":31379},{"batb":[[0,1.5,20],[1,1.16,40],[2,1.09,222.22]],"ltp":0.0,"tv":0.0,"id":655},{"batb":[[1,1.32,55.37],[2,1.3,20]],"ltp":0.0,"tv":0.0,"id":60443}]}]}
{"op":"mcm","clk":"11873715671","pt":1724020478252,"mc":[{"id":"1.231875383","rc":[{"batb":[[0,1.51,16.79],[1,1.5,20],[2,1.16,40]],"ltp":1.04,"tv":2.0,"id":31379},{"batb":[[0,1.51,16.79],[1,1.5,20],[2,1.16,40]],"ltp":0.0,"tv":0.0,"id":655},{"batb":[[0,1.36,23.79],[1,1.35,6.03],[2,1.32,55.37]],"ltp":0.0,"tv":0.0,"id":60443}]}]}
{"op":"mcm","clk":"11873822566","pt":1724022279870,"mc":[{"id":"1.231875383","rc":[{"batb":[[0,1.5,20],[1,1.16,40],[2,1.09,222.22]],"ltp":1.04,"tv":2.0,"id":31379},{"batb":[[0,1.5,20],[1,1.16,40],[2,1.09,222.22]],"ltp":0.0,"tv":0.0,"id":655},{"batb":[[0,1.35,6.03],[1,1.32,55.37],[2,1.3,20]],"ltp":0.0,"tv":0.0,"id":60443}]}]}
{"op":"mcm","clk":"11873829142","pt":1724022405023,"mc":[{"id":"1.231875383","rc":[{"batb":[[0,1.51,16.79],[1,1.5,20],[2,1.16,40]],"ltp":1.04,"tv":2.0,"id":31379},{"batb":[[0,1.51,16.79],[1,1.5,20],[2,1.16,40]],"ltp":0.0,"tv":0.0,"id":655},{"batb":[[0,1.36,23.79],[1,1.35,6.03],[2,1.32,55.37]],"ltp":0.0,"tv":0.0,"id":60443}]}]}
{"op":"mcm","clk":"11873842430","pt":1724022634817,"mc":[{"id":"1.231875383","rc":[{"batb":[[1,1.33,6.03]],"ltp":0.0,"tv":0.0,"id":60443}]}]}
{"op":"mcm","clk":"11873922553","pt":1724024206041,"mc":[{"id":"1.231875383","rc":[{"batb":[[0,1.5,20],[1,1.16,40],[2,1.09,222.22]],"ltp":1.04,"tv":2.0,"id":31379},{"batb":[[0,1.5,20],[1,1.16,40],[2,1.09,222.22]],"ltp":0.0,"tv":0.0,"id":655},{"batb":[[0,1.33,6.03],[1,1.32,55.37],[2,1.3,20]],"ltp":0.0,"tv":0.0,"id":60443}]}]}
{"op":"mcm","clk":"11873927286","pt":1724024290434,"mc":[{"id":"1.231875383","rc":[{"batb":[[0,1.51,16.79],[1,1.5,20],[2,1.16,40]],"ltp":1.04,"tv":2.0,"id":31379},{"batb":[[0,1.51,16.79],[1,1.5,20],[2,1.16,40]],"ltp":0.0,"tv":0.0,"id":655},{"batb":[[0,1.34,25.19],[1,1.33,6.03],[2,1.32,55.37]],"ltp":0.0,"tv":0.0,"id":60443}]}]}
{"op":"mcm","clk":"11873993933","pt":1724025381884,"mc":[{"id":"1.231875383","rc":[{"batb":[[0,1.35,6.03],[1,1.34,25.19]],"ltp":0.0,"tv":0.0,"id":60443}]}]}
{"op":"mcm","clk":"11874026596","pt":1724026092074,"mc":[{"id":"1.231875383","rc":[{"batb":[[0,1.5,20],[1,1.16,40],[2,1.09,222.22]],"ltp":1.04,"tv":2.0,"id":31379},{"batb":[[0,1.5,20],[1,1.16,40],[2,1.09,222.22]],"ltp":0.0,"tv":0.0,"id":655},{"batb":[[1,1.32,55.36],[2,1.3,20]],"ltp":0.0,"tv":0.0,"id":60443}]}]}
{"op":"mcm","clk":"11874029090","pt":1724026141813,"mc":[{"id":"1.231875383","rc":[{"batb":[[0,1.51,16.79],[1,1.5,20],[2,1.16,40]],"ltp":1.04,"tv":2.0,"id":31379},{"batb":[[0,1.51,16.79],[1,1.5,20],[2,1.16,40]],"ltp":0.0,"tv":0.0,"id":655},{"batb":[[0,1.36,23.78],[1,1.35,6.03],[2,1.32,55.36]],"ltp":0.0,"tv":0.0,"id":60443}]}]}
{"op":"mcm","clk":"11874120326","pt":1724027943522,"mc":[{"id":"1.231875383","rc":[{"batb":[[0,1.5,20],[1,1.16,40],[2,1.09,222.22]],"ltp":1.04,"tv":2.0,"id":31379},{"batb":[[0,1.5,20],[1,1.16,40],[2,1.09,222.22]],"ltp":0.0,"tv":0.0,"id":655},{"batb":[[0,1.35,6.03],[1,1.32,55.36],[2,1.3,20]],"ltp":0.0,"tv":0.0,"id":60443}]}]}
{"op":"mcm","clk":"11874121884","pt":1724027972960,"mc":[{"id":"1.231875383","rc":[{"batb":[[0,1.51,16.79],[1,1.5,20],[2,1.16,40]],"ltp":1.04,"tv":2.0,"id":31379},{"batb":[[0,1.51,16.79],[1,1.5,20],[2,1.16,40]],"ltp":0.0,"tv":0.0,"id":655},{"batb":[[0,1.36,23.78],[1,1.35,6.03],[2,1.32,55.36]],"ltp":0.0,"tv":0.0,"id":60443}]}]}
{"op":"mcm","clk":"11874126699","pt":1724028071731,"mc":[{"id":"1.231875383","rc":[{"batb":[[1,1.33,6.03]],"ltp":0.0,"tv":0.0,"id":60443}]}]}
{"op":"mcm","clk":"11874208230","pt":1724029773536,"mc":[{"id":"1.231875383","rc":[{"batb":[[0,1.5,20],[1,1.16,40],[2,1.09,222.22]],"ltp":1.04,"tv":2.0,"id":31379},{"batb":[[0,1.5,20],[1,1.16,40],[2,1.09,222.22]],"ltp":0.0,"tv":0.0,"id":655},{"batb":[[0,1.33,6.03],[1,1.32,55.39],[2,1.3,20]],"ltp":0.0,"tv":0.0,"id":60443}]}]}
{"op":"mcm","clk":"11874209063","pt":1724029790390,"mc":[{"id":"1.231875383","rc":[{"batb":[[0,1.51,16.8],[1,1.5,20],[2,1.16,40]],"ltp":1.04,"tv":2.0,"id":31379},{"batb":[[0,1.51,16.8],[1,1.5,20],[2,1.16,40]],"ltp":0.0,"tv":0.0,"id":655},{"batb":[[0,1.34,25.19],[1,1.33,6.03],[2,1.32,55.39]],"ltp":0.0,"tv":0.0,"id":60443}]}]}
{"op":"mcm","clk":"11874264504","pt":1724030741300,"mc":[{"id":"1.231875383","rc":[{"batb":[[0,1.35,6.03],[1,1.34,25.19]],"ltp":0.0,"tv":0.0,"id":60443}]}]}
{"op":"mcm","clk":"11874298719","pt":1724031590818,"mc":[{"id":"1.231875383","rc":[{"batb":[[0,1.5,20],[1,1.16,40],[2,1.09,222.22]],"ltp":1.04,"tv":2.0,"id":31379},{"batb":[[0,1.5,20],[1,1.16,40],[2,1.09,222.22]],"ltp":0.0,"tv":0.0,"id":655},{"batb":[[1,1.32,55.39],[2,1.3,20]],"ltp":0.0,"tv":0.0,"id":60443}]}]}
{"op":"mcm","clk":"11874303283","pt":1724031699234,"mc":[{"id":"1.231875383","rc":[{"batb":[[0,1.51,16.8],[1,1.5,20],[2,1.16,40]],"ltp":1.04,"tv":2.0,"id":31379},{"batb":[[0,1.51,16.8],[1,1.5,20],[2,1.16,40]],"ltp":0.0,"tv":0.0,"id":655},{"batb":[[0,1.36,23.79],[1,1.35,6.03],[2,1.32,55.39]],"ltp":0.0,"tv":0.0,"id":60443}]}]}
{"op":"mcm","clk":"11874359881","pt":1724033393927,"mc":[{"id":"1.231875383","rc":[{"batb":[[0,1.51,16.79]],"ltp":1.04,"tv":2.0,"id":31379},{"batb":[[0,1.51,16.79]],"ltp":0.0,"tv":0.0,"id":655},{"batb":[[0,1.36,23.78],[1,1.33,6.03],[2,1.32,55.36]],"ltp":0.0,"tv":0.0,"id":60443}]}]}
{"op":"mcm","clk":"11874363119","pt":1724033500783,"mc":[{"id":"1.231875383","rc":[{"batb":[[0,1.5,20],[1,1.16,40],[2,1.09,222.22]],"ltp":1.04,"tv":2.0,"id":31379},{"batb":[[0,1.5,20],[1,1.16,40],[2,1.09,222.22]],"ltp":0.0,"tv":0.0,"id":655},{"batb":[[0,1.33,6.03],[1,1.32,55.36],[2,1.3,20]],"ltp":0.0,"tv":0.0,"id":60443}]}]}
{"op":"mcm","clk":"11874365843","pt":1724033594404,"mc":[{"id":"1.231875383","rc":[{"batb":[[0,1.51,16.79],[1,1.5,20],[2,1.16,40]],"ltp":1.04,"tv":2.0,"id":31379},{"batb":[[0,1.51,16.79],[1,1.5,20],[2,1.16,40]],"ltp":0.0,"tv":0.0,"id":655},{"batb":[[0,1.34,25.18],[1,1.33,6.03],[2,1.32,55.36]],"ltp":0.0,"tv":0.0,"id":60443}]}]}
{"op":"mcm","clk":"11874437563","pt":1724035394946,"mc":[{"id":"1.231875383","rc":[{"batb":[[0,1.5,20],[1,1.16,40],[2,1.09,222.22]],"ltp":1.04,"tv":2.0,"id":31379},{"batb":[[0,1.33,6.03],[1,1.32,55.36],[2,1.3,20]],"ltp":0.0,"tv":0.0,"id":60443}]}]}
{"op":"mcm","clk":"11874437571","pt":1724035395152,"mc":[{"id":"1.231875383","rc":[{"batb":[[0,1.5,20],[1,1.16,40],[2,1.09,222.22]],"ltp":0.0,"tv":0.0,"id":655}]}]}
{"op":"mcm","clk":"11874440554","pt":1724035486191,"mc":[{"id":"1.231875383","rc":[{"batb":[[0,1.51,16.79],[1,1.5,20],[2,1.16,40]],"ltp":1.04,"tv":2.0,"id":31379},{"batb":[[0,1.51,16.79],[1,1.5,20],[2,1.16,40]],"ltp":0.0,"tv":0.0,"id":655},{"batb":[[0,1.34,25.18],[1,1.33,6.03],[2,1.32,55.36]],"ltp":0.0,"tv":0.0,"id":60443}]}]}
{"op":"mcm","clk":"11874461317","pt":1724036038057,"mc":[{"id":"1.231875383","rc":[{"batb":[[1,1.32,55.36],[2,1.3,20]],"ltp":0.0,"tv":0.0,"id":60443}]}]}
{"op":"mcm","clk":"11874461324","pt":1724036038160,"mc":[{"id":"1.231875383","rc":[{"batb":[[0,1.35,6.03],[1,1.34,25.18],[2,1.32,55.36]],"ltp":0.0,"tv":0.0,"id":60443}]}]}
{"op":"mcm","clk":"11874511934","pt":1724037287743,"mc":[{"id":"1.231875383","rc":[{"batb":[[0,1.5,20],[1,1.16,40],[2,1.09,222.22]],"ltp":1.04,"tv":2.0,"id":31379},{"batb":[[0,1.5,20],[1,1.16,40],[2,1.09,222.22]],"ltp":0.0,"tv":0.0,"id":655},{"batb":[[0,1.35,6.03],[1,1.32,55.35],[2,1.3,20]],"ltp":0.0,"tv":0.0,"id":60443}]}]}
{"op":"mcm","clk":"11874514549","pt":1724037362765,"mc":[{"id":"1.231875383","rc":[{"batb":[[0,1.51,16.78],[1,1.5,20],[2,1.16,40]],"ltp":1.04,"tv":2.0,"id":31379},{"batb":[[0,1.51,16.78],[1,1.5,20],[2,1.16,40]],"ltp":0.0,"tv":0.0,"id":655},{"batb":[[0,1.36,23.78],[1,1.35,6.03],[2,1.32,55.35]],"ltp":0.0,"tv":0.0,"id":60443}]}]}
{"op":"mcm","clk":"11874573044","pt":1724038697609,"mc":[{"id":"1.231875383","rc":[{"batb":[[1,1.33,6.03]],"ltp":0.0,"tv":0.0,"id":60443}]}]}
{"op":"mcm","clk":"11874596067","pt":1724039162996,"mc":[{"id":"1.231875383","rc":[{"batb":[[0,1.5,20],[1,1.16,40],[2,1.09,222.22]],"ltp":0.0,"tv":0.0,"id":655}]}]}
{"op":"mcm","clk":"11874596085","pt":1724039163302,"mc":[{"id":"1.231875383","rc":[{"batb":[[0,1.5,20],[1,1.16,40],[2,1.09,222.22]],"ltp":1.04,"tv":2.0,"id":31379},{"batb":[[0,1.33,6.03],[1,1.32,55.35],[2,1.3,20]],"ltp":0.0,"tv":0.0,"id":60443}]}]}
{"op":"mcm","clk":"11874598990","pt":1724039225064,"mc":[{"id":"1.231875383","rc":[{"batb":[[0,1.51,16.78],[1,1.5,20],[2,1.16,40]],"ltp":1.04,"tv":2.0,"id":31379},{"batb":[[0,1.51,16.78],[1,1.5,20],[2,1.16,40]],"ltp":0.0,"tv":0.0,"id":655},{"batb":[[0,1.34,25.18],[1,1.33,6.03],[2,1.32,55.35]],"ltp":0.0,"tv":0.0,"id":60443}]}]}
{"op":"mcm","clk":"11874667786","pt":1724040774912,"mc":[{"id":"1.231875383","rc":[{"batb":[[0,1.51,16.8]],"ltp":1.04,"tv":2.0,"id":31379},{"batb":[[0,1.51,16.8]],"ltp":0.0,"tv":0.0,"id":655},{"batb":[[0,1.34,25.19],[1,1.33,6.03],[2,1.32,55.39]],"ltp":0.0,"tv":0.0,"id":60443}]}]}
{"op":"mcm","clk":"11874684992","pt":1724041025626,"mc":[{"id":"1.231875383","rc":[{"batb":[[0,1.5,20],[1,1.16,40],[2,1.09,222.22]],"ltp":1.04,"tv":2.0,"id":31379},{"batb":[[0,1.5,20],[1,1.16,40],[2,1.09,222.22]],"ltp":0.0,"tv":0.0,"id":655},{"batb":[[0,1.33,6.03],[1,1.32,55.39],[2,1.3,20]],"ltp":0.0,"tv":0.0,"id":60443}]}]}
{"op":"mcm","clk":"11874687712","pt":1724041085588,"mc":[{"id":"1.231875383","rc":[{"batb":[[0,1.51,16.8],[1,1.5,20],[2,1.16,40]],"ltp":1.04,"tv":2.0,"id":31379},{"batb":[[0,1.51,16.8],[1,1.5,20],[2,1.16,40]],"ltp":0.0,"tv":0.0,"id":655},{"batb":[[0,1.34,25.19],[1,1.33,6.03],[2,1.32,55.39]],"ltp":0.0,"tv":0.0,"id":60443}]}]}
{"op":"mcm","clk":"11874699267","pt":1724041327075,"mc":[{"id":"1.231875383","rc":[{"batb":[[1,1.32,55.39],[2,1.3,20]],"ltp":0.0,"tv":0.0,"id":60443}]}]}
{"op":"mcm","clk":"11874699273","pt":1724041327177,"mc":[{"id":"1.231875383","rc":[{"batb":[[0,1.35,6.03],[1,1.34,25.19],[2,1.32,55.39]],"ltp":0.0,"tv":0.0,"id":60443}]}]}
{"op":"mcm","clk":"11874760269","pt":1724042885864,"mc":[{"id":"1.231875383","rc":[{"batb":[[0,1.5,20],[1,1.16,40],[2,1.09,222.22]],"ltp":1.04,"tv":2.0,"id":31379},{"batb":[[0,1.5,20],[1,1.16,40],[2,1.09,222.22]],"ltp":0.0,"tv":0.0,"id":655}]}]}
{"op":"mcm","clk":"11874760340","pt":1724042887756,"mc":[{"id":"1.231875383","rc":[{"batb":[[1,1.32,55.39],[2,1.3,20]],"ltp":0.0,"tv":0.0,"id":60443}]}]}
{"op":"mcm","clk":"11874762424","pt":1724042934018,"mc":[{"id":"1.231875383","rc":[{"batb":[[0,1.51,16.8],[1,1.5,20],[2,1.16,40]],"ltp":1.04,"tv":2.0,"id":31379},{"batb":[[0,1.51,16.8],[1,1.5,20],[2,1.16,40]],"ltp":0.0,"tv":0.0,"id":655},{"batb":[[0,1.36,23.79],[1,1.35,6.03],[2,1.32,55.39]],"ltp":0.0,"tv":0.0,"id":60443}]}]}
{"op":"mcm","clk":"11874798882","pt":1724043995863,"mc":[{"id":"1.231875383","rc":[{"batb":[[0,1.51,16.8]],"ltp":1.04,"tv":2.0,"id":31379},{"batb":[[0,1.51,16.8]],"ltp":0.0,"tv":0.0,"id":655},{"batb":[[0,1.36,23.8],[1,1.33,6.03],[2,1.32,55.4]],"ltp":0.0,"tv":0.0,"id":60443}]}]}
{"op":"mcm","clk":"11874820679","pt":1724044734818,"mc":[{"id":"1.231875383","rc":[{"batb":[[0,1.5,20],[1,1.16,40],[2,1.09,222.22]],"ltp":1.04,"tv":2.0,"id":31379},{"batb":[[0,1.5,20],[1,1.16,40],[2,1.09,222.22]],"ltp":0.0,"tv":0.0,"id":655},{"batb":[[0,1.33,6.03],[1,1.32,55.4],[2,1.3,20]],"ltp":0.0,"tv":0.0,"id":60443}]}]}
{"op":"mcm","clk":"11874821898","pt":1724044778186,"mc":[{"id":"1.231875383","rc":[{"batb":[[0,1.51,16.8],[1,1.5,20],[2,1.16,40]],"ltp":1.04,"tv":2.0,"id":31379},{"batb":[[0,1.51,16.8],[1,1.5,20],[2,1.16,40]],"ltp":0.0,"tv":0.0,"id":655},{"batb":[[0,1.34,25.2],[1,1.33,6.03],[2,1.32,55.4]],"ltp":0.0,"tv":0.0,"id":60443}]}]}
{"op":"mcm","clk":"11874885384","pt":1724046579959,"mc":[{"id":"1.231875383","rc":[{"batb":[[0,1.33,6.03],[1,1.32,55.4],[2,1.3,20]],"ltp":0.0,"tv":0.0,"id":60443}]}]}
{"op":"mcm","clk":"11874885397","pt":1724046580321,"mc":[{"id":"1.231875383","rc":[{"batb":[[0,1.5,20],[1,1.16,40],[2,1.09,222.22]],"ltp":1.04,"tv":2.0,"id":31379},{"batb":[[0,1.5,20],[1,1.16,40],[2,1.09,222.22]],"ltp":0.0,"tv":0.0,"id":655}]}]}
{"op":"mcm","clk":"11874886360","pt":1724046618880,"mc":[{"id":"1.231875383","rc":[{"batb":[[0,1.51,16.8],[1,1.5,20],[2,1.16,40]],"ltp":1.04,"tv":2.0,"id":31379},{"batb":[[0,1.51,16.8],[1,1.5,20],[2,1.16,40]],"ltp":0.0,"tv":0.0,"id":655},{"batb":[[0,1.34,25.2],[1,1.33,6.03],[2,1.32,55.4]],"ltp":0.0,"tv":0.0,"id":60443}]}]}
{"op":"mcm","clk":"11874887974","pt":1724046678446,"mc":[{"id":"1.231875383","rc":[{"batb":[[0,1.35,6.03],[1,1.34,25.2]],"ltp":0.0,"tv":0.0,"id":60443}]}]}
{"op":"mcm","clk":"11874942671","pt":1724048420050,"mc":[{"id":"1.231875383","rc":[{"batb":[[0,1.5,20],[1,1.16,40],[2,1.09,222.22]],"ltp":0.0,"tv":0.0,"id":655},{"batb":[[0,1.35,6.02],[1,1.32,55.39],[2,1.3,20]],"ltp":0.0,"tv":0.0,"id":60443}]}]}
{"op":"mcm","clk":"11874942678","pt":1724048420208,"mc":[{"id":"1.231875383","rc":[{"batb":[[0,1.5,20],[1,1.16,40],[2,1.09,222.22]],"ltp":1.04,"tv":2.0,"id":31379}]}]}
{"op":"mcm","clk":"11874943797","pt":1724048458982,"mc":[{"id":"1.231875383","rc":[{"batb":[[0,1.51,16.8],[1,1.5,20],[2,1.16,40]],"ltp":1.04,"tv":2.0,"id":31379},{"batb":[[0,1.51,16.8],[1,1.5,20],[2,1.16,40]],"ltp":0.0,"tv":0.0,"id":655},{"batb":[[0,1.36,23.8],[1,1.35,6.02],[2,1.32,55.39]],"ltp":0.0,"tv":0.0,"id":60443}]}]}
{"op":"mcm","clk":"11874969510","pt":1724049347504,"mc":[{"id":"1.231875383","rc":[{"batb":[[1,1.33,6.02]],"ltp":0.0,"tv":0.0,"id":60443}]}]}
{"op":"mcm","clk":"11875001137","pt":1724050259689,"mc":[{"id":"1.231875383","rc":[{"batb":[[0,1.5,20],[1,1.16,40],[2,1.09,222.22]],"ltp":1.04,"tv":2.0,"id":31379},{"batb":[[0,1.5,20],[1,1.16,40],[2,1.09,222.22]],"ltp":0.0,"tv":0.0,"id":655},{"batb":[[0,1.33,6.02],[1,1.32,55.39],[2,1.3,20]],"ltp":0.0,"tv":0.0,"id":60443}]}]}
{"op":"mcm","clk":"11875002420","pt":1724050293053,"mc":[{"id":"1.231875383","rc":[{"batb":[[0,1.51,16.8],[1,1.5,20],[2,1.16,40]],"ltp":1.04,"tv":2.0,"id":31379},{"batb":[[0,1.51,16.8],[1,1.5,20],[2,1.16,40]],"ltp":0.0,"tv":0.0,"id":655},{"batb":[[0,1.34,25.2],[1,1.33,6.02],[2,1.32,55.39]],"ltp":0.0,"tv":0.0,"id":60443}]}]}
{"op":"mcm","clk":"11875051610","pt":1724051574925,"mc":[{"id":"1.231875383","rc":[{"batb":[[0,1.51,16.79]],"ltp":1.04,"tv":2.0,"id":31379},{"batb":[[0,1.51,16.79]],"ltp":0.0,"tv":0.0,"id":655},{"batb":[[0,1.34,25.18],[2,1.32,55.37]],"ltp":0.0,"tv":0.0,"id":60443}]}]}
{"op":"mcm","clk":"11875074051","pt":1724052041040,"mc":[{"id":"1.231875383","rc":[{"batb":[[0,1.35,6.02],[1,1.34,25.18]],"ltp":0.0,"tv":0.0,"id":60443}]}]}
{"op":"mcm","clk":"11875075673","pt":1724052093901,"mc":[{"id":"1.231875383","rc":[{"batb":[[0,1.5,20],[1,1.16,40],[2,1.09,222.22]],"ltp":1.04,"tv":2.0,"id":31379},{"batb":[[0,1.5,20],[1,1.16,40],[2,1.09,222.22]],"ltp":0.0,"tv":0.0,"id":655},{"batb":[[1,1.32,55.37],[2,1.3,20]],"ltp":0.0,"tv":0.0,"id":60443}]}]}
{"op":"mcm","clk":"11875076688","pt":1724052123673,"mc":[{"id":"1.231875383","rc":[{"batb":[[0,1.51,16.79],[1,1.5,20],[2,1.16,40]],"ltp":1.04,"tv":2.0,"id":31379},{"batb":[[0,1.51,16.79],[1,1.5,20],[2,1.16,40]],"ltp":0.0,"tv":0.0,"id":655},{"batb":[[0,1.36,23.78],[1,1.35,6.02],[2,1.32,55.37]],"ltp":0.0,"tv":0.0,"id":60443}]}]}
{"op":"mcm","clk":"11875142884","pt":1724053924900,"mc":[{"id":"1.231875383","rc":[{"batb":[[0,1.5,20],[1,1.16,40],[2,1.09,222.22]],"ltp":1.04,"tv":2.0,"id":31379},{"batb":[[0,1.5,20],[1,1.16,40],[2,1.09,222.22]],"ltp":0.0,"tv":0.0,"id":655},{"batb":[[0,1.35,6.02],[1,1.32,55.37],[2,1.3,20]],"ltp":0.0,"tv":0.0,"id":60443}]}]}
{"op":"mcm","clk":"11875143680","pt":1724053954099,"mc":[{"id":"1.231875383","rc":[{"batb":[[0,1.51,16.79],[1,1.5,20],[2,1.16,40]],"ltp":1.04,"tv":2.0,"id":31379},{"batb":[[0,1.51,16.79],[1,1.5,20],[2,1.16,40]],"ltp":0.0,"tv":0.0,"id":655},{"batb":[[0,1.36,23.78],[1,1.35,6.02],[2,1.32,55.37]],"ltp":0.0,"tv":0.0,"id":60443}]}]}
{"op":"mcm","clk":"11875171438","pt":1724054695315,"mc":[{"id":"1.231875383","rc":[{"batb":[[0,1.36,23.78],[1,1.33,6.02]],"ltp":0.0,"tv":0.0,"id":60443}]}]}
{"op":"mcm","clk":"11875218704","pt":1724055756046,"mc":[{"id":"1.231875383","rc":[{"batb":[[0,1.5,20],[1,1.16,40],[2,1.09,222.22]],"ltp":0.0,"tv":0.0,"id":655},{"batb":[[0,1.33,6.02],[1,1.32,55.37],[2,1.3,20]],"ltp":0.0,"tv":0.0,"id":60443}]}]}
{"op":"mcm","clk":"11875218716","pt":1724055756203,"mc":[{"id":"1.231875383","rc":[{"batb":[[0,1.5,20],[1,1.16,40],[2,1.09,222.22]],"ltp":1.04,"tv":2.0,"id":31379}]}]}
{"op":"mcm","clk":"11875219795","pt":1724055779443,"mc":[{"id":"1.231875383","rc":[{"batb":[[0,1.51,16.79],[1,1.5,20],[2,1.16,40]],"ltp":1.04,"tv":2.0,"id":31379},{"batb":[[0,1.51,16.79],[1,1.5,20],[2,1.16,40]],"ltp":0.0,"tv":0.0,"id":655},{"batb":[[0,1.34,25.18],[1,1.33,6.02],[2,1.32,55.37]],"ltp":0.0,"tv":0.0,"id":60443}]}]}
{"op":"mcm","clk":"11875296612","pt":1724057207544,"mc":[{"id":"1.231875383","rc":[{"batb":[[0,1.35,40],[1,1.34,25.18],[2,1.33,6.02]],"ltp":0.0,"tv":0.0,"id":60443}]}]}
{"op":"mcm","clk":"11875302505","pt":1724057339717,"mc":[{"id":"1.231875383","rc":[{"batb":[[0,1.36,6.02],[1,1.35,40],[2,1.34,25.18]],"ltp":0.0,"tv":0.0,"id":60443}]}]}
{"op":"mcm","clk":"11875315152","pt":1724057579917,"mc":[{"id":"1.231875383","rc":[{"batb":[[0,1.5,20],[1,1.16,40],[2,1.09,222.22]],"ltp":0.0,"tv":0.0,"id":655},{"batb":[[2,1.32,55.37]],"ltp":0.0,"tv":0.0,"id":60443}]}]}
{"op":"mcm","clk":"11875315165","pt":1724057580121,"mc":[{"id":"1.231875383","rc":[{"batb":[[0,1.5,20],[1,1.16,40],[2,1.09,222.22]],"ltp":1.04,"tv":2.0,"id":31379}]}]}
{"op":"mcm","clk":"11875315879","pt":1724057594054,"mc":[{"id":"1.231875383","rc":[{"batb":[[0,1.51,16.79],[1,1.5,20],[2,1.16,40]],"ltp":1.04,"tv":2.0,"id":31379},{"batb":[[0,1.51,16.79],[1,1.5,20],[2,1.16,40]],"ltp":0.0,"tv":0.0,"id":655},{"batb":[[0,1.37,23.14],[1,1.36,6.02],[2,1.35,40]],"ltp":0.0,"tv":0.0,"id":60443}]}]}
{"op":"mcm","clk":"11875320196","pt":1724057685062,"mc":[{"id":"1.231875383","rc":[{"batb":[[2,1.32,55.37]],"ltp":0.0,"tv":0.0,"id":60443}]}]}
{"op":"mcm","clk":"11875320203","pt":1724057685164,"mc":[{"id":"1.231875383","rc":[{"batb":[[0,1.38,40],[1,1.37,23.14],[2,1.36,6.02]],"ltp":0.0,"tv":0.0,"id":60443}]}]}
{"op":"mcm","clk":"11875406642","pt":1724059394988,"mc":[{"id":"1.231875383","rc":[{"batb":[[0,1.51,16.77]],"ltp":1.04,"tv":2.0,"id":31379},{"batb":[[0,1.51,16.77]],"ltp":0.0,"tv":0.0,"id":655},{"batb":[[1,1.36,6.02],[2,1.32,55.31]],"ltp":0.0,"tv":0.0,"id":60443}]}]}
{"op":"mcm","clk":"11875406657","pt":1724059395245,"mc":[{"id":"1.231875383","rc":[{"batb":[[0,1.5,20],[1,1.16,40],[2,1.09,222.22]],"ltp":1.04,"tv":2.0,"id":31379},{"batb":[[0,1.5,20],[1,1.16,40],[2,1.09,222.22]],"ltp":0.0,"tv":0.0,"id":655}]}]}
{"op":"mcm","clk":"11875407420","pt":1724059408873,"mc":[{"id":"1.231875383","rc":[{"batb":[[0,1.51,16.77],[1,1.5,20],[2,1.16,40]],"ltp":1.04,"tv":2.0,"id":31379},{"batb":[[0,1.51,16.77],[1,1.5,20],[2,1.16,40]],"ltp":0.0,"tv":0.0,"id":655},{"batb":[[0,1.39,21.93],[1,1.38,40],[2,1.36,6.02]],"ltp":0.0,"tv":0.0,"id":60443}]}]}
{"op":"mcm","clk":"11875442889","pt":1724059999069,"mc":[{"id":"1.231875383","rc":[{"batb":[[0,1.39,27.95],[2,1.32,55.31]],"ltp":0.0,"tv":0.0,"id":60443}]}]}
{"op":"mcm","clk":"11875507593","pt":1724061209960,"mc":[{"id":"1.231875383","rc":[{"batb":[[0,1.5,20],[1,1.16,40],[2,1.09,222.22]],"ltp":0.0,"tv":0.0,"id":655},{"batb":[[0,1.39,6.02]],"ltp":0.0,"tv":0.0,"id":60443}]}]}
{"op":"mcm","clk":"11875507602","pt":1724061210165,"mc":[{"id":"1.231875383","rc":[{"batb":[[0,1.5,20],[1,1.16,40],[2,1.09,222.22]],"ltp":1.04,"tv":2.0,"id":31379}]}]}
{"op":"mcm","clk":"11875507897","pt":1724061215898,"mc":[{"id":"1.231875383","rc":[{"batb":[[0,1.51,16.77],[1,1.5,20],[2,1.16,40]],"ltp":1.04,"tv":2.0,"id":31379},{"batb":[[0,1.51,16.77],[1,1.5,20],[2,1.16,40]],"ltp":0.0,"tv":0.0,"id":655},{"batb":[[0,1.4,21.38],[1,1.39,6.02],[2,1.38,40]],"ltp":0.0,"tv":0.0,"id":60443}]}]}
{"op":"mcm","clk":"11875581604","pt":1724062374926,"mc":[{"id":"1.231875383","rc":[{"batb":[[0,1.51,16.78]],"ltp":1.04,"tv":2.0,"id":31379},{"batb":[[0,1.51,16.78]],"ltp":0.0,"tv":0.0,"id":655},{"batb":[[0,1.4,21.39],[1,1.39,6.02]],"ltp":0.0,"tv":0.0,"id":60443}]}]}
{"op":"mcm","clk":"11875627524","pt":1724063016729,"mc":[{"id":"1.231875383","rc":[{"batb":[[0,1.5,20],[1,1.16,40],[2,1.09,222.22]],"ltp":1.04,"tv":2.0,"id":31379},{"batb":[[0,1.5,20],[1,1.16,40],[2,1.09,222.22]],"ltp":0.0,"tv":0.0,"id":655},{"batb":[[0,1.39,6.02],[1,1.38,40],[2,1.32,55.33]],"ltp":0.0,"tv":0.0,"id":60443}]}]}
{"op":"mcm","clk":"11875633498","pt":1724063121233,"mc":[{"id":"1.231875383","rc":[{"batb":[[0,1.51,16.78],[1,1.5,20],[2,1.16,40]],"ltp":1.04,"tv":2.0,"id":31379},{"batb":[[0,1.51,16.78],[1,1.5,20],[2,1.16,40]],"ltp":0.0,"tv":0.0,"id":655},{"batb":[[0,1.4,21.39],[1,1.39,6.02],[2,1.38,40]],"ltp":0.0,"tv":0.0,"id":60443}]}]}
{"op":"mcm","clk":"11875750054","pt":1724064921831,"mc":[{"id":"1.231875383","rc":[{"batb":[[0,1.5,20],[1,1.16,40],[2,1.09,222.22]],"ltp":1.04,"tv":2.0,"id":31379},{"batb":[[0,1.5,20],[1,1.16,40],[2,1.09,222.22]],"ltp":0.0,"tv":0.0,"id":655},{"batb":[[0,1.39,6.02],[1,1.38,40],[2,1.32,55.33]],"ltp":0.0,"tv":0.0,"id":60443}]}]}
{"op":"mcm","clk":"11875752452","pt":1724064962197,"mc":[{"id":"1.231875383","rc":[{"batb":[[0,1.51,16.78],[1,1.5,20],[2,1.16,40]],"ltp":1.04,"tv":2.0,"id":31379},{"batb":[[0,1.51,16.78],[1,1.5,20],[2,1.16,40]],"ltp":0.0,"tv":0.0,"id":655},{"batb":[[0,1.4,21.39],[1,1.39,6.02],[2,1.38,40]],"ltp":0.0,"tv":0.0,"id":60443}]}]}
{"op":"mcm","clk":"11875867458","pt":1724066762706,"mc":[{"id":"1.231875383","rc":[{"batb":[[0,1.5,20],[1,1.16,40],[2,1.09,222.22]],"batl":[[0,95,5.85]],"ltp":1.04,"tv":2.0,"id":31379},{"batb":[[0,1.5,20],[1,1.16,40],[2,1.09,222.22]],"batl":[[0,95,5.85]],"ltp":0.0,"tv":0.0,"id":655},{"batb":[[0,1.39,6.03],[1,1.38,40],[2,1.32,55.4]],"batl":[[0,95,5.85]],"ltp":0.0,"tv":0.0,"id":60443}]}]}
{"op":"mcm","clk":"11875869351","pt":1724066800429,"mc":[{"id":"1.231875383","rc":[{"batb":[[0,1.51,16.8],[1,1.5,20],[2,1.16,40]],"ltp":1.04,"tv":2.0,"id":31379},{"batb":[[0,1.51,16.8],[1,1.5,20],[2,1.16,40]],"ltp":0.0,"tv":0.0,"id":655},{"batb":[[0,1.4,21.42],[1,1.39,6.03],[2,1.38,40]],"ltp":0.0,"tv":0.0,"id":60443}]}]}
{"op":"mcm","clk":"11875984757","pt":1724068601786,"mc":[{"id":"1.231875383","rc":[{"batb":[[0,1.5,20],[1,1.16,40],[2,1.09,222.22]],"ltp":1.04,"tv":2.0,"id":31379},{"batb":[[0,1.5,20],[1,1.16,40],[2,1.09,222.22]],"ltp":0.0,"tv":0.0,"id":655},{"batb":[[0,1.39,6.03],[1,1.38,40],[2,1.32,55.4]],"ltp":0.0,"tv":0.0,"id":60443}]}]}
{"op":"mcm","clk":"11875987002","pt":1724068635667,"mc":[{"id":"1.231875383","rc":[{"batb":[[0,1.51,16.8],[1,1.5,20],[2,1.16,40]],"ltp":1.04,"tv":2.0,"id":31379},{"batb":[[0,1.51,16.8],[1,1.5,20],[2,1.16,40]],"ltp":0.0,"tv":0.0,"id":655},{"batb":[[0,1.4,21.42],[1,1.39,6.03],[2,1.38,40]],"ltp":0.0,"tv":0.0,"id":60443}]}]}
{"op":"mcm","clk":"11876101164","pt":1724070436973,"mc":[{"id":"1.231875383","rc":[{"batb":[[0,1.5,20],[1,1.16,40],[2,1.09,222.22]],"ltp":1.04,"tv":2.0,"id":31379},{"batb":[[0,1.5,20],[1,1.16,40],[2,1.09,222.22]],"ltp":0.0,"tv":0.0,"id":655},{"batb":[[0,1.39,6.03],[1,1.38,40],[2,1.32,55.4]],"ltp":0.0,"tv":0.0,"id":60443}]}]}
{"op":"mcm","clk":"11876102481","pt":1724070463334,"mc":[{"id":"1.231875383","rc":[{"batb":[[0,1.51,16.8],[1,1.5,20],[2,1.16,40]],"ltp":1.04,"tv":2.0,"id":31379},{"batb":[[0,1.51,16.8],[1,1.5,20],[2,1.16,40]],"ltp":0.0,"tv":0.0,"id":655},{"batb":[[0,1.4,21.42],[1,1.39,6.03],[2,1.38,40]],"ltp":0.0,"tv":0.0,"id":60443}]}]}
{"op":"mcm","clk":"11876211190","pt":1724072264062,"mc":[{"id":"1.231875383","rc":[{"batb":[[0,1.5,20],[1,1.16,40],[2,1.09,222.22]],"ltp":1.04,"tv":2.0,"id":31379},{"batb":[[0,1.5,20],[1,1.16,40],[2,1.09,222.22]],"ltp":0.0,"tv":0.0,"id":655},{"batb":[[0,1.39,6.03],[1,1.38,40],[2,1.32,55.4]],"ltp":0.0,"tv":0.0,"id":60443}]}]}
{"op":"mcm","clk":"11876212663","pt":1724072287881,"mc":[{"id":"1.231875383","rc":[{"batb":[[0,1.51,16.8],[1,1.5,20],[2,1.16,40]],"ltp":1.04,"tv":2.0,"id":31379},{"batb":[[0,1.51,16.8],[1,1.5,20],[2,1.16,40]],"ltp":0.0,"tv":0.0,"id":655},{"batb":[[0,1.4,21.42],[1,1.39,6.03],[2,1.38,40]],"ltp":0.0,"tv":0.0,"id":60443}]}]}
{"op":"mcm","clk":"11876274715","pt":1724073174911,"mc":[{"id":"1.231875383","rc":[{"batb":[[0,1.51,16.8]],"ltp":1.04,"tv":2.0,"id":31379},{"batb":[[0,1.51,16.8]],"ltp":0.0,"tv":0.0,"id":655},{"batb":[[0,1.4,21.42],[1,1.39,6.03]],"ltp":0.0,"tv":0.0,"id":60443}]}]}
{"op":"mcm","clk":"11876345047","pt":1724074088993,"mc":[{"id":"1.231875383","rc":[{"batb":[[0,1.5,20],[1,1.16,40],[2,1.09,222.22]],"ltp":1.04,"tv":2.0,"id":31379},{"batb":[[0,1.5,20],[1,1.16,40],[2,1.09,222.22]],"ltp":0.0,"tv":0.0,"id":655},{"batb":[[0,1.39,6.03],[1,1.38,40],[2,1.32,55.4]],"ltp":0.0,"tv":0.0,"id":60443}]}]}
{"op":"mcm","clk":"11876346310","pt":1724074107704,"mc":[{"id":"1.231875383","rc":[{"batb":[[0,1.51,16.8],[1,1.5,20],[2,1.16,40]],"ltp":1.04,"tv":2.0,"id":31379},{"batb":[[0,1.51,16.8],[1,1.5,20],[2,1.16,40]],"ltp":0.0,"tv":0.0,"id":655},{"batb":[[0,1.4,21.42],[1,1.39,6.03],[2,1.38,40]],"ltp":0.0,"tv":0.0,"id":60443}]}]}
{"op":"mcm","clk":"11876421960","pt":1724075057527,"mc":[{"id":"1.231875383","rc":[{"batb":[[0,1.4,22.32]],"ltp":0.0,"tv":0.0,"id":60443}]}]}
{"op":"mcm","clk":"11876485629","pt":1724075909061,"mc":[{"id":"1.231875383","rc":[{"batb":[[0,1.5,20],[1,1.16,40],[2,1.09,222.22]],"ltp":1.04,"tv":2.0,"id":31379},{"batb":[[0,1.5,20],[1,1.16,40],[2,1.09,222.22]],"ltp":0.0,"tv":0.0,"id":655},{"batb":[[0,1.39,6.93],[1,1.38,40],[2,1.32,55.4]],"ltp":0.0,"tv":0.0,"id":60443}]}]}
{"op":"mcm","clk":"11876487037","pt":1724075930323,"mc":[{"id":"1.231875383","rc":[{"batb":[[0,1.51,16.8],[1,1.5,20],[2,1.16,40]],"ltp":1.04,"tv":2.0,"id":31379},{"batb":[[0,1.51,16.8],[1,1.5,20],[2,1.16,40]],"ltp":0.0,"tv":0.0,"id":655},{"batb":[[0,1.4,22.32],[1,1.39,6.03],[2,1.38,40]],"ltp":0.0,"tv":0.0,"id":60443}]}]}
{"op":"mcm","clk":"11876531100","pt":1724076495923,"mc":[{"id":"1.231875383","rc":[{"batb":[[0,1.51,16.79]],"ltp":1.04,"tv":2.0,"id":31379},{"batb":[[0,1.51,16.79]],"ltp":0.0,"tv":0.0,"id":655},{"batb":[[0,1.41,40.9],[1,1.4,21.41],[2,1.39,6.03]],"ltp":0.0,"tv":0.0,"id":60443}]}]}
{"op":"mcm","clk":"11876618301","pt":1724077730999,"mc":[{"id":"1.231875383","rc":[{"batb":[[0,1.5,20],[1,1.16,40],[2,1.09,222.22]],"ltp":1.04,"tv":2.0,"id":31379},{"batb":[[0,1.5,20],[1,1.16,40],[2,1.09,222.22]],"ltp":0.0,"tv":0.0,"id":655},{"batb":[[1,1.39,6.03],[2,1.32,55.39]],"ltp":0.0,"tv":0.0,"id":60443}]}]}
{"op":"mcm","clk":"11876618461","pt":1724077733235,"mc":[{"id":"1.231875383","rc":[{"batb":[[0,1.51,16.79],[1,1.5,20],[2,1.16,40]],"ltp":1.04,"tv":2.0,"id":31379},{"batb":[[0,1.51,16.79],[1,1.5,20],[2,1.16,40]],"ltp":0.0,"tv":0.0,"id":655},{"batb":[[0,1.42,21.29],[1,1.41,40],[2,1.39,6.03]],"ltp":0.0,"tv":0.0,"id":60443}]}]}
{"op":"mcm","clk":"11876716669","pt":1724078966619,"mc":[{"id":"1.231875383","rc":[{"batb":[[0,1.42,27.32],[2,1.32,55.39]],"ltp":0.0,"tv":0.0,"id":60443}]}]}
{"op":"mcm","clk":"11876759411","pt":1724079534712,"mc":[{"id":"1.231875383","rc":[{"batb":[[0,1.5,20],[1,1.16,40],[2,1.09,222.22]],"ltp":1.04,"tv":2.0,"id":31379},{"batb":[[0,1.5,20],[1,1.16,40],[2,1.09,222.22]],"ltp":0.0,"tv":0.0,"id":655},{"batb":[[0,1.42,6.92]],"ltp":0.0,"tv":0.0,"id":60443}]}]}
{"op":"mcm","clk":"11876770170","pt":1724079683472,"mc":[{"id":"1.231875383","rc":[{"batb":[[0,1.51,16.79],[1,1.5,20],[2,1.16,40]],"ltp":1.04,"tv":2.0,"id":31379},{"batb":[[0,1.51,16.79],[1,1.5,20],[2,1.16,40]],"ltp":0.0,"tv":0.0,"id":655},{"batb":[[0,1.43,20.81],[1,1.42,6.01],[2,1.41,40]],"ltp":0.0,"tv":0.0,"id":60443}]}]}
{"op":"mcm","clk":"11876863988","pt":1724080867480,"mc":[{"id":"1.231875383","rc":[{"batb":[[0,1.44,56.28],[1,1.43,19.92],[2,1.42,6.01]],"ltp":0.0,"tv":0.0,"id":60443}]}]}
{"op":"mcm","clk":"11876864388","pt":1724080872794,"mc":[{"id":"1.231875383","rc":[{"batb":[[0,1.44,38.39]],"ltp":0.0,"tv":0.0,"id":60443}]}]}
{"op":"mcm","clk":"11876919554","pt":1724081483895,"mc":[{"id":"1.231875383","rc":[{"batb":[[1,1.42,6.01],[2,1.41,40]],"ltp":0.0,"tv":0.0,"id":60443}]}]}
{"op":"mcm","clk":"11876919584","pt":1724081484304,"mc":[{"id":"1.231875383","rc":[{"batb":[[0,1.5,20],[1,1.16,40],[2,1.09,222.22]],"ltp":1.04,"tv":2.0,"id":31379},{"batb":[[0,1.5,20],[1,1.16,40],[2,1.09,222.22]],"ltp":0.0,"tv":0.0,"id":655}]}]}
{"op":"mcm","clk":"11876932031","pt":1724081631559,"mc":[{"id":"1.231875383","rc":[{"batb":[[0,1.51,16.79],[1,1.5,20],[2,1.16,40]],"ltp":1.04,"tv":2.0,"id":31379},{"batb":[[0,1.51,16.79],[1,1.5,20],[2,1.16,40]],"ltp":0.0,"tv":0.0,"id":655},{"batb":[[0,1.45,19.93],[1,1.44,37.49],[2,1.42,6.01]],"ltp":0.0,"tv":0.0,"id":60443}]}]}
{"op":"mcm","clk":"11876940022","pt":1724081717653,"mc":[{"id":"1.231875383","rc":[{"batb":[[0,1.45,25.94],[2,1.41,40]],"ltp":0.0,"tv":0.0,"id":60443}]}]}
{"op":"mcm","clk":"11877094744","pt":1724083433366,"mc":[{"id":"1.231875383","rc":[{"batb":[[0,1.5,20],[1,1.16,40],[2,1.09,222.22]],"ltp":1.04,"tv":2.0,"id":31379},{"batb":[[0,1.5,20],[1,1.16,40],[2,1.09,222.22]],"ltp":0.0,"tv":0.0,"id":655},{"batb":[[0,1.45,6.91],[1,1.44,37.52]],"ltp":0.0,"tv":0.0,"id":60443}]}]}
{"op":"mcm","clk":"11877094958","pt":1724083435691,"mc":[{"id":"1.231875383","rc":[{"batb":[[0,1.51,16.8],[1,1.5,20],[2,1.16,40]],"ltp":1.04,"tv":2.0,"id":31379},{"batb":[[0,1.51,16.8],[1,1.5,20],[2,1.16,40]],"ltp":0.0,"tv":0.0,"id":655},{"batb":[[0,1.46,19.53],[1,1.45,6.02],[2,1.44,37.52]],"ltp":0.0,"tv":0.0,"id":60443}]}]}
{"op":"mcm","clk":"11877269233","pt":1724085236998,"mc":[{"id":"1.231875383","rc":[{"batb":[[0,1.5,20],[1,1.16,40],[2,1.09,222.22]],"ltp":1.04,"tv":2.0,"id":31379}]}]}
{"op":"mcm","clk":"11877269265","pt":1724085237313,"mc":[{"id":"1.231875383","rc":[{"batb":[[0,1.5,20],[1,1.16,40],[2,1.09,222.22]],"ltp":0.0,"tv":0.0,"id":655},{"batb":[[0,1.45,6.91],[1,1.44,37.52],[2,1.41,40]],"ltp":0.0,"tv":0.0,"id":60443}]}]}
{"op":"mcm","clk":"11877273240","pt":1724085282837,"mc":[{"id":"1.231875383","rc":[{"batb":[[0,1.51,16.8],[1,1.5,20],[2,1.16,40]],"ltp":1.04,"tv":2.0,"id":31379},{"batb":[[0,1.51,16.8],[1,1.5,20],[2,1.16,40]],"ltp":0.0,"tv":0.0,"id":655},{"batb":[[0,1.46,19.53],[1,1.45,6.02],[2,1.44,37.52]],"ltp":0.0,"tv":0.0,"id":60443}]}]}
{"op":"mcm","clk":"11877438354","pt":1724087083928,"mc":[{"id":"1.231875383","rc":[{"batb":[[0,1.5,20],[1,1.16,40],[2,1.09,222.22]],"ltp":1.04,"tv":2.0,"id":31379},{"batb":[[0,1.5,20],[1,1.16,40],[2,1.09,222.22]],"ltp":0.0,"tv":0.0,"id":655},{"batb":[[0,1.45,6.91],[1,1.44,37.53],[2,1.41,40]],"ltp":0.0,"tv":0.0,"id":60443}]}]}
{"op":"mcm","clk":"11877441328","pt":1724087110296,"mc":[{"id":"1.231875383","rc":[{"batb":[[0,1.51,16.81],[1,1.5,20],[2,1.16,40]],"ltp":1.04,"tv":2.0,"id":31379},{"batb":[[0,1.51,16.81],[1,1.5,20],[2,1.16,40]],"ltp":0.0,"tv":0.0,"id":655},{"batb":[[0,1.46,19.53],[1,1.45,6.02],[2,1.44,37.53]],"ltp":0.0,"tv":0.0,"id":60443}]}]}
{"op":"mcm","clk":"11877646067","pt":1724088912075,"mc":[{"id":"1.231875383","rc":[{"batb":[[0,1.5,20],[1,1.16,40],[2,1.09,222.22]],"ltp":1.04,"tv":2.0,"id":31379},{"batb":[[0,1.5,20],[1,1.16,40],[2,1.09,222.22]],"ltp":0.0,"tv":0.0,"id":655},{"batb":[[0,1.45,6.91],[1,1.44,37.53],[2,1.41,40]],"ltp":0.0,"tv":0.0,"id":60443}]}]}
{"op":"mcm","clk":"11877646104","pt":1724088912502,"mc":[{"id":"1.231875383","rc":[{"batb":[[0,1.51,16.81],[1,1.5,20],[2,1.16,40]],"ltp":1.04,"tv":2.0,"id":31379},{"batb":[[0,1.51,16.81],[1,1.5,20],[2,1.16,40]],"ltp":0.0,"tv":0.0,"id":655},{"batb":[[0,1.46,19.53],[1,1.45,6.02],[2,1.44,37.53]],"ltp":0.0,"tv":0.0,"id":60443}]}]}
{"op":"mcm","clk":"11877856850","pt":1724090581536,"mc":[{"id":"1.231875383","rc":[{"batb":[[0,1.51,17.7]],"ltp":1.04,"tv":2.0,"id":31379},{"batb":[[0,1.51,16.8]],"ltp":0.0,"tv":0.0,"id":655},{"batb":[[0,1.46,19.52],[1,1.45,6.01],[2,1.44,37.52]],"ltp":0.0,"tv":0.0,"id":60443}]}]}
{"op":"mcm","clk":"11877874880","pt":1724090714075,"mc":[{"id":"1.231875383","rc":[{"batb":[[0,1.5,20.9],[1,1.16,40],[2,1.09,222.22]],"ltp":1.04,"tv":2.0,"id":31379}]}]}
{"op":"mcm","clk":"11877874913","pt":1724090714275,"mc":[{"id":"1.231875383","rc":[{"batb":[[0,1.5,20],[1,1.16,40],[2,1.09,222.22]],"ltp":0.0,"tv":0.0,"id":655},{"batb":[[0,1.45,6.91],[1,1.44,37.52],[2,1.41,40]],"ltp":0.0,"tv":0.0,"id":60443}]}]}
{"op":"mcm","clk":"11877896757","pt":1724090857928,"mc":[{"id":"1.231875383","rc":[{"batb":[[0,1.51,17.7],[1,1.5,20],[2,1.16,40]],"ltp":1.04,"tv":2.0,"id":31379},{"batb":[[0,1.51,16.8],[1,1.5,20],[2,1.16,40]],"ltp":0.0,"tv":0.0,"id":655},{"batb":[[0,1.46,19.52],[1,1.45,6.01],[2,1.44,37.52]],"ltp":0.0,"tv":0.0,"id":60443}]}]}
{"op":"mcm","clk":"11878173117","pt":1724092660021,"mc":[{"id":"1.231875383","rc":[{"batb":[[0,1.5,20.9],[1,1.16,40],[2,1.09,222.22]],"ltp":1.04,"tv":2.0,"id":31379},{"batb":[[0,1.5,20],[1,1.16,40],[2,1.09,222.22]],"ltp":0.0,"tv":0.0,"id":655},{"batb":[[0,1.45,6.91],[1,1.44,37.52],[2,1.41,40]],"ltp":0.0,"tv":0.0,"id":60443}]}]}
{"op":"mcm","clk":"11878188641","pt":1724092760253,"mc":[{"id":"1.231875383","rc":[{"batb":[[0,1.51,17.7],[1,1.5,20],[2,1.16,40]],"ltp":1.04,"tv":2.0,"id":31379},{"batb":[[0,1.51,16.8],[1,1.5,20],[2,1.16,40]],"ltp":0.0,"tv":0.0,"id":655},{"batb":[[0,1.46,19.52],[1,1.45,6.01],[2,1.44,37.52]],"ltp":0.0,"tv":0.0,"id":60443}]}]}
{"op":"mcm","clk":"11878412557","pt":1724094560864,"mc":[{"id":"1.231875383","rc":[{"batb":[[0,1.5,20.9],[1,1.16,40],[2,1.09,222.22]],"ltp":1.04,"tv":2.0,"id":31379},{"batb":[[0,1.5,20],[1,1.16,40],[2,1.09,222.22]],"ltp":0.0,"tv":0.0,"id":655},{"batb":[[0,1.46,19.53],[1,1.45,6.01],[2,1.44,37.53]],"ltp":0.0,"tv":0.0,"id":60443}]}]}
{"op":"mcm","clk":"11878412576","pt":1724094561092,"mc":[{"id":"1.231875383","rc":[{"batb":[[0,1.45,6.91],[1,1.44,37.53],[2,1.41,40]],"ltp":0.0,"tv":0.0,"id":60443}]}]}
{"op":"mcm","clk":"11878420254","pt":1724094629177,"mc":[{"id":"1.231875383","rc":[{"batb":[[0,1.51,17.7],[1,1.5,20],[2,1.16,40]],"ltp":1.04,"tv":2.0,"id":31379},{"batb":[[0,1.51,16.81],[1,1.5,20],[2,1.16,40]],"ltp":0.0,"tv":0.0,"id":655},{"batb":[[0,1.46,19.53],[1,1.45,6.01],[2,1.44,37.53]],"ltp":0.0,"tv":0.0,"id":60443}]}]}
{"op":"mcm","clk":"11878627924","pt":1724096430997,"mc":[{"id":"1.231875383","rc":[{"batb":[[0,1.5,20.9],[1,1.16,40],[2,1.09,222.22]],"ltp":1.04,"tv":2.0,"id":31379},{"batb":[[0,1.45,6.91],[1,1.44,37.53],[2,1.41,40]],"ltp":0.0,"tv":0.0,"id":60443}]}]}
{"op":"mcm","clk":"11878627945","pt":1724096431204,"mc":[{"id":"1.231875383","rc":[{"batb":[[0,1.5,20],[1,1.16,40],[2,1.09,222.22]],"ltp":0.0,"tv":0.0,"id":655}]}]}
{"op":"mcm","clk":"11878635554","pt":1724096501768,"mc":[{"id":"1.231875383","rc":[{"batb":[[0,1.51,17.7],[1,1.5,20],[2,1.16,40]],"ltp":1.04,"tv":2.0,"id":31379},{"batb":[[0,1.51,16.81],[1,1.5,20],[2,1.16,40]],"ltp":0.0,"tv":0.0,"id":655},{"batb":[[0,1.46,19.53],[1,1.45,6.01],[2,1.44,37.53]],"ltp":0.0,"tv":0.0,"id":60443}]}]}
{"op":"mcm","clk":"11878793589","pt":1724098303823,"mc":[{"id":"1.231875383","rc":[{"batb":[[0,1.5,20.9],[1,1.16,40],[2,1.09,222.22]],"ltp":1.04,"tv":2.0,"id":31379},{"batb":[[0,1.5,20],[1,1.16,40],[2,1.09,222.22]],"ltp":0.0,"tv":0.0,"id":655},{"batb":[[0,1.45,6.91],[1,1.44,37.54],[2,1.41,40]],"ltp":0.0,"tv":0.0,"id":60443}]}]}
{"op":"mcm","clk":"11878800063","pt":1724098386391,"mc":[{"id":"1.231875383","rc":[{"batb":[[0,1.51,17.71],[1,1.5,20],[2,1.16,40]],"ltp":1.04,"tv":2.0,"id":31379},{"batb":[[0,1.51,16.81],[1,1.5,20],[2,1.16,40]],"ltp":0.0,"tv":0.0,"id":655},{"batb":[[0,1.46,19.54],[1,1.45,6.01],[2,1.44,37.54]],"ltp":0.0,"tv":0.0,"id":60443}]}]}
{"op":"mcm","clk":"11878927030","pt":1724100187734,"mc":[{"id":"1.231875383","rc":[{"batb":[[0,1.5,20.9],[1,1.16,40],[2,1.09,222.22]],"ltp":1.04,"tv":2.0,"id":31379},{"batb":[[0,1.5,20],[1,1.16,40],[2,1.09,222.22]],"ltp":0.0,"tv":0.0,"id":655},{"batb":[[0,1.45,6.91],[1,1.44,37.54],[2,1.41,40]],"ltp":0.0,"tv":0.0,"id":60443}]}]}
{"op":"mcm","clk":"11878928755","pt":1724100220471,"mc":[{"id":"1.231875383","rc":[{"batb":[[0,1.51,17.71],[1,1.5,20],[2,1.16,40]],"ltp":1.04,"tv":2.0,"id":31379},{"batb":[[0,1.51,16.81],[1,1.5,20],[2,1.16,40]],"ltp":0.0,"tv":0.0,"id":655},{"batb":[[0,1.46,19.54],[1,1.45,6.01],[2,1.44,37.54]],"ltp":0.0,"tv":0.0,"id":60443}]}]}
{"op":"mcm","clk":"11879007531","pt":1724102021956,"mc":[{"id":"1.231875383","rc":[{"batb":[[0,1.5,20.9],[1,1.16,40],[2,1.09,222.22]],"ltp":1.04,"tv":2.0,"id":31379},{"batb":[[0,1.5,20],[1,1.16,40],[2,1.09,222.22]],"ltp":0.0,"tv":0.0,"id":655},{"batb":[[0,1.45,6.91],[1,1.44,37.54],[2,1.41,40]],"ltp":0.0,"tv":0.0,"id":60443}]}]}
{"op":"mcm","clk":"11879013302","pt":1724102168935,"mc":[{"id":"1.231875383","rc":[{"batb":[[0,1.51,17.71],[1,1.5,20],[2,1.16,40]],"ltp":1.04,"tv":2.0,"id":31379},{"batb":[[0,1.51,16.82],[1,1.5,20],[2,1.16,40]],"ltp":0.0,"tv":0.0,"id":655},{"batb":[[0,1.46,19.54],[1,1.45,6.01],[2,1.44,37.54]],"ltp":0.0,"tv":0.0,"id":60443}]}]}
{"op":"mcm","clk":"11879104934","pt":1724103970836,"mc":[{"id":"1.231875383","rc":[{"batb":[[0,1.5,20.9],[1,1.16,40],[2,1.09,222.22]],"ltp":1.04,"tv":2.0,"id":31379},{"batb":[[0,1.5,20],[1,1.16,40],[2,1.09,222.22]],"ltp":0.0,"tv":0.0,"id":655},{"batb":[[0,1.45,6.91],[1,1.44,37.54],[2,1.41,40]],"ltp":0.0,"tv":0.0,"id":60443}]}]}
{"op":"mcm","clk":"11879112225","pt":1724104090659,"mc":[{"id":"1.231875383","rc":[{"batb":[[0,1.51,17.71],[1,1.5,20],[2,1.16,40]],"ltp":1.04,"tv":2.0,"id":31379},{"batb":[[0,1.51,16.82],[1,1.5,20],[2,1.16,40]],"ltp":0.0,"tv":0.0,"id":655},{"batb":[[0,1.46,19.54],[1,1.45,6.01],[2,1.44,37.54]],"ltp":0.0,"tv":0.0,"id":60443}]}]}
{"op":"mcm","clk":"11879195090","pt":1724105574927,"mc":[{"id":"1.231875383","rc":[{"batb":[[0,1.51,17.71]],"ltp":1.04,"tv":2.0,"id":31379},{"batb":[[0,1.51,16.82]],"ltp":0.0,"tv":0.0,"id":655},{"batb":[[0,1.46,19.54],[2,1.44,37.55]],"ltp":0.0,"tv":0.0,"id":60443}]}]}
{"op":"mcm","clk":"11879217264","pt":1724105891086,"mc":[{"id":"1.231875383","rc":[{"batb":[[0,1.5,20.9],[1,1.16,40],[2,1.09,222.22]],"ltp":1.04,"tv":2.0,"id":31379},{"batb":[[0,1.5,20],[1,1.16,40],[2,1.09,222.22]],"ltp":0.0,"tv":0.0,"id":655}]}]}
{"op":"mcm","clk":"11879217327","pt":1724105892614,"mc":[{"id":"1.231875383","rc":[{"batb":[[0,1.45,6.91],[1,1.44,37.55],[2,1.41,40]],"ltp":0.0,"tv":0.0,"id":60443}]}]}
{"op":"mcm","clk":"11879222200","pt":1724105989330,"mc":[{"id":"1.231875383","rc":[{"batb":[[0,1.51,17.71],[1,1.5,20],[2,1.16,40]],"ltp":1.04,"tv":2.0,"id":31379},{"batb":[[0,1.51,16.82],[1,1.5,20],[2,1.16,40]],"ltp":0.0,"tv":0.0,"id":655},{"batb":[[0,1.46,19.54],[1,1.45,6.01],[2,1.44,37.55]],"ltp":0.0,"tv":0.0,"id":60443}]}]}
{"op":"mcm","clk":"11879304692","pt":1724107790028,"mc":[{"id":"1.231875383","rc":[{"batb":[[0,1.5,20.9],[1,1.16,40],[2,1.09,222.22]],"ltp":1.04,"tv":2.0,"id":31379},{"batb":[[0,1.5,20],[1,1.16,40],[2,1.09,222.22]],"ltp":0.0,"tv":0.0,"id":655},{"batb":[[0,1.45,6.91],[1,1.44,37.55],[2,1.41,40]],"ltp":0.0,"tv":0.0,"id":60443}]}]}
{"op":"mcm","clk":"11879308649","pt":1724107870862,"mc":[{"id":"1.231875383","rc":[{"batb":[[0,1.51,17.71],[1,1.5,20],[2,1.16,40]],"ltp":1.04,"tv":2.0,"id":31379},{"batb":[[0,1.51,16.82],[1,1.5,20],[2,1.16,40]],"ltp":0.0,"tv":0.0,"id":655},{"batb":[[0,1.46,19.54],[1,1.45,6.01],[2,1.44,37.55]],"ltp":0.0,"tv":0.0,"id":60443}]}]}
{"op":"mcm","clk":"11879419884","pt":1724109672077,"mc":[{"id":"1.231875383","rc":[{"batb":[[0,1.5,20.9],[1,1.16,40],[2,1.09,222.22]],"ltp":1.04,"tv":2.0,"id":31379},{"batb":[[0,1.5,20],[1,1.16,40],[2,1.09,222.22]],"ltp":0.0,"tv":0.0,"id":655},{"batb":[[0,1.45,6.91],[1,1.44,37.55],[2,1.41,40]],"ltp":0.0,"tv":0.0,"id":60443}]}]}
{"op":"mcm","clk":"11879424793","pt":1724109744377,"mc":[{"id":"1.231875383","rc":[{"batb":[[0,1.51,17.71],[1,1.5,20],[2,1.16,40]],"ltp":1.04,"tv":2.0,"id":31379},{"batb":[[0,1.51,16.82],[1,1.5,20],[2,1.16,40]],"ltp":0.0,"tv":0.0,"id":655},{"batb":[[0,1.46,19.54],[1,1.45,6.01],[2,1.44,37.55]],"ltp":0.0,"tv":0.0,"id":60443}]}]}
{"op":"mcm","clk":"11879564497","pt":1724111546608,"mc":[{"id":"1.231875383","rc":[{"batb":[[0,1.5,20.9],[1,1.16,40],[2,1.09,222.22]],"ltp":1.04,"tv":2.0,"id":31379},{"batb":[[0,1.5,20],[1,1.16,40],[2,1.09,222.22]],"ltp":0.0,"tv":0.0,"id":655},{"batb":[[0,1.45,6.91],[1,1.44,37.55],[2,1.41,40]],"ltp":0.0,"tv":0.0,"id":60443}]}]}
{"op":"mcm","clk":"11879567759","pt":1724111599841,"mc":[{"id":"1.231875383","rc":[{"batb":[[0,1.51,17.71],[1,1.5,20],[2,1.16,40]],"ltp":1.04,"tv":2.0,"id":31379},{"batb":[[0,1.51,16.82],[1,1.5,20],[2,1.16,40]],"ltp":0.0,"tv":0.0,"id":655},{"batb":[[0,1.46,19.54],[1,1.45,6.01],[2,1.44,37.55]],"ltp":0.0,"tv":0.0,"id":60443}]}]}
{"op":"mcm","clk":"11879703747","pt":1724113401012,"mc":[{"id":"1.231875383","rc":[{"batb":[[0,1.5,20.9],[1,1.16,40],[2,1.09,222.22]],"ltp":1.04,"tv":2.0,"id":31379},{"batb":[[0,1.5,20],[1,1.16,40],[2,1.09,222.22]],"ltp":0.0,"tv":0.0,"id":655}]}]}
{"op":"mcm","clk":"11879703767","pt":1724113401216,"mc":[{"id":"1.231875383","rc":[{"batb":[[0,1.45,6.91],[1,1.44,37.55],[2,1.41,40]],"ltp":0.0,"tv":0.0,"id":60443}]}]}
{"op":"mcm","clk":"11879706775","pt":1724113430846,"mc":[{"id":"1.231875383","rc":[{"batb":[[0,1.51,17.71],[1,1.5,20],[2,1.16,40]],"ltp":1.04,"tv":2.0,"id":31379},{"batb":[[0,1.51,16.82],[1,1.5,20],[2,1.16,40]],"ltp":0.0,"tv":0.0,"id":655},{"batb":[[0,1.46,19.54],[1,1.45,6.01],[2,1.44,37.55]],"ltp":0.0,"tv":0.0,"id":60443}]}]}
{"op":"mcm","clk":"11879856673","pt":1724115232984,"mc":[{"id":"1.231875383","rc":[{"batb":[[0,1.5,20.9],[1,1.16,40],[2,1.09,222.22]],"ltp":1.04,"tv":2.0,"id":31379},{"batb":[[0,1.5,20],[1,1.16,40],[2,1.09,222.22]],"ltp":0.0,"tv":0.0,"id":655},{"batb":[[0,1.45,6.91],[1,1.44,37.55],[2,1.41,40]],"ltp":0.0,"tv":0.0,"id":60443}]}]}
{"op":"mcm","clk":"11879857188","pt":1724115239606,"mc":[{"id":"1.231875383","rc":[{"batb":[[0,1.51,17.71],[1,1.5,20],[2,1.16,40]],"ltp":1.04,"tv":2.0,"id":31379},{"batb":[[0,1.51,16.82],[1,1.5,20],[2,1.16,40]],"ltp":0.0,"tv":0.0,"id":655},{"batb":[[0,1.46,19.54],[1,1.45,6.01],[2,1.44,37.55]],"ltp":0.0,"tv":0.0,"id":60443}]}]}
{"op":"mcm","clk":"11879975843","pt":1724117041083,"mc":[{"id":"1.231875383","rc":[{"batb":[[0,1.5,20.9],[1,1.16,40],[2,1.09,222.22]],"ltp":1.04,"tv":2.0,"id":31379},{"batb":[[0,1.5,20],[1,1.16,40],[2,1.09,222.22]],"ltp":0.0,"tv":0.0,"id":655},{"batb":[[0,1.45,6.91],[1,1.44,37.55],[2,1.41,40]],"ltp":0.0,"tv":0.0,"id":60443}]}]}
{"op":"mcm","clk":"11879983015","pt":1724117166932,"mc":[{"id":"1.231875383","rc":[{"batb":[[0,1.51,17.71],[1,1.5,20],[2,1.16,40]],"ltp":1.04,"tv":2.0,"id":31379},{"batb":[[0,1.51,16.82],[1,1.5,20],[2,1.16,40]],"ltp":0.0,"tv":0.0,"id":655},{"batb":[[0,1.46,19.54],[1,1.45,6.01],[2,1.44,37.55]],"ltp":0.0,"tv":0.0,"id":60443}]}]}
{"op":"mcm","clk":"11880081160","pt":1724118968078,"mc":[{"id":"1.231875383","rc":[{"batb":[[0,1.5,20.9],[1,1.16,40],[2,1.09,222.22]],"ltp":1.04,"tv":2.0,"id":31379},{"batb":[[0,1.45,6.91],[1,1.44,37.55],[2,1.41,40]],"ltp":0.0,"tv":0.0,"id":60443}]}]}
{"op":"mcm","clk":"11880081168","pt":1724118968282,"mc":[{"id":"1.231875383","rc":[{"batb":[[0,1.5,20],[1,1.16,40],[2,1.09,222.22]],"ltp":0.0,"tv":0.0,"id":655}]}]}
{"op":"mcm","clk":"11880085315","pt":1724119050745,"mc":[{"id":"1.231875383","rc":[{"batb":[[0,1.51,17.71],[1,1.5,20],[2,1.16,40]],"ltp":1.04,"tv":2.0,"id":31379},{"batb":[[0,1.51,16.82],[1,1.5,20],[2,1.16,40]],"ltp":0.0,"tv":0.0,"id":655},{"batb":[[0,1.46,19.54],[1,1.45,6.01],[2,1.44,37.55]],"ltp":0.0,"tv":0.0,"id":60443}]}]}
{"op":"mcm","clk":"11880157415","pt":1724120851492,"mc":[{"id":"1.231875383","rc":[{"batb":[[0,1.5,20.9],[1,1.16,40],[2,1.09,222.22]],"ltp":1.04,"tv":2.0,"id":31379},{"batb":[[0,1.5,20],[1,1.16,40],[2,1.09,222.22]],"ltp":0.0,"tv":0.0,"id":655},{"batb":[[0,1.45,6.91],[1,1.44,37.56],[2,1.41,40]],"ltp":0.0,"tv":0.0,"id":60443}]}]}
{"op":"mcm","clk":"11880159752","pt":1724120911680,"mc":[{"id":"1.231875383","rc":[{"batb":[[0,1.51,17.72],[1,1.5,20],[2,1.16,40]],"ltp":1.04,"tv":2.0,"id":31379},{"batb":[[0,1.51,16.82],[1,1.5,20],[2,1.16,40]],"ltp":0.0,"tv":0.0,"id":655},{"batb":[[0,1.46,19.55],[1,1.45,6.01],[2,1.44,37.56]],"ltp":0.0,"tv":0.0,"id":60443}]}]}
{"op":"mcm","clk":"11880275729","pt":1724123618073,"mc":[{"id":"1.231875383","rc":[{"batb":[[0,1.5,20.9],[1,1.16,40],[2,1.09,222.22]],"ltp":1.04,"tv":2.0,"id":31379},{"batb":[[0,1.51,16.82]],"ltp":0.0,"tv":0.0,"id":655},{"batb":[[0,1.45,6.91],[1,1.44,37.55],[2,1.41,40]],"ltp":0.0,"tv":0.0,"id":60443}]}]}
{"op":"mcm","clk":"11880275735","pt":1724123618280,"mc":[{"id":"1.231875383","rc":[{"batb":[[0,1.5,20],[1,1.16,40],[2,1.09,222.22]],"ltp":0.0,"tv":0.0,"id":655}]}]}
{"op":"mcm","clk":"11880280196","pt":1724123740003,"mc":[{"id":"1.231875383","rc":[{"batb":[[0,1.51,17.71],[1,1.5,20],[2,1.16,40]],"ltp":1.04,"tv":2.0,"id":31379},{"batb":[[0,1.51,16.82],[1,1.5,20],[2,1.16,40]],"ltp":0.0,"tv":0.0,"id":655},{"batb":[[0,1.46,19.54],[1,1.45,6.02],[2,1.44,37.55]],"ltp":0.0,"tv":0.0,"id":60443}]}]}
{"op":"mcm","clk":"11880337326","pt":1724125541895,"mc":[{"id":"1.231875383","rc":[{"batb":[[0,1.5,20.9],[1,1.16,40],[2,1.09,222.22]],"ltp":1.04,"tv":2.0,"id":31379},{"batb":[[0,1.5,20],[1,1.16,40],[2,1.09,222.22]],"ltp":0.0,"tv":0.0,"id":655}]}]}
{"op":"mcm","clk":"11880337335","pt":1724125542099,"mc":[{"id":"1.231875383","rc":[{"batb":[[0,1.45,6.91],[1,1.44,37.55],[2,1.41,40]],"ltp":0.0,"tv":0.0,"id":60443}]}]}
{"op":"mcm","clk":"11880337844","pt":1724125557352,"mc":[{"id":"1.231875383","rc":[{"batb":[[0,1.51,17.71],[1,1.5,20],[2,1.16,40]],"ltp":1.04,"tv":2.0,"id":31379},{"batb":[[0,1.51,16.82],[1,1.5,20],[2,1.16,40]],"ltp":0.0,"tv":0.0,"id":655},{"batb":[[0,1.46,19.54],[1,1.45,6.02],[2,1.44,37.55]],"ltp":0.0,"tv":0.0,"id":60443}]}]}
{"op":"mcm","clk":"11880395344","pt":1724127358009,"mc":[{"id":"1.231875383","rc":[{"batb":[[0,1.5,20.9],[1,1.16,40],[2,1.09,222.22]],"ltp":1.04,"tv":2.0,"id":31379},{"batb":[[0,1.5,20],[1,1.16,40],[2,1.09,222.22]],"ltp":0.0,"tv":0.0,"id":655},{"batb":[[0,1.45,6.91],[1,1.44,37.55],[2,1.41,40]],"ltp":0.0,"tv":0.0,"id":60443}]}]}
{"op":"mcm","clk":"11880395478","pt":1724127363024,"mc":[{"id":"1.231875383","rc":[{"batb":[[0,1.51,17.71],[1,1.5,20],[2,1.16,40]],"ltp":1.04,"tv":2.0,"id":31379},{"batb":[[0,1.51,16.82],[1,1.5,20],[2,1.16,40]],"ltp":0.0,"tv":0.0,"id":655},{"batb":[[0,1.46,19.54],[1,1.45,6.02],[2,1.44,37.55]],"ltp":0.0,"tv":0.0,"id":60443}]}]}
{"op":"mcm","clk":"11880442566","pt":1724129163529,"mc":[{"id":"1.231875383","rc":[{"batb":[[0,1.5,20],[1,1.16,40],[2,1.09,222.22]],"ltp":0.0,"tv":0.0,"id":655},{"batb":[[0,1.45,6.91],[1,1.44,37.55],[2,1.41,40]],"ltp":0.0,"tv":0.0,"id":60443}]}]}
{"op":"mcm","clk":"11880442615","pt":1724129166138,"mc":[{"id":"1.231875383","rc":[{"batb":[[0,1.5,20.9],[1,1.16,40],[2,1.09,222.22]],"ltp":1.04,"tv":2.0,"id":31379}]}]}
{"op":"mcm","clk":"11880446054","pt":1724129313650,"mc":[{"id":"1.231875383","rc":[{"batb":[[0,1.51,17.71],[1,1.5,20],[2,1.16,40]],"ltp":1.04,"tv":2.0,"id":31379},{"batb":[[0,1.51,16.82],[1,1.5,20],[2,1.16,40]],"ltp":0.0,"tv":0.0,"id":655},{"batb":[[0,1.46,19.54],[1,1.45,6.02],[2,1.44,37.55]],"ltp":0.0,"tv":0.0,"id":60443}]}]}
{"op":"mcm","clk":"11880498505","pt":1724131114808,"mc":[{"id":"1.231875383","rc":[{"batb":[[0,1.5,20.9],[1,1.16,40],[2,1.09,222.22]],"ltp":1.04,"tv":2.0,"id":31379},{"batb":[[0,1.5,20],[1,1.16,40],[2,1.09,222.22]],"ltp":0.0,"tv":0.0,"id":655},{"batb":[[0,1.45,6.91],[1,1.44,37.55],[2,1.41,40]],"ltp":0.0,"tv":0.0,"id":60443}]}]}
{"op":"mcm","clk":"11880500175","pt":1724131180575,"mc":[{"id":"1.231875383","rc":[{"batb":[[0,1.51,17.71],[1,1.5,20],[2,1.16,40]],"ltp":1.04,"tv":2.0,"id":31379},{"batb":[[0,1.51,16.82],[1,1.5,20],[2,1.16,40]],"ltp":0.0,"tv":0.0,"id":655},{"batb":[[0,1.46,19.54],[1,1.45,6.02],[2,1.44,37.55]],"ltp":0.0,"tv":0.0,"id":60443}]}]}
{"op":"mcm","clk":"11880567081","pt":1724132982936,"mc":[{"id":"1.231875383","rc":[{"batb":[[0,1.5,20.9],[1,1.16,40],[2,1.09,222.22]],"ltp":1.04,"tv":2.0,"id":31379},{"batb":[[0,1.5,20],[1,1.16,40],[2,1.09,222.22]],"ltp":0.0,"tv":0.0,"id":655},{"batb":[[0,1.45,6.91],[1,1.44,37.55],[2,1.41,40]],"ltp":0.0,"tv":0.0,"id":60443}]}]}
{"op":"mcm","clk":"11880568718","pt":1724133047466,"mc":[{"id":"1.231875383","rc":[{"batb":[[0,1.51,17.71],[1,1.5,20],[2,1.16,40]],"ltp":1.04,"tv":2.0,"id":31379},{"batb":[[0,1.51,16.82],[1,1.5,20],[2,1.16,40]],"ltp":0.0,"tv":0.0,"id":655},{"batb":[[0,1.46,19.54],[1,1.45,6.02],[2,1.44,37.55]],"ltp":0.0,"tv":0.0,"id":60443}]}]}
{"op":"mcm","clk":"11880631370","pt":1724134849541,"mc":[{"id":"1.231875383","rc":[{"batb":[[0,1.5,20.9],[1,1.16,40],[2,1.09,222.22]],"ltp":1.04,"tv":2.0,"id":31379},{"batb":[[0,1.5,20],[1,1.16,40],[2,1.09,222.22]],"ltp":0.0,"tv":0.0,"id":655},{"batb":[[0,1.45,6.91],[1,1.44,37.55],[2,1.41,40]],"ltp":0.0,"tv":0.0,"id":60443}]}]}
{"op":"mcm","clk":"11880633730","pt":1724134913022,"mc":[{"id":"1.231875383","rc":[{"batb":[[0,1.51,17.71],[1,1.5,20],[2,1.16,40]],"ltp":1.04,"tv":2.0,"id":31379},{"batb":[[0,1.51,16.82],[1,1.5,20],[2,1.16,40]],"ltp":0.0,"tv":0.0,"id":655}]}]}
{"op":"mcm","clk":"11880633734","pt":1724134913224,"mc":[{"id":"1.231875383","rc":[{"batb":[[0,1.46,19.54],[1,1.45,6.02],[2,1.44,37.55]],"ltp":0.0,"tv":0.0,"id":60443}]}]}
{"op":"mcm","clk":"11880692287","pt":1724136715061,"mc":[{"id":"1.231875383","rc":[{"batb":[[0,1.5,20.9],[1,1.16,40],[2,1.09,222.22]],"ltp":1.04,"tv":2.0,"id":31379},{"batb":[[0,1.45,6.91],[1,1.44,37.55],[2,1.41,40]],"ltp":0.0,"tv":0.0,"id":60443}]}]}
{"op":"mcm","clk":"11880692298","pt":1724136715267,"mc":[{"id":"1.231875383","rc":[{"batb":[[0,1.5,20],[1,1.16,40],[2,1.09,222.22]],"ltp":0.0,"tv":0.0,"id":655}]}]}
{"op":"mcm","clk":"11880694943","pt":1724136777028,"mc":[{"id":"1.231875383","rc":[{"batb":[[0,1.51,17.71],[1,1.5,20],[2,1.16,40]],"ltp":1.04,"tv":2.0,"id":31379},{"batb":[[0,1.51,16.82],[1,1.5,20],[2,1.16,40]],"ltp":0.0,"tv":0.0,"id":655},{"batb":[[0,1.46,19.54],[1,1.45,6.02],[2,1.44,37.55]],"ltp":0.0,"tv":0.0,"id":60443}]}]}
{"op":"mcm","clk":"11880739741","pt":1724137974966,"mc":[{"id":"1.231875383","rc":[{"batb":[[0,1.51,17.7]],"ltp":1.04,"tv":2.0,"id":31379},{"batb":[[0,1.51,16.81]],"ltp":0.0,"tv":0.0,"id":655},{"batb":[[0,1.46,19.53],[1,1.45,6.01],[2,1.44,37.52]],"ltp":0.0,"tv":0.0,"id":60443}]}]}
{"op":"mcm","clk":"11880763325","pt":1724138578049,"mc":[{"id":"1.231875383","rc":[{"batb":[[0,1.5,20],[1,1.16,40],[2,1.09,222.22]],"ltp":0.0,"tv":0.0,"id":655}]}]}
{"op":"mcm","clk":"11880763341","pt":1724138578461,"mc":[{"id":"1.231875383","rc":[{"batb":[[0,1.5,20.9],[1,1.16,40],[2,1.09,222.22]],"ltp":1.04,"tv":2.0,"id":31379},{"batb":[[0,1.45,6.91],[1,1.44,37.52],[2,1.41,40]],"ltp":0.0,"tv":0.0,"id":60443}]}]}
{"op":"mcm","clk":"11880765682","pt":1724138639939,"mc":[{"id":"1.231875383","rc":[{"batb":[[0,1.51,17.7],[1,1.5,20],[2,1.16,40]],"ltp":1.04,"tv":2.0,"id":31379},{"batb":[[0,1.51,16.81],[1,1.5,20],[2,1.16,40]],"ltp":0.0,"tv":0.0,"id":655},{"batb":[[0,1.46,19.53],[1,1.45,6.01],[2,1.44,37.52]],"ltp":0.0,"tv":0.0,"id":60443}]}]}
{"op":"mcm","clk":"11880840205","pt":1724140441001,"mc":[{"id":"1.231875383","rc":[{"batb":[[0,1.5,20.9],[1,1.16,40],[2,1.09,222.22]],"ltp":1.04,"tv":2.0,"id":31379},{"batb":[[0,1.5,20],[1,1.16,40],[2,1.09,222.22]],"ltp":0.0,"tv":0.0,"id":655}]}]}
{"op":"mcm","clk":"11880840214","pt":1724140441206,"mc":[{"id":"1.231875383","rc":[{"batb":[[0,1.45,6.91],[1,1.44,37.52],[2,1.41,40]],"ltp":0.0,"tv":0.0,"id":60443}]}]}
{"op":"mcm","clk":"11880842775","pt":1724140504162,"mc":[{"id":"1.231875383","rc":[{"batb":[[0,1.51,17.7],[1,1.5,20],[2,1.16,40]],"ltp":1.04,"tv":2.0,"id":31379},{"batb":[[0,1.51,16.81],[1,1.5,20],[2,1.16,40]],"ltp":0.0,"tv":0.0,"id":655},{"batb":[[0,1.46,19.53],[1,1.45,6.01],[2,1.44,37.52]],"ltp":0.0,"tv":0.0,"id":60443}]}]}
{"op":"mcm","clk":"11880918472","pt":1724142305972,"mc":[{"id":"1.231875383","rc":[{"batb":[[0,1.51,17.7]],"ltp":1.04,"tv":2.0,"id":31379},{"batb":[[0,1.5,20],[1,1.16,40],[2,1.09,222.22]],"ltp":0.0,"tv":0.0,"id":655},{"batb":[[0,1.46,19.52],[1,1.45,6.01],[2,1.44,37.52]],"ltp":0.0,"tv":0.0,"id":60443}]}]}
{"op":"mcm","clk":"11880918490","pt":1724142306385,"mc":[{"id":"1.231875383","rc":[{"batb":[[0,1.5,20.89],[1,1.16,40],[2,1.09,222.22]],"ltp":1.04,"tv":2.0,"id":31379},{"batb":[[0,1.45,6.9],[1,1.44,37.52],[2,1.41,40]],"ltp":0.0,"tv":0.0,"id":60443}]}]}
{"op":"mcm","clk":"11880924072","pt":1724142441337,"mc":[{"id":"1.231875383","rc":[{"batb":[[0,1.51,17.7],[1,1.5,20],[2,1.16,40]],"ltp":1.04,"tv":2.0,"id":31379},{"batb":[[0,1.51,16.8],[1,1.5,20],[2,1.16,40]],"ltp":0.0,"tv":0.0,"id":655},{"batb":[[0,1.46,19.52],[1,1.45,6.01],[2,1.44,37.52]],"ltp":0.0,"tv":0.0,"id":60443}]}]}
{"op":"mcm","clk":"11881033596","pt":1724144243899,"mc":[{"id":"1.231875383","rc":[{"batb":[[0,1.5,20.89],[1,1.16,40],[2,1.09,222.22]],"ltp":1.04,"tv":2.0,"id":31379},{"batb":[[0,1.5,20],[1,1.16,40],[2,1.09,222.22]],"ltp":0.0,"tv":0.0,"id":655},{"batb":[[0,1.45,6.9],[1,1.44,37.52],[2,1.41,40]],"ltp":0.0,"tv":0.0,"id":60443}]}]}
{"op":"mcm","clk":"11881036429","pt":1724144285014,"mc":[{"id":"1.231875383","rc":[{"batb":[[0,1.51,17.7],[1,1.5,20],[2,1.16,40]],"ltp":1.04,"tv":2.0,"id":31379},{"batb":[[0,1.51,16.8],[1,1.5,20],[2,1.16,40]],"ltp":0.0,"tv":0.0,"id":655},{"batb":[[0,1.46,19.52],[1,1.45,6.01],[2,1.44,37.52]],"ltp":0.0,"tv":0.0,"id":60443}]}]}
{"op":"mcm","clk":"11881149800","pt":1724146085625,"mc":[{"id":"1.231875383","rc":[{"batb":[[0,1.5,20.89],[1,1.16,40],[2,1.09,222.22]],"ltp":1.04,"tv":2.0,"id":31379},{"batb":[[0,1.5,20],[1,1.16,40],[2,1.09,222.22]],"ltp":0.0,"tv":0.0,"id":655},{"batb":[[0,1.45,6.9],[1,1.44,37.5],[2,1.41,40]],"ltp":0.0,"tv":0.0,"id":60443}]}]}
{"op":"mcm","clk":"11881152352","pt":1724146122104,"mc":[{"id":"1.231875383","rc":[{"batb":[[0,1.51,17.69],[1,1.5,20],[2,1.16,40]],"ltp":1.04,"tv":2.0,"id":31379},{"batb":[[0,1.51,16.8],[1,1.5,20],[2,1.16,40]],"ltp":0.0,"tv":0.0,"id":655},{"batb":[[0,1.46,19.52],[1,1.45,6.01],[2,1.44,37.5]],"ltp":0.0,"tv":0.0,"id":60443}]}]}
{"op":"mcm","clk":"11881299038","pt":1724147924814,"mc":[{"id":"1.231875383","rc":[{"batb":[[0,1.5,20.89],[1,1.16,40],[2,1.09,222.22]],"ltp":1.04,"tv":2.0,"id":31379},{"batb":[[0,1.5,20],[1,1.16,40],[2,1.09,222.22]],"ltp":0.0,"tv":0.0,"id":655},{"batb":[[0,1.45,6.9],[1,1.44,37.5],[2,1.41,40]],"ltp":0.0,"tv":0.0,"id":60443}]}]}
{"op":"mcm","clk":"11881302282","pt":1724147954250,"mc":[{"id":"1.231875383","rc":[{"batb":[[0,1.51,17.69],[1,1.5,20],[2,1.16,40]],"ltp":1.04,"tv":2.0,"id":31379},{"batb":[[0,1.51,16.8],[1,1.5,20],[2,1.16,40]],"ltp":0.0,"tv":0.0,"id":655},{"batb":[[0,1.46,19.52],[1,1.45,6.01],[2,1.44,37.5]],"ltp":0.0,"tv":0.0,"id":60443}]}]}
{"op":"mcm","clk":"11881394424","pt":1724148774957,"mc":[{"id":"1.231875383","rc":[{"batb":[[0,1.51,17.68]],"ltp":1.04,"tv":2.0,"id":31379},{"batb":[[0,1.51,16.79]],"ltp":0.0,"tv":0.0,"id":655},{"batb":[[0,1.46,19.5],[2,1.44,37.48]],"ltp":0.0,"tv":0.0,"id":60443}]}]}
{"op":"mcm","clk":"11881486009","pt":1724149756071,"mc":[{"id":"1.231875383","rc":[{"batb":[[0,1.5,20],[1,1.16,40],[2,1.09,222.22]],"ltp":0.0,"tv":0.0,"id":655}]}]}
{"op":"mcm","clk":"11881486043","pt":1724149756383,"mc":[{"id":"1.231875383","rc":[{"batb":[[0,1.5,20.89],[1,1.16,40],[2,1.09,222.22]],"ltp":1.04,"tv":2.0,"id":31379},{"batb":[[0,1.45,6.9],[1,1.44,37.48],[2,1.41,40]],"ltp":0.0,"tv":0.0,"id":60443}]}]}
{"op":"mcm","clk":"11881488701","pt":1724149785949,"mc":[{"id":"1.231875383","rc":[{"batb":[[0,1.51,17.68],[1,1.5,20],[2,1.16,40]],"ltp":1.04,"tv":2.0,"id":31379},{"batb":[[0,1.51,16.79],[1,1.5,20],[2,1.16,40]],"ltp":0.0,"tv":0.0,"id":655},{"batb":[[0,1.46,19.5],[1,1.45,6.01],[2,1.44,37.48]],"ltp":0.0,"tv":0.0,"id":60443}]}]}
{"op":"mcm","clk":"11881667466","pt":1724151588543,"mc":[{"id":"1.231875383","rc":[{"batb":[[0,1.5,20.89],[1,1.16,40],[2,1.09,222.22]],"ltp":1.04,"tv":2.0,"id":31379},{"batb":[[0,1.5,20],[1,1.16,40],[2,1.09,222.22]],"ltp":0.0,"tv":0.0,"id":655},{"batb":[[0,1.45,6.9],[1,1.44,37.48],[2,1.41,40]],"ltp":0.0,"tv":0.0,"id":60443}]}]}
{"op":"mcm","clk":"11881668832","pt":1724151602343,"mc":[{"id":"1.231875383","rc":[{"batb":[[0,1.51,17.68],[1,1.5,20],[2,1.16,40]],"ltp":1.04,"tv":2.0,"id":31379},{"batb":[[0,1.51,16.79],[1,1.5,20],[2,1.16,40]],"ltp":0.0,"tv":0.0,"id":655},{"batb":[[0,1.46,19.5],[1,1.45,6.01],[2,1.44,37.48]],"ltp":0.0,"tv":0.0,"id":60443}]}]}
{"op":"mcm","clk":"11881832664","pt":1724153404074,"mc":[{"id":"1.231875383","rc":[{"batb":[[0,1.5,20.89],[1,1.16,40],[2,1.09,222.22]],"ltp":1.04,"tv":2.0,"id":31379},{"batb":[[0,1.51,16.79]],"ltp":0.0,"tv":0.0,"id":655},{"batb":[[0,1.45,6.9],[1,1.44,37.5],[2,1.41,40]],"ltp":0.0,"tv":0.0,"id":60443}]}]}
{"op":"mcm","clk":"11881832671","pt":1724153404177,"mc":[{"id":"1.231875383","rc":[{"batb":[[0,1.5,20],[1,1.16,40],[2,1.09,222.22]],"ltp":0.0,"tv":0.0,"id":655}]}]}
{"op":"mcm","clk":"11881845758","pt":1724153567039,"mc":[{"id":"1.231875383","rc":[{"batb":[[0,1.51,16.79],[1,1.5,20],[2,1.16,40]],"ltp":0.0,"tv":0.0,"id":655},{"batb":[[0,1.46,19.51],[1,1.45,6.01],[2,1.44,37.5]],"ltp":0.0,"tv":0.0,"id":60443}]}]}
{"op":"mcm","clk":"11881845764","pt":1724153567140,"mc":[{"id":"1.231875383","rc":[{"batb":[[0,1.51,17.69],[1,1.5,20],[2,1.16,40]],"ltp":1.04,"tv":2.0,"id":31379}]}]}
{"op":"mcm","clk":"11882000718","pt":1724155367503,"mc":[{"id":"1.231875383","rc":[{"batb":[[0,1.5,20.89],[1,1.16,40],[2,1.09,222.22]],"ltp":1.04,"tv":2.0,"id":31379},{"batb":[[0,1.5,20],[1,1.16,40],[2,1.09,222.22]],"ltp":0.0,"tv":0.0,"id":655},{"batb":[[0,1.45,6.9],[1,1.44,37.48],[2,1.41,40]],"ltp":0.0,"tv":0.0,"id":60443}]}]}
{"op":"mcm","clk":"11882013600","pt":1724155511982,"mc":[{"id":"1.231875383","rc":[{"batb":[[0,1.51,17.68],[1,1.5,20],[2,1.16,40]],"ltp":1.04,"tv":2.0,"id":31379},{"batb":[[0,1.51,16.78],[1,1.5,20],[2,1.16,40]],"ltp":0.0,"tv":0.0,"id":655},{"batb":[[0,1.46,19.5],[1,1.45,6],[2,1.44,37.48]],"ltp":0.0,"tv":0.0,"id":60443}]}]}
{"op":"mcm","clk":"11882156960","pt":1724157312075,"mc":[{"id":"1.231875383","rc":[{"batb":[[0,1.45,6.9],[1,1.44,37.48],[2,1.41,40]],"ltp":0.0,"tv":0.0,"id":60443}]}]}
{"op":"mcm","clk":"11882156981","pt":1724157312386,"mc":[{"id":"1.231875383","rc":[{"batb":[[0,1.5,20.89],[1,1.16,40],[2,1.09,222.22]],"ltp":1.04,"tv":2.0,"id":31379},{"batb":[[0,1.5,20],[1,1.16,40],[2,1.09,222.22]],"ltp":0.0,"tv":0.0,"id":655}]}]}
{"op":"mcm","clk":"11882159333","pt":1724157347321,"mc":[{"id":"1.231875383","rc":[{"batb":[[0,1.51,17.68],[1,1.5,20],[2,1.16,40]],"ltp":1.04,"tv":2.0,"id":31379},{"batb":[[0,1.51,16.78],[1,1.5,20],[2,1.16,40]],"ltp":0.0,"tv":0.0,"id":655},{"batb":[[0,1.46,19.5],[1,1.45,6],[2,1.44,37.48]],"ltp":0.0,"tv":0.0,"id":60443}]}]}
{"op":"mcm","clk":"11882199136","pt":1724157845142,"mc":[{"id":"1.231875383","rc":[{"batb":[[0,1.47,40],[1,1.46,19.5],[2,1.45,6]],"ltp":0.0,"tv":0.0,"id":60443}]}]}
{"op":"mcm","clk":"11882306099","pt":1724159147850,"mc":[{"id":"1.231875383","rc":[{"batb":[[0,1.5,20.89],[1,1.16,40],[2,1.09,222.22]],"ltp":1.04,"tv":2.0,"id":31379},{"batb":[[0,1.5,20],[1,1.16,40],[2,1.09,222.22]],"ltp":0.0,"tv":0.0,"id":655},{"batb":[[1,1.45,6.89],[2,1.44,37.48]],"ltp":0.0,"tv":0.0,"id":60443}]}]}
{"op":"mcm","clk":"11882308086","pt":1724159167097,"mc":[{"id":"1.231875383","rc":[{"batb":[[0,1.51,17.68],[1,1.5,20],[2,1.16,40]],"ltp":1.04,"tv":2.0,"id":31379},{"batb":[[0,1.51,16.79],[1,1.5,20],[2,1.16,40]],"ltp":0.0,"tv":0.0,"id":655},{"batb":[[0,1.48,17.83],[1,1.47,40],[2,1.45,6.89]],"ltp":0.0,"tv":0.0,"id":60443}]}]}
{"op":"mcm","clk":"11882380108","pt":1724159885193,"mc":[{"id":"1.231875383","rc":[{"batb":[[0,1.48,23.83],[2,1.44,38.37]],"ltp":0.0,"tv":0.0,"id":60443}]}]}
{"op":"mcm","clk":"11882491516","pt":1724160967530,"mc":[{"id":"1.231875383","rc":[{"batb":[[0,1.5,20.89],[1,1.16,40],[2,1.09,222.22]],"ltp":1.04,"tv":2.0,"id":31379},{"batb":[[0,1.5,20],[1,1.16,40],[2,1.09,222.22]],"ltp":0.0,"tv":0.0,"id":655},{"batb":[[0,1.48,5.99]],"ltp":0.0,"tv":0.0,"id":60443}]}]}
{"op":"mcm","clk":"11882492872","pt":1724160978198,"mc":[{"id":"1.231875383","rc":[{"batb":[[0,1.51,17.68],[1,1.5,20],[2,1.16,40]],"ltp":1.04,"tv":2.0,"id":31379},{"batb":[[0,1.51,16.79],[1,1.5,20],[2,1.16,40]],"ltp":0.0,"tv":0.0,"id":655},{"batb":[[0,1.49,17.47],[1,1.48,5.99],[2,1.47,40]],"ltp":0.0,"tv":0.0,"id":60443}]}]}
{"op":"mcm","clk":"11882554598","pt":1724161542517,"mc":[{"id":"1.231875383","rc":[{"batb":[[0,1.51,16.79]],"ltp":1.04,"tv":2.0,"id":31379}]}]}
{"op":"mcm","clk":"11882670420","pt":1724162778665,"mc":[{"id":"1.231875383","rc":[{"batb":[[0,1.5,20],[1,1.16,40],[2,1.09,222.22]],"ltp":1.04,"tv":2.0,"id":31379},{"batb":[[0,1.5,20],[1,1.16,40],[2,1.09,222.22]],"ltp":0.0,"tv":0.0,"id":655},{"batb":[[0,1.48,6],[1,1.47,40],[2,1.44,38.39]],"ltp":0.0,"tv":0.0,"id":60443}]}]}
{"op":"mcm","clk":"11882670695","pt":1724162781183,"mc":[{"id":"1.231875383","rc":[{"batb":[[0,1.51,16.79],[1,1.5,20],[2,1.16,40]],"ltp":1.04,"tv":2.0,"id":31379},{"batb":[[0,1.51,16.79],[1,1.5,20],[2,1.16,40]],"ltp":0.0,"tv":0.0,"id":655},{"batb":[[0,1.49,17.48],[1,1.48,6],[2,1.47,40]],"ltp":0.0,"tv":0.0,"id":60443}]}]}
{"op":"mcm","clk":"11882845601","pt":1724164581741,"mc":[{"id":"1.231875383","rc":[{"batb":[[0,1.5,20],[1,1.16,40],[2,1.09,222.22]],"ltp":1.04,"tv":2.0,"id":31379},{"batb":[[0,1.5,20],[1,1.16,40],[2,1.09,222.22]],"ltp":0.0,"tv":0.0,"id":655},{"batb":[[0,1.48,6],[1,1.47,40],[2,1.44,37.49]],"ltp":0.0,"tv":0.0,"id":60443}]}]}
{"op":"mcm","clk":"11882859781","pt":1724164738785,"mc":[{"id":"1.231875383","rc":[{"batb":[[0,1.51,16.79],[1,1.5,20],[2,1.16,40]],"ltp":1.04,"tv":2.0,"id":31379},{"batb":[[0,1.51,16.79],[1,1.5,20],[2,1.16,40]],"ltp":0.0,"tv":0.0,"id":655},{"batb":[[0,1.49,17.48],[1,1.48,6],[2,1.47,40]],"ltp":0.0,"tv":0.0,"id":60443}]}]}
{"op":"mcm","clk":"11883020861","pt":1724166325079,"mc":[{"id":"1.231875383","rc":[{"batb":[[0,1.51,16.8]],"batl":[[0,90,1.02],[1,95,5],[2,990,5]],"ltp":1.04,"tv":2.0,"id":31379},{"batb":[[0,1.51,16.8]],"batl":[[0,90,1.02],[1,95,5],[2,990,5]],"ltp":0.0,"tv":0.0,"id":655},{"batb":[[0,1.49,17.49],[1,1.48,5.99]],"batl":[[0,90,1.02],[1,95,5],[2,990,5]],"ltp":0.0,"tv":0.0,"id":60443}]}]}
{"op":"mcm","clk":"11883026065","pt":1724166376497,"mc":[{"id":"1.231875383","rc":[{"batl":[[2,990,5.17]],"ltp":1.04,"tv":2.0,"id":31379},{"batl":[[2,990,5.17]],"ltp":0.0,"tv":0.0,"id":655},{"batl":[[2,990,5.17]],"ltp":0.0,"tv":0.0,"id":60443}]}]}
{"op":"mcm","clk":"11883029758","pt":1724166412469,"mc":[{"id":"1.231875383","rc":[{"batl":[[2,990,5.34]],"ltp":1.04,"tv":2.0,"id":31379},{"batl":[[2,990,5.34]],"ltp":0.0,"tv":0.0,"id":655},{"batl":[[2,990,5.34]],"ltp":0.0,"tv":0.0,"id":60443}]}]}
{"op":"mcm","clk":"11883036087","pt":1724166465318,"mc":[{"id":"1.231875383","rc":[{"batl":[[2,990,5.51]],"ltp":1.04,"tv":2.0,"id":31379},{"batl":[[2,990,5.51]],"ltp":0.0,"tv":0.0,"id":655},{"batl":[[2,990,5.51]],"ltp":0.0,"tv":0.0,"id":60443}]}]}
{"op":"mcm","clk":"11883045149","pt":1724166538978,"mc":[{"id":"1.231875383","rc":[{"batb":[[0,1.5,20],[1,1.16,40],[2,1.09,222.22]],"ltp":1.04,"tv":2.0,"id":31379}]}]}
{"op":"mcm","clk":"11883045185","pt":1724166539290,"mc":[{"id":"1.231875383","rc":[{"batb":[[0,1.5,20],[1,1.16,40],[2,1.09,222.22]],"ltp":0.0,"tv":0.0,"id":655},{"batb":[[0,1.48,5.99],[1,1.47,40],[2,1.44,37.52]],"ltp":0.0,"tv":0.0,"id":60443}]}]}
{"op":"mcm","clk":"11883060272","pt":1724166677241,"mc":[{"id":"1.231875383","rc":[{"batb":[[0,1.51,16.8],[1,1.5,20],[2,1.16,40]],"ltp":1.04,"tv":2.0,"id":31379},{"batb":[[0,1.51,16.8],[1,1.5,20],[2,1.16,40]],"ltp":0.0,"tv":0.0,"id":655},{"batb":[[0,1.49,17.49],[1,1.48,5.99],[2,1.47,40]],"ltp":0.0,"tv":0.0,"id":60443}]}]}
{"op":"mcm","clk":"11883299101","pt":1724168477736,"mc":[{"id":"1.231875383","rc":[{"batb":[[0,1.5,20],[1,1.16,40],[2,1.09,222.22]],"ltp":1.04,"tv":2.0,"id":31379},{"batb":[[0,1.5,20],[1,1.16,40],[2,1.09,222.22]],"ltp":0.0,"tv":0.0,"id":655},{"batb":[[0,1.48,5.99],[1,1.47,40],[2,1.44,37.52]],"ltp":0.0,"tv":0.0,"id":60443}]}]}
{"op":"mcm","clk":"11883317456","pt":1724168605679,"mc":[{"id":"1.231875383","rc":[{"batb":[[0,1.51,16.8],[1,1.5,20],[2,1.16,40]],"ltp":1.04,"tv":2.0,"id":31379},{"batb":[[0,1.51,16.8],[1,1.5,20],[2,1.16,40]],"ltp":0.0,"tv":0.0,"id":655},{"batb":[[0,1.49,17.49],[1,1.48,5.99],[2,1.47,40]],"ltp":0.0,"tv":0.0,"id":60443}]}]}
{"op":"mcm","clk":"11883567608","pt":1724170374949,"mc":[{"id":"1.231875383","rc":[{"batb":[[1,1.48,6]],"ltp":0.0,"tv":0.0,"id":60443}]}]}
{"op":"mcm","clk":"11883577525","pt":1724170406047,"mc":[{"id":"1.231875383","rc":[{"batb":[[0,1.5,20],[1,1.16,40],[2,1.09,222.22]],"ltp":1.04,"tv":2.0,"id":31379},{"batb":[[0,1.48,6],[1,1.47,40],[2,1.44,37.52]],"ltp":0.0,"tv":0.0,"id":60443}]}]}
{"op":"mcm","clk":"11883577566","pt":1724170406257,"mc":[{"id":"1.231875383","rc":[{"batb":[[0,1.5,20],[1,1.16,40],[2,1.09,222.22]],"ltp":0.0,"tv":0.0,"id":655}]}]}
{"op":"mcm","clk":"11883596356","pt":1724170521791,"mc":[{"id":"1.231875383","rc":[{"batb":[[0,1.51,16.8],[1,1.5,20],[2,1.16,40]],"ltp":1.04,"tv":2.0,"id":31379},{"batb":[[0,1.51,16.8],[1,1.5,20],[2,1.16,40]],"ltp":0.0,"tv":0.0,"id":655},{"batb":[[0,1.49,17.49],[1,1.48,6],[2,1.47,40]],"ltp":0.0,"tv":0.0,"id":60443}]}]}
{"op":"mcm","clk":"11883884133","pt":1724172321929,"mc":[{"id":"1.231875383","rc":[{"batb":[[0,1.5,20],[1,1.16,40],[2,1.09,222.22]],"ltp":0.0,"tv":0.0,"id":655}]}]}
{"op":"mcm","clk":"11883884211","pt":1724172322342,"mc":[{"id":"1.231875383","rc":[{"batb":[[0,1.5,20],[1,1.16,40],[2,1.09,222.22]],"ltp":1.04,"tv":2.0,"id":31379},{"batb":[[0,1.48,6],[1,1.47,40],[2,1.44,37.52]],"ltp":0.0,"tv":0.0,"id":60443}]}]}
{"op":"mcm","clk":"11883900745","pt":1724172414211,"mc":[{"id":"1.231875383","rc":[{"batb":[[0,1.51,16.8],[1,1.5,20],[2,1.16,40]],"ltp":1.04,"tv":2.0,"id":31379},{"batb":[[0,1.51,16.8],[1,1.5,20],[2,1.16,40]],"ltp":0.0,"tv":0.0,"id":655},{"batb":[[0,1.49,17.49],[1,1.48,6],[2,1.47,40]],"ltp":0.0,"tv":0.0,"id":60443}]}]}
{"op":"mcm","clk":"11884184976","pt":1724174214775,"mc":[{"id":"1.231875383","rc":[{"batb":[[0,1.5,20],[1,1.16,40],[2,1.09,222.22]],"ltp":1.04,"tv":2.0,"id":31379},{"batb":[[0,1.5,20],[1,1.16,40],[2,1.09,222.22]],"ltp":0.0,"tv":0.0,"id":655},{"batb":[[0,1.48,6],[1,1.47,40],[2,1.44,37.55]],"ltp":0.0,"tv":0.0,"id":60443}]}]}
{"op":"mcm","clk":"11884194782","pt":1724174282425,"mc":[{"id":"1.231875383","rc":[{"batb":[[0,1.51,16.82],[1,1.5,20],[2,1.16,40]],"ltp":1.04,"tv":2.0,"id":31379},{"batb":[[0,1.51,16.82],[1,1.5,20],[2,1.16,40]],"ltp":0.0,"tv":0.0,"id":655},{"batb":[[0,1.49,17.5],[1,1.48,6],[2,1.47,40]],"ltp":0.0,"tv":0.0,"id":60443}]}]}
{"op":"mcm","clk":"11884453205","pt":1724176083027,"mc":[{"id":"1.231875383","rc":[{"batb":[[0,1.5,20],[1,1.16,40],[2,1.09,222.22]],"ltp":1.04,"tv":2.0,"id":31379},{"batb":[[0,1.5,20],[1,1.16,40],[2,1.09,222.22]],"ltp":0.0,"tv":0.0,"id":655},{"batb":[[0,1.48,6],[1,1.47,40],[2,1.44,37.55]],"ltp":0.0,"tv":0.0,"id":60443}]}]}
{"op":"mcm","clk":"11884457709","pt":1724176116686,"mc":[{"id":"1.231875383","rc":[{"batb":[[0,1.51,16.82],[1,1.5,20],[2,1.16,40]],"ltp":1.04,"tv":2.0,"id":31379},{"batb":[[0,1.51,16.82],[1,1.5,20],[2,1.16,40]],"ltp":0.0,"tv":0.0,"id":655},{"batb":[[0,1.49,17.5],[1,1.48,6],[2,1.47,40]],"ltp":0.0,"tv":0.0,"id":60443}]}]}
{"op":"mcm","clk":"11884577474","pt":1724177014921,"mc":[{"id":"1.231875383","rc":[{"batb":[[0,1.51,16.83]],"ltp":1.04,"tv":2.0,"id":31379},{"batb":[[0,1.51,16.83]],"batl":[[0,85,1.17],[1,95,5.85]],"ltp":0.0,"tv":0.0,"id":655},{"batb":[[0,1.49,17.51],[1,1.48,6]],"ltp":0.0,"tv":0.0,"id":60443}]}]}
{"op":"mcm","clk":"11884585458","pt":1724177070944,"mc":[{"id":"1.231875383","rc":[{"batl":[[0,85,1.17],[1,95,5.85]],"ltp":0.0,"tv":0.0,"id":60443}]}]}
{"op":"mcm","clk":"11884586197","pt":1724177076556,"mc":[{"id":"1.231875383","rc":[{"batl":[[0,85,1.17],[1,95,5.85]],"ltp":1.04,"tv":2.0,"id":31379}]}]}
{"op":"mcm","clk":"11884722245","pt":1724177916866,"mc":[{"id":"1.231875383","rc":[{"batb":[[0,1.5,20],[1,1.16,40],[2,1.09,222.22]],"ltp":0.0,"tv":0.0,"id":655}]}]}
{"op":"mcm","clk":"11884722290","pt":1724177917160,"mc":[{"id":"1.231875383","rc":[{"batb":[[0,1.5,20],[1,1.16,40],[2,1.09,222.22]],"ltp":1.04,"tv":2.0,"id":31379},{"batb":[[0,1.48,6],[1,1.47,40],[2,1.44,37.56]],"ltp":0.0,"tv":0.0,"id":60443}]}]}
{"op":"mcm","clk":"11884722857","pt":1724177920993,"mc":[{"id":"1.231875383","rc":[{"batb":[[0,1.51,16.83],[1,1.5,20],[2,1.16,40]],"ltp":1.04,"tv":2.0,"id":31379},{"batb":[[0,1.51,16.83],[1,1.5,20],[2,1.16,40]],"ltp":0.0,"tv":0.0,"id":655}]}]}
{"op":"mcm","clk":"11884722871","pt":1724177921096,"mc":[{"id":"1.231875383","rc":[{"batb":[[0,1.49,17.51],[1,1.48,6],[2,1.47,40]],"ltp":0.0,"tv":0.0,"id":60443}]}]}
{"op":"mcm","clk":"11884995199","pt":1724179721426,"mc":[{"id":"1.231875383","rc":[{"batb":[[0,1.5,20],[1,1.16,40],[2,1.09,222.22]],"ltp":1.04,"tv":2.0,"id":31379},{"batb":[[0,1.5,20],[1,1.16,40],[2,1.09,222.22]],"ltp":0.0,"tv":0.0,"id":655},{"batb":[[0,1.48,6],[1,1.47,40],[2,1.44,37.56]],"ltp":0.0,"tv":0.0,"id":60443}]}]}
{"op":"mcm","clk":"11885013433","pt":1724179823320,"mc":[{"id":"1.231875383","rc":[{"batb":[[0,1.51,16.83],[1,1.5,20],[2,1.16,40]],"ltp":1.04,"tv":2.0,"id":31379},{"batb":[[0,1.51,16.83],[1,1.5,20],[2,1.16,40]],"ltp":0.0,"tv":0.0,"id":655},{"batb":[[0,1.49,17.51],[1,1.48,6],[2,1.47,40]],"ltp":0.0,"tv":0.0,"id":60443}]}]}
{"op":"mcm","clk":"11885244624","pt":1724181174930,"mc":[{"id":"1.231875383","rc":[{"batb":[[0,1.51,16.82]],"ltp":1.04,"tv":2.0,"id":31379},{"batb":[[0,1.51,16.82]],"ltp":0.0,"tv":0.0,"id":655},{"batb":[[0,1.49,17.51],[1,1.48,5.99]],"ltp":0.0,"tv":0.0,"id":60443}]}]}
{"op":"mcm","clk":"11885331555","pt":1724181623787,"mc":[{"id":"1.231875383","rc":[{"batb":[[0,1.5,20],[1,1.16,40],[2,1.09,222.22]],"ltp":1.04,"tv":2.0,"id":31379},{"batb":[[0,1.5,20],[1,1.16,40],[2,1.09,222.22]],"ltp":0.0,"tv":0.0,"id":655},{"batb":[[0,1.48,5.99],[1,1.47,40],[2,1.44,37.55]],"ltp":0.0,"tv":0.0,"id":60443}]}]}
{"op":"mcm","clk":"11885341841","pt":1724181680269,"mc":[{"id":"1.231875383","rc":[{"batb":[[0,1.51,16.82],[1,1.5,20],[2,1.16,40]],"ltp":1.04,"tv":2.0,"id":31379},{"batb":[[0,1.51,16.82],[1,1.5,20],[2,1.16,40]],"ltp":0.0,"tv":0.0,"id":655},{"batb":[[0,1.49,17.51],[1,1.48,5.99],[2,1.47,40]],"ltp":0.0,"tv":0.0,"id":60443}]}]}
{"op":"mcm","clk":"11885613781","pt":1724183480691,"mc":[{"id":"1.231875383","rc":[{"batb":[[0,1.5,20],[1,1.16,40],[2,1.09,222.22]],"ltp":1.04,"tv":2.0,"id":31379},{"batb":[[0,1.5,20],[1,1.16,40],[2,1.09,222.22]],"ltp":0.0,"tv":0.0,"id":655},{"batb":[[0,1.48,5.99],[1,1.47,40],[2,1.44,37.55]],"ltp":0.0,"tv":0.0,"id":60443}]}]}
{"op":"mcm","clk":"11885619815","pt":1724183518669,"mc":[{"id":"1.231875383","rc":[{"batb":[[0,1.51,16.82],[1,1.5,20],[2,1.16,40]],"ltp":1.04,"tv":2.0,"id":31379},{"batb":[[0,1.51,16.82],[1,1.5,20],[2,1.16,40]],"ltp":0.0,"tv":0.0,"id":655},{"batb":[[0,1.49,17.51],[1,1.48,5.99],[2,1.47,40]],"ltp":0.0,"tv":0.0,"id":60443}]}]}
{"op":"mcm","clk":"11885644674","pt":1724183676330,"mc":[{"id":"1.231875383","rc":[{"batb":[[0,1.5,40],[1,1.49,17.51],[2,1.48,5.99]],"ltp":0.0,"tv":0.0,"id":60443}]}]}
{"op":"mcm","clk":"11885872374","pt":1724185318978,"mc":[{"id":"1.231875383","rc":[{"batb":[[0,1.51,16.82]],"ltp":1.04,"tv":2.0,"id":31379},{"batb":[[0,1.51,16.82]],"ltp":0.0,"tv":0.0,"id":655},{"batb":[[1,1.48,5.99],[2,1.44,37.56]],"ltp":0.0,"tv":0.0,"id":60443}]}]}
{"op":"mcm","clk":"11885872416","pt":1724185319394,"mc":[{"id":"1.231875383","rc":[{"batb":[[0,1.5,20],[1,1.16,40],[2,1.09,222.22]],"ltp":1.04,"tv":2.0,"id":31379},{"batb":[[0,1.5,20],[1,1.16,40],[2,1.09,222.22]],"ltp":0.0,"tv":0.0,"id":655}]}]}
{"op":"mcm","clk":"11885888614","pt":1724185442631,"mc":[{"id":"1.231875383","rc":[{"batb":[[0,1.51,16.82],[1,1.5,20],[2,1.16,40]],"ltp":1.04,"tv":2.0,"id":31379},{"batb":[[0,1.51,16.82],[1,1.5,20],[2,1.16,40]],"ltp":0.0,"tv":0.0,"id":655},{"batb":[[0,1.51,16.82],[1,1.5,40],[2,1.48,5.99]],"ltp":0.0,"tv":0.0,"id":60443}]}]}
{"op":"mcm","clk":"11885938508","pt":1724185824622,"mc":[{"id":"1.231875383","rc":[{"batb":[[0,1.51,22.81],[2,1.44,37.56]],"ltp":0.0,"tv":0.0,"id":60443}]}]}
{"op":"mcm","clk":"11886077147","pt":1724187242916,"mc":[{"id":"1.231875383","rc":[{"batb":[[0,1.5,20],[1,1.16,40],[2,1.09,222.22]],"ltp":0.0,"tv":0.0,"id":655},{"batb":[[0,1.51,5.99]],"ltp":0.0,"tv":0.0,"id":60443}]}]}
{"op":"mcm","clk":"11886077160","pt":1724187243123,"mc":[{"id":"1.231875383","rc":[{"batb":[[0,1.5,20],[1,1.16,40],[2,1.09,222.22]],"ltp":1.04,"tv":2.0,"id":31379}]}]}
{"op":"mcm","clk":"11886080508","pt":1724187294499,"mc":[{"id":"1.231875383","rc":[{"batb":[[0,1.51,16.82],[1,1.5,20],[2,1.16,40]],"ltp":1.04,"tv":2.0,"id":31379},{"batb":[[0,1.51,16.82],[1,1.5,20],[2,1.16,40]],"ltp":0.0,"tv":0.0,"id":655},{"batb":[[0,1.52,16.5],[1,1.51,5.99],[2,1.5,40]],"ltp":0.0,"tv":0.0,"id":60443}]}]}
{"op":"mcm","clk":"11886189610","pt":1724189094966,"mc":[{"id":"1.231875383","rc":[{"batb":[[0,1.5,20],[1,1.16,40],[2,1.09,222.22]],"ltp":1.04,"tv":2.0,"id":31379},{"batb":[[0,1.51,16.83]],"ltp":0.0,"tv":0.0,"id":655},{"batb":[[0,1.51,5.99],[1,1.5,40],[2,1.44,37.57]],"ltp":0.0,"tv":0.0,"id":60443}]}]}
{"op":"mcm","clk":"11886189622","pt":1724189095276,"mc":[{"id":"1.231875383","rc":[{"batb":[[0,1.5,20],[1,1.16,40],[2,1.09,222.22]],"ltp":0.0,"tv":0.0,"id":655}]}]}
{"op":"mcm","clk":"11886193704","pt":1724189181657,"mc":[{"id":"1.231875383","rc":[{"batb":[[0,1.51,16.83],[1,1.5,20],[2,1.16,40]],"ltp":1.04,"tv":2.0,"id":31379},{"batb":[[0,1.51,16.83],[1,1.5,20],[2,1.16,40]],"ltp":0.0,"tv":0.0,"id":655},{"batb":[[0,1.52,16.5],[1,1.51,5.99],[2,1.5,40]],"ltp":0.0,"tv":0.0,"id":60443}]}]}
{"op":"mcm","clk":"11886291444","pt":1724190982001,"mc":[{"id":"1.231875383","rc":[{"batb":[[0,1.5,20],[1,1.16,40],[2,1.09,222.22]],"ltp":1.04,"tv":2.0,"id":31379},{"batb":[[0,1.51,5.99],[1,1.5,40],[2,1.44,37.57]],"ltp":0.0,"tv":0.0,"id":60443}]}]}
{"op":"mcm","clk":"11886291457","pt":1724190982221,"mc":[{"id":"1.231875383","rc":[{"batb":[[0,1.5,20],[1,1.16,40],[2,1.09,222.22]],"ltp":0.0,"tv":0.0,"id":655}]}]}
{"op":"mcm","clk":"11886293992","pt":1724191032987,"mc":[{"id":"1.231875383","rc":[{"batb":[[0,1.51,16.83],[1,1.5,20],[2,1.16,40]],"ltp":1.04,"tv":2.0,"id":31379},{"batb":[[0,1.51,16.83],[1,1.5,20],[2,1.16,40]],"ltp":0.0,"tv":0.0,"id":655},{"batb":[[0,1.52,16.5],[1,1.51,5.99],[2,1.5,40]],"ltp":0.0,"tv":0.0,"id":60443}]}]}
{"op":"mcm","clk":"11886407813","pt":1724192833619,"mc":[{"id":"1.231875383","rc":[{"batb":[[0,1.5,20],[1,1.16,40],[2,1.09,222.22]],"ltp":1.04,"tv":2.0,"id":31379},{"batb":[[0,1.5,20],[1,1.16,40],[2,1.09,222.22]],"ltp":0.0,"tv":0.0,"id":655},{"batb":[[0,1.51,5.99],[1,1.5,40],[2,1.44,37.57]],"ltp":0.0,"tv":0.0,"id":60443}]}]}
{"op":"mcm","clk":"11886410013","pt":1724192871272,"mc":[{"id":"1.231875383","rc":[{"batb":[[0,1.51,16.83],[1,1.5,20],[2,1.16,40]],"ltp":1.04,"tv":2.0,"id":31379},{"batb":[[0,1.51,16.83],[1,1.5,20],[2,1.16,40]],"ltp":0.0,"tv":0.0,"id":655},{"batb":[[0,1.52,16.51],[1,1.51,5.99],[2,1.5,40]],"ltp":0.0,"tv":0.0,"id":60443}]}]}
{"op":"mcm","clk":"11886463838","pt":1724193671836,"mc":[{"id":"1.231875383","rc":[{"batb":[[0,1.52,20],[1,1.51,16.83],[2,1.5,20]],"ltp":1.04,"tv":2.0,"id":31379}]}]}
{"op":"mcm","clk":"11886465249","pt":1724193691608,"mc":[{"id":"1.231875383","rc":[{"batb":[[0,1.52,20],[1,1.51,16.83],[2,1.5,20]],"ltp":0.0,"tv":0.0,"id":655}]}]}
{"op":"mcm","clk":"11886465971","pt":1724193701679,"mc":[{"id":"1.231875383","rc":[{"batb":[[0,1.53,20],[1,1.52,16.51],[2,1.51,5.99]],"ltp":0.0,"tv":0.0,"id":60443}]}]}
{"op":"mcm","clk":"11886466839","pt":1724193714134,"mc":[{"id":"1.231875383","rc":[{"batl":[[0,80,10.17],[1,85,1],[2,95,5.85]],"ltp":0.0,"tv":0.0,"id":655}]}]}
{"op":"mcm","clk":"11886466922","pt":1724193715420,"mc":[{"id":"1.231875383","rc":[{"batl":[[1,95,5.85],[2,990,5.51]],"ltp":0.0,"tv":0.0,"id":655}]}]}
{"op":"mcm","clk":"11886467229","pt":1724193721009,"mc":[{"id":"1.231875383","rc":[{"batl":[[0,80,10.17],[1,85,1],[2,95,5.85]],"ltp":1.04,"tv":2.0,"id":31379},{"batl":[[0,75,1.17],[1,80,10],[2,95,5.85]],"ltp":0.0,"tv":0.0,"id":655}]}]}
{"op":"mcm","clk":"11886467555","pt":1724193726608,"mc":[{"id":"1.231875383","rc":[{"batl":[[1,95,5.85],[2,990,5.51]],"ltp":1.04,"tv":2.0,"id":31379}]}]}
{"op":"mcm","clk":"11886467777","pt":1724193730358,"mc":[{"id":"1.231875383","rc":[{"batl":[[0,80,10.17],[1,85,1],[2,95,5.85]],"ltp":0.0,"tv":0.0,"id":60443}]}]}
{"op":"mcm","clk":"11886467902","pt":1724193732249,"mc":[{"id":"1.231875383","rc":[{"batl":[[0,75,1.17],[1,80,10],[2,95,5.85]],"ltp":1.04,"tv":2.0,"id":31379},{"batl":[[1,95,5.85],[2,990,5.51]],"ltp":0.0,"tv":0.0,"id":60443}]}]}
{"op":"mcm","clk":"11886468199","pt":1724193737648,"mc":[{"id":"1.231875383","rc":[{"batl":[[0,75,1.17],[1,80,10],[2,95,5.85]],"ltp":0.0,"tv":0.0,"id":60443}]}]}
{"op":"mcm","clk":"11886471242","pt":1724193786386,"mc":[{"id":"1.231875383","rc":[{"batl":[[0,70,10.17],[1,75,1]],"ltp":1.04,"tv":2.0,"id":31379}]}]}
{"op":"mcm","clk":"11886471324","pt":1724193787824,"mc":[{"id":"1.231875383","rc":[{"batl":[[1,95,5.85],[2,990,5.51]],"ltp":1.04,"tv":2.0,"id":31379}]}]}
{"op":"mcm","clk":"11886471651","pt":1724193793409,"mc":[{"id":"1.231875383","rc":[{"batl":[[0,65,1.17],[1,70,10],[2,95,5.85]],"ltp":1.04,"tv":2.0,"id":31379}]}]}
{"op":"mcm","clk":"11886471883","pt":1724193797003,"mc":[{"id":"1.231875383","rc":[{"batl":[[1,95,5.85],[2,990,5.51]],"ltp":0.0,"tv":0.0,"id":655}]}]}
{"op":"mcm","clk":"11886471893","pt":1724193797100,"mc":[{"id":"1.231875383","rc":[{"batl":[[0,70,10.17],[1,75,1],[2,95,5.85]],"ltp":0.0,"tv":0.0,"id":655}]}]}
{"op":"mcm","clk":"11886472023","pt":1724193798913,"mc":[{"id":"1.231875383","rc":[{"batl":[[1,95,5.85],[2,990,5.51]],"ltp":0.0,"tv":0.0,"id":655}]}]}
{"op":"mcm","clk":"11886472343","pt":1724193804454,"mc":[{"id":"1.231875383","rc":[{"batl":[[0,65,1.17],[1,70,10],[2,95,5.85]],"ltp":0.0,"tv":0.0,"id":655}]}]}
{"op":"mcm","clk":"11886472609","pt":1724193807634,"mc":[{"id":"1.231875383","rc":[{"batl":[[0,60,10.17],[1,75,1]],"ltp":0.0,"tv":0.0,"id":60443}]}]}
{"op":"mcm","clk":"11886472871","pt":1724193810144,"mc":[{"id":"1.231875383","rc":[{"batl":[[1,95,5.85],[2,990,5.51]],"ltp":0.0,"tv":0.0,"id":60443}]}]}
{"op":"mcm","clk":"11886473810","pt":1724193815663,"mc":[{"id":"1.231875383","rc":[{"batl":[[0,55,1.17],[1,60,10],[2,95,5.85]],"ltp":0.0,"tv":0.0,"id":60443}]}]}
{"op":"mcm","clk":"11886474058","pt":1724193817663,"mc":[{"id":"1.231875383","rc":[{"batl":[[0,55,10.17],[1,65,1]],"ltp":1.04,"tv":2.0,"id":31379}]}]}
{"op":"mcm","clk":"11886474522","pt":1724193821156,"mc":[{"id":"1.231875383","rc":[{"batl":[[1,95,5.85],[2,990,5.51]],"ltp":1.04,"tv":2.0,"id":31379}]}]}
{"op":"mcm","clk":"11886475317","pt":1724193826747,"mc":[{"id":"1.231875383","rc":[{"batl":[[0,50,1.17],[1,55,10],[2,95,5.85]],"ltp":1.04,"tv":2.0,"id":31379}]}]}
{"op":"mcm","clk":"11886475942","pt":1724193833566,"mc":[{"id":"1.231875383","rc":[{"batl":[[0,50,10.17],[1,65,1]],"ltp":0.0,"tv":0.0,"id":655}]}]}
{"op":"mcm","clk":"11886476247","pt":1724193837873,"mc":[{"id":"1.231875383","rc":[{"batl":[[1,95,5.85],[2,990,5.51]],"ltp":0.0,"tv":0.0,"id":655}]}]}
{"op":"mcm","clk":"11886476612","pt":1724193843364,"mc":[{"id":"1.231875383","rc":[{"batl":[[0,48,1.17],[1,50,10],[2,95,5.85]],"ltp":0.0,"tv":0.0,"id":655}]}]}
{"op":"mcm","clk":"11886476740","pt":1724193845587,"mc":[{"id":"1.231875383","rc":[{"batl":[[0,40,10],[1,50,1.17]],"ltp":1.04,"tv":2.0,"id":31379}]}]}
{"op":"mcm","clk":"11886476946","pt":1724193849021,"mc":[{"id":"1.231875383","rc":[{"batl":[[1,90,1.02],[2,95,5]],"ltp":1.04,"tv":2.0,"id":31379}]}]}
{"op":"mcm","clk":"11886477330","pt":1724193854619,"mc":[{"id":"1.231875383","rc":[{"batl":[[0,38,1],[1,40,10],[2,90,1.02]],"ltp":1.04,"tv":2.0,"id":31379}]}]}
{"op":"mcm","clk":"11886477963","pt":1724193863906,"mc":[{"id":"1.231875383","rc":[{"batl":[[0,36,10],[1,38,1]],"ltp":1.04,"tv":2.0,"id":31379}]}]}
{"op":"mcm","clk":"11886478332","pt":1724193865729,"mc":[{"id":"1.231875383","rc":[{"batl":[[1,90,1.02],[2,95,5]],"ltp":1.04,"tv":2.0,"id":31379}]}]}
{"op":"mcm","clk":"11886480635","pt":1724193882426,"mc":[{"id":"1.231875383","rc":[{"batl":[[0,34,1],[1,36,10],[2,90,1.02]],"ltp":1.04,"tv":2.0,"id":31379}]}]}
{"op":"mcm","clk":"11886480951","pt":1724193886510,"mc":[{"id":"1.231875383","rc":[{"batl":[[0,36,10],[1,48,1.17]],"ltp":0.0,"tv":0.0,"id":655}]}]}
{"op":"mcm","clk":"11886481089","pt":1724193887997,"mc":[{"id":"1.231875383","rc":[{"batl":[[1,90,1.02],[2,95,5]],"ltp":0.0,"tv":0.0,"id":655}]}]}
{"op":"mcm","clk":"11886481511","pt":1724193893516,"mc":[{"id":"1.231875383","rc":[{"batl":[[0,34,1],[1,36,10],[2,90,1.02]],"ltp":0.0,"tv":0.0,"id":655}]}]}
{"op":"mcm","clk":"11886481786","pt":1724193896708,"mc":[{"id":"1.231875383","rc":[{"batl":[[0,36,10],[1,55,1.17]],"ltp":0.0,"tv":0.0,"id":60443}]}]}
{"op":"mcm","clk":"11886482043","pt":1724193899139,"mc":[{"id":"1.231875383","rc":[{"batl":[[1,90,1.02],[2,95,5]],"ltp":0.0,"tv":0.0,"id":60443}]}]}
{"op":"mcm","clk":"11886482629","pt":1724193904634,"mc":[{"id":"1.231875383","rc":[{"batl":[[0,34,1],[1,36,10],[2,90,1.02]],"ltp":0.0,"tv":0.0,"id":60443}]}]}
{"op":"mcm","clk":"11886482835","pt":1724193907053,"mc":[{"id":"1.231875383","rc":[{"batl":[[0,32,10],[1,34,1]],"ltp":0.0,"tv":0.0,"id":60443}]}]}
{"op":"mcm","clk":"11886483332","pt":1724193911927,"mc":[{"id":"1.231875383","rc":[{"batl":[[0,29,10]],"ltp":0.0,"tv":0.0,"id":60443}]}]}
{"op":"mcm","clk":"11886483707","pt":1724193915858,"mc":[{"id":"1.231875383","rc":[{"batl":[[1,90,1.02],[2,95,5]],"ltp":0.0,"tv":0.0,"id":60443}]}]}
{"op":"mcm","clk":"11886484208","pt":1724193921368,"mc":[{"id":"1.231875383","rc":[{"batl":[[0,28,1],[1,29,10],[2,90,1.02]],"ltp":0.0,"tv":0.0,"id":60443}]}]}
{"op":"mcm","clk":"11886485396","pt":1724193934059,"mc":[{"id":"1.231875383","rc":[{"batl":[[1,90,1.02],[2,95,5]],"ltp":0.0,"tv":0.0,"id":60443}]}]}
{"op":"mcm","clk":"11886485408","pt":1724193934165,"mc":[{"id":"1.231875383","rc":[{"batl":[[0,27,10],[1,28,1],[2,90,1.02]],"ltp":0.0,"tv":0.0,"id":60443}]}]}
{"op":"mcm","clk":"11886485827","pt":1724193938044,"mc":[{"id":"1.231875383","rc":[{"batl":[[1,90,1.02],[2,95,5]],"ltp":0.0,"tv":0.0,"id":60443}]}]}
{"op":"mcm","clk":"11886486331","pt":1724193943674,"mc":[{"id":"1.231875383","rc":[{"batl":[[0,26,1],[1,27,10],[2,90,1.02]],"ltp":0.0,"tv":0.0,"id":60443}]}]}
{"op":"mcm","clk":"11886486667","pt":1724193947596,"mc":[{"id":"1.231875383","rc":[{"batl":[[0,25,10],[1,26,1]],"ltp":0.0,"tv":0.0,"id":60443}]}]}
{"op":"mcm","clk":"11886487291","pt":1724193954678,"mc":[{"id":"1.231875383","rc":[{"batl":[[1,90,1.02],[2,95,5]],"ltp":0.0,"tv":0.0,"id":60443}]}]}
{"op":"mcm","clk":"11886488164","pt":1724193960409,"mc":[{"id":"1.231875383","rc":[{"batl":[[0,24,1],[1,25,10],[2,90,1.02]],"ltp":0.0,"tv":0.0,"id":60443}]}]}
{"op":"mcm","clk":"11886488328","pt":1724193962011,"mc":[{"id":"1.231875383","rc":[{"batl":[[1,90,1.02],[2,95,5]],"ltp":0.0,"tv":0.0,"id":60443}]}]}
{"op":"mcm","clk":"11886488338","pt":1724193962114,"mc":[{"id":"1.231875383","rc":[{"batl":[[0,15,10],[1,24,1],[2,90,1.02]],"ltp":0.0,"tv":0.0,"id":60443}]}]}
{"op":"mcm","clk":"11886489427","pt":1724193971501,"mc":[{"id":"1.231875383","rc":[{"batl":[[1,90,1.02],[2,95,5]],"ltp":0.0,"tv":0.0,"id":60443}]}]}
{"op":"mcm","clk":"11886490067","pt":1724193977113,"mc":[{"id":"1.231875383","rc":[{"batl":[[0,14.5,1],[1,15,10],[2,90,1.02]],"ltp":0.0,"tv":0.0,"id":60443}]}]}
{"op":"mcm","clk":"11886490685","pt":1724193983308,"mc":[{"id":"1.231875383","rc":[{"batl":[[1,15,5]],"ltp":0.0,"tv":0.0,"id":60443}]}]}
{"op":"mcm","clk":"11886491195","pt":1724193988628,"mc":[{"id":"1.231875383","rc":[{"batl":[[0,10,5],[1,14.5,1]],"ltp":0.0,"tv":0.0,"id":60443}]}]}
{"op":"mcm","clk":"11886491710","pt":1724193993717,"mc":[{"id":"1.231875383","rc":[{"batl":[[1,90,1.02],[2,95,5]],"ltp":0.0,"tv":0.0,"id":60443}]}]}
{"op":"mcm","clk":"11886492261","pt":1724193999342,"mc":[{"id":"1.231875383","rc":[{"batl":[[0,9.8,1],[1,10,5],[2,90,1.02]],"ltp":0.0,"tv":0.0,"id":60443}]}]}
{"op":"mcm","clk":"11886492838","pt":1724194005625,"mc":[{"id":"1.231875383","rc":[{"batl":[[0,5,5],[1,9.8,1]],"ltp":0.0,"tv":0.0,"id":60443}]}]}
{"op":"mcm","clk":"11886493232","pt":1724194010521,"mc":[{"id":"1.231875383","rc":[{"batl":[[1,90,1.02],[2,95,5]],"ltp":0.0,"tv":0.0,"id":60443}]}]}
{"op":"mcm","clk":"11886493650","pt":1724194016035,"mc":[{"id":"1.231875383","rc":[{"batl":[[0,4.9,1],[1,5,5],[2,90,1.02]],"ltp":0.0,"tv":0.0,"id":60443}]}]}
{"op":"mcm","clk":"11886502093","pt":1724194119322,"mc":[{"id":"1.231875383","rc":[{"batl":[[0,3,5],[1,4.9,1]],"ltp":0.0,"tv":0.0,"id":60443}]}]}
{"op":"mcm","clk":"11886502298","pt":1724194121802,"mc":[{"id":"1.231875383","rc":[{"batl":[[1,90,1.02],[2,95,5]],"ltp":0.0,"tv":0.0,"id":60443}]}]}
{"op":"mcm","clk":"11886505105","pt":1724194159074,"mc":[{"id":"1.231875383","rc":[{"batl":[[0,10,10],[1,34,1]],"ltp":1.04,"tv":2.0,"id":31379}]}]}
{"op":"mcm","clk":"11886505247","pt":1724194160778,"mc":[{"id":"1.231875383","rc":[{"batl":[[1,90,1.02],[2,95,5]],"ltp":1.04,"tv":2.0,"id":31379}]}]}
{"op":"mcm","clk":"11886505649","pt":1724194166299,"mc":[{"id":"1.231875383","rc":[{"batl":[[0,9.8,1],[1,10,10],[2,90,1.02]],"ltp":1.04,"tv":2.0,"id":31379}]}]}
{"op":"mcm","clk":"11886505897","pt":1724194169867,"mc":[{"id":"1.231875383","rc":[{"batl":[[0,10,10],[1,34,1]],"ltp":0.0,"tv":0.0,"id":655}]}]}
{"op":"mcm","clk":"11886506047","pt":1724194171886,"mc":[{"id":"1.231875383","rc":[{"batl":[[1,90,1.02],[2,95,5]],"ltp":0.0,"tv":0.0,"id":655}]}]}
{"op":"mcm","clk":"11886506424","pt":1724194177395,"mc":[{"id":"1.231875383","rc":[{"batl":[[0,9.8,1],[1,10,10],[2,90,1.02]],"ltp":0.0,"tv":0.0,"id":655}]}]}
{"op":"mcm","clk":"11886507373","pt":1724194189394,"mc":[{"id":"1.231875383","rc":[{"batl":[[0,4,5]],"ltp":0.0,"tv":0.0,"id":60443}]}]}
{"op":"mcm","clk":"11886507748","pt":1724194194119,"mc":[{"id":"1.231875383","rc":[{"batl":[[0,3.95,1],[1,4,5],[2,90,1.02]],"ltp":0.0,"tv":0.0,"id":60443}]}]}
{"op":"mcm","clk":"11886541264","pt":1724194671785,"mc":[{"id":"1.231875383","rc":[{"batb":[[1,1.5,20],[2,1.16,40]],"ltp":1.04,"tv":2.0,"id":31379},{"batb":[[1,1.5,20],[2,1.16,40]],"ltp":0.0,"tv":0.0,"id":655},{"batb":[[1,1.51,5.99],[2,1.5,40]],"ltp":0.0,"tv":0.0,"id":60443}]}]}
{"op":"mcm","clk":"11886542691","pt":1724194692537,"mc":[{"id":"1.231875383","rc":[{"batb":[[0,1.56,15.33],[1,1.52,20],[2,1.5,20]],"ltp":1.04,"tv":2.0,"id":31379},{"batb":[[0,1.56,15.33],[1,1.52,20],[2,1.5,20]],"ltp":0.0,"tv":0.0,"id":655},{"batb":[[0,1.54,15.89],[1,1.53,20],[2,1.51,5.99]],"ltp":0.0,"tv":0.0,"id":60443}]}]}
{"op":"mcm","clk":"11886666683","pt":1724196492978,"mc":[{"id":"1.231875383","rc":[{"batb":[[0,1.56,15.33]],"ltp":1.04,"tv":2.0,"id":31379},{"batb":[[0,1.52,20],[1,1.5,20],[2,1.16,40]],"ltp":0.0,"tv":0.0,"id":655},{"batb":[[0,1.53,20],[1,1.51,5.99],[2,1.5,40]],"ltp":0.0,"tv":0.0,"id":60443}]}]}
{"op":"mcm","clk":"11886666697","pt":1724196493182,"mc":[{"id":"1.231875383","rc":[{"batb":[[0,1.52,20],[1,1.5,20],[2,1.16,40]],"ltp":1.04,"tv":2.0,"id":31379}]}]}
{"op":"mcm","clk":"11886674473","pt":1724196609338,"mc":[{"id":"1.231875383","rc":[{"batb":[[0,1.56,15.33],[1,1.52,20],[2,1.5,20]],"ltp":1.04,"tv":2.0,"id":31379},{"batb":[[0,1.56,15.33],[1,1.52,20],[2,1.5,20]],"ltp":0.0,"tv":0.0,"id":655},{"batb":[[0,1.54,15.9],[1,1.53,20],[2,1.51,5.99]],"ltp":0.0,"tv":0.0,"id":60443}]}]}
{"op":"mcm","clk":"11886804076","pt":1724198410023,"mc":[{"id":"1.231875383","rc":[{"batb":[[0,1.52,20],[1,1.5,20],[2,1.16,40]],"ltp":1.04,"tv":2.0,"id":31379},{"batb":[[0,1.52,20],[1,1.5,20],[2,1.16,40]],"ltp":0.0,"tv":0.0,"id":655},{"batb":[[0,1.53,20],[1,1.51,5.99],[2,1.5,40]],"ltp":0.0,"tv":0.0,"id":60443}]}]}
{"op":"mcm","clk":"11886809223","pt":1724198503811,"mc":[{"id":"1.231875383","rc":[{"batb":[[0,1.56,15.32],[1,1.52,20],[2,1.5,20]],"ltp":1.04,"tv":2.0,"id":31379},{"batb":[[0,1.56,15.32],[1,1.52,20],[2,1.5,20]],"ltp":0.0,"tv":0.0,"id":655},{"batb":[[0,1.54,15.89],[1,1.53,20],[2,1.51,5.99]],"ltp":0.0,"tv":0.0,"id":60443}]}]}
{"op":"mcm","clk":"11886910807","pt":1724200304410,"mc":[{"id":"1.231875383","rc":[{"batb":[[0,1.52,20],[1,1.5,20],[2,1.16,40]],"ltp":1.04,"tv":2.0,"id":31379},{"batb":[[0,1.52,20],[1,1.5,20],[2,1.16,40]],"ltp":0.0,"tv":0.0,"id":655},{"batb":[[0,1.53,20],[1,1.51,5.99],[2,1.5,40]],"ltp":0.0,"tv":0.0,"id":60443}]}]}
{"op":"mcm","clk":"11886913463","pt":1724200358561,"mc":[{"id":"1.231875383","rc":[{"batb":[[0,1.56,15.32],[1,1.52,20],[2,1.5,20]],"ltp":1.04,"tv":2.0,"id":31379},{"batb":[[0,1.56,15.32],[1,1.52,20],[2,1.5,20]],"ltp":0.0,"tv":0.0,"id":655},{"batb":[[0,1.54,15.89],[1,1.53,20],[2,1.51,5.99]],"ltp":0.0,"tv":0.0,"id":60443}]}]}
{"op":"mcm","clk":"11886990168","pt":1724202158976,"mc":[{"id":"1.231875383","rc":[{"batb":[[0,1.52,20],[1,1.5,20],[2,1.16,40]],"ltp":1.04,"tv":2.0,"id":31379},{"batb":[[0,1.56,15.32]],"ltp":0.0,"tv":0.0,"id":655},{"batb":[[0,1.53,20],[1,1.51,5.99],[2,1.5,40]],"ltp":0.0,"tv":0.0,"id":60443}]}]}
{"op":"mcm","clk":"11886990175","pt":1724202159183,"mc":[{"id":"1.231875383","rc":[{"batb":[[0,1.52,20],[1,1.5,20],[2,1.16,40]],"ltp":0.0,"tv":0.0,"id":655}]}]}
{"op":"mcm","clk":"11886991327","pt":1724202189211,"mc":[{"id":"1.231875383","rc":[{"batb":[[0,1.56,15.32],[1,1.52,20],[2,1.5,20]],"ltp":1.04,"tv":2.0,"id":31379},{"batb":[[0,1.56,15.32],[1,1.52,20],[2,1.5,20]],"ltp":0.0,"tv":0.0,"id":655},{"batb":[[0,1.54,15.89],[1,1.53,20],[2,1.51,5.99]],"ltp":0.0,"tv":0.0,"id":60443}]}]}
{"op":"mcm","clk":"11887076563","pt":1724203989876,"mc":[{"id":"1.231875383","rc":[{"batb":[[0,1.52,20],[1,1.5,20],[2,1.16,40]],"ltp":1.04,"tv":2.0,"id":31379},{"batb":[[0,1.52,20],[1,1.5,20],[2,1.16,40]],"ltp":0.0,"tv":0.0,"id":655},{"batb":[[0,1.53,20],[1,1.51,5.99],[2,1.5,40]],"ltp":0.0,"tv":0.0,"id":60443}]}]}
{"op":"mcm","clk":"11887076843","pt":1724203997061,"mc":[{"id":"1.231875383","rc":[{"batb":[[0,1.56,15.32],[1,1.52,20],[2,1.5,20]],"ltp":1.04,"tv":2.0,"id":31379},{"batb":[[0,1.56,15.32],[1,1.52,20],[2,1.5,20]],"ltp":0.0,"tv":0.0,"id":655},{"batb":[[0,1.54,15.89],[1,1.53,20],[2,1.51,5.99]],"ltp":0.0,"tv":0.0,"id":60443}]}]}
{"op":"mcm","clk":"11887151377","pt":1724205797721,"mc":[{"id":"1.231875383","rc":[{"batb":[[0,1.52,20],[1,1.5,20],[2,1.16,40]],"ltp":1.04,"tv":2.0,"id":31379},{"batb":[[0,1.52,20],[1,1.5,20],[2,1.16,40]],"ltp":0.0,"tv":0.0,"id":655},{"batb":[[0,1.53,20],[1,1.51,6],[2,1.5,40]],"ltp":0.0,"tv":0.0,"id":60443}]}]}
{"op":"mcm","clk":"11887153727","pt":1724205893529,"mc":[{"id":"1.231875383","rc":[{"batb":[[0,1.56,15.33],[1,1.52,20],[2,1.5,20]],"ltp":1.04,"tv":2.0,"id":31379},{"batb":[[0,1.56,15.33],[1,1.52,20],[2,1.5,20]],"ltp":0.0,"tv":0.0,"id":655},{"batb":[[0,1.54,15.89],[1,1.53,20],[2,1.51,6]],"ltp":0.0,"tv":0.0,"id":60443}]}]}
{"op":"mcm","clk":"11887215152","pt":1724207694076,"mc":[{"id":"1.231875383","rc":[{"batb":[[0,1.52,20],[1,1.5,20],[2,1.16,40]],"ltp":1.04,"tv":2.0,"id":31379},{"batb":[[0,1.53,20],[1,1.51,6],[2,1.5,40]],"ltp":0.0,"tv":0.0,"id":60443}]}]}
{"op":"mcm","clk":"11887215157","pt":1724207694280,"mc":[{"id":"1.231875383","rc":[{"batb":[[0,1.52,20],[1,1.5,20],[2,1.16,40]],"ltp":0.0,"tv":0.0,"id":655}]}]}
{"op":"mcm","clk":"11887217051","pt":1724207761662,"mc":[{"id":"1.231875383","rc":[{"batb":[[0,1.56,15.33],[1,1.52,20],[2,1.5,20]],"ltp":1.04,"tv":2.0,"id":31379},{"batb":[[0,1.56,15.33],[1,1.52,20],[2,1.5,20]],"ltp":0.0,"tv":0.0,"id":655},{"batb":[[0,1.54,15.89],[1,1.53,20],[2,1.51,6]],"ltp":0.0,"tv":0.0,"id":60443}]}]}
{"op":"mcm","clk":"11887283966","pt":1724209561921,"mc":[{"id":"1.231875383","rc":[{"batb":[[0,1.52,20],[1,1.5,20],[2,1.16,40]],"ltp":1.04,"tv":2.0,"id":31379},{"batb":[[0,1.56,15.32]],"ltp":0.0,"tv":0.0,"id":655},{"batb":[[0,1.54,15.89]],"ltp":0.0,"tv":0.0,"id":60443}]}]}
{"op":"mcm","clk":"11887283984","pt":1724209562336,"mc":[{"id":"1.231875383","rc":[{"batb":[[0,1.52,20],[1,1.5,20],[2,1.16,40]],"ltp":0.0,"tv":0.0,"id":655},{"batb":[[0,1.53,20],[1,1.51,5.99],[2,1.5,40]],"ltp":0.0,"tv":0.0,"id":60443}]}]}
{"op":"mcm","clk":"11887285166","pt":1724209596474,"mc":[{"id":"1.231875383","rc":[{"batb":[[0,1.56,15.32],[1,1.52,20],[2,1.5,20]],"ltp":1.04,"tv":2.0,"id":31379},{"batb":[[0,1.56,15.32],[1,1.52,20],[2,1.5,20]],"ltp":0.0,"tv":0.0,"id":655},{"batb":[[0,1.54,15.89],[1,1.53,20],[2,1.51,5.99]],"ltp":0.0,"tv":0.0,"id":60443}]}]}
{"op":"mcm","clk":"11887341283","pt":1724211396986,"mc":[{"id":"1.231875383","rc":[{"batb":[[0,1.52,20],[1,1.5,20],[2,1.16,40]],"ltp":1.04,"tv":2.0,"id":31379},{"batb":[[0,1.52,20],[1,1.5,20],[2,1.16,40]],"ltp":0.0,"tv":0.0,"id":655},{"batb":[[0,1.53,20],[1,1.51,5.99],[2,1.5,40]],"ltp":0.0,"tv":0.0,"id":60443}]}]}
{"op":"mcm","clk":"11887342129","pt":1724211419088,"mc":[{"id":"1.231875383","rc":[{"batb":[[0,1.56,15.32],[1,1.52,20],[2,1.5,20]],"ltp":1.04,"tv":2.0,"id":31379},{"batb":[[0,1.56,15.32],[1,1.52,20],[2,1.5,20]],"ltp":0.0,"tv":0.0,"id":655},{"batb":[[0,1.54,15.89],[1,1.53,20],[2,1.51,5.99]],"ltp":0.0,"tv":0.0,"id":60443}]}]}
{"op":"mcm","clk":"11887401424","pt":1724213219725,"mc":[{"id":"1.231875383","rc":[{"batb":[[0,1.52,20],[1,1.5,20],[2,1.16,40]],"ltp":1.04,"tv":2.0,"id":31379},{"batb":[[0,1.52,20],[1,1.5,20],[2,1.16,40]],"ltp":0.0,"tv":0.0,"id":655},{"batb":[[0,1.53,20],[1,1.51,6],[2,1.5,40]],"ltp":0.0,"tv":0.0,"id":60443}]}]}
{"op":"mcm","clk":"11887401742","pt":1724213232153,"mc":[{"id":"1.231875383","rc":[{"batb":[[0,1.56,15.32],[1,1.52,20],[2,1.5,20]],"ltp":1.04,"tv":2.0,"id":31379},{"batb":[[0,1.56,15.32],[1,1.52,20],[2,1.5,20]],"ltp":0.0,"tv":0.0,"id":655},{"batb":[[0,1.54,15.89],[1,1.53,20],[2,1.51,6]],"ltp":0.0,"tv":0.0,"id":60443}]}]}
{"op":"mcm","clk":"11887454068","pt":1724215032856,"mc":[{"id":"1.231875383","rc":[{"batb":[[0,1.52,20],[1,1.5,20],[2,1.16,40]],"ltp":1.04,"tv":2.0,"id":31379},{"batb":[[0,1.52,20],[1,1.5,20],[2,1.16,40]],"ltp":0.0,"tv":0.0,"id":655},{"batb":[[0,1.53,20],[1,1.51,6],[2,1.5,40]],"ltp":0.0,"tv":0.0,"id":60443}]}]}
{"op":"mcm","clk":"11887456834","pt":1724215126139,"mc":[{"id":"1.231875383","rc":[{"batb":[[0,1.56,15.32],[1,1.52,20],[2,1.5,20]],"ltp":1.04,"tv":2.0,"id":31379},{"batb":[[0,1.56,15.32],[1,1.52,20],[2,1.5,20]],"ltp":0.0,"tv":0.0,"id":655},{"batb":[[0,1.54,15.89],[1,1.53,20],[2,1.51,6]],"ltp":0.0,"tv":0.0,"id":60443}]}]}
{"op":"mcm","clk":"11887503390","pt":1724216926833,"mc":[{"id":"1.231875383","rc":[{"batb":[[0,1.52,20],[1,1.5,20],[2,1.16,40]],"ltp":1.04,"tv":2.0,"id":31379},{"batb":[[0,1.52,20],[1,1.5,20],[2,1.16,40]],"ltp":0.0,"tv":0.0,"id":655},{"batb":[[0,1.53,20],[1,1.51,6],[2,1.5,40]],"ltp":0.0,"tv":0.0,"id":60443}]}]}
{"op":"mcm","clk":"11887505288","pt":1724217011159,"mc":[{"id":"1.231875383","rc":[{"batb":[[0,1.56,15.32],[1,1.52,20],[2,1.5,20]],"ltp":1.04,"tv":2.0,"id":31379},{"batb":[[0,1.56,15.32],[1,1.52,20],[2,1.5,20]],"ltp":0.0,"tv":0.0,"id":655},{"batb":[[0,1.54,15.89],[1,1.53,20],[2,1.51,6]],"ltp":0.0,"tv":0.0,"id":60443}]}]}
{"op":"mcm","clk":"11887546602","pt":1724218811699,"mc":[{"id":"1.231875383","rc":[{"batb":[[0,1.52,20],[1,1.5,20],[2,1.16,40]],"ltp":1.04,"tv":2.0,"id":31379},{"batb":[[0,1.52,20],[1,1.5,20],[2,1.16,40]],"ltp":0.0,"tv":0.0,"id":655},{"batb":[[0,1.53,20],[1,1.51,6],[2,1.5,40]],"ltp":0.0,"tv":0.0,"id":60443}]}]}
{"op":"mcm","clk":"11887548559","pt":1724218889895,"mc":[{"id":"1.231875383","rc":[{"batb":[[0,1.56,15.32],[1,1.52,20],[2,1.5,20]],"ltp":1.04,"tv":2.0,"id":31379},{"batb":[[0,1.56,15.32],[1,1.52,20],[2,1.5,20]],"ltp":0.0,"tv":0.0,"id":655},{"batb":[[0,1.54,15.89],[1,1.53,20],[2,1.51,6]],"ltp":0.0,"tv":0.0,"id":60443}]}]}
{"op":"mcm","clk":"11887597943","pt":1724220690043,"mc":[{"id":"1.231875383","rc":[{"batb":[[0,1.56,15.32]],"ltp":1.04,"tv":2.0,"id":31379},{"batb":[[0,1.52,20],[1,1.5,20],[2,1.16,40]],"ltp":0.0,"tv":0.0,"id":655},{"batb":[[0,1.54,15.89],[2,1.51,6]],"ltp":0.0,"tv":0.0,"id":60443}]}]}
{"op":"mcm","clk":"11887597951","pt":1724220690451,"mc":[{"id":"1.231875383","rc":[{"batb":[[0,1.52,20],[1,1.5,20],[2,1.16,40]],"ltp":1.04,"tv":2.0,"id":31379},{"batb":[[0,1.53,20],[1,1.51,6],[2,1.5,40]],"ltp":0.0,"tv":0.0,"id":60443}]}]}
{"op":"mcm","clk":"11887599530","pt":1724220764512,"mc":[{"id":"1.231875383","rc":[{"batb":[[0,1.56,15.32],[1,1.52,20],[2,1.5,20]],"ltp":1.04,"tv":2.0,"id":31379},{"batb":[[0,1.56,15.32],[1,1.52,20],[2,1.5,20]],"ltp":0.0,"tv":0.0,"id":655},{"batb":[[0,1.54,15.89],[1,1.53,20],[2,1.51,6]],"ltp":0.0,"tv":0.0,"id":60443}]}]}
{"op":"mcm","clk":"11887642732","pt":1724222564913,"mc":[{"id":"1.231875383","rc":[{"batb":[[0,1.52,20],[1,1.5,20],[2,1.16,40]],"ltp":1.04,"tv":2.0,"id":31379},{"batb":[[0,1.52,20],[1,1.5,20],[2,1.16,40]],"ltp":0.0,"tv":0.0,"id":655}]}]}
{"op":"mcm","clk":"11887642739","pt":1724222565117,"mc":[{"id":"1.231875383","rc":[{"batb":[[0,1.53,20],[1,1.51,6],[2,1.5,40]],"ltp":0.0,"tv":0.0,"id":60443}]}]}
{"op":"mcm","clk":"11887644321","pt":1724222635496,"mc":[{"id":"1.231875383","rc":[{"batb":[[0,1.56,15.32],[1,1.52,20],[2,1.5,20]],"ltp":1.04,"tv":2.0,"id":31379},{"batb":[[0,1.56,15.32],[1,1.52,20],[2,1.5,20]],"ltp":0.0,"tv":0.0,"id":655},{"batb":[[0,1.54,15.89],[1,1.53,20],[2,1.51,6]],"ltp":0.0,"tv":0.0,"id":60443}]}]}
{"op":"mcm","clk":"11887696660","pt":1724224374954,"mc":[{"id":"1.231875383","rc":[{"batb":[[0,1.56,15.33]],"ltp":1.04,"tv":2.0,"id":31379},{"batb":[[0,1.56,15.33]],"ltp":0.0,"tv":0.0,"id":655},{"batb":[[0,1.54,15.9],[2,1.51,6]],"ltp":0.0,"tv":0.0,"id":60443}]}]}
{"op":"mcm","clk":"11887702358","pt":1724224435937,"mc":[{"id":"1.231875383","rc":[{"batb":[[0,1.52,20],[1,1.5,20],[2,1.16,40]],"ltp":0.0,"tv":0.0,"id":655},{"batb":[[0,1.53,20],[1,1.51,6],[2,1.5,40]],"ltp":0.0,"tv":0.0,"id":60443}]}]}
{"op":"mcm","clk":"11887702359","pt":1724224436141,"mc":[{"id":"1.231875383","rc":[{"batb":[[0,1.52,20],[1,1.5,20],[2,1.16,40]],"ltp":1.04,"tv":2.0,"id":31379}]}]}
{"op":"mcm","clk":"11887704155","pt":1724224502111,"mc":[{"id":"1.231875383","rc":[{"batb":[[0,1.56,15.33],[1,1.52,20],[2,1.5,20]],"ltp":1.04,"tv":2.0,"id":31379},{"batb":[[0,1.56,15.33],[1,1.52,20],[2,1.5,20]],"ltp":0.0,"tv":0.0,"id":655},{"batb":[[0,1.54,15.9],[1,1.53,20],[2,1.51,6]],"ltp":0.0,"tv":0.0,"id":60443}]}]}
{"op":"mcm","clk":"11887760746","pt":1724226302937,"mc":[{"id":"1.231875383","rc":[{"batb":[[0,1.52,20],[1,1.5,20],[2,1.16,40]],"ltp":1.04,"tv":2.0,"id":31379},{"batb":[[0,1.52,20],[1,1.5,20],[2,1.16,40]],"ltp":0.0,"tv":0.0,"id":655},{"batb":[[0,1.53,20],[1,1.51,6],[2,1.5,40]],"ltp":0.0,"tv":0.0,"id":60443}]}]}
{"op":"mcm","clk":"11887762890","pt":1724226363495,"mc":[{"id":"1.231875383","rc":[{"batb":[[0,1.56,15.33],[1,1.52,20],[2,1.5,20]],"ltp":1.04,"tv":2.0,"id":31379},{"batb":[[0,1.56,15.33],[1,1.52,20],[2,1.5,20]],"ltp":0.0,"tv":0.0,"id":655},{"batb":[[0,1.54,15.9],[1,1.53,20],[2,1.51,6]],"ltp":0.0,"tv":0.0,"id":60443}]}]}
{"op":"mcm","clk":"11887817496","pt":1724227990804,"mc":[{"id":"1.231875383","rc":[{"batb":[[0,3.5,1.54],[1,1.54,15.89],[2,1.53,20]],"ltp":0.0,"tv":0.0,"id":60443}]}]}
{"op":"mcm","clk":"11887817619","pt":1724227994029,"mc":[{"id":"1.231875383","rc":[{"batl":[[0,4,5],[1,90,1.02],[2,95,5]],"ltp":0.0,"tv":0.0,"id":60443}]}]}
{"op":"mcm","clk":"11887817669","pt":1724227995518,"mc":[{"id":"1.231875383","rc":[{"batb":[[0,1.54,15.89],[1,1.53,20],[2,1.51,6]],"ltp":0.0,"tv":0.0,"id":60443}]}]}
{"op":"mcm","clk":"11887817814","pt":1724227999521,"mc":[{"id":"1.231875383","rc":[{"batl":[[0,3.95,1],[1,4,5],[2,90,1.02]],"ltp":0.0,"tv":0.0,"id":60443}]}]}
{"op":"mcm","clk":"11887818365","pt":1724228015347,"mc":[{"id":"1.231875383","rc":[{"batb":[[0,3.5,2.31],[1,1.54,15.89],[2,1.53,20]],"ltp":0.0,"tv":0.0,"id":60443}]}]}
{"op":"mcm","clk":"11887818389","pt":1724228016224,"mc":[{"id":"1.231875383","rc":[{"batl":[[0,4,5],[1,90,1.02],[2,95,5]],"ltp":0.0,"tv":0.0,"id":60443}]}]}
{"op":"mcm","clk":"11887818630","pt":1724228022346,"mc":[{"id":"1.231875383","rc":[{"batb":[[0,1.54,15.89],[1,1.53,20],[2,1.51,6]],"ltp":0.0,"tv":0.0,"id":60443}]}]}
{"op":"mcm","clk":"11887818813","pt":1724228027346,"mc":[{"id":"1.231875383","rc":[{"batl":[[0,3.95,1],[1,4,5],[2,90,1.02]],"ltp":0.0,"tv":0.0,"id":60443}]}]}
{"op":"mcm","clk":"11887819828","pt":1724228054584,"mc":[{"id":"1.231875383","rc":[{"batb":[[0,3,2.31],[1,1.54,15.89],[2,1.53,20]],"ltp":0.0,"tv":0.0,"id":60443}]}]}
{"op":"mcm","clk":"11887819848","pt":1724228055295,"mc":[{"id":"1.231875383","rc":[{"batl":[[0,4,5],[1,90,1.02],[2,95,5]],"ltp":0.0,"tv":0.0,"id":60443}]}]}
{"op":"mcm","clk":"11887820096","pt":1724228062492,"mc":[{"id":"1.231875383","rc":[{"batb":[[0,1.54,15.89],[1,1.53,20],[2,1.51,6]],"ltp":0.0,"tv":0.0,"id":60443}]}]}
{"op":"mcm","clk":"11887820220","pt":1724228066403,"mc":[{"id":"1.231875383","rc":[{"batl":[[0,3.95,1],[1,4,5],[2,90,1.02]],"ltp":0.0,"tv":0.0,"id":60443}]}]}
{"op":"mcm","clk":"11887823631","pt":1724228163910,"mc":[{"id":"1.231875383","rc":[{"batb":[[0,1.52,20],[1,1.5,20],[2,1.16,40]],"ltp":1.04,"tv":2.0,"id":31379},{"batb":[[0,1.52,20],[1,1.5,20],[2,1.16,40]],"ltp":0.0,"tv":0.0,"id":655}]}]}
{"op":"mcm","clk":"11887823636","pt":1724228164115,"mc":[{"id":"1.231875383","rc":[{"batb":[[0,1.53,20],[1,1.51,6],[2,1.5,40]],"ltp":0.0,"tv":0.0,"id":60443}]}]}
{"op":"mcm","clk":"11887825595","pt":1724228228390,"mc":[{"id":"1.231875383","rc":[{"batb":[[0,1.56,15.33],[1,1.52,20],[2,1.5,20]],"ltp":1.04,"tv":2.0,"id":31379},{"batb":[[0,1.56,15.33],[1,1.52,20],[2,1.5,20]],"ltp":0.0,"tv":0.0,"id":655},{"batb":[[0,1.54,15.89],[1,1.53,20],[2,1.51,6]],"ltp":0.0,"tv":0.0,"id":60443}]}]}
{"op":"mcm","clk":"11887907335","pt":1724230029017,"mc":[{"id":"1.231875383","rc":[{"batb":[[0,1.52,20],[1,1.5,20],[2,1.16,40]],"ltp":1.04,"tv":2.0,"id":31379},{"batb":[[0,1.52,20],[1,1.5,20],[2,1.16,40]],"ltp":0.0,"tv":0.0,"id":655},{"batb":[[0,1.53,20],[1,1.51,6],[2,1.5,40]],"ltp":0.0,"tv":0.0,"id":60443}]}]}
{"op":"mcm","clk":"11887907968","pt":1724230045710,"mc":[{"id":"1.231875383","rc":[{"batb":[[0,1.56,15.33],[1,1.52,20],[2,1.5,20]],"ltp":1.04,"tv":2.0,"id":31379},{"batb":[[0,1.56,15.33],[1,1.52,20],[2,1.5,20]],"ltp":0.0,"tv":0.0,"id":655},{"batb":[[0,1.54,15.89],[1,1.53,20],[2,1.51,6]],"ltp":0.0,"tv":0.0,"id":60443}]}]}
{"op":"mcm","clk":"11887996827","pt":1724231848071,"mc":[{"id":"1.231875383","rc":[{"batb":[[0,1.52,20],[1,1.5,20],[2,1.16,40]],"ltp":1.04,"tv":2.0,"id":31379},{"batb":[[0,1.52,20],[1,1.5,20],[2,1.16,40]],"ltp":0.0,"tv":0.0,"id":655},{"batb":[[0,1.53,20],[1,1.51,6],[2,1.5,40]],"ltp":0.0,"tv":0.0,"id":60443}]}]}
{"op":"mcm","clk":"11887998981","pt":1724231893634,"mc":[{"id":"1.231875383","rc":[{"batb":[[0,1.56,15.33],[1,1.52,20],[2,1.5,20]],"ltp":1.04,"tv":2.0,"id":31379},{"batb":[[0,1.56,15.33],[1,1.52,20],[2,1.5,20]],"ltp":0.0,"tv":0.0,"id":655},{"batb":[[0,1.54,15.9],[1,1.53,20],[2,1.51,6]],"ltp":0.0,"tv":0.0,"id":60443}]}]}
{"op":"mcm","clk":"11888111422","pt":1724233693957,"mc":[{"id":"1.231875383","rc":[{"batb":[[0,1.53,20],[1,1.51,6],[2,1.5,40]],"ltp":0.0,"tv":0.0,"id":60443}]}]}
{"op":"mcm","clk":"11888111441","pt":1724233694398,"mc":[{"id":"1.231875383","rc":[{"batb":[[0,1.52,20],[1,1.5,20],[2,1.16,40]],"ltp":1.04,"tv":2.0,"id":31379},{"batb":[[0,1.52,20],[1,1.5,20],[2,1.16,40]],"ltp":0.0,"tv":0.0,"id":655}]}]}
{"op":"mcm","clk":"11888113566","pt":1724233738904,"mc":[{"id":"1.231875383","rc":[{"batb":[[0,1.56,15.33],[1,1.52,20],[2,1.5,20]],"ltp":1.04,"tv":2.0,"id":31379},{"batb":[[0,1.56,15.33],[1,1.52,20],[2,1.5,20]],"ltp":0.0,"tv":0.0,"id":655},{"batb":[[0,1.54,15.9],[1,1.53,20],[2,1.51,6]],"ltp":0.0,"tv":0.0,"id":60443}]}]}
{"op":"mcm","clk":"11888221890","pt":1724235174934,"mc":[{"id":"1.231875383","rc":[{"batb":[[0,1.56,15.32]],"batl":[[2,90,1.02]],"ltp":1.04,"tv":2.0,"id":31379},{"batb":[[0,1.56,15.32]],"batl":[[2,90,1.02]],"ltp":0.0,"tv":0.0,"id":655},{"batb":[[0,1.54,15.88],[2,1.51,6]],"batl":[[2,90,1.02]],"ltp":0.0,"tv":0.0,"id":60443}]}]}
{"op":"mcm","clk":"11888255405","pt":1724235541702,"mc":[{"id":"1.231875383","rc":[{"batb":[[0,1.52,20],[1,1.5,20],[2,1.16,40]],"ltp":1.04,"tv":2.0,"id":31379},{"batb":[[0,1.52,20],[1,1.5,20],[2,1.16,40]],"ltp":0.0,"tv":0.0,"id":655},{"batb":[[0,1.53,20],[1,1.51,6],[2,1.5,40]],"ltp":0.0,"tv":0.0,"id":60443}]}]}
{"op":"mcm","clk":"11888257979","pt":1724235573160,"mc":[{"id":"1.231875383","rc":[{"batb":[[0,1.56,15.32],[1,1.52,20],[2,1.5,20]],"ltp":1.04,"tv":2.0,"id":31379},{"batb":[[0,1.56,15.32],[1,1.52,20],[2,1.5,20]],"ltp":0.0,"tv":0.0,"id":655},{"batb":[[0,1.54,15.88],[1,1.53,20],[2,1.51,6]],"ltp":0.0,"tv":0.0,"id":60443}]}]}
{"op":"mcm","clk":"11888409258","pt":1724237373916,"mc":[{"id":"1.231875383","rc":[{"batb":[[0,1.52,20],[1,1.5,20],[2,1.16,40]],"ltp":1.04,"tv":2.0,"id":31379},{"batb":[[0,1.52,20],[1,1.5,20],[2,1.16,40]],"ltp":0.0,"tv":0.0,"id":655},{"batb":[[0,1.53,20],[1,1.51,6],[2,1.5,40]],"ltp":0.0,"tv":0.0,"id":60443}]}]}
{"op":"mcm","clk":"11888411541","pt":1724237400926,"mc":[{"id":"1.231875383","rc":[{"batb":[[0,1.56,15.32],[1,1.52,20],[2,1.5,20]],"ltp":1.04,"tv":2.0,"id":31379},{"batb":[[0,1.56,15.32],[1,1.52,20],[2,1.5,20]],"ltp":0.0,"tv":0.0,"id":655},{"batb":[[0,1.54,15.88],[1,1.53,20],[2,1.51,6]],"ltp":0.0,"tv":0.0,"id":60443}]}]}
{"op":"mcm","clk":"11888560659","pt":1724239202990,"mc":[{"id":"1.231875383","rc":[{"batb":[[0,1.52,20],[1,1.5,20],[2,1.16,40]],"ltp":1.04,"tv":2.0,"id":31379},{"batb":[[0,1.56,15.31]],"ltp":0.0,"tv":0.0,"id":655},{"batb":[[0,1.54,15.88],[2,1.51,5.99]],"ltp":0.0,"tv":0.0,"id":60443}]}]}
{"op":"mcm","clk":"11888560705","pt":1724239203406,"mc":[{"id":"1.231875383","rc":[{"batb":[[0,1.52,20],[1,1.5,20],[2,1.16,40]],"ltp":0.0,"tv":0.0,"id":655},{"batb":[[0,1.53,20],[1,1.51,5.99],[2,1.5,40]],"ltp":0.0,"tv":0.0,"id":60443}]}]}
{"op":"mcm","clk":"11888563345","pt":1724239231917,"mc":[{"id":"1.231875383","rc":[{"batb":[[0,1.56,15.31],[1,1.52,20],[2,1.5,20]],"ltp":1.04,"tv":2.0,"id":31379},{"batb":[[0,1.56,15.31],[1,1.52,20],[2,1.5,20]],"ltp":0.0,"tv":0.0,"id":655},{"batb":[[0,1.54,15.88],[1,1.53,20],[2,1.51,5.99]],"ltp":0.0,"tv":0.0,"id":60443}]}]}
{"op":"mcm","clk":"11888728161","pt":1724241033917,"mc":[{"id":"1.231875383","rc":[{"batb":[[0,1.52,20],[1,1.5,20],[2,1.16,40]],"ltp":1.04,"tv":2.0,"id":31379},{"batb":[[0,1.52,20],[1,1.5,20],[2,1.16,40]],"ltp":0.0,"tv":0.0,"id":655},{"batb":[[0,1.53,20],[1,1.51,5.99],[2,1.5,40]],"ltp":0.0,"tv":0.0,"id":60443}]}]}
{"op":"mcm","clk":"11888736970","pt":1724241135056,"mc":[{"id":"1.231875383","rc":[{"batb":[[0,1.56,15.31],[1,1.52,20],[2,1.5,20]],"ltp":1.04,"tv":2.0,"id":31379},{"batb":[[0,1.56,15.31],[1,1.52,20],[2,1.5,20]],"ltp":0.0,"tv":0.0,"id":655},{"batb":[[0,1.54,15.88],[1,1.53,20],[2,1.51,5.99]],"ltp":0.0,"tv":0.0,"id":60443}]}]}
{"op":"mcm","clk":"11888864093","pt":1724242936884,"mc":[{"id":"1.231875383","rc":[{"batb":[[0,1.52,20],[1,1.5,20],[2,1.16,40]],"ltp":1.04,"tv":2.0,"id":31379},{"batb":[[0,1.56,15.31]],"ltp":0.0,"tv":0.0,"id":655},{"batb":[[0,1.54,15.88],[2,1.51,5.99]],"ltp":0.0,"tv":0.0,"id":60443}]}]}
{"op":"mcm","clk":"11888864136","pt":1724242937353,"mc":[{"id":"1.231875383","rc":[{"batb":[[0,1.52,20],[1,1.5,20],[2,1.16,40]],"ltp":0.0,"tv":0.0,"id":655},{"batb":[[0,1.53,20],[1,1.51,5.99],[2,1.5,40]],"ltp":0.0,"tv":0.0,"id":60443}]}]}
{"op":"mcm","clk":"11888869486","pt":1724243015775,"mc":[{"id":"1.231875383","rc":[{"batb":[[0,1.56,15.31],[1,1.52,20],[2,1.5,20]],"ltp":1.04,"tv":2.0,"id":31379},{"batb":[[0,1.56,15.31],[1,1.52,20],[2,1.5,20]],"ltp":0.0,"tv":0.0,"id":655},{"batb":[[0,1.54,15.88],[1,1.53,20],[2,1.51,5.99]],"ltp":0.0,"tv":0.0,"id":60443}]}]}
{"op":"mcm","clk":"11888991416","pt":1724244817959,"mc":[{"id":"1.231875383","rc":[{"batb":[[0,1.52,20],[1,1.5,20],[2,1.16,40]],"ltp":1.04,"tv":2.0,"id":31379},{"batb":[[0,1.52,20],[1,1.5,20],[2,1.16,40]],"ltp":0.0,"tv":0.0,"id":655},{"batb":[[0,1.53,20],[1,1.51,5.99],[2,1.5,40]],"ltp":0.0,"tv":0.0,"id":60443}]}]}
{"op":"mcm","clk":"11888995133","pt":1724244871666,"mc":[{"id":"1.231875383","rc":[{"batb":[[0,1.56,15.31],[1,1.52,20],[2,1.5,20]],"ltp":1.04,"tv":2.0,"id":31379},{"batb":[[0,1.56,15.31],[1,1.52,20],[2,1.5,20]],"ltp":0.0,"tv":0.0,"id":655},{"batb":[[0,1.54,15.88],[1,1.53,20],[2,1.51,5.99]],"ltp":0.0,"tv":0.0,"id":60443}]}]}
{"op":"mcm","clk":"11889077391","pt":1724245974935,"mc":[{"id":"1.231875383","rc":[{"batb":[[0,1.56,15.31]],"ltp":1.04,"tv":2.0,"id":31379},{"batb":[[0,1.56,15.31]],"ltp":0.0,"tv":0.0,"id":655},{"batb":[[0,1.54,15.87],[2,1.51,5.99]],"ltp":0.0,"tv":0.0,"id":60443}]}]}
{"op":"mcm","clk":"11889128490","pt":1724246673703,"mc":[{"id":"1.231875383","rc":[{"batb":[[0,1.52,20],[1,1.5,20],[2,1.16,40]],"ltp":1.04,"tv":2.0,"id":31379},{"batb":[[0,1.52,20],[1,1.5,20],[2,1.16,40]],"ltp":0.0,"tv":0.0,"id":655},{"batb":[[0,1.53,20],[1,1.51,5.99],[2,1.5,40]],"ltp":0.0,"tv":0.0,"id":60443}]}]}
{"op":"mcm","clk":"11889130978","pt":1724246715637,"mc":[{"id":"1.231875383","rc":[{"batb":[[0,1.56,15.31],[1,1.52,20],[2,1.5,20]],"ltp":1.04,"tv":2.0,"id":31379},{"batb":[[0,1.56,15.31],[1,1.52,20],[2,1.5,20]],"ltp":0.0,"tv":0.0,"id":655},{"batb":[[0,1.54,15.87],[1,1.53,20],[2,1.51,5.99]],"ltp":0.0,"tv":0.0,"id":60443}]}]}
{"op":"mcm","clk":"11889171257","pt":1724247426089,"mc":[{"id":"1.231875383","rc":[{"batb":[[0,1.55,40],[1,1.54,15.87],[2,1.53,20]],"ltp":0.0,"tv":0.0,"id":60443}]}]}
{"op":"mcm","clk":"11889186419","pt":1724247655105,"mc":[{"id":"1.231875383","rc":[{"batb":[[0,1.56,5.99],[1,1.55,40],[2,1.54,15.87]],"ltp":0.0,"tv":0.0,"id":60443}]}]}
{"op":"mcm","clk":"11889232006","pt":1724248517705,"mc":[{"id":"1.231875383","rc":[{"batb":[[0,1.52,20],[1,1.5,20],[2,1.16,40]],"ltp":1.04,"tv":2.0,"id":31379},{"batb":[[0,1.52,20],[1,1.5,20],[2,1.16,40]],"ltp":0.0,"tv":0.0,"id":655},{"batb":[[2,1.53,20]],"ltp":0.0,"tv":0.0,"id":60443}]}]}
{"op":"mcm","clk":"11889233354","pt":1724248546437,"mc":[{"id":"1.231875383","rc":[{"batb":[[0,1.56,15.31],[1,1.52,20],[2,1.5,20]],"ltp":1.04,"tv":2.0,"id":31379},{"batb":[[0,1.56,15.31],[1,1.52,20],[2,1.5,20]],"ltp":0.0,"tv":0.0,"id":655},{"batb":[[0,1.57,15.04],[1,1.56,5.99],[2,1.55,40]],"ltp":0.0,"tv":0.0,"id":60443}]}]}
{"op":"mcm","clk":"11889242503","pt":1724248728460,"mc":[{"id":"1.231875383","rc":[{"batb":[[0,1.58,40],[1,1.57,15.04],[2,1.56,5.99]],"ltp":0.0,"tv":0.0,"id":60443}]}]}
{"op":"mcm","clk":"11889310293","pt":1724249808052,"mc":[{"id":"1.231875383","rc":[{"batb":[[0,1.56,15.29]],"ltp":1.04,"tv":2.0,"id":31379},{"batb":[[0,1.56,15.29]],"ltp":0.0,"tv":0.0,"id":655},{"batb":[[0,1.59,5.99],[1,1.58,40],[2,1.57,15.02]],"ltp":0.0,"tv":0.0,"id":60443}]}]}
{"op":"mcm","clk":"11889342870","pt":1724250348740,"mc":[{"id":"1.231875383","rc":[{"batb":[[0,1.52,20],[1,1.5,20],[2,1.16,40]],"ltp":1.04,"tv":2.0,"id":31379},{"batb":[[0,1.52,20],[1,1.5,20],[2,1.16,40]],"ltp":0.0,"tv":0.0,"id":655},{"batb":[[2,1.53,20]],"ltp":0.0,"tv":0.0,"id":60443}]}]}
{"op":"mcm","clk":"11889343774","pt":1724250364484,"mc":[{"id":"1.231875383","rc":[{"batb":[[0,1.56,15.29],[1,1.52,20],[2,1.5,20]],"ltp":1.04,"tv":2.0,"id":31379},{"batb":[[0,1.56,15.29],[1,1.52,20],[2,1.5,20]],"ltp":0.0,"tv":0.0,"id":655},{"batb":[[0,1.6,14.27],[1,1.59,5.99],[2,1.58,40]],"ltp":0.0,"tv":0.0,"id":60443}]}]}
{"op":"mcm","clk":"11889472363","pt":1724252167027,"mc":[{"id":"1.231875383","rc":[{"batb":[[0,1.52,20],[1,1.5,20],[2,1.16,40]],"ltp":0.0,"tv":0.0,"id":655},{"batb":[[0,1.59,5.99],[1,1.58,40],[2,1.53,20]],"ltp":0.0,"tv":0.0,"id":60443}]}]}
{"op":"mcm","clk":"11889472372","pt":1724252167129,"mc":[{"id":"1.231875383","rc":[{"batb":[[0,1.52,20],[1,1.5,20],[2,1.16,40]],"ltp":1.04,"tv":2.0,"id":31379}]}]}
{"op":"mcm","clk":"11889481405","pt":1724252295613,"mc":[{"id":"1.231875383","rc":[{"batb":[[0,1.56,15.29],[1,1.52,20],[2,1.5,20]],"ltp":1.04,"tv":2.0,"id":31379},{"batb":[[0,1.56,15.29],[1,1.52,20],[2,1.5,20]],"ltp":0.0,"tv":0.0,"id":655},{"batb":[[0,1.6,14.27],[1,1.59,5.99],[2,1.58,40]],"ltp":0.0,"tv":0.0,"id":60443}]}]}
{"op":"mcm","clk":"11889657136","pt":1724254097784,"mc":[{"id":"1.231875383","rc":[{"batb":[[0,1.52,20],[1,1.5,20],[2,1.16,40]],"ltp":1.04,"tv":2.0,"id":31379},{"batb":[[0,1.52,20],[1,1.5,20],[2,1.16,40]],"ltp":0.0,"tv":0.0,"id":655},{"batb":[[0,1.59,5.98],[1,1.58,40],[2,1.53,20]],"ltp":0.0,"tv":0.0,"id":60443}]}]}
{"op":"mcm","clk":"11889674900","pt":1724254263379,"mc":[{"id":"1.231875383","rc":[{"batb":[[0,1.56,15.29],[1,1.52,20],[2,1.5,20]],"ltp":1.04,"tv":2.0,"id":31379},{"batb":[[0,1.56,15.29],[1,1.52,20],[2,1.5,20]],"ltp":0.0,"tv":0.0,"id":655},{"batb":[[0,1.6,14.27],[1,1.59,5.98],[2,1.58,40]],"ltp":0.0,"tv":0.0,"id":60443}]}]}
{"op":"mcm","clk":"11889904713","pt":1724256064049,"mc":[{"id":"1.231875383","rc":[{"batb":[[0,1.56,15.29]],"ltp":1.04,"tv":2.0,"id":31379},{"batb":[[0,1.52,20],[1,1.5,20],[2,1.16,40]],"ltp":0.0,"tv":0.0,"id":655},{"batb":[[0,1.59,5.97],[1,1.58,40],[2,1.53,20]],"ltp":0.0,"tv":0.0,"id":60443}]}]}
{"op":"mcm","clk":"11889904751","pt":1724256064336,"mc":[{"id":"1.231875383","rc":[{"batb":[[0,1.52,20],[1,1.5,20],[2,1.16,40]],"ltp":1.04,"tv":2.0,"id":31379}]}]}
{"op":"mcm","clk":"11889925826","pt":1724256227917,"mc":[{"id":"1.231875383","rc":[{"batb":[[0,1.56,15.29],[1,1.52,20],[2,1.5,20]],"ltp":1.04,"tv":2.0,"id":31379},{"batb":[[0,1.56,15.29],[1,1.52,20],[2,1.5,20]],"ltp":0.0,"tv":0.0,"id":655},{"batb":[[0,1.6,14.27],[1,1.59,5.97],[2,1.58,40]],"ltp":0.0,"tv":0.0,"id":60443}]}]}
{"op":"mcm","clk":"11890165517","pt":1724258028649,"mc":[{"id":"1.231875383","rc":[{"batb":[[0,1.52,20],[1,1.5,20],[2,1.16,40]],"ltp":1.04,"tv":2.0,"id":31379},{"batb":[[0,1.52,20],[1,1.5,20],[2,1.16,40]],"ltp":0.0,"tv":0.0,"id":655},{"batb":[[0,1.59,5.97],[1,1.58,40],[2,1.53,20]],"ltp":0.0,"tv":0.0,"id":60443}]}]}
{"op":"mcm","clk":"11890184894","pt":1724258173341,"mc":[{"id":"1.231875383","rc":[{"batb":[[0,1.56,15.29],[1,1.52,20],[2,1.5,20]],"ltp":1.04,"tv":2.0,"id":31379},{"batb":[[0,1.56,15.29],[1,1.52,20],[2,1.5,20]],"ltp":0.0,"tv":0.0,"id":655},{"batb":[[0,1.6,14.27],[1,1.59,5.97],[2,1.58,40]],"ltp":0.0,"tv":0.0,"id":60443}]}]}
{"op":"mcm","clk":"11890420141","pt":1724259975874,"mc":[{"id":"1.231875383","rc":[{"batb":[[0,1.52,20],[1,1.5,20],[2,1.16,40]],"ltp":1.04,"tv":2.0,"id":31379},{"batb":[[0,1.52,20],[1,1.5,20],[2,1.16,40]],"ltp":0.0,"tv":0.0,"id":655},{"batb":[[0,1.59,5.97],[1,1.58,40],[2,1.53,20]],"ltp":0.0,"tv":0.0,"id":60443}]}]}
{"op":"mcm","clk":"11890425001","pt":1724260014492,"mc":[{"id":"1.231875383","rc":[{"batb":[[0,1.59,6.14]],"ltp":0.0,"tv":0.0,"id":60443}]}]}
{"op":"mcm","clk":"11890439694","pt":1724260130046,"mc":[{"id":"1.231875383","rc":[{"batb":[[0,1.56,15.28],[1,1.52,20],[2,1.5,20]],"ltp":1.04,"tv":2.0,"id":31379},{"batb":[[0,1.56,15.28],[1,1.52,20],[2,1.5,20]],"ltp":0.0,"tv":0.0,"id":655},{"batb":[[0,1.6,14.44],[1,1.59,5.97],[2,1.58,40]],"ltp":0.0,"tv":0.0,"id":60443}]}]}
{"op":"mcm","clk":"11890637546","pt":1724261931062,"mc":[{"id":"1.231875383","rc":[{"batb":[[0,1.52,20],[1,1.5,20],[2,1.16,40]],"ltp":1.04,"tv":2.0,"id":31379},{"batb":[[0,1.52,20],[1,1.5,20],[2,1.16,40]],"ltp":0.0,"tv":0.0,"id":655},{"batb":[[0,1.59,6.14],[1,1.58,40],[2,1.53,20]],"ltp":0.0,"tv":0.0,"id":60443}]}]}
{"op":"mcm","clk":"11890649819","pt":1724262043201,"mc":[{"id":"1.231875383","rc":[{"batb":[[0,1.56,15.28],[1,1.52,20],[2,1.5,20]],"ltp":1.04,"tv":2.0,"id":31379},{"batb":[[0,1.56,15.28],[1,1.52,20],[2,1.5,20]],"ltp":0.0,"tv":0.0,"id":655},{"batb":[[0,1.6,14.44],[1,1.59,5.97],[2,1.58,40]],"ltp":0.0,"tv":0.0,"id":60443}]}]}
{"op":"mcm","clk":"11890860834","pt":1724263843898,"mc":[{"id":"1.231875383","rc":[{"batb":[[0,1.56,15.29]],"ltp":1.04,"tv":2.0,"id":31379},{"batb":[[0,1.52,20],[1,1.5,20],[2,1.16,40]],"ltp":0.0,"tv":0.0,"id":655},{"batb":[[0,1.6,14.44],[1,1.59,5.96]],"ltp":0.0,"tv":0.0,"id":60443}]}]}
{"op":"mcm","clk":"11890860887","pt":1724263844259,"mc":[{"id":"1.231875383","rc":[{"batb":[[0,1.52,20],[1,1.5,20],[2,1.16,40]],"ltp":1.04,"tv":2.0,"id":31379},{"batb":[[0,1.59,6.14],[1,1.58,40],[2,1.53,20]],"ltp":0.0,"tv":0.0,"id":60443}]}]}
{"op":"mcm","clk":"11890869324","pt":1724263899738,"mc":[{"id":"1.231875383","rc":[{"batb":[[0,1.56,15.29],[1,1.52,20],[2,1.5,20]],"ltp":1.04,"tv":2.0,"id":31379},{"batb":[[0,1.56,15.29],[1,1.52,20],[2,1.5,20]],"ltp":0.0,"tv":0.0,"id":655},{"batb":[[0,1.6,14.44],[1,1.59,5.96],[2,1.58,40]],"ltp":0.0,"tv":0.0,"id":60443}]}]}
{"op":"mcm","clk":"11891131292","pt":1724265531489,"mc":[{"id":"1.231875383","rc":[{"batl":[[0,1.74,2.29],[1,9.8,1],[2,10,10]],"ltp":0.0,"tv":0.0,"id":655}]}]}
{"op":"mcm","clk":"11891131688","pt":1724265533805,"mc":[{"id":"1.231875383","rc":[{"batl":[[1,10,10],[2,90,1.02]],"ltp":0.0,"tv":0.0,"id":655},{"batl":[[0,4,5],[1,90,1.02],[2,95,5]],"ltp":0.0,"tv":0.0,"id":60443}]}]}
{"op":"mcm","clk":"11891132716","pt":1724265539981,"mc":[{"id":"1.231875383","rc":[{"batl":[[0,10,10],[1,90,1.02],[2,95,5]],"ltp":0.0,"tv":0.0,"id":655}]}]}
{"op":"mcm","clk":"11891133631","pt":1724265544996,"mc":[{"id":"1.231875383","rc":[{"batl":[[0,9.8,1],[1,10,10],[2,90,1.02]],"ltp":0.0,"tv":0.0,"id":655},{"batl":[[0,3.95,1],[1,4,5],[2,90,1.02]],"ltp":0.0,"tv":0.0,"id":60443}]}]}
{"op":"mcm","clk":"11891161874","pt":1724265700083,"mc":[{"id":"1.231875383","rc":[{"batb":[[0,1.52,20],[1,1.5,20],[2,1.16,40]],"ltp":0.0,"tv":0.0,"id":655}]}]}
{"op":"mcm","clk":"11891161969","pt":1724265700625,"mc":[{"id":"1.231875383","rc":[{"batb":[[0,1.52,20],[1,1.5,20],[2,1.16,40]],"ltp":1.04,"tv":2.0,"id":31379},{"batb":[[0,1.59,6.14],[1,1.58,40],[2,1.53,20]],"ltp":0.0,"tv":0.0,"id":60443}]}]}
{"op":"mcm","clk":"11891166685","pt":1724265726893,"mc":[{"id":"1.231875383","rc":[{"batb":[[0,1.56,15.29],[1,1.52,20],[2,1.5,20]],"ltp":1.04,"tv":2.0,"id":31379},{"batb":[[0,1.56,15.29],[1,1.52,20],[2,1.5,20]],"ltp":0.0,"tv":0.0,"id":655},{"batb":[[0,1.6,14.44],[1,1.59,5.96],[2,1.58,40]],"ltp":0.0,"tv":0.0,"id":60443}]}]}
{"op":"mcm","clk":"11891418787","pt":1724267527594,"mc":[{"id":"1.231875383","rc":[{"batb":[[0,1.52,20],[1,1.5,20],[2,1.16,40]],"ltp":1.04,"tv":2.0,"id":31379},{"batb":[[0,1.52,20],[1,1.5,20],[2,1.16,40]],"ltp":0.0,"tv":0.0,"id":655},{"batb":[[0,1.59,6.14],[1,1.58,40],[2,1.53,20]],"ltp":0.0,"tv":0.0,"id":60443}]}]}
{"op":"mcm","clk":"11891457085","pt":1724267697109,"mc":[{"id":"1.231875383","rc":[{"batb":[[0,1.56,15.28],[1,1.52,20],[2,1.5,20]],"ltp":1.04,"tv":2.0,"id":31379},{"batb":[[0,1.56,15.28],[1,1.52,20],[2,1.5,20]],"ltp":0.0,"tv":0.0,"id":655},{"batb":[[0,1.6,14.44],[1,1.59,5.96],[2,1.58,40]],"ltp":0.0,"tv":0.0,"id":60443}]}]}
{"op":"mcm","clk":"11891745638","pt":1724269497827,"mc":[{"id":"1.231875383","rc":[{"batb":[[0,1.52,20],[1,1.5,20],[2,1.16,40]],"ltp":1.04,"tv":2.0,"id":31379},{"batb":[[0,1.52,20],[1,1.5,20],[2,1.16,40]],"ltp":0.0,"tv":0.0,"id":655},{"batb":[[0,1.59,6.14],[1,1.58,40],[2,1.53,20]],"ltp":0.0,"tv":0.0,"id":60443}]}]}
{"op":"mcm","clk":"11891764311","pt":1724269624701,"mc":[{"id":"1.231875383","rc":[{"batb":[[0,1.56,15.28],[1,1.52,20],[2,1.5,20]],"ltp":1.04,"tv":2.0,"id":31379},{"batb":[[0,1.56,15.28],[1,1.52,20],[2,1.5,20]],"ltp":0.0,"tv":0.0,"id":655},{"batb":[[0,1.6,14.44],[1,1.59,5.96],[2,1.58,40]],"ltp":0.0,"tv":0.0,"id":60443}]}]}
{"op":"mcm","clk":"11891972250","pt":1724271426968,"mc":[{"id":"1.231875383","rc":[{"batb":[[0,1.52,20],[1,1.5,20],[2,1.16,40]],"ltp":1.04,"tv":2.0,"id":31379},{"batb":[[0,1.56,15.29]],"ltp":0.0,"tv":0.0,"id":655},{"batb":[[0,1.59,6.14],[1,1.58,40],[2,1.53,20]],"ltp":0.0,"tv":0.0,"id":60443}]}]}
{"op":"mcm","clk":"11891972268","pt":1724271427172,"mc":[{"id":"1.231875383","rc":[{"batb":[[0,1.52,20],[1,1.5,20],[2,1.16,40]],"ltp":0.0,"tv":0.0,"id":655}]}]}
{"op":"mcm","clk":"11891985344","pt":1724271549078,"mc":[{"id":"1.231875383","rc":[{"batb":[[0,1.56,15.29],[1,1.52,20],[2,1.5,20]],"ltp":1.04,"tv":2.0,"id":31379},{"batb":[[0,1.56,15.29],[1,1.52,20],[2,1.5,20]],"ltp":0.0,"tv":0.0,"id":655},{"batb":[[0,1.6,14.45],[1,1.59,5.97],[2,1.58,40]],"ltp":0.0,"tv":0.0,"id":60443}]}]}
{"op":"mcm","clk":"11892063628","pt":1724272298354,"mc":[{"id":"1.231875383","rc":[{"batb":[[0,1.8,62.5],[1,1.56,15.29],[2,1.52,20]],"ltp":0.0,"tv":0.0,"id":655}]}]}
{"op":"mcm","clk":"11892064531","pt":1724272307859,"mc":[{"id":"1.231875383","rc":[{"batb":[[0,1.8,62.5],[1,1.56,15.29],[2,1.52,20]],"ltp":1.04,"tv":2.0,"id":31379}]}]}
{"op":"mcm","clk":"11892176639","pt":1724273350978,"mc":[{"id":"1.231875383","rc":[{"batb":[[1,1.52,20],[2,1.5,20]],"ltp":1.04,"tv":2.0,"id":31379}]}]}
{"op":"mcm","clk":"11892176668","pt":1724273351352,"mc":[{"id":"1.231875383","rc":[{"batb":[[1,1.52,20],[2,1.5,20]],"ltp":0.0,"tv":0.0,"id":655},{"batb":[[0,1.59,6.14],[1,1.58,40],[2,1.53,20]],"ltp":0.0,"tv":0.0,"id":60443}]}]}
{"op":"mcm","clk":"11892180889","pt":1724273409319,"mc":[{"id":"1.231875383","rc":[{"batb":[[0,1.81,10.57],[1,1.8,62.5],[2,1.52,20]],"ltp":1.04,"tv":2.0,"id":31379},{"batb":[[0,1.81,10.57],[1,1.8,62.5],[2,1.52,20]],"ltp":0.0,"tv":0.0,"id":655},{"batb":[[0,1.6,14.45],[1,1.59,5.97],[2,1.58,40]],"ltp":0.0,"tv":0.0,"id":60443}]}]}
{"op":"mcm","clk":"11892329883","pt":1724275212011,"mc":[{"id":"1.231875383","rc":[{"batb":[[0,1.8,62.5],[1,1.52,20],[2,1.5,20]],"ltp":1.04,"tv":2.0,"id":31379},{"batb":[[0,1.81,10.57]],"ltp":0.0,"tv":0.0,"id":655},{"batb":[[0,1.59,6.14],[1,1.58,40],[2,1.53,20]],"ltp":0.0,"tv":0.0,"id":60443}]}]}
{"op":"mcm","clk":"11892329899","pt":1724275212218,"mc":[{"id":"1.231875383","rc":[{"batb":[[0,1.8,62.5],[1,1.52,20],[2,1.5,20]],"ltp":0.0,"tv":0.0,"id":655}]}]}
{"op":"mcm","clk":"11892331434","pt":1724275228653,"mc":[{"id":"1.231875383","rc":[{"batb":[[0,1.81,10.57],[1,1.8,62.5],[2,1.52,20]],"ltp":1.04,"tv":2.0,"id":31379},{"batb":[[0,1.81,10.57],[1,1.8,62.5],[2,1.52,20]],"ltp":0.0,"tv":0.0,"id":655},{"batb":[[0,1.6,14.44],[1,1.59,5.97],[2,1.58,40]],"ltp":0.0,"tv":0.0,"id":60443}]}]}
{"op":"mcm","clk":"11892490888","pt":1724277030954,"mc":[{"id":"1.231875383","rc":[{"batb":[[0,1.8,62.5],[1,1.52,20],[2,1.5,20]],"ltp":1.04,"tv":2.0,"id":31379},{"batb":[[0,1.8,62.5],[1,1.52,20],[2,1.5,20]],"ltp":0.0,"tv":0.0,"id":655}]}]}
{"op":"mcm","clk":"11892490922","pt":1724277031263,"mc":[{"id":"1.231875383","rc":[{"batb":[[0,1.59,6.14],[1,1.58,40],[2,1.53,20]],"ltp":0.0,"tv":0.0,"id":60443}]}]}
{"op":"mcm","clk":"11892503120","pt":1724277205174,"mc":[{"id":"1.231875383","rc":[{"batb":[[0,1.81,10.57],[1,1.8,62.5],[2,1.52,20]],"ltp":1.04,"tv":2.0,"id":31379},{"batb":[[0,1.81,10.57],[1,1.8,62.5],[2,1.52,20]],"ltp":0.0,"tv":0.0,"id":655},{"batb":[[0,1.6,14.44],[1,1.59,5.97],[2,1.58,40]],"ltp":0.0,"tv":0.0,"id":60443}]}]}
{"op":"mcm","clk":"11892601720","pt":1724278374893,"mc":[{"id":"1.231875383","rc":[{"batb":[[0,1.81,10.56]],"ltp":1.04,"tv":2.0,"id":31379},{"batb":[[0,1.81,10.56]],"ltp":0.0,"tv":0.0,"id":655},{"batb":[[0,1.6,14.44]],"ltp":0.0,"tv":0.0,"id":60443}]}]}
{"op":"mcm","clk":"11892661724","pt":1724279006946,"mc":[{"id":"1.231875383","rc":[{"batb":[[0,1.8,62.5],[1,1.52,20],[2,1.5,20]],"ltp":1.04,"tv":2.0,"id":31379},{"batb":[[0,1.8,62.5],[1,1.52,20],[2,1.5,20]],"ltp":0.0,"tv":0.0,"id":655},{"batb":[[0,1.59,6.14],[1,1.58,40],[2,1.53,20]],"ltp":0.0,"tv":0.0,"id":60443}]}]}
{"op":"mcm","clk":"11892673592","pt":1724279142173,"mc":[{"id":"1.231875383","rc":[{"batb":[[0,1.81,10.56],[1,1.8,62.5],[2,1.52,20]],"ltp":1.04,"tv":2.0,"id":31379},{"batb":[[0,1.81,10.56],[1,1.8,62.5],[2,1.52,20]],"ltp":0.0,"tv":0.0,"id":655},{"batb":[[0,1.6,14.44],[1,1.59,5.97],[2,1.58,40]],"ltp":0.0,"tv":0.0,"id":60443}]}]}
{"op":"mcm","clk":"11892832158","pt":1724280943068,"mc":[{"id":"1.231875383","rc":[{"batb":[[0,1.8,62.5],[1,1.52,20],[2,1.5,20]],"ltp":1.04,"tv":2.0,"id":31379},{"batb":[[0,1.8,62.5],[1,1.52,20],[2,1.5,20]],"ltp":0.0,"tv":0.0,"id":655},{"batb":[[0,1.59,6.14],[1,1.58,40],[2,1.53,20]],"ltp":0.0,"tv":0.0,"id":60443}]}]}
{"op":"mcm","clk":"11892840621","pt":1724281059408,"mc":[{"id":"1.231875383","rc":[{"batb":[[0,1.81,10.56],[1,1.8,62.5],[2,1.52,20]],"ltp":1.04,"tv":2.0,"id":31379},{"batb":[[0,1.81,10.56],[1,1.8,62.5],[2,1.52,20]],"ltp":0.0,"tv":0.0,"id":655},{"batb":[[0,1.6,14.44],[1,1.59,5.97],[2,1.58,40]],"ltp":0.0,"tv":0.0,"id":60443}]}]}
{"op":"mcm","clk":"11892994353","pt":1724282860572,"mc":[{"id":"1.231875383","rc":[{"batb":[[0,1.8,62.5],[1,1.52,20],[2,1.5,20]],"ltp":1.04,"tv":2.0,"id":31379},{"batb":[[0,1.8,62.5],[1,1.52,20],[2,1.5,20]],"ltp":0.0,"tv":0.0,"id":655},{"batb":[[0,1.59,6.14],[1,1.58,40],[2,1.53,20]],"ltp":0.0,"tv":0.0,"id":60443}]}]}
{"op":"mcm","clk":"11893002444","pt":1724282952704,"mc":[{"id":"1.231875383","rc":[{"batb":[[0,1.81,10.57],[1,1.8,62.5],[2,1.52,20]],"ltp":1.04,"tv":2.0,"id":31379},{"batb":[[0,1.81,10.57],[1,1.8,62.5],[2,1.52,20]],"ltp":0.0,"tv":0.0,"id":655},{"batb":[[0,1.6,14.45],[1,1.59,5.97],[2,1.58,40]],"ltp":0.0,"tv":0.0,"id":60443}]}]}
{"op":"mcm","clk":"11893152621","pt":1724284752996,"mc":[{"id":"1.231875383","rc":[{"batb":[[0,1.8,62.5],[1,1.52,20],[2,1.5,20]],"ltp":0.0,"tv":0.0,"id":655}]}]}
{"op":"mcm","clk":"11893152653","pt":1724284753354,"mc":[{"id":"1.231875383","rc":[{"batb":[[0,1.8,62.5],[1,1.52,20],[2,1.5,20]],"ltp":1.04,"tv":2.0,"id":31379},{"batb":[[0,1.59,6.14],[1,1.58,40],[2,1.53,20]],"ltp":0.0,"tv":0.0,"id":60443}]}]}
{"op":"mcm","clk":"11893157662","pt":1724284828322,"mc":[{"id":"1.231875383","rc":[{"batb":[[0,1.81,10.57],[1,1.8,62.5],[2,1.52,20]],"ltp":1.04,"tv":2.0,"id":31379},{"batb":[[0,1.81,10.57],[1,1.8,62.5],[2,1.52,20]],"ltp":0.0,"tv":0.0,"id":655},{"batb":[[0,1.6,14.45],[1,1.59,5.97],[2,1.58,40]],"ltp":0.0,"tv":0.0,"id":60443}]}]}
{"op":"mcm","clk":"11893269049","pt":1724286630608,"mc":[{"id":"1.231875383","rc":[{"batb":[[0,1.8,62.5],[1,1.52,20],[2,1.5,20]],"ltp":1.04,"tv":2.0,"id":31379},{"batb":[[0,1.8,62.5],[1,1.52,20],[2,1.5,20]],"ltp":0.0,"tv":0.0,"id":655},{"batb":[[0,1.59,6.14],[1,1.58,40],[2,1.53,20]],"ltp":0.0,"tv":0.0,"id":60443}]}]}
{"op":"mcm","clk":"11893272105","pt":1724286679274,"mc":[{"id":"1.231875383","rc":[{"batb":[[0,1.81,10.57],[1,1.8,62.5],[2,1.52,20]],"ltp":1.04,"tv":2.0,"id":31379},{"batb":[[0,1.81,10.57],[1,1.8,62.5],[2,1.52,20]],"ltp":0.0,"tv":0.0,"id":655},{"batb":[[0,1.6,14.45],[1,1.59,5.97],[2,1.58,40]],"ltp":0.0,"tv":0.0,"id":60443}]}]}
{"op":"mcm","clk":"11893382990","pt":1724288481977,"mc":[{"id":"1.231875383","rc":[{"batb":[[0,1.8,62.5],[1,1.52,20],[2,1.5,20]],"ltp":1.04,"tv":2.0,"id":31379},{"batb":[[0,1.8,62.5],[1,1.52,20],[2,1.5,20]],"ltp":0.0,"tv":0.0,"id":655},{"batb":[[0,1.59,6.14],[1,1.58,40],[2,1.53,20]],"ltp":0.0,"tv":0.0,"id":60443}]}]}
{"op":"mcm","clk":"11893384426","pt":1724288512121,"mc":[{"id":"1.231875383","rc":[{"batb":[[0,1.81,10.56],[1,1.8,62.5],[2,1.52,20]],"ltp":1.04,"tv":2.0,"id":31379},{"batb":[[0,1.81,10.56],[1,1.8,62.5],[2,1.52,20]],"ltp":0.0,"tv":0.0,"id":655},{"batb":[[0,1.6,14.44],[1,1.59,5.97],[2,1.58,40]],"ltp":0.0,"tv":0.0,"id":60443}]}]}
{"op":"mcm","clk":"11893480576","pt":1724290313012,"mc":[{"id":"1.231875383","rc":[{"batb":[[0,1.8,62.5],[1,1.52,20],[2,1.5,20]],"ltp":1.04,"tv":2.0,"id":31379},{"batb":[[0,1.8,62.5],[1,1.52,20],[2,1.5,20]],"ltp":0.0,"tv":0.0,"id":655},{"batb":[[0,1.59,6.14],[1,1.58,40],[2,1.53,20]],"ltp":0.0,"tv":0.0,"id":60443}]}]}
{"op":"mcm","clk":"11893481015","pt":1724290323490,"mc":[{"id":"1.231875383","rc":[{"batb":[[0,1.81,10.56],[1,1.8,62.5],[2,1.52,20]],"ltp":1.04,"tv":2.0,"id":31379},{"batb":[[0,1.81,10.56],[1,1.8,62.5],[2,1.52,20]],"ltp":0.0,"tv":0.0,"id":655},{"batb":[[0,1.6,14.44],[1,1.59,5.97],[2,1.58,40]],"ltp":0.0,"tv":0.0,"id":60443}]}]}
{"op":"mcm","clk":"11893584989","pt":1724292125672,"mc":[{"id":"1.231875383","rc":[{"batb":[[0,1.8,62.5],[1,1.52,20],[2,1.5,20]],"ltp":1.04,"tv":2.0,"id":31379},{"batb":[[0,1.8,62.5],[1,1.52,20],[2,1.5,20]],"ltp":0.0,"tv":0.0,"id":655},{"batb":[[0,1.59,6.15],[1,1.58,40],[2,1.53,20]],"ltp":0.0,"tv":0.0,"id":60443}]}]}
{"op":"mcm","clk":"11893594453","pt":1724292281487,"mc":[{"id":"1.231875383","rc":[{"batb":[[0,1.81,10.56],[1,1.8,62.5],[2,1.52,20]],"ltp":1.04,"tv":2.0,"id":31379},{"batb":[[0,1.81,10.56],[1,1.8,62.5],[2,1.52,20]],"ltp":0.0,"tv":0.0,"id":655},{"batb":[[0,1.6,14.44],[1,1.59,5.97],[2,1.58,40]],"ltp":0.0,"tv":0.0,"id":60443}]}]}
{"op":"mcm","clk":"11893697856","pt":1724294083822,"mc":[{"id":"1.231875383","rc":[{"batb":[[0,1.8,62.5],[1,1.52,20],[2,1.5,20]],"ltp":1.04,"tv":2.0,"id":31379},{"batb":[[0,1.8,62.5],[1,1.52,20],[2,1.5,20]],"ltp":0.0,"tv":0.0,"id":655},{"batb":[[0,1.59,6.15],[1,1.58,40],[2,1.53,20]],"ltp":0.0,"tv":0.0,"id":60443}]}]}
{"op":"mcm","clk":"11893705217","pt":1724294216258,"mc":[{"id":"1.231875383","rc":[{"batb":[[0,1.81,10.56],[1,1.8,62.5],[2,1.52,20]],"ltp":1.04,"tv":2.0,"id":31379},{"batb":[[0,1.81,10.56],[1,1.8,62.5],[2,1.52,20]],"ltp":0.0,"tv":0.0,"id":655},{"batb":[[0,1.6,14.44],[1,1.59,5.97],[2,1.58,40]],"ltp":0.0,"tv":0.0,"id":60443}]}]}
{"op":"mcm","clk":"11893794544","pt":1724296016957,"mc":[{"id":"1.231875383","rc":[{"batb":[[0,1.8,62.5],[1,1.52,20],[2,1.5,20]],"ltp":0.0,"tv":0.0,"id":655},{"batb":[[0,1.59,6.15],[1,1.58,40],[2,1.53,20]],"ltp":0.0,"tv":0.0,"id":60443}]}]}
{"op":"mcm","clk":"11893794549","pt":1724296017161,"mc":[{"id":"1.231875383","rc":[{"batb":[[0,1.8,62.5],[1,1.52,20],[2,1.5,20]],"ltp":1.04,"tv":2.0,"id":31379}]}]}
{"op":"mcm","clk":"11893799174","pt":1724296126319,"mc":[{"id":"1.231875383","rc":[{"batb":[[0,1.81,10.56],[1,1.8,62.5],[2,1.52,20]],"ltp":1.04,"tv":2.0,"id":31379},{"batb":[[0,1.81,10.56],[1,1.8,62.5],[2,1.52,20]],"ltp":0.0,"tv":0.0,"id":655},{"batb":[[0,1.6,14.44],[1,1.59,5.97],[2,1.58,40]],"ltp":0.0,"tv":0.0,"id":60443}]}]}
{"op":"mcm","clk":"11893871603","pt":1724297928072,"mc":[{"id":"1.231875383","rc":[{"batb":[[0,1.8,62.5],[1,1.52,20],[2,1.5,20]],"ltp":0.0,"tv":0.0,"id":655}]}]}
{"op":"mcm","clk":"11893871613","pt":1724297928330,"mc":[{"id":"1.231875383","rc":[{"batb":[[0,1.8,62.5],[1,1.52,20],[2,1.5,20]],"ltp":1.04,"tv":2.0,"id":31379},{"batb":[[0,1.59,6.15],[1,1.58,40],[2,1.53,20]],"ltp":0.0,"tv":0.0,"id":60443}]}]}
{"op":"mcm","clk":"11893875406","pt":1724298024818,"mc":[{"id":"1.231875383","rc":[{"batb":[[0,1.81,10.56],[1,1.8,62.5],[2,1.52,20]],"ltp":1.04,"tv":2.0,"id":31379},{"batb":[[0,1.81,10.56],[1,1.8,62.5],[2,1.52,20]],"ltp":0.0,"tv":0.0,"id":655},{"batb":[[0,1.6,14.44],[1,1.59,5.97],[2,1.58,40]],"ltp":0.0,"tv":0.0,"id":60443}]}]}
{"op":"mcm","clk":"11893939864","pt":1724299828064,"mc":[{"id":"1.231875383","rc":[{"batb":[[0,1.8,62.5],[1,1.52,20],[2,1.5,20]],"ltp":1.04,"tv":2.0,"id":31379},{"batb":[[0,1.8,62.5],[1,1.52,20],[2,1.5,20]],"ltp":0.0,"tv":0.0,"id":655},{"batb":[[0,1.59,6.15],[1,1.58,40],[2,1.53,20]],"ltp":0.0,"tv":0.0,"id":60443}]}]}
{"op":"mcm","clk":"11893942978","pt":1724299912900,"mc":[{"id":"1.231875383","rc":[{"batb":[[0,1.81,10.57],[1,1.8,62.5],[2,1.52,20]],"ltp":1.04,"tv":2.0,"id":31379},{"batb":[[0,1.81,10.57],[1,1.8,62.5],[2,1.52,20]],"ltp":0.0,"tv":0.0,"id":655},{"batb":[[0,1.6,14.44],[1,1.59,5.97],[2,1.58,40]],"ltp":0.0,"tv":0.0,"id":60443}]}]}
{"op":"mcm","clk":"11894007879","pt":1724301714807,"mc":[{"id":"1.231875383","rc":[{"batb":[[0,1.8,62.5],[1,1.52,20],[2,1.5,20]],"ltp":1.04,"tv":2.0,"id":31379},{"batb":[[0,1.8,62.5],[1,1.52,20],[2,1.5,20]],"ltp":0.0,"tv":0.0,"id":655},{"batb":[[0,1.59,6.15],[1,1.58,40],[2,1.53,20]],"ltp":0.0,"tv":0.0,"id":60443}]}]}
{"op":"mcm","clk":"11894010237","pt":1724301787760,"mc":[{"id":"1.231875383","rc":[{"batb":[[0,1.81,10.57],[1,1.8,62.5],[2,1.52,20]],"ltp":1.04,"tv":2.0,"id":31379},{"batb":[[0,1.81,10.57],[1,1.8,62.5],[2,1.52,20]],"ltp":0.0,"tv":0.0,"id":655},{"batb":[[0,1.6,14.44],[1,1.59,5.97],[2,1.58,40]],"ltp":0.0,"tv":0.0,"id":60443}]}]}
{"op":"mcm","clk":"11894076961","pt":1724303589897,"mc":[{"id":"1.231875383","rc":[{"batb":[[0,1.8,62.5],[1,1.52,20],[2,1.5,20]],"ltp":1.04,"tv":2.0,"id":31379},{"batb":[[0,1.8,62.5],[1,1.52,20],[2,1.5,20]],"ltp":0.0,"tv":0.0,"id":655},{"batb":[[0,1.59,6.15],[1,1.58,40],[2,1.53,20]],"ltp":0.0,"tv":0.0,"id":60443}]}]}
{"op":"mcm","clk":"11894079856","pt":1724303664202,"mc":[{"id":"1.231875383","rc":[{"batb":[[0,1.81,10.57],[1,1.8,62.5],[2,1.52,20]],"ltp":1.04,"tv":2.0,"id":31379},{"batb":[[0,1.81,10.57],[1,1.8,62.5],[2,1.52,20]],"ltp":0.0,"tv":0.0,"id":655},{"batb":[[0,1.6,14.44],[1,1.59,5.97],[2,1.58,40]],"ltp":0.0,"tv":0.0,"id":60443}]}]}
{"op":"mcm","clk":"11894160751","pt":1724305465853,"mc":[{"id":"1.231875383","rc":[{"batb":[[0,1.8,62.5],[1,1.52,20],[2,1.5,20]],"ltp":1.04,"tv":2.0,"id":31379},{"batb":[[0,1.8,62.5],[1,1.52,20],[2,1.5,20]],"ltp":0.0,"tv":0.0,"id":655},{"batb":[[0,1.59,6.15],[1,1.58,40],[2,1.53,20]],"ltp":0.0,"tv":0.0,"id":60443}]}]}
{"op":"mcm","clk":"11894167908","pt":1724305607535,"mc":[{"id":"1.231875383","rc":[{"batb":[[0,1.81,10.57],[1,1.8,62.5],[2,1.52,20]],"ltp":1.04,"tv":2.0,"id":31379},{"batb":[[0,1.81,10.57],[1,1.8,62.5],[2,1.52,20]],"ltp":0.0,"tv":0.0,"id":655},{"batb":[[0,1.6,14.44],[1,1.59,5.97],[2,1.58,40]],"ltp":0.0,"tv":0.0,"id":60443}]}]}
{"op":"mcm","clk":"11894233804","pt":1724307408492,"mc":[{"id":"1.231875383","rc":[{"batb":[[0,1.8,62.5],[1,1.52,20],[2,1.5,20]],"ltp":1.04,"tv":2.0,"id":31379},{"batb":[[0,1.8,62.5],[1,1.52,20],[2,1.5,20]],"ltp":0.0,"tv":0.0,"id":655},{"batb":[[0,1.59,6.15],[1,1.58,40],[2,1.53,20]],"ltp":0.0,"tv":0.0,"id":60443}]}]}
{"op":"mcm","clk":"11894239382","pt":1724307535973,"mc":[{"id":"1.231875383","rc":[{"batb":[[0,1.81,10.57],[1,1.8,62.5],[2,1.52,20]],"ltp":1.04,"tv":2.0,"id":31379},{"batb":[[0,1.81,10.57],[1,1.8,62.5],[2,1.52,20]],"ltp":0.0,"tv":0.0,"id":655},{"batb":[[0,1.6,14.44],[1,1.59,5.97],[2,1.58,40]],"ltp":0.0,"tv":0.0,"id":60443}]}]}
{"op":"mcm","clk":"11894268799","pt":1724308288356,"mc":[{"id":"1.231875383","rc":[{"batl":[[0,9.8,1.54]],"ltp":0.0,"tv":0.0,"id":655}]}]}
{"op":"mcm","clk":"11894269077","pt":1724308296587,"mc":[{"id":"1.231875383","rc":[{"batl":[[0,9.8,1.54]],"ltp":1.04,"tv":2.0,"id":31379}]}]}
{"op":"mcm","clk":"11894269591","pt":1724308309476,"mc":[{"id":"1.231875383","rc":[{"batb":[[0,1.81,11.33]],"ltp":0.0,"tv":0.0,"id":655}]}]}
{"op":"mcm","clk":"11894269864","pt":1724308315602,"mc":[{"id":"1.231875383","rc":[{"batb":[[0,1.81,11.33]],"ltp":1.04,"tv":2.0,"id":31379}]}]}
{"op":"mcm","clk":"11894270270","pt":1724308326417,"mc":[{"id":"1.231875383","rc":[{"batl":[[2,90,1.56]],"ltp":0.0,"tv":0.0,"id":60443}]}]}
{"op":"mcm","clk":"11894309045","pt":1724309338420,"mc":[{"id":"1.231875383","rc":[{"batb":[[0,1.8,63.26],[1,1.52,20],[2,1.5,20]],"ltp":1.04,"tv":2.0,"id":31379},{"batb":[[0,1.8,63.26],[1,1.52,20],[2,1.5,20]],"ltp":0.0,"tv":0.0,"id":655},{"batb":[[0,1.59,6.15],[1,1.58,40],[2,1.53,20]],"ltp":0.0,"tv":0.0,"id":60443}]}]}
{"op":"mcm","clk":"11894313945","pt":1724309463513,"mc":[{"id":"1.231875383","rc":[{"batb":[[0,1.81,11.33],[1,1.8,62.5],[2,1.52,20]],"ltp":1.04,"tv":2.0,"id":31379},{"batb":[[0,1.81,11.33],[1,1.8,62.5],[2,1.52,20]],"ltp":0.0,"tv":0.0,"id":655},{"batb":[[0,1.6,14.44],[1,1.59,5.97],[2,1.58,40]],"ltp":0.0,"tv":0.0,"id":60443}]}]}
{"op":"mcm","clk":"11894373507","pt":1724310774910,"mc":[{"id":"1.231875383","rc":[{"batb":[[0,1.81,11.33]],"ltp":1.04,"tv":2.0,"id":31379},{"batb":[[0,1.81,11.33]],"ltp":0.0,"tv":0.0,"id":655},{"batb":[[1,1.59,5.97]],"ltp":0.0,"tv":0.0,"id":60443}]}]}
{"op":"mcm","clk":"11894398572","pt":1724311264002,"mc":[{"id":"1.231875383","rc":[{"batb":[[0,1.8,63.26],[1,1.52,20],[2,1.5,20]],"ltp":1.04,"tv":2.0,"id":31379},{"batb":[[0,1.59,6.14],[1,1.58,40],[2,1.53,20]],"ltp":0.0,"tv":0.0,"id":60443}]}]}
{"op":"mcm","clk":"11894398583","pt":1724311264209,"mc":[{"id":"1.231875383","rc":[{"batb":[[0,1.8,63.26],[1,1.52,20],[2,1.5,20]],"ltp":0.0,"tv":0.0,"id":655}]}]}
{"op":"mcm","clk":"11894403363","pt":1724311387209,"mc":[{"id":"1.231875383","rc":[{"batb":[[0,1.81,11.33],[1,1.8,62.5],[2,1.52,20]],"ltp":1.04,"tv":2.0,"id":31379},{"batb":[[0,1.81,11.33],[1,1.8,62.5],[2,1.52,20]],"ltp":0.0,"tv":0.0,"id":655},{"batb":[[0,1.6,14.44],[1,1.59,5.97],[2,1.58,40]],"ltp":0.0,"tv":0.0,"id":60443}]}]}
{"op":"mcm","clk":"11894461125","pt":1724313187417,"mc":[{"id":"1.231875383","rc":[{"batb":[[0,1.59,6.14],[1,1.58,40],[2,1.53,20]],"ltp":0.0,"tv":0.0,"id":60443}]}]}
{"op":"mcm","clk":"11894461193","pt":1724313189623,"mc":[{"id":"1.231875383","rc":[{"batb":[[0,1.8,63.26],[1,1.52,20],[2,1.5,20]],"ltp":1.04,"tv":2.0,"id":31379},{"batb":[[0,1.8,63.26],[1,1.52,20],[2,1.5,20]],"ltp":0.0,"tv":0.0,"id":655}]}]}
{"op":"mcm","clk":"11894465139","pt":1724313313491,"mc":[{"id":"1.231875383","rc":[{"batb":[[0,1.81,11.33],[1,1.8,62.5],[2,1.52,20]],"ltp":1.04,"tv":2.0,"id":31379},{"batb":[[0,1.81,11.33],[1,1.8,62.5],[2,1.52,20]],"ltp":0.0,"tv":0.0,"id":655},{"batb":[[0,1.6,14.44],[1,1.59,5.97],[2,1.58,40]],"ltp":0.0,"tv":0.0,"id":60443}]}]}
{"op":"mcm","clk":"11894543509","pt":1724315132323,"mc":[{"id":"1.231875383","rc":[{"batb":[[0,1.8,63.26],[1,1.52,20],[2,1.5,20]],"batl":[[2,90,1.02]],"ltp":1.04,"tv":2.0,"id":31379},{"batb":[[0,1.8,63.26],[1,1.52,20],[2,1.5,20]],"batl":[[2,90,1.02]],"ltp":0.0,"tv":0.0,"id":655},{"batb":[[0,1.59,6.14],[1,1.58,40],[2,1.53,20]],"batl":[[2,90,1.55]],"ltp":0.0,"tv":0.0,"id":60443}]}]}
{"op":"mcm","clk":"11894549001","pt":1724315241772,"mc":[{"id":"1.231875383","rc":[{"batb":[[0,1.81,11.31],[1,1.8,62.5],[2,1.52,20]],"ltp":1.04,"tv":2.0,"id":31379},{"batb":[[0,1.81,11.31],[1,1.8,62.5],[2,1.52,20]],"ltp":0.0,"tv":0.0,"id":655},{"batb":[[0,1.6,14.42],[1,1.59,5.96],[2,1.58,40]],"ltp":0.0,"tv":0.0,"id":60443}]}]}
{"op":"mcm","clk":"11894649397","pt":1724317042457,"mc":[{"id":"1.231875383","rc":[{"batb":[[0,1.8,63.26],[1,1.52,20],[2,1.5,20]],"ltp":1.04,"tv":2.0,"id":31379},{"batb":[[0,1.8,63.26],[1,1.52,20],[2,1.5,20]],"ltp":0.0,"tv":0.0,"id":655},{"batb":[[0,1.59,6.14],[1,1.58,40],[2,1.53,20]],"ltp":0.0,"tv":0.0,"id":60443}]}]}
{"op":"mcm","clk":"11894654559","pt":1724317168213,"mc":[{"id":"1.231875383","rc":[{"batb":[[0,1.81,11.31],[1,1.8,62.5],[2,1.52,20]],"ltp":1.04,"tv":2.0,"id":31379},{"batb":[[0,1.81,11.31],[1,1.8,62.5],[2,1.52,20]],"ltp":0.0,"tv":0.0,"id":655},{"batb":[[0,1.6,14.42],[1,1.59,5.96],[2,1.58,40]],"ltp":0.0,"tv":0.0,"id":60443}]}]}
{"op":"mcm","clk":"11894656634","pt":1724317212878,"mc":[{"id":"1.231875383","rc":[{"batb":[[0,1.82,10.76],[1,1.81,10.54],[2,1.8,62.5]],"ltp":1.04,"tv":2.0,"id":31379},{"trd":[[1.8,39.12],[1.81,21.08],[1.83,1.52]],"batb":[[0,1.81,10],[1,1.8,42.94]],"ltp":1.8,"tv":61.72,"id":655},{"batb":[[0,1.6,14.41],[1,1.59,5.96]],"batl":[[2,90,1.55]],"ltp":0.0,"tv":0.0,"id":60443}],"tv":63.72}]}
{"op":"mcm","clk":"11894656774","pt":1724317216170,"mc":[{"id":"1.231875383","rc":[{"batb":[[0,1.81,11.3],[1,1.8,62.5],[2,1.52,20]],"ltp":1.04,"tv":2.0,"id":31379},{"batb":[[0,1.8,42.94],[1,1.52,20],[2,1.5,20]],"ltp":1.8,"tv":61.72,"id":655}]}]}
{"op":"mcm","clk":"11894657030","pt":1724317222187,"mc":[{"id":"1.231875383","rc":[{"batb":[[0,1.82,10.76],[1,1.81,10.54],[2,1.8,62.5]],"ltp":1.04,"tv":2.0,"id":31379},{"batb":[[0,1.81,10],[1,1.8,42.94],[2,1.52,20]],"ltp":1.8,"tv":61.72,"id":655}]}]}
{"op":"mcm","clk":"11894657194","pt":1724317225983,"mc":[{"id":"1.231875383","rc":[{"batb":[[0,1.81,11.3],[1,1.8,62.5],[2,1.52,20]],"ltp":1.04,"tv":2.0,"id":31379},{"batb":[[0,1.8,42.94],[1,1.52,20],[2,1.5,20]],"ltp":1.8,"tv":61.72,"id":655}]}]}
{"op":"mcm","clk":"11894657344","pt":1724317230005,"mc":[{"id":"1.231875383","rc":[{"batb":[[0,1.82,10.76],[1,1.81,10.54],[2,1.8,62.5]],"ltp":1.04,"tv":2.0,"id":31379},{"batb":[[0,1.81,10],[1,1.8,42.94],[2,1.52,20]],"ltp":1.8,"tv":61.72,"id":655}]}]}
{"op":"mcm","clk":"11894657512","pt":1724317233401,"mc":[{"id":"1.231875383","rc":[{"batb":[[0,1.81,11.3],[1,1.8,62.5],[2,1.52,20]],"ltp":1.04,"tv":2.0,"id":31379},{"batb":[[0,1.8,42.94],[1,1.52,20],[2,1.5,20]],"ltp":1.8,"tv":61.72,"id":655}]}]}
{"op":"mcm","clk":"11894657739","pt":1724317237790,"mc":[{"id":"1.231875383","rc":[{"batb":[[0,1.82,10.76],[1,1.81,10.54],[2,1.8,62.5]],"ltp":1.04,"tv":2.0,"id":31379},{"batb":[[0,1.81,10],[1,1.8,42.94],[2,1.52,20]],"ltp":1.8,"tv":61.72,"id":655}]}]}
{"op":"mcm","clk":"11894657891","pt":1724317241203,"mc":[{"id":"1.231875383","rc":[{"batb":[[0,1.81,11.3],[1,1.8,62.5],[2,1.52,20]],"ltp":1.04,"tv":2.0,"id":31379},{"batb":[[0,1.8,42.94],[1,1.52,20],[2,1.5,20]],"ltp":1.8,"tv":61.72,"id":655}]}]}
{"op":"mcm","clk":"11894658198","pt":1724317247221,"mc":[{"id":"1.231875383","rc":[{"batb":[[0,1.82,10.76],[1,1.81,10.54],[2,1.8,62.5]],"ltp":1.04,"tv":2.0,"id":31379},{"batb":[[0,1.81,10],[1,1.8,42.94],[2,1.52,20]],"ltp":1.8,"tv":61.72,"id":655}]}]}
{"op":"mcm","clk":"11894658347","pt":1724317250618,"mc":[{"id":"1.231875383","rc":[{"batb":[[0,1.81,11.3],[1,1.8,62.5],[2,1.52,20]],"ltp":1.04,"tv":2.0,"id":31379},{"batb":[[0,1.8,42.94],[1,1.52,20],[2,1.5,20]],"ltp":1.8,"tv":61.72,"id":655}]}]}
{"op":"mcm","clk":"11894658483","pt":1724317253304,"mc":[{"id":"1.231875383","rc":[{"batb":[[0,1.82,10.76],[1,1.81,10.54],[2,1.8,62.5]],"ltp":1.04,"tv":2.0,"id":31379},{"batb":[[0,1.81,10],[1,1.8,42.94],[2,1.52,20]],"ltp":1.8,"tv":61.72,"id":655}]}]}
{"op":"mcm","clk":"11894658620","pt":1724317256634,"mc":[{"id":"1.231875383","rc":[{"batb":[[0,1.81,11.3],[1,1.8,62.5],[2,1.52,20]],"ltp":1.04,"tv":2.0,"id":31379},{"batb":[[0,1.8,42.94],[1,1.52,20],[2,1.5,20]],"ltp":1.8,"tv":61.72,"id":655}]}]}
{"op":"mcm","clk":"11894658733","pt":1724317259009,"mc":[{"id":"1.231875383","rc":[{"batb":[[0,1.82,10.76],[1,1.81,10.54],[2,1.8,62.5]],"batl":[[0,9.8,1.83]],"ltp":1.04,"tv":2.0,"id":31379},{"batb":[[0,1.81,10],[1,1.8,42.94],[2,1.52,20]],"batl":[[0,9.8,1.83]],"ltp":1.8,"tv":61.72,"id":655},{"batl":[[0,3.95,1.3]],"ltp":0.0,"tv":0.0,"id":60443}]}]}
{"op":"mcm","clk":"11894658737","pt":1724317259109,"mc":[{"id":"1.231875383","rc":[{"batb":[[0,1.82,11.06]],"ltp":1.04,"tv":2.0,"id":31379},{"batb":[[0,1.81,10.3]],"ltp":1.8,"tv":61.72,"id":655},{"batb":[[0,1.6,14.71]],"ltp":0.0,"tv":0.0,"id":60443}]}]}
{"op":"mcm","clk":"11894658913","pt":1724317262934,"mc":[{"id":"1.231875383","rc":[{"batb":[[0,1.82,1.06]],"ltp":1.04,"tv":2.0,"id":31379},{"batb":[[0,1.81,1.06]],"ltp":1.8,"tv":61.72,"id":655}]}]}
{"op":"mcm","clk":"11894672542","pt":1724317566064,"mc":[{"id":"1.231875383","rc":[{"batb":[[0,1.82,10.76]],"ltp":1.04,"tv":2.0,"id":31379},{"batb":[[0,1.8,43.7],[1,1.52,20],[2,1.5,20]],"ltp":1.8,"tv":61.72,"id":655}]}]}
{"op":"mcm","clk":"11894672603","pt":1724317566993,"mc":[{"id":"1.231875383","rc":[{"batb":[[0,1.81,10.76],[1,1.8,42.94],[2,1.52,20]],"ltp":1.8,"tv":61.72,"id":655},{"batb":[[0,1.6,14.41]],"batl":[[0,3.95,1]],"ltp":0.0,"tv":0.0,"id":60443}]}]}
{"op":"mcm","clk":"11894672685","pt":1724317568078,"mc":[{"id":"1.231875383","rc":[{"batl":[[0,3.95,1.3]],"ltp":0.0,"tv":0.0,"id":60443}]}]}
{"op":"mcm","clk":"11894672691","pt":1724317568181,"mc":[{"id":"1.231875383","rc":[{"batb":[[0,1.83,1.06],[1,1.82,10],[2,1.81,10.54]],"ltp":1.04,"tv":2.0,"id":31379},{"batb":[[0,1.82,1.06],[1,1.81,10],[2,1.8,42.94]],"ltp":1.8,"tv":61.72,"id":655},{"batb":[[0,1.6,14.71]],"ltp":0.0,"tv":0.0,"id":60443}]}]}
{"op":"mcm","clk":"11894672767","pt":1724317569576,"mc":[{"id":"1.231875383","rc":[{"batb":[[1,1.81,10.54],[2,1.8,62.5]],"ltp":1.04,"tv":2.0,"id":31379},{"batb":[[1,1.8,42.94],[2,1.52,20]],"ltp":1.8,"tv":61.72,"id":655}]}]}
{"op":"mcm","clk":"11894683163","pt":1724317781064,"mc":[{"id":"1.231875383","rc":[{"batb":[[0,1.84,20],[1,1.82,1.06],[2,1.8,42.94]],"ltp":1.8,"tv":61.72,"id":655}]}]}
{"op":"mcm","clk":"11894683176","pt":1724317781252,"mc":[{"id":"1.231875383","rc":[{"batb":[[0,1.85,10],[1,1.84,20],[2,1.82,1.06]],"ltp":1.8,"tv":61.72,"id":655}]}]}
{"op":"mcm","clk":"11894683349","pt":1724317784457,"mc":[{"id":"1.231875383","rc":[{"batb":[[0,1.84,20],[1,1.82,1.06],[2,1.8,42.94]],"ltp":1.8,"tv":61.72,"id":655}]}]}
{"op":"mcm","clk":"11894683475","pt":1724317787344,"mc":[{"id":"1.231875383","rc":[{"batb":[[0,1.85,10],[1,1.84,20],[2,1.82,1.06]],"ltp":1.8,"tv":61.72,"id":655}]}]}
{"op":"mcm","clk":"11894683652","pt":1724317790666,"mc":[{"id":"1.231875383","rc":[{"batb":[[0,1.84,20],[1,1.82,1.06],[2,1.8,42.94]],"ltp":1.8,"tv":61.72,"id":655}]}]}
{"op":"mcm","clk":"11894683759","pt":1724317792836,"mc":[{"id":"1.231875383","rc":[{"batb":[[0,1.85,10],[1,1.84,20],[2,1.82,1.06]],"ltp":1.8,"tv":61.72,"id":655}]}]}
