{"op":"mcm","clk":"11883522873","pt":1724068034209,"mc":[{"id":"1.232011465","marketDefinition":{"bspMarket":false,"turnInPlayEnabled":true,"persistenceEnabled":true,"marketBaseRate":5.0,"eventId":"33507997","eventTypeId":"4","numberOfWinners":1,"bettingType":"ODDS","marketType":"MATCH_ODDS","marketTime":"2024-08-19T16:00:00.000Z","suspendTime":"2024-08-19T16:00:00.000Z","bspReconciled":false,"complete":true,"inPlay":false,"crossMatching":true,"runnersVoidable":false,"numberOfActiveRunners":2,"betDelay":0,"status":"OPEN","runners":[{"status":"ACTIVE","sortPriority":1,"id":67083366,"name":"New York Strikers"},{"status":"ACTIVE","sortPriority":2,"id":72857115,"name":"Miami Lions"}],"regulators":["MR_INT"],"countryCode":"GB","discountAllowed":false,"timezone":"GMT","openDate":"2024-08-19T16:00:00.000Z","version":6086341230,"name":"Match Odds","eventName":"New York Strikers v Miami Lions"},"rc":[{"batb":[[0,1.03,200],[1,1.02,200],[2,1.01,220]],"ltp":0.0,"tv":0.0,"id":67083366},{"batb":[[0,1.03,200],[1,1.02,200],[2,1.01,220]],"ltp":0.0,"tv":0.0,"id":72857115}]}]}
{"op":"mcm","clk":"11883522933","pt":1724068035469,"mc":[{"id":"1.232011465","marketDefinition":{"bspMarket":false,"turnInPlayEnabled":true,"persistenceEnabled":true,"marketBaseRate":5.0,"eventId":"33507997","eventTypeId":"4","numberOfWinners":1,"bettingType":"ODDS","marketType":"MATCH_ODDS","marketTime":"2024-08-19T16:00:00.000Z","suspendTime":"2024-08-19T16:00:00.000Z","bspReconciled":false,"complete":true,"inPlay":false,"crossMatching":true,"runnersVoidable":false,"numberOfActiveRunners":2,"betDelay":0,"status":"OPEN","runners":[{"status":"ACTIVE","sortPriority":1,"id":67083366,"name":"New York Strikers"},{"status":"ACTIVE","sortPriority":2,"id":72857115,"name":"Miami Lions"}],"regulators":["MR_INT"],"countryCode":"GB","discountAllowed":true,"timezone":"GMT","openDate":"2024-08-19T16:00:00.000Z","version":6086341230,"name":"Match Odds","eventName":"New York Strikers v Miami Lions"}}]}
{"op":"mcm","clk":"11883536997","pt":1724068346485,"mc":[{"id":"1.232011465","rc":[{"batb":[[0,1.09,3.23],[1,1.03,200],[2,1.02,200]],"ltp":0.0,"tv":0.0,"id":72857115}]}]}
{"op":"mcm","clk":"11883537547","pt":1724068366810,"mc":[{"id":"1.232011465","rc":[{"batl":[[0,13,0.94]],"ltp":0.0,"tv":0.0,"id":72857115}]}]}
{"op":"mcm","clk":"11883537938","pt":1724068379451,"mc":[{"id":"1.232011465","rc":[{"batl":[[0,13,0.94]],"ltp":0.0,"tv":0.0,"id":67083366}]}]}
{"op":"mcm","clk":"11883538131","pt":1724068383607,"mc":[{"id":"1.232011465","rc":[{"batb":[[0,1.03,200],[1,1.02,200],[2,1.01,220]],"ltp":0.0,"tv":0.0,"id":72857115}]}]}
{"op":"mcm","clk":"11883554351","pt":1724068773828,"mc":[{"id":"1.232011465","rc":[{"batb":[[0,1.09,63.73],[1,1.03,200],[2,1.02,200]],"ltp":0.0,"tv":0.0,"id":67083366}]}]}
{"op":"mcm","clk":"11883554605","pt":1724068779119,"mc":[{"id":"1.232011465","rc":[{"trd":[[1.09,126.65]],"batb":[[0,1.03,200.4],[1,1.02,200],[2,1.01,220]],"ltp":1.09,"tv":126.65,"id":67083366}],"tv":126.65}]}
{"op":"mcm","clk":"11883554799","pt":1724068783455,"mc":[{"id":"1.232011465","rc":[{"batb":[[0,1.03,200]],"ltp":1.09,"tv":126.65,"id":67083366}]}]}
{"op":"mcm","clk":"11883555681","pt":1724068800855,"mc":[{"id":"1.232011465","rc":[{"batb":[[0,1.04,10],[1,1.03,200],[2,1.02,200]],"ltp":1.09,"tv":126.65,"id":67083366}]}]}
{"op":"mcm","clk":"11883555918","pt":1724068804278,"mc":[{"id":"1.232011465","rc":[{"trd":[[1.09,126.56]],"batb":[[0,1.03,200],[1,1.02,200],[2,1.01,220]],"ltp":1.09,"tv":126.55,"id":67083366}],"tv":126.55}]}
{"op":"mcm","clk":"11883556012","pt":1724068805889,"mc":[{"id":"1.232011465","rc":[{"batb":[[0,1.09,448.46],[1,1.03,200],[2,1.02,200]],"ltp":0.0,"tv":0.0,"id":72857115}]}]}
{"op":"mcm","clk":"11883556092","pt":1724068807183,"mc":[{"id":"1.232011465","rc":[{"batb":[[0,1.04,10],[1,1.03,200],[2,1.02,200]],"ltp":1.09,"tv":126.55,"id":67083366}]}]}
{"op":"mcm","clk":"11883556276","pt":1724068811399,"mc":[{"id":"1.232011465","rc":[{"batb":[[0,1.03,200],[1,1.02,200],[2,1.01,220]],"ltp":1.09,"tv":126.55,"id":67083366},{"trd":[[1.09,896.74]],"batb":[[0,1.04,10.09]],"ltp":1.09,"tv":896.74,"id":72857115}],"tv":1023.3}]}
{"op":"mcm","clk":"11883556358","pt":1724068813198,"mc":[{"id":"1.232011465","rc":[{"batb":[[0,1.04,10],[1,1.03,200],[2,1.02,200]],"ltp":1.09,"tv":126.55,"id":67083366}]}]}
{"op":"mcm","clk":"11883556433","pt":1724068814600,"mc":[{"id":"1.232011465","rc":[{"batb":[[0,1.03,200.09],[1,1.02,200],[2,1.01,220]],"ltp":1.09,"tv":896.74,"id":72857115}]}]}
{"op":"mcm","clk":"11883556494","pt":1724068815592,"mc":[{"id":"1.232011465","rc":[{"batb":[[0,1.03,200]],"ltp":1.09,"tv":896.74,"id":72857115}]}]}
{"op":"mcm","clk":"11883556537","pt":1724068816603,"mc":[{"id":"1.232011465","rc":[{"batb":[[0,1.03,200],[1,1.02,200],[2,1.01,220]],"ltp":1.09,"tv":126.55,"id":67083366}]}]}
{"op":"mcm","clk":"11883556624","pt":1724068817996,"mc":[{"id":"1.232011465","rc":[{"batb":[[0,1.04,10],[1,1.03,200],[2,1.02,200]],"ltp":1.09,"tv":896.74,"id":72857115}]}]}
{"op":"mcm","clk":"11883556812","pt":1724068821400,"mc":[{"id":"1.232011465","rc":[{"batb":[[0,1.04,10],[1,1.03,200],[2,1.02,200]],"ltp":1.09,"tv":126.55,"id":67083366},{"batb":[[0,1.03,200],[1,1.02,200],[2,1.01,220]],"ltp":1.09,"tv":896.74,"id":72857115}]}]}
{"op":"mcm","clk":"11883556995","pt":1724068824699,"mc":[{"id":"1.232011465","rc":[{"batb":[[0,1.03,200],[1,1.02,200],[2,1.01,220]],"ltp":1.09,"tv":126.55,"id":67083366},{"batb":[[0,1.04,10],[1,1.03,200],[2,1.02,200]],"ltp":1.09,"tv":896.74,"id":72857115}]}]}
{"op":"mcm","clk":"11883557186","pt":1724068828093,"mc":[{"id":"1.232011465","rc":[{"batb":[[0,1.04,10],[1,1.03,200],[2,1.02,200]],"ltp":1.09,"tv":126.55,"id":67083366},{"batb":[[0,1.03,200],[1,1.02,200],[2,1.01,220]],"ltp":1.09,"tv":896.74,"id":72857115}]}]}
{"op":"mcm","clk":"11883557316","pt":1724068830206,"mc":[{"id":"1.232011465","rc":[{"batb":[[0,1.04,10],[1,1.03,200],[2,1.02,200]],"ltp":1.09,"tv":896.74,"id":72857115}]}]}
{"op":"mcm","clk":"11883557386","pt":1724068831287,"mc":[{"id":"1.232011465","rc":[{"batb":[[0,1.03,200],[1,1.02,200],[2,1.01,220]],"ltp":1.09,"tv":126.55,"id":67083366}]}]}
{"op":"mcm","clk":"11883557508","pt":1724068833818,"mc":[{"id":"1.232011465","rc":[{"batb":[[0,1.04,10],[1,1.03,200],[2,1.02,200]],"ltp":1.09,"tv":126.55,"id":67083366},{"batb":[[0,1.03,200],[1,1.02,200],[2,1.01,220]],"ltp":1.09,"tv":896.74,"id":72857115}]}]}
{"op":"mcm","clk":"11883557701","pt":1724068837409,"mc":[{"id":"1.232011465","rc":[{"batb":[[0,1.03,200],[1,1.02,200],[2,1.01,220]],"ltp":1.09,"tv":126.55,"id":67083366},{"batb":[[0,1.04,10],[1,1.03,200],[2,1.02,200]],"ltp":1.09,"tv":896.74,"id":72857115}]}]}
{"op":"mcm","clk":"11883557833","pt":1724068839927,"mc":[{"id":"1.232011465","rc":[{"batb":[[0,1.04,10],[1,1.03,200],[2,1.02,200]],"ltp":1.09,"tv":126.55,"id":67083366}]}]}
{"op":"mcm","clk":"11883557876","pt":1724068840700,"mc":[{"id":"1.232011465","rc":[{"batb":[[0,1.03,200],[1,1.02,200],[2,1.01,220]],"ltp":1.09,"tv":896.74,"id":72857115}]}]}
{"op":"mcm","clk":"11883557999","pt":1724068843423,"mc":[{"id":"1.232011465","rc":[{"batb":[[0,1.03,200],[1,1.02,200],[2,1.01,220]],"ltp":1.09,"tv":126.55,"id":67083366}]}]}
{"op":"mcm","clk":"11883558029","pt":1724068843833,"mc":[{"id":"1.232011465","rc":[{"batb":[[0,1.09,387.47],[1,1.03,200],[2,1.02,200]],"ltp":1.09,"tv":126.55,"id":67083366},{"batb":[[0,1.04,10],[1,1.03,200],[2,1.02,200]],"ltp":1.09,"tv":896.74,"id":72857115}]}]}
{"op":"mcm","clk":"11883558148","pt":1724068846107,"mc":[{"id":"1.232011465","rc":[{"batb":[[0,1.1,10],[1,1.09,387.47],[2,1.03,200]],"ltp":1.09,"tv":126.55,"id":67083366}]}]}
{"op":"mcm","clk":"11883558195","pt":1724068847029,"mc":[{"id":"1.232011465","rc":[{"batb":[[0,1.03,200],[1,1.02,200],[2,1.01,220]],"ltp":1.09,"tv":896.74,"id":72857115}]}]}
{"op":"mcm","clk":"11883558300","pt":1724068849497,"mc":[{"id":"1.232011465","rc":[{"batb":[[0,1.09,387.47],[1,1.03,200],[2,1.02,200]],"ltp":1.09,"tv":126.55,"id":67083366},{"batb":[[0,1.04,10],[1,1.03,200],[2,1.02,200]],"ltp":1.09,"tv":896.74,"id":72857115}]}]}
{"op":"mcm","clk":"11883558429","pt":1724068852840,"mc":[{"id":"1.232011465","rc":[{"batb":[[0,1.1,10],[1,1.09,387.47],[2,1.03,200]],"ltp":1.09,"tv":126.55,"id":67083366},{"batb":[[0,1.03,200],[1,1.02,200],[2,1.01,220]],"ltp":1.09,"tv":896.74,"id":72857115}]}]}
{"op":"mcm","clk":"11883558580","pt":1724068856135,"mc":[{"id":"1.232011465","rc":[{"batb":[[0,1.09,387.47],[1,1.03,200],[2,1.02,200]],"ltp":1.09,"tv":126.55,"id":67083366},{"batb":[[0,1.04,10],[1,1.03,200],[2,1.02,200]],"ltp":1.09,"tv":896.74,"id":72857115}]}]}
{"op":"mcm","clk":"11883558728","pt":1724068859429,"mc":[{"id":"1.232011465","rc":[{"batb":[[0,1.03,200],[1,1.02,200],[2,1.01,220]],"ltp":1.09,"tv":896.74,"id":72857115}]}]}
{"op":"mcm","clk":"11883558730","pt":1724068859526,"mc":[{"id":"1.232011465","rc":[{"batb":[[0,1.1,10],[1,1.09,387.47],[2,1.03,200]],"ltp":1.09,"tv":126.55,"id":67083366}]}]}
{"op":"mcm","clk":"11883558805","pt":1724068860926,"mc":[{"id":"1.232011465","rc":[{"trd":[[1.09,881.37],[1.1,20]],"batb":[[0,1.09,10.06],[1,1.03,200],[2,1.02,200]],"ltp":1.09,"tv":901.36,"id":67083366}],"tv":1798.11}]}
{"op":"mcm","clk":"11883559042","pt":1724068865616,"mc":[{"id":"1.232011465","rc":[{"batb":[[0,1.1,10],[1,1.09,10.06],[2,1.03,200]],"ltp":1.09,"tv":901.36,"id":67083366},{"batb":[[0,1.04,10],[1,1.03,200],[2,1.02,200]],"ltp":1.09,"tv":896.74,"id":72857115}]}]}
{"op":"mcm","clk":"11883559200","pt":1724068869065,"mc":[{"id":"1.232011465","rc":[{"batb":[[0,1.09,10.06],[1,1.03,200],[2,1.02,200]],"ltp":1.09,"tv":901.36,"id":67083366},{"batb":[[0,1.03,200],[1,1.02,200],[2,1.01,220]],"ltp":1.09,"tv":896.74,"id":72857115}]}]}
{"op":"mcm","clk":"11883559221","pt":1724068869530,"mc":[{"id":"1.232011465","rc":[{"batb":[[0,1.03,200],[1,1.02,200],[2,1.01,220]],"ltp":1.09,"tv":901.36,"id":67083366}]}]}
{"op":"mcm","clk":"11883559511","pt":1724068874662,"mc":[{"id":"1.232011465","rc":[{"batb":[[0,1.04,10],[1,1.03,200],[2,1.02,200]],"ltp":1.09,"tv":901.36,"id":67083366},{"batb":[[0,1.04,10],[1,1.03,200],[2,1.02,200]],"ltp":1.09,"tv":896.74,"id":72857115}]}]}
{"op":"mcm","clk":"11883559672","pt":1724068878044,"mc":[{"id":"1.232011465","rc":[{"batb":[[0,1.03,200],[1,1.02,200],[2,1.01,220]],"ltp":1.09,"tv":901.36,"id":67083366},{"batb":[[0,1.03,200],[1,1.02,200],[2,1.01,220]],"ltp":1.09,"tv":896.74,"id":72857115}]}]}
{"op":"mcm","clk":"11883559778","pt":1724068880250,"mc":[{"id":"1.232011465","rc":[{"batb":[[0,1.04,10],[1,1.03,200],[2,1.02,200]],"ltp":1.09,"tv":901.36,"id":67083366},{"batb":[[0,1.04,10],[1,1.03,200],[2,1.02,200]],"ltp":1.09,"tv":896.74,"id":72857115}]}]}
{"op":"mcm","clk":"11883559926","pt":1724068883558,"mc":[{"id":"1.232011465","rc":[{"batb":[[0,1.03,200],[1,1.02,200],[2,1.01,220]],"ltp":1.09,"tv":901.36,"id":67083366},{"batb":[[0,1.03,200],[1,1.02,200],[2,1.01,220]],"ltp":1.09,"tv":896.74,"id":72857115}]}]}
{"op":"mcm","clk":"11883560214","pt":1724068888553,"mc":[{"id":"1.232011465","rc":[{"batb":[[0,1.04,10],[1,1.03,200],[2,1.02,200]],"ltp":1.09,"tv":901.36,"id":67083366},{"batb":[[0,1.04,10],[1,1.03,200],[2,1.02,200]],"ltp":1.09,"tv":896.74,"id":72857115}]}]}
{"op":"mcm","clk":"11883560395","pt":1724068892145,"mc":[{"id":"1.232011465","rc":[{"batb":[[0,1.03,200],[1,1.02,200],[2,1.01,220]],"ltp":1.09,"tv":901.36,"id":67083366},{"batb":[[0,1.03,200],[1,1.02,200],[2,1.01,220]],"ltp":1.09,"tv":896.74,"id":72857115}]}]}
{"op":"mcm","clk":"11883560551","pt":1724068895076,"mc":[{"id":"1.232011465","rc":[{"batb":[[0,1.04,10],[1,1.03,200],[2,1.02,200]],"ltp":1.09,"tv":901.36,"id":67083366},{"batb":[[0,1.04,10],[1,1.03,200],[2,1.02,200]],"ltp":1.09,"tv":896.74,"id":72857115}]}]}
{"op":"mcm","clk":"11883560735","pt":1724068898471,"mc":[{"id":"1.232011465","rc":[{"batb":[[0,1.03,200],[1,1.02,200],[2,1.01,220]],"ltp":1.09,"tv":901.36,"id":67083366},{"batb":[[0,1.03,200],[1,1.02,200],[2,1.01,220]],"ltp":1.09,"tv":896.74,"id":72857115}]}]}
{"op":"mcm","clk":"11883560855","pt":1724068900775,"mc":[{"id":"1.232011465","rc":[{"batb":[[0,1.04,10],[1,1.03,200],[2,1.02,200]],"ltp":1.09,"tv":901.36,"id":67083366},{"batb":[[0,1.04,10],[1,1.03,200],[2,1.02,200]],"ltp":1.09,"tv":896.74,"id":72857115}]}]}
{"op":"mcm","clk":"11883561045","pt":1724068904268,"mc":[{"id":"1.232011465","rc":[{"batb":[[0,1.03,200],[1,1.02,200],[2,1.01,220]],"ltp":1.09,"tv":901.36,"id":67083366},{"batb":[[0,1.03,200],[1,1.02,200],[2,1.01,220]],"ltp":1.09,"tv":896.74,"id":72857115}]}]}
{"op":"mcm","clk":"11883561314","pt":1724068909705,"mc":[{"id":"1.232011465","rc":[{"batb":[[0,1.04,10],[1,1.03,200],[2,1.02,200]],"ltp":1.09,"tv":901.36,"id":67083366},{"batb":[[0,1.04,10],[1,1.03,200],[2,1.02,200]],"ltp":1.09,"tv":896.74,"id":72857115}]}]}
{"op":"mcm","clk":"11883561543","pt":1724068913305,"mc":[{"id":"1.232011465","rc":[{"batb":[[0,1.03,200],[1,1.02,200],[2,1.01,220]],"ltp":1.09,"tv":901.36,"id":67083366},{"batb":[[0,1.03,200],[1,1.02,200],[2,1.01,220]],"ltp":1.09,"tv":896.74,"id":72857115}]}]}
{"op":"mcm","clk":"11883561711","pt":1724068915773,"mc":[{"id":"1.232011465","rc":[{"batb":[[0,1.04,10],[1,1.03,200],[2,1.02,200]],"ltp":1.09,"tv":901.36,"id":67083366},{"batb":[[0,1.04,10],[1,1.03,200],[2,1.02,200]],"ltp":1.09,"tv":896.74,"id":72857115}]}]}
{"op":"mcm","clk":"11883561876","pt":1724068918999,"mc":[{"id":"1.232011465","rc":[{"batb":[[0,1.03,200],[1,1.02,200],[2,1.01,220]],"ltp":1.09,"tv":901.36,"id":67083366},{"batb":[[0,1.03,200],[1,1.02,200],[2,1.01,220]],"ltp":1.09,"tv":896.74,"id":72857115}]}]}
{"op":"mcm","clk":"11883562218","pt":1724068925896,"mc":[{"id":"1.232011465","rc":[{"batb":[[0,1.04,10],[1,1.03,200],[2,1.02,200]],"ltp":1.09,"tv":901.36,"id":67083366},{"batb":[[0,1.04,10],[1,1.03,200],[2,1.02,200]],"ltp":1.09,"tv":896.74,"id":72857115}]}]}
{"op":"mcm","clk":"11883562397","pt":1724068929383,"mc":[{"id":"1.232011465","rc":[{"batb":[[0,1.03,200],[1,1.02,200],[2,1.01,220]],"ltp":1.09,"tv":901.36,"id":67083366},{"batb":[[0,1.03,200],[1,1.02,200],[2,1.01,220]],"ltp":1.09,"tv":896.74,"id":72857115}]}]}
{"op":"mcm","clk":"11883562684","pt":1724068935295,"mc":[{"id":"1.232011465","rc":[{"batb":[[0,1.04,10],[1,1.03,200],[2,1.02,200]],"ltp":1.09,"tv":901.36,"id":67083366},{"batb":[[0,1.04,10],[1,1.03,200],[2,1.02,200]],"ltp":1.09,"tv":896.74,"id":72857115}]}]}
{"op":"mcm","clk":"11883562853","pt":1724068938637,"mc":[{"id":"1.232011465","rc":[{"batb":[[0,1.03,200],[1,1.02,200],[2,1.01,220]],"ltp":1.09,"tv":901.36,"id":67083366},{"batb":[[0,1.03,200],[1,1.02,200],[2,1.01,220]],"ltp":1.09,"tv":896.74,"id":72857115}]}]}
{"op":"mcm","clk":"11883563073","pt":1724068942803,"mc":[{"id":"1.232011465","rc":[{"batb":[[0,1.04,10],[1,1.03,200],[2,1.02,200]],"ltp":1.09,"tv":901.36,"id":67083366},{"batb":[[0,1.04,10],[1,1.03,200],[2,1.02,200]],"ltp":1.09,"tv":896.74,"id":72857115}]}]}
{"op":"mcm","clk":"11883563217","pt":1724068946132,"mc":[{"id":"1.232011465","rc":[{"batb":[[0,1.03,200],[1,1.02,200],[2,1.01,220]],"ltp":1.09,"tv":901.36,"id":67083366},{"batb":[[0,1.03,200],[1,1.02,200],[2,1.01,220]],"ltp":1.09,"tv":896.74,"id":72857115}]}]}
{"op":"mcm","clk":"11883563684","pt":1724068954155,"mc":[{"id":"1.232011465","rc":[{"batb":[[0,1.04,10],[1,1.03,200],[2,1.02,200]],"ltp":1.09,"tv":901.36,"id":67083366},{"batb":[[0,1.04,10],[1,1.03,200],[2,1.02,200]],"ltp":1.09,"tv":896.74,"id":72857115}]}]}
{"op":"mcm","clk":"11883563872","pt":1724068957556,"mc":[{"id":"1.232011465","rc":[{"batb":[[0,1.03,200],[1,1.02,200],[2,1.01,220]],"ltp":1.09,"tv":901.36,"id":67083366},{"batb":[[0,1.03,200],[1,1.02,200],[2,1.01,220]],"ltp":1.09,"tv":896.74,"id":72857115}]}]}
{"op":"mcm","clk":"11883564019","pt":1724068959871,"mc":[{"id":"1.232011465","rc":[{"batb":[[0,1.04,10],[1,1.03,200],[2,1.02,200]],"ltp":1.09,"tv":901.36,"id":67083366},{"batb":[[0,1.04,10],[1,1.03,200],[2,1.02,200]],"ltp":1.09,"tv":896.74,"id":72857115}]}]}
{"op":"mcm","clk":"11883564190","pt":1724068963434,"mc":[{"id":"1.232011465","rc":[{"batb":[[0,1.03,200],[1,1.02,200],[2,1.01,220]],"ltp":1.09,"tv":901.36,"id":67083366},{"batb":[[0,1.03,200],[1,1.02,200],[2,1.01,220]],"ltp":1.09,"tv":896.74,"id":72857115}]}]}
{"op":"mcm","clk":"11883564533","pt":1724068969447,"mc":[{"id":"1.232011465","rc":[{"batb":[[0,1.04,10],[1,1.03,200],[2,1.02,200]],"ltp":1.09,"tv":901.36,"id":67083366},{"batb":[[0,1.04,10],[1,1.03,200],[2,1.02,200]],"ltp":1.09,"tv":896.74,"id":72857115}]}]}
{"op":"mcm","clk":"11883564777","pt":1724068973268,"mc":[{"id":"1.232011465","rc":[{"batb":[[0,1.03,200],[1,1.02,200],[2,1.01,220]],"ltp":1.09,"tv":901.36,"id":67083366},{"batb":[[0,1.03,200],[1,1.02,200],[2,1.01,220]],"ltp":1.09,"tv":896.74,"id":72857115}]}]}
{"op":"mcm","clk":"11883564933","pt":1724068975873,"mc":[{"id":"1.232011465","rc":[{"batb":[[0,1.04,10],[1,1.03,200],[2,1.02,200]],"ltp":1.09,"tv":901.36,"id":67083366},{"batb":[[0,1.04,10],[1,1.03,200],[2,1.02,200]],"ltp":1.09,"tv":896.74,"id":72857115}]}]}
{"op":"mcm","clk":"11883565126","pt":1724068979989,"mc":[{"id":"1.232011465","rc":[{"batb":[[0,1.03,200],[1,1.02,200],[2,1.01,220]],"ltp":1.09,"tv":901.36,"id":67083366},{"batb":[[0,1.03,200],[1,1.02,200],[2,1.01,220]],"ltp":1.09,"tv":896.74,"id":72857115}]}]}
{"op":"mcm","clk":"11883565275","pt":1724068982775,"mc":[{"id":"1.232011465","rc":[{"batb":[[0,1.04,10],[1,1.03,200],[2,1.02,200]],"ltp":1.09,"tv":901.36,"id":67083366},{"batb":[[0,1.04,10],[1,1.03,200],[2,1.02,200]],"ltp":1.09,"tv":896.74,"id":72857115}]}]}
{"op":"mcm","clk":"11883565481","pt":1724068986387,"mc":[{"id":"1.232011465","rc":[{"batb":[[0,1.03,200],[1,1.02,200],[2,1.01,220]],"ltp":1.09,"tv":901.36,"id":67083366},{"batb":[[0,1.03,200],[1,1.02,200],[2,1.01,220]],"ltp":1.09,"tv":896.74,"id":72857115}]}]}
{"op":"mcm","clk":"11883565639","pt":1724068989418,"mc":[{"id":"1.232011465","rc":[{"batb":[[0,1.04,10],[1,1.03,200],[2,1.02,200]],"ltp":1.09,"tv":901.36,"id":67083366},{"batb":[[0,1.04,10],[1,1.03,200],[2,1.02,200]],"ltp":1.09,"tv":896.74,"id":72857115}]}]}
{"op":"mcm","clk":"11883565823","pt":1724068992819,"mc":[{"id":"1.232011465","rc":[{"batb":[[0,1.03,200],[1,1.02,200],[2,1.01,220]],"ltp":1.09,"tv":901.36,"id":67083366},{"batb":[[0,1.03,200],[1,1.02,200],[2,1.01,220]],"ltp":1.09,"tv":896.74,"id":72857115}]}]}
{"op":"mcm","clk":"11883565942","pt":1724068995022,"mc":[{"id":"1.232011465","rc":[{"batb":[[0,1.04,10],[1,1.03,200],[2,1.02,200]],"ltp":1.09,"tv":901.36,"id":67083366},{"batb":[[0,1.04,10],[1,1.03,200],[2,1.02,200]],"ltp":1.09,"tv":896.74,"id":72857115}]}]}
{"op":"mcm","clk":"11883566098","pt":1724068998237,"mc":[{"id":"1.232011465","rc":[{"batb":[[0,1.03,200],[1,1.02,200],[2,1.01,220]],"ltp":1.09,"tv":901.36,"id":67083366},{"batb":[[0,1.03,200],[1,1.02,200],[2,1.01,220]],"ltp":1.09,"tv":896.74,"id":72857115}]}]}
{"op":"mcm","clk":"11883566216","pt":1724069000937,"mc":[{"id":"1.232011465","rc":[{"batb":[[0,1.04,10],[1,1.03,200],[2,1.02,200]],"ltp":1.09,"tv":901.36,"id":67083366},{"batb":[[0,1.04,10],[1,1.03,200],[2,1.02,200]],"ltp":1.09,"tv":896.74,"id":72857115}]}]}
{"op":"mcm","clk":"11883566385","pt":1724069004336,"mc":[{"id":"1.232011465","rc":[{"batb":[[0,1.03,200],[1,1.02,200],[2,1.01,220]],"ltp":1.09,"tv":901.36,"id":67083366},{"batb":[[0,1.03,200],[1,1.02,200],[2,1.01,220]],"ltp":1.09,"tv":896.74,"id":72857115}]}]}
{"op":"mcm","clk":"11883566553","pt":1724069007419,"mc":[{"id":"1.232011465","rc":[{"batb":[[0,1.04,10],[1,1.03,200],[2,1.02,200]],"ltp":1.09,"tv":901.36,"id":67083366},{"batb":[[0,1.04,10],[1,1.03,200],[2,1.02,200]],"ltp":1.09,"tv":896.74,"id":72857115}]}]}
{"op":"mcm","clk":"11883566718","pt":1724069010962,"mc":[{"id":"1.232011465","rc":[{"batb":[[0,1.03,200],[1,1.02,200],[2,1.01,220]],"ltp":1.09,"tv":901.36,"id":67083366},{"batb":[[0,1.03,200],[1,1.02,200],[2,1.01,220]],"ltp":1.09,"tv":896.74,"id":72857115}]}]}
{"op":"mcm","clk":"11883566881","pt":1724069014455,"mc":[{"id":"1.232011465","rc":[{"batb":[[0,1.09,4.48],[1,1.03,200],[2,1.02,200]],"ltp":1.09,"tv":901.36,"id":67083366}]}]}
{"op":"mcm","clk":"11883566888","pt":1724069014557,"mc":[{"id":"1.232011465","rc":[{"batb":[[0,1.1,10],[1,1.09,4.48],[2,1.03,200]],"ltp":1.09,"tv":901.36,"id":67083366},{"batb":[[0,1.04,10],[1,1.03,200],[2,1.02,200]],"ltp":1.09,"tv":896.74,"id":72857115}]}]}
{"op":"mcm","clk":"11883567056","pt":1724069017746,"mc":[{"id":"1.232011465","rc":[{"batb":[[0,1.09,4.48],[1,1.03,200],[2,1.02,200]],"ltp":1.09,"tv":901.36,"id":67083366},{"batb":[[0,1.03,200],[1,1.02,200],[2,1.01,220]],"ltp":1.09,"tv":896.74,"id":72857115}]}]}
{"op":"mcm","clk":"11883567233","pt":1724069021038,"mc":[{"id":"1.232011465","rc":[{"batb":[[0,1.1,10],[1,1.09,4.48],[2,1.03,200]],"ltp":1.09,"tv":901.36,"id":67083366},{"batb":[[0,1.04,10],[1,1.03,200],[2,1.02,200]],"ltp":1.09,"tv":896.74,"id":72857115}]}]}
{"op":"mcm","clk":"11883567252","pt":1724069021550,"mc":[{"id":"1.232011465","rc":[{"batb":[[1,1.03,200],[2,1.02,200]],"ltp":1.09,"tv":901.36,"id":67083366}]}]}
{"op":"mcm","clk":"11883567395","pt":1724069024332,"mc":[{"id":"1.232011465","rc":[{"batb":[[0,1.03,200],[1,1.02,200],[2,1.01,220]],"ltp":1.09,"tv":901.36,"id":67083366},{"batb":[[0,1.03,200],[1,1.02,200],[2,1.01,220]],"ltp":1.09,"tv":896.74,"id":72857115}]}]}
{"op":"mcm","clk":"11883567537","pt":1724069026652,"mc":[{"id":"1.232011465","rc":[{"batb":[[0,1.04,10],[1,1.03,200],[2,1.02,200]],"ltp":1.09,"tv":901.36,"id":67083366},{"batb":[[0,1.04,10],[1,1.03,200],[2,1.02,200]],"ltp":1.09,"tv":896.74,"id":72857115}]}]}
{"op":"mcm","clk":"11883567711","pt":1724069030047,"mc":[{"id":"1.232011465","rc":[{"batb":[[0,1.03,200],[1,1.02,200],[2,1.01,220]],"ltp":1.09,"tv":901.36,"id":67083366},{"batb":[[0,1.03,200],[1,1.02,200],[2,1.01,220]],"ltp":1.09,"tv":896.74,"id":72857115}]}]}
{"op":"mcm","clk":"11883567778","pt":1724069031485,"mc":[{"id":"1.232011465","rc":[{"batb":[[0,1.09,4.48],[1,1.03,200],[2,1.02,200]],"ltp":1.09,"tv":896.74,"id":72857115}]}]}
{"op":"mcm","clk":"11883567838","pt":1724069032670,"mc":[{"id":"1.232011465","rc":[{"batb":[[0,1.04,10],[1,1.03,200],[2,1.02,200]],"ltp":1.09,"tv":901.36,"id":67083366},{"batb":[[0,1.1,10],[1,1.09,4.48],[2,1.03,200]],"ltp":1.09,"tv":896.74,"id":72857115}]}]}
{"op":"mcm","clk":"11883568027","pt":1724069036272,"mc":[{"id":"1.232011465","rc":[{"batb":[[0,1.03,200],[1,1.02,200],[2,1.01,220]],"ltp":1.09,"tv":901.36,"id":67083366},{"batb":[[0,1.09,4.48],[1,1.03,200],[2,1.02,200]],"ltp":1.09,"tv":896.74,"id":72857115}]}]}
{"op":"mcm","clk":"11883568274","pt":1724069041067,"mc":[{"id":"1.232011465","rc":[{"batb":[[0,1.04,10],[1,1.03,200],[2,1.02,200]],"ltp":1.09,"tv":901.36,"id":67083366},{"batb":[[0,1.1,10],[1,1.09,4.48],[2,1.03,200]],"ltp":1.09,"tv":896.74,"id":72857115}]}]}
{"op":"mcm","clk":"11883568322","pt":1724069041990,"mc":[{"id":"1.232011465","rc":[{"batb":[[1,1.03,200],[2,1.02,200]],"ltp":1.09,"tv":896.74,"id":72857115}]}]}
{"op":"mcm","clk":"11883568433","pt":1724069044358,"mc":[{"id":"1.232011465","rc":[{"batb":[[0,1.03,200],[1,1.02,200],[2,1.01,220]],"ltp":1.09,"tv":901.36,"id":67083366},{"batb":[[0,1.03,200],[1,1.02,200],[2,1.01,220]],"ltp":1.09,"tv":896.74,"id":72857115}]}]}
{"op":"mcm","clk":"11883568562","pt":1724069047186,"mc":[{"id":"1.232011465","rc":[{"batb":[[0,1.04,10],[1,1.03,200],[2,1.02,200]],"ltp":1.09,"tv":901.36,"id":67083366},{"batb":[[0,1.04,10],[1,1.03,200],[2,1.02,200]],"ltp":1.09,"tv":896.74,"id":72857115}]}]}
{"op":"mcm","clk":"11883568754","pt":1724069050790,"mc":[{"id":"1.232011465","rc":[{"batb":[[0,1.03,200],[1,1.02,200],[2,1.01,220]],"ltp":1.09,"tv":901.36,"id":67083366},{"batb":[[0,1.03,200],[1,1.02,200],[2,1.01,220]],"ltp":1.09,"tv":896.74,"id":72857115}]}]}
{"op":"mcm","clk":"11883569203","pt":1724069059391,"mc":[{"id":"1.232011465","rc":[{"batb":[[0,1.04,10],[1,1.03,200],[2,1.02,200]],"ltp":1.09,"tv":901.36,"id":67083366},{"batb":[[0,1.04,10],[1,1.03,200],[2,1.02,200]],"ltp":1.09,"tv":896.74,"id":72857115}]}]}
{"op":"mcm","clk":"11883569390","pt":1724069062789,"mc":[{"id":"1.232011465","rc":[{"batb":[[0,1.03,200],[1,1.02,200],[2,1.01,220]],"ltp":1.09,"tv":901.36,"id":67083366},{"batb":[[0,1.03,200],[1,1.02,200],[2,1.01,220]],"ltp":1.09,"tv":896.74,"id":72857115}]}]}
{"op":"mcm","clk":"11883569581","pt":1724069066998,"mc":[{"id":"1.232011465","rc":[{"batb":[[0,1.04,10],[1,1.03,200],[2,1.02,200]],"ltp":1.09,"tv":901.36,"id":67083366},{"batb":[[0,1.04,10],[1,1.03,200],[2,1.02,200]],"ltp":1.09,"tv":896.74,"id":72857115}]}]}
{"op":"mcm","clk":"11883569734","pt":1724069070500,"mc":[{"id":"1.232011465","rc":[{"batb":[[0,1.03,200],[1,1.02,200],[2,1.01,220]],"ltp":1.09,"tv":901.36,"id":67083366},{"batb":[[0,1.03,200],[1,1.02,200],[2,1.01,220]],"ltp":1.09,"tv":896.74,"id":72857115}]}]}
{"op":"mcm","clk":"11883569888","pt":1724069073691,"mc":[{"id":"1.232011465","rc":[{"batb":[[0,1.04,10],[1,1.03,200],[2,1.02,200]],"ltp":1.09,"tv":901.36,"id":67083366},{"batb":[[0,1.04,10],[1,1.03,200],[2,1.02,200]],"ltp":1.09,"tv":896.74,"id":72857115}]}]}
{"op":"mcm","clk":"11883570039","pt":1724069077192,"mc":[{"id":"1.232011465","rc":[{"batb":[[0,1.03,200],[1,1.02,200],[2,1.01,220]],"ltp":1.09,"tv":901.36,"id":67083366},{"batb":[[0,1.03,200],[1,1.02,200],[2,1.01,220]],"ltp":1.09,"tv":896.74,"id":72857115}]}]}
{"op":"mcm","clk":"11883570191","pt":1724069080291,"mc":[{"id":"1.232011465","rc":[{"batb":[[0,1.04,10],[1,1.03,200],[2,1.02,200]],"ltp":1.09,"tv":901.36,"id":67083366},{"batb":[[0,1.04,10],[1,1.03,200],[2,1.02,200]],"ltp":1.09,"tv":896.74,"id":72857115}]}]}
{"op":"mcm","clk":"11883570376","pt":1724069083689,"mc":[{"id":"1.232011465","rc":[{"batb":[[0,1.03,200],[1,1.02,200],[2,1.01,220]],"ltp":1.09,"tv":901.36,"id":67083366},{"batb":[[0,1.03,200],[1,1.02,200],[2,1.01,220]],"ltp":1.09,"tv":896.74,"id":72857115}]}]}
{"op":"mcm","clk":"11883570602","pt":1724069088011,"mc":[{"id":"1.232011465","rc":[{"batb":[[0,1.04,10],[1,1.03,200],[2,1.02,200]],"ltp":1.09,"tv":901.36,"id":67083366},{"batb":[[0,1.04,10],[1,1.03,200],[2,1.02,200]],"ltp":1.09,"tv":896.74,"id":72857115}]}]}
{"op":"mcm","clk":"11883570784","pt":1724069091517,"mc":[{"id":"1.232011465","rc":[{"batb":[[0,1.03,200],[1,1.02,200],[2,1.01,220]],"ltp":1.09,"tv":901.36,"id":67083366},{"batb":[[0,1.03,200],[1,1.02,200],[2,1.01,220]],"ltp":1.09,"tv":896.74,"id":72857115}]}]}
{"op":"mcm","clk":"11883571029","pt":1724069096422,"mc":[{"id":"1.232011465","rc":[{"batb":[[0,1.04,10],[1,1.03,200],[2,1.02,200]],"ltp":1.09,"tv":901.36,"id":67083366},{"batb":[[0,1.04,10],[1,1.03,200],[2,1.02,200]],"ltp":1.09,"tv":896.74,"id":72857115}]}]}
{"op":"mcm","clk":"11883571192","pt":1724069100012,"mc":[{"id":"1.232011465","rc":[{"batb":[[0,1.03,200],[1,1.02,200],[2,1.01,220]],"ltp":1.09,"tv":901.36,"id":67083366},{"batb":[[0,1.03,200],[1,1.02,200],[2,1.01,220]],"ltp":1.09,"tv":896.74,"id":72857115}]}]}
{"op":"mcm","clk":"11883571432","pt":1724069103818,"mc":[{"id":"1.232011465","rc":[{"batb":[[0,1.04,10],[1,1.03,200],[2,1.02,200]],"ltp":1.09,"tv":901.36,"id":67083366},{"batb":[[0,1.04,10],[1,1.03,200],[2,1.02,200]],"ltp":1.09,"tv":896.74,"id":72857115}]}]}
{"op":"mcm","clk":"11883571585","pt":1724069107428,"mc":[{"id":"1.232011465","rc":[{"batb":[[0,1.03,200],[1,1.02,200],[2,1.01,220]],"ltp":1.09,"tv":901.36,"id":67083366},{"batb":[[0,1.5,41.84]],"ltp":1.09,"tv":896.74,"id":72857115}]}]}
{"op":"mcm","clk":"11883571710","pt":1724069110417,"mc":[{"id":"1.232011465","rc":[{"batb":[[0,1.04,10],[1,1.03,200],[2,1.02,200]],"ltp":1.09,"tv":901.36,"id":67083366},{"batb":[[0,1.51,10],[1,1.5,41.84],[2,1.03,200]],"ltp":1.09,"tv":896.74,"id":72857115}]}]}
{"op":"mcm","clk":"11883571813","pt":1724069112636,"mc":[{"id":"1.232011465","rc":[{"batb":[[0,1.9,8.27],[1,1.51,10],[2,1.5,41.84]],"ltp":1.09,"tv":896.74,"id":72857115}]}]}
{"op":"mcm","clk":"11883571882","pt":1724069114029,"mc":[{"id":"1.232011465","rc":[{"batb":[[0,1.03,200],[1,1.02,200],[2,1.01,220]],"ltp":1.09,"tv":901.36,"id":67083366},{"batb":[[1,1.5,41.84],[2,1.03,200]],"ltp":1.09,"tv":896.74,"id":72857115}]}]}
{"op":"mcm","clk":"11883572046","pt":1724069117641,"mc":[{"id":"1.232011465","rc":[{"batb":[[0,1.04,10],[1,1.03,200],[2,1.02,200]],"ltp":1.09,"tv":901.36,"id":67083366},{"batb":[[0,1.91,10],[1,1.9,8.27],[2,1.5,41.84]],"ltp":1.09,"tv":896.74,"id":72857115}]}]}
{"op":"mcm","clk":"11883572183","pt":1724069120942,"mc":[{"id":"1.232011465","rc":[{"batb":[[0,1.03,200],[1,1.02,200],[2,1.01,220]],"ltp":1.09,"tv":901.36,"id":67083366},{"batb":[[0,1.9,8.27],[1,1.5,41.84],[2,1.03,200]],"ltp":1.09,"tv":896.74,"id":72857115}]}]}
{"op":"mcm","clk":"11883572480","pt":1724069128657,"mc":[{"id":"1.232011465","rc":[{"batb":[[0,1.04,10],[1,1.03,200],[2,1.02,200]],"ltp":1.09,"tv":901.36,"id":67083366},{"batb":[[0,1.91,10],[1,1.9,8.27],[2,1.5,41.84]],"ltp":1.09,"tv":896.74,"id":72857115}]}]}
{"op":"mcm","clk":"11883572612","pt":1724069132046,"mc":[{"id":"1.232011465","rc":[{"batb":[[0,1.03,200],[1,1.02,200],[2,1.01,220]],"ltp":1.09,"tv":901.36,"id":67083366},{"batb":[[0,1.9,8.27],[1,1.5,41.84],[2,1.03,200]],"ltp":1.09,"tv":896.74,"id":72857115}]}]}
{"op":"mcm","clk":"11883572774","pt":1724069135579,"mc":[{"id":"1.232011465","rc":[{"batb":[[0,1.04,10],[1,1.03,200],[2,1.02,200]],"ltp":1.09,"tv":901.36,"id":67083366},{"batb":[[0,1.91,10],[1,1.9,8.27],[2,1.5,41.84]],"ltp":1.09,"tv":896.74,"id":72857115}]}]}
{"op":"mcm","clk":"11883572911","pt":1724069139064,"mc":[{"id":"1.232011465","rc":[{"batb":[[0,1.03,200],[1,1.02,200],[2,1.01,220]],"ltp":1.09,"tv":901.36,"id":67083366},{"batb":[[0,1.9,8.27],[1,1.5,41.84],[2,1.03,200]],"ltp":1.09,"tv":896.74,"id":72857115}]}]}
{"op":"mcm","clk":"11883573032","pt":1724069141979,"mc":[{"id":"1.232011465","rc":[{"batb":[[0,1.51,10],[1,1.5,41.84],[2,1.03,200]],"ltp":1.09,"tv":901.36,"id":67083366},{"batb":[[0,1.91,10],[1,1.9,8.27],[2,1.5,41.84]],"ltp":1.09,"tv":896.74,"id":72857115}]}]}
{"op":"mcm","clk":"11883573152","pt":1724069145207,"mc":[{"id":"1.232011465","rc":[{"batb":[[0,1.5,41.84],[1,1.03,200],[2,1.02,200]],"ltp":1.09,"tv":901.36,"id":67083366},{"batb":[[0,1.9,8.27],[1,1.5,41.84],[2,1.03,200]],"ltp":1.09,"tv":896.74,"id":72857115}]}]}
{"op":"mcm","clk":"11883573246","pt":1724069147405,"mc":[{"id":"1.232011465","rc":[{"batb":[[0,1.51,10],[1,1.5,41.84],[2,1.03,200]],"ltp":1.09,"tv":901.36,"id":67083366},{"batb":[[0,1.91,10],[1,1.9,8.27],[2,1.5,41.84]],"ltp":1.09,"tv":896.74,"id":72857115}]}]}
{"op":"mcm","clk":"11883573362","pt":1724069150680,"mc":[{"id":"1.232011465","rc":[{"batb":[[0,1.5,41.84],[1,1.03,200],[2,1.02,200]],"ltp":1.09,"tv":901.36,"id":67083366},{"batb":[[0,1.9,8.27],[1,1.5,41.84],[2,1.03,200]],"ltp":1.09,"tv":896.74,"id":72857115}]}]}
{"op":"mcm","clk":"11883573407","pt":1724069151811,"mc":[{"id":"1.232011465","rc":[{"batb":[[0,1.79,8.78],[1,1.5,41.84],[2,1.03,200]],"ltp":1.09,"tv":901.36,"id":67083366}]}]}
{"op":"mcm","clk":"11883573548","pt":1724069155397,"mc":[{"id":"1.232011465","rc":[{"batb":[[0,1.8,10],[1,1.79,8.78],[2,1.5,41.84]],"ltp":1.09,"tv":901.36,"id":67083366},{"batb":[[0,1.91,10],[1,1.9,8.27],[2,1.5,41.84]],"ltp":1.09,"tv":896.74,"id":72857115}]}]}
{"op":"mcm","clk":"11883573684","pt":1724069159085,"mc":[{"id":"1.232011465","rc":[{"batb":[[0,1.79,8.78],[1,1.5,41.84],[2,1.03,200]],"ltp":1.09,"tv":901.36,"id":67083366},{"batb":[[0,1.9,8.27],[1,1.5,41.84],[2,1.03,200]],"ltp":1.09,"tv":896.74,"id":72857115}]}]}
{"op":"mcm","clk":"11883573836","pt":1724069162316,"mc":[{"id":"1.232011465","rc":[{"batb":[[0,1.8,10],[1,1.79,8.78],[2,1.5,41.84]],"ltp":1.09,"tv":901.36,"id":67083366},{"batb":[[0,1.91,10],[1,1.9,8.27],[2,1.5,41.84]],"ltp":1.09,"tv":896.74,"id":72857115}]}]}
{"op":"mcm","clk":"11883573993","pt":1724069166009,"mc":[{"id":"1.232011465","rc":[{"batb":[[0,1.79,8.78],[1,1.5,41.84],[2,1.03,200]],"ltp":1.09,"tv":901.36,"id":67083366},{"batb":[[0,1.9,8.27],[1,1.5,41.84],[2,1.03,200]],"ltp":1.09,"tv":896.74,"id":72857115}]}]}
{"op":"mcm","clk":"11883574151","pt":1724069169141,"mc":[{"id":"1.232011465","rc":[{"batb":[[0,1.8,10],[1,1.79,8.78],[2,1.5,41.84]],"ltp":1.09,"tv":901.36,"id":67083366},{"batb":[[0,1.91,10],[1,1.9,8.27],[2,1.5,41.84]],"ltp":1.09,"tv":896.74,"id":72857115}]}]}
{"op":"mcm","clk":"11883574283","pt":1724069172534,"mc":[{"id":"1.232011465","rc":[{"batb":[[0,1.79,8.78],[1,1.5,41.84],[2,1.03,200]],"ltp":1.09,"tv":901.36,"id":67083366},{"batb":[[0,1.9,8.27],[1,1.5,41.84],[2,1.03,200]],"ltp":1.09,"tv":896.74,"id":72857115}]}]}
{"op":"mcm","clk":"11883574556","pt":1724069178845,"mc":[{"id":"1.232011465","rc":[{"batb":[[0,1.8,10],[1,1.79,8.78],[2,1.5,41.84]],"ltp":1.09,"tv":901.36,"id":67083366},{"batb":[[0,1.91,10],[1,1.9,8.27],[2,1.5,41.84]],"ltp":1.09,"tv":896.74,"id":72857115}]}]}
{"op":"mcm","clk":"11883574740","pt":1724069182444,"mc":[{"id":"1.232011465","rc":[{"batb":[[0,1.79,8.78],[1,1.5,41.84],[2,1.03,200]],"ltp":1.09,"tv":901.36,"id":67083366},{"batb":[[0,1.9,8.27],[1,1.5,41.84],[2,1.03,200]],"ltp":1.09,"tv":896.74,"id":72857115}]}]}
{"op":"mcm","clk":"11883575271","pt":1724069195016,"mc":[{"id":"1.232011465","rc":[{"batb":[[0,1.8,10],[1,1.79,8.78],[2,1.5,41.84]],"ltp":1.09,"tv":901.36,"id":67083366},{"batb":[[0,1.91,10],[1,1.9,8.27],[2,1.5,41.84]],"ltp":1.09,"tv":896.74,"id":72857115}]}]}
{"op":"mcm","clk":"11883575411","pt":1724069198455,"mc":[{"id":"1.232011465","rc":[{"batb":[[0,1.79,8.78],[1,1.5,41.84],[2,1.03,200]],"ltp":1.09,"tv":901.36,"id":67083366},{"batb":[[0,1.9,8.27],[1,1.5,41.84],[2,1.03,200]],"ltp":1.09,"tv":896.74,"id":72857115}]}]}
{"op":"mcm","clk":"11883575579","pt":1724069201945,"mc":[{"id":"1.232011465","rc":[{"batb":[[0,1.8,10],[1,1.79,8.78],[2,1.5,41.84]],"batl":[[0,1.96,25.1],[1,13,0.94]],"ltp":1.09,"tv":901.36,"id":67083366},{"batb":[[0,1.91,10],[1,1.9,8.27],[2,1.5,41.84]],"ltp":1.09,"tv":896.74,"id":72857115}]}]}
{"op":"mcm","clk":"11883575731","pt":1724069205031,"mc":[{"id":"1.232011465","rc":[{"batb":[[0,1.79,8.78],[1,1.5,41.84],[2,1.03,200]],"ltp":1.09,"tv":901.36,"id":67083366},{"batb":[[0,1.9,8.27],[1,1.5,41.84],[2,1.03,200]],"ltp":1.09,"tv":896.74,"id":72857115}]}]}
{"op":"mcm","clk":"11883575829","pt":1724069207543,"mc":[{"id":"1.232011465","rc":[{"batb":[[0,1.91,10],[1,1.9,8.27],[2,1.5,41.84]],"ltp":1.09,"tv":896.74,"id":72857115}]}]}
{"op":"mcm","clk":"11883575882","pt":1724069208935,"mc":[{"id":"1.232011465","rc":[{"batb":[[0,1.92,8.2],[1,1.91,10]],"ltp":1.09,"tv":896.74,"id":72857115}]}]}
{"op":"mcm","clk":"11883575977","pt":1724069210882,"mc":[{"id":"1.232011465","rc":[{"batb":[[1,1.5,41.84],[2,1.03,200]],"ltp":1.09,"tv":896.74,"id":72857115}]}]}
{"op":"mcm","clk":"11883576229","pt":1724069216745,"mc":[{"id":"1.232011465","rc":[{"batb":[[0,1.93,10],[1,1.92,8.2],[2,1.5,41.84]],"ltp":1.09,"tv":896.74,"id":72857115}]}]}
{"op":"mcm","clk":"11883576369","pt":1724069220275,"mc":[{"id":"1.232011465","rc":[{"batb":[[0,1.92,8.2],[1,1.5,41.84],[2,1.03,200]],"ltp":1.09,"tv":896.74,"id":72857115}]}]}
{"op":"mcm","clk":"11883576505","pt":1724069223884,"mc":[{"id":"1.232011465","rc":[{"batb":[[0,1.93,10],[1,1.92,8.2],[2,1.5,41.84]],"ltp":1.09,"tv":896.74,"id":72857115}]}]}
{"op":"mcm","clk":"11883576644","pt":1724069227172,"mc":[{"id":"1.232011465","rc":[{"batb":[[0,1.92,8.2],[1,1.5,41.84],[2,1.03,200]],"ltp":1.09,"tv":896.74,"id":72857115}]}]}
{"op":"mcm","clk":"11883576769","pt":1724069230568,"mc":[{"id":"1.232011465","rc":[{"batb":[[0,1.93,10],[1,1.92,8.2],[2,1.5,41.84]],"ltp":1.09,"tv":896.74,"id":72857115}]}]}
{"op":"mcm","clk":"11883576892","pt":1724069233907,"mc":[{"id":"1.232011465","rc":[{"batb":[[0,1.92,8.2],[1,1.5,41.84],[2,1.03,200]],"ltp":1.09,"tv":896.74,"id":72857115}]}]}
{"op":"mcm","clk":"11883577134","pt":1724069238792,"mc":[{"id":"1.232011465","rc":[{"batb":[[0,1.93,10],[1,1.92,8.2],[2,1.5,41.84]],"ltp":1.09,"tv":896.74,"id":72857115}]}]}
{"op":"mcm","clk":"11883577284","pt":1724069242000,"mc":[{"id":"1.232011465","rc":[{"batb":[[0,1.92,8.2],[1,1.5,41.84],[2,1.03,200]],"ltp":1.09,"tv":896.74,"id":72857115}]}]}
{"op":"mcm","clk":"11883577468","pt":1724069246022,"mc":[{"id":"1.232011465","rc":[{"batb":[[0,1.93,10],[1,1.92,8.2],[2,1.5,41.84]],"ltp":1.09,"tv":896.74,"id":72857115}]}]}
{"op":"mcm","clk":"11883577623","pt":1724069249578,"mc":[{"id":"1.232011465","rc":[{"batb":[[0,1.92,8.2],[1,1.5,41.84],[2,1.03,200]],"ltp":1.09,"tv":896.74,"id":72857115}]}]}
{"op":"mcm","clk":"11883577796","pt":1724069253800,"mc":[{"id":"1.232011465","rc":[{"batb":[[0,1.93,10],[1,1.92,8.2],[2,1.5,41.84]],"ltp":1.09,"tv":896.74,"id":72857115}]}]}
{"op":"mcm","clk":"11883577939","pt":1724069257096,"mc":[{"id":"1.232011465","rc":[{"batb":[[0,1.92,8.2],[1,1.5,41.84],[2,1.03,200]],"ltp":1.09,"tv":896.74,"id":72857115}]}]}
{"op":"mcm","clk":"11883578215","pt":1724069262519,"mc":[{"id":"1.232011465","rc":[{"batb":[[0,1.93,10],[1,1.92,8.2],[2,1.5,41.84]],"ltp":1.09,"tv":896.74,"id":72857115}]}]}
{"op":"mcm","clk":"11883578371","pt":1724069266124,"mc":[{"id":"1.232011465","rc":[{"batb":[[0,1.92,8.2],[1,1.5,41.84],[2,1.03,200]],"ltp":1.09,"tv":896.74,"id":72857115}]}]}
{"op":"mcm","clk":"11883578504","pt":1724069269111,"mc":[{"id":"1.232011465","rc":[{"batb":[[0,1.93,10],[1,1.92,8.2],[2,1.5,41.84]],"ltp":1.09,"tv":896.74,"id":72857115}]}]}
{"op":"mcm","clk":"11883578700","pt":1724069273530,"mc":[{"id":"1.232011465","rc":[{"batb":[[0,1.92,8.2],[1,1.5,41.84],[2,1.03,200]],"ltp":1.09,"tv":896.74,"id":72857115}]}]}
{"op":"mcm","clk":"11883578793","pt":1724069275722,"mc":[{"id":"1.232011465","rc":[{"batb":[[0,1.93,10],[1,1.92,8.2],[2,1.5,41.84]],"ltp":1.09,"tv":896.74,"id":72857115}]}]}
{"op":"mcm","clk":"11883578904","pt":1724069278932,"mc":[{"id":"1.232011465","rc":[{"batb":[[0,1.92,8.2],[1,1.5,41.84],[2,1.03,200]],"ltp":1.09,"tv":896.74,"id":72857115}]}]}
{"op":"mcm","clk":"11883579148","pt":1724069284030,"mc":[{"id":"1.232011465","rc":[{"batb":[[0,1.93,10],[1,1.92,8.2],[2,1.5,41.84]],"ltp":1.09,"tv":896.74,"id":72857115}]}]}
{"op":"mcm","clk":"11883579287","pt":1724069287347,"mc":[{"id":"1.232011465","rc":[{"batb":[[0,1.92,8.2],[1,1.5,41.84],[2,1.03,200]],"ltp":1.09,"tv":896.74,"id":72857115}]}]}
{"op":"mcm","clk":"11883579447","pt":1724069291144,"mc":[{"id":"1.232011465","rc":[{"batb":[[0,1.93,10],[1,1.92,8.2],[2,1.5,41.84]],"ltp":1.09,"tv":896.74,"id":72857115}]}]}
{"op":"mcm","clk":"11883579620","pt":1724069294644,"mc":[{"id":"1.232011465","rc":[{"batb":[[0,1.92,8.2],[1,1.5,41.84],[2,1.03,200]],"ltp":1.09,"tv":896.74,"id":72857115}]}]}
{"op":"mcm","clk":"11883579840","pt":1724069299381,"mc":[{"id":"1.232011465","rc":[{"batb":[[0,1.93,10],[1,1.92,8.2],[2,1.5,41.84]],"ltp":1.09,"tv":896.74,"id":72857115}]}]}
{"op":"mcm","clk":"11883580022","pt":1724069302878,"mc":[{"id":"1.232011465","rc":[{"batb":[[0,1.92,8.2],[1,1.5,41.84],[2,1.03,200]],"ltp":1.09,"tv":896.74,"id":72857115}]}]}
{"op":"mcm","clk":"11883580172","pt":1724069305658,"mc":[{"id":"1.232011465","rc":[{"batb":[[0,1.93,10],[1,1.92,8.2],[2,1.5,41.84]],"ltp":1.09,"tv":896.74,"id":72857115}]}]}
{"op":"mcm","clk":"11883580348","pt":1724069309093,"mc":[{"id":"1.232011465","rc":[{"batb":[[0,1.92,8.2],[1,1.5,41.84],[2,1.03,200]],"ltp":1.09,"tv":896.74,"id":72857115}]}]}
{"op":"mcm","clk":"11883580594","pt":1724069314380,"mc":[{"id":"1.232011465","rc":[{"batb":[[0,1.93,10],[1,1.92,8.2],[2,1.5,41.84]],"ltp":1.09,"tv":896.74,"id":72857115}]}]}
{"op":"mcm","clk":"11883580770","pt":1724069317769,"mc":[{"id":"1.232011465","rc":[{"batb":[[0,1.92,8.2],[1,1.5,41.84],[2,1.03,200]],"ltp":1.09,"tv":896.74,"id":72857115}]}]}
{"op":"mcm","clk":"11883580900","pt":1724069320697,"mc":[{"id":"1.232011465","rc":[{"batb":[[0,1.93,10],[1,1.92,8.2],[2,1.5,41.84]],"ltp":1.09,"tv":896.74,"id":72857115}]}]}
{"op":"mcm","clk":"11883581088","pt":1724069324301,"mc":[{"id":"1.232011465","rc":[{"batb":[[0,1.92,8.2],[1,1.5,41.84],[2,1.03,200]],"ltp":1.09,"tv":896.74,"id":72857115}]}]}
{"op":"mcm","clk":"11883581300","pt":1724069328977,"mc":[{"id":"1.232011465","rc":[{"batb":[[0,1.93,10],[1,1.92,8.2],[2,1.5,41.84]],"ltp":1.09,"tv":896.74,"id":72857115}]}]}
{"op":"mcm","clk":"11883581456","pt":1724069332316,"mc":[{"id":"1.232011465","rc":[{"batb":[[0,1.92,8.2],[1,1.5,41.84],[2,1.03,200]],"ltp":1.09,"tv":896.74,"id":72857115}]}]}
{"op":"mcm","clk":"11883581555","pt":1724069334628,"mc":[{"id":"1.232011465","rc":[{"batb":[[0,1.93,10],[1,1.92,8.2],[2,1.5,41.84]],"ltp":1.09,"tv":896.74,"id":72857115}]}]}
{"op":"mcm","clk":"11883581712","pt":1724069337923,"mc":[{"id":"1.232011465","rc":[{"batb":[[0,1.92,8.2],[1,1.5,41.84],[2,1.03,200]],"ltp":1.09,"tv":896.74,"id":72857115}]}]}
{"op":"mcm","clk":"11883582034","pt":1724069345018,"mc":[{"id":"1.232011465","rc":[{"batb":[[0,1.93,10],[1,1.92,8.2],[2,1.5,41.84]],"ltp":1.09,"tv":896.74,"id":72857115}]}]}
{"op":"mcm","clk":"11883582178","pt":1724069348418,"mc":[{"id":"1.232011465","rc":[{"batb":[[0,1.92,8.2],[1,1.5,41.84],[2,1.03,200]],"ltp":1.09,"tv":896.74,"id":72857115}]}]}
{"op":"mcm","clk":"11883582374","pt":1724069352016,"mc":[{"id":"1.232011465","rc":[{"batb":[[0,1.93,10],[1,1.92,8.2],[2,1.5,41.84]],"ltp":1.09,"tv":896.74,"id":72857115}]}]}
{"op":"mcm","clk":"11883582519","pt":1724069355460,"mc":[{"id":"1.232011465","rc":[{"batb":[[0,1.92,8.2],[1,1.5,41.84],[2,1.03,200]],"ltp":1.09,"tv":896.74,"id":72857115}]}]}
{"op":"mcm","clk":"11883582629","pt":1724069357723,"mc":[{"id":"1.232011465","rc":[{"batb":[[0,1.93,10],[1,1.92,8.2],[2,1.5,41.84]],"ltp":1.09,"tv":896.74,"id":72857115}]}]}
{"op":"mcm","clk":"11883582794","pt":1724069361069,"mc":[{"id":"1.232011465","rc":[{"batb":[[0,1.92,8.2],[1,1.5,41.84],[2,1.03,200]],"ltp":1.09,"tv":896.74,"id":72857115}]}]}
{"op":"mcm","clk":"11883583018","pt":1724069365952,"mc":[{"id":"1.232011465","rc":[{"batb":[[0,1.93,10],[1,1.92,8.2],[2,1.5,41.84]],"ltp":1.09,"tv":896.74,"id":72857115}]}]}
{"op":"mcm","clk":"11883583158","pt":1724069369239,"mc":[{"id":"1.232011465","rc":[{"batb":[[0,1.92,8.2],[1,1.5,41.84],[2,1.03,200]],"ltp":1.09,"tv":896.74,"id":72857115}]}]}
{"op":"mcm","clk":"11883583319","pt":1724069372983,"mc":[{"id":"1.232011465","rc":[{"batb":[[0,1.93,10],[1,1.92,8.2],[2,1.5,41.84]],"ltp":1.09,"tv":896.74,"id":72857115}]}]}
{"op":"mcm","clk":"11883583492","pt":1724069376472,"mc":[{"id":"1.232011465","rc":[{"batb":[[0,1.92,8.2],[1,1.5,41.84],[2,1.03,200]],"ltp":1.09,"tv":896.74,"id":72857115}]}]}
{"op":"mcm","clk":"11883583631","pt":1724069379395,"mc":[{"id":"1.232011465","rc":[{"batb":[[0,1.93,10],[1,1.92,8.2],[2,1.5,41.84]],"ltp":1.09,"tv":896.74,"id":72857115}]}]}
{"op":"mcm","clk":"11883583785","pt":1724069382676,"mc":[{"id":"1.232011465","rc":[{"batb":[[0,1.92,8.2],[1,1.5,41.84],[2,1.03,200]],"ltp":1.09,"tv":896.74,"id":72857115}]}]}
{"op":"mcm","clk":"11883583937","pt":1724069385603,"mc":[{"id":"1.232011465","rc":[{"batb":[[0,1.93,10],[1,1.92,8.2],[2,1.5,41.84]],"ltp":1.09,"tv":896.74,"id":72857115}]}]}
{"op":"mcm","clk":"11883584104","pt":1724069388787,"mc":[{"id":"1.232011465","rc":[{"batb":[[0,1.92,8.2],[1,1.5,41.84],[2,1.03,200]],"ltp":1.09,"tv":896.74,"id":72857115}]}]}
{"op":"mcm","clk":"11883584253","pt":1724069391089,"mc":[{"id":"1.232011465","rc":[{"batb":[[0,1.93,10],[1,1.92,8.2],[2,1.5,41.84]],"ltp":1.09,"tv":896.74,"id":72857115}]}]}
{"op":"mcm","clk":"11883584403","pt":1724069394487,"mc":[{"id":"1.232011465","rc":[{"batb":[[0,1.92,8.2],[1,1.5,41.84],[2,1.03,200]],"ltp":1.09,"tv":896.74,"id":72857115}]}]}
{"op":"mcm","clk":"11883584598","pt":1724069398795,"mc":[{"id":"1.232011465","rc":[{"batb":[[0,1.93,10],[1,1.92,8.2],[2,1.5,41.84]],"ltp":1.09,"tv":896.74,"id":72857115}]}]}
{"op":"mcm","clk":"11883584756","pt":1724069401990,"mc":[{"id":"1.232011465","rc":[{"batb":[[0,1.92,8.2],[1,1.5,41.84],[2,1.03,200]],"ltp":1.09,"tv":896.74,"id":72857115}]}]}
{"op":"mcm","clk":"11883584947","pt":1724069406039,"mc":[{"id":"1.232011465","rc":[{"batb":[[0,1.93,10],[1,1.92,8.2],[2,1.5,41.84]],"ltp":1.09,"tv":896.74,"id":72857115}]}]}
{"op":"mcm","clk":"11883585140","pt":1724069409537,"mc":[{"id":"1.232011465","rc":[{"batb":[[0,1.92,8.2],[1,1.5,41.84],[2,1.03,200]],"ltp":1.09,"tv":896.74,"id":72857115}]}]}
{"op":"mcm","clk":"11883585376","pt":1724069414314,"mc":[{"id":"1.232011465","rc":[{"batb":[[0,1.93,10],[1,1.92,8.2],[2,1.5,41.84]],"ltp":1.09,"tv":896.74,"id":72857115}]}]}
{"op":"mcm","clk":"11883585556","pt":1724069417815,"mc":[{"id":"1.232011465","rc":[{"batb":[[0,1.92,8.2],[1,1.5,41.84],[2,1.03,200]],"ltp":1.09,"tv":896.74,"id":72857115}]}]}
{"op":"mcm","clk":"11883585736","pt":1724069421616,"mc":[{"id":"1.232011465","rc":[{"batb":[[0,1.93,10],[1,1.92,8.2],[2,1.5,41.84]],"ltp":1.09,"tv":896.74,"id":72857115}]}]}
{"op":"mcm","clk":"11883585893","pt":1724069424954,"mc":[{"id":"1.232011465","rc":[{"batb":[[0,1.92,8.2],[1,1.5,41.84],[2,1.03,200]],"ltp":1.09,"tv":896.74,"id":72857115}]}]}
{"op":"mcm","clk":"11883586044","pt":1724069427835,"mc":[{"id":"1.232011465","rc":[{"batb":[[0,1.93,10],[1,1.92,8.2],[2,1.5,41.84]],"ltp":1.09,"tv":896.74,"id":72857115}]}]}
{"op":"mcm","clk":"11883586202","pt":1724069431177,"mc":[{"id":"1.232011465","rc":[{"batb":[[0,1.92,8.2],[1,1.5,41.84],[2,1.03,200]],"ltp":1.09,"tv":896.74,"id":72857115}]}]}
{"op":"mcm","clk":"11883586499","pt":1724069436755,"mc":[{"id":"1.232011465","rc":[{"batb":[[0,1.93,10],[1,1.92,8.2],[2,1.5,41.84]],"ltp":1.09,"tv":896.74,"id":72857115}]}]}
{"op":"mcm","clk":"11883586654","pt":1724069440063,"mc":[{"id":"1.232011465","rc":[{"batb":[[0,1.92,8.2],[1,1.5,41.84],[2,1.03,200]],"ltp":1.09,"tv":896.74,"id":72857115}]}]}
{"op":"mcm","clk":"11883586843","pt":1724069443778,"mc":[{"id":"1.232011465","rc":[{"batb":[[0,1.93,10],[1,1.92,8.2],[2,1.5,41.84]],"ltp":1.09,"tv":896.74,"id":72857115}]}]}
{"op":"mcm","clk":"11883586989","pt":1724069447162,"mc":[{"id":"1.232011465","rc":[{"batb":[[0,1.92,8.2],[1,1.5,41.84],[2,1.03,200]],"ltp":1.09,"tv":896.74,"id":72857115}]}]}
{"op":"mcm","clk":"11883587719","pt":1724069462369,"mc":[{"id":"1.232011465","rc":[{"batb":[[0,1.93,10],[1,1.92,8.2],[2,1.5,41.84]],"ltp":1.09,"tv":896.74,"id":72857115}]}]}
{"op":"mcm","clk":"11883587903","pt":1724069465764,"mc":[{"id":"1.232011465","rc":[{"batb":[[0,1.92,8.2],[1,1.5,41.84],[2,1.03,200]],"ltp":1.09,"tv":896.74,"id":72857115}]}]}
{"op":"mcm","clk":"11883588237","pt":1724069472187,"mc":[{"id":"1.232011465","rc":[{"batb":[[0,1.93,10],[1,1.92,8.2],[2,1.5,41.84]],"ltp":1.09,"tv":896.74,"id":72857115}]}]}
{"op":"mcm","clk":"11883588448","pt":1724069476491,"mc":[{"id":"1.232011465","rc":[{"batb":[[0,1.92,8.2],[1,1.5,41.84],[2,1.03,200]],"ltp":1.09,"tv":896.74,"id":72857115}]}]}
{"op":"mcm","clk":"11883588615","pt":1724069480186,"mc":[{"id":"1.232011465","rc":[{"batb":[[0,1.93,10],[1,1.92,8.2],[2,1.5,41.84]],"ltp":1.09,"tv":896.74,"id":72857115}]}]}
{"op":"mcm","clk":"11883588784","pt":1724069483474,"mc":[{"id":"1.232011465","rc":[{"batb":[[0,1.92,8.2],[1,1.5,41.84],[2,1.03,200]],"ltp":1.09,"tv":896.74,"id":72857115}]}]}
{"op":"mcm","clk":"11883588955","pt":1724069487214,"mc":[{"id":"1.232011465","rc":[{"batb":[[0,1.93,10],[1,1.92,8.2],[2,1.5,41.84]],"ltp":1.09,"tv":896.74,"id":72857115}]}]}
{"op":"mcm","clk":"11883589092","pt":1724069490602,"mc":[{"id":"1.232011465","rc":[{"batb":[[0,1.92,8.2],[1,1.5,41.84],[2,1.03,200]],"ltp":1.09,"tv":896.74,"id":72857115}]}]}
{"op":"mcm","clk":"11883589361","pt":1724069495223,"mc":[{"id":"1.232011465","rc":[{"batb":[[0,1.93,10],[1,1.92,8.2],[2,1.5,41.84]],"ltp":1.09,"tv":896.74,"id":72857115}]}]}
{"op":"mcm","clk":"11883589535","pt":1724069498718,"mc":[{"id":"1.232011465","rc":[{"batb":[[0,1.92,8.2],[1,1.5,41.84],[2,1.03,200]],"ltp":1.09,"tv":896.74,"id":72857115}]}]}
{"op":"mcm","clk":"11883589815","pt":1724069504900,"mc":[{"id":"1.232011465","rc":[{"batb":[[0,1.93,10],[1,1.92,8.2],[2,1.5,41.84]],"ltp":1.09,"tv":896.74,"id":72857115}]}]}
{"op":"mcm","clk":"11883589990","pt":1724069508444,"mc":[{"id":"1.232011465","rc":[{"batb":[[0,1.92,8.2],[1,1.5,41.84],[2,1.03,200]],"ltp":1.09,"tv":896.74,"id":72857115}]}]}
{"op":"mcm","clk":"11883590356","pt":1724069514917,"mc":[{"id":"1.232011465","rc":[{"batb":[[0,1.93,10],[1,1.92,8.2],[2,1.5,41.84]],"ltp":1.09,"tv":896.74,"id":72857115}]}]}
{"op":"mcm","clk":"11883590522","pt":1724069518423,"mc":[{"id":"1.232011465","rc":[{"batb":[[0,1.92,8.2],[1,1.5,41.84],[2,1.03,200]],"ltp":1.09,"tv":896.74,"id":72857115}]}]}
{"op":"mcm","clk":"11883591051","pt":1724069529538,"mc":[{"id":"1.232011465","rc":[{"batb":[[0,1.93,10],[1,1.92,8.2],[2,1.5,41.84]],"ltp":1.09,"tv":896.74,"id":72857115}]}]}
{"op":"mcm","clk":"11883591220","pt":1724069532937,"mc":[{"id":"1.232011465","rc":[{"batb":[[0,1.92,8.2],[1,1.5,41.84],[2,1.03,200]],"ltp":1.09,"tv":896.74,"id":72857115}]}]}
{"op":"mcm","clk":"11883591504","pt":1724069538739,"mc":[{"id":"1.232011465","rc":[{"batb":[[0,1.93,10],[1,1.92,8.2],[2,1.5,41.84]],"ltp":1.09,"tv":896.74,"id":72857115}]}]}
{"op":"mcm","clk":"11883591657","pt":1724069542072,"mc":[{"id":"1.232011465","rc":[{"batb":[[0,1.92,8.2],[1,1.5,41.84],[2,1.03,200]],"ltp":1.09,"tv":896.74,"id":72857115}]}]}
{"op":"mcm","clk":"11883592038","pt":1724069551170,"mc":[{"id":"1.232011465","rc":[{"batb":[[0,1.93,10],[1,1.92,8.2],[2,1.5,41.84]],"ltp":1.09,"tv":896.74,"id":72857115}]}]}
{"op":"mcm","clk":"11883592208","pt":1724069554360,"mc":[{"id":"1.232011465","rc":[{"batb":[[0,1.92,8.2],[1,1.5,41.84],[2,1.03,200]],"ltp":1.09,"tv":896.74,"id":72857115}]}]}
{"op":"mcm","clk":"11883592246","pt":1724069555084,"mc":[{"id":"1.232011465","rc":[{"batb":[[0,1.84,44.02],[1,1.79,8.78],[2,1.5,41.84]],"ltp":1.09,"tv":901.36,"id":67083366},{"batb":[[0,2.08,34.24],[1,1.92,8.2],[2,1.5,41.84]],"ltp":1.09,"tv":896.74,"id":72857115}]}]}
{"op":"mcm","clk":"11883592328","pt":1724069557295,"mc":[{"id":"1.232011465","rc":[{"batb":[[0,2.1,10],[1,2.08,34.24],[2,1.92,8.2]],"ltp":1.09,"tv":896.74,"id":72857115}]}]}
{"op":"mcm","clk":"11883592448","pt":1724069560686,"mc":[{"id":"1.232011465","rc":[{"batb":[[0,2.08,34.24],[1,1.92,8.2],[2,1.5,41.84]],"ltp":1.09,"tv":896.74,"id":72857115}]}]}
{"op":"mcm","clk":"11883592589","pt":1724069564287,"mc":[{"id":"1.232011465","rc":[{"batb":[[0,2.1,10],[1,2.08,34.24],[2,1.92,8.2]],"ltp":1.09,"tv":896.74,"id":72857115}]}]}
{"op":"mcm","clk":"11883592707","pt":1724069567695,"mc":[{"id":"1.232011465","rc":[{"batb":[[0,2.08,34.24],[1,1.92,8.2],[2,1.5,41.84]],"ltp":1.09,"tv":896.74,"id":72857115}]}]}
{"op":"mcm","clk":"11883592916","pt":1724069572469,"mc":[{"id":"1.232011465","rc":[{"batb":[[0,2.1,10],[1,2.08,34.24],[2,1.92,8.2]],"ltp":1.09,"tv":896.74,"id":72857115}]}]}
{"op":"mcm","clk":"11883601716","pt":1724069575924,"mc":[{"id":"1.232011465","rc":[{"batb":[[0,2.08,34.24],[1,1.92,8.2],[2,1.5,41.84]],"ltp":1.09,"tv":896.74,"id":72857115}]}]}
{"op":"mcm","clk":"11883602165","pt":1724069586110,"mc":[{"id":"1.232011465","rc":[{"batb":[[0,2.1,10],[1,2.08,34.24],[2,1.92,8.2]],"ltp":1.09,"tv":896.74,"id":72857115}]}]}
{"op":"mcm","clk":"11883602325","pt":1724069589505,"mc":[{"id":"1.232011465","rc":[{"batb":[[0,2.08,34.24],[1,1.92,8.2],[2,1.5,41.84]],"ltp":1.09,"tv":896.74,"id":72857115}]}]}
{"op":"mcm","clk":"11883602374","pt":1724069590634,"mc":[{"id":"1.232011465","rc":[{"batb":[[1,1.5,41.84],[2,1.03,200]],"ltp":1.09,"tv":901.36,"id":67083366}]}]}
{"op":"mcm","clk":"11883602457","pt":1724069592592,"mc":[{"id":"1.232011465","rc":[{"batb":[[0,2.1,10],[1,2.08,34.24],[2,1.92,8.2]],"ltp":1.09,"tv":896.74,"id":72857115}]}]}
{"op":"mcm","clk":"11883602651","pt":1724069596194,"mc":[{"id":"1.232011465","rc":[{"batb":[[0,2.08,34.24],[1,1.92,8.2],[2,1.5,41.84]],"ltp":1.09,"tv":896.74,"id":72857115}]}]}
{"op":"mcm","clk":"11883602857","pt":1724069600636,"mc":[{"id":"1.232011465","rc":[{"batb":[[0,2.1,10],[1,2.08,34.24],[2,1.92,8.2]],"ltp":1.09,"tv":896.74,"id":72857115}]}]}
{"op":"mcm","clk":"11883602993","pt":1724069603929,"mc":[{"id":"1.232011465","rc":[{"batb":[[0,2.08,34.24],[1,1.92,8.2],[2,1.5,41.84]],"ltp":1.09,"tv":896.74,"id":72857115}]}]}
{"op":"mcm","clk":"11883603100","pt":1724069606757,"mc":[{"id":"1.232011465","rc":[{"batb":[[0,2.1,10],[1,2.08,34.24],[2,1.92,8.2]],"ltp":1.09,"tv":896.74,"id":72857115}]}]}
{"op":"mcm","clk":"11883603234","pt":1724069610018,"mc":[{"id":"1.232011465","rc":[{"batb":[[0,2.08,34.24],[1,1.92,8.2],[2,1.5,41.84]],"ltp":1.09,"tv":896.74,"id":72857115}]}]}
{"op":"mcm","clk":"11883603353","pt":1724069612443,"mc":[{"id":"1.232011465","rc":[{"batb":[[0,2.1,10],[1,2.08,34.24],[2,1.92,8.2]],"ltp":1.09,"tv":896.74,"id":72857115}]}]}
{"op":"mcm","clk":"11883603497","pt":1724069615663,"mc":[{"id":"1.232011465","rc":[{"batb":[[0,2.08,34.24],[1,1.92,8.2],[2,1.5,41.84]],"ltp":1.09,"tv":896.74,"id":72857115}]}]}
{"op":"mcm","clk":"11883603693","pt":1724069619845,"mc":[{"id":"1.232011465","rc":[{"batb":[[0,2.1,10],[1,2.08,34.24],[2,1.92,8.2]],"ltp":1.09,"tv":896.74,"id":72857115}]}]}
{"op":"mcm","clk":"11883603808","pt":1724069623152,"mc":[{"id":"1.232011465","rc":[{"batb":[[0,2.08,34.24],[1,1.92,8.2],[2,1.5,41.84]],"ltp":1.09,"tv":896.74,"id":72857115}]}]}
{"op":"mcm","clk":"11883603933","pt":1724069626463,"mc":[{"id":"1.232011465","rc":[{"batb":[[0,2.1,10],[1,2.08,34.24],[2,1.92,8.2]],"ltp":1.09,"tv":896.74,"id":72857115}]}]}
{"op":"mcm","clk":"11883604060","pt":1724069629760,"mc":[{"id":"1.232011465","rc":[{"batb":[[0,2.08,34.24],[1,1.92,8.2],[2,1.5,41.84]],"ltp":1.09,"tv":896.74,"id":72857115}]}]}
{"op":"mcm","clk":"11883604174","pt":1724069633168,"mc":[{"id":"1.232011465","rc":[{"batb":[[0,2.1,10],[1,2.08,34.24],[2,1.92,8.2]],"ltp":1.09,"tv":896.74,"id":72857115}]}]}
{"op":"mcm","clk":"11883604235","pt":1724069634765,"mc":[{"id":"1.232011465","rc":[{"trd":[[1.91,1.37]],"ltp":1.91,"tv":902.74,"id":67083366},{"trd":[[2.1,1.25]],"batb":[[0,2.1,8.75]],"ltp":2.1,"tv":897.99,"id":72857115}],"tv":1800.73}]}
{"op":"mcm","clk":"11883604288","pt":1724069636460,"mc":[{"id":"1.232011465","rc":[{"batb":[[0,2.08,34.24],[1,1.92,8.2],[2,1.5,41.84]],"ltp":2.1,"tv":897.99,"id":72857115}]}]}
{"op":"mcm","clk":"11883604563","pt":1724069642990,"mc":[{"id":"1.232011465","rc":[{"batb":[[0,2.1,10],[1,2.08,34.24],[2,1.92,8.2]],"ltp":2.1,"tv":897.99,"id":72857115}]}]}
{"op":"mcm","clk":"11883604720","pt":1724069646498,"mc":[{"id":"1.232011465","rc":[{"batb":[[0,2.08,34.24],[1,1.92,8.2],[2,1.5,41.84]],"ltp":2.1,"tv":897.99,"id":72857115}]}]}
{"op":"mcm","clk":"11883604808","pt":1724069648810,"mc":[{"id":"1.232011465","rc":[{"batb":[[0,2.1,10],[1,2.08,34.24],[2,1.92,8.2]],"ltp":2.1,"tv":897.99,"id":72857115}]}]}
{"op":"mcm","clk":"11883604907","pt":1724069651180,"mc":[{"id":"1.232011465","rc":[{"batb":[[1,1.77,8.89],[2,1.5,41.84]],"ltp":1.91,"tv":902.74,"id":67083366}]}]}
{"op":"mcm","clk":"11883604935","pt":1724069652009,"mc":[{"id":"1.232011465","rc":[{"batb":[[0,2.08,34.24],[1,1.92,8.2],[2,1.5,41.84]],"ltp":2.1,"tv":897.99,"id":72857115}]}]}
{"op":"mcm","clk":"11883605011","pt":1724069654185,"mc":[{"id":"1.232011465","rc":[{"batb":[[0,2.1,10],[1,2.08,34.24],[2,1.92,8.2]],"ltp":2.1,"tv":897.99,"id":72857115}]}]}
{"op":"mcm","clk":"11883605133","pt":1724069657478,"mc":[{"id":"1.232011465","rc":[{"batb":[[0,2.08,34.24],[1,1.92,8.2],[2,1.5,41.84]],"ltp":2.1,"tv":897.99,"id":72857115}]}]}
{"op":"mcm","clk":"11883605313","pt":1724069661194,"mc":[{"id":"1.232011465","rc":[{"batb":[[0,2.1,10],[1,2.08,34.24],[2,1.92,8.2]],"ltp":2.1,"tv":897.99,"id":72857115}]}]}
{"op":"mcm","clk":"11883605555","pt":1724069665423,"mc":[{"id":"1.232011465","rc":[{"batb":[[0,2.08,34.24],[1,1.92,8.2],[2,1.5,41.84]],"ltp":2.1,"tv":897.99,"id":72857115}]}]}
{"op":"mcm","clk":"11883605932","pt":1724069672943,"mc":[{"id":"1.232011465","rc":[{"batb":[[0,2.1,10],[1,2.08,34.24],[2,1.92,8.2]],"ltp":2.1,"tv":897.99,"id":72857115}]}]}
{"op":"mcm","clk":"11883606100","pt":1724069676352,"mc":[{"id":"1.232011465","rc":[{"batb":[[0,2.08,34.24],[1,1.92,8.2],[2,1.5,41.84]],"ltp":2.1,"tv":897.99,"id":72857115}]}]}
{"op":"mcm","clk":"11883606929","pt":1724069691469,"mc":[{"id":"1.232011465","rc":[{"batb":[[0,2.1,10],[1,2.08,34.24],[2,1.92,8.2]],"ltp":2.1,"tv":897.99,"id":72857115}]}]}
{"op":"mcm","clk":"11883607106","pt":1724069694868,"mc":[{"id":"1.232011465","rc":[{"batb":[[0,2.08,34.24],[1,1.92,8.2],[2,1.5,41.84]],"ltp":2.1,"tv":897.99,"id":72857115}]}]}
{"op":"mcm","clk":"11883607256","pt":1724069697391,"mc":[{"id":"1.232011465","rc":[{"batb":[[0,2.1,10],[1,2.08,34.24],[2,1.92,8.2]],"ltp":2.1,"tv":897.99,"id":72857115}]}]}
{"op":"mcm","clk":"11883607523","pt":1724069701817,"mc":[{"id":"1.232011465","rc":[{"batb":[[0,2.08,34.24],[1,1.92,8.2],[2,1.5,41.84]],"ltp":2.1,"tv":897.99,"id":72857115}]}]}
{"op":"mcm","clk":"11883607682","pt":1724069704305,"mc":[{"id":"1.232011465","rc":[{"batb":[[0,2.1,10],[1,2.08,34.24],[2,1.92,8.2]],"ltp":2.1,"tv":897.99,"id":72857115}]}]}
{"op":"mcm","clk":"11883607868","pt":1724069707641,"mc":[{"id":"1.232011465","rc":[{"batb":[[0,2.08,34.24],[1,1.92,8.2],[2,1.5,41.84]],"ltp":2.1,"tv":897.99,"id":72857115}]}]}
{"op":"mcm","clk":"11883609207","pt":1724069733346,"mc":[{"id":"1.232011465","rc":[{"batb":[[0,2.1,10],[1,2.08,34.24],[2,1.92,8.2]],"ltp":2.1,"tv":897.99,"id":72857115}]}]}
{"op":"mcm","clk":"11883609383","pt":1724069736845,"mc":[{"id":"1.232011465","rc":[{"batb":[[0,2.08,34.24],[1,1.92,8.2],[2,1.5,41.84]],"ltp":2.1,"tv":897.99,"id":72857115}]}]}
{"op":"mcm","clk":"11883609768","pt":1724069744753,"mc":[{"id":"1.232011465","rc":[{"batb":[[0,2.1,10],[1,2.08,34.24],[2,1.92,8.2]],"ltp":2.1,"tv":897.99,"id":72857115}]}]}
{"op":"mcm","clk":"11883609934","pt":1724069748050,"mc":[{"id":"1.232011465","rc":[{"batb":[[0,2.08,34.24],[1,1.92,8.2],[2,1.5,41.84]],"ltp":2.1,"tv":897.99,"id":72857115}]}]}
{"op":"mcm","clk":"11883610310","pt":1724069755957,"mc":[{"id":"1.232011465","rc":[{"batb":[[0,2.1,10],[1,2.08,34.24],[2,1.92,8.2]],"ltp":2.1,"tv":897.99,"id":72857115}]}]}
{"op":"mcm","clk":"11883610478","pt":1724069759354,"mc":[{"id":"1.232011465","rc":[{"batb":[[0,2.08,34.24],[1,1.92,8.2],[2,1.5,41.84]],"ltp":2.1,"tv":897.99,"id":72857115}]}]}
{"op":"mcm","clk":"11883611102","pt":1724069771620,"mc":[{"id":"1.232011465","rc":[{"batb":[[0,2.1,10],[1,2.08,34.24],[2,1.92,8.2]],"ltp":2.1,"tv":897.99,"id":72857115}]}]}
{"op":"mcm","clk":"11883611303","pt":1724069774883,"mc":[{"id":"1.232011465","rc":[{"batb":[[0,2.08,34.24],[1,1.92,8.2],[2,1.5,41.84]],"ltp":2.1,"tv":897.99,"id":72857115}]}]}
{"op":"mcm","clk":"11883611583","pt":1724069780511,"mc":[{"id":"1.232011465","rc":[{"batb":[[0,2.1,10],[1,2.08,34.24],[2,1.92,8.2]],"ltp":2.1,"tv":897.99,"id":72857115}]}]}
{"op":"mcm","clk":"11883611746","pt":1724069784008,"mc":[{"id":"1.232011465","rc":[{"batb":[[0,2.08,34.24],[1,1.92,8.2],[2,1.5,41.84]],"ltp":2.1,"tv":897.99,"id":72857115}]}]}
{"op":"mcm","clk":"11883611929","pt":1724069787606,"mc":[{"id":"1.232011465","rc":[{"batb":[[0,2.1,10],[1,2.08,34.24],[2,1.92,8.2]],"ltp":2.1,"tv":897.99,"id":72857115}]}]}
{"op":"mcm","clk":"11883612130","pt":1724069791111,"mc":[{"id":"1.232011465","rc":[{"batb":[[1,1.5,41.84],[2,1.03,200]],"ltp":1.91,"tv":902.74,"id":67083366},{"batb":[[0,2.08,34.24],[1,1.92,8.2],[2,1.5,41.84]],"ltp":2.1,"tv":897.99,"id":72857115}]}]}
{"op":"mcm","clk":"11883612374","pt":1724069794826,"mc":[{"id":"1.232011465","rc":[{"batb":[[0,2.1,10],[1,2.08,34.24],[2,1.92,8.2]],"ltp":2.1,"tv":897.99,"id":72857115}]}]}
{"op":"mcm","clk":"11883612551","pt":1724069798226,"mc":[{"id":"1.232011465","rc":[{"batb":[[0,2.08,34.24],[1,1.92,8.2],[2,1.5,41.84]],"ltp":2.1,"tv":897.99,"id":72857115}]}]}
{"op":"mcm","clk":"11883613425","pt":1724069814359,"mc":[{"id":"1.232011465","rc":[{"batb":[[1,1.77,8.89],[2,1.5,41.84]],"ltp":1.91,"tv":902.74,"id":67083366},{"batb":[[0,2.1,10],[1,2.08,34.24],[2,1.92,8.2]],"ltp":2.1,"tv":897.99,"id":72857115}]}]}
{"op":"mcm","clk":"11883613615","pt":1724069817563,"mc":[{"id":"1.232011465","rc":[{"batb":[[0,2.08,34.24],[1,1.92,8.2],[2,1.5,41.84]],"ltp":2.1,"tv":897.99,"id":72857115}]}]}
{"op":"mcm","clk":"11883613890","pt":1724069822237,"mc":[{"id":"1.232011465","rc":[{"batb":[[0,2.1,10],[1,2.08,34.24],[2,1.92,8.2]],"ltp":2.1,"tv":897.99,"id":72857115}]}]}
{"op":"mcm","clk":"11883614041","pt":1724069825469,"mc":[{"id":"1.232011465","rc":[{"batb":[[0,2.08,34.24],[1,1.92,8.2],[2,1.5,41.84]],"ltp":2.1,"tv":897.99,"id":72857115}]}]}
{"op":"mcm","clk":"11883614576","pt":1724069837762,"mc":[{"id":"1.232011465","rc":[{"batb":[[0,2.1,10],[1,2.08,34.24],[2,1.92,8.2]],"ltp":2.1,"tv":897.99,"id":72857115}]}]}
{"op":"mcm","clk":"11883614753","pt":1724069841059,"mc":[{"id":"1.232011465","rc":[{"batb":[[0,2.08,34.24],[1,1.92,8.2],[2,1.5,41.84]],"ltp":2.1,"tv":897.99,"id":72857115}]}]}
{"op":"mcm","clk":"11883614912","pt":1724069844098,"mc":[{"id":"1.232011465","rc":[{"batb":[[0,2.1,10],[1,2.08,34.24],[2,1.92,8.2]],"ltp":2.1,"tv":897.99,"id":72857115}]}]}
{"op":"mcm","clk":"11883615119","pt":1724069848384,"mc":[{"id":"1.232011465","rc":[{"batb":[[0,2.08,34.24],[1,1.92,8.2],[2,1.5,41.84]],"ltp":2.1,"tv":897.99,"id":72857115}]}]}
{"op":"mcm","clk":"11883615414","pt":1724069855283,"mc":[{"id":"1.232011465","rc":[{"batb":[[0,2.1,10],[1,2.08,34.24],[2,1.92,8.2]],"ltp":2.1,"tv":897.99,"id":72857115}]}]}
{"op":"mcm","clk":"11883615547","pt":1724069858406,"mc":[{"id":"1.232011465","rc":[{"batb":[[0,2.08,34.24],[1,1.92,8.2],[2,1.5,41.84]],"ltp":2.1,"tv":897.99,"id":72857115}]}]}
{"op":"mcm","clk":"11883616181","pt":1724069873512,"mc":[{"id":"1.232011465","rc":[{"batb":[[0,2.1,10],[1,2.08,34.24],[2,1.92,8.2]],"ltp":2.1,"tv":897.99,"id":72857115}]}]}
{"op":"mcm","clk":"11883616318","pt":1724069876813,"mc":[{"id":"1.232011465","rc":[{"batb":[[0,2.08,34.24],[1,1.92,8.2],[2,1.5,41.84]],"ltp":2.1,"tv":897.99,"id":72857115}]}]}
{"op":"mcm","clk":"11883616456","pt":1724069880206,"mc":[{"id":"1.232011465","rc":[{"batb":[[0,2.1,10],[1,2.08,34.24],[2,1.92,8.2]],"ltp":2.1,"tv":897.99,"id":72857115}]}]}
{"op":"mcm","clk":"11883616626","pt":1724069883711,"mc":[{"id":"1.232011465","rc":[{"batb":[[0,2.08,34.24],[1,1.92,8.2],[2,1.5,41.84]],"ltp":2.1,"tv":897.99,"id":72857115}]}]}
{"op":"mcm","clk":"11883616748","pt":1724069886440,"mc":[{"id":"1.232011465","rc":[{"batb":[[0,2.1,10],[1,2.08,34.24],[2,1.92,8.2]],"ltp":2.1,"tv":897.99,"id":72857115}]}]}
{"op":"mcm","clk":"11883616915","pt":1724069889634,"mc":[{"id":"1.232011465","rc":[{"batb":[[1,1.5,41.84],[2,1.03,200]],"ltp":1.91,"tv":902.74,"id":67083366},{"batb":[[0,2.08,34.24],[1,1.92,8.2],[2,1.5,41.84]],"ltp":2.1,"tv":897.99,"id":72857115}]}]}
{"op":"mcm","clk":"11883616968","pt":1724069890511,"mc":[{"id":"1.232011465","rc":[{"batb":[[1,1.52,7.75],[2,1.5,41.84]],"batl":[[1,2.48,4.65],[2,13,0.94]],"ltp":1.91,"tv":902.74,"id":67083366}]}]}
{"op":"mcm","clk":"11883617201","pt":1724069894836,"mc":[{"id":"1.232011465","rc":[{"batb":[[0,2.12,10],[1,2.08,34.24],[2,1.92,8.2]],"ltp":2.1,"tv":897.99,"id":72857115}]}]}
{"op":"mcm","clk":"11883617476","pt":1724069900455,"mc":[{"id":"1.232011465","rc":[{"batb":[[0,2.08,34.24],[1,1.92,8.2],[2,1.5,41.84]],"ltp":2.1,"tv":897.99,"id":72857115}]}]}
{"op":"mcm","clk":"11883617690","pt":1724069904940,"mc":[{"id":"1.232011465","rc":[{"batb":[[0,2.1,10],[1,2.08,34.24],[2,1.92,8.2]],"ltp":2.1,"tv":897.99,"id":72857115}]}]}
{"op":"mcm","clk":"11883617831","pt":1724069908239,"mc":[{"id":"1.232011465","rc":[{"batb":[[0,2.08,34.24],[1,1.92,8.2],[2,1.5,41.84]],"ltp":2.1,"tv":897.99,"id":72857115}]}]}
{"op":"mcm","clk":"11883617979","pt":1724069911437,"mc":[{"id":"1.232011465","rc":[{"batb":[[1,1.77,8.89],[2,1.52,7.75]],"ltp":1.91,"tv":902.74,"id":67083366}]}]}
{"op":"mcm","clk":"11883617986","pt":1724069911541,"mc":[{"id":"1.232011465","rc":[{"batb":[[0,2.1,10],[1,2.08,34.24],[2,1.92,8.2]],"ltp":2.1,"tv":897.99,"id":72857115}]}]}
{"op":"mcm","clk":"11883618162","pt":1724069914791,"mc":[{"id":"1.232011465","rc":[{"batb":[[0,2.08,34.24],[1,1.92,8.2],[2,1.5,41.84]],"ltp":2.1,"tv":897.99,"id":72857115}]}]}
{"op":"mcm","clk":"11883618401","pt":1724069919454,"mc":[{"id":"1.232011465","rc":[{"batb":[[0,2.1,10],[1,2.08,34.24],[2,1.92,8.2]],"ltp":2.1,"tv":897.99,"id":72857115}]}]}
{"op":"mcm","clk":"11883618562","pt":1724069922861,"mc":[{"id":"1.232011465","rc":[{"batb":[[0,2.08,34.24],[1,1.92,8.2],[2,1.5,41.84]],"ltp":2.1,"tv":897.99,"id":72857115}]}]}
{"op":"mcm","clk":"11883618956","pt":1724069930087,"mc":[{"id":"1.232011465","rc":[{"batb":[[0,2.1,10],[1,2.08,34.24],[2,1.92,8.2]],"ltp":2.1,"tv":897.99,"id":72857115}]}]}
{"op":"mcm","clk":"11883619214","pt":1724069934580,"mc":[{"id":"1.232011465","rc":[{"batb":[[0,2.08,34.24],[1,1.92,8.2],[2,1.5,41.84]],"ltp":2.1,"tv":897.99,"id":72857115}]}]}
{"op":"mcm","clk":"11883619746","pt":1724069945091,"mc":[{"id":"1.232011465","rc":[{"batb":[[0,2.1,10],[1,2.08,34.24],[2,1.92,8.2]],"ltp":2.1,"tv":897.99,"id":72857115}]}]}
{"op":"mcm","clk":"11883619935","pt":1724069948548,"mc":[{"id":"1.232011465","rc":[{"batb":[[0,2.08,34.24],[1,1.92,8.2],[2,1.5,41.84]],"ltp":2.1,"tv":897.99,"id":72857115}]}]}
{"op":"mcm","clk":"11883620207","pt":1724069954720,"mc":[{"id":"1.232011465","rc":[{"batb":[[0,2.1,10],[1,2.08,34.24],[2,1.92,8.2]],"ltp":2.1,"tv":897.99,"id":72857115}]}]}
{"op":"mcm","clk":"11883620359","pt":1724069958223,"mc":[{"id":"1.232011465","rc":[{"batb":[[0,2.08,34.24],[1,1.92,8.2],[2,1.5,41.84]],"ltp":2.1,"tv":897.99,"id":72857115}]}]}
{"op":"mcm","clk":"11883620781","pt":1724069966407,"mc":[{"id":"1.232011465","rc":[{"batb":[[0,2.1,10],[1,2.08,34.24],[2,1.92,8.2]],"ltp":2.1,"tv":897.99,"id":72857115}]}]}
{"op":"mcm","clk":"11883620921","pt":1724069969855,"mc":[{"id":"1.232011465","rc":[{"batb":[[1,1.52,7.75],[2,1.5,41.84]],"ltp":1.91,"tv":902.74,"id":67083366},{"batb":[[0,2.08,34.24],[1,1.92,8.2],[2,1.5,41.84]],"ltp":2.1,"tv":897.99,"id":72857115}]}]}
{"op":"mcm","clk":"11883621239","pt":1724069977470,"mc":[{"id":"1.232011465","rc":[{"batb":[[0,2.1,10],[1,2.08,34.24],[2,1.92,8.2]],"ltp":2.1,"tv":897.99,"id":72857115}]}]}
{"op":"mcm","clk":"11883621410","pt":1724069980976,"mc":[{"id":"1.232011465","rc":[{"batb":[[0,2.08,34.24],[1,1.92,8.2],[2,1.5,41.84]],"ltp":2.1,"tv":897.99,"id":72857115}]}]}
{"op":"mcm","clk":"11883621695","pt":1724069987479,"mc":[{"id":"1.232011465","rc":[{"batb":[[0,2.1,10],[1,2.08,34.24],[2,1.92,8.2]],"ltp":2.1,"tv":897.99,"id":72857115}]}]}
{"op":"mcm","clk":"11883621873","pt":1724069990882,"mc":[{"id":"1.232011465","rc":[{"batb":[[0,2.08,34.24],[1,1.92,8.2],[2,1.5,41.84]],"ltp":2.1,"tv":897.99,"id":72857115}]}]}
{"op":"mcm","clk":"11883622007","pt":1724069993573,"mc":[{"id":"1.232011465","rc":[{"batb":[[0,2.1,10],[1,2.08,34.24],[2,1.92,8.2]],"ltp":2.1,"tv":897.99,"id":72857115}]}]}
{"op":"mcm","clk":"11883622150","pt":1724069996764,"mc":[{"id":"1.232011465","rc":[{"batb":[[0,2.08,34.24],[1,1.92,8.2],[2,1.5,41.84]],"ltp":2.1,"tv":897.99,"id":72857115}]}]}
{"op":"mcm","clk":"11883622637","pt":1724070007983,"mc":[{"id":"1.232011465","rc":[{"batb":[[0,2.1,10],[1,2.08,34.24],[2,1.92,8.2]],"ltp":2.1,"tv":897.99,"id":72857115}]}]}
{"op":"mcm","clk":"11883622790","pt":1724070011379,"mc":[{"id":"1.232011465","rc":[{"batb":[[0,2.08,34.24],[1,1.92,8.2],[2,1.5,41.84]],"ltp":2.1,"tv":897.99,"id":72857115}]}]}
{"op":"mcm","clk":"11883623402","pt":1724070023595,"mc":[{"id":"1.232011465","rc":[{"batb":[[0,2.1,10],[1,2.08,34.24],[2,1.92,8.2]],"ltp":2.1,"tv":897.99,"id":72857115}]}]}
{"op":"mcm","clk":"11883623563","pt":1724070027091,"mc":[{"id":"1.232011465","rc":[{"batb":[[0,2.08,34.24],[1,1.92,8.2],[2,1.5,41.84]],"ltp":2.1,"tv":897.99,"id":72857115}]}]}
{"op":"mcm","clk":"11883623661","pt":1724070029601,"mc":[{"id":"1.232011465","rc":[{"batb":[[0,2.1,10],[1,2.08,34.24],[2,1.92,8.2]],"ltp":2.1,"tv":897.99,"id":72857115}]}]}
{"op":"mcm","clk":"11883623776","pt":1724070032013,"mc":[{"id":"1.232011465","rc":[{"batb":[[1,1.77,8.89],[2,1.52,7.75]],"ltp":1.91,"tv":902.74,"id":67083366}]}]}
{"op":"mcm","clk":"11883623832","pt":1724070032935,"mc":[{"id":"1.232011465","rc":[{"batb":[[0,2.08,34.24],[1,1.92,8.2],[2,1.5,41.84]],"ltp":2.1,"tv":897.99,"id":72857115}]}]}
{"op":"mcm","clk":"11883624304","pt":1724070041243,"mc":[{"id":"1.232011465","rc":[{"batb":[[0,2.1,10],[1,2.08,34.24],[2,1.92,8.2]],"ltp":2.1,"tv":897.99,"id":72857115}]}]}
{"op":"mcm","clk":"11883624455","pt":1724070044642,"mc":[{"id":"1.232011465","rc":[{"batb":[[0,2.08,34.24],[1,1.92,8.2],[2,1.5,41.84]],"ltp":2.1,"tv":897.99,"id":72857115}]}]}
{"op":"mcm","clk":"11883624705","pt":1724070049824,"mc":[{"id":"1.232011465","rc":[{"batb":[[0,2.1,10],[1,2.08,34.24],[2,1.92,8.2]],"ltp":2.1,"tv":897.99,"id":72857115}]}]}
{"op":"mcm","clk":"11883624828","pt":1724070053159,"mc":[{"id":"1.232011465","rc":[{"batb":[[0,2.08,34.24],[1,1.92,8.2],[2,1.5,41.84]],"ltp":2.1,"tv":897.99,"id":72857115}]}]}
{"op":"mcm","clk":"11883624959","pt":1724070056836,"mc":[{"id":"1.232011465","rc":[{"batb":[[0,2.1,10],[1,2.08,34.24],[2,1.92,8.2]],"ltp":2.1,"tv":897.99,"id":72857115}]}]}
{"op":"mcm","clk":"11883625095","pt":1724070060366,"mc":[{"id":"1.232011465","rc":[{"batb":[[0,2.08,34.24],[1,1.92,8.2],[2,1.5,41.84]],"ltp":2.1,"tv":897.99,"id":72857115}]}]}
{"op":"mcm","clk":"11883625194","pt":1724070062931,"mc":[{"id":"1.232011465","rc":[{"batb":[[0,2.1,10],[1,2.08,34.24],[2,1.92,8.2]],"ltp":2.1,"tv":897.99,"id":72857115}]}]}
{"op":"mcm","clk":"11883625331","pt":1724070066371,"mc":[{"id":"1.232011465","rc":[{"batb":[[0,2.08,34.24],[1,1.92,8.2],[2,1.5,41.84]],"ltp":2.1,"tv":897.99,"id":72857115}]}]}
{"op":"mcm","clk":"11883625785","pt":1724070077282,"mc":[{"id":"1.232011465","rc":[{"batb":[[0,2.1,10],[1,2.08,34.24],[2,1.92,8.2]],"ltp":2.1,"tv":897.99,"id":72857115}]}]}
{"op":"mcm","clk":"11883625889","pt":1724070080453,"mc":[{"id":"1.232011465","rc":[{"batb":[[0,2.08,34.24],[1,1.92,8.2],[2,1.5,41.84]],"ltp":2.1,"tv":897.99,"id":72857115}]}]}
{"op":"mcm","clk":"11883626267","pt":1724070090394,"mc":[{"id":"1.232011465","rc":[{"batb":[[0,2.1,10],[1,2.08,34.24],[2,1.92,8.2]],"ltp":2.1,"tv":897.99,"id":72857115}]}]}
{"op":"mcm","clk":"11883626389","pt":1724070093621,"mc":[{"id":"1.232011465","rc":[{"batb":[[0,2.08,34.24],[1,1.92,8.2],[2,1.5,41.84]],"ltp":2.1,"tv":897.99,"id":72857115}]}]}
{"op":"mcm","clk":"11883627308","pt":1724070115086,"mc":[{"id":"1.232011465","rc":[{"batb":[[0,2.1,10],[1,2.08,34.24],[2,1.92,8.2]],"ltp":2.1,"tv":897.99,"id":72857115}]}]}
{"op":"mcm","clk":"11883627455","pt":1724070118367,"mc":[{"id":"1.232011465","rc":[{"batb":[[0,2.08,34.24],[1,1.92,8.2],[2,1.5,41.84]],"ltp":2.1,"tv":897.99,"id":72857115}]}]}
{"op":"mcm","clk":"11883627799","pt":1724070125813,"mc":[{"id":"1.232011465","rc":[{"batb":[[0,2.1,10],[1,2.08,34.24],[2,1.92,8.2]],"ltp":2.1,"tv":897.99,"id":72857115}]}]}
{"op":"mcm","clk":"11883628003","pt":1724070129623,"mc":[{"id":"1.232011465","rc":[{"batb":[[0,2.08,34.24],[1,1.92,8.2],[2,1.5,41.84]],"ltp":2.1,"tv":897.99,"id":72857115}]}]}
{"op":"mcm","clk":"11883628088","pt":1724070131411,"mc":[{"id":"1.232011465","rc":[{"batb":[[1,1.52,7.75],[2,1.5,41.84]],"ltp":1.91,"tv":902.74,"id":67083366}]}]}
{"op":"mcm","clk":"11883628204","pt":1724070133917,"mc":[{"id":"1.232011465","rc":[{"batb":[[0,2.1,10],[1,2.08,34.24],[2,1.92,8.2]],"ltp":2.1,"tv":897.99,"id":72857115}]}]}
{"op":"mcm","clk":"11883628363","pt":1724070137308,"mc":[{"id":"1.232011465","rc":[{"batb":[[0,2.08,34.24],[1,1.92,8.2],[2,1.5,41.84]],"ltp":2.1,"tv":897.99,"id":72857115}]}]}
{"op":"mcm","clk":"11883628522","pt":1724070140898,"mc":[{"id":"1.232011465","rc":[{"batb":[[0,2.1,10],[1,2.08,34.24],[2,1.92,8.2]],"ltp":2.1,"tv":897.99,"id":72857115}]}]}
{"op":"mcm","clk":"11883628650","pt":1724070144332,"mc":[{"id":"1.232011465","rc":[{"batb":[[0,2.08,34.24],[1,1.92,8.2],[2,1.5,41.84]],"ltp":2.1,"tv":897.99,"id":72857115}]}]}
{"op":"mcm","clk":"11883628850","pt":1724070148717,"mc":[{"id":"1.232011465","rc":[{"batb":[[0,2.1,10],[1,2.08,34.24],[2,1.92,8.2]],"ltp":2.1,"tv":897.99,"id":72857115}]}]}
{"op":"mcm","clk":"11883629005","pt":1724070152153,"mc":[{"id":"1.232011465","rc":[{"batb":[[0,2.08,34.24],[1,1.92,8.2],[2,1.5,41.84]],"ltp":2.1,"tv":897.99,"id":72857115}]}]}
{"op":"mcm","clk":"11883629426","pt":1724070160965,"mc":[{"id":"1.232011465","rc":[{"batb":[[0,2.1,10],[1,2.08,34.24],[2,1.92,8.2]],"ltp":2.1,"tv":897.99,"id":72857115}]}]}
{"op":"mcm","clk":"11883629604","pt":1724070164157,"mc":[{"id":"1.232011465","rc":[{"batb":[[0,2.08,34.24],[1,1.92,8.2],[2,1.5,41.84]],"ltp":2.1,"tv":897.99,"id":72857115}]}]}
{"op":"mcm","clk":"11883629770","pt":1724070167242,"mc":[{"id":"1.232011465","rc":[{"batb":[[0,2.1,10],[1,2.08,34.24],[2,1.92,8.2]],"ltp":2.1,"tv":897.99,"id":72857115}]}]}
{"op":"mcm","clk":"11883630001","pt":1724070171868,"mc":[{"id":"1.232011465","rc":[{"batb":[[0,2.08,34.24],[1,1.92,8.2],[2,1.5,41.84]],"ltp":2.1,"tv":897.99,"id":72857115}]}]}
{"op":"mcm","clk":"11883630160","pt":1724070175157,"mc":[{"id":"1.232011465","rc":[{"batb":[[0,2.1,10],[1,2.08,34.24],[2,1.92,8.2]],"ltp":2.1,"tv":897.99,"id":72857115}]}]}
{"op":"mcm","clk":"11883630294","pt":1724070178645,"mc":[{"id":"1.232011465","rc":[{"batb":[[0,2.08,34.24],[1,1.92,8.2],[2,1.5,41.84]],"ltp":2.1,"tv":897.99,"id":72857115}]}]}
{"op":"mcm","clk":"11883630648","pt":1724070186765,"mc":[{"id":"1.232011465","rc":[{"batb":[[0,2.1,10],[1,2.08,34.24],[2,1.92,8.2]],"ltp":2.1,"tv":897.99,"id":72857115}]}]}
{"op":"mcm","clk":"11883630834","pt":1724070190099,"mc":[{"id":"1.232011465","rc":[{"batb":[[0,2.08,34.24],[1,1.92,8.2],[2,1.5,41.84]],"ltp":2.1,"tv":897.99,"id":72857115}]}]}
{"op":"mcm","clk":"11883630938","pt":1724070192305,"mc":[{"id":"1.232011465","rc":[{"batb":[[0,2.1,10],[1,2.08,34.24],[2,1.92,8.2]],"ltp":2.1,"tv":897.99,"id":72857115}]}]}
{"op":"mcm","clk":"11883631148","pt":1724070197089,"mc":[{"id":"1.232011465","rc":[{"batb":[[0,2.08,34.24],[1,1.92,8.2],[2,1.5,41.84]],"ltp":2.1,"tv":897.99,"id":72857115}]}]}
{"op":"mcm","clk":"11883631243","pt":1724070199901,"mc":[{"id":"1.232011465","rc":[{"batb":[[0,2.1,10],[1,2.08,34.24],[2,1.92,8.2]],"ltp":2.1,"tv":897.99,"id":72857115}]}]}
{"op":"mcm","clk":"11883631365","pt":1724070203295,"mc":[{"id":"1.232011465","rc":[{"batb":[[0,2.08,34.24],[1,1.92,8.2],[2,1.5,41.84]],"ltp":2.1,"tv":897.99,"id":72857115}]}]}
{"op":"mcm","clk":"11883631581","pt":1724070208522,"mc":[{"id":"1.232011465","rc":[{"batb":[[0,2.1,10],[1,2.08,34.24],[2,1.92,8.2]],"ltp":2.1,"tv":897.99,"id":72857115}]}]}
{"op":"mcm","clk":"11883631711","pt":1724070211704,"mc":[{"id":"1.232011465","rc":[{"batb":[[0,2.08,34.24],[1,1.92,8.2],[2,1.5,41.84]],"ltp":2.1,"tv":897.99,"id":72857115}]}]}
{"op":"mcm","clk":"11883632076","pt":1724070218498,"mc":[{"id":"1.232011465","rc":[{"batb":[[0,2.1,10],[1,2.08,34.24],[2,1.92,8.2]],"ltp":2.1,"tv":897.99,"id":72857115}]}]}
{"op":"mcm","clk":"11883632237","pt":1724070222237,"mc":[{"id":"1.232011465","rc":[{"batb":[[0,2.08,34.24],[1,1.92,8.2],[2,1.5,41.84]],"ltp":2.1,"tv":897.99,"id":72857115}]}]}
{"op":"mcm","clk":"11883632342","pt":1724070224809,"mc":[{"id":"1.232011465","rc":[{"batb":[[0,2.1,10],[1,2.08,34.24],[2,1.92,8.2]],"ltp":2.1,"tv":897.99,"id":72857115}]}]}
{"op":"mcm","clk":"11883632481","pt":1724070228033,"mc":[{"id":"1.232011465","rc":[{"batb":[[0,2.08,34.24],[1,1.92,8.2],[2,1.5,41.84]],"ltp":2.1,"tv":897.99,"id":72857115}]}]}
{"op":"mcm","clk":"11883632550","pt":1724070229531,"mc":[{"id":"1.232011465","rc":[{"batb":[[1,1.77,8.89],[2,1.52,7.75]],"ltp":1.91,"tv":902.74,"id":67083366}]}]}
{"op":"mcm","clk":"11883632611","pt":1724070230719,"mc":[{"id":"1.232011465","rc":[{"batb":[[0,2.1,10],[1,2.08,34.24],[2,1.92,8.2]],"ltp":2.1,"tv":897.99,"id":72857115}]}]}
{"op":"mcm","clk":"11883632734","pt":1724070234145,"mc":[{"id":"1.232011465","rc":[{"batb":[[0,2.08,34.24],[1,1.92,8.2],[2,1.5,41.84]],"ltp":2.1,"tv":897.99,"id":72857115}]}]}
{"op":"mcm","clk":"11883632970","pt":1724070239637,"mc":[{"id":"1.232011465","rc":[{"batb":[[0,2.1,10],[1,2.08,34.24],[2,1.92,8.2]],"ltp":2.1,"tv":897.99,"id":72857115}]}]}
{"op":"mcm","clk":"11883633127","pt":1724070242925,"mc":[{"id":"1.232011465","rc":[{"batb":[[0,2.08,34.24],[1,1.92,8.2],[2,1.5,41.84]],"ltp":2.1,"tv":897.99,"id":72857115}]}]}
{"op":"mcm","clk":"11883633483","pt":1724070250746,"mc":[{"id":"1.232011465","rc":[{"batb":[[0,2.1,10],[1,2.08,34.24],[2,1.92,8.2]],"ltp":2.1,"tv":897.99,"id":72857115}]}]}
{"op":"mcm","clk":"11883633675","pt":1724070254160,"mc":[{"id":"1.232011465","rc":[{"batb":[[0,2.08,34.24],[1,1.92,8.2],[2,1.5,41.84]],"ltp":2.1,"tv":897.99,"id":72857115}]}]}
{"op":"mcm","clk":"11883633880","pt":1724070258428,"mc":[{"id":"1.232011465","rc":[{"batb":[[0,2.1,10],[1,2.08,34.24],[2,1.92,8.2]],"ltp":2.1,"tv":897.99,"id":72857115}]}]}
{"op":"mcm","clk":"11883634040","pt":1724070261760,"mc":[{"id":"1.232011465","rc":[{"batb":[[0,2.08,34.24],[1,1.92,8.2],[2,1.5,41.84]],"ltp":2.1,"tv":897.99,"id":72857115}]}]}
{"op":"mcm","clk":"11883634186","pt":1724070265386,"mc":[{"id":"1.232011465","rc":[{"batb":[[0,2.1,10],[1,2.08,34.24],[2,1.92,8.2]],"ltp":2.1,"tv":897.99,"id":72857115}]}]}
{"op":"mcm","clk":"11883634306","pt":1724070268762,"mc":[{"id":"1.232011465","rc":[{"batb":[[0,2.08,34.24],[1,1.92,8.2],[2,1.5,41.84]],"ltp":2.1,"tv":897.99,"id":72857115}]}]}
{"op":"mcm","clk":"11883634430","pt":1724070272203,"mc":[{"id":"1.232011465","rc":[{"batb":[[0,2.1,10],[1,2.08,34.24],[2,1.92,8.2]],"ltp":2.1,"tv":897.99,"id":72857115}]}]}
{"op":"mcm","clk":"11883634556","pt":1724070275679,"mc":[{"id":"1.232011465","rc":[{"batb":[[0,2.08,34.24],[1,1.92,8.2],[2,1.5,41.84]],"ltp":2.1,"tv":897.99,"id":72857115}]}]}
{"op":"mcm","clk":"11883634758","pt":1724070281173,"mc":[{"id":"1.232011465","rc":[{"batb":[[0,2.1,10],[1,2.08,34.24],[2,1.92,8.2]],"ltp":2.1,"tv":897.99,"id":72857115}]}]}
{"op":"mcm","clk":"11883634860","pt":1724070284393,"mc":[{"id":"1.232011465","rc":[{"batb":[[0,2.08,34.24],[1,1.92,8.2],[2,1.5,41.84]],"ltp":2.1,"tv":897.99,"id":72857115}]}]}
{"op":"mcm","clk":"11883634995","pt":1724070287786,"mc":[{"id":"1.232011465","rc":[{"batb":[[0,2.1,10],[1,2.08,34.24],[2,1.92,8.2]],"ltp":2.1,"tv":897.99,"id":72857115}]}]}
{"op":"mcm","clk":"11883635081","pt":1724070290195,"mc":[{"id":"1.232011465","rc":[{"batb":[[1,1.52,7.75],[2,1.5,41.84]],"ltp":1.91,"tv":902.74,"id":67083366}]}]}
{"op":"mcm","clk":"11883635109","pt":1724070291114,"mc":[{"id":"1.232011465","rc":[{"batb":[[0,2.08,34.24],[1,1.92,8.2],[2,1.5,41.84]],"ltp":2.1,"tv":897.99,"id":72857115}]}]}
{"op":"mcm","clk":"11883635185","pt":1724070293580,"mc":[{"id":"1.232011465","rc":[{"batb":[[0,2.1,10],[1,2.08,34.24],[2,1.92,8.2]],"ltp":2.1,"tv":897.99,"id":72857115}]}]}
{"op":"mcm","clk":"11883635336","pt":1724070296911,"mc":[{"id":"1.232011465","rc":[{"batb":[[0,2.08,34.24],[1,1.92,8.2],[2,1.5,41.84]],"ltp":2.1,"tv":897.99,"id":72857115}]}]}
{"op":"mcm","clk":"11883635441","pt":1724070299628,"mc":[{"id":"1.232011465","rc":[{"batb":[[0,2.1,10],[1,2.08,34.24],[2,1.92,8.2]],"ltp":2.1,"tv":897.99,"id":72857115}]}]}
{"op":"mcm","clk":"11883635604","pt":1724070302892,"mc":[{"id":"1.232011465","rc":[{"batb":[[0,2.08,34.24],[1,1.92,8.2],[2,1.5,41.84]],"ltp":2.1,"tv":897.99,"id":72857115}]}]}
{"op":"mcm","clk":"11883635719","pt":1724070305101,"mc":[{"id":"1.232011465","rc":[{"batb":[[0,2.12,10],[1,2.08,34.24],[2,1.92,8.2]],"ltp":2.1,"tv":897.99,"id":72857115}]}]}
{"op":"mcm","clk":"11883635926","pt":1724070309621,"mc":[{"id":"1.232011465","rc":[{"batb":[[0,2.08,34.24],[1,1.92,8.2],[2,1.5,41.84]],"ltp":2.1,"tv":897.99,"id":72857115}]}]}
{"op":"mcm","clk":"11883635984","pt":1724070310904,"mc":[{"id":"1.232011465","rc":[{"batb":[[1,1.5,41.84],[2,1.03,200]],"ltp":2.1,"tv":897.99,"id":72857115}]}]}
{"op":"mcm","clk":"11883636128","pt":1724070314427,"mc":[{"id":"1.232011465","rc":[{"batb":[[0,2.1,10],[1,2.08,34.24],[2,1.5,41.84]],"ltp":2.1,"tv":897.99,"id":72857115}]}]}
{"op":"mcm","clk":"11883636268","pt":1724070317814,"mc":[{"id":"1.232011465","rc":[{"batb":[[0,2.08,34.24],[1,1.5,41.84],[2,1.03,200]],"ltp":2.1,"tv":897.99,"id":72857115}]}]}
{"op":"mcm","clk":"11883636477","pt":1724070323055,"mc":[{"id":"1.232011465","rc":[{"batb":[[2,1.03,200]],"ltp":1.91,"tv":902.74,"id":67083366},{"batb":[[0,2.1,10],[1,2.08,34.24],[2,1.5,41.84]],"ltp":2.1,"tv":897.99,"id":72857115}]}]}
{"op":"mcm","clk":"11883636605","pt":1724070326448,"mc":[{"id":"1.232011465","rc":[{"batb":[[0,2.08,34.24],[1,1.5,41.84],[2,1.03,200]],"ltp":2.1,"tv":897.99,"id":72857115}]}]}
{"op":"mcm","clk":"11883636692","pt":1724070328814,"mc":[{"id":"1.232011465","rc":[{"batb":[[0,2.1,10],[1,2.08,34.24],[2,1.5,41.84]],"ltp":2.1,"tv":897.99,"id":72857115}]}]}
{"op":"mcm","clk":"11883636789","pt":1724070332053,"mc":[{"id":"1.232011465","rc":[{"batb":[[0,1.85,10],[1,1.84,44.02],[2,1.52,7.75]],"batl":[[0,2.48,4.65],[1,13,0.94],[2,13,0]],"ltp":1.91,"tv":902.74,"id":67083366},{"batb":[[0,2.08,34.24],[1,1.03,200],[2,1.02,200]],"ltp":2.1,"tv":897.99,"id":72857115}]}]}
{"op":"mcm","clk":"11883636920","pt":1724070335434,"mc":[{"id":"1.232011465","rc":[{"batb":[[0,1.84,44.02],[1,1.52,7.75],[2,1.03,200]],"ltp":1.91,"tv":902.74,"id":67083366},{"batb":[[0,2.1,10],[1,2.08,34.24],[2,1.03,200]],"ltp":2.1,"tv":897.99,"id":72857115}]}]}
{"op":"mcm","clk":"11883637032","pt":1724070338362,"mc":[{"id":"1.232011465","rc":[{"batb":[[0,1.85,10],[1,1.84,44.02],[2,1.52,7.75]],"ltp":1.91,"tv":902.74,"id":67083366}]}]}
{"op":"mcm","clk":"11883637038","pt":1724070338568,"mc":[{"id":"1.232011465","rc":[{"batb":[[0,2.08,34.24],[1,1.03,200],[2,1.02,200]],"ltp":2.1,"tv":897.99,"id":72857115}]}]}
{"op":"mcm","clk":"11883637187","pt":1724070341970,"mc":[{"id":"1.232011465","rc":[{"batb":[[0,1.84,44.02],[1,1.52,7.75],[2,1.03,200]],"ltp":1.91,"tv":902.74,"id":67083366},{"batb":[[0,2.1,10],[1,2.08,34.24],[2,1.03,200]],"ltp":2.1,"tv":897.99,"id":72857115}]}]}
{"op":"mcm","clk":"11883637310","pt":1724070345360,"mc":[{"id":"1.232011465","rc":[{"batb":[[0,1.85,10],[1,1.84,44.02],[2,1.52,7.75]],"ltp":1.91,"tv":902.74,"id":67083366},{"batb":[[0,2.08,34.24],[1,1.03,200],[2,1.02,200]],"ltp":2.1,"tv":897.99,"id":72857115}]}]}
{"op":"mcm","clk":"11883637425","pt":1724070348442,"mc":[{"id":"1.232011465","rc":[{"batb":[[0,2.1,10],[1,2.08,34.24],[2,1.03,200]],"ltp":2.1,"tv":897.99,"id":72857115}]}]}
{"op":"mcm","clk":"11883637434","pt":1724070348651,"mc":[{"id":"1.232011465","rc":[{"batb":[[0,1.84,44.02],[1,1.52,7.75],[2,1.03,200]],"ltp":1.91,"tv":902.74,"id":67083366}]}]}
{"op":"mcm","clk":"11883637538","pt":1724070351885,"mc":[{"id":"1.232011465","rc":[{"batb":[[0,1.85,10],[1,1.84,44.02],[2,1.52,7.75]],"ltp":1.91,"tv":902.74,"id":67083366},{"batb":[[0,2.08,34.24],[1,1.03,200],[2,1.02,200]],"ltp":2.1,"tv":897.99,"id":72857115}]}]}
{"op":"mcm","clk":"11883637690","pt":1724070355388,"mc":[{"id":"1.232011465","rc":[{"batb":[[0,1.84,44.02],[1,1.52,7.75],[2,1.03,200]],"ltp":1.91,"tv":902.74,"id":67083366},{"batb":[[0,2.1,10],[1,2.08,34.24],[2,1.03,200]],"ltp":2.1,"tv":897.99,"id":72857115}]}]}
{"op":"mcm","clk":"11883637810","pt":1724070358881,"mc":[{"id":"1.232011465","rc":[{"batb":[[0,1.85,10],[1,1.84,44.02],[2,1.52,7.75]],"ltp":1.91,"tv":902.74,"id":67083366},{"batb":[[0,2.08,34.24],[1,1.03,200],[2,1.02,200]],"ltp":2.1,"tv":897.99,"id":72857115}]}]}
{"op":"mcm","clk":"11883637962","pt":1724070362388,"mc":[{"id":"1.232011465","rc":[{"batb":[[0,1.84,44.02],[1,1.52,7.75],[2,1.03,200]],"ltp":1.91,"tv":902.74,"id":67083366},{"batb":[[0,2.1,10],[1,2.08,34.24],[2,1.03,200]],"ltp":2.1,"tv":897.99,"id":72857115}]}]}
{"op":"mcm","clk":"11883638118","pt":1724070366080,"mc":[{"id":"1.232011465","rc":[{"batb":[[0,1.85,10],[1,1.84,44.02],[2,1.52,7.75]],"ltp":1.91,"tv":902.74,"id":67083366},{"batb":[[0,2.08,34.24],[1,1.03,200],[2,1.02,200]],"ltp":2.1,"tv":897.99,"id":72857115}]}]}
{"op":"mcm","clk":"11883638204","pt":1724070368386,"mc":[{"id":"1.232011465","rc":[{"batb":[[0,2.1,10],[1,2.08,34.24],[2,1.03,200]],"ltp":2.1,"tv":897.99,"id":72857115}]}]}
{"op":"mcm","clk":"11883638256","pt":1724070369569,"mc":[{"id":"1.232011465","rc":[{"batb":[[0,1.84,44.02],[1,1.52,7.75],[2,1.03,200]],"ltp":1.91,"tv":902.74,"id":67083366}]}]}
{"op":"mcm","clk":"11883638368","pt":1724070371995,"mc":[{"id":"1.232011465","rc":[{"batb":[[0,1.85,10],[1,1.84,44.02],[2,1.52,7.75]],"ltp":1.91,"tv":902.74,"id":67083366},{"batb":[[0,2.08,34.24],[1,1.03,200],[2,1.02,200]],"ltp":2.1,"tv":897.99,"id":72857115}]}]}
{"op":"mcm","clk":"11883638507","pt":1724070375384,"mc":[{"id":"1.232011465","rc":[{"batb":[[0,1.84,44.02],[1,1.52,7.75],[2,1.03,200]],"ltp":1.91,"tv":902.74,"id":67083366},{"batb":[[0,2.1,10],[1,2.08,34.24],[2,1.03,200]],"ltp":2.1,"tv":897.99,"id":72857115}]}]}
{"op":"mcm","clk":"11883638600","pt":1724070378196,"mc":[{"id":"1.232011465","rc":[{"batb":[[0,1.85,10],[1,1.84,44.02],[2,1.52,7.75]],"ltp":1.91,"tv":902.74,"id":67083366},{"batb":[[0,2.08,34.24],[1,1.03,200],[2,1.02,200]],"ltp":2.1,"tv":897.99,"id":72857115}]}]}
{"op":"mcm","clk":"11883638704","pt":1724070381623,"mc":[{"id":"1.232011465","rc":[{"batb":[[0,1.84,44.02],[1,1.52,7.75],[2,1.03,200]],"ltp":1.91,"tv":902.74,"id":67083366},{"batb":[[0,2.1,10],[1,2.08,34.24],[2,1.03,200]],"ltp":2.1,"tv":897.99,"id":72857115}]}]}
{"op":"mcm","clk":"11883638840","pt":1724070385120,"mc":[{"id":"1.232011465","rc":[{"batb":[[0,1.85,10],[1,1.84,44.02],[2,1.52,7.75]],"ltp":1.91,"tv":902.74,"id":67083366},{"batb":[[0,2.08,34.24],[1,1.03,200],[2,1.02,200]],"ltp":2.1,"tv":897.99,"id":72857115}]}]}
{"op":"mcm","clk":"11883638960","pt":1724070388408,"mc":[{"id":"1.232011465","rc":[{"batb":[[0,1.84,44.02],[1,1.52,7.75],[2,1.03,200]],"ltp":1.91,"tv":902.74,"id":67083366}]}]}
{"op":"mcm","clk":"11883638967","pt":1724070388614,"mc":[{"id":"1.232011465","rc":[{"batb":[[0,2.1,10],[1,2.08,34.24],[2,1.03,200]],"ltp":2.1,"tv":897.99,"id":72857115}]}]}
{"op":"mcm","clk":"11883639095","pt":1724070392100,"mc":[{"id":"1.232011465","rc":[{"batb":[[0,1.85,10],[1,1.84,44.02],[2,1.52,7.75]],"ltp":1.91,"tv":902.74,"id":67083366},{"batb":[[0,2.08,34.24],[1,1.03,200],[2,1.02,200]],"ltp":2.1,"tv":897.99,"id":72857115}]}]}
{"op":"mcm","clk":"11883639242","pt":1724070395638,"mc":[{"id":"1.232011465","rc":[{"batb":[[0,1.84,44.02],[1,1.52,7.75],[2,1.03,200]],"ltp":1.91,"tv":902.74,"id":67083366},{"batb":[[0,2.1,10],[1,2.08,34.24],[2,1.03,200]],"ltp":2.1,"tv":897.99,"id":72857115}]}]}
{"op":"mcm","clk":"11883639364","pt":1724070398817,"mc":[{"id":"1.232011465","rc":[{"batb":[[0,1.85,10],[1,1.84,44.02],[2,1.52,7.75]],"ltp":1.91,"tv":902.74,"id":67083366},{"batb":[[0,2.08,34.24],[1,1.03,200],[2,1.02,200]],"ltp":2.1,"tv":897.99,"id":72857115}]}]}
{"op":"mcm","clk":"11883639491","pt":1724070402043,"mc":[{"id":"1.232011465","rc":[{"batb":[[0,1.84,44.02],[1,1.52,7.75],[2,1.03,200]],"ltp":1.91,"tv":902.74,"id":67083366},{"batb":[[0,2.1,10],[1,2.08,34.24],[2,1.03,200]],"ltp":2.1,"tv":897.99,"id":72857115}]}]}
{"op":"mcm","clk":"11883639630","pt":1724070405434,"mc":[{"id":"1.232011465","rc":[{"batb":[[0,1.85,10],[1,1.84,44.02],[2,1.52,7.75]],"ltp":1.91,"tv":902.74,"id":67083366},{"batb":[[0,2.08,34.24],[1,1.03,200],[2,1.02,200]],"ltp":2.1,"tv":897.99,"id":72857115}]}]}
{"op":"mcm","clk":"11883639747","pt":1724070408350,"mc":[{"id":"1.232011465","rc":[{"batb":[[0,2.1,10],[1,2.08,34.24],[2,1.03,200]],"ltp":2.1,"tv":897.99,"id":72857115}]}]}
{"op":"mcm","clk":"11883639761","pt":1724070408660,"mc":[{"id":"1.232011465","rc":[{"batb":[[0,1.84,44.02],[1,1.52,7.75],[2,1.03,200]],"ltp":1.91,"tv":902.74,"id":67083366}]}]}
{"op":"mcm","clk":"11883639930","pt":1724070411839,"mc":[{"id":"1.232011465","rc":[{"batb":[[0,1.85,10],[1,1.84,44.02],[2,1.52,7.75]],"ltp":1.91,"tv":902.74,"id":67083366},{"batb":[[0,2.08,34.24],[1,1.03,200],[2,1.02,200]],"ltp":2.1,"tv":897.99,"id":72857115}]}]}
{"op":"mcm","clk":"11883640101","pt":1724070415226,"mc":[{"id":"1.232011465","rc":[{"batb":[[0,1.84,44.02],[1,1.52,7.75],[2,1.03,200]],"ltp":1.91,"tv":902.74,"id":67083366},{"batb":[[0,2.1,10],[1,2.08,34.24],[2,1.03,200]],"ltp":2.1,"tv":897.99,"id":72857115}]}]}
{"op":"mcm","clk":"11883640269","pt":1724070418455,"mc":[{"id":"1.232011465","rc":[{"batb":[[0,1.85,10],[1,1.84,44.02],[2,1.52,7.75]],"ltp":1.91,"tv":902.74,"id":67083366},{"batb":[[0,2.08,34.24],[1,1.03,200],[2,1.02,200]],"ltp":2.1,"tv":897.99,"id":72857115}]}]}
{"op":"mcm","clk":"11883640420","pt":1724070421540,"mc":[{"id":"1.232011465","rc":[{"batb":[[0,1.84,44.02],[1,1.52,7.75],[2,1.03,200]],"ltp":1.91,"tv":902.74,"id":67083366},{"batb":[[0,2.1,10],[1,2.08,34.24],[2,1.03,200]],"ltp":2.1,"tv":897.99,"id":72857115}]}]}
{"op":"mcm","clk":"11883640535","pt":1724070424049,"mc":[{"id":"1.232011465","rc":[{"batb":[[0,1.85,10],[1,1.84,44.02],[2,1.52,7.75]],"ltp":1.91,"tv":902.74,"id":67083366}]}]}
{"op":"mcm","clk":"11883640572","pt":1724070424765,"mc":[{"id":"1.232011465","rc":[{"batb":[[0,2.08,34.24],[1,1.03,200],[2,1.02,200]],"ltp":2.1,"tv":897.99,"id":72857115}]}]}
{"op":"mcm","clk":"11883640729","pt":1724070427744,"mc":[{"id":"1.232011465","rc":[{"batb":[[0,1.84,44.02],[1,1.52,7.75],[2,1.03,200]],"ltp":1.91,"tv":902.74,"id":67083366},{"batb":[[0,2.1,10],[1,2.08,34.24],[2,1.03,200]],"ltp":2.1,"tv":897.99,"id":72857115}]}]}
{"op":"mcm","clk":"11883640881","pt":1724070431072,"mc":[{"id":"1.232011465","rc":[{"batb":[[0,1.85,10],[1,1.84,44.02],[2,1.52,7.75]],"ltp":1.91,"tv":902.74,"id":67083366},{"batb":[[0,2.08,34.24],[1,1.03,200],[2,1.02,200]],"ltp":2.1,"tv":897.99,"id":72857115}]}]}
{"op":"mcm","clk":"11883641053","pt":1724070434461,"mc":[{"id":"1.232011465","rc":[{"batb":[[0,1.84,44.02],[1,1.52,7.75],[2,1.03,200]],"ltp":1.91,"tv":902.74,"id":67083366},{"batb":[[0,2.1,10],[1,2.08,34.24],[2,1.03,200]],"ltp":2.1,"tv":897.99,"id":72857115}]}]}
{"op":"mcm","clk":"11883641205","pt":1724070437179,"mc":[{"id":"1.232011465","rc":[{"batb":[[0,1.85,10],[1,1.84,44.02],[2,1.52,7.75]],"ltp":1.91,"tv":902.74,"id":67083366},{"batb":[[0,2.08,34.24],[1,1.03,200],[2,1.02,200]],"ltp":2.1,"tv":897.99,"id":72857115}]}]}
{"op":"mcm","clk":"11883641389","pt":1724070440758,"mc":[{"id":"1.232011465","rc":[{"batb":[[0,1.84,44.02],[1,1.52,7.75],[2,1.03,200]],"ltp":1.91,"tv":902.74,"id":67083366},{"batb":[[0,2.1,10],[1,2.08,34.24],[2,1.03,200]],"ltp":2.1,"tv":897.99,"id":72857115}]}]}
{"op":"mcm","clk":"11883641548","pt":1724070444188,"mc":[{"id":"1.232011465","rc":[{"batb":[[0,1.85,10],[1,1.84,44.02],[2,1.52,7.75]],"ltp":1.91,"tv":902.74,"id":67083366},{"batb":[[0,2.08,34.24],[1,1.03,200],[2,1.02,200]],"ltp":2.1,"tv":897.99,"id":72857115}]}]}
{"op":"mcm","clk":"11883641688","pt":1724070447367,"mc":[{"id":"1.232011465","rc":[{"batb":[[0,1.84,44.02],[1,1.52,7.75],[2,1.03,200]],"ltp":1.91,"tv":902.74,"id":67083366},{"batb":[[0,2.1,10],[1,2.08,34.24],[2,1.03,200]],"ltp":2.1,"tv":897.99,"id":72857115}]}]}
{"op":"mcm","clk":"11883641841","pt":1724070450598,"mc":[{"id":"1.232011465","rc":[{"batb":[[0,1.85,10],[1,1.84,44.02],[2,1.52,7.75]],"ltp":1.91,"tv":902.74,"id":67083366},{"batb":[[0,2.08,34.24],[1,1.03,200],[2,1.02,200]],"ltp":2.1,"tv":897.99,"id":72857115}]}]}
{"op":"mcm","clk":"11883641896","pt":1724070451670,"mc":[{"id":"1.232011465","rc":[{"batl":[[0,1.86,1.11],[1,2.48,4.65],[2,13,0.94]],"ltp":1.91,"tv":902.74,"id":67083366}]}]}
{"op":"mcm","clk":"11883641948","pt":1724070452895,"mc":[{"id":"1.232011465","rc":[{"batb":[[0,2.1,10],[1,2.08,34.24],[2,1.03,200]],"ltp":2.1,"tv":897.99,"id":72857115}]}]}
{"op":"mcm","clk":"11883642002","pt":1724070453870,"mc":[{"id":"1.232011465","rc":[{"batb":[[0,1.84,44.02],[1,1.52,7.75],[2,1.03,200]],"ltp":1.91,"tv":902.74,"id":67083366}]}]}
{"op":"mcm","clk":"11883642081","pt":1724070455966,"mc":[{"id":"1.232011465","rc":[{"batb":[[0,2.08,34.24],[1,1.03,200],[2,1.02,200]],"ltp":2.1,"tv":897.99,"id":72857115}]}]}
{"op":"mcm","clk":"11883642162","pt":1724070458161,"mc":[{"id":"1.232011465","rc":[{"batb":[[0,2.1,10],[1,2.08,34.24],[2,1.03,200]],"ltp":2.1,"tv":897.99,"id":72857115}]}]}
{"op":"mcm","clk":"11883642310","pt":1724070461595,"mc":[{"id":"1.232011465","rc":[{"batb":[[0,2.08,34.24],[1,1.03,200],[2,1.02,200]],"ltp":2.1,"tv":897.99,"id":72857115}]}]}
{"op":"mcm","clk":"11883642468","pt":1724070465285,"mc":[{"id":"1.232011465","rc":[{"batb":[[0,2.1,10],[1,2.08,34.24],[2,1.03,200]],"ltp":2.1,"tv":897.99,"id":72857115}]}]}
{"op":"mcm","clk":"11883642593","pt":1724070468674,"mc":[{"id":"1.232011465","rc":[{"batb":[[0,2.08,34.24],[1,1.03,200],[2,1.02,200]],"ltp":2.1,"tv":897.99,"id":72857115}]}]}
{"op":"mcm","clk":"11883642792","pt":1724070472921,"mc":[{"id":"1.232011465","rc":[{"batb":[[0,2.1,10],[1,2.08,34.24],[2,1.03,200]],"ltp":2.1,"tv":897.99,"id":72857115}]}]}
{"op":"mcm","clk":"11883642944","pt":1724070476412,"mc":[{"id":"1.232011465","rc":[{"batb":[[0,2.08,34.24],[1,1.03,200],[2,1.02,200]],"ltp":2.1,"tv":897.99,"id":72857115}]}]}
{"op":"mcm","clk":"11883643117","pt":1724070480210,"mc":[{"id":"1.232011465","rc":[{"batb":[[0,2.1,10],[1,2.08,34.24],[2,1.03,200]],"ltp":2.1,"tv":897.99,"id":72857115}]}]}
{"op":"mcm","clk":"11883643271","pt":1724070483709,"mc":[{"id":"1.232011465","rc":[{"batb":[[0,2.08,34.24],[1,1.03,200],[2,1.02,200]],"ltp":2.1,"tv":897.99,"id":72857115}]}]}
{"op":"mcm","clk":"11883643394","pt":1724070486221,"mc":[{"id":"1.232011465","rc":[{"batb":[[0,2.1,10],[1,2.08,34.24],[2,1.03,200]],"ltp":2.1,"tv":897.99,"id":72857115}]}]}
{"op":"mcm","clk":"11883643538","pt":1724070489512,"mc":[{"id":"1.232011465","rc":[{"batb":[[0,2.08,34.24],[1,1.03,200],[2,1.02,200]],"ltp":2.1,"tv":897.99,"id":72857115}]}]}
{"op":"mcm","clk":"11883643749","pt":1724070494338,"mc":[{"id":"1.232011465","rc":[{"batb":[[0,2.1,10],[1,2.08,34.24],[2,1.03,200]],"ltp":2.1,"tv":897.99,"id":72857115}]}]}
{"op":"mcm","clk":"11883643908","pt":1724070497940,"mc":[{"id":"1.232011465","rc":[{"batb":[[0,2.08,34.24],[1,1.03,200],[2,1.02,200]],"ltp":2.1,"tv":897.99,"id":72857115}]}]}
{"op":"mcm","clk":"11883644081","pt":1724070501948,"mc":[{"id":"1.232011465","rc":[{"batb":[[0,2.1,10],[1,2.08,34.24],[2,1.03,200]],"ltp":2.1,"tv":897.99,"id":72857115}]}]}
{"op":"mcm","clk":"11883644258","pt":1724070505443,"mc":[{"id":"1.232011465","rc":[{"batb":[[0,2.08,34.24],[1,1.03,200],[2,1.02,200]],"ltp":2.1,"tv":897.99,"id":72857115}]}]}
{"op":"mcm","clk":"11883644397","pt":1724070508425,"mc":[{"id":"1.232011465","rc":[{"batb":[[0,2.1,10],[1,2.08,34.24],[2,1.03,200]],"ltp":2.1,"tv":897.99,"id":72857115}]}]}
{"op":"mcm","clk":"11883644584","pt":1724070512069,"mc":[{"id":"1.232011465","rc":[{"batb":[[0,2.08,34.24],[1,1.03,200],[2,1.02,200]],"ltp":2.1,"tv":897.99,"id":72857115}]}]}
{"op":"mcm","clk":"11883644711","pt":1724070514374,"mc":[{"id":"1.232011465","rc":[{"batb":[[0,2.1,10],[1,2.08,34.24],[2,1.03,200]],"ltp":2.1,"tv":897.99,"id":72857115}]}]}
{"op":"mcm","clk":"11883644898","pt":1724070517656,"mc":[{"id":"1.232011465","rc":[{"batb":[[0,2.08,34.24],[1,1.03,200],[2,1.02,200]],"ltp":2.1,"tv":897.99,"id":72857115}]}]}
{"op":"mcm","clk":"11883645040","pt":1724070520374,"mc":[{"id":"1.232011465","rc":[{"batb":[[0,2.1,10],[1,2.08,34.24],[2,1.03,200]],"ltp":2.1,"tv":897.99,"id":72857115}]}]}
{"op":"mcm","clk":"11883645204","pt":1724070523775,"mc":[{"id":"1.232011465","rc":[{"batb":[[0,2.08,34.24],[1,1.03,200],[2,1.02,200]],"ltp":2.1,"tv":897.99,"id":72857115}]}]}
{"op":"mcm","clk":"11883645918","pt":1724070538638,"mc":[{"id":"1.232011465","rc":[{"batb":[[0,2.1,10],[1,2.08,34.24],[2,1.03,200]],"ltp":2.1,"tv":897.99,"id":72857115}]}]}
{"op":"mcm","clk":"11883646084","pt":1724070542086,"mc":[{"id":"1.232011465","rc":[{"batb":[[0,2.08,34.24],[1,1.03,200],[2,1.02,200]],"ltp":2.1,"tv":897.99,"id":72857115}]}]}
{"op":"mcm","clk":"11883646242","pt":1724070545417,"mc":[{"id":"1.232011465","rc":[{"batb":[[0,2.1,10],[1,2.08,34.24],[2,1.03,200]],"ltp":2.1,"tv":897.99,"id":72857115}]}]}
{"op":"mcm","clk":"11883646411","pt":1724070548808,"mc":[{"id":"1.232011465","rc":[{"batb":[[0,2.08,34.24],[1,1.03,200],[2,1.02,200]],"ltp":2.1,"tv":897.99,"id":72857115}]}]}
{"op":"mcm","clk":"11883646623","pt":1724070552549,"mc":[{"id":"1.232011465","rc":[{"batb":[[0,2.1,10],[1,2.08,34.24],[2,1.03,200]],"ltp":2.1,"tv":897.99,"id":72857115}]}]}
{"op":"mcm","clk":"11883646808","pt":1724070556038,"mc":[{"id":"1.232011465","rc":[{"batb":[[0,2.08,34.24],[1,1.03,200],[2,1.02,200]],"ltp":2.1,"tv":897.99,"id":72857115}]}]}
{"op":"mcm","clk":"11883646924","pt":1724070558454,"mc":[{"id":"1.232011465","rc":[{"batb":[[0,2.1,10],[1,2.08,34.24],[2,1.03,200]],"ltp":2.1,"tv":897.99,"id":72857115}]}]}
{"op":"mcm","clk":"11883647068","pt":1724070561836,"mc":[{"id":"1.232011465","rc":[{"batb":[[0,2.08,34.24],[1,1.03,200],[2,1.02,200]],"ltp":2.1,"tv":897.99,"id":72857115}]}]}
{"op":"mcm","clk":"11883647461","pt":1724070569980,"mc":[{"id":"1.232011465","rc":[{"batb":[[0,2.1,10],[1,2.08,34.24],[2,1.03,200]],"ltp":2.1,"tv":897.99,"id":72857115}]}]}
{"op":"mcm","clk":"11883647630","pt":1724070573462,"mc":[{"id":"1.232011465","rc":[{"batb":[[0,2.08,34.24],[1,1.03,200],[2,1.02,200]],"ltp":2.1,"tv":897.99,"id":72857115}]}]}
{"op":"mcm","clk":"11883648008","pt":1724070581464,"mc":[{"id":"1.232011465","rc":[{"batb":[[0,2.1,10],[1,2.08,34.24],[2,1.03,200]],"ltp":2.1,"tv":897.99,"id":72857115}]}]}
{"op":"mcm","clk":"11883648191","pt":1724070584905,"mc":[{"id":"1.232011465","rc":[{"batb":[[0,2.08,34.24],[1,1.03,200],[2,1.02,200]],"ltp":2.1,"tv":897.99,"id":72857115}]}]}
{"op":"mcm","clk":"11883648516","pt":1724070591112,"mc":[{"id":"1.232011465","rc":[{"batb":[[0,2.1,10],[1,2.08,34.24],[2,1.03,200]],"ltp":2.1,"tv":897.99,"id":72857115}]}]}
{"op":"mcm","clk":"11883648681","pt":1724070594496,"mc":[{"id":"1.232011465","rc":[{"batb":[[0,2.08,34.24],[1,1.03,200],[2,1.02,200]],"ltp":2.1,"tv":897.99,"id":72857115}]}]}
{"op":"mcm","clk":"11883648952","pt":1724070600099,"mc":[{"id":"1.232011465","rc":[{"batb":[[0,2.1,10],[1,2.08,34.24],[2,1.03,200]],"ltp":2.1,"tv":897.99,"id":72857115}]}]}
{"op":"mcm","clk":"11883649151","pt":1724070603511,"mc":[{"id":"1.232011465","rc":[{"batb":[[0,2.08,34.24],[1,1.03,200],[2,1.02,200]],"ltp":2.1,"tv":897.99,"id":72857115}]}]}
{"op":"mcm","clk":"11883649306","pt":1724070606196,"mc":[{"id":"1.232011465","rc":[{"batb":[[0,2.1,10],[1,2.08,34.24],[2,1.03,200]],"ltp":2.1,"tv":897.99,"id":72857115}]}]}
{"op":"mcm","clk":"11883649471","pt":1724070609627,"mc":[{"id":"1.232011465","rc":[{"batb":[[0,2.08,34.24],[1,1.03,200],[2,1.02,200]],"ltp":2.1,"tv":897.99,"id":72857115}]}]}
{"op":"mcm","clk":"11883649711","pt":1724070614929,"mc":[{"id":"1.232011465","rc":[{"batb":[[0,2.1,10],[1,2.08,34.24],[2,1.03,200]],"ltp":2.1,"tv":897.99,"id":72857115}]}]}
{"op":"mcm","clk":"11883649864","pt":1724070618121,"mc":[{"id":"1.232011465","rc":[{"batb":[[0,2.08,34.24],[1,1.03,200],[2,1.02,200]],"ltp":2.1,"tv":897.99,"id":72857115}]}]}
{"op":"mcm","clk":"11883650102","pt":1724070622548,"mc":[{"id":"1.232011465","rc":[{"batb":[[0,2.1,10],[1,2.08,34.24],[2,1.03,200]],"ltp":2.1,"tv":897.99,"id":72857115}]}]}
{"op":"mcm","clk":"11883650261","pt":1724070625928,"mc":[{"id":"1.232011465","rc":[{"batb":[[0,2.08,34.24],[1,1.03,200],[2,1.02,200]],"ltp":2.1,"tv":897.99,"id":72857115}]}]}
{"op":"mcm","clk":"11883650388","pt":1724070628645,"mc":[{"id":"1.232011465","rc":[{"batb":[[0,2.1,10],[1,2.08,34.24],[2,1.03,200]],"ltp":2.1,"tv":897.99,"id":72857115}]}]}
{"op":"mcm","clk":"11883650563","pt":1724070631835,"mc":[{"id":"1.232011465","rc":[{"batb":[[0,2.08,34.24],[1,1.03,200],[2,1.02,200]],"ltp":2.1,"tv":897.99,"id":72857115}]}]}
{"op":"mcm","clk":"11883650753","pt":1724070635272,"mc":[{"id":"1.232011465","rc":[{"batb":[[0,2.1,10],[1,2.08,34.24],[2,1.03,200]],"ltp":2.1,"tv":897.99,"id":72857115}]}]}
{"op":"mcm","clk":"11883650928","pt":1724070638671,"mc":[{"id":"1.232011465","rc":[{"batb":[[0,2.08,34.24],[1,1.03,200],[2,1.02,200]],"ltp":2.1,"tv":897.99,"id":72857115}]}]}
{"op":"mcm","clk":"11883651086","pt":1724070641355,"mc":[{"id":"1.232011465","rc":[{"batb":[[0,2.1,10],[1,2.08,34.24],[2,1.03,200]],"ltp":2.1,"tv":897.99,"id":72857115}]}]}
{"op":"mcm","clk":"11883651260","pt":1724070644691,"mc":[{"id":"1.232011465","rc":[{"batb":[[0,2.08,34.24],[1,1.03,200],[2,1.02,200]],"ltp":2.1,"tv":897.99,"id":72857115}]}]}
{"op":"mcm","clk":"11883651390","pt":1724070647572,"mc":[{"id":"1.232011465","rc":[{"batb":[[0,2.1,10],[1,2.08,34.24],[2,1.03,200]],"ltp":2.1,"tv":897.99,"id":72857115}]}]}
{"op":"mcm","clk":"11883651531","pt":1724070650862,"mc":[{"id":"1.232011465","rc":[{"batb":[[0,2.08,34.24],[1,1.03,200],[2,1.02,200]],"ltp":2.1,"tv":897.99,"id":72857115}]}]}
{"op":"mcm","clk":"11883651708","pt":1724070654892,"mc":[{"id":"1.232011465","rc":[{"batb":[[0,2.1,10],[1,2.08,34.24],[2,1.03,200]],"ltp":2.1,"tv":897.99,"id":72857115}]}]}
{"op":"mcm","clk":"11883651855","pt":1724070658177,"mc":[{"id":"1.232011465","rc":[{"batb":[[0,2.08,34.24],[1,1.03,200],[2,1.02,200]],"ltp":2.1,"tv":897.99,"id":72857115}]}]}
{"op":"mcm","clk":"11883652019","pt":1724070661921,"mc":[{"id":"1.232011465","rc":[{"batb":[[0,2.1,10],[1,2.08,34.24],[2,1.03,200]],"ltp":2.1,"tv":897.99,"id":72857115}]}]}
{"op":"mcm","clk":"11883652150","pt":1724070665100,"mc":[{"id":"1.232011465","rc":[{"batb":[[0,2.08,34.24],[1,1.03,200],[2,1.02,200]],"ltp":2.1,"tv":897.99,"id":72857115}]}]}
{"op":"mcm","clk":"11883652367","pt":1724070670181,"mc":[{"id":"1.232011465","rc":[{"batb":[[0,2.1,10],[1,2.08,34.24],[2,1.03,200]],"ltp":2.1,"tv":897.99,"id":72857115}]}]}
{"op":"mcm","clk":"11883652521","pt":1724070673512,"mc":[{"id":"1.232011465","rc":[{"batb":[[0,2.08,34.24],[1,1.03,200],[2,1.02,200]],"ltp":2.1,"tv":897.99,"id":72857115}]}]}
{"op":"mcm","clk":"11883653064","pt":1724070685730,"mc":[{"id":"1.232011465","rc":[{"batb":[[0,2.1,10],[1,2.08,34.24],[2,1.03,200]],"ltp":2.1,"tv":897.99,"id":72857115}]}]}
{"op":"mcm","clk":"11883653212","pt":1724070689115,"mc":[{"id":"1.232011465","rc":[{"batb":[[0,2.08,34.24],[1,1.03,200],[2,1.02,200]],"ltp":2.1,"tv":897.99,"id":72857115}]}]}
{"op":"mcm","clk":"11883653670","pt":1724070698378,"mc":[{"id":"1.232011465","rc":[{"batb":[[0,2.1,10],[1,2.08,34.24],[2,1.03,200]],"ltp":2.1,"tv":897.99,"id":72857115}]}]}
{"op":"mcm","clk":"11883653838","pt":1724070701832,"mc":[{"id":"1.232011465","rc":[{"batb":[[0,2.08,34.24],[1,1.03,200],[2,1.02,200]],"ltp":2.1,"tv":897.99,"id":72857115}]}]}
{"op":"mcm","clk":"11883653937","pt":1724070704035,"mc":[{"id":"1.232011465","rc":[{"batb":[[0,2.1,10],[1,2.08,34.24],[2,1.03,200]],"ltp":2.1,"tv":897.99,"id":72857115}]}]}
{"op":"mcm","clk":"11883654065","pt":1724070707467,"mc":[{"id":"1.232011465","rc":[{"batb":[[0,2.08,34.24],[1,1.03,200],[2,1.02,200]],"ltp":2.1,"tv":897.99,"id":72857115}]}]}
{"op":"mcm","clk":"11883654280","pt":1724070711764,"mc":[{"id":"1.232011465","rc":[{"batb":[[0,2.1,10],[1,2.08,34.24],[2,1.03,200]],"ltp":2.1,"tv":897.99,"id":72857115}]}]}
{"op":"mcm","clk":"11883654463","pt":1724070715373,"mc":[{"id":"1.232011465","rc":[{"batb":[[0,2.08,34.24],[1,1.03,200],[2,1.02,200]],"ltp":2.1,"tv":897.99,"id":72857115}]}]}
{"op":"mcm","clk":"11883654636","pt":1724070719173,"mc":[{"id":"1.232011465","rc":[{"batb":[[0,2.1,10],[1,2.08,34.24],[2,1.03,200]],"ltp":2.1,"tv":897.99,"id":72857115}]}]}
{"op":"mcm","clk":"11883654795","pt":1724070722578,"mc":[{"id":"1.232011465","rc":[{"batb":[[0,2.08,34.24],[1,1.03,200],[2,1.02,200]],"ltp":2.1,"tv":897.99,"id":72857115}]}]}
{"op":"mcm","clk":"11883654963","pt":1724070726268,"mc":[{"id":"1.232011465","rc":[{"batb":[[0,2.1,10],[1,2.08,34.24],[2,1.03,200]],"ltp":2.1,"tv":897.99,"id":72857115}]}]}
{"op":"mcm","clk":"11883655127","pt":1724070729509,"mc":[{"id":"1.232011465","rc":[{"batb":[[0,2.08,34.24],[1,1.03,200],[2,1.02,200]],"ltp":2.1,"tv":897.99,"id":72857115}]}]}
{"op":"mcm","clk":"11883655339","pt":1724070734388,"mc":[{"id":"1.232011465","rc":[{"batb":[[0,2.1,10],[1,2.08,34.24],[2,1.03,200]],"ltp":2.1,"tv":897.99,"id":72857115}]}]}
{"op":"mcm","clk":"11883655489","pt":1724070737514,"mc":[{"id":"1.232011465","rc":[{"batb":[[0,2.08,34.24],[1,1.03,200],[2,1.02,200]],"ltp":2.1,"tv":897.99,"id":72857115}]}]}
{"op":"mcm","clk":"11883655658","pt":1724070740897,"mc":[{"id":"1.232011465","rc":[{"batb":[[0,2.1,10],[1,2.08,34.24],[2,1.03,200]],"ltp":2.1,"tv":897.99,"id":72857115}]}]}
{"op":"mcm","clk":"11883655789","pt":1724070744186,"mc":[{"id":"1.232011465","rc":[{"batb":[[0,2.08,34.24],[1,1.03,200],[2,1.02,200]],"ltp":2.1,"tv":897.99,"id":72857115}]}]}
{"op":"mcm","clk":"11883655894","pt":1724070747319,"mc":[{"id":"1.232011465","rc":[{"batb":[[0,2.1,10],[1,2.08,34.24],[2,1.03,200]],"ltp":2.1,"tv":897.99,"id":72857115}]}]}
{"op":"mcm","clk":"11883656040","pt":1724070750711,"mc":[{"id":"1.232011465","rc":[{"batb":[[0,2.08,34.24],[1,1.03,200],[2,1.02,200]],"ltp":2.1,"tv":897.99,"id":72857115}]}]}
{"op":"mcm","clk":"11883656157","pt":1724070753286,"mc":[{"id":"1.232011465","rc":[{"batb":[[0,2.1,10],[1,2.08,34.24],[2,1.03,200]],"ltp":2.1,"tv":897.99,"id":72857115}]}]}
{"op":"mcm","clk":"11883656314","pt":1724070756683,"mc":[{"id":"1.232011465","rc":[{"batb":[[0,2.08,34.24],[1,1.03,200],[2,1.02,200]],"ltp":2.1,"tv":897.99,"id":72857115}]}]}
{"op":"mcm","clk":"11883656597","pt":1724070763221,"mc":[{"id":"1.232011465","rc":[{"batb":[[0,2.1,10],[1,2.08,34.24],[2,1.03,200]],"ltp":2.1,"tv":897.99,"id":72857115}]}]}
{"op":"mcm","clk":"11883656756","pt":1724070766722,"mc":[{"id":"1.232011465","rc":[{"batb":[[0,2.08,34.24],[1,1.03,200],[2,1.02,200]],"ltp":2.1,"tv":897.99,"id":72857115}]}]}
{"op":"mcm","clk":"11883656874","pt":1724070769507,"mc":[{"id":"1.232011465","rc":[{"batb":[[0,2.1,10],[1,2.08,34.24],[2,1.03,200]],"ltp":2.1,"tv":897.99,"id":72857115}]}]}
{"op":"mcm","clk":"11883657011","pt":1724070772913,"mc":[{"id":"1.232011465","rc":[{"batb":[[0,2.08,34.24],[1,1.03,200],[2,1.02,200]],"ltp":2.1,"tv":897.99,"id":72857115}]}]}
{"op":"mcm","clk":"11883657111","pt":1724070775433,"mc":[{"id":"1.232011465","rc":[{"batb":[[0,2.1,10],[1,2.08,34.24],[2,1.03,200]],"ltp":2.1,"tv":897.99,"id":72857115}]}]}
{"op":"mcm","clk":"11883657260","pt":1724070778855,"mc":[{"id":"1.232011465","rc":[{"batb":[[0,2.08,34.24],[1,1.03,200],[2,1.02,200]],"ltp":2.1,"tv":897.99,"id":72857115}]}]}
{"op":"mcm","clk":"11883657446","pt":1724070782721,"mc":[{"id":"1.232011465","rc":[{"batb":[[0,2.1,10],[1,2.08,34.24],[2,1.03,200]],"ltp":2.1,"tv":897.99,"id":72857115}]}]}
{"op":"mcm","clk":"11883657604","pt":1724070786128,"mc":[{"id":"1.232011465","rc":[{"batb":[[0,2.08,34.24],[1,1.03,200],[2,1.02,200]],"ltp":2.1,"tv":897.99,"id":72857115}]}]}
{"op":"mcm","clk":"11883657742","pt":1724070789472,"mc":[{"id":"1.232011465","rc":[{"batb":[[0,2.1,10],[1,2.08,34.24],[2,1.03,200]],"ltp":2.1,"tv":897.99,"id":72857115}]}]}
{"op":"mcm","clk":"11883657889","pt":1724070792961,"mc":[{"id":"1.232011465","rc":[{"batb":[[0,2.08,34.24],[1,1.03,200],[2,1.02,200]],"ltp":2.1,"tv":897.99,"id":72857115}]}]}
{"op":"mcm","clk":"11883658004","pt":1724070795270,"mc":[{"id":"1.232011465","rc":[{"batb":[[0,2.1,10],[1,2.08,34.24],[2,1.03,200]],"ltp":2.1,"tv":897.99,"id":72857115}]}]}
{"op":"mcm","clk":"11883658140","pt":1724070798662,"mc":[{"id":"1.232011465","rc":[{"batb":[[0,2.08,34.24],[1,1.03,200],[2,1.02,200]],"ltp":2.1,"tv":897.99,"id":72857115}]}]}
{"op":"mcm","clk":"11883658304","pt":1724070802565,"mc":[{"id":"1.232011465","rc":[{"batb":[[0,2.1,10],[1,2.08,34.24],[2,1.03,200]],"ltp":2.1,"tv":897.99,"id":72857115}]}]}
{"op":"mcm","clk":"11883658434","pt":1724070805943,"mc":[{"id":"1.232011465","rc":[{"batb":[[0,2.08,34.24],[1,1.03,200],[2,1.02,200]],"ltp":2.1,"tv":897.99,"id":72857115}]}]}
{"op":"mcm","clk":"11883658586","pt":1724070809485,"mc":[{"id":"1.232011465","rc":[{"batb":[[0,2.1,10],[1,2.08,34.24],[2,1.03,200]],"ltp":2.1,"tv":897.99,"id":72857115}]}]}
{"op":"mcm","clk":"11883658726","pt":1724070812972,"mc":[{"id":"1.232011465","rc":[{"batb":[[0,2.08,34.24],[1,1.03,200],[2,1.02,200]],"ltp":2.1,"tv":897.99,"id":72857115}]}]}
{"op":"mcm","clk":"11883658907","pt":1724070817277,"mc":[{"id":"1.232011465","rc":[{"batb":[[0,2.1,10],[1,2.08,34.24],[2,1.03,200]],"ltp":2.1,"tv":897.99,"id":72857115}]}]}
{"op":"mcm","clk":"11883659050","pt":1724070820557,"mc":[{"id":"1.232011465","rc":[{"batb":[[0,2.08,34.24],[1,1.03,200],[2,1.02,200]],"ltp":2.1,"tv":897.99,"id":72857115}]}]}
{"op":"mcm","clk":"11883659254","pt":1724070825474,"mc":[{"id":"1.232011465","rc":[{"batb":[[0,2.1,10],[1,2.08,34.24],[2,1.03,200]],"ltp":2.1,"tv":897.99,"id":72857115}]}]}
{"op":"mcm","clk":"11883659369","pt":1724070828914,"mc":[{"id":"1.232011465","rc":[{"batb":[[0,2.08,34.24],[1,1.03,200],[2,1.02,200]],"ltp":2.1,"tv":897.99,"id":72857115}]}]}
{"op":"mcm","clk":"11883659536","pt":1724070832977,"mc":[{"id":"1.232011465","rc":[{"batb":[[0,2.1,10],[1,2.08,34.24],[2,1.03,200]],"ltp":2.1,"tv":897.99,"id":72857115}]}]}
{"op":"mcm","clk":"11883659670","pt":1724070836434,"mc":[{"id":"1.232011465","rc":[{"batb":[[0,2.08,34.24],[1,1.03,200],[2,1.02,200]],"ltp":2.1,"tv":897.99,"id":72857115}]}]}
{"op":"mcm","clk":"11883659856","pt":1724070841226,"mc":[{"id":"1.232011465","rc":[{"batb":[[0,2.1,10],[1,2.08,34.24],[2,1.03,200]],"ltp":2.1,"tv":897.99,"id":72857115}]}]}
{"op":"mcm","clk":"11883659977","pt":1724070844700,"mc":[{"id":"1.232011465","rc":[{"batb":[[0,2.08,34.24],[1,1.03,200],[2,1.02,200]],"ltp":2.1,"tv":897.99,"id":72857115}]}]}
{"op":"mcm","clk":"11883660300","pt":1724070852243,"mc":[{"id":"1.232011465","rc":[{"batb":[[0,2.1,10],[1,2.08,34.24],[2,1.03,200]],"ltp":2.1,"tv":897.99,"id":72857115}]}]}
{"op":"mcm","clk":"11883660454","pt":1724070855735,"mc":[{"id":"1.232011465","rc":[{"batb":[[0,2.08,34.24],[1,1.03,200],[2,1.02,200]],"ltp":2.1,"tv":897.99,"id":72857115}]}]}
{"op":"mcm","clk":"11883660580","pt":1724070858147,"mc":[{"id":"1.232011465","rc":[{"batb":[[0,2.1,10],[1,2.08,34.24],[2,1.03,200]],"ltp":2.1,"tv":897.99,"id":72857115}]}]}
{"op":"mcm","clk":"11883660748","pt":1724070861326,"mc":[{"id":"1.232011465","rc":[{"batb":[[0,2.08,34.24],[1,1.03,200],[2,1.02,200]],"ltp":2.1,"tv":897.99,"id":72857115}]}]}
{"op":"mcm","clk":"11883660864","pt":1724070863947,"mc":[{"id":"1.232011465","rc":[{"batb":[[0,2.1,10],[1,2.08,34.24],[2,1.03,200]],"ltp":2.1,"tv":897.99,"id":72857115}]}]}
{"op":"mcm","clk":"11883661028","pt":1724070867236,"mc":[{"id":"1.232011465","rc":[{"batb":[[0,2.08,34.24],[1,1.03,200],[2,1.02,200]],"ltp":2.1,"tv":897.99,"id":72857115}]}]}
{"op":"mcm","clk":"11883661164","pt":1724070870153,"mc":[{"id":"1.232011465","rc":[{"batb":[[0,2.1,10],[1,2.08,34.24],[2,1.03,200]],"ltp":2.1,"tv":897.99,"id":72857115}]}]}
{"op":"mcm","clk":"11883661329","pt":1724070873542,"mc":[{"id":"1.232011465","rc":[{"batb":[[0,2.08,34.24],[1,1.03,200],[2,1.02,200]],"ltp":2.1,"tv":897.99,"id":72857115}]}]}
{"op":"mcm","clk":"11883661421","pt":1724070876250,"mc":[{"id":"1.232011465","rc":[{"batb":[[0,2.1,10],[1,2.08,34.24],[2,1.03,200]],"ltp":2.1,"tv":897.99,"id":72857115}]}]}
{"op":"mcm","clk":"11883661583","pt":1724070879537,"mc":[{"id":"1.232011465","rc":[{"batb":[[0,2.08,34.24],[1,1.03,200],[2,1.02,200]],"ltp":2.1,"tv":897.99,"id":72857115}]}]}
{"op":"mcm","clk":"11883661761","pt":1724070883738,"mc":[{"id":"1.232011465","rc":[{"batb":[[0,2.1,10],[1,2.08,34.24],[2,1.03,200]],"ltp":2.1,"tv":897.99,"id":72857115}]}]}
{"op":"mcm","clk":"11883661928","pt":1724070887197,"mc":[{"id":"1.232011465","rc":[{"batb":[[0,2.08,34.24],[1,1.03,200],[2,1.02,200]],"ltp":2.1,"tv":897.99,"id":72857115}]}]}
{"op":"mcm","clk":"11883662480","pt":1724070899080,"mc":[{"id":"1.232011465","rc":[{"batb":[[0,2.1,10],[1,2.08,34.24],[2,1.03,200]],"ltp":2.1,"tv":897.99,"id":72857115}]}]}
{"op":"mcm","clk":"11883662655","pt":1724070902579,"mc":[{"id":"1.232011465","rc":[{"batb":[[0,2.08,34.24],[1,1.03,200],[2,1.02,200]],"ltp":2.1,"tv":897.99,"id":72857115}]}]}
{"op":"mcm","clk":"11883662823","pt":1724070906285,"mc":[{"id":"1.232011465","rc":[{"batb":[[0,2.1,10],[1,2.08,34.24],[2,1.03,200]],"ltp":2.1,"tv":897.99,"id":72857115}]}]}
{"op":"mcm","clk":"11883662992","pt":1724070909685,"mc":[{"id":"1.232011465","rc":[{"batb":[[0,2.08,34.24],[1,1.03,200],[2,1.02,200]],"ltp":2.1,"tv":897.99,"id":72857115}]}]}
{"op":"mcm","clk":"11883663124","pt":1724070912558,"mc":[{"id":"1.232011465","rc":[{"batb":[[0,2.1,10],[1,2.08,34.24],[2,1.03,200]],"ltp":2.1,"tv":897.99,"id":72857115}]}]}
{"op":"mcm","clk":"11883663286","pt":1724070915952,"mc":[{"id":"1.232011465","rc":[{"batb":[[0,2.08,34.24],[1,1.03,200],[2,1.02,200]],"ltp":2.1,"tv":897.99,"id":72857115}]}]}
{"op":"mcm","clk":"11883663448","pt":1724070919497,"mc":[{"id":"1.232011465","rc":[{"batb":[[0,2.1,10],[1,2.08,34.24],[2,1.03,200]],"ltp":2.1,"tv":897.99,"id":72857115}]}]}
{"op":"mcm","clk":"11883663617","pt":1724070922780,"mc":[{"id":"1.232011465","rc":[{"batb":[[0,2.08,34.24],[1,1.03,200],[2,1.02,200]],"ltp":2.1,"tv":897.99,"id":72857115}]}]}
{"op":"mcm","clk":"11883664094","pt":1724070933610,"mc":[{"id":"1.232011465","rc":[{"batb":[[0,2.1,10],[1,2.08,34.24],[2,1.03,200]],"ltp":2.1,"tv":897.99,"id":72857115}]}]}
{"op":"mcm","clk":"11883664219","pt":1724070936793,"mc":[{"id":"1.232011465","rc":[{"batb":[[0,2.08,34.24],[1,1.03,200],[2,1.02,200]],"ltp":2.1,"tv":897.99,"id":72857115}]}]}
{"op":"mcm","clk":"11883664386","pt":1724070941098,"mc":[{"id":"1.232011465","rc":[{"batb":[[0,2.1,10],[1,2.08,34.24],[2,1.03,200]],"ltp":2.1,"tv":897.99,"id":72857115}]}]}
{"op":"mcm","clk":"11883664513","pt":1724070944426,"mc":[{"id":"1.232011465","rc":[{"batb":[[0,2.08,34.24],[1,1.03,200],[2,1.02,200]],"ltp":2.1,"tv":897.99,"id":72857115}]}]}
{"op":"mcm","clk":"11883664744","pt":1724070949199,"mc":[{"id":"1.232011465","rc":[{"batb":[[0,2.1,10],[1,2.08,34.24],[2,1.03,200]],"ltp":2.1,"tv":897.99,"id":72857115}]}]}
{"op":"mcm","clk":"11883664886","pt":1724070952530,"mc":[{"id":"1.232011465","rc":[{"batb":[[0,2.08,34.24],[1,1.03,200],[2,1.02,200]],"ltp":2.1,"tv":897.99,"id":72857115}]}]}
{"op":"mcm","clk":"11883665024","pt":1724070955409,"mc":[{"id":"1.232011465","rc":[{"batb":[[0,2.1,10],[1,2.08,34.24],[2,1.03,200]],"ltp":2.1,"tv":897.99,"id":72857115}]}]}
{"op":"mcm","clk":"11883665171","pt":1724070958740,"mc":[{"id":"1.232011465","rc":[{"batb":[[0,2.08,34.24],[1,1.03,200],[2,1.02,200]],"ltp":2.1,"tv":897.99,"id":72857115}]}]}
{"op":"mcm","clk":"11883665310","pt":1724070961834,"mc":[{"id":"1.232011465","rc":[{"batb":[[0,2.1,10],[1,2.08,34.24],[2,1.03,200]],"ltp":2.1,"tv":897.99,"id":72857115}]}]}
{"op":"mcm","clk":"11883665478","pt":1724070965341,"mc":[{"id":"1.232011465","rc":[{"batb":[[0,2.08,34.24],[1,1.03,200],[2,1.02,200]],"ltp":2.1,"tv":897.99,"id":72857115}]}]}
{"op":"mcm","clk":"11883665585","pt":1724070968011,"mc":[{"id":"1.232011465","rc":[{"batb":[[0,2.1,10],[1,2.08,34.24],[2,1.03,200]],"ltp":2.1,"tv":897.99,"id":72857115}]}]}
{"op":"mcm","clk":"11883665743","pt":1724070971451,"mc":[{"id":"1.232011465","rc":[{"batb":[[0,2.08,34.24],[1,1.03,200],[2,1.02,200]],"ltp":2.1,"tv":897.99,"id":72857115}]}]}
{"op":"mcm","clk":"11883665861","pt":1724070974734,"mc":[{"id":"1.232011465","rc":[{"batb":[[0,2.1,10],[1,2.08,34.24],[2,1.03,200]],"ltp":2.1,"tv":897.99,"id":72857115}]}]}
{"op":"mcm","clk":"11883665990","pt":1724070977916,"mc":[{"id":"1.232011465","rc":[{"batb":[[0,2.08,34.24],[1,1.03,200],[2,1.02,200]],"ltp":2.1,"tv":897.99,"id":72857115}]}]}
{"op":"mcm","clk":"11883666292","pt":1724070983966,"mc":[{"id":"1.232011465","rc":[{"batb":[[0,2.1,10],[1,2.08,34.24],[2,1.03,200]],"ltp":2.1,"tv":897.99,"id":72857115}]}]}
{"op":"mcm","clk":"11883666440","pt":1724070987460,"mc":[{"id":"1.232011465","rc":[{"batb":[[0,2.08,34.24],[1,1.03,200],[2,1.02,200]],"ltp":2.1,"tv":897.99,"id":72857115}]}]}
{"op":"mcm","clk":"11883666562","pt":1724070990453,"mc":[{"id":"1.232011465","rc":[{"batb":[[0,2.1,10],[1,2.08,34.24],[2,1.03,200]],"ltp":2.1,"tv":897.99,"id":72857115}]}]}
{"op":"mcm","clk":"11883666704","pt":1724070993746,"mc":[{"id":"1.232011465","rc":[{"batb":[[0,2.08,34.24],[1,1.03,200],[2,1.02,200]],"ltp":2.1,"tv":897.99,"id":72857115}]}]}
{"op":"mcm","clk":"11883666829","pt":1724070996476,"mc":[{"id":"1.232011465","rc":[{"batb":[[0,2.1,10],[1,2.08,34.24],[2,1.03,200]],"ltp":2.1,"tv":897.99,"id":72857115}]}]}
{"op":"mcm","clk":"11883666992","pt":1724070999877,"mc":[{"id":"1.232011465","rc":[{"batb":[[0,2.08,34.24],[1,1.03,200],[2,1.02,200]],"ltp":2.1,"tv":897.99,"id":72857115}]}]}
{"op":"mcm","clk":"11883667156","pt":1724071003888,"mc":[{"id":"1.232011465","rc":[{"batb":[[0,2.1,10],[1,2.08,34.24],[2,1.03,200]],"ltp":2.1,"tv":897.99,"id":72857115}]}]}
{"op":"mcm","clk":"11883667317","pt":1724071007181,"mc":[{"id":"1.232011465","rc":[{"batb":[[0,2.08,34.24],[1,1.03,200],[2,1.02,200]],"ltp":2.1,"tv":897.99,"id":72857115}]}]}
{"op":"mcm","clk":"11883667875","pt":1724071018373,"mc":[{"id":"1.232011465","rc":[{"batb":[[0,2.1,10],[1,2.08,34.24],[2,1.03,200]],"ltp":2.1,"tv":897.99,"id":72857115}]}]}
{"op":"mcm","clk":"11883668027","pt":1724071021766,"mc":[{"id":"1.232011465","rc":[{"batb":[[0,2.08,34.24],[1,1.03,200],[2,1.02,200]],"ltp":2.1,"tv":897.99,"id":72857115}]}]}
{"op":"mcm","clk":"11883668219","pt":1724071025362,"mc":[{"id":"1.232011465","rc":[{"batb":[[0,2.1,10],[1,2.08,34.24],[2,1.03,200]],"ltp":2.1,"tv":897.99,"id":72857115}]}]}
{"op":"mcm","clk":"11883668376","pt":1724071028901,"mc":[{"id":"1.232011465","rc":[{"batb":[[0,2.08,34.24],[1,1.03,200],[2,1.02,200]],"ltp":2.1,"tv":897.99,"id":72857115}]}]}
{"op":"mcm","clk":"11883668527","pt":1724071033002,"mc":[{"id":"1.232011465","rc":[{"batb":[[0,2.1,10],[1,2.08,34.24],[2,1.03,200]],"ltp":2.1,"tv":897.99,"id":72857115}]}]}
{"op":"mcm","clk":"11883668642","pt":1724071036596,"mc":[{"id":"1.232011465","rc":[{"batb":[[0,2.08,34.24],[1,1.03,200],[2,1.02,200]],"ltp":2.1,"tv":897.99,"id":72857115}]}]}
{"op":"mcm","clk":"11883668842","pt":1724071043009,"mc":[{"id":"1.232011465","rc":[{"batb":[[0,2.1,10],[1,2.08,34.24],[2,1.03,200]],"ltp":2.1,"tv":897.99,"id":72857115}]}]}
{"op":"mcm","clk":"11883669002","pt":1724071046305,"mc":[{"id":"1.232011465","rc":[{"batb":[[0,2.08,34.24],[1,1.03,200],[2,1.02,200]],"ltp":2.1,"tv":897.99,"id":72857115}]}]}
{"op":"mcm","clk":"11883669336","pt":1724071055331,"mc":[{"id":"1.232011465","rc":[{"batb":[[0,2.1,10],[1,2.08,34.24],[2,1.03,200]],"ltp":2.1,"tv":897.99,"id":72857115}]}]}
{"op":"mcm","clk":"11883669460","pt":1724071058713,"mc":[{"id":"1.232011465","rc":[{"batb":[[0,2.08,34.24],[1,1.03,200],[2,1.02,200]],"ltp":2.1,"tv":897.99,"id":72857115}]}]}
{"op":"mcm","clk":"11883669545","pt":1724071061527,"mc":[{"id":"1.232011465","rc":[{"batb":[[0,2.1,10],[1,2.08,34.24],[2,1.03,200]],"ltp":2.1,"tv":897.99,"id":72857115}]}]}
{"op":"mcm","clk":"11883669652","pt":1724071064705,"mc":[{"id":"1.232011465","rc":[{"batb":[[0,2.08,34.24],[1,1.03,200],[2,1.02,200]],"ltp":2.1,"tv":897.99,"id":72857115}]}]}
{"op":"mcm","clk":"11883669760","pt":1724071067731,"mc":[{"id":"1.232011465","rc":[{"batb":[[0,2.1,10],[1,2.08,34.24],[2,1.03,200]],"ltp":2.1,"tv":897.99,"id":72857115}]}]}
{"op":"mcm","clk":"11883669892","pt":1724071071206,"mc":[{"id":"1.232011465","rc":[{"batb":[[0,2.08,34.24],[1,1.03,200],[2,1.02,200]],"ltp":2.1,"tv":897.99,"id":72857115}]}]}
{"op":"mcm","clk":"11883670016","pt":1724071074953,"mc":[{"id":"1.232011465","rc":[{"batb":[[0,2.1,10],[1,2.08,34.24],[2,1.03,200]],"ltp":2.1,"tv":897.99,"id":72857115}]}]}
{"op":"mcm","clk":"11883670189","pt":1724071078230,"mc":[{"id":"1.232011465","rc":[{"batb":[[0,2.08,34.24],[1,1.03,200],[2,1.02,200]],"ltp":2.1,"tv":897.99,"id":72857115}]}]}
{"op":"mcm","clk":"11883670342","pt":1724071081453,"mc":[{"id":"1.232011465","rc":[{"batb":[[0,2.1,10],[1,2.08,34.24],[2,1.03,200]],"ltp":2.1,"tv":897.99,"id":72857115}]}]}
{"op":"mcm","clk":"11883670492","pt":1724071084841,"mc":[{"id":"1.232011465","rc":[{"batb":[[0,2.08,34.24],[1,1.03,200],[2,1.02,200]],"ltp":2.1,"tv":897.99,"id":72857115}]}]}
{"op":"mcm","clk":"11883670555","pt":1724071086931,"mc":[{"id":"1.232011465","rc":[{"batb":[[0,2.1,10],[1,2.08,34.24],[2,1.03,200]],"ltp":2.1,"tv":897.99,"id":72857115}]}]}
{"op":"mcm","clk":"11883670732","pt":1724071090466,"mc":[{"id":"1.232011465","rc":[{"batb":[[0,2.08,34.24],[1,1.03,200],[2,1.02,200]],"ltp":2.1,"tv":897.99,"id":72857115}]}]}
{"op":"mcm","clk":"11883670834","pt":1724071093071,"mc":[{"id":"1.232011465","rc":[{"batb":[[0,2.1,10],[1,2.08,34.24],[2,1.03,200]],"ltp":2.1,"tv":897.99,"id":72857115}]}]}
{"op":"mcm","clk":"11883670996","pt":1724071097377,"mc":[{"id":"1.232011465","rc":[{"batb":[[0,2.08,34.24],[1,1.03,200],[2,1.02,200]],"ltp":2.1,"tv":897.99,"id":72857115}]}]}
{"op":"mcm","clk":"11883671052","pt":1724071098866,"mc":[{"id":"1.232011465","rc":[{"batb":[[0,2.1,10],[1,2.08,34.24],[2,1.03,200]],"ltp":2.1,"tv":897.99,"id":72857115}]}]}
{"op":"mcm","clk":"11883671217","pt":1724071102245,"mc":[{"id":"1.232011465","rc":[{"batb":[[0,2.08,34.24],[1,1.03,200],[2,1.02,200]],"ltp":2.1,"tv":897.99,"id":72857115}]}]}
{"op":"mcm","clk":"11883671304","pt":1724071104455,"mc":[{"id":"1.232011465","rc":[{"batb":[[0,2.1,10],[1,2.08,34.24],[2,1.03,200]],"ltp":2.1,"tv":897.99,"id":72857115}]}]}
{"op":"mcm","clk":"11883671427","pt":1724071107678,"mc":[{"id":"1.232011465","rc":[{"batb":[[0,2.08,34.24],[1,1.03,200],[2,1.02,200]],"ltp":2.1,"tv":897.99,"id":72857115}]}]}
{"op":"mcm","clk":"11883671735","pt":1724071115893,"mc":[{"id":"1.232011465","rc":[{"batb":[[0,2.1,10],[1,2.08,34.24],[2,1.03,200]],"ltp":2.1,"tv":897.99,"id":72857115}]}]}
{"op":"mcm","clk":"11883671925","pt":1724071119586,"mc":[{"id":"1.232011465","rc":[{"batb":[[0,2.08,34.24],[1,1.03,200],[2,1.02,200]],"ltp":2.1,"tv":897.99,"id":72857115}]}]}
{"op":"mcm","clk":"11883673230","pt":1724071156407,"mc":[{"id":"1.232011465","rc":[{"batb":[[0,2.1,10],[1,2.08,34.24],[2,1.03,200]],"ltp":2.1,"tv":897.99,"id":72857115}]}]}
{"op":"mcm","clk":"11883673352","pt":1724071159746,"mc":[{"id":"1.232011465","rc":[{"batb":[[0,2.08,34.24],[1,1.03,200],[2,1.02,200]],"ltp":2.1,"tv":897.99,"id":72857115}]}]}
{"op":"mcm","clk":"11883673809","pt":1724071172939,"mc":[{"id":"1.232011465","rc":[{"batb":[[0,2.1,10],[1,2.08,34.24],[2,1.03,200]],"ltp":2.1,"tv":897.99,"id":72857115}]}]}
{"op":"mcm","clk":"11883673912","pt":1724071176334,"mc":[{"id":"1.232011465","rc":[{"batb":[[0,2.08,34.24],[1,1.03,200],[2,1.02,200]],"ltp":2.1,"tv":897.99,"id":72857115}]}]}
{"op":"mcm","clk":"11883674413","pt":1724071193759,"mc":[{"id":"1.232011465","rc":[{"batb":[[0,2.1,10],[1,2.08,34.24],[2,1.03,200]],"ltp":2.1,"tv":897.99,"id":72857115}]}]}
{"op":"mcm","clk":"11883674540","pt":1724071197188,"mc":[{"id":"1.232011465","rc":[{"batb":[[0,2.08,34.24],[1,1.03,200],[2,1.02,200]],"ltp":2.1,"tv":897.99,"id":72857115}]}]}
{"op":"mcm","clk":"11883674642","pt":1724071200373,"mc":[{"id":"1.232011465","rc":[{"batb":[[0,2.1,10],[1,2.08,34.24],[2,1.03,200]],"ltp":2.1,"tv":897.99,"id":72857115}]}]}
{"op":"mcm","clk":"11883674762","pt":1724071203768,"mc":[{"id":"1.232011465","rc":[{"batb":[[0,2.08,34.24],[1,1.03,200],[2,1.02,200]],"ltp":2.1,"tv":897.99,"id":72857115}]}]}
{"op":"mcm","clk":"11883675129","pt":1724071213508,"mc":[{"id":"1.232011465","rc":[{"batb":[[0,2.1,10],[1,2.08,34.24],[2,1.03,200]],"ltp":2.1,"tv":897.99,"id":72857115}]}]}
{"op":"mcm","clk":"11883675308","pt":1724071217206,"mc":[{"id":"1.232011465","rc":[{"batb":[[0,2.08,34.24],[1,1.03,200],[2,1.02,200]],"ltp":2.1,"tv":897.99,"id":72857115}]}]}
{"op":"mcm","clk":"11883675517","pt":1724071222191,"mc":[{"id":"1.232011465","rc":[{"batb":[[0,2.1,10],[1,2.08,34.24],[2,1.03,200]],"ltp":2.1,"tv":897.99,"id":72857115}]}]}
{"op":"mcm","clk":"11883675657","pt":1724071225630,"mc":[{"id":"1.232011465","rc":[{"batb":[[0,2.08,34.24],[1,1.03,200],[2,1.02,200]],"ltp":2.1,"tv":897.99,"id":72857115}]}]}
{"op":"mcm","clk":"11883675804","pt":1724071229226,"mc":[{"id":"1.232011465","rc":[{"batb":[[0,2.1,10],[1,2.08,34.24],[2,1.03,200]],"ltp":2.1,"tv":897.99,"id":72857115}]}]}
{"op":"mcm","clk":"11883675925","pt":1724071232513,"mc":[{"id":"1.232011465","rc":[{"batb":[[0,2.08,34.24],[1,1.03,200],[2,1.02,200]],"ltp":2.1,"tv":897.99,"id":72857115}]}]}
{"op":"mcm","clk":"11883676015","pt":1724071234924,"mc":[{"id":"1.232011465","rc":[{"batb":[[0,2.1,10],[1,2.08,34.24],[2,1.03,200]],"ltp":2.1,"tv":897.99,"id":72857115}]}]}
{"op":"mcm","clk":"11883676167","pt":1724071238324,"mc":[{"id":"1.232011465","rc":[{"batb":[[0,2.08,34.24],[1,1.03,200],[2,1.02,200]],"ltp":2.1,"tv":897.99,"id":72857115}]}]}
{"op":"mcm","clk":"11883676423","pt":1724071245522,"mc":[{"id":"1.232011465","rc":[{"trd":[[1.86,2.22]],"batl":[[0,2.48,4.65],[1,13,0.94],[2,13,0]],"ltp":1.86,"tv":904.95,"id":67083366}],"tv":1802.95}]}
{"op":"mcm","clk":"11883676527","pt":1724071247533,"mc":[{"id":"1.232011465","rc":[{"batb":[[0,1.85,10],[1,1.84,44.02],[2,1.52,7.75]],"ltp":1.86,"tv":904.95,"id":67083366},{"batb":[[0,2.1,10],[1,2.08,34.24],[2,1.03,200]],"ltp":2.1,"tv":897.99,"id":72857115}]}]}
{"op":"mcm","clk":"11883676650","pt":1724071250522,"mc":[{"id":"1.232011465","rc":[{"batl":[[1,13,0]],"ltp":1.86,"tv":904.95,"id":67083366}]}]}
{"op":"mcm","clk":"11883676718","pt":1724071252159,"mc":[{"id":"1.232011465","rc":[{"batb":[[0,1.84,44.02],[1,1.52,7.75],[2,1.03,200]],"ltp":1.86,"tv":904.95,"id":67083366},{"batb":[[0,2.08,34.24],[1,1.03,200],[2,1.02,200]],"ltp":2.1,"tv":897.99,"id":72857115}]}]}
{"op":"mcm","clk":"11883676851","pt":1724071255644,"mc":[{"id":"1.232011465","rc":[{"batb":[[0,1.85,10],[1,1.84,44.02],[2,1.52,7.75]],"ltp":1.86,"tv":904.95,"id":67083366},{"batb":[[0,2.1,10],[1,2.08,34.24],[2,1.03,200]],"ltp":2.1,"tv":897.99,"id":72857115}]}]}
{"op":"mcm","clk":"11883676939","pt":1724071258412,"mc":[{"id":"1.232011465","rc":[{"batl":[[0,2.48,5.6]],"ltp":1.86,"tv":904.95,"id":67083366}]}]}
{"op":"mcm","clk":"11883676966","pt":1724071259132,"mc":[{"id":"1.232011465","rc":[{"batb":[[0,1.84,44.02],[1,1.52,7.75],[2,1.03,200]],"ltp":1.86,"tv":904.95,"id":67083366},{"batb":[[0,2.08,34.24],[1,1.03,200],[2,1.02,200]],"ltp":2.1,"tv":897.99,"id":72857115}]}]}
{"op":"mcm","clk":"11883677042","pt":1724071261654,"mc":[{"id":"1.232011465","rc":[{"batb":[[0,1.85,10],[1,1.84,44.02],[2,1.52,7.75]],"ltp":1.86,"tv":904.95,"id":67083366},{"batb":[[0,2.1,10],[1,2.08,34.24],[2,1.03,200]],"ltp":2.1,"tv":897.99,"id":72857115}]}]}
{"op":"mcm","clk":"11883677176","pt":1724071265142,"mc":[{"id":"1.232011465","rc":[{"batb":[[0,1.84,44.02],[1,1.52,7.75],[2,1.03,200]],"ltp":1.86,"tv":904.95,"id":67083366},{"batb":[[0,2.08,34.24],[1,1.03,200],[2,1.02,200]],"ltp":2.1,"tv":897.99,"id":72857115}]}]}
{"op":"mcm","clk":"11883677265","pt":1724071267557,"mc":[{"id":"1.232011465","rc":[{"batb":[[0,1.85,10],[1,1.84,44.02],[2,1.52,7.75]],"ltp":1.86,"tv":904.95,"id":67083366}]}]}
{"op":"mcm","clk":"11883677389","pt":1724071271050,"mc":[{"id":"1.232011465","rc":[{"batb":[[0,1.84,44.02],[1,1.52,7.75],[2,1.03,200]],"ltp":1.86,"tv":904.95,"id":67083366}]}]}
{"op":"mcm","clk":"11883677556","pt":1724071275679,"mc":[{"id":"1.232011465","rc":[{"batb":[[0,1.85,10],[1,1.84,44.02],[2,1.52,7.75]],"ltp":1.86,"tv":904.95,"id":67083366}]}]}
{"op":"mcm","clk":"11883677697","pt":1724071279160,"mc":[{"id":"1.232011465","rc":[{"batb":[[0,1.84,44.02],[1,1.52,7.75],[2,1.03,200]],"ltp":1.86,"tv":904.95,"id":67083366}]}]}
{"op":"mcm","clk":"11883678327","pt":1724071295215,"mc":[{"id":"1.232011465","rc":[{"batb":[[0,1.85,10],[1,1.84,44.02],[2,1.52,7.75]],"ltp":1.86,"tv":904.95,"id":67083366}]}]}
{"op":"mcm","clk":"11883678488","pt":1724071298610,"mc":[{"id":"1.232011465","rc":[{"batb":[[0,1.84,44.02],[1,1.52,7.75],[2,1.03,200]],"ltp":1.86,"tv":904.95,"id":67083366}]}]}
{"op":"mcm","clk":"11883678894","pt":1724071309730,"mc":[{"id":"1.232011465","rc":[{"batb":[[0,1.85,10],[1,1.84,44.02],[2,1.52,7.75]],"batl":[[0,1.9,1.09],[1,2.48,4.65]],"ltp":1.86,"tv":904.95,"id":67083366}]}]}
{"op":"mcm","clk":"11883679034","pt":1724071313024,"mc":[{"id":"1.232011465","rc":[{"batb":[[0,1.84,44.02],[1,1.52,7.75],[2,1.03,200]],"ltp":1.86,"tv":904.95,"id":67083366}]}]}
{"op":"mcm","clk":"11883690917","pt":1724071590760,"mc":[{"id":"1.232011465","rc":[{"batl":[[0,1.89,1.09]],"ltp":1.86,"tv":904.95,"id":67083366}]}]}
{"op":"mcm","clk":"11883736349","pt":1724072810990,"mc":[{"id":"1.232011465","rc":[{"trd":[[1.09,881.77],[1.1,20.01]],"ltp":1.86,"tv":905.36,"id":67083366},{"trd":[[1.09,897.16]],"ltp":2.1,"tv":898.4,"id":72857115}],"tv":1803.77}]}
{"op":"mcm","clk":"11883737824","pt":1724072852842,"mc":[{"id":"1.232011465","rc":[{"trd":[[1.89,2.18]],"batb":[[0,1.9,10],[1,1.89,48.25],[2,1.84,44.02]],"batl":[[0,2.48,4.65],[1,2.48,0]],"ltp":1.89,"tv":907.55,"id":67083366}],"tv":1805.95}]}
{"op":"mcm","clk":"11883737926","pt":1724072856225,"mc":[{"id":"1.232011465","rc":[{"batb":[[0,1.89,48.25],[1,1.84,44.02],[2,1.52,7.76]],"ltp":1.89,"tv":907.55,"id":67083366}]}]}
{"op":"mcm","clk":"11883737990","pt":1724072858526,"mc":[{"id":"1.232011465","rc":[{"batb":[[0,1.9,10],[1,1.89,48.25],[2,1.84,44.02]],"ltp":1.89,"tv":907.55,"id":67083366}]}]}
{"op":"mcm","clk":"11883738037","pt":1724072859956,"mc":[{"id":"1.232011465","rc":[{"batb":[[1,1.84,44.02],[2,1.52,7.76]],"ltp":1.89,"tv":907.55,"id":67083366}]}]}
{"op":"mcm","clk":"11883738101","pt":1724072861958,"mc":[{"id":"1.232011465","rc":[{"batb":[[0,1.84,44.02],[1,1.52,7.76],[2,1.03,200]],"ltp":1.89,"tv":907.55,"id":67083366}]}]}
{"op":"mcm","clk":"11883738149","pt":1724072864264,"mc":[{"id":"1.232011465","rc":[{"batb":[[0,1.85,10],[1,1.84,44.02],[2,1.52,7.76]],"ltp":1.89,"tv":907.55,"id":67083366}]}]}
{"op":"mcm","clk":"11883738237","pt":1724072867658,"mc":[{"id":"1.232011465","rc":[{"batb":[[0,1.84,44.02],[1,1.52,7.76],[2,1.03,200]],"ltp":1.89,"tv":907.55,"id":67083366}]}]}
{"op":"mcm","clk":"11883738365","pt":1724072872734,"mc":[{"id":"1.232011465","rc":[{"batb":[[0,1.85,10],[1,1.84,44.02],[2,1.52,7.76]],"ltp":1.89,"tv":907.55,"id":67083366}]}]}
{"op":"mcm","clk":"11883738475","pt":1724072876175,"mc":[{"id":"1.232011465","rc":[{"batb":[[0,1.84,44.02],[1,1.52,7.76],[2,1.03,200]],"ltp":1.89,"tv":907.55,"id":67083366}]}]}
{"op":"mcm","clk":"11883738525","pt":1724072878376,"mc":[{"id":"1.232011465","rc":[{"batb":[[0,1.85,10],[1,1.84,44.02],[2,1.52,7.76]],"ltp":1.89,"tv":907.55,"id":67083366},{"batb":[[2,1.02,294.97]],"ltp":2.1,"tv":898.4,"id":72857115}]}]}
{"op":"mcm","clk":"11883738610","pt":1724072881556,"mc":[{"id":"1.232011465","rc":[{"batb":[[0,1.84,44.02],[1,1.52,7.76],[2,1.03,200]],"ltp":1.89,"tv":907.55,"id":67083366}]}]}
{"op":"mcm","clk":"11883738680","pt":1724072884376,"mc":[{"id":"1.232011465","rc":[{"batb":[[0,1.85,10],[1,1.84,44.02],[2,1.52,7.76]],"ltp":1.89,"tv":907.55,"id":67083366}]}]}
{"op":"mcm","clk":"11883738776","pt":1724072887659,"mc":[{"id":"1.232011465","rc":[{"batb":[[0,1.84,44.02],[1,1.52,7.76],[2,1.03,200]],"ltp":1.89,"tv":907.55,"id":67083366}]}]}
{"op":"mcm","clk":"11883738866","pt":1724072890274,"mc":[{"id":"1.232011465","rc":[{"batb":[[0,1.85,10],[1,1.84,44.02],[2,1.52,7.76]],"ltp":1.89,"tv":907.55,"id":67083366}]}]}
{"op":"mcm","clk":"11883738944","pt":1724072892684,"mc":[{"id":"1.232011465","rc":[{"trd":[[1.85,2.22]],"batb":[[0,1.85,8.89]],"ltp":1.85,"tv":909.77,"id":67083366}],"tv":1808.18}]}
{"op":"mcm","clk":"11883738979","pt":1724072893759,"mc":[{"id":"1.232011465","rc":[{"batb":[[0,1.84,44.02],[1,1.52,7.76],[2,1.03,200]],"ltp":1.85,"tv":909.77,"id":67083366}]}]}
{"op":"mcm","clk":"11883739102","pt":1724072897458,"mc":[{"id":"1.232011465","rc":[{"batb":[[0,1.85,10],[1,1.84,44.02],[2,1.52,7.76]],"ltp":1.85,"tv":909.77,"id":67083366}]}]}
{"op":"mcm","clk":"11883739209","pt":1724072900768,"mc":[{"id":"1.232011465","rc":[{"batb":[[0,1.84,44.02],[1,1.52,7.76],[2,1.03,200]],"ltp":1.85,"tv":909.77,"id":67083366}]}]}
{"op":"mcm","clk":"11883739310","pt":1724072904203,"mc":[{"id":"1.232011465","rc":[{"batb":[[0,1.85,10],[1,1.84,44.02],[2,1.52,7.76]],"ltp":1.85,"tv":909.77,"id":67083366}]}]}
{"op":"mcm","clk":"11883739464","pt":1724072908991,"mc":[{"id":"1.232011465","rc":[{"batb":[[0,1.84,44.02],[1,1.52,7.76],[2,1.03,200]],"ltp":1.85,"tv":909.77,"id":67083366}]}]}
{"op":"mcm","clk":"11883739558","pt":1724072911702,"mc":[{"id":"1.232011465","rc":[{"batb":[[0,1.85,10],[1,1.84,44.02],[2,1.52,7.76]],"ltp":1.85,"tv":909.77,"id":67083366}]}]}
{"op":"mcm","clk":"11883739675","pt":1724072915089,"mc":[{"id":"1.232011465","rc":[{"batb":[[0,1.84,44.02],[1,1.52,7.76],[2,1.03,200]],"ltp":1.85,"tv":909.77,"id":67083366}]}]}
{"op":"mcm","clk":"11883739813","pt":1724072919185,"mc":[{"id":"1.232011465","rc":[{"batb":[[0,1.85,10],[1,1.84,44.02],[2,1.52,7.76]],"ltp":1.85,"tv":909.77,"id":67083366}]}]}
{"op":"mcm","clk":"11883739881","pt":1724072921901,"mc":[{"id":"1.232011465","rc":[{"batb":[[0,1.84,44.02],[1,1.52,7.76],[2,1.1,1000]],"ltp":1.85,"tv":909.77,"id":67083366}]}]}
{"op":"mcm","clk":"11883739918","pt":1724072923180,"mc":[{"id":"1.232011465","rc":[{"batb":[[1,1.1,1000],[2,1.03,200]],"ltp":2.1,"tv":898.4,"id":72857115}]}]}
{"op":"mcm","clk":"11883739981","pt":1724072925287,"mc":[{"id":"1.232011465","rc":[{"batb":[[0,1.85,10],[1,1.84,44.02],[2,1.52,7.76]],"ltp":1.85,"tv":909.77,"id":67083366}]}]}
{"op":"mcm","clk":"11883740072","pt":1724072928616,"mc":[{"id":"1.232011465","rc":[{"batb":[[0,1.84,44.02],[1,1.52,7.76],[2,1.1,1000]],"ltp":1.85,"tv":909.77,"id":67083366}]}]}
{"op":"mcm","clk":"11883740145","pt":1724072931796,"mc":[{"id":"1.232011465","rc":[{"batb":[[0,1.85,10],[1,1.84,44.02],[2,1.52,7.76]],"ltp":1.85,"tv":909.77,"id":67083366}]}]}
{"op":"mcm","clk":"11883740220","pt":1724072935236,"mc":[{"id":"1.232011465","rc":[{"batb":[[0,1.84,44.02],[1,1.52,7.76],[2,1.1,1000]],"ltp":1.85,"tv":909.77,"id":67083366}]}]}
{"op":"mcm","clk":"11883740309","pt":1724072938311,"mc":[{"id":"1.232011465","rc":[{"batb":[[0,1.85,10],[1,1.84,44.02],[2,1.52,7.76]],"ltp":1.85,"tv":909.77,"id":67083366}]}]}
{"op":"mcm","clk":"11883740437","pt":1724072941704,"mc":[{"id":"1.232011465","rc":[{"batb":[[0,1.84,44.02],[1,1.52,7.76],[2,1.1,1000]],"ltp":1.85,"tv":909.77,"id":67083366}]}]}
{"op":"mcm","clk":"11883740602","pt":1724072947039,"mc":[{"id":"1.232011465","rc":[{"batb":[[0,1.85,10],[1,1.84,44.02],[2,1.52,7.76]],"ltp":1.85,"tv":909.77,"id":67083366}]}]}
{"op":"mcm","clk":"11883740722","pt":1724072950438,"mc":[{"id":"1.232011465","rc":[{"batb":[[0,1.84,44.02],[1,1.52,7.76],[2,1.1,1000]],"ltp":1.85,"tv":909.77,"id":67083366}]}]}
{"op":"mcm","clk":"11883740828","pt":1724072953423,"mc":[{"id":"1.232011465","rc":[{"batb":[[0,1.85,10],[1,1.84,44.02],[2,1.52,7.76]],"ltp":1.85,"tv":909.77,"id":67083366}]}]}
{"op":"mcm","clk":"11883740933","pt":1724072956754,"mc":[{"id":"1.232011465","rc":[{"batb":[[0,1.84,44.02],[1,1.52,7.76],[2,1.1,1000]],"ltp":1.85,"tv":909.77,"id":67083366}]}]}
{"op":"mcm","clk":"11883741066","pt":1724072960535,"mc":[{"id":"1.232011465","rc":[{"batb":[[0,1.85,10],[1,1.84,44.02],[2,1.52,7.76]],"ltp":1.85,"tv":909.77,"id":67083366}]}]}
{"op":"mcm","clk":"11883741172","pt":1724072964024,"mc":[{"id":"1.232011465","rc":[{"batb":[[0,1.84,44.02],[1,1.52,7.76],[2,1.1,1000]],"ltp":1.85,"tv":909.77,"id":67083366}]}]}
{"op":"mcm","clk":"11883741312","pt":1724072969822,"mc":[{"id":"1.232011465","rc":[{"batb":[[0,1.85,10],[1,1.84,44.02],[2,1.52,7.76]],"ltp":1.85,"tv":909.77,"id":67083366}]}]}
{"op":"mcm","clk":"11883741434","pt":1724072973272,"mc":[{"id":"1.232011465","rc":[{"batb":[[0,1.84,44.02],[1,1.52,7.76],[2,1.1,1000]],"ltp":1.85,"tv":909.77,"id":67083366}]}]}
{"op":"mcm","clk":"11883741546","pt":1724072976764,"mc":[{"id":"1.232011465","rc":[{"batb":[[0,1.85,10],[1,1.84,44.02],[2,1.52,7.76]],"ltp":1.85,"tv":909.77,"id":67083366}]}]}
{"op":"mcm","clk":"11883741645","pt":1724072980157,"mc":[{"id":"1.232011465","rc":[{"batb":[[0,1.84,44.02],[1,1.52,7.76],[2,1.1,1000]],"ltp":1.85,"tv":909.77,"id":67083366}]}]}
{"op":"mcm","clk":"11883741786","pt":1724072984263,"mc":[{"id":"1.232011465","rc":[{"batb":[[0,1.85,10],[1,1.84,44.02],[2,1.52,7.76]],"ltp":1.85,"tv":909.77,"id":67083366}]}]}
{"op":"mcm","clk":"11883741917","pt":1724072987646,"mc":[{"id":"1.232011465","rc":[{"batb":[[0,1.84,44.02],[1,1.52,7.76],[2,1.1,1000]],"ltp":1.85,"tv":909.77,"id":67083366}]}]}
{"op":"mcm","clk":"11883742080","pt":1724072992253,"mc":[{"id":"1.232011465","rc":[{"batb":[[0,1.85,10],[1,1.84,44.02],[2,1.52,7.76]],"ltp":1.85,"tv":909.77,"id":67083366}]}]}
{"op":"mcm","clk":"11883742159","pt":1724072995794,"mc":[{"id":"1.232011465","rc":[{"batb":[[0,1.84,44.02],[1,1.52,7.76],[2,1.1,1000]],"ltp":1.85,"tv":909.77,"id":67083366}]}]}
{"op":"mcm","clk":"11883742232","pt":1724072998295,"mc":[{"id":"1.232011465","rc":[{"batb":[[0,1.85,10],[1,1.84,44.02],[2,1.52,7.76]],"ltp":1.85,"tv":909.77,"id":67083366}]}]}
{"op":"mcm","clk":"11883742358","pt":1724073001700,"mc":[{"id":"1.232011465","rc":[{"batb":[[0,1.84,44.02],[1,1.52,7.76],[2,1.1,1000]],"ltp":1.85,"tv":909.77,"id":67083366}]}]}
{"op":"mcm","clk":"11883742467","pt":1724073004489,"mc":[{"id":"1.232011465","rc":[{"batb":[[0,1.85,10],[1,1.84,44.02],[2,1.52,7.76]],"ltp":1.85,"tv":909.77,"id":67083366}]}]}
{"op":"mcm","clk":"11883742646","pt":1724073009386,"mc":[{"id":"1.232011465","rc":[{"batb":[[0,1.84,44.02],[1,1.52,7.76],[2,1.1,1000]],"ltp":1.85,"tv":909.77,"id":67083366}]}]}
{"op":"mcm","clk":"11883742779","pt":1724073012981,"mc":[{"id":"1.232011465","rc":[{"batb":[[0,1.85,10],[1,1.84,44.02],[2,1.52,7.76]],"ltp":1.85,"tv":909.77,"id":67083366}]}]}
{"op":"mcm","clk":"11883742908","pt":1724073016628,"mc":[{"id":"1.232011465","rc":[{"batb":[[0,1.84,44.02],[1,1.52,7.76],[2,1.1,1000]],"ltp":1.85,"tv":909.77,"id":67083366}]}]}
{"op":"mcm","clk":"11883743006","pt":1724073019619,"mc":[{"id":"1.232011465","rc":[{"batb":[[0,1.85,10],[1,1.84,44.02],[2,1.52,7.76]],"ltp":1.85,"tv":909.77,"id":67083366}]}]}
{"op":"mcm","clk":"11883743108","pt":1724073023002,"mc":[{"id":"1.232011465","rc":[{"batb":[[0,1.84,44.02],[1,1.52,7.76],[2,1.1,1000]],"ltp":1.85,"tv":909.77,"id":67083366}]}]}
{"op":"mcm","clk":"11883743227","pt":1724073026358,"mc":[{"id":"1.232011465","rc":[{"batb":[[0,1.85,10],[1,1.84,44.02],[2,1.52,7.76]],"ltp":1.85,"tv":909.77,"id":67083366}]}]}
{"op":"mcm","clk":"11883743333","pt":1724073029807,"mc":[{"id":"1.232011465","rc":[{"batb":[[0,1.84,44.02],[1,1.52,7.76],[2,1.1,1000]],"ltp":1.85,"tv":909.77,"id":67083366}]}]}
{"op":"mcm","clk":"11883743641","pt":1724073038443,"mc":[{"id":"1.232011465","rc":[{"batb":[[0,1.85,10],[1,1.84,44.02],[2,1.52,7.76]],"batl":[[0,1.9,41.89],[1,2.48,4.65]],"ltp":1.85,"tv":909.77,"id":67083366}]}]}
{"op":"mcm","clk":"11883743723","pt":1724073041325,"mc":[{"id":"1.232011465","rc":[{"batb":[[0,1.84,44.02],[1,1.52,7.76],[2,1.1,1000]],"ltp":1.85,"tv":909.77,"id":67083366}]}]}
{"op":"mcm","clk":"11883744159","pt":1724073055167,"mc":[{"id":"1.232011465","rc":[{"trd":[[1.9,75.08]],"batl":[[0,1.9,4.35]],"ltp":1.9,"tv":984.85,"id":67083366}],"tv":1883.26}]}
{"op":"mcm","clk":"11883746008","pt":1724073122293,"mc":[{"id":"1.232011465","rc":[{"trd":[[1.9,83.78],[1.93,32.12]],"batb":[[0,1.85,10],[1,1.84,44.02],[2,1.52,7.76]],"batl":[[0,2.48,4.65],[1,2.48,0]],"ltp":1.93,"tv":1025.67,"id":67083366},{"trd":[[2.08,29.8]],"batb":[[0,2.08,4.44]],"ltp":2.08,"tv":928.2,"id":72857115}],"tv":1953.88}]}
{"op":"mcm","clk":"11883746028","pt":1724073122599,"mc":[{"id":"1.232011465","rc":[{"batb":[[0,2.08,34.24]],"ltp":2.08,"tv":928.2,"id":72857115}]}]}
{"op":"mcm","clk":"11883746114","pt":1724073125634,"mc":[{"id":"1.232011465","rc":[{"batb":[[0,1.84,44.02],[1,1.52,7.76],[2,1.1,1000]],"ltp":1.93,"tv":1025.67,"id":67083366}]}]}
{"op":"mcm","clk":"11883746168","pt":1724073127838,"mc":[{"id":"1.232011465","rc":[{"batb":[[0,1.85,10],[1,1.84,44.02],[2,1.52,7.76]],"ltp":1.93,"tv":1025.67,"id":67083366}]}]}
{"op":"mcm","clk":"11883746224","pt":1724073129329,"mc":[{"id":"1.232011465","rc":[{"batl":[[0,2.1,140.42]],"ltp":2.08,"tv":928.2,"id":72857115}]}]}
{"op":"mcm","clk":"11883746276","pt":1724073131325,"mc":[{"id":"1.232011465","rc":[{"batb":[[0,1.84,44.02],[1,1.52,7.76],[2,1.1,1000]],"ltp":1.93,"tv":1025.67,"id":67083366}]}]}
{"op":"mcm","clk":"11883746429","pt":1724073137450,"mc":[{"id":"1.232011465","rc":[{"batb":[[0,1.85,10],[1,1.84,44.02],[2,1.52,7.76]],"ltp":1.93,"tv":1025.67,"id":67083366}]}]}
{"op":"mcm","clk":"11883746515","pt":1724073140836,"mc":[{"id":"1.232011465","rc":[{"batb":[[0,1.84,44.02],[1,1.52,7.76],[2,1.1,1000]],"ltp":1.93,"tv":1025.67,"id":67083366}]}]}
{"op":"mcm","clk":"11883746602","pt":1724073144433,"mc":[{"id":"1.232011465","rc":[{"batb":[[0,1.85,10],[1,1.84,44.02],[2,1.52,7.76]],"ltp":1.93,"tv":1025.67,"id":67083366}]}]}
{"op":"mcm","clk":"11883746688","pt":1724073148041,"mc":[{"id":"1.232011465","rc":[{"batb":[[0,1.84,44.02],[1,1.52,7.76],[2,1.1,1000]],"ltp":1.93,"tv":1025.67,"id":67083366}]}]}
{"op":"mcm","clk":"11883746789","pt":1724073152215,"mc":[{"id":"1.232011465","rc":[{"batb":[[0,1.85,10],[1,1.84,44.02],[2,1.52,7.76]],"ltp":1.93,"tv":1025.67,"id":67083366}]}]}
{"op":"mcm","clk":"11883746872","pt":1724073155669,"mc":[{"id":"1.232011465","rc":[{"batb":[[0,1.84,44.02],[1,1.52,7.76],[2,1.1,1000]],"ltp":1.93,"tv":1025.67,"id":67083366}]}]}
{"op":"mcm","clk":"11883747014","pt":1724073160141,"mc":[{"id":"1.232011465","rc":[{"batb":[[0,1.85,10],[1,1.84,44.02],[2,1.52,7.76]],"ltp":1.93,"tv":1025.67,"id":67083366}]}]}
{"op":"mcm","clk":"11883747095","pt":1724073163057,"mc":[{"id":"1.232011465","rc":[{"trd":[[1.93,37.44]],"ltp":1.93,"tv":1030.99,"id":67083366},{"trd":[[2.08,34.74]],"batb":[[0,2.08,29.3]],"ltp":2.08,"tv":933.14,"id":72857115}],"tv":1964.14}]}
{"op":"mcm","clk":"11883747111","pt":1724073163674,"mc":[{"id":"1.232011465","rc":[{"batb":[[0,1.84,44.02],[1,1.52,7.76],[2,1.1,1000]],"ltp":1.93,"tv":1030.99,"id":67083366}]}]}
{"op":"mcm","clk":"11883747188","pt":1724073166763,"mc":[{"id":"1.232011465","rc":[{"batb":[[0,1.85,10],[1,1.84,44.02],[2,1.52,7.76]],"ltp":1.93,"tv":1030.99,"id":67083366}]}]}
{"op":"mcm","clk":"11883747226","pt":1724073167689,"mc":[{"id":"1.232011465","rc":[{"batb":[[0,2.08,34.24]],"ltp":2.08,"tv":933.14,"id":72857115}]}]}
{"op":"mcm","clk":"11883747311","pt":1724073170259,"mc":[{"id":"1.232011465","rc":[{"batb":[[0,1.84,44.02],[1,1.52,7.76],[2,1.1,1000]],"ltp":1.93,"tv":1030.99,"id":67083366}]}]}
{"op":"mcm","clk":"11883747357","pt":1724073172467,"mc":[{"id":"1.232011465","rc":[{"batb":[[0,1.85,10],[1,1.84,44.02],[2,1.52,7.76]],"ltp":1.93,"tv":1030.99,"id":67083366}]}]}
{"op":"mcm","clk":"11883747449","pt":1724073175967,"mc":[{"id":"1.232011465","rc":[{"batb":[[0,1.84,44.02],[1,1.52,7.76],[2,1.1,1000]],"ltp":1.93,"tv":1030.99,"id":67083366}]}]}
{"op":"mcm","clk":"11883747571","pt":1724073182077,"mc":[{"id":"1.232011465","rc":[{"batb":[[0,1.85,10],[1,1.84,44.02],[2,1.52,7.76]],"ltp":1.93,"tv":1030.99,"id":67083366}]}]}
{"op":"mcm","clk":"11883747669","pt":1724073185510,"mc":[{"id":"1.232011465","rc":[{"batb":[[0,1.84,44.02],[1,1.52,7.76],[2,1.1,1000]],"ltp":1.93,"tv":1030.99,"id":67083366}]}]}
{"op":"mcm","clk":"11883747956","pt":1724073193991,"mc":[{"id":"1.232011465","rc":[{"batb":[[0,1.85,10],[1,1.84,44.02],[2,1.52,7.76]],"ltp":1.93,"tv":1030.99,"id":67083366}]}]}
{"op":"mcm","clk":"11883748066","pt":1724073197514,"mc":[{"id":"1.232011465","rc":[{"batb":[[0,1.84,44.02],[1,1.52,7.76],[2,1.1,1000]],"ltp":1.93,"tv":1030.99,"id":67083366}]}]}
{"op":"mcm","clk":"11883748140","pt":1724073201427,"mc":[{"id":"1.232011465","rc":[{"batb":[[0,1.85,10],[1,1.84,44.02],[2,1.52,7.76]],"ltp":1.93,"tv":1030.99,"id":67083366},{"trd":[[2.08,103.22]],"batb":[[0,1.11,10]],"batl":[[0,2.08,106.83]],"ltp":2.08,"tv":1001.62,"id":72857115}],"tv":2032.62}]}
{"op":"mcm","clk":"11883748210","pt":1724073204734,"mc":[{"id":"1.232011465","rc":[{"batb":[[0,1.84,44.02],[1,1.52,7.76],[2,1.1,1000]],"ltp":1.93,"tv":1030.99,"id":67083366},{"batb":[[0,1.1,1000],[1,1.03,200],[2,1.02,294.97]],"ltp":2.08,"tv":1001.62,"id":72857115}]}]}
{"op":"mcm","clk":"11883748293","pt":1724073208402,"mc":[{"id":"1.232011465","rc":[{"batb":[[0,1.85,10],[1,1.84,44.02],[2,1.52,7.76]],"ltp":1.93,"tv":1030.99,"id":67083366},{"batb":[[0,1.11,10],[1,1.1,1000],[2,1.03,200]],"ltp":2.08,"tv":1001.62,"id":72857115}]}]}
{"op":"mcm","clk":"11883748407","pt":1724073211818,"mc":[{"id":"1.232011465","rc":[{"batb":[[0,1.84,44.02],[1,1.52,7.76],[2,1.1,1000]],"ltp":1.93,"tv":1030.99,"id":67083366},{"batb":[[0,1.1,1000],[1,1.03,200],[2,1.02,294.97]],"ltp":2.08,"tv":1001.62,"id":72857115}]}]}
{"op":"mcm","clk":"11883748533","pt":1724073215340,"mc":[{"id":"1.232011465","rc":[{"batb":[[0,1.85,10],[1,1.84,44.02],[2,1.52,7.76]],"ltp":1.93,"tv":1030.99,"id":67083366}]}]}
{"op":"mcm","clk":"11883748624","pt":1724073218748,"mc":[{"id":"1.232011465","rc":[{"batb":[[0,1.84,44.02],[1,1.52,7.76],[2,1.1,1000]],"ltp":1.93,"tv":1030.99,"id":67083366}]}]}
{"op":"mcm","clk":"11883748689","pt":1724073221129,"mc":[{"id":"1.232011465","rc":[{"batb":[[0,1.85,10],[1,1.84,44.02],[2,1.52,7.76]],"ltp":1.93,"tv":1030.99,"id":67083366}]}]}
{"op":"mcm","clk":"11883748796","pt":1724073224434,"mc":[{"id":"1.232011465","rc":[{"batb":[[0,1.84,44.02],[1,1.52,7.76],[2,1.1,1000]],"ltp":1.93,"tv":1030.99,"id":67083366}]}]}
{"op":"mcm","clk":"11883748856","pt":1724073227025,"mc":[{"id":"1.232011465","rc":[{"batb":[[0,1.85,10],[1,1.84,44.02],[2,1.52,7.76]],"ltp":1.93,"tv":1030.99,"id":67083366}]}]}
{"op":"mcm","clk":"11883748938","pt":1724073230348,"mc":[{"id":"1.232011465","rc":[{"batb":[[0,1.84,44.02],[1,1.52,7.76],[2,1.1,1000]],"ltp":1.93,"tv":1030.99,"id":67083366}]}]}
{"op":"mcm","clk":"11883749006","pt":1724073232923,"mc":[{"id":"1.232011465","rc":[{"batb":[[0,1.85,10],[1,1.84,44.02],[2,1.52,7.76]],"ltp":1.93,"tv":1030.99,"id":67083366}]}]}
{"op":"mcm","clk":"11883749086","pt":1724073236445,"mc":[{"id":"1.232011465","rc":[{"batb":[[0,1.84,44.02],[1,1.52,7.76],[2,1.1,1000]],"ltp":1.93,"tv":1030.99,"id":67083366}]}]}
{"op":"mcm","clk":"11883749154","pt":1724073239654,"mc":[{"id":"1.232011465","rc":[{"batb":[[0,1.85,10],[1,1.84,44.02],[2,1.52,7.76]],"ltp":1.93,"tv":1030.99,"id":67083366}]}]}
{"op":"mcm","clk":"11883749261","pt":1724073243185,"mc":[{"id":"1.232011465","rc":[{"batb":[[0,1.84,44.02],[1,1.52,7.76],[2,1.1,1000]],"ltp":1.93,"tv":1030.99,"id":67083366}]}]}
{"op":"mcm","clk":"11883749385","pt":1724073247655,"mc":[{"id":"1.232011465","rc":[{"batb":[[0,1.85,10],[1,1.84,44.02],[2,1.52,7.76]],"ltp":1.93,"tv":1030.99,"id":67083366}]}]}
{"op":"mcm","clk":"11883749483","pt":1724073250898,"mc":[{"id":"1.232011465","rc":[{"batb":[[0,1.84,44.02],[1,1.52,7.76],[2,1.1,1000]],"ltp":1.93,"tv":1030.99,"id":67083366}]}]}
{"op":"mcm","clk":"11883749613","pt":1724073255128,"mc":[{"id":"1.232011465","rc":[{"batb":[[0,1.85,10],[1,1.84,44.02],[2,1.52,7.76]],"ltp":1.93,"tv":1030.99,"id":67083366}]}]}
{"op":"mcm","clk":"11883749717","pt":1724073258691,"mc":[{"id":"1.232011465","rc":[{"batb":[[0,1.84,44.02],[1,1.52,7.76],[2,1.1,1000]],"ltp":1.93,"tv":1030.99,"id":67083366}]}]}
{"op":"mcm","clk":"11883749832","pt":1724073261897,"mc":[{"id":"1.232011465","rc":[{"batb":[[0,1.85,10],[1,1.84,44.02],[2,1.52,7.76]],"ltp":1.93,"tv":1030.99,"id":67083366}]}]}
{"op":"mcm","clk":"11883749948","pt":1724073265395,"mc":[{"id":"1.232011465","rc":[{"batb":[[0,1.84,44.02],[1,1.52,7.76],[2,1.1,1000]],"ltp":1.93,"tv":1030.99,"id":67083366}]}]}
{"op":"mcm","clk":"11883750191","pt":1724073272314,"mc":[{"id":"1.232011465","rc":[{"batb":[[0,1.85,10],[1,1.84,44.02],[2,1.52,7.76]],"ltp":1.93,"tv":1030.99,"id":67083366}]}]}
{"op":"mcm","clk":"11883750379","pt":1724073275907,"mc":[{"id":"1.232011465","rc":[{"batb":[[0,1.84,44.02],[1,1.52,7.76],[2,1.1,1000]],"ltp":1.93,"tv":1030.99,"id":67083366}]}]}
{"op":"mcm","clk":"11883750478","pt":1724073278739,"mc":[{"id":"1.232011465","rc":[{"batb":[[0,1.85,10],[1,1.84,44.02],[2,1.52,7.76]],"ltp":1.93,"tv":1030.99,"id":67083366}]}]}
{"op":"mcm","clk":"11883750634","pt":1724073283642,"mc":[{"id":"1.232011465","rc":[{"batb":[[0,1.84,44.02],[1,1.52,7.76],[2,1.1,1000]],"ltp":1.93,"tv":1030.99,"id":67083366}]}]}
{"op":"mcm","clk":"11883750704","pt":1724073285858,"mc":[{"id":"1.232011465","rc":[{"batb":[[0,1.85,10],[1,1.84,44.02],[2,1.52,7.76]],"ltp":1.93,"tv":1030.99,"id":67083366}]}]}
{"op":"mcm","clk":"11883750788","pt":1724073289026,"mc":[{"id":"1.232011465","rc":[{"batb":[[0,1.84,44.02],[1,1.52,7.76],[2,1.1,1000]],"ltp":1.93,"tv":1030.99,"id":67083366}]}]}
{"op":"mcm","clk":"11883750921","pt":1724073292839,"mc":[{"id":"1.232011465","rc":[{"batb":[[0,1.85,10],[1,1.84,44.02],[2,1.52,7.76]],"ltp":1.93,"tv":1030.99,"id":67083366}]}]}
{"op":"mcm","clk":"11883751024","pt":1724073296234,"mc":[{"id":"1.232011465","rc":[{"batb":[[0,1.84,44.02],[1,1.52,7.76],[2,1.1,1000]],"ltp":1.93,"tv":1030.99,"id":67083366}]}]}
{"op":"mcm","clk":"11883751115","pt":1724073300640,"mc":[{"id":"1.232011465","rc":[{"batb":[[0,1.85,10],[1,1.84,44.02],[2,1.52,7.76]],"ltp":1.93,"tv":1030.99,"id":67083366}]}]}
{"op":"mcm","clk":"11883751227","pt":1724073304346,"mc":[{"id":"1.232011465","rc":[{"batb":[[0,1.84,44.02],[1,1.52,7.76],[2,1.1,1000]],"ltp":1.93,"tv":1030.99,"id":67083366}]}]}
{"op":"mcm","clk":"11883751329","pt":1724073307655,"mc":[{"id":"1.232011465","rc":[{"batb":[[0,1.85,10],[1,1.84,44.02],[2,1.52,7.76]],"ltp":1.93,"tv":1030.99,"id":67083366}]}]}
{"op":"mcm","clk":"11883751420","pt":1724073310960,"mc":[{"id":"1.232011465","rc":[{"batb":[[0,1.84,44.02],[1,1.52,7.76],[2,1.1,1000]],"ltp":1.93,"tv":1030.99,"id":67083366}]}]}
{"op":"mcm","clk":"11883751484","pt":1724073313952,"mc":[{"id":"1.232011465","rc":[{"batb":[[0,1.85,10],[1,1.84,44.02],[2,1.52,7.76]],"ltp":1.93,"tv":1030.99,"id":67083366}]}]}
{"op":"mcm","clk":"11883751563","pt":1724073317351,"mc":[{"id":"1.232011465","rc":[{"batb":[[0,1.84,44.02],[1,1.52,7.76],[2,1.1,1000]],"ltp":1.93,"tv":1030.99,"id":67083366}]}]}
{"op":"mcm","clk":"11883751629","pt":1724073319764,"mc":[{"id":"1.232011465","rc":[{"batb":[[0,1.85,10],[1,1.84,44.02],[2,1.52,7.76]],"ltp":1.93,"tv":1030.99,"id":67083366}]}]}
{"op":"mcm","clk":"11883751766","pt":1724073323284,"mc":[{"id":"1.232011465","rc":[{"batb":[[0,1.84,44.02],[1,1.52,7.76],[2,1.1,1000]],"ltp":1.93,"tv":1030.99,"id":67083366}]}]}
{"op":"mcm","clk":"11883751866","pt":1724073325564,"mc":[{"id":"1.232011465","rc":[{"batb":[[0,1.85,10],[1,1.84,44.02],[2,1.52,7.76]],"ltp":1.93,"tv":1030.99,"id":67083366}]}]}
{"op":"mcm","clk":"11883752027","pt":1724073329003,"mc":[{"id":"1.232011465","rc":[{"batb":[[0,1.84,44.02],[1,1.52,7.76],[2,1.1,1000]],"ltp":1.93,"tv":1030.99,"id":67083366}]}]}
{"op":"mcm","clk":"11883752119","pt":1724073331778,"mc":[{"id":"1.232011465","rc":[{"batb":[[0,1.85,10],[1,1.84,44.02],[2,1.52,7.76]],"ltp":1.93,"tv":1030.99,"id":67083366}]}]}
{"op":"mcm","clk":"11883752212","pt":1724073335186,"mc":[{"id":"1.232011465","rc":[{"batb":[[0,1.84,44.02],[1,1.52,7.76],[2,1.1,1000]],"ltp":1.93,"tv":1030.99,"id":67083366}]}]}
{"op":"mcm","clk":"11883752244","pt":1724073336313,"mc":[{"id":"1.232011465","rc":[{"batb":[[0,1.85,8.52],[1,1.84,44.02],[2,1.52,7.76]],"ltp":1.93,"tv":1030.99,"id":67083366},{"batb":[[0,1.85,8.52],[1,1.1,1000],[2,1.03,200]],"ltp":2.08,"tv":1001.62,"id":72857115}]}]}
{"op":"mcm","clk":"11883752329","pt":1724073338988,"mc":[{"id":"1.232011465","rc":[{"batb":[[0,1.86,10],[1,1.85,8.52],[2,1.84,44.02]],"ltp":1.93,"tv":1030.99,"id":67083366}]}]}
{"op":"mcm","clk":"11883752398","pt":1724073342437,"mc":[{"id":"1.232011465","rc":[{"batb":[[0,1.85,8.52],[1,1.84,44.02],[2,1.52,7.76]],"ltp":1.93,"tv":1030.99,"id":67083366}]}]}
{"op":"mcm","clk":"11883752463","pt":1724073344708,"mc":[{"id":"1.232011465","rc":[{"batb":[[0,1.86,10],[1,1.85,8.52],[2,1.84,44.02]],"ltp":1.93,"tv":1030.99,"id":67083366}]}]}
{"op":"mcm","clk":"11883752579","pt":1724073348201,"mc":[{"id":"1.232011465","rc":[{"batb":[[0,1.85,8.52],[1,1.84,44.02],[2,1.52,7.76]],"ltp":1.93,"tv":1030.99,"id":67083366}]}]}
{"op":"mcm","clk":"11883752650","pt":1724073351435,"mc":[{"id":"1.232011465","rc":[{"batb":[[0,1.86,10],[1,1.85,8.52],[2,1.84,44.02]],"ltp":1.93,"tv":1030.99,"id":67083366}]}]}
{"op":"mcm","clk":"11883752728","pt":1724073354820,"mc":[{"id":"1.232011465","rc":[{"batb":[[0,1.85,8.52],[1,1.84,44.02],[2,1.52,7.76]],"ltp":1.93,"tv":1030.99,"id":67083366}]}]}
{"op":"mcm","clk":"11883752758","pt":1724073355534,"mc":[{"id":"1.232011465","rc":[{"batb":[[0,1.84,44.02],[1,1.82,8.64]],"ltp":1.93,"tv":1030.99,"id":67083366},{"batb":[[0,1.87,8.4]],"ltp":2.08,"tv":1001.62,"id":72857115}]}]}
{"op":"mcm","clk":"11883752795","pt":1724073357530,"mc":[{"id":"1.232011465","rc":[{"batb":[[0,1.85,10],[1,1.84,44.02],[2,1.82,8.64]],"ltp":1.93,"tv":1030.99,"id":67083366}]}]}
{"op":"mcm","clk":"11883752875","pt":1724073360821,"mc":[{"id":"1.232011465","rc":[{"batb":[[0,1.84,44.02],[1,1.82,8.64],[2,1.52,7.76]],"ltp":1.93,"tv":1030.99,"id":67083366}]}]}
{"op":"mcm","clk":"11883752945","pt":1724073363219,"mc":[{"id":"1.232011465","rc":[{"batb":[[0,1.85,10],[1,1.84,44.02],[2,1.82,8.64]],"ltp":1.93,"tv":1030.99,"id":67083366}]}]}
{"op":"mcm","clk":"11883753054","pt":1724073366513,"mc":[{"id":"1.232011465","rc":[{"batb":[[0,1.84,44.02],[1,1.82,8.64],[2,1.52,7.76]],"ltp":1.93,"tv":1030.99,"id":67083366}]}]}
{"op":"mcm","clk":"11883753230","pt":1724073371956,"mc":[{"id":"1.232011465","rc":[{"batb":[[0,1.85,10],[1,1.84,44.02],[2,1.82,8.64]],"ltp":1.93,"tv":1030.99,"id":67083366}]}]}
{"op":"mcm","clk":"11883753369","pt":1724073375355,"mc":[{"id":"1.232011465","rc":[{"batb":[[0,1.84,44.02],[1,1.82,8.64],[2,1.52,7.76]],"ltp":1.93,"tv":1030.99,"id":67083366}]}]}
{"op":"mcm","clk":"11883753456","pt":1724073378134,"mc":[{"id":"1.232011465","rc":[{"batb":[[0,1.85,10],[1,1.84,44.02],[2,1.82,8.64]],"ltp":1.93,"tv":1030.99,"id":67083366}]}]}
{"op":"mcm","clk":"11883753554","pt":1724073381643,"mc":[{"id":"1.232011465","rc":[{"batb":[[0,1.84,44.02],[1,1.82,8.64],[2,1.52,7.76]],"ltp":1.93,"tv":1030.99,"id":67083366}]}]}
{"op":"mcm","clk":"11883753611","pt":1724073383948,"mc":[{"id":"1.232011465","rc":[{"batb":[[0,1.85,10],[1,1.84,44.02],[2,1.82,8.64]],"ltp":1.93,"tv":1030.99,"id":67083366},{"batb":[[0,1.88,41.89],[1,1.87,8.4],[2,1.1,1000]],"ltp":2.08,"tv":1001.62,"id":72857115}]}]}
{"op":"mcm","clk":"11883753705","pt":1724073387140,"mc":[{"id":"1.232011465","rc":[{"batb":[[0,1.84,44.02],[1,1.82,8.64],[2,1.52,7.76]],"ltp":1.93,"tv":1030.99,"id":67083366}]}]}
{"op":"mcm","clk":"11883753785","pt":1724073389656,"mc":[{"id":"1.232011465","rc":[{"batb":[[0,1.85,10],[1,1.84,44.02],[2,1.82,8.64]],"ltp":1.93,"tv":1030.99,"id":67083366}]}]}
{"op":"mcm","clk":"11883753889","pt":1724073393044,"mc":[{"id":"1.232011465","rc":[{"batb":[[0,1.84,44.02],[1,1.82,8.64],[2,1.52,7.76]],"ltp":1.93,"tv":1030.99,"id":67083366}]}]}
{"op":"mcm","clk":"11883754034","pt":1724073397355,"mc":[{"id":"1.232011465","rc":[{"batb":[[0,1.85,10],[1,1.84,44.02],[2,1.82,8.64]],"ltp":1.93,"tv":1030.99,"id":67083366}]}]}
{"op":"mcm","clk":"11883754132","pt":1724073400760,"mc":[{"id":"1.232011465","rc":[{"batb":[[0,1.84,44.02],[1,1.82,8.64],[2,1.52,7.76]],"ltp":1.93,"tv":1030.99,"id":67083366}]}]}
{"op":"mcm","clk":"11883754223","pt":1724073403591,"mc":[{"id":"1.232011465","rc":[{"batb":[[0,1.85,10],[1,1.84,44.02],[2,1.82,8.64]],"ltp":1.93,"tv":1030.99,"id":67083366}]}]}
{"op":"mcm","clk":"11883754342","pt":1724073407168,"mc":[{"id":"1.232011465","rc":[{"batb":[[0,1.84,44.02],[1,1.82,8.64],[2,1.52,7.76]],"ltp":1.93,"tv":1030.99,"id":67083366}]}]}
{"op":"mcm","clk":"11883754408","pt":1724073409486,"mc":[{"id":"1.232011465","rc":[{"batb":[[0,1.85,10],[1,1.84,44.02],[2,1.82,8.64]],"ltp":1.93,"tv":1030.99,"id":67083366}]}]}
{"op":"mcm","clk":"11883754548","pt":1724073413091,"mc":[{"id":"1.232011465","rc":[{"batb":[[0,1.84,44.02],[1,1.82,8.64],[2,1.52,7.76]],"ltp":1.93,"tv":1030.99,"id":67083366}]}]}
{"op":"mcm","clk":"11883754651","pt":1724073416388,"mc":[{"id":"1.232011465","rc":[{"batb":[[0,1.85,10],[1,1.84,44.02],[2,1.82,8.64]],"ltp":1.93,"tv":1030.99,"id":67083366}]}]}
{"op":"mcm","clk":"11883754763","pt":1724073419890,"mc":[{"id":"1.232011465","rc":[{"batb":[[0,1.84,44.02],[1,1.82,8.64],[2,1.52,7.76]],"ltp":1.93,"tv":1030.99,"id":67083366}]}]}
{"op":"mcm","clk":"11883754950","pt":1724073426078,"mc":[{"id":"1.232011465","rc":[{"batb":[[0,1.89,83.77],[1,1.88,41.89],[2,1.87,8.4]],"ltp":2.08,"tv":1001.62,"id":72857115}]}]}
{"op":"mcm","clk":"11883755054","pt":1724073429007,"mc":[{"id":"1.232011465","rc":[{"batb":[[0,1.85,10],[1,1.84,44.02],[2,1.82,8.64]],"ltp":1.93,"tv":1030.99,"id":67083366}]}]}
{"op":"mcm","clk":"11883755215","pt":1724073433610,"mc":[{"id":"1.232011465","rc":[{"batb":[[0,1.84,44.02],[1,1.82,8.64],[2,1.52,7.76]],"ltp":1.93,"tv":1030.99,"id":67083366}]}]}
{"op":"mcm","clk":"11883755304","pt":1724073436706,"mc":[{"id":"1.232011465","rc":[{"batb":[[0,1.85,10],[1,1.84,44.02],[2,1.82,8.64]],"ltp":1.93,"tv":1030.99,"id":67083366}]}]}
{"op":"mcm","clk":"11883755404","pt":1724073440005,"mc":[{"id":"1.232011465","rc":[{"batb":[[0,1.84,44.02],[1,1.82,8.64],[2,1.52,7.76]],"ltp":1.93,"tv":1030.99,"id":67083366}]}]}
{"op":"mcm","clk":"11883755513","pt":1724073443430,"mc":[{"id":"1.232011465","rc":[{"batb":[[0,1.88,41.89],[1,1.87,8.4],[2,1.1,1000]],"ltp":2.08,"tv":1001.62,"id":72857115}]}]}
{"op":"mcm","clk":"11883755515","pt":1724073443534,"mc":[{"id":"1.232011465","rc":[{"batb":[[0,1.85,10],[1,1.84,44.02],[2,1.82,8.64]],"ltp":1.93,"tv":1030.99,"id":67083366}]}]}
{"op":"mcm","clk":"11883755601","pt":1724073446858,"mc":[{"id":"1.232011465","rc":[{"batb":[[0,1.84,44.02],[1,1.82,8.64],[2,1.52,7.76]],"ltp":1.93,"tv":1030.99,"id":67083366}]}]}
{"op":"mcm","clk":"11883756035","pt":1724073461466,"mc":[{"id":"1.232011465","rc":[{"batb":[[0,1.85,10],[1,1.84,44.02],[2,1.82,8.64]],"ltp":1.93,"tv":1030.99,"id":67083366}]}]}
{"op":"mcm","clk":"11883756122","pt":1724073465071,"mc":[{"id":"1.232011465","rc":[{"batb":[[0,1.84,44.02],[1,1.82,8.64],[2,1.52,7.76]],"ltp":1.93,"tv":1030.99,"id":67083366}]}]}
{"op":"mcm","clk":"11883756178","pt":1724073467743,"mc":[{"id":"1.232011465","rc":[{"batb":[[0,1.85,10],[1,1.84,44.02],[2,1.82,8.64]],"ltp":1.93,"tv":1030.99,"id":67083366}]}]}
{"op":"mcm","clk":"11883756265","pt":1724073471252,"mc":[{"id":"1.232011465","rc":[{"batb":[[0,1.84,44.02],[1,1.82,8.64],[2,1.52,7.76]],"ltp":1.93,"tv":1030.99,"id":67083366}]}]}
{"op":"mcm","clk":"11883756377","pt":1724073475149,"mc":[{"id":"1.232011465","rc":[{"batb":[[0,1.85,10],[1,1.84,44.02],[2,1.82,8.64]],"ltp":1.93,"tv":1030.99,"id":67083366}]}]}
{"op":"mcm","clk":"11883756463","pt":1724073478755,"mc":[{"id":"1.232011465","rc":[{"batb":[[0,1.84,44.02],[1,1.82,8.64],[2,1.52,7.76]],"ltp":1.93,"tv":1030.99,"id":67083366}]}]}
{"op":"mcm","clk":"11883756583","pt":1724073482983,"mc":[{"id":"1.232011465","rc":[{"batb":[[0,1.85,10],[1,1.84,44.02],[2,1.82,8.64]],"ltp":1.93,"tv":1030.99,"id":67083366}]}]}
{"op":"mcm","clk":"11883756683","pt":1724073486268,"mc":[{"id":"1.232011465","rc":[{"batb":[[0,1.84,44.02],[1,1.82,8.64],[2,1.52,7.76]],"ltp":1.93,"tv":1030.99,"id":67083366}]}]}
{"op":"mcm","clk":"11883756837","pt":1724073489807,"mc":[{"id":"1.232011465","rc":[{"batb":[[0,1.85,10],[1,1.84,44.02],[2,1.82,8.64]],"ltp":1.93,"tv":1030.99,"id":67083366}]}]}
{"op":"mcm","clk":"11883756965","pt":1724073493090,"mc":[{"id":"1.232011465","rc":[{"batb":[[0,1.84,44.02],[1,1.82,8.64],[2,1.52,7.76]],"ltp":1.93,"tv":1030.99,"id":67083366}]}]}
{"op":"mcm","clk":"11883757212","pt":1724073499203,"mc":[{"id":"1.232011465","rc":[{"batb":[[0,1.85,10],[1,1.84,44.02],[2,1.82,8.64]],"ltp":1.93,"tv":1030.99,"id":67083366}]}]}
{"op":"mcm","clk":"11883757342","pt":1724073502802,"mc":[{"id":"1.232011465","rc":[{"batb":[[0,1.84,44.02],[1,1.82,8.64],[2,1.52,7.76]],"ltp":1.93,"tv":1030.99,"id":67083366}]}]}
{"op":"mcm","clk":"11883757450","pt":1724073505582,"mc":[{"id":"1.232011465","rc":[{"batb":[[0,1.85,10],[1,1.84,44.02],[2,1.82,8.64]],"ltp":1.93,"tv":1030.99,"id":67083366}]}]}
{"op":"mcm","clk":"11883757553","pt":1724073508810,"mc":[{"id":"1.232011465","rc":[{"batb":[[0,1.84,44.02],[1,1.82,8.64],[2,1.52,7.76]],"ltp":1.93,"tv":1030.99,"id":67083366}]}]}
{"op":"mcm","clk":"11883757626","pt":1724073511009,"mc":[{"id":"1.232011465","rc":[{"batb":[[0,1.85,10],[1,1.84,44.02],[2,1.82,8.64]],"ltp":1.93,"tv":1030.99,"id":67083366}]}]}
{"op":"mcm","clk":"11883757732","pt":1724073514494,"mc":[{"id":"1.232011465","rc":[{"batb":[[0,1.84,44.02],[1,1.82,8.64],[2,1.52,7.76]],"ltp":1.93,"tv":1030.99,"id":67083366}]}]}
{"op":"mcm","clk":"11883757892","pt":1724073519110,"mc":[{"id":"1.232011465","rc":[{"batb":[[0,1.85,10],[1,1.84,44.02],[2,1.82,8.64]],"ltp":1.93,"tv":1030.99,"id":67083366}]}]}
{"op":"mcm","clk":"11883758018","pt":1724073522506,"mc":[{"id":"1.232011465","rc":[{"batb":[[0,1.84,44.02],[1,1.82,8.64],[2,1.52,7.76]],"ltp":1.93,"tv":1030.99,"id":67083366}]}]}
{"op":"mcm","clk":"11883758143","pt":1724073525844,"mc":[{"id":"1.232011465","rc":[{"batb":[[0,1.85,10],[1,1.84,44.02],[2,1.82,8.64]],"ltp":1.93,"tv":1030.99,"id":67083366}]}]}
{"op":"mcm","clk":"11883758247","pt":1724073529232,"mc":[{"id":"1.232011465","rc":[{"batb":[[0,1.84,44.02],[1,1.82,8.64],[2,1.52,7.76]],"ltp":1.93,"tv":1030.99,"id":67083366}]}]}
{"op":"mcm","clk":"11883758334","pt":1724073531542,"mc":[{"id":"1.232011465","rc":[{"batb":[[0,1.85,10],[1,1.84,44.02],[2,1.82,8.64]],"ltp":1.93,"tv":1030.99,"id":67083366}]}]}
{"op":"mcm","clk":"11883758469","pt":1724073535040,"mc":[{"id":"1.232011465","rc":[{"batb":[[0,1.84,44.02],[1,1.82,8.64],[2,1.52,7.76]],"ltp":1.93,"tv":1030.99,"id":67083366}]}]}
{"op":"mcm","clk":"11883758586","pt":1724073538123,"mc":[{"id":"1.232011465","rc":[{"batb":[[0,1.85,10],[1,1.84,44.02],[2,1.82,8.64]],"ltp":1.93,"tv":1030.99,"id":67083366}]}]}
{"op":"mcm","clk":"11883758706","pt":1724073541515,"mc":[{"id":"1.232011465","rc":[{"batb":[[0,1.84,44.02],[1,1.82,8.64],[2,1.52,7.76]],"ltp":1.93,"tv":1030.99,"id":67083366}]}]}
{"op":"mcm","clk":"11883758789","pt":1724073544758,"mc":[{"id":"1.232011465","rc":[{"batb":[[0,1.85,10],[1,1.84,44.02],[2,1.82,8.64]],"ltp":1.93,"tv":1030.99,"id":67083366}]}]}
{"op":"mcm","clk":"11883758892","pt":1724073548046,"mc":[{"id":"1.232011465","rc":[{"batb":[[0,1.84,44.02],[1,1.82,8.64],[2,1.52,7.76]],"ltp":1.93,"tv":1030.99,"id":67083366}]}]}
{"op":"mcm","clk":"11883759120","pt":1724073554644,"mc":[{"id":"1.232011465","rc":[{"batb":[[0,1.85,10],[1,1.84,44.02],[2,1.82,8.64]],"ltp":1.93,"tv":1030.99,"id":67083366}]}]}
{"op":"mcm","clk":"11883759241","pt":1724073558160,"mc":[{"id":"1.232011465","rc":[{"batb":[[0,1.84,44.02],[1,1.82,8.64],[2,1.52,7.76]],"ltp":1.93,"tv":1030.99,"id":67083366}]}]}
{"op":"mcm","clk":"11883759345","pt":1724073560974,"mc":[{"id":"1.232011465","rc":[{"batb":[[0,1.85,10],[1,1.84,44.02],[2,1.82,8.64]],"ltp":1.93,"tv":1030.99,"id":67083366}]}]}
{"op":"mcm","clk":"11883759428","pt":1724073564162,"mc":[{"id":"1.232011465","rc":[{"batb":[[0,1.84,44.02],[1,1.82,8.64],[2,1.52,7.76]],"ltp":1.93,"tv":1030.99,"id":67083366}]}]}
{"op":"mcm","clk":"11883759516","pt":1724073567557,"mc":[{"id":"1.232011465","rc":[{"batb":[[0,1.85,10],[1,1.84,44.02],[2,1.82,8.64]],"ltp":1.93,"tv":1030.99,"id":67083366}]}]}
{"op":"mcm","clk":"11883759621","pt":1724073571161,"mc":[{"id":"1.232011465","rc":[{"batb":[[0,1.84,44.02],[1,1.82,8.64],[2,1.52,7.76]],"ltp":1.93,"tv":1030.99,"id":67083366}]}]}
{"op":"mcm","clk":"11883759722","pt":1724073574092,"mc":[{"id":"1.232011465","rc":[{"batb":[[0,1.85,10],[1,1.84,44.02],[2,1.82,8.64]],"ltp":1.93,"tv":1030.99,"id":67083366},{"batb":[[2,1.03,200]],"ltp":2.08,"tv":1001.62,"id":72857115}]}]}
{"op":"mcm","clk":"11883759811","pt":1724073577083,"mc":[{"id":"1.232011465","rc":[{"batb":[[0,1.84,44.02],[1,1.82,8.64],[2,1.52,7.76]],"ltp":1.93,"tv":1030.99,"id":67083366}]}]}
{"op":"mcm","clk":"11883759926","pt":1724073581192,"mc":[{"id":"1.232011465","rc":[{"batb":[[0,1.85,10],[1,1.84,44.02],[2,1.82,8.64]],"ltp":1.93,"tv":1030.99,"id":67083366},{"batb":[[2,1.07,357.14]],"ltp":2.08,"tv":1001.62,"id":72857115}]}]}
{"op":"mcm","clk":"11883759978","pt":1724073582374,"mc":[{"id":"1.232011465","rc":[{"batb":[[2,1.33,151.52]],"ltp":2.08,"tv":1001.62,"id":72857115}]}]}
{"op":"mcm","clk":"11883759987","pt":1724073582578,"mc":[{"id":"1.232011465","rc":[{"batb":[[2,1.43,116.28]],"ltp":2.08,"tv":1001.62,"id":72857115}]}]}
{"op":"mcm","clk":"11883760040","pt":1724073584582,"mc":[{"id":"1.232011465","rc":[{"batb":[[0,1.84,44.02],[1,1.82,8.64],[2,1.52,7.76]],"ltp":1.93,"tv":1030.99,"id":67083366}]}]}
{"op":"mcm","clk":"11883760219","pt":1724073589985,"mc":[{"id":"1.232011465","rc":[{"batb":[[0,1.85,10],[1,1.84,44.02],[2,1.82,8.64]],"ltp":1.93,"tv":1030.99,"id":67083366}]}]}
{"op":"mcm","clk":"11883760315","pt":1724073593380,"mc":[{"id":"1.232011465","rc":[{"batb":[[0,1.84,44.02],[1,1.82,8.64],[2,1.52,7.76]],"ltp":1.93,"tv":1030.99,"id":67083366}]}]}
{"op":"mcm","clk":"11883760381","pt":1724073595795,"mc":[{"id":"1.232011465","rc":[{"batb":[[0,1.85,10],[1,1.84,44.02],[2,1.82,8.64]],"ltp":1.93,"tv":1030.99,"id":67083366}]}]}
{"op":"mcm","clk":"11883760488","pt":1724073599234,"mc":[{"id":"1.232011465","rc":[{"batb":[[0,1.84,44.02],[1,1.82,8.64],[2,1.52,7.76]],"ltp":1.93,"tv":1030.99,"id":67083366}]}]}
{"op":"mcm","clk":"11883760637","pt":1724073603930,"mc":[{"id":"1.232011465","rc":[{"batb":[[0,1.85,10],[1,1.84,44.02],[2,1.82,8.64]],"ltp":1.93,"tv":1030.99,"id":67083366}]}]}
{"op":"mcm","clk":"11883760744","pt":1724073607313,"mc":[{"id":"1.232011465","rc":[{"batb":[[0,1.84,44.02],[1,1.82,8.64],[2,1.52,7.76]],"ltp":1.93,"tv":1030.99,"id":67083366}]}]}
{"op":"mcm","clk":"11883760866","pt":1724073611130,"mc":[{"id":"1.232011465","rc":[{"batb":[[0,1.85,10],[1,1.84,44.02],[2,1.82,8.64]],"ltp":1.93,"tv":1030.99,"id":67083366}]}]}
{"op":"mcm","clk":"11883760982","pt":1724073614667,"mc":[{"id":"1.232011465","rc":[{"batb":[[0,1.84,44.02],[1,1.82,8.64],[2,1.52,7.76]],"ltp":1.93,"tv":1030.99,"id":67083366}]}]}
{"op":"mcm","clk":"11883761093","pt":1724073617655,"mc":[{"id":"1.232011465","rc":[{"batb":[[0,1.85,10],[1,1.84,44.02],[2,1.82,8.64]],"ltp":1.93,"tv":1030.99,"id":67083366}]}]}
{"op":"mcm","clk":"11883761191","pt":1724073621151,"mc":[{"id":"1.232011465","rc":[{"batb":[[0,1.84,44.02],[1,1.82,8.64],[2,1.52,7.76]],"ltp":1.93,"tv":1030.99,"id":67083366}]}]}
{"op":"mcm","clk":"11883761320","pt":1724073625167,"mc":[{"id":"1.232011465","rc":[{"batb":[[0,1.85,10],[1,1.84,44.02],[2,1.82,8.64]],"ltp":1.93,"tv":1030.99,"id":67083366}]}]}
{"op":"mcm","clk":"11883761430","pt":1724073628772,"mc":[{"id":"1.232011465","rc":[{"batb":[[0,1.84,44.02],[1,1.82,8.64],[2,1.52,7.76]],"ltp":1.93,"tv":1030.99,"id":67083366}]}]}
{"op":"mcm","clk":"11883761527","pt":1724073632266,"mc":[{"id":"1.232011465","rc":[{"batb":[[0,1.85,10],[1,1.84,44.02],[2,1.82,8.64]],"ltp":1.93,"tv":1030.99,"id":67083366}]}]}
{"op":"mcm","clk":"11883761609","pt":1724073635873,"mc":[{"id":"1.232011465","rc":[{"batb":[[0,1.84,44.02],[1,1.82,8.64],[2,1.52,7.76]],"ltp":1.93,"tv":1030.99,"id":67083366}]}]}
{"op":"mcm","clk":"11883761703","pt":1724073639275,"mc":[{"id":"1.232011465","rc":[{"batb":[[0,1.85,10],[1,1.84,44.02],[2,1.82,8.64]],"ltp":1.93,"tv":1030.99,"id":67083366}]}]}
{"op":"mcm","clk":"11883761807","pt":1724073642663,"mc":[{"id":"1.232011465","rc":[{"batb":[[0,1.84,44.02],[1,1.82,8.64],[2,1.52,7.76]],"ltp":1.93,"tv":1030.99,"id":67083366}]}]}
{"op":"mcm","clk":"11883762035","pt":1724073649905,"mc":[{"id":"1.232011465","rc":[{"batb":[[0,1.85,10],[1,1.84,44.02],[2,1.82,8.64]],"ltp":1.93,"tv":1030.99,"id":67083366}]}]}
{"op":"mcm","clk":"11883762158","pt":1724073653608,"mc":[{"id":"1.232011465","rc":[{"batb":[[0,1.84,44.02],[1,1.82,8.64],[2,1.52,7.76]],"ltp":1.93,"tv":1030.99,"id":67083366}]}]}
{"op":"mcm","clk":"11883762292","pt":1724073657515,"mc":[{"id":"1.232011465","rc":[{"batb":[[0,1.85,10],[1,1.84,44.02],[2,1.82,8.64]],"ltp":1.93,"tv":1030.99,"id":67083366}]}]}
{"op":"mcm","clk":"11883762435","pt":1724073661111,"mc":[{"id":"1.232011465","rc":[{"batb":[[0,1.84,44.02],[1,1.82,8.64],[2,1.52,7.76]],"ltp":1.93,"tv":1030.99,"id":67083366}]}]}
{"op":"mcm","clk":"11883762607","pt":1724073668206,"mc":[{"id":"1.232011465","rc":[{"batb":[[0,1.85,10],[1,1.84,44.02],[2,1.82,8.64]],"ltp":1.93,"tv":1030.99,"id":67083366}]}]}
{"op":"mcm","clk":"11883762701","pt":1724073671644,"mc":[{"id":"1.232011465","rc":[{"batb":[[0,1.84,44.02],[1,1.82,8.64],[2,1.52,7.76]],"ltp":1.93,"tv":1030.99,"id":67083366}]}]}
{"op":"mcm","clk":"11883763014","pt":1724073682046,"mc":[{"id":"1.232011465","rc":[{"batb":[[0,1.85,10],[1,1.84,44.02],[2,1.82,8.64]],"ltp":1.93,"tv":1030.99,"id":67083366}]}]}
{"op":"mcm","clk":"11883763134","pt":1724073685635,"mc":[{"id":"1.232011465","rc":[{"batb":[[0,1.84,44.02],[1,1.82,8.64],[2,1.52,7.76]],"ltp":1.93,"tv":1030.99,"id":67083366}]}]}
{"op":"mcm","clk":"11883763251","pt":1724073689232,"mc":[{"id":"1.232011465","rc":[{"batb":[[0,1.85,10],[1,1.84,44.02],[2,1.82,8.64]],"ltp":1.93,"tv":1030.99,"id":67083366}]}]}
{"op":"mcm","clk":"11883763367","pt":1724073692773,"mc":[{"id":"1.232011465","rc":[{"batb":[[0,1.84,44.02],[1,1.82,8.64],[2,1.52,7.76]],"ltp":1.93,"tv":1030.99,"id":67083366}]}]}
{"op":"mcm","clk":"11883763461","pt":1724073695872,"mc":[{"id":"1.232011465","rc":[{"batb":[[0,1.85,10],[1,1.84,44.02],[2,1.82,8.64]],"ltp":1.93,"tv":1030.99,"id":67083366}]}]}
{"op":"mcm","clk":"11883763633","pt":1724073699159,"mc":[{"id":"1.232011465","rc":[{"batb":[[0,1.84,44.02],[1,1.82,8.64],[2,1.52,7.76]],"ltp":1.93,"tv":1030.99,"id":67083366}]}]}
{"op":"mcm","clk":"11883763745","pt":1724073701943,"mc":[{"id":"1.232011465","rc":[{"batb":[[0,1.86,10],[1,1.84,44.02],[2,1.82,8.64]],"ltp":1.93,"tv":1030.99,"id":67083366}]}]}
{"op":"mcm","clk":"11883763950","pt":1724073707058,"mc":[{"id":"1.232011465","rc":[{"batb":[[0,1.84,44.02],[1,1.82,8.64],[2,1.52,7.76]],"ltp":1.93,"tv":1030.99,"id":67083366}]}]}
{"op":"mcm","clk":"11883764079","pt":1724073711583,"mc":[{"id":"1.232011465","rc":[{"batb":[[0,1.85,10],[1,1.84,44.02],[2,1.82,8.64]],"ltp":1.93,"tv":1030.99,"id":67083366}]}]}
{"op":"mcm","clk":"11883764108","pt":1724073712466,"mc":[{"id":"1.232011465","rc":[{"batb":[[0,1.9,3.54],[1,1.88,41.89],[2,1.87,8.4]],"ltp":2.08,"tv":1001.62,"id":72857115}]}]}
{"op":"mcm","clk":"11883764181","pt":1724073715083,"mc":[{"id":"1.232011465","rc":[{"batb":[[0,1.84,44.02],[1,1.82,8.64],[2,1.52,7.76]],"ltp":1.93,"tv":1030.99,"id":67083366}]}]}
{"op":"mcm","clk":"11883764200","pt":1724073715697,"mc":[{"id":"1.232011465","rc":[{"batl":[[0,2.1,6.71],[1,2.48,4.65]],"ltp":1.93,"tv":1030.99,"id":67083366}]}]}
{"op":"mcm","clk":"11883764413","pt":1724073720899,"mc":[{"id":"1.232011465","rc":[{"batb":[[0,1.85,10],[1,1.84,44.02],[2,1.82,8.64]],"ltp":1.93,"tv":1030.99,"id":67083366}]}]}
{"op":"mcm","clk":"11883764504","pt":1724073722673,"mc":[{"id":"1.232011465","rc":[{"batb":[[0,1.92,3.54]],"ltp":2.08,"tv":1001.62,"id":72857115}]}]}
{"op":"mcm","clk":"11883764559","pt":1724073724113,"mc":[{"id":"1.232011465","rc":[{"batb":[[2,1.52,7.76]],"ltp":1.93,"tv":1030.99,"id":67083366},{"batb":[[2,1.43,116.28]],"ltp":2.08,"tv":1001.62,"id":72857115}]}]}
{"op":"mcm","clk":"11883764610","pt":1724073725711,"mc":[{"id":"1.232011465","rc":[{"batb":[[0,1.84,44.02],[1,1.52,7.76],[2,1.43,116.28]],"ltp":1.93,"tv":1030.99,"id":67083366}]}]}
{"op":"mcm","clk":"11883764907","pt":1724073733712,"mc":[{"id":"1.232011465","rc":[{"batb":[[0,1.85,10],[1,1.84,44.02],[2,1.52,7.76]],"ltp":1.93,"tv":1030.99,"id":67083366}]}]}
{"op":"mcm","clk":"11883765041","pt":1724073737211,"mc":[{"id":"1.232011465","rc":[{"batb":[[0,1.84,44.02],[1,1.52,7.76],[2,1.43,116.28]],"ltp":1.93,"tv":1030.99,"id":67083366}]}]}
{"op":"mcm","clk":"11883765152","pt":1724073740305,"mc":[{"id":"1.232011465","rc":[{"batb":[[0,1.85,10],[1,1.84,44.02],[2,1.52,7.76]],"ltp":1.93,"tv":1030.99,"id":67083366}]}]}
{"op":"mcm","clk":"11883765169","pt":1724073740619,"mc":[{"id":"1.232011465","rc":[{"batb":[[0,1.88,41.89],[1,1.43,116.28],[2,1.38,131.58]],"ltp":2.08,"tv":1001.62,"id":72857115}]}]}
{"op":"mcm","clk":"11883765275","pt":1724073743712,"mc":[{"id":"1.232011465","rc":[{"batb":[[0,1.84,44.02],[1,1.52,7.76],[2,1.43,116.28]],"ltp":1.93,"tv":1030.99,"id":67083366}]}]}
{"op":"mcm","clk":"11883765423","pt":1724073747003,"mc":[{"id":"1.232011465","rc":[{"batb":[[0,1.85,10],[1,1.84,44.02],[2,1.52,7.76]],"ltp":1.93,"tv":1030.99,"id":67083366}]}]}
{"op":"mcm","clk":"11883765511","pt":1724073749419,"mc":[{"id":"1.232011465","rc":[{"batb":[[2,1.82,8.66]],"ltp":1.93,"tv":1030.99,"id":67083366},{"batb":[[0,1.88,50.28]],"ltp":2.08,"tv":1001.62,"id":72857115}]}]}
{"op":"mcm","clk":"11883765541","pt":1724073750337,"mc":[{"id":"1.232011465","rc":[{"batb":[[0,1.84,44.02],[1,1.82,8.66],[2,1.52,7.76]],"ltp":1.93,"tv":1030.99,"id":67083366}]}]}
{"op":"mcm","clk":"11883765858","pt":1724073758316,"mc":[{"id":"1.232011465","rc":[{"batb":[[0,1.85,10],[1,1.84,44.02],[2,1.82,8.66]],"ltp":1.93,"tv":1030.99,"id":67083366}]}]}
{"op":"mcm","clk":"11883765968","pt":1724073761615,"mc":[{"id":"1.232011465","rc":[{"batb":[[0,1.84,44.02],[1,1.82,8.66],[2,1.52,7.76]],"ltp":1.93,"tv":1030.99,"id":67083366}]}]}
{"op":"mcm","clk":"11883766071","pt":1724073764914,"mc":[{"id":"1.232011465","rc":[{"batb":[[0,1.85,10],[1,1.84,44.02],[2,1.82,8.66]],"ltp":1.93,"tv":1030.99,"id":67083366}]}]}
{"op":"mcm","clk":"11883766166","pt":1724073768356,"mc":[{"id":"1.232011465","rc":[{"batb":[[0,1.84,44.02],[1,1.82,8.66],[2,1.52,7.76]],"ltp":1.93,"tv":1030.99,"id":67083366}]}]}
{"op":"mcm","clk":"11883766368","pt":1724073774838,"mc":[{"id":"1.232011465","rc":[{"batb":[[0,1.85,10],[1,1.84,44.02],[2,1.82,8.66]],"ltp":1.93,"tv":1030.99,"id":67083366}]}]}
{"op":"mcm","clk":"11883766488","pt":1724073778247,"mc":[{"id":"1.232011465","rc":[{"batb":[[0,1.84,44.02],[1,1.82,8.66],[2,1.52,7.76]],"ltp":1.93,"tv":1030.99,"id":67083366}]}]}
{"op":"mcm","clk":"11883766585","pt":1724073781659,"mc":[{"id":"1.232011465","rc":[{"batb":[[0,1.85,10],[1,1.84,44.02],[2,1.82,8.66]],"ltp":1.93,"tv":1030.99,"id":67083366},{"batb":[[0,1.89,4.33],[1,1.88,50.28],[2,1.43,116.28]],"ltp":2.08,"tv":1001.62,"id":72857115}]}]}
{"op":"mcm","clk":"11883766677","pt":1724073784076,"mc":[{"id":"1.232011465","rc":[{"batb":[[0,1.88,50.28],[1,1.43,116.28],[2,1.38,131.58]],"ltp":2.08,"tv":1001.62,"id":72857115}]}]}
{"op":"mcm","clk":"11883766705","pt":1724073785262,"mc":[{"id":"1.232011465","rc":[{"batb":[[0,1.84,44.02],[1,1.82,8.66],[2,1.52,7.76]],"ltp":1.93,"tv":1030.99,"id":67083366}]}]}
{"op":"mcm","clk":"11883766831","pt":1724073788456,"mc":[{"id":"1.232011465","rc":[{"batb":[[0,1.85,10],[1,1.84,44.02],[2,1.82,8.66]],"ltp":1.93,"tv":1030.99,"id":67083366}]}]}
{"op":"mcm","clk":"11883766980","pt":1724073791963,"mc":[{"id":"1.232011465","rc":[{"batb":[[0,1.84,44.02],[1,1.82,8.66],[2,1.52,7.76]],"ltp":1.93,"tv":1030.99,"id":67083366}]}]}
{"op":"mcm","clk":"11883767090","pt":1724073795287,"mc":[{"id":"1.232011465","rc":[{"batb":[[0,1.85,10],[1,1.84,44.02],[2,1.8,8.75]],"ltp":1.93,"tv":1030.99,"id":67083366},{"batb":[[0,1.9,8.29],[1,1.88,41.89],[2,1.43,116.28]],"ltp":2.08,"tv":1001.62,"id":72857115}]}]}
{"op":"mcm","clk":"11883767177","pt":1724073798480,"mc":[{"id":"1.232011465","rc":[{"batb":[[0,1.84,44.02],[1,1.8,8.75],[2,1.52,7.76]],"ltp":1.93,"tv":1030.99,"id":67083366}]}]}
{"op":"mcm","clk":"11883767618","pt":1724073810104,"mc":[{"id":"1.232011465","rc":[{"batb":[[0,1.85,10],[1,1.84,44.02],[2,1.8,8.75]],"ltp":1.93,"tv":1030.99,"id":67083366}]}]}
{"op":"mcm","clk":"11883767739","pt":1724073813697,"mc":[{"id":"1.232011465","rc":[{"batb":[[0,1.84,44.02],[1,1.8,8.75],[2,1.52,7.76]],"ltp":1.93,"tv":1030.99,"id":67083366}]}]}
{"op":"mcm","clk":"11883768079","pt":1724073824092,"mc":[{"id":"1.232011465","rc":[{"batb":[[0,1.85,10],[1,1.84,44.02],[2,1.8,8.75]],"ltp":1.93,"tv":1030.99,"id":67083366}]}]}
{"op":"mcm","clk":"11883768203","pt":1724073827524,"mc":[{"id":"1.232011465","rc":[{"batb":[[0,1.84,44.02],[1,1.8,8.75],[2,1.52,7.76]],"ltp":1.93,"tv":1030.99,"id":67083366}]}]}
{"op":"mcm","clk":"11883768325","pt":1724073830705,"mc":[{"id":"1.232011465","rc":[{"batb":[[0,1.85,10],[1,1.84,44.02],[2,1.8,8.75]],"ltp":1.93,"tv":1030.99,"id":67083366}]}]}
{"op":"mcm","clk":"11883768448","pt":1724073834140,"mc":[{"id":"1.232011465","rc":[{"batb":[[0,1.84,44.02],[1,1.8,8.75],[2,1.52,7.76]],"ltp":1.93,"tv":1030.99,"id":67083366}]}]}
{"op":"mcm","clk":"11883768553","pt":1724073837220,"mc":[{"id":"1.232011465","rc":[{"batb":[[0,1.85,10],[1,1.84,44.02],[2,1.8,8.75]],"ltp":1.93,"tv":1030.99,"id":67083366}]}]}
{"op":"mcm","clk":"11883768688","pt":1724073840619,"mc":[{"id":"1.232011465","rc":[{"batb":[[0,1.84,44.02],[1,1.8,8.75],[2,1.52,7.76]],"ltp":1.93,"tv":1030.99,"id":67083366}]}]}
{"op":"mcm","clk":"11883769137","pt":1724073853453,"mc":[{"id":"1.232011465","rc":[{"batb":[[0,1.85,10],[1,1.84,44.02],[2,1.8,8.75]],"ltp":1.93,"tv":1030.99,"id":67083366}]}]}
{"op":"mcm","clk":"11883769235","pt":1724073856841,"mc":[{"id":"1.232011465","rc":[{"batb":[[0,1.84,44.02],[1,1.8,8.75],[2,1.52,7.76]],"ltp":1.93,"tv":1030.99,"id":67083366}]}]}
{"op":"mcm","clk":"11883769415","pt":1724073862178,"mc":[{"id":"1.232011465","rc":[{"batb":[[0,1.85,10],[1,1.84,44.02],[2,1.8,8.75]],"ltp":1.93,"tv":1030.99,"id":67083366}]}]}
{"op":"mcm","clk":"11883769519","pt":1724073865660,"mc":[{"id":"1.232011465","rc":[{"batb":[[0,1.84,44.02],[1,1.8,8.75],[2,1.52,7.76]],"ltp":1.93,"tv":1030.99,"id":67083366}]}]}
{"op":"mcm","clk":"11883769942","pt":1724073878704,"mc":[{"id":"1.232011465","rc":[{"batb":[[0,1.85,10],[1,1.84,44.02],[2,1.8,8.75]],"ltp":1.93,"tv":1030.99,"id":67083366}]}]}
{"op":"mcm","clk":"11883770030","pt":1724073882182,"mc":[{"id":"1.232011465","rc":[{"batb":[[0,1.84,44.02],[1,1.8,8.75],[2,1.52,7.76]],"ltp":1.93,"tv":1030.99,"id":67083366}]}]}
{"op":"mcm","clk":"11883770673","pt":1724073903100,"mc":[{"id":"1.232011465","rc":[{"batb":[[0,1.85,10],[1,1.84,44.02],[2,1.8,8.75]],"ltp":1.93,"tv":1030.99,"id":67083366}]}]}
{"op":"mcm","clk":"11883770798","pt":1724073906302,"mc":[{"id":"1.232011465","rc":[{"batb":[[0,1.84,44.02],[1,1.8,8.75],[2,1.52,7.76]],"ltp":1.93,"tv":1030.99,"id":67083366}]}]}
{"op":"mcm","clk":"11883771144","pt":1724073916026,"mc":[{"id":"1.232011465","rc":[{"batb":[[0,1.85,10],[1,1.84,44.02],[2,1.8,8.75]],"ltp":1.93,"tv":1030.99,"id":67083366}]}]}
{"op":"mcm","clk":"11883771283","pt":1724073919721,"mc":[{"id":"1.232011465","rc":[{"batb":[[0,1.84,44.02],[1,1.8,8.75],[2,1.52,7.76]],"ltp":1.93,"tv":1030.99,"id":67083366}]}]}
{"op":"mcm","clk":"11883771414","pt":1724073923023,"mc":[{"id":"1.232011465","rc":[{"batb":[[0,1.85,10],[1,1.84,44.02],[2,1.8,8.75]],"ltp":1.93,"tv":1030.99,"id":67083366}]}]}
{"op":"mcm","clk":"11883771560","pt":1724073927926,"mc":[{"id":"1.232011465","rc":[{"batb":[[0,1.84,44.02],[1,1.8,8.75],[2,1.52,7.76]],"ltp":1.93,"tv":1030.99,"id":67083366}]}]}
{"op":"mcm","clk":"11883771971","pt":1724073941078,"mc":[{"id":"1.232011465","rc":[{"batb":[[0,1.85,10],[1,1.84,44.02],[2,1.8,8.75]],"ltp":1.93,"tv":1030.99,"id":67083366}]}]}
{"op":"mcm","clk":"11883772091","pt":1724073944540,"mc":[{"id":"1.232011465","rc":[{"batb":[[0,1.84,44.02],[1,1.8,8.75],[2,1.52,7.76]],"ltp":1.93,"tv":1030.99,"id":67083366}]}]}
{"op":"mcm","clk":"11883773424","pt":1724073983324,"mc":[{"id":"1.232011465","rc":[{"batb":[[0,1.85,10],[1,1.84,44.02],[2,1.8,8.75]],"ltp":1.93,"tv":1030.99,"id":67083366}]}]}
{"op":"mcm","clk":"11883773549","pt":1724073986728,"mc":[{"id":"1.232011465","rc":[{"batb":[[0,1.84,44.02],[1,1.8,8.75],[2,1.52,7.76]],"ltp":1.93,"tv":1030.99,"id":67083366}]}]}
{"op":"mcm","clk":"11883774269","pt":1724074005718,"mc":[{"id":"1.232011465","rc":[{"batb":[[0,1.85,10],[1,1.84,44.02],[2,1.8,8.75]],"ltp":1.93,"tv":1030.99,"id":67083366}]}]}
{"op":"mcm","clk":"11883774380","pt":1724074009247,"mc":[{"id":"1.232011465","rc":[{"batb":[[0,1.84,44.02],[1,1.8,8.75],[2,1.52,7.76]],"ltp":1.93,"tv":1030.99,"id":67083366}]}]}
{"op":"mcm","clk":"11883774464","pt":1724074011725,"mc":[{"id":"1.232011465","rc":[{"batb":[[0,1.85,10],[1,1.84,44.02],[2,1.8,8.75]],"ltp":1.93,"tv":1030.99,"id":67083366}]}]}
{"op":"mcm","clk":"11883774594","pt":1724074015223,"mc":[{"id":"1.232011465","rc":[{"batb":[[0,1.84,44.02],[1,1.8,8.75],[2,1.52,7.76]],"ltp":1.93,"tv":1030.99,"id":67083366}]}]}
{"op":"mcm","clk":"11883775047","pt":1724074026261,"mc":[{"id":"1.232011465","rc":[{"batb":[[0,1.85,10],[1,1.84,44.02],[2,1.8,8.75]],"ltp":1.93,"tv":1030.99,"id":67083366}]}]}
{"op":"mcm","clk":"11883775189","pt":1724074029861,"mc":[{"id":"1.232011465","rc":[{"batb":[[0,1.84,44.02],[1,1.8,8.75],[2,1.52,7.76]],"ltp":1.93,"tv":1030.99,"id":67083366}]}]}
{"op":"mcm","clk":"11883775753","pt":1724074044380,"mc":[{"id":"1.232011465","rc":[{"batb":[[0,1.85,10],[1,1.84,44.02],[2,1.8,8.75]],"ltp":1.93,"tv":1030.99,"id":67083366}]}]}
{"op":"mcm","clk":"11883775870","pt":1724074047877,"mc":[{"id":"1.232011465","rc":[{"batb":[[0,1.84,44.02],[1,1.8,8.75],[2,1.52,7.76]],"ltp":1.93,"tv":1030.99,"id":67083366}]}]}
{"op":"mcm","clk":"11883776590","pt":1724074066600,"mc":[{"id":"1.232011465","rc":[{"batb":[[0,1.85,10],[1,1.84,44.02],[2,1.8,8.75]],"ltp":1.93,"tv":1030.99,"id":67083366}]}]}
{"op":"mcm","clk":"11883776734","pt":1724074070111,"mc":[{"id":"1.232011465","rc":[{"batb":[[0,1.84,44.02],[1,1.8,8.75],[2,1.52,7.76]],"ltp":1.93,"tv":1030.99,"id":67083366}]}]}
{"op":"mcm","clk":"11883780365","pt":1724074155683,"mc":[{"id":"1.232011465","rc":[{"trd":[[2.1,2]],"batb":[[0,1.85,10],[1,1.84,44.02],[2,1.8,8.75]],"batl":[[0,2.1,5.71]],"ltp":2.1,"tv":1032.99,"id":67083366}],"tv":2034.62}]}
{"op":"mcm","clk":"11883780505","pt":1724074159061,"mc":[{"id":"1.232011465","rc":[{"batb":[[0,1.84,44.02],[1,1.8,8.75],[2,1.52,7.76]],"ltp":2.1,"tv":1032.99,"id":67083366}]}]}
{"op":"mcm","clk":"11883781417","pt":1724074184392,"mc":[{"id":"1.232011465","rc":[{"batb":[[0,1.85,10],[1,1.84,44.02],[2,1.8,8.75]],"ltp":2.1,"tv":1032.99,"id":67083366},{"batb":[[1,1.43,116.28],[2,1.38,131.58]],"ltp":2.08,"tv":1001.62,"id":72857115}]}]}
{"op":"mcm","clk":"11883781536","pt":1724074187793,"mc":[{"id":"1.232011465","rc":[{"batb":[[0,1.84,44.02],[1,1.8,8.75],[2,1.52,7.76]],"ltp":2.1,"tv":1032.99,"id":67083366}]}]}
{"op":"mcm","clk":"11883782827","pt":1724074223576,"mc":[{"id":"1.232011465","rc":[{"batb":[[0,1.85,10],[1,1.84,44.02],[2,1.8,8.75]],"ltp":2.1,"tv":1032.99,"id":67083366}]}]}
{"op":"mcm","clk":"11883782972","pt":1724074226857,"mc":[{"id":"1.232011465","rc":[{"batb":[[0,1.84,44.02],[1,1.8,8.75],[2,1.52,7.76]],"ltp":2.1,"tv":1032.99,"id":67083366}]}]}
{"op":"mcm","clk":"11883784073","pt":1724074250971,"mc":[{"id":"1.232011465","rc":[{"batb":[[0,1.85,10],[1,1.84,44.02],[2,1.8,8.75]],"ltp":2.1,"tv":1032.99,"id":67083366}]}]}
{"op":"mcm","clk":"11883784184","pt":1724074254164,"mc":[{"id":"1.232011465","rc":[{"batb":[[0,1.84,44.02],[1,1.8,8.75],[2,1.52,7.76]],"ltp":2.1,"tv":1032.99,"id":67083366}]}]}
{"op":"mcm","clk":"11883784821","pt":1724074270389,"mc":[{"id":"1.232011465","rc":[{"batb":[[0,1.85,10],[1,1.84,44.02],[2,1.8,8.75]],"ltp":2.1,"tv":1032.99,"id":67083366}]}]}
{"op":"mcm","clk":"11883785017","pt":1724074275380,"mc":[{"id":"1.232011465","rc":[{"batb":[[0,1.84,44.02],[1,1.8,8.75],[2,1.52,7.76]],"ltp":2.1,"tv":1032.99,"id":67083366}]}]}
{"op":"mcm","clk":"11883785757","pt":1724074295715,"mc":[{"id":"1.232011465","rc":[{"batb":[[0,1.85,10],[1,1.84,44.02],[2,1.8,8.75]],"ltp":2.1,"tv":1032.99,"id":67083366}]}]}
{"op":"mcm","clk":"11883785883","pt":1724074299035,"mc":[{"id":"1.232011465","rc":[{"batb":[[0,1.84,44.02],[1,1.8,8.75],[2,1.52,7.76]],"ltp":2.1,"tv":1032.99,"id":67083366}]}]}
{"op":"mcm","clk":"11883786238","pt":1724074310320,"mc":[{"id":"1.232011465","rc":[{"batb":[[0,1.85,10],[1,1.84,44.02],[2,1.8,8.75]],"ltp":2.1,"tv":1032.99,"id":67083366}]}]}
{"op":"mcm","clk":"11883786380","pt":1724074314432,"mc":[{"id":"1.232011465","rc":[{"batb":[[0,1.84,44.02],[1,1.8,8.75],[2,1.52,7.76]],"ltp":2.1,"tv":1032.99,"id":67083366}]}]}
{"op":"mcm","clk":"11883787628","pt":1724074349074,"mc":[{"id":"1.232011465","rc":[{"batb":[[0,1.85,10],[1,1.84,44.02],[2,1.8,8.75]],"ltp":2.1,"tv":1032.99,"id":67083366}]}]}
{"op":"mcm","clk":"11883787758","pt":1724074352485,"mc":[{"id":"1.232011465","rc":[{"batb":[[0,1.84,44.02],[1,1.8,8.75],[2,1.52,7.76]],"ltp":2.1,"tv":1032.99,"id":67083366}]}]}
{"op":"mcm","clk":"11883788426","pt":1724074371613,"mc":[{"id":"1.232011465","rc":[{"trd":[[1.84,2]],"batb":[[0,1.85,10],[1,1.84,43.02],[2,1.8,8.75]],"ltp":1.84,"tv":1034.99,"id":67083366}],"tv":2036.62}]}
{"op":"mcm","clk":"11883788540","pt":1724074375219,"mc":[{"id":"1.232011465","rc":[{"batb":[[0,1.84,44.02],[1,1.8,8.75],[2,1.52,7.76]],"ltp":1.84,"tv":1034.99,"id":67083366}]}]}
{"op":"mcm","clk":"11883788856","pt":1724074384423,"mc":[{"id":"1.232011465","rc":[{"trd":[[2.1,4]],"batl":[[0,2.1,4.71]],"ltp":2.1,"tv":1036.99,"id":67083366}],"tv":2038.62}]}
{"op":"mcm","clk":"11883788941","pt":1724074386707,"mc":[{"id":"1.232011465","rc":[{"batb":[[0,1.85,10],[1,1.84,44.02],[2,1.8,8.75]],"ltp":2.1,"tv":1036.99,"id":67083366}]}]}
{"op":"mcm","clk":"11883789137","pt":1724074391921,"mc":[{"id":"1.232011465","rc":[{"batb":[[0,1.84,44.02],[1,1.8,8.75],[2,1.52,7.76]],"ltp":2.1,"tv":1036.99,"id":67083366}]}]}
{"op":"mcm","clk":"11883789744","pt":1724074408009,"mc":[{"id":"1.232011465","rc":[{"batb":[[0,1.85,10],[1,1.84,44.02],[2,1.8,8.75]],"ltp":2.1,"tv":1036.99,"id":67083366}]}]}
{"op":"mcm","clk":"11883789888","pt":1724074411646,"mc":[{"id":"1.232011465","rc":[{"batb":[[0,1.84,44.02],[1,1.8,8.75],[2,1.52,7.76]],"ltp":2.1,"tv":1036.99,"id":67083366}]}]}
{"op":"mcm","clk":"11883790191","pt":1724074419423,"mc":[{"id":"1.232011465","rc":[{"batb":[[0,1.85,10],[1,1.84,44.02],[2,1.8,8.75]],"ltp":2.1,"tv":1036.99,"id":67083366}]}]}
{"op":"mcm","clk":"11883790341","pt":1724074422661,"mc":[{"id":"1.232011465","rc":[{"batb":[[0,1.84,44.02],[1,1.8,8.75],[2,1.52,7.76]],"ltp":2.1,"tv":1036.99,"id":67083366}]}]}
{"op":"mcm","clk":"11883790724","pt":1724074430453,"mc":[{"id":"1.232011465","rc":[{"batb":[[0,1.85,10],[1,1.84,44.02],[2,1.8,8.75]],"ltp":2.1,"tv":1036.99,"id":67083366}]}]}
{"op":"mcm","clk":"11883790853","pt":1724074433957,"mc":[{"id":"1.232011465","rc":[{"batb":[[0,1.84,44.02],[1,1.8,8.75],[2,1.52,7.76]],"ltp":2.1,"tv":1036.99,"id":67083366}]}]}
{"op":"mcm","clk":"11883791035","pt":1724074437360,"mc":[{"id":"1.232011465","rc":[{"batb":[[0,1.85,10],[1,1.84,44.02],[2,1.8,8.75]],"ltp":2.1,"tv":1036.99,"id":67083366}]}]}
{"op":"mcm","clk":"11883791227","pt":1724074443042,"mc":[{"id":"1.232011465","rc":[{"batb":[[0,1.84,44.02],[1,1.8,8.75],[2,1.52,7.76]],"ltp":2.1,"tv":1036.99,"id":67083366}]}]}
{"op":"mcm","clk":"11883791313","pt":1724074445255,"mc":[{"id":"1.232011465","rc":[{"batb":[[0,1.85,10],[1,1.84,44.02],[2,1.8,8.75]],"ltp":2.1,"tv":1036.99,"id":67083366}]}]}
{"op":"mcm","clk":"11883791440","pt":1724074448759,"mc":[{"id":"1.232011465","rc":[{"batb":[[0,1.84,44.02],[1,1.8,8.75],[2,1.52,7.76]],"ltp":2.1,"tv":1036.99,"id":67083366}]}]}
{"op":"mcm","clk":"11883791785","pt":1724074458250,"mc":[{"id":"1.232011465","rc":[{"batb":[[0,1.85,10],[1,1.84,44.02],[2,1.8,8.75]],"ltp":2.1,"tv":1036.99,"id":67083366}]}]}
{"op":"mcm","clk":"11883791886","pt":1724074461692,"mc":[{"id":"1.232011465","rc":[{"batb":[[0,1.84,44.02],[1,1.8,8.75],[2,1.52,7.76]],"ltp":2.1,"tv":1036.99,"id":67083366}]}]}
{"op":"mcm","clk":"11883792181","pt":1724074473597,"mc":[{"id":"1.232011465","rc":[{"batb":[[0,1.85,10],[1,1.84,44.02],[2,1.8,8.75]],"ltp":2.1,"tv":1036.99,"id":67083366}]}]}
{"op":"mcm","clk":"11883792300","pt":1724074477197,"mc":[{"id":"1.232011465","rc":[{"batb":[[0,1.84,44.02],[1,1.8,8.75],[2,1.52,7.76]],"ltp":2.1,"tv":1036.99,"id":67083366}]}]}
{"op":"mcm","clk":"11883792657","pt":1724074489892,"mc":[{"id":"1.232011465","rc":[{"batb":[[0,1.85,10],[1,1.84,44.02],[2,1.8,8.75]],"ltp":2.1,"tv":1036.99,"id":67083366}]}]}
{"op":"mcm","clk":"11883792747","pt":1724074493284,"mc":[{"id":"1.232011465","rc":[{"batb":[[0,1.84,44.02],[1,1.8,8.75],[2,1.52,7.76]],"ltp":2.1,"tv":1036.99,"id":67083366}]}]}
{"op":"mcm","clk":"11883793401","pt":1724074515417,"mc":[{"id":"1.232011465","rc":[{"batb":[[0,1.84,96.02]],"ltp":2.1,"tv":1036.99,"id":67083366}]}]}
{"op":"mcm","clk":"11883793405","pt":1724074515519,"mc":[{"id":"1.232011465","rc":[{"batb":[[0,1.85,10],[1,1.84,52],[2,1.8,8.75]],"ltp":2.1,"tv":1036.99,"id":67083366}]}]}
{"op":"mcm","clk":"11883793498","pt":1724074518707,"mc":[{"id":"1.232011465","rc":[{"batb":[[0,1.84,52],[1,1.8,8.75],[2,1.52,7.76]],"ltp":2.1,"tv":1036.99,"id":67083366}]}]}
{"op":"mcm","clk":"11883793659","pt":1724074524919,"mc":[{"id":"1.232011465","rc":[{"trd":[[2.1,6]],"batb":[[0,1.85,10],[1,1.84,52],[2,1.8,8.75]],"batl":[[0,2.1,3.71]],"ltp":2.1,"tv":1038.99,"id":67083366}],"tv":2040.62}]}
{"op":"mcm","clk":"11883793765","pt":1724074528202,"mc":[{"id":"1.232011465","rc":[{"batb":[[0,1.84,52],[1,1.8,8.75],[2,1.52,7.76]],"ltp":2.1,"tv":1038.99,"id":67083366}]}]}
{"op":"mcm","clk":"11883794185","pt":1724074539912,"mc":[{"id":"1.232011465","rc":[{"batb":[[0,1.85,10],[1,1.84,52],[2,1.8,8.75]],"ltp":2.1,"tv":1038.99,"id":67083366}]}]}
{"op":"mcm","clk":"11883794314","pt":1724074543514,"mc":[{"id":"1.232011465","rc":[{"batb":[[0,1.84,52],[1,1.8,8.75],[2,1.52,7.76]],"ltp":2.1,"tv":1038.99,"id":67083366}]}]}
{"op":"mcm","clk":"11883794448","pt":1724074547930,"mc":[{"id":"1.232011465","rc":[{"batb":[[0,1.85,10],[1,1.84,52],[2,1.8,8.75]],"ltp":2.1,"tv":1038.99,"id":67083366}]}]}
{"op":"mcm","clk":"11883794538","pt":1724074551431,"mc":[{"id":"1.232011465","rc":[{"batb":[[0,1.84,52],[1,1.8,8.75],[2,1.52,7.76]],"ltp":2.1,"tv":1038.99,"id":67083366}]}]}
{"op":"mcm","clk":"11883794627","pt":1724074554598,"mc":[{"id":"1.232011465","rc":[{"batb":[[0,1.85,10],[1,1.84,52],[2,1.8,8.75]],"ltp":2.1,"tv":1038.99,"id":67083366}]}]}
{"op":"mcm","clk":"11883794705","pt":1724074557858,"mc":[{"id":"1.232011465","rc":[{"batb":[[0,1.84,52],[1,1.8,8.75],[2,1.52,7.76]],"ltp":2.1,"tv":1038.99,"id":67083366}]}]}
{"op":"mcm","clk":"11883795273","pt":1724074578451,"mc":[{"id":"1.232011465","rc":[{"batb":[[0,1.85,10],[1,1.84,52],[2,1.8,8.75]],"ltp":2.1,"tv":1038.99,"id":67083366}]}]}
{"op":"mcm","clk":"11883795396","pt":1724074582049,"mc":[{"id":"1.232011465","rc":[{"batb":[[0,1.84,52],[1,1.8,8.75],[2,1.52,7.76]],"ltp":2.1,"tv":1038.99,"id":67083366}]}]}
{"op":"mcm","clk":"11883795611","pt":1724074590970,"mc":[{"id":"1.232011465","rc":[{"batb":[[0,1.85,10],[1,1.84,52],[2,1.8,8.75]],"ltp":2.1,"tv":1038.99,"id":67083366}]}]}
{"op":"mcm","clk":"11883795700","pt":1724074594260,"mc":[{"id":"1.232011465","rc":[{"batb":[[0,1.84,52],[1,1.8,8.75],[2,1.52,7.76]],"ltp":2.1,"tv":1038.99,"id":67083366}]}]}
{"op":"mcm","clk":"11883796360","pt":1724074619776,"mc":[{"id":"1.232011465","rc":[{"batb":[[0,1.85,10],[1,1.84,52],[2,1.8,8.75]],"ltp":2.1,"tv":1038.99,"id":67083366},{"batb":[[0,2.16,1.54],[1,1.9,8.29],[2,1.43,116.28]],"ltp":2.08,"tv":1001.62,"id":72857115}]}]}
{"op":"mcm","clk":"11883796450","pt":1724074623015,"mc":[{"id":"1.232011465","rc":[{"batb":[[0,1.84,52],[1,1.8,8.75],[2,1.52,7.76]],"ltp":2.1,"tv":1038.99,"id":67083366}]}]}
{"op":"mcm","clk":"11883797308","pt":1724074643420,"mc":[{"id":"1.232011465","rc":[{"batb":[[0,1.85,10],[1,1.84,52],[2,1.8,8.75]],"ltp":2.1,"tv":1038.99,"id":67083366},{"batb":[[0,1.9,8.29],[1,1.43,116.28],[2,1.38,131.58]],"ltp":2.08,"tv":1001.62,"id":72857115}]}]}
{"op":"mcm","clk":"11883797404","pt":1724074646752,"mc":[{"id":"1.232011465","rc":[{"batb":[[0,1.84,52],[1,1.8,8.75],[2,1.52,7.76]],"ltp":2.1,"tv":1038.99,"id":67083366}]}]}
{"op":"mcm","clk":"11883797587","pt":1724074652454,"mc":[{"id":"1.232011465","rc":[{"batb":[[0,1.85,10],[1,1.84,52],[2,1.8,8.75]],"ltp":2.1,"tv":1038.99,"id":67083366}]}]}
{"op":"mcm","clk":"11883797721","pt":1724074655947,"mc":[{"id":"1.232011465","rc":[{"batb":[[0,1.84,52],[1,1.8,8.75],[2,1.52,7.76]],"ltp":2.1,"tv":1038.99,"id":67083366}]}]}
{"op":"mcm","clk":"11883797774","pt":1724074657435,"mc":[{"id":"1.232011465","rc":[{"batl":[[0,1.85,1.62],[1,2.1,3.71],[2,2.48,4.65]],"ltp":2.1,"tv":1038.99,"id":67083366}]}]}
{"op":"mcm","clk":"11883797777","pt":1724074657539,"mc":[{"id":"1.232011465","rc":[{"trd":[[1.85,5.46]],"batl":[[0,2.1,3.71],[1,2.48,4.65],[2,2.48,0]],"ltp":1.85,"tv":1042.23,"id":67083366}],"tv":2043.86}]}
{"op":"mcm","clk":"11883802522","pt":1724074810217,"mc":[{"id":"1.232011465","rc":[{"batb":[[0,1.85,10],[1,1.84,52],[2,1.8,8.75]],"ltp":1.85,"tv":1042.23,"id":67083366}]}]}
{"op":"mcm","clk":"11883802646","pt":1724074813714,"mc":[{"id":"1.232011465","rc":[{"batb":[[0,1.84,52],[1,1.8,8.75],[2,1.52,7.76]],"ltp":1.85,"tv":1042.23,"id":67083366}]}]}
{"op":"mcm","clk":"11883803947","pt":1724074858100,"mc":[{"id":"1.232011465","rc":[{"batb":[[0,1.85,10],[1,1.84,52],[2,1.8,8.75]],"ltp":1.85,"tv":1042.23,"id":67083366}]}]}
{"op":"mcm","clk":"11883804049","pt":1724074861667,"mc":[{"id":"1.232011465","rc":[{"batb":[[0,1.84,52],[1,1.8,8.75],[2,1.52,7.76]],"ltp":1.85,"tv":1042.23,"id":67083366}]}]}
{"op":"mcm","clk":"11883805003","pt":1724074887506,"mc":[{"id":"1.232011465","rc":[{"batb":[[0,1.85,10],[1,1.84,52],[2,1.8,8.75]],"ltp":1.85,"tv":1042.23,"id":67083366}]}]}
{"op":"mcm","clk":"11883805125","pt":1724074891120,"mc":[{"id":"1.232011465","rc":[{"batb":[[0,1.84,52],[1,1.8,8.75],[2,1.52,7.76]],"ltp":1.85,"tv":1042.23,"id":67083366}]}]}
{"op":"mcm","clk":"11883805290","pt":1724074896618,"mc":[{"id":"1.232011465","rc":[{"batb":[[0,1.85,10],[1,1.84,52],[2,1.8,8.75]],"ltp":1.85,"tv":1042.23,"id":67083366}]}]}
{"op":"mcm","clk":"11883805403","pt":1724074900314,"mc":[{"id":"1.232011465","rc":[{"batb":[[0,1.84,52],[1,1.8,8.75],[2,1.52,7.76]],"ltp":1.85,"tv":1042.23,"id":67083366}]}]}
{"op":"mcm","clk":"11883806446","pt":1724074934769,"mc":[{"id":"1.232011465","rc":[{"batb":[[0,1.85,10],[1,1.84,52],[2,1.8,8.75]],"ltp":1.85,"tv":1042.23,"id":67083366}]}]}
{"op":"mcm","clk":"11883806539","pt":1724074938369,"mc":[{"id":"1.232011465","rc":[{"batb":[[0,1.84,52],[1,1.8,8.75],[2,1.52,7.76]],"ltp":1.85,"tv":1042.23,"id":67083366}]}]}
{"op":"mcm","clk":"11883807066","pt":1724074958696,"mc":[{"id":"1.232011465","rc":[{"batb":[[0,1.85,10],[1,1.84,52],[2,1.8,8.75]],"ltp":1.85,"tv":1042.23,"id":67083366}]}]}
{"op":"mcm","clk":"11883807159","pt":1724074962006,"mc":[{"id":"1.232011465","rc":[{"batb":[[0,1.84,52],[1,1.8,8.75],[2,1.52,7.76]],"ltp":1.85,"tv":1042.23,"id":67083366}]}]}
{"op":"mcm","clk":"11883816364","pt":1724074975134,"mc":[{"id":"1.232011465","rc":[{"batb":[[0,1.85,10],[1,1.84,52],[2,1.8,8.75]],"ltp":1.85,"tv":1042.23,"id":67083366}]}]}
{"op":"mcm","clk":"11883816471","pt":1724074978738,"mc":[{"id":"1.232011465","rc":[{"batb":[[0,1.84,52],[1,1.8,8.75],[2,1.52,7.76]],"ltp":1.85,"tv":1042.23,"id":67083366}]}]}
{"op":"mcm","clk":"11883816788","pt":1724074988141,"mc":[{"id":"1.232011465","rc":[{"batb":[[0,1.85,10],[1,1.84,52],[2,1.8,8.75]],"ltp":1.85,"tv":1042.23,"id":67083366}]}]}
{"op":"mcm","clk":"11883816899","pt":1724074991654,"mc":[{"id":"1.232011465","rc":[{"batb":[[0,1.84,52],[1,1.8,8.75],[2,1.52,7.76]],"ltp":1.85,"tv":1042.23,"id":67083366}]}]}
{"op":"mcm","clk":"11883817230","pt":1724075003691,"mc":[{"id":"1.232011465","rc":[{"batb":[[0,1.85,10],[1,1.84,52],[2,1.8,8.75]],"ltp":1.85,"tv":1042.23,"id":67083366}]}]}
{"op":"mcm","clk":"11883817331","pt":1724075006992,"mc":[{"id":"1.232011465","rc":[{"batb":[[0,1.84,52],[1,1.8,8.75],[2,1.52,7.76]],"ltp":1.85,"tv":1042.23,"id":67083366}]}]}
{"op":"mcm","clk":"11883817443","pt":1724075010386,"mc":[{"id":"1.232011465","rc":[{"batb":[[0,1.85,10],[1,1.84,52],[2,1.8,8.75]],"ltp":1.85,"tv":1042.23,"id":67083366}]}]}
{"op":"mcm","clk":"11883817542","pt":1724075013693,"mc":[{"id":"1.232011465","rc":[{"batb":[[0,1.84,52],[1,1.8,8.75],[2,1.52,7.76]],"ltp":1.85,"tv":1042.23,"id":67083366}]}]}
{"op":"mcm","clk":"11883818009","pt":1724075028387,"mc":[{"id":"1.232011465","rc":[{"batb":[[0,1.85,10],[1,1.84,52],[2,1.8,8.75]],"ltp":1.85,"tv":1042.23,"id":67083366}]}]}
{"op":"mcm","clk":"11883818137","pt":1724075031931,"mc":[{"id":"1.232011465","rc":[{"batb":[[0,1.84,52],[1,1.8,8.75],[2,1.52,7.76]],"ltp":1.85,"tv":1042.23,"id":67083366}]}]}
{"op":"mcm","clk":"11883819793","pt":1724075077265,"mc":[{"id":"1.232011465","rc":[{"batb":[[0,1.85,10],[1,1.84,52],[2,1.8,8.75]],"ltp":1.85,"tv":1042.23,"id":67083366}]}]}
{"op":"mcm","clk":"11883819901","pt":1724075080781,"mc":[{"id":"1.232011465","rc":[{"batb":[[0,1.84,52],[1,1.8,8.75],[2,1.52,7.76]],"ltp":1.85,"tv":1042.23,"id":67083366}]}]}
{"op":"mcm","clk":"11883820159","pt":1724075087584,"mc":[{"id":"1.232011465","rc":[{"batb":[[0,1.85,10],[1,1.84,52],[2,1.8,8.75]],"ltp":1.85,"tv":1042.23,"id":67083366}]}]}
{"op":"mcm","clk":"11883820305","pt":1724075092421,"mc":[{"id":"1.232011465","rc":[{"batb":[[0,1.84,52],[1,1.8,8.75],[2,1.52,7.76]],"ltp":1.85,"tv":1042.23,"id":67083366}]}]}
{"op":"mcm","clk":"11883820621","pt":1724075102993,"mc":[{"id":"1.232011465","rc":[{"batb":[[0,1.85,10],[1,1.84,52],[2,1.8,8.75]],"ltp":1.85,"tv":1042.23,"id":67083366}]}]}
{"op":"mcm","clk":"11883820784","pt":1724075106409,"mc":[{"id":"1.232011465","rc":[{"batb":[[0,1.84,52],[1,1.8,8.75],[2,1.52,7.76]],"ltp":1.85,"tv":1042.23,"id":67083366}]}]}
{"op":"mcm","clk":"11883821248","pt":1724075118662,"mc":[{"id":"1.232011465","rc":[{"batb":[[0,1.85,10],[1,1.84,52],[2,1.8,8.75]],"ltp":1.85,"tv":1042.23,"id":67083366}]}]}
{"op":"mcm","clk":"11883821386","pt":1724075122016,"mc":[{"id":"1.232011465","rc":[{"batb":[[0,1.84,52],[1,1.8,8.75],[2,1.52,7.76]],"ltp":1.85,"tv":1042.23,"id":67083366}]}]}
{"op":"mcm","clk":"11883821630","pt":1724075129437,"mc":[{"id":"1.232011465","rc":[{"batb":[[0,1.88,1.67],[1,1.84,52],[2,1.8,8.75]],"ltp":1.85,"tv":1042.23,"id":67083366}]}]}
{"op":"mcm","clk":"11883821635","pt":1724075129541,"mc":[{"id":"1.232011465","rc":[{"batb":[[1,1.85,10],[2,1.84,52]],"ltp":1.85,"tv":1042.23,"id":67083366}]}]}
{"op":"mcm","clk":"11883821746","pt":1724075132839,"mc":[{"id":"1.232011465","rc":[{"batb":[[1,1.84,52],[2,1.8,8.75]],"ltp":1.85,"tv":1042.23,"id":67083366}]}]}
{"op":"mcm","clk":"11883829762","pt":1724075340402,"mc":[{"id":"1.232011465","rc":[{"trd":[[1.88,0.44]],"batb":[[0,1.88,1.45]],"ltp":1.88,"tv":1042.67,"id":67083366}],"tv":2044.3}]}
{"op":"mcm","clk":"11883840841","pt":1724075704345,"mc":[{"id":"1.232011465","rc":[{"trd":[[1.88,2.44]],"batb":[[0,1.84,52.45],[1,1.8,8.75],[2,1.52,7.76]],"ltp":1.88,"tv":1044.67,"id":67083366}],"tv":2046.3}]}
{"op":"mcm","clk":"11883841296","pt":1724075718031,"mc":[{"id":"1.232011465","rc":[{"trd":[[1.84,105.1],[1.88,3.34]],"batb":[[0,1.8,9.2],[1,1.52,7.76],[2,1.43,116.28]],"ltp":1.84,"tv":1148.67,"id":67083366}],"tv":2150.3}]}
{"op":"mcm","clk":"11883841364","pt":1724075720332,"mc":[{"id":"1.232011465","rc":[{"batl":[[1,2.48,4.73]],"ltp":1.84,"tv":1148.67,"id":67083366}]}]}
{"op":"mcm","clk":"11883841466","pt":1724075723049,"mc":[{"id":"1.232011465","rc":[{"batb":[[0,1.8,63.35]],"ltp":1.84,"tv":1148.67,"id":67083366}]}]}
{"op":"mcm","clk":"11883842375","pt":1724075754385,"mc":[{"id":"1.232011465","rc":[{"batb":[[0,1.81,4.76],[1,1.8,63.35],[2,1.52,7.76]],"batl":[[1,2.48,4.65]],"ltp":1.84,"tv":1148.67,"id":67083366}]}]}
{"op":"mcm","clk":"11883845913","pt":1724075877524,"mc":[{"id":"1.232011465","rc":[{"batb":[[0,1.84,1.34],[1,1.81,4.76],[2,1.8,63.35]],"ltp":1.84,"tv":1148.67,"id":67083366}]}]}
{"op":"mcm","clk":"11883850978","pt":1724076016561,"mc":[{"id":"1.232011465","rc":[{"trd":[[1.09,881.2],[1.1,20],[1.85,5.46],[1.86,2.22],[1.89,2.18]],"batb":[[1,1.8,63.35],[2,1.52,7.76]],"ltp":1.84,"tv":1148.09,"id":67083366},{"trd":[[1.09,896.57],[2.08,103.39]],"batb":[[0,1.9,8.29]],"ltp":2.08,"tv":1001.21,"id":72857115}],"tv":2149.3}]}
{"op":"mcm","clk":"11883852443","pt":1724076052192,"mc":[{"id":"1.232011465","rc":[{"trd":[[1.84,107.1]],"batb":[[0,1.81,10.34]],"ltp":1.84,"tv":1150.09,"id":67083366}],"tv":2151.3}]}
{"op":"mcm","clk":"11883852601","pt":1724076055590,"mc":[{"id":"1.232011465","rc":[{"batb":[[0,1.8,63.69],[1,1.52,7.76],[2,1.43,116.28]],"ltp":1.84,"tv":1150.09,"id":67083366}]}]}
{"op":"mcm","clk":"11883853382","pt":1724076073285,"mc":[{"id":"1.232011465","rc":[{"batl":[[0,2.1,7.06]],"ltp":1.84,"tv":1150.09,"id":67083366}]}]}
{"op":"mcm","clk":"11883853394","pt":1724076073496,"mc":[{"id":"1.232011465","rc":[{"batb":[[0,1.81,10.34],[1,1.8,63.35],[2,1.52,7.76]],"ltp":1.84,"tv":1150.09,"id":67083366}]}]}
{"op":"mcm","clk":"11883853559","pt":1724076076902,"mc":[{"id":"1.232011465","rc":[{"batb":[[0,1.8,63.69],[1,1.52,7.76],[2,1.43,116.28]],"ltp":1.84,"tv":1150.09,"id":67083366}]}]}
{"op":"mcm","clk":"11883853981","pt":1724076086855,"mc":[{"id":"1.232011465","rc":[{"batb":[[0,1.81,10.34],[1,1.8,63.35],[2,1.52,7.76]],"ltp":1.84,"tv":1150.09,"id":67083366}]}]}
{"op":"mcm","clk":"11883854100","pt":1724076090242,"mc":[{"id":"1.232011465","rc":[{"batb":[[0,1.8,63.69],[1,1.52,7.76],[2,1.43,116.28]],"ltp":1.84,"tv":1150.09,"id":67083366}]}]}
{"op":"mcm","clk":"11883854189","pt":1724076092664,"mc":[{"id":"1.232011465","rc":[{"batb":[[0,1.81,10.34],[1,1.8,63.35],[2,1.52,7.76]],"ltp":1.84,"tv":1150.09,"id":67083366}]}]}
{"op":"mcm","clk":"11883854331","pt":1724076096136,"mc":[{"id":"1.232011465","rc":[{"batb":[[0,1.8,63.69],[1,1.52,7.76],[2,1.43,116.28]],"ltp":1.84,"tv":1150.09,"id":67083366}]}]}
{"op":"mcm","clk":"11883855189","pt":1724076118478,"mc":[{"id":"1.232011465","rc":[{"batb":[[0,1.81,10.34],[1,1.8,63.35],[2,1.52,7.76]],"ltp":1.84,"tv":1150.09,"id":67083366}]}]}
{"op":"mcm","clk":"11883855316","pt":1724076121984,"mc":[{"id":"1.232011465","rc":[{"batb":[[0,1.8,63.69],[1,1.52,7.76],[2,1.43,116.28]],"ltp":1.84,"tv":1150.09,"id":67083366}]}]}
{"op":"mcm","clk":"11883855894","pt":1724076134300,"mc":[{"id":"1.232011465","rc":[{"batb":[[0,1.81,10.34],[1,1.8,63.35],[2,1.52,7.76]],"ltp":1.84,"tv":1150.09,"id":67083366}]}]}
