{"op":"mcm","clk":"11858976059","pt":1723380643450,"mc":[{"id":"1.231703146","marketDefinition":{"bspMarket":false,"turnInPlayEnabled":true,"persistenceEnabled":true,"marketBaseRate":5.0,"eventId":"33486248","eventTypeId":"4","numberOfWinners":1,"bettingType":"ODDS","marketType":"MATCH_ODDS","marketTime":"2024-08-13T14:00:00.000Z","suspendTime":"2024-08-13T14:00:00.000Z","bspReconciled":false,"complete":true,"inPlay":false,"crossMatching":true,"runnersVoidable":false,"numberOfActiveRunners":2,"betDelay":0,"status":"OPEN","runners":[{"status":"ACTIVE","sortPriority":1,"id":40096589,"name":"Northern Superchargers Women"},{"status":"ACTIVE","sortPriority":2,"id":40096576,"name":"London Spirit Women"}],"regulators":["MR_INT"],"countryCode":"GB","discountAllowed":false,"timezone":"GMT","openDate":"2024-08-13T14:00:00.000Z","version":6069400568,"name":"Match Odds","eventName":"Northern Superchargers Women v London Spirit Women"},"rc":[{"batb":[[0,1.03,200],[1,1.02,200],[2,1.01,220]],"ltp":0.0,"tv":0.0,"id":40096589},{"batb":[[0,1.03,200],[1,1.02,200],[2,1.01,220]],"ltp":0.0,"tv":0.0,"id":40096576}]}]}
{"op":"mcm","clk":"11858976230","pt":1723380645072,"mc":[{"id":"1.231703146","marketDefinition":{"bspMarket":false,"turnInPlayEnabled":true,"persistenceEnabled":true,"marketBaseRate":5.0,"eventId":"33486248","eventTypeId":"4","numberOfWinners":1,"bettingType":"ODDS","marketType":"MATCH_ODDS","marketTime":"2024-08-13T14:00:00.000Z","suspendTime":"2024-08-13T14:00:00.000Z","bspReconciled":false,"complete":true,"inPlay":false,"crossMatching":true,"runnersVoidable":false,"numberOfActiveRunners":2,"betDelay":0,"status":"OPEN","runners":[{"status":"ACTIVE","sortPriority":1,"id":40096589,"name":"Northern Superchargers Women"},{"status":"ACTIVE","sortPriority":2,"id":40096576,"name":"London Spirit Women"}],"regulators":["MR_INT"],"countryCode":"GB","discountAllowed":true,"timezone":"GMT","openDate":"2024-08-13T14:00:00.000Z","version":6069400568,"name":"Match Odds","eventName":"Northern Superchargers Women v London Spirit Women"}}]}
{"op":"mcm","clk":"11859330606","pt":1723383439276,"mc":[{"id":"1.231703146","rc":[{"batb":[[0,1.58,48.02],[1,1.03,200],[2,1.02,200]],"ltp":0.0,"tv":0.0,"id":40096576}]}]}
{"op":"mcm","clk":"11859333195","pt":1723383456748,"mc":[{"id":"1.231703146","rc":[{"trd":[[1.58,96.05]],"batb":[[0,1.03,200],[1,1.02,200],[2,1.01,220]],"batl":[[0,1.58,1.77]],"ltp":1.58,"tv":96.04,"id":40096576}],"tv":96.04}]}
{"op":"mcm","clk":"11859336055","pt":1723383476243,"mc":[{"id":"1.231703146","rc":[{"batb":[[0,1.58,84.75],[1,1.03,200],[2,1.02,200]],"ltp":0.0,"tv":0.0,"id":40096589}]}]}
{"op":"mcm","clk":"11859338483","pt":1723383492750,"mc":[{"id":"1.231703146","rc":[{"trd":[[1.58,169.49]],"batb":[[0,1.03,200],[1,1.02,200],[2,1.01,220]],"batl":[[0,1.58,0.16]],"ltp":1.58,"tv":169.49,"id":40096589}],"tv":265.53}]}
{"op":"mcm","clk":"11859346868","pt":1723383551700,"mc":[{"id":"1.231703146","rc":[{"batb":[[0,1.58,36.72],[1,1.03,200],[2,1.02,200]],"ltp":1.58,"tv":96.04,"id":40096576}]}]}
{"op":"mcm","clk":"11859348011","pt":1723383560378,"mc":[{"id":"1.231703146","rc":[{"trd":[[1.58,169.49]],"batb":[[0,1.03,200],[1,1.02,200],[2,1.01,220]],"batl":[[0,1.58,0.3]],"ltp":1.58,"tv":169.49,"id":40096576}],"tv":338.98}]}
{"op":"mcm","clk":"11859520546","pt":1723384866956,"mc":[{"id":"1.231703146","rc":[{"batb":[[2,1.01,480.71]],"ltp":1.58,"tv":169.49,"id":40096589},{"batb":[[2,1.01,480.71]],"ltp":1.58,"tv":169.49,"id":40096576}]}]}
{"op":"mcm","clk":"11860394882","pt":1723389846046,"mc":[{"id":"1.231703146","rc":[{"batb":[[0,1.1,25000],[1,1.09,25000],[2,1.08,25000]],"ltp":1.58,"tv":169.49,"id":40096589},{"batb":[[0,1.1,25000],[1,1.09,25000],[2,1.08,25000]],"ltp":1.58,"tv":169.49,"id":40096576}]}]}
{"op":"mcm","clk":"11860628362","pt":1723390993425,"mc":[{"id":"1.231703146","rc":[{"batb":[[0,1.26,16],[1,1.1,25000],[2,1.09,25000]],"ltp":1.58,"tv":169.49,"id":40096589},{"batb":[[0,1.3,12],[1,1.1,25000],[2,1.09,25000]],"ltp":1.58,"tv":169.49,"id":40096576}]}]}
{"op":"mcm","clk":"11860636561","pt":1723391038916,"mc":[{"id":"1.231703146","rc":[{"batb":[[1,1.09,25000],[2,1.08,25000]],"ltp":1.58,"tv":169.49,"id":40096589}]}]}
{"op":"mcm","clk":"11860636783","pt":1723391040020,"mc":[{"id":"1.231703146","rc":[{"batb":[[1,1.07,25000],[2,1.06,25000]],"ltp":1.58,"tv":169.49,"id":40096589}]}]}
{"op":"mcm","clk":"11860636921","pt":1723391040708,"mc":[{"id":"1.231703146","rc":[{"batb":[[1,1.05,25000],[2,1.04,25000]],"ltp":1.58,"tv":169.49,"id":40096589}]}]}
{"op":"mcm","clk":"11860637063","pt":1723391041305,"mc":[{"id":"1.231703146","rc":[{"batb":[[1,1.04,25000],[2,1.03,25200]],"ltp":1.58,"tv":169.49,"id":40096589}]}]}
{"op":"mcm","clk":"11860638540","pt":1723391048997,"mc":[{"id":"1.231703146","rc":[{"batb":[[1,1.08,25000],[2,1.07,25000]],"ltp":1.58,"tv":169.49,"id":40096576}]}]}
{"op":"mcm","clk":"11860638715","pt":1723391049925,"mc":[{"id":"1.231703146","rc":[{"batb":[[1,1.07,10000],[2,1.06,15000]],"ltp":1.58,"tv":169.49,"id":40096576}]}]}
{"op":"mcm","clk":"11860638873","pt":1723391050710,"mc":[{"id":"1.231703146","rc":[{"batb":[[1,1.04,25000],[2,1.03,25200]],"ltp":1.58,"tv":169.49,"id":40096576}]}]}
{"op":"mcm","clk":"11860834472","pt":1723392349887,"mc":[{"id":"1.231703146","rc":[{"trd":[[1.3,0.14]],"batb":[[0,1.3,11.93]],"ltp":1.3,"tv":169.63,"id":40096576}],"tv":339.12}]}
{"op":"mcm","clk":"11860857534","pt":1723392489097,"mc":[{"id":"1.231703146","rc":[{"batb":[[0,1.27,31.84],[1,1.26,16],[2,1.04,25000]],"ltp":1.58,"tv":169.49,"id":40096589},{"batb":[[0,1.31,27.74],[1,1.3,11.93],[2,1.04,25000]],"ltp":1.3,"tv":169.63,"id":40096576}]}]}
{"op":"mcm","clk":"11861004535","pt":1723393351372,"mc":[{"id":"1.231703146","rc":[{"batb":[[0,1.28,16],[1,1.27,31.84]],"ltp":1.58,"tv":169.49,"id":40096589},{"batb":[[0,1.32,11.93],[1,1.31,27.74]],"ltp":1.3,"tv":169.63,"id":40096576}]}]}
{"op":"mcm","clk":"11861091723","pt":1723393876919,"mc":[{"id":"1.231703146","rc":[{"batb":[[0,1.91,44.27],[1,1.28,16],[2,1.27,31.84]],"ltp":1.58,"tv":169.49,"id":40096589},{"batb":[[0,2,40.28],[1,1.32,11.93],[2,1.31,27.74]],"ltp":1.3,"tv":169.63,"id":40096576}]}]}
{"op":"mcm","clk":"11861164917","pt":1723394289510,"mc":[{"id":"1.231703146","rc":[{"batb":[[2,1.04,25000]],"ltp":1.3,"tv":169.63,"id":40096576}]}]}
{"op":"mcm","clk":"11861165018","pt":1723394290146,"mc":[{"id":"1.231703146","rc":[{"batb":[[2,1.04,25000]],"ltp":1.58,"tv":169.49,"id":40096589}]}]}
{"op":"mcm","clk":"11861189339","pt":1723394422661,"mc":[{"id":"1.231703146","rc":[{"batl":[[0,1.99,100]],"ltp":1.58,"tv":169.49,"id":40096589}]}]}
{"op":"mcm","clk":"11861311331","pt":1723395149780,"mc":[{"id":"1.231703146","rc":[{"batl":[[0,1.98,4.91],[1,1.99,100]],"ltp":1.58,"tv":169.49,"id":40096589},{"batb":[[0,2.02,6.86],[1,2,40.28],[2,1.32,11.93]],"ltp":1.3,"tv":169.63,"id":40096576}]}]}
{"op":"mcm","clk":"11861385597","pt":1723395729178,"mc":[{"id":"1.231703146","rc":[{"batb":[[1,2,43.19]],"ltp":1.3,"tv":169.63,"id":40096576}]}]}
{"op":"mcm","clk":"11861724714","pt":1723397707813,"mc":[{"id":"1.231703146","rc":[{"batb":[[2,1.25,100]],"ltp":1.58,"tv":169.49,"id":40096589}]}]}
{"op":"mcm","clk":"11863415502","pt":1723407175027,"mc":[{"id":"1.231703146","rc":[{"batl":[[0,1.98,4.9]],"ltp":1.58,"tv":169.49,"id":40096589},{"batb":[[0,2.02,6.84],[1,2,43.19]],"ltp":1.3,"tv":169.63,"id":40096576}]}]}
{"op":"mcm","clk":"11863553793","pt":1723408043867,"mc":[{"id":"1.231703146","rc":[{"batb":[[0,2,43.19],[1,1.32,11.93],[2,1.25,100]],"ltp":1.3,"tv":169.63,"id":40096576}]}]}
{"op":"mcm","clk":"11863555598","pt":1723408056294,"mc":[{"id":"1.231703146","rc":[{"batb":[[0,2,40.28],[1,1.91,333],[2,1.32,11.93]],"ltp":1.3,"tv":169.63,"id":40096576}]}]}
{"op":"mcm","clk":"11863950109","pt":1723411080065,"mc":[{"id":"1.231703146","rc":[{"trd":[[1.58,169.07]],"ltp":1.58,"tv":169.07,"id":40096589},{"trd":[[1.58,169.07]],"ltp":1.3,"tv":169.21,"id":40096576}],"tv":338.28}]}
{"op":"mcm","clk":"11864021372","pt":1723411748789,"mc":[{"id":"1.231703146","rc":[{"batb":[[1,1.32,11.93],[2,1.25,100]],"ltp":1.3,"tv":169.21,"id":40096576}]}]}
{"op":"mcm","clk":"11864392484","pt":1723415852604,"mc":[{"id":"1.231703146","rc":[{"trd":[[1.58,169.18]],"ltp":1.58,"tv":169.18,"id":40096589},{"trd":[[1.58,169.18]],"batb":[[1,1.9,555],[2,1.32,11.93]],"ltp":1.3,"tv":169.32,"id":40096576}],"tv":338.5}]}
{"op":"mcm","clk":"11864393205","pt":1723415862074,"mc":[{"id":"1.231703146","rc":[{"batb":[[1,1.91,555],[2,1.9,555]],"ltp":1.3,"tv":169.32,"id":40096576}]}]}
{"op":"mcm","clk":"11864542619","pt":1723417974981,"mc":[{"id":"1.231703146","rc":[{"trd":[[1.58,169.25]],"ltp":1.58,"tv":169.24,"id":40096589},{"trd":[[1.58,169.25]],"ltp":1.3,"tv":169.38,"id":40096576}],"tv":338.63}]}
{"op":"mcm","clk":"11864666123","pt":1723420015003,"mc":[{"id":"1.231703146","rc":[{"trd":[[1.91,0.08]],"batb":[[0,1.91,44.19]],"ltp":1.91,"tv":169.32,"id":40096589},{"trd":[[2.1,0.07]],"ltp":2.1,"tv":169.45,"id":40096576}],"tv":338.78}]}
{"op":"mcm","clk":"11864666203","pt":1723420016286,"mc":[{"id":"1.231703146","rc":[{"batb":[[0,1.91,44.27]],"ltp":1.91,"tv":169.32,"id":40096589}]}]}
{"op":"mcm","clk":"11864821142","pt":1723423375003,"mc":[{"id":"1.231703146","rc":[{"trd":[[1.58,169.28]],"ltp":1.91,"tv":169.35,"id":40096589},{"trd":[[1.58,169.28]],"ltp":2.1,"tv":169.48,"id":40096576}],"tv":338.84}]}
{"op":"mcm","clk":"11864997826","pt":1723428775001,"mc":[{"id":"1.231703146","rc":[{"trd":[[1.58,169.13]],"ltp":1.91,"tv":169.21,"id":40096589},{"trd":[[1.58,169.13]],"ltp":2.1,"tv":169.34,"id":40096576}],"tv":338.55}]}
{"op":"mcm","clk":"11865119489","pt":1723433021346,"mc":[{"id":"1.231703146","rc":[{"trd":[[1.58,169.1]],"ltp":1.91,"tv":169.17,"id":40096589},{"trd":[[1.58,169.1]],"batb":[[1,1.32,11.93],[2,1.25,100]],"ltp":2.1,"tv":169.3,"id":40096576}],"tv":338.48}]}
{"op":"mcm","clk":"11865336861","pt":1723439574994,"mc":[{"id":"1.231703146","rc":[{"trd":[[1.58,169.1]],"ltp":1.91,"tv":169.17,"id":40096589},{"trd":[[1.58,169.1]],"ltp":2.1,"tv":169.3,"id":40096576}],"tv":338.48}]}
{"op":"mcm","clk":"11865388269","pt":1723441414475,"mc":[{"id":"1.231703146","rc":[{"batb":[[1,1.25,100],[2,1.04,25000]],"ltp":1.91,"tv":169.17,"id":40096589},{"batb":[[1,1.25,100],[2,1.04,25000]],"ltp":2.1,"tv":169.3,"id":40096576}]}]}
{"op":"mcm","clk":"11865388404","pt":1723441422623,"mc":[{"id":"1.231703146","rc":[{"batl":[[0,1.99,20]],"ltp":1.91,"tv":169.17,"id":40096589}]}]}
{"op":"mcm","clk":"11865503964","pt":1723444974975,"mc":[{"id":"1.231703146","rc":[{"trd":[[1.58,169.04]],"ltp":1.91,"tv":169.12,"id":40096589},{"trd":[[1.58,169.04]],"ltp":2.1,"tv":169.25,"id":40096576}],"tv":338.37}]}
{"op":"mcm","clk":"11865516947","pt":1723445370332,"mc":[{"id":"1.231703146","rc":[{"batb":[[0,2.04,25.78],[1,2,40.28],[2,1.25,100]],"ltp":2.1,"tv":169.25,"id":40096576}]}]}
{"op":"mcm","clk":"11865517413","pt":1723445396556,"mc":[{"id":"1.231703146","rc":[{"batb":[[0,2,40.28],[1,1.25,100],[2,1.04,25000]],"ltp":2.1,"tv":169.25,"id":40096576}]}]}
{"op":"mcm","clk":"11865576543","pt":1723447654507,"mc":[{"id":"1.231703146","rc":[{"trd":[[1.58,169],[1.91,0.4]],"batb":[[0,1.91,44.11]],"ltp":1.91,"tv":169.4,"id":40096589},{"trd":[[1.58,169]],"ltp":2.1,"tv":169.21,"id":40096576}],"tv":338.61}]}
{"op":"mcm","clk":"11865576645","pt":1723447659013,"mc":[{"id":"1.231703146","rc":[{"batb":[[0,1.91,44.27]],"ltp":1.91,"tv":169.4,"id":40096589}]}]}
{"op":"mcm","clk":"11865656439","pt":1723450375041,"mc":[{"id":"1.231703146","rc":[{"trd":[[1.58,169.02]],"ltp":1.91,"tv":169.42,"id":40096589},{"trd":[[1.58,169.02]],"ltp":2.1,"tv":169.23,"id":40096576}],"tv":338.65}]}
{"op":"mcm","clk":"11865673489","pt":1723450926927,"mc":[{"id":"1.231703146","rc":[{"trd":[[1.91,0.8]],"batb":[[0,1.91,44.07]],"ltp":1.91,"tv":169.82,"id":40096589}],"tv":339.05}]}
{"op":"mcm","clk":"11865673546","pt":1723450929229,"mc":[{"id":"1.231703146","rc":[{"batb":[[0,1.91,44.27]],"ltp":1.91,"tv":169.82,"id":40096589}]}]}
{"op":"mcm","clk":"11865688657","pt":1723451378610,"mc":[{"id":"1.231703146","rc":[{"trd":[[1.91,1.2]],"batb":[[0,1.91,44.07]],"ltp":1.91,"tv":170.22,"id":40096589}],"tv":339.45}]}
{"op":"mcm","clk":"11865688725","pt":1723451380615,"mc":[{"id":"1.231703146","rc":[{"batb":[[0,1.91,44.27]],"ltp":1.91,"tv":170.22,"id":40096589}]}]}
{"op":"mcm","clk":"11865887442","pt":1723455639602,"mc":[{"id":"1.231703146","rc":[{"trd":[[1.58,169.11],[1.91,1.68]],"batb":[[0,1.91,44.03]],"ltp":1.91,"tv":170.79,"id":40096589},{"trd":[[1.58,169.11]],"ltp":2.1,"tv":169.31,"id":40096576}],"tv":340.1}]}
{"op":"mcm","clk":"11865887628","pt":1723455643805,"mc":[{"id":"1.231703146","rc":[{"batb":[[0,1.91,44.27]],"ltp":1.91,"tv":170.79,"id":40096589}]}]}
{"op":"mcm","clk":"11865892845","pt":1723455750835,"mc":[{"id":"1.231703146","rc":[{"trd":[[1.91,2.08]],"batb":[[0,1.91,44.07]],"ltp":1.91,"tv":171.19,"id":40096589}],"tv":340.5}]}
{"op":"mcm","clk":"11865893011","pt":1723455754184,"mc":[{"id":"1.231703146","rc":[{"batb":[[0,1.91,44.27]],"ltp":1.91,"tv":171.19,"id":40096589}]}]}
{"op":"mcm","clk":"11865919075","pt":1723456102013,"mc":[{"id":"1.231703146","rc":[{"batb":[[0,1.46,160.05]],"ltp":1.91,"tv":171.19,"id":40096589},{"batb":[[0,1.25,100],[1,1.04,25000],[2,1.03,25200]],"ltp":2.1,"tv":169.31,"id":40096576}]}]}
{"op":"mcm","clk":"11865930432","pt":1723456302126,"mc":[{"id":"1.231703146","rc":[{"batl":[[0,1.92,69.23],[1,1.99,20]],"ltp":1.91,"tv":171.19,"id":40096589}]}]}
{"op":"mcm","clk":"11865930797","pt":1723456310166,"mc":[{"id":"1.231703146","rc":[{"batb":[[0,1.55,138.46],[1,1.46,160.05],[2,1.25,100]],"ltp":1.91,"tv":171.19,"id":40096589}]}]}
{"op":"mcm","clk":"11865946872","pt":1723456612418,"mc":[{"id":"1.231703146","rc":[{"batb":[[0,1.57,148.69],[1,1.55,138.46]],"ltp":1.91,"tv":171.19,"id":40096589}]}]}
{"op":"mcm","clk":"11865961675","pt":1723456857096,"mc":[{"id":"1.231703146","rc":[{"trd":[[1.58,169.23]],"batb":[[0,1.58,6.01],[1,1.57,148.69],[2,1.55,138.46]],"ltp":1.91,"tv":171.31,"id":40096589},{"trd":[[1.58,169.23]],"ltp":2.1,"tv":169.44,"id":40096576}],"tv":340.76}]}
{"op":"mcm","clk":"11865988946","pt":1723457346997,"mc":[{"id":"1.231703146","rc":[{"batb":[[0,1.58,13.61],[1,1.55,138.46],[2,1.25,100]],"ltp":1.91,"tv":171.31,"id":40096589}]}]}
{"op":"mcm","clk":"11865988957","pt":1723457347157,"mc":[{"id":"1.231703146","rc":[{"batb":[[0,1.6,145.87],[1,1.58,13.61],[2,1.55,138.46]],"ltp":1.91,"tv":171.31,"id":40096589}]}]}
{"op":"mcm","clk":"11865989102","pt":1723457349782,"mc":[{"id":"1.231703146","rc":[{"batb":[[1,1.58,6.01]],"ltp":1.91,"tv":171.31,"id":40096589}]}]}
{"op":"mcm","clk":"11865997130","pt":1723457464713,"mc":[{"id":"1.231703146","rc":[{"batb":[[0,1.91,44.64],[1,1.6,145.87],[2,1.58,6.01]],"ltp":1.91,"tv":171.31,"id":40096589},{"batb":[[0,2,40.62],[1,1.25,100],[2,1.04,25000]],"ltp":2.1,"tv":169.44,"id":40096576}]}]}
{"op":"mcm","clk":"11866001195","pt":1723457508966,"mc":[{"id":"1.231703146","rc":[{"batb":[[1,1.58,6.01],[2,1.55,138.46]],"ltp":1.91,"tv":171.31,"id":40096589}]}]}
{"op":"mcm","clk":"11866019520","pt":1723457801819,"mc":[{"id":"1.231703146","rc":[{"batb":[[2,1.25,100]],"batl":[[0,1.99,20],[1,1.99,0]],"ltp":1.91,"tv":171.31,"id":40096589}]}]}
{"op":"mcm","clk":"11866020186","pt":1723457811410,"mc":[{"id":"1.231703146","rc":[{"trd":[[1.91,57.47]],"batb":[[0,1.91,16.95]],"ltp":1.91,"tv":226.69,"id":40096589}],"tv":396.14}]}
{"op":"mcm","clk":"11866020498","pt":1723457816107,"mc":[{"id":"1.231703146","rc":[{"batb":[[0,1.91,44.64]],"ltp":1.91,"tv":226.69,"id":40096589}]}]}
{"op":"mcm","clk":"11866056731","pt":1723458514693,"mc":[{"id":"1.231703146","rc":[{"batb":[[1,1.25,100],[2,1.04,25000]],"ltp":1.91,"tv":226.69,"id":40096589}]}]}
{"op":"mcm","clk":"11866196337","pt":1723461038808,"mc":[{"id":"1.231703146","rc":[{"trd":[[1.58,169.2],[1.91,59.47]],"batb":[[0,1.91,43.64]],"ltp":1.91,"tv":228.66,"id":40096589},{"trd":[[1.58,169.2]],"ltp":2.1,"tv":169.41,"id":40096576}],"tv":398.07}]}
{"op":"mcm","clk":"11866196514","pt":1723461041534,"mc":[{"id":"1.231703146","rc":[{"batb":[[0,1.91,44.64]],"ltp":1.91,"tv":228.66,"id":40096589}]}]}
{"op":"mcm","clk":"11866201631","pt":1723461124258,"mc":[{"id":"1.231703146","rc":[{"batl":[[0,1.97,27.69],[1,1.99,20]],"ltp":1.91,"tv":228.66,"id":40096589}]}]}
{"op":"mcm","clk":"11866253931","pt":1723461908941,"mc":[{"id":"1.231703146","rc":[{"batb":[[1,1.74,17.32],[2,1.25,100]],"ltp":1.91,"tv":228.66,"id":40096589},{"batb":[[1,1.74,17.32],[2,1.25,100]],"ltp":2.1,"tv":169.41,"id":40096576}]}]}
{"op":"mcm","clk":"11866274406","pt":1723462238914,"mc":[{"id":"1.231703146","rc":[{"batb":[[0,1.97,297.27],[1,1.91,44.64],[2,1.74,17.32]],"batl":[[0,1.99,20],[1,1.99,0]],"ltp":1.91,"tv":228.66,"id":40096589}]}]}
{"op":"mcm","clk":"11866274891","pt":1723462247122,"mc":[{"id":"1.231703146","rc":[{"trd":[[1.99,40]],"batb":[[0,1.99,304.96],[1,1.97,297.27],[2,1.91,44.64]],"ltp":1.99,"tv":268.66,"id":40096589}],"tv":438.07}]}
{"op":"mcm","clk":"11866275306","pt":1723462253814,"mc":[{"id":"1.231703146","rc":[{"trd":[[2,40.62]],"batb":[[0,2,284.34],[1,1.99,304.96],[2,1.97,297.27]],"ltp":2.0,"tv":309.28,"id":40096589},{"trd":[[2,40.62]],"batb":[[0,1.75,113.23]],"ltp":2.0,"tv":210.03,"id":40096576}],"tv":519.31}]}
{"op":"mcm","clk":"11866275397","pt":1723462255457,"mc":[{"id":"1.231703146","rc":[{"batb":[[0,1.96,42.31],[1,1.75,113.23],[2,1.74,17.32]],"ltp":2.0,"tv":210.03,"id":40096576}]}]}
{"op":"mcm","clk":"11866275697","pt":1723462260133,"mc":[{"id":"1.231703146","rc":[{"batb":[[0,1.91,44.64],[1,1.74,17.32],[2,1.25,100]],"ltp":2.0,"tv":309.28,"id":40096589}]}]}
{"op":"mcm","clk":"11866277459","pt":1723462288489,"mc":[{"id":"1.231703146","rc":[{"batb":[[1,1.74,17.32],[2,1.25,100]],"ltp":2.0,"tv":210.03,"id":40096576}]}]}
{"op":"mcm","clk":"11866279847","pt":1723462329006,"mc":[{"id":"1.231703146","rc":[{"trd":[[1.91,148.75]],"batb":[[0,1.74,17.32],[1,1.25,100],[2,1.04,25000]],"batl":[[0,1.91,44.72]],"ltp":1.91,"tv":398.56,"id":40096589}],"tv":608.59}]}
{"op":"mcm","clk":"11866279951","pt":1723462330625,"mc":[{"id":"1.231703146","rc":[{"batb":[[0,1.87,46.69],[1,1.74,17.32],[2,1.25,100]],"ltp":1.91,"tv":398.56,"id":40096589}]}]}
{"op":"mcm","clk":"11866280611","pt":1723462341652,"mc":[{"id":"1.231703146","rc":[{"trd":[[1.87,93.38]],"batb":[[0,1.74,17.32],[1,1.25,100],[2,1.04,25000]],"batl":[[0,1.87,34.55],[1,1.91,44.72]],"ltp":1.87,"tv":491.94,"id":40096589}],"tv":701.97}]}
{"op":"mcm","clk":"11866285339","pt":1723462422631,"mc":[{"id":"1.231703146","rc":[{"trd":[[1.74,34.64]],"batb":[[0,1.47,158.95]],"batl":[[0,1.74,63.92],[1,1.91,0]],"ltp":1.74,"tv":526.58,"id":40096589}],"tv":736.61}]}
{"op":"mcm","clk":"11866286588","pt":1723462448534,"mc":[{"id":"1.231703146","rc":[{"batb":[[0,1.5,155.89]],"ltp":1.74,"tv":526.58,"id":40096589}]}]}
{"op":"mcm","clk":"11866286980","pt":1723462457352,"mc":[{"id":"1.231703146","rc":[{"batb":[[0,1.68,138.46],[1,1.5,155.89],[2,1.25,100]],"ltp":1.74,"tv":526.58,"id":40096589}]}]}
{"op":"mcm","clk":"11866292297","pt":1723462560861,"mc":[{"id":"1.231703146","rc":[{"batb":[[1,1.25,100],[2,1.04,25000]],"ltp":1.74,"tv":526.58,"id":40096589}]}]}
{"op":"mcm","clk":"11866292930","pt":1723462571455,"mc":[{"id":"1.231703146","rc":[{"batb":[[0,1.69,23.89],[1,1.68,138.46],[2,1.25,100]],"ltp":1.74,"tv":526.58,"id":40096589}]}]}
{"op":"mcm","clk":"11866294824","pt":1723462602897,"mc":[{"id":"1.231703146","rc":[{"batb":[[0,1.78,69.23],[1,1.69,23.89],[2,1.68,138.46]],"ltp":1.74,"tv":526.58,"id":40096589}]}]}
{"op":"mcm","clk":"11866300746","pt":1723462702288,"mc":[{"id":"1.231703146","rc":[{"batb":[[1,1.68,138.46],[2,1.25,100]],"ltp":1.74,"tv":526.58,"id":40096589}]}]}
{"op":"mcm","clk":"11866333857","pt":1723463315543,"mc":[{"id":"1.231703146","rc":[{"batl":[[0,2.02,1]],"ltp":1.74,"tv":526.58,"id":40096589}]}]}
{"op":"mcm","clk":"11866348674","pt":1723463582876,"mc":[{"id":"1.231703146","rc":[{"batb":[[0,1.79,7.48],[1,1.78,69.23],[2,1.68,138.46]],"ltp":1.74,"tv":526.58,"id":40096589}]}]}
{"op":"mcm","clk":"11866368677","pt":1723463956734,"mc":[{"id":"1.231703146","rc":[{"batl":[[0,1.99,36.06],[1,2.02,1]],"ltp":1.74,"tv":526.58,"id":40096589}]}]}
{"op":"mcm","clk":"11866392509","pt":1723464376778,"mc":[{"id":"1.231703146","rc":[{"trd":[[1.58,169.09]],"batb":[[0,1.79,13.24]],"ltp":1.74,"tv":526.47,"id":40096589},{"trd":[[1.58,169.09]],"ltp":2.0,"tv":209.91,"id":40096576}],"tv":736.39}]}
{"op":"mcm","clk":"11866410456","pt":1723464727255,"mc":[{"id":"1.231703146","rc":[{"batb":[[2,1.74,36.06]],"ltp":1.74,"tv":526.47,"id":40096589}]}]}
{"op":"mcm","clk":"11866434556","pt":1723465172362,"mc":[{"id":"1.231703146","rc":[{"batl":[[0,1.98,129.38],[1,1.99,36.06],[2,2.02,1]],"ltp":1.74,"tv":526.47,"id":40096589}]}]}
{"op":"mcm","clk":"11866439241","pt":1723465265197,"mc":[{"id":"1.231703146","rc":[{"batb":[[0,2.04,7.68],[1,1.96,42.31],[2,1.74,17.32]],"ltp":2.0,"tv":209.91,"id":40096576}]}]}
{"op":"mcm","clk":"11866441316","pt":1723465305024,"mc":[{"id":"1.231703146","rc":[{"trd":[[1.97,7.96]],"batl":[[0,1.98,7.96]],"ltp":1.97,"tv":534.43,"id":40096589},{"trd":[[2.04,7.68]],"batb":[[0,1.96,42.31],[1,1.74,17.32],[2,1.25,100]],"ltp":2.04,"tv":217.6,"id":40096576}],"tv":752.03}]}
{"op":"mcm","clk":"11866441884","pt":1723465316930,"mc":[{"id":"1.231703146","rc":[{"batl":[[0,1.96,36.06],[1,1.98,7.96],[2,1.99,36.06]],"ltp":1.97,"tv":534.43,"id":40096589}]}]}
{"op":"mcm","clk":"11866452213","pt":1723465514801,"mc":[{"id":"1.231703146","rc":[{"batl":[[0,1.95,1],[1,1.96,36.06],[2,1.98,7.96]],"ltp":1.97,"tv":534.43,"id":40096589}]}]}
{"op":"mcm","clk":"11866453999","pt":1723465551252,"mc":[{"id":"1.231703146","rc":[{"batl":[[2,1.99,36.06]],"ltp":1.97,"tv":534.43,"id":40096589}]}]}
{"op":"mcm","clk":"11866456027","pt":1723465590200,"mc":[{"id":"1.231703146","rc":[{"batb":[[0,1.8,121.27],[1,1.79,13.24],[2,1.78,69.23]],"ltp":1.97,"tv":534.43,"id":40096589}]}]}
{"op":"mcm","clk":"11866456120","pt":1723465591898,"mc":[{"id":"1.231703146","rc":[{"batb":[[1,1.79,7.48]],"ltp":1.97,"tv":534.43,"id":40096589}]}]}
{"op":"mcm","clk":"11866458406","pt":1723465634247,"mc":[{"id":"1.231703146","rc":[{"batb":[[0,1.79,7.48],[1,1.78,69.23],[2,1.74,36.06]],"ltp":1.97,"tv":534.43,"id":40096589}]}]}
{"op":"mcm","clk":"11866469364","pt":1723465845413,"mc":[{"id":"1.231703146","rc":[{"batb":[[0,1.79,13.24]],"ltp":1.97,"tv":534.43,"id":40096589}]}]}
{"op":"mcm","clk":"11866473441","pt":1723465928338,"mc":[{"id":"1.231703146","rc":[{"batl":[[0,1.95,126.78]],"ltp":1.97,"tv":534.43,"id":40096589}]}]}
{"op":"mcm","clk":"11866476337","pt":1723465987674,"mc":[{"id":"1.231703146","rc":[{"trd":[[1.95,2]],"batl":[[0,1.96,36.79],[1,1.99,36.06],[2,1.99,0]],"ltp":1.95,"tv":536.43,"id":40096589}],"tv":754.03}]}
{"op":"mcm","clk":"11866478192","pt":1723466021525,"mc":[{"id":"1.231703146","rc":[{"batl":[[0,1.96,36.06]],"ltp":1.95,"tv":536.43,"id":40096589}]}]}
{"op":"mcm","clk":"11866481741","pt":1723466085581,"mc":[{"id":"1.231703146","rc":[{"batb":[[0,1.85,1.05],[1,1.79,13.24],[2,1.78,69.23]],"ltp":1.95,"tv":536.43,"id":40096589}]}]}
{"op":"mcm","clk":"11866482329","pt":1723466096749,"mc":[{"id":"1.231703146","rc":[{"batl":[[0,1.95,1],[1,1.96,36.06],[2,1.99,36.06]],"ltp":1.95,"tv":536.43,"id":40096589}]}]}
{"op":"mcm","clk":"11866493464","pt":1723466308205,"mc":[{"id":"1.231703146","rc":[{"batb":[[1,1.79,138.12]],"ltp":1.95,"tv":536.43,"id":40096589}]}]}
{"op":"mcm","clk":"11866495500","pt":1723466350737,"mc":[{"id":"1.231703146","rc":[{"trd":[[1.85,2.1]],"batb":[[0,1.79,138.12],[1,1.78,69.23],[2,1.74,36.06]],"batl":[[0,1.95,1.3]],"ltp":1.85,"tv":538.53,"id":40096589}],"tv":756.13}]}
{"op":"mcm","clk":"11866495997","pt":1723466360868,"mc":[{"id":"1.231703146","rc":[{"trd":[[1.79,26.48]],"batb":[[0,1.79,7.39]],"ltp":1.79,"tv":565.01,"id":40096589}],"tv":782.61}]}
{"op":"mcm","clk":"11866496058","pt":1723466362085,"mc":[{"id":"1.231703146","rc":[{"batl":[[0,1.95,6.59]],"ltp":1.79,"tv":565.01,"id":40096589}]}]}
{"op":"mcm","clk":"11866515111","pt":1723466633994,"mc":[{"id":"1.231703146","rc":[{"batl":[[0,2.28,4.46]],"ltp":2.04,"tv":217.6,"id":40096576}]}]}
{"op":"mcm","clk":"11866515141","pt":1723466634971,"mc":[{"id":"1.231703146","rc":[{"batl":[[0,1.94,31.85],[1,1.95,6.29],[2,1.96,36.06]],"ltp":1.79,"tv":565.01,"id":40096589}]}]}
{"op":"mcm","clk":"11866515204","pt":1723466636561,"mc":[{"id":"1.231703146","rc":[{"batl":[[0,1.93,5.64],[1,1.94,31.55],[2,1.95,1]],"ltp":1.79,"tv":565.01,"id":40096589}]}]}
{"op":"mcm","clk":"11866517233","pt":1723466688238,"mc":[{"id":"1.231703146","rc":[{"batl":[[0,2.28,4.46]],"ltp":2.04,"tv":217.6,"id":40096576}]}]}
{"op":"mcm","clk":"11866526593","pt":1723466906629,"mc":[{"id":"1.231703146","rc":[{"batl":[[0,1.93,122.58]],"ltp":1.79,"tv":565.01,"id":40096589}]}]}
{"op":"mcm","clk":"11866529297","pt":1723466959533,"mc":[{"id":"1.231703146","rc":[{"batl":[[0,2.28,4.46]],"ltp":2.04,"tv":217.6,"id":40096576}]}]}
{"op":"mcm","clk":"11866529586","pt":1723466965499,"mc":[{"id":"1.231703146","rc":[{"trd":[[1.93,10.68]],"batb":[[0,1.79,13.15]],"batl":[[0,1.93,5]],"ltp":1.93,"tv":575.68,"id":40096589}],"tv":793.29}]}
{"op":"mcm","clk":"11866556185","pt":1723467543247,"mc":[{"id":"1.231703146","rc":[{"batb":[[0,1.79,130.09]],"ltp":1.93,"tv":575.68,"id":40096589}]}]}
{"op":"mcm","clk":"11866556817","pt":1723467555263,"mc":[{"id":"1.231703146","rc":[{"batb":[[0,1.8,6.38],[1,1.79,130.09],[2,1.78,69.23]],"ltp":1.93,"tv":575.68,"id":40096589},{"batl":[[0,2.26,5.01]],"ltp":2.04,"tv":217.6,"id":40096576}]}]}
{"op":"mcm","clk":"11866559151","pt":1723467602966,"mc":[{"id":"1.231703146","rc":[{"batb":[[0,2.02,39.82],[1,1.96,42.31],[2,1.74,17.32]],"ltp":2.04,"tv":217.6,"id":40096576}]}]}
{"op":"mcm","clk":"11866559170","pt":1723467603180,"mc":[{"id":"1.231703146","rc":[{"trd":[[1.58,169.21]],"ltp":1.93,"tv":575.8,"id":40096589},{"trd":[[1.58,169.21]],"batb":[[0,2.04,10],[1,2.02,39.82]],"ltp":2.04,"tv":217.71,"id":40096576}],"tv":793.52}]}
{"op":"mcm","clk":"11866559413","pt":1723467606476,"mc":[{"id":"1.231703146","rc":[{"trd":[[1.79,26.48]],"ltp":1.93,"tv":575.81,"id":40096589},{"trd":[[2.04,7.69]],"batb":[[0,2.02,39.82],[1,1.74,17.32],[2,1.25,100]],"ltp":2.04,"tv":217.72,"id":40096576}],"tv":793.53}]}
{"op":"mcm","clk":"11866559521","pt":1723467608953,"mc":[{"id":"1.231703146","rc":[{"batb":[[0,2.04,10],[1,2.02,39.82],[2,1.74,17.32]],"ltp":2.04,"tv":217.72,"id":40096576}]}]}
{"op":"mcm","clk":"11866559735","pt":1723467613475,"mc":[{"id":"1.231703146","rc":[{"batb":[[0,2.02,39.82],[1,1.74,17.32],[2,1.25,100]],"ltp":2.04,"tv":217.72,"id":40096576}]}]}
{"op":"mcm","clk":"11866559895","pt":1723467617580,"mc":[{"id":"1.231703146","rc":[{"batb":[[0,2.04,10],[1,2.02,39.82],[2,1.74,17.32]],"ltp":2.04,"tv":217.72,"id":40096576}]}]}
{"op":"mcm","clk":"11866560073","pt":1723467620977,"mc":[{"id":"1.231703146","rc":[{"batb":[[0,2.02,39.82],[1,1.74,17.32],[2,1.25,100]],"ltp":2.04,"tv":217.72,"id":40096576}]}]}
{"op":"mcm","clk":"11866560181","pt":1723467623185,"mc":[{"id":"1.231703146","rc":[{"batb":[[0,2.04,10],[1,2.02,39.82],[2,1.74,17.32]],"ltp":2.04,"tv":217.72,"id":40096576}]}]}
{"op":"mcm","clk":"11866560459","pt":1723467627900,"mc":[{"id":"1.231703146","rc":[{"batb":[[0,2.02,39.82],[1,1.74,17.32],[2,1.25,100]],"ltp":2.04,"tv":217.72,"id":40096576}]}]}
{"op":"mcm","clk":"11866560758","pt":1723467634585,"mc":[{"id":"1.231703146","rc":[{"batb":[[0,2.04,10],[1,2.02,39.82],[2,1.74,17.32]],"ltp":2.04,"tv":217.72,"id":40096576}]}]}
{"op":"mcm","clk":"11866560980","pt":1723467637979,"mc":[{"id":"1.231703146","rc":[{"batb":[[0,2.02,39.82],[1,1.74,17.32],[2,1.25,100]],"ltp":2.04,"tv":217.72,"id":40096576}]}]}
{"op":"mcm","clk":"11866561179","pt":1723467641699,"mc":[{"id":"1.231703146","rc":[{"batb":[[0,2.04,10],[1,2.02,39.82],[2,1.74,17.32]],"ltp":2.04,"tv":217.72,"id":40096576}]}]}
{"op":"mcm","clk":"11866561386","pt":1723467645803,"mc":[{"id":"1.231703146","rc":[{"batb":[[0,2.02,39.82],[1,1.74,17.32],[2,1.25,100]],"ltp":2.04,"tv":217.72,"id":40096576}]}]}
{"op":"mcm","clk":"11866562188","pt":1723467660510,"mc":[{"id":"1.231703146","rc":[{"batb":[[0,2.04,10],[1,2.02,39.82],[2,1.74,17.32]],"ltp":2.04,"tv":217.72,"id":40096576}]}]}
{"op":"mcm","clk":"11866562374","pt":1723467664012,"mc":[{"id":"1.231703146","rc":[{"batb":[[0,2.02,39.82],[1,1.74,17.32],[2,1.25,100]],"ltp":2.04,"tv":217.72,"id":40096576}]}]}
{"op":"mcm","clk":"11866562805","pt":1723467672527,"mc":[{"id":"1.231703146","rc":[{"batb":[[0,2.04,10],[1,2.02,39.82],[2,1.74,17.32]],"ltp":2.04,"tv":217.72,"id":40096576}]}]}
{"op":"mcm","clk":"11866562966","pt":1723467675865,"mc":[{"id":"1.231703146","rc":[{"batb":[[0,2.02,39.82],[1,1.74,17.32],[2,1.25,100]],"ltp":2.04,"tv":217.72,"id":40096576}]}]}
{"op":"mcm","clk":"11866563398","pt":1723467683226,"mc":[{"id":"1.231703146","rc":[{"batb":[[0,2.04,10],[1,2.02,39.82],[2,1.74,17.32]],"ltp":2.04,"tv":217.72,"id":40096576}]}]}
{"op":"mcm","clk":"11866563589","pt":1723467687950,"mc":[{"id":"1.231703146","rc":[{"batb":[[0,2.02,39.82],[1,1.74,17.32],[2,1.25,100]],"ltp":2.04,"tv":217.72,"id":40096576}]}]}
{"op":"mcm","clk":"11866563925","pt":1723467694372,"mc":[{"id":"1.231703146","rc":[{"batb":[[0,2.04,10],[1,2.02,39.82],[2,1.74,17.32]],"ltp":2.04,"tv":217.72,"id":40096576}]}]}
{"op":"mcm","clk":"11866564093","pt":1723467697866,"mc":[{"id":"1.231703146","rc":[{"batb":[[0,2.02,39.82],[1,1.74,17.32],[2,1.25,100]],"ltp":2.04,"tv":217.72,"id":40096576}]}]}
{"op":"mcm","clk":"11866564298","pt":1723467701970,"mc":[{"id":"1.231703146","rc":[{"batb":[[0,2.04,10],[1,2.02,39.82],[2,1.74,17.32]],"ltp":2.04,"tv":217.72,"id":40096576}]}]}
{"op":"mcm","clk":"11866564510","pt":1723467706583,"mc":[{"id":"1.231703146","rc":[{"batb":[[0,2.02,39.82],[1,1.74,17.32],[2,1.25,100]],"ltp":2.04,"tv":217.72,"id":40096576}]}]}
{"op":"mcm","clk":"11866564830","pt":1723467713201,"mc":[{"id":"1.231703146","rc":[{"batb":[[0,2.04,10],[1,2.02,39.82],[2,1.74,17.32]],"ltp":2.04,"tv":217.72,"id":40096576}]}]}
{"op":"mcm","clk":"11866565022","pt":1723467717712,"mc":[{"id":"1.231703146","rc":[{"batb":[[0,2.02,39.82],[1,1.74,17.32],[2,1.25,100]],"ltp":2.04,"tv":217.72,"id":40096576}]}]}
{"op":"mcm","clk":"11866565110","pt":1723467719972,"mc":[{"id":"1.231703146","rc":[{"batb":[[0,2.04,10],[1,2.02,39.82],[2,1.74,17.32]],"ltp":2.04,"tv":217.72,"id":40096576}]}]}
{"op":"mcm","clk":"11866565251","pt":1723467723513,"mc":[{"id":"1.231703146","rc":[{"batb":[[0,2.02,39.82],[1,1.74,17.32],[2,1.25,100]],"ltp":2.04,"tv":217.72,"id":40096576}]}]}
{"op":"mcm","clk":"11866565851","pt":1723467735007,"mc":[{"id":"1.231703146","rc":[{"batb":[[0,2.04,10],[1,2.02,39.82],[2,1.74,17.32]],"ltp":2.04,"tv":217.72,"id":40096576}]}]}
{"op":"mcm","clk":"11866566020","pt":1723467738905,"mc":[{"id":"1.231703146","rc":[{"batb":[[0,2.02,39.82],[1,1.74,17.32],[2,1.25,100]],"ltp":2.04,"tv":217.72,"id":40096576}]}]}
{"op":"mcm","clk":"11866566187","pt":1723467742442,"mc":[{"id":"1.231703146","rc":[{"batb":[[0,2.04,10],[1,2.02,39.82],[2,1.74,17.32]],"ltp":2.04,"tv":217.72,"id":40096576}]}]}
{"op":"mcm","clk":"11866566364","pt":1723467746039,"mc":[{"id":"1.231703146","rc":[{"batb":[[0,2.02,39.82],[1,1.74,17.32],[2,1.25,100]],"ltp":2.04,"tv":217.72,"id":40096576}]}]}
{"op":"mcm","clk":"11866566545","pt":1723467749528,"mc":[{"id":"1.231703146","rc":[{"batb":[[0,2.04,10],[1,2.02,39.82],[2,1.74,17.32]],"ltp":2.04,"tv":217.72,"id":40096576}]}]}
{"op":"mcm","clk":"11866566786","pt":1723467753950,"mc":[{"id":"1.231703146","rc":[{"batb":[[0,2.02,39.82],[1,1.74,17.32],[2,1.25,100]],"ltp":2.04,"tv":217.72,"id":40096576}]}]}
{"op":"mcm","clk":"11866567013","pt":1723467759034,"mc":[{"id":"1.231703146","rc":[{"batb":[[0,2.04,10],[1,2.02,39.82],[2,1.74,17.32]],"ltp":2.04,"tv":217.72,"id":40096576}]}]}
{"op":"mcm","clk":"11866567145","pt":1723467762627,"mc":[{"id":"1.231703146","rc":[{"batb":[[0,2.02,39.82],[1,1.74,17.32],[2,1.25,100]],"ltp":2.04,"tv":217.72,"id":40096576}]}]}
{"op":"mcm","clk":"11866567199","pt":1723467763750,"mc":[{"id":"1.231703146","rc":[{"batb":[[2,1.74,36.06]],"ltp":1.93,"tv":575.81,"id":40096589}]}]}
{"op":"mcm","clk":"11866567441","pt":1723467768678,"mc":[{"id":"1.231703146","rc":[{"batb":[[0,2.04,10],[1,2.02,39.82],[2,1.74,17.32]],"ltp":2.04,"tv":217.72,"id":40096576}]}]}
{"op":"mcm","clk":"11866567609","pt":1723467772940,"mc":[{"id":"1.231703146","rc":[{"batb":[[0,1.83,60.92],[1,1.8,6.38],[2,1.79,130.09]],"ltp":1.93,"tv":575.81,"id":40096589},{"batb":[[0,2.02,39.82],[1,1.74,17.32],[2,1.25,100]],"ltp":2.04,"tv":217.72,"id":40096576}]}]}
{"op":"mcm","clk":"11866567697","pt":1723467774940,"mc":[{"id":"1.231703146","rc":[{"batb":[[1,1.79,124.33],[2,1.74,36.06]],"ltp":1.93,"tv":575.81,"id":40096589},{"batb":[[0,2.04,10],[1,2.02,39.82],[2,1.74,17.32]],"ltp":2.04,"tv":217.72,"id":40096576}]}]}
{"op":"mcm","clk":"11866567842","pt":1723467778587,"mc":[{"id":"1.231703146","rc":[{"batb":[[0,2.02,39.82],[1,1.74,17.32],[2,1.25,100]],"ltp":2.04,"tv":217.72,"id":40096576}]}]}
{"op":"mcm","clk":"11866569232","pt":1723467806495,"mc":[{"id":"1.231703146","rc":[{"batl":[[0,1.94,31.55],[1,1.95,1],[2,1.96,36.06]],"ltp":1.93,"tv":575.81,"id":40096589}]}]}
{"op":"mcm","clk":"11866569318","pt":1723467808189,"mc":[{"id":"1.231703146","rc":[{"batb":[[1,1.79,116.94]],"ltp":1.93,"tv":575.81,"id":40096589}]}]}
{"op":"mcm","clk":"11866569490","pt":1723467811693,"mc":[{"id":"1.231703146","rc":[{"batb":[[1,1.74,36.06],[2,1.68,138.46]],"ltp":1.93,"tv":575.81,"id":40096589}]}]}
{"op":"mcm","clk":"11866571297","pt":1723467845229,"mc":[{"id":"1.231703146","rc":[{"batb":[[1,1.8,116.94],[2,1.74,36.06]],"ltp":1.93,"tv":575.81,"id":40096589}]}]}
{"op":"mcm","clk":"11866571881","pt":1723467857038,"mc":[{"id":"1.231703146","rc":[{"batb":[[0,1.84,116.94],[1,1.83,60.92]],"ltp":1.93,"tv":575.81,"id":40096589}]}]}
{"op":"mcm","clk":"11866574453","pt":1723467905096,"mc":[{"id":"1.231703146","rc":[{"batb":[[0,1.83,61.1],[1,1.74,36.06],[2,1.68,138.46]],"ltp":1.93,"tv":575.81,"id":40096589}]}]}
{"op":"mcm","clk":"11866586429","pt":1723468116424,"mc":[{"id":"1.231703146","rc":[{"batb":[[0,1.84,4.77],[1,1.83,60.92],[2,1.74,36.06]],"ltp":1.93,"tv":575.81,"id":40096589}]}]}
{"op":"mcm","clk":"11866623534","pt":1723468759273,"mc":[{"id":"1.231703146","rc":[{"batb":[[0,1.84,4.59]],"ltp":1.93,"tv":575.81,"id":40096589}]}]}
{"op":"mcm","clk":"11866627192","pt":1723468814255,"mc":[{"id":"1.231703146","rc":[{"batb":[[0,1.92,2.35],[1,1.84,4.59],[2,1.83,60.92]],"ltp":1.93,"tv":575.81,"id":40096589}]}]}
{"op":"mcm","clk":"11866628089","pt":1723468829281,"mc":[{"id":"1.231703146","rc":[{"batb":[[0,1.84,4.59],[1,1.83,60.92],[2,1.74,36.06]],"ltp":1.93,"tv":575.81,"id":40096589}]}]}
{"op":"mcm","clk":"11866667726","pt":1723469483812,"mc":[{"id":"1.231703146","rc":[{"batl":[[0,1.93,1],[1,1.94,31.55]],"ltp":1.93,"tv":575.81,"id":40096589}]}]}
{"op":"mcm","clk":"11866668262","pt":1723469493217,"mc":[{"id":"1.231703146","rc":[{"batl":[[0,1.93,2]],"ltp":1.93,"tv":575.81,"id":40096589}]}]}
{"op":"mcm","clk":"11866681566","pt":1723469715459,"mc":[{"id":"1.231703146","rc":[{"batb":[[0,2.02,37.98]],"ltp":2.04,"tv":217.72,"id":40096576}]}]}
{"op":"mcm","clk":"11866701399","pt":1723470012265,"mc":[{"id":"1.231703146","rc":[{"batl":[[0,2.2,1]],"ltp":2.04,"tv":217.72,"id":40096576}]}]}
{"op":"mcm","clk":"11866701529","pt":1723470013974,"mc":[{"id":"1.231703146","rc":[{"batb":[[0,2.04,10],[1,2.02,37.98],[2,1.74,17.32]],"ltp":2.04,"tv":217.72,"id":40096576}]}]}
{"op":"mcm","clk":"11866701866","pt":1723470018157,"mc":[{"id":"1.231703146","rc":[{"batb":[[0,2.02,37.98],[1,1.74,17.32],[2,1.25,100]],"ltp":2.04,"tv":217.72,"id":40096576}]}]}
{"op":"mcm","clk":"11866702247","pt":1723470023671,"mc":[{"id":"1.231703146","rc":[{"batb":[[0,2.04,10],[1,2.02,37.98],[2,1.74,17.32]],"ltp":2.04,"tv":217.72,"id":40096576}]}]}
{"op":"mcm","clk":"11866702462","pt":1723470026974,"mc":[{"id":"1.231703146","rc":[{"batb":[[0,2.02,37.98],[1,1.74,17.32],[2,1.25,100]],"ltp":2.04,"tv":217.72,"id":40096576}]}]}
{"op":"mcm","clk":"11866705320","pt":1723470069652,"mc":[{"id":"1.231703146","rc":[{"batb":[[0,2.04,10],[1,2.02,37.98],[2,1.74,17.32]],"ltp":2.04,"tv":217.72,"id":40096576}]}]}
{"op":"mcm","clk":"11866705546","pt":1723470073353,"mc":[{"id":"1.231703146","rc":[{"batb":[[0,2.02,37.98],[1,1.74,17.32],[2,1.25,100]],"ltp":2.04,"tv":217.72,"id":40096576}]}]}
{"op":"mcm","clk":"11866706454","pt":1723470085870,"mc":[{"id":"1.231703146","rc":[{"batb":[[0,2.04,10],[1,2.02,37.98],[2,1.74,17.32]],"ltp":2.04,"tv":217.72,"id":40096576}]}]}
{"op":"mcm","clk":"11866706620","pt":1723470089616,"mc":[{"id":"1.231703146","rc":[{"batb":[[0,2.02,37.98],[1,1.74,17.32],[2,1.25,100]],"ltp":2.04,"tv":217.72,"id":40096576}]}]}
{"op":"mcm","clk":"11866707404","pt":1723470105637,"mc":[{"id":"1.231703146","rc":[{"batb":[[0,2.04,10],[1,2.02,37.98],[2,1.74,17.32]],"ltp":2.04,"tv":217.72,"id":40096576}]}]}
{"op":"mcm","clk":"11866707613","pt":1723470110420,"mc":[{"id":"1.231703146","rc":[{"batb":[[0,2.02,37.98],[1,1.74,17.32],[2,1.25,100]],"ltp":2.04,"tv":217.72,"id":40096576}]}]}
{"op":"mcm","clk":"11866707720","pt":1723470112836,"mc":[{"id":"1.231703146","rc":[{"batb":[[0,2.04,10],[1,2.02,37.98],[2,1.74,17.32]],"ltp":2.04,"tv":217.72,"id":40096576}]}]}
{"op":"mcm","clk":"11866707930","pt":1723470117943,"mc":[{"id":"1.231703146","rc":[{"batb":[[0,2.02,37.98],[1,1.74,17.32],[2,1.25,100]],"ltp":2.04,"tv":217.72,"id":40096576}]}]}
{"op":"mcm","clk":"11866708757","pt":1723470133166,"mc":[{"id":"1.231703146","rc":[{"batb":[[0,2.04,10],[1,2.02,37.98],[2,1.74,17.32]],"ltp":2.04,"tv":217.72,"id":40096576}]}]}
{"op":"mcm","clk":"11866708951","pt":1723470136855,"mc":[{"id":"1.231703146","rc":[{"batb":[[0,2.02,37.98],[1,1.74,17.32],[2,1.25,100]],"ltp":2.04,"tv":217.72,"id":40096576}]}]}
{"op":"mcm","clk":"11866710122","pt":1723470158872,"mc":[{"id":"1.231703146","rc":[{"batb":[[0,2.04,10],[1,2.02,37.98],[2,1.74,17.32]],"ltp":2.04,"tv":217.72,"id":40096576}]}]}
{"op":"mcm","clk":"11866710323","pt":1723470162793,"mc":[{"id":"1.231703146","rc":[{"batb":[[0,2.02,37.98],[1,1.74,17.32],[2,1.25,100]],"ltp":2.04,"tv":217.72,"id":40096576}]}]}
{"op":"mcm","clk":"11866710436","pt":1723470165118,"mc":[{"id":"1.231703146","rc":[{"batb":[[0,2.04,10],[1,2.02,37.98],[2,1.74,17.32]],"ltp":2.04,"tv":217.72,"id":40096576}]}]}
{"op":"mcm","clk":"11866710686","pt":1723470169709,"mc":[{"id":"1.231703146","rc":[{"batb":[[0,2.02,37.98],[1,1.74,17.32],[2,1.25,100]],"ltp":2.04,"tv":217.72,"id":40096576}]}]}
{"op":"mcm","clk":"11866712462","pt":1723470202474,"mc":[{"id":"1.231703146","rc":[{"batb":[[0,2.04,10],[1,2.02,37.98],[2,1.74,17.32]],"ltp":2.04,"tv":217.72,"id":40096576}]}]}
{"op":"mcm","clk":"11866712709","pt":1723470206459,"mc":[{"id":"1.231703146","rc":[{"batb":[[0,2.02,37.98],[1,1.74,17.32],[2,1.25,100]],"ltp":2.04,"tv":217.72,"id":40096576}]}]}
{"op":"mcm","clk":"11866712966","pt":1723470211671,"mc":[{"id":"1.231703146","rc":[{"batb":[[0,2.04,10],[1,2.02,37.98],[2,1.74,17.32]],"ltp":2.04,"tv":217.72,"id":40096576}]}]}
{"op":"mcm","clk":"11866713177","pt":1723470215257,"mc":[{"id":"1.231703146","rc":[{"batb":[[0,2.02,37.98],[1,1.74,17.32],[2,1.25,100]],"ltp":2.04,"tv":217.72,"id":40096576}]}]}
{"op":"mcm","clk":"11866713864","pt":1723470228902,"mc":[{"id":"1.231703146","rc":[{"batb":[[0,2.04,10],[1,2.02,37.98],[2,1.74,17.32]],"ltp":2.04,"tv":217.72,"id":40096576}]}]}
{"op":"mcm","clk":"11866714126","pt":1723470233516,"mc":[{"id":"1.231703146","rc":[{"batb":[[0,2.02,37.98],[1,1.74,17.32],[2,1.25,100]],"ltp":2.04,"tv":217.72,"id":40096576}]}]}
{"op":"mcm","clk":"11866714464","pt":1723470239416,"mc":[{"id":"1.231703146","rc":[{"batb":[[0,2.04,10],[1,2.02,37.98],[2,1.74,17.32]],"ltp":2.04,"tv":217.72,"id":40096576}]}]}
{"op":"mcm","clk":"11866714650","pt":1723470242700,"mc":[{"id":"1.231703146","rc":[{"batb":[[0,2.02,37.98],[1,1.74,17.32],[2,1.25,100]],"ltp":2.04,"tv":217.72,"id":40096576}]}]}
{"op":"mcm","clk":"11866715006","pt":1723470248305,"mc":[{"id":"1.231703146","rc":[{"batb":[[0,2.04,10],[1,2.02,37.98],[2,1.74,17.32]],"ltp":2.04,"tv":217.72,"id":40096576}]}]}
{"op":"mcm","clk":"11866715296","pt":1723470252935,"mc":[{"id":"1.231703146","rc":[{"batb":[[0,2.02,37.98],[1,1.74,17.32],[2,1.25,100]],"ltp":2.04,"tv":217.72,"id":40096576}]}]}
{"op":"mcm","clk":"11866715957","pt":1723470264716,"mc":[{"id":"1.231703146","rc":[{"batb":[[0,2.04,10],[1,2.02,37.98],[2,1.74,17.32]],"ltp":2.04,"tv":217.72,"id":40096576}]}]}
{"op":"mcm","clk":"11866716175","pt":1723470268343,"mc":[{"id":"1.231703146","rc":[{"batb":[[0,2.02,37.98],[1,1.74,17.32],[2,1.25,100]],"ltp":2.04,"tv":217.72,"id":40096576}]}]}
{"op":"mcm","clk":"11866719225","pt":1723470322021,"mc":[{"id":"1.231703146","rc":[{"batb":[[0,2.04,10],[1,2.02,37.98],[2,1.74,17.32]],"ltp":2.04,"tv":217.72,"id":40096576}]}]}
{"op":"mcm","clk":"11866719446","pt":1723470325605,"mc":[{"id":"1.231703146","rc":[{"batb":[[0,2.02,37.98],[1,1.74,17.32],[2,1.25,100]],"ltp":2.04,"tv":217.72,"id":40096576}]}]}
{"op":"mcm","clk":"11866720877","pt":1723470352037,"mc":[{"id":"1.231703146","rc":[{"batb":[[0,2.04,10],[1,2.02,37.98],[2,1.74,17.32]],"ltp":2.04,"tv":217.72,"id":40096576}]}]}
{"op":"mcm","clk":"11866721098","pt":1723470356212,"mc":[{"id":"1.231703146","rc":[{"batb":[[0,2.02,37.98],[1,1.74,17.32],[2,1.25,100]],"ltp":2.04,"tv":217.72,"id":40096576}]}]}
{"op":"mcm","clk":"11866721292","pt":1723470359553,"mc":[{"id":"1.231703146","rc":[{"batb":[[0,2.04,10],[1,2.02,37.98],[2,1.74,17.32]],"ltp":2.04,"tv":217.72,"id":40096576}]}]}
{"op":"mcm","clk":"11866721702","pt":1723470367244,"mc":[{"id":"1.231703146","rc":[{"batb":[[0,2.02,37.98],[1,1.74,17.32],[2,1.25,100]],"ltp":2.04,"tv":217.72,"id":40096576}]}]}
{"op":"mcm","clk":"11866721838","pt":1723470369924,"mc":[{"id":"1.231703146","rc":[{"batb":[[0,2.04,10],[1,2.02,37.98],[2,1.74,17.32]],"ltp":2.04,"tv":217.72,"id":40096576}]}]}
{"op":"mcm","clk":"11866722098","pt":1723470374560,"mc":[{"id":"1.231703146","rc":[{"batb":[[0,2.02,37.98],[1,1.74,17.32],[2,1.25,100]],"ltp":2.04,"tv":217.72,"id":40096576}]}]}
{"op":"mcm","clk":"11866723264","pt":1723470395180,"mc":[{"id":"1.231703146","rc":[{"batb":[[0,2.04,10],[1,2.02,37.98],[2,1.74,17.32]],"ltp":2.04,"tv":217.72,"id":40096576}]}]}
{"op":"mcm","clk":"11866723606","pt":1723470401588,"mc":[{"id":"1.231703146","rc":[{"batb":[[0,2.02,37.98],[1,1.74,17.32],[2,1.25,100]],"ltp":2.04,"tv":217.72,"id":40096576}]}]}
{"op":"mcm","clk":"11866738254","pt":1723470677140,"mc":[{"id":"1.231703146","rc":[{"trd":[[1.83,10.82],[1.84,9.18]],"batb":[[0,1.83,55.51],[1,1.74,36.06],[2,1.68,138.46]],"ltp":1.83,"tv":595.8,"id":40096589}],"tv":813.52}]}
{"op":"mcm","clk":"11866738323","pt":1723470678222,"mc":[{"id":"1.231703146","rc":[{"batl":[[0,1.93,6.37]],"ltp":1.83,"tv":595.8,"id":40096589}]}]}
{"op":"mcm","clk":"11866758679","pt":1723471058475,"mc":[{"id":"1.231703146","rc":[{"trd":[[1.83,12.78]],"batb":[[0,1.83,54.53]],"ltp":1.83,"tv":597.76,"id":40096589}],"tv":815.48}]}
{"op":"mcm","clk":"11866776869","pt":1723471334569,"mc":[{"id":"1.231703146","rc":[{"trd":[[1.58,169.19],[1.79,26.48]],"batb":[[1,1.77,3.35],[2,1.74,36.06]],"ltp":1.83,"tv":597.74,"id":40096589},{"trd":[[1.58,169.19],[2.04,7.68]],"batb":[[0,2.04,10],[1,2.02,37.98],[2,1.74,17.32]],"ltp":2.04,"tv":217.69,"id":40096576}],"tv":815.44}]}
{"op":"mcm","clk":"11866776926","pt":1723471335448,"mc":[{"id":"1.231703146","rc":[{"batb":[[1,1.74,36.06],[2,1.68,138.46]],"ltp":1.83,"tv":597.74,"id":40096589}]}]}
{"op":"mcm","clk":"11866777065","pt":1723471337833,"mc":[{"id":"1.231703146","rc":[{"batb":[[0,2.02,37.98],[1,1.74,17.32],[2,1.25,100]],"ltp":2.04,"tv":217.69,"id":40096576}]}]}
{"op":"mcm","clk":"11866805239","pt":1723471851115,"mc":[{"id":"1.231703146","rc":[{"batb":[[0,2.04,10],[1,2.02,37.98],[2,1.74,17.32]],"ltp":2.04,"tv":217.69,"id":40096576}]}]}
{"op":"mcm","clk":"11866805578","pt":1723471856606,"mc":[{"id":"1.231703146","rc":[{"batb":[[0,2.02,37.98],[1,1.74,17.32],[2,1.25,100]],"ltp":2.04,"tv":217.69,"id":40096576}]}]}
{"op":"mcm","clk":"11866805791","pt":1723471860953,"mc":[{"id":"1.231703146","rc":[{"batb":[[0,2.04,10],[1,2.02,37.98],[2,1.74,17.32]],"ltp":2.04,"tv":217.69,"id":40096576}]}]}
{"op":"mcm","clk":"11866806391","pt":1723471870248,"mc":[{"id":"1.231703146","rc":[{"batb":[[0,2.02,37.98],[1,1.74,17.32],[2,1.25,100]],"ltp":2.04,"tv":217.69,"id":40096576}]}]}
{"op":"mcm","clk":"11866806688","pt":1723471875330,"mc":[{"id":"1.231703146","rc":[{"batb":[[0,2.04,10],[1,2.02,37.98],[2,1.74,17.32]],"ltp":2.04,"tv":217.69,"id":40096576}]}]}
{"op":"mcm","clk":"11866807071","pt":1723471881989,"mc":[{"id":"1.231703146","rc":[{"batb":[[0,2.02,37.98],[1,1.74,17.32],[2,1.25,100]],"ltp":2.04,"tv":217.69,"id":40096576}]}]}
{"op":"mcm","clk":"11866868532","pt":1723472817005,"mc":[{"id":"1.231703146","rc":[{"batb":[[1,1.77,3.35],[2,1.74,36.06]],"ltp":1.83,"tv":597.74,"id":40096589}]}]}
{"op":"mcm","clk":"11866868615","pt":1723472818602,"mc":[{"id":"1.231703146","rc":[{"batb":[[1,1.74,36.06],[2,1.68,138.46]],"ltp":1.83,"tv":597.74,"id":40096589},{"batb":[[0,2.04,10],[1,2.02,37.98],[2,1.74,17.32]],"ltp":2.04,"tv":217.69,"id":40096576}]}]}
{"op":"mcm","clk":"11866868847","pt":1723472822523,"mc":[{"id":"1.231703146","rc":[{"batb":[[0,2.02,37.98],[1,1.74,17.32],[2,1.25,100]],"ltp":2.04,"tv":217.69,"id":40096576}]}]}
{"op":"mcm","clk":"11866894568","pt":1723473236207,"mc":[{"id":"1.231703146","rc":[{"batb":[[0,2.04,10],[1,2.02,37.98],[2,1.74,17.32]],"ltp":2.04,"tv":217.69,"id":40096576}]}]}
{"op":"mcm","clk":"11866895095","pt":1723473243408,"mc":[{"id":"1.231703146","rc":[{"batb":[[0,2.02,37.98],[1,1.74,17.32],[2,1.25,100]],"ltp":2.04,"tv":217.69,"id":40096576}]}]}
{"op":"mcm","clk":"11866895498","pt":1723473249508,"mc":[{"id":"1.231703146","rc":[{"batb":[[0,2.04,10],[1,2.02,37.98],[2,1.74,17.32]],"ltp":2.04,"tv":217.69,"id":40096576}]}]}
{"op":"mcm","clk":"11866896011","pt":1723473257198,"mc":[{"id":"1.231703146","rc":[{"batb":[[0,2.02,37.98],[1,1.74,17.32],[2,1.25,100]],"ltp":2.04,"tv":217.69,"id":40096576}]}]}
{"op":"mcm","clk":"11866937634","pt":1723473964867,"mc":[{"id":"1.231703146","rc":[{"batb":[[0,1.83,561.26]],"ltp":1.83,"tv":597.74,"id":40096589}]}]}
{"op":"mcm","clk":"11866946182","pt":1723474109331,"mc":[{"id":"1.231703146","rc":[{"batb":[[1,1.8,3.35],[2,1.74,36.06]],"ltp":1.83,"tv":597.74,"id":40096589}]}]}
{"op":"mcm","clk":"11866946249","pt":1723474110412,"mc":[{"id":"1.231703146","rc":[{"batb":[[1,1.74,36.06],[2,1.68,138.46]],"ltp":1.83,"tv":597.74,"id":40096589}]}]}
{"op":"mcm","clk":"11866953379","pt":1723474238675,"mc":[{"id":"1.231703146","rc":[{"batl":[[0,2.2,18.11]],"ltp":2.04,"tv":217.69,"id":40096576}]}]}
{"op":"mcm","clk":"11866963836","pt":1723474405162,"mc":[{"id":"1.231703146","rc":[{"batb":[[0,1.84,17.44],[1,1.83,561.26],[2,1.74,36.06]],"ltp":1.83,"tv":597.74,"id":40096589}]}]}
{"op":"mcm","clk":"11867000187","pt":1723474990717,"mc":[{"id":"1.231703146","rc":[{"trd":[[1.58,168.95],[1.79,26.46],[1.83,12.78],[1.84,9.17],[1.91,148.74],[1.93,10.67]],"batb":[[0,1.84,17.42],[2,1.79,444]],"batl":[[0,1.93,6.37]],"ltp":1.83,"tv":597.48,"id":40096589},{"trd":[[1.58,168.95],[2.04,7.67]],"batb":[[0,2.04,10],[1,2.02,37.98],[2,1.74,17.32]],"batl":[[0,2.2,18.1]],"ltp":2.04,"tv":217.45,"id":40096576}],"tv":814.93}]}
{"op":"mcm","clk":"11867000458","pt":1723474994112,"mc":[{"id":"1.231703146","rc":[{"batb":[[0,2.02,37.98],[1,1.74,17.32],[2,1.25,100]],"ltp":2.04,"tv":217.45,"id":40096576}]}]}
{"op":"mcm","clk":"11867028393","pt":1723475396450,"mc":[{"id":"1.231703146","rc":[{"batb":[[0,2.04,10],[1,2.02,37.98],[2,1.74,17.32]],"ltp":2.04,"tv":217.45,"id":40096576}]}]}
{"op":"mcm","clk":"11867028610","pt":1723475399656,"mc":[{"id":"1.231703146","rc":[{"batb":[[0,2.02,37.98],[1,1.74,17.32],[2,1.25,100]],"ltp":2.04,"tv":217.45,"id":40096576}]}]}
{"op":"mcm","clk":"11867029352","pt":1723475410497,"mc":[{"id":"1.231703146","rc":[{"batb":[[2,1.78,444]],"ltp":1.83,"tv":597.48,"id":40096589}]}]}
{"op":"mcm","clk":"11867029420","pt":1723475411180,"mc":[{"id":"1.231703146","rc":[{"batb":[[0,2.04,10],[1,2.02,37.98],[2,1.74,17.32]],"ltp":2.04,"tv":217.45,"id":40096576}]}]}
{"op":"mcm","clk":"11867029797","pt":1723475416281,"mc":[{"id":"1.231703146","rc":[{"batb":[[0,2.02,37.98],[1,1.74,17.32],[2,1.25,100]],"ltp":2.04,"tv":217.45,"id":40096576}]}]}
{"op":"mcm","clk":"11867049826","pt":1723475703027,"mc":[{"id":"1.231703146","rc":[{"batb":[[0,2.04,10],[1,2.02,37.98],[2,1.74,17.32]],"ltp":2.04,"tv":217.45,"id":40096576}]}]}
{"op":"mcm","clk":"11867050100","pt":1723475706549,"mc":[{"id":"1.231703146","rc":[{"batb":[[0,2.02,37.98],[1,1.74,17.32],[2,1.25,100]],"ltp":2.04,"tv":217.45,"id":40096576}]}]}
{"op":"mcm","clk":"11867056283","pt":1723475795647,"mc":[{"id":"1.231703146","rc":[{"batb":[[0,2.04,10],[1,2.02,37.98],[2,1.74,17.32]],"ltp":2.04,"tv":217.45,"id":40096576}]}]}
{"op":"mcm","clk":"11867056501","pt":1723475799352,"mc":[{"id":"1.231703146","rc":[{"batb":[[0,2.02,37.98],[1,1.74,17.32],[2,1.25,100]],"ltp":2.04,"tv":217.45,"id":40096576}]}]}
{"op":"mcm","clk":"11867069302","pt":1723475996149,"mc":[{"id":"1.231703146","rc":[{"batb":[[0,2.04,10],[1,2.02,37.98],[2,1.74,17.32]],"ltp":2.04,"tv":217.45,"id":40096576}]}]}
{"op":"mcm","clk":"11867069605","pt":1723476000556,"mc":[{"id":"1.231703146","rc":[{"batb":[[0,2.02,37.98],[1,1.74,17.32],[2,1.25,100]],"ltp":2.04,"tv":217.45,"id":40096576}]}]}
{"op":"mcm","clk":"11867076007","pt":1723476090462,"mc":[{"id":"1.231703146","rc":[{"batb":[[0,2.04,10],[1,2.02,37.98],[2,1.74,17.32]],"ltp":2.04,"tv":217.45,"id":40096576}]}]}
{"op":"mcm","clk":"11867076253","pt":1723476094193,"mc":[{"id":"1.231703146","rc":[{"batb":[[0,2.02,37.98],[1,1.74,17.32],[2,1.25,100]],"ltp":2.04,"tv":217.45,"id":40096576}]}]}
{"op":"mcm","clk":"11867092312","pt":1723476313790,"mc":[{"id":"1.231703146","rc":[{"batb":[[1,1.83,506.73]],"ltp":1.83,"tv":597.48,"id":40096589},{"batb":[[0,2.04,10],[1,2.02,37.98],[2,1.74,17.32]],"ltp":2.04,"tv":217.45,"id":40096576}]}]}
{"op":"mcm","clk":"11867092579","pt":1723476317175,"mc":[{"id":"1.231703146","rc":[{"batb":[[0,2.02,37.98],[1,1.74,17.32],[2,1.25,100]],"ltp":2.04,"tv":217.45,"id":40096576}]}]}
{"op":"mcm","clk":"11867093059","pt":1723476323500,"mc":[{"id":"1.231703146","rc":[{"batb":[[0,1.86,52.62],[1,1.84,17.42],[2,1.83,506.73]],"ltp":1.83,"tv":597.48,"id":40096589},{"batb":[[0,2.04,10],[1,2.02,37.98],[2,1.74,17.32]],"ltp":2.04,"tv":217.45,"id":40096576}]}]}
{"op":"mcm","clk":"11867093168","pt":1723476324797,"mc":[{"id":"1.231703146","rc":[{"batb":[[1,1.83,506.73],[2,1.78,444]],"ltp":1.83,"tv":597.48,"id":40096589}]}]}
{"op":"mcm","clk":"11867093233","pt":1723476325731,"mc":[{"id":"1.231703146","rc":[{"batl":[[0,2.2,1]],"ltp":2.04,"tv":217.45,"id":40096576}]}]}
{"op":"mcm","clk":"11867093312","pt":1723476326926,"mc":[{"id":"1.231703146","rc":[{"batb":[[0,2.02,37.98],[1,1.74,17.32],[2,1.25,100]],"ltp":2.04,"tv":217.45,"id":40096576}]}]}
{"op":"mcm","clk":"11867093872","pt":1723476334316,"mc":[{"id":"1.231703146","rc":[{"batb":[[0,2.04,10],[1,2.02,37.98],[2,1.74,17.32]],"ltp":2.04,"tv":217.45,"id":40096576}]}]}
{"op":"mcm","clk":"11867094117","pt":1723476337637,"mc":[{"id":"1.231703146","rc":[{"batb":[[0,2.02,37.98],[1,1.74,17.32],[2,1.25,100]],"ltp":2.04,"tv":217.45,"id":40096576}]}]}
{"op":"mcm","clk":"11867109048","pt":1723476537198,"mc":[{"id":"1.231703146","rc":[{"batb":[[0,2.04,10],[1,2.02,37.98],[2,1.74,17.32]],"ltp":2.04,"tv":217.45,"id":40096576}]}]}
{"op":"mcm","clk":"11867109449","pt":1723476541511,"mc":[{"id":"1.231703146","rc":[{"batb":[[0,2.02,37.98],[1,1.74,17.32],[2,1.25,100]],"ltp":2.04,"tv":217.45,"id":40096576}]}]}
{"op":"mcm","clk":"11867109819","pt":1723476545123,"mc":[{"id":"1.231703146","rc":[{"batb":[[0,2.04,10],[1,2.02,37.98],[2,1.74,17.32]],"ltp":2.04,"tv":217.45,"id":40096576}]}]}
{"op":"mcm","clk":"11867110526","pt":1723476554128,"mc":[{"id":"1.231703146","rc":[{"batb":[[0,2.02,37.98],[1,1.74,17.32],[2,1.25,100]],"ltp":2.04,"tv":217.45,"id":40096576}]}]}
{"op":"mcm","clk":"11867110840","pt":1723476558445,"mc":[{"id":"1.231703146","rc":[{"batb":[[0,2.04,10],[1,2.02,37.98],[2,1.74,17.32]],"ltp":2.04,"tv":217.45,"id":40096576}]}]}
{"op":"mcm","clk":"11867111248","pt":1723476564666,"mc":[{"id":"1.231703146","rc":[{"batb":[[0,2.02,37.98],[1,1.74,17.32],[2,1.25,100]],"ltp":2.04,"tv":217.45,"id":40096576}]}]}
{"op":"mcm","clk":"11867112966","pt":1723476589816,"mc":[{"id":"1.231703146","rc":[{"batl":[[2,1.98,13.85]],"ltp":1.83,"tv":597.48,"id":40096589}]}]}
{"op":"mcm","clk":"11867113057","pt":1723476590895,"mc":[{"id":"1.231703146","rc":[{"batb":[[0,2.04,10],[1,2.02,37.98],[2,1.74,17.32]],"ltp":2.04,"tv":217.45,"id":40096576}]}]}
{"op":"mcm","clk":"11867113272","pt":1723476593681,"mc":[{"id":"1.231703146","rc":[{"batl":[[1,1.98,13.85],[2,1.98,0]],"ltp":1.83,"tv":597.48,"id":40096589}]}]}
{"op":"mcm","clk":"11867113366","pt":1723476594986,"mc":[{"id":"1.231703146","rc":[{"batl":[[0,1.93,2]],"ltp":1.83,"tv":597.48,"id":40096589},{"batb":[[0,2.02,37.98],[1,1.74,17.32],[2,1.25,100]],"ltp":2.04,"tv":217.45,"id":40096576}]}]}
{"op":"mcm","clk":"11867113373","pt":1723476595090,"mc":[{"id":"1.231703146","rc":[{"batl":[[1,1.97,4.28],[2,1.98,13.85]],"ltp":1.83,"tv":597.48,"id":40096589}]}]}
{"op":"mcm","clk":"11867114957","pt":1723476613618,"mc":[{"id":"1.231703146","rc":[{"batl":[[1,1.96,40.57],[2,1.97,4.28]],"ltp":1.83,"tv":597.48,"id":40096589}]}]}
{"op":"mcm","clk":"11867115039","pt":1723476614313,"mc":[{"id":"1.231703146","rc":[{"batb":[[0,2.04,10],[1,2.02,37.98],[2,1.74,17.32]],"ltp":2.04,"tv":217.45,"id":40096576}]}]}
{"op":"mcm","clk":"11867115229","pt":1723476616290,"mc":[{"id":"1.231703146","rc":[{"batl":[[1,1.95,4.33],[2,1.96,40.57]],"ltp":1.83,"tv":597.48,"id":40096589}]}]}
{"op":"mcm","clk":"11867115488","pt":1723476618702,"mc":[{"id":"1.231703146","rc":[{"batb":[[0,2.02,37.98],[1,1.74,17.32],[2,1.25,100]],"ltp":2.04,"tv":217.45,"id":40096576}]}]}
{"op":"mcm","clk":"11867205115","pt":1723477707383,"mc":[{"id":"1.231703146","rc":[{"batb":[[2,1.76,444]],"ltp":1.83,"tv":597.48,"id":40096589}]}]}
{"op":"mcm","clk":"11867295851","pt":1723478966977,"mc":[{"id":"1.231703146","rc":[{"trd":[[1.58,169.13],[1.79,26.47],[1.83,12.78],[1.84,9.18],[1.91,148.74],[1.93,10.68]],"batl":[[1,1.95,4.33]],"ltp":1.83,"tv":597.68,"id":40096589},{"trd":[[1.58,169.13],[2.04,7.68]],"batb":[[0,2.04,10],[1,2.02,37.98],[2,1.74,17.32]],"ltp":2.04,"tv":217.63,"id":40096576}],"tv":815.31}]}
{"op":"mcm","clk":"11867296289","pt":1723478971996,"mc":[{"id":"1.231703146","rc":[{"batb":[[0,2.02,37.98],[1,1.74,17.32],[2,1.25,100]],"ltp":2.04,"tv":217.63,"id":40096576}]}]}
{"op":"mcm","clk":"11867296733","pt":1723478977001,"mc":[{"id":"1.231703146","rc":[{"batb":[[0,2.04,10],[1,2.02,37.98],[2,1.74,17.32]],"ltp":2.04,"tv":217.63,"id":40096576}]}]}
{"op":"mcm","clk":"11867297630","pt":1723478987619,"mc":[{"id":"1.231703146","rc":[{"batb":[[0,2.02,37.98],[1,1.74,17.32],[2,1.25,100]],"ltp":2.04,"tv":217.63,"id":40096576}]}]}
{"op":"mcm","clk":"11867298235","pt":1723478994521,"mc":[{"id":"1.231703146","rc":[{"batb":[[0,2.04,10],[1,2.02,37.98],[2,1.74,17.32]],"ltp":2.04,"tv":217.63,"id":40096576}]}]}
{"op":"mcm","clk":"11867299163","pt":1723479004121,"mc":[{"id":"1.231703146","rc":[{"batb":[[0,2.02,37.98],[1,1.74,17.32],[2,1.25,100]],"ltp":2.04,"tv":217.63,"id":40096576}]}]}
{"op":"mcm","clk":"11867299621","pt":1723479009221,"mc":[{"id":"1.231703146","rc":[{"batb":[[0,2.04,10],[1,2.02,37.98],[2,1.74,17.32]],"ltp":2.04,"tv":217.63,"id":40096576}]}]}
{"op":"mcm","clk":"11867300507","pt":1723479018652,"mc":[{"id":"1.231703146","rc":[{"batb":[[0,2.02,37.98],[1,1.74,17.32],[2,1.25,100]],"ltp":2.04,"tv":217.63,"id":40096576}]}]}
{"op":"mcm","clk":"11867300865","pt":1723479023136,"mc":[{"id":"1.231703146","rc":[{"batb":[[0,2.04,10],[1,2.02,37.98],[2,1.74,17.32]],"ltp":2.04,"tv":217.63,"id":40096576}]}]}
{"op":"mcm","clk":"11867301122","pt":1723479025536,"mc":[{"id":"1.231703146","rc":[{"batl":[[0,2.2,3]],"ltp":2.04,"tv":217.63,"id":40096576}]}]}
{"op":"mcm","clk":"11867301462","pt":1723479029665,"mc":[{"id":"1.231703146","rc":[{"batb":[[0,2.02,37.98],[1,1.74,17.32],[2,1.25,100]],"ltp":2.04,"tv":217.63,"id":40096576}]}]}
{"op":"mcm","clk":"11867301834","pt":1723479033401,"mc":[{"id":"1.231703146","rc":[{"batb":[[0,2.04,10],[1,2.02,37.98],[2,1.74,17.32]],"ltp":2.04,"tv":217.63,"id":40096576}]}]}
{"op":"mcm","clk":"11867302437","pt":1723479039954,"mc":[{"id":"1.231703146","rc":[{"batb":[[0,2.02,37.98],[1,1.74,17.32],[2,1.25,100]],"ltp":2.04,"tv":217.63,"id":40096576}]}]}
{"op":"mcm","clk":"11867302628","pt":1723479042369,"mc":[{"id":"1.231703146","rc":[{"batb":[[0,2.04,10],[1,2.02,37.98],[2,1.74,17.32]],"ltp":2.04,"tv":217.63,"id":40096576}]}]}
{"op":"mcm","clk":"11867303104","pt":1723479047857,"mc":[{"id":"1.231703146","rc":[{"batb":[[0,2.02,37.98],[1,1.74,17.32],[2,1.25,100]],"ltp":2.04,"tv":217.63,"id":40096576}]}]}
{"op":"mcm","clk":"11867303379","pt":1723479050663,"mc":[{"id":"1.231703146","rc":[{"batb":[[0,2.04,10],[1,2.02,37.98],[2,1.74,17.32]],"ltp":2.04,"tv":217.63,"id":40096576}]}]}
{"op":"mcm","clk":"11867303956","pt":1723479056484,"mc":[{"id":"1.231703146","rc":[{"batb":[[0,2.02,37.98],[1,1.74,17.32],[2,1.25,100]],"ltp":2.04,"tv":217.63,"id":40096576}]}]}
{"op":"mcm","clk":"11867337331","pt":1723479480982,"mc":[{"id":"1.231703146","rc":[{"batb":[[0,2.04,10],[1,2.02,37.98],[2,1.74,17.32]],"ltp":2.04,"tv":217.63,"id":40096576}]}]}
{"op":"mcm","clk":"11867337763","pt":1723479485798,"mc":[{"id":"1.231703146","rc":[{"batb":[[0,2.02,37.98],[1,1.74,17.32],[2,1.25,100]],"ltp":2.04,"tv":217.63,"id":40096576}]}]}
{"op":"mcm","clk":"11867338256","pt":1723479491891,"mc":[{"id":"1.231703146","rc":[{"batb":[[0,2.04,10],[1,2.02,37.98],[2,1.74,17.32]],"ltp":2.04,"tv":217.63,"id":40096576}]}]}
{"op":"mcm","clk":"11867339309","pt":1723479504888,"mc":[{"id":"1.231703146","rc":[{"batb":[[0,2.02,37.98],[1,1.74,17.32],[2,1.25,100]],"ltp":2.04,"tv":217.63,"id":40096576}]}]}
{"op":"mcm","clk":"11867340011","pt":1723479514028,"mc":[{"id":"1.231703146","rc":[{"batb":[[0,2.04,10],[1,2.02,37.98],[2,1.74,17.32]],"ltp":2.04,"tv":217.63,"id":40096576}]}]}
{"op":"mcm","clk":"11867340962","pt":1723479526448,"mc":[{"id":"1.231703146","rc":[{"batb":[[0,2.02,37.98],[1,1.74,17.32],[2,1.25,100]],"ltp":2.04,"tv":217.63,"id":40096576}]}]}
{"op":"mcm","clk":"11867341585","pt":1723479534649,"mc":[{"id":"1.231703146","rc":[{"batb":[[0,2.04,10],[1,2.02,37.98],[2,1.74,17.32]],"ltp":2.04,"tv":217.63,"id":40096576}]}]}
{"op":"mcm","clk":"11867342224","pt":1723479543565,"mc":[{"id":"1.231703146","rc":[{"batb":[[0,2.02,37.98],[1,1.74,17.32],[2,1.25,100]],"ltp":2.04,"tv":217.63,"id":40096576}]}]}
{"op":"mcm","clk":"11867342843","pt":1723479550081,"mc":[{"id":"1.231703146","rc":[{"batb":[[0,2.04,10],[1,2.02,37.98],[2,1.74,17.32]],"ltp":2.04,"tv":217.63,"id":40096576}]}]}
{"op":"mcm","clk":"11867343681","pt":1723479560401,"mc":[{"id":"1.231703146","rc":[{"batb":[[0,2.02,37.98],[1,1.74,17.32],[2,1.25,100]],"ltp":2.04,"tv":217.63,"id":40096576}]}]}
{"op":"mcm","clk":"11867344209","pt":1723479567887,"mc":[{"id":"1.231703146","rc":[{"batb":[[0,2.04,10],[1,2.02,37.98],[2,1.74,17.32]],"ltp":2.04,"tv":217.63,"id":40096576}]}]}
{"op":"mcm","clk":"11867344978","pt":1723479577914,"mc":[{"id":"1.231703146","rc":[{"batb":[[0,2.02,37.98],[1,1.74,17.32],[2,1.25,100]],"ltp":2.04,"tv":217.63,"id":40096576}]}]}
{"op":"mcm","clk":"11867345427","pt":1723479583933,"mc":[{"id":"1.231703146","rc":[{"batb":[[0,2.04,10],[1,2.02,37.98],[2,1.74,17.32]],"ltp":2.04,"tv":217.63,"id":40096576}]}]}
{"op":"mcm","clk":"11867346366","pt":1723479594031,"mc":[{"id":"1.231703146","rc":[{"batb":[[0,2.02,37.98],[1,1.74,17.32],[2,1.25,100]],"ltp":2.04,"tv":217.63,"id":40096576}]}]}
{"op":"mcm","clk":"11867347070","pt":1723479600963,"mc":[{"id":"1.231703146","rc":[{"batb":[[0,2.04,10],[1,2.02,37.98],[2,1.74,17.32]],"ltp":2.04,"tv":217.63,"id":40096576}]}]}
{"op":"mcm","clk":"11867347851","pt":1723479611068,"mc":[{"id":"1.231703146","rc":[{"batb":[[0,2.02,37.98],[1,1.74,17.32],[2,1.25,100]],"ltp":2.04,"tv":217.63,"id":40096576}]}]}
{"op":"mcm","clk":"11867348251","pt":1723479617359,"mc":[{"id":"1.231703146","rc":[{"batb":[[0,2.04,10],[1,2.02,37.98],[2,1.74,17.32]],"ltp":2.04,"tv":217.63,"id":40096576}]}]}
{"op":"mcm","clk":"11867348934","pt":1723479626984,"mc":[{"id":"1.231703146","rc":[{"batb":[[0,2.02,37.98],[1,1.74,17.32],[2,1.25,100]],"ltp":2.04,"tv":217.63,"id":40096576}]}]}
{"op":"mcm","clk":"11867349344","pt":1723479632998,"mc":[{"id":"1.231703146","rc":[{"batb":[[0,2.04,10],[1,2.02,37.98],[2,1.74,17.32]],"ltp":2.04,"tv":217.63,"id":40096576}]}]}
{"op":"mcm","clk":"11867350033","pt":1723479643509,"mc":[{"id":"1.231703146","rc":[{"batb":[[0,2.02,37.98],[1,1.74,17.32],[2,1.25,100]],"ltp":2.04,"tv":217.63,"id":40096576}]}]}
{"op":"mcm","clk":"11867350559","pt":1723479651318,"mc":[{"id":"1.231703146","rc":[{"batb":[[0,2.04,10],[1,2.02,37.98],[2,1.74,17.32]],"ltp":2.04,"tv":217.63,"id":40096576}]}]}
{"op":"mcm","clk":"11867351217","pt":1723479660141,"mc":[{"id":"1.231703146","rc":[{"batb":[[0,2.02,37.98],[1,1.74,17.32],[2,1.25,100]],"ltp":2.04,"tv":217.63,"id":40096576}]}]}
{"op":"mcm","clk":"11867351655","pt":1723479665814,"mc":[{"id":"1.231703146","rc":[{"batb":[[0,2.04,10],[1,2.02,37.98],[2,1.74,17.32]],"ltp":2.04,"tv":217.63,"id":40096576}]}]}
{"op":"mcm","clk":"11867352394","pt":1723479675427,"mc":[{"id":"1.231703146","rc":[{"batb":[[0,2.02,37.98],[1,1.74,17.32],[2,1.25,100]],"ltp":2.04,"tv":217.63,"id":40096576}]}]}
{"op":"mcm","clk":"11867352911","pt":1723479682474,"mc":[{"id":"1.231703146","rc":[{"batb":[[0,2.04,10],[1,2.02,37.98],[2,1.74,17.32]],"ltp":2.04,"tv":217.63,"id":40096576}]}]}
{"op":"mcm","clk":"11867353500","pt":1723479691275,"mc":[{"id":"1.231703146","rc":[{"batb":[[0,2.02,37.98],[1,1.74,17.32],[2,1.25,100]],"ltp":2.04,"tv":217.63,"id":40096576}]}]}
{"op":"mcm","clk":"11867353923","pt":1723479697074,"mc":[{"id":"1.231703146","rc":[{"batb":[[0,2.04,10],[1,2.02,37.98],[2,1.74,17.32]],"ltp":2.04,"tv":217.63,"id":40096576}]}]}
{"op":"mcm","clk":"11867354656","pt":1723479707677,"mc":[{"id":"1.231703146","rc":[{"batb":[[0,2.02,37.98],[1,1.74,17.32],[2,1.25,100]],"ltp":2.04,"tv":217.63,"id":40096576}]}]}
{"op":"mcm","clk":"11867355120","pt":1723479715173,"mc":[{"id":"1.231703146","rc":[{"batb":[[0,2.04,10],[1,2.02,37.98],[2,1.74,17.32]],"ltp":2.04,"tv":217.63,"id":40096576}]}]}
{"op":"mcm","clk":"11867355735","pt":1723479724598,"mc":[{"id":"1.231703146","rc":[{"batb":[[0,2.02,37.98],[1,1.74,17.32],[2,1.25,100]],"ltp":2.04,"tv":217.63,"id":40096576}]}]}
{"op":"mcm","clk":"11867356095","pt":1723479730389,"mc":[{"id":"1.231703146","rc":[{"batb":[[0,2.04,10],[1,2.02,37.98],[2,1.74,17.32]],"ltp":2.04,"tv":217.63,"id":40096576}]}]}
{"op":"mcm","clk":"11867356725","pt":1723479740707,"mc":[{"id":"1.231703146","rc":[{"batb":[[0,2.02,37.98],[1,1.74,17.32],[2,1.25,100]],"ltp":2.04,"tv":217.63,"id":40096576}]}]}
{"op":"mcm","clk":"11867357156","pt":1723479748445,"mc":[{"id":"1.231703146","rc":[{"batb":[[0,2.04,10],[1,2.02,37.98],[2,1.74,17.32]],"ltp":2.04,"tv":217.63,"id":40096576}]}]}
{"op":"mcm","clk":"11867357744","pt":1723479757973,"mc":[{"id":"1.231703146","rc":[{"batb":[[0,2.02,37.98],[1,1.74,17.32],[2,1.25,100]],"ltp":2.04,"tv":217.63,"id":40096576}]}]}
{"op":"mcm","clk":"11867358119","pt":1723479763385,"mc":[{"id":"1.231703146","rc":[{"batb":[[0,2.04,10],[1,2.02,37.98],[2,1.74,17.32]],"ltp":2.04,"tv":217.63,"id":40096576}]}]}
{"op":"mcm","clk":"11867358806","pt":1723479773511,"mc":[{"id":"1.231703146","rc":[{"batb":[[0,2.02,37.98],[1,1.74,17.32],[2,1.25,100]],"ltp":2.04,"tv":217.63,"id":40096576}]}]}
{"op":"mcm","clk":"11867359281","pt":1723479781301,"mc":[{"id":"1.231703146","rc":[{"batb":[[0,2.04,10],[1,2.02,37.98],[2,1.74,17.32]],"ltp":2.04,"tv":217.63,"id":40096576}]}]}
{"op":"mcm","clk":"11867360202","pt":1723479795224,"mc":[{"id":"1.231703146","rc":[{"batb":[[0,2.02,37.98],[1,1.74,17.32],[2,1.25,100]],"ltp":2.04,"tv":217.63,"id":40096576}]}]}
{"op":"mcm","clk":"11867360647","pt":1723479801226,"mc":[{"id":"1.231703146","rc":[{"batb":[[0,2.06,10],[1,2.02,37.98],[2,1.74,17.32]],"ltp":2.04,"tv":217.63,"id":40096576}]}]}
{"op":"mcm","clk":"11867361465","pt":1723479812813,"mc":[{"id":"1.231703146","rc":[{"batb":[[0,2.02,37.98],[1,1.74,17.32],[2,1.25,100]],"ltp":2.04,"tv":217.63,"id":40096576}]}]}
{"op":"mcm","clk":"11867362234","pt":1723479823709,"mc":[{"id":"1.231703146","rc":[{"batb":[[0,2.04,10],[1,2.02,37.98],[2,1.74,17.32]],"ltp":2.04,"tv":217.63,"id":40096576}]}]}
{"op":"mcm","clk":"11867362936","pt":1723479832786,"mc":[{"id":"1.231703146","rc":[{"batb":[[1,1.76,444],[2,1.75,555]],"ltp":1.83,"tv":597.68,"id":40096589}]}]}
{"op":"mcm","clk":"11867363469","pt":1723479840086,"mc":[{"id":"1.231703146","rc":[{"batb":[[0,2.02,37.98],[1,1.74,17.32],[2,1.25,100]],"ltp":2.04,"tv":217.63,"id":40096576}]}]}
{"op":"mcm","clk":"11867364023","pt":1723479846785,"mc":[{"id":"1.231703146","rc":[{"batb":[[0,2.06,10],[1,2.02,37.98],[2,1.74,17.32]],"ltp":2.04,"tv":217.63,"id":40096576}]}]}
{"op":"mcm","clk":"11867365172","pt":1723479863890,"mc":[{"id":"1.231703146","rc":[{"batb":[[0,2.02,37.98],[1,1.74,17.32],[2,1.25,100]],"ltp":2.04,"tv":217.63,"id":40096576}]}]}
{"op":"mcm","clk":"11867366200","pt":1723479879228,"mc":[{"id":"1.231703146","rc":[{"batb":[[0,2.04,10],[1,2.02,37.98],[2,1.74,17.32]],"ltp":2.04,"tv":217.63,"id":40096576}]}]}
{"op":"mcm","clk":"11867367395","pt":1723479898051,"mc":[{"id":"1.231703146","rc":[{"batb":[[0,2.02,37.98],[1,1.74,17.32],[2,1.25,100]],"ltp":2.04,"tv":217.63,"id":40096576}]}]}
{"op":"mcm","clk":"11867368460","pt":1723479914849,"mc":[{"id":"1.231703146","rc":[{"batb":[[0,2.04,10],[1,2.02,37.98],[2,1.74,17.32]],"ltp":2.04,"tv":217.63,"id":40096576}]}]}
{"op":"mcm","clk":"11867369874","pt":1723479934996,"mc":[{"id":"1.231703146","rc":[{"batb":[[0,2.02,37.98],[1,1.74,17.32],[2,1.25,100]],"ltp":2.04,"tv":217.63,"id":40096576}]}]}
{"op":"mcm","clk":"11867371080","pt":1723479952409,"mc":[{"id":"1.231703146","rc":[{"batb":[[0,2.04,10],[1,2.02,37.98],[2,1.74,17.32]],"ltp":2.04,"tv":217.63,"id":40096576}]}]}
{"op":"mcm","clk":"11867372765","pt":1723479974935,"mc":[{"id":"1.231703146","rc":[{"batb":[[0,2.02,37.98],[1,1.74,17.32],[2,1.25,100]],"ltp":2.04,"tv":217.63,"id":40096576}]}]}
{"op":"mcm","clk":"11867374385","pt":1723479995754,"mc":[{"id":"1.231703146","rc":[{"batb":[[0,2.04,10],[1,2.02,37.98],[2,1.74,17.32]],"ltp":2.04,"tv":217.63,"id":40096576}]}]}
{"op":"mcm","clk":"11867376279","pt":1723480019965,"mc":[{"id":"1.231703146","rc":[{"batb":[[0,2.02,37.98],[1,1.74,17.32],[2,1.25,100]],"ltp":2.04,"tv":217.63,"id":40096576}]}]}
{"op":"mcm","clk":"11867377952","pt":1723480039887,"mc":[{"id":"1.231703146","rc":[{"batb":[[0,2.04,10],[1,2.02,37.98],[2,1.74,17.32]],"ltp":2.04,"tv":217.63,"id":40096576}]}]}
{"op":"mcm","clk":"11867379648","pt":1723480061418,"mc":[{"id":"1.231703146","rc":[{"batb":[[0,2.02,37.98],[1,1.74,17.32],[2,1.25,100]],"ltp":2.04,"tv":217.63,"id":40096576}]}]}
{"op":"mcm","clk":"11867381169","pt":1723480079876,"mc":[{"id":"1.231703146","rc":[{"batb":[[0,2.04,10],[1,2.02,37.98],[2,1.74,17.32]],"ltp":2.04,"tv":217.63,"id":40096576}]}]}
{"op":"mcm","clk":"11867382441","pt":1723480095372,"mc":[{"id":"1.231703146","rc":[{"trd":[[1.93,11.75]],"batl":[[0,1.95,5.26],[1,1.96,40.57],[2,1.98,13.85]],"ltp":1.93,"tv":598.75,"id":40096589},{"trd":[[2.06,1]],"ltp":2.06,"tv":218.63,"id":40096576}],"tv":817.38}]}
{"op":"mcm","clk":"11867383114","pt":1723480104074,"mc":[{"id":"1.231703146","rc":[{"batb":[[0,2.02,37.98],[1,1.74,17.32],[2,1.25,100]],"ltp":2.06,"tv":218.63,"id":40096576}]}]}
{"op":"mcm","clk":"11867384459","pt":1723480120183,"mc":[{"id":"1.231703146","rc":[{"batb":[[0,2.06,10],[1,2.02,37.98],[2,1.74,17.32]],"ltp":2.06,"tv":218.63,"id":40096576}]}]}
{"op":"mcm","clk":"11867386139","pt":1723480142006,"mc":[{"id":"1.231703146","rc":[{"batb":[[0,2.02,37.98],[1,1.74,17.32],[2,1.25,100]],"ltp":2.06,"tv":218.63,"id":40096576}]}]}
{"op":"mcm","clk":"11867387706","pt":1723480161133,"mc":[{"id":"1.231703146","rc":[{"batb":[[0,2.04,10],[1,2.02,37.98],[2,1.74,17.32]],"ltp":2.06,"tv":218.63,"id":40096576}]}]}
{"op":"mcm","clk":"11867389397","pt":1723480183574,"mc":[{"id":"1.231703146","rc":[{"batb":[[0,2.02,37.98],[1,1.74,17.32],[2,1.25,100]],"ltp":2.06,"tv":218.63,"id":40096576}]}]}
{"op":"mcm","clk":"11867391011","pt":1723480202405,"mc":[{"id":"1.231703146","rc":[{"batb":[[0,2.04,10],[1,2.02,37.98],[2,1.74,17.32]],"ltp":2.06,"tv":218.63,"id":40096576}]}]}
{"op":"mcm","clk":"11867393082","pt":1723480224410,"mc":[{"id":"1.231703146","rc":[{"batb":[[0,2.02,37.98],[1,1.74,17.32],[2,1.25,100]],"ltp":2.06,"tv":218.63,"id":40096576}]}]}
{"op":"mcm","clk":"11867394947","pt":1723480244134,"mc":[{"id":"1.231703146","rc":[{"batb":[[0,2.04,10],[1,2.02,37.98],[2,1.74,17.32]],"ltp":2.06,"tv":218.63,"id":40096576}]}]}
{"op":"mcm","clk":"11867397141","pt":1723480266873,"mc":[{"id":"1.231703146","rc":[{"batb":[[0,2.02,37.98],[1,1.74,17.32],[2,1.25,100]],"ltp":2.06,"tv":218.63,"id":40096576}]}]}
{"op":"mcm","clk":"11867398821","pt":1723480285595,"mc":[{"id":"1.231703146","rc":[{"batb":[[0,2.04,10],[1,2.02,37.98],[2,1.74,17.32]],"ltp":2.06,"tv":218.63,"id":40096576}]}]}
{"op":"mcm","clk":"11867400365","pt":1723480308514,"mc":[{"id":"1.231703146","rc":[{"batb":[[0,2.02,37.98],[1,1.74,17.32],[2,1.25,100]],"ltp":2.06,"tv":218.63,"id":40096576}]}]}
{"op":"mcm","clk":"11867401734","pt":1723480328128,"mc":[{"id":"1.231703146","rc":[{"batb":[[0,2.04,10],[1,2.02,37.98],[2,1.74,17.32]],"ltp":2.06,"tv":218.63,"id":40096576}]}]}
{"op":"mcm","clk":"11867403277","pt":1723480350541,"mc":[{"id":"1.231703146","rc":[{"batb":[[0,2.02,37.98],[1,1.74,17.32],[2,1.25,100]],"ltp":2.06,"tv":218.63,"id":40096576}]}]}
{"op":"mcm","clk":"11867404642","pt":1723480369885,"mc":[{"id":"1.231703146","rc":[{"batb":[[0,2.04,10],[1,2.02,37.98],[2,1.74,17.32]],"ltp":2.06,"tv":218.63,"id":40096576}]}]}
{"op":"mcm","clk":"11867406102","pt":1723480390155,"mc":[{"id":"1.231703146","rc":[{"batb":[[0,2.02,37.98],[1,1.74,17.32],[2,1.25,100]],"ltp":2.06,"tv":218.63,"id":40096576}]}]}
{"op":"mcm","clk":"11867407699","pt":1723480408188,"mc":[{"id":"1.231703146","rc":[{"batb":[[0,2.04,10],[1,2.02,37.98],[2,1.74,17.32]],"ltp":2.06,"tv":218.63,"id":40096576}]}]}
{"op":"mcm","clk":"11867409751","pt":1723480434488,"mc":[{"id":"1.231703146","rc":[{"batb":[[0,2.02,37.98],[1,1.74,17.32],[2,1.25,100]],"ltp":2.06,"tv":218.63,"id":40096576}]}]}
{"op":"mcm","clk":"11867411310","pt":1723480453216,"mc":[{"id":"1.231703146","rc":[{"batb":[[0,2.04,10],[1,2.02,37.98],[2,1.74,17.32]],"ltp":2.06,"tv":218.63,"id":40096576}]}]}
{"op":"mcm","clk":"11867413125","pt":1723480474463,"mc":[{"id":"1.231703146","rc":[{"batb":[[0,2.02,37.98],[1,1.74,17.32],[2,1.25,100]],"ltp":2.06,"tv":218.63,"id":40096576}]}]}
{"op":"mcm","clk":"11867414876","pt":1723480493488,"mc":[{"id":"1.231703146","rc":[{"batb":[[0,2.04,10],[1,2.02,37.98],[2,1.74,17.32]],"ltp":2.06,"tv":218.63,"id":40096576}]}]}
{"op":"mcm","clk":"11867416677","pt":1723480514817,"mc":[{"id":"1.231703146","rc":[{"batb":[[0,2.02,37.98],[1,1.74,17.32],[2,1.25,100]],"ltp":2.06,"tv":218.63,"id":40096576}]}]}
{"op":"mcm","clk":"11867418335","pt":1723480533918,"mc":[{"id":"1.231703146","rc":[{"batb":[[0,2.04,10],[1,2.02,37.98],[2,1.74,17.32]],"ltp":2.06,"tv":218.63,"id":40096576}]}]}
{"op":"mcm","clk":"11867420133","pt":1723480555652,"mc":[{"id":"1.231703146","rc":[{"batb":[[0,2.02,37.98],[1,1.74,17.32],[2,1.25,100]],"ltp":2.06,"tv":218.63,"id":40096576}]}]}
{"op":"mcm","clk":"11867421688","pt":1723480574057,"mc":[{"id":"1.231703146","rc":[{"batb":[[0,2.04,10],[1,2.02,37.98],[2,1.74,17.32]],"ltp":2.06,"tv":218.63,"id":40096576}]}]}
{"op":"mcm","clk":"11867423523","pt":1723480594988,"mc":[{"id":"1.231703146","rc":[{"batb":[[0,2.02,37.98],[1,1.74,17.32],[2,1.25,100]],"ltp":2.06,"tv":218.63,"id":40096576}]}]}
{"op":"mcm","clk":"11867425183","pt":1723480614111,"mc":[{"id":"1.231703146","rc":[{"batb":[[0,2.04,10],[1,2.02,37.98],[2,1.74,17.32]],"ltp":2.06,"tv":218.63,"id":40096576}]}]}
{"op":"mcm","clk":"11867427107","pt":1723480635529,"mc":[{"id":"1.231703146","rc":[{"batb":[[0,2.02,37.98],[1,1.74,17.32],[2,1.25,100]],"ltp":2.06,"tv":218.63,"id":40096576}]}]}
{"op":"mcm","clk":"11867428855","pt":1723480654784,"mc":[{"id":"1.231703146","rc":[{"batb":[[0,2.04,10],[1,2.02,37.98],[2,1.74,17.32]],"ltp":2.06,"tv":218.63,"id":40096576}]}]}
{"op":"mcm","clk":"11867430724","pt":1723480677099,"mc":[{"id":"1.231703146","rc":[{"batb":[[0,2.02,37.98],[1,1.74,17.32],[2,1.25,100]],"ltp":2.06,"tv":218.63,"id":40096576}]}]}
{"op":"mcm","clk":"11867432434","pt":1723480697016,"mc":[{"id":"1.231703146","rc":[{"batb":[[0,2.04,10],[1,2.02,37.98],[2,1.74,17.32]],"ltp":2.06,"tv":218.63,"id":40096576}]}]}
{"op":"mcm","clk":"11867433374","pt":1723480707934,"mc":[{"id":"1.231703146","rc":[{"batl":[[0,1.94,9.95],[1,1.95,4.33],[2,1.96,40.57]],"ltp":1.93,"tv":598.75,"id":40096589}]}]}
{"op":"mcm","clk":"11867434425","pt":1723480720575,"mc":[{"id":"1.231703146","rc":[{"batb":[[0,2.02,37.98],[1,1.74,17.32],[2,1.25,100]],"ltp":2.06,"tv":218.63,"id":40096576}]}]}
{"op":"mcm","clk":"11867434595","pt":1723480722871,"mc":[{"id":"1.231703146","rc":[{"batb":[[0,2.06,10],[1,2.02,37.98],[2,1.74,17.32]],"ltp":2.06,"tv":218.63,"id":40096576}]}]}
{"op":"mcm","clk":"11867436709","pt":1723480752463,"mc":[{"id":"1.231703146","rc":[{"batb":[[0,2.02,37.98],[1,1.74,17.32],[2,1.25,100]],"ltp":2.06,"tv":218.63,"id":40096576}]}]}
{"op":"mcm","clk":"11867443798","pt":1723480857842,"mc":[{"id":"1.231703146","rc":[{"batb":[[1,1.77,36.06],[2,1.76,444]],"ltp":1.93,"tv":598.75,"id":40096589}]}]}
{"op":"mcm","clk":"11867454836","pt":1723481004050,"mc":[{"id":"1.231703146","rc":[{"batb":[[2,1.73,85.5]],"ltp":2.06,"tv":218.63,"id":40096576}]}]}
{"op":"mcm","clk":"11867477100","pt":1723481271228,"mc":[{"id":"1.231703146","rc":[{"batl":[[0,1.94,9.02]],"ltp":1.93,"tv":598.75,"id":40096589}]}]}
{"op":"mcm","clk":"11867478059","pt":1723481285782,"mc":[{"id":"1.231703146","rc":[{"batb":[[0,1.88,1.1],[1,1.86,52.62],[2,1.77,36.06]],"ltp":1.93,"tv":598.75,"id":40096589}]}]}
{"op":"mcm","clk":"11867479268","pt":1723481302079,"mc":[{"id":"1.231703146","rc":[{"batl":[[0,1.93,1],[1,1.94,9.02],[2,1.95,4.33]],"ltp":1.93,"tv":598.75,"id":40096589}]}]}
{"op":"mcm","clk":"11867516707","pt":1723481908321,"mc":[{"id":"1.231703146","rc":[{"batb":[[0,1.88,1.38]],"ltp":1.93,"tv":598.75,"id":40096589}]}]}
{"op":"mcm","clk":"11867518164","pt":1723481936483,"mc":[{"id":"1.231703146","rc":[{"batb":[[0,1.88,1.1]],"ltp":1.93,"tv":598.75,"id":40096589}]}]}
{"op":"mcm","clk":"11867518792","pt":1723481948072,"mc":[{"id":"1.231703146","rc":[{"batb":[[0,1.88,1.38]],"ltp":1.93,"tv":598.75,"id":40096589}]}]}
{"op":"mcm","clk":"11867519830","pt":1723481966614,"mc":[{"id":"1.231703146","rc":[{"trd":[[1.93,12.31]],"batb":[[0,1.88,1.1]],"batl":[[0,1.94,9.74],[1,1.95,4.33],[2,1.96,40.57]],"ltp":1.93,"tv":599.31,"id":40096589}],"tv":817.95}]}
{"op":"mcm","clk":"11867522444","pt":1723482006859,"mc":[{"id":"1.231703146","rc":[{"trd":[[1.58,169.31],[1.79,26.49],[1.83,12.78],[1.84,9.18],[1.91,148.75],[1.93,12.32]],"batl":[[1,1.95,4.33]],"ltp":1.93,"tv":599.51,"id":40096589},{"trd":[[1.58,169.31],[2.04,7.69]],"batb":[[0,2.04,10],[1,2.02,37.98],[2,1.74,17.32]],"ltp":2.06,"tv":218.82,"id":40096576}],"tv":818.34}]}
{"op":"mcm","clk":"11867522848","pt":1723482012885,"mc":[{"id":"1.231703146","rc":[{"batb":[[0,2.02,37.98],[1,1.74,17.32],[2,1.73,85.5]],"ltp":2.06,"tv":218.82,"id":40096576}]}]}
{"op":"mcm","clk":"11867523248","pt":1723482018353,"mc":[{"id":"1.231703146","rc":[{"batb":[[0,2.04,10],[1,2.02,37.98],[2,1.74,17.32]],"ltp":2.06,"tv":218.82,"id":40096576}]}]}
{"op":"mcm","clk":"11867523605","pt":1723482023006,"mc":[{"id":"1.231703146","rc":[{"batb":[[0,2.02,37.98],[1,1.74,17.32],[2,1.73,85.5]],"ltp":2.06,"tv":218.82,"id":40096576}]}]}
{"op":"mcm","clk":"11867523775","pt":1723482025300,"mc":[{"id":"1.231703146","rc":[{"batb":[[0,2.06,10],[1,2.02,37.98],[2,1.74,17.32]],"ltp":2.06,"tv":218.82,"id":40096576}]}]}
{"op":"mcm","clk":"11867524202","pt":1723482031468,"mc":[{"id":"1.231703146","rc":[{"batb":[[0,2.02,37.98],[1,1.74,17.32],[2,1.73,85.5]],"ltp":2.06,"tv":218.82,"id":40096576}]}]}
{"op":"mcm","clk":"11867524343","pt":1723482033969,"mc":[{"id":"1.231703146","rc":[{"batb":[[0,2.04,10],[1,2.02,37.98],[2,1.74,17.32]],"ltp":2.06,"tv":218.82,"id":40096576}]}]}
{"op":"mcm","clk":"11867524667","pt":1723482038498,"mc":[{"id":"1.231703146","rc":[{"batb":[[0,2.02,37.98],[1,1.74,17.32],[2,1.73,85.5]],"ltp":2.06,"tv":218.82,"id":40096576}]}]}
{"op":"mcm","clk":"11867524899","pt":1723482041327,"mc":[{"id":"1.231703146","rc":[{"batb":[[0,2.04,10],[1,2.02,37.98],[2,1.74,17.32]],"ltp":2.06,"tv":218.82,"id":40096576}]}]}
{"op":"mcm","clk":"11867525309","pt":1723482047692,"mc":[{"id":"1.231703146","rc":[{"batb":[[0,2.02,37.98],[1,1.74,17.32],[2,1.73,85.5]],"ltp":2.06,"tv":218.82,"id":40096576}]}]}
{"op":"mcm","clk":"11867525435","pt":1723482050127,"mc":[{"id":"1.231703146","rc":[{"batb":[[0,2.04,10],[1,2.02,37.98],[2,1.74,17.32]],"ltp":2.06,"tv":218.82,"id":40096576}]}]}
{"op":"mcm","clk":"11867525824","pt":1723482055043,"mc":[{"id":"1.231703146","rc":[{"batb":[[0,2.02,37.98],[1,1.74,17.32],[2,1.73,85.5]],"ltp":2.06,"tv":218.82,"id":40096576}]}]}
{"op":"mcm","clk":"11867526052","pt":1723482058449,"mc":[{"id":"1.231703146","rc":[{"batb":[[0,2.06,10],[1,2.02,37.98],[2,1.74,17.32]],"ltp":2.06,"tv":218.82,"id":40096576}]}]}
{"op":"mcm","clk":"11867526574","pt":1723482066266,"mc":[{"id":"1.231703146","rc":[{"batb":[[0,2.02,37.98],[1,1.74,17.32],[2,1.73,85.5]],"ltp":2.06,"tv":218.82,"id":40096576}]}]}
{"op":"mcm","clk":"11867526781","pt":1723482069844,"mc":[{"id":"1.231703146","rc":[{"batb":[[0,2.04,10],[1,2.02,37.98],[2,1.74,17.32]],"ltp":2.06,"tv":218.82,"id":40096576}]}]}
{"op":"mcm","clk":"11867527253","pt":1723482076242,"mc":[{"id":"1.231703146","rc":[{"batb":[[0,2.02,37.98],[1,1.74,17.32],[2,1.73,85.5]],"ltp":2.06,"tv":218.82,"id":40096576}]}]}
{"op":"mcm","clk":"11867527558","pt":1723482080679,"mc":[{"id":"1.231703146","rc":[{"batb":[[0,2.04,10],[1,2.02,37.98],[2,1.74,17.32]],"ltp":2.06,"tv":218.82,"id":40096576}]}]}
{"op":"mcm","clk":"11867527907","pt":1723482086977,"mc":[{"id":"1.231703146","rc":[{"batb":[[0,2.02,37.98],[1,1.74,17.32],[2,1.73,85.5]],"ltp":2.06,"tv":218.82,"id":40096576}]}]}
{"op":"mcm","clk":"11867528131","pt":1723482090366,"mc":[{"id":"1.231703146","rc":[{"batb":[[0,2.04,10],[1,2.02,37.98],[2,1.74,17.32]],"ltp":2.06,"tv":218.82,"id":40096576}]}]}
{"op":"mcm","clk":"11867528567","pt":1723482096495,"mc":[{"id":"1.231703146","rc":[{"batb":[[0,2.02,37.98],[1,1.74,17.32],[2,1.73,85.5]],"ltp":2.06,"tv":218.82,"id":40096576}]}]}
{"op":"mcm","clk":"11867528811","pt":1723482099368,"mc":[{"id":"1.231703146","rc":[{"batb":[[0,2.04,10],[1,2.02,37.98],[2,1.74,17.32]],"ltp":2.06,"tv":218.82,"id":40096576}]}]}
{"op":"mcm","clk":"11867529308","pt":1723482105657,"mc":[{"id":"1.231703146","rc":[{"batb":[[0,2.02,37.98],[1,1.74,17.32],[2,1.73,85.5]],"ltp":2.06,"tv":218.82,"id":40096576}]}]}
{"op":"mcm","clk":"11867529627","pt":1723482109808,"mc":[{"id":"1.231703146","rc":[{"batb":[[0,2.04,10],[1,2.02,37.98],[2,1.74,17.32]],"ltp":2.06,"tv":218.82,"id":40096576}]}]}
{"op":"mcm","clk":"11867530127","pt":1723482116299,"mc":[{"id":"1.231703146","rc":[{"batb":[[0,2.02,37.98],[1,1.74,17.32],[2,1.73,85.5]],"ltp":2.06,"tv":218.82,"id":40096576}]}]}
{"op":"mcm","clk":"11867530311","pt":1723482118374,"mc":[{"id":"1.231703146","rc":[{"batb":[[0,2.06,10],[1,2.02,37.98],[2,1.74,17.32]],"ltp":2.06,"tv":218.82,"id":40096576}]}]}
{"op":"mcm","clk":"11867530893","pt":1723482125603,"mc":[{"id":"1.231703146","rc":[{"batb":[[0,2.02,37.98],[1,1.74,17.32],[2,1.73,85.5]],"ltp":2.06,"tv":218.82,"id":40096576}]}]}
{"op":"mcm","clk":"11867531166","pt":1723482128929,"mc":[{"id":"1.231703146","rc":[{"batb":[[0,2.04,10],[1,2.02,37.98],[2,1.74,17.32]],"ltp":2.06,"tv":218.82,"id":40096576}]}]}
{"op":"mcm","clk":"11867531710","pt":1723482135605,"mc":[{"id":"1.231703146","rc":[{"batb":[[0,2.02,37.98],[1,1.74,17.32],[2,1.73,85.5]],"ltp":2.06,"tv":218.82,"id":40096576}]}]}
{"op":"mcm","clk":"11867531971","pt":1723482138828,"mc":[{"id":"1.231703146","rc":[{"batb":[[0,2.04,10],[1,2.02,37.98],[2,1.74,17.32]],"ltp":2.06,"tv":218.82,"id":40096576}]}]}
{"op":"mcm","clk":"11867532377","pt":1723482144641,"mc":[{"id":"1.231703146","rc":[{"batb":[[0,2.02,37.98],[1,1.74,17.32],[2,1.73,85.5]],"ltp":2.06,"tv":218.82,"id":40096576}]}]}
{"op":"mcm","clk":"11867532581","pt":1723482147142,"mc":[{"id":"1.231703146","rc":[{"batb":[[0,2.04,10],[1,2.02,37.98],[2,1.74,17.32]],"ltp":2.06,"tv":218.82,"id":40096576}]}]}
{"op":"mcm","clk":"11867533076","pt":1723482153275,"mc":[{"id":"1.231703146","rc":[{"batb":[[0,2.02,37.98],[1,1.74,17.32],[2,1.73,85.5]],"ltp":2.06,"tv":218.82,"id":40096576}]}]}
{"op":"mcm","clk":"11867533238","pt":1723482155376,"mc":[{"id":"1.231703146","rc":[{"batb":[[0,2.06,10],[1,2.02,37.98],[2,1.74,17.32]],"ltp":2.06,"tv":218.82,"id":40096576}]}]}
{"op":"mcm","clk":"11867533685","pt":1723482160954,"mc":[{"id":"1.231703146","rc":[{"batb":[[0,2.02,37.98],[1,1.74,17.32],[2,1.73,85.5]],"ltp":2.06,"tv":218.82,"id":40096576}]}]}
{"op":"mcm","clk":"11867533902","pt":1723482163959,"mc":[{"id":"1.231703146","rc":[{"batb":[[0,2.04,10],[1,2.02,37.98],[2,1.74,17.32]],"ltp":2.06,"tv":218.82,"id":40096576}]}]}
{"op":"mcm","clk":"11867534439","pt":1723482170353,"mc":[{"id":"1.231703146","rc":[{"trd":[[1.88,2.2]],"batb":[[0,1.86,52.62],[1,1.77,36.06],[2,1.76,444]],"batl":[[0,1.88,14.9],[1,1.94,9.74],[2,1.95,4.33]],"ltp":1.88,"tv":601.71,"id":40096589},{"batb":[[0,2.02,37.98],[1,1.74,17.32],[2,1.73,85.5]],"ltp":2.06,"tv":218.82,"id":40096576}],"tv":820.54}]}
{"op":"mcm","clk":"11867534573","pt":1723482172072,"mc":[{"id":"1.231703146","rc":[{"batl":[[2,1.96,40.57]],"ltp":1.88,"tv":601.71,"id":40096589}]}]}
{"op":"mcm","clk":"11867534667","pt":1723482173373,"mc":[{"id":"1.231703146","rc":[{"batb":[[0,2.06,10],[1,2.02,37.98],[2,1.74,17.32]],"ltp":2.06,"tv":218.82,"id":40096576}]}]}
{"op":"mcm","clk":"11867535220","pt":1723482180294,"mc":[{"id":"1.231703146","rc":[{"batb":[[0,2.02,37.98],[1,1.74,17.32],[2,1.73,85.5]],"ltp":2.06,"tv":218.82,"id":40096576}]}]}
{"op":"mcm","clk":"11867535531","pt":1723482183996,"mc":[{"id":"1.231703146","rc":[{"batb":[[0,2.04,10],[1,2.02,37.98],[2,1.74,17.32]],"ltp":2.06,"tv":218.82,"id":40096576}]}]}
{"op":"mcm","clk":"11867535970","pt":1723482190012,"mc":[{"id":"1.231703146","rc":[{"batb":[[0,1.86,36.62]],"ltp":1.88,"tv":601.71,"id":40096589},{"batb":[[0,2.02,37.98],[1,1.74,17.32],[2,1.73,85.5]],"ltp":2.06,"tv":218.82,"id":40096576}]}]}
{"op":"mcm","clk":"11867536176","pt":1723482192304,"mc":[{"id":"1.231703146","rc":[{"batb":[[0,2.06,10],[1,2.02,37.98],[2,1.74,17.32]],"ltp":2.06,"tv":218.82,"id":40096576}]}]}
{"op":"mcm","clk":"11867536797","pt":1723482199838,"mc":[{"id":"1.231703146","rc":[{"batb":[[0,2.02,37.98],[1,1.74,17.32],[2,1.73,85.5]],"ltp":2.06,"tv":218.82,"id":40096576}]}]}
{"op":"mcm","clk":"11867537016","pt":1723482202439,"mc":[{"id":"1.231703146","rc":[{"batb":[[0,2.08,10],[1,2.02,37.98],[2,1.74,17.32]],"ltp":2.06,"tv":218.82,"id":40096576}]}]}
{"op":"mcm","clk":"11867537533","pt":1723482207545,"mc":[{"id":"1.231703146","rc":[{"batb":[[0,2.02,37.98],[1,1.74,17.32],[2,1.73,85.5]],"ltp":2.06,"tv":218.82,"id":40096576}]}]}
{"op":"mcm","clk":"11867537709","pt":1723482209734,"mc":[{"id":"1.231703146","rc":[{"batb":[[0,2.04,10],[1,2.02,37.98],[2,1.74,17.32]],"ltp":2.06,"tv":218.82,"id":40096576}]}]}
{"op":"mcm","clk":"11867538269","pt":1723482216228,"mc":[{"id":"1.231703146","rc":[{"batb":[[0,2.02,37.98],[1,1.74,17.32],[2,1.73,85.5]],"ltp":2.06,"tv":218.82,"id":40096576}]}]}
{"op":"mcm","clk":"11867538519","pt":1723482219041,"mc":[{"id":"1.231703146","rc":[{"batb":[[0,2.04,10],[1,2.02,37.98],[2,1.74,17.32]],"ltp":2.06,"tv":218.82,"id":40096576}]}]}
{"op":"mcm","clk":"11867538807","pt":1723482221955,"mc":[{"id":"1.231703146","rc":[{"batl":[[0,1.94,97.59],[1,1.96,40.57],[2,1.98,13.85]],"ltp":1.88,"tv":601.71,"id":40096589}]}]}
{"op":"mcm","clk":"11867538824","pt":1723482222166,"mc":[{"id":"1.231703146","rc":[{"batl":[[0,1.94,9.74]],"ltp":1.88,"tv":601.71,"id":40096589}]}]}
{"op":"mcm","clk":"11867538985","pt":1723482224039,"mc":[{"id":"1.231703146","rc":[{"batl":[[1,1.95,4.33],[2,1.96,40.57]],"ltp":1.88,"tv":601.71,"id":40096589},{"batb":[[0,2.02,37.98],[1,1.74,17.32],[2,1.73,85.5]],"ltp":2.06,"tv":218.82,"id":40096576}]}]}
{"op":"mcm","clk":"11867539200","pt":1723482226545,"mc":[{"id":"1.231703146","rc":[{"batb":[[0,2.04,10],[1,2.02,37.98],[2,1.74,17.32]],"ltp":2.06,"tv":218.82,"id":40096576}]}]}
{"op":"mcm","clk":"11867539802","pt":1723482232540,"mc":[{"id":"1.231703146","rc":[{"batb":[[0,2.02,37.98],[1,1.74,17.32],[2,1.73,85.5]],"ltp":2.06,"tv":218.82,"id":40096576}]}]}
{"op":"mcm","clk":"11867540119","pt":1723482235871,"mc":[{"id":"1.231703146","rc":[{"batb":[[0,2.04,10],[1,2.02,37.98],[2,1.74,17.32]],"ltp":2.06,"tv":218.82,"id":40096576}]}]}
{"op":"mcm","clk":"11867540643","pt":1723482241764,"mc":[{"id":"1.231703146","rc":[{"batb":[[0,2.02,37.98],[1,1.74,17.32],[2,1.73,85.5]],"ltp":2.06,"tv":218.82,"id":40096576}]}]}
{"op":"mcm","clk":"11867540951","pt":1723482245387,"mc":[{"id":"1.231703146","rc":[{"batb":[[0,2.04,10],[1,2.02,37.98],[2,1.74,17.32]],"ltp":2.06,"tv":218.82,"id":40096576}]}]}
{"op":"mcm","clk":"11867541584","pt":1723482252493,"mc":[{"id":"1.231703146","rc":[{"batb":[[0,2.02,37.98],[1,1.74,17.32],[2,1.73,85.5]],"ltp":2.06,"tv":218.82,"id":40096576}]}]}
{"op":"mcm","clk":"11867541861","pt":1723482256002,"mc":[{"id":"1.231703146","rc":[{"batb":[[0,2.04,10],[1,2.02,37.98],[2,1.74,17.32]],"ltp":2.06,"tv":218.82,"id":40096576}]}]}
{"op":"mcm","clk":"11867542488","pt":1723482263305,"mc":[{"id":"1.231703146","rc":[{"batb":[[0,2.02,37.98],[1,1.74,17.32],[2,1.73,85.5]],"ltp":2.06,"tv":218.82,"id":40096576}]}]}
{"op":"mcm","clk":"11867542764","pt":1723482266595,"mc":[{"id":"1.231703146","rc":[{"batb":[[0,2.06,10],[1,2.02,37.98],[2,1.74,17.32]],"ltp":2.06,"tv":218.82,"id":40096576}]}]}
{"op":"mcm","clk":"11867543336","pt":1723482273183,"mc":[{"id":"1.231703146","rc":[{"batb":[[0,2.02,37.98],[1,1.74,17.32],[2,1.73,85.5]],"ltp":2.06,"tv":218.82,"id":40096576}]}]}
{"op":"mcm","clk":"11867543670","pt":1723482277097,"mc":[{"id":"1.231703146","rc":[{"batb":[[0,2.04,10],[1,2.02,37.98],[2,1.74,17.32]],"ltp":2.06,"tv":218.82,"id":40096576}]}]}
{"op":"mcm","clk":"11867544220","pt":1723482283912,"mc":[{"id":"1.231703146","rc":[{"batb":[[0,2.02,37.98],[1,1.74,17.32],[2,1.73,85.5]],"ltp":2.06,"tv":218.82,"id":40096576}]}]}
{"op":"mcm","clk":"11867544435","pt":1723482286605,"mc":[{"id":"1.231703146","rc":[{"batb":[[0,2.04,10],[1,2.02,37.98],[2,1.74,17.32]],"ltp":2.06,"tv":218.82,"id":40096576}]}]}
{"op":"mcm","clk":"11867545031","pt":1723482293315,"mc":[{"id":"1.231703146","rc":[{"batb":[[0,2.02,37.98],[1,1.74,17.32],[2,1.73,85.5]],"ltp":2.06,"tv":218.82,"id":40096576}]}]}
{"op":"mcm","clk":"11867545313","pt":1723482296403,"mc":[{"id":"1.231703146","rc":[{"batb":[[0,2.04,10],[1,2.02,37.98],[2,1.74,17.32]],"ltp":2.06,"tv":218.82,"id":40096576}]}]}
{"op":"mcm","clk":"11867545846","pt":1723482302012,"mc":[{"id":"1.231703146","rc":[{"batb":[[0,2.02,37.98],[1,1.74,17.32],[2,1.73,85.5]],"ltp":2.06,"tv":218.82,"id":40096576}]}]}
{"op":"mcm","clk":"11867546165","pt":1723482305529,"mc":[{"id":"1.231703146","rc":[{"batb":[[0,2.04,10],[1,2.02,37.98],[2,1.74,17.32]],"ltp":2.06,"tv":218.82,"id":40096576}]}]}
{"op":"mcm","clk":"11867546775","pt":1723482312726,"mc":[{"id":"1.231703146","rc":[{"batb":[[0,2.02,37.98],[1,1.74,17.32],[2,1.73,85.5]],"ltp":2.06,"tv":218.82,"id":40096576}]}]}
{"op":"mcm","clk":"11867547153","pt":1723482317847,"mc":[{"id":"1.231703146","rc":[{"batb":[[0,2.04,10],[1,2.02,37.98],[2,1.74,17.32]],"ltp":2.06,"tv":218.82,"id":40096576}]}]}
{"op":"mcm","clk":"11867547897","pt":1723482325649,"mc":[{"id":"1.231703146","rc":[{"batb":[[0,2.02,37.98],[1,1.74,17.32],[2,1.73,85.5]],"ltp":2.06,"tv":218.82,"id":40096576}]}]}
{"op":"mcm","clk":"11867548202","pt":1723482329462,"mc":[{"id":"1.231703146","rc":[{"batb":[[0,2.04,10],[1,2.02,37.98],[2,1.74,17.32]],"ltp":2.06,"tv":218.82,"id":40096576}]}]}
{"op":"mcm","clk":"11867548778","pt":1723482336040,"mc":[{"id":"1.231703146","rc":[{"batb":[[0,2.02,37.98],[1,1.74,17.32],[2,1.73,85.5]],"ltp":2.06,"tv":218.82,"id":40096576}]}]}
{"op":"mcm","clk":"11867549396","pt":1723482344171,"mc":[{"id":"1.231703146","rc":[{"batb":[[0,2.04,10],[1,2.02,37.98],[2,1.74,17.32]],"ltp":2.06,"tv":218.82,"id":40096576}]}]}
{"op":"mcm","clk":"11867550177","pt":1723482352974,"mc":[{"id":"1.231703146","rc":[{"batb":[[0,2.02,37.98],[1,1.74,17.32],[2,1.73,85.5]],"ltp":2.06,"tv":218.82,"id":40096576}]}]}
{"op":"mcm","clk":"11867550966","pt":1723482361077,"mc":[{"id":"1.231703146","rc":[{"batb":[[0,2.04,10],[1,2.02,37.98],[2,1.74,17.32]],"ltp":2.06,"tv":218.82,"id":40096576}]}]}
{"op":"mcm","clk":"11867552038","pt":1723482372771,"mc":[{"id":"1.231703146","rc":[{"batb":[[0,2.02,37.98],[1,1.74,17.32],[2,1.73,85.5]],"ltp":2.06,"tv":218.82,"id":40096576}]}]}
{"op":"mcm","clk":"11867552789","pt":1723482381206,"mc":[{"id":"1.231703146","rc":[{"batb":[[0,2.04,10],[1,2.02,37.98],[2,1.74,17.32]],"ltp":2.06,"tv":218.82,"id":40096576}]}]}
{"op":"mcm","clk":"11867553812","pt":1723482393324,"mc":[{"id":"1.231703146","rc":[{"batb":[[0,2.02,37.98],[1,1.74,17.32],[2,1.73,85.5]],"ltp":2.06,"tv":218.82,"id":40096576}]}]}
{"op":"mcm","clk":"11867554442","pt":1723482400507,"mc":[{"id":"1.231703146","rc":[{"batb":[[0,2.04,10],[1,2.02,37.98],[2,1.74,17.32]],"ltp":2.06,"tv":218.82,"id":40096576}]}]}
{"op":"mcm","clk":"11867555303","pt":1723482409653,"mc":[{"id":"1.231703146","rc":[{"batb":[[0,2.02,37.98],[1,1.74,17.32],[2,1.73,85.5]],"ltp":2.06,"tv":218.82,"id":40096576}]}]}
{"op":"mcm","clk":"11867555816","pt":1723482415260,"mc":[{"id":"1.231703146","rc":[{"batb":[[0,2.04,10],[1,2.02,37.98],[2,1.74,17.32]],"ltp":2.06,"tv":218.82,"id":40096576}]}]}
{"op":"mcm","clk":"11867556514","pt":1723482423239,"mc":[{"id":"1.231703146","rc":[{"batb":[[0,2.02,37.98],[1,1.74,17.32],[2,1.73,85.5]],"ltp":2.06,"tv":218.82,"id":40096576}]}]}
{"op":"mcm","clk":"11867556899","pt":1723482427972,"mc":[{"id":"1.231703146","rc":[{"batb":[[0,2.04,10],[1,2.02,37.98],[2,1.74,17.32]],"ltp":2.06,"tv":218.82,"id":40096576}]}]}
{"op":"mcm","clk":"11867557568","pt":1723482435092,"mc":[{"id":"1.231703146","rc":[{"batb":[[0,2.02,37.98],[1,1.74,17.32],[2,1.73,85.5]],"ltp":2.06,"tv":218.82,"id":40096576}]}]}
{"op":"mcm","clk":"11867557765","pt":1723482437672,"mc":[{"id":"1.231703146","rc":[{"batb":[[0,2.06,10],[1,2.02,37.98],[2,1.74,17.32]],"ltp":2.06,"tv":218.82,"id":40096576}]}]}
{"op":"mcm","clk":"11867558402","pt":1723482444655,"mc":[{"id":"1.231703146","rc":[{"batb":[[0,2.02,37.98],[1,1.74,17.32],[2,1.73,85.5]],"ltp":2.06,"tv":218.82,"id":40096576}]}]}
{"op":"mcm","clk":"11867558793","pt":1723482448901,"mc":[{"id":"1.231703146","rc":[{"batb":[[0,2.04,10],[1,2.02,37.98],[2,1.74,17.32]],"ltp":2.06,"tv":218.82,"id":40096576}]}]}
{"op":"mcm","clk":"11867559475","pt":1723482456906,"mc":[{"id":"1.231703146","rc":[{"batb":[[0,2.02,37.98],[1,1.74,17.32],[2,1.73,85.5]],"ltp":2.06,"tv":218.82,"id":40096576}]}]}
{"op":"mcm","clk":"11867559684","pt":1723482459408,"mc":[{"id":"1.231703146","rc":[{"batb":[[0,2.06,10],[1,2.02,37.98],[2,1.74,17.32]],"ltp":2.06,"tv":218.82,"id":40096576}]}]}
{"op":"mcm","clk":"11867560354","pt":1723482466285,"mc":[{"id":"1.231703146","rc":[{"batb":[[0,2.02,37.98],[1,1.74,17.32],[2,1.73,85.5]],"ltp":2.06,"tv":218.82,"id":40096576}]}]}
{"op":"mcm","clk":"11867560559","pt":1723482468692,"mc":[{"id":"1.231703146","rc":[{"batb":[[0,2.08,10],[1,2.02,37.98],[2,1.74,17.32]],"ltp":2.06,"tv":218.82,"id":40096576}]}]}
{"op":"mcm","clk":"11867560642","pt":1723482469699,"mc":[{"id":"1.231703146","rc":[{"batl":[[0,1.93,5.1],[1,1.94,9.02]],"ltp":1.88,"tv":601.71,"id":40096589}]}]}
{"op":"mcm","clk":"11867561144","pt":1723482476131,"mc":[{"id":"1.231703146","rc":[{"batb":[[0,2.02,37.98],[1,1.74,17.32],[2,1.73,85.5]],"ltp":2.06,"tv":218.82,"id":40096576}]}]}
{"op":"mcm","clk":"11867561278","pt":1723482477799,"mc":[{"id":"1.231703146","rc":[{"batl":[[0,1.94,9.74],[1,1.95,4.33]],"ltp":1.88,"tv":601.71,"id":40096589}]}]}
{"op":"mcm","clk":"11867561386","pt":1723482479264,"mc":[{"id":"1.231703146","rc":[{"batb":[[0,2.04,10],[1,2.02,37.98],[2,1.74,17.32]],"ltp":2.06,"tv":218.82,"id":40096576}]}]}
{"op":"mcm","clk":"11867561844","pt":1723482484638,"mc":[{"id":"1.231703146","rc":[{"batb":[[0,2.02,37.98],[1,1.74,17.32],[2,1.73,85.5]],"ltp":2.06,"tv":218.82,"id":40096576}]}]}
{"op":"mcm","clk":"11867562102","pt":1723482487620,"mc":[{"id":"1.231703146","rc":[{"batb":[[0,2.04,10],[1,2.02,37.98],[2,1.74,17.32]],"ltp":2.06,"tv":218.82,"id":40096576}]}]}
{"op":"mcm","clk":"11867562660","pt":1723482495036,"mc":[{"id":"1.231703146","rc":[{"batb":[[0,2.02,37.98],[1,1.74,17.32],[2,1.73,85.5]],"ltp":2.06,"tv":218.82,"id":40096576}]}]}
{"op":"mcm","clk":"11867562986","pt":1723482499295,"mc":[{"id":"1.231703146","rc":[{"batb":[[0,2.06,10],[1,2.02,37.98],[2,1.74,17.32]],"ltp":2.06,"tv":218.82,"id":40096576}]}]}
{"op":"mcm","clk":"11867563628","pt":1723482507166,"mc":[{"id":"1.231703146","rc":[{"batb":[[0,2.02,37.98],[1,1.74,17.32],[2,1.73,85.5]],"ltp":2.06,"tv":218.82,"id":40096576}]}]}
{"op":"mcm","clk":"11867563832","pt":1723482509461,"mc":[{"id":"1.231703146","rc":[{"batb":[[0,2.08,10],[1,2.02,37.98],[2,1.74,17.32]],"ltp":2.06,"tv":218.82,"id":40096576}]}]}
{"op":"mcm","clk":"11867563902","pt":1723482510303,"mc":[{"id":"1.231703146","rc":[{"batl":[[1,1.96,40.57],[2,1.98,13.85]],"ltp":1.88,"tv":601.71,"id":40096589}]}]}
{"op":"mcm","clk":"11867564086","pt":1723482512400,"mc":[{"id":"1.231703146","rc":[{"batl":[[0,1.93,5.1],[1,1.94,9.02],[2,1.96,40.57]],"ltp":1.88,"tv":601.71,"id":40096589}]}]}
{"op":"mcm","clk":"11867564575","pt":1723482517906,"mc":[{"id":"1.231703146","rc":[{"batl":[[0,1.94,9.74],[1,1.96,40.57],[2,1.98,13.85]],"ltp":1.88,"tv":601.71,"id":40096589},{"batb":[[0,2.02,37.98],[1,1.74,17.32],[2,1.73,85.5]],"ltp":2.06,"tv":218.82,"id":40096576}]}]}
{"op":"mcm","clk":"11867564884","pt":1723482521681,"mc":[{"id":"1.231703146","rc":[{"batl":[[1,1.95,4.33],[2,1.96,40.57]],"ltp":1.88,"tv":601.71,"id":40096589}]}]}
{"op":"mcm","clk":"11867564990","pt":1723482522971,"mc":[{"id":"1.231703146","rc":[{"batb":[[0,2.04,10],[1,2.02,37.98],[2,1.74,17.32]],"ltp":2.06,"tv":218.82,"id":40096576}]}]}
{"op":"mcm","clk":"11867565638","pt":1723482530810,"mc":[{"id":"1.231703146","rc":[{"batb":[[0,2.02,37.98],[1,1.74,17.32],[2,1.73,85.5]],"ltp":2.06,"tv":218.82,"id":40096576}]}]}
{"op":"mcm","clk":"11867566017","pt":1723482535323,"mc":[{"id":"1.231703146","rc":[{"batb":[[0,2.06,10],[1,2.02,37.98],[2,1.74,17.32]],"ltp":2.06,"tv":218.82,"id":40096576}]}]}
{"op":"mcm","clk":"11867566794","pt":1723482543233,"mc":[{"id":"1.231703146","rc":[{"batb":[[0,2.02,37.98],[1,1.74,17.32],[2,1.73,85.5]],"ltp":2.06,"tv":218.82,"id":40096576}]}]}
{"op":"mcm","clk":"11867567258","pt":1723482548443,"mc":[{"id":"1.231703146","rc":[{"batb":[[0,2.04,10],[1,2.02,37.98],[2,1.74,17.32]],"ltp":2.06,"tv":218.82,"id":40096576}]}]}
{"op":"mcm","clk":"11867568089","pt":1723482557720,"mc":[{"id":"1.231703146","rc":[{"batb":[[0,2.02,37.98],[1,1.74,17.32],[2,1.73,85.5]],"ltp":2.06,"tv":218.82,"id":40096576}]}]}
{"op":"mcm","clk":"11867568578","pt":1723482563420,"mc":[{"id":"1.231703146","rc":[{"batb":[[0,2.04,10],[1,2.02,37.98],[2,1.74,17.32]],"ltp":2.06,"tv":218.82,"id":40096576}]}]}
{"op":"mcm","clk":"11867569249","pt":1723482570968,"mc":[{"id":"1.231703146","rc":[{"batb":[[0,2.02,37.98],[1,1.74,17.32],[2,1.73,85.5]],"ltp":2.06,"tv":218.82,"id":40096576}]}]}
{"op":"mcm","clk":"11867569462","pt":1723482573663,"mc":[{"id":"1.231703146","rc":[{"batb":[[0,2.06,10],[1,2.02,37.98],[2,1.74,17.32]],"ltp":2.06,"tv":218.82,"id":40096576}]}]}
{"op":"mcm","clk":"11867570170","pt":1723482582084,"mc":[{"id":"1.231703146","rc":[{"batb":[[0,2.02,37.98],[1,1.74,17.32],[2,1.73,85.5]],"ltp":2.06,"tv":218.82,"id":40096576}]}]}
{"op":"mcm","clk":"11867570476","pt":1723482585455,"mc":[{"id":"1.231703146","rc":[{"batb":[[0,2.08,10],[1,2.02,37.98],[2,1.74,17.32]],"ltp":2.06,"tv":218.82,"id":40096576}]}]}
{"op":"mcm","clk":"11867570598","pt":1723482586864,"mc":[{"id":"1.231703146","rc":[{"batl":[[0,1.93,5.1],[1,1.94,9.02]],"ltp":1.88,"tv":601.71,"id":40096589}]}]}
{"op":"mcm","clk":"11867571297","pt":1723482594600,"mc":[{"id":"1.231703146","rc":[{"batb":[[0,2.02,37.98],[1,1.74,17.32],[2,1.73,85.5]],"ltp":2.06,"tv":218.82,"id":40096576}]}]}
{"op":"mcm","clk":"11867571485","pt":1723482596664,"mc":[{"id":"1.231703146","rc":[{"batl":[[0,1.94,9.74],[1,1.95,4.33]],"ltp":1.88,"tv":601.71,"id":40096589}]}]}
{"op":"mcm","clk":"11867571754","pt":1723482599680,"mc":[{"id":"1.231703146","rc":[{"batb":[[0,2.04,10],[1,2.02,37.98],[2,1.74,17.32]],"ltp":2.06,"tv":218.82,"id":40096576}]}]}
{"op":"mcm","clk":"11867572625","pt":1723482609195,"mc":[{"id":"1.231703146","rc":[{"batb":[[0,2.02,37.98],[1,1.74,17.32],[2,1.73,85.5]],"ltp":2.06,"tv":218.82,"id":40096576}]}]}
{"op":"mcm","clk":"11867573226","pt":1723482615800,"mc":[{"id":"1.231703146","rc":[{"batb":[[0,2.06,10],[1,2.02,37.98],[2,1.74,17.32]],"ltp":2.06,"tv":218.82,"id":40096576}]}]}
{"op":"mcm","clk":"11867573935","pt":1723482624301,"mc":[{"id":"1.231703146","rc":[{"batb":[[0,2.02,37.98],[1,1.74,17.32],[2,1.73,85.5]],"ltp":2.06,"tv":218.82,"id":40096576}]}]}
{"op":"mcm","clk":"11867574364","pt":1723482628919,"mc":[{"id":"1.231703146","rc":[{"batl":[[1,1.96,40.57],[2,1.98,13.85]],"ltp":1.88,"tv":601.71,"id":40096589},{"batb":[[0,2.08,10],[1,2.02,37.98],[2,1.74,17.32]],"ltp":2.06,"tv":218.82,"id":40096576}]}]}
{"op":"mcm","clk":"11867574379","pt":1723482629130,"mc":[{"id":"1.231703146","rc":[{"batl":[[0,1.93,5.1],[1,1.94,9.02],[2,1.96,40.57]],"ltp":1.88,"tv":601.71,"id":40096589}]}]}
{"op":"mcm","clk":"11867575132","pt":1723482637625,"mc":[{"id":"1.231703146","rc":[{"batb":[[0,2.02,37.98],[1,1.74,17.32],[2,1.73,85.5]],"ltp":2.06,"tv":218.82,"id":40096576}]}]}
{"op":"mcm","clk":"11867575366","pt":1723482639953,"mc":[{"id":"1.231703146","rc":[{"batl":[[0,1.94,9.74],[1,1.96,40.57],[2,1.98,13.85]],"ltp":1.88,"tv":601.71,"id":40096589}]}]}
{"op":"mcm","clk":"11867575390","pt":1723482640143,"mc":[{"id":"1.231703146","rc":[{"batl":[[1,1.95,4.33],[2,1.96,40.57]],"ltp":1.88,"tv":601.71,"id":40096589}]}]}
{"op":"mcm","clk":"11867575787","pt":1723482644245,"mc":[{"id":"1.231703146","rc":[{"batb":[[0,2.04,10],[1,2.02,37.98],[2,1.74,17.32]],"ltp":2.06,"tv":218.82,"id":40096576}]}]}
{"op":"mcm","clk":"11867576590","pt":1723482653254,"mc":[{"id":"1.231703146","rc":[{"batb":[[0,2.02,37.98],[1,1.74,17.32],[2,1.73,85.5]],"ltp":2.06,"tv":218.82,"id":40096576}]}]}
{"op":"mcm","clk":"11867577104","pt":1723482658956,"mc":[{"id":"1.231703146","rc":[{"batb":[[0,2.04,10],[1,2.02,37.98],[2,1.74,17.32]],"ltp":2.06,"tv":218.82,"id":40096576}]}]}
{"op":"mcm","clk":"11867578310","pt":1723482673082,"mc":[{"id":"1.231703146","rc":[{"batb":[[0,2.02,37.98],[1,1.74,17.32],[2,1.73,85.5]],"ltp":2.06,"tv":218.82,"id":40096576}]}]}
{"op":"mcm","clk":"11867578778","pt":1723482677663,"mc":[{"id":"1.231703146","rc":[{"batb":[[0,2.06,10],[1,2.02,37.98],[2,1.74,17.32]],"ltp":2.06,"tv":218.82,"id":40096576}]}]}
{"op":"mcm","clk":"11867579703","pt":1723482689779,"mc":[{"id":"1.231703146","rc":[{"batb":[[0,2.02,37.98],[1,1.74,17.32],[2,1.73,85.5]],"ltp":2.06,"tv":218.82,"id":40096576}]}]}
{"op":"mcm","clk":"11867580379","pt":1723482698592,"mc":[{"id":"1.231703146","rc":[{"batb":[[0,2.08,10],[1,2.02,37.98],[2,1.74,17.32]],"ltp":2.06,"tv":218.82,"id":40096576}]}]}
{"op":"mcm","clk":"11867580483","pt":1723482700003,"mc":[{"id":"1.231703146","rc":[{"batl":[[0,1.93,5.1],[1,1.94,9.02]],"ltp":1.88,"tv":601.71,"id":40096589}]}]}
{"op":"mcm","clk":"11867581340","pt":1723482712133,"mc":[{"id":"1.231703146","rc":[{"batb":[[0,2.02,37.98],[1,1.74,17.32],[2,1.73,85.5]],"ltp":2.06,"tv":218.82,"id":40096576}]}]}
{"op":"mcm","clk":"11867581563","pt":1723482714543,"mc":[{"id":"1.231703146","rc":[{"batl":[[0,1.94,9.74],[1,1.95,4.33]],"ltp":1.88,"tv":601.71,"id":40096589}]}]}
{"op":"mcm","clk":"11867581726","pt":1723482716433,"mc":[{"id":"1.231703146","rc":[{"batb":[[0,2.1,10],[1,2.02,37.98],[2,1.74,17.32]],"ltp":2.06,"tv":218.82,"id":40096576}]}]}
{"op":"mcm","clk":"11867581774","pt":1723482717120,"mc":[{"id":"1.231703146","rc":[{"batl":[[1,1.96,40.57],[2,1.98,13.85]],"ltp":1.88,"tv":601.71,"id":40096589}]}]}
{"op":"mcm","clk":"11867582896","pt":1723482729765,"mc":[{"id":"1.231703146","rc":[{"batb":[[0,2.02,37.98],[1,1.74,17.32],[2,1.73,85.5]],"ltp":2.06,"tv":218.82,"id":40096576}]}]}
{"op":"mcm","clk":"11867583163","pt":1723482732967,"mc":[{"id":"1.231703146","rc":[{"batb":[[0,2.12,10],[1,2.02,37.98],[2,1.74,17.32]],"ltp":2.06,"tv":218.82,"id":40096576}]}]}
{"op":"mcm","clk":"11867583183","pt":1723482733183,"mc":[{"id":"1.231703146","rc":[{"batb":[[1,1.74,17.32],[2,1.73,85.5]],"ltp":2.06,"tv":218.82,"id":40096576}]}]}
{"op":"mcm","clk":"11867584379","pt":1723482747105,"mc":[{"id":"1.231703146","rc":[{"batb":[[0,1.74,17.32],[1,1.73,85.5],[2,1.25,100]],"ltp":2.06,"tv":218.82,"id":40096576}]}]}
{"op":"mcm","clk":"11867584490","pt":1723482748218,"mc":[{"id":"1.231703146","rc":[{"batb":[[0,2.02,37.98],[1,1.74,17.32],[2,1.73,85.5]],"ltp":2.06,"tv":218.82,"id":40096576}]}]}
{"op":"mcm","clk":"11867585185","pt":1723482755834,"mc":[{"id":"1.231703146","rc":[{"batl":[[1,1.95,4.33],[2,1.96,40.57]],"ltp":1.88,"tv":601.71,"id":40096589}]}]}
{"op":"mcm","clk":"11867585223","pt":1723482756222,"mc":[{"id":"1.231703146","rc":[{"batb":[[1,1.75,10],[2,1.74,17.32]],"ltp":2.06,"tv":218.82,"id":40096576}]}]}
{"op":"mcm","clk":"11867586373","pt":1723482768531,"mc":[{"id":"1.231703146","rc":[{"batb":[[1,1.74,17.32],[2,1.73,85.5]],"ltp":2.06,"tv":218.82,"id":40096576}]}]}
{"op":"mcm","clk":"11867586693","pt":1723482772138,"mc":[{"id":"1.231703146","rc":[{"batb":[[0,2.04,10],[1,2.02,37.98],[2,1.74,17.32]],"ltp":2.06,"tv":218.82,"id":40096576}]}]}
{"op":"mcm","clk":"11867595329","pt":1723482783561,"mc":[{"id":"1.231703146","rc":[{"batb":[[0,2.02,37.98],[1,1.74,17.32],[2,1.73,85.5]],"ltp":2.06,"tv":218.82,"id":40096576}]}]}
{"op":"mcm","clk":"11867596053","pt":1723482791853,"mc":[{"id":"1.231703146","rc":[{"batb":[[0,2.04,10],[1,2.02,37.98],[2,1.74,17.32]],"ltp":2.06,"tv":218.82,"id":40096576}]}]}
{"op":"mcm","clk":"11867597003","pt":1723482802462,"mc":[{"id":"1.231703146","rc":[{"batb":[[0,2.02,37.98],[1,1.74,17.32],[2,1.73,85.5]],"ltp":2.06,"tv":218.82,"id":40096576}]}]}
{"op":"mcm","clk":"11867597725","pt":1723482809975,"mc":[{"id":"1.231703146","rc":[{"batb":[[0,2.04,10],[1,2.02,37.98],[2,1.74,17.32]],"ltp":2.06,"tv":218.82,"id":40096576}]}]}
{"op":"mcm","clk":"11867598753","pt":1723482821276,"mc":[{"id":"1.231703146","rc":[{"batb":[[0,2.02,37.98],[1,1.74,17.32],[2,1.73,85.5]],"ltp":2.06,"tv":218.82,"id":40096576}]}]}
{"op":"mcm","clk":"11867598952","pt":1723482823493,"mc":[{"id":"1.231703146","rc":[{"batb":[[0,2.06,10],[1,2.02,37.98],[2,1.74,17.32]],"ltp":2.06,"tv":218.82,"id":40096576}]}]}
{"op":"mcm","clk":"11867600017","pt":1723482834915,"mc":[{"id":"1.231703146","rc":[{"batb":[[0,2.02,37.98],[1,1.74,17.32],[2,1.73,85.5]],"ltp":2.06,"tv":218.82,"id":40096576}]}]}
{"op":"mcm","clk":"11867600587","pt":1723482840627,"mc":[{"id":"1.231703146","rc":[{"batb":[[0,2.08,10],[1,2.02,37.98],[2,1.74,17.32]],"ltp":2.06,"tv":218.82,"id":40096576}]}]}
{"op":"mcm","clk":"11867600652","pt":1723482841328,"mc":[{"id":"1.231703146","rc":[{"batl":[[0,1.93,5.1],[1,1.94,9.02]],"ltp":1.88,"tv":601.71,"id":40096589}]}]}
{"op":"mcm","clk":"11867601711","pt":1723482852438,"mc":[{"id":"1.231703146","rc":[{"batb":[[0,2.02,37.98],[1,1.74,17.32],[2,1.73,85.5]],"ltp":2.06,"tv":218.82,"id":40096576}]}]}
{"op":"mcm","clk":"11867602026","pt":1723482855553,"mc":[{"id":"1.231703146","rc":[{"batl":[[0,1.94,9.74],[1,1.95,4.33]],"ltp":1.88,"tv":601.71,"id":40096589}]}]}
{"op":"mcm","clk":"11867602248","pt":1723482858153,"mc":[{"id":"1.231703146","rc":[{"batb":[[0,2.1,10],[1,2.02,37.98],[2,1.74,17.32]],"ltp":2.06,"tv":218.82,"id":40096576}]}]}
{"op":"mcm","clk":"11867602408","pt":1723482859889,"mc":[{"id":"1.231703146","rc":[{"batl":[[1,1.96,40.57],[2,1.98,13.85]],"ltp":1.88,"tv":601.71,"id":40096589}]}]}
{"op":"mcm","clk":"11867603181","pt":1723482868196,"mc":[{"id":"1.231703146","rc":[{"batb":[[0,2.02,37.98],[1,1.74,17.32],[2,1.73,85.5]],"ltp":2.06,"tv":218.82,"id":40096576}]}]}
{"op":"mcm","clk":"11867603439","pt":1723482871287,"mc":[{"id":"1.231703146","rc":[{"batb":[[0,2.12,10],[1,2.02,37.98],[2,1.74,17.32]],"ltp":2.06,"tv":218.82,"id":40096576}]}]}
{"op":"mcm","clk":"11867603641","pt":1723482873720,"mc":[{"id":"1.231703146","rc":[{"batb":[[1,1.74,17.32],[2,1.73,85.5]],"ltp":2.06,"tv":218.82,"id":40096576}]}]}
{"op":"mcm","clk":"11867604101","pt":1723482879420,"mc":[{"id":"1.231703146","rc":[{"batb":[[0,1.74,17.32],[1,1.73,85.5],[2,1.25,100]],"ltp":2.06,"tv":218.82,"id":40096576}]}]}
{"op":"mcm","clk":"11867604416","pt":1723482883635,"mc":[{"id":"1.231703146","rc":[{"batb":[[0,2.02,37.98],[1,1.74,17.32],[2,1.73,85.5]],"ltp":2.06,"tv":218.82,"id":40096576}]}]}
{"op":"mcm","clk":"11867604526","pt":1723482884797,"mc":[{"id":"1.231703146","rc":[{"batb":[[1,1.75,10],[2,1.74,17.32]],"ltp":2.06,"tv":218.82,"id":40096576}]}]}
{"op":"mcm","clk":"11867605170","pt":1723482892635,"mc":[{"id":"1.231703146","rc":[{"batb":[[1,1.74,17.32],[2,1.73,85.5]],"ltp":2.06,"tv":218.82,"id":40096576}]}]}
{"op":"mcm","clk":"11867605427","pt":1723482895818,"mc":[{"id":"1.231703146","rc":[{"batl":[[1,1.95,4.33],[2,1.96,40.57]],"ltp":1.88,"tv":601.71,"id":40096589}]}]}
{"op":"mcm","clk":"11867605511","pt":1723482896817,"mc":[{"id":"1.231703146","rc":[{"batb":[[0,2.04,10],[1,2.02,37.98],[2,1.74,17.32]],"ltp":2.06,"tv":218.82,"id":40096576}]}]}
{"op":"mcm","clk":"11867606090","pt":1723482904530,"mc":[{"id":"1.231703146","rc":[{"batb":[[0,2.02,37.98],[1,1.74,17.32],[2,1.73,85.5]],"ltp":2.06,"tv":218.82,"id":40096576}]}]}
{"op":"mcm","clk":"11867606437","pt":1723482908933,"mc":[{"id":"1.231703146","rc":[{"batb":[[0,2.04,10],[1,2.02,37.98],[2,1.74,17.32]],"ltp":2.06,"tv":218.82,"id":40096576}]}]}
{"op":"mcm","clk":"11867607136","pt":1723482916750,"mc":[{"id":"1.231703146","rc":[{"batb":[[0,2.02,37.98],[1,1.74,17.32],[2,1.73,85.5]],"ltp":2.06,"tv":218.82,"id":40096576}]}]}
{"op":"mcm","clk":"11867607576","pt":1723482921480,"mc":[{"id":"1.231703146","rc":[{"batb":[[0,2.04,10],[1,2.02,37.98],[2,1.74,17.32]],"ltp":2.06,"tv":218.82,"id":40096576}]}]}
{"op":"mcm","clk":"11867607907","pt":1723482924849,"mc":[{"id":"1.231703146","rc":[{"batl":[[0,1.93,6.72],[1,1.94,9.02],[2,1.95,4.33]],"ltp":1.88,"tv":601.71,"id":40096589}]}]}
{"op":"mcm","clk":"11867608237","pt":1723482928881,"mc":[{"id":"1.231703146","rc":[{"batb":[[0,2.02,37.98],[1,1.74,17.32],[2,1.73,85.5]],"ltp":2.06,"tv":218.82,"id":40096576}]}]}
{"op":"mcm","clk":"11867608475","pt":1723482931573,"mc":[{"id":"1.231703146","rc":[{"batb":[[0,2.06,10],[1,2.02,37.98],[2,1.74,17.32]],"ltp":2.06,"tv":218.82,"id":40096576}]}]}
{"op":"mcm","clk":"11867609223","pt":1723482939770,"mc":[{"id":"1.231703146","rc":[{"batb":[[0,2.02,37.98],[1,1.74,17.32],[2,1.73,85.5]],"ltp":2.06,"tv":218.82,"id":40096576}]}]}
{"op":"mcm","clk":"11867609775","pt":1723482945812,"mc":[{"id":"1.231703146","rc":[{"batb":[[0,2.04,10],[1,2.02,37.98],[2,1.74,17.32]],"ltp":2.06,"tv":218.82,"id":40096576}]}]}
{"op":"mcm","clk":"11867610487","pt":1723482954423,"mc":[{"id":"1.231703146","rc":[{"batb":[[0,2.02,37.98],[1,1.74,17.32],[2,1.73,85.5]],"ltp":2.06,"tv":218.82,"id":40096576}]}]}
{"op":"mcm","clk":"11867610912","pt":1723482959601,"mc":[{"id":"1.231703146","rc":[{"batb":[[0,2.06,10],[1,2.02,37.98],[2,1.74,17.32]],"ltp":2.06,"tv":218.82,"id":40096576}]}]}
{"op":"mcm","clk":"11867611673","pt":1723482968538,"mc":[{"id":"1.231703146","rc":[{"batb":[[0,2.02,37.98],[1,1.74,17.32],[2,1.73,85.5]],"ltp":2.06,"tv":218.82,"id":40096576}]}]}
{"op":"mcm","clk":"11867612154","pt":1723482973729,"mc":[{"id":"1.231703146","rc":[{"batb":[[0,2.08,10],[1,2.02,37.98],[2,1.74,17.32]],"ltp":2.06,"tv":218.82,"id":40096576}]}]}
{"op":"mcm","clk":"11867612362","pt":1723482976042,"mc":[{"id":"1.231703146","rc":[{"batl":[[2,1.96,40.57]],"ltp":1.88,"tv":601.71,"id":40096589}]}]}
{"op":"mcm","clk":"11867612375","pt":1723482976156,"mc":[{"id":"1.231703146","rc":[{"batl":[[0,1.92,4.4],[1,1.93,6.72],[2,1.94,9.02]],"ltp":1.88,"tv":601.71,"id":40096589}]}]}
{"op":"mcm","clk":"11867612905","pt":1723482981910,"mc":[{"id":"1.231703146","rc":[{"batb":[[0,2.02,37.98],[1,1.74,17.32],[2,1.73,85.5]],"ltp":2.06,"tv":218.82,"id":40096576}]}]}
{"op":"mcm","clk":"11867613126","pt":1723482984475,"mc":[{"id":"1.231703146","rc":[{"batl":[[0,1.93,11.1],[1,1.94,9.02],[2,1.96,40.57]],"ltp":1.88,"tv":601.71,"id":40096589}]}]}
{"op":"mcm","clk":"11867613374","pt":1723482986886,"mc":[{"id":"1.231703146","rc":[{"batl":[[0,1.93,6.72],[2,1.95,4.33]],"ltp":1.88,"tv":601.71,"id":40096589}]}]}
{"op":"mcm","clk":"11867613466","pt":1723482987684,"mc":[{"id":"1.231703146","rc":[{"batb":[[0,2.04,10],[1,2.02,37.98],[2,1.74,17.32]],"ltp":2.06,"tv":218.82,"id":40096576}]}]}
{"op":"mcm","clk":"11867614633","pt":1723483000869,"mc":[{"id":"1.231703146","rc":[{"batb":[[0,2.02,37.98],[1,1.74,17.32],[2,1.73,85.5]],"ltp":2.06,"tv":218.82,"id":40096576}]}]}
{"op":"mcm","clk":"11867615394","pt":1723483009397,"mc":[{"id":"1.231703146","rc":[{"batb":[[0,2.04,10],[1,2.02,37.98],[2,1.74,17.32]],"ltp":2.06,"tv":218.82,"id":40096576}]}]}
{"op":"mcm","clk":"11867616539","pt":1723483022109,"mc":[{"id":"1.231703146","rc":[{"batb":[[0,2.02,37.98],[1,1.74,17.32],[2,1.73,85.5]],"ltp":2.06,"tv":218.82,"id":40096576}]}]}
{"op":"mcm","clk":"11867616778","pt":1723483025140,"mc":[{"id":"1.231703146","rc":[{"batb":[[0,2.06,10],[1,2.02,37.98],[2,1.74,17.32]],"ltp":2.06,"tv":218.82,"id":40096576}]}]}
{"op":"mcm","clk":"11867617804","pt":1723483036803,"mc":[{"id":"1.231703146","rc":[{"batb":[[0,2.02,37.98],[1,1.74,17.32],[2,1.73,85.5]],"ltp":2.06,"tv":218.82,"id":40096576}]}]}
{"op":"mcm","clk":"11867618183","pt":1723483041662,"mc":[{"id":"1.231703146","rc":[{"batb":[[0,2.08,10],[1,2.02,37.98],[2,1.74,17.32]],"ltp":2.06,"tv":218.82,"id":40096576}]}]}
{"op":"mcm","clk":"11867618254","pt":1723483042336,"mc":[{"id":"1.231703146","rc":[{"batl":[[0,1.92,4.4],[1,1.93,6.72],[2,1.94,9.02]],"ltp":1.88,"tv":601.71,"id":40096589}]}]}
{"op":"mcm","clk":"11867618996","pt":1723483050874,"mc":[{"id":"1.231703146","rc":[{"batb":[[0,2.02,37.98],[1,1.74,17.32],[2,1.73,85.5]],"ltp":2.06,"tv":218.82,"id":40096576}]}]}
{"op":"mcm","clk":"11867619174","pt":1723483052967,"mc":[{"id":"1.231703146","rc":[{"batl":[[0,1.93,11.1],[1,1.94,9.02],[2,1.96,40.57]],"ltp":1.88,"tv":601.71,"id":40096589}]}]}
{"op":"mcm","clk":"11867619283","pt":1723483054070,"mc":[{"id":"1.231703146","rc":[{"batb":[[0,2.1,10],[1,2.02,37.98],[2,1.74,17.32]],"ltp":2.06,"tv":218.82,"id":40096576}]}]}
{"op":"mcm","clk":"11867620085","pt":1723483062890,"mc":[{"id":"1.231703146","rc":[{"batb":[[0,2.02,37.98],[1,1.74,17.32],[2,1.73,85.5]],"ltp":2.06,"tv":218.82,"id":40096576}]}]}
{"op":"mcm","clk":"11867620196","pt":1723483063998,"mc":[{"id":"1.231703146","rc":[{"batl":[[0,1.93,6.72],[2,1.95,4.33]],"ltp":1.88,"tv":601.71,"id":40096589}]}]}
{"op":"mcm","clk":"11867620619","pt":1723483069108,"mc":[{"id":"1.231703146","rc":[{"batb":[[0,2.04,10],[1,2.02,37.98],[2,1.74,17.32]],"ltp":2.06,"tv":218.82,"id":40096576}]}]}
{"op":"mcm","clk":"11867621323","pt":1723483076284,"mc":[{"id":"1.231703146","rc":[{"batb":[[0,2.02,37.98],[1,1.74,17.32],[2,1.73,85.5]],"ltp":2.06,"tv":218.82,"id":40096576}]}]}
{"op":"mcm","clk":"11867621715","pt":1723483080690,"mc":[{"id":"1.231703146","rc":[{"batb":[[0,2.04,10],[1,2.02,37.98],[2,1.74,17.32]],"ltp":2.06,"tv":218.82,"id":40096576}]}]}
{"op":"mcm","clk":"11867622295","pt":1723483087424,"mc":[{"id":"1.231703146","rc":[{"batb":[[0,2.02,37.98],[1,1.74,17.32],[2,1.73,85.5]],"ltp":2.06,"tv":218.82,"id":40096576}]}]}
{"op":"mcm","clk":"11867622568","pt":1723483090420,"mc":[{"id":"1.231703146","rc":[{"batb":[[0,2.06,10],[1,2.02,37.98],[2,1.74,17.32]],"ltp":2.06,"tv":218.82,"id":40096576}]}]}
{"op":"mcm","clk":"11867623150","pt":1723483097237,"mc":[{"id":"1.231703146","rc":[{"batb":[[0,2.02,37.98],[1,1.74,17.32],[2,1.73,85.5]],"ltp":2.06,"tv":218.82,"id":40096576}]}]}
{"op":"mcm","clk":"11867623422","pt":1723483100400,"mc":[{"id":"1.231703146","rc":[{"batb":[[0,2.04,10],[1,2.02,37.98],[2,1.74,17.32]],"ltp":2.06,"tv":218.82,"id":40096576}]}]}
{"op":"mcm","clk":"11867624026","pt":1723483107151,"mc":[{"id":"1.231703146","rc":[{"batb":[[0,2.02,37.98],[1,1.74,17.32],[2,1.73,85.5]],"ltp":2.06,"tv":218.82,"id":40096576}]}]}
{"op":"mcm","clk":"11867624262","pt":1723483109727,"mc":[{"id":"1.231703146","rc":[{"batb":[[0,2.06,10],[1,2.02,37.98],[2,1.74,17.32]],"ltp":2.06,"tv":218.82,"id":40096576}]}]}
{"op":"mcm","clk":"11867624761","pt":1723483115769,"mc":[{"id":"1.231703146","rc":[{"batb":[[0,2.02,37.98],[1,1.74,17.32],[2,1.73,85.5]],"ltp":2.06,"tv":218.82,"id":40096576}]}]}
{"op":"mcm","clk":"11867625029","pt":1723483118974,"mc":[{"id":"1.231703146","rc":[{"batb":[[0,2.04,10],[1,2.02,37.98],[2,1.74,17.32]],"ltp":2.06,"tv":218.82,"id":40096576}]}]}
{"op":"mcm","clk":"11867625625","pt":1723483124965,"mc":[{"id":"1.231703146","rc":[{"batb":[[0,2.02,37.98],[1,1.74,17.32],[2,1.73,85.5]],"ltp":2.06,"tv":218.82,"id":40096576}]}]}
{"op":"mcm","clk":"11867625922","pt":1723483128072,"mc":[{"id":"1.231703146","rc":[{"batb":[[0,2.04,10],[1,2.02,37.98],[2,1.74,17.32]],"ltp":2.06,"tv":218.82,"id":40096576}]}]}
{"op":"mcm","clk":"11867626363","pt":1723483133193,"mc":[{"id":"1.231703146","rc":[{"batb":[[0,2.02,37.98],[1,1.74,17.32],[2,1.73,85.5]],"ltp":2.06,"tv":218.82,"id":40096576}]}]}
{"op":"mcm","clk":"11867626567","pt":1723483135569,"mc":[{"id":"1.231703146","rc":[{"batb":[[0,2.06,10],[1,2.02,37.98],[2,1.74,17.32]],"ltp":2.06,"tv":218.82,"id":40096576}]}]}
{"op":"mcm","clk":"11867627068","pt":1723483141899,"mc":[{"id":"1.231703146","rc":[{"batb":[[0,2.02,37.98],[1,1.74,17.32],[2,1.73,85.5]],"ltp":2.06,"tv":218.82,"id":40096576}]}]}
{"op":"mcm","clk":"11867627297","pt":1723483144706,"mc":[{"id":"1.231703146","rc":[{"batb":[[0,2.08,10],[1,2.02,37.98],[2,1.74,17.32]],"ltp":2.06,"tv":218.82,"id":40096576}]}]}
{"op":"mcm","clk":"11867627497","pt":1723483146882,"mc":[{"id":"1.231703146","rc":[{"batl":[[2,1.96,40.57]],"ltp":1.88,"tv":601.71,"id":40096589}]}]}
{"op":"mcm","clk":"11867627519","pt":1723483147082,"mc":[{"id":"1.231703146","rc":[{"batl":[[0,1.92,4.4],[1,1.93,6.72],[2,1.94,9.02]],"ltp":1.88,"tv":601.71,"id":40096589}]}]}
{"op":"mcm","clk":"11867627757","pt":1723483150278,"mc":[{"id":"1.231703146","rc":[{"batb":[[0,2.02,37.98],[1,1.74,17.32],[2,1.73,85.5]],"ltp":2.06,"tv":218.82,"id":40096576}]}]}
{"op":"mcm","clk":"11867627856","pt":1723483151600,"mc":[{"id":"1.231703146","rc":[{"batb":[[1,1.77,72.12]],"batl":[[0,1.93,11.1],[1,1.94,9.02],[2,1.96,40.57]],"ltp":1.88,"tv":601.71,"id":40096589}]}]}
{"op":"mcm","clk":"11867627971","pt":1723483152776,"mc":[{"id":"1.231703146","rc":[{"batb":[[0,2.04,10],[1,2.02,37.98],[2,1.74,17.32]],"ltp":2.06,"tv":218.82,"id":40096576}]}]}
{"op":"mcm","clk":"11867628045","pt":1723483153704,"mc":[{"id":"1.231703146","rc":[{"batl":[[0,1.93,6.72],[2,1.95,4.33]],"ltp":1.88,"tv":601.71,"id":40096589}]}]}
{"op":"mcm","clk":"11867628634","pt":1723483159619,"mc":[{"id":"1.231703146","rc":[{"batb":[[0,2.02,37.98],[1,1.74,17.32],[2,1.73,85.5]],"ltp":2.06,"tv":218.82,"id":40096576}]}]}
{"op":"mcm","clk":"11867628980","pt":1723483162997,"mc":[{"id":"1.231703146","rc":[{"batb":[[0,2.06,10],[1,2.02,37.98],[2,1.74,17.32]],"ltp":2.06,"tv":218.82,"id":40096576}]}]}
{"op":"mcm","clk":"11867629575","pt":1723483170012,"mc":[{"id":"1.231703146","rc":[{"batb":[[0,2.02,37.98],[1,1.74,17.32],[2,1.73,85.5]],"ltp":2.06,"tv":218.82,"id":40096576}]}]}
{"op":"mcm","clk":"11867629965","pt":1723483174333,"mc":[{"id":"1.231703146","rc":[{"batb":[[0,2.04,10],[1,2.02,37.98],[2,1.74,17.32]],"ltp":2.06,"tv":218.82,"id":40096576}]}]}
{"op":"mcm","clk":"11867630560","pt":1723483181542,"mc":[{"id":"1.231703146","rc":[{"batb":[[0,2.02,37.98],[1,1.74,17.32],[2,1.73,85.5]],"ltp":2.06,"tv":218.82,"id":40096576}]}]}
{"op":"mcm","clk":"11867630935","pt":1723483186158,"mc":[{"id":"1.231703146","rc":[{"batb":[[0,2.04,10],[1,2.02,37.98],[2,1.74,17.32]],"ltp":2.06,"tv":218.82,"id":40096576}]}]}
{"op":"mcm","clk":"11867631676","pt":1723483193747,"mc":[{"id":"1.231703146","rc":[{"batb":[[0,2.02,37.98],[1,1.74,17.32],[2,1.73,85.5]],"ltp":2.06,"tv":218.82,"id":40096576}]}]}
{"op":"mcm","clk":"11867631938","pt":1723483196702,"mc":[{"id":"1.231703146","rc":[{"batb":[[0,2.06,10],[1,2.02,37.98],[2,1.74,17.32]],"ltp":2.06,"tv":218.82,"id":40096576}]}]}
{"op":"mcm","clk":"11867632502","pt":1723483202580,"mc":[{"id":"1.231703146","rc":[{"batb":[[0,2.02,37.98],[1,1.74,17.32],[2,1.73,85.5]],"ltp":2.06,"tv":218.82,"id":40096576}]}]}
{"op":"mcm","clk":"11867632752","pt":1723483205185,"mc":[{"id":"1.231703146","rc":[{"batb":[[0,2.08,10],[1,2.02,37.98],[2,1.74,17.32]],"ltp":2.06,"tv":218.82,"id":40096576}]}]}
{"op":"mcm","clk":"11867632874","pt":1723483206653,"mc":[{"id":"1.231703146","rc":[{"batl":[[0,1.92,4.4],[1,1.93,6.72],[2,1.94,9.02]],"ltp":1.88,"tv":601.71,"id":40096589}]}]}
{"op":"mcm","clk":"11867633221","pt":1723483211268,"mc":[{"id":"1.231703146","rc":[{"batb":[[0,2.02,37.98],[1,1.74,17.32],[2,1.73,85.5]],"ltp":2.06,"tv":218.82,"id":40096576}]}]}
{"op":"mcm","clk":"11867633451","pt":1723483213975,"mc":[{"id":"1.231703146","rc":[{"batl":[[0,1.93,11.1],[1,1.94,9.02],[2,1.96,40.57]],"ltp":1.88,"tv":601.71,"id":40096589},{"batb":[[0,2.04,10],[1,2.02,37.98],[2,1.74,17.32]],"ltp":2.06,"tv":218.82,"id":40096576}]}]}
{"op":"mcm","clk":"11867633651","pt":1723483216370,"mc":[{"id":"1.231703146","rc":[{"batl":[[0,1.93,6.72],[2,1.95,4.33]],"ltp":1.88,"tv":601.71,"id":40096589}]}]}
{"op":"mcm","clk":"11867633903","pt":1723483219259,"mc":[{"id":"1.231703146","rc":[{"batb":[[0,2.02,37.98],[1,1.74,17.32],[2,1.73,85.5]],"ltp":2.06,"tv":218.82,"id":40096576}]}]}
{"op":"mcm","clk":"11867634220","pt":1723483222701,"mc":[{"id":"1.231703146","rc":[{"batb":[[0,2.04,10],[1,2.02,37.98],[2,1.74,17.32]],"ltp":2.06,"tv":218.82,"id":40096576}]}]}
{"op":"mcm","clk":"11867634627","pt":1723483227155,"mc":[{"id":"1.231703146","rc":[{"trd":[[1.86,2.02]],"batb":[[0,1.86,35.61]],"ltp":1.86,"tv":603.73,"id":40096589}],"tv":822.55}]}
{"op":"mcm","clk":"11867634733","pt":1723483228509,"mc":[{"id":"1.231703146","rc":[{"batb":[[0,2.02,37.98],[1,1.74,17.32],[2,1.73,85.5]],"ltp":2.06,"tv":218.82,"id":40096576}]}]}
{"op":"mcm","clk":"11867634993","pt":1723483231771,"mc":[{"id":"1.231703146","rc":[{"batb":[[0,2.04,10],[1,2.02,37.98],[2,1.74,17.32]],"ltp":2.06,"tv":218.82,"id":40096576}]}]}
{"op":"mcm","clk":"11867635519","pt":1723483238416,"mc":[{"id":"1.231703146","rc":[{"batb":[[0,2.02,37.98],[1,1.74,17.32],[2,1.73,85.5]],"ltp":2.06,"tv":218.82,"id":40096576}]}]}
{"op":"mcm","clk":"11867635854","pt":1723483242321,"mc":[{"id":"1.231703146","rc":[{"batb":[[0,2.04,10],[1,2.02,37.98],[2,1.74,17.32]],"ltp":2.06,"tv":218.82,"id":40096576}]}]}
{"op":"mcm","clk":"11867636419","pt":1723483249414,"mc":[{"id":"1.231703146","rc":[{"batb":[[0,2.02,37.98],[1,1.74,17.32],[2,1.73,85.5]],"ltp":2.06,"tv":218.82,"id":40096576}]}]}
{"op":"mcm","clk":"11867636617","pt":1723483251829,"mc":[{"id":"1.231703146","rc":[{"batb":[[0,2.06,10],[1,2.02,37.98],[2,1.74,17.32]],"ltp":2.06,"tv":218.82,"id":40096576}]}]}
{"op":"mcm","clk":"11867636828","pt":1723483254138,"mc":[{"id":"1.231703146","rc":[{"batb":[[0,1.86,36.61]],"ltp":1.86,"tv":603.73,"id":40096589}]}]}
{"op":"mcm","clk":"11867637073","pt":1723483257146,"mc":[{"id":"1.231703146","rc":[{"batb":[[0,2.02,37.98],[1,1.74,17.32],[2,1.73,85.5]],"ltp":2.06,"tv":218.82,"id":40096576}]}]}
{"op":"mcm","clk":"11867637332","pt":1723483260143,"mc":[{"id":"1.231703146","rc":[{"batb":[[0,2.04,10],[1,2.02,37.98],[2,1.74,17.32]],"ltp":2.06,"tv":218.82,"id":40096576}]}]}
{"op":"mcm","clk":"11867637905","pt":1723483266224,"mc":[{"id":"1.231703146","rc":[{"batb":[[0,2.02,37.98],[1,1.74,17.32],[2,1.73,85.5]],"ltp":2.06,"tv":218.82,"id":40096576}]}]}
{"op":"mcm","clk":"11867638122","pt":1723483268857,"mc":[{"id":"1.231703146","rc":[{"batb":[[0,2.04,10],[1,2.02,37.98],[2,1.74,17.32]],"ltp":2.06,"tv":218.82,"id":40096576}]}]}
{"op":"mcm","clk":"11867638215","pt":1723483269757,"mc":[{"id":"1.231703146","rc":[{"batb":[[0,1.86,35.61]],"ltp":1.86,"tv":603.73,"id":40096589}]}]}
{"op":"mcm","clk":"11867638594","pt":1723483273948,"mc":[{"id":"1.231703146","rc":[{"batb":[[0,2.02,37.98],[1,1.74,17.32],[2,1.73,85.5]],"ltp":2.06,"tv":218.82,"id":40096576}]}]}
{"op":"mcm","clk":"11867639689","pt":1723483286573,"mc":[{"id":"1.231703146","rc":[{"batb":[[0,2.04,10],[1,2.02,37.98],[2,1.74,17.32]],"ltp":2.06,"tv":218.82,"id":40096576}]}]}
{"op":"mcm","clk":"11867640162","pt":1723483291877,"mc":[{"id":"1.231703146","rc":[{"batb":[[0,2.02,37.98],[1,1.74,17.32],[2,1.73,85.5]],"ltp":2.06,"tv":218.82,"id":40096576}]}]}
{"op":"mcm","clk":"11867640423","pt":1723483294830,"mc":[{"id":"1.231703146","rc":[{"batb":[[0,2.04,10],[1,2.02,37.98],[2,1.74,17.32]],"ltp":2.06,"tv":218.82,"id":40096576}]}]}
{"op":"mcm","clk":"11867640977","pt":1723483300542,"mc":[{"id":"1.231703146","rc":[{"batb":[[0,2.02,37.98],[1,1.74,17.32],[2,1.73,85.5]],"ltp":2.06,"tv":218.82,"id":40096576}]}]}
{"op":"mcm","clk":"11867641071","pt":1723483301642,"mc":[{"id":"1.231703146","rc":[{"batb":[[0,1.91,2.14],[1,1.86,35.61],[2,1.77,72.12]],"ltp":1.86,"tv":603.73,"id":40096589}]}]}
{"op":"mcm","clk":"11867641203","pt":1723483303058,"mc":[{"id":"1.231703146","rc":[{"batb":[[0,2.04,10],[1,2.02,37.98],[2,1.74,17.32]],"ltp":2.06,"tv":218.82,"id":40096576}]}]}
{"op":"mcm","clk":"11867641686","pt":1723483308781,"mc":[{"id":"1.231703146","rc":[{"batb":[[0,2.02,37.98],[1,1.74,17.32],[2,1.73,85.5]],"ltp":2.06,"tv":218.82,"id":40096576}]}]}
{"op":"mcm","clk":"11867641977","pt":1723483312371,"mc":[{"id":"1.231703146","rc":[{"batb":[[0,2.06,10],[1,2.02,37.98],[2,1.74,17.32]],"ltp":2.06,"tv":218.82,"id":40096576}]}]}
{"op":"mcm","clk":"11867642212","pt":1723483314753,"mc":[{"id":"1.231703146","rc":[{"batb":[[0,1.86,35.61],[1,1.77,72.12],[2,1.76,444]],"ltp":1.86,"tv":603.73,"id":40096589}]}]}
{"op":"mcm","clk":"11867642527","pt":1723483318782,"mc":[{"id":"1.231703146","rc":[{"batb":[[0,2.02,37.98],[1,1.74,17.32],[2,1.73,85.5]],"ltp":2.06,"tv":218.82,"id":40096576}]}]}
{"op":"mcm","clk":"11867642795","pt":1723483321782,"mc":[{"id":"1.231703146","rc":[{"batb":[[0,2.04,10],[1,2.02,37.98],[2,1.74,17.32]],"ltp":2.06,"tv":218.82,"id":40096576}]}]}
{"op":"mcm","clk":"11867643309","pt":1723483328302,"mc":[{"id":"1.231703146","rc":[{"batb":[[0,2.02,37.98],[1,1.74,17.32],[2,1.73,85.5]],"ltp":2.06,"tv":218.82,"id":40096576}]}]}
{"op":"mcm","clk":"11867643656","pt":1723483332085,"mc":[{"id":"1.231703146","rc":[{"batb":[[0,2.04,10],[1,2.02,37.98],[2,1.74,17.32]],"ltp":2.06,"tv":218.82,"id":40096576}]}]}
{"op":"mcm","clk":"11867644220","pt":1723483338313,"mc":[{"id":"1.231703146","rc":[{"batb":[[0,2.02,37.98],[1,1.74,17.32],[2,1.73,85.5]],"ltp":2.06,"tv":218.82,"id":40096576}]}]}
{"op":"mcm","clk":"11867644495","pt":1723483341412,"mc":[{"id":"1.231703146","rc":[{"batb":[[0,2.04,10],[1,2.02,37.98],[2,1.74,17.32]],"ltp":2.06,"tv":218.82,"id":40096576}]}]}
{"op":"mcm","clk":"11867645021","pt":1723483347105,"mc":[{"id":"1.231703146","rc":[{"batb":[[0,2.02,37.98],[1,1.74,17.32],[2,1.73,85.5]],"ltp":2.06,"tv":218.82,"id":40096576}]}]}
{"op":"mcm","clk":"11867645234","pt":1723483349413,"mc":[{"id":"1.231703146","rc":[{"batb":[[0,2.16,2.14],[1,2.02,37.98],[2,1.74,17.32]],"ltp":2.06,"tv":218.82,"id":40096576}]}]}
{"op":"mcm","clk":"11867645392","pt":1723483351036,"mc":[{"id":"1.231703146","rc":[{"batl":[[0,1.93,11.1],[2,1.96,40.57]],"ltp":1.86,"tv":603.73,"id":40096589},{"batb":[[1,2.04,10],[2,2.02,37.98]],"batl":[[1,2.24,1.57]],"ltp":2.06,"tv":218.82,"id":40096576}]}]}
{"op":"mcm","clk":"11867645466","pt":1723483351801,"mc":[{"id":"1.231703146","rc":[{"batl":[[1,2.22,1.57]],"ltp":2.06,"tv":218.82,"id":40096576}]}]}
{"op":"mcm","clk":"11867645896","pt":1723483356896,"mc":[{"id":"1.231703146","rc":[{"batb":[[1,2.02,37.98],[2,1.74,17.32]],"ltp":2.06,"tv":218.82,"id":40096576}]}]}
{"op":"mcm","clk":"11867646402","pt":1723483362648,"mc":[{"id":"1.231703146","rc":[{"batb":[[0,2.02,37.98],[1,1.74,17.32],[2,1.73,85.5]],"ltp":2.06,"tv":218.82,"id":40096576}]}]}
{"op":"mcm","clk":"11867646512","pt":1723483363745,"mc":[{"id":"1.231703146","rc":[{"batl":[[0,1.93,6.72],[2,1.95,4.33]],"ltp":1.86,"tv":603.73,"id":40096589}]}]}
{"op":"mcm","clk":"11867646767","pt":1723483366527,"mc":[{"id":"1.231703146","rc":[{"batb":[[0,2.04,10],[1,2.02,37.98],[2,1.74,17.32]],"ltp":2.06,"tv":218.82,"id":40096576}]}]}
{"op":"mcm","clk":"11867647307","pt":1723483372840,"mc":[{"id":"1.231703146","rc":[{"batb":[[0,2.02,37.98],[1,1.74,17.32],[2,1.73,85.5]],"ltp":2.06,"tv":218.82,"id":40096576}]}]}
{"op":"mcm","clk":"11867647589","pt":1723483375830,"mc":[{"id":"1.231703146","rc":[{"batb":[[0,2.06,10],[1,2.02,37.98],[2,1.74,17.32]],"ltp":2.06,"tv":218.82,"id":40096576}]}]}
{"op":"mcm","clk":"11867648301","pt":1723483382865,"mc":[{"id":"1.231703146","rc":[{"batb":[[0,2.02,37.98],[1,1.74,17.32],[2,1.73,85.5]],"ltp":2.06,"tv":218.82,"id":40096576}]}]}
{"op":"mcm","clk":"11867648724","pt":1723483387175,"mc":[{"id":"1.231703146","rc":[{"batb":[[0,2.04,10],[1,2.02,37.98],[2,1.74,17.32]],"ltp":2.06,"tv":218.82,"id":40096576}]}]}
{"op":"mcm","clk":"11867649360","pt":1723483394689,"mc":[{"id":"1.231703146","rc":[{"batb":[[0,2.02,37.98],[1,1.74,17.32],[2,1.73,85.5]],"ltp":2.06,"tv":218.82,"id":40096576}]}]}
{"op":"mcm","clk":"11867649600","pt":1723483397687,"mc":[{"id":"1.231703146","rc":[{"batb":[[0,2.06,10],[1,2.02,37.98],[2,1.74,17.32]],"ltp":2.06,"tv":218.82,"id":40096576}]}]}
{"op":"mcm","clk":"11867650125","pt":1723483403289,"mc":[{"id":"1.231703146","rc":[{"batb":[[0,2.02,37.98],[1,1.74,17.32],[2,1.73,85.5]],"ltp":2.06,"tv":218.82,"id":40096576}]}]}
{"op":"mcm","clk":"11867650289","pt":1723483404771,"mc":[{"id":"1.231703146","rc":[{"batb":[[0,1.91,2.14],[1,1.86,35.61],[2,1.77,72.12]],"ltp":1.86,"tv":603.73,"id":40096589}]}]}
{"op":"mcm","clk":"11867650454","pt":1723483406680,"mc":[{"id":"1.231703146","rc":[{"batb":[[0,2.04,10],[1,2.02,37.98],[2,1.74,17.32]],"ltp":2.06,"tv":218.82,"id":40096576}]}]}
{"op":"mcm","clk":"11867650872","pt":1723483411705,"mc":[{"id":"1.231703146","rc":[{"batb":[[0,1.86,35.61],[1,1.77,72.12],[2,1.76,444]],"ltp":1.86,"tv":603.73,"id":40096589}]}]}
{"op":"mcm","clk":"11867651016","pt":1723483413399,"mc":[{"id":"1.231703146","rc":[{"batb":[[0,2.02,37.98],[1,1.74,17.32],[2,1.73,85.5]],"ltp":2.06,"tv":218.82,"id":40096576}]}]}
{"op":"mcm","clk":"11867651273","pt":1723483416691,"mc":[{"id":"1.231703146","rc":[{"batb":[[0,2.04,10],[1,2.02,37.98],[2,1.74,17.32]],"ltp":2.06,"tv":218.82,"id":40096576}]}]}
{"op":"mcm","clk":"11867651801","pt":1723483423410,"mc":[{"id":"1.231703146","rc":[{"batb":[[0,2.02,37.98],[1,1.74,17.32],[2,1.73,85.5]],"ltp":2.06,"tv":218.82,"id":40096576}]}]}
{"op":"mcm","clk":"11867652117","pt":1723483427224,"mc":[{"id":"1.231703146","rc":[{"batb":[[0,2.04,10],[1,2.02,37.98],[2,1.74,17.32]],"ltp":2.06,"tv":218.82,"id":40096576}]}]}
{"op":"mcm","clk":"11867652268","pt":1723483429100,"mc":[{"id":"1.231703146","rc":[{"batb":[[0,1.91,2.14],[1,1.86,35.61],[2,1.77,72.12]],"ltp":1.86,"tv":603.73,"id":40096589}]}]}
{"op":"mcm","clk":"11867652660","pt":1723483433432,"mc":[{"id":"1.231703146","rc":[{"batb":[[0,2.02,37.98],[1,1.74,17.32],[2,1.73,85.5]],"ltp":2.06,"tv":218.82,"id":40096576}]}]}
{"op":"mcm","clk":"11867653012","pt":1723483437199,"mc":[{"id":"1.231703146","rc":[{"batb":[[0,2.04,10],[1,2.02,37.98],[2,1.74,17.32]],"ltp":2.06,"tv":218.82,"id":40096576}]}]}
{"op":"mcm","clk":"11867653760","pt":1723483444905,"mc":[{"id":"1.231703146","rc":[{"batb":[[0,2.02,37.98],[1,1.74,17.32],[2,1.73,85.5]],"ltp":2.06,"tv":218.82,"id":40096576}]}]}
{"op":"mcm","clk":"11867654236","pt":1723483449604,"mc":[{"id":"1.231703146","rc":[{"batb":[[0,2.04,10],[1,2.02,37.98],[2,1.74,17.32]],"ltp":2.06,"tv":218.82,"id":40096576}]}]}
{"op":"mcm","clk":"11867655014","pt":1723483457196,"mc":[{"id":"1.231703146","rc":[{"batb":[[0,2.02,37.98],[1,1.74,17.32],[2,1.73,85.5]],"ltp":2.06,"tv":218.82,"id":40096576}]}]}
{"op":"mcm","clk":"11867655456","pt":1723483461783,"mc":[{"id":"1.231703146","rc":[{"batb":[[0,2.04,10],[1,2.02,37.98],[2,1.74,17.32]],"ltp":2.06,"tv":218.82,"id":40096576}]}]}
{"op":"mcm","clk":"11867655572","pt":1723483463197,"mc":[{"id":"1.231703146","rc":[{"trd":[[1.91,152.53]],"batb":[[0,1.86,35.86],[1,1.77,72.12],[2,1.76,444]],"ltp":1.91,"tv":607.51,"id":40096589}],"tv":826.33}]}
{"op":"mcm","clk":"11867656094","pt":1723483468524,"mc":[{"id":"1.231703146","rc":[{"batb":[[0,2.02,37.98],[1,1.74,17.32],[2,1.73,85.5]],"ltp":2.06,"tv":218.82,"id":40096576}]}]}
{"op":"mcm","clk":"11867656310","pt":1723483470919,"mc":[{"id":"1.231703146","rc":[{"batb":[[0,2.06,10],[1,2.02,37.98],[2,1.74,17.32]],"ltp":2.06,"tv":218.82,"id":40096576}]}]}
{"op":"mcm","clk":"11867656891","pt":1723483477110,"mc":[{"id":"1.231703146","rc":[{"batb":[[0,2.02,37.98],[1,1.74,17.32],[2,1.73,85.5]],"ltp":2.06,"tv":218.82,"id":40096576}]}]}
{"op":"mcm","clk":"11867657113","pt":1723483479447,"mc":[{"id":"1.231703146","rc":[{"batb":[[0,2.08,10],[1,2.02,37.98],[2,1.74,17.32]],"ltp":2.06,"tv":218.82,"id":40096576}]}]}
{"op":"mcm","clk":"11867657307","pt":1723483481337,"mc":[{"id":"1.231703146","rc":[{"batl":[[0,1.92,4.4],[1,1.93,6.72],[2,1.94,9.02]],"ltp":1.91,"tv":607.51,"id":40096589}]}]}
{"op":"mcm","clk":"11867657725","pt":1723483485531,"mc":[{"id":"1.231703146","rc":[{"batb":[[0,2.02,37.98],[1,1.74,17.32],[2,1.73,85.5]],"ltp":2.06,"tv":218.82,"id":40096576}]}]}
{"op":"mcm","clk":"11867657851","pt":1723483486932,"mc":[{"id":"1.231703146","rc":[{"trd":[[1.86,5.9]],"batb":[[0,1.86,33.67]],"batl":[[0,1.93,11.1],[1,1.94,9.02],[2,1.96,40.57]],"ltp":1.86,"tv":611.39,"id":40096589}],"tv":830.21}]}
{"op":"mcm","clk":"11867658034","pt":1723483488831,"mc":[{"id":"1.231703146","rc":[{"batl":[[0,1.93,6.72],[2,1.95,4.33]],"ltp":1.86,"tv":611.39,"id":40096589},{"batb":[[0,2.04,10],[1,2.02,37.98],[2,1.74,17.32]],"ltp":2.06,"tv":218.82,"id":40096576}]}]}
{"op":"mcm","clk":"11867658761","pt":1723483495940,"mc":[{"id":"1.231703146","rc":[{"batb":[[0,2.02,37.98],[1,1.74,17.32],[2,1.73,85.5]],"ltp":2.06,"tv":218.82,"id":40096576}]}]}
{"op":"mcm","clk":"11867659131","pt":1723483500276,"mc":[{"id":"1.231703146","rc":[{"batb":[[0,2.04,10],[1,2.02,37.98],[2,1.74,17.32]],"ltp":2.06,"tv":218.82,"id":40096576}]}]}
{"op":"mcm","clk":"11867659763","pt":1723483507477,"mc":[{"id":"1.231703146","rc":[{"batb":[[0,2.02,37.98],[1,1.74,17.32],[2,1.73,85.5]],"ltp":2.06,"tv":218.82,"id":40096576}]}]}
{"op":"mcm","clk":"11867660174","pt":1723483512079,"mc":[{"id":"1.231703146","rc":[{"batb":[[0,2.04,10],[1,2.02,37.98],[2,1.74,17.32]],"ltp":2.06,"tv":218.82,"id":40096576}]}]}
{"op":"mcm","clk":"11867660847","pt":1723483519799,"mc":[{"id":"1.231703146","rc":[{"batb":[[0,2.02,37.98],[1,1.74,17.32],[2,1.73,85.5]],"ltp":2.06,"tv":218.82,"id":40096576}]}]}
{"op":"mcm","clk":"11867661672","pt":1723483529485,"mc":[{"id":"1.231703146","rc":[{"batb":[[0,2.04,10],[1,2.02,37.98],[2,1.74,17.32]],"ltp":2.06,"tv":218.82,"id":40096576}]}]}
{"op":"mcm","clk":"11867662291","pt":1723483536902,"mc":[{"id":"1.231703146","rc":[{"batb":[[0,2.02,37.98],[1,1.74,17.32],[2,1.73,85.5]],"ltp":2.06,"tv":218.82,"id":40096576}]}]}
{"op":"mcm","clk":"11867662700","pt":1723483541291,"mc":[{"id":"1.231703146","rc":[{"batb":[[0,2.04,10],[1,2.02,37.98],[2,1.74,17.32]],"ltp":2.06,"tv":218.82,"id":40096576}]}]}
{"op":"mcm","clk":"11867663379","pt":1723483549901,"mc":[{"id":"1.231703146","rc":[{"batb":[[0,2.16,2.14]],"ltp":2.06,"tv":218.82,"id":40096576}]}]}
{"op":"mcm","clk":"11867663531","pt":1723483551418,"mc":[{"id":"1.231703146","rc":[{"batl":[[0,1.93,11.1],[2,1.96,40.57]],"ltp":1.86,"tv":611.39,"id":40096589}]}]}
{"op":"mcm","clk":"11867663736","pt":1723483553825,"mc":[{"id":"1.231703146","rc":[{"batb":[[0,2.02,37.98],[1,1.74,17.32],[2,1.73,85.5]],"ltp":2.06,"tv":218.82,"id":40096576}]}]}
{"op":"mcm","clk":"11867663839","pt":1723483554925,"mc":[{"id":"1.231703146","rc":[{"batb":[[0,2.04,10],[1,2.02,37.98],[2,1.74,17.32]],"ltp":2.06,"tv":218.82,"id":40096576}]}]}
{"op":"mcm","clk":"11867663948","pt":1723483556022,"mc":[{"id":"1.231703146","rc":[{"batl":[[0,1.93,6.72],[2,1.95,4.33]],"ltp":1.86,"tv":611.39,"id":40096589}]}]}
{"op":"mcm","clk":"11867664632","pt":1723483563331,"mc":[{"id":"1.231703146","rc":[{"batb":[[0,2.02,37.98],[1,1.74,17.32],[2,1.73,85.5]],"ltp":2.06,"tv":218.82,"id":40096576}]}]}
{"op":"mcm","clk":"11867665097","pt":1723483568244,"mc":[{"id":"1.231703146","rc":[{"batb":[[0,2.04,10],[1,2.02,37.98],[2,1.74,17.32]],"ltp":2.06,"tv":218.82,"id":40096576}]}]}
{"op":"mcm","clk":"11867665800","pt":1723483576178,"mc":[{"id":"1.231703146","rc":[{"batb":[[0,2.02,37.98],[1,1.74,17.32],[2,1.73,85.5]],"ltp":2.06,"tv":218.82,"id":40096576}]}]}
{"op":"mcm","clk":"11867666222","pt":1723483580850,"mc":[{"id":"1.231703146","rc":[{"batb":[[0,2.04,10],[1,2.02,37.98],[2,1.74,17.32]],"ltp":2.06,"tv":218.82,"id":40096576}]}]}
{"op":"mcm","clk":"11867666902","pt":1723483588297,"mc":[{"id":"1.231703146","rc":[{"batb":[[0,2.02,37.98],[1,1.74,17.32],[2,1.73,85.5]],"ltp":2.06,"tv":218.82,"id":40096576}]}]}
{"op":"mcm","clk":"11867667297","pt":1723483592688,"mc":[{"id":"1.231703146","rc":[{"batb":[[0,2.04,10],[1,2.02,37.98],[2,1.74,17.32]],"ltp":2.06,"tv":218.82,"id":40096576}]}]}
{"op":"mcm","clk":"11867668076","pt":1723483600827,"mc":[{"id":"1.231703146","rc":[{"batb":[[0,2.02,37.98],[1,1.74,17.32],[2,1.73,85.5]],"ltp":2.06,"tv":218.82,"id":40096576}]}]}
{"op":"mcm","clk":"11867668504","pt":1723483605922,"mc":[{"id":"1.231703146","rc":[{"batb":[[0,2.04,10],[1,2.02,37.98],[2,1.74,17.32]],"ltp":2.06,"tv":218.82,"id":40096576}]}]}
{"op":"mcm","clk":"11867669103","pt":1723483613711,"mc":[{"id":"1.231703146","rc":[{"batb":[[0,2.02,37.98],[1,1.74,17.32],[2,1.73,85.5]],"ltp":2.06,"tv":218.82,"id":40096576}]}]}
{"op":"mcm","clk":"11867669469","pt":1723483618410,"mc":[{"id":"1.231703146","rc":[{"batb":[[0,2.04,10],[1,2.02,37.98],[2,1.74,17.32]],"ltp":2.06,"tv":218.82,"id":40096576}]}]}
{"op":"mcm","clk":"11867670123","pt":1723483626052,"mc":[{"id":"1.231703146","rc":[{"batb":[[0,2.02,37.98],[1,1.74,17.32],[2,1.73,85.5]],"ltp":2.06,"tv":218.82,"id":40096576}]}]}
{"op":"mcm","clk":"11867670538","pt":1723483630231,"mc":[{"id":"1.231703146","rc":[{"batb":[[0,2.04,10],[1,2.02,37.98],[2,1.74,17.32]],"ltp":2.06,"tv":218.82,"id":40096576}]}]}
{"op":"mcm","clk":"11867671257","pt":1723483638393,"mc":[{"id":"1.231703146","rc":[{"batb":[[0,2.02,37.98],[1,1.74,17.32],[2,1.73,85.5]],"ltp":2.06,"tv":218.82,"id":40096576}]}]}
{"op":"mcm","clk":"11867671674","pt":1723483642859,"mc":[{"id":"1.231703146","rc":[{"batb":[[0,2.04,10],[1,2.02,37.98],[2,1.74,17.32]],"ltp":2.06,"tv":218.82,"id":40096576}]}]}
{"op":"mcm","clk":"11867672303","pt":1723483650014,"mc":[{"id":"1.231703146","rc":[{"batb":[[0,2.02,37.98],[1,1.74,17.32],[2,1.73,85.5]],"ltp":2.06,"tv":218.82,"id":40096576}]}]}
{"op":"mcm","clk":"11867672640","pt":1723483653880,"mc":[{"id":"1.231703146","rc":[{"batb":[[0,2.04,10],[1,2.02,37.98],[2,1.74,17.32]],"ltp":2.06,"tv":218.82,"id":40096576}]}]}
{"op":"mcm","clk":"11867673225","pt":1723483660510,"mc":[{"id":"1.231703146","rc":[{"batb":[[0,2.02,37.98],[1,1.74,17.32],[2,1.73,85.5]],"ltp":2.06,"tv":218.82,"id":40096576}]}]}
{"op":"mcm","clk":"11867673514","pt":1723483663800,"mc":[{"id":"1.231703146","rc":[{"batb":[[0,2.04,10],[1,2.02,37.98],[2,1.74,17.32]],"ltp":2.06,"tv":218.82,"id":40096576}]}]}
{"op":"mcm","clk":"11867674198","pt":1723483671591,"mc":[{"id":"1.231703146","rc":[{"batb":[[0,2.02,37.98],[1,1.74,17.32],[2,1.73,85.5]],"ltp":2.06,"tv":218.82,"id":40096576}]}]}
{"op":"mcm","clk":"11867674691","pt":1723483676710,"mc":[{"id":"1.231703146","rc":[{"batb":[[0,2.04,10],[1,2.02,37.98],[2,1.74,17.32]],"ltp":2.06,"tv":218.82,"id":40096576}]}]}
{"op":"mcm","clk":"11867675329","pt":1723483683840,"mc":[{"id":"1.231703146","rc":[{"batb":[[0,2.02,37.98],[1,1.74,17.32],[2,1.73,85.5]],"ltp":2.06,"tv":218.82,"id":40096576}]}]}
{"op":"mcm","clk":"11867675744","pt":1723483688037,"mc":[{"id":"1.231703146","rc":[{"batb":[[0,2.04,10],[1,2.02,37.98],[2,1.74,17.32]],"ltp":2.06,"tv":218.82,"id":40096576}]}]}
{"op":"mcm","clk":"11867676428","pt":1723483694673,"mc":[{"id":"1.231703146","rc":[{"batb":[[0,2.02,37.98],[1,1.74,17.32],[2,1.73,85.5]],"ltp":2.06,"tv":218.82,"id":40096576}]}]}
{"op":"mcm","clk":"11867676773","pt":1723483697941,"mc":[{"id":"1.231703146","rc":[{"batb":[[0,2.04,10],[1,2.02,37.98],[2,1.74,17.32]],"ltp":2.06,"tv":218.82,"id":40096576}]}]}
{"op":"mcm","clk":"11867677043","pt":1723483700568,"mc":[{"id":"1.231703146","rc":[{"batb":[[0,1.91,2.14],[1,1.86,33.67],[2,1.77,72.12]],"ltp":1.86,"tv":611.39,"id":40096589}]}]}
{"op":"mcm","clk":"11867677461","pt":1723483704762,"mc":[{"id":"1.231703146","rc":[{"batb":[[0,2.02,37.98],[1,1.74,17.32],[2,1.73,85.5]],"ltp":2.06,"tv":218.82,"id":40096576}]}]}
{"op":"mcm","clk":"11867677862","pt":1723483708657,"mc":[{"id":"1.231703146","rc":[{"trd":[[1.91,156.3]],"batb":[[0,1.86,33.92],[1,1.77,72.12],[2,1.76,444]],"ltp":1.91,"tv":615.17,"id":40096589},{"batb":[[0,2.04,10],[1,2.02,37.98],[2,1.74,17.32]],"ltp":2.06,"tv":218.82,"id":40096576}],"tv":833.99}]}
{"op":"mcm","clk":"11867678149","pt":1723483711653,"mc":[{"id":"1.231703146","rc":[{"batb":[[0,1.86,33.67]],"ltp":1.91,"tv":615.17,"id":40096589}]}]}
{"op":"mcm","clk":"11867678504","pt":1723483714993,"mc":[{"id":"1.231703146","rc":[{"batb":[[0,2.02,37.98],[1,1.74,17.32],[2,1.73,85.5]],"ltp":2.06,"tv":218.82,"id":40096576}]}]}
{"op":"mcm","clk":"11867678772","pt":1723483717582,"mc":[{"id":"1.231703146","rc":[{"batb":[[0,2.04,10],[1,2.02,37.98],[2,1.74,17.32]],"ltp":2.06,"tv":218.82,"id":40096576}]}]}
{"op":"mcm","clk":"11867679125","pt":1723483721502,"mc":[{"id":"1.231703146","rc":[{"trd":[[1.86,9.78]],"batb":[[0,1.86,31.73]],"ltp":1.86,"tv":619.05,"id":40096589}],"tv":837.87}]}
{"op":"mcm","clk":"11867679371","pt":1723483723925,"mc":[{"id":"1.231703146","rc":[{"batb":[[0,2.02,37.98],[1,1.74,17.32],[2,1.73,85.5]],"ltp":2.06,"tv":218.82,"id":40096576}]}]}
{"op":"mcm","clk":"11867679467","pt":1723483725012,"mc":[{"id":"1.231703146","rc":[{"batb":[[0,1.87,1.8],[1,1.86,31.73],[2,1.77,72.12]],"ltp":1.86,"tv":619.05,"id":40096589}]}]}
{"op":"mcm","clk":"11867679757","pt":1723483728129,"mc":[{"id":"1.231703146","rc":[{"batb":[[0,2.04,10],[1,2.02,37.98],[2,1.74,17.32]],"ltp":2.06,"tv":218.82,"id":40096576}]}]}
{"op":"mcm","clk":"11867680496","pt":1723483735719,"mc":[{"id":"1.231703146","rc":[{"batb":[[0,2.02,37.98],[1,1.74,17.32],[2,1.73,85.5]],"ltp":2.06,"tv":218.82,"id":40096576}]}]}
{"op":"mcm","clk":"11867680873","pt":1723483739917,"mc":[{"id":"1.231703146","rc":[{"batb":[[0,2.04,10],[1,2.02,37.98],[2,1.74,17.32]],"ltp":2.06,"tv":218.82,"id":40096576}]}]}
{"op":"mcm","clk":"11867680985","pt":1723483741019,"mc":[{"id":"1.231703146","rc":[{"batb":[[0,1.86,31.73],[1,1.77,72.12],[2,1.76,444]],"ltp":1.86,"tv":619.05,"id":40096589}]}]}
{"op":"mcm","clk":"11867681525","pt":1723483746324,"mc":[{"id":"1.231703146","rc":[{"batb":[[0,2.02,37.98],[1,1.74,17.32],[2,1.73,85.5]],"ltp":2.06,"tv":218.82,"id":40096576}]}]}
{"op":"mcm","clk":"11867681972","pt":1723483750523,"mc":[{"id":"1.231703146","rc":[{"batb":[[0,2.04,10],[1,2.02,37.98],[2,1.74,17.32]],"ltp":2.06,"tv":218.82,"id":40096576}]}]}
{"op":"mcm","clk":"11867682787","pt":1723483759260,"mc":[{"id":"1.231703146","rc":[{"batb":[[0,2.02,37.98],[1,1.74,17.32],[2,1.73,85.5]],"ltp":2.06,"tv":218.82,"id":40096576}]}]}
{"op":"mcm","clk":"11867683284","pt":1723483765032,"mc":[{"id":"1.231703146","rc":[{"batb":[[0,2.04,10],[1,2.02,37.98],[2,1.74,17.32]],"ltp":2.06,"tv":218.82,"id":40096576}]}]}
{"op":"mcm","clk":"11867683386","pt":1723483766338,"mc":[{"id":"1.231703146","rc":[{"batb":[[0,1.91,2.14],[1,1.86,31.73],[2,1.77,72.12]],"ltp":1.86,"tv":619.05,"id":40096589}]}]}
{"op":"mcm","clk":"11867683948","pt":1723483773629,"mc":[{"id":"1.231703146","rc":[{"batb":[[0,2.02,37.98],[1,1.74,17.32],[2,1.73,85.5]],"ltp":2.06,"tv":218.82,"id":40096576}]}]}
{"op":"mcm","clk":"11867684116","pt":1723483776335,"mc":[{"id":"1.231703146","rc":[{"batb":[[0,1.86,31.73],[1,1.77,72.12],[2,1.76,444]],"ltp":1.86,"tv":619.05,"id":40096589}]}]}
{"op":"mcm","clk":"11867684254","pt":1723483778148,"mc":[{"id":"1.231703146","rc":[{"batb":[[0,2.04,10],[1,2.02,37.98],[2,1.74,17.32]],"ltp":2.06,"tv":218.82,"id":40096576}]}]}
{"op":"mcm","clk":"11867684952","pt":1723483786878,"mc":[{"id":"1.231703146","rc":[{"batb":[[0,2.02,37.98],[1,1.74,17.32],[2,1.73,85.5]],"ltp":2.06,"tv":218.82,"id":40096576}]}]}
{"op":"mcm","clk":"11867685395","pt":1723483792457,"mc":[{"id":"1.231703146","rc":[{"batb":[[0,2.04,10],[1,2.02,37.98],[2,1.74,17.32]],"ltp":2.06,"tv":218.82,"id":40096576}]}]}
{"op":"mcm","clk":"11867685995","pt":1723483799403,"mc":[{"id":"1.231703146","rc":[{"batb":[[0,2.02,37.98],[1,1.74,17.32],[2,1.73,85.5]],"ltp":2.06,"tv":218.82,"id":40096576}]}]}
{"op":"mcm","clk":"11867686181","pt":1723483801299,"mc":[{"id":"1.231703146","rc":[{"batb":[[0,2.16,2.14],[1,2.02,37.98],[2,1.74,17.32]],"ltp":2.06,"tv":218.82,"id":40096576}]}]}
{"op":"mcm","clk":"11867686443","pt":1723483804010,"mc":[{"id":"1.231703146","rc":[{"batl":[[0,1.93,11.1],[2,1.96,40.57]],"ltp":1.86,"tv":619.05,"id":40096589},{"batb":[[1,2.04,10],[2,2.02,37.98]],"ltp":2.06,"tv":218.82,"id":40096576}]}]}
{"op":"mcm","clk":"11867687204","pt":1723483811796,"mc":[{"id":"1.231703146","rc":[{"batb":[[1,2.02,37.98],[2,1.74,17.32]],"ltp":2.06,"tv":218.82,"id":40096576}]}]}
{"op":"mcm","clk":"11867688060","pt":1723483821994,"mc":[{"id":"1.231703146","rc":[{"batb":[[0,2.02,37.98],[1,1.74,17.32],[2,1.73,85.5]],"ltp":2.06,"tv":218.82,"id":40096576}]}]}
{"op":"mcm","clk":"11867688196","pt":1723483823620,"mc":[{"id":"1.231703146","rc":[{"batl":[[0,1.93,6.72],[2,1.95,4.33]],"ltp":1.86,"tv":619.05,"id":40096589}]}]}
{"op":"mcm","clk":"11867688522","pt":1723483827612,"mc":[{"id":"1.231703146","rc":[{"batb":[[0,2.04,10],[1,2.02,37.98],[2,1.74,17.32]],"ltp":2.06,"tv":218.82,"id":40096576}]}]}
{"op":"mcm","clk":"11867689214","pt":1723483836001,"mc":[{"id":"1.231703146","rc":[{"batb":[[0,2.02,37.98],[1,1.74,17.32],[2,1.73,85.5]],"ltp":2.06,"tv":218.82,"id":40096576}]}]}
{"op":"mcm","clk":"11867689626","pt":1723483841211,"mc":[{"id":"1.231703146","rc":[{"batb":[[0,2.04,10],[1,2.02,37.98],[2,1.74,17.32]],"ltp":2.06,"tv":218.82,"id":40096576}]}]}
{"op":"mcm","clk":"11867690241","pt":1723483848432,"mc":[{"id":"1.231703146","rc":[{"batb":[[0,2.02,37.98],[1,1.74,17.32],[2,1.73,85.5]],"ltp":2.06,"tv":218.82,"id":40096576}]}]}
{"op":"mcm","clk":"11867690565","pt":1723483852342,"mc":[{"id":"1.231703146","rc":[{"batb":[[0,2.04,10],[1,2.02,37.98],[2,1.74,17.32]],"ltp":2.06,"tv":218.82,"id":40096576}]}]}
{"op":"mcm","clk":"11867691202","pt":1723483859475,"mc":[{"id":"1.231703146","rc":[{"batb":[[0,2.02,37.98],[1,1.74,17.32],[2,1.73,85.5]],"ltp":2.06,"tv":218.82,"id":40096576}]}]}
{"op":"mcm","clk":"11867691553","pt":1723483863255,"mc":[{"id":"1.231703146","rc":[{"batb":[[0,2.04,10],[1,2.02,37.98],[2,1.74,17.32]],"ltp":2.06,"tv":218.82,"id":40096576}]}]}
{"op":"mcm","clk":"11867691816","pt":1723483866057,"mc":[{"id":"1.231703146","rc":[{"batl":[[0,1.93,11.1],[2,1.96,40.57]],"ltp":1.86,"tv":619.05,"id":40096589},{"batb":[[0,2.16,2.14],[1,2.04,10],[2,2.02,37.98]],"ltp":2.06,"tv":218.82,"id":40096576}]}]}
{"op":"mcm","clk":"11867692134","pt":1723483869570,"mc":[{"id":"1.231703146","rc":[{"batb":[[1,2.02,37.98],[2,1.74,17.32]],"ltp":2.06,"tv":218.82,"id":40096576}]}]}
{"op":"mcm","clk":"11867692806","pt":1723483876494,"mc":[{"id":"1.231703146","rc":[{"batl":[[0,1.93,31.3]],"ltp":1.86,"tv":619.05,"id":40096589},{"batb":[[0,2.02,37.98],[1,1.74,17.32],[2,1.73,85.5]],"ltp":2.06,"tv":218.82,"id":40096576}]}]}
{"op":"mcm","clk":"11867692931","pt":1723483877665,"mc":[{"id":"1.231703146","rc":[{"batl":[[0,1.93,11.1]],"ltp":1.86,"tv":619.05,"id":40096589}]}]}
{"op":"mcm","clk":"11867693125","pt":1723483879889,"mc":[{"id":"1.231703146","rc":[{"batl":[[0,1.93,6.72],[2,1.95,4.33]],"ltp":1.86,"tv":619.05,"id":40096589},{"batb":[[0,2.04,10],[1,2.02,37.98],[2,1.74,17.32]],"ltp":2.06,"tv":218.82,"id":40096576}]}]}
{"op":"mcm","clk":"11867693604","pt":1723483884776,"mc":[{"id":"1.231703146","rc":[{"batb":[[0,2.02,37.98],[1,1.74,17.32],[2,1.73,85.5]],"ltp":2.06,"tv":218.82,"id":40096576}]}]}
{"op":"mcm","clk":"11867693882","pt":1723483888107,"mc":[{"id":"1.231703146","rc":[{"batb":[[0,2.04,10],[1,2.02,37.98],[2,1.74,17.32]],"ltp":2.06,"tv":218.82,"id":40096576}]}]}
{"op":"mcm","clk":"11867694350","pt":1723483894180,"mc":[{"id":"1.231703146","rc":[{"batb":[[0,2.02,37.98],[1,1.74,17.32],[2,1.73,85.5]],"ltp":2.06,"tv":218.82,"id":40096576}]}]}
{"op":"mcm","clk":"11867694697","pt":1723483898595,"mc":[{"id":"1.231703146","rc":[{"batb":[[0,2.04,10],[1,2.02,37.98],[2,1.74,17.32]],"ltp":2.06,"tv":218.82,"id":40096576}]}]}
{"op":"mcm","clk":"11867695212","pt":1723483904179,"mc":[{"id":"1.231703146","rc":[{"batb":[[0,1.91,2.14],[1,1.86,31.73],[2,1.77,72.12]],"ltp":1.86,"tv":619.05,"id":40096589}]}]}
{"op":"mcm","clk":"11867695299","pt":1723483905312,"mc":[{"id":"1.231703146","rc":[{"batb":[[0,2.02,37.98],[1,1.74,17.32],[2,1.73,85.5]],"ltp":2.06,"tv":218.82,"id":40096576}]}]}
{"op":"mcm","clk":"11867695523","pt":1723483908104,"mc":[{"id":"1.231703146","rc":[{"batb":[[0,2.04,10],[1,2.02,37.98],[2,1.74,17.32]],"ltp":2.06,"tv":218.82,"id":40096576}]}]}
{"op":"mcm","clk":"11867696159","pt":1723483915017,"mc":[{"id":"1.231703146","rc":[{"batb":[[0,2.02,37.98],[1,1.74,17.32],[2,1.73,85.5]],"ltp":2.06,"tv":218.82,"id":40096576}]}]}
{"op":"mcm","clk":"11867696412","pt":1723483917828,"mc":[{"id":"1.231703146","rc":[{"batb":[[0,1.86,31.73],[1,1.77,72.12],[2,1.76,444]],"ltp":1.86,"tv":619.05,"id":40096589}]}]}
{"op":"mcm","clk":"11867696610","pt":1723483919916,"mc":[{"id":"1.231703146","rc":[{"batb":[[0,2.04,10],[1,2.02,37.98],[2,1.74,17.32]],"ltp":2.06,"tv":218.82,"id":40096576}]}]}
{"op":"mcm","clk":"11867697214","pt":1723483926732,"mc":[{"id":"1.231703146","rc":[{"batb":[[0,2.02,37.98],[1,1.74,17.32],[2,1.73,85.5]],"ltp":2.06,"tv":218.82,"id":40096576}]}]}
{"op":"mcm","clk":"11867697473","pt":1723483929345,"mc":[{"id":"1.231703146","rc":[{"batb":[[0,2.04,10],[1,2.02,37.98],[2,1.74,17.32]],"ltp":2.06,"tv":218.82,"id":40096576}]}]}
{"op":"mcm","clk":"11867698563","pt":1723483941183,"mc":[{"id":"1.231703146","rc":[{"batb":[[0,2.02,37.98],[1,1.74,17.32],[2,1.73,85.5]],"ltp":2.06,"tv":218.82,"id":40096576}]}]}
{"op":"mcm","clk":"11867698990","pt":1723483945837,"mc":[{"id":"1.231703146","rc":[{"trd":[[1.93,12.98]],"batl":[[0,1.93,6.06]],"ltp":1.93,"tv":619.71,"id":40096589},{"trd":[[2.06,1.62]],"ltp":2.06,"tv":219.44,"id":40096576}],"tv":839.15}]}
{"op":"mcm","clk":"11867699385","pt":1723483949960,"mc":[{"id":"1.231703146","rc":[{"batb":[[0,2.16,2.14],[1,2.04,10],[2,2.02,37.98]],"ltp":2.06,"tv":219.44,"id":40096576}]}]}
{"op":"mcm","clk":"11867699509","pt":1723483951373,"mc":[{"id":"1.231703146","rc":[{"batl":[[0,1.93,10.44],[2,1.96,40.57]],"ltp":1.93,"tv":619.71,"id":40096589}]}]}
{"op":"mcm","clk":"11867700919","pt":1723483963649,"mc":[{"id":"1.231703146","rc":[{"batb":[[0,2.02,37.98],[1,1.74,17.32],[2,1.73,85.5]],"ltp":2.06,"tv":219.44,"id":40096576}]}]}
{"op":"mcm","clk":"11867701193","pt":1723483965553,"mc":[{"id":"1.231703146","rc":[{"batl":[[0,1.93,6.06],[2,1.95,4.33]],"ltp":1.93,"tv":619.71,"id":40096589}]}]}
{"op":"mcm","clk":"11867701865","pt":1723483973692,"mc":[{"id":"1.231703146","rc":[{"batb":[[0,2.06,10],[1,2.02,37.98],[2,1.74,17.32]],"ltp":2.06,"tv":219.44,"id":40096576}]}]}
{"op":"mcm","clk":"11867702051","pt":1723483975566,"mc":[{"id":"1.231703146","rc":[{"trd":[[1.86,9.81]],"batb":[[0,1.86,31.71]],"ltp":1.86,"tv":619.74,"id":40096589}],"tv":839.19}]}
{"op":"mcm","clk":"11867702899","pt":1723483985487,"mc":[{"id":"1.231703146","rc":[{"batb":[[0,1.91,2.14],[1,1.86,31.71],[2,1.77,72.12]],"ltp":1.86,"tv":619.74,"id":40096589}]}]}
{"op":"mcm","clk":"11867703004","pt":1723483986688,"mc":[{"id":"1.231703146","rc":[{"batb":[[0,2.02,37.98],[1,1.74,17.32],[2,1.73,85.5]],"ltp":2.06,"tv":219.44,"id":40096576}]}]}
{"op":"mcm","clk":"11867703708","pt":1723483994119,"mc":[{"id":"1.231703146","rc":[{"batb":[[0,2.08,10],[1,2.02,37.98],[2,1.74,17.32]],"ltp":2.06,"tv":219.44,"id":40096576}]}]}
{"op":"mcm","clk":"11867703927","pt":1723483996515,"mc":[{"id":"1.231703146","rc":[{"batl":[[0,1.93,10.44],[2,1.96,40.57]],"ltp":1.86,"tv":619.74,"id":40096589}]}]}
{"op":"mcm","clk":"11867703995","pt":1723483997198,"mc":[{"id":"1.231703146","rc":[{"batb":[[0,1.86,31.71],[1,1.77,72.12],[2,1.76,444]],"ltp":1.86,"tv":619.74,"id":40096589}]}]}
{"op":"mcm","clk":"11867704136","pt":1723483998816,"mc":[{"id":"1.231703146","rc":[{"batl":[[0,1.91,1.89],[1,1.93,10.44],[2,1.94,9.02]],"ltp":1.86,"tv":619.74,"id":40096589}]}]}
{"op":"mcm","clk":"11867704445","pt":1723484002332,"mc":[{"id":"1.231703146","rc":[{"batl":[[0,1.93,10.44],[1,1.94,9.02],[2,1.96,40.57]],"ltp":1.86,"tv":619.74,"id":40096589}]}]}
{"op":"mcm","clk":"11867704593","pt":1723484004104,"mc":[{"id":"1.231703146","rc":[{"batb":[[0,2.02,37.98],[1,1.74,17.32],[2,1.73,85.5]],"ltp":2.06,"tv":219.44,"id":40096576}]}]}
{"op":"mcm","clk":"11867704725","pt":1723484005830,"mc":[{"id":"1.231703146","rc":[{"batl":[[0,1.93,6.06]],"ltp":1.86,"tv":619.74,"id":40096589}]}]}
{"op":"mcm","clk":"11867704881","pt":1723484007599,"mc":[{"id":"1.231703146","rc":[{"batb":[[0,2.1,10],[1,2.02,37.98],[2,1.74,17.32]],"ltp":2.06,"tv":219.44,"id":40096576}]}]}
{"op":"mcm","clk":"11867705651","pt":1723484016835,"mc":[{"id":"1.231703146","rc":[{"batb":[[0,2.02,37.98],[1,1.74,17.32],[2,1.73,85.5]],"ltp":2.06,"tv":219.44,"id":40096576}]}]}
{"op":"mcm","clk":"11867705714","pt":1723484017719,"mc":[{"id":"1.231703146","rc":[{"batl":[[2,1.95,4.33]],"ltp":1.86,"tv":619.74,"id":40096589}]}]}
{"op":"mcm","clk":"11867706082","pt":1723484022253,"mc":[{"id":"1.231703146","rc":[{"batb":[[0,2.04,10],[1,2.02,37.98],[2,1.74,17.32]],"ltp":2.06,"tv":219.44,"id":40096576}]}]}
{"op":"mcm","clk":"11867706771","pt":1723484030253,"mc":[{"id":"1.231703146","rc":[{"batb":[[0,2.02,37.98],[1,1.74,17.32],[2,1.73,85.5]],"ltp":2.06,"tv":219.44,"id":40096576}]}]}
{"op":"mcm","clk":"11867707269","pt":1723484035964,"mc":[{"id":"1.231703146","rc":[{"batb":[[0,2.04,10],[1,2.02,37.98],[2,1.74,17.32]],"ltp":2.06,"tv":219.44,"id":40096576}]}]}
{"op":"mcm","clk":"11867707976","pt":1723484043975,"mc":[{"id":"1.231703146","rc":[{"batb":[[0,2.16,2.14],[1,2.04,10],[2,2.02,37.98]],"ltp":2.06,"tv":219.44,"id":40096576}]}]}
{"op":"mcm","clk":"11867708043","pt":1723484044662,"mc":[{"id":"1.231703146","rc":[{"batb":[[1,2.02,37.98],[2,1.74,17.32]],"ltp":2.06,"tv":219.44,"id":40096576}]}]}
{"op":"mcm","clk":"11867708194","pt":1723484046244,"mc":[{"id":"1.231703146","rc":[{"batl":[[0,1.93,10.44],[2,1.96,40.57]],"ltp":1.86,"tv":619.74,"id":40096589}]}]}
{"op":"mcm","clk":"11867709053","pt":1723484056505,"mc":[{"id":"1.231703146","rc":[{"trd":[[1.87,95.63]],"ltp":1.87,"tv":621.99,"id":40096589},{"trd":[[2.16,1.95]],"batb":[[0,2.02,38.17],[1,1.74,17.32],[2,1.73,85.5]],"ltp":2.16,"tv":221.39,"id":40096576}],"tv":843.39}]}
{"op":"mcm","clk":"11867709108","pt":1723484057097,"mc":[{"id":"1.231703146","rc":[{"batb":[[0,2.02,37.98]],"ltp":2.16,"tv":221.39,"id":40096576}]}]}
{"op":"mcm","clk":"11867709242","pt":1723484058195,"mc":[{"id":"1.231703146","rc":[{"batl":[[0,1.93,6.06]],"ltp":1.87,"tv":621.99,"id":40096589}]}]}
{"op":"mcm","clk":"11867709546","pt":1723484061510,"mc":[{"id":"1.231703146","rc":[{"batb":[[0,2.04,10],[1,2.02,37.98],[2,1.74,17.32]],"ltp":2.16,"tv":221.39,"id":40096576}]}]}
{"op":"mcm","clk":"11867709678","pt":1723484062981,"mc":[{"id":"1.231703146","rc":[{"batl":[[2,1.95,4.33]],"ltp":1.87,"tv":621.99,"id":40096589}]}]}
{"op":"mcm","clk":"11867710439","pt":1723484070631,"mc":[{"id":"1.231703146","rc":[{"trd":[[1.93,17.34]],"batl":[[0,1.93,3.88]],"ltp":1.93,"tv":626.35,"id":40096589},{"batb":[[0,2.02,37.98],[1,1.74,17.32],[2,1.73,85.5]],"ltp":2.16,"tv":221.39,"id":40096576}],"tv":847.75}]}
{"op":"mcm","clk":"11867710994","pt":1723484076881,"mc":[{"id":"1.231703146","rc":[{"batb":[[0,2.06,10],[1,2.02,37.98],[2,1.74,17.32]],"ltp":2.16,"tv":221.39,"id":40096576}]}]}
{"op":"mcm","clk":"11867711888","pt":1723484085904,"mc":[{"id":"1.231703146","rc":[{"batb":[[0,2.02,37.98],[1,1.74,17.32],[2,1.73,85.5]],"ltp":2.16,"tv":221.39,"id":40096576}]}]}
{"op":"mcm","clk":"11867712336","pt":1723484091002,"mc":[{"id":"1.231703146","rc":[{"batb":[[0,2.04,10],[1,2.02,37.98],[2,1.74,17.32]],"ltp":2.16,"tv":221.39,"id":40096576}]}]}
{"op":"mcm","clk":"11867712673","pt":1723484094931,"mc":[{"id":"1.231703146","rc":[{"batb":[[0,1.91,2.14],[1,1.86,31.71],[2,1.77,72.12]],"ltp":1.93,"tv":626.35,"id":40096589}]}]}
{"op":"mcm","clk":"11867713121","pt":1723484100243,"mc":[{"id":"1.231703146","rc":[{"batb":[[0,2.02,37.98],[1,1.74,17.32],[2,1.73,85.5]],"ltp":2.16,"tv":221.39,"id":40096576}]}]}
{"op":"mcm","clk":"11867713407","pt":1723484103331,"mc":[{"id":"1.231703146","rc":[{"trd":[[1.91,160.08]],"batb":[[0,1.86,31.96],[1,1.77,72.12],[2,1.76,444]],"ltp":1.91,"tv":630.13,"id":40096589}],"tv":851.53}]}
{"op":"mcm","clk":"11867713699","pt":1723484106930,"mc":[{"id":"1.231703146","rc":[{"batb":[[0,1.86,31.71]],"ltp":1.91,"tv":630.13,"id":40096589}]}]}
{"op":"mcm","clk":"11867713734","pt":1723484107346,"mc":[{"id":"1.231703146","rc":[{"batb":[[0,2.04,10],[1,2.02,37.98],[2,1.74,17.32]],"ltp":2.16,"tv":221.39,"id":40096576}]}]}
{"op":"mcm","clk":"11867714393","pt":1723484115735,"mc":[{"id":"1.231703146","rc":[{"batb":[[0,2.02,37.98],[1,1.74,17.32],[2,1.73,85.5]],"ltp":2.16,"tv":221.39,"id":40096576}]}]}
{"op":"mcm","clk":"11867714475","pt":1723484116732,"mc":[{"id":"1.231703146","rc":[{"trd":[[1.86,13.69]],"batb":[[0,1.86,29.77]],"ltp":1.86,"tv":634.01,"id":40096589}],"tv":855.4}]}
{"op":"mcm","clk":"11867714882","pt":1723484121520,"mc":[{"id":"1.231703146","rc":[{"batb":[[0,2.04,10],[1,2.02,37.98],[2,1.74,17.32]],"ltp":2.16,"tv":221.39,"id":40096576}]}]}
{"op":"mcm","clk":"11867715727","pt":1723484131651,"mc":[{"id":"1.231703146","rc":[{"batb":[[0,2.02,37.98],[1,1.74,17.32],[2,1.73,85.5]],"ltp":2.16,"tv":221.39,"id":40096576}]}]}
{"op":"mcm","clk":"11867716299","pt":1723484138056,"mc":[{"id":"1.231703146","rc":[{"batb":[[0,2.04,10],[1,2.02,37.98],[2,1.74,17.32]],"ltp":2.16,"tv":221.39,"id":40096576}]}]}
{"op":"mcm","clk":"11867717123","pt":1723484147554,"mc":[{"id":"1.231703146","rc":[{"batb":[[0,2.02,37.98],[1,1.74,17.32],[2,1.73,85.5]],"ltp":2.16,"tv":221.39,"id":40096576}]}]}
{"op":"mcm","clk":"11867717567","pt":1723484152693,"mc":[{"id":"1.231703146","rc":[{"batb":[[0,2.04,10],[1,2.02,37.98],[2,1.74,17.32]],"ltp":2.16,"tv":221.39,"id":40096576}]}]}
{"op":"mcm","clk":"11867718158","pt":1723484158955,"mc":[{"id":"1.231703146","rc":[{"batb":[[0,1.86,29.11]],"ltp":1.86,"tv":634.01,"id":40096589}]}]}
{"op":"mcm","clk":"11867718467","pt":1723484162169,"mc":[{"id":"1.231703146","rc":[{"batb":[[0,2.02,37.98],[1,1.74,17.32],[2,1.73,85.5]],"ltp":2.16,"tv":221.39,"id":40096576}]}]}
{"op":"mcm","clk":"11867718874","pt":1723484166493,"mc":[{"id":"1.231703146","rc":[{"batb":[[0,2.06,10],[1,2.02,37.98],[2,1.74,17.32]],"ltp":2.16,"tv":221.39,"id":40096576}]}]}
{"op":"mcm","clk":"11867719745","pt":1723484175101,"mc":[{"id":"1.231703146","rc":[{"batb":[[0,2.02,37.98],[1,1.74,17.32],[2,1.73,85.5]],"ltp":2.16,"tv":221.39,"id":40096576}]}]}
{"op":"mcm","clk":"11867720269","pt":1723484180704,"mc":[{"id":"1.231703146","rc":[{"batb":[[0,2.04,10],[1,2.02,37.98],[2,1.74,17.32]],"ltp":2.16,"tv":221.39,"id":40096576}]}]}
{"op":"mcm","clk":"11867720679","pt":1723484185428,"mc":[{"id":"1.231703146","rc":[{"batb":[[0,1.91,2.14],[1,1.86,29.11],[2,1.77,72.12]],"ltp":1.86,"tv":634.01,"id":40096589}]}]}
{"op":"mcm","clk":"11867721081","pt":1723484189618,"mc":[{"id":"1.231703146","rc":[{"batb":[[0,2.02,37.98],[1,1.74,17.32],[2,1.73,85.5]],"ltp":2.16,"tv":221.39,"id":40096576}]}]}
{"op":"mcm","clk":"11867721241","pt":1723484191218,"mc":[{"id":"1.231703146","rc":[{"trd":[[1.91,163.86]],"batb":[[0,1.86,29.36],[1,1.77,72.12],[2,1.76,444]],"ltp":1.91,"tv":637.79,"id":40096589}],"tv":859.18}]}
{"op":"mcm","clk":"11867721708","pt":1723484195929,"mc":[{"id":"1.231703146","rc":[{"batb":[[0,1.86,29.11]],"ltp":1.91,"tv":637.79,"id":40096589},{"batb":[[0,2.04,10],[1,2.02,37.98],[2,1.74,17.32]],"ltp":2.16,"tv":221.39,"id":40096576}]}]}
{"op":"mcm","clk":"11867722143","pt":1723484201129,"mc":[{"id":"1.231703146","rc":[{"trd":[[1.86,17.57]],"batb":[[0,1.86,27.17]],"ltp":1.86,"tv":641.67,"id":40096589}],"tv":863.06}]}
{"op":"mcm","clk":"11867722392","pt":1723484204021,"mc":[{"id":"1.231703146","rc":[{"batb":[[0,2.02,37.98],[1,1.74,17.32],[2,1.73,85.5]],"ltp":2.16,"tv":221.39,"id":40096576}]}]}
{"op":"mcm","clk":"11867722663","pt":1723484206662,"mc":[{"id":"1.231703146","rc":[{"batb":[[0,2.06,10],[1,2.02,37.98],[2,1.74,17.32]],"ltp":2.16,"tv":221.39,"id":40096576}]}]}
{"op":"mcm","clk":"11867723344","pt":1723484213826,"mc":[{"id":"1.231703146","rc":[{"batb":[[0,2.02,37.98],[1,1.74,17.32],[2,1.73,85.5]],"ltp":2.16,"tv":221.39,"id":40096576}]}]}
{"op":"mcm","clk":"11867723855","pt":1723484219284,"mc":[{"id":"1.231703146","rc":[{"batb":[[0,2.04,10],[1,2.02,37.98],[2,1.74,17.32]],"ltp":2.16,"tv":221.39,"id":40096576}]}]}
{"op":"mcm","clk":"11867724767","pt":1723484229302,"mc":[{"id":"1.231703146","rc":[{"batb":[[0,2.02,37.98],[1,1.74,17.32],[2,1.73,85.5]],"ltp":2.16,"tv":221.39,"id":40096576}]}]}
{"op":"mcm","clk":"11867725319","pt":1723484236270,"mc":[{"id":"1.231703146","rc":[{"batb":[[0,2.04,10],[1,2.02,37.98],[2,1.74,17.32]],"ltp":2.16,"tv":221.39,"id":40096576}]}]}
{"op":"mcm","clk":"11867726003","pt":1723484245194,"mc":[{"id":"1.231703146","rc":[{"batb":[[0,2.02,37.98],[1,1.74,17.32],[2,1.73,85.5]],"ltp":2.16,"tv":221.39,"id":40096576}]}]}
{"op":"mcm","clk":"11867726446","pt":1723484250998,"mc":[{"id":"1.231703146","rc":[{"batb":[[0,2.04,10],[1,2.02,37.98],[2,1.74,17.32]],"ltp":2.16,"tv":221.39,"id":40096576}]}]}
{"op":"mcm","clk":"11867727139","pt":1723484261020,"mc":[{"id":"1.231703146","rc":[{"batb":[[0,2.02,37.98],[1,1.74,17.32],[2,1.73,85.5]],"ltp":2.16,"tv":221.39,"id":40096576}]}]}
{"op":"mcm","clk":"11867727702","pt":1723484267110,"mc":[{"id":"1.231703146","rc":[{"batb":[[0,2.04,10],[1,2.02,37.98],[2,1.74,17.32]],"ltp":2.16,"tv":221.39,"id":40096576}]}]}
{"op":"mcm","clk":"11867728327","pt":1723484274630,"mc":[{"id":"1.231703146","rc":[{"batb":[[0,2.02,37.98],[1,1.74,17.32],[2,1.73,85.5]],"ltp":2.16,"tv":221.39,"id":40096576}]}]}
{"op":"mcm","clk":"11867728822","pt":1723484280739,"mc":[{"id":"1.231703146","rc":[{"batb":[[0,2.04,10],[1,2.02,37.98],[2,1.74,17.32]],"ltp":2.16,"tv":221.39,"id":40096576}]}]}
{"op":"mcm","clk":"11867729572","pt":1723484290049,"mc":[{"id":"1.231703146","rc":[{"batb":[[0,2.02,37.98],[1,1.74,17.32],[2,1.73,85.5]],"ltp":2.16,"tv":221.39,"id":40096576}]}]}
{"op":"mcm","clk":"11867730082","pt":1723484296544,"mc":[{"id":"1.231703146","rc":[{"batb":[[0,2.04,10],[1,2.02,37.98],[2,1.74,17.32]],"ltp":2.16,"tv":221.39,"id":40096576}]}]}
{"op":"mcm","clk":"11867731136","pt":1723484310569,"mc":[{"id":"1.231703146","rc":[{"batb":[[0,2.02,37.98],[1,1.74,17.32],[2,1.73,85.5]],"ltp":2.16,"tv":221.39,"id":40096576}]}]}
{"op":"mcm","clk":"11867731836","pt":1723484319380,"mc":[{"id":"1.231703146","rc":[{"batb":[[0,2.04,10],[1,2.02,37.98],[2,1.74,17.32]],"ltp":2.16,"tv":221.39,"id":40096576}]}]}
{"op":"mcm","clk":"11867732753","pt":1723484329668,"mc":[{"id":"1.231703146","rc":[{"batb":[[0,2.02,37.98],[1,1.74,17.32],[2,1.73,85.5]],"ltp":2.16,"tv":221.39,"id":40096576}]}]}
{"op":"mcm","clk":"11867733308","pt":1723484336163,"mc":[{"id":"1.231703146","rc":[{"batb":[[0,2.04,10],[1,2.02,37.98],[2,1.74,17.32]],"ltp":2.16,"tv":221.39,"id":40096576}]}]}
{"op":"mcm","clk":"11867734243","pt":1723484347681,"mc":[{"id":"1.231703146","rc":[{"batb":[[0,2.02,37.98],[1,1.74,17.32],[2,1.73,85.5]],"ltp":2.16,"tv":221.39,"id":40096576}]}]}
{"op":"mcm","clk":"11867734978","pt":1723484356582,"mc":[{"id":"1.231703146","rc":[{"batb":[[0,2.04,10],[1,2.02,37.98],[2,1.74,17.32]],"ltp":2.16,"tv":221.39,"id":40096576}]}]}
{"op":"mcm","clk":"11867736089","pt":1723484369118,"mc":[{"id":"1.231703146","rc":[{"batb":[[0,2.02,37.98],[1,1.74,17.32],[2,1.73,85.5]],"ltp":2.16,"tv":221.39,"id":40096576}]}]}
{"op":"mcm","clk":"11867736850","pt":1723484378116,"mc":[{"id":"1.231703146","rc":[{"batb":[[0,2.04,10],[1,2.02,37.98],[2,1.74,17.32]],"ltp":2.16,"tv":221.39,"id":40096576}]}]}
{"op":"mcm","clk":"11867737914","pt":1723484390633,"mc":[{"id":"1.231703146","rc":[{"batb":[[0,2.02,37.98],[1,1.74,17.32],[2,1.73,85.5]],"ltp":2.16,"tv":221.39,"id":40096576}]}]}
{"op":"mcm","clk":"11867762729","pt":1723484693404,"mc":[{"id":"1.231703146","rc":[{"batb":[[0,1.91,2.14],[1,1.86,27.17],[2,1.77,72.12]],"ltp":1.86,"tv":641.67,"id":40096589}]}]}
{"op":"mcm","clk":"11867763668","pt":1723484703412,"mc":[{"id":"1.231703146","rc":[{"batb":[[0,1.86,27.17],[1,1.77,72.12],[2,1.76,444]],"ltp":1.86,"tv":641.67,"id":40096589}]}]}
{"op":"mcm","clk":"11867767745","pt":1723484749973,"mc":[{"id":"1.231703146","rc":[{"batb":[[0,1.91,2.14],[1,1.86,27.17],[2,1.77,72.12]],"ltp":1.86,"tv":641.67,"id":40096589}]}]}
{"op":"mcm","clk":"11867768284","pt":1723484756763,"mc":[{"id":"1.231703146","rc":[{"batb":[[0,1.86,27.17],[1,1.77,72.12],[2,1.76,444]],"ltp":1.86,"tv":641.67,"id":40096589}]}]}
{"op":"mcm","clk":"11867772915","pt":1723484814112,"mc":[{"id":"1.231703146","rc":[{"batb":[[0,2.02,38.98]],"ltp":2.16,"tv":221.39,"id":40096576}]}]}
{"op":"mcm","clk":"11867773507","pt":1723484821934,"mc":[{"id":"1.231703146","rc":[{"batb":[[0,2.02,37.98]],"ltp":2.16,"tv":221.39,"id":40096576}]}]}
{"op":"mcm","clk":"11867783245","pt":1723484953886,"mc":[{"id":"1.231703146","rc":[{"batb":[[0,2.1,2.14],[1,2.02,37.98],[2,1.74,17.32]],"ltp":2.16,"tv":221.39,"id":40096576}]}]}
{"op":"mcm","clk":"11867783552","pt":1723484958210,"mc":[{"id":"1.231703146","rc":[{"batb":[[0,2.02,37.98],[1,1.74,17.32],[2,1.73,85.5]],"ltp":2.16,"tv":221.39,"id":40096576}]}]}
{"op":"mcm","clk":"11867791191","pt":1723485075470,"mc":[{"id":"1.231703146","rc":[{"batb":[[0,1.87,1.03],[1,1.86,27.17],[2,1.77,72.12]],"ltp":1.86,"tv":641.67,"id":40096589}]}]}
{"op":"mcm","clk":"11867793679","pt":1723485115377,"mc":[{"id":"1.231703146","rc":[{"trd":[[1.87,95.67]],"batb":[[0,1.87,1.01]],"ltp":1.87,"tv":641.71,"id":40096589}],"tv":863.1}]}
{"op":"mcm","clk":"11867809551","pt":1723485387103,"mc":[{"id":"1.231703146","rc":[{"batb":[[2,1.82,5.32]],"ltp":1.87,"tv":641.71,"id":40096589}]}]}
{"op":"mcm","clk":"11867825273","pt":1723485635972,"mc":[{"id":"1.231703146","rc":[{"trd":[[1.58,169.22],[1.79,26.48],[1.84,9.18],[1.86,17.55],[1.91,163.85],[1.93,17.33]],"batl":[[2,1.95,4.33]],"ltp":1.87,"tv":641.58,"id":40096589},{"trd":[[1.58,169.22],[2.04,7.68],[2.16,1.94]],"batb":[[0,2.04,10],[1,2.02,37.98],[2,1.74,17.32]],"ltp":2.16,"tv":221.29,"id":40096576}],"tv":862.87}]}
{"op":"mcm","clk":"11867825516","pt":1723485639252,"mc":[{"id":"1.231703146","rc":[{"batb":[[0,2.02,37.98],[1,1.74,17.32],[2,1.73,85.5]],"ltp":2.16,"tv":221.29,"id":40096576}]}]}
{"op":"mcm","clk":"11867837838","pt":1723485813826,"mc":[{"id":"1.231703146","rc":[{"trd":[[1.87,97.69]],"batb":[[0,1.86,27.17],[1,1.82,5.32],[2,1.77,72.12]],"batl":[[0,1.87,2.17],[1,1.93,3.88],[2,1.94,9.02]],"ltp":1.87,"tv":643.6,"id":40096589}],"tv":864.89}]}
{"op":"mcm","clk":"11867837956","pt":1723485815516,"mc":[{"id":"1.231703146","rc":[{"batb":[[0,2.04,10],[1,2.02,37.98],[2,1.74,17.32]],"ltp":2.16,"tv":221.29,"id":40096576}]}]}
{"op":"mcm","clk":"11867838330","pt":1723485819920,"mc":[{"id":"1.231703146","rc":[{"batb":[[0,2.02,37.98],[1,1.74,17.32],[2,1.73,85.5]],"ltp":2.16,"tv":221.29,"id":40096576}]}]}
{"op":"mcm","clk":"11867848433","pt":1723485967383,"mc":[{"id":"1.231703146","rc":[{"trd":[[1.86,17.61]],"batb":[[0,1.86,27.14]],"ltp":1.86,"tv":643.66,"id":40096589}],"tv":864.95}]}
{"op":"mcm","clk":"11867848675","pt":1723485969899,"mc":[{"id":"1.231703146","rc":[{"batb":[[0,2.04,10],[1,2.02,37.98],[2,1.74,17.32]],"ltp":2.16,"tv":221.29,"id":40096576}]}]}
{"op":"mcm","clk":"11867849099","pt":1723485974591,"mc":[{"id":"1.231703146","rc":[{"batb":[[0,2.02,37.98],[1,1.74,17.32],[2,1.73,85.5]],"ltp":2.16,"tv":221.29,"id":40096576}]}]}
{"op":"mcm","clk":"11867851384","pt":1723486003020,"mc":[{"id":"1.231703146","rc":[{"trd":[[1.87,101.65]],"batl":[[0,1.93,4.07],[1,1.94,9.02],[2,1.95,4.33]],"ltp":1.87,"tv":647.62,"id":40096589}],"tv":868.91}]}
{"op":"mcm","clk":"11867851401","pt":1723486003232,"mc":[{"id":"1.231703146","rc":[{"batb":[[0,2.04,10],[1,2.02,37.98],[2,1.74,17.32]],"ltp":2.16,"tv":221.29,"id":40096576}]}]}
{"op":"mcm","clk":"11867851688","pt":1723486006532,"mc":[{"id":"1.231703146","rc":[{"batb":[[0,2.02,37.98],[1,1.74,17.32],[2,1.73,85.5]],"ltp":2.16,"tv":221.29,"id":40096576}]}]}
{"op":"mcm","clk":"11867852165","pt":1723486013046,"mc":[{"id":"1.231703146","rc":[{"batb":[[1,1.77,72.12],[2,1.76,444]],"ltp":1.87,"tv":647.62,"id":40096589}]}]}
{"op":"mcm","clk":"11867852253","pt":1723486014339,"mc":[{"id":"1.231703146","rc":[{"batb":[[0,2.04,10],[1,2.02,37.98],[2,1.74,17.32]],"ltp":2.16,"tv":221.29,"id":40096576}]}]}
{"op":"mcm","clk":"11867852565","pt":1723486018168,"mc":[{"id":"1.231703146","rc":[{"batb":[[0,2.02,37.98],[1,1.74,17.32],[2,1.73,85.5]],"ltp":2.16,"tv":221.29,"id":40096576}]}]}
{"op":"mcm","clk":"11867864941","pt":1723486152441,"mc":[{"id":"1.231703146","rc":[{"batb":[[0,2.04,10],[1,2.02,37.98],[2,1.74,17.32]],"ltp":2.16,"tv":221.29,"id":40096576}]}]}
{"op":"mcm","clk":"11867866067","pt":1723486163931,"mc":[{"id":"1.231703146","rc":[{"batb":[[0,2.02,37.98],[1,1.74,17.32],[2,1.73,85.5]],"ltp":2.16,"tv":221.29,"id":40096576}]}]}
{"op":"mcm","clk":"11867866709","pt":1723486170830,"mc":[{"id":"1.231703146","rc":[{"batb":[[0,2.04,10],[1,2.02,37.98],[2,1.74,17.32]],"ltp":2.16,"tv":221.29,"id":40096576}]}]}
{"op":"mcm","clk":"11867867570","pt":1723486179173,"mc":[{"id":"1.231703146","rc":[{"batb":[[0,2.02,37.98],[1,1.74,17.32],[2,1.73,85.5]],"ltp":2.16,"tv":221.29,"id":40096576}]}]}
{"op":"mcm","clk":"11867868161","pt":1723486185362,"mc":[{"id":"1.231703146","rc":[{"batb":[[0,2.04,10],[1,2.02,37.98],[2,1.74,17.32]],"ltp":2.16,"tv":221.29,"id":40096576}]}]}
{"op":"mcm","clk":"11867869219","pt":1723486196362,"mc":[{"id":"1.231703146","rc":[{"batb":[[0,2.02,37.98],[1,1.74,17.32],[2,1.73,85.5]],"ltp":2.16,"tv":221.29,"id":40096576}]}]}
{"op":"mcm","clk":"11867869949","pt":1723486204593,"mc":[{"id":"1.231703146","rc":[{"batb":[[0,2.04,10],[1,2.02,37.98],[2,1.74,17.32]],"ltp":2.16,"tv":221.29,"id":40096576}]}]}
{"op":"mcm","clk":"11867870763","pt":1723486213823,"mc":[{"id":"1.231703146","rc":[{"batb":[[0,2.02,37.98],[1,1.74,17.32],[2,1.73,85.5]],"ltp":2.16,"tv":221.29,"id":40096576}]}]}
{"op":"mcm","clk":"11867871344","pt":1723486219511,"mc":[{"id":"1.231703146","rc":[{"batb":[[0,2.04,10],[1,2.02,37.98],[2,1.74,17.32]],"ltp":2.16,"tv":221.29,"id":40096576}]}]}
{"op":"mcm","clk":"11867872408","pt":1723486230523,"mc":[{"id":"1.231703146","rc":[{"batb":[[0,2.02,37.98],[1,1.74,17.32],[2,1.73,85.5]],"ltp":2.16,"tv":221.29,"id":40096576}]}]}
{"op":"mcm","clk":"11867872978","pt":1723486236525,"mc":[{"id":"1.231703146","rc":[{"batb":[[0,2.06,10],[1,2.02,37.98],[2,1.74,17.32]],"ltp":2.16,"tv":221.29,"id":40096576}]}]}
{"op":"mcm","clk":"11867873857","pt":1723486245148,"mc":[{"id":"1.231703146","rc":[{"batb":[[0,2.02,37.98],[1,1.74,17.32],[2,1.73,85.5]],"ltp":2.16,"tv":221.29,"id":40096576}]}]}
{"op":"mcm","clk":"11867874076","pt":1723486247551,"mc":[{"id":"1.231703146","rc":[{"batb":[[0,2.08,10],[1,2.02,37.98],[2,1.74,17.32]],"ltp":2.16,"tv":221.29,"id":40096576}]}]}
{"op":"mcm","clk":"11867874263","pt":1723486249551,"mc":[{"id":"1.231703146","rc":[{"batl":[[0,1.93,8.45],[2,1.96,40.57]],"ltp":1.87,"tv":647.62,"id":40096589}]}]}
{"op":"mcm","clk":"11867875121","pt":1723486258388,"mc":[{"id":"1.231703146","rc":[{"batb":[[0,2.02,37.98],[1,1.74,17.32],[2,1.73,85.5]],"ltp":2.16,"tv":221.29,"id":40096576}]}]}
{"op":"mcm","clk":"11867875837","pt":1723486265403,"mc":[{"id":"1.231703146","rc":[{"batb":[[0,2.04,10],[1,2.02,37.98],[2,1.74,17.32]],"ltp":2.16,"tv":221.29,"id":40096576}]}]}
{"op":"mcm","clk":"11867877023","pt":1723486277378,"mc":[{"id":"1.231703146","rc":[{"batb":[[0,2.02,37.98],[1,1.74,17.32],[2,1.73,85.5]],"ltp":2.16,"tv":221.29,"id":40096576}]}]}
{"op":"mcm","clk":"11867877854","pt":1723486286217,"mc":[{"id":"1.231703146","rc":[{"batb":[[0,2.06,10],[1,2.02,37.98],[2,1.74,17.32]],"ltp":2.16,"tv":221.29,"id":40096576}]}]}
{"op":"mcm","clk":"11867879025","pt":1723486300334,"mc":[{"id":"1.231703146","rc":[{"batb":[[0,2.02,37.98],[1,1.74,17.32],[2,1.73,85.5]],"ltp":2.16,"tv":221.29,"id":40096576}]}]}
{"op":"mcm","clk":"11867879753","pt":1723486310043,"mc":[{"id":"1.231703146","rc":[{"batb":[[0,2.04,10],[1,2.02,37.98],[2,1.74,17.32]],"ltp":2.16,"tv":221.29,"id":40096576}]}]}
{"op":"mcm","clk":"11867880677","pt":1723486320552,"mc":[{"id":"1.231703146","rc":[{"batb":[[0,2.02,37.98],[1,1.74,17.32],[2,1.73,85.5]],"ltp":2.16,"tv":221.29,"id":40096576}]}]}
{"op":"mcm","clk":"11867881581","pt":1723486330791,"mc":[{"id":"1.231703146","rc":[{"batb":[[0,2.04,10],[1,2.02,37.98],[2,1.74,17.32]],"ltp":2.16,"tv":221.29,"id":40096576}]}]}
{"op":"mcm","clk":"11867882881","pt":1723486344518,"mc":[{"id":"1.231703146","rc":[{"batb":[[0,2.02,37.98],[1,1.74,17.32],[2,1.73,85.5]],"ltp":2.16,"tv":221.29,"id":40096576}]}]}
{"op":"mcm","clk":"11867883894","pt":1723486355301,"mc":[{"id":"1.231703146","rc":[{"batb":[[0,2.04,10],[1,2.02,37.98],[2,1.74,17.32]],"ltp":2.16,"tv":221.29,"id":40096576}]}]}
{"op":"mcm","clk":"11867885217","pt":1723486370021,"mc":[{"id":"1.231703146","rc":[{"batb":[[0,2.02,37.98],[1,1.74,17.32],[2,1.73,85.5]],"ltp":2.16,"tv":221.29,"id":40096576}]}]}
{"op":"mcm","clk":"11867886169","pt":1723486379849,"mc":[{"id":"1.231703146","rc":[{"batb":[[0,2.04,10],[1,2.02,37.98],[2,1.74,17.32]],"ltp":2.16,"tv":221.29,"id":40096576}]}]}
{"op":"mcm","clk":"11867887379","pt":1723486392350,"mc":[{"id":"1.231703146","rc":[{"batb":[[0,2.02,37.98],[1,1.74,17.32],[2,1.73,85.5]],"ltp":2.16,"tv":221.29,"id":40096576}]}]}
{"op":"mcm","clk":"11867888184","pt":1723486400652,"mc":[{"id":"1.231703146","rc":[{"batb":[[0,2.04,10],[1,2.02,37.98],[2,1.74,17.32]],"ltp":2.16,"tv":221.29,"id":40096576}]}]}
{"op":"mcm","clk":"11867889136","pt":1723486410485,"mc":[{"id":"1.231703146","rc":[{"batb":[[0,2.02,37.98],[1,1.74,17.32],[2,1.73,85.5]],"ltp":2.16,"tv":221.29,"id":40096576}]}]}
{"op":"mcm","clk":"11867889513","pt":1723486414880,"mc":[{"id":"1.231703146","rc":[{"batb":[[0,2.04,10],[1,2.02,37.98],[2,1.74,17.32]],"ltp":2.16,"tv":221.29,"id":40096576}]}]}
{"op":"mcm","clk":"11867890349","pt":1723486424040,"mc":[{"id":"1.231703146","rc":[{"batb":[[0,2.02,37.98],[1,1.74,17.32],[2,1.73,85.5]],"ltp":2.16,"tv":221.29,"id":40096576}]}]}
{"op":"mcm","clk":"11867890925","pt":1723486430038,"mc":[{"id":"1.231703146","rc":[{"batb":[[0,2.04,10],[1,2.02,37.98],[2,1.74,17.32]],"ltp":2.16,"tv":221.29,"id":40096576}]}]}
{"op":"mcm","clk":"11867891629","pt":1723486437496,"mc":[{"id":"1.231703146","rc":[{"batb":[[0,2.02,37.98],[1,1.74,17.32],[2,1.73,85.5]],"ltp":2.16,"tv":221.29,"id":40096576}]}]}
{"op":"mcm","clk":"11867892190","pt":1723486443078,"mc":[{"id":"1.231703146","rc":[{"batb":[[0,2.04,10],[1,2.02,37.98],[2,1.74,17.32]],"ltp":2.16,"tv":221.29,"id":40096576}]}]}
{"op":"mcm","clk":"11867893380","pt":1723486454828,"mc":[{"id":"1.231703146","rc":[{"batb":[[0,2.02,37.98],[1,1.74,17.32],[2,1.73,85.5]],"ltp":2.16,"tv":221.29,"id":40096576}]}]}
{"op":"mcm","clk":"11867894072","pt":1723486461027,"mc":[{"id":"1.231703146","rc":[{"batb":[[0,2.04,10],[1,2.02,37.98],[2,1.74,17.32]],"ltp":2.16,"tv":221.29,"id":40096576}]}]}
{"op":"mcm","clk":"11867895479","pt":1723486474555,"mc":[{"id":"1.231703146","rc":[{"batb":[[0,2.02,37.98],[1,1.74,17.32],[2,1.73,85.5]],"ltp":2.16,"tv":221.29,"id":40096576}]}]}
{"op":"mcm","clk":"11867896431","pt":1723486484366,"mc":[{"id":"1.231703146","rc":[{"batb":[[0,2.04,10],[1,2.02,37.98],[2,1.74,17.32]],"ltp":2.16,"tv":221.29,"id":40096576}]}]}
{"op":"mcm","clk":"11867897986","pt":1723486500056,"mc":[{"id":"1.231703146","rc":[{"batb":[[0,2.02,37.98],[1,1.74,17.32],[2,1.73,85.5]],"ltp":2.16,"tv":221.29,"id":40096576}]}]}
{"op":"mcm","clk":"11867899136","pt":1723486510879,"mc":[{"id":"1.231703146","rc":[{"batb":[[0,2.04,10],[1,2.02,37.98],[2,1.74,17.32]],"ltp":2.16,"tv":221.29,"id":40096576}]}]}
{"op":"mcm","clk":"11867900506","pt":1723486523967,"mc":[{"id":"1.231703146","rc":[{"batb":[[0,2.02,37.98],[1,1.74,17.32],[2,1.73,85.5]],"ltp":2.16,"tv":221.29,"id":40096576}]}]}
{"op":"mcm","clk":"11867901485","pt":1723486533804,"mc":[{"id":"1.231703146","rc":[{"batb":[[0,2.04,10],[1,2.02,37.98],[2,1.74,17.32]],"ltp":2.16,"tv":221.29,"id":40096576}]}]}
{"op":"mcm","clk":"11867902884","pt":1723486548115,"mc":[{"id":"1.231703146","rc":[{"batb":[[0,2.02,37.98],[1,1.74,17.32],[2,1.73,85.5]],"ltp":2.16,"tv":221.29,"id":40096576}]}]}
{"op":"mcm","clk":"11867903960","pt":1723486559014,"mc":[{"id":"1.231703146","rc":[{"batb":[[0,2.04,10],[1,2.02,37.98],[2,1.74,17.32]],"ltp":2.16,"tv":221.29,"id":40096576}]}]}
{"op":"mcm","clk":"11867905344","pt":1723486572865,"mc":[{"id":"1.231703146","rc":[{"batb":[[0,2.02,37.98],[1,1.74,17.32],[2,1.73,85.5]],"ltp":2.16,"tv":221.29,"id":40096576}]}]}
{"op":"mcm","clk":"11867906410","pt":1723486583864,"mc":[{"id":"1.231703146","rc":[{"batb":[[0,2.04,10],[1,2.02,37.98],[2,1.74,17.32]],"ltp":2.16,"tv":221.29,"id":40096576}]}]}
{"op":"mcm","clk":"11867907762","pt":1723486598396,"mc":[{"id":"1.231703146","rc":[{"batb":[[0,2.02,37.98],[1,1.74,17.32],[2,1.73,85.5]],"ltp":2.16,"tv":221.29,"id":40096576}]}]}
{"op":"mcm","clk":"11867908867","pt":1723486611503,"mc":[{"id":"1.231703146","rc":[{"batb":[[0,2.04,10],[1,2.02,37.98],[2,1.74,17.32]],"ltp":2.16,"tv":221.29,"id":40096576}]}]}
{"op":"mcm","clk":"11867910362","pt":1723486627241,"mc":[{"id":"1.231703146","rc":[{"batb":[[0,2.02,37.98],[1,1.74,17.32],[2,1.73,85.5]],"ltp":2.16,"tv":221.29,"id":40096576}]}]}
{"op":"mcm","clk":"11867911489","pt":1723486639569,"mc":[{"id":"1.231703146","rc":[{"batb":[[0,2.04,10],[1,2.02,37.98],[2,1.74,17.32]],"ltp":2.16,"tv":221.29,"id":40096576}]}]}
{"op":"mcm","clk":"11867913051","pt":1723486655759,"mc":[{"id":"1.231703146","rc":[{"batb":[[0,2.02,37.98],[1,1.74,17.32],[2,1.73,85.5]],"ltp":2.16,"tv":221.29,"id":40096576}]}]}
{"op":"mcm","clk":"11867914036","pt":1723486666282,"mc":[{"id":"1.231703146","rc":[{"batb":[[0,2.06,10],[1,2.02,37.98],[2,1.74,17.32]],"ltp":2.16,"tv":221.29,"id":40096576}]}]}
{"op":"mcm","clk":"11867915610","pt":1723486682105,"mc":[{"id":"1.231703146","rc":[{"batb":[[0,2.02,37.98],[1,1.74,17.32],[2,1.73,85.5]],"ltp":2.16,"tv":221.29,"id":40096576}]}]}
{"op":"mcm","clk":"11867916815","pt":1723486694798,"mc":[{"id":"1.231703146","rc":[{"batb":[[0,2.04,10],[1,2.02,37.98],[2,1.74,17.32]],"ltp":2.16,"tv":221.29,"id":40096576}]}]}
{"op":"mcm","clk":"11867918255","pt":1723486709627,"mc":[{"id":"1.231703146","rc":[{"batb":[[0,2.02,37.98],[1,1.74,17.32],[2,1.73,85.5]],"ltp":2.16,"tv":221.29,"id":40096576}]}]}
{"op":"mcm","clk":"11867919455","pt":1723486722019,"mc":[{"id":"1.231703146","rc":[{"batb":[[0,2.04,10],[1,2.02,37.98],[2,1.74,17.32]],"ltp":2.16,"tv":221.29,"id":40096576}]}]}
{"op":"mcm","clk":"11867921000","pt":1723486737671,"mc":[{"id":"1.231703146","rc":[{"batb":[[0,2.02,37.98],[1,1.74,17.32],[2,1.73,85.5]],"ltp":2.16,"tv":221.29,"id":40096576}]}]}
{"op":"mcm","clk":"11867922130","pt":1723486749679,"mc":[{"id":"1.231703146","rc":[{"batb":[[0,2.04,10],[1,2.02,37.98],[2,1.74,17.32]],"ltp":2.16,"tv":221.29,"id":40096576}]}]}
{"op":"mcm","clk":"11867923639","pt":1723486766148,"mc":[{"id":"1.231703146","rc":[{"batb":[[0,2.02,37.98],[1,1.74,17.32],[2,1.73,85.5]],"ltp":2.16,"tv":221.29,"id":40096576}]}]}
{"op":"mcm","clk":"11867924855","pt":1723486779294,"mc":[{"id":"1.231703146","rc":[{"batb":[[0,2.04,10],[1,2.02,37.98],[2,1.74,17.32]],"ltp":2.16,"tv":221.29,"id":40096576}]}]}
{"op":"mcm","clk":"11867926430","pt":1723486795768,"mc":[{"id":"1.231703146","rc":[{"batb":[[0,2.02,37.98],[1,1.74,17.32],[2,1.73,85.5]],"ltp":2.16,"tv":221.29,"id":40096576}]}]}
{"op":"mcm","clk":"11867927428","pt":1723486806394,"mc":[{"id":"1.231703146","rc":[{"batb":[[0,2.06,10],[1,2.02,37.98],[2,1.74,17.32]],"ltp":2.16,"tv":221.29,"id":40096576}]}]}
{"op":"mcm","clk":"11867928931","pt":1723486822901,"mc":[{"id":"1.231703146","rc":[{"batb":[[0,2.02,37.98],[1,1.74,17.32],[2,1.73,85.5]],"ltp":2.16,"tv":221.29,"id":40096576}]}]}
{"op":"mcm","clk":"11867930663","pt":1723486841328,"mc":[{"id":"1.231703146","rc":[{"batb":[[0,2.04,10],[1,2.02,37.98],[2,1.74,17.32]],"ltp":2.16,"tv":221.29,"id":40096576}]}]}
{"op":"mcm","clk":"11867932193","pt":1723486858161,"mc":[{"id":"1.231703146","rc":[{"batb":[[0,2.02,37.98],[1,1.74,17.32],[2,1.73,85.5]],"ltp":2.16,"tv":221.29,"id":40096576}]}]}
{"op":"mcm","clk":"11867932893","pt":1723486865263,"mc":[{"id":"1.231703146","rc":[{"batb":[[0,2.06,10],[1,2.02,37.98],[2,1.74,17.32]],"ltp":2.16,"tv":221.29,"id":40096576}]}]}
{"op":"mcm","clk":"11867934569","pt":1723486882997,"mc":[{"id":"1.231703146","rc":[{"batb":[[0,2.02,37.98],[1,1.74,17.32],[2,1.73,85.5]],"ltp":2.16,"tv":221.29,"id":40096576}]}]}
{"op":"mcm","clk":"11867934770","pt":1723486885182,"mc":[{"id":"1.231703146","rc":[{"batb":[[0,2.08,10],[1,2.02,37.98],[2,1.74,17.32]],"ltp":2.16,"tv":221.29,"id":40096576}]}]}
{"op":"mcm","clk":"11867936539","pt":1723486903425,"mc":[{"id":"1.231703146","rc":[{"batb":[[0,2.02,37.98],[1,1.74,17.32],[2,1.73,85.5]],"ltp":2.16,"tv":221.29,"id":40096576}]}]}
{"op":"mcm","clk":"11867936964","pt":1723486907825,"mc":[{"id":"1.231703146","rc":[{"batb":[[0,2.1,10],[1,2.02,37.98],[2,1.74,17.32]],"ltp":2.16,"tv":221.29,"id":40096576}]}]}
{"op":"mcm","clk":"11867938772","pt":1723486926653,"mc":[{"id":"1.231703146","rc":[{"batb":[[0,2.02,37.98],[1,1.74,17.32],[2,1.73,85.5]],"ltp":2.16,"tv":221.29,"id":40096576}]}]}
{"op":"mcm","clk":"11867940441","pt":1723486943245,"mc":[{"id":"1.231703146","rc":[{"batb":[[0,2.04,10],[1,2.02,37.98],[2,1.74,17.32]],"ltp":2.16,"tv":221.29,"id":40096576}]}]}
{"op":"mcm","clk":"11867942271","pt":1723486962683,"mc":[{"id":"1.231703146","rc":[{"batb":[[0,2.02,37.98],[1,1.74,17.32],[2,1.73,85.5]],"ltp":2.16,"tv":221.29,"id":40096576}]}]}
{"op":"mcm","clk":"11867943841","pt":1723486979409,"mc":[{"id":"1.231703146","rc":[{"batb":[[0,2.04,10],[1,2.02,37.98],[2,1.74,17.32]],"ltp":2.16,"tv":221.29,"id":40096576}]}]}
{"op":"mcm","clk":"11867945694","pt":1723486999520,"mc":[{"id":"1.231703146","rc":[{"batb":[[0,2.02,37.98],[1,1.74,17.32],[2,1.73,85.5]],"ltp":2.16,"tv":221.29,"id":40096576}]}]}
{"op":"mcm","clk":"11867947122","pt":1723487014879,"mc":[{"id":"1.231703146","rc":[{"batb":[[0,2.04,10],[1,2.02,37.98],[2,1.74,17.32]],"ltp":2.16,"tv":221.29,"id":40096576}]}]}
{"op":"mcm","clk":"11867949084","pt":1723487034579,"mc":[{"id":"1.231703146","rc":[{"batb":[[0,2.02,37.98],[1,1.74,17.32],[2,1.73,85.5]],"ltp":2.16,"tv":221.29,"id":40096576}]}]}
{"op":"mcm","clk":"11867950778","pt":1723487052079,"mc":[{"id":"1.231703146","rc":[{"batb":[[0,2.04,10],[1,2.02,37.98],[2,1.74,17.32]],"ltp":2.16,"tv":221.29,"id":40096576}]}]}
{"op":"mcm","clk":"11867952733","pt":1723487072416,"mc":[{"id":"1.231703146","rc":[{"batb":[[0,2.02,37.98],[1,1.74,17.32],[2,1.73,85.5]],"ltp":2.16,"tv":221.29,"id":40096576}]}]}
{"op":"mcm","clk":"11867954293","pt":1723487089456,"mc":[{"id":"1.231703146","rc":[{"batb":[[0,2.04,10],[1,2.02,37.98],[2,1.74,17.32]],"ltp":2.16,"tv":221.29,"id":40096576}]}]}
{"op":"mcm","clk":"11867956117","pt":1723487109190,"mc":[{"id":"1.231703146","rc":[{"batb":[[0,2.02,37.98],[1,1.74,17.32],[2,1.73,85.5]],"ltp":2.16,"tv":221.29,"id":40096576}]}]}
{"op":"mcm","clk":"11867957723","pt":1723487125615,"mc":[{"id":"1.231703146","rc":[{"batb":[[0,2.04,10],[1,2.02,37.98],[2,1.74,17.32]],"ltp":2.16,"tv":221.29,"id":40096576}]}]}
{"op":"mcm","clk":"11867959636","pt":1723487145244,"mc":[{"id":"1.231703146","rc":[{"batb":[[0,2.02,37.98],[1,1.74,17.32],[2,1.73,85.5]],"ltp":2.16,"tv":221.29,"id":40096576}]}]}
{"op":"mcm","clk":"11867961307","pt":1723487161335,"mc":[{"id":"1.231703146","rc":[{"batb":[[0,2.04,10],[1,2.02,37.98],[2,1.74,17.32]],"ltp":2.16,"tv":221.29,"id":40096576}]}]}
{"op":"mcm","clk":"11867963299","pt":1723487181044,"mc":[{"id":"1.231703146","rc":[{"batb":[[0,2.02,37.98],[1,1.74,17.32],[2,1.73,85.5]],"ltp":2.16,"tv":221.29,"id":40096576}]}]}
{"op":"mcm","clk":"11867965056","pt":1723487198374,"mc":[{"id":"1.231703146","rc":[{"batb":[[0,2.04,10],[1,2.02,37.98],[2,1.74,17.32]],"ltp":2.16,"tv":221.29,"id":40096576}]}]}
{"op":"mcm","clk":"11867967044","pt":1723487219002,"mc":[{"id":"1.231703146","rc":[{"batb":[[0,2.02,37.98],[1,1.74,17.32],[2,1.73,85.5]],"ltp":2.16,"tv":221.29,"id":40096576}]}]}
{"op":"mcm","clk":"11867968635","pt":1723487236126,"mc":[{"id":"1.231703146","rc":[{"batb":[[0,2.04,10],[1,2.02,37.98],[2,1.74,17.32]],"ltp":2.16,"tv":221.29,"id":40096576}]}]}
{"op":"mcm","clk":"11867970457","pt":1723487257658,"mc":[{"id":"1.231703146","rc":[{"batb":[[0,2.02,37.98],[1,1.74,17.32],[2,1.73,85.5]],"ltp":2.16,"tv":221.29,"id":40096576}]}]}
{"op":"mcm","clk":"11867971806","pt":1723487274782,"mc":[{"id":"1.231703146","rc":[{"batb":[[0,2.04,10],[1,2.02,37.98],[2,1.74,17.32]],"ltp":2.16,"tv":221.29,"id":40096576}]}]}
{"op":"mcm","clk":"11867974059","pt":1723487300005,"mc":[{"id":"1.231703146","rc":[{"batb":[[0,2.02,37.98],[1,1.74,17.32],[2,1.73,85.5]],"ltp":2.16,"tv":221.29,"id":40096576}]}]}
{"op":"mcm","clk":"11867975542","pt":1723487315825,"mc":[{"id":"1.231703146","rc":[{"batb":[[0,2.04,10],[1,2.02,37.98],[2,1.74,17.32]],"ltp":2.16,"tv":221.29,"id":40096576}]}]}
{"op":"mcm","clk":"11867977286","pt":1723487334156,"mc":[{"id":"1.231703146","rc":[{"batb":[[0,2.02,37.98],[1,1.74,17.32],[2,1.73,85.5]],"ltp":2.16,"tv":221.29,"id":40096576}]}]}
{"op":"mcm","clk":"11867978640","pt":1723487349381,"mc":[{"id":"1.231703146","rc":[{"batb":[[0,2.04,10],[1,2.02,37.98],[2,1.74,17.32]],"ltp":2.16,"tv":221.29,"id":40096576}]}]}
{"op":"mcm","clk":"11867980357","pt":1723487367097,"mc":[{"id":"1.231703146","rc":[{"batb":[[0,2.02,37.98],[1,1.74,17.32],[2,1.73,85.5]],"ltp":2.16,"tv":221.29,"id":40096576}]}]}
{"op":"mcm","clk":"11867981772","pt":1723487382408,"mc":[{"id":"1.231703146","rc":[{"batb":[[0,2.04,10],[1,2.02,37.98],[2,1.74,17.32]],"ltp":2.16,"tv":221.29,"id":40096576}]}]}
{"op":"mcm","clk":"11867983531","pt":1723487401156,"mc":[{"id":"1.231703146","rc":[{"batb":[[0,2.02,37.98],[1,1.74,17.32],[2,1.73,85.5]],"ltp":2.16,"tv":221.29,"id":40096576}]}]}
{"op":"mcm","clk":"11867985051","pt":1723487416670,"mc":[{"id":"1.231703146","rc":[{"batb":[[0,2.04,10],[1,2.02,37.98],[2,1.74,17.32]],"ltp":2.16,"tv":221.29,"id":40096576}]}]}
{"op":"mcm","clk":"11867986917","pt":1723487436004,"mc":[{"id":"1.231703146","rc":[{"batb":[[0,2.02,37.98],[1,1.74,17.32],[2,1.73,85.5]],"ltp":2.16,"tv":221.29,"id":40096576}]}]}
{"op":"mcm","clk":"11867988431","pt":1723487451992,"mc":[{"id":"1.231703146","rc":[{"batb":[[0,2.04,10],[1,2.02,37.98],[2,1.74,17.32]],"ltp":2.16,"tv":221.29,"id":40096576}]}]}
{"op":"mcm","clk":"11867990292","pt":1723487471622,"mc":[{"id":"1.231703146","rc":[{"batb":[[0,2.02,37.98],[1,1.74,17.32],[2,1.73,85.5]],"ltp":2.16,"tv":221.29,"id":40096576}]}]}
{"op":"mcm","clk":"11867991749","pt":1723487487868,"mc":[{"id":"1.231703146","rc":[{"batb":[[0,2.04,10],[1,2.02,37.98],[2,1.74,17.32]],"ltp":2.16,"tv":221.29,"id":40096576}]}]}
{"op":"mcm","clk":"11867993493","pt":1723487506774,"mc":[{"id":"1.231703146","rc":[{"batb":[[0,2.02,37.98],[1,1.74,17.32],[2,1.73,85.5]],"ltp":2.16,"tv":221.29,"id":40096576}]}]}
{"op":"mcm","clk":"11867994921","pt":1723487522577,"mc":[{"id":"1.231703146","rc":[{"batb":[[0,2.04,10],[1,2.02,37.98],[2,1.74,17.32]],"ltp":2.16,"tv":221.29,"id":40096576}]}]}
{"op":"mcm","clk":"11867996743","pt":1723487540728,"mc":[{"id":"1.231703146","rc":[{"batb":[[0,2.02,37.98],[1,1.74,17.32],[2,1.73,85.5]],"ltp":2.16,"tv":221.29,"id":40096576}]}]}
{"op":"mcm","clk":"11867998199","pt":1723487556406,"mc":[{"id":"1.231703146","rc":[{"batb":[[0,2.04,10],[1,2.02,37.98],[2,1.74,17.32]],"ltp":2.16,"tv":221.29,"id":40096576}]}]}
{"op":"mcm","clk":"11867999910","pt":1723487574450,"mc":[{"id":"1.231703146","rc":[{"batb":[[0,2.02,37.98],[1,1.74,17.32],[2,1.73,85.5]],"ltp":2.16,"tv":221.29,"id":40096576}]}]}
{"op":"mcm","clk":"11868001430","pt":1723487591147,"mc":[{"id":"1.231703146","rc":[{"batb":[[0,2.04,10],[1,2.02,37.98],[2,1.74,17.32]],"ltp":2.16,"tv":221.29,"id":40096576}]}]}
{"op":"mcm","clk":"11868003199","pt":1723487610084,"mc":[{"id":"1.231703146","rc":[{"batb":[[0,2.02,37.98],[1,1.74,17.32],[2,1.73,85.5]],"ltp":2.16,"tv":221.29,"id":40096576}]}]}
{"op":"mcm","clk":"11868004674","pt":1723487628205,"mc":[{"id":"1.231703146","rc":[{"batb":[[0,2.04,10],[1,2.02,37.98],[2,1.74,17.32]],"ltp":2.16,"tv":221.29,"id":40096576}]}]}
{"op":"mcm","clk":"11868006546","pt":1723487649034,"mc":[{"id":"1.231703146","rc":[{"batb":[[0,2.02,37.98],[1,1.74,17.32],[2,1.73,85.5]],"ltp":2.16,"tv":221.29,"id":40096576}]}]}
{"op":"mcm","clk":"11868008213","pt":1723487666957,"mc":[{"id":"1.231703146","rc":[{"batb":[[0,2.04,10],[1,2.02,37.98],[2,1.74,17.32]],"ltp":2.16,"tv":221.29,"id":40096576}]}]}
{"op":"mcm","clk":"11868010101","pt":1723487687578,"mc":[{"id":"1.231703146","rc":[{"batb":[[0,2.02,37.98],[1,1.74,17.32],[2,1.73,85.5]],"ltp":2.16,"tv":221.29,"id":40096576}]}]}
{"op":"mcm","clk":"11868012394","pt":1723487712010,"mc":[{"id":"1.231703146","rc":[{"batb":[[0,2.04,10],[1,2.02,37.98],[2,1.74,17.32]],"ltp":2.16,"tv":221.29,"id":40096576}]}]}
{"op":"mcm","clk":"11868014400","pt":1723487733421,"mc":[{"id":"1.231703146","rc":[{"batb":[[0,2.02,37.98],[1,1.74,17.32],[2,1.73,85.5]],"ltp":2.16,"tv":221.29,"id":40096576}]}]}
{"op":"mcm","clk":"11868015945","pt":1723487751591,"mc":[{"id":"1.231703146","rc":[{"batb":[[0,2.04,10],[1,2.02,37.98],[2,1.74,17.32]],"ltp":2.16,"tv":221.29,"id":40096576}]}]}
{"op":"mcm","clk":"11868017881","pt":1723487773175,"mc":[{"id":"1.231703146","rc":[{"batb":[[0,2.02,37.98],[1,1.74,17.32],[2,1.73,85.5]],"ltp":2.16,"tv":221.29,"id":40096576}]}]}
{"op":"mcm","clk":"11868019277","pt":1723487789998,"mc":[{"id":"1.231703146","rc":[{"batb":[[0,2.04,10],[1,2.02,37.98],[2,1.74,17.32]],"ltp":2.16,"tv":221.29,"id":40096576}]}]}
{"op":"mcm","clk":"11868020942","pt":1723487809306,"mc":[{"id":"1.231703146","rc":[{"batb":[[0,2.02,37.98],[1,1.74,17.32],[2,1.73,85.5]],"ltp":2.16,"tv":221.29,"id":40096576}]}]}
{"op":"mcm","clk":"11868022430","pt":1723487825605,"mc":[{"id":"1.231703146","rc":[{"batb":[[0,2.04,10],[1,2.02,37.98],[2,1.74,17.32]],"ltp":2.16,"tv":221.29,"id":40096576}]}]}
{"op":"mcm","clk":"11868024424","pt":1723487846344,"mc":[{"id":"1.231703146","rc":[{"batb":[[0,2.02,37.98],[1,1.74,17.32],[2,1.73,85.5]],"ltp":2.16,"tv":221.29,"id":40096576}]}]}
{"op":"mcm","clk":"11868026306","pt":1723487864854,"mc":[{"id":"1.231703146","rc":[{"batb":[[0,2.04,10],[1,2.02,37.98],[2,1.74,17.32]],"ltp":2.16,"tv":221.29,"id":40096576}]}]}
{"op":"mcm","clk":"11868028639","pt":1723487887174,"mc":[{"id":"1.231703146","rc":[{"batb":[[0,2.02,37.98],[1,1.74,17.32],[2,1.73,85.5]],"ltp":2.16,"tv":221.29,"id":40096576}]}]}
{"op":"mcm","clk":"11868150220","pt":1723489210729,"mc":[{"id":"1.231703146","rc":[{"trd":[[1.58,169.16],[1.79,26.48],[1.84,9.18],[1.86,17.62],[1.91,163.85]],"batl":[[0,1.93,8.45]],"ltp":1.87,"tv":647.57,"id":40096589},{"trd":[[1.58,169.16],[2.04,7.68],[2.16,1.95]],"batb":[[0,2.04,10],[1,2.02,37.98],[2,1.74,17.32]],"ltp":2.16,"tv":221.24,"id":40096576}],"tv":868.81}]}
{"op":"mcm","clk":"11868150554","pt":1723489214301,"mc":[{"id":"1.231703146","rc":[{"batb":[[0,2.02,37.98],[1,1.74,17.32],[2,1.73,85.5]],"ltp":2.16,"tv":221.24,"id":40096576}]}]}
{"op":"mcm","clk":"11868152161","pt":1723489233155,"mc":[{"id":"1.231703146","rc":[{"batb":[[0,2.04,10],[1,2.02,37.98],[2,1.74,17.32]],"ltp":2.16,"tv":221.24,"id":40096576}]}]}
{"op":"mcm","clk":"11868152428","pt":1723489236747,"mc":[{"id":"1.231703146","rc":[{"batb":[[0,2.02,37.98],[1,1.74,17.32],[2,1.73,85.5]],"ltp":2.16,"tv":221.24,"id":40096576}]}]}
{"op":"mcm","clk":"11868153541","pt":1723489251463,"mc":[{"id":"1.231703146","rc":[{"batb":[[0,2.04,10],[1,2.02,37.98],[2,1.74,17.32]],"ltp":2.16,"tv":221.24,"id":40096576}]}]}
{"op":"mcm","clk":"11868153912","pt":1723489256959,"mc":[{"id":"1.231703146","rc":[{"batb":[[0,2.02,37.98],[1,1.74,17.32],[2,1.73,85.5]],"ltp":2.16,"tv":221.24,"id":40096576}]}]}
{"op":"mcm","clk":"11868154706","pt":1723489267900,"mc":[{"id":"1.231703146","rc":[{"batb":[[0,2.04,10],[1,2.02,37.98],[2,1.74,17.32]],"ltp":2.16,"tv":221.24,"id":40096576}]}]}
{"op":"mcm","clk":"11868155009","pt":1723489271901,"mc":[{"id":"1.231703146","rc":[{"batb":[[0,2.02,37.98],[1,1.74,17.32],[2,1.73,85.5]],"ltp":2.16,"tv":221.24,"id":40096576}]}]}
{"op":"mcm","clk":"11868155397","pt":1723489277106,"mc":[{"id":"1.231703146","rc":[{"batb":[[0,2.04,10],[1,2.02,37.98],[2,1.74,17.32]],"ltp":2.16,"tv":221.24,"id":40096576}]}]}
{"op":"mcm","clk":"11868155748","pt":1723489282090,"mc":[{"id":"1.231703146","rc":[{"batb":[[0,2.02,37.98],[1,1.74,17.32],[2,1.73,85.5]],"ltp":2.16,"tv":221.24,"id":40096576}]}]}
{"op":"mcm","clk":"11868155924","pt":1723489284730,"mc":[{"id":"1.231703146","rc":[{"batb":[[0,2.06,10],[1,2.02,37.98],[2,1.74,17.32]],"ltp":2.16,"tv":221.24,"id":40096576}]}]}
{"op":"mcm","clk":"11868156273","pt":1723489290321,"mc":[{"id":"1.231703146","rc":[{"batb":[[0,2.02,37.98],[1,1.74,17.32],[2,1.73,85.5]],"ltp":2.16,"tv":221.24,"id":40096576}]}]}
{"op":"mcm","clk":"11868156811","pt":1723489298619,"mc":[{"id":"1.231703146","rc":[{"batb":[[0,2.04,10],[1,2.02,37.98],[2,1.74,17.32]],"ltp":2.16,"tv":221.24,"id":40096576}]}]}
{"op":"mcm","clk":"11868157107","pt":1723489303742,"mc":[{"id":"1.231703146","rc":[{"batb":[[0,2.02,37.98],[1,1.74,17.32],[2,1.73,85.5]],"ltp":2.16,"tv":221.24,"id":40096576}]}]}
{"op":"mcm","clk":"11868157276","pt":1723489306241,"mc":[{"id":"1.231703146","rc":[{"batb":[[0,2.04,10],[1,2.02,37.98],[2,1.74,17.32]],"ltp":2.16,"tv":221.24,"id":40096576}]}]}
{"op":"mcm","clk":"11868157560","pt":1723489311033,"mc":[{"id":"1.231703146","rc":[{"batb":[[0,2.02,37.98],[1,1.74,17.32],[2,1.73,85.5]],"ltp":2.16,"tv":221.24,"id":40096576}]}]}
{"op":"mcm","clk":"11868162079","pt":1723489383048,"mc":[{"id":"1.231703146","rc":[{"batb":[[0,2.04,10],[1,2.02,37.98],[2,1.74,17.32]],"ltp":2.16,"tv":221.24,"id":40096576}]}]}
{"op":"mcm","clk":"11868162424","pt":1723489388341,"mc":[{"id":"1.231703146","rc":[{"batb":[[0,2.02,37.98],[1,1.74,17.32],[2,1.73,85.5]],"ltp":2.16,"tv":221.24,"id":40096576}]}]}
{"op":"mcm","clk":"11868163147","pt":1723489399879,"mc":[{"id":"1.231703146","rc":[{"batb":[[0,2.04,10],[1,2.02,37.98],[2,1.74,17.32]],"ltp":2.16,"tv":221.24,"id":40096576}]}]}
{"op":"mcm","clk":"11868163501","pt":1723489405496,"mc":[{"id":"1.231703146","rc":[{"batb":[[0,2.02,37.98],[1,1.74,17.32],[2,1.73,85.5]],"ltp":2.16,"tv":221.24,"id":40096576}]}]}
{"op":"mcm","clk":"11868163670","pt":1723489408250,"mc":[{"id":"1.231703146","rc":[{"batb":[[0,2.04,10],[1,2.02,37.98],[2,1.74,17.32]],"ltp":2.16,"tv":221.24,"id":40096576}]}]}
{"op":"mcm","clk":"11868164010","pt":1723489413587,"mc":[{"id":"1.231703146","rc":[{"batb":[[0,2.02,37.98],[1,1.74,17.32],[2,1.73,85.5]],"ltp":2.16,"tv":221.24,"id":40096576}]}]}
{"op":"mcm","clk":"11868165193","pt":1723489433580,"mc":[{"id":"1.231703146","rc":[{"batb":[[0,2.04,10],[1,2.02,37.98],[2,1.74,17.32]],"ltp":2.16,"tv":221.24,"id":40096576}]}]}
{"op":"mcm","clk":"11868165427","pt":1723489437205,"mc":[{"id":"1.231703146","rc":[{"batb":[[0,2.02,37.98],[1,1.74,17.32],[2,1.73,85.5]],"ltp":2.16,"tv":221.24,"id":40096576}]}]}
{"op":"mcm","clk":"11868165637","pt":1723489440720,"mc":[{"id":"1.231703146","rc":[{"batb":[[0,2.04,10],[1,2.02,37.98],[2,1.74,17.32]],"ltp":2.16,"tv":221.24,"id":40096576}]}]}
{"op":"mcm","clk":"11868166082","pt":1723489447498,"mc":[{"id":"1.231703146","rc":[{"batb":[[0,2.02,37.98],[1,1.74,17.32],[2,1.73,85.5]],"ltp":2.16,"tv":221.24,"id":40096576}]}]}
{"op":"mcm","clk":"11868192519","pt":1723489853501,"mc":[{"id":"1.231703146","rc":[{"batb":[[0,2.04,10],[1,2.02,37.98],[2,1.74,17.32]],"ltp":2.16,"tv":221.24,"id":40096576}]}]}
{"op":"mcm","clk":"11868193956","pt":1723489869760,"mc":[{"id":"1.231703146","rc":[{"batb":[[0,2.02,37.98],[1,1.74,17.32],[2,1.73,85.5]],"ltp":2.16,"tv":221.24,"id":40096576}]}]}
{"op":"mcm","clk":"11868195094","pt":1723489884265,"mc":[{"id":"1.231703146","rc":[{"batb":[[0,2.04,10],[1,2.02,37.98],[2,1.74,17.32]],"ltp":2.16,"tv":221.24,"id":40096576}]}]}
{"op":"mcm","clk":"11868196429","pt":1723489903055,"mc":[{"id":"1.231703146","rc":[{"batb":[[0,2.02,37.98],[1,1.74,17.32],[2,1.73,85.5]],"ltp":2.16,"tv":221.24,"id":40096576}]}]}
{"op":"mcm","clk":"11868197590","pt":1723489920100,"mc":[{"id":"1.231703146","rc":[{"batb":[[0,2.04,10],[1,2.02,37.98],[2,1.74,17.32]],"ltp":2.16,"tv":221.24,"id":40096576}]}]}
{"op":"mcm","clk":"11868199300","pt":1723489943699,"mc":[{"id":"1.231703146","rc":[{"batb":[[0,2.02,37.98],[1,1.74,17.32],[2,1.73,85.5]],"ltp":2.16,"tv":221.24,"id":40096576}]}]}
{"op":"mcm","clk":"11868200797","pt":1723489964515,"mc":[{"id":"1.231703146","rc":[{"batb":[[0,2.04,10],[1,2.02,37.98],[2,1.74,17.32]],"ltp":2.16,"tv":221.24,"id":40096576}]}]}
{"op":"mcm","clk":"11868202455","pt":1723489989139,"mc":[{"id":"1.231703146","rc":[{"batb":[[0,2.02,37.98],[1,1.74,17.32],[2,1.73,85.5]],"ltp":2.16,"tv":221.24,"id":40096576}]}]}
{"op":"mcm","clk":"11868204144","pt":1723490013159,"mc":[{"id":"1.231703146","rc":[{"batb":[[0,2.04,10],[1,2.02,37.98],[2,1.74,17.32]],"ltp":2.16,"tv":221.24,"id":40096576}]}]}
{"op":"mcm","clk":"11868206033","pt":1723490041977,"mc":[{"id":"1.231703146","rc":[{"batb":[[0,2.02,37.98],[1,1.74,17.32],[2,1.73,85.5]],"ltp":2.16,"tv":221.24,"id":40096576}]}]}
{"op":"mcm","clk":"11868207685","pt":1723490065741,"mc":[{"id":"1.231703146","rc":[{"batb":[[0,2.04,10],[1,2.02,37.98],[2,1.74,17.32]],"ltp":2.16,"tv":221.24,"id":40096576}]}]}
{"op":"mcm","clk":"11868209568","pt":1723490091779,"mc":[{"id":"1.231703146","rc":[{"batb":[[0,2.02,37.98],[1,1.74,17.32],[2,1.73,85.5]],"ltp":2.16,"tv":221.24,"id":40096576}]}]}
{"op":"mcm","clk":"11868211339","pt":1723490115114,"mc":[{"id":"1.231703146","rc":[{"batb":[[0,2.04,10],[1,2.02,37.98],[2,1.74,17.32]],"ltp":2.16,"tv":221.24,"id":40096576}]}]}
{"op":"mcm","clk":"11868213564","pt":1723490142017,"mc":[{"id":"1.231703146","rc":[{"batb":[[0,2.02,37.98],[1,1.74,17.32],[2,1.73,85.5]],"ltp":2.16,"tv":221.24,"id":40096576}]}]}
{"op":"mcm","clk":"11868215991","pt":1723490173075,"mc":[{"id":"1.231703146","rc":[{"batb":[[0,2.04,10],[1,2.02,37.98],[2,1.74,17.32]],"ltp":2.16,"tv":221.24,"id":40096576}]}]}
{"op":"mcm","clk":"11868217939","pt":1723490200499,"mc":[{"id":"1.231703146","rc":[{"batb":[[0,2.02,37.98],[1,1.74,17.32],[2,1.73,85.5]],"ltp":2.16,"tv":221.24,"id":40096576}]}]}
{"op":"mcm","clk":"11868219656","pt":1723490222543,"mc":[{"id":"1.231703146","rc":[{"batb":[[0,2.04,10],[1,2.02,37.98],[2,1.74,17.32]],"ltp":2.16,"tv":221.24,"id":40096576}]}]}
{"op":"mcm","clk":"11868221558","pt":1723490244063,"mc":[{"id":"1.231703146","rc":[{"batb":[[0,2.02,37.98],[1,1.74,17.32],[2,1.73,85.5]],"ltp":2.16,"tv":221.24,"id":40096576}]}]}
{"op":"mcm","clk":"11868222465","pt":1723490255168,"mc":[{"id":"1.231703146","rc":[{"batl":[[0,1.92,10.19],[1,1.93,8.25],[2,1.94,9.02]],"ltp":1.87,"tv":647.57,"id":40096589}]}]}
{"op":"mcm","clk":"11868222819","pt":1723490259671,"mc":[{"id":"1.231703146","rc":[{"batb":[[0,2.04,10],[1,2.02,37.98],[2,1.74,17.32]],"ltp":2.16,"tv":221.24,"id":40096576}]}]}
{"op":"mcm","clk":"11868223505","pt":1723490267863,"mc":[{"id":"1.231703146","rc":[{"trd":[[1.86,20.97]],"batb":[[0,1.86,25.47]],"ltp":1.86,"tv":650.92,"id":40096589}],"tv":872.16}]}
{"op":"mcm","clk":"11868224312","pt":1723490277700,"mc":[{"id":"1.231703146","rc":[{"batb":[[0,2.02,37.98],[1,1.74,17.32],[2,1.73,85.5]],"ltp":2.16,"tv":221.24,"id":40096576}]}]}
{"op":"mcm","clk":"11868224713","pt":1723490282305,"mc":[{"id":"1.231703146","rc":[{"batb":[[0,2.06,10],[1,2.02,37.98],[2,1.74,17.32]],"ltp":2.16,"tv":221.24,"id":40096576}]}]}
{"op":"mcm","clk":"11868226257","pt":1723490299145,"mc":[{"id":"1.231703146","rc":[{"batb":[[0,2.02,37.98],[1,1.74,17.32],[2,1.73,85.5]],"ltp":2.16,"tv":221.24,"id":40096576}]}]}
{"op":"mcm","clk":"11868227443","pt":1723490313642,"mc":[{"id":"1.231703146","rc":[{"batb":[[0,2.04,10],[1,2.02,37.98],[2,1.74,17.32]],"ltp":2.16,"tv":221.24,"id":40096576}]}]}
{"op":"mcm","clk":"11868228953","pt":1723490330671,"mc":[{"id":"1.231703146","rc":[{"batb":[[0,2.02,37.98],[1,1.74,17.32],[2,1.73,85.5]],"ltp":2.16,"tv":221.24,"id":40096576}]}]}
{"op":"mcm","clk":"11868230210","pt":1723490345088,"mc":[{"id":"1.231703146","rc":[{"batb":[[0,2.04,10],[1,2.02,37.98],[2,1.74,17.32]],"ltp":2.16,"tv":221.24,"id":40096576}]}]}
{"op":"mcm","clk":"11868231896","pt":1723490362530,"mc":[{"id":"1.231703146","rc":[{"batb":[[0,2.02,37.98],[1,1.74,17.32],[2,1.73,85.5]],"ltp":2.16,"tv":221.24,"id":40096576}]}]}
{"op":"mcm","clk":"11868233054","pt":1723490376753,"mc":[{"id":"1.231703146","rc":[{"batb":[[0,2.04,10],[1,2.02,37.98],[2,1.74,17.32]],"ltp":2.16,"tv":221.24,"id":40096576}]}]}
{"op":"mcm","clk":"11868234333","pt":1723490393473,"mc":[{"id":"1.231703146","rc":[{"batb":[[0,2.02,37.98],[1,1.74,17.32],[2,1.73,85.5]],"ltp":2.16,"tv":221.24,"id":40096576}]}]}
{"op":"mcm","clk":"11868235739","pt":1723490408580,"mc":[{"id":"1.231703146","rc":[{"batb":[[0,2.04,10],[1,2.02,37.98],[2,1.74,17.32]],"ltp":2.16,"tv":221.24,"id":40096576}]}]}
{"op":"mcm","clk":"11868237173","pt":1723490426718,"mc":[{"id":"1.231703146","rc":[{"batb":[[0,2.02,37.98],[1,1.74,17.32],[2,1.73,85.5]],"ltp":2.16,"tv":221.24,"id":40096576}]}]}
{"op":"mcm","clk":"11868238386","pt":1723490440717,"mc":[{"id":"1.231703146","rc":[{"batb":[[0,2.04,10],[1,2.02,37.98],[2,1.74,17.32]],"ltp":2.16,"tv":221.24,"id":40096576}]}]}
{"op":"mcm","clk":"11868239826","pt":1723490457069,"mc":[{"id":"1.231703146","rc":[{"batb":[[0,2.02,37.98],[1,1.74,17.32],[2,1.73,85.5]],"ltp":2.16,"tv":221.24,"id":40096576}]}]}
{"op":"mcm","clk":"11868240880","pt":1723490470571,"mc":[{"id":"1.231703146","rc":[{"batb":[[0,2.04,10],[1,2.02,37.98],[2,1.74,17.32]],"ltp":2.16,"tv":221.24,"id":40096576}]}]}
{"op":"mcm","clk":"11868242250","pt":1723490486561,"mc":[{"id":"1.231703146","rc":[{"batb":[[0,2.02,37.98],[1,1.74,17.32],[2,1.73,85.5]],"ltp":2.16,"tv":221.24,"id":40096576}]}]}
{"op":"mcm","clk":"11868243410","pt":1723490500412,"mc":[{"id":"1.231703146","rc":[{"batb":[[0,2.04,10],[1,2.02,37.98],[2,1.74,17.32]],"ltp":2.16,"tv":221.24,"id":40096576}]}]}
{"op":"mcm","clk":"11868244809","pt":1723490516859,"mc":[{"id":"1.231703146","rc":[{"batb":[[0,2.02,37.98],[1,1.74,17.32],[2,1.73,85.5]],"ltp":2.16,"tv":221.24,"id":40096576}]}]}
{"op":"mcm","clk":"11868246116","pt":1723490531550,"mc":[{"id":"1.231703146","rc":[{"batb":[[0,2.04,10],[1,2.02,37.98],[2,1.74,17.32]],"ltp":2.16,"tv":221.24,"id":40096576}]}]}
{"op":"mcm","clk":"11868247579","pt":1723490548237,"mc":[{"id":"1.231703146","rc":[{"batb":[[0,2.02,37.98],[1,1.74,17.32],[2,1.73,85.5]],"ltp":2.16,"tv":221.24,"id":40096576}]}]}
{"op":"mcm","clk":"11868248723","pt":1723490561760,"mc":[{"id":"1.231703146","rc":[{"batb":[[0,2.04,10],[1,2.02,37.98],[2,1.74,17.32]],"ltp":2.16,"tv":221.24,"id":40096576}]}]}
{"op":"mcm","clk":"11868250553","pt":1723490583102,"mc":[{"id":"1.231703146","rc":[{"batb":[[0,2.02,37.98],[1,1.74,17.32],[2,1.73,85.5]],"ltp":2.16,"tv":221.24,"id":40096576}]}]}
{"op":"mcm","clk":"11868250984","pt":1723490587719,"mc":[{"id":"1.231703146","rc":[{"batb":[[0,2.06,10],[1,2.02,37.98],[2,1.74,17.32]],"ltp":2.16,"tv":221.24,"id":40096576}]}]}
{"op":"mcm","clk":"11868252512","pt":1723490605545,"mc":[{"id":"1.231703146","rc":[{"batb":[[0,2.02,37.98],[1,1.74,17.32],[2,1.73,85.5]],"ltp":2.16,"tv":221.24,"id":40096576}]}]}
