{"op":"mcm","clk":"11765922647","pt":1722594483813,"mc":[{"id":"1.231345087","marketDefinition":{"bspMarket":false,"turnInPlayEnabled":true,"persistenceEnabled":true,"marketBaseRate":5.0,"eventId":"33462721","eventTypeId":"4","numberOfWinners":1,"bettingType":"ODDS","marketType":"MATCH_ODDS","marketTime":"2024-08-04T13:30:00.000Z","suspendTime":"2024-08-04T13:30:00.000Z","bspReconciled":false,"complete":true,"inPlay":false,"crossMatching":true,"runnersVoidable":false,"numberOfActiveRunners":2,"betDelay":0,"status":"OPEN","runners":[{"status":"ACTIVE","sortPriority":1,"id":40096589,"name":"Northern Superchargers Women"},{"status":"ACTIVE","sortPriority":2,"id":47651809,"name":"Manchester Original"}],"regulators":["MR_INT"],"countryCode":"GB","discountAllowed":false,"timezone":"GMT","openDate":"2024-08-04T13:30:00.000Z","version":6051298590,"name":"Match Odds","eventName":"Northern Superchargers Women v Manchester Original"},"rc":[{"batb":[[0,1.03,200],[1,1.02,200],[2,1.01,220]],"ltp":0.0,"tv":0.0,"id":40096589},{"batb":[[0,1.03,200],[1,1.02,200],[2,1.01,220]],"ltp":0.0,"tv":0.0,"id":47651809}]}]}
{"op":"mcm","clk":"11765922812","pt":1722594488446,"mc":[{"id":"1.231345087","marketDefinition":{"bspMarket":false,"turnInPlayEnabled":true,"persistenceEnabled":true,"marketBaseRate":5.0,"eventId":"33462721","eventTypeId":"4","numberOfWinners":1,"bettingType":"ODDS","marketType":"MATCH_ODDS","marketTime":"2024-08-04T13:30:00.000Z","suspendTime":"2024-08-04T13:30:00.000Z","bspReconciled":false,"complete":true,"inPlay":false,"crossMatching":true,"runnersVoidable":false,"numberOfActiveRunners":2,"betDelay":0,"status":"OPEN","runners":[{"status":"ACTIVE","sortPriority":1,"id":40096589,"name":"Northern Superchargers Women"},{"status":"ACTIVE","sortPriority":2,"id":47651809,"name":"Manchester Original"}],"regulators":["MR_INT"],"countryCode":"GB","discountAllowed":true,"timezone":"GMT","openDate":"2024-08-04T13:30:00.000Z","version":6051298590,"name":"Match Odds","eventName":"Northern Superchargers Women v Manchester Original"}}]}
{"op":"mcm","clk":"11765940075","pt":1722594985426,"mc":[{"id":"1.231345087","rc":[{"batb":[[0,1.04,50],[1,1.03,200],[2,1.02,200]],"ltp":0.0,"tv":0.0,"id":40096589},{"batb":[[0,1.04,50],[1,1.03,200],[2,1.02,200]],"ltp":0.0,"tv":0.0,"id":47651809}]}]}
{"op":"mcm","clk":"11766183803","pt":1722601285046,"mc":[{"id":"1.231345087","rc":[{"batb":[[0,1.1,25000],[1,1.09,25000],[2,1.08,25000]],"ltp":0.0,"tv":0.0,"id":40096589},{"batb":[[0,1.1,25000],[1,1.09,25000],[2,1.08,25000]],"ltp":0.0,"tv":0.0,"id":47651809}]}]}
{"op":"mcm","clk":"11766184011","pt":1722601289423,"mc":[{"id":"1.231345087","rc":[{"batb":[[0,1.1,15000]],"ltp":0.0,"tv":0.0,"id":40096589}]}]}
{"op":"mcm","clk":"11766184036","pt":1722601290247,"mc":[{"id":"1.231345087","rc":[{"batb":[[0,1.08,15000],[1,1.07,25000],[2,1.06,25000]],"ltp":0.0,"tv":0.0,"id":40096589}]}]}
{"op":"mcm","clk":"11766184059","pt":1722601290864,"mc":[{"id":"1.231345087","rc":[{"batb":[[0,1.06,25000],[1,1.05,25000],[2,1.04,25050]],"ltp":0.0,"tv":0.0,"id":40096589}]}]}
{"op":"mcm","clk":"11766184127","pt":1722601292321,"mc":[{"id":"1.231345087","rc":[{"batb":[[0,1.04,25050],[1,1.03,25200],[2,1.02,25200]],"ltp":0.0,"tv":0.0,"id":40096589}]}]}
{"op":"mcm","clk":"11766184284","pt":1722601296354,"mc":[{"id":"1.231345087","rc":[{"batb":[[0,1.09,25000],[1,1.08,25000],[2,1.07,25000]],"ltp":0.0,"tv":0.0,"id":47651809}]}]}
{"op":"mcm","clk":"11766184316","pt":1722601297036,"mc":[{"id":"1.231345087","rc":[{"batb":[[0,1.08,25000],[1,1.06,25000],[2,1.05,25000]],"ltp":0.0,"tv":0.0,"id":47651809}]}]}
{"op":"mcm","clk":"11766184397","pt":1722601299234,"mc":[{"id":"1.231345087","rc":[{"batb":[[0,1.05,25000],[1,1.04,25050],[2,1.03,25200]],"ltp":0.0,"tv":0.0,"id":47651809}]}]}
{"op":"mcm","clk":"11766184423","pt":1722601299856,"mc":[{"id":"1.231345087","rc":[{"batb":[[0,1.04,25050],[1,1.03,25200],[2,1.02,25200]],"ltp":0.0,"tv":0.0,"id":47651809}]}]}
{"op":"mcm","clk":"11767015313","pt":1722615960380,"mc":[{"id":"1.231345087","rc":[{"batb":[[2,1.02,25296.12]],"ltp":0.0,"tv":0.0,"id":40096589},{"batb":[[2,1.02,25296.12]],"ltp":0.0,"tv":0.0,"id":47651809}]}]}
{"op":"mcm","clk":"11767248489","pt":1722617562419,"mc":[{"id":"1.231345087","rc":[{"batb":[[0,1.25,100],[1,1.04,25050],[2,1.03,25200]],"ltp":0.0,"tv":0.0,"id":47651809}]}]}
{"op":"mcm","clk":"11767248518","pt":1722617562628,"mc":[{"id":"1.231345087","rc":[{"batb":[[0,1.25,100],[1,1.04,25050],[2,1.03,25200]],"ltp":0.0,"tv":0.0,"id":40096589}]}]}
{"op":"mcm","clk":"11767524639","pt":1722619396582,"mc":[{"id":"1.231345087","rc":[{"batl":[[0,4,0.78]],"ltp":0.0,"tv":0.0,"id":40096589},{"batl":[[0,4,0.78]],"ltp":0.0,"tv":0.0,"id":47651809}]}]}
{"op":"mcm","clk":"11767526000","pt":1722619404974,"mc":[{"id":"1.231345087","rc":[{"batl":[[0,5,1.56]],"ltp":0.0,"tv":0.0,"id":40096589},{"batl":[[0,5,1.56]],"ltp":0.0,"tv":0.0,"id":47651809}]}]}
{"op":"mcm","clk":"11767527161","pt":1722619412510,"mc":[{"id":"1.231345087","rc":[{"batl":[[1,6,0.78]],"ltp":0.0,"tv":0.0,"id":40096589},{"batl":[[1,6,0.78]],"ltp":0.0,"tv":0.0,"id":47651809}]}]}
{"op":"mcm","clk":"11767532216","pt":1722619446311,"mc":[{"id":"1.231345087","rc":[{"batb":[[2,1.03,25200.78]],"ltp":0.0,"tv":0.0,"id":40096589},{"batb":[[2,1.03,25200.78]],"ltp":0.0,"tv":0.0,"id":47651809}]}]}
{"op":"mcm","clk":"11767534345","pt":1722619459450,"mc":[{"id":"1.231345087","rc":[{"batb":[[1,1.04,25050.78]],"ltp":0.0,"tv":0.0,"id":40096589},{"batb":[[1,1.04,25050.78]],"ltp":0.0,"tv":0.0,"id":47651809}]}]}
{"op":"mcm","clk":"11767537162","pt":1722619478652,"mc":[{"id":"1.231345087","rc":[{"batb":[[1,1.04,25051.56]],"ltp":0.0,"tv":0.0,"id":40096589},{"batb":[[1,1.04,25051.56]],"ltp":0.0,"tv":0.0,"id":47651809}]}]}
{"op":"mcm","clk":"11768649514","pt":1722626257664,"mc":[{"id":"1.231345087","rc":[{"batb":[[0,1.34,25.19],[1,1.25,100],[2,1.04,25051.56]],"batl":[[0,5,1.56]],"ltp":0.0,"tv":0.0,"id":40096589},{"batb":[[0,1.34,25.19],[1,1.25,100],[2,1.04,25051.56]],"batl":[[0,5,1.56]],"ltp":0.0,"tv":0.0,"id":47651809}]}]}
{"op":"mcm","clk":"11768760743","pt":1722627040204,"mc":[{"id":"1.231345087","rc":[{"batb":[[0,1.35,7.29],[1,1.34,25.19],[2,1.25,100]],"ltp":0.0,"tv":0.0,"id":40096589},{"batb":[[0,1.35,5.87],[1,1.34,25.19],[2,1.25,100]],"ltp":0.0,"tv":0.0,"id":47651809}]}]}
{"op":"mcm","clk":"11768897976","pt":1722628058863,"mc":[{"id":"1.231345087","rc":[{"batb":[[1,1.25,100],[2,1.04,25051.56]],"ltp":0.0,"tv":0.0,"id":40096589},{"batb":[[1,1.25,100],[2,1.04,25051.56]],"ltp":0.0,"tv":0.0,"id":47651809}]}]}
{"op":"mcm","clk":"11768900630","pt":1722628082736,"mc":[{"id":"1.231345087","rc":[{"batb":[[0,1.36,23.79],[1,1.35,7.29],[2,1.25,100]],"ltp":0.0,"tv":0.0,"id":40096589},{"batb":[[0,1.36,23.79],[1,1.35,5.87],[2,1.25,100]],"ltp":0.0,"tv":0.0,"id":47651809}]}]}
{"op":"mcm","clk":"11768990964","pt":1722628994159,"mc":[{"id":"1.231345087","rc":[{"batb":[[0,1.36,23.79],[1,1.26,7.28]],"ltp":0.0,"tv":0.0,"id":40096589},{"batb":[[0,1.36,23.79],[1,1.26,5.87]],"ltp":0.0,"tv":0.0,"id":47651809}]}]}
{"op":"mcm","clk":"11769072227","pt":1722629883144,"mc":[{"id":"1.231345087","rc":[{"batb":[[0,1.26,7.28],[1,1.25,100],[2,1.04,25051.56]],"ltp":0.0,"tv":0.0,"id":40096589},{"batb":[[0,1.26,5.87],[1,1.25,100],[2,1.04,25051.56]],"ltp":0.0,"tv":0.0,"id":47651809}]}]}
{"op":"mcm","clk":"11769076734","pt":1722629954543,"mc":[{"id":"1.231345087","rc":[{"batb":[[0,1.34,10],[1,1.26,7.28],[2,1.25,100]],"ltp":0.0,"tv":0.0,"id":40096589},{"batb":[[0,1.34,10],[1,1.26,5.87],[2,1.25,100]],"ltp":0.0,"tv":0.0,"id":47651809}]}]}
{"op":"mcm","clk":"11769083528","pt":1722630052551,"mc":[{"id":"1.231345087","rc":[{"batb":[[0,1.35,24.47],[1,1.34,10],[2,1.26,7.28]],"ltp":0.0,"tv":0.0,"id":40096589},{"batb":[[0,1.35,24.47],[1,1.34,10],[2,1.26,5.87]],"ltp":0.0,"tv":0.0,"id":47651809}]}]}
{"op":"mcm","clk":"11769120155","pt":1722630579371,"mc":[{"id":"1.231345087","rc":[{"batb":[[0,1.36,10],[1,1.35,24.47]],"ltp":0.0,"tv":0.0,"id":40096589},{"batb":[[0,1.36,10],[1,1.35,24.47]],"ltp":0.0,"tv":0.0,"id":47651809}]}]}
{"op":"mcm","clk":"11769155624","pt":1722631226355,"mc":[{"id":"1.231345087","rc":[{"batl":[[0,1.39,1.01],[1,5,1.56],[2,6,0.78]],"ltp":0.0,"tv":0.0,"id":40096589}]}]}
{"op":"mcm","clk":"11769156075","pt":1722631236131,"mc":[{"id":"1.231345087","rc":[{"batl":[[0,5,1.56],[1,6,0.78],[2,6,0]],"ltp":0.0,"tv":0.0,"id":40096589}]}]}
{"op":"mcm","clk":"11769182127","pt":1722631853731,"mc":[{"id":"1.231345087","rc":[{"batb":[[1,1.26,7.28],[2,1.25,100]],"ltp":0.0,"tv":0.0,"id":40096589},{"batb":[[1,1.26,5.87],[2,1.25,100]],"ltp":0.0,"tv":0.0,"id":47651809}]}]}
{"op":"mcm","clk":"11769183497","pt":1722631910482,"mc":[{"id":"1.231345087","rc":[{"batl":[[0,1.4,1.01],[1,5,1.56],[2,6,0.78]],"ltp":0.0,"tv":0.0,"id":47651809}]}]}
{"op":"mcm","clk":"11769183761","pt":1722631920297,"mc":[{"id":"1.231345087","rc":[{"batl":[[0,5,1.56],[1,6,0.78],[2,6,0]],"ltp":0.0,"tv":0.0,"id":47651809}]}]}
{"op":"mcm","clk":"11769185053","pt":1722631973874,"mc":[{"id":"1.231345087","rc":[{"batb":[[0,1.37,23.14],[1,1.36,10],[2,1.26,7.28]],"ltp":0.0,"tv":0.0,"id":40096589},{"batb":[[0,1.37,23.14],[1,1.36,10],[2,1.26,5.87]],"ltp":0.0,"tv":0.0,"id":47651809}]}]}
{"op":"mcm","clk":"11769185354","pt":1722631987962,"mc":[{"id":"1.231345087","rc":[{"batb":[[2,1.25,100]],"ltp":0.0,"tv":0.0,"id":40096589},{"batb":[[2,1.25,100]],"ltp":0.0,"tv":0.0,"id":47651809}]}]}
{"op":"mcm","clk":"11769222480","pt":1722633174932,"mc":[{"id":"1.231345087","rc":[{"batb":[[0,1.37,23.15]],"ltp":0.0,"tv":0.0,"id":40096589},{"batb":[[0,1.37,23.15]],"ltp":0.0,"tv":0.0,"id":47651809}]}]}
{"op":"mcm","clk":"11769247141","pt":1722633782220,"mc":[{"id":"1.231345087","rc":[{"batb":[[0,1.36,10],[1,1.25,100],[2,1.04,25051.56]],"ltp":0.0,"tv":0.0,"id":40096589},{"batb":[[0,1.36,10],[1,1.25,100],[2,1.04,25051.56]],"ltp":0.0,"tv":0.0,"id":47651809}]}]}
{"op":"mcm","clk":"11769250022","pt":1722633852528,"mc":[{"id":"1.231345087","rc":[{"batb":[[0,1.37,23.15],[1,1.36,10],[2,1.25,100]],"ltp":0.0,"tv":0.0,"id":40096589},{"batb":[[0,1.37,23.15],[1,1.36,10],[2,1.25,100]],"ltp":0.0,"tv":0.0,"id":47651809}]}]}
{"op":"mcm","clk":"11769304100","pt":1722635652996,"mc":[{"id":"1.231345087","rc":[{"batb":[[0,1.36,10],[1,1.25,100],[2,1.04,25051.56]],"ltp":0.0,"tv":0.0,"id":40096589},{"batb":[[0,1.36,10],[1,1.25,100],[2,1.04,25051.56]],"ltp":0.0,"tv":0.0,"id":47651809}]}]}
{"op":"mcm","clk":"11769306210","pt":1722635717260,"mc":[{"id":"1.231345087","rc":[{"batb":[[0,1.37,23.15],[1,1.36,10],[2,1.25,100]],"ltp":0.0,"tv":0.0,"id":40096589},{"batb":[[0,1.37,23.15],[1,1.36,10],[2,1.25,100]],"ltp":0.0,"tv":0.0,"id":47651809}]}]}
{"op":"mcm","clk":"11769356265","pt":1722637518036,"mc":[{"id":"1.231345087","rc":[{"batb":[[0,1.36,10],[1,1.25,100],[2,1.04,25051.56]],"ltp":0.0,"tv":0.0,"id":40096589},{"batb":[[0,1.36,10],[1,1.25,100],[2,1.04,25051.56]],"ltp":0.0,"tv":0.0,"id":47651809}]}]}
{"op":"mcm","clk":"11769357623","pt":1722637576586,"mc":[{"id":"1.231345087","rc":[{"batb":[[0,1.37,23.15],[1,1.36,10],[2,1.25,100]],"ltp":0.0,"tv":0.0,"id":40096589},{"batb":[[0,1.37,23.15],[1,1.36,10],[2,1.25,100]],"ltp":0.0,"tv":0.0,"id":47651809}]}]}
{"op":"mcm","clk":"11769434539","pt":1722639376783,"mc":[{"id":"1.231345087","rc":[{"batb":[[0,1.36,10],[1,1.25,100],[2,1.04,25051.56]],"ltp":0.0,"tv":0.0,"id":40096589},{"batb":[[0,1.36,10],[1,1.25,100],[2,1.04,25051.56]],"ltp":0.0,"tv":0.0,"id":47651809}]}]}
{"op":"mcm","clk":"11769436875","pt":1722639429072,"mc":[{"id":"1.231345087","rc":[{"batb":[[0,1.37,23.15],[1,1.36,10],[2,1.25,100]],"ltp":0.0,"tv":0.0,"id":40096589},{"batb":[[0,1.37,23.15],[1,1.36,10],[2,1.25,100]],"ltp":0.0,"tv":0.0,"id":47651809}]}]}
{"op":"mcm","clk":"11769515074","pt":1722641229416,"mc":[{"id":"1.231345087","rc":[{"batb":[[0,1.36,10],[1,1.25,100],[2,1.04,25051.56]],"ltp":0.0,"tv":0.0,"id":40096589},{"batb":[[0,1.36,10],[1,1.25,100],[2,1.04,25051.56]],"ltp":0.0,"tv":0.0,"id":47651809}]}]}
{"op":"mcm","clk":"11769516861","pt":1722641277089,"mc":[{"id":"1.231345087","rc":[{"batb":[[0,1.37,23.15],[1,1.36,10],[2,1.25,100]],"ltp":0.0,"tv":0.0,"id":40096589},{"batb":[[0,1.37,23.15],[1,1.36,10],[2,1.25,100]],"ltp":0.0,"tv":0.0,"id":47651809}]}]}
{"op":"mcm","clk":"11769599095","pt":1722643077348,"mc":[{"id":"1.231345087","rc":[{"batb":[[0,1.36,10],[1,1.25,100],[2,1.04,25051.56]],"ltp":0.0,"tv":0.0,"id":47651809}]}]}
{"op":"mcm","clk":"11769599110","pt":1722643077554,"mc":[{"id":"1.231345087","rc":[{"batb":[[0,1.36,10],[1,1.25,100],[2,1.04,25051.56]],"ltp":0.0,"tv":0.0,"id":40096589}]}]}
{"op":"mcm","clk":"11769600967","pt":1722643115887,"mc":[{"id":"1.231345087","rc":[{"batb":[[0,1.37,23.15],[1,1.36,10],[2,1.25,100]],"ltp":0.0,"tv":0.0,"id":40096589},{"batb":[[0,1.37,23.15],[1,1.36,10],[2,1.25,100]],"ltp":0.0,"tv":0.0,"id":47651809}]}]}
{"op":"mcm","clk":"11769720210","pt":1722644916298,"mc":[{"id":"1.231345087","rc":[{"batb":[[0,1.36,10],[1,1.25,100],[2,1.04,25051.56]],"ltp":0.0,"tv":0.0,"id":40096589},{"batb":[[0,1.36,10],[1,1.25,100],[2,1.04,25051.56]],"ltp":0.0,"tv":0.0,"id":47651809}]}]}
{"op":"mcm","clk":"11769721787","pt":1722644941545,"mc":[{"id":"1.231345087","rc":[{"batb":[[0,1.37,23.15],[1,1.36,10],[2,1.25,100]],"ltp":0.0,"tv":0.0,"id":40096589},{"batb":[[0,1.37,23.15],[1,1.36,10],[2,1.25,100]],"ltp":0.0,"tv":0.0,"id":47651809}]}]}
{"op":"mcm","clk":"11769838171","pt":1722646741932,"mc":[{"id":"1.231345087","rc":[{"batb":[[0,1.36,10],[1,1.25,100],[2,1.04,25051.56]],"ltp":0.0,"tv":0.0,"id":40096589},{"batb":[[0,1.36,10],[1,1.25,100],[2,1.04,25051.56]],"ltp":0.0,"tv":0.0,"id":47651809}]}]}
{"op":"mcm","clk":"11769839227","pt":1722646755339,"mc":[{"id":"1.231345087","rc":[{"batb":[[0,1.37,23.15],[1,1.36,10],[2,1.25,100]],"ltp":0.0,"tv":0.0,"id":40096589},{"batb":[[0,1.37,23.15],[1,1.36,10],[2,1.25,100]],"ltp":0.0,"tv":0.0,"id":47651809}]}]}
{"op":"mcm","clk":"11769984265","pt":1722648555729,"mc":[{"id":"1.231345087","rc":[{"batb":[[0,1.36,10],[1,1.25,100],[2,1.04,25051.56]],"ltp":0.0,"tv":0.0,"id":40096589},{"batb":[[0,1.36,10],[1,1.25,100],[2,1.04,25051.56]],"ltp":0.0,"tv":0.0,"id":47651809}]}]}
{"op":"mcm","clk":"11769985105","pt":1722648566100,"mc":[{"id":"1.231345087","rc":[{"batb":[[0,1.37,23.15],[1,1.36,10],[2,1.25,100]],"ltp":0.0,"tv":0.0,"id":40096589},{"batb":[[0,1.37,23.15],[1,1.36,10],[2,1.25,100]],"ltp":0.0,"tv":0.0,"id":47651809}]}]}
{"op":"mcm","clk":"11770034200","pt":1722649158948,"mc":[{"id":"1.231345087","rc":[{"batb":[[0,1.37,24.06]],"ltp":0.0,"tv":0.0,"id":40096589}]}]}
{"op":"mcm","clk":"11770034922","pt":1722649167974,"mc":[{"id":"1.231345087","rc":[{"batb":[[0,1.37,24.06]],"ltp":0.0,"tv":0.0,"id":47651809}]}]}
{"op":"mcm","clk":"11770133579","pt":1722650366276,"mc":[{"id":"1.231345087","rc":[{"batb":[[0,1.36,10.91],[1,1.25,100],[2,1.04,25051.56]],"ltp":0.0,"tv":0.0,"id":47651809}]}]}
{"op":"mcm","clk":"11770133590","pt":1722650366479,"mc":[{"id":"1.231345087","rc":[{"batb":[[0,1.36,10.91],[1,1.25,100],[2,1.04,25051.56]],"ltp":0.0,"tv":0.0,"id":40096589}]}]}
{"op":"mcm","clk":"11770133918","pt":1722650371982,"mc":[{"id":"1.231345087","rc":[{"batb":[[0,1.37,24.06],[1,1.36,10],[2,1.25,100]],"ltp":0.0,"tv":0.0,"id":40096589},{"batb":[[0,1.37,24.06],[1,1.36,10],[2,1.25,100]],"ltp":0.0,"tv":0.0,"id":47651809}]}]}
{"op":"mcm","clk":"11770271467","pt":1722652177346,"mc":[{"id":"1.231345087","rc":[{"batb":[[0,1.36,10.91],[1,1.25,100],[2,1.04,25051.56]],"ltp":0.0,"tv":0.0,"id":47651809}]}]}
{"op":"mcm","clk":"11770271481","pt":1722652177552,"mc":[{"id":"1.231345087","rc":[{"batb":[[0,1.36,10.91],[1,1.25,100],[2,1.04,25051.56]],"ltp":0.0,"tv":0.0,"id":40096589}]}]}
{"op":"mcm","clk":"11770282559","pt":1722652326041,"mc":[{"id":"1.231345087","rc":[{"batb":[[0,1.37,24.06],[1,1.36,10],[2,1.25,100]],"ltp":0.0,"tv":0.0,"id":40096589},{"batb":[[0,1.37,24.06],[1,1.36,10],[2,1.25,100]],"ltp":0.0,"tv":0.0,"id":47651809}]}]}
{"op":"mcm","clk":"11770409895","pt":1722654126899,"mc":[{"id":"1.231345087","rc":[{"batb":[[0,1.36,10.91],[1,1.25,100],[2,1.04,25051.56]],"ltp":0.0,"tv":0.0,"id":40096589},{"batb":[[0,1.36,10.91],[1,1.25,100],[2,1.04,25051.56]],"ltp":0.0,"tv":0.0,"id":47651809}]}]}
{"op":"mcm","clk":"11770418471","pt":1722654271161,"mc":[{"id":"1.231345087","rc":[{"batb":[[0,1.37,24.06],[1,1.36,10],[2,1.25,100]],"ltp":0.0,"tv":0.0,"id":40096589},{"batb":[[0,1.37,24.06],[1,1.36,10],[2,1.25,100]],"ltp":0.0,"tv":0.0,"id":47651809}]}]}
{"op":"mcm","clk":"11770488693","pt":1722655301002,"mc":[{"id":"1.231345087","rc":[{"batb":[[0,1.4,1.46],[1,1.37,23.15],[2,1.36,10]],"ltp":0.0,"tv":0.0,"id":40096589}]}]}
{"op":"mcm","clk":"11770489228","pt":1722655310926,"mc":[{"id":"1.231345087","rc":[{"batb":[[0,1.4,1.46],[1,1.37,23.15],[2,1.36,10]],"ltp":0.0,"tv":0.0,"id":47651809}]}]}
{"op":"mcm","clk":"11770525053","pt":1722656071656,"mc":[{"id":"1.231345087","rc":[{"batb":[[1,1.36,10],[2,1.25,100]],"ltp":0.0,"tv":0.0,"id":40096589},{"batb":[[1,1.36,10],[2,1.25,100]],"ltp":0.0,"tv":0.0,"id":47651809}]}]}
{"op":"mcm","clk":"11770530826","pt":1722656198054,"mc":[{"id":"1.231345087","rc":[{"batb":[[1,1.37,23.15],[2,1.36,10]],"ltp":0.0,"tv":0.0,"id":40096589},{"batb":[[1,1.37,23.15],[2,1.36,10]],"ltp":0.0,"tv":0.0,"id":47651809}]}]}
{"op":"mcm","clk":"11770618152","pt":1722657998248,"mc":[{"id":"1.231345087","rc":[{"batb":[[1,1.36,10],[2,1.25,100]],"ltp":0.0,"tv":0.0,"id":40096589}]}]}
{"op":"mcm","clk":"11770618165","pt":1722657998457,"mc":[{"id":"1.231345087","rc":[{"batb":[[1,1.36,10],[2,1.25,100]],"ltp":0.0,"tv":0.0,"id":47651809}]}]}
{"op":"mcm","clk":"11770625390","pt":1722658122452,"mc":[{"id":"1.231345087","rc":[{"batb":[[1,1.37,23.15],[2,1.36,10]],"ltp":0.0,"tv":0.0,"id":40096589},{"batb":[[1,1.37,23.15],[2,1.36,10]],"ltp":0.0,"tv":0.0,"id":47651809}]}]}
{"op":"mcm","clk":"11770708376","pt":1722659923282,"mc":[{"id":"1.231345087","rc":[{"batb":[[1,1.36,10],[2,1.25,100]],"ltp":0.0,"tv":0.0,"id":40096589},{"batb":[[1,1.36,10],[2,1.25,100]],"ltp":0.0,"tv":0.0,"id":47651809}]}]}
{"op":"mcm","clk":"11770712837","pt":1722660033477,"mc":[{"id":"1.231345087","rc":[{"batb":[[1,1.37,23.15],[2,1.36,10]],"ltp":0.0,"tv":0.0,"id":40096589},{"batb":[[1,1.37,23.15],[2,1.36,10]],"ltp":0.0,"tv":0.0,"id":47651809}]}]}
{"op":"mcm","clk":"11770803774","pt":1722661833884,"mc":[{"id":"1.231345087","rc":[{"batb":[[1,1.36,10],[2,1.25,100]],"ltp":0.0,"tv":0.0,"id":40096589},{"batb":[[1,1.36,10],[2,1.25,100]],"ltp":0.0,"tv":0.0,"id":47651809}]}]}
{"op":"mcm","clk":"11770807809","pt":1722661934281,"mc":[{"id":"1.231345087","rc":[{"batb":[[1,1.37,23.15],[2,1.36,10]],"ltp":0.0,"tv":0.0,"id":40096589},{"batb":[[1,1.37,23.15],[2,1.36,10]],"ltp":0.0,"tv":0.0,"id":47651809}]}]}
{"op":"mcm","clk":"11770833397","pt":1722662582013,"mc":[{"id":"1.231345087","rc":[{"batb":[[0,1.41,15.55],[1,1.37,24.06]],"ltp":0.0,"tv":0.0,"id":40096589},{"batb":[[0,1.42,17.55],[1,1.37,24.06]],"ltp":0.0,"tv":0.0,"id":47651809}]}]}
{"op":"mcm","clk":"11770886577","pt":1722663734702,"mc":[{"id":"1.231345087","rc":[{"batb":[[1,1.36,10.91],[2,1.25,100]],"ltp":0.0,"tv":0.0,"id":40096589},{"batb":[[1,1.36,10.91],[2,1.25,100]],"ltp":0.0,"tv":0.0,"id":47651809}]}]}
{"op":"mcm","clk":"11770892202","pt":1722663834928,"mc":[{"id":"1.231345087","rc":[{"batb":[[0,1.42,20.94],[1,1.41,15],[2,1.36,10.91]],"ltp":0.0,"tv":0.0,"id":40096589},{"batb":[[0,1.43,20.47],[1,1.42,17],[2,1.36,10.91]],"ltp":0.0,"tv":0.0,"id":47651809}]}]}
{"op":"mcm","clk":"11770984131","pt":1722665635313,"mc":[{"id":"1.231345087","rc":[{"batb":[[0,1.41,15.55],[1,1.36,10.91],[2,1.25,100]],"ltp":0.0,"tv":0.0,"id":40096589},{"batb":[[0,1.42,17.55],[1,1.36,10.91],[2,1.25,100]],"ltp":0.0,"tv":0.0,"id":47651809}]}]}
{"op":"mcm","clk":"11770989160","pt":1722665737354,"mc":[{"id":"1.231345087","rc":[{"batb":[[0,1.42,20.94],[1,1.41,15],[2,1.36,10.91]],"ltp":0.0,"tv":0.0,"id":40096589},{"batb":[[0,1.43,20.47],[1,1.42,17],[2,1.36,10.91]],"ltp":0.0,"tv":0.0,"id":47651809}]}]}
{"op":"mcm","clk":"11771067748","pt":1722667537837,"mc":[{"id":"1.231345087","rc":[{"batb":[[0,1.41,15.55],[1,1.36,10.91],[2,1.25,100]],"ltp":0.0,"tv":0.0,"id":40096589},{"batb":[[0,1.42,17.55],[1,1.36,10.91],[2,1.25,100]],"ltp":0.0,"tv":0.0,"id":47651809}]}]}
{"op":"mcm","clk":"11771072879","pt":1722667637662,"mc":[{"id":"1.231345087","rc":[{"batb":[[0,1.42,20.94],[1,1.41,15],[2,1.36,10.91]],"ltp":0.0,"tv":0.0,"id":40096589},{"batb":[[0,1.43,20.47],[1,1.42,17],[2,1.36,10.91]],"ltp":0.0,"tv":0.0,"id":47651809}]}]}
{"op":"mcm","clk":"11771085005","pt":1722667926191,"mc":[{"id":"1.231345087","rc":[{"batb":[[0,1.42,20.94]],"ltp":0.0,"tv":0.0,"id":40096589}]}]}
{"op":"mcm","clk":"11771085347","pt":1722667933371,"mc":[{"id":"1.231345087","rc":[{"batb":[[0,1.43,20.47]],"ltp":0.0,"tv":0.0,"id":47651809}]}]}
{"op":"mcm","clk":"11771145199","pt":1722669438068,"mc":[{"id":"1.231345087","rc":[{"batb":[[0,1.41,15.55],[1,1.36,10.91],[2,1.25,100]],"ltp":0.0,"tv":0.0,"id":40096589},{"batb":[[0,1.42,17.55],[1,1.36,10.91],[2,1.25,100]],"ltp":0.0,"tv":0.0,"id":47651809}]}]}
{"op":"mcm","clk":"11771148575","pt":1722669536720,"mc":[{"id":"1.231345087","rc":[{"batb":[[0,1.42,20.94],[1,1.41,15],[2,1.36,10.91]],"ltp":0.0,"tv":0.0,"id":40096589},{"batb":[[0,1.43,20.47],[1,1.42,17],[2,1.36,10.91]],"ltp":0.0,"tv":0.0,"id":47651809}]}]}
{"op":"mcm","clk":"11771251220","pt":1722671337125,"mc":[{"id":"1.231345087","rc":[{"batb":[[0,1.41,15.55],[1,1.36,10.91],[2,1.25,100]],"ltp":0.0,"tv":0.0,"id":40096589},{"batb":[[0,1.42,17.55],[1,1.36,10.91],[2,1.25,100]],"ltp":0.0,"tv":0.0,"id":47651809}]}]}
{"op":"mcm","clk":"11771256468","pt":1722671436372,"mc":[{"id":"1.231345087","rc":[{"batb":[[0,1.42,20.94],[1,1.41,15],[2,1.36,10.91]],"ltp":0.0,"tv":0.0,"id":40096589},{"batb":[[0,1.43,20.47],[1,1.42,17],[2,1.36,10.91]],"ltp":0.0,"tv":0.0,"id":47651809}]}]}
{"op":"mcm","clk":"11771309796","pt":1722672359354,"mc":[{"id":"1.231345087","rc":[{"batb":[[2,1.25,100.91]],"ltp":0.0,"tv":0.0,"id":40096589},{"batb":[[2,1.25,100.91]],"ltp":0.0,"tv":0.0,"id":47651809}]}]}
{"op":"mcm","clk":"11771309800","pt":1722672359458,"mc":[{"id":"1.231345087","rc":[{"batb":[[0,1.43,10.55],[1,1.42,20.39],[2,1.41,15]],"ltp":0.0,"tv":0.0,"id":40096589},{"batb":[[0,1.44,10.55],[1,1.43,19.92],[2,1.42,17]],"ltp":0.0,"tv":0.0,"id":47651809}]}]}
{"op":"mcm","clk":"11771365862","pt":1722673236799,"mc":[{"id":"1.231345087","rc":[{"batb":[[1,1.41,15],[2,1.25,100.91]],"ltp":0.0,"tv":0.0,"id":40096589},{"batb":[[1,1.42,17],[2,1.25,100.91]],"ltp":0.0,"tv":0.0,"id":47651809}]}]}
{"op":"mcm","clk":"11771372469","pt":1722673337091,"mc":[{"id":"1.231345087","rc":[{"batb":[[0,1.44,20.01],[1,1.43,10],[2,1.41,15]],"ltp":0.0,"tv":0.0,"id":40096589},{"batb":[[0,1.45,19.58],[1,1.44,10],[2,1.42,17]],"ltp":0.0,"tv":0.0,"id":47651809}]}]}
{"op":"mcm","clk":"11771416870","pt":1722674110812,"mc":[{"id":"1.231345087","marketDefinition":{"bspMarket":false,"turnInPlayEnabled":true,"persistenceEnabled":true,"marketBaseRate":5.0,"eventId":"33462721","eventTypeId":"4","numberOfWinners":1,"bettingType":"ODDS","marketType":"MATCH_ODDS","marketTime":"2024-08-04T13:30:00.000Z","suspendTime":"2024-08-04T13:30:00.000Z","bspReconciled":false,"complete":true,"inPlay":false,"crossMatching":true,"runnersVoidable":false,"numberOfActiveRunners":2,"betDelay":0,"status":"SUSPENDED","runners":[{"status":"ACTIVE","sortPriority":1,"id":40096589,"name":"Northern Superchargers Women"},{"status":"ACTIVE","sortPriority":2,"id":47651809,"name":"Manchester Original"}],"regulators":["MR_INT"],"countryCode":"GB","discountAllowed":true,"timezone":"GMT","openDate":"2024-08-04T13:30:00.000Z","version":6052816150,"name":"Match Odds","eventName":"Northern Superchargers Women v Manchester Original"}}]}
{"op":"mcm","clk":"11771433133","pt":1722674362369,"mc":[{"id":"1.231345087","marketDefinition":{"bspMarket":false,"turnInPlayEnabled":true,"persistenceEnabled":true,"marketBaseRate":5.0,"eventId":"33462721","eventTypeId":"4","numberOfWinners":1,"bettingType":"ODDS","marketType":"MATCH_ODDS","marketTime":"2024-08-04T13:30:00.000Z","suspendTime":"2024-08-04T13:30:00.000Z","bspReconciled":false,"complete":true,"inPlay":false,"crossMatching":false,"runnersVoidable":false,"numberOfActiveRunners":0,"betDelay":0,"status":"CLOSED","settledTime":"2024-08-03T08:39:21.000Z","runners":[{"status":"REMOVED","sortPriority":1,"removalDate":"2024-08-03T08:39:21.000Z","id":40096589,"name":"Northern Superchargers Women"},{"status":"REMOVED","sortPriority":2,"removalDate":"2024-08-03T08:39:21.000Z","id":47651809,"name":"Manchester Original"}],"regulators":["MR_INT"],"countryCode":"GB","discountAllowed":true,"timezone":"GMT","openDate":"2024-08-04T13:30:00.000Z","version":6052822456,"name":"Match Odds","eventName":"Northern Superchargers Women v Manchester Original"}}]}
