{"op":"mcm","clk":"11916444210","pt":1724078060551,"mc":[{"id":"1.232019003","marketDefinition":{"bspMarket":false,"turnInPlayEnabled":true,"persistenceEnabled":true,"marketBaseRate":5.0,"eventId":"33508295","eventTypeId":"4","numberOfWinners":1,"bettingType":"ODDS","marketType":"MATCH_ODDS","marketTime":"2024-08-20T20:30:00.000Z","suspendTime":"2024-08-20T20:30:00.000Z","bspReconciled":false,"complete":true,"inPlay":false,"crossMatching":true,"runnersVoidable":false,"numberOfActiveRunners":2,"betDelay":0,"status":"OPEN","runners":[{"status":"ACTIVE","sortPriority":1,"id":67083366,"name":"New York Strikers"},{"status":"ACTIVE","sortPriority":2,"id":72857116,"name":"Grand Cayman Stingrays"}],"regulators":["MR_INT"],"countryCode":"GB","discountAllowed":false,"timezone":"GMT","openDate":"2024-08-20T20:30:00.000Z","version":6086446669,"name":"Match Odds","eventName":"New York Strikers v Grand Cayman Stingrays"},"rc":[{"batb":[[0,1.01,20]],"ltp":0.0,"tv":0.0,"id":67083366},{"batb":[[0,1.01,20]],"ltp":0.0,"tv":0.0,"id":72857116}]}]}
{"op":"mcm","clk":"11916444228","pt":1724078060865,"mc":[{"id":"1.232019003","rc":[{"batb":[[0,1.03,200],[1,1.02,200],[2,1.01,220]],"ltp":0.0,"tv":0.0,"id":67083366},{"batb":[[0,1.03,200],[1,1.02,200],[2,1.01,220]],"ltp":0.0,"tv":0.0,"id":72857116}]}]}
{"op":"mcm","clk":"11916444293","pt":1724078061642,"mc":[{"id":"1.232019003","marketDefinition":{"bspMarket":false,"turnInPlayEnabled":true,"persistenceEnabled":true,"marketBaseRate":5.0,"eventId":"33508295","eventTypeId":"4","numberOfWinners":1,"bettingType":"ODDS","marketType":"MATCH_ODDS","marketTime":"2024-08-20T20:30:00.000Z","suspendTime":"2024-08-20T20:30:00.000Z","bspReconciled":false,"complete":true,"inPlay":false,"crossMatching":true,"runnersVoidable":false,"numberOfActiveRunners":2,"betDelay":0,"status":"OPEN","runners":[{"status":"ACTIVE","sortPriority":1,"id":67083366,"name":"New York Strikers"},{"status":"ACTIVE","sortPriority":2,"id":72857116,"name":"Grand Cayman Stingrays"}],"regulators":["MR_INT"],"countryCode":"GB","discountAllowed":true,"timezone":"GMT","openDate":"2024-08-20T20:30:00.000Z","version":6086446669,"name":"Match Odds","eventName":"New York Strikers v Grand Cayman Stingrays"}}]}
{"op":"mcm","clk":"11916730968","pt":1724081453455,"mc":[{"id":"1.232019003","rc":[{"batb":[[2,1.01,480.89]],"ltp":0.0,"tv":0.0,"id":67083366},{"batb":[[2,1.01,480.89]],"ltp":0.0,"tv":0.0,"id":72857116}]}]}
{"op":"mcm","clk":"11916793989","pt":1724082095166,"mc":[{"id":"1.232019003","rc":[{"batb":[[0,1.11,24.82],[1,1.03,200],[2,1.02,200]],"ltp":0.0,"tv":0.0,"id":67083366}]}]}
{"op":"mcm","clk":"11916795404","pt":1724082110592,"mc":[{"id":"1.232019003","rc":[{"batb":[[0,1.11,24.82],[1,1.03,200],[2,1.02,200]],"ltp":0.0,"tv":0.0,"id":72857116}]}]}
{"op":"mcm","clk":"11916815687","pt":1724082227414,"mc":[{"id":"1.232019003","rc":[{"batb":[[0,1.12,71.37],[1,1.11,24.82],[2,1.03,200]],"ltp":0.0,"tv":0.0,"id":67083366},{"batb":[[0,1.12,71.37],[1,1.11,24.82],[2,1.03,200]],"ltp":0.0,"tv":0.0,"id":72857116}]}]}
{"op":"mcm","clk":"11916882665","pt":1724082942293,"mc":[{"id":"1.232019003","rc":[{"batb":[[0,1.2,250],[1,1.12,71.37],[2,1.11,24.82]],"ltp":0.0,"tv":0.0,"id":67083366},{"batb":[[0,1.2,250],[1,1.12,71.37],[2,1.11,24.82]],"ltp":0.0,"tv":0.0,"id":72857116}]}]}
{"op":"mcm","clk":"11917017788","pt":1724084027946,"mc":[{"id":"1.232019003","rc":[{"batb":[[1,1.11,24.83],[2,1.03,200]],"ltp":0.0,"tv":0.0,"id":67083366},{"batb":[[1,1.11,24.83],[2,1.03,200]],"ltp":0.0,"tv":0.0,"id":72857116}]}]}
{"op":"mcm","clk":"11917021943","pt":1724084059392,"mc":[{"id":"1.232019003","rc":[{"batb":[[0,1.21,6.84],[1,1.2,250],[2,1.11,24.83]],"ltp":0.0,"tv":0.0,"id":67083366}]}]}
{"op":"mcm","clk":"11917021980","pt":1724084059698,"mc":[{"id":"1.232019003","rc":[{"batb":[[0,1.21,7.56],[1,1.2,250],[2,1.11,24.83]],"ltp":0.0,"tv":0.0,"id":72857116}]}]}
{"op":"mcm","clk":"11917024939","pt":1724084082689,"mc":[{"id":"1.232019003","rc":[{"batb":[[0,1.22,38.96],[1,1.21,6.84],[2,1.2,250]],"ltp":0.0,"tv":0.0,"id":67083366},{"batb":[[0,1.22,38.96],[1,1.21,7.56],[2,1.2,250]],"ltp":0.0,"tv":0.0,"id":72857116}]}]}
{"op":"mcm","clk":"11917268028","pt":1724085883130,"mc":[{"id":"1.232019003","rc":[{"batb":[[0,1.21,6.84],[1,1.2,250],[2,1.11,24.83]],"ltp":0.0,"tv":0.0,"id":67083366},{"batb":[[0,1.21,7.56],[1,1.2,250],[2,1.11,24.83]],"ltp":0.0,"tv":0.0,"id":72857116}]}]}
{"op":"mcm","clk":"11917273206","pt":1724085921807,"mc":[{"id":"1.232019003","rc":[{"batb":[[0,1.22,38.96],[1,1.21,6.84],[2,1.2,250]],"ltp":0.0,"tv":0.0,"id":67083366},{"batb":[[0,1.22,38.96],[1,1.21,7.56],[2,1.2,250]],"ltp":0.0,"tv":0.0,"id":72857116}]}]}
{"op":"mcm","clk":"11917371896","pt":1724086788577,"mc":[{"id":"1.232019003","rc":[{"batb":[[0,1.23,6.84],[1,1.22,38.96]],"ltp":0.0,"tv":0.0,"id":67083366},{"batb":[[1,1.2,250],[2,1.11,24.83]],"ltp":0.0,"tv":0.0,"id":72857116}]}]}
{"op":"mcm","clk":"11917371908","pt":1724086788681,"mc":[{"id":"1.232019003","rc":[{"batb":[[0,1.23,7.56],[1,1.22,38.96],[2,1.2,250]],"ltp":0.0,"tv":0.0,"id":72857116}]}]}
{"op":"mcm","clk":"11917490822","pt":1724087574928,"mc":[{"id":"1.232019003","rc":[{"batb":[[1,1.22,38.97]],"ltp":0.0,"tv":0.0,"id":67083366},{"batb":[[1,1.22,38.97]],"ltp":0.0,"tv":0.0,"id":72857116}]}]}
{"op":"mcm","clk":"11917515781","pt":1724087722177,"mc":[{"id":"1.232019003","rc":[{"batb":[[1,1.2,250],[2,1.11,24.84]],"ltp":0.0,"tv":0.0,"id":67083366},{"batb":[[1,1.2,250],[2,1.11,24.84]],"ltp":0.0,"tv":0.0,"id":72857116}]}]}
{"op":"mcm","clk":"11917518454","pt":1724087740883,"mc":[{"id":"1.232019003","rc":[{"batb":[[0,1.24,35.72],[1,1.23,6.84],[2,1.2,250]],"ltp":0.0,"tv":0.0,"id":67083366},{"batb":[[0,1.24,35.72],[1,1.23,7.56],[2,1.2,250]],"ltp":0.0,"tv":0.0,"id":72857116}]}]}
{"op":"mcm","clk":"11917773282","pt":1724089462422,"mc":[{"id":"1.232019003","rc":[{"batb":[[0,1.25,6.84],[1,1.24,35.72]],"ltp":0.0,"tv":0.0,"id":67083366}]}]}
{"op":"mcm","clk":"11917773363","pt":1724089462917,"mc":[{"id":"1.232019003","rc":[{"batb":[[0,1.25,7.56],[1,1.24,35.72]],"ltp":0.0,"tv":0.0,"id":72857116}]}]}
{"op":"mcm","clk":"11917785637","pt":1724089541175,"mc":[{"id":"1.232019003","rc":[{"batb":[[1,1.2,250],[2,1.11,24.84]],"ltp":0.0,"tv":0.0,"id":67083366},{"batb":[[1,1.2,250],[2,1.11,24.84]],"ltp":0.0,"tv":0.0,"id":72857116}]}]}
{"op":"mcm","clk":"11917807170","pt":1724089679823,"mc":[{"id":"1.232019003","rc":[{"batb":[[0,1.25,8.09]],"ltp":0.0,"tv":0.0,"id":72857116}]}]}
{"op":"mcm","clk":"11917808596","pt":1724089688478,"mc":[{"id":"1.232019003","rc":[{"batb":[[0,1.25,7.38]],"ltp":0.0,"tv":0.0,"id":67083366}]}]}
{"op":"mcm","clk":"11917810346","pt":1724089699588,"mc":[{"id":"1.232019003","rc":[{"batb":[[0,1.26,33.51],[1,1.25,6.84],[2,1.2,250]],"ltp":0.0,"tv":0.0,"id":67083366},{"batb":[[0,1.26,33.51],[1,1.25,7.56],[2,1.2,250]],"ltp":0.0,"tv":0.0,"id":72857116}]}]}
{"op":"mcm","clk":"11917858011","pt":1724090056430,"mc":[{"id":"1.232019003","rc":[{"batl":[[0,4,0.77]],"ltp":0.0,"tv":0.0,"id":67083366},{"batl":[[0,4,0.77]],"ltp":0.0,"tv":0.0,"id":72857116}]}]}
{"op":"mcm","clk":"11917859046","pt":1724090064714,"mc":[{"id":"1.232019003","rc":[{"batl":[[0,5,1.54]],"ltp":0.0,"tv":0.0,"id":67083366},{"batl":[[0,5,1.54]],"ltp":0.0,"tv":0.0,"id":72857116}]}]}
{"op":"mcm","clk":"11917860093","pt":1724090073691,"mc":[{"id":"1.232019003","rc":[{"batl":[[1,6,0.77]],"ltp":0.0,"tv":0.0,"id":67083366},{"batl":[[1,6,0.77]],"ltp":0.0,"tv":0.0,"id":72857116}]}]}
{"op":"mcm","clk":"11917861340","pt":1724090082422,"mc":[{"id":"1.232019003","rc":[{"batl":[[1,9,1.54]],"ltp":0.0,"tv":0.0,"id":67083366},{"batl":[[1,9,1.54]],"ltp":0.0,"tv":0.0,"id":72857116}]}]}
{"op":"mcm","clk":"11918024799","pt":1724091278474,"mc":[{"id":"1.232019003","rc":[{"batb":[[0,1.26,33.5],[1,1.25,6.84]],"ltp":0.0,"tv":0.0,"id":67083366},{"batb":[[0,1.26,32.96],[1,1.25,7.55]],"ltp":0.0,"tv":0.0,"id":72857116}]}]}
{"op":"mcm","clk":"11918025223","pt":1724091281604,"mc":[{"id":"1.232019003","rc":[{"batb":[[0,1.26,32.96]],"ltp":0.0,"tv":0.0,"id":67083366}]}]}
{"op":"mcm","clk":"11918058748","pt":1724091500001,"mc":[{"id":"1.232019003","rc":[{"batb":[[0,1.25,6.84],[1,1.2,250],[2,1.11,24.84]],"ltp":0.0,"tv":0.0,"id":67083366},{"batb":[[0,1.25,7.55],[1,1.2,250],[2,1.11,24.84]],"ltp":0.0,"tv":0.0,"id":72857116}]}]}
{"op":"mcm","clk":"11918078963","pt":1724091627763,"mc":[{"id":"1.232019003","rc":[{"batb":[[0,1.34,25.2],[1,1.25,6.84],[2,1.2,250]],"ltp":0.0,"tv":0.0,"id":67083366},{"batb":[[0,1.34,25.2],[1,1.25,7.55],[2,1.2,250]],"ltp":0.0,"tv":0.0,"id":72857116}]}]}
{"op":"mcm","clk":"11918130596","pt":1724091946509,"mc":[{"id":"1.232019003","rc":[{"batb":[[1,1.2,250],[2,1.11,24.84]],"ltp":0.0,"tv":0.0,"id":67083366}]}]}
{"op":"mcm","clk":"11918130638","pt":1724091946820,"mc":[{"id":"1.232019003","rc":[{"batb":[[1,1.2,250],[2,1.11,24.84]],"ltp":0.0,"tv":0.0,"id":72857116}]}]}
{"op":"mcm","clk":"11918273430","pt":1724092821109,"mc":[{"id":"1.232019003","rc":[{"batb":[[1,1.11,24.84],[2,1.03,200]],"ltp":0.0,"tv":0.0,"id":67083366},{"batb":[[1,1.11,24.84],[2,1.03,200]],"ltp":0.0,"tv":0.0,"id":72857116}]}]}
{"op":"mcm","clk":"11918323619","pt":1724093060588,"mc":[{"id":"1.232019003","rc":[{"batb":[[1,1.18,277.78],[2,1.13,384.62]],"ltp":0.0,"tv":0.0,"id":67083366},{"batb":[[1,1.18,277.78],[2,1.13,384.62]],"ltp":0.0,"tv":0.0,"id":72857116}]}]}
{"op":"mcm","clk":"11918323712","pt":1724093061109,"mc":[{"id":"1.232019003","rc":[{"batb":[[0,1.43,116.28],[1,1.38,131.58],[2,1.34,25.2]],"ltp":0.0,"tv":0.0,"id":67083366},{"batb":[[0,1.43,116.28],[1,1.38,131.58],[2,1.34,25.2]],"ltp":0.0,"tv":0.0,"id":72857116}]}]}
{"op":"mcm","clk":"11918385778","pt":1724093428040,"mc":[{"id":"1.232019003","rc":[{"batb":[[2,1.33,151.52]],"ltp":0.0,"tv":0.0,"id":67083366},{"batb":[[2,1.33,151.52]],"ltp":0.0,"tv":0.0,"id":72857116}]}]}
{"op":"mcm","clk":"11918400340","pt":1724093520929,"mc":[{"id":"1.232019003","rc":[{"batb":[[0,1.44,19.48],[1,1.43,116.28],[2,1.38,131.58]],"ltp":0.0,"tv":0.0,"id":67083366},{"batb":[[0,1.44,19.48],[1,1.43,116.28],[2,1.38,131.58]],"ltp":0.0,"tv":0.0,"id":72857116}]}]}
{"op":"mcm","clk":"11918526397","pt":1724094508591,"mc":[{"id":"1.232019003","rc":[{"batb":[[0,1.44,26.65]],"ltp":0.0,"tv":0.0,"id":67083366},{"batb":[[0,1.44,19.48]],"ltp":0.0,"tv":0.0,"id":72857116}]}]}
{"op":"mcm","clk":"11918526431","pt":1724094508899,"mc":[{"id":"1.232019003","rc":[{"batb":[[0,1.44,25.89]],"ltp":0.0,"tv":0.0,"id":72857116}]}]}
{"op":"mcm","clk":"11918640498","pt":1724095321217,"mc":[{"id":"1.232019003","rc":[{"batb":[[0,1.44,7.17]],"ltp":0.0,"tv":0.0,"id":67083366},{"batb":[[0,1.44,6.4]],"ltp":0.0,"tv":0.0,"id":72857116}]}]}
{"op":"mcm","clk":"11918642827","pt":1724095337645,"mc":[{"id":"1.232019003","rc":[{"batb":[[0,1.44,13.23]],"ltp":0.0,"tv":0.0,"id":67083366},{"batb":[[0,1.44,12.43]],"ltp":0.0,"tv":0.0,"id":72857116}]}]}
{"op":"mcm","clk":"11918647226","pt":1724095368071,"mc":[{"id":"1.232019003","rc":[{"batb":[[0,1.45,19.05],[1,1.44,13.23],[2,1.43,116.28]],"ltp":0.0,"tv":0.0,"id":67083366},{"batb":[[0,1.45,19.05],[1,1.44,12.43],[2,1.43,116.28]],"ltp":0.0,"tv":0.0,"id":72857116}]}]}
{"op":"mcm","clk":"11918647327","pt":1724095368747,"mc":[{"id":"1.232019003","rc":[{"batb":[[1,1.44,7.17]],"ltp":0.0,"tv":0.0,"id":67083366},{"batb":[[1,1.44,6.4]],"ltp":0.0,"tv":0.0,"id":72857116}]}]}
{"op":"mcm","clk":"11918902040","pt":1724097168486,"mc":[{"id":"1.232019003","rc":[{"batb":[[0,1.44,7.17],[1,1.43,116.28],[2,1.38,131.58]],"ltp":0.0,"tv":0.0,"id":67083366},{"batb":[[0,1.44,6.4],[1,1.43,116.28],[2,1.38,131.58]],"ltp":0.0,"tv":0.0,"id":72857116}]}]}
{"op":"mcm","clk":"11918903040","pt":1724097176084,"mc":[{"id":"1.232019003","rc":[{"batb":[[0,1.44,13.23]],"ltp":0.0,"tv":0.0,"id":67083366},{"batb":[[0,1.44,12.43]],"ltp":0.0,"tv":0.0,"id":72857116}]}]}
{"op":"mcm","clk":"11918913601","pt":1724097263197,"mc":[{"id":"1.232019003","rc":[{"batb":[[0,1.45,19.05],[1,1.44,13.23],[2,1.43,116.28]],"ltp":0.0,"tv":0.0,"id":67083366},{"batb":[[0,1.45,19.05],[1,1.44,12.43],[2,1.43,116.28]],"ltp":0.0,"tv":0.0,"id":72857116}]}]}
{"op":"mcm","clk":"11918913823","pt":1724097265113,"mc":[{"id":"1.232019003","rc":[{"batb":[[1,1.44,7.17]],"ltp":0.0,"tv":0.0,"id":67083366},{"batb":[[1,1.44,6.4]],"ltp":0.0,"tv":0.0,"id":72857116}]}]}
{"op":"mcm","clk":"11919007428","pt":1724098238749,"mc":[{"id":"1.232019003","rc":[{"batb":[[0,1.45,19.06],[1,1.44,7.17]],"ltp":0.0,"tv":0.0,"id":67083366},{"batb":[[0,1.45,19.06]],"batl":[[0,1.49,1.15],[1,5,1.54],[2,9,1.54]],"ltp":0.0,"tv":0.0,"id":72857116}]}]}
{"op":"mcm","clk":"11919007662","pt":1724098242063,"mc":[{"id":"1.232019003","rc":[{"batl":[[0,5,1.54],[1,9,1.54],[2,9,0]],"ltp":0.0,"tv":0.0,"id":72857116}]}]}
{"op":"mcm","clk":"11919091942","pt":1724099063446,"mc":[{"id":"1.232019003","rc":[{"batb":[[0,1.44,7.17],[1,1.43,116.28],[2,1.38,131.58]],"ltp":0.0,"tv":0.0,"id":67083366}]}]}
{"op":"mcm","clk":"11919091952","pt":1724099063650,"mc":[{"id":"1.232019003","rc":[{"batb":[[0,1.44,6.4],[1,1.43,116.28],[2,1.38,131.58]],"ltp":0.0,"tv":0.0,"id":72857116}]}]}
{"op":"mcm","clk":"11919092905","pt":1724099073987,"mc":[{"id":"1.232019003","rc":[{"batb":[[0,1.44,13.23]],"ltp":0.0,"tv":0.0,"id":67083366},{"batb":[[0,1.44,12.43]],"ltp":0.0,"tv":0.0,"id":72857116}]}]}
{"op":"mcm","clk":"11919097569","pt":1724099122030,"mc":[{"id":"1.232019003","rc":[{"batb":[[0,1.45,19.06],[1,1.44,13.23],[2,1.43,116.28]],"ltp":0.0,"tv":0.0,"id":67083366},{"batb":[[0,1.45,19.06],[1,1.44,12.43],[2,1.43,116.28]],"ltp":0.0,"tv":0.0,"id":72857116}]}]}
{"op":"mcm","clk":"11919097667","pt":1724099123142,"mc":[{"id":"1.232019003","rc":[{"batb":[[1,1.44,7.17]],"ltp":0.0,"tv":0.0,"id":67083366},{"batb":[[1,1.44,6.4]],"ltp":0.0,"tv":0.0,"id":72857116}]}]}
{"op":"mcm","clk":"11919236220","pt":1724100879217,"mc":[{"id":"1.232019003","rc":[{"batb":[[0,1.5,10],[1,1.45,19.06],[2,1.44,7.17]],"ltp":0.0,"tv":0.0,"id":67083366},{"batb":[[0,1.51,10],[1,1.45,19.06],[2,1.44,6.4]],"ltp":0.0,"tv":0.0,"id":72857116}]}]}
{"op":"mcm","clk":"11919239050","pt":1724100923255,"mc":[{"id":"1.232019003","rc":[{"batb":[[1,1.44,7.17],[2,1.43,116.28]],"ltp":0.0,"tv":0.0,"id":67083366},{"batb":[[1,1.44,6.4],[2,1.43,116.28]],"ltp":0.0,"tv":0.0,"id":72857116}]}]}
{"op":"mcm","clk":"11919240177","pt":1724100940162,"mc":[{"id":"1.232019003","rc":[{"batb":[[0,1.51,16.81],[1,1.5,10],[2,1.44,7.17]],"ltp":0.0,"tv":0.0,"id":67083366},{"batb":[[0,1.52,16.49],[1,1.51,10],[2,1.44,6.4]],"ltp":0.0,"tv":0.0,"id":72857116}]}]}
{"op":"mcm","clk":"11919322947","pt":1724102740577,"mc":[{"id":"1.232019003","rc":[{"batb":[[0,1.5,10],[1,1.44,7.17],[2,1.43,116.28]],"ltp":0.0,"tv":0.0,"id":67083366},{"batb":[[0,1.51,10],[1,1.44,6.4],[2,1.43,116.28]],"ltp":0.0,"tv":0.0,"id":72857116}]}]}
{"op":"mcm","clk":"11919328190","pt":1724102877911,"mc":[{"id":"1.232019003","rc":[{"batb":[[0,1.51,16.82],[1,1.5,10],[2,1.44,7.17]],"ltp":0.0,"tv":0.0,"id":67083366},{"batb":[[0,1.52,16.49],[1,1.51,10],[2,1.44,6.4]],"ltp":0.0,"tv":0.0,"id":72857116}]}]}
{"op":"mcm","clk":"11919404795","pt":1724104678229,"mc":[{"id":"1.232019003","rc":[{"batb":[[0,1.5,10],[1,1.44,7.17],[2,1.43,116.28]],"ltp":0.0,"tv":0.0,"id":67083366},{"batb":[[0,1.51,10],[1,1.44,6.4],[2,1.43,116.28]],"ltp":0.0,"tv":0.0,"id":72857116}]}]}
{"op":"mcm","clk":"11919409184","pt":1724104791936,"mc":[{"id":"1.232019003","rc":[{"batb":[[0,1.51,16.82],[1,1.5,10],[2,1.44,7.17]],"ltp":0.0,"tv":0.0,"id":67083366},{"batb":[[0,1.52,16.49],[1,1.51,10],[2,1.44,6.4]],"ltp":0.0,"tv":0.0,"id":72857116}]}]}
{"op":"mcm","clk":"11919490759","pt":1724106592395,"mc":[{"id":"1.232019003","rc":[{"batb":[[0,1.5,10],[1,1.44,7.17],[2,1.43,116.28]],"ltp":0.0,"tv":0.0,"id":67083366},{"batb":[[0,1.51,10],[1,1.44,6.41],[2,1.43,116.28]],"ltp":0.0,"tv":0.0,"id":72857116}]}]}
{"op":"mcm","clk":"11919494834","pt":1724106683782,"mc":[{"id":"1.232019003","rc":[{"batb":[[0,1.51,16.82],[1,1.5,10],[2,1.44,7.17]],"ltp":0.0,"tv":0.0,"id":67083366},{"batb":[[0,1.52,16.49],[1,1.51,10],[2,1.44,6.41]],"ltp":0.0,"tv":0.0,"id":72857116}]}]}
{"op":"mcm","clk":"11919591881","pt":1724108484271,"mc":[{"id":"1.232019003","rc":[{"batb":[[0,1.5,10],[1,1.44,7.17],[2,1.43,116.28]],"ltp":0.0,"tv":0.0,"id":67083366},{"batb":[[0,1.51,10],[1,1.44,6.41],[2,1.43,116.28]],"ltp":0.0,"tv":0.0,"id":72857116}]}]}
{"op":"mcm","clk":"11919595823","pt":1724108561530,"mc":[{"id":"1.232019003","rc":[{"batb":[[0,1.51,16.82],[1,1.5,10],[2,1.44,7.17]],"ltp":0.0,"tv":0.0,"id":67083366},{"batb":[[0,1.52,16.49],[1,1.51,10],[2,1.44,6.41]],"ltp":0.0,"tv":0.0,"id":72857116}]}]}
{"op":"mcm","clk":"11919696001","pt":1724110362009,"mc":[{"id":"1.232019003","rc":[{"batb":[[0,1.5,10],[1,1.44,7.17],[2,1.43,116.28]],"ltp":0.0,"tv":0.0,"id":67083366},{"batb":[[0,1.51,10],[1,1.44,6.41],[2,1.43,116.28]],"ltp":0.0,"tv":0.0,"id":72857116}]}]}
{"op":"mcm","clk":"11919699904","pt":1724110431754,"mc":[{"id":"1.232019003","rc":[{"batb":[[0,1.51,16.82],[1,1.5,10],[2,1.44,7.17]],"ltp":0.0,"tv":0.0,"id":67083366},{"batb":[[0,1.52,16.49],[1,1.51,10],[2,1.44,6.41]],"ltp":0.0,"tv":0.0,"id":72857116}]}]}
{"op":"mcm","clk":"11919799688","pt":1724112232139,"mc":[{"id":"1.232019003","rc":[{"batb":[[0,1.5,10],[1,1.44,7.17],[2,1.43,116.28]],"ltp":0.0,"tv":0.0,"id":67083366},{"batb":[[0,1.51,10],[1,1.44,6.4],[2,1.43,116.28]],"ltp":0.0,"tv":0.0,"id":72857116}]}]}
{"op":"mcm","clk":"11919802220","pt":1724112276292,"mc":[{"id":"1.232019003","rc":[{"batb":[[0,1.51,16.82],[1,1.5,10],[2,1.44,7.17]],"ltp":0.0,"tv":0.0,"id":67083366},{"batb":[[0,1.52,16.5],[1,1.51,10],[2,1.44,6.4]],"ltp":0.0,"tv":0.0,"id":72857116}]}]}
{"op":"mcm","clk":"11919895788","pt":1724114076493,"mc":[{"id":"1.232019003","rc":[{"batb":[[0,1.5,10],[1,1.44,7.17],[2,1.43,116.28]],"ltp":0.0,"tv":0.0,"id":67083366}]}]}
{"op":"mcm","clk":"11919895796","pt":1724114076699,"mc":[{"id":"1.232019003","rc":[{"batb":[[0,1.51,10],[1,1.44,6.4],[2,1.43,116.28]],"ltp":0.0,"tv":0.0,"id":72857116}]}]}
{"op":"mcm","clk":"11919897235","pt":1724114101802,"mc":[{"id":"1.232019003","rc":[{"batb":[[0,1.51,16.82],[1,1.5,10],[2,1.44,7.17]],"ltp":0.0,"tv":0.0,"id":67083366},{"batb":[[0,1.52,16.5],[1,1.51,10],[2,1.44,6.4]],"ltp":0.0,"tv":0.0,"id":72857116}]}]}
{"op":"mcm","clk":"11919992192","pt":1724115902235,"mc":[{"id":"1.232019003","rc":[{"batb":[[0,1.5,10],[1,1.44,7.17],[2,1.43,116.28]],"ltp":0.0,"tv":0.0,"id":67083366},{"batb":[[0,1.51,10],[1,1.44,6.4],[2,1.43,116.28]],"ltp":0.0,"tv":0.0,"id":72857116}]}]}
{"op":"mcm","clk":"11919992602","pt":1724115910235,"mc":[{"id":"1.232019003","rc":[{"batb":[[0,1.51,16.82],[1,1.5,10],[2,1.44,7.17]],"ltp":0.0,"tv":0.0,"id":67083366},{"batb":[[0,1.52,16.5],[1,1.51,10],[2,1.44,6.4]],"ltp":0.0,"tv":0.0,"id":72857116}]}]}
{"op":"mcm","clk":"11920059890","pt":1724117390486,"mc":[{"id":"1.232019003","rc":[{"batb":[[0,1.52,17.44]],"ltp":0.0,"tv":0.0,"id":72857116}]}]}
{"op":"mcm","clk":"11920060314","pt":1724117400485,"mc":[{"id":"1.232019003","rc":[{"batb":[[0,1.51,17.76]],"ltp":0.0,"tv":0.0,"id":67083366}]}]}
{"op":"mcm","clk":"11920076404","pt":1724117710616,"mc":[{"id":"1.232019003","rc":[{"batb":[[0,1.5,10.94],[1,1.44,7.17],[2,1.43,116.28]],"ltp":0.0,"tv":0.0,"id":67083366},{"batb":[[0,1.51,10.94],[1,1.44,6.4],[2,1.43,116.28]],"ltp":0.0,"tv":0.0,"id":72857116}]}]}
{"op":"mcm","clk":"11920081013","pt":1724117812178,"mc":[{"id":"1.232019003","rc":[{"batb":[[0,1.51,17.76],[1,1.5,10],[2,1.44,7.17]],"ltp":0.0,"tv":0.0,"id":67083366},{"batb":[[0,1.52,17.44],[1,1.51,10],[2,1.44,6.4]],"ltp":0.0,"tv":0.0,"id":72857116}]}]}
{"op":"mcm","clk":"11920173668","pt":1724119599428,"mc":[{"id":"1.232019003","rc":[{"batb":[[0,1.52,1.84],[1,1.51,16.82],[2,1.5,10]],"ltp":0.0,"tv":0.0,"id":67083366},{"batb":[[0,1.52,17.44],[2,1.44,6.41]],"ltp":0.0,"tv":0.0,"id":72857116}]}]}
{"op":"mcm","clk":"11920174216","pt":1724119609446,"mc":[{"id":"1.232019003","rc":[{"batb":[[0,1.53,1.84],[1,1.52,16.5],[2,1.51,10]],"ltp":0.0,"tv":0.0,"id":72857116}]}]}
{"op":"mcm","clk":"11920174388","pt":1724119612530,"mc":[{"id":"1.232019003","rc":[{"batb":[[1,1.5,10],[2,1.44,7.17]],"ltp":0.0,"tv":0.0,"id":67083366},{"batb":[[1,1.51,10],[2,1.44,6.41]],"ltp":0.0,"tv":0.0,"id":72857116}]}]}
{"op":"mcm","clk":"11920177920","pt":1724119688327,"mc":[{"id":"1.232019003","rc":[{"batb":[[0,1.53,17.13],[1,1.5,10.9]],"ltp":0.0,"tv":0.0,"id":67083366},{"batb":[[0,1.54,16.83],[1,1.51,10.9]],"ltp":0.0,"tv":0.0,"id":72857116}]}]}
{"op":"mcm","clk":"11920180922","pt":1724119771439,"mc":[{"id":"1.232019003","rc":[{"trd":[[1.62,0.18]],"batb":[[0,1.53,17.04]],"ltp":1.62,"tv":0.17,"id":67083366}],"tv":0.17}]}
{"op":"mcm","clk":"11920181008","pt":1724119773847,"mc":[{"id":"1.232019003","rc":[{"trd":[[1.62,0.18]],"batb":[[0,1.54,16.74]],"ltp":1.62,"tv":0.17,"id":72857116}],"tv":0.35}]}
{"op":"mcm","clk":"11920254040","pt":1724121492263,"mc":[{"id":"1.232019003","rc":[{"batb":[[0,1.52,1.75],[1,1.5,10]],"ltp":1.62,"tv":0.17,"id":67083366},{"batb":[[0,1.53,1.75],[1,1.51,10]],"ltp":1.62,"tv":0.17,"id":72857116}]}]}
{"op":"mcm","clk":"11920256090","pt":1724121542394,"mc":[{"id":"1.232019003","rc":[{"batb":[[0,1.53,17.04],[1,1.5,10.9]],"ltp":1.62,"tv":0.17,"id":67083366},{"batb":[[0,1.54,16.74],[1,1.51,10.9]],"ltp":1.62,"tv":0.17,"id":72857116}]}]}
{"op":"mcm","clk":"11920330735","pt":1724123611929,"mc":[{"id":"1.232019003","rc":[{"batb":[[0,1.52,1.75],[1,1.5,10],[2,1.44,7.17]],"ltp":1.62,"tv":0.17,"id":67083366},{"batb":[[0,1.53,1.75],[1,1.51,10],[2,1.44,6.41]],"ltp":1.62,"tv":0.17,"id":72857116}]}]}
{"op":"mcm","clk":"11920333639","pt":1724123710515,"mc":[{"id":"1.232019003","rc":[{"batb":[[0,1.53,17.04],[1,1.5,10.9]],"ltp":1.62,"tv":0.17,"id":67083366},{"batb":[[0,1.54,16.74],[1,1.51,10.9]],"ltp":1.62,"tv":0.17,"id":72857116}]}]}
{"op":"mcm","clk":"11920380980","pt":1724125348424,"mc":[{"id":"1.232019003","rc":[{"batb":[[0,1.6,1.39],[1,1.53,16.18],[2,1.5,10.9]],"ltp":1.62,"tv":0.17,"id":67083366}]}]}
{"op":"mcm","clk":"11920381512","pt":1724125370990,"mc":[{"id":"1.232019003","rc":[{"batb":[[0,1.53,17.04],[1,1.5,10.9],[2,1.44,7.17]],"ltp":1.62,"tv":0.17,"id":67083366}]}]}
{"op":"mcm","clk":"11920393777","pt":1724125510930,"mc":[{"id":"1.232019003","rc":[{"batb":[[0,1.52,1.75],[1,1.5,10]],"ltp":1.62,"tv":0.17,"id":67083366},{"batb":[[0,1.53,1.75],[1,1.51,10]],"ltp":1.62,"tv":0.17,"id":72857116}]}]}
{"op":"mcm","clk":"11920394214","pt":1724125527899,"mc":[{"id":"1.232019003","rc":[{"batb":[[0,1.53,17.04],[1,1.5,10.9]],"ltp":1.62,"tv":0.17,"id":67083366},{"batb":[[0,1.54,16.74],[1,1.51,10.9]],"ltp":1.62,"tv":0.17,"id":72857116}]}]}
{"op":"mcm","clk":"11920396161","pt":1724125597167,"mc":[{"id":"1.232019003","rc":[{"batb":[[0,1.53,17.14]],"ltp":1.62,"tv":0.17,"id":67083366}]}]}
{"op":"mcm","clk":"11920396529","pt":1724125609556,"mc":[{"id":"1.232019003","rc":[{"batb":[[0,1.54,15.88]],"ltp":1.62,"tv":0.17,"id":72857116}]}]}
{"op":"mcm","clk":"11920396535","pt":1724125609761,"mc":[{"id":"1.232019003","rc":[{"batb":[[0,1.54,16.84]],"ltp":1.62,"tv":0.17,"id":72857116}]}]}
{"op":"mcm","clk":"11920426499","pt":1724126629018,"mc":[{"id":"1.232019003","rc":[{"batb":[[0,1.54,1.85],[1,1.53,16.18],[2,1.5,10]],"ltp":1.62,"tv":0.17,"id":67083366}]}]}
{"op":"mcm","clk":"11920426856","pt":1724126639098,"mc":[{"id":"1.232019003","rc":[{"batb":[[0,1.55,1.85]],"ltp":1.62,"tv":0.17,"id":67083366}]}]}
{"op":"mcm","clk":"11920450091","pt":1724127312878,"mc":[{"id":"1.232019003","rc":[{"batb":[[0,1.64,1.46],[1,1.53,17.08]],"ltp":1.62,"tv":0.17,"id":67083366}]}]}
{"op":"mcm","clk":"11920450558","pt":1724127328495,"mc":[{"id":"1.232019003","rc":[{"batb":[[1,1.5,10.9],[2,1.44,7.17]],"ltp":1.62,"tv":0.17,"id":67083366},{"batb":[[0,1.53,1.85],[1,1.51,10]],"ltp":1.62,"tv":0.17,"id":72857116}]}]}
{"op":"mcm","clk":"11920450666","pt":1724127331814,"mc":[{"id":"1.232019003","rc":[{"batb":[[0,1.64,1.46],[1,1.51,10.9]],"ltp":1.62,"tv":0.17,"id":72857116}]}]}
{"op":"mcm","clk":"11920450745","pt":1724127334174,"mc":[{"id":"1.232019003","rc":[{"batb":[[1,1.56,15.32],[2,1.5,10.9]],"ltp":1.62,"tv":0.17,"id":67083366},{"batb":[[1,1.54,15.88],[2,1.51,10.9]],"ltp":1.62,"tv":0.17,"id":72857116}]}]}
{"op":"mcm","clk":"11920510275","pt":1724129134426,"mc":[{"id":"1.232019003","rc":[{"batb":[[1,1.51,10.9],[2,1.44,6.41]],"ltp":1.62,"tv":0.17,"id":72857116}]}]}
{"op":"mcm","clk":"11920510280","pt":1724129134632,"mc":[{"id":"1.232019003","rc":[{"batb":[[1,1.5,10.9],[2,1.44,7.17]],"ltp":1.62,"tv":0.17,"id":67083366}]}]}
{"op":"mcm","clk":"11920514047","pt":1724129257351,"mc":[{"id":"1.232019003","rc":[{"batb":[[1,1.56,15.32],[2,1.5,10.9]],"ltp":1.62,"tv":0.17,"id":67083366},{"batb":[[1,1.54,15.88],[2,1.51,10.9]],"ltp":1.62,"tv":0.17,"id":72857116}]}]}
{"op":"mcm","clk":"11920592445","pt":1724131057736,"mc":[{"id":"1.232019003","rc":[{"batb":[[1,1.5,10.9],[2,1.44,7.17]],"ltp":1.62,"tv":0.17,"id":67083366},{"batb":[[1,1.51,10.9],[2,1.44,6.41]],"ltp":1.62,"tv":0.17,"id":72857116}]}]}
{"op":"mcm","clk":"11920594262","pt":1724131124177,"mc":[{"id":"1.232019003","rc":[{"batb":[[1,1.56,15.32],[2,1.5,10.9]],"ltp":1.62,"tv":0.17,"id":67083366},{"batb":[[1,1.54,15.88],[2,1.51,10.9]],"ltp":1.62,"tv":0.17,"id":72857116}]}]}
{"op":"mcm","clk":"11920657394","pt":1724132924537,"mc":[{"id":"1.232019003","rc":[{"batb":[[1,1.5,10.9],[2,1.44,7.17]],"ltp":1.62,"tv":0.17,"id":67083366},{"batb":[[1,1.51,10.9],[2,1.44,6.41]],"ltp":1.62,"tv":0.17,"id":72857116}]}]}
{"op":"mcm","clk":"11920660429","pt":1724132991085,"mc":[{"id":"1.232019003","rc":[{"batb":[[1,1.56,15.32],[2,1.5,10.9]],"ltp":1.62,"tv":0.17,"id":67083366},{"batb":[[1,1.54,15.88],[2,1.51,10.9]],"ltp":1.62,"tv":0.17,"id":72857116}]}]}
{"op":"mcm","clk":"11920715768","pt":1724134791486,"mc":[{"id":"1.232019003","rc":[{"batb":[[1,1.5,10.9],[2,1.44,7.17]],"ltp":1.62,"tv":0.17,"id":67083366},{"batb":[[1,1.54,15.88]],"ltp":1.62,"tv":0.17,"id":72857116}]}]}
{"op":"mcm","clk":"11920715774","pt":1724134791689,"mc":[{"id":"1.232019003","rc":[{"batb":[[1,1.51,10.9],[2,1.44,6.41]],"ltp":1.62,"tv":0.17,"id":72857116}]}]}
{"op":"mcm","clk":"11920717255","pt":1724134856758,"mc":[{"id":"1.232019003","rc":[{"batb":[[1,1.56,15.31],[2,1.5,10.9]],"ltp":1.62,"tv":0.17,"id":67083366},{"batb":[[1,1.54,15.88],[2,1.51,10.9]],"ltp":1.62,"tv":0.17,"id":72857116}]}]}
{"op":"mcm","clk":"11920781684","pt":1724136656976,"mc":[{"id":"1.232019003","rc":[{"batb":[[1,1.5,10.9],[2,1.44,7.17]],"ltp":1.62,"tv":0.17,"id":67083366},{"batb":[[1,1.51,10.9],[2,1.44,6.41]],"ltp":1.62,"tv":0.17,"id":72857116}]}]}
{"op":"mcm","clk":"11920783731","pt":1724136720958,"mc":[{"id":"1.232019003","rc":[{"batb":[[1,1.56,15.31],[2,1.5,10.9]],"ltp":1.62,"tv":0.17,"id":67083366},{"batb":[[1,1.54,15.88],[2,1.51,10.9]],"ltp":1.62,"tv":0.17,"id":72857116}]}]}
{"op":"mcm","clk":"11920784082","pt":1724136732446,"mc":[{"id":"1.232019003","rc":[{"batb":[[0,1.56,16.27],[1,1.5,10.9],[2,1.44,7.17]],"ltp":1.62,"tv":0.17,"id":67083366},{"batb":[[0,1.54,16.84],[1,1.51,10.9],[2,1.44,6.41]],"ltp":1.62,"tv":0.17,"id":72857116}]}]}
{"op":"mcm","clk":"11920844775","pt":1724138521469,"mc":[{"id":"1.232019003","rc":[{"batb":[[0,1.55,1.85],[1,1.5,10],[2,1.44,7.16]],"batl":[[0,5,1.54],[1,9,1.54]],"ltp":1.62,"tv":0.17,"id":67083366},{"batb":[[0,1.53,1.85],[1,1.51,10],[2,1.44,6.4]],"batl":[[0,5,1.54],[1,9,1.54]],"ltp":1.62,"tv":0.17,"id":72857116}]}]}
{"op":"mcm","clk":"11920846566","pt":1724138583946,"mc":[{"id":"1.232019003","rc":[{"batb":[[0,1.56,16.26],[1,1.5,10.9]],"ltp":1.62,"tv":0.17,"id":67083366},{"batb":[[0,1.54,16.83],[1,1.51,10.9]],"ltp":1.62,"tv":0.17,"id":72857116}]}]}
{"op":"mcm","clk":"11920900683","pt":1724140384561,"mc":[{"id":"1.232019003","rc":[{"batb":[[0,1.55,1.85],[1,1.5,10]],"ltp":1.62,"tv":0.17,"id":67083366},{"batb":[[0,1.53,1.85],[1,1.51,10]],"ltp":1.62,"tv":0.17,"id":72857116}]}]}
{"op":"mcm","clk":"11920902840","pt":1724140446727,"mc":[{"id":"1.232019003","rc":[{"batb":[[0,1.56,16.26],[1,1.5,10.9]],"ltp":1.62,"tv":0.17,"id":67083366},{"batb":[[0,1.54,16.83],[1,1.51,10.9]],"ltp":1.62,"tv":0.17,"id":72857116}]}]}
{"op":"mcm","clk":"11920941012","pt":1724141574990,"mc":[{"id":"1.232019003","rc":[{"batb":[[0,1.56,16.26],[2,1.44,7.16]],"ltp":1.62,"tv":0.17,"id":67083366},{"batb":[[0,1.54,16.82],[2,1.44,6.4]],"ltp":1.62,"tv":0.17,"id":72857116}]}]}
{"op":"mcm","clk":"11920964144","pt":1724142247157,"mc":[{"id":"1.232019003","rc":[{"batb":[[0,1.55,1.85],[1,1.5,10]],"ltp":1.62,"tv":0.17,"id":67083366},{"batb":[[0,1.53,1.85],[1,1.51,10]],"ltp":1.62,"tv":0.17,"id":72857116}]}]}
{"op":"mcm","clk":"11920968036","pt":1724142371779,"mc":[{"id":"1.232019003","rc":[{"batb":[[0,1.56,16.26],[1,1.5,10.89]],"ltp":1.62,"tv":0.17,"id":67083366},{"batb":[[0,1.54,16.82],[1,1.51,10.89]],"ltp":1.62,"tv":0.17,"id":72857116}]}]}
{"op":"mcm","clk":"11921031017","pt":1724144172285,"mc":[{"id":"1.232019003","rc":[{"batb":[[0,1.55,1.85],[1,1.5,10]],"ltp":1.62,"tv":0.17,"id":67083366},{"batb":[[0,1.53,1.85],[1,1.51,10]],"ltp":1.62,"tv":0.17,"id":72857116}]}]}
{"op":"mcm","clk":"11921032635","pt":1724144215538,"mc":[{"id":"1.232019003","rc":[{"batb":[[0,1.56,16.26],[1,1.5,10.89]],"ltp":1.62,"tv":0.17,"id":67083366},{"batb":[[0,1.54,16.82],[1,1.51,10.89]],"ltp":1.62,"tv":0.17,"id":72857116}]}]}
{"op":"mcm","clk":"11921095925","pt":1724146015954,"mc":[{"id":"1.232019003","rc":[{"batb":[[0,1.55,1.85],[1,1.5,10],[2,1.44,7.16]],"ltp":1.62,"tv":0.17,"id":67083366},{"batb":[[0,1.53,1.85],[1,1.51,10]],"ltp":1.62,"tv":0.17,"id":72857116}]}]}
{"op":"mcm","clk":"11921097617","pt":1724146053067,"mc":[{"id":"1.232019003","rc":[{"batb":[[0,1.56,16.25],[1,1.5,10.89]],"ltp":1.62,"tv":0.17,"id":67083366},{"batb":[[0,1.54,16.82],[1,1.51,10.89]],"ltp":1.62,"tv":0.17,"id":72857116}]}]}
{"op":"mcm","clk":"11921121924","pt":1724146609224,"mc":[{"id":"1.232019003","rc":[{"trd":[[1.56,0.1],[1.68,1.9]],"batb":[[0,1.56,15.25]],"ltp":1.56,"tv":2.18,"id":67083366}],"tv":2.36}]}
{"op":"mcm","clk":"11921122875","pt":1724146630471,"mc":[{"id":"1.232019003","rc":[{"trd":[[2.48,0.65],[2.86,0.35]],"ltp":2.86,"tv":3.18,"id":67083366},{"trd":[[1.54,0.65],[1.68,0.95]],"batb":[[0,1.54,15.21]],"ltp":1.54,"tv":1.78,"id":72857116}],"tv":4.96}]}
{"op":"mcm","clk":"11921123972","pt":1724146658913,"mc":[{"id":"1.232019003","rc":[{"trd":[[1.54,2.65]],"batb":[[0,1.54,14.21]],"ltp":1.54,"tv":3.78,"id":72857116}],"tv":6.96}]}
{"op":"mcm","clk":"11921125325","pt":1724146686400,"mc":[{"id":"1.232019003","rc":[{"batl":[[0,1.76,1],[1,5,1.54],[2,9,1.54]],"ltp":2.86,"tv":3.18,"id":67083366}]}]}
{"op":"mcm","clk":"11921132694","pt":1724146871805,"mc":[{"id":"1.232019003","rc":[{"trd":[[1.76,2]],"batl":[[0,5,1.54],[1,9,1.54],[2,9,0]],"ltp":1.76,"tv":5.18,"id":67083366}],"tv":8.96}]}
{"op":"mcm","clk":"11921133080","pt":1724146881841,"mc":[{"id":"1.232019003","rc":[{"batb":[[0,1.54,15.15]],"ltp":1.54,"tv":3.78,"id":72857116}]}]}
{"op":"mcm","clk":"11921133803","pt":1724146903875,"mc":[{"id":"1.232019003","rc":[{"batl":[[0,4,1.71],[1,6,1.54],[2,9,0.77]],"ltp":1.76,"tv":5.18,"id":67083366}]}]}
{"op":"mcm","clk":"11921134020","pt":1724146910573,"mc":[{"id":"1.232019003","rc":[{"batl":[[0,5,1.54],[1,9,1.54],[2,9,0]],"ltp":1.76,"tv":5.18,"id":67083366}]}]}
{"op":"mcm","clk":"11921135314","pt":1724146947893,"mc":[{"id":"1.232019003","rc":[{"trd":[[1.56,2.1]],"batb":[[0,1.56,14.25]],"ltp":1.56,"tv":7.18,"id":67083366}],"tv":10.96}]}
{"op":"mcm","clk":"11921148257","pt":1724147047403,"mc":[{"id":"1.232019003","rc":[{"batl":[[0,1.96,1],[1,5,1.54],[2,9,1.54]],"ltp":1.56,"tv":7.18,"id":67083366}]}]}
{"op":"mcm","clk":"11921152461","pt":1724147154918,"mc":[{"id":"1.232019003","rc":[{"batl":[[1,2.1,1.3],[2,5,1.54]],"ltp":1.56,"tv":7.18,"id":67083366}]}]}
{"op":"mcm","clk":"11921160489","pt":1724147348830,"mc":[{"id":"1.232019003","rc":[{"trd":[[1.56,3.9]],"batb":[[0,1.56,12.45]],"ltp":1.56,"tv":8.97,"id":67083366},{"trd":[[2.8,1]],"ltp":2.8,"tv":4.78,"id":72857116}],"tv":13.76}]}
{"op":"mcm","clk":"11921164184","pt":1724147445168,"mc":[{"id":"1.232019003","rc":[{"batl":[[2,2.2,1]],"ltp":1.56,"tv":8.97,"id":67083366}]}]}
{"op":"mcm","clk":"11921167090","pt":1724147516965,"mc":[{"id":"1.232019003","rc":[{"batl":[[0,1.58,1.54],[1,1.96,1],[2,2.1,1.3]],"ltp":1.56,"tv":8.97,"id":67083366}]}]}
{"op":"mcm","clk":"11921168304","pt":1724147545047,"mc":[{"id":"1.232019003","rc":[{"batl":[[0,1.96,1],[1,2.1,1.3],[2,2.2,1]],"ltp":1.56,"tv":8.97,"id":67083366}]}]}
{"op":"mcm","clk":"11921169047","pt":1724147562383,"mc":[{"id":"1.232019003","rc":[{"batb":[[0,1.95,1.54],[1,1.56,12.45],[2,1.5,10.89]],"ltp":1.56,"tv":8.97,"id":67083366}]}]}
{"op":"mcm","clk":"11921169764","pt":1724147580193,"mc":[{"id":"1.232019003","rc":[{"batb":[[0,1.56,12.45],[1,1.5,10.89],[2,1.44,7.16]],"ltp":1.56,"tv":8.97,"id":67083366}]}]}
{"op":"mcm","clk":"11921170684","pt":1724147600246,"mc":[{"id":"1.232019003","rc":[{"batl":[[0,1.57,1.54],[1,1.96,1],[2,2.1,1.3]],"ltp":1.56,"tv":8.97,"id":67083366}]}]}
{"op":"mcm","clk":"11921173695","pt":1724147669956,"mc":[{"id":"1.232019003","rc":[{"batl":[[0,1.96,1],[1,2.1,1.3],[2,2.2,1]],"ltp":1.56,"tv":8.97,"id":67083366}]}]}
{"op":"mcm","clk":"11921174977","pt":1724147696885,"mc":[{"id":"1.232019003","rc":[{"batb":[[0,1.95,1.54],[1,1.56,12.45],[2,1.5,10.89]],"ltp":1.56,"tv":8.97,"id":67083366}]}]}
{"op":"mcm","clk":"11921175564","pt":1724147707912,"mc":[{"id":"1.232019003","rc":[{"trd":[[1.95,2]],"batb":[[0,1.56,12.99],[1,1.5,10.89],[2,1.44,7.16]],"batl":[[0,2.1,1.3],[1,2.2,1],[2,5,1.54]],"ltp":1.95,"tv":10.97,"id":67083366}],"tv":15.76}]}
{"op":"mcm","clk":"11921176240","pt":1724147717207,"mc":[{"id":"1.232019003","rc":[{"batb":[[0,1.56,12.45]],"ltp":1.95,"tv":10.97,"id":67083366}]}]}
{"op":"mcm","clk":"11921176888","pt":1724147726903,"mc":[{"id":"1.232019003","rc":[{"batb":[[0,2.08,1.54],[1,1.56,12.45],[2,1.5,10.89]],"ltp":1.95,"tv":10.97,"id":67083366}]}]}
{"op":"mcm","clk":"11921177240","pt":1724147733151,"mc":[{"id":"1.232019003","rc":[{"batb":[[0,1.56,12.45],[1,1.5,10.89],[2,1.44,7.16]],"ltp":1.95,"tv":10.97,"id":67083366}]}]}
{"op":"mcm","clk":"11921182793","pt":1724147853380,"mc":[{"id":"1.232019003","rc":[{"batb":[[0,1.5,10.89],[1,1.44,7.16],[2,1.43,116.28]],"batl":[[0,1.57,1.54],[1,2.1,1.3],[2,2.2,1]],"ltp":1.95,"tv":10.97,"id":67083366},{"batb":[[0,1.53,1.84],[1,1.51,10]],"ltp":2.8,"tv":4.78,"id":72857116}]}]}
{"op":"mcm","clk":"11921183299","pt":1724147864397,"mc":[{"id":"1.232019003","rc":[{"batl":[[0,2.1,1.3],[1,2.2,1],[2,5,1.54]],"ltp":1.95,"tv":10.97,"id":67083366}]}]}
{"op":"mcm","clk":"11921183683","pt":1724147874002,"mc":[{"id":"1.232019003","rc":[{"batb":[[0,2.08,1.54],[1,1.5,10.89],[2,1.44,7.16]],"ltp":1.95,"tv":10.97,"id":67083366}]}]}
{"op":"mcm","clk":"11921184154","pt":1724147885208,"mc":[{"id":"1.232019003","rc":[{"batb":[[0,1.5,10.89],[1,1.44,7.16],[2,1.43,116.28]],"ltp":1.95,"tv":10.97,"id":67083366}]}]}
{"op":"mcm","clk":"11921184879","pt":1724147901039,"mc":[{"id":"1.232019003","rc":[{"batl":[[0,1.56,1.54],[1,2.1,1.3],[2,2.2,1]],"ltp":1.95,"tv":10.97,"id":67083366}]}]}
{"op":"mcm","clk":"11921185067","pt":1724147905024,"mc":[{"id":"1.232019003","rc":[{"trd":[[1.56,6.97]],"batb":[[0,1.55,1.32],[1,1.5,10],[2,1.44,7.16]],"batl":[[0,2.1,1.3],[1,2.2,1],[2,5,1.54]],"ltp":1.56,"tv":14.05,"id":67083366}],"tv":18.84}]}
{"op":"mcm","clk":"11921185101","pt":1724147905802,"mc":[{"id":"1.232019003","rc":[{"batb":[[0,1.56,2.42],[1,1.5,10.89]],"ltp":1.56,"tv":14.05,"id":67083366}]}]}
{"op":"mcm","clk":"11921185480","pt":1724147915565,"mc":[{"id":"1.232019003","rc":[{"batb":[[0,1.55,1.32],[1,1.5,10]],"ltp":1.56,"tv":14.05,"id":67083366}]}]}
{"op":"mcm","clk":"11921185512","pt":1724147916449,"mc":[{"id":"1.232019003","rc":[{"batb":[[0,1.56,1.37],[1,1.5,10.89]],"batl":[[0,1.57,1.54],[1,2.1,1.3],[2,2.2,1]],"ltp":1.56,"tv":14.05,"id":67083366}]}]}
{"op":"mcm","clk":"11921185649","pt":1724147920525,"mc":[{"id":"1.232019003","rc":[{"batb":[[0,1.55,1.32],[1,1.5,10]],"ltp":1.56,"tv":14.05,"id":67083366}]}]}
{"op":"mcm","clk":"11921185656","pt":1724147920682,"mc":[{"id":"1.232019003","rc":[{"trd":[[1.57,1.88]],"batl":[[0,2.1,1.9],[1,2.2,1],[2,5,1.54]],"ltp":1.57,"tv":15.93,"id":67083366}],"tv":20.71}]}
{"op":"mcm","clk":"11921185785","pt":1724147924862,"mc":[{"id":"1.232019003","rc":[{"batl":[[0,2.1,1.3]],"ltp":1.57,"tv":15.93,"id":67083366}]}]}
{"op":"mcm","clk":"11921185919","pt":1724147928872,"mc":[{"id":"1.232019003","rc":[{"batb":[[0,1.5,10.89],[1,1.44,7.16],[2,1.43,116.28]],"ltp":1.57,"tv":15.93,"id":67083366}]}]}
{"op":"mcm","clk":"11921186079","pt":1724147932835,"mc":[{"id":"1.232019003","rc":[{"batb":[[0,1.55,1.84],[1,1.5,10],[2,1.44,7.16]],"ltp":1.57,"tv":15.93,"id":67083366}]}]}
{"op":"mcm","clk":"11921186521","pt":1724147944458,"mc":[{"id":"1.232019003","rc":[{"batl":[[0,2.1,2.24]],"ltp":1.57,"tv":15.93,"id":67083366}]}]}
{"op":"mcm","clk":"11921186715","pt":1724147950591,"mc":[{"id":"1.232019003","rc":[{"batb":[[0,1.51,10.89],[1,1.44,6.4],[2,1.43,116.28]],"ltp":2.8,"tv":4.78,"id":72857116}]}]}
{"op":"mcm","clk":"11921187192","pt":1724147963488,"mc":[{"id":"1.232019003","rc":[{"batl":[[0,1.61,1.54],[1,2.1,2.24],[2,2.2,1]],"ltp":1.57,"tv":15.93,"id":67083366}]}]}
{"op":"mcm","clk":"11921187343","pt":1724147968604,"mc":[{"id":"1.232019003","rc":[{"batl":[[1,1.92,1.69],[2,2.1,1.3]],"ltp":1.57,"tv":15.93,"id":67083366}]}]}
{"op":"mcm","clk":"11921187438","pt":1724147972419,"mc":[{"id":"1.232019003","rc":[{"trd":[[1.61,3.08]],"batb":[[0,1.61,1.41],[1,1.55,1.84],[2,1.5,10]],"batl":[[0,1.92,1.69],[1,2.1,1.3],[2,2.2,1]],"ltp":1.61,"tv":19.01,"id":67083366}],"tv":23.79}]}
{"op":"mcm","clk":"11921187498","pt":1724147974502,"mc":[{"id":"1.232019003","rc":[{"batb":[[0,1.61,1.99]],"ltp":1.61,"tv":19.01,"id":67083366}]}]}
{"op":"mcm","clk":"11921188034","pt":1724147986615,"mc":[{"id":"1.232019003","rc":[{"batb":[[0,1.55,1.84],[1,1.5,10],[2,1.44,7.16]],"ltp":1.61,"tv":19.01,"id":67083366}]}]}
{"op":"mcm","clk":"11921188041","pt":1724147986816,"mc":[{"id":"1.232019003","rc":[{"batb":[[0,1.59,1.88],[1,1.5,10.89]],"ltp":1.61,"tv":19.01,"id":67083366}]}]}
{"op":"mcm","clk":"11921188293","pt":1724147994517,"mc":[{"id":"1.232019003","rc":[{"batl":[[0,1.62,1.54],[1,1.92,1.69],[2,2.1,1.3]],"ltp":1.61,"tv":19.01,"id":67083366}]}]}
{"op":"mcm","clk":"11921188502","pt":1724148000527,"mc":[{"id":"1.232019003","rc":[{"batb":[[0,1.62,2.95],[1,1.59,1.88],[2,1.5,10.89]],"batl":[[0,1.92,1.69],[1,2.1,1.3],[2,2.2,1]],"ltp":1.61,"tv":19.01,"id":67083366}]}]}
{"op":"mcm","clk":"11921188654","pt":1724148002560,"mc":[{"id":"1.232019003","rc":[{"batb":[[1,1.55,1.84],[2,1.5,10]],"ltp":1.61,"tv":19.01,"id":67083366}]}]}
{"op":"mcm","clk":"11921188691","pt":1724148003240,"mc":[{"id":"1.232019003","rc":[{"batb":[[0,1.59,1.88],[1,1.5,10.89],[2,1.44,7.16]],"ltp":1.61,"tv":19.01,"id":67083366}]}]}
{"op":"mcm","clk":"11921189876","pt":1724148030760,"mc":[{"id":"1.232019003","rc":[{"trd":[[1.56,6.97]],"ltp":1.61,"tv":19.01,"id":67083366},{"batl":[[0,2.1,1.54],[1,5,1.54],[2,9,1.54]],"ltp":2.8,"tv":4.78,"id":72857116}],"tv":23.79}]}
{"op":"mcm","clk":"11921189984","pt":1724148033557,"mc":[{"id":"1.232019003","rc":[{"batl":[[0,2.1,1.3],[1,2.2,1],[2,5,1.54]],"ltp":1.61,"tv":19.01,"id":67083366}]}]}
{"op":"mcm","clk":"11921189988","pt":1724148033662,"mc":[{"id":"1.232019003","rc":[{"trd":[[1.9,1.69]],"ltp":1.9,"tv":20.7,"id":67083366},{"trd":[[2.1,1.53]],"batl":[[0,5,1.55],[1,9,1.54],[2,9,0]],"ltp":2.1,"tv":6.31,"id":72857116}],"tv":27.01}]}
{"op":"mcm","clk":"11921190172","pt":1724148038162,"mc":[{"id":"1.232019003","rc":[{"batl":[[0,5,1.54]],"ltp":2.1,"tv":6.31,"id":72857116}]}]}
{"op":"mcm","clk":"11921190291","pt":1724148041483,"mc":[{"id":"1.232019003","rc":[{"batl":[[0,2,2.95],[1,2.1,1.3],[2,2.2,1]],"ltp":1.9,"tv":20.7,"id":67083366}]}]}
{"op":"mcm","clk":"11921190379","pt":1724148043550,"mc":[{"id":"1.232019003","rc":[{"trd":[[2,1.18]],"batl":[[0,2,2.36]],"ltp":2.0,"tv":21.88,"id":67083366}],"tv":28.19}]}
{"op":"mcm","clk":"11921190695","pt":1724148053462,"mc":[{"id":"1.232019003","rc":[{"batl":[[0,2,3.3]],"ltp":2.0,"tv":21.88,"id":67083366}]}]}
{"op":"mcm","clk":"11921209195","pt":1724148429012,"mc":[{"id":"1.232019003","rc":[{"batl":[[0,2.1,2.24],[1,2.2,1],[2,5,1.54]],"ltp":2.0,"tv":21.88,"id":67083366}]}]}
{"op":"mcm","clk":"11921211341","pt":1724148483178,"mc":[{"id":"1.232019003","rc":[{"trd":[[1.9,2.63],[2.1,1.04]],"batl":[[0,2.2,1.26],[1,5,1.54],[2,9,1.54]],"ltp":2.1,"tv":23.86,"id":67083366},{"trd":[[1.9,1.15],[2.1,2.38]],"ltp":1.9,"tv":8.31,"id":72857116}],"tv":32.18}]}
{"op":"mcm","clk":"11921212504","pt":1724148510991,"mc":[{"id":"1.232019003","rc":[{"batb":[[0,1.9,1.97],[1,1.51,10.89],[2,1.44,6.4]],"ltp":1.9,"tv":8.31,"id":72857116}]}]}
{"op":"mcm","clk":"11921218733","pt":1724148647429,"mc":[{"id":"1.232019003","rc":[{"batb":[[0,1.55,1.84],[1,1.5,10]],"ltp":2.1,"tv":23.86,"id":67083366}]}]}
{"op":"mcm","clk":"11921218745","pt":1724148647633,"mc":[{"id":"1.232019003","rc":[{"batb":[[0,1.71,1.04],[1,1.55,1.84],[2,1.5,10]],"ltp":2.1,"tv":23.86,"id":67083366}]}]}
{"op":"mcm","clk":"11921219156","pt":1724148657862,"mc":[{"id":"1.232019003","rc":[{"batb":[[1,1.5,10.89],[2,1.44,7.16]],"ltp":2.1,"tv":23.86,"id":67083366}]}]}
{"op":"mcm","clk":"11921236942","pt":1724149019144,"mc":[{"id":"1.232019003","rc":[{"batb":[[0,1.55,1.84],[1,1.5,10]],"ltp":2.1,"tv":23.86,"id":67083366}]}]}
{"op":"mcm","clk":"11921239707","pt":1724149076917,"mc":[{"id":"1.232019003","rc":[{"batb":[[0,1.51,10.89],[1,1.44,6.4],[2,1.43,116.28]],"ltp":1.9,"tv":8.31,"id":72857116}]}]}
{"op":"mcm","clk":"11921248351","pt":1724149243817,"mc":[{"id":"1.232019003","rc":[{"batb":[[0,1.85,1.97],[1,1.51,10.89],[2,1.44,6.4]],"ltp":1.9,"tv":8.31,"id":72857116}]}]}
{"op":"mcm","clk":"11921304981","pt":1724150605060,"mc":[{"id":"1.232019003","rc":[{"trd":[[2.1,1.3]],"batl":[[0,2.2,1]],"ltp":2.1,"tv":24.12,"id":67083366},{"trd":[[1.9,1.43]],"batl":[[0,1.86,3.56],[1,5,1.54],[2,9,1.54]],"ltp":1.9,"tv":8.59,"id":72857116}],"tv":32.72}]}
{"op":"mcm","clk":"11921312630","pt":1724150801769,"mc":[{"id":"1.232019003","rc":[{"batl":[[0,5,1.54],[1,9,1.54],[2,9,0]],"ltp":1.9,"tv":8.59,"id":72857116}]}]}
{"op":"mcm","clk":"11921313311","pt":1724150820104,"mc":[{"id":"1.232019003","rc":[{"batl":[[0,4,1.54],[1,6,1.54],[2,9,0.77]],"ltp":1.9,"tv":8.59,"id":72857116}]}]}
{"op":"mcm","clk":"11921313650","pt":1724150827109,"mc":[{"id":"1.232019003","rc":[{"trd":[[2.16,0.66]],"batl":[[0,2.14,1.89],[1,2.2,1],[2,5,1.54]],"ltp":2.16,"tv":24.79,"id":67083366},{"trd":[[1.86,0.77]],"batl":[[0,5,1.54],[1,9,1.54],[2,9,0]],"ltp":1.86,"tv":9.36,"id":72857116}],"tv":34.15}]}
{"op":"mcm","clk":"11921313763","pt":1724150829412,"mc":[{"id":"1.232019003","rc":[{"batl":[[0,2.2,1],[1,5,1.54],[2,9,1.54]],"ltp":2.16,"tv":24.79,"id":67083366}]}]}
{"op":"mcm","clk":"11921314098","pt":1724150837515,"mc":[{"id":"1.232019003","rc":[{"batb":[[0,1.63,4.35],[1,1.5,10.89]],"ltp":2.16,"tv":24.79,"id":67083366}]}]}
{"op":"mcm","clk":"11921314171","pt":1724150839219,"mc":[{"id":"1.232019003","rc":[{"batb":[[0,1.87,2.56],[1,1.85,1.97],[2,1.51,10.89]],"ltp":1.86,"tv":9.36,"id":72857116}]}]}
{"op":"mcm","clk":"11921314684","pt":1724150853544,"mc":[{"id":"1.232019003","rc":[{"batb":[[0,1.63,3.41]],"ltp":2.16,"tv":24.79,"id":67083366}]}]}
{"op":"mcm","clk":"11921314686","pt":1724150853647,"mc":[{"id":"1.232019003","rc":[{"batb":[[0,1.71,1.03],[1,1.63,3.41],[2,1.5,10.89]],"ltp":2.16,"tv":24.79,"id":67083366}]}]}
{"op":"mcm","clk":"11921315075","pt":1724150863936,"mc":[{"id":"1.232019003","rc":[{"batl":[[0,1.88,2.31],[1,5,1.54],[2,9,1.54]],"ltp":1.86,"tv":9.36,"id":72857116}]}]}
{"op":"mcm","clk":"11921315547","pt":1724150876152,"mc":[{"id":"1.232019003","rc":[{"batb":[[1,1.51,10.89],[2,1.44,6.4]],"ltp":1.86,"tv":9.36,"id":72857116}]}]}
{"op":"mcm","clk":"11921315695","pt":1724150879247,"mc":[{"id":"1.232019003","rc":[{"trd":[[1.88,3.94]],"batl":[[0,4,1.11],[1,6,1.54],[2,9,0.77]],"ltp":1.88,"tv":13.3,"id":72857116}],"tv":38.09}]}
{"op":"mcm","clk":"11921316029","pt":1724150887300,"mc":[{"id":"1.232019003","rc":[{"batl":[[0,5,1.54],[1,9,1.54],[2,9,0]],"ltp":1.88,"tv":13.3,"id":72857116}]}]}
{"op":"mcm","clk":"11921316234","pt":1724150892606,"mc":[{"id":"1.232019003","rc":[{"trd":[[1.63,4.8],[1.71,2.06]],"batb":[[0,1.63,1.01],[1,1.5,10.89],[2,1.44,7.16]],"ltp":1.63,"tv":31.65,"id":67083366}],"tv":44.96}]}
{"op":"mcm","clk":"11921320472","pt":1724150998887,"mc":[{"id":"1.232019003","rc":[{"batb":[[0,1.63,1.95]],"ltp":1.63,"tv":31.65,"id":67083366}]}]}
{"op":"mcm","clk":"11921321216","pt":1724151015510,"mc":[{"id":"1.232019003","rc":[{"batl":[[0,2.2,1.94]],"ltp":1.63,"tv":31.65,"id":67083366}]}]}
{"op":"mcm","clk":"11921388866","pt":1724152374943,"mc":[{"id":"1.232019003","rc":[{"trd":[[1.56,6.97]],"batb":[[2,1.44,7.16]],"ltp":1.63,"tv":31.65,"id":67083366},{"batb":[[0,1.87,2.56]],"ltp":1.88,"tv":13.3,"id":72857116}]}]}
{"op":"mcm","clk":"11921416340","pt":1724152923398,"mc":[{"id":"1.232019003","rc":[{"trd":[[1.96,0.94],[2.2,0.45]],"batb":[[0,1.65,10.94],[1,1.64,4],[2,1.63,1.01]],"batl":[[0,4,1.32],[1,6,1.54],[2,9,0.77]],"ltp":2.2,"tv":33.04,"id":67083366},{"trd":[[1.83,0.54],[1.87,5.12],[2.04,0.9]],"batb":[[0,1.52,10.89],[1,1.51,10]],"ltp":1.83,"tv":19.86,"id":72857116}],"tv":52.91}]}
{"op":"mcm","clk":"11921416405","pt":1724152925209,"mc":[{"id":"1.232019003","rc":[{"batb":[[1,1.63,1.01],[2,1.5,10.89]],"ltp":2.2,"tv":33.04,"id":67083366}]}]}
{"op":"mcm","clk":"11921416455","pt":1724152926500,"mc":[{"id":"1.232019003","rc":[{"batb":[[0,1.51,10.89],[1,1.44,6.4],[2,1.43,116.28]],"ltp":1.83,"tv":19.86,"id":72857116}]}]}
{"op":"mcm","clk":"11921416494","pt":1724152927379,"mc":[{"id":"1.232019003","rc":[{"batb":[[0,1.64,4.94]],"ltp":2.2,"tv":33.04,"id":67083366}]}]}
{"op":"mcm","clk":"11921416609","pt":1724152930097,"mc":[{"id":"1.232019003","rc":[{"batb":[[0,1.63,1.95],[1,1.5,10.89],[2,1.44,7.16]],"ltp":2.2,"tv":33.04,"id":67083366},{"batb":[[0,1.52,10.89],[1,1.51,10],[2,1.44,6.4]],"ltp":1.83,"tv":19.86,"id":72857116}]}]}
{"op":"mcm","clk":"11921416759","pt":1724152933606,"mc":[{"id":"1.232019003","rc":[{"batb":[[0,1.64,4.94],[1,1.63,1.01],[2,1.5,10.89]],"ltp":2.2,"tv":33.04,"id":67083366},{"batb":[[0,1.51,10.89],[1,1.44,6.4],[2,1.43,116.28]],"ltp":1.83,"tv":19.86,"id":72857116}]}]}
{"op":"mcm","clk":"11921416776","pt":1724152934119,"mc":[{"id":"1.232019003","rc":[{"batb":[[0,1.65,10.94],[1,1.64,4],[2,1.63,1.01]],"ltp":2.2,"tv":33.04,"id":67083366}]}]}
{"op":"mcm","clk":"11921416872","pt":1724152936407,"mc":[{"id":"1.232019003","rc":[{"batb":[[1,1.63,1.01],[2,1.5,10.89]],"ltp":2.2,"tv":33.04,"id":67083366},{"batb":[[0,1.52,10.89],[1,1.51,10],[2,1.44,6.4]],"ltp":1.83,"tv":19.86,"id":72857116}]}]}
{"op":"mcm","clk":"11921416896","pt":1724152936909,"mc":[{"id":"1.232019003","rc":[{"batl":[[0,2.36,2.56],[1,5,1.54],[2,9,1.54]],"ltp":1.83,"tv":19.86,"id":72857116}]}]}
{"op":"mcm","clk":"11921416926","pt":1724152937735,"mc":[{"id":"1.232019003","rc":[{"batb":[[0,1.63,1.95],[1,1.5,10.89],[2,1.44,7.16]],"ltp":2.2,"tv":33.04,"id":67083366}]}]}
{"op":"mcm","clk":"11921417035","pt":1724152940128,"mc":[{"id":"1.232019003","rc":[{"batb":[[0,1.65,10.94],[1,1.64,4],[2,1.63,1.01]],"ltp":2.2,"tv":33.04,"id":67083366},{"batb":[[0,1.51,10.89],[1,1.44,6.4],[2,1.43,116.28]],"ltp":1.83,"tv":19.86,"id":72857116}]}]}
{"op":"mcm","clk":"11921417138","pt":1724152942375,"mc":[{"id":"1.232019003","rc":[{"batb":[[1,1.63,1.01],[2,1.5,10.89]],"ltp":2.2,"tv":33.04,"id":67083366},{"batb":[[0,1.52,10.89],[1,1.51,10],[2,1.44,6.4]],"ltp":1.83,"tv":19.86,"id":72857116}]}]}
{"op":"mcm","clk":"11921417199","pt":1724152943524,"mc":[{"id":"1.232019003","rc":[{"batb":[[0,1.63,1.95],[1,1.5,10.89],[2,1.44,7.16]],"ltp":2.2,"tv":33.04,"id":67083366}]}]}
{"op":"mcm","clk":"11921417346","pt":1724152946441,"mc":[{"id":"1.232019003","rc":[{"batb":[[0,1.65,10.94],[1,1.64,4],[2,1.63,1.01]],"ltp":2.2,"tv":33.04,"id":67083366},{"batb":[[0,1.51,10.89],[1,1.44,6.4],[2,1.43,116.28]],"ltp":1.83,"tv":19.86,"id":72857116}]}]}
{"op":"mcm","clk":"11921417437","pt":1724152948561,"mc":[{"id":"1.232019003","rc":[{"batb":[[1,1.63,1.01],[2,1.5,10.89]],"ltp":2.2,"tv":33.04,"id":67083366}]}]}
{"op":"mcm","clk":"11921417446","pt":1724152948716,"mc":[{"id":"1.232019003","rc":[{"batb":[[0,1.52,10.89],[1,1.51,10],[2,1.44,6.4]],"ltp":1.83,"tv":19.86,"id":72857116}]}]}
{"op":"mcm","clk":"11921417483","pt":1724152949847,"mc":[{"id":"1.232019003","rc":[{"batb":[[0,1.63,1.95],[1,1.5,10.89],[2,1.44,7.16]],"ltp":2.2,"tv":33.04,"id":67083366}]}]}
{"op":"mcm","clk":"11921417567","pt":1724152952435,"mc":[{"id":"1.232019003","rc":[{"batb":[[0,1.65,10.94],[1,1.64,4],[2,1.63,1.01]],"ltp":2.2,"tv":33.04,"id":67083366},{"batb":[[0,1.51,10.89],[1,1.44,6.4],[2,1.43,116.28]],"ltp":1.83,"tv":19.86,"id":72857116}]}]}
{"op":"mcm","clk":"11921417691","pt":1724152954950,"mc":[{"id":"1.232019003","rc":[{"batb":[[1,1.63,1.01],[2,1.5,10.89]],"ltp":2.2,"tv":33.04,"id":67083366},{"batb":[[0,1.52,10.89],[1,1.51,10],[2,1.44,6.4]],"ltp":1.83,"tv":19.86,"id":72857116}]}]}
{"op":"mcm","clk":"11921417746","pt":1724152955826,"mc":[{"id":"1.232019003","rc":[{"batb":[[0,1.63,1.95],[1,1.5,10.89],[2,1.44,7.16]],"ltp":2.2,"tv":33.04,"id":67083366}]}]}
{"op":"mcm","clk":"11921417795","pt":1724152957348,"mc":[{"id":"1.232019003","rc":[{"batb":[[0,1.64,4.94],[1,1.63,1.01],[2,1.5,10.89]],"ltp":2.2,"tv":33.04,"id":67083366}]}]}
{"op":"mcm","clk":"11921417835","pt":1724152958415,"mc":[{"id":"1.232019003","rc":[{"batb":[[0,1.65,10.94],[1,1.64,4],[2,1.63,1.01]],"ltp":2.2,"tv":33.04,"id":67083366},{"batb":[[0,1.51,10.89],[1,1.44,6.4],[2,1.43,116.28]],"ltp":1.83,"tv":19.86,"id":72857116}]}]}
{"op":"mcm","clk":"11921417884","pt":1724152959753,"mc":[{"id":"1.232019003","rc":[{"batb":[[1,1.63,1.01],[2,1.5,10.89]],"ltp":2.2,"tv":33.04,"id":67083366}]}]}
{"op":"mcm","clk":"11921418014","pt":1724152962036,"mc":[{"id":"1.232019003","rc":[{"batb":[[0,1.64,4.94]],"ltp":2.2,"tv":33.04,"id":67083366},{"batb":[[0,1.52,10.89],[1,1.51,10],[2,1.44,6.4]],"ltp":1.83,"tv":19.86,"id":72857116}]}]}
{"op":"mcm","clk":"11921418132","pt":1724152964345,"mc":[{"id":"1.232019003","rc":[{"batb":[[0,1.63,1.95],[1,1.5,10.89],[2,1.44,7.16]],"ltp":2.2,"tv":33.04,"id":67083366}]}]}
{"op":"mcm","clk":"11921418163","pt":1724152965427,"mc":[{"id":"1.232019003","rc":[{"batb":[[0,1.51,10.89],[1,1.44,6.4],[2,1.43,116.28]],"ltp":1.83,"tv":19.86,"id":72857116}]}]}
{"op":"mcm","clk":"11921418287","pt":1724152968226,"mc":[{"id":"1.232019003","rc":[{"batb":[[0,1.65,10.94],[1,1.64,4],[2,1.63,1.01]],"ltp":2.2,"tv":33.04,"id":67083366},{"batb":[[0,1.52,10.89],[1,1.51,10],[2,1.44,6.4]],"ltp":1.83,"tv":19.86,"id":72857116}]}]}
{"op":"mcm","clk":"11921418357","pt":1724152970445,"mc":[{"id":"1.232019003","rc":[{"batb":[[1,1.63,1.01],[2,1.5,10.89]],"ltp":2.2,"tv":33.04,"id":67083366}]}]}
{"op":"mcm","clk":"11921418404","pt":1724152971332,"mc":[{"id":"1.232019003","rc":[{"batb":[[0,1.51,10.89],[1,1.44,6.4],[2,1.43,116.28]],"ltp":1.83,"tv":19.86,"id":72857116}]}]}
{"op":"mcm","clk":"11921418419","pt":1724152971756,"mc":[{"id":"1.232019003","rc":[{"batb":[[0,1.63,1.95],[1,1.5,10.89],[2,1.44,7.16]],"ltp":2.2,"tv":33.04,"id":67083366}]}]}
{"op":"mcm","clk":"11921418506","pt":1724152973957,"mc":[{"id":"1.232019003","rc":[{"batb":[[0,1.64,4.94],[1,1.63,1.01],[2,1.5,10.89]],"ltp":2.2,"tv":33.04,"id":67083366},{"batb":[[0,1.52,10.89],[1,1.51,10],[2,1.44,6.4]],"ltp":1.83,"tv":19.86,"id":72857116}]}]}
{"op":"mcm","clk":"11921418539","pt":1724152974653,"mc":[{"id":"1.232019003","rc":[{"batb":[[0,1.65,10.94],[1,1.64,4],[2,1.63,1.01]],"ltp":2.2,"tv":33.04,"id":67083366}]}]}
{"op":"mcm","clk":"11921418617","pt":1724152976637,"mc":[{"id":"1.232019003","rc":[{"batb":[[1,1.63,1.01],[2,1.5,10.89]],"ltp":2.2,"tv":33.04,"id":67083366}]}]}
{"op":"mcm","clk":"11921418682","pt":1724152978136,"mc":[{"id":"1.232019003","rc":[{"batb":[[0,1.63,1.95],[1,1.5,10.89],[2,1.44,7.16]],"ltp":2.2,"tv":33.04,"id":67083366},{"batb":[[0,1.51,10.89],[1,1.44,6.4],[2,1.43,116.28]],"ltp":1.83,"tv":19.86,"id":72857116}]}]}
{"op":"mcm","clk":"11921418746","pt":1724152979475,"mc":[{"id":"1.232019003","rc":[{"batb":[[0,1.64,4.94],[1,1.63,1.01],[2,1.5,10.89]],"ltp":2.2,"tv":33.04,"id":67083366}]}]}
{"op":"mcm","clk":"11921418845","pt":1724152981354,"mc":[{"id":"1.232019003","rc":[{"batb":[[0,1.65,10.94],[1,1.64,4],[2,1.63,1.01]],"ltp":2.2,"tv":33.04,"id":67083366},{"batb":[[0,1.52,10.89],[1,1.51,10],[2,1.44,6.4]],"ltp":1.83,"tv":19.86,"id":72857116}]}]}
{"op":"mcm","clk":"11921418880","pt":1724152981875,"mc":[{"id":"1.232019003","rc":[{"batb":[[1,1.63,1.01],[2,1.5,10.89]],"ltp":2.2,"tv":33.04,"id":67083366}]}]}
{"op":"mcm","clk":"11921419037","pt":1724152984969,"mc":[{"id":"1.232019003","rc":[{"batb":[[0,1.64,4.94]],"ltp":2.2,"tv":33.04,"id":67083366},{"batb":[[0,1.51,10.89],[1,1.44,6.4],[2,1.43,116.28]],"ltp":1.83,"tv":19.86,"id":72857116}]}]}
{"op":"mcm","clk":"11921419161","pt":1724152987491,"mc":[{"id":"1.232019003","rc":[{"batb":[[0,1.63,1.95],[1,1.5,10.89],[2,1.44,7.16]],"ltp":2.2,"tv":33.04,"id":67083366},{"batb":[[0,1.52,10.89],[1,1.51,10],[2,1.44,6.4]],"ltp":1.83,"tv":19.86,"id":72857116}]}]}
{"op":"mcm","clk":"11921419254","pt":1724152989560,"mc":[{"id":"1.232019003","rc":[{"batb":[[0,1.64,4.94],[1,1.63,1.01],[2,1.5,10.89]],"ltp":2.2,"tv":33.04,"id":67083366}]}]}
{"op":"mcm","clk":"11921419278","pt":1724152990176,"mc":[{"id":"1.232019003","rc":[{"batb":[[0,1.65,10.94],[1,1.64,4],[2,1.63,1.01]],"ltp":2.2,"tv":33.04,"id":67083366}]}]}
{"op":"mcm","clk":"11921419294","pt":1724152990794,"mc":[{"id":"1.232019003","rc":[{"batb":[[0,1.51,10.89],[1,1.44,6.4],[2,1.43,116.28]],"ltp":1.83,"tv":19.86,"id":72857116}]}]}
{"op":"mcm","clk":"11921419368","pt":1724152992285,"mc":[{"id":"1.232019003","rc":[{"batb":[[1,1.63,1.01],[2,1.5,10.89]],"ltp":2.2,"tv":33.04,"id":67083366}]}]}
{"op":"mcm","clk":"11921419435","pt":1724152993570,"mc":[{"id":"1.232019003","rc":[{"batb":[[0,1.63,1.95],[1,1.5,10.89],[2,1.44,7.16]],"ltp":2.2,"tv":33.04,"id":67083366},{"batb":[[0,1.52,10.89],[1,1.51,10],[2,1.44,6.4]],"ltp":1.83,"tv":19.86,"id":72857116}]}]}
{"op":"mcm","clk":"11921419510","pt":1724152995063,"mc":[{"id":"1.232019003","rc":[{"batb":[[0,1.64,4.94],[1,1.63,1.01],[2,1.5,10.89]],"ltp":2.2,"tv":33.04,"id":67083366}]}]}
{"op":"mcm","clk":"11921419609","pt":1724152997384,"mc":[{"id":"1.232019003","rc":[{"batb":[[0,1.65,10.94]],"ltp":2.2,"tv":33.04,"id":67083366},{"batb":[[0,1.51,10.89],[1,1.44,6.4],[2,1.43,116.28]],"ltp":1.83,"tv":19.86,"id":72857116}]}]}
{"op":"mcm","clk":"11921419777","pt":1724153000580,"mc":[{"id":"1.232019003","rc":[{"batb":[[0,1.64,4.94]],"ltp":2.2,"tv":33.04,"id":67083366},{"batb":[[0,1.52,10.89],[1,1.51,10],[2,1.44,6.4]],"ltp":1.83,"tv":19.86,"id":72857116}]}]}
{"op":"mcm","clk":"11921419852","pt":1724153002899,"mc":[{"id":"1.232019003","rc":[{"batb":[[0,1.63,1.95],[1,1.5,10.89],[2,1.44,7.16]],"ltp":2.2,"tv":33.04,"id":67083366}]}]}
{"op":"mcm","clk":"11921419902","pt":1724153003986,"mc":[{"id":"1.232019003","rc":[{"batb":[[0,1.51,10.89],[1,1.44,6.4],[2,1.43,116.28]],"ltp":1.83,"tv":19.86,"id":72857116}]}]}
{"op":"mcm","clk":"11921420061","pt":1724153008378,"mc":[{"id":"1.232019003","rc":[{"batb":[[0,1.64,4.94],[1,1.63,1.01],[2,1.5,10.89]],"ltp":2.2,"tv":33.04,"id":67083366},{"batb":[[0,1.52,10.89],[1,1.51,10],[2,1.44,6.4]],"ltp":1.83,"tv":19.86,"id":72857116}]}]}
{"op":"mcm","clk":"11921420075","pt":1724153008784,"mc":[{"id":"1.232019003","rc":[{"batb":[[0,1.65,10.94],[1,1.64,4],[2,1.63,1.01]],"ltp":2.2,"tv":33.04,"id":67083366}]}]}
{"op":"mcm","clk":"11921420149","pt":1724153010696,"mc":[{"id":"1.232019003","rc":[{"batb":[[1,1.63,1.01],[2,1.5,10.89]],"ltp":2.2,"tv":33.04,"id":67083366}]}]}
{"op":"mcm","clk":"11921420232","pt":1724153012602,"mc":[{"id":"1.232019003","rc":[{"batb":[[0,1.63,1.95],[1,1.5,10.89],[2,1.44,7.16]],"ltp":2.2,"tv":33.04,"id":67083366},{"batb":[[0,1.51,10.89],[1,1.44,6.4],[2,1.43,116.28]],"ltp":1.83,"tv":19.86,"id":72857116}]}]}
{"op":"mcm","clk":"11921420239","pt":1724153012802,"mc":[{"id":"1.232019003","rc":[{"batb":[[0,1.64,4.94],[1,1.63,1.01],[2,1.5,10.89]],"ltp":2.2,"tv":33.04,"id":67083366}]}]}
{"op":"mcm","clk":"11921420340","pt":1724153015187,"mc":[{"id":"1.232019003","rc":[{"batb":[[0,1.63,1.95],[1,1.5,10.89],[2,1.44,7.16]],"ltp":2.2,"tv":33.04,"id":67083366},{"batb":[[0,1.52,10.89],[1,1.51,10],[2,1.44,6.4]],"ltp":1.83,"tv":19.86,"id":72857116}]}]}
{"op":"mcm","clk":"11921420478","pt":1724153018586,"mc":[{"id":"1.232019003","rc":[{"batb":[[0,1.64,4.94],[1,1.63,1.01],[2,1.5,10.89]],"ltp":2.2,"tv":33.04,"id":67083366},{"batb":[[0,1.51,10.89],[1,1.44,6.4],[2,1.43,116.28]],"ltp":1.83,"tv":19.86,"id":72857116}]}]}
{"op":"mcm","clk":"11921420491","pt":1724153018901,"mc":[{"id":"1.232019003","rc":[{"batb":[[0,1.65,10.94],[1,1.64,4],[2,1.63,1.01]],"ltp":2.2,"tv":33.04,"id":67083366}]}]}
{"op":"mcm","clk":"11921420591","pt":1724153021397,"mc":[{"id":"1.232019003","rc":[{"batb":[[1,1.63,1.01],[2,1.5,10.89]],"ltp":2.2,"tv":33.04,"id":67083366},{"batb":[[0,1.52,10.89],[1,1.51,10],[2,1.44,6.4]],"ltp":1.83,"tv":19.86,"id":72857116}]}]}
{"op":"mcm","clk":"11921420664","pt":1724153022533,"mc":[{"id":"1.232019003","rc":[{"batb":[[0,1.63,1.95],[1,1.5,10.89],[2,1.44,7.16]],"ltp":2.2,"tv":33.04,"id":67083366}]}]}
{"op":"mcm","clk":"11921420806","pt":1724153025306,"mc":[{"id":"1.232019003","rc":[{"batb":[[0,1.64,4.94],[1,1.63,1.01],[2,1.5,10.89]],"ltp":2.2,"tv":33.04,"id":67083366},{"batb":[[0,1.51,10.89],[1,1.44,6.4],[2,1.43,116.28]],"ltp":1.83,"tv":19.86,"id":72857116}]}]}
{"op":"mcm","clk":"11921420823","pt":1724153025716,"mc":[{"id":"1.232019003","rc":[{"batb":[[0,1.65,10.94],[1,1.64,4],[2,1.63,1.01]],"ltp":2.2,"tv":33.04,"id":67083366}]}]}
{"op":"mcm","clk":"11921420918","pt":1724153027922,"mc":[{"id":"1.232019003","rc":[{"batb":[[1,1.63,1.01],[2,1.5,10.89]],"ltp":2.2,"tv":33.04,"id":67083366},{"batb":[[0,1.52,10.89],[1,1.51,10],[2,1.44,6.4]],"ltp":1.83,"tv":19.86,"id":72857116}]}]}
{"op":"mcm","clk":"11921420958","pt":1724153029104,"mc":[{"id":"1.232019003","rc":[{"batb":[[0,1.63,1.95],[1,1.5,10.89],[2,1.44,7.16]],"ltp":2.2,"tv":33.04,"id":67083366}]}]}
{"op":"mcm","clk":"11921421042","pt":1724153031523,"mc":[{"id":"1.232019003","rc":[{"batb":[[0,1.51,10.89],[1,1.44,6.4],[2,1.43,116.28]],"ltp":1.83,"tv":19.86,"id":72857116}]}]}
{"op":"mcm","clk":"11921421060","pt":1724153032034,"mc":[{"id":"1.232019003","rc":[{"batb":[[0,1.65,10.94],[1,1.64,4],[2,1.63,1.01]],"ltp":2.2,"tv":33.04,"id":67083366}]}]}
{"op":"mcm","clk":"11921421155","pt":1724153034301,"mc":[{"id":"1.232019003","rc":[{"batb":[[1,1.63,1.01],[2,1.5,10.89]],"ltp":2.2,"tv":33.04,"id":67083366},{"batb":[[0,1.52,10.89],[1,1.51,10],[2,1.44,6.4]],"ltp":1.83,"tv":19.86,"id":72857116}]}]}
{"op":"mcm","clk":"11921421221","pt":1724153035546,"mc":[{"id":"1.232019003","rc":[{"batb":[[0,1.63,1.95],[1,1.5,10.89],[2,1.44,7.16]],"ltp":2.2,"tv":33.04,"id":67083366}]}]}
{"op":"mcm","clk":"11921421316","pt":1724153038415,"mc":[{"id":"1.232019003","rc":[{"batb":[[0,1.65,10.94],[1,1.64,4],[2,1.63,1.01]],"ltp":2.2,"tv":33.04,"id":67083366},{"batb":[[0,1.51,10.89],[1,1.44,6.4],[2,1.43,116.28]],"ltp":1.83,"tv":19.86,"id":72857116}]}]}
{"op":"mcm","clk":"11921421411","pt":1724153040424,"mc":[{"id":"1.232019003","rc":[{"batb":[[1,1.63,1.01],[2,1.5,10.89]],"ltp":2.2,"tv":33.04,"id":67083366}]}]}
{"op":"mcm","clk":"11921421421","pt":1724153040631,"mc":[{"id":"1.232019003","rc":[{"batb":[[0,1.52,10.89],[1,1.51,10],[2,1.44,6.4]],"ltp":1.83,"tv":19.86,"id":72857116}]}]}
{"op":"mcm","clk":"11921421482","pt":1724153042023,"mc":[{"id":"1.232019003","rc":[{"batb":[[0,1.63,1.95],[1,1.5,10.89],[2,1.44,7.16]],"ltp":2.2,"tv":33.04,"id":67083366}]}]}
{"op":"mcm","clk":"11921421600","pt":1724153044338,"mc":[{"id":"1.232019003","rc":[{"batb":[[0,1.65,10.94],[1,1.64,4],[2,1.63,1.01]],"ltp":2.2,"tv":33.04,"id":67083366},{"batb":[[0,1.51,10.89],[1,1.44,6.4],[2,1.43,116.28]],"ltp":1.83,"tv":19.86,"id":72857116}]}]}
{"op":"mcm","clk":"11921421720","pt":1724153046463,"mc":[{"id":"1.232019003","rc":[{"batb":[[1,1.63,1.01],[2,1.5,10.89]],"ltp":2.2,"tv":33.04,"id":67083366},{"batb":[[0,1.52,10.89],[1,1.51,10],[2,1.44,6.4]],"ltp":1.83,"tv":19.86,"id":72857116}]}]}
{"op":"mcm","clk":"11921421792","pt":1724153047966,"mc":[{"id":"1.232019003","rc":[{"batb":[[0,1.63,1.95],[1,1.5,10.89],[2,1.44,7.16]],"ltp":2.2,"tv":33.04,"id":67083366}]}]}
{"op":"mcm","clk":"11921421909","pt":1724153050239,"mc":[{"id":"1.232019003","rc":[{"batb":[[0,1.65,10.94],[1,1.64,4],[2,1.63,1.01]],"ltp":2.2,"tv":33.04,"id":67083366},{"batb":[[0,1.51,10.89],[1,1.44,6.4],[2,1.43,116.28]],"ltp":1.83,"tv":19.86,"id":72857116}]}]}
{"op":"mcm","clk":"11921421993","pt":1724153052136,"mc":[{"id":"1.232019003","rc":[{"batb":[[1,1.63,1.01],[2,1.5,10.89]],"ltp":2.2,"tv":33.04,"id":67083366},{"batb":[[0,1.52,10.89],[1,1.51,10],[2,1.44,6.4]],"ltp":1.83,"tv":19.86,"id":72857116}]}]}
{"op":"mcm","clk":"11921422044","pt":1724153053724,"mc":[{"id":"1.232019003","rc":[{"batb":[[0,1.63,1.95],[1,1.5,10.89],[2,1.44,7.16]],"ltp":2.2,"tv":33.04,"id":67083366}]}]}
{"op":"mcm","clk":"11921422126","pt":1724153055627,"mc":[{"id":"1.232019003","rc":[{"batb":[[0,1.51,10.89],[1,1.44,6.4],[2,1.43,116.28]],"ltp":1.83,"tv":19.86,"id":72857116}]}]}
{"op":"mcm","clk":"11921422158","pt":1724153056249,"mc":[{"id":"1.232019003","rc":[{"batb":[[0,1.65,10.94],[1,1.64,4],[2,1.63,1.01]],"ltp":2.2,"tv":33.04,"id":67083366}]}]}
{"op":"mcm","clk":"11921422217","pt":1724153058353,"mc":[{"id":"1.232019003","rc":[{"batb":[[1,1.63,1.01],[2,1.5,10.89]],"ltp":2.2,"tv":33.04,"id":67083366},{"batb":[[0,1.52,10.89],[1,1.51,10],[2,1.44,6.4]],"ltp":1.83,"tv":19.86,"id":72857116}]}]}
{"op":"mcm","clk":"11921422266","pt":1724153059537,"mc":[{"id":"1.232019003","rc":[{"batb":[[0,1.63,1.95],[1,1.5,10.89],[2,1.44,7.16]],"ltp":2.2,"tv":33.04,"id":67083366}]}]}
{"op":"mcm","clk":"11921422381","pt":1724153062340,"mc":[{"id":"1.232019003","rc":[{"batb":[[0,1.65,10.94],[1,1.64,4],[2,1.63,1.01]],"ltp":2.2,"tv":33.04,"id":67083366},{"batb":[[0,1.51,10.89],[1,1.44,6.4],[2,1.43,116.28]],"ltp":1.83,"tv":19.86,"id":72857116}]}]}
{"op":"mcm","clk":"11921422455","pt":1724153064448,"mc":[{"id":"1.232019003","rc":[{"batb":[[1,1.63,1.01],[2,1.5,10.89]],"ltp":2.2,"tv":33.04,"id":67083366},{"batb":[[0,1.52,10.89],[1,1.51,10],[2,1.44,6.4]],"ltp":1.83,"tv":19.86,"id":72857116}]}]}
{"op":"mcm","clk":"11921422507","pt":1724153065780,"mc":[{"id":"1.232019003","rc":[{"batb":[[0,1.63,1.95],[1,1.5,10.89],[2,1.44,7.16]],"ltp":2.2,"tv":33.04,"id":67083366}]}]}
{"op":"mcm","clk":"11921422631","pt":1724153068184,"mc":[{"id":"1.232019003","rc":[{"batb":[[0,1.65,10.94],[1,1.64,4],[2,1.63,1.01]],"ltp":2.2,"tv":33.04,"id":67083366},{"batb":[[0,1.51,10.89],[1,1.44,6.4],[2,1.43,116.28]],"ltp":1.83,"tv":19.86,"id":72857116}]}]}
{"op":"mcm","clk":"11921422733","pt":1724153070562,"mc":[{"id":"1.232019003","rc":[{"batb":[[1,1.63,1.01],[2,1.5,10.89]],"ltp":2.2,"tv":33.04,"id":67083366},{"batb":[[0,1.52,10.89],[1,1.51,10],[2,1.44,6.4]],"ltp":1.83,"tv":19.86,"id":72857116}]}]}
{"op":"mcm","clk":"11921422778","pt":1724153071646,"mc":[{"id":"1.232019003","rc":[{"batb":[[0,1.63,1.95],[1,1.5,10.89],[2,1.44,7.16]],"ltp":2.2,"tv":33.04,"id":67083366}]}]}
{"op":"mcm","clk":"11921422873","pt":1724153074377,"mc":[{"id":"1.232019003","rc":[{"batb":[[0,1.65,10.94],[1,1.64,4],[2,1.63,1.01]],"ltp":2.2,"tv":33.04,"id":67083366},{"batb":[[0,1.51,10.89],[1,1.44,6.4],[2,1.43,116.28]],"ltp":1.83,"tv":19.86,"id":72857116}]}]}
{"op":"mcm","clk":"11921422974","pt":1724153076387,"mc":[{"id":"1.232019003","rc":[{"batb":[[1,1.63,1.01],[2,1.5,10.89]],"ltp":2.2,"tv":33.04,"id":67083366}]}]}
{"op":"mcm","clk":"11921422994","pt":1724153076695,"mc":[{"id":"1.232019003","rc":[{"batb":[[0,1.52,10.89],[1,1.51,10],[2,1.44,6.4]],"ltp":1.83,"tv":19.86,"id":72857116}]}]}
{"op":"mcm","clk":"11921423057","pt":1724153077983,"mc":[{"id":"1.232019003","rc":[{"batb":[[0,1.63,1.95],[1,1.5,10.89],[2,1.44,7.16]],"ltp":2.2,"tv":33.04,"id":67083366}]}]}
{"op":"mcm","clk":"11921423194","pt":1724153080600,"mc":[{"id":"1.232019003","rc":[{"batb":[[0,1.65,10.94],[1,1.64,4],[2,1.63,1.01]],"ltp":2.2,"tv":33.04,"id":67083366},{"batb":[[0,1.51,10.89],[1,1.44,6.4],[2,1.43,116.28]],"ltp":1.83,"tv":19.86,"id":72857116}]}]}
{"op":"mcm","clk":"11921423273","pt":1724153082979,"mc":[{"id":"1.232019003","rc":[{"batb":[[1,1.63,1.01],[2,1.5,10.89]],"ltp":2.2,"tv":33.04,"id":67083366},{"batb":[[0,1.52,10.89],[1,1.51,10],[2,1.44,6.4]],"ltp":1.83,"tv":19.86,"id":72857116}]}]}
{"op":"mcm","clk":"11921423309","pt":1724153083905,"mc":[{"id":"1.232019003","rc":[{"batb":[[0,1.63,1.95],[1,1.5,10.89],[2,1.44,7.16]],"ltp":2.2,"tv":33.04,"id":67083366}]}]}
{"op":"mcm","clk":"11921423449","pt":1724153086585,"mc":[{"id":"1.232019003","rc":[{"batb":[[0,1.65,10.94],[1,1.64,4],[2,1.63,1.01]],"ltp":2.2,"tv":33.04,"id":67083366},{"batb":[[0,1.51,10.89],[1,1.44,6.4],[2,1.43,116.28]],"ltp":1.83,"tv":19.86,"id":72857116}]}]}
{"op":"mcm","clk":"11921423560","pt":1724153089118,"mc":[{"id":"1.232019003","rc":[{"batb":[[1,1.63,1.01],[2,1.5,10.89]],"ltp":2.2,"tv":33.04,"id":67083366},{"batb":[[0,1.52,10.89],[1,1.51,10],[2,1.44,6.4]],"ltp":1.83,"tv":19.86,"id":72857116}]}]}
{"op":"mcm","clk":"11921423593","pt":1724153089992,"mc":[{"id":"1.232019003","rc":[{"batb":[[0,1.63,1.95],[1,1.5,10.89],[2,1.44,7.16]],"ltp":2.2,"tv":33.04,"id":67083366}]}]}
{"op":"mcm","clk":"11921423694","pt":1724153092485,"mc":[{"id":"1.232019003","rc":[{"batb":[[0,1.65,10.94],[1,1.64,4],[2,1.63,1.01]],"ltp":2.2,"tv":33.04,"id":67083366},{"batb":[[0,1.51,10.89],[1,1.44,6.4],[2,1.43,116.28]],"ltp":1.83,"tv":19.86,"id":72857116}]}]}
{"op":"mcm","clk":"11921423797","pt":1724153095009,"mc":[{"id":"1.232019003","rc":[{"batb":[[1,1.63,1.01],[2,1.5,10.89]],"ltp":2.2,"tv":33.04,"id":67083366},{"batb":[[0,1.52,10.89],[1,1.51,10],[2,1.44,6.4]],"ltp":1.83,"tv":19.86,"id":72857116}]}]}
{"op":"mcm","clk":"11921423837","pt":1724153096093,"mc":[{"id":"1.232019003","rc":[{"batb":[[0,1.63,1.95],[1,1.5,10.89],[2,1.44,7.16]],"ltp":2.2,"tv":33.04,"id":67083366}]}]}
{"op":"mcm","clk":"11921423895","pt":1724153097284,"mc":[{"id":"1.232019003","rc":[{"batb":[[0,1.64,4.94],[1,1.63,1.01],[2,1.5,10.89]],"ltp":2.2,"tv":33.04,"id":67083366}]}]}
{"op":"mcm","clk":"11921423949","pt":1724153098474,"mc":[{"id":"1.232019003","rc":[{"batb":[[0,1.65,10.94],[1,1.64,4],[2,1.63,1.01]],"ltp":2.2,"tv":33.04,"id":67083366},{"batb":[[0,1.51,10.89],[1,1.44,6.4],[2,1.43,116.28]],"ltp":1.83,"tv":19.86,"id":72857116}]}]}
{"op":"mcm","clk":"11921423997","pt":1724153099611,"mc":[{"id":"1.232019003","rc":[{"batb":[[1,1.63,1.01],[2,1.5,10.89]],"ltp":2.2,"tv":33.04,"id":67083366}]}]}
{"op":"mcm","clk":"11921424102","pt":1724153102203,"mc":[{"id":"1.232019003","rc":[{"batb":[[0,1.64,4.94]],"ltp":2.2,"tv":33.04,"id":67083366},{"batb":[[0,1.52,10.89],[1,1.51,10],[2,1.44,6.4]],"ltp":1.83,"tv":19.86,"id":72857116}]}]}
{"op":"mcm","clk":"11921424240","pt":1724153104499,"mc":[{"id":"1.232019003","rc":[{"batb":[[0,1.63,1.95],[1,1.5,10.89],[2,1.44,7.16]],"ltp":2.2,"tv":33.04,"id":67083366}]}]}
{"op":"mcm","clk":"11921424286","pt":1724153105420,"mc":[{"id":"1.232019003","rc":[{"batb":[[0,1.51,10.89],[1,1.44,6.4],[2,1.43,116.28]],"ltp":1.83,"tv":19.86,"id":72857116}]}]}
{"op":"mcm","clk":"11921424430","pt":1724153108331,"mc":[{"id":"1.232019003","rc":[{"batb":[[0,1.65,10.94],[1,1.64,4],[2,1.63,1.01]],"ltp":2.2,"tv":33.04,"id":67083366},{"batb":[[0,1.52,10.89],[1,1.51,10],[2,1.44,6.4]],"ltp":1.83,"tv":19.86,"id":72857116}]}]}
{"op":"mcm","clk":"11921424541","pt":1724153110397,"mc":[{"id":"1.232019003","rc":[{"batb":[[1,1.63,1.01],[2,1.5,10.89]],"ltp":2.2,"tv":33.04,"id":67083366}]}]}
{"op":"mcm","clk":"11921424585","pt":1724153111707,"mc":[{"id":"1.232019003","rc":[{"batb":[[0,1.63,1.95],[1,1.5,10.89],[2,1.44,7.16]],"ltp":2.2,"tv":33.04,"id":67083366},{"batb":[[0,1.51,10.89],[1,1.44,6.4],[2,1.43,116.28]],"ltp":1.83,"tv":19.86,"id":72857116}]}]}
{"op":"mcm","clk":"11921424747","pt":1724153115320,"mc":[{"id":"1.232019003","rc":[{"batb":[[0,1.64,4.94],[1,1.63,1.01],[2,1.5,10.89]],"ltp":2.2,"tv":33.04,"id":67083366},{"batb":[[0,1.52,10.89],[1,1.51,10],[2,1.44,6.4]],"ltp":1.83,"tv":19.86,"id":72857116}]}]}
{"op":"mcm","clk":"11921424778","pt":1724153116042,"mc":[{"id":"1.232019003","rc":[{"batb":[[0,1.65,10.94],[1,1.64,4],[2,1.63,1.01]],"ltp":2.2,"tv":33.04,"id":67083366}]}]}
{"op":"mcm","clk":"11921424897","pt":1724153118416,"mc":[{"id":"1.232019003","rc":[{"batb":[[1,1.63,1.01],[2,1.5,10.89]],"ltp":2.2,"tv":33.04,"id":67083366},{"batb":[[0,1.51,10.89],[1,1.44,6.4],[2,1.43,116.28]],"ltp":1.83,"tv":19.86,"id":72857116}]}]}
{"op":"mcm","clk":"11921424970","pt":1724153119611,"mc":[{"id":"1.232019003","rc":[{"batb":[[0,1.63,1.95],[1,1.5,10.89],[2,1.44,7.16]],"ltp":2.2,"tv":33.04,"id":67083366}]}]}
{"op":"mcm","clk":"11921425297","pt":1724153126625,"mc":[{"id":"1.232019003","rc":[{"batb":[[0,1.64,4.94],[1,1.63,1.01],[2,1.5,10.89]],"ltp":2.2,"tv":33.04,"id":67083366},{"batb":[[0,1.52,10.89],[1,1.51,10],[2,1.44,6.4]],"ltp":1.83,"tv":19.86,"id":72857116}]}]}
{"op":"mcm","clk":"11921425319","pt":1724153127139,"mc":[{"id":"1.232019003","rc":[{"batb":[[0,1.65,10.94],[1,1.64,4],[2,1.63,1.01]],"ltp":2.2,"tv":33.04,"id":67083366}]}]}
{"op":"mcm","clk":"11921425374","pt":1724153128937,"mc":[{"id":"1.232019003","rc":[{"batb":[[1,1.63,1.01],[2,1.5,10.89]],"ltp":2.2,"tv":33.04,"id":67083366}]}]}
{"op":"mcm","clk":"11921425536","pt":1724153130439,"mc":[{"id":"1.232019003","rc":[{"batb":[[0,1.63,1.95],[1,1.5,10.89],[2,1.44,7.16]],"ltp":2.2,"tv":33.04,"id":67083366},{"batb":[[0,1.51,10.89],[1,1.44,6.4],[2,1.43,116.28]],"ltp":1.83,"tv":19.86,"id":72857116}]}]}
{"op":"mcm","clk":"11921425808","pt":1724153135229,"mc":[{"id":"1.232019003","rc":[{"batb":[[0,1.65,10.94],[1,1.64,4],[2,1.63,1.01]],"ltp":2.2,"tv":33.04,"id":67083366},{"batb":[[0,1.52,10.89],[1,1.51,10],[2,1.44,6.4]],"ltp":1.83,"tv":19.86,"id":72857116}]}]}
{"op":"mcm","clk":"11921425894","pt":1724153137241,"mc":[{"id":"1.232019003","rc":[{"batb":[[1,1.63,1.01],[2,1.5,10.89]],"ltp":2.2,"tv":33.04,"id":67083366}]}]}
{"op":"mcm","clk":"11921425961","pt":1724153138269,"mc":[{"id":"1.232019003","rc":[{"batb":[[0,1.51,10.89],[1,1.44,6.4],[2,1.43,116.28]],"ltp":1.83,"tv":19.86,"id":72857116}]}]}
{"op":"mcm","clk":"11921426007","pt":1724153138841,"mc":[{"id":"1.232019003","rc":[{"batb":[[0,1.63,1.95],[1,1.5,10.89],[2,1.44,7.16]],"ltp":2.2,"tv":33.04,"id":67083366}]}]}
{"op":"mcm","clk":"11921426262","pt":1724153144156,"mc":[{"id":"1.232019003","rc":[{"batb":[[0,1.64,4.94],[1,1.63,1.01],[2,1.5,10.89]],"ltp":2.2,"tv":33.04,"id":67083366},{"batb":[[0,1.52,10.89],[1,1.51,10],[2,1.44,6.4]],"ltp":1.83,"tv":19.86,"id":72857116}]}]}
{"op":"mcm","clk":"11921426298","pt":1724153144773,"mc":[{"id":"1.232019003","rc":[{"batb":[[0,1.65,10.94],[1,1.64,4],[2,1.63,1.01]],"ltp":2.2,"tv":33.04,"id":67083366}]}]}
{"op":"mcm","clk":"11921426392","pt":1724153146940,"mc":[{"id":"1.232019003","rc":[{"batb":[[1,1.63,1.01],[2,1.5,10.89]],"ltp":2.2,"tv":33.04,"id":67083366}]}]}
{"op":"mcm","clk":"11921426447","pt":1724153148272,"mc":[{"id":"1.232019003","rc":[{"batb":[[0,1.63,1.95],[1,1.5,10.89],[2,1.44,7.16]],"ltp":2.2,"tv":33.04,"id":67083366},{"batb":[[0,1.51,10.89],[1,1.44,6.4],[2,1.43,116.28]],"ltp":1.83,"tv":19.86,"id":72857116}]}]}
{"op":"mcm","clk":"11921426981","pt":1724153161556,"mc":[{"id":"1.232019003","rc":[{"batb":[[0,1.64,4.94],[1,1.63,1.01],[2,1.5,10.89]],"ltp":2.2,"tv":33.04,"id":67083366},{"batb":[[0,1.52,10.89],[1,1.51,10],[2,1.44,6.4]],"ltp":1.83,"tv":19.86,"id":72857116}]}]}
{"op":"mcm","clk":"11921427015","pt":1724153162439,"mc":[{"id":"1.232019003","rc":[{"batb":[[0,1.65,10.94],[1,1.64,4],[2,1.63,1.01]],"ltp":2.2,"tv":33.04,"id":67083366}]}]}
{"op":"mcm","clk":"11921427089","pt":1724153164536,"mc":[{"id":"1.232019003","rc":[{"batb":[[1,1.63,1.01],[2,1.5,10.89]],"ltp":2.2,"tv":33.04,"id":67083366}]}]}
{"op":"mcm","clk":"11921427131","pt":1724153165366,"mc":[{"id":"1.232019003","rc":[{"batb":[[0,1.51,10.89],[1,1.44,6.4],[2,1.43,116.28]],"ltp":1.83,"tv":19.86,"id":72857116}]}]}
{"op":"mcm","clk":"11921427158","pt":1724153165984,"mc":[{"id":"1.232019003","rc":[{"batb":[[0,1.63,1.95],[1,1.5,10.89],[2,1.44,7.16]],"ltp":2.2,"tv":33.04,"id":67083366}]}]}
{"op":"mcm","clk":"11921427491","pt":1724153172462,"mc":[{"id":"1.232019003","rc":[{"batb":[[0,1.64,4.94],[1,1.63,1.01],[2,1.5,10.89]],"ltp":2.2,"tv":33.04,"id":67083366},{"batb":[[0,1.52,10.89],[1,1.51,10],[2,1.44,6.4]],"ltp":1.83,"tv":19.86,"id":72857116}]}]}
{"op":"mcm","clk":"11921427514","pt":1724153172975,"mc":[{"id":"1.232019003","rc":[{"batb":[[0,1.65,10.94],[1,1.64,4],[2,1.63,1.01]],"ltp":2.2,"tv":33.04,"id":67083366}]}]}
{"op":"mcm","clk":"11921427625","pt":1724153174982,"mc":[{"id":"1.232019003","rc":[{"batb":[[1,1.63,1.01],[2,1.5,10.89]],"ltp":2.2,"tv":33.04,"id":67083366}]}]}
{"op":"mcm","clk":"11921427679","pt":1724153176377,"mc":[{"id":"1.232019003","rc":[{"batb":[[0,1.63,1.95],[1,1.5,10.89],[2,1.44,7.16]],"ltp":2.2,"tv":33.04,"id":67083366},{"batb":[[0,1.51,10.89],[1,1.44,6.4],[2,1.43,116.28]],"ltp":1.83,"tv":19.86,"id":72857116}]}]}
{"op":"mcm","clk":"11921427834","pt":1724153180203,"mc":[{"id":"1.232019003","rc":[{"batb":[[0,1.64,4.94],[1,1.63,1.01],[2,1.5,10.89]],"ltp":2.2,"tv":33.04,"id":67083366},{"batb":[[0,1.52,10.89],[1,1.51,10],[2,1.44,6.4]],"ltp":1.83,"tv":19.86,"id":72857116}]}]}
{"op":"mcm","clk":"11921427864","pt":1724153181004,"mc":[{"id":"1.232019003","rc":[{"batb":[[0,1.65,10.94],[1,1.64,4],[2,1.63,1.01]],"ltp":2.2,"tv":33.04,"id":67083366}]}]}
{"op":"mcm","clk":"11921427967","pt":1724153182898,"mc":[{"id":"1.232019003","rc":[{"batb":[[1,1.63,1.01],[2,1.5,10.89]],"ltp":2.2,"tv":33.04,"id":67083366}]}]}
{"op":"mcm","clk":"11921428046","pt":1724153184486,"mc":[{"id":"1.232019003","rc":[{"batb":[[0,1.63,1.95],[1,1.5,10.89],[2,1.44,7.16]],"ltp":2.2,"tv":33.04,"id":67083366},{"batb":[[0,1.51,10.89],[1,1.44,6.4],[2,1.43,116.28]],"ltp":1.83,"tv":19.86,"id":72857116}]}]}
{"op":"mcm","clk":"11921428162","pt":1724153187476,"mc":[{"id":"1.232019003","rc":[{"batb":[[0,1.64,4.94],[1,1.63,1.01],[2,1.5,10.89]],"ltp":2.2,"tv":33.04,"id":67083366},{"batb":[[0,1.52,10.89],[1,1.51,10],[2,1.44,6.4]],"ltp":1.83,"tv":19.86,"id":72857116}]}]}
{"op":"mcm","clk":"11921428174","pt":1724153187777,"mc":[{"id":"1.232019003","rc":[{"batb":[[0,1.65,10.94],[1,1.64,4],[2,1.63,1.01]],"ltp":2.2,"tv":33.04,"id":67083366}]}]}
{"op":"mcm","clk":"11921428246","pt":1724153189786,"mc":[{"id":"1.232019003","rc":[{"batb":[[1,1.63,1.01],[2,1.5,10.89]],"ltp":2.2,"tv":33.04,"id":67083366}]}]}
{"op":"mcm","clk":"11921428324","pt":1724153191482,"mc":[{"id":"1.232019003","rc":[{"batb":[[0,1.63,1.95],[1,1.5,10.89],[2,1.44,7.16]],"ltp":2.2,"tv":33.04,"id":67083366},{"batb":[[0,1.51,10.89],[1,1.44,6.4],[2,1.43,116.28]],"ltp":1.83,"tv":19.86,"id":72857116}]}]}
{"op":"mcm","clk":"11921428503","pt":1724153195104,"mc":[{"id":"1.232019003","rc":[{"batb":[[0,1.65,10.94],[1,1.64,4],[2,1.63,1.01]],"ltp":2.2,"tv":33.04,"id":67083366},{"batb":[[0,1.52,10.89],[1,1.51,10],[2,1.44,6.4]],"ltp":1.83,"tv":19.86,"id":72857116}]}]}
{"op":"mcm","clk":"11921428583","pt":1724153197411,"mc":[{"id":"1.232019003","rc":[{"batb":[[1,1.63,1.01],[2,1.5,10.89]],"ltp":2.2,"tv":33.04,"id":67083366}]}]}
{"op":"mcm","clk":"11921428621","pt":1724153198388,"mc":[{"id":"1.232019003","rc":[{"batb":[[0,1.51,10.89],[1,1.44,6.4],[2,1.43,116.28]],"ltp":1.83,"tv":19.86,"id":72857116}]}]}
{"op":"mcm","clk":"11921428636","pt":1724153198696,"mc":[{"id":"1.232019003","rc":[{"batb":[[0,1.63,1.95],[1,1.5,10.89],[2,1.44,7.16]],"ltp":2.2,"tv":33.04,"id":67083366}]}]}
{"op":"mcm","clk":"11921428714","pt":1724153200607,"mc":[{"id":"1.232019003","rc":[{"batb":[[0,1.64,4.94],[1,1.63,1.01],[2,1.5,10.89]],"ltp":2.2,"tv":33.04,"id":67083366},{"batb":[[0,1.52,10.89],[1,1.51,10],[2,1.44,6.4]],"ltp":1.83,"tv":19.86,"id":72857116}]}]}
{"op":"mcm","clk":"11921428728","pt":1724153200913,"mc":[{"id":"1.232019003","rc":[{"batb":[[0,1.65,10.94],[1,1.64,4],[2,1.63,1.01]],"ltp":2.2,"tv":33.04,"id":67083366}]}]}
{"op":"mcm","clk":"11921428799","pt":1724153203310,"mc":[{"id":"1.232019003","rc":[{"batb":[[1,1.63,1.01],[2,1.5,10.89]],"ltp":2.2,"tv":33.04,"id":67083366}]}]}
{"op":"mcm","clk":"11921428840","pt":1724153204384,"mc":[{"id":"1.232019003","rc":[{"batb":[[0,1.63,1.95],[1,1.5,10.89],[2,1.44,7.16]],"ltp":2.2,"tv":33.04,"id":67083366},{"batb":[[0,1.51,10.89],[1,1.44,6.4],[2,1.43,116.28]],"ltp":1.83,"tv":19.86,"id":72857116}]}]}
{"op":"mcm","clk":"11921428893","pt":1724153205614,"mc":[{"id":"1.232019003","rc":[{"batb":[[0,1.64,4.94],[1,1.63,1.01],[2,1.5,10.89]],"ltp":2.2,"tv":33.04,"id":67083366}]}]}
{"op":"mcm","clk":"11921428989","pt":1724153208430,"mc":[{"id":"1.232019003","rc":[{"batb":[[0,1.63,1.95],[1,1.5,10.89],[2,1.44,7.16]],"ltp":2.2,"tv":33.04,"id":67083366}]}]}
{"op":"mcm","clk":"11921428996","pt":1724153208636,"mc":[{"id":"1.232019003","rc":[{"batb":[[0,1.52,10.89],[1,1.51,10],[2,1.44,6.4]],"ltp":1.83,"tv":19.86,"id":72857116}]}]}
{"op":"mcm","clk":"11921429137","pt":1724153212139,"mc":[{"id":"1.232019003","rc":[{"batb":[[0,1.64,4.94],[1,1.63,1.01],[2,1.5,10.89]],"ltp":2.2,"tv":33.04,"id":67083366},{"batb":[[0,1.51,10.89],[1,1.44,6.4],[2,1.43,116.28]],"ltp":1.83,"tv":19.86,"id":72857116}]}]}
{"op":"mcm","clk":"11921429171","pt":1724153212711,"mc":[{"id":"1.232019003","rc":[{"batb":[[0,1.65,10.94],[1,1.64,4],[2,1.63,1.01]],"ltp":2.2,"tv":33.04,"id":67083366}]}]}
{"op":"mcm","clk":"11921429282","pt":1724153215228,"mc":[{"id":"1.232019003","rc":[{"batb":[[1,1.63,1.01],[2,1.5,10.89]],"ltp":2.2,"tv":33.04,"id":67083366},{"batb":[[0,1.52,10.89],[1,1.51,10],[2,1.44,6.4]],"ltp":1.83,"tv":19.86,"id":72857116}]}]}
{"op":"mcm","clk":"11921429370","pt":1724153216456,"mc":[{"id":"1.232019003","rc":[{"batb":[[0,1.63,1.95],[1,1.5,10.89],[2,1.44,7.16]],"ltp":2.2,"tv":33.04,"id":67083366}]}]}
{"op":"mcm","clk":"11921429499","pt":1724153218823,"mc":[{"id":"1.232019003","rc":[{"batb":[[0,1.51,10.89],[1,1.44,6.4],[2,1.43,116.28]],"ltp":1.83,"tv":19.86,"id":72857116}]}]}
{"op":"mcm","clk":"11921429623","pt":1724153221245,"mc":[{"id":"1.232019003","rc":[{"batb":[[0,1.64,4.94],[1,1.63,1.01],[2,1.5,10.89]],"ltp":2.2,"tv":33.04,"id":67083366},{"batb":[[0,1.53,10.89],[1,1.51,10],[2,1.44,6.4]],"ltp":1.83,"tv":19.86,"id":72857116}]}]}
{"op":"mcm","clk":"11921429906","pt":1724153226237,"mc":[{"id":"1.232019003","rc":[{"batb":[[0,1.65,10.94],[1,1.64,4],[2,1.63,1.01]],"ltp":2.2,"tv":33.04,"id":67083366}]}]}
{"op":"mcm","clk":"11921429999","pt":1724153228244,"mc":[{"id":"1.232019003","rc":[{"batb":[[1,1.63,1.01],[2,1.5,10.89]],"ltp":2.2,"tv":33.04,"id":67083366}]}]}
{"op":"mcm","clk":"11921430037","pt":1724153229233,"mc":[{"id":"1.232019003","rc":[{"batb":[[0,1.51,10.89],[1,1.44,6.4],[2,1.43,116.28]],"ltp":1.83,"tv":19.86,"id":72857116}]}]}
{"op":"mcm","clk":"11921430180","pt":1724153231441,"mc":[{"id":"1.232019003","rc":[{"batb":[[0,1.66,4.94],[1,1.65,10],[2,1.63,1.01]],"ltp":2.2,"tv":33.04,"id":67083366},{"batb":[[0,1.52,10.89],[1,1.51,10],[2,1.44,6.4]],"ltp":1.83,"tv":19.86,"id":72857116}]}]}
{"op":"mcm","clk":"11921430246","pt":1724153232639,"mc":[{"id":"1.232019003","rc":[{"batb":[[1,1.63,1.01],[2,1.5,10.89]],"ltp":2.2,"tv":33.04,"id":67083366}]}]}
{"op":"mcm","clk":"11921430345","pt":1724153234745,"mc":[{"id":"1.232019003","rc":[{"batb":[[0,1.63,1.95],[1,1.5,10.89],[2,1.44,7.16]],"ltp":2.2,"tv":33.04,"id":67083366}]}]}
{"op":"mcm","clk":"11921430416","pt":1724153236240,"mc":[{"id":"1.232019003","rc":[{"batb":[[0,1.51,10.89],[1,1.44,6.4],[2,1.43,116.28]],"ltp":1.83,"tv":19.86,"id":72857116}]}]}
{"op":"mcm","clk":"11921430525","pt":1724153238457,"mc":[{"id":"1.232019003","rc":[{"batb":[[0,1.64,4.94],[1,1.63,1.01],[2,1.5,10.89]],"ltp":2.2,"tv":33.04,"id":67083366},{"batb":[[0,1.52,10.89],[1,1.51,10],[2,1.44,6.4]],"ltp":1.83,"tv":19.86,"id":72857116}]}]}
{"op":"mcm","clk":"11921430540","pt":1724153238867,"mc":[{"id":"1.232019003","rc":[{"batb":[[0,1.65,10.94],[1,1.64,4],[2,1.63,1.01]],"ltp":2.2,"tv":33.04,"id":67083366}]}]}
{"op":"mcm","clk":"11921430643","pt":1724153241033,"mc":[{"id":"1.232019003","rc":[{"batb":[[1,1.63,1.01],[2,1.5,10.89]],"ltp":2.2,"tv":33.04,"id":67083366}]}]}
{"op":"mcm","clk":"11921430705","pt":1724153242471,"mc":[{"id":"1.232019003","rc":[{"batb":[[0,1.63,1.95],[1,1.5,10.89],[2,1.44,7.16]],"ltp":2.2,"tv":33.04,"id":67083366},{"batb":[[0,1.51,10.89],[1,1.44,6.4],[2,1.43,116.28]],"ltp":1.83,"tv":19.86,"id":72857116}]}]}
{"op":"mcm","clk":"11921431122","pt":1724153250170,"mc":[{"id":"1.232019003","rc":[{"batb":[[0,1.65,10.94],[1,1.64,4],[2,1.63,1.01]],"ltp":2.2,"tv":33.04,"id":67083366},{"batb":[[0,1.52,10.89],[1,1.51,10],[2,1.44,6.4]],"ltp":1.83,"tv":19.86,"id":72857116}]}]}
{"op":"mcm","clk":"11921431211","pt":1724153252187,"mc":[{"id":"1.232019003","rc":[{"batb":[[1,1.63,1.01],[2,1.5,10.89]],"ltp":2.2,"tv":33.04,"id":67083366}]}]}
{"op":"mcm","clk":"11921431261","pt":1724153253273,"mc":[{"id":"1.232019003","rc":[{"batb":[[0,1.51,10.89],[1,1.44,6.4],[2,1.43,116.28]],"ltp":1.83,"tv":19.86,"id":72857116}]}]}
{"op":"mcm","clk":"11921431285","pt":1724153253852,"mc":[{"id":"1.232019003","rc":[{"batb":[[0,1.63,1.95],[1,1.5,10.89],[2,1.44,7.16]],"ltp":2.2,"tv":33.04,"id":67083366}]}]}
{"op":"mcm","clk":"11921431561","pt":1724153259563,"mc":[{"id":"1.232019003","rc":[{"batb":[[0,1.65,10.94],[1,1.64,4],[2,1.63,1.01]],"ltp":2.2,"tv":33.04,"id":67083366},{"batb":[[0,1.52,10.89],[1,1.51,10],[2,1.44,6.4]],"ltp":1.83,"tv":19.86,"id":72857116}]}]}
{"op":"mcm","clk":"11921431651","pt":1724153261777,"mc":[{"id":"1.232019003","rc":[{"batb":[[1,1.63,1.01],[2,1.5,10.89]],"ltp":2.2,"tv":33.04,"id":67083366}]}]}
{"op":"mcm","clk":"11921431714","pt":1724153263380,"mc":[{"id":"1.232019003","rc":[{"batb":[[0,1.63,1.95],[1,1.5,10.89],[2,1.44,7.16]],"ltp":2.2,"tv":33.04,"id":67083366},{"batb":[[0,1.51,10.89],[1,1.44,6.4],[2,1.43,116.28]],"ltp":1.83,"tv":19.86,"id":72857116}]}]}
{"op":"mcm","clk":"11921431779","pt":1724153264610,"mc":[{"id":"1.232019003","rc":[{"batb":[[0,1.64,4.94],[1,1.63,1.01],[2,1.5,10.89]],"ltp":2.2,"tv":33.04,"id":67083366}]}]}
{"op":"mcm","clk":"11921431941","pt":1724153267291,"mc":[{"id":"1.232019003","rc":[{"batb":[[0,1.63,1.95],[1,1.5,10.89],[2,1.44,7.16]],"ltp":2.2,"tv":33.04,"id":67083366}]}]}
{"op":"mcm","clk":"11921431960","pt":1724153267703,"mc":[{"id":"1.232019003","rc":[{"batb":[[0,1.52,10.89],[1,1.51,10],[2,1.44,6.4]],"ltp":1.83,"tv":19.86,"id":72857116}]}]}
{"op":"mcm","clk":"11921432116","pt":1724153271410,"mc":[{"id":"1.232019003","rc":[{"batb":[[0,1.65,10.94],[1,1.64,4],[2,1.63,1.01]],"ltp":2.2,"tv":33.04,"id":67083366},{"batb":[[0,1.51,10.89],[1,1.44,6.4],[2,1.43,116.28]],"ltp":1.83,"tv":19.86,"id":72857116}]}]}
{"op":"mcm","clk":"11921432276","pt":1724153274508,"mc":[{"id":"1.232019003","rc":[{"batb":[[1,1.63,1.01],[2,1.5,10.89]],"ltp":2.2,"tv":33.04,"id":67083366},{"batb":[[0,1.52,10.89],[1,1.51,10],[2,1.44,6.4]],"ltp":1.83,"tv":19.86,"id":72857116}]}]}
{"op":"mcm","clk":"11921432302","pt":1724153274979,"mc":[{"id":"1.232019003","rc":[{"batb":[[0,1.63,1.95],[1,1.5,10.89],[2,1.44,7.16]],"ltp":2.2,"tv":33.04,"id":67083366}]}]}
{"op":"mcm","clk":"11921432455","pt":1724153278088,"mc":[{"id":"1.232019003","rc":[{"batb":[[0,1.65,10.94],[1,1.64,4],[2,1.63,1.01]],"ltp":2.2,"tv":33.04,"id":67083366},{"batb":[[0,1.51,10.89],[1,1.44,6.4],[2,1.43,116.28]],"ltp":1.83,"tv":19.86,"id":72857116}]}]}
{"op":"mcm","clk":"11921432564","pt":1724153280513,"mc":[{"id":"1.232019003","rc":[{"batb":[[1,1.63,1.01],[2,1.5,10.89]],"ltp":2.2,"tv":33.04,"id":67083366},{"batb":[[0,1.52,10.89],[1,1.51,10],[2,1.44,6.4]],"ltp":1.83,"tv":19.86,"id":72857116}]}]}
{"op":"mcm","clk":"11921432607","pt":1724153281498,"mc":[{"id":"1.232019003","rc":[{"batb":[[0,1.63,1.95],[1,1.5,10.89],[2,1.44,7.16]],"ltp":2.2,"tv":33.04,"id":67083366}]}]}
{"op":"mcm","clk":"11921432753","pt":1724153284199,"mc":[{"id":"1.232019003","rc":[{"batb":[[0,1.65,10.94],[1,1.64,4],[2,1.63,1.01]],"ltp":2.2,"tv":33.04,"id":67083366},{"batb":[[0,1.51,10.89],[1,1.44,6.4],[2,1.43,116.28]],"ltp":1.83,"tv":19.86,"id":72857116}]}]}
{"op":"mcm","clk":"11921432877","pt":1724153286613,"mc":[{"id":"1.232019003","rc":[{"batb":[[1,1.63,1.01],[2,1.5,10.89]],"ltp":2.2,"tv":33.04,"id":67083366},{"batb":[[0,1.52,10.89],[1,1.51,10],[2,1.44,6.4]],"ltp":1.83,"tv":19.86,"id":72857116}]}]}
{"op":"mcm","clk":"11921432919","pt":1724153287795,"mc":[{"id":"1.232019003","rc":[{"batb":[[0,1.63,1.95],[1,1.5,10.89],[2,1.44,7.16]],"ltp":2.2,"tv":33.04,"id":67083366}]}]}
{"op":"mcm","clk":"11921433049","pt":1724153290523,"mc":[{"id":"1.232019003","rc":[{"batb":[[0,1.65,10.94],[1,1.64,4],[2,1.63,1.01]],"ltp":2.2,"tv":33.04,"id":67083366},{"batb":[[0,1.51,10.89],[1,1.44,6.4],[2,1.43,116.28]],"ltp":1.83,"tv":19.86,"id":72857116}]}]}
{"op":"mcm","clk":"11921433141","pt":1724153292533,"mc":[{"id":"1.232019003","rc":[{"batb":[[1,1.63,1.01],[2,1.5,10.89]],"ltp":2.2,"tv":33.04,"id":67083366}]}]}
{"op":"mcm","clk":"11921433145","pt":1724153292641,"mc":[{"id":"1.232019003","rc":[{"batb":[[0,1.52,10.89],[1,1.51,10],[2,1.44,6.4]],"ltp":1.83,"tv":19.86,"id":72857116}]}]}
{"op":"mcm","clk":"11921433245","pt":1724153294104,"mc":[{"id":"1.232019003","rc":[{"batb":[[0,1.63,1.95],[1,1.5,10.89],[2,1.44,7.16]],"ltp":2.2,"tv":33.04,"id":67083366}]}]}
{"op":"mcm","clk":"11921433344","pt":1724153295548,"mc":[{"id":"1.232019003","rc":[{"batb":[[0,1.63,1.01]],"ltp":2.2,"tv":33.04,"id":67083366}]}]}
{"op":"mcm","clk":"11921433374","pt":1724153296015,"mc":[{"id":"1.232019003","rc":[{"batb":[[0,1.51,10.89],[1,1.44,6.4],[2,1.43,116.28]],"ltp":1.83,"tv":19.86,"id":72857116}]}]}
{"op":"mcm","clk":"11921433560","pt":1724153299742,"mc":[{"id":"1.232019003","rc":[{"batb":[[0,1.64,4],[1,1.63,1.01],[2,1.5,10.89]],"ltp":2.2,"tv":33.04,"id":67083366},{"batb":[[0,1.53,10.89],[1,1.51,10],[2,1.44,6.4]],"ltp":1.83,"tv":19.86,"id":72857116}]}]}
{"op":"mcm","clk":"11921433845","pt":1724153305012,"mc":[{"id":"1.232019003","rc":[{"batb":[[0,1.65,10],[1,1.64,4],[2,1.63,1.01]],"ltp":2.2,"tv":33.04,"id":67083366}]}]}
{"op":"mcm","clk":"11921433923","pt":1724153307030,"mc":[{"id":"1.232019003","rc":[{"batb":[[1,1.63,1.01],[2,1.5,10.89]],"ltp":2.2,"tv":33.04,"id":67083366}]}]}
{"op":"mcm","clk":"11921433959","pt":1724153307960,"mc":[{"id":"1.232019003","rc":[{"batb":[[0,1.51,10.89],[1,1.44,6.4],[2,1.43,116.28]],"ltp":1.83,"tv":19.86,"id":72857116}]}]}
{"op":"mcm","clk":"11921434071","pt":1724153310330,"mc":[{"id":"1.232019003","rc":[{"batb":[[0,1.66,4],[1,1.65,10],[2,1.63,1.01]],"ltp":2.2,"tv":33.04,"id":67083366},{"batb":[[0,1.54,10],[1,1.51,10.89],[2,1.44,6.4]],"ltp":1.83,"tv":19.86,"id":72857116}]}]}
{"op":"mcm","clk":"11921434161","pt":1724153312463,"mc":[{"id":"1.232019003","rc":[{"batb":[[1,1.63,1.01],[2,1.5,10.89]],"ltp":2.2,"tv":33.04,"id":67083366},{"batl":[[0,2.36,3.5]],"ltp":1.83,"tv":19.86,"id":72857116}]}]}
{"op":"mcm","clk":"11921434254","pt":1724153314067,"mc":[{"id":"1.232019003","rc":[{"batb":[[0,1.63,1.01],[1,1.5,10.89],[2,1.44,7.16]],"ltp":2.2,"tv":33.04,"id":67083366}]}]}
{"op":"mcm","clk":"11921434302","pt":1724153315144,"mc":[{"id":"1.232019003","rc":[{"batb":[[0,1.51,10.89],[1,1.44,6.4],[2,1.43,116.28]],"ltp":1.83,"tv":19.86,"id":72857116}]}]}
{"op":"mcm","clk":"11921434389","pt":1724153317364,"mc":[{"id":"1.232019003","rc":[{"batb":[[0,1.65,10],[1,1.64,4],[2,1.63,1.01]],"ltp":2.2,"tv":33.04,"id":67083366},{"batb":[[0,1.52,10.89],[1,1.51,10],[2,1.44,6.4]],"ltp":1.83,"tv":19.86,"id":72857116}]}]}
{"op":"mcm","clk":"11921434494","pt":1724153319433,"mc":[{"id":"1.232019003","rc":[{"batb":[[1,1.63,1.01],[2,1.5,10.89]],"ltp":2.2,"tv":33.04,"id":67083366}]}]}
{"op":"mcm","clk":"11921434575","pt":1724153320777,"mc":[{"id":"1.232019003","rc":[{"batb":[[0,1.63,1.01],[1,1.5,10.89],[2,1.44,7.16]],"ltp":2.2,"tv":33.04,"id":67083366},{"batb":[[0,1.51,10.89],[1,1.44,6.4],[2,1.43,116.28]],"ltp":1.83,"tv":19.86,"id":72857116}]}]}
{"op":"mcm","clk":"11921434625","pt":1724153321982,"mc":[{"id":"1.232019003","rc":[{"batb":[[0,1.64,4],[1,1.63,1.01],[2,1.5,10.89]],"ltp":2.2,"tv":33.04,"id":67083366}]}]}
{"op":"mcm","clk":"11921434703","pt":1724153323530,"mc":[{"id":"1.232019003","rc":[{"batb":[[0,1.65,10],[1,1.64,4],[2,1.63,1.01]],"ltp":2.2,"tv":33.04,"id":67083366},{"batb":[[0,1.52,10.89],[1,1.51,10],[2,1.44,6.4]],"ltp":1.83,"tv":19.86,"id":72857116}]}]}
{"op":"mcm","clk":"11921434758","pt":1724153324667,"mc":[{"id":"1.232019003","rc":[{"batb":[[1,1.63,1.01],[2,1.5,10.89]],"ltp":2.2,"tv":33.04,"id":67083366}]}]}
{"op":"mcm","clk":"11921434861","pt":1724153327040,"mc":[{"id":"1.232019003","rc":[{"batb":[[0,1.64,4]],"ltp":2.2,"tv":33.04,"id":67083366},{"batb":[[0,1.51,10.89],[1,1.44,6.4],[2,1.43,116.28]],"ltp":1.83,"tv":19.86,"id":72857116}]}]}
{"op":"mcm","clk":"11921435005","pt":1724153329777,"mc":[{"id":"1.232019003","rc":[{"batb":[[0,1.63,1.01],[1,1.5,10.89],[2,1.44,7.16]],"ltp":2.2,"tv":33.04,"id":67083366}]}]}
{"op":"mcm","clk":"11921435253","pt":1724153334949,"mc":[{"id":"1.232019003","rc":[{"batb":[[0,1.64,4],[1,1.63,1.01],[2,1.5,10.89]],"ltp":2.2,"tv":33.04,"id":67083366},{"batb":[[0,1.52,10.89],[1,1.51,10],[2,1.44,6.4]],"ltp":1.83,"tv":19.86,"id":72857116}]}]}
{"op":"mcm","clk":"11921435493","pt":1724153339472,"mc":[{"id":"1.232019003","rc":[{"batb":[[0,1.65,10],[1,1.64,4],[2,1.63,1.01]],"ltp":2.2,"tv":33.04,"id":67083366}]}]}
{"op":"mcm","clk":"11921435603","pt":1724153341549,"mc":[{"id":"1.232019003","rc":[{"batb":[[1,1.63,1.01],[2,1.5,10.89]],"ltp":2.2,"tv":33.04,"id":67083366}]}]}
{"op":"mcm","clk":"11921435642","pt":1724153342477,"mc":[{"id":"1.232019003","rc":[{"batb":[[0,1.53,1.84]],"ltp":1.83,"tv":19.86,"id":72857116}]}]}
{"op":"mcm","clk":"11921435708","pt":1724153344380,"mc":[{"id":"1.232019003","rc":[{"batb":[[0,1.66,4],[1,1.65,10],[2,1.63,1.01]],"ltp":2.2,"tv":33.04,"id":67083366},{"batb":[[1,1.52,10],[2,1.51,10]],"ltp":1.83,"tv":19.86,"id":72857116}]}]}
{"op":"mcm","clk":"11921435811","pt":1724153346193,"mc":[{"id":"1.232019003","rc":[{"batb":[[1,1.63,1.01],[2,1.5,10.89]],"ltp":2.2,"tv":33.04,"id":67083366}]}]}
{"op":"mcm","clk":"11921435862","pt":1724153347478,"mc":[{"id":"1.232019003","rc":[{"batb":[[0,1.63,1.01],[1,1.5,10.89],[2,1.44,7.16]],"ltp":2.2,"tv":33.04,"id":67083366}]}]}
{"op":"mcm","clk":"11921435929","pt":1724153348760,"mc":[{"id":"1.232019003","rc":[{"batb":[[1,1.51,10],[2,1.44,6.4]],"ltp":1.83,"tv":19.86,"id":72857116}]}]}
{"op":"mcm","clk":"11921436158","pt":1724153353598,"mc":[{"id":"1.232019003","rc":[{"batb":[[0,1.65,10],[1,1.64,4],[2,1.63,1.01]],"ltp":2.2,"tv":33.04,"id":67083366}]}]}
{"op":"mcm","clk":"11921436248","pt":1724153355597,"mc":[{"id":"1.232019003","rc":[{"batb":[[1,1.63,1.01],[2,1.5,10.89]],"ltp":2.2,"tv":33.04,"id":67083366}]}]}
{"op":"mcm","clk":"11921436287","pt":1724153356775,"mc":[{"id":"1.232019003","rc":[{"batb":[[0,1.63,1.01],[1,1.5,10.89],[2,1.44,7.16]],"ltp":2.2,"tv":33.04,"id":67083366}]}]}
{"op":"mcm","clk":"11921436354","pt":1724153358571,"mc":[{"id":"1.232019003","rc":[{"batl":[[0,2.36,2.56]],"ltp":1.83,"tv":19.86,"id":72857116}]}]}
{"op":"mcm","clk":"11921436367","pt":1724153358978,"mc":[{"id":"1.232019003","rc":[{"batb":[[0,1.65,10],[1,1.64,4],[2,1.63,1.01]],"ltp":2.2,"tv":33.04,"id":67083366},{"batl":[[0,2.36,3.43]],"ltp":1.83,"tv":19.86,"id":72857116}]}]}
{"op":"mcm","clk":"11921436490","pt":1724153361193,"mc":[{"id":"1.232019003","rc":[{"batb":[[1,1.63,1.01],[2,1.5,10.89]],"ltp":2.2,"tv":33.04,"id":67083366}]}]}
{"op":"mcm","clk":"11921436553","pt":1724153362214,"mc":[{"id":"1.232019003","rc":[{"batb":[[0,1.63,1.01],[1,1.5,10.89],[2,1.44,7.16]],"ltp":2.2,"tv":33.04,"id":67083366}]}]}
{"op":"mcm","clk":"11921436707","pt":1724153366012,"mc":[{"id":"1.232019003","rc":[{"batb":[[0,1.66,14],[1,1.63,1.01],[2,1.5,10.89]],"ltp":2.2,"tv":33.04,"id":67083366}]}]}
{"op":"mcm","clk":"11921437063","pt":1724153373012,"mc":[{"id":"1.232019003","rc":[{"batb":[[0,1.66,10]],"ltp":2.2,"tv":33.04,"id":67083366}]}]}
{"op":"mcm","clk":"11921437107","pt":1724153374039,"mc":[{"id":"1.232019003","rc":[{"batb":[[0,1.63,1.01],[1,1.5,10.89],[2,1.44,7.16]],"ltp":2.2,"tv":33.04,"id":67083366}]}]}
{"op":"mcm","clk":"11921437201","pt":1724153376406,"mc":[{"id":"1.232019003","rc":[{"batb":[[0,1.67,14],[1,1.63,1.01],[2,1.5,10.89]],"ltp":2.2,"tv":33.04,"id":67083366}]}]}
{"op":"mcm","clk":"11921437346","pt":1724153380208,"mc":[{"id":"1.232019003","rc":[{"batb":[[0,1.67,10]],"ltp":2.2,"tv":33.04,"id":67083366}]}]}
{"op":"mcm","clk":"11921437412","pt":1724153381897,"mc":[{"id":"1.232019003","rc":[{"batb":[[0,1.63,1.01],[1,1.5,10.89],[2,1.44,7.16]],"ltp":2.2,"tv":33.04,"id":67083366}]}]}
{"op":"mcm","clk":"11921437730","pt":1724153390317,"mc":[{"id":"1.232019003","rc":[{"batb":[[0,1.65,10],[1,1.64,4],[2,1.63,1.01]],"ltp":2.2,"tv":33.04,"id":67083366}]}]}
{"op":"mcm","clk":"11921437786","pt":1724153392217,"mc":[{"id":"1.232019003","rc":[{"batb":[[1,1.63,1.01],[2,1.5,10.89]],"ltp":2.2,"tv":33.04,"id":67083366}]}]}
{"op":"mcm","clk":"11921437841","pt":1724153393653,"mc":[{"id":"1.232019003","rc":[{"batb":[[0,1.63,1.01],[1,1.5,10.89],[2,1.44,7.16]],"ltp":2.2,"tv":33.04,"id":67083366}]}]}
{"op":"mcm","clk":"11921437940","pt":1724153396520,"mc":[{"id":"1.232019003","rc":[{"batb":[[0,1.64,4],[1,1.63,1.01],[2,1.5,10.89]],"ltp":2.2,"tv":33.04,"id":67083366}]}]}
{"op":"mcm","clk":"11921437946","pt":1724153396725,"mc":[{"id":"1.232019003","rc":[{"batb":[[0,1.65,10],[1,1.64,4],[2,1.63,1.01]],"ltp":2.2,"tv":33.04,"id":67083366}]}]}
{"op":"mcm","clk":"11921438037","pt":1724153398725,"mc":[{"id":"1.232019003","rc":[{"batb":[[1,1.63,1.01],[2,1.5,10.89]],"ltp":2.2,"tv":33.04,"id":67083366}]}]}
{"op":"mcm","clk":"11921438088","pt":1724153400331,"mc":[{"id":"1.232019003","rc":[{"batb":[[0,1.63,1.01],[1,1.5,10.89],[2,1.44,7.16]],"ltp":2.2,"tv":33.04,"id":67083366}]}]}
{"op":"mcm","clk":"11921438401","pt":1724153406130,"mc":[{"id":"1.232019003","rc":[{"batb":[[0,1.65,10],[1,1.64,4],[2,1.63,1.01]],"ltp":2.2,"tv":33.04,"id":67083366}]}]}
{"op":"mcm","clk":"11921438457","pt":1724153407932,"mc":[{"id":"1.232019003","rc":[{"batb":[[1,1.63,1.01],[2,1.5,10.89]],"ltp":2.2,"tv":33.04,"id":67083366}]}]}
{"op":"mcm","clk":"11921438508","pt":1724153409569,"mc":[{"id":"1.232019003","rc":[{"batb":[[0,1.63,1.01],[1,1.5,10.89],[2,1.44,7.16]],"ltp":2.2,"tv":33.04,"id":67083366}]}]}
{"op":"mcm","clk":"11921439034","pt":1724153423291,"mc":[{"id":"1.232019003","rc":[{"batb":[[0,1.65,10],[1,1.64,4],[2,1.63,1.01]],"ltp":2.2,"tv":33.04,"id":67083366}]}]}
{"op":"mcm","clk":"11921439109","pt":1724153425096,"mc":[{"id":"1.232019003","rc":[{"batb":[[1,1.63,1.01],[2,1.5,10.89]],"ltp":2.2,"tv":33.04,"id":67083366}]}]}
{"op":"mcm","clk":"11921439212","pt":1724153427272,"mc":[{"id":"1.232019003","rc":[{"batb":[[0,1.64,4]],"ltp":2.2,"tv":33.04,"id":67083366}]}]}
{"op":"mcm","clk":"11921439285","pt":1724153429685,"mc":[{"id":"1.232019003","rc":[{"batb":[[0,1.63,1.01],[1,1.5,10.89],[2,1.44,7.16]],"ltp":2.2,"tv":33.04,"id":67083366}]}]}
{"op":"mcm","clk":"11921439414","pt":1724153433390,"mc":[{"id":"1.232019003","rc":[{"batb":[[0,1.65,10],[1,1.64,4],[2,1.63,1.01]],"ltp":2.2,"tv":33.04,"id":67083366}]}]}
{"op":"mcm","clk":"11921439507","pt":1724153435499,"mc":[{"id":"1.232019003","rc":[{"batb":[[1,1.63,1.01],[2,1.5,10.89]],"ltp":2.2,"tv":33.04,"id":67083366}]}]}
{"op":"mcm","clk":"11921439559","pt":1724153436785,"mc":[{"id":"1.232019003","rc":[{"batb":[[0,1.63,1.01],[1,1.5,10.89],[2,1.44,7.16]],"ltp":2.2,"tv":33.04,"id":67083366}]}]}
{"op":"mcm","clk":"11921439697","pt":1724153440395,"mc":[{"id":"1.232019003","rc":[{"batb":[[0,1.64,4],[1,1.63,1.01],[2,1.5,10.89]],"ltp":2.2,"tv":33.04,"id":67083366}]}]}
{"op":"mcm","clk":"11921439735","pt":1724153441176,"mc":[{"id":"1.232019003","rc":[{"batb":[[0,1.65,10],[1,1.64,4],[2,1.63,1.01]],"ltp":2.2,"tv":33.04,"id":67083366}]}]}
{"op":"mcm","clk":"11921439802","pt":1724153442729,"mc":[{"id":"1.232019003","rc":[{"batb":[[1,1.63,1.01],[2,1.5,10.89]],"ltp":2.2,"tv":33.04,"id":67083366}]}]}
{"op":"mcm","clk":"11921439876","pt":1724153444583,"mc":[{"id":"1.232019003","rc":[{"batb":[[0,1.63,1.01],[1,1.5,10.89],[2,1.44,7.16]],"ltp":2.2,"tv":33.04,"id":67083366}]}]}
{"op":"mcm","clk":"11921440394","pt":1724153457413,"mc":[{"id":"1.232019003","rc":[{"batb":[[0,1.64,4],[1,1.63,1.01],[2,1.5,10.89]],"ltp":2.2,"tv":33.04,"id":67083366}]}]}
{"op":"mcm","clk":"11921440407","pt":1724153457725,"mc":[{"id":"1.232019003","rc":[{"batb":[[0,1.65,10],[1,1.64,4],[2,1.63,1.01]],"ltp":2.2,"tv":33.04,"id":67083366}]}]}
{"op":"mcm","clk":"11921440479","pt":1724153459639,"mc":[{"id":"1.232019003","rc":[{"batb":[[1,1.63,1.01],[2,1.5,10.89]],"ltp":2.2,"tv":33.04,"id":67083366}]}]}
{"op":"mcm","clk":"11921440531","pt":1724153461343,"mc":[{"id":"1.232019003","rc":[{"batb":[[0,1.63,1.01],[1,1.5,10.89],[2,1.44,7.16]],"ltp":2.2,"tv":33.04,"id":67083366}]}]}
{"op":"mcm","clk":"11921441134","pt":1724153473610,"mc":[{"id":"1.232019003","rc":[{"batb":[[0,1.64,4],[1,1.63,1.01],[2,1.5,10.89]],"ltp":2.2,"tv":33.04,"id":67083366}]}]}
{"op":"mcm","clk":"11921441147","pt":1724153473815,"mc":[{"id":"1.232019003","rc":[{"batb":[[0,1.65,10],[1,1.64,4],[2,1.63,1.01]],"ltp":2.2,"tv":33.04,"id":67083366}]}]}
{"op":"mcm","clk":"11921441245","pt":1724153475820,"mc":[{"id":"1.232019003","rc":[{"batb":[[1,1.63,1.01],[2,1.5,10.89]],"ltp":2.2,"tv":33.04,"id":67083366}]}]}
{"op":"mcm","clk":"11921441336","pt":1724153477519,"mc":[{"id":"1.232019003","rc":[{"batb":[[0,1.63,1.01],[1,1.5,10.89],[2,1.44,7.16]],"ltp":2.2,"tv":33.04,"id":67083366}]}]}
{"op":"mcm","clk":"11921441999","pt":1724153491364,"mc":[{"id":"1.232019003","rc":[{"batb":[[0,1.64,4],[1,1.63,1.01],[2,1.5,10.89]],"ltp":2.2,"tv":33.04,"id":67083366}]}]}
{"op":"mcm","clk":"11921442015","pt":1724153491777,"mc":[{"id":"1.232019003","rc":[{"batb":[[0,1.65,10],[1,1.64,4],[2,1.63,1.01]],"ltp":2.2,"tv":33.04,"id":67083366}]}]}
{"op":"mcm","clk":"11921442106","pt":1724153493685,"mc":[{"id":"1.232019003","rc":[{"batb":[[1,1.63,1.01],[2,1.5,10.89]],"ltp":2.2,"tv":33.04,"id":67083366}]}]}
{"op":"mcm","clk":"11921442210","pt":1724153495279,"mc":[{"id":"1.232019003","rc":[{"batb":[[0,1.63,1.01],[1,1.5,10.89],[2,1.44,7.16]],"ltp":2.2,"tv":33.04,"id":67083366}]}]}
{"op":"mcm","clk":"11921443298","pt":1724153517097,"mc":[{"id":"1.232019003","rc":[{"batb":[[0,1.64,4],[1,1.63,1.01],[2,1.5,10.89]],"ltp":2.2,"tv":33.04,"id":67083366}]}]}
{"op":"mcm","clk":"11921443444","pt":1724153520034,"mc":[{"id":"1.232019003","rc":[{"batb":[[0,1.65,10],[1,1.64,4],[2,1.63,1.01]],"ltp":2.2,"tv":33.04,"id":67083366}]}]}
{"op":"mcm","clk":"11921443534","pt":1724153521906,"mc":[{"id":"1.232019003","rc":[{"batb":[[1,1.63,1.01],[2,1.5,10.89]],"ltp":2.2,"tv":33.04,"id":67083366}]}]}
{"op":"mcm","clk":"11921443674","pt":1724153525105,"mc":[{"id":"1.232019003","rc":[{"batb":[[0,1.64,4]],"ltp":2.2,"tv":33.04,"id":67083366}]}]}
{"op":"mcm","clk":"11921443826","pt":1724153527839,"mc":[{"id":"1.232019003","rc":[{"batb":[[0,1.63,1.01],[1,1.5,10.89],[2,1.44,7.16]],"ltp":2.2,"tv":33.04,"id":67083366}]}]}
{"op":"mcm","clk":"11921446471","pt":1724153577495,"mc":[{"id":"1.232019003","rc":[{"batb":[[0,1.65,10],[1,1.64,4],[2,1.63,1.01]],"ltp":2.2,"tv":33.04,"id":67083366}]}]}
{"op":"mcm","clk":"11921446620","pt":1724153579777,"mc":[{"id":"1.232019003","rc":[{"batb":[[1,1.63,1.01],[2,1.5,10.89]],"ltp":2.2,"tv":33.04,"id":67083366}]}]}
{"op":"mcm","clk":"11921446704","pt":1724153581011,"mc":[{"id":"1.232019003","rc":[{"batb":[[0,1.63,1.01],[1,1.5,10.89],[2,1.44,7.16]],"ltp":2.2,"tv":33.04,"id":67083366}]}]}
{"op":"mcm","clk":"11921447165","pt":1724153589298,"mc":[{"id":"1.232019003","rc":[{"batb":[[0,1.65,10],[1,1.64,4],[2,1.63,1.01]],"ltp":2.2,"tv":33.04,"id":67083366}]}]}
{"op":"mcm","clk":"11921447289","pt":1724153591816,"mc":[{"id":"1.232019003","rc":[{"batb":[[1,1.63,1.01],[2,1.5,10.89]],"ltp":2.2,"tv":33.04,"id":67083366}]}]}
{"op":"mcm","clk":"11921447336","pt":1724153592842,"mc":[{"id":"1.232019003","rc":[{"batb":[[0,1.63,1.01],[1,1.5,10.89],[2,1.44,7.16]],"ltp":2.2,"tv":33.04,"id":67083366}]}]}
{"op":"mcm","clk":"11921447460","pt":1724153595219,"mc":[{"id":"1.232019003","rc":[{"batb":[[0,1.64,4],[1,1.63,1.01],[2,1.5,10.89]],"ltp":2.2,"tv":33.04,"id":67083366}]}]}
{"op":"mcm","clk":"11921447504","pt":1724153595885,"mc":[{"id":"1.232019003","rc":[{"batb":[[0,1.65,10],[1,1.64,4],[2,1.63,1.01]],"ltp":2.2,"tv":33.04,"id":67083366}]}]}
{"op":"mcm","clk":"11921447627","pt":1724153597931,"mc":[{"id":"1.232019003","rc":[{"batb":[[1,1.63,1.01],[2,1.5,10.89]],"ltp":2.2,"tv":33.04,"id":67083366}]}]}
{"op":"mcm","clk":"11921447713","pt":1724153599522,"mc":[{"id":"1.232019003","rc":[{"batb":[[0,1.63,1.01],[1,1.5,10.89],[2,1.44,7.16]],"ltp":2.2,"tv":33.04,"id":67083366}]}]}
{"op":"mcm","clk":"11921448519","pt":1724153614332,"mc":[{"id":"1.232019003","rc":[{"batb":[[0,1.64,4],[1,1.63,1.01],[2,1.5,10.89]],"ltp":2.2,"tv":33.04,"id":67083366}]}]}
{"op":"mcm","clk":"11921448544","pt":1724153614745,"mc":[{"id":"1.232019003","rc":[{"batb":[[0,1.65,10],[1,1.64,4],[2,1.63,1.01]],"ltp":2.2,"tv":33.04,"id":67083366}]}]}
{"op":"mcm","clk":"11921448653","pt":1724153616814,"mc":[{"id":"1.232019003","rc":[{"batb":[[1,1.63,1.01],[2,1.5,10.89]],"ltp":2.2,"tv":33.04,"id":67083366}]}]}
{"op":"mcm","clk":"11921448722","pt":1724153618254,"mc":[{"id":"1.232019003","rc":[{"batb":[[0,1.63,1.01],[1,1.5,10.89],[2,1.44,7.16]],"ltp":2.2,"tv":33.04,"id":67083366}]}]}
{"op":"mcm","clk":"11921448962","pt":1724153622347,"mc":[{"id":"1.232019003","rc":[{"batb":[[0,1.65,10],[1,1.64,4],[2,1.63,1.01]],"ltp":2.2,"tv":33.04,"id":67083366}]}]}
{"op":"mcm","clk":"11921449063","pt":1724153624351,"mc":[{"id":"1.232019003","rc":[{"batb":[[1,1.63,1.01],[2,1.5,10.89]],"ltp":2.2,"tv":33.04,"id":67083366}]}]}
{"op":"mcm","clk":"11921449147","pt":1724153625855,"mc":[{"id":"1.232019003","rc":[{"batb":[[0,1.63,1.01],[1,1.5,10.89],[2,1.44,7.16]],"ltp":2.2,"tv":33.04,"id":67083366}]}]}
{"op":"mcm","clk":"11921451002","pt":1724153660311,"mc":[{"id":"1.232019003","rc":[{"batb":[[0,1.64,4],[1,1.63,1.01],[2,1.5,10.89]],"ltp":2.2,"tv":33.04,"id":67083366}]}]}
{"op":"mcm","clk":"11921451024","pt":1724153660882,"mc":[{"id":"1.232019003","rc":[{"batb":[[0,1.65,10],[1,1.64,4],[2,1.63,1.01]],"ltp":2.2,"tv":33.04,"id":67083366}]}]}
{"op":"mcm","clk":"11921451122","pt":1724153663000,"mc":[{"id":"1.232019003","rc":[{"batb":[[1,1.63,1.01],[2,1.5,10.89]],"ltp":2.2,"tv":33.04,"id":67083366}]}]}
{"op":"mcm","clk":"11921451172","pt":1724153664185,"mc":[{"id":"1.232019003","rc":[{"batb":[[0,1.63,1.01],[1,1.5,10.89],[2,1.44,7.16]],"ltp":2.2,"tv":33.04,"id":67083366}]}]}
{"op":"mcm","clk":"11921451238","pt":1724153665475,"mc":[{"id":"1.232019003","rc":[{"batb":[[0,1.64,4],[1,1.63,1.01],[2,1.5,10.89]],"ltp":2.2,"tv":33.04,"id":67083366}]}]}
{"op":"mcm","clk":"11921451302","pt":1724153666701,"mc":[{"id":"1.232019003","rc":[{"batb":[[0,1.65,10],[1,1.64,4],[2,1.63,1.01]],"ltp":2.2,"tv":33.04,"id":67083366}]}]}
{"op":"mcm","clk":"11921451364","pt":1724153668091,"mc":[{"id":"1.232019003","rc":[{"batb":[[1,1.63,1.01],[2,1.5,10.89]],"ltp":2.2,"tv":33.04,"id":67083366}]}]}
{"op":"mcm","clk":"11921451477","pt":1724153670423,"mc":[{"id":"1.232019003","rc":[{"batb":[[0,1.64,4]],"ltp":2.2,"tv":33.04,"id":67083366}]}]}
{"op":"mcm","clk":"11921451611","pt":1724153673011,"mc":[{"id":"1.232019003","rc":[{"batb":[[0,1.63,1.01],[1,1.5,10.89],[2,1.44,7.16]],"ltp":2.2,"tv":33.04,"id":67083366}]}]}
{"op":"mcm","clk":"11921452085","pt":1724153681601,"mc":[{"id":"1.232019003","rc":[{"batb":[[0,1.64,4],[1,1.63,1.01],[2,1.5,10.89]],"ltp":2.2,"tv":33.04,"id":67083366}]}]}
{"op":"mcm","clk":"11921452136","pt":1724153682422,"mc":[{"id":"1.232019003","rc":[{"batb":[[0,1.65,10],[1,1.64,4],[2,1.63,1.01]],"ltp":2.2,"tv":33.04,"id":67083366}]}]}
{"op":"mcm","clk":"11921452249","pt":1724153684404,"mc":[{"id":"1.232019003","rc":[{"batb":[[1,1.63,1.01],[2,1.5,10.89]],"ltp":2.2,"tv":33.04,"id":67083366}]}]}
{"op":"mcm","clk":"11921452351","pt":1724153686110,"mc":[{"id":"1.232019003","rc":[{"batb":[[0,1.63,1.01],[1,1.5,10.89],[2,1.44,7.16]],"ltp":2.2,"tv":33.04,"id":67083366}]}]}
{"op":"mcm","clk":"11921452544","pt":1724153689237,"mc":[{"id":"1.232019003","rc":[{"batb":[[0,1.65,10],[1,1.64,4],[2,1.63,1.01]],"ltp":2.2,"tv":33.04,"id":67083366}]}]}
{"op":"mcm","clk":"11921452678","pt":1724153691553,"mc":[{"id":"1.232019003","rc":[{"batb":[[1,1.63,1.01],[2,1.5,10.89]],"ltp":2.2,"tv":33.04,"id":67083366}]}]}
{"op":"mcm","clk":"11921452751","pt":1724153692744,"mc":[{"id":"1.232019003","rc":[{"batb":[[0,1.63,1.01],[1,1.5,10.89],[2,1.44,7.16]],"ltp":2.2,"tv":33.04,"id":67083366}]}]}
{"op":"mcm","clk":"11921452808","pt":1724153694032,"mc":[{"id":"1.232019003","rc":[{"batb":[[0,1.64,4],[1,1.63,1.01],[2,1.5,10.89]],"ltp":2.2,"tv":33.04,"id":67083366}]}]}
{"op":"mcm","clk":"11921452947","pt":1724153696526,"mc":[{"id":"1.232019003","rc":[{"batb":[[0,1.65,10]],"ltp":2.2,"tv":33.04,"id":67083366}]}]}
{"op":"mcm","clk":"11921453125","pt":1724153699530,"mc":[{"id":"1.232019003","rc":[{"batb":[[0,1.64,4]],"ltp":2.2,"tv":33.04,"id":67083366}]}]}
{"op":"mcm","clk":"11921453256","pt":1724153701833,"mc":[{"id":"1.232019003","rc":[{"batb":[[0,1.63,1.01],[1,1.5,10.89],[2,1.44,7.16]],"ltp":2.2,"tv":33.04,"id":67083366}]}]}
{"op":"mcm","clk":"11921453393","pt":1724153704436,"mc":[{"id":"1.232019003","rc":[{"batb":[[0,1.65,10],[1,1.64,4],[2,1.63,1.01]],"ltp":2.2,"tv":33.04,"id":67083366}]}]}
{"op":"mcm","clk":"11921453527","pt":1724153706762,"mc":[{"id":"1.232019003","rc":[{"batb":[[1,1.63,1.01],[2,1.5,10.89]],"ltp":2.2,"tv":33.04,"id":67083366}]}]}
{"op":"mcm","clk":"11921453605","pt":1724153708156,"mc":[{"id":"1.232019003","rc":[{"batb":[[0,1.63,1.01],[1,1.5,10.89],[2,1.44,7.16]],"ltp":2.2,"tv":33.04,"id":67083366}]}]}
{"op":"mcm","clk":"11921453697","pt":1724153709650,"mc":[{"id":"1.232019003","rc":[{"batb":[[0,1.64,4],[1,1.63,1.01],[2,1.5,10.89]],"ltp":2.2,"tv":33.04,"id":67083366}]}]}
{"op":"mcm","clk":"11921453801","pt":1724153711918,"mc":[{"id":"1.232019003","rc":[{"batb":[[0,1.63,1.01],[1,1.5,10.89],[2,1.44,7.16]],"ltp":2.2,"tv":33.04,"id":67083366}]}]}
{"op":"mcm","clk":"11921453947","pt":1724153714541,"mc":[{"id":"1.232019003","rc":[{"batb":[[0,1.65,10],[1,1.64,4],[2,1.63,1.01]],"ltp":2.2,"tv":33.04,"id":67083366}]}]}
{"op":"mcm","clk":"11921454039","pt":1724153716654,"mc":[{"id":"1.232019003","rc":[{"batb":[[1,1.63,1.01],[2,1.5,10.89]],"ltp":2.2,"tv":33.04,"id":67083366}]}]}
{"op":"mcm","clk":"11921454091","pt":1724153717744,"mc":[{"id":"1.232019003","rc":[{"batb":[[0,1.63,1.01],[1,1.5,10.89],[2,1.44,7.16]],"ltp":2.2,"tv":33.04,"id":67083366}]}]}
{"op":"mcm","clk":"11921454208","pt":1724153720061,"mc":[{"id":"1.232019003","rc":[{"batb":[[0,1.65,10],[1,1.64,4],[2,1.63,1.01]],"ltp":2.2,"tv":33.04,"id":67083366}]}]}
{"op":"mcm","clk":"11921454334","pt":1724153722339,"mc":[{"id":"1.232019003","rc":[{"batb":[[1,1.63,1.01],[2,1.5,10.89]],"ltp":2.2,"tv":33.04,"id":67083366}]}]}
{"op":"mcm","clk":"11921454392","pt":1724153723477,"mc":[{"id":"1.232019003","rc":[{"batb":[[0,1.63,1.01],[1,1.5,10.89],[2,1.44,7.16]],"ltp":2.2,"tv":33.04,"id":67083366}]}]}
{"op":"mcm","clk":"11921454466","pt":1724153724768,"mc":[{"id":"1.232019003","rc":[{"batb":[[0,1.64,4],[1,1.63,1.01],[2,1.5,10.89]],"ltp":2.2,"tv":33.04,"id":67083366}]}]}
{"op":"mcm","clk":"11921454606","pt":1724153727256,"mc":[{"id":"1.232019003","rc":[{"batb":[[0,1.63,1.01],[1,1.5,10.89],[2,1.44,7.16]],"ltp":2.2,"tv":33.04,"id":67083366}]}]}
{"op":"mcm","clk":"11921454803","pt":1724153731174,"mc":[{"id":"1.232019003","rc":[{"batb":[[0,1.65,10],[1,1.64,4],[2,1.63,1.01]],"ltp":2.2,"tv":33.04,"id":67083366}]}]}
{"op":"mcm","clk":"11921454912","pt":1724153733545,"mc":[{"id":"1.232019003","rc":[{"batb":[[1,1.63,1.01],[2,1.5,10.89]],"ltp":2.2,"tv":33.04,"id":67083366}]}]}
{"op":"mcm","clk":"11921454953","pt":1724153734478,"mc":[{"id":"1.232019003","rc":[{"batb":[[0,1.63,1.01],[1,1.5,10.89],[2,1.44,7.16]],"ltp":2.2,"tv":33.04,"id":67083366}]}]}
{"op":"mcm","clk":"11921455835","pt":1724153756386,"mc":[{"id":"1.232019003","rc":[{"batb":[[0,1.65,10],[1,1.64,4],[2,1.63,1.01]],"ltp":2.2,"tv":33.04,"id":67083366}]}]}
{"op":"mcm","clk":"11921455917","pt":1724153758391,"mc":[{"id":"1.232019003","rc":[{"batb":[[1,1.63,1.01],[2,1.5,10.89]],"ltp":2.2,"tv":33.04,"id":67083366}]}]}
{"op":"mcm","clk":"11921455977","pt":1724153759575,"mc":[{"id":"1.232019003","rc":[{"batb":[[0,1.63,1.01],[1,1.5,10.89],[2,1.44,7.16]],"ltp":2.2,"tv":33.04,"id":67083366}]}]}
{"op":"mcm","clk":"11921456455","pt":1724153769410,"mc":[{"id":"1.232019003","rc":[{"batb":[[0,1.64,4],[1,1.63,1.01],[2,1.5,10.89]],"ltp":2.2,"tv":33.04,"id":67083366}]}]}
{"op":"mcm","clk":"11921456482","pt":1724153769778,"mc":[{"id":"1.232019003","rc":[{"batb":[[0,1.65,10],[1,1.64,4],[2,1.63,1.01]],"ltp":2.2,"tv":33.04,"id":67083366}]}]}
{"op":"mcm","clk":"11921456575","pt":1724153771993,"mc":[{"id":"1.232019003","rc":[{"batb":[[1,1.63,1.01],[2,1.5,10.89]],"ltp":2.2,"tv":33.04,"id":67083366}]}]}
{"op":"mcm","clk":"11921456640","pt":1724153773180,"mc":[{"id":"1.232019003","rc":[{"batb":[[0,1.63,1.01],[1,1.5,10.89],[2,1.44,7.16]],"ltp":2.2,"tv":33.04,"id":67083366}]}]}
{"op":"mcm","clk":"11921456680","pt":1724153774471,"mc":[{"id":"1.232019003","rc":[{"batb":[[0,1.64,4],[1,1.63,1.01],[2,1.5,10.89]],"ltp":2.2,"tv":33.04,"id":67083366}]}]}
{"op":"mcm","clk":"11921456777","pt":1724153777077,"mc":[{"id":"1.232019003","rc":[{"batb":[[0,1.63,1.01],[1,1.5,10.89],[2,1.44,7.16]],"ltp":2.2,"tv":33.04,"id":67083366}]}]}
{"op":"mcm","clk":"11921457371","pt":1724153791492,"mc":[{"id":"1.232019003","rc":[{"batb":[[0,1.64,4],[1,1.63,1.01],[2,1.5,10.89]],"ltp":2.2,"tv":33.04,"id":67083366}]}]}
{"op":"mcm","clk":"11921457394","pt":1724153792210,"mc":[{"id":"1.232019003","rc":[{"batb":[[0,1.65,10],[1,1.64,4],[2,1.63,1.01]],"ltp":2.2,"tv":33.04,"id":67083366}]}]}
{"op":"mcm","clk":"11921457476","pt":1724153794218,"mc":[{"id":"1.232019003","rc":[{"batb":[[1,1.63,1.01],[2,1.5,10.89]],"ltp":2.2,"tv":33.04,"id":67083366}]}]}
{"op":"mcm","clk":"11921457531","pt":1724153795705,"mc":[{"id":"1.232019003","rc":[{"batb":[[0,1.63,1.01],[1,1.5,10.89],[2,1.44,7.16]],"ltp":2.2,"tv":33.04,"id":67083366}]}]}
{"op":"mcm","clk":"11921457606","pt":1724153797614,"mc":[{"id":"1.232019003","rc":[{"batb":[[0,1.64,4],[1,1.63,1.01],[2,1.5,10.89]],"ltp":2.2,"tv":33.04,"id":67083366}]}]}
{"op":"mcm","clk":"11921457630","pt":1724153798025,"mc":[{"id":"1.232019003","rc":[{"batb":[[0,1.65,10],[1,1.64,4],[2,1.63,1.01]],"ltp":2.2,"tv":33.04,"id":67083366}]}]}
{"op":"mcm","clk":"11921457736","pt":1724153800256,"mc":[{"id":"1.232019003","rc":[{"batb":[[1,1.63,1.01],[2,1.5,10.89]],"ltp":2.2,"tv":33.04,"id":67083366}]}]}
{"op":"mcm","clk":"11921457812","pt":1724153801734,"mc":[{"id":"1.232019003","rc":[{"batb":[[0,1.63,1.01],[1,1.5,10.89],[2,1.44,7.16]],"ltp":2.2,"tv":33.04,"id":67083366}]}]}
{"op":"mcm","clk":"11921457965","pt":1724153805137,"mc":[{"id":"1.232019003","rc":[{"batb":[[0,1.64,4],[1,1.63,1.01],[2,1.5,10.89]],"ltp":2.2,"tv":33.04,"id":67083366}]}]}
{"op":"mcm","clk":"11921457995","pt":1724153805805,"mc":[{"id":"1.232019003","rc":[{"batb":[[0,1.65,10],[1,1.64,4],[2,1.63,1.01]],"ltp":2.2,"tv":33.04,"id":67083366}]}]}
{"op":"mcm","clk":"11921458079","pt":1724153807917,"mc":[{"id":"1.232019003","rc":[{"batb":[[1,1.63,1.01],[2,1.5,10.89]],"ltp":2.2,"tv":33.04,"id":67083366}]}]}
{"op":"mcm","clk":"11921458135","pt":1724153809150,"mc":[{"id":"1.232019003","rc":[{"batb":[[0,1.63,1.01],[1,1.5,10.89],[2,1.44,7.16]],"ltp":2.2,"tv":33.04,"id":67083366}]}]}
{"op":"mcm","clk":"11921458401","pt":1724153815228,"mc":[{"id":"1.232019003","rc":[{"batb":[[0,1.65,10],[1,1.64,4],[2,1.63,1.01]],"ltp":2.2,"tv":33.04,"id":67083366}]}]}
{"op":"mcm","clk":"11921458484","pt":1724153817546,"mc":[{"id":"1.232019003","rc":[{"batb":[[1,1.63,1.01],[2,1.5,10.89]],"ltp":2.2,"tv":33.04,"id":67083366}]}]}
{"op":"mcm","clk":"11921458535","pt":1724153818831,"mc":[{"id":"1.232019003","rc":[{"batb":[[0,1.63,1.01],[1,1.5,10.89],[2,1.44,7.16]],"ltp":2.2,"tv":33.04,"id":67083366}]}]}
{"op":"mcm","clk":"11921458837","pt":1724153825453,"mc":[{"id":"1.232019003","rc":[{"batb":[[0,1.64,4],[1,1.63,1.01],[2,1.5,10.89]],"ltp":2.2,"tv":33.04,"id":67083366}]}]}
{"op":"mcm","clk":"11921458845","pt":1724153825659,"mc":[{"id":"1.232019003","rc":[{"batb":[[0,1.65,10],[1,1.64,4],[2,1.63,1.01]],"ltp":2.2,"tv":33.04,"id":67083366}]}]}
{"op":"mcm","clk":"11921458973","pt":1724153828247,"mc":[{"id":"1.232019003","rc":[{"batb":[[1,1.63,1.01],[2,1.5,10.89]],"ltp":2.2,"tv":33.04,"id":67083366}]}]}
{"op":"mcm","clk":"11921459041","pt":1724153829545,"mc":[{"id":"1.232019003","rc":[{"batb":[[0,1.63,1.01],[1,1.5,10.89],[2,1.44,7.16]],"ltp":2.2,"tv":33.04,"id":67083366}]}]}
{"op":"mcm","clk":"11921459685","pt":1724153844190,"mc":[{"id":"1.232019003","rc":[{"batb":[[0,1.65,10],[1,1.64,4],[2,1.63,1.01]],"ltp":2.2,"tv":33.04,"id":67083366}]}]}
{"op":"mcm","clk":"11921459790","pt":1724153846402,"mc":[{"id":"1.232019003","rc":[{"batb":[[1,1.63,1.01],[2,1.5,10.89]],"ltp":2.2,"tv":33.04,"id":67083366}]}]}
{"op":"mcm","clk":"11921459861","pt":1724153847999,"mc":[{"id":"1.232019003","rc":[{"batb":[[0,1.63,1.01],[1,1.5,10.89],[2,1.44,7.16]],"ltp":2.2,"tv":33.04,"id":67083366}]}]}
{"op":"mcm","clk":"11921460123","pt":1724153854395,"mc":[{"id":"1.232019003","rc":[{"batb":[[0,1.65,10],[1,1.64,4],[2,1.63,1.01]],"ltp":2.2,"tv":33.04,"id":67083366}]}]}
{"op":"mcm","clk":"11921460215","pt":1724153856505,"mc":[{"id":"1.232019003","rc":[{"batb":[[1,1.63,1.01],[2,1.5,10.89]],"ltp":2.2,"tv":33.04,"id":67083366}]}]}
{"op":"mcm","clk":"11921460274","pt":1724153857894,"mc":[{"id":"1.232019003","rc":[{"batb":[[0,1.63,1.01],[1,1.5,10.89],[2,1.44,7.16]],"ltp":2.2,"tv":33.04,"id":67083366}]}]}
{"op":"mcm","clk":"11921460323","pt":1724153859188,"mc":[{"id":"1.232019003","rc":[{"batb":[[0,1.64,4],[1,1.63,1.01],[2,1.5,10.89]],"ltp":2.2,"tv":33.04,"id":67083366}]}]}
{"op":"mcm","clk":"11921460427","pt":1724153861498,"mc":[{"id":"1.232019003","rc":[{"batb":[[0,1.63,1.01],[1,1.5,10.89],[2,1.44,7.16]],"ltp":2.2,"tv":33.04,"id":67083366}]}]}
{"op":"mcm","clk":"11921460614","pt":1724153865623,"mc":[{"id":"1.232019003","rc":[{"batb":[[0,1.65,10],[1,1.64,4],[2,1.63,1.01]],"ltp":2.2,"tv":33.04,"id":67083366}]}]}
{"op":"mcm","clk":"11921460722","pt":1724153867692,"mc":[{"id":"1.232019003","rc":[{"batb":[[1,1.63,1.01],[2,1.5,10.89]],"ltp":2.2,"tv":33.04,"id":67083366}]}]}
{"op":"mcm","clk":"11921460777","pt":1724153869222,"mc":[{"id":"1.232019003","rc":[{"batb":[[0,1.63,1.01],[1,1.5,10.89],[2,1.44,7.16]],"ltp":2.2,"tv":33.04,"id":67083366}]}]}
{"op":"mcm","clk":"11921460861","pt":1724153870922,"mc":[{"id":"1.232019003","rc":[{"batb":[[0,1.64,4],[1,1.63,1.01],[2,1.5,10.89]],"ltp":2.2,"tv":33.04,"id":67083366}]}]}
{"op":"mcm","clk":"11921460976","pt":1724153873394,"mc":[{"id":"1.232019003","rc":[{"batb":[[0,1.63,1.01],[1,1.5,10.89],[2,1.44,7.16]],"ltp":2.2,"tv":33.04,"id":67083366}]}]}
{"op":"mcm","clk":"11921461573","pt":1724153888048,"mc":[{"id":"1.232019003","rc":[{"batb":[[0,1.65,10],[1,1.64,4],[2,1.63,1.01]],"ltp":2.2,"tv":33.04,"id":67083366}]}]}
{"op":"mcm","clk":"11921461656","pt":1724153890359,"mc":[{"id":"1.232019003","rc":[{"batb":[[1,1.63,1.01],[2,1.5,10.89]],"ltp":2.2,"tv":33.04,"id":67083366}]}]}
{"op":"mcm","clk":"11921461692","pt":1724153891762,"mc":[{"id":"1.232019003","rc":[{"batb":[[0,1.63,1.01],[1,1.5,10.89],[2,1.44,7.16]],"ltp":2.2,"tv":33.04,"id":67083366}]}]}
{"op":"mcm","clk":"11921461865","pt":1724153894959,"mc":[{"id":"1.232019003","rc":[{"batb":[[0,1.65,10],[1,1.64,4],[2,1.63,1.01]],"ltp":2.2,"tv":33.04,"id":67083366}]}]}
{"op":"mcm","clk":"11921461975","pt":1724153897242,"mc":[{"id":"1.232019003","rc":[{"batb":[[1,1.63,1.01],[2,1.5,10.89]],"ltp":2.2,"tv":33.04,"id":67083366}]}]}
{"op":"mcm","clk":"11921462035","pt":1724153898741,"mc":[{"id":"1.232019003","rc":[{"batb":[[0,1.63,1.01],[1,1.5,10.89],[2,1.44,7.16]],"ltp":2.2,"tv":33.04,"id":67083366}]}]}
{"op":"mcm","clk":"11921462219","pt":1724153903258,"mc":[{"id":"1.232019003","rc":[{"batb":[[0,1.65,10],[1,1.64,4],[2,1.63,1.01]],"ltp":2.2,"tv":33.04,"id":67083366}]}]}
{"op":"mcm","clk":"11921462303","pt":1724153905447,"mc":[{"id":"1.232019003","rc":[{"batb":[[1,1.63,1.01],[2,1.5,10.89]],"ltp":2.2,"tv":33.04,"id":67083366}]}]}
{"op":"mcm","clk":"11921462351","pt":1724153906941,"mc":[{"id":"1.232019003","rc":[{"batb":[[0,1.63,1.01],[1,1.5,10.89],[2,1.44,7.16]],"ltp":2.2,"tv":33.04,"id":67083366}]}]}
{"op":"mcm","clk":"11921462404","pt":1724153908166,"mc":[{"id":"1.232019003","rc":[{"batb":[[0,1.64,4],[1,1.63,1.01],[2,1.5,10.89]],"ltp":2.2,"tv":33.04,"id":67083366}]}]}
{"op":"mcm","clk":"11921462476","pt":1724153910576,"mc":[{"id":"1.232019003","rc":[{"batb":[[0,1.63,1.01],[1,1.5,10.89],[2,1.44,7.16]],"ltp":2.2,"tv":33.04,"id":67083366}]}]}
{"op":"mcm","clk":"11921462675","pt":1724153917559,"mc":[{"id":"1.232019003","rc":[{"batb":[[0,1.65,10],[1,1.64,4],[2,1.63,1.01]],"ltp":2.2,"tv":33.04,"id":67083366}]}]}
{"op":"mcm","clk":"11921462715","pt":1724153919971,"mc":[{"id":"1.232019003","rc":[{"batb":[[1,1.63,1.01],[2,1.5,10.89]],"ltp":2.2,"tv":33.04,"id":67083366}]}]}
{"op":"mcm","clk":"11921462758","pt":1724153921264,"mc":[{"id":"1.232019003","rc":[{"batb":[[0,1.63,1.01],[1,1.5,10.89],[2,1.44,7.16]],"ltp":2.2,"tv":33.04,"id":67083366}]}]}
{"op":"mcm","clk":"11921463047","pt":1724153930000,"mc":[{"id":"1.232019003","rc":[{"batb":[[0,1.65,10],[1,1.64,4],[2,1.63,1.01]],"ltp":2.2,"tv":33.04,"id":67083366}]}]}
{"op":"mcm","clk":"11921463130","pt":1724153932403,"mc":[{"id":"1.232019003","rc":[{"batb":[[1,1.63,1.01],[2,1.5,10.89]],"ltp":2.2,"tv":33.04,"id":67083366}]}]}
{"op":"mcm","clk":"11921463197","pt":1724153933691,"mc":[{"id":"1.232019003","rc":[{"batb":[[0,1.63,1.01],[1,1.5,10.89],[2,1.44,7.16]],"ltp":2.2,"tv":33.04,"id":67083366}]}]}
{"op":"mcm","clk":"11921463286","pt":1724153935995,"mc":[{"id":"1.232019003","rc":[{"batb":[[0,1.65,10],[1,1.64,4],[2,1.63,1.01]],"ltp":2.2,"tv":33.04,"id":67083366}]}]}
{"op":"mcm","clk":"11921463355","pt":1724153938097,"mc":[{"id":"1.232019003","rc":[{"batb":[[1,1.63,1.01],[2,1.5,10.89]],"ltp":2.2,"tv":33.04,"id":67083366}]}]}
{"op":"mcm","clk":"11921463399","pt":1724153939642,"mc":[{"id":"1.232019003","rc":[{"batb":[[0,1.63,1.01],[1,1.5,10.89],[2,1.44,7.16]],"ltp":2.2,"tv":33.04,"id":67083366}]}]}
{"op":"mcm","clk":"11921463429","pt":1724153940782,"mc":[{"id":"1.232019003","rc":[{"batb":[[0,1.64,4],[1,1.63,1.01],[2,1.5,10.89]],"ltp":2.2,"tv":33.04,"id":67083366}]}]}
{"op":"mcm","clk":"11921463516","pt":1724153943114,"mc":[{"id":"1.232019003","rc":[{"batb":[[0,1.63,1.01],[1,1.5,10.89],[2,1.44,7.16]],"ltp":2.2,"tv":33.04,"id":67083366}]}]}
{"op":"mcm","clk":"11921463722","pt":1724153948210,"mc":[{"id":"1.232019003","rc":[{"batb":[[0,1.65,10],[1,1.64,4],[2,1.63,1.01]],"ltp":2.2,"tv":33.04,"id":67083366}]}]}
{"op":"mcm","clk":"11921463849","pt":1724153950340,"mc":[{"id":"1.232019003","rc":[{"batb":[[1,1.63,1.01],[2,1.5,10.89]],"ltp":2.2,"tv":33.04,"id":67083366}]}]}
{"op":"mcm","clk":"11921463920","pt":1724153951908,"mc":[{"id":"1.232019003","rc":[{"batb":[[0,1.63,1.01],[1,1.5,10.89],[2,1.44,7.16]],"ltp":2.2,"tv":33.04,"id":67083366}]}]}
{"op":"mcm","clk":"11921464054","pt":1724153955626,"mc":[{"id":"1.232019003","rc":[{"batb":[[0,1.65,10],[1,1.64,4],[2,1.63,1.01]],"ltp":2.2,"tv":33.04,"id":67083366}]}]}
{"op":"mcm","clk":"11921464112","pt":1724153957943,"mc":[{"id":"1.232019003","rc":[{"batb":[[1,1.63,1.01],[2,1.5,10.89]],"ltp":2.2,"tv":33.04,"id":67083366}]}]}
{"op":"mcm","clk":"11921464156","pt":1724153959549,"mc":[{"id":"1.232019003","rc":[{"batb":[[0,1.63,1.01],[1,1.5,10.89],[2,1.44,7.16]],"ltp":2.2,"tv":33.04,"id":67083366}]}]}
{"op":"mcm","clk":"11921464205","pt":1724153960835,"mc":[{"id":"1.232019003","rc":[{"batb":[[0,1.64,4],[1,1.63,1.01],[2,1.5,10.89]],"ltp":2.2,"tv":33.04,"id":67083366}]}]}
{"op":"mcm","clk":"11921464277","pt":1724153963351,"mc":[{"id":"1.232019003","rc":[{"batb":[[0,1.65,10]],"ltp":2.2,"tv":33.04,"id":67083366}]}]}
{"op":"mcm","clk":"11921464381","pt":1724153966432,"mc":[{"id":"1.232019003","rc":[{"batb":[[0,1.64,4]],"ltp":2.2,"tv":33.04,"id":67083366}]}]}
{"op":"mcm","clk":"11921464458","pt":1724153969044,"mc":[{"id":"1.232019003","rc":[{"batb":[[0,1.63,1.01],[1,1.5,10.89],[2,1.44,7.16]],"ltp":2.2,"tv":33.04,"id":67083366}]}]}
{"op":"mcm","clk":"11921464586","pt":1724153973264,"mc":[{"id":"1.232019003","rc":[{"batb":[[0,1.64,4],[1,1.63,1.01],[2,1.5,10.89]],"ltp":2.2,"tv":33.04,"id":67083366}]}]}
{"op":"mcm","clk":"11921464605","pt":1724153973735,"mc":[{"id":"1.232019003","rc":[{"batb":[[0,1.65,10],[1,1.64,4],[2,1.63,1.01]],"ltp":2.2,"tv":33.04,"id":67083366}]}]}
{"op":"mcm","clk":"11921464663","pt":1724153975958,"mc":[{"id":"1.232019003","rc":[{"batb":[[1,1.63,1.01],[2,1.5,10.89]],"ltp":2.2,"tv":33.04,"id":67083366}]}]}
{"op":"mcm","clk":"11921464694","pt":1724153977239,"mc":[{"id":"1.232019003","rc":[{"batb":[[0,1.63,1.01],[1,1.5,10.89],[2,1.44,7.16]],"ltp":2.2,"tv":33.04,"id":67083366}]}]}
{"op":"mcm","clk":"11921464962","pt":1724153985430,"mc":[{"id":"1.232019003","rc":[{"batb":[[0,1.64,4],[1,1.63,1.01],[2,1.5,10.89]],"ltp":2.2,"tv":33.04,"id":67083366}]}]}
{"op":"mcm","clk":"11921464974","pt":1724153985739,"mc":[{"id":"1.232019003","rc":[{"batb":[[0,1.65,10],[1,1.64,4],[2,1.63,1.01]],"ltp":2.2,"tv":33.04,"id":67083366}]}]}
{"op":"mcm","clk":"11921465037","pt":1724153987760,"mc":[{"id":"1.232019003","rc":[{"batb":[[1,1.63,1.01],[2,1.5,10.89]],"ltp":2.2,"tv":33.04,"id":67083366}]}]}
{"op":"mcm","clk":"11921465079","pt":1724153989352,"mc":[{"id":"1.232019003","rc":[{"batb":[[0,1.63,1.01],[1,1.5,10.89],[2,1.44,7.16]],"ltp":2.2,"tv":33.04,"id":67083366}]}]}
{"op":"mcm","clk":"11921465171","pt":1724153992482,"mc":[{"id":"1.232019003","rc":[{"batb":[[0,1.64,4],[1,1.63,1.01],[2,1.5,10.89]],"ltp":2.2,"tv":33.04,"id":67083366}]}]}
{"op":"mcm","clk":"11921465188","pt":1724153992852,"mc":[{"id":"1.232019003","rc":[{"batb":[[0,1.65,10],[1,1.64,4],[2,1.63,1.01]],"ltp":2.2,"tv":33.04,"id":67083366}]}]}
{"op":"mcm","clk":"11921465245","pt":1724153994956,"mc":[{"id":"1.232019003","rc":[{"batb":[[1,1.63,1.01],[2,1.5,10.89]],"ltp":2.2,"tv":33.04,"id":67083366}]}]}
{"op":"mcm","clk":"11921465275","pt":1724153996345,"mc":[{"id":"1.232019003","rc":[{"batb":[[0,1.63,1.01],[1,1.5,10.89],[2,1.44,7.16]],"ltp":2.2,"tv":33.04,"id":67083366}]}]}
{"op":"mcm","clk":"11921465428","pt":1724154000262,"mc":[{"id":"1.232019003","rc":[{"batb":[[0,1.64,4],[1,1.63,1.01],[2,1.5,10.89]],"ltp":2.2,"tv":33.04,"id":67083366}]}]}
{"op":"mcm","clk":"11921465449","pt":1724154000679,"mc":[{"id":"1.232019003","rc":[{"batb":[[0,1.65,10],[1,1.64,4],[2,1.63,1.01]],"ltp":2.2,"tv":33.04,"id":67083366}]}]}
{"op":"mcm","clk":"11921465520","pt":1724154002696,"mc":[{"id":"1.232019003","rc":[{"batb":[[1,1.63,1.01],[2,1.5,10.89]],"ltp":2.2,"tv":33.04,"id":67083366}]}]}
{"op":"mcm","clk":"11921465584","pt":1724154004299,"mc":[{"id":"1.232019003","rc":[{"batb":[[0,1.63,1.01],[1,1.5,10.89],[2,1.44,7.16]],"ltp":2.2,"tv":33.04,"id":67083366}]}]}
{"op":"mcm","clk":"11921465709","pt":1724154008474,"mc":[{"id":"1.232019003","rc":[{"batb":[[0,1.64,4],[1,1.63,1.01],[2,1.5,10.89]],"ltp":2.2,"tv":33.04,"id":67083366}]}]}
{"op":"mcm","clk":"11921465717","pt":1724154008782,"mc":[{"id":"1.232019003","rc":[{"batb":[[0,1.65,10],[1,1.64,4],[2,1.63,1.01]],"ltp":2.2,"tv":33.04,"id":67083366}]}]}
{"op":"mcm","clk":"11921465766","pt":1724154010876,"mc":[{"id":"1.232019003","rc":[{"batb":[[1,1.63,1.01],[2,1.5,10.89]],"ltp":2.2,"tv":33.04,"id":67083366}]}]}
{"op":"mcm","clk":"11921465823","pt":1724154012476,"mc":[{"id":"1.232019003","rc":[{"batb":[[0,1.63,1.01],[1,1.5,10.89],[2,1.44,7.16]],"ltp":2.2,"tv":33.04,"id":67083366}]}]}
{"op":"mcm","clk":"11921466068","pt":1724154021395,"mc":[{"id":"1.232019003","rc":[{"batb":[[0,1.65,10],[1,1.64,4],[2,1.63,1.01]],"ltp":2.2,"tv":33.04,"id":67083366}]}]}
{"op":"mcm","clk":"11921466132","pt":1724154023407,"mc":[{"id":"1.232019003","rc":[{"batb":[[1,1.63,1.01],[2,1.5,10.89]],"ltp":2.2,"tv":33.04,"id":67083366}]}]}
{"op":"mcm","clk":"11921466188","pt":1724154025214,"mc":[{"id":"1.232019003","rc":[{"batb":[[0,1.63,1.01],[1,1.5,10.89],[2,1.44,7.16]],"ltp":2.2,"tv":33.04,"id":67083366}]}]}
{"op":"mcm","clk":"11921466318","pt":1724154029528,"mc":[{"id":"1.232019003","rc":[{"batb":[[0,1.65,10],[1,1.64,4],[2,1.63,1.01]],"ltp":2.2,"tv":33.04,"id":67083366}]}]}
{"op":"mcm","clk":"11921466404","pt":1724154031593,"mc":[{"id":"1.232019003","rc":[{"batb":[[1,1.63,1.01],[2,1.5,10.89]],"ltp":2.2,"tv":33.04,"id":67083366}]}]}
{"op":"mcm","clk":"11921466442","pt":1724154032984,"mc":[{"id":"1.232019003","rc":[{"batb":[[0,1.63,1.01],[1,1.5,10.89],[2,1.44,7.16]],"ltp":2.2,"tv":33.04,"id":67083366}]}]}
{"op":"mcm","clk":"11921466493","pt":1724154034528,"mc":[{"id":"1.232019003","rc":[{"batb":[[0,1.64,4],[1,1.63,1.01],[2,1.5,10.89]],"ltp":2.2,"tv":33.04,"id":67083366},{"batb":[[0,2.08,1.54],[1,1.53,1.84],[2,1.51,10]],"ltp":1.83,"tv":19.86,"id":72857116}]}]}
{"op":"mcm","clk":"11921466566","pt":1724154037108,"mc":[{"id":"1.232019003","rc":[{"batb":[[0,1.63,1.01],[1,1.5,10.89],[2,1.44,7.16]],"ltp":2.2,"tv":33.04,"id":67083366}]}]}
{"op":"mcm","clk":"11921466672","pt":1724154040318,"mc":[{"id":"1.232019003","rc":[{"batb":[[0,1.65,10],[1,1.64,4],[2,1.63,1.01]],"ltp":2.2,"tv":33.04,"id":67083366},{"batb":[[0,1.53,1.84],[1,1.51,10],[2,1.44,6.4]],"ltp":1.83,"tv":19.86,"id":72857116}]}]}
{"op":"mcm","clk":"11921466751","pt":1724154042818,"mc":[{"id":"1.232019003","rc":[{"batb":[[1,1.63,1.01],[2,1.5,10.89]],"ltp":2.2,"tv":33.04,"id":67083366}]}]}
{"op":"mcm","clk":"11921466777","pt":1724154043800,"mc":[{"id":"1.232019003","rc":[{"batb":[[0,1.63,1.01],[1,1.5,10.89],[2,1.44,7.16]],"ltp":2.2,"tv":33.04,"id":67083366}]}]}
{"op":"mcm","clk":"11921466891","pt":1724154047295,"mc":[{"id":"1.232019003","rc":[{"batb":[[0,1.65,10],[1,1.64,4],[2,1.63,1.01]],"ltp":2.2,"tv":33.04,"id":67083366},{"batb":[[0,2.06,1.54],[1,1.53,1.84],[2,1.51,10]],"ltp":1.83,"tv":19.86,"id":72857116}]}]}
{"op":"mcm","clk":"11921466966","pt":1724154049415,"mc":[{"id":"1.232019003","rc":[{"batb":[[1,1.63,1.01],[2,1.5,10.89]],"ltp":2.2,"tv":33.04,"id":67083366}]}]}
{"op":"mcm","clk":"11921467022","pt":1724154050603,"mc":[{"id":"1.232019003","rc":[{"batb":[[0,1.63,1.01],[1,1.5,10.89],[2,1.44,7.16]],"ltp":2.2,"tv":33.04,"id":67083366}]}]}
{"op":"mcm","clk":"11921467118","pt":1724154053425,"mc":[{"id":"1.232019003","rc":[{"batb":[[0,1.64,4],[1,1.63,1.01],[2,1.5,10.89]],"ltp":2.2,"tv":33.04,"id":67083366}]}]}
{"op":"mcm","clk":"11921467136","pt":1724154053939,"mc":[{"id":"1.232019003","rc":[{"batb":[[0,1.65,10],[1,1.64,4],[2,1.63,1.01]],"ltp":2.2,"tv":33.04,"id":67083366}]}]}
{"op":"mcm","clk":"11921467200","pt":1724154056042,"mc":[{"id":"1.232019003","rc":[{"batb":[[1,1.63,1.01],[2,1.5,10.89]],"ltp":2.2,"tv":33.04,"id":67083366}]}]}
{"op":"mcm","clk":"11921467238","pt":1724154057325,"mc":[{"id":"1.232019003","rc":[{"batb":[[0,1.63,1.01],[1,1.5,10.89],[2,1.44,7.16]],"ltp":2.2,"tv":33.04,"id":67083366}]}]}
{"op":"mcm","clk":"11921467279","pt":1724154058611,"mc":[{"id":"1.232019003","rc":[{"batb":[[0,1.53,1.84],[1,1.51,10],[2,1.44,6.4]],"ltp":1.83,"tv":19.86,"id":72857116}]}]}
{"op":"mcm","clk":"11921467283","pt":1724154058714,"mc":[{"id":"1.232019003","rc":[{"batb":[[0,1.64,4],[1,1.63,1.01],[2,1.5,10.89]],"ltp":2.2,"tv":33.04,"id":67083366}]}]}
{"op":"mcm","clk":"11921467339","pt":1724154060311,"mc":[{"id":"1.232019003","rc":[{"batb":[[0,1.65,10],[1,1.64,4],[2,1.63,1.01]],"ltp":2.2,"tv":33.04,"id":67083366}]}]}
{"op":"mcm","clk":"11921467373","pt":1724154061244,"mc":[{"id":"1.232019003","rc":[{"batb":[[1,1.63,1.01],[2,1.5,10.89]],"ltp":2.2,"tv":33.04,"id":67083366}]}]}
{"op":"mcm","clk":"11921467496","pt":1724154064255,"mc":[{"id":"1.232019003","rc":[{"batb":[[0,1.64,4]],"ltp":2.2,"tv":33.04,"id":67083366}]}]}
{"op":"mcm","clk":"11921467572","pt":1724154066519,"mc":[{"id":"1.232019003","rc":[{"batb":[[0,1.63,1.01],[1,1.5,10.89],[2,1.44,7.16]],"ltp":2.2,"tv":33.04,"id":67083366}]}]}
{"op":"mcm","clk":"11921467817","pt":1724154074257,"mc":[{"id":"1.232019003","rc":[{"batb":[[0,1.65,10],[1,1.64,4],[2,1.63,1.01]],"ltp":2.2,"tv":33.04,"id":67083366}]}]}
{"op":"mcm","clk":"11921467909","pt":1724154076475,"mc":[{"id":"1.232019003","rc":[{"batb":[[1,1.63,1.01],[2,1.5,10.89]],"ltp":2.2,"tv":33.04,"id":67083366}]}]}
{"op":"mcm","clk":"11921467945","pt":1724154077662,"mc":[{"id":"1.232019003","rc":[{"batb":[[0,1.63,1.01],[1,1.5,10.89],[2,1.44,7.16]],"ltp":2.2,"tv":33.04,"id":67083366}]}]}
{"op":"mcm","clk":"11921468182","pt":1724154084562,"mc":[{"id":"1.232019003","rc":[{"batb":[[0,1.65,10],[1,1.64,4],[2,1.63,1.01]],"ltp":2.2,"tv":33.04,"id":67083366}]}]}
{"op":"mcm","clk":"11921468257","pt":1724154086469,"mc":[{"id":"1.232019003","rc":[{"batb":[[1,1.63,1.01],[2,1.5,10.89]],"ltp":2.2,"tv":33.04,"id":67083366}]}]}
{"op":"mcm","clk":"11921468308","pt":1724154088165,"mc":[{"id":"1.232019003","rc":[{"batb":[[0,1.63,1.01],[1,1.5,10.89],[2,1.44,7.16]],"ltp":2.2,"tv":33.04,"id":67083366}]}]}
{"op":"mcm","clk":"11921468443","pt":1724154091256,"mc":[{"id":"1.232019003","rc":[{"batb":[[0,1.65,10],[1,1.64,4],[2,1.63,1.01]],"ltp":2.2,"tv":33.04,"id":67083366}]}]}
{"op":"mcm","clk":"11921468529","pt":1724154093278,"mc":[{"id":"1.232019003","rc":[{"trd":[[2.2,1]],"batl":[[0,5,1.54],[1,9,1.54],[2,9,0]],"ltp":2.2,"tv":33.59,"id":67083366},{"trd":[[1.83,1.2]],"batl":[[0,2.1,1.75],[1,2.36,2.56],[2,5,1.54]],"ltp":1.83,"tv":20.52,"id":72857116}],"tv":54.12}]}
{"op":"mcm","clk":"11921468541","pt":1724154093688,"mc":[{"id":"1.232019003","rc":[{"batb":[[1,1.63,1.01],[2,1.5,10.89]],"ltp":2.2,"tv":33.59,"id":67083366}]}]}
{"op":"mcm","clk":"11921468587","pt":1724154094979,"mc":[{"id":"1.232019003","rc":[{"batb":[[0,1.63,1.01],[1,1.5,10.89],[2,1.44,7.16]],"ltp":2.2,"tv":33.59,"id":67083366}]}]}
{"op":"mcm","clk":"11921468891","pt":1724154103388,"mc":[{"id":"1.232019003","rc":[{"batl":[[0,2.36,3.43],[1,5,1.54],[2,9,1.54]],"ltp":1.83,"tv":20.52,"id":72857116}]}]}
{"op":"mcm","clk":"11921469186","pt":1724154111584,"mc":[{"id":"1.232019003","rc":[{"trd":[[2.1,3.52]],"batl":[[0,2.36,2.86]],"ltp":2.1,"tv":21.66,"id":72857116}],"tv":55.26}]}
{"op":"mcm","clk":"11921469359","pt":1724154116296,"mc":[{"id":"1.232019003","rc":[{"batb":[[0,1.56,10.94],[1,1.55,24.62],[2,1.51,10.89]],"ltp":2.1,"tv":21.66,"id":72857116}]}]}
{"op":"mcm","clk":"11921469468","pt":1724154119781,"mc":[{"id":"1.232019003","rc":[{"batb":[[0,1.55,25.56],[1,1.51,10.89],[2,1.44,6.4]],"ltp":2.1,"tv":21.66,"id":72857116}]}]}
{"op":"mcm","clk":"11921469566","pt":1724154122281,"mc":[{"id":"1.232019003","rc":[{"batb":[[0,1.56,10.94],[1,1.55,24.62],[2,1.51,10.89]],"ltp":2.1,"tv":21.66,"id":72857116}]}]}
{"op":"mcm","clk":"11921469730","pt":1724154125285,"mc":[{"id":"1.232019003","rc":[{"batl":[[0,1.61,1.54],[1,2.36,2.86],[2,5,1.54]],"ltp":2.1,"tv":21.66,"id":72857116}]}]}
{"op":"mcm","clk":"11921469750","pt":1724154125704,"mc":[{"id":"1.232019003","rc":[{"batb":[[0,1.55,25.56],[1,1.51,10.89],[2,1.44,6.4]],"ltp":2.1,"tv":21.66,"id":72857116}]}]}
{"op":"mcm","clk":"11921469954","pt":1724154129792,"mc":[{"id":"1.232019003","rc":[{"trd":[[1.61,3.08]],"batb":[[0,1.61,1.41],[1,1.55,25.56],[2,1.51,10.89]],"batl":[[0,2.36,2.86],[1,5,1.54],[2,9,1.54]],"ltp":1.61,"tv":24.73,"id":72857116}],"tv":58.33}]}
{"op":"mcm","clk":"11921470364","pt":1724154139624,"mc":[{"id":"1.232019003","rc":[{"trd":[[2.1,4.13],[2.36,1.5]],"batl":[[0,2.36,1.81]],"ltp":2.36,"tv":26.85,"id":72857116}],"tv":60.44}]}
{"op":"mcm","clk":"11921470391","pt":1724154140138,"mc":[{"id":"1.232019003","rc":[{"batb":[[0,1.56,10.94],[1,1.55,24.62]],"ltp":2.36,"tv":26.85,"id":72857116}]}]}
{"op":"mcm","clk":"11921470552","pt":1724154143640,"mc":[{"id":"1.232019003","rc":[{"batb":[[0,1.55,25.56],[1,1.51,10.89],[2,1.44,6.4]],"ltp":2.36,"tv":26.85,"id":72857116}]}]}
{"op":"mcm","clk":"11921470637","pt":1724154145904,"mc":[{"id":"1.232019003","rc":[{"batb":[[0,1.56,10.94],[1,1.55,24.62],[2,1.51,10.89]],"ltp":2.36,"tv":26.85,"id":72857116}]}]}
{"op":"mcm","clk":"11921470771","pt":1724154149241,"mc":[{"id":"1.232019003","rc":[{"batb":[[0,1.55,25.56],[1,1.51,10.89],[2,1.44,6.4]],"ltp":2.36,"tv":26.85,"id":72857116}]}]}
{"op":"mcm","clk":"11921471032","pt":1724154155944,"mc":[{"id":"1.232019003","rc":[{"batb":[[0,1.56,10.94],[1,1.55,24.62],[2,1.51,10.89]],"ltp":2.36,"tv":26.85,"id":72857116}]}]}
{"op":"mcm","clk":"11921471152","pt":1724154159242,"mc":[{"id":"1.232019003","rc":[{"batb":[[0,1.55,25.56],[1,1.51,10.89],[2,1.44,6.4]],"ltp":2.36,"tv":26.85,"id":72857116}]}]}
{"op":"mcm","clk":"11921471280","pt":1724154162030,"mc":[{"id":"1.232019003","rc":[{"batb":[[0,1.56,10.94],[1,1.55,24.62],[2,1.51,10.89]],"ltp":2.36,"tv":26.85,"id":72857116}]}]}
{"op":"mcm","clk":"11921471405","pt":1724154165435,"mc":[{"id":"1.232019003","rc":[{"batb":[[0,1.55,25.56],[1,1.51,10.89],[2,1.44,6.4]],"ltp":2.36,"tv":26.85,"id":72857116}]}]}
{"op":"mcm","clk":"11921471534","pt":1724154168736,"mc":[{"id":"1.232019003","rc":[{"batb":[[0,1.56,10.94],[1,1.55,24.62],[2,1.51,10.89]],"ltp":2.36,"tv":26.85,"id":72857116}]}]}
{"op":"mcm","clk":"11921471659","pt":1724154172077,"mc":[{"id":"1.232019003","rc":[{"batb":[[0,1.55,25.56],[1,1.51,10.89],[2,1.44,6.4]],"ltp":2.36,"tv":26.85,"id":72857116}]}]}
{"op":"mcm","clk":"11921471813","pt":1724154176061,"mc":[{"id":"1.232019003","rc":[{"batb":[[0,1.56,10.94],[1,1.55,24.62],[2,1.51,10.89]],"ltp":2.36,"tv":26.85,"id":72857116}]}]}
{"op":"mcm","clk":"11921471947","pt":1724154179873,"mc":[{"id":"1.232019003","rc":[{"batb":[[0,1.55,25.56],[1,1.51,10.89],[2,1.44,6.4]],"ltp":2.36,"tv":26.85,"id":72857116}]}]}
{"op":"mcm","clk":"11921472093","pt":1724154183549,"mc":[{"id":"1.232019003","rc":[{"batb":[[0,1.56,10.94],[1,1.55,24.62],[2,1.51,10.89]],"ltp":2.36,"tv":26.85,"id":72857116}]}]}
{"op":"mcm","clk":"11921472131","pt":1724154184368,"mc":[{"id":"1.232019003","rc":[{"batb":[[1,1.51,10.89],[2,1.44,6.4]],"ltp":2.36,"tv":26.85,"id":72857116}]}]}
{"op":"mcm","clk":"11921472253","pt":1724154186964,"mc":[{"id":"1.232019003","rc":[{"batb":[[0,1.53,1.84],[1,1.51,10]],"ltp":2.36,"tv":26.85,"id":72857116}]}]}
{"op":"mcm","clk":"11921543583","pt":1724155800369,"mc":[{"id":"1.232019003","rc":[{"trd":[[1.56,6.97],[1.57,1.88],[1.63,4.8],[1.71,2.06],[1.9,2.63]],"batb":[[2,1.44,7.16]],"ltp":2.2,"tv":33.58,"id":67083366},{"trd":[[1.87,5.12],[1.88,3.94],[2.1,4.13]],"batb":[[0,1.54,5.86],[1,1.51,10.89],[2,1.44,6.39]],"batl":[[0,2.36,1.81]],"ltp":2.36,"tv":26.84,"id":72857116}],"tv":60.42}]}
{"op":"mcm","clk":"11921543607","pt":1724155800782,"mc":[{"id":"1.232019003","rc":[{"batb":[[0,1.55,10.94],[1,1.54,4.92],[2,1.51,10.89]],"ltp":2.36,"tv":26.84,"id":72857116}]}]}
{"op":"mcm","clk":"11921543791","pt":1724155804020,"mc":[{"id":"1.232019003","rc":[{"batb":[[0,1.54,5.86],[1,1.51,10.89],[2,1.44,6.39]],"ltp":2.36,"tv":26.84,"id":72857116}]}]}
{"op":"mcm","clk":"11921543931","pt":1724155806593,"mc":[{"id":"1.232019003","rc":[{"batb":[[0,1.55,10.94],[1,1.54,4.92],[2,1.51,10.89]],"ltp":2.36,"tv":26.84,"id":72857116}]}]}
{"op":"mcm","clk":"11921544097","pt":1724155809880,"mc":[{"id":"1.232019003","rc":[{"batb":[[0,1.54,5.86],[1,1.51,10.89],[2,1.44,6.39]],"ltp":2.36,"tv":26.84,"id":72857116}]}]}
{"op":"mcm","clk":"11921544262","pt":1724155813320,"mc":[{"id":"1.232019003","rc":[{"batb":[[0,1.55,10.94],[1,1.54,4.92],[2,1.51,10.89]],"ltp":2.36,"tv":26.84,"id":72857116}]}]}
{"op":"mcm","clk":"11921544420","pt":1724155816402,"mc":[{"id":"1.232019003","rc":[{"batb":[[0,1.56,5.86],[1,1.55,10],[2,1.54,4.92]],"ltp":2.36,"tv":26.84,"id":72857116}]}]}
{"op":"mcm","clk":"11921544436","pt":1724155816814,"mc":[{"id":"1.232019003","rc":[{"batb":[[1,1.54,4.92],[2,1.51,10.89]],"ltp":2.36,"tv":26.84,"id":72857116}]}]}
{"op":"mcm","clk":"11921544743","pt":1724155822735,"mc":[{"id":"1.232019003","rc":[{"batb":[[0,1.57,10.94],[1,1.56,4.92],[2,1.54,4.92]],"ltp":2.36,"tv":26.84,"id":72857116}]}]}
{"op":"mcm","clk":"11921544915","pt":1724155826126,"mc":[{"id":"1.232019003","rc":[{"batb":[[0,1.56,5.86],[1,1.54,4.92],[2,1.51,10.89]],"ltp":2.36,"tv":26.84,"id":72857116}]}]}
{"op":"mcm","clk":"11921545018","pt":1724155828598,"mc":[{"id":"1.232019003","rc":[{"batb":[[0,1.55,10.94]],"ltp":2.36,"tv":26.84,"id":72857116}]}]}
{"op":"mcm","clk":"11921545204","pt":1724155832042,"mc":[{"id":"1.232019003","rc":[{"batb":[[0,1.54,5.86],[1,1.51,10.89],[2,1.44,6.39]],"ltp":2.36,"tv":26.84,"id":72857116}]}]}
{"op":"mcm","clk":"11921545322","pt":1724155834715,"mc":[{"id":"1.232019003","rc":[{"batb":[[0,1.55,10.94],[1,1.54,4.92],[2,1.51,10.89]],"ltp":2.36,"tv":26.84,"id":72857116}]}]}
{"op":"mcm","clk":"11921545484","pt":1724155838115,"mc":[{"id":"1.232019003","rc":[{"batb":[[0,1.54,5.86],[1,1.51,10.89],[2,1.44,6.39]],"ltp":2.36,"tv":26.84,"id":72857116}]}]}
{"op":"mcm","clk":"11921545696","pt":1724155843613,"mc":[{"id":"1.232019003","rc":[{"batb":[[0,1.55,10.94],[1,1.54,4.92],[2,1.51,10.89]],"ltp":2.36,"tv":26.84,"id":72857116}]}]}
{"op":"mcm","clk":"11921545829","pt":1724155846959,"mc":[{"id":"1.232019003","rc":[{"batb":[[0,1.54,5.86],[1,1.51,10.89],[2,1.44,6.39]],"ltp":2.36,"tv":26.84,"id":72857116}]}]}
{"op":"mcm","clk":"11921546047","pt":1724155852051,"mc":[{"id":"1.232019003","rc":[{"batb":[[0,1.55,10.94],[1,1.54,4.92],[2,1.51,10.89]],"ltp":2.36,"tv":26.84,"id":72857116}]}]}
{"op":"mcm","clk":"11921546196","pt":1724155855353,"mc":[{"id":"1.232019003","rc":[{"batb":[[0,1.54,5.86],[1,1.51,10.89],[2,1.44,6.39]],"ltp":2.36,"tv":26.84,"id":72857116}]}]}
{"op":"mcm","clk":"11921546305","pt":1724155857716,"mc":[{"id":"1.232019003","rc":[{"batb":[[0,1.55,10.94],[1,1.54,4.92],[2,1.51,10.89]],"ltp":2.36,"tv":26.84,"id":72857116}]}]}
{"op":"mcm","clk":"11921546489","pt":1724155861364,"mc":[{"id":"1.232019003","rc":[{"batb":[[0,1.54,5.86],[1,1.51,10.89],[2,1.44,6.39]],"ltp":2.36,"tv":26.84,"id":72857116}]}]}
{"op":"mcm","clk":"11921546636","pt":1724155864344,"mc":[{"id":"1.232019003","rc":[{"batb":[[0,1.55,10.94],[1,1.54,4.92],[2,1.51,10.89]],"ltp":2.36,"tv":26.84,"id":72857116}]}]}
{"op":"mcm","clk":"11921546783","pt":1724155867676,"mc":[{"id":"1.232019003","rc":[{"batb":[[0,1.54,5.86],[1,1.51,10.89],[2,1.44,6.39]],"ltp":2.36,"tv":26.84,"id":72857116}]}]}
{"op":"mcm","clk":"11921546941","pt":1724155870954,"mc":[{"id":"1.232019003","rc":[{"batb":[[0,1.55,10.94],[1,1.54,4.92],[2,1.51,10.89]],"ltp":2.36,"tv":26.84,"id":72857116}]}]}
{"op":"mcm","clk":"11921547095","pt":1724155874247,"mc":[{"id":"1.232019003","rc":[{"batb":[[0,1.54,5.86],[1,1.51,10.89],[2,1.44,6.39]],"ltp":2.36,"tv":26.84,"id":72857116}]}]}
{"op":"mcm","clk":"11921547250","pt":1724155877593,"mc":[{"id":"1.232019003","rc":[{"batb":[[0,1.55,10.94],[1,1.54,4.92],[2,1.51,10.89]],"ltp":2.36,"tv":26.84,"id":72857116}]}]}
{"op":"mcm","clk":"11921547426","pt":1724155881042,"mc":[{"id":"1.232019003","rc":[{"batb":[[0,1.54,5.86],[1,1.51,10.89],[2,1.44,6.39]],"ltp":2.36,"tv":26.84,"id":72857116}]}]}
{"op":"mcm","clk":"11921547637","pt":1724155885263,"mc":[{"id":"1.232019003","rc":[{"batb":[[0,1.55,10.94],[1,1.54,4.92],[2,1.51,10.89]],"ltp":2.36,"tv":26.84,"id":72857116}]}]}
{"op":"mcm","clk":"11921547808","pt":1724155888659,"mc":[{"id":"1.232019003","rc":[{"batb":[[0,1.54,5.86],[1,1.51,10.89],[2,1.44,6.39]],"ltp":2.36,"tv":26.84,"id":72857116}]}]}
{"op":"mcm","clk":"11921547902","pt":1724155890877,"mc":[{"id":"1.232019003","rc":[{"batb":[[0,1.55,10.94],[1,1.54,4.92],[2,1.51,10.89]],"ltp":2.36,"tv":26.84,"id":72857116}]}]}
{"op":"mcm","clk":"11921548055","pt":1724155894268,"mc":[{"id":"1.232019003","rc":[{"batb":[[0,1.54,5.86],[1,1.51,10.89],[2,1.44,6.39]],"ltp":2.36,"tv":26.84,"id":72857116}]}]}
{"op":"mcm","clk":"11921548212","pt":1724155897257,"mc":[{"id":"1.232019003","rc":[{"batb":[[0,1.55,10.94],[1,1.54,4.92],[2,1.51,10.89]],"ltp":2.36,"tv":26.84,"id":72857116}]}]}
{"op":"mcm","clk":"11921548412","pt":1724155900910,"mc":[{"id":"1.232019003","rc":[{"batb":[[0,1.54,5.86],[1,1.51,10.89],[2,1.44,6.39]],"ltp":2.36,"tv":26.84,"id":72857116}]}]}
{"op":"mcm","clk":"11921548583","pt":1724155904708,"mc":[{"id":"1.232019003","rc":[{"batb":[[0,1.55,10.94],[1,1.54,4.92],[2,1.51,10.89]],"ltp":2.36,"tv":26.84,"id":72857116}]}]}
{"op":"mcm","clk":"11921548743","pt":1724155908095,"mc":[{"id":"1.232019003","rc":[{"batb":[[0,1.54,5.86],[1,1.51,10.89],[2,1.44,6.39]],"ltp":2.36,"tv":26.84,"id":72857116}]}]}
{"op":"mcm","clk":"11921548924","pt":1724155910823,"mc":[{"id":"1.232019003","rc":[{"batb":[[0,1.55,10.94],[1,1.54,4.92],[2,1.51,10.89]],"ltp":2.36,"tv":26.84,"id":72857116}]}]}
{"op":"mcm","clk":"11921549107","pt":1724155914307,"mc":[{"id":"1.232019003","rc":[{"batb":[[0,1.54,5.86],[1,1.51,10.89],[2,1.44,6.39]],"ltp":2.36,"tv":26.84,"id":72857116}]}]}
{"op":"mcm","clk":"11921549261","pt":1724155917290,"mc":[{"id":"1.232019003","rc":[{"batb":[[0,1.55,10.94],[1,1.54,4.92],[2,1.51,10.89]],"ltp":2.36,"tv":26.84,"id":72857116}]}]}
{"op":"mcm","clk":"11921549452","pt":1724155920696,"mc":[{"id":"1.232019003","rc":[{"batb":[[0,1.54,5.86],[1,1.51,10.89],[2,1.44,6.39]],"ltp":2.36,"tv":26.84,"id":72857116}]}]}
{"op":"mcm","clk":"11921549573","pt":1724155923018,"mc":[{"id":"1.232019003","rc":[{"batb":[[0,1.55,10.94],[1,1.54,4.92],[2,1.51,10.89]],"ltp":2.36,"tv":26.84,"id":72857116}]}]}
{"op":"mcm","clk":"11921549742","pt":1724155926612,"mc":[{"id":"1.232019003","rc":[{"batb":[[0,1.54,5.86],[1,1.51,10.89],[2,1.44,6.39]],"ltp":2.36,"tv":26.84,"id":72857116}]}]}
{"op":"mcm","clk":"11921549894","pt":1724155929709,"mc":[{"id":"1.232019003","rc":[{"batb":[[0,1.55,10.94],[1,1.54,4.92],[2,1.51,10.89]],"ltp":2.36,"tv":26.84,"id":72857116}]}]}
{"op":"mcm","clk":"11921550036","pt":1724155933140,"mc":[{"id":"1.232019003","rc":[{"batb":[[0,1.54,5.86],[1,1.51,10.89],[2,1.44,6.39]],"ltp":2.36,"tv":26.84,"id":72857116}]}]}
{"op":"mcm","clk":"11921550175","pt":1724155936727,"mc":[{"id":"1.232019003","rc":[{"batb":[[0,1.55,10.94],[1,1.54,4.92],[2,1.51,10.89]],"ltp":2.36,"tv":26.84,"id":72857116}]}]}
{"op":"mcm","clk":"11921550312","pt":1724155940118,"mc":[{"id":"1.232019003","rc":[{"batb":[[0,1.54,5.86],[1,1.51,10.89],[2,1.44,6.39]],"ltp":2.36,"tv":26.84,"id":72857116}]}]}
{"op":"mcm","clk":"11921550532","pt":1724155945145,"mc":[{"id":"1.232019003","rc":[{"batb":[[0,1.55,10.94],[1,1.54,4.92],[2,1.51,10.89]],"ltp":2.36,"tv":26.84,"id":72857116}]}]}
{"op":"mcm","clk":"11921550709","pt":1724155948852,"mc":[{"id":"1.232019003","rc":[{"batb":[[0,1.54,5.86],[1,1.51,10.89],[2,1.44,6.39]],"ltp":2.36,"tv":26.84,"id":72857116}]}]}
{"op":"mcm","clk":"11921551042","pt":1724155956044,"mc":[{"id":"1.232019003","rc":[{"batb":[[0,1.55,10.94],[1,1.54,4.92],[2,1.51,10.89]],"ltp":2.36,"tv":26.84,"id":72857116}]}]}
{"op":"mcm","clk":"11921551200","pt":1724155959648,"mc":[{"id":"1.232019003","rc":[{"batb":[[0,1.54,5.86],[1,1.51,10.89],[2,1.44,6.39]],"ltp":2.36,"tv":26.84,"id":72857116}]}]}
{"op":"mcm","clk":"11921551329","pt":1724155962838,"mc":[{"id":"1.232019003","rc":[{"batb":[[0,1.55,10.94],[1,1.54,4.92],[2,1.51,10.89]],"ltp":2.36,"tv":26.84,"id":72857116}]}]}
{"op":"mcm","clk":"11921551456","pt":1724155966177,"mc":[{"id":"1.232019003","rc":[{"batb":[[0,1.54,5.86],[1,1.51,10.89],[2,1.44,6.39]],"ltp":2.36,"tv":26.84,"id":72857116}]}]}
{"op":"mcm","clk":"11921551648","pt":1724155971059,"mc":[{"id":"1.232019003","rc":[{"batb":[[0,1.55,10.94],[1,1.54,4.92],[2,1.51,10.89]],"ltp":2.36,"tv":26.84,"id":72857116}]}]}
{"op":"mcm","clk":"11921551830","pt":1724155975191,"mc":[{"id":"1.232019003","rc":[{"batb":[[0,1.54,5.86],[1,1.51,10.89],[2,1.44,6.39]],"ltp":2.36,"tv":26.84,"id":72857116}]}]}
{"op":"mcm","clk":"11921551870","pt":1724155976061,"mc":[{"id":"1.232019003","rc":[{"batb":[[0,1.62,2.56],[1,1.54,5.86],[2,1.51,10.89]],"ltp":2.36,"tv":26.84,"id":72857116}]}]}
{"op":"mcm","clk":"11921554478","pt":1724156034831,"mc":[{"id":"1.232019003","rc":[{"batb":[[1,1.54,4.92]],"ltp":2.36,"tv":26.84,"id":72857116}]}]}
{"op":"mcm","clk":"11921589930","pt":1724156804708,"mc":[{"id":"1.232019003","rc":[{"batb":[[0,1.74,2.95],[1,1.63,1.01],[2,1.5,10.89]],"ltp":2.2,"tv":33.58,"id":67083366}]}]}
{"op":"mcm","clk":"11921611721","pt":1724157146142,"mc":[{"id":"1.232019003","rc":[{"batb":[[0,1.63,1.01],[1,1.5,10.89],[2,1.44,7.16]],"ltp":2.2,"tv":33.58,"id":67083366},{"batb":[[1,1.51,10.89],[2,1.44,6.39]],"ltp":2.36,"tv":26.84,"id":72857116}]}]}
{"op":"mcm","clk":"11921612264","pt":1724157156379,"mc":[{"id":"1.232019003","rc":[{"batb":[[0,1.74,1.48],[1,1.63,1.01],[2,1.5,10.89]],"ltp":2.2,"tv":33.58,"id":67083366}]}]}
{"op":"mcm","clk":"11921640844","pt":1724157683383,"mc":[{"id":"1.232019003","rc":[{"batb":[[1,1.6,2.56],[2,1.51,10.89]],"ltp":2.36,"tv":26.84,"id":72857116}]}]}
{"op":"mcm","clk":"11921640899","pt":1724157684362,"mc":[{"id":"1.232019003","rc":[{"batb":[[2,1.57,2.56]],"ltp":2.36,"tv":26.84,"id":72857116}]}]}
{"op":"mcm","clk":"11921641067","pt":1724157687259,"mc":[{"id":"1.232019003","rc":[{"batb":[[0,1.75,3.41],[1,1.74,1.48],[2,1.63,1.01]],"ltp":2.2,"tv":33.58,"id":67083366}]}]}
{"op":"mcm","clk":"11921655060","pt":1724157784282,"mc":[{"id":"1.232019003","rc":[{"batb":[[1,1.63,1.01],[2,1.5,10.89]],"ltp":2.2,"tv":33.58,"id":67083366}]}]}
{"op":"mcm","clk":"11921669383","pt":1724158066167,"mc":[{"id":"1.232019003","rc":[{"trd":[[1.62,0.78]],"batb":[[0,1.62,2.26]],"ltp":1.62,"tv":27.44,"id":72857116}],"tv":61.02}]}
{"op":"mcm","clk":"11921707889","pt":1724158829440,"mc":[{"id":"1.232019003","rc":[{"trd":[[1.56,6.97],[1.57,1.88],[1.61,3.08],[1.63,4.8],[1.68,1.9],[1.71,2.06],[1.76,2],[1.9,2.63],[1.95,2],[1.96,0.94]],"batb":[[2,1.5,10.89]],"batl":[[0,5,1.54],[1,9,1.54]],"ltp":2.2,"tv":33.56,"id":67083366},{"trd":[[1.61,3.08],[1.68,0.95],[1.86,0.77],[1.88,3.93],[2.1,4.13]],"batl":[[0,2.36,2.74],[1,5,1.54],[2,9,1.54]],"ltp":1.62,"tv":27.42,"id":72857116}],"tv":60.98}]}
{"op":"mcm","clk":"11921708401","pt":1724158841118,"mc":[{"id":"1.232019003","rc":[{"batb":[[0,1.77,10],[1,1.76,4],[2,1.75,3.41]],"batl":[[0,4,1.71],[1,6,1.54],[2,9,0.77]],"ltp":2.2,"tv":33.56,"id":67083366}]}]}
{"op":"mcm","clk":"11921708491","pt":1724158843334,"mc":[{"id":"1.232019003","rc":[{"batb":[[1,1.75,3.41],[2,1.63,1.01]],"ltp":2.2,"tv":33.56,"id":67083366}]}]}
{"op":"mcm","clk":"11921708522","pt":1724158844516,"mc":[{"id":"1.232019003","rc":[{"batb":[[0,1.75,3.41],[1,1.63,1.01],[2,1.5,10.89]],"ltp":2.2,"tv":33.56,"id":67083366}]}]}
{"op":"mcm","clk":"11921708663","pt":1724158848344,"mc":[{"id":"1.232019003","rc":[{"batb":[[0,1.77,10],[1,1.76,4],[2,1.75,3.41]],"ltp":2.2,"tv":33.56,"id":67083366}]}]}
{"op":"mcm","clk":"11921708742","pt":1724158850451,"mc":[{"id":"1.232019003","rc":[{"batb":[[1,1.75,3.41],[2,1.63,1.01]],"ltp":2.2,"tv":33.56,"id":67083366}]}]}
{"op":"mcm","clk":"11921708797","pt":1724158851744,"mc":[{"id":"1.232019003","rc":[{"batb":[[0,1.75,3.41],[1,1.63,1.01],[2,1.5,10.89]],"ltp":2.2,"tv":33.56,"id":67083366}]}]}
{"op":"mcm","clk":"11921708839","pt":1724158852929,"mc":[{"id":"1.232019003","rc":[{"batb":[[0,1.76,4],[1,1.75,3.41],[2,1.63,1.01]],"ltp":2.2,"tv":33.56,"id":67083366}]}]}
{"op":"mcm","clk":"11921708896","pt":1724158854320,"mc":[{"id":"1.232019003","rc":[{"batb":[[0,1.77,10],[1,1.76,4],[2,1.75,3.41]],"ltp":2.2,"tv":33.56,"id":67083366}]}]}
{"op":"mcm","clk":"11921708949","pt":1724158855658,"mc":[{"id":"1.232019003","rc":[{"batb":[[1,1.75,3.41],[2,1.63,1.01]],"ltp":2.2,"tv":33.56,"id":67083366}]}]}
{"op":"mcm","clk":"11921709038","pt":1724158857824,"mc":[{"id":"1.232019003","rc":[{"batb":[[0,1.76,4]],"ltp":2.2,"tv":33.56,"id":67083366}]}]}
{"op":"mcm","clk":"11921709125","pt":1724158860238,"mc":[{"id":"1.232019003","rc":[{"batb":[[0,1.75,3.41],[1,1.63,1.01],[2,1.5,10.89]],"ltp":2.2,"tv":33.56,"id":67083366}]}]}
{"op":"mcm","clk":"11921709364","pt":1724158867429,"mc":[{"id":"1.232019003","rc":[{"batb":[[0,1.76,4],[1,1.75,3.41],[2,1.63,1.01]],"ltp":2.2,"tv":33.56,"id":67083366}]}]}
{"op":"mcm","clk":"11921709402","pt":1724158868252,"mc":[{"id":"1.232019003","rc":[{"batb":[[0,1.77,10],[1,1.76,4],[2,1.75,3.41]],"ltp":2.2,"tv":33.56,"id":67083366}]}]}
{"op":"mcm","clk":"11921709472","pt":1724158870255,"mc":[{"id":"1.232019003","rc":[{"batb":[[1,1.75,3.41],[2,1.63,1.01]],"ltp":2.2,"tv":33.56,"id":67083366}]}]}
{"op":"mcm","clk":"11921709519","pt":1724158871647,"mc":[{"id":"1.232019003","rc":[{"batb":[[0,1.75,3.41],[1,1.63,1.01],[2,1.5,10.89]],"ltp":2.2,"tv":33.56,"id":67083366}]}]}
{"op":"mcm","clk":"11921709602","pt":1724158873957,"mc":[{"id":"1.232019003","rc":[{"batb":[[0,1.77,10],[1,1.76,4],[2,1.75,3.41]],"ltp":2.2,"tv":33.56,"id":67083366}]}]}
{"op":"mcm","clk":"11921709698","pt":1724158876374,"mc":[{"id":"1.232019003","rc":[{"batb":[[1,1.75,3.41],[2,1.63,1.01]],"ltp":2.2,"tv":33.56,"id":67083366}]}]}
{"op":"mcm","clk":"11921709742","pt":1724158877659,"mc":[{"id":"1.232019003","rc":[{"batb":[[0,1.75,3.41],[1,1.63,1.01],[2,1.5,10.89]],"ltp":2.2,"tv":33.56,"id":67083366}]}]}
{"op":"mcm","clk":"11921709801","pt":1724158878842,"mc":[{"id":"1.232019003","rc":[{"batb":[[0,1.76,4],[1,1.75,3.41],[2,1.63,1.01]],"ltp":2.2,"tv":33.56,"id":67083366}]}]}
{"op":"mcm","clk":"11921709890","pt":1724158881363,"mc":[{"id":"1.232019003","rc":[{"batb":[[0,1.75,3.41],[1,1.63,1.01],[2,1.5,10.89]],"ltp":2.2,"tv":33.56,"id":67083366}]}]}
{"op":"mcm","clk":"11921709986","pt":1724158884076,"mc":[{"id":"1.232019003","rc":[{"batb":[[0,1.77,10],[1,1.76,4],[2,1.75,3.41]],"ltp":2.2,"tv":33.56,"id":67083366}]}]}
{"op":"mcm","clk":"11921710067","pt":1724158886083,"mc":[{"id":"1.232019003","rc":[{"batb":[[1,1.75,3.41],[2,1.63,1.01]],"ltp":2.2,"tv":33.56,"id":67083366}]}]}
{"op":"mcm","clk":"11921710144","pt":1724158887781,"mc":[{"id":"1.232019003","rc":[{"batb":[[0,1.75,3.41],[1,1.63,1.01],[2,1.5,10.89]],"ltp":2.2,"tv":33.56,"id":67083366}]}]}
{"op":"mcm","clk":"11921710238","pt":1724158890446,"mc":[{"id":"1.232019003","rc":[{"batb":[[0,1.76,4],[1,1.75,3.41],[2,1.63,1.01]],"ltp":2.2,"tv":33.56,"id":67083366}]}]}
{"op":"mcm","clk":"11921710246","pt":1724158890754,"mc":[{"id":"1.232019003","rc":[{"batb":[[0,1.77,10],[1,1.76,4],[2,1.75,3.41]],"ltp":2.2,"tv":33.56,"id":67083366}]}]}
{"op":"mcm","clk":"11921710328","pt":1724158893171,"mc":[{"id":"1.232019003","rc":[{"batb":[[1,1.75,3.41],[2,1.63,1.01]],"ltp":2.2,"tv":33.56,"id":67083366}]}]}
{"op":"mcm","clk":"11921710369","pt":1724158894347,"mc":[{"id":"1.232019003","rc":[{"batb":[[0,1.75,3.41],[1,1.63,1.01],[2,1.5,10.89]],"ltp":2.2,"tv":33.56,"id":67083366}]}]}
{"op":"mcm","clk":"11921710558","pt":1724158899478,"mc":[{"id":"1.232019003","rc":[{"batb":[[0,1.77,10],[1,1.76,4],[2,1.75,3.41]],"ltp":2.2,"tv":33.56,"id":67083366}]}]}
{"op":"mcm","clk":"11921710627","pt":1724158901686,"mc":[{"id":"1.232019003","rc":[{"batb":[[1,1.75,3.41],[2,1.63,1.01]],"ltp":2.2,"tv":33.56,"id":67083366}]}]}
{"op":"mcm","clk":"11921710697","pt":1724158903590,"mc":[{"id":"1.232019003","rc":[{"batb":[[0,1.75,3.41],[1,1.63,1.01],[2,1.5,10.89]],"ltp":2.2,"tv":33.56,"id":67083366}]}]}
{"op":"mcm","clk":"11921710707","pt":1724158903898,"mc":[{"id":"1.232019003","rc":[{"batb":[[0,1.76,4],[1,1.75,3.41],[2,1.63,1.01]],"ltp":2.2,"tv":33.56,"id":67083366}]}]}
{"op":"mcm","clk":"11921710778","pt":1724158906266,"mc":[{"id":"1.232019003","rc":[{"batb":[[0,1.77,10]],"ltp":2.2,"tv":33.56,"id":67083366}]}]}
{"op":"mcm","clk":"11921710909","pt":1724158910006,"mc":[{"id":"1.232019003","rc":[{"batb":[[0,1.76,4]],"ltp":2.2,"tv":33.56,"id":67083366}]}]}
{"op":"mcm","clk":"11921710952","pt":1724158910883,"mc":[{"id":"1.232019003","rc":[{"batl":[[0,1.69,1.15],[1,2.36,2.74],[2,5,1.54]],"ltp":1.62,"tv":27.42,"id":72857116}]}]}
{"op":"mcm","clk":"11921711013","pt":1724158912173,"mc":[{"id":"1.232019003","rc":[{"batb":[[0,1.75,3.41],[1,1.63,1.01],[2,1.5,10.89]],"ltp":2.2,"tv":33.56,"id":67083366}]}]}
{"op":"mcm","clk":"11921711068","pt":1724158913508,"mc":[{"id":"1.232019003","rc":[{"batl":[[0,2.36,2.74],[1,5,1.54],[2,9,1.54]],"ltp":1.62,"tv":27.42,"id":72857116}]}]}
{"op":"mcm","clk":"11921711160","pt":1724158915258,"mc":[{"id":"1.232019003","rc":[{"batb":[[0,1.77,10],[1,1.76,4],[2,1.75,3.41]],"ltp":2.2,"tv":33.56,"id":67083366}]}]}
{"op":"mcm","clk":"11921711241","pt":1724158917307,"mc":[{"id":"1.232019003","rc":[{"batb":[[1,1.75,3.41],[2,1.63,1.01]],"ltp":2.2,"tv":33.56,"id":67083366}]}]}
{"op":"mcm","clk":"11921711289","pt":1724158918590,"mc":[{"id":"1.232019003","rc":[{"batb":[[0,1.75,3.41],[1,1.63,1.01],[2,1.5,10.89]],"ltp":2.2,"tv":33.56,"id":67083366}]}]}
{"op":"mcm","clk":"11921711355","pt":1724158919979,"mc":[{"id":"1.232019003","rc":[{"batb":[[0,1.76,4],[1,1.75,3.41],[2,1.63,1.01]],"ltp":2.2,"tv":33.56,"id":67083366}]}]}
{"op":"mcm","clk":"11921711426","pt":1724158921575,"mc":[{"id":"1.232019003","rc":[{"batb":[[0,1.77,10],[1,1.76,4],[2,1.75,3.41]],"ltp":2.2,"tv":33.56,"id":67083366}]}]}
{"op":"mcm","clk":"11921711453","pt":1724158922192,"mc":[{"id":"1.232019003","rc":[{"batb":[[1,1.75,3.41],[2,1.63,1.01]],"ltp":2.2,"tv":33.56,"id":67083366}]}]}
{"op":"mcm","clk":"11921711591","pt":1724158925273,"mc":[{"id":"1.232019003","rc":[{"batb":[[0,1.76,4]],"ltp":2.2,"tv":33.56,"id":67083366}]}]}
{"op":"mcm","clk":"11921711704","pt":1724158927581,"mc":[{"id":"1.232019003","rc":[{"batb":[[0,1.77,10]],"ltp":2.2,"tv":33.56,"id":67083366},{"batl":[[0,1.69,1.15],[1,2.36,2.74],[2,5,1.54]],"ltp":1.62,"tv":27.42,"id":72857116}]}]}
{"op":"mcm","clk":"11921711840","pt":1724158930582,"mc":[{"id":"1.232019003","rc":[{"batb":[[0,1.78,4]],"ltp":2.2,"tv":33.56,"id":67083366},{"batl":[[0,2.36,2.74],[1,5,1.54],[2,9,1.54]],"ltp":1.62,"tv":27.42,"id":72857116}]}]}
{"op":"mcm","clk":"11921711907","pt":1724158932026,"mc":[{"id":"1.232019003","rc":[{"batb":[[0,1.75,3.41],[1,1.63,1.01],[2,1.5,10.89]],"ltp":2.2,"tv":33.56,"id":67083366}]}]}
{"op":"mcm","clk":"11921712025","pt":1724158934396,"mc":[{"id":"1.232019003","rc":[{"batb":[[0,1.76,4],[1,1.75,3.41],[2,1.63,1.01]],"ltp":2.2,"tv":33.56,"id":67083366}]}]}
{"op":"mcm","clk":"11921712067","pt":1724158935214,"mc":[{"id":"1.232019003","rc":[{"batb":[[0,1.77,10],[1,1.76,4],[2,1.75,3.41]],"ltp":2.2,"tv":33.56,"id":67083366}]}]}
{"op":"mcm","clk":"11921712187","pt":1724158937283,"mc":[{"id":"1.232019003","rc":[{"batb":[[1,1.75,3.41],[2,1.63,1.01]],"ltp":2.2,"tv":33.56,"id":67083366}]}]}
{"op":"mcm","clk":"11921712266","pt":1724158938716,"mc":[{"id":"1.232019003","rc":[{"batb":[[0,1.75,3.41],[1,1.63,1.01],[2,1.5,10.89]],"ltp":2.2,"tv":33.56,"id":67083366}]}]}
{"op":"mcm","clk":"11921712523","pt":1724158943508,"mc":[{"id":"1.232019003","rc":[{"batb":[[0,1.77,10],[1,1.76,4],[2,1.75,3.41]],"ltp":2.2,"tv":33.56,"id":67083366}]}]}
{"op":"mcm","clk":"11921712597","pt":1724158945209,"mc":[{"id":"1.232019003","rc":[{"batb":[[1,1.75,3.41],[2,1.63,1.01]],"ltp":2.2,"tv":33.56,"id":67083366}]}]}
{"op":"mcm","clk":"11921712719","pt":1724158947015,"mc":[{"id":"1.232019003","rc":[{"batb":[[0,1.75,3.41],[1,1.63,1.01],[2,1.5,10.89]],"ltp":2.2,"tv":33.56,"id":67083366}]}]}
{"op":"mcm","clk":"11921712957","pt":1724158951608,"mc":[{"id":"1.232019003","rc":[{"batb":[[0,1.77,10],[1,1.76,4],[2,1.75,3.41]],"ltp":2.2,"tv":33.56,"id":67083366}]}]}
{"op":"mcm","clk":"11921713053","pt":1724158953618,"mc":[{"id":"1.232019003","rc":[{"batb":[[1,1.75,3.41],[2,1.63,1.01]],"ltp":2.2,"tv":33.56,"id":67083366}]}]}
{"op":"mcm","clk":"11921713072","pt":1724158954029,"mc":[{"id":"1.232019003","rc":[{"batl":[[0,1.87,1.15],[1,4,1.71],[2,6,1.54]],"ltp":2.2,"tv":33.56,"id":67083366}]}]}
{"op":"mcm","clk":"11921713144","pt":1724158955317,"mc":[{"id":"1.232019003","rc":[{"batb":[[0,1.75,3.41],[1,1.63,1.01],[2,1.5,10.89]],"ltp":2.2,"tv":33.56,"id":67083366}]}]}
{"op":"mcm","clk":"11921713218","pt":1724158956603,"mc":[{"id":"1.232019003","rc":[{"batb":[[0,1.76,4],[1,1.75,3.41],[2,1.63,1.01]],"batl":[[0,4,1.71],[1,6,1.54],[2,9,0.77]],"ltp":2.2,"tv":33.56,"id":67083366}]}]}
{"op":"mcm","clk":"11921713279","pt":1724158957797,"mc":[{"id":"1.232019003","rc":[{"batb":[[0,1.77,10],[1,1.76,4],[2,1.75,3.41]],"ltp":2.2,"tv":33.56,"id":67083366}]}]}
{"op":"mcm","clk":"11921713358","pt":1724158959002,"mc":[{"id":"1.232019003","rc":[{"batb":[[1,1.75,3.41],[2,1.63,1.01]],"ltp":2.2,"tv":33.56,"id":67083366}]}]}
{"op":"mcm","clk":"11921713502","pt":1724158961617,"mc":[{"id":"1.232019003","rc":[{"batb":[[0,1.75,3.41],[1,1.63,1.01],[2,1.5,10.89]],"ltp":2.2,"tv":33.56,"id":67083366}]}]}
{"op":"mcm","clk":"11921713506","pt":1724158961719,"mc":[{"id":"1.232019003","rc":[{"batb":[[0,1.76,4],[1,1.75,3.41],[2,1.63,1.01]],"ltp":2.2,"tv":33.56,"id":67083366}]}]}
{"op":"mcm","clk":"11921713650","pt":1724158964445,"mc":[{"id":"1.232019003","rc":[{"batb":[[0,1.77,10]],"ltp":2.2,"tv":33.56,"id":67083366}]}]}
{"op":"mcm","clk":"11921713839","pt":1724158968041,"mc":[{"id":"1.232019003","rc":[{"batb":[[0,1.78,4]],"ltp":2.2,"tv":33.56,"id":67083366}]}]}
{"op":"mcm","clk":"11921713968","pt":1724158970413,"mc":[{"id":"1.232019003","rc":[{"batb":[[0,1.75,3.41],[1,1.63,1.01],[2,1.5,10.89]],"ltp":2.2,"tv":33.56,"id":67083366}]}]}
{"op":"mcm","clk":"11921714077","pt":1724158972624,"mc":[{"id":"1.232019003","rc":[{"batl":[[0,1.69,1.15],[1,2.36,2.74],[2,5,1.54]],"ltp":1.62,"tv":27.42,"id":72857116}]}]}
{"op":"mcm","clk":"11921714097","pt":1724158972933,"mc":[{"id":"1.232019003","rc":[{"batb":[[0,1.77,10],[1,1.76,4],[2,1.75,3.41]],"ltp":2.2,"tv":33.56,"id":67083366}]}]}
{"op":"mcm","clk":"11921714205","pt":1724158975145,"mc":[{"id":"1.232019003","rc":[{"batb":[[1,1.75,3.41],[2,1.63,1.01]],"ltp":2.2,"tv":33.56,"id":67083366},{"batl":[[0,2.36,2.74],[1,5,1.54],[2,9,1.54]],"ltp":1.62,"tv":27.42,"id":72857116}]}]}
{"op":"mcm","clk":"11921714258","pt":1724158976227,"mc":[{"id":"1.232019003","rc":[{"batb":[[0,1.75,3.41],[1,1.63,1.01],[2,1.5,10.89]],"ltp":2.2,"tv":33.56,"id":67083366}]}]}
{"op":"mcm","clk":"11921714391","pt":1724158979625,"mc":[{"id":"1.232019003","rc":[{"batb":[[0,1.77,10],[1,1.76,4],[2,1.75,3.41]],"ltp":2.2,"tv":33.56,"id":67083366}]}]}
{"op":"mcm","clk":"11921714519","pt":1724158981723,"mc":[{"id":"1.232019003","rc":[{"batb":[[1,1.75,3.41],[2,1.63,1.01]],"ltp":2.2,"tv":33.56,"id":67083366}]}]}
{"op":"mcm","clk":"11921714603","pt":1724158982955,"mc":[{"id":"1.232019003","rc":[{"batb":[[0,1.75,3.41],[1,1.63,1.01],[2,1.5,10.89]],"ltp":2.2,"tv":33.56,"id":67083366}]}]}
{"op":"mcm","clk":"11921714706","pt":1724158984759,"mc":[{"id":"1.232019003","rc":[{"batb":[[0,1.76,4],[1,1.75,3.41],[2,1.63,1.01]],"ltp":2.2,"tv":33.56,"id":67083366}]}]}
{"op":"mcm","clk":"11921714853","pt":1724158987233,"mc":[{"id":"1.232019003","rc":[{"batb":[[0,1.75,3.41],[1,1.63,1.01],[2,1.5,10.89]],"ltp":2.2,"tv":33.56,"id":67083366}]}]}
{"op":"mcm","clk":"11921715064","pt":1724158991566,"mc":[{"id":"1.232019003","rc":[{"batb":[[0,1.76,4],[1,1.75,3.41],[2,1.63,1.01]],"ltp":2.2,"tv":33.56,"id":67083366}]}]}
{"op":"mcm","clk":"11921715101","pt":1724158992442,"mc":[{"id":"1.232019003","rc":[{"batb":[[0,1.77,10],[1,1.76,4],[2,1.75,3.41]],"ltp":2.2,"tv":33.56,"id":67083366}]}]}
{"op":"mcm","clk":"11921715190","pt":1724158994341,"mc":[{"id":"1.232019003","rc":[{"batb":[[1,1.75,3.41],[2,1.63,1.01]],"ltp":2.2,"tv":33.56,"id":67083366}]}]}
{"op":"mcm","clk":"11921715288","pt":1724158996142,"mc":[{"id":"1.232019003","rc":[{"batb":[[0,1.75,3.41],[1,1.63,1.01],[2,1.5,10.89]],"ltp":2.2,"tv":33.56,"id":67083366}]}]}
{"op":"mcm","clk":"11921715357","pt":1724158997439,"mc":[{"id":"1.232019003","rc":[{"batb":[[0,1.76,4],[1,1.75,3.41],[2,1.63,1.01]],"ltp":2.2,"tv":33.56,"id":67083366}]}]}
{"op":"mcm","clk":"11921715415","pt":1724158998735,"mc":[{"id":"1.232019003","rc":[{"batb":[[0,1.77,10],[1,1.76,4],[2,1.75,3.41]],"ltp":2.2,"tv":33.56,"id":67083366}]}]}
{"op":"mcm","clk":"11921715462","pt":1724158999866,"mc":[{"id":"1.232019003","rc":[{"batb":[[1,1.75,3.41],[2,1.63,1.01]],"ltp":2.2,"tv":33.56,"id":67083366}]}]}
{"op":"mcm","clk":"11921715582","pt":1724159002156,"mc":[{"id":"1.232019003","rc":[{"batb":[[0,1.76,4]],"ltp":2.2,"tv":33.56,"id":67083366}]}]}
{"op":"mcm","clk":"11921715725","pt":1724159004453,"mc":[{"id":"1.232019003","rc":[{"batb":[[0,1.75,3.41],[1,1.63,1.01],[2,1.5,10.89]],"ltp":2.2,"tv":33.56,"id":67083366}]}]}
{"op":"mcm","clk":"11921715875","pt":1724159007447,"mc":[{"id":"1.232019003","rc":[{"batb":[[0,1.76,4],[1,1.75,3.41],[2,1.63,1.01]],"ltp":2.2,"tv":33.56,"id":67083366}]}]}
{"op":"mcm","clk":"11921715884","pt":1724159007652,"mc":[{"id":"1.232019003","rc":[{"batb":[[0,1.77,10],[1,1.76,4],[2,1.75,3.41]],"ltp":2.2,"tv":33.56,"id":67083366}]}]}
{"op":"mcm","clk":"11921716035","pt":1724159010172,"mc":[{"id":"1.232019003","rc":[{"batb":[[1,1.75,3.41],[2,1.63,1.01]],"batl":[[0,1.87,1.15],[1,4,1.71],[2,6,1.54]],"ltp":2.2,"tv":33.56,"id":67083366}]}]}
{"op":"mcm","clk":"11921716111","pt":1724159011356,"mc":[{"id":"1.232019003","rc":[{"batb":[[0,1.75,3.41],[1,1.63,1.01],[2,1.5,10.89]],"ltp":2.2,"tv":33.56,"id":67083366}]}]}
{"op":"mcm","clk":"11921716182","pt":1724159012492,"mc":[{"id":"1.232019003","rc":[{"batl":[[0,4,1.71],[1,6,1.54],[2,9,0.77]],"ltp":2.2,"tv":33.56,"id":67083366}]}]}
{"op":"mcm","clk":"11921716193","pt":1724159012653,"mc":[{"id":"1.232019003","rc":[{"batb":[[0,1.76,4],[1,1.75,3.41],[2,1.63,1.01]],"ltp":2.2,"tv":33.56,"id":67083366}]}]}
{"op":"mcm","clk":"11921716312","pt":1724159014977,"mc":[{"id":"1.232019003","rc":[{"batb":[[0,1.75,3.41],[1,1.63,1.01],[2,1.5,10.89]],"ltp":2.2,"tv":33.56,"id":67083366}]}]}
{"op":"mcm","clk":"11921716518","pt":1724159019459,"mc":[{"id":"1.232019003","rc":[{"batb":[[0,1.76,4],[1,1.75,3.41],[2,1.63,1.01]],"ltp":2.2,"tv":33.56,"id":67083366}]}]}
{"op":"mcm","clk":"11921716543","pt":1724159020076,"mc":[{"id":"1.232019003","rc":[{"batb":[[0,1.77,10],[1,1.76,4],[2,1.75,3.41]],"ltp":2.2,"tv":33.56,"id":67083366}]}]}
{"op":"mcm","clk":"11921716614","pt":1724159021368,"mc":[{"id":"1.232019003","rc":[{"batb":[[0,1.77,10.98]],"ltp":2.2,"tv":33.56,"id":67083366}]}]}
{"op":"mcm","clk":"11921716643","pt":1724159021886,"mc":[{"id":"1.232019003","rc":[{"batb":[[1,1.75,3.41],[2,1.63,1.01]],"ltp":2.2,"tv":33.56,"id":67083366}]}]}
{"op":"mcm","clk":"11921716768","pt":1724159024202,"mc":[{"id":"1.232019003","rc":[{"batb":[[0,1.76,4.98]],"ltp":2.2,"tv":33.56,"id":67083366}]}]}
{"op":"mcm","clk":"11921716884","pt":1724159026588,"mc":[{"id":"1.232019003","rc":[{"batb":[[0,1.75,4.39],[1,1.63,1.01],[2,1.5,10.89]],"ltp":2.2,"tv":33.56,"id":67083366}]}]}
{"op":"mcm","clk":"11921716890","pt":1724159026693,"mc":[{"id":"1.232019003","rc":[{"batb":[[0,1.76,10.98],[1,1.75,3.41],[2,1.63,1.01]],"ltp":2.2,"tv":33.56,"id":67083366}]}]}
{"op":"mcm","clk":"11921717043","pt":1724159029596,"mc":[{"id":"1.232019003","rc":[{"batb":[[0,1.77,4.98],[1,1.76,10],[2,1.75,3.41]],"ltp":2.2,"tv":33.56,"id":67083366}]}]}
{"op":"mcm","clk":"11921717080","pt":1724159030209,"mc":[{"id":"1.232019003","rc":[{"batb":[[1,1.75,3.41],[2,1.63,1.01]],"ltp":2.2,"tv":33.56,"id":67083366},{"batb":[[0,1.62,3.24]],"ltp":1.62,"tv":27.42,"id":72857116}]}]}
{"op":"mcm","clk":"11921717111","pt":1724159030879,"mc":[{"id":"1.232019003","rc":[{"trd":[[1.7,1.96]],"batb":[[0,1.62,2.26]],"batl":[[0,2.2,1.11],[1,2.36,1.81],[2,5,1.54]],"ltp":1.7,"tv":29.38,"id":72857116}],"tv":62.95}]}
{"op":"mcm","clk":"11921717168","pt":1724159032174,"mc":[{"id":"1.232019003","rc":[{"batb":[[0,1.76,10.98]],"ltp":2.2,"tv":33.56,"id":67083366}]}]}
{"op":"mcm","clk":"11921717302","pt":1724159034874,"mc":[{"id":"1.232019003","rc":[{"batb":[[0,1.77,4.98],[1,1.76,10],[2,1.75,3.41]],"ltp":2.2,"tv":33.56,"id":67083366},{"batl":[[0,2.36,2.74],[1,5,1.54],[2,9,1.54]],"ltp":1.7,"tv":29.38,"id":72857116}]}]}
{"op":"mcm","clk":"11921717331","pt":1724159035699,"mc":[{"id":"1.232019003","rc":[{"batb":[[1,1.75,3.41],[2,1.63,1.01]],"ltp":2.2,"tv":33.56,"id":67083366}]}]}
{"op":"mcm","clk":"11921717373","pt":1724159037086,"mc":[{"id":"1.232019003","rc":[{"batb":[[0,1.75,4.39],[1,1.63,1.01],[2,1.5,10.89]],"ltp":2.2,"tv":33.56,"id":67083366}]}]}
{"op":"mcm","clk":"11921717532","pt":1724159040395,"mc":[{"id":"1.232019003","rc":[{"batb":[[0,1.76,14.98],[1,1.75,3.41],[2,1.63,1.01]],"ltp":2.2,"tv":33.56,"id":67083366},{"batb":[[0,1.62,3.24]],"ltp":1.7,"tv":29.38,"id":72857116}]}]}
{"op":"mcm","clk":"11921717636","pt":1724159042729,"mc":[{"id":"1.232019003","rc":[{"batb":[[0,1.76,10.98]],"ltp":2.2,"tv":33.56,"id":67083366}]}]}
{"op":"mcm","clk":"11921717693","pt":1724159043810,"mc":[{"id":"1.232019003","rc":[{"batb":[[0,1.75,4.39],[1,1.63,1.01],[2,1.5,10.89]],"ltp":2.2,"tv":33.56,"id":67083366}]}]}
{"op":"mcm","clk":"11921717845","pt":1724159047322,"mc":[{"id":"1.232019003","rc":[{"batb":[[0,1.89,10.98],[1,1.88,4],[2,1.75,4.39]],"ltp":2.2,"tv":33.56,"id":67083366}]}]}
{"op":"mcm","clk":"11921717950","pt":1724159049430,"mc":[{"id":"1.232019003","rc":[{"batb":[[1,1.75,4.39],[2,1.63,1.01]],"ltp":2.2,"tv":33.56,"id":67083366},{"batl":[[0,1.71,1.15],[1,2.36,2.74],[2,5,1.54]],"ltp":1.7,"tv":29.38,"id":72857116}]}]}
{"op":"mcm","clk":"11921718022","pt":1724159050726,"mc":[{"id":"1.232019003","rc":[{"batb":[[0,1.87,1.96],[1,1.75,3.41]],"ltp":2.2,"tv":33.56,"id":67083366}]}]}
{"op":"mcm","clk":"11921718071","pt":1724159051920,"mc":[{"id":"1.232019003","rc":[{"batb":[[0,1.88,4.98],[1,1.75,4.39]],"ltp":2.2,"tv":33.56,"id":67083366},{"batl":[[0,2.36,2.74],[1,5,1.54],[2,9,1.54]],"ltp":1.7,"tv":29.38,"id":72857116}]}]}
{"op":"mcm","clk":"11921718128","pt":1724159053308,"mc":[{"id":"1.232019003","rc":[{"batb":[[0,1.89,10.98],[1,1.88,4],[2,1.75,4.39]],"ltp":2.2,"tv":33.56,"id":67083366}]}]}
{"op":"mcm","clk":"11921718161","pt":1724159054235,"mc":[{"id":"1.232019003","rc":[{"batb":[[1,1.75,4.39],[2,1.63,1.01]],"ltp":2.2,"tv":33.56,"id":67083366},{"batb":[[0,1.7,1.96],[1,1.62,2.26],[2,1.6,2.56]],"ltp":1.7,"tv":29.38,"id":72857116}]}]}
{"op":"mcm","clk":"11921718284","pt":1724159056812,"mc":[{"id":"1.232019003","rc":[{"batb":[[0,1.88,4.98]],"ltp":2.2,"tv":33.56,"id":67083366}]}]}
{"op":"mcm","clk":"11921718315","pt":1724159057837,"mc":[{"id":"1.232019003","rc":[{"batb":[[0,1.62,3.24],[1,1.6,2.56],[2,1.57,2.56]],"ltp":1.7,"tv":29.38,"id":72857116}]}]}
{"op":"mcm","clk":"11921718373","pt":1724159059132,"mc":[{"id":"1.232019003","rc":[{"batb":[[0,1.87,1.96],[1,1.75,3.41]],"ltp":2.2,"tv":33.56,"id":67083366}]}]}
{"op":"mcm","clk":"11921718571","pt":1724159063122,"mc":[{"id":"1.232019003","rc":[{"batb":[[0,1.89,10.98],[1,1.88,4],[2,1.75,4.39]],"ltp":2.2,"tv":33.56,"id":67083366}]}]}
{"op":"mcm","clk":"11921718654","pt":1724159065128,"mc":[{"id":"1.232019003","rc":[{"batb":[[1,1.75,4.39],[2,1.63,1.01]],"ltp":2.2,"tv":33.56,"id":67083366}]}]}
{"op":"mcm","clk":"11921718735","pt":1724159066629,"mc":[{"id":"1.232019003","rc":[{"batb":[[0,1.87,1.96],[1,1.75,3.41]],"ltp":2.2,"tv":33.56,"id":67083366}]}]}
{"op":"mcm","clk":"11921718794","pt":1724159067812,"mc":[{"id":"1.232019003","rc":[{"batb":[[0,1.88,4.98],[1,1.75,4.39]],"ltp":2.2,"tv":33.56,"id":67083366}]}]}
{"op":"mcm","clk":"11921718902","pt":1724159070230,"mc":[{"id":"1.232019003","rc":[{"batb":[[0,1.89,10.98],[1,1.88,4],[2,1.75,4.39]],"ltp":2.2,"tv":33.56,"id":67083366}]}]}
{"op":"mcm","clk":"11921718918","pt":1724159070643,"mc":[{"id":"1.232019003","rc":[{"batb":[[1,1.75,4.39],[2,1.63,1.01]],"ltp":2.2,"tv":33.56,"id":67083366}]}]}
{"op":"mcm","clk":"11921719072","pt":1724159073842,"mc":[{"id":"1.232019003","rc":[{"batb":[[0,1.9,4.98]],"ltp":2.2,"tv":33.56,"id":67083366}]}]}
{"op":"mcm","clk":"11921719168","pt":1724159076224,"mc":[{"id":"1.232019003","rc":[{"batb":[[0,1.87,1.96],[1,1.75,3.41]],"ltp":2.2,"tv":33.56,"id":67083366}]}]}
{"op":"mcm","clk":"11921719302","pt":1724159079463,"mc":[{"id":"1.232019003","rc":[{"batb":[[0,1.89,10.98],[1,1.88,4],[2,1.75,4.39]],"ltp":2.2,"tv":33.56,"id":67083366}]}]}
{"op":"mcm","clk":"11921719397","pt":1724159081636,"mc":[{"id":"1.232019003","rc":[{"batb":[[1,1.75,4.39],[2,1.63,1.01]],"ltp":2.2,"tv":33.56,"id":67083366}]}]}
{"op":"mcm","clk":"11921719445","pt":1724159082761,"mc":[{"id":"1.232019003","rc":[{"batb":[[0,1.87,1.96],[1,1.75,3.41]],"ltp":2.2,"tv":33.56,"id":67083366}]}]}
{"op":"mcm","clk":"11921719502","pt":1724159084465,"mc":[{"id":"1.232019003","rc":[{"batb":[[0,1.88,4.98],[1,1.75,4.39]],"ltp":2.2,"tv":33.56,"id":67083366}]}]}
{"op":"mcm","clk":"11921719533","pt":1724159085146,"mc":[{"id":"1.232019003","rc":[{"batb":[[0,1.89,10.98],[1,1.88,4],[2,1.75,4.39]],"ltp":2.2,"tv":33.56,"id":67083366}]}]}
{"op":"mcm","clk":"11921719646","pt":1724159087354,"mc":[{"id":"1.232019003","rc":[{"batb":[[1,1.75,4.39],[2,1.63,1.01]],"ltp":2.2,"tv":33.56,"id":67083366}]}]}
{"op":"mcm","clk":"11921719699","pt":1724159088746,"mc":[{"id":"1.232019003","rc":[{"batb":[[0,1.87,1.96],[1,1.75,3.41]],"ltp":2.2,"tv":33.56,"id":67083366}]}]}
{"op":"mcm","clk":"11921719852","pt":1724159091166,"mc":[{"id":"1.232019003","rc":[{"batb":[[0,1.88,4.98],[1,1.75,4.39]],"ltp":2.2,"tv":33.56,"id":67083366}]}]}
{"op":"mcm","clk":"11921719893","pt":1724159092152,"mc":[{"id":"1.232019003","rc":[{"batb":[[0,1.89,10.98],[1,1.88,4],[2,1.75,4.39]],"ltp":2.2,"tv":33.56,"id":67083366}]}]}
{"op":"mcm","clk":"11921719991","pt":1724159094059,"mc":[{"id":"1.232019003","rc":[{"batb":[[1,1.75,4.39],[2,1.63,1.01]],"ltp":2.2,"tv":33.56,"id":67083366}]}]}
{"op":"mcm","clk":"11921720086","pt":1724159096376,"mc":[{"id":"1.232019003","rc":[{"batb":[[0,1.87,1.96],[1,1.75,3.41]],"ltp":2.2,"tv":33.56,"id":67083366}]}]}
{"op":"mcm","clk":"11921720106","pt":1724159096848,"mc":[{"id":"1.232019003","rc":[{"batb":[[0,1.88,4.98],[1,1.75,4.39]],"batl":[[0,1.92,1.15],[1,4,1.71],[2,6,1.54]],"ltp":2.2,"tv":33.56,"id":67083366}]}]}
{"op":"mcm","clk":"11921720234","pt":1724159099060,"mc":[{"id":"1.232019003","rc":[{"batb":[[0,1.89,10.98]],"batl":[[0,4,1.71],[1,6,1.54],[2,9,0.77]],"ltp":2.2,"tv":33.56,"id":67083366}]}]}
{"op":"mcm","clk":"11921720444","pt":1724159102571,"mc":[{"id":"1.232019003","rc":[{"batb":[[0,1.87,1.96],[1,1.75,3.41]],"ltp":2.2,"tv":33.56,"id":67083366}]}]}
{"op":"mcm","clk":"11921720455","pt":1724159102772,"mc":[{"id":"1.232019003","rc":[{"batb":[[0,1.88,4.98],[1,1.75,4.39]],"ltp":2.2,"tv":33.56,"id":67083366}]}]}
{"op":"mcm","clk":"11921720582","pt":1724159105373,"mc":[{"id":"1.232019003","rc":[{"batb":[[0,1.87,1.96],[1,1.75,3.41]],"ltp":2.2,"tv":33.56,"id":67083366}]}]}
{"op":"mcm","clk":"11921720728","pt":1724159108592,"mc":[{"id":"1.232019003","rc":[{"batb":[[0,1.89,10.98],[1,1.88,4],[2,1.75,4.39]],"ltp":2.2,"tv":33.56,"id":67083366}]}]}
{"op":"mcm","clk":"11921720843","pt":1724159110760,"mc":[{"id":"1.232019003","rc":[{"batb":[[1,1.75,4.39],[2,1.63,1.01]],"ltp":2.2,"tv":33.56,"id":67083366}]}]}
{"op":"mcm","clk":"11921720895","pt":1724159112156,"mc":[{"id":"1.232019003","rc":[{"batb":[[0,1.87,1.96],[1,1.75,3.41]],"ltp":2.2,"tv":33.56,"id":67083366}]}]}
{"op":"mcm","clk":"11921720984","pt":1724159113974,"mc":[{"id":"1.232019003","rc":[{"batb":[[0,1.88,4.98],[1,1.75,4.39]],"ltp":2.2,"tv":33.56,"id":67083366}]}]}
{"op":"mcm","clk":"11921721022","pt":1724159114691,"mc":[{"id":"1.232019003","rc":[{"batb":[[0,1.89,10.98],[1,1.88,4],[2,1.75,4.39]],"ltp":2.2,"tv":33.56,"id":67083366}]}]}
{"op":"mcm","clk":"11921721138","pt":1724159116763,"mc":[{"id":"1.232019003","rc":[{"batb":[[1,1.75,4.39],[2,1.63,1.01]],"ltp":2.2,"tv":33.56,"id":67083366}]}]}
{"op":"mcm","clk":"11921721196","pt":1724159117952,"mc":[{"id":"1.232019003","rc":[{"batb":[[0,1.87,1.96],[1,1.75,3.41]],"ltp":2.2,"tv":33.56,"id":67083366}]}]}
{"op":"mcm","clk":"11921721248","pt":1724159119086,"mc":[{"id":"1.232019003","rc":[{"batb":[[0,1.88,4.98],[1,1.75,4.39]],"ltp":2.2,"tv":33.56,"id":67083366}]}]}
{"op":"mcm","clk":"11921721380","pt":1724159121595,"mc":[{"id":"1.232019003","rc":[{"batb":[[0,1.87,1.96],[1,1.75,3.41]],"ltp":2.2,"tv":33.56,"id":67083366}]}]}
{"op":"mcm","clk":"11921721552","pt":1724159124592,"mc":[{"id":"1.232019003","rc":[{"batb":[[0,1.89,10.98],[1,1.88,4],[2,1.75,4.39]],"ltp":2.2,"tv":33.56,"id":67083366}]}]}
{"op":"mcm","clk":"11921721577","pt":1724159125053,"mc":[{"id":"1.232019003","rc":[{"batl":[[0,1.71,1.15],[1,2.36,2.74],[2,5,1.54]],"ltp":1.7,"tv":29.38,"id":72857116}]}]}
{"op":"mcm","clk":"11921721680","pt":1724159127060,"mc":[{"id":"1.232019003","rc":[{"batb":[[1,1.75,4.39],[2,1.63,1.01]],"ltp":2.2,"tv":33.56,"id":67083366},{"batl":[[0,2.36,2.74],[1,5,1.54],[2,9,1.54]],"ltp":1.7,"tv":29.38,"id":72857116}]}]}
{"op":"mcm","clk":"11921721734","pt":1724159128193,"mc":[{"id":"1.232019003","rc":[{"batb":[[0,1.87,1.96],[1,1.75,3.41]],"ltp":2.2,"tv":33.56,"id":67083366}]}]}
{"op":"mcm","clk":"11921721800","pt":1724159129685,"mc":[{"id":"1.232019003","rc":[{"batb":[[0,1.88,4.98],[1,1.75,4.39]],"ltp":2.2,"tv":33.56,"id":67083366}]}]}
{"op":"mcm","clk":"11921721883","pt":1724159131294,"mc":[{"id":"1.232019003","rc":[{"batb":[[0,1.89,10.98],[1,1.88,4],[2,1.75,4.39]],"ltp":2.2,"tv":33.56,"id":67083366}]}]}
{"op":"mcm","clk":"11921721933","pt":1724159132274,"mc":[{"id":"1.232019003","rc":[{"batb":[[1,1.75,4.39],[2,1.63,1.01]],"ltp":2.2,"tv":33.56,"id":67083366}]}]}
{"op":"mcm","clk":"11921722061","pt":1724159135103,"mc":[{"id":"1.232019003","rc":[{"batb":[[0,1.88,4.98]],"ltp":2.2,"tv":33.56,"id":67083366}]}]}
{"op":"mcm","clk":"11921722196","pt":1724159137596,"mc":[{"id":"1.232019003","rc":[{"batb":[[0,1.87,1.96],[1,1.75,3.41]],"ltp":2.2,"tv":33.56,"id":67083366}]}]}
{"op":"mcm","clk":"11921722204","pt":1724159137697,"mc":[{"id":"1.232019003","rc":[{"batb":[[0,1.89,10.98],[1,1.75,4.39]],"ltp":2.2,"tv":33.56,"id":67083366}]}]}
{"op":"mcm","clk":"11921722276","pt":1724159139394,"mc":[{"id":"1.232019003","rc":[{"batb":[[0,1.89,11.96]],"ltp":2.2,"tv":33.56,"id":67083366}]}]}
{"op":"mcm","clk":"11921722371","pt":1724159141099,"mc":[{"id":"1.232019003","rc":[{"batb":[[0,1.9,4.98],[1,1.87,1.96],[2,1.75,3.41]],"ltp":2.2,"tv":33.56,"id":67083366}]}]}
{"op":"mcm","clk":"11921722498","pt":1724159143621,"mc":[{"id":"1.232019003","rc":[{"batb":[[0,1.89,1.96],[1,1.75,4.39],[2,1.63,1.01]],"batl":[[0,1.92,1.15],[1,4,1.71],[2,6,1.54]],"ltp":2.2,"tv":33.56,"id":67083366}]}]}
{"op":"mcm","clk":"11921722578","pt":1724159145619,"mc":[{"id":"1.232019003","rc":[{"batb":[[0,1.9,4.98],[1,1.87,1.96],[2,1.75,3.41]],"batl":[[0,4,1.71],[1,6,1.54],[2,9,0.77]],"ltp":2.2,"tv":33.56,"id":67083366}]}]}
{"op":"mcm","clk":"11921722588","pt":1724159145776,"mc":[{"id":"1.232019003","rc":[{"batb":[[0,1.91,10],[1,1.9,4.98],[2,1.87,1.96]],"ltp":2.2,"tv":33.56,"id":67083366}]}]}
{"op":"mcm","clk":"11921722692","pt":1724159147999,"mc":[{"id":"1.232019003","rc":[{"batb":[[1,1.89,1.96],[2,1.75,4.39]],"ltp":2.2,"tv":33.56,"id":67083366}]}]}
{"op":"mcm","clk":"11921722767","pt":1724159149086,"mc":[{"id":"1.232019003","rc":[{"batb":[[0,1.89,1.96],[1,1.75,4.39],[2,1.63,1.01]],"ltp":2.2,"tv":33.56,"id":67083366}]}]}
{"op":"mcm","clk":"11921722834","pt":1724159150428,"mc":[{"id":"1.232019003","rc":[{"batb":[[0,1.9,4.98],[1,1.87,1.96],[2,1.75,3.41]],"ltp":2.2,"tv":33.56,"id":67083366}]}]}
{"op":"mcm","clk":"11921722999","pt":1724159153004,"mc":[{"id":"1.232019003","rc":[{"batb":[[0,1.91,10],[1,1.89,1.96],[2,1.75,4.39]],"ltp":2.2,"tv":33.56,"id":67083366}]}]}
{"op":"mcm","clk":"11921723198","pt":1724159156306,"mc":[{"id":"1.232019003","rc":[{"batb":[[0,1.9,4.98],[1,1.87,1.96],[2,1.75,3.41]],"ltp":2.2,"tv":33.56,"id":67083366}]}]}
{"op":"mcm","clk":"11921723320","pt":1724159158835,"mc":[{"id":"1.232019003","rc":[{"batb":[[0,1.91,10],[1,1.89,1.96],[2,1.75,4.39]],"ltp":2.2,"tv":33.56,"id":67083366}]}]}
{"op":"mcm","clk":"11921723537","pt":1724159162610,"mc":[{"id":"1.232019003","rc":[{"batb":[[0,1.9,4.98],[1,1.87,1.96],[2,1.75,3.41]],"ltp":2.2,"tv":33.56,"id":67083366},{"batl":[[0,1.71,1.15],[1,2.36,2.74],[2,5,1.54]],"ltp":1.7,"tv":29.38,"id":72857116}]}]}
{"op":"mcm","clk":"11921723651","pt":1724159164622,"mc":[{"id":"1.232019003","rc":[{"batb":[[0,1.89,1.96],[1,1.75,4.39],[2,1.63,1.01]],"ltp":2.2,"tv":33.56,"id":67083366}]}]}
{"op":"mcm","clk":"11921723658","pt":1724159164725,"mc":[{"id":"1.232019003","rc":[{"batl":[[0,2.36,2.74],[1,5,1.54],[2,9,1.54]],"ltp":1.7,"tv":29.38,"id":72857116}]}]}
{"op":"mcm","clk":"11921723935","pt":1724159169628,"mc":[{"id":"1.232019003","rc":[{"batb":[[0,1.91,10],[1,1.9,4.98],[2,1.87,1.96]],"ltp":2.2,"tv":33.56,"id":67083366}]}]}
{"op":"mcm","clk":"11921724051","pt":1724159171745,"mc":[{"id":"1.232019003","rc":[{"batb":[[1,1.89,1.96],[2,1.75,4.39]],"ltp":2.2,"tv":33.56,"id":67083366}]}]}
{"op":"mcm","clk":"11921724153","pt":1724159173241,"mc":[{"id":"1.232019003","rc":[{"batb":[[0,1.89,1.96],[1,1.75,4.39],[2,1.63,1.01]],"ltp":2.2,"tv":33.56,"id":67083366},{"batb":[[0,1.7,1.96],[1,1.62,2.26],[2,1.6,2.56]],"ltp":1.7,"tv":29.38,"id":72857116}]}]}
{"op":"mcm","clk":"11921724302","pt":1724159176337,"mc":[{"id":"1.232019003","rc":[{"batb":[[0,1.91,10],[1,1.9,4.98],[2,1.87,1.96]],"ltp":2.2,"tv":33.56,"id":67083366}]}]}
{"op":"mcm","clk":"11921724397","pt":1724159178353,"mc":[{"id":"1.232019003","rc":[{"batb":[[1,1.89,1.96],[2,1.75,4.39]],"ltp":2.2,"tv":33.56,"id":67083366}]}]}
{"op":"mcm","clk":"11921724478","pt":1724159179948,"mc":[{"id":"1.232019003","rc":[{"batb":[[0,1.89,1.96],[1,1.75,4.39],[2,1.63,1.01]],"ltp":2.2,"tv":33.56,"id":67083366}]}]}
{"op":"mcm","clk":"11921724602","pt":1724159182423,"mc":[{"id":"1.232019003","rc":[{"batb":[[0,1.9,4.98],[1,1.87,1.96],[2,1.75,3.41]],"ltp":2.2,"tv":33.56,"id":67083366}]}]}
{"op":"mcm","clk":"11921724620","pt":1724159182837,"mc":[{"id":"1.232019003","rc":[{"batb":[[0,1.91,10],[1,1.9,4.98],[2,1.87,1.96]],"ltp":2.2,"tv":33.56,"id":67083366}]}]}
{"op":"mcm","clk":"11921724757","pt":1724159185228,"mc":[{"id":"1.232019003","rc":[{"batb":[[1,1.89,1.96],[2,1.75,4.39]],"ltp":2.2,"tv":33.56,"id":67083366}]}]}
{"op":"mcm","clk":"11921724831","pt":1724159186259,"mc":[{"id":"1.232019003","rc":[{"batb":[[0,1.89,1.96],[1,1.75,4.39],[2,1.63,1.01]],"ltp":2.2,"tv":33.56,"id":67083366}]}]}
{"op":"mcm","clk":"11921724926","pt":1724159187560,"mc":[{"id":"1.232019003","rc":[{"batl":[[0,1.92,1.15],[1,4,1.71],[2,6,1.54]],"ltp":2.2,"tv":33.56,"id":67083366}]}]}
{"op":"mcm","clk":"11921725040","pt":1724159189624,"mc":[{"id":"1.232019003","rc":[{"batb":[[0,1.91,10],[1,1.9,4.98],[2,1.87,1.96]],"batl":[[0,4,1.71],[1,6,1.54],[2,9,0.77]],"ltp":2.2,"tv":33.56,"id":67083366}]}]}
{"op":"mcm","clk":"11921725140","pt":1724159191845,"mc":[{"id":"1.232019003","rc":[{"batb":[[1,1.89,1.96],[2,1.75,4.39]],"ltp":2.2,"tv":33.56,"id":67083366}]}]}
{"op":"mcm","clk":"11921725209","pt":1724159193238,"mc":[{"id":"1.232019003","rc":[{"batb":[[0,1.89,1.96],[1,1.75,4.39],[2,1.63,1.01]],"ltp":2.2,"tv":33.56,"id":67083366}]}]}
{"op":"mcm","clk":"11921725486","pt":1724159198325,"mc":[{"id":"1.232019003","rc":[{"batb":[[0,1.91,10],[1,1.9,4.98],[2,1.87,1.96]],"ltp":2.2,"tv":33.56,"id":67083366}]}]}
{"op":"mcm","clk":"11921725641","pt":1724159200234,"mc":[{"id":"1.232019003","rc":[{"batb":[[1,1.89,1.96],[2,1.75,4.39]],"ltp":2.2,"tv":33.56,"id":67083366}]}]}
{"op":"mcm","clk":"11921725743","pt":1724159201941,"mc":[{"id":"1.232019003","rc":[{"batb":[[0,1.89,1.96],[1,1.75,4.39],[2,1.63,1.01]],"ltp":2.2,"tv":33.56,"id":67083366}]}]}
{"op":"mcm","clk":"11921725811","pt":1724159203230,"mc":[{"id":"1.232019003","rc":[{"batb":[[0,1.9,4.98],[1,1.87,1.96],[2,1.75,3.41]],"ltp":2.2,"tv":33.56,"id":67083366}]}]}
{"op":"mcm","clk":"11921725892","pt":1724159204566,"mc":[{"id":"1.232019003","rc":[{"batb":[[0,1.91,10],[1,1.9,4.98],[2,1.87,1.96]],"ltp":2.2,"tv":33.56,"id":67083366}]}]}
{"op":"mcm","clk":"11921725981","pt":1724159205960,"mc":[{"id":"1.232019003","rc":[{"batb":[[1,1.89,1.96],[2,1.75,4.39]],"ltp":2.2,"tv":33.56,"id":67083366}]}]}
{"op":"mcm","clk":"11921726098","pt":1724159208159,"mc":[{"id":"1.232019003","rc":[{"batb":[[0,1.9,4.98],[1,1.87,1.96],[2,1.75,3.41]],"ltp":2.2,"tv":33.56,"id":67083366}]}]}
{"op":"mcm","clk":"11921726242","pt":1724159210542,"mc":[{"id":"1.232019003","rc":[{"batb":[[0,1.89,1.96],[1,1.75,4.39],[2,1.63,1.01]],"ltp":2.2,"tv":33.56,"id":67083366}]}]}
{"op":"mcm","clk":"11921726303","pt":1724159211677,"mc":[{"id":"1.232019003","rc":[{"batl":[[0,1.73,1.15],[1,2.36,2.74],[2,5,1.54]],"ltp":1.7,"tv":29.38,"id":72857116}]}]}
{"op":"mcm","clk":"11921726440","pt":1724159214462,"mc":[{"id":"1.232019003","rc":[{"batb":[[0,1.91,10],[1,1.9,4.98],[2,1.87,1.96]],"ltp":2.2,"tv":33.56,"id":67083366},{"batl":[[0,2.36,2.74],[1,5,1.54],[2,9,1.54]],"ltp":1.7,"tv":29.38,"id":72857116}]}]}
{"op":"mcm","clk":"11921726565","pt":1724159216480,"mc":[{"id":"1.232019003","rc":[{"batb":[[1,1.89,1.96],[2,1.75,4.39]],"ltp":2.2,"tv":33.56,"id":67083366}]}]}
{"op":"mcm","clk":"11921726633","pt":1724159217872,"mc":[{"id":"1.232019003","rc":[{"batb":[[0,1.89,1.96],[1,1.75,4.39],[2,1.63,1.01]],"ltp":2.2,"tv":33.56,"id":67083366}]}]}
{"op":"mcm","clk":"11921726730","pt":1724159219684,"mc":[{"id":"1.232019003","rc":[{"batb":[[0,1.9,4.98],[1,1.87,1.96],[2,1.75,3.41]],"ltp":2.2,"tv":33.56,"id":67083366}]}]}
{"op":"mcm","clk":"11921726786","pt":1724159220879,"mc":[{"id":"1.232019003","rc":[{"batb":[[0,1.91,10],[1,1.9,4.98],[2,1.87,1.96]],"ltp":2.2,"tv":33.56,"id":67083366}]}]}
{"op":"mcm","clk":"11921726856","pt":1724159222078,"mc":[{"id":"1.232019003","rc":[{"batb":[[1,1.89,1.96],[2,1.75,4.39]],"ltp":2.2,"tv":33.56,"id":67083366}]}]}
{"op":"mcm","clk":"11921726947","pt":1724159224456,"mc":[{"id":"1.232019003","rc":[{"batb":[[0,1.9,4.98],[1,1.87,1.96],[2,1.75,3.41]],"ltp":2.2,"tv":33.56,"id":67083366}]}]}
{"op":"mcm","clk":"11921727081","pt":1724159226882,"mc":[{"id":"1.232019003","rc":[{"batb":[[0,1.89,1.96],[1,1.75,4.39],[2,1.63,1.01]],"ltp":2.2,"tv":33.56,"id":67083366},{"batl":[[0,1.73,1.15],[1,2.36,2.74],[2,5,1.54]],"ltp":1.7,"tv":29.38,"id":72857116}]}]}
{"op":"mcm","clk":"11921727224","pt":1724159229471,"mc":[{"id":"1.232019003","rc":[{"batb":[[0,1.91,10],[1,1.9,4.98],[2,1.87,1.96]],"ltp":2.2,"tv":33.56,"id":67083366},{"batl":[[0,2.36,2.74],[1,5,1.54],[2,9,1.54]],"ltp":1.7,"tv":29.38,"id":72857116}]}]}
{"op":"mcm","clk":"11921727354","pt":1724159231591,"mc":[{"id":"1.232019003","rc":[{"batb":[[1,1.89,1.96],[2,1.75,4.39]],"ltp":2.2,"tv":33.56,"id":67083366}]}]}
{"op":"mcm","clk":"11921727452","pt":1724159232988,"mc":[{"id":"1.232019003","rc":[{"batb":[[0,1.89,1.96],[1,1.75,4.39],[2,1.63,1.01]],"ltp":2.2,"tv":33.56,"id":67083366}]}]}
{"op":"mcm","clk":"11921727718","pt":1724159238071,"mc":[{"id":"1.232019003","rc":[{"batb":[[0,1.91,10],[1,1.9,4.98],[2,1.87,1.96]],"ltp":2.2,"tv":33.56,"id":67083366}]}]}
{"op":"mcm","clk":"11921727827","pt":1724159240165,"mc":[{"id":"1.232019003","rc":[{"batb":[[1,1.89,1.96],[2,1.75,4.39]],"ltp":2.2,"tv":33.56,"id":67083366}]}]}
{"op":"mcm","clk":"11921727897","pt":1724159241866,"mc":[{"id":"1.232019003","rc":[{"batb":[[0,1.89,1.96],[1,1.75,4.39],[2,1.63,1.01]],"ltp":2.2,"tv":33.56,"id":67083366}]}]}
{"op":"mcm","clk":"11921728223","pt":1724159247975,"mc":[{"id":"1.232019003","rc":[{"batb":[[0,1.91,10],[1,1.9,4.98],[2,1.87,1.96]],"ltp":2.2,"tv":33.56,"id":67083366}]}]}
{"op":"mcm","clk":"11921728369","pt":1724159250191,"mc":[{"id":"1.232019003","rc":[{"batb":[[1,1.89,1.96],[2,1.75,4.39]],"ltp":2.2,"tv":33.56,"id":67083366}]}]}
{"op":"mcm","clk":"11921728451","pt":1724159251793,"mc":[{"id":"1.232019003","rc":[{"batb":[[0,1.89,1.96],[1,1.75,4.39],[2,1.63,1.01]],"ltp":2.2,"tv":33.56,"id":67083366}]}]}
{"op":"mcm","clk":"11921728599","pt":1724159254472,"mc":[{"id":"1.232019003","rc":[{"batb":[[0,1.91,10],[1,1.9,4.98],[2,1.87,1.96]],"batl":[[0,1.93,1.15],[1,4,1.71],[2,6,1.54]],"ltp":2.2,"tv":33.56,"id":67083366}]}]}
{"op":"mcm","clk":"11921728699","pt":1724159256275,"mc":[{"id":"1.232019003","rc":[{"batb":[[1,1.89,1.96],[2,1.75,4.39]],"batl":[[0,4,1.71],[1,6,1.54],[2,9,0.77]],"ltp":2.2,"tv":33.56,"id":67083366}]}]}
{"op":"mcm","clk":"11921728824","pt":1724159258481,"mc":[{"id":"1.232019003","rc":[{"batb":[[0,1.9,4.98],[1,1.87,1.96],[2,1.75,3.41]],"ltp":2.2,"tv":33.56,"id":67083366}]}]}
{"op":"mcm","clk":"11921728980","pt":1724159260994,"mc":[{"id":"1.232019003","rc":[{"batb":[[0,1.89,1.96],[1,1.75,4.39],[2,1.63,1.01]],"ltp":2.2,"tv":33.56,"id":67083366}]}]}
{"op":"mcm","clk":"11921729233","pt":1724159265287,"mc":[{"id":"1.232019003","rc":[{"batb":[[0,1.91,14],[1,1.9,3.93],[2,1.87,1.96]],"ltp":2.2,"tv":33.56,"id":67083366}]}]}
{"op":"mcm","clk":"11921729411","pt":1724159268514,"mc":[{"id":"1.232019003","rc":[{"batb":[[0,1.9,3.93],[1,1.75,4.39],[2,1.63,1.01]],"ltp":2.2,"tv":33.56,"id":67083366}]}]}
{"op":"mcm","clk":"11921729510","pt":1724159269999,"mc":[{"id":"1.232019003","rc":[{"batb":[[0,1.91,4],[1,1.9,2.95],[2,1.75,4.39]],"ltp":2.2,"tv":33.56,"id":67083366}]}]}
{"op":"mcm","clk":"11921729611","pt":1724159272316,"mc":[{"id":"1.232019003","rc":[{"batb":[[0,1.92,10]],"ltp":2.2,"tv":33.56,"id":67083366}]}]}
{"op":"mcm","clk":"11921729664","pt":1724159273600,"mc":[{"id":"1.232019003","rc":[{"batl":[[0,2.36,1.81]],"ltp":1.7,"tv":29.38,"id":72857116}]}]}
{"op":"mcm","clk":"11921729670","pt":1724159273702,"mc":[{"id":"1.232019003","rc":[{"batl":[[0,2.36,2.74]],"ltp":1.7,"tv":29.38,"id":72857116}]}]}
{"op":"mcm","clk":"11921729782","pt":1724159276119,"mc":[{"id":"1.232019003","rc":[{"batb":[[0,1.93,4],[2,1.75,3.41]],"ltp":2.2,"tv":33.56,"id":67083366}]}]}
{"op":"mcm","clk":"11921729852","pt":1724159277606,"mc":[{"id":"1.232019003","rc":[{"batl":[[0,1.73,1.15],[1,2.36,2.74],[2,5,1.54]],"ltp":1.7,"tv":29.38,"id":72857116}]}]}
{"op":"mcm","clk":"11921729888","pt":1724159278221,"mc":[{"id":"1.232019003","rc":[{"batb":[[0,1.9,2.95],[1,1.75,3.41],[2,1.63,1.01]],"ltp":2.2,"tv":33.56,"id":67083366}]}]}
{"op":"mcm","clk":"11921729960","pt":1724159279398,"mc":[{"id":"1.232019003","rc":[{"batl":[[0,5,1.54],[1,9,1.54],[2,9,0]],"ltp":2.2,"tv":33.56,"id":67083366},{"batl":[[0,2.36,2.74],[1,5,1.54],[2,9,1.54]],"ltp":1.7,"tv":29.38,"id":72857116}]}]}
{"op":"mcm","clk":"11921730517","pt":1724159288339,"mc":[{"id":"1.232019003","rc":[{"batb":[[0,1.73,4.92],[1,1.7,1.96],[2,1.62,2.26]],"ltp":1.7,"tv":29.38,"id":72857116}]}]}
{"op":"mcm","clk":"11921730538","pt":1724159288813,"mc":[{"id":"1.232019003","rc":[{"batb":[[0,1.74,10.94],[1,1.73,4.92],[2,1.7,1.96]],"ltp":1.7,"tv":29.38,"id":72857116}]}]}
{"op":"mcm","clk":"11921730708","pt":1724159292317,"mc":[{"id":"1.232019003","rc":[{"batb":[[0,1.73,5.86],[1,1.7,1.96],[2,1.62,2.26]],"ltp":1.7,"tv":29.38,"id":72857116}]}]}
{"op":"mcm","clk":"11921730820","pt":1724159294836,"mc":[{"id":"1.232019003","rc":[{"batb":[[0,1.74,10.94],[1,1.73,4.92],[2,1.7,1.96]],"ltp":1.7,"tv":29.38,"id":72857116}]}]}
{"op":"mcm","clk":"11921731006","pt":1724159298019,"mc":[{"id":"1.232019003","rc":[{"batb":[[0,1.73,5.86],[1,1.7,1.96],[2,1.62,2.26]],"ltp":1.7,"tv":29.38,"id":72857116}]}]}
{"op":"mcm","clk":"11921731079","pt":1724159299757,"mc":[{"id":"1.232019003","rc":[{"trd":[[1.96,1.91]],"batl":[[0,5,1.71]],"ltp":1.96,"tv":34.53,"id":67083366},{"trd":[[2.04,1.84]],"batl":[[0,2.36,1.81]],"ltp":2.04,"tv":30.32,"id":72857116}],"tv":64.86}]}
{"op":"mcm","clk":"11921731245","pt":1724159302138,"mc":[{"id":"1.232019003","rc":[{"batl":[[0,5,1.54]],"ltp":1.96,"tv":34.53,"id":67083366},{"batb":[[0,1.74,10.94],[1,1.73,4.92],[2,1.7,1.96]],"ltp":2.04,"tv":30.32,"id":72857116}]}]}
{"op":"mcm","clk":"11921731465","pt":1724159305560,"mc":[{"id":"1.232019003","rc":[{"batb":[[0,1.73,5.86],[1,1.7,1.96],[2,1.62,2.26]],"ltp":2.04,"tv":30.32,"id":72857116}]}]}
{"op":"mcm","clk":"11921731623","pt":1724159308033,"mc":[{"id":"1.232019003","rc":[{"batb":[[0,1.74,10.94],[1,1.73,4.92],[2,1.7,1.96]],"ltp":2.04,"tv":30.32,"id":72857116}]}]}
{"op":"mcm","clk":"11921731815","pt":1724159311138,"mc":[{"id":"1.232019003","rc":[{"batb":[[0,1.73,5.86],[1,1.7,1.96],[2,1.62,2.26]],"ltp":2.04,"tv":30.32,"id":72857116}]}]}
{"op":"mcm","clk":"11921732064","pt":1724159315459,"mc":[{"id":"1.232019003","rc":[{"batb":[[0,1.74,10.94],[1,1.73,4.92],[2,1.7,1.96]],"ltp":2.04,"tv":30.32,"id":72857116}]}]}
{"op":"mcm","clk":"11921732080","pt":1724159315767,"mc":[{"id":"1.232019003","rc":[{"batl":[[0,1.94,1.15],[1,5,1.54],[2,9,1.54]],"ltp":1.96,"tv":34.53,"id":67083366}]}]}
{"op":"mcm","clk":"11921732196","pt":1724159317945,"mc":[{"id":"1.232019003","rc":[{"batl":[[0,5,1.54],[1,9,1.54],[2,9,0]],"ltp":1.96,"tv":34.53,"id":67083366}]}]}
{"op":"mcm","clk":"11921732300","pt":1724159319431,"mc":[{"id":"1.232019003","rc":[{"batb":[[0,1.73,5.86],[1,1.7,1.96],[2,1.62,2.26]],"batl":[[0,2.36,2.74]],"ltp":2.04,"tv":30.32,"id":72857116}]}]}
{"op":"mcm","clk":"11921732399","pt":1724159321176,"mc":[{"id":"1.232019003","rc":[{"batb":[[0,1.74,10.94],[1,1.73,4.92],[2,1.7,1.96]],"ltp":2.04,"tv":30.32,"id":72857116}]}]}
{"op":"mcm","clk":"11921732578","pt":1724159324477,"mc":[{"id":"1.232019003","rc":[{"batb":[[0,1.73,5.86],[1,1.7,1.96],[2,1.62,2.26]],"ltp":2.04,"tv":30.32,"id":72857116}]}]}
{"op":"mcm","clk":"11921732703","pt":1724159326772,"mc":[{"id":"1.232019003","rc":[{"batb":[[0,1.74,10.94],[1,1.73,4.92],[2,1.7,1.96]],"ltp":2.04,"tv":30.32,"id":72857116}]}]}
{"op":"mcm","clk":"11921732908","pt":1724159330246,"mc":[{"id":"1.232019003","rc":[{"batb":[[0,1.73,5.86],[1,1.7,1.96],[2,1.62,2.26]],"ltp":2.04,"tv":30.32,"id":72857116}]}]}
{"op":"mcm","clk":"11921733145","pt":1724159334070,"mc":[{"id":"1.232019003","rc":[{"batb":[[0,1.74,10.94],[1,1.73,4.92],[2,1.7,1.96]],"ltp":2.04,"tv":30.32,"id":72857116}]}]}
{"op":"mcm","clk":"11921733426","pt":1724159338553,"mc":[{"id":"1.232019003","rc":[{"batb":[[0,1.73,5.86],[1,1.7,1.96],[2,1.62,2.26]],"batl":[[0,1.79,1.15],[1,2.36,2.74],[2,5,1.54]],"ltp":2.04,"tv":30.32,"id":72857116}]}]}
{"op":"mcm","clk":"11921733568","pt":1724159341495,"mc":[{"id":"1.232019003","rc":[{"batl":[[0,2.36,2.74],[1,5,1.54],[2,9,1.54]],"ltp":2.04,"tv":30.32,"id":72857116}]}]}
{"op":"mcm","clk":"11921733602","pt":1724159341867,"mc":[{"id":"1.232019003","rc":[{"batb":[[0,1.74,10.94],[1,1.73,4.92],[2,1.7,1.96]],"ltp":2.04,"tv":30.32,"id":72857116}]}]}
{"op":"mcm","clk":"11921733795","pt":1724159345273,"mc":[{"id":"1.232019003","rc":[{"batb":[[0,1.73,5.86],[1,1.7,1.96],[2,1.62,2.26]],"ltp":2.04,"tv":30.32,"id":72857116}]}]}
{"op":"mcm","clk":"11921733948","pt":1724159347803,"mc":[{"id":"1.232019003","rc":[{"batb":[[0,1.74,10.94],[1,1.73,4.92],[2,1.7,1.96]],"ltp":2.04,"tv":30.32,"id":72857116}]}]}
{"op":"mcm","clk":"11921734154","pt":1724159351313,"mc":[{"id":"1.232019003","rc":[{"batb":[[0,1.73,5.86],[1,1.7,1.96],[2,1.62,2.26]],"ltp":2.04,"tv":30.32,"id":72857116}]}]}
{"op":"mcm","clk":"11921734278","pt":1724159353895,"mc":[{"id":"1.232019003","rc":[{"batb":[[0,1.74,10.94],[1,1.73,4.92],[2,1.7,1.96]],"ltp":2.04,"tv":30.32,"id":72857116}]}]}
{"op":"mcm","clk":"11921734548","pt":1724159358380,"mc":[{"id":"1.232019003","rc":[{"batb":[[0,2.02,1.15],[1,1.73,5.86]],"ltp":2.04,"tv":30.32,"id":72857116}]}]}
{"op":"mcm","clk":"11921734686","pt":1724159360803,"mc":[{"id":"1.232019003","rc":[{"batb":[[0,1.74,10.94],[1,1.73,4.92]],"ltp":2.04,"tv":30.32,"id":72857116}]}]}
{"op":"mcm","clk":"11921734791","pt":1724159362599,"mc":[{"id":"1.232019003","rc":[{"batl":[[0,2.36,1.81]],"ltp":2.04,"tv":30.32,"id":72857116}]}]}
{"op":"mcm","clk":"11921734799","pt":1724159362706,"mc":[{"id":"1.232019003","rc":[{"batl":[[0,2.36,2.74]],"ltp":2.04,"tv":30.32,"id":72857116}]}]}
{"op":"mcm","clk":"11921734871","pt":1724159364195,"mc":[{"id":"1.232019003","rc":[{"batb":[[0,1.73,5.86],[1,1.7,1.96],[2,1.62,2.26]],"ltp":2.04,"tv":30.32,"id":72857116}]}]}
{"op":"mcm","clk":"11921735074","pt":1724159367998,"mc":[{"id":"1.232019003","rc":[{"batb":[[0,1.74,10.94],[1,1.73,4.92],[2,1.7,1.96]],"ltp":2.04,"tv":30.32,"id":72857116}]}]}
{"op":"mcm","clk":"11921735185","pt":1724159369914,"mc":[{"id":"1.232019003","rc":[{"batl":[[0,2,1.97],[1,2.36,2.74],[2,5,1.54]],"ltp":2.04,"tv":30.32,"id":72857116}]}]}
{"op":"mcm","clk":"11921735254","pt":1724159371299,"mc":[{"id":"1.232019003","rc":[{"batb":[[0,1.73,5.86],[1,1.7,1.96],[2,1.62,2.26]],"ltp":2.04,"tv":30.32,"id":72857116}]}]}
{"op":"mcm","clk":"11921735406","pt":1724159373937,"mc":[{"id":"1.232019003","rc":[{"batb":[[0,1.74,10.94],[1,1.73,4.92],[2,1.7,1.96]],"ltp":2.04,"tv":30.32,"id":72857116}]}]}
{"op":"mcm","clk":"11921735641","pt":1724159378023,"mc":[{"id":"1.232019003","rc":[{"batb":[[0,1.73,5.86],[1,1.7,1.96],[2,1.62,2.26]],"ltp":2.04,"tv":30.32,"id":72857116}]}]}
{"op":"mcm","clk":"11921735849","pt":1724159381448,"mc":[{"id":"1.232019003","rc":[{"batb":[[0,1.74,10.94],[1,1.73,4.92],[2,1.7,1.96]],"ltp":2.04,"tv":30.32,"id":72857116}]}]}
{"op":"mcm","clk":"11921736046","pt":1724159384728,"mc":[{"id":"1.232019003","rc":[{"batb":[[0,1.73,5.86],[1,1.7,1.96],[2,1.62,2.26]],"ltp":2.04,"tv":30.32,"id":72857116}]}]}
{"op":"mcm","clk":"11921736228","pt":1724159387917,"mc":[{"id":"1.232019003","rc":[{"batb":[[0,1.74,10.94],[1,1.73,4.92],[2,1.7,1.96]],"ltp":2.04,"tv":30.32,"id":72857116}]}]}
{"op":"mcm","clk":"11921736367","pt":1724159390034,"mc":[{"id":"1.232019003","rc":[{"batl":[[0,1.81,1.15],[1,2,1.97],[2,2.36,2.74]],"ltp":2.04,"tv":30.32,"id":72857116}]}]}
{"op":"mcm","clk":"11921736441","pt":1724159391324,"mc":[{"id":"1.232019003","rc":[{"batb":[[0,1.73,5.86],[1,1.7,1.96],[2,1.62,2.26]],"ltp":2.04,"tv":30.32,"id":72857116}]}]}
{"op":"mcm","clk":"11921736477","pt":1724159391947,"mc":[{"id":"1.232019003","rc":[{"batl":[[0,2,1.97],[1,2.36,2.74],[2,5,1.54]],"ltp":2.04,"tv":30.32,"id":72857116}]}]}
{"op":"mcm","clk":"11921736557","pt":1724159393853,"mc":[{"id":"1.232019003","rc":[{"batb":[[0,1.74,10.94],[1,1.73,4.92],[2,1.7,1.96]],"ltp":2.04,"tv":30.32,"id":72857116}]}]}
{"op":"mcm","clk":"11921736754","pt":1724159397453,"mc":[{"id":"1.232019003","rc":[{"batb":[[0,1.73,5.86],[1,1.7,1.96],[2,1.62,2.26]],"ltp":2.04,"tv":30.32,"id":72857116}]}]}
{"op":"mcm","clk":"11921737048","pt":1724159401551,"mc":[{"id":"1.232019003","rc":[{"batb":[[0,1.74,10.94],[1,1.73,4.92],[2,1.7,1.96]],"ltp":2.04,"tv":30.32,"id":72857116}]}]}
{"op":"mcm","clk":"11921737442","pt":1724159407069,"mc":[{"id":"1.232019003","rc":[{"batb":[[0,1.73,5.86],[1,1.7,1.96],[2,1.62,2.26]],"ltp":2.04,"tv":30.32,"id":72857116}]}]}
{"op":"mcm","clk":"11921737533","pt":1724159408256,"mc":[{"id":"1.232019003","rc":[{"batb":[[0,1.98,1.15],[1,1.73,5.86],[2,1.7,1.96]],"ltp":2.04,"tv":30.32,"id":72857116}]}]}
{"op":"mcm","clk":"11921737718","pt":1724159410474,"mc":[{"id":"1.232019003","rc":[{"batb":[[0,1.73,5.86],[1,1.7,1.96],[2,1.62,2.26]],"ltp":2.04,"tv":30.32,"id":72857116}]}]}
{"op":"mcm","clk":"11921737764","pt":1724159410853,"mc":[{"id":"1.232019003","rc":[{"batb":[[0,1.74,10.94],[1,1.73,4.92],[2,1.7,1.96]],"ltp":2.04,"tv":30.32,"id":72857116}]}]}
{"op":"mcm","clk":"11921737930","pt":1724159413075,"mc":[{"id":"1.232019003","rc":[{"batl":[[0,2,2.91],[1,2.36,1.81]],"ltp":2.04,"tv":30.32,"id":72857116}]}]}
{"op":"mcm","clk":"11921738209","pt":1724159417276,"mc":[{"id":"1.232019003","rc":[{"batb":[[0,1.73,5.86],[1,1.7,1.96],[2,1.62,2.26]],"ltp":2.04,"tv":30.32,"id":72857116}]}]}
{"op":"mcm","clk":"11921738375","pt":1724159419553,"mc":[{"id":"1.232019003","rc":[{"batb":[[0,1.74,10.94],[1,1.73,4.92],[2,1.7,1.96]],"ltp":2.04,"tv":30.32,"id":72857116}]}]}
{"op":"mcm","clk":"11921738677","pt":1724159425065,"mc":[{"id":"1.232019003","rc":[{"batb":[[0,1.73,5.86],[1,1.7,1.96],[2,1.62,2.26]],"ltp":2.04,"tv":30.32,"id":72857116}]}]}
{"op":"mcm","clk":"11921738828","pt":1724159428049,"mc":[{"id":"1.232019003","rc":[{"batb":[[0,1.74,10.94],[1,1.73,4.92],[2,1.7,1.96]],"ltp":2.04,"tv":30.32,"id":72857116}]}]}
{"op":"mcm","clk":"11921739011","pt":1724159431353,"mc":[{"id":"1.232019003","rc":[{"batb":[[0,1.73,5.86],[1,1.7,1.96],[2,1.62,2.26]],"ltp":2.04,"tv":30.32,"id":72857116}]}]}
{"op":"mcm","clk":"11921739066","pt":1724159432278,"mc":[{"id":"1.232019003","rc":[{"batb":[[0,1.71,1.92],[1,1.62,3.24],[2,1.6,2.56]],"ltp":2.04,"tv":30.32,"id":72857116}]}]}
{"op":"mcm","clk":"11921739087","pt":1724159432647,"mc":[{"id":"1.232019003","rc":[{"batl":[[0,1.82,1.15],[1,2,2.91],[2,2.36,1.81]],"ltp":2.04,"tv":30.32,"id":72857116}]}]}
{"op":"mcm","clk":"11921739208","pt":1724159434976,"mc":[{"id":"1.232019003","rc":[{"batl":[[0,2,2.91],[1,2.36,1.81],[2,5,1.54]],"ltp":2.04,"tv":30.32,"id":72857116}]}]}
{"op":"mcm","clk":"11921739290","pt":1724159436575,"mc":[{"id":"1.232019003","rc":[{"batb":[[0,1.82,1.97],[1,1.7,1.96],[2,1.62,2.26]],"ltp":2.04,"tv":30.32,"id":72857116}]}]}
{"op":"mcm","clk":"11921739297","pt":1724159436680,"mc":[{"id":"1.232019003","rc":[{"batb":[[0,1.82,2.91]],"ltp":2.04,"tv":30.32,"id":72857116}]}]}
{"op":"mcm","clk":"11921740186","pt":1724159453586,"mc":[{"id":"1.232019003","rc":[{"batb":[[0,1.82,1.97]],"ltp":2.04,"tv":30.32,"id":72857116}]}]}
{"op":"mcm","clk":"11921740193","pt":1724159453687,"mc":[{"id":"1.232019003","rc":[{"batb":[[0,1.82,2.91]],"ltp":2.04,"tv":30.32,"id":72857116}]}]}
{"op":"mcm","clk":"11921740379","pt":1724159457407,"mc":[{"id":"1.232019003","rc":[{"batb":[[0,1.97,1.15],[1,1.82,2.91],[2,1.7,1.96]],"ltp":2.04,"tv":30.32,"id":72857116}]}]}
{"op":"mcm","clk":"11921740408","pt":1724159457918,"mc":[{"id":"1.232019003","rc":[{"batl":[[0,2,1.97]],"ltp":2.04,"tv":30.32,"id":72857116}]}]}
{"op":"mcm","clk":"11921740525","pt":1724159460078,"mc":[{"id":"1.232019003","rc":[{"batb":[[0,1.82,2.91],[1,1.7,1.96],[2,1.62,2.26]],"ltp":2.04,"tv":30.32,"id":72857116}]}]}
{"op":"mcm","clk":"11921741152","pt":1724159472610,"mc":[{"id":"1.232019003","rc":[{"batb":[[0,1.86,1.01],[1,1.82,1.97],[2,1.7,1.96]],"ltp":2.04,"tv":30.32,"id":72857116}]}]}
{"op":"mcm","clk":"11921742259","pt":1724159493919,"mc":[{"id":"1.232019003","rc":[{"batl":[[0,1.87,1.15],[1,2,1.97],[2,2.36,1.81]],"ltp":2.04,"tv":30.32,"id":72857116}]}]}
{"op":"mcm","clk":"11921742413","pt":1724159496601,"mc":[{"id":"1.232019003","rc":[{"batl":[[0,2,1.97],[1,2.36,1.81],[2,5,1.54]],"ltp":2.04,"tv":30.32,"id":72857116}]}]}
{"op":"mcm","clk":"11921742851","pt":1724159502841,"mc":[{"id":"1.232019003","rc":[{"batb":[[1,1.7,1.96],[2,1.62,2.26]],"ltp":2.04,"tv":30.32,"id":72857116}]}]}
{"op":"mcm","clk":"11921743666","pt":1724159518546,"mc":[{"id":"1.232019003","rc":[{"batl":[[0,1.87,1.15],[1,2,1.97],[2,2.36,1.81]],"ltp":2.04,"tv":30.32,"id":72857116}]}]}
{"op":"mcm","clk":"11921743748","pt":1724159520345,"mc":[{"id":"1.232019003","rc":[{"trd":[[1.87,7.42]],"batb":[[0,1.89,1.8],[1,1.86,1.01],[2,1.7,1.96]],"batl":[[0,2,1.97],[1,2.36,1.81],[2,5,1.54]],"ltp":1.87,"tv":32.62,"id":72857116}],"tv":67.16}]}
{"op":"mcm","clk":"11921743945","pt":1724159524160,"mc":[{"id":"1.232019003","rc":[{"trd":[[2,1.9]],"batl":[[0,2,1.02]],"ltp":2.0,"tv":34.53,"id":72857116}],"tv":69.06}]}
{"op":"mcm","clk":"11921744193","pt":1724159529044,"mc":[{"id":"1.232019003","rc":[{"batb":[[0,1.86,1.01],[1,1.7,1.96],[2,1.62,2.26]],"ltp":2.0,"tv":34.53,"id":72857116}]}]}
{"op":"mcm","clk":"11921758695","pt":1724159810628,"mc":[{"id":"1.232019003","rc":[{"batb":[[0,1.7,1.96],[1,1.62,2.26],[2,1.6,2.56]],"ltp":2.0,"tv":34.53,"id":72857116}]}]}
{"op":"mcm","clk":"11921758700","pt":1724159810731,"mc":[{"id":"1.232019003","rc":[{"batb":[[0,1.85,1.01],[1,1.7,1.96],[2,1.62,2.26]],"ltp":2.0,"tv":34.53,"id":72857116}]}]}
{"op":"mcm","clk":"11921759096","pt":1724159819528,"mc":[{"id":"1.232019003","rc":[{"batb":[[0,1.7,1.96],[1,1.62,2.26],[2,1.6,2.56]],"ltp":2.0,"tv":34.53,"id":72857116}]}]}
{"op":"mcm","clk":"11921759111","pt":1724159819735,"mc":[{"id":"1.232019003","rc":[{"batb":[[0,1.71,1.95],[1,1.62,3.24]],"ltp":2.0,"tv":34.53,"id":72857116}]}]}
{"op":"mcm","clk":"11921760639","pt":1724159850061,"mc":[{"id":"1.232019003","rc":[{"batb":[[0,1.72,10.82],[1,1.7,1.96],[2,1.62,2.26]],"ltp":2.0,"tv":34.53,"id":72857116}]}]}
{"op":"mcm","clk":"11921760961","pt":1724159854975,"mc":[{"id":"1.232019003","rc":[{"batb":[[0,1.73,10.97],[1,1.72,9.85],[2,1.7,1.96]],"ltp":2.0,"tv":34.53,"id":72857116}]}]}
{"op":"mcm","clk":"11921761420","pt":1724159862498,"mc":[{"id":"1.232019003","rc":[{"batb":[[0,1.72,10.82],[1,1.7,1.96],[2,1.62,2.26]],"ltp":2.0,"tv":34.53,"id":72857116}]}]}
{"op":"mcm","clk":"11921761557","pt":1724159864766,"mc":[{"id":"1.232019003","rc":[{"batb":[[0,1.73,10.97],[1,1.72,9.85],[2,1.7,1.96]],"ltp":2.0,"tv":34.53,"id":72857116}]}]}
{"op":"mcm","clk":"11921761802","pt":1724159868876,"mc":[{"id":"1.232019003","rc":[{"batb":[[0,1.72,10.82],[1,1.7,1.96],[2,1.62,2.26]],"ltp":2.0,"tv":34.53,"id":72857116}]}]}
{"op":"mcm","clk":"11921762869","pt":1724159886222,"mc":[{"id":"1.232019003","rc":[{"batb":[[0,1.73,10.97],[1,1.72,9.85],[2,1.7,1.96]],"ltp":2.0,"tv":34.53,"id":72857116}]}]}
{"op":"mcm","clk":"11921763226","pt":1724159892299,"mc":[{"id":"1.232019003","rc":[{"batb":[[0,1.72,10.82],[1,1.7,1.96],[2,1.62,2.26]],"ltp":2.0,"tv":34.53,"id":72857116}]}]}
{"op":"mcm","clk":"11921764077","pt":1724159908327,"mc":[{"id":"1.232019003","rc":[{"batb":[[0,1.73,10.97],[1,1.72,9.85],[2,1.7,1.96]],"ltp":2.0,"tv":34.53,"id":72857116}]}]}
{"op":"mcm","clk":"11921764347","pt":1724159912031,"mc":[{"id":"1.232019003","rc":[{"batb":[[0,1.72,10.82],[1,1.7,1.96],[2,1.62,2.26]],"ltp":2.0,"tv":34.53,"id":72857116}]}]}
{"op":"mcm","clk":"11921765970","pt":1724159936377,"mc":[{"id":"1.232019003","rc":[{"batb":[[0,1.73,10.97],[1,1.72,9.85],[2,1.7,1.96]],"ltp":2.0,"tv":34.53,"id":72857116}]}]}
