{"op":"mcm","clk":"11757025331","pt":1722448131510,"mc":[{"id":"1.231295013","marketDefinition":{"bspMarket":false,"turnInPlayEnabled":true,"persistenceEnabled":true,"marketBaseRate":5.0,"eventId":"33458989","eventTypeId":"4","numberOfWinners":1,"bettingType":"ODDS","marketType":"MATCH_ODDS","marketTime":"2024-08-02T13:45:00.000Z","suspendTime":"2024-08-02T13:45:00.000Z","bspReconciled":false,"complete":true,"inPlay":false,"crossMatching":false,"runnersVoidable":false,"numberOfActiveRunners":2,"betDelay":0,"status":"OPEN","runners":[{"status":"ACTIVE","sortPriority":1,"id":71234216,"name":"Tiruppur Tamizhans"},{"status":"ACTIVE","sortPriority":2,"id":11674133,"name":"Dindigul Dragons"}],"regulators":["MR_INT"],"countryCode":"GB","discountAllowed":false,"timezone":"GMT","openDate":"2024-08-02T13:45:00.000Z","version":6049191363,"name":"Match Odds","eventName":"Tiruppur Tamizhans v Dindigul Dragons"},"rc":[{"batb":[[0,1.03,200],[1,1.02,200],[2,1.01,220]],"ltp":0.0,"tv":0.0,"id":71234216},{"batb":[[0,1.03,200],[1,1.02,200],[2,1.01,220]],"ltp":0.0,"tv":0.0,"id":11674133}]}]}
{"op":"mcm","clk":"11757025490","pt":1722448133181,"mc":[{"id":"1.231295013","marketDefinition":{"bspMarket":false,"turnInPlayEnabled":true,"persistenceEnabled":true,"marketBaseRate":5.0,"eventId":"33458989","eventTypeId":"4","numberOfWinners":1,"bettingType":"ODDS","marketType":"MATCH_ODDS","marketTime":"2024-08-02T13:45:00.000Z","suspendTime":"2024-08-02T13:45:00.000Z","bspReconciled":false,"complete":true,"inPlay":false,"crossMatching":false,"runnersVoidable":false,"numberOfActiveRunners":2,"betDelay":0,"status":"OPEN","runners":[{"status":"ACTIVE","sortPriority":1,"id":71234216,"name":"Tiruppur Tamizhans"},{"status":"ACTIVE","sortPriority":2,"id":11674133,"name":"Dindigul Dragons"}],"regulators":["MR_INT"],"countryCode":"GB","discountAllowed":true,"timezone":"GMT","openDate":"2024-08-02T13:45:00.000Z","version":6049191363,"name":"Match Odds","eventName":"Tiruppur Tamizhans v Dindigul Dragons"}}]}
{"op":"mcm","clk":"11757076467","pt":1722448605943,"mc":[{"id":"1.231295013","rc":[{"batb":[[0,2.16,31.86],[1,1.03,200],[2,1.02,200]],"ltp":0.0,"tv":0.0,"id":71234216},{"batb":[[0,1.8,46.2],[1,1.03,200],[2,1.02,200]],"ltp":0.0,"tv":0.0,"id":11674133}]}]}
{"op":"mcm","clk":"11757078414","pt":1722448627421,"mc":[{"id":"1.231295013","marketDefinition":{"bspMarket":false,"turnInPlayEnabled":true,"persistenceEnabled":true,"marketBaseRate":5.0,"eventId":"33458989","eventTypeId":"4","numberOfWinners":1,"bettingType":"ODDS","marketType":"MATCH_ODDS","marketTime":"2024-08-02T13:45:00.000Z","suspendTime":"2024-08-02T13:45:00.000Z","bspReconciled":false,"complete":true,"inPlay":false,"crossMatching":true,"runnersVoidable":false,"numberOfActiveRunners":2,"betDelay":0,"status":"OPEN","runners":[{"status":"ACTIVE","sortPriority":1,"id":71234216,"name":"Tiruppur Tamizhans"},{"status":"ACTIVE","sortPriority":2,"id":11674133,"name":"Dindigul Dragons"}],"regulators":["MR_INT"],"countryCode":"GB","discountAllowed":true,"timezone":"GMT","openDate":"2024-08-02T13:45:00.000Z","version":6049191363,"name":"Match Odds","eventName":"Tiruppur Tamizhans v Dindigul Dragons"}}]}
{"op":"mcm","clk":"11757140248","pt":1722449186245,"mc":[{"id":"1.231295013","rc":[{"batb":[[0,1.03,200],[1,1.02,200],[2,1.01,220]],"ltp":0.0,"tv":0.0,"id":71234216},{"batb":[[0,1.03,200],[1,1.02,200],[2,1.01,220]],"ltp":0.0,"tv":0.0,"id":11674133}]}]}
{"op":"mcm","clk":"11757140521","pt":1722449187933,"mc":[{"id":"1.231295013","rc":[{"batb":[[0,2.16,31.86],[1,1.03,200],[2,1.02,200]],"ltp":0.0,"tv":0.0,"id":71234216},{"batb":[[0,1.8,46.2],[1,1.03,200],[2,1.02,200]],"ltp":0.0,"tv":0.0,"id":11674133}]}]}
{"op":"mcm","clk":"11757435418","pt":1722451356500,"mc":[{"id":"1.231295013","rc":[{"batb":[[1,1.51,771.27],[2,1.03,200]],"ltp":0.0,"tv":0.0,"id":11674133}]}]}
{"op":"mcm","clk":"11757581555","pt":1722452469376,"mc":[{"id":"1.231295013","rc":[{"batb":[[0,1.03,200],[1,1.02,200],[2,1.01,220]],"ltp":0.0,"tv":0.0,"id":71234216},{"batb":[[0,1.51,770.25],[1,1.03,200],[2,1.02,200]],"ltp":0.0,"tv":0.0,"id":11674133}]}]}
{"op":"mcm","clk":"11757640061","pt":1722452920627,"mc":[{"id":"1.231295013","rc":[{"batb":[[0,1.52,6.4],[1,1.51,770.25],[2,1.03,200]],"ltp":0.0,"tv":0.0,"id":11674133}]}]}
{"op":"mcm","clk":"11757723771","pt":1722453502230,"mc":[{"id":"1.231295013","rc":[{"batb":[[2,1.01,220.93]],"ltp":0.0,"tv":0.0,"id":71234216}]}]}
{"op":"mcm","clk":"11757725217","pt":1722453511711,"mc":[{"id":"1.231295013","rc":[{"batb":[[1,1.02,200.78]],"ltp":0.0,"tv":0.0,"id":71234216}]}]}
{"op":"mcm","clk":"11757726915","pt":1722453522614,"mc":[{"id":"1.231295013","rc":[{"batb":[[0,1.02,201.56],[1,1.01,220.93],[2,1.01,0]],"ltp":0.0,"tv":0.0,"id":71234216},{"batb":[[2,1.03,200.78]],"ltp":0.0,"tv":0.0,"id":11674133}]}]}
{"op":"mcm","clk":"11757728399","pt":1722453532760,"mc":[{"id":"1.231295013","rc":[{"batb":[[0,1.03,1.56],[1,1.02,200.78],[2,1.01,220.93]],"ltp":0.0,"tv":0.0,"id":71234216},{"batb":[[2,1.03,201.56]],"ltp":0.0,"tv":0.0,"id":11674133}]}]}
{"op":"mcm","clk":"11757813503","pt":1722454158145,"mc":[{"id":"1.231295013","rc":[{"batl":[[0,2.96,16.85]],"ltp":0.0,"tv":0.0,"id":71234216}]}]}
{"op":"mcm","clk":"11757888539","pt":1722454689909,"mc":[{"id":"1.231295013","rc":[{"batb":[[0,2.16,31.86],[1,1.03,1.56],[2,1.02,200.78]],"ltp":0.0,"tv":0.0,"id":71234216},{"batb":[[0,1.8,46.2],[1,1.52,6.4],[2,1.51,770.25]],"ltp":0.0,"tv":0.0,"id":11674133}]}]}
{"op":"mcm","clk":"11757910976","pt":1722454856423,"mc":[{"id":"1.231295013","rc":[{"batb":[[1,1.51,770.25],[2,1.03,201.56]],"ltp":0.0,"tv":0.0,"id":11674133}]}]}
{"op":"mcm","clk":"11758085367","pt":1722456326462,"mc":[{"id":"1.231295013","rc":[{"batb":[[2,1.02,296.46]],"ltp":0.0,"tv":0.0,"id":71234216},{"batb":[[1,1.51,770.13]],"ltp":0.0,"tv":0.0,"id":11674133}]}]}
{"op":"mcm","clk":"11758559195","pt":1722465774972,"mc":[{"id":"1.231295013","rc":[{"batb":[[2,1.02,296.43]],"ltp":0.0,"tv":0.0,"id":71234216},{"batb":[[1,1.51,769.89]],"ltp":0.0,"tv":0.0,"id":11674133}]}]}
{"op":"mcm","clk":"11758693312","pt":1722468476126,"mc":[{"id":"1.231295013","rc":[{"batb":[[2,1.02,296.45]],"ltp":0.0,"tv":0.0,"id":71234216},{"trd":[[1.8,0.34]],"batb":[[0,1.8,46.03],[1,1.51,770.01]],"ltp":1.8,"tv":0.33,"id":11674133}],"tv":0.33}]}
{"op":"mcm","clk":"11758693462","pt":1722468478659,"mc":[{"id":"1.231295013","rc":[{"batb":[[0,1.8,46.2]],"ltp":1.8,"tv":0.33,"id":11674133}]}]}
{"op":"mcm","clk":"11758693561","pt":1722468480619,"mc":[{"id":"1.231295013","rc":[{"trd":[[1.8,0.67]],"batb":[[0,1.8,46.03]],"ltp":1.8,"tv":0.67,"id":11674133}],"tv":0.67}]}
{"op":"mcm","clk":"11758693759","pt":1722468483826,"mc":[{"id":"1.231295013","rc":[{"batb":[[0,1.8,46.2]],"ltp":1.8,"tv":0.67,"id":11674133}]}]}
{"op":"mcm","clk":"11758874932","pt":1722471175042,"mc":[{"id":"1.231295013","rc":[{"batb":[[2,1.02,296.48]],"ltp":0.0,"tv":0.0,"id":71234216},{"batb":[[1,1.51,770.25]],"ltp":1.8,"tv":0.67,"id":11674133}]}]}
{"op":"mcm","clk":"11759274431","pt":1722476575081,"mc":[{"id":"1.231295013","rc":[{"batb":[[2,1.02,296.47]],"ltp":0.0,"tv":0.0,"id":71234216},{"batb":[[1,1.51,770.19]],"ltp":1.8,"tv":0.67,"id":11674133}]}]}
{"op":"mcm","clk":"11759657266","pt":1722481975062,"mc":[{"id":"1.231295013","rc":[{"batb":[[2,1.02,296.48]],"ltp":0.0,"tv":0.0,"id":71234216},{"batb":[[1,1.51,770.31]],"ltp":1.8,"tv":0.67,"id":11674133}]}]}
{"op":"mcm","clk":"11759785654","pt":1722484915348,"mc":[{"id":"1.231295013","rc":[{"batb":[[2,1.02,296.48]],"ltp":0.0,"tv":0.0,"id":71234216},{"batb":[[1,1.51,770.25]],"batl":[[0,1.85,45]],"ltp":1.8,"tv":0.67,"id":11674133}]}]}
{"op":"mcm","clk":"11760020167","pt":1722492386976,"mc":[{"id":"1.231295013","rc":[{"batb":[[2,1.02,296.51]],"ltp":0.0,"tv":0.0,"id":71234216},{"trd":[[1.8,93.07]],"batb":[[0,1.51,770.49],[1,1.03,201.56],[2,1.02,296.51]],"batl":[[0,1.8,5.73],[1,1.85,45]],"ltp":1.8,"tv":93.07,"id":11674133}],"tv":93.07}]}
{"op":"mcm","clk":"11760020219","pt":1722492388459,"mc":[{"id":"1.231295013","rc":[{"batb":[[0,1.76,48.63],[1,1.51,770.49],[2,1.03,201.56]],"ltp":1.8,"tv":93.07,"id":11674133}]}]}
{"op":"mcm","clk":"11760020441","pt":1722492394764,"mc":[{"id":"1.231295013","rc":[{"batb":[[1,1.52,51.93],[2,1.51,770.49]],"ltp":1.8,"tv":93.07,"id":11674133}]}]}
{"op":"mcm","clk":"11760140210","pt":1722495513018,"mc":[{"id":"1.231295013","rc":[{"batl":[[1,1.85,0]],"ltp":1.8,"tv":93.07,"id":11674133}]}]}
{"op":"mcm","clk":"11760266562","pt":1722498175023,"mc":[{"id":"1.231295013","rc":[{"batb":[[1,1.03,1.56],[2,1.02,296.83]],"ltp":0.0,"tv":0.0,"id":71234216},{"trd":[[1.8,93.07]],"batb":[[2,1.51,773.08]],"ltp":1.8,"tv":93.07,"id":11674133}],"tv":93.07}]}
{"op":"mcm","clk":"11760382144","pt":1722500334189,"mc":[{"id":"1.231295013","rc":[{"batb":[[1,1.03,1.56],[2,1.02,296.94]],"ltp":0.0,"tv":0.0,"id":71234216},{"batb":[[2,1.51,773.98]],"ltp":1.8,"tv":93.07,"id":11674133}]}]}
{"op":"mcm","clk":"11760457142","pt":1722501731481,"mc":[{"id":"1.231295013","rc":[{"batb":[[0,1.03,1.56],[1,1.02,296.94],[2,1.01,482.06]],"ltp":0.0,"tv":0.0,"id":71234216},{"batb":[[0,1.52,51.93],[1,1.51,773.98],[2,1.03,201.56]],"ltp":1.8,"tv":93.07,"id":11674133}]}]}
{"op":"mcm","clk":"11760514153","pt":1722502747692,"mc":[{"id":"1.231295013","rc":[{"batb":[[0,1.53,6.67],[1,1.52,51.93],[2,1.51,773.98]],"ltp":1.8,"tv":93.07,"id":11674133}]}]}
{"op":"mcm","clk":"11760564575","pt":1722503575041,"mc":[{"id":"1.231295013","rc":[{"batb":[[0,1.03,1.56],[1,1.02,297.01],[2,1.01,482.24]],"ltp":0.0,"tv":0.0,"id":71234216},{"batb":[[0,1.53,6.67],[2,1.51,774.53]],"ltp":1.8,"tv":93.07,"id":11674133}]}]}
{"op":"mcm","clk":"11760580396","pt":1722503839305,"mc":[{"id":"1.231295013","rc":[{"batb":[[0,2.16,31.86],[1,1.03,1.56],[2,1.02,297.01]],"ltp":0.0,"tv":0.0,"id":71234216}]}]}
{"op":"mcm","clk":"11760634809","pt":1722504831950,"mc":[{"id":"1.231295013","rc":[{"batl":[[0,1.79,10],[1,1.8,5.73]],"ltp":1.8,"tv":93.07,"id":11674133}]}]}
{"op":"mcm","clk":"11760635383","pt":1722504842860,"mc":[{"id":"1.231295013","rc":[{"batl":[[0,2.8,10]],"ltp":0.0,"tv":0.0,"id":71234216}]}]}
{"op":"mcm","clk":"11760725356","pt":1722506448131,"mc":[{"id":"1.231295013","rc":[{"batb":[[1,1.03,1.57],[2,1.02,297.19]],"ltp":0.0,"tv":0.0,"id":71234216},{"batb":[[0,1.53,6.69],[1,1.51,775.98],[2,1.05,5.19]],"ltp":1.8,"tv":93.07,"id":11674133}]}]}
{"op":"mcm","clk":"11760725736","pt":1722506453653,"mc":[{"id":"1.231295013","rc":[{"batb":[[0,1.56,51.93],[1,1.53,6.69],[2,1.51,775.98]],"ltp":1.8,"tv":93.07,"id":11674133}]}]}
{"op":"mcm","clk":"11760725892","pt":1722506455933,"mc":[{"id":"1.231295013","rc":[{"batl":[[1,1.8,0]],"ltp":1.8,"tv":93.07,"id":11674133}]}]}
{"op":"mcm","clk":"11760731446","pt":1722506546144,"mc":[{"id":"1.231295013","rc":[{"batb":[[1,1.51,775.98],[2,1.05,5.19]],"ltp":1.8,"tv":93.07,"id":11674133}]}]}
{"op":"mcm","clk":"11760731455","pt":1722506546247,"mc":[{"id":"1.231295013","rc":[{"batb":[[0,1.57,6.69],[1,1.56,51.93],[2,1.51,775.98]],"ltp":1.8,"tv":93.07,"id":11674133}]}]}
{"op":"mcm","clk":"11760798751","pt":1722507640043,"mc":[{"id":"1.231295013","rc":[{"batb":[[0,1.58,19.69],[1,1.57,6.69],[2,1.56,51.93]],"ltp":1.8,"tv":93.07,"id":11674133}]}]}
{"op":"mcm","clk":"11760806772","pt":1722507771392,"mc":[{"id":"1.231295013","rc":[{"batb":[[0,1.58,18.89]],"ltp":1.8,"tv":93.07,"id":11674133}]}]}
{"op":"mcm","clk":"11760828082","pt":1722508122756,"mc":[{"id":"1.231295013","rc":[{"batb":[[0,1.59,9.85],[1,1.58,18.89],[2,1.57,6.69]],"ltp":1.8,"tv":93.07,"id":11674133}]}]}
{"op":"mcm","clk":"11760833240","pt":1722508197310,"mc":[{"id":"1.231295013","rc":[{"batb":[[1,1.57,6.69],[2,1.56,51.93]],"ltp":1.8,"tv":93.07,"id":11674133}]}]}
{"op":"mcm","clk":"11760841989","pt":1722508323579,"mc":[{"id":"1.231295013","rc":[{"batb":[[0,1.59,9.45]],"ltp":1.8,"tv":93.07,"id":11674133}]}]}
{"op":"mcm","clk":"11760843921","pt":1722508351287,"mc":[{"id":"1.231295013","rc":[{"batb":[[0,1.57,6.69],[1,1.56,51.93],[2,1.51,775.98]],"ltp":1.8,"tv":93.07,"id":11674133}]}]}
{"op":"mcm","clk":"11760855728","pt":1722508537096,"mc":[{"id":"1.231295013","rc":[{"batb":[[1,1.51,775.98],[2,1.05,5.19]],"ltp":1.8,"tv":93.07,"id":11674133}]}]}
{"op":"mcm","clk":"11760969789","pt":1722510387501,"mc":[{"id":"1.231295013","rc":[{"batb":[[1,1.03,1.57],[2,1.02,297.04]],"ltp":0.0,"tv":0.0,"id":71234216},{"batb":[[0,1.52,6.68],[1,1.51,774.77]],"ltp":1.8,"tv":93.07,"id":11674133}]}]}
{"op":"mcm","clk":"11761146220","pt":1722513499986,"mc":[{"id":"1.231295013","rc":[{"batb":[[0,1.56,774.77],[1,1.52,6.68]],"ltp":1.8,"tv":93.07,"id":11674133}]}]}
{"op":"mcm","clk":"11761203307","pt":1722514374990,"mc":[{"id":"1.231295013","rc":[{"batb":[[1,1.03,1.56],[2,1.02,296.91]],"ltp":0.0,"tv":0.0,"id":71234216},{"batb":[[0,1.56,773.74],[1,1.52,6.67]],"ltp":1.8,"tv":93.07,"id":11674133}]}]}
{"op":"mcm","clk":"11761207483","pt":1722514393444,"mc":[{"id":"1.231295013","rc":[{"batb":[[0,1.57,6.67],[1,1.56,773.74]],"ltp":1.8,"tv":93.07,"id":11674133}]}]}
{"op":"mcm","clk":"11761211484","pt":1722514452365,"mc":[{"id":"1.231295013","rc":[{"batb":[[0,1.03,1.56],[1,1.02,296.91],[2,1.01,481.98]],"ltp":0.0,"tv":0.0,"id":71234216}]}]}
{"op":"mcm","clk":"11761222181","pt":1722514595849,"mc":[{"id":"1.231295013","rc":[{"batb":[[0,1.57,23.38]],"ltp":1.8,"tv":93.07,"id":11674133}]}]}
{"op":"mcm","clk":"11761252674","pt":1722515194549,"mc":[{"id":"1.231295013","rc":[{"batl":[[0,2.78,16.98],[1,2.8,10]],"ltp":0.0,"tv":0.0,"id":71234216}]}]}
{"op":"mcm","clk":"11761381924","pt":1722517410422,"mc":[{"id":"1.231295013","rc":[{"batb":[[0,2.16,31.86],[1,1.03,1.56],[2,1.02,296.81]],"batl":[[0,2.78,16.97]],"ltp":0.0,"tv":0.0,"id":71234216},{"batb":[[0,1.57,23.37],[1,1.56,772.95]],"ltp":1.8,"tv":93.07,"id":11674133}]}]}
{"op":"mcm","clk":"11761431798","pt":1722518326060,"mc":[{"id":"1.231295013","rc":[{"batl":[[0,2.8,10],[1,2.8,0]],"ltp":0.0,"tv":0.0,"id":71234216},{"batb":[[0,1.57,6.66],[1,1.05,5.19],[2,1.03,201.56]],"ltp":1.8,"tv":93.07,"id":11674133}]}]}
{"op":"mcm","clk":"11761441226","pt":1722518465860,"mc":[{"id":"1.231295013","rc":[{"batb":[[0,1.05,5.19],[1,1.03,201.56],[2,1.02,296.81]],"ltp":1.8,"tv":93.07,"id":11674133}]}]}
{"op":"mcm","clk":"11761491703","pt":1722519377129,"mc":[{"id":"1.231295013","rc":[{"batb":[[0,1.56,54.01],[1,1.05,5.19],[2,1.03,201.56]],"ltp":1.8,"tv":93.07,"id":11674133}]}]}
{"op":"mcm","clk":"11761579329","pt":1722520929478,"mc":[{"id":"1.231295013","rc":[{"batb":[[1,1.03,1.56],[2,1.02,296.71]],"ltp":0.0,"tv":0.0,"id":71234216},{"batb":[[0,1.57,12.8],[1,1.56,54.01],[2,1.05,5.19]],"ltp":1.8,"tv":93.07,"id":11674133}]}]}
{"op":"mcm","clk":"11761580649","pt":1722520950469,"mc":[{"id":"1.231295013","rc":[{"batb":[[0,1.57,12.28]],"ltp":1.8,"tv":93.07,"id":11674133}]}]}
{"op":"mcm","clk":"11761588601","pt":1722521073239,"mc":[{"id":"1.231295013","rc":[{"batb":[[0,1.56,54.01],[1,1.05,5.19],[2,1.03,201.56]],"ltp":1.8,"tv":93.07,"id":11674133}]}]}
{"op":"mcm","clk":"11761651659","pt":1722522109992,"mc":[{"id":"1.231295013","rc":[{"batb":[[0,2.16,37.21]],"ltp":0.0,"tv":0.0,"id":71234216}]}]}
{"op":"mcm","clk":"11761889214","pt":1722525174993,"mc":[{"id":"1.231295013","rc":[{"batb":[[1,1.03,1.56],[2,1.02,296.92]],"ltp":0.0,"tv":0.0,"id":71234216},{"batb":[[2,1.03,201.56]],"ltp":1.8,"tv":93.07,"id":11674133}]}]}
{"op":"mcm","clk":"11761940369","pt":1722525686808,"mc":[{"id":"1.231295013","rc":[{"batb":[[1,1.43,116.28],[2,1.38,131.58]],"ltp":0.0,"tv":0.0,"id":71234216},{"batb":[[1,1.43,116.28],[2,1.38,131.58]],"ltp":1.8,"tv":93.07,"id":11674133}]}]}
{"op":"mcm","clk":"11761972470","pt":1722526040171,"mc":[{"id":"1.231295013","rc":[{"batb":[[1,2.14,7.4],[2,1.43,116.28]],"ltp":0.0,"tv":0.0,"id":71234216},{"batb":[[0,1.67,9.47],[1,1.56,54.01],[2,1.43,116.28]],"ltp":1.8,"tv":93.07,"id":11674133}]}]}
{"op":"mcm","clk":"11761974099","pt":1722526057619,"mc":[{"id":"1.231295013","rc":[{"batb":[[0,1.69,9.39]],"ltp":1.8,"tv":93.07,"id":11674133}]}]}
{"op":"mcm","clk":"11761977081","pt":1722526088342,"mc":[{"id":"1.231295013","rc":[{"batb":[[1,2.1,7.55]],"ltp":0.0,"tv":0.0,"id":71234216}]}]}
{"op":"mcm","clk":"11762001775","pt":1722526352816,"mc":[{"id":"1.231295013","rc":[{"batl":[[0,1.75,22.5],[1,1.79,10]],"ltp":1.8,"tv":93.07,"id":11674133}]}]}
{"op":"mcm","clk":"11762178117","pt":1722528113493,"mc":[{"id":"1.231295013","rc":[{"batb":[[1,1.43,116.28],[2,1.38,131.58]],"ltp":0.0,"tv":0.0,"id":71234216},{"batb":[[0,1.56,54.01],[1,1.43,116.28],[2,1.38,131.58]],"ltp":1.8,"tv":93.07,"id":11674133}]}]}
{"op":"mcm","clk":"11762184142","pt":1722528156062,"mc":[{"id":"1.231295013","rc":[{"batb":[[1,2.14,7.41],[2,1.43,116.28]],"ltp":0.0,"tv":0.0,"id":71234216},{"batb":[[0,1.67,9.49],[1,1.56,54.01],[2,1.43,116.28]],"ltp":1.8,"tv":93.07,"id":11674133}]}]}
{"op":"mcm","clk":"11762185999","pt":1722528168498,"mc":[{"id":"1.231295013","rc":[{"batb":[[0,1.69,9.4]],"ltp":1.8,"tv":93.07,"id":11674133}]}]}
{"op":"mcm","clk":"11762567405","pt":1722531113500,"mc":[{"id":"1.231295013","rc":[{"batb":[[1,1.57,704.78],[2,1.56,54.01]],"ltp":1.8,"tv":93.07,"id":11674133}]}]}
{"op":"mcm","clk":"11762576831","pt":1722531217605,"mc":[{"id":"1.231295013","rc":[{"batb":[[0,1.7,37.5],[1,1.69,9.4],[2,1.57,704.78]],"ltp":1.8,"tv":93.07,"id":11674133}]}]}
{"op":"mcm","clk":"11762577795","pt":1722531227746,"mc":[{"id":"1.231295013","rc":[{"batb":[[1,1.43,116.28],[2,1.38,131.58]],"ltp":0.0,"tv":0.0,"id":71234216},{"batb":[[1,1.57,704.78],[2,1.56,54.01]],"ltp":1.8,"tv":93.07,"id":11674133}]}]}
{"op":"mcm","clk":"11762579167","pt":1722531243365,"mc":[{"id":"1.231295013","rc":[{"batb":[[1,1.6,37.5],[2,1.57,704.78]],"ltp":1.8,"tv":93.07,"id":11674133}]}]}
{"op":"mcm","clk":"11762583862","pt":1722531298429,"mc":[{"id":"1.231295013","rc":[{"batb":[[0,1.57,704.78],[1,1.56,54.01],[2,1.46,775.25]],"ltp":1.8,"tv":93.07,"id":11674133}]}]}
{"op":"mcm","clk":"11762641954","pt":1722531860525,"mc":[{"id":"1.231295013","rc":[{"batb":[[1,2.14,7.42],[2,1.43,116.28]],"ltp":0.0,"tv":0.0,"id":71234216},{"batb":[[0,1.67,9.5],[1,1.57,705.72],[2,1.56,54.01]],"ltp":1.8,"tv":93.07,"id":11674133}]}]}
{"op":"mcm","clk":"11762642766","pt":1722531867530,"mc":[{"id":"1.231295013","rc":[{"batb":[[0,1.69,9.41]],"ltp":1.8,"tv":93.07,"id":11674133}]}]}
{"op":"mcm","clk":"11762723806","pt":1722532447920,"mc":[{"id":"1.231295013","rc":[{"batl":[[0,2.74,17.07],[1,2.8,10]],"ltp":0.0,"tv":0.0,"id":71234216}]}]}
{"op":"mcm","clk":"11762725146","pt":1722532457056,"mc":[{"id":"1.231295013","rc":[{"trd":[[1.69,18]],"batb":[[0,1.57,706.13],[1,1.56,54.01],[2,1.46,776.29]],"ltp":1.69,"tv":111.07,"id":11674133}],"tv":111.07}]}
{"op":"mcm","clk":"11762725469","pt":1722532459449,"mc":[{"id":"1.231295013","rc":[{"batb":[[0,1.58,17.2],[1,1.57,705.72],[2,1.56,54.01]],"ltp":1.69,"tv":111.07,"id":11674133}]}]}
{"op":"mcm","clk":"11762726004","pt":1722532463759,"mc":[{"id":"1.231295013","rc":[{"batb":[[0,1.69,9.41],[1,1.61,9],[2,1.58,16.79]],"ltp":1.69,"tv":111.07,"id":11674133}]}]}
{"op":"mcm","clk":"11762726095","pt":1722532464457,"mc":[{"id":"1.231295013","rc":[{"batl":[[0,2.8,10],[1,2.8,0]],"ltp":0.0,"tv":0.0,"id":71234216},{"batb":[[2,1.57,705.72]],"ltp":1.69,"tv":111.07,"id":11674133}]}]}
{"op":"mcm","clk":"11763148347","pt":1722535540081,"mc":[{"id":"1.231295013","rc":[{"batb":[[1,2.14,7.43]],"ltp":0.0,"tv":0.0,"id":71234216},{"trd":[[1.69,18.01]],"batb":[[0,1.69,9.42],[2,1.57,706.05]],"ltp":1.69,"tv":111.08,"id":11674133}],"tv":111.08}]}
{"op":"mcm","clk":"11763150059","pt":1722535550591,"mc":[{"id":"1.231295013","rc":[{"batb":[[0,1.75,24.76],[1,1.69,9.42],[2,1.61,9]],"batl":[[0,1.79,10],[1,1.79,0]],"ltp":1.69,"tv":111.08,"id":11674133}]}]}
{"op":"mcm","clk":"11763153249","pt":1722535570147,"mc":[{"id":"1.231295013","rc":[{"batb":[[1,1.43,116.28],[2,1.38,131.58]],"ltp":0.0,"tv":0.0,"id":71234216},{"batb":[[1,1.61,9],[2,1.57,706.05]],"ltp":1.69,"tv":111.08,"id":11674133}]}]}
{"op":"mcm","clk":"11763809403","pt":1722539718550,"mc":[{"id":"1.231295013","rc":[{"trd":[[1.69,18.01]],"batb":[[0,1.61,9],[1,1.57,706.88],[2,1.46,777.57]],"ltp":1.69,"tv":111.08,"id":11674133}],"tv":111.08}]}
{"op":"mcm","clk":"11763810134","pt":1722539722735,"mc":[{"id":"1.231295013","rc":[{"batl":[[0,2.74,16.67],[1,2.8,10]],"ltp":0.0,"tv":0.0,"id":71234216}]}]}
{"op":"mcm","clk":"11763811267","pt":1722539729345,"mc":[{"id":"1.231295013","rc":[{"batb":[[1,1.58,27.52],[2,1.57,706.88]],"ltp":1.69,"tv":111.08,"id":11674133}]}]}
{"op":"mcm","clk":"11763811677","pt":1722539731883,"mc":[{"id":"1.231295013","rc":[{"batb":[[1,2.12,7.51],[2,1.43,116.28]],"batl":[[0,2.8,10],[1,2.8,0]],"ltp":0.0,"tv":0.0,"id":71234216},{"batb":[[0,1.69,9.43],[1,1.61,9],[2,1.58,27.52]],"ltp":1.69,"tv":111.08,"id":11674133}]}]}
{"op":"mcm","clk":"11764052745","pt":1722541531802,"mc":[{"id":"1.231295013","rc":[{"batb":[[0,2.12,7.51],[1,1.43,116.28],[2,1.38,131.58]],"ltp":0.0,"tv":0.0,"id":71234216}]}]}
{"op":"mcm","clk":"11764053125","pt":1722541534265,"mc":[{"id":"1.231295013","rc":[{"batb":[[0,2.16,37.21],[1,2.12,7.51],[2,1.43,116.28]],"ltp":0.0,"tv":0.0,"id":71234216}]}]}
{"op":"mcm","clk":"11764102519","pt":1722541981008,"mc":[{"id":"1.231295013","rc":[{"batb":[[1,1.43,116.28],[2,1.38,131.58]],"ltp":0.0,"tv":0.0,"id":71234216},{"batb":[[0,1.61,9],[1,1.58,27.52],[2,1.57,706.88]],"ltp":1.69,"tv":111.08,"id":11674133}]}]}
{"op":"mcm","clk":"11764110722","pt":1722542059483,"mc":[{"id":"1.231295013","rc":[{"batb":[[1,2.12,7.51],[2,1.43,116.28]],"ltp":0.0,"tv":0.0,"id":71234216},{"batb":[[0,1.69,9.43],[1,1.61,9],[2,1.58,27.52]],"ltp":1.69,"tv":111.08,"id":11674133}]}]}
{"op":"mcm","clk":"11764130337","pt":1722542306560,"mc":[{"id":"1.231295013","rc":[{"batb":[[2,1.57,706.88]],"ltp":1.69,"tv":111.08,"id":11674133}]}]}
{"op":"mcm","clk":"11764131425","pt":1722542321804,"mc":[{"id":"1.231295013","rc":[{"trd":[[1.69,33.31]],"batb":[[0,1.69,1.78]],"ltp":1.69,"tv":126.38,"id":11674133}],"tv":126.38}]}
{"op":"mcm","clk":"11764131560","pt":1722542323620,"mc":[{"id":"1.231295013","rc":[{"batb":[[0,1.61,9],[1,1.57,706.88],[2,1.46,777.57]],"ltp":1.69,"tv":126.38,"id":11674133}]}]}
{"op":"mcm","clk":"11764131632","pt":1722542324710,"mc":[{"id":"1.231295013","rc":[{"batl":[[0,2.74,17.21],[1,2.8,10]],"ltp":0.0,"tv":0.0,"id":71234216}]}]}
{"op":"mcm","clk":"11764135470","pt":1722542369117,"mc":[{"id":"1.231295013","rc":[{"batb":[[0,1.64,872.6],[1,1.61,9],[2,1.57,706.88]],"ltp":1.69,"tv":126.38,"id":11674133}]}]}
{"op":"mcm","clk":"11764135545","pt":1722542370045,"mc":[{"id":"1.231295013","rc":[{"batl":[[0,2.8,10],[1,2.8,0]],"ltp":0.0,"tv":0.0,"id":71234216}]}]}
{"op":"mcm","clk":"11764171499","pt":1722542722708,"mc":[{"id":"1.231295013","rc":[{"batb":[[1,1.43,116.28],[2,1.38,131.58]],"ltp":0.0,"tv":0.0,"id":71234216},{"trd":[[1.69,33.31]],"batb":[[0,1.64,871.92],[2,1.57,706.33]],"ltp":1.69,"tv":126.38,"id":11674133}],"tv":126.38}]}
{"op":"mcm","clk":"11764203438","pt":1722543023304,"mc":[{"id":"1.231295013","rc":[{"batb":[[1,2.12,7.51],[2,1.43,116.28]],"ltp":0.0,"tv":0.0,"id":71234216}]}]}
{"op":"mcm","clk":"11764211914","pt":1722543105076,"mc":[{"id":"1.231295013","rc":[{"batb":[[0,1.65,16.74],[1,1.64,871.92],[2,1.61,9]],"ltp":1.69,"tv":126.38,"id":11674133}]}]}
{"op":"mcm","clk":"11764218013","pt":1722543169971,"mc":[{"id":"1.231295013","rc":[{"batb":[[0,1.67,35],[1,1.65,16.74],[2,1.64,871.92]],"ltp":1.69,"tv":126.38,"id":11674133}]}]}
{"op":"mcm","clk":"11764218080","pt":1722543170691,"mc":[{"id":"1.231295013","rc":[{"batb":[[1,1.64,871.92],[2,1.61,9]],"ltp":1.69,"tv":126.38,"id":11674133}]}]}
{"op":"mcm","clk":"11764218865","pt":1722543179508,"mc":[{"id":"1.231295013","rc":[{"batl":[[1,1.84,23.45]],"ltp":1.69,"tv":126.38,"id":11674133}]}]}
{"op":"mcm","clk":"11764489966","pt":1722546774950,"mc":[{"id":"1.231295013","rc":[{"batb":[[1,2.12,7.51]],"ltp":0.0,"tv":0.0,"id":71234216},{"trd":[[1.69,33.31]],"batb":[[1,1.64,872.12]],"ltp":1.69,"tv":126.38,"id":11674133}],"tv":126.38}]}
{"op":"mcm","clk":"11764663733","pt":1722550794695,"mc":[{"id":"1.231295013","rc":[{"batb":[[1,1.43,116.28],[2,1.38,131.58]],"ltp":0.0,"tv":0.0,"id":71234216},{"trd":[[1.69,33.31]],"batb":[[1,1.64,872.19]],"ltp":1.69,"tv":126.38,"id":11674133}],"tv":126.38}]}
{"op":"mcm","clk":"11764665599","pt":1722550846253,"mc":[{"id":"1.231295013","rc":[{"batb":[[1,2.12,7.51],[2,1.43,116.28]],"ltp":0.0,"tv":0.0,"id":71234216}]}]}
{"op":"mcm","clk":"11764743909","pt":1722553000117,"mc":[{"id":"1.231295013","rc":[{"batb":[[1,2.12,46.04]],"ltp":0.0,"tv":0.0,"id":71234216}]}]}
{"op":"mcm","clk":"11764743913","pt":1722553000218,"mc":[{"id":"1.231295013","rc":[{"batb":[[0,2.12,46.04],[1,1.43,116.28],[2,1.38,131.58]],"ltp":0.0,"tv":0.0,"id":71234216}]}]}
{"op":"mcm","clk":"11764759161","pt":1722553419984,"mc":[{"id":"1.231295013","rc":[{"batb":[[0,2.12,38.53]],"ltp":0.0,"tv":0.0,"id":71234216},{"batb":[[1,1.64,872.4]],"ltp":1.69,"tv":126.38,"id":11674133}]}]}
{"op":"mcm","clk":"11764762995","pt":1722553522761,"mc":[{"id":"1.231295013","rc":[{"batb":[[0,2.12,46.04]],"ltp":0.0,"tv":0.0,"id":71234216}]}]}
{"op":"mcm","clk":"11764826472","pt":1722555405248,"mc":[{"id":"1.231295013","rc":[{"batb":[[0,2.12,38.53]],"ltp":0.0,"tv":0.0,"id":71234216}]}]}
{"op":"mcm","clk":"11764827577","pt":1722555439479,"mc":[{"id":"1.231295013","rc":[{"batb":[[1,2.1,7.61],[2,1.43,116.28]],"ltp":0.0,"tv":0.0,"id":71234216}]}]}
{"op":"mcm","clk":"11764894822","pt":1722557575003,"mc":[{"id":"1.231295013","rc":[{"batb":[[1,2.1,7.61]],"ltp":0.0,"tv":0.0,"id":71234216},{"trd":[[1.69,33.32]],"batb":[[1,1.64,872.81]],"ltp":1.69,"tv":126.39,"id":11674133}],"tv":126.39}]}
{"op":"mcm","clk":"11764910370","pt":1722557983981,"mc":[{"id":"1.231295013","rc":[{"trd":[[1.64,130],[1.67,70]],"batb":[[0,1.64,807.81],[1,1.61,9],[2,1.57,707.05]],"ltp":1.64,"tv":326.39,"id":11674133}],"tv":326.39}]}
{"op":"mcm","clk":"11764910498","pt":1722557989368,"mc":[{"id":"1.231295013","rc":[{"batl":[[0,2.56,16.58]],"ltp":0.0,"tv":0.0,"id":71234216},{"batb":[[0,1.65,16.58],[1,1.64,807.81],[2,1.61,9]],"ltp":1.64,"tv":326.39,"id":11674133}]}]}
{"op":"mcm","clk":"11764942016","pt":1722558900006,"mc":[{"id":"1.231295013","rc":[{"batb":[[2,1.57,707.05]],"ltp":1.64,"tv":326.39,"id":11674133}]}]}
{"op":"mcm","clk":"11764943690","pt":1722558942665,"mc":[{"id":"1.231295013","rc":[{"batb":[[1,1.43,116.28],[2,1.38,131.58]],"ltp":0.0,"tv":0.0,"id":71234216}]}]}
{"op":"mcm","clk":"11764947255","pt":1722559031817,"mc":[{"id":"1.231295013","rc":[{"batb":[[1,2.1,7.58],[2,1.43,116.28]],"ltp":0.0,"tv":0.0,"id":71234216}]}]}
{"op":"mcm","clk":"11765024709","pt":1722561746537,"mc":[{"id":"1.231295013","rc":[{"batb":[[1,2.1,7.59]],"ltp":0.0,"tv":0.0,"id":71234216},{"trd":[[1.64,130.02],[1.69,33.33]],"batb":[[0,1.67,32.85],[1,1.65,16.59],[2,1.64,808.06]],"ltp":1.64,"tv":326.42,"id":11674133}],"tv":326.42}]}
{"op":"mcm","clk":"11765024788","pt":1722561749161,"mc":[{"id":"1.231295013","rc":[{"batb":[[1,1.64,808.06],[2,1.57,707.27]],"ltp":1.64,"tv":326.42,"id":11674133}]}]}
{"op":"mcm","clk":"11765041592","pt":1722562427491,"mc":[{"id":"1.231295013","rc":[{"batb":[[1,1.43,116.28],[2,1.38,131.58]],"ltp":0.0,"tv":0.0,"id":71234216}]}]}
{"op":"mcm","clk":"11765042363","pt":1722562473244,"mc":[{"id":"1.231295013","rc":[{"batb":[[1,2.1,7.62],[2,1.43,116.28]],"ltp":0.0,"tv":0.0,"id":71234216}]}]}
{"op":"mcm","clk":"11765102585","pt":1722564686913,"mc":[{"id":"1.231295013","rc":[{"trd":[[1.64,130.03],[1.69,33.33]],"batb":[[1,1.65,707.32],[2,1.64,808.13]],"ltp":1.64,"tv":326.43,"id":11674133}],"tv":326.43}]}
{"op":"mcm","clk":"11765103210","pt":1722564722961,"mc":[{"id":"1.231295013","rc":[{"batb":[[1,1.66,86.42],[2,1.65,707.32]],"ltp":1.64,"tv":326.43,"id":11674133}]}]}
{"op":"mcm","clk":"11765106596","pt":1722564899008,"mc":[{"id":"1.231295013","rc":[{"batb":[[1,1.43,116.28],[2,1.38,131.58]],"ltp":0.0,"tv":0.0,"id":71234216}]}]}
{"op":"mcm","clk":"11765107230","pt":1722564931775,"mc":[{"id":"1.231295013","rc":[{"batb":[[1,2.1,7.62],[2,1.43,116.28]],"ltp":0.0,"tv":0.0,"id":71234216}]}]}
{"op":"mcm","clk":"11765108968","pt":1722565023681,"mc":[{"id":"1.231295013","rc":[{"batb":[[2,1.65,550.14]],"ltp":1.64,"tv":326.43,"id":11674133}]}]}
{"op":"mcm","clk":"11765109028","pt":1722565025991,"mc":[{"id":"1.231295013","rc":[{"batb":[[1,1.66,636.56],[2,1.64,808.13]],"ltp":1.64,"tv":326.43,"id":11674133}]}]}
{"op":"mcm","clk":"11765148391","pt":1722567651292,"mc":[{"id":"1.231295013","rc":[{"trd":[[2.26,0.02]],"ltp":2.26,"tv":0.01,"id":71234216},{"trd":[[1.69,33.33],[1.79,0.02]],"batl":[[0,1.79,9.98]],"ltp":1.79,"tv":326.45,"id":11674133}],"tv":326.47}]}
{"op":"mcm","clk":"11765148476","pt":1722567655289,"mc":[{"id":"1.231295013","rc":[{"trd":[[2.26,0.03]],"ltp":2.26,"tv":0.03,"id":71234216},{"trd":[[1.79,0.04]],"batl":[[0,1.79,9.96]],"ltp":1.79,"tv":326.47,"id":11674133}],"tv":326.5}]}
{"op":"mcm","clk":"11765148533","pt":1722567658212,"mc":[{"id":"1.231295013","rc":[{"trd":[[2.26,0.05]],"ltp":2.26,"tv":0.04,"id":71234216},{"trd":[[1.79,0.06]],"batl":[[0,1.79,9.94]],"ltp":1.79,"tv":326.49,"id":11674133}],"tv":326.54}]}
{"op":"mcm","clk":"11765148577","pt":1722567660784,"mc":[{"id":"1.231295013","rc":[{"trd":[[2.26,0.06]],"ltp":2.26,"tv":0.06,"id":71234216},{"trd":[[1.79,0.08]],"batl":[[0,1.79,9.92]],"ltp":1.79,"tv":326.51,"id":11674133}],"tv":326.57}]}
{"op":"mcm","clk":"11765186077","pt":1722568909432,"mc":[{"id":"1.231295013","rc":[{"batl":[[1,1.84,0]],"ltp":1.79,"tv":326.51,"id":11674133}]}]}
{"op":"mcm","clk":"11765186155","pt":1722568917654,"mc":[{"id":"1.231295013","rc":[{"batl":[[1,1.8,58.45]],"ltp":1.79,"tv":326.51,"id":11674133}]}]}
{"op":"mcm","clk":"11765187530","pt":1722569033975,"mc":[{"id":"1.231295013","rc":[{"batb":[[0,2.26,1],[1,2.12,38.53],[2,2.1,7.62]],"ltp":2.26,"tv":0.06,"id":71234216}]}]}
{"op":"mcm","clk":"11765187538","pt":1722569034285,"mc":[{"id":"1.231295013","rc":[{"batb":[[0,1.68,1.35],[1,1.67,32.85],[2,1.66,636.56]],"ltp":1.79,"tv":326.51,"id":11674133}]}]}
{"op":"mcm","clk":"11765212216","pt":1722571071862,"mc":[{"id":"1.231295013","rc":[{"trd":[[2.26,0.1]],"batb":[[0,2.12,39.51],[1,2.1,7.62],[2,1.43,116.28]],"ltp":2.26,"tv":0.1,"id":71234216}],"tv":326.61}]}
{"op":"mcm","clk":"11765212236","pt":1722571074161,"mc":[{"id":"1.231295013","rc":[{"trd":[[2.26,0.14]],"batb":[[0,2.12,39.49]],"ltp":2.26,"tv":0.14,"id":71234216}],"tv":326.65}]}
{"op":"mcm","clk":"11765212251","pt":1722571076455,"mc":[{"id":"1.231295013","rc":[{"trd":[[2.26,0.18]],"batb":[[0,2.12,39.47]],"ltp":2.26,"tv":0.17,"id":71234216}],"tv":326.69}]}
{"op":"mcm","clk":"11765212268","pt":1722571078862,"mc":[{"id":"1.231295013","rc":[{"trd":[[2.26,0.22]],"batb":[[0,2.12,39.45]],"ltp":2.26,"tv":0.21,"id":71234216}],"tv":326.73}]}
{"op":"mcm","clk":"11765212280","pt":1722571081471,"mc":[{"id":"1.231295013","rc":[{"trd":[[2.26,0.25]],"batb":[[0,2.12,39.43]],"ltp":2.26,"tv":0.25,"id":71234216}],"tv":326.76}]}
{"op":"mcm","clk":"11765212297","pt":1722571084587,"mc":[{"id":"1.231295013","rc":[{"trd":[[2.26,0.27]],"batb":[[0,2.12,39.42]],"ltp":2.26,"tv":0.27,"id":71234216}],"tv":326.78}]}
{"op":"mcm","clk":"11765212329","pt":1722571089495,"mc":[{"id":"1.231295013","rc":[{"trd":[[2.26,0.29]],"batb":[[0,2.12,39.41]],"ltp":2.26,"tv":0.29,"id":71234216}],"tv":326.8}]}
{"op":"mcm","clk":"11765261573","pt":1722573775008,"mc":[{"id":"1.231295013","rc":[{"batb":[[1,2.1,7.62]],"ltp":2.26,"tv":0.29,"id":71234216},{"trd":[[1.64,130.04],[1.69,33.34]],"batb":[[2,1.66,636.69]],"ltp":1.79,"tv":326.53,"id":11674133}],"tv":326.83}]}
{"op":"mcm","clk":"11765274172","pt":1722574253222,"mc":[{"id":"1.231295013","rc":[{"trd":[[2.26,0.33]],"batb":[[0,2.12,39.39]],"ltp":2.26,"tv":0.33,"id":71234216}],"tv":326.86}]}
{"op":"mcm","clk":"11765327212","pt":1722576347366,"mc":[{"id":"1.231295013","rc":[{"batb":[[1,1.43,116.28],[2,1.38,131.58]],"ltp":2.26,"tv":0.33,"id":71234216},{"trd":[[1.64,130.03],[1.69,33.34]],"batb":[[2,1.66,636.56]],"ltp":1.79,"tv":326.52,"id":11674133}],"tv":326.85}]}
{"op":"mcm","clk":"11765328472","pt":1722576394954,"mc":[{"id":"1.231295013","rc":[{"batb":[[1,2.08,7.65],[2,1.43,116.28]],"ltp":2.26,"tv":0.33,"id":71234216}]}]}
{"op":"mcm","clk":"11765330300","pt":1722576457118,"mc":[{"id":"1.231295013","rc":[{"batb":[[1,1.43,116.28],[2,1.38,131.58]],"ltp":2.26,"tv":0.33,"id":71234216}]}]}
{"op":"mcm","clk":"11765333007","pt":1722576550664,"mc":[{"id":"1.231295013","rc":[{"batb":[[1,2.08,7.65],[2,1.43,116.28]],"ltp":2.26,"tv":0.33,"id":71234216}]}]}
{"op":"mcm","clk":"11765346782","pt":1722577214151,"mc":[{"id":"1.231295013","rc":[{"batb":[[1,1.43,116.28],[2,1.38,131.58]],"ltp":2.26,"tv":0.33,"id":71234216}]}]}
{"op":"mcm","clk":"11765359992","pt":1722577881207,"mc":[{"id":"1.231295013","rc":[{"batb":[[1,2.08,7.65],[2,1.43,116.28]],"ltp":2.26,"tv":0.33,"id":71234216}]}]}
{"op":"mcm","clk":"11765360740","pt":1722577910624,"mc":[{"id":"1.231295013","rc":[{"batb":[[1,1.43,116.28],[2,1.38,131.58]],"ltp":2.26,"tv":0.33,"id":71234216}]}]}
{"op":"mcm","clk":"11765366375","pt":1722578090674,"mc":[{"id":"1.231295013","rc":[{"batb":[[1,2.08,7.65],[2,1.43,116.28]],"ltp":2.26,"tv":0.33,"id":71234216}]}]}
{"op":"mcm","clk":"11765371855","pt":1722578252659,"mc":[{"id":"1.231295013","rc":[{"batb":[[1,1.43,116.28],[2,1.38,131.58]],"ltp":2.26,"tv":0.33,"id":71234216}]}]}
{"op":"mcm","clk":"11765403846","pt":1722579174996,"mc":[{"id":"1.231295013","rc":[{"trd":[[1.64,129.98],[1.69,33.34]],"batb":[[2,1.66,636.17]],"ltp":1.79,"tv":326.47,"id":11674133}],"tv":326.8}]}
{"op":"mcm","clk":"11765425737","pt":1722579730569,"mc":[{"id":"1.231295013","rc":[{"batb":[[0,2.28,33.72],[1,1.43,117.14]],"ltp":2.26,"tv":0.33,"id":71234216},{"batb":[[0,1.72,59.95],[1,1.68,1.35],[2,1.67,32.85]],"ltp":1.79,"tv":326.47,"id":11674133}]}]}
{"op":"mcm","clk":"11765425948","pt":1722579740075,"mc":[{"id":"1.231295013","rc":[{"batb":[[1,2.1,8.45],[2,1.43,116.28]],"ltp":2.26,"tv":0.33,"id":71234216}]}]}
{"op":"mcm","clk":"11765427514","pt":1722579803958,"mc":[{"id":"1.231295013","rc":[{"batb":[[1,2.14,8.33]],"ltp":2.26,"tv":0.33,"id":71234216}]}]}
{"op":"mcm","clk":"11765427744","pt":1722579811883,"mc":[{"id":"1.231295013","rc":[{"batb":[[2,1.66,636.17]],"ltp":1.79,"tv":326.47,"id":11674133}]}]}
{"op":"mcm","clk":"11765427964","pt":1722579820961,"mc":[{"id":"1.231295013","rc":[{"batb":[[0,1.75,31.5],[1,1.72,59.95],[2,1.68,1.35]],"ltp":1.79,"tv":326.47,"id":11674133}]}]}
{"op":"mcm","clk":"11765428368","pt":1722579839067,"mc":[{"id":"1.231295013","rc":[{"batb":[[1,1.43,117.14],[2,1.38,131.58]],"ltp":2.26,"tv":0.33,"id":71234216}]}]}
{"op":"mcm","clk":"11765468846","pt":1722581219690,"mc":[{"id":"1.231295013","rc":[{"batl":[[0,1.77,59.69],[1,1.79,9.92],[2,1.8,58.45]],"ltp":1.79,"tv":326.47,"id":11674133}]}]}
{"op":"mcm","clk":"11765476605","pt":1722581467223,"mc":[{"id":"1.231295013","rc":[{"trd":[[1.77,4.44]],"batl":[[0,1.77,57.46]],"ltp":1.77,"tv":330.91,"id":11674133}],"tv":331.24}]}
{"op":"mcm","clk":"11765499140","pt":1722582000362,"mc":[{"id":"1.231295013","rc":[{"batb":[[0,1.72,59.95],[1,1.68,1.35],[2,1.66,636.17]],"ltp":1.77,"tv":330.91,"id":11674133}]}]}
{"op":"mcm","clk":"11765548002","pt":1722583364627,"mc":[{"id":"1.231295013","rc":[{"trd":[[1.64,130.01],[1.69,33.34],[1.72,0.24],[1.77,4.44]],"batb":[[0,1.72,59.83],[2,1.66,636.43]],"batl":[[0,1.77,57.49]],"ltp":1.72,"tv":331.18,"id":11674133}],"tv":331.51}]}
{"op":"mcm","clk":"11765548041","pt":1722583365550,"mc":[{"id":"1.231295013","rc":[{"batb":[[0,1.72,59.95]],"ltp":1.72,"tv":331.18,"id":11674133}]}]}
{"op":"mcm","clk":"11765548405","pt":1722583376956,"mc":[{"id":"1.231295013","rc":[{"trd":[[1.72,0.42]],"batb":[[0,1.72,59.86]],"ltp":1.72,"tv":331.36,"id":11674133}],"tv":331.69}]}
{"op":"mcm","clk":"11765548541","pt":1722583380632,"mc":[{"id":"1.231295013","rc":[{"batb":[[0,1.72,59.95]],"ltp":1.72,"tv":331.36,"id":11674133}]}]}
{"op":"mcm","clk":"11765574657","pt":1722584167368,"mc":[{"id":"1.231295013","rc":[{"batb":[[0,1.74,31.5],[1,1.72,59.95],[2,1.68,1.35]],"ltp":1.72,"tv":331.36,"id":11674133}]}]}
{"op":"mcm","clk":"11765637686","pt":1722585750680,"mc":[{"id":"1.231295013","rc":[{"trd":[[1.64,130.09],[1.69,33.37],[1.77,4.45]],"batl":[[0,1.77,57.56],[1,1.8,58.45],[2,1.86,1.68]],"ltp":1.72,"tv":331.48,"id":11674133}],"tv":331.81}]}
{"op":"mcm","clk":"11765641473","pt":1722585865085,"mc":[{"id":"1.231295013","rc":[{"trd":[[2.28,0.92]],"batb":[[0,2.28,66.98]],"ltp":2.28,"tv":1.25,"id":71234216}],"tv":332.73}]}
{"op":"mcm","clk":"11765641477","pt":1722585865188,"mc":[{"id":"1.231295013","rc":[{"batb":[[0,2.28,33.72]],"ltp":2.28,"tv":1.25,"id":71234216}]}]}
{"op":"mcm","clk":"11765694612","pt":1722587403338,"mc":[{"id":"1.231295013","rc":[{"batb":[[0,1.43,117.14],[1,1.38,131.58],[2,1.33,151.52]],"ltp":2.28,"tv":1.25,"id":71234216},{"batb":[[1,1.68,1.35],[2,1.66,637.12]],"ltp":1.72,"tv":331.48,"id":11674133}]}]}
{"op":"mcm","clk":"11765718474","pt":1722588465313,"mc":[{"id":"1.231295013","rc":[{"batl":[[0,5,1.54]],"ltp":2.28,"tv":1.25,"id":71234216}]}]}
{"op":"mcm","clk":"11765736883","pt":1722589211184,"mc":[{"id":"1.231295013","rc":[{"batb":[[0,1.44,10.86],[1,1.43,116.28],[2,1.38,131.58]],"batl":[[0,5,1.53]],"ltp":2.28,"tv":1.24,"id":71234216},{"trd":[[1.64,129.97],[1.69,33.35],[1.77,4.44]],"batb":[[2,1.66,636.04]],"batl":[[0,1.77,57.45],[2,1.86,1.67]],"ltp":1.72,"tv":331.33,"id":11674133}],"tv":332.58}]}
{"op":"mcm","clk":"11765737039","pt":1722589215409,"mc":[{"id":"1.231295013","rc":[{"batb":[[0,1.43,117.14],[1,1.38,131.58],[2,1.33,151.52]],"ltp":2.28,"tv":1.24,"id":71234216}]}]}
{"op":"mcm","clk":"11765741251","pt":1722589350360,"mc":[{"id":"1.231295013","rc":[{"batb":[[0,1.44,10.86],[1,1.43,116.28],[2,1.38,131.58]],"ltp":2.28,"tv":1.24,"id":71234216}]}]}
{"op":"mcm","clk":"11765741375","pt":1722589356514,"mc":[{"id":"1.231295013","rc":[{"batb":[[0,1.43,117.14],[1,1.38,131.58],[2,1.33,151.52]],"ltp":2.28,"tv":1.24,"id":71234216}]}]}
{"op":"mcm","clk":"11765741417","pt":1722589359143,"mc":[{"id":"1.231295013","rc":[{"batb":[[0,1.44,10.86],[1,1.43,116.28],[2,1.38,131.58]],"ltp":2.28,"tv":1.24,"id":71234216}]}]}
{"op":"mcm","clk":"11765741505","pt":1722589364057,"mc":[{"id":"1.231295013","rc":[{"batb":[[0,1.43,117.14],[1,1.38,131.58],[2,1.33,151.52]],"ltp":2.28,"tv":1.24,"id":71234216}]}]}
{"op":"mcm","clk":"11765750071","pt":1722589804660,"mc":[{"id":"1.231295013","rc":[{"batb":[[0,1.44,10.86],[1,1.43,116.28],[2,1.38,131.58]],"ltp":2.28,"tv":1.24,"id":71234216}]}]}
{"op":"mcm","clk":"11765750139","pt":1722589808059,"mc":[{"id":"1.231295013","rc":[{"batb":[[0,1.43,117.14],[1,1.38,131.58],[2,1.33,151.52]],"ltp":2.28,"tv":1.24,"id":71234216}]}]}
{"op":"mcm","clk":"11765769261","pt":1722590222750,"mc":[{"id":"1.231295013","rc":[{"batb":[[0,2.3,10],[1,2.28,33.72],[2,1.43,117.14]],"ltp":2.28,"tv":1.24,"id":71234216},{"batb":[[1,1.72,59.95],[2,1.68,1.35]],"ltp":1.72,"tv":331.33,"id":11674133}]}]}
{"op":"mcm","clk":"11765769690","pt":1722590226086,"mc":[{"id":"1.231295013","rc":[{"batb":[[0,2.28,33.72],[1,1.43,117.14],[2,1.38,131.58]],"ltp":2.28,"tv":1.24,"id":71234216}]}]}
{"op":"mcm","clk":"11765775660","pt":1722590372830,"mc":[{"id":"1.231295013","rc":[{"batb":[[0,2.3,10],[1,2.28,33.72],[2,1.43,117.14]],"ltp":2.28,"tv":1.24,"id":71234216}]}]}
{"op":"mcm","clk":"11765775688","pt":1722590373503,"mc":[{"id":"1.231295013","rc":[{"batb":[[1,1.43,117.14],[2,1.38,131.58]],"ltp":2.28,"tv":1.24,"id":71234216},{"batb":[[1,1.68,1.35],[2,1.66,636.04]],"ltp":1.72,"tv":331.33,"id":11674133}]}]}
{"op":"mcm","clk":"11765775784","pt":1722590376220,"mc":[{"id":"1.231295013","rc":[{"batb":[[0,1.43,117.14],[1,1.38,131.58],[2,1.33,151.52]],"ltp":2.28,"tv":1.24,"id":71234216}]}]}
{"op":"mcm","clk":"11765775843","pt":1722590378524,"mc":[{"id":"1.231295013","rc":[{"batb":[[0,2.3,10],[1,2.28,33.72],[2,1.43,117.14]],"ltp":2.28,"tv":1.24,"id":71234216},{"batb":[[1,1.72,59.95],[2,1.68,1.35]],"ltp":1.72,"tv":331.33,"id":11674133}]}]}
{"op":"mcm","clk":"11765775915","pt":1722590381927,"mc":[{"id":"1.231295013","rc":[{"batb":[[0,2.28,33.72],[1,1.43,117.14],[2,1.38,131.58]],"ltp":2.28,"tv":1.24,"id":71234216}]}]}
{"op":"mcm","clk":"11765778395","pt":1722590471005,"mc":[{"id":"1.231295013","rc":[{"batb":[[0,2.3,10],[1,2.28,33.72],[2,1.43,117.14]],"ltp":2.28,"tv":1.24,"id":71234216}]}]}
{"op":"mcm","clk":"11765778480","pt":1722590473890,"mc":[{"id":"1.231295013","rc":[{"batb":[[1,1.43,117.14],[2,1.38,131.58]],"ltp":2.28,"tv":1.24,"id":71234216},{"batb":[[1,1.68,1.35],[2,1.66,636.04]],"ltp":1.72,"tv":331.33,"id":11674133}]}]}
{"op":"mcm","clk":"11765778494","pt":1722590474405,"mc":[{"id":"1.231295013","rc":[{"batb":[[0,1.43,117.14],[1,1.38,131.58],[2,1.33,151.52]],"ltp":2.28,"tv":1.24,"id":71234216}]}]}
{"op":"mcm","clk":"11765778629","pt":1722590479137,"mc":[{"id":"1.231295013","rc":[{"batb":[[0,2.3,10],[1,2.28,33.72],[2,1.43,117.14]],"ltp":2.28,"tv":1.24,"id":71234216},{"batb":[[1,1.72,59.95],[2,1.68,1.35]],"ltp":1.72,"tv":331.33,"id":11674133}]}]}
{"op":"mcm","clk":"11765778726","pt":1722590482436,"mc":[{"id":"1.231295013","rc":[{"batb":[[0,2.28,33.72],[1,1.43,117.14],[2,1.38,131.58]],"ltp":2.28,"tv":1.24,"id":71234216}]}]}
{"op":"mcm","clk":"11765781478","pt":1722590566002,"mc":[{"id":"1.231295013","rc":[{"batb":[[0,2.3,10],[1,2.28,33.72],[2,1.43,117.14]],"ltp":2.28,"tv":1.24,"id":71234216}]}]}
{"op":"mcm","clk":"11765781588","pt":1722590569212,"mc":[{"id":"1.231295013","rc":[{"batb":[[1,1.43,117.14],[2,1.38,131.58]],"ltp":2.28,"tv":1.24,"id":71234216},{"batb":[[1,1.68,1.35],[2,1.66,636.04]],"ltp":1.72,"tv":331.33,"id":11674133}]}]}
{"op":"mcm","clk":"11765781648","pt":1722590571221,"mc":[{"id":"1.231295013","rc":[{"batb":[[0,1.43,117.14],[1,1.38,131.58],[2,1.33,151.52]],"ltp":2.28,"tv":1.24,"id":71234216}]}]}
{"op":"mcm","clk":"11765781756","pt":1722590574151,"mc":[{"id":"1.231295013","rc":[{"batb":[[0,2.28,33.72],[1,1.43,117.14],[2,1.38,131.58]],"ltp":2.28,"tv":1.24,"id":71234216},{"batb":[[1,1.72,59.95],[2,1.68,1.35]],"ltp":1.72,"tv":331.33,"id":11674133}]}]}
{"op":"mcm","clk":"11765781776","pt":1722590574820,"mc":[{"id":"1.231295013","rc":[{"batb":[[1,1.44,10.86],[2,1.43,116.28]],"ltp":2.28,"tv":1.24,"id":71234216}]}]}
{"op":"mcm","clk":"11765781929","pt":1722590580847,"mc":[{"id":"1.231295013","rc":[{"batb":[[1,1.43,117.14],[2,1.38,131.58]],"ltp":2.28,"tv":1.24,"id":71234216}]}]}
{"op":"mcm","clk":"11765788940","pt":1722590770088,"mc":[{"id":"1.231295013","rc":[{"batb":[[0,2.3,10],[1,2.28,33.72],[2,1.43,117.14]],"ltp":2.28,"tv":1.24,"id":71234216}]}]}
{"op":"mcm","clk":"11765789075","pt":1722590773687,"mc":[{"id":"1.231295013","rc":[{"batb":[[0,2.28,33.72],[1,1.43,117.14],[2,1.38,131.58]],"ltp":2.28,"tv":1.24,"id":71234216}]}]}
{"op":"mcm","clk":"11765790265","pt":1722590804823,"mc":[{"id":"1.231295013","rc":[{"batb":[[0,2.3,10],[1,2.28,33.72],[2,1.43,117.14]],"ltp":2.28,"tv":1.24,"id":71234216}]}]}
{"op":"mcm","clk":"11765790304","pt":1722590805543,"mc":[{"id":"1.231295013","rc":[{"batb":[[1,1.43,117.14],[2,1.38,131.58]],"ltp":2.28,"tv":1.24,"id":71234216},{"batb":[[0,1.74,5.53],[1,1.68,1.35],[2,1.66,636.04]],"ltp":1.72,"tv":331.33,"id":11674133}]}]}
{"op":"mcm","clk":"11765790394","pt":1722590808527,"mc":[{"id":"1.231295013","rc":[{"batb":[[0,1.43,117.14],[1,1.38,131.58],[2,1.33,151.52]],"ltp":2.28,"tv":1.24,"id":71234216}]}]}
{"op":"mcm","clk":"11765790460","pt":1722590810231,"mc":[{"id":"1.231295013","rc":[{"batb":[[0,2.28,33.72],[1,1.43,117.14],[2,1.38,131.58]],"ltp":2.28,"tv":1.24,"id":71234216},{"batb":[[1,1.72,59.95],[2,1.68,1.35]],"ltp":1.72,"tv":331.33,"id":11674133}]}]}
{"op":"mcm","clk":"11765790774","pt":1722590820157,"mc":[{"id":"1.231295013","rc":[{"batb":[[0,2.3,10],[1,2.28,33.72],[2,1.43,117.14]],"ltp":2.28,"tv":1.24,"id":71234216},{"batb":[[0,1.72,59.95],[1,1.68,1.35],[2,1.66,636.04]],"batl":[[0,1.74,15.05],[1,1.77,57.45],[2,1.8,58.45]],"ltp":1.72,"tv":331.33,"id":11674133}]}]}
{"op":"mcm","clk":"11765790890","pt":1722590823630,"mc":[{"id":"1.231295013","rc":[{"batb":[[0,2.28,33.72],[1,1.43,117.14],[2,1.38,131.58]],"ltp":2.28,"tv":1.24,"id":71234216}]}]}
{"op":"mcm","clk":"11765792079","pt":1722590859374,"mc":[{"id":"1.231295013","rc":[{"batb":[[0,2.3,10],[1,2.28,33.72],[2,1.43,117.14]],"ltp":2.28,"tv":1.24,"id":71234216}]}]}
{"op":"mcm","clk":"11765792206","pt":1722590862780,"mc":[{"id":"1.231295013","rc":[{"batb":[[0,2.28,33.72],[1,1.43,117.14],[2,1.38,131.58]],"ltp":2.28,"tv":1.24,"id":71234216}]}]}
{"op":"mcm","clk":"11765794232","pt":1722590919170,"mc":[{"id":"1.231295013","rc":[{"batb":[[0,2.3,10],[1,2.28,33.72],[2,1.43,117.14]],"ltp":2.28,"tv":1.24,"id":71234216}]}]}
{"op":"mcm","clk":"11765794404","pt":1722590923964,"mc":[{"id":"1.231295013","rc":[{"batb":[[0,2.28,33.72],[1,1.43,117.14],[2,1.38,131.58]],"ltp":2.28,"tv":1.24,"id":71234216}]}]}
{"op":"mcm","clk":"11765797092","pt":1722590991842,"mc":[{"id":"1.231295013","rc":[{"batb":[[0,2.3,10],[1,2.28,33.72],[2,1.43,117.14]],"ltp":2.28,"tv":1.24,"id":71234216}]}]}
{"op":"mcm","clk":"11765797258","pt":1722590995655,"mc":[{"id":"1.231295013","rc":[{"batb":[[0,2.28,33.72],[1,1.43,117.14],[2,1.38,131.58]],"ltp":2.28,"tv":1.24,"id":71234216}]}]}
{"op":"mcm","clk":"11765797500","pt":1722591002141,"mc":[{"id":"1.231295013","rc":[{"batb":[[0,2.3,10],[1,2.28,33.72],[2,1.43,117.14]],"ltp":2.28,"tv":1.24,"id":71234216}]}]}
{"op":"mcm","clk":"11765797676","pt":1722591005554,"mc":[{"id":"1.231295013","rc":[{"batb":[[0,2.28,33.72],[1,1.43,117.14],[2,1.38,131.58]],"ltp":2.28,"tv":1.24,"id":71234216}]}]}
{"op":"mcm","clk":"11765797808","pt":1722591009174,"mc":[{"id":"1.231295013","rc":[{"batb":[[0,2.3,10],[1,2.28,33.72],[2,1.43,117.14]],"ltp":2.28,"tv":1.24,"id":71234216}]}]}
{"op":"mcm","clk":"11765797969","pt":1722591012751,"mc":[{"id":"1.231295013","rc":[{"batb":[[0,2.28,33.72],[1,1.43,117.14],[2,1.38,131.58]],"ltp":2.28,"tv":1.24,"id":71234216}]}]}
{"op":"mcm","clk":"11765801122","pt":1722591084337,"mc":[{"id":"1.231295013","rc":[{"batb":[[0,2.3,10],[1,2.28,33.72],[2,1.43,117.14]],"ltp":2.28,"tv":1.24,"id":71234216}]}]}
{"op":"mcm","clk":"11765801378","pt":1722591089207,"mc":[{"id":"1.231295013","rc":[{"batb":[[0,2.28,33.72],[1,1.43,117.14],[2,1.38,131.58]],"ltp":2.28,"tv":1.24,"id":71234216}]}]}
{"op":"mcm","clk":"11765803233","pt":1722591126461,"mc":[{"id":"1.231295013","rc":[{"batb":[[0,2.3,10],[1,2.28,33.72],[2,1.43,117.14]],"ltp":2.28,"tv":1.24,"id":71234216}]}]}
{"op":"mcm","clk":"11765803425","pt":1722591130185,"mc":[{"id":"1.231295013","rc":[{"batb":[[0,2.28,33.72],[1,1.43,117.14],[2,1.38,131.58]],"ltp":2.28,"tv":1.24,"id":71234216}]}]}
{"op":"mcm","clk":"11765804217","pt":1722591150097,"mc":[{"id":"1.231295013","rc":[{"batb":[[0,2.3,10],[1,2.28,33.72],[2,1.43,117.14]],"ltp":2.28,"tv":1.24,"id":71234216}]}]}
{"op":"mcm","clk":"11765804352","pt":1722591153588,"mc":[{"id":"1.231295013","rc":[{"batb":[[0,2.28,33.72],[1,1.43,117.14],[2,1.38,131.58]],"ltp":2.28,"tv":1.24,"id":71234216}]}]}
{"op":"mcm","clk":"11765808153","pt":1722591256798,"mc":[{"id":"1.231295013","rc":[{"batb":[[0,2.3,10],[1,2.28,33.72],[2,1.43,117.14]],"ltp":2.28,"tv":1.24,"id":71234216}]}]}
{"op":"mcm","clk":"11765808310","pt":1722591260316,"mc":[{"id":"1.231295013","rc":[{"batb":[[0,2.28,33.72],[1,1.43,117.14],[2,1.38,131.58]],"ltp":2.28,"tv":1.24,"id":71234216}]}]}
{"op":"mcm","clk":"11765810791","pt":1722591326478,"mc":[{"id":"1.231295013","rc":[{"batb":[[0,2.3,10],[1,2.28,33.72],[2,1.43,117.14]],"ltp":2.28,"tv":1.24,"id":71234216}]}]}
{"op":"mcm","clk":"11765810925","pt":1722591329886,"mc":[{"id":"1.231295013","rc":[{"batb":[[0,2.28,33.72],[1,1.43,117.14],[2,1.38,131.58]],"ltp":2.28,"tv":1.24,"id":71234216}]}]}
{"op":"mcm","clk":"11765813139","pt":1722591384146,"mc":[{"id":"1.231295013","rc":[{"batb":[[0,2.3,10],[1,2.28,33.72],[2,1.43,117.14]],"ltp":2.28,"tv":1.24,"id":71234216}]}]}
{"op":"mcm","clk":"11765813287","pt":1722591387465,"mc":[{"id":"1.231295013","rc":[{"batb":[[0,2.28,33.72],[1,1.43,117.14],[2,1.38,131.58]],"ltp":2.28,"tv":1.24,"id":71234216}]}]}
{"op":"mcm","clk":"11765876138","pt":1722593139080,"mc":[{"id":"1.231295013","rc":[{"batb":[[0,2.3,10],[1,2.28,33.72],[2,1.43,117.14]],"batl":[[0,5,1.53]],"ltp":2.28,"tv":1.24,"id":71234216},{"trd":[[1.64,129.95],[1.69,33.36]],"batb":[[2,1.66,635.87]],"batl":[[1,1.77,57.43]],"ltp":1.72,"tv":331.32,"id":11674133}],"tv":332.57}]}
{"op":"mcm","clk":"11765876314","pt":1722593142685,"mc":[{"id":"1.231295013","rc":[{"batb":[[0,2.28,33.72],[1,1.43,117.14],[2,1.38,131.58]],"ltp":2.28,"tv":1.24,"id":71234216}]}]}
{"op":"mcm","clk":"11765878526","pt":1722593189224,"mc":[{"id":"1.231295013","rc":[{"batb":[[0,2.3,10],[1,2.28,33.72],[2,1.43,117.14]],"ltp":2.28,"tv":1.24,"id":71234216}]}]}
{"op":"mcm","clk":"11765878813","pt":1722593192844,"mc":[{"id":"1.231295013","rc":[{"batb":[[0,2.28,33.72],[1,1.43,117.14],[2,1.38,131.58]],"ltp":2.28,"tv":1.24,"id":71234216}]}]}
{"op":"mcm","clk":"11765881461","pt":1722593254614,"mc":[{"id":"1.231295013","rc":[{"batb":[[0,2.3,10],[1,2.28,33.72],[2,1.43,117.14]],"ltp":2.28,"tv":1.24,"id":71234216}]}]}
{"op":"mcm","clk":"11765881687","pt":1722593260132,"mc":[{"id":"1.231295013","rc":[{"batb":[[0,2.28,33.72],[1,1.43,117.14],[2,1.38,131.58]],"ltp":2.28,"tv":1.24,"id":71234216}]}]}
{"op":"mcm","clk":"11765885700","pt":1722593344810,"mc":[{"id":"1.231295013","rc":[{"batb":[[0,2.3,10],[1,2.28,33.72],[2,1.43,117.14]],"ltp":2.28,"tv":1.24,"id":71234216}]}]}
{"op":"mcm","clk":"11765885859","pt":1722593348430,"mc":[{"id":"1.231295013","rc":[{"batb":[[0,2.28,33.72],[1,1.43,117.14],[2,1.38,131.58]],"ltp":2.28,"tv":1.24,"id":71234216}]}]}
{"op":"mcm","clk":"11765886425","pt":1722593362260,"mc":[{"id":"1.231295013","rc":[{"batb":[[0,2.3,10],[1,2.28,33.72],[2,1.43,117.14]],"ltp":2.28,"tv":1.24,"id":71234216}]}]}
{"op":"mcm","clk":"11765886607","pt":1722593365781,"mc":[{"id":"1.231295013","rc":[{"batb":[[0,2.28,33.72],[1,1.43,117.14],[2,1.38,131.58]],"ltp":2.28,"tv":1.24,"id":71234216}]}]}
{"op":"mcm","clk":"11765896780","pt":1722593624336,"mc":[{"id":"1.231295013","rc":[{"batb":[[0,2.3,10],[1,2.28,33.72],[2,1.43,117.14]],"ltp":2.28,"tv":1.24,"id":71234216}]}]}
{"op":"mcm","clk":"11765896927","pt":1722593629360,"mc":[{"id":"1.231295013","rc":[{"batb":[[0,2.28,33.72],[1,1.43,117.14],[2,1.38,131.58]],"ltp":2.28,"tv":1.24,"id":71234216}]}]}
{"op":"mcm","clk":"11765898537","pt":1722593686318,"mc":[{"id":"1.231295013","rc":[{"batb":[[0,2.3,10],[1,2.28,33.72],[2,1.43,117.14]],"ltp":2.28,"tv":1.24,"id":71234216}]}]}
{"op":"mcm","clk":"11765898638","pt":1722593689825,"mc":[{"id":"1.231295013","rc":[{"batb":[[0,2.28,33.72],[1,1.43,117.14],[2,1.38,131.58]],"ltp":2.28,"tv":1.24,"id":71234216}]}]}
{"op":"mcm","clk":"11765900575","pt":1722593752221,"mc":[{"id":"1.231295013","rc":[{"batb":[[0,2.3,10],[1,2.28,33.72],[2,1.43,117.14]],"ltp":2.28,"tv":1.24,"id":71234216}]}]}
{"op":"mcm","clk":"11765900688","pt":1722593755813,"mc":[{"id":"1.231295013","rc":[{"batb":[[0,2.28,33.72],[1,1.43,117.14],[2,1.38,131.58]],"ltp":2.28,"tv":1.24,"id":71234216}]}]}
{"op":"mcm","clk":"11765903878","pt":1722593851942,"mc":[{"id":"1.231295013","rc":[{"batb":[[0,2.3,10],[1,2.28,33.72],[2,1.43,117.14]],"ltp":2.28,"tv":1.24,"id":71234216}]}]}
{"op":"mcm","clk":"11765903994","pt":1722593855516,"mc":[{"id":"1.231295013","rc":[{"batb":[[0,2.28,33.72],[1,1.43,117.14],[2,1.38,131.58]],"ltp":2.28,"tv":1.24,"id":71234216}]}]}
{"op":"mcm","clk":"11765904304","pt":1722593866117,"mc":[{"id":"1.231295013","rc":[{"batb":[[0,2.3,10],[1,2.28,33.72],[2,1.43,117.14]],"ltp":2.28,"tv":1.24,"id":71234216}]}]}
{"op":"mcm","clk":"11765904397","pt":1722593869526,"mc":[{"id":"1.231295013","rc":[{"batb":[[0,2.28,33.72],[1,1.43,117.14],[2,1.38,131.58]],"ltp":2.28,"tv":1.24,"id":71234216}]}]}
{"op":"mcm","clk":"11765908141","pt":1722593975202,"mc":[{"id":"1.231295013","rc":[{"batb":[[0,2.3,10],[1,2.28,33.72],[2,1.43,117.14]],"ltp":2.28,"tv":1.24,"id":71234216}]}]}
{"op":"mcm","clk":"11765908360","pt":1722593981209,"mc":[{"id":"1.231295013","rc":[{"batb":[[0,2.28,33.72],[1,1.43,117.14],[2,1.38,131.58]],"ltp":2.28,"tv":1.24,"id":71234216}]}]}
{"op":"mcm","clk":"11765908468","pt":1722593984571,"mc":[{"id":"1.231295013","rc":[{"batb":[[0,2.3,10],[1,2.28,33.72],[2,1.43,117.14]],"ltp":2.28,"tv":1.24,"id":71234216}]}]}
{"op":"mcm","clk":"11765908672","pt":1722593990383,"mc":[{"id":"1.231295013","rc":[{"batb":[[0,2.28,33.72],[1,1.43,117.14],[2,1.38,131.58]],"ltp":2.28,"tv":1.24,"id":71234216}]}]}
{"op":"mcm","clk":"11765910687","pt":1722594045996,"mc":[{"id":"1.231295013","rc":[{"batb":[[0,2.3,10],[1,2.28,33.72],[2,1.43,117.14]],"ltp":2.28,"tv":1.24,"id":71234216}]}]}
{"op":"mcm","clk":"11765910810","pt":1722594049420,"mc":[{"id":"1.231295013","rc":[{"batb":[[0,2.28,33.72],[1,1.43,117.14],[2,1.38,131.58]],"ltp":2.28,"tv":1.24,"id":71234216}]}]}
{"op":"mcm","clk":"11765910986","pt":1722594054610,"mc":[{"id":"1.231295013","rc":[{"batb":[[0,2.3,10],[1,2.28,33.72],[2,1.43,117.14]],"ltp":2.28,"tv":1.24,"id":71234216}]}]}
{"op":"mcm","clk":"11765911100","pt":1722594058396,"mc":[{"id":"1.231295013","rc":[{"batb":[[0,2.28,33.72],[1,1.43,117.14],[2,1.38,131.58]],"ltp":2.28,"tv":1.24,"id":71234216}]}]}
{"op":"mcm","clk":"11765912733","pt":1722594117655,"mc":[{"id":"1.231295013","rc":[{"batb":[[0,2.3,10],[1,2.28,33.72],[2,1.43,117.14]],"ltp":2.28,"tv":1.24,"id":71234216}]}]}
{"op":"mcm","clk":"11765912838","pt":1722594121380,"mc":[{"id":"1.231295013","rc":[{"batb":[[0,2.28,33.72],[1,1.43,117.14],[2,1.38,131.58]],"ltp":2.28,"tv":1.24,"id":71234216}]}]}
{"op":"mcm","clk":"11765934111","pt":1722594838563,"mc":[{"id":"1.231295013","rc":[{"batb":[[0,2.3,10],[1,2.28,33.72],[2,1.43,117.14]],"ltp":2.28,"tv":1.24,"id":71234216}]}]}
{"op":"mcm","clk":"11765934258","pt":1722594841958,"mc":[{"id":"1.231295013","rc":[{"batb":[[0,2.28,33.72],[1,1.43,117.14],[2,1.38,131.58]],"ltp":2.28,"tv":1.24,"id":71234216}]}]}
{"op":"mcm","clk":"11765941175","pt":1722595008879,"mc":[{"id":"1.231295013","rc":[{"batb":[[0,2.3,10],[1,2.28,33.72],[2,1.43,117.14]],"ltp":2.28,"tv":1.24,"id":71234216}]}]}
{"op":"mcm","clk":"11765941317","pt":1722595012257,"mc":[{"id":"1.231295013","rc":[{"batb":[[0,2.28,33.72],[1,1.43,117.14],[2,1.38,131.58]],"ltp":2.28,"tv":1.24,"id":71234216}]}]}
{"op":"mcm","clk":"11765941804","pt":1722595023387,"mc":[{"id":"1.231295013","rc":[{"batb":[[0,2.3,10],[1,2.28,33.72],[2,1.43,117.14]],"ltp":2.28,"tv":1.24,"id":71234216}]}]}
{"op":"mcm","clk":"11765941986","pt":1722595026899,"mc":[{"id":"1.231295013","rc":[{"batb":[[0,2.28,33.72],[1,1.43,117.14],[2,1.38,131.58]],"ltp":2.28,"tv":1.24,"id":71234216}]}]}
{"op":"mcm","clk":"11765942863","pt":1722595045227,"mc":[{"id":"1.231295013","rc":[{"batb":[[0,2.3,10],[1,2.28,33.72],[2,1.43,117.14]],"ltp":2.28,"tv":1.24,"id":71234216}]}]}
{"op":"mcm","clk":"11765943021","pt":1722595048426,"mc":[{"id":"1.231295013","rc":[{"batb":[[0,2.28,33.72],[1,1.43,117.14],[2,1.38,131.58]],"ltp":2.28,"tv":1.24,"id":71234216}]}]}
{"op":"mcm","clk":"11765944364","pt":1722595077357,"mc":[{"id":"1.231295013","rc":[{"batb":[[0,2.3,10],[1,2.28,33.72],[2,1.43,117.14]],"ltp":2.28,"tv":1.24,"id":71234216}]}]}
{"op":"mcm","clk":"11765944516","pt":1722595080769,"mc":[{"id":"1.231295013","rc":[{"batb":[[0,2.28,33.72],[1,1.43,117.14],[2,1.38,131.58]],"ltp":2.28,"tv":1.24,"id":71234216}]}]}
{"op":"mcm","clk":"11765945690","pt":1722595110205,"mc":[{"id":"1.231295013","rc":[{"batb":[[0,2.3,10],[1,2.28,33.72],[2,1.43,117.14]],"ltp":2.28,"tv":1.24,"id":71234216}]}]}
{"op":"mcm","clk":"11765945836","pt":1722595113608,"mc":[{"id":"1.231295013","rc":[{"batb":[[0,2.28,33.72],[1,1.43,117.14],[2,1.38,131.58]],"ltp":2.28,"tv":1.24,"id":71234216}]}]}
{"op":"mcm","clk":"11765948135","pt":1722595163798,"mc":[{"id":"1.231295013","rc":[{"batb":[[0,2.3,10],[1,2.28,33.72],[2,1.43,117.14]],"ltp":2.28,"tv":1.24,"id":71234216}]}]}
{"op":"mcm","clk":"11765948266","pt":1722595167215,"mc":[{"id":"1.231295013","rc":[{"batb":[[0,2.28,33.72],[1,1.43,117.14],[2,1.38,131.58]],"ltp":2.28,"tv":1.24,"id":71234216}]}]}
{"op":"mcm","clk":"11765948729","pt":1722595176701,"mc":[{"id":"1.231295013","rc":[{"batb":[[0,2.3,10],[1,2.28,33.72],[2,1.43,117.14]],"ltp":2.28,"tv":1.24,"id":71234216}]}]}
{"op":"mcm","clk":"11765948886","pt":1722595180314,"mc":[{"id":"1.231295013","rc":[{"batb":[[0,2.28,33.72],[1,1.43,117.14],[2,1.38,131.58]],"ltp":2.28,"tv":1.24,"id":71234216}]}]}
{"op":"mcm","clk":"11765949283","pt":1722595189032,"mc":[{"id":"1.231295013","rc":[{"batb":[[0,2.3,10],[1,2.28,33.72],[2,1.43,117.14]],"ltp":2.28,"tv":1.24,"id":71234216}]}]}
{"op":"mcm","clk":"11765949452","pt":1722595192544,"mc":[{"id":"1.231295013","rc":[{"batb":[[0,2.28,33.72],[1,1.43,117.14],[2,1.38,131.58]],"ltp":2.28,"tv":1.24,"id":71234216}]}]}
{"op":"mcm","clk":"11765969919","pt":1722595411393,"mc":[{"id":"1.231295013","rc":[{"batb":[[0,2.3,10],[1,2.28,33.72],[2,1.43,117.14]],"ltp":2.28,"tv":1.24,"id":71234216}]}]}
{"op":"mcm","clk":"11765970055","pt":1722595414832,"mc":[{"id":"1.231295013","rc":[{"batb":[[0,2.28,33.72],[1,1.43,117.14],[2,1.38,131.58]],"ltp":2.28,"tv":1.24,"id":71234216}]}]}
{"op":"mcm","clk":"11765976056","pt":1722595560892,"mc":[{"id":"1.231295013","rc":[{"batb":[[0,2.3,10],[1,2.28,33.72],[2,1.43,117.14]],"ltp":2.28,"tv":1.24,"id":71234216}]}]}
{"op":"mcm","clk":"11765976174","pt":1722595564278,"mc":[{"id":"1.231295013","rc":[{"batb":[[0,2.28,33.72],[1,1.43,117.14],[2,1.38,131.58]],"ltp":2.28,"tv":1.24,"id":71234216}]}]}
{"op":"mcm","clk":"11765978245","pt":1722595619467,"mc":[{"id":"1.231295013","rc":[{"batb":[[0,2.3,10],[1,2.28,33.72],[2,1.43,117.14]],"ltp":2.28,"tv":1.24,"id":71234216}]}]}
{"op":"mcm","clk":"11765978412","pt":1722595622789,"mc":[{"id":"1.231295013","rc":[{"batb":[[0,2.28,33.72],[1,1.43,117.14],[2,1.38,131.58]],"ltp":2.28,"tv":1.24,"id":71234216}]}]}
{"op":"mcm","clk":"11765980952","pt":1722595695291,"mc":[{"id":"1.231295013","rc":[{"batb":[[0,2.3,10],[1,2.28,33.72],[2,1.43,117.14]],"ltp":2.28,"tv":1.24,"id":71234216}]}]}
{"op":"mcm","clk":"11765981070","pt":1722595698913,"mc":[{"id":"1.231295013","rc":[{"batb":[[0,2.28,33.72],[1,1.43,117.14],[2,1.38,131.58]],"ltp":2.28,"tv":1.24,"id":71234216}]}]}
{"op":"mcm","clk":"11766008781","pt":1722596463095,"mc":[{"id":"1.231295013","rc":[{"batl":[[0,5,1.53]],"ltp":2.28,"tv":1.24,"id":71234216},{"trd":[[1.64,129.96],[1.69,33.36],[1.72,4.42]],"batb":[[0,1.72,57.95],[2,1.66,636]],"batl":[[1,1.77,57.45]],"ltp":1.72,"tv":335.34,"id":11674133}],"tv":336.59}]}
{"op":"mcm","clk":"11766008794","pt":1722596463401,"mc":[{"id":"1.231295013","rc":[{"batb":[[0,2.3,10],[1,2.28,33.72],[2,1.43,117.14]],"ltp":2.28,"tv":1.24,"id":71234216}]}]}
{"op":"mcm","clk":"11766008924","pt":1722596466731,"mc":[{"id":"1.231295013","rc":[{"batb":[[0,2.28,33.72],[1,1.43,117.14],[2,1.38,131.58]],"ltp":2.28,"tv":1.24,"id":71234216},{"batb":[[0,1.72,59.95]],"ltp":1.72,"tv":335.34,"id":11674133}]}]}
{"op":"mcm","clk":"11766010414","pt":1722596511558,"mc":[{"id":"1.231295013","rc":[{"batb":[[0,2.3,10],[1,2.28,33.72],[2,1.43,117.14]],"ltp":2.28,"tv":1.24,"id":71234216}]}]}
{"op":"mcm","clk":"11766010533","pt":1722596515379,"mc":[{"id":"1.231295013","rc":[{"batb":[[0,2.28,33.72],[1,1.43,117.14],[2,1.38,131.58]],"ltp":2.28,"tv":1.24,"id":71234216}]}]}
{"op":"mcm","clk":"11766015685","pt":1722596668574,"mc":[{"id":"1.231295013","rc":[{"batb":[[0,2.3,10],[1,2.28,33.72],[2,1.43,117.14]],"ltp":2.28,"tv":1.24,"id":71234216}]}]}
{"op":"mcm","clk":"11766015796","pt":1722596672147,"mc":[{"id":"1.231295013","rc":[{"batb":[[0,2.28,33.72],[1,1.43,117.14],[2,1.38,131.58]],"ltp":2.28,"tv":1.24,"id":71234216}]}]}
{"op":"mcm","clk":"11766017092","pt":1722596712901,"mc":[{"id":"1.231295013","rc":[{"batb":[[0,2.3,33.2]],"ltp":2.28,"tv":1.24,"id":71234216},{"batb":[[0,1.7,61.66]],"ltp":1.72,"tv":335.34,"id":11674133}]}]}
{"op":"mcm","clk":"11766017107","pt":1722596713414,"mc":[{"id":"1.231295013","rc":[{"batb":[[0,2.32,10],[1,2.3,33.2],[2,1.43,117.14]],"ltp":2.28,"tv":1.24,"id":71234216}]}]}
{"op":"mcm","clk":"11766017231","pt":1722596717107,"mc":[{"id":"1.231295013","rc":[{"batb":[[0,2.3,33.2],[1,1.43,117.14],[2,1.38,131.58]],"ltp":2.28,"tv":1.24,"id":71234216}]}]}
{"op":"mcm","clk":"11766026514","pt":1722596957511,"mc":[{"id":"1.231295013","rc":[{"batb":[[0,2.32,10],[1,2.3,33.2],[2,1.43,117.14]],"ltp":2.28,"tv":1.24,"id":71234216}]}]}
{"op":"mcm","clk":"11766026656","pt":1722596961753,"mc":[{"id":"1.231295013","rc":[{"batb":[[0,2.3,33.2],[1,1.43,117.14],[2,1.38,131.58]],"ltp":2.28,"tv":1.24,"id":71234216}]}]}
{"op":"mcm","clk":"11766034193","pt":1722597146266,"mc":[{"id":"1.231295013","rc":[{"batb":[[0,2.32,10],[1,2.3,33.2],[2,1.43,117.14]],"ltp":2.28,"tv":1.24,"id":71234216}]}]}
{"op":"mcm","clk":"11766034327","pt":1722597149892,"mc":[{"id":"1.231295013","rc":[{"batb":[[0,2.3,33.2],[1,1.43,117.14],[2,1.38,131.58]],"ltp":2.28,"tv":1.24,"id":71234216}]}]}
{"op":"mcm","clk":"11766034835","pt":1722597164403,"mc":[{"id":"1.231295013","rc":[{"batb":[[0,2.32,10],[1,2.3,33.2],[2,1.43,117.14]],"ltp":2.28,"tv":1.24,"id":71234216}]}]}
{"op":"mcm","clk":"11766034960","pt":1722597168692,"mc":[{"id":"1.231295013","rc":[{"batb":[[0,2.3,33.2],[1,1.43,117.14],[2,1.38,131.58]],"ltp":2.28,"tv":1.24,"id":71234216}]}]}
{"op":"mcm","clk":"11766035039","pt":1722597171216,"mc":[{"id":"1.231295013","rc":[{"batb":[[0,2.32,10],[1,2.3,33.2],[2,1.43,117.14]],"ltp":2.28,"tv":1.24,"id":71234216}]}]}
{"op":"mcm","clk":"11766035260","pt":1722597176693,"mc":[{"id":"1.231295013","rc":[{"batb":[[0,2.3,33.2],[1,1.43,117.14],[2,1.38,131.58]],"ltp":2.28,"tv":1.24,"id":71234216}]}]}
{"op":"mcm","clk":"11766039207","pt":1722597271521,"mc":[{"id":"1.231295013","rc":[{"batb":[[0,2.32,10],[1,2.3,33.2],[2,1.43,117.14]],"ltp":2.28,"tv":1.24,"id":71234216}]}]}
{"op":"mcm","clk":"11766039372","pt":1722597274826,"mc":[{"id":"1.231295013","rc":[{"batb":[[0,2.3,33.2],[1,1.43,117.14],[2,1.38,131.58]],"ltp":2.28,"tv":1.24,"id":71234216}]}]}
{"op":"mcm","clk":"11766040209","pt":1722597296056,"mc":[{"id":"1.231295013","rc":[{"trd":[[2.34,7.46]],"batb":[[0,2.32,10],[1,2.3,33.2],[2,1.43,117.14]],"ltp":2.34,"tv":8.71,"id":71234216},{"trd":[[1.74,10.04]],"batl":[[0,1.74,5.01]],"ltp":1.74,"tv":345.38,"id":11674133}],"tv":354.09}]}
{"op":"mcm","clk":"11766040372","pt":1722597299459,"mc":[{"id":"1.231295013","rc":[{"batb":[[0,2.3,33.2],[1,1.43,117.14],[2,1.38,131.58]],"ltp":2.34,"tv":8.71,"id":71234216}]}]}
{"op":"mcm","clk":"11766041390","pt":1722597321679,"mc":[{"id":"1.231295013","rc":[{"batb":[[0,2.32,10],[1,2.3,33.2],[2,1.43,117.14]],"ltp":2.34,"tv":8.71,"id":71234216}]}]}
{"op":"mcm","clk":"11766041542","pt":1722597325084,"mc":[{"id":"1.231295013","rc":[{"batb":[[0,2.3,33.2],[1,1.43,117.14],[2,1.38,131.58]],"ltp":2.34,"tv":8.71,"id":71234216}]}]}
{"op":"mcm","clk":"11766042494","pt":1722597345789,"mc":[{"id":"1.231295013","rc":[{"batb":[[0,2.32,10],[1,2.3,33.2],[2,1.43,117.14]],"ltp":2.34,"tv":8.71,"id":71234216}]}]}
{"op":"mcm","clk":"11766042711","pt":1722597350213,"mc":[{"id":"1.231295013","rc":[{"batb":[[0,2.3,33.2],[1,1.43,117.14],[2,1.38,131.58]],"ltp":2.34,"tv":8.71,"id":71234216}]}]}
{"op":"mcm","clk":"11766043956","pt":1722597375638,"mc":[{"id":"1.231295013","rc":[{"batb":[[0,2.32,10],[1,2.3,33.2],[2,1.43,117.14]],"ltp":2.34,"tv":8.71,"id":71234216}]}]}
{"op":"mcm","clk":"11766044089","pt":1722597378833,"mc":[{"id":"1.231295013","rc":[{"batb":[[0,2.3,33.2],[1,1.43,117.14],[2,1.38,131.58]],"ltp":2.34,"tv":8.71,"id":71234216}]}]}
{"op":"mcm","clk":"11766044919","pt":1722597395677,"mc":[{"id":"1.231295013","rc":[{"batb":[[0,2.32,10],[1,2.3,33.2],[2,1.43,117.14]],"ltp":2.34,"tv":8.71,"id":71234216}]}]}
{"op":"mcm","clk":"11766045068","pt":1722597399083,"mc":[{"id":"1.231295013","rc":[{"batb":[[0,2.3,33.2],[1,1.43,117.14],[2,1.38,131.58]],"ltp":2.34,"tv":8.71,"id":71234216}]}]}
{"op":"mcm","clk":"11766045348","pt":1722597405474,"mc":[{"id":"1.231295013","rc":[{"batb":[[0,2.32,10],[1,2.3,33.2],[2,1.43,117.14]],"ltp":2.34,"tv":8.71,"id":71234216},{"batb":[[2,1.66,86.42]],"ltp":1.74,"tv":345.38,"id":11674133}]}]}
{"op":"mcm","clk":"11766045530","pt":1722597409099,"mc":[{"id":"1.231295013","rc":[{"batb":[[0,2.3,33.2],[1,1.43,117.14],[2,1.38,131.58]],"ltp":2.34,"tv":8.71,"id":71234216}]}]}
{"op":"mcm","clk":"11766060074","pt":1722597782979,"mc":[{"id":"1.231295013","rc":[{"trd":[[2.34,11.19]],"batb":[[0,2.32,10],[1,2.3,33.2],[2,1.43,117.14]],"ltp":2.34,"tv":12.44,"id":71234216},{"trd":[[1.74,15.05]],"batl":[[0,1.77,57.45],[1,1.8,58.45],[2,1.86,1.67]],"ltp":1.74,"tv":350.39,"id":11674133}],"tv":362.83}]}
{"op":"mcm","clk":"11766060200","pt":1722597786357,"mc":[{"id":"1.231295013","rc":[{"batb":[[0,2.3,33.2],[1,1.43,117.14],[2,1.38,131.58]],"ltp":2.34,"tv":12.44,"id":71234216}]}]}
{"op":"mcm","clk":"11766060705","pt":1722597799171,"mc":[{"id":"1.231295013","rc":[{"batb":[[0,2.32,10],[1,2.3,33.2],[2,2.2,8.12]],"ltp":2.34,"tv":12.44,"id":71234216}]}]}
{"op":"mcm","clk":"11766060827","pt":1722597802368,"mc":[{"id":"1.231295013","rc":[{"batb":[[0,2.3,33.2],[1,2.2,8.12],[2,1.43,116.28]],"ltp":2.34,"tv":12.44,"id":71234216}]}]}
{"op":"mcm","clk":"11766061398","pt":1722597820707,"mc":[{"id":"1.231295013","rc":[{"batb":[[0,2.32,10],[1,2.3,33.2],[2,2.2,8.12]],"ltp":2.34,"tv":12.44,"id":71234216}]}]}
{"op":"mcm","clk":"11766061501","pt":1722597824328,"mc":[{"id":"1.231295013","rc":[{"batb":[[0,2.3,33.2],[1,2.2,8.12],[2,1.43,116.28]],"ltp":2.34,"tv":12.44,"id":71234216}]}]}
{"op":"mcm","clk":"11766064232","pt":1722597911739,"mc":[{"id":"1.231295013","rc":[{"batb":[[0,2.32,10],[1,2.3,33.2],[2,1.43,117.14]],"ltp":2.34,"tv":12.44,"id":71234216}]}]}
{"op":"mcm","clk":"11766064412","pt":1722597915332,"mc":[{"id":"1.231295013","rc":[{"batb":[[0,2.3,33.2],[1,1.43,117.14],[2,1.38,131.58]],"ltp":2.34,"tv":12.44,"id":71234216}]}]}
{"op":"mcm","clk":"11766065219","pt":1722597941974,"mc":[{"id":"1.231295013","rc":[{"batb":[[0,2.32,10],[1,2.3,33.2],[2,2.2,8.12]],"ltp":2.34,"tv":12.44,"id":71234216}]}]}
{"op":"mcm","clk":"11766065362","pt":1722597945284,"mc":[{"id":"1.231295013","rc":[{"batb":[[0,2.3,33.2],[1,2.2,8.12],[2,1.43,116.28]],"ltp":2.34,"tv":12.44,"id":71234216}]}]}
{"op":"mcm","clk":"11766065493","pt":1722597950498,"mc":[{"id":"1.231295013","rc":[{"batb":[[0,2.32,10],[1,2.3,33.2],[2,2.2,8.12]],"ltp":2.34,"tv":12.44,"id":71234216}]}]}
{"op":"mcm","clk":"11766065602","pt":1722597954069,"mc":[{"id":"1.231295013","rc":[{"batb":[[0,2.3,33.2],[1,2.2,8.12],[2,1.43,116.28]],"ltp":2.34,"tv":12.44,"id":71234216}]}]}
{"op":"mcm","clk":"11766069406","pt":1722598063966,"mc":[{"id":"1.231295013","rc":[{"batb":[[0,2.32,10],[1,2.3,33.2],[2,2.2,8.12]],"ltp":2.34,"tv":12.44,"id":71234216}]}]}
{"op":"mcm","clk":"11766069550","pt":1722598067326,"mc":[{"id":"1.231295013","rc":[{"batb":[[0,2.3,33.2],[1,2.2,8.12],[2,1.43,116.28]],"ltp":2.34,"tv":12.44,"id":71234216}]}]}
{"op":"mcm","clk":"11766082343","pt":1722598440052,"mc":[{"id":"1.231295013","rc":[{"batl":[[0,1.74,232.34],[1,1.77,57.45],[2,1.8,58.45]],"ltp":1.74,"tv":350.39,"id":11674133}]}]}
{"op":"mcm","clk":"11766082355","pt":1722598440263,"mc":[{"id":"1.231295013","rc":[{"batb":[[0,2.32,10],[1,2.3,33.2],[2,2.2,8.12]],"ltp":2.34,"tv":12.44,"id":71234216}]}]}
{"op":"mcm","clk":"11766082492","pt":1722598443969,"mc":[{"id":"1.231295013","rc":[{"batb":[[0,2.3,33.2],[1,1.43,117.14],[2,1.38,131.58]],"ltp":2.34,"tv":12.44,"id":71234216}]}]}
{"op":"mcm","clk":"11766083597","pt":1722598480105,"mc":[{"id":"1.231295013","rc":[{"batb":[[0,2.32,10],[1,2.3,33.2],[2,1.43,117.14]],"ltp":2.34,"tv":12.44,"id":71234216},{"batl":[[0,1.77,57.45],[1,1.8,58.45],[2,1.86,1.67]],"ltp":1.74,"tv":350.39,"id":11674133}]}]}
{"op":"mcm","clk":"11766083681","pt":1722598483717,"mc":[{"id":"1.231295013","rc":[{"batb":[[0,2.3,33.2],[1,1.43,117.14],[2,1.38,131.58]],"ltp":2.34,"tv":12.44,"id":71234216}]}]}
{"op":"mcm","clk":"11766083702","pt":1722598484389,"mc":[{"id":"1.231295013","rc":[{"batl":[[0,1.72,232.34],[1,1.77,57.45],[2,1.8,58.45]],"ltp":1.74,"tv":350.39,"id":11674133}]}]}
{"op":"mcm","clk":"11766083789","pt":1722598488827,"mc":[{"id":"1.231295013","rc":[{"batb":[[0,2.32,10],[1,2.3,33.2],[2,2.2,8.12]],"ltp":2.34,"tv":12.44,"id":71234216}]}]}
{"op":"mcm","clk":"11766083859","pt":1722598492336,"mc":[{"id":"1.231295013","rc":[{"batb":[[0,2.3,33.2],[1,2.2,8.12],[2,1.43,116.28]],"ltp":2.34,"tv":12.44,"id":71234216}]}]}
{"op":"mcm","clk":"11766083889","pt":1722598493934,"mc":[{"id":"1.231295013","rc":[{"trd":[[2.38,0.27]],"ltp":2.38,"tv":12.71,"id":71234216},{"trd":[[1.72,4.8]],"batl":[[0,1.72,231.96]],"ltp":1.72,"tv":350.77,"id":11674133}],"tv":363.49}]}
{"op":"mcm","clk":"11766084122","pt":1722598502425,"mc":[{"id":"1.231295013","rc":[{"batb":[[0,2.32,10],[1,2.3,33.2],[2,1.43,117.14]],"ltp":2.38,"tv":12.71,"id":71234216}]}]}
{"op":"mcm","clk":"11766084202","pt":1722598505852,"mc":[{"id":"1.231295013","rc":[{"batb":[[0,2.3,33.2],[1,1.43,117.14],[2,1.38,131.58]],"ltp":2.38,"tv":12.71,"id":71234216}]}]}
{"op":"mcm","clk":"11766084356","pt":1722598510969,"mc":[{"id":"1.231295013","rc":[{"batl":[[0,5,1.81]],"ltp":2.38,"tv":12.71,"id":71234216}]}]}
{"op":"mcm","clk":"11766084374","pt":1722598511649,"mc":[{"id":"1.231295013","rc":[{"batb":[[0,2.32,10],[1,2.3,33.2],[2,1.43,117.14]],"ltp":2.38,"tv":12.71,"id":71234216}]}]}
{"op":"mcm","clk":"11766084453","pt":1722598515161,"mc":[{"id":"1.231295013","rc":[{"batb":[[0,2.3,33.2],[1,1.43,117.14],[2,1.38,131.58]],"ltp":2.38,"tv":12.71,"id":71234216}]}]}
{"op":"mcm","clk":"11766084719","pt":1722598524978,"mc":[{"id":"1.231295013","rc":[{"batl":[[0,5,2.36]],"ltp":2.38,"tv":12.71,"id":71234216}]}]}
{"op":"mcm","clk":"11766084736","pt":1722598525962,"mc":[{"id":"1.231295013","rc":[{"batb":[[0,2.32,10],[1,2.3,33.2],[2,1.43,117.14]],"ltp":2.38,"tv":12.71,"id":71234216}]}]}
{"op":"mcm","clk":"11766084813","pt":1722598529777,"mc":[{"id":"1.231295013","rc":[{"batb":[[0,2.3,33.2],[1,1.43,117.14],[2,1.38,131.58]],"ltp":2.38,"tv":12.71,"id":71234216}]}]}
{"op":"mcm","clk":"11766085765","pt":1722598567592,"mc":[{"id":"1.231295013","rc":[{"batl":[[0,1.77,57.45],[1,1.8,58.45],[2,1.86,1.67]],"ltp":1.72,"tv":350.77,"id":11674133}]}]}
{"op":"mcm","clk":"11766085800","pt":1722598568829,"mc":[{"id":"1.231295013","rc":[{"batb":[[0,2.32,10],[1,2.3,33.2],[2,1.43,117.14]],"ltp":2.38,"tv":12.71,"id":71234216},{"trd":[[1.7,123.32]],"batb":[[0,1.68,1.35],[1,1.66,86.42],[2,1.56,549.58]],"batl":[[0,1.7,170.26],[1,1.77,57.45],[2,1.8,58.45]],"ltp":1.7,"tv":474.09,"id":11674133}],"tv":486.81}]}
{"op":"mcm","clk":"11766085880","pt":1722598571888,"mc":[{"id":"1.231295013","rc":[{"batb":[[0,2.3,33.2],[1,1.43,117.14],[2,1.38,131.58]],"ltp":2.38,"tv":12.71,"id":71234216},{"batb":[[1,1.66,151.82]],"ltp":1.7,"tv":474.09,"id":11674133}]}]}
{"op":"mcm","clk":"11766086092","pt":1722598578894,"mc":[{"id":"1.231295013","rc":[{"batl":[[0,4,1.1],[1,5,1.53]],"ltp":2.38,"tv":12.71,"id":71234216}]}]}
{"op":"mcm","clk":"11766086116","pt":1722598579617,"mc":[{"id":"1.231295013","rc":[{"batb":[[0,2.32,12],[1,2.3,33.2],[2,1.43,117.14]],"ltp":2.38,"tv":12.71,"id":71234216}]}]}
{"op":"mcm","clk":"11766086209","pt":1722598581936,"mc":[{"id":"1.231295013","rc":[{"batb":[[0,2.32,10]],"ltp":2.38,"tv":12.71,"id":71234216}]}]}
{"op":"mcm","clk":"11766086253","pt":1722598583022,"mc":[{"id":"1.231295013","rc":[{"batb":[[0,2.3,33.2],[1,1.43,117.14],[2,1.38,131.58]],"ltp":2.38,"tv":12.71,"id":71234216}]}]}
{"op":"mcm","clk":"11766086541","pt":1722598592543,"mc":[{"id":"1.231295013","rc":[{"batb":[[0,2.32,12],[1,2.3,33.2],[2,1.43,117.14]],"batl":[[1,5,1.81]],"ltp":2.38,"tv":12.71,"id":71234216}]}]}
{"op":"mcm","clk":"11766086649","pt":1722598595906,"mc":[{"id":"1.231295013","rc":[{"batb":[[0,2.3,33.2],[1,1.43,117.14],[2,1.38,131.58]],"ltp":2.38,"tv":12.71,"id":71234216}]}]}
{"op":"mcm","clk":"11766086890","pt":1722598605160,"mc":[{"id":"1.231295013","rc":[{"batb":[[0,2.32,12],[1,2.3,33.2],[2,1.43,117.14]],"ltp":2.38,"tv":12.71,"id":71234216}]}]}
{"op":"mcm","clk":"11766086976","pt":1722598607942,"mc":[{"id":"1.231295013","rc":[{"batb":[[0,2.32,10]],"batl":[[2,6.6,0.27]],"ltp":2.38,"tv":12.71,"id":71234216}]}]}
{"op":"mcm","clk":"11766086989","pt":1722598608561,"mc":[{"id":"1.231295013","rc":[{"batb":[[0,2.3,33.2],[1,1.43,117.14],[2,1.38,131.58]],"ltp":2.38,"tv":12.71,"id":71234216}]}]}
{"op":"mcm","clk":"11766087386","pt":1722598621040,"mc":[{"id":"1.231295013","rc":[{"batb":[[0,2.32,12],[1,2.3,33.2],[2,1.43,117.14]],"batl":[[2,8,0.55]],"ltp":2.38,"tv":12.71,"id":71234216}]}]}
{"op":"mcm","clk":"11766087457","pt":1722598623848,"mc":[{"id":"1.231295013","rc":[{"batb":[[0,2.32,10]],"ltp":2.38,"tv":12.71,"id":71234216}]}]}
{"op":"mcm","clk":"11766087486","pt":1722598624884,"mc":[{"id":"1.231295013","rc":[{"batb":[[0,2.3,33.2],[1,1.43,117.14],[2,1.38,131.58]],"ltp":2.38,"tv":12.71,"id":71234216}]}]}
{"op":"mcm","clk":"11766087731","pt":1722598632156,"mc":[{"id":"1.231295013","rc":[{"batb":[[0,2.32,12],[1,2.3,33.2],[2,1.43,117.14]],"ltp":2.38,"tv":12.71,"id":71234216}]}]}
{"op":"mcm","clk":"11766087859","pt":1722598635167,"mc":[{"id":"1.231295013","rc":[{"batb":[[0,2.32,10]],"batl":[[2,10,1.1]],"ltp":2.38,"tv":12.71,"id":71234216}]}]}
{"op":"mcm","clk":"11766087908","pt":1722598635998,"mc":[{"id":"1.231295013","rc":[{"batb":[[0,2.3,33.2],[1,1.43,117.14],[2,1.38,131.58]],"ltp":2.38,"tv":12.71,"id":71234216}]}]}
{"op":"mcm","clk":"11766088000","pt":1722598637962,"mc":[{"id":"1.231295013","rc":[{"batb":[[0,2.34,2],[1,2.3,33.2],[2,1.43,117.14]],"ltp":2.38,"tv":12.71,"id":71234216}]}]}
{"op":"mcm","clk":"11766088018","pt":1722598638582,"mc":[{"id":"1.231295013","rc":[{"batb":[[1,2.32,10],[2,2.3,33.2]],"ltp":2.38,"tv":12.71,"id":71234216}]}]}
{"op":"mcm","clk":"11766088183","pt":1722598644315,"mc":[{"id":"1.231295013","rc":[{"batb":[[0,2.32,10],[1,2.3,33.2],[2,1.43,117.14]],"ltp":2.38,"tv":12.71,"id":71234216}]}]}
{"op":"mcm","clk":"11766088238","pt":1722598646078,"mc":[{"id":"1.231295013","rc":[{"batb":[[0,2.3,33.2],[1,1.43,117.14],[2,1.38,131.58]],"ltp":2.38,"tv":12.71,"id":71234216}]}]}
{"op":"mcm","clk":"11766088248","pt":1722598646495,"mc":[{"id":"1.231295013","rc":[{"batb":[[0,2.34,2],[1,2.3,33.2],[2,1.43,117.14]],"ltp":2.38,"tv":12.71,"id":71234216}]}]}
{"op":"mcm","clk":"11766088373","pt":1722598650382,"mc":[{"id":"1.231295013","rc":[{"batb":[[0,2.3,33.2],[1,1.43,117.14],[2,1.38,131.58]],"ltp":2.38,"tv":12.71,"id":71234216}]}]}
{"op":"mcm","clk":"11766088427","pt":1722598651992,"mc":[{"id":"1.231295013","rc":[{"batb":[[0,2.32,10],[1,2.3,33.2],[2,1.43,117.14]],"ltp":2.38,"tv":12.71,"id":71234216}]}]}
{"op":"mcm","clk":"11766088463","pt":1722598653286,"mc":[{"id":"1.231295013","rc":[{"batb":[[0,2.34,2],[1,2.32,10],[2,2.3,33.2]],"ltp":2.38,"tv":12.71,"id":71234216}]}]}
{"op":"mcm","clk":"11766088553","pt":1722598656521,"mc":[{"id":"1.231295013","rc":[{"batb":[[0,2.3,33.2],[1,1.43,117.14],[2,1.38,131.58]],"ltp":2.38,"tv":12.71,"id":71234216}]}]}
{"op":"mcm","clk":"11766088731","pt":1722598663741,"mc":[{"id":"1.231295013","rc":[{"batb":[[0,2.32,12],[1,2.3,33.2],[2,1.43,117.14]],"ltp":2.38,"tv":12.71,"id":71234216}]}]}
{"op":"mcm","clk":"11766088813","pt":1722598666404,"mc":[{"id":"1.231295013","rc":[{"batb":[[0,2.3,33.2],[1,1.43,117.14],[2,1.38,131.58]],"ltp":2.38,"tv":12.71,"id":71234216}]}]}
{"op":"mcm","clk":"11766088864","pt":1722598668331,"mc":[{"id":"1.231295013","rc":[{"batb":[[0,2.32,2],[1,2.3,33.2],[2,1.43,117.14]],"ltp":2.38,"tv":12.71,"id":71234216}]}]}
{"op":"mcm","clk":"11766088944","pt":1722598671739,"mc":[{"id":"1.231295013","rc":[{"batb":[[0,2.3,33.2],[1,1.43,117.14],[2,1.38,131.58]],"ltp":2.38,"tv":12.71,"id":71234216}]}]}
{"op":"mcm","clk":"11766088988","pt":1722598674026,"mc":[{"id":"1.231295013","rc":[{"batb":[[0,2.32,12],[1,2.3,33.2],[2,1.43,117.14]],"ltp":2.38,"tv":12.71,"id":71234216}]}]}
{"op":"mcm","clk":"11766089114","pt":1722598677748,"mc":[{"id":"1.231295013","rc":[{"batb":[[0,2.32,10]],"ltp":2.38,"tv":12.71,"id":71234216}]}]}
{"op":"mcm","clk":"11766089143","pt":1722598678838,"mc":[{"id":"1.231295013","rc":[{"batb":[[0,2.3,33.2],[1,1.43,117.14],[2,1.38,131.58]],"ltp":2.38,"tv":12.71,"id":71234216}]}]}
{"op":"mcm","clk":"11766089207","pt":1722598681234,"mc":[{"id":"1.231295013","rc":[{"batb":[[0,2.32,12],[1,2.3,33.2],[2,1.43,117.14]],"ltp":2.38,"tv":12.71,"id":71234216}]}]}
{"op":"mcm","clk":"11766089303","pt":1722598683734,"mc":[{"id":"1.231295013","rc":[{"batb":[[0,2.32,10]],"ltp":2.38,"tv":12.71,"id":71234216}]}]}
{"op":"mcm","clk":"11766089329","pt":1722598684769,"mc":[{"id":"1.231295013","rc":[{"batb":[[0,2.3,33.2],[1,1.43,117.14],[2,1.38,131.58]],"ltp":2.38,"tv":12.71,"id":71234216}]}]}
{"op":"mcm","clk":"11766089685","pt":1722598695757,"mc":[{"id":"1.231295013","rc":[{"batb":[[0,2.32,12],[1,2.3,33.2],[2,1.43,117.14]],"ltp":2.38,"tv":12.71,"id":71234216}]}]}
{"op":"mcm","clk":"11766089791","pt":1722598698889,"mc":[{"id":"1.231295013","rc":[{"batb":[[0,2.32,10]],"ltp":2.38,"tv":12.71,"id":71234216}]}]}
{"op":"mcm","clk":"11766089814","pt":1722598699770,"mc":[{"id":"1.231295013","rc":[{"batb":[[0,2.3,33.2],[1,1.43,117.14],[2,1.38,131.58]],"ltp":2.38,"tv":12.71,"id":71234216}]}]}
{"op":"mcm","clk":"11766090057","pt":1722598708875,"mc":[{"id":"1.231295013","rc":[{"batb":[[0,2.32,12],[1,2.3,33.2],[2,1.43,117.14]],"ltp":2.38,"tv":12.71,"id":71234216}]}]}
{"op":"mcm","clk":"11766090182","pt":1722598712299,"mc":[{"id":"1.231295013","rc":[{"batb":[[0,2.32,10]],"ltp":2.38,"tv":12.71,"id":71234216}]}]}
{"op":"mcm","clk":"11766090218","pt":1722598713386,"mc":[{"id":"1.231295013","rc":[{"batb":[[0,2.3,33.2],[1,1.43,117.14],[2,1.38,131.58]],"ltp":2.38,"tv":12.71,"id":71234216}]}]}
{"op":"mcm","clk":"11766090259","pt":1722598714781,"mc":[{"id":"1.231295013","rc":[{"batb":[[0,2.32,2],[1,2.3,33.2],[2,1.43,117.14]],"ltp":2.38,"tv":12.71,"id":71234216}]}]}
{"op":"mcm","clk":"11766090361","pt":1722598718391,"mc":[{"id":"1.231295013","rc":[{"batb":[[0,2.3,33.2],[1,1.43,117.14],[2,1.38,131.58]],"ltp":2.38,"tv":12.71,"id":71234216}]}]}
{"op":"mcm","clk":"11766090410","pt":1722598719791,"mc":[{"id":"1.231295013","rc":[{"batb":[[0,2.32,10],[1,2.3,33.2],[2,1.43,117.14]],"ltp":2.38,"tv":12.71,"id":71234216}]}]}
{"op":"mcm","clk":"11766090444","pt":1722598720988,"mc":[{"id":"1.231295013","rc":[{"batb":[[0,2.34,2],[1,2.32,10],[2,2.3,33.2]],"ltp":2.38,"tv":12.71,"id":71234216}]}]}
{"op":"mcm","clk":"11766090553","pt":1722598724098,"mc":[{"id":"1.231295013","rc":[{"batb":[[0,2.3,33.2],[1,1.43,117.14],[2,1.38,131.58]],"ltp":2.38,"tv":12.71,"id":71234216}]}]}
{"op":"mcm","clk":"11766090931","pt":1722598738308,"mc":[{"id":"1.231295013","rc":[{"batb":[[0,2.32,12],[1,2.3,33.2],[2,1.43,117.14]],"ltp":2.38,"tv":12.71,"id":71234216}]}]}
{"op":"mcm","clk":"11766090992","pt":1722598740835,"mc":[{"id":"1.231295013","rc":[{"batb":[[0,2.32,10]],"ltp":2.38,"tv":12.71,"id":71234216}]}]}
{"op":"mcm","clk":"11766091019","pt":1722598741716,"mc":[{"id":"1.231295013","rc":[{"batb":[[0,2.3,33.2],[1,1.43,117.14],[2,1.38,131.58]],"ltp":2.38,"tv":12.71,"id":71234216}]}]}
{"op":"mcm","clk":"11766091242","pt":1722598751020,"mc":[{"id":"1.231295013","rc":[{"batb":[[0,2.32,12],[1,2.3,33.2],[2,1.43,117.14]],"ltp":2.38,"tv":12.71,"id":71234216}]}]}
{"op":"mcm","clk":"11766091314","pt":1722598753624,"mc":[{"id":"1.231295013","rc":[{"batb":[[0,2.32,10]],"ltp":2.38,"tv":12.71,"id":71234216}]}]}
{"op":"mcm","clk":"11766091356","pt":1722598754764,"mc":[{"id":"1.231295013","rc":[{"batb":[[0,2.3,33.2],[1,1.43,117.14],[2,1.38,131.58]],"ltp":2.38,"tv":12.71,"id":71234216}]}]}
{"op":"mcm","clk":"11766091397","pt":1722598756364,"mc":[{"id":"1.231295013","rc":[{"batb":[[0,2.32,2],[1,2.3,33.2],[2,1.43,117.14]],"ltp":2.38,"tv":12.71,"id":71234216}]}]}
{"op":"mcm","clk":"11766091454","pt":1722598758740,"mc":[{"id":"1.231295013","rc":[{"batb":[[0,2.3,33.2],[1,1.43,117.14],[2,1.38,131.58]],"ltp":2.38,"tv":12.71,"id":71234216}]}]}
{"op":"mcm","clk":"11766091472","pt":1722598759460,"mc":[{"id":"1.231295013","rc":[{"batb":[[0,2.32,10],[1,2.3,33.2],[2,1.43,117.14]],"ltp":2.38,"tv":12.71,"id":71234216}]}]}
{"op":"mcm","clk":"11766091572","pt":1722598763130,"mc":[{"id":"1.231295013","rc":[{"batb":[[0,2.3,33.2],[1,1.43,117.14],[2,1.38,131.58]],"ltp":2.38,"tv":12.71,"id":71234216}]}]}
{"op":"mcm","clk":"11766091583","pt":1722598763336,"mc":[{"id":"1.231295013","rc":[{"batb":[[0,2.32,2],[1,2.3,33.2],[2,1.43,117.14]],"ltp":2.38,"tv":12.71,"id":71234216}]}]}
{"op":"mcm","clk":"11766091661","pt":1722598766072,"mc":[{"id":"1.231295013","rc":[{"batb":[[0,2.3,33.2],[1,1.43,117.14],[2,1.38,131.58]],"ltp":2.38,"tv":12.71,"id":71234216}]}]}
{"op":"mcm","clk":"11766091670","pt":1722598766332,"mc":[{"id":"1.231295013","rc":[{"batb":[[0,2.32,10],[1,2.3,33.2],[2,1.43,117.14]],"ltp":2.38,"tv":12.71,"id":71234216}]}]}
{"op":"mcm","clk":"11766091763","pt":1722598770874,"mc":[{"id":"1.231295013","rc":[{"batb":[[0,2.32,2]],"ltp":2.38,"tv":12.71,"id":71234216}]}]}
{"op":"mcm","clk":"11766091842","pt":1722598773246,"mc":[{"id":"1.231295013","rc":[{"batb":[[0,2.3,33.2],[1,1.43,117.14],[2,1.38,131.58]],"ltp":2.38,"tv":12.71,"id":71234216}]}]}
{"op":"mcm","clk":"11766091875","pt":1722598774476,"mc":[{"id":"1.231295013","rc":[{"batb":[[0,2.32,10],[1,2.3,33.2],[2,1.43,117.14]],"ltp":2.38,"tv":12.71,"id":71234216}]}]}
{"op":"mcm","clk":"11766092007","pt":1722598778439,"mc":[{"id":"1.231295013","rc":[{"batb":[[0,2.3,33.2],[1,1.43,117.14],[2,1.38,131.58]],"ltp":2.38,"tv":12.71,"id":71234216}]}]}
{"op":"mcm","clk":"11766092035","pt":1722598779366,"mc":[{"id":"1.231295013","rc":[{"batb":[[0,2.34,2],[1,2.3,33.2],[2,1.43,117.14]],"ltp":2.38,"tv":12.71,"id":71234216}]}]}
{"op":"mcm","clk":"11766092129","pt":1722598782780,"mc":[{"id":"1.231295013","rc":[{"batb":[[0,2.3,33.2],[1,1.43,117.14],[2,1.38,131.58]],"ltp":2.38,"tv":12.71,"id":71234216}]}]}
{"op":"mcm","clk":"11766092146","pt":1722598783450,"mc":[{"id":"1.231295013","rc":[{"batb":[[0,2.32,10],[1,2.3,33.2],[2,1.43,117.14]],"ltp":2.38,"tv":12.71,"id":71234216}]}]}
{"op":"mcm","clk":"11766092277","pt":1722598787065,"mc":[{"id":"1.231295013","rc":[{"batb":[[0,2.3,33.2],[1,1.43,117.14],[2,1.38,131.58]],"ltp":2.38,"tv":12.71,"id":71234216}]}]}
{"op":"mcm","clk":"11766092285","pt":1722598787476,"mc":[{"id":"1.231295013","rc":[{"batb":[[0,2.32,2],[1,2.3,33.2],[2,1.43,117.14]],"ltp":2.38,"tv":12.71,"id":71234216}]}]}
{"op":"mcm","clk":"11766092367","pt":1722598789904,"mc":[{"id":"1.231295013","rc":[{"batb":[[0,2.3,33.2],[1,1.43,117.14],[2,1.38,131.58]],"ltp":2.38,"tv":12.71,"id":71234216}]}]}
{"op":"mcm","clk":"11766092398","pt":1722598790987,"mc":[{"id":"1.231295013","rc":[{"batb":[[0,2.32,10],[1,2.3,33.2],[2,1.43,117.14]],"ltp":2.38,"tv":12.71,"id":71234216}]}]}
{"op":"mcm","clk":"11766092481","pt":1722598794510,"mc":[{"id":"1.231295013","rc":[{"batb":[[0,2.32,2]],"ltp":2.38,"tv":12.71,"id":71234216}]}]}
{"op":"mcm","clk":"11766092556","pt":1722598797009,"mc":[{"id":"1.231295013","rc":[{"batb":[[0,2.32,10]],"ltp":2.38,"tv":12.71,"id":71234216}]}]}
{"op":"mcm","clk":"11766092689","pt":1722598800606,"mc":[{"id":"1.231295013","rc":[{"batb":[[0,2.32,2]],"ltp":2.38,"tv":12.71,"id":71234216}]}]}
{"op":"mcm","clk":"11766092782","pt":1722598802998,"mc":[{"id":"1.231295013","rc":[{"batb":[[0,2.3,33.2],[1,1.43,117.14],[2,1.38,131.58]],"ltp":2.38,"tv":12.71,"id":71234216}]}]}
{"op":"mcm","clk":"11766092803","pt":1722598803623,"mc":[{"id":"1.231295013","rc":[{"batb":[[0,2.32,10],[1,2.3,33.2],[2,1.43,117.14]],"ltp":2.38,"tv":12.71,"id":71234216}]}]}
{"op":"mcm","clk":"11766092884","pt":1722598807104,"mc":[{"id":"1.231295013","rc":[{"batb":[[0,2.3,33.2],[1,1.43,117.14],[2,1.38,131.58]],"ltp":2.38,"tv":12.71,"id":71234216}]}]}
{"op":"mcm","clk":"11766092897","pt":1722598807729,"mc":[{"id":"1.231295013","rc":[{"batb":[[0,2.32,2],[1,2.3,33.2],[2,1.43,117.14]],"ltp":2.38,"tv":12.71,"id":71234216}]}]}
{"op":"mcm","clk":"11766093016","pt":1722598810132,"mc":[{"id":"1.231295013","rc":[{"batb":[[0,2.3,33.2],[1,1.43,117.14],[2,1.38,131.58]],"ltp":2.38,"tv":12.71,"id":71234216}]}]}
{"op":"mcm","clk":"11766093040","pt":1722598810603,"mc":[{"id":"1.231295013","rc":[{"batb":[[0,2.32,10],[1,2.3,33.2],[2,1.43,117.14]],"ltp":2.38,"tv":12.71,"id":71234216}]}]}
{"op":"mcm","clk":"11766093125","pt":1722598814122,"mc":[{"id":"1.231295013","rc":[{"batb":[[0,2.3,33.2],[1,1.43,117.14],[2,1.38,131.58]],"ltp":2.38,"tv":12.71,"id":71234216}]}]}
{"op":"mcm","clk":"11766093127","pt":1722598814227,"mc":[{"id":"1.231295013","rc":[{"batb":[[0,2.32,2],[1,2.3,33.2],[2,1.43,117.14]],"ltp":2.38,"tv":12.71,"id":71234216}]}]}
{"op":"mcm","clk":"11766093234","pt":1722598816923,"mc":[{"id":"1.231295013","rc":[{"batb":[[0,2.3,33.2],[1,1.43,117.14],[2,1.38,131.58]],"ltp":2.38,"tv":12.71,"id":71234216}]}]}
{"op":"mcm","clk":"11766093255","pt":1722598817697,"mc":[{"id":"1.231295013","rc":[{"batb":[[0,2.32,10],[1,2.3,33.2],[2,1.43,117.14]],"ltp":2.38,"tv":12.71,"id":71234216}]}]}
{"op":"mcm","clk":"11766093300","pt":1722598819513,"mc":[{"id":"1.231295013","rc":[{"batb":[[0,2.34,2],[1,2.32,10],[2,2.3,33.2]],"ltp":2.38,"tv":12.71,"id":71234216}]}]}
{"op":"mcm","clk":"11766093393","pt":1722598822925,"mc":[{"id":"1.231295013","rc":[{"batb":[[1,2.3,33.2],[2,1.43,117.14]],"ltp":2.38,"tv":12.71,"id":71234216}]}]}
{"op":"mcm","clk":"11766093417","pt":1722598823649,"mc":[{"id":"1.231295013","rc":[{"batb":[[0,2.3,33.2],[1,1.43,117.14],[2,1.38,131.58]],"ltp":2.38,"tv":12.71,"id":71234216}]}]}
{"op":"mcm","clk":"11766093493","pt":1722598826043,"mc":[{"id":"1.231295013","rc":[{"batb":[[0,2.32,12],[1,2.3,33.2],[2,1.43,117.14]],"ltp":2.38,"tv":12.71,"id":71234216}]}]}
{"op":"mcm","clk":"11766093605","pt":1722598830116,"mc":[{"id":"1.231295013","rc":[{"batb":[[0,2.32,10]],"ltp":2.38,"tv":12.71,"id":71234216}]}]}
{"op":"mcm","clk":"11766093641","pt":1722598831150,"mc":[{"id":"1.231295013","rc":[{"batb":[[0,2.3,33.2],[1,1.43,117.14],[2,1.38,131.58]],"ltp":2.38,"tv":12.71,"id":71234216}]}]}
{"op":"mcm","clk":"11766093780","pt":1722598835153,"mc":[{"id":"1.231295013","rc":[{"batb":[[0,2.32,12],[1,2.3,33.2],[2,1.43,117.14]],"ltp":2.38,"tv":12.71,"id":71234216}]}]}
{"op":"mcm","clk":"11766093876","pt":1722598837539,"mc":[{"id":"1.231295013","rc":[{"batb":[[0,2.32,10]],"ltp":2.38,"tv":12.71,"id":71234216}]}]}
{"op":"mcm","clk":"11766093906","pt":1722598838573,"mc":[{"id":"1.231295013","rc":[{"batb":[[0,2.3,33.2],[1,1.43,117.14],[2,1.38,131.58]],"ltp":2.38,"tv":12.71,"id":71234216}]}]}
{"op":"mcm","clk":"11766094612","pt":1722598863768,"mc":[{"id":"1.231295013","rc":[{"batb":[[0,2.32,12],[1,2.3,33.2],[2,1.43,117.14]],"ltp":2.38,"tv":12.71,"id":71234216}]}]}
{"op":"mcm","clk":"11766094728","pt":1722598866399,"mc":[{"id":"1.231295013","rc":[{"batb":[[0,2.32,10]],"ltp":2.38,"tv":12.71,"id":71234216}]}]}
{"op":"mcm","clk":"11766094781","pt":1722598867597,"mc":[{"id":"1.231295013","rc":[{"batb":[[0,2.3,33.2],[1,1.43,117.14],[2,1.38,131.58]],"ltp":2.38,"tv":12.71,"id":71234216}]}]}
{"op":"mcm","clk":"11766095052","pt":1722598875795,"mc":[{"id":"1.231295013","rc":[{"batb":[[0,2.32,12],[1,2.3,33.2],[2,1.43,117.14]],"ltp":2.38,"tv":12.71,"id":71234216}]}]}
{"op":"mcm","clk":"11766095181","pt":1722598880420,"mc":[{"id":"1.231295013","rc":[{"batb":[[0,2.32,10]],"ltp":2.38,"tv":12.71,"id":71234216}]}]}
{"op":"mcm","clk":"11766095209","pt":1722598881403,"mc":[{"id":"1.231295013","rc":[{"batb":[[0,2.3,33.2],[1,1.43,117.14],[2,1.38,131.58]],"ltp":2.38,"tv":12.71,"id":71234216}]}]}
{"op":"mcm","clk":"11766095245","pt":1722598882591,"mc":[{"id":"1.231295013","rc":[{"batb":[[0,2.32,2],[1,2.3,33.2],[2,1.43,117.14]],"ltp":2.38,"tv":12.71,"id":71234216}]}]}
{"op":"mcm","clk":"11766095326","pt":1722598885631,"mc":[{"id":"1.231295013","rc":[{"batb":[[0,2.32,10]],"ltp":2.38,"tv":12.71,"id":71234216}]}]}
{"op":"mcm","clk":"11766095404","pt":1722598888928,"mc":[{"id":"1.231295013","rc":[{"batb":[[0,2.3,33.2],[1,1.43,117.14],[2,1.38,131.58]],"ltp":2.38,"tv":12.71,"id":71234216}]}]}
{"op":"mcm","clk":"11766095410","pt":1722598889195,"mc":[{"id":"1.231295013","rc":[{"batb":[[0,2.32,2],[1,2.3,33.2],[2,1.43,117.14]],"ltp":2.38,"tv":12.71,"id":71234216}]}]}
{"op":"mcm","clk":"11766095482","pt":1722598891729,"mc":[{"id":"1.231295013","rc":[{"batb":[[0,2.3,33.2],[1,1.43,117.14],[2,1.38,131.58]],"ltp":2.38,"tv":12.71,"id":71234216}]}]}
{"op":"mcm","clk":"11766095501","pt":1722598892436,"mc":[{"id":"1.231295013","rc":[{"batb":[[0,2.32,10],[1,2.3,33.2],[2,1.43,117.14]],"ltp":2.38,"tv":12.71,"id":71234216}]}]}
{"op":"mcm","clk":"11766095604","pt":1722598896118,"mc":[{"id":"1.231295013","rc":[{"batb":[[0,2.3,33.2],[1,1.43,117.14],[2,1.38,131.58]],"ltp":2.38,"tv":12.71,"id":71234216}]}]}
{"op":"mcm","clk":"11766095640","pt":1722598897082,"mc":[{"id":"1.231295013","rc":[{"batb":[[0,2.32,2],[1,2.3,33.2],[2,1.43,117.14]],"ltp":2.38,"tv":12.71,"id":71234216}]}]}
{"op":"mcm","clk":"11766095731","pt":1722598899838,"mc":[{"id":"1.231295013","rc":[{"batb":[[0,2.3,33.2],[1,1.43,117.14],[2,1.38,131.58]],"ltp":2.38,"tv":12.71,"id":71234216}]}]}
{"op":"mcm","clk":"11766095751","pt":1722598900306,"mc":[{"id":"1.231295013","rc":[{"batb":[[0,2.32,10],[1,2.3,33.2],[2,1.43,117.14]],"ltp":2.38,"tv":12.71,"id":71234216}]}]}
{"op":"mcm","clk":"11766095890","pt":1722598904132,"mc":[{"id":"1.231295013","rc":[{"batb":[[0,2.3,33.2],[1,1.43,117.14],[2,1.38,131.58]],"ltp":2.38,"tv":12.71,"id":71234216}]}]}
{"op":"mcm","clk":"11766095908","pt":1722598904651,"mc":[{"id":"1.231295013","rc":[{"batb":[[0,2.32,2],[1,2.3,33.2],[2,1.43,117.14]],"ltp":2.38,"tv":12.71,"id":71234216}]}]}
{"op":"mcm","clk":"11766095991","pt":1722598906820,"mc":[{"id":"1.231295013","rc":[{"batb":[[0,2.3,33.2],[1,1.43,117.14],[2,1.38,131.58]],"ltp":2.38,"tv":12.71,"id":71234216}]}]}
{"op":"mcm","clk":"11766096000","pt":1722598907235,"mc":[{"id":"1.231295013","rc":[{"batb":[[0,2.32,10],[1,2.3,33.2],[2,1.43,117.14]],"ltp":2.38,"tv":12.71,"id":71234216}]}]}
{"op":"mcm","clk":"11766096116","pt":1722598910853,"mc":[{"id":"1.231295013","rc":[{"batb":[[0,2.32,2]],"ltp":2.38,"tv":12.71,"id":71234216}]}]}
{"op":"mcm","clk":"11766096188","pt":1722598913742,"mc":[{"id":"1.231295013","rc":[{"batb":[[0,2.32,10]],"ltp":2.38,"tv":12.71,"id":71234216}]}]}
{"op":"mcm","clk":"11766096285","pt":1722598917151,"mc":[{"id":"1.231295013","rc":[{"batb":[[0,2.3,33.2],[1,1.43,117.14],[2,1.38,131.58]],"ltp":2.38,"tv":12.71,"id":71234216}]}]}
{"op":"mcm","clk":"11766096293","pt":1722598917561,"mc":[{"id":"1.231295013","rc":[{"batb":[[0,2.32,2],[1,2.3,33.2],[2,1.43,117.14]],"ltp":2.38,"tv":12.71,"id":71234216}]}]}
{"op":"mcm","clk":"11766096355","pt":1722598920055,"mc":[{"id":"1.231295013","rc":[{"batb":[[0,2.32,10]],"ltp":2.38,"tv":12.71,"id":71234216}]}]}
{"op":"mcm","clk":"11766096460","pt":1722598923372,"mc":[{"id":"1.231295013","rc":[{"batb":[[0,2.3,33.2],[1,1.43,117.14],[2,1.38,131.58]],"ltp":2.38,"tv":12.71,"id":71234216}]}]}
{"op":"mcm","clk":"11766096504","pt":1722598924356,"mc":[{"id":"1.231295013","rc":[{"batb":[[0,2.32,2],[1,2.3,33.2],[2,1.43,117.14]],"ltp":2.38,"tv":12.71,"id":71234216}]}]}
{"op":"mcm","clk":"11766096595","pt":1722598927147,"mc":[{"id":"1.231295013","rc":[{"batb":[[0,2.3,33.2],[1,1.43,117.14],[2,1.38,131.58]],"ltp":2.38,"tv":12.71,"id":71234216}]}]}
{"op":"mcm","clk":"11766096631","pt":1722598928487,"mc":[{"id":"1.231295013","rc":[{"batb":[[0,2.32,10],[1,2.3,33.2],[2,1.43,117.14]],"ltp":2.38,"tv":12.71,"id":71234216}]}]}
{"op":"mcm","clk":"11766096770","pt":1722598932376,"mc":[{"id":"1.231295013","rc":[{"batb":[[0,2.3,33.2],[1,1.43,117.14],[2,1.38,131.58]],"ltp":2.38,"tv":12.71,"id":71234216}]}]}
{"op":"mcm","clk":"11766098147","pt":1722598976319,"mc":[{"id":"1.231295013","rc":[{"trd":[[1.68,0.1]],"batb":[[0,1.68,1.3]],"ltp":1.68,"tv":474.19,"id":11674133}],"tv":486.91}]}
{"op":"mcm","clk":"11766101940","pt":1722599096079,"mc":[{"id":"1.231295013","rc":[{"batl":[[0,5,2.63],[1,10,1.1],[2,25,1.05]],"ltp":2.38,"tv":12.71,"id":71234216}]}]}
{"op":"mcm","clk":"11766101943","pt":1722599096182,"mc":[{"id":"1.231295013","rc":[{"batl":[[0,4,1.1],[1,5,1.81],[2,10,1.1]],"ltp":2.38,"tv":12.71,"id":71234216}]}]}
{"op":"mcm","clk":"11766102162","pt":1722599102113,"mc":[{"id":"1.231295013","rc":[{"batl":[[0,5,2.36],[1,10,1.1],[2,25,1.05]],"ltp":2.38,"tv":12.71,"id":71234216}]}]}
{"op":"mcm","clk":"11766102166","pt":1722599102216,"mc":[{"id":"1.231295013","rc":[{"batl":[[0,4,1.1],[1,5,1.81],[2,10,1.1]],"ltp":2.38,"tv":12.71,"id":71234216}]}]}
{"op":"mcm","clk":"11766102252","pt":1722599104092,"mc":[{"id":"1.231295013","rc":[{"batb":[[0,2.4,12.75],[1,2.3,33.2],[2,1.43,117.14]],"ltp":2.38,"tv":12.71,"id":71234216},{"batb":[[1,1.66,178.86]],"ltp":1.68,"tv":474.19,"id":11674133}]}]}
{"op":"mcm","clk":"11766102400","pt":1722599108100,"mc":[{"id":"1.231295013","rc":[{"batl":[[0,5,2.63],[1,10,1.1],[2,25,1.05]],"ltp":2.38,"tv":12.71,"id":71234216}]}]}
{"op":"mcm","clk":"11766102407","pt":1722599108209,"mc":[{"id":"1.231295013","rc":[{"batl":[[0,4,1.1],[1,5,1.81],[2,10,1.1]],"ltp":2.38,"tv":12.71,"id":71234216}]}]}
{"op":"mcm","clk":"11766102648","pt":1722599114084,"mc":[{"id":"1.231295013","rc":[{"batl":[[1,5,1.53]],"ltp":2.38,"tv":12.71,"id":71234216}]}]}
{"op":"mcm","clk":"11766102652","pt":1722599114189,"mc":[{"id":"1.231295013","rc":[{"batl":[[1,5,1.81]],"ltp":2.38,"tv":12.71,"id":71234216}]}]}
{"op":"mcm","clk":"11766102978","pt":1722599124037,"mc":[{"id":"1.231295013","rc":[{"trd":[[1.68,0.2]],"batb":[[0,1.68,1.25]],"ltp":1.68,"tv":474.29,"id":11674133}],"tv":487.01}]}
{"op":"mcm","clk":"11766103949","pt":1722599156064,"mc":[{"id":"1.231295013","rc":[{"batl":[[0,1.77,57.45],[1,1.8,58.45],[2,1.86,1.67]],"ltp":1.68,"tv":474.29,"id":11674133}]}]}
{"op":"mcm","clk":"11766104007","pt":1722599157154,"mc":[{"id":"1.231295013","rc":[{"batb":[[0,2.3,33.2],[1,2.28,13.94]],"ltp":2.38,"tv":12.71,"id":71234216}]}]}
{"op":"mcm","clk":"11766104156","pt":1722599162168,"mc":[{"id":"1.231295013","rc":[{"batb":[[2,2.2,8.12]],"ltp":2.38,"tv":12.71,"id":71234216}]}]}
{"op":"mcm","clk":"11766104343","pt":1722599168071,"mc":[{"id":"1.231295013","rc":[{"batl":[[0,1.7,170.31],[1,1.77,57.45],[2,1.8,58.45]],"ltp":1.68,"tv":474.29,"id":11674133}]}]}
{"op":"mcm","clk":"11766104350","pt":1722599168173,"mc":[{"id":"1.231295013","rc":[{"batb":[[0,2.3,46.92]],"ltp":2.38,"tv":12.71,"id":71234216}]}]}
{"op":"mcm","clk":"11766104410","pt":1722599170189,"mc":[{"id":"1.231295013","rc":[{"batb":[[0,2.4,12.75],[1,2.3,46.92],[2,2.28,13.94]],"ltp":2.38,"tv":12.71,"id":71234216}]}]}
{"op":"mcm","clk":"11766105163","pt":1722599193796,"mc":[{"id":"1.231295013","rc":[{"batl":[[2,1.86,1.67]],"ltp":1.68,"tv":474.29,"id":11674133}]}]}
{"op":"mcm","clk":"11766129797","pt":1722599973232,"mc":[{"id":"1.231295013","rc":[{"batl":[[0,3,2.65],[1,5,2.08]],"ltp":2.38,"tv":12.71,"id":71234216}]}]}
{"op":"mcm","clk":"11766132350","pt":1722600035930,"mc":[{"id":"1.231295013","rc":[{"trd":[[2.42,0.18]],"batb":[[0,2.4,12.75],[1,2.3,46.93],[2,2.28,13.95]],"ltp":2.42,"tv":12.89,"id":71234216},{"trd":[[1.64,129.95],[1.69,33.37],[1.7,123.58]],"batb":[[1,1.66,178.87],[2,1.56,549.45]],"batl":[[0,1.7,170.05],[1,1.77,57.43]],"ltp":1.7,"tv":474.54,"id":11674133}],"tv":487.44}]}
{"op":"mcm","clk":"11766132383","pt":1722600036602,"mc":[{"id":"1.231295013","rc":[{"batb":[[0,2.42,12],[1,2.4,12.75],[2,2.3,46.93]],"ltp":2.42,"tv":12.89,"id":71234216}]}]}
{"op":"mcm","clk":"11766132510","pt":1722600040132,"mc":[{"id":"1.231295013","rc":[{"batb":[[0,2.4,12.75],[1,2.3,46.93],[2,2.28,13.95]],"ltp":2.42,"tv":12.89,"id":71234216}]}]}
{"op":"mcm","clk":"11766132903","pt":1722600050927,"mc":[{"id":"1.231295013","rc":[{"batb":[[0,2.42,12],[1,2.4,12.75],[2,2.3,46.93]],"ltp":2.42,"tv":12.89,"id":71234216}]}]}
{"op":"mcm","clk":"11766133005","pt":1722600053843,"mc":[{"id":"1.231295013","rc":[{"batb":[[0,2.42,10]],"ltp":2.42,"tv":12.89,"id":71234216}]}]}
{"op":"mcm","clk":"11766133046","pt":1722600055040,"mc":[{"id":"1.231295013","rc":[{"batb":[[0,2.4,12.75],[1,2.3,46.93],[2,2.28,13.95]],"ltp":2.42,"tv":12.89,"id":71234216}]}]}
{"op":"mcm","clk":"11766136320","pt":1722600142623,"mc":[{"id":"1.231295013","rc":[{"batb":[[0,2.42,12],[1,2.4,12.75],[2,2.3,46.93]],"batl":[[1,3.2,3.58],[2,5,2.08]],"ltp":2.42,"tv":12.89,"id":71234216}]}]}
{"op":"mcm","clk":"11766136421","pt":1722600145424,"mc":[{"id":"1.231295013","rc":[{"batb":[[0,2.42,10]],"ltp":2.42,"tv":12.89,"id":71234216}]}]}
{"op":"mcm","clk":"11766136459","pt":1722600146355,"mc":[{"id":"1.231295013","rc":[{"batb":[[0,2.4,12.75],[1,2.3,46.93],[2,2.28,13.95]],"ltp":2.42,"tv":12.89,"id":71234216}]}]}
{"op":"mcm","clk":"11766136601","pt":1722600149845,"mc":[{"id":"1.231295013","rc":[{"batb":[[0,2.42,12],[1,2.4,12.75],[2,2.3,46.93]],"batl":[[0,3,6.23],[1,5,2.08],[2,10,1.1]],"ltp":2.42,"tv":12.89,"id":71234216}]}]}
{"op":"mcm","clk":"11766136686","pt":1722600152032,"mc":[{"id":"1.231295013","rc":[{"batb":[[0,2.42,10]],"ltp":2.42,"tv":12.89,"id":71234216}]}]}
{"op":"mcm","clk":"11766136743","pt":1722600153123,"mc":[{"id":"1.231295013","rc":[{"batb":[[0,2.4,12.75],[1,2.3,46.93],[2,2.28,13.95]],"ltp":2.42,"tv":12.89,"id":71234216}]}]}
{"op":"mcm","clk":"11766140069","pt":1722600246040,"mc":[{"id":"1.231295013","rc":[{"trd":[[2.42,1.1]],"batb":[[0,2.42,12],[1,2.4,12.75],[2,2.3,46.93]],"ltp":2.42,"tv":13.81,"id":71234216},{"trd":[[1.7,124.88]],"batl":[[0,1.7,168.75]],"ltp":1.7,"tv":475.84,"id":11674133}],"tv":489.65}]}
{"op":"mcm","clk":"11766140154","pt":1722600248324,"mc":[{"id":"1.231295013","rc":[{"batb":[[0,2.42,10]],"ltp":2.42,"tv":13.81,"id":71234216}]}]}
{"op":"mcm","clk":"11766140187","pt":1722600249461,"mc":[{"id":"1.231295013","rc":[{"batb":[[0,2.4,12.75],[1,2.3,46.93],[2,2.28,13.95]],"ltp":2.42,"tv":13.81,"id":71234216}]}]}
{"op":"mcm","clk":"11766142606","pt":1722600320206,"mc":[{"id":"1.231295013","rc":[{"batb":[[0,2.42,12],[1,2.4,12.75],[2,2.3,46.93]],"ltp":2.42,"tv":13.81,"id":71234216}]}]}
{"op":"mcm","clk":"11766142697","pt":1722600323008,"mc":[{"id":"1.231295013","rc":[{"batb":[[0,2.42,10]],"ltp":2.42,"tv":13.81,"id":71234216}]}]}
{"op":"mcm","clk":"11766142721","pt":1722600324042,"mc":[{"id":"1.231295013","rc":[{"batb":[[0,2.4,12.75],[1,2.3,46.93],[2,2.28,13.95]],"ltp":2.42,"tv":13.81,"id":71234216}]}]}
{"op":"mcm","clk":"11766145571","pt":1722600415531,"mc":[{"id":"1.231295013","rc":[{"batb":[[0,2.42,12],[1,2.4,12.75],[2,2.3,46.93]],"ltp":2.42,"tv":13.81,"id":71234216}]}]}
{"op":"mcm","clk":"11766145755","pt":1722600421280,"mc":[{"id":"1.231295013","rc":[{"batb":[[0,2.4,12.75],[1,2.3,46.93],[2,2.28,13.95]],"ltp":2.42,"tv":13.81,"id":71234216}]}]}
{"op":"mcm","clk":"11766145831","pt":1722600423785,"mc":[{"id":"1.231295013","rc":[{"batb":[[0,2.42,12],[1,2.4,12.75],[2,2.3,46.93]],"ltp":2.42,"tv":13.81,"id":71234216}]}]}
{"op":"mcm","clk":"11766145968","pt":1722600428543,"mc":[{"id":"1.231295013","rc":[{"batb":[[0,2.42,10]],"ltp":2.42,"tv":13.81,"id":71234216}]}]}
{"op":"mcm","clk":"11766145997","pt":1722600429639,"mc":[{"id":"1.231295013","rc":[{"batb":[[0,2.4,12.75],[1,2.3,46.93],[2,2.28,13.95]],"ltp":2.42,"tv":13.81,"id":71234216}]}]}
{"op":"mcm","clk":"11766146105","pt":1722600432654,"mc":[{"id":"1.231295013","rc":[{"batb":[[0,2.44,12],[1,2.4,12.75],[2,2.3,46.93]],"ltp":2.42,"tv":13.81,"id":71234216}]}]}
{"op":"mcm","clk":"11766146152","pt":1722600433471,"mc":[{"id":"1.231295013","rc":[{"batb":[[1,2.42,12.57],[2,2.4,12.75]],"ltp":2.42,"tv":13.81,"id":71234216}]}]}
{"op":"mcm","clk":"11766146338","pt":1722600438092,"mc":[{"id":"1.231295013","rc":[{"batb":[[0,2.44,10]],"ltp":2.42,"tv":13.81,"id":71234216}]}]}
{"op":"mcm","clk":"11766146382","pt":1722600439177,"mc":[{"id":"1.231295013","rc":[{"batb":[[0,2.42,12.57],[1,2.4,12.75],[2,2.3,46.93]],"ltp":2.42,"tv":13.81,"id":71234216}]}]}
{"op":"mcm","clk":"11766146444","pt":1722600440685,"mc":[{"id":"1.231295013","rc":[{"batb":[[0,2.44,2],[1,2.42,12.57],[2,2.4,12.75]],"ltp":2.42,"tv":13.81,"id":71234216}]}]}
{"op":"mcm","clk":"11766146535","pt":1722600443693,"mc":[{"id":"1.231295013","rc":[{"batb":[[0,2.42,12.57],[1,2.4,12.75],[2,2.3,46.93]],"ltp":2.42,"tv":13.81,"id":71234216}]}]}
{"op":"mcm","clk":"11766146574","pt":1722600445092,"mc":[{"id":"1.231295013","rc":[{"batb":[[0,2.44,10],[1,2.42,12.57],[2,2.4,12.75]],"ltp":2.42,"tv":13.81,"id":71234216}]}]}
{"op":"mcm","clk":"11766146619","pt":1722600446180,"mc":[{"id":"1.231295013","rc":[{"batb":[[0,2.46,2],[1,2.44,10],[2,2.42,12.57]],"ltp":2.42,"tv":13.81,"id":71234216}]}]}
{"op":"mcm","clk":"11766146738","pt":1722600449366,"mc":[{"id":"1.231295013","rc":[{"batb":[[0,2.42,12.57],[1,2.4,12.75],[2,2.3,46.93]],"ltp":2.42,"tv":13.81,"id":71234216}]}]}
{"op":"mcm","clk":"11766146816","pt":1722600451700,"mc":[{"id":"1.231295013","rc":[{"batb":[[0,2.44,12],[1,2.42,12.57],[2,2.4,12.75]],"ltp":2.42,"tv":13.81,"id":71234216}]}]}
{"op":"mcm","clk":"11766146895","pt":1722600454216,"mc":[{"id":"1.231295013","rc":[{"batb":[[0,2.44,10]],"ltp":2.42,"tv":13.81,"id":71234216}]}]}
{"op":"mcm","clk":"11766146927","pt":1722600455286,"mc":[{"id":"1.231295013","rc":[{"batb":[[0,2.42,12.57],[1,2.4,12.75],[2,2.3,46.93]],"ltp":2.42,"tv":13.81,"id":71234216}]}]}
{"op":"mcm","clk":"11766148070","pt":1722600487110,"mc":[{"id":"1.231295013","rc":[{"batb":[[0,2.44,12],[1,2.42,12.57],[2,2.4,12.75]],"ltp":2.42,"tv":13.81,"id":71234216}]}]}
{"op":"mcm","clk":"11766148161","pt":1722600489848,"mc":[{"id":"1.231295013","rc":[{"batb":[[0,2.44,10]],"ltp":2.42,"tv":13.81,"id":71234216}]}]}
{"op":"mcm","clk":"11766148192","pt":1722600490729,"mc":[{"id":"1.231295013","rc":[{"batb":[[0,2.42,12.57],[1,2.4,12.75],[2,2.3,46.93]],"ltp":2.42,"tv":13.81,"id":71234216}]}]}
{"op":"mcm","clk":"11766150781","pt":1722600582650,"mc":[{"id":"1.231295013","rc":[{"batb":[[0,2.44,12],[1,2.42,12.57],[2,2.4,12.75]],"ltp":2.42,"tv":13.81,"id":71234216}]}]}
{"op":"mcm","clk":"11766150892","pt":1722600585235,"mc":[{"id":"1.231295013","rc":[{"batb":[[0,2.44,10]],"ltp":2.42,"tv":13.81,"id":71234216}]}]}
{"op":"mcm","clk":"11766150929","pt":1722600586176,"mc":[{"id":"1.231295013","rc":[{"batb":[[0,2.42,12.57],[1,2.4,12.75],[2,2.3,46.93]],"ltp":2.42,"tv":13.81,"id":71234216}]}]}
{"op":"mcm","clk":"11766151993","pt":1722600620688,"mc":[{"id":"1.231295013","rc":[{"batb":[[0,2.44,12],[1,2.42,12.57],[2,2.4,12.75]],"ltp":2.42,"tv":13.81,"id":71234216}]}]}
{"op":"mcm","clk":"11766152066","pt":1722600624110,"mc":[{"id":"1.231295013","rc":[{"batb":[[0,2.42,12.57],[1,2.4,12.75],[2,2.3,46.93]],"ltp":2.42,"tv":13.81,"id":71234216}]}]}
{"op":"mcm","clk":"11766155269","pt":1722600746675,"mc":[{"id":"1.231295013","rc":[{"batb":[[0,2.44,12],[1,2.42,12.57],[2,2.4,12.75]],"ltp":2.42,"tv":13.81,"id":71234216}]}]}
{"op":"mcm","clk":"11766155356","pt":1722600749370,"mc":[{"id":"1.231295013","rc":[{"batb":[[0,2.44,10]],"ltp":2.42,"tv":13.81,"id":71234216}]}]}
{"op":"mcm","clk":"11766155388","pt":1722600750492,"mc":[{"id":"1.231295013","rc":[{"batb":[[0,2.42,12.57],[1,2.4,12.75],[2,2.3,46.93]],"ltp":2.42,"tv":13.81,"id":71234216}]}]}
{"op":"mcm","clk":"11766155432","pt":1722600751676,"mc":[{"id":"1.231295013","rc":[{"batb":[[0,2.44,2],[1,2.42,12.57],[2,2.4,12.75]],"ltp":2.42,"tv":13.81,"id":71234216}]}]}
{"op":"mcm","clk":"11766155540","pt":1722600754993,"mc":[{"id":"1.231295013","rc":[{"batb":[[0,2.42,12.57],[1,2.4,12.75],[2,2.3,46.93]],"ltp":2.42,"tv":13.81,"id":71234216}]}]}
{"op":"mcm","clk":"11766155554","pt":1722600755467,"mc":[{"id":"1.231295013","rc":[{"batb":[[0,2.44,10],[1,2.42,12.57],[2,2.4,12.75]],"ltp":2.42,"tv":13.81,"id":71234216}]}]}
{"op":"mcm","clk":"11766155672","pt":1722600760082,"mc":[{"id":"1.231295013","rc":[{"batb":[[0,2.44,2]],"ltp":2.42,"tv":13.81,"id":71234216}]}]}
{"op":"mcm","clk":"11766155763","pt":1722600762576,"mc":[{"id":"1.231295013","rc":[{"batb":[[0,2.42,12.57],[1,2.4,12.75],[2,2.3,46.93]],"ltp":2.42,"tv":13.81,"id":71234216}]}]}
{"op":"mcm","clk":"11766155792","pt":1722600763798,"mc":[{"id":"1.231295013","rc":[{"batb":[[0,2.44,10],[1,2.42,12.57],[2,2.4,12.75]],"ltp":2.42,"tv":13.81,"id":71234216}]}]}
{"op":"mcm","clk":"11766155898","pt":1722600767791,"mc":[{"id":"1.231295013","rc":[{"batb":[[0,2.44,2]],"ltp":2.42,"tv":13.81,"id":71234216}]}]}
{"op":"mcm","clk":"11766155974","pt":1722600770693,"mc":[{"id":"1.231295013","rc":[{"batb":[[0,2.44,10]],"ltp":2.42,"tv":13.81,"id":71234216}]}]}
{"op":"mcm","clk":"11766163069","pt":1722600775090,"mc":[{"id":"1.231295013","rc":[{"batb":[[0,2.44,2]],"ltp":2.42,"tv":13.81,"id":71234216}]}]}
{"op":"mcm","clk":"11766166742","pt":1722600777317,"mc":[{"id":"1.231295013","rc":[{"batb":[[0,2.42,12.57],[1,2.4,12.75],[2,2.3,46.93]],"ltp":2.42,"tv":13.81,"id":71234216}]}]}
{"op":"mcm","clk":"11766166788","pt":1722600778616,"mc":[{"id":"1.231295013","rc":[{"batb":[[0,2.44,10],[1,2.42,12.57],[2,2.4,12.75]],"ltp":2.42,"tv":13.81,"id":71234216}]}]}
{"op":"mcm","clk":"11766166905","pt":1722600783103,"mc":[{"id":"1.231295013","rc":[{"batb":[[0,2.44,2]],"ltp":2.42,"tv":13.81,"id":71234216}]}]}
{"op":"mcm","clk":"11766166958","pt":1722600785621,"mc":[{"id":"1.231295013","rc":[{"batb":[[0,2.42,12.57],[1,2.4,12.75],[2,2.3,46.93]],"ltp":2.42,"tv":13.81,"id":71234216}]}]}
{"op":"mcm","clk":"11766166990","pt":1722600787122,"mc":[{"id":"1.231295013","rc":[{"batb":[[0,2.44,10],[1,2.42,12.57],[2,2.4,12.75]],"ltp":2.42,"tv":13.81,"id":71234216}]}]}
{"op":"mcm","clk":"11766167014","pt":1722600788226,"mc":[{"id":"1.231295013","rc":[{"batb":[[0,2.46,2],[1,2.44,10],[2,2.42,12.57]],"ltp":2.42,"tv":13.81,"id":71234216}]}]}
{"op":"mcm","clk":"11766167086","pt":1722600791318,"mc":[{"id":"1.231295013","rc":[{"batb":[[0,2.42,12.57],[1,2.4,12.75],[2,2.3,46.93]],"ltp":2.42,"tv":13.81,"id":71234216}]}]}
{"op":"mcm","clk":"11766167306","pt":1722600799223,"mc":[{"id":"1.231295013","rc":[{"batl":[[0,2.46,87.25],[1,3,6.23],[2,5,2.08]],"ltp":2.42,"tv":13.81,"id":71234216}]}]}
{"op":"mcm","clk":"11766167387","pt":1722600801756,"mc":[{"id":"1.231295013","rc":[{"batb":[[1,1.67,26.64],[2,1.66,178.87]],"ltp":1.7,"tv":475.84,"id":11674133}]}]}
{"op":"mcm","clk":"11766167436","pt":1722600804045,"mc":[{"id":"1.231295013","rc":[{"batl":[[0,3,6.23],[1,5,2.08],[2,10,1.1]],"ltp":2.42,"tv":13.81,"id":71234216}]}]}
{"op":"mcm","clk":"11766167439","pt":1722600804242,"mc":[{"id":"1.231295013","rc":[{"batb":[[0,2.44,12],[1,2.42,12.57],[2,2.4,12.75]],"ltp":2.42,"tv":13.81,"id":71234216},{"batb":[[1,1.66,178.87],[2,1.56,549.45]],"ltp":1.7,"tv":475.84,"id":11674133}]}]}
{"op":"mcm","clk":"11766167513","pt":1722600806728,"mc":[{"id":"1.231295013","rc":[{"batb":[[0,2.44,10]],"ltp":2.42,"tv":13.81,"id":71234216}]}]}
{"op":"mcm","clk":"11766167543","pt":1722600807610,"mc":[{"id":"1.231295013","rc":[{"batb":[[0,2.42,12.57],[1,2.4,12.75],[2,2.3,46.93]],"ltp":2.42,"tv":13.81,"id":71234216}]}]}
{"op":"mcm","clk":"11766167585","pt":1722600809041,"mc":[{"id":"1.231295013","rc":[{"batb":[[0,2.44,2],[1,2.42,12.57],[2,2.4,12.75]],"ltp":2.42,"tv":13.81,"id":71234216}]}]}
{"op":"mcm","clk":"11766167673","pt":1722600811947,"mc":[{"id":"1.231295013","rc":[{"batb":[[0,2.42,12.57],[1,2.4,12.75],[2,2.3,46.93]],"ltp":2.42,"tv":13.81,"id":71234216}]}]}
{"op":"mcm","clk":"11766167698","pt":1722600813132,"mc":[{"id":"1.231295013","rc":[{"batb":[[0,2.44,10],[1,2.42,12.57],[2,2.4,12.75]],"ltp":2.42,"tv":13.81,"id":71234216}]}]}
{"op":"mcm","clk":"11766167793","pt":1722600817043,"mc":[{"id":"1.231295013","rc":[{"batb":[[0,2.42,12.57],[1,2.4,12.75],[2,2.3,46.93]],"ltp":2.42,"tv":13.81,"id":71234216}]}]}
{"op":"mcm","clk":"11766167797","pt":1722600817350,"mc":[{"id":"1.231295013","rc":[{"batb":[[0,2.44,2],[1,2.42,12.57],[2,2.4,12.75]],"ltp":2.42,"tv":13.81,"id":71234216}]}]}
{"op":"mcm","clk":"11766167843","pt":1722600819940,"mc":[{"id":"1.231295013","rc":[{"batb":[[0,2.42,12.57],[1,2.4,12.75],[2,2.3,46.93]],"ltp":2.42,"tv":13.81,"id":71234216}]}]}
{"op":"mcm","clk":"11766167850","pt":1722600820246,"mc":[{"id":"1.231295013","rc":[{"batb":[[0,2.44,10],[1,2.42,12.57],[2,2.4,12.75]],"ltp":2.42,"tv":13.81,"id":71234216}]}]}
{"op":"mcm","clk":"11766167922","pt":1722600823758,"mc":[{"id":"1.231295013","rc":[{"batb":[[0,2.42,12.57],[1,2.4,12.75],[2,2.3,46.93]],"ltp":2.42,"tv":13.81,"id":71234216}]}]}
{"op":"mcm","clk":"11766167943","pt":1722600824644,"mc":[{"id":"1.231295013","rc":[{"batb":[[0,2.44,2],[1,2.42,12.57],[2,2.4,12.75]],"ltp":2.42,"tv":13.81,"id":71234216}]}]}
{"op":"mcm","clk":"11766168009","pt":1722600827539,"mc":[{"id":"1.231295013","rc":[{"batb":[[0,2.42,12.57],[1,2.4,12.75],[2,2.3,46.93]],"ltp":2.42,"tv":13.81,"id":71234216}]}]}
{"op":"mcm","clk":"11766168047","pt":1722600829853,"mc":[{"id":"1.231295013","rc":[{"batb":[[0,2.44,12],[1,2.42,12.57],[2,2.4,12.75]],"ltp":2.42,"tv":13.81,"id":71234216}]}]}
{"op":"mcm","clk":"11766168130","pt":1722600833734,"mc":[{"id":"1.231295013","rc":[{"batb":[[0,2.44,10]],"ltp":2.42,"tv":13.81,"id":71234216}]}]}
{"op":"mcm","clk":"11766168143","pt":1722600834558,"mc":[{"id":"1.231295013","rc":[{"batb":[[0,2.42,12.57],[1,2.4,12.75],[2,2.3,46.93]],"ltp":2.42,"tv":13.81,"id":71234216}]}]}
{"op":"mcm","clk":"11766170052","pt":1722600901042,"mc":[{"id":"1.231295013","rc":[{"batb":[[0,2.44,12],[1,2.42,12.57],[2,2.4,12.75]],"ltp":2.42,"tv":13.81,"id":71234216}]}]}
{"op":"mcm","clk":"11766170183","pt":1722600905145,"mc":[{"id":"1.231295013","rc":[{"batb":[[0,2.42,12.57],[1,2.4,12.75],[2,2.3,46.93]],"ltp":2.42,"tv":13.81,"id":71234216}]}]}
{"op":"mcm","clk":"11766170330","pt":1722600911219,"mc":[{"id":"1.231295013","rc":[{"batb":[[0,2.44,12],[1,2.42,12.57],[2,2.4,12.75]],"ltp":2.42,"tv":13.81,"id":71234216}]}]}
{"op":"mcm","clk":"11766170410","pt":1722600913645,"mc":[{"id":"1.231295013","rc":[{"batb":[[0,2.44,10]],"ltp":2.42,"tv":13.81,"id":71234216}]}]}
{"op":"mcm","clk":"11766170445","pt":1722600914532,"mc":[{"id":"1.231295013","rc":[{"batb":[[0,2.42,12.57],[1,2.4,12.75],[2,2.3,46.93]],"ltp":2.42,"tv":13.81,"id":71234216}]}]}
{"op":"mcm","clk":"11766170491","pt":1722600915982,"mc":[{"id":"1.231295013","rc":[{"batb":[[0,2.44,2],[1,2.42,12.57],[2,2.4,12.75]],"ltp":2.42,"tv":13.81,"id":71234216}]}]}
{"op":"mcm","clk":"11766170666","pt":1722600920924,"mc":[{"id":"1.231295013","rc":[{"batb":[[0,2.42,12.57],[1,2.4,12.75],[2,2.3,46.93]],"ltp":2.42,"tv":13.81,"id":71234216}]}]}
{"op":"mcm","clk":"11766170742","pt":1722600923155,"mc":[{"id":"1.231295013","rc":[{"batb":[[0,2.44,12],[1,2.42,12.57],[2,2.4,12.75]],"ltp":2.42,"tv":13.81,"id":71234216}]}]}
{"op":"mcm","clk":"11766170878","pt":1722600926740,"mc":[{"id":"1.231295013","rc":[{"batb":[[0,2.44,10]],"ltp":2.42,"tv":13.81,"id":71234216}]}]}
{"op":"mcm","clk":"11766170918","pt":1722600927872,"mc":[{"id":"1.231295013","rc":[{"batb":[[0,2.42,12.57],[1,2.4,12.75],[2,2.3,46.93]],"ltp":2.42,"tv":13.81,"id":71234216}]}]}
{"op":"mcm","clk":"11766172307","pt":1722600962848,"mc":[{"id":"1.231295013","rc":[{"batb":[[0,2.44,12],[1,2.42,12.57],[2,2.4,12.75]],"ltp":2.42,"tv":13.81,"id":71234216}]}]}
{"op":"mcm","clk":"11766172418","pt":1722600965799,"mc":[{"id":"1.231295013","rc":[{"batb":[[0,2.44,10]],"ltp":2.42,"tv":13.81,"id":71234216}]}]}
{"op":"mcm","clk":"11766172458","pt":1722600966679,"mc":[{"id":"1.231295013","rc":[{"batb":[[0,2.42,12.57],[1,2.4,12.75],[2,2.3,46.93]],"ltp":2.42,"tv":13.81,"id":71234216}]}]}
{"op":"mcm","clk":"11766172664","pt":1722600970988,"mc":[{"id":"1.231295013","rc":[{"batb":[[0,2.44,12],[1,2.42,12.57],[2,2.4,12.75]],"ltp":2.42,"tv":13.81,"id":71234216}]}]}
{"op":"mcm","clk":"11766172768","pt":1722600973680,"mc":[{"id":"1.231295013","rc":[{"batb":[[0,2.44,10]],"ltp":2.42,"tv":13.81,"id":71234216}]}]}
{"op":"mcm","clk":"11766172806","pt":1722600974611,"mc":[{"id":"1.231295013","rc":[{"batb":[[0,2.42,12.57],[1,2.4,12.75],[2,2.3,46.93]],"ltp":2.42,"tv":13.81,"id":71234216}]}]}
{"op":"mcm","clk":"11766181412","pt":1722601216758,"mc":[{"id":"1.231295013","rc":[{"batb":[[0,2.44,12],[1,2.42,12.57],[2,2.4,12.75]],"ltp":2.42,"tv":13.81,"id":71234216}]}]}
{"op":"mcm","clk":"11766181588","pt":1722601220673,"mc":[{"id":"1.231295013","rc":[{"batb":[[0,2.42,12.57],[1,2.4,12.75],[2,2.3,46.93]],"ltp":2.42,"tv":13.81,"id":71234216}]}]}
{"op":"mcm","clk":"11766183948","pt":1722601287553,"mc":[{"id":"1.231295013","rc":[{"batb":[[0,2.44,12],[1,2.42,12.57],[2,2.4,12.75]],"ltp":2.42,"tv":13.81,"id":71234216}]}]}
{"op":"mcm","clk":"11766184060","pt":1722601290865,"mc":[{"id":"1.231295013","rc":[{"batb":[[0,2.42,12.57],[1,2.4,12.75],[2,2.3,46.93]],"ltp":2.42,"tv":13.81,"id":71234216}]}]}
{"op":"mcm","clk":"11766192375","pt":1722601532128,"mc":[{"id":"1.231295013","rc":[{"batb":[[0,2.44,12],[1,2.42,12.57],[2,2.4,12.75]],"ltp":2.42,"tv":13.81,"id":71234216}]}]}
{"op":"mcm","clk":"11766192501","pt":1722601535098,"mc":[{"id":"1.231295013","rc":[{"batb":[[0,2.44,10]],"ltp":2.42,"tv":13.81,"id":71234216}]}]}
{"op":"mcm","clk":"11766192544","pt":1722601536026,"mc":[{"id":"1.231295013","rc":[{"batb":[[0,2.42,12.57],[1,2.4,12.75],[2,2.3,46.93]],"ltp":2.42,"tv":13.81,"id":71234216}]}]}
{"op":"mcm","clk":"11766195418","pt":1722601627703,"mc":[{"id":"1.231295013","rc":[{"batb":[[0,2.44,12],[1,2.42,12.57],[2,2.4,12.75]],"ltp":2.42,"tv":13.81,"id":71234216}]}]}
{"op":"mcm","clk":"11766195486","pt":1722601630427,"mc":[{"id":"1.231295013","rc":[{"batb":[[0,2.44,10]],"ltp":2.42,"tv":13.81,"id":71234216}]}]}
{"op":"mcm","clk":"11766195521","pt":1722601631407,"mc":[{"id":"1.231295013","rc":[{"batb":[[0,2.42,12.57],[1,2.4,12.75],[2,2.3,46.93]],"ltp":2.42,"tv":13.81,"id":71234216}]}]}
{"op":"mcm","clk":"11766196918","pt":1722601681085,"mc":[{"id":"1.231295013","rc":[{"batb":[[0,2.44,12],[1,2.42,12.57],[2,2.4,12.75]],"ltp":2.42,"tv":13.81,"id":71234216}]}]}
{"op":"mcm","clk":"11766197089","pt":1722601686572,"mc":[{"id":"1.231295013","rc":[{"batb":[[0,2.44,10]],"ltp":2.42,"tv":13.81,"id":71234216}]}]}
{"op":"mcm","clk":"11766197123","pt":1722601687700,"mc":[{"id":"1.231295013","rc":[{"batb":[[0,2.42,12.57],[1,2.4,12.75],[2,2.3,46.93]],"ltp":2.42,"tv":13.81,"id":71234216}]}]}
{"op":"mcm","clk":"11766197172","pt":1722601689198,"mc":[{"id":"1.231295013","rc":[{"batb":[[0,2.46,2],[1,2.42,12.57],[2,2.4,12.75]],"ltp":2.42,"tv":13.81,"id":71234216}]}]}
{"op":"mcm","clk":"11766197205","pt":1722601690386,"mc":[{"id":"1.231295013","rc":[{"batb":[[1,2.44,10],[2,2.42,12.57]],"ltp":2.42,"tv":13.81,"id":71234216}]}]}
{"op":"mcm","clk":"11766197319","pt":1722601693799,"mc":[{"id":"1.231295013","rc":[{"batb":[[0,2.44,10],[1,2.42,12.57],[2,2.4,12.75]],"ltp":2.42,"tv":13.81,"id":71234216}]}]}
{"op":"mcm","clk":"11766197391","pt":1722601696172,"mc":[{"id":"1.231295013","rc":[{"batb":[[0,2.46,2]],"ltp":2.42,"tv":13.81,"id":71234216}]}]}
{"op":"mcm","clk":"11766197512","pt":1722601699602,"mc":[{"id":"1.231295013","rc":[{"batb":[[0,2.42,12.57],[1,2.4,12.75],[2,2.3,46.93]],"ltp":2.42,"tv":13.81,"id":71234216}]}]}
{"op":"mcm","clk":"11766197561","pt":1722601701194,"mc":[{"id":"1.231295013","rc":[{"batb":[[0,2.44,10],[1,2.42,12.57],[2,2.4,12.75]],"ltp":2.42,"tv":13.81,"id":71234216}]}]}
{"op":"mcm","clk":"11766197601","pt":1722601702281,"mc":[{"id":"1.231295013","rc":[{"batb":[[0,2.46,2],[1,2.44,10],[2,2.42,12.57]],"ltp":2.42,"tv":13.81,"id":71234216}]}]}
{"op":"mcm","clk":"11766197716","pt":1722601705589,"mc":[{"id":"1.231295013","rc":[{"batb":[[0,2.42,12.57],[1,2.4,12.75],[2,2.3,46.93]],"ltp":2.42,"tv":13.81,"id":71234216}]}]}
{"op":"mcm","clk":"11766200353","pt":1722601799859,"mc":[{"id":"1.231295013","rc":[{"batb":[[0,2.44,12],[1,2.42,12.57],[2,2.4,12.75]],"ltp":2.42,"tv":13.81,"id":71234216}]}]}
{"op":"mcm","clk":"11766200455","pt":1722601803183,"mc":[{"id":"1.231295013","rc":[{"batb":[[0,2.44,10]],"ltp":2.42,"tv":13.81,"id":71234216}]}]}
{"op":"mcm","clk":"11766200489","pt":1722601804274,"mc":[{"id":"1.231295013","rc":[{"batb":[[0,2.42,12.57],[1,2.4,12.75],[2,2.3,46.93]],"ltp":2.42,"tv":13.81,"id":71234216}]}]}
{"op":"mcm","clk":"11766200551","pt":1722601806291,"mc":[{"id":"1.231295013","rc":[{"batb":[[0,2.44,2],[1,2.42,12.57],[2,2.4,12.75]],"ltp":2.42,"tv":13.81,"id":71234216}]}]}
{"op":"mcm","clk":"11766200637","pt":1722601809703,"mc":[{"id":"1.231295013","rc":[{"batb":[[0,2.42,12.57],[1,2.4,12.75],[2,2.3,46.93]],"ltp":2.42,"tv":13.81,"id":71234216}]}]}
{"op":"mcm","clk":"11766200658","pt":1722601810579,"mc":[{"id":"1.231295013","rc":[{"batb":[[0,2.44,10],[1,2.42,12.57],[2,2.4,12.75]],"ltp":2.42,"tv":13.81,"id":71234216}]}]}
{"op":"mcm","clk":"11766200814","pt":1722601814871,"mc":[{"id":"1.231295013","rc":[{"batb":[[0,2.44,2]],"ltp":2.42,"tv":13.81,"id":71234216}]}]}
{"op":"mcm","clk":"11766200912","pt":1722601817667,"mc":[{"id":"1.231295013","rc":[{"batb":[[0,2.44,10]],"ltp":2.42,"tv":13.81,"id":71234216}]}]}
{"op":"mcm","clk":"11766201070","pt":1722601821612,"mc":[{"id":"1.231295013","rc":[{"batb":[[0,2.44,2]],"ltp":2.42,"tv":13.81,"id":71234216}]}]}
{"op":"mcm","clk":"11766201158","pt":1722601824418,"mc":[{"id":"1.231295013","rc":[{"batb":[[0,2.44,10]],"ltp":2.42,"tv":13.81,"id":71234216}]}]}
{"op":"mcm","clk":"11766201244","pt":1722601827722,"mc":[{"id":"1.231295013","rc":[{"batb":[[0,2.42,12.57],[1,2.4,12.75],[2,2.3,46.93]],"ltp":2.42,"tv":13.81,"id":71234216}]}]}
{"op":"mcm","clk":"11766201280","pt":1722601828910,"mc":[{"id":"1.231295013","rc":[{"batb":[[0,2.44,2],[1,2.42,12.57],[2,2.4,12.75]],"ltp":2.42,"tv":13.81,"id":71234216}]}]}
{"op":"mcm","clk":"11766201376","pt":1722601832106,"mc":[{"id":"1.231295013","rc":[{"batb":[[0,2.44,10]],"ltp":2.42,"tv":13.81,"id":71234216}]}]}
{"op":"mcm","clk":"11766201486","pt":1722601835725,"mc":[{"id":"1.231295013","rc":[{"batb":[[0,2.42,12.57],[1,2.4,12.75],[2,2.3,46.93]],"ltp":2.42,"tv":13.81,"id":71234216}]}]}
{"op":"mcm","clk":"11766201503","pt":1722601836293,"mc":[{"id":"1.231295013","rc":[{"batb":[[0,2.44,2],[1,2.42,12.57],[2,2.4,12.75]],"ltp":2.42,"tv":13.81,"id":71234216}]}]}
{"op":"mcm","clk":"11766201593","pt":1722601839106,"mc":[{"id":"1.231295013","rc":[{"batb":[[0,2.42,12.57],[1,2.4,12.75],[2,2.3,46.93]],"ltp":2.42,"tv":13.81,"id":71234216}]}]}
{"op":"mcm","clk":"11766201608","pt":1722601839725,"mc":[{"id":"1.231295013","rc":[{"batb":[[0,2.44,10],[1,2.42,12.57],[2,2.4,12.75]],"ltp":2.42,"tv":13.81,"id":71234216}]}]}
{"op":"mcm","clk":"11766201715","pt":1722601843702,"mc":[{"id":"1.231295013","rc":[{"batb":[[0,2.44,2]],"ltp":2.42,"tv":13.81,"id":71234216}]}]}
{"op":"mcm","clk":"11766201788","pt":1722601846125,"mc":[{"id":"1.231295013","rc":[{"batb":[[0,2.42,12.57],[1,2.4,12.75],[2,2.3,46.93]],"ltp":2.42,"tv":13.81,"id":71234216}]}]}
{"op":"mcm","clk":"11766201807","pt":1722601846744,"mc":[{"id":"1.231295013","rc":[{"batb":[[0,2.44,10],[1,2.42,12.57],[2,2.4,12.75]],"ltp":2.42,"tv":13.81,"id":71234216}]}]}
{"op":"mcm","clk":"11766201932","pt":1722601850617,"mc":[{"id":"1.231295013","rc":[{"batb":[[0,2.44,2]],"ltp":2.42,"tv":13.81,"id":71234216}]}]}
{"op":"mcm","clk":"11766202010","pt":1722601852904,"mc":[{"id":"1.231295013","rc":[{"batb":[[0,2.42,12.57],[1,2.4,12.75],[2,2.3,46.93]],"ltp":2.42,"tv":13.81,"id":71234216}]}]}
{"op":"mcm","clk":"11766202020","pt":1722601853215,"mc":[{"id":"1.231295013","rc":[{"batb":[[0,2.44,10],[1,2.42,12.57],[2,2.4,12.75]],"ltp":2.42,"tv":13.81,"id":71234216}]}]}
{"op":"mcm","clk":"11766202108","pt":1722601857053,"mc":[{"id":"1.231295013","rc":[{"batb":[[0,2.44,2]],"ltp":2.42,"tv":13.81,"id":71234216}]}]}
{"op":"mcm","clk":"11766202165","pt":1722601859626,"mc":[{"id":"1.231295013","rc":[{"batb":[[0,2.44,10]],"ltp":2.42,"tv":13.81,"id":71234216}]}]}
{"op":"mcm","clk":"11766202249","pt":1722601863133,"mc":[{"id":"1.231295013","rc":[{"batb":[[0,2.42,12.57],[1,2.4,12.75],[2,2.3,46.93]],"ltp":2.42,"tv":13.81,"id":71234216}]}]}
{"op":"mcm","clk":"11766202259","pt":1722601863340,"mc":[{"id":"1.231295013","rc":[{"batb":[[0,2.44,2],[1,2.42,12.57],[2,2.4,12.75]],"ltp":2.42,"tv":13.81,"id":71234216}]}]}
{"op":"mcm","clk":"11766202365","pt":1722601866441,"mc":[{"id":"1.231295013","rc":[{"batb":[[0,2.44,10]],"ltp":2.42,"tv":13.81,"id":71234216}]}]}
{"op":"mcm","clk":"11766202487","pt":1722601870171,"mc":[{"id":"1.231295013","rc":[{"batb":[[0,2.44,2]],"ltp":2.42,"tv":13.81,"id":71234216}]}]}
{"op":"mcm","clk":"11766202585","pt":1722601872860,"mc":[{"id":"1.231295013","rc":[{"batb":[[0,2.44,10]],"ltp":2.42,"tv":13.81,"id":71234216}]}]}
{"op":"mcm","clk":"11766202734","pt":1722601877054,"mc":[{"id":"1.231295013","rc":[{"batb":[[0,2.42,12.57],[1,2.4,12.75],[2,2.3,46.93]],"ltp":2.42,"tv":13.81,"id":71234216}]}]}
{"op":"mcm","clk":"11766202744","pt":1722601877365,"mc":[{"id":"1.231295013","rc":[{"batb":[[0,2.44,2],[1,2.42,12.57],[2,2.4,12.75]],"ltp":2.42,"tv":13.81,"id":71234216}]}]}
{"op":"mcm","clk":"11766202826","pt":1722601879646,"mc":[{"id":"1.231295013","rc":[{"batb":[[0,2.42,12.57],[1,2.4,12.75],[2,2.3,46.93]],"ltp":2.42,"tv":13.81,"id":71234216}]}]}
{"op":"mcm","clk":"11766202861","pt":1722601880471,"mc":[{"id":"1.231295013","rc":[{"batb":[[0,2.44,10],[1,2.42,12.57],[2,2.4,12.75]],"ltp":2.42,"tv":13.81,"id":71234216}]}]}
{"op":"mcm","clk":"11766202945","pt":1722601882766,"mc":[{"id":"1.231295013","rc":[{"batb":[[0,2.46,2],[1,2.44,10],[2,2.42,12.57]],"ltp":2.42,"tv":13.81,"id":71234216}]}]}
{"op":"mcm","clk":"11766203120","pt":1722601888353,"mc":[{"id":"1.231295013","rc":[{"batb":[[1,2.42,12.57],[2,2.4,12.75]],"ltp":2.42,"tv":13.81,"id":71234216}]}]}
{"op":"mcm","clk":"11766203260","pt":1722601891883,"mc":[{"id":"1.231295013","rc":[{"batb":[[0,2.42,12.57],[1,2.4,12.75],[2,2.3,46.93]],"ltp":2.42,"tv":13.81,"id":71234216}]}]}
{"op":"mcm","clk":"11766203364","pt":1722601894687,"mc":[{"id":"1.231295013","rc":[{"batb":[[0,2.44,12],[1,2.42,12.57],[2,2.4,12.75]],"ltp":2.42,"tv":13.81,"id":71234216}]}]}
{"op":"mcm","clk":"11766203470","pt":1722601898400,"mc":[{"id":"1.231295013","rc":[{"batb":[[0,2.44,10]],"ltp":2.42,"tv":13.81,"id":71234216}]}]}
{"op":"mcm","clk":"11766203502","pt":1722601899488,"mc":[{"id":"1.231295013","rc":[{"batb":[[0,2.42,12.57],[1,2.4,12.75],[2,2.3,46.93]],"ltp":2.42,"tv":13.81,"id":71234216}]}]}
{"op":"mcm","clk":"11766203550","pt":1722601900778,"mc":[{"id":"1.231295013","rc":[{"batb":[[0,2.46,2],[1,2.42,12.57],[2,2.4,12.75]],"ltp":2.42,"tv":13.81,"id":71234216}]}]}
{"op":"mcm","clk":"11766203637","pt":1722601904968,"mc":[{"id":"1.231295013","rc":[{"batb":[[0,2.42,12.57],[1,2.4,12.75],[2,2.3,46.93]],"ltp":2.42,"tv":13.81,"id":71234216}]}]}
{"op":"mcm","clk":"11766203660","pt":1722601905796,"mc":[{"id":"1.231295013","rc":[{"batb":[[0,2.44,10],[1,2.42,12.57],[2,2.4,12.75]],"ltp":2.42,"tv":13.81,"id":71234216}]}]}
{"op":"mcm","clk":"11766203750","pt":1722601910025,"mc":[{"id":"1.231295013","rc":[{"batb":[[0,2.44,2]],"ltp":2.42,"tv":13.81,"id":71234216}]}]}
{"op":"mcm","clk":"11766203817","pt":1722601912632,"mc":[{"id":"1.231295013","rc":[{"batb":[[0,2.42,12.57],[1,2.4,12.75],[2,2.3,46.93]],"ltp":2.42,"tv":13.81,"id":71234216}]}]}
{"op":"mcm","clk":"11766203842","pt":1722601913817,"mc":[{"id":"1.231295013","rc":[{"batb":[[0,2.44,10],[1,2.42,12.57],[2,2.4,12.75]],"ltp":2.42,"tv":13.81,"id":71234216}]}]}
{"op":"mcm","clk":"11766203949","pt":1722601918005,"mc":[{"id":"1.231295013","rc":[{"batb":[[0,2.44,2]],"ltp":2.42,"tv":13.81,"id":71234216}]}]}
{"op":"mcm","clk":"11766204023","pt":1722601920744,"mc":[{"id":"1.231295013","rc":[{"batb":[[0,2.44,10]],"ltp":2.42,"tv":13.81,"id":71234216}]}]}
{"op":"mcm","clk":"11766204096","pt":1722601922939,"mc":[{"id":"1.231295013","rc":[{"trd":[[2.44,7.32]],"batb":[[0,2.44,6.34]],"ltp":2.44,"tv":21.13,"id":71234216}],"tv":496.97}]}
{"op":"mcm","clk":"11766204144","pt":1722601924033,"mc":[{"id":"1.231295013","rc":[{"batb":[[0,2.46,2]],"ltp":2.44,"tv":21.13,"id":71234216}]}]}
{"op":"mcm","clk":"11766204211","pt":1722601925653,"mc":[{"id":"1.231295013","rc":[{"batb":[[0,2.42,12.57],[1,2.4,12.75],[2,2.3,46.93]],"ltp":2.44,"tv":21.13,"id":71234216}]}]}
{"op":"mcm","clk":"11766211797","pt":1722602137061,"mc":[{"id":"1.231295013","rc":[{"trd":[[2.42,54.58]],"batb":[[0,2.42,12]],"ltp":2.42,"tv":74.61,"id":71234216},{"trd":[[1.7,165.22]],"batl":[[0,1.7,128.41]],"ltp":1.7,"tv":516.18,"id":11674133}],"tv":590.8}]}
{"op":"mcm","clk":"11766211886","pt":1722602139446,"mc":[{"id":"1.231295013","rc":[{"batb":[[0,2.42,10]],"ltp":2.42,"tv":74.61,"id":71234216}]}]}
{"op":"mcm","clk":"11766211934","pt":1722602140531,"mc":[{"id":"1.231295013","rc":[{"batb":[[0,2.4,12.75],[1,2.3,46.93],[2,2.28,13.95]],"ltp":2.42,"tv":74.61,"id":71234216}]}]}
{"op":"mcm","clk":"11766212018","pt":1722602142753,"mc":[{"id":"1.231295013","rc":[{"batb":[[0,2.42,12],[1,2.4,12.75],[2,2.3,46.93]],"ltp":2.42,"tv":74.61,"id":71234216}]}]}
{"op":"mcm","clk":"11766212174","pt":1722602146151,"mc":[{"id":"1.231295013","rc":[{"batb":[[0,2.42,10]],"ltp":2.42,"tv":74.61,"id":71234216}]}]}
{"op":"mcm","clk":"11766212212","pt":1722602147175,"mc":[{"id":"1.231295013","rc":[{"batb":[[0,2.4,12.75],[1,2.3,46.93],[2,2.28,13.95]],"ltp":2.42,"tv":74.61,"id":71234216}]}]}
{"op":"mcm","clk":"11766212274","pt":1722602148776,"mc":[{"id":"1.231295013","rc":[{"batb":[[0,2.42,2],[1,2.4,12.75],[2,2.3,46.93]],"ltp":2.42,"tv":74.61,"id":71234216}]}]}
{"op":"mcm","clk":"11766212455","pt":1722602153745,"mc":[{"id":"1.231295013","rc":[{"batb":[[0,2.4,12.75],[1,2.3,46.93],[2,2.28,13.95]],"ltp":2.42,"tv":74.61,"id":71234216}]}]}
{"op":"mcm","clk":"11766212520","pt":1722602155579,"mc":[{"id":"1.231295013","rc":[{"batb":[[0,2.42,10],[1,2.4,12.75],[2,2.3,46.93]],"ltp":2.42,"tv":74.61,"id":71234216}]}]}
{"op":"mcm","clk":"11766212590","pt":1722602157084,"mc":[{"id":"1.231295013","rc":[{"batb":[[0,2.44,2],[1,2.42,22.57],[2,2.4,12.75]],"ltp":2.42,"tv":74.61,"id":71234216}]}]}
{"op":"mcm","clk":"11766212662","pt":1722602159558,"mc":[{"id":"1.231295013","rc":[{"batb":[[1,2.42,12.57]],"ltp":2.42,"tv":74.61,"id":71234216}]}]}
{"op":"mcm","clk":"11766212695","pt":1722602160489,"mc":[{"id":"1.231295013","rc":[{"batb":[[0,2.42,12.57],[1,2.4,12.75],[2,2.3,46.93]],"ltp":2.42,"tv":74.61,"id":71234216}]}]}
{"op":"mcm","clk":"11766212783","pt":1722602162690,"mc":[{"id":"1.231295013","rc":[{"batb":[[0,2.44,12],[1,2.42,12.57],[2,2.4,12.75]],"ltp":2.42,"tv":74.61,"id":71234216}]}]}
{"op":"mcm","clk":"11766212912","pt":1722602166398,"mc":[{"id":"1.231295013","rc":[{"batb":[[0,2.44,10]],"ltp":2.42,"tv":74.61,"id":71234216}]}]}
{"op":"mcm","clk":"11766212966","pt":1722602167366,"mc":[{"id":"1.231295013","rc":[{"batb":[[0,2.42,12.57],[1,2.4,12.75],[2,2.3,46.93]],"ltp":2.42,"tv":74.61,"id":71234216}]}]}
{"op":"mcm","clk":"11766213829","pt":1722602186418,"mc":[{"id":"1.231295013","rc":[{"batb":[[0,2.44,12],[1,2.42,12.57],[2,2.4,12.75]],"ltp":2.42,"tv":74.61,"id":71234216}]}]}
{"op":"mcm","clk":"11766213974","pt":1722602190209,"mc":[{"id":"1.231295013","rc":[{"batb":[[0,2.44,10]],"ltp":2.42,"tv":74.61,"id":71234216}]}]}
{"op":"mcm","clk":"11766214017","pt":1722602191192,"mc":[{"id":"1.231295013","rc":[{"batb":[[0,2.42,12.57],[1,2.4,12.75],[2,2.3,46.93]],"ltp":2.42,"tv":74.61,"id":71234216}]}]}
{"op":"mcm","clk":"11766214083","pt":1722602193000,"mc":[{"id":"1.231295013","rc":[{"batb":[[0,2.44,2],[1,2.42,12.57],[2,2.4,12.75]],"ltp":2.42,"tv":74.61,"id":71234216}]}]}
{"op":"mcm","clk":"11766214315","pt":1722602198420,"mc":[{"id":"1.231295013","rc":[{"batb":[[0,2.42,12.57],[1,2.4,12.75],[2,2.3,46.93]],"ltp":2.42,"tv":74.61,"id":71234216}]}]}
{"op":"mcm","clk":"11766214409","pt":1722602200515,"mc":[{"id":"1.231295013","rc":[{"batb":[[0,2.44,10],[1,2.42,12.57],[2,2.4,12.75]],"ltp":2.42,"tv":74.61,"id":71234216}]}]}
{"op":"mcm","clk":"11766214475","pt":1722602201704,"mc":[{"id":"1.231295013","rc":[{"batb":[[0,2.46,2],[1,2.44,10],[2,2.42,12.57]],"ltp":2.42,"tv":74.61,"id":71234216}]}]}
{"op":"mcm","clk":"11766214618","pt":1722602204850,"mc":[{"id":"1.231295013","rc":[{"batb":[[0,2.42,12.57],[1,2.4,12.75],[2,2.3,46.93]],"ltp":2.42,"tv":74.61,"id":71234216}]}]}
{"op":"mcm","clk":"11766217261","pt":1722602266168,"mc":[{"id":"1.231295013","rc":[{"trd":[[1.7,175.22]],"batl":[[0,1.7,123.41]],"ltp":1.7,"tv":526.18,"id":11674133}],"tv":600.8}]}
{"op":"mcm","clk":"11766217329","pt":1722602267662,"mc":[{"id":"1.231295013","rc":[{"batb":[[0,2.44,12],[1,2.42,12.57],[2,2.4,12.75]],"ltp":2.42,"tv":74.61,"id":71234216}]}]}
{"op":"mcm","clk":"11766217448","pt":1722602270760,"mc":[{"id":"1.231295013","rc":[{"batb":[[0,2.44,10]],"ltp":2.42,"tv":74.61,"id":71234216}]}]}
{"op":"mcm","clk":"11766217470","pt":1722602271576,"mc":[{"id":"1.231295013","rc":[{"batb":[[0,2.42,12.57],[1,2.4,12.75],[2,2.3,46.93]],"ltp":2.42,"tv":74.61,"id":71234216}]}]}
{"op":"mcm","clk":"11766222654","pt":1722602407120,"mc":[{"id":"1.231295013","rc":[{"trd":[[1.68,2.7]],"batb":[[0,1.66,178.87],[1,1.56,549.45],[2,1.43,116.28]],"batl":[[0,1.68,25.75],[1,1.7,123.41],[2,1.77,57.43]],"ltp":1.68,"tv":528.68,"id":11674133}],"tv":603.3}]}
{"op":"mcm","clk":"11766222660","pt":1722602407220,"mc":[{"id":"1.231295013","rc":[{"batb":[[0,1.66,151.82],[1,1.65,27.47],[2,1.56,549.45]],"ltp":1.68,"tv":528.68,"id":11674133}]}]}
{"op":"mcm","clk":"11766222727","pt":1722602409130,"mc":[{"id":"1.231295013","rc":[{"batb":[[0,2.44,12],[1,2.42,12.57],[2,2.4,12.75]],"ltp":2.42,"tv":74.61,"id":71234216}]}]}
{"op":"mcm","clk":"11766222732","pt":1722602409235,"mc":[{"id":"1.231295013","rc":[{"batb":[[0,2.44,24.39]],"ltp":2.42,"tv":74.61,"id":71234216}]}]}
{"op":"mcm","clk":"11766222852","pt":1722602412625,"mc":[{"id":"1.231295013","rc":[{"batb":[[0,2.44,22.39]],"ltp":2.42,"tv":74.61,"id":71234216},{"batl":[[0,1.7,123.41],[1,1.77,57.43],[2,1.86,1.67]],"ltp":1.68,"tv":528.68,"id":11674133}]}]}
{"op":"mcm","clk":"11766222908","pt":1722602413661,"mc":[{"id":"1.231295013","rc":[{"batb":[[0,2.42,12.57],[1,2.4,12.75],[2,2.3,33.2]],"ltp":2.42,"tv":74.61,"id":71234216}]}]}
{"op":"mcm","clk":"11766223032","pt":1722602416947,"mc":[{"id":"1.231295013","rc":[{"batb":[[0,2.46,12],[1,2.42,12.57],[2,2.4,12.75]],"ltp":2.42,"tv":74.61,"id":71234216},{"batb":[[0,1.66,86.42]],"ltp":1.68,"tv":528.68,"id":11674133}]}]}
{"op":"mcm","clk":"11766223179","pt":1722602420431,"mc":[{"id":"1.231295013","rc":[{"batb":[[0,2.46,10]],"ltp":2.42,"tv":74.61,"id":71234216}]}]}
{"op":"mcm","clk":"11766223219","pt":1722602421926,"mc":[{"id":"1.231295013","rc":[{"batb":[[0,2.42,12.57],[1,2.4,12.75],[2,2.3,33.2]],"ltp":2.42,"tv":74.61,"id":71234216},{"batb":[[0,1.66,151.82]],"ltp":1.68,"tv":528.68,"id":11674133}]}]}
{"op":"mcm","clk":"11766223252","pt":1722602422753,"mc":[{"id":"1.231295013","rc":[{"trd":[[2.48,4]],"ltp":2.48,"tv":78.61,"id":71234216}],"tv":607.3}]}
{"op":"mcm","clk":"11766223293","pt":1722602423743,"mc":[{"id":"1.231295013","rc":[{"batb":[[0,2.44,10],[1,2.42,12.57],[2,2.4,12.75]],"ltp":2.48,"tv":78.61,"id":71234216}]}]}
{"op":"mcm","clk":"11766223505","pt":1722602428156,"mc":[{"id":"1.231295013","rc":[{"batb":[[0,2.42,12.57],[1,2.4,12.75],[2,2.3,33.2]],"ltp":2.48,"tv":78.61,"id":71234216}]}]}
{"op":"mcm","clk":"11766223511","pt":1722602428259,"mc":[{"id":"1.231295013","rc":[{"batb":[[0,2.44,2],[1,2.42,12.57],[2,2.4,12.75]],"ltp":2.48,"tv":78.61,"id":71234216}]}]}
{"op":"mcm","clk":"11766223596","pt":1722602430568,"mc":[{"id":"1.231295013","rc":[{"batb":[[0,2.42,12.57],[1,2.4,12.75],[2,2.3,33.2]],"ltp":2.48,"tv":78.61,"id":71234216}]}]}
{"op":"mcm","clk":"11766223635","pt":1722602431760,"mc":[{"id":"1.231295013","rc":[{"batb":[[0,2.44,10],[1,2.42,12.57],[2,2.4,12.75]],"ltp":2.48,"tv":78.61,"id":71234216}]}]}
{"op":"mcm","clk":"11766223795","pt":1722602435561,"mc":[{"id":"1.231295013","rc":[{"batb":[[0,2.42,12.57],[1,2.4,12.75],[2,2.3,33.2]],"ltp":2.48,"tv":78.61,"id":71234216}]}]}
{"op":"mcm","clk":"11766223832","pt":1722602436755,"mc":[{"id":"1.231295013","rc":[{"batb":[[0,2.44,2],[1,2.42,12.57],[2,2.4,12.75]],"ltp":2.48,"tv":78.61,"id":71234216}]}]}
{"op":"mcm","clk":"11766223953","pt":1722602439863,"mc":[{"id":"1.231295013","rc":[{"batb":[[0,2.42,12.57],[1,2.4,12.75],[2,2.3,33.2]],"ltp":2.48,"tv":78.61,"id":71234216}]}]}
{"op":"mcm","clk":"11766223970","pt":1722602440274,"mc":[{"id":"1.231295013","rc":[{"batb":[[0,2.44,10],[1,2.42,12.57],[2,2.4,12.75]],"ltp":2.48,"tv":78.61,"id":71234216}]}]}
{"op":"mcm","clk":"11766224109","pt":1722602444167,"mc":[{"id":"1.231295013","rc":[{"batb":[[0,2.44,2]],"ltp":2.48,"tv":78.61,"id":71234216}]}]}
{"op":"mcm","clk":"11766224201","pt":1722602446458,"mc":[{"id":"1.231295013","rc":[{"batb":[[0,2.42,12.57],[1,2.4,12.75],[2,2.3,33.2]],"ltp":2.48,"tv":78.61,"id":71234216}]}]}
{"op":"mcm","clk":"11766224228","pt":1722602447183,"mc":[{"id":"1.231295013","rc":[{"batb":[[0,2.44,10],[1,2.42,12.57],[2,2.4,12.75]],"ltp":2.48,"tv":78.61,"id":71234216}]}]}
{"op":"mcm","clk":"11766224392","pt":1722602450970,"mc":[{"id":"1.231295013","rc":[{"batb":[[0,2.42,12.57],[1,2.4,12.75],[2,2.3,33.2]],"ltp":2.48,"tv":78.61,"id":71234216}]}]}
{"op":"mcm","clk":"11766224402","pt":1722602451389,"mc":[{"id":"1.231295013","rc":[{"batb":[[0,2.44,2],[1,2.42,12.57],[2,2.4,12.75]],"ltp":2.48,"tv":78.61,"id":71234216}]}]}
{"op":"mcm","clk":"11766224467","pt":1722602453767,"mc":[{"id":"1.231295013","rc":[{"batb":[[0,2.42,12.57],[1,2.4,12.75],[2,2.3,33.2]],"ltp":2.48,"tv":78.61,"id":71234216}]}]}
{"op":"mcm","clk":"11766224480","pt":1722602454176,"mc":[{"id":"1.231295013","rc":[{"batb":[[0,2.44,10],[1,2.42,12.57],[2,2.4,12.75]],"ltp":2.48,"tv":78.61,"id":71234216}]}]}
{"op":"mcm","clk":"11766224605","pt":1722602457753,"mc":[{"id":"1.231295013","rc":[{"batb":[[0,2.44,2]],"ltp":2.48,"tv":78.61,"id":71234216}]}]}
{"op":"mcm","clk":"11766224713","pt":1722602460385,"mc":[{"id":"1.231295013","rc":[{"batb":[[0,2.44,10]],"ltp":2.48,"tv":78.61,"id":71234216}]}]}
{"op":"mcm","clk":"11766224856","pt":1722602464064,"mc":[{"id":"1.231295013","rc":[{"batb":[[0,2.42,12.57],[1,2.4,12.75],[2,2.3,33.2]],"ltp":2.48,"tv":78.61,"id":71234216}]}]}
{"op":"mcm","clk":"11766224880","pt":1722602464785,"mc":[{"id":"1.231295013","rc":[{"batb":[[0,2.44,2],[1,2.42,12.57],[2,2.4,12.75]],"ltp":2.48,"tv":78.61,"id":71234216}]}]}
{"op":"mcm","clk":"11766224983","pt":1722602467688,"mc":[{"id":"1.231295013","rc":[{"batb":[[0,2.42,12.57],[1,2.4,12.75],[2,2.3,33.2]],"ltp":2.48,"tv":78.61,"id":71234216}]}]}
{"op":"mcm","clk":"11766225709","pt":1722602487804,"mc":[{"id":"1.231295013","rc":[{"trd":[[2.42,166.42]],"batb":[[0,2.3,33.2],[1,1.77,7],[2,1.43,116.28]],"batl":[[0,2.42,75.28],[1,3,6.23],[2,5,2.08]],"ltp":2.42,"tv":190.45,"id":71234216},{"trd":[[1.7,298.63]],"batl":[[0,1.77,57.43],[1,1.86,1.67],[2,3,1.37]],"ltp":1.7,"tv":652.09,"id":11674133}],"tv":842.55}]}
{"op":"mcm","clk":"11766225727","pt":1722602488321,"mc":[{"id":"1.231295013","rc":[{"batb":[[1,2.28,13.95],[2,1.77,7]],"ltp":2.42,"tv":190.45,"id":71234216},{"batb":[[0,1.66,178.87]],"ltp":1.7,"tv":652.09,"id":11674133}]}]}
{"op":"mcm","clk":"11766225774","pt":1722602489305,"mc":[{"id":"1.231295013","rc":[{"batb":[[0,1.69,25.87],[1,1.66,178.87],[2,1.65,27.47]],"ltp":1.7,"tv":652.09,"id":11674133}]}]}
{"op":"mcm","clk":"11766225979","pt":1722602495023,"mc":[{"id":"1.231295013","rc":[{"batl":[[0,3,6.23],[1,5,2.08],[2,10,1.1]],"ltp":2.42,"tv":190.45,"id":71234216}]}]}
{"op":"mcm","clk":"11766225993","pt":1722602495333,"mc":[{"id":"1.231295013","rc":[{"batb":[[0,1.66,178.87],[1,1.65,27.47],[2,1.56,549.45]],"ltp":1.7,"tv":652.09,"id":11674133}]}]}
{"op":"mcm","clk":"11766226261","pt":1722602501712,"mc":[{"id":"1.231295013","rc":[{"batb":[[2,2.22,8.09]],"ltp":2.42,"tv":190.45,"id":71234216}]}]}
{"op":"mcm","clk":"11766226324","pt":1722602503328,"mc":[{"id":"1.231295013","rc":[{"trd":[[2.3,146.32]],"batb":[[0,2.28,13.95],[1,2.22,8.09],[2,1.77,6.14]],"ltp":2.3,"tv":336.78,"id":71234216}],"tv":988.87}]}
{"op":"mcm","clk":"11766226465","pt":1722602507620,"mc":[{"id":"1.231295013","rc":[{"batb":[[1,2.22,43.47]],"ltp":2.3,"tv":336.78,"id":71234216}]}]}
{"op":"mcm","clk":"11766231181","pt":1722602682363,"mc":[{"id":"1.231295013","rc":[{"batl":[[0,1.75,4.5],[1,1.77,57.43],[2,1.86,1.67]],"ltp":1.7,"tv":652.09,"id":11674133}]}]}
{"op":"mcm","clk":"11766231460","pt":1722602696802,"mc":[{"id":"1.231295013","rc":[{"trd":[[1.66,156.98]],"batb":[[0,1.66,100.38]],"ltp":1.66,"tv":809.07,"id":11674133}],"tv":1145.85}]}
{"op":"mcm","clk":"11766231473","pt":1722602697371,"mc":[{"id":"1.231295013","rc":[{"batb":[[0,2.3,4.91],[1,2.28,13.95],[2,2.22,43.47]],"batl":[[0,2.5,4.79],[1,3,5.96],[2,5,2.08]],"ltp":2.3,"tv":336.78,"id":71234216},{"batb":[[0,1.67,6.77],[1,1.66,100.38],[2,1.65,27.47]],"batl":[[1,1.76,6.42],[2,1.77,57.43]],"ltp":1.66,"tv":809.07,"id":11674133}]}]}
{"op":"mcm","clk":"11766231634","pt":1722602704494,"mc":[{"id":"1.231295013","rc":[{"batb":[[2,2.22,8.09]],"ltp":2.3,"tv":336.78,"id":71234216},{"batb":[[1,1.66,7.93],[2,1.56,581.33]],"ltp":1.66,"tv":809.07,"id":11674133}]}]}
{"op":"mcm","clk":"11766231668","pt":1722602705516,"mc":[{"id":"1.231295013","rc":[{"trd":[[2.5,0.54]],"batl":[[0,3,5.96],[1,5,2.08],[2,10,1.1]],"ltp":2.5,"tv":337.32,"id":71234216},{"batb":[[0,1.66,7.93],[1,1.57,6.77]],"ltp":1.66,"tv":809.07,"id":11674133}],"tv":1146.4}]}
{"op":"mcm","clk":"11766231897","pt":1722602715111,"mc":[{"id":"1.231295013","rc":[{"batl":[[0,2.78,4.07],[1,3,5.96],[2,5,2.08]],"ltp":2.5,"tv":337.32,"id":71234216}]}]}
{"op":"mcm","clk":"11766232781","pt":1722602749757,"mc":[{"id":"1.231295013","rc":[{"batl":[[0,1.75,4]],"ltp":1.66,"tv":809.07,"id":11674133}]}]}
{"op":"mcm","clk":"11766233431","pt":1722602771898,"mc":[{"id":"1.231295013","rc":[{"trd":[[2.32,0.9]],"ltp":2.32,"tv":338.22,"id":71234216},{"trd":[[1.75,1.19]],"batl":[[0,1.75,2.81]],"ltp":1.75,"tv":810.26,"id":11674133}],"tv":1148.49}]}
{"op":"mcm","clk":"11766234567","pt":1722602810946,"mc":[{"id":"1.231295013","rc":[{"trd":[[2.32,3.02]],"batl":[[0,2.32,1.54],[1,2.78,4.07],[2,3,5.96]],"ltp":2.32,"tv":340.34,"id":71234216},{"trd":[[1.75,4]],"batl":[[0,1.76,6.42],[1,1.77,57.43],[2,1.86,1.67]],"ltp":1.75,"tv":813.07,"id":11674133}],"tv":1153.42}]}
{"op":"mcm","clk":"11766234617","pt":1722602813429,"mc":[{"id":"1.231295013","rc":[{"batb":[[0,1.7,1.13],[1,1.66,7.93],[2,1.57,6.77]],"ltp":1.75,"tv":813.07,"id":11674133}]}]}
{"op":"mcm","clk":"11766235194","pt":1722602833077,"mc":[{"id":"1.231295013","rc":[{"batb":[[0,1.72,2.25],[1,1.7,1.13],[2,1.66,7.93]],"ltp":1.75,"tv":813.07,"id":11674133}]}]}
{"op":"mcm","clk":"11766235636","pt":1722602848795,"mc":[{"id":"1.231295013","rc":[{"batb":[[2,1.68,2.25]],"ltp":1.75,"tv":813.07,"id":11674133}]}]}
{"op":"mcm","clk":"11766235655","pt":1722602849676,"mc":[{"id":"1.231295013","rc":[{"trd":[[2.32,4.56]],"batl":[[0,2.78,4.07],[1,3,5.96],[2,5,2.08]],"ltp":2.32,"tv":341.88,"id":71234216},{"trd":[[1.75,6.04]],"batl":[[0,1.75,136.42],[1,1.76,6.42],[2,1.77,57.43]],"ltp":1.75,"tv":815.11,"id":11674133}],"tv":1157.0}]}
{"op":"mcm","clk":"11766235732","pt":1722602852110,"mc":[{"id":"1.231295013","rc":[{"batb":[[0,2.3,18.64]],"ltp":2.32,"tv":341.88,"id":71234216}]}]}
{"op":"mcm","clk":"11766236649","pt":1722602882457,"mc":[{"id":"1.231295013","rc":[{"batl":[[0,2.5,4.07]],"ltp":2.32,"tv":341.88,"id":71234216}]}]}
{"op":"mcm","clk":"11766236992","pt":1722602894246,"mc":[{"id":"1.231295013","rc":[{"trd":[[2.32,11.31]],"ltp":2.32,"tv":348.63,"id":71234216},{"trd":[[1.75,14.99]],"batl":[[0,1.75,127.47]],"ltp":1.75,"tv":824.06,"id":11674133}],"tv":1172.7}]}
{"op":"mcm","clk":"11766237111","pt":1722602898165,"mc":[{"id":"1.231295013","rc":[{"batl":[[0,1.74,6.42],[1,1.75,127.47]],"ltp":1.75,"tv":824.06,"id":11674133}]}]}
{"op":"mcm","clk":"11766237130","pt":1722602899051,"mc":[{"id":"1.231295013","rc":[{"batb":[[0,2.32,13.53],[1,2.3,18.64]],"ltp":2.32,"tv":348.63,"id":71234216}]}]}
{"op":"mcm","clk":"11766237185","pt":1722602901937,"mc":[{"id":"1.231295013","rc":[{"batb":[[0,2.34,4.91],[1,2.32,13.53],[2,2.3,13.73]],"ltp":2.32,"tv":348.63,"id":71234216}]}]}
{"op":"mcm","clk":"11766240593","pt":1722603016603,"mc":[{"id":"1.231295013","rc":[{"trd":[[1.74,27.89]],"batb":[[0,1.74,218.58],[1,1.72,2.25],[2,1.7,1.13]],"batl":[[0,1.75,127.47],[1,1.77,57.43],[2,1.86,1.67]],"ltp":1.74,"tv":836.91,"id":11674133}],"tv":1185.54}]}
{"op":"mcm","clk":"11766240660","pt":1722603018699,"mc":[{"id":"1.231295013","rc":[{"batb":[[1,1.73,24.46],[2,1.72,2.25]],"ltp":1.74,"tv":836.91,"id":11674133}]}]}
{"op":"mcm","clk":"11766240802","pt":1722603024001,"mc":[{"id":"1.231295013","rc":[{"batb":[[0,1.73,24.46],[1,1.72,2.25],[2,1.7,1.13]],"ltp":1.74,"tv":836.91,"id":11674133}]}]}
{"op":"mcm","clk":"11766240810","pt":1722603024315,"mc":[{"id":"1.231295013","rc":[{"batb":[[0,1.72,2.25],[1,1.7,1.13],[2,1.68,2.25]],"ltp":1.74,"tv":836.91,"id":11674133}]}]}
{"op":"mcm","clk":"11766241248","pt":1722603039116,"mc":[{"id":"1.231295013","rc":[{"trd":[[2.34,16.11]],"batb":[[0,2.32,13.53],[1,2.3,13.73],[2,1.77,7]],"ltp":2.34,"tv":353.54,"id":71234216},{"trd":[[1.75,276.5]],"batb":[[0,1.75,81.96],[1,1.72,2.25],[2,1.7,1.13]],"batl":[[0,1.77,57.43],[1,1.86,1.67],[2,3,1.37]],"ltp":1.75,"tv":1098.42,"id":11674133}],"tv":1451.96}]}
{"op":"mcm","clk":"11766241278","pt":1722603039708,"mc":[{"id":"1.231295013","rc":[{"batb":[[0,2.26,15.03],[1,1.77,6.14],[2,1.43,116.28]],"ltp":2.34,"tv":353.54,"id":71234216}]}]}
{"op":"mcm","clk":"11766241325","pt":1722603040834,"mc":[{"id":"1.231295013","rc":[{"batb":[[1,2.22,5],[2,1.77,6.14]],"ltp":2.34,"tv":353.54,"id":71234216}]}]}
{"op":"mcm","clk":"11766241356","pt":1722603041727,"mc":[{"id":"1.231295013","rc":[{"batb":[[1,1.74,24.13],[2,1.72,2.25]],"ltp":1.75,"tv":1098.42,"id":11674133}]}]}
{"op":"mcm","clk":"11766241745","pt":1722603052018,"mc":[{"id":"1.231295013","rc":[{"batb":[[0,1.75,88.73]],"ltp":1.75,"tv":1098.42,"id":11674133}]}]}
{"op":"mcm","clk":"11766241950","pt":1722603056076,"mc":[{"id":"1.231295013","rc":[{"batl":[[0,2.32,4.95]],"ltp":2.34,"tv":353.54,"id":71234216}]}]}
{"op":"mcm","clk":"11766242162","pt":1722603062376,"mc":[{"id":"1.231295013","rc":[{"trd":[[1.77,11.82]],"batl":[[0,1.77,53.74]],"ltp":1.77,"tv":1105.79,"id":11674133}],"tv":1459.34}]}
{"op":"mcm","clk":"11766242297","pt":1722603066777,"mc":[{"id":"1.231295013","rc":[{"trd":[[1.75,328.44]],"batb":[[0,1.75,62.76]],"ltp":1.75,"tv":1157.73,"id":11674133}],"tv":1511.28}]}
{"op":"mcm","clk":"11766242374","pt":1722603068761,"mc":[{"id":"1.231295013","rc":[{"trd":[[1.75,453.96]],"batb":[[0,1.74,24.13],[1,1.72,2.25],[2,1.7,1.13]],"batl":[[0,1.76,36.06],[1,1.77,53.74],[2,1.86,1.67]],"ltp":1.75,"tv":1283.25,"id":11674133}],"tv":1636.8}]}
{"op":"mcm","clk":"11766242405","pt":1722603069675,"mc":[{"id":"1.231295013","rc":[{"batb":[[0,2.28,13.95],[1,2.26,15.03],[2,2.22,5]],"ltp":2.34,"tv":353.54,"id":71234216},{"batb":[[0,1.72,2.25],[1,1.7,1.13],[2,1.68,2.25]],"ltp":1.75,"tv":1283.25,"id":11674133}]}]}
{"op":"mcm","clk":"11766242446","pt":1722603071083,"mc":[{"id":"1.231295013","rc":[{"batb":[[2,1.77,6.14]],"batl":[[0,2.42,4.95]],"ltp":2.34,"tv":353.54,"id":71234216},{"batl":[[0,1.76,53.49]],"ltp":1.75,"tv":1283.25,"id":11674133}]}]}
{"op":"mcm","clk":"11766242714","pt":1722603077503,"mc":[{"id":"1.231295013","rc":[{"trd":[[1.76,1.48]],"batl":[[0,1.76,52.75]],"ltp":1.76,"tv":1284.73,"id":11674133}],"tv":1638.28}]}
{"op":"mcm","clk":"11766243054","pt":1722603087689,"mc":[{"id":"1.231295013","rc":[{"batl":[[0,2.5,4.6]],"ltp":2.34,"tv":353.54,"id":71234216}]}]}
{"op":"mcm","clk":"11766243559","pt":1722603103086,"mc":[{"id":"1.231295013","rc":[{"batb":[[2,2.2,7.26]],"ltp":2.34,"tv":353.54,"id":71234216}]}]}
{"op":"mcm","clk":"11766244116","pt":1722603116123,"mc":[{"id":"1.231295013","rc":[{"batb":[[1,2.22,5.86]],"ltp":2.34,"tv":353.54,"id":71234216},{"batl":[[0,1.75,17.43],[1,1.76,35.32],[2,1.77,53.74]],"ltp":1.76,"tv":1284.73,"id":11674133}]}]}
{"op":"mcm","clk":"11766244144","pt":1722603116845,"mc":[{"id":"1.231295013","rc":[{"batb":[[0,2.3,13.73],[1,2.28,13.95],[2,2.22,5.86]],"ltp":2.34,"tv":353.54,"id":71234216}]}]}
{"op":"mcm","clk":"11766244290","pt":1722603121252,"mc":[{"id":"1.231295013","rc":[{"batb":[[2,2.2,8.12]],"ltp":2.34,"tv":353.54,"id":71234216}]}]}
{"op":"mcm","clk":"11766244774","pt":1722603130938,"mc":[{"id":"1.231295013","rc":[{"trd":[[1.75,488.82]],"batb":[[0,1.75,5.07],[1,1.72,2.25],[2,1.7,1.13]],"batl":[[0,1.76,35.32],[1,1.77,53.74],[2,1.86,1.67]],"ltp":1.75,"tv":1319.6,"id":11674133}],"tv":1673.14}]}
{"op":"mcm","clk":"11766244784","pt":1722603131245,"mc":[{"id":"1.231295013","rc":[{"batb":[[0,2.28,13.95],[1,2.2,8.12],[2,1.77,6.14]],"ltp":2.34,"tv":353.54,"id":71234216}]}]}
{"op":"mcm","clk":"11766244997","pt":1722603136268,"mc":[{"id":"1.231295013","rc":[{"batb":[[1,2.22,5.86],[2,2.2,7.26]],"ltp":2.34,"tv":353.54,"id":71234216}]}]}
{"op":"mcm","clk":"11766245269","pt":1722603143462,"mc":[{"id":"1.231295013","rc":[{"batb":[[2,1.77,6.14]],"ltp":2.34,"tv":353.54,"id":71234216}]}]}
{"op":"mcm","clk":"11766245631","pt":1722603153782,"mc":[{"id":"1.231295013","rc":[{"batb":[[0,2.3,13.73],[1,2.28,13.95],[2,2.22,5.86]],"ltp":2.34,"tv":353.54,"id":71234216},{"trd":[[1.75,498.96]],"batb":[[0,1.72,2.25],[1,1.7,1.13],[2,1.68,2.25]],"batl":[[0,1.75,126.96],[1,1.76,35.32],[2,1.77,53.74]],"ltp":1.75,"tv":1329.74,"id":11674133}],"tv":1683.28}]}
{"op":"mcm","clk":"11766245682","pt":1722603154975,"mc":[{"id":"1.231295013","rc":[{"batb":[[0,2.32,13.22],[1,2.3,13.73],[2,2.28,13.95]],"ltp":2.34,"tv":353.54,"id":71234216}]}]}
{"op":"mcm","clk":"11766245878","pt":1722603160056,"mc":[{"id":"1.231295013","rc":[{"trd":[[1.75,752.88]],"batb":[[0,1.75,30.02],[1,1.72,2.25],[2,1.7,1.13]],"batl":[[0,1.76,35.32],[1,1.77,53.74],[2,1.86,1.67]],"ltp":1.75,"tv":1583.66,"id":11674133}],"tv":1937.21}]}
{"op":"mcm","clk":"11766245955","pt":1722603161766,"mc":[{"id":"1.231295013","rc":[{"batb":[[1,1.74,24.13],[2,1.72,2.25]],"ltp":1.75,"tv":1583.66,"id":11674133}]}]}
{"op":"mcm","clk":"11766246120","pt":1722603166581,"mc":[{"id":"1.231295013","rc":[{"batb":[[0,1.74,24.13],[1,1.72,2.25],[2,1.7,1.13]],"batl":[[0,1.75,166.21],[1,1.76,35.32],[2,1.77,53.74]],"ltp":1.75,"tv":1583.66,"id":11674133}]}]}
{"op":"mcm","clk":"11766246161","pt":1722603167563,"mc":[{"id":"1.231295013","rc":[{"batl":[[0,2.44,4.6]],"ltp":2.34,"tv":353.54,"id":71234216},{"batb":[[0,1.72,2.25],[1,1.7,1.13],[2,1.69,17.65]],"ltp":1.75,"tv":1583.66,"id":11674133}]}]}
{"op":"mcm","clk":"11766246275","pt":1722603169893,"mc":[{"id":"1.231295013","rc":[{"batl":[[0,1.74,78.49],[1,1.75,166.21],[2,1.76,35.32]],"ltp":1.75,"tv":1583.66,"id":11674133}]}]}
{"op":"mcm","clk":"11766246301","pt":1722603170774,"mc":[{"id":"1.231295013","rc":[{"batb":[[0,2.32,26.75],[2,1.77,7]],"ltp":2.34,"tv":353.54,"id":71234216}]}]}
{"op":"mcm","clk":"11766246397","pt":1722603173411,"mc":[{"id":"1.231295013","rc":[{"batl":[[0,1.75,166.21],[1,1.76,35.32],[2,1.77,53.74]],"ltp":1.75,"tv":1583.66,"id":11674133}]}]}
{"op":"mcm","clk":"11766246785","pt":1722603184323,"mc":[{"id":"1.231295013","rc":[{"batl":[[2,5,1.15]],"ltp":2.34,"tv":353.54,"id":71234216}]}]}
{"op":"mcm","clk":"11766246851","pt":1722603186086,"mc":[{"id":"1.231295013","rc":[{"batl":[[0,3,5.96],[1,5,1.15],[2,10,1.1]],"ltp":2.34,"tv":353.54,"id":71234216}]}]}
{"op":"mcm","clk":"11766246856","pt":1722603186186,"mc":[{"id":"1.231295013","rc":[{"batl":[[0,2.46,4.6],[1,3,5.96],[2,5,1.15]],"ltp":2.34,"tv":353.54,"id":71234216}]}]}
{"op":"mcm","clk":"11766247562","pt":1722603204110,"mc":[{"id":"1.231295013","rc":[{"batb":[[2,2.2,8.12]],"ltp":2.34,"tv":353.54,"id":71234216}]}]}
{"op":"mcm","clk":"11766247660","pt":1722603206341,"mc":[{"id":"1.231295013","rc":[{"batl":[[0,1.74,17.63],[1,1.75,166.21],[2,1.76,35.32]],"ltp":1.75,"tv":1583.66,"id":11674133}]}]}
{"op":"mcm","clk":"11766247877","pt":1722603211950,"mc":[{"id":"1.231295013","rc":[{"batb":[[0,1.7,1.13],[1,1.69,17.65],[2,1.68,2.25]],"batl":[[0,1.72,23.5],[1,1.74,17.63],[2,1.75,166.21]],"ltp":1.75,"tv":1583.66,"id":11674133}]}]}
{"op":"mcm","clk":"11766247899","pt":1722603212419,"mc":[{"id":"1.231295013","rc":[{"batb":[[1,1.68,2.25],[2,1.67,17.65]],"ltp":1.75,"tv":1583.66,"id":11674133}]}]}
{"op":"mcm","clk":"11766247955","pt":1722603213825,"mc":[{"id":"1.231295013","rc":[{"batb":[[1,2.2,8.12],[2,1.77,6.14]],"ltp":2.34,"tv":353.54,"id":71234216}]}]}
{"op":"mcm","clk":"11766247986","pt":1722603214870,"mc":[{"id":"1.231295013","rc":[{"batb":[[0,2.36,13.13],[1,2.32,26.75],[2,2.2,8.12]],"ltp":2.34,"tv":353.54,"id":71234216}]}]}
{"op":"mcm","clk":"11766248047","pt":1722603216161,"mc":[{"id":"1.231295013","rc":[{"batl":[[0,1.74,17.63],[1,1.75,166.21],[2,1.76,35.32]],"ltp":1.75,"tv":1583.66,"id":11674133}]}]}
{"op":"mcm","clk":"11766248058","pt":1722603216423,"mc":[{"id":"1.231295013","rc":[{"batb":[[0,2.32,26.75],[1,2.2,8.12],[2,1.77,6.14]],"ltp":2.34,"tv":353.54,"id":71234216}]}]}
{"op":"mcm","clk":"11766248121","pt":1722603218340,"mc":[{"id":"1.231295013","rc":[{"batl":[[0,2.5,4.6]],"ltp":2.34,"tv":353.54,"id":71234216}]}]}
{"op":"mcm","clk":"11766248613","pt":1722603231471,"mc":[{"id":"1.231295013","rc":[{"batb":[[0,1.68,2.25],[1,1.67,17.65],[2,1.66,366.48]],"batl":[[0,1.7,22.37],[1,1.74,17.63],[2,1.75,166.21]],"ltp":1.75,"tv":1583.66,"id":11674133}]}]}
{"op":"mcm","clk":"11766248705","pt":1722603233857,"mc":[{"id":"1.231295013","rc":[{"batb":[[0,2.4,12.75],[1,2.32,26.75],[2,2.2,8.12]],"ltp":2.34,"tv":353.54,"id":71234216}]}]}
{"op":"mcm","clk":"11766248756","pt":1722603235148,"mc":[{"id":"1.231295013","rc":[{"batl":[[0,1.74,17.63],[1,1.75,166.21],[2,1.76,35.32]],"ltp":1.75,"tv":1583.66,"id":11674133}]}]}
{"op":"mcm","clk":"11766248763","pt":1722603235460,"mc":[{"id":"1.231295013","rc":[{"batb":[[0,2.32,26.75],[1,2.2,8.12],[2,1.77,6.14]],"ltp":2.34,"tv":353.54,"id":71234216}]}]}
{"op":"mcm","clk":"11766249242","pt":1722603245070,"mc":[{"id":"1.231295013","rc":[{"batb":[[0,1.66,366.48],[1,1.56,581.33],[2,1.43,116.28]],"batl":[[0,1.68,20.12],[1,1.74,17.63],[2,1.75,166.21]],"ltp":1.75,"tv":1583.66,"id":11674133}]}]}
{"op":"mcm","clk":"11766249274","pt":1722603245854,"mc":[{"id":"1.231295013","rc":[{"batb":[[0,1.66,357.08],[1,1.65,27.47],[2,1.56,581.33]],"ltp":1.75,"tv":1583.66,"id":11674133}]}]}
{"op":"mcm","clk":"11766249307","pt":1722603246887,"mc":[{"id":"1.231295013","rc":[{"batb":[[0,2.34,13.32],[1,2.32,26.75],[2,2.2,8.12]],"ltp":2.34,"tv":353.54,"id":71234216}]}]}
{"op":"mcm","clk":"11766249658","pt":1722603255193,"mc":[{"id":"1.231295013","rc":[{"trd":[[2.46,0.9]],"ltp":2.46,"tv":354.44,"id":71234216},{"trd":[[1.68,4.02]],"batl":[[0,1.68,18.8]],"ltp":1.68,"tv":1584.98,"id":11674133}],"tv":1939.43}]}
{"op":"mcm","clk":"11766249775","pt":1722603258312,"mc":[{"id":"1.231295013","rc":[{"batb":[[0,2.34,26.54],[1,2.32,13.53]],"ltp":2.46,"tv":354.44,"id":71234216}]}]}
{"op":"mcm","clk":"11766250028","pt":1722603264593,"mc":[{"id":"1.231295013","rc":[{"batb":[[2,1.77,7]],"ltp":2.46,"tv":354.44,"id":71234216}]}]}
{"op":"mcm","clk":"11766251445","pt":1722603300760,"mc":[{"id":"1.231295013","rc":[{"batb":[[2,1.57,24.62]],"ltp":1.68,"tv":1584.98,"id":11674133}]}]}
{"op":"mcm","clk":"11766251835","pt":1722603308102,"mc":[{"id":"1.231295013","rc":[{"trd":[[2.46,1.81]],"ltp":2.46,"tv":355.36,"id":71234216},{"trd":[[1.68,5.36]],"batl":[[0,1.68,17.46]],"ltp":1.68,"tv":1586.32,"id":11674133}],"tv":1941.68}]}
{"op":"mcm","clk":"11766252816","pt":1722603327910,"mc":[{"id":"1.231295013","rc":[{"trd":[[2.46,13.74]],"batl":[[0,2.46,6.37],[1,2.5,4.6],[2,3,5.96]],"ltp":2.46,"tv":367.28,"id":71234216},{"trd":[[1.68,22.82]],"batb":[[0,1.66,384.13]],"batl":[[0,1.74,17.63],[1,1.75,166.21],[2,1.76,35.32]],"ltp":1.68,"tv":1603.78,"id":11674133}],"tv":1971.06}]}
{"op":"mcm","clk":"11766253500","pt":1722603341190,"mc":[{"id":"1.231295013","rc":[{"batl":[[0,2.5,4.6],[1,3,5.96],[2,5,1.15]],"ltp":2.46,"tv":367.28,"id":71234216}]}]}
{"op":"mcm","clk":"11766253773","pt":1722603345876,"mc":[{"id":"1.231295013","rc":[{"batl":[[0,1.72,1.13],[1,1.74,17.63],[2,1.75,166.21]],"ltp":1.68,"tv":1603.78,"id":11674133}]}]}
{"op":"mcm","clk":"11766253830","pt":1722603347011,"mc":[{"id":"1.231295013","rc":[{"batb":[[0,1.66,357.08]],"batl":[[0,1.68,8.55],[1,1.72,1.13],[2,1.74,17.63]],"ltp":1.68,"tv":1603.78,"id":11674133}]}]}
{"op":"mcm","clk":"11766254061","pt":1722603352904,"mc":[{"id":"1.231295013","rc":[{"batb":[[0,1.67,17.65],[1,1.66,339.43],[2,1.65,27.47]],"ltp":1.68,"tv":1603.78,"id":11674133}]}]}
{"op":"mcm","clk":"11766254104","pt":1722603353890,"mc":[{"id":"1.231295013","rc":[{"batb":[[1,1.66,366.48]],"ltp":1.68,"tv":1603.78,"id":11674133}]}]}
{"op":"mcm","clk":"11766254229","pt":1722603356024,"mc":[{"id":"1.231295013","rc":[{"trd":[[2.46,19.58]],"batl":[[0,2.46,12.45],[1,2.5,4.6],[2,3,5.96]],"ltp":2.46,"tv":373.12,"id":71234216},{"trd":[[1.68,31.37]],"batl":[[0,1.72,1.13],[1,1.74,17.63],[2,1.75,166.21]],"ltp":1.68,"tv":1612.33,"id":11674133}],"tv":1985.45}]}
{"op":"mcm","clk":"11766254332","pt":1722603357895,"mc":[{"id":"1.231295013","rc":[{"batb":[[0,1.67,44.29]],"ltp":1.68,"tv":1612.33,"id":11674133}]}]}
{"op":"mcm","clk":"11766254494","pt":1722603360908,"mc":[{"id":"1.231295013","rc":[{"batl":[[0,2.46,9.02]],"ltp":2.46,"tv":373.12,"id":71234216},{"batb":[[0,1.67,17.65]],"ltp":1.68,"tv":1612.33,"id":11674133}]}]}
{"op":"mcm","clk":"11766254652","pt":1722603363945,"mc":[{"id":"1.231295013","rc":[{"batb":[[2,2.2,8.12]],"ltp":2.46,"tv":373.12,"id":71234216}]}]}
{"op":"mcm","clk":"11766255457","pt":1722603382385,"mc":[{"id":"1.231295013","rc":[{"batb":[[2,1.77,7]],"ltp":2.46,"tv":373.12,"id":71234216}]}]}
{"op":"mcm","clk":"11766255604","pt":1722603385492,"mc":[{"id":"1.231295013","rc":[{"batl":[[0,2.44,4.6],[1,2.46,9.02]],"ltp":2.46,"tv":373.12,"id":71234216},{"batb":[[0,1.69,17.65]],"ltp":1.68,"tv":1612.33,"id":11674133}]}]}
{"op":"mcm","clk":"11766255729","pt":1722603387983,"mc":[{"id":"1.231295013","rc":[{"batb":[[1,1.68,26.25],[2,1.66,366.48]],"ltp":1.68,"tv":1612.33,"id":11674133}]}]}
{"op":"mcm","clk":"11766263395","pt":1722603574144,"mc":[{"id":"1.231295013","rc":[{"trd":[[2.38,0.31]],"ltp":2.38,"tv":373.15,"id":71234216},{"trd":[[1.72,4.85]],"batl":[[0,1.72,1.08]],"ltp":1.72,"tv":1612.38,"id":11674133}],"tv":1985.54}]}
{"op":"mcm","clk":"11766264559","pt":1722603602601,"mc":[{"id":"1.231295013","rc":[{"batb":[[0,2.36,10],[1,2.34,26.54],[2,2.32,13.53]],"ltp":2.38,"tv":373.15,"id":71234216}]}]}
{"op":"mcm","clk":"11766264825","pt":1722603606306,"mc":[{"id":"1.231295013","rc":[{"trd":[[2.28,0.92],[2.3,145.99],[2.32,11.29],[2.34,16.06],[2.38,0.31],[2.42,165.81],[2.44,7.3],[2.46,19.49],[2.5,0.54]],"batb":[[0,2.34,26.52],[1,2.32,13.53],[2,1.77,6.98]],"batl":[[0,2.44,4.58],[2,3,5.94]],"ltp":2.38,"tv":372.05,"id":71234216},{"trd":[[1.64,129.64],[1.66,156.61],[1.69,33.38],[1.74,27.88],[1.75,752.22],[1.77,11.79],[1.8,93.07]],"batb":[[0,1.69,17.61],[1,1.68,26.27],[2,1.66,365.38]],"batl":[[1,1.74,17.58],[2,1.75,165.42]],"ltp":1.72,"tv":1610.99,"id":11674133}],"tv":1983.04}]}
{"op":"mcm","clk":"11766265535","pt":1722603622617,"mc":[{"id":"1.231295013","rc":[{"batb":[[0,2.36,10],[1,2.34,26.52],[2,2.32,13.53]],"ltp":2.38,"tv":372.05,"id":71234216}]}]}
{"op":"mcm","clk":"11766265715","pt":1722603626002,"mc":[{"id":"1.231295013","rc":[{"batb":[[0,2.34,26.52],[1,2.32,13.53],[2,1.77,6.98]],"ltp":2.38,"tv":372.05,"id":71234216}]}]}
{"op":"mcm","clk":"11766265818","pt":1722603628600,"mc":[{"id":"1.231295013","rc":[{"batb":[[0,2.36,10],[1,2.34,26.52],[2,2.32,13.53]],"ltp":2.38,"tv":372.05,"id":71234216}]}]}
{"op":"mcm","clk":"11766266023","pt":1722603634005,"mc":[{"id":"1.231295013","rc":[{"batb":[[0,2.34,26.52],[1,2.32,13.53],[2,1.77,6.98]],"ltp":2.38,"tv":372.05,"id":71234216}]}]}
{"op":"mcm","clk":"11766268984","pt":1722603709887,"mc":[{"id":"1.231295013","rc":[{"batb":[[0,2.36,10],[1,2.34,26.52],[2,2.32,13.53]],"ltp":2.38,"tv":372.05,"id":71234216},{"batl":[[0,1.71,7.81],[1,1.72,1.08],[2,1.74,17.58]],"ltp":1.72,"tv":1610.99,"id":11674133}]}]}
{"op":"mcm","clk":"11766269050","pt":1722603711785,"mc":[{"id":"1.231295013","rc":[{"batb":[[2,1.77,6.98]],"ltp":2.38,"tv":372.05,"id":71234216}]}]}
{"op":"mcm","clk":"11766269074","pt":1722603712713,"mc":[{"id":"1.231295013","rc":[{"batb":[[0,2.36,23.13]],"ltp":2.38,"tv":372.05,"id":71234216}]}]}
{"op":"mcm","clk":"11766269106","pt":1722603713801,"mc":[{"id":"1.231295013","rc":[{"batb":[[0,2.34,26.52],[1,1.77,6.98],[2,1.43,116.28]],"ltp":2.38,"tv":372.05,"id":71234216}]}]}
{"op":"mcm","clk":"11766269116","pt":1722603714218,"mc":[{"id":"1.231295013","rc":[{"batl":[[0,1.7,7.81],[1,1.71,7.81],[2,1.72,1.08]],"ltp":1.72,"tv":1610.99,"id":11674133}]}]}
{"op":"mcm","clk":"11766269387","pt":1722603722094,"mc":[{"id":"1.231295013","rc":[{"trd":[[2.42,168.52]],"ltp":2.42,"tv":374.76,"id":71234216},{"trd":[[1.7,302.49]],"batl":[[0,1.7,3.95]],"ltp":1.7,"tv":1614.85,"id":11674133}],"tv":1989.61}]}
{"op":"mcm","clk":"11766269406","pt":1722603722610,"mc":[{"id":"1.231295013","rc":[{"trd":[[2.44,11.89]],"batl":[[0,2.46,9.02],[1,3,5.94],[2,5,1.15]],"ltp":2.44,"tv":379.34,"id":71234216},{"trd":[[1.69,75.21]],"batb":[[0,1.68,26.27],[1,1.66,365.38],[2,1.65,27.49]],"batl":[[0,1.69,7.02],[1,1.7,3.95],[2,1.71,7.81]],"ltp":1.69,"tv":1656.68,"id":11674133}],"tv":2036.03}]}
{"op":"mcm","clk":"11766269433","pt":1722603723229,"mc":[{"id":"1.231295013","rc":[{"batb":[[0,2.36,10],[1,2.34,26.52],[2,1.77,6.98]],"ltp":2.44,"tv":379.34,"id":71234216},{"batb":[[0,1.66,365.38],[1,1.65,27.49],[2,1.56,578.73]],"ltp":1.69,"tv":1656.68,"id":11674133}]}]}
{"op":"mcm","clk":"11766269543","pt":1722603725734,"mc":[{"id":"1.231295013","rc":[{"batb":[[0,2.36,23.13]],"ltp":2.44,"tv":379.34,"id":71234216}]}]}
{"op":"mcm","clk":"11766269636","pt":1722603728040,"mc":[{"id":"1.231295013","rc":[{"trd":[[2.46,28.51]],"batb":[[0,2.38,2],[1,2.36,13.13],[2,2.34,26.52]],"batl":[[0,3,5.94],[1,5,1.15],[2,10,1.09]],"ltp":2.46,"tv":388.36,"id":71234216},{"trd":[[1.66,364.51],[1.68,44.58]],"batb":[[0,1.66,195.28]],"ltp":1.66,"tv":1877.79,"id":11674133}],"tv":2266.16}]}
{"op":"mcm","clk":"11766269693","pt":1722603729704,"mc":[{"id":"1.231295013","rc":[{"batb":[[2,2.34,13.19]],"ltp":2.46,"tv":388.36,"id":71234216}]}]}
{"op":"mcm","clk":"11766269732","pt":1722603731004,"mc":[{"id":"1.231295013","rc":[{"batb":[[0,2.4,10],[1,2.38,12.95],[2,2.36,13.13]],"ltp":2.46,"tv":388.36,"id":71234216}]}]}
{"op":"mcm","clk":"11766269788","pt":1722603732714,"mc":[{"id":"1.231295013","rc":[{"batb":[[2,2.34,13.19]],"ltp":2.46,"tv":388.36,"id":71234216}]}]}
{"op":"mcm","clk":"11766269843","pt":1722603734028,"mc":[{"id":"1.231295013","rc":[{"batb":[[0,2.42,2],[1,2.4,22.76],[2,2.38,12.95]],"ltp":2.46,"tv":388.36,"id":71234216}]}]}
{"op":"mcm","clk":"11766269873","pt":1722603734743,"mc":[{"id":"1.231295013","rc":[{"batb":[[1,2.4,12.76]],"ltp":2.46,"tv":388.36,"id":71234216},{"trd":[[1.66,365.53]],"batb":[[0,1.66,194.77]],"ltp":1.66,"tv":1878.81,"id":11674133}],"tv":2267.18}]}
{"op":"mcm","clk":"11766269929","pt":1722603736917,"mc":[{"id":"1.231295013","rc":[{"batb":[[0,2.36,10],[1,2.34,26.52],[2,1.77,6.98]],"ltp":2.46,"tv":388.36,"id":71234216}]}]}
{"op":"mcm","clk":"11766269993","pt":1722603738949,"mc":[{"id":"1.231295013","rc":[{"batb":[[0,2.38,2],[1,2.36,23.13],[2,2.34,26.52]],"ltp":2.46,"tv":388.36,"id":71234216}]}]}
{"op":"mcm","clk":"11766270078","pt":1722603740722,"mc":[{"id":"1.231295013","rc":[{"batb":[[1,2.36,13.13],[2,2.34,13.19]],"ltp":2.46,"tv":388.36,"id":71234216}]}]}
{"op":"mcm","clk":"11766270110","pt":1722603741716,"mc":[{"id":"1.231295013","rc":[{"batb":[[0,2.34,26.52],[1,1.77,6.98],[2,1.43,116.28]],"ltp":2.46,"tv":388.36,"id":71234216}]}]}
{"op":"mcm","clk":"11766270895","pt":1722603759546,"mc":[{"id":"1.231295013","rc":[{"trd":[[2.44,12.79]],"batb":[[0,2.36,12],[1,2.34,26.52],[2,1.77,6.98]],"ltp":2.44,"tv":389.26,"id":71234216},{"trd":[[1.69,76.51]],"batl":[[0,1.69,5.73]],"ltp":1.69,"tv":1880.11,"id":11674133}],"tv":2269.37}]}
{"op":"mcm","clk":"11766270991","pt":1722603761938,"mc":[{"id":"1.231295013","rc":[{"batb":[[0,2.36,23.13]],"ltp":2.44,"tv":389.26,"id":71234216}]}]}
{"op":"mcm","clk":"11766271033","pt":1722603762963,"mc":[{"id":"1.231295013","rc":[{"batb":[[0,2.36,13.13]],"ltp":2.44,"tv":389.26,"id":71234216}]}]}
{"op":"mcm","clk":"11766271040","pt":1722603763273,"mc":[{"id":"1.231295013","rc":[{"batb":[[0,2.34,26.52],[1,1.77,6.98],[2,1.43,116.28]],"ltp":2.44,"tv":389.26,"id":71234216}]}]}
{"op":"mcm","clk":"11766271092","pt":1722603764742,"mc":[{"id":"1.231295013","rc":[{"batb":[[0,2.38,2],[1,2.34,26.52],[2,1.77,6.98]],"ltp":2.44,"tv":389.26,"id":71234216}]}]}
{"op":"mcm","clk":"11766271140","pt":1722603765872,"mc":[{"id":"1.231295013","rc":[{"batb":[[0,2.38,12]],"ltp":2.44,"tv":389.26,"id":71234216}]}]}
{"op":"mcm","clk":"11766271175","pt":1722603766752,"mc":[{"id":"1.231295013","rc":[{"batb":[[0,2.38,24.95]],"ltp":2.44,"tv":389.26,"id":71234216},{"batl":[[2,1.71,25.4]],"ltp":1.69,"tv":1880.11,"id":11674133}]}]}
{"op":"mcm","clk":"11766271228","pt":1722603768154,"mc":[{"id":"1.231295013","rc":[{"batb":[[1,2.34,13.33]],"ltp":2.44,"tv":389.26,"id":71234216},{"batb":[[0,1.67,18.32],[1,1.66,194.77],[2,1.65,27.49]],"ltp":1.69,"tv":1880.11,"id":11674133}]}]}
{"op":"mcm","clk":"11766271244","pt":1722603768672,"mc":[{"id":"1.231295013","rc":[{"batb":[[0,2.4,25.95],[1,2.38,24.95]],"ltp":2.44,"tv":389.26,"id":71234216},{"batb":[[1,1.66,221.84]],"ltp":1.69,"tv":1880.11,"id":11674133}]}]}
{"op":"mcm","clk":"11766271272","pt":1722603769656,"mc":[{"id":"1.231295013","rc":[{"batb":[[1,2.38,22.95]],"ltp":2.44,"tv":389.26,"id":71234216}]}]}
{"op":"mcm","clk":"11766271348","pt":1722603772157,"mc":[{"id":"1.231295013","rc":[{"batb":[[0,2.42,2],[1,2.4,25.95],[2,2.38,12.95]],"ltp":2.44,"tv":389.26,"id":71234216}]}]}
{"op":"mcm","clk":"11766271422","pt":1722603774161,"mc":[{"id":"1.231295013","rc":[{"batl":[[2,1.71,7.81]],"ltp":1.69,"tv":1880.11,"id":11674133}]}]}
{"op":"mcm","clk":"11766271477","pt":1722603775663,"mc":[{"id":"1.231295013","rc":[{"batb":[[0,2.42,10]],"ltp":2.44,"tv":389.26,"id":71234216}]}]}
{"op":"mcm","clk":"11766271512","pt":1722603776752,"mc":[{"id":"1.231295013","rc":[{"batb":[[1,2.4,12.76]],"ltp":2.44,"tv":389.26,"id":71234216}]}]}
{"op":"mcm","clk":"11766271559","pt":1722603777784,"mc":[{"id":"1.231295013","rc":[{"batb":[[2,2.34,13.19]],"ltp":2.44,"tv":389.26,"id":71234216}]}]}
{"op":"mcm","clk":"11766271594","pt":1722603779075,"mc":[{"id":"1.231295013","rc":[{"batb":[[0,2.42,12.58]],"ltp":2.44,"tv":389.26,"id":71234216}]}]}
{"op":"mcm","clk":"11766271614","pt":1722603779697,"mc":[{"id":"1.231295013","rc":[{"batb":[[0,2.44,2],[1,2.34,26.52],[2,2.22,5.86]],"ltp":2.44,"tv":389.26,"id":71234216}]}]}
{"op":"mcm","clk":"11766271739","pt":1722603782597,"mc":[{"id":"1.231295013","rc":[{"batb":[[0,2.34,26.52],[1,2.22,5.86],[2,1.77,6.12]],"ltp":2.44,"tv":389.26,"id":71234216}]}]}
{"op":"mcm","clk":"11766271775","pt":1722603783694,"mc":[{"id":"1.231295013","rc":[{"batb":[[0,2.36,10],[1,2.34,26.52],[2,2.22,5.86]],"ltp":2.44,"tv":389.26,"id":71234216}]}]}
{"op":"mcm","clk":"11766271814","pt":1722603784887,"mc":[{"id":"1.231295013","rc":[{"batb":[[0,2.38,2],[1,2.36,10],[2,2.34,26.52]],"ltp":2.44,"tv":389.26,"id":71234216}]}]}
{"op":"mcm","clk":"11766271863","pt":1722603785775,"mc":[{"id":"1.231295013","rc":[{"batb":[[1,2.36,23.13]],"ltp":2.44,"tv":389.26,"id":71234216}]}]}
{"op":"mcm","clk":"11766271902","pt":1722603786706,"mc":[{"id":"1.231295013","rc":[{"batb":[[2,2.34,13.19]],"ltp":2.44,"tv":389.26,"id":71234216}]}]}
{"op":"mcm","clk":"11766271950","pt":1722603787692,"mc":[{"id":"1.231295013","rc":[{"batb":[[0,2.34,26.52],[1,1.77,6.98],[2,1.43,116.28]],"ltp":2.44,"tv":389.26,"id":71234216}]}]}
{"op":"mcm","clk":"11766273170","pt":1722603815131,"mc":[{"id":"1.231295013","rc":[{"batb":[[0,2.36,12],[1,2.34,26.52],[2,1.77,6.98]],"ltp":2.44,"tv":389.26,"id":71234216}]}]}
{"op":"mcm","clk":"11766273281","pt":1722603817723,"mc":[{"id":"1.231295013","rc":[{"batb":[[0,2.36,23.13]],"ltp":2.44,"tv":389.26,"id":71234216}]}]}
{"op":"mcm","clk":"11766273319","pt":1722603818613,"mc":[{"id":"1.231295013","rc":[{"trd":[[2.44,16.76]],"batb":[[0,2.36,13.13]],"batl":[[0,2.44,86.19],[1,3,5.94],[2,5,1.15]],"ltp":2.44,"tv":393.23,"id":71234216},{"trd":[[1.69,82.24]],"batl":[[0,1.7,3.95],[1,1.71,25.4],[2,1.72,1.08]],"ltp":1.69,"tv":1885.83,"id":11674133}],"tv":2279.07}]}
{"op":"mcm","clk":"11766273384","pt":1722603820246,"mc":[{"id":"1.231295013","rc":[{"batb":[[1,1.77,6.98],[2,1.43,116.28]],"ltp":2.44,"tv":393.23,"id":71234216}]}]}
{"op":"mcm","clk":"11766273428","pt":1722603821219,"mc":[{"id":"1.231295013","rc":[{"batb":[[0,2.4,12.76],[1,2.36,13.13],[2,1.77,6.98]],"ltp":2.44,"tv":393.23,"id":71234216},{"batb":[[0,1.68,26.27],[1,1.67,18.32],[2,1.66,221.84]],"ltp":1.69,"tv":1885.83,"id":11674133}]}]}
{"op":"mcm","clk":"11766273628","pt":1722603826052,"mc":[{"id":"1.231295013","rc":[{"batl":[[1,1.71,7.81]],"ltp":1.69,"tv":1885.83,"id":11674133}]}]}
{"op":"mcm","clk":"11766273646","pt":1722603826521,"mc":[{"id":"1.231295013","rc":[{"batb":[[0,2.36,10],[1,2.34,13.33]],"ltp":2.44,"tv":393.23,"id":71234216}]}]}
{"op":"mcm","clk":"11766273683","pt":1722603827728,"mc":[{"id":"1.231295013","rc":[{"batb":[[1,2.34,26.41]],"ltp":2.44,"tv":393.23,"id":71234216}]}]}
{"op":"mcm","clk":"11766273701","pt":1722603828250,"mc":[{"id":"1.231295013","rc":[{"batb":[[0,2.36,23.13]],"ltp":2.44,"tv":393.23,"id":71234216}]}]}
{"op":"mcm","clk":"11766273801","pt":1722603830745,"mc":[{"id":"1.231295013","rc":[{"batb":[[0,2.34,26.41],[1,1.77,6.98],[2,1.43,116.28]],"ltp":2.44,"tv":393.23,"id":71234216}]}]}
{"op":"mcm","clk":"11766273923","pt":1722603834925,"mc":[{"id":"1.231295013","rc":[{"trd":[[2.44,52.42]],"batl":[[0,2.44,68.36]],"ltp":2.44,"tv":428.89,"id":71234216}],"tv":2314.73}]}
{"op":"mcm","clk":"11766273957","pt":1722603835960,"mc":[{"id":"1.231295013","rc":[{"batb":[[0,2.36,10],[1,2.34,26.41],[2,1.77,6.98]],"ltp":2.44,"tv":428.89,"id":71234216}]}]}
{"op":"mcm","clk":"11766274027","pt":1722603838245,"mc":[{"id":"1.231295013","rc":[{"batb":[[0,2.36,23.13]],"ltp":2.44,"tv":428.89,"id":71234216}]}]}
{"op":"mcm","clk":"11766274076","pt":1722603840154,"mc":[{"id":"1.231295013","rc":[{"batb":[[0,2.36,13.13]],"ltp":2.44,"tv":428.89,"id":71234216}]}]}
{"op":"mcm","clk":"11766274104","pt":1722603840834,"mc":[{"id":"1.231295013","rc":[{"batb":[[0,2.34,26.41],[1,1.77,6.98],[2,1.43,116.28]],"ltp":2.44,"tv":428.89,"id":71234216}]}]}
{"op":"mcm","clk":"11766274999","pt":1722603859669,"mc":[{"id":"1.231295013","rc":[{"batb":[[0,2.36,10],[1,2.34,26.41],[2,1.77,6.98]],"ltp":2.44,"tv":428.89,"id":71234216},{"batb":[[0,1.69,18.32],[1,1.68,26.27]],"ltp":1.69,"tv":1885.83,"id":11674133}]}]}
{"op":"mcm","clk":"11766275156","pt":1722603862963,"mc":[{"id":"1.231295013","rc":[{"batb":[[0,2.36,13.13]],"ltp":2.44,"tv":428.89,"id":71234216}]}]}
{"op":"mcm","clk":"11766275173","pt":1722603863368,"mc":[{"id":"1.231295013","rc":[{"batb":[[0,2.34,26.41],[1,1.77,6.98],[2,1.43,116.28]],"ltp":2.44,"tv":428.89,"id":71234216}]}]}
{"op":"mcm","clk":"11766275256","pt":1722603865266,"mc":[{"id":"1.231295013","rc":[{"batb":[[0,2.36,10],[1,2.34,26.41],[2,1.77,6.98]],"ltp":2.44,"tv":428.89,"id":71234216}]}]}
{"op":"mcm","clk":"11766275352","pt":1722603867258,"mc":[{"id":"1.231295013","rc":[{"batb":[[0,2.36,23.13]],"ltp":2.44,"tv":428.89,"id":71234216}]}]}
{"op":"mcm","clk":"11766275460","pt":1722603869792,"mc":[{"id":"1.231295013","rc":[{"batb":[[0,2.34,26.41],[1,1.77,6.98],[2,1.43,116.28]],"ltp":2.44,"tv":428.89,"id":71234216}]}]}
{"op":"mcm","clk":"11766277568","pt":1722603924332,"mc":[{"id":"1.231295013","rc":[{"trd":[[2.42,171.3]],"batl":[[0,2.42,153.04],[1,2.44,68.36],[2,3,5.94]],"ltp":2.42,"tv":431.67,"id":71234216},{"trd":[[1.7,306.44]],"batl":[[0,1.71,7.81],[1,1.72,1.08],[2,1.74,17.58]],"ltp":1.7,"tv":1889.79,"id":11674133}],"tv":2321.46}]}
{"op":"mcm","clk":"11766277594","pt":1722603925331,"mc":[{"id":"1.231295013","rc":[{"batb":[[0,1.69,44.21]],"ltp":1.7,"tv":1889.79,"id":11674133}]}]}
{"op":"mcm","clk":"11766278580","pt":1722603958977,"mc":[{"id":"1.231295013","rc":[{"batb":[[0,1.7,18.32],[1,1.69,25.89],[2,1.68,26.27]],"ltp":1.7,"tv":1889.79,"id":11674133}]}]}
{"op":"mcm","clk":"11766279306","pt":1722603973888,"mc":[{"id":"1.231295013","rc":[{"trd":[[2.34,96.7],[2.38,1.09],[2.4,5.56]],"batb":[[0,2.3,13.74]],"batl":[[0,2.34,31.87],[1,2.42,153.04],[2,2.44,68.36]],"ltp":2.34,"tv":518.66,"id":71234216},{"trd":[[1.71,7.81],[1.72,5.93],[1.74,45.46]],"batb":[[0,1.7,43.85]],"batl":[[0,1.75,165.42],[1,1.76,35.32],[2,1.77,53.49]],"ltp":1.74,"tv":1916.26,"id":11674133}],"tv":2434.92}]}
{"op":"mcm","clk":"11766279339","pt":1722603974975,"mc":[{"id":"1.231295013","rc":[{"batb":[[1,1.78,10.86],[2,1.77,6.12]],"ltp":2.34,"tv":518.66,"id":71234216}]}]}
{"op":"mcm","clk":"11766279378","pt":1722603975969,"mc":[{"id":"1.231295013","rc":[{"trd":[[2.34,114.9]],"batb":[[1,1.78,16.98],[2,1.43,116.28]],"batl":[[0,2.34,13.67]],"ltp":2.34,"tv":536.85,"id":71234216},{"trd":[[1.74,69.93]],"batb":[[0,1.73,24.47],[1,1.7,43.85],[2,1.69,25.89]],"ltp":1.74,"tv":1940.73,"id":11674133}],"tv":2477.59}]}
{"op":"mcm","clk":"11766279408","pt":1722603976382,"mc":[{"id":"1.231295013","rc":[{"batb":[[0,1.7,43.85],[1,1.69,25.89],[2,1.68,26.27]],"ltp":1.74,"tv":1940.73,"id":11674133}]}]}
{"op":"mcm","clk":"11766279532","pt":1722603979076,"mc":[{"id":"1.231295013","rc":[{"batb":[[1,1.78,6.98]],"ltp":2.34,"tv":536.85,"id":71234216}]}]}
{"op":"mcm","clk":"11766279649","pt":1722603982080,"mc":[{"id":"1.231295013","rc":[{"batl":[[0,2.42,153.04],[1,2.44,68.36],[2,3,5.94]],"ltp":2.34,"tv":536.85,"id":71234216}]}]}
{"op":"mcm","clk":"11766279658","pt":1722603982291,"mc":[{"id":"1.231295013","rc":[{"trd":[[2.32,24.96]],"batb":[[0,2.32,10],[1,2.3,13.74],[2,1.78,6.98]],"ltp":2.32,"tv":550.52,"id":71234216},{"trd":[[1.75,770.34]],"batl":[[0,1.75,147.29]],"ltp":1.75,"tv":1958.86,"id":11674133}],"tv":2509.38}]}
{"op":"mcm","clk":"11766279800","pt":1722603985911,"mc":[{"id":"1.231295013","rc":[{"batb":[[0,2.34,5],[1,1.78,6.98],[2,1.43,116.28]],"ltp":2.32,"tv":550.52,"id":71234216}]}]}
{"op":"mcm","clk":"11766279823","pt":1722603986381,"mc":[{"id":"1.231295013","rc":[{"batb":[[1,2.32,13.53],[2,1.78,6.98]],"ltp":2.32,"tv":550.52,"id":71234216}]}]}
{"op":"mcm","clk":"11766281551","pt":1722604027841,"mc":[{"id":"1.231295013","rc":[{"batl":[[0,1.74,67.5],[1,1.75,147.29],[2,1.76,35.32]],"ltp":1.75,"tv":1958.86,"id":11674133}]}]}
{"op":"mcm","clk":"11766282186","pt":1722604041031,"mc":[{"id":"1.231295013","rc":[{"batb":[[0,2.36,9.02],[1,2.34,17.96]],"ltp":2.32,"tv":550.52,"id":71234216}]}]}
{"op":"mcm","clk":"11766282213","pt":1722604041440,"mc":[{"id":"1.231295013","rc":[{"batb":[[1,2.34,31.29]],"ltp":2.32,"tv":550.52,"id":71234216}]}]}
{"op":"mcm","clk":"11766282379","pt":1722604045821,"mc":[{"id":"1.231295013","rc":[{"batb":[[1,2.34,26.29]],"ltp":2.32,"tv":550.52,"id":71234216}]}]}
{"op":"mcm","clk":"11766282526","pt":1722604049734,"mc":[{"id":"1.231295013","rc":[{"trd":[[1.74,81.69]],"batl":[[0,1.74,61.62]],"ltp":1.74,"tv":1970.62,"id":11674133}],"tv":2521.14}]}
{"op":"mcm","clk":"11766283822","pt":1722604078874,"mc":[{"id":"1.231295013","rc":[{"batb":[[0,2.36,21.98],[1,2.34,13.33]],"ltp":2.32,"tv":550.52,"id":71234216}]}]}
{"op":"mcm","clk":"11766285879","pt":1722604132331,"mc":[{"id":"1.231295013","rc":[{"batb":[[0,2.36,12.96]],"ltp":2.32,"tv":550.52,"id":71234216}]}]}
{"op":"mcm","clk":"11766286344","pt":1722604144080,"mc":[{"id":"1.231295013","rc":[{"trd":[[2.4,14.58]],"ltp":2.4,"tv":559.54,"id":71234216}],"tv":2530.16}]}
{"op":"mcm","clk":"11766289039","pt":1722604213930,"mc":[{"id":"1.231295013","rc":[{"batl":[[0,1.75,147.29],[1,1.76,35.32],[2,1.77,53.49]],"ltp":1.74,"tv":1970.62,"id":11674133}]}]}
{"op":"mcm","clk":"11766289096","pt":1722604215059,"mc":[{"id":"1.231295013","rc":[{"batb":[[1,2.32,13.53]],"ltp":2.4,"tv":559.54,"id":71234216}]}]}
{"op":"mcm","clk":"11766289160","pt":1722604216514,"mc":[{"id":"1.231295013","rc":[{"batb":[[1,2.34,5],[2,2.32,13.53]],"ltp":2.4,"tv":559.54,"id":71234216}]}]}
{"op":"mcm","clk":"11766289255","pt":1722604219052,"mc":[{"id":"1.231295013","rc":[{"batb":[[1,2.34,18.33],[2,1.78,6.98]],"ltp":2.4,"tv":559.54,"id":71234216}]}]}
{"op":"mcm","clk":"11766289305","pt":1722604221143,"mc":[{"id":"1.231295013","rc":[{"batb":[[0,2.34,18.33],[1,1.78,6.98],[2,1.43,116.28]],"ltp":2.4,"tv":559.54,"id":71234216}]}]}
{"op":"mcm","clk":"11766289336","pt":1722604222071,"mc":[{"id":"1.231295013","rc":[{"batb":[[0,2.34,12.96],[1,2.32,13.53],[2,1.78,6.98]],"ltp":2.4,"tv":559.54,"id":71234216}]}]}
{"op":"mcm","clk":"11766289368","pt":1722604223163,"mc":[{"id":"1.231295013","rc":[{"trd":[[2.42,183.18]],"batl":[[0,2.42,141.16]],"ltp":2.42,"tv":571.42,"id":71234216},{"trd":[[1.7,411.04]],"batb":[[0,1.69,25.89],[1,1.68,26.27],[2,1.66,221.84]],"ltp":1.7,"tv":2075.21,"id":11674133}],"tv":2646.64}]}
{"op":"mcm","clk":"11766289467","pt":1722604226668,"mc":[{"id":"1.231295013","rc":[{"batb":[[0,2.34,17.96]],"ltp":2.42,"tv":571.42,"id":71234216}]}]}
{"op":"mcm","clk":"11766289836","pt":1722604236174,"mc":[{"id":"1.231295013","rc":[{"trd":[[2.42,183.78]],"batl":[[0,2.42,140.56]],"ltp":2.42,"tv":572.02,"id":71234216},{"trd":[[1.7,411.9]],"ltp":1.7,"tv":2076.07,"id":11674133}],"tv":2648.1}]}
{"op":"mcm","clk":"11766290598","pt":1722604258390,"mc":[{"id":"1.231295013","rc":[{"trd":[[2.42,202.02]],"batl":[[0,2.42,122.32]],"ltp":2.42,"tv":590.26,"id":71234216},{"trd":[[1.7,437.87]],"ltp":1.7,"tv":2102.04,"id":11674133}],"tv":2692.31}]}
{"op":"mcm","clk":"11766291078","pt":1722604270145,"mc":[{"id":"1.231295013","rc":[{"batb":[[0,1.71,17.9],[1,1.7,25.52],[2,1.69,25.89]],"ltp":1.7,"tv":2102.04,"id":11674133}]}]}
{"op":"mcm","clk":"11766292787","pt":1722604315414,"mc":[{"id":"1.231295013","rc":[{"trd":[[2.34,120.31]],"batb":[[0,2.34,15.26]],"ltp":2.34,"tv":595.68,"id":71234216}],"tv":2697.73}]}
{"op":"mcm","clk":"11766293165","pt":1722604324895,"mc":[{"id":"1.231295013","rc":[{"trd":[[2.42,281.02]],"batl":[[0,2.42,82.82]],"ltp":2.42,"tv":674.68,"id":71234216},{"batl":[[2,1.86,1.67]],"ltp":1.7,"tv":2102.04,"id":11674133}],"tv":2776.72}]}
{"op":"mcm","clk":"11766295217","pt":1722604377363,"mc":[{"id":"1.231295013","rc":[{"batb":[[0,2.34,17.96]],"ltp":2.42,"tv":674.68,"id":71234216}]}]}
{"op":"mcm","clk":"11766297518","pt":1722604432789,"mc":[{"id":"1.231295013","rc":[{"batb":[[2,1.43,117.14]],"batl":[[2,3,2.37]],"ltp":2.42,"tv":674.68,"id":71234216}]}]}
{"op":"mcm","clk":"11766298794","pt":1722604463333,"mc":[{"id":"1.231295013","rc":[{"batb":[[0,2.34,12.96]],"ltp":2.42,"tv":674.68,"id":71234216}]}]}
{"op":"mcm","clk":"11766302214","pt":1722604551735,"mc":[{"id":"1.231295013","rc":[{"trd":[[2.34,122.31]],"batb":[[0,2.34,11.96]],"ltp":2.34,"tv":676.68,"id":71234216}],"tv":2778.72}]}
{"op":"mcm","clk":"11766302508","pt":1722604558936,"mc":[{"id":"1.231295013","rc":[{"batl":[[1,1.86,1.67],[2,3,1.37]],"ltp":1.7,"tv":2102.04,"id":11674133}]}]}
{"op":"mcm","clk":"11766303661","pt":1722604592686,"mc":[{"id":"1.231295013","rc":[{"batl":[[0,2.42,86.82]],"ltp":2.34,"tv":676.68,"id":71234216},{"batl":[[0,1.75,151.29]],"ltp":1.7,"tv":2102.04,"id":11674133}]}]}
{"op":"mcm","clk":"11766303966","pt":1722604601663,"mc":[{"id":"1.231295013","rc":[{"trd":[[2.4,23.6]],"ltp":2.4,"tv":685.7,"id":71234216}],"tv":2787.74}]}
{"op":"mcm","clk":"11766304157","pt":1722604607775,"mc":[{"id":"1.231295013","rc":[{"batb":[[0,2.34,15.96]],"ltp":2.4,"tv":685.7,"id":71234216},{"batb":[[0,1.71,21.9]],"ltp":1.7,"tv":2102.04,"id":11674133}]}]}
{"op":"mcm","clk":"11766304175","pt":1722604608498,"mc":[{"id":"1.231295013","rc":[{"trd":[[2.34,122.35]],"batb":[[0,2.34,15.94]],"ltp":2.34,"tv":685.74,"id":71234216}],"tv":2787.78}]}
{"op":"mcm","clk":"11766304214","pt":1722604610400,"mc":[{"id":"1.231295013","rc":[{"batb":[[0,2.34,16.94]],"ltp":2.34,"tv":685.74,"id":71234216}]}]}
{"op":"mcm","clk":"11766304848","pt":1722604630097,"mc":[{"id":"1.231295013","rc":[{"batl":[[2,2.8,7.21]],"ltp":2.34,"tv":685.74,"id":71234216}]}]}
{"op":"mcm","clk":"11766305434","pt":1722604648047,"mc":[{"id":"1.231295013","rc":[{"trd":[[2.34,124.15]],"batb":[[0,2.34,16.05]],"ltp":2.34,"tv":687.54,"id":71234216}],"tv":2789.58}]}
{"op":"mcm","clk":"11766306219","pt":1722604669642,"mc":[{"id":"1.231295013","rc":[{"trd":[[1.71,23.81]],"batb":[[0,1.71,13.89]],"ltp":1.71,"tv":2118.04,"id":11674133}],"tv":2805.58}]}
{"op":"mcm","clk":"11766306343","pt":1722604673329,"mc":[{"id":"1.231295013","rc":[{"batl":[[0,1.74,8],[1,1.75,151.29],[2,1.86,1.67]],"ltp":1.71,"tv":2118.04,"id":11674133}]}]}
{"op":"mcm","clk":"11766306513","pt":1722604678353,"mc":[{"id":"1.231295013","rc":[{"trd":[[1.71,24.15]],"batb":[[0,1.71,13.73]],"ltp":1.71,"tv":2118.38,"id":11674133}],"tv":2805.92}]}
{"op":"mcm","clk":"11766306703","pt":1722604683173,"mc":[{"id":"1.231295013","rc":[{"batb":[[0,1.72,4],[1,1.71,13.73],[2,1.7,25.52]],"batl":[[0,1.74,12]],"ltp":1.71,"tv":2118.38,"id":11674133}]}]}
{"op":"mcm","clk":"11766307048","pt":1722604690496,"mc":[{"id":"1.231295013","rc":[{"trd":[[1.72,13.93]],"batb":[[0,1.71,13.73],[1,1.7,25.52],[2,1.69,25.89]],"batl":[[0,1.72,4],[1,1.74,12],[2,1.75,151.29]],"ltp":1.72,"tv":2126.38,"id":11674133}],"tv":2813.92}]}
{"op":"mcm","clk":"11766307086","pt":1722604691483,"mc":[{"id":"1.231295013","rc":[{"batb":[[0,2.34,29.38]],"ltp":2.34,"tv":687.54,"id":71234216}]}]}
{"op":"mcm","clk":"11766307181","pt":1722604693781,"mc":[{"id":"1.231295013","rc":[{"batl":[[1,1.74,4]],"ltp":1.72,"tv":2126.38,"id":11674133}]}]}
{"op":"mcm","clk":"11766307367","pt":1722604697480,"mc":[{"id":"1.231295013","rc":[{"batl":[[0,2.42,4]],"ltp":2.34,"tv":687.54,"id":71234216},{"batb":[[1,1.69,25.89],[2,1.68,27.4]],"batl":[[0,1.72,6.71]],"ltp":1.72,"tv":2126.38,"id":11674133}]}]}
{"op":"mcm","clk":"11766307615","pt":1722604703097,"mc":[{"id":"1.231295013","rc":[{"batb":[[0,1.71,4]],"ltp":1.72,"tv":2126.38,"id":11674133}]}]}
{"op":"mcm","clk":"11766307628","pt":1722604703286,"mc":[{"id":"1.231295013","rc":[{"trd":[[2.38,3.34]],"ltp":2.38,"tv":689.79,"id":71234216},{"trd":[[1.72,17.04]],"batb":[[1,1.7,9.73],[2,1.69,25.89]],"batl":[[0,1.72,3.6]],"ltp":1.72,"tv":2129.49,"id":11674133}],"tv":2819.28}]}
{"op":"mcm","clk":"11766307751","pt":1722604706402,"mc":[{"id":"1.231295013","rc":[{"batb":[[0,2.34,30.27]],"ltp":2.38,"tv":689.79,"id":71234216}]}]}
{"op":"mcm","clk":"11766307901","pt":1722604710120,"mc":[{"id":"1.231295013","rc":[{"trd":[[1.71,32.15]],"batb":[[0,1.7,9.73],[1,1.69,25.89],[2,1.68,27.4]],"ltp":1.71,"tv":2137.49,"id":11674133}],"tv":2827.28}]}
{"op":"mcm","clk":"11766307935","pt":1722604711120,"mc":[{"id":"1.231295013","rc":[{"batl":[[0,2.42,16.64]],"ltp":2.38,"tv":689.79,"id":71234216}]}]}
{"op":"mcm","clk":"11766307991","pt":1722604712518,"mc":[{"id":"1.231295013","rc":[{"trd":[[1.72,18.82],[1.74,81.91]],"batl":[[0,1.74,3.89],[1,1.75,151.29],[2,1.86,1.67]],"ltp":1.74,"tv":2139.49,"id":11674133}],"tv":2829.28}]}
{"op":"mcm","clk":"11766308038","pt":1722604713404,"mc":[{"id":"1.231295013","rc":[{"batb":[[0,2.36,4],[1,2.34,30.27],[2,2.32,13.53]],"ltp":2.38,"tv":689.79,"id":71234216},{"batb":[[0,1.7,13.73]],"ltp":1.74,"tv":2139.49,"id":11674133}]}]}
{"op":"mcm","clk":"11766308213","pt":1722604718695,"mc":[{"id":"1.231295013","rc":[{"batb":[[0,1.7,21.77]],"ltp":1.74,"tv":2139.49,"id":11674133}]}]}
{"op":"mcm","clk":"11766308506","pt":1722604727946,"mc":[{"id":"1.231295013","rc":[{"trd":[[1.7,443.29]],"batb":[[0,1.7,19.07]],"ltp":1.7,"tv":2144.91,"id":11674133}],"tv":2834.7}]}
{"op":"mcm","clk":"11766308912","pt":1722604739514,"mc":[{"id":"1.231295013","rc":[{"trd":[[2.36,4.23]],"batb":[[0,2.34,30.27],[1,2.32,13.53],[2,1.43,117.14]],"ltp":2.36,"tv":694.02,"id":71234216},{"trd":[[1.74,94.8]],"batl":[[0,1.75,151.29],[1,1.86,1.67],[2,3,1.37]],"ltp":1.74,"tv":2157.8,"id":11674133}],"tv":2851.82}]}
{"op":"mcm","clk":"11766309055","pt":1722604743533,"mc":[{"id":"1.231295013","rc":[{"batl":[[0,1.74,4],[1,1.75,151.29],[2,1.86,1.67]],"ltp":1.74,"tv":2157.8,"id":11674133}]}]}
{"op":"mcm","clk":"11766309198","pt":1722604746950,"mc":[{"id":"1.231295013","rc":[{"trd":[[2.34,124.88]],"batb":[[0,2.34,29.91]],"ltp":2.34,"tv":694.74,"id":71234216}],"tv":2852.55}]}
{"op":"mcm","clk":"11766310236","pt":1722604770056,"mc":[{"id":"1.231295013","rc":[{"trd":[[1.74,102.8]],"batl":[[0,1.75,151.29],[1,1.86,1.67],[2,3,1.37]],"ltp":1.74,"tv":2165.81,"id":11674133}],"tv":2860.55}]}
{"op":"mcm","clk":"11766310260","pt":1722604770786,"mc":[{"id":"1.231295013","rc":[{"batb":[[2,1.79,6.98]],"ltp":2.34,"tv":694.74,"id":71234216}]}]}
{"op":"mcm","clk":"11766310539","pt":1722604778388,"mc":[{"id":"1.231295013","rc":[{"batb":[[0,1.7,21.77]],"ltp":1.74,"tv":2165.81,"id":11674133}]}]}
{"op":"mcm","clk":"11766312062","pt":1722604817850,"mc":[{"id":"1.231295013","rc":[{"trd":[[2.42,286.62]],"batl":[[0,2.42,13.84]],"ltp":2.42,"tv":700.34,"id":71234216}],"tv":2866.15}]}
{"op":"mcm","clk":"11766312375","pt":1722604825759,"mc":[{"id":"1.231295013","rc":[{"trd":[[1.75,785.31]],"batl":[[0,1.75,143.81]],"ltp":1.75,"tv":2180.77,"id":11674133}],"tv":2881.12}]}
{"op":"mcm","clk":"11766312493","pt":1722604829030,"mc":[{"id":"1.231295013","rc":[{"trd":[[2.34,126.38]],"batb":[[0,2.34,15.83]],"ltp":2.34,"tv":701.84,"id":71234216}],"tv":2882.62}]}
{"op":"mcm","clk":"11766312566","pt":1722604831160,"mc":[{"id":"1.231295013","rc":[{"batl":[[2,2.8,10.78]],"ltp":2.34,"tv":701.84,"id":71234216}]}]}
{"op":"mcm","clk":"11766312784","pt":1722604836070,"mc":[{"id":"1.231295013","rc":[{"trd":[[1.7,480.71]],"batb":[[0,1.7,3.06]],"ltp":1.7,"tv":2218.2,"id":11674133}],"tv":2920.04}]}
{"op":"mcm","clk":"11766312921","pt":1722604838574,"mc":[{"id":"1.231295013","rc":[{"trd":[[2.34,130.82]],"batb":[[0,2.34,13.61]],"batl":[[2,2.8,7.21]],"ltp":2.34,"tv":706.29,"id":71234216}],"tv":2924.49}]}
{"op":"mcm","clk":"11766313290","pt":1722604846984,"mc":[{"id":"1.231295013","rc":[{"trd":[[1.75,805.22]],"batl":[[0,1.75,133.85]],"ltp":1.75,"tv":2238.11,"id":11674133}],"tv":2944.41}]}
{"op":"mcm","clk":"11766313303","pt":1722604847188,"mc":[{"id":"1.231295013","rc":[{"batl":[[0,2.42,13.95]],"ltp":2.34,"tv":706.29,"id":71234216}]}]}
{"op":"mcm","clk":"11766313397","pt":1722604849175,"mc":[{"id":"1.231295013","rc":[{"batl":[[0,2.4,4.11],[1,2.42,13.84],[2,2.44,68.36]],"ltp":2.34,"tv":706.29,"id":71234216},{"batb":[[0,1.7,7.06]],"batl":[[0,1.74,4],[1,1.75,133.85],[2,1.86,1.67]],"ltp":1.75,"tv":2238.11,"id":11674133}]}]}
{"op":"mcm","clk":"11766313494","pt":1722604851094,"mc":[{"id":"1.231295013","rc":[{"trd":[[2.34,131.57]],"batb":[[0,2.34,13.24]],"ltp":2.34,"tv":707.03,"id":71234216},{"trd":[[1.73,4.12]],"batb":[[0,1.7,32.58]],"ltp":1.73,"tv":2242.23,"id":11674133}],"tv":2949.27}]}
{"op":"mcm","clk":"11766313828","pt":1722604859096,"mc":[{"id":"1.231295013","rc":[{"trd":[[2.34,133.07]],"batb":[[0,2.34,12.49]],"ltp":2.34,"tv":708.53,"id":71234216}],"tv":2950.77}]}
{"op":"mcm","clk":"11766313865","pt":1722604859980,"mc":[{"id":"1.231295013","rc":[{"batl":[[0,2.4,4]],"ltp":2.34,"tv":708.53,"id":71234216}]}]}
{"op":"mcm","clk":"11766313944","pt":1722604861595,"mc":[{"id":"1.231295013","rc":[{"trd":[[2.4,31.6]],"batb":[[0,2.4,5.02],[1,2.34,12.49],[2,2.32,13.53]],"batl":[[0,2.42,13.84],[1,2.44,68.36],[2,2.8,7.21]],"ltp":2.4,"tv":716.53,"id":71234216},{"batb":[[0,1.7,7.06]],"ltp":1.73,"tv":2242.23,"id":11674133}],"tv":2958.77}]}
{"op":"mcm","clk":"11766314007","pt":1722604862991,"mc":[{"id":"1.231295013","rc":[{"batb":[[1,2.34,25.82]],"ltp":2.4,"tv":716.53,"id":71234216},{"batl":[[0,1.74,4.12]],"ltp":1.73,"tv":2242.23,"id":11674133}]}]}
{"op":"mcm","clk":"11766314178","pt":1722604867009,"mc":[{"id":"1.231295013","rc":[{"trd":[[2.4,38.89]],"batb":[[0,2.4,1.38]],"ltp":2.4,"tv":723.82,"id":71234216}],"tv":2966.05}]}
{"op":"mcm","clk":"11766314230","pt":1722604868202,"mc":[{"id":"1.231295013","rc":[{"trd":[[2.4,39.11]],"batb":[[0,2.4,1.27]],"ltp":2.4,"tv":724.04,"id":71234216}],"tv":2966.27}]}
{"op":"mcm","clk":"11766314295","pt":1722604869497,"mc":[{"id":"1.231295013","rc":[{"trd":[[2.42,300.46]],"batl":[[0,2.44,68.36],[1,2.8,7.21],[2,3,5.94]],"ltp":2.42,"tv":737.88,"id":71234216},{"trd":[[1.7,514.54]],"batb":[[0,1.68,27.4],[1,1.66,221.84],[2,1.65,27.49]],"batl":[[0,1.7,879.87],[1,1.74,4.12],[2,1.75,4]],"ltp":1.7,"tv":2276.06,"id":11674133}],"tv":3013.95}]}
{"op":"mcm","clk":"11766314338","pt":1722604870995,"mc":[{"id":"1.231295013","rc":[{"batb":[[0,2.4,14.03]],"ltp":2.42,"tv":737.88,"id":71234216}]}]}
{"op":"mcm","clk":"11766314477","pt":1722604874517,"mc":[{"id":"1.231295013","rc":[{"batb":[[1,1.66,27.07]],"ltp":1.7,"tv":2276.06,"id":11674133}]}]}
{"op":"mcm","clk":"11766314603","pt":1722604877692,"mc":[{"id":"1.231295013","rc":[{"batb":[[1,2.34,17.33]],"batl":[[0,2.44,77.19]],"ltp":2.42,"tv":737.88,"id":71234216}]}]}
{"op":"mcm","clk":"11766314677","pt":1722604879302,"mc":[{"id":"1.231295013","rc":[{"batb":[[0,2.42,4],[1,2.4,14.03],[2,2.34,17.33]],"ltp":2.42,"tv":737.88,"id":71234216},{"batl":[[0,1.7,883.87]],"ltp":1.7,"tv":2276.06,"id":11674133}]}]}
{"op":"mcm","clk":"11766314730","pt":1722604880911,"mc":[{"id":"1.231295013","rc":[{"batl":[[1,1.74,4]],"ltp":1.7,"tv":2276.06,"id":11674133}]}]}
{"op":"mcm","clk":"11766314903","pt":1722604886034,"mc":[{"id":"1.231295013","rc":[{"batl":[[0,1.7,905.83]],"ltp":1.7,"tv":2276.06,"id":11674133}]}]}
{"op":"mcm","clk":"11766315027","pt":1722604888722,"mc":[{"id":"1.231295013","rc":[{"trd":[[1.7,517.54]],"batl":[[0,1.7,904.33]],"ltp":1.7,"tv":2279.06,"id":11674133}],"tv":3016.94}]}
{"op":"mcm","clk":"11766315413","pt":1722604897233,"mc":[{"id":"1.231295013","rc":[{"trd":[[2.42,300.74]],"batb":[[0,2.42,3.86]],"ltp":2.42,"tv":738.16,"id":71234216}],"tv":3017.22}]}
{"op":"mcm","clk":"11766315472","pt":1722604898844,"mc":[{"id":"1.231295013","rc":[{"trd":[[2.42,301.26]],"batb":[[0,2.42,3.6]],"ltp":2.42,"tv":738.68,"id":71234216}],"tv":3017.75}]}
{"op":"mcm","clk":"11766315563","pt":1722604900917,"mc":[{"id":"1.231295013","rc":[{"trd":[[2.42,301.58]],"batb":[[0,2.42,3.44]],"ltp":2.42,"tv":739.0,"id":71234216}],"tv":3018.06}]}
{"op":"mcm","clk":"11766315729","pt":1722604904934,"mc":[{"id":"1.231295013","rc":[{"trd":[[2.42,305.22]],"batb":[[0,2.42,1.62]],"ltp":2.42,"tv":742.64,"id":71234216}],"tv":3021.7}]}
{"op":"mcm","clk":"11766315863","pt":1722604908658,"mc":[{"id":"1.231295013","rc":[{"batl":[[2,3,2.37]],"ltp":2.42,"tv":742.64,"id":71234216}]}]}
{"op":"mcm","clk":"11766316162","pt":1722604915252,"mc":[{"id":"1.231295013","rc":[{"trd":[[1.7,517.76]],"batl":[[0,1.7,904.22]],"ltp":1.7,"tv":2279.28,"id":11674133}],"tv":3021.92}]}
{"op":"mcm","clk":"11766316719","pt":1722604926672,"mc":[{"id":"1.231295013","rc":[{"trd":[[2.42,356.84]],"batb":[[0,2.4,14.03],[1,2.34,17.33],[2,2.32,13.53]],"ltp":2.42,"tv":794.26,"id":71234216},{"trd":[[1.7,586.63]],"batl":[[0,1.7,835.35]],"ltp":1.7,"tv":2348.15,"id":11674133}],"tv":3142.41}]}
{"op":"mcm","clk":"11766316744","pt":1722604927248,"mc":[{"id":"1.231295013","rc":[{"trd":[[2.42,359.83]],"ltp":2.42,"tv":797.25,"id":71234216},{"trd":[[1.7,590.89]],"batl":[[0,1.7,831.09]],"ltp":1.7,"tv":2352.41,"id":11674133}],"tv":3149.67}]}
{"op":"mcm","clk":"11766317228","pt":1722604938881,"mc":[{"id":"1.231295013","rc":[{"batl":[[0,1.7,829.51]],"ltp":1.7,"tv":2352.41,"id":11674133}]}]}
{"op":"mcm","clk":"11766317258","pt":1722604939655,"mc":[{"id":"1.231295013","rc":[{"batb":[[0,2.42,4],[1,2.4,14.03],[2,2.34,17.33]],"ltp":2.42,"tv":797.25,"id":71234216}]}]}
{"op":"mcm","clk":"11766317298","pt":1722604940581,"mc":[{"id":"1.231295013","rc":[{"trd":[[1.7,592.17]],"batl":[[0,1.7,828.87]],"ltp":1.7,"tv":2353.69,"id":11674133}],"tv":3150.94}]}
{"op":"mcm","clk":"11766317685","pt":1722604951582,"mc":[{"id":"1.231295013","rc":[{"trd":[[2.42,360.06]],"batb":[[0,2.42,3.89]],"ltp":2.42,"tv":797.47,"id":71234216}],"tv":3151.17}]}
{"op":"mcm","clk":"11766318012","pt":1722604960093,"mc":[{"id":"1.231295013","rc":[{"batl":[[2,3,5.94]],"ltp":2.42,"tv":797.47,"id":71234216}]}]}
{"op":"mcm","clk":"11766318388","pt":1722604970015,"mc":[{"id":"1.231295013","rc":[{"trd":[[2.42,360.86]],"batb":[[0,2.42,3.49]],"ltp":2.42,"tv":798.28,"id":71234216}],"tv":3151.97}]}
{"op":"mcm","clk":"11766318465","pt":1722604972828,"mc":[{"id":"1.231295013","rc":[{"trd":[[2.42,395.51]],"batb":[[0,2.4,14.03],[1,2.34,17.33],[2,2.32,13.53]],"ltp":2.42,"tv":832.93,"id":71234216},{"trd":[[1.7,631.56]],"batl":[[0,1.7,789.48]],"ltp":1.7,"tv":2393.08,"id":11674133}],"tv":3226.01}]}
{"op":"mcm","clk":"11766318519","pt":1722604974630,"mc":[{"id":"1.231295013","rc":[{"trd":[[2.42,396.73]],"ltp":2.42,"tv":834.14,"id":71234216},{"trd":[[1.7,633.29]],"batl":[[0,1.7,787.75]],"ltp":1.7,"tv":2394.81,"id":11674133}],"tv":3228.96}]}
{"op":"mcm","clk":"11766318784","pt":1722604981951,"mc":[{"id":"1.231295013","rc":[{"trd":[[2.42,404.58]],"ltp":2.42,"tv":842.0,"id":71234216},{"trd":[[1.7,644.48]],"batl":[[0,1.7,776.56]],"ltp":1.7,"tv":2406.0,"id":11674133}],"tv":3248.0}]}
{"op":"mcm","clk":"11766318835","pt":1722604983027,"mc":[{"id":"1.231295013","rc":[{"trd":[[2.42,405.33]],"ltp":2.42,"tv":842.75,"id":71234216},{"trd":[[1.7,645.55]],"batl":[[0,1.7,775.49]],"ltp":1.7,"tv":2407.07,"id":11674133}],"tv":3249.82}]}
{"op":"mcm","clk":"11766318898","pt":1722604984909,"mc":[{"id":"1.231295013","rc":[{"batb":[[0,2.42,4],[1,2.4,14.03],[2,2.34,17.33]],"ltp":2.42,"tv":842.75,"id":71234216}]}]}
{"op":"mcm","clk":"11766319070","pt":1722604989822,"mc":[{"id":"1.231295013","rc":[{"trd":[[2.42,405.55]],"batb":[[0,2.42,3.89]],"ltp":2.42,"tv":842.97,"id":71234216}],"tv":3250.04}]}
{"op":"mcm","clk":"11766319090","pt":1722604990547,"mc":[{"id":"1.231295013","rc":[{"trd":[[2.42,406.07]],"batb":[[0,2.42,3.63]],"ltp":2.42,"tv":843.49,"id":71234216}],"tv":3250.56}]}
{"op":"mcm","clk":"11766319159","pt":1722604991958,"mc":[{"id":"1.231295013","rc":[{"trd":[[2.44,53.2]],"batl":[[0,2.44,76.41]],"ltp":2.44,"tv":844.27,"id":71234216},{"trd":[[1.69,83.36]],"ltp":1.69,"tv":2408.19,"id":11674133}],"tv":3252.47}]}
{"op":"mcm","clk":"11766319184","pt":1722604992541,"mc":[{"id":"1.231295013","rc":[{"trd":[[2.42,406.11]],"batb":[[0,2.42,3.61]],"ltp":2.42,"tv":844.31,"id":71234216}],"tv":3252.51}]}
{"op":"mcm","clk":"11766319311","pt":1722604996437,"mc":[{"id":"1.231295013","rc":[{"trd":[[2.42,406.64]],"batb":[[0,2.42,3.35]],"ltp":2.42,"tv":844.83,"id":71234216}],"tv":3253.03}]}
{"op":"mcm","clk":"11766319475","pt":1722605000044,"mc":[{"id":"1.231295013","rc":[{"trd":[[2.44,54.76]],"batl":[[0,2.44,74.85]],"ltp":2.44,"tv":846.39,"id":71234216},{"trd":[[1.69,85.61],[1.7,647.04]],"batl":[[0,1.7,774.74]],"ltp":1.69,"tv":2411.94,"id":11674133}],"tv":3258.34}]}
{"op":"mcm","clk":"11766319648","pt":1722605004929,"mc":[{"id":"1.231295013","rc":[{"batl":[[1,1.71,45.59],[2,1.74,4]],"ltp":1.69,"tv":2411.94,"id":11674133}]}]}
{"op":"mcm","clk":"11766319758","pt":1722605007944,"mc":[{"id":"1.231295013","rc":[{"trd":[[2.42,407.24]],"batb":[[0,2.42,3.05]],"ltp":2.42,"tv":847.0,"id":71234216}],"tv":3258.94}]}
{"op":"mcm","clk":"11766319791","pt":1722605008870,"mc":[{"id":"1.231295013","rc":[{"trd":[[1.7,847.04]],"batl":[[0,1.7,674.74]],"ltp":1.7,"tv":2611.94,"id":11674133}],"tv":3458.94}]}
{"op":"mcm","clk":"11766319880","pt":1722605010957,"mc":[{"id":"1.231295013","rc":[{"trd":[[2.42,407.44]],"batb":[[0,2.42,2.95]],"ltp":2.42,"tv":847.2,"id":71234216}],"tv":3459.14}]}
{"op":"mcm","clk":"11766319928","pt":1722605012043,"mc":[{"id":"1.231295013","rc":[{"trd":[[2.42,409.24]],"batb":[[0,2.42,2.05]],"ltp":2.42,"tv":849.0,"id":71234216}],"tv":3460.94}]}
{"op":"mcm","clk":"11766319955","pt":1722605012663,"mc":[{"id":"1.231295013","rc":[{"trd":[[2.42,409.98]],"batb":[[0,2.42,1.68]],"ltp":2.42,"tv":849.74,"id":71234216},{"batl":[[0,1.7,672.36]],"ltp":1.7,"tv":2611.94,"id":11674133}],"tv":3461.68}]}
{"op":"mcm","clk":"11766320239","pt":1722605020566,"mc":[{"id":"1.231295013","rc":[{"trd":[[2.42,414.28]],"batb":[[0,2.4,14.03],[1,2.34,17.33],[2,2.32,13.53]],"ltp":2.42,"tv":854.04,"id":71234216},{"trd":[[1.7,848.38]],"batl":[[0,1.7,671.02]],"ltp":1.7,"tv":2613.28,"id":11674133}],"tv":3467.32}]}
{"op":"mcm","clk":"11766320306","pt":1722605022056,"mc":[{"id":"1.231295013","rc":[{"trd":[[1.7,855.99]],"batl":[[0,1.7,667.32]],"ltp":1.7,"tv":2620.88,"id":11674133}],"tv":3474.92}]}
{"op":"mcm","clk":"11766320460","pt":1722605025996,"mc":[{"id":"1.231295013","rc":[{"trd":[[2.42,416.1]],"ltp":2.42,"tv":855.86,"id":71234216},{"trd":[[1.7,858.58]],"batl":[[0,1.7,664.73]],"ltp":1.7,"tv":2623.47,"id":11674133}],"tv":3479.34}]}
{"op":"mcm","clk":"11766320632","pt":1722605030154,"mc":[{"id":"1.231295013","rc":[{"batb":[[0,2.42,4],[1,2.4,14.03],[2,2.34,17.33]],"ltp":2.42,"tv":855.86,"id":71234216}]}]}
{"op":"mcm","clk":"11766320745","pt":1722605033163,"mc":[{"id":"1.231295013","rc":[{"trd":[[1.7,876.62]],"batl":[[0,1.7,655.71]],"ltp":1.7,"tv":2641.51,"id":11674133}],"tv":3497.38}]}
{"op":"mcm","clk":"11766321094","pt":1722605041111,"mc":[{"id":"1.231295013","rc":[{"trd":[[2.44,129.6]],"batl":[[0,2.8,7.21],[1,3,5.94],[2,5,1.15]],"ltp":2.44,"tv":930.71,"id":71234216},{"trd":[[1.69,193.67]],"batl":[[0,1.69,35.79],[1,1.7,655.71],[2,1.71,45.59]],"ltp":1.69,"tv":2749.57,"id":11674133}],"tv":3680.28}]}
{"op":"mcm","clk":"11766321148","pt":1722605042169,"mc":[{"id":"1.231295013","rc":[{"batb":[[0,2.44,12],[1,2.42,16.58],[2,2.4,14.03]],"batl":[[0,2.5,3.63],[1,2.8,7.21],[2,3,5.94]],"ltp":2.44,"tv":930.71,"id":71234216},{"batb":[[0,1.68,1.13],[1,1.56,579.63],[2,1.43,116.28]],"ltp":1.69,"tv":2749.57,"id":11674133}]}]}
{"op":"mcm","clk":"11766321184","pt":1722605043000,"mc":[{"id":"1.231295013","rc":[{"trd":[[1.69,220.73]],"batl":[[0,1.69,22.26],[1,1.7,655.61]],"ltp":1.69,"tv":2776.63,"id":11674133}],"tv":3707.34}]}
{"op":"mcm","clk":"11766321250","pt":1722605044100,"mc":[{"id":"1.231295013","rc":[{"batb":[[0,2.44,10]],"batl":[[0,2.8,7.21],[1,3,5.94],[2,5,1.15]],"ltp":2.44,"tv":930.71,"id":71234216},{"batb":[[1,1.57,20.39],[2,1.56,578.73]],"ltp":1.69,"tv":2776.63,"id":11674133}]}]}
{"op":"mcm","clk":"11766321280","pt":1722605044671,"mc":[{"id":"1.231295013","rc":[{"batb":[[0,2.42,16.58],[1,2.4,14.03],[2,2.34,17.33]],"ltp":2.44,"tv":930.71,"id":71234216}]}]}
{"op":"mcm","clk":"11766321308","pt":1722605045294,"mc":[{"id":"1.231295013","rc":[{"batl":[[0,1.69,26.26]],"ltp":1.69,"tv":2776.63,"id":11674133}]}]}
{"op":"mcm","clk":"11766321467","pt":1722605048778,"mc":[{"id":"1.231295013","rc":[{"batl":[[0,2.78,3.26],[1,2.8,7.21],[2,3,5.94]],"ltp":2.44,"tv":930.71,"id":71234216}]}]}
{"op":"mcm","clk":"11766321559","pt":1722605050904,"mc":[{"id":"1.231295013","rc":[{"batb":[[0,2.44,12],[1,2.42,16.58],[2,2.4,14.03]],"ltp":2.44,"tv":930.71,"id":71234216}]}]}
{"op":"mcm","clk":"11766321651","pt":1722605052722,"mc":[{"id":"1.231295013","rc":[{"trd":[[1.69,221.79]],"batb":[[2,1.56,598.26]],"batl":[[0,1.69,43.73],[1,1.7,637.61]],"ltp":1.69,"tv":2777.7,"id":11674133}],"tv":3708.41}]}
{"op":"mcm","clk":"11766321754","pt":1722605054707,"mc":[{"id":"1.231295013","rc":[{"batb":[[0,2.44,10]],"ltp":2.44,"tv":930.71,"id":71234216},{"batl":[[0,1.69,73.73]],"ltp":1.69,"tv":2777.7,"id":11674133}]}]}
{"op":"mcm","clk":"11766321782","pt":1722605055223,"mc":[{"id":"1.231295013","rc":[{"batb":[[0,2.42,16.58],[1,2.4,14.03],[2,2.34,17.33]],"ltp":2.44,"tv":930.71,"id":71234216}]}]}
{"op":"mcm","clk":"11766321880","pt":1722605057612,"mc":[{"id":"1.231295013","rc":[{"batb":[[0,2.44,12],[1,2.42,16.58],[2,2.4,14.03]],"ltp":2.44,"tv":930.71,"id":71234216},{"batb":[[2,1.56,578.73]],"ltp":1.69,"tv":2777.7,"id":11674133}]}]}
{"op":"mcm","clk":"11766321952","pt":1722605059021,"mc":[{"id":"1.231295013","rc":[{"batb":[[2,1.56,598.26]],"ltp":1.69,"tv":2777.7,"id":11674133}]}]}
{"op":"mcm","clk":"11766321986","pt":1722605059910,"mc":[{"id":"1.231295013","rc":[{"trd":[[2.44,130.61]],"batb":[[0,2.44,9.5]],"ltp":2.44,"tv":931.71,"id":71234216},{"batb":[[1,1.57,39.92]],"ltp":1.69,"tv":2777.7,"id":11674133}],"tv":3709.41}]}
{"op":"mcm","clk":"11766322043","pt":1722605061104,"mc":[{"id":"1.231295013","rc":[{"batb":[[0,2.42,16.58],[1,2.4,14.03],[2,2.34,17.33]],"ltp":2.44,"tv":931.71,"id":71234216},{"batl":[[0,1.69,73.88]],"ltp":1.69,"tv":2777.7,"id":11674133}]}]}
{"op":"mcm","clk":"11766322078","pt":1722605061822,"mc":[{"id":"1.231295013","rc":[{"batb":[[1,1.57,20.39],[2,1.56,578.73]],"ltp":1.69,"tv":2777.7,"id":11674133}]}]}
{"op":"mcm","clk":"11766322121","pt":1722605062916,"mc":[{"id":"1.231295013","rc":[{"batb":[[0,2.44,2],[1,2.42,16.58],[2,2.4,14.03]],"ltp":2.44,"tv":931.71,"id":71234216},{"batb":[[1,1.57,59.45]],"ltp":1.69,"tv":2777.7,"id":11674133}]}]}
{"op":"mcm","clk":"11766322133","pt":1722605063326,"mc":[{"id":"1.231295013","rc":[{"batb":[[1,1.59,20.43],[2,1.58,19.53]],"ltp":1.69,"tv":2777.7,"id":11674133}]}]}
{"op":"mcm","clk":"11766322193","pt":1722605064730,"mc":[{"id":"1.231295013","rc":[{"batb":[[0,1.59,20.43],[1,1.58,19.53],[2,1.57,89.89]],"batl":[[0,1.68,900.49],[1,1.69,73.88],[2,1.7,637.61]],"ltp":1.69,"tv":2777.7,"id":11674133}]}]}
{"op":"mcm","clk":"11766322248","pt":1722605065916,"mc":[{"id":"1.231295013","rc":[{"batb":[[0,2.44,22.4]],"ltp":2.44,"tv":931.71,"id":71234216},{"batb":[[1,1.58,30.8],[2,1.57,50.83]],"ltp":1.69,"tv":2777.7,"id":11674133}]}]}
{"op":"mcm","clk":"11766322261","pt":1722605066327,"mc":[{"id":"1.231295013","rc":[{"batb":[[1,1.57,50.83],[2,1.56,578.73]],"ltp":1.69,"tv":2777.7,"id":11674133}]}]}
{"op":"mcm","clk":"11766322381","pt":1722605069128,"mc":[{"id":"1.231295013","rc":[{"batb":[[0,2.46,2],[1,2.44,12.4],[2,2.42,16.58]],"ltp":2.44,"tv":931.71,"id":71234216},{"batb":[[0,1.57,20.39],[1,1.56,578.73],[2,1.43,116.28]],"ltp":1.69,"tv":2777.7,"id":11674133}]}]}
{"op":"mcm","clk":"11766322431","pt":1722605070015,"mc":[{"id":"1.231295013","rc":[{"batb":[[0,1.62,1.92],[1,1.57,19.49],[2,1.56,578.73]],"ltp":1.69,"tv":2777.7,"id":11674133}]}]}
{"op":"mcm","clk":"11766322466","pt":1722605070799,"mc":[{"id":"1.231295013","rc":[{"batb":[[0,2.44,12.4],[1,2.42,16.58],[2,2.4,14.03]],"ltp":2.44,"tv":931.71,"id":71234216}]}]}
{"op":"mcm","clk":"11766322531","pt":1722605072105,"mc":[{"id":"1.231295013","rc":[{"trd":[[2.48,4.75]],"batb":[[0,2.48,11.96],[1,2.46,10],[2,2.44,12.4]],"ltp":2.48,"tv":932.46,"id":71234216},{"trd":[[1.68,80.02]],"batb":[[1,1.61,1.02],[2,1.57,19.49]],"batl":[[0,1.68,878.26]],"ltp":1.68,"tv":2813.14,"id":11674133}],"tv":3745.6}]}
{"op":"mcm","clk":"11766322563","pt":1722605072732,"mc":[{"id":"1.231295013","rc":[{"batb":[[1,2.46,22.23]],"ltp":2.48,"tv":932.46,"id":71234216}]}]}
{"op":"mcm","clk":"11766322628","pt":1722605074028,"mc":[{"id":"1.231295013","rc":[{"batl":[[0,2.8,7.54],[1,3,5.94],[2,5,1.15]],"ltp":2.48,"tv":932.46,"id":71234216},{"batb":[[0,1.61,8.9],[1,1.57,19.49],[2,1.56,578.73]],"ltp":1.68,"tv":2813.14,"id":11674133}]}]}
{"op":"mcm","clk":"11766322694","pt":1722605075433,"mc":[{"id":"1.231295013","rc":[{"batb":[[0,2.5,2],[1,2.48,11.96],[2,2.46,12.23]],"ltp":2.48,"tv":932.46,"id":71234216}]}]}
{"op":"mcm","clk":"11766322749","pt":1722605076739,"mc":[{"id":"1.231295013","rc":[{"batl":[[0,1.67,25.09],[1,1.68,878.26],[2,1.69,55.88]],"ltp":1.68,"tv":2813.14,"id":11674133}]}]}
{"op":"mcm","clk":"11766322813","pt":1722605077939,"mc":[{"id":"1.231295013","rc":[{"batb":[[0,1.62,30.9],[1,1.61,8],[2,1.57,19.49]],"ltp":1.68,"tv":2813.14,"id":11674133}]}]}
{"op":"mcm","clk":"11766322851","pt":1722605078820,"mc":[{"id":"1.231295013","rc":[{"trd":[[2.5,0.77]],"batb":[[0,2.5,1.89]],"ltp":2.5,"tv":932.68,"id":71234216}],"tv":3745.82}]}
{"op":"mcm","clk":"11766322882","pt":1722605079639,"mc":[{"id":"1.231295013","rc":[{"batb":[[0,2.48,24.04],[1,2.46,12.23],[2,2.44,12.4]],"ltp":2.5,"tv":932.68,"id":71234216},{"batb":[[2,1.6,8]],"ltp":1.68,"tv":2813.14,"id":11674133}]}]}
{"op":"mcm","clk":"11766322947","pt":1722605081115,"mc":[{"id":"1.231295013","rc":[{"batb":[[0,2.5,10],[1,2.48,11.96],[2,2.46,12.23]],"ltp":2.5,"tv":932.68,"id":71234216},{"trd":[[1.67,120.18],[1.68,109.98]],"batb":[[1,1.61,37.29]],"batl":[[0,1.68,863.28],[1,1.69,55.88],[2,1.7,637.61]],"ltp":1.68,"tv":2893.28,"id":11674133}],"tv":3825.96}]}
{"op":"mcm","clk":"11766322978","pt":1722605081947,"mc":[{"id":"1.231295013","rc":[{"batb":[[0,2.5,12]],"ltp":2.5,"tv":932.68,"id":71234216},{"batb":[[0,1.62,152.42]],"ltp":1.68,"tv":2893.28,"id":11674133}]}]}
{"op":"mcm","clk":"11766323069","pt":1722605083870,"mc":[{"id":"1.231295013","rc":[{"batb":[[1,2.48,24.04]],"ltp":2.5,"tv":932.68,"id":71234216},{"batb":[[0,1.62,182.42]],"ltp":1.68,"tv":2893.28,"id":11674133}]}]}
{"op":"mcm","clk":"11766323134","pt":1722605085164,"mc":[{"id":"1.231295013","rc":[{"trd":[[2.5,3.78]],"batb":[[0,2.48,24.04],[1,2.46,12.23],[2,2.44,12.4]],"ltp":2.5,"tv":935.69,"id":71234216},{"trd":[[1.67,124.68]],"batl":[[1,1.69,34.15]],"ltp":1.67,"tv":2897.78,"id":11674133}],"tv":3833.47}]}
{"op":"mcm","clk":"11766323168","pt":1722605085741,"mc":[{"id":"1.231295013","rc":[{"batb":[[0,2.48,11.96]],"ltp":2.5,"tv":935.69,"id":71234216}]}]}
{"op":"mcm","clk":"11766323213","pt":1722605086938,"mc":[{"id":"1.231295013","rc":[{"batb":[[0,1.63,157.14],[1,1.62,181.52],[2,1.61,37.29]],"batl":[[0,1.67,4.45],[1,1.68,863.28],[2,1.69,34.15]],"ltp":1.67,"tv":2897.78,"id":11674133}]}]}
{"op":"mcm","clk":"11766323231","pt":1722605087316,"mc":[{"id":"1.231295013","rc":[{"batb":[[0,2.5,2],[1,2.48,11.96],[2,2.46,12.23]],"ltp":2.5,"tv":935.69,"id":71234216},{"batb":[[1,1.62,210.33]],"ltp":1.67,"tv":2897.78,"id":11674133}]}]}
{"op":"mcm","clk":"11766323330","pt":1722605089655,"mc":[{"id":"1.231295013","rc":[{"trd":[[2.5,4]],"batb":[[0,2.5,10],[1,2.48,24.04]],"ltp":2.5,"tv":935.91,"id":71234216}],"tv":3833.69}]}
