{"op":"mcm","clk":"11784110122","pt":1722942331970,"mc":[{"id":"1.231502182","marketDefinition":{"bspMarket":false,"turnInPlayEnabled":true,"persistenceEnabled":true,"marketBaseRate":5.0,"eventId":"33472587","eventTypeId":"4","numberOfWinners":1,"bettingType":"ODDS","marketType":"MATCH_ODDS","marketTime":"2024-08-08T14:00:00.000Z","suspendTime":"2024-08-08T14:00:00.000Z","bspReconciled":false,"complete":true,"inPlay":false,"crossMatching":true,"runnersVoidable":false,"numberOfActiveRunners":2,"betDelay":0,"status":"OPEN","runners":[{"status":"ACTIVE","sortPriority":1,"id":26354927,"name":"Welsh Fire"},{"status":"ACTIVE","sortPriority":2,"id":26354924,"name":"Northern Superchargers"}],"regulators":["MR_INT"],"countryCode":"GB","discountAllowed":false,"timezone":"GMT","openDate":"2024-08-08T14:00:00.000Z","version":6059511783,"name":"Match Odds","eventName":"Welsh Fire v Northern Superchargers"},"rc":[{"batb":[[0,1.01,20]],"ltp":0.0,"tv":0.0,"id":26354927},{"batb":[[0,1.01,20]],"ltp":0.0,"tv":0.0,"id":26354924}]}]}
{"op":"mcm","clk":"11784110153","pt":1722942332077,"mc":[{"id":"1.231502182","rc":[{"batb":[[0,1.06,100],[1,1.05,100],[2,1.04,100]],"ltp":0.0,"tv":0.0,"id":26354927},{"batb":[[0,1.06,100],[1,1.05,100],[2,1.04,100]],"ltp":0.0,"tv":0.0,"id":26354924}]}]}
{"op":"mcm","clk":"11784110255","pt":1722942334032,"mc":[{"id":"1.231502182","marketDefinition":{"bspMarket":false,"turnInPlayEnabled":true,"persistenceEnabled":true,"marketBaseRate":5.0,"eventId":"33472587","eventTypeId":"4","numberOfWinners":1,"bettingType":"ODDS","marketType":"MATCH_ODDS","marketTime":"2024-08-08T14:00:00.000Z","suspendTime":"2024-08-08T14:00:00.000Z","bspReconciled":false,"complete":true,"inPlay":false,"crossMatching":true,"runnersVoidable":false,"numberOfActiveRunners":2,"betDelay":0,"status":"OPEN","runners":[{"status":"ACTIVE","sortPriority":1,"id":26354927,"name":"Welsh Fire"},{"status":"ACTIVE","sortPriority":2,"id":26354924,"name":"Northern Superchargers"}],"regulators":["MR_INT"],"countryCode":"GB","discountAllowed":true,"timezone":"GMT","openDate":"2024-08-08T14:00:00.000Z","version":6059511783,"name":"Match Odds","eventName":"Welsh Fire v Northern Superchargers"}}]}
{"op":"mcm","clk":"11784835235","pt":1722955357416,"mc":[{"id":"1.231502182","rc":[{"batb":[[2,1.04,100.79]],"ltp":0.0,"tv":0.0,"id":26354927},{"batb":[[2,1.04,100.79]],"ltp":0.0,"tv":0.0,"id":26354924}]}]}
{"op":"mcm","clk":"11784836019","pt":1722955369212,"mc":[{"id":"1.231502182","rc":[{"batb":[[1,1.05,100.79]],"ltp":0.0,"tv":0.0,"id":26354927},{"batb":[[1,1.05,100.79]],"ltp":0.0,"tv":0.0,"id":26354924}]}]}
{"op":"mcm","clk":"11784897638","pt":1722956067990,"mc":[{"id":"1.231502182","rc":[{"batl":[[0,900,2.1]],"ltp":0.0,"tv":0.0,"id":26354927}]}]}
{"op":"mcm","clk":"11784899634","pt":1722956093017,"mc":[{"id":"1.231502182","rc":[{"batl":[[0,890,2.1]],"ltp":0.0,"tv":0.0,"id":26354927}]}]}
{"op":"mcm","clk":"11784999592","pt":1722957185798,"mc":[{"id":"1.231502182","rc":[{"batb":[[0,1.1,25000],[1,1.09,25000],[2,1.08,25000]],"ltp":0.0,"tv":0.0,"id":26354927},{"batb":[[0,1.1,25000],[1,1.09,25000],[2,1.08,25000]],"ltp":0.0,"tv":0.0,"id":26354924}]}]}
{"op":"mcm","clk":"11785389526","pt":1722960745996,"mc":[{"id":"1.231502182","rc":[{"batb":[[0,1.25,100],[1,1.1,25000],[2,1.09,25000]],"ltp":0.0,"tv":0.0,"id":26354927}]}]}
{"op":"mcm","clk":"11785389580","pt":1722960746412,"mc":[{"id":"1.231502182","rc":[{"batb":[[0,1.25,100],[1,1.1,25000],[2,1.09,25000]],"ltp":0.0,"tv":0.0,"id":26354924}]}]}
{"op":"mcm","clk":"11785415723","pt":1722960891999,"mc":[{"id":"1.231502182","rc":[{"batb":[[0,1.26,33.27],[1,1.25,100],[2,1.1,25000]],"ltp":0.0,"tv":0.0,"id":26354927},{"batb":[[0,1.26,33.27],[1,1.25,100],[2,1.1,25000]],"ltp":0.0,"tv":0.0,"id":26354924}]}]}
{"op":"mcm","clk":"11785439819","pt":1722961107518,"mc":[{"id":"1.231502182","rc":[{"batb":[[0,1.27,7.41],[1,1.26,33.27],[2,1.25,100]],"ltp":0.0,"tv":0.0,"id":26354927},{"batb":[[0,1.27,6.34],[1,1.26,33.27],[2,1.25,100]],"ltp":0.0,"tv":0.0,"id":26354924}]}]}
{"op":"mcm","clk":"11785627121","pt":1722962692954,"mc":[{"id":"1.231502182","rc":[{"batb":[[1,1.25,100],[2,1.1,25000]],"ltp":0.0,"tv":0.0,"id":26354924}]}]}
{"op":"mcm","clk":"11785627150","pt":1722962693160,"mc":[{"id":"1.231502182","rc":[{"batb":[[1,1.25,100],[2,1.1,25000]],"ltp":0.0,"tv":0.0,"id":26354927}]}]}
{"op":"mcm","clk":"11785635303","pt":1722962754078,"mc":[{"id":"1.231502182","rc":[{"batb":[[0,1.28,30.9],[1,1.27,7.41],[2,1.25,100]],"ltp":0.0,"tv":0.0,"id":26354927},{"batb":[[0,1.28,30.9],[1,1.27,6.34],[2,1.25,100]],"ltp":0.0,"tv":0.0,"id":26354924}]}]}
{"op":"mcm","clk":"11785637903","pt":1722962773925,"mc":[{"id":"1.231502182","rc":[{"batb":[[0,1.29,7.41],[1,1.28,30.9]],"ltp":0.0,"tv":0.0,"id":26354927}]}]}
{"op":"mcm","clk":"11785637959","pt":1722962774440,"mc":[{"id":"1.231502182","rc":[{"batb":[[0,1.29,6.34],[1,1.28,30.9]],"ltp":0.0,"tv":0.0,"id":26354924}]}]}
{"op":"mcm","clk":"11785842492","pt":1722964554708,"mc":[{"id":"1.231502182","rc":[{"batb":[[0,1.29,7.41],[1,1.25,100],[2,1.1,25000]],"ltp":0.0,"tv":0.0,"id":26354927},{"batb":[[0,1.29,6.34],[1,1.25,100],[2,1.1,25000]],"ltp":0.0,"tv":0.0,"id":26354924}]}]}
{"op":"mcm","clk":"11785849748","pt":1722964609851,"mc":[{"id":"1.231502182","rc":[{"batb":[[0,1.3,28.81],[1,1.29,7.41],[2,1.25,100]],"ltp":0.0,"tv":0.0,"id":26354927},{"batb":[[0,1.3,28.81],[1,1.29,6.34],[2,1.25,100]],"ltp":0.0,"tv":0.0,"id":26354924}]}]}
{"op":"mcm","clk":"11785914699","pt":1722965138003,"mc":[{"id":"1.231502182","rc":[{"trd":[[1.3,0.14]],"batb":[[0,1.3,28.74]],"ltp":1.3,"tv":0.14,"id":26354927}],"tv":0.14}]}
{"op":"mcm","clk":"11786052730","pt":1722966104777,"mc":[{"id":"1.231502182","rc":[{"batb":[[0,1.31,7.41],[1,1.3,28.74]],"ltp":1.3,"tv":0.14,"id":26354927}]}]}
{"op":"mcm","clk":"11786052788","pt":1722966105143,"mc":[{"id":"1.231502182","rc":[{"batb":[[0,1.31,6.34],[1,1.3,28.81]],"ltp":0.0,"tv":0.0,"id":26354924}]}]}
{"op":"mcm","clk":"11786106648","pt":1722966410464,"mc":[{"id":"1.231502182","rc":[{"batb":[[1,1.25,100],[2,1.1,25000]],"ltp":1.3,"tv":0.14,"id":26354927},{"batb":[[1,1.25,100],[2,1.1,25000]],"ltp":0.0,"tv":0.0,"id":26354924}]}]}
{"op":"mcm","clk":"11786113877","pt":1722966458125,"mc":[{"id":"1.231502182","rc":[{"batb":[[0,1.32,27.01],[1,1.31,6.34],[2,1.25,100]],"ltp":0.0,"tv":0.0,"id":26354924}]}]}
{"op":"mcm","clk":"11786292343","pt":1722967787004,"mc":[{"id":"1.231502182","rc":[{"batb":[[0,1.26,7.41]],"ltp":1.3,"tv":0.14,"id":26354927},{"batb":[[0,1.32,27.03],[1,1.31,6.34]],"ltp":0.0,"tv":0.0,"id":26354924}]}]}
{"op":"mcm","clk":"11786292410","pt":1722967787416,"mc":[{"id":"1.231502182","rc":[{"batb":[[0,1.33,6.34],[1,1.32,27.03]],"ltp":0.0,"tv":0.0,"id":26354924}]}]}
{"op":"mcm","clk":"11786316565","pt":1722967981249,"mc":[{"id":"1.231502182","rc":[{"batb":[[0,1.4,63.79],[1,1.33,6.34],[2,1.32,27.03]],"ltp":0.0,"tv":0.0,"id":26354924}]}]}
{"op":"mcm","clk":"11786317890","pt":1722967992715,"mc":[{"id":"1.231502182","rc":[{"batb":[[0,1.4,63.79],[1,1.26,7.41],[2,1.25,100]],"ltp":1.3,"tv":0.14,"id":26354927}]}]}
{"op":"mcm","clk":"11786319780","pt":1722968008149,"mc":[{"id":"1.231502182","rc":[{"trd":[[1.4,127.57]],"batb":[[0,1.26,7.41],[1,1.25,100],[2,1.1,25000]],"batl":[[0,1.4,0.33]],"ltp":1.4,"tv":127.71,"id":26354927}],"tv":127.71}]}
{"op":"mcm","clk":"11786321258","pt":1722968020167,"mc":[{"id":"1.231502182","rc":[{"trd":[[1.4,127.57]],"batb":[[0,1.33,6.34],[1,1.32,27.03],[2,1.25,100]],"batl":[[0,1.4,0.33]],"ltp":1.4,"tv":127.57,"id":26354924}],"tv":255.28}]}
{"op":"mcm","clk":"11786343286","pt":1722968186203,"mc":[{"id":"1.231502182","rc":[{"batb":[[0,1.4,63.79],[1,1.33,6.34],[2,1.32,27.03]],"ltp":1.4,"tv":127.57,"id":26354924}]}]}
{"op":"mcm","clk":"11786344763","pt":1722968196195,"mc":[{"id":"1.231502182","rc":[{"trd":[[1.4,255.14]],"batb":[[0,1.33,6.34],[1,1.32,27.03],[2,1.25,100]],"batl":[[0,1.4,0.33]],"ltp":1.4,"tv":255.14,"id":26354924}],"tv":382.85}]}
{"op":"mcm","clk":"11786347259","pt":1722968213035,"mc":[{"id":"1.231502182","rc":[{"batb":[[0,1.4,63.79],[1,1.26,7.41],[2,1.25,100]],"ltp":1.4,"tv":127.71,"id":26354927}]}]}
{"op":"mcm","clk":"11786348842","pt":1722968224163,"mc":[{"id":"1.231502182","rc":[{"trd":[[1.4,255.14]],"batb":[[0,1.26,7.41],[1,1.25,100],[2,1.1,25000]],"batl":[[0,1.4,0.33]],"ltp":1.4,"tv":255.28,"id":26354927}],"tv":510.42}]}
{"op":"mcm","clk":"11786353577","pt":1722968258289,"mc":[{"id":"1.231502182","rc":[{"batb":[[1,1.25,100],[2,1.1,25000]],"ltp":1.4,"tv":255.14,"id":26354924}]}]}
{"op":"mcm","clk":"11786359549","pt":1722968301037,"mc":[{"id":"1.231502182","rc":[{"batb":[[0,1.34,25.44],[1,1.33,6.34],[2,1.25,100]],"ltp":1.4,"tv":255.14,"id":26354924}]}]}
{"op":"mcm","clk":"11786515323","pt":1722969366393,"mc":[{"id":"1.231502182","rc":[{"batb":[[0,4.7,1.58],[1,1.34,25.44],[2,1.33,6.34]],"ltp":1.4,"tv":255.14,"id":26354924}]}]}
{"op":"mcm","clk":"11786516733","pt":1722969376409,"mc":[{"id":"1.231502182","rc":[{"batb":[[0,1.34,25.44],[1,1.33,6.34],[2,1.25,100]],"ltp":1.4,"tv":255.14,"id":26354924}]}]}
{"op":"mcm","clk":"11786522679","pt":1722969415849,"mc":[{"id":"1.231502182","rc":[{"batb":[[0,1.25,100],[1,1.1,25000],[2,1.09,25000]],"ltp":1.4,"tv":255.28,"id":26354927},{"batb":[[0,1.35,6.34],[1,1.34,25.44]],"ltp":1.4,"tv":255.14,"id":26354924}]}]}
{"op":"mcm","clk":"11786541600","pt":1722969542984,"mc":[{"id":"1.231502182","rc":[{"batb":[[0,1.35,6.89]],"ltp":1.4,"tv":255.14,"id":26354924}]}]}
{"op":"mcm","clk":"11786543465","pt":1722969554997,"mc":[{"id":"1.231502182","rc":[{"batb":[[0,1.25,100.55]],"ltp":1.4,"tv":255.28,"id":26354927}]}]}
{"op":"mcm","clk":"11786589207","pt":1722969845279,"mc":[{"id":"1.231502182","rc":[{"trd":[[3.5,0.22]],"batb":[[0,3.75,1.36],[1,1.25,100.55],[2,1.1,25000]],"ltp":3.5,"tv":255.5,"id":26354927},{"trd":[[1.4,255.69]],"batb":[[0,1.35,6.34]],"ltp":1.4,"tv":255.69,"id":26354924}],"tv":511.19}]}
{"op":"mcm","clk":"11786590677","pt":1722969855280,"mc":[{"id":"1.231502182","rc":[{"batb":[[0,1.25,100.55],[1,1.1,25000],[2,1.09,25000]],"ltp":3.5,"tv":255.5,"id":26354927}]}]}
{"op":"mcm","clk":"11786626145","pt":1722970101335,"mc":[{"id":"1.231502182","rc":[{"batb":[[1,1.25,100],[2,1.1,25000]],"ltp":1.4,"tv":255.69,"id":26354924}]}]}
{"op":"mcm","clk":"11786628637","pt":1722970118858,"mc":[{"id":"1.231502182","rc":[{"batb":[[0,1.36,24.03],[1,1.35,6.34],[2,1.25,100]],"ltp":1.4,"tv":255.69,"id":26354924}]}]}
{"op":"mcm","clk":"11786675708","pt":1722970457210,"mc":[{"id":"1.231502182","rc":[{"batb":[[0,1.36,24.58]],"ltp":1.4,"tv":255.69,"id":26354924}]}]}
{"op":"mcm","clk":"11786752438","pt":1722971042394,"mc":[{"id":"1.231502182","rc":[{"trd":[[1.4,255.05]],"ltp":3.5,"tv":255.41,"id":26354927},{"trd":[[1.4,255.6]],"batb":[[0,1.36,24.57],[1,1.26,6.34]],"ltp":1.4,"tv":255.6,"id":26354924}],"tv":511.01}]}
{"op":"mcm","clk":"11786866104","pt":1722971919023,"mc":[{"id":"1.231502182","rc":[{"batb":[[0,1.26,6.89],[1,1.25,100],[2,1.1,25000]],"ltp":1.4,"tv":255.6,"id":26354924}]}]}
{"op":"mcm","clk":"11786879210","pt":1722972040787,"mc":[{"id":"1.231502182","rc":[{"batb":[[0,1.27,32.58],[1,1.26,6.34],[2,1.25,100]],"ltp":1.4,"tv":255.6,"id":26354924}]}]}
{"op":"mcm","clk":"11786941492","pt":1722972629203,"mc":[{"id":"1.231502182","rc":[{"batb":[[0,1.28,6.89],[1,1.27,32.03]],"ltp":1.4,"tv":255.6,"id":26354924}]}]}
{"op":"mcm","clk":"11787010269","pt":1722973340266,"mc":[{"id":"1.231502182","rc":[{"batb":[[0,2.06,35.68],[1,1.25,100.55],[2,1.1,25000]],"ltp":3.5,"tv":255.41,"id":26354927},{"batb":[[0,1.87,43.47],[1,1.28,6.89],[2,1.27,32.03]],"ltp":1.4,"tv":255.6,"id":26354924}]}]}
{"op":"mcm","clk":"11787024452","pt":1722973496216,"mc":[{"id":"1.231502182","rc":[{"batb":[[1,1.25,100]],"ltp":3.5,"tv":255.41,"id":26354927},{"trd":[[1.87,0.82]],"batb":[[0,1.87,43.06],[1,1.28,6.34]],"ltp":1.87,"tv":256.42,"id":26354924}],"tv":511.83}]}
{"op":"mcm","clk":"11787024884","pt":1722973501003,"mc":[{"id":"1.231502182","rc":[{"batb":[[0,1.87,43.47]],"ltp":1.87,"tv":256.42,"id":26354924}]}]}
{"op":"mcm","clk":"11787051993","pt":1722973787769,"mc":[{"id":"1.231502182","rc":[{"batl":[[0,1.9,100]],"ltp":1.87,"tv":256.42,"id":26354924}]}]}
{"op":"mcm","clk":"11787053438","pt":1722973801943,"mc":[{"id":"1.231502182","rc":[{"trd":[[1.87,86.82]],"batb":[[0,1.83,45.57]],"ltp":1.87,"tv":342.42,"id":26354924}],"tv":597.83}]}
{"op":"mcm","clk":"11787057466","pt":1722973840921,"mc":[{"id":"1.231502182","rc":[{"batb":[[2,1.25,100]],"ltp":1.87,"tv":342.42,"id":26354924}]}]}
{"op":"mcm","clk":"11787078933","pt":1722974058639,"mc":[{"id":"1.231502182","rc":[{"batb":[[0,2.12,6.8],[1,2.06,35.68],[2,1.25,100]],"ltp":3.5,"tv":255.41,"id":26354927},{"batl":[[0,1.89,7.51],[1,1.9,100]],"ltp":1.87,"tv":342.42,"id":26354924}]}]}
{"op":"mcm","clk":"11787088470","pt":1722974185701,"mc":[{"id":"1.231502182","rc":[{"batb":[[1,1.25,100],[2,1.1,25000]],"ltp":1.87,"tv":342.42,"id":26354924}]}]}
{"op":"mcm","clk":"11787089465","pt":1722974199199,"mc":[{"id":"1.231502182","rc":[{"batl":[[2,1.94,200]],"ltp":1.87,"tv":342.42,"id":26354924}]}]}
{"op":"mcm","clk":"11787113260","pt":1722974523622,"mc":[{"id":"1.231502182","rc":[{"trd":[[1.4,255.18]],"batb":[[0,2.12,11.25]],"ltp":3.5,"tv":255.53,"id":26354927},{"trd":[[1.4,255.73]],"batl":[[0,1.89,13.17]],"ltp":1.87,"tv":342.54,"id":26354924}],"tv":598.08}]}
{"op":"mcm","clk":"11787113355","pt":1722974524814,"mc":[{"id":"1.231502182","rc":[{"batb":[[0,2.12,6.8]],"ltp":3.5,"tv":255.53,"id":26354927}]}]}
{"op":"mcm","clk":"11787308142","pt":1722977350124,"mc":[{"id":"1.231502182","rc":[{"batl":[[0,1.89,23.17]],"ltp":1.87,"tv":342.54,"id":26354924}]}]}
{"op":"mcm","clk":"11787308458","pt":1722977357415,"mc":[{"id":"1.231502182","rc":[{"batl":[[0,1.89,13.17]],"ltp":1.87,"tv":342.54,"id":26354924}]}]}
{"op":"mcm","clk":"11787509614","pt":1722982374915,"mc":[{"id":"1.231502182","rc":[{"trd":[[1.4,255.13]],"batb":[[0,2.12,6.8]],"ltp":3.5,"tv":255.48,"id":26354927},{"trd":[[1.4,255.68]],"batl":[[0,1.89,13.16]],"ltp":1.87,"tv":342.49,"id":26354924}],"tv":597.98}]}
{"op":"mcm","clk":"11787760507","pt":1722987774948,"mc":[{"id":"1.231502182","rc":[{"trd":[[1.4,255.17]],"batb":[[0,2.12,6.8]],"ltp":3.5,"tv":255.53,"id":26354927},{"trd":[[1.4,255.72]],"batl":[[0,1.89,13.17]],"ltp":1.87,"tv":342.54,"id":26354924}],"tv":598.07}]}
{"op":"mcm","clk":"11787819351","pt":1722988861652,"mc":[{"id":"1.231502182","rc":[{"trd":[[1.4,255.39]],"batb":[[0,2.12,6.81]],"ltp":3.5,"tv":255.75,"id":26354927},{"trd":[[1.4,255.94]],"batb":[[1,1.57,85.65],[2,1.25,100]],"batl":[[0,1.89,13.17]],"ltp":1.87,"tv":342.76,"id":26354924}],"tv":598.51}]}
{"op":"mcm","clk":"11787822187","pt":1722988915678,"mc":[{"id":"1.231502182","rc":[{"batb":[[1,1.25,100],[2,1.1,25000]],"ltp":1.87,"tv":342.76,"id":26354924}]}]}
{"op":"mcm","clk":"11788108477","pt":1722993174992,"mc":[{"id":"1.231502182","rc":[{"trd":[[1.4,254.9]],"batb":[[0,2.12,6.8]],"ltp":3.5,"tv":255.26,"id":26354927},{"trd":[[1.4,255.45]],"batl":[[0,1.89,13.16]],"ltp":1.87,"tv":342.27,"id":26354924}],"tv":597.53}]}
{"op":"mcm","clk":"11788224602","pt":1722994956931,"mc":[{"id":"1.231502182","rc":[{"batl":[[0,1.88,18.04],[1,1.89,13.16],[2,1.9,100]],"ltp":1.87,"tv":342.27,"id":26354924}]}]}
{"op":"mcm","clk":"11788224642","pt":1722994957395,"mc":[{"id":"1.231502182","rc":[{"batl":[[1,1.89,7.51]],"ltp":1.87,"tv":342.27,"id":26354924}]}]}
{"op":"mcm","clk":"11788224800","pt":1722994959449,"mc":[{"id":"1.231502182","rc":[{"batl":[[1,1.9,100],[2,1.94,200]],"ltp":1.87,"tv":342.27,"id":26354924}]}]}
{"op":"mcm","clk":"11788233297","pt":1722995079950,"mc":[{"id":"1.231502182","rc":[{"batl":[[1,1.89,13.53],[2,1.9,100]],"ltp":1.87,"tv":342.27,"id":26354924}]}]}
{"op":"mcm","clk":"11788410836","pt":1722998574982,"mc":[{"id":"1.231502182","rc":[{"trd":[[1.4,254.89]],"batb":[[0,2.12,6.79]],"ltp":3.5,"tv":255.25,"id":26354927},{"trd":[[1.4,255.44]],"ltp":1.87,"tv":342.26,"id":26354924}],"tv":597.51}]}
{"op":"mcm","clk":"11788510702","pt":1723001003377,"mc":[{"id":"1.231502182","rc":[{"trd":[[1.4,254.83]],"batb":[[0,2.12,6.79]],"ltp":3.5,"tv":255.18,"id":26354927},{"trd":[[1.4,255.37]],"ltp":1.87,"tv":342.19,"id":26354924}],"tv":597.38}]}
{"op":"mcm","clk":"11788630432","pt":1723003974961,"mc":[{"id":"1.231502182","rc":[{"trd":[[1.4,254.64]],"batb":[[0,2.12,6.78]],"ltp":3.5,"tv":254.99,"id":26354927},{"trd":[[1.4,255.19]],"ltp":1.87,"tv":342.0,"id":26354924}],"tv":597.0}]}
{"op":"mcm","clk":"11788827340","pt":1723009374918,"mc":[{"id":"1.231502182","rc":[{"trd":[[1.4,254.83]],"batb":[[0,2.12,6.78]],"ltp":3.5,"tv":255.18,"id":26354927},{"trd":[[1.4,255.38]],"ltp":1.87,"tv":342.19,"id":26354924}],"tv":597.38}]}
{"op":"mcm","clk":"11788987264","pt":1723013655633,"mc":[{"id":"1.231502182","rc":[{"trd":[[1.4,254.91]],"batb":[[2,1.74,17.32]],"ltp":3.5,"tv":255.27,"id":26354927},{"trd":[[1.4,255.46]],"batb":[[1,1.74,17.32],[2,1.25,100]],"ltp":1.87,"tv":342.28,"id":26354924}],"tv":597.55}]}
{"op":"mcm","clk":"11789034213","pt":1723014774917,"mc":[{"id":"1.231502182","rc":[{"trd":[[1.4,254.71]],"batb":[[0,2.12,6.78]],"ltp":3.5,"tv":255.07,"id":26354927},{"trd":[[1.4,255.26]],"ltp":1.87,"tv":342.07,"id":26354924}],"tv":597.14}]}
{"op":"mcm","clk":"11789181176","pt":1723017911964,"mc":[{"id":"1.231502182","rc":[{"trd":[[1.4,255.08]],"batb":[[0,2.12,6.8]],"batl":[[0,2.2,22.8]],"ltp":3.5,"tv":255.44,"id":26354927},{"trd":[[1.4,255.63]],"ltp":1.87,"tv":342.45,"id":26354924}],"tv":597.89}]}
{"op":"mcm","clk":"11789181765","pt":1723017922161,"mc":[{"id":"1.231502182","rc":[{"trd":[[1.83,20]],"batb":[[0,1.83,35.57]],"ltp":1.83,"tv":362.45,"id":26354924}],"tv":617.89}]}
{"op":"mcm","clk":"11789181906","pt":1723017924687,"mc":[{"id":"1.231502182","rc":[{"batb":[[0,1.83,45.57]],"ltp":1.83,"tv":362.45,"id":26354924}]}]}
{"op":"mcm","clk":"11789196744","pt":1723018184576,"mc":[{"id":"1.231502182","rc":[{"batb":[[0,1.84,5.48],[1,1.83,45.57],[2,1.74,17.32]],"ltp":1.83,"tv":362.45,"id":26354924}]}]}
{"op":"mcm","clk":"11789431437","pt":1723022208914,"mc":[{"id":"1.231502182","rc":[{"trd":[[1.4,254.94]],"batb":[[0,2.12,6.79]],"ltp":3.5,"tv":255.3,"id":26354927},{"trd":[[1.4,255.49],[1.84,1.9]],"batb":[[0,1.84,4.52]],"ltp":1.84,"tv":364.21,"id":26354924}],"tv":619.52}]}
{"op":"mcm","clk":"11789483868","pt":1723023000737,"mc":[{"id":"1.231502182","rc":[{"batl":[[1,1.89,49.59]],"ltp":1.84,"tv":364.21,"id":26354924}]}]}
{"op":"mcm","clk":"11789650213","pt":1723025437787,"mc":[{"id":"1.231502182","rc":[{"trd":[[1.4,254.75]],"batb":[[0,2.12,6.78]],"ltp":3.5,"tv":255.1,"id":26354927},{"trd":[[1.4,255.3],[1.84,1.9]],"batb":[[0,1.84,4.52]],"batl":[[1,1.89,85.65]],"ltp":1.84,"tv":364.02,"id":26354924}],"tv":619.13}]}
{"op":"mcm","clk":"11789651693","pt":1723025454949,"mc":[{"id":"1.231502182","rc":[{"batl":[[1,1.89,49.59]],"ltp":1.84,"tv":364.02,"id":26354924}]}]}
{"op":"mcm","clk":"11790042560","pt":1723030562860,"mc":[{"id":"1.231502182","rc":[{"trd":[[1.4,254.62]],"ltp":3.5,"tv":254.98,"id":26354927},{"trd":[[1.4,255.17]],"batl":[[0,1.88,25.25]],"ltp":1.84,"tv":363.89,"id":26354924}],"tv":618.87}]}
{"op":"mcm","clk":"11790094911","pt":1723031246394,"mc":[{"id":"1.231502182","rc":[{"batb":[[2,1.74,967.32]],"ltp":1.84,"tv":363.89,"id":26354924}]}]}
{"op":"mcm","clk":"11790315625","pt":1723034990725,"mc":[{"id":"1.231502182","rc":[{"trd":[[1.4,254.41],[2.12,29.58]],"batb":[[0,2.06,35.68],[1,1.74,17.32],[2,1.7,10]],"ltp":2.12,"tv":284.35,"id":26354927},{"trd":[[1.4,254.96],[1.88,18.07]],"batb":[[0,1.84,4.52]],"batl":[[0,1.88,7.18]],"ltp":1.88,"tv":381.75,"id":26354924}],"tv":666.11}]}
{"op":"mcm","clk":"11790315746","pt":1723034992327,"mc":[{"id":"1.231502182","rc":[{"batb":[[0,2.08,10],[1,2.06,35.68],[2,1.74,17.32]],"batl":[[0,2.2,6.53]],"ltp":2.12,"tv":284.35,"id":26354927},{"batb":[[0,1.83,45.57],[1,1.74,967.32],[2,1.7,10]],"ltp":1.88,"tv":381.75,"id":26354924}]}]}
{"op":"mcm","clk":"11790315943","pt":1723034995721,"mc":[{"id":"1.231502182","rc":[{"batb":[[0,2.06,35.68],[1,1.74,17.32],[2,1.7,10]],"ltp":2.12,"tv":284.35,"id":26354927}]}]}
{"op":"mcm","clk":"11790318040","pt":1723035025077,"mc":[{"id":"1.231502182","rc":[{"batb":[[0,2.08,10],[1,2.06,35.68],[2,1.74,17.32]],"ltp":2.12,"tv":284.35,"id":26354927}]}]}
{"op":"mcm","clk":"11790318276","pt":1723035028373,"mc":[{"id":"1.231502182","rc":[{"batb":[[0,2.06,35.68],[1,1.74,17.32],[2,1.7,10]],"ltp":2.12,"tv":284.35,"id":26354927}]}]}
{"op":"mcm","clk":"11790332361","pt":1723035222010,"mc":[{"id":"1.231502182","rc":[{"batb":[[1,1.75,18.04],[2,1.74,967.32]],"ltp":1.88,"tv":381.75,"id":26354924}]}]}
{"op":"mcm","clk":"11790332370","pt":1723035222113,"mc":[{"id":"1.231502182","rc":[{"batb":[[0,2.08,10],[1,2.06,35.68],[2,1.74,17.32]],"ltp":2.12,"tv":284.35,"id":26354927}]}]}
{"op":"mcm","clk":"11790332590","pt":1723035225418,"mc":[{"id":"1.231502182","rc":[{"batb":[[0,2.06,35.68],[1,1.74,17.32],[2,1.7,10]],"ltp":2.12,"tv":284.35,"id":26354927}]}]}
{"op":"mcm","clk":"11790338928","pt":1723035312539,"mc":[{"id":"1.231502182","rc":[{"batb":[[0,2.08,10],[1,2.06,35.68],[2,1.74,17.32]],"ltp":2.12,"tv":284.35,"id":26354927}]}]}
{"op":"mcm","clk":"11790339138","pt":1723035315766,"mc":[{"id":"1.231502182","rc":[{"batb":[[0,2.06,35.68],[1,1.74,17.32],[2,1.7,10]],"ltp":2.12,"tv":284.35,"id":26354927}]}]}
{"op":"mcm","clk":"11790340417","pt":1723035334399,"mc":[{"id":"1.231502182","rc":[{"batb":[[0,2.08,10],[1,2.06,35.68],[2,1.74,17.32]],"ltp":2.12,"tv":284.35,"id":26354927}]}]}
{"op":"mcm","clk":"11790340665","pt":1723035337803,"mc":[{"id":"1.231502182","rc":[{"batb":[[0,2.06,35.68],[1,1.74,17.32],[2,1.7,10]],"ltp":2.12,"tv":284.35,"id":26354927}]}]}
{"op":"mcm","clk":"11790346478","pt":1723035423589,"mc":[{"id":"1.231502182","rc":[{"batb":[[0,2.08,10],[1,2.06,35.68],[2,1.74,17.32]],"ltp":2.12,"tv":284.35,"id":26354927}]}]}
{"op":"mcm","clk":"11790346707","pt":1723035426908,"mc":[{"id":"1.231502182","rc":[{"batb":[[0,2.06,35.68],[1,1.74,17.32],[2,1.7,10]],"ltp":2.12,"tv":284.35,"id":26354927}]}]}
{"op":"mcm","clk":"11790358971","pt":1723035637950,"mc":[{"id":"1.231502182","rc":[{"trd":[[1.4,254.47],[2.12,29.58]],"batl":[[0,2.2,6.53]],"ltp":2.12,"tv":284.41,"id":26354927},{"trd":[[1.4,255.02]],"batl":[[1,1.89,85.65]],"ltp":1.88,"tv":381.81,"id":26354924}],"tv":666.23}]}
{"op":"mcm","clk":"11790358979","pt":1723035638047,"mc":[{"id":"1.231502182","rc":[{"batb":[[0,2.08,10],[1,2.06,35.68],[2,1.74,17.32]],"ltp":2.12,"tv":284.41,"id":26354927}]}]}
{"op":"mcm","clk":"11790359179","pt":1723035641348,"mc":[{"id":"1.231502182","rc":[{"batb":[[0,2.06,35.68],[1,1.74,17.32],[2,1.7,10]],"ltp":2.12,"tv":284.41,"id":26354927}]}]}
{"op":"mcm","clk":"11790373482","pt":1723035910855,"mc":[{"id":"1.231502182","rc":[{"batb":[[0,2.08,10],[1,2.06,35.68],[2,1.74,17.32]],"ltp":2.12,"tv":284.41,"id":26354927},{"batl":[[0,1.88,14.15]],"ltp":1.88,"tv":381.81,"id":26354924}]}]}
{"op":"mcm","clk":"11790373654","pt":1723035914148,"mc":[{"id":"1.231502182","rc":[{"batb":[[0,2.06,35.68],[1,1.74,17.32],[2,1.7,10]],"ltp":2.12,"tv":284.41,"id":26354927}]}]}
{"op":"mcm","clk":"11790374259","pt":1723035925546,"mc":[{"id":"1.231502182","rc":[{"batb":[[0,2.14,4.36],[1,2.06,35.68],[2,1.74,17.32]],"ltp":2.12,"tv":284.41,"id":26354927}]}]}
{"op":"mcm","clk":"11790376112","pt":1723035961998,"mc":[{"id":"1.231502182","rc":[{"batl":[[0,1.88,20.58]],"ltp":1.88,"tv":381.81,"id":26354924}]}]}
{"op":"mcm","clk":"11790500100","pt":1723037957883,"mc":[{"id":"1.231502182","rc":[{"batb":[[2,1.74,17.32]],"ltp":1.88,"tv":381.81,"id":26354924}]}]}
{"op":"mcm","clk":"11790645311","pt":1723040507746,"mc":[{"id":"1.231502182","rc":[{"trd":[[1.4,254.58]],"batb":[[1,2.06,41.89]],"ltp":2.12,"tv":284.51,"id":26354927},{"trd":[[1.4,255.12]],"batb":[[0,1.83,53.5]],"ltp":1.88,"tv":381.91,"id":26354924}],"tv":666.43}]}
{"op":"mcm","clk":"11790746780","pt":1723041774886,"mc":[{"id":"1.231502182","rc":[{"batl":[[0,1.88,32.58]],"ltp":1.88,"tv":381.91,"id":26354924}]}]}
{"op":"mcm","clk":"11790751449","pt":1723041775044,"mc":[{"id":"1.231502182","rc":[{"batl":[[0,1.87,12],[1,1.88,32.58],[2,1.89,85.65]],"ltp":1.88,"tv":381.91,"id":26354924}]}]}
{"op":"mcm","clk":"11790769786","pt":1723041977117,"mc":[{"id":"1.231502182","rc":[{"batl":[[0,1.86,3.61],[1,1.87,12],[2,1.88,32.58]],"ltp":1.88,"tv":381.91,"id":26354924}]}]}
{"op":"mcm","clk":"11790775180","pt":1723042034689,"mc":[{"id":"1.231502182","rc":[{"batl":[[0,1.86,7.22]],"ltp":1.88,"tv":381.91,"id":26354924}]}]}
{"op":"mcm","clk":"11791106008","pt":1723045424663,"mc":[{"id":"1.231502182","rc":[{"trd":[[1.4,254.42],[2.12,29.59]],"batb":[[0,2.14,4.37]],"batl":[[0,2.2,6.54]],"ltp":2.12,"tv":284.36,"id":26354927},{"trd":[[1.4,254.97]],"batl":[[2,1.88,32.59]],"ltp":1.88,"tv":381.75,"id":26354924}],"tv":666.12}]}
{"op":"mcm","clk":"11791144864","pt":1723045872364,"mc":[{"id":"1.231502182","rc":[{"batb":[[1,2.1,40.37]],"batl":[[1,2.22,1.54]],"ltp":2.12,"tv":284.36,"id":26354927}]}]}
{"op":"mcm","clk":"11791254791","pt":1723047102876,"mc":[{"id":"1.231502182","rc":[{"trd":[[1.4,254.55],[2.12,29.59]],"batl":[[0,2.2,6.54]],"ltp":2.12,"tv":284.5,"id":26354927},{"trd":[[1.4,255.1]],"batl":[[2,1.88,32.59]],"ltp":1.88,"tv":381.89,"id":26354924}],"tv":666.39}]}
{"op":"mcm","clk":"11791345087","pt":1723047903550,"mc":[{"id":"1.231502182","rc":[{"trd":[[1.83,24.4]],"batb":[[0,1.83,51.3]],"ltp":1.83,"tv":386.29,"id":26354924}],"tv":670.79}]}
{"op":"mcm","clk":"11791345323","pt":1723047906168,"mc":[{"id":"1.231502182","rc":[{"batb":[[0,1.83,53.5]],"ltp":1.83,"tv":386.29,"id":26354924}]}]}
{"op":"mcm","clk":"11791477108","pt":1723049332601,"mc":[{"id":"1.231502182","rc":[{"batb":[[1,1.75,52.04]],"ltp":1.83,"tv":386.29,"id":26354924}]}]}
{"op":"mcm","clk":"11791535654","pt":1723049900490,"mc":[{"id":"1.231502182","rc":[{"batl":[[1,1.88,32.59],[2,1.89,85.65]],"ltp":1.83,"tv":386.29,"id":26354924}]}]}
{"op":"mcm","clk":"11791535713","pt":1723049901115,"mc":[{"id":"1.231502182","rc":[{"batl":[[1,1.88,20.59]],"ltp":1.83,"tv":386.29,"id":26354924}]}]}
{"op":"mcm","clk":"11791536351","pt":1723049907705,"mc":[{"id":"1.231502182","rc":[{"batl":[[1,1.87,8],[2,1.88,28.59]],"ltp":1.83,"tv":386.29,"id":26354924}]}]}
{"op":"mcm","clk":"11791536421","pt":1723049908428,"mc":[{"id":"1.231502182","rc":[{"batl":[[0,1.86,15.22]],"ltp":1.83,"tv":386.29,"id":26354924}]}]}
{"op":"mcm","clk":"11791634468","pt":1723050682258,"mc":[{"id":"1.231502182","rc":[{"trd":[[1.4,254.74],[2.12,29.59],[2.16,1]],"batb":[[0,2.14,4.37]],"batl":[[0,2.2,6.54],[1,2.22,1.54]],"ltp":2.16,"tv":285.68,"id":26354927},{"trd":[[1.4,255.28],[1.86,1.16]],"batl":[[0,1.86,14.06],[2,1.88,28.6]],"ltp":1.86,"tv":387.63,"id":26354924}],"tv":673.32}]}
{"op":"mcm","clk":"11791824694","pt":1723052014686,"mc":[{"id":"1.231502182","rc":[{"trd":[[1.86,29.28]],"batb":[[0,1.86,31.81],[1,1.83,53.5],[2,1.75,52.04]],"batl":[[0,1.87,8],[1,1.88,28.6],[2,1.89,85.65]],"ltp":1.86,"tv":415.75,"id":26354924}],"tv":701.44}]}
{"op":"mcm","clk":"11791824762","pt":1723052015057,"mc":[{"id":"1.231502182","rc":[{"batb":[[1,1.85,8.04],[2,1.83,53.5]],"ltp":1.86,"tv":415.75,"id":26354924}]}]}
{"op":"mcm","clk":"11791825040","pt":1723052016680,"mc":[{"id":"1.231502182","rc":[{"batl":[[0,2.16,6.66],[1,2.22,0]],"ltp":2.16,"tv":285.68,"id":26354927}]}]}
{"op":"mcm","clk":"11791835149","pt":1723052078361,"mc":[{"id":"1.231502182","rc":[{"batb":[[0,1.85,8.04],[1,1.83,53.5],[2,1.75,52.04]],"ltp":1.86,"tv":415.75,"id":26354924}]}]}
{"op":"mcm","clk":"11791835367","pt":1723052079719,"mc":[{"id":"1.231502182","rc":[{"batl":[[0,2.2,6.54]],"ltp":2.16,"tv":285.68,"id":26354927}]}]}
{"op":"mcm","clk":"11791838632","pt":1723052100455,"mc":[{"id":"1.231502182","rc":[{"trd":[[1.85,16.08]],"batb":[[0,1.83,53.5],[1,1.75,52.04],[2,1.74,17.32]],"batl":[[0,1.85,3.43],[1,1.87,8],[2,1.88,28.6]],"ltp":1.85,"tv":431.83,"id":26354924}],"tv":717.52}]}
{"op":"mcm","clk":"11791840516","pt":1723052112394,"mc":[{"id":"1.231502182","rc":[{"trd":[[1.83,33.58]],"batb":[[0,1.83,48.91]],"ltp":1.83,"tv":441.01,"id":26354924}],"tv":726.7}]}
{"op":"mcm","clk":"11791840791","pt":1723052114084,"mc":[{"id":"1.231502182","rc":[{"batb":[[0,1.83,53.5]],"ltp":1.83,"tv":441.01,"id":26354924}]}]}
{"op":"mcm","clk":"11791889679","pt":1723052433060,"mc":[{"id":"1.231502182","rc":[{"batb":[[1,1.76,7.21],[2,1.75,52.04]],"ltp":1.83,"tv":441.01,"id":26354924}]}]}
{"op":"mcm","clk":"11792209726","pt":1723054434851,"mc":[{"id":"1.231502182","rc":[{"trd":[[1.4,254.98],[2.12,29.6]],"batb":[[0,2.14,4.37]],"batl":[[0,2.2,6.55]],"ltp":2.16,"tv":285.94,"id":26354927},{"trd":[[1.4,255.53],[1.83,49.58],[1.85,16.09],[1.86,29.29]],"batb":[[0,1.83,45.5]],"batl":[[0,1.85,3.43],[2,1.88,28.61]],"ltp":1.83,"tv":457.29,"id":26354924}],"tv":743.23}]}
{"op":"mcm","clk":"11792209867","pt":1723054435540,"mc":[{"id":"1.231502182","rc":[{"batb":[[0,1.83,53.5],[1,1.82,8.04],[2,1.76,7.21]],"ltp":1.83,"tv":457.29,"id":26354924}]}]}
{"op":"mcm","clk":"11792210029","pt":1723054436440,"mc":[{"id":"1.231502182","rc":[{"batb":[[2,1.81,16]],"ltp":1.83,"tv":457.29,"id":26354924}]}]}
{"op":"mcm","clk":"11792210202","pt":1723054437450,"mc":[{"id":"1.231502182","rc":[{"batb":[[2,1.81,24]],"ltp":1.83,"tv":457.29,"id":26354924}]}]}
{"op":"mcm","clk":"11792217478","pt":1723054480558,"mc":[{"id":"1.231502182","rc":[{"batb":[[2,1.81,16]],"ltp":1.83,"tv":457.29,"id":26354924}]}]}
{"op":"mcm","clk":"11792217600","pt":1723054481395,"mc":[{"id":"1.231502182","rc":[{"batb":[[2,1.81,8]],"ltp":1.83,"tv":457.29,"id":26354924}]}]}
{"op":"mcm","clk":"11792217827","pt":1723054482868,"mc":[{"id":"1.231502182","rc":[{"batb":[[2,1.76,7.21]],"ltp":1.83,"tv":457.29,"id":26354924}]}]}
{"op":"mcm","clk":"11792220859","pt":1723054502501,"mc":[{"id":"1.231502182","rc":[{"batl":[[1,1.86,8],[2,1.87,8]],"ltp":1.83,"tv":457.29,"id":26354924}]}]}
{"op":"mcm","clk":"11792221169","pt":1723054504314,"mc":[{"id":"1.231502182","rc":[{"batl":[[0,1.85,11.43]],"ltp":1.83,"tv":457.29,"id":26354924}]}]}
{"op":"mcm","clk":"11792529089","pt":1723056409358,"mc":[{"id":"1.231502182","rc":[{"batl":[[0,1.85,8]],"ltp":1.83,"tv":457.29,"id":26354924}]}]}
{"op":"mcm","clk":"11792595037","pt":1723056923053,"mc":[{"id":"1.231502182","rc":[{"batl":[[0,1.86,8],[1,1.87,8],[2,1.88,28.61]],"ltp":1.83,"tv":457.29,"id":26354924}]}]}
{"op":"mcm","clk":"11792595826","pt":1723056931073,"mc":[{"id":"1.231502182","rc":[{"batl":[[0,1.87,8],[1,1.88,28.61],[2,1.89,85.65]],"ltp":1.83,"tv":457.29,"id":26354924}]}]}
{"op":"mcm","clk":"11792602132","pt":1723056988610,"mc":[{"id":"1.231502182","rc":[{"batb":[[1,2.1,85.45]],"ltp":2.16,"tv":285.94,"id":26354927}]}]}
{"op":"mcm","clk":"11792718871","pt":1723057974892,"mc":[{"id":"1.231502182","rc":[{"trd":[[1.4,255.18],[2.12,29.6]],"batb":[[0,2.14,4.37]],"batl":[[0,2.2,6.55]],"ltp":2.16,"tv":286.14,"id":26354927},{"trd":[[1.4,255.73],[1.83,49.58],[1.85,16.09],[1.86,29.3]],"batl":[[1,1.88,28.62]],"ltp":1.83,"tv":457.51,"id":26354924}],"tv":743.65}]}
{"op":"mcm","clk":"11792918512","pt":1723059929201,"mc":[{"id":"1.231502182","rc":[{"batb":[[1,2.1,40.37]],"ltp":2.16,"tv":286.14,"id":26354927}]}]}
{"op":"mcm","clk":"11793035565","pt":1723061540480,"mc":[{"id":"1.231502182","rc":[{"trd":[[1.4,255.12],[2.2,5.41]],"batl":[[0,2.2,1.14]],"ltp":2.2,"tv":291.48,"id":26354927},{"trd":[[1.4,255.67],[1.83,163.08],[1.85,16.09],[1.86,29.3]],"batb":[[0,1.82,8.04],[1,1.76,7.21],[2,1.75,52.04]],"batl":[[1,1.88,28.62]],"ltp":1.83,"tv":570.94,"id":26354924}],"tv":862.43}]}
{"op":"mcm","clk":"11793035637","pt":1723061541979,"mc":[{"id":"1.231502182","rc":[{"batb":[[1,1.79,56.21],[2,1.76,7.21]],"ltp":1.83,"tv":570.94,"id":26354924}]}]}
{"op":"mcm","clk":"11793057045","pt":1723061957422,"mc":[{"id":"1.231502182","rc":[{"batl":[[0,1.86,13],[1,1.87,8],[2,1.88,28.62]],"ltp":1.83,"tv":570.94,"id":26354924}]}]}
{"op":"mcm","clk":"11793057796","pt":1723061971352,"mc":[{"id":"1.231502182","rc":[{"batl":[[0,1.85,12],[1,1.86,13],[2,1.87,8]],"ltp":1.83,"tv":570.94,"id":26354924}]}]}
{"op":"mcm","clk":"11793057913","pt":1723061973621,"mc":[{"id":"1.231502182","rc":[{"batb":[[0,2.1,40.37],[1,1.74,17.32],[2,1.7,10]],"ltp":2.2,"tv":291.48,"id":26354927}]}]}
{"op":"mcm","clk":"11793061191","pt":1723062033797,"mc":[{"id":"1.231502182","rc":[{"trd":[[1.82,10]],"batb":[[0,1.82,3.04]],"ltp":1.82,"tv":580.94,"id":26354924}],"tv":872.43}]}
{"op":"mcm","clk":"11793061728","pt":1723062044216,"mc":[{"id":"1.231502182","rc":[{"batb":[[1,1.8,5],[2,1.79,56.21]],"ltp":1.82,"tv":580.94,"id":26354924}]}]}
{"op":"mcm","clk":"11793064679","pt":1723062102797,"mc":[{"id":"1.231502182","rc":[{"batl":[[0,1.85,20]],"ltp":1.82,"tv":580.94,"id":26354924}]}]}
{"op":"mcm","clk":"11793064761","pt":1723062103882,"mc":[{"id":"1.231502182","rc":[{"batl":[[0,1.84,8],[1,1.85,20],[2,1.86,13]],"ltp":1.82,"tv":580.94,"id":26354924}]}]}
{"op":"mcm","clk":"11793071787","pt":1723062247012,"mc":[{"id":"1.231502182","rc":[{"batb":[[1,1.8,25]],"ltp":1.82,"tv":580.94,"id":26354924}]}]}
{"op":"mcm","clk":"11793088266","pt":1723062627156,"mc":[{"id":"1.231502182","rc":[{"batb":[[0,2.12,45.08],[1,2.1,40.37],[2,1.74,17.32]],"ltp":2.2,"tv":291.48,"id":26354927}]}]}
{"op":"mcm","clk":"11793089270","pt":1723062654488,"mc":[{"id":"1.231502182","rc":[{"batb":[[0,2.1,40.37],[1,1.74,17.32],[2,1.7,10]],"ltp":2.2,"tv":291.48,"id":26354927}]}]}
{"op":"mcm","clk":"11793091541","pt":1723062712173,"mc":[{"id":"1.231502182","rc":[{"batl":[[1,1.85,8]],"ltp":1.82,"tv":580.94,"id":26354924}]}]}
{"op":"mcm","clk":"11793092760","pt":1723062742402,"mc":[{"id":"1.231502182","rc":[{"batl":[[2,1.87,20]],"ltp":1.82,"tv":580.94,"id":26354924}]}]}
{"op":"mcm","clk":"11793105502","pt":1723063072542,"mc":[{"id":"1.231502182","rc":[{"batb":[[0,2.12,10],[1,2.1,40.37],[2,1.74,17.32]],"batl":[[0,2.26,2]],"ltp":2.2,"tv":291.48,"id":26354927}]}]}
{"op":"mcm","clk":"11793105644","pt":1723063075697,"mc":[{"id":"1.231502182","rc":[{"batb":[[0,2.1,40.37],[1,1.74,17.32],[2,1.7,10]],"ltp":2.2,"tv":291.48,"id":26354927}]}]}
{"op":"mcm","clk":"11793105737","pt":1723063078317,"mc":[{"id":"1.231502182","rc":[{"batb":[[0,2.12,10],[1,2.1,40.37],[2,1.74,17.32]],"ltp":2.2,"tv":291.48,"id":26354927}]}]}
{"op":"mcm","clk":"11793105887","pt":1723063081711,"mc":[{"id":"1.231502182","rc":[{"batb":[[0,2.1,40.37],[1,1.74,17.32],[2,1.7,10]],"ltp":2.2,"tv":291.48,"id":26354927}]}]}
{"op":"mcm","clk":"11793105973","pt":1723063083913,"mc":[{"id":"1.231502182","rc":[{"batb":[[0,2.12,10],[1,2.1,40.37],[2,1.74,17.32]],"ltp":2.2,"tv":291.48,"id":26354927}]}]}
{"op":"mcm","clk":"11793106130","pt":1723063087202,"mc":[{"id":"1.231502182","rc":[{"batb":[[0,2.1,40.37],[1,1.74,17.32],[2,1.7,10]],"ltp":2.2,"tv":291.48,"id":26354927}]}]}
{"op":"mcm","clk":"11793106299","pt":1723063091504,"mc":[{"id":"1.231502182","rc":[{"batb":[[0,2.12,10],[1,2.1,40.37],[2,1.74,17.32]],"ltp":2.2,"tv":291.48,"id":26354927}]}]}
{"op":"mcm","clk":"11793106415","pt":1723063094687,"mc":[{"id":"1.231502182","rc":[{"batb":[[0,2.1,40.37],[1,1.74,17.32],[2,1.7,10]],"ltp":2.2,"tv":291.48,"id":26354927}]}]}
{"op":"mcm","clk":"11793106503","pt":1723063097098,"mc":[{"id":"1.231502182","rc":[{"batb":[[0,2.12,10],[1,2.1,40.37],[2,1.74,17.32]],"ltp":2.2,"tv":291.48,"id":26354927}]}]}
{"op":"mcm","clk":"11793106636","pt":1723063100737,"mc":[{"id":"1.231502182","rc":[{"batb":[[0,2.1,40.37],[1,1.74,17.32],[2,1.7,10]],"ltp":2.2,"tv":291.48,"id":26354927}]}]}
{"op":"mcm","clk":"11793106871","pt":1723063107620,"mc":[{"id":"1.231502182","rc":[{"batb":[[0,2.12,10],[1,2.1,40.37],[2,1.74,17.32]],"ltp":2.2,"tv":291.48,"id":26354927}]}]}
{"op":"mcm","clk":"11793106993","pt":1723063111055,"mc":[{"id":"1.231502182","rc":[{"batb":[[0,2.1,40.37],[1,1.74,17.32],[2,1.7,10]],"ltp":2.2,"tv":291.48,"id":26354927}]}]}
{"op":"mcm","clk":"11793107106","pt":1723063113637,"mc":[{"id":"1.231502182","rc":[{"batb":[[0,2.12,10],[1,2.1,40.37],[2,1.74,17.32]],"ltp":2.2,"tv":291.48,"id":26354927}]}]}
{"op":"mcm","clk":"11793107214","pt":1723063116949,"mc":[{"id":"1.231502182","rc":[{"batb":[[0,2.1,40.37],[1,1.74,17.32],[2,1.7,10]],"ltp":2.2,"tv":291.48,"id":26354927}]}]}
{"op":"mcm","clk":"11793107387","pt":1723063121838,"mc":[{"id":"1.231502182","rc":[{"batb":[[0,2.12,10],[1,2.1,40.37],[2,1.74,17.32]],"ltp":2.2,"tv":291.48,"id":26354927}]}]}
{"op":"mcm","clk":"11793107491","pt":1723063125431,"mc":[{"id":"1.231502182","rc":[{"batb":[[0,2.1,40.37],[1,1.74,17.32],[2,1.7,10]],"ltp":2.2,"tv":291.48,"id":26354927}]}]}
{"op":"mcm","clk":"11793107583","pt":1723063127835,"mc":[{"id":"1.231502182","rc":[{"batb":[[0,2.12,10],[1,2.1,40.37],[2,1.74,17.32]],"ltp":2.2,"tv":291.48,"id":26354927}]}]}
{"op":"mcm","clk":"11793107696","pt":1723063131266,"mc":[{"id":"1.231502182","rc":[{"batb":[[0,2.1,40.37],[1,1.74,17.32],[2,1.7,10]],"ltp":2.2,"tv":291.48,"id":26354927}]}]}
{"op":"mcm","clk":"11793107803","pt":1723063134246,"mc":[{"id":"1.231502182","rc":[{"batb":[[0,2.12,10],[1,2.1,40.37],[2,1.74,17.32]],"ltp":2.2,"tv":291.48,"id":26354927}]}]}
{"op":"mcm","clk":"11793107935","pt":1723063137775,"mc":[{"id":"1.231502182","rc":[{"batb":[[0,2.1,40.37],[1,1.74,17.32],[2,1.7,10]],"ltp":2.2,"tv":291.48,"id":26354927}]}]}
{"op":"mcm","clk":"11793108103","pt":1723063141161,"mc":[{"id":"1.231502182","rc":[{"batb":[[0,2.12,10],[1,2.1,40.37],[2,1.74,17.32]],"ltp":2.2,"tv":291.48,"id":26354927}]}]}
{"op":"mcm","clk":"11793108251","pt":1723063144652,"mc":[{"id":"1.231502182","rc":[{"batb":[[0,2.1,40.37],[1,1.74,17.32],[2,1.7,10]],"ltp":2.2,"tv":291.48,"id":26354927}]}]}
{"op":"mcm","clk":"11793108364","pt":1723063147270,"mc":[{"id":"1.231502182","rc":[{"batb":[[0,2.12,10],[1,2.1,40.37],[2,1.74,17.32]],"ltp":2.2,"tv":291.48,"id":26354927}]}]}
{"op":"mcm","clk":"11793108511","pt":1723063150559,"mc":[{"id":"1.231502182","rc":[{"batb":[[0,2.1,40.37],[1,1.74,17.32],[2,1.7,10]],"ltp":2.2,"tv":291.48,"id":26354927}]}]}
{"op":"mcm","clk":"11793108632","pt":1723063153376,"mc":[{"id":"1.231502182","rc":[{"batb":[[0,2.12,10],[1,2.1,40.37],[2,1.74,17.32]],"ltp":2.2,"tv":291.48,"id":26354927}]}]}
{"op":"mcm","clk":"11793108753","pt":1723063156770,"mc":[{"id":"1.231502182","rc":[{"batb":[[0,2.1,40.37],[1,1.74,17.32],[2,1.7,10]],"ltp":2.2,"tv":291.48,"id":26354927}]}]}
{"op":"mcm","clk":"11793108850","pt":1723063159281,"mc":[{"id":"1.231502182","rc":[{"batb":[[0,2.12,10],[1,2.1,40.37],[2,1.74,17.32]],"ltp":2.2,"tv":291.48,"id":26354927}]}]}
{"op":"mcm","clk":"11793109004","pt":1723063162881,"mc":[{"id":"1.231502182","rc":[{"batb":[[0,2.1,40.37],[1,1.74,17.32],[2,1.7,10]],"ltp":2.2,"tv":291.48,"id":26354927}]}]}
{"op":"mcm","clk":"11793109126","pt":1723063166105,"mc":[{"id":"1.231502182","rc":[{"batb":[[0,2.12,10],[1,2.1,40.37],[2,1.74,17.32]],"ltp":2.2,"tv":291.48,"id":26354927}]}]}
{"op":"mcm","clk":"11793109231","pt":1723063169306,"mc":[{"id":"1.231502182","rc":[{"batb":[[0,2.1,40.37],[1,1.74,17.32],[2,1.7,10]],"ltp":2.2,"tv":291.48,"id":26354927}]}]}
{"op":"mcm","clk":"11793109345","pt":1723063172810,"mc":[{"id":"1.231502182","rc":[{"batb":[[0,2.12,10],[1,2.1,40.37],[2,1.74,17.32]],"ltp":2.2,"tv":291.48,"id":26354927}]}]}
{"op":"mcm","clk":"11793109494","pt":1723063176104,"mc":[{"id":"1.231502182","rc":[{"batb":[[0,2.1,40.37],[1,1.74,17.32],[2,1.7,10]],"ltp":2.2,"tv":291.48,"id":26354927}]}]}
{"op":"mcm","clk":"11793109594","pt":1723063178718,"mc":[{"id":"1.231502182","rc":[{"batb":[[0,2.12,10],[1,2.1,40.37],[2,1.74,17.32]],"ltp":2.2,"tv":291.48,"id":26354927}]}]}
{"op":"mcm","clk":"11793109713","pt":1723063182315,"mc":[{"id":"1.231502182","rc":[{"batb":[[0,2.1,40.37],[1,1.74,17.32],[2,1.7,10]],"ltp":2.2,"tv":291.48,"id":26354927}]}]}
{"op":"mcm","clk":"11793109800","pt":1723063185591,"mc":[{"id":"1.231502182","rc":[{"batb":[[0,2.12,10],[1,2.1,40.37],[2,1.74,17.32]],"ltp":2.2,"tv":291.48,"id":26354927}]}]}
{"op":"mcm","clk":"11793109901","pt":1723063189127,"mc":[{"id":"1.231502182","rc":[{"batb":[[0,2.1,40.37],[1,1.74,17.32],[2,1.7,10]],"ltp":2.2,"tv":291.48,"id":26354927}]}]}
{"op":"mcm","clk":"11793109983","pt":1723063191744,"mc":[{"id":"1.231502182","rc":[{"batb":[[0,2.12,10],[1,2.1,40.37],[2,1.74,17.32]],"ltp":2.2,"tv":291.48,"id":26354927}]}]}
{"op":"mcm","clk":"11793110118","pt":1723063195133,"mc":[{"id":"1.231502182","rc":[{"batb":[[0,2.1,40.37],[1,1.74,17.32],[2,1.7,10]],"ltp":2.2,"tv":291.48,"id":26354927}]}]}
{"op":"mcm","clk":"11793110239","pt":1723063198629,"mc":[{"id":"1.231502182","rc":[{"batb":[[0,2.12,10],[1,2.1,40.37],[2,1.74,17.32]],"ltp":2.2,"tv":291.48,"id":26354927}]}]}
{"op":"mcm","clk":"11793110380","pt":1723063202227,"mc":[{"id":"1.231502182","rc":[{"batb":[[0,2.1,40.37],[1,1.74,17.32],[2,1.7,10]],"ltp":2.2,"tv":291.48,"id":26354927}]}]}
{"op":"mcm","clk":"11793110470","pt":1723063204433,"mc":[{"id":"1.231502182","rc":[{"batb":[[0,2.12,10],[1,2.1,40.37],[2,1.74,17.32]],"ltp":2.2,"tv":291.48,"id":26354927}]}]}
{"op":"mcm","clk":"11793110591","pt":1723063207826,"mc":[{"id":"1.231502182","rc":[{"batb":[[0,2.1,40.37],[1,1.74,17.32],[2,1.7,10]],"ltp":2.2,"tv":291.48,"id":26354927}]}]}
{"op":"mcm","clk":"11793110826","pt":1723063213633,"mc":[{"id":"1.231502182","rc":[{"batb":[[0,2.12,10],[1,2.1,40.37],[2,1.74,17.32]],"ltp":2.2,"tv":291.48,"id":26354927}]}]}
{"op":"mcm","clk":"11793110961","pt":1723063216961,"mc":[{"id":"1.231502182","rc":[{"batb":[[0,2.1,40.37],[1,1.74,17.32],[2,1.7,10]],"ltp":2.2,"tv":291.48,"id":26354927}]}]}
{"op":"mcm","clk":"11793111043","pt":1723063219438,"mc":[{"id":"1.231502182","rc":[{"batb":[[0,2.12,10],[1,2.1,40.37],[2,1.74,17.32]],"ltp":2.2,"tv":291.48,"id":26354927}]}]}
{"op":"mcm","clk":"11793111171","pt":1723063222826,"mc":[{"id":"1.231502182","rc":[{"batb":[[0,2.1,40.37],[1,1.74,17.32],[2,1.7,10]],"ltp":2.2,"tv":291.48,"id":26354927}]}]}
{"op":"mcm","clk":"11793111243","pt":1723063225039,"mc":[{"id":"1.231502182","rc":[{"batb":[[0,2.12,10],[1,2.1,40.37],[2,1.74,17.32]],"ltp":2.2,"tv":291.48,"id":26354927}]}]}
{"op":"mcm","clk":"11793111368","pt":1723063228477,"mc":[{"id":"1.231502182","rc":[{"batb":[[0,2.1,40.37],[1,1.74,17.32],[2,1.7,10]],"ltp":2.2,"tv":291.48,"id":26354927}]}]}
{"op":"mcm","clk":"11793111486","pt":1723063231055,"mc":[{"id":"1.231502182","rc":[{"batb":[[0,2.12,10],[1,2.1,40.37],[2,1.74,17.32]],"ltp":2.2,"tv":291.48,"id":26354927}]}]}
{"op":"mcm","clk":"11793111622","pt":1723063234347,"mc":[{"id":"1.231502182","rc":[{"batb":[[0,2.1,40.37],[1,1.74,17.32],[2,1.7,10]],"ltp":2.2,"tv":291.48,"id":26354927}]}]}
{"op":"mcm","clk":"11793111803","pt":1723063238259,"mc":[{"id":"1.231502182","rc":[{"batb":[[0,2.12,10],[1,2.1,40.37],[2,1.74,17.32]],"ltp":2.2,"tv":291.48,"id":26354927}]}]}
{"op":"mcm","clk":"11793111947","pt":1723063241695,"mc":[{"id":"1.231502182","rc":[{"batb":[[0,2.1,40.37],[1,1.74,17.32],[2,1.7,10]],"ltp":2.2,"tv":291.48,"id":26354927}]}]}
{"op":"mcm","clk":"11793112104","pt":1723063244474,"mc":[{"id":"1.231502182","rc":[{"batb":[[0,2.12,10],[1,2.1,40.37],[2,1.74,17.32]],"ltp":2.2,"tv":291.48,"id":26354927}]}]}
{"op":"mcm","clk":"11793112253","pt":1723063248070,"mc":[{"id":"1.231502182","rc":[{"batb":[[0,2.1,40.37],[1,1.74,17.32],[2,1.7,10]],"ltp":2.2,"tv":291.48,"id":26354927}]}]}
{"op":"mcm","clk":"11793112427","pt":1723063251674,"mc":[{"id":"1.231502182","rc":[{"batb":[[0,2.12,10],[1,2.1,40.37],[2,1.74,17.32]],"ltp":2.2,"tv":291.48,"id":26354927}]}]}
{"op":"mcm","clk":"11793112543","pt":1723063255108,"mc":[{"id":"1.231502182","rc":[{"batb":[[0,2.1,40.37],[1,1.74,17.32],[2,1.7,10]],"ltp":2.2,"tv":291.48,"id":26354927}]}]}
{"op":"mcm","clk":"11793112629","pt":1723063257780,"mc":[{"id":"1.231502182","rc":[{"batb":[[0,2.12,10],[1,2.1,40.37],[2,1.74,17.32]],"ltp":2.2,"tv":291.48,"id":26354927}]}]}
{"op":"mcm","clk":"11793112792","pt":1723063261120,"mc":[{"id":"1.231502182","rc":[{"batb":[[0,2.1,40.37],[1,1.74,17.32],[2,1.7,10]],"ltp":2.2,"tv":291.48,"id":26354927}]}]}
{"op":"mcm","clk":"11793112908","pt":1723063263493,"mc":[{"id":"1.231502182","rc":[{"batb":[[0,2.12,10],[1,2.1,40.37],[2,1.74,17.32]],"ltp":2.2,"tv":291.48,"id":26354927}]}]}
{"op":"mcm","clk":"11793113064","pt":1723063266890,"mc":[{"id":"1.231502182","rc":[{"batb":[[0,2.1,40.37],[1,1.74,17.32],[2,1.7,10]],"ltp":2.2,"tv":291.48,"id":26354927}]}]}
{"op":"mcm","clk":"11793113198","pt":1723063269915,"mc":[{"id":"1.231502182","rc":[{"batb":[[0,2.12,10],[1,2.1,40.37],[2,1.74,17.32]],"ltp":2.2,"tv":291.48,"id":26354927}]}]}
{"op":"mcm","clk":"11793113385","pt":1723063273723,"mc":[{"id":"1.231502182","rc":[{"batb":[[0,2.1,40.37],[1,1.74,17.32],[2,1.7,10]],"ltp":2.2,"tv":291.48,"id":26354927}]}]}
{"op":"mcm","clk":"11793113487","pt":1723063276598,"mc":[{"id":"1.231502182","rc":[{"batb":[[0,2.12,10],[1,2.1,40.37],[2,1.74,17.32]],"ltp":2.2,"tv":291.48,"id":26354927}]}]}
{"op":"mcm","clk":"11793113628","pt":1723063279926,"mc":[{"id":"1.231502182","rc":[{"batb":[[0,2.1,40.37],[1,1.74,17.32],[2,1.7,10]],"ltp":2.2,"tv":291.48,"id":26354927}]}]}
{"op":"mcm","clk":"11793113742","pt":1723063282399,"mc":[{"id":"1.231502182","rc":[{"batb":[[0,2.12,10],[1,2.1,40.37],[2,1.74,17.32]],"ltp":2.2,"tv":291.48,"id":26354927}]}]}
{"op":"mcm","clk":"11793113865","pt":1723063285833,"mc":[{"id":"1.231502182","rc":[{"batb":[[0,2.1,40.37],[1,1.74,17.32],[2,1.7,10]],"ltp":2.2,"tv":291.48,"id":26354927}]}]}
{"op":"mcm","clk":"11793113965","pt":1723063288605,"mc":[{"id":"1.231502182","rc":[{"batb":[[0,2.12,10],[1,2.1,40.37],[2,1.74,17.32]],"ltp":2.2,"tv":291.48,"id":26354927}]}]}
{"op":"mcm","clk":"11793114096","pt":1723063291948,"mc":[{"id":"1.231502182","rc":[{"batb":[[0,2.1,40.37],[1,1.74,17.32],[2,1.7,10]],"ltp":2.2,"tv":291.48,"id":26354927}]}]}
{"op":"mcm","clk":"11793114305","pt":1723063296732,"mc":[{"id":"1.231502182","rc":[{"batb":[[0,2.12,10],[1,2.1,40.37],[2,1.74,17.32]],"ltp":2.2,"tv":291.48,"id":26354927}]}]}
{"op":"mcm","clk":"11793114425","pt":1723063300171,"mc":[{"id":"1.231502182","rc":[{"batb":[[0,2.1,40.37],[1,1.74,17.32],[2,1.7,10]],"ltp":2.2,"tv":291.48,"id":26354927}]}]}
{"op":"mcm","clk":"11793114501","pt":1723063302275,"mc":[{"id":"1.231502182","rc":[{"batb":[[0,2.12,10],[1,2.1,40.37],[2,1.74,17.32]],"ltp":2.2,"tv":291.48,"id":26354927}]}]}
{"op":"mcm","clk":"11793114627","pt":1723063305453,"mc":[{"id":"1.231502182","rc":[{"batb":[[0,2.1,40.37],[1,1.74,17.32],[2,1.7,10]],"ltp":2.2,"tv":291.48,"id":26354927}]}]}
{"op":"mcm","clk":"11793114733","pt":1723063308349,"mc":[{"id":"1.231502182","rc":[{"batb":[[0,2.12,10],[1,2.1,40.37],[2,1.74,17.32]],"ltp":2.2,"tv":291.48,"id":26354927}]}]}
{"op":"mcm","clk":"11793114878","pt":1723063311845,"mc":[{"id":"1.231502182","rc":[{"batb":[[0,2.1,40.37],[1,1.74,17.32],[2,1.7,10]],"ltp":2.2,"tv":291.48,"id":26354927}]}]}
{"op":"mcm","clk":"11793134630","pt":1723063585772,"mc":[{"id":"1.231502182","rc":[{"batb":[[0,1.83,5],[1,1.82,3.04],[2,1.8,20]],"ltp":1.82,"tv":580.94,"id":26354924}]}]}
{"op":"mcm","clk":"11793135639","pt":1723063625339,"mc":[{"id":"1.231502182","rc":[{"trd":[[1.8,33.92],[1.82,16.08],[1.83,173.08]],"batb":[[0,1.8,3.04],[1,1.79,56.21],[2,1.78,800]],"ltp":1.8,"tv":630.94,"id":26354924}],"tv":922.43}]}
{"op":"mcm","clk":"11793136538","pt":1723063657167,"mc":[{"id":"1.231502182","rc":[{"batb":[[0,1.8,8.04]],"ltp":1.8,"tv":630.94,"id":26354924}]}]}
{"op":"mcm","clk":"11793137069","pt":1723063679985,"mc":[{"id":"1.231502182","rc":[{"batb":[[0,1.8,5]],"ltp":1.8,"tv":630.94,"id":26354924}]}]}
{"op":"mcm","clk":"11793137071","pt":1723063680088,"mc":[{"id":"1.231502182","rc":[{"batb":[[0,1.81,3.04],[1,1.8,5],[2,1.79,56.21]],"ltp":1.8,"tv":630.94,"id":26354924}]}]}
{"op":"mcm","clk":"11793137406","pt":1723063697014,"mc":[{"id":"1.231502182","rc":[{"batb":[[2,1.79,66.21]],"ltp":1.8,"tv":630.94,"id":26354924}]}]}
{"op":"mcm","clk":"11793137450","pt":1723063699324,"mc":[{"id":"1.231502182","rc":[{"batb":[[2,1.79,56.21]],"ltp":1.8,"tv":630.94,"id":26354924}]}]}
{"op":"mcm","clk":"11793144072","pt":1723063968627,"mc":[{"id":"1.231502182","rc":[{"batl":[[2,1.87,8]],"ltp":1.8,"tv":630.94,"id":26354924}]}]}
{"op":"mcm","clk":"11793149315","pt":1723064054095,"mc":[{"id":"1.231502182","rc":[{"batb":[[1,1.8,55]],"ltp":1.8,"tv":630.94,"id":26354924}]}]}
{"op":"mcm","clk":"11793150030","pt":1723064069792,"mc":[{"id":"1.231502182","rc":[{"batl":[[2,1.86,25]],"ltp":1.8,"tv":630.94,"id":26354924}]}]}
{"op":"mcm","clk":"11793150670","pt":1723064083234,"mc":[{"id":"1.231502182","rc":[{"batl":[[1,1.85,30]],"ltp":1.8,"tv":630.94,"id":26354924}]}]}
{"op":"mcm","clk":"11793161811","pt":1723064400813,"mc":[{"id":"1.231502182","rc":[{"batb":[[0,2.12,10],[1,2.1,40.37],[2,1.74,17.32]],"ltp":2.2,"tv":291.48,"id":26354927}]}]}
{"op":"mcm","clk":"11793161994","pt":1723064404316,"mc":[{"id":"1.231502182","rc":[{"trd":[[1.4,255.04]],"batb":[[0,2.1,40.37],[1,1.74,17.32],[2,1.7,10]],"ltp":2.2,"tv":291.4,"id":26354927},{"trd":[[1.4,255.59],[1.83,173.08],[1.85,16.09],[1.86,29.3]],"ltp":1.8,"tv":630.85,"id":26354924}],"tv":922.26}]}
{"op":"mcm","clk":"11793162101","pt":1723064407296,"mc":[{"id":"1.231502182","rc":[{"batb":[[0,2.12,10],[1,2.1,40.37],[2,1.74,17.32]],"ltp":2.2,"tv":291.4,"id":26354927}]}]}
{"op":"mcm","clk":"11793162223","pt":1723064410521,"mc":[{"id":"1.231502182","rc":[{"batb":[[0,2.1,40.37],[1,1.74,17.32],[2,1.7,10]],"ltp":2.2,"tv":291.4,"id":26354927}]}]}
{"op":"mcm","clk":"11793162347","pt":1723064414623,"mc":[{"id":"1.231502182","rc":[{"batb":[[0,2.12,10],[1,2.1,40.37],[2,1.74,17.32]],"ltp":2.2,"tv":291.4,"id":26354927}]}]}
{"op":"mcm","clk":"11793162458","pt":1723064418196,"mc":[{"id":"1.231502182","rc":[{"batb":[[0,2.1,40.37],[1,1.74,17.32],[2,1.7,10]],"ltp":2.2,"tv":291.4,"id":26354927}]}]}
{"op":"mcm","clk":"11793162579","pt":1723064421422,"mc":[{"id":"1.231502182","rc":[{"batb":[[0,2.12,10],[1,2.1,40.37],[2,1.74,17.32]],"ltp":2.2,"tv":291.4,"id":26354927}]}]}
{"op":"mcm","clk":"11793162683","pt":1723064424805,"mc":[{"id":"1.231502182","rc":[{"batb":[[0,2.1,40.37],[1,1.74,17.32],[2,1.7,10]],"ltp":2.2,"tv":291.4,"id":26354927}]}]}
{"op":"mcm","clk":"11793162749","pt":1723064427516,"mc":[{"id":"1.231502182","rc":[{"batb":[[0,2.12,10],[1,2.1,40.37],[2,1.74,17.32]],"ltp":2.2,"tv":291.4,"id":26354927}]}]}
{"op":"mcm","clk":"11793162859","pt":1723064430903,"mc":[{"id":"1.231502182","rc":[{"batb":[[0,2.1,40.37],[1,1.74,17.32],[2,1.7,10]],"ltp":2.2,"tv":291.4,"id":26354927}]}]}
{"op":"mcm","clk":"11793162968","pt":1723064434241,"mc":[{"id":"1.231502182","rc":[{"batb":[[0,2.12,10],[1,2.1,40.37],[2,1.74,17.32]],"ltp":2.2,"tv":291.4,"id":26354927}]}]}
{"op":"mcm","clk":"11793163085","pt":1723064437726,"mc":[{"id":"1.231502182","rc":[{"batb":[[0,2.1,40.37],[1,1.74,17.32],[2,1.7,10]],"ltp":2.2,"tv":291.4,"id":26354927}]}]}
{"op":"mcm","clk":"11793163180","pt":1723064440037,"mc":[{"id":"1.231502182","rc":[{"batb":[[0,2.12,10],[1,2.1,40.37],[2,1.74,17.32]],"ltp":2.2,"tv":291.4,"id":26354927}]}]}
{"op":"mcm","clk":"11793163298","pt":1723064443314,"mc":[{"id":"1.231502182","rc":[{"batb":[[0,2.1,40.37],[1,1.74,17.32],[2,1.7,10]],"ltp":2.2,"tv":291.4,"id":26354927}]}]}
{"op":"mcm","clk":"11793163430","pt":1723064447453,"mc":[{"id":"1.231502182","rc":[{"batb":[[0,2.12,10],[1,2.1,40.37],[2,1.74,17.32]],"ltp":2.2,"tv":291.4,"id":26354927}]}]}
{"op":"mcm","clk":"11793163521","pt":1723064450729,"mc":[{"id":"1.231502182","rc":[{"batb":[[0,2.1,40.37],[1,1.74,17.32],[2,1.7,10]],"ltp":2.2,"tv":291.4,"id":26354927}]}]}
{"op":"mcm","clk":"11793163656","pt":1723064455236,"mc":[{"id":"1.231502182","rc":[{"batb":[[0,2.12,10],[1,2.1,40.37],[2,1.74,17.32]],"ltp":2.2,"tv":291.4,"id":26354927}]}]}
{"op":"mcm","clk":"11793163768","pt":1723064458829,"mc":[{"id":"1.231502182","rc":[{"batb":[[0,2.1,40.37],[1,1.74,17.32],[2,1.7,10]],"ltp":2.2,"tv":291.4,"id":26354927}]}]}
{"op":"mcm","clk":"11793163853","pt":1723064461646,"mc":[{"id":"1.231502182","rc":[{"batb":[[0,2.12,10],[1,2.1,40.37],[2,1.74,17.32]],"ltp":2.2,"tv":291.4,"id":26354927}]}]}
{"op":"mcm","clk":"11793163978","pt":1723064465043,"mc":[{"id":"1.231502182","rc":[{"batb":[[0,2.1,40.37],[1,1.74,17.32],[2,1.7,10]],"ltp":2.2,"tv":291.4,"id":26354927}]}]}
{"op":"mcm","clk":"11793164078","pt":1723064467959,"mc":[{"id":"1.231502182","rc":[{"batb":[[0,2.12,10],[1,2.1,40.37],[2,1.74,17.32]],"ltp":2.2,"tv":291.4,"id":26354927}]}]}
{"op":"mcm","clk":"11793164194","pt":1723064471453,"mc":[{"id":"1.231502182","rc":[{"batb":[[0,2.1,40.37],[1,1.74,17.32],[2,1.7,10]],"ltp":2.2,"tv":291.4,"id":26354927}]}]}
{"op":"mcm","clk":"11793164281","pt":1723064473662,"mc":[{"id":"1.231502182","rc":[{"batb":[[0,2.12,10],[1,2.1,40.37],[2,1.74,17.32]],"ltp":2.2,"tv":291.4,"id":26354927}]}]}
{"op":"mcm","clk":"11793164391","pt":1723064476954,"mc":[{"id":"1.231502182","rc":[{"batb":[[0,2.1,40.37],[1,1.74,17.32],[2,1.7,10]],"ltp":2.2,"tv":291.4,"id":26354927}]}]}
{"op":"mcm","clk":"11793164490","pt":1723064479988,"mc":[{"id":"1.231502182","rc":[{"batb":[[0,2.12,10],[1,2.1,40.37],[2,1.74,17.32]],"ltp":2.2,"tv":291.4,"id":26354927}]}]}
{"op":"mcm","clk":"11793164634","pt":1723064483176,"mc":[{"id":"1.231502182","rc":[{"batb":[[0,2.1,40.37],[1,1.74,17.32],[2,1.7,10]],"ltp":2.2,"tv":291.4,"id":26354927}]}]}
{"op":"mcm","clk":"11793164721","pt":1723064485589,"mc":[{"id":"1.231502182","rc":[{"batb":[[0,2.12,10],[1,2.1,40.37],[2,1.74,17.32]],"ltp":2.2,"tv":291.4,"id":26354927}]}]}
{"op":"mcm","clk":"11793164866","pt":1723064489083,"mc":[{"id":"1.231502182","rc":[{"batb":[[0,2.1,40.37],[1,1.74,17.32],[2,1.7,10]],"ltp":2.2,"tv":291.4,"id":26354927}]}]}
{"op":"mcm","clk":"11793164995","pt":1723064491284,"mc":[{"id":"1.231502182","rc":[{"batb":[[0,2.12,10],[1,2.1,40.37],[2,1.74,17.32]],"ltp":2.2,"tv":291.4,"id":26354927}]}]}
{"op":"mcm","clk":"11793165152","pt":1723064494519,"mc":[{"id":"1.231502182","rc":[{"batb":[[0,2.1,40.37],[1,1.74,17.32],[2,1.7,10]],"ltp":2.2,"tv":291.4,"id":26354927}]}]}
{"op":"mcm","clk":"11793165316","pt":1723064498013,"mc":[{"id":"1.231502182","rc":[{"batb":[[0,2.12,10],[1,2.1,40.37],[2,1.74,17.32]],"ltp":2.2,"tv":291.4,"id":26354927}]}]}
{"op":"mcm","clk":"11793165466","pt":1723064501293,"mc":[{"id":"1.231502182","rc":[{"batb":[[0,2.1,40.37],[1,1.74,17.32],[2,1.7,10]],"ltp":2.2,"tv":291.4,"id":26354927}]}]}
{"op":"mcm","clk":"11793165584","pt":1723064503606,"mc":[{"id":"1.231502182","rc":[{"batb":[[0,2.12,10],[1,2.1,40.37],[2,1.74,17.32]],"ltp":2.2,"tv":291.4,"id":26354927}]}]}
{"op":"mcm","clk":"11793165735","pt":1723064506787,"mc":[{"id":"1.231502182","rc":[{"batb":[[0,2.1,40.37],[1,1.74,17.32],[2,1.7,10]],"ltp":2.2,"tv":291.4,"id":26354927}]}]}
{"op":"mcm","clk":"11793165870","pt":1723064509818,"mc":[{"id":"1.231502182","rc":[{"batb":[[0,2.12,10],[1,2.1,40.37],[2,1.74,17.32]],"ltp":2.2,"tv":291.4,"id":26354927}]}]}
{"op":"mcm","clk":"11793166002","pt":1723064513102,"mc":[{"id":"1.231502182","rc":[{"batb":[[0,2.1,40.37],[1,1.74,17.32],[2,1.7,10]],"ltp":2.2,"tv":291.4,"id":26354927}]}]}
{"op":"mcm","clk":"11793166118","pt":1723064515820,"mc":[{"id":"1.231502182","rc":[{"batb":[[0,2.12,10],[1,2.1,40.37],[2,1.74,17.32]],"ltp":2.2,"tv":291.4,"id":26354927}]}]}
{"op":"mcm","clk":"11793166268","pt":1723064519000,"mc":[{"id":"1.231502182","rc":[{"batb":[[0,2.1,40.37],[1,1.74,17.32],[2,1.7,10]],"ltp":2.2,"tv":291.4,"id":26354927}]}]}
{"op":"mcm","clk":"11793166412","pt":1723064522232,"mc":[{"id":"1.231502182","rc":[{"batb":[[0,2.12,10],[1,2.1,40.37],[2,1.74,17.32]],"ltp":2.2,"tv":291.4,"id":26354927}]}]}
{"op":"mcm","clk":"11793166569","pt":1723064525518,"mc":[{"id":"1.231502182","rc":[{"batb":[[0,2.1,40.37],[1,1.74,17.32],[2,1.7,10]],"ltp":2.2,"tv":291.4,"id":26354927}]}]}
{"op":"mcm","clk":"11793166668","pt":1723064527724,"mc":[{"id":"1.231502182","rc":[{"batb":[[0,2.12,10],[1,2.1,40.37],[2,1.74,17.32]],"ltp":2.2,"tv":291.4,"id":26354927}]}]}
{"op":"mcm","clk":"11793166791","pt":1723064531106,"mc":[{"id":"1.231502182","rc":[{"batb":[[0,2.1,40.37],[1,1.74,17.32],[2,1.7,10]],"ltp":2.2,"tv":291.4,"id":26354927}]}]}
{"op":"mcm","clk":"11793166912","pt":1723064533721,"mc":[{"id":"1.231502182","rc":[{"batb":[[0,2.12,10],[1,2.1,40.37],[2,1.74,17.32]],"ltp":2.2,"tv":291.4,"id":26354927}]}]}
{"op":"mcm","clk":"11793167060","pt":1723064536950,"mc":[{"id":"1.231502182","rc":[{"batb":[[0,2.1,40.37],[1,1.74,17.32],[2,1.7,10]],"ltp":2.2,"tv":291.4,"id":26354927}]}]}
{"op":"mcm","clk":"11793167341","pt":1723064542131,"mc":[{"id":"1.231502182","rc":[{"batb":[[0,2.12,10],[1,2.1,40.37],[2,1.74,17.32]],"ltp":2.2,"tv":291.4,"id":26354927}]}]}
{"op":"mcm","clk":"11793167470","pt":1723064545377,"mc":[{"id":"1.231502182","rc":[{"batb":[[0,2.1,40.37],[1,1.74,17.32],[2,1.7,10]],"ltp":2.2,"tv":291.4,"id":26354927}]}]}
{"op":"mcm","clk":"11793167590","pt":1723064548339,"mc":[{"id":"1.231502182","rc":[{"batb":[[0,2.12,10],[1,2.1,40.37],[2,1.74,17.32]],"ltp":2.2,"tv":291.4,"id":26354927}]}]}
{"op":"mcm","clk":"11793167737","pt":1723064551586,"mc":[{"id":"1.231502182","rc":[{"batb":[[0,2.1,40.37],[1,1.74,17.32],[2,1.7,10]],"ltp":2.2,"tv":291.4,"id":26354927}]}]}
{"op":"mcm","clk":"11793167820","pt":1723064553794,"mc":[{"id":"1.231502182","rc":[{"trd":[[2.18,1]],"ltp":2.18,"tv":292.4,"id":26354927},{"trd":[[1.84,3.09]],"batl":[[0,1.84,6.82]],"ltp":1.84,"tv":632.03,"id":26354924}],"tv":924.44}]}
{"op":"mcm","clk":"11793167861","pt":1723064554765,"mc":[{"id":"1.231502182","rc":[{"batb":[[0,2.12,10],[1,2.1,40.37],[2,1.74,17.32]],"ltp":2.18,"tv":292.4,"id":26354927}]}]}
{"op":"mcm","clk":"11793168023","pt":1723064558568,"mc":[{"id":"1.231502182","rc":[{"batb":[[0,2.1,40.37],[1,1.74,17.32],[2,1.7,10]],"ltp":2.18,"tv":292.4,"id":26354927}]}]}
{"op":"mcm","clk":"11793168112","pt":1723064561593,"mc":[{"id":"1.231502182","rc":[{"batb":[[0,2.12,10],[1,2.1,40.37],[2,1.74,17.32]],"ltp":2.18,"tv":292.4,"id":26354927}]}]}
{"op":"mcm","clk":"11793168237","pt":1723064564782,"mc":[{"id":"1.231502182","rc":[{"batb":[[0,2.1,40.37],[1,1.74,17.32],[2,1.7,10]],"ltp":2.18,"tv":292.4,"id":26354927}]}]}
{"op":"mcm","clk":"11793168347","pt":1723064568114,"mc":[{"id":"1.231502182","rc":[{"batb":[[0,2.12,10],[1,2.1,40.37],[2,1.74,17.32]],"ltp":2.18,"tv":292.4,"id":26354927}]}]}
{"op":"mcm","clk":"11793168486","pt":1723064571511,"mc":[{"id":"1.231502182","rc":[{"batb":[[0,2.1,40.37],[1,1.74,17.32],[2,1.7,10]],"ltp":2.18,"tv":292.4,"id":26354927}]}]}
{"op":"mcm","clk":"11793168606","pt":1723064573926,"mc":[{"id":"1.231502182","rc":[{"batb":[[0,2.12,10],[1,2.1,40.37],[2,1.74,17.32]],"ltp":2.18,"tv":292.4,"id":26354927}]}]}
{"op":"mcm","clk":"11793168736","pt":1723064577422,"mc":[{"id":"1.231502182","rc":[{"batb":[[0,2.1,40.37],[1,1.74,17.32],[2,1.7,10]],"ltp":2.18,"tv":292.4,"id":26354927}]}]}
{"op":"mcm","clk":"11793168889","pt":1723064580399,"mc":[{"id":"1.231502182","rc":[{"batb":[[0,2.12,10],[1,2.1,40.37],[2,1.74,17.32]],"ltp":2.18,"tv":292.4,"id":26354927}]}]}
{"op":"mcm","clk":"11793169040","pt":1723064583646,"mc":[{"id":"1.231502182","rc":[{"batb":[[0,2.1,40.37],[1,1.74,17.32],[2,1.7,10]],"ltp":2.18,"tv":292.4,"id":26354927}]}]}
{"op":"mcm","clk":"11793169164","pt":1723064587207,"mc":[{"id":"1.231502182","rc":[{"batb":[[0,2.12,10],[1,2.1,40.37],[2,1.74,17.32]],"ltp":2.18,"tv":292.4,"id":26354927}]}]}
{"op":"mcm","clk":"11793169284","pt":1723064590638,"mc":[{"id":"1.231502182","rc":[{"batb":[[0,2.1,40.37],[1,1.74,17.32],[2,1.7,10]],"ltp":2.18,"tv":292.4,"id":26354927}]}]}
{"op":"mcm","clk":"11793169392","pt":1723064594031,"mc":[{"id":"1.231502182","rc":[{"batb":[[0,2.12,10],[1,2.1,40.37],[2,1.74,17.32]],"ltp":2.18,"tv":292.4,"id":26354927}]}]}
{"op":"mcm","clk":"11793169517","pt":1723064597425,"mc":[{"id":"1.231502182","rc":[{"batb":[[0,2.1,40.37],[1,1.74,17.32],[2,1.7,10]],"ltp":2.18,"tv":292.4,"id":26354927}]}]}
{"op":"mcm","clk":"11793169567","pt":1723064599934,"mc":[{"id":"1.231502182","rc":[{"batb":[[0,2.12,10],[1,2.1,40.37],[2,1.74,17.32]],"ltp":2.18,"tv":292.4,"id":26354927}]}]}
{"op":"mcm","clk":"11793169647","pt":1723064603332,"mc":[{"id":"1.231502182","rc":[{"batb":[[0,2.1,40.37],[1,1.74,17.32],[2,1.7,10]],"ltp":2.18,"tv":292.4,"id":26354927}]}]}
{"op":"mcm","clk":"11793169747","pt":1723064606040,"mc":[{"id":"1.231502182","rc":[{"batb":[[0,2.12,10],[1,2.1,40.37],[2,1.74,17.32]],"ltp":2.18,"tv":292.4,"id":26354927}]}]}
{"op":"mcm","clk":"11793169900","pt":1723064609271,"mc":[{"id":"1.231502182","rc":[{"batb":[[0,2.1,40.37],[1,1.74,17.32],[2,1.7,10]],"ltp":2.18,"tv":292.4,"id":26354927}]}]}
{"op":"mcm","clk":"11793170007","pt":1723064612047,"mc":[{"id":"1.231502182","rc":[{"batb":[[0,2.12,10],[1,2.1,40.37],[2,1.74,17.32]],"ltp":2.18,"tv":292.4,"id":26354927}]}]}
{"op":"mcm","clk":"11793170146","pt":1723064615274,"mc":[{"id":"1.231502182","rc":[{"batb":[[0,2.1,40.37],[1,1.74,17.32],[2,1.7,10]],"ltp":2.18,"tv":292.4,"id":26354927}]}]}
{"op":"mcm","clk":"11793170240","pt":1723064617682,"mc":[{"id":"1.231502182","rc":[{"batb":[[0,2.12,10],[1,2.1,40.37],[2,1.74,17.32]],"ltp":2.18,"tv":292.4,"id":26354927}]}]}
{"op":"mcm","clk":"11793170387","pt":1723064621168,"mc":[{"id":"1.231502182","rc":[{"batb":[[0,2.1,40.37],[1,1.74,17.32],[2,1.7,10]],"ltp":2.18,"tv":292.4,"id":26354927}]}]}
{"op":"mcm","clk":"11793170509","pt":1723064623880,"mc":[{"id":"1.231502182","rc":[{"batb":[[0,2.12,10],[1,2.1,40.37],[2,1.74,17.32]],"ltp":2.18,"tv":292.4,"id":26354927}]}]}
{"op":"mcm","clk":"11793170678","pt":1723064627262,"mc":[{"id":"1.231502182","rc":[{"batb":[[0,2.1,40.37],[1,1.74,17.32],[2,1.7,10]],"ltp":2.18,"tv":292.4,"id":26354927}]}]}
{"op":"mcm","clk":"11793170796","pt":1723064630696,"mc":[{"id":"1.231502182","rc":[{"batb":[[0,2.12,10],[1,2.1,40.37],[2,1.74,17.32]],"ltp":2.18,"tv":292.4,"id":26354927}]}]}
{"op":"mcm","clk":"11793170929","pt":1723064634085,"mc":[{"id":"1.231502182","rc":[{"batb":[[0,2.1,40.37],[1,1.74,17.32],[2,1.7,10]],"ltp":2.18,"tv":292.4,"id":26354927}]}]}
{"op":"mcm","clk":"11793171030","pt":1723064636801,"mc":[{"id":"1.231502182","rc":[{"batb":[[0,2.12,10],[1,2.1,40.37],[2,1.74,17.32]],"ltp":2.18,"tv":292.4,"id":26354927}]}]}
{"op":"mcm","clk":"11793171160","pt":1723064640287,"mc":[{"id":"1.231502182","rc":[{"batb":[[0,2.1,40.37],[1,1.74,17.32],[2,1.7,10]],"ltp":2.18,"tv":292.4,"id":26354927}]}]}
{"op":"mcm","clk":"11793171257","pt":1723064642597,"mc":[{"id":"1.231502182","rc":[{"batb":[[0,2.12,10],[1,2.1,40.37],[2,1.74,17.32]],"ltp":2.18,"tv":292.4,"id":26354927}]}]}
{"op":"mcm","clk":"11793171396","pt":1723064646103,"mc":[{"id":"1.231502182","rc":[{"batb":[[0,2.1,40.37],[1,1.74,17.32],[2,1.7,10]],"ltp":2.18,"tv":292.4,"id":26354927}]}]}
{"op":"mcm","clk":"11793171505","pt":1723064649294,"mc":[{"id":"1.231502182","rc":[{"batb":[[0,2.12,10],[1,2.1,40.37],[2,1.74,17.32]],"ltp":2.18,"tv":292.4,"id":26354927}]}]}
{"op":"mcm","clk":"11793171625","pt":1723064653519,"mc":[{"id":"1.231502182","rc":[{"batb":[[0,2.1,40.37],[1,1.74,17.32],[2,1.7,10]],"ltp":2.18,"tv":292.4,"id":26354927}]}]}
{"op":"mcm","clk":"11793171727","pt":1723064656491,"mc":[{"id":"1.231502182","rc":[{"batb":[[0,2.12,10],[1,2.1,40.37],[2,1.74,17.32]],"ltp":2.18,"tv":292.4,"id":26354927}]}]}
{"op":"mcm","clk":"11793171834","pt":1723064660028,"mc":[{"id":"1.231502182","rc":[{"batb":[[0,2.1,40.37],[1,1.74,17.32],[2,1.7,10]],"ltp":2.18,"tv":292.4,"id":26354927}]}]}
{"op":"mcm","clk":"11793171906","pt":1723064662898,"mc":[{"id":"1.231502182","rc":[{"batb":[[0,2.12,10],[1,2.1,40.37],[2,1.74,17.32]],"ltp":2.18,"tv":292.4,"id":26354927}]}]}
{"op":"mcm","clk":"11793172023","pt":1723064666330,"mc":[{"id":"1.231502182","rc":[{"batb":[[0,2.1,40.37],[1,1.74,17.32],[2,1.7,10]],"ltp":2.18,"tv":292.4,"id":26354927}]}]}
{"op":"mcm","clk":"11793172132","pt":1723064669720,"mc":[{"id":"1.231502182","rc":[{"batb":[[0,2.12,10],[1,2.1,40.37],[2,1.74,17.32]],"ltp":2.18,"tv":292.4,"id":26354927}]}]}
{"op":"mcm","clk":"11793172252","pt":1723064673113,"mc":[{"id":"1.231502182","rc":[{"batb":[[0,2.1,40.37],[1,1.74,17.32],[2,1.7,10]],"ltp":2.18,"tv":292.4,"id":26354927}]}]}
{"op":"mcm","clk":"11793172457","pt":1723064678147,"mc":[{"id":"1.231502182","rc":[{"batb":[[0,2.12,10],[1,2.1,40.37],[2,1.74,17.32]],"ltp":2.18,"tv":292.4,"id":26354927}]}]}
{"op":"mcm","clk":"11793172540","pt":1723064681324,"mc":[{"id":"1.231502182","rc":[{"batb":[[0,2.1,40.37],[1,1.74,17.32],[2,1.7,10]],"ltp":2.18,"tv":292.4,"id":26354927}]}]}
{"op":"mcm","clk":"11793172633","pt":1723064684054,"mc":[{"id":"1.231502182","rc":[{"batb":[[0,2.12,10],[1,2.1,40.37],[2,1.74,17.32]],"ltp":2.18,"tv":292.4,"id":26354927}]}]}
{"op":"mcm","clk":"11793172720","pt":1723064687234,"mc":[{"id":"1.231502182","rc":[{"batb":[[0,2.1,40.37],[1,1.74,17.32],[2,1.7,10]],"ltp":2.18,"tv":292.4,"id":26354927}]}]}
{"op":"mcm","clk":"11793172777","pt":1723064689737,"mc":[{"id":"1.231502182","rc":[{"batb":[[0,2.12,10],[1,2.1,40.37],[2,1.74,17.32]],"ltp":2.18,"tv":292.4,"id":26354927}]}]}
{"op":"mcm","clk":"11793172866","pt":1723064693082,"mc":[{"id":"1.231502182","rc":[{"batb":[[0,2.1,40.37],[1,1.74,17.32],[2,1.7,10]],"ltp":2.18,"tv":292.4,"id":26354927}]}]}
{"op":"mcm","clk":"11793172944","pt":1723064695339,"mc":[{"id":"1.231502182","rc":[{"batb":[[0,2.12,10],[1,2.1,40.37],[2,1.74,17.32]],"ltp":2.18,"tv":292.4,"id":26354927}]}]}
{"op":"mcm","clk":"11793173057","pt":1723064698777,"mc":[{"id":"1.231502182","rc":[{"batb":[[0,2.1,40.37],[1,1.74,17.32],[2,1.7,10]],"ltp":2.18,"tv":292.4,"id":26354927}]}]}
{"op":"mcm","clk":"11793173116","pt":1723064701148,"mc":[{"id":"1.231502182","rc":[{"batb":[[0,2.12,10],[1,2.1,40.37],[2,1.74,17.32]],"ltp":2.18,"tv":292.4,"id":26354927}]}]}
{"op":"mcm","clk":"11793173239","pt":1723064704596,"mc":[{"id":"1.231502182","rc":[{"batb":[[0,2.1,40.37],[1,1.74,17.32],[2,1.7,10]],"ltp":2.18,"tv":292.4,"id":26354927}]}]}
{"op":"mcm","clk":"11793173410","pt":1723064709984,"mc":[{"id":"1.231502182","rc":[{"batb":[[0,2.12,10],[1,2.1,40.37],[2,1.74,17.32]],"ltp":2.18,"tv":292.4,"id":26354927}]}]}
{"op":"mcm","clk":"11793173535","pt":1723064713477,"mc":[{"id":"1.231502182","rc":[{"batb":[[0,2.1,40.37],[1,1.74,17.32],[2,1.7,10]],"ltp":2.18,"tv":292.4,"id":26354927}]}]}
{"op":"mcm","clk":"11793173620","pt":1723064716356,"mc":[{"id":"1.231502182","rc":[{"batb":[[0,2.12,10],[1,2.1,40.37],[2,1.74,17.32]],"ltp":2.18,"tv":292.4,"id":26354927}]}]}
{"op":"mcm","clk":"11793173709","pt":1723064719794,"mc":[{"id":"1.231502182","rc":[{"batb":[[0,2.1,40.37],[1,1.74,17.32],[2,1.7,10]],"ltp":2.18,"tv":292.4,"id":26354927}]}]}
{"op":"mcm","clk":"11793173798","pt":1723064723074,"mc":[{"id":"1.231502182","rc":[{"batb":[[0,2.12,10],[1,2.1,40.37],[2,1.74,17.32]],"ltp":2.18,"tv":292.4,"id":26354927}]}]}
{"op":"mcm","clk":"11793173898","pt":1723064726321,"mc":[{"id":"1.231502182","rc":[{"batb":[[0,2.1,40.37],[1,1.74,17.32],[2,1.7,10]],"ltp":2.18,"tv":292.4,"id":26354927}]}]}
{"op":"mcm","clk":"11793173988","pt":1723064728482,"mc":[{"id":"1.231502182","rc":[{"batb":[[0,2.12,10],[1,2.1,40.37],[2,1.74,17.32]],"ltp":2.18,"tv":292.4,"id":26354927}]}]}
{"op":"mcm","clk":"11793174090","pt":1723064731912,"mc":[{"id":"1.231502182","rc":[{"batb":[[0,2.1,40.37],[1,1.74,17.32],[2,1.7,10]],"ltp":2.18,"tv":292.4,"id":26354927}]}]}
{"op":"mcm","clk":"11793174219","pt":1723064735901,"mc":[{"id":"1.231502182","rc":[{"batb":[[0,2.12,10],[1,2.1,40.37],[2,1.74,17.32]],"ltp":2.18,"tv":292.4,"id":26354927}]}]}
{"op":"mcm","clk":"11793174336","pt":1723064739129,"mc":[{"id":"1.231502182","rc":[{"batb":[[0,2.1,40.37],[1,1.74,17.32],[2,1.7,10]],"ltp":2.18,"tv":292.4,"id":26354927}]}]}
{"op":"mcm","clk":"11793174490","pt":1723064742587,"mc":[{"id":"1.231502182","rc":[{"batb":[[0,2.12,10],[1,2.1,40.37],[2,1.74,17.32]],"ltp":2.18,"tv":292.4,"id":26354927}]}]}
{"op":"mcm","clk":"11793174637","pt":1723064745935,"mc":[{"id":"1.231502182","rc":[{"batb":[[0,2.1,40.37],[1,1.74,17.32],[2,1.7,10]],"ltp":2.18,"tv":292.4,"id":26354927}]}]}
{"op":"mcm","clk":"11793174799","pt":1723064749800,"mc":[{"id":"1.231502182","rc":[{"batb":[[0,2.12,10],[1,2.1,40.37],[2,1.74,17.32]],"ltp":2.18,"tv":292.4,"id":26354927}]}]}
{"op":"mcm","clk":"11793174938","pt":1723064753243,"mc":[{"id":"1.231502182","rc":[{"batb":[[0,2.1,40.37],[1,1.74,17.32],[2,1.7,10]],"ltp":2.18,"tv":292.4,"id":26354927}]}]}
{"op":"mcm","clk":"11793175098","pt":1723064757120,"mc":[{"id":"1.231502182","rc":[{"batb":[[0,2.12,10],[1,2.1,40.37],[2,1.74,17.32]],"ltp":2.18,"tv":292.4,"id":26354927}]}]}
{"op":"mcm","clk":"11793175218","pt":1723064760455,"mc":[{"id":"1.231502182","rc":[{"batb":[[0,2.1,40.37],[1,1.74,17.32],[2,1.7,10]],"ltp":2.18,"tv":292.4,"id":26354927}]}]}
{"op":"mcm","clk":"11793175396","pt":1723064766255,"mc":[{"id":"1.231502182","rc":[{"batb":[[0,2.12,10],[1,2.1,40.37],[2,1.74,17.32]],"ltp":2.18,"tv":292.4,"id":26354927}]}]}
{"op":"mcm","clk":"11793175488","pt":1723064769435,"mc":[{"id":"1.231502182","rc":[{"batb":[[0,2.1,40.37],[1,1.74,17.32],[2,1.7,10]],"ltp":2.18,"tv":292.4,"id":26354927}]}]}
{"op":"mcm","clk":"11793175582","pt":1723064771847,"mc":[{"id":"1.231502182","rc":[{"batb":[[0,2.12,10],[1,2.1,40.37],[2,1.74,17.32]],"ltp":2.18,"tv":292.4,"id":26354927}]}]}
{"op":"mcm","clk":"11793175676","pt":1723064775072,"mc":[{"id":"1.231502182","rc":[{"batb":[[0,2.1,40.37],[1,1.74,17.32],[2,1.7,10]],"ltp":2.18,"tv":292.4,"id":26354927}]}]}
{"op":"mcm","clk":"11793175794","pt":1723064778051,"mc":[{"id":"1.231502182","rc":[{"batb":[[0,2.12,10],[1,2.1,40.37],[2,1.74,17.32]],"ltp":2.18,"tv":292.4,"id":26354927}]}]}
{"op":"mcm","clk":"11793175927","pt":1723064781490,"mc":[{"id":"1.231502182","rc":[{"batb":[[0,2.1,40.37],[1,1.74,17.32],[2,1.7,10]],"ltp":2.18,"tv":292.4,"id":26354927}]}]}
{"op":"mcm","clk":"11793176029","pt":1723064784558,"mc":[{"id":"1.231502182","rc":[{"batb":[[0,2.12,10],[1,2.1,40.37],[2,1.74,17.32]],"ltp":2.18,"tv":292.4,"id":26354927}]}]}
{"op":"mcm","clk":"11793176164","pt":1723064787995,"mc":[{"id":"1.231502182","rc":[{"batb":[[0,2.1,40.37],[1,1.74,17.32],[2,1.7,10]],"ltp":2.18,"tv":292.4,"id":26354927}]}]}
{"op":"mcm","clk":"11793176260","pt":1723064790355,"mc":[{"id":"1.231502182","rc":[{"batb":[[0,2.12,10],[1,2.1,40.37],[2,1.74,17.32]],"ltp":2.18,"tv":292.4,"id":26354927}]}]}
{"op":"mcm","clk":"11793176381","pt":1723064793889,"mc":[{"id":"1.231502182","rc":[{"batb":[[0,2.1,40.37],[1,1.74,17.32],[2,1.7,10]],"ltp":2.18,"tv":292.4,"id":26354927}]}]}
{"op":"mcm","clk":"11793176466","pt":1723064796360,"mc":[{"id":"1.231502182","rc":[{"batb":[[0,2.12,10],[1,2.1,40.37],[2,1.74,17.32]],"ltp":2.18,"tv":292.4,"id":26354927}]}]}
{"op":"mcm","clk":"11793176567","pt":1723064799792,"mc":[{"id":"1.231502182","rc":[{"batb":[[0,2.1,40.37],[1,1.74,17.32],[2,1.7,10]],"ltp":2.18,"tv":292.4,"id":26354927}]}]}
{"op":"mcm","clk":"11793176663","pt":1723064802410,"mc":[{"id":"1.231502182","rc":[{"batb":[[0,2.12,10],[1,2.1,40.37],[2,1.74,17.32]],"ltp":2.18,"tv":292.4,"id":26354927}]}]}
{"op":"mcm","clk":"11793176783","pt":1723064805688,"mc":[{"id":"1.231502182","rc":[{"batb":[[0,2.1,40.37],[1,1.74,17.32],[2,1.7,10]],"ltp":2.18,"tv":292.4,"id":26354927}]}]}
{"op":"mcm","clk":"11793176841","pt":1723064808199,"mc":[{"id":"1.231502182","rc":[{"batb":[[0,2.12,10],[1,2.1,40.37],[2,1.74,17.32]],"ltp":2.18,"tv":292.4,"id":26354927}]}]}
{"op":"mcm","clk":"11793176932","pt":1723064811583,"mc":[{"id":"1.231502182","rc":[{"batb":[[0,2.1,40.37],[1,1.74,17.32],[2,1.7,10]],"ltp":2.18,"tv":292.4,"id":26354927}]}]}
{"op":"mcm","clk":"11793177099","pt":1723064817413,"mc":[{"id":"1.231502182","rc":[{"batb":[[0,2.12,10],[1,2.1,40.37],[2,1.74,17.32]],"ltp":2.18,"tv":292.4,"id":26354927}]}]}
{"op":"mcm","clk":"11793177207","pt":1723064820904,"mc":[{"id":"1.231502182","rc":[{"batb":[[0,2.1,40.37],[1,1.74,17.32],[2,1.7,10]],"ltp":2.18,"tv":292.4,"id":26354927}]}]}
{"op":"mcm","clk":"11793177280","pt":1723064823515,"mc":[{"id":"1.231502182","rc":[{"batb":[[0,2.12,10],[1,2.1,40.37],[2,1.74,17.32]],"ltp":2.18,"tv":292.4,"id":26354927}]}]}
{"op":"mcm","clk":"11793177396","pt":1723064826997,"mc":[{"id":"1.231502182","rc":[{"batb":[[0,2.1,40.37],[1,1.74,17.32],[2,1.7,10]],"ltp":2.18,"tv":292.4,"id":26354927}]}]}
{"op":"mcm","clk":"11793177473","pt":1723064829715,"mc":[{"id":"1.231502182","rc":[{"batb":[[0,2.12,10],[1,2.1,40.37],[2,1.74,17.32]],"ltp":2.18,"tv":292.4,"id":26354927}]}]}
{"op":"mcm","clk":"11793177633","pt":1723064833315,"mc":[{"id":"1.231502182","rc":[{"batb":[[0,2.1,40.37],[1,1.74,17.32],[2,1.7,10]],"ltp":2.18,"tv":292.4,"id":26354927}]}]}
{"op":"mcm","clk":"11793177753","pt":1723064836130,"mc":[{"id":"1.231502182","rc":[{"batb":[[0,2.12,10],[1,2.1,40.37],[2,1.74,17.32]],"ltp":2.18,"tv":292.4,"id":26354927}]}]}
{"op":"mcm","clk":"11793177887","pt":1723064839514,"mc":[{"id":"1.231502182","rc":[{"batb":[[0,2.1,40.37],[1,1.74,17.32],[2,1.7,10]],"ltp":2.18,"tv":292.4,"id":26354927}]}]}
{"op":"mcm","clk":"11793178028","pt":1723064843047,"mc":[{"id":"1.231502182","rc":[{"batb":[[0,2.12,10],[1,2.1,40.37],[2,1.74,17.32]],"ltp":2.18,"tv":292.4,"id":26354927}]}]}
{"op":"mcm","clk":"11793178144","pt":1723064846234,"mc":[{"id":"1.231502182","rc":[{"batb":[[0,2.1,40.37],[1,1.74,17.32],[2,1.7,10]],"ltp":2.18,"tv":292.4,"id":26354927}]}]}
{"op":"mcm","clk":"11793178272","pt":1723064848846,"mc":[{"id":"1.231502182","rc":[{"batb":[[0,2.12,10],[1,2.1,40.37],[2,1.74,17.32]],"ltp":2.18,"tv":292.4,"id":26354927}]}]}
{"op":"mcm","clk":"11793178400","pt":1723064852262,"mc":[{"id":"1.231502182","rc":[{"batb":[[0,2.1,40.37],[1,1.74,17.32],[2,1.7,10]],"ltp":2.18,"tv":292.4,"id":26354927}]}]}
{"op":"mcm","clk":"11793178505","pt":1723064854941,"mc":[{"id":"1.231502182","rc":[{"batb":[[0,2.12,10],[1,2.1,40.37],[2,1.74,17.32]],"ltp":2.18,"tv":292.4,"id":26354927}]}]}
{"op":"mcm","clk":"11793178615","pt":1723064858437,"mc":[{"id":"1.231502182","rc":[{"batb":[[0,2.1,40.37],[1,1.74,17.32],[2,1.7,10]],"ltp":2.18,"tv":292.4,"id":26354927}]}]}
{"op":"mcm","clk":"11793178689","pt":1723064860744,"mc":[{"id":"1.231502182","rc":[{"batb":[[0,2.12,10],[1,2.1,40.37],[2,1.74,17.32]],"ltp":2.18,"tv":292.4,"id":26354927}]}]}
{"op":"mcm","clk":"11793178818","pt":1723064864071,"mc":[{"id":"1.231502182","rc":[{"batb":[[0,2.1,40.37],[1,1.74,17.32],[2,1.7,10]],"ltp":2.18,"tv":292.4,"id":26354927}]}]}
{"op":"mcm","clk":"11793178934","pt":1723064867663,"mc":[{"id":"1.231502182","rc":[{"batb":[[0,2.12,10],[1,2.1,40.37],[2,1.74,17.32]],"ltp":2.18,"tv":292.4,"id":26354927}]}]}
{"op":"mcm","clk":"11793179041","pt":1723064871045,"mc":[{"id":"1.231502182","rc":[{"batb":[[0,2.1,40.37],[1,1.74,17.32],[2,1.7,10]],"ltp":2.18,"tv":292.4,"id":26354927}]}]}
{"op":"mcm","clk":"11793179157","pt":1723064874371,"mc":[{"id":"1.231502182","rc":[{"batb":[[0,2.12,10],[1,2.1,40.37],[2,1.74,17.32]],"ltp":2.18,"tv":292.4,"id":26354927}]}]}
{"op":"mcm","clk":"11793179282","pt":1723064877860,"mc":[{"id":"1.231502182","rc":[{"batb":[[0,2.1,40.37],[1,1.74,17.32],[2,1.7,10]],"ltp":2.18,"tv":292.4,"id":26354927}]}]}
{"op":"mcm","clk":"11793179407","pt":1723064880774,"mc":[{"id":"1.231502182","rc":[{"batb":[[0,2.12,10],[1,2.1,40.37],[2,1.74,17.32]],"ltp":2.18,"tv":292.4,"id":26354927}]}]}
{"op":"mcm","clk":"11793179518","pt":1723064884166,"mc":[{"id":"1.231502182","rc":[{"batb":[[0,2.1,40.37],[1,1.74,17.32],[2,1.7,10]],"ltp":2.18,"tv":292.4,"id":26354927}]}]}
{"op":"mcm","clk":"11793179621","pt":1723064886879,"mc":[{"id":"1.231502182","rc":[{"batb":[[0,2.12,10],[1,2.1,40.37],[2,1.74,17.32]],"ltp":2.18,"tv":292.4,"id":26354927}]}]}
{"op":"mcm","clk":"11793179740","pt":1723064890260,"mc":[{"id":"1.231502182","rc":[{"batb":[[0,2.1,40.37],[1,1.74,17.32],[2,1.7,10]],"ltp":2.18,"tv":292.4,"id":26354927}]}]}
{"op":"mcm","clk":"11793179844","pt":1723064892976,"mc":[{"id":"1.231502182","rc":[{"batb":[[0,2.12,10],[1,2.1,40.37],[2,1.74,17.32]],"ltp":2.18,"tv":292.4,"id":26354927}]}]}
{"op":"mcm","clk":"11793179952","pt":1723064896415,"mc":[{"id":"1.231502182","rc":[{"batb":[[0,2.1,40.37],[1,1.74,17.32],[2,1.7,10]],"ltp":2.18,"tv":292.4,"id":26354927}]}]}
{"op":"mcm","clk":"11793180050","pt":1723064899649,"mc":[{"id":"1.231502182","rc":[{"batb":[[0,2.12,10],[1,2.1,40.37],[2,1.74,17.32]],"ltp":2.18,"tv":292.4,"id":26354927}]}]}
{"op":"mcm","clk":"11793180177","pt":1723064902988,"mc":[{"id":"1.231502182","rc":[{"batb":[[0,2.1,40.37],[1,1.74,17.32],[2,1.7,10]],"ltp":2.18,"tv":292.4,"id":26354927}]}]}
{"op":"mcm","clk":"11793180280","pt":1723064905803,"mc":[{"id":"1.231502182","rc":[{"batb":[[0,2.12,10],[1,2.1,40.37],[2,1.74,17.32]],"ltp":2.18,"tv":292.4,"id":26354927}]}]}
{"op":"mcm","clk":"11793180424","pt":1723064909289,"mc":[{"id":"1.231502182","rc":[{"batb":[[0,2.1,40.37],[1,1.74,17.32],[2,1.7,10]],"ltp":2.18,"tv":292.4,"id":26354927}]}]}
{"op":"mcm","clk":"11793180511","pt":1723064911803,"mc":[{"id":"1.231502182","rc":[{"batb":[[0,2.12,10],[1,2.1,40.37],[2,1.74,17.32]],"ltp":2.18,"tv":292.4,"id":26354927}]}]}
{"op":"mcm","clk":"11793180615","pt":1723064915233,"mc":[{"id":"1.231502182","rc":[{"batb":[[0,2.1,40.37],[1,1.74,17.32],[2,1.7,10]],"ltp":2.18,"tv":292.4,"id":26354927}]}]}
{"op":"mcm","clk":"11793180723","pt":1723064917803,"mc":[{"id":"1.231502182","rc":[{"batb":[[0,2.12,10],[1,2.1,40.37],[2,1.74,17.32]],"ltp":2.18,"tv":292.4,"id":26354927}]}]}
{"op":"mcm","clk":"11793180848","pt":1723064921544,"mc":[{"id":"1.231502182","rc":[{"batb":[[0,2.1,40.37],[1,1.74,17.32],[2,1.7,10]],"ltp":2.18,"tv":292.4,"id":26354927}]}]}
{"op":"mcm","clk":"11793180947","pt":1723064924150,"mc":[{"id":"1.231502182","rc":[{"batb":[[0,2.12,10],[1,2.1,40.37],[2,1.74,17.32]],"ltp":2.18,"tv":292.4,"id":26354927}]}]}
{"op":"mcm","clk":"11793181062","pt":1723064927530,"mc":[{"id":"1.231502182","rc":[{"batb":[[0,2.1,40.37],[1,1.74,17.32],[2,1.7,10]],"ltp":2.18,"tv":292.4,"id":26354927}]}]}
{"op":"mcm","clk":"11793181195","pt":1723064930350,"mc":[{"id":"1.231502182","rc":[{"batb":[[0,2.12,10],[1,2.1,40.37],[2,1.74,17.32]],"ltp":2.18,"tv":292.4,"id":26354927}]}]}
{"op":"mcm","clk":"11793181312","pt":1723064933532,"mc":[{"id":"1.231502182","rc":[{"batb":[[0,2.1,40.37],[1,1.74,17.32],[2,1.7,10]],"ltp":2.18,"tv":292.4,"id":26354927}]}]}
{"op":"mcm","clk":"11793181420","pt":1723064936465,"mc":[{"id":"1.231502182","rc":[{"batb":[[0,2.12,10],[1,2.1,40.37],[2,1.74,17.32]],"ltp":2.18,"tv":292.4,"id":26354927}]}]}
{"op":"mcm","clk":"11793181594","pt":1723064939767,"mc":[{"id":"1.231502182","rc":[{"batb":[[0,2.1,40.37],[1,1.74,17.32],[2,1.7,10]],"ltp":2.18,"tv":292.4,"id":26354927}]}]}
{"op":"mcm","clk":"11793181722","pt":1723064942099,"mc":[{"id":"1.231502182","rc":[{"batb":[[0,2.12,10],[1,2.1,40.37],[2,1.74,17.32]],"ltp":2.18,"tv":292.4,"id":26354927}]}]}
{"op":"mcm","clk":"11793181869","pt":1723064945476,"mc":[{"id":"1.231502182","rc":[{"batb":[[0,2.1,40.37],[1,1.74,17.32],[2,1.7,10]],"ltp":2.18,"tv":292.4,"id":26354927}]}]}
{"op":"mcm","clk":"11793181977","pt":1723064947941,"mc":[{"id":"1.231502182","rc":[{"batb":[[0,2.12,10],[1,2.1,40.37],[2,1.74,17.32]],"ltp":2.18,"tv":292.4,"id":26354927}]}]}
{"op":"mcm","clk":"11793182087","pt":1723064951487,"mc":[{"id":"1.231502182","rc":[{"batb":[[0,2.1,40.37],[1,1.74,17.32],[2,1.7,10]],"ltp":2.18,"tv":292.4,"id":26354927}]}]}
{"op":"mcm","clk":"11793182203","pt":1723064954162,"mc":[{"id":"1.231502182","rc":[{"batb":[[0,2.12,10],[1,2.1,40.37],[2,1.74,17.32]],"ltp":2.18,"tv":292.4,"id":26354927}]}]}
{"op":"mcm","clk":"11793182319","pt":1723064957456,"mc":[{"id":"1.231502182","rc":[{"batb":[[0,2.1,40.37],[1,1.74,17.32],[2,1.7,10]],"ltp":2.18,"tv":292.4,"id":26354927}]}]}
{"op":"mcm","clk":"11793182466","pt":1723064960798,"mc":[{"id":"1.231502182","rc":[{"batb":[[0,2.12,10],[1,2.1,40.37],[2,1.74,17.32]],"ltp":2.18,"tv":292.4,"id":26354927}]}]}
{"op":"mcm","clk":"11793182588","pt":1723064964192,"mc":[{"id":"1.231502182","rc":[{"batb":[[0,2.1,40.37],[1,1.74,17.32],[2,1.7,10]],"ltp":2.18,"tv":292.4,"id":26354927}]}]}
{"op":"mcm","clk":"11793182721","pt":1723064967479,"mc":[{"id":"1.231502182","rc":[{"batb":[[0,2.12,10],[1,2.1,40.37],[2,1.74,17.32]],"ltp":2.18,"tv":292.4,"id":26354927}]}]}
{"op":"mcm","clk":"11793182872","pt":1723064971280,"mc":[{"id":"1.231502182","rc":[{"batb":[[0,2.1,40.37],[1,1.74,17.32],[2,1.7,10]],"ltp":2.18,"tv":292.4,"id":26354927}]}]}
{"op":"mcm","clk":"11793182971","pt":1723064973793,"mc":[{"id":"1.231502182","rc":[{"batb":[[0,2.12,10],[1,2.1,40.37],[2,1.74,17.32]],"ltp":2.18,"tv":292.4,"id":26354927}]}]}
{"op":"mcm","clk":"11793183109","pt":1723064977185,"mc":[{"id":"1.231502182","rc":[{"batb":[[0,2.1,40.37],[1,1.74,17.32],[2,1.7,10]],"ltp":2.18,"tv":292.4,"id":26354927}]}]}
{"op":"mcm","clk":"11793183282","pt":1723064981493,"mc":[{"id":"1.231502182","rc":[{"batb":[[0,2.12,10],[1,2.1,40.37],[2,1.74,17.32]],"ltp":2.18,"tv":292.4,"id":26354927}]}]}
{"op":"mcm","clk":"11793183429","pt":1723064984779,"mc":[{"id":"1.231502182","rc":[{"batb":[[0,2.1,40.37],[1,1.74,17.32],[2,1.7,10]],"ltp":2.18,"tv":292.4,"id":26354927}]}]}
{"op":"mcm","clk":"11793183536","pt":1723064987399,"mc":[{"id":"1.231502182","rc":[{"batb":[[0,2.12,10],[1,2.1,40.37],[2,1.74,17.32]],"ltp":2.18,"tv":292.4,"id":26354927}]}]}
{"op":"mcm","clk":"11793183672","pt":1723064990833,"mc":[{"id":"1.231502182","rc":[{"batb":[[0,2.1,40.37],[1,1.74,17.32],[2,1.7,10]],"ltp":2.18,"tv":292.4,"id":26354927}]}]}
{"op":"mcm","clk":"11793183850","pt":1723064994837,"mc":[{"id":"1.231502182","rc":[{"batb":[[0,2.12,10],[1,2.1,40.37],[2,1.74,17.32]],"ltp":2.18,"tv":292.4,"id":26354927}]}]}
{"op":"mcm","clk":"11793183985","pt":1723064998224,"mc":[{"id":"1.231502182","rc":[{"batb":[[0,2.1,40.37],[1,1.74,17.32],[2,1.7,10]],"ltp":2.18,"tv":292.4,"id":26354927}]}]}
{"op":"mcm","clk":"11793184097","pt":1723065000839,"mc":[{"id":"1.231502182","rc":[{"batb":[[0,2.12,10],[1,2.1,40.37],[2,1.74,17.32]],"ltp":2.18,"tv":292.4,"id":26354927}]}]}
{"op":"mcm","clk":"11793184237","pt":1723065004025,"mc":[{"id":"1.231502182","rc":[{"batb":[[0,2.1,40.37],[1,1.74,17.32],[2,1.7,10]],"ltp":2.18,"tv":292.4,"id":26354927}]}]}
{"op":"mcm","clk":"11793184427","pt":1723065008138,"mc":[{"id":"1.231502182","rc":[{"batb":[[0,2.12,10],[1,2.1,40.37],[2,1.74,17.32]],"ltp":2.18,"tv":292.4,"id":26354927}]}]}
{"op":"mcm","clk":"11793184567","pt":1723065011331,"mc":[{"id":"1.231502182","rc":[{"batb":[[0,2.1,40.37],[1,1.74,17.32],[2,1.7,10]],"ltp":2.18,"tv":292.4,"id":26354927}]}]}
{"op":"mcm","clk":"11793184699","pt":1723065014421,"mc":[{"id":"1.231502182","rc":[{"batb":[[0,2.12,10],[1,2.1,40.37],[2,1.74,17.32]],"ltp":2.18,"tv":292.4,"id":26354927}]}]}
{"op":"mcm","clk":"11793184841","pt":1723065017821,"mc":[{"id":"1.231502182","rc":[{"batb":[[0,2.1,40.37],[1,1.74,17.32],[2,1.7,10]],"ltp":2.18,"tv":292.4,"id":26354927}]}]}
{"op":"mcm","clk":"11793184946","pt":1723065020436,"mc":[{"id":"1.231502182","rc":[{"batb":[[0,2.12,10],[1,2.1,40.37],[2,1.74,17.32]],"ltp":2.18,"tv":292.4,"id":26354927}]}]}
{"op":"mcm","clk":"11793185130","pt":1723065023925,"mc":[{"id":"1.231502182","rc":[{"batb":[[0,2.1,40.37],[1,1.74,17.32],[2,1.7,10]],"ltp":2.18,"tv":292.4,"id":26354927}]}]}
{"op":"mcm","clk":"11793185239","pt":1723065026855,"mc":[{"id":"1.231502182","rc":[{"batb":[[0,2.12,10],[1,2.1,40.37],[2,1.74,17.32]],"ltp":2.18,"tv":292.4,"id":26354927}]}]}
{"op":"mcm","clk":"11793185390","pt":1723065030141,"mc":[{"id":"1.231502182","rc":[{"batb":[[0,2.1,40.37],[1,1.74,17.32],[2,1.7,10]],"ltp":2.18,"tv":292.4,"id":26354927}]}]}
{"op":"mcm","clk":"11793185526","pt":1723065034148,"mc":[{"id":"1.231502182","rc":[{"batb":[[0,2.12,10],[1,2.1,40.37],[2,1.74,17.32]],"ltp":2.18,"tv":292.4,"id":26354927}]}]}
{"op":"mcm","clk":"11793185652","pt":1723065037436,"mc":[{"id":"1.231502182","rc":[{"batb":[[0,2.1,40.37],[1,1.74,17.32],[2,1.7,10]],"ltp":2.18,"tv":292.4,"id":26354927}]}]}
{"op":"mcm","clk":"11793185760","pt":1723065040149,"mc":[{"id":"1.231502182","rc":[{"batb":[[0,2.12,10],[1,2.1,40.37],[2,1.74,17.32]],"ltp":2.18,"tv":292.4,"id":26354927}]}]}
{"op":"mcm","clk":"11793185860","pt":1723065043642,"mc":[{"id":"1.231502182","rc":[{"batb":[[0,2.1,40.37],[1,1.74,17.32],[2,1.7,10]],"ltp":2.18,"tv":292.4,"id":26354927}]}]}
{"op":"mcm","clk":"11793185957","pt":1723065046678,"mc":[{"id":"1.231502182","rc":[{"batb":[[0,2.12,10],[1,2.1,40.37],[2,1.74,17.32]],"ltp":2.18,"tv":292.4,"id":26354927}]}]}
{"op":"mcm","clk":"11793186100","pt":1723065050062,"mc":[{"id":"1.231502182","rc":[{"batb":[[0,2.1,40.37],[1,1.74,17.32],[2,1.7,10]],"ltp":2.18,"tv":292.4,"id":26354927}]}]}
{"op":"mcm","clk":"11793186202","pt":1723065052681,"mc":[{"id":"1.231502182","rc":[{"batb":[[0,2.12,10],[1,2.1,40.37],[2,1.74,17.32]],"ltp":2.18,"tv":292.4,"id":26354927}]}]}
{"op":"mcm","clk":"11793186333","pt":1723065056473,"mc":[{"id":"1.231502182","rc":[{"batb":[[0,2.1,40.37],[1,1.74,17.32],[2,1.7,10]],"ltp":2.18,"tv":292.4,"id":26354927}]}]}
{"op":"mcm","clk":"11793186476","pt":1723065060008,"mc":[{"id":"1.231502182","rc":[{"batb":[[0,2.12,10],[1,2.1,40.37],[2,1.74,17.32]],"ltp":2.18,"tv":292.4,"id":26354927}]}]}
{"op":"mcm","clk":"11793186601","pt":1723065063235,"mc":[{"id":"1.231502182","rc":[{"batb":[[0,2.1,40.37],[1,1.74,17.32],[2,1.7,10]],"ltp":2.18,"tv":292.4,"id":26354927}]}]}
{"op":"mcm","clk":"11793186706","pt":1723065065641,"mc":[{"id":"1.231502182","rc":[{"batb":[[0,2.12,10],[1,2.1,40.37],[2,1.74,17.32]],"ltp":2.18,"tv":292.4,"id":26354927}]}]}
{"op":"mcm","clk":"11793186799","pt":1723065068974,"mc":[{"id":"1.231502182","rc":[{"batb":[[0,2.1,40.37],[1,1.74,17.32],[2,1.7,10]],"ltp":2.18,"tv":292.4,"id":26354927}]}]}
{"op":"mcm","clk":"11793186900","pt":1723065072349,"mc":[{"id":"1.231502182","rc":[{"batb":[[0,2.12,10],[1,2.1,40.37],[2,1.74,17.32]],"ltp":2.18,"tv":292.4,"id":26354927}]}]}
{"op":"mcm","clk":"11793187011","pt":1723065075953,"mc":[{"id":"1.231502182","rc":[{"batb":[[0,2.1,40.37],[1,1.74,17.32],[2,1.7,10]],"ltp":2.18,"tv":292.4,"id":26354927}]}]}
{"op":"mcm","clk":"11793187122","pt":1723065078776,"mc":[{"id":"1.231502182","rc":[{"batb":[[0,2.12,10],[1,2.1,40.37],[2,1.74,17.32]],"ltp":2.18,"tv":292.4,"id":26354927}]}]}
{"op":"mcm","clk":"11793187259","pt":1723065082157,"mc":[{"id":"1.231502182","rc":[{"batb":[[0,2.1,40.37],[1,1.74,17.32],[2,1.7,10]],"ltp":2.18,"tv":292.4,"id":26354927}]}]}
{"op":"mcm","clk":"11793187417","pt":1723065085554,"mc":[{"id":"1.231502182","rc":[{"batb":[[0,2.12,10],[1,2.1,40.37],[2,1.74,17.32]],"ltp":2.18,"tv":292.4,"id":26354927}]}]}
{"op":"mcm","clk":"11793187544","pt":1723065088783,"mc":[{"id":"1.231502182","rc":[{"batb":[[0,2.1,40.37],[1,1.74,17.32],[2,1.7,10]],"ltp":2.18,"tv":292.4,"id":26354927}]}]}
{"op":"mcm","clk":"11793187682","pt":1723065091708,"mc":[{"id":"1.231502182","rc":[{"batb":[[0,2.12,10],[1,2.1,40.37],[2,1.74,17.32]],"ltp":2.18,"tv":292.4,"id":26354927}]}]}
{"op":"mcm","clk":"11793187803","pt":1723065095095,"mc":[{"id":"1.231502182","rc":[{"batb":[[0,2.1,40.37],[1,1.74,17.32],[2,1.7,10]],"ltp":2.18,"tv":292.4,"id":26354927}]}]}
{"op":"mcm","clk":"11793187919","pt":1723065098791,"mc":[{"id":"1.231502182","rc":[{"batb":[[0,2.12,10],[1,2.1,40.37],[2,1.74,17.32]],"ltp":2.18,"tv":292.4,"id":26354927}]}]}
{"op":"mcm","clk":"11793188021","pt":1723065102120,"mc":[{"id":"1.231502182","rc":[{"batb":[[0,2.1,40.37],[1,1.74,17.32],[2,1.7,10]],"ltp":2.18,"tv":292.4,"id":26354927}]}]}
{"op":"mcm","clk":"11793188096","pt":1723065104997,"mc":[{"id":"1.231502182","rc":[{"batb":[[0,2.12,10],[1,2.1,40.37],[2,1.74,17.32]],"ltp":2.18,"tv":292.4,"id":26354927}]}]}
{"op":"mcm","clk":"11793188192","pt":1723065108432,"mc":[{"id":"1.231502182","rc":[{"batb":[[0,2.1,40.37],[1,1.74,17.32],[2,1.7,10]],"ltp":2.18,"tv":292.4,"id":26354927}]}]}
{"op":"mcm","clk":"11793188384","pt":1723065111003,"mc":[{"id":"1.231502182","rc":[{"batb":[[0,2.12,10],[1,2.1,40.37],[2,1.74,17.32]],"ltp":2.18,"tv":292.4,"id":26354927}]}]}
{"op":"mcm","clk":"11793188663","pt":1723065114499,"mc":[{"id":"1.231502182","rc":[{"batb":[[0,2.1,40.37],[1,1.74,17.32],[2,1.7,10]],"ltp":2.18,"tv":292.4,"id":26354927}]}]}
{"op":"mcm","clk":"11793188758","pt":1723065117523,"mc":[{"id":"1.231502182","rc":[{"batb":[[0,2.12,10],[1,2.1,40.37],[2,1.74,17.32]],"ltp":2.18,"tv":292.4,"id":26354927}]}]}
{"op":"mcm","clk":"11793188861","pt":1723065120805,"mc":[{"id":"1.231502182","rc":[{"batb":[[0,2.1,40.37],[1,1.74,17.32],[2,1.7,10]],"ltp":2.18,"tv":292.4,"id":26354927}]}]}
{"op":"mcm","clk":"11793188945","pt":1723065123117,"mc":[{"id":"1.231502182","rc":[{"batb":[[0,2.12,10],[1,2.1,40.37],[2,1.74,17.32]],"ltp":2.18,"tv":292.4,"id":26354927}]}]}
{"op":"mcm","clk":"11793189049","pt":1723065126499,"mc":[{"id":"1.231502182","rc":[{"batb":[[0,2.1,40.37],[1,1.74,17.32],[2,1.7,10]],"ltp":2.18,"tv":292.4,"id":26354927}]}]}
{"op":"mcm","clk":"11793189112","pt":1723065128806,"mc":[{"id":"1.231502182","rc":[{"batb":[[0,2.12,10],[1,2.1,40.37],[2,1.74,17.32]],"ltp":2.18,"tv":292.4,"id":26354927}]}]}
{"op":"mcm","clk":"11793189196","pt":1723065132035,"mc":[{"id":"1.231502182","rc":[{"batb":[[0,2.1,40.37],[1,1.74,17.32],[2,1.7,10]],"ltp":2.18,"tv":292.4,"id":26354927}]}]}
{"op":"mcm","clk":"11793189305","pt":1723065135727,"mc":[{"id":"1.231502182","rc":[{"batb":[[0,2.12,10],[1,2.1,40.37],[2,1.74,17.32]],"ltp":2.18,"tv":292.4,"id":26354927}]}]}
{"op":"mcm","clk":"11793189427","pt":1723065139131,"mc":[{"id":"1.231502182","rc":[{"batb":[[0,2.1,40.37],[1,1.74,17.32],[2,1.7,10]],"ltp":2.18,"tv":292.4,"id":26354927}]}]}
{"op":"mcm","clk":"11793189518","pt":1723065141542,"mc":[{"id":"1.231502182","rc":[{"batb":[[0,2.12,10],[1,2.1,40.37],[2,1.74,17.32]],"ltp":2.18,"tv":292.4,"id":26354927}]}]}
{"op":"mcm","clk":"11793189645","pt":1723065144926,"mc":[{"id":"1.231502182","rc":[{"batb":[[0,2.1,40.37],[1,1.74,17.32],[2,1.7,10]],"ltp":2.18,"tv":292.4,"id":26354927}]}]}
{"op":"mcm","clk":"11793189710","pt":1723065147429,"mc":[{"id":"1.231502182","rc":[{"batb":[[0,2.12,10],[1,2.1,40.37],[2,1.74,17.32]],"ltp":2.18,"tv":292.4,"id":26354927}]}]}
{"op":"mcm","clk":"11793189850","pt":1723065150865,"mc":[{"id":"1.231502182","rc":[{"batb":[[0,2.1,40.37],[1,1.74,17.32],[2,1.7,10]],"ltp":2.18,"tv":292.4,"id":26354927}]}]}
{"op":"mcm","clk":"11793189967","pt":1723065154452,"mc":[{"id":"1.231502182","rc":[{"batb":[[0,2.12,10],[1,2.1,40.37],[2,1.74,17.32]],"ltp":2.18,"tv":292.4,"id":26354927}]}]}
{"op":"mcm","clk":"11793190064","pt":1723065157736,"mc":[{"id":"1.231502182","rc":[{"batb":[[0,2.1,40.37],[1,1.74,17.32],[2,1.7,10]],"ltp":2.18,"tv":292.4,"id":26354927}]}]}
{"op":"mcm","clk":"11793190166","pt":1723065160866,"mc":[{"id":"1.231502182","rc":[{"batb":[[0,2.12,10],[1,2.1,40.37],[2,1.74,17.32]],"ltp":2.18,"tv":292.4,"id":26354927}]}]}
{"op":"mcm","clk":"11793190274","pt":1723065164050,"mc":[{"id":"1.231502182","rc":[{"batb":[[0,2.1,40.37],[1,1.74,17.32],[2,1.7,10]],"ltp":2.18,"tv":292.4,"id":26354927}]}]}
{"op":"mcm","clk":"11793190390","pt":1723065167386,"mc":[{"id":"1.231502182","rc":[{"batb":[[0,2.12,10],[1,2.1,40.37],[2,1.74,17.32]],"ltp":2.18,"tv":292.4,"id":26354927}]}]}
{"op":"mcm","clk":"11793190521","pt":1723065170673,"mc":[{"id":"1.231502182","rc":[{"batb":[[0,2.1,40.37],[1,1.74,17.32],[2,1.7,10]],"ltp":2.18,"tv":292.4,"id":26354927}]}]}
{"op":"mcm","clk":"11793190613","pt":1723065173287,"mc":[{"id":"1.231502182","rc":[{"batb":[[0,2.12,10],[1,2.1,40.37],[2,1.74,17.32]],"ltp":2.18,"tv":292.4,"id":26354927}]}]}
{"op":"mcm","clk":"11793190724","pt":1723065176565,"mc":[{"id":"1.231502182","rc":[{"batb":[[0,2.1,40.37],[1,1.74,17.32],[2,1.7,10]],"ltp":2.18,"tv":292.4,"id":26354927}]}]}
{"op":"mcm","clk":"11793190816","pt":1723065178872,"mc":[{"id":"1.231502182","rc":[{"batb":[[0,2.12,10],[1,2.1,40.37],[2,1.74,17.32]],"ltp":2.18,"tv":292.4,"id":26354927}]}]}
{"op":"mcm","clk":"11793190949","pt":1723065182311,"mc":[{"id":"1.231502182","rc":[{"batb":[[0,2.1,40.37],[1,1.74,17.32],[2,1.7,10]],"ltp":2.18,"tv":292.4,"id":26354927}]}]}
{"op":"mcm","clk":"11793191039","pt":1723065184571,"mc":[{"id":"1.231502182","rc":[{"batb":[[0,2.12,10],[1,2.1,40.37],[2,1.74,17.32]],"ltp":2.18,"tv":292.4,"id":26354927}]}]}
{"op":"mcm","clk":"11793191159","pt":1723065187996,"mc":[{"id":"1.231502182","rc":[{"batb":[[0,2.1,40.37],[1,1.74,17.32],[2,1.7,10]],"ltp":2.18,"tv":292.4,"id":26354927}]}]}
{"op":"mcm","clk":"11793191248","pt":1723065190612,"mc":[{"id":"1.231502182","rc":[{"batb":[[0,2.12,10],[1,2.1,40.37],[2,1.74,17.32]],"ltp":2.18,"tv":292.4,"id":26354927}]}]}
{"op":"mcm","clk":"11793191398","pt":1723065193904,"mc":[{"id":"1.231502182","rc":[{"batb":[[0,2.1,40.37],[1,1.74,17.32],[2,1.7,10]],"ltp":2.18,"tv":292.4,"id":26354927}]}]}
{"op":"mcm","clk":"11793191472","pt":1723065196319,"mc":[{"id":"1.231502182","rc":[{"batb":[[0,2.12,10],[1,2.1,40.37],[2,1.74,17.32]],"ltp":2.18,"tv":292.4,"id":26354927}]}]}
{"op":"mcm","clk":"11793191562","pt":1723065199906,"mc":[{"id":"1.231502182","rc":[{"batb":[[0,2.1,40.37],[1,1.74,17.32],[2,1.7,10]],"ltp":2.18,"tv":292.4,"id":26354927}]}]}
{"op":"mcm","clk":"11793191720","pt":1723065204531,"mc":[{"id":"1.231502182","rc":[{"batb":[[0,2.12,10],[1,2.1,40.37],[2,1.74,17.32]],"ltp":2.18,"tv":292.4,"id":26354927}]}]}
{"op":"mcm","clk":"11793191835","pt":1723065208032,"mc":[{"id":"1.231502182","rc":[{"batb":[[0,2.1,40.37],[1,1.74,17.32],[2,1.7,10]],"ltp":2.18,"tv":292.4,"id":26354927}]}]}
{"op":"mcm","clk":"11793191904","pt":1723065210194,"mc":[{"id":"1.231502182","rc":[{"batb":[[0,2.12,10],[1,2.1,40.37],[2,1.74,17.32]],"ltp":2.18,"tv":292.4,"id":26354927}]}]}
{"op":"mcm","clk":"11793192031","pt":1723065213730,"mc":[{"id":"1.231502182","rc":[{"batb":[[0,2.1,40.37],[1,1.74,17.32],[2,1.7,10]],"ltp":2.18,"tv":292.4,"id":26354927}]}]}
{"op":"mcm","clk":"11793192120","pt":1723065216497,"mc":[{"id":"1.231502182","rc":[{"batb":[[0,2.12,10],[1,2.1,40.37],[2,1.74,17.32]],"ltp":2.18,"tv":292.4,"id":26354927},{"trd":[[1.81,6.08]],"batb":[[0,1.8,55],[1,1.79,56.21],[2,1.78,800]],"batl":[[0,1.84,7.78]],"ltp":1.81,"tv":638.11,"id":26354924}],"tv":930.52}]}
{"op":"mcm","clk":"11793192228","pt":1723065219832,"mc":[{"id":"1.231502182","rc":[{"batb":[[0,2.1,40.37],[1,1.74,17.32],[2,1.7,10]],"ltp":2.18,"tv":292.4,"id":26354927}]}]}
{"op":"mcm","clk":"11793192317","pt":1723065223220,"mc":[{"id":"1.231502182","rc":[{"batb":[[0,2.12,10],[1,2.1,40.37],[2,1.74,17.32]],"ltp":2.18,"tv":292.4,"id":26354927}]}]}
{"op":"mcm","clk":"11793192420","pt":1723065227047,"mc":[{"id":"1.231502182","rc":[{"batb":[[0,2.1,40.37],[1,1.74,17.32],[2,1.7,10]],"ltp":2.18,"tv":292.4,"id":26354927}]}]}
{"op":"mcm","clk":"11793192572","pt":1723065232147,"mc":[{"id":"1.231502182","rc":[{"batb":[[0,2.12,10],[1,2.1,40.37],[2,1.74,17.32]],"ltp":2.18,"tv":292.4,"id":26354927}]}]}
{"op":"mcm","clk":"11793192679","pt":1723065235536,"mc":[{"id":"1.231502182","rc":[{"batb":[[0,2.1,40.37],[1,1.74,17.32],[2,1.7,10]],"ltp":2.18,"tv":292.4,"id":26354927}]}]}
{"op":"mcm","clk":"11793192763","pt":1723065238356,"mc":[{"id":"1.231502182","rc":[{"batb":[[0,2.12,10],[1,2.1,40.37],[2,1.74,17.32]],"ltp":2.18,"tv":292.4,"id":26354927}]}]}
{"op":"mcm","clk":"11793192870","pt":1723065241739,"mc":[{"id":"1.231502182","rc":[{"batb":[[0,2.1,40.37],[1,1.74,17.32],[2,1.7,10]],"ltp":2.18,"tv":292.4,"id":26354927}]}]}
{"op":"mcm","clk":"11793192939","pt":1723065244351,"mc":[{"id":"1.231502182","rc":[{"batb":[[0,2.12,10],[1,2.1,40.37],[2,1.74,17.32]],"ltp":2.18,"tv":292.4,"id":26354927}]}]}
{"op":"mcm","clk":"11793193032","pt":1723065247838,"mc":[{"id":"1.231502182","rc":[{"batb":[[0,2.1,40.37],[1,1.74,17.32],[2,1.7,10]],"ltp":2.18,"tv":292.4,"id":26354927}]}]}
{"op":"mcm","clk":"11793193114","pt":1723065250959,"mc":[{"id":"1.231502182","rc":[{"batb":[[0,2.12,10],[1,2.1,40.37],[2,1.74,17.32]],"ltp":2.18,"tv":292.4,"id":26354927}]}]}
{"op":"mcm","clk":"11793193232","pt":1723065254239,"mc":[{"id":"1.231502182","rc":[{"batb":[[0,2.1,40.37],[1,1.74,17.32],[2,1.7,10]],"ltp":2.18,"tv":292.4,"id":26354927}]}]}
{"op":"mcm","clk":"11793193335","pt":1723065257976,"mc":[{"id":"1.231502182","rc":[{"batb":[[0,2.12,10],[1,2.1,40.37],[2,1.74,17.32]],"ltp":2.18,"tv":292.4,"id":26354927}]}]}
{"op":"mcm","clk":"11793193419","pt":1723065261161,"mc":[{"id":"1.231502182","rc":[{"batb":[[0,2.1,40.37],[1,1.74,17.32],[2,1.7,10]],"ltp":2.18,"tv":292.4,"id":26354927}]}]}
{"op":"mcm","clk":"11793193496","pt":1723065263674,"mc":[{"id":"1.231502182","rc":[{"batb":[[0,2.12,10],[1,2.1,40.37],[2,1.74,17.32]],"ltp":2.18,"tv":292.4,"id":26354927}]}]}
{"op":"mcm","clk":"11793193602","pt":1723065267059,"mc":[{"id":"1.231502182","rc":[{"batb":[[0,2.1,40.37],[1,1.74,17.32],[2,1.7,10]],"ltp":2.18,"tv":292.4,"id":26354927}]}]}
{"op":"mcm","clk":"11793193691","pt":1723065269467,"mc":[{"id":"1.231502182","rc":[{"batb":[[0,2.12,10],[1,2.1,40.37],[2,1.74,17.32]],"ltp":2.18,"tv":292.4,"id":26354927}]}]}
{"op":"mcm","clk":"11793193808","pt":1723065272900,"mc":[{"id":"1.231502182","rc":[{"batb":[[0,2.1,40.37],[1,1.74,17.32],[2,1.7,10]],"ltp":2.18,"tv":292.4,"id":26354927}]}]}
{"op":"mcm","clk":"11793193905","pt":1723065275871,"mc":[{"id":"1.231502182","rc":[{"batb":[[0,2.12,10],[1,2.1,40.37],[2,1.74,17.32]],"ltp":2.18,"tv":292.4,"id":26354927}]}]}
{"op":"mcm","clk":"11793194010","pt":1723065279209,"mc":[{"id":"1.231502182","rc":[{"batb":[[0,2.1,40.37],[1,1.74,17.32],[2,1.7,10]],"ltp":2.18,"tv":292.4,"id":26354927}]}]}
{"op":"mcm","clk":"11793194080","pt":1723065281410,"mc":[{"id":"1.231502182","rc":[{"batb":[[0,2.12,10],[1,2.1,40.37],[2,1.74,17.32]],"ltp":2.18,"tv":292.4,"id":26354927}]}]}
{"op":"mcm","clk":"11793194252","pt":1723065284892,"mc":[{"id":"1.231502182","rc":[{"batb":[[0,2.1,40.37],[1,1.74,17.32],[2,1.7,10]],"ltp":2.18,"tv":292.4,"id":26354927}]}]}
{"op":"mcm","clk":"11793194412","pt":1723065289400,"mc":[{"id":"1.231502182","rc":[{"batb":[[0,2.12,10],[1,2.1,40.37],[2,1.74,17.32]],"ltp":2.18,"tv":292.4,"id":26354927}]}]}
{"op":"mcm","clk":"11793194511","pt":1723065292733,"mc":[{"id":"1.231502182","rc":[{"batb":[[0,2.1,40.37],[1,1.74,17.32],[2,1.7,10]],"ltp":2.18,"tv":292.4,"id":26354927}]}]}
{"op":"mcm","clk":"11793194625","pt":1723065295295,"mc":[{"id":"1.231502182","rc":[{"batb":[[0,2.12,10],[1,2.1,40.37],[2,1.74,17.32]],"ltp":2.18,"tv":292.4,"id":26354927}]}]}
{"op":"mcm","clk":"11793194781","pt":1723065298944,"mc":[{"id":"1.231502182","rc":[{"batb":[[0,2.1,40.37],[1,1.74,17.32],[2,1.7,10]],"ltp":2.18,"tv":292.4,"id":26354927}]}]}
{"op":"mcm","clk":"11793194863","pt":1723065301054,"mc":[{"id":"1.231502182","rc":[{"batb":[[0,2.12,10],[1,2.1,40.37],[2,1.74,17.32]],"ltp":2.18,"tv":292.4,"id":26354927}]}]}
{"op":"mcm","clk":"11793194973","pt":1723065304338,"mc":[{"id":"1.231502182","rc":[{"batb":[[0,2.1,40.37],[1,1.74,17.32],[2,1.7,10]],"ltp":2.18,"tv":292.4,"id":26354927}]}]}
{"op":"mcm","clk":"11793195080","pt":1723065307121,"mc":[{"id":"1.231502182","rc":[{"batb":[[0,2.12,10],[1,2.1,40.37],[2,1.74,17.32]],"ltp":2.18,"tv":292.4,"id":26354927}]}]}
{"op":"mcm","clk":"11793195215","pt":1723065310716,"mc":[{"id":"1.231502182","rc":[{"batb":[[0,2.1,40.37],[1,1.74,17.32],[2,1.7,10]],"ltp":2.18,"tv":292.4,"id":26354927}]}]}
{"op":"mcm","clk":"11793195333","pt":1723065314052,"mc":[{"id":"1.231502182","rc":[{"batb":[[0,2.12,10],[1,2.1,40.37],[2,1.74,17.32]],"ltp":2.18,"tv":292.4,"id":26354927}]}]}
{"op":"mcm","clk":"11793195466","pt":1723065317442,"mc":[{"id":"1.231502182","rc":[{"batb":[[0,2.1,40.37],[1,1.74,17.32],[2,1.7,10]],"ltp":2.18,"tv":292.4,"id":26354927}]}]}
{"op":"mcm","clk":"11793195560","pt":1723065320731,"mc":[{"id":"1.231502182","rc":[{"batb":[[0,2.12,10],[1,2.1,40.37],[2,1.74,17.32]],"ltp":2.18,"tv":292.4,"id":26354927}]}]}
{"op":"mcm","clk":"11793195682","pt":1723065323968,"mc":[{"id":"1.231502182","rc":[{"batb":[[0,2.1,40.37],[1,1.74,17.32],[2,1.7,10]],"ltp":2.18,"tv":292.4,"id":26354927}]}]}
{"op":"mcm","clk":"11793195805","pt":1723065326848,"mc":[{"id":"1.231502182","rc":[{"batb":[[0,2.12,10],[1,2.1,40.37],[2,1.74,17.32]],"ltp":2.18,"tv":292.4,"id":26354927}]}]}
{"op":"mcm","clk":"11793195930","pt":1723065330150,"mc":[{"id":"1.231502182","rc":[{"batb":[[0,2.1,40.37],[1,1.74,17.32],[2,1.7,10]],"ltp":2.18,"tv":292.4,"id":26354927}]}]}
{"op":"mcm","clk":"11793196068","pt":1723065333074,"mc":[{"id":"1.231502182","rc":[{"batb":[[0,2.12,10],[1,2.1,40.37],[2,1.74,17.32]],"ltp":2.18,"tv":292.4,"id":26354927}]}]}
{"op":"mcm","clk":"11793196198","pt":1723065336369,"mc":[{"id":"1.231502182","rc":[{"batb":[[0,2.1,40.37],[1,1.74,17.32],[2,1.7,10]],"ltp":2.18,"tv":292.4,"id":26354927}]}]}
{"op":"mcm","clk":"11793196292","pt":1723065338475,"mc":[{"id":"1.231502182","rc":[{"batb":[[0,2.12,10],[1,2.1,40.37],[2,1.74,17.32]],"ltp":2.18,"tv":292.4,"id":26354927}]}]}
{"op":"mcm","clk":"11793196423","pt":1723065341768,"mc":[{"id":"1.231502182","rc":[{"batb":[[0,2.1,40.37],[1,1.74,17.32],[2,1.7,10]],"ltp":2.18,"tv":292.4,"id":26354927}]}]}
{"op":"mcm","clk":"11793196516","pt":1723065344280,"mc":[{"id":"1.231502182","rc":[{"batb":[[0,2.12,10],[1,2.1,40.37],[2,1.74,17.32]],"ltp":2.18,"tv":292.4,"id":26354927}]}]}
{"op":"mcm","clk":"11793196632","pt":1723065347667,"mc":[{"id":"1.231502182","rc":[{"batb":[[0,2.1,40.37],[1,1.74,17.32],[2,1.7,10]],"ltp":2.18,"tv":292.4,"id":26354927}]}]}
{"op":"mcm","clk":"11793196791","pt":1723065352497,"mc":[{"id":"1.231502182","rc":[{"batb":[[0,2.12,10],[1,2.1,40.37],[2,1.74,17.32]],"ltp":2.18,"tv":292.4,"id":26354927}]}]}
{"op":"mcm","clk":"11793196912","pt":1723065355784,"mc":[{"id":"1.231502182","rc":[{"batb":[[0,2.1,40.37],[1,1.74,17.32],[2,1.7,10]],"ltp":2.18,"tv":292.4,"id":26354927}]}]}
{"op":"mcm","clk":"11793197124","pt":1723065360621,"mc":[{"id":"1.231502182","rc":[{"batb":[[0,2.12,10],[1,2.1,40.37],[2,1.74,17.32]],"ltp":2.18,"tv":292.4,"id":26354927}]}]}
{"op":"mcm","clk":"11793197281","pt":1723065364688,"mc":[{"id":"1.231502182","rc":[{"batb":[[0,2.1,40.37],[1,1.74,17.32],[2,1.7,10]],"ltp":2.18,"tv":292.4,"id":26354927}]}]}
{"op":"mcm","clk":"11793197354","pt":1723065366698,"mc":[{"id":"1.231502182","rc":[{"batb":[[0,2.12,10],[1,2.1,40.37],[2,1.74,17.32]],"ltp":2.18,"tv":292.4,"id":26354927}]}]}
{"op":"mcm","clk":"11793197491","pt":1723065370135,"mc":[{"id":"1.231502182","rc":[{"batb":[[0,2.1,40.37],[1,1.74,17.32],[2,1.7,10]],"ltp":2.18,"tv":292.4,"id":26354927}]}]}
{"op":"mcm","clk":"11793197602","pt":1723065372498,"mc":[{"id":"1.231502182","rc":[{"batb":[[0,2.12,10],[1,2.1,40.37],[2,1.74,17.32]],"ltp":2.18,"tv":292.4,"id":26354927}]}]}
{"op":"mcm","clk":"11793197713","pt":1723065375829,"mc":[{"id":"1.231502182","rc":[{"batb":[[0,2.1,40.37],[1,1.74,17.32],[2,1.7,10]],"ltp":2.18,"tv":292.4,"id":26354927}]}]}
{"op":"mcm","clk":"11793197823","pt":1723065378501,"mc":[{"id":"1.231502182","rc":[{"batb":[[0,2.12,10],[1,2.1,40.37],[2,1.74,17.32]],"ltp":2.18,"tv":292.4,"id":26354927}]}]}
{"op":"mcm","clk":"11793197959","pt":1723065381727,"mc":[{"id":"1.231502182","rc":[{"batb":[[0,2.1,40.37],[1,1.74,17.32],[2,1.7,10]],"ltp":2.18,"tv":292.4,"id":26354927}]}]}
{"op":"mcm","clk":"11793198067","pt":1723065384545,"mc":[{"id":"1.231502182","rc":[{"batb":[[0,2.12,10],[1,2.1,40.37],[2,1.74,17.32]],"ltp":2.18,"tv":292.4,"id":26354927}]}]}
{"op":"mcm","clk":"11793198221","pt":1723065387931,"mc":[{"id":"1.231502182","rc":[{"batb":[[0,2.1,40.37],[1,1.74,17.32],[2,1.7,10]],"ltp":2.18,"tv":292.4,"id":26354927}]}]}
{"op":"mcm","clk":"11793198299","pt":1723065390252,"mc":[{"id":"1.231502182","rc":[{"batb":[[0,2.12,10],[1,2.1,40.37],[2,1.74,17.32]],"ltp":2.18,"tv":292.4,"id":26354927}]}]}
{"op":"mcm","clk":"11793198414","pt":1723065393842,"mc":[{"id":"1.231502182","rc":[{"batb":[[0,2.1,40.37],[1,1.74,17.32],[2,1.7,10]],"ltp":2.18,"tv":292.4,"id":26354927}]}]}
{"op":"mcm","clk":"11793198535","pt":1723065396461,"mc":[{"id":"1.231502182","rc":[{"batb":[[0,2.12,10],[1,2.1,40.37],[2,1.74,17.32]],"ltp":2.18,"tv":292.4,"id":26354927}]}]}
{"op":"mcm","clk":"11793198651","pt":1723065399846,"mc":[{"id":"1.231502182","rc":[{"batb":[[0,2.1,40.37],[1,1.74,17.32],[2,1.7,10]],"ltp":2.18,"tv":292.4,"id":26354927}]}]}
{"op":"mcm","clk":"11793198732","pt":1723065402072,"mc":[{"id":"1.231502182","rc":[{"batb":[[0,2.12,10],[1,2.1,40.37],[2,1.74,17.32]],"ltp":2.18,"tv":292.4,"id":26354927}]}]}
{"op":"mcm","clk":"11793198857","pt":1723065405545,"mc":[{"id":"1.231502182","rc":[{"batb":[[0,2.1,40.37],[1,1.74,17.32],[2,1.7,10]],"ltp":2.18,"tv":292.4,"id":26354927}]}]}
{"op":"mcm","clk":"11793198970","pt":1723065408672,"mc":[{"id":"1.231502182","rc":[{"batb":[[0,2.12,10],[1,2.1,40.37],[2,1.74,17.32]],"ltp":2.18,"tv":292.4,"id":26354927}]}]}
{"op":"mcm","clk":"11793199083","pt":1723065412070,"mc":[{"id":"1.231502182","rc":[{"batb":[[0,2.1,40.37],[1,1.74,17.32],[2,1.7,10]],"ltp":2.18,"tv":292.4,"id":26354927}]}]}
{"op":"mcm","clk":"11793199199","pt":1723065414587,"mc":[{"id":"1.231502182","rc":[{"batb":[[0,2.12,10],[1,2.1,40.37],[2,1.74,17.32]],"ltp":2.18,"tv":292.4,"id":26354927}]}]}
{"op":"mcm","clk":"11793199361","pt":1723065418084,"mc":[{"id":"1.231502182","rc":[{"batb":[[0,2.1,40.37],[1,1.74,17.32],[2,1.7,10]],"ltp":2.18,"tv":292.4,"id":26354927}]}]}
{"op":"mcm","clk":"11793199643","pt":1723065424190,"mc":[{"id":"1.231502182","rc":[{"batb":[[0,2.12,10],[1,2.1,40.37],[2,1.74,17.32]],"ltp":2.18,"tv":292.4,"id":26354927}]}]}
{"op":"mcm","clk":"11793199795","pt":1723065427680,"mc":[{"id":"1.231502182","rc":[{"batb":[[0,2.1,40.37],[1,1.74,17.32],[2,1.7,10]],"ltp":2.18,"tv":292.4,"id":26354927}]}]}
{"op":"mcm","clk":"11793199996","pt":1723065432401,"mc":[{"id":"1.231502182","rc":[{"batb":[[0,2.12,10],[1,2.1,40.37],[2,1.74,17.32]],"ltp":2.18,"tv":292.4,"id":26354927}]}]}
{"op":"mcm","clk":"11793200135","pt":1723065435784,"mc":[{"id":"1.231502182","rc":[{"batb":[[0,2.1,40.37],[1,1.74,17.32],[2,1.7,10]],"ltp":2.18,"tv":292.4,"id":26354927}]}]}
{"op":"mcm","clk":"11793200220","pt":1723065438393,"mc":[{"id":"1.231502182","rc":[{"batb":[[0,2.12,10],[1,2.1,40.37],[2,1.74,17.32]],"ltp":2.18,"tv":292.4,"id":26354927}]}]}
{"op":"mcm","clk":"11793200372","pt":1723065441727,"mc":[{"id":"1.231502182","rc":[{"batb":[[0,2.1,40.37],[1,1.74,17.32],[2,1.7,10]],"ltp":2.18,"tv":292.4,"id":26354927}]}]}
{"op":"mcm","clk":"11793200465","pt":1723065444138,"mc":[{"id":"1.231502182","rc":[{"batb":[[0,2.12,10],[1,2.1,40.37],[2,1.74,17.32]],"ltp":2.18,"tv":292.4,"id":26354927}]}]}
{"op":"mcm","clk":"11793200602","pt":1723065447635,"mc":[{"id":"1.231502182","rc":[{"batb":[[0,2.1,40.37],[1,1.74,17.32],[2,1.7,10]],"ltp":2.18,"tv":292.4,"id":26354927}]}]}
{"op":"mcm","clk":"11793200714","pt":1723065450104,"mc":[{"id":"1.231502182","rc":[{"batb":[[0,2.12,10],[1,2.1,40.37],[2,1.74,17.32]],"ltp":2.18,"tv":292.4,"id":26354927}]}]}
{"op":"mcm","clk":"11793200880","pt":1723065453644,"mc":[{"id":"1.231502182","rc":[{"batb":[[0,2.1,40.37],[1,1.74,17.32],[2,1.7,10]],"ltp":2.18,"tv":292.4,"id":26354927}]}]}
{"op":"mcm","clk":"11793201000","pt":1723065456425,"mc":[{"id":"1.231502182","rc":[{"batb":[[0,2.12,10],[1,2.1,40.37],[2,1.74,17.32]],"ltp":2.18,"tv":292.4,"id":26354927}]}]}
{"op":"mcm","clk":"11793201132","pt":1723065459712,"mc":[{"id":"1.231502182","rc":[{"batb":[[0,2.1,40.37],[1,1.74,17.32],[2,1.7,10]],"ltp":2.18,"tv":292.4,"id":26354927}]}]}
{"op":"mcm","clk":"11793201251","pt":1723065462435,"mc":[{"id":"1.231502182","rc":[{"batb":[[0,2.12,10],[1,2.1,40.37],[2,1.74,17.32]],"ltp":2.18,"tv":292.4,"id":26354927}]}]}
{"op":"mcm","clk":"11793201387","pt":1723065465723,"mc":[{"id":"1.231502182","rc":[{"batb":[[0,2.1,40.37],[1,1.74,17.32],[2,1.7,10]],"ltp":2.18,"tv":292.4,"id":26354927}]}]}
{"op":"mcm","clk":"11793201497","pt":1723065468238,"mc":[{"id":"1.231502182","rc":[{"batb":[[0,2.12,10],[1,2.1,40.37],[2,1.74,17.32]],"ltp":2.18,"tv":292.4,"id":26354927}]}]}
{"op":"mcm","clk":"11793201650","pt":1723065471834,"mc":[{"id":"1.231502182","rc":[{"batb":[[0,2.1,40.37],[1,1.74,17.32],[2,1.7,10]],"ltp":2.18,"tv":292.4,"id":26354927}]}]}
{"op":"mcm","clk":"11793201764","pt":1723065474460,"mc":[{"id":"1.231502182","rc":[{"batb":[[0,2.12,10],[1,2.1,40.37],[2,1.74,17.32]],"ltp":2.18,"tv":292.4,"id":26354927}]}]}
{"op":"mcm","clk":"11793201886","pt":1723065477846,"mc":[{"id":"1.231502182","rc":[{"batb":[[0,2.1,40.37],[1,1.74,17.32],[2,1.7,10]],"ltp":2.18,"tv":292.4,"id":26354927}]}]}
{"op":"mcm","clk":"11793201993","pt":1723065480262,"mc":[{"id":"1.231502182","rc":[{"batb":[[0,2.12,10],[1,2.1,40.37],[2,1.74,17.32]],"ltp":2.18,"tv":292.4,"id":26354927}]}]}
{"op":"mcm","clk":"11793202121","pt":1723065483755,"mc":[{"id":"1.231502182","rc":[{"batb":[[0,2.1,40.37],[1,1.74,17.32],[2,1.7,10]],"ltp":2.18,"tv":292.4,"id":26354927}]}]}
{"op":"mcm","clk":"11793202238","pt":1723065486478,"mc":[{"id":"1.231502182","rc":[{"batb":[[0,2.12,10],[1,2.1,40.37],[2,1.74,17.32]],"ltp":2.18,"tv":292.4,"id":26354927}]}]}
{"op":"mcm","clk":"11793202382","pt":1723065489646,"mc":[{"id":"1.231502182","rc":[{"batb":[[0,2.1,40.37],[1,1.74,17.32],[2,1.7,10]],"ltp":2.18,"tv":292.4,"id":26354927}]}]}
{"op":"mcm","clk":"11793202585","pt":1723065494780,"mc":[{"id":"1.231502182","rc":[{"batb":[[0,2.12,10],[1,2.1,40.37],[2,1.74,17.32]],"ltp":2.18,"tv":292.4,"id":26354927}]}]}
{"op":"mcm","clk":"11793202690","pt":1723065497087,"mc":[{"id":"1.231502182","rc":[{"batb":[[1,1.79,315.88]],"ltp":1.81,"tv":638.11,"id":26354924}]}]}
{"op":"mcm","clk":"11793202736","pt":1723065498067,"mc":[{"id":"1.231502182","rc":[{"batb":[[0,2.1,40.37],[1,1.74,17.32],[2,1.7,10]],"ltp":2.18,"tv":292.4,"id":26354927}]}]}
{"op":"mcm","clk":"11793202830","pt":1723065500475,"mc":[{"id":"1.231502182","rc":[{"batb":[[0,2.12,10],[1,2.1,40.37],[2,1.74,17.32]],"ltp":2.18,"tv":292.4,"id":26354927}]}]}
{"op":"mcm","clk":"11793202881","pt":1723065501754,"mc":[{"id":"1.231502182","rc":[{"batb":[[0,1.8,314.67]],"ltp":1.81,"tv":638.11,"id":26354924}]}]}
{"op":"mcm","clk":"11793202962","pt":1723065503857,"mc":[{"id":"1.231502182","rc":[{"batb":[[0,2.1,40.37],[1,1.74,17.32],[2,1.7,10]],"ltp":2.18,"tv":292.4,"id":26354927}]}]}
{"op":"mcm","clk":"11793203096","pt":1723065506890,"mc":[{"id":"1.231502182","rc":[{"batb":[[0,2.12,10],[1,2.1,40.37],[2,1.74,17.32]],"ltp":2.18,"tv":292.4,"id":26354927},{"trd":[[1.81,8]],"batb":[[0,1.81,258.71],[1,1.8,314.67],[2,1.79,315.88]],"batl":[[0,1.84,6.82]],"ltp":1.81,"tv":640.03,"id":26354924}],"tv":932.44}]}
{"op":"mcm","clk":"11793203227","pt":1723065510080,"mc":[{"id":"1.231502182","rc":[{"batb":[[0,2.1,40.37],[1,1.74,17.32],[2,1.7,10]],"ltp":2.18,"tv":292.4,"id":26354927}]}]}
{"op":"mcm","clk":"11793203404","pt":1723065513569,"mc":[{"id":"1.231502182","rc":[{"batb":[[0,2.12,10],[1,2.1,40.37],[2,1.74,17.32]],"ltp":2.18,"tv":292.4,"id":26354927}]}]}
{"op":"mcm","clk":"11793203583","pt":1723065517003,"mc":[{"id":"1.231502182","rc":[{"batb":[[0,2.1,40.37],[1,1.74,17.32],[2,1.7,10]],"ltp":2.18,"tv":292.4,"id":26354927},{"batb":[[0,1.8,314.67],[1,1.79,315.88],[2,1.78,800]],"ltp":1.81,"tv":640.03,"id":26354924}]}]}
{"op":"mcm","clk":"11793203686","pt":1723065519470,"mc":[{"id":"1.231502182","rc":[{"batb":[[0,2.12,10],[1,2.1,40.37],[2,1.74,17.32]],"ltp":2.18,"tv":292.4,"id":26354927}]}]}
{"op":"mcm","clk":"11793203810","pt":1723065522798,"mc":[{"id":"1.231502182","rc":[{"batb":[[0,2.1,40.37],[1,1.74,17.32],[2,1.7,10]],"ltp":2.18,"tv":292.4,"id":26354927}]}]}
{"op":"mcm","clk":"11793203902","pt":1723065525411,"mc":[{"id":"1.231502182","rc":[{"batb":[[0,2.12,10],[1,2.1,40.37],[2,1.74,17.32]],"ltp":2.18,"tv":292.4,"id":26354927}]}]}
{"op":"mcm","clk":"11793203937","pt":1723065526077,"mc":[{"id":"1.231502182","rc":[{"batb":[[0,1.81,259.67],[1,1.8,314.67],[2,1.79,315.88]],"ltp":1.81,"tv":640.03,"id":26354924}]}]}
{"op":"mcm","clk":"11793204056","pt":1723065528790,"mc":[{"id":"1.231502182","rc":[{"batb":[[0,2.1,40.37],[1,1.74,17.32],[2,1.7,10]],"ltp":2.18,"tv":292.4,"id":26354927}]}]}
{"op":"mcm","clk":"11793204216","pt":1723065531714,"mc":[{"id":"1.231502182","rc":[{"batb":[[0,2.12,10],[1,2.1,40.37],[2,1.74,17.32]],"ltp":2.18,"tv":292.4,"id":26354927}]}]}
{"op":"mcm","clk":"11793204349","pt":1723065534995,"mc":[{"id":"1.231502182","rc":[{"batb":[[0,2.1,40.37],[1,1.74,17.32],[2,1.7,10]],"ltp":2.18,"tv":292.4,"id":26354927}]}]}
{"op":"mcm","clk":"11793204424","pt":1723065537400,"mc":[{"id":"1.231502182","rc":[{"batb":[[0,2.12,10],[1,2.1,40.37],[2,1.74,17.32]],"ltp":2.18,"tv":292.4,"id":26354927}]}]}
{"op":"mcm","clk":"11793204565","pt":1723065540993,"mc":[{"id":"1.231502182","rc":[{"batb":[[0,2.1,40.37],[1,1.74,17.32],[2,1.7,10]],"ltp":2.18,"tv":292.4,"id":26354927}]}]}
{"op":"mcm","clk":"11793204664","pt":1723065543713,"mc":[{"id":"1.231502182","rc":[{"batb":[[0,2.12,10],[1,2.1,40.37],[2,1.74,17.32]],"ltp":2.18,"tv":292.4,"id":26354927}]}]}
{"op":"mcm","clk":"11793204804","pt":1723065547105,"mc":[{"id":"1.231502182","rc":[{"batb":[[0,2.1,40.37],[1,1.74,17.32],[2,1.7,10]],"ltp":2.18,"tv":292.4,"id":26354927}]}]}
{"op":"mcm","clk":"11793204892","pt":1723065549509,"mc":[{"id":"1.231502182","rc":[{"batb":[[0,2.12,10],[1,2.1,40.37],[2,1.74,17.32]],"ltp":2.18,"tv":292.4,"id":26354927}]}]}
{"op":"mcm","clk":"11793205003","pt":1723065552946,"mc":[{"id":"1.231502182","rc":[{"batb":[[0,2.1,40.37],[1,1.74,17.32],[2,1.7,10]],"ltp":2.18,"tv":292.4,"id":26354927}]}]}
{"op":"mcm","clk":"11793205054","pt":1723065555143,"mc":[{"id":"1.231502182","rc":[{"batb":[[0,2.12,10],[1,2.1,40.37],[2,1.74,17.32]],"ltp":2.18,"tv":292.4,"id":26354927}]}]}
{"op":"mcm","clk":"11793205201","pt":1723065558425,"mc":[{"id":"1.231502182","rc":[{"batb":[[0,2.1,40.37],[1,1.74,17.32],[2,1.7,10]],"ltp":2.18,"tv":292.4,"id":26354927}]}]}
{"op":"mcm","clk":"11793205295","pt":1723065562060,"mc":[{"id":"1.231502182","rc":[{"batb":[[0,2.12,10],[1,2.1,40.37],[2,1.74,17.32]],"ltp":2.18,"tv":292.4,"id":26354927}]}]}
{"op":"mcm","clk":"11793205421","pt":1723065565440,"mc":[{"id":"1.231502182","rc":[{"batb":[[0,2.1,40.37],[1,1.74,17.32],[2,1.7,10]],"ltp":2.18,"tv":292.4,"id":26354927}]}]}
{"op":"mcm","clk":"11793205546","pt":1723065568523,"mc":[{"id":"1.231502182","rc":[{"batb":[[0,2.12,10],[1,2.1,40.37],[2,1.74,17.32]],"ltp":2.18,"tv":292.4,"id":26354927}]}]}
{"op":"mcm","clk":"11793205674","pt":1723065571956,"mc":[{"id":"1.231502182","rc":[{"batb":[[0,2.1,40.37],[1,1.74,17.32],[2,1.7,10]],"ltp":2.18,"tv":292.4,"id":26354927}]}]}
{"op":"mcm","clk":"11793205866","pt":1723065577855,"mc":[{"id":"1.231502182","rc":[{"batb":[[0,2.12,10],[1,2.1,40.37],[2,1.74,17.32]],"ltp":2.18,"tv":292.4,"id":26354927}]}]}
{"op":"mcm","clk":"11793205968","pt":1723065581132,"mc":[{"id":"1.231502182","rc":[{"batb":[[0,2.1,40.37],[1,1.74,17.32],[2,1.7,10]],"ltp":2.18,"tv":292.4,"id":26354927}]}]}
{"op":"mcm","clk":"11793206060","pt":1723065583861,"mc":[{"id":"1.231502182","rc":[{"batb":[[0,2.12,10],[1,2.1,40.37],[2,1.74,17.32]],"ltp":2.18,"tv":292.4,"id":26354927}]}]}
{"op":"mcm","clk":"11793206210","pt":1723065587650,"mc":[{"id":"1.231502182","rc":[{"batb":[[0,2.1,40.37],[1,1.74,17.32],[2,1.7,10]],"ltp":2.18,"tv":292.4,"id":26354927},{"batb":[[0,1.82,5],[1,1.81,259.67],[2,1.8,309.67]],"ltp":1.81,"tv":640.03,"id":26354924}]}]}
{"op":"mcm","clk":"11793206304","pt":1723065590574,"mc":[{"id":"1.231502182","rc":[{"batb":[[0,2.12,10],[1,2.1,40.37],[2,1.74,17.32]],"ltp":2.18,"tv":292.4,"id":26354927}]}]}
{"op":"mcm","clk":"11793206418","pt":1723065593852,"mc":[{"id":"1.231502182","rc":[{"batb":[[0,2.1,40.37],[1,1.74,17.32],[2,1.7,10]],"ltp":2.18,"tv":292.4,"id":26354927}]}]}
{"op":"mcm","clk":"11793206544","pt":1723065597192,"mc":[{"id":"1.231502182","rc":[{"batb":[[0,2.12,10],[1,2.1,40.37],[2,1.74,17.32]],"ltp":2.18,"tv":292.4,"id":26354927}]}]}
{"op":"mcm","clk":"11793206669","pt":1723065600474,"mc":[{"id":"1.231502182","rc":[{"batb":[[0,2.1,40.37],[1,1.74,17.32],[2,1.7,10]],"ltp":2.18,"tv":292.4,"id":26354927}]}]}
{"op":"mcm","clk":"11793206825","pt":1723065604274,"mc":[{"id":"1.231502182","rc":[{"batb":[[0,2.12,10],[1,2.1,40.37],[2,1.74,17.32]],"ltp":2.18,"tv":292.4,"id":26354927}]}]}
{"op":"mcm","clk":"11793206957","pt":1723065607563,"mc":[{"id":"1.231502182","rc":[{"batb":[[0,2.1,40.37],[1,1.74,17.32],[2,1.7,10]],"ltp":2.18,"tv":292.4,"id":26354927}]}]}
{"op":"mcm","clk":"11793207071","pt":1723065610287,"mc":[{"id":"1.231502182","rc":[{"batb":[[0,2.12,10],[1,2.1,40.37],[2,1.74,17.32]],"ltp":2.18,"tv":292.4,"id":26354927}]}]}
{"op":"mcm","clk":"11793207186","pt":1723065613481,"mc":[{"id":"1.231502182","rc":[{"batb":[[0,2.1,40.37],[1,1.74,17.32],[2,1.7,10]],"ltp":2.18,"tv":292.4,"id":26354927}]}]}
{"op":"mcm","clk":"11793207311","pt":1723065616922,"mc":[{"id":"1.231502182","rc":[{"batb":[[0,2.12,10],[1,2.1,40.37],[2,1.74,17.32]],"ltp":2.18,"tv":292.4,"id":26354927}]}]}
{"op":"mcm","clk":"11793207421","pt":1723065620101,"mc":[{"id":"1.231502182","rc":[{"batb":[[0,2.1,40.37],[1,1.74,17.32],[2,1.7,10]],"ltp":2.18,"tv":292.4,"id":26354927}]}]}
{"op":"mcm","clk":"11793207579","pt":1723065624607,"mc":[{"id":"1.231502182","rc":[{"batb":[[0,2.12,10],[1,2.1,40.37],[2,1.74,17.32]],"ltp":2.18,"tv":292.4,"id":26354927}]}]}
{"op":"mcm","clk":"11793207694","pt":1723065627942,"mc":[{"id":"1.231502182","rc":[{"batb":[[0,2.1,40.37],[1,1.74,17.32],[2,1.7,10]],"ltp":2.18,"tv":292.4,"id":26354927}]}]}
{"op":"mcm","clk":"11793207840","pt":1723065631839,"mc":[{"id":"1.231502182","rc":[{"batb":[[0,2.12,10],[1,2.1,40.37],[2,1.74,17.32]],"ltp":2.18,"tv":292.4,"id":26354927}]}]}
{"op":"mcm","clk":"11793207949","pt":1723065635143,"mc":[{"id":"1.231502182","rc":[{"batb":[[0,2.1,40.37],[1,1.74,17.32],[2,1.7,10]],"ltp":2.18,"tv":292.4,"id":26354927}]}]}
{"op":"mcm","clk":"11793208067","pt":1723065638832,"mc":[{"id":"1.231502182","rc":[{"batb":[[0,2.12,10],[1,2.1,40.37],[2,1.74,17.32]],"ltp":2.18,"tv":292.4,"id":26354927}]}]}
{"op":"mcm","clk":"11793208201","pt":1723065642121,"mc":[{"id":"1.231502182","rc":[{"batb":[[0,2.1,40.37],[1,1.74,17.32],[2,1.7,10]],"ltp":2.18,"tv":292.4,"id":26354927}]}]}
{"op":"mcm","clk":"11793208283","pt":1723065644837,"mc":[{"id":"1.231502182","rc":[{"batb":[[0,2.12,10],[1,2.1,40.37],[2,1.74,17.32]],"ltp":2.18,"tv":292.4,"id":26354927}]}]}
{"op":"mcm","clk":"11793208396","pt":1723065648123,"mc":[{"id":"1.231502182","rc":[{"batb":[[0,2.1,40.37],[1,1.74,17.32],[2,1.7,10]],"ltp":2.18,"tv":292.4,"id":26354927}]}]}
{"op":"mcm","clk":"11793208486","pt":1723065651038,"mc":[{"id":"1.231502182","rc":[{"batb":[[0,2.12,10],[1,2.1,40.37],[2,1.74,17.32]],"ltp":2.18,"tv":292.4,"id":26354927}]}]}
{"op":"mcm","clk":"11793208591","pt":1723065654575,"mc":[{"id":"1.231502182","rc":[{"batb":[[0,2.1,40.37],[1,1.74,17.32],[2,1.7,10]],"ltp":2.18,"tv":292.4,"id":26354927}]}]}
{"op":"mcm","clk":"11793208703","pt":1723065657859,"mc":[{"id":"1.231502182","rc":[{"batb":[[0,2.12,10],[1,2.1,40.37],[2,1.74,17.32]],"ltp":2.18,"tv":292.4,"id":26354927}]}]}
{"op":"mcm","clk":"11793208824","pt":1723065661347,"mc":[{"id":"1.231502182","rc":[{"batb":[[0,2.1,40.37],[1,1.74,17.32],[2,1.7,10]],"ltp":2.18,"tv":292.4,"id":26354927}]}]}
{"op":"mcm","clk":"11793208915","pt":1723065664271,"mc":[{"id":"1.231502182","rc":[{"batb":[[0,2.12,10],[1,2.1,40.37],[2,1.74,17.32]],"ltp":2.18,"tv":292.4,"id":26354927}]}]}
{"op":"mcm","clk":"11793209035","pt":1723065667548,"mc":[{"id":"1.231502182","rc":[{"batb":[[0,2.1,40.37],[1,1.74,17.32],[2,1.7,10]],"ltp":2.18,"tv":292.4,"id":26354927}]}]}
{"op":"mcm","clk":"11793209121","pt":1723065670265,"mc":[{"id":"1.231502182","rc":[{"batb":[[0,2.12,10],[1,2.1,40.37],[2,1.74,17.32]],"ltp":2.18,"tv":292.4,"id":26354927}]}]}
{"op":"mcm","clk":"11793209220","pt":1723065673651,"mc":[{"id":"1.231502182","rc":[{"batb":[[0,2.1,40.37],[1,1.74,17.32],[2,1.7,10]],"ltp":2.18,"tv":292.4,"id":26354927}]}]}
{"op":"mcm","clk":"11793209349","pt":1723065677655,"mc":[{"id":"1.231502182","rc":[{"batb":[[0,2.12,10],[1,2.1,40.37],[2,1.74,17.32]],"ltp":2.18,"tv":292.4,"id":26354927}]}]}
{"op":"mcm","clk":"11793209463","pt":1723065681196,"mc":[{"id":"1.231502182","rc":[{"batb":[[0,2.1,40.37],[1,1.74,17.32],[2,1.7,10]],"ltp":2.18,"tv":292.4,"id":26354927}]}]}
{"op":"mcm","clk":"11793209533","pt":1723065683552,"mc":[{"id":"1.231502182","rc":[{"batb":[[0,2.12,10],[1,2.1,40.37],[2,1.74,17.32]],"ltp":2.18,"tv":292.4,"id":26354927}]}]}
{"op":"mcm","clk":"11793209641","pt":1723065687196,"mc":[{"id":"1.231502182","rc":[{"batb":[[0,2.1,40.37],[1,1.74,17.32],[2,1.7,10]],"ltp":2.18,"tv":292.4,"id":26354927}]}]}
{"op":"mcm","clk":"11793209737","pt":1723065689511,"mc":[{"id":"1.231502182","rc":[{"batb":[[0,2.12,10],[1,2.1,40.37],[2,1.74,17.32]],"ltp":2.18,"tv":292.4,"id":26354927}]}]}
{"op":"mcm","clk":"11793209866","pt":1723065692892,"mc":[{"id":"1.231502182","rc":[{"batb":[[0,2.1,40.37],[1,1.74,17.32],[2,1.7,10]],"ltp":2.18,"tv":292.4,"id":26354927}]}]}
{"op":"mcm","clk":"11793209996","pt":1723065696780,"mc":[{"id":"1.231502182","rc":[{"batb":[[0,2.12,10],[1,2.1,40.37],[2,1.74,17.32]],"ltp":2.18,"tv":292.4,"id":26354927}]}]}
{"op":"mcm","clk":"11793210100","pt":1723065700108,"mc":[{"id":"1.231502182","rc":[{"batb":[[0,2.1,40.37],[1,1.74,17.32],[2,1.7,10]],"ltp":2.18,"tv":292.4,"id":26354927}]}]}
{"op":"mcm","clk":"11793210181","pt":1723065703026,"mc":[{"id":"1.231502182","rc":[{"batb":[[0,2.12,10],[1,2.1,40.37],[2,1.74,17.32]],"ltp":2.18,"tv":292.4,"id":26354927}]}]}
{"op":"mcm","clk":"11793210290","pt":1723065706304,"mc":[{"id":"1.231502182","rc":[{"batb":[[0,2.1,40.37],[1,1.74,17.32],[2,1.7,10]],"ltp":2.18,"tv":292.4,"id":26354927}]}]}
{"op":"mcm","clk":"11793210395","pt":1723065709447,"mc":[{"id":"1.231502182","rc":[{"batb":[[0,2.12,10],[1,2.1,40.37],[2,1.74,17.32]],"ltp":2.18,"tv":292.4,"id":26354927}]}]}
{"op":"mcm","clk":"11793210490","pt":1723065712817,"mc":[{"id":"1.231502182","rc":[{"batb":[[0,2.1,40.37],[1,1.74,17.32],[2,1.7,10]],"ltp":2.18,"tv":292.4,"id":26354927}]}]}
{"op":"mcm","clk":"11793210600","pt":1723065715732,"mc":[{"id":"1.231502182","rc":[{"batb":[[0,2.12,10],[1,2.1,40.37],[2,1.74,17.32]],"ltp":2.18,"tv":292.4,"id":26354927}]}]}
{"op":"mcm","clk":"11793210733","pt":1723065719119,"mc":[{"id":"1.231502182","rc":[{"batb":[[0,2.1,40.37],[1,1.74,17.32],[2,1.7,10]],"ltp":2.18,"tv":292.4,"id":26354927}]}]}
{"op":"mcm","clk":"11793210911","pt":1723065723598,"mc":[{"id":"1.231502182","rc":[{"batb":[[0,2.12,10],[1,2.1,40.37],[2,1.74,17.32]],"ltp":2.18,"tv":292.4,"id":26354927}]}]}
{"op":"mcm","clk":"11793211023","pt":1723065726935,"mc":[{"id":"1.231502182","rc":[{"batb":[[0,2.1,40.37],[1,1.74,17.32],[2,1.7,10]],"ltp":2.18,"tv":292.4,"id":26354927}]}]}
{"op":"mcm","clk":"11793211108","pt":1723065729548,"mc":[{"id":"1.231502182","rc":[{"batb":[[0,2.12,10],[1,2.1,40.37],[2,1.74,17.32]],"ltp":2.18,"tv":292.4,"id":26354927}]}]}
{"op":"mcm","clk":"11793211219","pt":1723065732939,"mc":[{"id":"1.231502182","rc":[{"batb":[[0,2.1,40.37],[1,1.74,17.32],[2,1.7,10]],"ltp":2.18,"tv":292.4,"id":26354927}]}]}
{"op":"mcm","clk":"11793211348","pt":1723065736837,"mc":[{"id":"1.231502182","rc":[{"batb":[[0,2.12,10],[1,2.1,40.37],[2,1.74,17.32]],"ltp":2.18,"tv":292.4,"id":26354927}]}]}
{"op":"mcm","clk":"11793211446","pt":1723065740332,"mc":[{"id":"1.231502182","rc":[{"batb":[[0,2.1,40.37],[1,1.74,17.32],[2,1.7,10]],"ltp":2.18,"tv":292.4,"id":26354927}]}]}
{"op":"mcm","clk":"11793211558","pt":1723065742964,"mc":[{"id":"1.231502182","rc":[{"batb":[[0,2.12,10],[1,2.1,40.37],[2,1.74,17.32]],"ltp":2.18,"tv":292.4,"id":26354927}]}]}
{"op":"mcm","clk":"11793211695","pt":1723065746646,"mc":[{"id":"1.231502182","rc":[{"batb":[[0,2.1,40.37],[1,1.74,17.32],[2,1.7,10]],"ltp":2.18,"tv":292.4,"id":26354927}]}]}
{"op":"mcm","clk":"11793211806","pt":1723065749977,"mc":[{"id":"1.231502182","rc":[{"batb":[[0,2.12,10],[1,2.1,40.37],[2,1.74,17.32]],"ltp":2.18,"tv":292.4,"id":26354927}]}]}
{"op":"mcm","clk":"11793211901","pt":1723065753367,"mc":[{"id":"1.231502182","rc":[{"batb":[[0,2.1,40.37],[1,1.74,17.32],[2,1.7,10]],"ltp":2.18,"tv":292.4,"id":26354927}]}]}
{"op":"mcm","clk":"11793212061","pt":1723065756762,"mc":[{"id":"1.231502182","rc":[{"batb":[[0,2.12,10],[1,2.1,40.37],[2,1.74,17.32]],"ltp":2.18,"tv":292.4,"id":26354927}]}]}
{"op":"mcm","clk":"11793212231","pt":1723065760255,"mc":[{"id":"1.231502182","rc":[{"batb":[[0,2.1,40.37],[1,1.74,17.32],[2,1.7,10]],"ltp":2.18,"tv":292.4,"id":26354927}]}]}
{"op":"mcm","clk":"11793212326","pt":1723065762871,"mc":[{"id":"1.231502182","rc":[{"batb":[[0,2.12,10],[1,2.1,40.37],[2,1.74,17.32]],"ltp":2.18,"tv":292.4,"id":26354927}]}]}
{"op":"mcm","clk":"11793212442","pt":1723065766108,"mc":[{"id":"1.231502182","rc":[{"batb":[[0,2.1,40.37],[1,1.74,17.32],[2,1.7,10]],"ltp":2.18,"tv":292.4,"id":26354927}]}]}
{"op":"mcm","clk":"11793212544","pt":1723065768879,"mc":[{"id":"1.231502182","rc":[{"batb":[[0,2.12,10],[1,2.1,40.37],[2,1.74,17.32]],"ltp":2.18,"tv":292.4,"id":26354927}]}]}
{"op":"mcm","clk":"11793212649","pt":1723065772057,"mc":[{"id":"1.231502182","rc":[{"batb":[[0,2.1,40.37],[1,1.74,17.32],[2,1.7,10]],"ltp":2.18,"tv":292.4,"id":26354927}]}]}
{"op":"mcm","clk":"11793212742","pt":1723065774623,"mc":[{"id":"1.231502182","rc":[{"batb":[[0,2.12,10],[1,2.1,40.37],[2,1.74,17.32]],"ltp":2.18,"tv":292.4,"id":26354927}]}]}
{"op":"mcm","clk":"11793212885","pt":1723065778783,"mc":[{"id":"1.231502182","rc":[{"batb":[[0,2.1,40.37],[1,1.74,17.32],[2,1.7,10]],"ltp":2.18,"tv":292.4,"id":26354927}]}]}
{"op":"mcm","clk":"11793213008","pt":1723065781811,"mc":[{"id":"1.231502182","rc":[{"batb":[[0,2.12,10],[1,2.1,40.37],[2,1.74,17.32]],"ltp":2.18,"tv":292.4,"id":26354927}]}]}
{"op":"mcm","clk":"11793213136","pt":1723065785302,"mc":[{"id":"1.231502182","rc":[{"batb":[[0,2.1,40.37],[1,1.74,17.32],[2,1.7,10]],"ltp":2.18,"tv":292.4,"id":26354927}]}]}
{"op":"mcm","clk":"11793213230","pt":1723065788110,"mc":[{"id":"1.231502182","rc":[{"batb":[[0,2.12,10],[1,2.1,40.37],[2,1.74,17.32]],"ltp":2.18,"tv":292.4,"id":26354927}]}]}
{"op":"mcm","clk":"11793213330","pt":1723065791395,"mc":[{"id":"1.231502182","rc":[{"batb":[[0,2.1,40.37],[1,1.74,17.32],[2,1.7,10]],"ltp":2.18,"tv":292.4,"id":26354927}]}]}
{"op":"mcm","clk":"11793213433","pt":1723065794223,"mc":[{"id":"1.231502182","rc":[{"batb":[[0,2.12,10],[1,2.1,40.37],[2,1.74,17.32]],"ltp":2.18,"tv":292.4,"id":26354927}]}]}
{"op":"mcm","clk":"11793213568","pt":1723065797509,"mc":[{"id":"1.231502182","rc":[{"batb":[[0,2.1,40.37],[1,1.74,17.32],[2,1.7,10]],"ltp":2.18,"tv":292.4,"id":26354927}]}]}
{"op":"mcm","clk":"11793213607","pt":1723065798890,"mc":[{"id":"1.231502182","rc":[{"batl":[[0,2.22,16.07],[1,2.26,2]],"ltp":2.18,"tv":292.4,"id":26354927}]}]}
{"op":"mcm","clk":"11793213648","pt":1723065800123,"mc":[{"id":"1.231502182","rc":[{"batb":[[0,2.12,10],[1,2.1,40.37],[2,1.74,17.32]],"ltp":2.18,"tv":292.4,"id":26354927}]}]}
{"op":"mcm","clk":"11793213839","pt":1723065804141,"mc":[{"id":"1.231502182","rc":[{"batb":[[0,2.1,40.37],[1,1.74,17.32],[2,1.7,10]],"ltp":2.18,"tv":292.4,"id":26354927}]}]}
{"op":"mcm","clk":"11793213957","pt":1723065806862,"mc":[{"id":"1.231502182","rc":[{"batb":[[0,2.12,10],[1,2.1,40.37],[2,1.74,17.32]],"ltp":2.18,"tv":292.4,"id":26354927}]}]}
{"op":"mcm","clk":"11793214103","pt":1723065810251,"mc":[{"id":"1.231502182","rc":[{"batb":[[0,2.1,40.37],[1,1.74,17.32],[2,1.7,10]],"ltp":2.18,"tv":292.4,"id":26354927}]}]}
{"op":"mcm","clk":"11793214215","pt":1723065812919,"mc":[{"id":"1.231502182","rc":[{"batb":[[0,2.12,10],[1,2.1,40.37],[2,1.74,17.32]],"ltp":2.18,"tv":292.4,"id":26354927}]}]}
{"op":"mcm","clk":"11793214338","pt":1723065816152,"mc":[{"id":"1.231502182","rc":[{"batb":[[0,2.1,40.37],[1,1.74,17.32],[2,1.7,10]],"ltp":2.18,"tv":292.4,"id":26354927}]}]}
{"op":"mcm","clk":"11793214483","pt":1723065819750,"mc":[{"id":"1.231502182","rc":[{"batb":[[0,2.12,10],[1,2.1,40.37],[2,1.74,17.32]],"ltp":2.18,"tv":292.4,"id":26354927}]}]}
{"op":"mcm","clk":"11793214592","pt":1723065823152,"mc":[{"id":"1.231502182","rc":[{"batb":[[0,2.1,40.37],[1,1.74,17.32],[2,1.7,10]],"ltp":2.18,"tv":292.4,"id":26354927}]}]}
{"op":"mcm","clk":"11793214686","pt":1723065825834,"mc":[{"id":"1.231502182","rc":[{"batb":[[0,2.12,10],[1,2.1,40.37],[2,1.74,17.32]],"ltp":2.18,"tv":292.4,"id":26354927}]}]}
{"op":"mcm","clk":"11793214802","pt":1723065829161,"mc":[{"id":"1.231502182","rc":[{"batb":[[0,2.1,40.37],[1,1.74,17.32],[2,1.7,10]],"ltp":2.18,"tv":292.4,"id":26354927}]}]}
{"op":"mcm","clk":"11793214905","pt":1723065831977,"mc":[{"id":"1.231502182","rc":[{"batb":[[0,2.12,10],[1,2.1,40.37],[2,1.74,17.32]],"ltp":2.18,"tv":292.4,"id":26354927}]}]}
{"op":"mcm","clk":"11793215046","pt":1723065835264,"mc":[{"id":"1.231502182","rc":[{"batb":[[0,2.1,40.37],[1,1.74,17.32],[2,1.7,10]],"ltp":2.18,"tv":292.4,"id":26354927}]}]}
{"op":"mcm","clk":"11793215126","pt":1723065837872,"mc":[{"id":"1.231502182","rc":[{"batb":[[0,2.12,10],[1,2.1,40.37],[2,1.74,17.32]],"ltp":2.18,"tv":292.4,"id":26354927}]}]}
{"op":"mcm","clk":"11793215267","pt":1723065841252,"mc":[{"id":"1.231502182","rc":[{"batb":[[0,2.1,40.37],[1,1.74,17.32],[2,1.7,10]],"ltp":2.18,"tv":292.4,"id":26354927}]}]}
{"op":"mcm","clk":"11793215423","pt":1723065844857,"mc":[{"id":"1.231502182","rc":[{"batb":[[0,2.12,10],[1,2.1,40.37],[2,1.74,17.32]],"ltp":2.18,"tv":292.4,"id":26354927}]}]}
{"op":"mcm","clk":"11793215571","pt":1723065848268,"mc":[{"id":"1.231502182","rc":[{"batb":[[0,2.1,40.37],[1,1.74,17.32],[2,1.7,10]],"ltp":2.18,"tv":292.4,"id":26354927}]}]}
{"op":"mcm","clk":"11793215691","pt":1723065851402,"mc":[{"id":"1.231502182","rc":[{"batb":[[0,2.12,10],[1,2.1,40.37],[2,1.74,17.32]],"ltp":2.18,"tv":292.4,"id":26354927}]}]}
{"op":"mcm","clk":"11793215761","pt":1723065853604,"mc":[{"id":"1.231502182","rc":[{"batl":[[0,2.22,31.83]],"ltp":2.18,"tv":292.4,"id":26354927}]}]}
{"op":"mcm","clk":"11793215817","pt":1723065854998,"mc":[{"id":"1.231502182","rc":[{"batb":[[0,2.1,40.37],[1,1.74,17.32],[2,1.7,10]],"ltp":2.18,"tv":292.4,"id":26354927}]}]}
{"op":"mcm","clk":"11793215936","pt":1723065858175,"mc":[{"id":"1.231502182","rc":[{"batb":[[0,2.12,10],[1,2.1,40.37],[2,1.74,17.32]],"ltp":2.18,"tv":292.4,"id":26354927}]}]}
{"op":"mcm","clk":"11793216033","pt":1723065861608,"mc":[{"id":"1.231502182","rc":[{"batb":[[0,2.1,40.37],[1,1.74,17.32],[2,1.7,10]],"ltp":2.18,"tv":292.4,"id":26354927}]}]}
{"op":"mcm","clk":"11793216159","pt":1723065864787,"mc":[{"id":"1.231502182","rc":[{"batb":[[0,2.12,10],[1,2.1,40.37],[2,1.74,17.32]],"ltp":2.18,"tv":292.4,"id":26354927}]}]}
{"op":"mcm","clk":"11793216287","pt":1723065868420,"mc":[{"id":"1.231502182","rc":[{"batb":[[0,2.1,40.37],[1,1.74,17.32],[2,1.7,10]],"ltp":2.18,"tv":292.4,"id":26354927}]}]}
{"op":"mcm","clk":"11793216392","pt":1723065870929,"mc":[{"id":"1.231502182","rc":[{"batb":[[0,2.12,10],[1,2.1,40.37],[2,1.74,17.32]],"ltp":2.18,"tv":292.4,"id":26354927}]}]}
{"op":"mcm","clk":"11793216512","pt":1723065874311,"mc":[{"id":"1.231502182","rc":[{"batb":[[0,2.1,40.37],[1,1.74,17.32],[2,1.7,10]],"ltp":2.18,"tv":292.4,"id":26354927}]}]}
{"op":"mcm","clk":"11793216606","pt":1723065877026,"mc":[{"id":"1.231502182","rc":[{"batb":[[0,2.12,10],[1,2.1,40.37],[2,1.74,17.32]],"ltp":2.18,"tv":292.4,"id":26354927}]}]}
{"op":"mcm","clk":"11793216700","pt":1723065880349,"mc":[{"id":"1.231502182","rc":[{"batb":[[0,2.1,40.37],[1,1.74,17.32],[2,1.7,10]],"ltp":2.18,"tv":292.4,"id":26354927}]}]}
{"op":"mcm","clk":"11793216805","pt":1723065882920,"mc":[{"id":"1.231502182","rc":[{"batb":[[0,2.12,10],[1,2.1,40.37],[2,1.74,17.32]],"ltp":2.18,"tv":292.4,"id":26354927}]}]}
{"op":"mcm","clk":"11793216909","pt":1723065886135,"mc":[{"id":"1.231502182","rc":[{"batb":[[0,2.1,40.37],[1,1.74,17.32],[2,1.7,10]],"ltp":2.18,"tv":292.4,"id":26354927}]}]}
{"op":"mcm","clk":"11793217044","pt":1723065890133,"mc":[{"id":"1.231502182","rc":[{"batb":[[0,2.12,10],[1,2.1,40.37],[2,1.74,17.32]],"ltp":2.18,"tv":292.4,"id":26354927}]}]}
{"op":"mcm","clk":"11793217173","pt":1723065893460,"mc":[{"id":"1.231502182","rc":[{"batb":[[0,2.1,40.37],[1,1.74,17.32],[2,1.7,10]],"ltp":2.18,"tv":292.4,"id":26354927}]}]}
{"op":"mcm","clk":"11793217273","pt":1723065896021,"mc":[{"id":"1.231502182","rc":[{"batb":[[0,2.12,10],[1,2.1,40.37],[2,1.74,17.32]],"ltp":2.18,"tv":292.4,"id":26354927}]}]}
{"op":"mcm","clk":"11793217382","pt":1723065899353,"mc":[{"id":"1.231502182","rc":[{"batb":[[0,2.1,40.37],[1,1.74,17.32],[2,1.7,10]],"ltp":2.18,"tv":292.4,"id":26354927}]}]}
{"op":"mcm","clk":"11793217455","pt":1723065901865,"mc":[{"id":"1.231502182","rc":[{"batb":[[0,2.12,10],[1,2.1,40.37],[2,1.74,17.32]],"ltp":2.18,"tv":292.4,"id":26354927}]}]}
{"op":"mcm","clk":"11793217583","pt":1723065905451,"mc":[{"id":"1.231502182","rc":[{"batb":[[0,2.1,40.37],[1,1.74,17.32],[2,1.7,10]],"ltp":2.18,"tv":292.4,"id":26354927}]}]}
{"op":"mcm","clk":"11793217696","pt":1723065908883,"mc":[{"id":"1.231502182","rc":[{"batb":[[0,2.12,10],[1,2.1,40.37],[2,1.74,17.32]],"ltp":2.18,"tv":292.4,"id":26354927}]}]}
{"op":"mcm","clk":"11793217806","pt":1723065912164,"mc":[{"id":"1.231502182","rc":[{"batb":[[0,2.1,40.37],[1,1.74,17.32],[2,1.7,10]],"ltp":2.18,"tv":292.4,"id":26354927}]}]}
{"op":"mcm","clk":"11793217887","pt":1723065914976,"mc":[{"id":"1.231502182","rc":[{"batb":[[0,2.12,10],[1,2.1,40.37],[2,1.74,17.32]],"ltp":2.18,"tv":292.4,"id":26354927}]}]}
{"op":"mcm","clk":"11793218025","pt":1723065918391,"mc":[{"id":"1.231502182","rc":[{"batb":[[0,2.1,40.37],[1,1.74,17.32],[2,1.7,10]],"ltp":2.18,"tv":292.4,"id":26354927}]}]}
{"op":"mcm","clk":"11793218154","pt":1723065921410,"mc":[{"id":"1.231502182","rc":[{"batb":[[0,2.12,10],[1,2.1,40.37],[2,1.74,17.32]],"ltp":2.18,"tv":292.4,"id":26354927}]}]}
{"op":"mcm","clk":"11793218298","pt":1723065925098,"mc":[{"id":"1.231502182","rc":[{"batb":[[0,2.1,40.37],[1,1.74,17.32],[2,1.7,10]],"ltp":2.18,"tv":292.4,"id":26354927}]}]}
{"op":"mcm","clk":"11793218370","pt":1723065927408,"mc":[{"id":"1.231502182","rc":[{"batb":[[0,2.12,10],[1,2.1,40.37],[2,1.74,17.32]],"ltp":2.18,"tv":292.4,"id":26354927}]}]}
{"op":"mcm","clk":"11793218506","pt":1723065930598,"mc":[{"id":"1.231502182","rc":[{"batb":[[0,2.1,40.37],[1,1.74,17.32],[2,1.7,10]],"ltp":2.18,"tv":292.4,"id":26354927}]}]}
{"op":"mcm","clk":"11793218678","pt":1723065935508,"mc":[{"id":"1.231502182","rc":[{"batb":[[0,2.12,10],[1,2.1,40.37],[2,1.74,17.32]],"ltp":2.18,"tv":292.4,"id":26354927}]}]}
{"op":"mcm","clk":"11793218792","pt":1723065938997,"mc":[{"id":"1.231502182","rc":[{"batb":[[0,2.1,40.37],[1,1.74,17.32],[2,1.7,10]],"ltp":2.18,"tv":292.4,"id":26354927}]}]}
{"op":"mcm","clk":"11793218876","pt":1723065941508,"mc":[{"id":"1.231502182","rc":[{"batb":[[0,2.12,10],[1,2.1,40.37],[2,1.74,17.32]],"ltp":2.18,"tv":292.4,"id":26354927}]}]}
{"op":"mcm","clk":"11793218979","pt":1723065944900,"mc":[{"id":"1.231502182","rc":[{"batb":[[0,2.1,40.37],[1,1.74,17.32],[2,1.7,10]],"ltp":2.18,"tv":292.4,"id":26354927}]}]}
{"op":"mcm","clk":"11793219087","pt":1723065947328,"mc":[{"id":"1.231502182","rc":[{"batb":[[0,2.12,10],[1,2.1,40.37],[2,1.74,17.32]],"ltp":2.18,"tv":292.4,"id":26354927}]}]}
{"op":"mcm","clk":"11793219216","pt":1723065950620,"mc":[{"id":"1.231502182","rc":[{"batb":[[0,2.1,40.37],[1,1.74,17.32],[2,1.7,10]],"ltp":2.18,"tv":292.4,"id":26354927}]}]}
{"op":"mcm","clk":"11793219326","pt":1723065953339,"mc":[{"id":"1.231502182","rc":[{"batb":[[0,2.12,10],[1,2.1,40.37],[2,1.74,17.32]],"ltp":2.18,"tv":292.4,"id":26354927}]}]}
{"op":"mcm","clk":"11793219444","pt":1723065956730,"mc":[{"id":"1.231502182","rc":[{"batb":[[0,2.1,40.37],[1,1.74,17.32],[2,1.7,10]],"ltp":2.18,"tv":292.4,"id":26354927}]}]}
{"op":"mcm","clk":"11793219528","pt":1723065959147,"mc":[{"id":"1.231502182","rc":[{"batb":[[0,2.12,10],[1,2.1,40.37],[2,1.74,17.32]],"ltp":2.18,"tv":292.4,"id":26354927}]}]}
{"op":"mcm","clk":"11793219604","pt":1723065960849,"mc":[{"id":"1.231502182","rc":[{"batb":[[0,1.82,19.92]],"ltp":1.81,"tv":640.03,"id":26354924}]}]}
{"op":"mcm","clk":"11793219658","pt":1723065962445,"mc":[{"id":"1.231502182","rc":[{"batb":[[0,2.1,40.37],[1,1.74,17.32],[2,1.7,10]],"ltp":2.18,"tv":292.4,"id":26354927}]}]}
{"op":"mcm","clk":"11793219745","pt":1723065964913,"mc":[{"id":"1.231502182","rc":[{"batb":[[0,2.12,10],[1,2.1,40.37],[2,1.74,17.32]],"ltp":2.18,"tv":292.4,"id":26354927}]}]}
{"op":"mcm","clk":"11793219861","pt":1723065968152,"mc":[{"id":"1.231502182","rc":[{"batb":[[0,2.1,40.37],[1,1.74,17.32],[2,1.7,10]],"ltp":2.18,"tv":292.4,"id":26354927}]}]}
{"op":"mcm","clk":"11793219956","pt":1723065970616,"mc":[{"id":"1.231502182","rc":[{"batb":[[0,2.12,10],[1,2.1,40.37],[2,1.74,17.32]],"ltp":2.18,"tv":292.4,"id":26354927}]}]}
{"op":"mcm","clk":"11793220075","pt":1723065973957,"mc":[{"id":"1.231502182","rc":[{"batb":[[0,2.1,40.37],[1,1.74,17.32],[2,1.7,10]],"ltp":2.18,"tv":292.4,"id":26354927}]}]}
{"op":"mcm","clk":"11793220163","pt":1723065976526,"mc":[{"id":"1.231502182","rc":[{"batb":[[0,2.12,10],[1,2.1,40.37],[2,1.74,17.32]],"ltp":2.18,"tv":292.4,"id":26354927}]}]}
{"op":"mcm","clk":"11793220261","pt":1723065980055,"mc":[{"id":"1.231502182","rc":[{"batb":[[0,2.1,40.37],[1,1.74,17.32],[2,1.7,10]],"ltp":2.18,"tv":292.4,"id":26354927}]}]}
{"op":"mcm","clk":"11793220374","pt":1723065982524,"mc":[{"id":"1.231502182","rc":[{"batb":[[0,2.12,10],[1,2.1,40.37],[2,1.74,17.32]],"ltp":2.18,"tv":292.4,"id":26354927}]}]}
{"op":"mcm","clk":"11793220482","pt":1723065986064,"mc":[{"id":"1.231502182","rc":[{"batb":[[0,2.1,40.37],[1,1.74,17.32],[2,1.7,10]],"ltp":2.18,"tv":292.4,"id":26354927}]}]}
{"op":"mcm","clk":"11793220580","pt":1723065988966,"mc":[{"id":"1.231502182","rc":[{"batb":[[0,2.12,10],[1,2.1,40.37],[2,1.74,17.32]],"ltp":2.18,"tv":292.4,"id":26354927}]}]}
{"op":"mcm","clk":"11793220704","pt":1723065992137,"mc":[{"id":"1.231502182","rc":[{"batb":[[0,2.1,40.37],[1,1.74,17.32],[2,1.7,10]],"ltp":2.18,"tv":292.4,"id":26354927}]}]}
{"op":"mcm","clk":"11793220786","pt":1723065994744,"mc":[{"id":"1.231502182","rc":[{"batb":[[0,2.12,10],[1,2.1,40.37],[2,1.74,17.32]],"ltp":2.18,"tv":292.4,"id":26354927}]}]}
{"op":"mcm","clk":"11793220877","pt":1723065998167,"mc":[{"id":"1.231502182","rc":[{"batb":[[0,2.1,40.37],[1,1.74,17.32],[2,1.7,10]],"ltp":2.18,"tv":292.4,"id":26354927}]}]}
{"op":"mcm","clk":"11793220955","pt":1723066000677,"mc":[{"id":"1.231502182","rc":[{"batb":[[0,2.12,10],[1,2.1,40.37],[2,1.74,17.32]],"ltp":2.18,"tv":292.4,"id":26354927}]}]}
{"op":"mcm","clk":"11793221068","pt":1723066004162,"mc":[{"id":"1.231502182","rc":[{"batb":[[0,2.1,40.37],[1,1.74,17.32],[2,1.7,10]],"ltp":2.18,"tv":292.4,"id":26354927}]}]}
{"op":"mcm","clk":"11793221160","pt":1723066006973,"mc":[{"id":"1.231502182","rc":[{"batb":[[0,2.12,10],[1,2.1,40.37],[2,1.74,17.32]],"ltp":2.18,"tv":292.4,"id":26354927}]}]}
{"op":"mcm","clk":"11793221262","pt":1723066010359,"mc":[{"id":"1.231502182","rc":[{"batb":[[0,2.1,40.37],[1,1.74,17.32],[2,1.7,10]],"ltp":2.18,"tv":292.4,"id":26354927}]}]}
{"op":"mcm","clk":"11793221389","pt":1723066013581,"mc":[{"id":"1.231502182","rc":[{"batb":[[0,2.12,10],[1,2.1,40.37],[2,1.74,17.32]],"ltp":2.18,"tv":292.4,"id":26354927}]}]}
{"op":"mcm","clk":"11793221525","pt":1723066017107,"mc":[{"id":"1.231502182","rc":[{"batb":[[0,2.1,40.37],[1,1.74,17.32],[2,1.7,10]],"ltp":2.18,"tv":292.4,"id":26354927}]}]}
{"op":"mcm","clk":"11793221634","pt":1723066019567,"mc":[{"id":"1.231502182","rc":[{"batb":[[0,2.12,10],[1,2.1,40.37],[2,1.74,17.32]],"ltp":2.18,"tv":292.4,"id":26354927}]}]}
{"op":"mcm","clk":"11793221736","pt":1723066023006,"mc":[{"id":"1.231502182","rc":[{"batb":[[0,2.1,40.37],[1,1.74,17.32],[2,1.7,10]],"ltp":2.18,"tv":292.4,"id":26354927}]}]}
{"op":"mcm","clk":"11793221807","pt":1723066025309,"mc":[{"id":"1.231502182","rc":[{"batb":[[0,2.12,10],[1,2.1,40.37],[2,1.74,17.32]],"ltp":2.18,"tv":292.4,"id":26354927}]}]}
{"op":"mcm","clk":"11793221916","pt":1723066028692,"mc":[{"id":"1.231502182","rc":[{"batb":[[0,2.1,40.37],[1,1.74,17.32],[2,1.7,10]],"ltp":2.18,"tv":292.4,"id":26354927}]}]}
{"op":"mcm","clk":"11793221974","pt":1723066031195,"mc":[{"id":"1.231502182","rc":[{"batb":[[0,2.12,10],[1,2.1,40.37],[2,1.74,17.32]],"ltp":2.18,"tv":292.4,"id":26354927}]}]}
{"op":"mcm","clk":"11793222088","pt":1723066034629,"mc":[{"id":"1.231502182","rc":[{"batb":[[0,2.1,40.37],[1,1.74,17.32],[2,1.7,10]],"ltp":2.18,"tv":292.4,"id":26354927}]}]}
{"op":"mcm","clk":"11793222295","pt":1723066041703,"mc":[{"id":"1.231502182","rc":[{"batb":[[0,2.12,10],[1,2.1,40.37],[2,1.74,17.32]],"ltp":2.18,"tv":292.4,"id":26354927}]}]}
{"op":"mcm","clk":"11793222424","pt":1723066045137,"mc":[{"id":"1.231502182","rc":[{"batb":[[0,2.1,40.37],[1,1.74,17.32],[2,1.7,10]],"ltp":2.18,"tv":292.4,"id":26354927}]}]}
{"op":"mcm","clk":"11793222525","pt":1723066047544,"mc":[{"id":"1.231502182","rc":[{"batb":[[0,2.12,10],[1,2.1,40.37],[2,1.74,17.32]],"ltp":2.18,"tv":292.4,"id":26354927}]}]}
{"op":"mcm","clk":"11793222651","pt":1723066051024,"mc":[{"id":"1.231502182","rc":[{"batb":[[0,2.1,40.37],[1,1.74,17.32],[2,1.7,10]],"ltp":2.18,"tv":292.4,"id":26354927}]}]}
{"op":"mcm","clk":"11793222740","pt":1723066053427,"mc":[{"id":"1.231502182","rc":[{"batb":[[0,2.12,10],[1,2.1,40.37],[2,1.74,17.32]],"ltp":2.18,"tv":292.4,"id":26354927}]}]}
{"op":"mcm","clk":"11793222874","pt":1723066056911,"mc":[{"id":"1.231502182","rc":[{"batb":[[0,2.1,40.37],[1,1.74,17.32],[2,1.7,10]],"ltp":2.18,"tv":292.4,"id":26354927}]}]}
{"op":"mcm","clk":"11793222977","pt":1723066060128,"mc":[{"id":"1.231502182","rc":[{"batb":[[0,2.12,10],[1,2.1,40.37],[2,1.74,17.32]],"ltp":2.18,"tv":292.4,"id":26354927}]}]}
{"op":"mcm","clk":"11793223081","pt":1723066063357,"mc":[{"id":"1.231502182","rc":[{"batb":[[0,2.1,40.37],[1,1.74,17.32],[2,1.7,10]],"ltp":2.18,"tv":292.4,"id":26354927}]}]}
{"op":"mcm","clk":"11793223153","pt":1723066065666,"mc":[{"id":"1.231502182","rc":[{"batb":[[0,2.12,10],[1,2.1,40.37],[2,1.74,17.32]],"ltp":2.18,"tv":292.4,"id":26354927}]}]}
{"op":"mcm","clk":"11793223273","pt":1723066068939,"mc":[{"id":"1.231502182","rc":[{"batb":[[0,2.1,40.37],[1,1.74,17.32],[2,1.7,10]],"ltp":2.18,"tv":292.4,"id":26354927}]}]}
{"op":"mcm","clk":"11793223407","pt":1723066073662,"mc":[{"id":"1.231502182","rc":[{"batb":[[0,2.12,10],[1,2.1,40.37],[2,1.74,17.32]],"ltp":2.18,"tv":292.4,"id":26354927}]}]}
{"op":"mcm","clk":"11793223500","pt":1723066076985,"mc":[{"id":"1.231502182","rc":[{"batb":[[0,2.1,40.37],[1,1.74,17.32],[2,1.7,10]],"ltp":2.18,"tv":292.4,"id":26354927}]}]}
{"op":"mcm","clk":"11793223600","pt":1723066079546,"mc":[{"id":"1.231502182","rc":[{"batb":[[0,2.12,10],[1,2.1,40.37],[2,1.74,17.32]],"ltp":2.18,"tv":292.4,"id":26354927}]}]}
{"op":"mcm","clk":"11793223730","pt":1723066082784,"mc":[{"id":"1.231502182","rc":[{"batb":[[0,2.1,40.37],[1,1.74,17.32],[2,1.7,10]],"ltp":2.18,"tv":292.4,"id":26354927}]}]}
{"op":"mcm","clk":"11793223821","pt":1723066085496,"mc":[{"id":"1.231502182","rc":[{"batb":[[0,2.12,10],[1,2.1,40.37],[2,1.74,17.32]],"ltp":2.18,"tv":292.4,"id":26354927}]}]}
{"op":"mcm","clk":"11793223950","pt":1723066088882,"mc":[{"id":"1.231502182","rc":[{"batb":[[0,2.1,40.37],[1,1.74,17.32],[2,1.7,10]],"ltp":2.18,"tv":292.4,"id":26354927}]}]}
{"op":"mcm","clk":"11793224036","pt":1723066091181,"mc":[{"id":"1.231502182","rc":[{"batb":[[0,2.12,10],[1,2.1,40.37],[2,1.74,17.32]],"ltp":2.18,"tv":292.4,"id":26354927}]}]}
{"op":"mcm","clk":"11793224140","pt":1723066094572,"mc":[{"id":"1.231502182","rc":[{"batb":[[0,2.1,40.37],[1,1.74,17.32],[2,1.7,10]],"ltp":2.18,"tv":292.4,"id":26354927}]}]}
{"op":"mcm","clk":"11793224243","pt":1723066098008,"mc":[{"id":"1.231502182","rc":[{"batb":[[0,2.12,10],[1,2.1,40.37],[2,1.74,17.32]],"ltp":2.18,"tv":292.4,"id":26354927}]}]}
{"op":"mcm","clk":"11793224359","pt":1723066101295,"mc":[{"id":"1.231502182","rc":[{"batb":[[0,2.1,40.37],[1,1.74,17.32],[2,1.7,10]],"ltp":2.18,"tv":292.4,"id":26354927}]}]}
{"op":"mcm","clk":"11793224475","pt":1723066104114,"mc":[{"id":"1.231502182","rc":[{"batb":[[0,2.12,10],[1,2.1,40.37],[2,1.74,17.32]],"ltp":2.18,"tv":292.4,"id":26354927}]}]}
{"op":"mcm","clk":"11793224614","pt":1723066107494,"mc":[{"id":"1.231502182","rc":[{"batb":[[0,2.1,40.37],[1,1.74,17.32],[2,1.7,10]],"ltp":2.18,"tv":292.4,"id":26354927}]}]}
{"op":"mcm","clk":"11793224716","pt":1723066109804,"mc":[{"id":"1.231502182","rc":[{"batb":[[0,2.12,10],[1,2.1,40.37],[2,1.74,17.32]],"ltp":2.18,"tv":292.4,"id":26354927}]}]}
{"op":"mcm","clk":"11793224836","pt":1723066113029,"mc":[{"id":"1.231502182","rc":[{"batb":[[0,2.1,40.37],[1,1.74,17.32],[2,1.7,10]],"ltp":2.18,"tv":292.4,"id":26354927}]}]}
{"op":"mcm","clk":"11793224920","pt":1723066115593,"mc":[{"id":"1.231502182","rc":[{"batb":[[0,2.12,10],[1,2.1,40.37],[2,1.74,17.32]],"ltp":2.18,"tv":292.4,"id":26354927}]}]}
{"op":"mcm","clk":"11793225021","pt":1723066118919,"mc":[{"id":"1.231502182","rc":[{"batb":[[0,2.1,40.37],[1,1.74,17.32],[2,1.7,10]],"ltp":2.18,"tv":292.4,"id":26354927}]}]}
{"op":"mcm","clk":"11793225124","pt":1723066121893,"mc":[{"id":"1.231502182","rc":[{"batb":[[0,2.12,10],[1,2.1,40.37],[2,1.74,17.32]],"ltp":2.18,"tv":292.4,"id":26354927}]}]}
{"op":"mcm","clk":"11793225232","pt":1723066125131,"mc":[{"id":"1.231502182","rc":[{"batb":[[0,2.1,40.37],[1,1.74,17.32],[2,1.7,10]],"ltp":2.18,"tv":292.4,"id":26354927}]}]}
{"op":"mcm","clk":"11793225304","pt":1723066127761,"mc":[{"id":"1.231502182","rc":[{"batb":[[0,2.12,10],[1,2.1,40.37],[2,1.74,17.32]],"ltp":2.18,"tv":292.4,"id":26354927}]}]}
{"op":"mcm","clk":"11793225434","pt":1723066131437,"mc":[{"id":"1.231502182","rc":[{"batb":[[0,2.1,40.37],[1,1.74,17.32],[2,1.7,10]],"ltp":2.18,"tv":292.4,"id":26354927}]}]}
{"op":"mcm","clk":"11793225559","pt":1723066134205,"mc":[{"id":"1.231502182","rc":[{"batb":[[0,2.12,10],[1,2.1,40.37],[2,1.74,17.32]],"ltp":2.18,"tv":292.4,"id":26354927}]}]}
{"op":"mcm","clk":"11793225663","pt":1723066137529,"mc":[{"id":"1.231502182","rc":[{"batb":[[0,2.1,40.37],[1,1.74,17.32],[2,1.7,10]],"ltp":2.18,"tv":292.4,"id":26354927}]}]}
{"op":"mcm","clk":"11793225747","pt":1723066139731,"mc":[{"id":"1.231502182","rc":[{"batb":[[0,2.12,10],[1,2.1,40.37],[2,1.74,17.32]],"ltp":2.18,"tv":292.4,"id":26354927}]}]}
{"op":"mcm","clk":"11793225900","pt":1723066143130,"mc":[{"id":"1.231502182","rc":[{"batb":[[0,2.1,40.37],[1,1.74,17.32],[2,1.7,10]],"ltp":2.18,"tv":292.4,"id":26354927}]}]}
{"op":"mcm","clk":"11793225984","pt":1723066145648,"mc":[{"id":"1.231502182","rc":[{"batb":[[0,2.12,10],[1,2.1,40.37],[2,1.74,17.32]],"ltp":2.18,"tv":292.4,"id":26354927}]}]}
{"op":"mcm","clk":"11793226143","pt":1723066149040,"mc":[{"id":"1.231502182","rc":[{"batb":[[0,2.1,40.37],[1,1.74,17.32],[2,1.7,10]],"ltp":2.18,"tv":292.4,"id":26354927}]}]}
{"op":"mcm","clk":"11793226262","pt":1723066151965,"mc":[{"id":"1.231502182","rc":[{"batb":[[0,2.12,10],[1,2.1,40.37],[2,1.74,17.32]],"ltp":2.18,"tv":292.4,"id":26354927}]}]}
{"op":"mcm","clk":"11793226397","pt":1723066155354,"mc":[{"id":"1.231502182","rc":[{"batb":[[0,2.1,40.37],[1,1.74,17.32],[2,1.7,10]],"ltp":2.18,"tv":292.4,"id":26354927}]}]}
{"op":"mcm","clk":"11793226694","pt":1723066162188,"mc":[{"id":"1.231502182","rc":[{"batb":[[0,2.12,10],[1,2.1,40.37],[2,1.74,17.32]],"ltp":2.18,"tv":292.4,"id":26354927}]}]}
{"op":"mcm","clk":"11793226830","pt":1723066165679,"mc":[{"id":"1.231502182","rc":[{"batb":[[0,2.1,40.37],[1,1.74,17.32],[2,1.7,10]],"ltp":2.18,"tv":292.4,"id":26354927}]}]}
{"op":"mcm","clk":"11793226972","pt":1723066169376,"mc":[{"id":"1.231502182","rc":[{"batb":[[0,2.12,10],[1,2.1,40.37],[2,1.74,17.32]],"ltp":2.18,"tv":292.4,"id":26354927}]}]}
{"op":"mcm","clk":"11793227100","pt":1723066172808,"mc":[{"id":"1.231502182","rc":[{"batb":[[0,2.1,40.37],[1,1.74,17.32],[2,1.7,10]],"ltp":2.18,"tv":292.4,"id":26354927}]}]}
{"op":"mcm","clk":"11793227205","pt":1723066175681,"mc":[{"id":"1.231502182","rc":[{"batb":[[0,2.12,10],[1,2.1,40.37],[2,1.74,17.32]],"ltp":2.18,"tv":292.4,"id":26354927}]}]}
{"op":"mcm","clk":"11793227330","pt":1723066179071,"mc":[{"id":"1.231502182","rc":[{"batb":[[0,2.1,40.37],[1,1.74,17.32],[2,1.7,10]],"ltp":2.18,"tv":292.4,"id":26354927}]}]}
{"op":"mcm","clk":"11793227421","pt":1723066181889,"mc":[{"id":"1.231502182","rc":[{"batb":[[0,2.12,10],[1,2.1,40.37],[2,1.74,17.32]],"ltp":2.18,"tv":292.4,"id":26354927}]}]}
{"op":"mcm","clk":"11793227555","pt":1723066185075,"mc":[{"id":"1.231502182","rc":[{"batb":[[0,2.1,40.37],[1,1.74,17.32],[2,1.7,10]],"ltp":2.18,"tv":292.4,"id":26354927}]}]}
{"op":"mcm","clk":"11793227683","pt":1723066188334,"mc":[{"id":"1.231502182","rc":[{"batb":[[0,2.12,10],[1,2.1,40.37],[2,1.74,17.32]],"ltp":2.18,"tv":292.4,"id":26354927}]}]}
{"op":"mcm","clk":"11793227787","pt":1723066191799,"mc":[{"id":"1.231502182","rc":[{"batb":[[0,2.1,40.37],[1,1.74,17.32],[2,1.7,10]],"ltp":2.18,"tv":292.4,"id":26354927}]}]}
{"op":"mcm","clk":"11793227900","pt":1723066194731,"mc":[{"id":"1.231502182","rc":[{"batb":[[0,2.12,10],[1,2.1,40.37],[2,1.74,17.32]],"ltp":2.18,"tv":292.4,"id":26354927}]}]}
{"op":"mcm","clk":"11793228042","pt":1723066198119,"mc":[{"id":"1.231502182","rc":[{"batb":[[0,2.1,40.37],[1,1.74,17.32],[2,1.7,10]],"ltp":2.18,"tv":292.4,"id":26354927}]}]}
{"op":"mcm","clk":"11793228157","pt":1723066200335,"mc":[{"id":"1.231502182","rc":[{"batb":[[0,2.12,10],[1,2.1,40.37],[2,1.74,17.32]],"ltp":2.18,"tv":292.4,"id":26354927}]}]}
{"op":"mcm","clk":"11793228337","pt":1723066203537,"mc":[{"id":"1.231502182","rc":[{"batb":[[0,2.1,40.37],[1,1.74,17.32],[2,1.7,10]],"ltp":2.18,"tv":292.4,"id":26354927}]}]}
{"op":"mcm","clk":"11793228495","pt":1723066207023,"mc":[{"id":"1.231502182","rc":[{"batb":[[0,2.12,10],[1,2.1,40.37],[2,1.74,17.32]],"ltp":2.18,"tv":292.4,"id":26354927}]}]}
{"op":"mcm","clk":"11793228630","pt":1723066210515,"mc":[{"id":"1.231502182","rc":[{"batb":[[0,2.1,40.37],[1,1.74,17.32],[2,1.7,10]],"ltp":2.18,"tv":292.4,"id":26354927}]}]}
{"op":"mcm","clk":"11793228756","pt":1723066213961,"mc":[{"id":"1.231502182","rc":[{"batb":[[0,2.12,10],[1,2.1,40.37],[2,1.74,17.32]],"ltp":2.18,"tv":292.4,"id":26354927}]}]}
{"op":"mcm","clk":"11793228895","pt":1723066217349,"mc":[{"id":"1.231502182","rc":[{"batb":[[0,2.1,40.37],[1,1.74,17.32],[2,1.7,10]],"ltp":2.18,"tv":292.4,"id":26354927}]}]}
{"op":"mcm","clk":"11793229015","pt":1723066220323,"mc":[{"id":"1.231502182","rc":[{"batb":[[0,2.12,10],[1,2.1,40.37],[2,1.74,17.32]],"ltp":2.18,"tv":292.4,"id":26354927}]}]}
{"op":"mcm","clk":"11793229148","pt":1723066223659,"mc":[{"id":"1.231502182","rc":[{"batb":[[0,2.1,40.37],[1,1.74,17.32],[2,1.7,10]],"ltp":2.18,"tv":292.4,"id":26354927}]}]}
{"op":"mcm","clk":"11793229243","pt":1723066225929,"mc":[{"id":"1.231502182","rc":[{"batb":[[0,2.12,10],[1,2.1,40.37],[2,1.74,17.32]],"ltp":2.18,"tv":292.4,"id":26354927}]}]}
{"op":"mcm","clk":"11793229396","pt":1723066229665,"mc":[{"id":"1.231502182","rc":[{"batb":[[0,2.1,40.37],[1,1.74,17.32],[2,1.7,10]],"ltp":2.18,"tv":292.4,"id":26354927}]}]}
{"op":"mcm","clk":"11793229543","pt":1723066232855,"mc":[{"id":"1.231502182","rc":[{"batb":[[0,2.12,10],[1,2.1,40.37],[2,1.74,17.32]],"ltp":2.18,"tv":292.4,"id":26354927}]}]}
{"op":"mcm","clk":"11793229681","pt":1723066236181,"mc":[{"id":"1.231502182","rc":[{"batb":[[0,2.1,40.37],[1,1.74,17.32],[2,1.7,10]],"ltp":2.18,"tv":292.4,"id":26354927}]}]}
{"op":"mcm","clk":"11793229820","pt":1723066239779,"mc":[{"id":"1.231502182","rc":[{"batb":[[0,2.12,10],[1,2.1,40.37],[2,1.74,17.32]],"ltp":2.18,"tv":292.4,"id":26354927}]}]}
{"op":"mcm","clk":"11793229926","pt":1723066243062,"mc":[{"id":"1.231502182","rc":[{"batb":[[0,2.1,40.37],[1,1.74,17.32],[2,1.7,10]],"ltp":2.18,"tv":292.4,"id":26354927}]}]}
{"op":"mcm","clk":"11793230027","pt":1723066245572,"mc":[{"id":"1.231502182","rc":[{"batb":[[0,2.12,10],[1,2.1,40.37],[2,1.74,17.32]],"ltp":2.18,"tv":292.4,"id":26354927}]}]}
{"op":"mcm","clk":"11793230156","pt":1723066248902,"mc":[{"id":"1.231502182","rc":[{"batb":[[0,2.1,40.37],[1,1.74,17.32],[2,1.7,10]],"ltp":2.18,"tv":292.4,"id":26354927}]}]}
{"op":"mcm","clk":"11793230233","pt":1723066251153,"mc":[{"id":"1.231502182","rc":[{"batb":[[0,2.12,10],[1,2.1,40.37],[2,1.74,17.32]],"ltp":2.18,"tv":292.4,"id":26354927}]}]}
{"op":"mcm","clk":"11793230364","pt":1723066254588,"mc":[{"id":"1.231502182","rc":[{"batb":[[0,2.1,40.37],[1,1.74,17.32],[2,1.7,10]],"ltp":2.18,"tv":292.4,"id":26354927}]}]}
{"op":"mcm","clk":"11793230506","pt":1723066258384,"mc":[{"id":"1.231502182","rc":[{"batb":[[0,2.12,10],[1,2.1,40.37],[2,1.74,17.32]],"ltp":2.18,"tv":292.4,"id":26354927}]}]}
{"op":"mcm","clk":"11793230673","pt":1723066261673,"mc":[{"id":"1.231502182","rc":[{"batb":[[0,2.1,40.37],[1,1.74,17.32],[2,1.7,10]],"ltp":2.18,"tv":292.4,"id":26354927}]}]}
{"op":"mcm","clk":"11793230782","pt":1723066263992,"mc":[{"id":"1.231502182","rc":[{"batb":[[0,2.12,10],[1,2.1,40.37],[2,1.74,17.32]],"ltp":2.18,"tv":292.4,"id":26354927}]}]}
{"op":"mcm","clk":"11793230933","pt":1723066267274,"mc":[{"id":"1.231502182","rc":[{"batb":[[0,2.1,40.37],[1,1.74,17.32],[2,1.7,10]],"ltp":2.18,"tv":292.4,"id":26354927}]}]}
{"op":"mcm","clk":"11793231103","pt":1723066271020,"mc":[{"id":"1.231502182","rc":[{"batb":[[0,2.12,10],[1,2.1,40.37],[2,1.74,17.32]],"ltp":2.18,"tv":292.4,"id":26354927}]}]}
{"op":"mcm","clk":"11793231253","pt":1723066274308,"mc":[{"id":"1.231502182","rc":[{"batb":[[0,2.1,40.37],[1,1.74,17.32],[2,1.7,10]],"ltp":2.18,"tv":292.4,"id":26354927}]}]}
{"op":"mcm","clk":"11793231412","pt":1723066277897,"mc":[{"id":"1.231502182","rc":[{"batb":[[0,2.12,10],[1,2.1,40.37],[2,1.74,17.32]],"ltp":2.18,"tv":292.4,"id":26354927}]}]}
{"op":"mcm","clk":"11793231580","pt":1723066281523,"mc":[{"id":"1.231502182","rc":[{"batb":[[0,2.1,40.37],[1,1.74,17.32],[2,1.7,10]],"ltp":2.18,"tv":292.4,"id":26354927}]}]}
{"op":"mcm","clk":"11793231666","pt":1723066284035,"mc":[{"id":"1.231502182","rc":[{"batb":[[0,2.12,10],[1,2.1,40.37],[2,1.74,17.32]],"ltp":2.18,"tv":292.4,"id":26354927}]}]}
{"op":"mcm","clk":"11793231792","pt":1723066287325,"mc":[{"id":"1.231502182","rc":[{"batb":[[0,2.1,40.37],[1,1.74,17.32],[2,1.7,10]],"ltp":2.18,"tv":292.4,"id":26354927}]}]}
{"op":"mcm","clk":"11793231923","pt":1723066290005,"mc":[{"id":"1.231502182","rc":[{"batb":[[0,2.12,10],[1,2.1,40.37],[2,1.74,17.32]],"ltp":2.18,"tv":292.4,"id":26354927}]}]}
{"op":"mcm","clk":"11793232073","pt":1723066293503,"mc":[{"id":"1.231502182","rc":[{"batb":[[0,2.1,40.37],[1,1.74,17.32],[2,1.7,10]],"ltp":2.18,"tv":292.4,"id":26354927}]}]}
{"op":"mcm","clk":"11793232190","pt":1723066296220,"mc":[{"id":"1.231502182","rc":[{"batb":[[0,2.12,10],[1,2.1,40.37],[2,1.74,17.32]],"ltp":2.18,"tv":292.4,"id":26354927}]}]}
{"op":"mcm","clk":"11793232349","pt":1723066299715,"mc":[{"id":"1.231502182","rc":[{"batb":[[0,2.1,40.37],[1,1.74,17.32],[2,1.7,10]],"ltp":2.18,"tv":292.4,"id":26354927}]}]}
{"op":"mcm","clk":"11793232458","pt":1723066302225,"mc":[{"id":"1.231502182","rc":[{"batb":[[0,2.12,10],[1,2.1,40.37],[2,1.74,17.32]],"ltp":2.18,"tv":292.4,"id":26354927}]}]}
{"op":"mcm","clk":"11793232597","pt":1723066305812,"mc":[{"id":"1.231502182","rc":[{"batb":[[0,2.1,40.37],[1,1.74,17.32],[2,1.7,10]],"ltp":2.18,"tv":292.4,"id":26354927}]}]}
{"op":"mcm","clk":"11793232732","pt":1723066308746,"mc":[{"id":"1.231502182","rc":[{"batb":[[0,2.12,10],[1,2.1,40.37],[2,1.74,17.32]],"ltp":2.18,"tv":292.4,"id":26354927}]}]}
{"op":"mcm","clk":"11793232858","pt":1723066312124,"mc":[{"id":"1.231502182","rc":[{"batb":[[0,2.1,40.37],[1,1.74,17.32],[2,1.7,10]],"ltp":2.18,"tv":292.4,"id":26354927}]}]}
{"op":"mcm","clk":"11793233023","pt":1723066316226,"mc":[{"id":"1.231502182","rc":[{"batb":[[0,2.12,10],[1,2.1,40.37],[2,1.74,17.32]],"ltp":2.18,"tv":292.4,"id":26354927}]}]}
{"op":"mcm","clk":"11793233149","pt":1723066319569,"mc":[{"id":"1.231502182","rc":[{"batb":[[0,2.1,40.37],[1,1.74,17.32],[2,1.7,10]],"ltp":2.18,"tv":292.4,"id":26354927}]}]}
{"op":"mcm","clk":"11793233243","pt":1723066321733,"mc":[{"id":"1.231502182","rc":[{"batb":[[0,2.12,10],[1,2.1,40.37],[2,1.74,17.32]],"ltp":2.18,"tv":292.4,"id":26354927}]}]}
{"op":"mcm","clk":"11793233338","pt":1723066325057,"mc":[{"id":"1.231502182","rc":[{"batb":[[0,2.1,40.37],[1,1.74,17.32],[2,1.7,10]],"ltp":2.18,"tv":292.4,"id":26354927}]}]}
{"op":"mcm","clk":"11793233451","pt":1723066328339,"mc":[{"id":"1.231502182","rc":[{"batb":[[0,2.12,10],[1,2.1,40.37],[2,1.74,17.32]],"ltp":2.18,"tv":292.4,"id":26354927}]}]}
{"op":"mcm","clk":"11793233569","pt":1723066331878,"mc":[{"id":"1.231502182","rc":[{"batb":[[0,2.1,40.37],[1,1.74,17.32],[2,1.7,10]],"ltp":2.18,"tv":292.4,"id":26354927}]}]}
{"op":"mcm","clk":"11793233723","pt":1723066335267,"mc":[{"id":"1.231502182","rc":[{"batb":[[0,2.12,10],[1,2.1,40.37],[2,1.74,17.32]],"ltp":2.18,"tv":292.4,"id":26354927}]}]}
{"op":"mcm","clk":"11793233853","pt":1723066338546,"mc":[{"id":"1.231502182","rc":[{"batb":[[0,2.1,40.37],[1,1.74,17.32],[2,1.7,10]],"ltp":2.18,"tv":292.4,"id":26354927}]}]}
{"op":"mcm","clk":"11793233958","pt":1723066341992,"mc":[{"id":"1.231502182","rc":[{"batb":[[0,2.12,10],[1,2.1,40.37],[2,1.74,17.32]],"ltp":2.18,"tv":292.4,"id":26354927}]}]}
{"op":"mcm","clk":"11793234094","pt":1723066345379,"mc":[{"id":"1.231502182","rc":[{"batb":[[0,2.1,40.37],[1,1.74,17.32],[2,1.7,10]],"ltp":2.18,"tv":292.4,"id":26354927}]}]}
{"op":"mcm","clk":"11793234194","pt":1723066348198,"mc":[{"id":"1.231502182","rc":[{"batb":[[0,2.12,10],[1,2.1,40.37],[2,1.74,17.32]],"ltp":2.18,"tv":292.4,"id":26354927}]}]}
{"op":"mcm","clk":"11793234325","pt":1723066351584,"mc":[{"id":"1.231502182","rc":[{"batb":[[0,2.1,40.37],[1,1.74,17.32],[2,1.7,10]],"ltp":2.18,"tv":292.4,"id":26354927}]}]}
{"op":"mcm","clk":"11793234458","pt":1723066354565,"mc":[{"id":"1.231502182","rc":[{"batb":[[0,2.12,10],[1,2.1,40.37],[2,1.74,17.32]],"ltp":2.18,"tv":292.4,"id":26354927}]}]}
{"op":"mcm","clk":"11793234602","pt":1723066357893,"mc":[{"id":"1.231502182","rc":[{"batb":[[0,2.1,40.37],[1,1.74,17.32],[2,1.7,10]],"ltp":2.18,"tv":292.4,"id":26354927}]}]}
{"op":"mcm","clk":"11793234711","pt":1723066360867,"mc":[{"id":"1.231502182","rc":[{"batb":[[0,2.12,10],[1,2.1,40.37],[2,1.74,17.32]],"ltp":2.18,"tv":292.4,"id":26354927}]}]}
{"op":"mcm","clk":"11793234844","pt":1723066364311,"mc":[{"id":"1.231502182","rc":[{"batb":[[0,2.1,40.37],[1,1.74,17.32],[2,1.7,10]],"ltp":2.18,"tv":292.4,"id":26354927}]}]}
{"op":"mcm","clk":"11793234972","pt":1723066366975,"mc":[{"id":"1.231502182","rc":[{"batb":[[0,2.12,10],[1,2.1,40.37],[2,1.74,17.32]],"ltp":2.18,"tv":292.4,"id":26354927}]}]}
{"op":"mcm","clk":"11793235099","pt":1723066370411,"mc":[{"id":"1.231502182","rc":[{"batb":[[0,2.1,40.37],[1,1.74,17.32],[2,1.7,10]],"ltp":2.18,"tv":292.4,"id":26354927}]}]}
{"op":"mcm","clk":"11793235261","pt":1723066374617,"mc":[{"id":"1.231502182","rc":[{"batb":[[0,2.12,10],[1,2.1,40.37],[2,1.74,17.32]],"ltp":2.18,"tv":292.4,"id":26354927}]}]}
{"op":"mcm","clk":"11793235372","pt":1723066377895,"mc":[{"id":"1.231502182","rc":[{"batb":[[0,2.1,40.37],[1,1.74,17.32],[2,1.7,10]],"ltp":2.18,"tv":292.4,"id":26354927}]}]}
{"op":"mcm","clk":"11793235474","pt":1723066380405,"mc":[{"id":"1.231502182","rc":[{"batb":[[0,2.12,10],[1,2.1,40.37],[2,1.74,17.32]],"ltp":2.18,"tv":292.4,"id":26354927}]}]}
{"op":"mcm","clk":"11793235618","pt":1723066383898,"mc":[{"id":"1.231502182","rc":[{"batb":[[0,2.1,40.37],[1,1.74,17.32],[2,1.7,10]],"ltp":2.18,"tv":292.4,"id":26354927}]}]}
{"op":"mcm","clk":"11793235725","pt":1723066387083,"mc":[{"id":"1.231502182","rc":[{"batb":[[0,2.12,10],[1,2.1,40.37],[2,1.74,17.32]],"ltp":2.18,"tv":292.4,"id":26354927}]}]}
{"op":"mcm","clk":"11793235883","pt":1723066390625,"mc":[{"id":"1.231502182","rc":[{"batb":[[0,2.1,40.37],[1,1.74,17.32],[2,1.7,10]],"ltp":2.18,"tv":292.4,"id":26354927}]}]}
{"op":"mcm","clk":"11793235971","pt":1723066393144,"mc":[{"id":"1.231502182","rc":[{"batb":[[0,2.12,10],[1,2.1,40.37],[2,1.74,17.32]],"ltp":2.18,"tv":292.4,"id":26354927}]}]}
{"op":"mcm","clk":"11793236091","pt":1723066396420,"mc":[{"id":"1.231502182","rc":[{"batb":[[0,2.1,40.37],[1,1.74,17.32],[2,1.7,10]],"ltp":2.18,"tv":292.4,"id":26354927}]}]}
{"op":"mcm","clk":"11793236205","pt":1723066399543,"mc":[{"id":"1.231502182","rc":[{"batb":[[0,2.12,10],[1,2.1,40.37],[2,1.74,17.32]],"ltp":2.18,"tv":292.4,"id":26354927}]}]}
{"op":"mcm","clk":"11793236344","pt":1723066402834,"mc":[{"id":"1.231502182","rc":[{"batb":[[0,2.1,40.37],[1,1.74,17.32],[2,1.7,10]],"ltp":2.18,"tv":292.4,"id":26354927}]}]}
{"op":"mcm","clk":"11793236463","pt":1723066405700,"mc":[{"id":"1.231502182","rc":[{"batb":[[0,2.12,10],[1,2.1,40.37],[2,1.74,17.32]],"ltp":2.18,"tv":292.4,"id":26354927}]}]}
{"op":"mcm","clk":"11793236602","pt":1723066408933,"mc":[{"id":"1.231502182","rc":[{"batb":[[0,2.1,40.37],[1,1.74,17.32],[2,1.7,10]],"ltp":2.18,"tv":292.4,"id":26354927}]}]}
{"op":"mcm","clk":"11793236713","pt":1723066411650,"mc":[{"id":"1.231502182","rc":[{"batb":[[0,2.12,10],[1,2.1,40.37],[2,1.74,17.32]],"ltp":2.18,"tv":292.4,"id":26354927}]}]}
{"op":"mcm","clk":"11793236837","pt":1723066414931,"mc":[{"id":"1.231502182","rc":[{"batb":[[0,2.1,40.37],[1,1.74,17.32],[2,1.7,10]],"ltp":2.18,"tv":292.4,"id":26354927}]}]}
{"op":"mcm","clk":"11793236975","pt":1723066418413,"mc":[{"id":"1.231502182","rc":[{"batb":[[0,2.12,10],[1,2.1,40.37],[2,1.74,17.32]],"ltp":2.18,"tv":292.4,"id":26354927}]}]}
{"op":"mcm","clk":"11793237093","pt":1723066421847,"mc":[{"id":"1.231502182","rc":[{"batb":[[0,2.1,40.37],[1,1.74,17.32],[2,1.7,10]],"ltp":2.18,"tv":292.4,"id":26354927}]}]}
{"op":"mcm","clk":"11793237218","pt":1723066424925,"mc":[{"id":"1.231502182","rc":[{"batb":[[0,2.12,10],[1,2.1,40.37],[2,1.74,17.32]],"ltp":2.18,"tv":292.4,"id":26354927}]}]}
{"op":"mcm","clk":"11793237355","pt":1723066428359,"mc":[{"id":"1.231502182","rc":[{"batb":[[0,2.1,40.37],[1,1.74,17.32],[2,1.7,10]],"ltp":2.18,"tv":292.4,"id":26354927}]}]}
{"op":"mcm","clk":"11793237448","pt":1723066430924,"mc":[{"id":"1.231502182","rc":[{"batb":[[0,2.12,10],[1,2.1,40.37],[2,1.74,17.32]],"ltp":2.18,"tv":292.4,"id":26354927}]}]}
{"op":"mcm","clk":"11793237633","pt":1723066435951,"mc":[{"id":"1.231502182","rc":[{"batb":[[0,2.1,40.37],[1,1.74,17.32],[2,1.7,10]],"ltp":2.18,"tv":292.4,"id":26354927}]}]}
{"op":"mcm","clk":"11793237711","pt":1723066438371,"mc":[{"id":"1.231502182","rc":[{"batb":[[0,2.12,10],[1,2.1,40.37],[2,1.74,17.32]],"ltp":2.18,"tv":292.4,"id":26354927}]}]}
{"op":"mcm","clk":"11793237862","pt":1723066441557,"mc":[{"id":"1.231502182","rc":[{"batb":[[0,2.1,40.37],[1,1.74,17.32],[2,1.7,10]],"ltp":2.18,"tv":292.4,"id":26354927}]}]}
{"op":"mcm","clk":"11793237960","pt":1723066444480,"mc":[{"id":"1.231502182","rc":[{"batb":[[0,2.12,10],[1,2.1,40.37],[2,1.74,17.32]],"ltp":2.18,"tv":292.4,"id":26354927}]}]}
{"op":"mcm","clk":"11793238091","pt":1723066447967,"mc":[{"id":"1.231502182","rc":[{"batb":[[0,2.1,40.37],[1,1.74,17.32],[2,1.7,10]],"ltp":2.18,"tv":292.4,"id":26354927}]}]}
{"op":"mcm","clk":"11793238207","pt":1723066450478,"mc":[{"id":"1.231502182","rc":[{"batb":[[0,2.12,10],[1,2.1,40.37],[2,1.74,17.32]],"ltp":2.18,"tv":292.4,"id":26354927}]}]}
{"op":"mcm","clk":"11793238313","pt":1723066453856,"mc":[{"id":"1.231502182","rc":[{"batb":[[0,2.1,40.37],[1,1.74,17.32],[2,1.7,10]],"ltp":2.18,"tv":292.4,"id":26354927}]}]}
{"op":"mcm","clk":"11793238464","pt":1723066457494,"mc":[{"id":"1.231502182","rc":[{"batb":[[0,2.12,10],[1,2.1,40.37],[2,1.74,17.32]],"ltp":2.18,"tv":292.4,"id":26354927}]}]}
{"op":"mcm","clk":"11793238644","pt":1723066462156,"mc":[{"id":"1.231502182","rc":[{"batb":[[0,2.1,40.37],[1,1.74,17.32],[2,1.7,10]],"ltp":2.18,"tv":292.4,"id":26354927}]}]}
{"op":"mcm","clk":"11793238781","pt":1723066465184,"mc":[{"id":"1.231502182","rc":[{"batb":[[0,2.12,10],[1,2.1,40.37],[2,1.74,17.32]],"ltp":2.18,"tv":292.4,"id":26354927}]}]}
{"op":"mcm","clk":"11793238913","pt":1723066468671,"mc":[{"id":"1.231502182","rc":[{"batb":[[0,2.1,40.37],[1,1.74,17.32],[2,1.7,10]],"ltp":2.18,"tv":292.4,"id":26354927}]}]}
{"op":"mcm","clk":"11793239024","pt":1723066471495,"mc":[{"id":"1.231502182","rc":[{"batb":[[0,2.12,10],[1,2.1,40.37],[2,1.74,17.32]],"ltp":2.18,"tv":292.4,"id":26354927}]}]}
{"op":"mcm","clk":"11793239131","pt":1723066475092,"mc":[{"id":"1.231502182","rc":[{"batb":[[0,2.1,40.37],[1,1.74,17.32],[2,1.7,10]],"ltp":2.18,"tv":292.4,"id":26354927}]}]}
{"op":"mcm","clk":"11793239205","pt":1723066477504,"mc":[{"id":"1.231502182","rc":[{"batb":[[0,2.12,10],[1,2.1,40.37],[2,1.74,17.32]],"ltp":2.18,"tv":292.4,"id":26354927}]}]}
{"op":"mcm","clk":"11793239331","pt":1723066480889,"mc":[{"id":"1.231502182","rc":[{"batb":[[0,2.1,40.37],[1,1.74,17.32],[2,1.7,10]],"ltp":2.18,"tv":292.4,"id":26354927}]}]}
{"op":"mcm","clk":"11793239415","pt":1723066483101,"mc":[{"id":"1.231502182","rc":[{"batb":[[0,2.12,10],[1,2.1,40.37],[2,1.74,17.32]],"ltp":2.18,"tv":292.4,"id":26354927}]}]}
{"op":"mcm","clk":"11793239535","pt":1723066486588,"mc":[{"id":"1.231502182","rc":[{"batb":[[0,2.1,40.37],[1,1.74,17.32],[2,1.7,10]],"ltp":2.18,"tv":292.4,"id":26354927}]}]}
{"op":"mcm","clk":"11793239648","pt":1723066489710,"mc":[{"id":"1.231502182","rc":[{"batb":[[0,2.12,10],[1,2.1,40.37],[2,1.74,17.32]],"ltp":2.18,"tv":292.4,"id":26354927}]}]}
{"op":"mcm","clk":"11793239757","pt":1723066493092,"mc":[{"id":"1.231502182","rc":[{"batb":[[0,2.1,40.37],[1,1.74,17.32],[2,1.7,10]],"ltp":2.18,"tv":292.4,"id":26354927}]}]}
{"op":"mcm","clk":"11793239862","pt":1723066496319,"mc":[{"id":"1.231502182","rc":[{"batb":[[0,2.12,10],[1,2.1,40.37],[2,1.74,17.32]],"ltp":2.18,"tv":292.4,"id":26354927}]}]}
{"op":"mcm","clk":"11793240013","pt":1723066500221,"mc":[{"id":"1.231502182","rc":[{"batb":[[0,2.1,40.37],[1,1.74,17.32],[2,1.7,10]],"ltp":2.18,"tv":292.4,"id":26354927}]}]}
{"op":"mcm","clk":"11793240103","pt":1723066502487,"mc":[{"id":"1.231502182","rc":[{"batb":[[0,2.12,10],[1,2.1,40.37],[2,1.74,17.32]],"ltp":2.18,"tv":292.4,"id":26354927}]}]}
{"op":"mcm","clk":"11793240205","pt":1723066505824,"mc":[{"id":"1.231502182","rc":[{"batb":[[0,2.1,40.37],[1,1.74,17.32],[2,1.7,10]],"ltp":2.18,"tv":292.4,"id":26354927}]}]}
{"op":"mcm","clk":"11793240351","pt":1723066509728,"mc":[{"id":"1.231502182","rc":[{"batb":[[0,2.12,10],[1,2.1,40.37],[2,1.74,17.32]],"ltp":2.18,"tv":292.4,"id":26354927}]}]}
{"op":"mcm","clk":"11793240466","pt":1723066512908,"mc":[{"id":"1.231502182","rc":[{"batb":[[0,2.1,40.37],[1,1.74,17.32],[2,1.7,10]],"ltp":2.18,"tv":292.4,"id":26354927}]}]}
{"op":"mcm","clk":"11793240607","pt":1723066516297,"mc":[{"id":"1.231502182","rc":[{"batb":[[0,2.12,10],[1,2.1,40.37],[2,1.74,17.32]],"ltp":2.18,"tv":292.4,"id":26354927}]}]}
{"op":"mcm","clk":"11793240745","pt":1723066519735,"mc":[{"id":"1.231502182","rc":[{"batb":[[0,2.1,40.37],[1,1.74,17.32],[2,1.7,10]],"ltp":2.18,"tv":292.4,"id":26354927}]}]}
{"op":"mcm","clk":"11793240885","pt":1723066523354,"mc":[{"id":"1.231502182","rc":[{"batb":[[0,2.12,10],[1,2.1,40.37],[2,1.74,17.32]],"ltp":2.18,"tv":292.4,"id":26354927}]}]}
{"op":"mcm","clk":"11793241017","pt":1723066526631,"mc":[{"id":"1.231502182","rc":[{"batb":[[0,2.1,40.37],[1,1.74,17.32],[2,1.7,10]],"ltp":2.18,"tv":292.4,"id":26354927}]}]}
{"op":"mcm","clk":"11793241256","pt":1723066532742,"mc":[{"id":"1.231502182","rc":[{"batb":[[0,2.12,10],[1,2.1,40.37],[2,1.74,17.32]],"ltp":2.18,"tv":292.4,"id":26354927}]}]}
{"op":"mcm","clk":"11793241405","pt":1723066536232,"mc":[{"id":"1.231502182","rc":[{"batb":[[0,2.1,40.37],[1,1.74,17.32],[2,1.7,10]],"ltp":2.18,"tv":292.4,"id":26354927}]}]}
{"op":"mcm","clk":"11793241512","pt":1723066538849,"mc":[{"id":"1.231502182","rc":[{"batb":[[0,2.12,10],[1,2.1,40.37],[2,1.74,17.32]],"ltp":2.18,"tv":292.4,"id":26354927}]}]}
{"op":"mcm","clk":"11793241656","pt":1723066542345,"mc":[{"id":"1.231502182","rc":[{"batb":[[0,2.1,40.37],[1,1.74,17.32],[2,1.7,10]],"ltp":2.18,"tv":292.4,"id":26354927}]}]}
{"op":"mcm","clk":"11793241815","pt":1723066545629,"mc":[{"id":"1.231502182","rc":[{"batb":[[0,2.12,10],[1,2.1,40.37],[2,1.74,17.32]],"ltp":2.18,"tv":292.4,"id":26354927}]}]}
{"op":"mcm","clk":"11793241947","pt":1723066549174,"mc":[{"id":"1.231502182","rc":[{"batb":[[0,2.1,40.37],[1,1.74,17.32],[2,1.7,10]],"ltp":2.18,"tv":292.4,"id":26354927}]}]}
{"op":"mcm","clk":"11793242045","pt":1723066551843,"mc":[{"id":"1.231502182","rc":[{"batb":[[0,2.12,10],[1,2.1,40.37],[2,1.74,17.32]],"ltp":2.18,"tv":292.4,"id":26354927}]}]}
{"op":"mcm","clk":"11793242199","pt":1723066555232,"mc":[{"id":"1.231502182","rc":[{"batb":[[0,2.1,40.37],[1,1.74,17.32],[2,1.7,10]],"ltp":2.18,"tv":292.4,"id":26354927}]}]}
{"op":"mcm","clk":"11793242298","pt":1723066557952,"mc":[{"id":"1.231502182","rc":[{"batb":[[0,2.12,10],[1,2.1,40.37],[2,1.74,17.32]],"ltp":2.18,"tv":292.4,"id":26354927}]}]}
{"op":"mcm","clk":"11793242467","pt":1723066561545,"mc":[{"id":"1.231502182","rc":[{"batb":[[0,2.1,40.37],[1,1.74,17.32],[2,1.7,10]],"ltp":2.18,"tv":292.4,"id":26354927}]}]}
{"op":"mcm","clk":"11793242607","pt":1723066564977,"mc":[{"id":"1.231502182","rc":[{"batb":[[0,2.12,10],[1,2.1,40.37],[2,1.74,17.32]],"ltp":2.18,"tv":292.4,"id":26354927}]}]}
{"op":"mcm","clk":"11793242725","pt":1723066568262,"mc":[{"id":"1.231502182","rc":[{"batb":[[0,2.1,40.37],[1,1.74,17.32],[2,1.7,10]],"ltp":2.18,"tv":292.4,"id":26354927}]}]}
{"op":"mcm","clk":"11793242830","pt":1723066570975,"mc":[{"id":"1.231502182","rc":[{"batb":[[0,2.12,10],[1,2.1,40.37],[2,1.74,17.32]],"ltp":2.18,"tv":292.4,"id":26354927}]}]}
{"op":"mcm","clk":"11793242973","pt":1723066574165,"mc":[{"id":"1.231502182","rc":[{"batb":[[0,2.1,40.37],[1,1.74,17.32],[2,1.7,10]],"ltp":2.18,"tv":292.4,"id":26354927}]}]}
{"op":"mcm","clk":"11793243075","pt":1723066576791,"mc":[{"id":"1.231502182","rc":[{"batb":[[0,2.12,10],[1,2.1,40.37],[2,1.74,17.32]],"ltp":2.18,"tv":292.4,"id":26354927}]}]}
{"op":"mcm","clk":"11793243200","pt":1723066580160,"mc":[{"id":"1.231502182","rc":[{"batb":[[0,2.1,40.37],[1,1.74,17.32],[2,1.7,10]],"ltp":2.18,"tv":292.4,"id":26354927}]}]}
{"op":"mcm","clk":"11793243356","pt":1723066583897,"mc":[{"id":"1.231502182","rc":[{"batb":[[0,2.12,10],[1,2.1,40.37],[2,1.74,17.32]],"ltp":2.18,"tv":292.4,"id":26354927}]}]}
{"op":"mcm","clk":"11793243501","pt":1723066587502,"mc":[{"id":"1.231502182","rc":[{"batb":[[0,2.1,40.37],[1,1.74,17.32],[2,1.7,10]],"ltp":2.18,"tv":292.4,"id":26354927}]}]}
{"op":"mcm","clk":"11793243582","pt":1723066590109,"mc":[{"id":"1.231502182","rc":[{"batb":[[0,2.12,10],[1,2.1,40.37],[2,1.74,17.32]],"ltp":2.18,"tv":292.4,"id":26354927}]}]}
{"op":"mcm","clk":"11793243746","pt":1723066593490,"mc":[{"id":"1.231502182","rc":[{"batb":[[0,2.1,40.37],[1,1.74,17.32],[2,1.7,10]],"ltp":2.18,"tv":292.4,"id":26354927}]}]}
{"op":"mcm","clk":"11793243864","pt":1723066596317,"mc":[{"id":"1.231502182","rc":[{"batb":[[0,2.12,10],[1,2.1,40.37],[2,1.74,17.32]],"ltp":2.18,"tv":292.4,"id":26354927}]}]}
{"op":"mcm","clk":"11793244010","pt":1723066600080,"mc":[{"id":"1.231502182","rc":[{"batb":[[0,2.1,40.37],[1,1.74,17.32],[2,1.7,10]],"ltp":2.18,"tv":292.4,"id":26354927}]}]}
{"op":"mcm","clk":"11793244135","pt":1723066602796,"mc":[{"id":"1.231502182","rc":[{"batb":[[0,2.12,10],[1,2.1,40.37],[2,1.74,17.32]],"ltp":2.18,"tv":292.4,"id":26354927}]}]}
{"op":"mcm","clk":"11793244270","pt":1723066606187,"mc":[{"id":"1.231502182","rc":[{"batb":[[0,2.1,40.37],[1,1.74,17.32],[2,1.7,10]],"ltp":2.18,"tv":292.4,"id":26354927}]}]}
{"op":"mcm","clk":"11793244372","pt":1723066609105,"mc":[{"id":"1.231502182","rc":[{"batb":[[0,2.12,10],[1,2.1,40.37],[2,1.74,17.32]],"ltp":2.18,"tv":292.4,"id":26354927}]}]}
{"op":"mcm","clk":"11793244500","pt":1723066612592,"mc":[{"id":"1.231502182","rc":[{"batb":[[0,2.1,40.37],[1,1.74,17.32],[2,1.7,10]],"ltp":2.18,"tv":292.4,"id":26354927}]}]}
{"op":"mcm","clk":"11793244601","pt":1723066615514,"mc":[{"id":"1.231502182","rc":[{"batb":[[0,2.12,10],[1,2.1,40.37],[2,1.74,17.32]],"ltp":2.18,"tv":292.4,"id":26354927}]}]}
{"op":"mcm","clk":"11793244734","pt":1723066618805,"mc":[{"id":"1.231502182","rc":[{"batb":[[0,2.1,40.37],[1,1.74,17.32],[2,1.7,10]],"ltp":2.18,"tv":292.4,"id":26354927}]}]}
{"op":"mcm","clk":"11793244879","pt":1723066622295,"mc":[{"id":"1.231502182","rc":[{"batb":[[0,2.12,10],[1,2.1,40.37],[2,1.74,17.32]],"ltp":2.18,"tv":292.4,"id":26354927}]}]}
{"op":"mcm","clk":"11793245014","pt":1723066625630,"mc":[{"id":"1.231502182","rc":[{"batb":[[0,2.1,40.37],[1,1.74,17.32],[2,1.7,10]],"ltp":2.18,"tv":292.4,"id":26354927}]}]}
{"op":"mcm","clk":"11793245124","pt":1723066628506,"mc":[{"id":"1.231502182","rc":[{"batb":[[0,2.12,10],[1,2.1,40.37],[2,1.74,17.32]],"ltp":2.18,"tv":292.4,"id":26354927}]}]}
{"op":"mcm","clk":"11793245264","pt":1723066631937,"mc":[{"id":"1.231502182","rc":[{"batb":[[0,2.1,40.37],[1,1.74,17.32],[2,1.7,10]],"ltp":2.18,"tv":292.4,"id":26354927}]}]}
{"op":"mcm","clk":"11793245351","pt":1723066634503,"mc":[{"id":"1.231502182","rc":[{"batb":[[0,2.12,10],[1,2.1,40.37],[2,1.74,17.32]],"ltp":2.18,"tv":292.4,"id":26354927}]}]}
{"op":"mcm","clk":"11793245468","pt":1723066638038,"mc":[{"id":"1.231502182","rc":[{"batb":[[0,2.1,40.37],[1,1.74,17.32],[2,1.7,10]],"ltp":2.18,"tv":292.4,"id":26354927}]}]}
{"op":"mcm","clk":"11793245597","pt":1723066642647,"mc":[{"id":"1.231502182","rc":[{"batb":[[0,2.12,10],[1,2.1,40.37],[2,1.74,17.32]],"ltp":2.18,"tv":292.4,"id":26354927}]}]}
{"op":"mcm","clk":"11793245741","pt":1723066646262,"mc":[{"id":"1.231502182","rc":[{"batb":[[0,2.1,40.37],[1,1.74,17.32],[2,1.7,10]],"ltp":2.18,"tv":292.4,"id":26354927}]}]}
{"op":"mcm","clk":"11793245852","pt":1723066648725,"mc":[{"id":"1.231502182","rc":[{"batb":[[0,2.12,10],[1,2.1,40.37],[2,1.74,17.32]],"ltp":2.18,"tv":292.4,"id":26354927}]}]}
{"op":"mcm","clk":"11793245995","pt":1723066652261,"mc":[{"id":"1.231502182","rc":[{"batb":[[0,2.1,40.37],[1,1.74,17.32],[2,1.7,10]],"ltp":2.18,"tv":292.4,"id":26354927}]}]}
{"op":"mcm","clk":"11793246075","pt":1723066654572,"mc":[{"id":"1.231502182","rc":[{"batb":[[0,2.12,10],[1,2.1,40.37],[2,1.74,17.32]],"ltp":2.18,"tv":292.4,"id":26354927}]}]}
{"op":"mcm","clk":"11793246178","pt":1723066657950,"mc":[{"id":"1.231502182","rc":[{"batb":[[0,2.1,40.37],[1,1.74,17.32],[2,1.7,10]],"ltp":2.18,"tv":292.4,"id":26354927}]}]}
{"op":"mcm","clk":"11793246268","pt":1723066660566,"mc":[{"id":"1.231502182","rc":[{"batb":[[0,2.12,10],[1,2.1,40.37],[2,1.74,17.32]],"ltp":2.18,"tv":292.4,"id":26354927}]}]}
{"op":"mcm","clk":"11793246394","pt":1723066663848,"mc":[{"id":"1.231502182","rc":[{"batb":[[0,2.1,40.37],[1,1.74,17.32],[2,1.7,10]],"ltp":2.18,"tv":292.4,"id":26354927}]}]}
{"op":"mcm","clk":"11793246518","pt":1723066667643,"mc":[{"id":"1.231502182","rc":[{"batb":[[0,2.12,10],[1,2.1,40.37],[2,1.74,17.32]],"ltp":2.18,"tv":292.4,"id":26354927}]}]}
{"op":"mcm","clk":"11793246616","pt":1723066671176,"mc":[{"id":"1.231502182","rc":[{"batb":[[0,2.1,40.37],[1,1.74,17.32],[2,1.7,10]],"ltp":2.18,"tv":292.4,"id":26354927}]}]}
{"op":"mcm","clk":"11793246727","pt":1723066673947,"mc":[{"id":"1.231502182","rc":[{"batb":[[0,2.12,10],[1,2.1,40.37],[2,1.74,17.32]],"ltp":2.18,"tv":292.4,"id":26354927}]}]}
{"op":"mcm","clk":"11793246858","pt":1723066677591,"mc":[{"id":"1.231502182","rc":[{"batb":[[0,2.1,40.37],[1,1.74,17.32],[2,1.7,10]],"ltp":2.18,"tv":292.4,"id":26354927}]}]}
{"op":"mcm","clk":"11793246942","pt":1723066680165,"mc":[{"id":"1.231502182","rc":[{"batb":[[0,2.12,10],[1,2.1,40.37],[2,1.74,17.32]],"ltp":2.18,"tv":292.4,"id":26354927}]}]}
{"op":"mcm","clk":"11793247096","pt":1723066683506,"mc":[{"id":"1.231502182","rc":[{"batb":[[0,2.1,40.37],[1,1.74,17.32],[2,1.7,10]],"ltp":2.18,"tv":292.4,"id":26354927}]}]}
{"op":"mcm","clk":"11793247228","pt":1723066686689,"mc":[{"id":"1.231502182","rc":[{"batb":[[0,2.12,10],[1,2.1,40.37],[2,1.74,17.32]],"ltp":2.18,"tv":292.4,"id":26354927}]}]}
{"op":"mcm","clk":"11793247392","pt":1723066690074,"mc":[{"id":"1.231502182","rc":[{"batb":[[0,2.1,40.37],[1,1.74,17.32],[2,1.7,10]],"ltp":2.18,"tv":292.4,"id":26354927}]}]}
{"op":"mcm","clk":"11793247543","pt":1723066693469,"mc":[{"id":"1.231502182","rc":[{"batb":[[0,2.12,10],[1,2.1,40.37],[2,1.74,17.32]],"ltp":2.18,"tv":292.4,"id":26354927}]}]}
{"op":"mcm","clk":"11793247699","pt":1723066696910,"mc":[{"id":"1.231502182","rc":[{"batb":[[0,2.1,40.37],[1,1.74,17.32],[2,1.7,10]],"ltp":2.18,"tv":292.4,"id":26354927}]}]}
{"op":"mcm","clk":"11793247775","pt":1723066699319,"mc":[{"id":"1.231502182","rc":[{"batb":[[0,2.12,10],[1,2.1,40.37],[2,1.74,17.32]],"ltp":2.18,"tv":292.4,"id":26354927}]}]}
{"op":"mcm","clk":"11793247916","pt":1723066702802,"mc":[{"id":"1.231502182","rc":[{"batb":[[0,2.1,40.37],[1,1.74,17.32],[2,1.7,10]],"ltp":2.18,"tv":292.4,"id":26354927}]}]}
{"op":"mcm","clk":"11793248047","pt":1723066705622,"mc":[{"id":"1.231502182","rc":[{"batb":[[0,2.12,10],[1,2.1,40.37],[2,1.74,17.32]],"ltp":2.18,"tv":292.4,"id":26354927}]}]}
{"op":"mcm","clk":"11793248181","pt":1723066708903,"mc":[{"id":"1.231502182","rc":[{"batb":[[0,2.1,40.37],[1,1.74,17.32],[2,1.7,10]],"ltp":2.18,"tv":292.4,"id":26354927}]}]}
{"op":"mcm","clk":"11793248374","pt":1723066712707,"mc":[{"id":"1.231502182","rc":[{"batb":[[0,2.12,10],[1,2.1,40.37],[2,1.74,17.32]],"ltp":2.18,"tv":292.4,"id":26354927}]}]}
{"op":"mcm","clk":"11793248516","pt":1723066716037,"mc":[{"id":"1.231502182","rc":[{"batb":[[0,2.1,40.37],[1,1.74,17.32],[2,1.7,10]],"ltp":2.18,"tv":292.4,"id":26354927}]}]}
{"op":"mcm","clk":"11793248682","pt":1723066719421,"mc":[{"id":"1.231502182","rc":[{"batb":[[0,2.12,10],[1,2.1,40.37],[2,1.74,17.32]],"ltp":2.18,"tv":292.4,"id":26354927}]}]}
{"op":"mcm","clk":"11793248858","pt":1723066722920,"mc":[{"id":"1.231502182","rc":[{"batb":[[0,2.1,40.37],[1,1.74,17.32],[2,1.7,10]],"ltp":2.18,"tv":292.4,"id":26354927}]}]}
{"op":"mcm","clk":"11793248988","pt":1723066725848,"mc":[{"id":"1.231502182","rc":[{"batb":[[0,2.12,10],[1,2.1,40.37],[2,1.74,17.32]],"ltp":2.18,"tv":292.4,"id":26354927}]}]}
{"op":"mcm","clk":"11793249156","pt":1723066729145,"mc":[{"id":"1.231502182","rc":[{"batb":[[0,2.1,40.37],[1,1.74,17.32],[2,1.7,10]],"ltp":2.18,"tv":292.4,"id":26354927}]}]}
{"op":"mcm","clk":"11793249281","pt":1723066731721,"mc":[{"id":"1.231502182","rc":[{"batb":[[0,2.12,10],[1,2.1,40.37],[2,1.74,17.32]],"ltp":2.18,"tv":292.4,"id":26354927}]}]}
{"op":"mcm","clk":"11793249434","pt":1723066735052,"mc":[{"id":"1.231502182","rc":[{"batb":[[0,2.1,40.37],[1,1.74,17.32],[2,1.7,10]],"ltp":2.18,"tv":292.4,"id":26354927}]}]}
{"op":"mcm","clk":"11793249569","pt":1723066738951,"mc":[{"id":"1.231502182","rc":[{"batb":[[0,2.12,10],[1,2.1,40.37],[2,1.74,17.32]],"ltp":2.18,"tv":292.4,"id":26354927}]}]}
{"op":"mcm","clk":"11793249717","pt":1723066742245,"mc":[{"id":"1.231502182","rc":[{"batb":[[0,2.1,40.37],[1,1.74,17.32],[2,1.7,10]],"ltp":2.18,"tv":292.4,"id":26354927}]}]}
{"op":"mcm","clk":"11793249849","pt":1723066745634,"mc":[{"id":"1.231502182","rc":[{"batb":[[0,2.12,10],[1,2.1,40.37],[2,1.74,17.32]],"ltp":2.18,"tv":292.4,"id":26354927}]}]}
{"op":"mcm","clk":"11793249998","pt":1723066749071,"mc":[{"id":"1.231502182","rc":[{"batb":[[0,2.1,40.37],[1,1.74,17.32],[2,1.7,10]],"ltp":2.18,"tv":292.4,"id":26354927}]}]}
{"op":"mcm","clk":"11793250120","pt":1723066751643,"mc":[{"id":"1.231502182","rc":[{"batb":[[0,2.12,10],[1,2.1,40.37],[2,1.74,17.32]],"ltp":2.18,"tv":292.4,"id":26354927}]}]}
{"op":"mcm","clk":"11793250243","pt":1723066755177,"mc":[{"id":"1.231502182","rc":[{"batb":[[0,2.1,40.37],[1,1.74,17.32],[2,1.7,10]],"ltp":2.18,"tv":292.4,"id":26354927}]}]}
{"op":"mcm","clk":"11793250368","pt":1723066757755,"mc":[{"id":"1.231502182","rc":[{"batb":[[0,2.12,10],[1,2.1,40.37],[2,1.74,17.32]],"ltp":2.18,"tv":292.4,"id":26354927}]}]}
{"op":"mcm","clk":"11793250503","pt":1723066761190,"mc":[{"id":"1.231502182","rc":[{"batb":[[0,2.1,40.37],[1,1.74,17.32],[2,1.7,10]],"ltp":2.18,"tv":292.4,"id":26354927}]}]}
{"op":"mcm","clk":"11793250623","pt":1723066764473,"mc":[{"id":"1.231502182","rc":[{"batb":[[0,2.12,10],[1,2.1,40.37],[2,1.74,17.32]],"ltp":2.18,"tv":292.4,"id":26354927}]}]}
{"op":"mcm","clk":"11793250747","pt":1723066767910,"mc":[{"id":"1.231502182","rc":[{"batb":[[0,2.1,40.37],[1,1.74,17.32],[2,1.7,10]],"ltp":2.18,"tv":292.4,"id":26354927}]}]}
{"op":"mcm","clk":"11793250866","pt":1723066770689,"mc":[{"id":"1.231502182","rc":[{"batb":[[0,2.12,10],[1,2.1,40.37],[2,1.74,17.32]],"ltp":2.18,"tv":292.4,"id":26354927}]}]}
{"op":"mcm","clk":"11793250986","pt":1723066773973,"mc":[{"id":"1.231502182","rc":[{"batb":[[0,2.1,40.37],[1,1.74,17.32],[2,1.7,10]],"ltp":2.18,"tv":292.4,"id":26354927}]}]}
{"op":"mcm","clk":"11793251086","pt":1723066776485,"mc":[{"id":"1.231502182","rc":[{"batb":[[0,2.12,10],[1,2.1,40.37],[2,1.74,17.32]],"ltp":2.18,"tv":292.4,"id":26354927}]}]}
{"op":"mcm","clk":"11793251245","pt":1723066780086,"mc":[{"id":"1.231502182","rc":[{"batb":[[0,2.1,40.37],[1,1.74,17.32],[2,1.7,10]],"ltp":2.18,"tv":292.4,"id":26354927}]}]}
{"op":"mcm","clk":"11793251357","pt":1723066782804,"mc":[{"id":"1.231502182","rc":[{"batb":[[0,2.12,10],[1,2.1,40.37],[2,1.74,17.32]],"ltp":2.18,"tv":292.4,"id":26354927}]}]}
{"op":"mcm","clk":"11793251498","pt":1723066786205,"mc":[{"id":"1.231502182","rc":[{"batb":[[0,2.1,40.37],[1,1.74,17.32],[2,1.7,10]],"ltp":2.18,"tv":292.4,"id":26354927}]}]}
{"op":"mcm","clk":"11793251634","pt":1723066789220,"mc":[{"id":"1.231502182","rc":[{"batb":[[0,2.12,10],[1,2.1,40.37],[2,1.74,17.32]],"ltp":2.18,"tv":292.4,"id":26354927}]}]}
{"op":"mcm","clk":"11793251798","pt":1723066792613,"mc":[{"id":"1.231502182","rc":[{"batb":[[0,2.1,40.37],[1,1.74,17.32],[2,1.7,10]],"ltp":2.18,"tv":292.4,"id":26354927}]}]}
{"op":"mcm","clk":"11793251923","pt":1723066795894,"mc":[{"id":"1.231502182","rc":[{"batb":[[0,2.12,10],[1,2.1,40.37],[2,1.74,17.32]],"ltp":2.18,"tv":292.4,"id":26354927}]}]}
{"op":"mcm","clk":"11793252063","pt":1723066799336,"mc":[{"id":"1.231502182","rc":[{"batb":[[0,2.1,40.37],[1,1.74,17.32],[2,1.7,10]],"ltp":2.18,"tv":292.4,"id":26354927}]}]}
{"op":"mcm","clk":"11793256472","pt":1723066909439,"mc":[{"id":"1.231502182","rc":[{"trd":[[1.82,32.08]],"batb":[[0,1.82,11.91]],"ltp":1.82,"tv":656.04,"id":26354924}],"tv":948.44}]}
{"op":"mcm","clk":"11793257555","pt":1723066929874,"mc":[{"id":"1.231502182","rc":[{"batl":[[0,1.83,5],[1,1.84,6.82],[2,1.85,30]],"ltp":1.82,"tv":656.04,"id":26354924}]}]}
{"op":"mcm","clk":"11793270792","pt":1723067267341,"mc":[{"id":"1.231502182","rc":[{"trd":[[2.2,5.92]],"ltp":2.2,"tv":292.92,"id":26354927},{"trd":[[1.83,173.7]],"batl":[[0,1.83,4.38]],"ltp":1.83,"tv":656.66,"id":26354924}],"tv":949.58}]}
{"op":"mcm","clk":"11793277751","pt":1723067430800,"mc":[{"id":"1.231502182","rc":[{"batb":[[0,2.16,38.28]],"ltp":2.2,"tv":292.92,"id":26354927}]}]}
{"op":"mcm","clk":"11793345694","pt":1723068774911,"mc":[{"id":"1.231502182","rc":[{"trd":[[1.4,255.02],[2.12,29.6],[2.2,5.92]],"batl":[[0,2.22,31.82]],"ltp":2.2,"tv":292.89,"id":26354927},{"trd":[[1.4,255.57],[1.86,29.3]],"batb":[[0,1.82,11.91]],"ltp":1.83,"tv":656.63,"id":26354924}],"tv":949.53}]}
{"op":"mcm","clk":"11793365474","pt":1723069068885,"mc":[{"id":"1.231502182","rc":[{"trd":[[1.82,33.51]],"batb":[[0,1.82,11.2]],"ltp":1.82,"tv":658.06,"id":26354924}],"tv":950.95}]}
{"op":"mcm","clk":"11793422039","pt":1723070246454,"mc":[{"id":"1.231502182","rc":[{"batl":[[0,1.83,4]],"ltp":1.82,"tv":658.06,"id":26354924}]}]}
{"op":"mcm","clk":"11793485434","pt":1723071582635,"mc":[{"id":"1.231502182","rc":[{"trd":[[2.2,9.25]],"batl":[[0,2.2,36.67],[1,2.22,31.82],[2,2.26,2]],"ltp":2.2,"tv":296.22,"id":26354927},{"trd":[[1.83,177.7]],"batl":[[0,1.84,6.82],[1,1.85,30],[2,1.86,25]],"ltp":1.83,"tv":662.06,"id":26354924}],"tv":958.28}]}
{"op":"mcm","clk":"11793485488","pt":1723071584020,"mc":[{"id":"1.231502182","rc":[{"batb":[[0,1.81,259.67],[1,1.8,309.67],[2,1.79,315.88]],"ltp":1.83,"tv":662.06,"id":26354924}]}]}
{"op":"mcm","clk":"11793485558","pt":1723071585859,"mc":[{"id":"1.231502182","rc":[{"batl":[[1,2.26,2],[2,2.26,0]],"ltp":2.2,"tv":296.22,"id":26354927},{"batl":[[0,1.84,10.49]],"ltp":1.83,"tv":662.06,"id":26354924}]}]}
{"op":"mcm","clk":"11793486633","pt":1723071608882,"mc":[{"id":"1.231502182","rc":[{"trd":[[1.4,255.18],[2.12,29.6],[2.18,29.86],[2.2,9.25]],"batl":[[0,2.18,17.81]],"ltp":2.18,"tv":325.25,"id":26354927},{"trd":[[1.4,255.73],[1.82,33.51],[1.83,177.7],[1.84,13.58],[1.85,16.09],[1.86,29.3]],"batl":[[0,1.85,30],[1,1.86,25],[2,1.87,8]],"ltp":1.84,"tv":672.74,"id":26354924}],"tv":997.99}]}
{"op":"mcm","clk":"11793486659","pt":1723071609286,"mc":[{"id":"1.231502182","rc":[{"batb":[[0,1.83,8.04],[1,1.81,259.67],[2,1.8,309.67]],"ltp":1.84,"tv":672.74,"id":26354924}]}]}
{"op":"mcm","clk":"11793486819","pt":1723071612687,"mc":[{"id":"1.231502182","rc":[{"batb":[[0,2.18,10],[1,2.16,38.28],[2,1.74,17.32]],"batl":[[0,2.26,2],[1,2.26,0]],"ltp":2.18,"tv":325.25,"id":26354927}]}]}
{"op":"mcm","clk":"11793486848","pt":1723071613281,"mc":[{"id":"1.231502182","rc":[{"batl":[[0,2.22,16.25],[1,2.26,2]],"ltp":2.18,"tv":325.25,"id":26354927}]}]}
{"op":"mcm","clk":"11793486928","pt":1723071615052,"mc":[{"id":"1.231502182","rc":[{"batb":[[1,1.74,17.32],[2,1.7,10]],"ltp":2.18,"tv":325.25,"id":26354927}]}]}
{"op":"mcm","clk":"11793486975","pt":1723071616077,"mc":[{"id":"1.231502182","rc":[{"batb":[[0,1.74,17.32],[1,1.7,10],[2,1.25,100]],"ltp":2.18,"tv":325.25,"id":26354927}]}]}
{"op":"mcm","clk":"11793487133","pt":1723071619360,"mc":[{"id":"1.231502182","rc":[{"batb":[[0,1.75,10],[1,1.74,17.32],[2,1.7,10]],"ltp":2.18,"tv":325.25,"id":26354927}]}]}
{"op":"mcm","clk":"11793487162","pt":1723071620076,"mc":[{"id":"1.231502182","rc":[{"batb":[[0,2.16,38.28],[1,1.75,10],[2,1.74,17.32]],"ltp":2.18,"tv":325.25,"id":26354927}]}]}
{"op":"mcm","clk":"11793487257","pt":1723071622581,"mc":[{"id":"1.231502182","rc":[{"batb":[[1,1.74,17.32],[2,1.7,10]],"ltp":2.18,"tv":325.25,"id":26354927}]}]}
{"op":"mcm","clk":"11793487562","pt":1723071629876,"mc":[{"id":"1.231502182","rc":[{"batb":[[1,1.82,14.13],[2,1.81,259.67]],"ltp":1.84,"tv":672.74,"id":26354924}]}]}
{"op":"mcm","clk":"11793536456","pt":1723072629598,"mc":[{"id":"1.231502182","rc":[{"batl":[[1,1.86,33],[2,1.88,820.18]],"ltp":1.84,"tv":672.74,"id":26354924}]}]}
{"op":"mcm","clk":"11793577667","pt":1723073351143,"mc":[{"id":"1.231502182","rc":[{"batb":[[0,2.18,4.54],[1,2.16,38.28],[2,1.74,17.32]],"ltp":2.18,"tv":325.25,"id":26354927}]}]}
{"op":"mcm","clk":"11793764465","pt":1723076302975,"mc":[{"id":"1.231502182","rc":[{"trd":[[1.4,255.51],[2.12,29.61],[2.2,9.26]],"batb":[[0,2.18,4.54]],"batl":[[0,2.22,16.26]],"ltp":2.18,"tv":325.59,"id":26354927},{"trd":[[1.4,256.06],[1.82,33.51],[1.83,179.55],[1.84,13.59],[1.85,16.1],[1.86,29.32]],"batb":[[0,1.83,7.12],[1,1.82,14.14]],"ltp":1.83,"tv":674.94,"id":26354924}],"tv":1000.53}]}
{"op":"mcm","clk":"11793917742","pt":1723079011921,"mc":[{"id":"1.231502182","rc":[{"trd":[[1.4,255.56],[2.12,29.61]],"batl":[[0,2.22,21.46]],"ltp":2.18,"tv":325.64,"id":26354927},{"trd":[[1.4,256.11],[1.81,265.5],[1.82,61.78],[1.83,193.79],[1.85,16.11],[1.86,29.33]],"batb":[[0,1.81,130.92],[1,1.8,309.67],[2,1.79,315.88]],"batl":[[0,1.84,13.98],[1,1.85,30],[2,1.86,33]],"ltp":1.81,"tv":975.0,"id":26354924}],"tv":1300.64}]}
{"op":"mcm","clk":"11793917803","pt":1723079012950,"mc":[{"id":"1.231502182","rc":[{"batl":[[0,2.22,29.4]],"ltp":2.18,"tv":325.64,"id":26354927}]}]}
{"op":"mcm","clk":"11794031748","pt":1723080748526,"mc":[{"id":"1.231502182","rc":[{"batl":[[0,2.2,10],[1,2.22,29.4],[2,2.26,2]],"ltp":2.18,"tv":325.64,"id":26354927}]}]}
{"op":"mcm","clk":"11794033333","pt":1723080773779,"mc":[{"id":"1.231502182","rc":[{"trd":[[2.2,19.26]],"batl":[[0,2.22,29.4],[1,2.26,2],[2,2.26,0]],"ltp":2.2,"tv":335.64,"id":26354927},{"trd":[[1.81,281.46],[1.83,205.81]],"batb":[[0,1.81,122.94]],"ltp":1.81,"tv":1002.98,"id":26354924}],"tv":1338.62}]}
{"op":"mcm","clk":"11794037044","pt":1723080836041,"mc":[{"id":"1.231502182","rc":[{"trd":[[1.84,41.54]],"batb":[[0,1.84,191.02],[1,1.81,122.94],[2,1.8,309.67]],"batl":[[0,1.85,30],[1,1.86,33],[2,1.88,820.18]],"ltp":1.84,"tv":1030.93,"id":26354924}],"tv":1366.57}]}
{"op":"mcm","clk":"11794037120","pt":1723080837326,"mc":[{"id":"1.231502182","rc":[{"batb":[[0,2.16,38.28],[1,1.74,17.32],[2,1.7,10]],"batl":[[0,2.22,24.21]],"ltp":2.2,"tv":335.64,"id":26354927}]}]}
{"op":"mcm","clk":"11794037175","pt":1723080838347,"mc":[{"id":"1.231502182","rc":[{"batb":[[0,2.18,10],[1,2.16,38.28],[2,1.74,17.32]],"batl":[[0,2.26,2],[1,2.26,0]],"ltp":2.2,"tv":335.64,"id":26354927}]}]}
{"op":"mcm","clk":"11794037385","pt":1723080841733,"mc":[{"id":"1.231502182","rc":[{"batb":[[0,2.16,38.28],[1,1.74,17.32],[2,1.7,10]],"ltp":2.2,"tv":335.64,"id":26354927}]}]}
{"op":"mcm","clk":"11794037556","pt":1723080844755,"mc":[{"id":"1.231502182","rc":[{"batb":[[0,2.18,10],[1,2.16,38.28],[2,1.74,17.32]],"ltp":2.2,"tv":335.64,"id":26354927}]}]}
{"op":"mcm","clk":"11794037725","pt":1723080847928,"mc":[{"id":"1.231502182","rc":[{"batb":[[1,1.74,17.32],[2,1.7,10]],"ltp":2.2,"tv":335.64,"id":26354927}]}]}
{"op":"mcm","clk":"11794037732","pt":1723080848134,"mc":[{"id":"1.231502182","rc":[{"batb":[[0,1.74,17.32],[1,1.7,10],[2,1.25,100]],"ltp":2.2,"tv":335.64,"id":26354927}]}]}
{"op":"mcm","clk":"11794037925","pt":1723080850650,"mc":[{"id":"1.231502182","rc":[{"batb":[[0,1.75,10],[1,1.74,17.32],[2,1.7,10]],"ltp":2.2,"tv":335.64,"id":26354927},{"trd":[[1.85,76.11]],"batb":[[0,1.85,161.02]],"batl":[[0,1.86,33],[1,1.88,820.18],[2,1.89,97.65]],"ltp":1.85,"tv":1090.93,"id":26354924}],"tv":1426.57}]}
{"op":"mcm","clk":"11794038037","pt":1723080852851,"mc":[{"id":"1.231502182","rc":[{"batb":[[0,2.16,38.28],[1,1.75,10],[2,1.74,17.32]],"ltp":2.2,"tv":335.64,"id":26354927}]}]}
{"op":"mcm","clk":"11794038089","pt":1723080854033,"mc":[{"id":"1.231502182","rc":[{"batb":[[1,1.74,17.32],[2,1.7,10]],"ltp":2.2,"tv":335.64,"id":26354927}]}]}
{"op":"mcm","clk":"11794038283","pt":1723080857470,"mc":[{"id":"1.231502182","rc":[{"trd":[[2.18,39.86]],"ltp":2.18,"tv":345.64,"id":26354927},{"trd":[[1.85,87.89]],"batb":[[0,1.85,149.24]],"ltp":1.85,"tv":1102.71,"id":26354924}],"tv":1448.35}]}
{"op":"mcm","clk":"11794038480","pt":1723080860139,"mc":[{"id":"1.231502182","rc":[{"trd":[[2.18,49.86]],"ltp":2.18,"tv":355.64,"id":26354927},{"trd":[[1.85,99.67]],"batb":[[0,1.85,137.46]],"ltp":1.85,"tv":1114.49,"id":26354924}],"tv":1470.13}]}
{"op":"mcm","clk":"11794038657","pt":1723080863575,"mc":[{"id":"1.231502182","rc":[{"trd":[[2.18,59.86]],"ltp":2.18,"tv":365.64,"id":26354927},{"trd":[[1.85,111.45]],"batb":[[0,1.85,125.68]],"ltp":1.85,"tv":1126.27,"id":26354924}],"tv":1491.91}]}
{"op":"mcm","clk":"11794038821","pt":1723080866253,"mc":[{"id":"1.231502182","rc":[{"trd":[[2.18,69.86]],"ltp":2.18,"tv":375.64,"id":26354927},{"trd":[[1.85,123.23]],"batb":[[0,1.85,113.9]],"ltp":1.85,"tv":1138.05,"id":26354924}],"tv":1513.69}]}
{"op":"mcm","clk":"11794038978","pt":1723080869680,"mc":[{"id":"1.231502182","rc":[{"batb":[[0,2.18,10],[1,2.16,38.28],[2,1.74,17.32]],"ltp":2.18,"tv":375.64,"id":26354927},{"batb":[[0,1.81,122.94],[1,1.8,309.67],[2,1.79,315.88]],"ltp":1.85,"tv":1138.05,"id":26354924}]}]}
{"op":"mcm","clk":"11794039030","pt":1723080870756,"mc":[{"id":"1.231502182","rc":[{"batl":[[0,2.22,7.46],[1,2.26,2]],"ltp":2.18,"tv":375.64,"id":26354927}]}]}
{"op":"mcm","clk":"11794039152","pt":1723080873270,"mc":[{"id":"1.231502182","rc":[{"batb":[[0,2.16,38.28],[1,1.74,17.32],[2,1.7,10]],"ltp":2.18,"tv":375.64,"id":26354927}]}]}
{"op":"mcm","clk":"11794039662","pt":1723080881583,"mc":[{"id":"1.231502182","rc":[{"batl":[[0,2.22,12.7]],"ltp":2.18,"tv":375.64,"id":26354927},{"batb":[[0,1.82,6.49],[1,1.81,122.94],[2,1.8,309.67]],"ltp":1.85,"tv":1138.05,"id":26354924}]}]}
{"op":"mcm","clk":"11794041248","pt":1723080913820,"mc":[{"id":"1.231502182","rc":[{"batl":[[0,2.22,20.17]],"ltp":2.18,"tv":375.64,"id":26354927}]}]}
{"op":"mcm","clk":"11794042026","pt":1723080928529,"mc":[{"id":"1.231502182","rc":[{"batl":[[0,1.85,91],[1,1.86,33],[2,1.88,820.18]],"ltp":1.85,"tv":1138.05,"id":26354924}]}]}
{"op":"mcm","clk":"11794042139","pt":1723080930634,"mc":[{"id":"1.231502182","rc":[{"batb":[[0,2.18,7.1],[1,2.16,38.28],[2,1.74,17.32]],"ltp":2.18,"tv":375.64,"id":26354927}]}]}
{"op":"mcm","clk":"11794042306","pt":1723080933357,"mc":[{"id":"1.231502182","rc":[{"batb":[[1,1.74,17.32],[2,1.7,10]],"ltp":2.18,"tv":375.64,"id":26354927}]}]}
{"op":"mcm","clk":"11794043763","pt":1723080960988,"mc":[{"id":"1.231502182","rc":[{"batl":[[0,1.84,7.46],[1,1.85,91],[2,1.86,33]],"ltp":1.85,"tv":1138.05,"id":26354924}]}]}
{"op":"mcm","clk":"11794045747","pt":1723081004105,"mc":[{"id":"1.231502182","rc":[{"batl":[[0,1.84,15.49]],"ltp":1.85,"tv":1138.05,"id":26354924}]}]}
{"op":"mcm","clk":"11794054504","pt":1723081170911,"mc":[{"id":"1.231502182","rc":[{"batl":[[0,1.84,20.36]],"ltp":1.85,"tv":1138.05,"id":26354924}]}]}
{"op":"mcm","clk":"11794127756","pt":1723082909153,"mc":[{"id":"1.231502182","rc":[{"trd":[[1.4,255.41],[2.12,29.61],[2.2,19.25]],"batb":[[0,2.18,7.1]],"batl":[[0,2.22,20.16]],"ltp":2.18,"tv":375.48,"id":26354927},{"trd":[[1.4,255.96],[1.82,61.77],[1.83,205.8],[1.84,41.54],[1.85,123.22],[1.86,29.32]],"batb":[[0,1.82,6.49]],"batl":[[0,1.84,20.36],[1,1.86,33],[2,1.88,820.18]],"ltp":1.85,"tv":1137.87,"id":26354924}],"tv":1513.36}]}
{"op":"mcm","clk":"11794127788","pt":1723082910139,"mc":[{"id":"1.231502182","rc":[{"batl":[[0,1.84,12.9]],"ltp":1.85,"tv":1137.87,"id":26354924}]}]}
{"op":"mcm","clk":"11794127832","pt":1723082911435,"mc":[{"id":"1.231502182","rc":[{"batb":[[0,1.75,10]],"ltp":2.18,"tv":375.48,"id":26354927},{"batl":[[0,1.84,8.02]],"ltp":1.85,"tv":1137.87,"id":26354924}]}]}
{"op":"mcm","clk":"11794127878","pt":1723082912938,"mc":[{"id":"1.231502182","rc":[{"batb":[[0,2.16,38.28],[1,1.75,10],[2,1.74,17.32]],"ltp":2.18,"tv":375.48,"id":26354927},{"batl":[[0,1.86,33],[1,1.88,820.18],[2,1.89,97.65]],"ltp":1.85,"tv":1137.87,"id":26354924}]}]}
{"op":"mcm","clk":"11794127940","pt":1723082914745,"mc":[{"id":"1.231502182","rc":[{"batb":[[1,1.74,17.32],[2,1.7,10]],"ltp":2.18,"tv":375.48,"id":26354927}]}]}
{"op":"mcm","clk":"11794129053","pt":1723082951599,"mc":[{"id":"1.231502182","rc":[{"batb":[[0,2.18,77.25],[1,2.16,38.28],[2,1.74,17.32]],"batl":[[0,2.22,14.92]],"ltp":2.18,"tv":375.48,"id":26354927},{"batl":[[0,1.84,4.47],[1,1.86,33],[2,1.88,820.18]],"ltp":1.85,"tv":1137.87,"id":26354924}]}]}
{"op":"mcm","clk":"11794129066","pt":1723082952123,"mc":[{"id":"1.231502182","rc":[{"batl":[[0,1.84,11.65]],"ltp":1.85,"tv":1137.87,"id":26354924}]}]}
{"op":"mcm","clk":"11794129110","pt":1723082953408,"mc":[{"id":"1.231502182","rc":[{"batb":[[1,1.74,17.32],[2,1.7,10]],"ltp":2.18,"tv":375.48,"id":26354927}]}]}
{"op":"mcm","clk":"11794130597","pt":1723082996353,"mc":[{"id":"1.231502182","rc":[{"batl":[[0,1.84,18.49]],"ltp":1.85,"tv":1137.87,"id":26354924}]}]}
{"op":"mcm","clk":"11794229853","pt":1723085653966,"mc":[{"id":"1.231502182","rc":[{"batl":[[0,2.22,7.46]],"ltp":2.18,"tv":375.48,"id":26354927},{"trd":[[1.82,74.75]],"batb":[[0,1.81,122.94],[1,1.8,309.67],[2,1.79,259.67]],"batl":[[0,1.82,31.91],[1,1.84,11.65],[2,1.86,33]],"ltp":1.82,"tv":1150.85,"id":26354924}],"tv":1526.34}]}
{"op":"mcm","clk":"11794229869","pt":1723085654480,"mc":[{"id":"1.231502182","rc":[{"batl":[[0,1.82,38.4],[1,1.84,7.18]],"ltp":1.82,"tv":1150.85,"id":26354924}]}]}
{"op":"mcm","clk":"11794229893","pt":1723085655357,"mc":[{"id":"1.231502182","rc":[{"batb":[[1,2.16,38.28],[2,1.74,17.32]],"ltp":2.18,"tv":375.48,"id":26354927},{"batb":[[2,1.79,315.88]],"ltp":1.82,"tv":1150.85,"id":26354924}]}]}
{"op":"mcm","clk":"11794229917","pt":1723085656280,"mc":[{"id":"1.231502182","rc":[{"batl":[[1,1.86,33],[2,1.88,820.18]],"ltp":1.82,"tv":1150.85,"id":26354924}]}]}
{"op":"mcm","clk":"11794230239","pt":1723085666964,"mc":[{"id":"1.231502182","rc":[{"trd":[[1.82,151.54]],"batb":[[0,1.82,412.41],[1,1.81,122.94],[2,1.8,309.67]],"batl":[[0,1.84,11.31]],"ltp":1.82,"tv":1227.65,"id":26354924}],"tv":1603.13}]}
{"op":"mcm","clk":"11794230365","pt":1723085670578,"mc":[{"id":"1.231502182","rc":[{"batb":[[1,1.74,17.32],[2,1.7,10]],"ltp":2.18,"tv":375.48,"id":26354927}]}]}
{"op":"mcm","clk":"11794230417","pt":1723085672003,"mc":[{"id":"1.231502182","rc":[{"trd":[[1.82,343.56]],"batb":[[0,1.82,316.4]],"ltp":1.82,"tv":1419.67,"id":26354924}],"tv":1795.15}]}
{"op":"mcm","clk":"11794230555","pt":1723085675965,"mc":[{"id":"1.231502182","rc":[{"trd":[[1.82,535.58]],"batb":[[0,1.82,220.39]],"ltp":1.82,"tv":1611.69,"id":26354924}],"tv":1987.17}]}
{"op":"mcm","clk":"11794230754","pt":1723085681775,"mc":[{"id":"1.231502182","rc":[{"trd":[[1.82,727.6]],"batb":[[0,1.82,124.38]],"ltp":1.82,"tv":1803.71,"id":26354924}],"tv":2179.19}]}
{"op":"mcm","clk":"11794230928","pt":1723085687594,"mc":[{"id":"1.231502182","rc":[{"trd":[[1.82,919.62]],"batb":[[0,1.82,28.37]],"ltp":1.82,"tv":1995.73,"id":26354924}],"tv":2371.21}]}
{"op":"mcm","clk":"11794231202","pt":1723085695626,"mc":[{"id":"1.231502182","rc":[{"batb":[[1,2.16,38.28],[2,1.74,17.32]],"ltp":2.18,"tv":375.48,"id":26354927},{"trd":[[1.82,976.36]],"batb":[[0,1.81,122.94],[1,1.8,309.67],[2,1.79,315.88]],"batl":[[0,1.82,67.64],[1,1.84,11.31],[2,1.86,33]],"ltp":1.82,"tv":2052.47,"id":26354924}],"tv":2427.95}]}
{"op":"mcm","clk":"11794231236","pt":1723085696393,"mc":[{"id":"1.231502182","rc":[{"batl":[[1,1.84,4.47]],"ltp":1.82,"tv":2052.47,"id":26354924}]}]}
{"op":"mcm","clk":"11794231295","pt":1723085698135,"mc":[{"id":"1.231502182","rc":[{"batl":[[1,1.86,33],[2,1.88,820.18]],"ltp":1.82,"tv":2052.47,"id":26354924}]}]}
{"op":"mcm","clk":"11794231484","pt":1723085703349,"mc":[{"id":"1.231502182","rc":[{"trd":[[1.82,1111.64]],"batb":[[0,1.82,383.17],[1,1.81,122.94],[2,1.8,309.67]],"batl":[[0,1.86,33],[1,1.88,820.18],[2,1.89,97.65]],"ltp":1.82,"tv":2187.75,"id":26354924}],"tv":2563.23}]}
{"op":"mcm","clk":"11794231577","pt":1723085705824,"mc":[{"id":"1.231502182","rc":[{"batb":[[1,1.74,17.32],[2,1.7,10]],"ltp":2.18,"tv":375.48,"id":26354927}]}]}
{"op":"mcm","clk":"11794231690","pt":1723085709110,"mc":[{"id":"1.231502182","rc":[{"trd":[[1.82,1303.66]],"batb":[[0,1.82,287.16]],"ltp":1.82,"tv":2379.77,"id":26354924}],"tv":2755.25}]}
{"op":"mcm","clk":"11794231737","pt":1723085710544,"mc":[{"id":"1.231502182","rc":[{"batl":[[0,1.84,6.84],[1,1.86,33],[2,1.88,820.18]],"ltp":1.82,"tv":2379.77,"id":26354924}]}]}
{"op":"mcm","clk":"11794231827","pt":1723085713216,"mc":[{"id":"1.231502182","rc":[{"trd":[[1.82,1495.68]],"batb":[[0,1.82,191.15]],"ltp":1.82,"tv":2571.79,"id":26354924}],"tv":2947.27}]}
{"op":"mcm","clk":"11794233324","pt":1723085753903,"mc":[{"id":"1.231502182","rc":[{"batl":[[0,1.84,14.19]],"ltp":1.82,"tv":2571.79,"id":26354924}]}]}
{"op":"mcm","clk":"11794233352","pt":1723085754678,"mc":[{"id":"1.231502182","rc":[{"batb":[[0,2.18,81.25]],"batl":[[0,2.22,11.46]],"ltp":2.18,"tv":375.48,"id":26354927},{"batb":[[0,1.83,4],[1,1.82,195.15],[2,1.81,122.94]],"ltp":1.82,"tv":2571.79,"id":26354924}]}]}
{"op":"mcm","clk":"11794233854","pt":1723085769793,"mc":[{"id":"1.231502182","rc":[{"batl":[[0,1.84,18.19]],"ltp":1.82,"tv":2571.79,"id":26354924}]}]}
{"op":"mcm","clk":"11794233886","pt":1723085770618,"mc":[{"id":"1.231502182","rc":[{"batb":[[0,1.82,195.15],[1,1.81,122.94],[2,1.8,309.67]],"batl":[[0,1.84,14.19]],"ltp":1.82,"tv":2571.79,"id":26354924}]}]}
{"op":"mcm","clk":"11794234059","pt":1723085776220,"mc":[{"id":"1.231502182","rc":[{"batl":[[0,1.84,18.89]],"ltp":1.82,"tv":2571.79,"id":26354924}]}]}
{"op":"mcm","clk":"11794234348","pt":1723085784816,"mc":[{"id":"1.231502182","rc":[{"batb":[[0,1.83,4],[1,1.82,195.15],[2,1.81,122.94]],"ltp":1.82,"tv":2571.79,"id":26354924}]}]}
{"op":"mcm","clk":"11794234837","pt":1723085799924,"mc":[{"id":"1.231502182","rc":[{"batl":[[0,1.84,22.89]],"ltp":1.82,"tv":2571.79,"id":26354924}]}]}
{"op":"mcm","clk":"11794234864","pt":1723085800745,"mc":[{"id":"1.231502182","rc":[{"batb":[[0,1.82,195.15],[1,1.81,122.94],[2,1.8,309.67]],"batl":[[0,1.84,18.89]],"ltp":1.82,"tv":2571.79,"id":26354924}]}]}
{"op":"mcm","clk":"11794235360","pt":1723085814960,"mc":[{"id":"1.231502182","rc":[{"batb":[[0,1.83,4],[1,1.82,195.15],[2,1.81,122.94]],"ltp":1.82,"tv":2571.79,"id":26354924}]}]}
{"op":"mcm","clk":"11794235988","pt":1723085830594,"mc":[{"id":"1.231502182","rc":[{"batb":[[0,1.82,195.15],[1,1.81,122.94],[2,1.8,309.67]],"batl":[[0,1.84,18.19]],"ltp":1.82,"tv":2571.79,"id":26354924}]}]}
{"op":"mcm","clk":"11794236021","pt":1723085831155,"mc":[{"id":"1.231502182","rc":[{"batl":[[0,1.84,14.19]],"ltp":1.82,"tv":2571.79,"id":26354924}]}]}
{"op":"mcm","clk":"11794236586","pt":1723085845158,"mc":[{"id":"1.231502182","rc":[{"batb":[[0,1.83,4],[1,1.82,195.15],[2,1.81,122.94]],"ltp":1.82,"tv":2571.79,"id":26354924}]}]}
{"op":"mcm","clk":"11794237120","pt":1723085860596,"mc":[{"id":"1.231502182","rc":[{"batb":[[0,1.82,195.15],[1,1.81,122.94],[2,1.8,309.67]],"batl":[[0,1.84,18.19]],"ltp":1.82,"tv":2571.79,"id":26354924}]}]}
{"op":"mcm","clk":"11794237142","pt":1723085861215,"mc":[{"id":"1.231502182","rc":[{"batl":[[0,1.84,14.19]],"ltp":1.82,"tv":2571.79,"id":26354924}]}]}
{"op":"mcm","clk":"11794237632","pt":1723085875337,"mc":[{"id":"1.231502182","rc":[{"batb":[[0,1.83,4],[1,1.82,195.15],[2,1.81,122.94]],"ltp":1.82,"tv":2571.79,"id":26354924}]}]}
{"op":"mcm","clk":"11794238143","pt":1723085890943,"mc":[{"id":"1.231502182","rc":[{"batb":[[0,1.82,195.15],[1,1.81,122.94],[2,1.8,309.67]],"batl":[[0,1.84,18.19]],"ltp":1.82,"tv":2571.79,"id":26354924}]}]}
{"op":"mcm","clk":"11794238159","pt":1723085891405,"mc":[{"id":"1.231502182","rc":[{"batl":[[0,1.84,14.19]],"ltp":1.82,"tv":2571.79,"id":26354924}]}]}
{"op":"mcm","clk":"11794238274","pt":1723085895006,"mc":[{"id":"1.231502182","rc":[{"batl":[[0,1.84,18.89]],"ltp":1.82,"tv":2571.79,"id":26354924}]}]}
{"op":"mcm","clk":"11794238620","pt":1723085905456,"mc":[{"id":"1.231502182","rc":[{"batb":[[0,1.83,4],[1,1.82,195.15],[2,1.81,122.94]],"ltp":1.82,"tv":2571.79,"id":26354924}]}]}
