{"op":"mcm","clk":"11833142883","pt":1723108868521,"mc":[{"id":"1.231582198","marketDefinition":{"bspMarket":false,"turnInPlayEnabled":true,"persistenceEnabled":true,"marketBaseRate":5.0,"eventId":"33477752","eventTypeId":"4","numberOfWinners":1,"bettingType":"ODDS","marketType":"MATCH_ODDS","marketTime":"2024-08-11T10:00:00.000Z","suspendTime":"2024-08-11T10:00:00.000Z","bspReconciled":false,"complete":true,"inPlay":false,"crossMatching":false,"runnersVoidable":false,"numberOfActiveRunners":2,"betDelay":0,"status":"OPEN","runners":[{"status":"ACTIVE","sortPriority":1,"id":2780,"name":"Nottinghamshire"},{"status":"ACTIVE","sortPriority":2,"id":31376,"name":"Essex"}],"regulators":["MR_INT"],"countryCode":"GB","discountAllowed":false,"timezone":"GMT","openDate":"2024-08-11T10:00:00.000Z","version":6061697186,"name":"Match Odds","eventName":"Nottinghamshire v Essex"},"rc":[{"batb":[[0,1.01,20]],"ltp":0.0,"tv":0.0,"id":2780},{"batb":[[0,1.01,20]],"ltp":0.0,"tv":0.0,"id":31376}]}]}
{"op":"mcm","clk":"11833142924","pt":1723108869131,"mc":[{"id":"1.231582198","marketDefinition":{"bspMarket":false,"turnInPlayEnabled":true,"persistenceEnabled":true,"marketBaseRate":5.0,"eventId":"33477752","eventTypeId":"4","numberOfWinners":1,"bettingType":"ODDS","marketType":"MATCH_ODDS","marketTime":"2024-08-11T10:00:00.000Z","suspendTime":"2024-08-11T10:00:00.000Z","bspReconciled":false,"complete":true,"inPlay":false,"crossMatching":false,"runnersVoidable":false,"numberOfActiveRunners":2,"betDelay":0,"status":"OPEN","runners":[{"status":"ACTIVE","sortPriority":1,"id":2780,"name":"Nottinghamshire"},{"status":"ACTIVE","sortPriority":2,"id":31376,"name":"Essex"}],"regulators":["MR_INT"],"countryCode":"GB","discountAllowed":true,"timezone":"GMT","openDate":"2024-08-11T10:00:00.000Z","version":6061697186,"name":"Match Odds","eventName":"Nottinghamshire v Essex"},"rc":[{"batb":[[0,1.01,220]],"ltp":0.0,"tv":0.0,"id":2780},{"batb":[[0,1.01,220]],"ltp":0.0,"tv":0.0,"id":31376}]}]}
{"op":"mcm","clk":"11833142963","pt":1723108869759,"mc":[{"id":"1.231582198","rc":[{"batb":[[0,1.03,200],[1,1.02,200],[2,1.01,220]],"ltp":0.0,"tv":0.0,"id":2780},{"batb":[[0,1.03,200],[1,1.02,200],[2,1.01,220]],"ltp":0.0,"tv":0.0,"id":31376}]}]}
{"op":"mcm","clk":"11833424946","pt":1723113946933,"mc":[{"id":"1.231582198","rc":[{"batb":[[2,1.01,227.89]],"ltp":0.0,"tv":0.0,"id":2780},{"batb":[[2,1.01,227.89]],"ltp":0.0,"tv":0.0,"id":31376}]}]}
{"op":"mcm","clk":"11833425616","pt":1723113961638,"mc":[{"id":"1.231582198","rc":[{"batb":[[1,1.02,207.89]],"ltp":0.0,"tv":0.0,"id":2780},{"batb":[[1,1.02,207.89]],"ltp":0.0,"tv":0.0,"id":31376}]}]}
{"op":"mcm","clk":"11833426429","pt":1723113975666,"mc":[{"id":"1.231582198","rc":[{"batb":[[0,1.03,207.89]],"ltp":0.0,"tv":0.0,"id":2780},{"batb":[[0,1.03,207.89]],"ltp":0.0,"tv":0.0,"id":31376}]}]}
{"op":"mcm","clk":"11833427584","pt":1723113996300,"mc":[{"id":"1.231582198","rc":[{"batb":[[1,1.02,247.34]],"ltp":0.0,"tv":0.0,"id":2780},{"batb":[[1,1.02,247.34]],"ltp":0.0,"tv":0.0,"id":31376}]}]}
{"op":"mcm","clk":"11833428622","pt":1723114017820,"mc":[{"id":"1.231582198","rc":[{"batb":[[0,1.04,7.89],[1,1.03,207.89],[2,1.02,247.34]],"ltp":0.0,"tv":0.0,"id":2780},{"batb":[[0,1.04,7.89],[1,1.03,207.89],[2,1.02,247.34]],"ltp":0.0,"tv":0.0,"id":31376}]}]}
{"op":"mcm","clk":"11833429233","pt":1723114029343,"mc":[{"id":"1.231582198","rc":[{"batb":[[0,1.05,7.89],[1,1.04,7.89],[2,1.03,207.89]],"ltp":0.0,"tv":0.0,"id":2780},{"batb":[[0,1.05,7.89],[1,1.04,7.89],[2,1.03,207.89]],"ltp":0.0,"tv":0.0,"id":31376}]}]}
{"op":"mcm","clk":"11833430071","pt":1723114045456,"mc":[{"id":"1.231582198","rc":[{"batb":[[0,1.06,7.89],[1,1.05,7.89],[2,1.04,7.89]],"ltp":0.0,"tv":0.0,"id":2780},{"batb":[[0,1.06,7.89],[1,1.05,7.89],[2,1.04,7.89]],"ltp":0.0,"tv":0.0,"id":31376}]}]}
{"op":"mcm","clk":"11833430974","pt":1723114062970,"mc":[{"id":"1.231582198","rc":[{"batb":[[0,1.07,7.89],[1,1.06,7.89],[2,1.05,7.89]],"ltp":0.0,"tv":0.0,"id":2780},{"batb":[[0,1.07,7.89],[1,1.06,7.89],[2,1.05,7.89]],"ltp":0.0,"tv":0.0,"id":31376}]}]}
{"op":"mcm","clk":"11833431724","pt":1723114076667,"mc":[{"id":"1.231582198","rc":[{"batb":[[0,1.08,7.89],[1,1.07,7.89],[2,1.06,7.89]],"ltp":0.0,"tv":0.0,"id":2780},{"batb":[[0,1.08,7.89],[1,1.07,7.89],[2,1.06,7.89]],"ltp":0.0,"tv":0.0,"id":31376}]}]}
{"op":"mcm","clk":"11833529327","pt":1723115575161,"mc":[{"id":"1.231582198","rc":[{"batb":[[0,1.08,7.88],[1,1.07,7.88],[2,1.06,7.88]],"ltp":0.0,"tv":0.0,"id":2780},{"batb":[[0,1.08,7.88],[1,1.07,7.88],[2,1.06,7.88]],"ltp":0.0,"tv":0.0,"id":31376}]}]}
{"op":"mcm","clk":"11833543126","pt":1723115799113,"mc":[{"id":"1.231582198","marketDefinition":{"bspMarket":false,"turnInPlayEnabled":true,"persistenceEnabled":true,"marketBaseRate":5.0,"eventId":"33477752","eventTypeId":"4","numberOfWinners":1,"bettingType":"ODDS","marketType":"MATCH_ODDS","marketTime":"2024-08-11T10:00:00.000Z","suspendTime":"2024-08-11T10:00:00.000Z","bspReconciled":false,"complete":true,"inPlay":false,"crossMatching":true,"runnersVoidable":false,"numberOfActiveRunners":2,"betDelay":0,"status":"OPEN","runners":[{"status":"ACTIVE","sortPriority":1,"id":2780,"name":"Nottinghamshire"},{"status":"ACTIVE","sortPriority":2,"id":31376,"name":"Essex"}],"regulators":["MR_INT"],"countryCode":"GB","discountAllowed":true,"timezone":"GMT","openDate":"2024-08-11T10:00:00.000Z","version":6061697186,"name":"Match Odds","eventName":"Nottinghamshire v Essex"}}]}
{"op":"mcm","clk":"11833846950","pt":1723120975184,"mc":[{"id":"1.231582198","rc":[{"batb":[[0,1.08,7.88],[1,1.07,7.88],[2,1.06,7.88]],"ltp":0.0,"tv":0.0,"id":2780},{"batb":[[0,1.08,7.88],[1,1.07,7.88],[2,1.06,7.88]],"ltp":0.0,"tv":0.0,"id":31376}]}]}
{"op":"mcm","clk":"11834136168","pt":1723126375193,"mc":[{"id":"1.231582198","rc":[{"batb":[[0,1.08,7.87],[1,1.07,7.87],[2,1.06,7.87]],"ltp":0.0,"tv":0.0,"id":2780},{"batb":[[0,1.08,7.87],[1,1.07,7.87],[2,1.06,7.87]],"ltp":0.0,"tv":0.0,"id":31376}]}]}
{"op":"mcm","clk":"11834342123","pt":1723129859795,"mc":[{"id":"1.231582198","rc":[{"batb":[[0,1.25,100],[1,1.08,7.86],[2,1.07,7.86]],"ltp":0.0,"tv":0.0,"id":2780},{"batb":[[0,1.25,100],[1,1.08,7.86],[2,1.07,7.86]],"ltp":0.0,"tv":0.0,"id":31376}]}]}
{"op":"mcm","clk":"11835138547","pt":1723137175192,"mc":[{"id":"1.231582198","rc":[{"batb":[[1,1.08,7.85],[2,1.07,7.85]],"ltp":0.0,"tv":0.0,"id":2780},{"batb":[[1,1.08,7.85],[2,1.07,7.85]],"ltp":0.0,"tv":0.0,"id":31376}]}]}
{"op":"mcm","clk":"11835347388","pt":1723138587651,"mc":[{"id":"1.231582198","rc":[{"batb":[[0,1.27,2.18],[1,1.25,100],[2,1.08,7.85]],"ltp":0.0,"tv":0.0,"id":2780}]}]}
{"op":"mcm","clk":"11835349321","pt":1723138599399,"mc":[{"id":"1.231582198","rc":[{"batb":[[0,1.27,3.14]],"ltp":0.0,"tv":0.0,"id":2780}]}]}
{"op":"mcm","clk":"11835351494","pt":1723138612414,"mc":[{"id":"1.231582198","rc":[{"batb":[[0,1.26,1.66],[1,1.25,100],[2,1.08,7.85]],"ltp":0.0,"tv":0.0,"id":31376}]}]}
{"op":"mcm","clk":"11835353142","pt":1723138622416,"mc":[{"id":"1.231582198","rc":[{"batb":[[0,1.26,2.62]],"ltp":0.0,"tv":0.0,"id":31376}]}]}
{"op":"mcm","clk":"11836036722","pt":1723142575249,"mc":[{"id":"1.231582198","rc":[{"batb":[[0,1.27,3.14],[2,1.08,7.85]],"ltp":0.0,"tv":0.0,"id":2780},{"batb":[[0,1.26,2.62],[2,1.08,7.85]],"ltp":0.0,"tv":0.0,"id":31376}]}]}
{"op":"mcm","clk":"11836849520","pt":1723151744964,"mc":[{"id":"1.231582198","rc":[{"batb":[[0,1.27,3.14],[2,1.08,7.84]],"ltp":0.0,"tv":0.0,"id":2780},{"batb":[[0,1.26,2.62],[2,1.08,7.84]],"ltp":0.0,"tv":0.0,"id":31376}]}]}
{"op":"mcm","clk":"11837126249","pt":1723158775185,"mc":[{"id":"1.231582198","rc":[{"batb":[[0,1.27,3.14],[2,1.08,7.85]],"ltp":0.0,"tv":0.0,"id":2780},{"batb":[[0,1.26,2.62],[2,1.08,7.85]],"ltp":0.0,"tv":0.0,"id":31376}]}]}
{"op":"mcm","clk":"11837360313","pt":1723164175193,"mc":[{"id":"1.231582198","rc":[{"batb":[[2,1.08,7.84]],"ltp":0.0,"tv":0.0,"id":2780},{"batb":[[2,1.08,7.84]],"ltp":0.0,"tv":0.0,"id":31376}]}]}
{"op":"mcm","clk":"11837584861","pt":1723169575208,"mc":[{"id":"1.231582198","rc":[{"batb":[[0,1.27,3.14],[2,1.08,7.84]],"ltp":0.0,"tv":0.0,"id":2780},{"batb":[[0,1.26,2.62],[2,1.08,7.84]],"ltp":0.0,"tv":0.0,"id":31376}]}]}
{"op":"mcm","clk":"11837806879","pt":1723174975229,"mc":[{"id":"1.231582198","rc":[{"batb":[[0,1.27,3.14],[2,1.08,7.84]],"ltp":0.0,"tv":0.0,"id":2780},{"batb":[[2,1.08,7.84]],"ltp":0.0,"tv":0.0,"id":31376}]}]}
{"op":"mcm","clk":"11838037931","pt":1723180375223,"mc":[{"id":"1.231582198","rc":[{"batb":[[0,1.27,3.14],[2,1.08,7.84]],"ltp":0.0,"tv":0.0,"id":2780},{"batb":[[0,1.26,2.62],[2,1.08,7.84]],"ltp":0.0,"tv":0.0,"id":31376}]}]}
{"op":"mcm","clk":"11838272949","pt":1723185775270,"mc":[{"id":"1.231582198","rc":[{"batb":[[0,1.27,3.14],[2,1.08,7.84]],"ltp":0.0,"tv":0.0,"id":2780},{"batb":[[2,1.08,7.84]],"ltp":0.0,"tv":0.0,"id":31376}]}]}
{"op":"mcm","clk":"11838479469","pt":1723189566441,"mc":[{"id":"1.231582198","rc":[{"batb":[[0,1.27,3.13],[2,1.08,7.83]],"batl":[[0,1000,1]],"ltp":0.0,"tv":0.0,"id":2780},{"batb":[[0,1.26,2.61],[2,1.08,7.83]],"batl":[[0,1000,1]],"ltp":0.0,"tv":0.0,"id":31376}]}]}
{"op":"mcm","clk":"11838479472","pt":1723189566540,"mc":[{"id":"1.231582198","rc":[{"batl":[[0,1000,0.02]],"ltp":0.0,"tv":0.0,"id":2780},{"batl":[[0,1000,0.02]],"ltp":0.0,"tv":0.0,"id":31376}]}]}
{"op":"mcm","clk":"11838578654","pt":1723191175259,"mc":[{"id":"1.231582198","rc":[{"batb":[[0,1.27,3.13],[2,1.08,7.84]],"ltp":0.0,"tv":0.0,"id":2780},{"batb":[[0,1.26,2.62],[2,1.08,7.84]],"ltp":0.0,"tv":0.0,"id":31376}]}]}
{"op":"mcm","clk":"11838865887","pt":1723196575264,"mc":[{"id":"1.231582198","rc":[{"batb":[[2,1.08,7.83]],"ltp":0.0,"tv":0.0,"id":2780},{"batb":[[2,1.08,7.83]],"ltp":0.0,"tv":0.0,"id":31376}]}]}
{"op":"mcm","clk":"11839232325","pt":1723201975265,"mc":[{"id":"1.231582198","rc":[{"batb":[[0,1.27,3.14],[2,1.08,7.85]],"ltp":0.0,"tv":0.0,"id":2780},{"batb":[[0,1.26,2.62],[2,1.08,7.85]],"ltp":0.0,"tv":0.0,"id":31376}]}]}
{"op":"mcm","clk":"11839690450","pt":1723207375317,"mc":[{"id":"1.231582198","rc":[{"batb":[[2,1.08,7.85]],"ltp":0.0,"tv":0.0,"id":2780},{"batb":[[2,1.08,7.85]],"ltp":0.0,"tv":0.0,"id":31376}]}]}
{"op":"mcm","clk":"11840174921","pt":1723212775328,"mc":[{"id":"1.231582198","rc":[{"batb":[[2,1.08,7.85]],"ltp":0.0,"tv":0.0,"id":2780},{"batb":[[2,1.08,7.85]],"ltp":0.0,"tv":0.0,"id":31376}]}]}
{"op":"mcm","clk":"11840730950","pt":1723218175328,"mc":[{"id":"1.231582198","rc":[{"batb":[[0,1.27,3.13],[2,1.08,7.84]],"ltp":0.0,"tv":0.0,"id":2780},{"batb":[[0,1.26,2.61],[2,1.08,7.84]],"ltp":0.0,"tv":0.0,"id":31376}]}]}
{"op":"mcm","clk":"11841163622","pt":1723221507329,"mc":[{"id":"1.231582198","rc":[{"batb":[[1,1.08,7.84],[2,1.07,7.84]],"ltp":0.0,"tv":0.0,"id":2780},{"batb":[[1,1.08,7.84],[2,1.07,7.84]],"ltp":0.0,"tv":0.0,"id":31376}]}]}
{"op":"mcm","clk":"11841171691","pt":1723221558489,"mc":[{"id":"1.231582198","rc":[{"batb":[[0,1.33,75.76],[1,1.28,90.25],[2,1.27,2.18]],"ltp":0.0,"tv":0.0,"id":2780},{"batb":[[0,1.28,90.25],[1,1.26,1.66],[2,1.23,108.7]],"ltp":0.0,"tv":0.0,"id":31376}]}]}
{"op":"mcm","clk":"11841171749","pt":1723221558804,"mc":[{"id":"1.231582198","rc":[{"batb":[[0,1.48,52.08],[1,1.43,58.14],[2,1.38,65.79]],"ltp":0.0,"tv":0.0,"id":2780},{"batb":[[0,1.48,52.08],[1,1.43,58.14],[2,1.38,65.79]],"ltp":0.0,"tv":0.0,"id":31376}]}]}
{"op":"mcm","clk":"11841306753","pt":1723222457499,"mc":[{"id":"1.231582198","rc":[{"batb":[[0,1.49,7.6],[1,1.48,52.08],[2,1.43,58.14]],"ltp":0.0,"tv":0.0,"id":2780},{"batb":[[0,1.49,7.36],[1,1.48,52.08],[2,1.43,58.14]],"ltp":0.0,"tv":0.0,"id":31376}]}]}
{"op":"mcm","clk":"11841508451","pt":1723223575434,"mc":[{"id":"1.231582198","rc":[{"batb":[[0,1.49,7.6]],"ltp":0.0,"tv":0.0,"id":2780},{"batb":[[0,1.49,7.36]],"ltp":0.0,"tv":0.0,"id":31376}]}]}
{"op":"mcm","clk":"11841736517","pt":1723224821199,"mc":[{"id":"1.231582198","rc":[{"batb":[[0,1.69,60.56],[1,1.49,7.6],[2,1.48,52.08]],"ltp":0.0,"tv":0.0,"id":2780},{"batb":[[0,2.34,31.18],[1,1.49,7.36],[2,1.48,52.08]],"ltp":0.0,"tv":0.0,"id":31376}]}]}
{"op":"mcm","clk":"11841962366","pt":1723226039336,"mc":[{"id":"1.231582198","rc":[{"batb":[[1,1.48,52.08],[2,1.43,58.14]],"ltp":0.0,"tv":0.0,"id":2780},{"batb":[[1,1.48,52.08],[2,1.43,58.14]],"ltp":0.0,"tv":0.0,"id":31376}]}]}
{"op":"mcm","clk":"11846418802","pt":1723278734698,"mc":[{"id":"1.231582198","rc":[{"batb":[[1,1.08,7.85],[2,1.07,7.85]],"ltp":0.0,"tv":0.0,"id":2780},{"batb":[[1,1.08,7.85],[2,1.07,7.85]],"ltp":0.0,"tv":0.0,"id":31376}]}]}
{"op":"mcm","clk":"11846442307","pt":1723278979218,"mc":[{"id":"1.231582198","rc":[{"batb":[[1,1.25,1200],[2,1.08,7.85]],"ltp":0.0,"tv":0.0,"id":2780},{"batb":[[1,1.25,1200],[2,1.08,7.85]],"ltp":0.0,"tv":0.0,"id":31376}]}]}
{"op":"mcm","clk":"11846449840","pt":1723279056146,"mc":[{"id":"1.231582198","rc":[{"batb":[[1,1.08,7.85],[2,1.07,7.85]],"ltp":0.0,"tv":0.0,"id":2780},{"batb":[[1,1.08,7.85],[2,1.07,7.85]],"ltp":0.0,"tv":0.0,"id":31376}]}]}
{"op":"mcm","clk":"11846450184","pt":1723279059852,"mc":[{"id":"1.231582198","rc":[{"batb":[[1,1.3,1000],[2,1.08,7.85]],"ltp":0.0,"tv":0.0,"id":2780},{"batb":[[1,1.3,1000],[2,1.08,7.85]],"ltp":0.0,"tv":0.0,"id":31376}]}]}
{"op":"mcm","clk":"11849802102","pt":1723299707900,"mc":[{"id":"1.231582198","rc":[{"batb":[[0,1.69,56.58]],"ltp":0.0,"tv":0.0,"id":2780},{"batb":[[0,2.34,29.13]],"ltp":0.0,"tv":0.0,"id":31376}]}]}
{"op":"mcm","clk":"11851047220","pt":1723304541823,"mc":[{"id":"1.231582198","rc":[{"batl":[[0,1.85,100],[1,1000,0.02]],"ltp":0.0,"tv":0.0,"id":2780}]}]}
{"op":"mcm","clk":"11851047973","pt":1723304545094,"mc":[{"id":"1.231582198","rc":[{"batl":[[1,1.86,200],[2,1000,0.02]],"ltp":0.0,"tv":0.0,"id":2780}]}]}
{"op":"mcm","clk":"11851048742","pt":1723304548429,"mc":[{"id":"1.231582198","rc":[{"batl":[[2,1.87,300]],"ltp":0.0,"tv":0.0,"id":2780}]}]}
{"op":"mcm","clk":"11851895782","pt":1723309112825,"mc":[{"id":"1.231582198","rc":[{"batl":[[0,1.74,5],[1,1.85,100],[2,1.86,200]],"ltp":0.0,"tv":0.0,"id":2780}]}]}
{"op":"mcm","clk":"11852807149","pt":1723313774722,"mc":[{"id":"1.231582198","rc":[{"batl":[[0,2.7,5],[1,1000,0.02]],"ltp":0.0,"tv":0.0,"id":31376}]}]}
{"op":"mcm","clk":"11853833029","pt":1723320054730,"mc":[{"id":"1.231582198","rc":[{"batb":[[1,1.61,4.56],[2,1.3,1000]],"ltp":0.0,"tv":0.0,"id":2780}]}]}
{"op":"mcm","clk":"11853834672","pt":1723320065744,"mc":[{"id":"1.231582198","rc":[{"batb":[[2,1.56,4.56]],"ltp":0.0,"tv":0.0,"id":2780}]}]}
{"op":"mcm","clk":"11853838233","pt":1723320094364,"mc":[{"id":"1.231582198","rc":[{"batl":[[1,1.84,4.56],[2,1.85,100]],"ltp":0.0,"tv":0.0,"id":2780}]}]}
{"op":"mcm","clk":"11854361679","pt":1723323809034,"mc":[{"id":"1.231582198","rc":[{"batl":[[0,1.73,5]],"ltp":0.0,"tv":0.0,"id":2780}]}]}
{"op":"mcm","clk":"11854467932","pt":1723324997306,"mc":[{"id":"1.231582198","rc":[{"trd":[[1.69,3.32]],"batb":[[0,1.69,54.92]],"ltp":1.69,"tv":3.32,"id":2780}],"tv":3.32}]}
{"op":"mcm","clk":"11854468137","pt":1723324999378,"mc":[{"id":"1.231582198","rc":[{"batb":[[0,1.69,56.58]],"ltp":1.69,"tv":3.32,"id":2780}]}]}
{"op":"mcm","clk":"11856042707","pt":1723348358993,"mc":[{"id":"1.231582198","rc":[{"batb":[[1,1.62,25],[2,1.61,4.56]],"ltp":1.69,"tv":3.32,"id":2780}]}]}
{"op":"mcm","clk":"11856043550","pt":1723348382488,"mc":[{"id":"1.231582198","rc":[{"batl":[[0,1.73,20.5]],"ltp":1.69,"tv":3.32,"id":2780}]}]}
{"op":"mcm","clk":"11856575262","pt":1723359038709,"mc":[{"id":"1.231582198","rc":[{"trd":[[1.33,420.75],[1.51,9.12],[1.56,9.12],[1.58,8.55],[1.61,9.12],[1.62,50],[1.69,116.48]],"batb":[[0,1.34,161.06],[1,1.33,17.62],[2,1.3,1000]],"ltp":1.33,"tv":623.14,"id":2780},{"trd":[[2.7,5]],"batl":[[0,1000,0.02],[1,1000,0]],"ltp":2.7,"tv":5.0,"id":31376}],"tv":628.14}]}
{"op":"mcm","clk":"11856575436","pt":1723359042541,"mc":[{"id":"1.231582198","rc":[{"batb":[[0,1.65,60.06],[1,1.34,161.06],[2,1.33,17.62]],"ltp":1.33,"tv":623.14,"id":2780}]}]}
{"op":"mcm","clk":"11856576087","pt":1723359057932,"mc":[{"id":"1.231582198","rc":[{"batb":[[1,1.3,1000],[2,1.08,7.85]],"ltp":1.33,"tv":623.14,"id":2780}]}]}
{"op":"mcm","clk":"11856595128","pt":1723359407517,"mc":[{"id":"1.231582198","rc":[{"batb":[[1,1.39,8.76],[2,1.3,1007.21]],"ltp":1.33,"tv":623.14,"id":2780}]}]}
{"op":"mcm","clk":"11856607782","pt":1723359600420,"mc":[{"id":"1.231582198","rc":[{"batb":[[0,2.36,10],[1,2.34,29.13],[2,1.3,1000]],"ltp":2.7,"tv":5.0,"id":31376}]}]}
{"op":"mcm","clk":"11856608228","pt":1723359603738,"mc":[{"id":"1.231582198","rc":[{"batb":[[0,2.34,29.13],[1,1.3,1000],[2,1.08,7.85]],"ltp":2.7,"tv":5.0,"id":31376}]}]}
{"op":"mcm","clk":"11856608721","pt":1723359609044,"mc":[{"id":"1.231582198","rc":[{"batb":[[0,2.36,10],[1,2.34,29.13],[2,1.3,1000]],"ltp":2.7,"tv":5.0,"id":31376}]}]}
{"op":"mcm","clk":"11856609092","pt":1723359612556,"mc":[{"id":"1.231582198","rc":[{"batb":[[0,2.34,29.13],[1,1.3,1000],[2,1.08,7.85]],"ltp":2.7,"tv":5.0,"id":31376}]}]}
{"op":"mcm","clk":"11856609306","pt":1723359614759,"mc":[{"id":"1.231582198","rc":[{"batb":[[0,2.36,10],[1,2.34,29.13],[2,1.3,1000]],"ltp":2.7,"tv":5.0,"id":31376}]}]}
{"op":"mcm","clk":"11856609601","pt":1723359618062,"mc":[{"id":"1.231582198","rc":[{"batb":[[0,2.34,29.13],[1,1.3,1000],[2,1.08,7.85]],"ltp":2.7,"tv":5.0,"id":31376}]}]}
{"op":"mcm","clk":"11856609896","pt":1723359621686,"mc":[{"id":"1.231582198","rc":[{"batb":[[0,2.36,10],[1,2.34,29.13],[2,1.3,1000]],"ltp":2.7,"tv":5.0,"id":31376}]}]}
{"op":"mcm","clk":"11856610158","pt":1723359625077,"mc":[{"id":"1.231582198","rc":[{"batb":[[0,2.34,29.13],[1,1.3,1000],[2,1.08,7.85]],"ltp":2.7,"tv":5.0,"id":31376}]}]}
{"op":"mcm","clk":"11856610638","pt":1723359631999,"mc":[{"id":"1.231582198","rc":[{"batb":[[0,2.36,10],[1,2.34,29.13],[2,1.3,1000]],"ltp":2.7,"tv":5.0,"id":31376}]}]}
{"op":"mcm","clk":"11856610977","pt":1723359635616,"mc":[{"id":"1.231582198","rc":[{"batb":[[0,2.34,29.13],[1,1.3,1000],[2,1.08,7.85]],"ltp":2.7,"tv":5.0,"id":31376}]}]}
{"op":"mcm","clk":"11856611232","pt":1723359638896,"mc":[{"id":"1.231582198","rc":[{"batb":[[0,2.36,10],[1,2.34,29.13],[2,1.3,1000]],"ltp":2.7,"tv":5.0,"id":31376}]}]}
{"op":"mcm","clk":"11856611516","pt":1723359642200,"mc":[{"id":"1.231582198","rc":[{"batb":[[0,2.34,29.13],[1,1.3,1000],[2,1.08,7.85]],"ltp":2.7,"tv":5.0,"id":31376}]}]}
{"op":"mcm","clk":"11856611699","pt":1723359644506,"mc":[{"id":"1.231582198","rc":[{"batb":[[0,2.36,10],[1,2.34,29.13],[2,1.3,1000]],"ltp":2.7,"tv":5.0,"id":31376}]}]}
{"op":"mcm","clk":"11856611935","pt":1723359647799,"mc":[{"id":"1.231582198","rc":[{"batb":[[0,2.34,29.13],[1,1.3,1000],[2,1.08,7.85]],"ltp":2.7,"tv":5.0,"id":31376}]}]}
{"op":"mcm","clk":"11856612175","pt":1723359651132,"mc":[{"id":"1.231582198","rc":[{"batb":[[0,2.36,10],[1,2.34,29.13],[2,1.3,1000]],"ltp":2.7,"tv":5.0,"id":31376}]}]}
{"op":"mcm","clk":"11856612388","pt":1723359653732,"mc":[{"id":"1.231582198","rc":[{"batb":[[1,1.51,4.56],[2,1.39,8.76]],"ltp":1.33,"tv":623.14,"id":2780}]}]}
{"op":"mcm","clk":"11856612461","pt":1723359654707,"mc":[{"id":"1.231582198","rc":[{"batb":[[0,2.34,29.13],[1,1.3,1000],[2,1.08,7.85]],"ltp":2.7,"tv":5.0,"id":31376}]}]}
{"op":"mcm","clk":"11856612630","pt":1723359657142,"mc":[{"id":"1.231582198","rc":[{"batb":[[0,2.36,10],[1,2.34,29.13],[2,1.3,1000]],"ltp":2.7,"tv":5.0,"id":31376}]}]}
{"op":"mcm","clk":"11856612857","pt":1723359660328,"mc":[{"id":"1.231582198","rc":[{"batb":[[0,2.34,29.13],[1,1.3,1000],[2,1.08,7.85]],"ltp":2.7,"tv":5.0,"id":31376}]}]}
{"op":"mcm","clk":"11856613060","pt":1723359663106,"mc":[{"id":"1.231582198","rc":[{"batb":[[0,2.36,10],[1,2.34,29.13],[2,1.3,1000]],"ltp":2.7,"tv":5.0,"id":31376}]}]}
{"op":"mcm","clk":"11856613339","pt":1723359667217,"mc":[{"id":"1.231582198","rc":[{"batb":[[0,2.34,29.13],[1,1.3,1000],[2,1.08,7.85]],"ltp":2.7,"tv":5.0,"id":31376}]}]}
{"op":"mcm","clk":"11856613460","pt":1723359669418,"mc":[{"id":"1.231582198","rc":[{"batb":[[2,1.46,4.56]],"ltp":1.33,"tv":623.14,"id":2780},{"batb":[[0,2.36,10],[1,2.34,29.13],[2,1.3,1000]],"ltp":2.7,"tv":5.0,"id":31376}]}]}
{"op":"mcm","clk":"11856613482","pt":1723359669724,"mc":[{"id":"1.231582198","rc":[{"batb":[[2,1.46,13.32]],"ltp":1.33,"tv":623.14,"id":2780}]}]}
{"op":"mcm","clk":"11856613710","pt":1723359672854,"mc":[{"id":"1.231582198","rc":[{"batb":[[0,2.34,29.13],[1,1.3,1000],[2,1.08,7.85]],"ltp":2.7,"tv":5.0,"id":31376}]}]}
{"op":"mcm","clk":"11856613976","pt":1723359676558,"mc":[{"id":"1.231582198","rc":[{"batb":[[0,2.36,10],[1,2.34,29.13],[2,1.3,1000]],"ltp":2.7,"tv":5.0,"id":31376}]}]}
{"op":"mcm","clk":"11856614193","pt":1723359679839,"mc":[{"id":"1.231582198","rc":[{"batb":[[0,2.34,29.13],[1,1.3,1000],[2,1.08,7.85]],"ltp":2.7,"tv":5.0,"id":31376}]}]}
{"op":"mcm","clk":"11856614324","pt":1723359681635,"mc":[{"id":"1.231582198","rc":[{"batb":[[1,1.56,4.56],[2,1.51,4.56]],"ltp":1.33,"tv":623.14,"id":2780}]}]}
{"op":"mcm","clk":"11856614430","pt":1723359682869,"mc":[{"id":"1.231582198","rc":[{"batb":[[0,2.36,10],[1,2.34,29.13],[2,1.3,1000]],"ltp":2.7,"tv":5.0,"id":31376}]}]}
{"op":"mcm","clk":"11856614671","pt":1723359686252,"mc":[{"id":"1.231582198","rc":[{"batb":[[0,2.34,29.13],[1,1.3,1000],[2,1.08,7.85]],"ltp":2.7,"tv":5.0,"id":31376}]}]}
{"op":"mcm","clk":"11856614900","pt":1723359689945,"mc":[{"id":"1.231582198","rc":[{"batb":[[0,2.36,10],[1,2.34,29.13],[2,1.3,1000]],"ltp":2.7,"tv":5.0,"id":31376}]}]}
{"op":"mcm","clk":"11856615123","pt":1723359693353,"mc":[{"id":"1.231582198","rc":[{"batb":[[0,2.34,29.13],[1,1.3,1000],[2,1.08,7.85]],"ltp":2.7,"tv":5.0,"id":31376}]}]}
{"op":"mcm","clk":"11856615417","pt":1723359696945,"mc":[{"id":"1.231582198","rc":[{"batb":[[0,2.36,10],[1,2.34,29.13],[2,1.3,1000]],"ltp":2.7,"tv":5.0,"id":31376}]}]}
{"op":"mcm","clk":"11856615683","pt":1723359700453,"mc":[{"id":"1.231582198","rc":[{"batb":[[0,2.34,29.13],[1,1.3,1000],[2,1.08,7.85]],"ltp":2.7,"tv":5.0,"id":31376}]}]}
{"op":"mcm","clk":"11856615961","pt":1723359704098,"mc":[{"id":"1.231582198","rc":[{"batb":[[0,2.36,10],[1,2.34,29.13],[2,1.3,1000]],"ltp":2.7,"tv":5.0,"id":31376}]}]}
{"op":"mcm","clk":"11856616186","pt":1723359707380,"mc":[{"id":"1.231582198","rc":[{"batb":[[0,2.34,29.13],[1,1.3,1000],[2,1.08,7.85]],"ltp":2.7,"tv":5.0,"id":31376}]}]}
{"op":"mcm","clk":"11856616636","pt":1723359713384,"mc":[{"id":"1.231582198","rc":[{"batb":[[0,2.36,10],[1,2.34,29.13],[2,1.3,1000]],"ltp":2.7,"tv":5.0,"id":31376}]}]}
{"op":"mcm","clk":"11856616865","pt":1723359716817,"mc":[{"id":"1.231582198","rc":[{"batb":[[0,2.34,29.13],[1,1.3,1000],[2,1.08,7.85]],"ltp":2.7,"tv":5.0,"id":31376}]}]}
{"op":"mcm","clk":"11856617010","pt":1723359719278,"mc":[{"id":"1.231582198","rc":[{"batb":[[0,2.36,10],[1,2.34,29.13],[2,1.3,1000]],"ltp":2.7,"tv":5.0,"id":31376}]}]}
{"op":"mcm","clk":"11856617306","pt":1723359722686,"mc":[{"id":"1.231582198","rc":[{"batb":[[0,2.34,29.13],[1,1.3,1000],[2,1.08,7.85]],"ltp":2.7,"tv":5.0,"id":31376}]}]}
{"op":"mcm","clk":"11856617554","pt":1723359725626,"mc":[{"id":"1.231582198","rc":[{"batb":[[0,2.36,10],[1,2.34,29.13],[2,1.3,1000]],"ltp":2.7,"tv":5.0,"id":31376}]}]}
{"op":"mcm","clk":"11856617798","pt":1723359728930,"mc":[{"id":"1.231582198","rc":[{"batb":[[0,2.34,29.13],[1,1.3,1000],[2,1.08,7.85]],"ltp":2.7,"tv":5.0,"id":31376}]}]}
{"op":"mcm","clk":"11856618003","pt":1723359731611,"mc":[{"id":"1.231582198","rc":[{"batb":[[0,2.36,10],[1,2.34,29.13],[2,1.3,1000]],"ltp":2.7,"tv":5.0,"id":31376}]}]}
{"op":"mcm","clk":"11856618238","pt":1723359734891,"mc":[{"id":"1.231582198","rc":[{"batb":[[0,2.34,29.13],[1,1.3,1000],[2,1.08,7.85]],"ltp":2.7,"tv":5.0,"id":31376}]}]}
{"op":"mcm","clk":"11856618407","pt":1723359737206,"mc":[{"id":"1.231582198","rc":[{"batb":[[0,2.36,10],[1,2.34,29.13],[2,1.3,1000]],"ltp":2.7,"tv":5.0,"id":31376}]}]}
{"op":"mcm","clk":"11856618671","pt":1723359740542,"mc":[{"id":"1.231582198","rc":[{"batb":[[0,2.34,29.13],[1,1.3,1000],[2,1.08,7.85]],"ltp":2.7,"tv":5.0,"id":31376}]}]}
{"op":"mcm","clk":"11856619010","pt":1723359745055,"mc":[{"id":"1.231582198","rc":[{"batb":[[0,2.36,10],[1,2.34,29.13],[2,1.3,1000]],"ltp":2.7,"tv":5.0,"id":31376}]}]}
{"op":"mcm","clk":"11856619248","pt":1723359748444,"mc":[{"id":"1.231582198","rc":[{"batb":[[0,2.34,29.13],[1,1.3,1000],[2,1.08,7.85]],"ltp":2.7,"tv":5.0,"id":31376}]}]}
{"op":"mcm","clk":"11856619431","pt":1723359750655,"mc":[{"id":"1.231582198","rc":[{"batb":[[0,2.36,10],[1,2.34,29.13],[2,1.3,1000]],"ltp":2.7,"tv":5.0,"id":31376}]}]}
{"op":"mcm","clk":"11856619659","pt":1723359754117,"mc":[{"id":"1.231582198","rc":[{"batb":[[0,2.34,29.13],[1,1.3,1000],[2,1.08,7.85]],"ltp":2.7,"tv":5.0,"id":31376}]}]}
{"op":"mcm","clk":"11856619848","pt":1723359757036,"mc":[{"id":"1.231582198","rc":[{"batb":[[0,2.36,10],[1,2.34,29.13],[2,1.3,1000]],"ltp":2.7,"tv":5.0,"id":31376}]}]}
{"op":"mcm","clk":"11856620076","pt":1723359760563,"mc":[{"id":"1.231582198","rc":[{"batb":[[0,2.34,29.13],[1,1.3,1000],[2,1.08,7.85]],"ltp":2.7,"tv":5.0,"id":31376}]}]}
{"op":"mcm","clk":"11856620632","pt":1723359767960,"mc":[{"id":"1.231582198","rc":[{"batb":[[0,2.36,10],[1,2.34,29.13],[2,1.3,1000]],"ltp":2.7,"tv":5.0,"id":31376}]}]}
{"op":"mcm","clk":"11856620924","pt":1723359771400,"mc":[{"id":"1.231582198","rc":[{"batb":[[0,2.34,29.13],[1,1.3,1000],[2,1.08,7.85]],"ltp":2.7,"tv":5.0,"id":31376}]}]}
{"op":"mcm","clk":"11856621123","pt":1723359773767,"mc":[{"id":"1.231582198","rc":[{"batl":[[0,1.72,4.56],[1,1.73,20.5],[2,1.84,4.56]],"ltp":1.33,"tv":623.14,"id":2780},{"batb":[[0,2.36,10],[1,2.34,29.13],[2,1.3,1000]],"ltp":2.7,"tv":5.0,"id":31376}]}]}
{"op":"mcm","clk":"11856621401","pt":1723359776970,"mc":[{"id":"1.231582198","rc":[{"batb":[[0,2.34,29.13],[1,1.3,1000],[2,1.08,7.85]],"ltp":2.7,"tv":5.0,"id":31376}]}]}
{"op":"mcm","clk":"11856621580","pt":1723359779065,"mc":[{"id":"1.231582198","rc":[{"batb":[[0,2.36,10],[1,2.34,29.13],[2,1.3,1000]],"ltp":2.7,"tv":5.0,"id":31376}]}]}
{"op":"mcm","clk":"11856621848","pt":1723359782306,"mc":[{"id":"1.231582198","rc":[{"batb":[[0,2.34,29.13],[1,1.3,1000],[2,1.08,7.85]],"ltp":2.7,"tv":5.0,"id":31376}]}]}
{"op":"mcm","clk":"11856622355","pt":1723359788686,"mc":[{"id":"1.231582198","rc":[{"batb":[[0,2.36,10],[1,2.34,29.13],[2,1.3,1000]],"ltp":2.7,"tv":5.0,"id":31376}]}]}
{"op":"mcm","clk":"11856622614","pt":1723359792180,"mc":[{"id":"1.231582198","rc":[{"batb":[[0,2.34,29.13],[1,1.3,1000],[2,1.08,7.85]],"ltp":2.7,"tv":5.0,"id":31376}]}]}
{"op":"mcm","clk":"11856622808","pt":1723359794894,"mc":[{"id":"1.231582198","rc":[{"batb":[[0,2.36,10],[1,2.34,29.13],[2,1.3,1000]],"ltp":2.7,"tv":5.0,"id":31376}]}]}
{"op":"mcm","clk":"11856623068","pt":1723359798230,"mc":[{"id":"1.231582198","rc":[{"batb":[[0,2.34,29.13],[1,1.3,1000],[2,1.08,7.85]],"ltp":2.7,"tv":5.0,"id":31376}]}]}
{"op":"mcm","clk":"11856623236","pt":1723359800794,"mc":[{"id":"1.231582198","rc":[{"batb":[[0,2.36,10],[1,2.34,29.13],[2,1.3,1000]],"ltp":2.7,"tv":5.0,"id":31376}]}]}
{"op":"mcm","clk":"11856623511","pt":1723359804211,"mc":[{"id":"1.231582198","rc":[{"batb":[[0,2.34,29.13],[1,1.3,1000],[2,1.08,7.85]],"ltp":2.7,"tv":5.0,"id":31376}]}]}
{"op":"mcm","clk":"11856623779","pt":1723359807305,"mc":[{"id":"1.231582198","rc":[{"batb":[[0,2.36,10],[1,2.34,29.13],[2,1.3,1000]],"ltp":2.7,"tv":5.0,"id":31376}]}]}
{"op":"mcm","clk":"11856624013","pt":1723359810739,"mc":[{"id":"1.231582198","rc":[{"batb":[[0,2.34,29.13],[1,1.3,1000],[2,1.08,7.85]],"ltp":2.7,"tv":5.0,"id":31376}]}]}
{"op":"mcm","clk":"11856624263","pt":1723359813833,"mc":[{"id":"1.231582198","rc":[{"batb":[[0,2.36,10],[1,2.34,29.13],[2,1.3,1000]],"ltp":2.7,"tv":5.0,"id":31376}]}]}
{"op":"mcm","clk":"11856624555","pt":1723359817227,"mc":[{"id":"1.231582198","rc":[{"batb":[[0,2.34,29.13],[1,1.3,1000],[2,1.08,7.85]],"ltp":2.7,"tv":5.0,"id":31376}]}]}
{"op":"mcm","clk":"11856624810","pt":1723359820571,"mc":[{"id":"1.231582198","rc":[{"batb":[[0,2.36,10],[1,2.34,29.13],[2,1.3,1000]],"ltp":2.7,"tv":5.0,"id":31376}]}]}
{"op":"mcm","clk":"11856625064","pt":1723359823965,"mc":[{"id":"1.231582198","rc":[{"batb":[[0,2.34,29.13],[1,1.3,1000],[2,1.08,7.85]],"ltp":2.7,"tv":5.0,"id":31376}]}]}
{"op":"mcm","clk":"11856625306","pt":1723359826972,"mc":[{"id":"1.231582198","rc":[{"batb":[[0,2.36,10],[1,2.34,29.13],[2,1.3,1000]],"ltp":2.7,"tv":5.0,"id":31376}]}]}
{"op":"mcm","clk":"11856625554","pt":1723359830368,"mc":[{"id":"1.231582198","rc":[{"batb":[[0,2.34,29.13],[1,1.3,1000],[2,1.08,7.85]],"ltp":2.7,"tv":5.0,"id":31376}]}]}
{"op":"mcm","clk":"11856625709","pt":1723359832983,"mc":[{"id":"1.231582198","rc":[{"batb":[[0,2.36,10],[1,2.34,29.13],[2,1.3,1000]],"ltp":2.7,"tv":5.0,"id":31376}]}]}
{"op":"mcm","clk":"11856626003","pt":1723359836567,"mc":[{"id":"1.231582198","rc":[{"batb":[[0,2.34,29.13],[1,1.3,1000],[2,1.08,7.85]],"ltp":2.7,"tv":5.0,"id":31376}]}]}
{"op":"mcm","clk":"11856626276","pt":1723359840066,"mc":[{"id":"1.231582198","rc":[{"batb":[[0,2.36,10],[1,2.34,29.13],[2,1.3,1000]],"ltp":2.7,"tv":5.0,"id":31376}]}]}
{"op":"mcm","clk":"11856626573","pt":1723359843581,"mc":[{"id":"1.231582198","rc":[{"batb":[[0,2.34,29.13],[1,1.3,1000],[2,1.08,7.85]],"ltp":2.7,"tv":5.0,"id":31376}]}]}
{"op":"mcm","clk":"11856626773","pt":1723359845794,"mc":[{"id":"1.231582198","rc":[{"batb":[[0,2.36,10],[1,2.34,29.13],[2,1.3,1000]],"ltp":2.7,"tv":5.0,"id":31376}]}]}
{"op":"mcm","clk":"11856627022","pt":1723359849089,"mc":[{"id":"1.231582198","rc":[{"batb":[[0,2.34,29.13],[1,1.3,1000],[2,1.08,7.85]],"ltp":2.7,"tv":5.0,"id":31376}]}]}
{"op":"mcm","clk":"11856627460","pt":1723359854629,"mc":[{"id":"1.231582198","rc":[{"batb":[[0,2.36,10],[1,2.34,29.13],[2,1.3,1000]],"ltp":2.7,"tv":5.0,"id":31376}]}]}
{"op":"mcm","clk":"11856627733","pt":1723359858019,"mc":[{"id":"1.231582198","rc":[{"batb":[[0,2.34,29.13],[1,1.3,1000],[2,1.08,7.85]],"ltp":2.7,"tv":5.0,"id":31376}]}]}
{"op":"mcm","clk":"11856627933","pt":1723359860991,"mc":[{"id":"1.231582198","rc":[{"batb":[[0,2.36,10],[1,2.34,29.13],[2,1.3,1000]],"ltp":2.7,"tv":5.0,"id":31376}]}]}
{"op":"mcm","clk":"11856628153","pt":1723359864226,"mc":[{"id":"1.231582198","rc":[{"batb":[[0,2.34,29.13],[1,1.3,1000],[2,1.08,7.85]],"ltp":2.7,"tv":5.0,"id":31376}]}]}
{"op":"mcm","clk":"11856628403","pt":1723359867705,"mc":[{"id":"1.231582198","rc":[{"batb":[[0,2.36,10],[1,2.34,29.13],[2,1.3,1000]],"ltp":2.7,"tv":5.0,"id":31376}]}]}
{"op":"mcm","clk":"11856628590","pt":1723359870930,"mc":[{"id":"1.231582198","rc":[{"batb":[[0,2.34,29.13],[1,1.3,1000],[2,1.08,7.85]],"ltp":2.7,"tv":5.0,"id":31376}]}]}
{"op":"mcm","clk":"11856628823","pt":1723359873910,"mc":[{"id":"1.231582198","rc":[{"batb":[[0,2.36,10],[1,2.34,29.13],[2,1.3,1000]],"ltp":2.7,"tv":5.0,"id":31376}]}]}
{"op":"mcm","clk":"11856629097","pt":1723359877434,"mc":[{"id":"1.231582198","rc":[{"batb":[[0,2.34,29.13],[1,1.3,1000],[2,1.08,7.85]],"ltp":2.7,"tv":5.0,"id":31376}]}]}
{"op":"mcm","clk":"11856629269","pt":1723359879843,"mc":[{"id":"1.231582198","rc":[{"batb":[[0,2.36,10],[1,2.34,29.13],[2,1.3,1000]],"ltp":2.7,"tv":5.0,"id":31376}]}]}
{"op":"mcm","clk":"11856629503","pt":1723359883140,"mc":[{"id":"1.231582198","rc":[{"batb":[[0,2.34,29.13],[1,1.3,1000],[2,1.08,7.85]],"ltp":2.7,"tv":5.0,"id":31376}]}]}
{"op":"mcm","clk":"11856629720","pt":1723359885866,"mc":[{"id":"1.231582198","rc":[{"batb":[[0,2.36,10],[1,2.34,29.13],[2,1.3,1000]],"ltp":2.7,"tv":5.0,"id":31376}]}]}
{"op":"mcm","clk":"11856629978","pt":1723359889531,"mc":[{"id":"1.231582198","rc":[{"batb":[[0,2.34,29.13],[1,1.3,1000],[2,1.08,7.85]],"ltp":2.7,"tv":5.0,"id":31376}]}]}
{"op":"mcm","clk":"11856630167","pt":1723359891959,"mc":[{"id":"1.231582198","rc":[{"batb":[[0,2.36,10],[1,2.34,29.13],[2,1.3,1000]],"ltp":2.7,"tv":5.0,"id":31376}]}]}
{"op":"mcm","clk":"11856630457","pt":1723359895557,"mc":[{"id":"1.231582198","rc":[{"batb":[[0,2.34,29.13],[1,1.3,1000],[2,1.08,7.85]],"ltp":2.7,"tv":5.0,"id":31376}]}]}
{"op":"mcm","clk":"11856630706","pt":1723359898949,"mc":[{"id":"1.231582198","rc":[{"batb":[[0,2.36,10],[1,2.34,29.13],[2,1.3,1000]],"ltp":2.7,"tv":5.0,"id":31376}]}]}
{"op":"mcm","clk":"11856630982","pt":1723359902459,"mc":[{"id":"1.231582198","rc":[{"batb":[[0,2.34,29.13],[1,1.3,1000],[2,1.08,7.85]],"ltp":2.7,"tv":5.0,"id":31376}]}]}
{"op":"mcm","clk":"11856631204","pt":1723359904887,"mc":[{"id":"1.231582198","rc":[{"batb":[[0,2.36,10],[1,2.34,29.13],[2,1.3,1000]],"ltp":2.7,"tv":5.0,"id":31376}]}]}
{"op":"mcm","clk":"11856631625","pt":1723359910499,"mc":[{"id":"1.231582198","rc":[{"batb":[[0,2.34,29.13],[1,1.3,1000],[2,1.08,7.85]],"ltp":2.7,"tv":5.0,"id":31376}]}]}
{"op":"mcm","clk":"11856631974","pt":1723359914486,"mc":[{"id":"1.231582198","rc":[{"batb":[[0,2.36,10],[1,2.34,29.13],[2,1.3,1000]],"ltp":2.7,"tv":5.0,"id":31376}]}]}
{"op":"mcm","clk":"11856632262","pt":1723359918316,"mc":[{"id":"1.231582198","rc":[{"batb":[[0,2.34,29.13],[1,1.3,1000],[2,1.08,7.85]],"ltp":2.7,"tv":5.0,"id":31376}]}]}
{"op":"mcm","clk":"11856632517","pt":1723359921318,"mc":[{"id":"1.231582198","rc":[{"batb":[[0,2.36,10],[1,2.34,29.13],[2,1.3,1000]],"ltp":2.7,"tv":5.0,"id":31376}]}]}
{"op":"mcm","clk":"11856632831","pt":1723359924727,"mc":[{"id":"1.231582198","rc":[{"batb":[[0,2.34,29.13],[1,1.3,1000],[2,1.08,7.85]],"ltp":2.7,"tv":5.0,"id":31376}]}]}
{"op":"mcm","clk":"11856633048","pt":1723359927504,"mc":[{"id":"1.231582198","rc":[{"batb":[[0,2.36,10],[1,2.34,29.13],[2,1.3,1000]],"ltp":2.7,"tv":5.0,"id":31376}]}]}
{"op":"mcm","clk":"11856633302","pt":1723359930803,"mc":[{"id":"1.231582198","rc":[{"batb":[[0,2.34,29.13],[1,1.3,1000],[2,1.08,7.85]],"ltp":2.7,"tv":5.0,"id":31376}]}]}
{"op":"mcm","clk":"11856633570","pt":1723359934209,"mc":[{"id":"1.231582198","rc":[{"batb":[[0,2.36,10],[1,2.34,29.13],[2,1.3,1000]],"ltp":2.7,"tv":5.0,"id":31376}]}]}
{"op":"mcm","clk":"11856633863","pt":1723359937421,"mc":[{"id":"1.231582198","rc":[{"batb":[[0,2.34,29.13],[1,1.3,1000],[2,1.08,7.85]],"ltp":2.7,"tv":5.0,"id":31376}]}]}
{"op":"mcm","clk":"11856634050","pt":1723359939839,"mc":[{"id":"1.231582198","rc":[{"batb":[[0,2.36,10],[1,2.34,29.13],[2,1.3,1000]],"ltp":2.7,"tv":5.0,"id":31376}]}]}
{"op":"mcm","clk":"11856634300","pt":1723359943234,"mc":[{"id":"1.231582198","rc":[{"batb":[[0,2.34,29.13],[1,1.3,1000],[2,1.08,7.85]],"ltp":2.7,"tv":5.0,"id":31376}]}]}
{"op":"mcm","clk":"11856634504","pt":1723359945925,"mc":[{"id":"1.231582198","rc":[{"batb":[[0,2.36,10],[1,2.34,29.13],[2,1.3,1000]],"ltp":2.7,"tv":5.0,"id":31376}]}]}
{"op":"mcm","clk":"11856634808","pt":1723359949341,"mc":[{"id":"1.231582198","rc":[{"batb":[[0,2.34,29.13],[1,1.3,1000],[2,1.08,7.85]],"ltp":2.7,"tv":5.0,"id":31376}]}]}
{"op":"mcm","clk":"11856635085","pt":1723359952232,"mc":[{"id":"1.231582198","rc":[{"batb":[[0,2.36,10],[1,2.34,29.13],[2,1.3,1000]],"ltp":2.7,"tv":5.0,"id":31376}]}]}
{"op":"mcm","clk":"11856635328","pt":1723359955564,"mc":[{"id":"1.231582198","rc":[{"batb":[[0,2.34,29.13],[1,1.3,1000],[2,1.08,7.85]],"ltp":2.7,"tv":5.0,"id":31376}]}]}
{"op":"mcm","clk":"11856635509","pt":1723359957836,"mc":[{"id":"1.231582198","rc":[{"batb":[[0,2.36,10],[1,2.34,29.13],[2,1.3,1000]],"ltp":2.7,"tv":5.0,"id":31376}]}]}
{"op":"mcm","clk":"11856635768","pt":1723359961274,"mc":[{"id":"1.231582198","rc":[{"batb":[[0,2.34,29.13],[1,1.3,1000],[2,1.08,7.85]],"ltp":2.7,"tv":5.0,"id":31376}]}]}
{"op":"mcm","clk":"11856635965","pt":1723359963557,"mc":[{"id":"1.231582198","rc":[{"batb":[[0,2.36,10],[1,2.34,29.13],[2,1.3,1000]],"ltp":2.7,"tv":5.0,"id":31376}]}]}
{"op":"mcm","clk":"11856636261","pt":1723359966963,"mc":[{"id":"1.231582198","rc":[{"batb":[[0,2.34,29.13],[1,1.3,1000],[2,1.08,7.85]],"ltp":2.7,"tv":5.0,"id":31376}]}]}
{"op":"mcm","clk":"11856636423","pt":1723359969273,"mc":[{"id":"1.231582198","rc":[{"batb":[[0,2.36,10],[1,2.34,29.13],[2,1.3,1000]],"ltp":2.7,"tv":5.0,"id":31376}]}]}
{"op":"mcm","clk":"11856636680","pt":1723359972658,"mc":[{"id":"1.231582198","rc":[{"batb":[[0,2.34,29.13],[1,1.3,1000],[2,1.08,7.85]],"ltp":2.7,"tv":5.0,"id":31376}]}]}
{"op":"mcm","clk":"11856637009","pt":1723359976264,"mc":[{"id":"1.231582198","rc":[{"batb":[[0,2.36,10],[1,2.34,29.13],[2,1.3,1000]],"ltp":2.7,"tv":5.0,"id":31376}]}]}
{"op":"mcm","clk":"11856637299","pt":1723359979457,"mc":[{"id":"1.231582198","rc":[{"batb":[[0,2.34,29.13],[1,1.3,1000],[2,1.08,7.85]],"ltp":2.7,"tv":5.0,"id":31376}]}]}
{"op":"mcm","clk":"11856637528","pt":1723359981874,"mc":[{"id":"1.231582198","rc":[{"batb":[[0,2.36,10],[1,2.34,29.13],[2,1.3,1000]],"ltp":2.7,"tv":5.0,"id":31376}]}]}
{"op":"mcm","clk":"11856637833","pt":1723359985364,"mc":[{"id":"1.231582198","rc":[{"batb":[[0,2.34,29.13],[1,1.3,1000],[2,1.08,7.85]],"ltp":2.7,"tv":5.0,"id":31376}]}]}
{"op":"mcm","clk":"11856638024","pt":1723359987775,"mc":[{"id":"1.231582198","rc":[{"batb":[[0,2.36,10],[1,2.34,29.13],[2,1.3,1000]],"ltp":2.7,"tv":5.0,"id":31376}]}]}
{"op":"mcm","clk":"11856638297","pt":1723359991109,"mc":[{"id":"1.231582198","rc":[{"batb":[[0,2.34,29.13],[1,1.3,1000],[2,1.08,7.85]],"ltp":2.7,"tv":5.0,"id":31376}]}]}
{"op":"mcm","clk":"11856638761","pt":1723359996814,"mc":[{"id":"1.231582198","rc":[{"batb":[[0,2.36,10],[1,2.34,29.13],[2,1.3,1000]],"ltp":2.7,"tv":5.0,"id":31376}]}]}
{"op":"mcm","clk":"11856639050","pt":1723360000320,"mc":[{"id":"1.231582198","rc":[{"batb":[[0,2.34,29.13],[1,1.3,1000],[2,1.08,7.85]],"ltp":2.7,"tv":5.0,"id":31376}]}]}
{"op":"mcm","clk":"11856639246","pt":1723360002502,"mc":[{"id":"1.231582198","rc":[{"batb":[[0,2.36,10],[1,2.34,29.13],[2,1.3,1000]],"ltp":2.7,"tv":5.0,"id":31376}]}]}
{"op":"mcm","clk":"11856639518","pt":1723360005710,"mc":[{"id":"1.231582198","rc":[{"batb":[[0,2.34,29.13],[1,1.3,1000],[2,1.08,7.85]],"ltp":2.7,"tv":5.0,"id":31376}]}]}
{"op":"mcm","clk":"11856639733","pt":1723360007907,"mc":[{"id":"1.231582198","rc":[{"batb":[[0,2.36,10],[1,2.34,29.13],[2,1.3,1000]],"ltp":2.7,"tv":5.0,"id":31376}]}]}
{"op":"mcm","clk":"11856640017","pt":1723360011405,"mc":[{"id":"1.231582198","rc":[{"batb":[[0,2.34,29.13],[1,1.3,1000],[2,1.08,7.85]],"ltp":2.7,"tv":5.0,"id":31376}]}]}
{"op":"mcm","clk":"11856640187","pt":1723360013837,"mc":[{"id":"1.231582198","rc":[{"batb":[[0,2.36,10],[1,2.34,29.13],[2,1.3,1000]],"ltp":2.7,"tv":5.0,"id":31376}]}]}
{"op":"mcm","clk":"11856640464","pt":1723360017334,"mc":[{"id":"1.231582198","rc":[{"batb":[[0,2.34,29.13],[1,1.3,1000],[2,1.08,7.85]],"ltp":2.7,"tv":5.0,"id":31376}]}]}
{"op":"mcm","clk":"11856640644","pt":1723360019847,"mc":[{"id":"1.231582198","rc":[{"batb":[[0,2.36,10],[1,2.34,29.13],[2,1.3,1000]],"ltp":2.7,"tv":5.0,"id":31376}]}]}
{"op":"mcm","clk":"11856640925","pt":1723360023157,"mc":[{"id":"1.231582198","rc":[{"batb":[[0,2.34,29.13],[1,1.3,1000],[2,1.08,7.85]],"ltp":2.7,"tv":5.0,"id":31376}]}]}
{"op":"mcm","clk":"11856641136","pt":1723360026348,"mc":[{"id":"1.231582198","rc":[{"batb":[[0,2.36,10],[1,2.34,29.13],[2,1.3,1000]],"ltp":2.7,"tv":5.0,"id":31376}]}]}
{"op":"mcm","clk":"11856641390","pt":1723360029752,"mc":[{"id":"1.231582198","rc":[{"batb":[[0,2.34,29.13],[1,1.3,1000],[2,1.08,7.85]],"ltp":2.7,"tv":5.0,"id":31376}]}]}
{"op":"mcm","clk":"11856641670","pt":1723360033659,"mc":[{"id":"1.231582198","rc":[{"batb":[[0,2.36,10],[1,2.34,29.13],[2,1.3,1000]],"ltp":2.7,"tv":5.0,"id":31376}]}]}
{"op":"mcm","clk":"11856641894","pt":1723360036842,"mc":[{"id":"1.231582198","rc":[{"batb":[[0,2.34,29.13],[1,1.3,1000],[2,1.08,7.85]],"ltp":2.7,"tv":5.0,"id":31376}]}]}
{"op":"mcm","clk":"11856642072","pt":1723360039461,"mc":[{"id":"1.231582198","rc":[{"batb":[[0,2.36,10],[1,2.34,29.13],[2,1.3,1000]],"ltp":2.7,"tv":5.0,"id":31376}]}]}
{"op":"mcm","clk":"11856642343","pt":1723360043055,"mc":[{"id":"1.231582198","rc":[{"batb":[[0,2.34,29.13],[1,1.3,1000],[2,1.08,7.85]],"ltp":2.7,"tv":5.0,"id":31376}]}]}
{"op":"mcm","clk":"11856642630","pt":1723360047162,"mc":[{"id":"1.231582198","rc":[{"batb":[[0,2.36,10],[1,2.34,29.13],[2,1.3,1000]],"ltp":2.7,"tv":5.0,"id":31376}]}]}
{"op":"mcm","clk":"11856642880","pt":1723360050507,"mc":[{"id":"1.231582198","rc":[{"batb":[[0,2.34,29.13],[1,1.3,1000],[2,1.08,7.85]],"ltp":2.7,"tv":5.0,"id":31376}]}]}
{"op":"mcm","clk":"11856643097","pt":1723360053091,"mc":[{"id":"1.231582198","rc":[{"batb":[[0,2.36,10],[1,2.34,29.13],[2,1.3,1000]],"ltp":2.7,"tv":5.0,"id":31376}]}]}
{"op":"mcm","clk":"11856643367","pt":1723360056375,"mc":[{"id":"1.231582198","rc":[{"batb":[[0,2.34,29.13],[1,1.3,1000],[2,1.08,7.85]],"ltp":2.7,"tv":5.0,"id":31376}]}]}
{"op":"mcm","clk":"11856643578","pt":1723360059183,"mc":[{"id":"1.231582198","rc":[{"batb":[[0,2.36,10],[1,2.34,29.13],[2,1.3,1000]],"ltp":2.7,"tv":5.0,"id":31376}]}]}
{"op":"mcm","clk":"11856643833","pt":1723360062383,"mc":[{"id":"1.231582198","rc":[{"batb":[[0,2.34,29.13],[1,1.3,1000],[2,1.08,7.85]],"ltp":2.7,"tv":5.0,"id":31376}]}]}
{"op":"mcm","clk":"11856644099","pt":1723360066529,"mc":[{"id":"1.231582198","rc":[{"batb":[[0,2.36,10],[1,2.34,29.13],[2,1.3,1000]],"ltp":2.7,"tv":5.0,"id":31376}]}]}
{"op":"mcm","clk":"11856644311","pt":1723360070119,"mc":[{"id":"1.231582198","rc":[{"batb":[[0,2.34,29.13],[1,1.3,1000],[2,1.08,7.85]],"ltp":2.7,"tv":5.0,"id":31376}]}]}
{"op":"mcm","clk":"11856644462","pt":1723360072220,"mc":[{"id":"1.231582198","rc":[{"batb":[[0,2.36,10],[1,2.34,29.13],[2,1.3,1000]],"ltp":2.7,"tv":5.0,"id":31376}]}]}
{"op":"mcm","clk":"11856644697","pt":1723360075423,"mc":[{"id":"1.231582198","rc":[{"batb":[[0,2.34,29.13],[1,1.3,1000],[2,1.08,7.85]],"ltp":2.7,"tv":5.0,"id":31376}]}]}
{"op":"mcm","clk":"11856644891","pt":1723360078808,"mc":[{"id":"1.231582198","rc":[{"batb":[[0,2.36,10],[1,2.34,29.13],[2,1.3,1000]],"ltp":2.7,"tv":5.0,"id":31376}]}]}
{"op":"mcm","clk":"11856645093","pt":1723360082211,"mc":[{"id":"1.231582198","rc":[{"batb":[[0,2.34,29.13],[1,1.3,1000],[2,1.08,7.85]],"ltp":2.7,"tv":5.0,"id":31376}]}]}
{"op":"mcm","clk":"11856645248","pt":1723360084825,"mc":[{"id":"1.231582198","rc":[{"batb":[[0,2.36,10],[1,2.34,29.13],[2,1.3,1000]],"ltp":2.7,"tv":5.0,"id":31376}]}]}
{"op":"mcm","clk":"11856645609","pt":1723360088960,"mc":[{"id":"1.231582198","rc":[{"batb":[[0,2.34,29.13],[1,1.3,1000],[2,1.08,7.85]],"ltp":2.7,"tv":5.0,"id":31376}]}]}
{"op":"mcm","clk":"11856645837","pt":1723360091438,"mc":[{"id":"1.231582198","rc":[{"batb":[[0,2.36,10],[1,2.34,29.13],[2,1.3,1000]],"ltp":2.7,"tv":5.0,"id":31376}]}]}
{"op":"mcm","clk":"11856646022","pt":1723360094632,"mc":[{"id":"1.231582198","rc":[{"batb":[[0,2.34,29.13],[1,1.3,1000],[2,1.08,7.85]],"ltp":2.7,"tv":5.0,"id":31376}]}]}
{"op":"mcm","clk":"11856646269","pt":1723360097729,"mc":[{"id":"1.231582198","rc":[{"batb":[[0,2.36,10],[1,2.34,29.13],[2,1.3,1000]],"ltp":2.7,"tv":5.0,"id":31376}]}]}
{"op":"mcm","clk":"11856646507","pt":1723360101071,"mc":[{"id":"1.231582198","rc":[{"batb":[[0,2.34,29.13],[1,1.3,1000],[2,1.08,7.85]],"ltp":2.7,"tv":5.0,"id":31376}]}]}
{"op":"mcm","clk":"11856646715","pt":1723360104044,"mc":[{"id":"1.231582198","rc":[{"batb":[[0,2.36,10],[1,2.34,29.13],[2,1.3,1000]],"ltp":2.7,"tv":5.0,"id":31376}]}]}
{"op":"mcm","clk":"11856646939","pt":1723360107275,"mc":[{"id":"1.231582198","rc":[{"batb":[[0,2.34,29.13],[1,1.3,1000],[2,1.08,7.85]],"ltp":2.7,"tv":5.0,"id":31376}]}]}
{"op":"mcm","clk":"11856647212","pt":1723360110768,"mc":[{"id":"1.231582198","rc":[{"batb":[[0,2.36,10],[1,2.34,29.13],[2,1.3,1000]],"ltp":2.7,"tv":5.0,"id":31376}]}]}
{"op":"mcm","clk":"11856647475","pt":1723360114680,"mc":[{"id":"1.231582198","rc":[{"batb":[[0,2.34,29.13],[1,1.3,1000],[2,1.08,7.85]],"ltp":2.7,"tv":5.0,"id":31376}]}]}
{"op":"mcm","clk":"11856647630","pt":1723360117268,"mc":[{"id":"1.231582198","rc":[{"batb":[[0,2.36,10],[1,2.34,29.13],[2,1.3,1000]],"ltp":2.7,"tv":5.0,"id":31376}]}]}
{"op":"mcm","clk":"11856647856","pt":1723360120504,"mc":[{"id":"1.231582198","rc":[{"batb":[[0,2.34,29.13],[1,1.3,1000],[2,1.08,7.85]],"ltp":2.7,"tv":5.0,"id":31376}]}]}
{"op":"mcm","clk":"11856648054","pt":1723360123484,"mc":[{"id":"1.231582198","rc":[{"batb":[[0,2.36,10],[1,2.34,29.13],[2,1.3,1000]],"ltp":2.7,"tv":5.0,"id":31376}]}]}
{"op":"mcm","clk":"11856648258","pt":1723360126678,"mc":[{"id":"1.231582198","rc":[{"batb":[[0,2.34,29.13],[1,1.3,1000],[2,1.08,7.85]],"ltp":2.7,"tv":5.0,"id":31376}]}]}
{"op":"mcm","clk":"11856648451","pt":1723360129593,"mc":[{"id":"1.231582198","rc":[{"batb":[[0,2.36,10],[1,2.34,29.13],[2,1.3,1000]],"ltp":2.7,"tv":5.0,"id":31376}]}]}
{"op":"mcm","clk":"11856648719","pt":1723360133505,"mc":[{"id":"1.231582198","rc":[{"batb":[[0,2.34,29.13],[1,1.3,1000],[2,1.08,7.85]],"ltp":2.7,"tv":5.0,"id":31376}]}]}
{"op":"mcm","clk":"11856648799","pt":1723360134691,"mc":[{"id":"1.231582198","rc":[{"batb":[[0,1.66,4.51],[1,1.65,60.06],[2,1.56,4.56]],"ltp":1.33,"tv":623.14,"id":2780}]}]}
{"op":"mcm","clk":"11856648909","pt":1723360136334,"mc":[{"id":"1.231582198","rc":[{"batb":[[0,2.36,10],[1,2.34,29.13],[2,1.3,1000]],"ltp":2.7,"tv":5.0,"id":31376}]}]}
{"op":"mcm","clk":"11856649136","pt":1723360139922,"mc":[{"id":"1.231582198","rc":[{"batb":[[0,2.34,29.13],[1,1.3,1000],[2,1.08,7.85]],"ltp":2.7,"tv":5.0,"id":31376}]}]}
{"op":"mcm","clk":"11856649375","pt":1723360142823,"mc":[{"id":"1.231582198","rc":[{"batb":[[0,2.36,10],[1,2.34,29.13],[2,1.3,1000]],"ltp":2.7,"tv":5.0,"id":31376}]}]}
{"op":"mcm","clk":"11856649629","pt":1723360146318,"mc":[{"id":"1.231582198","rc":[{"batb":[[0,2.34,29.13],[1,1.3,1000],[2,1.08,7.85]],"ltp":2.7,"tv":5.0,"id":31376}]}]}
{"op":"mcm","clk":"11856649893","pt":1723360150124,"mc":[{"id":"1.231582198","rc":[{"batb":[[0,2.36,10],[1,2.34,29.13],[2,1.3,1000]],"ltp":2.7,"tv":5.0,"id":31376}]}]}
{"op":"mcm","clk":"11856650135","pt":1723360153410,"mc":[{"id":"1.231582198","rc":[{"batb":[[0,2.34,29.13],[1,1.3,1000],[2,1.08,7.85]],"ltp":2.7,"tv":5.0,"id":31376}]}]}
{"op":"mcm","clk":"11856650345","pt":1723360156140,"mc":[{"id":"1.231582198","rc":[{"batb":[[0,2.36,10],[1,2.34,29.13],[2,1.3,1000]],"ltp":2.7,"tv":5.0,"id":31376}]}]}
{"op":"mcm","clk":"11856650564","pt":1723360159325,"mc":[{"id":"1.231582198","rc":[{"batb":[[0,2.34,29.13],[1,1.3,1000],[2,1.08,7.85]],"ltp":2.7,"tv":5.0,"id":31376}]}]}
{"op":"mcm","clk":"11856651010","pt":1723360165843,"mc":[{"id":"1.231582198","rc":[{"batb":[[0,2.36,10],[1,2.34,29.13],[2,1.3,1000]],"ltp":2.7,"tv":5.0,"id":31376}]}]}
{"op":"mcm","clk":"11856651260","pt":1723360169248,"mc":[{"id":"1.231582198","rc":[{"batb":[[0,2.34,29.13],[1,1.3,1000],[2,1.08,7.85]],"ltp":2.7,"tv":5.0,"id":31376}]}]}
{"op":"mcm","clk":"11856651510","pt":1723360172971,"mc":[{"id":"1.231582198","rc":[{"batb":[[0,2.36,10],[1,2.34,29.13],[2,1.3,1000]],"ltp":2.7,"tv":5.0,"id":31376}]}]}
{"op":"mcm","clk":"11856651800","pt":1723360176375,"mc":[{"id":"1.231582198","rc":[{"batb":[[0,2.34,29.13],[1,1.3,1000],[2,1.08,7.85]],"ltp":2.7,"tv":5.0,"id":31376}]}]}
{"op":"mcm","clk":"11856651997","pt":1723360178993,"mc":[{"id":"1.231582198","rc":[{"batb":[[0,2.36,10],[1,2.34,29.13],[2,1.3,1000]],"ltp":2.7,"tv":5.0,"id":31376}]}]}
{"op":"mcm","clk":"11856652289","pt":1723360182894,"mc":[{"id":"1.231582198","rc":[{"batb":[[0,2.34,29.13],[1,1.3,1000],[2,1.08,7.85]],"ltp":2.7,"tv":5.0,"id":31376}]}]}
{"op":"mcm","clk":"11856652486","pt":1723360186174,"mc":[{"id":"1.231582198","rc":[{"batb":[[0,2.36,10],[1,2.34,29.13],[2,1.3,1000]],"ltp":2.7,"tv":5.0,"id":31376}]}]}
{"op":"mcm","clk":"11856652714","pt":1723360189461,"mc":[{"id":"1.231582198","rc":[{"batb":[[0,2.34,29.13],[1,1.3,1000],[2,1.08,7.85]],"ltp":2.7,"tv":5.0,"id":31376}]}]}
{"op":"mcm","clk":"11856653190","pt":1723360197400,"mc":[{"id":"1.231582198","rc":[{"batb":[[0,2.36,10],[1,2.34,29.13],[2,1.3,1000]],"ltp":2.7,"tv":5.0,"id":31376}]}]}
{"op":"mcm","clk":"11856653430","pt":1723360200703,"mc":[{"id":"1.231582198","rc":[{"batb":[[0,2.34,29.13],[1,1.3,1000],[2,1.08,7.85]],"ltp":2.7,"tv":5.0,"id":31376}]}]}
{"op":"mcm","clk":"11856653640","pt":1723360202985,"mc":[{"id":"1.231582198","rc":[{"batb":[[0,2.36,10],[1,2.34,29.13],[2,1.3,1000]],"ltp":2.7,"tv":5.0,"id":31376}]}]}
{"op":"mcm","clk":"11856653903","pt":1723360206281,"mc":[{"id":"1.231582198","rc":[{"batb":[[0,2.34,29.13],[1,1.3,1000],[2,1.08,7.85]],"ltp":2.7,"tv":5.0,"id":31376}]}]}
{"op":"mcm","clk":"11856654126","pt":1723360209520,"mc":[{"id":"1.231582198","rc":[{"batb":[[0,2.36,10],[1,2.34,29.13],[2,1.3,1000]],"ltp":2.7,"tv":5.0,"id":31376}]}]}
{"op":"mcm","clk":"11856654348","pt":1723360212913,"mc":[{"id":"1.231582198","rc":[{"batb":[[0,2.34,29.13],[1,1.3,1000],[2,1.08,7.85]],"ltp":2.7,"tv":5.0,"id":31376}]}]}
{"op":"mcm","clk":"11856654630","pt":1723360216615,"mc":[{"id":"1.231582198","rc":[{"batb":[[0,2.36,10],[1,2.34,29.13],[2,1.3,1000]],"ltp":2.7,"tv":5.0,"id":31376}]}]}
{"op":"mcm","clk":"11856654839","pt":1723360220012,"mc":[{"id":"1.231582198","rc":[{"batb":[[0,2.34,29.13],[1,1.3,1000],[2,1.08,7.85]],"ltp":2.7,"tv":5.0,"id":31376}]}]}
{"op":"mcm","clk":"11856655108","pt":1723360224226,"mc":[{"id":"1.231582198","rc":[{"batb":[[0,2.36,10],[1,2.34,29.13],[2,1.3,1000]],"ltp":2.7,"tv":5.0,"id":31376}]}]}
{"op":"mcm","clk":"11856655334","pt":1723360227617,"mc":[{"id":"1.231582198","rc":[{"batb":[[0,2.34,29.13],[1,1.3,1000],[2,1.08,7.85]],"ltp":2.7,"tv":5.0,"id":31376}]}]}
{"op":"mcm","clk":"11856655487","pt":1723360230027,"mc":[{"id":"1.231582198","rc":[{"batb":[[0,2.36,10],[1,2.34,29.13],[2,1.3,1000]],"ltp":2.7,"tv":5.0,"id":31376}]}]}
{"op":"mcm","clk":"11856655714","pt":1723360233420,"mc":[{"id":"1.231582198","rc":[{"batb":[[0,2.34,29.13],[1,1.3,1000],[2,1.08,7.85]],"ltp":2.7,"tv":5.0,"id":31376}]}]}
{"op":"mcm","clk":"11856655885","pt":1723360235934,"mc":[{"id":"1.231582198","rc":[{"batb":[[0,2.36,10],[1,2.34,29.13],[2,1.3,1000]],"ltp":2.7,"tv":5.0,"id":31376}]}]}
{"op":"mcm","clk":"11856656146","pt":1723360239247,"mc":[{"id":"1.231582198","rc":[{"batb":[[0,2.34,29.13],[1,1.3,1000],[2,1.08,7.85]],"ltp":2.7,"tv":5.0,"id":31376}]}]}
{"op":"mcm","clk":"11856656372","pt":1723360241839,"mc":[{"id":"1.231582198","rc":[{"batb":[[0,2.36,10],[1,2.34,29.13],[2,1.3,1000]],"ltp":2.7,"tv":5.0,"id":31376}]}]}
{"op":"mcm","clk":"11856656609","pt":1723360245130,"mc":[{"id":"1.231582198","rc":[{"batb":[[0,2.34,29.13],[1,1.3,1000],[2,1.08,7.85]],"ltp":2.7,"tv":5.0,"id":31376}]}]}
{"op":"mcm","clk":"11856656757","pt":1723360247437,"mc":[{"id":"1.231582198","rc":[{"batb":[[0,2.36,10],[1,2.34,29.13],[2,1.3,1000]],"ltp":2.7,"tv":5.0,"id":31376}]}]}
{"op":"mcm","clk":"11856656988","pt":1723360250666,"mc":[{"id":"1.231582198","rc":[{"batb":[[0,2.34,29.13],[1,1.3,1000],[2,1.08,7.85]],"ltp":2.7,"tv":5.0,"id":31376}]}]}
{"op":"mcm","clk":"11856657247","pt":1723360253562,"mc":[{"id":"1.231582198","rc":[{"batb":[[0,2.36,10],[1,2.34,29.13],[2,1.3,1000]],"ltp":2.7,"tv":5.0,"id":31376}]}]}
{"op":"mcm","clk":"11856657458","pt":1723360257154,"mc":[{"id":"1.231582198","rc":[{"batb":[[0,2.34,29.13],[1,1.3,1000],[2,1.08,7.85]],"ltp":2.7,"tv":5.0,"id":31376}]}]}
{"op":"mcm","clk":"11856657610","pt":1723360259587,"mc":[{"id":"1.231582198","rc":[{"batb":[[0,2.36,10],[1,2.34,29.13],[2,1.3,1000]],"ltp":2.7,"tv":5.0,"id":31376}]}]}
{"op":"mcm","clk":"11856657890","pt":1723360263285,"mc":[{"id":"1.231582198","rc":[{"batb":[[0,2.34,29.13],[1,1.3,1000],[2,1.08,7.85]],"ltp":2.7,"tv":5.0,"id":31376}]}]}
{"op":"mcm","clk":"11856658105","pt":1723360266157,"mc":[{"id":"1.231582198","rc":[{"batb":[[0,2.36,10],[1,2.34,29.13],[2,1.3,1000]],"ltp":2.7,"tv":5.0,"id":31376}]}]}
{"op":"mcm","clk":"11856658323","pt":1723360269569,"mc":[{"id":"1.231582198","rc":[{"batb":[[0,2.34,29.13],[1,1.3,1000],[2,1.08,7.85]],"ltp":2.7,"tv":5.0,"id":31376}]}]}
{"op":"mcm","clk":"11856658541","pt":1723360272713,"mc":[{"id":"1.231582198","rc":[{"batb":[[0,2.36,10],[1,2.34,29.13],[2,1.3,1000]],"ltp":2.7,"tv":5.0,"id":31376}]}]}
{"op":"mcm","clk":"11856658730","pt":1723360275891,"mc":[{"id":"1.231582198","rc":[{"batb":[[0,2.34,29.13],[1,1.3,1000],[2,1.08,7.85]],"ltp":2.7,"tv":5.0,"id":31376}]}]}
{"op":"mcm","clk":"11856658881","pt":1723360278098,"mc":[{"id":"1.231582198","rc":[{"batb":[[0,2.36,10],[1,2.34,29.13],[2,1.3,1000]],"ltp":2.7,"tv":5.0,"id":31376}]}]}
{"op":"mcm","clk":"11856659096","pt":1723360281481,"mc":[{"id":"1.231582198","rc":[{"batb":[[0,2.34,29.13],[1,1.3,1000],[2,1.08,7.85]],"ltp":2.7,"tv":5.0,"id":31376}]}]}
{"op":"mcm","clk":"11856659268","pt":1723360283992,"mc":[{"id":"1.231582198","rc":[{"batb":[[0,2.36,10],[1,2.34,29.13],[2,1.3,1000]],"ltp":2.7,"tv":5.0,"id":31376}]}]}
{"op":"mcm","clk":"11856659468","pt":1723360287317,"mc":[{"id":"1.231582198","rc":[{"batb":[[0,2.34,29.13],[1,1.3,1000],[2,1.08,7.85]],"ltp":2.7,"tv":5.0,"id":31376}]}]}
{"op":"mcm","clk":"11856659639","pt":1723360290335,"mc":[{"id":"1.231582198","rc":[{"batb":[[0,2.36,10],[1,2.34,29.13],[2,1.3,1000]],"ltp":2.7,"tv":5.0,"id":31376}]}]}
{"op":"mcm","clk":"11856659822","pt":1723360293925,"mc":[{"id":"1.231582198","rc":[{"batb":[[0,2.34,29.13],[1,1.3,1000],[2,1.08,7.85]],"ltp":2.7,"tv":5.0,"id":31376}]}]}
{"op":"mcm","clk":"11856660207","pt":1723360296642,"mc":[{"id":"1.231582198","rc":[{"batb":[[0,2.36,10],[1,2.34,29.13],[2,1.3,1000]],"ltp":2.7,"tv":5.0,"id":31376}]}]}
{"op":"mcm","clk":"11856660586","pt":1723360300032,"mc":[{"id":"1.231582198","rc":[{"batb":[[0,2.34,29.13],[1,1.3,1000],[2,1.08,7.85]],"ltp":2.7,"tv":5.0,"id":31376}]}]}
{"op":"mcm","clk":"11856660704","pt":1723360302550,"mc":[{"id":"1.231582198","rc":[{"batb":[[0,2.36,10],[1,2.34,29.13],[2,1.3,1000]],"ltp":2.7,"tv":5.0,"id":31376}]}]}
{"op":"mcm","clk":"11856660878","pt":1723360305834,"mc":[{"id":"1.231582198","rc":[{"batb":[[0,2.34,29.13],[1,1.3,1000],[2,1.08,7.85]],"ltp":2.7,"tv":5.0,"id":31376}]}]}
{"op":"mcm","clk":"11856661010","pt":1723360308317,"mc":[{"id":"1.231582198","rc":[{"batb":[[0,2.36,10],[1,2.34,29.13],[2,1.3,1000]],"ltp":2.7,"tv":5.0,"id":31376}]}]}
{"op":"mcm","clk":"11856661244","pt":1723360311810,"mc":[{"id":"1.231582198","rc":[{"batb":[[0,2.34,29.13],[1,1.3,1000],[2,1.08,7.85]],"ltp":2.7,"tv":5.0,"id":31376}]}]}
{"op":"mcm","clk":"11856661573","pt":1723360317448,"mc":[{"id":"1.231582198","rc":[{"batb":[[0,2.36,10],[1,2.34,29.13],[2,1.3,1000]],"ltp":2.7,"tv":5.0,"id":31376}]}]}
{"op":"mcm","clk":"11856661787","pt":1723360320742,"mc":[{"id":"1.231582198","rc":[{"batb":[[0,2.34,29.13],[1,1.3,1000],[2,1.08,7.85]],"ltp":2.7,"tv":5.0,"id":31376}]}]}
{"op":"mcm","clk":"11856661993","pt":1723360323566,"mc":[{"id":"1.231582198","rc":[{"batb":[[0,2.36,10],[1,2.34,29.13],[2,1.3,1000]],"ltp":2.7,"tv":5.0,"id":31376}]}]}
{"op":"mcm","clk":"11856662213","pt":1723360327159,"mc":[{"id":"1.231582198","rc":[{"batb":[[0,2.34,29.13],[1,1.3,1000],[2,1.08,7.85]],"ltp":2.7,"tv":5.0,"id":31376}]}]}
{"op":"mcm","clk":"11856662417","pt":1723360330042,"mc":[{"id":"1.231582198","rc":[{"batb":[[0,2.36,10],[1,2.34,29.13],[2,1.3,1000]],"ltp":2.7,"tv":5.0,"id":31376}]}]}
{"op":"mcm","clk":"11856662633","pt":1723360333579,"mc":[{"id":"1.231582198","rc":[{"batb":[[0,2.34,29.13],[1,1.3,1000],[2,1.08,7.85]],"ltp":2.7,"tv":5.0,"id":31376}]}]}
{"op":"mcm","clk":"11856662828","pt":1723360336455,"mc":[{"id":"1.231582198","rc":[{"batb":[[0,2.36,10],[1,2.34,29.13],[2,1.3,1000]],"ltp":2.7,"tv":5.0,"id":31376}]}]}
{"op":"mcm","clk":"11856663057","pt":1723360339756,"mc":[{"id":"1.231582198","rc":[{"batb":[[0,2.34,29.13],[1,1.3,1000],[2,1.08,7.85]],"ltp":2.7,"tv":5.0,"id":31376}]}]}
{"op":"mcm","clk":"11856663232","pt":1723360342271,"mc":[{"id":"1.231582198","rc":[{"batb":[[0,2.36,10],[1,2.34,29.13],[2,1.3,1000]],"ltp":2.7,"tv":5.0,"id":31376}]}]}
{"op":"mcm","clk":"11856663437","pt":1723360345590,"mc":[{"id":"1.231582198","rc":[{"batb":[[0,2.34,29.13],[1,1.3,1000],[2,1.08,7.85]],"ltp":2.7,"tv":5.0,"id":31376}]}]}
{"op":"mcm","clk":"11856663733","pt":1723360350900,"mc":[{"id":"1.231582198","rc":[{"batb":[[0,2.36,10],[1,2.34,29.13],[2,1.3,1000]],"ltp":2.7,"tv":5.0,"id":31376}]}]}
{"op":"mcm","clk":"11856663966","pt":1723360354907,"mc":[{"id":"1.231582198","rc":[{"batb":[[0,2.34,29.13],[1,1.3,1000],[2,1.08,7.85]],"ltp":2.7,"tv":5.0,"id":31376}]}]}
{"op":"mcm","clk":"11856664076","pt":1723360357078,"mc":[{"id":"1.231582198","rc":[{"batb":[[0,2.36,10],[1,2.34,29.13],[2,1.3,1000]],"ltp":2.7,"tv":5.0,"id":31376}]}]}
{"op":"mcm","clk":"11856664245","pt":1723360360323,"mc":[{"id":"1.231582198","rc":[{"batb":[[0,2.34,29.13],[1,1.3,1000],[2,1.08,7.85]],"ltp":2.7,"tv":5.0,"id":31376}]}]}
{"op":"mcm","clk":"11856664384","pt":1723360362696,"mc":[{"id":"1.231582198","rc":[{"batb":[[0,2.36,10],[1,2.34,29.13],[2,1.3,1000]],"ltp":2.7,"tv":5.0,"id":31376}]}]}
{"op":"mcm","clk":"11856664611","pt":1723360366397,"mc":[{"id":"1.231582198","rc":[{"batb":[[0,2.34,29.13],[1,1.3,1000],[2,1.08,7.85]],"ltp":2.7,"tv":5.0,"id":31376}]}]}
{"op":"mcm","clk":"11856664770","pt":1723360369122,"mc":[{"id":"1.231582198","rc":[{"batb":[[0,2.36,10],[1,2.34,29.13],[2,1.3,1000]],"ltp":2.7,"tv":5.0,"id":31376}]}]}
{"op":"mcm","clk":"11856664938","pt":1723360372406,"mc":[{"id":"1.231582198","rc":[{"batb":[[0,2.34,29.13],[1,1.3,1000],[2,1.08,7.85]],"ltp":2.7,"tv":5.0,"id":31376}]}]}
{"op":"mcm","clk":"11856665337","pt":1723360378821,"mc":[{"id":"1.231582198","rc":[{"batb":[[0,2.36,10],[1,2.34,29.13],[2,1.3,1000]],"ltp":2.7,"tv":5.0,"id":31376}]}]}
{"op":"mcm","clk":"11856665564","pt":1723360382122,"mc":[{"id":"1.231582198","rc":[{"batb":[[0,2.34,29.13],[1,1.3,1000],[2,1.08,7.85]],"ltp":2.7,"tv":5.0,"id":31376}]}]}
{"op":"mcm","clk":"11856666116","pt":1723360384639,"mc":[{"id":"1.231582198","rc":[{"batb":[[0,2.36,10],[1,2.34,29.13],[2,1.3,1000]],"ltp":2.7,"tv":5.0,"id":31376}]}]}
{"op":"mcm","clk":"11856666329","pt":1723360388047,"mc":[{"id":"1.231582198","rc":[{"batb":[[0,2.34,29.13],[1,1.3,1000],[2,1.08,7.85]],"ltp":2.7,"tv":5.0,"id":31376}]}]}
{"op":"mcm","clk":"11856666427","pt":1723360390261,"mc":[{"id":"1.231582198","rc":[{"batb":[[0,2.36,10],[1,2.34,29.13],[2,1.3,1000]],"ltp":2.7,"tv":5.0,"id":31376}]}]}
{"op":"mcm","clk":"11856666593","pt":1723360393640,"mc":[{"id":"1.231582198","rc":[{"batb":[[0,2.34,29.13],[1,1.3,1000],[2,1.08,7.85]],"ltp":2.7,"tv":5.0,"id":31376}]}]}
{"op":"mcm","clk":"11856666776","pt":1723360396865,"mc":[{"id":"1.231582198","rc":[{"batb":[[0,2.36,10],[1,2.34,29.13],[2,1.3,1000]],"ltp":2.7,"tv":5.0,"id":31376}]}]}
{"op":"mcm","clk":"11856666965","pt":1723360400273,"mc":[{"id":"1.231582198","rc":[{"batb":[[0,2.34,29.13],[1,1.3,1000],[2,1.08,7.85]],"ltp":2.7,"tv":5.0,"id":31376}]}]}
{"op":"mcm","clk":"11856667130","pt":1723360402854,"mc":[{"id":"1.231582198","rc":[{"batb":[[0,2.36,10],[1,2.34,29.13],[2,1.3,1000]],"ltp":2.7,"tv":5.0,"id":31376}]}]}
{"op":"mcm","clk":"11856667335","pt":1723360406393,"mc":[{"id":"1.231582198","rc":[{"batb":[[0,2.34,29.13],[1,1.3,1000],[2,1.08,7.85]],"ltp":2.7,"tv":5.0,"id":31376}]}]}
{"op":"mcm","clk":"11856667499","pt":1723360409279,"mc":[{"id":"1.231582198","rc":[{"batb":[[0,2.36,10],[1,2.34,29.13],[2,1.3,1000]],"ltp":2.7,"tv":5.0,"id":31376}]}]}
{"op":"mcm","clk":"11856667710","pt":1723360412793,"mc":[{"id":"1.231582198","rc":[{"batb":[[0,2.34,29.13],[1,1.3,1000],[2,1.08,7.85]],"ltp":2.7,"tv":5.0,"id":31376}]}]}
{"op":"mcm","clk":"11856668367","pt":1723360416200,"mc":[{"id":"1.231582198","rc":[{"batb":[[0,2.36,10],[1,2.34,29.13],[2,1.3,1000]],"ltp":2.7,"tv":5.0,"id":31376}]}]}
{"op":"mcm","clk":"11856668549","pt":1723360419570,"mc":[{"id":"1.231582198","rc":[{"batb":[[0,2.34,29.13],[1,1.3,1000],[2,1.08,7.85]],"ltp":2.7,"tv":5.0,"id":31376}]}]}
{"op":"mcm","clk":"11856668711","pt":1723360423006,"mc":[{"id":"1.231582198","rc":[{"batb":[[0,2.36,10],[1,2.34,29.13],[2,1.3,1000]],"ltp":2.7,"tv":5.0,"id":31376}]}]}
{"op":"mcm","clk":"11856668859","pt":1723360426497,"mc":[{"id":"1.231582198","rc":[{"batb":[[0,2.34,29.13],[1,1.3,1000],[2,1.08,7.85]],"ltp":2.7,"tv":5.0,"id":31376}]}]}
{"op":"mcm","clk":"11856668980","pt":1723360429013,"mc":[{"id":"1.231582198","rc":[{"batb":[[0,2.36,10],[1,2.34,29.13],[2,1.3,1000]],"ltp":2.7,"tv":5.0,"id":31376}]}]}
{"op":"mcm","clk":"11856669203","pt":1723360432998,"mc":[{"id":"1.231582198","rc":[{"batb":[[0,2.34,29.13],[1,1.3,1000],[2,1.08,7.85]],"ltp":2.7,"tv":5.0,"id":31376}]}]}
{"op":"mcm","clk":"11856669434","pt":1723360437725,"mc":[{"id":"1.231582198","rc":[{"batb":[[0,2.36,10],[1,2.34,29.13],[2,1.3,1000]],"ltp":2.7,"tv":5.0,"id":31376}]}]}
{"op":"mcm","clk":"11856669615","pt":1723360441032,"mc":[{"id":"1.231582198","rc":[{"trd":[[1.66,9.02]],"batb":[[0,1.65,60.06],[1,1.56,4.56],[2,1.51,4.56]],"ltp":1.66,"tv":632.17,"id":2780},{"batb":[[0,2.34,29.13],[1,1.3,1000],[2,1.08,7.85]],"ltp":2.7,"tv":5.0,"id":31376}],"tv":637.17}]}
{"op":"mcm","clk":"11856669753","pt":1723360443328,"mc":[{"id":"1.231582198","rc":[{"batl":[[0,1.72,8.92]],"ltp":1.66,"tv":632.17,"id":2780},{"batb":[[0,2.36,10],[1,2.34,29.13],[2,1.3,1000]],"ltp":2.7,"tv":5.0,"id":31376}]}]}
{"op":"mcm","clk":"11856669935","pt":1723360446823,"mc":[{"id":"1.231582198","rc":[{"batb":[[0,2.34,29.13],[1,1.3,1000],[2,1.08,7.85]],"ltp":2.7,"tv":5.0,"id":31376}]}]}
{"op":"mcm","clk":"11856670068","pt":1723360449404,"mc":[{"id":"1.231582198","rc":[{"batb":[[0,2.36,10],[1,2.34,29.13],[2,1.3,1000]],"ltp":2.7,"tv":5.0,"id":31376}]}]}
{"op":"mcm","clk":"11856670238","pt":1723360452744,"mc":[{"id":"1.231582198","rc":[{"batb":[[0,2.34,29.13],[1,1.3,1000],[2,1.08,7.85]],"ltp":2.7,"tv":5.0,"id":31376}]}]}
{"op":"mcm","clk":"11856670433","pt":1723360456554,"mc":[{"id":"1.231582198","rc":[{"batb":[[0,2.36,10],[1,2.34,29.13],[2,1.3,1000]],"ltp":2.7,"tv":5.0,"id":31376}]}]}
{"op":"mcm","clk":"11856670504","pt":1723360457750,"mc":[{"id":"1.231582198","rc":[{"batl":[[0,1.71,182.4],[1,1.72,8.92],[2,1.73,20.5]],"ltp":1.66,"tv":632.17,"id":2780}]}]}
{"op":"mcm","clk":"11856670592","pt":1723360459347,"mc":[{"id":"1.231582198","rc":[{"batl":[[0,1.7,4.41],[1,1.71,182.4],[2,1.72,4.56]],"ltp":1.66,"tv":632.17,"id":2780}]}]}
{"op":"mcm","clk":"11856670635","pt":1723360459915,"mc":[{"id":"1.231582198","rc":[{"batb":[[0,2.34,29.13],[1,1.3,1000],[2,1.08,7.85]],"ltp":2.7,"tv":5.0,"id":31376}]}]}
{"op":"mcm","clk":"11856670799","pt":1723360462765,"mc":[{"id":"1.231582198","rc":[{"batb":[[0,2.36,10],[1,2.34,29.13],[2,1.3,1000]],"ltp":2.7,"tv":5.0,"id":31376}]}]}
{"op":"mcm","clk":"11856671018","pt":1723360466241,"mc":[{"id":"1.231582198","rc":[{"batb":[[0,2.34,29.13],[1,1.3,1000],[2,1.08,7.85]],"ltp":2.7,"tv":5.0,"id":31376}]}]}
{"op":"mcm","clk":"11856671199","pt":1723360469228,"mc":[{"id":"1.231582198","rc":[{"batb":[[0,2.36,10],[1,2.34,29.13],[2,1.3,1000]],"ltp":2.7,"tv":5.0,"id":31376}]}]}
{"op":"mcm","clk":"11856671398","pt":1723360472540,"mc":[{"id":"1.231582198","rc":[{"batb":[[0,2.34,29.13],[1,1.3,1000],[2,1.08,7.85]],"ltp":2.7,"tv":5.0,"id":31376}]}]}
{"op":"mcm","clk":"11856671531","pt":1723360474760,"mc":[{"id":"1.231582198","rc":[{"batb":[[0,2.36,10],[1,2.34,29.13],[2,1.3,1000]],"ltp":2.7,"tv":5.0,"id":31376}]}]}
{"op":"mcm","clk":"11856671740","pt":1723360478168,"mc":[{"id":"1.231582198","rc":[{"batb":[[0,2.34,29.13],[1,1.3,1000],[2,1.08,7.85]],"ltp":2.7,"tv":5.0,"id":31376}]}]}
{"op":"mcm","clk":"11856671982","pt":1723360482053,"mc":[{"id":"1.231582198","rc":[{"batb":[[0,2.36,10],[1,2.34,29.13],[2,1.3,1000]],"ltp":2.7,"tv":5.0,"id":31376}]}]}
{"op":"mcm","clk":"11856672161","pt":1723360485456,"mc":[{"id":"1.231582198","rc":[{"batb":[[0,2.34,29.13],[1,1.3,1000],[2,1.08,7.85]],"ltp":2.7,"tv":5.0,"id":31376}]}]}
{"op":"mcm","clk":"11856672293","pt":1723360487763,"mc":[{"id":"1.231582198","rc":[{"batb":[[0,2.36,10],[1,2.34,29.13],[2,1.3,1000]],"ltp":2.7,"tv":5.0,"id":31376}]}]}
{"op":"mcm","clk":"11856672457","pt":1723360491197,"mc":[{"id":"1.231582198","rc":[{"batb":[[0,2.34,29.13],[1,1.3,1000],[2,1.08,7.85]],"ltp":2.7,"tv":5.0,"id":31376}]}]}
{"op":"mcm","clk":"11856672625","pt":1723360494693,"mc":[{"id":"1.231582198","rc":[{"batb":[[0,2.36,10],[1,2.34,29.13],[2,1.3,1000]],"ltp":2.7,"tv":5.0,"id":31376}]}]}
{"op":"mcm","clk":"11856672757","pt":1723360497884,"mc":[{"id":"1.231582198","rc":[{"batb":[[0,2.34,29.13],[1,1.3,1000],[2,1.08,7.85]],"ltp":2.7,"tv":5.0,"id":31376}]}]}
{"op":"mcm","clk":"11856672963","pt":1723360501779,"mc":[{"id":"1.231582198","rc":[{"batb":[[0,2.36,10],[1,2.34,29.13],[2,1.3,1000]],"ltp":2.7,"tv":5.0,"id":31376}]}]}
{"op":"mcm","clk":"11856673177","pt":1723360505218,"mc":[{"id":"1.231582198","rc":[{"trd":[[1.7,8.81],[1.71,364.8]],"batb":[[0,1.71,1.71],[1,1.65,60.06],[2,1.56,4.56]],"batl":[[0,1.72,4.56],[1,1.73,20.5],[2,1.84,4.56]],"ltp":1.71,"tv":1005.78,"id":2780},{"batb":[[0,2.34,29.13],[1,1.3,1000],[2,1.08,7.85]],"ltp":2.7,"tv":5.0,"id":31376}],"tv":1010.78}]}
{"op":"mcm","clk":"11856673207","pt":1723360505885,"mc":[{"id":"1.231582198","rc":[{"batb":[[1,1.66,4.64],[2,1.65,60.06]],"ltp":1.71,"tv":1005.78,"id":2780}]}]}
{"op":"mcm","clk":"11856673333","pt":1723360508497,"mc":[{"id":"1.231582198","rc":[{"batb":[[0,2.36,10],[1,2.34,29.13],[2,1.3,1000]],"ltp":2.7,"tv":5.0,"id":31376}]}]}
{"op":"mcm","clk":"11856673504","pt":1723360511924,"mc":[{"id":"1.231582198","rc":[{"batb":[[0,2.34,29.13],[1,1.3,1000],[2,1.08,7.85]],"ltp":2.7,"tv":5.0,"id":31376}]}]}
{"op":"mcm","clk":"11856673659","pt":1723360515205,"mc":[{"id":"1.231582198","rc":[{"batb":[[0,2.36,10],[1,2.34,29.13],[2,1.3,1000]],"ltp":2.7,"tv":5.0,"id":31376}]}]}
{"op":"mcm","clk":"11856673849","pt":1723360518633,"mc":[{"id":"1.231582198","rc":[{"batb":[[0,2.34,29.13],[1,1.3,1000],[2,1.08,7.85]],"ltp":2.7,"tv":5.0,"id":31376}]}]}
{"op":"mcm","clk":"11856673970","pt":1723360520898,"mc":[{"id":"1.231582198","rc":[{"batb":[[0,2.36,10],[1,2.34,29.13],[2,1.3,1000]],"ltp":2.7,"tv":5.0,"id":31376}]}]}
{"op":"mcm","clk":"11856674128","pt":1723360523312,"mc":[{"id":"1.231582198","rc":[{"trd":[[1.71,368.22]],"batb":[[0,1.66,4.64],[1,1.65,60.06],[2,1.56,4.56]],"batl":[[0,1.71,7.31],[1,1.72,4.56],[2,1.73,20.5]],"ltp":1.71,"tv":1009.2,"id":2780}],"tv":1014.2}]}
{"op":"mcm","clk":"11856674186","pt":1723360524231,"mc":[{"id":"1.231582198","rc":[{"batb":[[0,2.34,29.13],[1,1.3,1000],[2,1.08,7.85]],"ltp":2.7,"tv":5.0,"id":31376}]}]}
{"op":"mcm","clk":"11856674523","pt":1723360530140,"mc":[{"id":"1.231582198","rc":[{"batb":[[0,2.36,10],[1,2.34,29.13],[2,1.3,1000]],"ltp":2.7,"tv":5.0,"id":31376}]}]}
{"op":"mcm","clk":"11856674709","pt":1723360533420,"mc":[{"id":"1.231582198","rc":[{"batb":[[0,2.34,29.13],[1,1.3,1000],[2,1.08,7.85]],"ltp":2.7,"tv":5.0,"id":31376}]}]}
{"op":"mcm","clk":"11856674909","pt":1723360536756,"mc":[{"id":"1.231582198","rc":[{"batb":[[0,2.36,10],[1,2.34,29.13],[2,1.3,1000]],"ltp":2.7,"tv":5.0,"id":31376}]}]}
{"op":"mcm","clk":"11856675029","pt":1723360538809,"mc":[{"id":"1.231582198","rc":[{"batl":[[0,1.72,4.56],[1,1.73,20.5],[2,1.84,4.56]],"ltp":1.71,"tv":1009.2,"id":2780}]}]}
{"op":"mcm","clk":"11856675103","pt":1723360540549,"mc":[{"id":"1.231582198","rc":[{"batb":[[0,2.34,29.13],[1,1.3,1000],[2,1.08,7.85]],"ltp":2.7,"tv":5.0,"id":31376}]}]}
{"op":"mcm","clk":"11856675228","pt":1723360543125,"mc":[{"id":"1.231582198","rc":[{"batb":[[0,2.36,10],[1,2.34,29.13],[2,1.3,1000]],"ltp":2.7,"tv":5.0,"id":31376}]}]}
{"op":"mcm","clk":"11856675440","pt":1723360546715,"mc":[{"id":"1.231582198","rc":[{"batb":[[0,2.34,29.13],[1,1.3,1000],[2,1.08,7.85]],"ltp":2.7,"tv":5.0,"id":31376}]}]}
{"op":"mcm","clk":"11856675541","pt":1723360548817,"mc":[{"id":"1.231582198","rc":[{"batb":[[0,2.36,10],[1,2.34,29.13],[2,1.3,1000]],"ltp":2.7,"tv":5.0,"id":31376}]}]}
{"op":"mcm","clk":"11856675729","pt":1723360552357,"mc":[{"id":"1.231582198","rc":[{"batb":[[0,2.34,29.13],[1,1.3,1000],[2,1.08,7.85]],"ltp":2.7,"tv":5.0,"id":31376}]}]}
{"op":"mcm","clk":"11856675910","pt":1723360555635,"mc":[{"id":"1.231582198","rc":[{"batb":[[0,2.36,10],[1,2.34,29.13],[2,1.3,1000]],"ltp":2.7,"tv":5.0,"id":31376}]}]}
{"op":"mcm","clk":"11856676050","pt":1723360558964,"mc":[{"id":"1.231582198","rc":[{"batb":[[0,2.34,29.13],[1,1.3,1000],[2,1.08,7.85]],"ltp":2.7,"tv":5.0,"id":31376}]}]}
{"op":"mcm","clk":"11856676239","pt":1723360561542,"mc":[{"id":"1.231582198","rc":[{"batb":[[0,2.36,10],[1,2.34,29.13],[2,1.3,1000]],"ltp":2.7,"tv":5.0,"id":31376}]}]}
{"op":"mcm","clk":"11856676456","pt":1723360565046,"mc":[{"id":"1.231582198","rc":[{"batb":[[0,2.34,29.13],[1,1.3,1000],[2,1.08,7.85]],"ltp":2.7,"tv":5.0,"id":31376}]}]}
{"op":"mcm","clk":"11856676703","pt":1723360570083,"mc":[{"id":"1.231582198","rc":[{"batb":[[0,2.36,10],[1,2.34,29.13],[2,1.3,1000]],"ltp":2.7,"tv":5.0,"id":31376}]}]}
{"op":"mcm","clk":"11856676872","pt":1723360573467,"mc":[{"id":"1.231582198","rc":[{"batb":[[0,2.34,29.13],[1,1.3,1000],[2,1.08,7.85]],"ltp":2.7,"tv":5.0,"id":31376}]}]}
{"op":"mcm","clk":"11856677016","pt":1723360575881,"mc":[{"id":"1.231582198","rc":[{"batb":[[0,2.36,10],[1,2.34,29.13],[2,1.3,1000]],"ltp":2.7,"tv":5.0,"id":31376}]}]}
{"op":"mcm","clk":"11856677181","pt":1723360579461,"mc":[{"id":"1.231582198","rc":[{"batb":[[0,2.34,29.13],[1,1.3,1000],[2,1.08,7.85]],"ltp":2.7,"tv":5.0,"id":31376}]}]}
{"op":"mcm","clk":"11856677290","pt":1723360582079,"mc":[{"id":"1.231582198","rc":[{"batb":[[0,2.36,10],[1,2.34,29.13],[2,1.3,1000]],"ltp":2.7,"tv":5.0,"id":31376}]}]}
{"op":"mcm","clk":"11856677409","pt":1723360584485,"mc":[{"id":"1.231582198","rc":[{"trd":[[1.72,9.12],[1.73,41],[1.74,13.57],[1.75,32.06]],"batl":[[0,1.84,4.56],[1,1.85,100],[2,1.86,200]],"ltp":1.75,"tv":1104.95,"id":2780},{"trd":[[2.34,23.98],[2.36,10]],"batb":[[0,2.34,34.28],[1,1.3,1000],[2,1.08,7.85]],"ltp":2.34,"tv":38.98,"id":31376}],"tv":1143.93}]}
{"op":"mcm","clk":"11856677412","pt":1723360584588,"mc":[{"id":"1.231582198","rc":[{"batb":[[0,2.34,29.13]],"ltp":2.34,"tv":38.98,"id":31376}]}]}
{"op":"mcm","clk":"11856677553","pt":1723360587303,"mc":[{"id":"1.231582198","rc":[{"batb":[[0,2.36,10],[1,2.34,29.13],[2,1.3,1000]],"ltp":2.34,"tv":38.98,"id":31376}]}]}
{"op":"mcm","clk":"11856677677","pt":1723360590580,"mc":[{"id":"1.231582198","rc":[{"batb":[[0,2.34,29.13],[1,1.3,1000],[2,1.08,7.85]],"ltp":2.34,"tv":38.98,"id":31376}]}]}
{"op":"mcm","clk":"11856677766","pt":1723360592887,"mc":[{"id":"1.231582198","rc":[{"batb":[[0,2.36,10],[1,2.34,29.13],[2,1.3,1000]],"ltp":2.34,"tv":38.98,"id":31376}]}]}
{"op":"mcm","clk":"11856677934","pt":1723360596585,"mc":[{"id":"1.231582198","rc":[{"batb":[[0,2.34,29.13],[1,1.3,1000],[2,1.08,7.85]],"ltp":2.34,"tv":38.98,"id":31376}]}]}
{"op":"mcm","clk":"11856678043","pt":1723360598951,"mc":[{"id":"1.231582198","rc":[{"batb":[[0,2.36,10],[1,2.34,29.13],[2,1.3,1000]],"ltp":2.34,"tv":38.98,"id":31376}]}]}
{"op":"mcm","clk":"11856678214","pt":1723360602279,"mc":[{"id":"1.231582198","rc":[{"batb":[[0,2.34,29.13],[1,1.3,1000],[2,1.08,7.85]],"ltp":2.34,"tv":38.98,"id":31376}]}]}
{"op":"mcm","clk":"11856678355","pt":1723360604990,"mc":[{"id":"1.231582198","rc":[{"batb":[[0,2.36,10],[1,2.34,29.13],[2,1.3,1000]],"ltp":2.34,"tv":38.98,"id":31376}]}]}
{"op":"mcm","clk":"11856678512","pt":1723360608329,"mc":[{"id":"1.231582198","rc":[{"batb":[[0,2.34,29.13],[1,1.3,1000],[2,1.08,7.85]],"ltp":2.34,"tv":38.98,"id":31376}]}]}
{"op":"mcm","clk":"11856678614","pt":1723360610839,"mc":[{"id":"1.231582198","rc":[{"batb":[[0,2.36,10],[1,2.34,29.13],[2,1.3,1000]],"ltp":2.34,"tv":38.98,"id":31376}]}]}
{"op":"mcm","clk":"11856678779","pt":1723360614122,"mc":[{"id":"1.231582198","rc":[{"batb":[[0,2.34,29.13],[1,1.3,1000],[2,1.08,7.85]],"ltp":2.34,"tv":38.98,"id":31376}]}]}
{"op":"mcm","clk":"11856678916","pt":1723360617152,"mc":[{"id":"1.231582198","rc":[{"batb":[[0,2.36,10],[1,2.34,29.13],[2,1.3,1000]],"ltp":2.34,"tv":38.98,"id":31376}]}]}
{"op":"mcm","clk":"11856679073","pt":1723360620458,"mc":[{"id":"1.231582198","rc":[{"batb":[[0,2.34,29.13],[1,1.3,1000],[2,1.08,7.85]],"ltp":2.34,"tv":38.98,"id":31376}]}]}
{"op":"mcm","clk":"11856679261","pt":1723360624053,"mc":[{"id":"1.231582198","rc":[{"batb":[[0,2.36,10],[1,2.34,29.13],[2,1.3,1000]],"ltp":2.34,"tv":38.98,"id":31376}]}]}
{"op":"mcm","clk":"11856679405","pt":1723360627437,"mc":[{"id":"1.231582198","rc":[{"batb":[[0,2.34,29.13],[1,1.3,1000],[2,1.08,7.85]],"ltp":2.34,"tv":38.98,"id":31376}]}]}
{"op":"mcm","clk":"11856679571","pt":1723360630847,"mc":[{"id":"1.231582198","rc":[{"batb":[[0,2.36,10],[1,2.34,29.13],[2,1.3,1000]],"ltp":2.34,"tv":38.98,"id":31376}]}]}
{"op":"mcm","clk":"11856679762","pt":1723360634337,"mc":[{"id":"1.231582198","rc":[{"batb":[[0,2.34,29.13],[1,1.3,1000],[2,1.08,7.85]],"ltp":2.34,"tv":38.98,"id":31376}]}]}
{"op":"mcm","clk":"11856679892","pt":1723360637269,"mc":[{"id":"1.231582198","rc":[{"batb":[[0,2.36,10],[1,2.34,29.13],[2,1.3,1000]],"ltp":2.34,"tv":38.98,"id":31376}]}]}
{"op":"mcm","clk":"11856680032","pt":1723360640563,"mc":[{"id":"1.231582198","rc":[{"batb":[[0,2.34,29.13],[1,1.3,1000],[2,1.08,7.85]],"ltp":2.34,"tv":38.98,"id":31376}]}]}
{"op":"mcm","clk":"11856680320","pt":1723360646353,"mc":[{"id":"1.231582198","rc":[{"batb":[[0,2.36,10],[1,2.34,29.13],[2,1.3,1000]],"ltp":2.34,"tv":38.98,"id":31376}]}]}
{"op":"mcm","clk":"11856680466","pt":1723360649789,"mc":[{"id":"1.231582198","rc":[{"batb":[[0,2.34,29.13],[1,1.3,1000],[2,1.08,7.85]],"ltp":2.34,"tv":38.98,"id":31376}]}]}
{"op":"mcm","clk":"11856680574","pt":1723360651964,"mc":[{"id":"1.231582198","rc":[{"batb":[[0,2.36,10],[1,2.34,29.13],[2,1.3,1000]],"ltp":2.34,"tv":38.98,"id":31376}]}]}
{"op":"mcm","clk":"11856680734","pt":1723360655397,"mc":[{"id":"1.231582198","rc":[{"batb":[[0,2.34,29.13],[1,1.3,1000],[2,1.08,7.85]],"ltp":2.34,"tv":38.98,"id":31376}]}]}
{"op":"mcm","clk":"11856680866","pt":1723360657763,"mc":[{"id":"1.231582198","rc":[{"batb":[[0,2.36,10],[1,2.34,29.13],[2,1.3,1000]],"ltp":2.34,"tv":38.98,"id":31376}]}]}
{"op":"mcm","clk":"11856680994","pt":1723360661093,"mc":[{"id":"1.231582198","rc":[{"batb":[[0,2.34,29.13],[1,1.3,1000],[2,1.08,7.85]],"ltp":2.34,"tv":38.98,"id":31376}]}]}
{"op":"mcm","clk":"11856681154","pt":1723360664072,"mc":[{"id":"1.231582198","rc":[{"batb":[[0,2.36,10],[1,2.34,29.13],[2,1.3,1000]],"ltp":2.34,"tv":38.98,"id":31376}]}]}
{"op":"mcm","clk":"11856681340","pt":1723360667504,"mc":[{"id":"1.231582198","rc":[{"batb":[[0,2.34,29.13],[1,1.3,1000],[2,1.08,7.85]],"ltp":2.34,"tv":38.98,"id":31376}]}]}
{"op":"mcm","clk":"11856681464","pt":1723360670223,"mc":[{"id":"1.231582198","rc":[{"batb":[[0,2.36,10],[1,2.34,29.13],[2,1.3,1000]],"ltp":2.34,"tv":38.98,"id":31376}]}]}
{"op":"mcm","clk":"11856681632","pt":1723360673710,"mc":[{"id":"1.231582198","rc":[{"batl":[[0,1.74,111.35],[1,1.84,4.56],[2,1.85,100]],"ltp":1.75,"tv":1104.95,"id":2780},{"batb":[[0,2.34,29.13],[1,1.3,1000],[2,1.08,7.85]],"ltp":2.34,"tv":38.98,"id":31376}]}]}
{"op":"mcm","clk":"11856681828","pt":1723360676984,"mc":[{"id":"1.231582198","rc":[{"batb":[[0,2.36,10],[1,2.34,29.13],[2,1.3,1000]],"ltp":2.34,"tv":38.98,"id":31376}]}]}
{"op":"mcm","clk":"11856681959","pt":1723360679912,"mc":[{"id":"1.231582198","rc":[{"batb":[[0,2.34,29.13],[1,1.3,1000],[2,1.08,7.85]],"ltp":2.34,"tv":38.98,"id":31376}]}]}
{"op":"mcm","clk":"11856682120","pt":1723360682893,"mc":[{"id":"1.231582198","rc":[{"batb":[[0,2.36,10],[1,2.34,29.13],[2,1.3,1000]],"ltp":2.34,"tv":38.98,"id":31376}]}]}
{"op":"mcm","clk":"11856682319","pt":1723360686395,"mc":[{"id":"1.231582198","rc":[{"batb":[[0,2.34,29.13],[1,1.3,1000],[2,1.08,7.85]],"ltp":2.34,"tv":38.98,"id":31376}]}]}
{"op":"mcm","clk":"11856682434","pt":1723360688817,"mc":[{"id":"1.231582198","rc":[{"batb":[[0,2.36,10],[1,2.34,29.13],[2,1.3,1000]],"ltp":2.34,"tv":38.98,"id":31376}]}]}
{"op":"mcm","clk":"11856682585","pt":1723360692203,"mc":[{"id":"1.231582198","rc":[{"batb":[[0,2.34,29.13],[1,1.3,1000],[2,1.08,7.85]],"ltp":2.34,"tv":38.98,"id":31376}]}]}
{"op":"mcm","clk":"11856682732","pt":1723360695124,"mc":[{"id":"1.231582198","rc":[{"batb":[[0,2.36,10],[1,2.34,29.13],[2,1.3,1000]],"ltp":2.34,"tv":38.98,"id":31376}]}]}
{"op":"mcm","clk":"11856682908","pt":1723360698409,"mc":[{"id":"1.231582198","rc":[{"batb":[[0,2.34,29.13],[1,1.3,1000],[2,1.08,7.85]],"ltp":2.34,"tv":38.98,"id":31376}]}]}
{"op":"mcm","clk":"11856683031","pt":1723360700617,"mc":[{"id":"1.231582198","rc":[{"batb":[[0,2.36,10],[1,2.34,29.13],[2,1.3,1000]],"ltp":2.34,"tv":38.98,"id":31376}]}]}
{"op":"mcm","clk":"11856683171","pt":1723360704047,"mc":[{"id":"1.231582198","rc":[{"batb":[[0,2.34,29.13],[1,1.3,1000],[2,1.08,7.85]],"ltp":2.34,"tv":38.98,"id":31376}]}]}
{"op":"mcm","clk":"11856683250","pt":1723360705740,"mc":[{"id":"1.231582198","rc":[{"batl":[[0,1.73,8.36],[1,1.74,111.35],[2,1.84,4.56]],"ltp":1.75,"tv":1104.95,"id":2780}]}]}
{"op":"mcm","clk":"11856683439","pt":1723360709845,"mc":[{"id":"1.231582198","rc":[{"batb":[[0,2.36,10],[1,2.34,29.13],[2,1.3,1000]],"ltp":2.34,"tv":38.98,"id":31376}]}]}
{"op":"mcm","clk":"11856683611","pt":1723360713332,"mc":[{"id":"1.231582198","rc":[{"batb":[[0,2.34,29.13],[1,1.3,1000],[2,1.08,7.85]],"ltp":2.34,"tv":38.98,"id":31376}]}]}
{"op":"mcm","clk":"11856683842","pt":1723360717366,"mc":[{"id":"1.231582198","rc":[{"batb":[[0,2.36,10],[1,2.34,29.13],[2,1.3,1000]],"ltp":2.34,"tv":38.98,"id":31376}]}]}
{"op":"mcm","clk":"11856684022","pt":1723360720849,"mc":[{"id":"1.231582198","rc":[{"batb":[[0,2.34,29.13],[1,1.3,1000],[2,1.08,7.85]],"ltp":2.34,"tv":38.98,"id":31376}]}]}
{"op":"mcm","clk":"11856684134","pt":1723360723456,"mc":[{"id":"1.231582198","rc":[{"batb":[[0,2.36,10],[1,2.34,29.13],[2,1.3,1000]],"ltp":2.34,"tv":38.98,"id":31376}]}]}
{"op":"mcm","clk":"11856684267","pt":1723360726585,"mc":[{"id":"1.231582198","rc":[{"batb":[[0,2.34,29.13],[1,1.3,1000],[2,1.08,7.85]],"ltp":2.34,"tv":38.98,"id":31376}]}]}
{"op":"mcm","clk":"11856684322","pt":1723360727568,"mc":[{"id":"1.231582198","rc":[{"batl":[[1,1.84,4.56],[2,1.85,100]],"ltp":1.75,"tv":1104.95,"id":2780}]}]}
{"op":"mcm","clk":"11856684398","pt":1723360729157,"mc":[{"id":"1.231582198","rc":[{"batb":[[0,2.36,10],[1,2.34,29.13],[2,1.3,1000]],"ltp":2.34,"tv":38.98,"id":31376}]}]}
{"op":"mcm","clk":"11856684433","pt":1723360729979,"mc":[{"id":"1.231582198","rc":[{"batl":[[0,1.84,4.56],[1,1.85,100],[2,1.86,200]],"ltp":1.75,"tv":1104.95,"id":2780}]}]}
{"op":"mcm","clk":"11856684574","pt":1723360732595,"mc":[{"id":"1.231582198","rc":[{"batb":[[0,2.34,29.13],[1,1.3,1000],[2,1.08,7.85]],"ltp":2.34,"tv":38.98,"id":31376}]}]}
{"op":"mcm","clk":"11856684691","pt":1723360734954,"mc":[{"id":"1.231582198","rc":[{"batb":[[0,2.36,10],[1,2.34,29.13],[2,1.3,1000]],"ltp":2.34,"tv":38.98,"id":31376}]}]}
{"op":"mcm","clk":"11856684845","pt":1723360738183,"mc":[{"id":"1.231582198","rc":[{"batb":[[0,2.34,29.13],[1,1.3,1000],[2,1.08,7.85]],"ltp":2.34,"tv":38.98,"id":31376}]}]}
{"op":"mcm","clk":"11856684974","pt":1723360740902,"mc":[{"id":"1.231582198","rc":[{"batb":[[0,2.36,10],[1,2.34,29.13],[2,1.3,1000]],"ltp":2.34,"tv":38.98,"id":31376}]}]}
{"op":"mcm","clk":"11856685177","pt":1723360744198,"mc":[{"id":"1.231582198","rc":[{"batb":[[0,2.34,29.13],[1,1.3,1000],[2,1.08,7.85]],"ltp":2.34,"tv":38.98,"id":31376}]}]}
{"op":"mcm","clk":"11856685340","pt":1723360746879,"mc":[{"id":"1.231582198","rc":[{"batb":[[0,2.36,10],[1,2.34,29.13],[2,1.3,1000]],"ltp":2.34,"tv":38.98,"id":31376}]}]}
{"op":"mcm","clk":"11856685506","pt":1723360750311,"mc":[{"id":"1.231582198","rc":[{"batb":[[0,2.34,29.13],[1,1.3,1000],[2,1.08,7.85]],"ltp":2.34,"tv":38.98,"id":31376}]}]}
{"op":"mcm","clk":"11856685641","pt":1723360752775,"mc":[{"id":"1.231582198","rc":[{"batb":[[0,2.36,10],[1,2.34,29.13],[2,1.3,1000]],"ltp":2.34,"tv":38.98,"id":31376}]}]}
{"op":"mcm","clk":"11856685800","pt":1723360755984,"mc":[{"id":"1.231582198","rc":[{"batb":[[0,2.34,29.13],[1,1.3,1000],[2,1.08,7.85]],"ltp":2.34,"tv":38.98,"id":31376}]}]}
{"op":"mcm","clk":"11856685899","pt":1723360758199,"mc":[{"id":"1.231582198","rc":[{"batb":[[0,2.36,10],[1,2.34,29.13],[2,1.3,1000]],"ltp":2.34,"tv":38.98,"id":31376}]}]}
{"op":"mcm","clk":"11856686061","pt":1723360761626,"mc":[{"id":"1.231582198","rc":[{"batb":[[0,2.34,29.13],[1,1.3,1000],[2,1.08,7.85]],"ltp":2.34,"tv":38.98,"id":31376}]}]}
{"op":"mcm","clk":"11856686206","pt":1723360764915,"mc":[{"id":"1.231582198","rc":[{"batb":[[0,2.36,10],[1,2.34,29.13],[2,1.3,1000]],"ltp":2.34,"tv":38.98,"id":31376}]}]}
{"op":"mcm","clk":"11856686355","pt":1723360768423,"mc":[{"id":"1.231582198","rc":[{"batb":[[0,2.34,29.13],[1,1.3,1000],[2,1.08,7.85]],"ltp":2.34,"tv":38.98,"id":31376}]}]}
{"op":"mcm","clk":"11856686515","pt":1723360771817,"mc":[{"id":"1.231582198","rc":[{"batb":[[0,2.36,10],[1,2.34,29.13],[2,1.3,1000]],"ltp":2.34,"tv":38.98,"id":31376}]}]}
{"op":"mcm","clk":"11856686685","pt":1723360775154,"mc":[{"id":"1.231582198","rc":[{"batb":[[0,2.34,29.13],[1,1.3,1000],[2,1.08,7.85]],"ltp":2.34,"tv":38.98,"id":31376}]}]}
{"op":"mcm","clk":"11856686898","pt":1723360779122,"mc":[{"id":"1.231582198","rc":[{"batb":[[0,2.36,10],[1,2.34,29.13],[2,1.3,1000]],"ltp":2.34,"tv":38.98,"id":31376}]}]}
{"op":"mcm","clk":"11856687060","pt":1723360782435,"mc":[{"id":"1.231582198","rc":[{"batb":[[0,2.34,29.13],[1,1.3,1000],[2,1.08,7.85]],"ltp":2.34,"tv":38.98,"id":31376}]}]}
{"op":"mcm","clk":"11856687196","pt":1723360785529,"mc":[{"id":"1.231582198","rc":[{"batb":[[0,2.36,10],[1,2.34,29.13],[2,1.3,1000]],"ltp":2.34,"tv":38.98,"id":31376}]}]}
{"op":"mcm","clk":"11856687344","pt":1723360788867,"mc":[{"id":"1.231582198","rc":[{"batb":[[0,2.34,29.13],[1,1.3,1000],[2,1.08,7.85]],"ltp":2.34,"tv":38.98,"id":31376}]}]}
{"op":"mcm","clk":"11856687434","pt":1723360790968,"mc":[{"id":"1.231582198","rc":[{"batb":[[0,2.36,10],[1,2.34,29.13],[2,1.3,1000]],"ltp":2.34,"tv":38.98,"id":31376}]}]}
{"op":"mcm","clk":"11856687598","pt":1723360794145,"mc":[{"id":"1.231582198","rc":[{"batb":[[0,2.34,29.13],[1,1.3,1000],[2,1.08,7.85]],"ltp":2.34,"tv":38.98,"id":31376}]}]}
{"op":"mcm","clk":"11856687768","pt":1723360797067,"mc":[{"id":"1.231582198","rc":[{"batb":[[0,2.36,10],[1,2.34,29.13],[2,1.3,1000]],"ltp":2.34,"tv":38.98,"id":31376}]}]}
{"op":"mcm","clk":"11856687924","pt":1723360800463,"mc":[{"id":"1.231582198","rc":[{"batb":[[0,2.34,29.13],[1,1.3,1000],[2,1.08,7.85]],"ltp":2.34,"tv":38.98,"id":31376}]}]}
{"op":"mcm","clk":"11856688063","pt":1723360802785,"mc":[{"id":"1.231582198","rc":[{"batb":[[0,2.36,10],[1,2.34,29.13],[2,1.3,1000]],"ltp":2.34,"tv":38.98,"id":31376}]}]}
{"op":"mcm","clk":"11856688244","pt":1723360806181,"mc":[{"id":"1.231582198","rc":[{"batb":[[0,2.34,29.13],[1,1.3,1000],[2,1.08,7.85]],"ltp":2.34,"tv":38.98,"id":31376}]}]}
{"op":"mcm","clk":"11856688358","pt":1723360808391,"mc":[{"id":"1.231582198","rc":[{"batb":[[0,2.36,10],[1,2.34,29.13],[2,1.3,1000]],"ltp":2.34,"tv":38.98,"id":31376}]}]}
{"op":"mcm","clk":"11856688546","pt":1723360811674,"mc":[{"id":"1.231582198","rc":[{"batb":[[0,2.34,29.13],[1,1.3,1000],[2,1.08,7.85]],"ltp":2.34,"tv":38.98,"id":31376}]}]}
{"op":"mcm","clk":"11856688738","pt":1723360814961,"mc":[{"id":"1.231582198","rc":[{"batb":[[0,2.36,10],[1,2.34,29.13],[2,1.3,1000]],"ltp":2.34,"tv":38.98,"id":31376}]}]}
{"op":"mcm","clk":"11856688913","pt":1723360818602,"mc":[{"id":"1.231582198","rc":[{"batb":[[0,2.34,29.13],[1,1.3,1000],[2,1.08,7.85]],"ltp":2.34,"tv":38.98,"id":31376}]}]}
{"op":"mcm","clk":"11856689081","pt":1723360821829,"mc":[{"id":"1.231582198","rc":[{"batb":[[0,2.36,10],[1,2.34,29.13],[2,1.3,1000]],"ltp":2.34,"tv":38.98,"id":31376}]}]}
{"op":"mcm","clk":"11856689292","pt":1723360825432,"mc":[{"id":"1.231582198","rc":[{"batb":[[0,2.34,29.13],[1,1.3,1000],[2,1.08,7.85]],"ltp":2.34,"tv":38.98,"id":31376}]}]}
{"op":"mcm","clk":"11856689429","pt":1723360827790,"mc":[{"id":"1.231582198","rc":[{"batb":[[0,2.36,10],[1,2.34,29.13],[2,1.3,1000]],"ltp":2.34,"tv":38.98,"id":31376}]}]}
{"op":"mcm","clk":"11856689577","pt":1723360831124,"mc":[{"id":"1.231582198","rc":[{"batb":[[0,2.34,29.13],[1,1.3,1000],[2,1.08,7.85]],"ltp":2.34,"tv":38.98,"id":31376}]}]}
{"op":"mcm","clk":"11856689737","pt":1723360833799,"mc":[{"id":"1.231582198","rc":[{"batb":[[0,2.36,10],[1,2.34,29.13],[2,1.3,1000]],"ltp":2.34,"tv":38.98,"id":31376}]}]}
{"op":"mcm","clk":"11856689893","pt":1723360837229,"mc":[{"id":"1.231582198","rc":[{"batb":[[0,2.34,29.13],[1,1.3,1000],[2,1.08,7.85]],"ltp":2.34,"tv":38.98,"id":31376}]}]}
{"op":"mcm","clk":"11856690063","pt":1723360840314,"mc":[{"id":"1.231582198","rc":[{"batb":[[0,2.36,10],[1,2.34,29.13],[2,1.3,1000]],"ltp":2.34,"tv":38.98,"id":31376}]}]}
{"op":"mcm","clk":"11856690257","pt":1723360843951,"mc":[{"id":"1.231582198","rc":[{"batb":[[0,2.34,29.13],[1,1.3,1000],[2,1.08,7.85]],"ltp":2.34,"tv":38.98,"id":31376}]}]}
{"op":"mcm","clk":"11856690505","pt":1723360847931,"mc":[{"id":"1.231582198","rc":[{"batb":[[0,2.36,10],[1,2.34,29.13],[2,1.3,1000]],"ltp":2.34,"tv":38.98,"id":31376}]}]}
{"op":"mcm","clk":"11856690672","pt":1723360851322,"mc":[{"id":"1.231582198","rc":[{"batb":[[0,2.34,29.13],[1,1.3,1000],[2,1.08,7.85]],"ltp":2.34,"tv":38.98,"id":31376}]}]}
{"op":"mcm","clk":"11856690858","pt":1723360854250,"mc":[{"id":"1.231582198","rc":[{"batb":[[0,2.36,10],[1,2.34,29.13],[2,1.3,1000]],"ltp":2.34,"tv":38.98,"id":31376}]}]}
{"op":"mcm","clk":"11856691075","pt":1723360857544,"mc":[{"id":"1.231582198","rc":[{"batb":[[0,2.34,29.13],[1,1.3,1000],[2,1.08,7.85]],"ltp":2.34,"tv":38.98,"id":31376}]}]}
{"op":"mcm","clk":"11856691205","pt":1723360860157,"mc":[{"id":"1.231582198","rc":[{"batb":[[0,2.36,10],[1,2.34,29.13],[2,1.3,1000]],"ltp":2.34,"tv":38.98,"id":31376}]}]}
{"op":"mcm","clk":"11856691442","pt":1723360863455,"mc":[{"id":"1.231582198","rc":[{"batb":[[0,2.34,29.13],[1,1.3,1000],[2,1.08,7.85]],"ltp":2.34,"tv":38.98,"id":31376}]}]}
{"op":"mcm","clk":"11856691623","pt":1723360865932,"mc":[{"id":"1.231582198","rc":[{"batb":[[0,2.36,10],[1,2.34,29.13],[2,1.3,1000]],"ltp":2.34,"tv":38.98,"id":31376}]}]}
{"op":"mcm","clk":"11856691843","pt":1723360869279,"mc":[{"id":"1.231582198","rc":[{"batb":[[0,2.34,29.13],[1,1.3,1000],[2,1.08,7.85]],"ltp":2.34,"tv":38.98,"id":31376}]}]}
{"op":"mcm","clk":"11856691976","pt":1723360871585,"mc":[{"id":"1.231582198","rc":[{"batb":[[0,2.36,10],[1,2.34,29.13],[2,1.3,1000]],"ltp":2.34,"tv":38.98,"id":31376}]}]}
{"op":"mcm","clk":"11856692138","pt":1723360874768,"mc":[{"id":"1.231582198","rc":[{"batb":[[0,2.34,29.13],[1,1.3,1000],[2,1.08,7.85]],"ltp":2.34,"tv":38.98,"id":31376}]}]}
{"op":"mcm","clk":"11856692382","pt":1723360878265,"mc":[{"id":"1.231582198","rc":[{"batb":[[0,2.36,10],[1,2.34,29.13],[2,1.3,1000]],"ltp":2.34,"tv":38.98,"id":31376}]}]}
{"op":"mcm","clk":"11856692605","pt":1723360881776,"mc":[{"id":"1.231582198","rc":[{"batb":[[0,2.34,29.13],[1,1.3,1000],[2,1.08,7.85]],"ltp":2.34,"tv":38.98,"id":31376}]}]}
{"op":"mcm","clk":"11856692833","pt":1723360885574,"mc":[{"id":"1.231582198","rc":[{"batb":[[0,2.36,10],[1,2.34,29.13],[2,1.3,1000]],"ltp":2.34,"tv":38.98,"id":31376}]}]}
{"op":"mcm","clk":"11856693006","pt":1723360889209,"mc":[{"id":"1.231582198","rc":[{"batb":[[0,2.34,29.13],[1,1.3,1000],[2,1.08,7.85]],"ltp":2.34,"tv":38.98,"id":31376}]}]}
{"op":"mcm","clk":"11856693316","pt":1723360894806,"mc":[{"id":"1.231582198","rc":[{"batb":[[0,2.36,10],[1,2.34,29.13],[2,1.3,1000]],"ltp":2.34,"tv":38.98,"id":31376}]}]}
{"op":"mcm","clk":"11856693516","pt":1723360898191,"mc":[{"id":"1.231582198","rc":[{"batb":[[0,2.34,29.13],[1,1.3,1000],[2,1.08,7.85]],"ltp":2.34,"tv":38.98,"id":31376}]}]}
{"op":"mcm","clk":"11856693657","pt":1723360900709,"mc":[{"id":"1.231582198","rc":[{"batb":[[0,2.36,10],[1,2.34,29.13],[2,1.3,1000]],"ltp":2.34,"tv":38.98,"id":31376}]}]}
{"op":"mcm","clk":"11856693872","pt":1723360904004,"mc":[{"id":"1.231582198","rc":[{"batb":[[0,2.34,29.13],[1,1.3,1000],[2,1.08,7.85]],"ltp":2.34,"tv":38.98,"id":31376}]}]}
{"op":"mcm","clk":"11856694059","pt":1723360906887,"mc":[{"id":"1.231582198","rc":[{"batb":[[0,2.36,10],[1,2.34,29.13],[2,1.3,1000]],"ltp":2.34,"tv":38.98,"id":31376}]}]}
{"op":"mcm","clk":"11856694238","pt":1723360910225,"mc":[{"id":"1.231582198","rc":[{"batb":[[0,2.34,29.13],[1,1.3,1000],[2,1.08,7.85]],"ltp":2.34,"tv":38.98,"id":31376}]}]}
{"op":"mcm","clk":"11856694422","pt":1723360913318,"mc":[{"id":"1.231582198","rc":[{"batb":[[0,2.36,10],[1,2.34,29.13],[2,1.3,1000]],"ltp":2.34,"tv":38.98,"id":31376}]}]}
{"op":"mcm","clk":"11856694629","pt":1723360916709,"mc":[{"id":"1.231582198","rc":[{"batb":[[0,2.34,29.13],[1,1.3,1000],[2,1.08,7.85]],"ltp":2.34,"tv":38.98,"id":31376}]}]}
{"op":"mcm","clk":"11856694753","pt":1723360918924,"mc":[{"id":"1.231582198","rc":[{"batb":[[0,2.36,10],[1,2.34,29.13],[2,1.3,1000]],"ltp":2.34,"tv":38.98,"id":31376}]}]}
{"op":"mcm","clk":"11856694976","pt":1723360922741,"mc":[{"id":"1.231582198","rc":[{"batb":[[0,2.34,29.13],[1,1.3,1000],[2,1.08,7.85]],"ltp":2.34,"tv":38.98,"id":31376}]}]}
{"op":"mcm","clk":"11856695121","pt":1723360925924,"mc":[{"id":"1.231582198","rc":[{"batb":[[0,2.36,10],[1,2.34,29.13],[2,1.3,1000]],"ltp":2.34,"tv":38.98,"id":31376}]}]}
{"op":"mcm","clk":"11856695303","pt":1723360929264,"mc":[{"id":"1.231582198","rc":[{"batb":[[0,2.34,29.13],[1,1.3,1000],[2,1.08,7.85]],"ltp":2.34,"tv":38.98,"id":31376}]}]}
{"op":"mcm","clk":"11856695473","pt":1723360932757,"mc":[{"id":"1.231582198","rc":[{"batb":[[0,2.36,10],[1,2.34,29.13],[2,1.3,1000]],"ltp":2.34,"tv":38.98,"id":31376}]}]}
{"op":"mcm","clk":"11856695662","pt":1723360936146,"mc":[{"id":"1.231582198","rc":[{"batb":[[0,2.34,29.13],[1,1.3,1000],[2,1.08,7.85]],"ltp":2.34,"tv":38.98,"id":31376}]}]}
{"op":"mcm","clk":"11856695790","pt":1723360938460,"mc":[{"id":"1.231582198","rc":[{"batb":[[0,2.36,10],[1,2.34,29.13],[2,1.3,1000]],"ltp":2.34,"tv":38.98,"id":31376}]}]}
{"op":"mcm","clk":"11856695997","pt":1723360941644,"mc":[{"id":"1.231582198","rc":[{"batb":[[0,2.34,29.13],[1,1.3,1000],[2,1.08,7.85]],"ltp":2.34,"tv":38.98,"id":31376}]}]}
{"op":"mcm","clk":"11856696163","pt":1723360944467,"mc":[{"id":"1.231582198","rc":[{"batb":[[0,2.36,10],[1,2.34,29.13],[2,1.3,1000]],"ltp":2.34,"tv":38.98,"id":31376}]}]}
{"op":"mcm","clk":"11856696393","pt":1723360947856,"mc":[{"id":"1.231582198","rc":[{"batb":[[0,2.34,29.13],[1,1.3,1000],[2,1.08,7.85]],"ltp":2.34,"tv":38.98,"id":31376}]}]}
{"op":"mcm","clk":"11856696571","pt":1723360951153,"mc":[{"id":"1.231582198","rc":[{"batb":[[0,2.36,10],[1,2.34,29.13],[2,1.3,1000]],"ltp":2.34,"tv":38.98,"id":31376}]}]}
{"op":"mcm","clk":"11856696792","pt":1723360954501,"mc":[{"id":"1.231582198","rc":[{"batb":[[0,2.34,29.13],[1,1.3,1000],[2,1.08,7.85]],"ltp":2.34,"tv":38.98,"id":31376}]}]}
{"op":"mcm","clk":"11856696906","pt":1723360956977,"mc":[{"id":"1.231582198","rc":[{"batb":[[0,2.36,10],[1,2.34,29.13],[2,1.3,1000]],"ltp":2.34,"tv":38.98,"id":31376}]}]}
{"op":"mcm","clk":"11856697091","pt":1723360960371,"mc":[{"id":"1.231582198","rc":[{"batb":[[0,2.34,29.13],[1,1.3,1000],[2,1.08,7.85]],"ltp":2.34,"tv":38.98,"id":31376}]}]}
{"op":"mcm","clk":"11856697294","pt":1723360963905,"mc":[{"id":"1.231582198","rc":[{"batb":[[0,2.36,10],[1,2.34,29.13],[2,1.3,1000]],"ltp":2.34,"tv":38.98,"id":31376}]}]}
{"op":"mcm","clk":"11856697539","pt":1723360967801,"mc":[{"id":"1.231582198","rc":[{"batb":[[0,2.34,29.13],[1,1.3,1000],[2,1.08,7.85]],"ltp":2.34,"tv":38.98,"id":31376}]}]}
{"op":"mcm","clk":"11856697693","pt":1723360970423,"mc":[{"id":"1.231582198","rc":[{"batb":[[0,2.36,10],[1,2.34,29.13],[2,1.3,1000]],"ltp":2.34,"tv":38.98,"id":31376}]}]}
{"op":"mcm","clk":"11856697862","pt":1723360973719,"mc":[{"id":"1.231582198","rc":[{"batb":[[0,2.34,29.13],[1,1.3,1000],[2,1.08,7.85]],"ltp":2.34,"tv":38.98,"id":31376}]}]}
{"op":"mcm","clk":"11856698038","pt":1723360976692,"mc":[{"id":"1.231582198","rc":[{"batb":[[0,2.36,10],[1,2.34,29.13],[2,1.3,1000]],"ltp":2.34,"tv":38.98,"id":31376}]}]}
{"op":"mcm","clk":"11856698242","pt":1723360980325,"mc":[{"id":"1.231582198","rc":[{"batb":[[0,2.34,29.13],[1,1.3,1000],[2,1.08,7.85]],"ltp":2.34,"tv":38.98,"id":31376}]}]}
{"op":"mcm","clk":"11856698408","pt":1723360982598,"mc":[{"id":"1.231582198","rc":[{"batb":[[0,2.36,10],[1,2.34,29.13],[2,1.3,1000]],"ltp":2.34,"tv":38.98,"id":31376}]}]}
{"op":"mcm","clk":"11856698635","pt":1723360986132,"mc":[{"id":"1.231582198","rc":[{"batb":[[0,2.34,29.13],[1,1.3,1000],[2,1.08,7.85]],"ltp":2.34,"tv":38.98,"id":31376}]}]}
{"op":"mcm","clk":"11856698793","pt":1723360988499,"mc":[{"id":"1.231582198","rc":[{"batb":[[0,2.36,10],[1,2.34,29.13],[2,1.3,1000]],"ltp":2.34,"tv":38.98,"id":31376}]}]}
{"op":"mcm","clk":"11856698995","pt":1723360991829,"mc":[{"id":"1.231582198","rc":[{"batb":[[0,2.34,29.13],[1,1.3,1000],[2,1.08,7.85]],"ltp":2.34,"tv":38.98,"id":31376}]}]}
{"op":"mcm","clk":"11856699151","pt":1723360994407,"mc":[{"id":"1.231582198","rc":[{"batb":[[0,2.36,10],[1,2.34,29.13],[2,1.3,1000]],"ltp":2.34,"tv":38.98,"id":31376}]}]}
{"op":"mcm","clk":"11856699334","pt":1723360997636,"mc":[{"id":"1.231582198","rc":[{"batb":[[0,2.34,29.13],[1,1.3,1000],[2,1.08,7.85]],"ltp":2.34,"tv":38.98,"id":31376}]}]}
{"op":"mcm","clk":"11856699489","pt":1723361000149,"mc":[{"id":"1.231582198","rc":[{"batb":[[0,2.36,10],[1,2.34,29.13],[2,1.3,1000]],"ltp":2.34,"tv":38.98,"id":31376}]}]}
{"op":"mcm","clk":"11856699691","pt":1723361003449,"mc":[{"id":"1.231582198","rc":[{"batb":[[0,2.34,29.13],[1,1.3,1000],[2,1.08,7.85]],"ltp":2.34,"tv":38.98,"id":31376}]}]}
{"op":"mcm","clk":"11856699816","pt":1723361005857,"mc":[{"id":"1.231582198","rc":[{"batb":[[0,2.36,10],[1,2.34,29.13],[2,1.3,1000]],"ltp":2.34,"tv":38.98,"id":31376}]}]}
{"op":"mcm","clk":"11856700007","pt":1723361009143,"mc":[{"id":"1.231582198","rc":[{"batb":[[0,2.34,29.13],[1,1.3,1000],[2,1.08,7.85]],"ltp":2.34,"tv":38.98,"id":31376}]}]}
{"op":"mcm","clk":"11856700147","pt":1723361011357,"mc":[{"id":"1.231582198","rc":[{"batb":[[0,2.36,10],[1,2.34,29.13],[2,1.3,1000]],"ltp":2.34,"tv":38.98,"id":31376}]}]}
{"op":"mcm","clk":"11856700383","pt":1723361014864,"mc":[{"id":"1.231582198","rc":[{"batb":[[0,2.34,29.13],[1,1.3,1000],[2,1.08,7.85]],"ltp":2.34,"tv":38.98,"id":31376}]}]}
{"op":"mcm","clk":"11856700532","pt":1723361017538,"mc":[{"id":"1.231582198","rc":[{"batb":[[0,2.36,10],[1,2.34,29.13],[2,1.3,1000]],"ltp":2.34,"tv":38.98,"id":31376}]}]}
{"op":"mcm","clk":"11856700702","pt":1723361020884,"mc":[{"id":"1.231582198","rc":[{"batb":[[0,2.34,29.13],[1,1.3,1000],[2,1.08,7.85]],"ltp":2.34,"tv":38.98,"id":31376}]}]}
{"op":"mcm","clk":"11856701134","pt":1723361028748,"mc":[{"id":"1.231582198","rc":[{"batb":[[0,2.36,10],[1,2.34,29.13],[2,1.3,1000]],"ltp":2.34,"tv":38.98,"id":31376}]}]}
{"op":"mcm","clk":"11856701319","pt":1723361032187,"mc":[{"id":"1.231582198","rc":[{"batb":[[0,2.34,29.13],[1,1.3,1000],[2,1.08,7.85]],"ltp":2.34,"tv":38.98,"id":31376}]}]}
{"op":"mcm","clk":"11856701524","pt":1723361035056,"mc":[{"id":"1.231582198","rc":[{"batb":[[0,2.36,10],[1,2.34,29.13],[2,1.3,1000]],"ltp":2.34,"tv":38.98,"id":31376}]}]}
{"op":"mcm","clk":"11856701692","pt":1723361038691,"mc":[{"id":"1.231582198","rc":[{"batb":[[0,2.34,29.13],[1,1.3,1000],[2,1.08,7.85]],"ltp":2.34,"tv":38.98,"id":31376}]}]}
{"op":"mcm","clk":"11856701816","pt":1723361041099,"mc":[{"id":"1.231582198","rc":[{"batb":[[0,2.36,10],[1,2.34,29.13],[2,1.3,1000]],"ltp":2.34,"tv":38.98,"id":31376}]}]}
{"op":"mcm","clk":"11856702001","pt":1723361044386,"mc":[{"id":"1.231582198","rc":[{"batb":[[0,2.34,29.13],[1,1.3,1000],[2,1.08,7.85]],"ltp":2.34,"tv":38.98,"id":31376}]}]}
{"op":"mcm","clk":"11856702167","pt":1723361047313,"mc":[{"id":"1.231582198","rc":[{"batb":[[0,2.36,10],[1,2.34,29.13],[2,1.3,1000]],"ltp":2.34,"tv":38.98,"id":31376}]}]}
{"op":"mcm","clk":"11856702329","pt":1723361050388,"mc":[{"id":"1.231582198","rc":[{"batb":[[0,2.34,29.13],[1,1.3,1000],[2,1.08,7.85]],"ltp":2.34,"tv":38.98,"id":31376}]}]}
{"op":"mcm","clk":"11856702463","pt":1723361053317,"mc":[{"id":"1.231582198","rc":[{"batb":[[0,2.36,10],[1,2.34,29.13],[2,1.3,1000]],"ltp":2.34,"tv":38.98,"id":31376}]}]}
{"op":"mcm","clk":"11856702646","pt":1723361056698,"mc":[{"id":"1.231582198","rc":[{"batb":[[0,2.34,29.13],[1,1.3,1000],[2,1.08,7.85]],"ltp":2.34,"tv":38.98,"id":31376}]}]}
{"op":"mcm","clk":"11856702926","pt":1723361062434,"mc":[{"id":"1.231582198","rc":[{"batb":[[0,2.36,10],[1,2.34,29.13],[2,1.3,1000]],"ltp":2.34,"tv":38.98,"id":31376}]}]}
{"op":"mcm","clk":"11856703119","pt":1723361065717,"mc":[{"id":"1.231582198","rc":[{"batb":[[0,2.34,29.13],[1,1.3,1000],[2,1.08,7.85]],"ltp":2.34,"tv":38.98,"id":31376}]}]}
{"op":"mcm","clk":"11856703246","pt":1723361068424,"mc":[{"id":"1.231582198","rc":[{"batb":[[0,2.36,10],[1,2.34,29.13],[2,1.3,1000]],"ltp":2.34,"tv":38.98,"id":31376}]}]}
{"op":"mcm","clk":"11856703395","pt":1723361071720,"mc":[{"id":"1.231582198","rc":[{"batb":[[0,2.34,29.13],[1,1.3,1000],[2,1.08,7.85]],"ltp":2.34,"tv":38.98,"id":31376}]}]}
{"op":"mcm","clk":"11856703529","pt":1723361074237,"mc":[{"id":"1.231582198","rc":[{"batb":[[0,2.36,10],[1,2.34,29.13],[2,1.3,1000]],"ltp":2.34,"tv":38.98,"id":31376}]}]}
{"op":"mcm","clk":"11856703703","pt":1723361077631,"mc":[{"id":"1.231582198","rc":[{"batb":[[0,2.34,29.13],[1,1.3,1000],[2,1.08,7.85]],"ltp":2.34,"tv":38.98,"id":31376}]}]}
{"op":"mcm","clk":"11856703857","pt":1723361080253,"mc":[{"id":"1.231582198","rc":[{"batb":[[0,2.36,10],[1,2.34,29.13],[2,1.3,1000]],"ltp":2.34,"tv":38.98,"id":31376}]}]}
{"op":"mcm","clk":"11856704063","pt":1723361084151,"mc":[{"id":"1.231582198","rc":[{"batb":[[0,2.34,29.13],[1,1.3,1000],[2,1.08,7.85]],"ltp":2.34,"tv":38.98,"id":31376}]}]}
{"op":"mcm","clk":"11856704173","pt":1723361086458,"mc":[{"id":"1.231582198","rc":[{"batb":[[0,2.36,10],[1,2.34,29.13],[2,1.3,1000]],"ltp":2.34,"tv":38.98,"id":31376}]}]}
{"op":"mcm","clk":"11856704346","pt":1723361089842,"mc":[{"id":"1.231582198","rc":[{"batb":[[0,2.34,29.13],[1,1.3,1000],[2,1.08,7.85]],"ltp":2.34,"tv":38.98,"id":31376}]}]}
{"op":"mcm","clk":"11856704591","pt":1723361094053,"mc":[{"id":"1.231582198","rc":[{"batb":[[0,2.36,10],[1,2.34,29.13],[2,1.3,1000]],"ltp":2.34,"tv":38.98,"id":31376}]}]}
{"op":"mcm","clk":"11856704777","pt":1723361097335,"mc":[{"id":"1.231582198","rc":[{"batb":[[0,2.34,29.13],[1,1.3,1000],[2,1.08,7.85]],"ltp":2.34,"tv":38.98,"id":31376}]}]}
{"op":"mcm","clk":"11856704908","pt":1723361099957,"mc":[{"id":"1.231582198","rc":[{"batb":[[0,2.36,10],[1,2.34,29.13],[2,1.3,1000]],"ltp":2.34,"tv":38.98,"id":31376}]}]}
{"op":"mcm","clk":"11856705076","pt":1723361103249,"mc":[{"id":"1.231582198","rc":[{"batb":[[0,2.34,29.13],[1,1.3,1000],[2,1.08,7.85]],"ltp":2.34,"tv":38.98,"id":31376}]}]}
{"op":"mcm","clk":"11856705278","pt":1723361106349,"mc":[{"id":"1.231582198","rc":[{"batb":[[0,2.36,10],[1,2.34,29.13],[2,1.3,1000]],"ltp":2.34,"tv":38.98,"id":31376}]}]}
{"op":"mcm","clk":"11856705486","pt":1723361109748,"mc":[{"id":"1.231582198","rc":[{"batb":[[0,2.34,29.13],[1,1.3,1000],[2,1.08,7.85]],"ltp":2.34,"tv":38.98,"id":31376}]}]}
{"op":"mcm","clk":"11856705674","pt":1723361113083,"mc":[{"id":"1.231582198","rc":[{"batb":[[0,2.36,10],[1,2.34,29.13],[2,1.3,1000]],"ltp":2.34,"tv":38.98,"id":31376}]}]}
{"op":"mcm","clk":"11856705865","pt":1723361116349,"mc":[{"id":"1.231582198","rc":[{"batb":[[0,2.34,29.13],[1,1.3,1000],[2,1.08,7.85]],"ltp":2.34,"tv":38.98,"id":31376}]}]}
{"op":"mcm","clk":"11856706008","pt":1723361118766,"mc":[{"id":"1.231582198","rc":[{"batb":[[0,2.36,10],[1,2.34,29.13],[2,1.3,1000]],"ltp":2.34,"tv":38.98,"id":31376}]}]}
{"op":"mcm","clk":"11856706180","pt":1723361122167,"mc":[{"id":"1.231582198","rc":[{"batb":[[0,2.34,29.13],[1,1.3,1000],[2,1.08,7.85]],"ltp":2.34,"tv":38.98,"id":31376}]}]}
{"op":"mcm","clk":"11856706321","pt":1723361124953,"mc":[{"id":"1.231582198","rc":[{"batb":[[0,2.36,10],[1,2.34,29.13],[2,1.3,1000]],"ltp":2.34,"tv":38.98,"id":31376}]}]}
{"op":"mcm","clk":"11856706503","pt":1723361128380,"mc":[{"id":"1.231582198","rc":[{"batb":[[0,2.34,29.13],[1,1.3,1000],[2,1.08,7.85]],"ltp":2.34,"tv":38.98,"id":31376}]}]}
{"op":"mcm","clk":"11856706630","pt":1723361130763,"mc":[{"id":"1.231582198","rc":[{"batb":[[0,2.36,10],[1,2.34,29.13],[2,1.3,1000]],"ltp":2.34,"tv":38.98,"id":31376}]}]}
{"op":"mcm","clk":"11856706788","pt":1723361134203,"mc":[{"id":"1.231582198","rc":[{"batb":[[0,2.34,29.13],[1,1.3,1000],[2,1.08,7.85]],"ltp":2.34,"tv":38.98,"id":31376}]}]}
{"op":"mcm","clk":"11856706917","pt":1723361136787,"mc":[{"id":"1.231582198","rc":[{"batb":[[0,2.36,10],[1,2.34,29.13],[2,1.3,1000]],"ltp":2.34,"tv":38.98,"id":31376}]}]}
{"op":"mcm","clk":"11856707102","pt":1723361140207,"mc":[{"id":"1.231582198","rc":[{"batb":[[0,2.34,29.13],[1,1.3,1000],[2,1.08,7.85]],"ltp":2.34,"tv":38.98,"id":31376}]}]}
{"op":"mcm","clk":"11856707304","pt":1723361144383,"mc":[{"id":"1.231582198","rc":[{"batb":[[0,2.36,10],[1,2.34,29.13],[2,1.3,1000]],"ltp":2.34,"tv":38.98,"id":31376}]}]}
{"op":"mcm","clk":"11856707445","pt":1723361147780,"mc":[{"id":"1.231582198","rc":[{"batb":[[0,2.34,29.13],[1,1.3,1000],[2,1.08,7.85]],"ltp":2.34,"tv":38.98,"id":31376}]}]}
{"op":"mcm","clk":"11856707550","pt":1723361149990,"mc":[{"id":"1.231582198","rc":[{"batb":[[0,2.36,10],[1,2.34,29.13],[2,1.3,1000]],"ltp":2.34,"tv":38.98,"id":31376}]}]}
{"op":"mcm","clk":"11856707721","pt":1723361153381,"mc":[{"id":"1.231582198","rc":[{"batb":[[0,2.34,29.13],[1,1.3,1000],[2,1.08,7.85]],"ltp":2.34,"tv":38.98,"id":31376}]}]}
{"op":"mcm","clk":"11856707874","pt":1723361156402,"mc":[{"id":"1.231582198","rc":[{"batb":[[0,2.36,10],[1,2.34,29.13],[2,1.3,1000]],"ltp":2.34,"tv":38.98,"id":31376}]}]}
{"op":"mcm","clk":"11856708032","pt":1723361159890,"mc":[{"id":"1.231582198","rc":[{"batb":[[0,2.34,29.13],[1,1.3,1000],[2,1.08,7.85]],"ltp":2.34,"tv":38.98,"id":31376}]}]}
{"op":"mcm","clk":"11856708222","pt":1723361163316,"mc":[{"id":"1.231582198","rc":[{"batb":[[0,2.36,10],[1,2.34,29.13],[2,1.3,1000]],"ltp":2.34,"tv":38.98,"id":31376}]}]}
{"op":"mcm","clk":"11856708396","pt":1723361166604,"mc":[{"id":"1.231582198","rc":[{"batb":[[0,2.34,29.13],[1,1.3,1000],[2,1.08,7.85]],"ltp":2.34,"tv":38.98,"id":31376}]}]}
{"op":"mcm","clk":"11856708570","pt":1723361169793,"mc":[{"id":"1.231582198","rc":[{"batb":[[0,2.36,10],[1,2.34,29.13],[2,1.3,1000]],"ltp":2.34,"tv":38.98,"id":31376}]}]}
{"op":"mcm","clk":"11856708740","pt":1723361173206,"mc":[{"id":"1.231582198","rc":[{"batb":[[0,2.34,29.13],[1,1.3,1000],[2,1.08,7.85]],"ltp":2.34,"tv":38.98,"id":31376}]}]}
{"op":"mcm","clk":"11856708849","pt":1723361175717,"mc":[{"id":"1.231582198","rc":[{"batb":[[0,2.36,10],[1,2.34,29.13],[2,1.3,1000]],"ltp":2.34,"tv":38.98,"id":31376}]}]}
{"op":"mcm","clk":"11856709004","pt":1723361178946,"mc":[{"id":"1.231582198","rc":[{"batb":[[0,2.34,29.13],[1,1.3,1000],[2,1.08,7.85]],"ltp":2.34,"tv":38.98,"id":31376}]}]}
{"op":"mcm","clk":"11856709112","pt":1723361181352,"mc":[{"id":"1.231582198","rc":[{"trd":[[1.66,18.3]],"batb":[[0,1.65,60.06],[1,1.56,4.56],[2,1.51,4.56]],"batl":[[0,1.84,4.92]],"ltp":1.66,"tv":1114.23,"id":2780},{"batb":[[0,2.36,10],[1,2.34,29.13],[2,1.3,1000]],"ltp":2.34,"tv":38.98,"id":31376}],"tv":1153.21}]}
{"op":"mcm","clk":"11856709165","pt":1723361182534,"mc":[{"id":"1.231582198","rc":[{"batl":[[0,1.74,4.79],[1,1.84,4.56],[2,1.85,100]],"ltp":1.66,"tv":1114.23,"id":2780}]}]}
{"op":"mcm","clk":"11856709288","pt":1723361184616,"mc":[{"id":"1.231582198","rc":[{"batb":[[0,2.34,29.13],[1,1.3,1000],[2,1.08,7.85]],"ltp":2.34,"tv":38.98,"id":31376}]}]}
{"op":"mcm","clk":"11856709433","pt":1723361187528,"mc":[{"id":"1.231582198","rc":[{"batb":[[0,2.36,10],[1,2.34,29.13],[2,1.3,1000]],"ltp":2.34,"tv":38.98,"id":31376}]}]}
{"op":"mcm","clk":"11856709597","pt":1723361191056,"mc":[{"id":"1.231582198","rc":[{"batb":[[0,2.34,29.13],[1,1.3,1000],[2,1.08,7.85]],"ltp":2.34,"tv":38.98,"id":31376}]}]}
{"op":"mcm","clk":"11856709665","pt":1723361192746,"mc":[{"id":"1.231582198","rc":[{"batl":[[0,1.74,29.79]],"ltp":1.66,"tv":1114.23,"id":2780}]}]}
{"op":"mcm","clk":"11856709720","pt":1723361194026,"mc":[{"id":"1.231582198","rc":[{"batb":[[0,2.36,10],[1,2.34,29.13],[2,1.3,1000]],"ltp":2.34,"tv":38.98,"id":31376}]}]}
{"op":"mcm","clk":"11856709917","pt":1723361197834,"mc":[{"id":"1.231582198","rc":[{"batb":[[0,2.34,29.13],[1,1.3,1000],[2,1.08,7.85]],"ltp":2.34,"tv":38.98,"id":31376}]}]}
{"op":"mcm","clk":"11856710173","pt":1723361202335,"mc":[{"id":"1.231582198","rc":[{"trd":[[1.66,19.02]],"batb":[[0,1.66,15.64],[1,1.65,60.06],[2,1.56,4.56]],"batl":[[0,1.74,29.43]],"ltp":1.66,"tv":1114.95,"id":2780},{"batb":[[0,2.36,10],[1,2.34,29.13],[2,1.3,1000]],"ltp":2.34,"tv":38.98,"id":31376}],"tv":1153.93}]}
{"op":"mcm","clk":"11856710323","pt":1723361205355,"mc":[{"id":"1.231582198","rc":[{"batb":[[0,2.34,29.13],[1,1.3,1000],[2,1.08,7.85]],"ltp":2.34,"tv":38.98,"id":31376}]}]}
{"op":"mcm","clk":"11856710568","pt":1723361209757,"mc":[{"id":"1.231582198","rc":[{"batb":[[0,2.36,10],[1,2.34,29.13],[2,1.3,1000]],"ltp":2.34,"tv":38.98,"id":31376}]}]}
{"op":"mcm","clk":"11856710719","pt":1723361213080,"mc":[{"id":"1.231582198","rc":[{"batb":[[0,2.34,29.13],[1,1.3,1000],[2,1.08,7.85]],"ltp":2.34,"tv":38.98,"id":31376}]}]}
{"op":"mcm","clk":"11856710877","pt":1723361216769,"mc":[{"id":"1.231582198","rc":[{"batb":[[0,2.36,10],[1,2.34,29.13],[2,1.3,1000]],"ltp":2.34,"tv":38.98,"id":31376}]}]}
{"op":"mcm","clk":"11856711056","pt":1723361220050,"mc":[{"id":"1.231582198","rc":[{"batb":[[0,2.34,29.13],[1,1.3,1000],[2,1.08,7.85]],"ltp":2.34,"tv":38.98,"id":31376}]}]}
{"op":"mcm","clk":"11856711141","pt":1723361221547,"mc":[{"id":"1.231582198","rc":[{"batl":[[0,1.74,29.79]],"ltp":1.66,"tv":1114.95,"id":2780}]}]}
{"op":"mcm","clk":"11856711295","pt":1723361224780,"mc":[{"id":"1.231582198","rc":[{"batb":[[0,2.36,10],[1,2.34,29.13],[2,1.3,1000]],"ltp":2.34,"tv":38.98,"id":31376}]}]}
{"op":"mcm","clk":"11856711550","pt":1723361228365,"mc":[{"id":"1.231582198","rc":[{"batb":[[0,2.34,29.13],[1,1.3,1000],[2,1.08,7.85]],"ltp":2.34,"tv":38.98,"id":31376}]}]}
{"op":"mcm","clk":"11856711741","pt":1723361231472,"mc":[{"id":"1.231582198","rc":[{"batb":[[0,2.36,10],[1,2.34,29.13],[2,1.3,1000]],"ltp":2.34,"tv":38.98,"id":31376}]}]}
{"op":"mcm","clk":"11856711925","pt":1723361235212,"mc":[{"id":"1.231582198","rc":[{"batb":[[0,2.34,29.13],[1,1.3,1000],[2,1.08,7.85]],"ltp":2.34,"tv":38.98,"id":31376}]}]}
{"op":"mcm","clk":"11856712165","pt":1723361239782,"mc":[{"id":"1.231582198","rc":[{"batb":[[0,2.36,10],[1,2.34,29.13],[2,1.3,1000]],"ltp":2.34,"tv":38.98,"id":31376}]}]}
{"op":"mcm","clk":"11856712351","pt":1723361243094,"mc":[{"id":"1.231582198","rc":[{"batb":[[0,2.34,29.13],[1,1.3,1000],[2,1.08,7.85]],"ltp":2.34,"tv":38.98,"id":31376}]}]}
{"op":"mcm","clk":"11856712516","pt":1723361246004,"mc":[{"id":"1.231582198","rc":[{"batb":[[0,2.36,10],[1,2.34,29.13],[2,1.3,1000]],"ltp":2.34,"tv":38.98,"id":31376}]}]}
{"op":"mcm","clk":"11856712674","pt":1723361249486,"mc":[{"id":"1.231582198","rc":[{"batb":[[0,2.34,29.13],[1,1.3,1000],[2,1.08,7.85]],"ltp":2.34,"tv":38.98,"id":31376}]}]}
{"op":"mcm","clk":"11856712792","pt":1723361252502,"mc":[{"id":"1.231582198","rc":[{"batb":[[0,2.36,10],[1,2.34,29.13],[2,1.3,1000]],"ltp":2.34,"tv":38.98,"id":31376}]}]}
{"op":"mcm","clk":"11856712958","pt":1723361256030,"mc":[{"id":"1.231582198","rc":[{"batb":[[0,2.34,29.13],[1,1.3,1000],[2,1.08,7.85]],"ltp":2.34,"tv":38.98,"id":31376}]}]}
{"op":"mcm","clk":"11856713088","pt":1723361258485,"mc":[{"id":"1.231582198","rc":[{"batb":[[0,2.36,10],[1,2.34,29.13],[2,1.3,1000]],"ltp":2.34,"tv":38.98,"id":31376}]}]}
{"op":"mcm","clk":"11856713251","pt":1723361262014,"mc":[{"id":"1.231582198","rc":[{"batb":[[0,2.34,29.13],[1,1.3,1000],[2,1.08,7.85]],"ltp":2.34,"tv":38.98,"id":31376}]}]}
{"op":"mcm","clk":"11856713573","pt":1723361267502,"mc":[{"id":"1.231582198","rc":[{"batb":[[0,2.36,10],[1,2.34,29.13],[2,1.3,1000]],"ltp":2.34,"tv":38.98,"id":31376}]}]}
{"op":"mcm","clk":"11856713723","pt":1723361270745,"mc":[{"id":"1.231582198","rc":[{"batb":[[0,2.34,29.13],[1,1.3,1000],[2,1.08,7.85]],"ltp":2.34,"tv":38.98,"id":31376}]}]}
{"op":"mcm","clk":"11856713864","pt":1723361273109,"mc":[{"id":"1.231582198","rc":[{"batb":[[0,2.36,10],[1,2.34,29.13],[2,1.3,1000]],"ltp":2.34,"tv":38.98,"id":31376}]}]}
{"op":"mcm","clk":"11856714072","pt":1723361276449,"mc":[{"id":"1.231582198","rc":[{"batb":[[0,2.34,29.13],[1,1.3,1000],[2,1.08,7.85]],"ltp":2.34,"tv":38.98,"id":31376}]}]}
{"op":"mcm","clk":"11856714269","pt":1723361280121,"mc":[{"id":"1.231582198","rc":[{"batb":[[0,2.36,10],[1,2.34,29.13],[2,1.3,1000]],"ltp":2.34,"tv":38.98,"id":31376}]}]}
{"op":"mcm","clk":"11856714460","pt":1723361283637,"mc":[{"id":"1.231582198","rc":[{"batb":[[0,2.34,29.13],[1,1.3,1000],[2,1.08,7.85]],"ltp":2.34,"tv":38.98,"id":31376}]}]}
{"op":"mcm","clk":"11856714608","pt":1723361286257,"mc":[{"id":"1.231582198","rc":[{"batb":[[0,2.36,10],[1,2.34,29.13],[2,1.3,1000]],"ltp":2.34,"tv":38.98,"id":31376}]}]}
{"op":"mcm","clk":"11856714815","pt":1723361289653,"mc":[{"id":"1.231582198","rc":[{"batb":[[0,2.34,29.13],[1,1.3,1000],[2,1.08,7.85]],"ltp":2.34,"tv":38.98,"id":31376}]}]}
{"op":"mcm","clk":"11856715026","pt":1723361293453,"mc":[{"id":"1.231582198","rc":[{"batb":[[0,2.36,10],[1,2.34,29.13],[2,1.3,1000]],"ltp":2.34,"tv":38.98,"id":31376}]}]}
{"op":"mcm","clk":"11856715266","pt":1723361297045,"mc":[{"id":"1.231582198","rc":[{"batb":[[0,2.34,29.13],[1,1.3,1000],[2,1.08,7.85]],"ltp":2.34,"tv":38.98,"id":31376}]}]}
{"op":"mcm","clk":"11856715420","pt":1723361300233,"mc":[{"id":"1.231582198","rc":[{"batb":[[0,2.36,10],[1,2.34,29.13],[2,1.3,1000]],"ltp":2.34,"tv":38.98,"id":31376}]}]}
{"op":"mcm","clk":"11856715590","pt":1723361303466,"mc":[{"id":"1.231582198","rc":[{"batb":[[0,2.34,29.13],[1,1.3,1000],[2,1.08,7.85]],"ltp":2.34,"tv":38.98,"id":31376}]}]}
{"op":"mcm","clk":"11856715745","pt":1723361305637,"mc":[{"id":"1.231582198","rc":[{"batb":[[0,2.36,10],[1,2.34,29.13],[2,1.3,1000]],"ltp":2.34,"tv":38.98,"id":31376}]}]}
{"op":"mcm","clk":"11856715915","pt":1723361309161,"mc":[{"id":"1.231582198","rc":[{"batb":[[0,2.34,29.13],[1,1.3,1000],[2,1.08,7.85]],"ltp":2.34,"tv":38.98,"id":31376}]}]}
{"op":"mcm","clk":"11856716088","pt":1723361312854,"mc":[{"id":"1.231582198","rc":[{"batb":[[0,2.36,10],[1,2.34,29.13],[2,1.3,1000]],"ltp":2.34,"tv":38.98,"id":31376}]}]}
{"op":"mcm","clk":"11856716264","pt":1723361316244,"mc":[{"id":"1.231582198","rc":[{"batb":[[0,2.34,29.13],[1,1.3,1000],[2,1.08,7.85]],"ltp":2.34,"tv":38.98,"id":31376}]}]}
{"op":"mcm","clk":"11856716439","pt":1723361319267,"mc":[{"id":"1.231582198","rc":[{"batb":[[0,2.36,10],[1,2.34,29.13],[2,1.3,1000]],"ltp":2.34,"tv":38.98,"id":31376}]}]}
{"op":"mcm","clk":"11856716596","pt":1723361322447,"mc":[{"id":"1.231582198","rc":[{"batb":[[0,2.34,29.13],[1,1.3,1000],[2,1.08,7.85]],"ltp":2.34,"tv":38.98,"id":31376}]}]}
{"op":"mcm","clk":"11856716907","pt":1723361329253,"mc":[{"id":"1.231582198","rc":[{"batb":[[0,2.36,10],[1,2.34,29.13],[2,1.3,1000]],"ltp":2.34,"tv":38.98,"id":31376}]}]}
{"op":"mcm","clk":"11856717066","pt":1723361332680,"mc":[{"id":"1.231582198","rc":[{"batb":[[0,2.34,29.13],[1,1.3,1000],[2,1.08,7.85]],"ltp":2.34,"tv":38.98,"id":31376}]}]}
{"op":"mcm","clk":"11856717454","pt":1723361340895,"mc":[{"id":"1.231582198","rc":[{"batb":[[0,2.36,10],[1,2.34,29.13],[2,1.3,1000]],"ltp":2.34,"tv":38.98,"id":31376}]}]}
{"op":"mcm","clk":"11856717616","pt":1723361344202,"mc":[{"id":"1.231582198","rc":[{"batb":[[0,2.34,29.13],[1,1.3,1000],[2,1.08,7.85]],"ltp":2.34,"tv":38.98,"id":31376}]}]}
{"op":"mcm","clk":"11856717776","pt":1723361346918,"mc":[{"id":"1.231582198","rc":[{"batb":[[0,2.36,10],[1,2.34,29.13],[2,1.3,1000]],"ltp":2.34,"tv":38.98,"id":31376}]}]}
{"op":"mcm","clk":"11856717970","pt":1723361350102,"mc":[{"id":"1.231582198","rc":[{"batb":[[0,2.34,29.13],[1,1.3,1000],[2,1.08,7.85]],"ltp":2.34,"tv":38.98,"id":31376}]}]}
{"op":"mcm","clk":"11856718088","pt":1723361352619,"mc":[{"id":"1.231582198","rc":[{"batb":[[0,2.36,10],[1,2.34,29.13],[2,1.3,1000]],"ltp":2.34,"tv":38.98,"id":31376}]}]}
{"op":"mcm","clk":"11856718296","pt":1723361355913,"mc":[{"id":"1.231582198","rc":[{"batb":[[0,2.34,29.13],[1,1.3,1000],[2,1.08,7.85]],"ltp":2.34,"tv":38.98,"id":31376}]}]}
{"op":"mcm","clk":"11856718344","pt":1723361357096,"mc":[{"id":"1.231582198","rc":[{"batb":[[0,1.67,45.08],[1,1.66,15.64],[2,1.65,60.06]],"ltp":1.66,"tv":1114.95,"id":2780}]}]}
{"op":"mcm","clk":"11856718466","pt":1723361359714,"mc":[{"id":"1.231582198","rc":[{"batb":[[0,2.36,10],[1,2.34,29.13],[2,1.3,1000]],"ltp":2.34,"tv":38.98,"id":31376}]}]}
{"op":"mcm","clk":"11856718639","pt":1723361363201,"mc":[{"id":"1.231582198","rc":[{"batb":[[0,2.34,29.13],[1,1.3,1000],[2,1.08,7.85]],"ltp":2.34,"tv":38.98,"id":31376}]}]}
{"op":"mcm","clk":"11856718900","pt":1723361367712,"mc":[{"id":"1.231582198","rc":[{"batb":[[0,2.36,10],[1,2.34,29.13],[2,1.3,1000]],"ltp":2.34,"tv":38.98,"id":31376}]}]}
{"op":"mcm","clk":"11856719100","pt":1723361371108,"mc":[{"id":"1.231582198","rc":[{"batb":[[0,2.34,29.13],[1,1.3,1000],[2,1.08,7.85]],"ltp":2.34,"tv":38.98,"id":31376}]}]}
{"op":"mcm","clk":"11856719392","pt":1723361376217,"mc":[{"id":"1.231582198","rc":[{"batb":[[0,2.36,10],[1,2.34,29.13],[2,1.3,1000]],"ltp":2.34,"tv":38.98,"id":31376}]}]}
{"op":"mcm","clk":"11856719629","pt":1723361379968,"mc":[{"id":"1.231582198","rc":[{"batb":[[0,2.34,29.13],[1,1.3,1000],[2,1.08,7.85]],"ltp":2.34,"tv":38.98,"id":31376}]}]}
{"op":"mcm","clk":"11856719771","pt":1723361382327,"mc":[{"id":"1.231582198","rc":[{"batb":[[0,2.36,10],[1,2.34,29.13],[2,1.3,1000]],"ltp":2.34,"tv":38.98,"id":31376}]}]}
{"op":"mcm","clk":"11856720013","pt":1723361385770,"mc":[{"id":"1.231582198","rc":[{"batb":[[0,2.34,29.13],[1,1.3,1000],[2,1.08,7.85]],"ltp":2.34,"tv":38.98,"id":31376}]}]}
{"op":"mcm","clk":"11856720161","pt":1723361388534,"mc":[{"id":"1.231582198","rc":[{"batb":[[0,2.36,10],[1,2.34,29.13],[2,1.3,1000]],"ltp":2.34,"tv":38.98,"id":31376}]}]}
{"op":"mcm","clk":"11856720340","pt":1723361392070,"mc":[{"id":"1.231582198","rc":[{"batb":[[0,2.34,29.13],[1,1.3,1000],[2,1.08,7.85]],"ltp":2.34,"tv":38.98,"id":31376}]}]}
{"op":"mcm","clk":"11856720479","pt":1723361394578,"mc":[{"id":"1.231582198","rc":[{"batb":[[0,2.36,10],[1,2.34,29.13],[2,1.3,1000]],"ltp":2.34,"tv":38.98,"id":31376}]}]}
{"op":"mcm","clk":"11856720649","pt":1723361397752,"mc":[{"id":"1.231582198","rc":[{"batb":[[0,2.34,29.13],[1,1.3,1000],[2,1.08,7.85]],"ltp":2.34,"tv":38.98,"id":31376}]}]}
{"op":"mcm","clk":"11856720835","pt":1723361400887,"mc":[{"id":"1.231582198","rc":[{"batb":[[0,2.36,10],[1,2.34,29.13],[2,1.3,1000]],"ltp":2.34,"tv":38.98,"id":31376}]}]}
{"op":"mcm","clk":"11856721098","pt":1723361404395,"mc":[{"id":"1.231582198","rc":[{"batb":[[0,2.34,29.13],[1,1.3,1000],[2,1.08,7.85]],"ltp":2.34,"tv":38.98,"id":31376}]}]}
{"op":"mcm","clk":"11856721267","pt":1723361406864,"mc":[{"id":"1.231582198","rc":[{"batb":[[0,2.36,10],[1,2.34,29.13],[2,1.3,1000]],"ltp":2.34,"tv":38.98,"id":31376}]}]}
{"op":"mcm","clk":"11856721442","pt":1723361410297,"mc":[{"id":"1.231582198","rc":[{"batb":[[0,2.34,29.13],[1,1.3,1000],[2,1.08,7.85]],"ltp":2.34,"tv":38.98,"id":31376}]}]}
{"op":"mcm","clk":"11856721592","pt":1723361412809,"mc":[{"id":"1.231582198","rc":[{"batb":[[0,2.36,10],[1,2.34,29.13],[2,1.3,1000]],"ltp":2.34,"tv":38.98,"id":31376}]}]}
{"op":"mcm","clk":"11856721793","pt":1723361416097,"mc":[{"id":"1.231582198","rc":[{"batb":[[0,2.34,29.13],[1,1.3,1000],[2,1.08,7.85]],"ltp":2.34,"tv":38.98,"id":31376}]}]}
{"op":"mcm","clk":"11856721843","pt":1723361417021,"mc":[{"id":"1.231582198","rc":[{"batb":[[0,1.66,15.64],[1,1.65,60.06],[2,1.56,4.56]],"ltp":1.66,"tv":1114.95,"id":2780}]}]}
{"op":"mcm","clk":"11856721903","pt":1723361418302,"mc":[{"id":"1.231582198","rc":[{"batb":[[0,2.36,10],[1,2.34,29.13],[2,1.3,1000]],"ltp":2.34,"tv":38.98,"id":31376}]}]}
{"op":"mcm","clk":"11856722104","pt":1723361421528,"mc":[{"id":"1.231582198","rc":[{"batb":[[0,2.34,29.13],[1,1.3,1000],[2,1.08,7.85]],"ltp":2.34,"tv":38.98,"id":31376}]}]}
{"op":"mcm","clk":"11856722257","pt":1723361423910,"mc":[{"id":"1.231582198","rc":[{"batb":[[0,2.36,10],[1,2.34,29.13],[2,1.3,1000]],"ltp":2.34,"tv":38.98,"id":31376}]}]}
{"op":"mcm","clk":"11856722473","pt":1723361427195,"mc":[{"id":"1.231582198","rc":[{"batb":[[0,2.34,29.13],[1,1.3,1000],[2,1.08,7.85]],"ltp":2.34,"tv":38.98,"id":31376}]}]}
{"op":"mcm","clk":"11856722664","pt":1723361430116,"mc":[{"id":"1.231582198","rc":[{"batb":[[0,2.36,10],[1,2.34,29.13],[2,1.3,1000]],"ltp":2.34,"tv":38.98,"id":31376}]}]}
{"op":"mcm","clk":"11856722855","pt":1723361433406,"mc":[{"id":"1.231582198","rc":[{"batb":[[0,2.34,29.13],[1,1.3,1000],[2,1.08,7.85]],"ltp":2.34,"tv":38.98,"id":31376}]}]}
{"op":"mcm","clk":"11856723012","pt":1723361435930,"mc":[{"id":"1.231582198","rc":[{"batb":[[0,2.36,10],[1,2.34,29.13],[2,1.3,1000]],"ltp":2.34,"tv":38.98,"id":31376}]}]}
{"op":"mcm","clk":"11856723213","pt":1723361439215,"mc":[{"id":"1.231582198","rc":[{"batb":[[0,2.34,29.13],[1,1.3,1000],[2,1.08,7.85]],"ltp":2.34,"tv":38.98,"id":31376}]}]}
{"op":"mcm","clk":"11856723376","pt":1723361441831,"mc":[{"id":"1.231582198","rc":[{"batb":[[0,2.36,10],[1,2.34,29.13],[2,1.3,1000]],"ltp":2.34,"tv":38.98,"id":31376}]}]}
{"op":"mcm","clk":"11856723591","pt":1723361445269,"mc":[{"id":"1.231582198","rc":[{"batb":[[0,2.34,29.13],[1,1.3,1000],[2,1.08,7.85]],"ltp":2.34,"tv":38.98,"id":31376}]}]}
{"op":"mcm","clk":"11856723764","pt":1723361448344,"mc":[{"id":"1.231582198","rc":[{"batb":[[0,2.36,10],[1,2.34,29.13],[2,1.3,1000]],"ltp":2.34,"tv":38.98,"id":31376}]}]}
{"op":"mcm","clk":"11856723973","pt":1723361451841,"mc":[{"id":"1.231582198","rc":[{"batb":[[0,2.34,29.13],[1,1.3,1000],[2,1.08,7.85]],"ltp":2.34,"tv":38.98,"id":31376}]}]}
{"op":"mcm","clk":"11856724207","pt":1723361455845,"mc":[{"id":"1.231582198","rc":[{"batb":[[0,2.36,10],[1,2.34,29.13],[2,1.3,1000]],"ltp":2.34,"tv":38.98,"id":31376}]}]}
{"op":"mcm","clk":"11856724347","pt":1723361457955,"mc":[{"id":"1.231582198","rc":[{"batb":[[0,2.38,4],[1,2.36,10],[2,2.34,29.13]],"batl":[[0,2.78,5],[1,1000,0.02]],"ltp":2.34,"tv":38.98,"id":31376}]}]}
{"op":"mcm","clk":"11856724416","pt":1723361459189,"mc":[{"id":"1.231582198","rc":[{"batb":[[1,2.34,29.13],[2,1.3,1000]],"ltp":2.34,"tv":38.98,"id":31376}]}]}
{"op":"mcm","clk":"11856724466","pt":1723361460266,"mc":[{"id":"1.231582198","rc":[{"batb":[[0,2.34,29.13],[1,1.3,1000],[2,1.08,7.85]],"ltp":2.34,"tv":38.98,"id":31376}]}]}
{"op":"mcm","clk":"11856724580","pt":1723361462480,"mc":[{"id":"1.231582198","rc":[{"batb":[[0,2.38,4],[1,2.36,10],[2,2.34,29.13]],"ltp":2.34,"tv":38.98,"id":31376}]}]}
{"op":"mcm","clk":"11856724742","pt":1723361465094,"mc":[{"id":"1.231582198","rc":[{"batb":[[0,2.36,10],[1,2.34,29.13],[2,1.3,1000]],"ltp":2.34,"tv":38.98,"id":31376}]}]}
{"op":"mcm","clk":"11856724781","pt":1723361465664,"mc":[{"id":"1.231582198","rc":[{"batb":[[0,2.34,29.13],[1,1.3,1000],[2,1.08,7.85]],"ltp":2.34,"tv":38.98,"id":31376}]}]}
{"op":"mcm","clk":"11856725003","pt":1723361468676,"mc":[{"id":"1.231582198","rc":[{"batb":[[0,2.36,14],[1,2.34,29.13],[2,1.3,1000]],"ltp":2.34,"tv":38.98,"id":31376}]}]}
{"op":"mcm","clk":"11856725193","pt":1723361471395,"mc":[{"id":"1.231582198","rc":[{"batl":[[0,1.73,89.98],[1,1.74,29.79],[2,1.84,4.56]],"ltp":1.66,"tv":1114.95,"id":2780},{"batb":[[0,2.36,10]],"ltp":2.34,"tv":38.98,"id":31376}]}]}
{"op":"mcm","clk":"11856725232","pt":1723361472068,"mc":[{"id":"1.231582198","rc":[{"batb":[[0,2.34,29.13],[1,1.3,1000],[2,1.08,7.85]],"ltp":2.34,"tv":38.98,"id":31376}]}]}
{"op":"mcm","clk":"11856725336","pt":1723361473707,"mc":[{"id":"1.231582198","rc":[{"batl":[[0,1.72,4.48],[1,1.73,89.98],[2,1.74,25.36]],"ltp":1.66,"tv":1114.95,"id":2780},{"batb":[[0,2.36,4],[1,2.34,29.13],[2,1.3,1000]],"ltp":2.34,"tv":38.98,"id":31376}]}]}
{"op":"mcm","clk":"11856725406","pt":1723361474890,"mc":[{"id":"1.231582198","rc":[{"batb":[[0,2.38,10],[1,2.36,4],[2,2.34,29.13]],"ltp":2.34,"tv":38.98,"id":31376}]}]}
{"op":"mcm","clk":"11856725481","pt":1723361475969,"mc":[{"id":"1.231582198","rc":[{"batb":[[1,2.34,29.13],[2,1.3,1000]],"ltp":2.34,"tv":38.98,"id":31376}]}]}
{"op":"mcm","clk":"11856725635","pt":1723361478495,"mc":[{"id":"1.231582198","rc":[{"batb":[[0,2.4,4]],"ltp":2.34,"tv":38.98,"id":31376}]}]}
{"op":"mcm","clk":"11856725777","pt":1723361481005,"mc":[{"id":"1.231582198","rc":[{"batb":[[0,2.36,10]],"ltp":2.34,"tv":38.98,"id":31376}]}]}
{"op":"mcm","clk":"11856725894","pt":1723361483312,"mc":[{"id":"1.231582198","rc":[{"batb":[[0,2.38,4],[1,2.36,10],[2,2.34,29.13]],"ltp":2.34,"tv":38.98,"id":31376}]}]}
{"op":"mcm","clk":"11856725973","pt":1723361484389,"mc":[{"id":"1.231582198","rc":[{"batb":[[1,2.34,29.13],[2,1.3,1000]],"ltp":2.34,"tv":38.98,"id":31376}]}]}
{"op":"mcm","clk":"11856726042","pt":1723361485516,"mc":[{"id":"1.231582198","rc":[{"batb":[[0,2.34,29.13],[1,1.3,1000],[2,1.08,7.85]],"ltp":2.34,"tv":38.98,"id":31376}]}]}
{"op":"mcm","clk":"11856726140","pt":1723361486900,"mc":[{"id":"1.231582198","rc":[{"batb":[[0,2.36,10],[1,2.34,29.13],[2,1.3,1000]],"ltp":2.34,"tv":38.98,"id":31376}]}]}
{"op":"mcm","clk":"11856726235","pt":1723361488490,"mc":[{"id":"1.231582198","rc":[{"batb":[[0,2.38,4],[1,2.36,10],[2,2.34,29.13]],"ltp":2.34,"tv":38.98,"id":31376}]}]}
{"op":"mcm","clk":"11856726339","pt":1723361490398,"mc":[{"id":"1.231582198","rc":[{"batb":[[1,2.34,29.13],[2,1.3,1000]],"ltp":2.34,"tv":38.98,"id":31376}]}]}
{"op":"mcm","clk":"11856726398","pt":1723361491226,"mc":[{"id":"1.231582198","rc":[{"batb":[[0,2.34,29.13],[1,1.3,1000],[2,1.08,7.85]],"ltp":2.34,"tv":38.98,"id":31376}]}]}
{"op":"mcm","clk":"11856726570","pt":1723361494011,"mc":[{"id":"1.231582198","rc":[{"batb":[[0,2.36,14],[1,2.34,29.13],[2,1.3,1000]],"ltp":2.34,"tv":38.98,"id":31376}]}]}
{"op":"mcm","clk":"11856726807","pt":1723361497511,"mc":[{"id":"1.231582198","rc":[{"batb":[[0,2.34,29.13],[1,1.3,1000],[2,1.08,7.85]],"ltp":2.34,"tv":38.98,"id":31376}]}]}
{"op":"mcm","clk":"11856726993","pt":1723361500606,"mc":[{"id":"1.231582198","rc":[{"batb":[[0,2.36,14],[1,2.34,29.13],[2,1.3,1000]],"ltp":2.34,"tv":38.98,"id":31376}]}]}
{"op":"mcm","clk":"11856727145","pt":1723361502919,"mc":[{"id":"1.231582198","rc":[{"batb":[[0,2.36,10]],"ltp":2.34,"tv":38.98,"id":31376}]}]}
{"op":"mcm","clk":"11856727255","pt":1723361504413,"mc":[{"id":"1.231582198","rc":[{"batl":[[0,1.72,11.57]],"ltp":1.66,"tv":1114.95,"id":2780},{"batb":[[0,2.34,29.13],[1,1.3,1000],[2,1.08,7.85]],"ltp":2.34,"tv":38.98,"id":31376}]}]}
{"op":"mcm","clk":"11856727381","pt":1723361506510,"mc":[{"id":"1.231582198","rc":[{"batb":[[0,2.36,14],[1,2.34,29.13],[2,1.3,1000]],"ltp":2.34,"tv":38.98,"id":31376}]}]}
{"op":"mcm","clk":"11856727516","pt":1723361508825,"mc":[{"id":"1.231582198","rc":[{"batb":[[0,2.36,10]],"ltp":2.34,"tv":38.98,"id":31376}]}]}
{"op":"mcm","clk":"11856727567","pt":1723361509848,"mc":[{"id":"1.231582198","rc":[{"batb":[[0,2.34,29.13],[1,1.3,1000],[2,1.08,7.85]],"ltp":2.34,"tv":38.98,"id":31376}]}]}
{"op":"mcm","clk":"11856727623","pt":1723361510923,"mc":[{"id":"1.231582198","rc":[{"batb":[[0,2.36,4],[1,2.34,29.13],[2,1.3,1000]],"ltp":2.34,"tv":38.98,"id":31376}]}]}
{"op":"mcm","clk":"11856727753","pt":1723361513141,"mc":[{"id":"1.231582198","rc":[{"batb":[[0,2.38,10]],"ltp":2.34,"tv":38.98,"id":31376}]}]}
{"op":"mcm","clk":"11856727988","pt":1723361516320,"mc":[{"id":"1.231582198","rc":[{"batb":[[0,2.4,4]],"ltp":2.34,"tv":38.98,"id":31376}]}]}
{"op":"mcm","clk":"11856728142","pt":1723361519038,"mc":[{"id":"1.231582198","rc":[{"batb":[[0,2.42,10]],"ltp":2.34,"tv":38.98,"id":31376}]}]}
{"op":"mcm","clk":"11856728355","pt":1723361522330,"mc":[{"id":"1.231582198","rc":[{"batb":[[0,2.36,4]],"ltp":2.34,"tv":38.98,"id":31376}]}]}
{"op":"mcm","clk":"11856728525","pt":1723361525166,"mc":[{"id":"1.231582198","rc":[{"batl":[[1,1.74,25.36],[2,1.84,4.56]],"ltp":1.66,"tv":1114.95,"id":2780},{"batb":[[0,2.36,10]],"ltp":2.34,"tv":38.98,"id":31376}]}]}
{"op":"mcm","clk":"11856728654","pt":1723361526937,"mc":[{"id":"1.231582198","rc":[{"batl":[[0,1.73,4.45]],"ltp":1.66,"tv":1114.95,"id":2780},{"batb":[[0,2.38,4],[1,2.36,10],[2,2.34,29.13]],"ltp":2.34,"tv":38.98,"id":31376}]}]}
{"op":"mcm","clk":"11856728727","pt":1723361528072,"mc":[{"id":"1.231582198","rc":[{"batb":[[1,2.34,29.13],[2,1.3,1000]],"ltp":2.34,"tv":38.98,"id":31376}]}]}
{"op":"mcm","clk":"11856728802","pt":1723361529261,"mc":[{"id":"1.231582198","rc":[{"batb":[[0,2.34,29.13],[1,1.3,1000],[2,1.08,7.85]],"ltp":2.34,"tv":38.98,"id":31376}]}]}
{"op":"mcm","clk":"11856728898","pt":1723361530748,"mc":[{"id":"1.231582198","rc":[{"batb":[[0,2.36,10],[1,2.34,29.13],[2,1.3,1000]],"ltp":2.34,"tv":38.98,"id":31376}]}]}
{"op":"mcm","clk":"11856728968","pt":1723361531887,"mc":[{"id":"1.231582198","rc":[{"batb":[[0,2.38,4],[1,2.36,10],[2,2.34,29.13]],"ltp":2.34,"tv":38.98,"id":31376}]}]}
{"op":"mcm","clk":"11856729137","pt":1723361534253,"mc":[{"id":"1.231582198","rc":[{"batb":[[0,2.34,29.13],[1,1.3,1000],[2,1.08,7.85]],"ltp":2.34,"tv":38.98,"id":31376}]}]}
{"op":"mcm","clk":"11856729284","pt":1723361536569,"mc":[{"id":"1.231582198","rc":[{"batb":[[0,2.36,14],[1,2.34,29.13],[2,1.3,1000]],"ltp":2.34,"tv":38.98,"id":31376}]}]}
{"op":"mcm","clk":"11856729434","pt":1723361538884,"mc":[{"id":"1.231582198","rc":[{"batb":[[0,2.36,10]],"ltp":2.34,"tv":38.98,"id":31376}]}]}
{"op":"mcm","clk":"11856729504","pt":1723361539859,"mc":[{"id":"1.231582198","rc":[{"batb":[[0,2.34,29.13],[1,1.3,1000],[2,1.08,7.85]],"ltp":2.34,"tv":38.98,"id":31376}]}]}
{"op":"mcm","clk":"11856729588","pt":1723361541040,"mc":[{"id":"1.231582198","rc":[{"batb":[[0,2.36,4],[1,2.34,29.13],[2,1.3,1000]],"ltp":2.34,"tv":38.98,"id":31376}]}]}
{"op":"mcm","clk":"11856729673","pt":1723361542373,"mc":[{"id":"1.231582198","rc":[{"batb":[[0,2.38,10],[1,2.36,4],[2,2.34,29.13]],"ltp":2.34,"tv":38.98,"id":31376}]}]}
{"op":"mcm","clk":"11856729729","pt":1723361543354,"mc":[{"id":"1.231582198","rc":[{"batb":[[1,2.34,29.13],[2,1.3,1000]],"ltp":2.34,"tv":38.98,"id":31376}]}]}
{"op":"mcm","clk":"11856729875","pt":1723361545886,"mc":[{"id":"1.231582198","rc":[{"batb":[[0,2.4,4]],"ltp":2.34,"tv":38.98,"id":31376}]}]}
{"op":"mcm","clk":"11856730044","pt":1723361548288,"mc":[{"id":"1.231582198","rc":[{"batb":[[0,2.34,29.13],[1,1.3,1000],[2,1.08,7.85]],"ltp":2.34,"tv":38.98,"id":31376}]}]}
{"op":"mcm","clk":"11856730077","pt":1723361548750,"mc":[{"id":"1.231582198","rc":[{"batb":[[0,2.36,10],[1,2.34,29.13],[2,1.3,1000]],"ltp":2.34,"tv":38.98,"id":31376}]}]}
{"op":"mcm","clk":"11856730271","pt":1723361552080,"mc":[{"id":"1.231582198","rc":[{"batb":[[0,2.38,4]],"ltp":2.34,"tv":38.98,"id":31376}]}]}
{"op":"mcm","clk":"11856730384","pt":1723361553670,"mc":[{"id":"1.231582198","rc":[{"batb":[[0,2.34,29.13],[1,1.3,1000],[2,1.08,7.85]],"ltp":2.34,"tv":38.98,"id":31376}]}]}
{"op":"mcm","clk":"11856730470","pt":1723361554770,"mc":[{"id":"1.231582198","rc":[{"batb":[[0,2.36,10],[1,2.34,29.13],[2,1.3,1000]],"ltp":2.34,"tv":38.98,"id":31376}]}]}
{"op":"mcm","clk":"11856730554","pt":1723361555966,"mc":[{"id":"1.231582198","rc":[{"batb":[[0,2.38,4],[1,2.36,10],[2,2.34,29.13]],"ltp":2.34,"tv":38.98,"id":31376}]}]}
{"op":"mcm","clk":"11856730720","pt":1723361558397,"mc":[{"id":"1.231582198","rc":[{"batb":[[0,2.34,29.13],[1,1.3,1000],[2,1.08,7.85]],"ltp":2.34,"tv":38.98,"id":31376}]}]}
{"op":"mcm","clk":"11856738030","pt":1723361675411,"mc":[{"id":"1.231582198","rc":[{"batb":[[0,1.67,5.47],[1,1.66,15.64],[2,1.65,60.06]],"ltp":1.66,"tv":1114.95,"id":2780}]}]}
{"op":"mcm","clk":"11856739929","pt":1723361705234,"mc":[{"id":"1.231582198","rc":[{"trd":[[1.67,9.92]],"batb":[[0,1.66,16.15],[1,1.65,60.06],[2,1.56,4.56]],"ltp":1.67,"tv":1124.87,"id":2780}],"tv":1163.85}]}
{"op":"mcm","clk":"11856740990","pt":1723361720316,"mc":[{"id":"1.231582198","rc":[{"batl":[[0,1.72,5.47],[1,1.73,4.45],[2,1.74,25.36]],"ltp":1.67,"tv":1124.87,"id":2780}]}]}
{"op":"mcm","clk":"11856742693","pt":1723361747766,"mc":[{"id":"1.231582198","rc":[{"batb":[[0,1.67,3.8],[1,1.66,15.64],[2,1.65,60.06]],"ltp":1.67,"tv":1124.87,"id":2780}]}]}
{"op":"mcm","clk":"11856744457","pt":1723361776390,"mc":[{"id":"1.231582198","rc":[{"batl":[[0,1.73,4.45],[1,1.74,25.36],[2,1.84,4.56]],"ltp":1.67,"tv":1124.87,"id":2780}]}]}
{"op":"mcm","clk":"11856746354","pt":1723361807759,"mc":[{"id":"1.231582198","rc":[{"batl":[[0,1.73,13.57]],"ltp":1.67,"tv":1124.87,"id":2780}]}]}
{"op":"mcm","clk":"11856751027","pt":1723361879920,"mc":[{"id":"1.231582198","rc":[{"batl":[[0,1.72,9.12],[1,1.73,4.45],[2,1.74,25.36]],"ltp":1.67,"tv":1124.87,"id":2780}]}]}
{"op":"mcm","clk":"11856752430","pt":1723361900973,"mc":[{"id":"1.231582198","rc":[{"batl":[[0,1.72,5.47]],"ltp":1.67,"tv":1124.87,"id":2780}]}]}
{"op":"mcm","clk":"11856755528","pt":1723361946882,"mc":[{"id":"1.231582198","rc":[{"batb":[[0,2.42,10],[1,2.34,29.13],[2,1.3,1000]],"ltp":2.34,"tv":38.98,"id":31376}]}]}
{"op":"mcm","clk":"11856758209","pt":1723361996438,"mc":[{"id":"1.231582198","rc":[{"batl":[[0,1.73,4.45],[1,1.74,25.36],[2,1.84,4.56]],"ltp":1.67,"tv":1124.87,"id":2780}]}]}
{"op":"mcm","clk":"11856758215","pt":1723361996544,"mc":[{"id":"1.231582198","rc":[{"batl":[[1,1.74,30.83]],"ltp":1.67,"tv":1124.87,"id":2780}]}]}
{"op":"mcm","clk":"11856758473","pt":1723362001480,"mc":[{"id":"1.231582198","rc":[{"batl":[[1,1.74,25.36]],"ltp":1.67,"tv":1124.87,"id":2780}]}]}
{"op":"mcm","clk":"11856758487","pt":1723362001686,"mc":[{"id":"1.231582198","rc":[{"batl":[[0,1.73,9.92]],"ltp":1.67,"tv":1124.87,"id":2780}]}]}
{"op":"mcm","clk":"11856780924","pt":1723362357458,"mc":[{"id":"1.231582198","rc":[{"batl":[[2,1.85,100]],"ltp":1.67,"tv":1124.87,"id":2780}]}]}
{"op":"mcm","clk":"11856785103","pt":1723362418350,"mc":[{"id":"1.231582198","rc":[{"batl":[[0,1.7,4.56],[1,1.73,9.92],[2,1.74,25.36]],"ltp":1.67,"tv":1124.87,"id":2780}]}]}
{"op":"mcm","clk":"11856785223","pt":1723362420355,"mc":[{"id":"1.231582198","rc":[{"batl":[[0,1.7,9.09],[1,1.73,5.47]],"ltp":1.67,"tv":1124.87,"id":2780}]}]}
{"op":"mcm","clk":"11856793627","pt":1723362554482,"mc":[{"id":"1.231582198","rc":[{"batl":[[0,1.7,4.53],[1,1.74,25.36],[2,1.85,100]],"ltp":1.67,"tv":1124.87,"id":2780}]}]}
{"op":"mcm","clk":"11856795183","pt":1723362579753,"mc":[{"id":"1.231582198","rc":[{"batl":[[1,1.73,5.84],[2,1.74,25.36]],"ltp":1.67,"tv":1124.87,"id":2780}]}]}
{"op":"mcm","clk":"11856801218","pt":1723362677339,"mc":[{"id":"1.231582198","rc":[{"batl":[[0,1.7,5.44]],"ltp":1.67,"tv":1124.87,"id":2780}]}]}
{"op":"mcm","clk":"11856801704","pt":1723362685345,"mc":[{"id":"1.231582198","rc":[{"batl":[[0,1.7,6.35]],"ltp":1.67,"tv":1124.87,"id":2780}]}]}
{"op":"mcm","clk":"11856802091","pt":1723362692357,"mc":[{"id":"1.231582198","rc":[{"batl":[[0,1.69,1.82],[1,1.7,5.44],[2,1.73,5.84]],"ltp":1.67,"tv":1124.87,"id":2780}]}]}
{"op":"mcm","clk":"11856802539","pt":1723362700663,"mc":[{"id":"1.231582198","rc":[{"batl":[[1,1.7,6.35]],"ltp":1.67,"tv":1124.87,"id":2780}]}]}
{"op":"mcm","clk":"11856803306","pt":1723362714381,"mc":[{"id":"1.231582198","rc":[{"batl":[[2,1.73,6.75]],"ltp":1.67,"tv":1124.87,"id":2780}]}]}
{"op":"mcm","clk":"11856803702","pt":1723362721669,"mc":[{"id":"1.231582198","rc":[{"batl":[[2,1.72,1.82]],"ltp":1.67,"tv":1124.87,"id":2780}]}]}
{"op":"mcm","clk":"11856833196","pt":1723363201663,"mc":[{"id":"1.231582198","rc":[{"batb":[[2,1.65,87.77]],"ltp":1.67,"tv":1124.87,"id":2780},{"batb":[[0,2.42,22.68]],"ltp":2.34,"tv":38.98,"id":31376}]}]}
{"op":"mcm","clk":"11856833367","pt":1723363203272,"mc":[{"id":"1.231582198","rc":[{"batb":[[0,2.44,14],[1,2.42,22.68],[2,2.34,29.13]],"ltp":2.34,"tv":38.98,"id":31376}]}]}
{"op":"mcm","clk":"11856833662","pt":1723363206255,"mc":[{"id":"1.231582198","rc":[{"batb":[[0,2.44,10]],"ltp":2.34,"tv":38.98,"id":31376}]}]}
{"op":"mcm","clk":"11856833760","pt":1723363207339,"mc":[{"id":"1.231582198","rc":[{"batb":[[0,2.42,22.68],[1,2.34,29.13],[2,1.3,1000]],"ltp":2.34,"tv":38.98,"id":31376}]}]}
{"op":"mcm","clk":"11856833829","pt":1723363208370,"mc":[{"id":"1.231582198","rc":[{"batb":[[0,2.44,4],[1,2.42,22.68],[2,2.34,29.13]],"ltp":2.34,"tv":38.98,"id":31376}]}]}
{"op":"mcm","clk":"11856833977","pt":1723363210171,"mc":[{"id":"1.231582198","rc":[{"batb":[[0,2.46,10],[1,2.44,4],[2,2.42,22.68]],"ltp":2.34,"tv":38.98,"id":31376}]}]}
{"op":"mcm","clk":"11856834071","pt":1723363211360,"mc":[{"id":"1.231582198","rc":[{"batb":[[2,1.65,27.71]],"ltp":1.67,"tv":1124.87,"id":2780},{"batb":[[1,2.42,22.68],[2,1.3,1000]],"ltp":2.34,"tv":38.98,"id":31376}]}]}
{"op":"mcm","clk":"11856834101","pt":1723363211770,"mc":[{"id":"1.231582198","rc":[{"batb":[[2,1.39,8.76]],"ltp":1.67,"tv":1124.87,"id":2780}]}]}
{"op":"mcm","clk":"11856834263","pt":1723363213872,"mc":[{"id":"1.231582198","rc":[{"batb":[[0,2.44,4]],"ltp":2.34,"tv":38.98,"id":31376}]}]}
{"op":"mcm","clk":"11856834449","pt":1723363216264,"mc":[{"id":"1.231582198","rc":[{"batb":[[2,1.65,60.06]],"ltp":1.67,"tv":1124.87,"id":2780},{"batb":[[0,2.42,22.68],[1,2.34,29.13]],"ltp":2.34,"tv":38.98,"id":31376}]}]}
{"op":"mcm","clk":"11856834515","pt":1723363217062,"mc":[{"id":"1.231582198","rc":[{"batb":[[0,2.44,10],[1,2.42,22.68],[2,2.34,29.13]],"ltp":2.34,"tv":38.98,"id":31376}]}]}
{"op":"mcm","clk":"11856834646","pt":1723363218669,"mc":[{"id":"1.231582198","rc":[{"batb":[[2,1.65,87.77]],"ltp":1.67,"tv":1124.87,"id":2780},{"batb":[[0,2.46,4],[1,2.44,10],[2,2.42,22.68]],"ltp":2.34,"tv":38.98,"id":31376}]}]}
{"op":"mcm","clk":"11856834796","pt":1723363220656,"mc":[{"id":"1.231582198","rc":[{"batb":[[1,2.44,22.5]],"ltp":2.34,"tv":38.98,"id":31376}]}]}
{"op":"mcm","clk":"11856834947","pt":1723363222260,"mc":[{"id":"1.231582198","rc":[{"batb":[[0,2.42,22.68],[1,2.34,29.13],[2,1.3,1000]],"ltp":2.34,"tv":38.98,"id":31376}]}]}
{"op":"mcm","clk":"11856835349","pt":1723363228163,"mc":[{"id":"1.231582198","rc":[{"batb":[[0,2.44,14],[1,2.42,22.68],[2,2.34,29.13]],"ltp":2.34,"tv":38.98,"id":31376}]}]}
{"op":"mcm","clk":"11856835534","pt":1723363230802,"mc":[{"id":"1.231582198","rc":[{"batb":[[0,2.44,10]],"ltp":2.34,"tv":38.98,"id":31376}]}]}
{"op":"mcm","clk":"11856835608","pt":1723363231761,"mc":[{"id":"1.231582198","rc":[{"batb":[[0,2.42,22.68],[1,2.34,29.13],[2,1.3,1000]],"ltp":2.34,"tv":38.98,"id":31376}]}]}
{"op":"mcm","clk":"11856835699","pt":1723363233064,"mc":[{"id":"1.231582198","rc":[{"batb":[[0,2.44,4],[1,2.42,22.68],[2,2.34,29.13]],"ltp":2.34,"tv":38.98,"id":31376}]}]}
{"op":"mcm","clk":"11856835772","pt":1723363233999,"mc":[{"id":"1.231582198","rc":[{"batb":[[0,2.46,10],[1,2.44,4],[2,2.42,22.68]],"ltp":2.34,"tv":38.98,"id":31376}]}]}
{"op":"mcm","clk":"11856836007","pt":1723363236474,"mc":[{"id":"1.231582198","rc":[{"batb":[[2,1.65,27.71]],"ltp":1.67,"tv":1124.87,"id":2780},{"batb":[[1,2.42,22.68],[2,1.3,1000]],"ltp":2.34,"tv":38.98,"id":31376}]}]}
{"op":"mcm","clk":"11856836025","pt":1723363236784,"mc":[{"id":"1.231582198","rc":[{"batb":[[2,1.39,8.76]],"ltp":1.67,"tv":1124.87,"id":2780}]}]}
{"op":"mcm","clk":"11856836103","pt":1723363237664,"mc":[{"id":"1.231582198","rc":[{"batb":[[0,2.42,22.68],[1,1.3,1000],[2,1.08,7.85]],"ltp":2.34,"tv":38.98,"id":31376}]}]}
{"op":"mcm","clk":"11856836196","pt":1723363238904,"mc":[{"id":"1.231582198","rc":[{"batb":[[0,2.44,4],[1,2.42,22.68],[2,1.3,1000]],"ltp":2.34,"tv":38.98,"id":31376}]}]}
{"op":"mcm","clk":"11856836387","pt":1723363241489,"mc":[{"id":"1.231582198","rc":[{"batb":[[0,2.46,10]],"ltp":2.34,"tv":38.98,"id":31376}]}]}
{"op":"mcm","clk":"11856836591","pt":1723363244377,"mc":[{"id":"1.231582198","rc":[{"batb":[[0,2.44,4]],"ltp":2.34,"tv":38.98,"id":31376}]}]}
{"op":"mcm","clk":"11856836774","pt":1723363246488,"mc":[{"id":"1.231582198","rc":[{"batb":[[2,1.65,60.06]],"ltp":1.67,"tv":1124.87,"id":2780},{"batb":[[2,2.34,29.13]],"ltp":2.34,"tv":38.98,"id":31376}]}]}
{"op":"mcm","clk":"11856836809","pt":1723363246796,"mc":[{"id":"1.231582198","rc":[{"batb":[[0,2.46,10]],"ltp":2.34,"tv":38.98,"id":31376}]}]}
{"op":"mcm","clk":"11856836944","pt":1723363248698,"mc":[{"id":"1.231582198","rc":[{"batb":[[2,1.65,87.77]],"ltp":1.67,"tv":1124.87,"id":2780}]}]}
{"op":"mcm","clk":"11856837202","pt":1723363252411,"mc":[{"id":"1.231582198","rc":[{"batb":[[2,1.39,8.76]],"ltp":1.67,"tv":1124.87,"id":2780},{"batb":[[0,2.48,4],[2,1.3,1000]],"ltp":2.34,"tv":38.98,"id":31376}]}]}
{"op":"mcm","clk":"11856837414","pt":1723363255194,"mc":[{"id":"1.231582198","rc":[{"trd":[[1.67,13.72]],"batb":[[0,1.66,15.64],[1,1.39,8.76],[2,1.3,1000]],"ltp":1.67,"tv":1128.67,"id":2780},{"trd":[[2.5,2.54]],"batb":[[0,2.5,7.46]],"ltp":2.5,"tv":41.52,"id":31376}],"tv":1170.19}]}
{"op":"mcm","clk":"11856837612","pt":1723363257987,"mc":[{"id":"1.231582198","rc":[{"batb":[[0,2.42,22.68],[1,1.3,1000],[2,1.08,7.85]],"ltp":2.5,"tv":41.52,"id":31376}]}]}
{"op":"mcm","clk":"11856837666","pt":1723363258917,"mc":[{"id":"1.231582198","rc":[{"batb":[[0,2.44,4],[1,2.42,22.68],[2,1.3,1000]],"ltp":2.5,"tv":41.52,"id":31376}]}]}
{"op":"mcm","clk":"11856837817","pt":1723363261225,"mc":[{"id":"1.231582198","rc":[{"batb":[[0,2.46,10]],"ltp":2.5,"tv":41.52,"id":31376}]}]}
{"op":"mcm","clk":"11856838122","pt":1723363264900,"mc":[{"id":"1.231582198","rc":[{"batb":[[0,2.44,4]],"ltp":2.5,"tv":41.52,"id":31376}]}]}
{"op":"mcm","clk":"11856838245","pt":1723363266506,"mc":[{"id":"1.231582198","rc":[{"batb":[[1,1.65,60.06],[2,1.39,8.76]],"ltp":1.67,"tv":1128.67,"id":2780},{"batb":[[2,2.34,29.13]],"ltp":2.5,"tv":41.52,"id":31376}]}]}
{"op":"mcm","clk":"11856838308","pt":1723363267433,"mc":[{"id":"1.231582198","rc":[{"batb":[[0,2.42,22.68],[1,2.34,29.13],[2,1.3,1000]],"ltp":2.5,"tv":41.52,"id":31376}]}]}
{"op":"mcm","clk":"11856838321","pt":1723363267640,"mc":[{"id":"1.231582198","rc":[{"batb":[[0,2.44,10],[1,2.42,22.68],[2,2.34,29.13]],"ltp":2.5,"tv":41.52,"id":31376}]}]}
{"op":"mcm","clk":"11856838413","pt":1723363268724,"mc":[{"id":"1.231582198","rc":[{"batb":[[1,1.65,87.77]],"ltp":1.67,"tv":1128.67,"id":2780}]}]}
{"op":"mcm","clk":"11856838505","pt":1723363269907,"mc":[{"id":"1.231582198","rc":[{"batb":[[0,2.46,4],[1,2.44,10],[2,2.42,22.68]],"ltp":2.5,"tv":41.52,"id":31376}]}]}
{"op":"mcm","clk":"11856838583","pt":1723363270838,"mc":[{"id":"1.231582198","rc":[{"batb":[[2,1.61,16.42]],"ltp":1.67,"tv":1128.67,"id":2780},{"batb":[[1,2.42,22.68],[2,2.34,29.13]],"ltp":2.5,"tv":41.52,"id":31376}]}]}
{"op":"mcm","clk":"11856838681","pt":1723363272231,"mc":[{"id":"1.231582198","rc":[{"batb":[[0,2.42,22.68],[1,2.34,29.13],[2,1.3,1000]],"ltp":2.5,"tv":41.52,"id":31376}]}]}
{"op":"mcm","clk":"11856838782","pt":1723363273526,"mc":[{"id":"1.231582198","rc":[{"batb":[[0,2.44,10],[1,2.42,22.68],[2,2.34,29.13]],"ltp":2.5,"tv":41.52,"id":31376}]}]}
{"op":"mcm","clk":"11856838900","pt":1723363275128,"mc":[{"id":"1.231582198","rc":[{"batb":[[0,2.46,4],[1,2.44,10],[2,2.42,22.68]],"ltp":2.5,"tv":41.52,"id":31376}]}]}
{"op":"mcm","clk":"11856839096","pt":1723363277451,"mc":[{"id":"1.231582198","rc":[{"batb":[[0,2.42,22.68],[1,2.34,29.13],[2,1.3,1000]],"ltp":2.5,"tv":41.52,"id":31376}]}]}
{"op":"mcm","clk":"11856839261","pt":1723363279627,"mc":[{"id":"1.231582198","rc":[{"batb":[[0,2.44,14],[1,2.42,22.68],[2,2.34,29.13]],"ltp":2.5,"tv":41.52,"id":31376}]}]}
{"op":"mcm","clk":"11856839444","pt":1723363282144,"mc":[{"id":"1.231582198","rc":[{"batb":[[0,2.44,10]],"ltp":2.5,"tv":41.52,"id":31376}]}]}
{"op":"mcm","clk":"11856839514","pt":1723363283024,"mc":[{"id":"1.231582198","rc":[{"batb":[[0,2.42,22.68],[1,2.34,29.13],[2,1.3,1000]],"ltp":2.5,"tv":41.52,"id":31376}]}]}
{"op":"mcm","clk":"11856839609","pt":1723363284461,"mc":[{"id":"1.231582198","rc":[{"batb":[[0,2.44,4],[1,2.42,22.68],[2,2.34,29.13]],"ltp":2.5,"tv":41.52,"id":31376}]}]}
{"op":"mcm","clk":"11856839823","pt":1723363287354,"mc":[{"id":"1.231582198","rc":[{"batb":[[0,2.44,10]],"ltp":2.5,"tv":41.52,"id":31376}]}]}
{"op":"mcm","clk":"11856839918","pt":1723363288746,"mc":[{"id":"1.231582198","rc":[{"batb":[[0,1.67,4.56],[1,1.66,15.64],[2,1.65,87.77]],"ltp":1.67,"tv":1128.67,"id":2780}]}]}
{"op":"mcm","clk":"11856840037","pt":1723363290855,"mc":[{"id":"1.231582198","rc":[{"batl":[[0,1.69,10.58]],"ltp":1.67,"tv":1128.67,"id":2780},{"batb":[[0,2.46,4]],"ltp":2.5,"tv":41.52,"id":31376}]}]}
{"op":"mcm","clk":"11856840219","pt":1723363293072,"mc":[{"id":"1.231582198","rc":[{"batb":[[0,2.42,22.68],[1,2.34,29.13],[2,1.3,1000]],"ltp":2.5,"tv":41.52,"id":31376}]}]}
{"op":"mcm","clk":"11856840243","pt":1723363293540,"mc":[{"id":"1.231582198","rc":[{"batb":[[0,2.44,10],[1,2.42,22.68],[2,2.34,29.13]],"ltp":2.5,"tv":41.52,"id":31376}]}]}
{"op":"mcm","clk":"11856840341","pt":1723363295254,"mc":[{"id":"1.231582198","rc":[{"batb":[[0,2.46,4],[1,2.44,10],[2,2.42,22.68]],"ltp":2.5,"tv":41.52,"id":31376}]}]}
{"op":"mcm","clk":"11856840377","pt":1723363295667,"mc":[{"id":"1.231582198","rc":[{"batb":[[1,2.44,22.5]],"ltp":2.5,"tv":41.52,"id":31376}]}]}
{"op":"mcm","clk":"11856840500","pt":1723363297271,"mc":[{"id":"1.231582198","rc":[{"batb":[[1,2.42,22.68],[2,2.34,29.13]],"ltp":2.5,"tv":41.52,"id":31376}]}]}
{"op":"mcm","clk":"11856840524","pt":1723363297582,"mc":[{"id":"1.231582198","rc":[{"batb":[[0,2.42,22.68],[1,2.34,29.13],[2,1.3,1000]],"ltp":2.5,"tv":41.52,"id":31376}]}]}
{"op":"mcm","clk":"11856840693","pt":1723363299860,"mc":[{"id":"1.231582198","rc":[{"batb":[[0,2.44,14],[1,2.42,22.68],[2,2.34,29.13]],"ltp":2.5,"tv":41.52,"id":31376}]}]}
{"op":"mcm","clk":"11856840852","pt":1723363302148,"mc":[{"id":"1.231582198","rc":[{"batb":[[0,2.44,10]],"ltp":2.5,"tv":41.52,"id":31376}]}]}
{"op":"mcm","clk":"11856840947","pt":1723363303283,"mc":[{"id":"1.231582198","rc":[{"batb":[[0,2.42,22.68],[1,2.34,29.13],[2,1.3,1000]],"ltp":2.5,"tv":41.52,"id":31376}]}]}
{"op":"mcm","clk":"11856841113","pt":1723363305558,"mc":[{"id":"1.231582198","rc":[{"batb":[[0,2.44,14],[1,2.42,22.68],[2,2.34,29.13]],"ltp":2.5,"tv":41.52,"id":31376}]}]}
{"op":"mcm","clk":"11856841283","pt":1723363308092,"mc":[{"id":"1.231582198","rc":[{"batb":[[0,2.44,10]],"ltp":2.5,"tv":41.52,"id":31376}]}]}
{"op":"mcm","clk":"11856841338","pt":1723363308868,"mc":[{"id":"1.231582198","rc":[{"batb":[[0,2.42,22.68],[1,2.34,29.13],[2,1.3,1000]],"ltp":2.5,"tv":41.52,"id":31376}]}]}
{"op":"mcm","clk":"11856841433","pt":1723363310264,"mc":[{"id":"1.231582198","rc":[{"batb":[[0,2.44,4],[1,2.42,22.68],[2,2.34,29.13]],"ltp":2.5,"tv":41.52,"id":31376}]}]}
{"op":"mcm","clk":"11856841522","pt":1723363311503,"mc":[{"id":"1.231582198","rc":[{"batb":[[0,2.46,10],[1,2.44,4],[2,2.42,22.68]],"ltp":2.5,"tv":41.52,"id":31376}]}]}
{"op":"mcm","clk":"11856841584","pt":1723363312285,"mc":[{"id":"1.231582198","rc":[{"batb":[[2,1.61,16.42]],"ltp":1.67,"tv":1128.67,"id":2780}]}]}
{"op":"mcm","clk":"11856841628","pt":1723363312701,"mc":[{"id":"1.231582198","rc":[{"batb":[[2,1.61,45.94]],"ltp":1.67,"tv":1128.67,"id":2780},{"batb":[[1,2.42,22.68],[2,1.3,1000]],"ltp":2.5,"tv":41.52,"id":31376}]}]}
{"op":"mcm","clk":"11856841730","pt":1723363313959,"mc":[{"id":"1.231582198","rc":[{"batl":[[0,1.68,4.58],[1,1.69,10.58],[2,1.7,1.82]],"ltp":1.67,"tv":1128.67,"id":2780},{"batb":[[1,2.44,12.5],[2,2.42,22.68]],"ltp":2.5,"tv":41.52,"id":31376}]}]}
{"op":"mcm","clk":"11856841820","pt":1723363315271,"mc":[{"id":"1.231582198","rc":[{"batb":[[0,2.46,4],[1,2.42,22.68],[2,1.3,1000]],"ltp":2.5,"tv":41.52,"id":31376}]}]}
{"op":"mcm","clk":"11856841954","pt":1723363317302,"mc":[{"id":"1.231582198","rc":[{"batb":[[2,1.65,60.06]],"ltp":1.67,"tv":1128.67,"id":2780},{"batb":[[0,2.48,10],[2,2.34,29.13]],"ltp":2.5,"tv":41.52,"id":31376}]}]}
{"op":"mcm","clk":"11856842060","pt":1723363318699,"mc":[{"id":"1.231582198","rc":[{"batb":[[2,1.65,87.77]],"ltp":1.67,"tv":1128.67,"id":2780},{"batb":[[1,2.44,12.5],[2,2.42,22.68]],"ltp":2.5,"tv":41.52,"id":31376}]}]}
{"op":"mcm","clk":"11856842200","pt":1723363320509,"mc":[{"id":"1.231582198","rc":[{"batb":[[0,2.46,4]],"ltp":2.5,"tv":41.52,"id":31376}]}]}
{"op":"mcm","clk":"11856842214","pt":1723363320676,"mc":[{"id":"1.231582198","rc":[{"batb":[[1,2.42,22.68],[2,2.34,29.13]],"ltp":2.5,"tv":41.52,"id":31376}]}]}
{"op":"mcm","clk":"11856842406","pt":1723363322983,"mc":[{"id":"1.231582198","rc":[{"batb":[[0,2.42,22.68],[1,2.34,29.13],[2,1.3,1000]],"ltp":2.5,"tv":41.52,"id":31376}]}]}
{"op":"mcm","clk":"11856842472","pt":1723363323809,"mc":[{"id":"1.231582198","rc":[{"batb":[[0,2.44,10],[1,2.42,22.68],[2,2.34,29.13]],"ltp":2.5,"tv":41.52,"id":31376}]}]}
{"op":"mcm","clk":"11856842587","pt":1723363325473,"mc":[{"id":"1.231582198","rc":[{"batl":[[0,1.69,15.13],[1,1.7,1.82],[2,1.72,1.82]],"ltp":1.67,"tv":1128.67,"id":2780},{"batb":[[0,2.46,4],[1,2.44,10],[2,2.42,22.68]],"ltp":2.5,"tv":41.52,"id":31376}]}]}
{"op":"mcm","clk":"11856842603","pt":1723363325677,"mc":[{"id":"1.231582198","rc":[{"batb":[[1,2.44,22.5]],"ltp":2.5,"tv":41.52,"id":31376}]}]}
{"op":"mcm","clk":"11856842726","pt":1723363327188,"mc":[{"id":"1.231582198","rc":[{"batb":[[1,2.44,12.5]],"ltp":2.5,"tv":41.52,"id":31376}]}]}
{"op":"mcm","clk":"11856842780","pt":1723363327705,"mc":[{"id":"1.231582198","rc":[{"batb":[[0,2.42,22.68],[1,2.34,29.13],[2,1.3,1000]],"ltp":2.5,"tv":41.52,"id":31376}]}]}
{"op":"mcm","clk":"11856842997","pt":1723363330078,"mc":[{"id":"1.231582198","rc":[{"batl":[[0,1.69,10.58],[1,1.7,6.35]],"ltp":1.67,"tv":1128.67,"id":2780},{"batb":[[0,2.46,4],[1,2.44,10],[2,2.42,22.68]],"ltp":2.5,"tv":41.52,"id":31376}]}]}
{"op":"mcm","clk":"11856843089","pt":1723363331678,"mc":[{"id":"1.231582198","rc":[{"batb":[[1,2.44,22.5]],"ltp":2.5,"tv":41.52,"id":31376}]}]}
{"op":"mcm","clk":"11856843217","pt":1723363333321,"mc":[{"id":"1.231582198","rc":[{"batb":[[0,2.42,22.68],[1,2.34,29.13],[2,1.3,1000]],"ltp":2.5,"tv":41.52,"id":31376}]}]}
{"op":"mcm","clk":"11856843388","pt":1723363335602,"mc":[{"id":"1.231582198","rc":[{"batb":[[0,2.44,14],[1,2.42,22.68],[2,2.34,29.13]],"ltp":2.5,"tv":41.52,"id":31376}]}]}
{"op":"mcm","clk":"11856843562","pt":1723363337990,"mc":[{"id":"1.231582198","rc":[{"batb":[[0,2.44,10]],"ltp":2.5,"tv":41.52,"id":31376}]}]}
{"op":"mcm","clk":"11856843643","pt":1723363338926,"mc":[{"id":"1.231582198","rc":[{"batb":[[0,2.42,22.68],[1,2.34,29.13],[2,1.3,1000]],"ltp":2.5,"tv":41.52,"id":31376}]}]}
{"op":"mcm","clk":"11856844078","pt":1723363344424,"mc":[{"id":"1.231582198","rc":[{"batb":[[0,2.44,4],[1,2.42,22.68],[2,2.34,29.13]],"ltp":2.5,"tv":41.52,"id":31376}]}]}
{"op":"mcm","clk":"11856844086","pt":1723363344528,"mc":[{"id":"1.231582198","rc":[{"batb":[[0,2.44,14]],"ltp":2.5,"tv":41.52,"id":31376}]}]}
{"op":"mcm","clk":"11856844315","pt":1723363347426,"mc":[{"id":"1.231582198","rc":[{"batb":[[0,2.44,10]],"ltp":2.5,"tv":41.52,"id":31376}]}]}
{"op":"mcm","clk":"11856844390","pt":1723363348514,"mc":[{"id":"1.231582198","rc":[{"batb":[[0,2.42,22.68],[1,2.34,29.13],[2,1.3,1000]],"ltp":2.5,"tv":41.52,"id":31376}]}]}
{"op":"mcm","clk":"11856844486","pt":1723363349821,"mc":[{"id":"1.231582198","rc":[{"batb":[[0,2.44,4],[1,2.42,22.68],[2,2.34,29.13]],"ltp":2.5,"tv":41.52,"id":31376}]}]}
{"op":"mcm","clk":"11856844561","pt":1723363351011,"mc":[{"id":"1.231582198","rc":[{"batb":[[0,2.46,10],[1,2.44,4],[2,2.42,22.68]],"ltp":2.5,"tv":41.52,"id":31376}]}]}
{"op":"mcm","clk":"11856844645","pt":1723363352223,"mc":[{"id":"1.231582198","rc":[{"batb":[[2,1.61,45.94]],"ltp":1.67,"tv":1128.67,"id":2780},{"batb":[[1,2.42,22.68],[2,1.3,1000]],"ltp":2.5,"tv":41.52,"id":31376}]}]}
{"op":"mcm","clk":"11856844711","pt":1723363353112,"mc":[{"id":"1.231582198","rc":[{"batl":[[1,1.7,1.82]],"ltp":1.67,"tv":1128.67,"id":2780},{"batb":[[1,2.44,12.5],[2,2.42,22.68]],"ltp":2.5,"tv":41.52,"id":31376}]}]}
{"op":"mcm","clk":"11856844896","pt":1723363355239,"mc":[{"id":"1.231582198","rc":[{"batb":[[0,2.46,4],[1,2.42,22.68],[2,1.3,1000]],"ltp":2.5,"tv":41.52,"id":31376}]}]}
{"op":"mcm","clk":"11856845058","pt":1723363357325,"mc":[{"id":"1.231582198","rc":[{"batb":[[2,1.65,60.06]],"ltp":1.67,"tv":1128.67,"id":2780},{"batb":[[0,2.48,10],[2,2.34,29.13]],"ltp":2.5,"tv":41.52,"id":31376}]}]}
{"op":"mcm","clk":"11856845140","pt":1723363358719,"mc":[{"id":"1.231582198","rc":[{"batb":[[2,1.65,87.77]],"ltp":1.67,"tv":1128.67,"id":2780},{"batb":[[1,2.44,12.5],[2,2.42,22.68]],"ltp":2.5,"tv":41.52,"id":31376}]}]}
{"op":"mcm","clk":"11856845356","pt":1723363361509,"mc":[{"id":"1.231582198","rc":[{"batl":[[0,1.68,4.58],[1,1.69,10.58],[2,1.7,1.82]],"ltp":1.67,"tv":1128.67,"id":2780},{"batb":[[0,2.46,4],[1,2.42,22.68],[2,2.34,29.13]],"ltp":2.5,"tv":41.52,"id":31376}]}]}
{"op":"mcm","clk":"11856845569","pt":1723363364040,"mc":[{"id":"1.231582198","rc":[{"batb":[[0,2.44,10]],"ltp":2.5,"tv":41.52,"id":31376}]}]}
{"op":"mcm","clk":"11856845719","pt":1723363366053,"mc":[{"id":"1.231582198","rc":[{"batl":[[0,1.69,1.82],[1,1.7,10.58],[2,1.72,1.82]],"ltp":1.67,"tv":1128.67,"id":2780},{"batb":[[0,2.46,4],[1,2.44,22.5],[2,2.42,22.68]],"ltp":2.5,"tv":41.52,"id":31376}]}]}
{"op":"mcm","clk":"11856845811","pt":1723363367355,"mc":[{"id":"1.231582198","rc":[{"batb":[[1,2.44,12.5]],"ltp":2.5,"tv":41.52,"id":31376}]}]}
{"op":"mcm","clk":"11856845891","pt":1723363368444,"mc":[{"id":"1.231582198","rc":[{"batb":[[0,2.42,22.68],[1,2.34,29.13],[2,1.3,1000]],"ltp":2.5,"tv":41.52,"id":31376}]}]}
{"op":"mcm","clk":"11856845994","pt":1723363369936,"mc":[{"id":"1.231582198","rc":[{"batb":[[0,2.44,10],[1,2.42,22.68],[2,2.34,29.13]],"ltp":2.5,"tv":41.52,"id":31376}]}]}
{"op":"mcm","clk":"11856846125","pt":1723363371431,"mc":[{"id":"1.231582198","rc":[{"batb":[[0,2.46,4],[1,2.44,10],[2,2.42,22.68]],"ltp":2.5,"tv":41.52,"id":31376}]}]}
{"op":"mcm","clk":"11856846257","pt":1723363373443,"mc":[{"id":"1.231582198","rc":[{"batb":[[1,2.42,22.68],[2,2.34,29.13]],"ltp":2.5,"tv":41.52,"id":31376}]}]}
{"op":"mcm","clk":"11856846315","pt":1723363374115,"mc":[{"id":"1.231582198","rc":[{"batb":[[0,2.42,22.68],[1,2.34,29.13],[2,1.3,1000]],"ltp":2.5,"tv":41.52,"id":31376}]}]}
{"op":"mcm","clk":"11856846500","pt":1723363377125,"mc":[{"id":"1.231582198","rc":[{"batb":[[0,2.44,14],[1,2.42,22.68],[2,2.34,29.13]],"ltp":2.5,"tv":41.52,"id":31376}]}]}
{"op":"mcm","clk":"11856846631","pt":1723363379534,"mc":[{"id":"1.231582198","rc":[{"batb":[[0,2.44,10]],"ltp":2.5,"tv":41.52,"id":31376}]}]}
{"op":"mcm","clk":"11856846696","pt":1723363380674,"mc":[{"id":"1.231582198","rc":[{"batb":[[0,2.42,22.68],[1,2.34,29.13],[2,1.3,1000]],"ltp":2.5,"tv":41.52,"id":31376}]}]}
{"op":"mcm","clk":"11856846767","pt":1723363381867,"mc":[{"id":"1.231582198","rc":[{"batb":[[0,2.44,4],[1,2.42,22.68],[2,2.34,29.13]],"ltp":2.5,"tv":41.52,"id":31376}]}]}
{"op":"mcm","clk":"11856846904","pt":1723363383480,"mc":[{"id":"1.231582198","rc":[{"batb":[[0,2.46,10],[1,2.44,4],[2,2.42,22.68]],"ltp":2.5,"tv":41.52,"id":31376}]}]}
{"op":"mcm","clk":"11856846959","pt":1723363384151,"mc":[{"id":"1.231582198","rc":[{"batl":[[0,1.69,6.38]],"ltp":1.67,"tv":1128.67,"id":2780},{"batb":[[1,2.42,22.68],[2,2.34,29.13]],"ltp":2.5,"tv":41.52,"id":31376}]}]}
{"op":"mcm","clk":"11856847177","pt":1723363387182,"mc":[{"id":"1.231582198","rc":[{"batb":[[0,2.48,4]],"ltp":2.5,"tv":41.52,"id":31376}]}]}
{"op":"mcm","clk":"11856847418","pt":1723363390290,"mc":[{"id":"1.231582198","rc":[{"batb":[[0,2.44,10]],"ltp":2.5,"tv":41.52,"id":31376}]}]}
{"op":"mcm","clk":"11856847683","pt":1723363393895,"mc":[{"id":"1.231582198","rc":[{"batb":[[0,2.44,4]],"ltp":2.5,"tv":41.52,"id":31376}]}]}
{"op":"mcm","clk":"11856847842","pt":1723363396211,"mc":[{"id":"1.231582198","rc":[{"batb":[[0,2.42,22.68],[1,2.34,29.13],[2,1.3,1000]],"ltp":2.5,"tv":41.52,"id":31376}]}]}
{"op":"mcm","clk":"11856847884","pt":1723363396779,"mc":[{"id":"1.231582198","rc":[{"batb":[[0,2.44,10],[1,2.42,22.68],[2,2.34,29.13]],"ltp":2.5,"tv":41.52,"id":31376}]}]}
{"op":"mcm","clk":"11856848074","pt":1723363399198,"mc":[{"id":"1.231582198","rc":[{"batb":[[0,2.46,4],[1,2.44,10],[2,2.42,22.68]],"ltp":2.5,"tv":41.52,"id":31376}]}]}
{"op":"mcm","clk":"11856848128","pt":1723363399914,"mc":[{"id":"1.231582198","rc":[{"batb":[[1,2.42,22.68],[2,2.34,29.13]],"ltp":2.5,"tv":41.52,"id":31376}]}]}
{"op":"mcm","clk":"11856848294","pt":1723363402282,"mc":[{"id":"1.231582198","rc":[{"batb":[[0,2.44,10]],"ltp":2.5,"tv":41.52,"id":31376}]}]}
{"op":"mcm","clk":"11856848412","pt":1723363404181,"mc":[{"id":"1.231582198","rc":[{"batb":[[0,2.46,4],[1,2.44,10],[2,2.42,22.68]],"ltp":2.5,"tv":41.52,"id":31376}]}]}
{"op":"mcm","clk":"11856848502","pt":1723363405718,"mc":[{"id":"1.231582198","rc":[{"batb":[[1,2.42,22.68],[2,2.34,29.13]],"ltp":2.5,"tv":41.52,"id":31376}]}]}
{"op":"mcm","clk":"11856848574","pt":1723363406902,"mc":[{"id":"1.231582198","rc":[{"batb":[[0,2.42,22.68],[1,2.34,29.13],[2,1.3,1000]],"ltp":2.5,"tv":41.52,"id":31376}]}]}
{"op":"mcm","clk":"11856848635","pt":1723363407927,"mc":[{"id":"1.231582198","rc":[{"batl":[[0,1.69,1.82],[1,1.7,15.11]],"ltp":1.67,"tv":1128.67,"id":2780},{"batb":[[0,2.44,10],[1,2.42,22.68],[2,2.34,29.13]],"ltp":2.5,"tv":41.52,"id":31376}]}]}
{"op":"mcm","clk":"11856848700","pt":1723363409007,"mc":[{"id":"1.231582198","rc":[{"batb":[[0,2.46,4],[1,2.44,10],[2,2.42,22.68]],"ltp":2.5,"tv":41.52,"id":31376}]}]}
{"op":"mcm","clk":"11856848856","pt":1723363411324,"mc":[{"id":"1.231582198","rc":[{"batb":[[0,2.44,12.5],[1,2.42,22.68],[2,2.34,29.13]],"ltp":2.5,"tv":41.52,"id":31376}]}]}
{"op":"mcm","clk":"11856848901","pt":1723363411895,"mc":[{"id":"1.231582198","rc":[{"batb":[[0,2.42,22.68],[1,2.34,29.13],[2,1.3,1000]],"ltp":2.5,"tv":41.52,"id":31376}]}]}
{"op":"mcm","clk":"11856849168","pt":1723363415301,"mc":[{"id":"1.231582198","rc":[{"batb":[[0,2.44,14],[1,2.42,22.68],[2,2.34,29.13]],"ltp":2.5,"tv":41.52,"id":31376}]}]}
{"op":"mcm","clk":"11856849388","pt":1723363418441,"mc":[{"id":"1.231582198","rc":[{"batb":[[0,2.42,22.68],[1,2.34,29.13],[2,1.3,1000]],"ltp":2.5,"tv":41.52,"id":31376}]}]}
{"op":"mcm","clk":"11856849641","pt":1723363422448,"mc":[{"id":"1.231582198","rc":[{"batb":[[0,2.44,14],[1,2.42,22.68],[2,2.34,29.13]],"ltp":2.5,"tv":41.52,"id":31376}]}]}
{"op":"mcm","clk":"11856849763","pt":1723363424345,"mc":[{"id":"1.231582198","rc":[{"batb":[[0,2.44,10]],"ltp":2.5,"tv":41.52,"id":31376}]}]}
{"op":"mcm","clk":"11856849815","pt":1723363425223,"mc":[{"id":"1.231582198","rc":[{"batb":[[0,2.42,22.68],[1,2.34,29.13],[2,1.3,1000]],"ltp":2.5,"tv":41.52,"id":31376}]}]}
{"op":"mcm","clk":"11856850086","pt":1723363428923,"mc":[{"id":"1.231582198","rc":[{"batb":[[0,2.44,14],[1,2.42,22.68],[2,2.34,29.13]],"ltp":2.5,"tv":41.52,"id":31376}]}]}
{"op":"mcm","clk":"11856850312","pt":1723363431755,"mc":[{"id":"1.231582198","rc":[{"batb":[[0,2.44,10]],"ltp":2.5,"tv":41.52,"id":31376}]}]}
{"op":"mcm","clk":"11856850373","pt":1723363432630,"mc":[{"id":"1.231582198","rc":[{"batb":[[0,2.42,22.68],[1,2.34,29.13],[2,1.3,1000]],"ltp":2.5,"tv":41.52,"id":31376}]}]}
{"op":"mcm","clk":"11856850521","pt":1723363434847,"mc":[{"id":"1.231582198","rc":[{"batb":[[0,2.44,14],[1,2.42,22.68],[2,2.34,29.13]],"ltp":2.5,"tv":41.52,"id":31376}]}]}
{"op":"mcm","clk":"11856850670","pt":1723363437174,"mc":[{"id":"1.231582198","rc":[{"batb":[[0,2.44,10]],"ltp":2.5,"tv":41.52,"id":31376}]}]}
{"op":"mcm","clk":"11856850767","pt":1723363438367,"mc":[{"id":"1.231582198","rc":[{"batb":[[0,2.42,22.68],[1,2.34,29.13],[2,1.3,1000]],"ltp":2.5,"tv":41.52,"id":31376}]}]}
{"op":"mcm","clk":"11856850961","pt":1723363440948,"mc":[{"id":"1.231582198","rc":[{"batb":[[0,2.44,14],[1,2.42,22.68],[2,2.34,29.13]],"ltp":2.5,"tv":41.52,"id":31376}]}]}
{"op":"mcm","clk":"11856851156","pt":1723363443277,"mc":[{"id":"1.231582198","rc":[{"batb":[[0,2.44,10]],"ltp":2.5,"tv":41.52,"id":31376}]}]}
{"op":"mcm","clk":"11856851235","pt":1723363444259,"mc":[{"id":"1.231582198","rc":[{"batb":[[0,2.42,22.68],[1,2.34,29.13],[2,1.3,1000]],"ltp":2.5,"tv":41.52,"id":31376}]}]}
{"op":"mcm","clk":"11856851311","pt":1723363445448,"mc":[{"id":"1.231582198","rc":[{"batb":[[0,2.44,4],[1,2.42,22.68],[2,2.34,29.13]],"ltp":2.5,"tv":41.52,"id":31376}]}]}
{"op":"mcm","clk":"11856851469","pt":1723363447455,"mc":[{"id":"1.231582198","rc":[{"batb":[[2,1.65,27.71]],"ltp":1.67,"tv":1128.67,"id":2780},{"batb":[[0,2.46,10],[1,2.44,4],[2,2.42,22.68]],"ltp":2.5,"tv":41.52,"id":31376}]}]}
{"op":"mcm","clk":"11856851504","pt":1723363447860,"mc":[{"id":"1.231582198","rc":[{"batb":[[2,1.61,45.94]],"ltp":1.67,"tv":1128.67,"id":2780},{"batb":[[1,2.42,22.68],[2,1.3,1000]],"ltp":2.5,"tv":41.52,"id":31376}]}]}
{"op":"mcm","clk":"11856851658","pt":1723363450179,"mc":[{"id":"1.231582198","rc":[{"batb":[[0,2.48,4],[1,2.46,10],[2,2.42,22.68]],"ltp":2.5,"tv":41.52,"id":31376}]}]}
{"op":"mcm","clk":"11856851751","pt":1723363451478,"mc":[{"id":"1.231582198","rc":[{"batb":[[1,2.42,22.68],[2,1.3,1000]],"ltp":2.5,"tv":41.52,"id":31376}]}]}
{"op":"mcm","clk":"11856851818","pt":1723363452357,"mc":[{"id":"1.231582198","rc":[{"batb":[[2,1.65,60.06]],"ltp":1.67,"tv":1128.67,"id":2780},{"batb":[[2,2.34,29.13]],"ltp":2.5,"tv":41.52,"id":31376}]}]}
{"op":"mcm","clk":"11856851832","pt":1723363452566,"mc":[{"id":"1.231582198","rc":[{"batb":[[0,2.42,22.68],[1,2.34,29.13],[2,1.3,1000]],"ltp":2.5,"tv":41.52,"id":31376}]}]}
{"op":"mcm","clk":"11856851988","pt":1723363455080,"mc":[{"id":"1.231582198","rc":[{"batb":[[2,1.65,87.77]],"ltp":1.67,"tv":1128.67,"id":2780},{"batb":[[0,2.44,14],[1,2.42,22.68],[2,2.34,29.13]],"ltp":2.5,"tv":41.52,"id":31376}]}]}
{"op":"mcm","clk":"11856852152","pt":1723363457397,"mc":[{"id":"1.231582198","rc":[{"batb":[[0,2.44,10]],"ltp":2.5,"tv":41.52,"id":31376}]}]}
{"op":"mcm","clk":"11856852233","pt":1723363458381,"mc":[{"id":"1.231582198","rc":[{"batb":[[0,2.42,22.68],[1,2.34,29.13],[2,1.3,1000]],"ltp":2.5,"tv":41.52,"id":31376}]}]}
{"op":"mcm","clk":"11856852421","pt":1723363460969,"mc":[{"id":"1.231582198","rc":[{"batb":[[0,2.44,14],[1,2.42,22.68],[2,2.34,29.13]],"ltp":2.5,"tv":41.52,"id":31376}]}]}
{"op":"mcm","clk":"11856852589","pt":1723363463289,"mc":[{"id":"1.231582198","rc":[{"batb":[[0,2.44,10]],"ltp":2.5,"tv":41.52,"id":31376}]}]}
{"op":"mcm","clk":"11856852657","pt":1723363464273,"mc":[{"id":"1.231582198","rc":[{"batb":[[0,2.42,22.68],[1,2.34,29.13],[2,1.3,1000]],"ltp":2.5,"tv":41.52,"id":31376}]}]}
{"op":"mcm","clk":"11856852979","pt":1723363468800,"mc":[{"id":"1.231582198","rc":[{"batb":[[0,2.44,14],[1,2.42,22.68],[2,2.34,29.13]],"ltp":2.5,"tv":41.52,"id":31376}]}]}
{"op":"mcm","clk":"11856853157","pt":1723363471324,"mc":[{"id":"1.231582198","rc":[{"batb":[[0,2.44,10]],"ltp":2.5,"tv":41.52,"id":31376}]}]}
{"op":"mcm","clk":"11856853269","pt":1723363472423,"mc":[{"id":"1.231582198","rc":[{"batb":[[0,2.42,22.68],[1,2.34,29.13],[2,1.3,1000]],"ltp":2.5,"tv":41.52,"id":31376}]}]}
{"op":"mcm","clk":"11856853412","pt":1723363474284,"mc":[{"id":"1.231582198","rc":[{"batb":[[0,2.44,4],[1,2.42,22.68],[2,2.34,29.13]],"ltp":2.5,"tv":41.52,"id":31376}]}]}
{"op":"mcm","clk":"11856853450","pt":1723363474795,"mc":[{"id":"1.231582198","rc":[{"batb":[[0,2.46,10],[1,2.44,4],[2,2.42,22.68]],"ltp":2.5,"tv":41.52,"id":31376}]}]}
{"op":"mcm","clk":"11856853652","pt":1723363477400,"mc":[{"id":"1.231582198","rc":[{"batb":[[1,2.42,22.68],[2,2.34,29.13]],"ltp":2.5,"tv":41.52,"id":31376}]}]}
{"op":"mcm","clk":"11856853719","pt":1723363478328,"mc":[{"id":"1.231582198","rc":[{"batb":[[2,1.61,45.94]],"ltp":1.67,"tv":1128.67,"id":2780},{"batb":[[0,2.42,22.68],[1,1.3,1000],[2,1.08,7.85]],"ltp":2.5,"tv":41.52,"id":31376}]}]}
{"op":"mcm","clk":"11856853872","pt":1723363480295,"mc":[{"id":"1.231582198","rc":[{"batb":[[0,2.44,4],[1,2.42,22.68],[2,1.3,1000]],"ltp":2.5,"tv":41.52,"id":31376}]}]}
{"op":"mcm","clk":"11856853910","pt":1723363480709,"mc":[{"id":"1.231582198","rc":[{"batb":[[0,2.46,10],[1,2.44,4],[2,2.42,22.68]],"ltp":2.5,"tv":41.52,"id":31376}]}]}
{"op":"mcm","clk":"11856854104","pt":1723363483338,"mc":[{"id":"1.231582198","rc":[{"batb":[[1,2.42,22.68],[2,1.3,1000]],"ltp":2.5,"tv":41.52,"id":31376}]}]}
{"op":"mcm","clk":"11856854193","pt":1723363484423,"mc":[{"id":"1.231582198","rc":[{"batb":[[0,2.42,22.68],[1,1.3,1000],[2,1.08,7.85]],"ltp":2.5,"tv":41.52,"id":31376}]}]}
{"op":"mcm","clk":"11856854341","pt":1723363486206,"mc":[{"id":"1.231582198","rc":[{"batb":[[0,2.44,4],[1,2.42,22.68],[2,1.3,1000]],"ltp":2.5,"tv":41.52,"id":31376}]}]}
{"op":"mcm","clk":"11856854457","pt":1723363487504,"mc":[{"id":"1.231582198","rc":[{"batb":[[2,1.65,60.06]],"ltp":1.67,"tv":1128.67,"id":2780},{"batb":[[2,2.34,29.13]],"ltp":2.5,"tv":41.52,"id":31376}]}]}
{"op":"mcm","clk":"11856854473","pt":1723363487715,"mc":[{"id":"1.231582198","rc":[{"batb":[[0,2.46,10],[1,2.44,4],[2,2.42,22.68]],"ltp":2.5,"tv":41.52,"id":31376}]}]}
{"op":"mcm","clk":"11856854532","pt":1723363488537,"mc":[{"id":"1.231582198","rc":[{"batb":[[1,2.42,22.68],[2,2.34,29.13]],"ltp":2.5,"tv":41.52,"id":31376}]}]}
{"op":"mcm","clk":"11856854629","pt":1723363489827,"mc":[{"id":"1.231582198","rc":[{"batb":[[2,1.65,87.77]],"ltp":1.67,"tv":1128.67,"id":2780}]}]}
{"op":"mcm","clk":"11856854718","pt":1723363491118,"mc":[{"id":"1.231582198","rc":[{"batb":[[0,2.44,4]],"ltp":2.5,"tv":41.52,"id":31376}]}]}
{"op":"mcm","clk":"11856854906","pt":1723363493445,"mc":[{"id":"1.231582198","rc":[{"batb":[[0,2.46,10]],"ltp":2.5,"tv":41.52,"id":31376}]}]}
{"op":"mcm","clk":"11856855204","pt":1723363496820,"mc":[{"id":"1.231582198","rc":[{"batb":[[0,2.44,4]],"ltp":2.5,"tv":41.52,"id":31376}]}]}
{"op":"mcm","clk":"11856855384","pt":1723363499410,"mc":[{"id":"1.231582198","rc":[{"batb":[[0,2.46,10]],"ltp":2.5,"tv":41.52,"id":31376}]}]}
{"op":"mcm","clk":"11856855735","pt":1723363503413,"mc":[{"id":"1.231582198","rc":[{"batb":[[2,1.61,45.94]],"ltp":1.67,"tv":1128.67,"id":2780},{"batb":[[0,2.44,4],[2,1.3,1000]],"ltp":2.5,"tv":41.52,"id":31376}]}]}
{"op":"mcm","clk":"11856855895","pt":1723363505445,"mc":[{"id":"1.231582198","rc":[{"batb":[[0,2.42,22.68],[1,1.3,1000],[2,1.08,7.85]],"ltp":2.5,"tv":41.52,"id":31376}]}]}
{"op":"mcm","clk":"11856855936","pt":1723363506015,"mc":[{"id":"1.231582198","rc":[{"batb":[[0,2.44,10],[1,2.42,22.68],[2,1.3,1000]],"ltp":2.5,"tv":41.52,"id":31376}]}]}
{"op":"mcm","clk":"11856856047","pt":1723363507623,"mc":[{"id":"1.231582198","rc":[{"batb":[[2,1.65,60.06]],"ltp":1.67,"tv":1128.67,"id":2780},{"batb":[[0,2.46,4],[1,2.44,10],[2,2.42,22.68]],"ltp":2.5,"tv":41.52,"id":31376}]}]}
{"op":"mcm","clk":"11856856190","pt":1723363510140,"mc":[{"id":"1.231582198","rc":[{"batb":[[2,1.65,87.77]],"ltp":1.67,"tv":1128.67,"id":2780},{"batb":[[0,2.42,22.68],[1,2.34,29.13],[2,1.3,1000]],"ltp":2.5,"tv":41.52,"id":31376}]}]}
{"op":"mcm","clk":"11856856366","pt":1723363512641,"mc":[{"id":"1.231582198","rc":[{"batb":[[0,2.44,14],[1,2.42,22.68],[2,2.34,29.13]],"ltp":2.5,"tv":41.52,"id":31376}]}]}
{"op":"mcm","clk":"11856856520","pt":1723363515068,"mc":[{"id":"1.231582198","rc":[{"batb":[[0,2.44,10]],"ltp":2.5,"tv":41.52,"id":31376}]}]}
{"op":"mcm","clk":"11856856583","pt":1723363515945,"mc":[{"id":"1.231582198","rc":[{"batb":[[0,2.42,22.68],[1,2.34,29.13],[2,1.3,1000]],"ltp":2.5,"tv":41.52,"id":31376}]}]}
{"op":"mcm","clk":"11856856737","pt":1723363518061,"mc":[{"id":"1.231582198","rc":[{"batb":[[0,2.44,14],[1,2.42,22.68],[2,2.34,29.13]],"ltp":2.5,"tv":41.52,"id":31376}]}]}
{"op":"mcm","clk":"11856856949","pt":1723363520440,"mc":[{"id":"1.231582198","rc":[{"batb":[[0,2.44,10]],"ltp":2.5,"tv":41.52,"id":31376}]}]}
{"op":"mcm","clk":"11856857037","pt":1723363521464,"mc":[{"id":"1.231582198","rc":[{"batb":[[0,2.42,22.68],[1,2.34,29.13],[2,1.3,1000]],"ltp":2.5,"tv":41.52,"id":31376}]}]}
{"op":"mcm","clk":"11856857150","pt":1723363522958,"mc":[{"id":"1.231582198","rc":[{"batb":[[0,2.44,4],[1,2.42,22.68],[2,2.34,29.13]],"ltp":2.5,"tv":41.52,"id":31376}]}]}
{"op":"mcm","clk":"11856857239","pt":1723363524248,"mc":[{"id":"1.231582198","rc":[{"batb":[[0,2.46,10],[1,2.44,4],[2,2.42,22.68]],"ltp":2.5,"tv":41.52,"id":31376}]}]}
{"op":"mcm","clk":"11856857343","pt":1723363525448,"mc":[{"id":"1.231582198","rc":[{"batb":[[1,2.42,22.68],[2,2.34,29.13]],"ltp":2.5,"tv":41.52,"id":31376}]}]}
{"op":"mcm","clk":"11856857564","pt":1723363528458,"mc":[{"id":"1.231582198","rc":[{"batb":[[2,1.61,45.94]],"batl":[[1,1.7,10.58]],"ltp":1.67,"tv":1128.67,"id":2780},{"batb":[[0,2.48,4],[2,1.3,1000]],"ltp":2.5,"tv":41.52,"id":31376}]}]}
{"op":"mcm","clk":"11856857580","pt":1723363528665,"mc":[{"id":"1.231582198","rc":[{"batl":[[0,1.68,4.58],[1,1.69,1.82],[2,1.7,10.58]],"ltp":1.67,"tv":1128.67,"id":2780}]}]}
{"op":"mcm","clk":"11856857673","pt":1723363530268,"mc":[{"id":"1.231582198","rc":[{"batb":[[0,2.42,22.68],[1,1.3,1000],[2,1.08,7.85]],"ltp":2.5,"tv":41.52,"id":31376}]}]}
{"op":"mcm","clk":"11856857725","pt":1723363530846,"mc":[{"id":"1.231582198","rc":[{"batl":[[0,1.69,6.38],[1,1.7,10.58],[2,1.72,1.82]],"ltp":1.67,"tv":1128.67,"id":2780},{"batb":[[0,2.44,10],[1,2.42,22.68],[2,1.3,1000]],"ltp":2.5,"tv":41.52,"id":31376}]}]}
{"op":"mcm","clk":"11856857870","pt":1723363532958,"mc":[{"id":"1.231582198","rc":[{"batb":[[2,1.65,60.06]],"ltp":1.67,"tv":1128.67,"id":2780},{"batb":[[0,2.46,4],[1,2.44,10],[2,2.42,22.68]],"ltp":2.5,"tv":41.52,"id":31376}]}]}
{"op":"mcm","clk":"11856857978","pt":1723363534371,"mc":[{"id":"1.231582198","rc":[{"batb":[[1,2.42,22.68],[2,2.34,29.13]],"ltp":2.5,"tv":41.52,"id":31376}]}]}
{"op":"mcm","clk":"11856858070","pt":1723363535358,"mc":[{"id":"1.231582198","rc":[{"batb":[[2,1.65,87.77]],"ltp":1.67,"tv":1128.67,"id":2780},{"batb":[[0,2.42,22.68],[1,2.34,29.13],[2,1.3,1000]],"ltp":2.5,"tv":41.52,"id":31376}]}]}
{"op":"mcm","clk":"11856858150","pt":1723363536445,"mc":[{"id":"1.231582198","rc":[{"batl":[[0,1.69,1.82],[1,1.7,15.11]],"ltp":1.67,"tv":1128.67,"id":2780}]}]}
{"op":"mcm","clk":"11856858155","pt":1723363536546,"mc":[{"id":"1.231582198","rc":[{"batb":[[0,2.44,10],[1,2.42,22.68],[2,2.34,29.13]],"ltp":2.5,"tv":41.52,"id":31376}]}]}
{"op":"mcm","clk":"11856858252","pt":1723363537784,"mc":[{"id":"1.231582198","rc":[{"batb":[[0,2.46,4],[1,2.44,10],[2,2.42,22.68]],"ltp":2.5,"tv":41.52,"id":31376}]}]}
{"op":"mcm","clk":"11856858429","pt":1723363540469,"mc":[{"id":"1.231582198","rc":[{"batb":[[0,2.42,22.68],[1,2.34,29.13],[2,1.3,1000]],"ltp":2.5,"tv":41.52,"id":31376}]}]}
{"op":"mcm","clk":"11856858642","pt":1723363543577,"mc":[{"id":"1.231582198","rc":[{"batb":[[0,2.44,14],[1,2.42,22.68],[2,2.34,29.13]],"ltp":2.5,"tv":41.52,"id":31376}]}]}
{"op":"mcm","clk":"11856858812","pt":1723363545998,"mc":[{"id":"1.231582198","rc":[{"batb":[[0,2.44,10]],"ltp":2.5,"tv":41.52,"id":31376}]}]}
{"op":"mcm","clk":"11856858905","pt":1723363547186,"mc":[{"id":"1.231582198","rc":[{"batb":[[0,2.42,22.68],[1,2.34,29.13],[2,1.3,1000]],"ltp":2.5,"tv":41.52,"id":31376}]}]}
{"op":"mcm","clk":"11856858987","pt":1723363548471,"mc":[{"id":"1.231582198","rc":[{"batb":[[0,2.44,4],[1,2.42,22.68],[2,2.34,29.13]],"ltp":2.5,"tv":41.52,"id":31376}]}]}
{"op":"mcm","clk":"11856859085","pt":1723363549673,"mc":[{"id":"1.231582198","rc":[{"batb":[[0,2.46,10],[1,2.44,4],[2,2.42,22.68]],"ltp":2.5,"tv":41.52,"id":31376}]}]}
{"op":"mcm","clk":"11856859186","pt":1723363550893,"mc":[{"id":"1.231582198","rc":[{"batb":[[1,2.42,22.68],[2,2.34,29.13]],"ltp":2.5,"tv":41.52,"id":31376}]}]}
{"op":"mcm","clk":"11856859429","pt":1723363553485,"mc":[{"id":"1.231582198","rc":[{"batb":[[2,1.61,45.94]],"ltp":1.67,"tv":1128.67,"id":2780},{"batb":[[0,2.48,4],[2,1.3,1000]],"ltp":2.5,"tv":41.52,"id":31376}]}]}
{"op":"mcm","clk":"11856859569","pt":1723363555589,"mc":[{"id":"1.231582198","rc":[{"batb":[[0,2.42,22.68],[1,1.3,1000],[2,1.08,7.85]],"ltp":2.5,"tv":41.52,"id":31376}]}]}
{"op":"mcm","clk":"11856859647","pt":1723363556571,"mc":[{"id":"1.231582198","rc":[{"batb":[[0,2.44,10],[1,2.42,22.68],[2,1.3,1000]],"ltp":2.5,"tv":41.52,"id":31376}]}]}
{"op":"mcm","clk":"11856859734","pt":1723363557905,"mc":[{"id":"1.231582198","rc":[{"batb":[[2,1.65,60.06]],"ltp":1.67,"tv":1128.67,"id":2780},{"batb":[[0,2.46,4],[1,2.44,10],[2,2.42,22.68]],"ltp":2.5,"tv":41.52,"id":31376}]}]}
{"op":"mcm","clk":"11856859913","pt":1723363560485,"mc":[{"id":"1.231582198","rc":[{"batb":[[2,1.65,87.77]],"ltp":1.67,"tv":1128.67,"id":2780},{"batb":[[0,2.42,22.68],[1,2.34,29.13],[2,1.3,1000]],"ltp":2.5,"tv":41.52,"id":31376}]}]}
{"op":"mcm","clk":"11856860075","pt":1723363562908,"mc":[{"id":"1.231582198","rc":[{"batb":[[0,2.44,14],[1,2.42,22.68],[2,2.34,29.13]],"ltp":2.5,"tv":41.52,"id":31376}]}]}
{"op":"mcm","clk":"11856860244","pt":1723363565131,"mc":[{"id":"1.231582198","rc":[{"batb":[[0,2.44,10]],"ltp":2.5,"tv":41.52,"id":31376}]}]}
{"op":"mcm","clk":"11856860309","pt":1723363566214,"mc":[{"id":"1.231582198","rc":[{"batb":[[0,2.42,22.68],[1,2.34,29.13],[2,1.3,1000]],"ltp":2.5,"tv":41.52,"id":31376}]}]}
{"op":"mcm","clk":"11856860794","pt":1723363573228,"mc":[{"id":"1.231582198","rc":[{"batb":[[0,2.44,14],[1,2.42,22.68],[2,2.34,29.13]],"ltp":2.5,"tv":41.52,"id":31376}]}]}
{"op":"mcm","clk":"11856860983","pt":1723363575806,"mc":[{"id":"1.231582198","rc":[{"batb":[[0,2.44,10]],"ltp":2.5,"tv":41.52,"id":31376}]}]}
{"op":"mcm","clk":"11856861030","pt":1723363576730,"mc":[{"id":"1.231582198","rc":[{"batb":[[0,2.42,22.68],[1,2.34,29.13],[2,1.3,1000]],"ltp":2.5,"tv":41.52,"id":31376}]}]}
{"op":"mcm","clk":"11856861194","pt":1723363579214,"mc":[{"id":"1.231582198","rc":[{"batb":[[0,2.44,14],[1,2.42,22.68],[2,2.34,29.13]],"ltp":2.5,"tv":41.52,"id":31376}]}]}
{"op":"mcm","clk":"11856861372","pt":1723363581522,"mc":[{"id":"1.231582198","rc":[{"batb":[[0,2.44,10]],"ltp":2.5,"tv":41.52,"id":31376}]}]}
{"op":"mcm","clk":"11856861431","pt":1723363582503,"mc":[{"id":"1.231582198","rc":[{"batb":[[0,2.42,22.68],[1,2.34,29.13],[2,1.3,1000]],"ltp":2.5,"tv":41.52,"id":31376}]}]}
{"op":"mcm","clk":"11856861511","pt":1723363583733,"mc":[{"id":"1.231582198","rc":[{"batb":[[0,2.44,4],[1,2.42,22.68],[2,2.34,29.13]],"ltp":2.5,"tv":41.52,"id":31376}]}]}
{"op":"mcm","clk":"11856861591","pt":1723363585019,"mc":[{"id":"1.231582198","rc":[{"batb":[[0,2.46,10],[1,2.44,4],[2,2.42,22.68]],"ltp":2.5,"tv":41.52,"id":31376}]}]}
{"op":"mcm","clk":"11856861680","pt":1723363586404,"mc":[{"id":"1.231582198","rc":[{"batb":[[1,2.42,22.68],[2,2.34,29.13]],"ltp":2.5,"tv":41.52,"id":31376}]}]}
{"op":"mcm","clk":"11856861820","pt":1723363588514,"mc":[{"id":"1.231582198","rc":[{"batb":[[2,1.61,45.94]],"ltp":1.67,"tv":1128.67,"id":2780},{"batb":[[0,2.42,22.68],[1,1.3,1000],[2,1.08,7.85]],"ltp":2.5,"tv":41.52,"id":31376}]}]}
{"op":"mcm","clk":"11856861845","pt":1723363588817,"mc":[{"id":"1.231582198","rc":[{"batb":[[0,2.48,4],[1,2.42,22.68],[2,1.3,1000]],"ltp":2.5,"tv":41.52,"id":31376}]}]}
{"op":"mcm","clk":"11856862036","pt":1723363591445,"mc":[{"id":"1.231582198","rc":[{"batb":[[0,2.44,10]],"ltp":2.5,"tv":41.52,"id":31376}]}]}
{"op":"mcm","clk":"11856862173","pt":1723363593038,"mc":[{"id":"1.231582198","rc":[{"batb":[[2,1.65,60.06]],"ltp":1.67,"tv":1128.67,"id":2780},{"batb":[[2,2.34,29.13]],"ltp":2.5,"tv":41.52,"id":31376}]}]}
{"op":"mcm","clk":"11856862311","pt":1723363594839,"mc":[{"id":"1.231582198","rc":[{"batb":[[2,1.65,87.77]],"ltp":1.67,"tv":1128.67,"id":2780},{"batb":[[0,2.46,4]],"ltp":2.5,"tv":41.52,"id":31376}]}]}
{"op":"mcm","clk":"11856862473","pt":1723363597161,"mc":[{"id":"1.231582198","rc":[{"batb":[[0,2.44,10]],"ltp":2.5,"tv":41.52,"id":31376}]}]}
{"op":"mcm","clk":"11856862675","pt":1723363600347,"mc":[{"id":"1.231582198","rc":[{"batb":[[0,2.46,4]],"ltp":2.5,"tv":41.52,"id":31376}]}]}
{"op":"mcm","clk":"11856862830","pt":1723363602654,"mc":[{"id":"1.231582198","rc":[{"batb":[[0,2.42,22.68],[1,2.34,29.13],[2,1.3,1000]],"ltp":2.5,"tv":41.52,"id":31376}]}]}
{"op":"mcm","clk":"11856862884","pt":1723363603633,"mc":[{"id":"1.231582198","rc":[{"batb":[[0,2.48,10],[1,2.42,22.68],[2,2.34,29.13]],"ltp":2.5,"tv":41.52,"id":31376}]}]}
{"op":"mcm","clk":"11856863171","pt":1723363607454,"mc":[{"id":"1.231582198","rc":[{"batb":[[0,2.44,4]],"ltp":2.5,"tv":41.52,"id":31376}]}]}
{"op":"mcm","clk":"11856863353","pt":1723363609867,"mc":[{"id":"1.231582198","rc":[{"batb":[[0,2.46,10]],"ltp":2.5,"tv":41.52,"id":31376}]}]}
{"op":"mcm","clk":"11856863602","pt":1723363613462,"mc":[{"id":"1.231582198","rc":[{"batb":[[2,1.61,45.94]],"ltp":1.67,"tv":1128.67,"id":2780},{"batb":[[0,2.48,4],[2,1.3,1000]],"ltp":2.5,"tv":41.52,"id":31376}]}]}
{"op":"mcm","clk":"11856863780","pt":1723363616343,"mc":[{"id":"1.231582198","rc":[{"trd":[[1.67,18.28]],"batb":[[0,1.66,15.64],[1,1.61,16.42],[2,1.56,16.42]],"ltp":1.67,"tv":1133.23,"id":2780},{"trd":[[2.5,5.59]],"batb":[[0,2.5,6.95]],"ltp":2.5,"tv":44.57,"id":31376}],"tv":1177.8}]}
{"op":"mcm","clk":"11856863812","pt":1723363616859,"mc":[{"id":"1.231582198","rc":[{"batb":[[2,1.56,48.58]],"ltp":1.67,"tv":1133.23,"id":2780}]}]}
{"op":"mcm","clk":"11856864000","pt":1723363619477,"mc":[{"id":"1.231582198","rc":[{"batb":[[0,2.44,4]],"ltp":2.5,"tv":44.57,"id":31376}]}]}
{"op":"mcm","clk":"11856864186","pt":1723363622067,"mc":[{"id":"1.231582198","rc":[{"batb":[[0,2.46,10]],"ltp":2.5,"tv":44.57,"id":31376}]}]}
{"op":"mcm","clk":"11856864461","pt":1723363625477,"mc":[{"id":"1.231582198","rc":[{"batb":[[0,2.48,4]],"ltp":2.5,"tv":44.57,"id":31376}]}]}
{"op":"mcm","clk":"11856864625","pt":1723363627891,"mc":[{"id":"1.231582198","rc":[{"batb":[[0,2.5,10]],"ltp":2.5,"tv":44.57,"id":31376}]}]}
{"op":"mcm","clk":"11856864844","pt":1723363631397,"mc":[{"id":"1.231582198","rc":[{"batb":[[0,2.44,4]],"ltp":2.5,"tv":44.57,"id":31376}]}]}
{"op":"mcm","clk":"11856864990","pt":1723363633200,"mc":[{"id":"1.231582198","rc":[{"batb":[[1,1.65,60.06],[2,1.61,16.42]],"ltp":1.67,"tv":1133.23,"id":2780},{"batb":[[2,2.34,29.13]],"ltp":2.5,"tv":44.57,"id":31376}]}]}
{"op":"mcm","clk":"11856865067","pt":1723363634183,"mc":[{"id":"1.231582198","rc":[{"batb":[[0,2.44,10]],"ltp":2.5,"tv":44.57,"id":31376}]}]}
{"op":"mcm","clk":"11856865113","pt":1723363634900,"mc":[{"id":"1.231582198","rc":[{"batb":[[1,1.65,87.77]],"ltp":1.67,"tv":1133.23,"id":2780}]}]}
{"op":"mcm","clk":"11856865269","pt":1723363637185,"mc":[{"id":"1.231582198","rc":[{"batb":[[0,2.46,4],[1,2.44,10],[2,2.42,22.68]],"ltp":2.5,"tv":44.57,"id":31376}]}]}
{"op":"mcm","clk":"11856865296","pt":1723363637595,"mc":[{"id":"1.231582198","rc":[{"batb":[[1,2.42,22.68],[2,2.34,29.13]],"ltp":2.5,"tv":44.57,"id":31376}]}]}
{"op":"mcm","clk":"11856865412","pt":1723363639517,"mc":[{"id":"1.231582198","rc":[{"batb":[[0,2.42,22.68],[1,2.34,29.13],[2,1.3,1000]],"ltp":2.5,"tv":44.57,"id":31376}]}]}
{"op":"mcm","clk":"11856865440","pt":1723363639783,"mc":[{"id":"1.231582198","rc":[{"batb":[[0,2.48,10],[1,2.42,22.68],[2,2.34,29.13]],"ltp":2.5,"tv":44.57,"id":31376}]}]}
{"op":"mcm","clk":"11856865741","pt":1723363643500,"mc":[{"id":"1.231582198","rc":[{"batb":[[1,1.65,27.71]],"batl":[[0,1.67,4.61],[1,1.69,1.82],[2,1.7,10.58]],"ltp":1.67,"tv":1133.23,"id":2780},{"batb":[[0,2.5,4],[2,1.3,1000]],"ltp":2.5,"tv":44.57,"id":31376}]}]}
{"op":"mcm","clk":"11856865785","pt":1723363644013,"mc":[{"id":"1.231582198","rc":[{"batb":[[1,1.61,16.42],[2,1.56,48.58]],"ltp":1.67,"tv":1133.23,"id":2780}]}]}
{"op":"mcm","clk":"11856865903","pt":1723363645511,"mc":[{"id":"1.231582198","rc":[{"batb":[[0,2.42,22.68],[1,1.3,1000],[2,1.08,7.85]],"ltp":2.5,"tv":44.57,"id":31376}]}]}
{"op":"mcm","clk":"11856865941","pt":1723363645976,"mc":[{"id":"1.231582198","rc":[{"batl":[[0,1.69,6.38],[1,1.7,10.58],[2,1.72,1.82]],"ltp":1.67,"tv":1133.23,"id":2780},{"batb":[[0,2.44,10],[1,2.42,22.68],[2,1.3,1000]],"ltp":2.5,"tv":44.57,"id":31376}]}]}
{"op":"mcm","clk":"11856866115","pt":1723363648500,"mc":[{"id":"1.231582198","rc":[{"batb":[[1,1.65,60.06],[2,1.61,16.42]],"ltp":1.67,"tv":1133.23,"id":2780},{"batb":[[0,2.46,4],[1,2.44,10],[2,2.42,22.68]],"ltp":2.5,"tv":44.57,"id":31376}]}]}
{"op":"mcm","clk":"11856866160","pt":1723363649014,"mc":[{"id":"1.231582198","rc":[{"batb":[[1,2.42,22.68],[2,2.34,29.13]],"ltp":2.5,"tv":44.57,"id":31376}]}]}
{"op":"mcm","clk":"11856866318","pt":1723363650924,"mc":[{"id":"1.231582198","rc":[{"batb":[[1,1.65,87.77]],"ltp":1.67,"tv":1133.23,"id":2780},{"batb":[[0,2.42,22.68],[1,2.34,29.13],[2,1.3,1000]],"ltp":2.5,"tv":44.57,"id":31376}]}]}
{"op":"mcm","clk":"11856866398","pt":1723363651904,"mc":[{"id":"1.231582198","rc":[{"batl":[[0,1.69,1.82],[1,1.7,15.11]],"ltp":1.67,"tv":1133.23,"id":2780},{"batb":[[0,2.44,10],[1,2.42,22.68],[2,2.34,29.13]],"ltp":2.5,"tv":44.57,"id":31376}]}]}
{"op":"mcm","clk":"11856866543","pt":1723363653612,"mc":[{"id":"1.231582198","rc":[{"batb":[[0,2.46,4],[1,2.44,10],[2,2.42,22.68]],"ltp":2.5,"tv":44.57,"id":31376}]}]}
{"op":"mcm","clk":"11856866673","pt":1723363655326,"mc":[{"id":"1.231582198","rc":[{"batb":[[1,2.42,22.68],[2,2.34,29.13]],"ltp":2.5,"tv":44.57,"id":31376}]}]}
{"op":"mcm","clk":"11856866733","pt":1723363655996,"mc":[{"id":"1.231582198","rc":[{"batb":[[0,2.42,22.68],[1,2.34,29.13],[2,1.3,1000]],"ltp":2.5,"tv":44.57,"id":31376}]}]}
{"op":"mcm","clk":"11856866940","pt":1723363658625,"mc":[{"id":"1.231582198","rc":[{"batb":[[0,2.44,14],[1,2.42,22.68],[2,2.34,29.13]],"ltp":2.5,"tv":44.57,"id":31376}]}]}
{"op":"mcm","clk":"11856867149","pt":1723363661208,"mc":[{"id":"1.231582198","rc":[{"batb":[[0,2.44,10]],"ltp":2.5,"tv":44.57,"id":31376}]}]}
{"op":"mcm","clk":"11856867213","pt":1723363662236,"mc":[{"id":"1.231582198","rc":[{"batb":[[0,2.42,22.68],[1,2.34,29.13],[2,1.3,1000]],"ltp":2.5,"tv":44.57,"id":31376}]}]}
{"op":"mcm","clk":"11856867302","pt":1723363663421,"mc":[{"id":"1.231582198","rc":[{"batb":[[0,2.44,4],[1,2.42,22.68],[2,2.34,29.13]],"ltp":2.5,"tv":44.57,"id":31376}]}]}
{"op":"mcm","clk":"11856867410","pt":1723363664825,"mc":[{"id":"1.231582198","rc":[{"batb":[[0,2.46,10],[1,2.44,4],[2,2.42,22.68]],"ltp":2.5,"tv":44.57,"id":31376}]}]}
{"op":"mcm","clk":"11856867479","pt":1723363665647,"mc":[{"id":"1.231582198","rc":[{"batb":[[1,2.42,22.68],[2,2.34,29.13]],"ltp":2.5,"tv":44.57,"id":31376}]}]}
{"op":"mcm","clk":"11856867676","pt":1723363668436,"mc":[{"id":"1.231582198","rc":[{"batb":[[1,1.65,27.71]],"ltp":1.67,"tv":1133.23,"id":2780},{"batb":[[2,1.3,1000]],"ltp":2.5,"tv":44.57,"id":31376}]}]}
{"op":"mcm","clk":"11856867716","pt":1723363669050,"mc":[{"id":"1.231582198","rc":[{"batb":[[1,1.61,16.42],[2,1.56,48.58]],"ltp":1.67,"tv":1133.23,"id":2780},{"batb":[[0,2.48,4]],"ltp":2.5,"tv":44.57,"id":31376}]}]}
{"op":"mcm","clk":"11856867866","pt":1723363671016,"mc":[{"id":"1.231582198","rc":[{"batb":[[0,2.44,10]],"ltp":2.5,"tv":44.57,"id":31376}]}]}
{"op":"mcm","clk":"11856868046","pt":1723363673433,"mc":[{"id":"1.231582198","rc":[{"batb":[[1,1.65,60.06],[2,1.61,16.42]],"ltp":1.67,"tv":1133.23,"id":2780},{"batb":[[2,2.34,29.13]],"ltp":2.5,"tv":44.57,"id":31376}]}]}
{"op":"mcm","clk":"11856868121","pt":1723363674416,"mc":[{"id":"1.231582198","rc":[{"batb":[[0,2.46,4]],"ltp":2.5,"tv":44.57,"id":31376}]}]}
{"op":"mcm","clk":"11856868272","pt":1723363675917,"mc":[{"id":"1.231582198","rc":[{"batb":[[1,1.65,87.77]],"ltp":1.67,"tv":1133.23,"id":2780},{"batb":[[0,2.42,22.68],[1,2.34,29.13],[2,1.3,1000]],"ltp":2.5,"tv":44.57,"id":31376}]}]}
{"op":"mcm","clk":"11856868327","pt":1723363676638,"mc":[{"id":"1.231582198","rc":[{"batb":[[0,2.44,10],[1,2.42,22.68],[2,2.34,29.13]],"ltp":2.5,"tv":44.57,"id":31376}]}]}
{"op":"mcm","clk":"11856868590","pt":1723363680056,"mc":[{"id":"1.231582198","rc":[{"batb":[[0,2.46,4]],"ltp":2.5,"tv":44.57,"id":31376}]}]}
{"op":"mcm","clk":"11856868796","pt":1723363682337,"mc":[{"id":"1.231582198","rc":[{"batb":[[0,2.42,22.68],[1,2.34,29.13],[2,1.3,1000]],"ltp":2.5,"tv":44.57,"id":31376}]}]}
{"op":"mcm","clk":"11856868819","pt":1723363682546,"mc":[{"id":"1.231582198","rc":[{"batb":[[0,2.44,10],[1,2.42,22.68],[2,2.34,29.13]],"ltp":2.5,"tv":44.57,"id":31376}]}]}
{"op":"mcm","clk":"11856869072","pt":1723363684947,"mc":[{"id":"1.231582198","rc":[{"batb":[[0,2.46,4],[1,2.44,10],[2,2.42,22.68]],"ltp":2.5,"tv":44.57,"id":31376}]}]}
{"op":"mcm","clk":"11856869145","pt":1723363685826,"mc":[{"id":"1.231582198","rc":[{"batb":[[1,2.42,22.68],[2,2.34,29.13]],"ltp":2.5,"tv":44.57,"id":31376}]}]}
{"op":"mcm","clk":"11856869269","pt":1723363687370,"mc":[{"id":"1.231582198","rc":[{"batb":[[0,2.42,22.68],[1,2.34,29.13],[2,1.3,1000]],"ltp":2.5,"tv":44.57,"id":31376}]}]}
{"op":"mcm","clk":"11856869439","pt":1723363689343,"mc":[{"id":"1.231582198","rc":[{"batb":[[0,2.44,10],[1,2.42,22.68],[2,2.34,29.13]],"ltp":2.5,"tv":44.57,"id":31376}]}]}
{"op":"mcm","clk":"11856869524","pt":1723363690474,"mc":[{"id":"1.231582198","rc":[{"batb":[[0,2.46,4],[1,2.44,10],[2,2.42,22.68]],"ltp":2.5,"tv":44.57,"id":31376}]}]}
{"op":"mcm","clk":"11856869798","pt":1723363693463,"mc":[{"id":"1.231582198","rc":[{"batb":[[0,2.44,12.5],[1,2.42,22.68],[2,2.34,29.13]],"ltp":2.5,"tv":44.57,"id":31376}]}]}
{"op":"mcm","clk":"11856869809","pt":1723363693567,"mc":[{"id":"1.231582198","rc":[{"batb":[[0,2.42,22.68],[1,2.34,29.13],[2,1.3,1000]],"ltp":2.5,"tv":44.57,"id":31376}]}]}
{"op":"mcm","clk":"11856869955","pt":1723363695675,"mc":[{"id":"1.231582198","rc":[{"batb":[[0,2.46,10],[1,2.44,4],[2,2.42,22.68]],"ltp":2.5,"tv":44.57,"id":31376}]}]}
{"op":"mcm","clk":"11856870189","pt":1723363698476,"mc":[{"id":"1.231582198","rc":[{"trd":[[1.69,120.8]],"batl":[[0,1.7,15.11],[1,1.72,1.82],[2,1.74,26.27]],"ltp":1.69,"tv":1137.55,"id":2780},{"trd":[[2.46,0.47]],"batb":[[0,2.46,9.53],[1,2.42,22.68],[2,2.34,29.13]],"ltp":2.46,"tv":45.04,"id":31376}],"tv":1182.59}]}
{"op":"mcm","clk":"11856870249","pt":1723363699149,"mc":[{"id":"1.231582198","rc":[{"batb":[[1,1.61,16.42],[2,1.56,48.58]],"ltp":1.69,"tv":1137.55,"id":2780},{"batb":[[0,2.42,22.68],[1,1.3,1000],[2,1.08,7.85]],"ltp":2.46,"tv":45.04,"id":31376}]}]}
{"op":"mcm","clk":"11856870326","pt":1723363700074,"mc":[{"id":"1.231582198","rc":[{"batb":[[0,2.44,4],[1,2.42,10],[2,2.4,12.86]],"ltp":2.46,"tv":45.04,"id":31376}]}]}
{"op":"mcm","clk":"11856870409","pt":1723363700955,"mc":[{"id":"1.231582198","rc":[{"batb":[[1,2.42,22.68]],"ltp":2.46,"tv":45.04,"id":31376}]}]}
{"op":"mcm","clk":"11856870523","pt":1723363702449,"mc":[{"id":"1.231582198","rc":[{"batb":[[0,2.46,10]],"ltp":2.46,"tv":45.04,"id":31376}]}]}
{"op":"mcm","clk":"11856870769","pt":1723363705486,"mc":[{"id":"1.231582198","rc":[{"batb":[[0,2.44,4]],"ltp":2.46,"tv":45.04,"id":31376}]}]}
{"op":"mcm","clk":"11856871038","pt":1723363708188,"mc":[{"id":"1.231582198","rc":[{"batb":[[0,2.44,10]],"ltp":2.46,"tv":45.04,"id":31376}]}]}
{"op":"mcm","clk":"11856871080","pt":1723363708594,"mc":[{"id":"1.231582198","rc":[{"batb":[[1,1.65,60.06],[2,1.61,16.42]],"ltp":1.69,"tv":1137.55,"id":2780}]}]}
{"op":"mcm","clk":"11856871296","pt":1723363711082,"mc":[{"id":"1.231582198","rc":[{"batb":[[1,1.65,87.77]],"ltp":1.69,"tv":1137.55,"id":2780},{"batb":[[0,2.46,4],[1,2.44,10],[2,2.42,22.68]],"ltp":2.46,"tv":45.04,"id":31376}]}]}
{"op":"mcm","clk":"11856871340","pt":1723363711593,"mc":[{"id":"1.231582198","rc":[{"batb":[[1,2.42,22.68],[2,2.4,12.86]],"ltp":2.46,"tv":45.04,"id":31376}]}]}
{"op":"mcm","clk":"11856871495","pt":1723363713400,"mc":[{"id":"1.231582198","rc":[{"batb":[[0,2.42,22.68],[1,2.4,12.86],[2,2.34,29.13]],"ltp":2.46,"tv":45.04,"id":31376}]}]}
{"op":"mcm","clk":"11856871596","pt":1723363714588,"mc":[{"id":"1.231582198","rc":[{"batb":[[0,2.44,10],[1,2.42,22.68],[2,2.4,12.86]],"ltp":2.46,"tv":45.04,"id":31376}]}]}
{"op":"mcm","clk":"11856871895","pt":1723363718098,"mc":[{"id":"1.231582198","rc":[{"batb":[[0,2.44,4]],"ltp":2.46,"tv":45.04,"id":31376}]}]}
{"op":"mcm","clk":"11856872091","pt":1723363720508,"mc":[{"id":"1.231582198","rc":[{"batb":[[0,2.42,22.68],[1,2.4,12.86],[2,2.34,29.13]],"ltp":2.46,"tv":45.04,"id":31376}]}]}
{"op":"mcm","clk":"11856872137","pt":1723363720976,"mc":[{"id":"1.231582198","rc":[{"batb":[[0,2.44,10],[1,2.42,22.68],[2,2.4,12.86]],"ltp":2.46,"tv":45.04,"id":31376}]}]}
{"op":"mcm","clk":"11856872453","pt":1723363724494,"mc":[{"id":"1.231582198","rc":[{"batb":[[0,2.42,22.68],[1,2.4,12.86],[2,2.34,29.13]],"ltp":2.46,"tv":45.04,"id":31376}]}]}
{"op":"mcm","clk":"11856872464","pt":1723363724599,"mc":[{"id":"1.231582198","rc":[{"batb":[[0,2.44,4],[1,2.42,22.68],[2,2.4,12.86]],"ltp":2.46,"tv":45.04,"id":31376}]}]}
{"op":"mcm","clk":"11856872704","pt":1723363727223,"mc":[{"id":"1.231582198","rc":[{"batb":[[0,2.44,10]],"ltp":2.46,"tv":45.04,"id":31376}]}]}
{"op":"mcm","clk":"11856872959","pt":1723363730417,"mc":[{"id":"1.231582198","rc":[{"batb":[[0,2.46,4]],"ltp":2.46,"tv":45.04,"id":31376}]}]}
{"op":"mcm","clk":"11856873113","pt":1723363732322,"mc":[{"id":"1.231582198","rc":[{"batb":[[0,2.42,22.68],[1,2.4,12.86],[2,2.34,29.13]],"ltp":2.46,"tv":45.04,"id":31376}]}]}
{"op":"mcm","clk":"11856873220","pt":1723363733413,"mc":[{"id":"1.231582198","rc":[{"batb":[[0,2.44,10],[1,2.42,22.68],[2,2.4,12.86]],"ltp":2.46,"tv":45.04,"id":31376}]}]}
{"op":"mcm","clk":"11856873304","pt":1723363734596,"mc":[{"id":"1.231582198","rc":[{"batb":[[0,2.46,4],[1,2.44,10],[2,2.42,22.68]],"ltp":2.46,"tv":45.04,"id":31376}]}]}
{"op":"mcm","clk":"11856873516","pt":1723363736797,"mc":[{"id":"1.231582198","rc":[{"batb":[[0,2.42,22.68],[1,2.4,12.86],[2,2.34,29.13]],"ltp":2.46,"tv":45.04,"id":31376}]}]}
{"op":"mcm","clk":"11856873738","pt":1723363739522,"mc":[{"id":"1.231582198","rc":[{"batb":[[0,2.44,14],[1,2.42,22.68],[2,2.4,12.86]],"ltp":2.46,"tv":45.04,"id":31376}]}]}
{"op":"mcm","clk":"11856873835","pt":1723363740705,"mc":[{"id":"1.231582198","rc":[{"trd":[[1.65,8.72],[1.66,50.3]],"batb":[[0,1.65,83.41],[1,1.61,16.42],[2,1.56,48.58]],"ltp":1.65,"tv":1177.55,"id":2780}],"tv":1222.59}]}
{"op":"mcm","clk":"11856873936","pt":1723363741997,"mc":[{"id":"1.231582198","rc":[{"batb":[[0,2.44,10]],"ltp":2.46,"tv":45.04,"id":31376}]}]}
{"op":"mcm","clk":"11856874023","pt":1723363743028,"mc":[{"id":"1.231582198","rc":[{"batb":[[0,2.42,22.68],[1,2.4,12.86],[2,2.34,29.13]],"ltp":2.46,"tv":45.04,"id":31376}]}]}
{"op":"mcm","clk":"11856874100","pt":1723363743815,"mc":[{"id":"1.231582198","rc":[{"batb":[[0,1.65,87.77]],"ltp":1.65,"tv":1177.55,"id":2780}]}]}
{"op":"mcm","clk":"11856874253","pt":1723363745435,"mc":[{"id":"1.231582198","rc":[{"batb":[[0,2.46,10],[1,2.44,4],[2,2.42,22.68]],"ltp":2.46,"tv":45.04,"id":31376}]}]}
{"op":"mcm","clk":"11856874411","pt":1723363747430,"mc":[{"id":"1.231582198","rc":[{"batb":[[1,2.42,22.68],[2,2.4,12.86]],"ltp":2.46,"tv":45.04,"id":31376}]}]}
{"op":"mcm","clk":"11856874520","pt":1723363748826,"mc":[{"id":"1.231582198","rc":[{"batb":[[0,2.42,22.68],[1,2.4,12.86],[2,2.34,29.13]],"ltp":2.46,"tv":45.04,"id":31376}]}]}
{"op":"mcm","clk":"11856874695","pt":1723363751144,"mc":[{"id":"1.231582198","rc":[{"batb":[[0,2.46,10],[1,2.44,4],[2,2.42,22.68]],"ltp":2.46,"tv":45.04,"id":31376}]}]}
{"op":"mcm","clk":"11856874871","pt":1723363753415,"mc":[{"id":"1.231582198","rc":[{"batb":[[1,2.42,22.68],[2,2.4,12.86]],"ltp":2.46,"tv":45.04,"id":31376}]}]}
{"op":"mcm","clk":"11856874977","pt":1723363754650,"mc":[{"id":"1.231582198","rc":[{"batb":[[0,2.42,22.68],[1,2.4,12.86],[2,2.34,29.13]],"ltp":2.46,"tv":45.04,"id":31376}]}]}
{"op":"mcm","clk":"11856875067","pt":1723363755937,"mc":[{"id":"1.231582198","rc":[{"batb":[[0,2.44,4],[1,2.42,22.68],[2,2.4,12.86]],"ltp":2.46,"tv":45.04,"id":31376}]}]}
{"op":"mcm","clk":"11856875161","pt":1723363757125,"mc":[{"id":"1.231582198","rc":[{"batb":[[0,2.46,10],[1,2.44,4],[2,2.42,22.68]],"ltp":2.46,"tv":45.04,"id":31376}]}]}
{"op":"mcm","clk":"11856875239","pt":1723363758252,"mc":[{"id":"1.231582198","rc":[{"batb":[[1,2.42,22.68],[2,2.4,12.86]],"ltp":2.46,"tv":45.04,"id":31376}]}]}
{"op":"mcm","clk":"11856875398","pt":1723363760418,"mc":[{"id":"1.231582198","rc":[{"batb":[[0,2.42,22.68],[1,2.4,12.86],[2,2.34,29.13]],"ltp":2.46,"tv":45.04,"id":31376}]}]}
{"op":"mcm","clk":"11856875415","pt":1723363760627,"mc":[{"id":"1.231582198","rc":[{"batb":[[0,2.48,4],[1,2.42,22.68],[2,2.4,12.86]],"ltp":2.46,"tv":45.04,"id":31376}]}]}
{"op":"mcm","clk":"11856875607","pt":1723363763050,"mc":[{"id":"1.231582198","rc":[{"batb":[[0,1.65,60.06],[1,1.64,28.14],[2,1.61,16.42]],"ltp":1.65,"tv":1177.55,"id":2780},{"batb":[[0,2.5,10]],"ltp":2.46,"tv":45.04,"id":31376}]}]}
{"op":"mcm","clk":"11856875703","pt":1723363764142,"mc":[{"id":"1.231582198","rc":[{"batb":[[0,1.61,202.19],[1,1.56,48.58],[2,1.39,8.76]],"ltp":1.65,"tv":1177.55,"id":2780}]}]}
{"op":"mcm","clk":"11856875803","pt":1723363765338,"mc":[{"id":"1.231582198","rc":[{"batb":[[0,2.52,4],[1,2.5,10],[2,2.42,22.68]],"ltp":2.46,"tv":45.04,"id":31376}]}]}
{"op":"mcm","clk":"11856875872","pt":1723363766156,"mc":[{"id":"1.231582198","rc":[{"batb":[[1,1.6,30.02],[2,1.56,48.58]],"ltp":1.65,"tv":1177.55,"id":2780},{"batb":[[1,2.42,22.68],[2,2.4,12.86]],"ltp":2.46,"tv":45.04,"id":31376}]}]}
{"op":"mcm","clk":"11856876023","pt":1723363768337,"mc":[{"id":"1.231582198","rc":[{"batb":[[0,1.61,16.42]],"ltp":1.65,"tv":1177.55,"id":2780},{"batb":[[0,2.44,10]],"ltp":2.46,"tv":45.04,"id":31376}]}]}
{"op":"mcm","clk":"11856876064","pt":1723363768947,"mc":[{"id":"1.231582198","rc":[{"batb":[[0,1.65,60.06],[1,1.61,16.42]],"ltp":1.65,"tv":1177.55,"id":2780}]}]}
{"op":"mcm","clk":"11856876225","pt":1723363770948,"mc":[{"id":"1.231582198","rc":[{"batb":[[1,1.64,28.14],[2,1.61,16.42]],"ltp":1.65,"tv":1177.55,"id":2780},{"batb":[[0,2.46,4],[1,2.44,10],[2,2.42,22.68]],"ltp":2.46,"tv":45.04,"id":31376}]}]}
{"op":"mcm","clk":"11856876275","pt":1723363771629,"mc":[{"id":"1.231582198","rc":[{"batb":[[1,2.42,22.68],[2,2.4,12.86]],"ltp":2.46,"tv":45.04,"id":31376}]}]}
{"op":"mcm","clk":"11856876386","pt":1723363773117,"mc":[{"id":"1.231582198","rc":[{"batb":[[0,2.42,22.68],[1,2.4,12.86],[2,2.34,29.13]],"ltp":2.46,"tv":45.04,"id":31376}]}]}
{"op":"mcm","clk":"11856876577","pt":1723363775551,"mc":[{"id":"1.231582198","rc":[{"batb":[[0,2.44,14],[1,2.42,22.68],[2,2.4,12.86]],"ltp":2.46,"tv":45.04,"id":31376}]}]}
{"op":"mcm","clk":"11856876760","pt":1723363777942,"mc":[{"id":"1.231582198","rc":[{"batb":[[0,2.44,10]],"ltp":2.46,"tv":45.04,"id":31376}]}]}
{"op":"mcm","clk":"11856876839","pt":1723363779026,"mc":[{"id":"1.231582198","rc":[{"batb":[[0,2.42,22.68],[1,2.4,12.86],[2,2.34,29.13]],"ltp":2.46,"tv":45.04,"id":31376}]}]}
{"op":"mcm","clk":"11856876941","pt":1723363780671,"mc":[{"id":"1.231582198","rc":[{"batb":[[0,2.44,4],[1,2.42,22.68],[2,2.4,12.86]],"ltp":2.46,"tv":45.04,"id":31376}]}]}
{"op":"mcm","clk":"11856877034","pt":1723363781859,"mc":[{"id":"1.231582198","rc":[{"batb":[[0,2.46,10],[1,2.44,4],[2,2.42,22.68]],"ltp":2.46,"tv":45.04,"id":31376}]}]}
{"op":"mcm","clk":"11856877120","pt":1723363782951,"mc":[{"id":"1.231582198","rc":[{"batb":[[1,2.42,22.68],[2,2.4,12.86]],"ltp":2.46,"tv":45.04,"id":31376}]}]}
{"op":"mcm","clk":"11856877316","pt":1723363785270,"mc":[{"id":"1.231582198","rc":[{"batb":[[0,2.48,4]],"ltp":2.46,"tv":45.04,"id":31376}]}]}
{"op":"mcm","clk":"11856877481","pt":1723363787429,"mc":[{"id":"1.231582198","rc":[{"batb":[[0,2.42,22.68],[1,2.4,12.86],[2,2.34,29.13]],"ltp":2.46,"tv":45.04,"id":31376}]}]}
{"op":"mcm","clk":"11856877488","pt":1723363787535,"mc":[{"id":"1.231582198","rc":[{"batb":[[0,2.5,10],[1,2.42,22.68],[2,2.4,12.86]],"ltp":2.46,"tv":45.04,"id":31376}]}]}
{"op":"mcm","clk":"11856877610","pt":1723363789135,"mc":[{"id":"1.231582198","rc":[{"batb":[[0,1.64,28.14],[1,1.61,16.42],[2,1.56,48.58]],"ltp":1.65,"tv":1177.55,"id":2780}]}]}
{"op":"mcm","clk":"11856877723","pt":1723363790369,"mc":[{"id":"1.231582198","rc":[{"batb":[[0,1.61,16.42],[1,1.56,48.58],[2,1.39,8.76]],"batl":[[0,1.66,4.64],[1,1.7,10.58],[2,1.72,1.82]],"ltp":1.65,"tv":1177.55,"id":2780},{"batb":[[0,2.52,4],[1,2.5,10],[2,2.42,22.68]],"ltp":2.46,"tv":45.04,"id":31376}]}]}
{"op":"mcm","clk":"11856877770","pt":1723363790838,"mc":[{"id":"1.231582198","rc":[{"batb":[[1,2.42,22.68],[2,2.4,12.86]],"ltp":2.46,"tv":45.04,"id":31376}]}]}
{"op":"mcm","clk":"11856877883","pt":1723363791865,"mc":[{"id":"1.231582198","rc":[{"batb":[[0,2.42,22.68],[1,2.4,12.86],[2,1.3,1000]],"ltp":2.46,"tv":45.04,"id":31376}]}]}
{"op":"mcm","clk":"11856878003","pt":1723363793264,"mc":[{"id":"1.231582198","rc":[{"batl":[[0,1.7,15.11],[1,1.72,1.82],[2,1.74,26.27]],"ltp":1.65,"tv":1177.55,"id":2780},{"batb":[[0,2.44,10],[1,2.42,22.68],[2,2.4,12.86]],"ltp":2.46,"tv":45.04,"id":31376}]}]}
{"op":"mcm","clk":"11856878080","pt":1723363794240,"mc":[{"id":"1.231582198","rc":[{"batb":[[0,1.65,60.06],[1,1.61,16.42],[2,1.56,48.58]],"ltp":1.65,"tv":1177.55,"id":2780},{"batb":[[0,2.46,4],[1,2.44,10],[2,2.42,22.68]],"ltp":2.46,"tv":45.04,"id":31376}]}]}
{"op":"mcm","clk":"11856878214","pt":1723363795941,"mc":[{"id":"1.231582198","rc":[{"batb":[[1,1.64,28.14],[2,1.61,16.42]],"ltp":1.65,"tv":1177.55,"id":2780}]}]}
{"op":"mcm","clk":"11856878256","pt":1723363796558,"mc":[{"id":"1.231582198","rc":[{"batb":[[0,2.42,22.68],[1,2.4,12.86],[2,2.34,29.13]],"ltp":2.46,"tv":45.04,"id":31376}]}]}
{"op":"mcm","clk":"11856878415","pt":1723363798671,"mc":[{"id":"1.231582198","rc":[{"batb":[[0,2.44,14],[1,2.42,22.68],[2,2.4,12.86]],"ltp":2.46,"tv":45.04,"id":31376}]}]}
{"op":"mcm","clk":"11856878622","pt":1723363801173,"mc":[{"id":"1.231582198","rc":[{"batb":[[0,2.44,10]],"ltp":2.46,"tv":45.04,"id":31376}]}]}
{"op":"mcm","clk":"11856878718","pt":1723363802151,"mc":[{"id":"1.231582198","rc":[{"batb":[[0,2.42,22.68],[1,2.4,12.86],[2,2.34,29.13]],"ltp":2.46,"tv":45.04,"id":31376}]}]}
{"op":"mcm","clk":"11856878848","pt":1723363803501,"mc":[{"id":"1.231582198","rc":[{"batb":[[0,2.44,4],[1,2.42,22.68],[2,2.4,12.86]],"ltp":2.46,"tv":45.04,"id":31376}]}]}
{"op":"mcm","clk":"11856878958","pt":1723363804656,"mc":[{"id":"1.231582198","rc":[{"batb":[[0,2.46,10],[1,2.44,4],[2,2.42,22.68]],"ltp":2.46,"tv":45.04,"id":31376}]}]}
{"op":"mcm","clk":"11856879051","pt":1723363805851,"mc":[{"id":"1.231582198","rc":[{"batb":[[1,2.42,22.68],[2,2.4,12.86]],"ltp":2.46,"tv":45.04,"id":31376}]}]}
{"op":"mcm","clk":"11856879214","pt":1723363807972,"mc":[{"id":"1.231582198","rc":[{"batb":[[0,2.42,22.68],[1,2.4,12.86],[2,2.34,29.13]],"ltp":2.46,"tv":45.04,"id":31376}]}]}
{"op":"mcm","clk":"11856879314","pt":1723363809057,"mc":[{"id":"1.231582198","rc":[{"batb":[[0,2.44,4],[1,2.42,22.68],[2,2.4,12.86]],"ltp":2.46,"tv":45.04,"id":31376}]}]}
{"op":"mcm","clk":"11856879475","pt":1723363810802,"mc":[{"id":"1.231582198","rc":[{"batb":[[0,2.46,10],[1,2.44,4],[2,2.42,22.68]],"ltp":2.46,"tv":45.04,"id":31376}]}]}
{"op":"mcm","clk":"11856879583","pt":1723363811793,"mc":[{"id":"1.231582198","rc":[{"batb":[[1,2.42,22.68],[2,2.4,12.86]],"ltp":2.46,"tv":45.04,"id":31376}]}]}
{"op":"mcm","clk":"11856879804","pt":1723363814363,"mc":[{"id":"1.231582198","rc":[{"batb":[[0,2.44,4]],"ltp":2.46,"tv":45.04,"id":31376}]}]}
{"op":"mcm","clk":"11856879987","pt":1723363816990,"mc":[{"id":"1.231582198","rc":[{"batb":[[0,2.46,10]],"ltp":2.46,"tv":45.04,"id":31376}]}]}
{"op":"mcm","clk":"11856880169","pt":1723363819416,"mc":[{"id":"1.231582198","rc":[{"batb":[[0,2.48,4],[1,2.46,10],[2,2.42,22.68]],"ltp":2.46,"tv":45.04,"id":31376}]}]}
{"op":"mcm","clk":"11856880226","pt":1723363820195,"mc":[{"id":"1.231582198","rc":[{"batb":[[1,2.42,22.68],[2,2.4,12.86]],"ltp":2.46,"tv":45.04,"id":31376}]}]}
{"op":"mcm","clk":"11856880370","pt":1723363821889,"mc":[{"id":"1.231582198","rc":[{"batb":[[0,2.42,22.68],[1,2.4,12.86],[2,2.34,29.13]],"ltp":2.46,"tv":45.04,"id":31376}]}]}
{"op":"mcm","clk":"11856880435","pt":1723363822599,"mc":[{"id":"1.231582198","rc":[{"batb":[[0,2.44,10],[1,2.42,22.68],[2,2.4,12.86]],"ltp":2.46,"tv":45.04,"id":31376}]}]}
{"op":"mcm","clk":"11856880560","pt":1723363824198,"mc":[{"id":"1.231582198","rc":[{"batb":[[0,2.46,4],[1,2.44,10],[2,2.42,22.68]],"ltp":2.46,"tv":45.04,"id":31376}]}]}
{"op":"mcm","clk":"11856880786","pt":1723363826522,"mc":[{"id":"1.231582198","rc":[{"batb":[[0,2.42,22.68],[1,2.4,12.86],[2,2.34,29.13]],"ltp":2.46,"tv":45.04,"id":31376}]}]}
{"op":"mcm","clk":"11856881030","pt":1723363829518,"mc":[{"id":"1.231582198","rc":[{"batb":[[0,2.44,14],[1,2.42,22.68],[2,2.4,12.86]],"ltp":2.46,"tv":45.04,"id":31376}]}]}
{"op":"mcm","clk":"11856881215","pt":1723363831799,"mc":[{"id":"1.231582198","rc":[{"batb":[[0,2.44,10]],"ltp":2.46,"tv":45.04,"id":31376}]}]}
{"op":"mcm","clk":"11856881294","pt":1723363832836,"mc":[{"id":"1.231582198","rc":[{"batb":[[0,2.42,22.68],[1,2.4,12.86],[2,2.34,29.13]],"ltp":2.46,"tv":45.04,"id":31376}]}]}
{"op":"mcm","clk":"11856881435","pt":1723363834637,"mc":[{"id":"1.231582198","rc":[{"batb":[[0,2.44,4],[1,2.42,22.68],[2,2.4,12.86]],"ltp":2.46,"tv":45.04,"id":31376}]}]}
{"op":"mcm","clk":"11856881642","pt":1723363836801,"mc":[{"id":"1.231582198","rc":[{"batb":[[0,2.46,10]],"ltp":2.46,"tv":45.04,"id":31376}]}]}
{"op":"mcm","clk":"11856881922","pt":1723363840149,"mc":[{"id":"1.231582198","rc":[{"batb":[[0,2.44,4]],"ltp":2.46,"tv":45.04,"id":31376}]}]}
{"op":"mcm","clk":"11856882137","pt":1723363842320,"mc":[{"id":"1.231582198","rc":[{"batb":[[0,2.42,22.68],[1,2.4,12.86],[2,2.34,29.13]],"ltp":2.46,"tv":45.04,"id":31376}]}]}
{"op":"mcm","clk":"11856882171","pt":1723363842829,"mc":[{"id":"1.231582198","rc":[{"batb":[[0,2.44,10],[1,2.42,22.68],[2,2.4,12.86]],"ltp":2.46,"tv":45.04,"id":31376}]}]}
{"op":"mcm","clk":"11856882493","pt":1723363846437,"mc":[{"id":"1.231582198","rc":[{"batb":[[0,2.44,4]],"ltp":2.46,"tv":45.04,"id":31376}]}]}
{"op":"mcm","clk":"11856882677","pt":1723363848865,"mc":[{"id":"1.231582198","rc":[{"batb":[[0,2.44,10]],"ltp":2.46,"tv":45.04,"id":31376}]}]}
{"op":"mcm","clk":"11856882944","pt":1723363852136,"mc":[{"id":"1.231582198","rc":[{"batb":[[0,2.42,22.68],[1,2.4,12.86],[2,2.34,29.13]],"ltp":2.46,"tv":45.04,"id":31376}]}]}
{"op":"mcm","clk":"11856882989","pt":1723363852653,"mc":[{"id":"1.231582198","rc":[{"batb":[[0,2.44,4],[1,2.42,22.68],[2,2.4,12.86]],"ltp":2.46,"tv":45.04,"id":31376}]}]}
{"op":"mcm","clk":"11856883199","pt":1723363855428,"mc":[{"id":"1.231582198","rc":[{"batb":[[0,2.44,10]],"ltp":2.46,"tv":45.04,"id":31376}]}]}
{"op":"mcm","clk":"11856883425","pt":1723363858328,"mc":[{"id":"1.231582198","rc":[{"batb":[[0,2.46,4],[1,2.44,10],[2,2.42,22.68]],"ltp":2.46,"tv":45.04,"id":31376}]}]}
{"op":"mcm","clk":"11856883486","pt":1723363859047,"mc":[{"id":"1.231582198","rc":[{"batb":[[1,2.42,22.68],[2,2.4,12.86]],"ltp":2.46,"tv":45.04,"id":31376}]}]}
{"op":"mcm","clk":"11856883607","pt":1723363860649,"mc":[{"id":"1.231582198","rc":[{"batb":[[0,2.42,22.68],[1,2.4,12.86],[2,2.34,29.13]],"ltp":2.46,"tv":45.04,"id":31376}]}]}
{"op":"mcm","clk":"11856883711","pt":1723363862044,"mc":[{"id":"1.231582198","rc":[{"batb":[[0,2.44,10],[1,2.42,22.68],[2,2.4,12.86]],"ltp":2.46,"tv":45.04,"id":31376}]}]}
{"op":"mcm","clk":"11856883957","pt":1723363865474,"mc":[{"id":"1.231582198","rc":[{"batb":[[0,2.42,22.68],[1,2.4,12.86],[2,2.34,29.13]],"ltp":2.46,"tv":45.04,"id":31376}]}]}
{"op":"mcm","clk":"11856883967","pt":1723363865530,"mc":[{"id":"1.231582198","rc":[{"batb":[[0,2.46,4],[1,2.42,22.68],[2,2.4,12.86]],"ltp":2.46,"tv":45.04,"id":31376}]}]}
{"op":"mcm","clk":"11856884190","pt":1723363868059,"mc":[{"id":"1.231582198","rc":[{"batb":[[0,2.48,10]],"ltp":2.46,"tv":45.04,"id":31376}]}]}
{"op":"mcm","clk":"11856884368","pt":1723363870344,"mc":[{"id":"1.231582198","rc":[{"batb":[[0,2.5,4],[1,2.48,10],[2,2.42,22.68]],"ltp":2.46,"tv":45.04,"id":31376}]}]}
{"op":"mcm","clk":"11856884456","pt":1723363871381,"mc":[{"id":"1.231582198","rc":[{"batb":[[1,2.42,22.68],[2,2.4,12.86]],"ltp":2.46,"tv":45.04,"id":31376}]}]}
{"op":"mcm","clk":"11856884568","pt":1723363872675,"mc":[{"id":"1.231582198","rc":[{"batb":[[0,2.42,22.68],[1,2.4,12.86],[2,2.34,29.13]],"ltp":2.46,"tv":45.04,"id":31376}]}]}
{"op":"mcm","clk":"11856884762","pt":1723363875048,"mc":[{"id":"1.231582198","rc":[{"batb":[[0,2.46,4],[1,2.44,10],[2,2.42,22.68]],"ltp":2.46,"tv":45.04,"id":31376}]}]}
{"op":"mcm","clk":"11856884934","pt":1723363877361,"mc":[{"id":"1.231582198","rc":[{"batb":[[0,2.44,10],[1,2.42,22.68],[2,2.4,12.86]],"ltp":2.46,"tv":45.04,"id":31376}]}]}
{"op":"mcm","clk":"11856884987","pt":1723363878147,"mc":[{"id":"1.231582198","rc":[{"batb":[[0,2.42,22.68],[1,2.4,12.86],[2,2.34,29.13]],"ltp":2.46,"tv":45.04,"id":31376}]}]}
{"op":"mcm","clk":"11856885233","pt":1723363881078,"mc":[{"id":"1.231582198","rc":[{"batb":[[0,2.44,14],[1,2.42,22.68],[2,2.4,12.86]],"ltp":2.46,"tv":45.04,"id":31376}]}]}
{"op":"mcm","clk":"11856885527","pt":1723363884277,"mc":[{"id":"1.231582198","rc":[{"batb":[[0,2.42,22.68],[1,2.4,12.86],[2,2.34,29.13]],"ltp":2.46,"tv":45.04,"id":31376}]}]}
{"op":"mcm","clk":"11856885727","pt":1723363887156,"mc":[{"id":"1.231582198","rc":[{"batb":[[0,2.44,14],[1,2.42,22.68],[2,2.4,12.86]],"ltp":2.46,"tv":45.04,"id":31376}]}]}
{"op":"mcm","clk":"11856885881","pt":1723363889373,"mc":[{"id":"1.231582198","rc":[{"batb":[[0,2.44,10]],"ltp":2.46,"tv":45.04,"id":31376}]}]}
{"op":"mcm","clk":"11856885999","pt":1723363890970,"mc":[{"id":"1.231582198","rc":[{"batb":[[0,2.42,22.68],[1,2.4,12.86],[2,2.34,29.13]],"ltp":2.46,"tv":45.04,"id":31376}]}]}
{"op":"mcm","clk":"11856886134","pt":1723363892678,"mc":[{"id":"1.231582198","rc":[{"batb":[[0,2.44,4],[1,2.42,22.68],[2,2.4,12.86]],"ltp":2.46,"tv":45.04,"id":31376}]}]}
{"op":"mcm","clk":"11856886278","pt":1723363894175,"mc":[{"id":"1.231582198","rc":[{"batb":[[0,2.46,10],[1,2.44,4],[2,2.42,22.68]],"ltp":2.46,"tv":45.04,"id":31376}]}]}
{"op":"mcm","clk":"11856886336","pt":1723363894989,"mc":[{"id":"1.231582198","rc":[{"batb":[[1,2.42,22.68],[2,2.4,12.86]],"ltp":2.46,"tv":45.04,"id":31376}]}]}
{"op":"mcm","clk":"11856886524","pt":1723363897476,"mc":[{"id":"1.231582198","rc":[{"batb":[[0,2.48,4],[1,2.46,10],[2,2.42,22.68]],"ltp":2.46,"tv":45.04,"id":31376}]}]}
{"op":"mcm","clk":"11856886561","pt":1723363897996,"mc":[{"id":"1.231582198","rc":[{"batb":[[1,2.42,22.68],[2,2.4,12.86]],"ltp":2.46,"tv":45.04,"id":31376}]}]}
{"op":"mcm","clk":"11856886755","pt":1723363900016,"mc":[{"id":"1.231582198","rc":[{"batb":[[0,2.42,22.68],[1,2.4,12.86],[2,2.34,29.13]],"ltp":2.46,"tv":45.04,"id":31376}]}]}
{"op":"mcm","clk":"11856886997","pt":1723363902394,"mc":[{"id":"1.231582198","rc":[{"batb":[[0,2.44,14],[1,2.42,22.68],[2,2.4,12.86]],"ltp":2.46,"tv":45.04,"id":31376}]}]}
