{"op":"mcm","clk":"11771672352","pt":1722677185163,"mc":[{"id":"1.231397068","marketDefinition":{"bspMarket":false,"turnInPlayEnabled":true,"persistenceEnabled":true,"marketBaseRate":5.0,"eventId":"33462721","eventTypeId":"4","numberOfWinners":1,"bettingType":"ODDS","marketType":"MATCH_ODDS","marketTime":"2024-08-04T13:30:00.000Z","suspendTime":"2024-08-04T13:30:00.000Z","bspReconciled":false,"complete":true,"inPlay":false,"crossMatching":true,"runnersVoidable":false,"numberOfActiveRunners":2,"betDelay":0,"status":"OPEN","runners":[{"status":"ACTIVE","sortPriority":1,"id":40380900,"name":"Northern Superchargers W"},{"status":"ACTIVE","sortPriority":2,"id":40296818,"name":"Manchester Originals W"}],"regulators":["MR_INT"],"countryCode":"GB","discountAllowed":false,"timezone":"GMT","openDate":"2024-08-04T13:30:00.000Z","version":6052890623,"name":"Match Odds","eventName":"Northern Superchargers W v Manchester Originals W"},"rc":[{"batb":[[0,1.03,200],[1,1.02,200],[2,1.01,220]],"ltp":0.0,"tv":0.0,"id":40380900},{"batb":[[0,1.03,200],[1,1.02,200],[2,1.01,220]],"ltp":0.0,"tv":0.0,"id":40296818}]}]}
{"op":"mcm","clk":"11771672511","pt":1722677186635,"mc":[{"id":"1.231397068","marketDefinition":{"bspMarket":false,"turnInPlayEnabled":true,"persistenceEnabled":true,"marketBaseRate":5.0,"eventId":"33462721","eventTypeId":"4","numberOfWinners":1,"bettingType":"ODDS","marketType":"MATCH_ODDS","marketTime":"2024-08-04T13:30:00.000Z","suspendTime":"2024-08-04T13:30:00.000Z","bspReconciled":false,"complete":true,"inPlay":false,"crossMatching":true,"runnersVoidable":false,"numberOfActiveRunners":2,"betDelay":0,"status":"OPEN","runners":[{"status":"ACTIVE","sortPriority":1,"id":40380900,"name":"Northern Superchargers W"},{"status":"ACTIVE","sortPriority":2,"id":40296818,"name":"Manchester Originals W"}],"regulators":["MR_INT"],"countryCode":"GB","discountAllowed":true,"timezone":"GMT","openDate":"2024-08-04T13:30:00.000Z","version":6052890623,"name":"Match Odds","eventName":"Northern Superchargers W v Manchester Originals W"}}]}
{"op":"mcm","clk":"11772039193","pt":1722680930947,"mc":[{"id":"1.231397068","rc":[{"batb":[[0,1.17,78.73],[1,1.03,200],[2,1.02,200]],"ltp":0.0,"tv":0.0,"id":40380900}]}]}
{"op":"mcm","clk":"11772053734","pt":1722681076028,"mc":[{"id":"1.231397068","rc":[{"batb":[[2,1.01,478.41]],"ltp":0.0,"tv":0.0,"id":40296818}]}]}
{"op":"mcm","clk":"11772156326","pt":1722681966093,"mc":[{"id":"1.231397068","rc":[{"batb":[[0,1.25,100],[1,1.17,78.73],[2,1.03,200]],"ltp":0.0,"tv":0.0,"id":40380900}]}]}
{"op":"mcm","clk":"11772156554","pt":1722681968086,"mc":[{"id":"1.231397068","rc":[{"batb":[[0,1.25,100],[1,1.03,200],[2,1.02,200]],"ltp":0.0,"tv":0.0,"id":40296818}]}]}
{"op":"mcm","clk":"11772316735","pt":1722683440908,"mc":[{"id":"1.231397068","rc":[{"batl":[[0,4,0.78]],"ltp":0.0,"tv":0.0,"id":40380900},{"batl":[[0,4,0.78]],"ltp":0.0,"tv":0.0,"id":40296818}]}]}
{"op":"mcm","clk":"11772317716","pt":1722683448009,"mc":[{"id":"1.231397068","rc":[{"batl":[[0,5,1.56]],"ltp":0.0,"tv":0.0,"id":40380900},{"batl":[[0,5,1.56]],"ltp":0.0,"tv":0.0,"id":40296818}]}]}
{"op":"mcm","clk":"11772318630","pt":1722683455206,"mc":[{"id":"1.231397068","rc":[{"batl":[[1,6,0.78]],"ltp":0.0,"tv":0.0,"id":40380900},{"batl":[[1,6,0.78]],"ltp":0.0,"tv":0.0,"id":40296818}]}]}
{"op":"mcm","clk":"11772321489","pt":1722683475462,"mc":[{"id":"1.231397068","rc":[{"batb":[[2,1.02,200.78]],"ltp":0.0,"tv":0.0,"id":40296818}]}]}
{"op":"mcm","clk":"11772322912","pt":1722683486458,"mc":[{"id":"1.231397068","rc":[{"batb":[[2,1.03,200.78]],"ltp":0.0,"tv":0.0,"id":40380900},{"batb":[[1,1.03,200.78]],"ltp":0.0,"tv":0.0,"id":40296818}]}]}
{"op":"mcm","clk":"11772324646","pt":1722683499149,"mc":[{"id":"1.231397068","rc":[{"batb":[[2,1.03,201.56]],"ltp":0.0,"tv":0.0,"id":40380900},{"batb":[[1,1.03,201.56]],"ltp":0.0,"tv":0.0,"id":40296818}]}]}
{"op":"mcm","clk":"11772376871","pt":1722683864941,"mc":[{"id":"1.231397068","rc":[{"batb":[[0,1.25,100.91]],"ltp":0.0,"tv":0.0,"id":40380900}]}]}
{"op":"mcm","clk":"11772378386","pt":1722683874957,"mc":[{"id":"1.231397068","rc":[{"batb":[[0,1.25,100.91]],"ltp":0.0,"tv":0.0,"id":40296818}]}]}
{"op":"mcm","clk":"11772440007","pt":1722684315638,"mc":[{"id":"1.231397068","rc":[{"batb":[[0,1.26,7.11],[1,1.25,100],[2,1.17,78.73]],"ltp":0.0,"tv":0.0,"id":40380900}]}]}
{"op":"mcm","clk":"11772586878","pt":1722685471748,"mc":[{"id":"1.231397068","rc":[{"batb":[[2,1.02,296.83]],"ltp":0.0,"tv":0.0,"id":40296818}]}]}
{"op":"mcm","clk":"11772927124","pt":1722687882066,"mc":[{"id":"1.231397068","rc":[{"batb":[[2,1.03,201.56]],"ltp":0.0,"tv":0.0,"id":40380900}]}]}
{"op":"mcm","clk":"11773180742","pt":1722689557161,"mc":[{"id":"1.231397068","rc":[{"batb":[[0,1.25,100.91],[1,1.03,201.56],[2,1.02,296.83]],"ltp":0.0,"tv":0.0,"id":40380900}]}]}
{"op":"mcm","clk":"11775116722","pt":1722701214000,"mc":[{"id":"1.231397068","rc":[{"batb":[[0,1.7,10],[1,1.25,100.91],[2,1.03,201.56]],"ltp":0.0,"tv":0.0,"id":40380900},{"batb":[[0,1.7,10],[1,1.25,100.91],[2,1.03,201.56]],"ltp":0.0,"tv":0.0,"id":40296818}]}]}
{"op":"mcm","clk":"11775301261","pt":1722702176964,"mc":[{"id":"1.231397068","rc":[{"batb":[[1,1.25,100]],"ltp":0.0,"tv":0.0,"id":40380900}]}]}
{"op":"mcm","clk":"11775301975","pt":1722702181055,"mc":[{"id":"1.231397068","rc":[{"batb":[[1,1.25,100]],"ltp":0.0,"tv":0.0,"id":40296818}]}]}
{"op":"mcm","clk":"11775692026","pt":1722704582025,"mc":[{"id":"1.231397068","rc":[{"batb":[[0,1.8,29],[1,1.7,10],[2,1.25,100]],"ltp":0.0,"tv":0.0,"id":40380900}]}]}
{"op":"mcm","clk":"11775693068","pt":1722704589557,"mc":[{"id":"1.231397068","rc":[{"batl":[[0,2,23.2],[1,5,1.56],[2,6,0.78]],"ltp":0.0,"tv":0.0,"id":40380900}]}]}
{"op":"mcm","clk":"11776356252","pt":1722708726932,"mc":[{"id":"1.231397068","rc":[{"batb":[[0,1.81,607.7],[1,1.8,29],[2,1.7,10]],"ltp":0.0,"tv":0.0,"id":40380900}]}]}
{"op":"mcm","clk":"11776572016","pt":1722709860931,"mc":[{"id":"1.231397068","rc":[{"batb":[[2,1.74,17.32]],"ltp":0.0,"tv":0.0,"id":40380900},{"batb":[[0,1.74,17.32],[1,1.7,10],[2,1.25,100]],"ltp":0.0,"tv":0.0,"id":40296818}]}]}
{"op":"mcm","clk":"11776614450","pt":1722710114655,"mc":[{"id":"1.231397068","rc":[{"batb":[[0,1.82,16.67],[1,1.81,607.7],[2,1.8,29]],"ltp":0.0,"tv":0.0,"id":40380900},{"batl":[[0,2.22,16.67],[1,5,1.56],[2,6,0.78]],"ltp":0.0,"tv":0.0,"id":40296818}]}]}
{"op":"mcm","clk":"11776728579","pt":1722710736915,"mc":[{"id":"1.231397068","rc":[{"batl":[[0,2.2,3],[1,2.22,16.67],[2,5,1.56]],"ltp":0.0,"tv":0.0,"id":40296818}]}]}
{"op":"mcm","clk":"11777241101","pt":1722714260801,"mc":[{"id":"1.231397068","rc":[{"batb":[[1,1.8,29],[2,1.74,17.32]],"ltp":0.0,"tv":0.0,"id":40380900}]}]}
{"op":"mcm","clk":"11777241304","pt":1722714262798,"mc":[{"id":"1.231397068","rc":[{"batb":[[0,1.8,29],[1,1.74,17.32],[2,1.7,10]],"ltp":0.0,"tv":0.0,"id":40380900},{"batl":[[1,5,1.56],[2,6,0.78]],"ltp":0.0,"tv":0.0,"id":40296818}]}]}
{"op":"mcm","clk":"11777262765","pt":1722714475852,"mc":[{"id":"1.231397068","rc":[{"trd":[[2,23.2]],"batl":[[0,5,1.56],[1,6,0.78],[2,6,0]],"ltp":2.0,"tv":23.2,"id":40380900},{"trd":[[2,23.2]],"batl":[[0,1.99,36.8],[1,2.2,3],[2,5,1.56]],"ltp":2.0,"tv":23.2,"id":40296818}],"tv":46.4}]}
{"op":"mcm","clk":"11777263454","pt":1722714482450,"mc":[{"id":"1.231397068","rc":[{"batl":[[0,2.2,3],[1,5,1.56],[2,6,0.78]],"ltp":2.0,"tv":23.2,"id":40296818}]}]}
{"op":"mcm","clk":"11777313127","pt":1722715013594,"mc":[{"id":"1.231397068","rc":[{"batb":[[0,1.74,17.32],[1,1.7,10],[2,1.25,100]],"ltp":2.0,"tv":23.2,"id":40380900}]}]}
{"op":"mcm","clk":"11777313833","pt":1722715024286,"mc":[{"id":"1.231397068","rc":[{"batb":[[0,1.83,56],[1,1.74,17.32],[2,1.7,10]],"ltp":2.0,"tv":23.2,"id":40380900}]}]}
{"op":"mcm","clk":"11777314401","pt":1722715032794,"mc":[{"id":"1.231397068","rc":[{"batb":[[0,1.82,333],[1,1.74,17.32],[2,1.7,10]],"ltp":2.0,"tv":23.2,"id":40296818}]}]}
{"op":"mcm","clk":"11777372210","pt":1722715757056,"mc":[{"id":"1.231397068","rc":[{"batl":[[0,2.2,13.41],[1,5,1.56],[2,6,0.78]],"ltp":2.0,"tv":23.2,"id":40380900},{"batb":[[0,1.83,16.35],[1,1.82,333],[2,1.74,17.32]],"ltp":2.0,"tv":23.2,"id":40296818}]}]}
{"op":"mcm","clk":"11777431709","pt":1722716508083,"mc":[{"id":"1.231397068","rc":[{"batb":[[0,1.83,22.95]],"ltp":2.0,"tv":23.2,"id":40296818}]}]}
{"op":"mcm","clk":"11777441330","pt":1722716649277,"mc":[{"id":"1.231397068","rc":[{"batl":[[1,2.5,2],[2,5,1.56]],"ltp":2.0,"tv":23.2,"id":40380900}]}]}
{"op":"mcm","clk":"11777442091","pt":1722716660322,"mc":[{"id":"1.231397068","rc":[{"batl":[[1,2.5,2],[2,5,1.56]],"ltp":2.0,"tv":23.2,"id":40296818}]}]}
{"op":"mcm","clk":"11777656930","pt":1722719810016,"mc":[{"id":"1.231397068","rc":[{"batl":[[0,2.2,8]],"ltp":2.0,"tv":23.2,"id":40296818}]}]}
{"op":"mcm","clk":"11777983686","pt":1722725896330,"mc":[{"id":"1.231397068","rc":[{"trd":[[2.2,13.41]],"batl":[[0,2.5,2],[1,5,1.56],[2,6,0.78]],"ltp":2.2,"tv":36.6,"id":40380900},{"trd":[[1.83,62.02]],"batb":[[0,1.82,333],[1,1.74,17.32],[2,1.7,10]],"batl":[[0,1.83,62.63],[1,2.2,8],[2,2.5,2]],"ltp":1.83,"tv":85.22,"id":40296818}],"tv":121.82}]}
{"op":"mcm","clk":"11777983745","pt":1722725897051,"mc":[{"id":"1.231397068","rc":[{"batb":[[0,2.2,13.41],[1,1.84,10],[2,1.83,56]],"ltp":2.2,"tv":36.6,"id":40380900},{"trd":[[1.83,182.5]],"batl":[[0,1.83,18.74]],"ltp":1.83,"tv":205.7,"id":40296818}],"tv":242.3}]}
{"op":"mcm","clk":"11777983882","pt":1722725898858,"mc":[{"id":"1.231397068","rc":[{"batb":[[0,1.84,10],[1,1.83,56],[2,1.74,17.32]],"ltp":2.2,"tv":36.6,"id":40380900},{"trd":[[1.83,219.98]],"batb":[[0,1.83,26.02],[1,1.82,333],[2,1.74,17.32]],"batl":[[0,2.2,8],[1,2.5,2],[2,5,1.56]],"ltp":1.83,"tv":243.18,"id":40296818}],"tv":279.78}]}
{"op":"mcm","clk":"11777983947","pt":1722725899737,"mc":[{"id":"1.231397068","rc":[{"batb":[[0,1.83,56],[1,1.74,17.32],[2,1.7,10]],"ltp":2.2,"tv":36.6,"id":40380900}]}]}
{"op":"mcm","clk":"11777984139","pt":1722725902064,"mc":[{"id":"1.231397068","rc":[{"batb":[[0,1.84,10],[1,1.83,56],[2,1.74,17.32]],"ltp":2.2,"tv":36.6,"id":40380900},{"batb":[[0,1.83,16.2]],"ltp":1.83,"tv":243.18,"id":40296818}]}]}
{"op":"mcm","clk":"11777984407","pt":1722725905369,"mc":[{"id":"1.231397068","rc":[{"batb":[[0,1.83,56],[1,1.74,17.32],[2,1.7,10]],"ltp":2.2,"tv":36.6,"id":40380900}]}]}
{"op":"mcm","clk":"11777984421","pt":1722725905573,"mc":[{"id":"1.231397068","rc":[{"batb":[[0,1.84,10],[1,1.83,16.2],[2,1.82,333]],"ltp":1.83,"tv":243.18,"id":40296818}]}]}
{"op":"mcm","clk":"11777984696","pt":1722725908870,"mc":[{"id":"1.231397068","rc":[{"batb":[[0,1.84,10],[1,1.83,56],[2,1.74,17.32]],"ltp":2.2,"tv":36.6,"id":40380900},{"batb":[[0,1.83,16.2],[1,1.82,333],[2,1.74,17.32]],"ltp":1.83,"tv":243.18,"id":40296818}]}]}
{"op":"mcm","clk":"11777984978","pt":1722725912190,"mc":[{"id":"1.231397068","rc":[{"batb":[[0,1.83,56],[1,1.74,17.32],[2,1.7,10]],"ltp":2.2,"tv":36.6,"id":40380900},{"batb":[[0,1.84,10],[1,1.83,16.2],[2,1.82,333]],"ltp":1.83,"tv":243.18,"id":40296818}]}]}
{"op":"mcm","clk":"11777985243","pt":1722725915751,"mc":[{"id":"1.231397068","rc":[{"batb":[[0,1.84,10],[1,1.83,56],[2,1.74,17.32]],"ltp":2.2,"tv":36.6,"id":40380900},{"batb":[[0,1.83,16.2],[1,1.82,333],[2,1.74,17.32]],"ltp":1.83,"tv":243.18,"id":40296818}]}]}
{"op":"mcm","clk":"11777985508","pt":1722725919150,"mc":[{"id":"1.231397068","rc":[{"batb":[[0,1.83,56],[1,1.74,17.32],[2,1.7,10]],"ltp":2.2,"tv":36.6,"id":40380900}]}]}
{"op":"mcm","clk":"11777985530","pt":1722725919460,"mc":[{"id":"1.231397068","rc":[{"batb":[[0,1.84,10],[1,1.83,16.2],[2,1.82,333]],"ltp":1.83,"tv":243.18,"id":40296818}]}]}
{"op":"mcm","clk":"11777985789","pt":1722725923067,"mc":[{"id":"1.231397068","rc":[{"batb":[[0,1.84,26.02],[1,1.83,56],[2,1.74,17.32]],"ltp":2.2,"tv":36.6,"id":40380900},{"batb":[[0,1.83,16.2],[1,1.82,333],[2,1.74,17.32]],"ltp":1.83,"tv":243.18,"id":40296818}]}]}
{"op":"mcm","clk":"11777986077","pt":1722725926379,"mc":[{"id":"1.231397068","rc":[{"batb":[[0,1.84,16.02]],"ltp":2.2,"tv":36.6,"id":40380900},{"batb":[[0,1.84,10],[1,1.83,16.2],[2,1.82,333]],"ltp":1.83,"tv":243.18,"id":40296818}]}]}
{"op":"mcm","clk":"11777986375","pt":1722725930096,"mc":[{"id":"1.231397068","rc":[{"batb":[[0,1.85,10],[1,1.84,16.02],[2,1.83,56]],"ltp":2.2,"tv":36.6,"id":40380900},{"batb":[[0,1.83,16.2],[1,1.82,333],[2,1.74,17.32]],"ltp":1.83,"tv":243.18,"id":40296818}]}]}
{"op":"mcm","clk":"11777986685","pt":1722725933705,"mc":[{"id":"1.231397068","rc":[{"batb":[[0,1.84,16.02],[1,1.83,56],[2,1.74,17.32]],"ltp":2.2,"tv":36.6,"id":40380900},{"batb":[[0,1.84,10],[1,1.83,16.2],[2,1.82,333]],"ltp":1.83,"tv":243.18,"id":40296818}]}]}
{"op":"mcm","clk":"11777986954","pt":1722725937066,"mc":[{"id":"1.231397068","rc":[{"batb":[[0,1.85,10],[1,1.84,16.02],[2,1.83,56]],"ltp":2.2,"tv":36.6,"id":40380900},{"batb":[[0,1.83,16.2],[1,1.82,333],[2,1.74,17.32]],"ltp":1.83,"tv":243.18,"id":40296818}]}]}
{"op":"mcm","clk":"11777987253","pt":1722725940676,"mc":[{"id":"1.231397068","rc":[{"batb":[[0,1.84,16.02],[1,1.83,56],[2,1.74,17.32]],"ltp":2.2,"tv":36.6,"id":40380900},{"batb":[[0,1.84,10],[1,1.83,16.2],[2,1.82,333]],"ltp":1.83,"tv":243.18,"id":40296818}]}]}
{"op":"mcm","clk":"11777987556","pt":1722725944110,"mc":[{"id":"1.231397068","rc":[{"batb":[[0,1.85,10],[1,1.84,16.02],[2,1.83,56]],"ltp":2.2,"tv":36.6,"id":40380900},{"batb":[[0,1.83,16.2],[1,1.82,333],[2,1.74,17.32]],"ltp":1.83,"tv":243.18,"id":40296818}]}]}
{"op":"mcm","clk":"11777987824","pt":1722725947423,"mc":[{"id":"1.231397068","rc":[{"batb":[[0,1.84,16.02],[1,1.83,56],[2,1.74,17.32]],"ltp":2.2,"tv":36.6,"id":40380900},{"batb":[[0,1.84,10],[1,1.83,16.2],[2,1.82,333]],"ltp":1.83,"tv":243.18,"id":40296818}]}]}
{"op":"mcm","clk":"11777988094","pt":1722725950902,"mc":[{"id":"1.231397068","rc":[{"batb":[[0,1.85,10],[1,1.84,16.02],[2,1.83,56]],"ltp":2.2,"tv":36.6,"id":40380900},{"batb":[[0,1.83,16.2],[1,1.82,333],[2,1.74,17.32]],"ltp":1.83,"tv":243.18,"id":40296818}]}]}
{"op":"mcm","clk":"11777988383","pt":1722725954427,"mc":[{"id":"1.231397068","rc":[{"batb":[[0,1.84,16.02],[1,1.83,56],[2,1.74,17.32]],"ltp":2.2,"tv":36.6,"id":40380900},{"batb":[[0,1.84,10],[1,1.83,16.2],[2,1.82,333]],"ltp":1.83,"tv":243.18,"id":40296818}]}]}
{"op":"mcm","clk":"11777988634","pt":1722725957908,"mc":[{"id":"1.231397068","rc":[{"batb":[[0,1.85,10],[1,1.84,16.02],[2,1.83,56]],"ltp":2.2,"tv":36.6,"id":40380900},{"batb":[[0,1.83,16.2],[1,1.82,333],[2,1.74,17.32]],"ltp":1.83,"tv":243.18,"id":40296818}]}]}
{"op":"mcm","clk":"11777988905","pt":1722725961297,"mc":[{"id":"1.231397068","rc":[{"batb":[[0,1.84,16.02],[1,1.83,56],[2,1.74,17.32]],"ltp":2.2,"tv":36.6,"id":40380900},{"batb":[[0,1.84,10],[1,1.83,16.2],[2,1.82,333]],"ltp":1.83,"tv":243.18,"id":40296818}]}]}
{"op":"mcm","clk":"11777989191","pt":1722725964914,"mc":[{"id":"1.231397068","rc":[{"batb":[[0,1.85,10],[1,1.84,16.02],[2,1.83,56]],"ltp":2.2,"tv":36.6,"id":40380900},{"batb":[[0,1.83,16.2],[1,1.82,333],[2,1.74,17.32]],"ltp":1.83,"tv":243.18,"id":40296818}]}]}
{"op":"mcm","clk":"11777989438","pt":1722725968421,"mc":[{"id":"1.231397068","rc":[{"batb":[[0,1.84,16.02],[1,1.83,56],[2,1.74,17.32]],"ltp":2.2,"tv":36.6,"id":40380900},{"batb":[[0,1.84,10],[1,1.83,16.2],[2,1.82,333]],"ltp":1.83,"tv":243.18,"id":40296818}]}]}
{"op":"mcm","clk":"11777989692","pt":1722725971838,"mc":[{"id":"1.231397068","rc":[{"batb":[[0,1.85,10],[1,1.84,16.02],[2,1.83,56]],"ltp":2.2,"tv":36.6,"id":40380900},{"batb":[[0,1.83,16.2],[1,1.82,333],[2,1.74,17.32]],"ltp":1.83,"tv":243.18,"id":40296818}]}]}
{"op":"mcm","clk":"11777989951","pt":1722725975246,"mc":[{"id":"1.231397068","rc":[{"batb":[[0,1.84,16.02],[1,1.83,56],[2,1.74,17.32]],"ltp":2.2,"tv":36.6,"id":40380900},{"batb":[[0,1.84,10],[1,1.83,16.2],[2,1.82,333]],"ltp":1.83,"tv":243.18,"id":40296818}]}]}
{"op":"mcm","clk":"11777990200","pt":1722725978815,"mc":[{"id":"1.231397068","rc":[{"batb":[[0,1.85,10],[1,1.84,16.02],[2,1.83,56]],"ltp":2.2,"tv":36.6,"id":40380900},{"batb":[[0,1.83,16.2],[1,1.82,333],[2,1.74,17.32]],"ltp":1.83,"tv":243.18,"id":40296818}]}]}
{"op":"mcm","clk":"11777990452","pt":1722725982214,"mc":[{"id":"1.231397068","rc":[{"batb":[[0,1.84,16.02],[1,1.83,56],[2,1.74,17.32]],"ltp":2.2,"tv":36.6,"id":40380900},{"batb":[[0,1.84,10],[1,1.83,16.2],[2,1.82,333]],"ltp":1.83,"tv":243.18,"id":40296818}]}]}
{"op":"mcm","clk":"11777990760","pt":1722725985728,"mc":[{"id":"1.231397068","rc":[{"batb":[[0,1.85,10],[1,1.84,16.02],[2,1.83,56]],"ltp":2.2,"tv":36.6,"id":40380900},{"batb":[[0,1.83,16.2],[1,1.82,333],[2,1.74,17.32]],"ltp":1.83,"tv":243.18,"id":40296818}]}]}
{"op":"mcm","clk":"11777990988","pt":1722725989034,"mc":[{"id":"1.231397068","rc":[{"batb":[[0,1.84,16.02],[1,1.83,56],[2,1.74,17.32]],"ltp":2.2,"tv":36.6,"id":40380900},{"batb":[[0,1.84,10],[1,1.83,16.2],[2,1.82,333]],"ltp":1.83,"tv":243.18,"id":40296818}]}]}
{"op":"mcm","clk":"11777991210","pt":1722725992337,"mc":[{"id":"1.231397068","rc":[{"batb":[[0,1.83,16.2],[1,1.82,333],[2,1.74,17.32]],"ltp":1.83,"tv":243.18,"id":40296818}]}]}
{"op":"mcm","clk":"11777991226","pt":1722725992546,"mc":[{"id":"1.231397068","rc":[{"batb":[[0,1.85,10],[1,1.84,16.02],[2,1.83,56]],"ltp":2.2,"tv":36.6,"id":40380900}]}]}
{"op":"mcm","clk":"11777991494","pt":1722725996149,"mc":[{"id":"1.231397068","rc":[{"batb":[[0,1.84,16.02],[1,1.83,56],[2,1.74,17.32]],"ltp":2.2,"tv":36.6,"id":40380900},{"batb":[[0,1.84,10],[1,1.83,16.2],[2,1.82,333]],"ltp":1.83,"tv":243.18,"id":40296818}]}]}
{"op":"mcm","clk":"11777991761","pt":1722725999662,"mc":[{"id":"1.231397068","rc":[{"batb":[[0,1.85,10],[1,1.84,16.02],[2,1.83,56]],"ltp":2.2,"tv":36.6,"id":40380900},{"batb":[[0,1.83,16.2],[1,1.82,333],[2,1.74,17.32]],"ltp":1.83,"tv":243.18,"id":40296818}]}]}
{"op":"mcm","clk":"11777992100","pt":1722726003104,"mc":[{"id":"1.231397068","rc":[{"batb":[[0,1.84,16.02],[1,1.83,56],[2,1.74,17.32]],"ltp":2.2,"tv":36.6,"id":40380900},{"batb":[[0,1.84,10],[1,1.83,16.2],[2,1.82,333]],"ltp":1.83,"tv":243.18,"id":40296818}]}]}
{"op":"mcm","clk":"11777992413","pt":1722726006600,"mc":[{"id":"1.231397068","rc":[{"batb":[[0,1.85,10],[1,1.84,16.02],[2,1.83,56]],"ltp":2.2,"tv":36.6,"id":40380900},{"batb":[[0,1.83,16.2],[1,1.82,333],[2,1.74,17.32]],"ltp":1.83,"tv":243.18,"id":40296818}]}]}
{"op":"mcm","clk":"11777992687","pt":1722726010128,"mc":[{"id":"1.231397068","rc":[{"batb":[[0,1.84,16.02],[1,1.83,56],[2,1.74,17.32]],"ltp":2.2,"tv":36.6,"id":40380900},{"batb":[[0,1.84,10],[1,1.83,16.2],[2,1.82,333]],"ltp":1.83,"tv":243.18,"id":40296818}]}]}
{"op":"mcm","clk":"11777993032","pt":1722726013619,"mc":[{"id":"1.231397068","rc":[{"batb":[[0,1.85,10],[1,1.84,16.02],[2,1.83,56]],"ltp":2.2,"tv":36.6,"id":40380900},{"batb":[[0,1.83,16.2],[1,1.82,333],[2,1.74,17.32]],"ltp":1.83,"tv":243.18,"id":40296818}]}]}
{"op":"mcm","clk":"11777993339","pt":1722726017241,"mc":[{"id":"1.231397068","rc":[{"batb":[[0,1.84,16.02],[1,1.83,56],[2,1.74,17.32]],"ltp":2.2,"tv":36.6,"id":40380900},{"batb":[[0,1.84,10],[1,1.83,16.2],[2,1.82,333]],"ltp":1.83,"tv":243.18,"id":40296818}]}]}
{"op":"mcm","clk":"11777993648","pt":1722726020834,"mc":[{"id":"1.231397068","rc":[{"batb":[[0,1.85,10],[1,1.84,16.02],[2,1.83,56]],"ltp":2.2,"tv":36.6,"id":40380900},{"batb":[[0,1.83,16.2],[1,1.82,333],[2,1.74,17.32]],"ltp":1.83,"tv":243.18,"id":40296818}]}]}
{"op":"mcm","clk":"11777993923","pt":1722726024360,"mc":[{"id":"1.231397068","rc":[{"batb":[[0,1.84,16.02],[1,1.83,56],[2,1.74,17.32]],"ltp":2.2,"tv":36.6,"id":40380900},{"batb":[[0,1.84,10],[1,1.83,16.2],[2,1.82,333]],"ltp":1.83,"tv":243.18,"id":40296818}]}]}
{"op":"mcm","clk":"11777994238","pt":1722726027836,"mc":[{"id":"1.231397068","rc":[{"batb":[[0,1.85,10],[1,1.84,16.02],[2,1.83,56]],"ltp":2.2,"tv":36.6,"id":40380900},{"batb":[[0,1.83,16.2],[1,1.82,333],[2,1.74,17.32]],"ltp":1.83,"tv":243.18,"id":40296818}]}]}
{"op":"mcm","clk":"11777994529","pt":1722726031362,"mc":[{"id":"1.231397068","rc":[{"batb":[[0,1.84,16.02],[1,1.83,56],[2,1.74,17.32]],"ltp":2.2,"tv":36.6,"id":40380900},{"batb":[[0,1.84,10],[1,1.83,16.2],[2,1.82,333]],"ltp":1.83,"tv":243.18,"id":40296818}]}]}
{"op":"mcm","clk":"11777994825","pt":1722726034936,"mc":[{"id":"1.231397068","rc":[{"batb":[[0,1.85,10],[1,1.84,16.02],[2,1.83,56]],"ltp":2.2,"tv":36.6,"id":40380900},{"batb":[[0,1.83,16.2],[1,1.82,333],[2,1.74,17.32]],"ltp":1.83,"tv":243.18,"id":40296818}]}]}
{"op":"mcm","clk":"11777995099","pt":1722726038279,"mc":[{"id":"1.231397068","rc":[{"batb":[[0,1.84,16.02],[1,1.83,56],[2,1.74,17.32]],"ltp":2.2,"tv":36.6,"id":40380900},{"batb":[[0,1.84,10],[1,1.83,16.2],[2,1.82,333]],"ltp":1.83,"tv":243.18,"id":40296818}]}]}
{"op":"mcm","clk":"11777995385","pt":1722726041746,"mc":[{"id":"1.231397068","rc":[{"batb":[[0,1.85,10],[1,1.84,16.02],[2,1.83,56]],"ltp":2.2,"tv":36.6,"id":40380900},{"batb":[[0,1.83,16.2],[1,1.82,333],[2,1.74,17.32]],"ltp":1.83,"tv":243.18,"id":40296818}]}]}
{"op":"mcm","clk":"11777995613","pt":1722726045154,"mc":[{"id":"1.231397068","rc":[{"batb":[[0,1.84,16.02],[1,1.83,56],[2,1.74,17.32]],"ltp":2.2,"tv":36.6,"id":40380900},{"batb":[[0,1.84,10],[1,1.83,16.2],[2,1.82,333]],"ltp":1.83,"tv":243.18,"id":40296818}]}]}
{"op":"mcm","clk":"11777995872","pt":1722726048554,"mc":[{"id":"1.231397068","rc":[{"batb":[[0,1.85,10],[1,1.84,16.02],[2,1.83,56]],"ltp":2.2,"tv":36.6,"id":40380900},{"batb":[[0,1.83,16.2],[1,1.82,333],[2,1.74,17.32]],"ltp":1.83,"tv":243.18,"id":40296818}]}]}
{"op":"mcm","clk":"11777996140","pt":1722726051863,"mc":[{"id":"1.231397068","rc":[{"batb":[[0,1.84,16.02],[1,1.83,56],[2,1.74,17.32]],"ltp":2.2,"tv":36.6,"id":40380900},{"batb":[[0,1.84,10],[1,1.83,16.2],[2,1.82,333]],"ltp":1.83,"tv":243.18,"id":40296818}]}]}
{"op":"mcm","clk":"11777996395","pt":1722726055263,"mc":[{"id":"1.231397068","rc":[{"batb":[[0,1.83,16.2],[1,1.82,333],[2,1.74,17.32]],"ltp":1.83,"tv":243.18,"id":40296818}]}]}
{"op":"mcm","clk":"11777996411","pt":1722726055471,"mc":[{"id":"1.231397068","rc":[{"batb":[[0,1.85,10],[1,1.84,16.02],[2,1.83,56]],"ltp":2.2,"tv":36.6,"id":40380900}]}]}
{"op":"mcm","clk":"11777996667","pt":1722726058907,"mc":[{"id":"1.231397068","rc":[{"batb":[[0,1.84,16.02],[1,1.83,56],[2,1.74,17.32]],"ltp":2.2,"tv":36.6,"id":40380900},{"batb":[[0,1.84,10],[1,1.83,16.2],[2,1.82,333]],"ltp":1.83,"tv":243.18,"id":40296818}]}]}
{"op":"mcm","clk":"11777996993","pt":1722726062282,"mc":[{"id":"1.231397068","rc":[{"batb":[[0,1.83,16.2],[1,1.82,333],[2,1.74,17.32]],"ltp":1.83,"tv":243.18,"id":40296818}]}]}
{"op":"mcm","clk":"11777997016","pt":1722726062490,"mc":[{"id":"1.231397068","rc":[{"batb":[[0,1.85,10],[1,1.84,16.02],[2,1.83,56]],"ltp":2.2,"tv":36.6,"id":40380900}]}]}
{"op":"mcm","clk":"11777997324","pt":1722726065999,"mc":[{"id":"1.231397068","rc":[{"batb":[[0,1.84,16.02],[1,1.83,56],[2,1.74,17.32]],"ltp":2.2,"tv":36.6,"id":40380900},{"batb":[[0,1.84,10],[1,1.83,16.2],[2,1.82,333]],"ltp":1.83,"tv":243.18,"id":40296818}]}]}
{"op":"mcm","clk":"11777997614","pt":1722726069406,"mc":[{"id":"1.231397068","rc":[{"batb":[[0,1.85,10],[1,1.84,16.02],[2,1.83,56]],"ltp":2.2,"tv":36.6,"id":40380900},{"batb":[[0,1.83,16.2],[1,1.82,333],[2,1.74,17.32]],"ltp":1.83,"tv":243.18,"id":40296818}]}]}
{"op":"mcm","clk":"11777997891","pt":1722726072776,"mc":[{"id":"1.231397068","rc":[{"batb":[[0,1.84,16.02],[1,1.83,56],[2,1.74,17.32]],"ltp":2.2,"tv":36.6,"id":40380900},{"batb":[[0,1.84,10],[1,1.83,16.2],[2,1.82,333]],"ltp":1.83,"tv":243.18,"id":40296818}]}]}
{"op":"mcm","clk":"11777998165","pt":1722726076091,"mc":[{"id":"1.231397068","rc":[{"batb":[[0,1.85,10],[1,1.84,16.02],[2,1.83,56]],"ltp":2.2,"tv":36.6,"id":40380900},{"batb":[[0,1.83,16.2],[1,1.82,333],[2,1.74,17.32]],"ltp":1.83,"tv":243.18,"id":40296818}]}]}
{"op":"mcm","clk":"11777998454","pt":1722726079711,"mc":[{"id":"1.231397068","rc":[{"batb":[[0,1.84,16.02],[1,1.83,56],[2,1.74,17.32]],"ltp":2.2,"tv":36.6,"id":40380900},{"batb":[[0,1.84,10],[1,1.83,16.2],[2,1.82,333]],"ltp":1.83,"tv":243.18,"id":40296818}]}]}
{"op":"mcm","clk":"11777998734","pt":1722726083132,"mc":[{"id":"1.231397068","rc":[{"batb":[[0,1.85,10],[1,1.84,16.02],[2,1.83,56]],"ltp":2.2,"tv":36.6,"id":40380900},{"batb":[[0,1.83,16.2],[1,1.82,333],[2,1.74,17.32]],"ltp":1.83,"tv":243.18,"id":40296818}]}]}
{"op":"mcm","clk":"11777999058","pt":1722726086749,"mc":[{"id":"1.231397068","rc":[{"batb":[[0,1.84,16.02],[1,1.83,56],[2,1.74,17.32]],"ltp":2.2,"tv":36.6,"id":40380900},{"batb":[[0,1.84,10],[1,1.83,16.2],[2,1.82,333]],"ltp":1.83,"tv":243.18,"id":40296818}]}]}
{"op":"mcm","clk":"11777999375","pt":1722726090347,"mc":[{"id":"1.231397068","rc":[{"batb":[[0,1.85,10],[1,1.84,16.02],[2,1.83,56]],"ltp":2.2,"tv":36.6,"id":40380900},{"batb":[[0,1.83,16.2],[1,1.82,333],[2,1.74,17.32]],"ltp":1.83,"tv":243.18,"id":40296818}]}]}
{"op":"mcm","clk":"11777999668","pt":1722726093737,"mc":[{"id":"1.231397068","rc":[{"batb":[[0,1.84,16.02],[1,1.83,56],[2,1.74,17.32]],"ltp":2.2,"tv":36.6,"id":40380900},{"batb":[[0,1.84,10],[1,1.83,16.2],[2,1.82,333]],"ltp":1.83,"tv":243.18,"id":40296818}]}]}
{"op":"mcm","clk":"11777999920","pt":1722726097029,"mc":[{"id":"1.231397068","rc":[{"batb":[[0,1.85,10],[1,1.84,16.02],[2,1.83,56]],"ltp":2.2,"tv":36.6,"id":40380900},{"batb":[[0,1.83,16.2],[1,1.82,333],[2,1.74,17.32]],"ltp":1.83,"tv":243.18,"id":40296818}]}]}
{"op":"mcm","clk":"11778000176","pt":1722726100349,"mc":[{"id":"1.231397068","rc":[{"batb":[[0,1.84,16.02],[1,1.83,56],[2,1.74,17.32]],"ltp":2.2,"tv":36.6,"id":40380900},{"batb":[[0,1.84,10],[1,1.83,16.2],[2,1.82,333]],"ltp":1.83,"tv":243.18,"id":40296818}]}]}
{"op":"mcm","clk":"11778000455","pt":1722726103728,"mc":[{"id":"1.231397068","rc":[{"batb":[[0,1.85,10],[1,1.84,16.02],[2,1.83,56]],"ltp":2.2,"tv":36.6,"id":40380900},{"batb":[[0,1.83,16.2],[1,1.82,333],[2,1.74,17.32]],"ltp":1.83,"tv":243.18,"id":40296818}]}]}
{"op":"mcm","clk":"11778000712","pt":1722726107127,"mc":[{"id":"1.231397068","rc":[{"batb":[[0,1.84,16.02],[1,1.83,56],[2,1.74,17.32]],"ltp":2.2,"tv":36.6,"id":40380900},{"batb":[[0,1.84,10],[1,1.83,16.2],[2,1.82,333]],"ltp":1.83,"tv":243.18,"id":40296818}]}]}
{"op":"mcm","clk":"11778000998","pt":1722726110643,"mc":[{"id":"1.231397068","rc":[{"batb":[[0,1.85,10],[1,1.84,16.02],[2,1.83,56]],"ltp":2.2,"tv":36.6,"id":40380900},{"batb":[[0,1.83,16.2],[1,1.82,333],[2,1.74,17.32]],"ltp":1.83,"tv":243.18,"id":40296818}]}]}
{"op":"mcm","clk":"11778001257","pt":1722726114163,"mc":[{"id":"1.231397068","rc":[{"batb":[[0,1.84,16.02],[1,1.83,56],[2,1.74,17.32]],"ltp":2.2,"tv":36.6,"id":40380900},{"batb":[[0,1.84,10],[1,1.83,16.2],[2,1.82,333]],"ltp":1.83,"tv":243.18,"id":40296818}]}]}
{"op":"mcm","clk":"11778001522","pt":1722726117626,"mc":[{"id":"1.231397068","rc":[{"batb":[[0,1.85,10],[1,1.84,16.02],[2,1.83,56]],"ltp":2.2,"tv":36.6,"id":40380900},{"batb":[[0,1.83,16.2],[1,1.82,333],[2,1.74,17.32]],"ltp":1.83,"tv":243.18,"id":40296818}]}]}
{"op":"mcm","clk":"11778001809","pt":1722726121187,"mc":[{"id":"1.231397068","rc":[{"batb":[[0,1.84,16.02],[1,1.83,56],[2,1.74,17.32]],"ltp":2.2,"tv":36.6,"id":40380900},{"batb":[[0,1.84,10],[1,1.83,16.2],[2,1.82,333]],"ltp":1.83,"tv":243.18,"id":40296818}]}]}
{"op":"mcm","clk":"11778002121","pt":1722726124834,"mc":[{"id":"1.231397068","rc":[{"batb":[[0,1.85,10],[1,1.84,16.02],[2,1.83,56]],"ltp":2.2,"tv":36.6,"id":40380900},{"batb":[[0,1.83,16.2],[1,1.82,333],[2,1.74,17.32]],"ltp":1.83,"tv":243.18,"id":40296818}]}]}
{"op":"mcm","clk":"11778002385","pt":1722726128354,"mc":[{"id":"1.231397068","rc":[{"batb":[[0,1.84,16.02],[1,1.83,56],[2,1.74,17.32]],"ltp":2.2,"tv":36.6,"id":40380900}]}]}
{"op":"mcm","clk":"11778002393","pt":1722726128462,"mc":[{"id":"1.231397068","rc":[{"batb":[[0,1.84,10],[1,1.83,16.2],[2,1.82,333]],"ltp":1.83,"tv":243.18,"id":40296818}]}]}
{"op":"mcm","clk":"11778002656","pt":1722726131785,"mc":[{"id":"1.231397068","rc":[{"batb":[[0,1.85,10],[1,1.84,16.02],[2,1.83,56]],"ltp":2.2,"tv":36.6,"id":40380900},{"batb":[[0,1.83,16.2],[1,1.82,333],[2,1.74,17.32]],"ltp":1.83,"tv":243.18,"id":40296818}]}]}
{"op":"mcm","clk":"11778002930","pt":1722726135155,"mc":[{"id":"1.231397068","rc":[{"batb":[[0,1.84,16.02],[1,1.83,56],[2,1.74,17.32]],"ltp":2.2,"tv":36.6,"id":40380900},{"batb":[[0,1.84,10],[1,1.83,16.2],[2,1.82,333]],"ltp":1.83,"tv":243.18,"id":40296818}]}]}
{"op":"mcm","clk":"11778003201","pt":1722726138579,"mc":[{"id":"1.231397068","rc":[{"batb":[[0,1.85,10],[1,1.84,16.02],[2,1.83,56]],"ltp":2.2,"tv":36.6,"id":40380900},{"batb":[[0,1.83,16.2],[1,1.82,333],[2,1.74,17.32]],"ltp":1.83,"tv":243.18,"id":40296818}]}]}
{"op":"mcm","clk":"11778003482","pt":1722726141885,"mc":[{"id":"1.231397068","rc":[{"batb":[[0,1.84,16.02],[1,1.83,56],[2,1.74,17.32]],"ltp":2.2,"tv":36.6,"id":40380900},{"batb":[[0,1.84,10],[1,1.83,16.2],[2,1.82,333]],"ltp":1.83,"tv":243.18,"id":40296818}]}]}
{"op":"mcm","clk":"11778003812","pt":1722726145311,"mc":[{"id":"1.231397068","rc":[{"batb":[[0,1.83,16.2],[1,1.82,333],[2,1.74,17.32]],"ltp":1.83,"tv":243.18,"id":40296818}]}]}
{"op":"mcm","clk":"11778003829","pt":1722726145468,"mc":[{"id":"1.231397068","rc":[{"batb":[[0,1.85,10],[1,1.84,16.02],[2,1.83,56]],"ltp":2.2,"tv":36.6,"id":40380900}]}]}
{"op":"mcm","clk":"11778004137","pt":1722726149194,"mc":[{"id":"1.231397068","rc":[{"batb":[[0,1.84,16.02],[1,1.83,56],[2,1.74,17.32]],"ltp":2.2,"tv":36.6,"id":40380900},{"batb":[[0,1.84,10],[1,1.83,16.2],[2,1.82,333]],"ltp":1.83,"tv":243.18,"id":40296818}]}]}
{"op":"mcm","clk":"11778004422","pt":1722726152677,"mc":[{"id":"1.231397068","rc":[{"batb":[[0,1.85,10],[1,1.84,16.02],[2,1.83,56]],"ltp":2.2,"tv":36.6,"id":40380900},{"batb":[[0,1.83,16.2],[1,1.82,333],[2,1.74,17.32]],"ltp":1.83,"tv":243.18,"id":40296818}]}]}
{"op":"mcm","clk":"11778004711","pt":1722726156211,"mc":[{"id":"1.231397068","rc":[{"batb":[[0,1.84,16.02],[1,1.83,56],[2,1.74,17.32]],"ltp":2.2,"tv":36.6,"id":40380900},{"batb":[[0,1.84,10],[1,1.83,16.2],[2,1.82,333]],"ltp":1.83,"tv":243.18,"id":40296818}]}]}
{"op":"mcm","clk":"11778005050","pt":1722726159787,"mc":[{"id":"1.231397068","rc":[{"batb":[[0,1.85,10],[1,1.84,16.02],[2,1.83,56]],"ltp":2.2,"tv":36.6,"id":40380900},{"batb":[[0,1.83,16.2],[1,1.82,333],[2,1.74,17.32]],"ltp":1.83,"tv":243.18,"id":40296818}]}]}
{"op":"mcm","clk":"11778005329","pt":1722726163409,"mc":[{"id":"1.231397068","rc":[{"batb":[[0,1.84,16.02],[1,1.83,56],[2,1.74,17.32]],"ltp":2.2,"tv":36.6,"id":40380900},{"batb":[[0,1.84,10],[1,1.83,16.2],[2,1.82,333]],"ltp":1.83,"tv":243.18,"id":40296818}]}]}
{"op":"mcm","clk":"11778005617","pt":1722726167032,"mc":[{"id":"1.231397068","rc":[{"batb":[[0,1.85,10],[1,1.84,16.02],[2,1.83,56]],"ltp":2.2,"tv":36.6,"id":40380900},{"batb":[[0,1.83,16.2],[1,1.82,333],[2,1.74,17.32]],"ltp":1.83,"tv":243.18,"id":40296818}]}]}
{"op":"mcm","clk":"11778005902","pt":1722726170403,"mc":[{"id":"1.231397068","rc":[{"batb":[[0,1.84,16.02],[1,1.83,56],[2,1.74,17.32]],"ltp":2.2,"tv":36.6,"id":40380900},{"batb":[[0,1.84,10],[1,1.83,16.2],[2,1.82,333]],"ltp":1.83,"tv":243.18,"id":40296818}]}]}
{"op":"mcm","clk":"11778006184","pt":1722726173947,"mc":[{"id":"1.231397068","rc":[{"batb":[[0,1.85,10],[1,1.84,16.02],[2,1.83,56]],"ltp":2.2,"tv":36.6,"id":40380900},{"batb":[[0,1.83,16.2],[1,1.82,333],[2,1.74,17.32]],"ltp":1.83,"tv":243.18,"id":40296818}]}]}
{"op":"mcm","clk":"11778006457","pt":1722726177398,"mc":[{"id":"1.231397068","rc":[{"batb":[[0,1.84,16.02],[1,1.83,56],[2,1.74,17.32]],"ltp":2.2,"tv":36.6,"id":40380900},{"batb":[[0,1.84,10],[1,1.83,16.2],[2,1.82,333]],"ltp":1.83,"tv":243.18,"id":40296818}]}]}
{"op":"mcm","clk":"11778006721","pt":1722726180833,"mc":[{"id":"1.231397068","rc":[{"batb":[[0,1.85,10],[1,1.84,16.02],[2,1.83,56]],"ltp":2.2,"tv":36.6,"id":40380900},{"batb":[[0,1.83,16.2],[1,1.82,333],[2,1.74,17.32]],"ltp":1.83,"tv":243.18,"id":40296818}]}]}
{"op":"mcm","clk":"11778007050","pt":1722726184209,"mc":[{"id":"1.231397068","rc":[{"batb":[[0,1.84,16.02],[1,1.83,56],[2,1.74,17.32]],"ltp":2.2,"tv":36.6,"id":40380900},{"batb":[[0,1.84,10],[1,1.83,16.2],[2,1.82,333]],"ltp":1.83,"tv":243.18,"id":40296818}]}]}
{"op":"mcm","clk":"11778007365","pt":1722726187717,"mc":[{"id":"1.231397068","rc":[{"batb":[[0,1.85,10],[1,1.84,16.02],[2,1.83,56]],"ltp":2.2,"tv":36.6,"id":40380900},{"batb":[[0,1.83,16.2],[1,1.82,333],[2,1.74,17.32]],"ltp":1.83,"tv":243.18,"id":40296818}]}]}
{"op":"mcm","clk":"11778007653","pt":1722726191355,"mc":[{"id":"1.231397068","rc":[{"batb":[[0,1.84,16.02],[1,1.83,56],[2,1.74,17.32]],"ltp":2.2,"tv":36.6,"id":40380900},{"batb":[[0,1.84,10],[1,1.83,16.2],[2,1.82,333]],"ltp":1.83,"tv":243.18,"id":40296818}]}]}
{"op":"mcm","clk":"11778007946","pt":1722726194966,"mc":[{"id":"1.231397068","rc":[{"batb":[[0,1.85,10],[1,1.84,16.02],[2,1.83,56]],"ltp":2.2,"tv":36.6,"id":40380900},{"batb":[[0,1.83,16.2],[1,1.82,333],[2,1.74,17.32]],"ltp":1.83,"tv":243.18,"id":40296818}]}]}
{"op":"mcm","clk":"11778008224","pt":1722726198347,"mc":[{"id":"1.231397068","rc":[{"batb":[[0,1.84,16.02],[1,1.83,56],[2,1.74,17.32]],"ltp":2.2,"tv":36.6,"id":40380900}]}]}
{"op":"mcm","clk":"11778008240","pt":1722726198454,"mc":[{"id":"1.231397068","rc":[{"batb":[[0,1.84,10],[1,1.83,16.2],[2,1.82,333]],"ltp":1.83,"tv":243.18,"id":40296818}]}]}
{"op":"mcm","clk":"11778008534","pt":1722726202025,"mc":[{"id":"1.231397068","rc":[{"batb":[[0,1.85,10],[1,1.84,16.02],[2,1.83,56]],"ltp":2.2,"tv":36.6,"id":40380900},{"batb":[[0,1.83,16.2],[1,1.82,333],[2,1.74,17.32]],"ltp":1.83,"tv":243.18,"id":40296818}]}]}
{"op":"mcm","clk":"11778008826","pt":1722726205556,"mc":[{"id":"1.231397068","rc":[{"batb":[[0,1.84,16.02],[1,1.83,56],[2,1.74,17.32]],"ltp":2.2,"tv":36.6,"id":40380900},{"batb":[[0,1.84,10],[1,1.83,16.2],[2,1.82,333]],"ltp":1.83,"tv":243.18,"id":40296818}]}]}
{"op":"mcm","clk":"11778009113","pt":1722726209070,"mc":[{"id":"1.231397068","rc":[{"batb":[[0,1.85,10],[1,1.84,16.02],[2,1.83,56]],"ltp":2.2,"tv":36.6,"id":40380900},{"batb":[[0,1.83,16.2],[1,1.82,333],[2,1.74,17.32]],"ltp":1.83,"tv":243.18,"id":40296818}]}]}
{"op":"mcm","clk":"11778009417","pt":1722726212592,"mc":[{"id":"1.231397068","rc":[{"batb":[[0,1.84,16.02],[1,1.83,56],[2,1.74,17.32]],"ltp":2.2,"tv":36.6,"id":40380900},{"batb":[[0,1.84,10],[1,1.83,16.2],[2,1.82,333]],"ltp":1.83,"tv":243.18,"id":40296818}]}]}
{"op":"mcm","clk":"11778009714","pt":1722726216055,"mc":[{"id":"1.231397068","rc":[{"batb":[[0,1.85,10],[1,1.84,16.02],[2,1.83,56]],"ltp":2.2,"tv":36.6,"id":40380900},{"batb":[[0,1.83,16.2],[1,1.82,333],[2,1.74,17.32]],"ltp":1.83,"tv":243.18,"id":40296818}]}]}
{"op":"mcm","clk":"11778010003","pt":1722726219686,"mc":[{"id":"1.231397068","rc":[{"batb":[[0,1.84,16.02],[1,1.83,56],[2,1.74,17.32]],"ltp":2.2,"tv":36.6,"id":40380900},{"batb":[[0,1.84,10],[1,1.83,16.2],[2,1.82,333]],"ltp":1.83,"tv":243.18,"id":40296818}]}]}
{"op":"mcm","clk":"11778010280","pt":1722726223255,"mc":[{"id":"1.231397068","rc":[{"batb":[[0,1.85,10],[1,1.84,16.02],[2,1.83,56]],"ltp":2.2,"tv":36.6,"id":40380900},{"batb":[[0,1.83,16.2],[1,1.82,333],[2,1.74,17.32]],"ltp":1.83,"tv":243.18,"id":40296818}]}]}
{"op":"mcm","clk":"11778010601","pt":1722726226981,"mc":[{"id":"1.231397068","rc":[{"batb":[[0,1.84,16.02],[1,1.83,56],[2,1.74,17.32]],"ltp":2.2,"tv":36.6,"id":40380900},{"batb":[[0,1.84,10],[1,1.83,16.2],[2,1.82,333]],"ltp":1.83,"tv":243.18,"id":40296818}]}]}
{"op":"mcm","clk":"11778010855","pt":1722726230371,"mc":[{"id":"1.231397068","rc":[{"batb":[[0,1.83,16.2],[1,1.82,333],[2,1.74,17.32]],"ltp":1.83,"tv":243.18,"id":40296818}]}]}
{"op":"mcm","clk":"11778010874","pt":1722726230576,"mc":[{"id":"1.231397068","rc":[{"batb":[[0,1.85,10],[1,1.84,16.02],[2,1.83,56]],"ltp":2.2,"tv":36.6,"id":40380900}]}]}
{"op":"mcm","clk":"11778011115","pt":1722726233990,"mc":[{"id":"1.231397068","rc":[{"batb":[[0,1.84,16.02],[1,1.83,56],[2,1.74,17.32]],"ltp":2.2,"tv":36.6,"id":40380900},{"batb":[[0,1.84,10],[1,1.83,16.2],[2,1.82,333]],"ltp":1.83,"tv":243.18,"id":40296818}]}]}
{"op":"mcm","clk":"11778011388","pt":1722726237407,"mc":[{"id":"1.231397068","rc":[{"batb":[[0,1.83,16.2],[1,1.82,333],[2,1.74,17.32]],"ltp":1.83,"tv":243.18,"id":40296818}]}]}
{"op":"mcm","clk":"11778011400","pt":1722726237513,"mc":[{"id":"1.231397068","rc":[{"batb":[[0,1.85,10],[1,1.84,16.02],[2,1.83,56]],"ltp":2.2,"tv":36.6,"id":40380900}]}]}
{"op":"mcm","clk":"11778011667","pt":1722726240876,"mc":[{"id":"1.231397068","rc":[{"batb":[[0,1.84,16.02],[1,1.83,56],[2,1.74,17.32]],"ltp":2.2,"tv":36.6,"id":40380900},{"batb":[[0,1.84,10],[1,1.83,16.2],[2,1.82,333]],"ltp":1.83,"tv":243.18,"id":40296818}]}]}
{"op":"mcm","clk":"11778011909","pt":1722726244287,"mc":[{"id":"1.231397068","rc":[{"batb":[[0,1.85,10],[1,1.84,16.02],[2,1.83,56]],"ltp":2.2,"tv":36.6,"id":40380900},{"batb":[[0,1.83,16.2],[1,1.82,333],[2,1.74,17.32]],"ltp":1.83,"tv":243.18,"id":40296818}]}]}
{"op":"mcm","clk":"11778012121","pt":1722726247710,"mc":[{"id":"1.231397068","rc":[{"batb":[[0,1.84,16.02],[1,1.83,56],[2,1.74,17.32]],"ltp":2.2,"tv":36.6,"id":40380900},{"batb":[[0,1.84,10],[1,1.83,16.2],[2,1.82,333]],"ltp":1.83,"tv":243.18,"id":40296818}]}]}
{"op":"mcm","clk":"11778012336","pt":1722726251291,"mc":[{"id":"1.231397068","rc":[{"batb":[[0,1.85,10],[1,1.84,16.02],[2,1.83,56]],"ltp":2.2,"tv":36.6,"id":40380900},{"batb":[[0,1.83,16.2],[1,1.82,333],[2,1.74,17.32]],"ltp":1.83,"tv":243.18,"id":40296818}]}]}
{"op":"mcm","clk":"11778012561","pt":1722726254721,"mc":[{"id":"1.231397068","rc":[{"batb":[[0,1.84,16.02],[1,1.83,56],[2,1.74,17.32]],"ltp":2.2,"tv":36.6,"id":40380900},{"batb":[[0,1.84,10],[1,1.83,16.2],[2,1.82,333]],"ltp":1.83,"tv":243.18,"id":40296818}]}]}
{"op":"mcm","clk":"11778012804","pt":1722726258199,"mc":[{"id":"1.231397068","rc":[{"batb":[[0,1.85,10],[1,1.84,16.02],[2,1.83,56]],"ltp":2.2,"tv":36.6,"id":40380900},{"batb":[[0,1.83,16.2],[1,1.82,333],[2,1.74,17.32]],"ltp":1.83,"tv":243.18,"id":40296818}]}]}
{"op":"mcm","clk":"11778013035","pt":1722726261826,"mc":[{"id":"1.231397068","rc":[{"batb":[[0,1.84,16.02],[1,1.83,56],[2,1.74,17.32]],"ltp":2.2,"tv":36.6,"id":40380900},{"batb":[[0,1.84,10],[1,1.83,16.2],[2,1.82,333]],"ltp":1.83,"tv":243.18,"id":40296818}]}]}
{"op":"mcm","clk":"11778013262","pt":1722726265297,"mc":[{"id":"1.231397068","rc":[{"batb":[[0,1.85,10],[1,1.84,16.02],[2,1.83,56]],"ltp":2.2,"tv":36.6,"id":40380900},{"batb":[[0,1.83,16.2],[1,1.82,333],[2,1.74,17.32]],"ltp":1.83,"tv":243.18,"id":40296818}]}]}
{"op":"mcm","clk":"11778013485","pt":1722726268815,"mc":[{"id":"1.231397068","rc":[{"batb":[[0,1.84,16.02],[1,1.83,56],[2,1.74,17.32]],"ltp":2.2,"tv":36.6,"id":40380900},{"batb":[[0,1.84,10],[1,1.83,16.2],[2,1.82,333]],"ltp":1.83,"tv":243.18,"id":40296818}]}]}
{"op":"mcm","clk":"11778013726","pt":1722726272126,"mc":[{"id":"1.231397068","rc":[{"batb":[[0,1.85,10],[1,1.84,16.02],[2,1.83,56]],"ltp":2.2,"tv":36.6,"id":40380900},{"batb":[[0,1.83,16.2],[1,1.82,333],[2,1.74,17.32]],"ltp":1.83,"tv":243.18,"id":40296818}]}]}
{"op":"mcm","clk":"11778013945","pt":1722726275350,"mc":[{"id":"1.231397068","rc":[{"batb":[[0,1.84,16.02],[1,1.83,56],[2,1.74,17.32]],"ltp":2.2,"tv":36.6,"id":40380900}]}]}
{"op":"mcm","clk":"11778013952","pt":1722726275452,"mc":[{"id":"1.231397068","rc":[{"batb":[[0,1.84,10],[1,1.83,16.2],[2,1.82,333]],"ltp":1.83,"tv":243.18,"id":40296818}]}]}
{"op":"mcm","clk":"11778014142","pt":1722726278822,"mc":[{"id":"1.231397068","rc":[{"batb":[[0,1.85,10],[1,1.84,16.02],[2,1.83,56]],"ltp":2.2,"tv":36.6,"id":40380900},{"batb":[[0,1.83,16.2],[1,1.82,333],[2,1.74,17.32]],"ltp":1.83,"tv":243.18,"id":40296818}]}]}
{"op":"mcm","clk":"11778014346","pt":1722726282235,"mc":[{"id":"1.231397068","rc":[{"batb":[[0,1.84,16.02],[1,1.83,56],[2,1.74,17.32]],"ltp":2.2,"tv":36.6,"id":40380900},{"batb":[[0,1.84,10],[1,1.83,16.2],[2,1.82,333]],"ltp":1.83,"tv":243.18,"id":40296818}]}]}
{"op":"mcm","clk":"11778014573","pt":1722726285816,"mc":[{"id":"1.231397068","rc":[{"batb":[[0,1.85,10],[1,1.84,16.02],[2,1.83,56]],"ltp":2.2,"tv":36.6,"id":40380900},{"batb":[[0,1.83,16.2],[1,1.82,333],[2,1.74,17.32]],"ltp":1.83,"tv":243.18,"id":40296818}]}]}
{"op":"mcm","clk":"11778014795","pt":1722726289241,"mc":[{"id":"1.231397068","rc":[{"batb":[[0,1.84,16.02],[1,1.83,56],[2,1.74,17.32]],"ltp":2.2,"tv":36.6,"id":40380900}]}]}
{"op":"mcm","clk":"11778014804","pt":1722726289443,"mc":[{"id":"1.231397068","rc":[{"batb":[[0,1.84,10],[1,1.83,16.2],[2,1.82,333]],"ltp":1.83,"tv":243.18,"id":40296818}]}]}
{"op":"mcm","clk":"11778015014","pt":1722726292825,"mc":[{"id":"1.231397068","rc":[{"batb":[[0,1.85,10],[1,1.84,16.02],[2,1.83,56]],"ltp":2.2,"tv":36.6,"id":40380900},{"batb":[[0,1.83,16.2],[1,1.82,333],[2,1.74,17.32]],"ltp":1.83,"tv":243.18,"id":40296818}]}]}
{"op":"mcm","clk":"11778015235","pt":1722726296261,"mc":[{"id":"1.231397068","rc":[{"batb":[[0,1.84,16.02],[1,1.83,56],[2,1.74,17.32]],"ltp":2.2,"tv":36.6,"id":40380900},{"batb":[[0,1.84,10],[1,1.83,16.2],[2,1.82,333]],"ltp":1.83,"tv":243.18,"id":40296818}]}]}
{"op":"mcm","clk":"11778015474","pt":1722726299879,"mc":[{"id":"1.231397068","rc":[{"batb":[[0,1.85,10],[1,1.84,16.02],[2,1.83,56]],"ltp":2.2,"tv":36.6,"id":40380900},{"batb":[[0,1.83,16.2],[1,1.82,333],[2,1.74,17.32]],"ltp":1.83,"tv":243.18,"id":40296818}]}]}
{"op":"mcm","clk":"11778015777","pt":1722726303372,"mc":[{"id":"1.231397068","rc":[{"batb":[[0,1.84,16.02],[1,1.83,56],[2,1.74,17.32]],"ltp":2.2,"tv":36.6,"id":40380900},{"batb":[[0,1.84,10],[1,1.83,16.2],[2,1.82,333]],"ltp":1.83,"tv":243.18,"id":40296818}]}]}
{"op":"mcm","clk":"11778016042","pt":1722726307065,"mc":[{"id":"1.231397068","rc":[{"batb":[[0,1.85,10],[1,1.84,16.02],[2,1.83,56]],"ltp":2.2,"tv":36.6,"id":40380900},{"batb":[[0,1.83,16.2],[1,1.82,333],[2,1.74,17.32]],"ltp":1.83,"tv":243.18,"id":40296818}]}]}
{"op":"mcm","clk":"11778016295","pt":1722726310548,"mc":[{"id":"1.231397068","rc":[{"batb":[[0,1.84,16.02],[1,1.83,56],[2,1.74,17.32]],"ltp":2.2,"tv":36.6,"id":40380900},{"batb":[[0,1.84,10],[1,1.83,16.2],[2,1.82,333]],"ltp":1.83,"tv":243.18,"id":40296818}]}]}
{"op":"mcm","clk":"11778016536","pt":1722726314191,"mc":[{"id":"1.231397068","rc":[{"batb":[[0,1.85,10],[1,1.84,16.02],[2,1.83,56]],"ltp":2.2,"tv":36.6,"id":40380900},{"batb":[[0,1.83,16.2],[1,1.82,333],[2,1.74,17.32]],"ltp":1.83,"tv":243.18,"id":40296818}]}]}
{"op":"mcm","clk":"11778016809","pt":1722726317574,"mc":[{"id":"1.231397068","rc":[{"batb":[[0,1.84,16.02],[1,1.83,56],[2,1.74,17.32]],"ltp":2.2,"tv":36.6,"id":40380900},{"batb":[[0,1.84,10],[1,1.83,16.2],[2,1.82,333]],"ltp":1.83,"tv":243.18,"id":40296818}]}]}
{"op":"mcm","clk":"11778017059","pt":1722726320997,"mc":[{"id":"1.231397068","rc":[{"batb":[[0,1.85,10],[1,1.84,16.02],[2,1.83,56]],"ltp":2.2,"tv":36.6,"id":40380900},{"batb":[[0,1.83,16.2],[1,1.82,333],[2,1.74,17.32]],"ltp":1.83,"tv":243.18,"id":40296818}]}]}
{"op":"mcm","clk":"11778017297","pt":1722726324421,"mc":[{"id":"1.231397068","rc":[{"batb":[[0,1.84,16.02],[1,1.83,56],[2,1.74,17.32]],"ltp":2.2,"tv":36.6,"id":40380900}]}]}
{"op":"mcm","clk":"11778017314","pt":1722726324580,"mc":[{"id":"1.231397068","rc":[{"batb":[[0,1.84,10],[1,1.83,16.2],[2,1.82,333]],"ltp":1.83,"tv":243.18,"id":40296818}]}]}
{"op":"mcm","clk":"11778017605","pt":1722726328105,"mc":[{"id":"1.231397068","rc":[{"batb":[[0,1.85,10],[1,1.84,16.02],[2,1.83,56]],"ltp":2.2,"tv":36.6,"id":40380900},{"batb":[[0,1.83,16.2],[1,1.82,333],[2,1.74,17.32]],"ltp":1.83,"tv":243.18,"id":40296818}]}]}
{"op":"mcm","clk":"11778017888","pt":1722726331581,"mc":[{"id":"1.231397068","rc":[{"batb":[[0,1.84,16.02],[1,1.83,56],[2,1.74,17.32]],"ltp":2.2,"tv":36.6,"id":40380900},{"batb":[[0,1.84,10],[1,1.83,16.2],[2,1.82,333]],"ltp":1.83,"tv":243.18,"id":40296818}]}]}
{"op":"mcm","clk":"11778018159","pt":1722726335210,"mc":[{"id":"1.231397068","rc":[{"batb":[[0,1.85,10],[1,1.84,16.02],[2,1.83,56]],"ltp":2.2,"tv":36.6,"id":40380900},{"batb":[[0,1.83,16.2],[1,1.82,333],[2,1.74,17.32]],"ltp":1.83,"tv":243.18,"id":40296818}]}]}
{"op":"mcm","clk":"11778018412","pt":1722726338687,"mc":[{"id":"1.231397068","rc":[{"batb":[[0,1.84,16.02],[1,1.83,56],[2,1.74,17.32]],"ltp":2.2,"tv":36.6,"id":40380900},{"batb":[[0,1.84,10],[1,1.83,16.2],[2,1.82,333]],"ltp":1.83,"tv":243.18,"id":40296818}]}]}
{"op":"mcm","clk":"11778018678","pt":1722726342315,"mc":[{"id":"1.231397068","rc":[{"batb":[[0,1.85,10],[1,1.84,16.02],[2,1.83,56]],"ltp":2.2,"tv":36.6,"id":40380900},{"batb":[[0,1.83,16.2],[1,1.82,333],[2,1.74,17.32]],"ltp":1.83,"tv":243.18,"id":40296818}]}]}
{"op":"mcm","clk":"11778018936","pt":1722726345679,"mc":[{"id":"1.231397068","rc":[{"batb":[[0,1.84,16.02],[1,1.83,56],[2,1.74,17.32]],"ltp":2.2,"tv":36.6,"id":40380900},{"batb":[[0,1.84,10],[1,1.83,16.2],[2,1.82,333]],"ltp":1.83,"tv":243.18,"id":40296818}]}]}
{"op":"mcm","clk":"11778019194","pt":1722726349208,"mc":[{"id":"1.231397068","rc":[{"batb":[[0,1.85,10],[1,1.84,16.02],[2,1.83,56]],"ltp":2.2,"tv":36.6,"id":40380900},{"batb":[[0,1.83,16.2],[1,1.82,333],[2,1.74,17.32]],"ltp":1.83,"tv":243.18,"id":40296818}]}]}
{"op":"mcm","clk":"11778019476","pt":1722726352837,"mc":[{"id":"1.231397068","rc":[{"batb":[[0,1.84,16.02],[1,1.83,56],[2,1.74,17.32]],"ltp":2.2,"tv":36.6,"id":40380900},{"batb":[[0,1.84,10],[1,1.83,16.2],[2,1.82,333]],"ltp":1.83,"tv":243.18,"id":40296818}]}]}
{"op":"mcm","clk":"11778019718","pt":1722726356206,"mc":[{"id":"1.231397068","rc":[{"batb":[[0,1.85,10],[1,1.84,16.02],[2,1.83,56]],"ltp":2.2,"tv":36.6,"id":40380900},{"batb":[[0,1.83,16.2],[1,1.82,333],[2,1.74,17.32]],"ltp":1.83,"tv":243.18,"id":40296818}]}]}
{"op":"mcm","clk":"11778019947","pt":1722726359626,"mc":[{"id":"1.231397068","rc":[{"batb":[[0,1.84,16.02],[1,1.83,56],[2,1.74,17.32]],"ltp":2.2,"tv":36.6,"id":40380900},{"batb":[[0,1.84,10],[1,1.83,16.2],[2,1.82,333]],"ltp":1.83,"tv":243.18,"id":40296818}]}]}
{"op":"mcm","clk":"11778020180","pt":1722726363103,"mc":[{"id":"1.231397068","rc":[{"batb":[[0,1.85,10],[1,1.84,16.02],[2,1.83,56]],"ltp":2.2,"tv":36.6,"id":40380900},{"batb":[[0,1.83,16.2],[1,1.82,333],[2,1.74,17.32]],"ltp":1.83,"tv":243.18,"id":40296818}]}]}
{"op":"mcm","clk":"11778020419","pt":1722726366423,"mc":[{"id":"1.231397068","rc":[{"batb":[[0,1.84,16.02],[1,1.83,56],[2,1.74,17.32]],"ltp":2.2,"tv":36.6,"id":40380900}]}]}
{"op":"mcm","clk":"11778020434","pt":1722726366627,"mc":[{"id":"1.231397068","rc":[{"batb":[[0,1.84,10],[1,1.83,16.2],[2,1.82,333]],"ltp":1.83,"tv":243.18,"id":40296818}]}]}
{"op":"mcm","clk":"11778020650","pt":1722726369937,"mc":[{"id":"1.231397068","rc":[{"batb":[[0,1.85,10],[1,1.84,16.02],[2,1.83,56]],"ltp":2.2,"tv":36.6,"id":40380900},{"batb":[[0,1.83,16.2],[1,1.82,333],[2,1.74,17.32]],"ltp":1.83,"tv":243.18,"id":40296818}]}]}
{"op":"mcm","clk":"11778020926","pt":1722726373404,"mc":[{"id":"1.231397068","rc":[{"batb":[[0,1.84,16.02],[1,1.83,56],[2,1.74,17.32]],"ltp":2.2,"tv":36.6,"id":40380900}]}]}
{"op":"mcm","clk":"11778020933","pt":1722726373511,"mc":[{"id":"1.231397068","rc":[{"batb":[[0,1.84,10],[1,1.83,16.2],[2,1.82,333]],"ltp":1.83,"tv":243.18,"id":40296818}]}]}
{"op":"mcm","clk":"11778021152","pt":1722726377031,"mc":[{"id":"1.231397068","rc":[{"batb":[[0,1.85,10],[1,1.84,16.02],[2,1.83,56]],"ltp":2.2,"tv":36.6,"id":40380900},{"batb":[[0,1.83,16.2],[1,1.82,333],[2,1.74,17.32]],"ltp":1.83,"tv":243.18,"id":40296818}]}]}
{"op":"mcm","clk":"11778021407","pt":1722726380350,"mc":[{"id":"1.231397068","rc":[{"batb":[[0,1.84,16.02],[1,1.83,56],[2,1.74,17.32]],"ltp":2.2,"tv":36.6,"id":40380900}]}]}
{"op":"mcm","clk":"11778021421","pt":1722726380553,"mc":[{"id":"1.231397068","rc":[{"batb":[[0,1.84,10],[1,1.83,16.2],[2,1.82,333]],"ltp":1.83,"tv":243.18,"id":40296818}]}]}
{"op":"mcm","clk":"11778021688","pt":1722726384032,"mc":[{"id":"1.231397068","rc":[{"batb":[[0,1.85,10],[1,1.84,16.02],[2,1.83,56]],"ltp":2.2,"tv":36.6,"id":40380900},{"batb":[[0,1.83,16.2],[1,1.82,333],[2,1.74,17.32]],"ltp":1.83,"tv":243.18,"id":40296818}]}]}
{"op":"mcm","clk":"11778021935","pt":1722726387561,"mc":[{"id":"1.231397068","rc":[{"batb":[[0,1.84,16.02],[1,1.83,56],[2,1.74,17.32]],"ltp":2.2,"tv":36.6,"id":40380900},{"batb":[[0,1.84,10],[1,1.83,16.2],[2,1.82,333]],"ltp":1.83,"tv":243.18,"id":40296818}]}]}
{"op":"mcm","clk":"11778022185","pt":1722726390949,"mc":[{"id":"1.231397068","rc":[{"batb":[[0,1.85,10],[1,1.84,16.02],[2,1.83,56]],"ltp":2.2,"tv":36.6,"id":40380900},{"batb":[[0,1.83,16.2],[1,1.82,333],[2,1.74,17.32]],"ltp":1.83,"tv":243.18,"id":40296818}]}]}
{"op":"mcm","clk":"11778022478","pt":1722726394369,"mc":[{"id":"1.231397068","rc":[{"batb":[[0,1.84,16.02],[1,1.83,56],[2,1.74,17.32]],"ltp":2.2,"tv":36.6,"id":40380900},{"batb":[[0,1.84,10],[1,1.83,16.2],[2,1.82,333]],"ltp":1.83,"tv":243.18,"id":40296818}]}]}
{"op":"mcm","clk":"11778022723","pt":1722726397744,"mc":[{"id":"1.231397068","rc":[{"batb":[[0,1.85,10],[1,1.84,16.02],[2,1.83,56]],"ltp":2.2,"tv":36.6,"id":40380900},{"batb":[[0,1.83,16.2],[1,1.82,333],[2,1.74,17.32]],"ltp":1.83,"tv":243.18,"id":40296818}]}]}
{"op":"mcm","clk":"11778022993","pt":1722726401366,"mc":[{"id":"1.231397068","rc":[{"batb":[[0,1.84,16.02],[1,1.83,56],[2,1.74,17.32]],"ltp":2.2,"tv":36.6,"id":40380900},{"batb":[[0,1.84,10],[1,1.83,16.2],[2,1.82,333]],"ltp":1.83,"tv":243.18,"id":40296818}]}]}
{"op":"mcm","clk":"11778023359","pt":1722726404965,"mc":[{"id":"1.231397068","rc":[{"batb":[[0,1.85,10],[1,1.84,16.02],[2,1.83,56]],"ltp":2.2,"tv":36.6,"id":40380900},{"batb":[[0,1.83,16.2],[1,1.82,333],[2,1.74,17.32]],"ltp":1.83,"tv":243.18,"id":40296818}]}]}
{"op":"mcm","clk":"11778023573","pt":1722726408279,"mc":[{"id":"1.231397068","rc":[{"batb":[[0,1.84,16.02],[1,1.83,56],[2,1.74,17.32]],"ltp":2.2,"tv":36.6,"id":40380900},{"batb":[[0,1.84,10],[1,1.83,16.2],[2,1.82,333]],"ltp":1.83,"tv":243.18,"id":40296818}]}]}
{"op":"mcm","clk":"11778023815","pt":1722726411766,"mc":[{"id":"1.231397068","rc":[{"batb":[[0,1.85,10],[1,1.84,16.02],[2,1.83,56]],"ltp":2.2,"tv":36.6,"id":40380900},{"batb":[[0,1.83,16.2],[1,1.82,333],[2,1.74,17.32]],"ltp":1.83,"tv":243.18,"id":40296818}]}]}
{"op":"mcm","clk":"11778024039","pt":1722726415178,"mc":[{"id":"1.231397068","rc":[{"batb":[[0,1.84,16.02],[1,1.83,56],[2,1.74,17.32]],"ltp":2.2,"tv":36.6,"id":40380900},{"batb":[[0,1.84,10],[1,1.83,16.2],[2,1.82,333]],"ltp":1.83,"tv":243.18,"id":40296818}]}]}
{"op":"mcm","clk":"11778024254","pt":1722726418696,"mc":[{"id":"1.231397068","rc":[{"batb":[[0,1.85,10],[1,1.84,16.02],[2,1.83,56]],"ltp":2.2,"tv":36.6,"id":40380900},{"batb":[[0,1.83,16.2],[1,1.82,333],[2,1.74,17.32]],"ltp":1.83,"tv":243.18,"id":40296818}]}]}
{"op":"mcm","clk":"11778024477","pt":1722726422077,"mc":[{"id":"1.231397068","rc":[{"batb":[[0,1.84,16.02],[1,1.83,56],[2,1.74,17.32]],"ltp":2.2,"tv":36.6,"id":40380900},{"batb":[[0,1.84,10],[1,1.83,16.2],[2,1.82,333]],"ltp":1.83,"tv":243.18,"id":40296818}]}]}
{"op":"mcm","clk":"11778024704","pt":1722726425393,"mc":[{"id":"1.231397068","rc":[{"batb":[[0,1.85,10],[1,1.84,16.02],[2,1.83,56]],"ltp":2.2,"tv":36.6,"id":40380900},{"batb":[[0,1.83,16.2],[1,1.82,333],[2,1.74,17.32]],"ltp":1.83,"tv":243.18,"id":40296818}]}]}
{"op":"mcm","clk":"11778024930","pt":1722726428984,"mc":[{"id":"1.231397068","rc":[{"batb":[[0,1.84,16.02],[1,1.83,56],[2,1.74,17.32]],"ltp":2.2,"tv":36.6,"id":40380900},{"batb":[[0,1.84,10],[1,1.83,16.2],[2,1.82,333]],"ltp":1.83,"tv":243.18,"id":40296818}]}]}
{"op":"mcm","clk":"11778025119","pt":1722726432305,"mc":[{"id":"1.231397068","rc":[{"batb":[[0,1.83,16.2],[1,1.82,333],[2,1.74,17.32]],"ltp":1.83,"tv":243.18,"id":40296818}]}]}
{"op":"mcm","clk":"11778025131","pt":1722726432511,"mc":[{"id":"1.231397068","rc":[{"batb":[[0,1.85,10],[1,1.84,16.02],[2,1.83,56]],"ltp":2.2,"tv":36.6,"id":40380900}]}]}
{"op":"mcm","clk":"11778025346","pt":1722726436244,"mc":[{"id":"1.231397068","rc":[{"batb":[[0,1.84,16.02],[1,1.83,56],[2,1.74,17.32]],"ltp":2.2,"tv":36.6,"id":40380900},{"batb":[[0,1.84,10],[1,1.83,16.2],[2,1.82,333]],"ltp":1.83,"tv":243.18,"id":40296818}]}]}
{"op":"mcm","clk":"11778025594","pt":1722726439818,"mc":[{"id":"1.231397068","rc":[{"batb":[[0,1.85,10],[1,1.84,16.02],[2,1.83,56]],"ltp":2.2,"tv":36.6,"id":40380900},{"batb":[[0,1.83,16.2],[1,1.82,333],[2,1.74,17.32]],"ltp":1.83,"tv":243.18,"id":40296818}]}]}
{"op":"mcm","clk":"11778025860","pt":1722726443308,"mc":[{"id":"1.231397068","rc":[{"batb":[[0,1.84,16.02],[1,1.83,56],[2,1.74,17.32]],"ltp":2.2,"tv":36.6,"id":40380900},{"batb":[[0,1.84,10],[1,1.83,16.2],[2,1.82,333]],"ltp":1.83,"tv":243.18,"id":40296818}]}]}
{"op":"mcm","clk":"11778026232","pt":1722726447041,"mc":[{"id":"1.231397068","rc":[{"batb":[[0,1.85,10],[1,1.84,16.02],[2,1.83,56]],"ltp":2.2,"tv":36.6,"id":40380900},{"batb":[[0,1.83,16.2],[1,1.82,333],[2,1.74,17.32]],"ltp":1.83,"tv":243.18,"id":40296818}]}]}
{"op":"mcm","clk":"11778026396","pt":1722726450309,"mc":[{"id":"1.231397068","rc":[{"batb":[[0,1.84,16.02],[1,1.83,56],[2,1.74,17.32]],"ltp":2.2,"tv":36.6,"id":40380900}]}]}
{"op":"mcm","clk":"11778026405","pt":1722726450519,"mc":[{"id":"1.231397068","rc":[{"batb":[[0,1.84,10],[1,1.83,16.2],[2,1.82,333]],"ltp":1.83,"tv":243.18,"id":40296818}]}]}
{"op":"mcm","clk":"11778026710","pt":1722726454324,"mc":[{"id":"1.231397068","rc":[{"batb":[[0,1.83,16.2],[1,1.82,333],[2,1.74,17.32]],"ltp":1.83,"tv":243.18,"id":40296818}]}]}
{"op":"mcm","clk":"11778026722","pt":1722726454530,"mc":[{"id":"1.231397068","rc":[{"batb":[[0,1.85,10],[1,1.84,16.02],[2,1.83,56]],"ltp":2.2,"tv":36.6,"id":40380900}]}]}
{"op":"mcm","clk":"11778027047","pt":1722726458113,"mc":[{"id":"1.231397068","rc":[{"batb":[[0,1.84,16.02],[1,1.83,56],[2,1.74,17.32]],"ltp":2.2,"tv":36.6,"id":40380900},{"batb":[[0,1.84,10],[1,1.83,16.2],[2,1.82,333]],"ltp":1.83,"tv":243.18,"id":40296818}]}]}
{"op":"mcm","clk":"11778027282","pt":1722726461552,"mc":[{"id":"1.231397068","rc":[{"batb":[[0,1.85,10],[1,1.84,16.02],[2,1.83,56]],"ltp":2.2,"tv":36.6,"id":40380900},{"batb":[[0,1.83,16.2],[1,1.82,333],[2,1.74,17.32]],"ltp":1.83,"tv":243.18,"id":40296818}]}]}
{"op":"mcm","clk":"11778027596","pt":1722726464942,"mc":[{"id":"1.231397068","rc":[{"batb":[[0,1.84,16.02],[1,1.83,56],[2,1.74,17.32]],"ltp":2.2,"tv":36.6,"id":40380900},{"batb":[[0,1.84,10],[1,1.83,16.2],[2,1.82,333]],"ltp":1.83,"tv":243.18,"id":40296818}]}]}
{"op":"mcm","clk":"11778027890","pt":1722726468428,"mc":[{"id":"1.231397068","rc":[{"batb":[[0,1.85,10],[1,1.84,16.02],[2,1.83,56]],"ltp":2.2,"tv":36.6,"id":40380900},{"batb":[[0,1.83,16.2],[1,1.82,333],[2,1.74,17.32]],"ltp":1.83,"tv":243.18,"id":40296818}]}]}
{"op":"mcm","clk":"11778028131","pt":1722726472051,"mc":[{"id":"1.231397068","rc":[{"batb":[[0,1.84,16.02],[1,1.83,56],[2,1.74,17.32]],"ltp":2.2,"tv":36.6,"id":40380900},{"batb":[[0,1.84,10],[1,1.83,16.2],[2,1.82,333]],"ltp":1.83,"tv":243.18,"id":40296818}]}]}
{"op":"mcm","clk":"11778028396","pt":1722726475705,"mc":[{"id":"1.231397068","rc":[{"batb":[[0,1.85,10],[1,1.84,16.02],[2,1.83,56]],"ltp":2.2,"tv":36.6,"id":40380900},{"batb":[[0,1.83,16.2],[1,1.82,333],[2,1.74,17.32]],"ltp":1.83,"tv":243.18,"id":40296818}]}]}
{"op":"mcm","clk":"11778028640","pt":1722726479072,"mc":[{"id":"1.231397068","rc":[{"batb":[[0,1.84,16.02],[1,1.83,56],[2,1.74,17.32]],"ltp":2.2,"tv":36.6,"id":40380900},{"batb":[[0,1.84,10],[1,1.83,16.2],[2,1.82,333]],"ltp":1.83,"tv":243.18,"id":40296818}]}]}
{"op":"mcm","clk":"11778028901","pt":1722726482654,"mc":[{"id":"1.231397068","rc":[{"batb":[[0,1.85,10],[1,1.84,16.02],[2,1.83,56]],"ltp":2.2,"tv":36.6,"id":40380900},{"batb":[[0,1.83,16.2],[1,1.82,333],[2,1.74,17.32]],"ltp":1.83,"tv":243.18,"id":40296818}]}]}
{"op":"mcm","clk":"11778029163","pt":1722726486187,"mc":[{"id":"1.231397068","rc":[{"batb":[[0,1.84,16.02],[1,1.83,56],[2,1.74,17.32]],"ltp":2.2,"tv":36.6,"id":40380900},{"batb":[[0,1.84,10],[1,1.83,16.2],[2,1.82,333]],"ltp":1.83,"tv":243.18,"id":40296818}]}]}
{"op":"mcm","clk":"11778029420","pt":1722726489663,"mc":[{"id":"1.231397068","rc":[{"batb":[[0,1.85,10],[1,1.84,16.02],[2,1.83,56]],"ltp":2.2,"tv":36.6,"id":40380900},{"batb":[[0,1.83,16.2],[1,1.82,333],[2,1.74,17.32]],"ltp":1.83,"tv":243.18,"id":40296818}]}]}
{"op":"mcm","clk":"11778029648","pt":1722726493293,"mc":[{"id":"1.231397068","rc":[{"batb":[[0,1.84,16.02],[1,1.83,56],[2,1.74,17.32]],"ltp":2.2,"tv":36.6,"id":40380900},{"batb":[[0,1.84,10],[1,1.83,16.2],[2,1.82,333]],"ltp":1.83,"tv":243.18,"id":40296818}]}]}
{"op":"mcm","clk":"11778029888","pt":1722726496767,"mc":[{"id":"1.231397068","rc":[{"batb":[[0,1.85,10],[1,1.84,16.02],[2,1.83,56]],"ltp":2.2,"tv":36.6,"id":40380900},{"batb":[[0,1.83,16.2],[1,1.82,333],[2,1.74,17.32]],"ltp":1.83,"tv":243.18,"id":40296818}]}]}
{"op":"mcm","clk":"11778030131","pt":1722726500302,"mc":[{"id":"1.231397068","rc":[{"batb":[[0,1.84,16.02],[1,1.83,56],[2,1.74,17.32]],"ltp":2.2,"tv":36.6,"id":40380900},{"batb":[[0,1.84,10],[1,1.83,16.2],[2,1.82,333]],"ltp":1.83,"tv":243.18,"id":40296818}]}]}
{"op":"mcm","clk":"11778030422","pt":1722726503791,"mc":[{"id":"1.231397068","rc":[{"batb":[[0,1.85,10],[1,1.84,16.02],[2,1.83,56]],"ltp":2.2,"tv":36.6,"id":40380900},{"batb":[[0,1.83,16.2],[1,1.82,333],[2,1.74,17.32]],"ltp":1.83,"tv":243.18,"id":40296818}]}]}
{"op":"mcm","clk":"11778030667","pt":1722726507276,"mc":[{"id":"1.231397068","rc":[{"batb":[[0,1.84,16.02],[1,1.83,56],[2,1.74,17.32]],"ltp":2.2,"tv":36.6,"id":40380900}]}]}
{"op":"mcm","clk":"11778030681","pt":1722726507487,"mc":[{"id":"1.231397068","rc":[{"batb":[[0,1.84,10],[1,1.83,16.2],[2,1.82,333]],"ltp":1.83,"tv":243.18,"id":40296818}]}]}
{"op":"mcm","clk":"11778030926","pt":1722726511135,"mc":[{"id":"1.231397068","rc":[{"batb":[[0,1.85,10],[1,1.84,16.02],[2,1.83,56]],"ltp":2.2,"tv":36.6,"id":40380900},{"batb":[[0,1.83,16.2],[1,1.82,333],[2,1.74,17.32]],"ltp":1.83,"tv":243.18,"id":40296818}]}]}
{"op":"mcm","clk":"11778031235","pt":1722726514615,"mc":[{"id":"1.231397068","rc":[{"batb":[[0,1.84,16.02],[1,1.83,56],[2,1.74,17.32]],"ltp":2.2,"tv":36.6,"id":40380900},{"batb":[[0,1.84,10],[1,1.83,16.2],[2,1.82,333]],"ltp":1.83,"tv":243.18,"id":40296818}]}]}
{"op":"mcm","clk":"11778031456","pt":1722726518142,"mc":[{"id":"1.231397068","rc":[{"batb":[[0,1.85,10],[1,1.84,16.02],[2,1.83,56]],"ltp":2.2,"tv":36.6,"id":40380900},{"batb":[[0,1.83,16.2],[1,1.82,333],[2,1.74,17.32]],"ltp":1.83,"tv":243.18,"id":40296818}]}]}
{"op":"mcm","clk":"11778031669","pt":1722726521339,"mc":[{"id":"1.231397068","rc":[{"batb":[[0,1.84,16.02],[1,1.83,56],[2,1.74,17.32]],"ltp":2.2,"tv":36.6,"id":40380900}]}]}
{"op":"mcm","clk":"11778031686","pt":1722726521550,"mc":[{"id":"1.231397068","rc":[{"batb":[[0,1.84,10],[1,1.83,16.2],[2,1.82,333]],"ltp":1.83,"tv":243.18,"id":40296818}]}]}
{"op":"mcm","clk":"11778031964","pt":1722726525269,"mc":[{"id":"1.231397068","rc":[{"batb":[[0,1.85,10],[1,1.84,16.02],[2,1.83,56]],"ltp":2.2,"tv":36.6,"id":40380900},{"batb":[[0,1.83,16.2],[1,1.82,333],[2,1.74,17.32]],"ltp":1.83,"tv":243.18,"id":40296818}]}]}
{"op":"mcm","clk":"11778032238","pt":1722726528736,"mc":[{"id":"1.231397068","rc":[{"batb":[[0,1.84,16.02],[1,1.83,56],[2,1.74,17.32]],"ltp":2.2,"tv":36.6,"id":40380900},{"batb":[[0,1.84,10],[1,1.83,16.2],[2,1.82,333]],"ltp":1.83,"tv":243.18,"id":40296818}]}]}
{"op":"mcm","clk":"11778032496","pt":1722726532255,"mc":[{"id":"1.231397068","rc":[{"batb":[[0,1.85,10],[1,1.84,16.02],[2,1.83,56]],"ltp":2.2,"tv":36.6,"id":40380900},{"batb":[[0,1.83,16.2],[1,1.82,333],[2,1.74,17.32]],"ltp":1.83,"tv":243.18,"id":40296818}]}]}
{"op":"mcm","clk":"11778032706","pt":1722726535868,"mc":[{"id":"1.231397068","rc":[{"batb":[[0,1.84,16.02],[1,1.83,56],[2,1.74,17.32]],"ltp":2.2,"tv":36.6,"id":40380900},{"batb":[[0,1.84,10],[1,1.83,16.2],[2,1.82,333]],"ltp":1.83,"tv":243.18,"id":40296818}]}]}
{"op":"mcm","clk":"11778032910","pt":1722726539333,"mc":[{"id":"1.231397068","rc":[{"batb":[[0,1.83,16.2],[1,1.82,333],[2,1.74,17.32]],"ltp":1.83,"tv":243.18,"id":40296818}]}]}
{"op":"mcm","clk":"11778032914","pt":1722726539436,"mc":[{"id":"1.231397068","rc":[{"batb":[[0,1.85,10],[1,1.84,16.02],[2,1.83,56]],"ltp":2.2,"tv":36.6,"id":40380900}]}]}
{"op":"mcm","clk":"11778033152","pt":1722726543151,"mc":[{"id":"1.231397068","rc":[{"batb":[[0,1.84,16.02],[1,1.83,56],[2,1.74,17.32]],"ltp":2.2,"tv":36.6,"id":40380900},{"batb":[[0,1.84,10],[1,1.83,16.2],[2,1.82,333]],"ltp":1.83,"tv":243.18,"id":40296818}]}]}
{"op":"mcm","clk":"11778033388","pt":1722726546735,"mc":[{"id":"1.231397068","rc":[{"batb":[[0,1.85,10],[1,1.84,16.02],[2,1.83,56]],"ltp":2.2,"tv":36.6,"id":40380900},{"batb":[[0,1.83,16.2],[1,1.82,333],[2,1.74,17.32]],"ltp":1.83,"tv":243.18,"id":40296818}]}]}
{"op":"mcm","clk":"11778033611","pt":1722726550219,"mc":[{"id":"1.231397068","rc":[{"batb":[[0,1.84,16.02],[1,1.83,56],[2,1.74,17.32]],"ltp":2.2,"tv":36.6,"id":40380900},{"batb":[[0,1.84,10],[1,1.83,16.2],[2,1.82,333]],"ltp":1.83,"tv":243.18,"id":40296818}]}]}
{"op":"mcm","clk":"11778033852","pt":1722726553642,"mc":[{"id":"1.231397068","rc":[{"batb":[[0,1.85,10],[1,1.84,16.02],[2,1.83,56]],"ltp":2.2,"tv":36.6,"id":40380900},{"batb":[[0,1.83,16.2],[1,1.82,333],[2,1.74,17.32]],"ltp":1.83,"tv":243.18,"id":40296818}]}]}
{"op":"mcm","clk":"11778034101","pt":1722726557219,"mc":[{"id":"1.231397068","rc":[{"batb":[[0,1.84,16.02],[1,1.83,56],[2,1.74,17.32]],"ltp":2.2,"tv":36.6,"id":40380900},{"batb":[[0,1.84,10],[1,1.83,16.2],[2,1.82,333]],"ltp":1.83,"tv":243.18,"id":40296818}]}]}
{"op":"mcm","clk":"11778034330","pt":1722726560938,"mc":[{"id":"1.231397068","rc":[{"batb":[[0,1.85,10],[1,1.84,16.02],[2,1.83,56]],"ltp":2.2,"tv":36.6,"id":40380900},{"batb":[[0,1.83,16.2],[1,1.82,333],[2,1.74,17.32]],"ltp":1.83,"tv":243.18,"id":40296818}]}]}
{"op":"mcm","clk":"11778034454","pt":1722726563043,"mc":[{"id":"1.231397068","rc":[{"batb":[[0,1.84,10],[1,1.83,16.2],[2,1.82,333]],"ltp":1.83,"tv":243.18,"id":40296818}]}]}
{"op":"mcm","clk":"11778034528","pt":1722726564436,"mc":[{"id":"1.231397068","rc":[{"batb":[[0,1.84,16.02],[1,1.83,56],[2,1.74,17.32]],"ltp":2.2,"tv":36.6,"id":40380900}]}]}
{"op":"mcm","clk":"11778034731","pt":1722726566264,"mc":[{"id":"1.231397068","rc":[{"batb":[[0,1.83,16.2],[1,1.82,333],[2,1.74,17.32]],"ltp":1.83,"tv":243.18,"id":40296818}]}]}
{"op":"mcm","clk":"11778035064","pt":1722726571235,"mc":[{"id":"1.231397068","rc":[{"batb":[[0,1.85,10],[1,1.84,16.02],[2,1.83,56]],"ltp":2.2,"tv":36.6,"id":40380900},{"batb":[[0,1.84,10],[1,1.83,16.2],[2,1.82,333]],"ltp":1.83,"tv":243.18,"id":40296818}]}]}
{"op":"mcm","clk":"11778035386","pt":1722726574868,"mc":[{"id":"1.231397068","rc":[{"batb":[[0,1.84,16.02],[1,1.83,56],[2,1.74,17.32]],"ltp":2.2,"tv":36.6,"id":40380900},{"batb":[[0,1.83,16.2],[1,1.82,333],[2,1.74,17.32]],"ltp":1.83,"tv":243.18,"id":40296818}]}]}
{"op":"mcm","clk":"11778036382","pt":1722726587271,"mc":[{"id":"1.231397068","rc":[{"batb":[[0,1.85,10],[1,1.84,16.02],[2,1.83,56]],"ltp":2.2,"tv":36.6,"id":40380900},{"batb":[[0,1.84,10],[1,1.83,16.2],[2,1.82,333]],"ltp":1.83,"tv":243.18,"id":40296818}]}]}
{"op":"mcm","clk":"11778036658","pt":1722726590656,"mc":[{"id":"1.231397068","rc":[{"batb":[[0,1.84,16.02],[1,1.83,56],[2,1.74,17.32]],"ltp":2.2,"tv":36.6,"id":40380900},{"batb":[[0,1.83,16.2],[1,1.82,333],[2,1.74,17.32]],"ltp":1.83,"tv":243.18,"id":40296818}]}]}
{"op":"mcm","clk":"11778036865","pt":1722726593499,"mc":[{"id":"1.231397068","rc":[{"batb":[[0,1.85,10],[1,1.84,16.02],[2,1.83,56]],"ltp":2.2,"tv":36.6,"id":40380900},{"batb":[[0,1.84,10],[1,1.83,16.2],[2,1.82,333]],"ltp":1.83,"tv":243.18,"id":40296818}]}]}
{"op":"mcm","clk":"11778037154","pt":1722726596976,"mc":[{"id":"1.231397068","rc":[{"batb":[[0,1.84,16.02],[1,1.83,56],[2,1.74,17.32]],"ltp":2.2,"tv":36.6,"id":40380900},{"batb":[[0,1.83,16.2],[1,1.82,333],[2,1.74,17.32]],"ltp":1.83,"tv":243.18,"id":40296818}]}]}
{"op":"mcm","clk":"11778040294","pt":1722726635117,"mc":[{"id":"1.231397068","rc":[{"batb":[[0,1.85,10],[1,1.84,16.02],[2,1.83,56]],"ltp":2.2,"tv":36.6,"id":40380900},{"batb":[[0,1.84,10],[1,1.83,16.2],[2,1.82,333]],"ltp":1.83,"tv":243.18,"id":40296818}]}]}
{"op":"mcm","clk":"11778040575","pt":1722726638450,"mc":[{"id":"1.231397068","rc":[{"batb":[[0,1.84,16.02],[1,1.83,56],[2,1.74,17.32]],"ltp":2.2,"tv":36.6,"id":40380900},{"batb":[[0,1.83,16.2],[1,1.82,333],[2,1.74,17.32]],"ltp":1.83,"tv":243.18,"id":40296818}]}]}
{"op":"mcm","clk":"11778042440","pt":1722726663340,"mc":[{"id":"1.231397068","rc":[{"batb":[[0,1.85,10],[1,1.84,16.02],[2,1.83,56]],"ltp":2.2,"tv":36.6,"id":40380900},{"batb":[[0,1.84,10],[1,1.83,16.2],[2,1.82,333]],"ltp":1.83,"tv":243.18,"id":40296818}]}]}
{"op":"mcm","clk":"11778042678","pt":1722726666774,"mc":[{"id":"1.231397068","rc":[{"batb":[[0,1.84,16.02],[1,1.83,56],[2,1.74,17.32]],"ltp":2.2,"tv":36.6,"id":40380900},{"batb":[[0,1.83,16.2],[1,1.82,333],[2,1.74,17.32]],"ltp":1.83,"tv":243.18,"id":40296818}]}]}
{"op":"mcm","clk":"11778045887","pt":1722726708916,"mc":[{"id":"1.231397068","rc":[{"batb":[[0,1.85,10],[1,1.84,16.02],[2,1.83,56]],"ltp":2.2,"tv":36.6,"id":40380900},{"batb":[[0,1.84,10],[1,1.83,16.2],[2,1.82,333]],"ltp":1.83,"tv":243.18,"id":40296818}]}]}
{"op":"mcm","clk":"11778046149","pt":1722726712190,"mc":[{"id":"1.231397068","rc":[{"batb":[[0,1.84,16.02],[1,1.83,56],[2,1.74,17.32]],"ltp":2.2,"tv":36.6,"id":40380900},{"batb":[[0,1.83,16.2],[1,1.82,333],[2,1.74,17.32]],"ltp":1.83,"tv":243.18,"id":40296818}]}]}
{"op":"mcm","clk":"11778064929","pt":1722726962549,"mc":[{"id":"1.231397068","rc":[{"batb":[[0,1.85,10],[1,1.84,16.02],[2,1.83,56]],"ltp":2.2,"tv":36.6,"id":40380900},{"batb":[[0,1.84,10],[1,1.83,16.2],[2,1.82,333]],"ltp":1.83,"tv":243.18,"id":40296818}]}]}
{"op":"mcm","clk":"11778065156","pt":1722726965893,"mc":[{"id":"1.231397068","rc":[{"batb":[[0,1.84,16.02],[1,1.83,56],[2,1.74,17.32]],"ltp":2.2,"tv":36.6,"id":40380900},{"batb":[[0,1.83,16.2],[1,1.82,333],[2,1.74,17.32]],"ltp":1.83,"tv":243.18,"id":40296818}]}]}
{"op":"mcm","clk":"11778077719","pt":1722727123068,"mc":[{"id":"1.231397068","rc":[{"batb":[[0,1.85,10],[1,1.84,16.02],[2,1.83,56]],"ltp":2.2,"tv":36.6,"id":40380900},{"trd":[[1.83,221]],"batb":[[0,1.84,10],[1,1.83,15.69],[2,1.82,333]],"ltp":1.83,"tv":244.2,"id":40296818}],"tv":280.8}]}
{"op":"mcm","clk":"11778077954","pt":1722727126337,"mc":[{"id":"1.231397068","rc":[{"batb":[[0,1.84,16.02],[1,1.83,56],[2,1.74,17.32]],"ltp":2.2,"tv":36.6,"id":40380900},{"batb":[[0,1.83,15.69],[1,1.82,333],[2,1.74,17.32]],"ltp":1.83,"tv":244.2,"id":40296818}]}]}
{"op":"mcm","clk":"11778112715","pt":1722727559197,"mc":[{"id":"1.231397068","rc":[{"batb":[[0,1.85,10],[1,1.84,16.02],[2,1.83,56]],"ltp":2.2,"tv":36.6,"id":40380900},{"batb":[[0,1.84,10],[1,1.83,15.69],[2,1.82,333]],"ltp":1.83,"tv":244.2,"id":40296818}]}]}
{"op":"mcm","clk":"11778112972","pt":1722727562498,"mc":[{"id":"1.231397068","rc":[{"batb":[[0,1.84,16.02],[1,1.83,56],[2,1.74,17.32]],"ltp":2.2,"tv":36.6,"id":40380900},{"batb":[[0,1.83,15.69],[1,1.82,333],[2,1.74,17.32]],"ltp":1.83,"tv":244.2,"id":40296818}]}]}
{"op":"mcm","clk":"11778113195","pt":1722727565394,"mc":[{"id":"1.231397068","rc":[{"batb":[[0,1.85,10],[1,1.84,16.02],[2,1.83,56]],"ltp":2.2,"tv":36.6,"id":40380900},{"batb":[[0,1.84,10],[1,1.83,15.69],[2,1.82,333]],"ltp":1.83,"tv":244.2,"id":40296818}]}]}
{"op":"mcm","clk":"11778113457","pt":1722727568917,"mc":[{"id":"1.231397068","rc":[{"batb":[[0,1.84,16.02],[1,1.83,56],[2,1.74,17.32]],"ltp":2.2,"tv":36.6,"id":40380900},{"batb":[[0,1.83,15.69],[1,1.82,333],[2,1.74,17.32]],"ltp":1.83,"tv":244.2,"id":40296818}]}]}
{"op":"mcm","clk":"11778113632","pt":1722727571194,"mc":[{"id":"1.231397068","rc":[{"batb":[[0,1.85,10],[1,1.84,16.02],[2,1.83,56]],"ltp":2.2,"tv":36.6,"id":40380900},{"batb":[[0,1.84,10],[1,1.83,15.69],[2,1.82,333]],"ltp":1.83,"tv":244.2,"id":40296818}]}]}
{"op":"mcm","clk":"11778113885","pt":1722727574604,"mc":[{"id":"1.231397068","rc":[{"batb":[[0,1.84,16.02],[1,1.83,56],[2,1.74,17.32]],"ltp":2.2,"tv":36.6,"id":40380900},{"batb":[[0,1.83,15.69],[1,1.82,333],[2,1.74,17.32]],"ltp":1.83,"tv":244.2,"id":40296818}]}]}
{"op":"mcm","clk":"11778114115","pt":1722727577663,"mc":[{"id":"1.231397068","rc":[{"batb":[[0,1.85,10],[1,1.84,16.02],[2,1.83,56]],"ltp":2.2,"tv":36.6,"id":40380900},{"batb":[[0,1.84,10],[1,1.83,15.69],[2,1.82,333]],"ltp":1.83,"tv":244.2,"id":40296818}]}]}
{"op":"mcm","clk":"11778114356","pt":1722727581111,"mc":[{"id":"1.231397068","rc":[{"batb":[[0,1.84,16.02],[1,1.83,56],[2,1.74,17.32]],"ltp":2.2,"tv":36.6,"id":40380900},{"batb":[[0,1.83,15.69],[1,1.82,333],[2,1.74,17.32]],"ltp":1.83,"tv":244.2,"id":40296818}]}]}
{"op":"mcm","clk":"11778114731","pt":1722727585568,"mc":[{"id":"1.231397068","rc":[{"batb":[[0,1.85,10],[1,1.84,16.02],[2,1.83,56]],"ltp":2.2,"tv":36.6,"id":40380900},{"batb":[[0,1.84,10],[1,1.83,15.69],[2,1.82,333]],"ltp":1.83,"tv":244.2,"id":40296818}]}]}
{"op":"mcm","clk":"11778115012","pt":1722727588980,"mc":[{"id":"1.231397068","rc":[{"batb":[[0,1.84,16.02],[1,1.83,56],[2,1.74,17.32]],"ltp":2.2,"tv":36.6,"id":40380900},{"batb":[[0,1.83,15.69],[1,1.82,333],[2,1.74,17.32]],"ltp":1.83,"tv":244.2,"id":40296818}]}]}
{"op":"mcm","clk":"11778115240","pt":1722727592132,"mc":[{"id":"1.231397068","rc":[{"batb":[[0,1.85,10],[1,1.84,16.02],[2,1.83,56]],"ltp":2.2,"tv":36.6,"id":40380900},{"batb":[[0,1.84,10],[1,1.83,15.69],[2,1.82,333]],"ltp":1.83,"tv":244.2,"id":40296818}]}]}
{"op":"mcm","clk":"11778115499","pt":1722727595545,"mc":[{"id":"1.231397068","rc":[{"batb":[[0,1.84,16.02],[1,1.83,56],[2,1.74,17.32]],"ltp":2.2,"tv":36.6,"id":40380900},{"batb":[[0,1.83,15.69],[1,1.82,333],[2,1.74,17.32]],"ltp":1.83,"tv":244.2,"id":40296818}]}]}
{"op":"mcm","clk":"11778115665","pt":1722727598173,"mc":[{"id":"1.231397068","rc":[{"batb":[[0,1.85,10],[1,1.84,16.02],[2,1.83,56]],"ltp":2.2,"tv":36.6,"id":40380900},{"batb":[[0,1.84,10],[1,1.83,15.69],[2,1.82,333]],"ltp":1.83,"tv":244.2,"id":40296818}]}]}
{"op":"mcm","clk":"11778115870","pt":1722727601576,"mc":[{"id":"1.231397068","rc":[{"batb":[[0,1.84,16.02],[1,1.83,56],[2,1.74,17.32]],"ltp":2.2,"tv":36.6,"id":40380900},{"batb":[[0,1.83,15.69],[1,1.82,333],[2,1.74,17.32]],"ltp":1.83,"tv":244.2,"id":40296818}]}]}
{"op":"mcm","clk":"11778116069","pt":1722727604261,"mc":[{"id":"1.231397068","rc":[{"batb":[[0,1.85,10],[1,1.84,16.02],[2,1.83,56]],"ltp":2.2,"tv":36.6,"id":40380900},{"batb":[[0,1.84,10],[1,1.83,15.69],[2,1.82,333]],"ltp":1.83,"tv":244.2,"id":40296818}]}]}
{"op":"mcm","clk":"11778116311","pt":1722727607667,"mc":[{"id":"1.231397068","rc":[{"batb":[[0,1.84,16.02],[1,1.83,56],[2,1.74,17.32]],"ltp":2.2,"tv":36.6,"id":40380900},{"batb":[[0,1.83,15.69],[1,1.82,333],[2,1.74,17.32]],"ltp":1.83,"tv":244.2,"id":40296818}]}]}
{"op":"mcm","clk":"11778116459","pt":1722727610097,"mc":[{"id":"1.231397068","rc":[{"batb":[[0,1.85,10],[1,1.84,16.02],[2,1.83,56]],"ltp":2.2,"tv":36.6,"id":40380900},{"batb":[[0,1.84,10],[1,1.83,15.69],[2,1.82,333]],"ltp":1.83,"tv":244.2,"id":40296818}]}]}
{"op":"mcm","clk":"11778116717","pt":1722727613345,"mc":[{"id":"1.231397068","rc":[{"batb":[[0,1.84,16.02],[1,1.83,56],[2,1.74,17.32]],"ltp":2.2,"tv":36.6,"id":40380900},{"batb":[[0,1.83,15.69],[1,1.82,333],[2,1.74,17.32]],"ltp":1.83,"tv":244.2,"id":40296818}]}]}
{"op":"mcm","clk":"11778117220","pt":1722727620047,"mc":[{"id":"1.231397068","rc":[{"batb":[[0,1.85,10],[1,1.84,16.02],[2,1.83,56]],"ltp":2.2,"tv":36.6,"id":40380900},{"batb":[[0,1.84,10],[1,1.83,15.69],[2,1.82,333]],"ltp":1.83,"tv":244.2,"id":40296818}]}]}
{"op":"mcm","clk":"11778117474","pt":1722727623606,"mc":[{"id":"1.231397068","rc":[{"batb":[[0,1.84,16.02],[1,1.83,56],[2,1.74,17.32]],"ltp":2.2,"tv":36.6,"id":40380900},{"batb":[[0,1.83,15.69],[1,1.82,333],[2,1.74,17.32]],"ltp":1.83,"tv":244.2,"id":40296818}]}]}
{"op":"mcm","clk":"11778117723","pt":1722727626598,"mc":[{"id":"1.231397068","rc":[{"batb":[[0,1.85,10],[1,1.84,16.02],[2,1.83,56]],"ltp":2.2,"tv":36.6,"id":40380900},{"batb":[[0,1.84,10],[1,1.83,15.69],[2,1.82,333]],"ltp":1.83,"tv":244.2,"id":40296818}]}]}
{"op":"mcm","clk":"11778117965","pt":1722727629900,"mc":[{"id":"1.231397068","rc":[{"batb":[[0,1.84,16.02],[1,1.83,56],[2,1.74,17.32]],"ltp":2.2,"tv":36.6,"id":40380900},{"batb":[[0,1.83,15.69],[1,1.82,333],[2,1.74,17.32]],"ltp":1.83,"tv":244.2,"id":40296818}]}]}
{"op":"mcm","clk":"11778118149","pt":1722727632480,"mc":[{"id":"1.231397068","rc":[{"batb":[[0,1.85,10],[1,1.84,16.02],[2,1.83,56]],"ltp":2.2,"tv":36.6,"id":40380900},{"batb":[[0,1.84,10],[1,1.83,15.69],[2,1.82,333]],"ltp":1.83,"tv":244.2,"id":40296818}]}]}
{"op":"mcm","clk":"11778118359","pt":1722727635784,"mc":[{"id":"1.231397068","rc":[{"batb":[[0,1.84,16.02],[1,1.83,56],[2,1.74,17.32]],"ltp":2.2,"tv":36.6,"id":40380900},{"batb":[[0,1.83,15.69],[1,1.82,333],[2,1.74,17.32]],"ltp":1.83,"tv":244.2,"id":40296818}]}]}
{"op":"mcm","clk":"11778118867","pt":1722727642605,"mc":[{"id":"1.231397068","rc":[{"batb":[[0,1.85,10],[1,1.84,16.02],[2,1.83,56]],"ltp":2.2,"tv":36.6,"id":40380900},{"batb":[[0,1.84,10],[1,1.83,15.69],[2,1.82,333]],"ltp":1.83,"tv":244.2,"id":40296818}]}]}
{"op":"mcm","clk":"11778119115","pt":1722727646019,"mc":[{"id":"1.231397068","rc":[{"batb":[[0,1.84,16.02],[1,1.83,56],[2,1.74,17.32]],"ltp":2.2,"tv":36.6,"id":40380900},{"batb":[[0,1.83,15.69],[1,1.82,333],[2,1.74,17.32]],"ltp":1.83,"tv":244.2,"id":40296818}]}]}
{"op":"mcm","clk":"11778119929","pt":1722727656996,"mc":[{"id":"1.231397068","rc":[{"batb":[[0,1.85,10],[1,1.84,16.02],[2,1.83,56]],"ltp":2.2,"tv":36.6,"id":40380900},{"batb":[[0,1.84,10],[1,1.83,15.69],[2,1.82,333]],"ltp":1.83,"tv":244.2,"id":40296818}]}]}
{"op":"mcm","clk":"11778120178","pt":1722727660320,"mc":[{"id":"1.231397068","rc":[{"batb":[[0,1.84,16.02],[1,1.83,56],[2,1.74,17.32]],"ltp":2.2,"tv":36.6,"id":40380900},{"batb":[[0,1.83,15.69],[1,1.82,333],[2,1.74,17.32]],"ltp":1.83,"tv":244.2,"id":40296818}]}]}
{"op":"mcm","clk":"11778120376","pt":1722727663311,"mc":[{"id":"1.231397068","rc":[{"batb":[[0,1.85,10],[1,1.84,16.02],[2,1.83,56]],"ltp":2.2,"tv":36.6,"id":40380900},{"batb":[[0,1.84,10],[1,1.83,15.69],[2,1.82,333]],"ltp":1.83,"tv":244.2,"id":40296818}]}]}
{"op":"mcm","clk":"11778120680","pt":1722727666828,"mc":[{"id":"1.231397068","rc":[{"batb":[[0,1.84,16.02],[1,1.83,56],[2,1.74,17.32]],"ltp":2.2,"tv":36.6,"id":40380900},{"batb":[[0,1.83,15.69],[1,1.82,333],[2,1.74,17.32]],"ltp":1.83,"tv":244.2,"id":40296818}]}]}
{"op":"mcm","clk":"11778120943","pt":1722727670238,"mc":[{"id":"1.231397068","rc":[{"batb":[[0,1.85,10],[1,1.84,16.02],[2,1.83,56]],"ltp":2.2,"tv":36.6,"id":40380900},{"batb":[[0,1.84,10],[1,1.83,15.69],[2,1.82,333]],"ltp":1.83,"tv":244.2,"id":40296818}]}]}
{"op":"mcm","clk":"11778121184","pt":1722727673620,"mc":[{"id":"1.231397068","rc":[{"batb":[[0,1.84,16.02],[1,1.83,56],[2,1.74,17.32]],"ltp":2.2,"tv":36.6,"id":40380900},{"batb":[[0,1.83,15.69],[1,1.82,333],[2,1.74,17.32]],"ltp":1.83,"tv":244.2,"id":40296818}]}]}
{"op":"mcm","clk":"11778121426","pt":1722727677228,"mc":[{"id":"1.231397068","rc":[{"batb":[[0,1.85,10],[1,1.84,16.02],[2,1.83,56]],"ltp":2.2,"tv":36.6,"id":40380900},{"batb":[[0,1.84,10],[1,1.83,15.69],[2,1.82,333]],"ltp":1.83,"tv":244.2,"id":40296818}]}]}
{"op":"mcm","clk":"11778121677","pt":1722727680652,"mc":[{"id":"1.231397068","rc":[{"batb":[[0,1.84,16.02],[1,1.83,56],[2,1.74,17.32]],"ltp":2.2,"tv":36.6,"id":40380900},{"batb":[[0,1.83,15.69],[1,1.82,333],[2,1.74,17.32]],"ltp":1.83,"tv":244.2,"id":40296818}]}]}
{"op":"mcm","clk":"11778121881","pt":1722727683461,"mc":[{"id":"1.231397068","rc":[{"batb":[[0,1.85,10],[1,1.84,16.02],[2,1.83,56]],"ltp":2.2,"tv":36.6,"id":40380900},{"batb":[[0,1.84,10],[1,1.83,15.69],[2,1.82,333]],"ltp":1.83,"tv":244.2,"id":40296818}]}]}
{"op":"mcm","clk":"11778122147","pt":1722727686833,"mc":[{"id":"1.231397068","rc":[{"batb":[[0,1.84,16.02],[1,1.83,56],[2,1.74,17.32]],"ltp":2.2,"tv":36.6,"id":40380900},{"batb":[[0,1.83,15.69],[1,1.82,333],[2,1.74,17.32]],"ltp":1.83,"tv":244.2,"id":40296818}]}]}
{"op":"mcm","clk":"11778122408","pt":1722727689849,"mc":[{"id":"1.231397068","rc":[{"batb":[[0,1.85,10],[1,1.84,16.02],[2,1.83,56]],"ltp":2.2,"tv":36.6,"id":40380900},{"batb":[[0,1.84,10],[1,1.83,15.69],[2,1.82,333]],"ltp":1.83,"tv":244.2,"id":40296818}]}]}
{"op":"mcm","clk":"11778122673","pt":1722727693268,"mc":[{"id":"1.231397068","rc":[{"batb":[[0,1.84,16.02],[1,1.83,56],[2,1.74,17.32]],"ltp":2.2,"tv":36.6,"id":40380900},{"batb":[[0,1.83,15.69],[1,1.82,333],[2,1.74,17.32]],"ltp":1.83,"tv":244.2,"id":40296818}]}]}
{"op":"mcm","clk":"11778122934","pt":1722727696080,"mc":[{"id":"1.231397068","rc":[{"batb":[[0,1.85,10],[1,1.84,16.02],[2,1.83,56]],"ltp":2.2,"tv":36.6,"id":40380900},{"batb":[[0,1.84,10],[1,1.83,15.69],[2,1.82,333]],"ltp":1.83,"tv":244.2,"id":40296818}]}]}
{"op":"mcm","clk":"11778123166","pt":1722727699353,"mc":[{"id":"1.231397068","rc":[{"batb":[[0,1.84,16.02],[1,1.83,56],[2,1.74,17.32]],"ltp":2.2,"tv":36.6,"id":40380900},{"batb":[[0,1.83,15.69],[1,1.82,333],[2,1.74,17.32]],"ltp":1.83,"tv":244.2,"id":40296818}]}]}
{"op":"mcm","clk":"11778123386","pt":1722727702674,"mc":[{"id":"1.231397068","rc":[{"batb":[[0,1.85,10],[1,1.84,16.02],[2,1.83,56]],"ltp":2.2,"tv":36.6,"id":40380900},{"batb":[[0,1.84,10],[1,1.83,15.69],[2,1.82,333]],"ltp":1.83,"tv":244.2,"id":40296818}]}]}
{"op":"mcm","clk":"11778123587","pt":1722727705989,"mc":[{"id":"1.231397068","rc":[{"batb":[[0,1.84,16.02],[1,1.83,56],[2,1.74,17.32]],"ltp":2.2,"tv":36.6,"id":40380900},{"batb":[[0,1.83,15.69],[1,1.82,333],[2,1.74,17.32]],"ltp":1.83,"tv":244.2,"id":40296818}]}]}
{"op":"mcm","clk":"11778123784","pt":1722727709307,"mc":[{"id":"1.231397068","rc":[{"batb":[[0,1.85,10],[1,1.84,16.02],[2,1.83,56]],"ltp":2.2,"tv":36.6,"id":40380900},{"batb":[[0,1.84,10],[1,1.83,15.69],[2,1.82,333]],"ltp":1.83,"tv":244.2,"id":40296818}]}]}
{"op":"mcm","clk":"11778124079","pt":1722727712676,"mc":[{"id":"1.231397068","rc":[{"batb":[[0,1.84,16.02],[1,1.83,56],[2,1.74,17.32]],"ltp":2.2,"tv":36.6,"id":40380900},{"batb":[[0,1.83,15.69],[1,1.82,333],[2,1.74,17.32]],"ltp":1.83,"tv":244.2,"id":40296818}]}]}
{"op":"mcm","clk":"11778124337","pt":1722727716408,"mc":[{"id":"1.231397068","rc":[{"batb":[[0,1.85,10],[1,1.84,16.02],[2,1.83,56]],"ltp":2.2,"tv":36.6,"id":40380900},{"batb":[[0,1.84,10],[1,1.83,15.69],[2,1.82,333]],"ltp":1.83,"tv":244.2,"id":40296818}]}]}
{"op":"mcm","clk":"11778124582","pt":1722727719916,"mc":[{"id":"1.231397068","rc":[{"batb":[[0,1.84,16.02],[1,1.83,56],[2,1.74,17.32]],"ltp":2.2,"tv":36.6,"id":40380900},{"batb":[[0,1.83,15.69],[1,1.82,333],[2,1.74,17.32]],"ltp":1.83,"tv":244.2,"id":40296818}]}]}
{"op":"mcm","clk":"11778124727","pt":1722727722610,"mc":[{"id":"1.231397068","rc":[{"batb":[[0,1.85,10],[1,1.84,16.02],[2,1.83,56]],"ltp":2.2,"tv":36.6,"id":40380900},{"batb":[[0,1.84,10],[1,1.83,15.69],[2,1.82,333]],"ltp":1.83,"tv":244.2,"id":40296818}]}]}
{"op":"mcm","clk":"11778124928","pt":1722727726019,"mc":[{"id":"1.231397068","rc":[{"batb":[[0,1.84,16.02],[1,1.83,56],[2,1.74,17.32]],"ltp":2.2,"tv":36.6,"id":40380900},{"batb":[[0,1.83,15.69],[1,1.82,333],[2,1.74,17.32]],"ltp":1.83,"tv":244.2,"id":40296818}]}]}
{"op":"mcm","clk":"11778125107","pt":1722727728603,"mc":[{"id":"1.231397068","rc":[{"batb":[[0,1.85,10],[1,1.84,16.02],[2,1.83,56]],"ltp":2.2,"tv":36.6,"id":40380900},{"batb":[[0,1.84,10],[1,1.83,15.69],[2,1.82,333]],"ltp":1.83,"tv":244.2,"id":40296818}]}]}
{"op":"mcm","clk":"11778125314","pt":1722727732013,"mc":[{"id":"1.231397068","rc":[{"batb":[[0,1.84,16.02],[1,1.83,56],[2,1.74,17.32]],"ltp":2.2,"tv":36.6,"id":40380900},{"batb":[[0,1.83,15.69],[1,1.82,333],[2,1.74,17.32]],"ltp":1.83,"tv":244.2,"id":40296818}]}]}
{"op":"mcm","clk":"11778125449","pt":1722727734386,"mc":[{"id":"1.231397068","rc":[{"batb":[[0,1.85,10],[1,1.84,16.02],[2,1.83,56]],"ltp":2.2,"tv":36.6,"id":40380900},{"batb":[[0,1.84,10],[1,1.83,15.69],[2,1.82,333]],"ltp":1.83,"tv":244.2,"id":40296818}]}]}
{"op":"mcm","clk":"11778125697","pt":1722727737790,"mc":[{"id":"1.231397068","rc":[{"batb":[[0,1.84,16.02],[1,1.83,56],[2,1.74,17.32]],"ltp":2.2,"tv":36.6,"id":40380900},{"batb":[[0,1.83,15.69],[1,1.82,333],[2,1.74,17.32]],"ltp":1.83,"tv":244.2,"id":40296818}]}]}
{"op":"mcm","clk":"11778125923","pt":1722727741196,"mc":[{"id":"1.231397068","rc":[{"batb":[[0,1.85,10],[1,1.84,16.02],[2,1.83,56]],"ltp":2.2,"tv":36.6,"id":40380900},{"batb":[[0,1.84,10],[1,1.83,15.69],[2,1.82,333]],"ltp":1.83,"tv":244.2,"id":40296818}]}]}
{"op":"mcm","clk":"11778126158","pt":1722727744517,"mc":[{"id":"1.231397068","rc":[{"batb":[[0,1.84,16.02],[1,1.83,56],[2,1.74,17.32]],"ltp":2.2,"tv":36.6,"id":40380900},{"batb":[[0,1.83,15.69],[1,1.82,333],[2,1.74,17.32]],"ltp":1.83,"tv":244.2,"id":40296818}]}]}
{"op":"mcm","clk":"11778126436","pt":1722727748243,"mc":[{"id":"1.231397068","rc":[{"batb":[[0,1.85,10],[1,1.84,16.02],[2,1.83,56]],"ltp":2.2,"tv":36.6,"id":40380900},{"batb":[[0,1.84,10],[1,1.83,15.69],[2,1.82,333]],"ltp":1.83,"tv":244.2,"id":40296818}]}]}
{"op":"mcm","clk":"11778126652","pt":1722727751644,"mc":[{"id":"1.231397068","rc":[{"batb":[[0,1.84,16.02],[1,1.83,56],[2,1.74,17.32]],"ltp":2.2,"tv":36.6,"id":40380900},{"batb":[[0,1.83,15.69],[1,1.82,333],[2,1.74,17.32]],"ltp":1.83,"tv":244.2,"id":40296818}]}]}
{"op":"mcm","clk":"11778126826","pt":1722727753917,"mc":[{"id":"1.231397068","rc":[{"batb":[[0,1.85,10],[1,1.84,16.02],[2,1.83,56]],"ltp":2.2,"tv":36.6,"id":40380900},{"batb":[[0,1.84,10],[1,1.83,15.69],[2,1.82,333]],"ltp":1.83,"tv":244.2,"id":40296818}]}]}
{"op":"mcm","clk":"11778127043","pt":1722727757319,"mc":[{"id":"1.231397068","rc":[{"batb":[[0,1.84,16.02],[1,1.83,56],[2,1.74,17.32]],"ltp":2.2,"tv":36.6,"id":40380900},{"batb":[[0,1.83,15.69],[1,1.82,333],[2,1.74,17.32]],"ltp":1.83,"tv":244.2,"id":40296818}]}]}
{"op":"mcm","clk":"11778127351","pt":1722727762124,"mc":[{"id":"1.231397068","rc":[{"batb":[[0,1.85,10],[1,1.84,16.02],[2,1.83,56]],"ltp":2.2,"tv":36.6,"id":40380900},{"batb":[[0,1.84,10],[1,1.83,15.69],[2,1.82,333]],"ltp":1.83,"tv":244.2,"id":40296818}]}]}
{"op":"mcm","clk":"11778127551","pt":1722727765538,"mc":[{"id":"1.231397068","rc":[{"batb":[[0,1.84,16.02],[1,1.83,56],[2,1.74,17.32]],"ltp":2.2,"tv":36.6,"id":40380900},{"batb":[[0,1.83,15.69],[1,1.82,333],[2,1.74,17.32]],"ltp":1.83,"tv":244.2,"id":40296818}]}]}
{"op":"mcm","clk":"11778127670","pt":1722727767716,"mc":[{"id":"1.231397068","rc":[{"batb":[[0,1.85,10],[1,1.84,16.02],[2,1.83,56]],"ltp":2.2,"tv":36.6,"id":40380900},{"batb":[[0,1.84,10],[1,1.83,15.69],[2,1.82,333]],"ltp":1.83,"tv":244.2,"id":40296818}]}]}
{"op":"mcm","clk":"11778127894","pt":1722727771235,"mc":[{"id":"1.231397068","rc":[{"batb":[[0,1.84,16.02],[1,1.83,56],[2,1.74,17.32]],"ltp":2.2,"tv":36.6,"id":40380900},{"batb":[[0,1.83,15.69],[1,1.82,333],[2,1.74,17.32]],"ltp":1.83,"tv":244.2,"id":40296818}]}]}
{"op":"mcm","clk":"11778128030","pt":1722727773419,"mc":[{"id":"1.231397068","rc":[{"batb":[[0,1.85,10],[1,1.84,16.02],[2,1.83,56]],"ltp":2.2,"tv":36.6,"id":40380900},{"batb":[[0,1.84,10],[1,1.83,15.69],[2,1.82,333]],"ltp":1.83,"tv":244.2,"id":40296818}]}]}
{"op":"mcm","clk":"11778128235","pt":1722727776837,"mc":[{"id":"1.231397068","rc":[{"batb":[[0,1.84,16.02],[1,1.83,56],[2,1.74,17.32]],"ltp":2.2,"tv":36.6,"id":40380900},{"batb":[[0,1.83,15.69],[1,1.82,333],[2,1.74,17.32]],"ltp":1.83,"tv":244.2,"id":40296818}]}]}
{"op":"mcm","clk":"11778128634","pt":1722727782950,"mc":[{"id":"1.231397068","rc":[{"batb":[[0,1.85,10],[1,1.84,16.02],[2,1.83,56]],"ltp":2.2,"tv":36.6,"id":40380900},{"batb":[[0,1.84,10],[1,1.83,15.69],[2,1.82,333]],"ltp":1.83,"tv":244.2,"id":40296818}]}]}
{"op":"mcm","clk":"11778128870","pt":1722727786383,"mc":[{"id":"1.231397068","rc":[{"batb":[[0,1.84,16.02],[1,1.83,56],[2,1.74,17.32]],"ltp":2.2,"tv":36.6,"id":40380900},{"batb":[[0,1.83,15.69],[1,1.82,333],[2,1.74,17.32]],"ltp":1.83,"tv":244.2,"id":40296818}]}]}
{"op":"mcm","clk":"11778129044","pt":1722727788871,"mc":[{"id":"1.231397068","rc":[{"batb":[[0,1.85,10],[1,1.84,16.02],[2,1.83,56]],"ltp":2.2,"tv":36.6,"id":40380900},{"batb":[[0,1.84,10],[1,1.83,15.69],[2,1.82,333]],"ltp":1.83,"tv":244.2,"id":40296818}]}]}
{"op":"mcm","clk":"11778129278","pt":1722727792145,"mc":[{"id":"1.231397068","rc":[{"batb":[[0,1.84,16.02],[1,1.83,56],[2,1.74,17.32]],"ltp":2.2,"tv":36.6,"id":40380900},{"batb":[[0,1.83,15.69],[1,1.82,333],[2,1.74,17.32]],"ltp":1.83,"tv":244.2,"id":40296818}]}]}
{"op":"mcm","clk":"11778129495","pt":1722727795868,"mc":[{"id":"1.231397068","rc":[{"batb":[[0,1.85,10],[1,1.84,16.02],[2,1.83,56]],"ltp":2.2,"tv":36.6,"id":40380900},{"batb":[[0,1.84,10],[1,1.83,15.69],[2,1.82,333]],"ltp":1.83,"tv":244.2,"id":40296818}]}]}
{"op":"mcm","clk":"11778129714","pt":1722727799284,"mc":[{"id":"1.231397068","rc":[{"batb":[[0,1.84,16.02],[1,1.83,56],[2,1.74,17.32]],"ltp":2.2,"tv":36.6,"id":40380900},{"batb":[[0,1.83,15.69],[1,1.82,333],[2,1.74,17.32]],"ltp":1.83,"tv":244.2,"id":40296818}]}]}
{"op":"mcm","clk":"11778129984","pt":1722727802479,"mc":[{"id":"1.231397068","rc":[{"batb":[[0,1.85,10],[1,1.84,16.02],[2,1.83,56]],"ltp":2.2,"tv":36.6,"id":40380900},{"batb":[[0,1.84,10],[1,1.83,15.69],[2,1.82,333]],"ltp":1.83,"tv":244.2,"id":40296818}]}]}
{"op":"mcm","clk":"11778130335","pt":1722727805881,"mc":[{"id":"1.231397068","rc":[{"batb":[[0,1.84,16.02],[1,1.83,56],[2,1.74,17.32]],"ltp":2.2,"tv":36.6,"id":40380900},{"batb":[[0,1.83,15.69],[1,1.82,333],[2,1.74,17.32]],"ltp":1.83,"tv":244.2,"id":40296818}]}]}
{"op":"mcm","clk":"11778130543","pt":1722727808793,"mc":[{"id":"1.231397068","rc":[{"batb":[[0,1.85,10],[1,1.84,16.02],[2,1.83,56]],"ltp":2.2,"tv":36.6,"id":40380900},{"batb":[[0,1.84,10],[1,1.83,15.69],[2,1.82,333]],"ltp":1.83,"tv":244.2,"id":40296818}]}]}
{"op":"mcm","clk":"11778130804","pt":1722727812078,"mc":[{"id":"1.231397068","rc":[{"batb":[[0,1.84,16.02],[1,1.83,56],[2,1.74,17.32]],"ltp":2.2,"tv":36.6,"id":40380900},{"batb":[[0,1.83,15.69],[1,1.82,333],[2,1.74,17.32]],"ltp":1.83,"tv":244.2,"id":40296818}]}]}
{"op":"mcm","clk":"11778131066","pt":1722727815390,"mc":[{"id":"1.231397068","rc":[{"batb":[[0,1.85,10],[1,1.84,16.02],[2,1.83,56]],"ltp":2.2,"tv":36.6,"id":40380900},{"batb":[[0,1.84,10],[1,1.83,15.69],[2,1.82,333]],"ltp":1.83,"tv":244.2,"id":40296818}]}]}
{"op":"mcm","clk":"11778131324","pt":1722727818665,"mc":[{"id":"1.231397068","rc":[{"batb":[[0,1.84,16.02],[1,1.83,56],[2,1.74,17.32]],"ltp":2.2,"tv":36.6,"id":40380900},{"batb":[[0,1.83,15.69],[1,1.82,333],[2,1.74,17.32]],"ltp":1.83,"tv":244.2,"id":40296818}]}]}
{"op":"mcm","clk":"11778131517","pt":1722727821622,"mc":[{"id":"1.231397068","rc":[{"batb":[[0,1.85,10],[1,1.84,16.02],[2,1.83,56]],"ltp":2.2,"tv":36.6,"id":40380900},{"batb":[[0,1.84,10],[1,1.83,15.69],[2,1.82,333]],"ltp":1.83,"tv":244.2,"id":40296818}]}]}
{"op":"mcm","clk":"11778131724","pt":1722727824884,"mc":[{"id":"1.231397068","rc":[{"batb":[[0,1.84,16.02],[1,1.83,56],[2,1.74,17.32]],"ltp":2.2,"tv":36.6,"id":40380900},{"batb":[[0,1.83,15.69],[1,1.82,333],[2,1.74,17.32]],"ltp":1.83,"tv":244.2,"id":40296818}]}]}
{"op":"mcm","clk":"11778131917","pt":1722727827424,"mc":[{"id":"1.231397068","rc":[{"batb":[[0,1.85,10],[1,1.84,16.02],[2,1.83,56]],"ltp":2.2,"tv":36.6,"id":40380900},{"batb":[[0,1.84,10],[1,1.83,15.69],[2,1.82,333]],"ltp":1.83,"tv":244.2,"id":40296818}]}]}
{"op":"mcm","clk":"11778132148","pt":1722727830794,"mc":[{"id":"1.231397068","rc":[{"batb":[[0,1.84,16.02],[1,1.83,56],[2,1.74,17.32]],"ltp":2.2,"tv":36.6,"id":40380900},{"batb":[[0,1.83,15.69],[1,1.82,333],[2,1.74,17.32]],"ltp":1.83,"tv":244.2,"id":40296818}]}]}
{"op":"mcm","clk":"11778132400","pt":1722727833902,"mc":[{"id":"1.231397068","rc":[{"batb":[[0,1.85,10],[1,1.84,16.02],[2,1.83,56]],"ltp":2.2,"tv":36.6,"id":40380900},{"batb":[[0,1.84,10],[1,1.83,15.69],[2,1.82,333]],"ltp":1.83,"tv":244.2,"id":40296818}]}]}
{"op":"mcm","clk":"11778132669","pt":1722727837324,"mc":[{"id":"1.231397068","rc":[{"batb":[[0,1.84,16.02],[1,1.83,56],[2,1.74,17.32]],"ltp":2.2,"tv":36.6,"id":40380900},{"batb":[[0,1.83,15.69],[1,1.82,333],[2,1.74,17.32]],"ltp":1.83,"tv":244.2,"id":40296818}]}]}
{"op":"mcm","clk":"11778132990","pt":1722727841846,"mc":[{"id":"1.231397068","rc":[{"batb":[[0,1.85,10],[1,1.84,16.02],[2,1.83,56]],"ltp":2.2,"tv":36.6,"id":40380900},{"batb":[[0,1.84,10],[1,1.83,15.69],[2,1.82,333]],"ltp":1.83,"tv":244.2,"id":40296818}]}]}
{"op":"mcm","clk":"11778133206","pt":1722727845011,"mc":[{"id":"1.231397068","rc":[{"batb":[[0,1.84,16.02],[1,1.83,56],[2,1.74,17.32]],"ltp":2.2,"tv":36.6,"id":40380900},{"batb":[[0,1.83,15.69],[1,1.82,333],[2,1.74,17.32]],"ltp":1.83,"tv":244.2,"id":40296818}]}]}
{"op":"mcm","clk":"11778133415","pt":1722727847814,"mc":[{"id":"1.231397068","rc":[{"batb":[[0,1.85,10],[1,1.84,16.02],[2,1.83,56]],"ltp":2.2,"tv":36.6,"id":40380900},{"batb":[[0,1.84,10],[1,1.83,15.69],[2,1.82,333]],"ltp":1.83,"tv":244.2,"id":40296818}]}]}
{"op":"mcm","clk":"11778133547","pt":1722727849425,"mc":[{"id":"1.231397068","rc":[{"batb":[[0,1.85,16.54]],"ltp":2.2,"tv":36.6,"id":40380900},{"batb":[[1,1.83,21.95]],"ltp":1.83,"tv":244.2,"id":40296818}]}]}
{"op":"mcm","clk":"11778133689","pt":1722727851135,"mc":[{"id":"1.231397068","rc":[{"batb":[[0,1.85,6.54]],"ltp":2.2,"tv":36.6,"id":40380900},{"batb":[[0,1.83,21.95],[1,1.82,333],[2,1.74,17.32]],"ltp":1.83,"tv":244.2,"id":40296818}]}]}
{"op":"mcm","clk":"11778133937","pt":1722727854349,"mc":[{"id":"1.231397068","rc":[{"batb":[[0,1.86,10],[1,1.85,6.54],[2,1.84,16.02]],"ltp":2.2,"tv":36.6,"id":40380900},{"batb":[[0,1.84,10],[1,1.83,21.95],[2,1.82,333]],"ltp":1.83,"tv":244.2,"id":40296818}]}]}
{"op":"mcm","clk":"11778134167","pt":1722727857668,"mc":[{"id":"1.231397068","rc":[{"batb":[[0,1.85,6.54],[1,1.84,16.02],[2,1.83,56]],"ltp":2.2,"tv":36.6,"id":40380900},{"batb":[[0,1.83,21.95],[1,1.82,333],[2,1.74,17.32]],"ltp":1.83,"tv":244.2,"id":40296818}]}]}
{"op":"mcm","clk":"11778134421","pt":1722727861159,"mc":[{"id":"1.231397068","rc":[{"batb":[[0,1.86,10],[1,1.85,6.54],[2,1.84,16.02]],"ltp":2.2,"tv":36.6,"id":40380900},{"batb":[[0,1.84,10],[1,1.83,21.95],[2,1.82,333]],"ltp":1.83,"tv":244.2,"id":40296818}]}]}
{"op":"mcm","clk":"11778134733","pt":1722727864546,"mc":[{"id":"1.231397068","rc":[{"batb":[[0,1.85,6.54],[1,1.84,16.02],[2,1.83,56]],"ltp":2.2,"tv":36.6,"id":40380900},{"batb":[[0,1.83,21.95],[1,1.82,333],[2,1.74,17.32]],"ltp":1.83,"tv":244.2,"id":40296818}]}]}
{"op":"mcm","clk":"11778134958","pt":1722727867161,"mc":[{"id":"1.231397068","rc":[{"batb":[[0,1.86,10],[1,1.85,6.54],[2,1.84,16.02]],"ltp":2.2,"tv":36.6,"id":40380900},{"batb":[[0,1.84,10],[1,1.83,21.95],[2,1.82,333]],"ltp":1.83,"tv":244.2,"id":40296818}]}]}
{"op":"mcm","clk":"11778135244","pt":1722727870686,"mc":[{"id":"1.231397068","rc":[{"batb":[[0,1.85,6.54],[1,1.84,16.02],[2,1.83,56]],"ltp":2.2,"tv":36.6,"id":40380900},{"batb":[[0,1.83,21.95],[1,1.82,333],[2,1.74,17.32]],"ltp":1.83,"tv":244.2,"id":40296818}]}]}
{"op":"mcm","clk":"11778135462","pt":1722727873067,"mc":[{"id":"1.231397068","rc":[{"batb":[[0,1.86,10],[1,1.85,6.54],[2,1.84,16.02]],"ltp":2.2,"tv":36.6,"id":40380900},{"batb":[[0,1.84,10],[1,1.83,21.95],[2,1.82,333]],"ltp":1.83,"tv":244.2,"id":40296818}]}]}
{"op":"mcm","clk":"11778135713","pt":1722727876291,"mc":[{"id":"1.231397068","rc":[{"batb":[[0,1.85,6.54],[1,1.84,16.02],[2,1.83,56]],"ltp":2.2,"tv":36.6,"id":40380900},{"batb":[[0,1.83,21.95],[1,1.82,333],[2,1.74,17.32]],"ltp":1.83,"tv":244.2,"id":40296818}]}]}
{"op":"mcm","clk":"11778135908","pt":1722727878942,"mc":[{"id":"1.231397068","rc":[{"batb":[[0,1.86,10],[1,1.85,6.54],[2,1.84,16.02]],"ltp":2.2,"tv":36.6,"id":40380900},{"batb":[[0,1.84,10],[1,1.83,21.95],[2,1.82,333]],"ltp":1.83,"tv":244.2,"id":40296818}]}]}
{"op":"mcm","clk":"11778136192","pt":1722727882367,"mc":[{"id":"1.231397068","rc":[{"batb":[[0,1.85,6.54],[1,1.84,16.02],[2,1.83,56]],"ltp":2.2,"tv":36.6,"id":40380900},{"batb":[[0,1.83,21.95],[1,1.82,333],[2,1.74,17.32]],"ltp":1.83,"tv":244.2,"id":40296818}]}]}
{"op":"mcm","clk":"11778136399","pt":1722727884837,"mc":[{"id":"1.231397068","rc":[{"batb":[[0,1.86,10],[1,1.85,6.54],[2,1.84,16.02]],"ltp":2.2,"tv":36.6,"id":40380900},{"batb":[[0,1.84,10],[1,1.83,21.95],[2,1.82,333]],"ltp":1.83,"tv":244.2,"id":40296818}]}]}
{"op":"mcm","clk":"11778136682","pt":1722727888281,"mc":[{"id":"1.231397068","rc":[{"batb":[[0,1.85,6.54],[1,1.84,16.02],[2,1.83,56]],"ltp":2.2,"tv":36.6,"id":40380900},{"batb":[[0,1.83,21.95],[1,1.82,333],[2,1.74,17.32]],"ltp":1.83,"tv":244.2,"id":40296818}]}]}
{"op":"mcm","clk":"11778137072","pt":1722727892763,"mc":[{"id":"1.231397068","rc":[{"batb":[[0,1.86,10],[1,1.85,6.54],[2,1.84,16.02]],"ltp":2.2,"tv":36.6,"id":40380900},{"batb":[[0,1.84,10],[1,1.83,21.95],[2,1.82,333]],"ltp":1.83,"tv":244.2,"id":40296818}]}]}
{"op":"mcm","clk":"11778137363","pt":1722727896097,"mc":[{"id":"1.231397068","rc":[{"batb":[[0,1.85,6.54],[1,1.84,16.02],[2,1.83,56]],"ltp":2.2,"tv":36.6,"id":40380900},{"batb":[[0,1.83,21.95],[1,1.82,333],[2,1.74,17.32]],"ltp":1.83,"tv":244.2,"id":40296818}]}]}
{"op":"mcm","clk":"11778137657","pt":1722727899570,"mc":[{"id":"1.231397068","rc":[{"batb":[[0,1.86,10],[1,1.85,6.54],[2,1.84,16.02]],"ltp":2.2,"tv":36.6,"id":40380900},{"batb":[[0,1.84,10],[1,1.83,21.95],[2,1.82,333]],"ltp":1.83,"tv":244.2,"id":40296818}]}]}
{"op":"mcm","clk":"11778137893","pt":1722727903085,"mc":[{"id":"1.231397068","rc":[{"batb":[[0,1.85,6.54],[1,1.84,16.02],[2,1.83,56]],"ltp":2.2,"tv":36.6,"id":40380900},{"batb":[[0,1.83,21.95],[1,1.82,333],[2,1.74,17.32]],"ltp":1.83,"tv":244.2,"id":40296818}]}]}
{"op":"mcm","clk":"11778138346","pt":1722727908887,"mc":[{"id":"1.231397068","rc":[{"batb":[[0,1.86,10],[1,1.85,6.54],[2,1.84,16.02]],"ltp":2.2,"tv":36.6,"id":40380900},{"batb":[[0,1.84,10],[1,1.83,21.95],[2,1.82,333]],"ltp":1.83,"tv":244.2,"id":40296818}]}]}
{"op":"mcm","clk":"11778138627","pt":1722727912310,"mc":[{"id":"1.231397068","rc":[{"batb":[[0,1.85,6.54],[1,1.84,16.02],[2,1.83,56]],"ltp":2.2,"tv":36.6,"id":40380900},{"batb":[[0,1.83,21.95],[1,1.82,333],[2,1.74,17.32]],"ltp":1.83,"tv":244.2,"id":40296818}]}]}
{"op":"mcm","clk":"11778138949","pt":1722727915528,"mc":[{"id":"1.231397068","rc":[{"batb":[[0,1.86,10],[1,1.85,6.54],[2,1.84,16.02]],"ltp":2.2,"tv":36.6,"id":40380900},{"batb":[[0,1.84,10],[1,1.83,21.95],[2,1.82,333]],"ltp":1.83,"tv":244.2,"id":40296818}]}]}
{"op":"mcm","clk":"11778139226","pt":1722727918835,"mc":[{"id":"1.231397068","rc":[{"batb":[[0,1.85,6.54],[1,1.84,16.02],[2,1.83,56]],"ltp":2.2,"tv":36.6,"id":40380900},{"batb":[[0,1.83,21.95],[1,1.82,333],[2,1.74,17.32]],"ltp":1.83,"tv":244.2,"id":40296818}]}]}
{"op":"mcm","clk":"11778139478","pt":1722727921486,"mc":[{"id":"1.231397068","rc":[{"batb":[[0,1.86,10],[1,1.85,6.54],[2,1.84,16.02]],"ltp":2.2,"tv":36.6,"id":40380900},{"batb":[[0,1.84,10],[1,1.83,21.95],[2,1.82,333]],"ltp":1.83,"tv":244.2,"id":40296818}]}]}
{"op":"mcm","clk":"11778139810","pt":1722727924985,"mc":[{"id":"1.231397068","rc":[{"batb":[[0,1.85,6.54],[1,1.84,16.02],[2,1.83,56]],"ltp":2.2,"tv":36.6,"id":40380900},{"batb":[[0,1.83,21.95],[1,1.82,333],[2,1.74,17.32]],"ltp":1.83,"tv":244.2,"id":40296818}]}]}
{"op":"mcm","clk":"11778140041","pt":1722727927324,"mc":[{"id":"1.231397068","rc":[{"batb":[[0,1.86,10],[1,1.85,6.54],[2,1.84,16.02]],"ltp":2.2,"tv":36.6,"id":40380900},{"batb":[[0,1.84,10],[1,1.83,21.95],[2,1.82,333]],"ltp":1.83,"tv":244.2,"id":40296818}]}]}
{"op":"mcm","clk":"11778140371","pt":1722727930809,"mc":[{"id":"1.231397068","rc":[{"batb":[[0,1.85,6.54],[1,1.84,16.02],[2,1.83,56]],"ltp":2.2,"tv":36.6,"id":40380900},{"batb":[[0,1.83,21.95],[1,1.82,333],[2,1.74,17.32]],"ltp":1.83,"tv":244.2,"id":40296818}]}]}
{"op":"mcm","clk":"11778140567","pt":1722727933040,"mc":[{"id":"1.231397068","rc":[{"batb":[[0,1.86,10],[1,1.85,6.54],[2,1.84,16.02]],"ltp":2.2,"tv":36.6,"id":40380900},{"batb":[[0,1.84,10],[1,1.83,21.95],[2,1.82,333]],"ltp":1.83,"tv":244.2,"id":40296818}]}]}
{"op":"mcm","clk":"11778140871","pt":1722727936509,"mc":[{"id":"1.231397068","rc":[{"batb":[[0,1.85,6.54],[1,1.84,16.02],[2,1.83,56]],"ltp":2.2,"tv":36.6,"id":40380900},{"batb":[[0,1.83,21.95],[1,1.82,333],[2,1.74,17.32]],"ltp":1.83,"tv":244.2,"id":40296818}]}]}
{"op":"mcm","clk":"11778141151","pt":1722727939613,"mc":[{"id":"1.231397068","rc":[{"batb":[[0,1.86,10],[1,1.85,6.54],[2,1.84,16.02]],"ltp":2.2,"tv":36.6,"id":40380900},{"batb":[[0,1.84,10],[1,1.83,21.95],[2,1.82,333]],"ltp":1.83,"tv":244.2,"id":40296818}]}]}
{"op":"mcm","clk":"11778141439","pt":1722727942958,"mc":[{"id":"1.231397068","rc":[{"batb":[[0,1.85,6.54],[1,1.84,16.02],[2,1.83,56]],"ltp":2.2,"tv":36.6,"id":40380900},{"batb":[[0,1.83,21.95],[1,1.82,333],[2,1.74,17.32]],"ltp":1.83,"tv":244.2,"id":40296818}]}]}
{"op":"mcm","clk":"11778141674","pt":1722727945418,"mc":[{"id":"1.231397068","rc":[{"batb":[[0,1.86,10],[1,1.85,6.54],[2,1.84,16.02]],"ltp":2.2,"tv":36.6,"id":40380900},{"batb":[[0,1.84,10],[1,1.83,21.95],[2,1.82,333]],"ltp":1.83,"tv":244.2,"id":40296818}]}]}
{"op":"mcm","clk":"11778141960","pt":1722727948646,"mc":[{"id":"1.231397068","rc":[{"batb":[[0,1.85,6.54],[1,1.84,16.02],[2,1.83,56]],"ltp":2.2,"tv":36.6,"id":40380900},{"batb":[[0,1.83,21.95],[1,1.82,333],[2,1.74,17.32]],"ltp":1.83,"tv":244.2,"id":40296818}]}]}
{"op":"mcm","clk":"11778142243","pt":1722727952064,"mc":[{"id":"1.231397068","rc":[{"batb":[[0,1.86,10],[1,1.85,6.54],[2,1.84,16.02]],"ltp":2.2,"tv":36.6,"id":40380900},{"batb":[[0,1.84,10],[1,1.83,21.95],[2,1.82,333]],"ltp":1.83,"tv":244.2,"id":40296818}]}]}
{"op":"mcm","clk":"11778142522","pt":1722727955548,"mc":[{"id":"1.231397068","rc":[{"batb":[[0,1.85,6.54],[1,1.84,16.02],[2,1.83,56]],"ltp":2.2,"tv":36.6,"id":40380900},{"batb":[[0,1.83,21.95],[1,1.82,333],[2,1.74,17.32]],"ltp":1.83,"tv":244.2,"id":40296818}]}]}
{"op":"mcm","clk":"11778142732","pt":1722727958242,"mc":[{"id":"1.231397068","rc":[{"batb":[[0,1.86,10],[1,1.85,6.54],[2,1.84,16.02]],"ltp":2.2,"tv":36.6,"id":40380900},{"batb":[[0,1.84,10],[1,1.83,21.95],[2,1.82,333]],"ltp":1.83,"tv":244.2,"id":40296818}]}]}
{"op":"mcm","clk":"11778143005","pt":1722727961557,"mc":[{"id":"1.231397068","rc":[{"batb":[[0,1.85,6.54],[1,1.84,16.02],[2,1.83,56]],"ltp":2.2,"tv":36.6,"id":40380900},{"batb":[[0,1.83,21.95],[1,1.82,333],[2,1.74,17.32]],"ltp":1.83,"tv":244.2,"id":40296818}]}]}
{"op":"mcm","clk":"11778143243","pt":1722727964160,"mc":[{"id":"1.231397068","rc":[{"batb":[[0,1.86,10],[1,1.85,6.54],[2,1.84,16.02]],"ltp":2.2,"tv":36.6,"id":40380900},{"batb":[[0,1.84,10],[1,1.83,21.95],[2,1.82,333]],"ltp":1.83,"tv":244.2,"id":40296818}]}]}
{"op":"mcm","clk":"11778143545","pt":1722727967644,"mc":[{"id":"1.231397068","rc":[{"batb":[[0,1.85,6.54],[1,1.84,16.02],[2,1.83,56]],"ltp":2.2,"tv":36.6,"id":40380900},{"batb":[[0,1.83,21.95],[1,1.82,333],[2,1.74,17.32]],"ltp":1.83,"tv":244.2,"id":40296818}]}]}
{"op":"mcm","clk":"11778143734","pt":1722727969978,"mc":[{"id":"1.231397068","rc":[{"batb":[[0,1.86,10],[1,1.85,6.54],[2,1.84,16.02]],"ltp":2.2,"tv":36.6,"id":40380900},{"batb":[[0,1.84,10],[1,1.83,21.95],[2,1.82,333]],"ltp":1.83,"tv":244.2,"id":40296818}]}]}
{"op":"mcm","clk":"11778144019","pt":1722727973253,"mc":[{"id":"1.231397068","rc":[{"batb":[[0,1.85,6.54],[1,1.84,16.02],[2,1.83,56]],"ltp":2.2,"tv":36.6,"id":40380900},{"batb":[[0,1.83,21.95],[1,1.82,333],[2,1.74,17.32]],"ltp":1.83,"tv":244.2,"id":40296818}]}]}
{"op":"mcm","clk":"11778144225","pt":1722727975890,"mc":[{"id":"1.231397068","rc":[{"batb":[[0,1.86,10],[1,1.85,6.54],[2,1.84,16.02]],"ltp":2.2,"tv":36.6,"id":40380900},{"batb":[[0,1.84,10],[1,1.83,21.95],[2,1.82,333]],"ltp":1.83,"tv":244.2,"id":40296818}]}]}
{"op":"mcm","clk":"11778144535","pt":1722727979316,"mc":[{"id":"1.231397068","rc":[{"batb":[[0,1.85,6.54],[1,1.84,16.02],[2,1.83,56]],"ltp":2.2,"tv":36.6,"id":40380900},{"batb":[[0,1.83,21.95],[1,1.82,333],[2,1.74,17.32]],"ltp":1.83,"tv":244.2,"id":40296818}]}]}
{"op":"mcm","clk":"11778144733","pt":1722727981607,"mc":[{"id":"1.231397068","rc":[{"batb":[[0,1.86,10],[1,1.85,6.54],[2,1.84,16.02]],"ltp":2.2,"tv":36.6,"id":40380900},{"batb":[[0,1.84,10],[1,1.83,21.95],[2,1.82,333]],"ltp":1.83,"tv":244.2,"id":40296818}]}]}
{"op":"mcm","clk":"11778145038","pt":1722727984828,"mc":[{"id":"1.231397068","rc":[{"batb":[[0,1.85,6.54],[1,1.84,16.02],[2,1.83,56]],"ltp":2.2,"tv":36.6,"id":40380900},{"batb":[[0,1.83,21.95],[1,1.82,333],[2,1.74,17.32]],"ltp":1.83,"tv":244.2,"id":40296818}]}]}
{"op":"mcm","clk":"11778145265","pt":1722727987318,"mc":[{"id":"1.231397068","rc":[{"batb":[[0,1.86,10],[1,1.85,6.54],[2,1.84,16.02]],"ltp":2.2,"tv":36.6,"id":40380900},{"batb":[[0,1.84,10],[1,1.83,21.95],[2,1.82,333]],"ltp":1.83,"tv":244.2,"id":40296818}]}]}
{"op":"mcm","clk":"11778145527","pt":1722727990736,"mc":[{"id":"1.231397068","rc":[{"batb":[[0,1.85,6.54],[1,1.84,16.02],[2,1.83,56]],"ltp":2.2,"tv":36.6,"id":40380900},{"batb":[[0,1.83,21.95],[1,1.82,333],[2,1.74,17.32]],"ltp":1.83,"tv":244.2,"id":40296818}]}]}
{"op":"mcm","clk":"11778145745","pt":1722727993031,"mc":[{"id":"1.231397068","rc":[{"batb":[[0,1.86,10],[1,1.85,6.54],[2,1.84,16.02]],"ltp":2.2,"tv":36.6,"id":40380900},{"batb":[[0,1.84,10],[1,1.83,21.95],[2,1.82,333]],"ltp":1.83,"tv":244.2,"id":40296818}]}]}
{"op":"mcm","clk":"11778146050","pt":1722727996661,"mc":[{"id":"1.231397068","rc":[{"batb":[[0,1.85,6.54],[1,1.84,16.02],[2,1.83,56]],"ltp":2.2,"tv":36.6,"id":40380900},{"batb":[[0,1.83,21.95],[1,1.82,333],[2,1.74,17.32]],"ltp":1.83,"tv":244.2,"id":40296818}]}]}
{"op":"mcm","clk":"11778146304","pt":1722727999623,"mc":[{"id":"1.231397068","rc":[{"batb":[[0,1.86,10],[1,1.85,6.54],[2,1.84,16.02]],"ltp":2.2,"tv":36.6,"id":40380900},{"batb":[[0,1.84,10],[1,1.83,21.95],[2,1.82,333]],"ltp":1.83,"tv":244.2,"id":40296818}]}]}
{"op":"mcm","clk":"11778146594","pt":1722728003051,"mc":[{"id":"1.231397068","rc":[{"batb":[[0,1.85,6.54],[1,1.84,16.02],[2,1.83,56]],"ltp":2.2,"tv":36.6,"id":40380900},{"batb":[[0,1.83,21.95],[1,1.82,333],[2,1.74,17.32]],"ltp":1.83,"tv":244.2,"id":40296818}]}]}
{"op":"mcm","clk":"11778146819","pt":1722728005436,"mc":[{"id":"1.231397068","rc":[{"batb":[[0,1.86,10],[1,1.85,6.54],[2,1.84,16.02]],"ltp":2.2,"tv":36.6,"id":40380900},{"batb":[[0,1.84,10],[1,1.83,21.95],[2,1.82,333]],"ltp":1.83,"tv":244.2,"id":40296818}]}]}
{"op":"mcm","clk":"11778147106","pt":1722728008764,"mc":[{"id":"1.231397068","rc":[{"batb":[[0,1.85,6.54],[1,1.84,16.02],[2,1.83,56]],"ltp":2.2,"tv":36.6,"id":40380900},{"batb":[[0,1.83,21.95],[1,1.82,333],[2,1.74,17.32]],"ltp":1.83,"tv":244.2,"id":40296818}]}]}
{"op":"mcm","clk":"11778147429","pt":1722728012474,"mc":[{"id":"1.231397068","rc":[{"batb":[[0,1.86,10],[1,1.85,6.54],[2,1.84,16.02]],"ltp":2.2,"tv":36.6,"id":40380900},{"batb":[[0,1.84,10],[1,1.83,21.95],[2,1.82,333]],"ltp":1.83,"tv":244.2,"id":40296818}]}]}
{"op":"mcm","clk":"11778147693","pt":1722728015959,"mc":[{"id":"1.231397068","rc":[{"batb":[[0,1.85,6.54],[1,1.84,16.02],[2,1.83,56]],"ltp":2.2,"tv":36.6,"id":40380900},{"batb":[[0,1.83,21.95],[1,1.82,333],[2,1.74,17.32]],"ltp":1.83,"tv":244.2,"id":40296818}]}]}
{"op":"mcm","clk":"11778148009","pt":1722728019484,"mc":[{"id":"1.231397068","rc":[{"batb":[[0,1.86,10],[1,1.85,6.54],[2,1.84,16.02]],"ltp":2.2,"tv":36.6,"id":40380900},{"batb":[[0,1.84,10],[1,1.83,21.95],[2,1.82,333]],"ltp":1.83,"tv":244.2,"id":40296818}]}]}
{"op":"mcm","clk":"11778148319","pt":1722728022762,"mc":[{"id":"1.231397068","rc":[{"batb":[[0,1.85,6.54],[1,1.84,16.02],[2,1.83,56]],"ltp":2.2,"tv":36.6,"id":40380900},{"batb":[[0,1.83,21.95],[1,1.82,333],[2,1.74,17.32]],"ltp":1.83,"tv":244.2,"id":40296818}]}]}
{"op":"mcm","clk":"11778148566","pt":1722728025455,"mc":[{"id":"1.231397068","rc":[{"batb":[[0,1.86,10],[1,1.85,6.54],[2,1.84,16.02]],"ltp":2.2,"tv":36.6,"id":40380900},{"batb":[[0,1.84,10],[1,1.83,21.95],[2,1.82,333]],"ltp":1.83,"tv":244.2,"id":40296818}]}]}
{"op":"mcm","clk":"11778148846","pt":1722728028772,"mc":[{"id":"1.231397068","rc":[{"batb":[[0,1.85,6.54],[1,1.84,16.02],[2,1.83,56]],"ltp":2.2,"tv":36.6,"id":40380900},{"batb":[[0,1.83,21.95],[1,1.82,333],[2,1.74,17.32]],"ltp":1.83,"tv":244.2,"id":40296818}]}]}
{"op":"mcm","clk":"11778149063","pt":1722728031068,"mc":[{"id":"1.231397068","rc":[{"batb":[[0,1.86,10],[1,1.85,6.54],[2,1.84,16.02]],"ltp":2.2,"tv":36.6,"id":40380900},{"batb":[[0,1.84,10],[1,1.83,21.95],[2,1.82,333]],"ltp":1.83,"tv":244.2,"id":40296818}]}]}
{"op":"mcm","clk":"11778149369","pt":1722728034597,"mc":[{"id":"1.231397068","rc":[{"batb":[[0,1.85,6.54],[1,1.84,16.02],[2,1.83,56]],"ltp":2.2,"tv":36.6,"id":40380900},{"batb":[[0,1.83,21.95],[1,1.82,333],[2,1.74,17.32]],"ltp":1.83,"tv":244.2,"id":40296818}]}]}
{"op":"mcm","clk":"11778149621","pt":1722728037654,"mc":[{"id":"1.231397068","rc":[{"batb":[[0,1.86,10],[1,1.85,6.54],[2,1.84,16.02]],"ltp":2.2,"tv":36.6,"id":40380900},{"batb":[[0,1.84,10],[1,1.83,21.95],[2,1.82,333]],"ltp":1.83,"tv":244.2,"id":40296818}]}]}
{"op":"mcm","clk":"11778149932","pt":1722728041078,"mc":[{"id":"1.231397068","rc":[{"batb":[[0,1.85,6.54],[1,1.84,16.02],[2,1.83,56]],"ltp":2.2,"tv":36.6,"id":40380900},{"batb":[[0,1.83,21.95],[1,1.82,333],[2,1.74,17.32]],"ltp":1.83,"tv":244.2,"id":40296818}]}]}
{"op":"mcm","clk":"11778150129","pt":1722728043419,"mc":[{"id":"1.231397068","rc":[{"batb":[[0,1.86,10],[1,1.85,6.54],[2,1.84,16.02]],"ltp":2.2,"tv":36.6,"id":40380900},{"batb":[[0,1.84,10],[1,1.83,21.95],[2,1.82,333]],"ltp":1.83,"tv":244.2,"id":40296818}]}]}
{"op":"mcm","clk":"11778150482","pt":1722728047213,"mc":[{"id":"1.231397068","rc":[{"batb":[[0,1.85,6.54],[1,1.84,16.02],[2,1.83,56]],"ltp":2.2,"tv":36.6,"id":40380900},{"batb":[[0,1.83,21.95],[1,1.82,333],[2,1.74,17.32]],"ltp":1.83,"tv":244.2,"id":40296818}]}]}
{"op":"mcm","clk":"11778150768","pt":1722728050184,"mc":[{"id":"1.231397068","rc":[{"batb":[[0,1.86,10],[1,1.85,6.54],[2,1.84,16.02]],"ltp":2.2,"tv":36.6,"id":40380900},{"batb":[[0,1.84,10],[1,1.83,21.95],[2,1.82,333]],"ltp":1.83,"tv":244.2,"id":40296818}]}]}
{"op":"mcm","clk":"11778151058","pt":1722728053517,"mc":[{"id":"1.231397068","rc":[{"batb":[[0,1.85,6.54],[1,1.84,16.02],[2,1.83,56]],"ltp":2.2,"tv":36.6,"id":40380900},{"batb":[[0,1.83,21.95],[1,1.82,333],[2,1.74,17.32]],"ltp":1.83,"tv":244.2,"id":40296818}]}]}
{"op":"mcm","clk":"11778151478","pt":1722728058412,"mc":[{"id":"1.231397068","rc":[{"batb":[[0,1.86,10],[1,1.85,6.54],[2,1.84,16.02]],"ltp":2.2,"tv":36.6,"id":40380900},{"batb":[[0,1.84,10],[1,1.83,21.95],[2,1.82,333]],"ltp":1.83,"tv":244.2,"id":40296818}]}]}
{"op":"mcm","clk":"11778151768","pt":1722728061632,"mc":[{"id":"1.231397068","rc":[{"batb":[[0,1.85,6.54],[1,1.84,16.02],[2,1.83,56]],"ltp":2.2,"tv":36.6,"id":40380900},{"batb":[[0,1.83,21.95],[1,1.82,333],[2,1.74,17.32]],"ltp":1.83,"tv":244.2,"id":40296818}]}]}
{"op":"mcm","clk":"11778152097","pt":1722728065113,"mc":[{"id":"1.231397068","rc":[{"batb":[[0,1.86,10],[1,1.85,6.54],[2,1.84,16.02]],"ltp":2.2,"tv":36.6,"id":40380900},{"batb":[[0,1.84,10],[1,1.83,21.95],[2,1.82,333]],"ltp":1.83,"tv":244.2,"id":40296818}]}]}
{"op":"mcm","clk":"11778152368","pt":1722728068408,"mc":[{"id":"1.231397068","rc":[{"batb":[[0,1.85,6.54],[1,1.84,16.02],[2,1.83,56]],"ltp":2.2,"tv":36.6,"id":40380900},{"batb":[[0,1.83,21.95],[1,1.82,333],[2,1.74,17.32]],"ltp":1.83,"tv":244.2,"id":40296818}]}]}
{"op":"mcm","clk":"11778152873","pt":1722728074330,"mc":[{"id":"1.231397068","rc":[{"batb":[[0,1.86,10],[1,1.85,6.54],[2,1.84,16.02]],"ltp":2.2,"tv":36.6,"id":40380900},{"batb":[[0,1.84,10],[1,1.83,21.95],[2,1.82,333]],"ltp":1.83,"tv":244.2,"id":40296818}]}]}
{"op":"mcm","clk":"11778153160","pt":1722728077610,"mc":[{"id":"1.231397068","rc":[{"batb":[[0,1.85,6.54],[1,1.84,16.02],[2,1.83,56]],"ltp":2.2,"tv":36.6,"id":40380900},{"batb":[[0,1.83,21.95],[1,1.82,333],[2,1.74,17.32]],"ltp":1.83,"tv":244.2,"id":40296818}]}]}
{"op":"mcm","clk":"11778153499","pt":1722728081406,"mc":[{"id":"1.231397068","rc":[{"batb":[[0,1.86,10],[1,1.85,6.54],[2,1.84,16.02]],"ltp":2.2,"tv":36.6,"id":40380900},{"batb":[[0,1.84,10],[1,1.83,21.95],[2,1.82,333]],"ltp":1.83,"tv":244.2,"id":40296818}]}]}
{"op":"mcm","clk":"11778153764","pt":1722728084735,"mc":[{"id":"1.231397068","rc":[{"batb":[[0,1.85,6.54],[1,1.84,16.02],[2,1.83,56]],"ltp":2.2,"tv":36.6,"id":40380900},{"batb":[[0,1.83,21.95],[1,1.82,333],[2,1.74,17.32]],"ltp":1.83,"tv":244.2,"id":40296818}]}]}
{"op":"mcm","clk":"11778153994","pt":1722728087333,"mc":[{"id":"1.231397068","rc":[{"batb":[[0,1.86,10],[1,1.85,6.54],[2,1.84,16.02]],"ltp":2.2,"tv":36.6,"id":40380900},{"batb":[[0,1.84,10],[1,1.83,21.95],[2,1.82,333]],"ltp":1.83,"tv":244.2,"id":40296818}]}]}
{"op":"mcm","clk":"11778154332","pt":1722728090866,"mc":[{"id":"1.231397068","rc":[{"batb":[[0,1.85,6.54],[1,1.84,16.02],[2,1.83,56]],"ltp":2.2,"tv":36.6,"id":40380900},{"batb":[[0,1.83,21.95],[1,1.82,333],[2,1.74,17.32]],"ltp":1.83,"tv":244.2,"id":40296818}]}]}
{"op":"mcm","clk":"11778154534","pt":1722728093102,"mc":[{"id":"1.231397068","rc":[{"batb":[[0,1.86,10],[1,1.85,6.54],[2,1.84,16.02]],"ltp":2.2,"tv":36.6,"id":40380900},{"batb":[[0,1.84,10],[1,1.83,21.95],[2,1.82,333]],"ltp":1.83,"tv":244.2,"id":40296818}]}]}
{"op":"mcm","clk":"11778154820","pt":1722728096430,"mc":[{"id":"1.231397068","rc":[{"batb":[[0,1.85,6.54],[1,1.84,16.02],[2,1.83,56]],"ltp":2.2,"tv":36.6,"id":40380900},{"batb":[[0,1.83,21.95],[1,1.82,333],[2,1.74,17.32]],"ltp":1.83,"tv":244.2,"id":40296818}]}]}
{"op":"mcm","clk":"11778155140","pt":1722728099844,"mc":[{"id":"1.231397068","rc":[{"batb":[[0,1.86,10],[1,1.85,6.54],[2,1.84,16.02]],"ltp":2.2,"tv":36.6,"id":40380900},{"batb":[[0,1.84,10],[1,1.83,21.95],[2,1.82,333]],"ltp":1.83,"tv":244.2,"id":40296818}]}]}
{"op":"mcm","clk":"11778155449","pt":1722728103059,"mc":[{"id":"1.231397068","rc":[{"batb":[[0,1.85,6.54],[1,1.84,16.02],[2,1.83,56]],"ltp":2.2,"tv":36.6,"id":40380900},{"batb":[[0,1.83,21.95],[1,1.82,333],[2,1.74,17.32]],"ltp":1.83,"tv":244.2,"id":40296818}]}]}
{"op":"mcm","clk":"11778155713","pt":1722728105870,"mc":[{"id":"1.231397068","rc":[{"batb":[[0,1.86,10],[1,1.85,6.54],[2,1.84,16.02]],"ltp":2.2,"tv":36.6,"id":40380900},{"batb":[[0,1.84,10],[1,1.83,21.95],[2,1.82,333]],"ltp":1.83,"tv":244.2,"id":40296818}]}]}
{"op":"mcm","clk":"11778156016","pt":1722728109242,"mc":[{"id":"1.231397068","rc":[{"batb":[[0,1.85,6.54],[1,1.84,16.02],[2,1.83,56]],"ltp":2.2,"tv":36.6,"id":40380900},{"batb":[[0,1.83,21.95],[1,1.82,333],[2,1.74,17.32]],"ltp":1.83,"tv":244.2,"id":40296818}]}]}
{"op":"mcm","clk":"11778156330","pt":1722728112879,"mc":[{"id":"1.231397068","rc":[{"batb":[[0,1.86,10],[1,1.85,6.54],[2,1.84,16.02]],"ltp":2.2,"tv":36.6,"id":40380900},{"batb":[[0,1.84,10],[1,1.83,21.95],[2,1.82,333]],"ltp":1.83,"tv":244.2,"id":40296818}]}]}
{"op":"mcm","clk":"11778156659","pt":1722728116270,"mc":[{"id":"1.231397068","rc":[{"batb":[[0,1.85,6.54],[1,1.84,16.02],[2,1.83,56]],"ltp":2.2,"tv":36.6,"id":40380900},{"batb":[[0,1.83,21.95],[1,1.82,333],[2,1.74,17.32]],"ltp":1.83,"tv":244.2,"id":40296818}]}]}
{"op":"mcm","clk":"11778156949","pt":1722728119084,"mc":[{"id":"1.231397068","rc":[{"batb":[[0,1.86,10],[1,1.85,6.54],[2,1.84,16.02]],"ltp":2.2,"tv":36.6,"id":40380900},{"batb":[[0,1.84,10],[1,1.83,21.95],[2,1.82,333]],"ltp":1.83,"tv":244.2,"id":40296818}]}]}
{"op":"mcm","clk":"11778157270","pt":1722728122468,"mc":[{"id":"1.231397068","rc":[{"batb":[[0,1.85,6.54],[1,1.84,16.02],[2,1.83,56]],"ltp":2.2,"tv":36.6,"id":40380900},{"batb":[[0,1.83,21.95],[1,1.82,333],[2,1.74,17.32]],"ltp":1.83,"tv":244.2,"id":40296818}]}]}
{"op":"mcm","clk":"11778157814","pt":1722728128463,"mc":[{"id":"1.231397068","rc":[{"batb":[[0,1.86,10],[1,1.85,6.54],[2,1.84,16.02]],"ltp":2.2,"tv":36.6,"id":40380900},{"batb":[[0,1.84,10],[1,1.83,21.95],[2,1.82,333]],"ltp":1.83,"tv":244.2,"id":40296818}]}]}
{"op":"mcm","clk":"11778158122","pt":1722728132004,"mc":[{"id":"1.231397068","rc":[{"batb":[[0,1.85,6.54],[1,1.84,16.02],[2,1.83,56]],"ltp":2.2,"tv":36.6,"id":40380900},{"batb":[[0,1.83,21.95],[1,1.82,333],[2,1.74,17.32]],"ltp":1.83,"tv":244.2,"id":40296818}]}]}
{"op":"mcm","clk":"11778158357","pt":1722728134400,"mc":[{"id":"1.231397068","rc":[{"batb":[[0,1.86,10],[1,1.85,6.54],[2,1.84,16.02]],"ltp":2.2,"tv":36.6,"id":40380900},{"batb":[[0,1.84,10],[1,1.83,21.95],[2,1.82,333]],"ltp":1.83,"tv":244.2,"id":40296818}]}]}
{"op":"mcm","clk":"11778158690","pt":1722728137882,"mc":[{"id":"1.231397068","rc":[{"batb":[[0,1.85,6.54],[1,1.84,16.02],[2,1.83,56]],"ltp":2.2,"tv":36.6,"id":40380900},{"batb":[[0,1.83,21.95],[1,1.82,333],[2,1.74,17.32]],"ltp":1.83,"tv":244.2,"id":40296818}]}]}
{"op":"mcm","clk":"11778158945","pt":1722728140889,"mc":[{"id":"1.231397068","rc":[{"batb":[[0,1.86,10],[1,1.85,6.54],[2,1.84,16.02]],"ltp":2.2,"tv":36.6,"id":40380900},{"batb":[[0,1.84,10],[1,1.83,21.95],[2,1.82,333]],"ltp":1.83,"tv":244.2,"id":40296818}]}]}
{"op":"mcm","clk":"11778159226","pt":1722728144109,"mc":[{"id":"1.231397068","rc":[{"batb":[[0,1.85,6.54],[1,1.84,16.02],[2,1.83,56]],"ltp":2.2,"tv":36.6,"id":40380900},{"batb":[[0,1.83,21.95],[1,1.82,333],[2,1.74,17.32]],"ltp":1.83,"tv":244.2,"id":40296818}]}]}
{"op":"mcm","clk":"11778159517","pt":1722728146912,"mc":[{"id":"1.231397068","rc":[{"batb":[[0,1.86,10],[1,1.85,6.54],[2,1.84,16.02]],"ltp":2.2,"tv":36.6,"id":40380900},{"batb":[[0,1.84,10],[1,1.83,21.95],[2,1.82,333]],"ltp":1.83,"tv":244.2,"id":40296818}]}]}
{"op":"mcm","clk":"11778159804","pt":1722728150388,"mc":[{"id":"1.231397068","rc":[{"batb":[[0,1.85,6.54],[1,1.84,16.02],[2,1.83,56]],"ltp":2.2,"tv":36.6,"id":40380900},{"batb":[[0,1.83,21.95],[1,1.82,333],[2,1.74,17.32]],"ltp":1.83,"tv":244.2,"id":40296818}]}]}
{"op":"mcm","clk":"11778160027","pt":1722728152834,"mc":[{"id":"1.231397068","rc":[{"batb":[[0,1.86,10],[1,1.85,6.54],[2,1.84,16.02]],"ltp":2.2,"tv":36.6,"id":40380900},{"batb":[[0,1.84,10],[1,1.83,21.95],[2,1.82,333]],"ltp":1.83,"tv":244.2,"id":40296818}]}]}
{"op":"mcm","clk":"11778160319","pt":1722728156418,"mc":[{"id":"1.231397068","rc":[{"batb":[[0,1.85,6.54],[1,1.84,16.02],[2,1.83,56]],"ltp":2.2,"tv":36.6,"id":40380900},{"batb":[[0,1.83,21.95],[1,1.82,333],[2,1.74,17.32]],"ltp":1.83,"tv":244.2,"id":40296818}]}]}
{"op":"mcm","clk":"11778160708","pt":1722728160834,"mc":[{"id":"1.231397068","rc":[{"batb":[[0,1.86,10],[1,1.85,6.54],[2,1.84,16.02]],"ltp":2.2,"tv":36.6,"id":40380900},{"batb":[[0,1.84,10],[1,1.83,21.95],[2,1.82,333]],"ltp":1.83,"tv":244.2,"id":40296818}]}]}
{"op":"mcm","clk":"11778161057","pt":1722728164229,"mc":[{"id":"1.231397068","rc":[{"batb":[[0,1.85,6.54],[1,1.84,16.02],[2,1.83,56]],"ltp":2.2,"tv":36.6,"id":40380900},{"batb":[[0,1.83,21.95],[1,1.82,333],[2,1.74,17.32]],"ltp":1.83,"tv":244.2,"id":40296818}]}]}
{"op":"mcm","clk":"11778161565","pt":1722728169939,"mc":[{"id":"1.231397068","rc":[{"batb":[[0,1.86,10],[1,1.85,6.54],[2,1.84,16.02]],"ltp":2.2,"tv":36.6,"id":40380900},{"batb":[[0,1.84,10],[1,1.83,21.95],[2,1.82,333]],"ltp":1.83,"tv":244.2,"id":40296818}]}]}
{"op":"mcm","clk":"11778161833","pt":1722728173225,"mc":[{"id":"1.231397068","rc":[{"batb":[[0,1.85,6.54],[1,1.84,16.02],[2,1.83,56]],"ltp":2.2,"tv":36.6,"id":40380900},{"batb":[[0,1.83,21.95],[1,1.82,333],[2,1.74,17.32]],"ltp":1.83,"tv":244.2,"id":40296818}]}]}
{"op":"mcm","clk":"11778162264","pt":1722728176875,"mc":[{"id":"1.231397068","rc":[{"batb":[[0,1.86,10],[1,1.85,6.54],[2,1.84,16.02]],"ltp":2.2,"tv":36.6,"id":40380900},{"batb":[[0,1.84,10],[1,1.83,21.95],[2,1.82,333]],"ltp":1.83,"tv":244.2,"id":40296818}]}]}
{"op":"mcm","clk":"11778162526","pt":1722728180156,"mc":[{"id":"1.231397068","rc":[{"batb":[[0,1.85,6.54],[1,1.84,16.02],[2,1.83,56]],"ltp":2.2,"tv":36.6,"id":40380900},{"batb":[[0,1.83,21.95],[1,1.82,333],[2,1.74,17.32]],"ltp":1.83,"tv":244.2,"id":40296818}]}]}
{"op":"mcm","clk":"11778162814","pt":1722728182852,"mc":[{"id":"1.231397068","rc":[{"batb":[[0,1.86,10],[1,1.85,6.54],[2,1.84,16.02]],"ltp":2.2,"tv":36.6,"id":40380900},{"batb":[[0,1.84,10],[1,1.83,21.95],[2,1.82,333]],"ltp":1.83,"tv":244.2,"id":40296818}]}]}
{"op":"mcm","clk":"11778163038","pt":1722728186058,"mc":[{"id":"1.231397068","rc":[{"batb":[[0,1.85,6.54],[1,1.84,16.02],[2,1.83,56]],"ltp":2.2,"tv":36.6,"id":40380900},{"batb":[[0,1.83,21.95],[1,1.82,333],[2,1.74,17.32]],"ltp":1.83,"tv":244.2,"id":40296818}]}]}
{"op":"mcm","clk":"11778163374","pt":1722728189531,"mc":[{"id":"1.231397068","rc":[{"batb":[[0,1.86,10],[1,1.85,6.54],[2,1.84,16.02]],"ltp":2.2,"tv":36.6,"id":40380900},{"batb":[[0,1.84,10],[1,1.83,21.95],[2,1.82,333]],"ltp":1.83,"tv":244.2,"id":40296818}]}]}
{"op":"mcm","clk":"11778163654","pt":1722728193064,"mc":[{"id":"1.231397068","rc":[{"batb":[[0,1.85,6.54],[1,1.84,16.02],[2,1.83,56]],"ltp":2.2,"tv":36.6,"id":40380900},{"batb":[[0,1.83,21.95],[1,1.82,333],[2,1.74,17.32]],"ltp":1.83,"tv":244.2,"id":40296818}]}]}
{"op":"mcm","clk":"11778163866","pt":1722728195453,"mc":[{"id":"1.231397068","rc":[{"batb":[[0,1.86,10],[1,1.85,6.54],[2,1.84,16.02]],"ltp":2.2,"tv":36.6,"id":40380900},{"batb":[[0,1.84,10],[1,1.83,21.95],[2,1.82,333]],"ltp":1.83,"tv":244.2,"id":40296818}]}]}
{"op":"mcm","clk":"11778164141","pt":1722728198557,"mc":[{"id":"1.231397068","rc":[{"batb":[[0,1.85,6.54],[1,1.84,16.02],[2,1.83,56]],"ltp":2.2,"tv":36.6,"id":40380900},{"batb":[[0,1.83,21.95],[1,1.82,333],[2,1.74,17.32]],"ltp":1.83,"tv":244.2,"id":40296818}]}]}
{"op":"mcm","clk":"11778164364","pt":1722728201242,"mc":[{"id":"1.231397068","rc":[{"batb":[[0,1.86,10],[1,1.85,6.54],[2,1.84,16.02]],"ltp":2.2,"tv":36.6,"id":40380900},{"batb":[[0,1.84,10],[1,1.83,21.95],[2,1.82,333]],"ltp":1.83,"tv":244.2,"id":40296818}]}]}
{"op":"mcm","clk":"11778164691","pt":1722728204666,"mc":[{"id":"1.231397068","rc":[{"batb":[[0,1.85,6.54],[1,1.84,16.02],[2,1.83,56]],"ltp":2.2,"tv":36.6,"id":40380900},{"batb":[[0,1.83,21.95],[1,1.82,333],[2,1.74,17.32]],"ltp":1.83,"tv":244.2,"id":40296818}]}]}
{"op":"mcm","clk":"11778164901","pt":1722728207043,"mc":[{"id":"1.231397068","rc":[{"batb":[[0,1.86,10],[1,1.85,6.54],[2,1.84,16.02]],"ltp":2.2,"tv":36.6,"id":40380900},{"batb":[[0,1.84,10],[1,1.83,21.95],[2,1.82,333]],"ltp":1.83,"tv":244.2,"id":40296818}]}]}
{"op":"mcm","clk":"11778165237","pt":1722728210362,"mc":[{"id":"1.231397068","rc":[{"batb":[[0,1.85,6.54],[1,1.84,16.02],[2,1.83,56]],"ltp":2.2,"tv":36.6,"id":40380900},{"batb":[[0,1.83,21.95],[1,1.82,333],[2,1.74,17.32]],"ltp":1.83,"tv":244.2,"id":40296818}]}]}
{"op":"mcm","clk":"11778165542","pt":1722728212854,"mc":[{"id":"1.231397068","rc":[{"batb":[[0,1.86,10],[1,1.85,6.54],[2,1.84,16.02]],"ltp":2.2,"tv":36.6,"id":40380900},{"batb":[[0,1.84,10],[1,1.83,21.95],[2,1.82,333]],"ltp":1.83,"tv":244.2,"id":40296818}]}]}
{"op":"mcm","clk":"11778165865","pt":1722728216371,"mc":[{"id":"1.231397068","rc":[{"batb":[[0,1.85,6.54],[1,1.84,16.02],[2,1.83,56]],"ltp":2.2,"tv":36.6,"id":40380900},{"batb":[[0,1.83,21.95],[1,1.82,333],[2,1.74,17.32]],"ltp":1.83,"tv":244.2,"id":40296818}]}]}
{"op":"mcm","clk":"11778166288","pt":1722728221082,"mc":[{"id":"1.231397068","rc":[{"batb":[[0,1.86,10],[1,1.85,6.54],[2,1.84,16.02]],"ltp":2.2,"tv":36.6,"id":40380900},{"batb":[[0,1.84,10],[1,1.83,21.95],[2,1.82,333]],"ltp":1.83,"tv":244.2,"id":40296818}]}]}
{"op":"mcm","clk":"11778166580","pt":1722728224395,"mc":[{"id":"1.231397068","rc":[{"batb":[[0,1.85,6.54],[1,1.84,16.02],[2,1.83,56]],"ltp":2.2,"tv":36.6,"id":40380900}]}]}
{"op":"mcm","clk":"11778166587","pt":1722728224497,"mc":[{"id":"1.231397068","rc":[{"batb":[[0,1.83,21.95],[1,1.82,333],[2,1.74,17.32]],"ltp":1.83,"tv":244.2,"id":40296818}]}]}
{"op":"mcm","clk":"11778166799","pt":1722728226783,"mc":[{"id":"1.231397068","rc":[{"batb":[[0,1.86,10],[1,1.85,6.54],[2,1.84,16.02]],"ltp":2.2,"tv":36.6,"id":40380900},{"batb":[[0,1.84,10],[1,1.83,21.95],[2,1.82,333]],"ltp":1.83,"tv":244.2,"id":40296818}]}]}
{"op":"mcm","clk":"11778167081","pt":1722728229979,"mc":[{"id":"1.231397068","rc":[{"batb":[[0,1.85,6.54],[1,1.84,16.02],[2,1.83,56]],"ltp":2.2,"tv":36.6,"id":40380900},{"batb":[[0,1.83,21.95],[1,1.82,333],[2,1.74,17.32]],"ltp":1.83,"tv":244.2,"id":40296818}]}]}
{"op":"mcm","clk":"11778167413","pt":1722728233496,"mc":[{"id":"1.231397068","rc":[{"batb":[[0,1.86,10],[1,1.85,6.54],[2,1.84,16.02]],"ltp":2.2,"tv":36.6,"id":40380900},{"batb":[[0,1.84,10],[1,1.83,21.95],[2,1.82,333]],"ltp":1.83,"tv":244.2,"id":40296818}]}]}
{"op":"mcm","clk":"11778167690","pt":1722728237015,"mc":[{"id":"1.231397068","rc":[{"batb":[[0,1.85,6.54],[1,1.84,16.02],[2,1.83,56]],"ltp":2.2,"tv":36.6,"id":40380900},{"batb":[[0,1.83,21.95],[1,1.82,333],[2,1.74,17.32]],"ltp":1.83,"tv":244.2,"id":40296818}]}]}
{"op":"mcm","clk":"11778167975","pt":1722728240494,"mc":[{"id":"1.231397068","rc":[{"batb":[[0,1.86,10],[1,1.85,6.54],[2,1.84,16.02]],"ltp":2.2,"tv":36.6,"id":40380900},{"batb":[[0,1.84,10],[1,1.83,21.95],[2,1.82,333]],"ltp":1.83,"tv":244.2,"id":40296818}]}]}
{"op":"mcm","clk":"11778168318","pt":1722728243926,"mc":[{"id":"1.231397068","rc":[{"batb":[[0,1.85,6.54],[1,1.84,16.02],[2,1.83,56]],"ltp":2.2,"tv":36.6,"id":40380900},{"batb":[[0,1.83,21.95],[1,1.82,333],[2,1.74,17.32]],"ltp":1.83,"tv":244.2,"id":40296818}]}]}
{"op":"mcm","clk":"11778168526","pt":1722728246113,"mc":[{"id":"1.231397068","rc":[{"batb":[[0,1.86,10],[1,1.85,6.54],[2,1.84,16.02]],"ltp":2.2,"tv":36.6,"id":40380900},{"batb":[[0,1.84,10],[1,1.83,21.95],[2,1.82,333]],"ltp":1.83,"tv":244.2,"id":40296818}]}]}
{"op":"mcm","clk":"11778168840","pt":1722728249432,"mc":[{"id":"1.231397068","rc":[{"batb":[[0,1.85,6.54],[1,1.84,16.02],[2,1.83,56]],"ltp":2.2,"tv":36.6,"id":40380900},{"batb":[[0,1.83,21.95],[1,1.82,333],[2,1.74,17.32]],"ltp":1.83,"tv":244.2,"id":40296818}]}]}
{"op":"mcm","clk":"11778169051","pt":1722728251824,"mc":[{"id":"1.231397068","rc":[{"batb":[[0,1.86,10],[1,1.85,6.54],[2,1.84,16.02]],"ltp":2.2,"tv":36.6,"id":40380900},{"batb":[[0,1.84,10],[1,1.83,21.95],[2,1.82,333]],"ltp":1.83,"tv":244.2,"id":40296818}]}]}
{"op":"mcm","clk":"11778169367","pt":1722728255136,"mc":[{"id":"1.231397068","rc":[{"batb":[[0,1.85,6.54],[1,1.84,16.02],[2,1.83,56]],"ltp":2.2,"tv":36.6,"id":40380900},{"batb":[[0,1.83,21.95],[1,1.82,333],[2,1.74,17.32]],"ltp":1.83,"tv":244.2,"id":40296818}]}]}
{"op":"mcm","clk":"11778169712","pt":1722728258505,"mc":[{"id":"1.231397068","rc":[{"batb":[[0,1.86,10],[1,1.85,6.54],[2,1.84,16.02]],"ltp":2.2,"tv":36.6,"id":40380900},{"batb":[[0,1.84,10],[1,1.83,21.95],[2,1.82,333]],"ltp":1.83,"tv":244.2,"id":40296818}]}]}
{"op":"mcm","clk":"11778169957","pt":1722728261818,"mc":[{"id":"1.231397068","rc":[{"batb":[[0,1.85,6.54],[1,1.84,16.02],[2,1.83,56]],"ltp":2.2,"tv":36.6,"id":40380900},{"batb":[[0,1.83,21.95],[1,1.82,333],[2,1.74,17.32]],"ltp":1.83,"tv":244.2,"id":40296818}]}]}
{"op":"mcm","clk":"11778170404","pt":1722728266839,"mc":[{"id":"1.231397068","rc":[{"batb":[[0,1.86,10],[1,1.85,6.54],[2,1.84,16.02]],"ltp":2.2,"tv":36.6,"id":40380900},{"batb":[[0,1.84,10],[1,1.83,21.95],[2,1.82,333]],"ltp":1.83,"tv":244.2,"id":40296818}]}]}
{"op":"mcm","clk":"11778170721","pt":1722728270225,"mc":[{"id":"1.231397068","rc":[{"batb":[[0,1.85,6.54],[1,1.84,16.02],[2,1.83,56]],"ltp":2.2,"tv":36.6,"id":40380900},{"batb":[[0,1.83,21.95],[1,1.82,333],[2,1.74,17.32]],"ltp":1.83,"tv":244.2,"id":40296818}]}]}
{"op":"mcm","clk":"11778171073","pt":1722728274098,"mc":[{"id":"1.231397068","rc":[{"batb":[[0,1.86,10],[1,1.85,6.54],[2,1.84,16.02]],"ltp":2.2,"tv":36.6,"id":40380900},{"batb":[[0,1.84,10],[1,1.83,21.95],[2,1.82,333]],"ltp":1.83,"tv":244.2,"id":40296818}]}]}
{"op":"mcm","clk":"11778171351","pt":1722728277519,"mc":[{"id":"1.231397068","rc":[{"batb":[[0,1.85,6.54],[1,1.84,16.02],[2,1.83,56]],"ltp":2.2,"tv":36.6,"id":40380900},{"batb":[[0,1.83,21.95],[1,1.82,333],[2,1.74,17.32]],"ltp":1.83,"tv":244.2,"id":40296818}]}]}
{"op":"mcm","clk":"11778171799","pt":1722728281937,"mc":[{"id":"1.231397068","rc":[{"batb":[[0,1.86,10],[1,1.85,6.54],[2,1.84,16.02]],"ltp":2.2,"tv":36.6,"id":40380900},{"batb":[[0,1.84,10],[1,1.83,21.95],[2,1.82,333]],"ltp":1.83,"tv":244.2,"id":40296818}]}]}
{"op":"mcm","clk":"11778172168","pt":1722728285339,"mc":[{"id":"1.231397068","rc":[{"batb":[[0,1.85,6.54],[1,1.84,16.02],[2,1.83,56]],"ltp":2.2,"tv":36.6,"id":40380900},{"batb":[[0,1.83,21.95],[1,1.82,333],[2,1.74,17.32]],"ltp":1.83,"tv":244.2,"id":40296818}]}]}
{"op":"mcm","clk":"11778172505","pt":1722728289216,"mc":[{"id":"1.231397068","rc":[{"batb":[[0,1.86,10],[1,1.85,6.54],[2,1.84,16.02]],"ltp":2.2,"tv":36.6,"id":40380900},{"batb":[[0,1.84,10],[1,1.83,21.95],[2,1.82,333]],"ltp":1.83,"tv":244.2,"id":40296818}]}]}
{"op":"mcm","clk":"11778172783","pt":1722728292631,"mc":[{"id":"1.231397068","rc":[{"batb":[[0,1.85,6.54],[1,1.84,16.02],[2,1.83,56]],"ltp":2.2,"tv":36.6,"id":40380900},{"batb":[[0,1.83,21.95],[1,1.82,333],[2,1.74,17.32]],"ltp":1.83,"tv":244.2,"id":40296818}]}]}
{"op":"mcm","clk":"11778173016","pt":1722728295239,"mc":[{"id":"1.231397068","rc":[{"batb":[[0,1.86,10],[1,1.85,6.54],[2,1.84,16.02]],"ltp":2.2,"tv":36.6,"id":40380900},{"batb":[[0,1.84,10],[1,1.83,21.95],[2,1.82,333]],"ltp":1.83,"tv":244.2,"id":40296818}]}]}
{"op":"mcm","clk":"11778173297","pt":1722728298653,"mc":[{"id":"1.231397068","rc":[{"batb":[[0,1.85,6.54],[1,1.84,16.02],[2,1.83,56]],"ltp":2.2,"tv":36.6,"id":40380900},{"batb":[[0,1.83,21.95],[1,1.82,333],[2,1.74,17.32]],"ltp":1.83,"tv":244.2,"id":40296818}]}]}
{"op":"mcm","clk":"11778173593","pt":1722728302129,"mc":[{"id":"1.231397068","rc":[{"batb":[[0,1.86,10],[1,1.85,6.54],[2,1.84,16.02]],"ltp":2.2,"tv":36.6,"id":40380900},{"batb":[[0,1.84,10],[1,1.83,21.95],[2,1.82,333]],"ltp":1.83,"tv":244.2,"id":40296818}]}]}
{"op":"mcm","clk":"11778173876","pt":1722728305437,"mc":[{"id":"1.231397068","rc":[{"batb":[[0,1.85,6.54],[1,1.84,16.02],[2,1.83,56]],"ltp":2.2,"tv":36.6,"id":40380900},{"batb":[[0,1.83,21.95],[1,1.82,333],[2,1.74,17.32]],"ltp":1.83,"tv":244.2,"id":40296818}]}]}
{"op":"mcm","clk":"11778174071","pt":1722728307734,"mc":[{"id":"1.231397068","rc":[{"batb":[[0,1.86,10],[1,1.85,6.54],[2,1.84,16.02]],"ltp":2.2,"tv":36.6,"id":40380900},{"batb":[[0,1.84,10],[1,1.83,21.95],[2,1.82,333]],"ltp":1.83,"tv":244.2,"id":40296818}]}]}
{"op":"mcm","clk":"11778174349","pt":1722728311165,"mc":[{"id":"1.231397068","rc":[{"batb":[[0,1.85,6.54],[1,1.84,16.02],[2,1.83,56]],"ltp":2.2,"tv":36.6,"id":40380900},{"batb":[[0,1.83,21.95],[1,1.82,333],[2,1.74,17.32]],"ltp":1.83,"tv":244.2,"id":40296818}]}]}
{"op":"mcm","clk":"11778174848","pt":1722728317258,"mc":[{"id":"1.231397068","rc":[{"batb":[[0,1.86,10],[1,1.85,6.54],[2,1.84,16.02]],"ltp":2.2,"tv":36.6,"id":40380900},{"batb":[[0,1.84,10],[1,1.83,21.95],[2,1.82,333]],"ltp":1.83,"tv":244.2,"id":40296818}]}]}
{"op":"mcm","clk":"11778175143","pt":1722728320671,"mc":[{"id":"1.231397068","rc":[{"batb":[[0,1.85,6.54],[1,1.84,16.02],[2,1.83,56]],"ltp":2.2,"tv":36.6,"id":40380900},{"batb":[[0,1.83,21.95],[1,1.82,333],[2,1.74,17.32]],"ltp":1.83,"tv":244.2,"id":40296818}]}]}
{"op":"mcm","clk":"11778175440","pt":1722728324082,"mc":[{"id":"1.231397068","rc":[{"batb":[[0,1.86,10],[1,1.85,6.54],[2,1.84,16.02]],"ltp":2.2,"tv":36.6,"id":40380900},{"batb":[[0,1.84,10],[1,1.83,21.95],[2,1.82,333]],"ltp":1.83,"tv":244.2,"id":40296818}]}]}
{"op":"mcm","clk":"11778175661","pt":1722728327460,"mc":[{"id":"1.231397068","rc":[{"batb":[[0,1.85,6.54],[1,1.84,16.02],[2,1.83,56]],"ltp":2.2,"tv":36.6,"id":40380900},{"batb":[[0,1.83,21.95],[1,1.82,333],[2,1.74,17.32]],"ltp":1.83,"tv":244.2,"id":40296818}]}]}
{"op":"mcm","clk":"11778175872","pt":1722728330101,"mc":[{"id":"1.231397068","rc":[{"batb":[[0,1.86,10],[1,1.85,6.54],[2,1.84,16.02]],"ltp":2.2,"tv":36.6,"id":40380900},{"batb":[[0,1.84,10],[1,1.83,21.95],[2,1.82,333]],"ltp":1.83,"tv":244.2,"id":40296818}]}]}
{"op":"mcm","clk":"11778176166","pt":1722728333479,"mc":[{"id":"1.231397068","rc":[{"batb":[[0,1.85,6.54],[1,1.84,16.02],[2,1.83,56]],"ltp":2.2,"tv":36.6,"id":40380900},{"batb":[[0,1.83,21.95],[1,1.82,333],[2,1.74,17.32]],"ltp":1.83,"tv":244.2,"id":40296818}]}]}
{"op":"mcm","clk":"11778176709","pt":1722728339596,"mc":[{"id":"1.231397068","rc":[{"batb":[[0,1.86,10],[1,1.85,6.54],[2,1.84,16.02]],"ltp":2.2,"tv":36.6,"id":40380900},{"batb":[[0,1.84,10],[1,1.83,21.95],[2,1.82,333]],"ltp":1.83,"tv":244.2,"id":40296818}]}]}
{"op":"mcm","clk":"11778176991","pt":1722728343022,"mc":[{"id":"1.231397068","rc":[{"batb":[[0,1.85,6.54],[1,1.84,16.02],[2,1.83,56]],"ltp":2.2,"tv":36.6,"id":40380900},{"batb":[[0,1.83,21.95],[1,1.82,333],[2,1.74,17.32]],"ltp":1.83,"tv":244.2,"id":40296818}]}]}
{"op":"mcm","clk":"11778177480","pt":1722728349020,"mc":[{"id":"1.231397068","rc":[{"batb":[[0,1.86,10],[1,1.85,6.54],[2,1.84,16.02]],"ltp":2.2,"tv":36.6,"id":40380900},{"batb":[[0,1.84,10],[1,1.83,21.95],[2,1.82,333]],"ltp":1.83,"tv":244.2,"id":40296818}]}]}
{"op":"mcm","clk":"11778177718","pt":1722728352421,"mc":[{"id":"1.231397068","rc":[{"batb":[[0,1.85,6.54],[1,1.84,16.02],[2,1.83,56]],"ltp":2.2,"tv":36.6,"id":40380900},{"batb":[[0,1.83,21.95],[1,1.82,333],[2,1.74,17.32]],"ltp":1.83,"tv":244.2,"id":40296818}]}]}
{"op":"mcm","clk":"11778177942","pt":1722728355627,"mc":[{"id":"1.231397068","rc":[{"batb":[[0,1.86,10],[1,1.85,6.54],[2,1.84,16.02]],"ltp":2.2,"tv":36.6,"id":40380900},{"batb":[[0,1.84,10],[1,1.83,21.95],[2,1.82,333]],"ltp":1.83,"tv":244.2,"id":40296818}]}]}
{"op":"mcm","clk":"11778178190","pt":1722728358885,"mc":[{"id":"1.231397068","rc":[{"batb":[[0,1.85,6.54],[1,1.84,16.02],[2,1.83,56]],"ltp":2.2,"tv":36.6,"id":40380900},{"batb":[[0,1.83,21.95],[1,1.82,333],[2,1.74,17.32]],"ltp":1.83,"tv":244.2,"id":40296818}]}]}
{"op":"mcm","clk":"11778178842","pt":1722728365838,"mc":[{"id":"1.231397068","rc":[{"batb":[[0,1.86,10],[1,1.85,6.54],[2,1.84,16.02]],"ltp":2.2,"tv":36.6,"id":40380900},{"batb":[[0,1.84,10],[1,1.83,21.95],[2,1.82,333]],"ltp":1.83,"tv":244.2,"id":40296818}]}]}
{"op":"mcm","clk":"11778179121","pt":1722728369100,"mc":[{"id":"1.231397068","rc":[{"batb":[[0,1.85,6.54],[1,1.84,16.02],[2,1.83,56]],"ltp":2.2,"tv":36.6,"id":40380900},{"batb":[[0,1.83,21.95],[1,1.82,333],[2,1.74,17.32]],"ltp":1.83,"tv":244.2,"id":40296818}]}]}
{"op":"mcm","clk":"11778179557","pt":1722728374842,"mc":[{"id":"1.231397068","rc":[{"batb":[[0,1.86,10],[1,1.85,6.54],[2,1.84,16.02]],"ltp":2.2,"tv":36.6,"id":40380900},{"batb":[[0,1.84,10],[1,1.83,21.95],[2,1.82,333]],"ltp":1.83,"tv":244.2,"id":40296818}]}]}
{"op":"mcm","clk":"11778179839","pt":1722728378249,"mc":[{"id":"1.231397068","rc":[{"batb":[[0,1.85,6.54],[1,1.84,16.02],[2,1.83,56]],"ltp":2.2,"tv":36.6,"id":40380900},{"batb":[[0,1.83,21.95],[1,1.82,333],[2,1.74,17.32]],"ltp":1.83,"tv":244.2,"id":40296818}]}]}
{"op":"mcm","clk":"11778180060","pt":1722728380931,"mc":[{"id":"1.231397068","rc":[{"batb":[[0,1.86,10],[1,1.85,6.54],[2,1.84,16.02]],"ltp":2.2,"tv":36.6,"id":40380900},{"batb":[[0,1.84,10],[1,1.83,21.95],[2,1.82,333]],"ltp":1.83,"tv":244.2,"id":40296818}]}]}
{"op":"mcm","clk":"11778180326","pt":1722728384243,"mc":[{"id":"1.231397068","rc":[{"batb":[[0,1.85,6.54],[1,1.84,16.02],[2,1.83,56]],"ltp":2.2,"tv":36.6,"id":40380900},{"batb":[[0,1.83,21.95],[1,1.82,333],[2,1.74,17.32]],"ltp":1.83,"tv":244.2,"id":40296818}]}]}
{"op":"mcm","clk":"11778180578","pt":1722728387467,"mc":[{"id":"1.231397068","rc":[{"batb":[[0,1.86,10],[1,1.85,6.54],[2,1.84,16.02]],"ltp":2.2,"tv":36.6,"id":40380900},{"batb":[[0,1.84,10],[1,1.83,21.95],[2,1.82,333]],"ltp":1.83,"tv":244.2,"id":40296818}]}]}
{"op":"mcm","clk":"11778180840","pt":1722728390728,"mc":[{"id":"1.231397068","rc":[{"batb":[[0,1.85,6.54],[1,1.84,16.02],[2,1.83,56]],"ltp":2.2,"tv":36.6,"id":40380900},{"batb":[[0,1.83,21.95],[1,1.82,333],[2,1.74,17.32]],"ltp":1.83,"tv":244.2,"id":40296818}]}]}
{"op":"mcm","clk":"11778181133","pt":1722728393261,"mc":[{"id":"1.231397068","rc":[{"batb":[[0,1.86,10],[1,1.85,6.54],[2,1.84,16.02]],"ltp":2.2,"tv":36.6,"id":40380900},{"batb":[[0,1.84,10],[1,1.83,21.95],[2,1.82,333]],"ltp":1.83,"tv":244.2,"id":40296818}]}]}
{"op":"mcm","clk":"11778181394","pt":1722728396763,"mc":[{"id":"1.231397068","rc":[{"batb":[[0,1.85,6.54],[1,1.84,16.02],[2,1.83,56]],"ltp":2.2,"tv":36.6,"id":40380900},{"batb":[[0,1.83,21.95],[1,1.82,333],[2,1.74,17.32]],"ltp":1.83,"tv":244.2,"id":40296818}]}]}
{"op":"mcm","clk":"11778181627","pt":1722728399674,"mc":[{"id":"1.231397068","rc":[{"batb":[[0,1.86,10],[1,1.85,6.54],[2,1.84,16.02]],"ltp":2.2,"tv":36.6,"id":40380900},{"batb":[[0,1.84,10],[1,1.83,21.95],[2,1.82,333]],"ltp":1.83,"tv":244.2,"id":40296818}]}]}
{"op":"mcm","clk":"11778181931","pt":1722728403139,"mc":[{"id":"1.231397068","rc":[{"batb":[[0,1.85,6.54],[1,1.84,16.02],[2,1.83,56]],"ltp":2.2,"tv":36.6,"id":40380900},{"batb":[[0,1.83,21.95],[1,1.82,333],[2,1.74,17.32]],"ltp":1.83,"tv":244.2,"id":40296818}]}]}
{"op":"mcm","clk":"11778182134","pt":1722728405971,"mc":[{"id":"1.231397068","rc":[{"batb":[[0,1.86,10],[1,1.85,6.54],[2,1.84,16.02]],"ltp":2.2,"tv":36.6,"id":40380900},{"batb":[[0,1.84,10],[1,1.83,21.95],[2,1.82,333]],"ltp":1.83,"tv":244.2,"id":40296818}]}]}
{"op":"mcm","clk":"11778182384","pt":1722728409385,"mc":[{"id":"1.231397068","rc":[{"batb":[[0,1.85,6.54],[1,1.84,16.02],[2,1.83,56]],"ltp":2.2,"tv":36.6,"id":40380900},{"batb":[[0,1.83,21.95],[1,1.82,333],[2,1.74,17.32]],"ltp":1.83,"tv":244.2,"id":40296818}]}]}
{"op":"mcm","clk":"11778182535","pt":1722728411555,"mc":[{"id":"1.231397068","rc":[{"batb":[[0,1.86,10],[1,1.85,6.54],[2,1.84,16.02]],"ltp":2.2,"tv":36.6,"id":40380900},{"batb":[[0,1.84,10],[1,1.83,21.95],[2,1.82,333]],"ltp":1.83,"tv":244.2,"id":40296818}]}]}
{"op":"mcm","clk":"11778182791","pt":1722728414971,"mc":[{"id":"1.231397068","rc":[{"batb":[[0,1.85,6.54],[1,1.84,16.02],[2,1.83,56]],"ltp":2.2,"tv":36.6,"id":40380900},{"batb":[[0,1.83,21.95],[1,1.82,333],[2,1.74,17.32]],"ltp":1.83,"tv":244.2,"id":40296818}]}]}
{"op":"mcm","clk":"11778183028","pt":1722728417458,"mc":[{"id":"1.231397068","rc":[{"batb":[[0,1.86,10],[1,1.85,6.54],[2,1.84,16.02]],"ltp":2.2,"tv":36.6,"id":40380900},{"batb":[[0,1.84,10],[1,1.83,21.95],[2,1.82,333]],"ltp":1.83,"tv":244.2,"id":40296818}]}]}
{"op":"mcm","clk":"11778183354","pt":1722728420869,"mc":[{"id":"1.231397068","rc":[{"batb":[[0,1.85,6.54],[1,1.84,16.02],[2,1.83,56]],"ltp":2.2,"tv":36.6,"id":40380900},{"batb":[[0,1.83,21.95],[1,1.82,333],[2,1.74,17.32]],"ltp":1.83,"tv":244.2,"id":40296818}]}]}
{"op":"mcm","clk":"11778183565","pt":1722728423356,"mc":[{"id":"1.231397068","rc":[{"batb":[[0,1.86,10],[1,1.85,6.54],[2,1.84,16.02]],"ltp":2.2,"tv":36.6,"id":40380900},{"batb":[[0,1.84,10],[1,1.83,21.95],[2,1.82,333]],"ltp":1.83,"tv":244.2,"id":40296818}]}]}
{"op":"mcm","clk":"11778183802","pt":1722728426671,"mc":[{"id":"1.231397068","rc":[{"batb":[[0,1.85,6.54],[1,1.84,16.02],[2,1.83,56]],"ltp":2.2,"tv":36.6,"id":40380900},{"batb":[[0,1.83,21.95],[1,1.82,333],[2,1.74,17.32]],"ltp":1.83,"tv":244.2,"id":40296818}]}]}
{"op":"mcm","clk":"11778184101","pt":1722728430399,"mc":[{"id":"1.231397068","rc":[{"batb":[[0,1.86,10],[1,1.85,6.54],[2,1.84,16.02]],"ltp":2.2,"tv":36.6,"id":40380900},{"batb":[[0,1.84,10],[1,1.83,21.95],[2,1.82,333]],"ltp":1.83,"tv":244.2,"id":40296818}]}]}
{"op":"mcm","clk":"11778184370","pt":1722728433674,"mc":[{"id":"1.231397068","rc":[{"batb":[[0,1.85,6.54],[1,1.84,16.02],[2,1.83,56]],"ltp":2.2,"tv":36.6,"id":40380900},{"batb":[[0,1.83,21.95],[1,1.82,333],[2,1.74,17.32]],"ltp":1.83,"tv":244.2,"id":40296818}]}]}
{"op":"mcm","clk":"11778184530","pt":1722728436008,"mc":[{"id":"1.231397068","rc":[{"batb":[[0,1.86,10],[1,1.85,6.54],[2,1.84,16.02]],"ltp":2.2,"tv":36.6,"id":40380900},{"batb":[[0,1.84,10],[1,1.83,21.95],[2,1.82,333]],"ltp":1.83,"tv":244.2,"id":40296818}]}]}
{"op":"mcm","clk":"11778184763","pt":1722728439520,"mc":[{"id":"1.231397068","rc":[{"batb":[[0,1.85,6.54],[1,1.84,16.02],[2,1.83,56]],"ltp":2.2,"tv":36.6,"id":40380900},{"batb":[[0,1.83,21.95],[1,1.82,333],[2,1.74,17.32]],"ltp":1.83,"tv":244.2,"id":40296818}]}]}
{"op":"mcm","clk":"11778184979","pt":1722728442414,"mc":[{"id":"1.231397068","rc":[{"batb":[[0,1.86,10],[1,1.85,6.54],[2,1.84,16.02]],"ltp":2.2,"tv":36.6,"id":40380900},{"batb":[[0,1.84,10],[1,1.83,21.95],[2,1.82,333]],"ltp":1.83,"tv":244.2,"id":40296818}]}]}
{"op":"mcm","clk":"11778185243","pt":1722728445828,"mc":[{"id":"1.231397068","rc":[{"batb":[[0,1.85,6.54],[1,1.84,16.02],[2,1.83,56]],"ltp":2.2,"tv":36.6,"id":40380900},{"batb":[[0,1.83,21.95],[1,1.82,333],[2,1.74,17.32]],"ltp":1.83,"tv":244.2,"id":40296818}]}]}
{"op":"mcm","clk":"11778185637","pt":1722728450808,"mc":[{"id":"1.231397068","rc":[{"batb":[[0,1.86,10],[1,1.85,6.54],[2,1.84,16.02]],"ltp":2.2,"tv":36.6,"id":40380900},{"batb":[[0,1.84,10],[1,1.83,21.95],[2,1.82,333]],"ltp":1.83,"tv":244.2,"id":40296818}]}]}
{"op":"mcm","clk":"11778185905","pt":1722728454131,"mc":[{"id":"1.231397068","rc":[{"batb":[[0,1.85,6.54],[1,1.84,16.02],[2,1.83,56]],"ltp":2.2,"tv":36.6,"id":40380900},{"batb":[[0,1.83,21.95],[1,1.82,333],[2,1.74,17.32]],"ltp":1.83,"tv":244.2,"id":40296818}]}]}
{"op":"mcm","clk":"11778186177","pt":1722728457616,"mc":[{"id":"1.231397068","rc":[{"batb":[[0,1.86,10],[1,1.85,6.54],[2,1.84,16.02]],"ltp":2.2,"tv":36.6,"id":40380900},{"batb":[[0,1.84,10],[1,1.83,21.95],[2,1.82,333]],"ltp":1.83,"tv":244.2,"id":40296818}]}]}
{"op":"mcm","clk":"11778186429","pt":1722728461021,"mc":[{"id":"1.231397068","rc":[{"batb":[[0,1.85,6.54],[1,1.84,16.02],[2,1.83,56]],"ltp":2.2,"tv":36.6,"id":40380900},{"batb":[[0,1.83,21.95],[1,1.82,333],[2,1.74,17.32]],"ltp":1.83,"tv":244.2,"id":40296818}]}]}
{"op":"mcm","clk":"11778186915","pt":1722728466933,"mc":[{"id":"1.231397068","rc":[{"batb":[[0,1.86,10],[1,1.85,6.54],[2,1.84,16.02]],"ltp":2.2,"tv":36.6,"id":40380900},{"batb":[[0,1.84,10],[1,1.83,21.95],[2,1.82,333]],"ltp":1.83,"tv":244.2,"id":40296818}]}]}
{"op":"mcm","clk":"11778187175","pt":1722728470148,"mc":[{"id":"1.231397068","rc":[{"batb":[[0,1.85,6.54],[1,1.84,16.02],[2,1.83,56]],"ltp":2.2,"tv":36.6,"id":40380900},{"batb":[[0,1.83,21.95],[1,1.82,333],[2,1.74,17.32]],"ltp":1.83,"tv":244.2,"id":40296818}]}]}
{"op":"mcm","clk":"11778187382","pt":1722728472924,"mc":[{"id":"1.231397068","rc":[{"batb":[[0,1.86,10],[1,1.85,6.54],[2,1.84,16.02]],"ltp":2.2,"tv":36.6,"id":40380900},{"batb":[[0,1.84,10],[1,1.83,21.95],[2,1.82,333]],"ltp":1.83,"tv":244.2,"id":40296818}]}]}
{"op":"mcm","clk":"11778187623","pt":1722728476234,"mc":[{"id":"1.231397068","rc":[{"batb":[[0,1.85,6.54],[1,1.84,16.02],[2,1.83,56]],"ltp":2.2,"tv":36.6,"id":40380900},{"batb":[[0,1.83,21.95],[1,1.82,333],[2,1.74,17.32]],"ltp":1.83,"tv":244.2,"id":40296818}]}]}
{"op":"mcm","clk":"11778187949","pt":1722728479583,"mc":[{"id":"1.231397068","rc":[{"batb":[[0,1.86,10],[1,1.85,6.54],[2,1.84,16.02]],"ltp":2.2,"tv":36.6,"id":40380900},{"batb":[[0,1.84,10],[1,1.83,21.95],[2,1.82,333]],"ltp":1.83,"tv":244.2,"id":40296818}]}]}
{"op":"mcm","clk":"11778188211","pt":1722728483065,"mc":[{"id":"1.231397068","rc":[{"batb":[[0,1.85,6.54],[1,1.84,16.02],[2,1.83,56]],"ltp":2.2,"tv":36.6,"id":40380900},{"batb":[[0,1.83,21.95],[1,1.82,333],[2,1.74,17.32]],"ltp":1.83,"tv":244.2,"id":40296818}]}]}
{"op":"mcm","clk":"11778188418","pt":1722728485453,"mc":[{"id":"1.231397068","rc":[{"batb":[[0,1.86,10],[1,1.85,6.54],[2,1.84,16.02]],"ltp":2.2,"tv":36.6,"id":40380900},{"batb":[[0,1.84,10],[1,1.83,21.95],[2,1.82,333]],"ltp":1.83,"tv":244.2,"id":40296818}]}]}
{"op":"mcm","clk":"11778188703","pt":1722728488864,"mc":[{"id":"1.231397068","rc":[{"batb":[[0,1.85,6.54],[1,1.84,16.02],[2,1.83,56]],"ltp":2.2,"tv":36.6,"id":40380900},{"batb":[[0,1.83,21.95],[1,1.82,333],[2,1.74,17.32]],"ltp":1.83,"tv":244.2,"id":40296818}]}]}
{"op":"mcm","clk":"11778189003","pt":1722728492333,"mc":[{"id":"1.231397068","rc":[{"batb":[[0,1.86,10],[1,1.85,6.54],[2,1.84,16.02]],"ltp":2.2,"tv":36.6,"id":40380900},{"batb":[[0,1.84,10],[1,1.83,21.95],[2,1.82,333]],"ltp":1.83,"tv":244.2,"id":40296818}]}]}
{"op":"mcm","clk":"11778189306","pt":1722728495752,"mc":[{"id":"1.231397068","rc":[{"batb":[[0,1.85,6.54],[1,1.84,16.02],[2,1.83,56]],"ltp":2.2,"tv":36.6,"id":40380900},{"batb":[[0,1.83,21.95],[1,1.82,333],[2,1.74,17.32]],"ltp":1.83,"tv":244.2,"id":40296818}]}]}
{"op":"mcm","clk":"11778190144","pt":1722728506185,"mc":[{"id":"1.231397068","rc":[{"batb":[[0,1.86,10],[1,1.85,6.54],[2,1.84,16.02]],"ltp":2.2,"tv":36.6,"id":40380900},{"batb":[[0,1.84,10],[1,1.83,21.95],[2,1.82,333]],"ltp":1.83,"tv":244.2,"id":40296818}]}]}
{"op":"mcm","clk":"11778190410","pt":1722728509447,"mc":[{"id":"1.231397068","rc":[{"batb":[[0,1.85,6.54],[1,1.84,16.02],[2,1.83,56]],"ltp":2.2,"tv":36.6,"id":40380900},{"batb":[[0,1.83,21.95],[1,1.82,333],[2,1.74,17.32]],"ltp":1.83,"tv":244.2,"id":40296818}]}]}
{"op":"mcm","clk":"11778190635","pt":1722728511676,"mc":[{"id":"1.231397068","rc":[{"batb":[[0,1.86,10],[1,1.85,6.54],[2,1.84,16.02]],"ltp":2.2,"tv":36.6,"id":40380900},{"batb":[[0,1.84,10],[1,1.83,21.95],[2,1.82,333]],"ltp":1.83,"tv":244.2,"id":40296818}]}]}
{"op":"mcm","clk":"11778190902","pt":1722728515155,"mc":[{"id":"1.231397068","rc":[{"batb":[[0,1.85,6.54],[1,1.84,16.02],[2,1.83,56]],"ltp":2.2,"tv":36.6,"id":40380900},{"batb":[[0,1.83,21.95],[1,1.82,333],[2,1.74,17.32]],"ltp":1.83,"tv":244.2,"id":40296818}]}]}
{"op":"mcm","clk":"11778191121","pt":1722728517480,"mc":[{"id":"1.231397068","rc":[{"batb":[[0,1.86,10],[1,1.85,6.54],[2,1.84,16.02]],"ltp":2.2,"tv":36.6,"id":40380900},{"batb":[[0,1.84,10],[1,1.83,21.95],[2,1.82,333]],"ltp":1.83,"tv":244.2,"id":40296818}]}]}
{"op":"mcm","clk":"11778191410","pt":1722728520897,"mc":[{"id":"1.231397068","rc":[{"batb":[[0,1.85,6.54],[1,1.84,16.02],[2,1.83,56]],"ltp":2.2,"tv":36.6,"id":40380900},{"batb":[[0,1.83,21.95],[1,1.82,333],[2,1.74,17.32]],"ltp":1.83,"tv":244.2,"id":40296818}]}]}
{"op":"mcm","clk":"11778191662","pt":1722728523591,"mc":[{"id":"1.231397068","rc":[{"batb":[[0,1.86,10],[1,1.85,6.54],[2,1.84,16.02]],"ltp":2.2,"tv":36.6,"id":40380900},{"batb":[[0,1.84,10],[1,1.83,21.95],[2,1.82,333]],"ltp":1.83,"tv":244.2,"id":40296818}]}]}
{"op":"mcm","clk":"11778191968","pt":1722728527011,"mc":[{"id":"1.231397068","rc":[{"batb":[[0,1.85,6.54],[1,1.84,16.02],[2,1.83,56]],"ltp":2.2,"tv":36.6,"id":40380900},{"batb":[[0,1.83,21.95],[1,1.82,333],[2,1.74,17.32]],"ltp":1.83,"tv":244.2,"id":40296818}]}]}
{"op":"mcm","clk":"11778192233","pt":1722728530009,"mc":[{"id":"1.231397068","rc":[{"batb":[[0,1.86,10],[1,1.85,6.54],[2,1.84,16.02]],"ltp":2.2,"tv":36.6,"id":40380900},{"batb":[[0,1.84,10],[1,1.83,21.95],[2,1.82,333]],"ltp":1.83,"tv":244.2,"id":40296818}]}]}
{"op":"mcm","clk":"11778192486","pt":1722728533275,"mc":[{"id":"1.231397068","rc":[{"batb":[[0,1.85,6.54],[1,1.84,16.02],[2,1.83,56]],"ltp":2.2,"tv":36.6,"id":40380900},{"batb":[[0,1.83,21.95],[1,1.82,333],[2,1.74,17.32]],"ltp":1.83,"tv":244.2,"id":40296818}]}]}
{"op":"mcm","clk":"11778192679","pt":1722728535711,"mc":[{"id":"1.231397068","rc":[{"batb":[[0,1.86,10],[1,1.85,6.54],[2,1.84,16.02]],"ltp":2.2,"tv":36.6,"id":40380900},{"batb":[[0,1.84,10],[1,1.83,21.95],[2,1.82,333]],"ltp":1.83,"tv":244.2,"id":40296818}]}]}
{"op":"mcm","clk":"11778192973","pt":1722728539223,"mc":[{"id":"1.231397068","rc":[{"batb":[[0,1.85,6.54],[1,1.84,16.02],[2,1.83,56]],"ltp":2.2,"tv":36.6,"id":40380900},{"batb":[[0,1.83,21.95],[1,1.82,333],[2,1.74,17.32]],"ltp":1.83,"tv":244.2,"id":40296818}]}]}
{"op":"mcm","clk":"11778193320","pt":1722728542742,"mc":[{"id":"1.231397068","rc":[{"batb":[[0,1.86,10],[1,1.85,6.54],[2,1.84,16.02]],"ltp":2.2,"tv":36.6,"id":40380900},{"batb":[[0,1.84,10],[1,1.83,21.95],[2,1.82,333]],"ltp":1.83,"tv":244.2,"id":40296818}]}]}
{"op":"mcm","clk":"11778193528","pt":1722728545338,"mc":[{"id":"1.231397068","rc":[{"trd":[[1.86,20]],"batb":[[0,1.85,6.54],[1,1.84,16.02],[2,1.83,56]],"batl":[[0,1.86,80],[1,2.5,2],[2,5,1.56]],"ltp":1.86,"tv":56.6,"id":40380900}],"tv":300.8}]}
{"op":"mcm","clk":"11778193581","pt":1722728546113,"mc":[{"id":"1.231397068","rc":[{"batb":[[0,1.83,6.25],[1,1.82,333],[2,1.74,17.32]],"ltp":1.83,"tv":244.2,"id":40296818}]}]}
{"op":"mcm","clk":"11778193778","pt":1722728548442,"mc":[{"id":"1.231397068","rc":[{"batb":[[0,1.84,10],[1,1.83,6.25],[2,1.82,333]],"ltp":1.83,"tv":244.2,"id":40296818}]}]}
{"op":"mcm","clk":"11778194062","pt":1722728551755,"mc":[{"id":"1.231397068","rc":[{"batb":[[0,1.83,6.25],[1,1.82,333],[2,1.74,17.32]],"ltp":1.83,"tv":244.2,"id":40296818}]}]}
{"op":"mcm","clk":"11778194426","pt":1722728555330,"mc":[{"id":"1.231397068","rc":[{"batb":[[0,1.84,10],[1,1.83,6.25],[2,1.82,333]],"ltp":1.83,"tv":244.2,"id":40296818}]}]}
{"op":"mcm","clk":"11778194686","pt":1722728558558,"mc":[{"id":"1.231397068","rc":[{"batb":[[0,1.83,6.25],[1,1.82,333],[2,1.74,17.32]],"ltp":1.83,"tv":244.2,"id":40296818}]}]}
{"op":"mcm","clk":"11778194940","pt":1722728561241,"mc":[{"id":"1.231397068","rc":[{"batb":[[0,1.84,10],[1,1.83,6.25],[2,1.82,333]],"ltp":1.83,"tv":244.2,"id":40296818}]}]}
{"op":"mcm","clk":"11778195232","pt":1722728564643,"mc":[{"id":"1.231397068","rc":[{"batb":[[0,1.83,6.25],[1,1.82,333],[2,1.74,17.32]],"ltp":1.83,"tv":244.2,"id":40296818}]}]}
{"op":"mcm","clk":"11778195486","pt":1722728567742,"mc":[{"id":"1.231397068","rc":[{"batb":[[0,1.84,10],[1,1.83,6.25],[2,1.82,333]],"ltp":1.83,"tv":244.2,"id":40296818}]}]}
{"op":"mcm","clk":"11778195764","pt":1722728570951,"mc":[{"id":"1.231397068","rc":[{"batb":[[0,1.83,6.25],[1,1.82,333],[2,1.74,17.32]],"ltp":1.83,"tv":244.2,"id":40296818}]}]}
{"op":"mcm","clk":"11778196001","pt":1722728574043,"mc":[{"id":"1.231397068","rc":[{"batb":[[0,1.84,10],[1,1.83,6.25],[2,1.82,333]],"ltp":1.83,"tv":244.2,"id":40296818}]}]}
{"op":"mcm","clk":"11778196280","pt":1722728577454,"mc":[{"id":"1.231397068","rc":[{"batb":[[0,1.83,6.25],[1,1.82,333],[2,1.74,17.32]],"ltp":1.83,"tv":244.2,"id":40296818}]}]}
{"op":"mcm","clk":"11778196524","pt":1722728580250,"mc":[{"id":"1.231397068","rc":[{"batb":[[0,1.84,10],[1,1.83,6.25],[2,1.82,333]],"ltp":1.83,"tv":244.2,"id":40296818}]}]}
{"op":"mcm","clk":"11778196824","pt":1722728583556,"mc":[{"id":"1.231397068","rc":[{"batb":[[0,1.83,6.25],[1,1.82,333],[2,1.74,17.32]],"ltp":1.83,"tv":244.2,"id":40296818}]}]}
{"op":"mcm","clk":"11778197070","pt":1722728586353,"mc":[{"id":"1.231397068","rc":[{"batb":[[0,1.84,10],[1,1.83,6.25],[2,1.82,333]],"ltp":1.83,"tv":244.2,"id":40296818}]}]}
{"op":"mcm","clk":"11778197348","pt":1722728589662,"mc":[{"id":"1.231397068","rc":[{"batb":[[0,1.83,6.25],[1,1.82,333],[2,1.74,17.32]],"ltp":1.83,"tv":244.2,"id":40296818}]}]}
{"op":"mcm","clk":"11778197569","pt":1722728592357,"mc":[{"id":"1.231397068","rc":[{"batb":[[0,1.84,10],[1,1.83,6.25],[2,1.82,333]],"ltp":1.83,"tv":244.2,"id":40296818}]}]}
{"op":"mcm","clk":"11778197865","pt":1722728595679,"mc":[{"id":"1.231397068","rc":[{"batb":[[0,1.83,6.25],[1,1.82,333],[2,1.74,17.32]],"ltp":1.83,"tv":244.2,"id":40296818}]}]}
{"op":"mcm","clk":"11778198095","pt":1722728598200,"mc":[{"id":"1.231397068","rc":[{"batb":[[0,1.84,10],[1,1.83,6.25],[2,1.82,333]],"ltp":1.83,"tv":244.2,"id":40296818}]}]}
{"op":"mcm","clk":"11778198405","pt":1722728601516,"mc":[{"id":"1.231397068","rc":[{"batb":[[0,1.83,6.25],[1,1.82,333],[2,1.74,17.32]],"ltp":1.83,"tv":244.2,"id":40296818}]}]}
{"op":"mcm","clk":"11778198672","pt":1722728604290,"mc":[{"id":"1.231397068","rc":[{"batb":[[0,1.84,10],[1,1.83,6.25],[2,1.82,333]],"ltp":1.83,"tv":244.2,"id":40296818}]}]}
{"op":"mcm","clk":"11778198958","pt":1722728607720,"mc":[{"id":"1.231397068","rc":[{"batb":[[0,1.83,6.25],[1,1.82,333],[2,1.74,17.32]],"ltp":1.83,"tv":244.2,"id":40296818}]}]}
{"op":"mcm","clk":"11778199240","pt":1722728610905,"mc":[{"id":"1.231397068","rc":[{"batb":[[0,1.84,10],[1,1.83,6.25],[2,1.82,333]],"ltp":1.83,"tv":244.2,"id":40296818}]}]}
{"op":"mcm","clk":"11778199540","pt":1722728614314,"mc":[{"id":"1.231397068","rc":[{"batb":[[0,1.83,6.25],[1,1.82,333],[2,1.74,17.32]],"ltp":1.83,"tv":244.2,"id":40296818}]}]}
{"op":"mcm","clk":"11778199841","pt":1722728617896,"mc":[{"id":"1.231397068","rc":[{"batb":[[0,1.84,10],[1,1.83,6.25],[2,1.82,333]],"ltp":1.83,"tv":244.2,"id":40296818}]}]}
{"op":"mcm","clk":"11778200165","pt":1722728621407,"mc":[{"id":"1.231397068","rc":[{"batb":[[0,1.83,6.25],[1,1.82,333],[2,1.74,17.32]],"ltp":1.83,"tv":244.2,"id":40296818}]}]}
{"op":"mcm","clk":"11778200361","pt":1722728623739,"mc":[{"id":"1.231397068","rc":[{"batb":[[0,1.84,10],[1,1.83,6.25],[2,1.82,333]],"ltp":1.83,"tv":244.2,"id":40296818}]}]}
{"op":"mcm","clk":"11778200625","pt":1722728627000,"mc":[{"id":"1.231397068","rc":[{"batb":[[0,1.83,6.25],[1,1.82,333],[2,1.74,17.32]],"ltp":1.83,"tv":244.2,"id":40296818}]}]}
{"op":"mcm","clk":"11778201248","pt":1722728633939,"mc":[{"id":"1.231397068","rc":[{"batb":[[0,1.84,10],[1,1.83,6.25],[2,1.82,333]],"ltp":1.83,"tv":244.2,"id":40296818}]}]}
{"op":"mcm","clk":"11778201586","pt":1722728637311,"mc":[{"id":"1.231397068","rc":[{"batb":[[0,1.83,6.25],[1,1.82,333],[2,1.74,17.32]],"ltp":1.83,"tv":244.2,"id":40296818}]}]}
{"op":"mcm","clk":"11778201745","pt":1722728639642,"mc":[{"id":"1.231397068","rc":[{"batb":[[0,1.84,10],[1,1.83,6.25],[2,1.82,333]],"ltp":1.83,"tv":244.2,"id":40296818}]}]}
{"op":"mcm","clk":"11778202004","pt":1722728643155,"mc":[{"id":"1.231397068","rc":[{"batb":[[0,1.83,6.25],[1,1.82,333],[2,1.74,17.32]],"ltp":1.83,"tv":244.2,"id":40296818}]}]}
{"op":"mcm","clk":"11778202203","pt":1722728645525,"mc":[{"id":"1.231397068","rc":[{"batb":[[0,1.84,10],[1,1.83,6.25],[2,1.82,333]],"ltp":1.83,"tv":244.2,"id":40296818}]}]}
{"op":"mcm","clk":"11778202457","pt":1722728648835,"mc":[{"id":"1.231397068","rc":[{"batb":[[0,1.83,6.25],[1,1.82,333],[2,1.74,17.32]],"ltp":1.83,"tv":244.2,"id":40296818}]}]}
{"op":"mcm","clk":"11778202687","pt":1722728651321,"mc":[{"id":"1.231397068","rc":[{"batb":[[0,1.84,10],[1,1.83,6.25],[2,1.82,333]],"ltp":1.83,"tv":244.2,"id":40296818}]}]}
{"op":"mcm","clk":"11778202943","pt":1722728654728,"mc":[{"id":"1.231397068","rc":[{"batb":[[0,1.83,6.25],[1,1.82,333],[2,1.74,17.32]],"ltp":1.83,"tv":244.2,"id":40296818}]}]}
{"op":"mcm","clk":"11778203125","pt":1722728657156,"mc":[{"id":"1.231397068","rc":[{"batb":[[0,1.84,10],[1,1.83,6.25],[2,1.82,333]],"ltp":1.83,"tv":244.2,"id":40296818}]}]}
{"op":"mcm","clk":"11778203343","pt":1722728660456,"mc":[{"id":"1.231397068","rc":[{"batb":[[0,1.83,6.25],[1,1.82,333],[2,1.74,17.32]],"ltp":1.83,"tv":244.2,"id":40296818}]}]}
{"op":"mcm","clk":"11778203524","pt":1722728662938,"mc":[{"id":"1.231397068","rc":[{"batb":[[0,1.84,10],[1,1.83,6.25],[2,1.82,333]],"ltp":1.83,"tv":244.2,"id":40296818}]}]}
{"op":"mcm","clk":"11778203804","pt":1722728666338,"mc":[{"id":"1.231397068","rc":[{"batb":[[0,1.83,6.25],[1,1.82,333],[2,1.74,17.32]],"ltp":1.83,"tv":244.2,"id":40296818}]}]}
{"op":"mcm","clk":"11778203975","pt":1722728668862,"mc":[{"id":"1.231397068","rc":[{"batb":[[0,1.84,10],[1,1.83,6.25],[2,1.82,333]],"ltp":1.83,"tv":244.2,"id":40296818}]}]}
{"op":"mcm","clk":"11778204265","pt":1722728672340,"mc":[{"id":"1.231397068","rc":[{"batb":[[0,1.83,6.25],[1,1.82,333],[2,1.74,17.32]],"ltp":1.83,"tv":244.2,"id":40296818}]}]}
{"op":"mcm","clk":"11778204704","pt":1722728678073,"mc":[{"id":"1.231397068","rc":[{"batb":[[0,1.84,10],[1,1.83,6.25],[2,1.82,333]],"ltp":1.83,"tv":244.2,"id":40296818}]}]}
{"op":"mcm","clk":"11778204952","pt":1722728681455,"mc":[{"id":"1.231397068","rc":[{"batb":[[0,1.83,6.25],[1,1.82,333],[2,1.74,17.32]],"ltp":1.83,"tv":244.2,"id":40296818}]}]}
{"op":"mcm","clk":"11778205233","pt":1722728684988,"mc":[{"id":"1.231397068","rc":[{"batb":[[0,1.84,10],[1,1.83,6.25],[2,1.82,333]],"ltp":1.83,"tv":244.2,"id":40296818}]}]}
{"op":"mcm","clk":"11778205499","pt":1722728688460,"mc":[{"id":"1.231397068","rc":[{"batb":[[0,1.83,6.25],[1,1.82,333],[2,1.74,17.32]],"ltp":1.83,"tv":244.2,"id":40296818}]}]}
{"op":"mcm","clk":"11778205703","pt":1722728690890,"mc":[{"id":"1.231397068","rc":[{"batb":[[0,1.84,10],[1,1.83,6.25],[2,1.82,333]],"ltp":1.83,"tv":244.2,"id":40296818}]}]}
{"op":"mcm","clk":"11778205954","pt":1722728694203,"mc":[{"id":"1.231397068","rc":[{"batb":[[0,1.83,6.25],[1,1.82,333],[2,1.74,17.32]],"ltp":1.83,"tv":244.2,"id":40296818}]}]}
{"op":"mcm","clk":"11778206217","pt":1722728697771,"mc":[{"id":"1.231397068","rc":[{"batb":[[0,1.84,10],[1,1.83,6.25],[2,1.82,333]],"ltp":1.83,"tv":244.2,"id":40296818}]}]}
{"op":"mcm","clk":"11778206469","pt":1722728701021,"mc":[{"id":"1.231397068","rc":[{"batb":[[0,1.83,6.25],[1,1.82,333],[2,1.74,17.32]],"ltp":1.83,"tv":244.2,"id":40296818}]}]}
{"op":"mcm","clk":"11778206765","pt":1722728704320,"mc":[{"id":"1.231397068","rc":[{"batb":[[0,1.84,10],[1,1.83,6.25],[2,1.82,333]],"ltp":1.83,"tv":244.2,"id":40296818}]}]}
{"op":"mcm","clk":"11778207035","pt":1722728707801,"mc":[{"id":"1.231397068","rc":[{"batb":[[0,1.83,6.25],[1,1.82,333],[2,1.74,17.32]],"ltp":1.83,"tv":244.2,"id":40296818}]}]}
{"op":"mcm","clk":"11778207272","pt":1722728710496,"mc":[{"id":"1.231397068","rc":[{"batb":[[0,1.84,10],[1,1.83,6.25],[2,1.82,333]],"ltp":1.83,"tv":244.2,"id":40296818}]}]}
{"op":"mcm","clk":"11778207620","pt":1722728714016,"mc":[{"id":"1.231397068","rc":[{"batb":[[0,1.83,6.25],[1,1.82,333],[2,1.74,17.32]],"ltp":1.83,"tv":244.2,"id":40296818}]}]}
{"op":"mcm","clk":"11778207818","pt":1722728716305,"mc":[{"id":"1.231397068","rc":[{"batb":[[0,1.84,10],[1,1.83,6.25],[2,1.82,333]],"ltp":1.83,"tv":244.2,"id":40296818}]}]}
{"op":"mcm","clk":"11778208120","pt":1722728719738,"mc":[{"id":"1.231397068","rc":[{"batb":[[0,1.83,6.25],[1,1.82,333],[2,1.74,17.32]],"ltp":1.83,"tv":244.2,"id":40296818}]}]}
{"op":"mcm","clk":"11778208443","pt":1722728723099,"mc":[{"id":"1.231397068","rc":[{"batb":[[0,1.84,10],[1,1.83,6.25],[2,1.82,333]],"ltp":1.83,"tv":244.2,"id":40296818}]}]}
{"op":"mcm","clk":"11778208749","pt":1722728726416,"mc":[{"id":"1.231397068","rc":[{"batb":[[0,1.83,6.25],[1,1.82,333],[2,1.74,17.32]],"ltp":1.83,"tv":244.2,"id":40296818}]}]}
{"op":"mcm","clk":"11778209153","pt":1722728731031,"mc":[{"id":"1.231397068","rc":[{"batb":[[0,1.84,10],[1,1.83,6.25],[2,1.82,333]],"ltp":1.83,"tv":244.2,"id":40296818}]}]}
{"op":"mcm","clk":"11778209485","pt":1722728734360,"mc":[{"id":"1.231397068","rc":[{"batb":[[0,1.83,6.25],[1,1.82,333],[2,1.74,17.32]],"ltp":1.83,"tv":244.2,"id":40296818}]}]}
{"op":"mcm","clk":"11778209716","pt":1722728736944,"mc":[{"id":"1.231397068","rc":[{"batb":[[0,1.84,10],[1,1.83,6.25],[2,1.82,333]],"ltp":1.83,"tv":244.2,"id":40296818}]}]}
{"op":"mcm","clk":"11778210007","pt":1722728740161,"mc":[{"id":"1.231397068","rc":[{"batb":[[0,1.83,6.25],[1,1.82,333],[2,1.74,17.32]],"ltp":1.83,"tv":244.2,"id":40296818}]}]}
{"op":"mcm","clk":"11778210313","pt":1722728743539,"mc":[{"id":"1.231397068","rc":[{"batb":[[0,1.84,10],[1,1.83,6.25],[2,1.82,333]],"ltp":1.83,"tv":244.2,"id":40296818}]}]}
{"op":"mcm","clk":"11778210645","pt":1722728746967,"mc":[{"id":"1.231397068","rc":[{"batb":[[0,1.83,6.25],[1,1.82,333],[2,1.74,17.32]],"ltp":1.83,"tv":244.2,"id":40296818}]}]}
{"op":"mcm","clk":"11778210896","pt":1722728749763,"mc":[{"id":"1.231397068","rc":[{"batb":[[0,1.84,10],[1,1.83,6.25],[2,1.82,333]],"ltp":1.83,"tv":244.2,"id":40296818}]}]}
{"op":"mcm","clk":"11778211210","pt":1722728753134,"mc":[{"id":"1.231397068","rc":[{"batb":[[0,1.83,6.25],[1,1.82,333],[2,1.74,17.32]],"ltp":1.83,"tv":244.2,"id":40296818}]}]}
{"op":"mcm","clk":"11778211412","pt":1722728755678,"mc":[{"id":"1.231397068","rc":[{"batb":[[0,1.84,10],[1,1.83,6.25],[2,1.82,333]],"ltp":1.83,"tv":244.2,"id":40296818}]}]}
{"op":"mcm","clk":"11778211759","pt":1722728759071,"mc":[{"id":"1.231397068","rc":[{"batb":[[0,1.83,6.25],[1,1.82,333],[2,1.74,17.32]],"ltp":1.83,"tv":244.2,"id":40296818}]}]}
{"op":"mcm","clk":"11778211987","pt":1722728761455,"mc":[{"id":"1.231397068","rc":[{"batb":[[0,1.84,10],[1,1.83,6.25],[2,1.82,333]],"ltp":1.83,"tv":244.2,"id":40296818}]}]}
{"op":"mcm","clk":"11778212321","pt":1722728764775,"mc":[{"id":"1.231397068","rc":[{"batb":[[0,1.83,6.25],[1,1.82,333],[2,1.74,17.32]],"ltp":1.83,"tv":244.2,"id":40296818}]}]}
{"op":"mcm","clk":"11778212675","pt":1722728768619,"mc":[{"id":"1.231397068","rc":[{"batb":[[0,1.84,10],[1,1.83,6.25],[2,1.82,333]],"ltp":1.83,"tv":244.2,"id":40296818}]}]}
{"op":"mcm","clk":"11778212996","pt":1722728771988,"mc":[{"id":"1.231397068","rc":[{"batb":[[0,1.83,6.25],[1,1.82,333],[2,1.74,17.32]],"ltp":1.83,"tv":244.2,"id":40296818}]}]}
{"op":"mcm","clk":"11778213253","pt":1722728774789,"mc":[{"id":"1.231397068","rc":[{"batb":[[0,1.84,10],[1,1.83,6.25],[2,1.82,333]],"ltp":1.83,"tv":244.2,"id":40296818}]}]}
{"op":"mcm","clk":"11778213572","pt":1722728778208,"mc":[{"id":"1.231397068","rc":[{"batb":[[0,1.83,6.25],[1,1.82,333],[2,1.74,17.32]],"ltp":1.83,"tv":244.2,"id":40296818}]}]}
{"op":"mcm","clk":"11778213906","pt":1722728781783,"mc":[{"id":"1.231397068","rc":[{"batb":[[0,1.84,10],[1,1.83,6.25],[2,1.82,333]],"ltp":1.83,"tv":244.2,"id":40296818}]}]}
{"op":"mcm","clk":"11778214207","pt":1722728785199,"mc":[{"id":"1.231397068","rc":[{"batb":[[0,1.83,6.25],[1,1.82,333],[2,1.74,17.32]],"ltp":1.83,"tv":244.2,"id":40296818}]}]}
{"op":"mcm","clk":"11778214522","pt":1722728788585,"mc":[{"id":"1.231397068","rc":[{"batb":[[0,1.84,10],[1,1.83,6.25],[2,1.82,333]],"ltp":1.83,"tv":244.2,"id":40296818}]}]}
{"op":"mcm","clk":"11778214833","pt":1722728791914,"mc":[{"id":"1.231397068","rc":[{"batb":[[0,1.83,6.25],[1,1.82,333],[2,1.74,17.32]],"ltp":1.83,"tv":244.2,"id":40296818}]}]}
{"op":"mcm","clk":"11778215059","pt":1722728794457,"mc":[{"id":"1.231397068","rc":[{"batb":[[0,1.84,10],[1,1.83,6.25],[2,1.82,333]],"ltp":1.83,"tv":244.2,"id":40296818}]}]}
{"op":"mcm","clk":"11778215383","pt":1722728797736,"mc":[{"id":"1.231397068","rc":[{"batb":[[0,1.83,6.25],[1,1.82,333],[2,1.74,17.32]],"ltp":1.83,"tv":244.2,"id":40296818}]}]}
{"op":"mcm","clk":"11778215693","pt":1722728801328,"mc":[{"id":"1.231397068","rc":[{"batb":[[0,1.84,10],[1,1.83,6.25],[2,1.82,333]],"ltp":1.83,"tv":244.2,"id":40296818}]}]}
{"op":"mcm","clk":"11778215977","pt":1722728804748,"mc":[{"id":"1.231397068","rc":[{"batb":[[0,1.83,6.25],[1,1.82,333],[2,1.74,17.32]],"ltp":1.83,"tv":244.2,"id":40296818}]}]}
{"op":"mcm","clk":"11778216201","pt":1722728807285,"mc":[{"id":"1.231397068","rc":[{"batb":[[0,1.84,10],[1,1.83,6.25],[2,1.82,333]],"ltp":1.83,"tv":244.2,"id":40296818}]}]}
{"op":"mcm","clk":"11778216267","pt":1722728807964,"mc":[{"id":"1.231397068","rc":[{"trd":[[1.85,13.08]],"batb":[[0,1.84,16.02],[1,1.83,56],[2,1.74,17.32]],"batl":[[0,1.85,83.46],[1,1.86,80],[2,2.5,2]],"ltp":1.85,"tv":69.68,"id":40380900}],"tv":313.88}]}
{"op":"mcm","clk":"11778216483","pt":1722728810658,"mc":[{"id":"1.231397068","rc":[{"batb":[[0,1.83,6.25],[1,1.82,333],[2,1.74,17.32]],"ltp":1.83,"tv":244.2,"id":40296818}]}]}
{"op":"mcm","clk":"11778216740","pt":1722728813649,"mc":[{"id":"1.231397068","rc":[{"batb":[[0,1.84,10],[1,1.83,6.25],[2,1.82,333]],"ltp":1.83,"tv":244.2,"id":40296818}]}]}
{"op":"mcm","clk":"11778217046","pt":1722728816963,"mc":[{"id":"1.231397068","rc":[{"batb":[[0,1.83,6.25],[1,1.82,333],[2,1.74,17.32]],"ltp":1.83,"tv":244.2,"id":40296818}]}]}
{"op":"mcm","clk":"11778217237","pt":1722728819489,"mc":[{"id":"1.231397068","rc":[{"batb":[[0,1.84,10],[1,1.83,6.25],[2,1.82,333]],"ltp":1.83,"tv":244.2,"id":40296818}]}]}
{"op":"mcm","clk":"11778217548","pt":1722728822901,"mc":[{"id":"1.231397068","rc":[{"batb":[[0,1.83,6.25],[1,1.82,333],[2,1.74,17.32]],"ltp":1.83,"tv":244.2,"id":40296818}]}]}
{"op":"mcm","clk":"11778218131","pt":1722728829799,"mc":[{"id":"1.231397068","rc":[{"batb":[[0,1.84,10],[1,1.83,6.25],[2,1.82,333]],"ltp":1.83,"tv":244.2,"id":40296818}]}]}
{"op":"mcm","clk":"11778218432","pt":1722728833073,"mc":[{"id":"1.231397068","rc":[{"batb":[[0,1.83,6.25],[1,1.82,333],[2,1.74,17.32]],"ltp":1.83,"tv":244.2,"id":40296818}]}]}
{"op":"mcm","clk":"11778218779","pt":1722728836699,"mc":[{"id":"1.231397068","rc":[{"batb":[[0,1.84,10],[1,1.83,6.25],[2,1.82,333]],"ltp":1.83,"tv":244.2,"id":40296818}]}]}
{"op":"mcm","clk":"11778219046","pt":1722728839311,"mc":[{"id":"1.231397068","rc":[{"trd":[[1.84,32.04]],"batb":[[0,1.83,56],[1,1.74,17.32],[2,1.7,10]],"batl":[[0,1.84,1783.98],[1,1.85,83.46],[2,1.86,80]],"ltp":1.84,"tv":101.72,"id":40380900}],"tv":345.92}]}
{"op":"mcm","clk":"11778219126","pt":1722728840025,"mc":[{"id":"1.231397068","rc":[{"batb":[[0,1.83,6.25],[1,1.82,333],[2,1.74,17.32]],"ltp":1.83,"tv":244.2,"id":40296818}]}]}
{"op":"mcm","clk":"11778219388","pt":1722728842620,"mc":[{"id":"1.231397068","rc":[{"batb":[[0,1.84,10],[1,1.83,6.25],[2,1.82,333]],"ltp":1.83,"tv":244.2,"id":40296818}]}]}
{"op":"mcm","clk":"11778219713","pt":1722728846095,"mc":[{"id":"1.231397068","rc":[{"batb":[[0,1.83,6.25],[1,1.82,333],[2,1.74,17.32]],"ltp":1.83,"tv":244.2,"id":40296818}]}]}
{"op":"mcm","clk":"11778220073","pt":1722728848913,"mc":[{"id":"1.231397068","rc":[{"batb":[[0,1.84,10],[1,1.83,6.25],[2,1.82,333]],"ltp":1.83,"tv":244.2,"id":40296818}]}]}
{"op":"mcm","clk":"11778220414","pt":1722728852497,"mc":[{"id":"1.231397068","rc":[{"batb":[[0,1.83,6.25],[1,1.82,333],[2,1.74,17.32]],"ltp":1.83,"tv":244.2,"id":40296818}]}]}
{"op":"mcm","clk":"11778220619","pt":1722728854828,"mc":[{"id":"1.231397068","rc":[{"batb":[[0,1.84,10],[1,1.83,6.25],[2,1.82,333]],"ltp":1.83,"tv":244.2,"id":40296818}]}]}
{"op":"mcm","clk":"11778220935","pt":1722728858340,"mc":[{"id":"1.231397068","rc":[{"batb":[[0,1.83,6.25],[1,1.82,333],[2,1.74,17.32]],"ltp":1.83,"tv":244.2,"id":40296818}]}]}
{"op":"mcm","clk":"11778221219","pt":1722728861608,"mc":[{"id":"1.231397068","rc":[{"batb":[[0,1.84,10],[1,1.83,6.25],[2,1.82,333]],"ltp":1.83,"tv":244.2,"id":40296818}]}]}
{"op":"mcm","clk":"11778221524","pt":1722728865130,"mc":[{"id":"1.231397068","rc":[{"batb":[[0,1.83,6.25],[1,1.82,333],[2,1.74,17.32]],"ltp":1.83,"tv":244.2,"id":40296818}]}]}
{"op":"mcm","clk":"11778221753","pt":1722728867857,"mc":[{"id":"1.231397068","rc":[{"batb":[[0,1.84,10],[1,1.83,6.25],[2,1.82,333]],"ltp":1.83,"tv":244.2,"id":40296818}]}]}
{"op":"mcm","clk":"11778222029","pt":1722728871338,"mc":[{"id":"1.231397068","rc":[{"batb":[[0,1.83,6.25],[1,1.82,333],[2,1.74,17.32]],"ltp":1.83,"tv":244.2,"id":40296818}]}]}
{"op":"mcm","clk":"11778222246","pt":1722728873622,"mc":[{"id":"1.231397068","rc":[{"batb":[[0,1.84,10],[1,1.83,6.25],[2,1.82,333]],"ltp":1.83,"tv":244.2,"id":40296818}]}]}
{"op":"mcm","clk":"11778222543","pt":1722728876938,"mc":[{"id":"1.231397068","rc":[{"batb":[[0,1.83,6.25],[1,1.82,333],[2,1.74,17.32]],"ltp":1.83,"tv":244.2,"id":40296818}]}]}
{"op":"mcm","clk":"11778223087","pt":1722728883269,"mc":[{"id":"1.231397068","rc":[{"batb":[[0,1.84,10],[1,1.83,6.25],[2,1.82,333]],"ltp":1.83,"tv":244.2,"id":40296818}]}]}
{"op":"mcm","clk":"11778223366","pt":1722728886652,"mc":[{"id":"1.231397068","rc":[{"batb":[[0,1.83,6.25],[1,1.82,333],[2,1.74,17.32]],"ltp":1.83,"tv":244.2,"id":40296818}]}]}
{"op":"mcm","clk":"11778223588","pt":1722728889172,"mc":[{"id":"1.231397068","rc":[{"batb":[[0,1.84,10],[1,1.83,6.25],[2,1.82,333]],"ltp":1.83,"tv":244.2,"id":40296818}]}]}
{"op":"mcm","clk":"11778223894","pt":1722728892653,"mc":[{"id":"1.231397068","rc":[{"batb":[[0,1.83,6.25],[1,1.82,333],[2,1.74,17.32]],"ltp":1.83,"tv":244.2,"id":40296818}]}]}
{"op":"mcm","clk":"11778224109","pt":1722728895046,"mc":[{"id":"1.231397068","rc":[{"batb":[[0,1.84,10],[1,1.83,6.25],[2,1.82,333]],"ltp":1.83,"tv":244.2,"id":40296818}]}]}
{"op":"mcm","clk":"11778224413","pt":1722728898557,"mc":[{"id":"1.231397068","rc":[{"batb":[[0,1.83,6.25],[1,1.82,333],[2,1.74,17.32]],"ltp":1.83,"tv":244.2,"id":40296818}]}]}
{"op":"mcm","clk":"11778224793","pt":1722728902971,"mc":[{"id":"1.231397068","rc":[{"batb":[[0,1.84,10],[1,1.83,6.25],[2,1.82,333]],"ltp":1.83,"tv":244.2,"id":40296818}]}]}
{"op":"mcm","clk":"11778225109","pt":1722728906478,"mc":[{"id":"1.231397068","rc":[{"batb":[[0,1.83,6.25],[1,1.82,333],[2,1.74,17.32]],"ltp":1.83,"tv":244.2,"id":40296818}]}]}
{"op":"mcm","clk":"11778225356","pt":1722728909071,"mc":[{"id":"1.231397068","rc":[{"batb":[[0,1.84,10],[1,1.83,6.25],[2,1.82,333]],"ltp":1.83,"tv":244.2,"id":40296818}]}]}
{"op":"mcm","clk":"11778225698","pt":1722728912478,"mc":[{"id":"1.231397068","rc":[{"batb":[[0,1.83,6.25],[1,1.82,333],[2,1.74,17.32]],"ltp":1.83,"tv":244.2,"id":40296818}]}]}
{"op":"mcm","clk":"11778226063","pt":1722728915901,"mc":[{"id":"1.231397068","rc":[{"batb":[[0,1.84,10],[1,1.83,6.25],[2,1.82,333]],"ltp":1.83,"tv":244.2,"id":40296818}]}]}
{"op":"mcm","clk":"11778226410","pt":1722728919174,"mc":[{"id":"1.231397068","rc":[{"batb":[[0,1.83,6.25],[1,1.82,333],[2,1.74,17.32]],"ltp":1.83,"tv":244.2,"id":40296818}]}]}
{"op":"mcm","clk":"11778226703","pt":1722728921914,"mc":[{"id":"1.231397068","rc":[{"batb":[[0,1.84,10],[1,1.83,6.25],[2,1.82,333]],"ltp":1.83,"tv":244.2,"id":40296818}]}]}
{"op":"mcm","clk":"11778227040","pt":1722728925385,"mc":[{"id":"1.231397068","rc":[{"batb":[[0,1.83,6.25],[1,1.82,333],[2,1.74,17.32]],"ltp":1.83,"tv":244.2,"id":40296818}]}]}
{"op":"mcm","clk":"11778227343","pt":1722728928392,"mc":[{"id":"1.231397068","rc":[{"batb":[[0,1.84,10],[1,1.83,6.25],[2,1.82,333]],"ltp":1.83,"tv":244.2,"id":40296818}]}]}
{"op":"mcm","clk":"11778227663","pt":1722728931701,"mc":[{"id":"1.231397068","rc":[{"batb":[[0,1.83,6.25],[1,1.82,333],[2,1.74,17.32]],"ltp":1.83,"tv":244.2,"id":40296818}]}]}
{"op":"mcm","clk":"11778227970","pt":1722728934619,"mc":[{"id":"1.231397068","rc":[{"batb":[[0,1.84,10],[1,1.83,6.25],[2,1.82,333]],"ltp":1.83,"tv":244.2,"id":40296818}]}]}
{"op":"mcm","clk":"11778228281","pt":1722728938132,"mc":[{"id":"1.231397068","rc":[{"batb":[[0,1.83,6.25],[1,1.82,333],[2,1.74,17.32]],"ltp":1.83,"tv":244.2,"id":40296818}]}]}
{"op":"mcm","clk":"11778228851","pt":1722728944752,"mc":[{"id":"1.231397068","rc":[{"batb":[[0,1.84,10],[1,1.83,6.25],[2,1.82,333]],"ltp":1.83,"tv":244.2,"id":40296818}]}]}
{"op":"mcm","clk":"11778229150","pt":1722728948222,"mc":[{"id":"1.231397068","rc":[{"batb":[[0,1.83,6.25],[1,1.82,333],[2,1.74,17.32]],"ltp":1.83,"tv":244.2,"id":40296818}]}]}
{"op":"mcm","clk":"11778229775","pt":1722728955246,"mc":[{"id":"1.231397068","rc":[{"batb":[[0,1.84,10],[1,1.83,6.25],[2,1.82,333]],"ltp":1.83,"tv":244.2,"id":40296818}]}]}
{"op":"mcm","clk":"11778230087","pt":1722728958659,"mc":[{"id":"1.231397068","rc":[{"batb":[[0,1.83,6.25],[1,1.82,333],[2,1.74,17.32]],"ltp":1.83,"tv":244.2,"id":40296818}]}]}
{"op":"mcm","clk":"11778230538","pt":1722728963535,"mc":[{"id":"1.231397068","rc":[{"batb":[[0,1.84,10],[1,1.83,6.25],[2,1.82,333]],"ltp":1.83,"tv":244.2,"id":40296818}]}]}
{"op":"mcm","clk":"11778230870","pt":1722728966947,"mc":[{"id":"1.231397068","rc":[{"batb":[[0,1.83,6.25],[1,1.82,333],[2,1.74,17.32]],"ltp":1.83,"tv":244.2,"id":40296818}]}]}
{"op":"mcm","clk":"11778231152","pt":1722728970263,"mc":[{"id":"1.231397068","rc":[{"batb":[[0,1.84,10],[1,1.83,6.25],[2,1.82,333]],"ltp":1.83,"tv":244.2,"id":40296818}]}]}
{"op":"mcm","clk":"11778231477","pt":1722728973770,"mc":[{"id":"1.231397068","rc":[{"batb":[[0,1.83,6.25],[1,1.82,333],[2,1.74,17.32]],"ltp":1.83,"tv":244.2,"id":40296818}]}]}
{"op":"mcm","clk":"11778231697","pt":1722728976047,"mc":[{"id":"1.231397068","rc":[{"batb":[[0,1.84,10],[1,1.83,6.25],[2,1.82,333]],"ltp":1.83,"tv":244.2,"id":40296818}]}]}
{"op":"mcm","clk":"11778231987","pt":1722728979355,"mc":[{"id":"1.231397068","rc":[{"batb":[[0,1.83,6.25],[1,1.82,333],[2,1.74,17.32]],"ltp":1.83,"tv":244.2,"id":40296818}]}]}
{"op":"mcm","clk":"11778232243","pt":1722728982047,"mc":[{"id":"1.231397068","rc":[{"batb":[[0,1.84,10],[1,1.83,6.25],[2,1.82,333]],"ltp":1.83,"tv":244.2,"id":40296818}]}]}
{"op":"mcm","clk":"11778232549","pt":1722728985514,"mc":[{"id":"1.231397068","rc":[{"batb":[[0,1.83,6.25],[1,1.82,333],[2,1.74,17.32]],"ltp":1.83,"tv":244.2,"id":40296818}]}]}
{"op":"mcm","clk":"11778233014","pt":1722728990575,"mc":[{"id":"1.231397068","rc":[{"batb":[[0,1.84,10],[1,1.83,6.25],[2,1.82,333]],"ltp":1.83,"tv":244.2,"id":40296818}]}]}
{"op":"mcm","clk":"11778233313","pt":1722728994101,"mc":[{"id":"1.231397068","rc":[{"batb":[[0,1.83,6.25],[1,1.82,333],[2,1.74,17.32]],"ltp":1.83,"tv":244.2,"id":40296818}]}]}
{"op":"mcm","clk":"11778233610","pt":1722728997499,"mc":[{"id":"1.231397068","rc":[{"batb":[[0,1.84,10],[1,1.83,6.25],[2,1.82,333]],"ltp":1.83,"tv":244.2,"id":40296818}]}]}
{"op":"mcm","clk":"11778233901","pt":1722729001016,"mc":[{"id":"1.231397068","rc":[{"batb":[[0,1.83,6.25],[1,1.82,333],[2,1.74,17.32]],"ltp":1.83,"tv":244.2,"id":40296818}]}]}
{"op":"mcm","clk":"11778234113","pt":1722729003201,"mc":[{"id":"1.231397068","rc":[{"batb":[[0,1.84,10],[1,1.83,6.25],[2,1.82,333]],"ltp":1.83,"tv":244.2,"id":40296818}]}]}
{"op":"mcm","clk":"11778234425","pt":1722729006478,"mc":[{"id":"1.231397068","rc":[{"batb":[[0,1.83,6.25],[1,1.82,333],[2,1.74,17.32]],"ltp":1.83,"tv":244.2,"id":40296818}]}]}
{"op":"mcm","clk":"11778234734","pt":1722729009912,"mc":[{"id":"1.231397068","rc":[{"batb":[[0,1.84,10],[1,1.83,6.25],[2,1.82,333]],"ltp":1.83,"tv":244.2,"id":40296818}]}]}
{"op":"mcm","clk":"11778235017","pt":1722729013216,"mc":[{"id":"1.231397068","rc":[{"batb":[[0,1.83,6.25],[1,1.82,333],[2,1.74,17.32]],"ltp":1.83,"tv":244.2,"id":40296818}]}]}
{"op":"mcm","clk":"11778235406","pt":1722729017212,"mc":[{"id":"1.231397068","rc":[{"batb":[[0,1.84,10],[1,1.83,6.25],[2,1.82,333]],"ltp":1.83,"tv":244.2,"id":40296818}]}]}
{"op":"mcm","clk":"11778235717","pt":1722729020635,"mc":[{"id":"1.231397068","rc":[{"batb":[[0,1.83,6.25],[1,1.82,333],[2,1.74,17.32]],"ltp":1.83,"tv":244.2,"id":40296818}]}]}
{"op":"mcm","clk":"11778235960","pt":1722729023222,"mc":[{"id":"1.231397068","rc":[{"batb":[[0,1.84,10],[1,1.83,6.25],[2,1.82,333]],"ltp":1.83,"tv":244.2,"id":40296818}]}]}
{"op":"mcm","clk":"11778236262","pt":1722729026530,"mc":[{"id":"1.231397068","rc":[{"batb":[[0,1.83,6.25],[1,1.82,333],[2,1.74,17.32]],"ltp":1.83,"tv":244.2,"id":40296818}]}]}
{"op":"mcm","clk":"11778236545","pt":1722729029689,"mc":[{"id":"1.231397068","rc":[{"batb":[[0,1.84,10],[1,1.83,6.25],[2,1.82,333]],"ltp":1.83,"tv":244.2,"id":40296818}]}]}
{"op":"mcm","clk":"11778236861","pt":1722729033110,"mc":[{"id":"1.231397068","rc":[{"batb":[[0,1.83,6.25],[1,1.82,333],[2,1.74,17.32]],"ltp":1.83,"tv":244.2,"id":40296818}]}]}
{"op":"mcm","clk":"11778237362","pt":1722729038912,"mc":[{"id":"1.231397068","rc":[{"batb":[[0,1.84,10],[1,1.83,6.25],[2,1.82,333]],"ltp":1.83,"tv":244.2,"id":40296818}]}]}
{"op":"mcm","clk":"11778237663","pt":1722729042424,"mc":[{"id":"1.231397068","rc":[{"batb":[[0,1.83,6.25],[1,1.82,333],[2,1.74,17.32]],"ltp":1.83,"tv":244.2,"id":40296818}]}]}
{"op":"mcm","clk":"11778237868","pt":1722729044723,"mc":[{"id":"1.231397068","rc":[{"batb":[[0,1.84,10],[1,1.83,6.25],[2,1.82,333]],"ltp":1.83,"tv":244.2,"id":40296818}]}]}
{"op":"mcm","clk":"11778238145","pt":1722729048036,"mc":[{"id":"1.231397068","rc":[{"batb":[[0,1.83,6.25],[1,1.82,333],[2,1.74,17.32]],"ltp":1.83,"tv":244.2,"id":40296818}]}]}
{"op":"mcm","clk":"11778238376","pt":1722729050527,"mc":[{"id":"1.231397068","rc":[{"batb":[[0,1.84,10],[1,1.83,6.25],[2,1.82,333]],"ltp":1.83,"tv":244.2,"id":40296818}]}]}
{"op":"mcm","clk":"11778238689","pt":1722729053852,"mc":[{"id":"1.231397068","rc":[{"batb":[[0,1.83,6.25],[1,1.82,333],[2,1.74,17.32]],"ltp":1.83,"tv":244.2,"id":40296818}]}]}
{"op":"mcm","clk":"11778239207","pt":1722729059542,"mc":[{"id":"1.231397068","rc":[{"batb":[[0,1.84,10],[1,1.83,6.25],[2,1.82,333]],"ltp":1.83,"tv":244.2,"id":40296818}]}]}
{"op":"mcm","clk":"11778239560","pt":1722729062862,"mc":[{"id":"1.231397068","rc":[{"batb":[[0,1.83,6.25],[1,1.82,333],[2,1.74,17.32]],"ltp":1.83,"tv":244.2,"id":40296818}]}]}
{"op":"mcm","clk":"11778239882","pt":1722729066426,"mc":[{"id":"1.231397068","rc":[{"batb":[[0,1.84,10],[1,1.83,6.25],[2,1.82,333]],"ltp":1.83,"tv":244.2,"id":40296818}]}]}
{"op":"mcm","clk":"11778240192","pt":1722729070050,"mc":[{"id":"1.231397068","rc":[{"batb":[[0,1.83,6.25],[1,1.82,333],[2,1.74,17.32]],"ltp":1.83,"tv":244.2,"id":40296818}]}]}
{"op":"mcm","clk":"11778240671","pt":1722729075056,"mc":[{"id":"1.231397068","rc":[{"batb":[[0,1.84,10],[1,1.83,6.25],[2,1.82,333]],"ltp":1.83,"tv":244.2,"id":40296818}]}]}
{"op":"mcm","clk":"11778241006","pt":1722729078578,"mc":[{"id":"1.231397068","rc":[{"batb":[[0,1.83,6.25],[1,1.82,333],[2,1.74,17.32]],"ltp":1.83,"tv":244.2,"id":40296818}]}]}
{"op":"mcm","clk":"11778241214","pt":1722729080746,"mc":[{"id":"1.231397068","rc":[{"batb":[[0,1.84,10],[1,1.83,6.25],[2,1.82,333]],"ltp":1.83,"tv":244.2,"id":40296818}]}]}
{"op":"mcm","clk":"11778241533","pt":1722729084068,"mc":[{"id":"1.231397068","rc":[{"batb":[[0,1.83,6.25],[1,1.82,333],[2,1.74,17.32]],"ltp":1.83,"tv":244.2,"id":40296818}]}]}
{"op":"mcm","clk":"11778241749","pt":1722729086448,"mc":[{"id":"1.231397068","rc":[{"batb":[[0,1.84,10],[1,1.83,6.25],[2,1.82,333]],"ltp":1.83,"tv":244.2,"id":40296818}]}]}
{"op":"mcm","clk":"11778242079","pt":1722729089965,"mc":[{"id":"1.231397068","rc":[{"batb":[[0,1.83,6.25],[1,1.82,333],[2,1.74,17.32]],"ltp":1.83,"tv":244.2,"id":40296818}]}]}
{"op":"mcm","clk":"11778242362","pt":1722729092767,"mc":[{"id":"1.231397068","rc":[{"batb":[[0,1.84,10],[1,1.83,6.25],[2,1.82,333]],"ltp":1.83,"tv":244.2,"id":40296818}]}]}
{"op":"mcm","clk":"11778242656","pt":1722729095979,"mc":[{"id":"1.231397068","rc":[{"batb":[[0,1.83,6.25],[1,1.82,333],[2,1.74,17.32]],"ltp":1.83,"tv":244.2,"id":40296818}]}]}
{"op":"mcm","clk":"11778242892","pt":1722729098862,"mc":[{"id":"1.231397068","rc":[{"batb":[[0,1.84,10],[1,1.83,6.25],[2,1.82,333]],"ltp":1.83,"tv":244.2,"id":40296818}]}]}
{"op":"mcm","clk":"11778243206","pt":1722729102376,"mc":[{"id":"1.231397068","rc":[{"batb":[[0,1.83,6.25],[1,1.82,333],[2,1.74,17.32]],"ltp":1.83,"tv":244.2,"id":40296818}]}]}
{"op":"mcm","clk":"11778243448","pt":1722729104867,"mc":[{"id":"1.231397068","rc":[{"batb":[[0,1.84,10],[1,1.83,6.25],[2,1.82,333]],"ltp":1.83,"tv":244.2,"id":40296818}]}]}
{"op":"mcm","clk":"11778243797","pt":1722729108285,"mc":[{"id":"1.231397068","rc":[{"batb":[[0,1.83,6.25],[1,1.82,333],[2,1.74,17.32]],"ltp":1.83,"tv":244.2,"id":40296818}]}]}
{"op":"mcm","clk":"11778244004","pt":1722729110604,"mc":[{"id":"1.231397068","rc":[{"batb":[[0,1.84,10],[1,1.83,6.25],[2,1.82,333]],"ltp":1.83,"tv":244.2,"id":40296818}]}]}
{"op":"mcm","clk":"11778244324","pt":1722729114070,"mc":[{"id":"1.231397068","rc":[{"batb":[[0,1.83,6.25],[1,1.82,333],[2,1.74,17.32]],"ltp":1.83,"tv":244.2,"id":40296818}]}]}
{"op":"mcm","clk":"11778244576","pt":1722729116600,"mc":[{"id":"1.231397068","rc":[{"batb":[[0,1.84,10],[1,1.83,6.25],[2,1.82,333]],"ltp":1.83,"tv":244.2,"id":40296818}]}]}
{"op":"mcm","clk":"11778244892","pt":1722729119992,"mc":[{"id":"1.231397068","rc":[{"batb":[[0,1.83,6.25],[1,1.82,333],[2,1.74,17.32]],"ltp":1.83,"tv":244.2,"id":40296818}]}]}
{"op":"mcm","clk":"11778245152","pt":1722729122679,"mc":[{"id":"1.231397068","rc":[{"batb":[[0,1.84,10],[1,1.83,6.25],[2,1.82,333]],"ltp":1.83,"tv":244.2,"id":40296818}]}]}
{"op":"mcm","clk":"11778245471","pt":1722729126182,"mc":[{"id":"1.231397068","rc":[{"batb":[[0,1.83,6.25],[1,1.82,333],[2,1.74,17.32]],"ltp":1.83,"tv":244.2,"id":40296818}]}]}
{"op":"mcm","clk":"11778245705","pt":1722729128809,"mc":[{"id":"1.231397068","rc":[{"batb":[[0,1.84,10],[1,1.83,6.25],[2,1.82,333]],"ltp":1.83,"tv":244.2,"id":40296818}]}]}
{"op":"mcm","clk":"11778246035","pt":1722729132122,"mc":[{"id":"1.231397068","rc":[{"batb":[[0,1.83,6.25],[1,1.82,333],[2,1.74,17.32]],"ltp":1.83,"tv":244.2,"id":40296818}]}]}
{"op":"mcm","clk":"11778246277","pt":1722729134320,"mc":[{"id":"1.231397068","rc":[{"batb":[[0,1.84,10],[1,1.83,6.25],[2,1.82,333]],"ltp":1.83,"tv":244.2,"id":40296818}]}]}
{"op":"mcm","clk":"11778246643","pt":1722729137728,"mc":[{"id":"1.231397068","rc":[{"batb":[[0,1.83,6.25],[1,1.82,333],[2,1.74,17.32]],"ltp":1.83,"tv":244.2,"id":40296818}]}]}
{"op":"mcm","clk":"11778246990","pt":1722729141238,"mc":[{"id":"1.231397068","rc":[{"batb":[[0,1.84,10],[1,1.83,6.25],[2,1.82,333]],"ltp":1.83,"tv":244.2,"id":40296818}]}]}
{"op":"mcm","clk":"11778247367","pt":1722729144717,"mc":[{"id":"1.231397068","rc":[{"batb":[[0,1.83,6.25],[1,1.82,333],[2,1.74,17.32]],"ltp":1.83,"tv":244.2,"id":40296818}]}]}
{"op":"mcm","clk":"11778247706","pt":1722729148024,"mc":[{"id":"1.231397068","rc":[{"batb":[[0,1.84,10],[1,1.83,6.25],[2,1.82,333]],"ltp":1.83,"tv":244.2,"id":40296818}]}]}
{"op":"mcm","clk":"11778248039","pt":1722729151539,"mc":[{"id":"1.231397068","rc":[{"batb":[[0,1.83,6.25],[1,1.82,333],[2,1.74,17.32]],"ltp":1.83,"tv":244.2,"id":40296818}]}]}
{"op":"mcm","clk":"11778248265","pt":1722729154022,"mc":[{"id":"1.231397068","rc":[{"batb":[[0,1.84,10],[1,1.83,6.25],[2,1.82,333]],"ltp":1.83,"tv":244.2,"id":40296818}]}]}
{"op":"mcm","clk":"11778248588","pt":1722729157534,"mc":[{"id":"1.231397068","rc":[{"batb":[[0,1.83,6.25],[1,1.82,333],[2,1.74,17.32]],"ltp":1.83,"tv":244.2,"id":40296818}]}]}
{"op":"mcm","clk":"11778248902","pt":1722729161253,"mc":[{"id":"1.231397068","rc":[{"batb":[[0,1.84,10],[1,1.83,6.25],[2,1.82,333]],"ltp":1.83,"tv":244.2,"id":40296818}]}]}
{"op":"mcm","clk":"11778249211","pt":1722729164721,"mc":[{"id":"1.231397068","rc":[{"batb":[[0,1.83,6.25],[1,1.82,333],[2,1.74,17.32]],"ltp":1.83,"tv":244.2,"id":40296818}]}]}
{"op":"mcm","clk":"11778249532","pt":1722729168030,"mc":[{"id":"1.231397068","rc":[{"batb":[[0,1.84,10],[1,1.83,6.25],[2,1.82,333]],"ltp":1.83,"tv":244.2,"id":40296818}]}]}
{"op":"mcm","clk":"11778249833","pt":1722729171382,"mc":[{"id":"1.231397068","rc":[{"batb":[[0,1.83,6.25],[1,1.82,333],[2,1.74,17.32]],"ltp":1.83,"tv":244.2,"id":40296818}]}]}
{"op":"mcm","clk":"11778250129","pt":1722729174132,"mc":[{"id":"1.231397068","rc":[{"batb":[[0,1.84,10],[1,1.83,6.25],[2,1.82,333]],"ltp":1.83,"tv":244.2,"id":40296818}]}]}
{"op":"mcm","clk":"11778250440","pt":1722729177437,"mc":[{"id":"1.231397068","rc":[{"batb":[[0,1.83,6.25],[1,1.82,333],[2,1.74,17.32]],"ltp":1.83,"tv":244.2,"id":40296818}]}]}
{"op":"mcm","clk":"11778250673","pt":1722729179968,"mc":[{"id":"1.231397068","rc":[{"batb":[[0,1.84,10],[1,1.83,6.25],[2,1.82,333]],"ltp":1.83,"tv":244.2,"id":40296818}]}]}
{"op":"mcm","clk":"11778251042","pt":1722729183459,"mc":[{"id":"1.231397068","rc":[{"batb":[[0,1.83,6.25],[1,1.82,333],[2,1.74,17.32]],"ltp":1.83,"tv":244.2,"id":40296818}]}]}
{"op":"mcm","clk":"11778251304","pt":1722729185879,"mc":[{"id":"1.231397068","rc":[{"batb":[[0,1.84,10],[1,1.83,6.25],[2,1.82,333]],"ltp":1.83,"tv":244.2,"id":40296818}]}]}
{"op":"mcm","clk":"11778251640","pt":1722729189253,"mc":[{"id":"1.231397068","rc":[{"batb":[[0,1.83,6.25],[1,1.82,333],[2,1.74,17.32]],"ltp":1.83,"tv":244.2,"id":40296818}]}]}
{"op":"mcm","clk":"11778251902","pt":1722729191880,"mc":[{"id":"1.231397068","rc":[{"batb":[[0,1.84,10],[1,1.83,6.25],[2,1.82,333]],"ltp":1.83,"tv":244.2,"id":40296818}]}]}
{"op":"mcm","clk":"11778252193","pt":1722729195076,"mc":[{"id":"1.231397068","rc":[{"batb":[[0,1.83,6.25],[1,1.82,333],[2,1.74,17.32]],"ltp":1.83,"tv":244.2,"id":40296818}]}]}
{"op":"mcm","clk":"11778252435","pt":1722729197668,"mc":[{"id":"1.231397068","rc":[{"batb":[[0,1.84,10],[1,1.83,6.25],[2,1.82,333]],"ltp":1.83,"tv":244.2,"id":40296818}]}]}
{"op":"mcm","clk":"11778252752","pt":1722729200968,"mc":[{"id":"1.231397068","rc":[{"batb":[[0,1.83,6.25],[1,1.82,333],[2,1.74,17.32]],"ltp":1.83,"tv":244.2,"id":40296818}]}]}
{"op":"mcm","clk":"11778252991","pt":1722729203703,"mc":[{"id":"1.231397068","rc":[{"batb":[[0,1.84,10],[1,1.83,6.25],[2,1.82,333]],"ltp":1.83,"tv":244.2,"id":40296818}]}]}
{"op":"mcm","clk":"11778253277","pt":1722729206910,"mc":[{"id":"1.231397068","rc":[{"batb":[[0,1.83,6.25],[1,1.82,333],[2,1.74,17.32]],"ltp":1.83,"tv":244.2,"id":40296818}]}]}
{"op":"mcm","clk":"11778253564","pt":1722729210001,"mc":[{"id":"1.231397068","rc":[{"batb":[[0,1.84,10],[1,1.83,6.25],[2,1.82,333]],"ltp":1.83,"tv":244.2,"id":40296818}]}]}
{"op":"mcm","clk":"11778253872","pt":1722729213297,"mc":[{"id":"1.231397068","rc":[{"batb":[[0,1.83,6.25],[1,1.82,333],[2,1.74,17.32]],"ltp":1.83,"tv":244.2,"id":40296818}]}]}
{"op":"mcm","clk":"11778254177","pt":1722729216391,"mc":[{"id":"1.231397068","rc":[{"batb":[[0,1.84,10],[1,1.83,6.25],[2,1.82,333]],"ltp":1.83,"tv":244.2,"id":40296818}]}]}
{"op":"mcm","clk":"11778254462","pt":1722729219797,"mc":[{"id":"1.231397068","rc":[{"batb":[[0,1.83,6.25],[1,1.82,333],[2,1.74,17.32]],"ltp":1.83,"tv":244.2,"id":40296818}]}]}
{"op":"mcm","clk":"11778254804","pt":1722729223989,"mc":[{"id":"1.231397068","rc":[{"batb":[[0,1.84,10],[1,1.83,6.25],[2,1.82,333]],"ltp":1.83,"tv":244.2,"id":40296818}]}]}
{"op":"mcm","clk":"11778255126","pt":1722729227496,"mc":[{"id":"1.231397068","rc":[{"batb":[[0,1.83,6.25],[1,1.82,333],[2,1.74,17.32]],"ltp":1.83,"tv":244.2,"id":40296818}]}]}
{"op":"mcm","clk":"11778255322","pt":1722729229918,"mc":[{"id":"1.231397068","rc":[{"batb":[[0,1.84,10],[1,1.83,6.25],[2,1.82,333]],"ltp":1.83,"tv":244.2,"id":40296818}]}]}
{"op":"mcm","clk":"11778255649","pt":1722729233427,"mc":[{"id":"1.231397068","rc":[{"batb":[[0,1.83,6.25],[1,1.82,333],[2,1.74,17.32]],"ltp":1.83,"tv":244.2,"id":40296818}]}]}
{"op":"mcm","clk":"11778255935","pt":1722729236423,"mc":[{"id":"1.231397068","rc":[{"batb":[[0,1.84,10],[1,1.83,6.25],[2,1.82,333]],"ltp":1.83,"tv":244.2,"id":40296818}]}]}
{"op":"mcm","clk":"11778256267","pt":1722729239717,"mc":[{"id":"1.231397068","rc":[{"batb":[[0,1.83,6.25],[1,1.82,333],[2,1.74,17.32]],"ltp":1.83,"tv":244.2,"id":40296818}]}]}
{"op":"mcm","clk":"11778256675","pt":1722729244411,"mc":[{"id":"1.231397068","rc":[{"batb":[[0,1.84,10],[1,1.83,6.25],[2,1.82,333]],"ltp":1.83,"tv":244.2,"id":40296818}]}]}
{"op":"mcm","clk":"11778256968","pt":1722729247917,"mc":[{"id":"1.231397068","rc":[{"batb":[[0,1.83,6.25],[1,1.82,333],[2,1.74,17.32]],"ltp":1.83,"tv":244.2,"id":40296818}]}]}
{"op":"mcm","clk":"11778257291","pt":1722729251236,"mc":[{"id":"1.231397068","rc":[{"batb":[[0,1.84,10],[1,1.83,6.25],[2,1.82,333]],"ltp":1.83,"tv":244.2,"id":40296818}]}]}
{"op":"mcm","clk":"11778257590","pt":1722729254739,"mc":[{"id":"1.231397068","rc":[{"batb":[[0,1.83,6.25],[1,1.82,333],[2,1.74,17.32]],"ltp":1.83,"tv":244.2,"id":40296818}]}]}
{"op":"mcm","clk":"11778257763","pt":1722729257057,"mc":[{"id":"1.231397068","rc":[{"batb":[[0,1.84,10],[1,1.83,6.25],[2,1.82,333]],"ltp":1.83,"tv":244.2,"id":40296818}]}]}
{"op":"mcm","clk":"11778258070","pt":1722729260471,"mc":[{"id":"1.231397068","rc":[{"batb":[[0,1.83,6.25],[1,1.82,333],[2,1.74,17.32]],"ltp":1.83,"tv":244.2,"id":40296818}]}]}
{"op":"mcm","clk":"11778258366","pt":1722729263356,"mc":[{"id":"1.231397068","rc":[{"batb":[[0,1.84,10],[1,1.83,6.25],[2,1.82,333]],"ltp":1.83,"tv":244.2,"id":40296818}]}]}
{"op":"mcm","clk":"11778258712","pt":1722729266769,"mc":[{"id":"1.231397068","rc":[{"batb":[[0,1.83,6.25],[1,1.82,333],[2,1.74,17.32]],"ltp":1.83,"tv":244.2,"id":40296818}]}]}
{"op":"mcm","clk":"11778259064","pt":1722729270178,"mc":[{"id":"1.231397068","rc":[{"batb":[[0,1.84,10],[1,1.83,6.25],[2,1.82,333]],"ltp":1.83,"tv":244.2,"id":40296818}]}]}
{"op":"mcm","clk":"11778259369","pt":1722729273482,"mc":[{"id":"1.231397068","rc":[{"batb":[[0,1.83,6.25],[1,1.82,333],[2,1.74,17.32]],"ltp":1.83,"tv":244.2,"id":40296818}]}]}
{"op":"mcm","clk":"11778259592","pt":1722729275966,"mc":[{"id":"1.231397068","rc":[{"batb":[[0,1.84,10],[1,1.83,6.25],[2,1.82,333]],"ltp":1.83,"tv":244.2,"id":40296818}]}]}
{"op":"mcm","clk":"11778259868","pt":1722729279261,"mc":[{"id":"1.231397068","rc":[{"batb":[[0,1.83,6.25],[1,1.82,333],[2,1.74,17.32]],"ltp":1.83,"tv":244.2,"id":40296818}]}]}
{"op":"mcm","clk":"11778260118","pt":1722729281791,"mc":[{"id":"1.231397068","rc":[{"batb":[[0,1.84,10],[1,1.83,6.25],[2,1.82,333]],"ltp":1.83,"tv":244.2,"id":40296818}]}]}
{"op":"mcm","clk":"11778260465","pt":1722729285103,"mc":[{"id":"1.231397068","rc":[{"batb":[[0,1.83,6.25],[1,1.82,333],[2,1.74,17.32]],"ltp":1.83,"tv":244.2,"id":40296818}]}]}
{"op":"mcm","clk":"11778260705","pt":1722729287585,"mc":[{"id":"1.231397068","rc":[{"batb":[[0,1.84,10],[1,1.83,6.25],[2,1.82,333]],"ltp":1.83,"tv":244.2,"id":40296818}]}]}
{"op":"mcm","clk":"11778260995","pt":1722729290882,"mc":[{"id":"1.231397068","rc":[{"batb":[[0,1.83,6.25],[1,1.82,333],[2,1.74,17.32]],"ltp":1.83,"tv":244.2,"id":40296818}]}]}
{"op":"mcm","clk":"11778281792","pt":1722729519909,"mc":[{"id":"1.231397068","rc":[{"trd":[[1.83,121.62]],"batb":[[0,1.74,17.32],[1,1.7,10],[2,1.25,100]],"batl":[[0,1.83,114.38],[1,1.84,1783.98],[2,1.85,83.46]],"ltp":1.83,"tv":223.34,"id":40380900},{"trd":[[2.2,8]],"batl":[[0,2.5,2],[1,5,1.56],[2,6,0.78]],"ltp":2.2,"tv":252.2,"id":40296818}],"tv":475.54}]}
{"op":"mcm","clk":"11778282526","pt":1722729528723,"mc":[{"id":"1.231397068","rc":[{"batl":[[0,2.5,2],[1,5,1.56],[2,6,0.78]],"ltp":1.83,"tv":223.34,"id":40380900}]}]}
{"op":"mcm","clk":"11778282841","pt":1722729532596,"mc":[{"id":"1.231397068","rc":[{"batl":[[0,2.2,13.65],[1,2.5,2],[2,5,1.56]],"ltp":1.83,"tv":223.34,"id":40380900},{"batb":[[0,1.83,22.48]],"ltp":2.2,"tv":252.2,"id":40296818}]}]}
{"op":"mcm","clk":"11778284507","pt":1722729550808,"mc":[{"id":"1.231397068","rc":[{"batl":[[0,1.84,180],[1,2.2,13.65],[2,2.5,2]],"ltp":1.83,"tv":223.34,"id":40380900}]}]}
{"op":"mcm","clk":"11778284665","pt":1722729552308,"mc":[{"id":"1.231397068","rc":[{"batl":[[1,2.5,2],[2,5,1.56]],"ltp":1.83,"tv":223.34,"id":40380900},{"batb":[[0,1.83,6.25]],"ltp":2.2,"tv":252.2,"id":40296818}]}]}
{"op":"mcm","clk":"11778289296","pt":1722729601540,"mc":[{"id":"1.231397068","rc":[{"batb":[[0,1.84,10],[1,1.83,6.25],[2,1.82,333]],"ltp":2.2,"tv":252.2,"id":40296818}]}]}
{"op":"mcm","clk":"11778289731","pt":1722729605116,"mc":[{"id":"1.231397068","rc":[{"batb":[[0,1.83,6.25],[1,1.82,333],[2,1.74,17.32]],"ltp":2.2,"tv":252.2,"id":40296818}]}]}
{"op":"mcm","clk":"11778289990","pt":1722729607528,"mc":[{"id":"1.231397068","rc":[{"batb":[[0,1.84,10],[1,1.83,6.25],[2,1.82,333]],"ltp":2.2,"tv":252.2,"id":40296818}]}]}
{"op":"mcm","clk":"11778290362","pt":1722729611019,"mc":[{"id":"1.231397068","rc":[{"batb":[[0,1.83,6.25],[1,1.82,333],[2,1.74,17.32]],"ltp":2.2,"tv":252.2,"id":40296818}]}]}
{"op":"mcm","clk":"11778290627","pt":1722729613200,"mc":[{"id":"1.231397068","rc":[{"batb":[[0,1.84,10],[1,1.83,6.25],[2,1.82,333]],"ltp":2.2,"tv":252.2,"id":40296818}]}]}
{"op":"mcm","clk":"11778291007","pt":1722729616620,"mc":[{"id":"1.231397068","rc":[{"batb":[[0,1.83,6.25],[1,1.82,333],[2,1.74,17.32]],"ltp":2.2,"tv":252.2,"id":40296818}]}]}
{"op":"mcm","clk":"11778291267","pt":1722729619322,"mc":[{"id":"1.231397068","rc":[{"batb":[[0,1.84,10],[1,1.83,6.25],[2,1.82,333]],"ltp":2.2,"tv":252.2,"id":40296818}]}]}
{"op":"mcm","clk":"11778291666","pt":1722729622849,"mc":[{"id":"1.231397068","rc":[{"batb":[[0,1.83,6.25],[1,1.82,333],[2,1.74,17.32]],"ltp":2.2,"tv":252.2,"id":40296818}]}]}
{"op":"mcm","clk":"11778292012","pt":1722729626154,"mc":[{"id":"1.231397068","rc":[{"batb":[[0,1.84,10],[1,1.83,6.25],[2,1.82,333]],"ltp":2.2,"tv":252.2,"id":40296818}]}]}
{"op":"mcm","clk":"11778292387","pt":1722729629621,"mc":[{"id":"1.231397068","rc":[{"batb":[[0,1.83,6.25],[1,1.82,333],[2,1.74,17.32]],"ltp":2.2,"tv":252.2,"id":40296818}]}]}
{"op":"mcm","clk":"11778292707","pt":1722729632734,"mc":[{"id":"1.231397068","rc":[{"batb":[[0,1.84,10],[1,1.83,6.25],[2,1.82,333]],"ltp":2.2,"tv":252.2,"id":40296818}]}]}
{"op":"mcm","clk":"11778293096","pt":1722729636253,"mc":[{"id":"1.231397068","rc":[{"batb":[[0,1.83,6.25],[1,1.82,333],[2,1.74,17.32]],"ltp":2.2,"tv":252.2,"id":40296818}]}]}
{"op":"mcm","clk":"11778293453","pt":1722729639763,"mc":[{"id":"1.231397068","rc":[{"batb":[[0,1.84,10],[1,1.83,6.25],[2,1.82,333]],"ltp":2.2,"tv":252.2,"id":40296818}]}]}
{"op":"mcm","clk":"11778293787","pt":1722729643073,"mc":[{"id":"1.231397068","rc":[{"batb":[[0,1.83,6.25],[1,1.82,333],[2,1.74,17.32]],"ltp":2.2,"tv":252.2,"id":40296818}]}]}
{"op":"mcm","clk":"11778294069","pt":1722729645864,"mc":[{"id":"1.231397068","rc":[{"batb":[[0,1.84,10],[1,1.83,6.25],[2,1.82,333]],"ltp":2.2,"tv":252.2,"id":40296818}]}]}
{"op":"mcm","clk":"11778294428","pt":1722729649237,"mc":[{"id":"1.231397068","rc":[{"batb":[[0,1.83,6.25],[1,1.82,333],[2,1.74,17.32]],"ltp":2.2,"tv":252.2,"id":40296818}]}]}
{"op":"mcm","clk":"11778294691","pt":1722729651874,"mc":[{"id":"1.231397068","rc":[{"batb":[[0,1.84,10],[1,1.83,6.25],[2,1.82,333]],"ltp":2.2,"tv":252.2,"id":40296818}]}]}
{"op":"mcm","clk":"11778295043","pt":1722729655139,"mc":[{"id":"1.231397068","rc":[{"batb":[[0,1.83,6.25],[1,1.82,333],[2,1.74,17.32]],"ltp":2.2,"tv":252.2,"id":40296818}]}]}
{"op":"mcm","clk":"11778295326","pt":1722729658082,"mc":[{"id":"1.231397068","rc":[{"batb":[[0,1.84,10],[1,1.83,6.25],[2,1.82,333]],"ltp":2.2,"tv":252.2,"id":40296818}]}]}
{"op":"mcm","clk":"11778295676","pt":1722729661650,"mc":[{"id":"1.231397068","rc":[{"batb":[[0,1.83,6.25],[1,1.82,333],[2,1.74,17.32]],"ltp":2.2,"tv":252.2,"id":40296818}]}]}
{"op":"mcm","clk":"11778296042","pt":1722729665398,"mc":[{"id":"1.231397068","rc":[{"batb":[[0,1.84,10],[1,1.83,6.25],[2,1.82,333]],"ltp":2.2,"tv":252.2,"id":40296818}]}]}
{"op":"mcm","clk":"11778296400","pt":1722729668677,"mc":[{"id":"1.231397068","rc":[{"batb":[[0,1.83,6.25],[1,1.82,333],[2,1.74,17.32]],"ltp":2.2,"tv":252.2,"id":40296818}]}]}
{"op":"mcm","clk":"11778296620","pt":1722729671095,"mc":[{"id":"1.231397068","rc":[{"batb":[[0,1.84,10],[1,1.83,6.25],[2,1.82,333]],"ltp":2.2,"tv":252.2,"id":40296818}]}]}
{"op":"mcm","clk":"11778296970","pt":1722729674502,"mc":[{"id":"1.231397068","rc":[{"batb":[[0,1.83,6.25],[1,1.82,333],[2,1.74,17.32]],"ltp":2.2,"tv":252.2,"id":40296818}]}]}
{"op":"mcm","clk":"11778297257","pt":1722729677307,"mc":[{"id":"1.231397068","rc":[{"batb":[[0,1.84,10],[1,1.83,6.25],[2,1.82,333]],"ltp":2.2,"tv":252.2,"id":40296818}]}]}
{"op":"mcm","clk":"11778297606","pt":1722729680720,"mc":[{"id":"1.231397068","rc":[{"batb":[[0,1.83,6.25],[1,1.82,333],[2,1.74,17.32]],"ltp":2.2,"tv":252.2,"id":40296818}]}]}
{"op":"mcm","clk":"11778297826","pt":1722729683137,"mc":[{"id":"1.231397068","rc":[{"batb":[[0,1.84,10],[1,1.83,6.25],[2,1.82,333]],"ltp":2.2,"tv":252.2,"id":40296818}]}]}
{"op":"mcm","clk":"11778298127","pt":1722729686549,"mc":[{"id":"1.231397068","rc":[{"batb":[[0,1.83,6.25],[1,1.82,333],[2,1.74,17.32]],"ltp":2.2,"tv":252.2,"id":40296818}]}]}
{"op":"mcm","clk":"11778298355","pt":1722729688926,"mc":[{"id":"1.231397068","rc":[{"batb":[[0,1.84,10],[1,1.83,6.25],[2,1.82,333]],"ltp":2.2,"tv":252.2,"id":40296818}]}]}
{"op":"mcm","clk":"11778298719","pt":1722729692351,"mc":[{"id":"1.231397068","rc":[{"batb":[[0,1.83,6.25],[1,1.82,333],[2,1.74,17.32]],"ltp":2.2,"tv":252.2,"id":40296818}]}]}
{"op":"mcm","clk":"11778299298","pt":1722729698132,"mc":[{"id":"1.231397068","rc":[{"batb":[[0,1.84,10],[1,1.83,6.25],[2,1.82,333]],"ltp":2.2,"tv":252.2,"id":40296818}]}]}
{"op":"mcm","clk":"11778299595","pt":1722729701438,"mc":[{"id":"1.231397068","rc":[{"batb":[[0,1.83,6.25],[1,1.82,333],[2,1.74,17.32]],"ltp":2.2,"tv":252.2,"id":40296818}]}]}
{"op":"mcm","clk":"11778299869","pt":1722729704038,"mc":[{"id":"1.231397068","rc":[{"batb":[[0,1.84,10],[1,1.83,6.25],[2,1.82,333]],"ltp":2.2,"tv":252.2,"id":40296818}]}]}
{"op":"mcm","clk":"11778300174","pt":1722729707542,"mc":[{"id":"1.231397068","rc":[{"batb":[[0,1.83,6.25],[1,1.82,333],[2,1.74,17.32]],"ltp":2.2,"tv":252.2,"id":40296818}]}]}
{"op":"mcm","clk":"11778300392","pt":1722729709975,"mc":[{"id":"1.231397068","rc":[{"batb":[[0,1.84,10],[1,1.83,6.25],[2,1.82,333]],"ltp":2.2,"tv":252.2,"id":40296818}]}]}
{"op":"mcm","clk":"11778300710","pt":1722729713335,"mc":[{"id":"1.231397068","rc":[{"batb":[[0,1.83,6.25],[1,1.82,333],[2,1.74,17.32]],"ltp":2.2,"tv":252.2,"id":40296818}]}]}
{"op":"mcm","clk":"11778300947","pt":1722729715658,"mc":[{"id":"1.231397068","rc":[{"batb":[[0,1.84,10],[1,1.83,6.25],[2,1.82,333]],"ltp":2.2,"tv":252.2,"id":40296818}]}]}
{"op":"mcm","clk":"11778301247","pt":1722729718963,"mc":[{"id":"1.231397068","rc":[{"batb":[[0,1.83,6.25],[1,1.82,333],[2,1.74,17.32]],"ltp":2.2,"tv":252.2,"id":40296818}]}]}
{"op":"mcm","clk":"11778301571","pt":1722729722489,"mc":[{"id":"1.231397068","rc":[{"batb":[[0,1.84,10],[1,1.83,6.25],[2,1.82,333]],"ltp":2.2,"tv":252.2,"id":40296818}]}]}
{"op":"mcm","clk":"11778301908","pt":1722729725964,"mc":[{"id":"1.231397068","rc":[{"batb":[[0,1.83,6.25],[1,1.82,333],[2,1.74,17.32]],"ltp":2.2,"tv":252.2,"id":40296818}]}]}
{"op":"mcm","clk":"11778302233","pt":1722729729564,"mc":[{"id":"1.231397068","rc":[{"batb":[[0,1.84,10],[1,1.83,6.25],[2,1.82,333]],"ltp":2.2,"tv":252.2,"id":40296818}]}]}
{"op":"mcm","clk":"11778302524","pt":1722729732978,"mc":[{"id":"1.231397068","rc":[{"batb":[[0,1.83,6.25],[1,1.82,333],[2,1.74,17.32]],"ltp":2.2,"tv":252.2,"id":40296818}]}]}
{"op":"mcm","clk":"11778303079","pt":1722729739069,"mc":[{"id":"1.231397068","rc":[{"batb":[[0,1.84,10],[1,1.83,6.25],[2,1.82,333]],"ltp":2.2,"tv":252.2,"id":40296818}]}]}
{"op":"mcm","clk":"11778303408","pt":1722729742479,"mc":[{"id":"1.231397068","rc":[{"batb":[[0,1.83,6.25],[1,1.82,333],[2,1.74,17.32]],"ltp":2.2,"tv":252.2,"id":40296818}]}]}
{"op":"mcm","clk":"11778303640","pt":1722729744911,"mc":[{"id":"1.231397068","rc":[{"batb":[[0,1.84,10],[1,1.83,6.25],[2,1.82,333]],"ltp":2.2,"tv":252.2,"id":40296818}]}]}
{"op":"mcm","clk":"11778303912","pt":1722729748176,"mc":[{"id":"1.231397068","rc":[{"batb":[[0,1.83,6.25],[1,1.82,333],[2,1.74,17.32]],"ltp":2.2,"tv":252.2,"id":40296818}]}]}
{"op":"mcm","clk":"11778304229","pt":1722729751696,"mc":[{"id":"1.231397068","rc":[{"batb":[[0,1.84,10],[1,1.83,6.25],[2,1.82,333]],"ltp":2.2,"tv":252.2,"id":40296818}]}]}
{"op":"mcm","clk":"11778304594","pt":1722729755215,"mc":[{"id":"1.231397068","rc":[{"batb":[[0,1.83,6.25],[1,1.82,333],[2,1.74,17.32]],"ltp":2.2,"tv":252.2,"id":40296818}]}]}
{"op":"mcm","clk":"11778304962","pt":1722729758891,"mc":[{"id":"1.231397068","rc":[{"batb":[[0,1.84,10],[1,1.83,6.25],[2,1.82,333]],"ltp":2.2,"tv":252.2,"id":40296818}]}]}
{"op":"mcm","clk":"11778305237","pt":1722729762190,"mc":[{"id":"1.231397068","rc":[{"batb":[[0,1.83,6.25],[1,1.82,333],[2,1.74,17.32]],"ltp":2.2,"tv":252.2,"id":40296818}]}]}
{"op":"mcm","clk":"11778305503","pt":1722729765042,"mc":[{"id":"1.231397068","rc":[{"batb":[[0,1.84,10],[1,1.83,6.25],[2,1.82,333]],"ltp":2.2,"tv":252.2,"id":40296818}]}]}
{"op":"mcm","clk":"11778305802","pt":1722729768410,"mc":[{"id":"1.231397068","rc":[{"batb":[[0,1.83,6.25],[1,1.82,333],[2,1.74,17.32]],"ltp":2.2,"tv":252.2,"id":40296818}]}]}
{"op":"mcm","clk":"11778306186","pt":1722729772204,"mc":[{"id":"1.231397068","rc":[{"batb":[[0,1.84,10],[1,1.83,6.25],[2,1.82,333]],"ltp":2.2,"tv":252.2,"id":40296818}]}]}
{"op":"mcm","clk":"11778306557","pt":1722729775816,"mc":[{"id":"1.231397068","rc":[{"batb":[[0,1.83,6.25],[1,1.82,333],[2,1.74,17.32]],"ltp":2.2,"tv":252.2,"id":40296818}]}]}
{"op":"mcm","clk":"11778306868","pt":1722729779228,"mc":[{"id":"1.231397068","rc":[{"batb":[[0,1.84,10],[1,1.83,6.25],[2,1.82,333]],"ltp":2.2,"tv":252.2,"id":40296818}]}]}
{"op":"mcm","clk":"11778307260","pt":1722729782809,"mc":[{"id":"1.231397068","rc":[{"batb":[[0,1.83,6.25],[1,1.82,333],[2,1.74,17.32]],"ltp":2.2,"tv":252.2,"id":40296818}]}]}
{"op":"mcm","clk":"11778307501","pt":1722729785236,"mc":[{"id":"1.231397068","rc":[{"batb":[[0,1.84,10],[1,1.83,6.25],[2,1.82,333]],"ltp":2.2,"tv":252.2,"id":40296818}]}]}
{"op":"mcm","clk":"11778307791","pt":1722729788704,"mc":[{"id":"1.231397068","rc":[{"batb":[[0,1.83,6.25],[1,1.82,333],[2,1.74,17.32]],"ltp":2.2,"tv":252.2,"id":40296818}]}]}
{"op":"mcm","clk":"11778308230","pt":1722729793613,"mc":[{"id":"1.231397068","rc":[{"batb":[[0,1.84,10],[1,1.83,6.25],[2,1.82,333]],"ltp":2.2,"tv":252.2,"id":40296818}]}]}
{"op":"mcm","clk":"11778308536","pt":1722729797128,"mc":[{"id":"1.231397068","rc":[{"batb":[[0,1.83,6.25],[1,1.82,333],[2,1.74,17.32]],"ltp":2.2,"tv":252.2,"id":40296818}]}]}
{"op":"mcm","clk":"11778308753","pt":1722729799523,"mc":[{"id":"1.231397068","rc":[{"batb":[[0,1.84,10],[1,1.83,6.25],[2,1.82,333]],"ltp":2.2,"tv":252.2,"id":40296818}]}]}
{"op":"mcm","clk":"11778309075","pt":1722729802831,"mc":[{"id":"1.231397068","rc":[{"batb":[[0,1.83,6.25],[1,1.82,333],[2,1.74,17.32]],"ltp":2.2,"tv":252.2,"id":40296818}]}]}
{"op":"mcm","clk":"11778309693","pt":1722729809141,"mc":[{"id":"1.231397068","rc":[{"batb":[[0,1.84,10],[1,1.83,6.25],[2,1.82,333]],"ltp":2.2,"tv":252.2,"id":40296818}]}]}
{"op":"mcm","clk":"11778309991","pt":1722729812644,"mc":[{"id":"1.231397068","rc":[{"batb":[[0,1.83,6.25],[1,1.82,333],[2,1.74,17.32]],"ltp":2.2,"tv":252.2,"id":40296818}]}]}
{"op":"mcm","clk":"11778310311","pt":1722729816361,"mc":[{"id":"1.231397068","rc":[{"batb":[[0,1.84,10],[1,1.83,6.25],[2,1.82,333]],"ltp":2.2,"tv":252.2,"id":40296818}]}]}
{"op":"mcm","clk":"11778310586","pt":1722729819730,"mc":[{"id":"1.231397068","rc":[{"batb":[[0,1.83,6.25],[1,1.82,333],[2,1.74,17.32]],"ltp":2.2,"tv":252.2,"id":40296818}]}]}
{"op":"mcm","clk":"11778310786","pt":1722729821850,"mc":[{"id":"1.231397068","rc":[{"batb":[[0,1.84,10],[1,1.83,6.25],[2,1.82,333]],"ltp":2.2,"tv":252.2,"id":40296818}]}]}
{"op":"mcm","clk":"11778311105","pt":1722729825263,"mc":[{"id":"1.231397068","rc":[{"batb":[[0,1.83,6.25],[1,1.82,333],[2,1.74,17.32]],"ltp":2.2,"tv":252.2,"id":40296818}]}]}
{"op":"mcm","clk":"11778311340","pt":1722729827894,"mc":[{"id":"1.231397068","rc":[{"batb":[[0,1.84,10],[1,1.83,6.25],[2,1.82,333]],"ltp":2.2,"tv":252.2,"id":40296818}]}]}
{"op":"mcm","clk":"11778311668","pt":1722729831467,"mc":[{"id":"1.231397068","rc":[{"batb":[[0,1.83,6.25],[1,1.82,333],[2,1.74,17.32]],"ltp":2.2,"tv":252.2,"id":40296818}]}]}
{"op":"mcm","clk":"11778311886","pt":1722729833845,"mc":[{"id":"1.231397068","rc":[{"batb":[[0,1.84,10],[1,1.83,6.25],[2,1.82,333]],"ltp":2.2,"tv":252.2,"id":40296818}]}]}
{"op":"mcm","clk":"11778312181","pt":1722729837465,"mc":[{"id":"1.231397068","rc":[{"batb":[[0,1.83,6.25],[1,1.82,333],[2,1.74,17.32]],"ltp":2.2,"tv":252.2,"id":40296818}]}]}
{"op":"mcm","clk":"11778312365","pt":1722729839885,"mc":[{"id":"1.231397068","rc":[{"batb":[[0,1.84,10],[1,1.83,6.25],[2,1.82,333]],"ltp":2.2,"tv":252.2,"id":40296818}]}]}
{"op":"mcm","clk":"11778312694","pt":1722729843455,"mc":[{"id":"1.231397068","rc":[{"batb":[[0,1.83,6.25],[1,1.82,333],[2,1.74,17.32]],"ltp":2.2,"tv":252.2,"id":40296818}]}]}
{"op":"mcm","clk":"11778312932","pt":1722729845886,"mc":[{"id":"1.231397068","rc":[{"batb":[[0,1.84,10],[1,1.83,6.25],[2,1.82,333]],"ltp":2.2,"tv":252.2,"id":40296818}]}]}
{"op":"mcm","clk":"11778313210","pt":1722729849286,"mc":[{"id":"1.231397068","rc":[{"batb":[[0,1.83,6.25],[1,1.82,333],[2,1.74,17.32]],"ltp":2.2,"tv":252.2,"id":40296818}]}]}
{"op":"mcm","clk":"11778313553","pt":1722729853205,"mc":[{"id":"1.231397068","rc":[{"batb":[[0,1.84,10],[1,1.83,6.25],[2,1.82,333]],"ltp":2.2,"tv":252.2,"id":40296818}]}]}
{"op":"mcm","clk":"11778313861","pt":1722729856512,"mc":[{"id":"1.231397068","rc":[{"batb":[[0,1.83,6.25],[1,1.82,333],[2,1.74,17.32]],"ltp":2.2,"tv":252.2,"id":40296818}]}]}
{"op":"mcm","clk":"11778314092","pt":1722729859198,"mc":[{"id":"1.231397068","rc":[{"batb":[[0,1.84,10],[1,1.83,6.25],[2,1.82,333]],"ltp":2.2,"tv":252.2,"id":40296818}]}]}
{"op":"mcm","clk":"11778314432","pt":1722729862710,"mc":[{"id":"1.231397068","rc":[{"batb":[[0,1.83,6.25],[1,1.82,333],[2,1.74,17.32]],"ltp":2.2,"tv":252.2,"id":40296818}]}]}
{"op":"mcm","clk":"11778315004","pt":1722729868811,"mc":[{"id":"1.231397068","rc":[{"batb":[[0,1.84,10],[1,1.83,6.25],[2,1.82,333]],"ltp":2.2,"tv":252.2,"id":40296818}]}]}
{"op":"mcm","clk":"11778315379","pt":1722729872329,"mc":[{"id":"1.231397068","rc":[{"batb":[[0,1.83,6.25],[1,1.82,333],[2,1.74,17.32]],"ltp":2.2,"tv":252.2,"id":40296818}]}]}
{"op":"mcm","clk":"11778315652","pt":1722729875232,"mc":[{"id":"1.231397068","rc":[{"batb":[[0,1.84,10],[1,1.83,6.25],[2,1.82,333]],"ltp":2.2,"tv":252.2,"id":40296818}]}]}
{"op":"mcm","clk":"11778315927","pt":1722729878634,"mc":[{"id":"1.231397068","rc":[{"batb":[[0,1.83,6.25],[1,1.82,333],[2,1.74,17.32]],"ltp":2.2,"tv":252.2,"id":40296818}]}]}
{"op":"mcm","clk":"11778316272","pt":1722729882653,"mc":[{"id":"1.231397068","rc":[{"batb":[[0,1.84,10],[1,1.83,6.25],[2,1.82,333]],"ltp":2.2,"tv":252.2,"id":40296818}]}]}
{"op":"mcm","clk":"11778316563","pt":1722729885917,"mc":[{"id":"1.231397068","rc":[{"batb":[[0,1.83,6.25],[1,1.82,333],[2,1.74,17.32]],"ltp":2.2,"tv":252.2,"id":40296818}]}]}
{"op":"mcm","clk":"11778316877","pt":1722729889471,"mc":[{"id":"1.231397068","rc":[{"batb":[[0,1.84,10],[1,1.83,6.25],[2,1.82,333]],"ltp":2.2,"tv":252.2,"id":40296818}]}]}
{"op":"mcm","clk":"11778317233","pt":1722729893035,"mc":[{"id":"1.231397068","rc":[{"batb":[[0,1.83,6.25],[1,1.82,333],[2,1.74,17.32]],"ltp":2.2,"tv":252.2,"id":40296818}]}]}
{"op":"mcm","clk":"11778317877","pt":1722729899954,"mc":[{"id":"1.231397068","rc":[{"batb":[[0,1.84,10],[1,1.83,6.25],[2,1.82,333]],"ltp":2.2,"tv":252.2,"id":40296818}]}]}
{"op":"mcm","clk":"11778318302","pt":1722729903463,"mc":[{"id":"1.231397068","rc":[{"batb":[[0,1.83,6.25],[1,1.82,333],[2,1.74,17.32]],"ltp":2.2,"tv":252.2,"id":40296818}]}]}
{"op":"mcm","clk":"11778318582","pt":1722729905995,"mc":[{"id":"1.231397068","rc":[{"batb":[[0,1.84,10],[1,1.83,6.25],[2,1.82,333]],"ltp":2.2,"tv":252.2,"id":40296818}]}]}
{"op":"mcm","clk":"11778318934","pt":1722729909386,"mc":[{"id":"1.231397068","rc":[{"batb":[[0,1.83,6.25],[1,1.82,333],[2,1.74,17.32]],"ltp":2.2,"tv":252.2,"id":40296818}]}]}
{"op":"mcm","clk":"11778319180","pt":1722729911765,"mc":[{"id":"1.231397068","rc":[{"batb":[[0,1.84,10],[1,1.83,6.25],[2,1.82,333]],"ltp":2.2,"tv":252.2,"id":40296818}]}]}
{"op":"mcm","clk":"11778319551","pt":1722729915292,"mc":[{"id":"1.231397068","rc":[{"batb":[[0,1.83,6.25],[1,1.82,333],[2,1.74,17.32]],"ltp":2.2,"tv":252.2,"id":40296818}]}]}
